{"op":"mcm","clk":"998154875","pt":1580585274635,"mc":[{"id":"1.168224459","marketDefinition":{"bspMarket":false,"turnInPlayEnabled":true,"persistenceEnabled":true,"marketBaseRate":5.0,"eventId":"29681747","eventTypeId":"2","numberOfWinners":1,"bettingType":"ODDS","marketType":"MATCH_ODDS","marketTime":"2020-02-02T09:00:00.000Z","suspendTime":"2020-02-02T09:00:00.000Z","bspReconciled":false,"complete":true,"inPlay":false,"crossMatching":false,"runnersVoidable":false,"numberOfActiveRunners":2,"betDelay":0,"status":"OPEN","runners":[{"status":"ACTIVE","sortPriority":1,"id":5858055,"name":"Hiroki Moriya"},{"status":"ACTIVE","sortPriority":2,"id":7444998,"name":"Danilo Petrovic"}],"regulators":["MR_INT"],"countryCode":"FR","discountAllowed":false,"timezone":"UTC","openDate":"2020-02-02T09:00:00.000Z","version":3147098663,"name":"Match Odds","eventName":"Moriya v Petrovic"},"rc":[{"batb":[[0,1.05,152.2],[1,1.04,168.86],[2,1.03,190.07]],"ltp":0.0,"tv":0.0,"id":5858055},{"batb":[[0,1.05,152.2],[1,1.04,168.86],[2,1.03,190.07]],"ltp":0.0,"tv":0.0,"id":7444998}]}]}
{"op":"mcm","clk":"998155189","pt":1580585276473,"mc":[{"id":"1.168224459","marketDefinition":{"bspMarket":false,"turnInPlayEnabled":true,"persistenceEnabled":true,"marketBaseRate":5.0,"eventId":"29681747","eventTypeId":"2","numberOfWinners":1,"bettingType":"ODDS","marketType":"MATCH_ODDS","marketTime":"2020-02-02T09:00:00.000Z","suspendTime":"2020-02-02T09:00:00.000Z","bspReconciled":false,"complete":true,"inPlay":false,"crossMatching":false,"runnersVoidable":false,"numberOfActiveRunners":2,"betDelay":0,"status":"OPEN","runners":[{"status":"ACTIVE","sortPriority":1,"id":5858055,"name":"Hiroki Moriya"},{"status":"ACTIVE","sortPriority":2,"id":7444998,"name":"Danilo Petrovic"}],"regulators":["MR_INT"],"countryCode":"FR","discountAllowed":true,"timezone":"UTC","openDate":"2020-02-02T09:00:00.000Z","version":3147098663,"name":"Match Odds","eventName":"Moriya v Petrovic"}}]}
{"op":"mcm","clk":"998196782","pt":1580585516475,"mc":[{"id":"1.168224459","marketDefinition":{"bspMarket":false,"turnInPlayEnabled":true,"persistenceEnabled":true,"marketBaseRate":5.0,"eventId":"29681747","eventTypeId":"2","numberOfWinners":1,"bettingType":"ODDS","marketType":"MATCH_ODDS","marketTime":"2020-02-02T15:30:00.000Z","suspendTime":"2020-02-02T15:30:00.000Z","bspReconciled":false,"complete":true,"inPlay":false,"crossMatching":false,"runnersVoidable":false,"numberOfActiveRunners":2,"betDelay":0,"status":"OPEN","runners":[{"status":"ACTIVE","sortPriority":1,"id":5858055,"name":"Hiroki Moriya"},{"status":"ACTIVE","sortPriority":2,"id":7444998,"name":"Danilo Petrovic"}],"regulators":["MR_INT"],"countryCode":"FR","discountAllowed":true,"timezone":"UTC","openDate":"2020-02-02T09:00:00.000Z","version":3147125081,"name":"Match Odds","eventName":"Moriya v Petrovic"}}]}
{"op":"mcm","clk":"998197430","pt":1580585519449,"mc":[{"id":"1.168224459","marketDefinition":{"bspMarket":false,"turnInPlayEnabled":true,"persistenceEnabled":true,"marketBaseRate":5.0,"eventId":"29681747","eventTypeId":"2","numberOfWinners":1,"bettingType":"ODDS","marketType":"MATCH_ODDS","marketTime":"2020-02-02T15:30:00.000Z","suspendTime":"2020-02-02T15:30:00.000Z","bspReconciled":false,"complete":true,"inPlay":false,"crossMatching":false,"runnersVoidable":false,"numberOfActiveRunners":2,"betDelay":0,"status":"OPEN","runners":[{"status":"ACTIVE","sortPriority":1,"id":5858055,"name":"Hiroki Moriya"},{"status":"ACTIVE","sortPriority":2,"id":7444998,"name":"Danilo Petrovic"}],"regulators":["MR_INT"],"countryCode":"FR","discountAllowed":true,"timezone":"UTC","openDate":"2020-02-02T15:30:00.000Z","version":3147125081,"name":"Match Odds","eventName":"Moriya v Petrovic"}}]}
{"op":"mcm","clk":"998202058","pt":1580585544438,"mc":[{"id":"1.168224459","rc":[{"batb":[[0,1.06,50.48],[1,1.05,152.2],[2,1.04,168.86]],"ltp":0.0,"tv":0.0,"id":5858055},{"batb":[[0,1.06,50.48],[1,1.05,152.2],[2,1.04,168.86]],"ltp":0.0,"tv":0.0,"id":7444998}]}]}
{"op":"mcm","clk":"998203242","pt":1580585550628,"mc":[{"id":"1.168224459","marketDefinition":{"bspMarket":false,"turnInPlayEnabled":true,"persistenceEnabled":true,"marketBaseRate":5.0,"eventId":"29681747","eventTypeId":"2","numberOfWinners":1,"bettingType":"ODDS","marketType":"MATCH_ODDS","marketTime":"2020-02-02T15:30:00.000Z","suspendTime":"2020-02-02T15:30:00.000Z","bspReconciled":false,"complete":true,"inPlay":false,"crossMatching":true,"runnersVoidable":false,"numberOfActiveRunners":2,"betDelay":0,"status":"OPEN","runners":[{"status":"ACTIVE","sortPriority":1,"id":5858055,"name":"Hiroki Moriya"},{"status":"ACTIVE","sortPriority":2,"id":7444998,"name":"Danilo Petrovic"}],"regulators":["MR_INT"],"countryCode":"FR","discountAllowed":true,"timezone":"UTC","openDate":"2020-02-02T15:30:00.000Z","version":3147125081,"name":"Match Odds","eventName":"Moriya v Petrovic"}}]}
{"op":"mcm","clk":"998266343","pt":1580585906532,"mc":[{"id":"1.168224459","rc":[{"batl":[[0,48,31.05]],"ltp":0.0,"tv":0.0,"id":5858055},{"batl":[[0,48,31.05]],"ltp":0.0,"tv":0.0,"id":7444998}]}]}
{"op":"mcm","clk":"998566472","pt":1580587950066,"mc":[{"id":"1.168224459","rc":[{"batl":[[1,990,2.2]],"ltp":0.0,"tv":0.0,"id":5858055},{"batl":[[1,990,2.2]],"ltp":0.0,"tv":0.0,"id":7444998}]}]}
{"op":"mcm","clk":"999858023","pt":1580601576356,"mc":[{"id":"1.168224459","rc":[{"batl":[[2,1000,2]],"ltp":0.0,"tv":0.0,"id":5858055},{"batl":[[2,1000,2]],"ltp":0.0,"tv":0.0,"id":7444998}]}]}
{"op":"mcm","clk":"999858028","pt":1580601576461,"mc":[{"id":"1.168224459","rc":[{"batb":[[0,1.06,50.58],[2,1.04,169.36]],"batl":[[2,1000,0.02]],"ltp":0.0,"tv":0.0,"id":5858055},{"batb":[[0,1.06,50.58],[2,1.04,169.36]],"batl":[[2,1000,0.02]],"ltp":0.0,"tv":0.0,"id":7444998}]}]}
{"op":"mcm","clk":"999860166","pt":1580601625030,"mc":[{"id":"1.168224459","rc":[{"batb":[[0,1.06,50.68]],"ltp":0.0,"tv":0.0,"id":5858055},{"batb":[[0,1.06,50.68]],"ltp":0.0,"tv":0.0,"id":7444998}]}]}
{"op":"mcm","clk":"1000473030","pt":1580615093140,"mc":[{"id":"1.168224459","rc":[{"batl":[[0,990,2.2],[1,1000,0.02],[2,1000,0]],"ltp":0.0,"tv":0.0,"id":5858055},{"batl":[[0,990,2.2],[1,1000,0.02],[2,1000,0]],"ltp":0.0,"tv":0.0,"id":7444998}]}]}
{"op":"mcm","clk":"1000535446","pt":1580616368536,"mc":[{"id":"1.168224459","rc":[{"batl":[[0,95,15.9],[1,990,2.2],[2,1000,0.02]],"ltp":0.0,"tv":0.0,"id":5858055},{"batl":[[0,95,15.9],[1,990,2.2],[2,1000,0.02]],"ltp":0.0,"tv":0.0,"id":7444998}]}]}
{"op":"mcm","clk":"1000548102","pt":1580616635693,"mc":[{"id":"1.168224459","rc":[{"batb":[[0,1.13,75.82],[1,1.06,50.58],[2,1.05,152.2]],"ltp":0.0,"tv":0.0,"id":5858055},{"batb":[[0,1.13,75.82],[1,1.06,50.58],[2,1.05,152.2]],"ltp":0.0,"tv":0.0,"id":7444998}]}]}
{"op":"mcm","clk":"1001063071","pt":1580627610304,"mc":[{"id":"1.168224459","rc":[{"batb":[[0,1.14,15.22],[1,1.13,75.72],[2,1.06,50.58]],"batl":[[0,11.5,3.36],[1,95,15.9],[2,990,2.2]],"ltp":0.0,"tv":0.0,"id":5858055},{"batb":[[0,1.14,15.22],[1,1.13,75.72],[2,1.06,50.58]],"batl":[[0,13,3.36],[1,95,15.9],[2,990,2.2]],"ltp":0.0,"tv":0.0,"id":7444998}]}]}
{"op":"mcm","clk":"1001086603","pt":1580628190897,"mc":[{"id":"1.168224459","rc":[{"batb":[[0,1.6,42.74],[1,1.14,15.22],[2,1.13,75.72]],"ltp":0.0,"tv":0.0,"id":5858055},{"batb":[[0,1.69,36.21],[1,1.14,15.22],[2,1.13,75.72]],"ltp":0.0,"tv":0.0,"id":7444998}]}]}
{"op":"mcm","clk":"1001087001","pt":1580628199033,"mc":[{"id":"1.168224459","rc":[{"batb":[[0,1.14,15.22],[1,1.13,75.72],[2,1.06,50.58]],"ltp":0.0,"tv":0.0,"id":5858055},{"batb":[[0,1.14,15.22],[1,1.13,75.72],[2,1.06,50.58]],"ltp":0.0,"tv":0.0,"id":7444998}]}]}
{"op":"mcm","clk":"1001087044","pt":1580628199804,"mc":[{"id":"1.168224459","rc":[{"batb":[[0,1.63,37.96],[1,1.14,15.22],[2,1.13,75.72]],"ltp":0.0,"tv":0.0,"id":5858055},{"batb":[[0,1.65,41.93],[1,1.14,15.22],[2,1.13,75.72]],"ltp":0.0,"tv":0.0,"id":7444998}]}]}
{"op":"mcm","clk":"1001087758","pt":1580628214824,"mc":[{"id":"1.168224459","rc":[{"batb":[[1,1.13,75.82],[2,1.06,50.58]],"ltp":0.0,"tv":0.0,"id":5858055},{"batb":[[1,1.13,75.82],[2,1.06,50.58]],"ltp":0.0,"tv":0.0,"id":7444998}]}]}
{"op":"mcm","clk":"1001088149","pt":1580628223268,"mc":[{"id":"1.168224459","rc":[{"batb":[[0,1.84,49.22],[1,1.63,37.96],[2,1.13,75.82]],"ltp":0.0,"tv":0.0,"id":5858055}]}]}
{"op":"mcm","clk":"1001088179","pt":1580628223737,"mc":[{"id":"1.168224459","rc":[{"batb":[[0,1.86,33.18],[1,1.84,49.22]],"ltp":0.0,"tv":0.0,"id":5858055},{"batb":[[0,1.75,39.35],[1,1.73,35.59],[2,1.13,75.82]],"ltp":0.0,"tv":0.0,"id":7444998}]}]}
{"op":"mcm","clk":"1001090210","pt":1580628272735,"mc":[{"id":"1.168224459","rc":[{"batb":[[2,1.1,75.92]],"ltp":0.0,"tv":0.0,"id":5858055},{"batb":[[2,1.1,75.92]],"ltp":0.0,"tv":0.0,"id":7444998}]}]}
{"op":"mcm","clk":"1001090724","pt":1580628285858,"mc":[{"id":"1.168224459","rc":[{"batb":[[2,1.41,7.57]],"ltp":0.0,"tv":0.0,"id":5858055},{"batb":[[2,1.41,7.57]],"ltp":0.0,"tv":0.0,"id":7444998}]}]}
{"op":"mcm","clk":"1001092831","pt":1580628339083,"mc":[{"id":"1.168224459","rc":[{"batb":[[0,1.86,82.4],[1,1.41,7.57],[2,1.1,75.92]],"ltp":0.0,"tv":0.0,"id":5858055}]}]}
{"op":"mcm","clk":"1001099662","pt":1580628465317,"mc":[{"id":"1.168224459","rc":[{"batb":[[0,1.88,49.22],[1,1.86,33.18],[2,1.41,7.57]],"ltp":0.0,"tv":0.0,"id":5858055}]}]}
{"op":"mcm","clk":"1001099679","pt":1580628465626,"mc":[{"id":"1.168224459","rc":[{"batb":[[0,1.94,31.76],[1,1.88,49.22]],"ltp":0.0,"tv":0.0,"id":5858055}]}]}
{"op":"mcm","clk":"1001105156","pt":1580628582393,"mc":[{"id":"1.168224459","rc":[{"batb":[[1,1.87,49.22]],"ltp":0.0,"tv":0.0,"id":5858055}]}]}
{"op":"mcm","clk":"1001114901","pt":1580628791968,"mc":[{"id":"1.168224459","rc":[{"batb":[[1,1.84,49.22]],"ltp":0.0,"tv":0.0,"id":5858055}]}]}
{"op":"mcm","clk":"1001116895","pt":1580628836029,"mc":[{"id":"1.168224459","rc":[{"batb":[[1,1.87,49.22]],"ltp":0.0,"tv":0.0,"id":5858055}]}]}
{"op":"mcm","clk":"1001122900","pt":1580628976724,"mc":[{"id":"1.168224459","rc":[{"batb":[[1,1.88,49.22]],"ltp":0.0,"tv":0.0,"id":5858055}]}]}
{"op":"mcm","clk":"1001144540","pt":1580629417393,"mc":[{"id":"1.168224459","rc":[{"batb":[[1,1.41,7.57],[2,1.1,75.92]],"ltp":0.0,"tv":0.0,"id":5858055}]}]}
{"op":"mcm","clk":"1001144546","pt":1580629417496,"mc":[{"id":"1.168224459","rc":[{"batb":[[1,1.91,49.22],[2,1.41,7.57]],"ltp":0.0,"tv":0.0,"id":5858055}]}]}
{"op":"mcm","clk":"1001172108","pt":1580630097132,"mc":[{"id":"1.168224459","rc":[{"batb":[[0,1.91,49.22],[1,1.41,7.57],[2,1.1,75.92]],"ltp":0.0,"tv":0.0,"id":5858055}]}]}
{"op":"mcm","clk":"1001172226","pt":1580630099860,"mc":[{"id":"1.168224459","rc":[{"batb":[[0,1.65,38.93]],"ltp":0.0,"tv":0.0,"id":5858055}]}]}
{"op":"mcm","clk":"1001173746","pt":1580630139786,"mc":[{"id":"1.168224459","rc":[{"batb":[[0,1.68,38.11],[1,1.66,11.76],[2,1.41,7.57]],"ltp":0.0,"tv":0.0,"id":5858055}]}]}
{"op":"mcm","clk":"1001175995","pt":1580630199078,"mc":[{"id":"1.168224459","rc":[{"batb":[[1,1.41,7.57],[2,1.1,75.92]],"ltp":0.0,"tv":0.0,"id":5858055}]}]}
{"op":"mcm","clk":"1001178369","pt":1580630260030,"mc":[{"id":"1.168224459","rc":[{"batb":[[0,1.74,36.79],[1,1.69,11.76],[2,1.41,7.57]],"ltp":0.0,"tv":0.0,"id":5858055}]}]}
{"op":"mcm","clk":"1001178875","pt":1580630273214,"mc":[{"id":"1.168224459","rc":[{"batb":[[1,1.73,52.25]],"ltp":0.0,"tv":0.0,"id":7444998}]}]}
{"op":"mcm","clk":"1001180753","pt":1580630319609,"mc":[{"id":"1.168224459","rc":[{"batb":[[1,1.41,7.57],[2,1.1,75.92]],"ltp":0.0,"tv":0.0,"id":5858055}]}]}
{"op":"mcm","clk":"1001183720","pt":1580630382921,"mc":[{"id":"1.168224459","rc":[{"batb":[[0,1.83,35.03],[1,1.75,10.92],[2,1.41,7.57]],"ltp":0.0,"tv":0.0,"id":5858055}]}]}
{"op":"mcm","clk":"1001186845","pt":1580630443232,"mc":[{"id":"1.168224459","rc":[{"batb":[[1,1.41,7.57],[2,1.1,75.92]],"ltp":0.0,"tv":0.0,"id":5858055}]}]}
{"op":"mcm","clk":"1001187652","pt":1580630458237,"mc":[{"id":"1.168224459","rc":[{"batb":[[0,1.83,85.01]],"ltp":0.0,"tv":0.0,"id":5858055},{"batb":[[0,1.8,36.18],[1,1.79,52.25]],"ltp":0.0,"tv":0.0,"id":7444998}]}]}
{"op":"mcm","clk":"1001197357","pt":1580630634002,"mc":[{"id":"1.168224459","rc":[{"batb":[[0,1.86,34.68],[1,1.83,52.25]],"ltp":0.0,"tv":0.0,"id":7444998}]}]}
{"op":"mcm","clk":"1001198234","pt":1580630649424,"mc":[{"id":"1.168224459","rc":[{"batb":[[0,1.83,35.03],[1,1.81,49.98],[2,1.41,7.57]],"ltp":0.0,"tv":0.0,"id":5858055},{"batb":[[1,1.81,52.25]],"ltp":0.0,"tv":0.0,"id":7444998}]}]}
{"op":"mcm","clk":"1001207231","pt":1580630797871,"mc":[{"id":"1.168224459","rc":[{"batb":[[0,1.81,49.98],[1,1.41,7.57],[2,1.1,75.92]],"ltp":0.0,"tv":0.0,"id":5858055},{"batl":[[0,1.92,2.52],[1,13,3.36],[2,95,15.9]],"ltp":0.0,"tv":0.0,"id":7444998}]}]}
{"op":"mcm","clk":"1001208050","pt":1580630811829,"mc":[{"id":"1.168224459","rc":[{"batl":[[1,95,15.9],[2,990,2.2]],"ltp":0.0,"tv":0.0,"id":7444998}]}]}
{"op":"mcm","clk":"1001250904","pt":1580631800355,"mc":[{"id":"1.168224459","rc":[{"batb":[[0,1.81,52.25],[1,1.41,7.57],[2,1.1,75.92]],"ltp":0.0,"tv":0.0,"id":7444998}]}]}
{"op":"mcm","clk":"1001250912","pt":1580631800558,"mc":[{"id":"1.168224459","rc":[{"batb":[[0,1.84,34.97],[1,1.81,52.25],[2,1.41,7.57]],"ltp":0.0,"tv":0.0,"id":7444998}]}]}
{"op":"mcm","clk":"1001251899","pt":1580631827950,"mc":[{"id":"1.168224459","rc":[{"batb":[[0,1.84,52.47]],"ltp":0.0,"tv":0.0,"id":7444998}]}]}
{"op":"mcm","clk":"1001258428","pt":1580631970506,"mc":[{"id":"1.168224459","rc":[{"batb":[[2,1.11,37.96]],"ltp":0.0,"tv":0.0,"id":5858055}]}]}
{"op":"mcm","clk":"1001258504","pt":1580631972008,"mc":[{"id":"1.168224459","rc":[{"batb":[[2,1.21,37.86]],"ltp":0.0,"tv":0.0,"id":5858055}]}]}
{"op":"mcm","clk":"1001258597","pt":1580631973301,"mc":[{"id":"1.168224459","rc":[{"batb":[[1,1.51,37.86],[2,1.41,45.43]],"ltp":0.0,"tv":0.0,"id":5858055},{"batb":[[2,1.41,45.43]],"ltp":0.0,"tv":0.0,"id":7444998}]}]}
{"op":"mcm","clk":"1001258629","pt":1580631973916,"mc":[{"id":"1.168224459","rc":[{"batb":[[0,1.81,87.84],[1,1.71,37.86],[2,1.61,37.86]],"ltp":0.0,"tv":0.0,"id":5858055},{"batb":[[2,1.71,37.86]],"ltp":0.0,"tv":0.0,"id":7444998}]}]}
{"op":"mcm","clk":"1001306618","pt":1580633093741,"mc":[{"id":"1.168224459","rc":[{"batb":[[1,1.71,37.86],[2,1.61,37.86]],"ltp":0.0,"tv":0.0,"id":7444998}]}]}
{"op":"mcm","clk":"1001312835","pt":1580633214682,"mc":[{"id":"1.168224459","rc":[{"trd":[[1.81,0.41],[2.08,2.32]],"batb":[[0,1.81,87.63]],"ltp":1.81,"tv":2.73,"id":5858055},{"trd":[[1.92,2.52]],"batl":[[0,95,15.9],[1,990,2.2],[2,1000,0.02]],"ltp":1.92,"tv":2.52,"id":7444998}],"tv":5.25}]}
{"op":"mcm","clk":"1001316719","pt":1580633295358,"mc":[{"id":"1.168224459","rc":[{"batl":[[0,12,3.36],[1,95,15.9],[2,990,2.2]],"ltp":1.92,"tv":2.52,"id":7444998}]}]}
{"op":"mcm","clk":"1001325238","pt":1580633486975,"mc":[{"id":"1.168224459","rc":[{"batb":[[1,1.77,37.37],[2,1.71,37.86]],"ltp":1.81,"tv":2.73,"id":5858055},{"batb":[[1,1.73,39.41],[2,1.71,37.86]],"ltp":1.92,"tv":2.52,"id":7444998}]}]}
{"op":"mcm","clk":"1001336892","pt":1580633774056,"mc":[{"id":"1.168224459","rc":[{"batb":[[0,1.9,2.53],[1,1.81,87.63],[2,1.77,37.37]],"ltp":1.81,"tv":2.73,"id":5858055}]}]}
{"op":"mcm","clk":"1001349176","pt":1580634086126,"mc":[{"id":"1.168224459","rc":[{"batb":[[0,1.75,3.11]],"ltp":1.92,"tv":2.52,"id":7444998}]}]}
{"op":"mcm","clk":"1001349267","pt":1580634087625,"mc":[{"id":"1.168224459","rc":[{"batb":[[1,1.83,49.77],[2,1.81,37.86]],"ltp":1.81,"tv":2.73,"id":5858055}]}]}
{"op":"mcm","clk":"1001349329","pt":1580634089020,"mc":[{"id":"1.168224459","rc":[{"batb":[[0,1.73,39.41],[1,1.71,37.86],[2,1.61,37.86]],"ltp":1.92,"tv":2.52,"id":7444998}]}]}
{"op":"mcm","clk":"1001350408","pt":1580634114352,"mc":[{"id":"1.168224459","rc":[{"batb":[[0,1.79,50.73],[1,1.73,39.41],[2,1.71,37.86]],"ltp":1.92,"tv":2.52,"id":7444998}]}]}
{"op":"mcm","clk":"1001350773","pt":1580634122588,"mc":[{"id":"1.168224459","rc":[{"batb":[[0,1.8,54.43],[1,1.79,50.73],[2,1.73,39.41]],"ltp":1.92,"tv":2.52,"id":7444998}]}]}
{"op":"mcm","clk":"1001351784","pt":1580634143324,"mc":[{"id":"1.168224459","rc":[{"batb":[[0,1.93,64.13],[1,1.9,2.53],[2,1.83,49.77]],"ltp":1.81,"tv":2.73,"id":5858055},{"batb":[[0,1.89,59.18],[1,1.8,54.43],[2,1.79,50.73]],"ltp":1.92,"tv":2.52,"id":7444998}]}]}
{"op":"mcm","clk":"1001400574","pt":1580635113256,"mc":[{"id":"1.168224459","rc":[{"batl":[[0,2.06,7.57],[1,12,3.36],[2,95,15.9]],"ltp":1.92,"tv":2.52,"id":7444998}]}]}
{"op":"mcm","clk":"1001402591","pt":1580635152512,"mc":[{"id":"1.168224459","rc":[{"batl":[[1,95,15.9],[2,990,2.2]],"ltp":1.92,"tv":2.52,"id":7444998}]}]}
{"op":"mcm","clk":"1001403009","pt":1580635162298,"mc":[{"id":"1.168224459","rc":[{"batb":[[0,1.95,50.02]],"ltp":1.81,"tv":2.73,"id":5858055}]}]}
{"op":"mcm","clk":"1001417559","pt":1580635472689,"mc":[{"id":"1.168224459","rc":[{"batb":[[1,1.79,50.73],[2,1.73,39.41]],"ltp":1.92,"tv":2.52,"id":7444998}]}]}
{"op":"mcm","clk":"1001417715","pt":1580635476099,"mc":[{"id":"1.168224459","rc":[{"batb":[[2,1.73,51.86]],"ltp":1.92,"tv":2.52,"id":7444998}]}]}
{"op":"mcm","clk":"1001426382","pt":1580635616377,"mc":[{"id":"1.168224459","marketDefinition":{"bspMarket":false,"turnInPlayEnabled":true,"persistenceEnabled":true,"marketBaseRate":5.0,"eventId":"29681747","eventTypeId":"2","numberOfWinners":1,"bettingType":"ODDS","marketType":"MATCH_ODDS","marketTime":"2020-02-02T15:24:00.000Z","suspendTime":"2020-02-02T15:24:00.000Z","bspReconciled":false,"complete":true,"inPlay":false,"crossMatching":true,"runnersVoidable":false,"numberOfActiveRunners":2,"betDelay":0,"status":"OPEN","runners":[{"status":"ACTIVE","sortPriority":1,"id":5858055,"name":"Hiroki Moriya"},{"status":"ACTIVE","sortPriority":2,"id":7444998,"name":"Danilo Petrovic"}],"regulators":["MR_INT"],"countryCode":"FR","discountAllowed":true,"timezone":"UTC","openDate":"2020-02-02T15:30:00.000Z","version":3148345723,"name":"Match Odds","eventName":"Moriya v Petrovic"}}]}
{"op":"mcm","clk":"1001426714","pt":1580635619343,"mc":[{"id":"1.168224459","marketDefinition":{"bspMarket":false,"turnInPlayEnabled":true,"persistenceEnabled":true,"marketBaseRate":5.0,"eventId":"29681747","eventTypeId":"2","numberOfWinners":1,"bettingType":"ODDS","marketType":"MATCH_ODDS","marketTime":"2020-02-02T15:24:00.000Z","suspendTime":"2020-02-02T15:24:00.000Z","bspReconciled":false,"complete":true,"inPlay":false,"crossMatching":true,"runnersVoidable":false,"numberOfActiveRunners":2,"betDelay":0,"status":"OPEN","runners":[{"status":"ACTIVE","sortPriority":1,"id":5858055,"name":"Hiroki Moriya"},{"status":"ACTIVE","sortPriority":2,"id":7444998,"name":"Danilo Petrovic"}],"regulators":["MR_INT"],"countryCode":"FR","discountAllowed":true,"timezone":"UTC","openDate":"2020-02-02T15:24:00.000Z","version":3148345723,"name":"Match Odds","eventName":"Moriya v Petrovic"}}]}
{"op":"mcm","clk":"1001428646","pt":1580635653405,"mc":[{"id":"1.168224459","rc":[{"batb":[[2,1.81,37.86]],"ltp":1.81,"tv":2.73,"id":5858055},{"batb":[[1,1.73,51.86],[2,1.71,37.86]],"ltp":1.92,"tv":2.52,"id":7444998}]}]}
{"op":"mcm","clk":"1001453328","pt":1580636173146,"mc":[{"id":"1.168224459","rc":[{"batl":[[0,2.28,18.48],[1,11.5,3.36],[2,95,15.9]],"ltp":1.81,"tv":2.73,"id":5858055}]}]}
{"op":"mcm","clk":"1001454237","pt":1580636193060,"mc":[{"id":"1.168224459","rc":[{"batl":[[1,2.28,18.48],[2,95,15.9]],"ltp":1.92,"tv":2.52,"id":7444998}]}]}
{"op":"mcm","clk":"1001454962","pt":1580636213094,"mc":[{"id":"1.168224459","rc":[{"batl":[[1,95,15.9],[2,990,2.2]],"ltp":1.81,"tv":2.73,"id":5858055}]}]}
{"op":"mcm","clk":"1001477249","pt":1580636673572,"mc":[{"id":"1.168224459","rc":[{"batl":[[2,2.6,74.21]],"ltp":1.92,"tv":2.52,"id":7444998}]}]}
{"op":"mcm","clk":"1001509179","pt":1580637249118,"mc":[{"id":"1.168224459","rc":[{"batb":[[1,1.71,37.86],[2,1.7,54.09]],"ltp":1.92,"tv":2.52,"id":7444998}]}]}
{"op":"mcm","clk":"1001542849","pt":1580637750889,"mc":[{"id":"1.168224459","rc":[{"batb":[[2,1.87,48.46]],"ltp":1.81,"tv":2.73,"id":5858055},{"batb":[[1,1.76,51.49],[2,1.71,37.86]],"ltp":1.92,"tv":2.52,"id":7444998}]}]}
{"op":"mcm","clk":"1001562902","pt":1580637981079,"mc":[{"id":"1.168224459","rc":[{"batl":[[0,2.04,7.57],[1,2.06,7.57],[2,2.28,18.48]],"ltp":1.92,"tv":2.52,"id":7444998}]}]}
{"op":"mcm","clk":"1001563022","pt":1580637982580,"mc":[{"id":"1.168224459","rc":[{"batl":[[1,2.28,18.48],[2,2.6,74.21]],"ltp":1.92,"tv":2.52,"id":7444998}]}]}
{"op":"mcm","clk":"1001568827","pt":1580638050104,"mc":[{"id":"1.168224459","rc":[{"batb":[[0,1.97,36.4]],"ltp":1.81,"tv":2.73,"id":5858055}]}]}
{"op":"mcm","clk":"1001599030","pt":1580638365174,"mc":[{"id":"1.168224459","rc":[{"batl":[[0,2.02,7.57],[1,2.04,7.57],[2,2.28,18.48]],"ltp":1.92,"tv":2.52,"id":7444998}]}]}
{"op":"mcm","clk":"1001599233","pt":1580638367196,"mc":[{"id":"1.168224459","rc":[{"batl":[[1,2.28,18.48],[2,2.6,74.21]],"ltp":1.92,"tv":2.52,"id":7444998}]}]}
{"op":"mcm","clk":"1001606607","pt":1580638439664,"mc":[{"id":"1.168224459","rc":[{"batb":[[0,1.93,64.13]],"ltp":1.81,"tv":2.73,"id":5858055}]}]}
{"op":"mcm","clk":"1001704938","pt":1580639395035,"mc":[{"id":"1.168224459","rc":[{"batl":[[0,2.1,15.14],[1,2.28,18.48],[2,95,15.9]],"ltp":1.81,"tv":2.73,"id":5858055}]}]}
{"op":"mcm","clk":"1001715235","pt":1580639482839,"mc":[{"id":"1.168224459","rc":[{"batb":[[0,1.91,44.17]],"ltp":1.92,"tv":2.52,"id":7444998}]}]}
{"op":"mcm","clk":"1001816331","pt":1580640414463,"mc":[{"id":"1.168224459","marketDefinition":{"bspMarket":false,"turnInPlayEnabled":true,"persistenceEnabled":true,"marketBaseRate":5.0,"eventId":"29681747","eventTypeId":"2","numberOfWinners":1,"bettingType":"ODDS","marketType":"MATCH_ODDS","marketTime":"2020-02-02T14:51:00.000Z","suspendTime":"2020-02-02T14:51:00.000Z","bspReconciled":false,"complete":true,"inPlay":false,"crossMatching":true,"runnersVoidable":false,"numberOfActiveRunners":2,"betDelay":0,"status":"OPEN","runners":[{"status":"ACTIVE","sortPriority":1,"id":5858055,"name":"Hiroki Moriya"},{"status":"ACTIVE","sortPriority":2,"id":7444998,"name":"Danilo Petrovic"}],"regulators":["MR_INT"],"countryCode":"FR","discountAllowed":true,"timezone":"UTC","openDate":"2020-02-02T15:24:00.000Z","version":3148438365,"name":"Match Odds","eventName":"Moriya v Petrovic"}}]}
{"op":"mcm","clk":"1001817051","pt":1580640420518,"mc":[{"id":"1.168224459","marketDefinition":{"bspMarket":false,"turnInPlayEnabled":true,"persistenceEnabled":true,"marketBaseRate":5.0,"eventId":"29681747","eventTypeId":"2","numberOfWinners":1,"bettingType":"ODDS","marketType":"MATCH_ODDS","marketTime":"2020-02-02T14:51:00.000Z","suspendTime":"2020-02-02T14:51:00.000Z","bspReconciled":false,"complete":true,"inPlay":false,"crossMatching":true,"runnersVoidable":false,"numberOfActiveRunners":2,"betDelay":0,"status":"OPEN","runners":[{"status":"ACTIVE","sortPriority":1,"id":5858055,"name":"Hiroki Moriya"},{"status":"ACTIVE","sortPriority":2,"id":7444998,"name":"Danilo Petrovic"}],"regulators":["MR_INT"],"countryCode":"FR","discountAllowed":true,"timezone":"UTC","openDate":"2020-02-02T14:51:00.000Z","version":3148438365,"name":"Match Odds","eventName":"Moriya v Petrovic"}}]}
{"op":"mcm","clk":"1001822050","pt":1580640462067,"mc":[{"id":"1.168224459","rc":[{"batb":[[2,1.81,37.86]],"ltp":1.81,"tv":2.73,"id":5858055},{"batb":[[1,1.71,37.86],[2,1.7,68.15]],"ltp":1.92,"tv":2.52,"id":7444998}]}]}
{"op":"mcm","clk":"1001826271","pt":1580640494906,"mc":[{"id":"1.168224459","rc":[{"batb":[[2,1.61,37.86]],"ltp":1.92,"tv":2.52,"id":7444998}]}]}
{"op":"mcm","clk":"1001826342","pt":1580640495529,"mc":[{"id":"1.168224459","rc":[{"batb":[[1,1.76,62.77],[2,1.71,37.86]],"ltp":1.92,"tv":2.52,"id":7444998}]}]}
{"op":"mcm","clk":"1001853042","pt":1580640715174,"mc":[{"id":"1.168224459","marketDefinition":{"bspMarket":false,"turnInPlayEnabled":true,"persistenceEnabled":true,"marketBaseRate":5.0,"eventId":"29681747","eventTypeId":"2","numberOfWinners":1,"bettingType":"ODDS","marketType":"MATCH_ODDS","marketTime":"2020-02-02T14:48:00.000Z","suspendTime":"2020-02-02T14:48:00.000Z","bspReconciled":false,"complete":true,"inPlay":false,"crossMatching":true,"runnersVoidable":false,"numberOfActiveRunners":2,"betDelay":0,"status":"OPEN","runners":[{"status":"ACTIVE","sortPriority":1,"id":5858055,"name":"Hiroki Moriya"},{"status":"ACTIVE","sortPriority":2,"id":7444998,"name":"Danilo Petrovic"}],"regulators":["MR_INT"],"countryCode":"FR","discountAllowed":true,"timezone":"UTC","openDate":"2020-02-02T14:51:00.000Z","version":3148443821,"name":"Match Odds","eventName":"Moriya v Petrovic"}}]}
{"op":"mcm","clk":"1001853415","pt":1580640718147,"mc":[{"id":"1.168224459","marketDefinition":{"bspMarket":false,"turnInPlayEnabled":true,"persistenceEnabled":true,"marketBaseRate":5.0,"eventId":"29681747","eventTypeId":"2","numberOfWinners":1,"bettingType":"ODDS","marketType":"MATCH_ODDS","marketTime":"2020-02-02T14:48:00.000Z","suspendTime":"2020-02-02T14:48:00.000Z","bspReconciled":false,"complete":true,"inPlay":false,"crossMatching":true,"runnersVoidable":false,"numberOfActiveRunners":2,"betDelay":0,"status":"OPEN","runners":[{"status":"ACTIVE","sortPriority":1,"id":5858055,"name":"Hiroki Moriya"},{"status":"ACTIVE","sortPriority":2,"id":7444998,"name":"Danilo Petrovic"}],"regulators":["MR_INT"],"countryCode":"FR","discountAllowed":true,"timezone":"UTC","openDate":"2020-02-02T14:48:00.000Z","version":3148443821,"name":"Match Odds","eventName":"Moriya v Petrovic"}}]}
{"op":"mcm","clk":"1001862196","pt":1580640795955,"mc":[{"id":"1.168224459","rc":[{"trd":[[1.91,4]],"batb":[[0,1.91,42.17]],"ltp":1.91,"tv":6.52,"id":7444998}],"tv":9.25}]}
{"op":"mcm","clk":"1001862306","pt":1580640797153,"mc":[{"id":"1.168224459","rc":[{"batb":[[0,1.94,58.93]],"ltp":1.81,"tv":2.73,"id":5858055}]}]}
{"op":"mcm","clk":"1001878296","pt":1580640945242,"mc":[{"id":"1.168224459","rc":[{"batb":[[1,1.78,109.7]],"ltp":1.91,"tv":6.52,"id":7444998}]}]}
{"op":"mcm","clk":"1001921451","pt":1580641272732,"mc":[{"id":"1.168224459","rc":[{"batb":[[1,1.82,49.98],[2,1.78,109.7]],"ltp":1.91,"tv":6.52,"id":7444998}]}]}
{"op":"mcm","clk":"1001934446","pt":1580641353052,"mc":[{"id":"1.168224459","rc":[{"batl":[[0,2.02,15.14]],"ltp":1.91,"tv":6.52,"id":7444998}]}]}
{"op":"mcm","clk":"1001934820","pt":1580641355332,"mc":[{"id":"1.168224459","rc":[{"batl":[[0,2.28,18.48],[1,2.6,74.21],[2,95,15.9]],"ltp":1.91,"tv":6.52,"id":7444998}]}]}
{"op":"mcm","clk":"1001936795","pt":1580641367227,"mc":[{"id":"1.168224459","rc":[{"batb":[[0,1.91,42.25]],"ltp":1.91,"tv":6.52,"id":7444998}]}]}
{"op":"mcm","clk":"1001937416","pt":1580641370931,"mc":[{"id":"1.168224459","rc":[{"batb":[[0,1.93,7.57],[1,1.91,42.25],[2,1.82,49.98]],"ltp":1.91,"tv":6.52,"id":7444998}]}]}
{"op":"mcm","clk":"1001937655","pt":1580641372475,"mc":[{"id":"1.168224459","rc":[{"batb":[[0,1.91,42.25],[1,1.82,49.98],[2,1.81,37.86]],"ltp":1.91,"tv":6.52,"id":7444998}]}]}
{"op":"mcm","clk":"1001966062","pt":1580641526968,"mc":[{"id":"1.168224459","rc":[{"batb":[[0,1.92,7.65],[1,1.91,42.17],[2,1.82,49.98]],"ltp":1.91,"tv":6.52,"id":7444998}]}]}
{"op":"mcm","clk":"1001966567","pt":1580641529049,"mc":[{"id":"1.168224459","rc":[{"batb":[[0,1.91,42.25],[1,1.82,49.98],[2,1.81,37.86]],"ltp":1.91,"tv":6.52,"id":7444998}]}]}
{"op":"mcm","clk":"1001992010","pt":1580641666632,"mc":[{"id":"1.168224459","rc":[{"batb":[[0,1.94,59.01]],"ltp":1.81,"tv":2.73,"id":5858055}]}]}
{"op":"mcm","clk":"1002068371","pt":1580642098363,"mc":[{"id":"1.168224459","rc":[{"batb":[[1,1.81,37.86],[2,1.78,109.7]],"ltp":1.91,"tv":6.52,"id":7444998}]}]}
{"op":"mcm","clk":"1002097134","pt":1580642266521,"mc":[{"id":"1.168224459","rc":[{"batb":[[1,1.82,49.98],[2,1.81,37.86]],"ltp":1.91,"tv":6.52,"id":7444998}]}]}
{"op":"mcm","clk":"1002142045","pt":1580642507439,"mc":[{"id":"1.168224459","rc":[{"batl":[[2,4.2,153.72]],"ltp":1.81,"tv":2.73,"id":5858055},{"batl":[[2,4.2,153.72]],"ltp":1.91,"tv":6.52,"id":7444998}]}]}
{"op":"mcm","clk":"1002187719","pt":1580642769312,"mc":[{"id":"1.168224459","rc":[{"batb":[[2,1.81,183.7]],"ltp":1.91,"tv":6.52,"id":7444998}]}]}
{"op":"mcm","clk":"1002194311","pt":1580642804365,"mc":[{"id":"1.168224459","rc":[{"batl":[[2,4,3.03]],"ltp":1.91,"tv":6.52,"id":7444998}]}]}
{"op":"mcm","clk":"1002195634","pt":1580642810801,"mc":[{"id":"1.168224459","rc":[{"batl":[[2,4,3.48]],"ltp":1.91,"tv":6.52,"id":7444998}]}]}
{"op":"mcm","clk":"1002206612","pt":1580642865436,"mc":[{"id":"1.168224459","rc":[{"batl":[[2,4.2,153.72]],"ltp":1.91,"tv":6.52,"id":7444998}]}]}
{"op":"mcm","clk":"1002206639","pt":1580642865555,"mc":[{"id":"1.168224459","rc":[{"batl":[[0,2.28,18.94]],"ltp":1.91,"tv":6.52,"id":7444998}]}]}
{"op":"mcm","clk":"1002268781","pt":1580643195332,"mc":[{"id":"1.168224459","rc":[{"batl":[[0,2,2],[1,2.28,18.94],[2,2.6,74.21]],"ltp":1.91,"tv":6.52,"id":7444998}]}]}
{"op":"mcm","clk":"1002493615","pt":1580644595285,"mc":[{"id":"1.168224459","rc":[{"batb":[[2,1.81,260.36]],"ltp":1.91,"tv":6.52,"id":7444998}]}]}
{"op":"mcm","clk":"1002676122","pt":1580645813890,"mc":[{"id":"1.168224459","marketDefinition":{"bspMarket":false,"turnInPlayEnabled":true,"persistenceEnabled":true,"marketBaseRate":5.0,"eventId":"29681747","eventTypeId":"2","numberOfWinners":1,"bettingType":"ODDS","marketType":"MATCH_ODDS","marketTime":"2020-02-02T14:16:00.000Z","suspendTime":"2020-02-02T14:16:00.000Z","bspReconciled":false,"complete":true,"inPlay":false,"crossMatching":true,"runnersVoidable":false,"numberOfActiveRunners":2,"betDelay":0,"status":"OPEN","runners":[{"status":"ACTIVE","sortPriority":1,"id":5858055,"name":"Hiroki Moriya"},{"status":"ACTIVE","sortPriority":2,"id":7444998,"name":"Danilo Petrovic"}],"regulators":["MR_INT"],"countryCode":"FR","discountAllowed":true,"timezone":"UTC","openDate":"2020-02-02T14:48:00.000Z","version":3148684761,"name":"Match Odds","eventName":"Moriya v Petrovic"}}]}
{"op":"mcm","clk":"1002676782","pt":1580645817903,"mc":[{"id":"1.168224459","marketDefinition":{"bspMarket":false,"turnInPlayEnabled":true,"persistenceEnabled":true,"marketBaseRate":5.0,"eventId":"29681747","eventTypeId":"2","numberOfWinners":1,"bettingType":"ODDS","marketType":"MATCH_ODDS","marketTime":"2020-02-02T14:16:00.000Z","suspendTime":"2020-02-02T14:16:00.000Z","bspReconciled":false,"complete":true,"inPlay":false,"crossMatching":true,"runnersVoidable":false,"numberOfActiveRunners":2,"betDelay":0,"status":"OPEN","runners":[{"status":"ACTIVE","sortPriority":1,"id":5858055,"name":"Hiroki Moriya"},{"status":"ACTIVE","sortPriority":2,"id":7444998,"name":"Danilo Petrovic"}],"regulators":["MR_INT"],"countryCode":"FR","discountAllowed":true,"timezone":"UTC","openDate":"2020-02-02T14:16:00.000Z","version":3148684761,"name":"Match Odds","eventName":"Moriya v Petrovic"}}]}
{"op":"mcm","clk":"1002685937","pt":1580645875432,"mc":[{"id":"1.168224459","rc":[{"batb":[[1,1.81,260.36],[2,1.71,37.86]],"ltp":1.91,"tv":6.52,"id":7444998}]}]}
{"op":"mcm","clk":"1002689796","pt":1580645900666,"mc":[{"id":"1.168224459","rc":[{"batb":[[1,1.82,49.98],[2,1.81,260.36]],"ltp":1.91,"tv":6.52,"id":7444998}]}]}
{"op":"mcm","clk":"1002770090","pt":1580646420999,"mc":[{"id":"1.168224459","rc":[{"batb":[[2,1.81,37.86]],"ltp":1.91,"tv":6.52,"id":7444998}]}]}
{"op":"mcm","clk":"1002770199","pt":1580646421716,"mc":[{"id":"1.168224459","rc":[{"batb":[[2,1.81,260.36]],"ltp":1.81,"tv":2.73,"id":5858055},{"batb":[[1,1.82,269.76]],"ltp":1.91,"tv":6.52,"id":7444998}]}]}
{"op":"mcm","clk":"1002772068","pt":1580646432334,"mc":[{"id":"1.168224459","rc":[{"batb":[[2,1.81,311.09]],"ltp":1.81,"tv":2.73,"id":5858055},{"batb":[[1,1.83,49.98],[2,1.82,219.78]],"ltp":1.91,"tv":6.52,"id":7444998}]}]}
{"op":"mcm","clk":"1002812099","pt":1580646672218,"mc":[{"id":"1.168224459","rc":[{"batb":[[0,1.94,117.95]],"ltp":1.81,"tv":2.73,"id":5858055},{"batb":[[0,1.91,84.47]],"ltp":1.91,"tv":6.52,"id":7444998}]}]}
{"op":"mcm","clk":"1002814556","pt":1580646686364,"mc":[{"id":"1.168224459","rc":[{"batb":[[2,1.81,88.6]],"ltp":1.81,"tv":2.73,"id":5858055},{"batb":[[2,1.81,37.86]],"ltp":1.91,"tv":6.52,"id":7444998}]}]}
{"op":"mcm","clk":"1002814678","pt":1580646687033,"mc":[{"id":"1.168224459","rc":[{"batb":[[2,1.82,219.78]],"ltp":1.81,"tv":2.73,"id":5858055},{"batb":[[2,1.81,260.36]],"ltp":1.91,"tv":6.52,"id":7444998}]}]}
{"op":"mcm","clk":"1002814941","pt":1580646688433,"mc":[{"id":"1.168224459","rc":[{"batb":[[1,1.81,260.36],[2,1.71,37.86]],"ltp":1.91,"tv":6.52,"id":7444998}]}]}
{"op":"mcm","clk":"1002814963","pt":1580646688538,"mc":[{"id":"1.168224459","rc":[{"batb":[[2,1.85,50.73]],"ltp":1.81,"tv":2.73,"id":5858055},{"batb":[[1,1.83,49.98],[2,1.81,260.36]],"ltp":1.91,"tv":6.52,"id":7444998}]}]}
{"op":"mcm","clk":"1002817026","pt":1580646700133,"mc":[{"id":"1.168224459","rc":[{"batb":[[2,1.83,50.73]],"ltp":1.81,"tv":2.73,"id":5858055},{"batb":[[1,1.81,310.34],[2,1.71,37.86]],"ltp":1.91,"tv":6.52,"id":7444998}]}]}
{"op":"mcm","clk":"1002854611","pt":1580646893376,"mc":[{"id":"1.168224459","rc":[{"batb":[[2,1.83,267.87]],"ltp":1.81,"tv":2.73,"id":5858055},{"batb":[[1,1.81,87.84],[2,1.8,225.28]],"ltp":1.91,"tv":6.52,"id":7444998}]}]}
{"op":"mcm","clk":"1002856161","pt":1580646901697,"mc":[{"id":"1.168224459","rc":[{"batb":[[1,1.81,37.86],[2,1.8,275.25]],"ltp":1.91,"tv":6.52,"id":7444998}]}]}
{"op":"mcm","clk":"1002891413","pt":1580647077437,"mc":[{"id":"1.168224459","rc":[{"batb":[[0,1.95,5.86],[1,1.94,117.87],[2,1.9,2.53]],"ltp":1.81,"tv":2.73,"id":5858055}]}]}
{"op":"mcm","clk":"1002891518","pt":1580647077920,"mc":[{"id":"1.168224459","rc":[{"batb":[[0,1.92,6.88],[1,1.91,84.4],[2,1.81,37.86]],"ltp":1.91,"tv":6.52,"id":7444998}]}]}
{"op":"mcm","clk":"1002917514","pt":1580647203424,"mc":[{"id":"1.168224459","rc":[{"batb":[[0,1.96,90.12],[1,1.95,5.86]],"ltp":1.81,"tv":2.73,"id":5858055},{"batb":[[0,1.93,55.49],[1,1.92,6.88]],"ltp":1.91,"tv":6.52,"id":7444998}]}]}
{"op":"mcm","clk":"1002937824","pt":1580647301157,"mc":[{"id":"1.168224459","rc":[{"batb":[[1,1.95,5.79]],"ltp":1.81,"tv":2.73,"id":5858055},{"batb":[[1,1.92,6.81]],"ltp":1.91,"tv":6.52,"id":7444998}]}]}
{"op":"mcm","clk":"1002950004","pt":1580647361367,"mc":[{"id":"1.168224459","rc":[{"batb":[[0,1.96,90.2]],"ltp":1.81,"tv":2.73,"id":5858055}]}]}
{"op":"mcm","clk":"1003011133","pt":1580647661116,"mc":[{"id":"1.168224459","rc":[{"batb":[[0,1.93,55.56]],"ltp":1.91,"tv":6.52,"id":7444998}]}]}
{"op":"mcm","clk":"1003047715","pt":1580647857877,"mc":[{"id":"1.168224459","rc":[{"batl":[[0,1.99,7.57],[1,2,2],[2,2.28,18.94]],"ltp":1.91,"tv":6.52,"id":7444998}]}]}
{"op":"mcm","clk":"1003051356","pt":1580647878924,"mc":[{"id":"1.168224459","rc":[{"batl":[[0,1.99,15.14]],"ltp":1.91,"tv":6.52,"id":7444998}]}]}
{"op":"mcm","clk":"1003051613","pt":1580647880430,"mc":[{"id":"1.168224459","rc":[{"batl":[[0,2,2],[1,2.28,18.94],[2,2.6,74.21]],"ltp":1.91,"tv":6.52,"id":7444998}]}]}
{"op":"mcm","clk":"1003112094","pt":1580648242191,"mc":[{"id":"1.168224459","rc":[{"batb":[[2,1.81,330.47]],"ltp":1.91,"tv":6.52,"id":7444998}]}]}
{"op":"mcm","clk":"1003258554","pt":1580649053944,"mc":[{"id":"1.168224459","rc":[{"batl":[[0,2.06,15.14]],"ltp":1.81,"tv":2.73,"id":5858055}]}]}
{"op":"mcm","clk":"1003299849","pt":1580649271972,"mc":[{"id":"1.168224459","rc":[{"trd":[[2.06,15.14]],"batl":[[0,2.28,18.48],[1,4.2,153.72],[2,95,15.9]],"ltp":2.06,"tv":17.88,"id":5858055},{"trd":[[1.94,16.23]],"batb":[[0,1.93,55.49]],"batl":[[0,1.94,25.85],[1,2,2],[2,2.28,18.94]],"ltp":1.94,"tv":22.75,"id":7444998}],"tv":40.63}]}
{"op":"mcm","clk":"1003316406","pt":1580649365718,"mc":[{"id":"1.168224459","rc":[{"batb":[[0,1.98,25.72],[1,1.96,90.2],[2,1.95,5.79]],"ltp":2.06,"tv":17.88,"id":5858055},{"batb":[[2,1.86,29.31]],"ltp":1.94,"tv":22.75,"id":7444998}]}]}
{"op":"mcm","clk":"1003317576","pt":1580649372085,"mc":[{"id":"1.168224459","rc":[{"trd":[[1.93,6]],"batb":[[0,1.93,52.49]],"ltp":1.93,"tv":28.75,"id":7444998}],"tv":46.63}]}
{"op":"mcm","clk":"1003317733","pt":1580649372950,"mc":[{"id":"1.168224459","rc":[{"batb":[[0,1.99,78.06],[1,1.98,25.72],[2,1.95,5.86]],"ltp":2.06,"tv":17.88,"id":5858055},{"trd":[[1.94,67.94]],"batb":[[0,1.92,6.81],[1,1.87,116.35]],"batl":[[0,2,2],[1,2.28,18.94],[2,2.6,74.21]],"ltp":1.94,"tv":80.45,"id":7444998}],"tv":98.33}]}
{"op":"mcm","clk":"1003317871","pt":1580649373750,"mc":[{"id":"1.168224459","rc":[{"batb":[[1,1.87,145.32]],"ltp":1.94,"tv":80.45,"id":7444998}]}]}
{"op":"mcm","clk":"1003322672","pt":1580649399006,"mc":[{"id":"1.168224459","rc":[{"batb":[[2,1.95,5.79]],"ltp":2.06,"tv":17.88,"id":5858055}]}]}
{"op":"mcm","clk":"1003333402","pt":1580649459372,"mc":[{"id":"1.168224459","rc":[{"batb":[[0,1.99,78.14]],"ltp":2.06,"tv":17.88,"id":5858055}]}]}
{"op":"mcm","clk":"1003397957","pt":1580649858417,"mc":[{"id":"1.168224459","rc":[{"batb":[[2,1.9,2.53]],"ltp":2.06,"tv":17.88,"id":5858055},{"batb":[[0,1.87,145.32],[1,1.86,29.31],[2,1.81,37.86]],"ltp":1.94,"tv":80.45,"id":7444998}]}]}
{"op":"mcm","clk":"1003408886","pt":1580649923642,"mc":[{"id":"1.168224459","rc":[{"batb":[[0,1.89,7.57],[1,1.87,145.32],[2,1.86,29.31]],"ltp":1.94,"tv":80.45,"id":7444998}]}]}
{"op":"mcm","clk":"1003409276","pt":1580649926071,"mc":[{"id":"1.168224459","rc":[{"batb":[[0,1.87,145.32],[1,1.86,29.31],[2,1.81,37.86]],"ltp":1.94,"tv":80.45,"id":7444998}]}]}
{"op":"mcm","clk":"1003424070","pt":1580650021141,"mc":[{"id":"1.168224459","rc":[{"trd":[[2,2.16]],"batb":[[0,1.99,78.06]],"batl":[[0,2,12.17],[1,2.28,18.48],[2,4.2,153.72]],"ltp":2.0,"tv":20.03,"id":5858055},{"trd":[[2,2]],"batl":[[0,2.28,18.94],[1,2.6,74.21],[2,4.2,153.72]],"ltp":2.0,"tv":82.45,"id":7444998}],"tv":102.49}]}
{"op":"mcm","clk":"1003424204","pt":1580650021959,"mc":[{"id":"1.168224459","rc":[{"batb":[[1,1.93,27.1]],"ltp":2.0,"tv":20.03,"id":5858055}]}]}
{"op":"mcm","clk":"1003425685","pt":1580650031317,"mc":[{"id":"1.168224459","rc":[{"trd":[[2,9.73]],"batl":[[0,2,4.6]],"ltp":2.0,"tv":27.6,"id":5858055},{"trd":[[2,9.57]],"ltp":2.0,"tv":90.02,"id":7444998}],"tv":117.63}]}
{"op":"mcm","clk":"1003425867","pt":1580650032379,"mc":[{"id":"1.168224459","rc":[{"trd":[[2,14.33]],"batl":[[0,2.28,18.48],[1,4.2,153.72],[2,95,15.9]],"ltp":2.0,"tv":32.2,"id":5858055},{"trd":[[1.99,15.22],[2,14.17]],"batb":[[0,1.99,4.62],[1,1.87,145.32],[2,1.86,29.31]],"batl":[[0,2,2.98],[1,2.28,18.94],[2,2.6,74.21]],"ltp":1.99,"tv":109.84,"id":7444998}],"tv":142.05}]}
{"op":"mcm","clk":"1003425955","pt":1580650033004,"mc":[{"id":"1.168224459","rc":[{"batb":[[1,1.98,25.72],[2,1.93,27.1]],"ltp":2.0,"tv":32.2,"id":5858055},{"trd":[[1.99,24.46]],"batb":[[0,1.87,145.32],[1,1.86,29.31],[2,1.81,37.86]],"ltp":1.99,"tv":119.08,"id":7444998}],"tv":151.29}]}
{"op":"mcm","clk":"1003426430","pt":1580650035984,"mc":[{"id":"1.168224459","rc":[{"batl":[[0,2,10.55]],"ltp":1.99,"tv":119.08,"id":7444998}]}]}
{"op":"mcm","clk":"1003427214","pt":1580650041293,"mc":[{"id":"1.168224459","rc":[{"batl":[[0,2,18.12]],"ltp":1.99,"tv":119.08,"id":7444998}]}]}
{"op":"mcm","clk":"1003427333","pt":1580650042124,"mc":[{"id":"1.168224459","rc":[{"batb":[[0,1.87,116.35]],"ltp":1.99,"tv":119.08,"id":7444998}]}]}
{"op":"mcm","clk":"1003427494","pt":1580650043298,"mc":[{"id":"1.168224459","rc":[{"batl":[[0,2.28,18.94],[1,2.6,74.21],[2,4.2,153.72]],"ltp":1.99,"tv":119.08,"id":7444998}]}]}
{"op":"mcm","clk":"1003427650","pt":1580650044404,"mc":[{"id":"1.168224459","rc":[{"batb":[[0,1.87,145.32]],"batl":[[0,2,7.57],[1,2.28,18.94],[2,2.6,74.21]],"ltp":1.99,"tv":119.08,"id":7444998}]}]}
{"op":"mcm","clk":"1003438099","pt":1580650113123,"mc":[{"id":"1.168224459","rc":[{"batb":[[0,2.02,1.25],[1,1.99,78.06],[2,1.98,25.72]],"ltp":2.0,"tv":32.2,"id":5858055},{"batb":[[0,1.88,1.34],[1,1.87,145.32],[2,1.86,29.31]],"ltp":1.99,"tv":119.08,"id":7444998}]}]}
{"op":"mcm","clk":"1003439086","pt":1580650119642,"mc":[{"id":"1.168224459","rc":[{"batl":[[0,1.99,7.57],[1,2,7.57],[2,2.28,18.94]],"ltp":1.99,"tv":119.08,"id":7444998}]}]}
{"op":"mcm","clk":"1003439414","pt":1580650121726,"mc":[{"id":"1.168224459","rc":[{"batl":[[1,2.28,18.94],[2,2.6,74.21]],"ltp":1.99,"tv":119.08,"id":7444998}]}]}
{"op":"mcm","clk":"1003439794","pt":1580650124322,"mc":[{"id":"1.168224459","rc":[{"batl":[[0,2.28,18.94],[1,2.6,74.21],[2,4.2,153.72]],"ltp":1.99,"tv":119.08,"id":7444998}]}]}
{"op":"mcm","clk":"1003446923","pt":1580650170801,"mc":[{"id":"1.168224459","rc":[{"batl":[[0,1.98,7.57],[1,2.28,18.94],[2,2.6,74.21]],"ltp":1.99,"tv":119.08,"id":7444998}]}]}
{"op":"mcm","clk":"1003447395","pt":1580650173624,"mc":[{"id":"1.168224459","rc":[{"batl":[[0,1.99,7.57]],"ltp":1.99,"tv":119.08,"id":7444998}]}]}
{"op":"mcm","clk":"1003449136","pt":1580650185508,"mc":[{"id":"1.168224459","rc":[{"batl":[[0,2.28,18.94],[1,2.6,74.21],[2,4.2,153.72]],"ltp":1.99,"tv":119.08,"id":7444998}]}]}
{"op":"mcm","clk":"1003449297","pt":1580650186632,"mc":[{"id":"1.168224459","rc":[{"batl":[[0,1.99,7.57],[1,2.28,18.94],[2,2.6,74.21]],"ltp":1.99,"tv":119.08,"id":7444998}]}]}
{"op":"mcm","clk":"1003449661","pt":1580650188829,"mc":[{"id":"1.168224459","rc":[{"batl":[[0,1.99,15.14]],"ltp":1.99,"tv":119.08,"id":7444998}]}]}
{"op":"mcm","clk":"1003451395","pt":1580650199749,"mc":[{"id":"1.168224459","rc":[{"batl":[[0,2.28,18.94],[1,2.6,74.21],[2,4.2,153.72]],"ltp":1.99,"tv":119.08,"id":7444998}]}]}
{"op":"mcm","clk":"1003473396","pt":1580650337949,"mc":[{"id":"1.168224459","rc":[{"batl":[[0,1.99,7.57],[1,2.28,18.94],[2,2.6,74.21]],"ltp":1.99,"tv":119.08,"id":7444998}]}]}
{"op":"mcm","clk":"1003473726","pt":1580650340259,"mc":[{"id":"1.168224459","rc":[{"batl":[[0,2.28,18.94],[1,2.6,74.21],[2,4.2,153.72]],"ltp":1.99,"tv":119.08,"id":7444998}]}]}
{"op":"mcm","clk":"1003480145","pt":1580650381396,"mc":[{"id":"1.168224459","rc":[{"trd":[[1.87,0.67],[1.88,2.69]],"batb":[[0,1.87,144.98],[1,1.86,29.31],[2,1.81,37.86]],"ltp":1.87,"tv":122.44,"id":7444998}],"tv":154.65}]}
{"op":"mcm","clk":"1003481539","pt":1580650389888,"mc":[{"id":"1.168224459","rc":[{"trd":[[1.87,36.04]],"batb":[[0,1.87,127.3]],"ltp":1.87,"tv":157.81,"id":7444998}],"tv":190.01}]}
{"op":"mcm","clk":"1003481633","pt":1580650390473,"mc":[{"id":"1.168224459","rc":[{"batb":[[1,1.99,94.71]],"ltp":2.0,"tv":32.2,"id":5858055}]}]}
{"op":"mcm","clk":"1003484542","pt":1580650408230,"mc":[{"id":"1.168224459","rc":[{"batb":[[0,1.88,7.57],[1,1.87,127.3],[2,1.86,29.31]],"ltp":1.87,"tv":157.81,"id":7444998}]}]}
{"op":"mcm","clk":"1003486169","pt":1580650417068,"mc":[{"id":"1.168224459","rc":[{"batb":[[0,1.88,15.14]],"ltp":1.87,"tv":157.81,"id":7444998}]}]}
{"op":"mcm","clk":"1003486512","pt":1580650418947,"mc":[{"id":"1.168224459","rc":[{"batb":[[0,1.87,127.3],[1,1.86,29.31],[2,1.81,37.86]],"ltp":1.87,"tv":157.81,"id":7444998}]}]}
{"op":"mcm","clk":"1003486586","pt":1580650419474,"mc":[{"id":"1.168224459","rc":[{"batb":[[0,1.88,7.57],[1,1.87,127.3],[2,1.86,29.31]],"ltp":1.87,"tv":157.81,"id":7444998}]}]}
{"op":"mcm","clk":"1003491933","pt":1580650448595,"mc":[{"id":"1.168224459","rc":[{"batb":[[0,1.88,15.14]],"ltp":1.87,"tv":157.81,"id":7444998}]}]}
{"op":"mcm","clk":"1003492247","pt":1580650450448,"mc":[{"id":"1.168224459","rc":[{"batb":[[0,1.87,127.3],[1,1.86,29.31],[2,1.81,37.86]],"ltp":1.87,"tv":157.81,"id":7444998}]}]}
{"op":"mcm","clk":"1003492680","pt":1580650452946,"mc":[{"id":"1.168224459","rc":[{"batl":[[0,1.99,7.57],[1,2.28,18.94],[2,2.6,74.21]],"ltp":1.87,"tv":157.81,"id":7444998}]}]}
{"op":"mcm","clk":"1003501719","pt":1580650502335,"mc":[{"id":"1.168224459","rc":[{"batb":[[1,1.98,25.72],[2,1.93,27.1]],"ltp":2.0,"tv":32.2,"id":5858055}]}]}
{"op":"mcm","clk":"1003501750","pt":1580650502499,"mc":[{"id":"1.168224459","rc":[{"batb":[[0,2.02,57.86]],"ltp":2.0,"tv":32.2,"id":5858055}]}]}
{"op":"mcm","clk":"1003501942","pt":1580650503491,"mc":[{"id":"1.168224459","rc":[{"batb":[[1,2,25.21],[2,1.98,25.72]],"ltp":2.0,"tv":32.2,"id":5858055},{"batb":[[0,1.87,98.33],[1,1.85,29.65]],"ltp":1.87,"tv":157.81,"id":7444998}]}]}
{"op":"mcm","clk":"1003502365","pt":1580650506014,"mc":[{"id":"1.168224459","rc":[{"batb":[[0,1.88,7.57],[1,1.87,98.33],[2,1.85,29.65]],"ltp":1.87,"tv":157.81,"id":7444998}]}]}
{"op":"mcm","clk":"1003503000","pt":1580650509022,"mc":[{"id":"1.168224459","rc":[{"batb":[[0,1.87,98.33],[1,1.85,29.65],[2,1.81,37.86]],"ltp":1.87,"tv":157.81,"id":7444998}]}]}
{"op":"mcm","clk":"1003528380","pt":1580650641777,"mc":[{"id":"1.168224459","rc":[{"batb":[[0,1.86,114.58]],"ltp":1.87,"tv":157.81,"id":7444998}]}]}
{"op":"mcm","clk":"1003528990","pt":1580650645068,"mc":[{"id":"1.168224459","rc":[{"batb":[[0,1.86,550.76]],"ltp":1.87,"tv":157.81,"id":7444998}]}]}
{"op":"mcm","clk":"1003540950","pt":1580650712168,"mc":[{"id":"1.168224459","rc":[{"batb":[[0,1.87,7.57],[1,1.86,550.76],[2,1.85,29.65]],"ltp":1.87,"tv":157.81,"id":7444998}]}]}
{"op":"mcm","clk":"1003541132","pt":1580650713079,"mc":[{"id":"1.168224459","rc":[{"batb":[[1,1.86,114.58]],"ltp":1.87,"tv":157.81,"id":7444998}]}]}
{"op":"mcm","clk":"1003554573","pt":1580650788407,"mc":[{"id":"1.168224459","rc":[{"batb":[[1,1.85,29.65],[2,1.81,37.86]],"ltp":1.87,"tv":157.81,"id":7444998}]}]}
{"op":"mcm","clk":"1003554589","pt":1580650788500,"mc":[{"id":"1.168224459","rc":[{"batb":[[0,1.88,83.05],[1,1.87,7.57],[2,1.85,29.65]],"ltp":1.87,"tv":157.81,"id":7444998}]}]}
{"op":"mcm","clk":"1003554795","pt":1580650789792,"mc":[{"id":"1.168224459","rc":[{"batb":[[1,1.99,25.46]],"ltp":2.0,"tv":32.2,"id":5858055},{"batb":[[1,1.87,15.14],[2,1.86,29.31]],"ltp":1.87,"tv":157.81,"id":7444998}]}]}
{"op":"mcm","clk":"1003555018","pt":1580650791089,"mc":[{"id":"1.168224459","rc":[{"batb":[[1,1.86,29.31],[2,1.85,29.65]],"ltp":1.87,"tv":157.81,"id":7444998}]}]}
{"op":"mcm","clk":"1003577118","pt":1580650914354,"mc":[{"id":"1.168224459","rc":[{"batl":[[0,2.28,18.94],[1,2.6,74.21],[2,4.2,153.72]],"ltp":1.87,"tv":157.81,"id":7444998}]}]}
{"op":"mcm","clk":"1003577555","pt":1580650916754,"mc":[{"id":"1.168224459","rc":[{"batb":[[0,1.88,508.51]],"ltp":1.87,"tv":157.81,"id":7444998}]}]}
{"op":"mcm","clk":"1003578620","pt":1580650922356,"mc":[{"id":"1.168224459","rc":[{"batb":[[0,2.02,1.25]],"ltp":2.0,"tv":32.2,"id":5858055}]}]}
{"op":"mcm","clk":"1003578655","pt":1580650922552,"mc":[{"id":"1.168224459","rc":[{"batb":[[1,2,81.78],[2,1.99,25.46]],"ltp":2.0,"tv":32.2,"id":5858055}]}]}
{"op":"mcm","clk":"1003581135","pt":1580650934200,"mc":[{"id":"1.168224459","rc":[{"batl":[[0,1.98,7.57],[1,2.28,18.94],[2,2.6,74.21]],"ltp":1.87,"tv":157.81,"id":7444998}]}]}
{"op":"mcm","clk":"1003581636","pt":1580650936690,"mc":[{"id":"1.168224459","rc":[{"batl":[[0,2.28,18.94],[1,2.6,74.21],[2,4.2,153.72]],"ltp":1.87,"tv":157.81,"id":7444998}]}]}
{"op":"mcm","clk":"1003583945","pt":1580650948009,"mc":[{"id":"1.168224459","rc":[{"batb":[[2,1.98,25.72]],"ltp":2.0,"tv":32.2,"id":5858055},{"batb":[[1,1.87,28.97],[2,1.86,29.31]],"ltp":1.87,"tv":157.81,"id":7444998}]}]}
{"op":"mcm","clk":"1003584591","pt":1580650951305,"mc":[{"id":"1.168224459","rc":[{"batb":[[0,1.89,7.57],[1,1.88,508.51],[2,1.87,28.97]],"ltp":1.87,"tv":157.81,"id":7444998}]}]}
{"op":"mcm","clk":"1003584718","pt":1580650951908,"mc":[{"id":"1.168224459","rc":[{"batb":[[1,1.88,83.05]],"ltp":1.87,"tv":157.81,"id":7444998}]}]}
{"op":"mcm","clk":"1003585037","pt":1580650953517,"mc":[{"id":"1.168224459","rc":[{"batb":[[0,1.88,83.05],[1,1.87,28.97],[2,1.86,29.31]],"ltp":1.87,"tv":157.81,"id":7444998}]}]}
{"op":"mcm","clk":"1003593793","pt":1580650998264,"mc":[{"id":"1.168224459","rc":[{"batl":[[0,1.99,7.57],[1,2.28,18.94],[2,2.6,74.21]],"ltp":1.87,"tv":157.81,"id":7444998}]}]}
{"op":"mcm","clk":"1003593876","pt":1580650998684,"mc":[{"id":"1.168224459","rc":[{"batb":[[0,1.88,508.51]],"ltp":1.87,"tv":157.81,"id":7444998}]}]}
{"op":"mcm","clk":"1003594146","pt":1580651000084,"mc":[{"id":"1.168224459","rc":[{"batl":[[0,2.28,18.94],[1,2.6,74.21],[2,4.2,153.72]],"ltp":1.87,"tv":157.81,"id":7444998}]}]}
{"op":"mcm","clk":"1003597246","pt":1580651015785,"mc":[{"id":"1.168224459","rc":[{"batb":[[0,1.89,7.57],[1,1.88,508.51],[2,1.87,28.97]],"ltp":1.87,"tv":157.81,"id":7444998}]}]}
{"op":"mcm","clk":"1003605510","pt":1580651057339,"mc":[{"id":"1.168224459","rc":[{"batb":[[1,1.99,94.71]],"ltp":2.0,"tv":32.2,"id":5858055},{"batb":[[1,1.88,83.05]],"ltp":1.87,"tv":157.81,"id":7444998}]}]}
{"op":"mcm","clk":"1003621326","pt":1580651138171,"mc":[{"id":"1.168224459","rc":[{"batb":[[2,1.97,25.99]],"ltp":2.0,"tv":32.2,"id":5858055}]}]}
{"op":"mcm","clk":"1003629115","pt":1580651178441,"mc":[{"id":"1.168224459","rc":[{"batb":[[0,1.89,15.14]],"ltp":1.87,"tv":157.81,"id":7444998}]}]}
{"op":"mcm","clk":"1003629571","pt":1580651180536,"mc":[{"id":"1.168224459","rc":[{"batb":[[0,1.88,83.05],[1,1.87,28.97],[2,1.86,29.31]],"ltp":1.87,"tv":157.81,"id":7444998}]}]}
{"op":"mcm","clk":"1003632219","pt":1580651193280,"mc":[{"id":"1.168224459","rc":[{"batb":[[1,1.97,25.99],[2,1.93,27.1]],"ltp":2.0,"tv":32.2,"id":5858055}]}]}
{"op":"mcm","clk":"1003632300","pt":1580651193651,"mc":[{"id":"1.168224459","rc":[{"batb":[[1,1.98,107.86],[2,1.9,2.53]],"ltp":2.0,"tv":32.2,"id":5858055},{"batb":[[0,1.88,537.16]],"ltp":1.87,"tv":157.81,"id":7444998}]}]}
{"op":"mcm","clk":"1003632479","pt":1580651194573,"mc":[{"id":"1.168224459","rc":[{"batb":[[2,1.97,25.99]],"ltp":2.0,"tv":32.2,"id":5858055}]}]}
{"op":"mcm","clk":"1003641232","pt":1580651238768,"mc":[{"id":"1.168224459","rc":[{"batb":[[2,1.9,2.53]],"ltp":2.0,"tv":32.2,"id":5858055},{"batb":[[0,1.88,508.51],[1,1.81,37.86],[2,1.8,1.25]],"ltp":1.87,"tv":157.81,"id":7444998}]}]}
{"op":"mcm","clk":"1003659498","pt":1580651337726,"mc":[{"id":"1.168224459","rc":[{"batb":[[1,1.97,121.24]],"ltp":2.0,"tv":32.2,"id":5858055}]}]}
{"op":"mcm","clk":"1003659909","pt":1580651339821,"mc":[{"id":"1.168224459","rc":[{"batl":[[1,4.2,153.72],[2,95,15.9]],"ltp":1.87,"tv":157.81,"id":7444998}]}]}
{"op":"mcm","clk":"1003661336","pt":1580651346614,"mc":[{"id":"1.168224459","rc":[{"batb":[[2,1.96,26.26]],"ltp":2.0,"tv":32.2,"id":5858055},{"batb":[[0,1.88,537.16]],"ltp":1.87,"tv":157.81,"id":7444998}]}]}
{"op":"mcm","clk":"1003730151","pt":1580651716259,"mc":[{"id":"1.168224459","rc":[{"batb":[[1,1.96,26.26],[2,1.9,2.53]],"ltp":2.0,"tv":32.2,"id":5858055},{"trd":[[1.88,61.2]],"batb":[[0,1.88,507.9]],"ltp":1.88,"tv":216.32,"id":7444998}],"tv":248.53}]}
{"op":"mcm","clk":"1003730181","pt":1580651716470,"mc":[{"id":"1.168224459","rc":[{"batb":[[1,1.99,121.75],[2,1.96,26.26]],"ltp":2.0,"tv":32.2,"id":5858055}]}]}
{"op":"mcm","clk":"1003730426","pt":1580651717807,"mc":[{"id":"1.168224459","rc":[{"batb":[[2,1.97,25.99]],"ltp":2.0,"tv":32.2,"id":5858055},{"batb":[[0,1.88,479.26],[1,1.87,28.97],[2,1.81,37.86]],"ltp":1.88,"tv":216.32,"id":7444998}]}]}
{"op":"mcm","clk":"1003730778","pt":1580651719673,"mc":[{"id":"1.168224459","rc":[{"batl":[[0,1.99,7.57],[1,2.28,18.94],[2,4.2,153.72]],"ltp":1.88,"tv":216.32,"id":7444998}]}]}
{"op":"mcm","clk":"1003731183","pt":1580651721780,"mc":[{"id":"1.168224459","rc":[{"batl":[[0,2.28,18.94],[1,4.2,153.72],[2,95,15.9]],"ltp":1.88,"tv":216.32,"id":7444998}]}]}
{"op":"mcm","clk":"1003734275","pt":1580651738813,"mc":[{"id":"1.168224459","rc":[{"trd":[[1.88,139.22]],"batb":[[0,1.88,440.25]],"ltp":1.88,"tv":294.34,"id":7444998}],"tv":326.55}]}
{"op":"mcm","clk":"1003734693","pt":1580651741013,"mc":[{"id":"1.168224459","rc":[{"batb":[[1,1.99,121.15]],"ltp":2.0,"tv":32.2,"id":5858055},{"batb":[[0,1.89,39.56],[1,1.88,440.25],[2,1.87,28.97]],"ltp":1.88,"tv":294.34,"id":7444998}]}]}
{"op":"mcm","clk":"1003734828","pt":1580651741709,"mc":[{"id":"1.168224459","rc":[{"batb":[[1,1.88,468.89]],"ltp":1.88,"tv":294.34,"id":7444998}]}]}
{"op":"mcm","clk":"1003754309","pt":1580651847397,"mc":[{"id":"1.168224459","rc":[{"batb":[[0,1.89,39.22]],"ltp":1.88,"tv":294.34,"id":7444998}]}]}
{"op":"mcm","clk":"1003754367","pt":1580651847710,"mc":[{"id":"1.168224459","rc":[{"batb":[[1,1.88,43.43]],"ltp":1.88,"tv":294.34,"id":7444998}]}]}
{"op":"mcm","clk":"1003756020","pt":1580651856715,"mc":[{"id":"1.168224459","rc":[{"trd":[[1.99,107.33],[2.02,1.25]],"batb":[[0,1.99,13.82],[1,1.97,25.99],[2,1.96,26.26]],"ltp":1.99,"tv":140.78,"id":5858055},{"trd":[[1.99,25.73],[2.02,105.73]],"ltp":2.02,"tv":401.34,"id":7444998}],"tv":542.13}]}
{"op":"mcm","clk":"1003756234","pt":1580651857798,"mc":[{"id":"1.168224459","rc":[{"batb":[[1,1.9,2.53],[2,1.89,29.44]],"ltp":1.99,"tv":140.78,"id":5858055},{"batb":[[0,1.89,67.54]],"ltp":2.02,"tv":401.34,"id":7444998}]}]}
{"op":"mcm","clk":"1003756921","pt":1580651861310,"mc":[{"id":"1.168224459","rc":[{"batb":[[0,1.98,28.55]],"ltp":1.99,"tv":140.78,"id":5858055},{"batb":[[0,1.91,120.11],[1,1.89,28.32],[2,1.88,28.64]],"ltp":2.02,"tv":401.34,"id":7444998}]}]}
{"op":"mcm","clk":"1003757001","pt":1580651861797,"mc":[{"id":"1.168224459","rc":[{"batb":[[1,1.95,26.53],[2,1.9,2.53]],"ltp":1.99,"tv":140.78,"id":5858055}]}]}
{"op":"mcm","clk":"1003757225","pt":1580651863191,"mc":[{"id":"1.168224459","rc":[{"batl":[[0,2.02,7.57],[1,2.28,18.94],[2,4.2,153.72]],"ltp":2.02,"tv":401.34,"id":7444998}]}]}
{"op":"mcm","clk":"1003759009","pt":1580651873193,"mc":[{"id":"1.168224459","rc":[{"batb":[[0,1.92,16.46],[1,1.91,120.11],[2,1.89,28.32]],"ltp":2.02,"tv":401.34,"id":7444998}]}]}
{"op":"mcm","clk":"1003759935","pt":1580651878017,"mc":[{"id":"1.168224459","rc":[{"batl":[[0,2.28,18.94],[1,4.2,153.72],[2,95,15.9]],"ltp":2.02,"tv":401.34,"id":7444998}]}]}
{"op":"mcm","clk":"1003762583","pt":1580651891442,"mc":[{"id":"1.168224459","rc":[{"batl":[[0,2.02,7.57],[1,2.28,18.94],[2,4.2,153.72]],"ltp":2.02,"tv":401.34,"id":7444998}]}]}
{"op":"mcm","clk":"1003763254","pt":1580651894530,"mc":[{"id":"1.168224459","rc":[{"batb":[[2,1.9,16.83]],"ltp":2.02,"tv":401.34,"id":7444998}]}]}
{"op":"mcm","clk":"1003763456","pt":1580651895541,"mc":[{"id":"1.168224459","rc":[{"batb":[[2,1.89,28.32]],"ltp":2.02,"tv":401.34,"id":7444998}]}]}
{"op":"mcm","clk":"1003766091","pt":1580651908653,"mc":[{"id":"1.168224459","rc":[{"batl":[[0,2.02,15.14]],"ltp":2.02,"tv":401.34,"id":7444998}]}]}
{"op":"mcm","clk":"1003766861","pt":1580651912265,"mc":[{"id":"1.168224459","rc":[{"batl":[[0,2.02,7.57]],"ltp":2.02,"tv":401.34,"id":7444998}]}]}
{"op":"mcm","clk":"1003767244","pt":1580651914291,"mc":[{"id":"1.168224459","rc":[{"batb":[[0,1.95,26.53],[1,1.9,2.53],[2,1.89,29.44]],"ltp":1.99,"tv":140.78,"id":5858055},{"batb":[[1,1.89,28.32],[2,1.88,28.64]],"ltp":2.02,"tv":401.34,"id":7444998}]}]}
{"op":"mcm","clk":"1003767349","pt":1580651914779,"mc":[{"id":"1.168224459","rc":[{"batb":[[0,1.96,55.15],[2,1.89,1.12]],"ltp":1.99,"tv":140.78,"id":5858055},{"batb":[[0,1.93,91.01],[1,1.92,16.46],[2,1.82,67.68]],"ltp":2.02,"tv":401.34,"id":7444998}]}]}
{"op":"mcm","clk":"1003767565","pt":1580651915758,"mc":[{"id":"1.168224459","rc":[{"batb":[[1,1.94,26.81],[2,1.9,2.53]],"ltp":1.99,"tv":140.78,"id":5858055},{"batb":[[2,1.91,27.7]],"ltp":2.02,"tv":401.34,"id":7444998}]}]}
{"op":"mcm","clk":"1003774150","pt":1580651949229,"mc":[{"id":"1.168224459","rc":[{"batb":[[1,1.91,27.7],[2,1.82,67.68]],"ltp":2.02,"tv":401.34,"id":7444998}]}]}
{"op":"mcm","clk":"1003779177","pt":1580651974993,"mc":[{"id":"1.168224459","rc":[{"batl":[[0,2.02,15.14]],"ltp":2.02,"tv":401.34,"id":7444998}]}]}
{"op":"mcm","clk":"1003779602","pt":1580651977178,"mc":[{"id":"1.168224459","rc":[{"batl":[[0,2.02,7.57]],"ltp":2.02,"tv":401.34,"id":7444998}]}]}
{"op":"mcm","clk":"1003786601","pt":1580652009848,"mc":[{"id":"1.168224459","rc":[{"batl":[[0,2.02,15.14]],"ltp":2.02,"tv":401.34,"id":7444998}]}]}
{"op":"mcm","clk":"1003786998","pt":1580652011602,"mc":[{"id":"1.168224459","rc":[{"batl":[[0,2.28,18.94],[1,4.2,153.72],[2,95,15.9]],"ltp":2.02,"tv":401.34,"id":7444998}]}]}
{"op":"mcm","clk":"1003789786","pt":1580652025127,"mc":[{"id":"1.168224459","rc":[{"batl":[[0,2.02,7.57],[1,2.28,18.94],[2,4.2,153.72]],"ltp":2.02,"tv":401.34,"id":7444998}]}]}
{"op":"mcm","clk":"1003790481","pt":1580652028961,"mc":[{"id":"1.168224459","rc":[{"batl":[[0,2.28,18.94],[1,4.2,153.72],[2,95,15.9]],"ltp":2.02,"tv":401.34,"id":7444998}]}]}
{"op":"mcm","clk":"1003800480","pt":1580652077956,"mc":[{"id":"1.168224459","rc":[{"batb":[[0,1.95,68.81]],"ltp":1.99,"tv":140.78,"id":5858055},{"batb":[[0,1.92,105.43]],"ltp":2.02,"tv":401.34,"id":7444998}]}]}
{"op":"mcm","clk":"1003804191","pt":1580652096329,"mc":[{"id":"1.168224459","rc":[{"batb":[[0,1.93,1.3],[1,1.92,105.43],[2,1.91,27.7]],"ltp":2.02,"tv":401.34,"id":7444998}]}]}
{"op":"mcm","clk":"1003808359","pt":1580652114770,"mc":[{"id":"1.168224459","marketDefinition":{"bspMarket":false,"turnInPlayEnabled":true,"persistenceEnabled":true,"marketBaseRate":5.0,"eventId":"29681747","eventTypeId":"2","numberOfWinners":1,"bettingType":"ODDS","marketType":"MATCH_ODDS","marketTime":"2020-02-02T14:06:00.000Z","suspendTime":"2020-02-02T14:06:00.000Z","bspReconciled":false,"complete":true,"inPlay":false,"crossMatching":true,"runnersVoidable":false,"numberOfActiveRunners":2,"betDelay":0,"status":"OPEN","runners":[{"status":"ACTIVE","sortPriority":1,"id":5858055,"name":"Hiroki Moriya"},{"status":"ACTIVE","sortPriority":2,"id":7444998,"name":"Danilo Petrovic"}],"regulators":["MR_INT"],"countryCode":"FR","discountAllowed":true,"timezone":"UTC","openDate":"2020-02-02T14:16:00.000Z","version":3149081982,"name":"Match Odds","eventName":"Moriya v Petrovic"}}]}
{"op":"mcm","clk":"1003809195","pt":1580652118802,"mc":[{"id":"1.168224459","marketDefinition":{"bspMarket":false,"turnInPlayEnabled":true,"persistenceEnabled":true,"marketBaseRate":5.0,"eventId":"29681747","eventTypeId":"2","numberOfWinners":1,"bettingType":"ODDS","marketType":"MATCH_ODDS","marketTime":"2020-02-02T14:06:00.000Z","suspendTime":"2020-02-02T14:06:00.000Z","bspReconciled":false,"complete":true,"inPlay":false,"crossMatching":true,"runnersVoidable":false,"numberOfActiveRunners":2,"betDelay":0,"status":"OPEN","runners":[{"status":"ACTIVE","sortPriority":1,"id":5858055,"name":"Hiroki Moriya"},{"status":"ACTIVE","sortPriority":2,"id":7444998,"name":"Danilo Petrovic"}],"regulators":["MR_INT"],"countryCode":"FR","discountAllowed":true,"timezone":"UTC","openDate":"2020-02-02T14:06:00.000Z","version":3149081982,"name":"Match Odds","eventName":"Moriya v Petrovic"}}]}
{"op":"mcm","clk":"1003811258","pt":1580652128235,"mc":[{"id":"1.168224459","rc":[{"batb":[[0,1.95,463.12]],"ltp":1.99,"tv":140.78,"id":5858055}]}]}
{"op":"mcm","clk":"1003812150","pt":1580652132566,"mc":[{"id":"1.168224459","rc":[{"batb":[[0,1.96,168.04],[1,1.95,463.12],[2,1.94,26.81]],"ltp":1.99,"tv":140.78,"id":5858055},{"batb":[[0,1.96,168.04],[1,1.93,1.3],[2,1.92,105.43]],"ltp":2.02,"tv":401.34,"id":7444998}]}]}
{"op":"mcm","clk":"1003812474","pt":1580652134055,"mc":[{"id":"1.168224459","rc":[{"batb":[[1,1.95,68.81],[2,1.93,27.1]],"ltp":1.99,"tv":140.78,"id":5858055},{"batb":[[1,1.93,28.41]],"ltp":2.02,"tv":401.34,"id":7444998}]}]}
{"op":"mcm","clk":"1003829031","pt":1580652207709,"mc":[{"id":"1.168224459","rc":[{"batb":[[0,1.97,41.73],[1,1.96,168.04]],"ltp":1.99,"tv":140.78,"id":5858055},{"batb":[[0,1.97,35.92],[1,1.96,168.04],[2,1.93,28.41]],"ltp":2.02,"tv":401.34,"id":7444998}]}]}
{"op":"mcm","clk":"1003833788","pt":1580652228232,"mc":[{"id":"1.168224459","rc":[{"trd":[[1.97,0.85]],"batb":[[0,1.97,41.3]],"ltp":1.97,"tv":141.63,"id":5858055}],"tv":542.98}]}
{"op":"mcm","clk":"1003845478","pt":1580652277851,"mc":[{"id":"1.168224459","rc":[{"batb":[[2,1.94,62.55]],"ltp":1.97,"tv":141.63,"id":5858055},{"batb":[[2,1.94,62.55]],"ltp":2.02,"tv":401.34,"id":7444998}]}]}
{"op":"mcm","clk":"1003858873","pt":1580652332132,"mc":[{"id":"1.168224459","rc":[{"trd":[[1.97,43.25]],"batb":[[0,1.97,14.28]],"ltp":1.97,"tv":444.59,"id":7444998}],"tv":586.23}]}
{"op":"mcm","clk":"1003859083","pt":1580652332916,"mc":[{"id":"1.168224459","rc":[{"batb":[[0,1.97,62.72]],"ltp":1.97,"tv":141.63,"id":5858055},{"batb":[[0,1.96,168.04],[1,1.95,41.76]],"ltp":1.97,"tv":444.59,"id":7444998}]}]}
{"op":"mcm","clk":"1003859678","pt":1580652335327,"mc":[{"id":"1.168224459","rc":[{"batl":[[0,2.02,7.57],[1,2.28,18.94],[2,4.2,153.72]],"ltp":1.97,"tv":444.59,"id":7444998}]}]}
{"op":"mcm","clk":"1003862513","pt":1580652346828,"mc":[{"id":"1.168224459","rc":[{"batl":[[0,2.02,15.14]],"ltp":1.97,"tv":444.59,"id":7444998}]}]}
{"op":"mcm","clk":"1003863468","pt":1580652350965,"mc":[{"id":"1.168224459","rc":[{"batl":[[0,2.28,18.94],[1,4.2,153.72],[2,95,15.9]],"ltp":1.97,"tv":444.59,"id":7444998}]}]}
{"op":"mcm","clk":"1003878607","pt":1580652413628,"mc":[{"id":"1.168224459","marketDefinition":{"bspMarket":false,"turnInPlayEnabled":true,"persistenceEnabled":true,"marketBaseRate":5.0,"eventId":"29681747","eventTypeId":"2","numberOfWinners":1,"bettingType":"ODDS","marketType":"MATCH_ODDS","marketTime":"2020-02-02T14:03:00.000Z","suspendTime":"2020-02-02T14:03:00.000Z","bspReconciled":false,"complete":true,"inPlay":false,"crossMatching":true,"runnersVoidable":false,"numberOfActiveRunners":2,"betDelay":0,"status":"OPEN","runners":[{"status":"ACTIVE","sortPriority":1,"id":5858055,"name":"Hiroki Moriya"},{"status":"ACTIVE","sortPriority":2,"id":7444998,"name":"Danilo Petrovic"}],"regulators":["MR_INT"],"countryCode":"FR","discountAllowed":true,"timezone":"UTC","openDate":"2020-02-02T14:06:00.000Z","version":3149117367,"name":"Match Odds","eventName":"Moriya v Petrovic"}}]}
{"op":"mcm","clk":"1003879387","pt":1580652416642,"mc":[{"id":"1.168224459","marketDefinition":{"bspMarket":false,"turnInPlayEnabled":true,"persistenceEnabled":true,"marketBaseRate":5.0,"eventId":"29681747","eventTypeId":"2","numberOfWinners":1,"bettingType":"ODDS","marketType":"MATCH_ODDS","marketTime":"2020-02-02T14:03:00.000Z","suspendTime":"2020-02-02T14:03:00.000Z","bspReconciled":false,"complete":true,"inPlay":false,"crossMatching":true,"runnersVoidable":false,"numberOfActiveRunners":2,"betDelay":0,"status":"OPEN","runners":[{"status":"ACTIVE","sortPriority":1,"id":5858055,"name":"Hiroki Moriya"},{"status":"ACTIVE","sortPriority":2,"id":7444998,"name":"Danilo Petrovic"}],"regulators":["MR_INT"],"countryCode":"FR","discountAllowed":true,"timezone":"UTC","openDate":"2020-02-02T14:03:00.000Z","version":3149117367,"name":"Match Odds","eventName":"Moriya v Petrovic"}}]}
{"op":"mcm","clk":"1003881678","pt":1580652425393,"mc":[{"id":"1.168224459","rc":[{"trd":[[1.96,20]],"batb":[[0,1.96,158.04]],"ltp":1.96,"tv":464.59,"id":7444998}],"tv":606.23}]}
{"op":"mcm","clk":"1003882842","pt":1580652429709,"mc":[{"id":"1.168224459","rc":[{"batl":[[0,4.2,153.72],[1,95,15.9],[2,990,2.2]],"ltp":1.97,"tv":141.63,"id":5858055},{"batl":[[0,4.2,154.17],[1,95,15.9],[2,990,2.2]],"ltp":1.96,"tv":464.59,"id":7444998}]}]}
{"op":"mcm","clk":"1003930605","pt":1580652610576,"mc":[{"id":"1.168224459","rc":[{"batl":[[0,2.14,36.13],[1,4.2,153.72],[2,95,15.9]],"ltp":1.97,"tv":141.63,"id":5858055},{"batl":[[0,2.08,38.65],[1,4.2,154.17],[2,95,15.9]],"ltp":1.96,"tv":464.59,"id":7444998}]}]}
{"op":"mcm","clk":"1003937867","pt":1580652639055,"mc":[{"id":"1.168224459","rc":[{"batl":[[0,2,18.48],[1,2.08,38.65],[2,4.2,154.17]],"ltp":1.96,"tv":464.59,"id":7444998}]}]}
{"op":"mcm","clk":"1003938272","pt":1580652640443,"mc":[{"id":"1.168224459","rc":[{"batb":[[2,1.94,89.36]],"ltp":1.97,"tv":141.63,"id":5858055}]}]}
{"op":"mcm","clk":"1003991343","pt":1580652850905,"mc":[{"id":"1.168224459","rc":[{"trd":[[1.96,56.97]],"batb":[[0,1.96,139.56]],"batl":[[0,2.08,38.65],[1,4.2,154.17],[2,95,15.9]],"ltp":1.96,"tv":501.56,"id":7444998}],"tv":643.2}]}
{"op":"mcm","clk":"1003991619","pt":1580652852177,"mc":[{"id":"1.168224459","rc":[{"batb":[[2,1.94,62.55]],"ltp":1.97,"tv":141.63,"id":5858055}]}]}
{"op":"mcm","clk":"1003995124","pt":1580652868100,"mc":[{"id":"1.168224459","rc":[{"batb":[[2,1.93,71.64]],"ltp":1.97,"tv":141.63,"id":5858055},{"batb":[[2,1.93,1.3]],"ltp":1.96,"tv":501.56,"id":7444998}]}]}
{"op":"mcm","clk":"1003995312","pt":1580652868929,"mc":[{"id":"1.168224459","marketDefinition":{"bspMarket":false,"turnInPlayEnabled":true,"persistenceEnabled":true,"marketBaseRate":5.0,"eventId":"29681747","eventTypeId":"2","numberOfWinners":1,"bettingType":"ODDS","marketType":"MATCH_ODDS","marketTime":"2020-02-02T14:03:00.000Z","suspendTime":"2020-02-02T14:03:00.000Z","bspReconciled":false,"complete":true,"inPlay":true,"crossMatching":true,"runnersVoidable":false,"numberOfActiveRunners":2,"betDelay":3,"status":"OPEN","runners":[{"status":"ACTIVE","sortPriority":1,"id":5858055,"name":"Hiroki Moriya"},{"status":"ACTIVE","sortPriority":2,"id":7444998,"name":"Danilo Petrovic"}],"regulators":["MR_INT"],"countryCode":"FR","discountAllowed":true,"timezone":"UTC","openDate":"2020-02-02T14:03:00.000Z","version":3149153479,"name":"Match Odds","eventName":"Moriya v Petrovic"},"rc":[{"batb":[[0,1.96,168.04],[1,1.11,37.97],[2,1.05,152.3]],"batl":[[0,1000,0.02],[1,4.2,0],[2,95,0]],"ltp":1.97,"tv":141.63,"id":5858055},{"batb":[[1,1.11,37.97],[2,1.05,152.3]],"batl":[[0,1000,0.47],[1,4.2,0],[2,95,0]],"ltp":1.96,"tv":501.56,"id":7444998}]}]}
{"op":"mcm","clk":"1003996528","pt":1580652874416,"mc":[{"id":"1.168224459","rc":[{"batb":[[1,1.83,109.48],[2,1.81,130.92]],"batl":[[0,2.1,100.11],[1,2.12,82.82],[2,1000,0.02]],"ltp":1.96,"tv":501.56,"id":7444998}]}]}
{"op":"mcm","clk":"1003998571","pt":1580652883113,"mc":[{"id":"1.168224459","rc":[{"batb":[[2,1.05,530.92]],"ltp":1.97,"tv":141.63,"id":5858055},{"batb":[[1,1.11,37.97],[2,1.05,530.92]],"batl":[[0,1000,0.47],[1,2.12,0],[2,1000,0]],"ltp":1.96,"tv":501.56,"id":7444998}]}]}
{"op":"mcm","clk":"1003999222","pt":1580652885932,"mc":[{"id":"1.168224459","rc":[{"batb":[[1,1.94,8.28],[2,1.92,145.08]],"batl":[[0,1.98,104.11],[1,2,172.35],[2,2.02,231]],"ltp":1.97,"tv":141.63,"id":5858055},{"batb":[[0,2,74.71],[1,1.96,139.56],[2,1.11,37.97]],"batl":[[0,2.14,225.45],[1,1000,0.02]],"ltp":1.96,"tv":501.56,"id":7444998}]}]}
{"op":"mcm","clk":"1003999414","pt":1580652886808,"mc":[{"id":"1.168224459","rc":[{"batb":[[0,2.02,110.08],[1,2,74.71],[2,1.96,139.56]],"ltp":1.96,"tv":501.56,"id":7444998}]}]}
{"op":"mcm","clk":"1003999649","pt":1580652887845,"mc":[{"id":"1.168224459","rc":[{"batl":[[1,2.16,36.13],[2,1000,0.02]],"ltp":1.96,"tv":501.56,"id":7444998}]}]}
{"op":"mcm","clk":"1004001743","pt":1580652897034,"mc":[{"id":"1.168224459","rc":[{"trd":[[1.98,98.98]],"batl":[[0,2,74.71],[1,2.02,231],[2,2.06,39.49]],"ltp":1.98,"tv":240.61,"id":5858055}],"tv":742.17}]}
{"op":"mcm","clk":"1004001994","pt":1580652898233,"mc":[{"id":"1.168224459","rc":[{"batb":[[1,1.91,105],[2,1.89,113.96]],"batl":[[0,2.06,39.49],[1,1000,0.02],[2,2.06,0]],"ltp":1.98,"tv":240.61,"id":5858055},{"batb":[[1,1.96,139.56],[2,1.95,43.69]],"batl":[[0,2.16,36.58],[1,1000,0.02],[2,1000,0]],"ltp":1.96,"tv":501.56,"id":7444998}]}]}
{"op":"mcm","clk":"1004002205","pt":1580652899144,"mc":[{"id":"1.168224459","rc":[{"batb":[[1,1.82,76.79],[2,1.4,75.73]],"batl":[[0,1000,0.02],[1,1000,0]],"ltp":1.98,"tv":240.61,"id":5858055},{"batb":[[0,1.96,139.56],[1,1.91,65.62],[2,1.5,113.58]],"batl":[[0,1000,0.47],[1,1000,0]],"ltp":1.96,"tv":501.56,"id":7444998}]}]}
{"op":"mcm","clk":"1004002767","pt":1580652901545,"mc":[{"id":"1.168224459","rc":[{"batb":[[1,1.86,109.88],[2,1.84,124.11]],"batl":[[0,2.1,99.99],[1,2.12,82.37],[2,1000,0.02]],"ltp":1.98,"tv":240.61,"id":5858055}]}]}
{"op":"mcm","clk":"1004005663","pt":1580652914435,"mc":[{"id":"1.168224459","rc":[{"batl":[[0,1000,0.02],[1,2.12,0],[2,1000,0]],"ltp":1.98,"tv":240.61,"id":5858055}]}]}
{"op":"mcm","clk":"1004006235","pt":1580652917326,"mc":[{"id":"1.168224459","rc":[{"trd":[[1.96,336.08]],"batb":[[0,1.86,109.88],[1,1.84,124.11],[2,1.82,76.79]],"batl":[[0,1.93,115.84],[1,1.94,177.27],[2,1.95,105.29]],"ltp":1.96,"tv":576.69,"id":5858055},{"batl":[[0,2.12,11.27],[1,2.2,270.38],[2,2.22,218]],"ltp":1.96,"tv":501.56,"id":7444998}],"tv":1078.25}]}
{"op":"mcm","clk":"1004006474","pt":1580652918339,"mc":[{"id":"1.168224459","rc":[{"batb":[[2,1.82,127.21]],"ltp":1.96,"tv":576.69,"id":5858055},{"batb":[[0,2.08,100.63],[1,2,42.01],[2,1.99,115.43]],"batl":[[2,2.22,251.61]],"ltp":1.96,"tv":501.56,"id":7444998}]}]}
{"op":"mcm","clk":"1004008198","pt":1580652926254,"mc":[{"id":"1.168224459","rc":[{"trd":[[1.93,27.7]],"batl":[[0,1.93,101.99]],"ltp":1.93,"tv":604.39,"id":5858055}],"tv":1105.95}]}
{"op":"mcm","clk":"1004008663","pt":1580652928350,"mc":[{"id":"1.168224459","rc":[{"batb":[[0,1.82,50.41],[1,1.77,83.4],[2,1.4,75.73]],"batl":[[0,2,42.01],[1,1000,0.02],[2,1.95,0]],"ltp":1.93,"tv":604.39,"id":5858055},{"batb":[[0,2,42.01],[1,1.99,115.43],[2,1.96,139.56]],"batl":[[0,2.22,34.06],[1,1000,0.02],[2,2.22,0]],"ltp":1.96,"tv":501.56,"id":7444998}]}]}
{"op":"mcm","clk":"1004008778","pt":1580652928853,"mc":[{"id":"1.168224459","rc":[{"batb":[[0,1.77,83.4],[1,1.4,75.73],[2,1.3,113.58]],"batl":[[0,1000,0.02],[1,1000,0]],"ltp":1.93,"tv":604.39,"id":5858055},{"batb":[[0,1.99,115.43],[1,1.96,139.56],[2,1.5,113.58]],"batl":[[0,1000,0.47],[1,1000,0]],"ltp":1.96,"tv":501.56,"id":7444998}]}]}
{"op":"mcm","clk":"1004009306","pt":1580652931266,"mc":[{"id":"1.168224459","rc":[{"batb":[[0,1.82,137.58],[1,1.8,133.34],[2,1.77,83.4]],"batl":[[0,2.02,159.55],[1,2.04,92.06],[2,1000,0.02]],"ltp":1.93,"tv":604.39,"id":5858055}]}]}
{"op":"mcm","clk":"1004009478","pt":1580652931996,"mc":[{"id":"1.168224459","rc":[{"batb":[[2,1.78,83.09]],"ltp":1.93,"tv":604.39,"id":5858055}]}]}
{"op":"mcm","clk":"1004010101","pt":1580652934707,"mc":[{"id":"1.168224459","rc":[{"batl":[[0,1000,0.02],[1,2.04,0],[2,1000,0]],"ltp":1.93,"tv":604.39,"id":5858055}]}]}
{"op":"mcm","clk":"1004010752","pt":1580652937380,"mc":[{"id":"1.168224459","rc":[{"trd":[[1.89,0.51]],"batl":[[0,1.89,8.4],[1,1.9,217],[2,1.91,3157.2]],"ltp":1.89,"tv":604.9,"id":5858055},{"trd":[[2.12,0.45]],"batl":[[0,2.2,17.27],[1,2.24,179.9],[2,2.28,193]],"ltp":2.12,"tv":502.01,"id":7444998}],"tv":1106.91}]}
{"op":"mcm","clk":"1004010942","pt":1580652938298,"mc":[{"id":"1.168224459","rc":[{"batb":[[2,1.78,136.86]],"batl":[[0,1.89,121.13],[2,1.91,112.14]],"ltp":1.89,"tv":604.9,"id":5858055},{"batb":[[0,2.14,92.53],[1,2.06,142.56],[2,1.99,115.43]],"batl":[[2,2.28,225.77]],"ltp":2.12,"tv":502.01,"id":7444998}]}]}
{"op":"mcm","clk":"1004011011","pt":1580652938639,"mc":[{"id":"1.168224459","rc":[{"batb":[[2,1.96,139.56]],"ltp":2.12,"tv":502.01,"id":7444998}]}]}
{"op":"mcm","clk":"1004012385","pt":1580652945307,"mc":[{"id":"1.168224459","rc":[{"trd":[[1.88,14.02]],"ltp":1.88,"tv":618.92,"id":5858055},{"trd":[[2.14,12.31]],"batb":[[0,2.14,80.22]],"ltp":2.14,"tv":514.32,"id":7444998}],"tv":1133.25}]}
{"op":"mcm","clk":"1004012849","pt":1580652947591,"mc":[{"id":"1.168224459","rc":[{"batl":[[0,1.89,112.73]],"ltp":1.88,"tv":618.92,"id":5858055},{"batl":[[0,2.24,179.9],[1,2.28,225.77],[2,1000,0.02]],"ltp":2.14,"tv":514.32,"id":7444998}]}]}
{"op":"mcm","clk":"1004013478","pt":1580652950496,"mc":[{"id":"1.168224459","rc":[{"batl":[[0,1.89,121.13]],"ltp":1.88,"tv":618.92,"id":5858055},{"batl":[[0,2.2,17.71],[1,2.24,179.9],[2,2.28,225.77]],"ltp":2.14,"tv":514.32,"id":7444998}]}]}
{"op":"mcm","clk":"1004013786","pt":1580652952018,"mc":[{"id":"1.168224459","rc":[{"trd":[[1.83,21.29]],"batl":[[0,1.83,10.64],[1,1.89,121.13],[2,1.9,217]],"ltp":1.83,"tv":640.21,"id":5858055},{"trd":[[2.2,17.71]],"batl":[[0,2.24,179.9],[1,2.28,225.77],[2,1000,0.02]],"ltp":2.2,"tv":532.03,"id":7444998}],"tv":1172.25}]}
{"op":"mcm","clk":"1004013959","pt":1580652952893,"mc":[{"id":"1.168224459","rc":[{"batb":[[0,1.8,110.06],[1,1.78,53.77],[2,1.75,87.57]],"batl":[[1,1.97,42.01],[2,1000,0.02]],"ltp":1.83,"tv":640.21,"id":5858055},{"batb":[[0,2.06,142.56],[1,1.96,139.56],[2,1.5,113.58]],"batl":[[0,2.28,32.77],[1,1000,0.02],[2,1000,0]],"ltp":2.2,"tv":532.03,"id":7444998}]}]}
{"op":"mcm","clk":"1004014456","pt":1580652955300,"mc":[{"id":"1.168224459","rc":[{"batb":[[1,1.75,87.57],[2,1.4,75.73]],"batl":[[0,1000,0.02],[1,1.97,0],[2,1000,0]],"ltp":1.83,"tv":640.21,"id":5858055},{"batb":[[0,2.06,103.07],[2,1.6,75.72]],"batl":[[0,1000,0.02],[1,1000,0]],"ltp":2.2,"tv":532.03,"id":7444998}]}]}
{"op":"mcm","clk":"1004014609","pt":1580652956004,"mc":[{"id":"1.168224459","rc":[{"batb":[[1,1.78,138.28],[2,1.76,87.02]],"batl":[[0,1.94,105.57],[1,1.96,103.69],[2,1000,0.02]],"ltp":1.83,"tv":640.21,"id":5858055}]}]}
{"op":"mcm","clk":"1004016287","pt":1580652964100,"mc":[{"id":"1.168224459","rc":[{"batb":[[0,1.76,87.02],[1,1.4,75.73],[2,1.3,113.58]],"batl":[[0,1.8,10.92],[1,1.94,105.57],[2,1.96,103.69]],"ltp":1.83,"tv":640.21,"id":5858055}]}]}
{"op":"mcm","clk":"1004016451","pt":1580652964808,"mc":[{"id":"1.168224459","rc":[{"batb":[[1,1.3,113.59],[2,1.2,284.06]],"ltp":1.83,"tv":640.21,"id":5858055}]}]}
{"op":"mcm","clk":"1004016812","pt":1580652966398,"mc":[{"id":"1.168224459","rc":[{"batb":[[0,1.81,1042.72],[1,1.76,87.02],[2,1.3,113.59]],"batl":[[0,1.92,9.27]],"ltp":1.83,"tv":640.21,"id":5858055},{"batl":[[0,2.14,2827.2],[1,2.16,249.55],[2,2.18,189]],"ltp":2.2,"tv":532.03,"id":7444998}]}]}
{"op":"mcm","clk":"1004017005","pt":1580652967282,"mc":[{"id":"1.168224459","rc":[{"batb":[[0,1.87,114.86],[1,1.85,121.97],[2,1.84,74.59]],"ltp":1.83,"tv":640.21,"id":5858055},{"batb":[[1,1.97,119.2],[2,1.96,139.56]],"batl":[[0,2.16,249.55],[1,2.18,189],[2,1000,0.02]],"ltp":2.2,"tv":532.03,"id":7444998}]}]}
{"op":"mcm","clk":"1004017369","pt":1580652969195,"mc":[{"id":"1.168224459","rc":[{"batb":[[2,1.84,124.16]],"ltp":1.83,"tv":640.21,"id":5858055},{"batb":[[1,1.98,42.85],[2,1.97,119.2]],"batl":[[2,2.2,34.45]],"ltp":2.2,"tv":532.03,"id":7444998}]}]}
{"op":"mcm","clk":"1004018427","pt":1580652974004,"mc":[{"id":"1.168224459","rc":[{"trd":[[1.87,21.84]],"batb":[[0,1.87,103.94]],"ltp":1.87,"tv":662.05,"id":5858055}],"tv":1194.09}]}
{"op":"mcm","clk":"1004020531","pt":1580652983335,"mc":[{"id":"1.168224459","rc":[{"batl":[[0,1.94,105.57],[1,1.96,103.69],[2,2.02,41.17]],"ltp":1.87,"tv":662.05,"id":5858055},{"batl":[[0,2.2,34.45],[1,1000,0.02],[2,2.2,0]],"ltp":2.2,"tv":532.03,"id":7444998}]}]}
{"op":"mcm","clk":"1004020624","pt":1580652983734,"mc":[{"id":"1.168224459","rc":[{"batb":[[0,1.84,49.57],[1,1.8,80.65],[2,1.4,75.73]],"batl":[[0,2.02,41.17],[1,1000,0.02],[2,2.02,0]],"ltp":1.87,"tv":662.05,"id":5858055},{"batb":[[0,1.98,42.85],[1,1.97,119.2],[2,1.96,139.56]],"ltp":2.2,"tv":532.03,"id":7444998}]}]}
{"op":"mcm","clk":"1004020868","pt":1580652984837,"mc":[{"id":"1.168224459","rc":[{"batb":[[0,1.8,80.65],[1,1.4,75.73],[2,1.3,113.58]],"batl":[[0,1000,0.02],[1,1000,0]],"ltp":1.87,"tv":662.05,"id":5858055},{"batb":[[0,1.97,119.2],[1,1.96,139.56],[2,1.6,75.72]],"batl":[[0,1000,0.02],[1,1000,0]],"ltp":2.2,"tv":532.03,"id":7444998}]}]}
{"op":"mcm","clk":"1004021210","pt":1580652986525,"mc":[{"id":"1.168224459","rc":[{"batb":[[0,1.83,130.68],[1,1.81,130.94],[2,1.8,80.65]],"batl":[[0,2.02,126.66],[1,2.04,92.08],[2,1000,0.02]],"ltp":1.87,"tv":662.05,"id":5858055}]}]}
{"op":"mcm","clk":"1004021771","pt":1580652989251,"mc":[{"id":"1.168224459","rc":[{"batb":[[0,1.8,80.65],[1,1.4,75.73],[2,1.3,113.58]],"batl":[[0,1000,0.02],[1,2.04,0],[2,1000,0]],"ltp":1.87,"tv":662.05,"id":5858055}]}]}
{"op":"mcm","clk":"1004022493","pt":1580652992530,"mc":[{"id":"1.168224459","rc":[{"batb":[[2,1.5,113.58]],"ltp":2.2,"tv":532.03,"id":7444998}]}]}
{"op":"mcm","clk":"1004022916","pt":1580652994361,"mc":[{"id":"1.168224459","rc":[{"batb":[[0,1.83,130.68],[1,1.81,130.94],[2,1.8,80.65]],"batl":[[0,2.02,126.66],[1,2.04,92.08],[2,1000,0.02]],"ltp":1.87,"tv":662.05,"id":5858055}]}]}
{"op":"mcm","clk":"1004024700","pt":1580653002881,"mc":[{"id":"1.168224459","rc":[{"batl":[[0,1000,0.02],[1,2.04,0],[2,1000,0]],"ltp":1.87,"tv":662.05,"id":5858055}]}]}
{"op":"mcm","clk":"1004025405","pt":1580653006239,"mc":[{"id":"1.168224459","rc":[{"batl":[[0,1.89,16.57],[1,1.9,113.25],[2,1.92,295.38]],"ltp":1.87,"tv":662.05,"id":5858055},{"batb":[[0,2.08,284.77],[1,2,101.67],[2,1.97,119.2]],"batl":[[0,2.2,171.49],[1,2.24,179],[2,1000,0.02]],"ltp":2.2,"tv":532.03,"id":7444998}]}]}
{"op":"mcm","clk":"1004025508","pt":1580653006784,"mc":[{"id":"1.168224459","rc":[{"batb":[[0,2.12,95.52],[1,2.08,284.77],[2,2.04,107.56]],"ltp":2.2,"tv":532.03,"id":7444998}]}]}
{"op":"mcm","clk":"1004025720","pt":1580653007778,"mc":[{"id":"1.168224459","rc":[{"batb":[[2,2.06,39.49]],"batl":[[2,2.3,31.93]],"ltp":2.2,"tv":532.03,"id":7444998}]}]}
{"op":"mcm","clk":"1004028538","pt":1580653021384,"mc":[{"id":"1.168224459","rc":[{"trd":[[2.12,5]],"batb":[[0,2.12,93.25]],"ltp":2.12,"tv":536.58,"id":7444998}],"tv":1198.63}]}
{"op":"mcm","clk":"1004032856","pt":1580653042973,"mc":[{"id":"1.168224459","rc":[{"batb":[[0,1.8,80.65],[1,1.78,53.77],[2,1.7,96.94]],"batl":[[1,1.92,185],[2,1.96,42.01]],"ltp":1.87,"tv":662.05,"id":5858055}]}]}
{"op":"mcm","clk":"1004033067","pt":1580653044170,"mc":[{"id":"1.168224459","rc":[{"batb":[[0,1.78,53.77],[1,1.7,96.94],[2,1.4,75.73]],"batl":[[0,1.96,42.01],[1,1000,0.02],[2,1.96,0]],"ltp":1.87,"tv":662.05,"id":5858055},{"batb":[[0,2.06,39.49],[1,2.04,107.56],[2,1.96,139.56]],"batl":[[0,2.3,31.93],[1,1000,0.02],[2,2.3,0]],"ltp":2.12,"tv":536.58,"id":7444998}]}]}
{"op":"mcm","clk":"1004033195","pt":1580653044936,"mc":[{"id":"1.168224459","rc":[{"batb":[[0,1.7,96.94],[1,1.4,75.73],[2,1.3,113.58]],"batl":[[0,1000,0.02],[1,1000,0]],"ltp":1.87,"tv":662.05,"id":5858055},{"batb":[[0,2.04,107.56],[1,1.96,139.56],[2,1.5,113.58]],"batl":[[0,1000,0.02],[1,1000,0]],"ltp":2.12,"tv":536.58,"id":7444998}]}]}
{"op":"mcm","clk":"1004033385","pt":1580653045976,"mc":[{"id":"1.168224459","rc":[{"batb":[[0,1.73,109.57],[1,1.71,158.31],[2,1.7,96.94]],"batl":[[0,1.97,103.2],[1,1.99,99.08],[2,1000,0.02]],"ltp":1.87,"tv":662.05,"id":5858055}]}]}
{"op":"mcm","clk":"1004034153","pt":1580653049899,"mc":[{"id":"1.168224459","rc":[{"batb":[[0,1.7,96.94],[1,1.4,75.73],[2,1.3,113.58]],"ltp":1.87,"tv":662.05,"id":5858055}]}]}
{"op":"mcm","clk":"1004034768","pt":1580653053200,"mc":[{"id":"1.168224459","rc":[{"batb":[[0,1.9,101.19],[1,1.88,115.87],[2,1.84,115.65]],"batl":[[2,2,192]],"ltp":1.87,"tv":662.05,"id":5858055},{"batb":[[0,2.06,6.76],[1,2.04,107.56],[2,1.96,139.56]],"batl":[[0,2.12,223.07],[1,2.14,171],[2,2.2,82.67]],"ltp":2.12,"tv":536.58,"id":7444998}]}]}
{"op":"mcm","clk":"1004034904","pt":1580653053905,"mc":[{"id":"1.168224459","rc":[{"batb":[[2,1.86,71.99]],"ltp":1.87,"tv":662.05,"id":5858055},{"batb":[[2,1.99,42.01]],"ltp":2.12,"tv":536.58,"id":7444998}]}]}
{"op":"mcm","clk":"1004036613","pt":1580653062304,"mc":[{"id":"1.168224459","rc":[{"batl":[[2,2.02,41.17]],"ltp":1.87,"tv":662.05,"id":5858055},{"batb":[[0,2.04,107.56],[1,1.99,42.01],[2,1.96,260.25]],"batl":[[0,2.22,33.61],[1,1000,1.53],[2,2.2,0]],"ltp":2.12,"tv":536.58,"id":7444998}]}]}
{"op":"mcm","clk":"1004036734","pt":1580653062941,"mc":[{"id":"1.168224459","rc":[{"batb":[[0,1.77,84.9],[1,1.4,75.73],[2,1.3,113.58]],"batl":[[0,1000,0.02],[1,1.99,0],[2,2.02,0]],"ltp":1.87,"tv":662.05,"id":5858055},{"batb":[[0,1.96,260.25],[1,1.5,113.58],[2,1.4,75.73]],"batl":[[0,1000,0.02],[1,1000,0]],"ltp":2.12,"tv":536.58,"id":7444998}]}]}
{"op":"mcm","clk":"1004037356","pt":1580653066146,"mc":[{"id":"1.168224459","rc":[{"batl":[[0,2.06,1.51],[1,1000,0.02]],"ltp":2.12,"tv":536.58,"id":7444998}]}]}
{"op":"mcm","clk":"1004038454","pt":1580653072314,"mc":[{"id":"1.168224459","rc":[{"batb":[[0,1.8,144.84],[1,1.78,138.37],[2,1.77,84.9]],"batl":[[0,2.04,135.98],[1,2.06,89.48],[2,1000,0.02]],"ltp":1.87,"tv":662.05,"id":5858055}]}]}
{"op":"mcm","clk":"1004039393","pt":1580653077124,"mc":[{"id":"1.168224459","rc":[{"batl":[[0,1000,0.02],[1,2.06,0],[2,1000,0]],"ltp":1.87,"tv":662.05,"id":5858055}]}]}
{"op":"mcm","clk":"1004039962","pt":1580653080031,"mc":[{"id":"1.168224459","rc":[{"trd":[[1.94,1.61]],"batl":[[0,1.87,118.63],[1,1.88,184.39],[2,1.89,115.84]],"ltp":1.94,"tv":663.66,"id":5858055},{"trd":[[2.06,1.51]],"batb":[[0,2.2,6.34],[1,2.12,193.43],[2,2.06,106.74]],"batl":[[0,2.24,6.02],[1,2.28,222.24],[2,2.3,188]],"ltp":2.06,"tv":538.09,"id":7444998}],"tv":1201.76}]}
{"op":"mcm","clk":"1004040101","pt":1580653080758,"mc":[{"id":"1.168224459","rc":[{"batb":[[1,2.16,90.41],[2,2.12,193.43]],"ltp":2.06,"tv":538.09,"id":7444998}]}]}
{"op":"mcm","clk":"1004042425","pt":1580653092345,"mc":[{"id":"1.168224459","rc":[{"batl":[[1,1.89,115.84],[2,1.92,136.76]],"ltp":1.94,"tv":663.66,"id":5858055},{"batb":[[0,2.16,90.41],[1,2.08,38.65],[2,2.06,211.86]],"batl":[[0,2.34,31.09],[1,1000,0.02],[2,2.3,0]],"ltp":2.06,"tv":538.09,"id":7444998}]}]}
{"op":"mcm","clk":"1004042518","pt":1580653092874,"mc":[{"id":"1.168224459","rc":[{"batb":[[0,1.66,104.88],[1,1.4,75.73],[2,1.3,113.58]],"batl":[[0,1000,0.02],[1,1.89,0],[2,1.92,0]],"ltp":1.94,"tv":663.66,"id":5858055},{"batb":[[0,2.06,105.12],[1,1.96,139.56],[2,1.6,75.72]],"batl":[[0,1000,0.02],[1,1000,0]],"ltp":2.06,"tv":538.09,"id":7444998}]}]}
{"op":"mcm","clk":"1004043031","pt":1580653095799,"mc":[{"id":"1.168224459","rc":[{"batb":[[0,1.69,88.36],[1,1.67,171.77],[2,1.66,104.88]],"batl":[[0,1.95,95.04],[1,1.97,102.13],[2,1000,0.02]],"ltp":1.94,"tv":663.66,"id":5858055}]}]}
{"op":"mcm","clk":"1004044100","pt":1580653101368,"mc":[{"id":"1.168224459","rc":[{"batb":[[0,1.66,104.88],[1,1.4,75.73],[2,1.3,113.58]],"ltp":1.94,"tv":663.66,"id":5858055}]}]}
{"op":"mcm","clk":"1004044717","pt":1580653104372,"mc":[{"id":"1.168224459","rc":[{"batb":[[0,1.88,230.76],[1,1.86,119.9],[2,1.79,111.55]],"batl":[[0,1.92,10.11],[1,1.95,95.04],[2,1.97,297.13]],"ltp":1.94,"tv":663.66,"id":5858055},{"batb":[[2,1.5,113.58]],"batl":[[0,2.16,232.55],[1,2.18,186],[2,1000,0.02]],"ltp":2.06,"tv":538.09,"id":7444998}]}]}
{"op":"mcm","clk":"1004044861","pt":1580653105190,"mc":[{"id":"1.168224459","rc":[{"batb":[[2,1.85,73.65]],"ltp":1.94,"tv":663.66,"id":5858055},{"batb":[[1,1.98,117.79],[2,1.96,139.56]],"ltp":2.06,"tv":538.09,"id":7444998}]}]}
{"op":"mcm","clk":"1004044969","pt":1580653105769,"mc":[{"id":"1.168224459","rc":[{"batb":[[1,2,42.01],[2,1.98,117.79]],"batl":[[2,2.24,33.61]],"ltp":2.06,"tv":538.09,"id":7444998}]}]}
{"op":"mcm","clk":"1004046379","pt":1580653113387,"mc":[{"id":"1.168224459","rc":[{"batl":[[0,1.95,95.04],[1,1.97,102.13],[2,2,42.01]],"ltp":1.94,"tv":663.66,"id":5858055},{"batl":[[0,2.24,33.61],[1,1000,0.02],[2,2.24,0]],"ltp":2.06,"tv":538.09,"id":7444998}]}]}
{"op":"mcm","clk":"1004046455","pt":1580653113776,"mc":[{"id":"1.168224459","rc":[{"batb":[[0,1.81,51.25],[1,1.74,89.46],[2,1.55,420.5]],"batl":[[0,2,42.01],[1,2.42,286.52],[2,1000,0.02]],"ltp":1.94,"tv":663.66,"id":5858055},{"batb":[[0,2,42.01],[1,1.98,117.79],[2,1.96,139.56]],"ltp":2.06,"tv":538.09,"id":7444998}]}]}
{"op":"mcm","clk":"1004046677","pt":1580653114897,"mc":[{"id":"1.168224459","rc":[{"batb":[[0,1.74,89.46],[1,1.55,420.5],[2,1.4,75.73]],"batl":[[0,2.42,286.52],[1,1000,0.02],[2,1000,0]],"ltp":1.94,"tv":663.66,"id":5858055},{"batb":[[0,1.98,117.79],[1,1.96,139.56],[2,1.5,113.58]],"batl":[[0,1000,0.02],[1,1000,0]],"ltp":2.06,"tv":538.09,"id":7444998}]}]}
{"op":"mcm","clk":"1004047010","pt":1580653116683,"mc":[{"id":"1.168224459","rc":[{"batb":[[0,1.78,93.46],[1,1.76,143.53],[2,1.74,89.46]],"batl":[[0,2.02,87.45],[1,2.04,92.08],[2,2.42,286.52]],"ltp":1.94,"tv":663.66,"id":5858055}]}]}
{"op":"mcm","clk":"1004050377","pt":1580653134116,"mc":[{"id":"1.168224459","rc":[{"batb":[[0,1.74,89.46],[1,1.55,420.5],[2,1.4,75.73]],"ltp":1.94,"tv":663.66,"id":5858055}]}]}
{"op":"mcm","clk":"1004050940","pt":1580653136954,"mc":[{"id":"1.168224459","rc":[{"batb":[[0,1.95,93.41],[1,1.94,173.14],[2,1.93,206.61]],"batl":[[0,2,6.95],[1,2.02,87.45],[2,2.04,253.08]],"ltp":1.94,"tv":663.66,"id":5858055},{"batb":[[0,2,6.95],[1,1.98,117.79],[2,1.96,139.56]],"batl":[[0,2.06,10.14],[1,2.1,218],[2,2.14,86.53]],"ltp":2.06,"tv":538.09,"id":7444998}]}]}
{"op":"mcm","clk":"1004052754","pt":1580653146047,"mc":[{"id":"1.168224459","rc":[{"batb":[[0,1.86,48.73],[1,1.83,75.85],[2,1.55,420.5]],"batl":[[0,2.06,39.49],[1,2.42,286.52],[2,1000,1]],"ltp":1.94,"tv":663.66,"id":5858055},{"batb":[[0,1.96,139.56],[1,1.94,44.53],[2,1.93,63.65]],"batl":[[0,2.18,35.29],[1,1000,0.02],[2,2.14,0]],"ltp":2.06,"tv":538.09,"id":7444998}]}]}
{"op":"mcm","clk":"1004052929","pt":1580653146959,"mc":[{"id":"1.168224459","rc":[{"batb":[[0,1.83,75.85],[1,1.55,420.5],[2,1.4,75.73]],"batl":[[0,2.42,286.52],[1,1000,1],[2,1000,0]],"ltp":1.94,"tv":663.66,"id":5858055},{"batb":[[1,1.93,63.65],[2,1.5,113.58]],"batl":[[0,1000,0.02],[1,1000,0]],"ltp":2.06,"tv":538.09,"id":7444998}]}]}
{"op":"mcm","clk":"1004053330","pt":1580653148988,"mc":[{"id":"1.168224459","rc":[{"batb":[[0,1.88,84.55],[1,1.86,119.86],[2,1.83,75.85]],"batl":[[0,2.08,146.83],[1,2.1,84.65],[2,2.42,286.52]],"ltp":1.94,"tv":663.66,"id":5858055}]}]}
{"op":"mcm","clk":"1004054119","pt":1580653152786,"mc":[{"id":"1.168224459","rc":[{"batb":[[0,1.83,75.85],[1,1.55,420.5],[2,1.4,75.73]],"batl":[[0,2.42,286.52],[1,1000,1],[2,2.42,0]],"ltp":1.94,"tv":663.66,"id":5858055}]}]}
{"op":"mcm","clk":"1004054993","pt":1580653157353,"mc":[{"id":"1.168224459","rc":[{"batb":[[0,1.88,84.55],[1,1.86,119.86],[2,1.83,75.85]],"batl":[[0,2.08,146.83],[1,2.1,84.65],[2,2.42,286.52]],"ltp":1.94,"tv":663.66,"id":5858055}]}]}
{"op":"mcm","clk":"1004055754","pt":1580653161266,"mc":[{"id":"1.168224459","rc":[{"trd":[[1.88,18.02]],"batb":[[0,1.88,82.55]],"ltp":1.88,"tv":667.66,"id":5858055}],"tv":1205.76}]}
{"op":"mcm","clk":"1004056731","pt":1580653166301,"mc":[{"id":"1.168224459","rc":[{"batl":[[0,2.42,286.52],[1,1000,1],[2,2.42,0]],"ltp":1.88,"tv":667.66,"id":5858055}]}]}
{"op":"mcm","clk":"1004057326","pt":1580653169305,"mc":[{"id":"1.168224459","rc":[{"batl":[[0,1.92,19.45],[1,1.94,78.44],[2,1.95,191]],"ltp":1.88,"tv":667.66,"id":5858055},{"batb":[[0,2.04,92.59],[1,1.96,285.19],[2,1.93,63.65]],"batl":[[0,2.16,7.86],[1,2.2,446.93],[2,1000,0.02]],"ltp":2.06,"tv":538.09,"id":7444998}]}]}
{"op":"mcm","clk":"1004057545","pt":1580653170330,"mc":[{"id":"1.168224459","rc":[{"trd":[[1.92,5.27]],"batl":[[0,1.92,16.81]],"ltp":1.92,"tv":672.93,"id":5858055},{"batb":[[0,2.08,101.89],[1,2.04,132.92],[2,1.99,115.9]],"batl":[[2,2.28,32.77]],"ltp":2.06,"tv":538.09,"id":7444998}],"tv":1211.03}]}
{"op":"mcm","clk":"1004059400","pt":1580653179715,"mc":[{"id":"1.168224459","rc":[{"batl":[[0,1.94,78.44],[1,1.95,191],[2,1.96,336.04]],"ltp":1.92,"tv":672.93,"id":5858055},{"batl":[[0,2.2,446.93],[1,2.28,32.77],[2,1000,0.02]],"ltp":2.06,"tv":538.09,"id":7444998}]}]}
{"op":"mcm","clk":"1004059761","pt":1580653181437,"mc":[{"id":"1.168224459","rc":[{"batb":[[0,1.83,75.85],[1,1.8,52.09],[2,1.73,92.22]],"batl":[[0,1.98,42.01],[1,2.42,286.52],[2,1000,1]],"ltp":1.92,"tv":672.93,"id":5858055},{"batb":[[1,2.04,40.33]],"batl":[[0,2.28,32.77],[1,1000,0.02],[2,1000,0]],"ltp":2.06,"tv":538.09,"id":7444998}]}]}
{"op":"mcm","clk":"1004059778","pt":1580653181543,"mc":[{"id":"1.168224459","rc":[{"batb":[[0,1.8,52.09],[1,1.73,92.22],[2,1.55,420.5]],"ltp":1.92,"tv":672.93,"id":5858055},{"batb":[[0,2.04,40.33],[1,1.99,115.9],[2,1.97,2.61]],"ltp":2.06,"tv":538.09,"id":7444998}]}]}
{"op":"mcm","clk":"1004060069","pt":1580653182904,"mc":[{"id":"1.168224459","rc":[{"batb":[[0,1.73,92.22],[1,1.55,420.5],[2,1.4,75.73]],"batl":[[0,2.42,286.52],[1,1000,1],[2,1000,0]],"ltp":1.92,"tv":672.93,"id":5858055},{"batb":[[0,1.99,115.9],[1,1.97,2.61],[2,1.96,139.56]],"batl":[[0,1000,0.02],[1,1000,0]],"ltp":2.06,"tv":538.09,"id":7444998}]}]}
{"op":"mcm","clk":"1004060348","pt":1580653184396,"mc":[{"id":"1.168224459","rc":[{"batb":[[0,1.76,127.48],[1,1.74,149.26],[2,1.73,92.22]],"batl":[[0,2.02,83.53],[1,2.04,92.08],[2,2.42,286.52]],"ltp":1.92,"tv":672.93,"id":5858055}]}]}
{"op":"mcm","clk":"1004061649","pt":1580653190812,"mc":[{"id":"1.168224459","rc":[{"batb":[[0,1.73,92.22],[1,1.55,420.5],[2,1.4,75.73]],"ltp":1.92,"tv":672.93,"id":5858055}]}]}
{"op":"mcm","clk":"1004062006","pt":1580653192790,"mc":[{"id":"1.168224459","rc":[{"batb":[[1,1.96,139.56],[2,1.93,63.65]],"ltp":2.06,"tv":538.09,"id":7444998}]}]}
{"op":"mcm","clk":"1004062224","pt":1580653193912,"mc":[{"id":"1.168224459","rc":[{"batb":[[0,1.95,97.48],[1,1.94,8.22],[2,1.93,106.73]],"batl":[[0,1.98,9.53],[1,2.02,83.53],[2,2.04,556.79]],"ltp":1.92,"tv":672.93,"id":5858055},{"batl":[[0,2.12,413.09],[1,2.16,523.54],[2,1000,0.02]],"ltp":2.06,"tv":538.09,"id":7444998}]}]}
{"op":"mcm","clk":"1004062469","pt":1580653195204,"mc":[{"id":"1.168224459","rc":[{"batb":[[2,1.86,71.76]],"ltp":2.06,"tv":538.09,"id":7444998}]}]}
{"op":"mcm","clk":"1004062600","pt":1580653195835,"mc":[{"id":"1.168224459","rc":[{"batb":[[2,1.93,44.53]],"batl":[[1,2.16,559.67]],"ltp":2.06,"tv":538.09,"id":7444998}]}]}
{"op":"mcm","clk":"1004063618","pt":1580653201021,"mc":[{"id":"1.168224459","rc":[{"batb":[[0,2.02,13.17],[1,1.99,115.9],[2,1.96,139.56]],"ltp":2.06,"tv":538.09,"id":7444998}]}]}
{"op":"mcm","clk":"1004064173","pt":1580653203512,"mc":[{"id":"1.168224459","rc":[{"trd":[[1.95,1.96]],"batb":[[0,1.95,96.5]],"ltp":1.95,"tv":674.9,"id":5858055}],"tv":1212.99}]}
{"op":"mcm","clk":"1004066935","pt":1580653217133,"mc":[{"id":"1.168224459","rc":[{"batb":[[0,1.99,115.9],[1,1.96,139.56],[2,1.93,44.53]],"ltp":2.06,"tv":538.09,"id":7444998}]}]}
{"op":"mcm","clk":"1004067128","pt":1580653218056,"mc":[{"id":"1.168224459","rc":[{"trd":[[1.95,6.92]],"batb":[[0,1.95,94.02]],"ltp":1.95,"tv":679.85,"id":5858055}],"tv":1217.95}]}
{"op":"mcm","clk":"1004067331","pt":1580653219143,"mc":[{"id":"1.168224459","rc":[{"batb":[[0,1.88,47.05],[1,1.84,74.59],[2,1.55,420.5]],"batl":[[0,2.08,38.65],[1,2.42,286.52],[2,1000,0.02]],"ltp":1.95,"tv":679.85,"id":5858055},{"batb":[[0,1.96,139.56],[1,1.93,44.53],[2,1.86,71.76]],"batl":[[0,2.16,36.13],[1,1000,0.02],[2,1000,0]],"ltp":2.06,"tv":538.09,"id":7444998}]}]}
{"op":"mcm","clk":"1004067573","pt":1580653220344,"mc":[{"id":"1.168224459","rc":[{"batb":[[0,2.06,13.17],[1,1.96,139.56],[2,1.93,44.53]],"ltp":2.06,"tv":538.09,"id":7444998}]}]}
{"op":"mcm","clk":"1004067685","pt":1580653220850,"mc":[{"id":"1.168224459","rc":[{"batb":[[0,1.84,74.59],[1,1.55,420.5],[2,1.4,75.73]],"batl":[[0,2.42,286.52],[1,1000,0.02],[2,1000,0]],"ltp":1.95,"tv":679.85,"id":5858055},{"batb":[[2,1.86,71.76]],"batl":[[0,1000,0.02],[1,1000,0]],"ltp":2.06,"tv":538.09,"id":7444998}]}]}
{"op":"mcm","clk":"1004067908","pt":1580653221968,"mc":[{"id":"1.168224459","rc":[{"batb":[[0,1.88,90.52],[1,1.86,119.86],[2,1.84,74.59]],"batl":[[0,2.18,103.96],[1,2.2,74.17],[2,2.42,286.52]],"ltp":1.95,"tv":679.85,"id":5858055}]}]}
{"op":"mcm","clk":"1004068267","pt":1580653223764,"mc":[{"id":"1.168224459","rc":[{"trd":[[2.06,9.09]],"batb":[[0,2.06,9.39]],"ltp":2.06,"tv":545.66,"id":7444998}],"tv":1225.52}]}
{"op":"mcm","clk":"1004070413","pt":1580653234267,"mc":[{"id":"1.168224459","rc":[{"trd":[[2.06,27.86]],"batb":[[0,1.96,139.56],[1,1.86,71.76],[2,1.4,75.73]],"batl":[[0,2,15.43],[1,1000,0.02]],"ltp":2.06,"tv":564.44,"id":7444998}],"tv":1244.3}]}
{"op":"mcm","clk":"1004070589","pt":1580653235192,"mc":[{"id":"1.168224459","rc":[{"batl":[[0,2.42,286.52],[1,1000,0.02],[2,2.42,0]],"ltp":1.95,"tv":679.85,"id":5858055}]}]}
{"op":"mcm","clk":"1004071232","pt":1580653238202,"mc":[{"id":"1.168224459","rc":[{"trd":[[2,29.76]],"batl":[[0,1.92,17.54],[1,1.95,322.65],[2,1.96,248.31]],"ltp":2.0,"tv":695.28,"id":5858055},{"trd":[[2,29.6]],"batb":[[0,2.04,105.27],[1,1.96,139.56],[2,1.86,71.76]],"batl":[[0,2.16,9.55],[1,2.2,436.05],[2,1000,0.02]],"ltp":2.0,"tv":579.87,"id":7444998}],"tv":1275.16}]}
{"op":"mcm","clk":"1004071465","pt":1580653239269,"mc":[{"id":"1.168224459","rc":[{"batb":[[0,2.06,103.7],[1,2.04,105.27],[2,1.96,139.56]],"ltp":2.0,"tv":579.87,"id":7444998}]}]}
{"op":"mcm","clk":"1004071661","pt":1580653240192,"mc":[{"id":"1.168224459","rc":[{"batb":[[0,2.08,2.57],[1,2.06,103.7],[2,2.04,105.27]],"batl":[[2,2.22,33.61]],"ltp":2.0,"tv":579.87,"id":7444998}]}]}
{"op":"mcm","clk":"1004073375","pt":1580653248568,"mc":[{"id":"1.168224459","rc":[{"trd":[[1.92,22.81]],"batl":[[0,1.95,322.65],[1,1.96,248.31],[2,1.97,102.11]],"ltp":1.92,"tv":712.82,"id":5858055},{"trd":[[2.06,94.32],[2.08,21.34]],"batb":[[0,2.06,70.47],[1,2.04,105.27],[2,1.99,42.01]],"ltp":2.06,"tv":667.68,"id":7444998}],"tv":1380.5}]}
{"op":"mcm","clk":"1004073998","pt":1580653251679,"mc":[{"id":"1.168224459","rc":[{"batl":[[0,2.08,25.33],[1,2.16,9.55],[2,2.2,436.05]],"ltp":2.06,"tv":667.68,"id":7444998}]}]}
{"op":"mcm","clk":"1004074276","pt":1580653253015,"mc":[{"id":"1.168224459","rc":[{"batb":[[0,1.78,82.93],[1,1.55,420.5],[2,1.4,75.73]],"batl":[[0,2.42,286.52],[1,1000,0.02],[2,1.97,0]],"ltp":1.92,"tv":712.82,"id":5858055},{"batb":[[0,1.96,139.56],[1,1.95,62],[2,1.5,113.58]],"batl":[[0,2.08,265.33],[1,1000,0.02],[2,2.2,0]],"ltp":2.06,"tv":667.68,"id":7444998}]}]}
{"op":"mcm","clk":"1004075020","pt":1580653256095,"mc":[{"id":"1.168224459","rc":[{"batb":[[0,1.82,132.5],[1,1.8,215.55],[2,1.55,420.5]],"batl":[[0,2.06,88.72],[1,2.08,87.01],[2,2.42,286.52]],"ltp":1.92,"tv":712.82,"id":5858055},{"batb":[[2,1.94,62.55]],"ltp":2.06,"tv":667.68,"id":7444998}]}]}
{"op":"mcm","clk":"1004076011","pt":1580653260618,"mc":[{"id":"1.168224459","rc":[{"batl":[[0,2.08,240]],"ltp":2.06,"tv":667.68,"id":7444998}]}]}
{"op":"mcm","clk":"1004076550","pt":1580653263236,"mc":[{"id":"1.168224459","rc":[{"trd":[[1.96,86.2]],"batb":[[0,1.96,124.94]],"batl":[[0,1000,0.02],[1,1000,0]],"ltp":1.96,"tv":696.91,"id":7444998}],"tv":1409.74}]}
{"op":"mcm","clk":"1004076699","pt":1580653263892,"mc":[{"id":"1.168224459","rc":[{"batl":[[0,2.42,286.52],[1,1000,0.02],[2,2.42,0]],"ltp":1.92,"tv":712.82,"id":5858055},{"batl":[[0,2.04,25.33],[1,1000,0.02]],"ltp":1.96,"tv":696.91,"id":7444998}]}]}
{"op":"mcm","clk":"1004077041","pt":1580653265491,"mc":[{"id":"1.168224459","rc":[{"batl":[[0,1000,0.02],[1,1000,0]],"ltp":1.92,"tv":712.82,"id":5858055}]}]}
{"op":"mcm","clk":"1004077370","pt":1580653267122,"mc":[{"id":"1.168224459","rc":[{"trd":[[1.96,362.47]],"batl":[[0,1.89,353.68],[1,1.91,112.14],[2,1.92,112.28]],"ltp":1.96,"tv":739.21,"id":5858055},{"trd":[[2.04,25.33]],"batb":[[0,2.02,96.61],[1,1.96,124.94],[2,1.95,62]],"batl":[[0,2.2,11.99],[1,2.28,254.09],[2,2.3,208]],"ltp":2.04,"tv":722.24,"id":7444998}],"tv":1461.46}]}
{"op":"mcm","clk":"1004077625","pt":1580653268396,"mc":[{"id":"1.168224459","rc":[{"batb":[[2,1.76,89.38]],"ltp":1.96,"tv":739.21,"id":5858055},{"batb":[[0,2.14,93.55],[1,2.04,35.31],[2,2.02,205.43]],"ltp":2.04,"tv":722.24,"id":7444998}]}]}
{"op":"mcm","clk":"1004077705","pt":1580653268824,"mc":[{"id":"1.168224459","rc":[{"batb":[[1,2.04,54.23]],"ltp":2.04,"tv":722.24,"id":7444998}]}]}
{"op":"mcm","clk":"1004077962","pt":1580653270124,"mc":[{"id":"1.168224459","rc":[{"batb":[[2,1.77,53.77]],"ltp":1.96,"tv":739.21,"id":5858055},{"batb":[[1,2.08,38.65],[2,2.04,54.23]],"ltp":2.04,"tv":722.24,"id":7444998}]}]}
{"op":"mcm","clk":"1004078194","pt":1580653271214,"mc":[{"id":"1.168224459","rc":[{"batb":[[2,2.02,205.43]],"ltp":2.04,"tv":722.24,"id":7444998}]}]}
{"op":"mcm","clk":"1004079240","pt":1580653276140,"mc":[{"id":"1.168224459","rc":[{"batb":[[0,1.77,53.77],[1,1.76,89.38],[2,1.55,420.5]],"batl":[[0,1.95,42.01],[1,2.3,309.75],[2,1000,0.02]],"ltp":1.96,"tv":739.21,"id":5858055},{"batb":[[0,2.08,38.65],[1,2.02,108.82],[2,1.96,124.94]],"batl":[[0,2.32,31.09],[1,1000,0.02],[2,2.3,0]],"ltp":2.04,"tv":722.24,"id":7444998}]}]}
{"op":"mcm","clk":"1004079403","pt":1580653276944,"mc":[{"id":"1.168224459","rc":[{"batb":[[0,1.76,89.38],[1,1.55,420.5],[2,1.4,75.73]],"batl":[[0,2.3,309.75],[1,1000,0.02],[2,1000,0]],"ltp":1.96,"tv":739.21,"id":5858055},{"batb":[[0,2.02,108.82],[1,1.96,124.94],[2,1.94,62.55]],"batl":[[0,1000,0.02],[1,1000,0]],"ltp":2.04,"tv":722.24,"id":7444998}]}]}
{"op":"mcm","clk":"1004079865","pt":1580653278868,"mc":[{"id":"1.168224459","rc":[{"batb":[[0,1.79,87.64],[1,1.77,140.83],[2,1.76,89.38]],"batl":[[0,1.97,117.93],[1,1.99,99.07],[2,2.3,309.75]],"ltp":1.96,"tv":739.21,"id":5858055}]}]}
{"op":"mcm","clk":"1004082695","pt":1580653292066,"mc":[{"id":"1.168224459","rc":[{"batl":[[0,2.3,309.75],[1,1000,0.02],[2,2.3,0]],"ltp":1.96,"tv":739.21,"id":5858055}]}]}
{"op":"mcm","clk":"1004083389","pt":1580653295447,"mc":[{"id":"1.168224459","rc":[{"batb":[[0,1.8,10.13],[1,1.79,87.64],[2,1.77,140.83]],"batl":[[0,1.84,195],[1,1.85,119.73],[2,1.86,423.03]],"ltp":1.96,"tv":739.21,"id":5858055},{"batb":[[0,2.2,7.18],[1,2.16,99.08],[2,2.02,108.82]],"batl":[[0,2.36,173],[1,1000,0.02]],"ltp":2.04,"tv":722.24,"id":7444998}]}]}
{"op":"mcm","clk":"1004083480","pt":1580653295975,"mc":[{"id":"1.168224459","rc":[{"batb":[[0,2.2,92.71],[2,2.12,133.35]],"batl":[[1,2.38,30.25],[2,1000,0.02]],"ltp":2.04,"tv":722.24,"id":7444998}]}]}
{"op":"mcm","clk":"1004086591","pt":1580653311402,"mc":[{"id":"1.168224459","rc":[{"trd":[[1.86,99.93]],"batb":[[0,1.73,151.32],[1,1.46,435.71],[2,1.4,75.72]],"batl":[[0,1.9,42.01],[1,2.3,309.75],[2,1000,0.02]],"ltp":1.86,"tv":839.14,"id":5858055},{"trd":[[2.16,284.21]],"batb":[[0,2.12,133.35],[1,1.96,124.94],[2,1.6,75.72]],"batl":[[0,2.14,54.87]],"ltp":2.16,"tv":1006.45,"id":7444998}],"tv":1845.6}]}
{"op":"mcm","clk":"1004086694","pt":1580653311866,"mc":[{"id":"1.168224459","rc":[{"batl":[[1,1000,0.02],[2,1000,0]],"ltp":2.16,"tv":1006.45,"id":7444998}]}]}
{"op":"mcm","clk":"1004086938","pt":1580653313190,"mc":[{"id":"1.168224459","rc":[{"batb":[[0,1.73,94.18]],"batl":[[0,2.3,309.75],[1,1000,0.02],[2,1000,0]],"ltp":1.86,"tv":839.14,"id":5858055},{"batb":[[0,2.12,96.39]],"batl":[[0,1000,0.02],[1,1000,0]],"ltp":2.16,"tv":1006.45,"id":7444998}]}]}
{"op":"mcm","clk":"1004087137","pt":1580653314191,"mc":[{"id":"1.168224459","rc":[{"batb":[[0,1.76,137.28],[1,1.74,149.28],[2,1.73,94.18]],"batl":[[0,1.9,112.75],[1,1.92,110.37],[2,2.3,309.75]],"ltp":1.86,"tv":839.14,"id":5858055}]}]}
{"op":"mcm","clk":"1004088084","pt":1580653318877,"mc":[{"id":"1.168224459","rc":[{"batl":[[0,2.3,309.75],[1,1000,0.02],[2,2.3,0]],"ltp":1.86,"tv":839.14,"id":5858055}]}]}
{"op":"mcm","clk":"1004088491","pt":1580653320981,"mc":[{"id":"1.168224459","rc":[{"batl":[[0,1000,0.02],[1,1000,0]],"ltp":1.86,"tv":839.14,"id":5858055}]}]}
{"op":"mcm","clk":"1004088775","pt":1580653322396,"mc":[{"id":"1.168224459","rc":[{"batb":[[0,1.76,155.33]],"batl":[[0,1.81,197],[1,1.82,90.48],[2,1.83,333.19]],"ltp":1.86,"tv":839.14,"id":5858055},{"batb":[[0,2.24,7.91],[1,2.22,91.71],[2,2.2,34.45]],"batl":[[0,2.36,137.61],[1,2.4,139],[2,2.48,27.73]],"ltp":2.16,"tv":1006.45,"id":7444998}]}]}
{"op":"mcm","clk":"1004088895","pt":1580653322987,"mc":[{"id":"1.168224459","rc":[{"batb":[[0,2.24,88.72]],"ltp":2.16,"tv":1006.45,"id":7444998}]}]}
{"op":"mcm","clk":"1004091834","pt":1580653337733,"mc":[{"id":"1.168224459","rc":[{"trd":[[2.24,4.54]],"batb":[[0,2.24,86.45]],"ltp":2.24,"tv":1010.99,"id":7444998}],"tv":1850.14}]}
{"op":"mcm","clk":"1004093890","pt":1580653347942,"mc":[{"id":"1.168224459","rc":[{"batb":[[0,1.76,137.28]],"ltp":1.86,"tv":839.14,"id":5858055},{"batb":[[0,2.24,80.81]],"ltp":2.24,"tv":1010.99,"id":7444998}]}]}
{"op":"mcm","clk":"1004094447","pt":1580653350842,"mc":[{"id":"1.168224459","rc":[{"batl":[[2,1.83,353.15]],"ltp":1.86,"tv":839.14,"id":5858055},{"batl":[[0,2.28,6.05],[1,2.36,137.61],[2,2.4,139]],"ltp":2.24,"tv":1010.99,"id":7444998}]}]}
{"op":"mcm","clk":"1004103616","pt":1580653398231,"mc":[{"id":"1.168224459","rc":[{"batb":[[0,1.69,60.49],[1,1.63,116.13],[2,1.46,435.71]],"batl":[[0,1.85,42.01],[1,2.16,342.82],[2,1000,0.02]],"ltp":1.86,"tv":839.14,"id":5858055},{"batb":[[0,2.2,34.45],[1,2.14,92.69],[2,1.96,124.94]],"batl":[[0,2.48,27.73],[1,1000,0.02],[2,2.4,0]],"ltp":2.24,"tv":1010.99,"id":7444998}]}]}
{"op":"mcm","clk":"1004103788","pt":1580653399176,"mc":[{"id":"1.168224459","rc":[{"batb":[[0,1.63,116.13],[1,1.46,435.71],[2,1.3,113.58]],"batl":[[0,2.16,342.82],[1,1000,0.02],[2,1000,0]],"ltp":1.86,"tv":839.14,"id":5858055},{"batb":[[0,2.14,92.69],[1,1.96,124.94],[2,1.6,75.72]],"batl":[[0,1000,0.02],[1,1000,0]],"ltp":2.24,"tv":1010.99,"id":7444998}]}]}
{"op":"mcm","clk":"1004104115","pt":1580653401042,"mc":[{"id":"1.168224459","rc":[{"batb":[[0,1.66,135.46],[1,1.65,90.31],[2,1.63,116.13]],"batl":[[0,1.89,93.21],[1,1.91,112.18],[2,2.16,342.82]],"ltp":1.86,"tv":839.14,"id":5858055}]}]}
{"op":"mcm","clk":"1004104622","pt":1580653403920,"mc":[{"id":"1.168224459","rc":[{"batb":[[0,1.63,116.13],[1,1.46,435.71],[2,1.3,113.58]],"batl":[[0,2.16,342.82],[1,1000,0.02],[2,2.16,0]],"ltp":1.86,"tv":839.14,"id":5858055}]}]}
{"op":"mcm","clk":"1004105723","pt":1580653409358,"mc":[{"id":"1.168224459","rc":[{"batb":[[0,1.66,135.46],[1,1.65,90.31],[2,1.63,116.13]],"batl":[[0,1.89,93.21],[1,1.91,112.18],[2,2.16,342.82]],"ltp":1.86,"tv":839.14,"id":5858055}]}]}
{"op":"mcm","clk":"1004105890","pt":1580653410179,"mc":[{"id":"1.168224459","rc":[{"batl":[[2,2.1,50.41]],"ltp":1.86,"tv":839.14,"id":5858055}]}]}
{"op":"mcm","clk":"1004108448","pt":1580653423577,"mc":[{"id":"1.168224459","rc":[{"batb":[[0,1.63,116.13],[1,1.46,435.71],[2,1.3,113.58]],"ltp":1.86,"tv":839.14,"id":5858055}]}]}
{"op":"mcm","clk":"1004108692","pt":1580653424872,"mc":[{"id":"1.168224459","rc":[{"batb":[[1,1.3,113.59],[2,1.25,378.62]],"ltp":1.86,"tv":839.14,"id":5858055}]}]}
{"op":"mcm","clk":"1004108988","pt":1580653426274,"mc":[{"id":"1.168224459","rc":[{"batb":[[0,1.8,1000.84],[1,1.76,474.05],[2,1.63,116.13]],"batl":[[0,1.88,187],[1,1.89,337.68],[2,1.91,112.18]],"ltp":1.86,"tv":839.14,"id":5858055},{"batl":[[0,2.2,12.81],[1,2.26,906.02],[2,2.3,187]],"ltp":2.24,"tv":1010.99,"id":7444998}]}]}
{"op":"mcm","clk":"1004109205","pt":1580653427449,"mc":[{"id":"1.168224459","rc":[{"batb":[[0,1.83,92.86],[1,1.81,130.86],[2,1.8,183.01]],"ltp":1.86,"tv":839.14,"id":5858055},{"batb":[[1,2.06,102.84],[2,1.96,124.94]],"batl":[[1,2.26,90.6]],"ltp":2.24,"tv":1010.99,"id":7444998}]}]}
{"op":"mcm","clk":"1004109320","pt":1580653428198,"mc":[{"id":"1.168224459","rc":[{"batl":[[2,1.91,154.19]],"ltp":1.86,"tv":839.14,"id":5858055},{"batb":[[1,2.1,37.81],[2,2.06,102.84]],"ltp":2.24,"tv":1010.99,"id":7444998}]}]}
{"op":"mcm","clk":"1004110974","pt":1580653436386,"mc":[{"id":"1.168224459","rc":[{"batb":[[0,1.74,56.29],[1,1.69,100.87],[2,1.5,426.9]],"batl":[[0,1.91,42.01],[1,2.1,50.41],[2,2.16,342.82]],"ltp":1.86,"tv":839.14,"id":5858055},{"batb":[[0,2.1,37.81],[1,2.06,102.84],[2,1.96,124.94]],"batl":[[0,2.38,30.25],[1,1000,0.02],[2,2.3,0]],"ltp":2.24,"tv":1010.99,"id":7444998}]}]}
{"op":"mcm","clk":"1004111133","pt":1580653437180,"mc":[{"id":"1.168224459","rc":[{"batb":[[0,1.69,100.87],[1,1.5,426.9],[2,1.3,113.59]],"batl":[[0,2.1,50.41],[1,2.16,342.82],[2,1000,0.02]],"ltp":1.86,"tv":839.14,"id":5858055},{"batb":[[0,2.06,102.84],[1,1.96,124.94],[2,1.6,75.72]],"batl":[[0,1000,0.02],[1,1000,0]],"ltp":2.24,"tv":1010.99,"id":7444998}]}]}
{"op":"mcm","clk":"1004111516","pt":1580653439112,"mc":[{"id":"1.168224459","rc":[{"batb":[[0,1.74,84.53],[1,1.72,155.07],[2,1.69,100.87]],"batl":[[0,1.95,90.86],[1,1.97,102.12],[2,2.1,50.41]],"ltp":1.86,"tv":839.14,"id":5858055}]}]}
{"op":"mcm","clk":"1004112797","pt":1580653445367,"mc":[{"id":"1.168224459","rc":[{"batb":[[0,1.69,100.87],[1,1.5,426.9],[2,1.3,113.59]],"ltp":1.86,"tv":839.14,"id":5858055}]}]}
{"op":"mcm","clk":"1004113431","pt":1580653448345,"mc":[{"id":"1.168224459","rc":[{"batb":[[0,1.88,124.64],[1,1.86,119.9],[2,1.69,100.87]],"batl":[[0,1.94,174.31],[1,1.95,90.86],[2,1.97,102.12]],"ltp":1.86,"tv":839.14,"id":5858055},{"batb":[[0,2.06,271.54]],"batl":[[0,2.12,12.63],[1,2.16,91.47],[2,2.18,98.91]],"ltp":2.24,"tv":1010.99,"id":7444998}]}]}
{"op":"mcm","clk":"1004113636","pt":1580653449340,"mc":[{"id":"1.168224459","rc":[{"batb":[[1,1.86,195.04],[2,1.77,87.34]],"ltp":1.86,"tv":839.14,"id":5858055},{"batb":[[1,2.02,111.49],[2,1.96,124.94]],"ltp":2.24,"tv":1010.99,"id":7444998}]}]}
{"op":"mcm","clk":"1004113809","pt":1580653450213,"mc":[{"id":"1.168224459","rc":[{"batb":[[2,1.78,53.77]],"batl":[[2,1.97,144.13]],"ltp":1.86,"tv":839.14,"id":5858055},{"batb":[[1,2.04,40.33],[2,2.02,111.49]],"ltp":2.24,"tv":1010.99,"id":7444998}]}]}
{"op":"mcm","clk":"1004115281","pt":1580653457337,"mc":[{"id":"1.168224459","rc":[{"batl":[[0,1.95,90.86],[1,1.97,144.13],[2,2.1,50.41]],"ltp":1.86,"tv":839.14,"id":5858055},{"batb":[[0,2.06,102.84]],"batl":[[0,2.16,91.47],[1,2.18,98.91],[2,2.3,31.93]],"ltp":2.24,"tv":1010.99,"id":7444998}]}]}
{"op":"mcm","clk":"1004115386","pt":1580653457839,"mc":[{"id":"1.168224459","rc":[{"batb":[[0,1.78,53.77],[1,1.77,87.34],[2,1.5,426.9]],"batl":[[0,1.97,42.01],[1,2.1,50.41],[2,2.16,342.82]],"ltp":1.86,"tv":839.14,"id":5858055},{"batb":[[0,2.04,40.33],[1,2.02,111.49],[2,1.96,124.94]],"batl":[[0,2.3,31.93],[1,1000,0.02],[2,2.3,0]],"ltp":2.24,"tv":1010.99,"id":7444998}]}]}
{"op":"mcm","clk":"1004115695","pt":1580653459251,"mc":[{"id":"1.168224459","rc":[{"batb":[[0,1.77,87.34],[1,1.5,426.9],[2,1.4,75.73]],"batl":[[0,2.1,50.41],[1,2.16,342.82],[2,1000,0.02]],"ltp":1.86,"tv":839.14,"id":5858055},{"batb":[[0,2.02,111.49],[1,1.96,124.94],[2,1.5,113.58]],"batl":[[0,1000,0.02],[1,1000,0]],"ltp":2.24,"tv":1010.99,"id":7444998}]}]}
{"op":"mcm","clk":"1004116009","pt":1580653460649,"mc":[{"id":"1.168224459","rc":[{"batb":[[0,1.81,113.94],[1,1.79,135.75],[2,1.77,87.34]],"batl":[[0,2,108.38],[1,2.02,94.77],[2,2.1,50.41]],"ltp":1.86,"tv":839.14,"id":5858055}]}]}
{"op":"mcm","clk":"1004118128","pt":1580653470780,"mc":[{"id":"1.168224459","rc":[{"batb":[[0,1.77,87.34],[1,1.5,426.9],[2,1.4,75.73]],"ltp":1.86,"tv":839.14,"id":5858055}]}]}
{"op":"mcm","clk":"1004118651","pt":1580653473384,"mc":[{"id":"1.168224459","rc":[{"batb":[[1,1.4,75.73],[2,1.3,113.58]],"batl":[[0,2.1,50.41],[1,1000,0.02],[2,2.1,0]],"ltp":1.86,"tv":839.14,"id":5858055},{"batb":[[0,1.96,124.94],[1,1.5,113.58],[2,1.4,75.73]],"ltp":2.24,"tv":1010.99,"id":7444998}]}]}
{"op":"mcm","clk":"1004118795","pt":1580653473986,"mc":[{"id":"1.168224459","rc":[{"batb":[[0,1.89,108.14],[1,1.77,87.34],[2,1.4,75.73]],"ltp":1.86,"tv":839.14,"id":5858055},{"batl":[[0,2.08,97.79],[1,1000,0.02]],"ltp":2.24,"tv":1010.99,"id":7444998}]}]}
{"op":"mcm","clk":"1004119081","pt":1580653475287,"mc":[{"id":"1.168224459","rc":[{"batb":[[0,1.9,69.55],[1,1.89,108.14],[2,1.83,77.9]],"ltp":1.86,"tv":839.14,"id":5858055},{"batb":[[0,1.97,119.2],[1,1.96,124.94],[2,1.5,113.58]],"ltp":2.24,"tv":1010.99,"id":7444998}]}]}
{"op":"mcm","clk":"1004119189","pt":1580653475776,"mc":[{"id":"1.168224459","rc":[{"batb":[[0,1.89,108.14],[1,1.87,127.01],[2,1.85,121.98]],"batl":[[0,2.04,148.04],[1,2.06,89.48],[2,2.1,50.41]],"ltp":1.86,"tv":839.14,"id":5858055}]}]}
{"op":"mcm","clk":"1004120367","pt":1580653481127,"mc":[{"id":"1.168224459","rc":[{"batl":[[0,2.1,50.41],[1,2.42,286.52],[2,1000,0.02]],"ltp":1.86,"tv":839.14,"id":5858055},{"trd":[[2.08,47.01]],"batl":[[0,2.08,84.96]],"ltp":2.08,"tv":1036.65,"id":7444998}],"tv":1875.8}]}
{"op":"mcm","clk":"1004120813","pt":1580653483288,"mc":[{"id":"1.168224459","rc":[{"trd":[[1.92,114.85]],"batl":[[0,1.92,274.09],[1,1.96,964.15],[2,2.1,50.41]],"ltp":1.92,"tv":931.18,"id":5858055},{"trd":[[2.08,131.97]],"batb":[[0,2.02,986.34],[1,1.97,119.2],[2,1.96,124.94]],"batl":[[0,2.16,16.29],[1,2.24,471.55],[2,1000,0.02]],"ltp":2.08,"tv":1121.61,"id":7444998}],"tv":2052.8}]}
{"op":"mcm","clk":"1004121024","pt":1580653484275,"mc":[{"id":"1.168224459","rc":[{"batl":[[1,1.94,93.9],[2,1.96,242.12]],"ltp":1.92,"tv":931.18,"id":5858055},{"batb":[[0,2.1,99.14],[1,2.08,38.65],[2,2.06,39.49]],"batl":[[2,2.26,32.77]],"ltp":2.08,"tv":1121.61,"id":7444998}]}]}
{"op":"mcm","clk":"1004121068","pt":1580653484480,"mc":[{"id":"1.168224459","rc":[{"batl":[[2,1.96,200.11]],"ltp":1.92,"tv":931.18,"id":5858055},{"batb":[[1,2.06,39.49],[2,2.04,108.27]],"batl":[[2,1000,0.02]],"ltp":2.08,"tv":1121.61,"id":7444998}]}]}
{"op":"mcm","clk":"1004121547","pt":1580653486795,"mc":[{"id":"1.168224459","rc":[{"batl":[[2,1.95,42.01]],"ltp":1.92,"tv":931.18,"id":5858055},{"batl":[[2,2.32,31.09]],"ltp":2.08,"tv":1121.61,"id":7444998}]}]}
{"op":"mcm","clk":"1004123525","pt":1580653496188,"mc":[{"id":"1.168224459","rc":[{"batb":[[0,1.77,53.77],[1,1.76,88.6],[2,1.55,420.5]],"batl":[[0,1.95,42.01],[1,2.1,50.41],[2,2.3,309.75]],"ltp":1.92,"tv":931.18,"id":5858055},{"batb":[[0,2.06,39.49],[1,2.04,108.27],[2,1.96,124.94]],"batl":[[0,2.32,31.09],[1,1000,0.02],[2,2.32,0]],"ltp":2.08,"tv":1121.61,"id":7444998}]}]}
{"op":"mcm","clk":"1004123742","pt":1580653497213,"mc":[{"id":"1.168224459","rc":[{"batb":[[0,1.76,88.6],[1,1.55,420.5],[2,1.4,75.73]],"batl":[[0,2.1,50.41],[1,2.3,309.75],[2,1000,0.02]],"ltp":1.92,"tv":931.18,"id":5858055},{"batb":[[0,2.04,108.27],[1,1.96,124.94],[2,1.5,113.58]],"batl":[[0,1000,0.02],[1,1000,0]],"ltp":2.08,"tv":1121.61,"id":7444998}]}]}
{"op":"mcm","clk":"1004124167","pt":1580653499103,"mc":[{"id":"1.168224459","rc":[{"batb":[[0,1.8,146.23],[1,1.78,138.37],[2,1.76,88.6]],"batl":[[0,1.98,73.3],[1,2,97.63],[2,2.1,50.41]],"ltp":1.92,"tv":931.18,"id":5858055}]}]}
{"op":"mcm","clk":"1004124926","pt":1580653502695,"mc":[{"id":"1.168224459","rc":[{"batl":[[0,2.1,50.41],[1,2.3,309.75],[2,1000,0.02]],"ltp":1.92,"tv":931.18,"id":5858055}]}]}
{"op":"mcm","clk":"1004125542","pt":1580653505427,"mc":[{"id":"1.168224459","rc":[{"batl":[[0,1.85,175],[1,1.92,1120.18],[2,2.1,50.41]],"ltp":1.92,"tv":931.18,"id":5858055},{"batb":[[0,2.12,1019.6],[1,2.04,108.27],[2,1.96,124.94]],"batl":[[0,2.34,177],[1,1000,0.02]],"ltp":2.08,"tv":1121.61,"id":7444998}]}]}
{"op":"mcm","clk":"1004125750","pt":1580653506310,"mc":[{"id":"1.168224459","rc":[{"batb":[[0,1.8,156.84]],"batl":[[1,1.86,332.5],[2,1.87,159.27]],"ltp":1.92,"tv":931.18,"id":5858055},{"batb":[[0,2.2,93.08],[1,2.16,36.13],[2,2.12,101.96]],"batl":[[1,2.44,28.57],[2,1000,0.02]],"ltp":2.08,"tv":1121.61,"id":7444998}]}]}
{"op":"mcm","clk":"1004125917","pt":1580653507015,"mc":[{"id":"1.168224459","rc":[{"trd":[[2.16,298.05],[2.2,203.87]],"batb":[[0,2.16,29.21],[1,2.12,101.96],[2,2.1,98.2]],"batl":[[1,1000,0.02],[2,1000,0]],"ltp":2.16,"tv":1321.62,"id":7444998}],"tv":2252.81}]}
{"op":"mcm","clk":"1004126578","pt":1580653510007,"mc":[{"id":"1.168224459","rc":[{"batb":[[0,2.16,35.93]],"batl":[[1,2.42,29.41],[2,1000,0.02]],"ltp":2.16,"tv":1321.62,"id":7444998}]}]}
{"op":"mcm","clk":"1004128245","pt":1580653517441,"mc":[{"id":"1.168224459","rc":[{"batb":[[0,1.64,111.65],[1,1.46,435.71],[2,1.4,75.72]],"batl":[[0,2.1,50.41],[1,2.3,309.75],[2,1000,0.02]],"ltp":1.92,"tv":931.18,"id":5858055},{"batb":[[0,2.1,98.2],[1,2.04,108.27],[2,1.96,124.94]],"batl":[[0,1000,0.02],[1,2.42,0],[2,1000,0]],"ltp":2.16,"tv":1321.62,"id":7444998}]}]}
{"op":"mcm","clk":"1004128885","pt":1580653520239,"mc":[{"id":"1.168224459","rc":[{"batb":[[0,1.69,156.38],[1,1.67,281.14],[2,1.64,111.65]],"batl":[[0,1.94,83.48],[1,1.96,103.71],[2,2.1,50.41]],"ltp":1.92,"tv":931.18,"id":5858055},{"batb":[[1,2.08,100.79],[2,2.04,108.27]],"ltp":2.16,"tv":1321.62,"id":7444998}]}]}
{"op":"mcm","clk":"1004128939","pt":1580653520455,"mc":[{"id":"1.168224459","rc":[{"batb":[[2,1.46,435.71]],"ltp":1.92,"tv":931.18,"id":5858055},{"batb":[[0,2.08,100.79],[1,1.96,124.94],[2,1.6,75.72]],"ltp":2.16,"tv":1321.62,"id":7444998}]}]}
{"op":"mcm","clk":"1004130774","pt":1580653528650,"mc":[{"id":"1.168224459","rc":[{"batl":[[0,2.1,50.41],[1,2.3,309.75],[2,1000,0.02]],"ltp":1.92,"tv":931.18,"id":5858055}]}]}
{"op":"mcm","clk":"1004131060","pt":1580653529975,"mc":[{"id":"1.168224459","rc":[{"batb":[[2,1.4,75.73]],"batl":[[1,1000,0.02],[2,1000,0]],"ltp":1.92,"tv":931.18,"id":5858055}]}]}
{"op":"mcm","clk":"1004131658","pt":1580653532449,"mc":[{"id":"1.168224459","rc":[{"batb":[[0,1.7,10.55],[1,1.69,156.38],[2,1.67,281.14]],"batl":[[0,1.73,194],[1,1.75,230.75],[2,1.77,142.63]],"ltp":1.92,"tv":931.18,"id":5858055},{"batb":[[0,2.38,68.53],[1,2.36,9.69],[2,2.2,84.98]],"batl":[[0,2.56,152],[1,2.6,256.55],[2,2.62,25.21]],"ltp":2.16,"tv":1321.62,"id":7444998}]}]}
{"op":"mcm","clk":"1004131771","pt":1580653532935,"mc":[{"id":"1.168224459","rc":[{"batl":[[2,1.77,184.64]],"ltp":1.92,"tv":931.18,"id":5858055},{"batb":[[2,2.3,31.93]],"ltp":2.16,"tv":1321.62,"id":7444998}]}]}
{"op":"mcm","clk":"1004134044","pt":1580653543419,"mc":[{"id":"1.168224459","rc":[{"batb":[[0,1.69,156.38],[1,1.67,281.14],[2,1.62,67.22]],"batl":[[0,1.75,230.75],[1,1.77,184.64],[2,1.8,108.15]],"ltp":1.92,"tv":931.18,"id":5858055},{"batb":[[1,2.3,31.93],[2,2.2,84.98]],"batl":[[0,2.62,25.21],[1,1000,0.02],[2,2.62,0]],"ltp":2.16,"tv":1321.62,"id":7444998}]}]}
{"op":"mcm","clk":"1004134246","pt":1580653544173,"mc":[{"id":"1.168224459","rc":[{"batb":[[0,1.62,67.22],[1,1.53,147.06],[2,1.38,448.46]],"batl":[[0,1.77,42.01],[1,2.04,383.01],[2,2.1,50.41]],"ltp":1.92,"tv":931.18,"id":5858055},{"batb":[[0,2.3,31.93],[1,2.2,84.98],[2,1.96,124.94]],"ltp":2.16,"tv":1321.62,"id":7444998}]}]}
{"op":"mcm","clk":"1004134492","pt":1580653545288,"mc":[{"id":"1.168224459","rc":[{"batb":[[0,1.53,147.06],[1,1.38,448.46],[2,1.3,113.58]],"batl":[[0,2.04,383.01],[1,2.1,50.41],[2,1000,0.02]],"ltp":1.92,"tv":931.18,"id":5858055},{"batb":[[0,2.2,84.98],[1,1.96,124.94],[2,1.6,75.72]],"batl":[[0,1000,0.02],[1,1000,0]],"ltp":2.16,"tv":1321.62,"id":7444998}]}]}
{"op":"mcm","clk":"1004134703","pt":1580653546185,"mc":[{"id":"1.168224459","rc":[{"trd":[[1.53,3.03]],"batb":[[0,1.53,145.54]],"ltp":1.53,"tv":934.21,"id":5858055}],"tv":2255.84}]}
{"op":"mcm","clk":"1004134805","pt":1580653546575,"mc":[{"id":"1.168224459","rc":[{"batb":[[2,1.7,75.72]],"ltp":2.16,"tv":1321.62,"id":7444998}]}]}
{"op":"mcm","clk":"1004135035","pt":1580653547573,"mc":[{"id":"1.168224459","rc":[{"batb":[[0,1.55,175.93],[1,1.54,116.93],[2,1.53,145.54]],"batl":[[0,1.85,79.69],[1,1.87,119.79],[2,2.04,383.01]],"ltp":1.53,"tv":934.21,"id":5858055}]}]}
{"op":"mcm","clk":"1004138264","pt":1580653562519,"mc":[{"id":"1.168224459","rc":[{"batb":[[0,1.53,145.54],[1,1.38,448.46],[2,1.3,113.58]],"ltp":1.53,"tv":934.21,"id":5858055}]}]}
{"op":"mcm","clk":"1004138689","pt":1580653564321,"mc":[{"id":"1.168224459","rc":[{"batb":[[1,1.3,113.59],[2,1.25,378.62]],"ltp":1.53,"tv":934.21,"id":5858055}]}]}
{"op":"mcm","clk":"1004138963","pt":1580653565422,"mc":[{"id":"1.168224459","rc":[{"batb":[[0,1.79,129.53],[1,1.77,140.93],[2,1.72,295.48]],"batl":[[0,1.83,479.88],[1,1.85,79.69],[2,1.87,119.79]],"ltp":1.53,"tv":934.21,"id":5858055},{"batl":[[0,2.24,90.01],[1,2.28,13.45],[2,2.3,95.61]],"ltp":2.16,"tv":1321.62,"id":7444998}]}]}
{"op":"mcm","clk":"1004139200","pt":1580653566440,"mc":[{"id":"1.168224459","rc":[{"batb":[[2,1.76,89.93]],"batl":[[1,1.85,121.7]],"ltp":1.53,"tv":934.21,"id":5858055},{"batb":[[0,2.2,119.42],[1,2.1,97.57],[2,1.96,124.94]],"ltp":2.16,"tv":1321.62,"id":7444998}]}]}
{"op":"mcm","clk":"1004141594","pt":1580653577365,"mc":[{"id":"1.168224459","rc":[{"batb":[[0,1.76,89.93],[1,1.68,61.33],[2,1.66,111.57]],"batl":[[0,1.85,42.01],[1,2.04,383.01],[2,2.1,50.41]],"ltp":1.53,"tv":934.21,"id":5858055},{"batl":[[1,2.3,95.61],[2,2.46,28.57]],"ltp":2.16,"tv":1321.62,"id":7444998}]}]}
{"op":"mcm","clk":"1004141712","pt":1580653577969,"mc":[{"id":"1.168224459","rc":[{"batb":[[0,1.68,61.33],[1,1.66,111.57],[2,1.44,436.19]],"ltp":1.53,"tv":934.21,"id":5858055},{"batb":[[0,2.2,34.45]],"batl":[[0,2.46,28.57],[1,1000,0.02],[2,2.46,0]],"ltp":2.16,"tv":1321.62,"id":7444998}]}]}
{"op":"mcm","clk":"1004142008","pt":1580653579371,"mc":[{"id":"1.168224459","rc":[{"batb":[[0,1.66,111.57],[1,1.44,436.19],[2,1.3,113.58]],"batl":[[0,2.04,383.01],[1,2.1,50.41],[2,1000,0.02]],"ltp":1.53,"tv":934.21,"id":5858055},{"batb":[[0,2.1,97.57],[1,2.08,4.04]],"batl":[[0,1000,0.02],[1,1000,0]],"ltp":2.16,"tv":1321.62,"id":7444998}]}]}
{"op":"mcm","clk":"1004142239","pt":1580653580367,"mc":[{"id":"1.168224459","rc":[{"batb":[[0,1.68,147],[1,1.66,287.29],[2,1.44,436.19]],"batl":[[0,1.93,103.29],[1,1.95,105.3],[2,2.04,383.01]],"ltp":1.53,"tv":934.21,"id":5858055},{"batb":[[1,1.96,124.94],[2,1.6,75.72]],"ltp":2.16,"tv":1321.62,"id":7444998}]}]}
{"op":"mcm","clk":"1004142342","pt":1580653580840,"mc":[{"id":"1.168224459","rc":[{"batb":[[0,2.28,54.41],[1,2.1,97.57],[2,1.96,124.94]],"ltp":2.16,"tv":1321.62,"id":7444998}]}]}
{"op":"mcm","clk":"1004142632","pt":1580653582059,"mc":[{"id":"1.168224459","rc":[{"batb":[[0,1.66,111.57],[1,1.44,436.19],[2,1.3,113.58]],"batl":[[0,2.04,383.01],[1,2.1,50.41],[2,1000,0.02]],"ltp":1.53,"tv":934.21,"id":5858055}]}]}
{"op":"mcm","clk":"1004143262","pt":1580653585062,"mc":[{"id":"1.168224459","rc":[{"batb":[[0,1.77,110.25],[1,1.75,146.33],[2,1.66,111.57]],"batl":[[0,1.83,110.12],[1,1.85,123.83],[2,2.04,383.01]],"ltp":1.53,"tv":934.21,"id":5858055}]}]}
{"op":"mcm","clk":"1004143508","pt":1580653586174,"mc":[{"id":"1.168224459","rc":[{"batb":[[0,1.66,111.57],[1,1.44,436.19],[2,1.3,113.58]],"batl":[[0,2.04,383.01],[1,2.1,50.41],[2,1000,0.02]],"ltp":1.53,"tv":934.21,"id":5858055}]}]}
{"op":"mcm","clk":"1004144180","pt":1580653589168,"mc":[{"id":"1.168224459","rc":[{"batb":[[0,1.68,147],[1,1.66,287.29],[2,1.44,436.19]],"batl":[[0,1.93,103.29],[1,1.95,105.3],[2,2.04,383.01]],"ltp":1.53,"tv":934.21,"id":5858055}]}]}
{"op":"mcm","clk":"1004144700","pt":1580653591475,"mc":[{"id":"1.168224459","rc":[{"batl":[[0,2.04,383.01],[1,2.1,50.41],[2,1000,0.02]],"ltp":1.53,"tv":934.21,"id":5858055}]}]}
{"op":"mcm","clk":"1004145321","pt":1580653594265,"mc":[{"id":"1.168224459","rc":[{"batb":[[0,1.68,158.43],[2,1.62,275.36]],"batl":[[0,1.71,192],[1,1.72,1275.02],[2,2.04,383.01]],"ltp":1.53,"tv":934.21,"id":5858055},{"batb":[[0,2.4,217.88],[1,2.34,771.09],[2,2.28,54.41]],"batl":[[0,2.6,142],[1,1000,0.02]],"ltp":2.16,"tv":1321.62,"id":7444998}]}]}
{"op":"mcm","clk":"1004145580","pt":1580653595399,"mc":[{"id":"1.168224459","rc":[{"batl":[[1,1.72,127.5],[2,1.74,138.93]],"ltp":1.53,"tv":934.21,"id":5858055},{"batb":[[0,2.4,284.68],[1,2.34,77.11]],"ltp":2.16,"tv":1321.62,"id":7444998}]}]}
{"op":"mcm","clk":"1004145771","pt":1580653596281,"mc":[{"id":"1.168224459","rc":[{"batb":[[1,2.34,108.2]],"batl":[[1,2.66,25.21],[2,1000,0.02]],"ltp":2.16,"tv":1321.62,"id":7444998}]}]}
{"op":"mcm","clk":"1004147723","pt":1580653606320,"mc":[{"id":"1.168224459","rc":[{"batb":[[0,1.66,111.57],[1,1.61,68.06],[2,1.53,149.89]],"batl":[[0,1.72,127.5],[1,1.75,42.01],[2,2.04,383.01]],"ltp":1.53,"tv":934.21,"id":5858055},{"batb":[[0,2.4,66.8]],"batl":[[0,2.66,25.21],[1,1000,0.02],[2,1000,0]],"ltp":2.16,"tv":1321.62,"id":7444998}]}]}
{"op":"mcm","clk":"1004147928","pt":1580653607394,"mc":[{"id":"1.168224459","rc":[{"batb":[[0,1.53,149.89],[1,1.38,448.46],[2,1.3,113.58]],"batl":[[0,2.04,383.01],[1,2.1,50.41],[2,1000,3.05]],"ltp":1.53,"tv":934.21,"id":5858055},{"batb":[[0,2.28,54.41],[1,2.24,82.3],[2,1.96,124.94]],"batl":[[0,1000,0.02],[1,1000,0]],"ltp":2.16,"tv":1321.62,"id":7444998}]}]}
{"op":"mcm","clk":"1004148014","pt":1580653607873,"mc":[{"id":"1.168224459","rc":[{"batl":[[2,1000,1.53]],"ltp":1.53,"tv":934.21,"id":5858055}]}]}
{"op":"mcm","clk":"1004148312","pt":1580653609399,"mc":[{"id":"1.168224459","rc":[{"batb":[[0,1.54,186.61],[1,1.53,269.89],[2,1.38,448.46]],"batl":[[0,1.84,102.45],[1,1.86,121.77],[2,2.04,383.01]],"ltp":1.53,"tv":934.21,"id":5858055}]}]}
{"op":"mcm","clk":"1004148451","pt":1580653610057,"mc":[{"id":"1.168224459","rc":[{"batl":[[0,2.4,7.6],[1,1000,0.02]],"ltp":2.16,"tv":1321.62,"id":7444998}]}]}
{"op":"mcm","clk":"1004148750","pt":1580653611795,"mc":[{"id":"1.168224459","rc":[{"trd":[[1.71,1.51]],"batb":[[0,1.53,149.89],[1,1.38,448.46],[2,1.3,113.58]],"batl":[[0,2.04,383.01],[1,2.1,50.41],[2,1000,0.02]],"ltp":1.71,"tv":935.73,"id":5858055},{"trd":[[2.4,1.08]],"batl":[[0,2.4,6.52]],"ltp":2.4,"tv":1322.7,"id":7444998}],"tv":2258.43}]}
{"op":"mcm","clk":"1004149286","pt":1580653614721,"mc":[{"id":"1.168224459","rc":[{"trd":[[1.71,10.66]],"batb":[[0,1.65,153.89],[1,1.64,92.34],[2,1.53,149.89]],"batl":[[0,1.71,149.14],[1,1.73,153.62],[2,2.04,383.01]],"ltp":1.71,"tv":944.88,"id":5858055},{"trd":[[2.4,7.6]],"batl":[[0,1000,0.02],[1,1000,0]],"ltp":2.4,"tv":1329.22,"id":7444998}],"tv":2274.1}]}
{"op":"mcm","clk":"1004149694","pt":1580653616685,"mc":[{"id":"1.168224459","rc":[{"batb":[[0,1.53,149.89],[1,1.38,448.46],[2,1.3,113.58]],"batl":[[0,2.04,383.01],[1,2.1,50.41],[2,1000,0.02]],"ltp":1.71,"tv":944.88,"id":5858055}]}]}
{"op":"mcm","clk":"1004150176","pt":1580653619106,"mc":[{"id":"1.168224459","rc":[{"batl":[[0,1.68,246.1],[1,2.04,383.01],[2,2.1,50.41]],"ltp":1.71,"tv":944.88,"id":5858055}]}]}
{"op":"mcm","clk":"1004150405","pt":1580653620302,"mc":[{"id":"1.168224459","rc":[{"batb":[[0,1.54,192.24],[1,1.53,269.9],[2,1.38,448.46]],"batl":[[1,1.84,97.74],[2,1.86,121.77]],"ltp":1.71,"tv":944.88,"id":5858055}]}]}
{"op":"mcm","clk":"1004150508","pt":1580653620825,"mc":[{"id":"1.168224459","rc":[{"batl":[[1,2.04,383.01],[2,2.1,50.41]],"ltp":1.71,"tv":944.88,"id":5858055}]}]}
{"op":"mcm","clk":"1004150745","pt":1580653622023,"mc":[{"id":"1.168224459","rc":[{"batb":[[2,1.3,113.59]],"batl":[[0,2.1,50.41],[1,1000,0.02],[2,2.1,0]],"ltp":1.71,"tv":944.88,"id":5858055}]}]}
{"op":"mcm","clk":"1004151019","pt":1580653623414,"mc":[{"id":"1.168224459","rc":[{"batb":[[2,1.48,455.17]],"batl":[[0,1.56,1322.52],[1,1.57,263],[2,1.58,1642.99]],"ltp":1.71,"tv":944.88,"id":5858055},{"batl":[[0,2.84,5.25],[1,3.05,178],[2,1000,0.02]],"ltp":2.4,"tv":1329.22,"id":7444998}]}]}
{"op":"mcm","clk":"1004151222","pt":1580653624404,"mc":[{"id":"1.168224459","rc":[{"batb":[[2,1.5,84.02]],"batl":[[0,1.56,132.25],[2,1.58,560.81]],"ltp":1.71,"tv":944.88,"id":5858055},{"batb":[[0,2.74,47.13],[1,2.6,26.05],[2,2.44,64.68]],"batl":[[1,3,21],[2,3.05,178]],"ltp":2.4,"tv":1329.22,"id":7444998}]}]}
{"op":"mcm","clk":"1004153172","pt":1580653634330,"mc":[{"id":"1.168224459","rc":[{"trd":[[1.54,7.58]],"batb":[[0,1.54,188.45]],"ltp":1.54,"tv":952.45,"id":5858055}],"tv":2281.68}]}
{"op":"mcm","clk":"1004153751","pt":1580653637356,"mc":[{"id":"1.168224459","rc":[{"trd":[[1.54,10.6]],"batb":[[0,1.54,186.94]],"ltp":1.54,"tv":955.48,"id":5858055}],"tv":2284.7}]}
{"op":"mcm","clk":"1004154381","pt":1580653640281,"mc":[{"id":"1.168224459","rc":[{"trd":[[1.56,20.96]],"batl":[[0,1.56,111.29]],"ltp":1.56,"tv":976.44,"id":5858055},{"trd":[[2.78,11.76]],"ltp":2.78,"tv":1340.98,"id":7444998}],"tv":2317.43}]}
{"op":"mcm","clk":"1004154599","pt":1580653641360,"mc":[{"id":"1.168224459","rc":[{"batb":[[0,1.53,149.89],[1,1.5,84.02],[2,1.37,232.2]],"batl":[[1,1.58,120.24],[2,1.62,42.01]],"ltp":1.56,"tv":976.44,"id":5858055},{"batl":[[0,3,21],[1,1000,0.02],[2,3.05,0]],"ltp":2.78,"tv":1340.98,"id":7444998}]}]}
{"op":"mcm","clk":"1004154656","pt":1580653641678,"mc":[{"id":"1.168224459","rc":[{"batb":[[0,1.5,84.02],[1,1.37,232.2],[2,1.31,477.51]],"batl":[[0,1.62,42.01],[1,1.89,435.28],[2,2.1,50.41]],"ltp":1.56,"tv":976.44,"id":5858055},{"batb":[[0,2.6,26.05],[1,2.44,64.68],[2,2.28,54.41]],"ltp":2.78,"tv":1340.98,"id":7444998}]}]}
{"op":"mcm","clk":"1004154984","pt":1580653643363,"mc":[{"id":"1.168224459","rc":[{"batb":[[0,1.37,232.2],[1,1.31,477.51],[2,1.25,378.62]],"batl":[[0,1.89,435.28],[1,2.1,50.41],[2,1000,0.02]],"ltp":1.56,"tv":976.44,"id":5858055},{"batb":[[0,2.44,64.68],[1,2.28,54.41],[2,1.96,124.94]],"batl":[[0,1000,0.02],[1,1000,0]],"ltp":2.78,"tv":1340.98,"id":7444998}]}]}
{"op":"mcm","clk":"1004155155","pt":1580653644262,"mc":[{"id":"1.168224459","rc":[{"batb":[[0,1.37,486.2],[1,1.36,200.5],[2,1.31,477.51]],"batl":[[0,1.73,146.55],[1,1.75,147.93],[2,1.89,435.28]],"ltp":1.56,"tv":976.44,"id":5858055}]}]}
{"op":"mcm","clk":"1004156483","pt":1580653650389,"mc":[{"id":"1.168224459","rc":[{"batb":[[0,1.37,232.2],[1,1.31,477.51],[2,1.25,378.62]],"ltp":1.56,"tv":976.44,"id":5858055}]}]}
{"op":"mcm","clk":"1004156883","pt":1580653652273,"mc":[{"id":"1.168224459","rc":[{"batb":[[1,1.25,378.62],[2,1.2,284.06]],"ltp":1.56,"tv":976.44,"id":5858055}]}]}
{"op":"mcm","clk":"1004157076","pt":1580653653381,"mc":[{"id":"1.168224459","rc":[{"batb":[[0,1.67,147.73],[1,1.66,101.59],[2,1.64,1296.13]],"batl":[[0,1.7,590.06],[1,1.73,146.55],[2,1.75,147.93]],"ltp":1.56,"tv":976.44,"id":5858055},{"batl":[[0,2.46,1296.13],[1,2.64,134],[2,1000,0.02]],"ltp":2.78,"tv":1340.98,"id":7444998}]}]}
{"op":"mcm","clk":"1004157260","pt":1580653654269,"mc":[{"id":"1.168224459","rc":[{"batb":[[2,1.64,244.41]],"batl":[[1,1.73,188.56]],"ltp":1.56,"tv":976.44,"id":5858055},{"batb":[[1,2.4,29.41],[2,2.28,54.41]],"batl":[[0,2.46,129.61],[2,2.7,24.37]],"ltp":2.78,"tv":1340.98,"id":7444998}]}]}
{"op":"mcm","clk":"1004159029","pt":1580653663301,"mc":[{"id":"1.168224459","rc":[{"batb":[[0,1.52,153.04],[1,1.34,465.44],[2,1.3,113.58]],"batl":[[0,1.89,435.28],[1,2.1,50.41],[2,1000,0.02]],"ltp":1.56,"tv":976.44,"id":5858055},{"batb":[[0,2.28,54.41],[1,2.26,80.26],[2,1.96,124.94]],"batl":[[0,1000,0.02],[1,2.64,0],[2,2.7,0]],"ltp":2.78,"tv":1340.98,"id":7444998}]}]}
{"op":"mcm","clk":"1004159188","pt":1580653664107,"mc":[{"id":"1.168224459","rc":[{"batl":[[0,1.68,1.68],[1,1.89,435.28],[2,2.1,50.41]],"ltp":1.56,"tv":976.44,"id":5858055}]}]}
{"op":"mcm","clk":"1004159540","pt":1580653665793,"mc":[{"id":"1.168224459","rc":[{"batb":[[0,1.54,94.35],[1,1.53,119.5],[2,1.52,153.04]],"batl":[[1,1.83,113.03],[2,1.85,123.82]],"ltp":1.56,"tv":976.44,"id":5858055}]}]}
{"op":"mcm","clk":"1004159736","pt":1580653666711,"mc":[{"id":"1.168224459","rc":[{"trd":[[1.68,1.68]],"batl":[[0,1.83,113.03],[1,1.85,123.82],[2,1.89,435.28]],"ltp":1.68,"tv":978.12,"id":5858055},{"trd":[[2.46,1.15]],"batl":[[0,2.44,3.85],[1,1000,0.02]],"ltp":2.46,"tv":1342.13,"id":7444998}],"tv":2320.26}]}
{"op":"mcm","clk":"1004160023","pt":1580653668091,"mc":[{"id":"1.168224459","rc":[{"batl":[[0,1000,0.02],[1,1000,0]],"ltp":2.46,"tv":1342.13,"id":7444998}]}]}
{"op":"mcm","clk":"1004160149","pt":1580653668679,"mc":[{"id":"1.168224459","rc":[{"batb":[[0,1.52,153.04],[1,1.34,465.44],[2,1.3,113.58]],"batl":[[0,1.89,435.28],[1,2.1,50.41],[2,1000,0.02]],"ltp":1.68,"tv":978.12,"id":5858055}]}]}
{"op":"mcm","clk":"1004160486","pt":1580653670514,"mc":[{"id":"1.168224459","rc":[{"batb":[[1,1.3,113.59],[2,1.25,378.62]],"batl":[[0,2.1,50.41],[1,1000,0.02],[2,1000,0]],"ltp":1.68,"tv":978.12,"id":5858055}]}]}
{"op":"mcm","clk":"1004160890","pt":1580653672405,"mc":[{"id":"1.168224459","rc":[{"trd":[[1.79,444.41]],"batb":[[0,1.77,107.19],[1,1.75,146.31],[2,1.74,112.68]],"batl":[[0,1.8,42.01],[1,1.83,113.03],[2,1.85,123.82]],"ltp":1.79,"tv":1422.53,"id":5858055},{"trd":[[2.26,590.33],[2.28,108.82]],"batb":[[0,2.14,93.32],[1,1.96,124.94],[2,1.6,75.72]],"batl":[[0,2.26,82.76],[1,2.44,136],[2,2.46,189.5]],"ltp":2.26,"tv":2041.29,"id":7444998}],"tv":3463.82}]}
{"op":"mcm","clk":"1004161399","pt":1580653675029,"mc":[{"id":"1.168224459","rc":[{"batb":[[0,2.24,33.61],[1,2.14,93.32],[2,1.96,124.94]],"batl":[[2,2.46,218.07]],"ltp":2.26,"tv":2041.29,"id":7444998}]}]}
{"op":"mcm","clk":"1004161541","pt":1580653675629,"mc":[{"id":"1.168224459","rc":[{"trd":[[2.26,597.05]],"batl":[[0,2.26,79.4]],"ltp":2.26,"tv":2048.01,"id":7444998}],"tv":3470.54}]}
{"op":"mcm","clk":"1004162079","pt":1580653678255,"mc":[{"id":"1.168224459","rc":[{"trd":[[1.75,39.46],[1.77,214.38],[1.79,544.66]],"batb":[[0,1.75,126.58],[1,1.74,112.68],[2,1.73,107.6]],"ltp":1.75,"tv":1776.62,"id":5858055},{"trd":[[2.26,676.45]],"batl":[[0,2.44,136],[1,2.46,218.07],[2,1000,0.02]],"ltp":2.26,"tv":2127.41,"id":7444998}],"tv":3904.03}]}
{"op":"mcm","clk":"1004162236","pt":1580653678908,"mc":[{"id":"1.168224459","rc":[{"batb":[[0,1.74,112.68],[1,1.73,107.6],[2,1.68,61.33]],"batl":[[1,2.1,413.72],[2,1000,0.02]],"ltp":1.75,"tv":1776.62,"id":5858055}]}]}
{"op":"mcm","clk":"1004162914","pt":1580653682135,"mc":[{"id":"1.168224459","rc":[{"batb":[[0,1.76,109.58],[1,1.74,244.13],[2,1.73,107.6]],"batl":[[1,1.82,117.6],[2,1.84,126.15]],"ltp":1.75,"tv":1776.62,"id":5858055}]}]}
{"op":"mcm","clk":"1004163173","pt":1580653683348,"mc":[{"id":"1.168224459","rc":[{"batb":[[0,1.73,107.6],[1,1.64,116.45],[2,1.4,451.01]],"batl":[[0,2.1,413.72],[1,1000,0.02],[2,1.84,0]],"ltp":1.75,"tv":1776.62,"id":5858055},{"batb":[[0,2.14,93.32],[1,1.96,124.94],[2,1.6,75.72]],"batl":[[0,1000,0.02],[1,2.46,0],[2,1000,0]],"ltp":2.26,"tv":2127.41,"id":7444998}]}]}
{"op":"mcm","clk":"1004163243","pt":1580653683729,"mc":[{"id":"1.168224459","rc":[{"batb":[[0,1.64,116.45],[1,1.4,451.01],[2,1.3,113.58]],"ltp":1.75,"tv":1776.62,"id":5858055}]}]}
{"op":"mcm","clk":"1004163855","pt":1580653686396,"mc":[{"id":"1.168224459","rc":[{"batb":[[0,1.65,271.68],[1,1.64,92.53],[2,1.4,451.01]],"batl":[[0,1.89,88.37],[1,1.91,112.33],[2,2.1,413.72]],"ltp":1.75,"tv":1776.62,"id":5858055},{"batb":[[0,2.38,47.45],[1,2.12,96.07],[2,1.96,124.94]],"ltp":2.26,"tv":2127.41,"id":7444998}]}]}
{"op":"mcm","clk":"1004164407","pt":1580653689247,"mc":[{"id":"1.168224459","rc":[{"batb":[[0,1.65,113.46],[1,1.4,451.01],[2,1.3,113.58]],"ltp":1.75,"tv":1776.62,"id":5858055}]}]}
{"op":"mcm","clk":"1004164947","pt":1580653691427,"mc":[{"id":"1.168224459","rc":[{"trd":[[1.73,65.28]],"batb":[[0,1.8,970.98],[1,1.78,1203.23],[2,1.76,384.69]],"batl":[[0,1.89,578.62]],"ltp":1.73,"tv":1841.9,"id":5858055},{"trd":[[2.38,47.45]],"batb":[[0,2.12,96.07],[1,1.96,124.94],[2,1.7,75.72]],"batl":[[0,2.28,174],[1,1000,0.02]],"ltp":2.38,"tv":2174.86,"id":7444998}],"tv":4016.77}]}
{"op":"mcm","clk":"1004165147","pt":1580653692322,"mc":[{"id":"1.168224459","rc":[{"batb":[[0,1.83,98.34],[1,1.81,131.02],[2,1.8,103.63]],"batl":[[0,1.89,641.35]],"ltp":1.73,"tv":1841.9,"id":5858055},{"batb":[[0,2.14,36.13],[1,2.12,96.07],[2,1.96,124.94]],"batl":[[0,2.2,6.98],[1,2.28,174],[2,2.38,30.25]],"ltp":2.38,"tv":2174.86,"id":7444998}]}]}
{"op":"mcm","clk":"1004165249","pt":1580653692819,"mc":[{"id":"1.168224459","rc":[{"batb":[[0,1.83,178.52]],"ltp":1.73,"tv":1841.9,"id":5858055},{"batb":[[0,2.12,96.07],[1,1.96,124.94],[2,1.95,122.74]],"batl":[[2,1000,0.02]],"ltp":2.38,"tv":2174.86,"id":7444998}]}]}
{"op":"mcm","clk":"1004165537","pt":1580653694246,"mc":[{"id":"1.168224459","rc":[{"batl":[[2,2.34,37.86]],"ltp":2.38,"tv":2174.86,"id":7444998}]}]}
{"op":"mcm","clk":"1004165727","pt":1580653695116,"mc":[{"id":"1.168224459","rc":[{"batb":[[0,2.12,133.04]],"batl":[[2,2.34,31.09]],"ltp":2.38,"tv":2174.86,"id":7444998}]}]}
{"op":"mcm","clk":"1004166295","pt":1580653697943,"mc":[{"id":"1.168224459","rc":[{"trd":[[1.83,78.06]],"batb":[[0,1.83,80.18],[1,1.8,103.63],[2,1.78,120.32]],"ltp":1.83,"tv":1898.67,"id":5858055},{"trd":[[2.2,217.83],[2.22,46.8]],"batl":[[0,2.28,174],[1,2.34,31.09],[2,1000,0.02]],"ltp":2.22,"tv":2235.62,"id":7444998}],"tv":4134.3}]}
{"op":"mcm","clk":"1004166479","pt":1580653698739,"mc":[{"id":"1.168224459","rc":[{"trd":[[1.83,79.6]],"batb":[[0,1.83,78.64]],"ltp":1.83,"tv":1900.21,"id":5858055},{"trd":[[2.22,48.07]],"ltp":2.22,"tv":2236.89,"id":7444998}],"tv":4137.11}]}
{"op":"mcm","clk":"1004166943","pt":1580653700861,"mc":[{"id":"1.168224459","rc":[{"batb":[[1,1.82,132.06],[2,1.8,237.17]],"batl":[[0,1.89,671.74]],"ltp":1.83,"tv":1900.21,"id":5858055}]}]}
{"op":"mcm","clk":"1004168207","pt":1580653707651,"mc":[{"id":"1.168224459","rc":[{"batl":[[0,1.89,651.02]],"ltp":1.83,"tv":1900.21,"id":5858055}]}]}
{"op":"mcm","clk":"1004168797","pt":1580653710591,"mc":[{"id":"1.168224459","rc":[{"batl":[[0,1.86,14.06],[1,1.89,651.02],[2,1.91,112.33]],"ltp":1.83,"tv":1900.21,"id":5858055},{"batl":[[0,2.24,12.19],[1,2.28,174],[2,2.34,31.09]],"ltp":2.22,"tv":2236.89,"id":7444998}]}]}
{"op":"mcm","clk":"1004170389","pt":1580653719279,"mc":[{"id":"1.168224459","rc":[{"trd":[[1.83,89.6]],"batb":[[0,1.83,73.64],[1,1.8,103.63],[2,1.78,120.32]],"batl":[[0,1.89,42.01],[1,2.1,413.72],[2,1000,0.02]],"ltp":1.83,"tv":1910.21,"id":5858055},{"batl":[[0,2.34,31.09],[1,1000,0.02],[2,2.34,0]],"ltp":2.22,"tv":2236.89,"id":7444998}],"tv":4147.11}]}
{"op":"mcm","clk":"1004170536","pt":1580653719992,"mc":[{"id":"1.168224459","rc":[{"batb":[[0,1.76,90.88],[1,1.44,436.19],[2,1.3,113.58]],"batl":[[0,2.1,413.72],[1,1000,0.02],[2,1000,0]],"ltp":1.83,"tv":1910.21,"id":5858055},{"batb":[[0,1.96,124.94],[1,1.95,122.74],[2,1.6,75.72]],"batl":[[0,1000,0.02],[1,1000,0]],"ltp":2.22,"tv":2236.89,"id":7444998}]}]}
{"op":"mcm","clk":"1004170973","pt":1580653722275,"mc":[{"id":"1.168224459","rc":[{"batb":[[0,1.76,192.57],[1,1.74,149.6],[2,1.44,436.19]],"batl":[[0,2.04,123.84],[1,2.06,89.43],[2,2.1,413.72]],"ltp":1.83,"tv":1910.21,"id":5858055}]}]}
{"op":"mcm","clk":"1004171148","pt":1580653723298,"mc":[{"id":"1.168224459","rc":[{"batb":[[0,1.77,89.78],[1,1.76,101.69],[2,1.74,149.6]],"ltp":1.83,"tv":1910.21,"id":5858055},{"batb":[[0,1.96,246.58],[1,1.6,75.72],[2,1.5,113.58]],"ltp":2.22,"tv":2236.89,"id":7444998}]}]}
{"op":"mcm","clk":"1004174383","pt":1580653739603,"mc":[{"id":"1.168224459","rc":[{"batl":[[0,2.1,413.72],[1,1000,0.02],[2,2.1,0]],"ltp":1.83,"tv":1910.21,"id":5858055}]}]}
{"op":"mcm","clk":"1004174990","pt":1580653742289,"mc":[{"id":"1.168224459","rc":[{"batb":[[2,1.74,166.1]],"batl":[[0,1.78,8.46],[1,1.82,209],[2,1.84,1121.48]],"ltp":1.83,"tv":1910.21,"id":5858055},{"batb":[[0,2.18,879.08],[1,1.96,246.58],[2,1.6,75.72]],"batl":[[0,2.4,357.57],[1,1000,0.02]],"ltp":2.22,"tv":2236.89,"id":7444998}]}]}
{"op":"mcm","clk":"1004175171","pt":1580653743217,"mc":[{"id":"1.168224459","rc":[{"batl":[[1,1.82,334.82],[2,1.84,238.48]],"ltp":1.83,"tv":1910.21,"id":5858055},{"batb":[[0,2.2,85.06],[1,2.18,87.91],[2,2.06,103.55]],"ltp":2.22,"tv":2236.89,"id":7444998}]}]}
{"op":"mcm","clk":"1004175442","pt":1580653744415,"mc":[{"id":"1.168224459","rc":[{"batl":[[2,1.84,280.49]],"ltp":1.83,"tv":1910.21,"id":5858055},{"batb":[[0,2.2,119.5]],"batl":[[1,2.42,29.41],[2,1000,0.02]],"ltp":2.22,"tv":2236.89,"id":7444998}]}]}
{"op":"mcm","clk":"1004176361","pt":1580653748694,"mc":[{"id":"1.168224459","rc":[{"batl":[[1,1.81,480.59],[2,1.82,334.82]],"ltp":1.83,"tv":1910.21,"id":5858055}]}]}
{"op":"mcm","clk":"1004176981","pt":1580653751243,"mc":[{"id":"1.168224459","rc":[{"batb":[[0,1.73,494.03],[1,1.71,670.52],[2,1.44,436.19]],"batl":[[0,1.81,480.59],[1,1.83,497.4],[2,1.84,154.16]],"ltp":1.83,"tv":1910.21,"id":5858055},{"batb":[[0,2.2,34.45]],"batl":[[0,2.42,29.41],[1,1000,0.02],[2,1000,0]],"ltp":2.22,"tv":2236.89,"id":7444998}]}]}
{"op":"mcm","clk":"1004177096","pt":1580653751728,"mc":[{"id":"1.168224459","rc":[{"batb":[[1,1.71,611.71]],"batl":[[2,2.1,413.72]],"ltp":1.83,"tv":1910.21,"id":5858055},{"batb":[[0,2.06,103.55],[1,1.96,124.94],[2,1.6,75.72]],"batl":[[0,1000,0.02],[1,1000,0]],"ltp":2.22,"tv":2236.89,"id":7444998}]}]}
{"op":"mcm","clk":"1004177579","pt":1580653754138,"mc":[{"id":"1.168224459","rc":[{"batb":[[1,1.71,728.04],[2,1.69,165.53]],"batl":[[2,1.93,122.19]],"ltp":1.83,"tv":1910.21,"id":5858055}]}]}
{"op":"mcm","clk":"1004179315","pt":1580653761929,"mc":[{"id":"1.168224459","rc":[{"batb":[[0,1.71,217.2],[1,1.69,165.53],[2,1.44,436.19]],"batl":[[2,2.1,413.72]],"ltp":1.83,"tv":1910.21,"id":5858055}]}]}
{"op":"mcm","clk":"1004179549","pt":1580653763137,"mc":[{"id":"1.168224459","rc":[{"batb":[[2,1.3,113.59]],"ltp":1.83,"tv":1910.21,"id":5858055}]}]}
{"op":"mcm","clk":"1004179772","pt":1580653764342,"mc":[{"id":"1.168224459","rc":[{"batb":[[1,1.7,10.55],[2,1.69,165.53]],"batl":[[0,1.75,1098.7],[1,1.76,3451.8],[2,1.77,253]],"ltp":1.83,"tv":1910.21,"id":5858055},{"batb":[[0,2.36,9.69],[1,2.32,215.04],[2,2.28,879.16]],"batl":[[0,2.5,346.07],[1,1000,0.02]],"ltp":2.22,"tv":2236.89,"id":7444998}]}]}
{"op":"mcm","clk":"1004179997","pt":1580653765326,"mc":[{"id":"1.168224459","rc":[{"batl":[[0,1.75,109.87],[1,1.77,399.62],[2,1.79,138.02]],"ltp":1.83,"tv":1910.21,"id":5858055},{"batb":[[1,2.32,289.95],[2,2.28,87.92]],"ltp":2.22,"tv":2236.89,"id":7444998}]}]}
{"op":"mcm","clk":"1004180290","pt":1580653766627,"mc":[{"id":"1.168224459","rc":[{"batl":[[2,1.79,180.03]],"ltp":1.83,"tv":1910.21,"id":5858055},{"batl":[[1,2.52,26.89],[2,1000,0.02]],"ltp":2.22,"tv":2236.89,"id":7444998}]}]}
{"op":"mcm","clk":"1004181184","pt":1580653770925,"mc":[{"id":"1.168224459","rc":[{"batl":[[1,1.77,880.21],[2,1.79,677.43]],"ltp":1.83,"tv":1910.21,"id":5858055}]}]}
{"op":"mcm","clk":"1004181658","pt":1580653773269,"mc":[{"id":"1.168224459","rc":[{"trd":[[1.74,5.22]],"ltp":1.74,"tv":1915.43,"id":5858055},{"trd":[[2.36,3.85]],"batb":[[0,2.36,5.84]],"ltp":2.36,"tv":2240.74,"id":7444998}],"tv":4156.18}]}
{"op":"mcm","clk":"1004182872","pt":1580653779400,"mc":[{"id":"1.168224459","rc":[{"batb":[[0,1.71,100.87],[1,1.67,665.03],[2,1.65,510.84]],"batl":[[0,1.77,480.59],[1,1.79,539.41],[2,2.1,413.72]],"ltp":1.74,"tv":1915.43,"id":5858055},{"batb":[[0,2.32,74.91],[1,2.26,32.77],[2,2.16,89.38]],"batl":[[0,2.52,26.89],[1,1000,0.02],[2,1000,0]],"ltp":2.36,"tv":2240.74,"id":7444998}]}]}
{"op":"mcm","clk":"1004182906","pt":1580653779599,"mc":[{"id":"1.168224459","rc":[{"batb":[[0,1.67,602.85],[1,1.65,510.84],[2,1.38,448.46]],"batl":[[1,1.79,497.4]],"ltp":1.74,"tv":1915.43,"id":5858055},{"batb":[[0,2.16,89.38],[1,1.96,124.94],[2,1.7,75.72]],"batl":[[0,1000,0.02],[1,1000,0]],"ltp":2.36,"tv":2240.74,"id":7444998}]}]}
{"op":"mcm","clk":"1004183306","pt":1580653781298,"mc":[{"id":"1.168224459","rc":[{"batb":[[2,1.3,113.59]],"ltp":1.74,"tv":1915.43,"id":5858055}]}]}
{"op":"mcm","clk":"1004183552","pt":1580653782391,"mc":[{"id":"1.168224459","rc":[{"trd":[[1.67,3.03]],"batb":[[0,1.68,94.06],[1,1.67,601.34],[2,1.66,176.27]],"batl":[[2,1.84,119.56]],"ltp":1.67,"tv":1918.46,"id":5858055}],"tv":4159.21}]}
{"op":"mcm","clk":"1004183936","pt":1580653784430,"mc":[{"id":"1.168224459","rc":[{"batb":[[0,1.67,601.34],[1,1.65,510.84],[2,1.3,113.59]],"batl":[[2,2.1,413.72]],"ltp":1.67,"tv":1918.46,"id":5858055}]}]}
{"op":"mcm","clk":"1004183950","pt":1580653784503,"mc":[{"id":"1.168224459","rc":[{"batl":[[0,1.7,1.68],[1,1.77,480.59],[2,1.79,497.4]],"ltp":1.67,"tv":1918.46,"id":5858055}]}]}
{"op":"mcm","clk":"1004184262","pt":1580653786087,"mc":[{"id":"1.168224459","rc":[{"batb":[[2,1.44,436.19]],"batl":[[0,1.77,480.59],[1,1.79,497.4],[2,2.1,413.72]],"ltp":1.67,"tv":1918.46,"id":5858055}]}]}
{"op":"mcm","clk":"1004184514","pt":1580653787427,"mc":[{"id":"1.168224459","rc":[{"batb":[[0,1.72,140],[1,1.7,162.25],[2,1.67,601.34]],"batl":[[1,1.78,116.58],[2,1.79,497.4]],"ltp":1.67,"tv":1918.46,"id":5858055}]}]}
{"op":"mcm","clk":"1004185646","pt":1580653793563,"mc":[{"id":"1.168224459","rc":[{"batb":[[0,1.67,601.34],[1,1.65,510.84],[2,1.44,436.19]],"batl":[[1,1.79,497.4],[2,2.1,413.72]],"ltp":1.67,"tv":1918.46,"id":5858055}]}]}
{"op":"mcm","clk":"1004186204","pt":1580653796407,"mc":[{"id":"1.168224459","rc":[{"batb":[[0,1.68,94.06],[1,1.67,601.34],[2,1.66,176.27]],"batl":[[2,1.84,119.56]],"ltp":1.67,"tv":1918.46,"id":5858055}]}]}
{"op":"mcm","clk":"1004186701","pt":1580653798943,"mc":[{"id":"1.168224459","rc":[{"batb":[[0,1.67,601.34],[1,1.65,510.84],[2,1.44,436.19]],"batl":[[0,1.84,119.56],[1,1.86,122.1],[2,2.1,413.72]],"ltp":1.67,"tv":1918.46,"id":5858055}]}]}
{"op":"mcm","clk":"1004187426","pt":1580653802448,"mc":[{"id":"1.168224459","rc":[{"batb":[[0,1.78,95.34],[1,1.76,143.93],[2,1.73,57.13]],"batl":[[0,1.83,225.57],[1,1.84,119.56],[2,1.85,276.01]],"ltp":1.67,"tv":1918.46,"id":5858055},{"batb":[[0,2.16,125.51],[2,1.6,75.72]],"batl":[[0,2.28,8.14],[1,2.36,192],[2,2.38,90.88]],"ltp":2.36,"tv":2240.74,"id":7444998}]}]}
{"op":"mcm","clk":"1004187514","pt":1580653802865,"mc":[{"id":"1.168224459","rc":[{"batb":[[0,1.79,85.84],[1,1.78,95.34],[2,1.76,143.93]],"ltp":1.67,"tv":1918.46,"id":5858055},{"batb":[[0,2.18,89.38],[1,2.16,36.13],[2,2,112.12]],"ltp":2.36,"tv":2240.74,"id":7444998}]}]}
{"op":"mcm","clk":"1004187984","pt":1580653805615,"mc":[{"id":"1.168224459","rc":[{"trd":[[1.79,598.76]],"batb":[[0,1.79,31.74]],"ltp":1.79,"tv":1972.56,"id":5858055},{"trd":[[2.28,167.58]],"batl":[[0,2.36,192],[1,2.38,90.88],[2,2.4,29.41]],"ltp":2.28,"tv":2299.5,"id":7444998}],"tv":4272.07}]}
{"op":"mcm","clk":"1004189996","pt":1580653815385,"mc":[{"id":"1.168224459","rc":[{"trd":[[1.79,602.79]],"batb":[[0,1.79,27.71]],"batl":[[0,1.83,208.3]],"ltp":1.79,"tv":1976.59,"id":5858055},{"trd":[[2.28,170.74]],"ltp":2.28,"tv":2302.66,"id":7444998}],"tv":4279.26}]}
{"op":"mcm","clk":"1004190159","pt":1580653816361,"mc":[{"id":"1.168224459","rc":[{"trd":[[1.79,608.49]],"batb":[[0,1.79,24.86]],"ltp":1.79,"tv":1982.29,"id":5858055}],"tv":4284.96}]}
{"op":"mcm","clk":"1004190553","pt":1580653818346,"mc":[{"id":"1.168224459","rc":[{"batb":[[2,1.76,156.98]],"batl":[[0,1.8,10.94],[1,1.83,208.3],[2,1.84,119.56]],"ltp":1.79,"tv":1982.29,"id":5858055}]}]}
{"op":"mcm","clk":"1004191074","pt":1580653821378,"mc":[{"id":"1.168224459","rc":[{"batb":[[1,1.75,494.03],[2,1.73,567.97]],"batl":[[0,1.85,42.01],[1,1.86,480.59],[2,1.88,497.4]],"ltp":1.79,"tv":1982.29,"id":5858055},{"batl":[[0,2.4,29.41],[1,1000,0.02],[2,2.4,0]],"ltp":2.28,"tv":2302.66,"id":7444998}]}]}
{"op":"mcm","clk":"1004191161","pt":1580653821866,"mc":[{"id":"1.168224459","rc":[{"trd":[[1.79,633.35]],"batb":[[0,1.75,494.03],[1,1.73,510.84],[2,1.72,97.41]],"batl":[[0,1.86,480.59],[1,1.88,497.4],[2,2.1,413.72]],"ltp":1.79,"tv":2007.15,"id":5858055},{"trd":[[2.28,190.26]],"batb":[[0,2.28,31.1],[1,2,112.12],[2,1.96,124.94]],"batl":[[0,1000,0.02],[1,1000,0]],"ltp":2.28,"tv":2322.18,"id":7444998}],"tv":4329.33}]}
{"op":"mcm","clk":"1004191600","pt":1580653824362,"mc":[{"id":"1.168224459","rc":[{"batb":[[2,1.72,205.75]],"batl":[[2,1.97,104.59]],"ltp":1.79,"tv":2007.15,"id":5858055}]}]}
{"op":"mcm","clk":"1004191723","pt":1580653825045,"mc":[{"id":"1.168224459","rc":[{"batb":[[1,2.02,110.63],[2,2,112.12]],"ltp":2.28,"tv":2322.18,"id":7444998}]}]}
{"op":"mcm","clk":"1004192029","pt":1580653826677,"mc":[{"id":"1.168224459","rc":[{"batb":[[2,1.72,97.41]],"batl":[[2,2.1,413.72]],"ltp":1.79,"tv":2007.15,"id":5858055}]}]}
{"op":"mcm","clk":"1004192393","pt":1580653828650,"mc":[{"id":"1.168224459","rc":[{"batl":[[2,2.1,50.41]],"ltp":1.79,"tv":2007.15,"id":5858055}]}]}
{"op":"mcm","clk":"1004192632","pt":1580653830153,"mc":[{"id":"1.168224459","rc":[{"trd":[[1.79,672.96]],"batb":[[0,1.8,75.33],[1,1.78,138.61],[2,1.75,494.03]],"batl":[[0,1.86,569.56],[1,1.88,615.51]],"ltp":1.79,"tv":2046.76,"id":5858055},{"trd":[[2.28,221.36]],"batb":[[0,2.02,110.63],[1,2,112.12],[2,1.96,124.94]],"ltp":2.28,"tv":2353.28,"id":7444998}],"tv":4400.04}]}
{"op":"mcm","clk":"1004193189","pt":1580653833282,"mc":[{"id":"1.168224459","rc":[{"batb":[[0,1.75,494.03],[1,1.73,510.84],[2,1.72,97.41]],"batl":[[0,1.86,480.59],[1,1.88,497.4]],"ltp":1.79,"tv":2046.76,"id":5858055}]}]}
{"op":"mcm","clk":"1004193578","pt":1580653835581,"mc":[{"id":"1.168224459","rc":[{"batb":[[2,1.72,182.95]],"batl":[[2,1.96,74]],"ltp":1.79,"tv":2046.76,"id":5858055}]}]}
{"op":"mcm","clk":"1004193937","pt":1580653837673,"mc":[{"id":"1.168224459","rc":[{"batb":[[2,1.72,97.41]],"batl":[[0,1.96,74],[1,1.98,100.71],[2,2.1,50.41]],"ltp":1.79,"tv":2046.76,"id":5858055}]}]}
{"op":"mcm","clk":"1004194453","pt":1580653840411,"mc":[{"id":"1.168224459","rc":[{"batb":[[0,1.9,79.41],[1,1.88,115.94],[2,1.75,494.03]],"batl":[[1,1.98,546.52]],"ltp":1.79,"tv":2046.76,"id":5858055},{"batb":[[0,2.08,8.07],[1,2.02,110.63],[2,2,112.12]],"batl":[[0,2.12,190.41],[1,2.16,167],[2,2.18,100.25]],"ltp":2.28,"tv":2353.28,"id":7444998}]}]}
{"op":"mcm","clk":"1004194630","pt":1580653841270,"mc":[{"id":"1.168224459","rc":[{"batb":[[0,1.91,70.5],[1,1.9,79.41],[2,1.88,115.94]],"ltp":1.79,"tv":2046.76,"id":5858055}]}]}
{"op":"mcm","clk":"1004194817","pt":1580653842419,"mc":[{"id":"1.168224459","rc":[{"batb":[[1,2.02,110],[2,1.96,124.94]],"ltp":2.28,"tv":2353.28,"id":7444998}]}]}
{"op":"mcm","clk":"1004195000","pt":1580653843435,"mc":[{"id":"1.168224459","rc":[{"batl":[[0,1.96,116.01]],"ltp":1.79,"tv":2046.76,"id":5858055},{"batb":[[1,2.02,151.17]],"ltp":2.28,"tv":2353.28,"id":7444998}]}]}
{"op":"mcm","clk":"1004195748","pt":1580653847441,"mc":[{"id":"1.168224459","rc":[{"trd":[[1.91,33.26]],"batb":[[0,1.91,37.24]],"ltp":1.91,"tv":2080.02,"id":5858055},{"trd":[[2.1,30.25]],"ltp":2.1,"tv":2383.53,"id":7444998}],"tv":4463.55}]}
{"op":"mcm","clk":"1004196591","pt":1580653851718,"mc":[{"id":"1.168224459","rc":[{"trd":[[1.91,51.81]],"batb":[[0,1.91,18.69]],"ltp":1.91,"tv":2098.57,"id":5858055},{"trd":[[2.1,47.12]],"ltp":2.1,"tv":2400.4,"id":7444998}],"tv":4498.97}]}
{"op":"mcm","clk":"1004197158","pt":1580653854854,"mc":[{"id":"1.168224459","rc":[{"trd":[[1.91,70.5]],"batb":[[0,1.9,79.41],[1,1.88,115.94],[2,1.81,51.25]],"ltp":1.91,"tv":2117.26,"id":5858055},{"trd":[[2.1,64.12],[2.12,110.2]],"batl":[[0,2.12,137.81]],"ltp":2.12,"tv":2522.6,"id":7444998}],"tv":4639.86}]}
{"op":"mcm","clk":"1004197838","pt":1580653858285,"mc":[{"id":"1.168224459","rc":[{"batl":[[1,1.98,100.71]],"ltp":1.91,"tv":2117.26,"id":5858055},{"batb":[[0,2.02,151.17],[1,1.96,124.94],[2,1.81,78.21]],"batl":[[0,2.12,131.44],[1,2.18,100.25],[2,2.22,33.61]],"ltp":2.12,"tv":2522.6,"id":7444998}]}]}
{"op":"mcm","clk":"1004197974","pt":1580653859037,"mc":[{"id":"1.168224459","rc":[{"batb":[[0,1.81,51.25],[1,1.79,85.53],[2,1.55,420.5]],"batl":[[0,1.96,42.01],[1,2.1,50.41],[2,2.3,309.75]],"ltp":1.91,"tv":2117.26,"id":5858055},{"batb":[[0,2.02,41.17]],"batl":[[0,2.22,33.61],[1,1000,0.02],[2,2.22,0]],"ltp":2.12,"tv":2522.6,"id":7444998}]}]}
{"op":"mcm","clk":"1004198069","pt":1580653859527,"mc":[{"id":"1.168224459","rc":[{"batb":[[0,1.79,85.53],[1,1.55,420.5],[2,1.4,75.73]],"batl":[[0,2.1,50.41],[1,2.3,309.75],[2,1000,0.02]],"ltp":1.91,"tv":2117.26,"id":5858055},{"batb":[[0,1.96,124.94],[1,1.81,78.21],[2,1.5,113.58]],"batl":[[0,1000,0.02],[1,1000,0]],"ltp":2.12,"tv":2522.6,"id":7444998}]}]}
{"op":"mcm","clk":"1004198392","pt":1580653861446,"mc":[{"id":"1.168224459","rc":[{"batb":[[1,1.78,117.92],[2,1.76,144.08]],"batl":[[1,2.24,106.51],[2,2.26,68.6]],"ltp":1.91,"tv":2117.26,"id":5858055}]}]}
{"op":"mcm","clk":"1004198499","pt":1580653862057,"mc":[{"id":"1.168224459","rc":[{"batb":[[0,1.78,204.78],[1,1.76,144.08],[2,1.55,420.5]],"ltp":1.91,"tv":2117.26,"id":5858055},{"batb":[[1,1.82,76.87]],"ltp":2.12,"tv":2522.6,"id":7444998}]}]}
{"op":"mcm","clk":"1004198747","pt":1580653863141,"mc":[{"id":"1.168224459","rc":[{"batb":[[0,2.12,16.87],[1,1.96,124.94],[2,1.82,76.87]],"ltp":2.12,"tv":2522.6,"id":7444998}]}]}
{"op":"mcm","clk":"1004200656","pt":1580653873461,"mc":[{"id":"1.168224459","rc":[{"batb":[[0,1.78,86.86],[1,1.55,420.5],[2,1.4,75.73]],"batl":[[1,2.3,309.75],[2,1000,0.02]],"ltp":1.91,"tv":2117.26,"id":5858055}]}]}
{"op":"mcm","clk":"1004201330","pt":1580653876438,"mc":[{"id":"1.168224459","rc":[{"trd":[[1.9,18.83],[2.06,134.01],[2.1,100.82]],"batb":[[0,2.12,99.71],[1,2.1,99.71],[2,1.78,86.86]],"batl":[[0,2.18,35.29],[1,2.2,12.88],[2,2.26,188]],"ltp":2.1,"tv":2355.78,"id":5858055},{"trd":[[1.96,211.14],[2.12,127.07]],"batb":[[0,1.85,48.73],[1,1.82,76.87],[2,1.81,108.34]],"batl":[[0,1.87,87.75],[1,1.89,129.59],[2,1.91,199]],"ltp":1.96,"tv":2664.41,"id":7444998}],"tv":5020.19}]}
{"op":"mcm","clk":"1004201523","pt":1580653877362,"mc":[{"id":"1.168224459","rc":[{"batb":[[0,2.12,200.11],[2,1.93,68.06]],"ltp":2.1,"tv":2355.78,"id":5858055},{"batb":[[0,1.82,76.87],[1,1.81,108.34],[2,1.79,135.33]],"ltp":1.96,"tv":2664.41,"id":7444998}]}]}
{"op":"mcm","clk":"1004202102","pt":1580653880276,"mc":[{"id":"1.168224459","rc":[{"trd":[[2.18,8.87]],"batl":[[0,2.2,12.88],[1,2.26,188],[2,2.28,298.5]],"ltp":2.18,"tv":2364.65,"id":5858055},{"batb":[[0,1.84,49.57],[1,1.82,76.87],[2,1.81,108.34]],"ltp":1.96,"tv":2664.41,"id":7444998}],"tv":5029.06}]}
{"op":"mcm","clk":"1004202728","pt":1580653883066,"mc":[{"id":"1.168224459","rc":[{"batb":[[2,2.02,41.17]],"batl":[[0,2.2,47.33]],"ltp":2.18,"tv":2364.65,"id":5858055},{"batl":[[2,1.9,480.59]],"ltp":1.96,"tv":2664.41,"id":7444998}]}]}
{"op":"mcm","clk":"1004204623","pt":1580653892159,"mc":[{"id":"1.168224459","rc":[{"trd":[[2.2,0.1]],"batl":[[0,2.2,47.28]],"ltp":2.2,"tv":2364.75,"id":5858055}],"tv":5029.16}]}
{"op":"mcm","clk":"1004204787","pt":1580653892873,"mc":[{"id":"1.168224459","rc":[{"trd":[[1.87,103.52]],"batl":[[0,1.89,14.06],[1,1.9,480.59],[2,1.91,199]],"ltp":1.87,"tv":2731.89,"id":7444998}],"tv":5096.64}]}
{"op":"mcm","clk":"1004205108","pt":1580653894388,"mc":[{"id":"1.168224459","rc":[{"trd":[[1.89,28.12]],"batb":[[0,1.89,70.09],[1,1.84,49.57],[2,1.82,76.87]],"batl":[[0,1.9,480.59],[1,1.91,199],[2,1.92,497.4]],"ltp":1.89,"tv":2760.01,"id":7444998}],"tv":5124.76}]}
{"op":"mcm","clk":"1004205486","pt":1580653896211,"mc":[{"id":"1.168224459","rc":[{"trd":[[1.89,168.3]],"batb":[[0,1.84,49.57],[1,1.82,76.87],[2,1.77,494.03]],"batl":[[0,1.88,58.76],[1,1.9,594.15],[2,1.91,199]],"ltp":1.89,"tv":2900.19,"id":7444998}],"tv":5264.95}]}
{"op":"mcm","clk":"1004205710","pt":1580653897296,"mc":[{"id":"1.168224459","rc":[{"batl":[[0,2.2,34.45],[1,2.72,241.55],[2,1000,0.02]],"ltp":2.2,"tv":2364.75,"id":5858055},{"trd":[[1.84,40]],"batb":[[0,1.84,29.57]],"batl":[[2,1.92,497.4]],"ltp":1.84,"tv":2940.19,"id":7444998}],"tv":5304.94}]}
{"op":"mcm","clk":"1004205865","pt":1580653898096,"mc":[{"id":"1.168224459","rc":[{"batb":[[0,2.02,41.17],[1,1.93,68.06],[2,1.67,409.76]],"ltp":2.2,"tv":2364.75,"id":5858055},{"batb":[[1,1.77,494.03],[2,1.75,510.84]],"batl":[[0,1.9,480.59],[1,1.92,497.4],[2,1.99,42.01]],"ltp":1.84,"tv":2940.19,"id":7444998}]}]}
{"op":"mcm","clk":"1004206305","pt":1580653900195,"mc":[{"id":"1.168224459","rc":[{"batb":[[0,1.93,68.06],[1,1.67,409.76],[2,1.4,75.73]],"batl":[[0,2.72,241.55],[1,1000,0.02],[2,1000,0]],"ltp":2.2,"tv":2364.75,"id":5858055},{"batb":[[0,1.84,19.32]],"batl":[[2,2.12,3.58]],"ltp":1.84,"tv":2940.19,"id":7444998}]}]}
{"op":"mcm","clk":"1004206364","pt":1580653900495,"mc":[{"id":"1.168224459","rc":[{"batb":[[0,1.77,494.03],[1,1.75,510.84],[2,1.56,129.27]],"batl":[[2,2.1,81.65]],"ltp":1.84,"tv":2940.19,"id":7444998}]}]}
{"op":"mcm","clk":"1004206931","pt":1580653903193,"mc":[{"id":"1.168224459","rc":[{"trd":[[1.9,33.74]],"batl":[[0,1.9,463.72]],"ltp":1.9,"tv":2973.93,"id":7444998}],"tv":5338.69}]}
{"op":"mcm","clk":"1004207022","pt":1580653903621,"mc":[{"id":"1.168224459","rc":[{"batb":[[2,1.5,113.58]],"ltp":2.2,"tv":2364.75,"id":5858055},{"batl":[[0,2.12,3.58],[1,1000,0.02],[2,2.1,0]],"ltp":1.9,"tv":2973.93,"id":7444998}]}]}
{"op":"mcm","clk":"1004207327","pt":1580653905073,"mc":[{"id":"1.168224459","rc":[{"batl":[[0,1000,0.02],[1,1000,0]],"ltp":2.2,"tv":2364.75,"id":5858055}]}]}
{"op":"mcm","clk":"1004207594","pt":1580653906419,"mc":[{"id":"1.168224459","rc":[{"trd":[[1.93,163.82]],"batb":[[0,1.67,409.76],[1,1.5,113.58],[2,1.4,75.73]],"batl":[[0,1.92,7.97],[1,1.93,210.76],[2,1.95,1234.08]],"ltp":1.93,"tv":2500.87,"id":5858055},{"batb":[[0,2,187.5],[1,1.77,494.03],[2,1.75,510.84]],"batl":[[1,2.14,214],[2,2.16,263.1]],"ltp":1.9,"tv":2973.93,"id":7444998}],"tv":5474.81}]}
{"op":"mcm","clk":"1004207773","pt":1580653907286,"mc":[{"id":"1.168224459","rc":[{"batb":[[0,1.91,84.7],[1,1.89,113.98],[2,1.81,83.32]],"batl":[[0,1.93,210.76],[1,1.98,114.37],[2,2,97.68]],"ltp":1.93,"tv":2500.87,"id":5858055},{"batb":[[0,2,301.59],[1,1.8,80.18],[2,1.77,494.03]],"batl":[[2,2.16,245.08]],"ltp":1.9,"tv":2973.93,"id":7444998}]}]}
{"op":"mcm","clk":"1004207985","pt":1580653908409,"mc":[{"id":"1.168224459","rc":[{"batb":[[2,1.4,75.73]],"ltp":1.9,"tv":2973.93,"id":7444998}]}]}
{"op":"mcm","clk":"1004208113","pt":1580653909007,"mc":[{"id":"1.168224459","rc":[{"batb":[[2,1.86,48.73]],"ltp":1.93,"tv":2500.87,"id":5858055},{"batb":[[1,1.99,42.01],[2,1.8,80.18]],"batl":[[2,2.16,281.21]],"ltp":1.9,"tv":2973.93,"id":7444998}]}]}
{"op":"mcm","clk":"1004208266","pt":1580653909832,"mc":[{"id":"1.168224459","rc":[{"batl":[[0,1.92,7.97],[1,1.93,210.76],[2,1.98,114.37]],"ltp":1.93,"tv":2500.87,"id":5858055},{"batl":[[2,2.16,299.23]],"ltp":1.9,"tv":2973.93,"id":7444998}]}]}
{"op":"mcm","clk":"1004209092","pt":1580653914186,"mc":[{"id":"1.168224459","rc":[{"batl":[[0,2.14,214],[1,2.16,299.23],[2,1000,0.02]],"ltp":1.9,"tv":2973.93,"id":7444998}]}]}
{"op":"mcm","clk":"1004209239","pt":1580653914992,"mc":[{"id":"1.168224459","rc":[{"trd":[[1.91,87.28]],"batb":[[0,1.86,48.73],[1,1.81,83.32],[2,1.67,409.76]],"ltp":1.91,"tv":2517.65,"id":5858055},{"trd":[[2.1,79.38]],"ltp":2.1,"tv":2989.2,"id":7444998}],"tv":5506.85}]}
{"op":"mcm","clk":"1004209904","pt":1580653918406,"mc":[{"id":"1.168224459","rc":[{"trd":[[1.92,118.73]],"batl":[[0,2.02,41.17],[1,2.5,274.54],[2,1000,0.02]],"ltp":1.92,"tv":2521.53,"id":5858055},{"trd":[[2.08,135.55]],"batb":[[0,1.99,42.01],[1,1.8,80.18],[2,1.5,113.58]],"batl":[[0,2.16,36.13],[1,1000,0.02],[2,1000,0]],"ltp":2.08,"tv":2992.78,"id":7444998}],"tv":5514.32}]}
{"op":"mcm","clk":"1004210028","pt":1580653918989,"mc":[{"id":"1.168224459","rc":[{"batl":[[0,2.08,3],[1,2.16,36.13],[2,1000,0.02]],"ltp":2.08,"tv":2992.78,"id":7444998}]}]}
{"op":"mcm","clk":"1004210127","pt":1580653919528,"mc":[{"id":"1.168224459","rc":[{"batb":[[0,1.81,83.32],[1,1.67,409.76],[2,1.4,75.73]],"batl":[[0,2.5,274.54],[1,1000,0.02],[2,1000,0]],"ltp":1.92,"tv":2521.53,"id":5858055},{"batb":[[0,1.8,80.18],[1,1.5,113.58],[2,1.4,75.73]],"batl":[[1,1000,0.02],[2,1000,0]],"ltp":2.08,"tv":2992.78,"id":7444998}]}]}
{"op":"mcm","clk":"1004210476","pt":1580653921295,"mc":[{"id":"1.168224459","rc":[{"batb":[[1,1.77,84.98],[2,1.67,409.76]],"ltp":1.92,"tv":2521.53,"id":5858055},{"batb":[[0,1.81,78.6],[1,1.8,80.18],[2,1.5,113.58]],"ltp":2.08,"tv":2992.78,"id":7444998}]}]}
{"op":"mcm","clk":"1004210611","pt":1580653922014,"mc":[{"id":"1.168224459","rc":[{"batb":[[0,1.79,97.33],[1,1.77,226.32]],"batl":[[0,2.26,131.75],[1,2.28,66.92],[2,2.5,274.54]],"ltp":1.92,"tv":2521.53,"id":5858055},{"batb":[[1,1.5,113.58],[2,1.4,75.73]],"ltp":2.08,"tv":2992.78,"id":7444998}]}]}
{"op":"mcm","clk":"1004211877","pt":1580653927917,"mc":[{"id":"1.168224459","rc":[{"batb":[[0,1.77,84.98],[1,1.67,409.76],[2,1.4,75.73]],"batl":[[0,2.5,274.54],[1,1000,0.02],[2,2.5,0]],"ltp":1.92,"tv":2521.53,"id":5858055}]}]}
{"op":"mcm","clk":"1004212180","pt":1580653929336,"mc":[{"id":"1.168224459","rc":[{"batl":[[0,1000,0.02],[1,1000,0]],"ltp":1.92,"tv":2521.53,"id":5858055}]}]}
{"op":"mcm","clk":"1004212494","pt":1580653931123,"mc":[{"id":"1.168224459","rc":[{"batl":[[0,2.3,206],[1,1000,0.02]],"ltp":1.92,"tv":2521.53,"id":5858055},{"batb":[[1,1.8,122.6],[2,1.78,137.75]],"batl":[[0,1.86,214.95],[1,1.88,117.34],[2,1.89,223]],"ltp":2.08,"tv":2992.78,"id":7444998}]}]}
{"op":"mcm","clk":"1004212745","pt":1580653932423,"mc":[{"id":"1.168224459","rc":[{"batb":[[0,2.1,98.2],[1,1.91,66.56],[2,1.67,409.76]],"ltp":1.92,"tv":2521.53,"id":5858055}]}]}
{"op":"mcm","clk":"1004212913","pt":1580653933335,"mc":[{"id":"1.168224459","rc":[{"batb":[[1,2.04,40.33],[2,1.91,66.56]],"batl":[[0,2.24,33.61],[1,2.3,206],[2,2.82,231.28]],"ltp":1.92,"tv":2521.53,"id":5858055},{"batb":[[0,1.81,129.86]],"ltp":2.08,"tv":2992.78,"id":7444998}]}]}
{"op":"mcm","clk":"1004212978","pt":1580653933612,"mc":[{"id":"1.168224459","rc":[{"batl":[[0,2.2,11.55],[1,2.24,33.61],[2,2.3,206]],"ltp":1.92,"tv":2521.53,"id":5858055},{"batl":[[2,1.89,238.55]],"ltp":2.08,"tv":2992.78,"id":7444998}]}]}
{"op":"mcm","clk":"1004213185","pt":1580653934728,"mc":[{"id":"1.168224459","rc":[{"trd":[[2.16,0.12]],"ltp":2.16,"tv":2521.65,"id":5858055},{"trd":[[1.86,0.14]],"batl":[[0,1.86,214.81]],"ltp":1.86,"tv":2992.92,"id":7444998}],"tv":5514.58}]}
{"op":"mcm","clk":"1004215289","pt":1580653946351,"mc":[{"id":"1.168224459","rc":[{"batl":[[0,2.24,33.61],[1,2.82,231.28],[2,1000,0.02]],"ltp":2.16,"tv":2521.65,"id":5858055},{"batb":[[1,1.55,132.66],[2,1.4,75.73]],"batl":[[0,1.86,135.67],[1,1.91,135.81],[2,1.96,42.01]],"ltp":1.86,"tv":2992.92,"id":7444998}]}]}
{"op":"mcm","clk":"1004215421","pt":1580653947127,"mc":[{"id":"1.168224459","rc":[{"batb":[[0,2.04,40.33],[1,1.91,66.56],[2,1.67,409.76]],"ltp":2.16,"tv":2521.65,"id":5858055},{"batb":[[0,1.81,51.25]],"batl":[[0,1.96,42.01],[1,1000,0.02],[2,1.96,0]],"ltp":1.86,"tv":2992.92,"id":7444998}]}]}
{"op":"mcm","clk":"1004215517","pt":1580653947534,"mc":[{"id":"1.168224459","rc":[{"batb":[[0,1.91,66.56],[1,1.67,409.76],[2,1.5,113.58]],"batl":[[0,2.82,231.28],[1,1000,0.02],[2,1000,0]],"ltp":2.16,"tv":2521.65,"id":5858055},{"batb":[[0,1.55,132.66],[1,1.4,75.73],[2,1.3,113.58]],"batl":[[0,1000,0.02],[1,1000,0]],"ltp":1.86,"tv":2992.92,"id":7444998}]}]}
{"op":"mcm","clk":"1004215843","pt":1580653949365,"mc":[{"id":"1.168224459","rc":[{"batb":[[1,1.54,106.51],[2,1.53,119.25]],"batl":[[0,2.08,93.36],[1,2.1,84.64],[2,1000,0.02]],"ltp":1.86,"tv":2992.92,"id":7444998}]}]}
{"op":"mcm","clk":"1004217386","pt":1580653957979,"mc":[{"id":"1.168224459","rc":[{"batb":[[1,1.4,75.73],[2,1.3,113.58]],"batl":[[0,1000,0.02],[1,2.1,0],[2,1000,0]],"ltp":1.86,"tv":2992.92,"id":7444998}]}]}
{"op":"mcm","clk":"1004217714","pt":1580653959760,"mc":[{"id":"1.168224459","rc":[{"batl":[[0,1000,0.02],[1,1000,0]],"ltp":2.16,"tv":2521.65,"id":5858055}]}]}
{"op":"mcm","clk":"1004217986","pt":1580653961252,"mc":[{"id":"1.168224459","rc":[{"trd":[[1.91,451.64]],"batb":[[0,1.91,80.86],[1,1.89,251.26],[2,1.67,409.76]],"batl":[[0,1.96,10.63],[1,2.02,94.83],[2,2.04,461.74]],"ltp":1.91,"tv":2886.01,"id":5858055},{"batb":[[0,2,102.82],[1,1.55,132.66],[2,1.4,75.73]],"batl":[[0,2.1,174],[1,1000,0.02]],"ltp":1.86,"tv":2992.92,"id":7444998}],"tv":5878.94}]}
{"op":"mcm","clk":"1004218215","pt":1580653962449,"mc":[{"id":"1.168224459","rc":[{"batb":[[2,1.88,47.05]],"batl":[[2,2.04,502.07]],"ltp":1.91,"tv":2886.01,"id":5858055},{"batb":[[1,1.99,115.82],[2,1.96,43.69]],"batl":[[1,2.16,36.13],[2,1000,0.02]],"ltp":1.86,"tv":2992.92,"id":7444998}]}]}
{"op":"mcm","clk":"1004218546","pt":1580653964262,"mc":[{"id":"1.168224459","rc":[{"batb":[[0,1.91,130.03],[1,1.89,365.27]],"batl":[[1,1.99,119.79],[2,2.02,142.99]],"ltp":1.91,"tv":2886.01,"id":5858055}]}]}
{"op":"mcm","clk":"1004219194","pt":1580653967794,"mc":[{"id":"1.168224459","rc":[{"batl":[[2,2.24,3.98]],"ltp":1.86,"tv":2992.92,"id":7444998}]}]}
{"op":"mcm","clk":"1004219742","pt":1580653970739,"mc":[{"id":"1.168224459","rc":[{"batl":[[0,1.99,119.79],[1,2.02,142.99],[2,2.04,502.07]],"ltp":1.91,"tv":2886.01,"id":5858055}]}]}
{"op":"mcm","clk":"1004220259","pt":1580653973710,"mc":[{"id":"1.168224459","rc":[{"batl":[[0,1.94,9.23],[1,1.99,119.79],[2,2.02,142.99]],"ltp":1.91,"tv":2886.01,"id":5858055},{"batl":[[1,2.12,11.78],[2,2.16,36.13]],"ltp":1.86,"tv":2992.92,"id":7444998}]}]}
{"op":"mcm","clk":"1004221057","pt":1580653978213,"mc":[{"id":"1.168224459","rc":[{"batb":[[0,1.88,47.17],[1,1.79,81.51],[2,1.78,24.66]],"batl":[[0,2.04,40.33],[1,2.2,5.23],[2,2.28,4.84]],"ltp":1.91,"tv":2886.01,"id":5858055},{"batb":[[0,1.96,43.69],[1,1.78,81.99],[2,1.77,24.37]],"batl":[[0,2.16,36.13],[1,2.3,4.95],[2,1000,0.02]],"ltp":1.86,"tv":2992.92,"id":7444998}]}]}
{"op":"mcm","clk":"1004221247","pt":1580653979074,"mc":[{"id":"1.168224459","rc":[{"batl":[[1,2.3,4.15],[2,2.5,274.54]],"ltp":1.91,"tv":2886.01,"id":5858055}]}]}
{"op":"mcm","clk":"1004221359","pt":1580653979623,"mc":[{"id":"1.168224459","rc":[{"batb":[[0,1.79,81.64],[1,1.78,24.66],[2,1.67,409.76]],"batl":[[0,2.3,4.15],[1,2.5,274.54],[2,1000,0.02]],"ltp":1.91,"tv":2886.01,"id":5858055},{"batb":[[0,1.78,81.99],[1,1.77,24.37],[2,1.5,113.58]],"batl":[[0,2.3,4.95],[1,1000,0.02],[2,1000,0]],"ltp":1.86,"tv":2992.92,"id":7444998}]}]}
{"op":"mcm","clk":"1004221696","pt":1580653981196,"mc":[{"id":"1.168224459","rc":[{"batb":[[0,1.79,148.4],[1,1.78,107.75],[2,1.77,141.52]],"batl":[[0,2.26,88.59],[1,2.28,66.82],[2,2.3,4.15]],"ltp":1.91,"tv":2886.01,"id":5858055},{"batb":[[0,1.81,80.49]],"ltp":1.86,"tv":2992.92,"id":7444998}]}]}
{"op":"mcm","clk":"1004221891","pt":1580653982292,"mc":[{"id":"1.168224459","rc":[{"batb":[[0,1.84,23.22],[1,1.81,80.49],[2,1.77,24.37]],"ltp":1.86,"tv":2992.92,"id":7444998}]}]}
{"op":"mcm","clk":"1004222096","pt":1580653983284,"mc":[{"id":"1.168224459","rc":[{"batb":[[0,1.79,148.28]],"ltp":1.91,"tv":2886.01,"id":5858055},{"batb":[[0,1.81,80.49],[1,1.77,24.37],[2,1.5,113.58]],"ltp":1.86,"tv":2992.92,"id":7444998}]}]}
{"op":"mcm","clk":"1004222201","pt":1580653983802,"mc":[{"id":"1.168224459","rc":[{"batb":[[0,1.78,107.75],[1,1.67,409.76],[2,1.4,75.73]],"batl":[[0,2.3,4.15],[1,2.5,274.54],[2,1000,0.02]],"ltp":1.91,"tv":2886.01,"id":5858055}]}]}
{"op":"mcm","clk":"1004222524","pt":1580653985286,"mc":[{"id":"1.168224459","rc":[{"batl":[[0,2.2,5.08],[1,2.3,4.15],[2,2.5,274.54]],"ltp":1.91,"tv":2886.01,"id":5858055}]}]}
{"op":"mcm","clk":"1004222732","pt":1580653986387,"mc":[{"id":"1.168224459","rc":[{"batb":[[1,1.4,75.73],[2,1.3,113.58]],"batl":[[0,1.83,13.77],[1,1.85,3264.2],[2,1.91,223]],"ltp":1.91,"tv":2886.01,"id":5858055},{"batb":[[0,2.18,874.21],[1,2.16,910.96],[2,1.81,80.49]],"batl":[[0,2.26,168],[1,2.28,237.8],[2,2.3,4.95]],"ltp":1.86,"tv":2992.92,"id":7444998}]}]}
{"op":"mcm","clk":"1004222805","pt":1580653986780,"mc":[{"id":"1.168224459","rc":[{"batb":[[0,1.79,148.28],[1,1.78,107.75],[2,1.77,163.89]],"batl":[[1,1.86,123.85],[2,1.88,118.27]],"ltp":1.91,"tv":2886.01,"id":5858055},{"batb":[[0,2.18,87.42],[1,2.16,91.1]],"ltp":1.86,"tv":2992.92,"id":7444998}]}]}
{"op":"mcm","clk":"1004223109","pt":1580653988419,"mc":[{"id":"1.168224459","rc":[{"batb":[[1,2.16,183.63],[2,1.99,119.52]],"ltp":1.86,"tv":2992.92,"id":7444998}]}]}
{"op":"mcm","clk":"1004223129","pt":1580653988506,"mc":[{"id":"1.168224459","rc":[{"batb":[[1,1.78,161.52]],"ltp":1.91,"tv":2886.01,"id":5858055},{"batb":[[2,2.08,38.65]],"batl":[[1,2.28,270.57]],"ltp":1.86,"tv":2992.92,"id":7444998}]}]}
{"op":"mcm","clk":"1004224405","pt":1580653994826,"mc":[{"id":"1.168224459","rc":[{"trd":[[1.83,89.84]],"batl":[[0,1.83,13.65]],"ltp":1.83,"tv":2886.26,"id":5858055}],"tv":5879.19}]}
{"op":"mcm","clk":"1004225113","pt":1580653998367,"mc":[{"id":"1.168224459","rc":[{"batl":[[0,1.86,123.85],[1,1.88,118.27],[2,1.93,42.01]],"ltp":1.83,"tv":2886.26,"id":5858055},{"batl":[[0,2.28,32.77],[1,2.3,4.95],[2,2.32,4.61]],"ltp":1.86,"tv":2992.92,"id":7444998}]}]}
{"op":"mcm","clk":"1004225332","pt":1580653999400,"mc":[{"id":"1.168224459","rc":[{"batb":[[0,1.78,53.77],[1,1.74,22.52],[2,1.7,96.07]],"batl":[[0,1.93,42.01],[1,2,15.45],[2,2.3,4.15]],"ltp":1.83,"tv":2886.26,"id":5858055},{"batb":[[0,2.08,38.65],[1,2,17.41],[2,1.99,119.52]],"batl":[[1,2.36,4.57],[2,1000,0.02]],"ltp":1.86,"tv":2992.92,"id":7444998}]}]}
{"op":"mcm","clk":"1004225349","pt":1580653999533,"mc":[{"id":"1.168224459","rc":[{"batb":[[0,1.74,22.52],[1,1.7,96.07],[2,1.52,425.49]],"batl":[[0,2,15.45],[1,2.3,4.15],[2,2.36,299.17]],"ltp":1.83,"tv":2886.26,"id":5858055},{"batb":[[0,2,17.41],[1,1.99,119.52],[2,1.77,24.37]],"batl":[[0,2.36,4.57],[1,1000,0.02],[2,1000,0]],"ltp":1.86,"tv":2992.92,"id":7444998}]}]}
{"op":"mcm","clk":"1004225672","pt":1580654001203,"mc":[{"id":"1.168224459","rc":[{"batl":[[0,1.79,1.22],[1,2,15.45],[2,2.3,4.15]],"ltp":1.83,"tv":2886.26,"id":5858055}]}]}
{"op":"mcm","clk":"1004225871","pt":1580654002212,"mc":[{"id":"1.168224459","rc":[{"batb":[[1,1.73,87.74],[2,1.71,158.83]],"batl":[[0,1.79,4.58],[2,2.02,150.72]],"ltp":1.83,"tv":2886.26,"id":5858055}]}]}
{"op":"mcm","clk":"1004226482","pt":1580654005441,"mc":[{"id":"1.168224459","rc":[{"batb":[[0,1.76,21.73],[1,1.74,22.52],[2,1.73,87.74]],"ltp":1.83,"tv":2886.26,"id":5858055},{"batb":[[0,2.04,6.12],[1,2,17.41],[2,1.99,119.52]],"batl":[[0,2.32,4.61],[1,2.36,4.57],[2,1000,0.02]],"ltp":1.86,"tv":2992.92,"id":7444998}]}]}
{"op":"mcm","clk":"1004226641","pt":1580654006219,"mc":[{"id":"1.168224459","rc":[{"batb":[[0,1.74,22.52],[1,1.73,87.74],[2,1.71,158.83]],"batl":[[0,1.79,3.36]],"ltp":1.83,"tv":2886.26,"id":5858055},{"batb":[[0,2,17.41],[1,1.99,119.52],[2,1.77,24.37]],"batl":[[0,2.36,4.57],[1,1000,0.02],[2,1000,0]],"ltp":1.86,"tv":2992.92,"id":7444998}]}]}
{"op":"mcm","clk":"1004226915","pt":1580654007619,"mc":[{"id":"1.168224459","rc":[{"batb":[[1,1.7,96.07],[2,1.52,425.49]],"ltp":1.83,"tv":2886.26,"id":5858055}]}]}
{"op":"mcm","clk":"1004227258","pt":1580654009436,"mc":[{"id":"1.168224459","rc":[{"batl":[[1,1.95,15.7],[2,2,15.45]],"ltp":1.83,"tv":2886.26,"id":5858055}]}]}
{"op":"mcm","clk":"1004227453","pt":1580654010427,"mc":[{"id":"1.168224459","rc":[{"trd":[[1.79,676.32]],"batb":[[0,1.89,1094.54],[1,1.74,22.52],[2,1.7,96.07]],"batl":[[0,2,15.45],[1,2.02,150.72],[2,2.04,92.13]],"ltp":1.79,"tv":2889.62,"id":5858055},{"trd":[[2.26,679.11]],"batb":[[0,2.04,7.1],[1,2,17.41],[2,1.99,119.52]],"batl":[[0,2.08,1381.08],[1,2.1,982.3],[2,2.28,1010.89]],"ltp":2.26,"tv":2995.58,"id":7444998}],"tv":5885.21}]}
{"op":"mcm","clk":"1004227631","pt":1580654011329,"mc":[{"id":"1.168224459","rc":[{"batb":[[0,1.94,80.92],[1,1.92,173.47],[2,1.89,109.45]],"ltp":1.79,"tv":2889.62,"id":5858055},{"batl":[[0,2.08,223.16],[1,2.1,98.5]],"ltp":2.26,"tv":2995.58,"id":7444998}]}]}
{"op":"mcm","clk":"1004228016","pt":1580654013237,"mc":[{"id":"1.168224459","rc":[{"trd":[[2,45.21]],"batl":[[0,2.02,150.72],[1,2.04,92.13],[2,2.06,445.63]],"ltp":2.0,"tv":2905.07,"id":5858055},{"trd":[[1.99,55.81],[2,79.87],[2.04,39.53]],"batb":[[0,1.99,104.48],[1,1.95,43.69],[2,1.79,83.95]],"ltp":1.99,"tv":3090.14,"id":7444998}],"tv":5995.21}]}
{"op":"mcm","clk":"1004228249","pt":1580654014231,"mc":[{"id":"1.168224459","rc":[{"batb":[[2,1.89,156.5]],"ltp":2.0,"tv":2905.07,"id":5858055},{"batl":[[2,2.12,36.97]],"ltp":1.99,"tv":3090.14,"id":7444998}]}]}
{"op":"mcm","clk":"1004230097","pt":1580654023457,"mc":[{"id":"1.168224459","rc":[{"batl":[[0,2.08,215]],"ltp":1.99,"tv":3090.14,"id":7444998}]}]}
{"op":"mcm","clk":"1004230699","pt":1580654026367,"mc":[{"id":"1.168224459","rc":[{"batl":[[0,1.98,8],[1,2.02,150.72],[2,2.04,92.13]],"ltp":2.0,"tv":2905.07,"id":5858055},{"batl":[[0,2.06,7.71],[1,2.08,215],[2,2.1,98.5]],"ltp":1.99,"tv":3090.14,"id":7444998}]}]}
{"op":"mcm","clk":"1004231292","pt":1580654029266,"mc":[{"id":"1.168224459","rc":[{"trd":[[1.94,116.31]],"batb":[[0,1.94,23.57]],"batl":[[0,2.02,150.72],[1,2.04,92.13],[2,2.06,39.49]],"ltp":1.94,"tv":3019.77,"id":5858055},{"batl":[[0,2.1,98.5],[1,2.12,36.97],[2,2.24,5.73]],"ltp":1.99,"tv":3090.14,"id":7444998}],"tv":6109.91}]}
{"op":"mcm","clk":"1004231435","pt":1580654029877,"mc":[{"id":"1.168224459","rc":[{"batb":[[0,1.89,47.05],[1,1.81,22.29],[2,1.8,79.23]],"batl":[[0,2.06,39.49],[1,2.36,299.17],[2,3.05,2.9]],"ltp":1.94,"tv":3019.77,"id":5858055},{"batb":[[0,1.95,43.69],[1,1.79,83.95],[2,1.5,113.58]],"batl":[[0,2.12,36.97],[1,2.24,5.73],[2,2.36,4.57]],"ltp":1.99,"tv":3090.14,"id":7444998}]}]}
{"op":"mcm","clk":"1004231622","pt":1580654030750,"mc":[{"id":"1.168224459","rc":[{"batb":[[1,1.8,79.23],[2,1.79,21.31]],"batl":[[2,2.84,3.53]],"ltp":1.94,"tv":3019.77,"id":5858055},{"batl":[[1,2.28,5.34],[2,1000,0.02]],"ltp":1.99,"tv":3090.14,"id":7444998}]}]}
{"op":"mcm","clk":"1004231791","pt":1580654031559,"mc":[{"id":"1.168224459","rc":[{"batb":[[0,1.8,79.23],[1,1.79,21.31],[2,1.58,416.47]],"batl":[[0,2.36,299.17],[1,2.84,3.53],[2,3.05,2.9]],"ltp":1.94,"tv":3019.77,"id":5858055},{"batb":[[0,1.79,83.95],[1,1.5,113.58],[2,1.49,35.01]],"batl":[[0,2.28,5.34],[1,1000,0.02],[2,1000,0]],"ltp":1.99,"tv":3090.14,"id":7444998}]}]}
{"op":"mcm","clk":"1004232143","pt":1580654033255,"mc":[{"id":"1.168224459","rc":[{"batb":[[0,1.81,94.26],[1,1.8,78.92],[2,1.79,157.56]],"batl":[[0,2.28,86.4],[1,2.3,65.19],[2,2.36,299.17]],"ltp":1.94,"tv":3019.77,"id":5858055},{"batb":[[0,1.78,84.27]],"ltp":1.99,"tv":3090.14,"id":7444998}]}]}
{"op":"mcm","clk":"1004232322","pt":1580654034147,"mc":[{"id":"1.168224459","rc":[{"batb":[[1,1.55,34.39],[2,1.5,113.58]],"ltp":1.99,"tv":3090.14,"id":7444998}]}]}
{"op":"mcm","clk":"1004233213","pt":1580654038357,"mc":[{"id":"1.168224459","rc":[{"batb":[[0,1.84,23.97],[1,1.81,94.26],[2,1.8,78.92]],"ltp":1.94,"tv":3019.77,"id":5858055},{"batl":[[0,2.2,5.68],[1,2.28,5.34],[2,1000,0.02]],"ltp":1.99,"tv":3090.14,"id":7444998}]}]}
{"op":"mcm","clk":"1004233371","pt":1580654039170,"mc":[{"id":"1.168224459","rc":[{"batb":[[0,1.8,78.92],[1,1.79,21.31],[2,1.58,416.47]],"batl":[[0,2.36,299.17],[1,2.82,3.75],[2,2.84,3.53]],"ltp":1.94,"tv":3019.77,"id":5858055},{"batl":[[0,2.08,2.27]],"ltp":1.99,"tv":3090.14,"id":7444998}]}]}
{"op":"mcm","clk":"1004233615","pt":1580654040270,"mc":[{"id":"1.168224459","rc":[{"batb":[[2,1.4,75.73]],"batl":[[0,2.82,3.75],[1,2.84,3.53],[2,3.05,2.9]],"ltp":1.94,"tv":3019.77,"id":5858055}]}]}
{"op":"mcm","clk":"1004234035","pt":1580654042372,"mc":[{"id":"1.168224459","rc":[{"batb":[[0,2.16,7.03],[1,2.14,94.91],[2,1.8,78.92]],"batl":[[0,2.36,173],[1,2.82,3.75],[2,2.84,3.53]],"ltp":1.94,"tv":3019.77,"id":5858055},{"batb":[[0,1.8,9.13],[1,1.78,203.63],[2,1.76,142.87]],"batl":[[0,1.83,7.79],[1,1.84,287.32],[2,1.85,136.65]],"ltp":1.99,"tv":3090.14,"id":7444998}]}]}
{"op":"mcm","clk":"1004234249","pt":1580654043251,"mc":[{"id":"1.168224459","rc":[{"batb":[[0,2.16,98.14],[2,2.1,37.81]],"batl":[[0,2.3,31.93],[1,2.36,173],[2,2.82,3.75]],"ltp":1.94,"tv":3019.77,"id":5858055},{"batb":[[2,1.77,53.77]],"ltp":1.99,"tv":3090.14,"id":7444998}]}]}
{"op":"mcm","clk":"1004236081","pt":1580654051973,"mc":[{"id":"1.168224459","rc":[{"trd":[[1.8,4.88]],"batb":[[0,1.8,6.69]],"ltp":1.8,"tv":3095.01,"id":7444998}],"tv":6114.78}]}
{"op":"mcm","clk":"1004236495","pt":1580654053890,"mc":[{"id":"1.168224459","rc":[{"trd":[[1.83,2.44]],"batl":[[0,1.83,6.57]],"ltp":1.83,"tv":3097.45,"id":7444998}],"tv":6117.22}]}
{"op":"mcm","clk":"1004237385","pt":1580654057989,"mc":[{"id":"1.168224459","rc":[{"trd":[[1.8,8.24]],"batb":[[0,1.8,5.01]],"ltp":1.8,"tv":3100.81,"id":7444998}],"tv":6120.58}]}
{"op":"mcm","clk":"1004237651","pt":1580654059277,"mc":[{"id":"1.168224459","rc":[{"trd":[[1.83,15.58],[1.84,226.86]],"batl":[[0,1.84,193.89],[1,1.85,136.65],[2,1.86,121.13]],"ltp":1.84,"tv":3300.81,"id":7444998}],"tv":6320.58}]}
{"op":"mcm","clk":"1004237834","pt":1580654060308,"mc":[{"id":"1.168224459","rc":[{"batl":[[1,2.82,3.75],[2,2.84,3.53]],"ltp":1.94,"tv":3019.77,"id":5858055},{"batb":[[0,1.78,203.63],[1,1.77,53.77],[2,1.76,142.87]],"batl":[[0,1.84,93.32]],"ltp":1.84,"tv":3300.81,"id":7444998}]}]}
{"op":"mcm","clk":"1004238053","pt":1580654061407,"mc":[{"id":"1.168224459","rc":[{"batb":[[0,2.1,37.81],[1,1.94,62.32],[2,1.93,21.93]],"batl":[[1,3,213.45],[2,3.15,3.1]],"ltp":1.94,"tv":3019.77,"id":5858055},{"batb":[[0,1.77,53.77],[1,1.54,140.29],[2,1.47,35.68]],"batl":[[0,1.91,42.01],[1,2.08,7.96],[2,2.12,3.79]],"ltp":1.84,"tv":3300.81,"id":7444998}]}]}
{"op":"mcm","clk":"1004238126","pt":1580654061785,"mc":[{"id":"1.168224459","rc":[{"batb":[[0,1.94,62.32],[1,1.85,21.57],[2,1.77,402.27]],"batl":[[0,3,213.45],[1,3.15,3.1],[2,3.8,2.02]],"ltp":1.94,"tv":3019.77,"id":5858055},{"batb":[[0,1.54,140.29],[1,1.47,35.68],[2,1.4,75.72]],"batl":[[0,2.08,2.27],[1,2.12,3.79],[2,2.18,5.25]],"ltp":1.84,"tv":3300.81,"id":7444998}]}]}
{"op":"mcm","clk":"1004238382","pt":1580654063087,"mc":[{"id":"1.168224459","rc":[{"batb":[[1,1.87,21.27],[2,1.85,21.57]],"ltp":1.94,"tv":3019.77,"id":5858055},{"batl":[[2,2.16,5.22]],"ltp":1.84,"tv":3300.81,"id":7444998}]}]}
{"op":"mcm","clk":"1004238470","pt":1580654063508,"mc":[{"id":"1.168224459","rc":[{"batb":[[1,1.53,110.61],[2,1.52,122.07]],"batl":[[0,2.06,127.86],[1,2.08,89.27],[2,2.12,3.79]],"ltp":1.84,"tv":3300.81,"id":7444998}]}]}
{"op":"mcm","clk":"1004238765","pt":1580654064884,"mc":[{"id":"1.168224459","rc":[{"batb":[[1,1.93,18.36],[2,1.87,21.27]],"ltp":1.94,"tv":3019.77,"id":5858055},{"batl":[[1,2.08,95.46]],"ltp":1.84,"tv":3300.81,"id":7444998}]}]}
{"op":"mcm","clk":"1004238997","pt":1580654066088,"mc":[{"id":"1.168224459","rc":[{"batb":[[1,1.87,21.27],[2,1.85,21.57]],"ltp":1.94,"tv":3019.77,"id":5858055},{"batb":[[1,1.47,35.68],[2,1.4,75.72]],"batl":[[0,2.08,2.27],[1,2.12,3.79],[2,2.16,5.22]],"ltp":1.84,"tv":3300.81,"id":7444998}]}]}
{"op":"mcm","clk":"1004239611","pt":1580654069382,"mc":[{"id":"1.168224459","rc":[{"batb":[[1,1.93,18.93],[2,1.87,21.27]],"ltp":1.94,"tv":3019.77,"id":5858055},{"batl":[[0,2.08,7.96]],"ltp":1.84,"tv":3300.81,"id":7444998}]}]}
{"op":"mcm","clk":"1004239759","pt":1580654070011,"mc":[{"id":"1.168224459","rc":[{"batb":[[1,1.87,21.27],[2,1.85,21.57]],"ltp":1.94,"tv":3019.77,"id":5858055},{"batb":[[2,1.36,50.43]],"batl":[[0,2.08,2.27]],"ltp":1.84,"tv":3300.81,"id":7444998}]}]}
{"op":"mcm","clk":"1004240158","pt":1580654072092,"mc":[{"id":"1.168224459","rc":[{"trd":[[1.94,116.55]],"batb":[[0,1.94,62.19]],"ltp":1.94,"tv":3020.01,"id":5858055}],"tv":6320.83}]}
{"op":"mcm","clk":"1004240500","pt":1580654073793,"mc":[{"id":"1.168224459","rc":[{"batb":[[1,1.53,104.61],[2,1.52,122.07]],"batl":[[0,2.06,131.93],[1,2.08,89.28],[2,2.12,3.79]],"ltp":1.84,"tv":3300.81,"id":7444998}]}]}
{"op":"mcm","clk":"1004241002","pt":1580654076220,"mc":[{"id":"1.168224459","rc":[{"batb":[[1,1.93,19.36],[2,1.87,21.27]],"ltp":1.94,"tv":3020.01,"id":5858055},{"batl":[[1,2.08,94.97]],"ltp":1.84,"tv":3300.81,"id":7444998}]}]}
{"op":"mcm","clk":"1004244611","pt":1580654093444,"mc":[{"id":"1.168224459","rc":[{"batl":[[0,2.08,5.69],[1,2.12,3.79],[2,2.16,5.22]],"ltp":1.84,"tv":3300.81,"id":7444998}]}]}
{"op":"mcm","clk":"1004244670","pt":1580654093822,"mc":[{"id":"1.168224459","rc":[{"batb":[[1,1.87,21.27],[2,1.85,21.57]],"ltp":1.94,"tv":3020.01,"id":5858055},{"batl":[[0,2.12,3.79],[1,2.16,5.22],[2,2.18,5.25]],"ltp":1.84,"tv":3300.81,"id":7444998}]}]}
{"op":"mcm","clk":"1004245242","pt":1580654096428,"mc":[{"id":"1.168224459","rc":[{"batb":[[0,2.66,103.35],[1,2.42,103.35],[2,1.94,62.19]],"batl":[[0,2.88,9.17],[1,3,136],[2,3.15,3.1]],"ltp":1.94,"tv":3020.01,"id":5858055},{"batl":[[0,1.56,10.6],[1,1.57,132.5],[2,1.58,404.37]],"ltp":1.84,"tv":3300.81,"id":7444998}]}]}
{"op":"mcm","clk":"1004245491","pt":1580654097434,"mc":[{"id":"1.168224459","rc":[{"batb":[[0,2.74,23.53],[1,2.66,154.41],[2,2.42,103.35]],"batl":[[2,3.05,20.16]],"ltp":1.94,"tv":3020.01,"id":5858055},{"batl":[[1,1.57,174.51]],"ltp":1.84,"tv":3300.81,"id":7444998}]}]}
{"op":"mcm","clk":"1004247157","pt":1580654105369,"mc":[{"id":"1.168224459","rc":[{"batb":[[1,2.68,50.2],[2,2.66,103.35]],"ltp":1.94,"tv":3020.01,"id":5858055},{"batb":[[0,1.53,246.95],[1,1.52,122.07],[2,1.48,249.87]],"ltp":1.84,"tv":3300.81,"id":7444998}]}]}
{"op":"mcm","clk":"1004247575","pt":1580654107347,"mc":[{"id":"1.168224459","rc":[{"trd":[[1.56,25.24]],"batb":[[0,1.56,87.38],[1,1.53,246.95],[2,1.52,122.07]],"batl":[[0,1.57,174.51],[1,1.58,404.37],[2,1.6,505.25]],"ltp":1.56,"tv":3326.05,"id":7444998}],"tv":6346.07}]}
{"op":"mcm","clk":"1004248226","pt":1580654110239,"mc":[{"id":"1.168224459","rc":[{"trd":[[1.56,200]],"batb":[[0,1.53,246.95],[1,1.52,122.07],[2,1.48,249.87]],"batl":[[0,1.56,9.87],[1,1.57,174.51],[2,1.58,404.37]],"ltp":1.56,"tv":3500.81,"id":7444998}],"tv":6520.83}]}
{"op":"mcm","clk":"1004248394","pt":1580654111069,"mc":[{"id":"1.168224459","rc":[{"trd":[[2.88,4.04]],"batl":[[0,2.88,7.15]],"ltp":2.88,"tv":3024.05,"id":5858055},{"batl":[[0,1.57,174.51],[1,1.58,404.37],[2,1.6,505.25]],"ltp":1.56,"tv":3500.81,"id":7444998}],"tv":6524.87}]}
{"op":"mcm","clk":"1004248625","pt":1580654112138,"mc":[{"id":"1.168224459","rc":[{"batb":[[0,1.56,2],[1,1.53,246.95],[2,1.52,122.07]],"ltp":1.56,"tv":3500.81,"id":7444998}]}]}
{"op":"mcm","clk":"1004249241","pt":1580654114980,"mc":[{"id":"1.168224459","rc":[{"batb":[[0,1.56,25.19]],"ltp":1.56,"tv":3500.81,"id":7444998}]}]}
{"op":"mcm","clk":"1004249721","pt":1580654117069,"mc":[{"id":"1.168224459","rc":[{"batl":[[0,3,136],[1,3.05,20.16],[2,3.15,3.1]],"ltp":2.88,"tv":3024.05,"id":5858055}]}]}
{"op":"mcm","clk":"1004249935","pt":1580654117934,"mc":[{"id":"1.168224459","rc":[{"trd":[[1.57,3.36]],"batb":[[0,1.56,23.19]],"batl":[[0,1.57,172.83]],"ltp":1.57,"tv":3504.17,"id":7444998}],"tv":6528.23}]}
{"op":"mcm","clk":"1004250127","pt":1580654118950,"mc":[{"id":"1.168224459","rc":[{"trd":[[1.56,218.48]],"batb":[[0,1.56,13.95]],"ltp":1.56,"tv":3522.66,"id":7444998}],"tv":6546.71}]}
{"op":"mcm","clk":"1004250322","pt":1580654119983,"mc":[{"id":"1.168224459","rc":[{"batl":[[0,2.84,6.73],[1,3,136],[2,3.05,20.16]],"ltp":2.88,"tv":3024.05,"id":5858055},{"batl":[[1,1.58,426.36]],"ltp":1.56,"tv":3522.66,"id":7444998}]}]}
{"op":"mcm","clk":"1004250589","pt":1580654121247,"mc":[{"id":"1.168224459","rc":[{"batl":[[0,3,136],[1,3.05,20.16],[2,3.15,3.1]],"ltp":2.88,"tv":3024.05,"id":5858055},{"trd":[[1.57,5.8]],"batl":[[0,1.57,171.61],[1,1.58,404.37]],"ltp":1.57,"tv":3525.1,"id":7444998}],"tv":6549.15}]}
{"op":"mcm","clk":"1004251202","pt":1580654124248,"mc":[{"id":"1.168224459","rc":[{"batl":[[0,2.84,6.73],[1,3,136],[2,3.05,20.16]],"ltp":2.88,"tv":3024.05,"id":5858055},{"batb":[[1,1.54,20],[2,1.53,246.95]],"batl":[[1,1.58,426.36]],"ltp":1.57,"tv":3525.1,"id":7444998}]}]}
{"op":"mcm","clk":"1004251702","pt":1580654126676,"mc":[{"id":"1.168224459","rc":[{"trd":[[1.57,9.76]],"batl":[[0,1.57,169.63]],"ltp":1.57,"tv":3529.06,"id":7444998}],"tv":6553.12}]}
{"op":"mcm","clk":"1004252599","pt":1580654131073,"mc":[{"id":"1.168224459","rc":[{"trd":[[1.57,70.57]],"batl":[[0,1.57,139.21]],"ltp":1.57,"tv":3589.87,"id":7444998}],"tv":6613.93}]}
{"op":"mcm","clk":"1004253372","pt":1580654134562,"mc":[{"id":"1.168224459","rc":[{"batb":[[2,1.53,266.37]],"batl":[[0,1.57,154.6]],"ltp":1.57,"tv":3589.87,"id":7444998}]}]}
{"op":"mcm","clk":"1004253911","pt":1580654137109,"mc":[{"id":"1.168224459","rc":[{"trd":[[1.56,229.09]],"batb":[[0,1.56,8.65]],"ltp":1.56,"tv":3600.47,"id":7444998}],"tv":6624.53}]}
{"op":"mcm","clk":"1004254292","pt":1580654138807,"mc":[{"id":"1.168224459","rc":[{"trd":[[1.56,234.02]],"batb":[[0,1.56,6.18]],"ltp":1.56,"tv":3605.41,"id":7444998}],"tv":6629.47}]}
{"op":"mcm","clk":"1004255411","pt":1580654144305,"mc":[{"id":"1.168224459","rc":[{"trd":[[1.57,70.87]],"batl":[[0,1.57,154.45]],"ltp":1.57,"tv":3605.71,"id":7444998}],"tv":6629.76}]}
{"op":"mcm","clk":"1004256099","pt":1580654147798,"mc":[{"id":"1.168224459","rc":[{"trd":[[1.57,84.33]],"batl":[[0,1.57,147.72]],"ltp":1.57,"tv":3619.16,"id":7444998}],"tv":6643.22}]}
{"op":"mcm","clk":"1004256594","pt":1580654150128,"mc":[{"id":"1.168224459","rc":[{"batb":[[1,1.55,14.02],[2,1.54,20]],"ltp":1.57,"tv":3619.16,"id":7444998}]}]}
{"op":"mcm","clk":"1004256977","pt":1580654152229,"mc":[{"id":"1.168224459","rc":[{"batb":[[2,1.53,266.37]],"ltp":1.57,"tv":3619.16,"id":7444998}]}]}
{"op":"mcm","clk":"1004257545","pt":1580654154915,"mc":[{"id":"1.168224459","rc":[{"trd":[[1.56,238.56]],"batb":[[0,1.56,3.91]],"ltp":1.56,"tv":3623.7,"id":7444998}],"tv":6647.76}]}
{"op":"mcm","clk":"1004257752","pt":1580654156009,"mc":[{"id":"1.168224459","rc":[{"batb":[[2,1.53,266.21]],"ltp":1.56,"tv":3623.7,"id":7444998}]}]}
{"op":"mcm","clk":"1004260259","pt":1580654167950,"mc":[{"id":"1.168224459","rc":[{"batb":[[0,1.55,14.02],[1,1.53,266.21],[2,1.52,122.07]],"ltp":1.56,"tv":3623.7,"id":7444998}]}]}
{"op":"mcm","clk":"1004260934","pt":1580654171008,"mc":[{"id":"1.168224459","rc":[{"trd":[[1.57,92.14]],"batl":[[0,1.57,143.81]],"ltp":1.57,"tv":3631.52,"id":7444998}],"tv":6655.58}]}
{"op":"mcm","clk":"1004263413","pt":1580654183041,"mc":[{"id":"1.168224459","rc":[{"batl":[[1,3.05,20.16],[2,3.15,3.1]],"ltp":2.88,"tv":3024.05,"id":5858055},{"batl":[[1,1.58,125.36]],"ltp":1.57,"tv":3631.52,"id":7444998}]}]}
{"op":"mcm","clk":"1004263836","pt":1580654185050,"mc":[{"id":"1.168224459","rc":[{"batb":[[0,1.56,5],[1,1.55,14.02],[2,1.53,266.21]],"ltp":1.57,"tv":3631.52,"id":7444998}]}]}
{"op":"mcm","clk":"1004264123","pt":1580654186447,"mc":[{"id":"1.168224459","rc":[{"batl":[[1,3,3.28],[2,3.05,20.16]],"ltp":2.88,"tv":3024.05,"id":5858055}]}]}
{"op":"mcm","clk":"1004264170","pt":1580654186701,"mc":[{"id":"1.168224459","rc":[{"batl":[[1,3.05,20.16],[2,3.15,3.1]],"ltp":2.88,"tv":3024.05,"id":5858055}]}]}
{"op":"mcm","clk":"1004264919","pt":1580654190442,"mc":[{"id":"1.168224459","rc":[{"trd":[[1.57,94.16]],"batb":[[0,1.55,14.02],[1,1.53,266.21],[2,1.52,122.07]],"batl":[[0,1.57,142.8]],"ltp":1.57,"tv":3633.54,"id":7444998}],"tv":6657.6}]}
{"op":"mcm","clk":"1004265454","pt":1580654193258,"mc":[{"id":"1.168224459","rc":[{"batl":[[1,3,2.69],[2,3.05,20.16]],"ltp":2.88,"tv":3024.05,"id":5858055}]}]}
{"op":"mcm","clk":"1004265513","pt":1580654193484,"mc":[{"id":"1.168224459","rc":[{"batl":[[1,3.05,20.16],[2,3.15,3.1]],"ltp":2.88,"tv":3024.05,"id":5858055}]}]}
{"op":"mcm","clk":"1004267278","pt":1580654202253,"mc":[{"id":"1.168224459","rc":[{"batl":[[0,3.05,20.16],[1,3.15,3.1],[2,3.8,2.02]],"ltp":2.88,"tv":3024.05,"id":5858055},{"batl":[[1,1.58,103.37],[2,1.68,24.39]],"ltp":1.57,"tv":3633.54,"id":7444998}]}]}
{"op":"mcm","clk":"1004267396","pt":1580654202783,"mc":[{"id":"1.168224459","rc":[{"batb":[[1,2.46,4.88],[2,2.42,65.94]],"batl":[[2,3.9,158.24]],"ltp":2.88,"tv":3024.05,"id":5858055},{"batb":[[1,1.48,249.87],[2,1.47,35.67]],"batl":[[0,1.57,42.01],[1,1.68,24.39],[2,1.72,22.91]],"ltp":1.57,"tv":3633.54,"id":7444998}]}]}
{"op":"mcm","clk":"1004267626","pt":1580654203824,"mc":[{"id":"1.168224459","rc":[{"batb":[[0,2.42,65.94],[1,2.38,4.96],[2,2.04,394.09]],"batl":[[0,3,2.9],[1,3.9,158.24],[2,1000,0.02]],"ltp":2.88,"tv":3024.05,"id":5858055},{"batb":[[1,1.5,40],[2,1.48,162.49]],"batl":[[0,1.72,22.91],[1,2.12,3.79],[2,1000,0.02]],"ltp":1.57,"tv":3633.54,"id":7444998}]}]}
{"op":"mcm","clk":"1004268025","pt":1580654205636,"mc":[{"id":"1.168224459","rc":[{"batb":[[2,1.48,314.94]],"batl":[[0,1.68,164.74],[1,1.7,160.64],[2,1.72,22.91]],"ltp":1.57,"tv":3633.54,"id":7444998}]}]}
{"op":"mcm","clk":"1004269072","pt":1580654210442,"mc":[{"id":"1.168224459","rc":[{"batb":[[0,2.46,4.88],[1,2.42,65.94],[2,2.38,4.96]],"ltp":2.88,"tv":3024.05,"id":5858055},{"batl":[[0,1.68,194.63]],"ltp":1.57,"tv":3633.54,"id":7444998}]}]}
{"op":"mcm","clk":"1004269278","pt":1580654211428,"mc":[{"id":"1.168224459","rc":[{"batb":[[0,2.42,65.94],[1,2.38,4.96],[2,2.04,394.09]],"ltp":2.88,"tv":3024.05,"id":5858055},{"batb":[[2,1.48,162.49]],"batl":[[0,1.68,164.74]],"ltp":1.57,"tv":3633.54,"id":7444998}]}]}
{"op":"mcm","clk":"1004269561","pt":1580654212692,"mc":[{"id":"1.168224459","rc":[{"batb":[[2,1.8,75.72]],"batl":[[1,1000,0.02],[2,1000,0]],"ltp":2.88,"tv":3024.05,"id":5858055}]}]}
{"op":"mcm","clk":"1004269916","pt":1580654214320,"mc":[{"id":"1.168224459","rc":[{"batl":[[0,2.56,8.75],[1,2.62,190.1],[2,2.68,131]],"ltp":2.88,"tv":3024.05,"id":5858055},{"batb":[[0,1.62,172.02],[1,1.61,97.54],[2,1.55,14.02]],"batl":[[0,1.68,740.89]],"ltp":1.57,"tv":3633.54,"id":7444998}]}]}
{"op":"mcm","clk":"1004270176","pt":1580654215408,"mc":[{"id":"1.168224459","rc":[{"batb":[[0,2.5,27.73],[1,2.42,65.94],[2,2.38,4.96]],"ltp":2.88,"tv":3024.05,"id":5858055},{"batb":[[0,1.63,112.75],[1,1.62,172.02],[2,1.61,97.54]],"batl":[[0,1.67,42.01],[1,1.68,740.89],[2,1.7,160.64]],"ltp":1.57,"tv":3633.54,"id":7444998}]}]}
{"op":"mcm","clk":"1004271374","pt":1580654221056,"mc":[{"id":"1.168224459","rc":[{"batl":[[2,1.7,641.23]],"ltp":1.57,"tv":3633.54,"id":7444998}]}]}
{"op":"mcm","clk":"1004272284","pt":1580654225342,"mc":[{"id":"1.168224459","rc":[{"batb":[[2,2.22,5.34]],"batl":[[0,2.62,190.1],[1,2.74,2.98],[2,2.8,22.69]],"ltp":2.88,"tv":3024.05,"id":5858055},{"batl":[[1,1.68,164.74]],"ltp":1.57,"tv":3633.54,"id":7444998}]}]}
{"op":"mcm","clk":"1004272420","pt":1580654225948,"mc":[{"id":"1.168224459","rc":[{"batb":[[0,2.22,5.34],[1,2.16,96.39],[2,1.86,398.62]],"batl":[[0,2.74,2.98],[1,2.82,3.25],[2,3,2.9]],"ltp":2.88,"tv":3024.05,"id":5858055},{"batb":[[0,1.6,494.03],[1,1.58,542.4],[2,1.56,133.84]],"batl":[[0,1.7,480.59],[1,1.72,497.4],[2,1.81,21.5]],"ltp":1.57,"tv":3633.54,"id":7444998}]}]}
{"op":"mcm","clk":"1004272842","pt":1580654228141,"mc":[{"id":"1.168224459","rc":[{"batl":[[0,1.7,481.26]],"ltp":1.57,"tv":3633.54,"id":7444998}]}]}
{"op":"mcm","clk":"1004272985","pt":1580654228862,"mc":[{"id":"1.168224459","rc":[{"batb":[[1,2.18,89.38],[2,2.16,5.28]],"ltp":2.88,"tv":3024.05,"id":5858055},{"batb":[[2,1.55,335.82]],"ltp":1.57,"tv":3633.54,"id":7444998}]}]}
{"op":"mcm","clk":"1004273667","pt":1580654232316,"mc":[{"id":"1.168224459","rc":[{"batb":[[2,1.55,182.93]],"ltp":1.57,"tv":3633.54,"id":7444998}]}]}
{"op":"mcm","clk":"1004273791","pt":1580654232919,"mc":[{"id":"1.168224459","rc":[{"batb":[[0,2.18,89.38],[1,2.16,5.28],[2,1.86,398.62]],"ltp":2.88,"tv":3024.05,"id":5858055},{"batl":[[0,1.83,114.33],[1,1.85,122.57],[2,1.86,21.25]],"ltp":1.57,"tv":3633.54,"id":7444998}]}]}
{"op":"mcm","clk":"1004274012","pt":1580654233901,"mc":[{"id":"1.168224459","rc":[{"batb":[[2,1.8,75.72]],"ltp":2.88,"tv":3024.05,"id":5858055}]}]}
{"op":"mcm","clk":"1004274313","pt":1580654235369,"mc":[{"id":"1.168224459","rc":[{"trd":[[2.56,0.43]],"batb":[[2,1.73,3.46]],"batl":[[0,2.28,218.61],[1,2.32,161.64],[2,2.36,140]],"ltp":2.56,"tv":3024.48,"id":5858055},{"trd":[[1.64,0.67]],"batb":[[0,1.77,104.35],[1,1.75,144.91],[2,1.72,274.59]],"batl":[[0,1.83,123.36],[1,1.84,236],[2,1.85,122.57]],"ltp":1.64,"tv":3634.21,"id":7444998}],"tv":6658.7}]}
{"op":"mcm","clk":"1004274541","pt":1580654236414,"mc":[{"id":"1.168224459","rc":[{"batb":[[2,1.96,122.43]],"ltp":2.56,"tv":3024.48,"id":5858055},{"batb":[[0,1.77,190.19]],"ltp":1.64,"tv":3634.21,"id":7444998}]}]}
{"op":"mcm","clk":"1004274625","pt":1580654236855,"mc":[{"id":"1.168224459","rc":[{"trd":[[2.28,32.8]],"batl":[[0,2.28,185.81]],"ltp":2.28,"tv":3057.28,"id":5858055},{"trd":[[1.78,42.01]],"ltp":1.78,"tv":3676.22,"id":7444998}],"tv":6733.51}]}
{"op":"mcm","clk":"1004275093","pt":1580654239263,"mc":[{"id":"1.168224459","rc":[{"trd":[[2.28,98.34]],"batl":[[0,2.28,153.04]],"ltp":2.28,"tv":3122.82,"id":5858055}],"tv":6799.05}]}
{"op":"mcm","clk":"1004275217","pt":1580654239862,"mc":[{"id":"1.168224459","rc":[{"batl":[[1,1.84,278.01]],"ltp":1.78,"tv":3676.22,"id":7444998}]}]}
{"op":"mcm","clk":"1004275616","pt":1580654241843,"mc":[{"id":"1.168224459","rc":[{"batb":[[0,2.2,34.45],[1,2.18,89.38],[2,2.16,5.28]],"ltp":2.28,"tv":3122.82,"id":5858055},{"batb":[[2,1.74,494.03]],"ltp":1.78,"tv":3676.22,"id":7444998}]}]}
{"op":"mcm","clk":"1004276410","pt":1580654245342,"mc":[{"id":"1.168224459","rc":[{"batl":[[0,2.44,28.57],[1,2.48,4.24],[2,2.58,3.75]],"ltp":2.28,"tv":3122.82,"id":5858055},{"batl":[[0,1.83,113.66],[1,1.84,42.01]],"ltp":1.78,"tv":3676.22,"id":7444998}]}]}
{"op":"mcm","clk":"1004276561","pt":1580654246040,"mc":[{"id":"1.168224459","rc":[{"batb":[[0,1.97,18.17],[1,1.96,122.43],[2,1.91,19.39]],"batl":[[0,2.48,4.24],[1,2.58,3.75],[2,2.74,2.98]],"ltp":2.28,"tv":3122.82,"id":5858055},{"batb":[[0,1.74,494.03],[1,1.72,510.84],[2,1.68,23.61]],"batl":[[0,1.78,2],[1,1.87,480.59],[2,1.89,497.4]],"ltp":1.78,"tv":3676.22,"id":7444998}]}]}
{"op":"mcm","clk":"1004277018","pt":1580654248333,"mc":[{"id":"1.168224459","rc":[{"batl":[[0,1.78,22.16]],"ltp":1.78,"tv":3676.22,"id":7444998}]}]}
{"op":"mcm","clk":"1004277175","pt":1580654249065,"mc":[{"id":"1.168224459","rc":[{"batl":[[0,1.78,20.16]],"ltp":1.78,"tv":3676.22,"id":7444998}]}]}
{"op":"mcm","clk":"1004277828","pt":1580654252186,"mc":[{"id":"1.168224459","rc":[{"batl":[[0,2.58,3.75],[1,2.74,2.98],[2,2.82,234.53]],"ltp":2.28,"tv":3122.82,"id":5858055},{"batb":[[0,1.67,230.65],[1,1.66,87.29],[2,1.64,31.07]],"ltp":1.78,"tv":3676.22,"id":7444998}]}]}
{"op":"mcm","clk":"1004278074","pt":1580654253152,"mc":[{"id":"1.168224459","rc":[{"batl":[[2,2.82,3.25]],"ltp":2.28,"tv":3122.82,"id":5858055}]}]}
{"op":"mcm","clk":"1004278311","pt":1580654254263,"mc":[{"id":"1.168224459","rc":[{"batb":[[0,2.36,275.63],[1,1.97,18.17],[2,1.96,122.43]],"batl":[[0,2.46,11.67],[1,2.56,134],[2,2.58,3.75]],"ltp":2.28,"tv":3122.82,"id":5858055},{"batl":[[0,1.71,3575.2],[1,1.73,220],[2,1.74,1187.23]],"ltp":1.78,"tv":3676.22,"id":7444998}]}]}
{"op":"mcm","clk":"1004278545","pt":1580654255380,"mc":[{"id":"1.168224459","rc":[{"batb":[[0,2.36,353.1],[1,2.06,103.55],[2,1.97,18.17]],"ltp":2.28,"tv":3122.82,"id":5858055},{"batl":[[0,1.72,88.91],[1,1.73,244.5],[2,1.74,267.89]],"ltp":1.78,"tv":3676.22,"id":7444998}]}]}
{"op":"mcm","clk":"1004278919","pt":1580654257193,"mc":[{"id":"1.168224459","rc":[{"batb":[[1,2.32,31.09],[2,2.06,103.55]],"ltp":2.28,"tv":3122.82,"id":5858055}]}]}
{"op":"mcm","clk":"1004279701","pt":1580654261263,"mc":[{"id":"1.168224459","rc":[{"batb":[[2,1.64,525.1]],"ltp":1.78,"tv":3676.22,"id":7444998}]}]}
{"op":"mcm","clk":"1004279878","pt":1580654261708,"mc":[{"id":"1.168224459","rc":[{"batb":[[2,2.06,109.13]],"ltp":2.28,"tv":3122.82,"id":5858055}]}]}
{"op":"mcm","clk":"1004280271","pt":1580654263455,"mc":[{"id":"1.168224459","rc":[{"trd":[[1.72,1.34]],"batl":[[0,1.72,88.24]],"ltp":1.72,"tv":3677.57,"id":7444998}],"tv":6800.39}]}
{"op":"mcm","clk":"1004280608","pt":1580654265085,"mc":[{"id":"1.168224459","rc":[{"trd":[[1.72,51.32]],"batl":[[0,1.72,63.25]],"ltp":1.72,"tv":3727.54,"id":7444998}],"tv":6850.37}]}
{"op":"mcm","clk":"1004280817","pt":1580654266178,"mc":[{"id":"1.168224459","rc":[{"batb":[[0,2.36,6.18],[2,2.06,103.55]],"batl":[[0,2.6,26.05],[1,2.68,3.39],[2,2.74,2.98]],"ltp":2.28,"tv":3122.82,"id":5858055},{"batb":[[0,1.64,494.03],[1,1.62,510.84],[2,1.61,68.06]],"batl":[[0,1.73,24.5],[1,1.75,522.6],[2,1.77,497.4]],"ltp":1.72,"tv":3727.54,"id":7444998}]}]}
{"op":"mcm","clk":"1004281265","pt":1580654268372,"mc":[{"id":"1.168224459","rc":[{"batb":[[0,2.06,103.55],[1,2,19.11],[2,1.97,18.17]],"batl":[[0,2.68,3.39],[1,2.74,2.98],[2,2.8,3.47]],"ltp":2.28,"tv":3122.82,"id":5858055},{"batb":[[0,1.67,14.6],[1,1.64,494.03],[2,1.62,510.84]],"batl":[[0,1.73,149.93],[1,1.75,626.58]],"ltp":1.72,"tv":3727.54,"id":7444998}]}]}
{"op":"mcm","clk":"1004281471","pt":1580654269400,"mc":[{"id":"1.168224459","rc":[{"batb":[[0,2.46,5],[1,2.06,103.55],[2,2,19.11]],"ltp":2.28,"tv":3122.82,"id":5858055},{"batb":[[0,1.64,494.03],[1,1.62,510.84],[2,1.6,32.39]],"batl":[[0,1.75,480.59],[1,1.77,497.4],[2,1.78,20.16]],"ltp":1.72,"tv":3727.54,"id":7444998}]}]}
{"op":"mcm","clk":"1004282015","pt":1580654272087,"mc":[{"id":"1.168224459","rc":[{"batb":[[0,2.06,103.55],[1,2,19.11],[2,1.97,18.17]],"ltp":2.28,"tv":3122.82,"id":5858055}]}]}
{"op":"mcm","clk":"1004282165","pt":1580654272804,"mc":[{"id":"1.168224459","rc":[{"batb":[[0,1.71,99.86],[1,1.69,162.91],[2,1.64,494.03]],"batl":[[1,1.76,87.46],[2,1.77,497.4]],"ltp":1.72,"tv":3727.54,"id":7444998}]}]}
{"op":"mcm","clk":"1004282625","pt":1580654275107,"mc":[{"id":"1.168224459","rc":[{"batb":[[0,1.64,494.03],[1,1.62,510.84],[2,1.6,32.39]],"batl":[[1,1.77,497.4],[2,1.78,20.16]],"ltp":1.72,"tv":3727.54,"id":7444998}]}]}
{"op":"mcm","clk":"1004283547","pt":1580654279405,"mc":[{"id":"1.168224459","rc":[{"batb":[[0,2.06,109.13]],"ltp":2.28,"tv":3122.82,"id":5858055}]}]}
{"op":"mcm","clk":"1004283609","pt":1580654279694,"mc":[{"id":"1.168224459","rc":[{"batb":[[0,2.06,103.55]],"ltp":2.28,"tv":3122.82,"id":5858055}]}]}
{"op":"mcm","clk":"1004284298","pt":1580654283137,"mc":[{"id":"1.168224459","rc":[{"batl":[[0,2.8,3.47],[1,2.82,3.25],[2,3,2.9]],"ltp":2.28,"tv":3122.82,"id":5858055},{"batb":[[0,1.57,321.81],[1,1.56,141.98],[2,1.55,47.21]],"ltp":1.72,"tv":3727.54,"id":7444998}]}]}
{"op":"mcm","clk":"1004284805","pt":1580654285435,"mc":[{"id":"1.168224459","rc":[{"batb":[[0,2.6,188.98],[1,2.06,103.55],[2,2,19.11]],"batl":[[1,2.82,129.25],[2,2.84,152.56]],"ltp":2.28,"tv":3122.82,"id":5858055},{"batl":[[0,1.63,4071.2],[1,1.64,1304.84],[2,1.65,1205.39]],"ltp":1.72,"tv":3727.54,"id":7444998}]}]}
{"op":"mcm","clk":"1004285022","pt":1580654286448,"mc":[{"id":"1.168224459","rc":[{"batb":[[0,2.6,194.52],[1,2.58,56.02],[2,2.24,82.69]],"batl":[[0,2.72,14.05],[1,2.8,3.47],[2,2.82,129.25]],"ltp":2.28,"tv":3122.82,"id":5858055},{"batl":[[0,1.62,143.99],[1,1.63,351.4],[2,1.64,130.48]],"ltp":1.72,"tv":3727.54,"id":7444998}]}]}
{"op":"mcm","clk":"1004285180","pt":1580654287141,"mc":[{"id":"1.168224459","rc":[{"batb":[[2,2.48,27.73]],"batl":[[1,2.8,26.16]],"ltp":2.28,"tv":3122.82,"id":5858055},{"batb":[[2,1.55,122.82]],"ltp":1.72,"tv":3727.54,"id":7444998}]}]}
{"op":"mcm","clk":"1004286228","pt":1580654292107,"mc":[{"id":"1.168224459","rc":[{"trd":[[2.72,10]],"batl":[[0,2.72,9.05]],"ltp":2.72,"tv":3132.82,"id":5858055}],"tv":6860.37}]}
{"op":"mcm","clk":"1004286644","pt":1580654294152,"mc":[{"id":"1.168224459","rc":[{"batb":[[2,1.55,108.81]],"ltp":1.72,"tv":3727.54,"id":7444998}]}]}
{"op":"mcm","clk":"1004287668","pt":1580654299430,"mc":[{"id":"1.168224459","rc":[{"batb":[[0,2.58,56.02],[1,2.48,27.73],[2,2.24,82.69]],"batl":[[0,2.8,22.69],[1,2.94,2.75],[2,3,2.9]],"ltp":2.72,"tv":3132.82,"id":5858055},{"batb":[[0,1.57,129.9],[1,1.55,75.62],[2,1.52,29.74]],"batl":[[0,1.64,130.48],[1,1.65,120.54],[2,1.66,42.01]],"ltp":1.72,"tv":3727.54,"id":7444998}]}]}
{"op":"mcm","clk":"1004287850","pt":1580654300251,"mc":[{"id":"1.168224459","rc":[{"batb":[[0,2.24,82.69],[1,2,19.11],[2,1.97,18.17]],"batl":[[0,3.05,2.9],[1,3.15,200.42],[2,1000,0.02]],"ltp":2.72,"tv":3132.82,"id":5858055},{"batb":[[0,1.5,14.02],[1,1.49,33.01],[2,1.48,161.7]],"batl":[[0,1.78,20.16],[1,1.88,19.29],[2,2,16.49]],"ltp":1.72,"tv":3727.54,"id":7444998}]}]}
{"op":"mcm","clk":"1004288454","pt":1580654303445,"mc":[{"id":"1.168224459","rc":[{"batb":[[1,2.22,5.34],[2,2.12,6.04]],"batl":[[0,2.94,3.58],[1,3.05,2.9],[2,3.15,200.42]],"ltp":2.72,"tv":3132.82,"id":5858055},{"batb":[[0,1.52,31.74],[1,1.5,14.02],[2,1.49,207]],"batl":[[1,1.8,100.96],[2,1.81,22.5]],"ltp":1.72,"tv":3727.54,"id":7444998}]}]}
{"op":"mcm","clk":"1004288643","pt":1580654304344,"mc":[{"id":"1.168224459","rc":[{"batb":[[1,2.12,6.04],[2,2,19.11]],"batl":[[0,3.05,2.9],[1,3.15,200.42],[2,1000,0.02]],"ltp":2.72,"tv":3132.82,"id":5858055},{"batb":[[0,1.5,14.02],[1,1.49,207],[2,1.48,296.37]],"batl":[[1,1.88,19.29],[2,2,16.49]],"ltp":1.72,"tv":3727.54,"id":7444998}]}]}
{"op":"mcm","clk":"1004288891","pt":1580654305630,"mc":[{"id":"1.168224459","rc":[{"batl":[[1,1000,0.02],[2,1000,0]],"ltp":2.72,"tv":3132.82,"id":5858055}]}]}
{"op":"mcm","clk":"1004289190","pt":1580654307157,"mc":[{"id":"1.168224459","rc":[{"batb":[[0,2.88,9.83],[1,2.84,94.18],[2,2.24,82.69]],"batl":[[0,3,3.87],[1,3.05,2.9],[2,3.15,303.02]],"ltp":2.72,"tv":3132.82,"id":5858055},{"batb":[[0,1.5,7.75]],"batl":[[0,1.53,105.17],[1,1.54,397.32],[2,1.55,134.72]],"ltp":1.72,"tv":3727.54,"id":7444998}]}]}
{"op":"mcm","clk":"1004289315","pt":1580654307862,"mc":[{"id":"1.168224459","rc":[{"batb":[[1,2.84,137.14],[2,2.54,57.6]],"ltp":2.72,"tv":3132.82,"id":5858055}]}]}
{"op":"mcm","clk":"1004289479","pt":1580654308712,"mc":[{"id":"1.168224459","rc":[{"batb":[[2,2.68,24.37]],"batl":[[1,3.05,23.06]],"ltp":2.72,"tv":3132.82,"id":5858055},{"batb":[[2,1.48,383.75]],"ltp":1.72,"tv":3727.54,"id":7444998}]}]}
{"op":"mcm","clk":"1004289847","pt":1580654310400,"mc":[{"id":"1.168224459","rc":[{"trd":[[1.53,28.04]],"batl":[[0,1.53,91.15]],"ltp":1.53,"tv":3755.58,"id":7444998}],"tv":6888.4}]}
{"op":"mcm","clk":"1004290428","pt":1580654313346,"mc":[{"id":"1.168224459","rc":[{"batl":[[2,1.55,615.31]],"ltp":1.53,"tv":3755.58,"id":7444998}]}]}
{"op":"mcm","clk":"1004290491","pt":1580654313650,"mc":[{"id":"1.168224459","rc":[{"batl":[[2,3.15,305.72]],"ltp":2.72,"tv":3132.82,"id":5858055}]}]}
{"op":"mcm","clk":"1004290810","pt":1580654315280,"mc":[{"id":"1.168224459","rc":[{"batb":[[0,2.84,137.14],[1,2.68,24.37],[2,2.62,4.54]],"batl":[[0,3.05,23.06],[1,3.15,2.7],[2,3.25,2.66]],"ltp":2.72,"tv":3132.82,"id":5858055},{"batb":[[0,1.49,207],[1,1.48,383.75],[2,1.47,533.87]],"batl":[[1,1.54,141.32]],"ltp":1.53,"tv":3755.58,"id":7444998}]}]}
{"op":"mcm","clk":"1004290948","pt":1580654316073,"mc":[{"id":"1.168224459","rc":[{"batb":[[0,2.84,5.22],[1,2.62,4.54],[2,2.56,4.58]],"batl":[[0,3.15,2.7],[1,3.25,2.66],[2,3.9,158.24]],"ltp":2.72,"tv":3132.82,"id":5858055},{"batb":[[0,1.47,533.88],[1,1.45,552.65],[2,1.43,188.52]],"batl":[[0,1.54,27.75],[1,1.55,480.59],[2,1.57,497.4]],"ltp":1.53,"tv":3755.58,"id":7444998}]}]}
{"op":"mcm","clk":"1004291074","pt":1580654316732,"mc":[{"id":"1.168224459","rc":[{"batb":[[0,1.53,1.68],[1,1.47,533.88],[2,1.45,552.65]],"ltp":1.53,"tv":3755.58,"id":7444998}]}]}
{"op":"mcm","clk":"1004291760","pt":1580654320365,"mc":[{"id":"1.168224459","rc":[{"batb":[[0,2.62,4.54],[1,2.56,4.58],[2,2.54,57.6]],"batl":[[0,3.25,2.66],[1,3.9,158.24],[2,1000,0.02]],"ltp":2.72,"tv":3132.82,"id":5858055},{"batb":[[0,1.45,41.82],[1,1.44,199.69],[2,1.43,344.36]],"batl":[[0,1.55,480.59],[1,1.57,497.4],[2,1.61,24.5]],"ltp":1.53,"tv":3755.58,"id":7444998}]}]}
{"op":"mcm","clk":"1004292306","pt":1580654323078,"mc":[{"id":"1.168224459","rc":[{"batb":[[0,3.1,7.27],[1,3.05,71.46],[2,3,5]],"batl":[[0,3.2,5.07],[1,3.25,2.66],[2,3.4,160]],"ltp":2.72,"tv":3132.82,"id":5858055},{"trd":[[1.48,0.02]],"batb":[[0,1.45,41.81]],"batl":[[0,1.48,441.48],[1,1.49,431.6],[2,1.5,27.13]],"ltp":1.48,"tv":3755.6,"id":7444998}],"tv":6888.42}]}
{"op":"mcm","clk":"1004292419","pt":1580654323680,"mc":[{"id":"1.168224459","rc":[{"batb":[[1,3.05,161.08]],"ltp":2.72,"tv":3132.82,"id":5858055}]}]}
{"op":"mcm","clk":"1004292573","pt":1580654324548,"mc":[{"id":"1.168224459","rc":[{"batl":[[2,3.3,17.64]],"ltp":2.72,"tv":3132.82,"id":5858055},{"batb":[[2,1.43,441.82]],"ltp":1.48,"tv":3755.6,"id":7444998}]}]}
{"op":"mcm","clk":"1004293530","pt":1580654329563,"mc":[{"id":"1.168224459","rc":[{"batb":[[2,1.43,478.25]],"ltp":1.48,"tv":3755.6,"id":7444998}]}]}
{"op":"mcm","clk":"1004293794","pt":1580654330867,"mc":[{"id":"1.168224459","rc":[{"trd":[[1.48,3.38]],"batl":[[0,1.48,439.8]],"ltp":1.48,"tv":3758.96,"id":7444998}],"tv":6891.79}]}
{"op":"mcm","clk":"1004294362","pt":1580654333781,"mc":[{"id":"1.168224459","rc":[{"trd":[[3.1,5.4]],"batb":[[0,3.1,4.57]],"ltp":3.1,"tv":3138.22,"id":5858055}],"tv":6897.19}]}
{"op":"mcm","clk":"1004294529","pt":1580654334783,"mc":[{"id":"1.168224459","rc":[{"trd":[[1.45,47.4]],"batb":[[0,1.45,18.11]],"ltp":1.45,"tv":3806.36,"id":7444998}],"tv":6944.59}]}
{"op":"mcm","clk":"1004295754","pt":1580654340706,"mc":[{"id":"1.168224459","rc":[{"trd":[[3.2,1.74]],"batl":[[0,3.2,3.33]],"ltp":3.2,"tv":3139.96,"id":5858055},{"trd":[[1.45,87.47]],"batb":[[0,1.44,199.69],[1,1.43,478.25],[2,1.42,345.4]],"ltp":1.45,"tv":3846.43,"id":7444998}],"tv":6986.4}]}
{"op":"mcm","clk":"1004296001","pt":1580654341915,"mc":[{"id":"1.168224459","rc":[{"batb":[[0,1.46,30.29],[1,1.44,199.69],[2,1.43,478.25]],"ltp":1.45,"tv":3846.43,"id":7444998}]}]}
{"op":"mcm","clk":"1004296163","pt":1580654342685,"mc":[{"id":"1.168224459","rc":[{"trd":[[1.46,4]],"batb":[[0,1.46,28.29]],"ltp":1.46,"tv":3850.43,"id":7444998}],"tv":6990.4}]}
{"op":"mcm","clk":"1004296427","pt":1580654343996,"mc":[{"id":"1.168224459","rc":[{"batb":[[0,3.05,161.08],[1,3,5],[2,2.96,84.43]],"batl":[[0,3.25,2.66],[1,3.3,17.64],[2,3.35,2.9]],"ltp":3.2,"tv":3139.96,"id":5858055}]}]}
{"op":"mcm","clk":"1004297008","pt":1580654346893,"mc":[{"id":"1.168224459","rc":[{"batb":[[0,3.1,6.37],[1,3.05,161.08],[2,3,5]],"batl":[[0,3.2,5.95],[1,3.25,2.66],[2,3.3,17.64]],"ltp":3.2,"tv":3139.96,"id":5858055}]}]}
{"op":"mcm","clk":"1004297244","pt":1580654348112,"mc":[{"id":"1.168224459","rc":[{"batl":[[2,3.3,20.19]],"ltp":3.2,"tv":3139.96,"id":5858055},{"batb":[[1,1.44,240.36]],"ltp":1.46,"tv":3850.43,"id":7444998}]}]}
{"op":"mcm","clk":"1004297843","pt":1580654351332,"mc":[{"id":"1.168224459","rc":[{"batb":[[0,3.05,161.08],[1,2.96,84.43],[2,2.92,100.4]],"batl":[[0,3.3,17.64],[1,3.35,2.9],[2,3.45,2.1]],"ltp":3.2,"tv":3139.96,"id":5858055},{"batl":[[0,1.48,143.41],[1,1.49,128.6],[2,1.51,43]],"ltp":1.46,"tv":3850.43,"id":7444998}]}]}
{"op":"mcm","clk":"1004297959","pt":1580654351899,"mc":[{"id":"1.168224459","rc":[{"batb":[[0,2.92,100.4],[1,2.88,14.42],[2,2.04,394.09]],"batl":[[0,3.45,2.1],[1,3.9,158.24],[2,1000,0.02]],"ltp":3.2,"tv":3139.96,"id":5858055},{"batb":[[1,1.41,43.89],[2,1.38,217.79]],"batl":[[0,1.53,34.34],[1,2.12,3.79],[2,1000,0.02]],"ltp":1.46,"tv":3850.43,"id":7444998}]}]}
{"op":"mcm","clk":"1004298666","pt":1580654355229,"mc":[{"id":"1.168224459","rc":[{"batb":[[0,2.96,9.88],[1,2.92,100.4],[2,2.88,14.42]],"ltp":3.2,"tv":3139.96,"id":5858055},{"trd":[[1.46,4.67]],"batb":[[0,1.46,27.96],[2,1.4,197.68]],"batl":[[0,1.51,170.13],[1,1.52,118.89],[2,1.53,34.34]],"ltp":1.46,"tv":3851.1,"id":7444998}],"tv":6991.07}]}
{"op":"mcm","clk":"1004298771","pt":1580654355599,"mc":[{"id":"1.168224459","rc":[{"batb":[[0,2.92,100.4],[1,2.88,14.42],[2,2.04,394.09]],"ltp":3.2,"tv":3139.96,"id":5858055},{"batl":[[0,1.51,163.59]],"ltp":1.46,"tv":3851.1,"id":7444998}]}]}
{"op":"mcm","clk":"1004299489","pt":1580654359037,"mc":[{"id":"1.168224459","rc":[{"batb":[[0,1.41,43.89],[1,1.4,197.68],[2,1.39,176.44]],"ltp":1.46,"tv":3851.1,"id":7444998}]}]}
{"op":"mcm","clk":"1004300447","pt":1580654363647,"mc":[{"id":"1.168224459","rc":[{"batb":[[1,1.38,217.79],[2,1.2,284.06]],"ltp":1.46,"tv":3851.1,"id":7444998}]}]}
{"op":"mcm","clk":"1004300820","pt":1580654365442,"mc":[{"id":"1.168224459","rc":[{"batb":[[0,2.96,8.13],[1,2.92,100.4],[2,2.88,14.42]],"ltp":3.2,"tv":3139.96,"id":5858055},{"trd":[[1.41,3.36]],"batb":[[0,1.41,42.21]],"batl":[[0,1.51,212.09]],"ltp":1.41,"tv":3854.46,"id":7444998}],"tv":6994.43}]}
{"op":"mcm","clk":"1004301011","pt":1580654366319,"mc":[{"id":"1.168224459","rc":[{"batb":[[0,2.96,184.7]],"batl":[[0,3.1,2063.4],[1,3.25,723.67],[2,3.3,4.6]],"ltp":3.2,"tv":3139.96,"id":5858055},{"batb":[[0,1.48,14.75],[1,1.45,1545.99],[2,1.41,42.21]],"batl":[[0,1.51,163.59],[1,1.52,426.89]],"ltp":1.41,"tv":3854.46,"id":7444998}]}]}
{"op":"mcm","clk":"1004301070","pt":1580654366655,"mc":[{"id":"1.168224459","rc":[{"batl":[[0,3.25,206.47],[1,3.45,2.1],[2,3.9,158.24]],"ltp":3.2,"tv":3139.96,"id":5858055},{"batb":[[1,1.47,136.72],[2,1.46,142.05]],"ltp":1.41,"tv":3854.46,"id":7444998}]}]}
{"op":"mcm","clk":"1004301307","pt":1580654367838,"mc":[{"id":"1.168224459","rc":[{"batb":[[2,1.46,314.52]],"ltp":1.41,"tv":3854.46,"id":7444998}]}]}
{"op":"mcm","clk":"1004301621","pt":1580654369430,"mc":[{"id":"1.168224459","rc":[{"batl":[[0,3.2,18.48],[1,3.25,206.47],[2,3.45,2.1]],"ltp":3.2,"tv":3139.96,"id":5858055}]}]}
