{"op":"mcm","clk":"998154875","pt":1580585274635,"mc":[{"id":"1.168224472","marketDefinition":{"bspMarket":false,"turnInPlayEnabled":true,"persistenceEnabled":true,"marketBaseRate":5.0,"eventId":"29681747","eventTypeId":"2","numberOfWinners":1,"bettingType":"ODDS","marketType":"SET_WINNER","marketTime":"2020-02-02T09:00:00.000Z","suspendTime":"2020-02-02T09:00:00.000Z","bspReconciled":false,"complete":true,"inPlay":false,"crossMatching":false,"runnersVoidable":false,"numberOfActiveRunners":2,"betDelay":0,"status":"OPEN","runners":[{"status":"ACTIVE","sortPriority":1,"id":5858055,"name":"Hiroki Moriya"},{"status":"ACTIVE","sortPriority":2,"id":7444998,"name":"Danilo Petrovic"}],"regulators":["MR_INT"],"countryCode":"FR","discountAllowed":false,"timezone":"UTC","openDate":"2020-02-02T09:00:00.000Z","version":3147098680,"name":"Set 1 Winner","eventName":"Moriya v Petrovic"},"rc":[{"batb":[[0,1.01,20]],"ltp":0.0,"tv":0.0,"id":5858055},{"batb":[[0,1.01,20]],"ltp":0.0,"tv":0.0,"id":7444998}]}]}
{"op":"mcm","clk":"998155189","pt":1580585276473,"mc":[{"id":"1.168224472","marketDefinition":{"bspMarket":false,"turnInPlayEnabled":true,"persistenceEnabled":true,"marketBaseRate":5.0,"eventId":"29681747","eventTypeId":"2","numberOfWinners":1,"bettingType":"ODDS","marketType":"SET_WINNER","marketTime":"2020-02-02T09:00:00.000Z","suspendTime":"2020-02-02T09:00:00.000Z","bspReconciled":false,"complete":true,"inPlay":false,"crossMatching":false,"runnersVoidable":false,"numberOfActiveRunners":2,"betDelay":0,"status":"OPEN","runners":[{"status":"ACTIVE","sortPriority":1,"id":5858055,"name":"Hiroki Moriya"},{"status":"ACTIVE","sortPriority":2,"id":7444998,"name":"Danilo Petrovic"}],"regulators":["MR_INT"],"countryCode":"FR","discountAllowed":true,"timezone":"UTC","openDate":"2020-02-02T09:00:00.000Z","version":3147098680,"name":"Set 1 Winner","eventName":"Moriya v Petrovic"}}]}
{"op":"mcm","clk":"998178965","pt":1580585419340,"mc":[{"id":"1.168224472","rc":[{"batb":[[0,1.01,15]],"ltp":0.0,"tv":0.0,"id":5858055},{"batb":[[0,1.01,15]],"ltp":0.0,"tv":0.0,"id":7444998}]}]}
{"op":"mcm","clk":"998196782","pt":1580585516475,"mc":[{"id":"1.168224472","marketDefinition":{"bspMarket":false,"turnInPlayEnabled":true,"persistenceEnabled":true,"marketBaseRate":5.0,"eventId":"29681747","eventTypeId":"2","numberOfWinners":1,"bettingType":"ODDS","marketType":"SET_WINNER","marketTime":"2020-02-02T15:30:00.000Z","suspendTime":"2020-02-02T15:30:00.000Z","bspReconciled":false,"complete":true,"inPlay":false,"crossMatching":false,"runnersVoidable":false,"numberOfActiveRunners":2,"betDelay":0,"status":"OPEN","runners":[{"status":"ACTIVE","sortPriority":1,"id":5858055,"name":"Hiroki Moriya"},{"status":"ACTIVE","sortPriority":2,"id":7444998,"name":"Danilo Petrovic"}],"regulators":["MR_INT"],"countryCode":"FR","discountAllowed":true,"timezone":"UTC","openDate":"2020-02-02T09:00:00.000Z","version":3147125085,"name":"Set 1 Winner","eventName":"Moriya v Petrovic"}}]}
{"op":"mcm","clk":"998197430","pt":1580585519449,"mc":[{"id":"1.168224472","marketDefinition":{"bspMarket":false,"turnInPlayEnabled":true,"persistenceEnabled":true,"marketBaseRate":5.0,"eventId":"29681747","eventTypeId":"2","numberOfWinners":1,"bettingType":"ODDS","marketType":"SET_WINNER","marketTime":"2020-02-02T15:30:00.000Z","suspendTime":"2020-02-02T15:30:00.000Z","bspReconciled":false,"complete":true,"inPlay":false,"crossMatching":false,"runnersVoidable":false,"numberOfActiveRunners":2,"betDelay":0,"status":"OPEN","runners":[{"status":"ACTIVE","sortPriority":1,"id":5858055,"name":"Hiroki Moriya"},{"status":"ACTIVE","sortPriority":2,"id":7444998,"name":"Danilo Petrovic"}],"regulators":["MR_INT"],"countryCode":"FR","discountAllowed":true,"timezone":"UTC","openDate":"2020-02-02T15:30:00.000Z","version":3147125085,"name":"Set 1 Winner","eventName":"Moriya v Petrovic"}}]}
{"op":"mcm","clk":"999887684","pt":1580602193223,"mc":[{"id":"1.168224472","rc":[{"batb":[[0,1.01,15.51]],"ltp":0.0,"tv":0.0,"id":5858055},{"batb":[[0,1.01,15.51]],"ltp":0.0,"tv":0.0,"id":7444998}]}]}
{"op":"mcm","clk":"999983644","pt":1580603733234,"mc":[{"id":"1.168224472","rc":[{"batb":[[0,1.01,16.01]],"ltp":0.0,"tv":0.0,"id":5858055},{"batb":[[0,1.01,16.01]],"ltp":0.0,"tv":0.0,"id":7444998}]}]}
{"op":"mcm","clk":"1001426382","pt":1580635616377,"mc":[{"id":"1.168224472","marketDefinition":{"bspMarket":false,"turnInPlayEnabled":true,"persistenceEnabled":true,"marketBaseRate":5.0,"eventId":"29681747","eventTypeId":"2","numberOfWinners":1,"bettingType":"ODDS","marketType":"SET_WINNER","marketTime":"2020-02-02T15:24:00.000Z","suspendTime":"2020-02-02T15:24:00.000Z","bspReconciled":false,"complete":true,"inPlay":false,"crossMatching":false,"runnersVoidable":false,"numberOfActiveRunners":2,"betDelay":0,"status":"OPEN","runners":[{"status":"ACTIVE","sortPriority":1,"id":5858055,"name":"Hiroki Moriya"},{"status":"ACTIVE","sortPriority":2,"id":7444998,"name":"Danilo Petrovic"}],"regulators":["MR_INT"],"countryCode":"FR","discountAllowed":true,"timezone":"UTC","openDate":"2020-02-02T15:30:00.000Z","version":3148345727,"name":"Set 1 Winner","eventName":"Moriya v Petrovic"}}]}
{"op":"mcm","clk":"1001426714","pt":1580635619343,"mc":[{"id":"1.168224472","marketDefinition":{"bspMarket":false,"turnInPlayEnabled":true,"persistenceEnabled":true,"marketBaseRate":5.0,"eventId":"29681747","eventTypeId":"2","numberOfWinners":1,"bettingType":"ODDS","marketType":"SET_WINNER","marketTime":"2020-02-02T15:24:00.000Z","suspendTime":"2020-02-02T15:24:00.000Z","bspReconciled":false,"complete":true,"inPlay":false,"crossMatching":false,"runnersVoidable":false,"numberOfActiveRunners":2,"betDelay":0,"status":"OPEN","runners":[{"status":"ACTIVE","sortPriority":1,"id":5858055,"name":"Hiroki Moriya"},{"status":"ACTIVE","sortPriority":2,"id":7444998,"name":"Danilo Petrovic"}],"regulators":["MR_INT"],"countryCode":"FR","discountAllowed":true,"timezone":"UTC","openDate":"2020-02-02T15:24:00.000Z","version":3148345727,"name":"Set 1 Winner","eventName":"Moriya v Petrovic"}}]}
{"op":"mcm","clk":"1001816331","pt":1580640414463,"mc":[{"id":"1.168224472","marketDefinition":{"bspMarket":false,"turnInPlayEnabled":true,"persistenceEnabled":true,"marketBaseRate":5.0,"eventId":"29681747","eventTypeId":"2","numberOfWinners":1,"bettingType":"ODDS","marketType":"SET_WINNER","marketTime":"2020-02-02T14:51:00.000Z","suspendTime":"2020-02-02T14:51:00.000Z","bspReconciled":false,"complete":true,"inPlay":false,"crossMatching":false,"runnersVoidable":false,"numberOfActiveRunners":2,"betDelay":0,"status":"OPEN","runners":[{"status":"ACTIVE","sortPriority":1,"id":5858055,"name":"Hiroki Moriya"},{"status":"ACTIVE","sortPriority":2,"id":7444998,"name":"Danilo Petrovic"}],"regulators":["MR_INT"],"countryCode":"FR","discountAllowed":true,"timezone":"UTC","openDate":"2020-02-02T15:24:00.000Z","version":3148438371,"name":"Set 1 Winner","eventName":"Moriya v Petrovic"}}]}
{"op":"mcm","clk":"1001817051","pt":1580640420518,"mc":[{"id":"1.168224472","marketDefinition":{"bspMarket":false,"turnInPlayEnabled":true,"persistenceEnabled":true,"marketBaseRate":5.0,"eventId":"29681747","eventTypeId":"2","numberOfWinners":1,"bettingType":"ODDS","marketType":"SET_WINNER","marketTime":"2020-02-02T14:51:00.000Z","suspendTime":"2020-02-02T14:51:00.000Z","bspReconciled":false,"complete":true,"inPlay":false,"crossMatching":false,"runnersVoidable":false,"numberOfActiveRunners":2,"betDelay":0,"status":"OPEN","runners":[{"status":"ACTIVE","sortPriority":1,"id":5858055,"name":"Hiroki Moriya"},{"status":"ACTIVE","sortPriority":2,"id":7444998,"name":"Danilo Petrovic"}],"regulators":["MR_INT"],"countryCode":"FR","discountAllowed":true,"timezone":"UTC","openDate":"2020-02-02T14:51:00.000Z","version":3148438371,"name":"Set 1 Winner","eventName":"Moriya v Petrovic"}}]}
{"op":"mcm","clk":"1001853042","pt":1580640715174,"mc":[{"id":"1.168224472","marketDefinition":{"bspMarket":false,"turnInPlayEnabled":true,"persistenceEnabled":true,"marketBaseRate":5.0,"eventId":"29681747","eventTypeId":"2","numberOfWinners":1,"bettingType":"ODDS","marketType":"SET_WINNER","marketTime":"2020-02-02T14:48:00.000Z","suspendTime":"2020-02-02T14:48:00.000Z","bspReconciled":false,"complete":true,"inPlay":false,"crossMatching":false,"runnersVoidable":false,"numberOfActiveRunners":2,"betDelay":0,"status":"OPEN","runners":[{"status":"ACTIVE","sortPriority":1,"id":5858055,"name":"Hiroki Moriya"},{"status":"ACTIVE","sortPriority":2,"id":7444998,"name":"Danilo Petrovic"}],"regulators":["MR_INT"],"countryCode":"FR","discountAllowed":true,"timezone":"UTC","openDate":"2020-02-02T14:51:00.000Z","version":3148443825,"name":"Set 1 Winner","eventName":"Moriya v Petrovic"}}]}
{"op":"mcm","clk":"1001853415","pt":1580640718147,"mc":[{"id":"1.168224472","marketDefinition":{"bspMarket":false,"turnInPlayEnabled":true,"persistenceEnabled":true,"marketBaseRate":5.0,"eventId":"29681747","eventTypeId":"2","numberOfWinners":1,"bettingType":"ODDS","marketType":"SET_WINNER","marketTime":"2020-02-02T14:48:00.000Z","suspendTime":"2020-02-02T14:48:00.000Z","bspReconciled":false,"complete":true,"inPlay":false,"crossMatching":false,"runnersVoidable":false,"numberOfActiveRunners":2,"betDelay":0,"status":"OPEN","runners":[{"status":"ACTIVE","sortPriority":1,"id":5858055,"name":"Hiroki Moriya"},{"status":"ACTIVE","sortPriority":2,"id":7444998,"name":"Danilo Petrovic"}],"regulators":["MR_INT"],"countryCode":"FR","discountAllowed":true,"timezone":"UTC","openDate":"2020-02-02T14:48:00.000Z","version":3148443825,"name":"Set 1 Winner","eventName":"Moriya v Petrovic"}}]}
{"op":"mcm","clk":"1002676122","pt":1580645813890,"mc":[{"id":"1.168224472","marketDefinition":{"bspMarket":false,"turnInPlayEnabled":true,"persistenceEnabled":true,"marketBaseRate":5.0,"eventId":"29681747","eventTypeId":"2","numberOfWinners":1,"bettingType":"ODDS","marketType":"SET_WINNER","marketTime":"2020-02-02T14:16:00.000Z","suspendTime":"2020-02-02T14:16:00.000Z","bspReconciled":false,"complete":true,"inPlay":false,"crossMatching":false,"runnersVoidable":false,"numberOfActiveRunners":2,"betDelay":0,"status":"OPEN","runners":[{"status":"ACTIVE","sortPriority":1,"id":5858055,"name":"Hiroki Moriya"},{"status":"ACTIVE","sortPriority":2,"id":7444998,"name":"Danilo Petrovic"}],"regulators":["MR_INT"],"countryCode":"FR","discountAllowed":true,"timezone":"UTC","openDate":"2020-02-02T14:48:00.000Z","version":3148684765,"name":"Set 1 Winner","eventName":"Moriya v Petrovic"}}]}
{"op":"mcm","clk":"1002676782","pt":1580645817903,"mc":[{"id":"1.168224472","marketDefinition":{"bspMarket":false,"turnInPlayEnabled":true,"persistenceEnabled":true,"marketBaseRate":5.0,"eventId":"29681747","eventTypeId":"2","numberOfWinners":1,"bettingType":"ODDS","marketType":"SET_WINNER","marketTime":"2020-02-02T14:16:00.000Z","suspendTime":"2020-02-02T14:16:00.000Z","bspReconciled":false,"complete":true,"inPlay":false,"crossMatching":false,"runnersVoidable":false,"numberOfActiveRunners":2,"betDelay":0,"status":"OPEN","runners":[{"status":"ACTIVE","sortPriority":1,"id":5858055,"name":"Hiroki Moriya"},{"status":"ACTIVE","sortPriority":2,"id":7444998,"name":"Danilo Petrovic"}],"regulators":["MR_INT"],"countryCode":"FR","discountAllowed":true,"timezone":"UTC","openDate":"2020-02-02T14:16:00.000Z","version":3148684765,"name":"Set 1 Winner","eventName":"Moriya v Petrovic"}}]}
{"op":"mcm","clk":"1002710712","pt":1580646040838,"mc":[{"id":"1.168224472","rc":[{"batl":[[0,2.96,4.54]],"ltp":0.0,"tv":0.0,"id":5858055},{"batl":[[0,2.94,4.54]],"ltp":0.0,"tv":0.0,"id":7444998}]}]}
{"op":"mcm","clk":"1003651360","pt":1580651294971,"mc":[{"id":"1.168224472","rc":[{"batb":[[0,1.02,2],[1,1.01,16.01]],"ltp":0.0,"tv":0.0,"id":5858055},{"batb":[[0,1.02,2],[1,1.01,16.01]],"ltp":0.0,"tv":0.0,"id":7444998}]}]}
{"op":"mcm","clk":"1003656991","pt":1580651325024,"mc":[{"id":"1.168224472","marketDefinition":{"bspMarket":false,"turnInPlayEnabled":true,"persistenceEnabled":true,"marketBaseRate":5.0,"eventId":"29681747","eventTypeId":"2","numberOfWinners":1,"bettingType":"ODDS","marketType":"SET_WINNER","marketTime":"2020-02-02T14:16:00.000Z","suspendTime":"2020-02-02T14:16:00.000Z","bspReconciled":false,"complete":true,"inPlay":false,"crossMatching":true,"runnersVoidable":false,"numberOfActiveRunners":2,"betDelay":0,"status":"OPEN","runners":[{"status":"ACTIVE","sortPriority":1,"id":5858055,"name":"Hiroki Moriya"},{"status":"ACTIVE","sortPriority":2,"id":7444998,"name":"Danilo Petrovic"}],"regulators":["MR_INT"],"countryCode":"FR","discountAllowed":true,"timezone":"UTC","openDate":"2020-02-02T14:16:00.000Z","version":3148684765,"name":"Set 1 Winner","eventName":"Moriya v Petrovic"}}]}
{"op":"mcm","clk":"1003763186","pt":1580651894257,"mc":[{"id":"1.168224472","rc":[{"batb":[[0,1.01,16.01],[1,1.01,0]],"ltp":0.0,"tv":0.0,"id":5858055}]}]}
{"op":"mcm","clk":"1003763254","pt":1580651894530,"mc":[{"id":"1.168224472","rc":[{"batb":[[0,1.01,16.01],[1,1.01,0]],"ltp":0.0,"tv":0.0,"id":7444998}]}]}
{"op":"mcm","clk":"1003808359","pt":1580652114770,"mc":[{"id":"1.168224472","marketDefinition":{"bspMarket":false,"turnInPlayEnabled":true,"persistenceEnabled":true,"marketBaseRate":5.0,"eventId":"29681747","eventTypeId":"2","numberOfWinners":1,"bettingType":"ODDS","marketType":"SET_WINNER","marketTime":"2020-02-02T14:06:00.000Z","suspendTime":"2020-02-02T14:06:00.000Z","bspReconciled":false,"complete":true,"inPlay":false,"crossMatching":true,"runnersVoidable":false,"numberOfActiveRunners":2,"betDelay":0,"status":"OPEN","runners":[{"status":"ACTIVE","sortPriority":1,"id":5858055,"name":"Hiroki Moriya"},{"status":"ACTIVE","sortPriority":2,"id":7444998,"name":"Danilo Petrovic"}],"regulators":["MR_INT"],"countryCode":"FR","discountAllowed":true,"timezone":"UTC","openDate":"2020-02-02T14:16:00.000Z","version":3149081986,"name":"Set 1 Winner","eventName":"Moriya v Petrovic"}}]}
{"op":"mcm","clk":"1003809195","pt":1580652118802,"mc":[{"id":"1.168224472","marketDefinition":{"bspMarket":false,"turnInPlayEnabled":true,"persistenceEnabled":true,"marketBaseRate":5.0,"eventId":"29681747","eventTypeId":"2","numberOfWinners":1,"bettingType":"ODDS","marketType":"SET_WINNER","marketTime":"2020-02-02T14:06:00.000Z","suspendTime":"2020-02-02T14:06:00.000Z","bspReconciled":false,"complete":true,"inPlay":false,"crossMatching":true,"runnersVoidable":false,"numberOfActiveRunners":2,"betDelay":0,"status":"OPEN","runners":[{"status":"ACTIVE","sortPriority":1,"id":5858055,"name":"Hiroki Moriya"},{"status":"ACTIVE","sortPriority":2,"id":7444998,"name":"Danilo Petrovic"}],"regulators":["MR_INT"],"countryCode":"FR","discountAllowed":true,"timezone":"UTC","openDate":"2020-02-02T14:06:00.000Z","version":3149081986,"name":"Set 1 Winner","eventName":"Moriya v Petrovic"}}]}
{"op":"mcm","clk":"1003845478","pt":1580652277851,"mc":[{"id":"1.168224472","rc":[{"batb":[[0,1.93,15.66],[1,1.01,16.01]],"ltp":0.0,"tv":0.0,"id":5858055},{"batb":[[0,1.93,15.66],[1,1.01,16.01]],"ltp":0.0,"tv":0.0,"id":7444998}]}]}
{"op":"mcm","clk":"1003878607","pt":1580652413628,"mc":[{"id":"1.168224472","marketDefinition":{"bspMarket":false,"turnInPlayEnabled":true,"persistenceEnabled":true,"marketBaseRate":5.0,"eventId":"29681747","eventTypeId":"2","numberOfWinners":1,"bettingType":"ODDS","marketType":"SET_WINNER","marketTime":"2020-02-02T14:03:00.000Z","suspendTime":"2020-02-02T14:03:00.000Z","bspReconciled":false,"complete":true,"inPlay":false,"crossMatching":true,"runnersVoidable":false,"numberOfActiveRunners":2,"betDelay":0,"status":"OPEN","runners":[{"status":"ACTIVE","sortPriority":1,"id":5858055,"name":"Hiroki Moriya"},{"status":"ACTIVE","sortPriority":2,"id":7444998,"name":"Danilo Petrovic"}],"regulators":["MR_INT"],"countryCode":"FR","discountAllowed":true,"timezone":"UTC","openDate":"2020-02-02T14:06:00.000Z","version":3149117371,"name":"Set 1 Winner","eventName":"Moriya v Petrovic"}}]}
{"op":"mcm","clk":"1003879387","pt":1580652416642,"mc":[{"id":"1.168224472","marketDefinition":{"bspMarket":false,"turnInPlayEnabled":true,"persistenceEnabled":true,"marketBaseRate":5.0,"eventId":"29681747","eventTypeId":"2","numberOfWinners":1,"bettingType":"ODDS","marketType":"SET_WINNER","marketTime":"2020-02-02T14:03:00.000Z","suspendTime":"2020-02-02T14:03:00.000Z","bspReconciled":false,"complete":true,"inPlay":false,"crossMatching":true,"runnersVoidable":false,"numberOfActiveRunners":2,"betDelay":0,"status":"OPEN","runners":[{"status":"ACTIVE","sortPriority":1,"id":5858055,"name":"Hiroki Moriya"},{"status":"ACTIVE","sortPriority":2,"id":7444998,"name":"Danilo Petrovic"}],"regulators":["MR_INT"],"countryCode":"FR","discountAllowed":true,"timezone":"UTC","openDate":"2020-02-02T14:03:00.000Z","version":3149117371,"name":"Set 1 Winner","eventName":"Moriya v Petrovic"}}]}
{"op":"mcm","clk":"1003930605","pt":1580652610576,"mc":[{"id":"1.168224472","rc":[{"batb":[[0,1.93,60.19]],"batl":[[0,2.14,36.13],[1,2.96,4.54]],"ltp":0.0,"tv":0.0,"id":5858055},{"batb":[[1,1.89,47.05],[2,1.01,16.01]],"batl":[[0,2.1,37.81],[1,2.94,4.54]],"ltp":0.0,"tv":0.0,"id":7444998}]}]}
{"op":"mcm","clk":"1003995124","pt":1580652868100,"mc":[{"id":"1.168224472","rc":[{"batb":[[0,1.93,44.53]],"ltp":0.0,"tv":0.0,"id":5858055},{"batb":[[0,1.89,47.05],[1,1.01,16.01],[2,1.01,0]],"ltp":0.0,"tv":0.0,"id":7444998}]}]}
{"op":"mcm","clk":"1003995312","pt":1580652868929,"mc":[{"id":"1.168224472","marketDefinition":{"bspMarket":false,"turnInPlayEnabled":true,"persistenceEnabled":true,"marketBaseRate":5.0,"eventId":"29681747","eventTypeId":"2","numberOfWinners":1,"bettingType":"ODDS","marketType":"SET_WINNER","marketTime":"2020-02-02T14:03:00.000Z","suspendTime":"2020-02-02T14:03:00.000Z","bspReconciled":false,"complete":true,"inPlay":true,"crossMatching":true,"runnersVoidable":false,"numberOfActiveRunners":2,"betDelay":3,"status":"OPEN","runners":[{"status":"ACTIVE","sortPriority":1,"id":5858055,"name":"Hiroki Moriya"},{"status":"ACTIVE","sortPriority":2,"id":7444998,"name":"Danilo Petrovic"}],"regulators":["MR_INT"],"countryCode":"FR","discountAllowed":true,"timezone":"UTC","openDate":"2020-02-02T14:03:00.000Z","version":3149153559,"name":"Set 1 Winner","eventName":"Moriya v Petrovic"},"rc":[{"batb":[[0,1.01,15.51],[1,1.01,0]],"ltp":0.0,"tv":0.0,"id":5858055},{"batb":[[0,1.01,15.51],[1,1.01,0]],"ltp":0.0,"tv":0.0,"id":7444998}]}]}
{"op":"mcm","clk":"1003996528","pt":1580652874416,"mc":[{"id":"1.168224472","rc":[{"batb":[[0,1.76,98.55],[1,1.74,99.09],[2,1.01,15.51]],"batl":[[0,2.18,63.58],[1,2.2,49.17]],"ltp":0.0,"tv":0.0,"id":7444998}]}]}
{"op":"mcm","clk":"1003998571","pt":1580652883113,"mc":[{"id":"1.168224472","rc":[{"batb":[[0,1.01,15.51],[1,1.74,0],[2,1.01,0]],"ltp":0.0,"tv":0.0,"id":7444998}]}]}
{"op":"mcm","clk":"1003999222","pt":1580652885932,"mc":[{"id":"1.168224472","rc":[{"batb":[[0,1.85,64.5],[1,1.83,83.76],[2,1.01,15.51]],"batl":[[0,1.93,70.88],[1,1.95,69.78]],"ltp":0.0,"tv":0.0,"id":5858055}]}]}
{"op":"mcm","clk":"1003999414","pt":1580652886808,"mc":[{"id":"1.168224472","rc":[{"batb":[[2,1.82,18.96]],"ltp":0.0,"tv":0.0,"id":5858055},{"batb":[[0,2.06,25.49],[1,1.89,16.76],[2,1.01,15.51]],"ltp":0.0,"tv":0.0,"id":7444998}]}]}
{"op":"mcm","clk":"1003999649","pt":1580652887845,"mc":[{"id":"1.168224472","rc":[{"batb":[[2,1.82,69.37]],"batl":[[2,2.02,41.17]],"ltp":0.0,"tv":0.0,"id":5858055},{"batb":[[1,1.97,42.85],[2,1.89,16.76]],"batl":[[0,2.22,33.61]],"ltp":0.0,"tv":0.0,"id":7444998}]}]}
{"op":"mcm","clk":"1004002205","pt":1580652899144,"mc":[{"id":"1.168224472","rc":[{"batb":[[0,1.74,22.11],[1,1.01,15.51],[2,1.82,0]],"ltp":0.0,"tv":0.0,"id":5858055},{"batb":[[0,1.89,16.76],[1,1.01,15.51],[2,1.89,0]],"ltp":0.0,"tv":0.0,"id":7444998}]}]}
{"op":"mcm","clk":"1004002767","pt":1580652901545,"mc":[{"id":"1.168224472","rc":[{"batb":[[0,1.77,81.97],[1,1.75,97.12],[2,1.74,22.11]],"batl":[[0,2.12,92.91],[1,2.14,53.18]],"ltp":0.0,"tv":0.0,"id":5858055}]}]}
{"op":"mcm","clk":"1004006235","pt":1580652917326,"mc":[{"id":"1.168224472","rc":[{"batl":[[0,1.85,90.77],[1,1.87,79.27]],"ltp":0.0,"tv":0.0,"id":5858055}]}]}
{"op":"mcm","clk":"1004006474","pt":1580652918339,"mc":[{"id":"1.168224472","rc":[{"batb":[[1,1.75,152.57]],"batl":[[2,1.94,42.01]],"ltp":0.0,"tv":0.0,"id":5858055},{"batb":[[0,2.18,21.64],[1,2.06,39.49],[2,2.04,26.59]],"batl":[[0,2.32,31.09]],"ltp":0.0,"tv":0.0,"id":7444998}]}]}
{"op":"mcm","clk":"1004008663","pt":1580652928350,"mc":[{"id":"1.168224472","rc":[{"batb":[[0,1.75,55.45],[1,1.68,24.86],[2,1.01,15.51]],"batl":[[0,1.94,42.01],[1,1.87,0],[2,1.94,0]],"ltp":0.0,"tv":0.0,"id":5858055},{"batb":[[0,2.06,39.49],[1,2.04,26.59],[2,1.01,15.51]],"ltp":0.0,"tv":0.0,"id":7444998}]}]}
{"op":"mcm","clk":"1004008778","pt":1580652928853,"mc":[{"id":"1.168224472","rc":[{"batb":[[0,1.68,24.86],[1,1.01,15.51],[2,1.01,0]],"ltp":0.0,"tv":0.0,"id":5858055},{"batb":[[0,2.04,26.59],[1,1.01,15.51],[2,1.01,0]],"ltp":0.0,"tv":0.0,"id":7444998}]}]}
{"op":"mcm","clk":"1004009306","pt":1580652931266,"mc":[{"id":"1.168224472","rc":[{"batb":[[0,1.72,91.63],[1,1.7,107.26],[2,1.68,24.86]],"batl":[[0,1.95,56.41],[1,1.97,67.67]],"ltp":0.0,"tv":0.0,"id":5858055}]}]}
{"op":"mcm","clk":"1004010942","pt":1580652938298,"mc":[{"id":"1.168224472","rc":[{"batb":[[1,1.71,58.81],[2,1.7,107.26]],"batl":[[0,1.79,65.26],[1,1.81,87.91],[2,1.87,42.01]],"ltp":0.0,"tv":0.0,"id":5858055},{"batb":[[0,2.28,19.04],[1,2.16,22.19],[2,2.12,36.97]],"batl":[[0,2.4,29.41]],"ltp":0.0,"tv":0.0,"id":7444998}]}]}
{"op":"mcm","clk":"1004013959","pt":1580652952893,"mc":[{"id":"1.168224472","rc":[{"batb":[[0,1.71,58.81],[1,1.65,26.36],[2,1.01,15.51]],"batl":[[0,1.87,42.01],[1,1.81,0],[2,1.87,0]],"ltp":0.0,"tv":0.0,"id":5858055},{"batb":[[0,2.16,22.19],[1,2.12,36.97],[2,1.01,15.51]],"ltp":0.0,"tv":0.0,"id":7444998}]}]}
{"op":"mcm","clk":"1004014456","pt":1580652955300,"mc":[{"id":"1.168224472","rc":[{"batb":[[0,1.65,26.36],[1,1.01,15.51],[2,1.01,0]],"ltp":0.0,"tv":0.0,"id":5858055},{"batb":[[1,1.01,15.51],[2,1.01,0]],"ltp":0.0,"tv":0.0,"id":7444998}]}]}
{"op":"mcm","clk":"1004014609","pt":1580652956004,"mc":[{"id":"1.168224472","rc":[{"batb":[[0,1.69,111.39],[1,1.67,114.26],[2,1.65,26.36]],"batl":[[0,1.85,74.61],[1,1.87,79.3]],"ltp":0.0,"tv":0.0,"id":5858055}]}]}
{"op":"mcm","clk":"1004016287","pt":1580652964100,"mc":[{"id":"1.168224472","rc":[{"batb":[[0,1.65,26.36],[1,1.01,15.51],[2,1.65,0]],"ltp":0.0,"tv":0.0,"id":5858055}]}]}
{"op":"mcm","clk":"1004017005","pt":1580652967282,"mc":[{"id":"1.168224472","rc":[{"batb":[[0,1.77,99.01],[1,1.75,118.72],[2,1.69,24.31]],"ltp":0.0,"tv":0.0,"id":5858055},{"batb":[[1,2.02,27.22],[2,1.01,15.51]],"ltp":0.0,"tv":0.0,"id":7444998}]}]}
{"op":"mcm","clk":"1004017211","pt":1580652968291,"mc":[{"id":"1.168224472","rc":[{"batb":[[1,1.76,54.61],[2,1.75,118.72]],"batl":[[2,1.93,42.01]],"ltp":0.0,"tv":0.0,"id":5858055},{"batb":[[1,2.08,38.65],[2,2.02,27.22]],"batl":[[0,2.32,31.09]],"ltp":0.0,"tv":0.0,"id":7444998}]}]}
{"op":"mcm","clk":"1004020624","pt":1580652983734,"mc":[{"id":"1.168224472","rc":[{"batb":[[0,1.76,54.61],[1,1.69,24.31],[2,1.01,15.51]],"batl":[[0,1.93,42.01],[1,1.87,0],[2,1.93,0]],"ltp":0.0,"tv":0.0,"id":5858055},{"batb":[[0,2.08,38.65],[1,2.02,27.22],[2,1.01,15.51]],"ltp":0.0,"tv":0.0,"id":7444998}]}]}
{"op":"mcm","clk":"1004020868","pt":1580652984837,"mc":[{"id":"1.168224472","rc":[{"batb":[[0,1.69,24.31],[1,1.01,15.51],[2,1.01,0]],"ltp":0.0,"tv":0.0,"id":5858055},{"batb":[[0,2.02,27.22],[1,1.01,15.51],[2,1.01,0]],"ltp":0.0,"tv":0.0,"id":7444998}]}]}
{"op":"mcm","clk":"1004021210","pt":1580652986525,"mc":[{"id":"1.168224472","rc":[{"batb":[[0,1.73,60.17],[1,1.71,105],[2,1.69,24.31]],"batl":[[0,1.95,65.69],[1,1.97,67.66]],"ltp":0.0,"tv":0.0,"id":5858055}]}]}
{"op":"mcm","clk":"1004021771","pt":1580652989251,"mc":[{"id":"1.168224472","rc":[{"batb":[[0,1.69,24.31],[1,1.01,15.51],[2,1.69,0]],"ltp":0.0,"tv":0.0,"id":5858055}]}]}
{"op":"mcm","clk":"1004022916","pt":1580652994361,"mc":[{"id":"1.168224472","rc":[{"batb":[[0,1.73,60.17],[1,1.71,105],[2,1.69,24.31]],"batl":[[0,1.95,65.69],[1,1.97,67.66]],"ltp":0.0,"tv":0.0,"id":5858055}]}]}
{"op":"mcm","clk":"1004025405","pt":1580653006239,"mc":[{"id":"1.168224472","rc":[{"batl":[[0,1.8,89.98],[1,1.82,86.31]],"ltp":0.0,"tv":0.0,"id":5858055}]}]}
{"op":"mcm","clk":"1004025508","pt":1580653006784,"mc":[{"id":"1.168224472","rc":[{"batb":[[0,2.26,19.51],[1,2.1,24],[2,1.01,15.51]],"ltp":0.0,"tv":0.0,"id":7444998}]}]}
{"op":"mcm","clk":"1004025720","pt":1580653007778,"mc":[{"id":"1.168224472","rc":[{"batb":[[2,1.7,59.65]],"batl":[[2,1.86,42.01]],"ltp":0.0,"tv":0.0,"id":5858055},{"batb":[[1,2.14,36.13],[2,2.1,24]],"batl":[[0,2.42,29.41]],"ltp":0.0,"tv":0.0,"id":7444998}]}]}
{"op":"mcm","clk":"1004032856","pt":1580653042973,"mc":[{"id":"1.168224472","rc":[{"batb":[[0,1.7,59.65],[1,1.69,24.31],[2,1.55,33.28]],"batl":[[0,1.86,42.01],[1,1.82,0],[2,1.86,0]],"ltp":0.0,"tv":0.0,"id":5858055}]}]}
{"op":"mcm","clk":"1004033067","pt":1580653044170,"mc":[{"id":"1.168224472","rc":[{"batb":[[1,1.55,33.28],[2,1.01,15.51]],"ltp":0.0,"tv":0.0,"id":5858055},{"batb":[[0,2.14,36.13],[1,2.1,24],[2,1.01,15.51]],"ltp":0.0,"tv":0.0,"id":7444998}]}]}
{"op":"mcm","clk":"1004033195","pt":1580653044936,"mc":[{"id":"1.168224472","rc":[{"batb":[[0,1.55,33.28],[1,1.01,15.51],[2,1.01,0]],"ltp":0.0,"tv":0.0,"id":5858055},{"batb":[[0,2.1,24],[1,1.01,15.51],[2,1.01,0]],"ltp":0.0,"tv":0.0,"id":7444998}]}]}
{"op":"mcm","clk":"1004033385","pt":1580653045976,"mc":[{"id":"1.168224472","rc":[{"batb":[[0,1.58,83.36],[1,1.57,71.98],[2,1.55,33.28]],"batl":[[0,1.9,56.3],[1,1.92,73.14]],"ltp":0.0,"tv":0.0,"id":5858055}]}]}
{"op":"mcm","clk":"1004034153","pt":1580653049899,"mc":[{"id":"1.168224472","rc":[{"batb":[[0,1.55,33.28],[1,1.01,15.51],[2,1.55,0]],"ltp":0.0,"tv":0.0,"id":5858055}]}]}
{"op":"mcm","clk":"1004034768","pt":1580653053200,"mc":[{"id":"1.168224472","rc":[{"batb":[[0,1.82,93.12],[1,1.8,88.44],[2,1.55,33.28]],"ltp":0.0,"tv":0.0,"id":5858055}]}]}
{"op":"mcm","clk":"1004034904","pt":1580653053905,"mc":[{"id":"1.168224472","rc":[{"batb":[[2,1.79,20.06]],"batl":[[2,1.96,42.01]],"ltp":0.0,"tv":0.0,"id":5858055},{"batb":[[1,2.04,40.33],[2,1.99,28.72]],"batl":[[0,2.28,32.77]],"ltp":0.0,"tv":0.0,"id":7444998}]}]}
{"op":"mcm","clk":"1004036734","pt":1580653062941,"mc":[{"id":"1.168224472","rc":[{"batb":[[0,1.65,26.2],[1,1.01,15.51],[2,1.79,0]],"ltp":0.0,"tv":0.0,"id":5858055},{"batb":[[0,1.99,28.72],[1,1.01,15.51],[2,1.99,0]],"ltp":0.0,"tv":0.0,"id":7444998}]}]}
{"op":"mcm","clk":"1004038454","pt":1580653072314,"mc":[{"id":"1.168224472","rc":[{"batb":[[0,1.69,81.78],[1,1.67,114.12],[2,1.65,26.2]],"batl":[[0,2,74.87],[1,2.02,62.81]],"ltp":0.0,"tv":0.0,"id":5858055}]}]}
{"op":"mcm","clk":"1004039962","pt":1580653080031,"mc":[{"id":"1.168224472","rc":[{"batl":[[0,1.76,91.17],[1,1.78,92.69]],"ltp":0.0,"tv":0.0,"id":5858055}]}]}
{"op":"mcm","clk":"1004040101","pt":1580653080758,"mc":[{"id":"1.168224472","rc":[{"batb":[[0,2.34,17.94],[1,2.12,23.29],[2,1.01,15.51]],"ltp":0.0,"tv":0.0,"id":7444998}]}]}
{"op":"mcm","clk":"1004040304","pt":1580653081741,"mc":[{"id":"1.168224472","rc":[{"batb":[[1,1.68,61.33],[2,1.67,114.12]],"batl":[[2,1.84,42.01]],"ltp":0.0,"tv":0.0,"id":5858055},{"batb":[[1,2.2,34.45],[2,2.12,23.29]],"batl":[[0,2.5,27.73]],"ltp":0.0,"tv":0.0,"id":7444998}]}]}
{"op":"mcm","clk":"1004042518","pt":1580653092874,"mc":[{"id":"1.168224472","rc":[{"batb":[[0,1.49,38.16],[1,1.01,15.51],[2,1.67,0]],"ltp":0.0,"tv":0.0,"id":5858055},{"batb":[[0,2.12,23.29],[1,1.01,15.51],[2,2.12,0]],"ltp":0.0,"tv":0.0,"id":7444998}]}]}
{"op":"mcm","clk":"1004043031","pt":1580653095799,"mc":[{"id":"1.168224472","rc":[{"batb":[[0,1.52,102.81],[1,1.51,83.91],[2,1.49,38.16]],"batl":[[0,1.89,88.1],[1,1.91,74.27]],"ltp":0.0,"tv":0.0,"id":5858055}]}]}
{"op":"mcm","clk":"1004044100","pt":1580653101368,"mc":[{"id":"1.168224472","rc":[{"batb":[[0,1.49,38.16],[1,1.01,15.51],[2,1.49,0]],"ltp":0.0,"tv":0.0,"id":5858055}]}]}
{"op":"mcm","clk":"1004044717","pt":1580653104372,"mc":[{"id":"1.168224472","rc":[{"batb":[[0,1.81,64.39],[1,1.79,90.02],[2,1.49,38.16]],"ltp":0.0,"tv":0.0,"id":5858055}]}]}
{"op":"mcm","clk":"1004044861","pt":1580653105190,"mc":[{"id":"1.168224472","rc":[{"batb":[[2,1.77,20.61]],"ltp":0.0,"tv":0.0,"id":5858055},{"batb":[[1,2,28.17],[2,1.01,15.51]],"ltp":0.0,"tv":0.0,"id":7444998}]}]}
{"op":"mcm","clk":"1004044969","pt":1580653105769,"mc":[{"id":"1.168224472","rc":[{"batl":[[2,1.94,42.01]],"ltp":0.0,"tv":0.0,"id":5858055},{"batb":[[1,2.06,39.49],[2,2,28.17]],"batl":[[0,2.3,31.93]],"ltp":0.0,"tv":0.0,"id":7444998}]}]}
{"op":"mcm","clk":"1004046455","pt":1580653113776,"mc":[{"id":"1.168224472","rc":[{"batb":[[0,1.76,54.61],[1,1.62,28.4],[2,1.52,425.49]],"batl":[[0,1.94,42.01],[1,1.91,0],[2,1.94,0]],"ltp":0.0,"tv":0.0,"id":5858055},{"batb":[[0,2.06,39.49],[1,2,28.17],[2,1.74,404.28]],"ltp":0.0,"tv":0.0,"id":7444998}]}]}
{"op":"mcm","clk":"1004046677","pt":1580653114897,"mc":[{"id":"1.168224472","rc":[{"batb":[[0,1.62,28.4],[1,1.52,425.49],[2,1.01,15.51]],"ltp":0.0,"tv":0.0,"id":5858055},{"batb":[[0,2,28.17],[1,1.74,404.28],[2,1.01,15.51]],"ltp":0.0,"tv":0.0,"id":7444998}]}]}
{"op":"mcm","clk":"1004047010","pt":1580653116683,"mc":[{"id":"1.168224472","rc":[{"batb":[[0,1.65,111.49],[1,1.64,61.34],[2,1.62,28.4]],"batl":[[0,2,79.27],[1,2.02,62.8]],"ltp":0.0,"tv":0.0,"id":5858055}]}]}
{"op":"mcm","clk":"1004050377","pt":1580653134116,"mc":[{"id":"1.168224472","rc":[{"batb":[[0,1.62,28.4],[1,1.52,425.49],[2,1.01,15.51]],"ltp":0.0,"tv":0.0,"id":5858055}]}]}
{"op":"mcm","clk":"1004050762","pt":1580653136130,"mc":[{"id":"1.168224472","rc":[{"batb":[[1,1.01,15.51],[2,1.01,0]],"ltp":0.0,"tv":0.0,"id":5858055}]}]}
{"op":"mcm","clk":"1004050940","pt":1580653136954,"mc":[{"id":"1.168224472","rc":[{"batb":[[0,1.91,65.71],[1,1.89,75.54],[2,1.62,28.4]],"ltp":0.0,"tv":0.0,"id":5858055}]}]}
{"op":"mcm","clk":"1004051171","pt":1580653138154,"mc":[{"id":"1.168224472","rc":[{"batb":[[2,1.88,17.23]],"batl":[[2,2.04,40.33]],"ltp":0.0,"tv":0.0,"id":5858055},{"batb":[[1,1.96,43.69],[2,1.93,15.82]],"batl":[[0,2.18,35.29]],"ltp":0.0,"tv":0.0,"id":7444998}]}]}
{"op":"mcm","clk":"1004052754","pt":1580653146047,"mc":[{"id":"1.168224472","rc":[{"batb":[[0,1.84,49.57],[1,1.76,21.01],[2,1.58,416.47]],"batl":[[0,2.04,40.33],[1,2.02,0],[2,2.04,0]],"ltp":0.0,"tv":0.0,"id":5858055},{"batb":[[0,1.96,43.69],[1,1.93,15.82],[2,1.74,404.28]],"ltp":0.0,"tv":0.0,"id":7444998}]}]}
{"op":"mcm","clk":"1004052929","pt":1580653146959,"mc":[{"id":"1.168224472","rc":[{"batb":[[0,1.76,21.01],[1,1.58,416.47],[2,1.01,15.51]],"ltp":0.0,"tv":0.0,"id":5858055},{"batb":[[0,1.93,15.82],[1,1.74,404.28],[2,1.01,15.51]],"ltp":0.0,"tv":0.0,"id":7444998}]}]}
{"op":"mcm","clk":"1004053330","pt":1580653148988,"mc":[{"id":"1.168224472","rc":[{"batb":[[0,1.81,77.43],[1,1.79,90.05],[2,1.76,21.01]],"batl":[[0,2.06,61.74],[1,2.08,57.67]],"ltp":0.0,"tv":0.0,"id":5858055}]}]}
{"op":"mcm","clk":"1004054119","pt":1580653152786,"mc":[{"id":"1.168224472","rc":[{"batb":[[0,1.76,21.01],[1,1.58,416.47],[2,1.01,15.51]],"ltp":0.0,"tv":0.0,"id":5858055}]}]}
{"op":"mcm","clk":"1004054993","pt":1580653157353,"mc":[{"id":"1.168224472","rc":[{"batb":[[0,1.81,77.43],[1,1.79,90.05],[2,1.76,21.01]],"batl":[[0,2.06,61.74],[1,2.08,57.67]],"ltp":0.0,"tv":0.0,"id":5858055}]}]}
{"op":"mcm","clk":"1004057326","pt":1580653169305,"mc":[{"id":"1.168224472","rc":[{"batl":[[0,1.89,76.15],[1,1.91,74.29]],"ltp":0.0,"tv":0.0,"id":5858055}]}]}
{"op":"mcm","clk":"1004057545","pt":1580653170330,"mc":[{"id":"1.168224472","rc":[{"batb":[[2,1.76,75.62]],"batl":[[2,1.95,42.01]],"ltp":0.0,"tv":0.0,"id":5858055},{"batb":[[0,2.14,22.82],[1,2.04,40.33],[2,1.99,28.72]],"batl":[[0,2.3,31.93]],"ltp":0.0,"tv":0.0,"id":7444998}]}]}
{"op":"mcm","clk":"1004059761","pt":1580653181437,"mc":[{"id":"1.168224472","rc":[{"batb":[[0,1.76,75.62],[1,1.6,29.51],[2,1.58,416.47]],"batl":[[0,1.95,42.01],[1,1.91,0],[2,1.95,0]],"ltp":0.0,"tv":0.0,"id":5858055}]}]}
{"op":"mcm","clk":"1004059778","pt":1580653181543,"mc":[{"id":"1.168224472","rc":[{"batb":[[0,1.76,54.61]],"ltp":0.0,"tv":0.0,"id":5858055},{"batb":[[0,2.04,40.33],[1,1.99,28.72],[2,1.74,404.28]],"ltp":0.0,"tv":0.0,"id":7444998}]}]}
{"op":"mcm","clk":"1004060069","pt":1580653182904,"mc":[{"id":"1.168224472","rc":[{"batb":[[0,1.6,29.51],[1,1.58,416.47],[2,1.01,15.51]],"ltp":0.0,"tv":0.0,"id":5858055},{"batb":[[0,1.99,28.72],[1,1.74,404.28],[2,1.01,15.51]],"ltp":0.0,"tv":0.0,"id":7444998}]}]}
{"op":"mcm","clk":"1004060348","pt":1580653184396,"mc":[{"id":"1.168224472","rc":[{"batb":[[0,1.64,85.12],[1,1.63,62.63],[2,1.6,29.51]],"batl":[[0,2.02,80.9],[1,2.04,61.02]],"ltp":0.0,"tv":0.0,"id":5858055}]}]}
{"op":"mcm","clk":"1004061649","pt":1580653190812,"mc":[{"id":"1.168224472","rc":[{"batb":[[0,1.6,29.51],[1,1.58,416.47],[2,1.01,15.51]],"ltp":0.0,"tv":0.0,"id":5858055}]}]}
{"op":"mcm","clk":"1004062224","pt":1580653193912,"mc":[{"id":"1.168224472","rc":[{"batb":[[0,1.93,56.1],[1,1.91,73.08],[2,1.6,29.51]],"ltp":0.0,"tv":0.0,"id":5858055}]}]}
{"op":"mcm","clk":"1004062469","pt":1580653195204,"mc":[{"id":"1.168224472","rc":[{"batb":[[2,1.89,16.84]],"ltp":0.0,"tv":0.0,"id":5858055},{"batb":[[1,1.78,20.22],[2,1.74,404.28]],"ltp":0.0,"tv":0.0,"id":7444998}]}]}
{"op":"mcm","clk":"1004062600","pt":1580653195835,"mc":[{"id":"1.168224472","rc":[{"batl":[[2,2.08,38.65]],"ltp":0.0,"tv":0.0,"id":5858055},{"batb":[[1,1.93,44.53],[2,1.78,20.22]],"batl":[[0,2.14,36.13]],"ltp":0.0,"tv":0.0,"id":7444998}]}]}
{"op":"mcm","clk":"1004067331","pt":1580653219143,"mc":[{"id":"1.168224472","rc":[{"batb":[[0,1.87,47.89],[1,1.77,20.61],[2,1.58,416.47]],"batl":[[0,2.08,38.65],[1,2.04,0],[2,2.08,0]],"ltp":0.0,"tv":0.0,"id":5858055},{"batb":[[0,1.93,44.53],[1,1.78,20.22],[2,1.74,404.28]],"ltp":0.0,"tv":0.0,"id":7444998}]}]}
{"op":"mcm","clk":"1004067685","pt":1580653220850,"mc":[{"id":"1.168224472","rc":[{"batb":[[0,1.77,20.61],[1,1.58,416.47],[2,1.01,15.51]],"ltp":0.0,"tv":0.0,"id":5858055},{"batb":[[0,1.78,20.22],[1,1.74,404.28],[2,1.01,15.51]],"ltp":0.0,"tv":0.0,"id":7444998}]}]}
{"op":"mcm","clk":"1004067908","pt":1580653221968,"mc":[{"id":"1.168224472","rc":[{"batb":[[0,1.81,87.29],[1,1.79,90.07],[2,1.77,20.61]],"batl":[[0,2.28,54.88],[1,2.3,43.47]],"ltp":0.0,"tv":0.0,"id":5858055}]}]}
{"op":"mcm","clk":"1004071232","pt":1580653238202,"mc":[{"id":"1.168224472","rc":[{"batl":[[0,1.89,66.36],[1,1.91,74.31]],"ltp":0.0,"tv":0.0,"id":5858055}]}]}
{"op":"mcm","clk":"1004071465","pt":1580653239269,"mc":[{"id":"1.168224472","rc":[{"batb":[[0,2.12,23.29],[1,1.93,15.66],[2,1.74,404.28]],"ltp":0.0,"tv":0.0,"id":7444998}]}]}
{"op":"mcm","clk":"1004071661","pt":1580653240192,"mc":[{"id":"1.168224472","rc":[{"batb":[[1,1.79,143]],"ltp":0.0,"tv":0.0,"id":5858055},{"batl":[[0,2.28,32.77]],"ltp":0.0,"tv":0.0,"id":7444998}]}]}
{"op":"mcm","clk":"1004071860","pt":1580653241173,"mc":[{"id":"1.168224472","rc":[{"batl":[[2,1.97,42.01]],"ltp":0.0,"tv":0.0,"id":5858055},{"batb":[[1,2.04,40.33],[2,1.93,15.66]],"ltp":0.0,"tv":0.0,"id":7444998}]}]}
{"op":"mcm","clk":"1004074276","pt":1580653253015,"mc":[{"id":"1.168224472","rc":[{"batb":[[0,1.69,24.16],[1,1.58,416.47],[2,1.01,15.51]],"ltp":0.0,"tv":0.0,"id":5858055},{"batb":[[0,1.93,15.66],[1,1.74,404.28],[2,1.01,15.51]],"ltp":0.0,"tv":0.0,"id":7444998}]}]}
{"op":"mcm","clk":"1004075020","pt":1580653256095,"mc":[{"id":"1.168224472","rc":[{"batb":[[0,1.73,99.93],[1,1.71,105.15],[2,1.69,24.16]],"batl":[[0,2.08,88.5],[1,2.1,56.11]],"ltp":0.0,"tv":0.0,"id":5858055},{"batb":[[0,1.94,15.58],[1,1.93,15.66],[2,1.74,404.28]],"ltp":0.0,"tv":0.0,"id":7444998}]}]}
{"op":"mcm","clk":"1004075048","pt":1580653256458,"mc":[{"id":"1.168224472","rc":[{"batb":[[1,1.74,404.28],[2,1.01,15.51]],"ltp":0.0,"tv":0.0,"id":7444998}]}]}
{"op":"mcm","clk":"1004077041","pt":1580653265491,"mc":[{"id":"1.168224472","rc":[{"batb":[[1,1.01,15.51],[2,1.01,0]],"ltp":0.0,"tv":0.0,"id":7444998}]}]}
{"op":"mcm","clk":"1004077370","pt":1580653267122,"mc":[{"id":"1.168224472","rc":[{"batl":[[0,1.81,95.71],[1,1.83,84.81]],"ltp":0.0,"tv":0.0,"id":5858055}]}]}
{"op":"mcm","clk":"1004077625","pt":1580653268396,"mc":[{"id":"1.168224472","rc":[{"batb":[[1,1.71,163.96]],"batl":[[2,1.88,42.01]],"ltp":0.0,"tv":0.0,"id":5858055},{"batb":[[0,2.26,19.67],[1,2.12,36.97],[2,2.1,24.55]],"batl":[[0,2.38,30.25]],"ltp":0.0,"tv":0.0,"id":7444998}]}]}
{"op":"mcm","clk":"1004079240","pt":1580653276140,"mc":[{"id":"1.168224472","rc":[{"batb":[[0,1.71,58.81],[1,1.63,27.3],[2,1.46,435.7]],"batl":[[0,1.88,42.01],[1,1.83,0],[2,1.88,0]],"ltp":0.0,"tv":0.0,"id":5858055},{"batb":[[0,2.12,36.97],[1,2.1,24.55],[2,1.82,401.24]],"ltp":0.0,"tv":0.0,"id":7444998}]}]}
{"op":"mcm","clk":"1004079403","pt":1580653276944,"mc":[{"id":"1.168224472","rc":[{"batb":[[0,1.63,27.3],[1,1.46,435.7],[2,1.01,15.51]],"ltp":0.0,"tv":0.0,"id":5858055},{"batb":[[0,2.1,24.55],[1,1.82,401.24],[2,1.01,15.51]],"ltp":0.0,"tv":0.0,"id":7444998}]}]}
{"op":"mcm","clk":"1004079865","pt":1580653278868,"mc":[{"id":"1.168224472","rc":[{"batb":[[0,1.69,58.77],[1,1.67,114],[2,1.63,27.3]],"batl":[[0,1.91,63.67],[1,1.93,71.98]],"ltp":0.0,"tv":0.0,"id":5858055}]}]}
{"op":"mcm","clk":"1004083389","pt":1580653295447,"mc":[{"id":"1.168224472","rc":[{"batl":[[0,1.75,65.14],[1,1.77,94.5]],"ltp":0.0,"tv":0.0,"id":5858055},{"batb":[[0,2.12,222.04],[1,2.1,24.55],[2,1.82,401.24]],"ltp":0.0,"tv":0.0,"id":7444998}]}]}
{"op":"mcm","clk":"1004083480","pt":1580653295975,"mc":[{"id":"1.168224472","rc":[{"batb":[[1,1.67,176.17]],"batl":[[2,1.83,42.01]],"ltp":0.0,"tv":0.0,"id":5858055},{"batb":[[0,2.38,17.07],[1,2.24,19.99],[2,2.2,34.45]],"batl":[[0,2.46,28.57]],"ltp":0.0,"tv":0.0,"id":7444998}]}]}
{"op":"mcm","clk":"1004086591","pt":1580653311402,"mc":[{"id":"1.168224472","rc":[{"batb":[[0,1.67,62.17],[1,1.61,29.03],[2,1.46,435.7]],"batl":[[0,1.83,42.01],[1,1.77,0],[2,1.83,0]],"ltp":0.0,"tv":0.0,"id":5858055},{"batb":[[0,2.24,19.99],[1,2.2,34.45],[2,1.82,401.24]],"ltp":0.0,"tv":0.0,"id":7444998}]}]}
{"op":"mcm","clk":"1004086938","pt":1580653313190,"mc":[{"id":"1.168224472","rc":[{"batb":[[0,1.61,29.03],[1,1.46,435.7],[2,1.01,15.51]],"ltp":0.0,"tv":0.0,"id":5858055},{"batb":[[1,1.82,401.24],[2,1.01,15.51]],"ltp":0.0,"tv":0.0,"id":7444998}]}]}
{"op":"mcm","clk":"1004087137","pt":1580653314191,"mc":[{"id":"1.168224472","rc":[{"batb":[[0,1.66,92.39],[1,1.65,59.96],[2,1.61,29.03]],"batl":[[0,1.81,85.49],[1,1.83,84.84]],"ltp":0.0,"tv":0.0,"id":5858055}]}]}
{"op":"mcm","clk":"1004088775","pt":1580653322396,"mc":[{"id":"1.168224472","rc":[{"batb":[[2,1.64,65.54]],"batl":[[0,1.73,99.48],[1,1.75,97.93],[2,1.78,42.01]],"ltp":0.0,"tv":0.0,"id":5858055},{"batb":[[0,2.28,32.77],[1,2.24,19.99],[2,1.82,401.24]],"batl":[[0,2.58,26.05]],"ltp":0.0,"tv":0.0,"id":7444998}]}]}
{"op":"mcm","clk":"1004088895","pt":1580653322987,"mc":[{"id":"1.168224472","rc":[{"batb":[[0,2.44,15.97],[1,2.28,32.77],[2,2.24,19.99]],"ltp":0.0,"tv":0.0,"id":7444998}]}]}
{"op":"mcm","clk":"1004103616","pt":1580653398231,"mc":[{"id":"1.168224472","rc":[{"batb":[[0,1.64,65.54],[1,1.47,40.76],[2,1.46,435.7]],"batl":[[0,1.78,42.01],[1,1.75,0],[2,1.78,0]],"ltp":0.0,"tv":0.0,"id":5858055},{"batb":[[0,2.28,32.77],[1,2.24,19.99],[2,1.82,401.24]],"ltp":0.0,"tv":0.0,"id":7444998}]}]}
{"op":"mcm","clk":"1004103788","pt":1580653399176,"mc":[{"id":"1.168224472","rc":[{"batb":[[0,1.47,40.76],[1,1.46,435.7],[2,1.01,15.51]],"ltp":0.0,"tv":0.0,"id":5858055},{"batb":[[0,2.24,19.99],[1,1.82,401.24],[2,1.01,15.51]],"ltp":0.0,"tv":0.0,"id":7444998}]}]}
{"op":"mcm","clk":"1004104115","pt":1580653401042,"mc":[{"id":"1.168224472","rc":[{"batb":[[0,1.52,81.33],[1,1.51,83.78],[2,1.47,40.76]],"batl":[[0,1.83,74.02],[1,1.85,82.01]],"ltp":0.0,"tv":0.0,"id":5858055}]}]}
{"op":"mcm","clk":"1004104622","pt":1580653403920,"mc":[{"id":"1.168224472","rc":[{"batb":[[0,1.47,40.76],[1,1.46,435.7],[2,1.01,15.51]],"ltp":0.0,"tv":0.0,"id":5858055}]}]}
{"op":"mcm","clk":"1004104994","pt":1580653405700,"mc":[{"id":"1.168224472","rc":[{"batb":[[1,1.01,15.51],[2,1.01,0]],"ltp":0.0,"tv":0.0,"id":7444998}]}]}
{"op":"mcm","clk":"1004105723","pt":1580653409358,"mc":[{"id":"1.168224472","rc":[{"batb":[[0,1.52,81.33],[1,1.51,83.78],[2,1.47,40.76]],"batl":[[0,1.83,74.02],[1,1.85,82.01]],"ltp":0.0,"tv":0.0,"id":5858055}]}]}
{"op":"mcm","clk":"1004105890","pt":1580653410179,"mc":[{"id":"1.168224472","rc":[{"batb":[[1,1.92,394.91],[2,1.01,15.51]],"ltp":0.0,"tv":0.0,"id":7444998}]}]}
{"op":"mcm","clk":"1004108448","pt":1580653423577,"mc":[{"id":"1.168224472","rc":[{"batb":[[0,1.47,40.76],[1,1.46,435.7],[2,1.01,15.51]],"ltp":0.0,"tv":0.0,"id":5858055}]}]}
{"op":"mcm","clk":"1004108692","pt":1580653424872,"mc":[{"id":"1.168224472","rc":[{"batb":[[1,1.01,15.51],[2,1.01,0]],"ltp":0.0,"tv":0.0,"id":5858055},{"batb":[[1,1.01,15.51],[2,1.01,0]],"ltp":0.0,"tv":0.0,"id":7444998}]}]}
{"op":"mcm","clk":"1004109205","pt":1580653427449,"mc":[{"id":"1.168224472","rc":[{"batb":[[0,1.76,61.74],[1,1.74,98.95],[2,1.7,23.6]],"ltp":0.0,"tv":0.0,"id":5858055},{"batb":[[1,2.12,23.84],[2,1.01,15.51]],"ltp":0.0,"tv":0.0,"id":7444998}]}]}
{"op":"mcm","clk":"1004109320","pt":1580653428198,"mc":[{"id":"1.168224472","rc":[{"batb":[[2,1.71,58.81]],"batl":[[2,1.88,42.01]],"ltp":0.0,"tv":0.0,"id":5858055},{"batb":[[1,2.14,36.13],[2,2.12,23.84]],"batl":[[0,2.4,29.41]],"ltp":0.0,"tv":0.0,"id":7444998}]}]}
{"op":"mcm","clk":"1004110974","pt":1580653436386,"mc":[{"id":"1.168224472","rc":[{"batb":[[0,1.71,58.81],[1,1.57,31.55],[2,1.5,426.9]],"batl":[[0,1.88,42.01],[1,1.85,0],[2,1.88,0]],"ltp":0.0,"tv":0.0,"id":5858055},{"batb":[[0,2.14,36.13],[1,2.12,23.84],[2,1.77,402.27]],"ltp":0.0,"tv":0.0,"id":7444998}]}]}
{"op":"mcm","clk":"1004111133","pt":1580653437180,"mc":[{"id":"1.168224472","rc":[{"batb":[[0,1.57,31.55],[1,1.5,426.9],[2,1.01,15.51]],"ltp":0.0,"tv":0.0,"id":5858055},{"batb":[[0,2.12,23.84],[1,1.77,402.27],[2,1.01,15.51]],"ltp":0.0,"tv":0.0,"id":7444998}]}]}
{"op":"mcm","clk":"1004111516","pt":1580653439112,"mc":[{"id":"1.168224472","rc":[{"batb":[[0,1.63,66.05],[1,1.62,63.99],[2,1.57,31.55]],"batl":[[0,1.92,69.31],[1,1.94,70.85]],"ltp":0.0,"tv":0.0,"id":5858055}]}]}
{"op":"mcm","clk":"1004112797","pt":1580653445367,"mc":[{"id":"1.168224472","rc":[{"batb":[[0,1.57,31.55],[1,1.5,426.9],[2,1.01,15.51]],"ltp":0.0,"tv":0.0,"id":5858055}]}]}
{"op":"mcm","clk":"1004113196","pt":1580653447105,"mc":[{"id":"1.168224472","rc":[{"batb":[[1,1.01,15.51],[2,1.01,0]],"ltp":0.0,"tv":0.0,"id":5858055}]}]}
{"op":"mcm","clk":"1004113431","pt":1580653448345,"mc":[{"id":"1.168224472","rc":[{"batb":[[0,1.84,70.42],[1,1.82,85.26],[2,1.57,31.55]],"ltp":0.0,"tv":0.0,"id":5858055}]}]}
{"op":"mcm","clk":"1004113636","pt":1580653449340,"mc":[{"id":"1.168224472","rc":[{"batb":[[2,1.78,20.22]],"ltp":0.0,"tv":0.0,"id":5858055},{"batb":[[1,2.02,26.91],[2,1.77,402.27]],"ltp":0.0,"tv":0.0,"id":7444998}]}]}
{"op":"mcm","clk":"1004113809","pt":1580653450213,"mc":[{"id":"1.168224472","rc":[{"batb":[[2,1.78,73.99]],"batl":[[2,1.96,42.01]],"ltp":0.0,"tv":0.0,"id":5858055},{"batb":[[1,2.04,40.33],[2,2.02,26.91]],"batl":[[0,2.28,32.77]],"ltp":0.0,"tv":0.0,"id":7444998}]}]}
{"op":"mcm","clk":"1004115386","pt":1580653457839,"mc":[{"id":"1.168224472","rc":[{"batb":[[0,1.78,53.77],[1,1.68,24.86],[2,1.55,420.5]],"batl":[[0,1.96,42.01],[1,1.94,0],[2,1.96,0]],"ltp":0.0,"tv":0.0,"id":5858055},{"batb":[[0,2.04,40.33],[1,2.02,26.91],[2,1.77,402.27]],"ltp":0.0,"tv":0.0,"id":7444998}]}]}
{"op":"mcm","clk":"1004115695","pt":1580653459251,"mc":[{"id":"1.168224472","rc":[{"batb":[[0,1.68,24.86],[1,1.55,420.5],[2,1.01,15.51]],"ltp":0.0,"tv":0.0,"id":5858055},{"batb":[[0,2.02,26.91],[1,1.77,402.27],[2,1.01,15.51]],"ltp":0.0,"tv":0.0,"id":7444998}]}]}
{"op":"mcm","clk":"1004116009","pt":1580653460649,"mc":[{"id":"1.168224472","rc":[{"batb":[[0,1.74,82.04],[1,1.72,102.99],[2,1.68,24.86]],"batl":[[0,1.98,50.56],[1,2,64.69]],"ltp":0.0,"tv":0.0,"id":5858055}]}]}
{"op":"mcm","clk":"1004118128","pt":1580653470780,"mc":[{"id":"1.168224472","rc":[{"batb":[[0,1.68,24.86],[1,1.55,420.5],[2,1.01,15.51]],"ltp":0.0,"tv":0.0,"id":5858055}]}]}
{"op":"mcm","clk":"1004118651","pt":1580653473384,"mc":[{"id":"1.168224472","rc":[{"batb":[[0,1.77,402.27],[1,1.01,15.51],[2,1.01,0]],"ltp":0.0,"tv":0.0,"id":7444998}]}]}
{"op":"mcm","clk":"1004119081","pt":1580653475287,"mc":[{"id":"1.168224472","rc":[{"batb":[[0,1.85,18.02],[1,1.77,20.77],[2,1.55,420.5]],"ltp":0.0,"tv":0.0,"id":5858055},{"batb":[[0,1.98,29.03],[1,1.77,402.27],[2,1.01,15.51]],"ltp":0.0,"tv":0.0,"id":7444998}]}]}
{"op":"mcm","clk":"1004119189","pt":1580653475776,"mc":[{"id":"1.168224472","rc":[{"batb":[[0,1.84,63.93],[1,1.82,85.24],[2,1.77,20.77]],"batl":[[0,2.02,62.12],[1,2.04,61.02]],"ltp":0.0,"tv":0.0,"id":5858055}]}]}
{"op":"mcm","clk":"1004121024","pt":1580653484275,"mc":[{"id":"1.168224472","rc":[{"batb":[[2,1.78,53.77]],"batl":[[0,1.92,75.49],[1,1.94,70.84],[2,1.96,42.01]],"ltp":0.0,"tv":0.0,"id":5858055},{"batb":[[0,2.14,23.05],[1,2.04,66.61],[2,1.98,29.03]],"batl":[[0,2.28,32.77]],"ltp":0.0,"tv":0.0,"id":7444998}]}]}
{"op":"mcm","clk":"1004121068","pt":1580653484480,"mc":[{"id":"1.168224472","rc":[{"batb":[[2,1.77,402.27]],"ltp":0.0,"tv":0.0,"id":7444998}]}]}
{"op":"mcm","clk":"1004123525","pt":1580653496188,"mc":[{"id":"1.168224472","rc":[{"batb":[[0,1.78,53.77],[1,1.67,25.1],[2,1.55,420.5]],"batl":[[0,1.96,42.01],[1,1.94,0],[2,1.96,0]],"ltp":0.0,"tv":0.0,"id":5858055},{"batb":[[0,2.04,66.61],[1,1.77,402.27],[2,1.01,15.51]],"ltp":0.0,"tv":0.0,"id":7444998}]}]}
{"op":"mcm","clk":"1004123742","pt":1580653497213,"mc":[{"id":"1.168224472","rc":[{"batb":[[0,1.67,25.1],[1,1.55,420.5],[2,1.01,15.51]],"ltp":0.0,"tv":0.0,"id":5858055},{"batb":[[0,2.04,26.28]],"ltp":0.0,"tv":0.0,"id":7444998}]}]}
{"op":"mcm","clk":"1004124167","pt":1580653499103,"mc":[{"id":"1.168224472","rc":[{"batb":[[0,1.75,56.37],[1,1.73,100.87],[2,1.67,25.1]],"batl":[[0,1.98,67.46],[1,2,64.68]],"ltp":0.0,"tv":0.0,"id":5858055}]}]}
{"op":"mcm","clk":"1004125750","pt":1580653506310,"mc":[{"id":"1.168224472","rc":[{"batb":[[2,1.7,59.65]],"batl":[[0,1.82,83.76],[1,1.84,83.39],[2,1.86,42.01]],"ltp":0.0,"tv":0.0,"id":5858055},{"batb":[[0,2.3,18.8],[1,2.14,36.13],[2,2.12,23.68]],"batl":[[0,2.42,29.41]],"ltp":0.0,"tv":0.0,"id":7444998}]}]}
{"op":"mcm","clk":"1004128245","pt":1580653517441,"mc":[{"id":"1.168224472","rc":[{"batb":[[0,1.51,36.19],[1,1.46,435.7],[2,1.01,15.51]],"ltp":0.0,"tv":0.0,"id":5858055},{"batb":[[0,2.12,23.68],[1,1.77,402.27],[2,1.01,15.51]],"ltp":0.0,"tv":0.0,"id":7444998}]}]}
{"op":"mcm","clk":"1004128885","pt":1580653520239,"mc":[{"id":"1.168224472","rc":[{"batb":[[0,1.58,88.24],[1,1.57,71.99],[2,1.52,35.72]],"batl":[[0,1.94,70.13],[1,1.96,68.7]],"ltp":0.0,"tv":0.0,"id":5858055},{"batb":[[1,2.1,24.08],[2,1.77,402.27]],"ltp":0.0,"tv":0.0,"id":7444998}]}]}
{"op":"mcm","clk":"1004128939","pt":1580653520455,"mc":[{"id":"1.168224472","rc":[{"batb":[[0,2.1,24.08],[1,1.77,402.27],[2,1.01,15.51]],"ltp":0.0,"tv":0.0,"id":7444998}]}]}
{"op":"mcm","clk":"1004131060","pt":1580653529975,"mc":[{"id":"1.168224472","rc":[{"batb":[[1,1.01,15.51],[2,1.01,0]],"ltp":0.0,"tv":0.0,"id":7444998}]}]}
{"op":"mcm","clk":"1004131658","pt":1580653532449,"mc":[{"id":"1.168224472","rc":[{"batb":[[1,1.57,145.09]],"batl":[[0,1.64,103.94],[1,1.65,59.38]],"ltp":0.0,"tv":0.0,"id":5858055},{"batb":[[0,2.68,12.51],[1,2.32,18.41],[2,2.1,24.08]],"batl":[[0,2.78,23.53]],"ltp":0.0,"tv":0.0,"id":7444998}]}]}
{"op":"mcm","clk":"1004131771","pt":1580653532935,"mc":[{"id":"1.168224472","rc":[{"batl":[[2,1.71,42.01]],"ltp":0.0,"tv":0.0,"id":5858055},{"batb":[[1,2.42,29.41],[2,2.32,18.41]],"ltp":0.0,"tv":0.0,"id":7444998}]}]}
{"op":"mcm","clk":"1004134246","pt":1580653544173,"mc":[{"id":"1.168224472","rc":[{"batb":[[0,1.57,73.1],[1,1.38,448.45],[2,1.34,62.08]],"batl":[[0,1.71,42.01],[1,1.65,0],[2,1.71,0]],"ltp":0.0,"tv":0.0,"id":5858055},{"batb":[[0,2.42,29.41],[1,2.32,18.41],[2,1.97,394.86]],"ltp":0.0,"tv":0.0,"id":7444998}]}]}
{"op":"mcm","clk":"1004134492","pt":1580653545288,"mc":[{"id":"1.168224472","rc":[{"batb":[[0,1.38,448.45],[1,1.34,62.08],[2,1.01,15.51]],"ltp":0.0,"tv":0.0,"id":5858055},{"batb":[[0,2.32,18.41],[1,1.97,394.86],[2,1.01,15.51]],"ltp":0.0,"tv":0.0,"id":7444998}]}]}
{"op":"mcm","clk":"1004135035","pt":1580653547573,"mc":[{"id":"1.168224472","rc":[{"batb":[[0,1.38,532.86],[1,1.37,127.73],[2,1.34,62.08]],"batl":[[0,1.81,96.35],[1,1.83,84.78]],"ltp":0.0,"tv":0.0,"id":5858055}]}]}
{"op":"mcm","clk":"1004138237","pt":1580653562394,"mc":[{"id":"1.168224472","rc":[{"batb":[[0,1.38,448.45],[1,1.34,62.08],[2,1.01,15.51]],"ltp":0.0,"tv":0.0,"id":5858055}]}]}
{"op":"mcm","clk":"1004138689","pt":1580653564321,"mc":[{"id":"1.168224472","rc":[{"batb":[[0,1.34,62.08],[1,1.01,15.51],[2,1.01,0]],"ltp":0.0,"tv":0.0,"id":5858055}]}]}
{"op":"mcm","clk":"1004138963","pt":1580653565422,"mc":[{"id":"1.168224472","rc":[{"batb":[[0,1.73,99.15],[1,1.71,105.12],[2,1.34,62.08]],"ltp":0.0,"tv":0.0,"id":5858055}]}]}
{"op":"mcm","clk":"1004139200","pt":1580653566440,"mc":[{"id":"1.168224472","rc":[{"batb":[[2,1.66,25.65]],"batl":[[2,1.85,42.01]],"ltp":0.0,"tv":0.0,"id":5858055},{"batb":[[1,2.18,35.29],[2,2.14,23.21]],"ltp":0.0,"tv":0.0,"id":7444998}]}]}
{"op":"mcm","clk":"1004139249","pt":1580653566613,"mc":[{"id":"1.168224472","rc":[{"batb":[[2,1.69,60.49]],"ltp":0.0,"tv":0.0,"id":5858055},{"batl":[[0,2.44,28.57]],"ltp":0.0,"tv":0.0,"id":7444998}]}]}
{"op":"mcm","clk":"1004141594","pt":1580653577365,"mc":[{"id":"1.168224472","rc":[{"batb":[[0,1.69,60.49],[1,1.66,25.65],[2,1.51,36.9]],"batl":[[0,1.85,42.01],[1,1.83,0],[2,1.85,0]],"ltp":0.0,"tv":0.0,"id":5858055}]}]}
{"op":"mcm","clk":"1004141712","pt":1580653577969,"mc":[{"id":"1.168224472","rc":[{"batb":[[1,1.51,36.9],[2,1.46,435.7]],"ltp":0.0,"tv":0.0,"id":5858055},{"batb":[[0,2.18,35.29],[1,2.14,23.21],[2,1.97,394.86]],"ltp":0.0,"tv":0.0,"id":7444998}]}]}
{"op":"mcm","clk":"1004142008","pt":1580653579371,"mc":[{"id":"1.168224472","rc":[{"batb":[[0,1.51,36.9],[1,1.46,435.7],[2,1.01,15.51]],"ltp":0.0,"tv":0.0,"id":5858055},{"batb":[[0,2.14,23.21],[1,1.97,394.86],[2,1.01,15.51]],"ltp":0.0,"tv":0.0,"id":7444998}]}]}
{"op":"mcm","clk":"1004142239","pt":1580653580367,"mc":[{"id":"1.168224472","rc":[{"batb":[[0,1.57,89.69],[1,1.56,73.75],[2,1.51,36.9]],"batl":[[0,1.93,79.74],[1,1.95,69.75]],"ltp":0.0,"tv":0.0,"id":5858055}]}]}
{"op":"mcm","clk":"1004142632","pt":1580653582059,"mc":[{"id":"1.168224472","rc":[{"batb":[[0,1.51,36.9],[1,1.46,435.7],[2,1.01,15.51]],"ltp":0.0,"tv":0.0,"id":5858055}]}]}
{"op":"mcm","clk":"1004143262","pt":1580653585062,"mc":[{"id":"1.168224472","rc":[{"batb":[[0,1.7,72.35],[1,1.68,111.67],[2,1.51,36.9]],"batl":[[0,1.77,94.3],[1,1.79,90.98]],"ltp":0.0,"tv":0.0,"id":5858055}]}]}
{"op":"mcm","clk":"1004143508","pt":1580653586174,"mc":[{"id":"1.168224472","rc":[{"batb":[[0,1.51,36.9],[1,1.46,435.7],[2,1.01,15.51]],"ltp":0.0,"tv":0.0,"id":5858055}]}]}
{"op":"mcm","clk":"1004144180","pt":1580653589168,"mc":[{"id":"1.168224472","rc":[{"batb":[[0,1.57,89.69],[1,1.56,73.75],[2,1.51,36.9]],"batl":[[0,1.93,79.74],[1,1.95,69.75]],"ltp":0.0,"tv":0.0,"id":5858055}]}]}
{"op":"mcm","clk":"1004145580","pt":1580653595399,"mc":[{"id":"1.168224472","rc":[{"batl":[[0,1.63,109.98],[1,1.64,60.61]],"ltp":0.0,"tv":0.0,"id":5858055},{"batb":[[0,2.72,12.04],[1,2.34,17.7],[2,2.18,225.58]],"ltp":0.0,"tv":0.0,"id":7444998}]}]}
{"op":"mcm","clk":"1004145771","pt":1580653596281,"mc":[{"id":"1.168224472","rc":[{"batb":[[1,1.56,148.53]],"batl":[[2,1.7,42.01]],"ltp":0.0,"tv":0.0,"id":5858055},{"batb":[[1,2.44,28.57],[2,2.34,17.7]],"batl":[[0,2.8,22.69]],"ltp":0.0,"tv":0.0,"id":7444998}]}]}
{"op":"mcm","clk":"1004145829","pt":1580653596602,"mc":[{"id":"1.168224472","rc":[{"batl":[[2,1.7,0]],"ltp":0.0,"tv":0.0,"id":5858055}]}]}
{"op":"mcm","clk":"1004146116","pt":1580653597888,"mc":[{"id":"1.168224472","rc":[{"batl":[[2,1.68,42.01]],"ltp":0.0,"tv":0.0,"id":5858055}]}]}
{"op":"mcm","clk":"1004147723","pt":1580653606320,"mc":[{"id":"1.168224472","rc":[{"batb":[[0,1.56,74.78],[1,1.51,36.9],[2,1.34,465.43]],"batl":[[0,1.68,42.01],[1,1.64,0],[2,1.68,0]],"ltp":0.0,"tv":0.0,"id":5858055}]}]}
{"op":"mcm","clk":"1004147928","pt":1580653607394,"mc":[{"id":"1.168224472","rc":[{"batb":[[0,1.34,465.43],[1,1.33,63.57],[2,1.01,15.51]],"ltp":0.0,"tv":0.0,"id":5858055},{"batb":[[0,2.34,17.7],[1,1.97,394.86],[2,1.01,15.51]],"ltp":0.0,"tv":0.0,"id":7444998}]}]}
{"op":"mcm","clk":"1004148312","pt":1580653609399,"mc":[{"id":"1.168224472","rc":[{"batb":[[0,1.37,123.26],[1,1.36,132.77],[2,1.34,465.43]],"batl":[[0,1.79,67.47],[1,1.81,87.89]],"ltp":0.0,"tv":0.0,"id":5858055}]}]}
{"op":"mcm","clk":"1004148750","pt":1580653611795,"mc":[{"id":"1.168224472","rc":[{"batb":[[0,1.34,465.43],[1,1.33,63.57],[2,1.01,15.51]],"ltp":0.0,"tv":0.0,"id":5858055}]}]}
{"op":"mcm","clk":"1004149286","pt":1580653614721,"mc":[{"id":"1.168224472","rc":[{"batb":[[0,1.52,139.46],[1,1.51,84.07],[2,1.34,465.43]],"batl":[[0,1.58,106.08],[1,1.59,67.71]],"ltp":0.0,"tv":0.0,"id":5858055}]}]}
{"op":"mcm","clk":"1004149694","pt":1580653616685,"mc":[{"id":"1.168224472","rc":[{"batb":[[0,1.34,465.43],[1,1.33,63.57],[2,1.01,15.51]],"ltp":0.0,"tv":0.0,"id":5858055}]}]}
{"op":"mcm","clk":"1004150405","pt":1580653620302,"mc":[{"id":"1.168224472","rc":[{"batb":[[0,1.37,125.78],[1,1.36,132.77],[2,1.34,465.43]],"batl":[[0,1.79,65.55],[1,1.81,87.88]],"ltp":0.0,"tv":0.0,"id":5858055}]}]}
{"op":"mcm","clk":"1004150745","pt":1580653622023,"mc":[{"id":"1.168224472","rc":[{"batb":[[2,1.33,63.57]],"ltp":0.0,"tv":0.0,"id":5858055},{"batb":[[1,1.01,15.51],[2,1.01,0]],"ltp":0.0,"tv":0.0,"id":7444998}]}]}
{"op":"mcm","clk":"1004151222","pt":1580653624404,"mc":[{"id":"1.168224472","rc":[{"batb":[[0,1.38,110.07],[1,1.37,125.78],[2,1.36,132.77]],"batl":[[0,1.41,116.44],[1,1.42,105.7]],"ltp":0.0,"tv":0.0,"id":5858055},{"batb":[[0,3.55,15.11],[1,2.76,11.57],[2,2.5,231.74]],"batl":[[0,3.65,15.12]],"ltp":0.0,"tv":0.0,"id":7444998}]}]}
{"op":"mcm","clk":"1004151352","pt":1580653625022,"mc":[{"id":"1.168224472","rc":[{"batl":[[2,1.48,42.01]],"ltp":0.0,"tv":0.0,"id":5858055},{"batb":[[1,3.1,19.32],[2,2.76,11.57]],"ltp":0.0,"tv":0.0,"id":7444998}]}]}
{"op":"mcm","clk":"1004154599","pt":1580653641360,"mc":[{"id":"1.168224472","rc":[{"batb":[[1,1.33,63.57],[2,1.22,523]],"batl":[[0,1.48,42.01],[1,1.42,0],[2,1.48,0]],"ltp":0.0,"tv":0.0,"id":5858055}]}]}
{"op":"mcm","clk":"1004154656","pt":1580653641678,"mc":[{"id":"1.168224472","rc":[{"batb":[[1,1.22,523],[2,1.14,171.61]],"ltp":0.0,"tv":0.0,"id":5858055},{"batb":[[0,3.1,19.32],[1,2.76,11.57],[2,2.42,381.73]],"ltp":0.0,"tv":0.0,"id":7444998}]}]}
{"op":"mcm","clk":"1004154984","pt":1580653643363,"mc":[{"id":"1.168224472","rc":[{"batb":[[0,1.14,171.61],[1,1.01,15.51],[2,1.14,0]],"ltp":0.0,"tv":0.0,"id":5858055},{"batb":[[0,2.76,11.57],[1,1.01,15.51],[2,2.42,0]],"ltp":0.0,"tv":0.0,"id":7444998}]}]}
{"op":"mcm","clk":"1004155155","pt":1580653644262,"mc":[{"id":"1.168224472","rc":[{"batb":[[0,1.15,107.26],[1,1.14,581.07],[2,1.01,15.51]],"batl":[[0,1.62,111.52],[1,1.63,61.92]],"ltp":0.0,"tv":0.0,"id":5858055}]}]}
{"op":"mcm","clk":"1004156483","pt":1580653650389,"mc":[{"id":"1.168224472","rc":[{"batb":[[0,1.14,171.61],[1,1.01,15.51],[2,1.01,0]],"ltp":0.0,"tv":0.0,"id":5858055}]}]}
{"op":"mcm","clk":"1004157076","pt":1580653653381,"mc":[{"id":"1.168224472","rc":[{"batb":[[0,1.56,96.39],[1,1.55,75.62],[2,1.14,171.61]],"ltp":0.0,"tv":0.0,"id":5858055}]}]}
{"op":"mcm","clk":"1004157260","pt":1580653654269,"mc":[{"id":"1.168224472","rc":[{"batb":[[2,1.49,38.16]],"batl":[[2,1.67,42.01]],"ltp":0.0,"tv":0.0,"id":5858055},{"batb":[[1,2.48,27.73],[2,2.38,17.07]],"ltp":0.0,"tv":0.0,"id":7444998}]}]}
{"op":"mcm","clk":"1004157488","pt":1580653655395,"mc":[{"id":"1.168224472","rc":[{"batb":[[2,1.54,77.3]],"ltp":0.0,"tv":0.0,"id":5858055},{"batl":[[0,2.84,22.69]],"ltp":0.0,"tv":0.0,"id":7444998}]}]}
{"op":"mcm","clk":"1004159029","pt":1580653663301,"mc":[{"id":"1.168224472","rc":[{"batb":[[0,1.34,465.43],[1,1.32,65.31],[2,1.01,15.51]],"ltp":0.0,"tv":0.0,"id":5858055},{"batb":[[0,2.38,17.07],[1,2.04,394.09],[2,1.01,15.51]],"ltp":0.0,"tv":0.0,"id":7444998}]}]}
{"op":"mcm","clk":"1004159540","pt":1580653665793,"mc":[{"id":"1.168224472","rc":[{"batb":[[0,1.36,177.85],[1,1.35,138.33],[2,1.34,465.43]],"batl":[[0,1.78,74.08],[1,1.8,89.43]],"ltp":0.0,"tv":0.0,"id":5858055}]}]}
{"op":"mcm","clk":"1004160149","pt":1580653668679,"mc":[{"id":"1.168224472","rc":[{"batb":[[0,1.34,465.43],[1,1.32,65.31],[2,1.01,15.51]],"ltp":0.0,"tv":0.0,"id":5858055}]}]}
{"op":"mcm","clk":"1004160486","pt":1580653670514,"mc":[{"id":"1.168224472","rc":[{"batb":[[0,1.32,65.31],[1,1.01,15.51],[2,1.01,0]],"ltp":0.0,"tv":0.0,"id":5858055},{"batb":[[1,1.01,15.51],[2,1.01,0]],"ltp":0.0,"tv":0.0,"id":7444998}]}]}
{"op":"mcm","clk":"1004160890","pt":1580653672405,"mc":[{"id":"1.168224472","rc":[{"batb":[[0,1.71,87.88],[1,1.69,109.44],[2,1.63,27.38]],"batl":[[0,1.78,74.08],[1,1.8,89.43],[2,1.83,42.01]],"ltp":0.0,"tv":0.0,"id":5858055},{"batb":[[1,2.22,33.61],[2,2.16,22.11]],"ltp":0.0,"tv":0.0,"id":7444998}]}]}
{"op":"mcm","clk":"1004161051","pt":1580653673224,"mc":[{"id":"1.168224472","rc":[{"batb":[[2,1.67,62.17]],"ltp":0.0,"tv":0.0,"id":5858055},{"batb":[[1,2.16,22.11],[2,1.01,15.51]],"ltp":0.0,"tv":0.0,"id":7444998}]}]}
{"op":"mcm","clk":"1004161399","pt":1580653675029,"mc":[{"id":"1.168224472","rc":[{"batb":[[1,2.2,34.45],[2,2.16,22.11]],"batl":[[0,2.48,27.73]],"ltp":0.0,"tv":0.0,"id":7444998}]}]}
{"op":"mcm","clk":"1004162236","pt":1580653678908,"mc":[{"id":"1.168224472","rc":[{"batb":[[0,1.71,59.23]],"batl":[[0,1.83,42.01],[1,1.8,0],[2,1.83,0]],"ltp":0.0,"tv":0.0,"id":5858055}]}]}
{"op":"mcm","clk":"1004162914","pt":1580653682135,"mc":[{"id":"1.168224472","rc":[{"batl":[[0,1.77,55.75],[1,1.79,91.24],[2,1.83,42.01]],"ltp":0.0,"tv":0.0,"id":5858055}]}]}
{"op":"mcm","clk":"1004163173","pt":1580653683348,"mc":[{"id":"1.168224472","rc":[{"batb":[[0,1.49,38.4],[1,1.44,436.18],[2,1.01,15.51]],"ltp":0.0,"tv":0.0,"id":5858055},{"batb":[[0,2.16,22.11],[1,1.86,398.62],[2,1.01,15.51]],"ltp":0.0,"tv":0.0,"id":7444998}]}]}
{"op":"mcm","clk":"1004163855","pt":1580653686396,"mc":[{"id":"1.168224472","rc":[{"batb":[[0,1.55,67.69],[1,1.54,77.53],[2,1.49,38.4]],"batl":[[0,1.9,87.47],[1,1.92,73.16]],"ltp":0.0,"tv":0.0,"id":5858055}]}]}
{"op":"mcm","clk":"1004164407","pt":1580653689247,"mc":[{"id":"1.168224472","rc":[{"batb":[[0,1.49,38.4],[1,1.44,436.18],[2,1.01,15.51]],"ltp":0.0,"tv":0.0,"id":5858055}]}]}
{"op":"mcm","clk":"1004164947","pt":1580653691427,"mc":[{"id":"1.168224472","rc":[{"batb":[[1,1.01,15.51],[2,1.01,0]],"ltp":0.0,"tv":0.0,"id":5858055}]}]}
{"op":"mcm","clk":"1004165147","pt":1580653692322,"mc":[{"id":"1.168224472","rc":[{"batb":[[0,1.82,60.65],[1,1.8,88.44],[2,1.76,54.61]],"batl":[[2,1.94,42.01]],"ltp":0.0,"tv":0.0,"id":5858055},{"batb":[[1,2.06,39.49],[2,1.86,398.62]],"batl":[[0,2.3,31.93]],"ltp":0.0,"tv":0.0,"id":7444998}]}]}
{"op":"mcm","clk":"1004165249","pt":1580653692819,"mc":[{"id":"1.168224472","rc":[{"batb":[[2,1.75,21.4]],"batl":[[2,1.94,0]],"ltp":0.0,"tv":0.0,"id":5858055},{"batb":[[2,1.9,16.6]],"ltp":0.0,"tv":0.0,"id":7444998}]}]}
{"op":"mcm","clk":"1004165727","pt":1580653695116,"mc":[{"id":"1.168224472","rc":[{"batb":[[2,1.77,53.77]],"batl":[[2,1.95,42.01]],"ltp":0.0,"tv":0.0,"id":5858055}]}]}
{"op":"mcm","clk":"1004166295","pt":1580653697943,"mc":[{"id":"1.168224472","rc":[{"batb":[[0,1.77,53.77],[1,1.75,21.4],[2,1.65,26.2]],"batl":[[0,1.95,42.01],[1,1.92,0],[2,1.95,0]],"ltp":0.0,"tv":0.0,"id":5858055}]}]}
{"op":"mcm","clk":"1004166943","pt":1580653700861,"mc":[{"id":"1.168224472","rc":[{"batb":[[0,1.81,92.15],[1,1.79,90.18],[2,1.77,53.77]],"batl":[[0,1.89,62.11],[1,1.91,74.4],[2,1.95,42.01]],"ltp":0.0,"tv":0.0,"id":5858055}]}]}
{"op":"mcm","clk":"1004170389","pt":1580653719279,"mc":[{"id":"1.168224472","rc":[{"batb":[[0,1.77,53.77],[1,1.75,21.4],[2,1.65,26.2]],"batl":[[0,1.95,42.01],[1,1.91,0],[2,1.95,0]],"ltp":0.0,"tv":0.0,"id":5858055}]}]}
{"op":"mcm","clk":"1004170536","pt":1580653719992,"mc":[{"id":"1.168224472","rc":[{"batb":[[0,1.65,26.2],[1,1.5,426.9],[2,1.01,15.51]],"ltp":0.0,"tv":0.0,"id":5858055},{"batb":[[0,1.9,16.6],[1,1.86,398.62],[2,1.01,15.51]],"ltp":0.0,"tv":0.0,"id":7444998}]}]}
{"op":"mcm","clk":"1004170973","pt":1580653722275,"mc":[{"id":"1.168224472","rc":[{"batb":[[0,1.71,74.71],[1,1.69,109.68],[2,1.65,26.2]],"batl":[[0,2.16,84.51],[1,2.18,50.42]],"ltp":0.0,"tv":0.0,"id":5858055}]}]}
{"op":"mcm","clk":"1004171148","pt":1580653723298,"mc":[{"id":"1.168224472","rc":[{"batb":[[2,1.66,25.89]],"ltp":0.0,"tv":0.0,"id":5858055}]}]}
{"op":"mcm","clk":"1004175171","pt":1580653743217,"mc":[{"id":"1.168224472","rc":[{"batl":[[0,1.78,87.5],[1,1.8,89.64]],"ltp":0.0,"tv":0.0,"id":5858055},{"batb":[[0,2.32,18.18],[1,2.08,25.02],[2,1.9,16.6]],"ltp":0.0,"tv":0.0,"id":7444998}]}]}
{"op":"mcm","clk":"1004175442","pt":1580653744415,"mc":[{"id":"1.168224472","rc":[{"batb":[[1,1.69,170.17]],"batl":[[2,1.86,42.01]],"ltp":0.0,"tv":0.0,"id":5858055},{"batb":[[1,2.16,36.13],[2,2.08,25.02]],"batl":[[0,2.46,28.57]],"ltp":0.0,"tv":0.0,"id":7444998}]}]}
{"op":"mcm","clk":"1004176981","pt":1580653751243,"mc":[{"id":"1.168224472","rc":[{"batb":[[0,1.69,60.49],[1,1.59,30.37],[2,1.5,426.9]],"batl":[[0,1.86,42.01],[1,1.8,0],[2,1.86,0]],"ltp":0.0,"tv":0.0,"id":5858055},{"batb":[[0,2.16,36.13],[1,2.08,25.02],[2,1.86,398.62]],"ltp":0.0,"tv":0.0,"id":7444998}]}]}
{"op":"mcm","clk":"1004177096","pt":1580653751728,"mc":[{"id":"1.168224472","rc":[{"batb":[[0,1.59,30.37],[1,1.5,426.9],[2,1.01,15.51]],"ltp":0.0,"tv":0.0,"id":5858055},{"batb":[[0,2.08,25.02],[1,1.86,398.62],[2,1.01,15.51]],"ltp":0.0,"tv":0.0,"id":7444998}]}]}
{"op":"mcm","clk":"1004177579","pt":1580653754138,"mc":[{"id":"1.168224472","rc":[{"batb":[[0,1.64,67.78],[1,1.63,62.78],[2,1.59,30.37]],"batl":[[0,1.95,72.87],[1,1.97,67.71]],"ltp":0.0,"tv":0.0,"id":5858055}]}]}
{"op":"mcm","clk":"1004179997","pt":1580653765326,"mc":[{"id":"1.168224472","rc":[{"batl":[[0,1.7,84.94],[1,1.72,104.15]],"ltp":0.0,"tv":0.0,"id":5858055},{"batb":[[0,2.48,15.11],[1,2.28,19.2],[2,2.08,25.02]],"ltp":0.0,"tv":0.0,"id":7444998}]}]}
{"op":"mcm","clk":"1004180222","pt":1580653766347,"mc":[{"id":"1.168224472","rc":[{"batb":[[2,1.86,398.62]],"ltp":0.0,"tv":0.0,"id":7444998}]}]}
{"op":"mcm","clk":"1004180290","pt":1580653766627,"mc":[{"id":"1.168224472","rc":[{"batb":[[2,1.62,67.22]],"batl":[[2,1.77,42.01]],"ltp":0.0,"tv":0.0,"id":5858055},{"batb":[[1,2.28,51.97]],"batl":[[0,2.6,26.05]],"ltp":0.0,"tv":0.0,"id":7444998}]}]}
{"op":"mcm","clk":"1004182872","pt":1580653779400,"mc":[{"id":"1.168224472","rc":[{"batb":[[0,1.62,67.22],[1,1.59,30.37],[2,1.53,34.54]],"batl":[[0,1.77,42.01],[1,1.72,0],[2,1.77,0]],"ltp":0.0,"tv":0.0,"id":5858055}]}]}
{"op":"mcm","clk":"1004182906","pt":1580653779599,"mc":[{"id":"1.168224472","rc":[{"batb":[[0,1.53,34.54],[1,1.4,451],[2,1.01,15.51]],"ltp":0.0,"tv":0.0,"id":5858055},{"batb":[[0,2.28,19.2],[1,1.86,398.62],[2,1.01,15.51]],"ltp":0.0,"tv":0.0,"id":7444998}]}]}
{"op":"mcm","clk":"1004183552","pt":1580653782391,"mc":[{"id":"1.168224472","rc":[{"batb":[[0,1.59,119.27],[1,1.58,70.7],[2,1.53,34.54]],"batl":[[0,1.8,85.74],[1,1.82,86.53]],"ltp":0.0,"tv":0.0,"id":5858055}]}]}
{"op":"mcm","clk":"1004183936","pt":1580653784430,"mc":[{"id":"1.168224472","rc":[{"batb":[[0,1.53,34.54],[1,1.01,15.51],[2,1.53,0]],"ltp":0.0,"tv":0.0,"id":5858055}]}]}
{"op":"mcm","clk":"1004184262","pt":1580653786087,"mc":[{"id":"1.168224472","rc":[{"batb":[[1,1.44,436.18],[2,1.01,15.51]],"ltp":0.0,"tv":0.0,"id":5858055}]}]}
{"op":"mcm","clk":"1004184514","pt":1580653787427,"mc":[{"id":"1.168224472","rc":[{"batb":[[0,1.65,111.04],[1,1.64,61.53],[2,1.53,34.54]],"batl":[[0,1.72,89.69],[1,1.74,100.17]],"ltp":0.0,"tv":0.0,"id":5858055}]}]}
{"op":"mcm","clk":"1004185646","pt":1580653793563,"mc":[{"id":"1.168224472","rc":[{"batb":[[0,1.53,34.54],[1,1.44,436.18],[2,1.01,15.51]],"ltp":0.0,"tv":0.0,"id":5858055}]}]}
{"op":"mcm","clk":"1004186204","pt":1580653796407,"mc":[{"id":"1.168224472","rc":[{"batb":[[0,1.59,119.27],[1,1.58,70.7],[2,1.53,34.54]],"batl":[[0,1.8,85.74],[1,1.82,86.53]],"ltp":0.0,"tv":0.0,"id":5858055}]}]}
{"op":"mcm","clk":"1004186701","pt":1580653798943,"mc":[{"id":"1.168224472","rc":[{"batb":[[0,1.53,34.54],[1,1.44,436.18],[2,1.01,15.51]],"ltp":0.0,"tv":0.0,"id":5858055}]}]}
{"op":"mcm","clk":"1004186976","pt":1580653800440,"mc":[{"id":"1.168224472","rc":[{"batb":[[1,1.01,15.51],[2,1.01,0]],"ltp":0.0,"tv":0.0,"id":5858055}]}]}
{"op":"mcm","clk":"1004187426","pt":1580653802448,"mc":[{"id":"1.168224472","rc":[{"batb":[[0,1.73,65.47],[1,1.71,105.25],[2,1.7,59.65]],"batl":[[2,1.86,42.01]],"ltp":0.0,"tv":0.0,"id":5858055},{"batb":[[1,2.16,36.13],[2,1.86,398.62]],"batl":[[0,2.44,28.57]],"ltp":0.0,"tv":0.0,"id":7444998}]}]}
{"op":"mcm","clk":"1004187514","pt":1580653802865,"mc":[{"id":"1.168224472","rc":[{"batb":[[2,2,28.01]],"ltp":0.0,"tv":0.0,"id":7444998}]}]}
{"op":"mcm","clk":"1004191074","pt":1580653821378,"mc":[{"id":"1.168224472","rc":[{"batb":[[0,1.7,59.65],[1,1.68,24.63],[2,1.59,30.29]],"batl":[[0,1.86,42.01],[1,1.82,0],[2,1.86,0]],"ltp":0.0,"tv":0.0,"id":5858055}]}]}
{"op":"mcm","clk":"1004191161","pt":1580653821866,"mc":[{"id":"1.168224472","rc":[{"batb":[[0,1.59,30.29],[1,1.5,426.9],[2,1.01,15.51]],"ltp":0.0,"tv":0.0,"id":5858055},{"batb":[[0,2,28.01],[1,1.86,398.62],[2,1.01,15.51]],"ltp":0.0,"tv":0.0,"id":7444998}]}]}
{"op":"mcm","clk":"1004191600","pt":1580653824362,"mc":[{"id":"1.168224472","rc":[{"batb":[[0,1.64,73.56],[1,1.63,62.82],[2,1.59,30.29]],"batl":[[0,2.02,88.89],[1,2.04,61.04]],"ltp":0.0,"tv":0.0,"id":5858055}]}]}
{"op":"mcm","clk":"1004191723","pt":1580653825045,"mc":[{"id":"1.168224472","rc":[{"batb":[[2,1.58,30.45]],"ltp":0.0,"tv":0.0,"id":5858055},{"batb":[[0,2,27.85]],"ltp":0.0,"tv":0.0,"id":7444998}]}]}
{"op":"mcm","clk":"1004192029","pt":1580653826677,"mc":[{"id":"1.168224472","rc":[{"batb":[[0,1.58,30.45],[1,1.5,426.9],[2,1.01,15.51]],"ltp":0.0,"tv":0.0,"id":5858055}]}]}
{"op":"mcm","clk":"1004192632","pt":1580653830153,"mc":[{"id":"1.168224472","rc":[{"batb":[[0,1.76,93.29],[1,1.74,99.23],[2,1.58,30.45]],"ltp":0.0,"tv":0.0,"id":5858055}]}]}
{"op":"mcm","clk":"1004193189","pt":1580653833282,"mc":[{"id":"1.168224472","rc":[{"batb":[[0,1.58,30.45],[1,1.5,426.9],[2,1.01,15.51]],"ltp":0.0,"tv":0.0,"id":5858055}]}]}
{"op":"mcm","clk":"1004193578","pt":1580653835581,"mc":[{"id":"1.168224472","rc":[{"batb":[[0,1.64,64.12],[1,1.63,62.81],[2,1.58,30.45]],"batl":[[0,2.02,96.56],[1,2.04,61.05]],"ltp":0.0,"tv":0.0,"id":5858055}]}]}
{"op":"mcm","clk":"1004193937","pt":1580653837673,"mc":[{"id":"1.168224472","rc":[{"batb":[[0,1.58,30.45],[1,1.5,426.9],[2,1.01,15.51]],"ltp":0.0,"tv":0.0,"id":5858055}]}]}
{"op":"mcm","clk":"1004194453","pt":1580653840411,"mc":[{"id":"1.168224472","rc":[{"batb":[[0,1.92,76.2],[1,1.9,74.33],[2,1.58,30.45]],"ltp":0.0,"tv":0.0,"id":5858055},{"batb":[[1,1.01,15.51],[2,1.01,0]],"ltp":0.0,"tv":0.0,"id":7444998}]}]}
{"op":"mcm","clk":"1004194630","pt":1580653841270,"mc":[{"id":"1.168224472","rc":[{"batb":[[2,1.87,17.47]],"ltp":0.0,"tv":0.0,"id":5858055},{"batb":[[1,1.66,25.97],[2,1.01,15.51]],"ltp":0.0,"tv":0.0,"id":7444998}]}]}
{"op":"mcm","clk":"1004195000","pt":1580653843435,"mc":[{"id":"1.168224472","rc":[{"batl":[[2,2.06,39.49]],"ltp":0.0,"tv":0.0,"id":5858055},{"batb":[[1,1.95,43.69],[2,1.67,409.76]],"batl":[[0,2.16,36.13]],"ltp":0.0,"tv":0.0,"id":7444998}]}]}
{"op":"mcm","clk":"1004197974","pt":1580653859037,"mc":[{"id":"1.168224472","rc":[{"batb":[[0,1.86,48.73],[1,1.68,24.94],[2,1.58,416.47]],"batl":[[0,2.06,39.49],[1,2.04,0],[2,2.06,0]],"ltp":0.0,"tv":0.0,"id":5858055},{"batb":[[0,1.95,43.69],[1,1.67,409.76],[2,1.66,25.97]],"ltp":0.0,"tv":0.0,"id":7444998}]}]}
{"op":"mcm","clk":"1004198069","pt":1580653859527,"mc":[{"id":"1.168224472","rc":[{"batb":[[0,1.68,24.94],[1,1.58,416.47],[2,1.01,15.51]],"ltp":0.0,"tv":0.0,"id":5858055},{"batb":[[0,1.67,409.76],[1,1.66,25.97],[2,1.01,15.51]],"ltp":0.0,"tv":0.0,"id":7444998}]}]}
{"op":"mcm","clk":"1004198392","pt":1580653861446,"mc":[{"id":"1.168224472","rc":[{"batb":[[0,1.72,84.02],[1,1.7,107.55],[2,1.68,24.94]],"batl":[[0,2.58,57.57],[1,2.62,61.8]],"ltp":0.0,"tv":0.0,"id":5858055}]}]}
{"op":"mcm","clk":"1004198499","pt":1580653862057,"mc":[{"id":"1.168224472","rc":[{"batb":[[2,1.67,25.18]],"ltp":0.0,"tv":0.0,"id":5858055},{"batb":[[1,1.66,25.73]],"ltp":0.0,"tv":0.0,"id":7444998}]}]}
{"op":"mcm","clk":"1004200656","pt":1580653873461,"mc":[{"id":"1.168224472","rc":[{"batb":[[0,1.67,25.18],[1,1.58,416.47],[2,1.01,15.51]],"ltp":0.0,"tv":0.0,"id":5858055}]}]}
{"op":"mcm","clk":"1004201330","pt":1580653876438,"mc":[{"id":"1.168224472","rc":[{"batb":[[1,1.01,15.51],[2,1.01,0]],"batl":[[0,2.6,26.05]],"ltp":0.0,"tv":0.0,"id":5858055},{"batb":[[0,1.66,25.73],[1,1.63,109.4],[2,1.62,131.18]],"batl":[[0,1.7,102.76],[1,1.72,103.4]],"ltp":0.0,"tv":0.0,"id":7444998}]}]}
{"op":"mcm","clk":"1004201523","pt":1580653877362,"mc":[{"id":"1.168224472","rc":[{"batb":[[0,2.32,18.33],[1,2.3,31.93],[2,1.89,16.76]],"ltp":0.0,"tv":0.0,"id":5858055},{"batl":[[2,1.77,42.01]],"ltp":0.0,"tv":0.0,"id":7444998}]}]}
{"op":"mcm","clk":"1004205486","pt":1580653896211,"mc":[{"id":"1.168224472","rc":[{"batb":[[1,1.63,62.34],[2,1.62,67.22]],"batl":[[0,1.7,78.18]],"ltp":0.0,"tv":0.0,"id":7444998}]}]}
{"op":"mcm","clk":"1004205865","pt":1580653898096,"mc":[{"id":"1.168224472","rc":[{"batb":[[0,2.3,31.93],[1,1.89,16.76],[2,1.86,398.62]],"ltp":0.0,"tv":0.0,"id":5858055},{"batb":[[0,1.62,67.22],[1,1.44,436.18],[2,1.3,72.86]],"batl":[[0,1.77,42.01],[1,1.72,0],[2,1.77,0]],"ltp":0.0,"tv":0.0,"id":7444998}]}]}
{"op":"mcm","clk":"1004206305","pt":1580653900195,"mc":[{"id":"1.168224472","rc":[{"batb":[[0,1.89,16.76],[1,1.01,15.51],[2,1.86,0]],"ltp":0.0,"tv":0.0,"id":5858055},{"batb":[[0,1.3,72.86],[1,1.01,15.51],[2,1.3,0]],"ltp":0.0,"tv":0.0,"id":7444998}]}]}
{"op":"mcm","clk":"1004206364","pt":1580653900495,"mc":[{"id":"1.168224472","rc":[{"batb":[[1,1.26,260.14],[2,1.25,211.5]],"batl":[[0,2.08,102.49],[1,2.1,56.11]],"ltp":0.0,"tv":0.0,"id":7444998}]}]}
{"op":"mcm","clk":"1004207022","pt":1580653903621,"mc":[{"id":"1.168224472","rc":[{"batb":[[1,1.01,15.51],[2,1.25,0]],"ltp":0.0,"tv":0.0,"id":7444998}]}]}
{"op":"mcm","clk":"1004207773","pt":1580653907286,"mc":[{"id":"1.168224472","rc":[{"batb":[[0,1.94,59.97],[1,1.92,71.88],[2,1.89,16.76]],"batl":[[0,2.04,103.58],[1,2.06,59.31]],"ltp":0.0,"tv":0.0,"id":5858055},{"batb":[[0,1.98,28.88],[1,1.64,26.83],[2,1.3,72.86]],"ltp":0.0,"tv":0.0,"id":7444998}]}]}
{"op":"mcm","clk":"1004207985","pt":1580653908409,"mc":[{"id":"1.168224472","rc":[{"batb":[[2,1.62,415.43]],"ltp":0.0,"tv":0.0,"id":7444998}]}]}
{"op":"mcm","clk":"1004208113","pt":1580653909007,"mc":[{"id":"1.168224472","rc":[{"batb":[[2,1.89,63.81]],"batl":[[2,2.1,37.81]],"ltp":0.0,"tv":0.0,"id":5858055},{"batb":[[1,1.91,45.37],[2,1.64,26.83]],"batl":[[0,2.14,36.13]],"ltp":0.0,"tv":0.0,"id":7444998}]}]}
{"op":"mcm","clk":"1004209904","pt":1580653918406,"mc":[{"id":"1.168224472","rc":[{"batb":[[0,1.89,47.05],[1,1.69,24.08],[2,1.62,415.43]],"batl":[[0,2.1,37.81],[1,2.06,0],[2,2.1,0]],"ltp":0.0,"tv":0.0,"id":5858055},{"batb":[[0,1.91,45.37],[1,1.64,26.83],[2,1.62,415.43]],"ltp":0.0,"tv":0.0,"id":7444998}]}]}
{"op":"mcm","clk":"1004210127","pt":1580653919528,"mc":[{"id":"1.168224472","rc":[{"batb":[[0,1.69,24.08],[1,1.62,415.43],[2,1.01,15.51]],"ltp":0.0,"tv":0.0,"id":5858055},{"batb":[[0,1.64,26.83],[1,1.62,415.43],[2,1.01,15.51]],"ltp":0.0,"tv":0.0,"id":7444998}]}]}
{"op":"mcm","clk":"1004210476","pt":1580653921295,"mc":[{"id":"1.168224472","rc":[{"batb":[[0,1.65,26.52],[1,1.64,26.83],[2,1.62,415.43]],"ltp":0.0,"tv":0.0,"id":7444998}]}]}
{"op":"mcm","clk":"1004210611","pt":1580653922014,"mc":[{"id":"1.168224472","rc":[{"batb":[[0,1.73,83],[1,1.71,105.39],[2,1.69,24.08]],"batl":[[0,2.6,50.33],[1,2.64,60.48]],"ltp":0.0,"tv":0.0,"id":5858055},{"batb":[[1,1.62,415.43],[2,1.01,15.51]],"ltp":0.0,"tv":0.0,"id":7444998}]}]}
{"op":"mcm","clk":"1004211877","pt":1580653927917,"mc":[{"id":"1.168224472","rc":[{"batb":[[0,1.69,24.08],[1,1.62,415.43],[2,1.01,15.51]],"ltp":0.0,"tv":0.0,"id":5858055}]}]}
{"op":"mcm","clk":"1004212180","pt":1580653929336,"mc":[{"id":"1.168224472","rc":[{"batb":[[1,1.01,15.51],[2,1.01,0]],"ltp":0.0,"tv":0.0,"id":5858055},{"batb":[[1,1.01,15.51],[2,1.01,0]],"ltp":0.0,"tv":0.0,"id":7444998}]}]}
{"op":"mcm","clk":"1004212494","pt":1580653931123,"mc":[{"id":"1.168224472","rc":[{"batb":[[1,1.62,112.78],[2,1.61,65.36]],"batl":[[0,1.69,106.34],[1,1.71,105.28]],"ltp":0.0,"tv":0.0,"id":7444998}]}]}
{"op":"mcm","clk":"1004212745","pt":1580653932423,"mc":[{"id":"1.168224472","rc":[{"batb":[[0,2.34,17.62],[1,1.91,16.29],[2,1.01,15.51]],"ltp":0.0,"tv":0.0,"id":5858055}]}]}
{"op":"mcm","clk":"1004212913","pt":1580653933335,"mc":[{"id":"1.168224472","rc":[{"batb":[[0,2.34,48.71],[2,1.86,398.62]],"batl":[[0,2.66,25.21]],"ltp":0.0,"tv":0.0,"id":5858055},{"batb":[[2,1.61,133.42]],"batl":[[2,1.75,42.01]],"ltp":0.0,"tv":0.0,"id":7444998}]}]}
{"op":"mcm","clk":"1004215289","pt":1580653946351,"mc":[{"id":"1.168224472","rc":[{"batb":[[1,1.61,68.06],[2,1.44,436.18]],"batl":[[0,1.75,42.01],[1,1.71,0],[2,1.75,0]],"ltp":0.0,"tv":0.0,"id":7444998}]}]}
{"op":"mcm","clk":"1004215421","pt":1580653947127,"mc":[{"id":"1.168224472","rc":[{"batb":[[0,2.34,31.09]],"ltp":0.0,"tv":0.0,"id":5858055},{"batb":[[0,1.61,68.06],[1,1.44,436.18],[2,1.29,73.88]],"ltp":0.0,"tv":0.0,"id":7444998}]}]}
{"op":"mcm","clk":"1004215517","pt":1580653947534,"mc":[{"id":"1.168224472","rc":[{"batb":[[0,1.91,16.29],[1,1.01,15.51],[2,1.86,0]],"ltp":0.0,"tv":0.0,"id":5858055},{"batb":[[0,1.29,73.88],[1,1.01,15.51],[2,1.29,0]],"ltp":0.0,"tv":0.0,"id":7444998}]}]}
{"op":"mcm","clk":"1004215843","pt":1580653949365,"mc":[{"id":"1.168224472","rc":[{"batb":[[1,1.26,187],[2,1.25,209.8]],"batl":[[0,2.04,54.08],[1,2.06,59.3]],"ltp":0.0,"tv":0.0,"id":7444998}]}]}
{"op":"mcm","clk":"1004217386","pt":1580653957979,"mc":[{"id":"1.168224472","rc":[{"batb":[[1,1.01,15.51],[2,1.25,0]],"ltp":0.0,"tv":0.0,"id":7444998}]}]}
{"op":"mcm","clk":"1004218215","pt":1580653962449,"mc":[{"id":"1.168224472","rc":[{"batb":[[0,1.91,61.66],[1,1.71,23.21],[2,1.01,15.51]],"batl":[[0,2.12,36.97]],"ltp":0.0,"tv":0.0,"id":5858055},{"batb":[[0,1.97,29.74],[1,1.89,47.05],[2,1.63,27.62]],"batl":[[0,2.1,37.81]],"ltp":0.0,"tv":0.0,"id":7444998}]}]}
{"op":"mcm","clk":"1004218290","pt":1580653962874,"mc":[{"id":"1.168224472","rc":[{"batb":[[2,1.62,415.43]],"ltp":0.0,"tv":0.0,"id":5858055}]}]}
{"op":"mcm","clk":"1004218546","pt":1580653964262,"mc":[{"id":"1.168224472","rc":[{"batb":[[0,1.95,73.27],[1,1.93,70.74],[2,1.91,61.66]],"batl":[[0,2.04,57.34],[1,2.06,59.32],[2,2.12,36.97]],"ltp":0.0,"tv":0.0,"id":5858055}]}]}
{"op":"mcm","clk":"1004221057","pt":1580653978213,"mc":[{"id":"1.168224472","rc":[{"batb":[[0,1.91,45.37],[1,1.71,23.21],[2,1.62,415.43]],"batl":[[0,2.12,36.97],[1,2.06,0],[2,2.12,0]],"ltp":0.0,"tv":0.0,"id":5858055},{"batb":[[0,1.89,47.05],[1,1.63,27.3],[2,1.62,415.43]],"ltp":0.0,"tv":0.0,"id":7444998}]}]}
{"op":"mcm","clk":"1004221359","pt":1580653979623,"mc":[{"id":"1.168224472","rc":[{"batb":[[0,1.71,23.21],[1,1.62,415.43],[2,1.01,15.51]],"ltp":0.0,"tv":0.0,"id":5858055},{"batb":[[0,1.63,27.3],[1,1.62,415.43],[2,1.01,15.51]],"ltp":0.0,"tv":0.0,"id":7444998}]}]}
{"op":"mcm","clk":"1004221696","pt":1580653981196,"mc":[{"id":"1.168224472","rc":[{"batb":[[0,1.74,82.01],[1,1.72,103.33],[2,1.71,23.21]],"batl":[[0,2.62,43.61],[1,2.66,59.23]],"ltp":0.0,"tv":0.0,"id":5858055}]}]}
{"op":"mcm","clk":"1004222201","pt":1580653983802,"mc":[{"id":"1.168224472","rc":[{"batb":[[0,1.71,23.21],[1,1.62,415.43],[2,1.01,15.51]],"ltp":0.0,"tv":0.0,"id":5858055}]}]}
{"op":"mcm","clk":"1004222732","pt":1580653986387,"mc":[{"id":"1.168224472","rc":[{"batb":[[1,1.01,15.51],[2,1.01,0]],"ltp":0.0,"tv":0.0,"id":5858055},{"batb":[[1,1.01,15.51],[2,1.01,0]],"ltp":0.0,"tv":0.0,"id":7444998}]}]}
{"op":"mcm","clk":"1004222805","pt":1580653986780,"mc":[{"id":"1.168224472","rc":[{"batb":[[0,1.74,82.01],[1,1.72,103.33],[2,1.71,23.21]],"batl":[[0,1.81,65.38],[1,1.83,85.21]],"ltp":0.0,"tv":0.0,"id":5858055}]}]}
{"op":"mcm","clk":"1004223109","pt":1580653988419,"mc":[{"id":"1.168224472","rc":[{"batb":[[0,2.24,20.3],[1,1.94,15.5],[2,1.01,15.51]],"ltp":0.0,"tv":0.0,"id":7444998}]}]}
{"op":"mcm","clk":"1004223129","pt":1580653988506,"mc":[{"id":"1.168224472","rc":[{"batb":[[1,1.72,161.3]],"batl":[[2,1.9,42.01]],"ltp":0.0,"tv":0.0,"id":5858055},{"batb":[[1,2.12,36.97],[2,1.94,15.5]],"batl":[[0,2.38,30.25]],"ltp":0.0,"tv":0.0,"id":7444998}]}]}
{"op":"mcm","clk":"1004225332","pt":1580653999400,"mc":[{"id":"1.168224472","rc":[{"batb":[[0,1.72,57.97],[1,1.59,29.82],[2,1.52,425.49]],"batl":[[0,1.9,42.01],[1,1.83,0],[2,1.9,0]],"ltp":0.0,"tv":0.0,"id":5858055},{"batb":[[0,2.12,36.97],[1,1.94,15.5],[2,1.74,404.28]],"ltp":0.0,"tv":0.0,"id":7444998}]}]}
{"op":"mcm","clk":"1004225349","pt":1580653999533,"mc":[{"id":"1.168224472","rc":[{"batb":[[0,1.59,29.82],[1,1.52,425.49],[2,1.01,15.51]],"ltp":0.0,"tv":0.0,"id":5858055},{"batb":[[0,1.94,15.5],[1,1.74,404.28],[2,1.01,15.51]],"ltp":0.0,"tv":0.0,"id":7444998}]}]}
{"op":"mcm","clk":"1004225871","pt":1580654002212,"mc":[{"id":"1.168224472","rc":[{"batb":[[0,1.63,116.37],[1,1.62,64.37],[2,1.59,29.82]],"batl":[[0,2.08,100.91],[1,2.1,56.12]],"ltp":0.0,"tv":0.0,"id":5858055}]}]}
{"op":"mcm","clk":"1004226915","pt":1580654007619,"mc":[{"id":"1.168224472","rc":[{"batb":[[0,1.59,29.82],[1,1.52,425.49],[2,1.01,15.51]],"ltp":0.0,"tv":0.0,"id":5858055}]}]}
{"op":"mcm","clk":"1004227453","pt":1580654010427,"mc":[{"id":"1.168224472","rc":[{"batb":[[1,1.01,15.51],[2,1.01,0]],"ltp":0.0,"tv":0.0,"id":5858055},{"batb":[[1,1.01,15.51],[2,1.01,0]],"ltp":0.0,"tv":0.0,"id":7444998}]}]}
{"op":"mcm","clk":"1004227631","pt":1580654011329,"mc":[{"id":"1.168224472","rc":[{"batb":[[0,1.93,15.66],[1,1.73,22.42],[2,1.59,29.82]],"ltp":0.0,"tv":0.0,"id":5858055},{"batb":[[0,1.94,73.78],[1,1.92,71.9],[2,1.61,28.72]],"batl":[[0,2.04,105.19],[1,2.06,59.3]],"ltp":0.0,"tv":0.0,"id":7444998}]}]}
{"op":"mcm","clk":"1004227689","pt":1580654011637,"mc":[{"id":"1.168224472","rc":[{"batb":[[2,1.01,15.51]],"ltp":0.0,"tv":0.0,"id":5858055}]}]}
{"op":"mcm","clk":"1004228016","pt":1580654013237,"mc":[{"id":"1.168224472","rc":[{"batb":[[1,1.91,45.37],[2,1.73,22.42]],"batl":[[0,2.14,36.13]],"ltp":0.0,"tv":0.0,"id":5858055},{"batb":[[2,1.89,47.05]],"batl":[[2,2.1,37.81]],"ltp":0.0,"tv":0.0,"id":7444998}]}]}
{"op":"mcm","clk":"1004231435","pt":1580654029877,"mc":[{"id":"1.168224472","rc":[{"batb":[[0,1.91,45.37],[1,1.73,22.42],[2,1.67,409.76]],"ltp":0.0,"tv":0.0,"id":5858055},{"batb":[[0,1.89,47.05],[1,1.61,28.72],[2,1.58,416.47]],"batl":[[0,2.1,37.81],[1,2.06,0],[2,2.1,0]],"ltp":0.0,"tv":0.0,"id":7444998}]}]}
{"op":"mcm","clk":"1004231791","pt":1580654031559,"mc":[{"id":"1.168224472","rc":[{"batb":[[0,1.73,22.42],[1,1.67,409.76],[2,1.01,15.51]],"ltp":0.0,"tv":0.0,"id":5858055},{"batb":[[0,1.61,28.72],[1,1.58,416.47],[2,1.01,15.51]],"ltp":0.0,"tv":0.0,"id":7444998}]}]}
{"op":"mcm","clk":"1004232143","pt":1580654033255,"mc":[{"id":"1.168224472","rc":[{"batb":[[1,1.6,110.01],[2,1.59,68.39]],"batl":[[0,2.32,44.03],[1,2.34,41.59]],"ltp":0.0,"tv":0.0,"id":7444998}]}]}
{"op":"mcm","clk":"1004233615","pt":1580654040270,"mc":[{"id":"1.168224472","rc":[{"batb":[[1,1.01,15.51],[2,1.01,0]],"ltp":0.0,"tv":0.0,"id":5858055}]}]}
{"op":"mcm","clk":"1004234035","pt":1580654042372,"mc":[{"id":"1.168224472","rc":[{"batl":[[0,1.66,67.38],[1,1.68,111.9]],"ltp":0.0,"tv":0.0,"id":7444998}]}]}
{"op":"mcm","clk":"1004234249","pt":1580654043251,"mc":[{"id":"1.168224472","rc":[{"batb":[[0,2.42,16.13],[1,2.38,30.25],[2,1.96,30.21]],"batl":[[0,2.72,24.37]],"ltp":0.0,"tv":0.0,"id":5858055},{"batb":[[2,1.59,138.97]],"batl":[[2,1.73,42.01]],"ltp":0.0,"tv":0.0,"id":7444998}]}]}
{"op":"mcm","clk":"1004238053","pt":1580654061407,"mc":[{"id":"1.168224472","rc":[{"batb":[[0,2.38,30.25],[1,1.96,30.21],[2,1.01,15.51]],"ltp":0.0,"tv":0.0,"id":5858055},{"batb":[[0,1.59,70.58],[1,1.28,77.97],[2,1.01,15.51]],"batl":[[0,1.73,42.01],[1,1.68,0],[2,1.73,0]],"ltp":0.0,"tv":0.0,"id":7444998}]}]}
{"op":"mcm","clk":"1004238126","pt":1580654061785,"mc":[{"id":"1.168224472","rc":[{"batb":[[0,1.96,30.21],[1,1.01,15.51],[2,1.01,0]],"ltp":0.0,"tv":0.0,"id":5858055},{"batb":[[0,1.28,77.97],[1,1.01,15.51],[2,1.01,0]],"ltp":0.0,"tv":0.0,"id":7444998}]}]}
{"op":"mcm","clk":"1004238470","pt":1580654063508,"mc":[{"id":"1.168224472","rc":[{"batb":[[1,1.26,90.63],[2,1.25,206.94]],"batl":[[0,2.02,99.68],[1,2.04,61]],"ltp":0.0,"tv":0.0,"id":7444998}]}]}
{"op":"mcm","clk":"1004238997","pt":1580654066088,"mc":[{"id":"1.168224472","rc":[{"batb":[[1,1.01,15.51],[2,1.25,0]],"ltp":0.0,"tv":0.0,"id":7444998}]}]}
{"op":"mcm","clk":"1004239886","pt":1580654070703,"mc":[{"id":"1.168224472","rc":[{"batb":[[0,2.04,394.09],[1,1.96,30.21],[2,1.01,15.51]],"ltp":0.0,"tv":0.0,"id":5858055},{"batb":[[0,1.34,465.43],[1,1.28,77.97],[2,1.01,15.51]],"ltp":0.0,"tv":0.0,"id":7444998}]}]}
{"op":"mcm","clk":"1004240158","pt":1580654072092,"mc":[{"id":"1.168224472","rc":[{"batb":[[0,1.96,30.21],[1,1.01,15.51],[2,1.01,0]],"ltp":0.0,"tv":0.0,"id":5858055},{"batb":[[0,1.28,77.97],[1,1.01,15.51],[2,1.01,0]],"ltp":0.0,"tv":0.0,"id":7444998}]}]}
{"op":"mcm","clk":"1004240500","pt":1580654073793,"mc":[{"id":"1.168224472","rc":[{"batb":[[1,1.26,79.59],[2,1.25,206.94]],"batl":[[0,2.02,104.3],[1,2.04,61]],"ltp":0.0,"tv":0.0,"id":7444998}]}]}
{"op":"mcm","clk":"1004245242","pt":1580654096428,"mc":[{"id":"1.168224472","rc":[{"batl":[[0,1.29,206.62],[1,1.3,156.74]],"ltp":0.0,"tv":0.0,"id":7444998}]}]}
{"op":"mcm","clk":"1004245491","pt":1580654097434,"mc":[{"id":"1.168224472","rc":[{"batb":[[0,4.5,11.76],[1,3.95,22.98],[2,3.15,20.61]],"batl":[[0,5.3,9.24]],"ltp":0.0,"tv":0.0,"id":5858055},{"trd":[[1.28,84.02]],"batb":[[0,1.28,35.96]],"batl":[[0,1.29,248.63]],"ltp":1.28,"tv":84.02,"id":7444998}],"tv":84.02}]}
{"op":"mcm","clk":"1004246106","pt":1580654100267,"mc":[{"id":"1.168224472","rc":[{"trd":[[1.28,109.23]],"batb":[[0,1.28,23.36]],"ltp":1.28,"tv":109.22,"id":7444998}],"tv":109.22}]}
{"op":"mcm","clk":"1004247157","pt":1580654105369,"mc":[{"id":"1.168224472","rc":[{"batb":[[1,4.1,22.03],[2,3.25,19.75]],"ltp":0.0,"tv":0.0,"id":5858055},{"batb":[[0,1.27,80.33]],"ltp":1.28,"tv":109.22,"id":7444998}]}]}
{"op":"mcm","clk":"1004265036","pt":1580654191046,"mc":[{"id":"1.168224472","rc":[{"batl":[[0,1.29,235.05]],"ltp":1.28,"tv":109.22,"id":7444998}]}]}
{"op":"mcm","clk":"1004267396","pt":1580654202783,"mc":[{"id":"1.168224472","rc":[{"batb":[[1,3.25,19.75],[2,2.62,379.26]],"ltp":0.0,"tv":0.0,"id":5858055},{"batb":[[0,1.23,168.04],[1,1.21,107.4],[2,1.18,549.72]],"batl":[[0,1.29,42.01],[1,1.3,0]],"ltp":1.28,"tv":109.22,"id":7444998}]}]}
{"op":"mcm","clk":"1004267626","pt":1580654203824,"mc":[{"id":"1.168224472","rc":[{"batb":[[0,3.25,19.75],[1,2.62,379.26],[2,1.01,15.51]],"ltp":0.0,"tv":0.0,"id":5858055},{"batb":[[0,1.21,107.4],[1,1.18,549.72],[2,1.01,15.51]],"ltp":1.28,"tv":109.22,"id":7444998}]}]}
{"op":"mcm","clk":"1004268025","pt":1580654205636,"mc":[{"id":"1.168224472","rc":[{"batb":[[1,1.2,271.91],[2,1.19,259.05]],"batl":[[0,1.41,173.78],[1,1.42,103.66]],"ltp":1.28,"tv":109.22,"id":7444998}]}]}
{"op":"mcm","clk":"1004269278","pt":1580654211428,"mc":[{"id":"1.168224472","rc":[{"batb":[[1,1.18,549.72],[2,1.01,15.51]],"ltp":1.28,"tv":109.22,"id":7444998}]}]}
{"op":"mcm","clk":"1004269561","pt":1580654212692,"mc":[{"id":"1.168224472","rc":[{"batb":[[1,1.01,15.51],[2,1.01,0]],"ltp":1.28,"tv":109.22,"id":7444998}]}]}
{"op":"mcm","clk":"1004269916","pt":1580654214320,"mc":[{"id":"1.168224472","rc":[{"batb":[[0,1.36,190.58],[1,1.35,136.71],[2,1.21,107.4]],"ltp":1.28,"tv":109.22,"id":7444998}]}]}
{"op":"mcm","clk":"1004270176","pt":1580654215408,"mc":[{"id":"1.168224472","rc":[{"batb":[[0,3.55,15.96],[1,3.25,19.75],[2,2.62,379.26]],"batl":[[0,4.1,13.44]],"ltp":0.0,"tv":0.0,"id":5858055},{"trd":[[1.39,84.02]],"batb":[[0,1.39,9.84],[1,1.36,190.58],[2,1.35,136.71]],"ltp":1.39,"tv":193.25,"id":7444998}],"tv":193.25}]}
{"op":"mcm","clk":"1004270877","pt":1580654218614,"mc":[{"id":"1.168224472","rc":[{"batl":[[0,4,13.44]],"ltp":0.0,"tv":0.0,"id":5858055},{"trd":[[1.39,102.51]],"batb":[[0,1.36,191.18],[1,1.35,136.71],[2,1.32,131.07]],"batl":[[0,1.4,42.01],[1,1.41,173.78],[2,1.42,103.66]],"ltp":1.39,"tv":211.73,"id":7444998}],"tv":211.73}]}
{"op":"mcm","clk":"1004272420","pt":1580654225948,"mc":[{"id":"1.168224472","rc":[{"batb":[[0,2.62,379.26],[1,2.58,14.71],[2,1.01,15.51]],"ltp":0.0,"tv":0.0,"id":5858055},{"batb":[[0,1.29,73.8],[1,1.23,516.48],[2,1.01,15.51]],"ltp":1.39,"tv":211.73,"id":7444998}]}]}
{"op":"mcm","clk":"1004272985","pt":1580654228862,"mc":[{"id":"1.168224472","rc":[{"batb":[[0,2.62,393.42],[1,1.01,15.51],[2,1.01,0]],"ltp":0.0,"tv":0.0,"id":5858055},{"batb":[[0,1.28,180.1],[1,1.27,186.97],[2,1.23,516.48]],"batl":[[0,1.6,67.6],[1,1.61,64.21]],"ltp":1.39,"tv":211.73,"id":7444998}]}]}
{"op":"mcm","clk":"1004273667","pt":1580654232316,"mc":[{"id":"1.168224472","rc":[{"batb":[[0,1.28,76.01],[1,1.23,516.48],[2,1.01,15.51]],"ltp":1.39,"tv":211.73,"id":7444998}]}]}
{"op":"mcm","clk":"1004274012","pt":1580654233901,"mc":[{"id":"1.168224472","rc":[{"batb":[[0,2.62,14.16]],"ltp":0.0,"tv":0.0,"id":5858055},{"batb":[[1,1.01,15.51],[2,1.01,0]],"ltp":1.39,"tv":211.73,"id":7444998}]}]}
{"op":"mcm","clk":"1004274313","pt":1580654235369,"mc":[{"id":"1.168224472","rc":[{"batb":[[0,1.55,81.35],[1,1.54,76.67],[2,1.28,76.01]],"ltp":1.39,"tv":211.73,"id":7444998}]}]}
{"op":"mcm","clk":"1004274541","pt":1580654236414,"mc":[{"id":"1.168224472","rc":[{"batb":[[1,2.12,25.41],[2,1.01,15.51]],"ltp":0.0,"tv":0.0,"id":5858055},{"batb":[[0,1.56,32.1],[1,1.55,81.35],[2,1.54,76.67]],"ltp":1.39,"tv":211.73,"id":7444998}]}]}
{"op":"mcm","clk":"1004274625","pt":1580654236855,"mc":[{"id":"1.168224472","rc":[{"batb":[[0,2.7,24.37],[1,2.62,14.16],[2,2.12,25.41]],"ltp":0.0,"tv":0.0,"id":5858055},{"batl":[[0,1.58,42.01],[1,1.6,67.6],[2,1.61,64.21]],"ltp":1.39,"tv":211.73,"id":7444998}]}]}
{"op":"mcm","clk":"1004275217","pt":1580654239862,"mc":[{"id":"1.168224472","rc":[{"batl":[[0,3,21]],"ltp":0.0,"tv":0.0,"id":5858055}]}]}
{"op":"mcm","clk":"1004276561","pt":1580654246040,"mc":[{"id":"1.168224472","rc":[{"batb":[[0,2.12,25.41],[1,1.97,394.86],[2,1.01,15.51]],"ltp":0.0,"tv":0.0,"id":5858055},{"batb":[[0,1.43,45.71],[1,1.38,448.45],[2,1.01,15.51]],"ltp":1.39,"tv":211.73,"id":7444998}]}]}
{"op":"mcm","clk":"1004277175","pt":1580654249065,"mc":[{"id":"1.168224472","rc":[{"batb":[[1,1.42,108.41],[2,1.41,110.74]],"batl":[[0,1.9,57.56],[1,1.92,72.6]],"ltp":1.39,"tv":211.73,"id":7444998}]}]}
{"op":"mcm","clk":"1004278074","pt":1580654253152,"mc":[{"id":"1.168224472","rc":[{"batb":[[1,1.01,15.51],[2,1.01,0]],"ltp":0.0,"tv":0.0,"id":5858055}]}]}
{"op":"mcm","clk":"1004278545","pt":1580654255380,"mc":[{"id":"1.168224472","rc":[{"batl":[[0,1.46,71.66],[1,1.47,90.66]],"ltp":1.39,"tv":211.73,"id":7444998}]}]}
{"op":"mcm","clk":"1004278612","pt":1580654255677,"mc":[{"id":"1.168224472","rc":[{"batb":[[0,3.05,23.29],[1,2.34,19.28],[2,1.01,15.51]],"ltp":0.0,"tv":0.0,"id":5858055}]}]}
{"op":"mcm","clk":"1004278919","pt":1580654257193,"mc":[{"id":"1.168224472","rc":[{"batb":[[0,3.15,19.32],[1,3.05,23.29],[2,2.34,19.28]],"batl":[[0,3.6,15.96]],"ltp":0.0,"tv":0.0,"id":5858055},{"batl":[[0,1.46,113.67]],"ltp":1.39,"tv":211.73,"id":7444998}]}]}
{"op":"mcm","clk":"1004280817","pt":1580654266178,"mc":[{"id":"1.168224472","rc":[{"batb":[[1,2.34,19.28],[2,2.22,384.52]],"ltp":0.0,"tv":0.0,"id":5858055},{"batb":[[0,1.38,110.07],[1,1.31,69.79],[2,1.28,485.89]],"batl":[[0,1.46,42.01],[1,1.47,0]],"ltp":1.39,"tv":211.73,"id":7444998}]}]}
{"op":"mcm","clk":"1004281265","pt":1580654268372,"mc":[{"id":"1.168224472","rc":[{"batb":[[0,2.34,19.28],[1,2.22,384.52],[2,1.01,15.51]],"ltp":0.0,"tv":0.0,"id":5858055},{"batb":[[0,1.31,69.79],[1,1.28,485.89],[2,1.01,15.51]],"batl":[[0,1.47,64.68],[1,1.48,87.47]],"ltp":1.39,"tv":211.73,"id":7444998}]}]}
{"op":"mcm","clk":"1004282165","pt":1580654272804,"mc":[{"id":"1.168224472","rc":[{"batb":[[0,1.47,71.79],[1,1.46,94.9],[2,1.31,69.79]],"batl":[[0,1.52,141.19],[1,1.53,76.96]],"ltp":1.39,"tv":211.73,"id":7444998}]}]}
{"op":"mcm","clk":"1004282625","pt":1580654275107,"mc":[{"id":"1.168224472","rc":[{"batb":[[0,1.31,69.79],[1,1.01,15.51],[2,1.31,0]],"ltp":1.39,"tv":211.73,"id":7444998}]}]}
{"op":"mcm","clk":"1004282988","pt":1580654276754,"mc":[{"id":"1.168224472","rc":[{"batb":[[0,1.31,547.3]],"ltp":1.39,"tv":211.73,"id":7444998}]}]}
{"op":"mcm","clk":"1004283276","pt":1580654278079,"mc":[{"id":"1.168224472","rc":[{"batb":[[1,1.3,138.91],[2,1.29,171.86]],"batl":[[0,1.75,60.97],[1,1.77,93.62]],"ltp":1.39,"tv":211.73,"id":7444998}]}]}
{"op":"mcm","clk":"1004284805","pt":1580654285435,"mc":[{"id":"1.168224472","rc":[{"batb":[[1,1.01,15.51],[2,1.01,0]],"ltp":0.0,"tv":0.0,"id":5858055},{"batb":[[0,1.31,69.79]],"ltp":1.39,"tv":211.73,"id":7444998}]}]}
{"op":"mcm","clk":"1004285022","pt":1580654286448,"mc":[{"id":"1.168224472","rc":[{"batb":[[0,3.85,13.3],[1,2.76,12.27],[2,2.34,19.28]],"ltp":0.0,"tv":0.0,"id":5858055},{"batl":[[0,1.33,78.3],[1,1.34,136.3]],"ltp":1.39,"tv":211.73,"id":7444998}]}]}
{"op":"mcm","clk":"1004285180","pt":1580654287141,"mc":[{"id":"1.168224472","rc":[{"batb":[[0,3.9,14.28],[1,3.85,13.3],[2,2.76,12.27]],"batl":[[0,4.6,10.92]],"ltp":0.0,"tv":0.0,"id":5858055},{"batl":[[1,1.34,178.31]],"ltp":1.39,"tv":211.73,"id":7444998}]}]}
{"op":"mcm","clk":"1004286772","pt":1580654294798,"mc":[{"id":"1.168224472","rc":[{"trd":[[1.31,3.36]],"batb":[[0,1.31,68.11]],"ltp":1.31,"tv":215.09,"id":7444998}],"tv":215.09}]}
{"op":"mcm","clk":"1004287668","pt":1580654299430,"mc":[{"id":"1.168224472","rc":[{"batb":[[1,1.27,155.44],[2,1.2,642.75]],"batl":[[0,1.34,42.01],[1,1.34,0]],"ltp":1.31,"tv":215.09,"id":7444998}]}]}
{"op":"mcm","clk":"1004287850","pt":1580654300251,"mc":[{"id":"1.168224472","rc":[{"batb":[[0,2.76,12.27],[1,2.52,381.46],[2,1.01,15.51]],"ltp":0.0,"tv":0.0,"id":5858055},{"batb":[[0,1.2,642.75],[1,1.01,15.51],[2,1.2,0]],"ltp":1.31,"tv":215.09,"id":7444998}]}]}
{"op":"mcm","clk":"1004288454","pt":1580654303445,"mc":[{"id":"1.168224472","rc":[{"batb":[[0,1.2,884.55],[1,1.19,288.47],[2,1.01,15.51]],"batl":[[0,1.56,61.54],[1,1.57,70.37]],"ltp":1.31,"tv":215.09,"id":7444998}]}]}
{"op":"mcm","clk":"1004288891","pt":1580654305630,"mc":[{"id":"1.168224472","rc":[{"batb":[[1,1.01,15.51],[2,1.01,0]],"ltp":0.0,"tv":0.0,"id":5858055},{"batb":[[0,1.2,353.69]],"ltp":1.31,"tv":215.09,"id":7444998}]}]}
{"op":"mcm","clk":"1004289190","pt":1580654307157,"mc":[{"id":"1.168224472","rc":[{"batl":[[0,1.23,220.09],[1,1.24,203.47]],"ltp":1.31,"tv":215.09,"id":7444998}]}]}
{"op":"mcm","clk":"1004289315","pt":1580654307862,"mc":[{"id":"1.168224472","rc":[{"batb":[[0,5.1,13.53],[1,3.8,13.85],[2,1.01,15.51]],"ltp":0.0,"tv":0.0,"id":5858055},{"batb":[[2,1.14,163.66]],"ltp":1.31,"tv":215.09,"id":7444998}]}]}
{"op":"mcm","clk":"1004289479","pt":1580654308712,"mc":[{"id":"1.168224472","rc":[{"batb":[[0,5.2,9.24],[1,5.1,13.53],[2,3.8,13.85]],"batl":[[0,6.2,7.56]],"ltp":0.0,"tv":0.0,"id":5858055},{"batb":[[1,1.19,456.51]],"batl":[[1,1.24,245.48]],"ltp":1.31,"tv":215.09,"id":7444998}]}]}
{"op":"mcm","clk":"1004290948","pt":1580654316073,"mc":[{"id":"1.168224472","rc":[{"batb":[[0,3.8,13.85],[1,2.9,375.84],[2,1.01,15.51]],"ltp":0.0,"tv":0.0,"id":5858055},{"batb":[[0,1.14,163.66],[1,1.13,629.97],[2,1.01,15.51]],"ltp":1.31,"tv":215.09,"id":7444998}]}]}
{"op":"mcm","clk":"1004291417","pt":1580654318529,"mc":[{"id":"1.168224472","rc":[{"batb":[[0,1.15,219.65],[1,1.14,498.71],[2,1.13,629.97]],"batl":[[0,1.34,89.07],[1,1.35,131.35]],"ltp":1.31,"tv":215.09,"id":7444998}]}]}
{"op":"mcm","clk":"1004292064","pt":1580654321866,"mc":[{"id":"1.168224472","rc":[{"batb":[[1,1.01,15.51],[2,1.01,0]],"ltp":0.0,"tv":0.0,"id":5858055},{"batb":[[2,1.01,15.51]],"ltp":1.31,"tv":215.09,"id":7444998}]}]}
{"op":"mcm","clk":"1004292306","pt":1580654323078,"mc":[{"id":"1.168224472","rc":[{"batl":[[0,1.17,184.15],[1,1.18,284.49]],"ltp":1.31,"tv":215.09,"id":7444998}]}]}
{"op":"mcm","clk":"1004292419","pt":1580654323680,"mc":[{"id":"1.168224472","rc":[{"batb":[[0,6.6,15.19],[1,5.9,19.83],[2,1.01,15.51]],"ltp":0.0,"tv":0.0,"id":5858055},{"batb":[[2,1.11,218.26]],"ltp":1.31,"tv":215.09,"id":7444998}]}]}
{"op":"mcm","clk":"1004292573","pt":1580654324548,"mc":[{"id":"1.168224472","rc":[{"batb":[[0,6.6,21.91]],"batl":[[0,8,5.88]],"ltp":0.0,"tv":0.0,"id":5858055},{"batb":[[1,1.14,666.75]],"batl":[[1,1.18,326.5]],"ltp":1.31,"tv":215.09,"id":7444998}]}]}
{"op":"mcm","clk":"1004292842","pt":1580654325962,"mc":[{"id":"1.168224472","rc":[{"batb":[[2,3.15,373.59]],"ltp":0.0,"tv":0.0,"id":5858055}]}]}
{"op":"mcm","clk":"1004297959","pt":1580654351899,"mc":[{"id":"1.168224472","rc":[{"batb":[[0,5.9,19.83],[1,3.15,373.59],[2,1.01,15.51]],"ltp":0.0,"tv":0.0,"id":5858055},{"batb":[[0,1.11,218.26],[1,1.09,779.05],[2,1.01,15.51]],"ltp":1.31,"tv":215.09,"id":7444998}]}]}
{"op":"mcm","clk":"1004298666","pt":1580654355229,"mc":[{"id":"1.168224472","rc":[{"batb":[[0,1.12,100.91],[1,1.11,687.42],[2,1.09,779.05]],"batl":[[0,1.19,88.75],[1,1.2,255.55]],"ltp":1.31,"tv":215.09,"id":7444998}]}]}
{"op":"mcm","clk":"1004300447","pt":1580654363647,"mc":[{"id":"1.168224472","rc":[{"batb":[[0,1.11,218.26],[1,1.09,779.05],[2,1.01,15.51]],"ltp":1.31,"tv":215.09,"id":7444998}]}]}
{"op":"mcm","clk":"1004300820","pt":1580654365442,"mc":[{"id":"1.168224472","rc":[{"batb":[[1,1.01,15.51],[2,1.01,0]],"ltp":1.31,"tv":215.09,"id":7444998}]}]}
{"op":"mcm","clk":"1004301070","pt":1580654366655,"mc":[{"id":"1.168224472","rc":[{"batb":[[0,1.17,239.79],[1,1.16,304.52],[2,1.11,218.26]],"ltp":1.31,"tv":215.09,"id":7444998}]}]}
{"op":"mcm","clk":"1004301307","pt":1580654367838,"mc":[{"id":"1.168224472","rc":[{"batb":[[1,5.4,11.88],[2,3.15,373.59]],"ltp":0.0,"tv":0.0,"id":5858055},{"batb":[[0,1.17,378.27],[2,1.14,171.84]],"ltp":1.31,"tv":215.09,"id":7444998}]}]}
{"op":"mcm","clk":"1004301621","pt":1580654369430,"mc":[{"id":"1.168224472","rc":[{"batb":[[0,5.9,28.23]],"batl":[[0,7.2,6.72]],"ltp":0.0,"tv":0.0,"id":5858055},{"batl":[[1,1.2,297.56]],"ltp":1.31,"tv":215.09,"id":7444998}]}]}
{"op":"mcm","clk":"1004303310","pt":1580654377262,"mc":[{"id":"1.168224472","rc":[{"batl":[[0,1.2,297.56],[1,1.2,0]],"ltp":1.31,"tv":215.09,"id":7444998}]}]}
{"op":"mcm","clk":"1004303902","pt":1580654380251,"mc":[{"id":"1.168224472","rc":[{"batl":[[0,1.2,376.53],[1,1.21,192.04]],"ltp":1.31,"tv":215.09,"id":7444998}]}]}
{"op":"mcm","clk":"1004304082","pt":1580654381158,"mc":[{"id":"1.168224472","rc":[{"batb":[[0,1.17,138.48],[1,1.14,171.84],[2,1.11,684.32]],"batl":[[0,1.2,42.01],[1,1.21,105.81]],"ltp":1.31,"tv":215.09,"id":7444998}]}]}
{"op":"mcm","clk":"1004304291","pt":1580654382143,"mc":[{"id":"1.168224472","rc":[{"batb":[[0,5.4,11.88],[1,3.15,373.59],[2,1.01,15.51]],"ltp":0.0,"tv":0.0,"id":5858055},{"batb":[[0,1.14,171.84],[1,1.11,684.32],[2,1.01,15.51]],"batl":[[0,1.21,105.81],[1,1.21,0]],"ltp":1.31,"tv":215.09,"id":7444998}]}]}
{"op":"mcm","clk":"1004304759","pt":1580654384385,"mc":[{"id":"1.168224472","rc":[{"batb":[[0,1.14,538.59],[1,1.13,190.88],[2,1.11,684.32]],"batl":[[1,1.22,228.01]],"ltp":1.31,"tv":215.09,"id":7444998}]}]}
{"op":"mcm","clk":"1004305131","pt":1580654386397,"mc":[{"id":"1.168224472","rc":[{"batb":[[0,1.14,171.84],[1,1.11,684.32],[2,1.01,15.51]],"ltp":1.31,"tv":215.09,"id":7444998}]}]}
{"op":"mcm","clk":"1004305801","pt":1580654389360,"mc":[{"id":"1.168224472","rc":[{"batb":[[0,1.16,408.04],[1,1.15,139.53],[2,1.14,171.84]],"batl":[[0,1.19,247.54],[1,1.2,249.67]],"ltp":1.31,"tv":215.09,"id":7444998}]}]}
{"op":"mcm","clk":"1004306378","pt":1580654392376,"mc":[{"id":"1.168224472","rc":[{"batb":[[0,1.14,171.84],[1,1.11,684.32],[2,1.01,15.51]],"ltp":1.31,"tv":215.09,"id":7444998}]}]}
{"op":"mcm","clk":"1004306948","pt":1580654395399,"mc":[{"id":"1.168224472","rc":[{"batb":[[0,1.14,538.59],[1,1.13,190.88],[2,1.11,684.32]],"batl":[[0,1.21,105.81],[1,1.22,228.01]],"ltp":1.31,"tv":215.09,"id":7444998}]}]}
{"op":"mcm","clk":"1004310535","pt":1580654412792,"mc":[{"id":"1.168224472","rc":[{"batb":[[0,1.14,171.84],[1,1.11,684.32],[2,1.01,15.51]],"ltp":1.31,"tv":215.09,"id":7444998}]}]}
{"op":"mcm","clk":"1004311112","pt":1580654415391,"mc":[{"id":"1.168224472","rc":[{"batb":[[1,1.01,15.51],[2,1.01,0]],"ltp":1.31,"tv":215.09,"id":7444998}]}]}
{"op":"mcm","clk":"1004311190","pt":1580654415824,"mc":[{"id":"1.168224472","rc":[{"batb":[[0,1.19,153.82],[1,1.18,303],[2,1.14,171.84]],"ltp":1.31,"tv":215.09,"id":7444998}]}]}
{"op":"mcm","clk":"1004311452","pt":1580654416987,"mc":[{"id":"1.168224472","rc":[{"batb":[[1,5.2,13.22],[2,3.15,373.59]],"ltp":0.0,"tv":0.0,"id":5858055},{"batb":[[0,1.19,275.54],[2,1.16,141.71]],"ltp":1.31,"tv":215.09,"id":7444998}]}]}
{"op":"mcm","clk":"1004311834","pt":1580654418832,"mc":[{"id":"1.168224472","rc":[{"batb":[[0,5.6,8.4],[1,5.4,11.88],[2,5.2,13.22]],"batl":[[0,6.8,6.72]],"ltp":0.0,"tv":0.0,"id":5858055},{"batb":[[2,1.17,168.04]],"ltp":1.31,"tv":215.09,"id":7444998}]}]}
{"op":"mcm","clk":"1004314721","pt":1580654433351,"mc":[{"id":"1.168224472","rc":[{"batb":[[1,5.2,13.22],[2,3.15,373.59]],"ltp":0.0,"tv":0.0,"id":5858055},{"batb":[[0,1.17,168.04],[1,1.16,141.71],[2,1.13,629.97]],"ltp":1.31,"tv":215.09,"id":7444998}]}]}
{"op":"mcm","clk":"1004314824","pt":1580654433846,"mc":[{"id":"1.168224472","rc":[{"batb":[[0,5.2,13.22],[1,3.15,373.59],[2,1.01,15.51]],"ltp":0.0,"tv":0.0,"id":5858055},{"batb":[[0,1.16,141.71],[1,1.13,629.97],[2,1.01,15.51]],"ltp":1.31,"tv":215.09,"id":7444998}]}]}
{"op":"mcm","clk":"1004315337","pt":1580654436329,"mc":[{"id":"1.168224472","rc":[{"batb":[[0,1.17,179.09],[1,1.16,489.82],[2,1.13,629.97]],"batl":[[0,1.23,259.83],[1,1.24,201.72]],"ltp":1.31,"tv":215.09,"id":7444998}]}]}
{"op":"mcm","clk":"1004315769","pt":1580654438257,"mc":[{"id":"1.168224472","rc":[{"batb":[[0,1.16,141.71],[1,1.13,629.97],[2,1.01,15.51]],"ltp":1.31,"tv":215.09,"id":7444998}]}]}
{"op":"mcm","clk":"1004316413","pt":1580654441352,"mc":[{"id":"1.168224472","rc":[{"batb":[[0,1.2,195.12],[1,1.19,285.98],[2,1.16,141.71]],"ltp":1.31,"tv":215.09,"id":7444998}]}]}
{"op":"mcm","clk":"1004316563","pt":1580654442071,"mc":[{"id":"1.168224472","rc":[{"batb":[[1,5,14.32],[2,3.15,373.59]],"ltp":0.0,"tv":0.0,"id":5858055},{"batb":[[0,1.2,308.58],[1,1.19,408.17],[2,1.13,629.97]],"ltp":1.31,"tv":215.09,"id":7444998}]}]}
{"op":"mcm","clk":"1004316775","pt":1580654443032,"mc":[{"id":"1.168224472","rc":[{"batb":[[0,5.4,9.24],[1,5.2,13.22],[2,5,14.32]],"batl":[[0,6.4,7.56]],"ltp":0.0,"tv":0.0,"id":5858055},{"batb":[[2,1.18,168.04]],"batl":[[0,1.23,301.84]],"ltp":1.31,"tv":215.09,"id":7444998}]}]}
{"op":"mcm","clk":"1004319360","pt":1580654455118,"mc":[{"id":"1.168224472","rc":[{"batb":[[1,5,14.32],[2,3.15,373.59]],"ltp":0.0,"tv":0.0,"id":5858055},{"batb":[[0,1.19,307.7],[1,1.18,168.04],[2,1.13,629.97]],"batl":[[0,1.23,166.35]],"ltp":1.31,"tv":215.09,"id":7444998}]}]}
{"op":"mcm","clk":"1004319617","pt":1580654456239,"mc":[{"id":"1.168224472","rc":[{"batb":[[0,5,14.32],[1,3.15,373.59],[2,1.01,15.51]],"ltp":0.0,"tv":0.0,"id":5858055},{"batb":[[1,1.13,629.97],[2,1.01,15.51]],"batl":[[0,1.23,124.34]],"ltp":1.31,"tv":215.09,"id":7444998}]}]}
{"op":"mcm","clk":"1004319998","pt":1580654458135,"mc":[{"id":"1.168224472","rc":[{"batb":[[1,1.18,304.29],[2,1.13,629.97]],"ltp":1.31,"tv":215.09,"id":7444998}]}]}
{"op":"mcm","clk":"1004320311","pt":1580654459733,"mc":[{"id":"1.168224472","rc":[{"batb":[[0,1.19,122.19],[1,1.13,629.97],[2,1.01,15.51]],"ltp":1.31,"tv":215.09,"id":7444998}]}]}
{"op":"mcm","clk":"1004320633","pt":1580654461347,"mc":[{"id":"1.168224472","rc":[{"batl":[[0,1.2,1000],[1,1.23,124.34],[2,1.24,201.72]],"ltp":1.31,"tv":215.09,"id":7444998}]}]}
{"op":"mcm","clk":"1004321091","pt":1580654463329,"mc":[{"id":"1.168224472","rc":[{"batb":[[1,3.65,15.34],[2,3.15,373.59]],"ltp":0.0,"tv":0.0,"id":5858055},{"trd":[[1.2,907.64]],"batb":[[1,1.15,158.23],[2,1.13,629.97]],"batl":[[0,1.2,546.18]],"ltp":1.2,"tv":1122.74,"id":7444998}],"tv":1122.74}]}
{"op":"mcm","clk":"1004321137","pt":1580654463544,"mc":[{"id":"1.168224472","rc":[{"batb":[[0,1.15,158.23],[1,1.13,629.97],[2,1.01,15.51]],"ltp":1.2,"tv":1122.74,"id":7444998}]}]}
{"op":"mcm","clk":"1004321358","pt":1580654464633,"mc":[{"id":"1.168224472","rc":[{"batb":[[0,5.2,9.24],[1,5,14.32],[2,3.65,15.34]],"batl":[[0,6.2,7.56]],"ltp":0.0,"tv":0.0,"id":5858055},{"batl":[[1,1.23,166.35]],"ltp":1.2,"tv":1122.74,"id":7444998}]}]}
{"op":"mcm","clk":"1004321668","pt":1580654466157,"mc":[{"id":"1.168224472","rc":[{"trd":[[1.2,1347.6]],"batb":[[0,1.19,291.24],[1,1.15,158.23],[2,1.13,629.97]],"batl":[[0,1.2,326.2],[1,1.23,290.37]],"ltp":1.2,"tv":1562.7,"id":7444998}],"tv":1562.7}]}
{"op":"mcm","clk":"1004321718","pt":1580654466473,"mc":[{"id":"1.168224472","rc":[{"batl":[[1,1.23,264.38],[2,1.24,0]],"ltp":1.2,"tv":1562.7,"id":7444998}]}]}
{"op":"mcm","clk":"1004322474","pt":1580654469734,"mc":[{"id":"1.168224472","rc":[{"trd":[[1.2,1626.42]],"batl":[[0,1.2,186.79],[1,1.22,105.54],[2,1.23,264.38]],"ltp":1.2,"tv":1841.52,"id":7444998}],"tv":1841.52}]}
{"op":"mcm","clk":"1004322914","pt":1580654471751,"mc":[{"id":"1.168224472","rc":[{"batb":[[0,5.2,22.46],[1,3.75,14.24],[2,3.15,373.59]],"ltp":0.0,"tv":0.0,"id":5858055},{"trd":[[1.2,1853.49]],"batb":[[1,1.14,166.33]],"batl":[[0,1.2,73.26]],"ltp":1.2,"tv":2068.58,"id":7444998}],"tv":2068.58}]}
{"op":"mcm","clk":"1004323208","pt":1580654473148,"mc":[{"id":"1.168224472","rc":[{"trd":[[1.2,2000.01]],"batl":[[0,1.22,155.79],[1,1.23,264.38],[2,1.23,0]],"ltp":1.2,"tv":2215.1,"id":7444998}],"tv":2215.1}]}
{"op":"mcm","clk":"1004323838","pt":1580654476180,"mc":[{"id":"1.168224472","rc":[{"batb":[[0,1.19,353.31],[1,1.18,181.45],[2,1.14,166.33]],"batl":[[0,1.22,182.2]],"ltp":1.2,"tv":2215.1,"id":7444998}]}]}
{"op":"mcm","clk":"1004324606","pt":1580654479682,"mc":[{"id":"1.168224472","rc":[{"batb":[[0,5.4,12.2],[1,5.2,9.24],[2,3.85,13.14]],"ltp":0.0,"tv":0.0,"id":5858055},{"batb":[[0,1.19,473.14],[2,1.13,805.27]],"ltp":1.2,"tv":2215.1,"id":7444998}]}]}
{"op":"mcm","clk":"1004331260","pt":1580654511280,"mc":[{"id":"1.168224472","rc":[{"batb":[[0,1.19,472.99],[2,1.13,805.12]],"ltp":1.2,"tv":2215.1,"id":7444998}]}]}
{"op":"mcm","clk":"1004336257","pt":1580654535023,"mc":[{"id":"1.168224472","rc":[{"batb":[[1,3.85,13.14],[2,3.15,373.59]],"ltp":0.0,"tv":0.0,"id":5858055}]}]}
{"op":"mcm","clk":"1004336469","pt":1580654535889,"mc":[{"id":"1.168224472","rc":[{"trd":[[1.19,888.01]],"batb":[[0,1.19,28.98]],"ltp":1.19,"tv":3103.11,"id":7444998}],"tv":3103.11}]}
{"op":"mcm","clk":"1004336937","pt":1580654538003,"mc":[{"id":"1.168224472","rc":[{"batb":[[1,5.3,9.24],[2,3.85,13.14]],"ltp":0.0,"tv":0.0,"id":5858055}]}]}
{"op":"mcm","clk":"1004337225","pt":1580654539306,"mc":[{"id":"1.168224472","rc":[{"batb":[[0,1.19,256.89],[1,1.18,307.91]],"batl":[[0,1.22,304.65]],"ltp":1.19,"tv":3103.11,"id":7444998}]}]}
{"op":"mcm","clk":"1004337320","pt":1580654539752,"mc":[{"id":"1.168224472","rc":[{"batb":[[0,5.3,9.24],[1,3.85,13.14],[2,3.15,373.59]],"ltp":0.0,"tv":0.0,"id":5858055},{"batb":[[0,1.13,805.12],[1,1.01,15.51],[2,1.13,0]],"batl":[[0,1.23,42.01],[1,1.23,0]],"ltp":1.19,"tv":3103.11,"id":7444998}]}]}
{"op":"mcm","clk":"1004337793","pt":1580654541690,"mc":[{"id":"1.168224472","rc":[{"batb":[[0,3.85,13.14],[1,3.15,373.59],[2,1.01,15.51]],"ltp":0.0,"tv":0.0,"id":5858055}]}]}
{"op":"mcm","clk":"1004338089","pt":1580654542928,"mc":[{"id":"1.168224472","rc":[{"batb":[[0,3.95,25.18]],"ltp":0.0,"tv":0.0,"id":5858055},{"batb":[[0,1.14,178.37],[1,1.13,1186.72],[2,1.01,15.51]],"batl":[[0,1.33,110.51],[1,1.34,141.76]],"ltp":1.19,"tv":3103.11,"id":7444998}]}]}
{"op":"mcm","clk":"1004340816","pt":1580654555127,"mc":[{"id":"1.168224472","rc":[{"batb":[[1,1.13,556.75]],"ltp":1.19,"tv":3103.11,"id":7444998}]}]}
{"op":"mcm","clk":"1004341304","pt":1580654557340,"mc":[{"id":"1.168224472","rc":[{"batb":[[0,7,12.75],[1,5.1,13.45],[2,3.95,25.18]],"batl":[[0,8.2,5.04]],"ltp":0.0,"tv":0.0,"id":5858055},{"batb":[[2,1.09,259.73]],"batl":[[0,1.16,303.84],[1,1.17,241.1]],"ltp":1.19,"tv":3103.11,"id":7444998}]}]}
{"op":"mcm","clk":"1004341451","pt":1580654557943,"mc":[{"id":"1.168224472","rc":[{"batb":[[1,6.6,6.72],[2,5.1,13.45]],"ltp":0.0,"tv":0.0,"id":5858055}]}]}
{"op":"mcm","clk":"1004341696","pt":1580654559023,"mc":[{"id":"1.168224472","rc":[{"batb":[[2,1.09,1038.78]],"ltp":1.19,"tv":3103.11,"id":7444998}]}]}
{"op":"mcm","clk":"1004343349","pt":1580654566367,"mc":[{"id":"1.168224472","rc":[{"batb":[[0,1.13,175.15],[1,1.09,1038.78],[2,1.01,15.51]],"ltp":1.19,"tv":3103.11,"id":7444998}]}]}
{"op":"mcm","clk":"1004343424","pt":1580654566630,"mc":[{"id":"1.168224472","rc":[{"batb":[[0,6.6,6.72],[1,5.1,13.45],[2,3.15,373.59]],"ltp":0.0,"tv":0.0,"id":5858055},{"batb":[[0,1.09,1038.78],[1,1.01,15.51],[2,1.01,0]],"ltp":1.19,"tv":3103.11,"id":7444998}]}]}
{"op":"mcm","clk":"1004343687","pt":1580654567744,"mc":[{"id":"1.168224472","rc":[{"batb":[[0,5.1,13.45],[1,3.15,373.59],[2,1.01,15.51]],"ltp":0.0,"tv":0.0,"id":5858055}]}]}
{"op":"mcm","clk":"1004344057","pt":1580654569375,"mc":[{"id":"1.168224472","rc":[{"batb":[[0,1.1,460.71],[1,1.09,1156],[2,1.01,15.51]],"batl":[[0,1.24,247.07],[1,1.25,203.04]],"ltp":1.19,"tv":3103.11,"id":7444998}]}]}
{"op":"mcm","clk":"1004344938","pt":1580654573216,"mc":[{"id":"1.168224472","rc":[{"batb":[[1,1.01,15.51],[2,1.01,0]],"ltp":0.0,"tv":0.0,"id":5858055},{"batb":[[1,1.09,376.95]],"ltp":1.19,"tv":3103.11,"id":7444998}]}]}
{"op":"mcm","clk":"1004345216","pt":1580654574448,"mc":[{"id":"1.168224472","rc":[{"batl":[[0,1.12,346.12],[1,1.13,218.49]],"ltp":1.19,"tv":3103.11,"id":7444998}]}]}
{"op":"mcm","clk":"1004345419","pt":1580654575259,"mc":[{"id":"1.168224472","rc":[{"batb":[[0,9.2,7.16],[1,8.4,5.04],[2,6.8,13.61]],"batl":[[0,10.5,4.2]],"ltp":0.0,"tv":0.0,"id":5858055},{"batb":[[0,1.1,628.75],[2,1.07,345.96]],"ltp":1.19,"tv":3103.11,"id":7444998}]}]}
{"op":"mcm","clk":"1004347590","pt":1580654584183,"mc":[{"id":"1.168224472","rc":[{"batb":[[0,8.4,5.04],[1,6.8,13.61],[2,3.5,371.08]],"ltp":0.0,"tv":0.0,"id":5858055},{"batb":[[0,1.1,168.04],[1,1.07,345.96],[2,1.06,955.61]],"ltp":1.19,"tv":3103.11,"id":7444998}]}]}
{"op":"mcm","clk":"1004347976","pt":1580654585752,"mc":[{"id":"1.168224472","rc":[{"batb":[[0,6.8,13.61],[1,3.5,371.08],[2,1.01,15.51]],"ltp":0.0,"tv":0.0,"id":5858055},{"batb":[[0,1.07,345.96],[1,1.06,955.61],[2,1.01,15.51]],"ltp":1.19,"tv":3103.11,"id":7444998}]}]}
{"op":"mcm","clk":"1004348802","pt":1580654589426,"mc":[{"id":"1.168224472","rc":[{"batb":[[1,1.01,15.51],[2,1.01,0]],"ltp":1.19,"tv":3103.11,"id":7444998}]}]}
{"op":"mcm","clk":"1004349314","pt":1580654591866,"mc":[{"id":"1.168224472","rc":[{"batb":[[0,1.11,301.41],[1,1.1,272.71],[2,1.07,345.96]],"batl":[[0,1.13,392.23],[1,1.14,167.83]],"ltp":1.19,"tv":3103.11,"id":7444998}]}]}
{"op":"mcm","clk":"1004349572","pt":1580654592950,"mc":[{"id":"1.168224472","rc":[{"batb":[[0,1.07,345.96],[1,1.01,15.51],[2,1.07,0]],"ltp":1.19,"tv":3103.11,"id":7444998}]}]}
{"op":"mcm","clk":"1004349881","pt":1580654594355,"mc":[{"id":"1.168224472","rc":[{"batb":[[0,1.07,1239.95]],"ltp":1.19,"tv":3103.11,"id":7444998}]}]}
{"op":"mcm","clk":"1004350204","pt":1580654595730,"mc":[{"id":"1.168224472","rc":[{"batb":[[0,1.08,522.62],[1,1.07,1239.95],[2,1.01,15.51]],"batl":[[0,1.16,147.95],[1,1.17,322.36]],"ltp":1.19,"tv":3103.11,"id":7444998}]}]}
{"op":"mcm","clk":"1004352361","pt":1580654605379,"mc":[{"id":"1.168224472","rc":[{"batb":[[1,1.07,345.96]],"ltp":1.19,"tv":3103.11,"id":7444998}]}]}
{"op":"mcm","clk":"1004352579","pt":1580654606301,"mc":[{"id":"1.168224472","rc":[{"batb":[[0,11,11.25],[1,9.4,17],[2,6.8,13.61]],"ltp":0.0,"tv":0.0,"id":5858055},{"batb":[[2,1.06,402.3]],"batl":[[0,1.1,535.08]],"ltp":1.19,"tv":3103.11,"id":7444998}]}]}
{"op":"mcm","clk":"1004352689","pt":1580654606790,"mc":[{"id":"1.168224472","rc":[{"batb":[[1,9.8,4.2],[2,9.4,17]],"batl":[[0,13,3.36]],"ltp":0.0,"tv":0.0,"id":5858055},{"batl":[[1,1.11,42.01]],"ltp":1.19,"tv":3103.11,"id":7444998}]}]}
{"op":"mcm","clk":"1004355108","pt":1580654617168,"mc":[{"id":"1.168224472","rc":[{"batb":[[0,9.8,4.2],[1,9.4,17],[2,3.5,371.08]],"ltp":0.0,"tv":0.0,"id":5858055},{"batb":[[0,1.06,402.3],[1,1.05,1069.56],[2,1.01,15.51]],"batl":[[0,1.11,42.01],[1,1.11,0]],"ltp":1.19,"tv":3103.11,"id":7444998}]}]}
{"op":"mcm","clk":"1004355328","pt":1580654618188,"mc":[{"id":"1.168224472","rc":[{"batb":[[0,9.4,17],[1,3.5,371.08],[2,1.01,15.51]],"ltp":0.0,"tv":0.0,"id":5858055}]}]}
{"op":"mcm","clk":"1004355747","pt":1580654620240,"mc":[{"id":"1.168224472","rc":[{"batb":[[0,1.07,593.04],[1,1.06,402.3],[2,1.05,1069.56]],"batl":[[0,1.11,90.28],[1,1.12,477.09]],"ltp":1.19,"tv":3103.11,"id":7444998}]}]}
{"op":"mcm","clk":"1004357058","pt":1580654626100,"mc":[{"id":"1.168224472","rc":[{"batb":[[2,1.01,15.51]],"ltp":1.19,"tv":3103.11,"id":7444998}]}]}
{"op":"mcm","clk":"1004357579","pt":1580654628373,"mc":[{"id":"1.168224472","rc":[{"batb":[[0,12.5,8.66],[1,11,11.09],[2,9.4,17]],"ltp":0.0,"tv":0.0,"id":5858055},{"batb":[[2,1.04,547.94]],"batl":[[0,1.09,511.59]],"ltp":1.19,"tv":3103.11,"id":7444998}]}]}
{"op":"mcm","clk":"1004357649","pt":1580654628690,"mc":[{"id":"1.168224472","rc":[{"batb":[[1,11,15.3],[2,3.5,371.08]],"ltp":0.0,"tv":0.0,"id":5858055},{"batl":[[1,1.1,42.01]],"ltp":1.19,"tv":3103.11,"id":7444998}]}]}
{"op":"mcm","clk":"1004357907","pt":1580654629982,"mc":[{"id":"1.168224472","rc":[{"batb":[[2,1.04,1810.94]],"ltp":1.19,"tv":3103.11,"id":7444998}]}]}
{"op":"mcm","clk":"1004364638","pt":1580654660405,"mc":[{"id":"1.168224472","rc":[{"batb":[[0,1.06,402.3],[1,1.04,1810.94],[2,1.01,15.51]],"batl":[[0,1.1,42.01],[1,1.1,0]],"ltp":1.19,"tv":3103.11,"id":7444998}]}]}
{"op":"mcm","clk":"1004364864","pt":1580654661435,"mc":[{"id":"1.168224472","rc":[{"batb":[[0,11,15.3],[1,3.5,371.08],[2,1.01,15.51]],"ltp":0.0,"tv":0.0,"id":5858055},{"batb":[[0,1.04,1809.44],[1,1.01,15.51],[2,1.01,0]],"ltp":1.19,"tv":3103.11,"id":7444998}]}]}
{"op":"mcm","clk":"1004364958","pt":1580654661873,"mc":[{"id":"1.168224472","rc":[{"batb":[[0,11,11.09]],"ltp":0.0,"tv":0.0,"id":5858055}]}]}
{"op":"mcm","clk":"1004365264","pt":1580654663270,"mc":[{"id":"1.168224472","rc":[{"batb":[[0,1.06,123.07],[1,1.05,480.28],[2,1.04,1809.44]],"batl":[[0,1.1,409.41],[1,1.11,166.11]],"ltp":1.19,"tv":3103.11,"id":7444998}]}]}
{"op":"mcm","clk":"1004365825","pt":1580654665899,"mc":[{"id":"1.168224472","rc":[{"batb":[[1,1.04,1809.44],[2,1.01,15.51]],"ltp":1.19,"tv":3103.11,"id":7444998}]}]}
{"op":"mcm","clk":"1004366524","pt":1580654669121,"mc":[{"id":"1.168224472","rc":[{"batb":[[0,1.07,444.56],[1,1.06,150.06],[2,1.04,1809.44]],"batl":[[0,1.08,102.64],[1,1.09,480.64]],"ltp":1.19,"tv":3103.11,"id":7444998}]}]}
{"op":"mcm","clk":"1004366960","pt":1580654671182,"mc":[{"id":"1.168224472","rc":[{"batb":[[0,1.06,127],[1,1.04,1809.44],[2,1.01,15.51]],"ltp":1.19,"tv":3103.11,"id":7444998}]}]}
{"op":"mcm","clk":"1004367626","pt":1580654674185,"mc":[{"id":"1.168224472","rc":[{"batb":[[1,1.05,476.3],[2,1.04,1809.44]],"batl":[[0,1.1,405.68],[1,1.11,169.81]],"ltp":1.19,"tv":3103.11,"id":7444998}]}]}
{"op":"mcm","clk":"1004370240","pt":1580654686212,"mc":[{"id":"1.168224472","rc":[{"batb":[[0,1.04,1809.44],[1,1.01,15.51],[2,1.04,0]],"ltp":1.19,"tv":3103.11,"id":7444998}]}]}
{"op":"mcm","clk":"1004370891","pt":1580654689191,"mc":[{"id":"1.168224472","rc":[{"batb":[[0,1.08,587.73],[1,1.04,546.45],[2,1.01,15.51]],"ltp":1.19,"tv":3103.11,"id":7444998}]}]}
{"op":"mcm","clk":"1004371077","pt":1580654690090,"mc":[{"id":"1.168224472","rc":[{"batb":[[1,10.5,13.14],[2,3.5,371.08]],"ltp":0.0,"tv":0.0,"id":5858055},{"trd":[[1.08,22.88]],"batb":[[0,1.08,576.29],[1,1.05,427.01]],"ltp":1.08,"tv":3125.98,"id":7444998}],"tv":3125.98}]}
{"op":"mcm","clk":"1004371283","pt":1580654690982,"mc":[{"id":"1.168224472","rc":[{"batb":[[2,10,4.2]],"batl":[[0,13,3.36]],"ltp":0.0,"tv":0.0,"id":5858055},{"batb":[[0,1.08,744.33]],"batl":[[1,1.11,211.82]],"ltp":1.08,"tv":3125.98,"id":7444998}]}]}
{"op":"mcm","clk":"1004371623","pt":1580654692584,"mc":[{"id":"1.168224472","rc":[{"batb":[[1,1.05,1496.57]],"ltp":1.08,"tv":3125.98,"id":7444998}]}]}
{"op":"mcm","clk":"1004373799","pt":1580654702810,"mc":[{"id":"1.168224472","rc":[{"batb":[[0,10.5,13.14],[1,10,4.2],[2,3.5,371.08]],"ltp":0.0,"tv":0.0,"id":5858055},{"batb":[[0,1.08,168.04]],"batl":[[0,1.11,211.82],[1,1.11,0]],"ltp":1.08,"tv":3125.98,"id":7444998}]}]}
{"op":"mcm","clk":"1004374020","pt":1580654703844,"mc":[{"id":"1.168224472","rc":[{"batb":[[1,3.5,371.08],[2,1.01,15.51]],"ltp":0.0,"tv":0.0,"id":5858055},{"batb":[[0,1.05,1496.57],[1,1.01,15.51],[2,1.01,0]],"batl":[[0,1.11,169.81]],"ltp":1.08,"tv":3125.98,"id":7444998}]}]}
{"op":"mcm","clk":"1004374397","pt":1580654705440,"mc":[{"id":"1.168224472","rc":[{"batb":[[0,1.07,436.26],[1,1.06,158.44],[2,1.05,1496.57]],"batl":[[0,1.11,454.41],[1,1.12,116.38]],"ltp":1.08,"tv":3125.98,"id":7444998}]}]}
{"op":"mcm","clk":"1004375158","pt":1580654708438,"mc":[{"id":"1.168224472","rc":[{"batb":[[0,1.07,128.23],[1,1.05,1496.57],[2,1.01,15.51]],"ltp":1.08,"tv":3125.98,"id":7444998}]}]}
{"op":"mcm","clk":"1004375302","pt":1580654709004,"mc":[{"id":"1.168224472","rc":[{"batl":[[0,1.15,2.53]],"ltp":1.08,"tv":3125.98,"id":7444998}]}]}
{"op":"mcm","clk":"1004375854","pt":1580654711432,"mc":[{"id":"1.168224472","rc":[{"batb":[[0,1.08,460.68],[1,1.07,128.23],[2,1.05,1496.57]],"batl":[[0,1.1,577.04],[1,1.15,2.53]],"ltp":1.08,"tv":3125.98,"id":7444998}]}]}
{"op":"mcm","clk":"1004376902","pt":1580654716161,"mc":[{"id":"1.168224472","rc":[{"batb":[[0,1.07,128.23],[1,1.05,1496.57],[2,1.01,15.51]],"batl":[[0,1.15,2.53],[1,1.15,0]],"ltp":1.08,"tv":3125.98,"id":7444998}]}]}
{"op":"mcm","clk":"1004377556","pt":1580654719115,"mc":[{"id":"1.168224472","rc":[{"batb":[[0,1.07,436.26],[1,1.06,158.44],[2,1.05,1496.57]],"batl":[[0,1.11,454.41],[1,1.12,116.38],[2,1.15,2.53]],"ltp":1.08,"tv":3125.98,"id":7444998}]}]}
{"op":"mcm","clk":"1004377781","pt":1580654720136,"mc":[{"id":"1.168224472","rc":[{"batb":[[0,1.05,1496.57],[1,1.01,15.51],[2,1.05,0]],"ltp":1.08,"tv":3125.98,"id":7444998}]}]}
{"op":"mcm","clk":"1004378437","pt":1580654723146,"mc":[{"id":"1.168224472","rc":[{"batb":[[0,1.09,461.15],[1,1.08,122.31],[2,1.05,1496.57]],"ltp":1.08,"tv":3125.98,"id":7444998}]}]}
{"op":"mcm","clk":"1004378683","pt":1580654724348,"mc":[{"id":"1.168224472","rc":[{"batb":[[1,10,14.79],[2,3.5,371.08]],"ltp":0.0,"tv":0.0,"id":5858055},{"batb":[[2,1.07,315.83]],"ltp":1.08,"tv":3125.98,"id":7444998}]}]}
{"op":"mcm","clk":"1004378769","pt":1580654724769,"mc":[{"id":"1.168224472","rc":[{"batb":[[2,9.6,4.2]],"batl":[[0,12,3.36]],"ltp":0.0,"tv":0.0,"id":5858055},{"batb":[[0,1.09,629.19]],"batl":[[1,1.12,158.39]],"ltp":1.08,"tv":3125.98,"id":7444998}]}]}
{"op":"mcm","clk":"1004380980","pt":1580654735065,"mc":[{"id":"1.168224472","rc":[{"batb":[[0,10,14.79],[1,9.6,4.2],[2,3.5,371.08]],"ltp":0.0,"tv":0.0,"id":5858055},{"batb":[[0,1.09,168.04],[2,1.06,355.88]],"batl":[[0,1.11,166.5]],"ltp":1.08,"tv":3125.98,"id":7444998}]}]}
{"op":"mcm","clk":"1004381122","pt":1580654735784,"mc":[{"id":"1.168224472","rc":[{"batb":[[1,3.5,371.08],[2,1.01,15.51]],"ltp":0.0,"tv":0.0,"id":5858055},{"batb":[[0,1.08,122.31],[1,1.06,355.88],[2,1.05,1069.56]],"batl":[[1,1.12,116.38]],"ltp":1.08,"tv":3125.98,"id":7444998}]}]}
{"op":"mcm","clk":"1004381670","pt":1580654738289,"mc":[{"id":"1.168224472","rc":[{"batb":[[0,1.08,587.73]],"batl":[[1,1.12,401.72]],"ltp":1.08,"tv":3125.98,"id":7444998}]}]}
{"op":"mcm","clk":"1004382021","pt":1580654740175,"mc":[{"id":"1.168224472","rc":[{"batb":[[0,1.08,247.44]],"batl":[[1,1.15,2.53],[2,1.15,0]],"ltp":1.08,"tv":3125.98,"id":7444998}]}]}
{"op":"mcm","clk":"1004382716","pt":1580654743380,"mc":[{"id":"1.168224472","rc":[{"batb":[[0,1.09,337.16],[1,1.08,247.44],[2,1.06,355.88]],"batl":[[0,1.11,557.85]],"ltp":1.08,"tv":3125.98,"id":7444998}]}]}
{"op":"mcm","clk":"1004383378","pt":1580654746656,"mc":[{"id":"1.168224472","rc":[{"batb":[[0,1.08,247.44],[1,1.06,355.88],[2,1.05,1069.56]],"batl":[[0,1.11,166.5]],"ltp":1.08,"tv":3125.98,"id":7444998}]}]}
{"op":"mcm","clk":"1004384049","pt":1580654749579,"mc":[{"id":"1.168224472","rc":[{"batb":[[0,1.08,587.73]],"batl":[[1,1.12,401.72],[2,1.15,2.53]],"ltp":1.08,"tv":3125.98,"id":7444998}]}]}
{"op":"mcm","clk":"1004385490","pt":1580654756305,"mc":[{"id":"1.168224472","rc":[{"batl":[[0,1.11,105.6],[1,1.15,2.53],[2,1.15,0]],"ltp":1.08,"tv":3125.98,"id":7444998}]}]}
{"op":"mcm","clk":"1004386073","pt":1580654758900,"mc":[{"id":"1.168224472","rc":[{"batl":[[0,1.1,470.47],[1,1.11,105.6],[2,1.15,2.53]],"ltp":1.08,"tv":3125.98,"id":7444998}]}]}
{"op":"mcm","clk":"1004386301","pt":1580654759916,"mc":[{"id":"1.168224472","rc":[{"batb":[[0,11.5,10.7],[1,10,13.38],[2,3.5,371.08]],"ltp":0.0,"tv":0.0,"id":5858055},{"batb":[[2,1.05,1530.24]],"ltp":1.08,"tv":3125.98,"id":7444998}]}]}
{"op":"mcm","clk":"1004386494","pt":1580654760823,"mc":[{"id":"1.168224472","rc":[{"batb":[[1,10,17.58]],"batl":[[0,13,3.36]],"ltp":0.0,"tv":0.0,"id":5858055},{"batb":[[0,1.08,755.77]],"batl":[[1,1.11,147.61]],"ltp":1.08,"tv":3125.98,"id":7444998}]}]}
{"op":"mcm","clk":"1004389660","pt":1580654775415,"mc":[{"id":"1.168224472","rc":[{"batb":[[0,1.08,168.04]],"batl":[[0,1.11,147.61],[1,1.15,2.53],[2,1.15,0]],"ltp":1.08,"tv":3125.98,"id":7444998}]}]}
{"op":"mcm","clk":"1004389727","pt":1580654775737,"mc":[{"id":"1.168224472","rc":[{"batb":[[0,10,13.38],[1,3.5,371.08],[2,1.01,15.51]],"ltp":0.0,"tv":0.0,"id":5858055},{"batb":[[0,1.05,1530.24],[1,1.01,15.51],[2,1.05,0]],"batl":[[0,1.11,105.6]],"ltp":1.08,"tv":3125.98,"id":7444998}]}]}
{"op":"mcm","clk":"1004390492","pt":1580654779205,"mc":[{"id":"1.168224472","rc":[{"batb":[[0,1.07,105.73],[1,1.06,492.09],[2,1.05,1530.24]],"batl":[[0,1.11,409.73],[1,1.12,160.66],[2,1.15,2.53]],"ltp":1.08,"tv":3125.98,"id":7444998}]}]}
{"op":"mcm","clk":"1004391197","pt":1580654782344,"mc":[{"id":"1.168224472","rc":[{"batb":[[0,1.05,1530.24],[1,1.01,15.51],[2,1.05,0]],"ltp":1.08,"tv":3125.98,"id":7444998}]}]}
{"op":"mcm","clk":"1004391817","pt":1580654785004,"mc":[{"id":"1.168224472","rc":[{"batb":[[0,1.09,514.16],[1,1.05,1530.24],[2,1.01,15.51]],"ltp":1.08,"tv":3125.98,"id":7444998}]}]}
{"op":"mcm","clk":"1004392049","pt":1580654786073,"mc":[{"id":"1.168224472","rc":[{"batb":[[1,9.8,14.95],[2,3.5,371.08]],"ltp":0.0,"tv":0.0,"id":5858055},{"batb":[[1,1.07,350.21],[2,1.05,1069.56]],"ltp":1.08,"tv":3125.98,"id":7444998}]}]}
{"op":"mcm","clk":"1004392189","pt":1580654786770,"mc":[{"id":"1.168224472","rc":[{"batb":[[2,9.6,4.2]],"batl":[[0,12,3.36]],"ltp":0.0,"tv":0.0,"id":5858055},{"batb":[[0,1.09,682.2]],"batl":[[1,1.12,202.67]],"ltp":1.08,"tv":3125.98,"id":7444998}]}]}
{"op":"mcm","clk":"1004394430","pt":1580654797317,"mc":[{"id":"1.168224472","rc":[{"batb":[[0,9.8,14.95],[1,9.6,4.2],[2,3.5,371.08]],"ltp":0.0,"tv":0.0,"id":5858055},{"batb":[[0,1.09,168.04]],"batl":[[0,1.11,152.37]],"ltp":1.08,"tv":3125.98,"id":7444998}]}]}
{"op":"mcm","clk":"1004394534","pt":1580654797795,"mc":[{"id":"1.168224472","rc":[{"batb":[[1,3.5,371.08],[2,1.01,15.51]],"ltp":0.0,"tv":0.0,"id":5858055},{"batb":[[0,1.07,350.21],[1,1.05,1069.56],[2,1.01,15.51]],"batl":[[1,1.12,160.66]],"ltp":1.08,"tv":3125.98,"id":7444998}]}]}
{"op":"mcm","clk":"1004395101","pt":1580654800374,"mc":[{"id":"1.168224472","rc":[{"batb":[[0,1.08,587.73],[1,1.07,350.21],[2,1.05,1069.56]],"batl":[[1,1.12,415.72]],"ltp":1.08,"tv":3125.98,"id":7444998}]}]}
{"op":"mcm","clk":"1004395905","pt":1580654804206,"mc":[{"id":"1.168224472","rc":[{"batb":[[0,1.07,350.21],[1,1.05,1069.56],[2,1.01,15.51]],"ltp":1.08,"tv":3125.98,"id":7444998}]}]}
{"op":"mcm","clk":"1004396285","pt":1580654806186,"mc":[{"id":"1.168224472","rc":[{"batb":[[1,1.01,15.51],[2,1.01,0]],"ltp":1.08,"tv":3125.98,"id":7444998}]}]}
{"op":"mcm","clk":"1004396453","pt":1580654807090,"mc":[{"id":"1.168224472","rc":[{"batb":[[0,1.1,128.84],[1,1.09,452.49],[2,1.07,350.21]],"ltp":1.08,"tv":3125.98,"id":7444998}]}]}
{"op":"mcm","clk":"1004396666","pt":1580654808118,"mc":[{"id":"1.168224472","rc":[{"batb":[[1,5.7,10.54],[2,3.5,371.08]],"ltp":0.0,"tv":0.0,"id":5858055},{"batb":[[2,1.08,292.85]],"ltp":1.08,"tv":3125.98,"id":7444998}]}]}
{"op":"mcm","clk":"1004396794","pt":1580654808710,"mc":[{"id":"1.168224472","rc":[{"batb":[[1,9,5.04],[2,5.7,10.54]],"batl":[[0,11.5,3.36]],"ltp":0.0,"tv":0.0,"id":5858055}]}]}
{"op":"mcm","clk":"1004398602","pt":1580654818114,"mc":[{"id":"1.168224472","rc":[{"batl":[[2,1.15,0]],"ltp":1.08,"tv":3125.98,"id":7444998}]}]}
{"op":"mcm","clk":"1004399208","pt":1580654821308,"mc":[{"id":"1.168224472","rc":[{"trd":[[1.1,5.06]],"batb":[[0,1.1,126.31]],"ltp":1.1,"tv":3131.05,"id":7444998}],"tv":3131.05}]}
{"op":"mcm","clk":"1004411205","pt":1580654885420,"mc":[{"id":"1.168224472","rc":[{"batb":[[0,1.08,292.85],[1,1.06,955.61],[2,1.03,604.43]],"ltp":1.1,"tv":3131.05,"id":7444998}]}]}
{"op":"mcm","clk":"1004411268","pt":1580654885743,"mc":[{"id":"1.168224472","rc":[{"batb":[[0,5.7,10.54],[1,3.5,371.08],[2,1.01,15.51]],"ltp":0.0,"tv":0.0,"id":5858055},{"batb":[[0,1.06,955.61],[1,1.03,604.43],[2,1.01,15.51]],"ltp":1.1,"tv":3131.05,"id":7444998}]}]}
{"op":"mcm","clk":"1004411462","pt":1580654886819,"mc":[{"id":"1.168224472","rc":[{"batb":[[1,1.01,15.51],[2,1.01,0]],"ltp":0.0,"tv":0.0,"id":5858055},{"batb":[[0,1.03,604.43],[1,1.01,15.51],[2,1.01,0]],"ltp":1.1,"tv":3131.05,"id":7444998}]}]}
{"op":"mcm","clk":"1004411727","pt":1580654888346,"mc":[{"id":"1.168224472","rc":[{"batb":[[0,1.05,520.93],[1,1.03,604.43],[2,1.01,15.51]],"batl":[[0,1.22,131.3],[1,1.23,227.37]],"ltp":1.1,"tv":3131.05,"id":7444998}]}]}
{"op":"mcm","clk":"1004412546","pt":1580654892741,"mc":[{"id":"1.168224472","rc":[{"batl":[[0,1.06,334.82],[1,1.07,261.71]],"ltp":1.1,"tv":3131.05,"id":7444998}]}]}
{"op":"mcm","clk":"1004412753","pt":1580654893843,"mc":[{"id":"1.168224472","rc":[{"batb":[[0,17,4.33],[1,8.8,7.87],[2,1.01,15.51]],"ltp":0.0,"tv":0.0,"id":5858055}]}]}
{"op":"mcm","clk":"1004412920","pt":1580654894743,"mc":[{"id":"1.168224472","rc":[{"batb":[[2,4,369.93]],"ltp":0.0,"tv":0.0,"id":5858055},{"batb":[[0,1.05,688.97],[2,1.02,2184.08]],"batl":[[1,1.07,303.72]],"ltp":1.1,"tv":3131.05,"id":7444998}]}]}
{"op":"mcm","clk":"1004414510","pt":1580654903325,"mc":[{"id":"1.168224472","rc":[{"batb":[[0,1.05,168.04]],"batl":[[0,1.07,42.01],[1,1.07,0]],"ltp":1.1,"tv":3131.05,"id":7444998}]}]}
{"op":"mcm","clk":"1004414620","pt":1580654903858,"mc":[{"id":"1.168224472","rc":[{"batb":[[0,8.8,7.87],[1,4,369.93],[2,1.01,15.51]],"ltp":0.0,"tv":0.0,"id":5858055},{"batb":[[0,1.02,2184.08],[1,1.01,15.51],[2,1.02,0]],"ltp":1.1,"tv":3131.05,"id":7444998}]}]}
{"op":"mcm","clk":"1004414882","pt":1580654905336,"mc":[{"id":"1.168224472","rc":[{"batb":[[1,1.01,15.51],[2,1.01,0]],"ltp":0.0,"tv":0.0,"id":5858055},{"batb":[[0,1.01,15.51],[1,1.01,0]],"ltp":1.1,"tv":3131.05,"id":7444998}]}]}
{"op":"mcm","clk":"1004415035","pt":1580654906337,"mc":[{"id":"1.168224472","rc":[{"batb":[[0,1.02,630.37],[1,1.01,15.51]],"batl":[[0,1.13,168.68],[1,1.14,389.77]],"ltp":1.1,"tv":3131.05,"id":7444998}]}]}
{"op":"mcm","clk":"1004415758","pt":1580654910267,"mc":[{"id":"1.168224472","rc":[{"batl":[[0,1.03,616.46]],"ltp":1.1,"tv":3131.05,"id":7444998}]}]}
{"op":"mcm","clk":"1004415943","pt":1580654911357,"mc":[{"id":"1.168224472","rc":[{"batb":[[0,16,4.8]],"ltp":0.0,"tv":0.0,"id":5858055}]}]}
{"op":"mcm","clk":"1004416105","pt":1580654912369,"mc":[{"id":"1.168224472","rc":[{"batb":[[1,4.4,375.46],[2,1.01,15.51]],"ltp":0.0,"tv":0.0,"id":5858055}]}]}
{"op":"mcm","clk":"1004417428","pt":1580654920045,"mc":[{"id":"1.168224472","rc":[{"batb":[[0,1.02,7.87]],"ltp":1.1,"tv":3131.05,"id":7444998}]}]}
{"op":"mcm","clk":"1004417799","pt":1580654922370,"mc":[{"id":"1.168224472","rc":[{"batb":[[1,1.01,15.51],[2,1.01,0]],"ltp":0.0,"tv":0.0,"id":5858055}]}]}
{"op":"mcm","clk":"1004417935","pt":1580654923154,"mc":[{"id":"1.168224472","rc":[{"batb":[[1,1.01,23.37]],"batl":[[0,1.06,99.02],[1,1.07,495.31]],"ltp":1.1,"tv":3131.05,"id":7444998}]}]}
{"op":"mcm","clk":"1004418727","pt":1580654928085,"mc":[{"id":"1.168224472","rc":[{"batb":[[0,1.02,630.37]],"batl":[[0,1.04,610.53]],"ltp":1.1,"tv":3131.05,"id":7444998}]}]}
{"op":"mcm","clk":"1004418911","pt":1580654929276,"mc":[{"id":"1.168224472","rc":[{"batb":[[0,1.02,7.87]],"ltp":1.1,"tv":3131.05,"id":7444998}]}]}
{"op":"mcm","clk":"1004418965","pt":1580654929693,"mc":[{"id":"1.168224472","rc":[{"batb":[[1,4.4,369.4],[2,1.01,15.51]],"batl":[[0,520,35.52]],"ltp":0.0,"tv":0.0,"id":5858055}]}]}
{"op":"mcm","clk":"1004419214","pt":1580654931291,"mc":[{"id":"1.168224472","rc":[{"batb":[[1,1.01,15.51],[2,1.01,0]],"ltp":0.0,"tv":0.0,"id":5858055}]}]}
{"op":"mcm","clk":"1004419397","pt":1580654932362,"mc":[{"id":"1.168224472","rc":[{"batl":[[0,1.06,157.87],[1,1.07,437.01]],"ltp":1.1,"tv":3131.05,"id":7444998}]}]}
{"op":"mcm","clk":"1004420102","pt":1580654937094,"mc":[{"id":"1.168224472","rc":[{"batb":[[0,1.01,15.51],[1,1.01,0]],"ltp":0.0,"tv":0.0,"id":5858055}]}]}
{"op":"mcm","clk":"1004420499","pt":1580654939281,"mc":[{"id":"1.168224472","rc":[{"trd":[[1.01,46.75],[1.02,15.74]],"batl":[[0,1.01,597.41]],"ltp":1.01,"tv":3193.54,"id":7444998}],"tv":3193.54}]}
{"op":"mcm","clk":"1004420808","pt":1580654941205,"mc":[{"id":"1.168224472","rc":[{"batb":[[0,4.8,367.63],[1,1.01,15.51]],"ltp":0.0,"tv":0.0,"id":5858055}]}]}
{"op":"mcm","clk":"1004420971","pt":1580654942277,"mc":[{"id":"1.168224472","rc":[{"batl":[[0,1.01,628.66]],"ltp":1.01,"tv":3193.54,"id":7444998}]}]}
{"op":"mcm","clk":"1004421004","pt":1580654942503,"mc":[{"id":"1.168224472","rc":[{"batl":[[0,1.01,670.67]],"ltp":1.01,"tv":3193.54,"id":7444998}]}]}
{"op":"mcm","clk":"1004422048","pt":1580654948291,"mc":[{"id":"1.168224472","rc":[{"batl":[[0,1.01,42.01]],"ltp":1.01,"tv":3193.54,"id":7444998}]}]}
{"op":"mcm","clk":"1004422371","pt":1580654950313,"mc":[{"id":"1.168224472","rc":[{"batb":[[0,1.01,15.51],[1,1.01,0]],"ltp":0.0,"tv":0.0,"id":5858055}]}]}
{"op":"mcm","clk":"1004422551","pt":1580654951411,"mc":[{"id":"1.168224472","rc":[{"batl":[[0,1.02,622.5]],"ltp":1.01,"tv":3193.54,"id":7444998}]}]}
{"op":"mcm","clk":"1004423341","pt":1580654956907,"mc":[{"id":"1.168224472","rc":[{"batl":[[0,1.01,628.66]],"ltp":1.01,"tv":3193.54,"id":7444998}]}]}
{"op":"mcm","clk":"1004423695","pt":1580654959431,"mc":[{"id":"1.168224472","rc":[{"batb":[[0,4.7,374.21],[1,1.01,15.51]],"ltp":0.0,"tv":0.0,"id":5858055}]}]}
{"op":"mcm","clk":"1004423928","pt":1580654961089,"mc":[{"id":"1.168224472","rc":[{"batb":[[0,1.01,15.51],[1,1.01,0]],"ltp":0.0,"tv":0.0,"id":5858055}]}]}
{"op":"mcm","clk":"1004424420","pt":1580654964342,"mc":[{"id":"1.168224472","rc":[{"batl":[[0,1.02,622.5]],"ltp":1.01,"tv":3193.54,"id":7444998}]}]}
{"op":"mcm","clk":"1004424852","pt":1580654967234,"mc":[{"id":"1.168224472","rc":[{"batb":[[0,1.01,628.66]],"ltp":1.01,"tv":3193.54,"id":7444998}]}]}
{"op":"mcm","clk":"1004424979","pt":1580654968035,"mc":[{"id":"1.168224472","rc":[{"batb":[[0,18.5,7.08],[1,1.01,15.51]],"ltp":0.0,"tv":0.0,"id":5858055}]}]}
{"op":"mcm","clk":"1004425160","pt":1580654969138,"mc":[{"id":"1.168224472","rc":[{"batb":[[1,4.6,368.39],[2,1.01,15.51]],"ltp":0.0,"tv":0.0,"id":5858055}]}]}
{"op":"mcm","clk":"1004427048","pt":1580654981316,"mc":[{"id":"1.168224472","rc":[{"batb":[[1,1.01,15.51],[2,1.01,0]],"ltp":0.0,"tv":0.0,"id":5858055}]}]}
{"op":"mcm","clk":"1004427341","pt":1580654983328,"mc":[{"id":"1.168224472","rc":[{"batl":[[0,1.05,111.19],[1,1.06,488.87]],"ltp":1.01,"tv":3193.54,"id":7444998}]}]}
{"op":"mcm","clk":"1004427783","pt":1580654986264,"mc":[{"id":"1.168224472","marketDefinition":{"bspMarket":false,"turnInPlayEnabled":true,"persistenceEnabled":true,"marketBaseRate":5.0,"eventId":"29681747","eventTypeId":"2","numberOfWinners":1,"bettingType":"ODDS","marketType":"SET_WINNER","marketTime":"2020-02-02T14:03:00.000Z","suspendTime":"2020-02-02T14:03:00.000Z","bspReconciled":false,"complete":true,"inPlay":true,"crossMatching":true,"runnersVoidable":false,"numberOfActiveRunners":2,"betDelay":3,"status":"SUSPENDED","runners":[{"status":"ACTIVE","sortPriority":1,"id":5858055,"name":"Hiroki Moriya"},{"status":"ACTIVE","sortPriority":2,"id":7444998,"name":"Danilo Petrovic"}],"regulators":["MR_INT"],"countryCode":"FR","discountAllowed":true,"timezone":"UTC","openDate":"2020-02-02T14:03:00.000Z","version":3149292024,"name":"Set 1 Winner","eventName":"Moriya v Petrovic"}}]}
{"op":"mcm","clk":"1004427820","pt":1580654986535,"mc":[{"id":"1.168224472","rc":[{"batb":[[0,1.01,15.51],[1,1.01,0]],"ltp":0.0,"tv":0.0,"id":5858055}]}]}
{"op":"mcm","clk":"1004432741","pt":1580655019173,"mc":[{"id":"1.168224472","marketDefinition":{"bspMarket":false,"turnInPlayEnabled":true,"persistenceEnabled":true,"marketBaseRate":5.0,"eventId":"29681747","eventTypeId":"2","numberOfWinners":1,"bettingType":"ODDS","marketType":"SET_WINNER","marketTime":"2020-02-02T14:03:00.000Z","suspendTime":"2020-02-02T14:03:00.000Z","bspReconciled":false,"complete":true,"inPlay":true,"crossMatching":false,"runnersVoidable":false,"numberOfActiveRunners":0,"betDelay":3,"status":"CLOSED","settledTime":"2020-02-02T14:50:17.000Z","runners":[{"status":"LOSER","sortPriority":1,"id":5858055,"name":"Hiroki Moriya"},{"status":"WINNER","sortPriority":2,"id":7444998,"name":"Danilo Petrovic"}],"regulators":["MR_INT"],"countryCode":"FR","discountAllowed":true,"timezone":"UTC","openDate":"2020-02-02T14:03:00.000Z","version":3149293835,"name":"Set 1 Winner","eventName":"Moriya v Petrovic"},"tv":0.0}]}
