{"op":"mcm","clk":"993170579","pt":1580537866635,"mc":[{"id":"1.168186840","marketDefinition":{"bspMarket":false,"turnInPlayEnabled":true,"persistenceEnabled":true,"marketBaseRate":5.0,"eventId":"29680287","eventTypeId":"2","numberOfWinners":1,"bettingType":"ODDS","marketType":"SET_WINNER","marketTime":"2020-02-02T02:00:00.000Z","suspendTime":"2020-02-02T02:00:00.000Z","bspReconciled":false,"complete":true,"inPlay":false,"crossMatching":false,"runnersVoidable":false,"numberOfActiveRunners":2,"betDelay":0,"status":"OPEN","runners":[{"status":"ACTIVE","sortPriority":1,"id":8173434,"name":"Taro Daniel"},{"status":"ACTIVE","sortPriority":2,"id":8639275,"name":"Yannick Hanfmann"}],"regulators":["MR_INT"],"countryCode":"AU","discountAllowed":false,"timezone":"UTC","openDate":"2020-02-02T02:00:00.000Z","version":3144541456,"name":"Set 2 Winner","eventName":"Daniel v Hanfmann"},"rc":[{"batb":[[0,1.01,20]],"ltp":0.0,"tv":0.0,"id":8639275},{"batb":[[0,1.01,20]],"ltp":0.0,"tv":0.0,"id":8173434}]}]}
{"op":"mcm","clk":"993170622","pt":1580537867691,"mc":[{"id":"1.168186840","marketDefinition":{"bspMarket":false,"turnInPlayEnabled":true,"persistenceEnabled":true,"marketBaseRate":5.0,"eventId":"29680287","eventTypeId":"2","numberOfWinners":1,"bettingType":"ODDS","marketType":"SET_WINNER","marketTime":"2020-02-02T02:00:00.000Z","suspendTime":"2020-02-02T02:00:00.000Z","bspReconciled":false,"complete":true,"inPlay":false,"crossMatching":false,"runnersVoidable":false,"numberOfActiveRunners":2,"betDelay":0,"status":"OPEN","runners":[{"status":"ACTIVE","sortPriority":1,"id":8173434,"name":"Taro Daniel"},{"status":"ACTIVE","sortPriority":2,"id":8639275,"name":"Yannick Hanfmann"}],"regulators":["MR_INT"],"countryCode":"AU","discountAllowed":true,"timezone":"UTC","openDate":"2020-02-02T02:00:00.000Z","version":3144541456,"name":"Set 2 Winner","eventName":"Daniel v Hanfmann"}}]}
{"op":"mcm","clk":"993211515","pt":1580538616870,"mc":[{"id":"1.168186840","rc":[{"batb":[[0,1.01,10]],"ltp":0.0,"tv":0.0,"id":8639275},{"batb":[[0,1.01,10]],"ltp":0.0,"tv":0.0,"id":8173434}]}]}
{"op":"mcm","clk":"1002913591","pt":1580600511640,"mc":[{"id":"1.168186840","marketDefinition":{"bspMarket":false,"turnInPlayEnabled":true,"persistenceEnabled":true,"marketBaseRate":5.0,"eventId":"29680287","eventTypeId":"2","numberOfWinners":1,"bettingType":"ODDS","marketType":"SET_WINNER","marketTime":"2020-02-02T02:30:00.000Z","suspendTime":"2020-02-02T02:30:00.000Z","bspReconciled":false,"complete":true,"inPlay":false,"crossMatching":false,"runnersVoidable":false,"numberOfActiveRunners":2,"betDelay":0,"status":"OPEN","runners":[{"status":"ACTIVE","sortPriority":1,"id":8173434,"name":"Taro Daniel"},{"status":"ACTIVE","sortPriority":2,"id":8639275,"name":"Yannick Hanfmann"}],"regulators":["MR_INT"],"countryCode":"AU","discountAllowed":true,"timezone":"UTC","openDate":"2020-02-02T02:00:00.000Z","version":3147850879,"name":"Set 2 Winner","eventName":"Daniel v Hanfmann"}}]}
{"op":"mcm","clk":"1002913961","pt":1580600516653,"mc":[{"id":"1.168186840","marketDefinition":{"bspMarket":false,"turnInPlayEnabled":true,"persistenceEnabled":true,"marketBaseRate":5.0,"eventId":"29680287","eventTypeId":"2","numberOfWinners":1,"bettingType":"ODDS","marketType":"SET_WINNER","marketTime":"2020-02-02T02:30:00.000Z","suspendTime":"2020-02-02T02:30:00.000Z","bspReconciled":false,"complete":true,"inPlay":false,"crossMatching":false,"runnersVoidable":false,"numberOfActiveRunners":2,"betDelay":0,"status":"OPEN","runners":[{"status":"ACTIVE","sortPriority":1,"id":8173434,"name":"Taro Daniel"},{"status":"ACTIVE","sortPriority":2,"id":8639275,"name":"Yannick Hanfmann"}],"regulators":["MR_INT"],"countryCode":"AU","discountAllowed":true,"timezone":"UTC","openDate":"2020-02-02T02:30:00.000Z","version":3147850879,"name":"Set 2 Winner","eventName":"Daniel v Hanfmann"}}]}
{"op":"mcm","clk":"1003064003","pt":1580602526481,"mc":[{"id":"1.168186840","rc":[{"batb":[[0,1.01,12.53]],"ltp":0.0,"tv":0.0,"id":8639275},{"batb":[[0,1.01,12.53]],"ltp":0.0,"tv":0.0,"id":8173434}]}]}
{"op":"mcm","clk":"1003064084","pt":1580602527569,"mc":[{"id":"1.168186840","rc":[{"batb":[[0,1.01,10.51]],"ltp":0.0,"tv":0.0,"id":8639275},{"batb":[[0,1.01,10.51]],"ltp":0.0,"tv":0.0,"id":8173434}]}]}
{"op":"mcm","clk":"1003071724","pt":1580602612426,"mc":[{"id":"1.168186840","marketDefinition":{"bspMarket":false,"turnInPlayEnabled":true,"persistenceEnabled":true,"marketBaseRate":5.0,"eventId":"29680287","eventTypeId":"2","numberOfWinners":1,"bettingType":"ODDS","marketType":"SET_WINNER","marketTime":"2020-02-02T03:00:00.000Z","suspendTime":"2020-02-02T03:00:00.000Z","bspReconciled":false,"complete":true,"inPlay":false,"crossMatching":false,"runnersVoidable":false,"numberOfActiveRunners":2,"betDelay":0,"status":"OPEN","runners":[{"status":"ACTIVE","sortPriority":1,"id":8173434,"name":"Taro Daniel"},{"status":"ACTIVE","sortPriority":2,"id":8639275,"name":"Yannick Hanfmann"}],"regulators":["MR_INT"],"countryCode":"AU","discountAllowed":true,"timezone":"UTC","openDate":"2020-02-02T02:30:00.000Z","version":3147905871,"name":"Set 2 Winner","eventName":"Daniel v Hanfmann"}}]}
{"op":"mcm","clk":"1003071944","pt":1580602615018,"mc":[{"id":"1.168186840","marketDefinition":{"bspMarket":false,"turnInPlayEnabled":true,"persistenceEnabled":true,"marketBaseRate":5.0,"eventId":"29680287","eventTypeId":"2","numberOfWinners":1,"bettingType":"ODDS","marketType":"SET_WINNER","marketTime":"2020-02-02T03:00:00.000Z","suspendTime":"2020-02-02T03:00:00.000Z","bspReconciled":false,"complete":true,"inPlay":false,"crossMatching":false,"runnersVoidable":false,"numberOfActiveRunners":2,"betDelay":0,"status":"OPEN","runners":[{"status":"ACTIVE","sortPriority":1,"id":8173434,"name":"Taro Daniel"},{"status":"ACTIVE","sortPriority":2,"id":8639275,"name":"Yannick Hanfmann"}],"regulators":["MR_INT"],"countryCode":"AU","discountAllowed":true,"timezone":"UTC","openDate":"2020-02-02T03:00:00.000Z","version":3147905871,"name":"Set 2 Winner","eventName":"Daniel v Hanfmann"}}]}
{"op":"mcm","clk":"1003106087","pt":1580603069576,"mc":[{"id":"1.168186840","rc":[{"batb":[[0,1.01,10.52]],"ltp":0.0,"tv":0.0,"id":8639275},{"batb":[[0,1.01,10.52]],"ltp":0.0,"tv":0.0,"id":8173434}]}]}
{"op":"mcm","clk":"1003183729","pt":1580604056546,"mc":[{"id":"1.168186840","rc":[{"batb":[[0,1.01,11.02]],"ltp":0.0,"tv":0.0,"id":8639275},{"batb":[[0,1.01,11.02]],"ltp":0.0,"tv":0.0,"id":8173434}]}]}
{"op":"mcm","clk":"1003241528","pt":1580605013215,"mc":[{"id":"1.168186840","marketDefinition":{"bspMarket":false,"turnInPlayEnabled":true,"persistenceEnabled":true,"marketBaseRate":5.0,"eventId":"29680287","eventTypeId":"2","numberOfWinners":1,"bettingType":"ODDS","marketType":"SET_WINNER","marketTime":"2020-02-02T02:54:00.000Z","suspendTime":"2020-02-02T02:54:00.000Z","bspReconciled":false,"complete":true,"inPlay":false,"crossMatching":false,"runnersVoidable":false,"numberOfActiveRunners":2,"betDelay":0,"status":"OPEN","runners":[{"status":"ACTIVE","sortPriority":1,"id":8173434,"name":"Taro Daniel"},{"status":"ACTIVE","sortPriority":2,"id":8639275,"name":"Yannick Hanfmann"}],"regulators":["MR_INT"],"countryCode":"AU","discountAllowed":true,"timezone":"UTC","openDate":"2020-02-02T03:00:00.000Z","version":3147960794,"name":"Set 2 Winner","eventName":"Daniel v Hanfmann"}}]}
{"op":"mcm","clk":"1003241745","pt":1580605016220,"mc":[{"id":"1.168186840","marketDefinition":{"bspMarket":false,"turnInPlayEnabled":true,"persistenceEnabled":true,"marketBaseRate":5.0,"eventId":"29680287","eventTypeId":"2","numberOfWinners":1,"bettingType":"ODDS","marketType":"SET_WINNER","marketTime":"2020-02-02T02:54:00.000Z","suspendTime":"2020-02-02T02:54:00.000Z","bspReconciled":false,"complete":true,"inPlay":false,"crossMatching":false,"runnersVoidable":false,"numberOfActiveRunners":2,"betDelay":0,"status":"OPEN","runners":[{"status":"ACTIVE","sortPriority":1,"id":8173434,"name":"Taro Daniel"},{"status":"ACTIVE","sortPriority":2,"id":8639275,"name":"Yannick Hanfmann"}],"regulators":["MR_INT"],"countryCode":"AU","discountAllowed":true,"timezone":"UTC","openDate":"2020-02-02T02:54:00.000Z","version":3147960794,"name":"Set 2 Winner","eventName":"Daniel v Hanfmann"}}]}
{"op":"mcm","clk":"1003743479","pt":1580612213601,"mc":[{"id":"1.168186840","marketDefinition":{"bspMarket":false,"turnInPlayEnabled":true,"persistenceEnabled":true,"marketBaseRate":5.0,"eventId":"29680287","eventTypeId":"2","numberOfWinners":1,"bettingType":"ODDS","marketType":"SET_WINNER","marketTime":"2020-02-02T03:09:00.000Z","suspendTime":"2020-02-02T03:09:00.000Z","bspReconciled":false,"complete":true,"inPlay":false,"crossMatching":false,"runnersVoidable":false,"numberOfActiveRunners":2,"betDelay":0,"status":"OPEN","runners":[{"status":"ACTIVE","sortPriority":1,"id":8173434,"name":"Taro Daniel"},{"status":"ACTIVE","sortPriority":2,"id":8639275,"name":"Yannick Hanfmann"}],"regulators":["MR_INT"],"countryCode":"AU","discountAllowed":true,"timezone":"UTC","openDate":"2020-02-02T02:54:00.000Z","version":3148075166,"name":"Set 2 Winner","eventName":"Daniel v Hanfmann"}}]}
{"op":"mcm","clk":"1003743595","pt":1580612215470,"mc":[{"id":"1.168186840","marketDefinition":{"bspMarket":false,"turnInPlayEnabled":true,"persistenceEnabled":true,"marketBaseRate":5.0,"eventId":"29680287","eventTypeId":"2","numberOfWinners":1,"bettingType":"ODDS","marketType":"SET_WINNER","marketTime":"2020-02-02T03:09:00.000Z","suspendTime":"2020-02-02T03:09:00.000Z","bspReconciled":false,"complete":true,"inPlay":false,"crossMatching":false,"runnersVoidable":false,"numberOfActiveRunners":2,"betDelay":0,"status":"OPEN","runners":[{"status":"ACTIVE","sortPriority":1,"id":8173434,"name":"Taro Daniel"},{"status":"ACTIVE","sortPriority":2,"id":8639275,"name":"Yannick Hanfmann"}],"regulators":["MR_INT"],"countryCode":"AU","discountAllowed":true,"timezone":"UTC","openDate":"2020-02-02T03:09:00.000Z","version":3148075166,"name":"Set 2 Winner","eventName":"Daniel v Hanfmann"}}]}
{"op":"mcm","clk":"1003792313","pt":1580613113519,"mc":[{"id":"1.168186840","marketDefinition":{"bspMarket":false,"turnInPlayEnabled":true,"persistenceEnabled":true,"marketBaseRate":5.0,"eventId":"29680287","eventTypeId":"2","numberOfWinners":1,"bettingType":"ODDS","marketType":"SET_WINNER","marketTime":"2020-02-02T03:24:00.000Z","suspendTime":"2020-02-02T03:24:00.000Z","bspReconciled":false,"complete":true,"inPlay":false,"crossMatching":false,"runnersVoidable":false,"numberOfActiveRunners":2,"betDelay":0,"status":"OPEN","runners":[{"status":"ACTIVE","sortPriority":1,"id":8173434,"name":"Taro Daniel"},{"status":"ACTIVE","sortPriority":2,"id":8639275,"name":"Yannick Hanfmann"}],"regulators":["MR_INT"],"countryCode":"AU","discountAllowed":true,"timezone":"UTC","openDate":"2020-02-02T03:09:00.000Z","version":3148099997,"name":"Set 2 Winner","eventName":"Daniel v Hanfmann"}}]}
{"op":"mcm","clk":"1003792394","pt":1580613115526,"mc":[{"id":"1.168186840","marketDefinition":{"bspMarket":false,"turnInPlayEnabled":true,"persistenceEnabled":true,"marketBaseRate":5.0,"eventId":"29680287","eventTypeId":"2","numberOfWinners":1,"bettingType":"ODDS","marketType":"SET_WINNER","marketTime":"2020-02-02T03:24:00.000Z","suspendTime":"2020-02-02T03:24:00.000Z","bspReconciled":false,"complete":true,"inPlay":false,"crossMatching":false,"runnersVoidable":false,"numberOfActiveRunners":2,"betDelay":0,"status":"OPEN","runners":[{"status":"ACTIVE","sortPriority":1,"id":8173434,"name":"Taro Daniel"},{"status":"ACTIVE","sortPriority":2,"id":8639275,"name":"Yannick Hanfmann"}],"regulators":["MR_INT"],"countryCode":"AU","discountAllowed":true,"timezone":"UTC","openDate":"2020-02-02T03:24:00.000Z","version":3148099997,"name":"Set 2 Winner","eventName":"Daniel v Hanfmann"}}]}
{"op":"mcm","clk":"1003804069","pt":1580613413219,"mc":[{"id":"1.168186840","marketDefinition":{"bspMarket":false,"turnInPlayEnabled":true,"persistenceEnabled":true,"marketBaseRate":5.0,"eventId":"29680287","eventTypeId":"2","numberOfWinners":1,"bettingType":"ODDS","marketType":"SET_WINNER","marketTime":"2020-02-02T03:33:00.000Z","suspendTime":"2020-02-02T03:33:00.000Z","bspReconciled":false,"complete":true,"inPlay":false,"crossMatching":false,"runnersVoidable":false,"numberOfActiveRunners":2,"betDelay":0,"status":"OPEN","runners":[{"status":"ACTIVE","sortPriority":1,"id":8173434,"name":"Taro Daniel"},{"status":"ACTIVE","sortPriority":2,"id":8639275,"name":"Yannick Hanfmann"}],"regulators":["MR_INT"],"countryCode":"AU","discountAllowed":true,"timezone":"UTC","openDate":"2020-02-02T03:24:00.000Z","version":3148104075,"name":"Set 2 Winner","eventName":"Daniel v Hanfmann"}}]}
{"op":"mcm","clk":"1003804278","pt":1580613417227,"mc":[{"id":"1.168186840","marketDefinition":{"bspMarket":false,"turnInPlayEnabled":true,"persistenceEnabled":true,"marketBaseRate":5.0,"eventId":"29680287","eventTypeId":"2","numberOfWinners":1,"bettingType":"ODDS","marketType":"SET_WINNER","marketTime":"2020-02-02T03:33:00.000Z","suspendTime":"2020-02-02T03:33:00.000Z","bspReconciled":false,"complete":true,"inPlay":false,"crossMatching":false,"runnersVoidable":false,"numberOfActiveRunners":2,"betDelay":0,"status":"OPEN","runners":[{"status":"ACTIVE","sortPriority":1,"id":8173434,"name":"Taro Daniel"},{"status":"ACTIVE","sortPriority":2,"id":8639275,"name":"Yannick Hanfmann"}],"regulators":["MR_INT"],"countryCode":"AU","discountAllowed":true,"timezone":"UTC","openDate":"2020-02-02T03:33:00.000Z","version":3148104075,"name":"Set 2 Winner","eventName":"Daniel v Hanfmann"}}]}
{"op":"mcm","clk":"1003844122","pt":1580614313152,"mc":[{"id":"1.168186840","marketDefinition":{"bspMarket":false,"turnInPlayEnabled":true,"persistenceEnabled":true,"marketBaseRate":5.0,"eventId":"29680287","eventTypeId":"2","numberOfWinners":1,"bettingType":"ODDS","marketType":"SET_WINNER","marketTime":"2020-02-02T03:48:00.000Z","suspendTime":"2020-02-02T03:48:00.000Z","bspReconciled":false,"complete":true,"inPlay":false,"crossMatching":false,"runnersVoidable":false,"numberOfActiveRunners":2,"betDelay":0,"status":"OPEN","runners":[{"status":"ACTIVE","sortPriority":1,"id":8173434,"name":"Taro Daniel"},{"status":"ACTIVE","sortPriority":2,"id":8639275,"name":"Yannick Hanfmann"}],"regulators":["MR_INT"],"countryCode":"AU","discountAllowed":true,"timezone":"UTC","openDate":"2020-02-02T03:33:00.000Z","version":3148118356,"name":"Set 2 Winner","eventName":"Daniel v Hanfmann"}}]}
{"op":"mcm","clk":"1003844287","pt":1580614316160,"mc":[{"id":"1.168186840","marketDefinition":{"bspMarket":false,"turnInPlayEnabled":true,"persistenceEnabled":true,"marketBaseRate":5.0,"eventId":"29680287","eventTypeId":"2","numberOfWinners":1,"bettingType":"ODDS","marketType":"SET_WINNER","marketTime":"2020-02-02T03:48:00.000Z","suspendTime":"2020-02-02T03:48:00.000Z","bspReconciled":false,"complete":true,"inPlay":false,"crossMatching":false,"runnersVoidable":false,"numberOfActiveRunners":2,"betDelay":0,"status":"OPEN","runners":[{"status":"ACTIVE","sortPriority":1,"id":8173434,"name":"Taro Daniel"},{"status":"ACTIVE","sortPriority":2,"id":8639275,"name":"Yannick Hanfmann"}],"regulators":["MR_INT"],"countryCode":"AU","discountAllowed":true,"timezone":"UTC","openDate":"2020-02-02T03:48:00.000Z","version":3148118356,"name":"Set 2 Winner","eventName":"Daniel v Hanfmann"}}]}
{"op":"mcm","clk":"1003884924","pt":1580615213127,"mc":[{"id":"1.168186840","marketDefinition":{"bspMarket":false,"turnInPlayEnabled":true,"persistenceEnabled":true,"marketBaseRate":5.0,"eventId":"29680287","eventTypeId":"2","numberOfWinners":1,"bettingType":"ODDS","marketType":"SET_WINNER","marketTime":"2020-02-02T04:03:00.000Z","suspendTime":"2020-02-02T04:03:00.000Z","bspReconciled":false,"complete":true,"inPlay":false,"crossMatching":false,"runnersVoidable":false,"numberOfActiveRunners":2,"betDelay":0,"status":"OPEN","runners":[{"status":"ACTIVE","sortPriority":1,"id":8173434,"name":"Taro Daniel"},{"status":"ACTIVE","sortPriority":2,"id":8639275,"name":"Yannick Hanfmann"}],"regulators":["MR_INT"],"countryCode":"AU","discountAllowed":true,"timezone":"UTC","openDate":"2020-02-02T03:48:00.000Z","version":3148131916,"name":"Set 2 Winner","eventName":"Daniel v Hanfmann"}}]}
{"op":"mcm","clk":"1003885260","pt":1580615222147,"mc":[{"id":"1.168186840","marketDefinition":{"bspMarket":false,"turnInPlayEnabled":true,"persistenceEnabled":true,"marketBaseRate":5.0,"eventId":"29680287","eventTypeId":"2","numberOfWinners":1,"bettingType":"ODDS","marketType":"SET_WINNER","marketTime":"2020-02-02T04:03:00.000Z","suspendTime":"2020-02-02T04:03:00.000Z","bspReconciled":false,"complete":true,"inPlay":false,"crossMatching":false,"runnersVoidable":false,"numberOfActiveRunners":2,"betDelay":0,"status":"OPEN","runners":[{"status":"ACTIVE","sortPriority":1,"id":8173434,"name":"Taro Daniel"},{"status":"ACTIVE","sortPriority":2,"id":8639275,"name":"Yannick Hanfmann"}],"regulators":["MR_INT"],"countryCode":"AU","discountAllowed":true,"timezone":"UTC","openDate":"2020-02-02T04:03:00.000Z","version":3148131916,"name":"Set 2 Winner","eventName":"Daniel v Hanfmann"}}]}
{"op":"mcm","clk":"1003917285","pt":1580616113068,"mc":[{"id":"1.168186840","marketDefinition":{"bspMarket":false,"turnInPlayEnabled":true,"persistenceEnabled":true,"marketBaseRate":5.0,"eventId":"29680287","eventTypeId":"2","numberOfWinners":1,"bettingType":"ODDS","marketType":"SET_WINNER","marketTime":"2020-02-02T04:18:00.000Z","suspendTime":"2020-02-02T04:18:00.000Z","bspReconciled":false,"complete":true,"inPlay":false,"crossMatching":false,"runnersVoidable":false,"numberOfActiveRunners":2,"betDelay":0,"status":"OPEN","runners":[{"status":"ACTIVE","sortPriority":1,"id":8173434,"name":"Taro Daniel"},{"status":"ACTIVE","sortPriority":2,"id":8639275,"name":"Yannick Hanfmann"}],"regulators":["MR_INT"],"countryCode":"AU","discountAllowed":true,"timezone":"UTC","openDate":"2020-02-02T04:03:00.000Z","version":3148141599,"name":"Set 2 Winner","eventName":"Daniel v Hanfmann"}}]}
{"op":"mcm","clk":"1003917423","pt":1580616116074,"mc":[{"id":"1.168186840","marketDefinition":{"bspMarket":false,"turnInPlayEnabled":true,"persistenceEnabled":true,"marketBaseRate":5.0,"eventId":"29680287","eventTypeId":"2","numberOfWinners":1,"bettingType":"ODDS","marketType":"SET_WINNER","marketTime":"2020-02-02T04:18:00.000Z","suspendTime":"2020-02-02T04:18:00.000Z","bspReconciled":false,"complete":true,"inPlay":false,"crossMatching":false,"runnersVoidable":false,"numberOfActiveRunners":2,"betDelay":0,"status":"OPEN","runners":[{"status":"ACTIVE","sortPriority":1,"id":8173434,"name":"Taro Daniel"},{"status":"ACTIVE","sortPriority":2,"id":8639275,"name":"Yannick Hanfmann"}],"regulators":["MR_INT"],"countryCode":"AU","discountAllowed":true,"timezone":"UTC","openDate":"2020-02-02T04:18:00.000Z","version":3148141599,"name":"Set 2 Winner","eventName":"Daniel v Hanfmann"}}]}
{"op":"mcm","clk":"1003958135","pt":1580617013090,"mc":[{"id":"1.168186840","marketDefinition":{"bspMarket":false,"turnInPlayEnabled":true,"persistenceEnabled":true,"marketBaseRate":5.0,"eventId":"29680287","eventTypeId":"2","numberOfWinners":1,"bettingType":"ODDS","marketType":"SET_WINNER","marketTime":"2020-02-02T04:33:00.000Z","suspendTime":"2020-02-02T04:33:00.000Z","bspReconciled":false,"complete":true,"inPlay":false,"crossMatching":false,"runnersVoidable":false,"numberOfActiveRunners":2,"betDelay":0,"status":"OPEN","runners":[{"status":"ACTIVE","sortPriority":1,"id":8173434,"name":"Taro Daniel"},{"status":"ACTIVE","sortPriority":2,"id":8639275,"name":"Yannick Hanfmann"}],"regulators":["MR_INT"],"countryCode":"AU","discountAllowed":true,"timezone":"UTC","openDate":"2020-02-02T04:18:00.000Z","version":3148155794,"name":"Set 2 Winner","eventName":"Daniel v Hanfmann"}}]}
{"op":"mcm","clk":"1003958235","pt":1580617015095,"mc":[{"id":"1.168186840","marketDefinition":{"bspMarket":false,"turnInPlayEnabled":true,"persistenceEnabled":true,"marketBaseRate":5.0,"eventId":"29680287","eventTypeId":"2","numberOfWinners":1,"bettingType":"ODDS","marketType":"SET_WINNER","marketTime":"2020-02-02T04:33:00.000Z","suspendTime":"2020-02-02T04:33:00.000Z","bspReconciled":false,"complete":true,"inPlay":false,"crossMatching":false,"runnersVoidable":false,"numberOfActiveRunners":2,"betDelay":0,"status":"OPEN","runners":[{"status":"ACTIVE","sortPriority":1,"id":8173434,"name":"Taro Daniel"},{"status":"ACTIVE","sortPriority":2,"id":8639275,"name":"Yannick Hanfmann"}],"regulators":["MR_INT"],"countryCode":"AU","discountAllowed":true,"timezone":"UTC","openDate":"2020-02-02T04:33:00.000Z","version":3148155794,"name":"Set 2 Winner","eventName":"Daniel v Hanfmann"}}]}
{"op":"mcm","clk":"1003999254","pt":1580617912895,"mc":[{"id":"1.168186840","marketDefinition":{"bspMarket":false,"turnInPlayEnabled":true,"persistenceEnabled":true,"marketBaseRate":5.0,"eventId":"29680287","eventTypeId":"2","numberOfWinners":1,"bettingType":"ODDS","marketType":"SET_WINNER","marketTime":"2020-02-02T04:48:00.000Z","suspendTime":"2020-02-02T04:48:00.000Z","bspReconciled":false,"complete":true,"inPlay":false,"crossMatching":false,"runnersVoidable":false,"numberOfActiveRunners":2,"betDelay":0,"status":"OPEN","runners":[{"status":"ACTIVE","sortPriority":1,"id":8173434,"name":"Taro Daniel"},{"status":"ACTIVE","sortPriority":2,"id":8639275,"name":"Yannick Hanfmann"}],"regulators":["MR_INT"],"countryCode":"AU","discountAllowed":true,"timezone":"UTC","openDate":"2020-02-02T04:33:00.000Z","version":3148160051,"name":"Set 2 Winner","eventName":"Daniel v Hanfmann"}}]}
{"op":"mcm","clk":"1003999478","pt":1580617916902,"mc":[{"id":"1.168186840","marketDefinition":{"bspMarket":false,"turnInPlayEnabled":true,"persistenceEnabled":true,"marketBaseRate":5.0,"eventId":"29680287","eventTypeId":"2","numberOfWinners":1,"bettingType":"ODDS","marketType":"SET_WINNER","marketTime":"2020-02-02T04:48:00.000Z","suspendTime":"2020-02-02T04:48:00.000Z","bspReconciled":false,"complete":true,"inPlay":false,"crossMatching":false,"runnersVoidable":false,"numberOfActiveRunners":2,"betDelay":0,"status":"OPEN","runners":[{"status":"ACTIVE","sortPriority":1,"id":8173434,"name":"Taro Daniel"},{"status":"ACTIVE","sortPriority":2,"id":8639275,"name":"Yannick Hanfmann"}],"regulators":["MR_INT"],"countryCode":"AU","discountAllowed":true,"timezone":"UTC","openDate":"2020-02-02T04:48:00.000Z","version":3148160051,"name":"Set 2 Winner","eventName":"Daniel v Hanfmann"}}]}
{"op":"mcm","clk":"1004042103","pt":1580618812677,"mc":[{"id":"1.168186840","marketDefinition":{"bspMarket":false,"turnInPlayEnabled":true,"persistenceEnabled":true,"marketBaseRate":5.0,"eventId":"29680287","eventTypeId":"2","numberOfWinners":1,"bettingType":"ODDS","marketType":"SET_WINNER","marketTime":"2020-02-02T05:03:00.000Z","suspendTime":"2020-02-02T05:03:00.000Z","bspReconciled":false,"complete":true,"inPlay":false,"crossMatching":false,"runnersVoidable":false,"numberOfActiveRunners":2,"betDelay":0,"status":"OPEN","runners":[{"status":"ACTIVE","sortPriority":1,"id":8173434,"name":"Taro Daniel"},{"status":"ACTIVE","sortPriority":2,"id":8639275,"name":"Yannick Hanfmann"}],"regulators":["MR_INT"],"countryCode":"AU","discountAllowed":true,"timezone":"UTC","openDate":"2020-02-02T04:48:00.000Z","version":3148167222,"name":"Set 2 Winner","eventName":"Daniel v Hanfmann"}}]}
{"op":"mcm","clk":"1004043048","pt":1580618830708,"mc":[{"id":"1.168186840","marketDefinition":{"bspMarket":false,"turnInPlayEnabled":true,"persistenceEnabled":true,"marketBaseRate":5.0,"eventId":"29680287","eventTypeId":"2","numberOfWinners":1,"bettingType":"ODDS","marketType":"SET_WINNER","marketTime":"2020-02-02T05:03:00.000Z","suspendTime":"2020-02-02T05:03:00.000Z","bspReconciled":false,"complete":true,"inPlay":false,"crossMatching":false,"runnersVoidable":false,"numberOfActiveRunners":2,"betDelay":0,"status":"OPEN","runners":[{"status":"ACTIVE","sortPriority":1,"id":8173434,"name":"Taro Daniel"},{"status":"ACTIVE","sortPriority":2,"id":8639275,"name":"Yannick Hanfmann"}],"regulators":["MR_INT"],"countryCode":"AU","discountAllowed":true,"timezone":"UTC","openDate":"2020-02-02T05:03:00.000Z","version":3148167222,"name":"Set 2 Winner","eventName":"Daniel v Hanfmann"}}]}
{"op":"mcm","clk":"1004076105","pt":1580619713479,"mc":[{"id":"1.168186840","marketDefinition":{"bspMarket":false,"turnInPlayEnabled":true,"persistenceEnabled":true,"marketBaseRate":5.0,"eventId":"29680287","eventTypeId":"2","numberOfWinners":1,"bettingType":"ODDS","marketType":"SET_WINNER","marketTime":"2020-02-02T05:18:00.000Z","suspendTime":"2020-02-02T05:18:00.000Z","bspReconciled":false,"complete":true,"inPlay":false,"crossMatching":false,"runnersVoidable":false,"numberOfActiveRunners":2,"betDelay":0,"status":"OPEN","runners":[{"status":"ACTIVE","sortPriority":1,"id":8173434,"name":"Taro Daniel"},{"status":"ACTIVE","sortPriority":2,"id":8639275,"name":"Yannick Hanfmann"}],"regulators":["MR_INT"],"countryCode":"AU","discountAllowed":true,"timezone":"UTC","openDate":"2020-02-02T05:03:00.000Z","version":3148176200,"name":"Set 2 Winner","eventName":"Daniel v Hanfmann"}}]}
{"op":"mcm","clk":"1004076270","pt":1580619716486,"mc":[{"id":"1.168186840","marketDefinition":{"bspMarket":false,"turnInPlayEnabled":true,"persistenceEnabled":true,"marketBaseRate":5.0,"eventId":"29680287","eventTypeId":"2","numberOfWinners":1,"bettingType":"ODDS","marketType":"SET_WINNER","marketTime":"2020-02-02T05:18:00.000Z","suspendTime":"2020-02-02T05:18:00.000Z","bspReconciled":false,"complete":true,"inPlay":false,"crossMatching":false,"runnersVoidable":false,"numberOfActiveRunners":2,"betDelay":0,"status":"OPEN","runners":[{"status":"ACTIVE","sortPriority":1,"id":8173434,"name":"Taro Daniel"},{"status":"ACTIVE","sortPriority":2,"id":8639275,"name":"Yannick Hanfmann"}],"regulators":["MR_INT"],"countryCode":"AU","discountAllowed":true,"timezone":"UTC","openDate":"2020-02-02T05:18:00.000Z","version":3148176200,"name":"Set 2 Winner","eventName":"Daniel v Hanfmann"}}]}
{"op":"mcm","clk":"1004111507","pt":1580620613279,"mc":[{"id":"1.168186840","marketDefinition":{"bspMarket":false,"turnInPlayEnabled":true,"persistenceEnabled":true,"marketBaseRate":5.0,"eventId":"29680287","eventTypeId":"2","numberOfWinners":1,"bettingType":"ODDS","marketType":"SET_WINNER","marketTime":"2020-02-02T05:33:00.000Z","suspendTime":"2020-02-02T05:33:00.000Z","bspReconciled":false,"complete":true,"inPlay":false,"crossMatching":false,"runnersVoidable":false,"numberOfActiveRunners":2,"betDelay":0,"status":"OPEN","runners":[{"status":"ACTIVE","sortPriority":1,"id":8173434,"name":"Taro Daniel"},{"status":"ACTIVE","sortPriority":2,"id":8639275,"name":"Yannick Hanfmann"}],"regulators":["MR_INT"],"countryCode":"AU","discountAllowed":true,"timezone":"UTC","openDate":"2020-02-02T05:18:00.000Z","version":3148190108,"name":"Set 2 Winner","eventName":"Daniel v Hanfmann"}}]}
{"op":"mcm","clk":"1004111685","pt":1580620616285,"mc":[{"id":"1.168186840","marketDefinition":{"bspMarket":false,"turnInPlayEnabled":true,"persistenceEnabled":true,"marketBaseRate":5.0,"eventId":"29680287","eventTypeId":"2","numberOfWinners":1,"bettingType":"ODDS","marketType":"SET_WINNER","marketTime":"2020-02-02T05:33:00.000Z","suspendTime":"2020-02-02T05:33:00.000Z","bspReconciled":false,"complete":true,"inPlay":false,"crossMatching":false,"runnersVoidable":false,"numberOfActiveRunners":2,"betDelay":0,"status":"OPEN","runners":[{"status":"ACTIVE","sortPriority":1,"id":8173434,"name":"Taro Daniel"},{"status":"ACTIVE","sortPriority":2,"id":8639275,"name":"Yannick Hanfmann"}],"regulators":["MR_INT"],"countryCode":"AU","discountAllowed":true,"timezone":"UTC","openDate":"2020-02-02T05:33:00.000Z","version":3148190108,"name":"Set 2 Winner","eventName":"Daniel v Hanfmann"}}]}
{"op":"mcm","clk":"1004151850","pt":1580621513271,"mc":[{"id":"1.168186840","marketDefinition":{"bspMarket":false,"turnInPlayEnabled":true,"persistenceEnabled":true,"marketBaseRate":5.0,"eventId":"29680287","eventTypeId":"2","numberOfWinners":1,"bettingType":"ODDS","marketType":"SET_WINNER","marketTime":"2020-02-02T05:48:00.000Z","suspendTime":"2020-02-02T05:48:00.000Z","bspReconciled":false,"complete":true,"inPlay":false,"crossMatching":false,"runnersVoidable":false,"numberOfActiveRunners":2,"betDelay":0,"status":"OPEN","runners":[{"status":"ACTIVE","sortPriority":1,"id":8173434,"name":"Taro Daniel"},{"status":"ACTIVE","sortPriority":2,"id":8639275,"name":"Yannick Hanfmann"}],"regulators":["MR_INT"],"countryCode":"AU","discountAllowed":true,"timezone":"UTC","openDate":"2020-02-02T05:33:00.000Z","version":3148205940,"name":"Set 2 Winner","eventName":"Daniel v Hanfmann"}}]}
{"op":"mcm","clk":"1004151955","pt":1580621516276,"mc":[{"id":"1.168186840","marketDefinition":{"bspMarket":false,"turnInPlayEnabled":true,"persistenceEnabled":true,"marketBaseRate":5.0,"eventId":"29680287","eventTypeId":"2","numberOfWinners":1,"bettingType":"ODDS","marketType":"SET_WINNER","marketTime":"2020-02-02T05:48:00.000Z","suspendTime":"2020-02-02T05:48:00.000Z","bspReconciled":false,"complete":true,"inPlay":false,"crossMatching":false,"runnersVoidable":false,"numberOfActiveRunners":2,"betDelay":0,"status":"OPEN","runners":[{"status":"ACTIVE","sortPriority":1,"id":8173434,"name":"Taro Daniel"},{"status":"ACTIVE","sortPriority":2,"id":8639275,"name":"Yannick Hanfmann"}],"regulators":["MR_INT"],"countryCode":"AU","discountAllowed":true,"timezone":"UTC","openDate":"2020-02-02T05:48:00.000Z","version":3148205940,"name":"Set 2 Winner","eventName":"Daniel v Hanfmann"}}]}
{"op":"mcm","clk":"1004183498","pt":1580622413114,"mc":[{"id":"1.168186840","marketDefinition":{"bspMarket":false,"turnInPlayEnabled":true,"persistenceEnabled":true,"marketBaseRate":5.0,"eventId":"29680287","eventTypeId":"2","numberOfWinners":1,"bettingType":"ODDS","marketType":"SET_WINNER","marketTime":"2020-02-02T06:03:00.000Z","suspendTime":"2020-02-02T06:03:00.000Z","bspReconciled":false,"complete":true,"inPlay":false,"crossMatching":false,"runnersVoidable":false,"numberOfActiveRunners":2,"betDelay":0,"status":"OPEN","runners":[{"status":"ACTIVE","sortPriority":1,"id":8173434,"name":"Taro Daniel"},{"status":"ACTIVE","sortPriority":2,"id":8639275,"name":"Yannick Hanfmann"}],"regulators":["MR_INT"],"countryCode":"AU","discountAllowed":true,"timezone":"UTC","openDate":"2020-02-02T05:48:00.000Z","version":3148212367,"name":"Set 2 Winner","eventName":"Daniel v Hanfmann"}}]}
{"op":"mcm","clk":"1004184590","pt":1580622440175,"mc":[{"id":"1.168186840","marketDefinition":{"bspMarket":false,"turnInPlayEnabled":true,"persistenceEnabled":true,"marketBaseRate":5.0,"eventId":"29680287","eventTypeId":"2","numberOfWinners":1,"bettingType":"ODDS","marketType":"SET_WINNER","marketTime":"2020-02-02T06:03:00.000Z","suspendTime":"2020-02-02T06:03:00.000Z","bspReconciled":false,"complete":true,"inPlay":false,"crossMatching":false,"runnersVoidable":false,"numberOfActiveRunners":2,"betDelay":0,"status":"OPEN","runners":[{"status":"ACTIVE","sortPriority":1,"id":8173434,"name":"Taro Daniel"},{"status":"ACTIVE","sortPriority":2,"id":8639275,"name":"Yannick Hanfmann"}],"regulators":["MR_INT"],"countryCode":"AU","discountAllowed":true,"timezone":"UTC","openDate":"2020-02-02T06:03:00.000Z","version":3148212367,"name":"Set 2 Winner","eventName":"Daniel v Hanfmann"}}]}
{"op":"mcm","clk":"1004211888","pt":1580623312961,"mc":[{"id":"1.168186840","marketDefinition":{"bspMarket":false,"turnInPlayEnabled":true,"persistenceEnabled":true,"marketBaseRate":5.0,"eventId":"29680287","eventTypeId":"2","numberOfWinners":1,"bettingType":"ODDS","marketType":"SET_WINNER","marketTime":"2020-02-02T06:18:00.000Z","suspendTime":"2020-02-02T06:18:00.000Z","bspReconciled":false,"complete":true,"inPlay":false,"crossMatching":false,"runnersVoidable":false,"numberOfActiveRunners":2,"betDelay":0,"status":"OPEN","runners":[{"status":"ACTIVE","sortPriority":1,"id":8173434,"name":"Taro Daniel"},{"status":"ACTIVE","sortPriority":2,"id":8639275,"name":"Yannick Hanfmann"}],"regulators":["MR_INT"],"countryCode":"AU","discountAllowed":true,"timezone":"UTC","openDate":"2020-02-02T06:03:00.000Z","version":3148224741,"name":"Set 2 Winner","eventName":"Daniel v Hanfmann"}}]}
{"op":"mcm","clk":"1004211992","pt":1580623315969,"mc":[{"id":"1.168186840","marketDefinition":{"bspMarket":false,"turnInPlayEnabled":true,"persistenceEnabled":true,"marketBaseRate":5.0,"eventId":"29680287","eventTypeId":"2","numberOfWinners":1,"bettingType":"ODDS","marketType":"SET_WINNER","marketTime":"2020-02-02T06:18:00.000Z","suspendTime":"2020-02-02T06:18:00.000Z","bspReconciled":false,"complete":true,"inPlay":false,"crossMatching":false,"runnersVoidable":false,"numberOfActiveRunners":2,"betDelay":0,"status":"OPEN","runners":[{"status":"ACTIVE","sortPriority":1,"id":8173434,"name":"Taro Daniel"},{"status":"ACTIVE","sortPriority":2,"id":8639275,"name":"Yannick Hanfmann"}],"regulators":["MR_INT"],"countryCode":"AU","discountAllowed":true,"timezone":"UTC","openDate":"2020-02-02T06:18:00.000Z","version":3148224741,"name":"Set 2 Winner","eventName":"Daniel v Hanfmann"}}]}
{"op":"mcm","clk":"1004239219","pt":1580624212832,"mc":[{"id":"1.168186840","marketDefinition":{"bspMarket":false,"turnInPlayEnabled":true,"persistenceEnabled":true,"marketBaseRate":5.0,"eventId":"29680287","eventTypeId":"2","numberOfWinners":1,"bettingType":"ODDS","marketType":"SET_WINNER","marketTime":"2020-02-02T06:33:00.000Z","suspendTime":"2020-02-02T06:33:00.000Z","bspReconciled":false,"complete":true,"inPlay":false,"crossMatching":false,"runnersVoidable":false,"numberOfActiveRunners":2,"betDelay":0,"status":"OPEN","runners":[{"status":"ACTIVE","sortPriority":1,"id":8173434,"name":"Taro Daniel"},{"status":"ACTIVE","sortPriority":2,"id":8639275,"name":"Yannick Hanfmann"}],"regulators":["MR_INT"],"countryCode":"AU","discountAllowed":true,"timezone":"UTC","openDate":"2020-02-02T06:18:00.000Z","version":3148240056,"name":"Set 2 Winner","eventName":"Daniel v Hanfmann"}}]}
{"op":"mcm","clk":"1004239304","pt":1580624215838,"mc":[{"id":"1.168186840","marketDefinition":{"bspMarket":false,"turnInPlayEnabled":true,"persistenceEnabled":true,"marketBaseRate":5.0,"eventId":"29680287","eventTypeId":"2","numberOfWinners":1,"bettingType":"ODDS","marketType":"SET_WINNER","marketTime":"2020-02-02T06:33:00.000Z","suspendTime":"2020-02-02T06:33:00.000Z","bspReconciled":false,"complete":true,"inPlay":false,"crossMatching":false,"runnersVoidable":false,"numberOfActiveRunners":2,"betDelay":0,"status":"OPEN","runners":[{"status":"ACTIVE","sortPriority":1,"id":8173434,"name":"Taro Daniel"},{"status":"ACTIVE","sortPriority":2,"id":8639275,"name":"Yannick Hanfmann"}],"regulators":["MR_INT"],"countryCode":"AU","discountAllowed":true,"timezone":"UTC","openDate":"2020-02-02T06:33:00.000Z","version":3148240056,"name":"Set 2 Winner","eventName":"Daniel v Hanfmann"}}]}
{"op":"mcm","clk":"1004267027","pt":1580625113633,"mc":[{"id":"1.168186840","marketDefinition":{"bspMarket":false,"turnInPlayEnabled":true,"persistenceEnabled":true,"marketBaseRate":5.0,"eventId":"29680287","eventTypeId":"2","numberOfWinners":1,"bettingType":"ODDS","marketType":"SET_WINNER","marketTime":"2020-02-02T06:48:00.000Z","suspendTime":"2020-02-02T06:48:00.000Z","bspReconciled":false,"complete":true,"inPlay":false,"crossMatching":false,"runnersVoidable":false,"numberOfActiveRunners":2,"betDelay":0,"status":"OPEN","runners":[{"status":"ACTIVE","sortPriority":1,"id":8173434,"name":"Taro Daniel"},{"status":"ACTIVE","sortPriority":2,"id":8639275,"name":"Yannick Hanfmann"}],"regulators":["MR_INT"],"countryCode":"AU","discountAllowed":true,"timezone":"UTC","openDate":"2020-02-02T06:33:00.000Z","version":3148248258,"name":"Set 2 Winner","eventName":"Daniel v Hanfmann"}}]}
{"op":"mcm","clk":"1004267120","pt":1580625115637,"mc":[{"id":"1.168186840","marketDefinition":{"bspMarket":false,"turnInPlayEnabled":true,"persistenceEnabled":true,"marketBaseRate":5.0,"eventId":"29680287","eventTypeId":"2","numberOfWinners":1,"bettingType":"ODDS","marketType":"SET_WINNER","marketTime":"2020-02-02T06:48:00.000Z","suspendTime":"2020-02-02T06:48:00.000Z","bspReconciled":false,"complete":true,"inPlay":false,"crossMatching":false,"runnersVoidable":false,"numberOfActiveRunners":2,"betDelay":0,"status":"OPEN","runners":[{"status":"ACTIVE","sortPriority":1,"id":8173434,"name":"Taro Daniel"},{"status":"ACTIVE","sortPriority":2,"id":8639275,"name":"Yannick Hanfmann"}],"regulators":["MR_INT"],"countryCode":"AU","discountAllowed":true,"timezone":"UTC","openDate":"2020-02-02T06:48:00.000Z","version":3148248258,"name":"Set 2 Winner","eventName":"Daniel v Hanfmann"}}]}
{"op":"mcm","clk":"1004280009","pt":1580625538410,"mc":[{"id":"1.168186840","rc":[{"batb":[[0,1.84,37.77],[1,1.01,11.02]],"ltp":0.0,"tv":0.0,"id":8639275},{"batb":[[0,2.04,53.9],[1,1.01,11.02]],"ltp":0.0,"tv":0.0,"id":8173434}]}]}
{"op":"mcm","clk":"1004280171","pt":1580625542533,"mc":[{"id":"1.168186840","marketDefinition":{"bspMarket":false,"turnInPlayEnabled":true,"persistenceEnabled":true,"marketBaseRate":5.0,"eventId":"29680287","eventTypeId":"2","numberOfWinners":1,"bettingType":"ODDS","marketType":"SET_WINNER","marketTime":"2020-02-02T06:48:00.000Z","suspendTime":"2020-02-02T06:48:00.000Z","bspReconciled":false,"complete":true,"inPlay":false,"crossMatching":true,"runnersVoidable":false,"numberOfActiveRunners":2,"betDelay":0,"status":"OPEN","runners":[{"status":"ACTIVE","sortPriority":1,"id":8173434,"name":"Taro Daniel"},{"status":"ACTIVE","sortPriority":2,"id":8639275,"name":"Yannick Hanfmann"}],"regulators":["MR_INT"],"countryCode":"AU","discountAllowed":true,"timezone":"UTC","openDate":"2020-02-02T06:48:00.000Z","version":3148248258,"name":"Set 2 Winner","eventName":"Daniel v Hanfmann"}}]}
{"op":"mcm","clk":"1004286954","pt":1580625713660,"mc":[{"id":"1.168186840","marketDefinition":{"bspMarket":false,"turnInPlayEnabled":true,"persistenceEnabled":true,"marketBaseRate":5.0,"eventId":"29680287","eventTypeId":"2","numberOfWinners":1,"bettingType":"ODDS","marketType":"SET_WINNER","marketTime":"2020-02-02T06:37:00.000Z","suspendTime":"2020-02-02T06:37:00.000Z","bspReconciled":false,"complete":true,"inPlay":false,"crossMatching":true,"runnersVoidable":false,"numberOfActiveRunners":2,"betDelay":0,"status":"OPEN","runners":[{"status":"ACTIVE","sortPriority":1,"id":8173434,"name":"Taro Daniel"},{"status":"ACTIVE","sortPriority":2,"id":8639275,"name":"Yannick Hanfmann"}],"regulators":["MR_INT"],"countryCode":"AU","discountAllowed":true,"timezone":"UTC","openDate":"2020-02-02T06:48:00.000Z","version":3148253847,"name":"Set 2 Winner","eventName":"Daniel v Hanfmann"}}]}
{"op":"mcm","clk":"1004287082","pt":1580625716763,"mc":[{"id":"1.168186840","marketDefinition":{"bspMarket":false,"turnInPlayEnabled":true,"persistenceEnabled":true,"marketBaseRate":5.0,"eventId":"29680287","eventTypeId":"2","numberOfWinners":1,"bettingType":"ODDS","marketType":"SET_WINNER","marketTime":"2020-02-02T06:37:00.000Z","suspendTime":"2020-02-02T06:37:00.000Z","bspReconciled":false,"complete":true,"inPlay":false,"crossMatching":true,"runnersVoidable":false,"numberOfActiveRunners":2,"betDelay":0,"status":"OPEN","runners":[{"status":"ACTIVE","sortPriority":1,"id":8173434,"name":"Taro Daniel"},{"status":"ACTIVE","sortPriority":2,"id":8639275,"name":"Yannick Hanfmann"}],"regulators":["MR_INT"],"countryCode":"AU","discountAllowed":true,"timezone":"UTC","openDate":"2020-02-02T06:37:00.000Z","version":3148253847,"name":"Set 2 Winner","eventName":"Daniel v Hanfmann"}}]}
{"op":"mcm","clk":"1004295533","pt":1580626084688,"mc":[{"id":"1.168186840","marketDefinition":{"bspMarket":false,"turnInPlayEnabled":true,"persistenceEnabled":true,"marketBaseRate":5.0,"eventId":"29680287","eventTypeId":"2","numberOfWinners":1,"bettingType":"ODDS","marketType":"SET_WINNER","marketTime":"2020-02-02T06:37:00.000Z","suspendTime":"2020-02-02T06:37:00.000Z","bspReconciled":false,"complete":true,"inPlay":false,"crossMatching":true,"runnersVoidable":false,"numberOfActiveRunners":2,"betDelay":0,"status":"OPEN","runners":[{"status":"ACTIVE","sortPriority":1,"id":8173434,"name":"Taro Daniel"},{"status":"ACTIVE","sortPriority":2,"id":8639275,"name":"Yannick Hanfmann"}],"regulators":["MR_INT"],"countryCode":"AU","discountAllowed":true,"timezone":"UTC","openDate":"2020-02-02T06:37:00.000Z","version":3148253847,"name":"Set 2 Winner","eventName":"Daniel v Hanfmann"},"rc":[{"batb":[[0,1.01,11.02],[1,1.01,0]],"ltp":0.0,"tv":0.0,"id":8639275},{"batb":[[0,1.01,11.02],[1,1.01,0]],"ltp":0.0,"tv":0.0,"id":8173434}]}]}
{"op":"mcm","clk":"1004295537","pt":1580626084788,"mc":[{"id":"1.168186840","marketDefinition":{"bspMarket":false,"turnInPlayEnabled":true,"persistenceEnabled":true,"marketBaseRate":5.0,"eventId":"29680287","eventTypeId":"2","numberOfWinners":1,"bettingType":"ODDS","marketType":"SET_WINNER","marketTime":"2020-02-02T06:37:00.000Z","suspendTime":"2020-02-02T06:37:00.000Z","bspReconciled":false,"complete":true,"inPlay":true,"crossMatching":true,"runnersVoidable":false,"numberOfActiveRunners":2,"betDelay":3,"status":"OPEN","runners":[{"status":"ACTIVE","sortPriority":1,"id":8173434,"name":"Taro Daniel"},{"status":"ACTIVE","sortPriority":2,"id":8639275,"name":"Yannick Hanfmann"}],"regulators":["MR_INT"],"countryCode":"AU","discountAllowed":true,"timezone":"UTC","openDate":"2020-02-02T06:37:00.000Z","version":3148255424,"name":"Set 2 Winner","eventName":"Daniel v Hanfmann"},"rc":[{"batb":[[0,1.01,10.52]],"ltp":0.0,"tv":0.0,"id":8639275},{"batb":[[0,1.01,10.52]],"ltp":0.0,"tv":0.0,"id":8173434}]}]}
{"op":"mcm","clk":"1004296272","pt":1580626118669,"mc":[{"id":"1.168186840","rc":[{"batb":[[0,1.55,166.59],[1,1.01,10.52]],"ltp":0.0,"tv":0.0,"id":8639275}]}]}
{"op":"mcm","clk":"1004296289","pt":1580626119281,"mc":[{"id":"1.168186840","rc":[{"batb":[[0,1.86,36.19],[1,1.83,38.71],[2,1.01,10.52]],"ltp":0.0,"tv":0.0,"id":8639275},{"batb":[[0,2.02,56.34],[1,2,58.15],[2,1.01,10.52]],"ltp":0.0,"tv":0.0,"id":8173434}]}]}
{"op":"mcm","clk":"1004296590","pt":1580626130693,"mc":[{"id":"1.168186840","rc":[{"batb":[[0,1.83,38.71],[1,1.01,10.52],[2,1.01,0]],"ltp":0.0,"tv":0.0,"id":8639275},{"batb":[[0,2,58.15],[1,1.01,10.52],[2,1.01,0]],"ltp":0.0,"tv":0.0,"id":8173434}]}]}
{"op":"mcm","clk":"1004297097","pt":1580626150543,"mc":[{"id":"1.168186840","rc":[{"batb":[[0,1.88,35.09],[1,1.84,37.61],[2,1.01,10.52]],"ltp":0.0,"tv":0.0,"id":8639275},{"batb":[[1,1.98,59.88],[2,1.01,10.52]],"ltp":0.0,"tv":0.0,"id":8173434}]}]}
{"op":"mcm","clk":"1004297511","pt":1580626167587,"mc":[{"id":"1.168186840","rc":[{"batb":[[0,1.84,37.61],[1,1.01,10.52],[2,1.01,0]],"ltp":0.0,"tv":0.0,"id":8639275},{"batb":[[0,1.98,59.88],[1,1.01,10.52],[2,1.01,0]],"ltp":0.0,"tv":0.0,"id":8173434}]}]}
{"op":"mcm","clk":"1004297612","pt":1580626170670,"mc":[{"id":"1.168186840","rc":[{"batb":[[0,1.85,36.98]],"ltp":0.0,"tv":0.0,"id":8639275},{"batb":[[0,1.97,60.9]],"ltp":0.0,"tv":0.0,"id":8173434}]}]}
{"op":"mcm","clk":"1004298549","pt":1580626199604,"mc":[{"id":"1.168186840","rc":[{"batb":[[1,1.82,39.26],[2,1.01,10.52]],"ltp":0.0,"tv":0.0,"id":8639275},{"batb":[[0,2.04,55.08],[1,2,57.52],[2,1.97,11.53]],"ltp":0.0,"tv":0.0,"id":8173434}]}]}
{"op":"mcm","clk":"1004298584","pt":1580626200525,"mc":[{"id":"1.168186840","rc":[{"batb":[[2,1.01,10.52]],"ltp":0.0,"tv":0.0,"id":8173434}]}]}
{"op":"mcm","clk":"1004299292","pt":1580626219649,"mc":[{"id":"1.168186840","rc":[{"batb":[[0,1.82,39.26],[1,1.01,10.52],[2,1.01,0]],"ltp":0.0,"tv":0.0,"id":8639275},{"batb":[[0,2,57.52],[1,1.01,10.52],[2,1.01,0]],"ltp":0.0,"tv":0.0,"id":8173434}]}]}
{"op":"mcm","clk":"1004299317","pt":1580626220365,"mc":[{"id":"1.168186840","rc":[{"batb":[[0,1.82,38.79]],"ltp":0.0,"tv":0.0,"id":8639275}]}]}
{"op":"mcm","clk":"1004299720","pt":1580626233538,"mc":[{"id":"1.168186840","rc":[{"batb":[[0,2,171.32]],"ltp":0.0,"tv":0.0,"id":8173434}]}]}
{"op":"mcm","clk":"1004299741","pt":1580626234256,"mc":[{"id":"1.168186840","rc":[{"batb":[[1,1.77,43.2],[2,1.01,10.52]],"ltp":0.0,"tv":0.0,"id":8639275},{"batb":[[0,2.06,52.4],[1,2.04,54.29],[2,1.01,10.52]],"ltp":0.0,"tv":0.0,"id":8173434}]}]}
{"op":"mcm","clk":"1004300412","pt":1580626253680,"mc":[{"id":"1.168186840","rc":[{"batb":[[0,1.77,43.2],[1,1.01,10.52],[2,1.01,0]],"ltp":0.0,"tv":0.0,"id":8639275},{"batb":[[0,2.04,54.29],[1,1.01,10.52],[2,1.01,0]],"ltp":0.0,"tv":0.0,"id":8173434}]}]}
{"op":"mcm","clk":"1004300507","pt":1580626256303,"mc":[{"id":"1.168186840","rc":[{"batb":[[0,1.76,43.35]],"ltp":0.0,"tv":0.0,"id":8639275},{"batb":[[0,2.04,54.05]],"ltp":0.0,"tv":0.0,"id":8173434}]}]}
{"op":"mcm","clk":"1004301313","pt":1580626284625,"mc":[{"id":"1.168186840","rc":[{"batb":[[0,1.84,37.69],[1,1.8,40.36],[2,1.77,209.72]],"ltp":0.0,"tv":0.0,"id":8639275},{"batb":[[1,2.02,56.02],[2,1.01,10.52]],"ltp":0.0,"tv":0.0,"id":8173434}]}]}
{"op":"mcm","clk":"1004301342","pt":1580626285648,"mc":[{"id":"1.168186840","rc":[{"batb":[[2,1.01,10.52]],"ltp":0.0,"tv":0.0,"id":8639275}]}]}
{"op":"mcm","clk":"1004301781","pt":1580626301766,"mc":[{"id":"1.168186840","rc":[{"batb":[[0,1.8,40.36],[1,1.01,10.52],[2,1.01,0]],"ltp":0.0,"tv":0.0,"id":8639275},{"batb":[[0,2.02,56.02],[1,1.01,10.52],[2,1.01,0]],"ltp":0.0,"tv":0.0,"id":8173434}]}]}
{"op":"mcm","clk":"1004302451","pt":1580626321692,"mc":[{"id":"1.168186840","rc":[{"batb":[[0,1.86,36.35],[1,1.84,37.77],[2,1.8,143.03]],"ltp":0.0,"tv":0.0,"id":8639275},{"batb":[[1,1.97,60.82],[2,1.01,10.52]],"ltp":0.0,"tv":0.0,"id":8173434}]}]}
{"op":"mcm","clk":"1004302475","pt":1580626322203,"mc":[{"id":"1.168186840","rc":[{"batb":[[2,1.01,10.52]],"ltp":0.0,"tv":0.0,"id":8639275}]}]}
{"op":"mcm","clk":"1004302569","pt":1580626324824,"mc":[{"id":"1.168186840","rc":[{"batl":[[0,2.6,257.57]],"ltp":0.0,"tv":0.0,"id":8639275},{"batl":[[0,2.6,257.57]],"ltp":0.0,"tv":0.0,"id":8173434}]}]}
{"op":"mcm","clk":"1004304518","pt":1580626378491,"mc":[{"id":"1.168186840","rc":[{"batb":[[0,1.84,37.61],[1,1.01,10.52],[2,1.01,0]],"ltp":0.0,"tv":0.0,"id":8639275},{"batb":[[0,1.97,60.82],[1,1.01,10.52],[2,1.01,0]],"ltp":0.0,"tv":0.0,"id":8173434}]}]}
{"op":"mcm","clk":"1004304876","pt":1580626388322,"mc":[{"id":"1.168186840","rc":[{"batb":[[1,1.82,38.79],[2,1.01,10.52]],"ltp":0.0,"tv":0.0,"id":8639275},{"batb":[[0,2.04,54.05],[1,1.99,58.93],[2,1.01,10.52]],"ltp":0.0,"tv":0.0,"id":8173434}]}]}
{"op":"mcm","clk":"1004305248","pt":1580626398117,"mc":[{"id":"1.168186840","rc":[{"batb":[[0,1.82,38.79],[1,1.01,10.52],[2,1.01,0]],"ltp":0.0,"tv":0.0,"id":8639275},{"batb":[[0,1.99,58.93],[1,1.01,10.52],[2,1.01,0]],"ltp":0.0,"tv":0.0,"id":8173434}]}]}
{"op":"mcm","clk":"1004305376","pt":1580626401617,"mc":[{"id":"1.168186840","rc":[{"batb":[[0,1.83,38.71]],"ltp":0.0,"tv":0.0,"id":8639275},{"batb":[[0,2,58.07]],"ltp":0.0,"tv":0.0,"id":8173434}]}]}
{"op":"mcm","clk":"1004305645","pt":1580626407663,"mc":[{"id":"1.168186840","rc":[{"batb":[[1,1.81,39.81],[2,1.01,10.52]],"ltp":0.0,"tv":0.0,"id":8639275},{"batb":[[0,2.06,52.56],[1,2.02,56.26],[2,2,58.07]],"ltp":0.0,"tv":0.0,"id":8173434}]}]}
{"op":"mcm","clk":"1004305665","pt":1580626408235,"mc":[{"id":"1.168186840","rc":[{"batb":[[2,1.01,10.52]],"ltp":0.0,"tv":0.0,"id":8173434}]}]}
{"op":"mcm","clk":"1004306216","pt":1580626421464,"mc":[{"id":"1.168186840","rc":[{"batb":[[0,1.81,39.81],[1,1.01,10.52],[2,1.01,0]],"ltp":0.0,"tv":0.0,"id":8639275},{"batb":[[0,2.02,56.26],[1,1.01,10.52],[2,1.01,0]],"ltp":0.0,"tv":0.0,"id":8173434}]}]}
{"op":"mcm","clk":"1004306761","pt":1580626437587,"mc":[{"id":"1.168186840","rc":[{"batb":[[0,1.86,36.67],[1,1.84,37.92],[2,1.01,10.52]],"ltp":0.0,"tv":0.0,"id":8639275},{"batb":[[0,2.02,55.63],[1,1.98,60.43],[2,1.01,10.52]],"ltp":0.0,"tv":0.0,"id":8173434}]}]}
{"op":"mcm","clk":"1004307246","pt":1580626451320,"mc":[{"id":"1.168186840","rc":[{"batb":[[0,1.84,37.92],[1,1.01,10.52],[2,1.01,0]],"ltp":0.0,"tv":0.0,"id":8639275},{"batb":[[0,1.98,60.43],[1,1.01,10.52],[2,1.01,0]],"ltp":0.0,"tv":0.0,"id":8173434}]}]}
{"op":"mcm","clk":"1004307949","pt":1580626473362,"mc":[{"id":"1.168186840","rc":[{"batb":[[1,1.82,39.1],[2,1.01,10.52]],"ltp":0.0,"tv":0.0,"id":8639275},{"batb":[[0,2.06,53.66],[1,2,57.44],[2,1.01,10.52]],"ltp":0.0,"tv":0.0,"id":8173434}]}]}
{"op":"mcm","clk":"1004308594","pt":1580626491684,"mc":[{"id":"1.168186840","rc":[{"batb":[[0,1.82,39.1],[1,1.01,10.52],[2,1.01,0]],"ltp":0.0,"tv":0.0,"id":8639275},{"batb":[[0,2,57.44],[1,1.01,10.52],[2,1.01,0]],"ltp":0.0,"tv":0.0,"id":8173434}]}]}
{"op":"mcm","clk":"1004308677","pt":1580626494566,"mc":[{"id":"1.168186840","rc":[{"batb":[[0,1.81,39.5]],"ltp":0.0,"tv":0.0,"id":8639275},{"batb":[[0,2.02,56.89]],"ltp":0.0,"tv":0.0,"id":8173434}]}]}
{"op":"mcm","clk":"1004309000","pt":1580626503510,"mc":[{"id":"1.168186840","rc":[{"batb":[[0,1.87,35.88],[1,1.85,36.9],[2,1.81,39.5]],"ltp":0.0,"tv":0.0,"id":8639275},{"batb":[[1,1.96,62],[2,1.01,10.52]],"ltp":0.0,"tv":0.0,"id":8173434}]}]}
{"op":"mcm","clk":"1004309032","pt":1580626504382,"mc":[{"id":"1.168186840","rc":[{"batb":[[2,1.01,10.52]],"ltp":0.0,"tv":0.0,"id":8639275}]}]}
{"op":"mcm","clk":"1004309723","pt":1580626522421,"mc":[{"id":"1.168186840","rc":[{"batb":[[0,1.85,36.9],[1,1.01,10.52],[2,1.01,0]],"ltp":0.0,"tv":0.0,"id":8639275},{"batb":[[0,1.96,62],[1,1.01,10.52],[2,1.01,0]],"ltp":0.0,"tv":0.0,"id":8173434}]}]}
{"op":"mcm","clk":"1004310140","pt":1580626532511,"mc":[{"id":"1.168186840","rc":[{"batb":[[1,1.81,40.05],[2,1.01,10.52]],"ltp":0.0,"tv":0.0,"id":8639275},{"batb":[[0,2.04,55.16],[1,2.02,56.81],[2,1.01,10.52]],"ltp":0.0,"tv":0.0,"id":8173434}]}]}
{"op":"mcm","clk":"1004311202","pt":1580626559470,"mc":[{"id":"1.168186840","rc":[{"batb":[[0,1.81,40.05],[1,1.01,10.52],[2,1.01,0]],"ltp":0.0,"tv":0.0,"id":8639275},{"batb":[[0,2.02,56.81],[1,1.01,10.52],[2,1.01,0]],"ltp":0.0,"tv":0.0,"id":8173434}]}]}
{"op":"mcm","clk":"1004311300","pt":1580626562456,"mc":[{"id":"1.168186840","rc":[{"batb":[[0,1.8,40.52]],"ltp":0.0,"tv":0.0,"id":8639275},{"batb":[[0,2.02,56.18]],"ltp":0.0,"tv":0.0,"id":8173434}]}]}
{"op":"mcm","clk":"1004311950","pt":1580626579505,"mc":[{"id":"1.168186840","rc":[{"batb":[[0,1.86,36.27],[1,1.82,39.1],[2,1.8,183.55]],"ltp":0.0,"tv":0.0,"id":8639275},{"batb":[[1,2,58.38],[2,1.01,10.52]],"ltp":0.0,"tv":0.0,"id":8173434}]}]}
{"op":"mcm","clk":"1004311982","pt":1580626580603,"mc":[{"id":"1.168186840","rc":[{"batb":[[2,1.01,10.52]],"ltp":0.0,"tv":0.0,"id":8639275}]}]}
{"op":"mcm","clk":"1004312644","pt":1580626594501,"mc":[{"id":"1.168186840","rc":[{"batb":[[0,1.82,39.1],[1,1.01,10.52],[2,1.01,0]],"ltp":0.0,"tv":0.0,"id":8639275},{"batb":[[0,2,58.38],[1,1.01,10.52],[2,1.01,0]],"ltp":0.0,"tv":0.0,"id":8173434}]}]}
{"op":"mcm","clk":"1004313444","pt":1580626620243,"mc":[{"id":"1.168186840","rc":[{"batb":[[0,1.89,34.93],[1,1.85,37.37],[2,1.01,10.52]],"ltp":0.0,"tv":0.0,"id":8639275},{"batb":[[1,1.97,60.74],[2,1.01,10.52]],"ltp":0.0,"tv":0.0,"id":8173434}]}]}
{"op":"mcm","clk":"1004313992","pt":1580626636482,"mc":[{"id":"1.168186840","rc":[{"batb":[[0,1.85,37.37],[1,1.01,10.52],[2,1.01,0]],"ltp":0.0,"tv":0.0,"id":8639275},{"batb":[[0,1.97,60.74],[1,1.01,10.52],[2,1.01,0]],"ltp":0.0,"tv":0.0,"id":8173434}]}]}
{"op":"mcm","clk":"1004314693","pt":1580626659651,"mc":[{"id":"1.168186840","rc":[{"batb":[[1,1.8,40.84],[2,1.01,10.52]],"ltp":0.0,"tv":0.0,"id":8639275},{"batb":[[0,2.04,54.53],[1,2.02,56.57],[2,1.98,11.76]],"ltp":0.0,"tv":0.0,"id":8173434}]}]}
{"op":"mcm","clk":"1004314700","pt":1580626659858,"mc":[{"id":"1.168186840","rc":[{"batb":[[2,1.01,10.52]],"ltp":0.0,"tv":0.0,"id":8173434}]}]}
{"op":"mcm","clk":"1004315335","pt":1580626678678,"mc":[{"id":"1.168186840","rc":[{"batb":[[0,1.8,40.84],[1,1.01,10.52],[2,1.01,0]],"ltp":0.0,"tv":0.0,"id":8639275},{"batb":[[0,2.02,56.57],[1,1.01,10.52],[2,1.01,0]],"ltp":0.0,"tv":0.0,"id":8173434}]}]}
{"op":"mcm","clk":"1004315905","pt":1580626696588,"mc":[{"id":"1.168186840","rc":[{"batb":[[0,1.87,35.96],[1,1.82,38.79],[2,1.01,10.52]],"ltp":0.0,"tv":0.0,"id":8639275},{"batb":[[1,2,58.54],[2,1.01,10.52]],"ltp":0.0,"tv":0.0,"id":8173434}]}]}
{"op":"mcm","clk":"1004316412","pt":1580626715305,"mc":[{"id":"1.168186840","rc":[{"batb":[[0,1.82,38.79],[1,1.01,10.52],[2,1.01,0]],"ltp":0.0,"tv":0.0,"id":8639275},{"batb":[[0,2,58.54],[1,1.01,10.52],[2,1.01,0]],"ltp":0.0,"tv":0.0,"id":8173434}]}]}
{"op":"mcm","clk":"1004316866","pt":1580626734652,"mc":[{"id":"1.168186840","rc":[{"batb":[[1,1.78,42.09],[2,1.01,10.52]],"ltp":0.0,"tv":0.0,"id":8639275},{"batb":[[0,2.06,52.48],[1,2.04,54.76],[2,1.01,10.52]],"ltp":0.0,"tv":0.0,"id":8173434}]}]}
{"op":"mcm","clk":"1004317366","pt":1580626753876,"mc":[{"id":"1.168186840","rc":[{"batb":[[0,1.78,41.78],[1,1.01,10.52],[2,1.01,0]],"ltp":0.0,"tv":0.0,"id":8639275},{"batb":[[0,2.04,54.76],[1,1.01,10.52],[2,1.01,0]],"ltp":0.0,"tv":0.0,"id":8173434}]}]}
{"op":"mcm","clk":"1004317709","pt":1580626764499,"mc":[{"id":"1.168186840","rc":[{"batb":[[0,1.85,36.9],[1,1.83,38.55],[2,1.01,10.52]],"ltp":0.0,"tv":0.0,"id":8639275},{"batb":[[1,1.98,60.11],[2,1.01,10.52]],"ltp":0.0,"tv":0.0,"id":8173434}]}]}
{"op":"mcm","clk":"1004320396","pt":1580626842640,"mc":[{"id":"1.168186840","rc":[{"batb":[[0,1.83,38.55],[1,1.01,10.52],[2,1.01,0]],"ltp":0.0,"tv":0.0,"id":8639275},{"batb":[[0,1.98,60.11],[1,1.01,10.52],[2,1.01,0]],"ltp":0.0,"tv":0.0,"id":8173434}]}]}
{"op":"mcm","clk":"1004321142","pt":1580626859660,"mc":[{"id":"1.168186840","rc":[{"batb":[[1,1.81,39.81],[2,1.01,10.52]],"ltp":0.0,"tv":0.0,"id":8639275},{"batb":[[0,2.06,52.87],[1,2.02,56.89],[2,1.98,60.11]],"ltp":0.0,"tv":0.0,"id":8173434}]}]}
{"op":"mcm","clk":"1004321195","pt":1580626860644,"mc":[{"id":"1.168186840","rc":[{"batb":[[2,1.01,10.52]],"ltp":0.0,"tv":0.0,"id":8173434}]}]}
{"op":"mcm","clk":"1004321475","pt":1580626868572,"mc":[{"id":"1.168186840","rc":[{"batb":[[0,1.81,39.81],[1,1.01,10.52],[2,1.01,0]],"ltp":0.0,"tv":0.0,"id":8639275},{"batb":[[0,2.02,56.89],[1,1.01,10.52],[2,1.01,0]],"ltp":0.0,"tv":0.0,"id":8173434}]}]}
{"op":"mcm","clk":"1004321734","pt":1580626877678,"mc":[{"id":"1.168186840","rc":[{"batb":[[1,1.79,41.07],[2,1.01,10.52]],"ltp":0.0,"tv":0.0,"id":8639275},{"batb":[[0,2.08,51.06],[1,2.04,55.08],[2,1.01,10.52]],"ltp":0.0,"tv":0.0,"id":8173434}]}]}
{"op":"mcm","clk":"1004321931","pt":1580626887027,"mc":[{"id":"1.168186840","rc":[{"batb":[[0,1.79,41.07],[1,1.01,10.52],[2,1.01,0]],"ltp":0.0,"tv":0.0,"id":8639275},{"batb":[[0,2.04,55.08],[1,1.01,10.52],[2,1.01,0]],"ltp":0.0,"tv":0.0,"id":8173434}]}]}
{"op":"mcm","clk":"1004322339","pt":1580626905618,"mc":[{"id":"1.168186840","rc":[{"batb":[[0,1.85,36.9],[1,1.84,38],[2,1.79,185]],"ltp":0.0,"tv":0.0,"id":8639275},{"batb":[[1,1.97,60.9],[2,1.01,10.52]],"ltp":0.0,"tv":0.0,"id":8173434}]}]}
{"op":"mcm","clk":"1004322346","pt":1580626905819,"mc":[{"id":"1.168186840","rc":[{"batb":[[2,1.01,10.52]],"ltp":0.0,"tv":0.0,"id":8639275}]}]}
{"op":"mcm","clk":"1004322680","pt":1580626918147,"mc":[{"id":"1.168186840","rc":[{"batb":[[0,1.84,38],[1,1.01,10.52],[2,1.01,0]],"ltp":0.0,"tv":0.0,"id":8639275},{"batb":[[0,1.97,60.9],[1,1.01,10.52],[2,1.01,0]],"ltp":0.0,"tv":0.0,"id":8173434}]}]}
{"op":"mcm","clk":"1004323105","pt":1580626936652,"mc":[{"id":"1.168186840","rc":[{"batb":[[1,1.82,39.1],[2,1.01,10.52]],"ltp":0.0,"tv":0.0,"id":8639275},{"batb":[[0,2.06,53.58],[1,2,57.67],[2,1.01,10.52]],"ltp":0.0,"tv":0.0,"id":8173434}]}]}
{"op":"mcm","clk":"1004323264","pt":1580626944683,"mc":[{"id":"1.168186840","rc":[{"batb":[[0,1.82,39.1],[1,1.01,10.52],[2,1.01,0]],"ltp":0.0,"tv":0.0,"id":8639275},{"batb":[[0,2,57.67],[1,1.01,10.52],[2,1.01,0]],"ltp":0.0,"tv":0.0,"id":8173434}]}]}
{"op":"mcm","clk":"1004323431","pt":1580626951697,"mc":[{"id":"1.168186840","rc":[{"batb":[[0,1.88,35.41],[1,1.85,36.98],[2,1.82,11.92]],"ltp":0.0,"tv":0.0,"id":8639275},{"batb":[[1,1.95,62.95],[2,1.01,10.52]],"ltp":0.0,"tv":0.0,"id":8173434}]}]}
{"op":"mcm","clk":"1004323775","pt":1580626963580,"mc":[{"id":"1.168186840","rc":[{"batb":[[0,1.85,36.98],[1,1.01,10.52],[2,1.82,0]],"ltp":0.0,"tv":0.0,"id":8639275},{"batb":[[0,1.95,62.95],[1,1.01,10.52],[2,1.01,0]],"ltp":0.0,"tv":0.0,"id":8173434}]}]}
{"op":"mcm","clk":"1004324413","pt":1580626988634,"mc":[{"id":"1.168186840","rc":[{"batb":[[0,1.93,32.42],[1,1.89,34.54],[2,1.86,617.11]],"ltp":0.0,"tv":0.0,"id":8639275},{"batb":[[1,1.89,34.93],[2,1.01,10.52]],"ltp":0.0,"tv":0.0,"id":8173434}]}]}
{"op":"mcm","clk":"1004324966","pt":1580627008681,"mc":[{"id":"1.168186840","rc":[{"batb":[[0,1.89,34.54],[1,1.01,10.52],[2,1.86,0]],"ltp":0.0,"tv":0.0,"id":8639275},{"batb":[[0,1.89,34.93],[1,1.01,10.52],[2,1.01,0]],"ltp":0.0,"tv":0.0,"id":8173434}]}]}
{"op":"mcm","clk":"1004325234","pt":1580627018698,"mc":[{"id":"1.168186840","rc":[{"batb":[[0,2,58.46],[1,1.94,31.94],[2,1.01,10.52]],"ltp":0.0,"tv":0.0,"id":8639275},{"batb":[[1,1.79,41.15],[2,1.01,10.52]],"ltp":0.0,"tv":0.0,"id":8173434}]}]}
{"op":"mcm","clk":"1004325346","pt":1580627022498,"mc":[{"id":"1.168186840","rc":[{"batb":[[2,1.86,20.47]],"ltp":0.0,"tv":0.0,"id":8639275}]}]}
{"op":"mcm","clk":"1004325672","pt":1580627034496,"mc":[{"id":"1.168186840","rc":[{"batb":[[0,1.94,31.94],[1,1.01,10.52],[2,1.86,0]],"ltp":0.0,"tv":0.0,"id":8639275},{"batb":[[0,1.79,41.15],[1,1.01,10.52],[2,1.01,0]],"ltp":0.0,"tv":0.0,"id":8173434}]}]}
{"op":"mcm","clk":"1004325692","pt":1580627035622,"mc":[{"id":"1.168186840","rc":[{"batb":[[0,1.79,40.99]],"ltp":0.0,"tv":0.0,"id":8173434}]}]}
{"op":"mcm","clk":"1004326122","pt":1580627049531,"mc":[{"id":"1.168186840","rc":[{"batb":[[1,1.91,33.6],[2,1.01,10.52]],"ltp":0.0,"tv":0.0,"id":8639275},{"batb":[[0,1.94,31.87],[1,1.87,35.64],[2,1.79,40.99]],"ltp":0.0,"tv":0.0,"id":8173434}]}]}
{"op":"mcm","clk":"1004326154","pt":1580627050616,"mc":[{"id":"1.168186840","rc":[{"batb":[[2,1.01,10.52]],"ltp":0.0,"tv":0.0,"id":8173434}]}]}
{"op":"mcm","clk":"1004326395","pt":1580627062350,"mc":[{"id":"1.168186840","rc":[{"batb":[[0,1.91,33.6],[1,1.01,10.52],[2,1.01,0]],"ltp":0.0,"tv":0.0,"id":8639275},{"batb":[[0,1.87,35.64],[1,1.01,10.52],[2,1.01,0]],"ltp":0.0,"tv":0.0,"id":8173434}]}]}
{"op":"mcm","clk":"1004326707","pt":1580627073551,"mc":[{"id":"1.168186840","rc":[{"batb":[[1,1.89,34.93],[2,1.01,10.52]],"ltp":0.0,"tv":0.0,"id":8639275},{"batb":[[0,1.97,60.74],[1,1.92,33.2],[2,1.01,10.52]],"ltp":0.0,"tv":0.0,"id":8173434}]}]}
{"op":"mcm","clk":"1004327182","pt":1580627087560,"mc":[{"id":"1.168186840","rc":[{"batb":[[0,1.89,34.93],[1,1.01,10.52],[2,1.01,0]],"ltp":0.0,"tv":0.0,"id":8639275},{"batb":[[0,1.92,33.2],[1,1.01,10.52],[2,1.01,0]],"ltp":0.0,"tv":0.0,"id":8173434}]}]}
{"op":"mcm","clk":"1004327255","pt":1580627089658,"mc":[{"id":"1.168186840","rc":[{"batb":[[1,1.88,34.93],[2,1.01,10.52]],"ltp":0.0,"tv":0.0,"id":8639275}]}]}
{"op":"mcm","clk":"1004327266","pt":1580627089964,"mc":[{"id":"1.168186840","rc":[{"batb":[[0,1.88,34.93],[1,1.01,10.52],[2,1.01,0]],"ltp":0.0,"tv":0.0,"id":8639275}]}]}
{"op":"mcm","clk":"1004327959","pt":1580627109406,"mc":[{"id":"1.168186840","rc":[{"batb":[[0,1.96,61.61],[1,1.93,32.65],[2,1.86,138.54]],"ltp":0.0,"tv":0.0,"id":8639275},{"batb":[[1,1.85,36.9],[2,1.01,10.52]],"ltp":0.0,"tv":0.0,"id":8173434}]}]}
{"op":"mcm","clk":"1004328472","pt":1580627122616,"mc":[{"id":"1.168186840","rc":[{"batb":[[0,1.93,32.65],[1,1.01,10.52],[2,1.86,0]],"ltp":0.0,"tv":0.0,"id":8639275},{"batb":[[0,1.85,36.9],[1,1.01,10.52],[2,1.01,0]],"ltp":0.0,"tv":0.0,"id":8173434}]}]}
{"op":"mcm","clk":"1004328716","pt":1580627129700,"mc":[{"id":"1.168186840","rc":[{"batb":[[1,1.9,33.99],[2,1.01,10.52]],"ltp":0.0,"tv":0.0,"id":8639275},{"batb":[[0,1.95,62.55],[1,1.91,33.83],[2,1.85,36.9]],"ltp":0.0,"tv":0.0,"id":8173434}]}]}
{"op":"mcm","clk":"1004328736","pt":1580627130622,"mc":[{"id":"1.168186840","rc":[{"batb":[[2,1.01,10.52]],"ltp":0.0,"tv":0.0,"id":8173434}]}]}
{"op":"mcm","clk":"1004329157","pt":1580627141626,"mc":[{"id":"1.168186840","rc":[{"batb":[[0,1.9,33.99],[1,1.01,10.52],[2,1.01,0]],"ltp":0.0,"tv":0.0,"id":8639275},{"batb":[[0,1.91,33.83],[1,1.01,10.52],[2,1.01,0]],"ltp":0.0,"tv":0.0,"id":8173434}]}]}
{"op":"mcm","clk":"1004330328","pt":1580627175652,"mc":[{"id":"1.168186840","rc":[{"batb":[[1,1.85,37.3],[2,1.01,10.52]],"ltp":0.0,"tv":0.0,"id":8639275},{"batb":[[0,1.98,59.96],[1,1.95,62.79],[2,1.01,10.52]],"ltp":0.0,"tv":0.0,"id":8173434}]}]}
{"op":"mcm","clk":"1004331660","pt":1580627215548,"mc":[{"id":"1.168186840","rc":[{"batb":[[0,1.85,37.3],[1,1.01,10.52],[2,1.01,0]],"ltp":0.0,"tv":0.0,"id":8639275},{"batb":[[0,1.95,62.79],[1,1.01,10.52],[2,1.01,0]],"ltp":0.0,"tv":0.0,"id":8173434}]}]}
{"op":"mcm","clk":"1004332948","pt":1580627248543,"mc":[{"id":"1.168186840","rc":[{"batb":[[1,1.79,41.15],[2,1.01,10.52]],"ltp":0.0,"tv":0.0,"id":8639275},{"batb":[[0,2.04,54.61],[1,2,57.83],[2,1.01,10.52]],"ltp":0.0,"tv":0.0,"id":8173434}]}]}
{"op":"mcm","clk":"1004333051","pt":1580627251521,"mc":[{"id":"1.168186840","rc":[{"batb":[[2,1.97,117.84]],"ltp":0.0,"tv":0.0,"id":8173434}]}]}
{"op":"mcm","clk":"1004333777","pt":1580627270619,"mc":[{"id":"1.168186840","rc":[{"batb":[[0,1.79,41.15],[1,1.01,10.52],[2,1.01,0]],"ltp":0.0,"tv":0.0,"id":8639275},{"batb":[[0,2,57.83],[1,1.01,10.52],[2,1.97,0]],"ltp":0.0,"tv":0.0,"id":8173434}]}]}
{"op":"mcm","clk":"1004334078","pt":1580627278597,"mc":[{"id":"1.168186840","rc":[{"batb":[[0,1.88,35.33],[1,1.82,39.18],[2,1.79,41.15]],"ltp":0.0,"tv":0.0,"id":8639275},{"batb":[[1,1.98,59.88],[2,1.01,10.52]],"ltp":0.0,"tv":0.0,"id":8173434}]}]}
{"op":"mcm","clk":"1004334105","pt":1580627279628,"mc":[{"id":"1.168186840","rc":[{"batb":[[2,1.01,10.52]],"ltp":0.0,"tv":0.0,"id":8639275}]}]}
{"op":"mcm","clk":"1004334868","pt":1580627298570,"mc":[{"id":"1.168186840","rc":[{"batb":[[0,1.82,39.18],[1,1.01,10.52],[2,1.01,0]],"ltp":0.0,"tv":0.0,"id":8639275},{"batb":[[0,1.98,59.88],[1,1.01,10.52],[2,1.01,0]],"ltp":0.0,"tv":0.0,"id":8173434}]}]}
{"op":"mcm","clk":"1004335900","pt":1580627329675,"mc":[{"id":"1.168186840","rc":[{"batb":[[0,1.9,34.15],[1,1.85,36.98],[2,1.01,10.52]],"ltp":0.0,"tv":0.0,"id":8639275},{"batb":[[1,1.95,62.71],[2,1.01,10.52]],"ltp":0.0,"tv":0.0,"id":8173434}]}]}
{"op":"mcm","clk":"1004336521","pt":1580627347297,"mc":[{"id":"1.168186840","rc":[{"batb":[[0,1.85,36.98],[1,1.01,10.52],[2,1.01,0]],"ltp":0.0,"tv":0.0,"id":8639275},{"batb":[[0,1.95,62.71],[1,1.01,10.52],[2,1.01,0]],"ltp":0.0,"tv":0.0,"id":8173434}]}]}
{"op":"mcm","clk":"1004336838","pt":1580627357407,"mc":[{"id":"1.168186840","rc":[{"batb":[[1,1.78,41.7],[2,1.01,10.52]],"ltp":0.0,"tv":0.0,"id":8639275},{"batb":[[0,2.04,55],[1,2,58.7],[2,1.97,122.84]],"ltp":0.0,"tv":0.0,"id":8173434}]}]}
{"op":"mcm","clk":"1004337432","pt":1580627374657,"mc":[{"id":"1.168186840","rc":[{"batb":[[0,1.78,41.7],[1,1.01,10.52],[2,1.01,0]],"ltp":0.0,"tv":0.0,"id":8639275},{"batb":[[0,2,58.7],[1,1.01,10.52],[2,1.97,0]],"ltp":0.0,"tv":0.0,"id":8173434}]}]}
{"op":"mcm","clk":"1004338962","pt":1580627417622,"mc":[{"id":"1.168186840","rc":[{"batb":[[0,1.89,34.78],[1,1.83,38.55],[2,1.78,41.7]],"ltp":0.0,"tv":0.0,"id":8639275},{"batb":[[1,1.97,60.66],[2,1.01,10.52]],"ltp":0.0,"tv":0.0,"id":8173434}]}]}
{"op":"mcm","clk":"1004338999","pt":1580627418507,"mc":[{"id":"1.168186840","rc":[{"batb":[[2,1.01,10.52]],"ltp":0.0,"tv":0.0,"id":8639275}]}]}
{"op":"mcm","clk":"1004339703","pt":1580627437701,"mc":[{"id":"1.168186840","rc":[{"batb":[[0,1.83,38.55],[1,1.01,10.52],[2,1.01,0]],"ltp":0.0,"tv":0.0,"id":8639275},{"batb":[[0,1.97,60.66],[1,1.01,10.52],[2,1.01,0]],"ltp":0.0,"tv":0.0,"id":8173434}]}]}
{"op":"mcm","clk":"1004340026","pt":1580627448531,"mc":[{"id":"1.168186840","rc":[{"batb":[[1,1.77,42.88],[2,1.01,10.52]],"ltp":0.0,"tv":0.0,"id":8639275},{"batb":[[0,2.06,52.8],[1,2.02,56.57],[2,1.97,181.17]],"ltp":0.0,"tv":0.0,"id":8173434}]}]}
{"op":"mcm","clk":"1004340036","pt":1580627448737,"mc":[{"id":"1.168186840","rc":[{"batb":[[2,1.97,120.51]],"ltp":0.0,"tv":0.0,"id":8173434}]}]}
{"op":"mcm","clk":"1004340862","pt":1580627469343,"mc":[{"id":"1.168186840","rc":[{"batb":[[0,1.77,42.88],[1,1.01,10.52],[2,1.01,0]],"ltp":0.0,"tv":0.0,"id":8639275},{"batb":[[0,2.02,56.57],[1,1.01,10.52],[2,1.97,0]],"ltp":0.0,"tv":0.0,"id":8173434}]}]}
{"op":"mcm","clk":"1004341326","pt":1580627479462,"mc":[{"id":"1.168186840","rc":[{"batb":[[0,1.87,36.04],[1,1.81,39.5],[2,1.01,10.52]],"ltp":0.0,"tv":0.0,"id":8639275},{"batb":[[1,2,58.62],[2,1.01,10.52]],"ltp":0.0,"tv":0.0,"id":8173434}]}]}
{"op":"mcm","clk":"1004341998","pt":1580627492508,"mc":[{"id":"1.168186840","rc":[{"batb":[[0,1.81,39.5],[1,1.01,10.52],[2,1.01,0]],"ltp":0.0,"tv":0.0,"id":8639275},{"batb":[[0,2,58.62],[1,1.01,10.52],[2,1.01,0]],"ltp":0.0,"tv":0.0,"id":8173434}]}]}
{"op":"mcm","clk":"1004344997","pt":1580627582638,"mc":[{"id":"1.168186840","rc":[{"batb":[[1,1.97,117.84],[2,1.01,10.52]],"ltp":0.0,"tv":0.0,"id":8173434}]}]}
{"op":"mcm","clk":"1004345046","pt":1580627583613,"mc":[{"id":"1.168186840","rc":[{"batb":[[1,1.75,44.3],[2,1.01,10.52]],"ltp":0.0,"tv":0.0,"id":8639275},{"batb":[[0,2.08,51.46],[1,2.04,54.92]],"ltp":0.0,"tv":0.0,"id":8173434}]}]}
{"op":"mcm","clk":"1004345715","pt":1580627601319,"mc":[{"id":"1.168186840","rc":[{"batb":[[0,1.75,44.3],[1,1.01,10.52],[2,1.01,0]],"ltp":0.0,"tv":0.0,"id":8639275},{"batb":[[0,2.04,54.92],[1,1.01,10.52],[2,1.01,0]],"ltp":0.0,"tv":0.0,"id":8173434}]}]}
{"op":"mcm","clk":"1004346442","pt":1580627621521,"mc":[{"id":"1.168186840","rc":[{"batb":[[0,1.85,37.06],[1,1.8,40.68],[2,1.76,21.48]],"ltp":0.0,"tv":0.0,"id":8639275},{"batb":[[1,2,57.28],[2,1.01,10.52]],"ltp":0.0,"tv":0.0,"id":8173434}]}]}
{"op":"mcm","clk":"1004346456","pt":1580627621932,"mc":[{"id":"1.168186840","rc":[{"batb":[[2,1.01,10.52]],"ltp":0.0,"tv":0.0,"id":8639275}]}]}
{"op":"mcm","clk":"1004347245","pt":1580627639445,"mc":[{"id":"1.168186840","rc":[{"batb":[[0,1.8,40.68],[1,1.01,10.52],[2,1.01,0]],"ltp":0.0,"tv":0.0,"id":8639275},{"batb":[[0,2,57.28],[1,1.01,10.52],[2,1.01,0]],"ltp":0.0,"tv":0.0,"id":8173434}]}]}
{"op":"mcm","clk":"1004347405","pt":1580627642678,"mc":[{"id":"1.168186840","rc":[{"batb":[[0,1.81,39.89]],"ltp":0.0,"tv":0.0,"id":8639275}]}]}
{"op":"mcm","clk":"1004348375","pt":1580627664501,"mc":[{"id":"1.168186840","rc":[{"batb":[[0,1.81,182.18]],"ltp":0.0,"tv":0.0,"id":8639275}]}]}
{"op":"mcm","clk":"1004348437","pt":1580627665686,"mc":[{"id":"1.168186840","rc":[{"batb":[[0,1.89,34.86],[1,1.86,36.74],[2,1.01,10.52]],"ltp":0.0,"tv":0.0,"id":8639275},{"batb":[[1,1.94,31.94],[2,1.01,10.52]],"ltp":0.0,"tv":0.0,"id":8173434}]}]}
{"op":"mcm","clk":"1004352060","pt":1580627755097,"mc":[{"id":"1.168186840","rc":[{"batb":[[0,1.86,36.74],[1,1.01,10.52],[2,1.01,0]],"ltp":0.0,"tv":0.0,"id":8639275},{"batb":[[0,1.94,31.94],[1,1.01,10.52],[2,1.01,0]],"ltp":0.0,"tv":0.0,"id":8173434}]}]}
{"op":"mcm","clk":"1004352469","pt":1580627766614,"mc":[{"id":"1.168186840","rc":[{"batb":[[0,1.94,31.94],[1,1.9,33.99],[2,1.86,175.28]],"ltp":0.0,"tv":0.0,"id":8639275},{"batb":[[1,1.87,35.56],[2,1.01,10.52]],"ltp":0.0,"tv":0.0,"id":8173434}]}]}
{"op":"mcm","clk":"1004352495","pt":1580627767489,"mc":[{"id":"1.168186840","rc":[{"batb":[[2,1.01,10.52]],"ltp":0.0,"tv":0.0,"id":8639275}]}]}
{"op":"mcm","clk":"1004352813","pt":1580627776533,"mc":[{"id":"1.168186840","rc":[{"batb":[[0,1.9,33.99],[1,1.01,10.52],[2,1.01,0]],"ltp":0.0,"tv":0.0,"id":8639275},{"batb":[[0,1.87,35.56],[1,1.01,10.52],[2,1.01,0]],"ltp":0.0,"tv":0.0,"id":8173434}]}]}
{"op":"mcm","clk":"1004353603","pt":1580627799691,"mc":[{"id":"1.168186840","rc":[{"batb":[[0,2,57.36],[1,1.96,61.92],[2,1.01,10.52]],"ltp":0.0,"tv":0.0,"id":8639275},{"batb":[[1,1.8,40.29],[2,1.01,10.52]],"ltp":0.0,"tv":0.0,"id":8173434}]}]}
{"op":"mcm","clk":"1004354272","pt":1580627818416,"mc":[{"id":"1.168186840","rc":[{"batb":[[0,1.96,61.92],[1,1.01,10.52],[2,1.01,0]],"ltp":0.0,"tv":0.0,"id":8639275},{"batb":[[0,1.8,40.29],[1,1.01,10.52],[2,1.01,0]],"ltp":0.0,"tv":0.0,"id":8173434}]}]}
{"op":"mcm","clk":"1004354385","pt":1580627821555,"mc":[{"id":"1.168186840","rc":[{"batb":[[0,1.95,62.63]],"ltp":0.0,"tv":0.0,"id":8639275},{"batb":[[0,1.81,39.81]],"ltp":0.0,"tv":0.0,"id":8173434}]}]}
{"op":"mcm","clk":"1004354860","pt":1580627833662,"mc":[{"id":"1.168186840","rc":[{"batb":[[1,1.92,33.13],[2,1.01,10.52]],"ltp":0.0,"tv":0.0,"id":8639275},{"batb":[[0,1.93,32.57],[1,1.85,37.14],[2,1.01,10.52]],"ltp":0.0,"tv":0.0,"id":8173434}]}]}
{"op":"mcm","clk":"1004355599","pt":1580627852598,"mc":[{"id":"1.168186840","rc":[{"batb":[[0,1.92,33.13],[1,1.01,10.52],[2,1.01,0]],"ltp":0.0,"tv":0.0,"id":8639275},{"batb":[[0,1.85,37.14],[1,1.01,10.52],[2,1.01,0]],"ltp":0.0,"tv":0.0,"id":8173434}]}]}
{"op":"mcm","clk":"1004356845","pt":1580627885700,"mc":[{"id":"1.168186840","rc":[{"batb":[[0,2.04,54.84],[1,1.99,58.93],[2,1.95,129.31]],"ltp":0.0,"tv":0.0,"id":8639275},{"batb":[[1,1.77,42.88],[2,1.01,10.52]],"ltp":0.0,"tv":0.0,"id":8173434}]}]}
{"op":"mcm","clk":"1004357773","pt":1580627905536,"mc":[{"id":"1.168186840","rc":[{"batb":[[0,1.99,58.93],[1,1.01,10.52],[2,1.95,0]],"ltp":0.0,"tv":0.0,"id":8639275},{"batb":[[0,1.77,42.57],[1,1.01,10.52],[2,1.01,0]],"ltp":0.0,"tv":0.0,"id":8173434}]}]}
{"op":"mcm","clk":"1004358844","pt":1580627928554,"mc":[{"id":"1.168186840","rc":[{"batb":[[1,1.93,32.57],[2,1.01,10.52]],"ltp":0.0,"tv":0.0,"id":8639275},{"batb":[[0,1.9,34.31],[1,1.79,41.15],[2,1.01,10.52]],"ltp":0.0,"tv":0.0,"id":8173434}]}]}
{"op":"mcm","clk":"1004359710","pt":1580627947574,"mc":[{"id":"1.168186840","rc":[{"batb":[[0,1.93,32.57],[1,1.01,10.52],[2,1.01,0]],"ltp":0.0,"tv":0.0,"id":8639275},{"batb":[[0,1.79,41.15],[1,1.01,10.52],[2,1.01,0]],"ltp":0.0,"tv":0.0,"id":8173434}]}]}
{"op":"mcm","clk":"1004359803","pt":1580627949690,"mc":[{"id":"1.168186840","rc":[{"batb":[[0,1.94,32.18],[1,1.93,32.57],[2,1.01,10.52]],"ltp":0.0,"tv":0.0,"id":8639275},{"batb":[[1,1.78,41.62],[2,1.01,10.52]],"ltp":0.0,"tv":0.0,"id":8173434}]}]}
{"op":"mcm","clk":"1004359821","pt":1580627950088,"mc":[{"id":"1.168186840","rc":[{"batb":[[1,1.01,10.52],[2,1.01,0]],"ltp":0.0,"tv":0.0,"id":8639275},{"batb":[[0,1.78,41.62],[1,1.01,10.52],[2,1.01,0]],"ltp":0.0,"tv":0.0,"id":8173434}]}]}
{"op":"mcm","clk":"1004361479","pt":1580627990459,"mc":[{"id":"1.168186840","rc":[{"batb":[[0,2.12,48.63],[1,2.04,54.21],[2,1.96,108.63]],"ltp":0.0,"tv":0.0,"id":8639275},{"batb":[[1,1.76,43.59],[2,1.01,10.52]],"ltp":0.0,"tv":0.0,"id":8173434}]}]}
{"op":"mcm","clk":"1004361635","pt":1580627993550,"mc":[{"id":"1.168186840","rc":[{"batl":[[0,2.4,515.7]],"ltp":0.0,"tv":0.0,"id":8173434}]}]}
{"op":"mcm","clk":"1004361676","pt":1580627994423,"mc":[{"id":"1.168186840","rc":[{"batl":[[0,2.84,37.52]],"ltp":0.0,"tv":0.0,"id":8639275}]}]}
{"op":"mcm","clk":"1004363381","pt":1580628027515,"mc":[{"id":"1.168186840","rc":[{"batb":[[0,2.04,54.21],[1,1.01,10.52],[2,1.96,0]],"ltp":0.0,"tv":0.0,"id":8639275},{"batb":[[0,1.76,43.2],[1,1.01,10.52],[2,1.01,0]],"ltp":0.0,"tv":0.0,"id":8173434}]}]}
{"op":"mcm","clk":"1004364549","pt":1580628056402,"mc":[{"id":"1.168186840","rc":[{"batb":[[0,2.16,46.74],[1,2.08,52.01],[2,2.04,99.87]],"ltp":0.0,"tv":0.0,"id":8639275},{"batb":[[1,1.74,44.93],[2,1.01,10.52]],"ltp":0.0,"tv":0.0,"id":8173434}]}]}
{"op":"mcm","clk":"1004365586","pt":1580628076676,"mc":[{"id":"1.168186840","rc":[{"batb":[[0,2.08,52.01],[1,1.01,10.52],[2,2.04,0]],"ltp":0.0,"tv":0.0,"id":8639275},{"batb":[[0,1.74,44.93],[1,1.01,10.52],[2,1.01,0]],"ltp":0.0,"tv":0.0,"id":8173434}]}]}
{"op":"mcm","clk":"1004365716","pt":1580628079645,"mc":[{"id":"1.168186840","rc":[{"batb":[[0,2.06,52.87]],"ltp":0.0,"tv":0.0,"id":8639275},{"batb":[[0,1.75,44.3]],"ltp":0.0,"tv":0.0,"id":8173434}]}]}
{"op":"mcm","clk":"1004366758","pt":1580628097664,"mc":[{"id":"1.168186840","rc":[{"batb":[[0,2.18,45.48],[1,2.1,50.36],[2,2.08,91.31]],"ltp":0.0,"tv":0.0,"id":8639275},{"batb":[[1,1.73,46.26],[2,1.01,10.52]],"ltp":0.0,"tv":0.0,"id":8173434}]}]}
{"op":"mcm","clk":"1004367483","pt":1580628113694,"mc":[{"id":"1.168186840","rc":[{"batb":[[2,1.01,10.52]],"ltp":0.0,"tv":0.0,"id":8639275}]}]}
{"op":"mcm","clk":"1004367538","pt":1580628114517,"mc":[{"id":"1.168186840","rc":[{"batb":[[0,2.1,50.2],[1,1.01,10.52],[2,1.01,0]],"ltp":0.0,"tv":0.0,"id":8639275},{"batb":[[0,1.73,46.26],[1,1.01,10.52],[2,1.01,0]],"ltp":0.0,"tv":0.0,"id":8173434}]}]}
{"op":"mcm","clk":"1004368419","pt":1580628134209,"mc":[{"id":"1.168186840","rc":[{"batb":[[1,2.02,55.86],[2,1.01,10.52]],"ltp":0.0,"tv":0.0,"id":8639275},{"batb":[[0,1.8,40.36],[1,1.77,42.65],[2,1.01,10.52]],"ltp":0.0,"tv":0.0,"id":8173434}]}]}
{"op":"mcm","clk":"1004369456","pt":1580628157258,"mc":[{"id":"1.168186840","rc":[{"batb":[[0,2.02,55.86],[1,1.01,10.52],[2,1.01,0]],"ltp":0.0,"tv":0.0,"id":8639275},{"batb":[[0,1.77,42.65],[1,1.01,10.52],[2,1.01,0]],"ltp":0.0,"tv":0.0,"id":8173434}]}]}
{"op":"mcm","clk":"1004370363","pt":1580628180001,"mc":[{"id":"1.168186840","rc":[{"batb":[[1,1.95,63.1],[2,1.01,10.52]],"ltp":0.0,"tv":0.0,"id":8639275},{"batb":[[0,1.86,36.51],[1,1.82,38.95],[2,1.76,146.48]],"ltp":0.0,"tv":0.0,"id":8173434}]}]}
{"op":"mcm","clk":"1004370459","pt":1580628182212,"mc":[{"id":"1.168186840","rc":[{"batl":[[0,2.7,44.95]],"ltp":0.0,"tv":0.0,"id":8639275}]}]}
{"op":"mcm","clk":"1004371323","pt":1580628200625,"mc":[{"id":"1.168186840","rc":[{"batb":[[0,1.95,62.87],[1,1.01,10.52],[2,1.01,0]],"ltp":0.0,"tv":0.0,"id":8639275},{"batb":[[0,1.82,38.95],[1,1.01,10.52],[2,1.76,0]],"ltp":0.0,"tv":0.0,"id":8173434}]}]}
{"op":"mcm","clk":"1004371806","pt":1580628212515,"mc":[{"id":"1.168186840","rc":[{"batb":[[0,2.08,52.01],[1,2,57.52],[2,1.95,62.87]],"ltp":0.0,"tv":0.0,"id":8639275},{"batb":[[1,1.79,41.23],[2,1.01,10.52]],"ltp":0.0,"tv":0.0,"id":8173434}]}]}
{"op":"mcm","clk":"1004371823","pt":1580628212822,"mc":[{"id":"1.168186840","rc":[{"batb":[[2,1.01,10.52]],"ltp":0.0,"tv":0.0,"id":8639275}]}]}
{"op":"mcm","clk":"1004372292","pt":1580628224455,"mc":[{"id":"1.168186840","rc":[{"batb":[[0,2,57.52],[1,1.01,10.52],[2,1.01,0]],"ltp":0.0,"tv":0.0,"id":8639275},{"batb":[[0,1.79,41.23],[1,1.01,10.52],[2,1.01,0]],"ltp":0.0,"tv":0.0,"id":8173434}]}]}
{"op":"mcm","clk":"1004373411","pt":1580628259701,"mc":[{"id":"1.168186840","rc":[{"batb":[[0,2.12,49.18],[1,2.08,51.54],[2,1.01,10.52]],"ltp":0.0,"tv":0.0,"id":8639275},{"batb":[[1,1.75,44.53],[2,1.01,10.52]],"ltp":0.0,"tv":0.0,"id":8173434}]}]}
{"op":"mcm","clk":"1004376027","pt":1580628339391,"mc":[{"id":"1.168186840","rc":[{"batb":[[0,2.08,51.22],[1,1.01,10.52],[2,1.01,0]],"ltp":0.0,"tv":0.0,"id":8639275},{"batb":[[0,1.75,44.53],[1,1.01,10.52],[2,1.01,0]],"ltp":0.0,"tv":0.0,"id":8173434}]}]}
{"op":"mcm","clk":"1004377165","pt":1580628364648,"mc":[{"id":"1.168186840","rc":[{"batb":[[0,2.18,45.01],[1,2.14,47.76],[2,1.01,10.52]],"ltp":0.0,"tv":0.0,"id":8639275},{"batb":[[1,1.7,49.33],[2,1.01,10.52]],"ltp":0.0,"tv":0.0,"id":8173434}]}]}
{"op":"mcm","clk":"1004377493","pt":1580628371641,"mc":[{"id":"1.168186840","rc":[{"batb":[[0,2.14,47.76],[1,1.01,10.52],[2,1.01,0]],"ltp":0.0,"tv":0.0,"id":8639275},{"batb":[[0,1.7,49.33],[1,1.01,10.52],[2,1.01,0]],"ltp":0.0,"tv":0.0,"id":8173434}]}]}
{"op":"mcm","clk":"1004378276","pt":1580628386661,"mc":[{"id":"1.168186840","rc":[{"batb":[[0,2.26,40.44],[1,2.22,43.2],[2,2.14,47.76]],"ltp":0.0,"tv":0.0,"id":8639275},{"batb":[[1,1.65,54.53],[2,1.01,10.52]],"ltp":0.0,"tv":0.0,"id":8173434}]}]}
{"op":"mcm","clk":"1004378386","pt":1580628387690,"mc":[{"id":"1.168186840","rc":[{"batb":[[2,1.01,10.52]],"ltp":0.0,"tv":0.0,"id":8639275}]}]}
{"op":"mcm","clk":"1004378454","pt":1580628389590,"mc":[{"id":"1.168186840","rc":[{"batl":[[0,3,42.38]],"ltp":0.0,"tv":0.0,"id":8639275},{"batl":[[0,2.3,532.36]],"ltp":0.0,"tv":0.0,"id":8173434}]}]}
{"op":"mcm","clk":"1004379112","pt":1580628398575,"mc":[{"id":"1.168186840","rc":[{"batb":[[0,2.22,43.2],[1,1.01,10.52],[2,1.01,0]],"ltp":0.0,"tv":0.0,"id":8639275},{"batb":[[0,1.65,54.53],[1,1.01,10.52],[2,1.01,0]],"ltp":0.0,"tv":0.0,"id":8173434}]}]}
{"op":"mcm","clk":"1004379808","pt":1580628418032,"mc":[{"id":"1.168186840","rc":[{"batb":[[1,2.16,45.79],[2,1.01,10.52]],"ltp":0.0,"tv":0.0,"id":8639275},{"batb":[[0,1.73,46.5],[1,1.68,51.14],[2,1.66,304.52]],"ltp":0.0,"tv":0.0,"id":8173434}]}]}
{"op":"mcm","clk":"1004380257","pt":1580628430664,"mc":[{"id":"1.168186840","rc":[{"batb":[[0,2.16,45.79],[1,1.01,10.52],[2,1.01,0]],"ltp":0.0,"tv":0.0,"id":8639275},{"batb":[[0,1.68,51.14],[1,1.01,10.52],[2,1.66,0]],"ltp":0.0,"tv":0.0,"id":8173434}]}]}
{"op":"mcm","clk":"1004381083","pt":1580628454490,"mc":[{"id":"1.168186840","rc":[{"batb":[[0,2.3,38.87],[1,2.24,41.86],[2,2.18,73.47]],"ltp":0.0,"tv":0.0,"id":8639275},{"batb":[[1,1.62,57.83],[2,1.01,10.52]],"ltp":0.0,"tv":0.0,"id":8173434}]}]}
{"op":"mcm","clk":"1004381413","pt":1580628464180,"mc":[{"id":"1.168186840","rc":[{"batb":[[0,2.24,41.86],[1,1.01,10.52],[2,2.18,0]],"ltp":0.0,"tv":0.0,"id":8639275},{"batb":[[0,1.62,57.83],[1,1.01,10.52],[2,1.01,0]],"ltp":0.0,"tv":0.0,"id":8173434}]}]}
{"op":"mcm","clk":"1004381751","pt":1580628473414,"mc":[{"id":"1.168186840","rc":[{"batb":[[1,2.18,45.16],[2,1.01,10.52]],"ltp":0.0,"tv":0.0,"id":8639275},{"batb":[[0,1.71,47.84],[1,1.65,54.21],[2,1.01,10.52]],"ltp":0.0,"tv":0.0,"id":8173434}]}]}
{"op":"mcm","clk":"1004382527","pt":1580628493614,"mc":[{"id":"1.168186840","rc":[{"batb":[[0,2.18,44.69],[1,1.01,10.52],[2,1.01,0]],"ltp":0.0,"tv":0.0,"id":8639275},{"batb":[[0,1.65,54.21],[1,1.01,10.52],[2,1.01,0]],"ltp":0.0,"tv":0.0,"id":8173434}]}]}
{"op":"mcm","clk":"1004383382","pt":1580628515543,"mc":[{"id":"1.168186840","rc":[{"batb":[[0,1.65,503.7],[1,1.64,241.86],[2,1.01,10.52]],"batl":[[0,1.72,330.77],[1,1.74,394],[2,2.3,532.36]],"ltp":0.0,"tv":0.0,"id":8173434}]}]}
{"op":"mcm","clk":"1004383405","pt":1580628516274,"mc":[{"id":"1.168186840","rc":[{"batb":[[0,2.36,36.04],[1,2.1,50.59],[2,1.01,10.52]],"ltp":0.0,"tv":0.0,"id":8639275},{"batb":[[2,1.58,63.42]],"ltp":0.0,"tv":0.0,"id":8173434}]}]}
{"op":"mcm","clk":"1004383867","pt":1580628530567,"mc":[{"id":"1.168186840","rc":[{"batb":[[2,1.58,63.26]],"ltp":0.0,"tv":0.0,"id":8173434}]}]}
{"op":"mcm","clk":"1004384694","pt":1580628552509,"mc":[{"id":"1.168186840","rc":[{"trd":[[1.65,15.12]],"batb":[[0,1.65,496.14]],"ltp":1.65,"tv":15.12,"id":8173434}],"tv":15.12}]}
{"op":"mcm","clk":"1004388840","pt":1580628655159,"mc":[{"id":"1.168186840","rc":[{"trd":[[2.38,112.44]],"ltp":2.38,"tv":112.44,"id":8639275},{"trd":[[1.72,155.57]],"batb":[[0,1.65,282.65],[1,1.58,63.26],[2,1.01,10.52]],"batl":[[0,1.72,175.2]],"ltp":1.72,"tv":170.69,"id":8173434}],"tv":283.13}]}
{"op":"mcm","clk":"1004388970","pt":1580628658052,"mc":[{"id":"1.168186840","rc":[{"batb":[[0,1.66,251.66],[1,1.65,282.65],[2,1.58,63.26]],"batl":[[0,1.72,292.75]],"ltp":1.72,"tv":170.69,"id":8173434}]}]}
{"op":"mcm","clk":"1004389140","pt":1580628661621,"mc":[{"id":"1.168186840","rc":[{"batb":[[0,2.1,50.59],[1,1.01,10.52],[2,1.01,0]],"ltp":2.38,"tv":112.44,"id":8639275},{"batb":[[0,1.58,63.26],[1,1.01,10.52],[2,1.58,0]],"batl":[[0,2.3,532.36],[1,1.74,0],[2,2.3,0]],"ltp":1.72,"tv":170.69,"id":8173434}]}]}
{"op":"mcm","clk":"1004389348","pt":1580628666520,"mc":[{"id":"1.168186840","rc":[{"batb":[[0,1.68,447.5],[1,1.66,459.87],[2,1.58,63.26]],"batl":[[0,1.75,256.53],[1,1.77,372.47],[2,2.3,532.36]],"ltp":1.72,"tv":170.69,"id":8173434}]}]}
{"op":"mcm","clk":"1004389373","pt":1580628667030,"mc":[{"id":"1.168186840","rc":[{"trd":[[1.68,1.52]],"batb":[[0,1.68,446.74]],"ltp":1.68,"tv":172.21,"id":8173434}],"tv":284.65}]}
{"op":"mcm","clk":"1004389564","pt":1580628671733,"mc":[{"id":"1.168186840","rc":[{"batb":[[0,1.58,63.26],[1,1.01,10.52],[2,1.58,0]],"batl":[[0,2.3,532.36],[1,1.77,0],[2,2.3,0]],"ltp":1.68,"tv":172.21,"id":8173434}]}]}
{"op":"mcm","clk":"1004389702","pt":1580628674620,"mc":[{"id":"1.168186840","rc":[{"batb":[[0,1.58,470.07],[1,1.57,284.43],[2,1.01,10.52]],"batl":[[0,1.89,243.98],[1,1.91,292.32],[2,2.3,532.36]],"ltp":1.68,"tv":172.21,"id":8173434}]}]}
{"op":"mcm","clk":"1004390064","pt":1580628683019,"mc":[{"id":"1.168186840","rc":[{"batb":[[2,1.55,4.43]],"ltp":1.68,"tv":172.21,"id":8173434}]}]}
{"op":"mcm","clk":"1004390938","pt":1580628705457,"mc":[{"id":"1.168186840","rc":[{"batb":[[0,1.58,406.81]],"batl":[[0,2.3,532.36],[1,1.91,0],[2,2.3,0]],"ltp":1.68,"tv":172.21,"id":8173434}]}]}
{"op":"mcm","clk":"1004391067","pt":1580628708659,"mc":[{"id":"1.168186840","rc":[{"batb":[[0,2.54,29.74],[1,2.3,39.18],[2,1.01,10.52]],"ltp":2.38,"tv":112.44,"id":8639275},{"batb":[[1,1.57,349.19]],"batl":[[0,1.64,348.86],[1,1.65,234.76]],"ltp":1.68,"tv":172.21,"id":8173434}]}]}
{"op":"mcm","clk":"1004391183","pt":1580628711503,"mc":[{"id":"1.168186840","rc":[{"batl":[[2,2.16,570.15]],"ltp":1.68,"tv":172.21,"id":8173434}]}]}
{"op":"mcm","clk":"1004391654","pt":1580628722379,"mc":[{"id":"1.168186840","rc":[{"trd":[[2.56,4.56]],"ltp":2.56,"tv":117.0,"id":8639275},{"trd":[[1.64,7.12]],"batl":[[0,1.64,341.74]],"ltp":1.64,"tv":179.33,"id":8173434}],"tv":296.33}]}
{"op":"mcm","clk":"1004391796","pt":1580628725497,"mc":[{"id":"1.168186840","rc":[{"batl":[[2,1.84,13.28]],"ltp":1.64,"tv":179.33,"id":8173434}]}]}
{"op":"mcm","clk":"1004392162","pt":1580628733698,"mc":[{"id":"1.168186840","rc":[{"batb":[[0,1.57,64.76],[1,1.55,4.43],[2,1.53,72.62]],"batl":[[0,2.16,570.15],[1,1.65,0],[2,1.84,0]],"ltp":1.64,"tv":179.33,"id":8173434}]}]}
{"op":"mcm","clk":"1004392197","pt":1580628734520,"mc":[{"id":"1.168186840","rc":[{"batb":[[0,2.3,39.18],[1,1.01,10.52],[2,1.01,0]],"ltp":2.56,"tv":117.0,"id":8639275},{"batb":[[0,1.55,4.43],[1,1.53,72.62],[2,1.01,10.52]],"ltp":1.64,"tv":179.33,"id":8173434}]}]}
{"op":"mcm","clk":"1004392291","pt":1580628736685,"mc":[{"id":"1.168186840","rc":[{"batb":[[1,1.53,414.68],[2,1.52,322.52]],"batl":[[0,1.76,338.93],[1,1.78,365.41],[2,2.16,570.15]],"ltp":1.64,"tv":179.33,"id":8173434}]}]}
{"op":"mcm","clk":"1004392321","pt":1580628737508,"mc":[{"id":"1.168186840","rc":[{"batb":[[1,1.53,72.62],[2,1.01,10.52]],"batl":[[0,2.16,570.15],[1,1.78,0],[2,2.16,0]],"ltp":1.64,"tv":179.33,"id":8173434}]}]}
{"op":"mcm","clk":"1004392383","pt":1580628739416,"mc":[{"id":"1.168186840","rc":[{"batb":[[0,1.6,409.76],[1,1.59,271.09],[2,1.55,4.43]],"batl":[[0,1.66,289.37],[1,1.68,443.96],[2,2.16,570.15]],"ltp":1.64,"tv":179.33,"id":8173434}]}]}
{"op":"mcm","clk":"1004392662","pt":1580628745701,"mc":[{"id":"1.168186840","rc":[{"batb":[[0,1.55,4.43],[1,1.53,72.62],[2,1.01,10.52]],"batl":[[0,2.16,570.15],[1,1.68,0],[2,2.16,0]],"ltp":1.64,"tv":179.33,"id":8173434}]}]}
{"op":"mcm","clk":"1004392788","pt":1580628748430,"mc":[{"id":"1.168186840","rc":[{"batb":[[1,1.53,414.68],[2,1.52,322.52]],"batl":[[0,1.76,338.93],[1,1.78,365.41],[2,2.16,570.15]],"ltp":1.64,"tv":179.33,"id":8173434}]}]}
{"op":"mcm","clk":"1004392908","pt":1580628751518,"mc":[{"id":"1.168186840","rc":[{"batl":[[0,2.16,570.15],[1,1.78,0],[2,2.16,0]],"ltp":1.64,"tv":179.33,"id":8173434}]}]}
{"op":"mcm","clk":"1004393049","pt":1580628754246,"mc":[{"id":"1.168186840","rc":[{"batl":[[0,1.58,305.99],[1,1.59,268.37]],"ltp":1.64,"tv":179.33,"id":8173434}]}]}
{"op":"mcm","clk":"1004393100","pt":1580628755330,"mc":[{"id":"1.168186840","rc":[{"batb":[[0,2.68,25.89],[1,2.48,31.79],[2,1.01,10.52]],"ltp":2.56,"tv":117.0,"id":8639275}]}]}
{"op":"mcm","clk":"1004393214","pt":1580628757548,"mc":[{"id":"1.168186840","rc":[{"batl":[[0,3.65,30.99]],"ltp":2.56,"tv":117.0,"id":8639275},{"batl":[[2,2.04,631.78]],"ltp":1.64,"tv":179.33,"id":8173434}]}]}
{"op":"mcm","clk":"1004393362","pt":1580628760849,"mc":[{"id":"1.168186840","rc":[{"batl":[[2,1.84,19.78]],"ltp":1.64,"tv":179.33,"id":8173434}]}]}
{"op":"mcm","clk":"1004393687","pt":1580628769652,"mc":[{"id":"1.168186840","rc":[{"batb":[[1,1.53,72.62],[2,1.5,78.21]],"batl":[[0,2.04,631.78],[1,1.59,0],[2,1.84,0]],"ltp":1.64,"tv":179.33,"id":8173434}]}]}
{"op":"mcm","clk":"1004393731","pt":1580628770631,"mc":[{"id":"1.168186840","rc":[{"batb":[[0,2.48,31.79],[1,1.01,10.52],[2,1.01,0]],"ltp":2.56,"tv":117.0,"id":8639275},{"batb":[[1,1.5,78.21],[2,1.01,10.52]],"ltp":1.64,"tv":179.33,"id":8173434}]}]}
{"op":"mcm","clk":"1004393827","pt":1580628772541,"mc":[{"id":"1.168186840","rc":[{"batb":[[1,1.5,344.72],[2,1.49,349.18]],"batl":[[0,1.65,261.66],[1,1.67,453.45],[2,2.04,631.78]],"ltp":1.64,"tv":179.33,"id":8173434}]}]}
{"op":"mcm","clk":"1004394251","pt":1580628781056,"mc":[{"id":"1.168186840","rc":[{"trd":[[1.55,1.04]],"batb":[[0,1.55,3.91]],"ltp":1.55,"tv":180.37,"id":8173434}],"tv":297.37}]}
{"op":"mcm","clk":"1004394762","pt":1580628791505,"mc":[{"id":"1.168186840","rc":[{"trd":[[1.55,8.87]],"batb":[[0,1.5,344.72],[1,1.49,349.18],[2,1.01,10.52]],"batl":[[0,1.54,80.1],[1,1.65,261.66],[2,1.67,453.45]],"ltp":1.55,"tv":188.2,"id":8173434}],"tv":305.2}]}
{"op":"mcm","clk":"1004394954","pt":1580628795586,"mc":[{"id":"1.168186840","rc":[{"batl":[[1,2.04,631.79],[2,1.67,0]],"ltp":1.55,"tv":188.2,"id":8173434}]}]}
{"op":"mcm","clk":"1004394988","pt":1580628796565,"mc":[{"id":"1.168186840","rc":[{"batl":[[0,2.04,631.79],[1,2.04,0]],"ltp":1.55,"tv":188.2,"id":8173434}]}]}
{"op":"mcm","clk":"1004395061","pt":1580628798684,"mc":[{"id":"1.168186840","rc":[{"batl":[[0,1.55,473.19],[1,1.56,287.2],[2,2.04,631.78]],"ltp":1.55,"tv":188.2,"id":8173434}]}]}
{"op":"mcm","clk":"1004395088","pt":1580628799402,"mc":[{"id":"1.168186840","rc":[{"batb":[[0,2.78,23.76],[1,2.64,27.15],[2,1.01,10.52]],"ltp":2.56,"tv":117.0,"id":8639275},{"trd":[[1.5,160.21]],"batb":[[0,1.5,264.61],[2,1.48,82.55]],"ltp":1.5,"tv":348.41,"id":8173434}],"tv":465.42}]}
{"op":"mcm","clk":"1004395807","pt":1580628819654,"mc":[{"id":"1.168186840","rc":[{"batb":[[0,1.48,82.55],[1,1.01,10.51],[2,1.48,0]],"batl":[[0,2.04,631.79],[1,1.56,0],[2,2.04,0]],"ltp":1.5,"tv":348.41,"id":8173434}]}]}
{"op":"mcm","clk":"1004395812","pt":1580628819709,"mc":[{"id":"1.168186840","rc":[{"batb":[[0,2.64,27.15],[1,1.01,10.52],[2,1.01,0]],"ltp":2.56,"tv":117.0,"id":8639275}]}]}
{"op":"mcm","clk":"1004395921","pt":1580628822640,"mc":[{"id":"1.168186840","rc":[{"batb":[[0,1.48,466.16],[1,1.47,370.22],[2,1.01,10.51]],"batl":[[0,1.58,274.08],[1,1.59,268.52],[2,2.04,631.78]],"ltp":1.5,"tv":348.41,"id":8173434}]}]}
{"op":"mcm","clk":"1004395943","pt":1580628823105,"mc":[{"id":"1.168186840","rc":[{"batb":[[0,2.72,26.36]],"ltp":2.56,"tv":117.0,"id":8639275},{"batb":[[0,1.47,84.67],[1,1.01,10.51],[2,1.01,0]],"batl":[[0,2.04,631.79],[1,1.59,0],[2,2.04,0]],"ltp":1.5,"tv":348.41,"id":8173434}]}]}
{"op":"mcm","clk":"1004396045","pt":1580628826344,"mc":[{"id":"1.168186840","rc":[{"batb":[[0,1.5,493.14],[1,1.49,350.56],[2,1.47,84.67]],"batl":[[0,1.55,260.09],[1,1.56,288.28],[2,2.04,631.78]],"ltp":1.5,"tv":348.41,"id":8173434}]}]}
{"op":"mcm","clk":"1004396226","pt":1580628831547,"mc":[{"id":"1.168186840","rc":[{"trd":[[1.5,164.76]],"batb":[[0,1.47,84.67],[1,1.01,10.51],[2,1.47,0]],"batl":[[0,2.04,631.79],[1,1.56,0],[2,2.04,0]],"ltp":1.5,"tv":352.95,"id":8173434}],"tv":469.96}]}
{"op":"mcm","clk":"1004396343","pt":1580628834224,"mc":[{"id":"1.168186840","rc":[{"batb":[[0,1.48,383.62],[1,1.47,454.88],[2,1.01,10.51]],"batl":[[0,1.58,274.08],[1,1.59,268.52],[2,2.04,631.78]],"ltp":1.5,"tv":352.95,"id":8173434}]}]}
{"op":"mcm","clk":"1004396529","pt":1580628839431,"mc":[{"id":"1.168186840","rc":[{"batl":[[0,2.04,631.79],[1,1.59,0],[2,2.04,0]],"ltp":1.5,"tv":352.95,"id":8173434}]}]}
{"op":"mcm","clk":"1004396645","pt":1580628842528,"mc":[{"id":"1.168186840","rc":[{"batb":[[0,2.94,21.48],[1,2.72,26.36],[2,2.7,26.67]],"ltp":2.56,"tv":117.0,"id":8639275},{"batb":[[2,1.37,114.32]],"batl":[[0,1.53,435.9],[1,1.54,301.75],[2,2.04,631.79]],"ltp":1.5,"tv":352.95,"id":8173434}]}]}
{"op":"mcm","clk":"1004396667","pt":1580628842943,"mc":[{"id":"1.168186840","rc":[{"batb":[[1,2.7,26.67],[2,1.01,10.52]],"ltp":2.56,"tv":117.0,"id":8639275}]}]}
{"op":"mcm","clk":"1004396868","pt":1580628849557,"mc":[{"id":"1.168186840","rc":[{"batb":[[1,1.47,454.41],[2,1.37,113.77]],"ltp":1.5,"tv":352.95,"id":8173434}]}]}
{"op":"mcm","clk":"1004396896","pt":1580628850435,"mc":[{"id":"1.168186840","rc":[{"batl":[[0,1.53,328.96]],"ltp":1.5,"tv":352.95,"id":8173434}]}]}
{"op":"mcm","clk":"1004397008","pt":1580628853669,"mc":[{"id":"1.168186840","rc":[{"batb":[[0,1.48,493.46]],"ltp":1.5,"tv":352.95,"id":8173434}]}]}
{"op":"mcm","clk":"1004397953","pt":1580628879118,"mc":[{"id":"1.168186840","rc":[{"batb":[[0,1.47,84.2],[1,1.37,113.77],[2,1.01,10.51]],"batl":[[0,2.04,631.79],[1,1.54,0],[2,2.04,0]],"ltp":1.5,"tv":352.95,"id":8173434}]}]}
{"op":"mcm","clk":"1004398032","pt":1580628882100,"mc":[{"id":"1.168186840","rc":[{"batb":[[1,1.38,707.04],[2,1.37,623.75]],"batl":[[0,1.61,366.31],[1,1.62,249.93],[2,2.04,631.78]],"ltp":1.5,"tv":352.95,"id":8173434}]}]}
{"op":"mcm","clk":"1004398116","pt":1580628884890,"mc":[{"id":"1.168186840","rc":[{"batb":[[0,2.7,26.67],[1,1.01,10.52],[2,1.01,0]],"ltp":2.56,"tv":117.0,"id":8639275},{"batb":[[0,1.38,707.05],[1,1.37,623.75],[2,1.01,10.51]],"ltp":1.5,"tv":352.95,"id":8173434}]}]}
{"op":"mcm","clk":"1004398222","pt":1580628888629,"mc":[{"id":"1.168186840","rc":[{"batb":[[0,2.68,27.15]],"ltp":2.56,"tv":117.0,"id":8639275},{"batb":[[1,1.37,622.65]],"ltp":1.5,"tv":352.95,"id":8173434}]}]}
{"op":"mcm","clk":"1004398309","pt":1580628890699,"mc":[{"id":"1.168186840","rc":[{"batb":[[0,1.37,112.68],[1,1.01,10.51],[2,1.01,0]],"ltp":1.5,"tv":352.95,"id":8173434}]}]}
{"op":"mcm","clk":"1004398403","pt":1580628893635,"mc":[{"id":"1.168186840","rc":[{"trd":[[1.55,8.9]],"batb":[[0,1.55,484.82],[1,1.54,306.25],[2,1.37,112.68]],"batl":[[0,1.61,366.29]],"ltp":1.55,"tv":352.99,"id":8173434}],"tv":469.99}]}
{"op":"mcm","clk":"1004398441","pt":1580628894618,"mc":[{"id":"1.168186840","rc":[{"batb":[[1,2.52,31.94],[2,1.01,10.52]],"ltp":2.56,"tv":117.0,"id":8639275},{"batb":[[1,1.54,376.04],[2,1.45,89.47]],"ltp":1.55,"tv":352.99,"id":8173434}]}]}
{"op":"mcm","clk":"1004398527","pt":1580628896628,"mc":[{"id":"1.168186840","rc":[{"batl":[[0,3.45,36.98]],"ltp":2.56,"tv":117.0,"id":8639275}]}]}
{"op":"mcm","clk":"1004398689","pt":1580628900401,"mc":[{"id":"1.168186840","rc":[{"batb":[[0,2.52,31.94],[1,1.01,10.52],[2,1.01,0]],"ltp":2.56,"tv":117.0,"id":8639275},{"batb":[[0,1.45,89.47],[1,1.01,10.51],[2,1.45,0]],"batl":[[0,2.04,631.78],[1,1.62,0],[2,2.04,0]],"ltp":1.55,"tv":352.99,"id":8173434}]}]}
{"op":"mcm","clk":"1004398763","pt":1580628902311,"mc":[{"id":"1.168186840","rc":[{"batb":[[0,1.45,89.49]],"ltp":1.55,"tv":352.99,"id":8173434}]}]}
{"op":"mcm","clk":"1004398937","pt":1580628906641,"mc":[{"id":"1.168186840","rc":[{"batb":[[0,1.53,498.34],[1,1.52,322.81],[2,1.45,89.47]],"batl":[[0,1.59,423.9],[1,1.6,261.33],[2,2.04,631.78]],"ltp":1.55,"tv":352.99,"id":8173434}]}]}
{"op":"mcm","clk":"1004399030","pt":1580628909739,"mc":[{"id":"1.168186840","rc":[{"batb":[[0,1.45,89.49],[1,1.01,10.51],[2,1.45,0]],"batl":[[0,2.04,631.78],[1,1.6,0],[2,2.04,0]],"ltp":1.55,"tv":352.99,"id":8173434}]}]}
{"op":"mcm","clk":"1004399141","pt":1580628912633,"mc":[{"id":"1.168186840","rc":[{"batb":[[0,1.46,525.03],[1,1.45,482.29],[2,1.01,10.51]],"batl":[[0,1.68,394.98],[1,1.7,424.91],[2,2.04,631.78]],"ltp":1.55,"tv":352.99,"id":8173434}]}]}
{"op":"mcm","clk":"1004399481","pt":1580628923652,"mc":[{"id":"1.168186840","rc":[{"batl":[[0,2.04,631.78],[1,1.7,0],[2,2.04,0]],"ltp":1.55,"tv":352.99,"id":8173434}]}]}
{"op":"mcm","clk":"1004399616","pt":1580628926687,"mc":[{"id":"1.168186840","rc":[{"trd":[[1.55,8.94]],"batb":[[0,1.46,525.01]],"batl":[[0,1.51,379.39],[1,1.52,317.28],[2,2.04,631.78]],"ltp":1.55,"tv":353.02,"id":8173434}],"tv":470.03}]}
{"op":"mcm","clk":"1004399640","pt":1580628927369,"mc":[{"id":"1.168186840","rc":[{"batb":[[0,3,50.75],[1,2.72,26.2],[2,1.01,10.52]],"ltp":2.56,"tv":117.0,"id":8639275},{"batb":[[2,1.33,130.14]],"ltp":1.55,"tv":353.02,"id":8173434}]}]}
{"op":"mcm","clk":"1004399722","pt":1580628929675,"mc":[{"id":"1.168186840","rc":[{"batl":[[0,3.9,27.37]],"ltp":2.56,"tv":117.0,"id":8639275}]}]}
{"op":"mcm","clk":"1004400123","pt":1580628940571,"mc":[{"id":"1.168186840","rc":[{"batb":[[0,2.72,26.2],[1,1.01,10.52],[2,1.01,0]],"ltp":2.56,"tv":117.0,"id":8639275},{"batb":[[0,1.33,130.15],[1,1.01,10.51],[2,1.33,0]],"batl":[[0,2.04,631.78],[1,1.52,0],[2,2.04,0]],"ltp":1.55,"tv":353.02,"id":8173434}]}]}
{"op":"mcm","clk":"1004400199","pt":1580628942677,"mc":[{"id":"1.168186840","rc":[{"batl":[[0,3,84.02],[1,3.9,27.37]],"ltp":2.56,"tv":117.0,"id":8639275},{"batb":[[0,1.35,490.26],[1,1.34,566.21],[2,1.33,130.14]],"batl":[[0,1.6,277.45],[1,1.61,256.05],[2,2.04,631.78]],"ltp":1.55,"tv":353.02,"id":8173434}]}]}
{"op":"mcm","clk":"1004400234","pt":1580628943697,"mc":[{"id":"1.168186840","rc":[{"batb":[[0,1.33,130.15],[1,1.01,10.51],[2,1.33,0]],"batl":[[0,2.04,631.78],[1,1.61,0],[2,2.04,0]],"ltp":1.55,"tv":353.02,"id":8173434}]}]}
{"op":"mcm","clk":"1004400290","pt":1580628945602,"mc":[{"id":"1.168186840","rc":[{"trd":[[3,84.02]],"batl":[[0,3.9,27.37],[1,3.9,0]],"ltp":3.0,"tv":201.02,"id":8639275},{"trd":[[1.48,0.02],[1.5,332.8]],"batb":[[0,1.44,375.66],[1,1.43,416.15],[2,1.33,130.14]],"batl":[[0,1.48,94.83],[1,1.49,344.17]],"ltp":1.48,"tv":521.08,"id":8173434}],"tv":722.11}]}
{"op":"mcm","clk":"1004400310","pt":1580628946216,"mc":[{"id":"1.168186840","rc":[{"batl":[[0,1.49,344.17],[1,1.49,0]],"ltp":1.48,"tv":521.08,"id":8173434}]}]}
{"op":"mcm","clk":"1004400384","pt":1580628948526,"mc":[{"id":"1.168186840","rc":[{"batb":[[0,1.33,130.14],[1,1.01,10.51],[2,1.33,0]],"ltp":1.48,"tv":521.08,"id":8173434}]}]}
{"op":"mcm","clk":"1004400407","pt":1580628949297,"mc":[{"id":"1.168186840","rc":[{"batl":[[0,1.89,709.46]],"ltp":1.48,"tv":521.08,"id":8173434}]}]}
{"op":"mcm","clk":"1004400455","pt":1580628951093,"mc":[{"id":"1.168186840","rc":[{"batb":[[0,1.35,559.18],[1,1.34,566.36],[2,1.33,130.14]],"batl":[[0,1.61,474.39],[1,1.62,249.37],[2,1.89,709.46]],"ltp":1.48,"tv":521.08,"id":8173434}]}]}
{"op":"mcm","clk":"1004400624","pt":1580628957316,"mc":[{"id":"1.168186840","rc":[{"batl":[[0,1.89,709.46],[1,1.62,0],[2,1.89,0]],"ltp":1.48,"tv":521.08,"id":8173434}]}]}
{"op":"mcm","clk":"1004400744","pt":1580628960505,"mc":[{"id":"1.168186840","rc":[{"batb":[[0,2.76,590.73],[1,2.72,26.2],[2,1.01,10.52]],"ltp":3.0,"tv":201.02,"id":8639275},{"batl":[[0,1.39,512.72],[1,1.4,445.06]],"ltp":1.48,"tv":521.08,"id":8173434}]}]}
{"op":"mcm","clk":"1004400789","pt":1580628961532,"mc":[{"id":"1.168186840","rc":[{"batb":[[0,3.65,31],[1,3.1,46.58]],"ltp":3.0,"tv":201.02,"id":8639275}]}]}
{"op":"mcm","clk":"1004400939","pt":1580628964629,"mc":[{"id":"1.168186840","rc":[{"batl":[[0,4.9,17.27]],"ltp":3.0,"tv":201.02,"id":8639275},{"batl":[[2,1.77,800.57]],"ltp":1.48,"tv":521.08,"id":8173434}]}]}
{"op":"mcm","clk":"1004401264","pt":1580628972621,"mc":[{"id":"1.168186840","rc":[{"batb":[[0,3.1,46.58],[1,1.01,10.52],[2,1.01,0]],"ltp":3.0,"tv":201.02,"id":8639275},{"batb":[[0,1.2,234.55],[1,1.01,10.51],[2,1.33,0]],"batl":[[0,1.77,800.57],[1,1.4,0],[2,1.77,0]],"ltp":1.48,"tv":521.08,"id":8173434}]}]}
{"op":"mcm","clk":"1004401379","pt":1580628975646,"mc":[{"id":"1.168186840","rc":[{"batb":[[0,1.23,670.9],[1,1.22,973.02],[2,1.2,234.55]],"batl":[[0,1.49,298.54],[1,1.5,334.4],[2,1.77,800.57]],"ltp":1.48,"tv":521.08,"id":8173434}]}]}
{"op":"mcm","clk":"1004401643","pt":1580628983261,"mc":[{"id":"1.168186840","rc":[{"batl":[[0,1.77,800.57],[1,1.5,0],[2,1.77,0]],"ltp":1.48,"tv":521.08,"id":8173434}]}]}
{"op":"mcm","clk":"1004401819","pt":1580628986636,"mc":[{"id":"1.168186840","rc":[{"batb":[[0,5.2,26.83],[1,4,47.45],[2,1.01,10.52]],"ltp":3.0,"tv":201.02,"id":8639275},{"batl":[[0,1.26,800.7],[1,1.27,718.86]],"ltp":1.48,"tv":521.08,"id":8173434}]}]}
{"op":"mcm","clk":"1004401912","pt":1580628989654,"mc":[{"id":"1.168186840","rc":[{"batl":[[2,1.62,951.87]],"ltp":1.48,"tv":521.08,"id":8173434}]}]}
{"op":"mcm","clk":"1004401973","pt":1580628991765,"mc":[{"id":"1.168186840","rc":[{"batl":[[0,7.8,14.93]],"ltp":3.0,"tv":201.02,"id":8639275}]}]}
{"op":"mcm","clk":"1004402253","pt":1580628999648,"mc":[{"id":"1.168186840","rc":[{"trd":[[1.23,391.54]],"batb":[[0,1.23,475.13]],"ltp":1.23,"tv":912.62,"id":8173434}],"tv":1113.64}]}
{"op":"mcm","clk":"1004402414","pt":1580629003676,"mc":[{"id":"1.168186840","rc":[{"batb":[[0,4,47.45],[1,1.01,10.52],[2,1.01,0]],"ltp":3.0,"tv":201.02,"id":8639275},{"batb":[[0,1.09,519.85],[1,1.01,10.51],[2,1.2,0]],"batl":[[0,1.62,951.87],[1,1.27,0],[2,1.62,0]],"ltp":1.23,"tv":912.62,"id":8173434}]}]}
{"op":"mcm","clk":"1004402660","pt":1580629009390,"mc":[{"id":"1.168186840","rc":[{"batl":[[0,5.2,21],[1,7.8,14.93]],"ltp":3.0,"tv":201.02,"id":8639275},{"batb":[[0,1.21,651.68],[1,1.2,1091.64],[2,1.09,519.85]],"batl":[[0,1.24,1062.2],[1,1.25,783.66],[2,1.62,951.87]],"ltp":1.23,"tv":912.62,"id":8173434}]}]}
{"op":"mcm","clk":"1004402800","pt":1580629012787,"mc":[{"id":"1.168186840","rc":[{"batb":[[0,1.09,519.85],[1,1.01,10.51],[2,1.09,0]],"batl":[[0,1.62,951.87],[1,1.25,0],[2,1.62,0]],"ltp":1.23,"tv":912.62,"id":8173434}]}]}
{"op":"mcm","clk":"1004402880","pt":1580629015680,"mc":[{"id":"1.168186840","rc":[{"batb":[[0,1.14,359.49],[1,1.13,1778.49],[2,1.09,519.85]],"batl":[[0,1.34,726.17],[1,1.35,525.05],[2,1.62,951.87]],"ltp":1.23,"tv":912.62,"id":8173434}]}]}
{"op":"mcm","clk":"1004402968","pt":1580629018095,"mc":[{"id":"1.168186840","rc":[{"batl":[[0,7.8,14.93],[1,7.8,0]],"ltp":3.0,"tv":201.02,"id":8639275}]}]}
{"op":"mcm","clk":"1004403150","pt":1580629023600,"mc":[{"id":"1.168186840","rc":[{"batb":[[0,1.09,519.85],[1,1.01,10.51],[2,1.09,0]],"ltp":1.23,"tv":912.62,"id":8173434}]}]}
{"op":"mcm","clk":"1004403242","pt":1580629026527,"mc":[{"id":"1.168186840","rc":[{"batb":[[0,1.3,716.66],[1,1.29,696.24],[2,1.09,519.85]],"ltp":1.23,"tv":912.62,"id":8173434}]}]}
{"op":"mcm","clk":"1004403276","pt":1580629027200,"mc":[{"id":"1.168186840","rc":[{"batb":[[1,3.1,47.13],[2,1.01,10.52]],"ltp":3.0,"tv":201.02,"id":8639275},{"batb":[[2,1.28,159.25]],"ltp":1.23,"tv":912.62,"id":8173434}]}]}
{"op":"mcm","clk":"1004403403","pt":1580629030228,"mc":[{"id":"1.168186840","rc":[{"batl":[[0,6,14.93]],"ltp":3.0,"tv":201.02,"id":8639275}]}]}
{"op":"mcm","clk":"1004403697","pt":1580629037523,"mc":[{"id":"1.168186840","rc":[{"trd":[[1.3,7.58]],"batb":[[0,1.3,712.87]],"ltp":1.3,"tv":920.2,"id":8173434}],"tv":1121.22}]}
{"op":"mcm","clk":"1004403837","pt":1580629041630,"mc":[{"id":"1.168186840","rc":[{"batb":[[0,1.28,159.25],[1,1.1,501.99],[2,1.01,10.51]],"batl":[[0,1.62,951.87],[1,1.35,0],[2,1.62,0]],"ltp":1.3,"tv":920.2,"id":8173434}]}]}
{"op":"mcm","clk":"1004403873","pt":1580629042249,"mc":[{"id":"1.168186840","rc":[{"batb":[[0,3.1,47.13],[1,1.01,10.52],[2,1.01,0]],"ltp":3.0,"tv":201.02,"id":8639275},{"batb":[[0,1.1,501.99],[1,1.01,10.51],[2,1.01,0]],"ltp":1.3,"tv":920.2,"id":8173434}]}]}
{"op":"mcm","clk":"1004403956","pt":1580629044651,"mc":[{"id":"1.168186840","rc":[{"batb":[[0,1.14,946.21],[1,1.13,1303.33],[2,1.1,501.99]],"batl":[[0,1.49,483.2],[1,1.5,333.71]],"ltp":1.3,"tv":920.2,"id":8173434}]}]}
{"op":"mcm","clk":"1004403979","pt":1580629045264,"mc":[{"id":"1.168186840","rc":[{"batb":[[0,1.1,501.99],[1,1.01,10.51],[2,1.1,0]],"ltp":1.3,"tv":920.2,"id":8173434}]}]}
{"op":"mcm","clk":"1004404059","pt":1580629047672,"mc":[{"id":"1.168186840","rc":[{"batb":[[0,1.26,1090.85],[1,1.25,844.58],[2,1.1,501.99]],"batl":[[0,1.3,774.11],[1,1.31,609.49]],"ltp":1.3,"tv":920.2,"id":8173434}]}]}
{"op":"mcm","clk":"1004404153","pt":1580629050560,"mc":[{"id":"1.168186840","rc":[{"batl":[[0,6.6,14.96]],"ltp":3.0,"tv":201.02,"id":8639275},{"batl":[[2,1.62,951.87]],"ltp":1.3,"tv":920.2,"id":8173434}]}]}
{"op":"mcm","clk":"1004404194","pt":1580629051440,"mc":[{"id":"1.168186840","rc":[{"batb":[[0,1.1,501.99],[1,1.01,10.51],[2,1.1,0]],"batl":[[0,1.62,951.87],[1,1.31,0],[2,1.62,0]],"ltp":1.3,"tv":920.2,"id":8173434}]}]}
{"op":"mcm","clk":"1004404323","pt":1580629054457,"mc":[{"id":"1.168186840","rc":[{"batb":[[0,1.14,944.4],[1,1.13,1305.16],[2,1.1,501.99]],"batl":[[0,1.49,484.16],[1,1.5,333.71],[2,1.62,951.87]],"ltp":1.3,"tv":920.2,"id":8173434}]}]}
{"op":"mcm","clk":"1004404586","pt":1580629062645,"mc":[{"id":"1.168186840","rc":[{"batb":[[0,1.1,501.99],[1,1.01,10.51],[2,1.1,0]],"ltp":1.3,"tv":920.2,"id":8173434}]}]}
{"op":"mcm","clk":"1004404655","pt":1580629064386,"mc":[{"id":"1.168186840","rc":[{"batl":[[2,1.62,0]],"ltp":1.3,"tv":920.2,"id":8173434}]}]}
{"op":"mcm","clk":"1004404707","pt":1580629065671,"mc":[{"id":"1.168186840","rc":[{"batb":[[0,1.44,506.69],[1,1.43,417.38],[2,1.1,501.99]],"ltp":1.3,"tv":920.2,"id":8173434}]}]}
{"op":"mcm","clk":"1004404752","pt":1580629066591,"mc":[{"id":"1.168186840","rc":[{"batb":[[1,2.72,26.52],[2,1.01,10.52]],"ltp":3.0,"tv":201.02,"id":8639275},{"batb":[[1,1.43,512.11],[2,1.28,160.28]],"ltp":1.3,"tv":920.2,"id":8173434}]}]}
{"op":"mcm","clk":"1004404770","pt":1580629067000,"mc":[{"id":"1.168186840","rc":[{"trd":[[1.44,19.56]],"batb":[[0,1.44,496.91]],"ltp":1.44,"tv":939.76,"id":8173434}],"tv":1140.78}]}
{"op":"mcm","clk":"1004404860","pt":1580629068691,"mc":[{"id":"1.168186840","rc":[{"batl":[[0,4.6,20.95]],"ltp":3.0,"tv":201.02,"id":8639275},{"batl":[[2,1.82,752.81]],"ltp":1.44,"tv":939.76,"id":8173434}]}]}
{"op":"mcm","clk":"1004405096","pt":1580629073663,"mc":[{"id":"1.168186840","rc":[{"batl":[[0,4.2,24.53]],"ltp":3.0,"tv":201.02,"id":8639275}]}]}
{"op":"mcm","clk":"1004405616","pt":1580629088086,"mc":[{"id":"1.168186840","rc":[{"batb":[[0,2.72,26.52],[1,1.01,10.52],[2,1.01,0]],"ltp":3.0,"tv":201.02,"id":8639275},{"batb":[[0,1.28,160.28],[1,1.01,10.51],[2,1.28,0]],"batl":[[0,1.82,752.81],[1,1.5,0],[2,1.82,0]],"ltp":1.44,"tv":939.76,"id":8173434}]}]}
{"op":"mcm","clk":"1004405699","pt":1580629090604,"mc":[{"id":"1.168186840","rc":[{"batb":[[0,1.3,515.13],[1,1.29,693.08],[2,1.28,160.28]],"batl":[[0,1.61,354.07],[1,1.62,250.26],[2,1.82,752.81]],"ltp":1.44,"tv":939.76,"id":8173434}]}]}
{"op":"mcm","clk":"1004405733","pt":1580629091433,"mc":[{"id":"1.168186840","rc":[{"batl":[[0,3.1,42.01],[1,4.2,24.53]],"ltp":3.0,"tv":201.02,"id":8639275}]}]}
{"op":"mcm","clk":"1004406133","pt":1580629100530,"mc":[{"id":"1.168186840","rc":[{"batl":[[0,1.82,752.81],[1,1.62,0],[2,1.82,0]],"ltp":1.44,"tv":939.76,"id":8173434}]}]}
{"op":"mcm","clk":"1004406222","pt":1580629101453,"mc":[{"id":"1.168186840","rc":[{"batl":[[1,4.2,0]],"ltp":3.0,"tv":201.02,"id":8639275}]}]}
{"op":"mcm","clk":"1004406391","pt":1580629103458,"mc":[{"id":"1.168186840","rc":[{"trd":[[3.1,42.01]],"ltp":3.1,"tv":243.03,"id":8639275},{"trd":[[1.47,88.59]],"batl":[[0,1.33,274.92],[1,1.34,550.04]],"ltp":1.47,"tv":1028.35,"id":8173434}],"tv":1271.38}]}
{"op":"mcm","clk":"1004406436","pt":1580629104331,"mc":[{"id":"1.168186840","rc":[{"batb":[[0,4.1,47.05],[1,3.1,46.42],[2,1.01,10.52]],"ltp":3.1,"tv":243.03,"id":8639275}]}]}
{"op":"mcm","clk":"1004406488","pt":1580629105558,"mc":[{"id":"1.168186840","rc":[{"batl":[[0,5.5,15.17]],"ltp":3.1,"tv":243.03,"id":8639275},{"batl":[[2,1.71,858.45]],"ltp":1.47,"tv":1028.35,"id":8173434}]}]}
{"op":"mcm","clk":"1004406535","pt":1580629106540,"mc":[{"id":"1.168186840","rc":[{"batl":[[0,1.33,327.62]],"ltp":1.47,"tv":1028.35,"id":8173434}]}]}
{"op":"mcm","clk":"1004407021","pt":1580629117650,"mc":[{"id":"1.168186840","rc":[{"trd":[[4.1,20]],"batb":[[0,4.1,37.05]],"ltp":4.1,"tv":263.03,"id":8639275}],"tv":1291.38}]}
{"op":"mcm","clk":"1004407732","pt":1580629133686,"mc":[{"id":"1.168186840","rc":[{"batb":[[0,3.1,46.42],[1,1.01,10.52],[2,1.01,0]],"ltp":4.1,"tv":263.03,"id":8639275},{"batb":[[0,1.1,501.28],[1,1.01,10.51],[2,1.28,0]],"batl":[[0,1.71,858.45],[1,1.34,0],[2,1.71,0]],"ltp":1.47,"tv":1028.35,"id":8173434}]}]}
{"op":"mcm","clk":"1004407866","pt":1580629136682,"mc":[{"id":"1.168186840","rc":[{"batb":[[0,3.05,46.97]],"ltp":4.1,"tv":263.03,"id":8639275},{"batb":[[0,1.14,726.72],[1,1.13,1524.77],[2,1.1,497.43]],"batl":[[0,1.48,311.67],[1,1.49,344.25]],"ltp":1.47,"tv":1028.35,"id":8173434}]}]}
{"op":"mcm","clk":"1004408168","pt":1580629144694,"mc":[{"id":"1.168186840","rc":[{"batb":[[0,1.1,497.43],[1,1.01,10.51],[2,1.1,0]],"ltp":1.47,"tv":1028.35,"id":8173434}]}]}
{"op":"mcm","clk":"1004408272","pt":1580629147581,"mc":[{"id":"1.168186840","rc":[{"batb":[[1,2.72,26.36],[2,1.01,10.52]],"ltp":4.1,"tv":263.03,"id":8639275},{"batb":[[0,1.44,325.76],[1,1.43,511.27],[2,1.28,160.98]],"ltp":1.47,"tv":1028.35,"id":8173434}]}]}
{"op":"mcm","clk":"1004408331","pt":1580629148917,"mc":[{"id":"1.168186840","rc":[{"batl":[[0,4.2,24.53]],"ltp":4.1,"tv":263.03,"id":8639275},{"batl":[[2,1.89,704.59]],"ltp":1.47,"tv":1028.35,"id":8173434}]}]}
{"op":"mcm","clk":"1004409229","pt":1580629169609,"mc":[{"id":"1.168186840","rc":[{"batb":[[0,2.72,26.36],[1,1.01,10.52],[2,1.01,0]],"ltp":4.1,"tv":263.03,"id":8639275},{"batb":[[0,1.28,160.98],[1,1.01,10.51],[2,1.28,0]],"batl":[[0,1.89,704.59],[1,1.49,0],[2,1.89,0]],"ltp":1.47,"tv":1028.35,"id":8173434}]}]}
{"op":"mcm","clk":"1004409323","pt":1580629172127,"mc":[{"id":"1.168186840","rc":[{"batb":[[0,1.3,328.19],[1,1.29,690.12],[2,1.28,160.98]],"batl":[[0,1.61,483.54],[1,1.62,249.86],[2,1.89,704.59]],"ltp":1.47,"tv":1028.35,"id":8173434}]}]}
{"op":"mcm","clk":"1004409639","pt":1580629180359,"mc":[{"id":"1.168186840","rc":[{"batb":[[0,1.28,160.98],[1,1.01,10.51],[2,1.28,0]],"ltp":1.47,"tv":1028.35,"id":8173434}]}]}
{"op":"mcm","clk":"1004409763","pt":1580629183236,"mc":[{"id":"1.168186840","rc":[{"batb":[[0,1.55,362.29],[1,1.54,306.11],[2,1.28,160.98]],"ltp":1.47,"tv":1028.35,"id":8173434}]}]}
{"op":"mcm","clk":"1004409814","pt":1580629184460,"mc":[{"id":"1.168186840","rc":[{"batb":[[1,2.52,32.18],[2,1.01,10.52]],"ltp":4.1,"tv":263.03,"id":8639275},{"batb":[[2,1.53,71.52]],"ltp":1.47,"tv":1028.35,"id":8173434}]}]}
{"op":"mcm","clk":"1004409848","pt":1580629185640,"mc":[{"id":"1.168186840","rc":[{"batl":[[0,3.65,30.99]],"ltp":4.1,"tv":263.03,"id":8639275},{"batl":[[2,1.89,0]],"ltp":1.47,"tv":1028.35,"id":8173434}]}]}
{"op":"mcm","clk":"1004409958","pt":1580629188155,"mc":[{"id":"1.168186840","rc":[{"batl":[[2,2.16,570.15]],"ltp":1.47,"tv":1028.35,"id":8173434}]}]}
{"op":"mcm","clk":"1004410013","pt":1580629190666,"mc":[{"id":"1.168186840","rc":[{"batl":[[0,3.3,41.35]],"ltp":4.1,"tv":263.03,"id":8639275}]}]}
{"op":"mcm","clk":"1004410310","pt":1580629197653,"mc":[{"id":"1.168186840","rc":[{"batb":[[0,2.52,32.18],[1,1.01,10.52],[2,1.01,0]],"ltp":4.1,"tv":263.03,"id":8639275},{"batb":[[0,1.42,96.07],[1,1.01,10.51],[2,1.53,0]],"batl":[[0,2.16,570.15],[1,1.62,0],[2,2.16,0]],"ltp":1.47,"tv":1028.35,"id":8173434}]}]}
{"op":"mcm","clk":"1004410542","pt":1580629203654,"mc":[{"id":"1.168186840","rc":[{"batb":[[0,1.52,541.16],[1,1.51,332.05],[2,1.42,96.07]],"batl":[[0,1.58,422.51],[1,1.59,267.66],[2,2.16,570.15]],"ltp":1.47,"tv":1028.35,"id":8173434}]}]}
{"op":"mcm","clk":"1004410683","pt":1580629207102,"mc":[{"id":"1.168186840","rc":[{"batb":[[0,1.42,96.07],[1,1.01,10.51],[2,1.42,0]],"batl":[[0,2.16,570.15],[1,1.59,0],[2,2.16,0]],"ltp":1.47,"tv":1028.35,"id":8173434}]}]}
{"op":"mcm","clk":"1004410785","pt":1580629209872,"mc":[{"id":"1.168186840","rc":[{"batb":[[0,1.43,572.88],[1,1.42,527.54],[2,1.01,10.51]],"batl":[[0,1.7,346.2],[1,1.72,408.97],[2,2.16,570.15]],"ltp":1.47,"tv":1028.35,"id":8173434}]}]}
{"op":"mcm","clk":"1004410897","pt":1580629212589,"mc":[{"id":"1.168186840","rc":[{"batb":[[0,1.42,96.07],[1,1.01,10.51],[2,1.01,0]],"ltp":1.47,"tv":1028.35,"id":8173434}]}]}
{"op":"mcm","clk":"1004411018","pt":1580629215569,"mc":[{"id":"1.168186840","rc":[{"batb":[[0,1.64,241.83],[1,1.63,246.43],[2,1.42,96.07]],"ltp":1.47,"tv":1028.35,"id":8173434}]}]}
{"op":"mcm","clk":"1004411058","pt":1580629216383,"mc":[{"id":"1.168186840","rc":[{"batb":[[1,2.2,46.42],[2,1.01,10.52]],"ltp":4.1,"tv":263.03,"id":8639275},{"batb":[[2,1.6,60.43]],"ltp":1.47,"tv":1028.35,"id":8173434}]}]}
{"op":"mcm","clk":"1004411620","pt":1580629228504,"mc":[{"id":"1.168186840","rc":[{"batb":[[0,1.63,246.43],[1,1.6,60.43],[2,1.54,69.48]],"ltp":1.47,"tv":1028.35,"id":8173434}]}]}
{"op":"mcm","clk":"1004411734","pt":1580629231586,"mc":[{"id":"1.168186840","rc":[{"batb":[[0,1.63,468.06],[1,1.62,252.81],[2,1.6,60.43]],"ltp":1.47,"tv":1028.35,"id":8173434}]}]}
{"op":"mcm","clk":"1004412036","pt":1580629239633,"mc":[{"id":"1.168186840","rc":[{"batb":[[0,1.63,419.64]],"ltp":1.47,"tv":1028.35,"id":8173434}]}]}
{"op":"mcm","clk":"1004412076","pt":1580629240507,"mc":[{"id":"1.168186840","rc":[{"batb":[[0,1.63,376.62]],"batl":[[0,2.16,570.15],[1,1.72,0],[2,2.16,0]],"ltp":1.47,"tv":1028.35,"id":8173434}]}]}
{"op":"mcm","clk":"1004412154","pt":1580629243120,"mc":[{"id":"1.168186840","rc":[{"batl":[[0,1.69,244.05],[1,1.71,418.2],[2,2.16,570.15]],"ltp":1.47,"tv":1028.35,"id":8173434}]}]}
{"op":"mcm","clk":"1004412385","pt":1580629251538,"mc":[{"id":"1.168186840","rc":[{"batb":[[0,2.2,46.42],[1,1.01,10.52],[2,1.01,0]],"ltp":4.1,"tv":263.03,"id":8639275},{"batb":[[0,1.54,69.48],[1,1.01,10.51],[2,1.6,0]],"batl":[[0,2.16,570.15],[1,1.71,0],[2,2.16,0]],"ltp":1.47,"tv":1028.35,"id":8173434}]}]}
{"op":"mcm","clk":"1004412442","pt":1580629254150,"mc":[{"id":"1.168186840","rc":[{"batb":[[0,1.56,281.1],[1,1.55,298.42],[2,1.54,69.48]],"batl":[[0,1.87,250.64],[1,1.89,302.13],[2,2.16,570.15]],"ltp":1.47,"tv":1028.35,"id":8173434}]}]}
{"op":"mcm","clk":"1004412629","pt":1580629261346,"mc":[{"id":"1.168186840","rc":[{"batb":[[0,1.54,69.48],[1,1.01,10.51],[2,1.54,0]],"ltp":1.47,"tv":1028.35,"id":8173434}]}]}
{"op":"mcm","clk":"1004412735","pt":1580629263452,"mc":[{"id":"1.168186840","rc":[{"batl":[[2,2.16,0]],"ltp":1.47,"tv":1028.35,"id":8173434}]}]}
{"op":"mcm","clk":"1004412802","pt":1580629264643,"mc":[{"id":"1.168186840","rc":[{"batb":[[1,1.85,39.26],[2,1.01,10.52]],"ltp":4.1,"tv":263.03,"id":8639275},{"batb":[[0,1.79,385.24],[1,1.77,367.91],[2,1.76,43.51]],"ltp":1.47,"tv":1028.35,"id":8173434}]}]}
{"op":"mcm","clk":"1004412891","pt":1580629267364,"mc":[{"id":"1.168186840","rc":[{"batl":[[0,2.72,67.84]],"ltp":4.1,"tv":263.03,"id":8639275},{"batl":[[2,2.5,464.67]],"ltp":1.47,"tv":1028.35,"id":8173434}]}]}
{"op":"mcm","clk":"1004413050","pt":1580629272040,"mc":[{"id":"1.168186840","rc":[{"batb":[[0,1.79,327.16]],"ltp":1.47,"tv":1028.35,"id":8173434}]}]}
{"op":"mcm","clk":"1004413192","pt":1580629275140,"mc":[{"id":"1.168186840","rc":[{"batl":[[0,1.87,306.21]],"ltp":1.47,"tv":1028.35,"id":8173434}]}]}
{"op":"mcm","clk":"1004413403","pt":1580629280682,"mc":[{"id":"1.168186840","rc":[{"batb":[[0,1.85,39.26],[1,1.01,10.52],[2,1.01,0]],"ltp":4.1,"tv":263.03,"id":8639275},{"batb":[[0,1.65,54.13],[1,1.01,10.51],[2,1.76,0]],"batl":[[0,2.5,464.67],[1,1.89,0],[2,2.5,0]],"ltp":1.47,"tv":1028.35,"id":8173434}]}]}
{"op":"mcm","clk":"1004413655","pt":1580629283563,"mc":[{"id":"1.168186840","rc":[{"batb":[[0,1.66,434.55],[1,1.65,290.81],[2,1.01,10.51]],"batl":[[0,2.2,289.84],[1,2.22,188.07],[2,2.5,464.67]],"ltp":1.47,"tv":1028.35,"id":8173434}]}]}
{"op":"mcm","clk":"1004413804","pt":1580629287571,"mc":[{"id":"1.168186840","rc":[{"batl":[[0,2.5,464.67],[1,2.22,0],[2,2.5,0]],"ltp":1.47,"tv":1028.35,"id":8173434}]}]}
{"op":"mcm","clk":"1004413890","pt":1580629289680,"mc":[{"id":"1.168186840","rc":[{"batl":[[0,1.73,319.93],[1,1.75,386.86]],"ltp":1.47,"tv":1028.35,"id":8173434}]}]}
{"op":"mcm","clk":"1004413923","pt":1580629290605,"mc":[{"id":"1.168186840","rc":[{"batb":[[0,2.4,36.51],[1,2.04,57.44],[2,1.01,10.52]],"ltp":4.1,"tv":263.03,"id":8639275},{"batb":[[2,1.57,65.54]],"ltp":1.47,"tv":1028.35,"id":8173434}]}]}
{"op":"mcm","clk":"1004414003","pt":1580629292509,"mc":[{"id":"1.168186840","rc":[{"batl":[[2,2.3,522.55]],"ltp":1.47,"tv":1028.35,"id":8173434}]}]}
{"op":"mcm","clk":"1004414641","pt":1580629304587,"mc":[{"id":"1.168186840","rc":[{"batb":[[1,2.06,14.58],[2,2.04,57.44]],"ltp":4.1,"tv":263.03,"id":8639275}]}]}
{"op":"mcm","clk":"1004415103","pt":1580629313636,"mc":[{"id":"1.168186840","rc":[{"batb":[[0,2.04,57.44],[1,1.01,10.52],[2,2.04,0]],"ltp":4.1,"tv":263.03,"id":8639275},{"batb":[[0,1.57,65.54],[1,1.01,10.51],[2,1.57,0]],"batl":[[0,2.3,522.55],[1,1.75,0],[2,2.3,0]],"ltp":1.47,"tv":1028.35,"id":8173434}]}]}
{"op":"mcm","clk":"1004415208","pt":1580629314613,"mc":[{"id":"1.168186840","rc":[{"batb":[[0,2.04,57.28]],"ltp":4.1,"tv":263.03,"id":8639275}]}]}
{"op":"mcm","clk":"1004415342","pt":1580629316306,"mc":[{"id":"1.168186840","rc":[{"batb":[[0,1.57,335.03],[1,1.56,291.25],[2,1.01,10.51]],"batl":[[0,1.97,243.99],[1,1.99,258.16],[2,2.3,522.55]],"ltp":1.47,"tv":1028.35,"id":8173434}]}]}
{"op":"mcm","clk":"1004416386","pt":1580629343624,"mc":[{"id":"1.168186840","rc":[{"batb":[[0,1.57,65.54],[1,1.01,10.51],[2,1.01,0]],"ltp":1.47,"tv":1028.35,"id":8173434}]}]}
{"op":"mcm","clk":"1004416435","pt":1580629345260,"mc":[{"id":"1.168186840","rc":[{"batl":[[2,2.3,0]],"ltp":1.47,"tv":1028.35,"id":8173434}]}]}
{"op":"mcm","clk":"1004416494","pt":1580629346555,"mc":[{"id":"1.168186840","rc":[{"batb":[[0,1.89,218.04],[1,1.87,307.01],[2,1.57,65.54]],"ltp":1.47,"tv":1028.35,"id":8173434}]}]}
{"op":"mcm","clk":"1004416533","pt":1580629347565,"mc":[{"id":"1.168186840","rc":[{"batb":[[1,1.65,56.65],[2,1.01,10.52]],"ltp":4.1,"tv":263.03,"id":8639275},{"batb":[[1,1.87,342.65],[2,1.7,48.78]],"ltp":1.47,"tv":1028.35,"id":8173434}]}]}
{"op":"mcm","clk":"1004416614","pt":1580629349665,"mc":[{"id":"1.168186840","rc":[{"batl":[[0,2.6,74.97]],"ltp":4.1,"tv":263.03,"id":8639275},{"batl":[[2,2.6,440.17]],"ltp":1.47,"tv":1028.35,"id":8173434}]}]}
{"op":"mcm","clk":"1004417409","pt":1580629369687,"mc":[{"id":"1.168186840","rc":[{"batb":[[0,1.65,56.65],[1,1.01,10.52],[2,1.01,0]],"ltp":4.1,"tv":263.03,"id":8639275},{"batb":[[0,1.7,48.78],[1,1.2,3.94],[2,1.01,10.51]],"batl":[[0,2.6,440.17],[1,1.99,0],[2,2.6,0]],"ltp":1.47,"tv":1028.35,"id":8173434}]}]}
{"op":"mcm","clk":"1004417531","pt":1580629372567,"mc":[{"id":"1.168186840","rc":[{"batb":[[0,1.66,55.31],[1,1.65,56.65],[2,1.01,10.52]],"ltp":4.1,"tv":263.03,"id":8639275},{"batb":[[0,1.7,453.57],[1,1.69,49.96],[2,1.68,440.84]],"batl":[[0,2.48,220.76],[1,2.52,268.33],[2,2.6,440.17]],"ltp":1.47,"tv":1028.35,"id":8173434}]}]}
{"op":"mcm","clk":"1004417573","pt":1580629373689,"mc":[{"id":"1.168186840","rc":[{"batb":[[1,1.01,10.52],[2,1.01,0]],"ltp":4.1,"tv":263.03,"id":8639275},{"batb":[[0,1.7,404.79]],"batl":[[0,2.6,440.17],[1,2.52,0],[2,2.6,0]],"ltp":1.47,"tv":1028.35,"id":8173434}]}]}
{"op":"mcm","clk":"1004417688","pt":1580629376676,"mc":[{"id":"1.168186840","rc":[{"batb":[[0,2.32,39.89],[1,1.88,37.61],[2,1.66,55.31]],"ltp":4.1,"tv":263.03,"id":8639275},{"batl":[[0,1.77,252.19],[1,1.79,359.37]],"ltp":1.47,"tv":1028.35,"id":8173434}]}]}
{"op":"mcm","clk":"1004417727","pt":1580629377497,"mc":[{"id":"1.168186840","rc":[{"batb":[[2,1.01,10.52]],"ltp":4.1,"tv":263.03,"id":8639275}]}]}
{"op":"mcm","clk":"1004417766","pt":1580629378474,"mc":[{"id":"1.168186840","rc":[{"batl":[[0,2.92,55.6]],"ltp":4.1,"tv":263.03,"id":8639275},{"batl":[[2,2.36,504.18]],"ltp":1.47,"tv":1028.35,"id":8173434}]}]}
{"op":"mcm","clk":"1004418224","pt":1580629391277,"mc":[{"id":"1.168186840","rc":[{"batb":[[0,1.7,313.35]],"ltp":1.47,"tv":1028.35,"id":8173434}]}]}
{"op":"mcm","clk":"1004418420","pt":1580629394681,"mc":[{"id":"1.168186840","rc":[{"batb":[[0,1.69,49.96],[1,1.56,66.41],[2,1.2,3.94]],"batl":[[0,2.36,504.18],[1,1.79,0],[2,2.36,0]],"ltp":1.47,"tv":1028.35,"id":8173434}]}]}
{"op":"mcm","clk":"1004418448","pt":1580629395400,"mc":[{"id":"1.168186840","rc":[{"batb":[[0,1.88,37.61],[1,1.01,10.52],[2,1.01,0]],"ltp":4.1,"tv":263.03,"id":8639275},{"batb":[[0,1.56,66.41],[1,1.2,3.94],[2,1.01,10.51]],"ltp":1.47,"tv":1028.35,"id":8173434}]}]}
{"op":"mcm","clk":"1004418537","pt":1580629397507,"mc":[{"id":"1.168186840","rc":[{"batb":[[0,1.56,417.58],[1,1.55,299.32],[2,1.2,3.94]],"batl":[[0,2.14,212.6],[1,2.16,203.15],[2,2.36,504.18]],"ltp":1.47,"tv":1028.35,"id":8173434}]}]}
{"op":"mcm","clk":"1004418619","pt":1580629399620,"mc":[{"id":"1.168186840","rc":[{"batl":[[0,2.36,504.18],[1,2.16,0],[2,2.36,0]],"ltp":1.47,"tv":1028.35,"id":8173434}]}]}
{"op":"mcm","clk":"1004418734","pt":1580629402608,"mc":[{"id":"1.168186840","rc":[{"batl":[[0,1.62,466.53],[1,1.63,245.31]],"ltp":1.47,"tv":1028.35,"id":8173434}]}]}
{"op":"mcm","clk":"1004418781","pt":1580629403529,"mc":[{"id":"1.168186840","rc":[{"batb":[[0,2.62,28.88],[1,2.28,42.33],[2,1.01,10.52]],"ltp":4.1,"tv":263.03,"id":8639275},{"batb":[[2,1.51,76.16]],"ltp":1.47,"tv":1028.35,"id":8173434}]}]}
{"op":"mcm","clk":"1004418857","pt":1580629405597,"mc":[{"id":"1.168186840","rc":[{"batl":[[0,3.3,38.74]],"ltp":4.1,"tv":263.03,"id":8639275},{"batl":[[2,2.16,574.09]],"ltp":1.47,"tv":1028.35,"id":8173434}]}]}
{"op":"mcm","clk":"1004419219","pt":1580629415246,"mc":[{"id":"1.168186840","rc":[{"batb":[[0,2.28,42.33],[1,1.01,10.52],[2,1.01,0]],"ltp":4.1,"tv":263.03,"id":8639275},{"batb":[[0,1.51,76.16],[1,1.2,3.94],[2,1.01,10.51]],"batl":[[0,2.16,574.09],[1,1.63,0],[2,2.16,0]],"ltp":1.47,"tv":1028.35,"id":8173434}]}]}
{"op":"mcm","clk":"1004419340","pt":1580629417652,"mc":[{"id":"1.168186840","rc":[{"batb":[[1,1.49,328.03],[2,1.48,360.57]],"batl":[[0,1.79,361.87],[1,1.81,346.7],[2,2.16,574.09]],"ltp":1.47,"tv":1028.35,"id":8173434}]}]}
{"op":"mcm","clk":"1004419377","pt":1580629418527,"mc":[{"id":"1.168186840","rc":[{"batb":[[1,1.2,3.94],[2,1.01,10.51]],"batl":[[0,2.16,574.09],[1,1.81,0],[2,2.16,0]],"ltp":1.47,"tv":1028.35,"id":8173434}]}]}
{"op":"mcm","clk":"1004419505","pt":1580629421650,"mc":[{"id":"1.168186840","rc":[{"batb":[[0,1.59,314.37],[1,1.58,277.87],[2,1.51,76.16]],"batl":[[0,1.65,410.68],[1,1.67,453.55],[2,2.16,574.09]],"ltp":1.47,"tv":1028.35,"id":8173434}]}]}
{"op":"mcm","clk":"1004419750","pt":1580629426628,"mc":[{"id":"1.168186840","rc":[{"batb":[[0,1.51,76.16],[1,1.2,3.94],[2,1.01,10.51]],"batl":[[0,2.16,574.09],[1,1.67,0],[2,2.16,0]],"ltp":1.47,"tv":1028.35,"id":8173434}]}]}
{"op":"mcm","clk":"1004419817","pt":1580629428740,"mc":[{"id":"1.168186840","rc":[{"batb":[[1,1.49,328.03],[2,1.48,360.57]],"batl":[[0,1.79,361.87],[1,1.81,346.7],[2,2.16,574.09]],"ltp":1.47,"tv":1028.35,"id":8173434}]}]}
{"op":"mcm","clk":"1004419976","pt":1580629432645,"mc":[{"id":"1.168186840","rc":[{"batl":[[0,2.16,574.09],[1,1.81,0],[2,2.16,0]],"ltp":1.47,"tv":1028.35,"id":8173434}]}]}
{"op":"mcm","clk":"1004420101","pt":1580629435674,"mc":[{"id":"1.168186840","rc":[{"batb":[[0,2.32,578.64],[1,2.28,42.33],[2,1.01,10.52]],"ltp":4.1,"tv":263.03,"id":8639275},{"batl":[[0,1.54,455.55],[1,1.55,295.18]],"ltp":1.47,"tv":1028.35,"id":8173434}]}]}
{"op":"mcm","clk":"1004420137","pt":1580629436652,"mc":[{"id":"1.168186840","rc":[{"batb":[[0,2.8,24.47],[1,2.58,30.21]],"ltp":4.1,"tv":263.03,"id":8639275}]}]}
{"op":"mcm","clk":"1004420193","pt":1580629438142,"mc":[{"id":"1.168186840","rc":[{"batl":[[0,3.65,30.37]],"ltp":4.1,"tv":263.03,"id":8639275},{"batl":[[2,2.04,630.67]],"ltp":1.47,"tv":1028.35,"id":8173434}]}]}
{"op":"mcm","clk":"1004421874","pt":1580629482519,"mc":[{"id":"1.168186840","rc":[{"batl":[[0,1.54,319.25]],"ltp":1.47,"tv":1028.35,"id":8173434}]}]}
{"op":"mcm","clk":"1004421971","pt":1580629485642,"mc":[{"id":"1.168186840","rc":[{"batb":[[1,1.49,469.12]],"ltp":1.47,"tv":1028.35,"id":8173434}]}]}
{"op":"mcm","clk":"1004423042","pt":1580629511647,"mc":[{"id":"1.168186840","rc":[{"batb":[[1,1.39,105.98],[2,1.2,3.94]],"batl":[[0,2.04,630.67],[1,1.55,0],[2,2.04,0]],"ltp":1.47,"tv":1028.35,"id":8173434}]}]}
{"op":"mcm","clk":"1004423074","pt":1580629512165,"mc":[{"id":"1.168186840","rc":[{"batb":[[0,2.58,30.21],[1,1.01,10.52],[2,1.01,0]],"ltp":4.1,"tv":263.03,"id":8639275},{"batb":[[0,1.39,105.98],[1,1.2,3.94],[2,1.01,10.51]],"ltp":1.47,"tv":1028.35,"id":8173434}]}]}
{"op":"mcm","clk":"1004423185","pt":1580629514675,"mc":[{"id":"1.168186840","rc":[{"batb":[[1,1.38,755.35],[2,1.37,512.03]],"batl":[[0,1.63,445.13],[1,1.64,239.45],[2,2.04,630.67]],"ltp":1.47,"tv":1028.35,"id":8173434}]}]}
{"op":"mcm","clk":"1004423835","pt":1580629529883,"mc":[{"id":"1.168186840","rc":[{"batb":[[1,1.2,3.94],[2,1.01,10.51]],"ltp":1.47,"tv":1028.35,"id":8173434}]}]}
{"op":"mcm","clk":"1004423932","pt":1580629532699,"mc":[{"id":"1.168186840","rc":[{"batb":[[0,1.57,336.7],[1,1.56,291.13],[2,1.39,105.98]],"ltp":1.47,"tv":1028.35,"id":8173434}]}]}
{"op":"mcm","clk":"1004423983","pt":1580629533673,"mc":[{"id":"1.168186840","rc":[{"batb":[[1,2.44,35.17],[2,1.01,10.52]],"ltp":4.1,"tv":263.03,"id":8639275},{"batb":[[0,1.58,63.89],[1,1.57,336.7],[2,1.56,291.13]],"ltp":1.47,"tv":1028.35,"id":8173434}]}]}
{"op":"mcm","clk":"1004424103","pt":1580629536594,"mc":[{"id":"1.168186840","rc":[{"batl":[[0,3.3,41.35]],"ltp":4.1,"tv":263.03,"id":8639275}]}]}
{"op":"mcm","clk":"1004424266","pt":1580629540397,"mc":[{"id":"1.168186840","rc":[{"batb":[[1,1.48,82.93],[2,1.2,3.94]],"batl":[[0,2.04,630.67],[1,1.64,0],[2,2.04,0]],"ltp":1.47,"tv":1028.35,"id":8173434}]}]}
{"op":"mcm","clk":"1004424320","pt":1580629541273,"mc":[{"id":"1.168186840","rc":[{"batb":[[0,2.44,35.17],[1,1.01,10.52],[2,1.01,0]],"ltp":4.1,"tv":263.03,"id":8639275},{"batb":[[0,1.48,82.93],[1,1.2,3.94],[2,1.01,10.51]],"ltp":1.47,"tv":1028.35,"id":8173434}]}]}
{"op":"mcm","clk":"1004424456","pt":1580629543583,"mc":[{"id":"1.168186840","rc":[{"batb":[[1,1.47,460.36],[2,1.46,381.66]],"batl":[[0,1.7,315.79],[1,1.72,409.25],[2,2.04,630.67]],"ltp":1.47,"tv":1028.35,"id":8173434}]}]}
{"op":"mcm","clk":"1004424972","pt":1580629554601,"mc":[{"id":"1.168186840","rc":[{"batb":[[1,1.2,3.94],[2,1.01,10.51]],"ltp":1.47,"tv":1028.35,"id":8173434}]}]}
{"op":"mcm","clk":"1004425115","pt":1580629557631,"mc":[{"id":"1.168186840","rc":[{"batb":[[0,1.64,271.61],[1,1.63,246.6],[2,1.48,82.93]],"ltp":1.47,"tv":1028.35,"id":8173434}]}]}
{"op":"mcm","clk":"1004425162","pt":1580629558403,"mc":[{"id":"1.168186840","rc":[{"batb":[[1,2.34,39.5],[2,1.01,10.52]],"ltp":4.1,"tv":263.03,"id":8639275},{"batb":[[0,1.64,327.55],[2,1.56,66.56]],"ltp":1.47,"tv":1028.35,"id":8173434}]}]}
{"op":"mcm","clk":"1004425732","pt":1580629571601,"mc":[{"id":"1.168186840","rc":[{"batb":[[0,1.64,55.94],[1,1.56,66.56],[2,1.2,3.94]],"batl":[[0,2.04,630.67],[1,1.72,0],[2,2.04,0]],"ltp":1.47,"tv":1028.35,"id":8173434}]}]}
{"op":"mcm","clk":"1004425764","pt":1580629572524,"mc":[{"id":"1.168186840","rc":[{"batb":[[0,2.34,39.5],[1,1.01,10.52],[2,1.01,0]],"ltp":4.1,"tv":263.03,"id":8639275},{"batb":[[0,1.56,66.56],[1,1.2,3.94],[2,1.01,10.51]],"ltp":1.47,"tv":1028.35,"id":8173434}]}]}
{"op":"mcm","clk":"1004425868","pt":1580629574534,"mc":[{"id":"1.168186840","rc":[{"batb":[[0,1.56,524.45],[1,1.55,298.99],[2,1.2,3.94]],"batl":[[0,1.75,231.32],[1,1.77,372.26],[2,2.04,630.67]],"ltp":1.47,"tv":1028.35,"id":8173434}]}]}
{"op":"mcm","clk":"1004426036","pt":1580629578538,"mc":[{"id":"1.168186840","rc":[{"batl":[[0,2.04,630.67],[1,1.77,0],[2,2.04,0]],"ltp":1.47,"tv":1028.35,"id":8173434}]}]}
{"op":"mcm","clk":"1004426141","pt":1580629581615,"mc":[{"id":"1.168186840","rc":[{"batl":[[0,1.62,362.43],[1,1.63,244.99],[2,2.04,630.67]],"ltp":1.47,"tv":1028.35,"id":8173434}]}]}
{"op":"mcm","clk":"1004426189","pt":1580629582645,"mc":[{"id":"1.168186840","rc":[{"batb":[[0,2.62,28.72],[1,2.46,34.7],[2,1.01,10.52]],"ltp":4.1,"tv":263.03,"id":8639275},{"batb":[[2,1.45,89.62]],"ltp":1.47,"tv":1028.35,"id":8173434}]}]}
{"op":"mcm","clk":"1004427004","pt":1580629600160,"mc":[{"id":"1.168186840","rc":[{"batb":[[0,2.46,34.7],[1,1.01,10.52],[2,1.01,0]],"ltp":4.1,"tv":263.03,"id":8639275},{"batb":[[0,1.45,89.62],[1,1.2,3.94],[2,1.01,10.51]],"batl":[[0,2.04,630.67],[1,1.63,0],[2,2.04,0]],"ltp":1.47,"tv":1028.35,"id":8173434}]}]}
{"op":"mcm","clk":"1004427118","pt":1580629602776,"mc":[{"id":"1.168186840","rc":[{"batb":[[0,1.45,527.66],[1,1.44,404.89],[2,1.2,3.94]],"batl":[[0,1.71,368.46],[1,1.73,401.05],[2,2.04,630.67]],"ltp":1.47,"tv":1028.35,"id":8173434}]}]}
{"op":"mcm","clk":"1004427525","pt":1580629612384,"mc":[{"id":"1.168186840","rc":[{"batl":[[0,2.04,630.67],[1,1.73,0],[2,2.04,0]],"ltp":1.47,"tv":1028.35,"id":8173434}]}]}
{"op":"mcm","clk":"1004427603","pt":1580629614080,"mc":[{"id":"1.168186840","rc":[{"batl":[[0,1.65,2.27],[1,2.04,630.67]],"ltp":1.47,"tv":1028.35,"id":8173434}]}]}
{"op":"mcm","clk":"1004427672","pt":1580629615680,"mc":[{"id":"1.168186840","rc":[{"batb":[[0,2.98,50.59],[1,2.64,28.72],[2,2.46,34.7]],"ltp":4.1,"tv":263.03,"id":8639275},{"batb":[[2,1.28,157.36]],"batl":[[0,1.5,506.89],[1,1.51,325.46],[2,1.65,2.27]],"ltp":1.47,"tv":1028.35,"id":8173434}]}]}
{"op":"mcm","clk":"1004427698","pt":1580629616092,"mc":[{"id":"1.168186840","rc":[{"batb":[[2,1.01,10.52]],"ltp":4.1,"tv":263.03,"id":8639275}]}]}
{"op":"mcm","clk":"1004427791","pt":1580629617685,"mc":[{"id":"1.168186840","rc":[{"batl":[[0,3.9,27.37]],"ltp":4.1,"tv":263.03,"id":8639275}]}]}
{"op":"mcm","clk":"1004428524","pt":1580629633637,"mc":[{"id":"1.168186840","rc":[{"batb":[[0,1.45,89.62],[1,1.28,157.36],[2,1.2,3.94]],"batl":[[0,1.65,2.27],[1,2.04,630.67],[2,1.65,0]],"ltp":1.47,"tv":1028.35,"id":8173434}]}]}
{"op":"mcm","clk":"1004428570","pt":1580629634613,"mc":[{"id":"1.168186840","rc":[{"batb":[[0,2.64,28.72],[1,1.01,10.52],[2,1.01,0]],"ltp":4.1,"tv":263.03,"id":8639275},{"batb":[[0,1.28,157.36],[1,1.2,3.94],[2,1.01,10.51]],"ltp":1.47,"tv":1028.35,"id":8173434}]}]}
{"op":"mcm","clk":"1004428729","pt":1580629638116,"mc":[{"id":"1.168186840","rc":[{"batl":[[1,2.04,0]],"ltp":1.47,"tv":1028.35,"id":8173434}]}]}
{"op":"mcm","clk":"1004428785","pt":1580629639448,"mc":[{"id":"1.168186840","rc":[{"batb":[[0,1.42,271.97],[1,1.41,443.16],[2,1.28,157.36]],"batl":[[0,1.46,441.24],[1,1.47,363.11],[2,1.65,2.27]],"ltp":1.47,"tv":1028.35,"id":8173434}]}]}
{"op":"mcm","clk":"1004428990","pt":1580629644632,"mc":[{"id":"1.168186840","rc":[{"batb":[[0,1.28,157.36],[1,1.2,3.94],[2,1.01,10.51]],"batl":[[0,1.65,2.27],[1,1.89,709.46],[2,1.65,0]],"ltp":1.47,"tv":1028.35,"id":8173434}]}]}
{"op":"mcm","clk":"1004429058","pt":1580629646640,"mc":[{"id":"1.168186840","rc":[{"batb":[[0,1.29,870.66],[1,1.28,889.38],[2,1.2,3.94]],"batl":[[0,1.63,304.33],[1,1.64,239.87],[2,1.65,2.27]],"ltp":1.47,"tv":1028.35,"id":8173434}]}]}
{"op":"mcm","clk":"1004429448","pt":1580629655635,"mc":[{"id":"1.168186840","rc":[{"batb":[[0,1.28,157.36],[1,1.2,3.94],[2,1.01,10.51]],"ltp":1.47,"tv":1028.35,"id":8173434}]}]}
{"op":"mcm","clk":"1004429485","pt":1580629656457,"mc":[{"id":"1.168186840","rc":[{"batb":[[0,1.01,10.52],[1,1.01,0]],"ltp":4.1,"tv":263.03,"id":8639275}]}]}
{"op":"mcm","clk":"1004429599","pt":1580629658666,"mc":[{"id":"1.168186840","rc":[{"batb":[[0,1.57,485.98],[1,1.56,291.67],[2,1.28,157.36]],"ltp":1.47,"tv":1028.35,"id":8173434}]}]}
{"op":"mcm","clk":"1004429642","pt":1580629659537,"mc":[{"id":"1.168186840","rc":[{"batb":[[0,2.62,28.8],[1,2.42,35.64],[2,1.01,10.52]],"ltp":4.1,"tv":263.03,"id":8639275},{"batb":[[1,1.56,358.08],[2,1.44,91.82]],"ltp":1.47,"tv":1028.35,"id":8173434}]}]}
{"op":"mcm","clk":"1004429720","pt":1580629661181,"mc":[{"id":"1.168186840","rc":[{"batl":[[0,3.3,41.35]],"ltp":4.1,"tv":263.03,"id":8639275}]}]}
{"op":"mcm","clk":"1004430694","pt":1580629681686,"mc":[{"id":"1.168186840","rc":[{"batb":[[0,1.56,66.41],[1,1.44,91.82],[2,1.2,3.94]],"batl":[[0,1.65,2.27],[1,2.16,570.15],[2,1.65,0]],"ltp":1.47,"tv":1028.35,"id":8173434}]}]}
{"op":"mcm","clk":"1004430707","pt":1580629681892,"mc":[{"id":"1.168186840","rc":[{"batb":[[0,2.42,35.64],[1,1.01,10.52],[2,1.01,0]],"ltp":4.1,"tv":263.03,"id":8639275},{"batb":[[0,1.44,90.72],[1,1.2,3.94],[2,1.01,10.51]],"ltp":1.47,"tv":1028.35,"id":8173434}]}]}
{"op":"mcm","clk":"1004430810","pt":1580629684405,"mc":[{"id":"1.168186840","rc":[{"batb":[[0,1.44,751.34],[1,1.43,419.18],[2,1.2,3.94]],"batl":[[1,1.73,225.83],[2,1.75,386.48]],"ltp":1.47,"tv":1028.35,"id":8173434}]}]}
{"op":"mcm","clk":"1004431181","pt":1580629692225,"mc":[{"id":"1.168186840","rc":[{"batl":[[0,1.65,4.54]],"ltp":1.47,"tv":1028.35,"id":8173434}]}]}
{"op":"mcm","clk":"1004431226","pt":1580629693610,"mc":[{"id":"1.168186840","rc":[{"batl":[[1,2.16,570.15],[2,1.75,0]],"ltp":1.47,"tv":1028.35,"id":8173434}]}]}
{"op":"mcm","clk":"1004431288","pt":1580629695303,"mc":[{"id":"1.168186840","rc":[{"batl":[[1,2.16,0]],"ltp":1.47,"tv":1028.35,"id":8173434}]}]}
{"op":"mcm","clk":"1004431349","pt":1580629696698,"mc":[{"id":"1.168186840","rc":[{"batl":[[0,1.49,344.01],[1,1.5,335.16],[2,1.65,4.54]],"ltp":1.47,"tv":1028.35,"id":8173434}]}]}
{"op":"mcm","clk":"1004431388","pt":1580629697527,"mc":[{"id":"1.168186840","rc":[{"batb":[[0,3,49.88],[1,2.64,28.72],[2,1.01,10.52]],"ltp":4.1,"tv":263.03,"id":8639275},{"batb":[[2,1.28,158.94]],"ltp":1.47,"tv":1028.35,"id":8173434}]}]}
{"op":"mcm","clk":"1004431446","pt":1580629698918,"mc":[{"id":"1.168186840","rc":[{"batl":[[0,3.9,27.37]],"ltp":4.1,"tv":263.03,"id":8639275}]}]}
{"op":"mcm","clk":"1004432282","pt":1580629718338,"mc":[{"id":"1.168186840","rc":[{"batb":[[0,2.64,28.72],[1,1.01,10.52],[2,1.01,0]],"ltp":4.1,"tv":263.03,"id":8639275},{"batb":[[0,1.28,158.94],[1,1.2,3.94],[2,1.01,10.51]],"batl":[[0,1.65,4.54],[1,1.95,669.26],[2,1.65,0]],"ltp":1.47,"tv":1028.35,"id":8173434}]}]}
{"op":"mcm","clk":"1004432420","pt":1580629721532,"mc":[{"id":"1.168186840","rc":[{"batb":[[0,1.29,656.67],[1,1.28,886.86],[2,1.2,3.94]],"batl":[[0,1.63,443.44],[1,1.64,239.35],[2,1.65,4.54]],"ltp":1.47,"tv":1028.35,"id":8173434}]}]}
{"op":"mcm","clk":"1004432488","pt":1580629722664,"mc":[{"id":"1.168186840","rc":[{"batb":[[0,1.28,158.94],[1,1.2,3.94],[2,1.01,10.51]],"batl":[[0,1.65,4.54],[1,1.95,669.26],[2,1.65,0]],"ltp":1.47,"tv":1028.35,"id":8173434}]}]}
{"op":"mcm","clk":"1004432606","pt":1580629725335,"mc":[{"id":"1.168186840","rc":[{"batb":[[0,1.41,528.3],[1,1.4,460.1],[2,1.28,158.94]],"batl":[[0,1.46,615.41],[1,1.47,361.68],[2,1.65,4.54]],"ltp":1.47,"tv":1028.35,"id":8173434}]}]}
{"op":"mcm","clk":"1004432782","pt":1580629729143,"mc":[{"id":"1.168186840","rc":[{"batb":[[0,1.28,158.94],[1,1.2,3.94],[2,1.01,10.51]],"batl":[[0,1.65,4.54],[1,1.95,669.26],[2,1.65,0]],"ltp":1.47,"tv":1028.35,"id":8173434}]}]}
{"op":"mcm","clk":"1004432937","pt":1580629732651,"mc":[{"id":"1.168186840","rc":[{"batb":[[0,1.29,656.67],[1,1.28,886.86],[2,1.2,3.94]],"batl":[[0,1.63,443.44],[1,1.64,239.35],[2,1.65,4.54]],"ltp":1.47,"tv":1028.35,"id":8173434}]}]}
{"op":"mcm","clk":"1004433046","pt":1580629735073,"mc":[{"id":"1.168186840","rc":[{"batl":[[0,1.65,4.54],[1,1.95,669.26],[2,1.65,0]],"ltp":1.47,"tv":1028.35,"id":8173434}]}]}
{"op":"mcm","clk":"1004433113","pt":1580629736356,"mc":[{"id":"1.168186840","rc":[{"batl":[[1,1.95,0]],"ltp":1.47,"tv":1028.35,"id":8173434}]}]}
{"op":"mcm","clk":"1004433247","pt":1580629738678,"mc":[{"id":"1.168186840","rc":[{"batb":[[0,4,47.6],[1,3,49.65],[2,1.01,10.52]],"ltp":4.1,"tv":263.03,"id":8639275},{"batl":[[0,1.32,302.21],[1,1.33,572.99],[2,1.65,4.54]],"ltp":1.47,"tv":1028.35,"id":8173434}]}]}
{"op":"mcm","clk":"1004433339","pt":1580629740374,"mc":[{"id":"1.168186840","rc":[{"batl":[[0,5.5,15.17]],"ltp":4.1,"tv":263.03,"id":8639275}]}]}
{"op":"mcm","clk":"1004433508","pt":1580629743355,"mc":[{"id":"1.168186840","rc":[{"trd":[[4.1,117.3]],"ltp":4.1,"tv":360.32,"id":8639275},{"trd":[[1.32,302.2]],"batl":[[0,1.33,573],[1,1.65,4.54],[2,1.71,858.45]],"ltp":1.32,"tv":1330.55,"id":8173434}],"tv":1690.87}]}
{"op":"mcm","clk":"1004433567","pt":1580629744385,"mc":[{"id":"1.168186840","rc":[{"batl":[[0,1.33,572.99]],"ltp":1.32,"tv":1330.55,"id":8173434}]}]}
{"op":"mcm","clk":"1004433740","pt":1580629747676,"mc":[{"id":"1.168186840","rc":[{"batb":[[0,1.29,770.25]],"batl":[[0,1.33,763.01],[1,1.34,543.61],[2,1.65,4.54]],"ltp":1.32,"tv":1330.55,"id":8173434}]}]}
{"op":"mcm","clk":"1004434159","pt":1580629755669,"mc":[{"id":"1.168186840","rc":[{"batb":[[0,3,49.65],[1,1.01,10.52],[2,1.01,0]],"ltp":4.1,"tv":360.32,"id":8639275},{"batb":[[0,1.2,3.94],[1,1.08,595.39],[2,1.01,10.51]],"batl":[[0,1.65,4.54],[1,1.71,858.45],[2,1.65,0]],"ltp":1.32,"tv":1330.55,"id":8173434}]}]}
{"op":"mcm","clk":"1004434252","pt":1580629757580,"mc":[{"id":"1.168186840","rc":[{"batl":[[1,1.71,0]],"ltp":1.32,"tv":1330.55,"id":8173434}]}]}
{"op":"mcm","clk":"1004434286","pt":1580629758464,"mc":[{"id":"1.168186840","rc":[{"batb":[[1,1.12,926.16],[2,1.11,1362.78]],"batl":[[0,1.49,398.97],[1,1.5,333.95],[2,1.65,4.54]],"ltp":1.32,"tv":1330.55,"id":8173434}]}]}
{"op":"mcm","clk":"1004434569","pt":1580629765611,"mc":[{"id":"1.168186840","rc":[{"batl":[[0,1.65,4.54],[1,1.5,0],[2,1.65,0]],"ltp":1.32,"tv":1330.55,"id":8173434}]}]}
{"op":"mcm","clk":"1004434703","pt":1580629768691,"mc":[{"id":"1.168186840","rc":[{"trd":[[1.2,7.88]],"batb":[[0,1.12,926.16],[1,1.11,1362.78],[2,1.08,595.39]],"batl":[[0,1.14,1398.09],[1,1.15,829.47],[2,1.65,4.54]],"ltp":1.2,"tv":1338.42,"id":8173434}],"tv":1698.75}]}
{"op":"mcm","clk":"1004434756","pt":1580629769670,"mc":[{"id":"1.168186840","rc":[{"trd":[[9.4,31.24]],"batb":[[0,6.8,27.46]],"ltp":9.4,"tv":391.56,"id":8639275},{"trd":[[1.12,262.15]],"batb":[[0,1.12,664.01]],"batl":[[1,1.15,633.6]],"ltp":1.12,"tv":1600.57,"id":8173434}],"tv":1992.14}]}
{"op":"mcm","clk":"1004434796","pt":1580629770596,"mc":[{"id":"1.168186840","rc":[{"batl":[[0,11.5,17.17]],"ltp":9.4,"tv":391.56,"id":8639275},{"batl":[[2,1.47,1199.34]],"ltp":1.12,"tv":1600.57,"id":8173434}]}]}
{"op":"mcm","clk":"1004434872","pt":1580629772394,"mc":[{"id":"1.168186840","rc":[{"batb":[[1,1.11,1566.76]],"batl":[[0,1.14,1599.62]],"ltp":1.12,"tv":1600.57,"id":8173434}]}]}
{"op":"mcm","clk":"1004435214","pt":1580629779601,"mc":[{"id":"1.168186840","rc":[{"trd":[[1.14,21.7]],"batl":[[0,1.14,1588.77]],"ltp":1.14,"tv":1622.27,"id":8173434}],"tv":2013.83}]}
{"op":"mcm","clk":"1004435271","pt":1580629780632,"mc":[{"id":"1.168186840","rc":[{"trd":[[1.14,27.62]],"batl":[[0,1.14,1585.81]],"ltp":1.14,"tv":1628.19,"id":8173434}],"tv":2019.76}]}
{"op":"mcm","clk":"1004435389","pt":1580629782586,"mc":[{"id":"1.168186840","rc":[{"batb":[[0,1.12,730.04]],"ltp":1.14,"tv":1628.19,"id":8173434}]}]}
{"op":"mcm","clk":"1004435536","pt":1580629785317,"mc":[{"id":"1.168186840","rc":[{"trd":[[1.14,27.8]],"batl":[[0,1.14,1585.72]],"ltp":1.14,"tv":1628.37,"id":8173434}],"tv":2019.94}]}
{"op":"mcm","clk":"1004436037","pt":1580629795656,"mc":[{"id":"1.168186840","rc":[{"batb":[[0,1.08,595.39],[1,1.06,781.47],[2,1.01,10.51]],"batl":[[0,1.47,1199.34],[1,1.65,4.54],[2,1.47,0]],"ltp":1.14,"tv":1628.37,"id":8173434}]}]}
{"op":"mcm","clk":"1004436077","pt":1580629796531,"mc":[{"id":"1.168186840","rc":[{"batb":[[0,1.06,781.47],[1,1.01,10.51],[2,1.01,0]],"batl":[[1,1.65,2.27]],"ltp":1.14,"tv":1628.37,"id":8173434}]}]}
{"op":"mcm","clk":"1004436121","pt":1580629797509,"mc":[{"id":"1.168186840","rc":[{"batl":[[0,1.12,205.01],[1,1.47,1199.34],[2,1.65,2.27]],"ltp":1.14,"tv":1628.37,"id":8173434}]}]}
{"op":"mcm","clk":"1004436198","pt":1580629799364,"mc":[{"id":"1.168186840","rc":[{"batb":[[0,6,35.64]],"ltp":9.4,"tv":391.56,"id":8639275},{"batb":[[0,1.07,667.54]],"ltp":1.14,"tv":1628.37,"id":8173434}]}]}
{"op":"mcm","clk":"1004436316","pt":1580629801626,"mc":[{"id":"1.168186840","rc":[{"trd":[[1.12,672.17]],"batb":[[0,1.13,526.15],[1,1.12,1541.07],[2,1.07,667.54]],"batl":[[0,1.15,1343.55],[1,1.16,868.21],[2,1.47,1199.34]],"ltp":1.12,"tv":2038.39,"id":8173434}],"tv":2429.96}]}
{"op":"mcm","clk":"1004436360","pt":1580629802550,"mc":[{"id":"1.168186840","rc":[{"batl":[[1,1.16,795.59]],"ltp":1.12,"tv":2038.39,"id":8173434}]}]}
{"op":"mcm","clk":"1004436467","pt":1580629804654,"mc":[{"id":"1.168186840","rc":[{"batl":[[0,11.5,17.83]],"ltp":9.4,"tv":391.56,"id":8639275}]}]}
{"op":"mcm","clk":"1004436477","pt":1580629804859,"mc":[{"id":"1.168186840","rc":[{"batb":[[0,1.13,656.74],[1,1.12,1616.15]],"batl":[[0,1.15,1416.8]],"ltp":1.12,"tv":2038.39,"id":8173434}]}]}
{"op":"mcm","clk":"1004436549","pt":1580629806557,"mc":[{"id":"1.168186840","rc":[{"batb":[[0,1.07,667.54],[1,1.01,10.51],[2,1.07,0]],"batl":[[0,1.47,1199.34],[1,1.65,2.27],[2,1.47,0]],"ltp":1.12,"tv":2038.39,"id":8173434}]}]}
{"op":"mcm","clk":"1004436663","pt":1580629809431,"mc":[{"id":"1.168186840","rc":[{"batb":[[0,1.09,2057],[1,1.07,667.54],[2,1.01,10.51]],"batl":[[0,1.19,438.76],[1,1.2,1050.56],[2,1.47,1199.34]],"ltp":1.12,"tv":2038.39,"id":8173434}]}]}
{"op":"mcm","clk":"1004437175","pt":1580629820951,"mc":[{"id":"1.168186840","rc":[{"batb":[[0,1.07,667.54],[1,1.01,10.51],[2,1.01,0]],"ltp":1.12,"tv":2038.39,"id":8173434}]}]}
{"op":"mcm","clk":"1004437325","pt":1580629824554,"mc":[{"id":"1.168186840","rc":[{"batb":[[1,4.2,42.17],[2,1.01,10.52]],"ltp":9.4,"tv":391.56,"id":8639275},{"batb":[[0,1.17,932.73],[1,1.16,1568.07],[2,1.11,433.69]],"ltp":1.12,"tv":2038.39,"id":8173434}]}]}
{"op":"mcm","clk":"1004437466","pt":1580629827585,"mc":[{"id":"1.168186840","rc":[{"batl":[[0,8.6,15.01]],"ltp":9.4,"tv":391.56,"id":8639275}]}]}
{"op":"mcm","clk":"1004437925","pt":1580629837690,"mc":[{"id":"1.168186840","rc":[{"trd":[[1.17,4]],"batb":[[0,1.17,930.73]],"ltp":1.17,"tv":2042.39,"id":8173434}],"tv":2433.96}]}
{"op":"mcm","clk":"1004437982","pt":1580629839076,"mc":[{"id":"1.168186840","rc":[{"trd":[[6.2,12.6]],"ltp":6.2,"tv":404.16,"id":8639275},{"trd":[[1.19,65.66]],"batl":[[0,1.19,373.1]],"ltp":1.19,"tv":2108.05,"id":8173434}],"tv":2512.22}]}
{"op":"mcm","clk":"1004438060","pt":1580629840612,"mc":[{"id":"1.168186840","rc":[{"batl":[[1,10.5,174.47]],"ltp":6.2,"tv":404.16,"id":8639275}]}]}
{"op":"mcm","clk":"1004438285","pt":1580629845492,"mc":[{"id":"1.168186840","rc":[{"batb":[[0,4.2,42.17],[1,1.01,10.52],[2,1.01,0]],"batl":[[1,10.5,0]],"ltp":6.2,"tv":404.16,"id":8639275},{"batb":[[0,1.11,433.69],[1,1.01,10.51],[2,1.11,0]],"batl":[[0,1.47,1199.34],[1,1.65,2.27],[2,1.47,0]],"ltp":1.19,"tv":2108.05,"id":8173434}]}]}
{"op":"mcm","clk":"1004438455","pt":1580629848683,"mc":[{"id":"1.168186840","rc":[{"batb":[[0,4.2,41.86]],"ltp":6.2,"tv":404.16,"id":8639275},{"batb":[[0,1.13,857.69],[1,1.12,1840.02],[2,1.01,10.51]],"batl":[[0,1.29,703.88],[1,1.3,642.59],[2,1.47,1199.34]],"ltp":1.19,"tv":2108.05,"id":8173434}]}]}
{"op":"mcm","clk":"1004438746","pt":1580629853516,"mc":[{"id":"1.168186840","rc":[{"batl":[[0,1.17,126.03],[1,1.29,703.88],[2,1.3,642.59]],"ltp":1.19,"tv":2108.05,"id":8173434}]}]}
{"op":"mcm","clk":"1004438810","pt":1580629854695,"mc":[{"id":"1.168186840","rc":[{"batl":[[0,1.17,277.48]],"ltp":1.19,"tv":2108.05,"id":8173434}]}]}
{"op":"mcm","clk":"1004438970","pt":1580629857621,"mc":[{"id":"1.168186840","rc":[{"batl":[[0,1.17,126.03]],"ltp":1.19,"tv":2108.05,"id":8173434}]}]}
{"op":"mcm","clk":"1004439100","pt":1580629860602,"mc":[{"id":"1.168186840","rc":[{"batl":[[0,1.29,703.88],[1,1.3,642.59],[2,1.47,1199.34]],"ltp":1.19,"tv":2108.05,"id":8173434}]}]}
{"op":"mcm","clk":"1004439543","pt":1580629871227,"mc":[{"id":"1.168186840","rc":[{"batl":[[0,1.47,1199.34],[1,1.65,2.27],[2,1.47,0]],"ltp":1.19,"tv":2108.05,"id":8173434}]}]}
{"op":"mcm","clk":"1004439691","pt":1580629874630,"mc":[{"id":"1.168186840","rc":[{"batl":[[0,1.15,1243.29],[1,1.16,967.61],[2,1.26,1266.25]],"ltp":1.19,"tv":2108.05,"id":8173434}]}]}
{"op":"mcm","clk":"1004439707","pt":1580629874938,"mc":[{"id":"1.168186840","rc":[{"batb":[[0,7.6,21.09],[1,5.2,25.34],[2,1.01,10.52]],"ltp":6.2,"tv":404.16,"id":8639275},{"batb":[[2,1.08,606.72]],"batl":[[2,1.47,1199.34]],"ltp":1.19,"tv":2108.05,"id":8173434}]}]}
{"op":"mcm","clk":"1004439877","pt":1580629878436,"mc":[{"id":"1.168186840","rc":[{"batl":[[0,11.5,17.17]],"ltp":6.2,"tv":404.16,"id":8639275}]}]}
{"op":"mcm","clk":"1004440073","pt":1580629883115,"mc":[{"id":"1.168186840","rc":[{"trd":[[1.13,336.08]],"batb":[[0,1.13,689.65]],"ltp":1.13,"tv":2444.13,"id":8173434}],"tv":2848.3}]}
{"op":"mcm","clk":"1004440224","pt":1580629886514,"mc":[{"id":"1.168186840","rc":[{"batb":[[0,1.13,796.08]],"ltp":1.13,"tv":2444.13,"id":8173434}]}]}
{"op":"mcm","clk":"1004440435","pt":1580629891655,"mc":[{"id":"1.168186840","rc":[{"trd":[[7.6,8.4]],"batb":[[0,7.6,16.89]],"ltp":7.6,"tv":412.57,"id":8639275},{"batb":[[0,1.12,426.61],[1,1.08,606.72],[2,1.01,10.51]],"batl":[[0,1.47,1199.34],[1,1.65,2.27],[2,1.47,0]],"ltp":1.13,"tv":2444.13,"id":8173434}],"tv":2856.7}]}
{"op":"mcm","clk":"1004440480","pt":1580629892638,"mc":[{"id":"1.168186840","rc":[{"batb":[[0,5.2,25.34],[1,1.01,10.52],[2,1.01,0]],"ltp":7.6,"tv":412.57,"id":8639275},{"batb":[[0,1.08,606.72],[1,1.01,10.51],[2,1.01,0]],"ltp":1.13,"tv":2444.13,"id":8173434}]}]}
{"op":"mcm","clk":"1004440549","pt":1580629894442,"mc":[{"id":"1.168186840","rc":[{"batb":[[0,1.09,2341.48],[1,1.08,606.72],[2,1.01,10.51]],"batl":[[0,1.22,352.74],[1,1.23,896.42],[2,1.47,1199.34]],"ltp":1.13,"tv":2444.13,"id":8173434}]}]}
{"op":"mcm","clk":"1004440566","pt":1580629894954,"mc":[{"id":"1.168186840","rc":[{"batb":[[0,5.1,25.57]],"ltp":7.6,"tv":412.57,"id":8639275},{"batb":[[1,1.08,603.18]],"ltp":1.13,"tv":2444.13,"id":8173434}]}]}
{"op":"mcm","clk":"1004440808","pt":1580629900556,"mc":[{"id":"1.168186840","rc":[{"batl":[[0,1.13,4.2],[1,1.22,352.74],[2,1.23,896.42]],"ltp":1.13,"tv":2444.13,"id":8173434}]}]}
{"op":"mcm","clk":"1004441112","pt":1580629904565,"mc":[{"id":"1.168186840","rc":[{"batl":[[0,1.13,6.2]],"ltp":1.13,"tv":2444.13,"id":8173434}]}]}
{"op":"mcm","clk":"1004441203","pt":1580629906678,"mc":[{"id":"1.168186840","rc":[{"batl":[[0,1.13,2]],"ltp":1.13,"tv":2444.13,"id":8173434}]}]}
{"op":"mcm","clk":"1004441593","pt":1580629917695,"mc":[{"id":"1.168186840","rc":[{"batb":[[0,1.08,603.18],[1,1.01,10.51],[2,1.01,0]],"batl":[[1,1.47,1199.34],[2,1.65,2.27]],"ltp":1.13,"tv":2444.13,"id":8173434}]}]}
{"op":"mcm","clk":"1004441664","pt":1580629918468,"mc":[{"id":"1.168186840","rc":[{"trd":[[11.5,0.39]],"batl":[[0,11.5,16.78]],"ltp":11.5,"tv":412.96,"id":8639275},{"trd":[[1.09,4.2]],"ltp":1.09,"tv":2448.33,"id":8173434}],"tv":2861.3}]}
{"op":"mcm","clk":"1004441727","pt":1580629920568,"mc":[{"id":"1.168186840","rc":[{"trd":[[1.13,340.08]],"batb":[[0,1.13,794.51],[1,1.12,1475.14],[2,1.08,603.18]],"batl":[[0,1.15,1303.42],[1,1.16,907.99],[2,1.47,1199.34]],"ltp":1.13,"tv":2452.33,"id":8173434}],"tv":2865.3}]}
{"op":"mcm","clk":"1004442331","pt":1580629938315,"mc":[{"id":"1.168186840","rc":[{"batb":[[0,1.08,603.18],[1,1.01,10.51],[2,1.08,0]],"batl":[[0,1.47,1199.34],[1,1.65,2.27],[2,1.47,0]],"ltp":1.13,"tv":2452.33,"id":8173434}]}]}
{"op":"mcm","clk":"1004442416","pt":1580629940675,"mc":[{"id":"1.168186840","rc":[{"batb":[[0,1.09,2341.48],[1,1.08,603.18],[2,1.01,10.51]],"batl":[[0,1.22,353.02],[1,1.23,896.42],[2,1.47,1199.34]],"ltp":1.13,"tv":2452.33,"id":8173434}]}]}
{"op":"mcm","clk":"1004442487","pt":1580629942621,"mc":[{"id":"1.168186840","rc":[{"batb":[[0,1.08,603.18],[1,1.01,10.51],[2,1.01,0]],"batl":[[0,1.47,1199.34],[1,1.65,2.27],[2,1.47,0]],"ltp":1.13,"tv":2452.33,"id":8173434}]}]}
{"op":"mcm","clk":"1004442578","pt":1580629945506,"mc":[{"id":"1.168186840","rc":[{"batb":[[0,1.14,1310.7],[1,1.13,936.28],[2,1.08,603.18]],"batl":[[0,1.16,625.15],[1,1.17,1263.9],[2,1.47,1199.34]],"ltp":1.13,"tv":2452.33,"id":8173434}]}]}
{"op":"mcm","clk":"1004442830","pt":1580629951427,"mc":[{"id":"1.168186840","rc":[{"batb":[[0,1.08,603.18],[1,1.01,10.51],[2,1.08,0]],"batl":[[0,1.47,1199.34],[1,1.65,2.27],[2,1.47,0]],"ltp":1.13,"tv":2452.33,"id":8173434}]}]}
{"op":"mcm","clk":"1004442935","pt":1580629954508,"mc":[{"id":"1.168186840","rc":[{"batb":[[0,1.09,2341.48],[1,1.08,603.18],[2,1.01,10.51]],"batl":[[0,1.22,347.5],[1,1.23,896.42],[2,1.47,1199.34]],"ltp":1.13,"tv":2452.33,"id":8173434}]}]}
{"op":"mcm","clk":"1004443263","pt":1580629964546,"mc":[{"id":"1.168186840","rc":[{"batl":[[0,1.47,1199.34],[1,1.65,2.27],[2,1.47,0]],"ltp":1.13,"tv":2452.33,"id":8173434}]}]}
{"op":"mcm","clk":"1004443399","pt":1580629967543,"mc":[{"id":"1.168186840","rc":[{"batl":[[0,1.11,905.35],[1,1.12,1381.49],[2,1.65,2.27]],"ltp":1.13,"tv":2452.33,"id":8173434}]}]}
{"op":"mcm","clk":"1004443456","pt":1580629968624,"mc":[{"id":"1.168186840","rc":[{"batb":[[0,9.6,30.53],[1,6.8,26.67],[2,1.01,10.52]],"ltp":11.5,"tv":412.96,"id":8639275},{"batb":[[1,1.08,603.02],[2,1.06,811.92]],"ltp":1.13,"tv":2452.33,"id":8173434}]}]}
{"op":"mcm","clk":"1004443566","pt":1580629971356,"mc":[{"id":"1.168186840","rc":[{"batl":[[0,17,21.52]],"ltp":11.5,"tv":412.96,"id":8639275},{"batl":[[2,1.4,1352.42]],"ltp":1.13,"tv":2452.33,"id":8173434}]}]}
{"op":"mcm","clk":"1004443695","pt":1580629974443,"mc":[{"id":"1.168186840","rc":[{"batl":[[2,1.21,2146.93]],"ltp":1.13,"tv":2452.33,"id":8173434}]}]}
{"op":"mcm","clk":"1004443724","pt":1580629975262,"mc":[{"id":"1.168186840","rc":[{"trd":[[1.09,18.52]],"batb":[[0,1.09,2334.32]],"ltp":1.09,"tv":2466.65,"id":8173434}],"tv":2879.62}]}
{"op":"mcm","clk":"1004444079","pt":1580629984664,"mc":[{"id":"1.168186840","rc":[{"batb":[[0,6.8,26.67],[1,1.01,10.52],[2,1.01,0]],"ltp":11.5,"tv":412.96,"id":8639275},{"batb":[[0,1.06,809.4],[1,1.01,10.51],[2,1.06,0]],"batl":[[0,1.4,1352.42],[1,1.65,2.27],[2,1.21,0]],"ltp":1.09,"tv":2466.65,"id":8173434}]}]}
{"op":"mcm","clk":"1004444194","pt":1580629987546,"mc":[{"id":"1.168186840","rc":[{"batl":[[0,10,4.2],[1,17,21.52]],"ltp":11.5,"tv":412.96,"id":8639275}]}]}
{"op":"mcm","clk":"1004444214","pt":1580629988060,"mc":[{"id":"1.168186840","rc":[{"trd":[[10,4.2]],"batl":[[0,17,21.52],[1,17,0]],"ltp":10.0,"tv":417.16,"id":8639275},{"trd":[[1.11,37.85]],"batl":[[0,1.09,157.91],[1,1.4,1352.42],[2,1.65,2.27]],"ltp":1.11,"tv":2504.5,"id":8173434}],"tv":2921.67}]}
{"op":"mcm","clk":"1004444310","pt":1580629990684,"mc":[{"id":"1.168186840","rc":[{"trd":[[1.09,334.35]],"batb":[[0,1.1,2145.23],[1,1.06,809.4],[2,1.01,10.51]],"batl":[[0,1.12,916.16],[1,1.13,1350.54],[2,1.4,1352.42]],"ltp":1.09,"tv":2820.33,"id":8173434}],"tv":3237.49}]}
{"op":"mcm","clk":"1004444481","pt":1580629994446,"mc":[{"id":"1.168186840","rc":[{"batl":[[0,14,19.3]],"ltp":10.0,"tv":417.16,"id":8639275},{"batb":[[0,1.1,2245.87]],"ltp":1.09,"tv":2820.33,"id":8173434}]}]}
{"op":"mcm","clk":"1004444566","pt":1580629996657,"mc":[{"id":"1.168186840","rc":[{"batb":[[0,1.06,809.4],[1,1.01,10.51],[2,1.01,0]],"batl":[[0,1.4,1352.42],[1,1.65,2.27],[2,1.4,0]],"ltp":1.09,"tv":2820.33,"id":8173434}]}]}
{"op":"mcm","clk":"1004444659","pt":1580629998663,"mc":[{"id":"1.168186840","rc":[{"batb":[[0,1.07,2385.25],[1,1.06,809.4],[2,1.01,10.51]],"batl":[[0,1.16,741.34],[1,1.17,1261.27],[2,1.4,1352.42]],"ltp":1.09,"tv":2820.33,"id":8173434}]}]}
{"op":"mcm","clk":"1004444720","pt":1580630000053,"mc":[{"id":"1.168186840","rc":[{"batb":[[0,1.1,2],[1,1.07,2385.25],[2,1.06,809.4]],"ltp":1.09,"tv":2820.33,"id":8173434}]}]}
{"op":"mcm","clk":"1004444911","pt":1580630004474,"mc":[{"id":"1.168186840","rc":[{"batb":[[0,1.07,2385.25],[1,1.06,809.4],[2,1.01,10.51]],"ltp":1.09,"tv":2820.33,"id":8173434}]}]}
{"op":"mcm","clk":"1004445012","pt":1580630007505,"mc":[{"id":"1.168186840","rc":[{"batb":[[0,1.08,2],[1,1.07,2385.25],[2,1.06,809.4]],"ltp":1.09,"tv":2820.33,"id":8173434}]}]}
{"op":"mcm","clk":"1004445059","pt":1580630008688,"mc":[{"id":"1.168186840","rc":[{"batb":[[1,1.06,809.4],[2,1.01,10.51]],"ltp":1.09,"tv":2820.33,"id":8173434}]}]}
{"op":"mcm","clk":"1004445194","pt":1580630011579,"mc":[{"id":"1.168186840","rc":[{"batb":[[0,1.14,1185.84],[1,1.13,1062.26],[2,1.08,2]],"ltp":1.09,"tv":2820.33,"id":8173434}]}]}
{"op":"mcm","clk":"1004445231","pt":1580630012501,"mc":[{"id":"1.168186840","rc":[{"batb":[[1,4.2,41.07],[2,1.01,10.52]],"ltp":10.0,"tv":417.16,"id":8639275},{"batb":[[1,1.13,1430.57],[2,1.08,594.24]],"ltp":1.09,"tv":2820.33,"id":8173434}]}]}
{"op":"mcm","clk":"1004445331","pt":1580630015020,"mc":[{"id":"1.168186840","rc":[{"batl":[[0,11.5,16.77]],"ltp":10.0,"tv":417.16,"id":8639275}]}]}
{"op":"mcm","clk":"1004446017","pt":1580630031130,"mc":[{"id":"1.168186840","rc":[{"batb":[[0,4.2,41.07],[1,1.01,10.52],[2,1.01,0]],"ltp":10.0,"tv":417.16,"id":8639275},{"batb":[[0,1.08,594.24],[1,1.01,10.51],[2,1.08,0]],"batl":[[0,1.4,1352.42],[1,1.65,2.27],[2,1.4,0]],"ltp":1.09,"tv":2820.33,"id":8173434}]}]}
{"op":"mcm","clk":"1004446138","pt":1580630033805,"mc":[{"id":"1.168186840","rc":[{"batb":[[0,1.09,2148.61],[1,1.08,594.24],[2,1.01,10.51]],"batl":[[0,1.28,946.51],[1,1.29,667.41],[2,1.4,1352.42]],"ltp":1.09,"tv":2820.33,"id":8173434}]}]}
{"op":"mcm","clk":"1004446305","pt":1580630037996,"mc":[{"id":"1.168186840","rc":[{"batl":[[0,1.14,18.93],[1,1.28,946.51],[2,1.29,667.41]],"ltp":1.09,"tv":2820.33,"id":8173434}]}]}
{"op":"mcm","clk":"1004446578","pt":1580630044518,"mc":[{"id":"1.168186840","rc":[{"batl":[[1,1.4,1352.42],[2,1.65,2.27]],"ltp":1.09,"tv":2820.33,"id":8173434}]}]}
{"op":"mcm","clk":"1004446726","pt":1580630047613,"mc":[{"id":"1.168186840","rc":[{"batl":[[0,1.11,1488.85],[1,1.12,803.2],[2,1.14,18.93]],"ltp":1.09,"tv":2820.33,"id":8173434}]}]}
{"op":"mcm","clk":"1004446769","pt":1580630048545,"mc":[{"id":"1.168186840","rc":[{"batb":[[0,9.6,31.47],[1,6.4,30.37],[2,1.01,10.52]],"ltp":10.0,"tv":417.16,"id":8639275},{"batb":[[2,1.06,835.44]],"ltp":1.09,"tv":2820.33,"id":8173434}]}]}
{"op":"mcm","clk":"1004446901","pt":1580630051020,"mc":[{"id":"1.168186840","rc":[{"batl":[[0,17,21.52]],"ltp":10.0,"tv":417.16,"id":8639275}]}]}
{"op":"mcm","clk":"1004447529","pt":1580630066640,"mc":[{"id":"1.168186840","rc":[{"batb":[[0,1.08,594.24],[1,1.06,835.44],[2,1.01,10.51]],"batl":[[0,1.14,18.93],[1,1.4,1352.42],[2,1.65,2.27]],"ltp":1.09,"tv":2820.33,"id":8173434}]}]}
{"op":"mcm","clk":"1004447573","pt":1580630067670,"mc":[{"id":"1.168186840","rc":[{"batb":[[0,6.4,30.37],[1,1.01,10.52],[2,1.01,0]],"ltp":10.0,"tv":417.16,"id":8639275},{"batb":[[0,1.08,2]],"ltp":1.09,"tv":2820.33,"id":8173434}]}]}
{"op":"mcm","clk":"1004447665","pt":1580630069582,"mc":[{"id":"1.168186840","rc":[{"batb":[[1,1.07,621.55],[2,1.06,2615.77]],"batl":[[1,1.17,1298.7],[2,1.18,875.19]],"ltp":1.09,"tv":2820.33,"id":8173434}]}]}
{"op":"mcm","clk":"1004448466","pt":1580630090587,"mc":[{"id":"1.168186840","rc":[{"batl":[[1,1.4,1352.42],[2,1.65,2.27]],"ltp":1.09,"tv":2820.33,"id":8173434}]}]}
{"op":"mcm","clk":"1004448624","pt":1580630093683,"mc":[{"id":"1.168186840","rc":[{"trd":[[1.08,4]],"batb":[[0,1.07,621.55],[1,1.06,2464.48],[2,1.01,10.51]],"batl":[[0,1.08,1230.59],[1,1.09,975.11],[2,1.14,18.93]],"ltp":1.08,"tv":2824.33,"id":8173434}],"tv":3241.49}]}
{"op":"mcm","clk":"1004448656","pt":1580630094607,"mc":[{"id":"1.168186840","rc":[{"batb":[[0,12,17.47],[1,11,22.11],[2,1.01,10.52]],"ltp":10.0,"tv":417.16,"id":8639275},{"batb":[[2,1.04,1081.8]],"ltp":1.08,"tv":2824.33,"id":8173434}]}]}
{"op":"mcm","clk":"1004448794","pt":1580630097494,"mc":[{"id":"1.168186840","rc":[{"batl":[[0,24,24.68]],"ltp":10.0,"tv":417.16,"id":8639275},{"batb":[[0,1.07,771.84]],"batl":[[1,1.09,1122.58]],"ltp":1.08,"tv":2824.33,"id":8173434}]}]}
{"op":"mcm","clk":"1004449282","pt":1580630108132,"mc":[{"id":"1.168186840","rc":[{"trd":[[1.08,4.18]],"batl":[[0,1.08,1230.5]],"ltp":1.08,"tv":2824.51,"id":8173434}],"tv":3241.67}]}
{"op":"mcm","clk":"1004449616","pt":1580630115652,"mc":[{"id":"1.168186840","rc":[{"trd":[[1.07,176]],"batb":[[0,1.07,683.84]],"ltp":1.07,"tv":3000.51,"id":8173434}],"tv":3417.67}]}
{"op":"mcm","clk":"1004450242","pt":1580630128446,"mc":[{"id":"1.168186840","rc":[{"batb":[[0,1.07,835.98]],"ltp":1.07,"tv":3000.51,"id":8173434}]}]}
{"op":"mcm","clk":"1004450305","pt":1580630129736,"mc":[{"id":"1.168186840","rc":[{"batb":[[1,1.06,2398.08]],"batl":[[0,1.08,1165.52]],"ltp":1.07,"tv":3000.51,"id":8173434}]}]}
{"op":"mcm","clk":"1004452103","pt":1580630167617,"mc":[{"id":"1.168186840","rc":[{"trd":[[1.07,478.9]],"batb":[[0,1.07,684.53]],"ltp":1.07,"tv":3303.4,"id":8173434}],"tv":3720.57}]}
{"op":"mcm","clk":"1004452242","pt":1580630171114,"mc":[{"id":"1.168186840","rc":[{"batb":[[0,1.07,777.49]],"ltp":1.07,"tv":3303.4,"id":8173434}]}]}
{"op":"mcm","clk":"1004452444","pt":1580630175407,"mc":[{"id":"1.168186840","rc":[{"batb":[[0,11,22.11],[1,1.01,10.52],[2,1.01,0]],"ltp":10.0,"tv":417.16,"id":8639275},{"batb":[[0,1.04,1081.8],[1,1.01,10.51],[2,1.04,0]],"batl":[[0,1.09,386.75],[1,1.14,18.93],[2,1.4,1352.42]],"ltp":1.07,"tv":3303.4,"id":8173434}]}]}
{"op":"mcm","clk":"1004452703","pt":1580630178629,"mc":[{"id":"1.168186840","rc":[{"batb":[[0,1.05,2430.34],[1,1.04,1081.8],[2,1.01,10.51]],"batl":[[1,1.1,1936.64],[2,1.14,18.93]],"ltp":1.07,"tv":3303.4,"id":8173434}]}]}
{"op":"mcm","clk":"1004452871","pt":1580630182404,"mc":[{"id":"1.168186840","rc":[{"trd":[[1.05,24]],"batb":[[0,1.05,2418.34]],"ltp":1.05,"tv":3327.4,"id":8173434}],"tv":3744.57}]}
{"op":"mcm","clk":"1004452936","pt":1580630184046,"mc":[{"id":"1.168186840","rc":[{"batl":[[0,1.07,28.57],[1,1.09,386.75],[2,1.1,1936.64]],"ltp":1.05,"tv":3327.4,"id":8173434}]}]}
{"op":"mcm","clk":"1004453429","pt":1580630192446,"mc":[{"id":"1.168186840","rc":[{"batl":[[0,1.09,386.75],[1,1.1,1936.64],[2,1.14,18.93]],"ltp":1.05,"tv":3327.4,"id":8173434}]}]}
{"op":"mcm","clk":"1004453491","pt":1580630193237,"mc":[{"id":"1.168186840","rc":[{"batb":[[0,1.04,1081.8],[1,1.01,10.51],[2,1.01,0]],"ltp":1.05,"tv":3327.4,"id":8173434}]}]}
{"op":"mcm","clk":"1004453637","pt":1580630195521,"mc":[{"id":"1.168186840","rc":[{"trd":[[1.04,57.14]],"batb":[[0,1.04,1053.23]],"ltp":1.04,"tv":3384.54,"id":8173434}],"tv":3801.7}]}
{"op":"mcm","clk":"1004453706","pt":1580630196656,"mc":[{"id":"1.168186840","rc":[{"batb":[[1,10,26.99],[2,1.01,10.52]],"ltp":10.0,"tv":417.16,"id":8639275},{"batb":[[0,1.08,1292.41],[1,1.07,1808.62],[2,1.05,874.08]],"ltp":1.04,"tv":3384.54,"id":8173434}]}]}
{"op":"mcm","clk":"1004453737","pt":1580630197324,"mc":[{"id":"1.168186840","rc":[{"batb":[[0,1.08,1201.45]],"batl":[[1,1.1,1843.16]],"ltp":1.04,"tv":3384.54,"id":8173434}]}]}
{"op":"mcm","clk":"1004453836","pt":1580630199535,"mc":[{"id":"1.168186840","rc":[{"batl":[[0,21,23.11]],"ltp":10.0,"tv":417.16,"id":8639275}]}]}
{"op":"mcm","clk":"1004453871","pt":1580630200457,"mc":[{"id":"1.168186840","rc":[{"batb":[[1,1.07,1900.43]],"batl":[[0,1.09,481.08]],"ltp":1.04,"tv":3384.54,"id":8173434}]}]}
{"op":"mcm","clk":"1004454321","pt":1580630210544,"mc":[{"id":"1.168186840","rc":[{"batb":[[0,10,26.75],[1,1.01,10.52],[2,1.01,0]],"batl":[[0,12,21],[1,21,23.11]],"ltp":10.0,"tv":417.16,"id":8639275},{"batb":[[0,1.05,874.08],[1,1.01,10.51],[2,1.05,0]],"batl":[[0,1.14,18.93],[1,1.4,1352.42],[2,1.65,2.27]],"ltp":1.04,"tv":3384.54,"id":8173434}]}]}
{"op":"mcm","clk":"1004454437","pt":1580630212655,"mc":[{"id":"1.168186840","rc":[{"batb":[[0,1.06,2407.42],[1,1.05,874.08],[2,1.01,10.51]],"batl":[[0,1.11,2298.97],[1,1.14,18.93],[2,1.4,1352.42]],"ltp":1.04,"tv":3384.54,"id":8173434}]}]}
{"op":"mcm","clk":"1004454480","pt":1580630213641,"mc":[{"id":"1.168186840","rc":[{"trd":[[12,1.53]],"batl":[[0,12,19.48]],"ltp":12.0,"tv":418.69,"id":8639275},{"trd":[[1.09,351.15]],"ltp":1.09,"tv":3401.34,"id":8173434}],"tv":3820.04}]}
{"op":"mcm","clk":"1004455204","pt":1580630228683,"mc":[{"id":"1.168186840","rc":[{"batb":[[0,1.05,874.08],[1,1.01,10.51],[2,1.01,0]],"ltp":1.09,"tv":3401.34,"id":8173434}]}]}
{"op":"mcm","clk":"1004455320","pt":1580630231665,"mc":[{"id":"1.168186840","rc":[{"batl":[[1,21,0]],"ltp":12.0,"tv":418.69,"id":8639275},{"batb":[[0,1.09,1079.35],[1,1.08,1273.48],[2,1.05,874.08]],"ltp":1.09,"tv":3401.34,"id":8173434}]}]}
{"op":"mcm","clk":"1004455362","pt":1580630232591,"mc":[{"id":"1.168186840","rc":[{"batb":[[1,9.8,29.43],[2,1.01,10.52]],"ltp":12.0,"tv":418.69,"id":8639275},{"batb":[[2,1.07,736.31]],"ltp":1.09,"tv":3401.34,"id":8173434}]}]}
{"op":"mcm","clk":"1004455498","pt":1580630235271,"mc":[{"id":"1.168186840","rc":[{"batl":[[1,17,21.52]],"ltp":12.0,"tv":418.69,"id":8639275}]}]}
{"op":"mcm","clk":"1004455763","pt":1580630240587,"mc":[{"id":"1.168186840","rc":[{"batb":[[0,1.08,1060.58],[1,1.07,736.31],[2,1.01,10.51]],"batl":[[0,1.11,773.93]],"ltp":1.09,"tv":3401.34,"id":8173434}]}]}
{"op":"mcm","clk":"1004455785","pt":1580630241002,"mc":[{"id":"1.168186840","rc":[{"batb":[[0,9.8,29.43],[1,1.01,10.52],[2,1.01,0]],"ltp":12.0,"tv":418.69,"id":8639275}]}]}
{"op":"mcm","clk":"1004455954","pt":1580630243591,"mc":[{"id":"1.168186840","rc":[{"batb":[[1,1.07,2050.73]],"batl":[[1,1.12,1511.42],[2,1.14,18.93]],"ltp":1.09,"tv":3401.34,"id":8173434}]}]}
{"op":"mcm","clk":"1004455999","pt":1580630244511,"mc":[{"id":"1.168186840","rc":[{"batl":[[0,17,21.52],[1,17,0]],"ltp":12.0,"tv":418.69,"id":8639275}]}]}
{"op":"mcm","clk":"1004456189","pt":1580630247604,"mc":[{"id":"1.168186840","rc":[{"trd":[[10,23.68]],"ltp":10.0,"tv":438.17,"id":8639275},{"trd":[[1.11,213.31]],"batl":[[0,1.11,598.47]],"ltp":1.11,"tv":3576.8,"id":8173434}],"tv":4014.97}]}
{"op":"mcm","clk":"1004456260","pt":1580630248530,"mc":[{"id":"1.168186840","rc":[{"batb":[[1,1.07,1983.75]],"ltp":1.11,"tv":3576.8,"id":8173434}]}]}
{"op":"mcm","clk":"1004456410","pt":1580630251105,"mc":[{"id":"1.168186840","rc":[{"batb":[[0,1.08,1126.94]],"batl":[[0,1.11,709.6],[1,1.12,1575.18]],"ltp":1.11,"tv":3576.8,"id":8173434}]}]}
{"op":"mcm","clk":"1004456638","pt":1580630256046,"mc":[{"id":"1.168186840","rc":[{"batb":[[0,1.07,736.31],[1,1.01,10.51],[2,1.01,0]],"ltp":1.11,"tv":3576.8,"id":8173434}]}]}
{"op":"mcm","clk":"1004456868","pt":1580630259620,"mc":[{"id":"1.168186840","rc":[{"batb":[[1,9.6,31.55],[2,1.01,10.52]],"ltp":10.0,"tv":438.17,"id":8639275},{"batb":[[0,1.1,358.57],[1,1.09,1979.29],[2,1.07,736.31]],"ltp":1.11,"tv":3576.8,"id":8173434}]}]}
{"op":"mcm","clk":"1004456881","pt":1580630259825,"mc":[{"id":"1.168186840","rc":[{"batb":[[2,1.07,668.64]],"ltp":1.11,"tv":3576.8,"id":8173434}]}]}
{"op":"mcm","clk":"1004457031","pt":1580630262661,"mc":[{"id":"1.168186840","rc":[{"batl":[[0,14,19.3]],"ltp":10.0,"tv":438.17,"id":8639275}]}]}
{"op":"mcm","clk":"1004457080","pt":1580630263649,"mc":[{"id":"1.168186840","rc":[{"trd":[[10,33.28]],"ltp":10.0,"tv":447.77,"id":8639275},{"trd":[[1.11,299.8]],"batl":[[0,1.11,623.11]],"ltp":1.11,"tv":3663.29,"id":8173434}],"tv":4111.06}]}
{"op":"mcm","clk":"1004457521","pt":1580630274248,"mc":[{"id":"1.168186840","rc":[{"batb":[[0,9.6,31.55],[1,1.01,10.52],[2,1.01,0]],"ltp":10.0,"tv":447.77,"id":8639275},{"batb":[[0,1.09,1552.07],[1,1.07,668.64],[2,1.01,10.51]],"batl":[[0,1.12,1575.18],[1,1.14,18.93],[2,1.4,1352.42]],"ltp":1.11,"tv":3663.29,"id":8173434}]}]}
{"op":"mcm","clk":"1004457637","pt":1580630277067,"mc":[{"id":"1.168186840","rc":[{"batb":[[1,1.08,796.39],[2,1.07,668.64]],"batl":[[0,1.12,1771.81],[1,1.13,502.14],[2,1.14,18.93]],"ltp":1.11,"tv":3663.29,"id":8173434}]}]}
{"op":"mcm","clk":"1004457879","pt":1580630283698,"mc":[{"id":"1.168186840","rc":[{"batl":[[0,1.14,18.93],[1,1.4,1352.42],[2,1.65,2.27]],"ltp":1.11,"tv":3663.29,"id":8173434}]}]}
{"op":"mcm","clk":"1004457999","pt":1580630286570,"mc":[{"id":"1.168186840","rc":[{"batl":[[0,1.11,1969.77],[1,1.14,18.93],[2,1.4,1352.42]],"ltp":1.11,"tv":3663.29,"id":8173434}]}]}
{"op":"mcm","clk":"1004458028","pt":1580630287391,"mc":[{"id":"1.168186840","rc":[{"batb":[[0,10.5,25.57],[1,10,28.33],[2,1.01,10.52]],"ltp":10.0,"tv":447.77,"id":8639275}]}]}
{"op":"mcm","clk":"1004458119","pt":1580630289658,"mc":[{"id":"1.168186840","rc":[{"batl":[[0,17,21.52]],"ltp":10.0,"tv":447.77,"id":8639275}]}]}
{"op":"mcm","clk":"1004458363","pt":1580630295000,"mc":[{"id":"1.168186840","rc":[{"batl":[[0,1.11,1971.67]],"ltp":1.11,"tv":3663.29,"id":8173434}]}]}
{"op":"mcm","clk":"1004458682","pt":1580630300610,"mc":[{"id":"1.168186840","rc":[{"batb":[[0,1.08,796.39],[1,1.07,668.64],[2,1.06,742.6]],"batl":[[0,1.11,476.34]],"ltp":1.11,"tv":3663.29,"id":8173434}]}]}
{"op":"mcm","clk":"1004458704","pt":1580630301023,"mc":[{"id":"1.168186840","rc":[{"batb":[[0,10,28.33],[1,1.01,10.52],[2,1.01,0]],"ltp":10.0,"tv":447.77,"id":8639275},{"batb":[[1,1.06,742.29],[2,1.01,10.51]],"ltp":1.11,"tv":3663.29,"id":8173434}]}]}
{"op":"mcm","clk":"1004458836","pt":1580630303692,"mc":[{"id":"1.168186840","rc":[{"batb":[[0,1.08,1339.91]],"ltp":1.11,"tv":3663.29,"id":8173434}]}]}
{"op":"mcm","clk":"1004458955","pt":1580630306618,"mc":[{"id":"1.168186840","rc":[{"batb":[[0,1.09,1013.54],[1,1.08,1339.91],[2,1.06,742.29]],"batl":[[0,1.11,2300.87]],"ltp":1.11,"tv":3663.29,"id":8173434}]}]}
{"op":"mcm","clk":"1004459239","pt":1580630312928,"mc":[{"id":"1.168186840","rc":[{"batb":[[0,1.08,1339.91],[1,1.06,742.29],[2,1.01,10.51]],"batl":[[0,1.11,476.34]],"ltp":1.11,"tv":3663.29,"id":8173434}]}]}
{"op":"mcm","clk":"1004459394","pt":1580630315698,"mc":[{"id":"1.168186840","rc":[{"batb":[[0,1.08,1764.65],[1,1.07,603.77],[2,1.06,742.29]],"batl":[[1,1.12,1808.24],[2,1.14,18.93]],"ltp":1.11,"tv":3663.29,"id":8173434}]}]}
{"op":"mcm","clk":"1004459581","pt":1580630319612,"mc":[{"id":"1.168186840","rc":[{"batb":[[0,1.06,742.29],[1,1.01,10.51],[2,1.06,0]],"ltp":1.11,"tv":3663.29,"id":8173434}]}]}
{"op":"mcm","clk":"1004459725","pt":1580630322646,"mc":[{"id":"1.168186840","rc":[{"batb":[[0,1.1,612.15],[1,1.09,1723.06],[2,1.06,742.29]],"ltp":1.11,"tv":3663.29,"id":8173434}]}]}
{"op":"mcm","clk":"1004459778","pt":1580630323523,"mc":[{"id":"1.168186840","rc":[{"batb":[[1,6.4,30.21],[2,1.01,10.52]],"ltp":10.0,"tv":447.77,"id":8639275},{"batb":[[2,1.08,629.3]],"ltp":1.11,"tv":3663.29,"id":8173434}]}]}
{"op":"mcm","clk":"1004460914","pt":1580630351379,"mc":[{"id":"1.168186840","rc":[{"batb":[[0,6.4,30.21],[1,1.01,10.52],[2,1.01,0]],"ltp":10.0,"tv":447.77,"id":8639275},{"batb":[[0,1.05,889.18],[1,1.01,10.51],[2,1.08,0]],"batl":[[0,1.11,1.9],[1,1.14,18.93],[2,1.4,1352.42]],"ltp":1.11,"tv":3663.29,"id":8173434}]}]}
{"op":"mcm","clk":"1004461024","pt":1580630353958,"mc":[{"id":"1.168186840","rc":[{"batb":[[0,1.07,1638.85],[1,1.06,752.76],[2,1.05,889.18]],"batl":[[2,1.18,1322.8]],"ltp":1.11,"tv":3663.29,"id":8173434}]}]}
{"op":"mcm","clk":"1004461442","pt":1580630362670,"mc":[{"id":"1.168186840","rc":[{"batl":[[2,1.4,1352.42]],"ltp":1.11,"tv":3663.29,"id":8173434}]}]}
{"op":"mcm","clk":"1004461634","pt":1580630365685,"mc":[{"id":"1.168186840","rc":[{"batl":[[0,1.08,468.89],[1,1.09,1876.24],[2,1.11,1.9]],"ltp":1.11,"tv":3663.29,"id":8173434}]}]}
{"op":"mcm","clk":"1004461675","pt":1580630366564,"mc":[{"id":"1.168186840","rc":[{"batb":[[0,13,15.66],[1,8.6,15.66],[2,1.01,10.52]],"ltp":10.0,"tv":447.77,"id":8639275}]}]}
{"op":"mcm","clk":"1004461790","pt":1580630369296,"mc":[{"id":"1.168186840","rc":[{"batl":[[0,24,24.68]],"ltp":10.0,"tv":447.77,"id":8639275}]}]}
{"op":"mcm","clk":"1004462203","pt":1580630379414,"mc":[{"id":"1.168186840","rc":[{"batb":[[0,8.6,15.66],[1,1.01,10.52],[2,1.01,0]],"ltp":10.0,"tv":447.77,"id":8639275},{"batb":[[0,1.03,1275.28],[1,1.01,10.51],[2,1.05,0]],"batl":[[0,1.11,1.9],[1,1.14,18.93],[2,1.4,1352.42]],"ltp":1.11,"tv":3663.29,"id":8173434}]}]}
{"op":"mcm","clk":"1004462528","pt":1580630385444,"mc":[{"id":"1.168186840","rc":[{"batb":[[0,1.08,727.66],[1,1.07,1650.11],[2,1.03,1275.28]],"batl":[[0,1.09,902.39],[1,1.1,1425.36],[2,1.11,1.9]],"ltp":1.11,"tv":3663.29,"id":8173434}]}]}
{"op":"mcm","clk":"1004462669","pt":1580630388532,"mc":[{"id":"1.168186840","rc":[{"batl":[[0,21,23.32]],"ltp":10.0,"tv":447.77,"id":8639275}]}]}
{"op":"mcm","clk":"1004462796","pt":1580630391325,"mc":[{"id":"1.168186840","rc":[{"batb":[[0,1.03,1275.28],[1,1.01,10.51],[2,1.03,0]],"batl":[[0,1.11,1.9],[1,1.14,18.93],[2,1.4,1352.42]],"ltp":1.11,"tv":3663.29,"id":8173434}]}]}
{"op":"mcm","clk":"1004462847","pt":1580630392257,"mc":[{"id":"1.168186840","rc":[{"batl":[[0,1.07,70.3],[1,1.11,1.9],[2,1.14,18.93]],"ltp":1.11,"tv":3663.29,"id":8173434}]}]}
{"op":"mcm","clk":"1004462932","pt":1580630393649,"mc":[{"id":"1.168186840","rc":[{"batb":[[0,1.05,2430],[1,1.03,1275.28],[2,1.01,10.51]],"batl":[[2,1.13,1673.41]],"ltp":1.11,"tv":3663.29,"id":8173434}]}]}
{"op":"mcm","clk":"1004462949","pt":1580630393859,"mc":[{"id":"1.168186840","rc":[{"batb":[[0,1.03,1275.28],[1,1.01,10.51],[2,1.01,0]],"ltp":1.11,"tv":3663.29,"id":8173434}]}]}
{"op":"mcm","clk":"1004463096","pt":1580630396638,"mc":[{"id":"1.168186840","rc":[{"trd":[[1.07,619.53],[1.11,303.6]],"batb":[[0,1.11,923.99],[1,1.1,1314.26],[2,1.03,1275.28]],"batl":[[0,1.13,1673.41],[1,1.14,598.35],[2,1.4,1352.42]],"ltp":1.11,"tv":3807.72,"id":8173434}],"tv":4255.49}]}
{"op":"mcm","clk":"1004463131","pt":1580630397558,"mc":[{"id":"1.168186840","rc":[{"batb":[[1,5.3,24],[2,1.01,10.52]],"ltp":10.0,"tv":447.77,"id":8639275},{"batb":[[1,1.1,1824.98],[2,1.06,812.08]],"ltp":1.11,"tv":3807.72,"id":8173434}]}]}
{"op":"mcm","clk":"1004463227","pt":1580630400075,"mc":[{"id":"1.168186840","rc":[{"batl":[[0,14,19.18]],"ltp":10.0,"tv":447.77,"id":8639275}]}]}
{"op":"mcm","clk":"1004464427","pt":1580630415694,"mc":[{"id":"1.168186840","rc":[{"batb":[[0,1.1,510.72],[1,1.06,812.08],[2,1.01,10.51]],"batl":[[0,1.14,18.93],[1,1.4,1352.42],[2,1.65,2.27]],"ltp":1.11,"tv":3807.72,"id":8173434}]}]}
{"op":"mcm","clk":"1004464453","pt":1580630416057,"mc":[{"id":"1.168186840","rc":[{"batb":[[0,5.3,24],[1,1.01,10.52],[2,1.01,0]],"ltp":10.0,"tv":447.77,"id":8639275},{"batb":[[0,1.06,812.08],[1,1.01,10.51],[2,1.01,0]],"ltp":1.11,"tv":3807.72,"id":8173434}]}]}
{"op":"mcm","clk":"1004464579","pt":1580630418386,"mc":[{"id":"1.168186840","rc":[{"batb":[[0,1.07,2384.58],[1,1.06,812.08],[2,1.01,10.51]],"batl":[[1,1.21,725.16],[2,1.22,933.16]],"ltp":1.11,"tv":3807.72,"id":8173434}]}]}
{"op":"mcm","clk":"1004465111","pt":1580630429506,"mc":[{"id":"1.168186840","rc":[{"batl":[[1,1.4,1352.42],[2,1.65,2.27]],"ltp":1.11,"tv":3807.72,"id":8173434}]}]}
{"op":"mcm","clk":"1004465283","pt":1580630432613,"mc":[{"id":"1.168186840","rc":[{"batl":[[0,1.09,2298.65],[1,1.14,18.93],[2,1.4,1352.42]],"ltp":1.11,"tv":3807.72,"id":8173434}]}]}
{"op":"mcm","clk":"1004465326","pt":1580630433391,"mc":[{"id":"1.168186840","rc":[{"batb":[[0,12,18.33],[1,7.6,21.48],[2,1.01,10.52]],"ltp":10.0,"tv":447.77,"id":8639275},{"batb":[[2,1.03,1264.97]],"ltp":1.11,"tv":3807.72,"id":8173434}]}]}
{"op":"mcm","clk":"1004465434","pt":1580630435612,"mc":[{"id":"1.168186840","rc":[{"batl":[[0,24,24.61]],"ltp":10.0,"tv":447.77,"id":8639275}]}]}
{"op":"mcm","clk":"1004466038","pt":1580630448440,"mc":[{"id":"1.168186840","rc":[{"batb":[[0,7.6,21.48],[1,1.01,10.52],[2,1.01,0]],"ltp":10.0,"tv":447.77,"id":8639275},{"trd":[[1.07,759.53]],"batb":[[0,1.03,1264.97],[1,1.01,10.51],[2,1.03,0]],"batl":[[0,1.14,18.93],[1,1.4,1352.42],[2,1.65,2.27]],"ltp":1.07,"tv":3947.72,"id":8173434}],"tv":4395.49}]}
{"op":"mcm","clk":"1004466186","pt":1580630451410,"mc":[{"id":"1.168186840","rc":[{"batb":[[0,1.05,1470.55],[1,1.04,968.67],[2,1.03,1264.97]],"batl":[[0,1.07,33.61],[1,1.14,933.94],[2,1.15,1311.64]],"ltp":1.07,"tv":3947.72,"id":8173434}]}]}
{"op":"mcm","clk":"1004466304","pt":1580630453620,"mc":[{"id":"1.168186840","rc":[{"batl":[[0,1.14,933.94],[1,1.15,1311.64],[2,1.4,1352.42]],"ltp":1.07,"tv":3947.72,"id":8173434}]}]}
{"op":"mcm","clk":"1004466487","pt":1580630457622,"mc":[{"id":"1.168186840","rc":[{"batl":[[0,1.06,8.4],[1,1.14,933.94],[2,1.15,1311.64]],"ltp":1.07,"tv":3947.72,"id":8173434}]}]}
{"op":"mcm","clk":"1004466639","pt":1580630460657,"mc":[{"id":"1.168186840","rc":[{"batl":[[1,1.14,18.93],[2,1.4,1352.42]],"ltp":1.07,"tv":3947.72,"id":8173434}]}]}
{"op":"mcm","clk":"1004466764","pt":1580630463534,"mc":[{"id":"1.168186840","rc":[{"batl":[[0,1.06,1816.05],[1,1.07,593.82],[2,1.14,18.93]],"ltp":1.07,"tv":3947.72,"id":8173434}]}]}
{"op":"mcm","clk":"1004466830","pt":1580630464669,"mc":[{"id":"1.168186840","rc":[{"batb":[[0,16.5,8.58],[1,12,18.18],[2,1.01,10.52]],"ltp":10.0,"tv":447.77,"id":8639275},{"batl":[[0,1.06,1807.65]],"ltp":1.07,"tv":3947.72,"id":8173434}]}]}
{"op":"mcm","clk":"1004466951","pt":1580630467652,"mc":[{"id":"1.168186840","rc":[{"batl":[[0,42,28.62]],"ltp":10.0,"tv":447.77,"id":8639275}]}]}
{"op":"mcm","clk":"1004466999","pt":1580630468471,"mc":[{"id":"1.168186840","rc":[{"trd":[[1.05,40.8]],"batb":[[0,1.05,1462.15]],"ltp":1.05,"tv":3964.52,"id":8173434}],"tv":4412.29}]}
{"op":"mcm","clk":"1004467503","pt":1580630481569,"mc":[{"id":"1.168186840","rc":[{"trd":[[1.05,170.2]],"batb":[[0,1.05,1397.45]],"ltp":1.05,"tv":4093.92,"id":8173434}],"tv":4541.69}]}
{"op":"mcm","clk":"1004467562","pt":1580630482552,"mc":[{"id":"1.168186840","rc":[{"batb":[[0,1.04,968.67],[1,1.03,1264.97],[2,1.02,1628.09]],"batl":[[0,1.14,18.93],[1,1.34,1569.23],[2,1.65,2.27]],"ltp":1.05,"tv":4093.92,"id":8173434}]}]}
{"op":"mcm","clk":"1004467601","pt":1580630483573,"mc":[{"id":"1.168186840","rc":[{"batb":[[0,12,18.18],[1,1.01,10.52],[2,1.01,0]],"ltp":10.0,"tv":447.77,"id":8639275},{"batb":[[1,1.02,1628.09],[2,1.01,10.51]],"ltp":1.05,"tv":4093.92,"id":8173434}]}]}
{"op":"mcm","clk":"1004467669","pt":1580630485681,"mc":[{"id":"1.168186840","rc":[{"batb":[[0,1.04,1669.19],[1,1.03,791.78],[2,1.02,1628.09]],"batl":[[0,1.08,846.84],[1,1.09,1501.75],[2,1.14,18.93]],"ltp":1.05,"tv":4093.92,"id":8173434}]}]}
{"op":"mcm","clk":"1004467748","pt":1580630487384,"mc":[{"id":"1.168186840","rc":[{"batb":[[0,1.02,1628.09],[1,1.01,10.51],[2,1.02,0]],"batl":[[0,1.14,18.93],[1,1.34,1569.23],[2,1.65,2.27]],"ltp":1.05,"tv":4093.92,"id":8173434}]}]}
{"op":"mcm","clk":"1004467891","pt":1580630490572,"mc":[{"id":"1.168186840","rc":[{"batb":[[0,1.05,2430],[1,1.02,1628.09],[2,1.01,10.51]],"batl":[[0,1.07,2384.58],[1,1.14,18.93],[2,1.34,1569.23]],"ltp":1.05,"tv":4093.92,"id":8173434}]}]}
{"op":"mcm","clk":"1004468081","pt":1580630494580,"mc":[{"id":"1.168186840","rc":[{"batb":[[0,1.02,1628.09],[1,1.01,10.51],[2,1.01,0]],"batl":[[0,1.14,18.93],[1,1.34,1569.23],[2,1.65,2.27]],"ltp":1.05,"tv":4093.92,"id":8173434}]}]}
{"op":"mcm","clk":"1004468112","pt":1580630495306,"mc":[{"id":"1.168186840","rc":[{"batl":[[0,42,28.62]],"ltp":10.0,"tv":447.77,"id":8639275}]}]}
{"op":"mcm","clk":"1004468204","pt":1580630497565,"mc":[{"id":"1.168186840","rc":[{"batb":[[0,1.04,1669.19],[1,1.03,791.78],[2,1.02,1628.09]],"batl":[[0,1.08,846.84],[1,1.09,1501.75],[2,1.14,18.93]],"ltp":1.05,"tv":4093.92,"id":8173434}]}]}
{"op":"mcm","clk":"1004468435","pt":1580630503008,"mc":[{"id":"1.168186840","rc":[{"batb":[[0,1.04,1022.21],[1,1.02,1628.09],[2,1.01,10.51]],"batl":[[0,1.14,18.93],[1,1.34,1569.23],[2,1.65,2.27]],"ltp":1.05,"tv":4093.92,"id":8173434}]}]}
{"op":"mcm","clk":"1004468574","pt":1580630505891,"mc":[{"id":"1.168186840","rc":[{"batb":[[0,1.05,1417.52],[1,1.04,1022.21],[2,1.02,1628.09]],"batl":[[0,1.06,1834.21],[1,1.07,567.51],[2,1.14,18.93]],"ltp":1.05,"tv":4093.92,"id":8173434}]}]}
{"op":"mcm","clk":"1004469369","pt":1580630523601,"mc":[{"id":"1.168186840","rc":[{"batb":[[0,1.04,1022.21],[1,1.02,1628.09],[2,1.01,10.51]],"batl":[[0,1.14,18.93],[1,1.34,1569.23],[2,1.65,2.27]],"ltp":1.05,"tv":4093.92,"id":8173434}]}]}
{"op":"mcm","clk":"1004469525","pt":1580630526640,"mc":[{"id":"1.168186840","rc":[{"batb":[[0,1.04,1669.19],[1,1.03,791.78],[2,1.02,1628.09]],"batl":[[0,1.08,846.84],[1,1.09,1501.75],[2,1.14,18.93]],"ltp":1.05,"tv":4093.92,"id":8173434}]}]}
{"op":"mcm","clk":"1004469729","pt":1580630530626,"mc":[{"id":"1.168186840","rc":[{"batl":[[0,1.14,18.93],[1,1.34,1569.23],[2,1.65,2.27]],"ltp":1.05,"tv":4093.92,"id":8173434}]}]}
{"op":"mcm","clk":"1004469921","pt":1580630533659,"mc":[{"id":"1.168186840","rc":[{"batl":[[0,1.05,2429.91],[1,1.14,18.93],[2,1.34,1569.23]],"ltp":1.05,"tv":4093.92,"id":8173434}]}]}
{"op":"mcm","clk":"1004469945","pt":1580630533923,"mc":[{"id":"1.168186840","rc":[{"batb":[[0,20,11.41],[1,18,14.16],[2,1.01,10.52]],"ltp":10.0,"tv":447.77,"id":8639275}]}]}
{"op":"mcm","clk":"1004470068","pt":1580630536318,"mc":[{"id":"1.168186840","rc":[{"batl":[[0,65,30.58]],"ltp":10.0,"tv":447.77,"id":8639275}]}]}
{"op":"mcm","clk":"1004472878","pt":1580630597245,"mc":[{"id":"1.168186840","rc":[{"trd":[[1.04,57.17]],"batb":[[0,1.04,1669.17]],"ltp":1.04,"tv":4093.95,"id":8173434}],"tv":4541.72}]}
{"op":"mcm","clk":"1004473249","pt":1580630606961,"mc":[{"id":"1.168186840","rc":[{"batb":[[0,1.04,1669.19]],"ltp":1.04,"tv":4093.95,"id":8173434}]}]}
{"op":"mcm","clk":"1004473403","pt":1580630611280,"mc":[{"id":"1.168186840","rc":[{"batb":[[0,18,14.16],[1,1.01,10.52],[2,1.01,0]],"ltp":10.0,"tv":447.77,"id":8639275},{"batb":[[0,1.03,791.8],[1,1.02,1628.09],[2,1.01,10.51]],"batl":[[0,1.14,18.93],[1,1.34,1569.23],[2,1.65,2.27]],"ltp":1.04,"tv":4093.95,"id":8173434}]}]}
{"op":"mcm","clk":"1004473525","pt":1580630614266,"mc":[{"id":"1.168186840","rc":[{"batb":[[0,1.03,1830.33],[1,1.02,2281.21]],"batl":[[0,1.06,2406.99],[1,1.14,18.93],[2,1.34,1569.23]],"ltp":1.04,"tv":4093.95,"id":8173434}]}]}
{"op":"mcm","clk":"1004473833","pt":1580630620500,"mc":[{"id":"1.168186840","rc":[{"batl":[[0,1.14,18.93],[1,1.34,1569.23],[2,1.65,2.27]],"ltp":1.04,"tv":4093.95,"id":8173434}]}]}
{"op":"mcm","clk":"1004473987","pt":1580630623597,"mc":[{"id":"1.168186840","rc":[{"trd":[[1.04,57.21]],"batb":[[0,1.03,1830.31]],"batl":[[0,1.04,2453.26],[1,1.14,18.93],[2,1.34,1569.23]],"ltp":1.04,"tv":4093.99,"id":8173434}],"tv":4541.76}]}
{"op":"mcm","clk":"1004474011","pt":1580630624062,"mc":[{"id":"1.168186840","rc":[{"batb":[[0,24,5.85],[1,21,9.65],[2,1.01,10.52]],"ltp":10.0,"tv":447.77,"id":8639275},{"batb":[[1,1.02,653.12]],"ltp":1.04,"tv":4093.99,"id":8173434}]}]}
{"op":"mcm","clk":"1004474062","pt":1580630625400,"mc":[{"id":"1.168186840","rc":[{"batl":[[0,160,33.14]],"ltp":10.0,"tv":447.77,"id":8639275}]}]}
{"op":"mcm","clk":"1004474457","pt":1580630635495,"mc":[{"id":"1.168186840","rc":[{"batb":[[0,1.01,10.51],[1,1.02,0],[2,1.01,0]],"batl":[[0,1.14,18.93],[1,1.34,1569.23],[2,1.65,2.27]],"ltp":1.04,"tv":4093.99,"id":8173434}]}]}
{"op":"mcm","clk":"1004474501","pt":1580630636689,"mc":[{"id":"1.168186840","rc":[{"batb":[[0,21,9.65],[1,1.01,10.52],[2,1.01,0]],"ltp":10.0,"tv":447.77,"id":8639275}]}]}
{"op":"mcm","clk":"1004474571","pt":1580630638288,"mc":[{"id":"1.168186840","rc":[{"batb":[[0,1.01,2536.66]],"batl":[[0,1.05,2429.91],[1,1.14,18.93],[2,1.34,1569.23]],"ltp":1.04,"tv":4093.99,"id":8173434}]}]}
{"op":"mcm","clk":"1004474685","pt":1580630640700,"mc":[{"id":"1.168186840","rc":[{"batb":[[0,1.01,10.51]],"ltp":1.04,"tv":4093.99,"id":8173434}]}]}
{"op":"mcm","clk":"1004474840","pt":1580630643632,"mc":[{"id":"1.168186840","rc":[{"batb":[[0,1.04,611.94],[1,1.03,1859.21],[2,1.01,10.51]],"ltp":1.04,"tv":4093.99,"id":8173434}]}]}
{"op":"mcm","clk":"1004474891","pt":1580630644406,"mc":[{"id":"1.168186840","rc":[{"batb":[[1,18.5,13.3],[2,1.01,10.52]],"ltp":10.0,"tv":447.77,"id":8639275},{"batb":[[2,1.02,1738.32]],"ltp":1.04,"tv":4093.99,"id":8173434}]}]}
{"op":"mcm","clk":"1004474972","pt":1580630646629,"mc":[{"id":"1.168186840","rc":[{"batl":[[0,65,30.65]],"ltp":10.0,"tv":447.77,"id":8639275}]}]}
{"op":"mcm","clk":"1004475340","pt":1580630651438,"mc":[{"id":"1.168186840","rc":[{"batb":[[0,18.5,13.3],[1,1.01,10.52],[2,1.01,0]],"ltp":10.0,"tv":447.77,"id":8639275},{"batb":[[0,1.01,10.51],[1,1.03,0],[2,1.02,0]],"batl":[[0,1.14,18.93],[1,1.34,1569.23],[2,1.65,2.27]],"ltp":1.04,"tv":4093.99,"id":8173434}]}]}
{"op":"mcm","clk":"1004475588","pt":1580630657439,"mc":[{"id":"1.168186840","rc":[{"batb":[[0,1.03,2477.1],[1,1.01,10.51]],"batl":[[0,1.05,2429.91],[1,1.14,18.93],[2,1.34,1569.23]],"ltp":1.04,"tv":4093.99,"id":8173434}]}]}
{"op":"mcm","clk":"1004475709","pt":1580630659963,"mc":[{"id":"1.168186840","rc":[{"batl":[[0,95,31.93]],"ltp":10.0,"tv":447.77,"id":8639275}]}]}
{"op":"mcm","clk":"1004475763","pt":1580630660853,"mc":[{"id":"1.168186840","rc":[{"batb":[[0,1.01,10.51],[1,1.01,0]],"batl":[[0,1.14,18.93],[1,1.34,1569.23],[2,1.65,2.27]],"ltp":1.04,"tv":4093.99,"id":8173434}]}]}
{"op":"mcm","clk":"1004475915","pt":1580630663838,"mc":[{"id":"1.168186840","rc":[{"batb":[[0,1.02,2501.38],[1,1.01,10.51]],"batl":[[0,1.06,2406.99],[1,1.14,18.93],[2,1.34,1569.23]],"ltp":1.04,"tv":4093.99,"id":8173434}]}]}
{"op":"mcm","clk":"1004476336","pt":1580630671260,"mc":[{"id":"1.168186840","rc":[{"batl":[[0,1.14,18.93],[1,1.34,1569.23],[2,1.65,2.27]],"ltp":1.04,"tv":4093.99,"id":8173434}]}]}
{"op":"mcm","clk":"1004476464","pt":1580630674665,"mc":[{"id":"1.168186840","rc":[{"batb":[[0,26,8.1],[1,22,8.14],[2,18.5,13.3]],"ltp":10.0,"tv":447.77,"id":8639275},{"batl":[[0,1.04,2453.28],[1,1.14,18.93],[2,1.34,1569.23]],"ltp":1.04,"tv":4093.99,"id":8173434}]}]}
{"op":"mcm","clk":"1004476527","pt":1580630675653,"mc":[{"id":"1.168186840","rc":[{"batb":[[2,1.01,10.52]],"ltp":10.0,"tv":447.77,"id":8639275}]}]}
{"op":"mcm","clk":"1004476654","pt":1580630678079,"mc":[{"id":"1.168186840","rc":[{"batl":[[0,160,33.15]],"ltp":10.0,"tv":447.77,"id":8639275}]}]}
{"op":"mcm","clk":"1004477030","pt":1580630687583,"mc":[{"id":"1.168186840","rc":[{"batb":[[0,22,8.14],[1,1.01,10.52],[2,1.01,0]],"ltp":10.0,"tv":447.77,"id":8639275},{"batb":[[0,1.01,10.51],[1,1.01,0]],"batl":[[0,1.14,18.93],[1,1.34,1569.23],[2,1.65,2.27]],"ltp":1.04,"tv":4093.99,"id":8173434}]}]}
{"op":"mcm","clk":"1004477076","pt":1580630688974,"mc":[{"id":"1.168186840","rc":[{"batl":[[1,1.65,2.27],[2,1.65,0]],"ltp":1.04,"tv":4093.99,"id":8173434}]}]}
{"op":"mcm","clk":"1004477128","pt":1580630690413,"mc":[{"id":"1.168186840","rc":[{"batb":[[0,1.01,2536.66]],"batl":[[0,1.05,2429.91],[1,1.14,18.93],[2,1.65,2.27]],"ltp":1.04,"tv":4093.99,"id":8173434}]}]}
{"op":"mcm","clk":"1004477358","pt":1580630694598,"mc":[{"id":"1.168186840","rc":[{"batl":[[0,1.14,18.93],[1,1.65,2.27],[2,1.65,0]],"ltp":1.04,"tv":4093.99,"id":8173434}]}]}
{"op":"mcm","clk":"1004477497","pt":1580630697693,"mc":[{"id":"1.168186840","rc":[{"batl":[[0,1.02,2501.38],[1,1.14,18.93],[2,1.65,2.27]],"ltp":1.04,"tv":4093.99,"id":8173434}]}]}
{"op":"mcm","clk":"1004477533","pt":1580630698409,"mc":[{"id":"1.168186840","rc":[{"batb":[[0,30,3.7]],"ltp":10.0,"tv":447.77,"id":8639275}]}]}
{"op":"mcm","clk":"1004477571","pt":1580630699287,"mc":[{"id":"1.168186840","rc":[{"batl":[[2,1.28,1813.17]],"ltp":1.04,"tv":4093.99,"id":8173434}]}]}
{"op":"mcm","clk":"1004478324","pt":1580630716437,"mc":[{"id":"1.168186840","rc":[{"batb":[[0,1.01,10.51]],"batl":[[0,1.14,18.93],[1,1.28,1813.17],[2,1.65,2.27]],"ltp":1.04,"tv":4093.99,"id":8173434}]}]}
{"op":"mcm","clk":"1004478429","pt":1580630718654,"mc":[{"id":"1.168186840","rc":[{"trd":[[1.01,21.01]],"batl":[[0,1.01,82.76],[1,1.14,18.93]],"ltp":1.01,"tv":4115.0,"id":8173434}],"tv":4562.77}]}
{"op":"mcm","clk":"1004478449","pt":1580630719128,"mc":[{"id":"1.168186840","rc":[{"batl":[[1,1.03,2477.1],[2,1.14,18.93]],"ltp":1.01,"tv":4115.0,"id":8173434}]}]}
{"op":"mcm","clk":"1004478496","pt":1580630720458,"mc":[{"id":"1.168186840","rc":[{"batl":[[1,1.14,18.93],[2,1.65,2.27]],"ltp":1.01,"tv":4115.0,"id":8173434}]}]}
{"op":"mcm","clk":"1004478599","pt":1580630722932,"mc":[{"id":"1.168186840","rc":[{"trd":[[1.01,186.53]],"batb":[[0,1.01,1764.74]],"batl":[[0,1.02,2501.38]],"ltp":1.01,"tv":4280.52,"id":8173434}],"tv":4728.29}]}
{"op":"mcm","clk":"1004478697","pt":1580630725449,"mc":[{"id":"1.168186840","rc":[{"batl":[[2,1.28,1834.79]],"ltp":1.01,"tv":4280.52,"id":8173434}]}]}
{"op":"mcm","clk":"1004478725","pt":1580630726376,"mc":[{"id":"1.168186840","rc":[{"batl":[[0,1.14,18.93],[1,1.28,1834.79],[2,1.65,2.27]],"ltp":1.01,"tv":4280.52,"id":8173434}]}]}
{"op":"mcm","clk":"1004478754","pt":1580630727052,"mc":[{"id":"1.168186840","rc":[{"batl":[[1,1.65,2.27],[2,1.65,0]],"ltp":1.01,"tv":4280.52,"id":8173434}]}]}
{"op":"mcm","clk":"1004478834","pt":1580630728757,"mc":[{"id":"1.168186840","rc":[{"batl":[[0,1.03,2477.1],[1,1.14,18.93],[2,1.65,2.27]],"ltp":1.01,"tv":4280.52,"id":8173434}]}]}
{"op":"mcm","clk":"1004479975","pt":1580630756022,"mc":[{"id":"1.168186840","rc":[{"batl":[[0,1.14,18.93],[1,1.65,2.27],[2,1.65,0]],"ltp":1.01,"tv":4280.52,"id":8173434}]}]}
{"op":"mcm","clk":"1004480146","pt":1580630759618,"mc":[{"id":"1.168186840","rc":[{"batb":[[1,21,9.12],[2,1.01,10.52]],"ltp":10.0,"tv":447.77,"id":8639275},{"batb":[[0,1.02,2501.38]],"batl":[[0,1.03,2477.1],[1,1.14,18.93],[2,1.65,2.27]],"ltp":1.01,"tv":4280.52,"id":8173434}]}]}
{"op":"mcm","clk":"1004480229","pt":1580630761731,"mc":[{"id":"1.168186840","rc":[{"batl":[[2,1.29,1757.23]],"ltp":1.01,"tv":4280.52,"id":8173434}]}]}
{"op":"mcm","clk":"1004481134","pt":1580630781631,"mc":[{"id":"1.168186840","rc":[{"batl":[[0,1.14,18.93],[1,1.29,1757.23],[2,1.65,2.27]],"ltp":1.01,"tv":4280.52,"id":8173434}]}]}
{"op":"mcm","clk":"1004481138","pt":1580630781737,"mc":[{"id":"1.168186840","rc":[{"batb":[[0,21,9.12],[1,1.01,10.52],[2,1.01,0]],"ltp":10.0,"tv":447.77,"id":8639275}]}]}
{"op":"mcm","clk":"1004481209","pt":1580630783233,"mc":[{"id":"1.168186840","rc":[{"batl":[[1,1.65,2.27],[2,1.65,0]],"ltp":1.01,"tv":4280.52,"id":8173434}]}]}
{"op":"mcm","clk":"1004481258","pt":1580630784259,"mc":[{"id":"1.168186840","rc":[{"batl":[[0,1.05,2429.91],[1,1.14,18.93],[2,1.65,2.27]],"ltp":1.01,"tv":4280.52,"id":8173434}]}]}
{"op":"mcm","clk":"1004481352","pt":1580630786527,"mc":[{"id":"1.168186840","rc":[{"batl":[[0,1.14,18.93],[1,1.65,2.27],[2,1.65,0]],"ltp":1.01,"tv":4280.52,"id":8173434}]}]}
{"op":"mcm","clk":"1004481441","pt":1580630788953,"mc":[{"id":"1.168186840","rc":[{"batb":[[0,1.01,2526.15]],"batl":[[0,1.02,725.78],[1,1.03,1758.36],[2,1.14,18.93]],"ltp":1.01,"tv":4280.52,"id":8173434}]}]}
{"op":"mcm","clk":"1004481545","pt":1580630791949,"mc":[{"id":"1.168186840","rc":[{"batl":[[0,1.14,18.93],[1,1.29,1781.29],[2,1.65,2.27]],"ltp":1.01,"tv":4280.52,"id":8173434}]}]}
{"op":"mcm","clk":"1004481602","pt":1580630793245,"mc":[{"id":"1.168186840","rc":[{"batl":[[1,1.65,2.27],[2,1.65,0]],"ltp":1.01,"tv":4280.52,"id":8173434}]}]}
{"op":"mcm","clk":"1004481673","pt":1580630794956,"mc":[{"id":"1.168186840","rc":[{"batl":[[0,1.05,2429.91],[1,1.14,18.93],[2,1.65,2.27]],"ltp":1.01,"tv":4280.52,"id":8173434}]}]}
{"op":"mcm","clk":"1004481974","pt":1580630801688,"mc":[{"id":"1.168186840","rc":[{"batl":[[0,1.14,18.93],[1,1.65,2.27],[2,1.65,0]],"ltp":1.01,"tv":4280.52,"id":8173434}]}]}
{"op":"mcm","clk":"1004482027","pt":1580630802683,"mc":[{"id":"1.168186840","marketDefinition":{"bspMarket":false,"turnInPlayEnabled":true,"persistenceEnabled":true,"marketBaseRate":5.0,"eventId":"29680287","eventTypeId":"2","numberOfWinners":1,"bettingType":"ODDS","marketType":"SET_WINNER","marketTime":"2020-02-02T06:37:00.000Z","suspendTime":"2020-02-02T06:37:00.000Z","bspReconciled":false,"complete":true,"inPlay":true,"crossMatching":true,"runnersVoidable":false,"numberOfActiveRunners":2,"betDelay":3,"status":"SUSPENDED","runners":[{"status":"ACTIVE","sortPriority":1,"id":8173434,"name":"Taro Daniel"},{"status":"ACTIVE","sortPriority":2,"id":8639275,"name":"Yannick Hanfmann"}],"regulators":["MR_INT"],"countryCode":"AU","discountAllowed":true,"timezone":"UTC","openDate":"2020-02-02T06:37:00.000Z","version":3148317458,"name":"Set 2 Winner","eventName":"Daniel v Hanfmann"},"rc":[{"batb":[[0,1.01,10.52],[1,1.01,0]],"ltp":10.0,"tv":447.77,"id":8639275}]}]}
{"op":"mcm","clk":"1004483280","pt":1580630835248,"mc":[{"id":"1.168186840","tv":0.0}]}
{"op":"mcm","clk":"1004483349","pt":1580630836742,"mc":[{"id":"1.168186840","marketDefinition":{"bspMarket":false,"turnInPlayEnabled":true,"persistenceEnabled":true,"marketBaseRate":5.0,"eventId":"29680287","eventTypeId":"2","numberOfWinners":1,"bettingType":"ODDS","marketType":"SET_WINNER","marketTime":"2020-02-02T06:37:00.000Z","suspendTime":"2020-02-02T06:37:00.000Z","bspReconciled":false,"complete":true,"inPlay":true,"crossMatching":false,"runnersVoidable":false,"numberOfActiveRunners":0,"betDelay":3,"status":"CLOSED","settledTime":"2020-02-02T08:07:14.000Z","runners":[{"status":"WINNER","sortPriority":1,"id":8173434,"name":"Taro Daniel"},{"status":"LOSER","sortPriority":2,"id":8639275,"name":"Yannick Hanfmann"}],"regulators":["MR_INT"],"countryCode":"AU","discountAllowed":true,"timezone":"UTC","openDate":"2020-02-02T06:37:00.000Z","version":3148318460,"name":"Set 2 Winner","eventName":"Daniel v Hanfmann"}}]}
