{"op":"mcm","clk":"993170579","pt":1580537866635,"mc":[{"id":"1.168186839","marketDefinition":{"bspMarket":false,"turnInPlayEnabled":true,"persistenceEnabled":true,"marketBaseRate":5.0,"eventId":"29680287","eventTypeId":"2","numberOfWinners":1,"bettingType":"ODDS","marketType":"SET_WINNER","marketTime":"2020-02-02T02:00:00.000Z","suspendTime":"2020-02-02T02:00:00.000Z","bspReconciled":false,"complete":true,"inPlay":false,"crossMatching":false,"runnersVoidable":false,"numberOfActiveRunners":2,"betDelay":0,"status":"OPEN","runners":[{"status":"ACTIVE","sortPriority":1,"id":8173434,"name":"Taro Daniel"},{"status":"ACTIVE","sortPriority":2,"id":8639275,"name":"Yannick Hanfmann"}],"regulators":["MR_INT"],"countryCode":"AU","discountAllowed":false,"timezone":"UTC","openDate":"2020-02-02T02:00:00.000Z","version":3144541462,"name":"Set 1 Winner","eventName":"Daniel v Hanfmann"},"rc":[{"batb":[[0,1.01,20]],"ltp":0.0,"tv":0.0,"id":8639275},{"batb":[[0,1.01,20]],"ltp":0.0,"tv":0.0,"id":8173434}]}]}
{"op":"mcm","clk":"993170622","pt":1580537867691,"mc":[{"id":"1.168186839","marketDefinition":{"bspMarket":false,"turnInPlayEnabled":true,"persistenceEnabled":true,"marketBaseRate":5.0,"eventId":"29680287","eventTypeId":"2","numberOfWinners":1,"bettingType":"ODDS","marketType":"SET_WINNER","marketTime":"2020-02-02T02:00:00.000Z","suspendTime":"2020-02-02T02:00:00.000Z","bspReconciled":false,"complete":true,"inPlay":false,"crossMatching":false,"runnersVoidable":false,"numberOfActiveRunners":2,"betDelay":0,"status":"OPEN","runners":[{"status":"ACTIVE","sortPriority":1,"id":8173434,"name":"Taro Daniel"},{"status":"ACTIVE","sortPriority":2,"id":8639275,"name":"Yannick Hanfmann"}],"regulators":["MR_INT"],"countryCode":"AU","discountAllowed":true,"timezone":"UTC","openDate":"2020-02-02T02:00:00.000Z","version":3144541462,"name":"Set 1 Winner","eventName":"Daniel v Hanfmann"}}]}
{"op":"mcm","clk":"993211509","pt":1580538616662,"mc":[{"id":"1.168186839","rc":[{"batb":[[0,1.01,10]],"ltp":0.0,"tv":0.0,"id":8639275},{"batb":[[0,1.01,10]],"ltp":0.0,"tv":0.0,"id":8173434}]}]}
{"op":"mcm","clk":"995402666","pt":1580556777401,"mc":[{"id":"1.168186839","rc":[{"batb":[[0,1.71,24.57],[1,1.01,10]],"ltp":0.0,"tv":0.0,"id":8639275},{"batb":[[0,1.74,22.79],[1,1.01,10]],"ltp":0.0,"tv":0.0,"id":8173434}]}]}
{"op":"mcm","clk":"996088512","pt":1580560377509,"mc":[{"id":"1.168186839","rc":[{"batb":[[0,1.01,10],[1,1.01,0]],"ltp":0.0,"tv":0.0,"id":8639275},{"batb":[[0,1.01,10],[1,1.01,0]],"ltp":0.0,"tv":0.0,"id":8173434}]}]}
{"op":"mcm","clk":"996088577","pt":1580560377790,"mc":[{"id":"1.168186839","rc":[{"batb":[[0,1.89,20.96],[1,1.01,10]],"ltp":0.0,"tv":0.0,"id":8173434}]}]}
{"op":"mcm","clk":"996488029","pt":1580562414544,"mc":[{"id":"1.168186839","rc":[{"batb":[[0,1.55,29.19],[1,1.01,10]],"ltp":0.0,"tv":0.0,"id":8639275}]}]}
{"op":"mcm","clk":"996631181","pt":1580563040367,"mc":[{"id":"1.168186839","rc":[{"batb":[[0,1.01,10],[1,1.01,0]],"ltp":0.0,"tv":0.0,"id":8639275},{"batb":[[0,1.01,10],[1,1.01,0]],"ltp":0.0,"tv":0.0,"id":8173434}]}]}
{"op":"mcm","clk":"996631257","pt":1580563040756,"mc":[{"id":"1.168186839","rc":[{"batb":[[0,1.61,27.68],[1,1.01,10]],"ltp":0.0,"tv":0.0,"id":8639275},{"batb":[[0,1.86,21.68],[1,1.01,10]],"ltp":0.0,"tv":0.0,"id":8173434}]}]}
{"op":"mcm","clk":"996632182","pt":1580563045660,"mc":[{"id":"1.168186839","rc":[{"batb":[[0,1.01,10],[1,1.01,0]],"ltp":0.0,"tv":0.0,"id":8639275},{"batb":[[0,1.01,10],[1,1.01,0]],"ltp":0.0,"tv":0.0,"id":8173434}]}]}
{"op":"mcm","clk":"996632759","pt":1580563048794,"mc":[{"id":"1.168186839","rc":[{"batb":[[0,1.62,27.04],[1,1.01,10]],"ltp":0.0,"tv":0.0,"id":8639275},{"batb":[[0,1.76,22.73],[1,1.01,10]],"ltp":0.0,"tv":0.0,"id":8173434}]}]}
{"op":"mcm","clk":"996858697","pt":1580564102364,"mc":[{"id":"1.168186839","rc":[{"batb":[[0,1.62,47.04]],"ltp":0.0,"tv":0.0,"id":8639275},{"batb":[[0,1.76,39.23]],"ltp":0.0,"tv":0.0,"id":8173434}]}]}
{"op":"mcm","clk":"997392016","pt":1580566649478,"mc":[{"id":"1.168186839","rc":[{"batb":[[0,1.01,10],[1,1.01,0]],"ltp":0.0,"tv":0.0,"id":8639275},{"batb":[[0,1.01,10],[1,1.01,0]],"ltp":0.0,"tv":0.0,"id":8173434}]}]}
{"op":"mcm","clk":"997392087","pt":1580566649767,"mc":[{"id":"1.168186839","rc":[{"batb":[[0,1.72,44.34],[1,1.01,10]],"ltp":0.0,"tv":0.0,"id":8639275},{"batb":[[0,1.78,39.16],[1,1.01,10]],"ltp":0.0,"tv":0.0,"id":8173434}]}]}
{"op":"mcm","clk":"998282226","pt":1580570249796,"mc":[{"id":"1.168186839","rc":[{"batb":[[0,1.01,10],[1,1.01,0]],"ltp":0.0,"tv":0.0,"id":8639275},{"batb":[[0,1.01,10],[1,1.01,0]],"ltp":0.0,"tv":0.0,"id":8173434}]}]}
{"op":"mcm","clk":"998487356","pt":1580571029715,"mc":[{"id":"1.168186839","rc":[{"batb":[[0,1.61,67.86],[1,1.01,10]],"ltp":0.0,"tv":0.0,"id":8639275},{"batb":[[0,1.87,53.04],[1,1.01,10]],"ltp":0.0,"tv":0.0,"id":8173434}]}]}
{"op":"mcm","clk":"999390380","pt":1580574630033,"mc":[{"id":"1.168186839","rc":[{"batb":[[0,1.78,55.89]],"ltp":0.0,"tv":0.0,"id":8173434}]}]}
{"op":"mcm","clk":"1000025329","pt":1580578230695,"mc":[{"id":"1.168186839","rc":[{"batb":[[0,1.58,69.18]],"ltp":0.0,"tv":0.0,"id":8639275},{"batb":[[0,1.81,54.87]],"ltp":0.0,"tv":0.0,"id":8173434}]}]}
{"op":"mcm","clk":"1000557773","pt":1580581830505,"mc":[{"id":"1.168186839","rc":[{"batb":[[0,1.01,10],[1,1.01,0]],"ltp":0.0,"tv":0.0,"id":8639275}]}]}
{"op":"mcm","clk":"1000557795","pt":1580581830709,"mc":[{"id":"1.168186839","rc":[{"batb":[[0,1.01,10],[1,1.01,0]],"ltp":0.0,"tv":0.0,"id":8173434}]}]}
{"op":"mcm","clk":"1000591497","pt":1580582042674,"mc":[{"id":"1.168186839","rc":[{"batb":[[0,1.59,103.11],[1,1.01,10]],"ltp":0.0,"tv":0.0,"id":8639275},{"batb":[[0,1.87,79.81],[1,1.01,10]],"ltp":0.0,"tv":0.0,"id":8173434}]}]}
{"op":"mcm","clk":"1001121841","pt":1580584996376,"mc":[{"id":"1.168186839","rc":[{"batb":[[0,1.7,20.34],[1,1.59,103.11],[2,1.01,10]],"ltp":0.0,"tv":0.0,"id":8639275},{"batb":[[1,1.86,16.55],[2,1.01,10]],"ltp":0.0,"tv":0.0,"id":8173434}]}]}
{"op":"mcm","clk":"1001121954","pt":1580584996968,"mc":[{"id":"1.168186839","rc":[{"batb":[[0,1.72,94.09],[1,1.7,20.34]],"ltp":0.0,"tv":0.0,"id":8639275}]}]}
{"op":"mcm","clk":"1001125684","pt":1580585015536,"mc":[{"id":"1.168186839","rc":[{"batb":[[1,1.01,10],[2,1.01,0]],"ltp":0.0,"tv":0.0,"id":8639275},{"batb":[[1,1.01,10],[2,1.01,0]],"ltp":0.0,"tv":0.0,"id":8173434}]}]}
{"op":"mcm","clk":"1001125920","pt":1580585016681,"mc":[{"id":"1.168186839","rc":[{"batb":[[0,1.72,113.86]],"ltp":0.0,"tv":0.0,"id":8639275},{"batb":[[1,1.83,17.15],[2,1.01,10]],"ltp":0.0,"tv":0.0,"id":8173434}]}]}
{"op":"mcm","clk":"1001247847","pt":1580585643324,"mc":[{"id":"1.168186839","rc":[{"batb":[[0,1.73,92.13],[1,1.72,19.77],[2,1.01,10]],"ltp":0.0,"tv":0.0,"id":8639275},{"batb":[[0,1.83,17.15],[1,1.01,10],[2,1.01,0]],"ltp":0.0,"tv":0.0,"id":8173434}]}]}
{"op":"mcm","clk":"1001247931","pt":1580585643703,"mc":[{"id":"1.168186839","rc":[{"batb":[[0,1.84,80.72],[1,1.83,17.15],[2,1.01,10]],"ltp":0.0,"tv":0.0,"id":8173434}]}]}
{"op":"mcm","clk":"1001564836","pt":1580587442521,"mc":[{"id":"1.168186839","rc":[{"batb":[[1,1.01,10],[2,1.01,0]],"ltp":0.0,"tv":0.0,"id":8639275},{"batb":[[1,1.01,10],[2,1.01,0]],"ltp":0.0,"tv":0.0,"id":8173434}]}]}
{"op":"mcm","clk":"1001564938","pt":1580587443160,"mc":[{"id":"1.168186839","rc":[{"batb":[[0,1.73,111.63]],"ltp":0.0,"tv":0.0,"id":8639275},{"batb":[[0,1.85,16.75],[1,1.84,80.72],[2,1.01,10]],"ltp":0.0,"tv":0.0,"id":8173434}]}]}
{"op":"mcm","clk":"1001565020","pt":1580587443841,"mc":[{"id":"1.168186839","rc":[{"batb":[[0,1.88,77.71],[1,1.85,16.75]],"ltp":0.0,"tv":0.0,"id":8173434}]}]}
{"op":"mcm","clk":"1001905316","pt":1580589243313,"mc":[{"id":"1.168186839","rc":[{"batb":[[0,1.73,19.5]],"ltp":0.0,"tv":0.0,"id":8639275}]}]}
{"op":"mcm","clk":"1001905510","pt":1580589244318,"mc":[{"id":"1.168186839","rc":[{"batb":[[0,1.87,78.58]],"ltp":0.0,"tv":0.0,"id":8173434}]}]}
{"op":"mcm","clk":"1002243711","pt":1580591776148,"mc":[{"id":"1.168186839","rc":[{"batb":[[0,1.77,89.72],[1,1.73,19.5],[2,1.01,10]],"batl":[[0,2.96,4.54]],"ltp":0.0,"tv":0.0,"id":8639275},{"batl":[[0,2.94,4.54]],"ltp":0.0,"tv":0.0,"id":8173434}]}]}
{"op":"mcm","clk":"1002245382","pt":1580591793678,"mc":[{"id":"1.168186839","marketDefinition":{"bspMarket":false,"turnInPlayEnabled":true,"persistenceEnabled":true,"marketBaseRate":5.0,"eventId":"29680287","eventTypeId":"2","numberOfWinners":1,"bettingType":"ODDS","marketType":"SET_WINNER","marketTime":"2020-02-02T02:00:00.000Z","suspendTime":"2020-02-02T02:00:00.000Z","bspReconciled":false,"complete":true,"inPlay":false,"crossMatching":true,"runnersVoidable":false,"numberOfActiveRunners":2,"betDelay":0,"status":"OPEN","runners":[{"status":"ACTIVE","sortPriority":1,"id":8173434,"name":"Taro Daniel"},{"status":"ACTIVE","sortPriority":2,"id":8639275,"name":"Yannick Hanfmann"}],"regulators":["MR_INT"],"countryCode":"AU","discountAllowed":true,"timezone":"UTC","openDate":"2020-02-02T02:00:00.000Z","version":3144541462,"name":"Set 1 Winner","eventName":"Daniel v Hanfmann"}}]}
{"op":"mcm","clk":"1002357974","pt":1580592844496,"mc":[{"id":"1.168186839","rc":[{"batb":[[0,1.85,16.75],[1,1.01,10],[2,1.01,0]],"ltp":0.0,"tv":0.0,"id":8173434}]}]}
{"op":"mcm","clk":"1002357995","pt":1580592844706,"mc":[{"id":"1.168186839","rc":[{"batb":[[0,1.88,78.21],[1,1.85,16.75],[2,1.01,10]],"ltp":0.0,"tv":0.0,"id":8173434}]}]}
{"op":"mcm","clk":"1002360678","pt":1580592870812,"mc":[{"id":"1.168186839","rc":[{"batb":[[0,1.77,119.11]],"ltp":0.0,"tv":0.0,"id":8639275},{"batb":[[0,1.88,103.71]],"ltp":0.0,"tv":0.0,"id":8173434}]}]}
{"op":"mcm","clk":"1002441975","pt":1580593734517,"mc":[{"id":"1.168186839","rc":[{"batb":[[1,1.74,25.58]],"ltp":0.0,"tv":0.0,"id":8639275},{"batb":[[1,1.84,22.54]],"ltp":0.0,"tv":0.0,"id":8173434}]}]}
{"op":"mcm","clk":"1002563147","pt":1580595377308,"mc":[{"id":"1.168186839","rc":[{"batb":[[0,1.79,117.74]],"ltp":0.0,"tv":0.0,"id":8639275}]}]}
{"op":"mcm","clk":"1002623032","pt":1580596221128,"mc":[{"id":"1.168186839","rc":[{"batb":[[1,1.01,10],[2,1.01,0]],"ltp":0.0,"tv":0.0,"id":8639275},{"batb":[[1,1.01,10],[2,1.01,0]],"ltp":0.0,"tv":0.0,"id":8173434}]}]}
{"op":"mcm","clk":"1002623082","pt":1580596221706,"mc":[{"id":"1.168186839","rc":[{"batb":[[1,1.73,25.94],[2,1.01,10]],"ltp":0.0,"tv":0.0,"id":8639275},{"batb":[[1,1.85,22.27],[2,1.01,10]],"ltp":0.0,"tv":0.0,"id":8173434}]}]}
{"op":"mcm","clk":"1002638545","pt":1580596445490,"mc":[{"id":"1.168186839","rc":[{"batb":[[0,1.88,104.21]],"ltp":0.0,"tv":0.0,"id":8173434}]}]}
{"op":"mcm","clk":"1002759561","pt":1580598383677,"mc":[{"id":"1.168186839","rc":[{"batb":[[1,1.01,10],[2,1.01,0]],"ltp":0.0,"tv":0.0,"id":8639275},{"batb":[[1,1.01,10],[2,1.01,0]],"ltp":0.0,"tv":0.0,"id":8173434}]}]}
{"op":"mcm","clk":"1002759615","pt":1580598384253,"mc":[{"id":"1.168186839","rc":[{"batb":[[1,1.74,25.58],[2,1.01,10]],"ltp":0.0,"tv":0.0,"id":8639275},{"batb":[[1,1.82,23.09],[2,1.01,10]],"ltp":0.0,"tv":0.0,"id":8173434}]}]}
{"op":"mcm","clk":"1002803782","pt":1580598977525,"mc":[{"id":"1.168186839","rc":[{"batb":[[0,1.79,117.12]],"ltp":0.0,"tv":0.0,"id":8639275}]}]}
{"op":"mcm","clk":"1002883092","pt":1580600045563,"mc":[{"id":"1.168186839","rc":[{"batb":[[0,1.82,23.09],[1,1.01,10],[2,1.01,0]],"ltp":0.0,"tv":0.0,"id":8173434}]}]}
{"op":"mcm","clk":"1002913591","pt":1580600511640,"mc":[{"id":"1.168186839","marketDefinition":{"bspMarket":false,"turnInPlayEnabled":true,"persistenceEnabled":true,"marketBaseRate":5.0,"eventId":"29680287","eventTypeId":"2","numberOfWinners":1,"bettingType":"ODDS","marketType":"SET_WINNER","marketTime":"2020-02-02T02:30:00.000Z","suspendTime":"2020-02-02T02:30:00.000Z","bspReconciled":false,"complete":true,"inPlay":false,"crossMatching":true,"runnersVoidable":false,"numberOfActiveRunners":2,"betDelay":0,"status":"OPEN","runners":[{"status":"ACTIVE","sortPriority":1,"id":8173434,"name":"Taro Daniel"},{"status":"ACTIVE","sortPriority":2,"id":8639275,"name":"Yannick Hanfmann"}],"regulators":["MR_INT"],"countryCode":"AU","discountAllowed":true,"timezone":"UTC","openDate":"2020-02-02T02:00:00.000Z","version":3147850877,"name":"Set 1 Winner","eventName":"Daniel v Hanfmann"}}]}
{"op":"mcm","clk":"1002913961","pt":1580600516653,"mc":[{"id":"1.168186839","marketDefinition":{"bspMarket":false,"turnInPlayEnabled":true,"persistenceEnabled":true,"marketBaseRate":5.0,"eventId":"29680287","eventTypeId":"2","numberOfWinners":1,"bettingType":"ODDS","marketType":"SET_WINNER","marketTime":"2020-02-02T02:30:00.000Z","suspendTime":"2020-02-02T02:30:00.000Z","bspReconciled":false,"complete":true,"inPlay":false,"crossMatching":true,"runnersVoidable":false,"numberOfActiveRunners":2,"betDelay":0,"status":"OPEN","runners":[{"status":"ACTIVE","sortPriority":1,"id":8173434,"name":"Taro Daniel"},{"status":"ACTIVE","sortPriority":2,"id":8639275,"name":"Yannick Hanfmann"}],"regulators":["MR_INT"],"countryCode":"AU","discountAllowed":true,"timezone":"UTC","openDate":"2020-02-02T02:30:00.000Z","version":3147850877,"name":"Set 1 Winner","eventName":"Daniel v Hanfmann"}}]}
{"op":"mcm","clk":"1002914458","pt":1580600524200,"mc":[{"id":"1.168186839","rc":[{"batb":[[0,1.84,107.97],[1,1.82,23.09],[2,1.01,10]],"ltp":0.0,"tv":0.0,"id":8173434}]}]}
{"op":"mcm","clk":"1003064084","pt":1580602527569,"mc":[{"id":"1.168186839","rc":[{"batb":[[2,1.01,12.53]],"ltp":0.0,"tv":0.0,"id":8639275},{"batb":[[2,1.01,12.53]],"ltp":0.0,"tv":0.0,"id":8173434}]}]}
{"op":"mcm","clk":"1003064133","pt":1580602528193,"mc":[{"id":"1.168186839","rc":[{"batb":[[2,1.01,10.51]],"ltp":0.0,"tv":0.0,"id":8639275},{"batb":[[2,1.01,10.51]],"ltp":0.0,"tv":0.0,"id":8173434}]}]}
{"op":"mcm","clk":"1003068535","pt":1580602577575,"mc":[{"id":"1.168186839","rc":[{"batb":[[0,1.74,25.58],[1,1.01,10.51],[2,1.01,0]],"ltp":0.0,"tv":0.0,"id":8639275}]}]}
{"op":"mcm","clk":"1003071724","pt":1580602612426,"mc":[{"id":"1.168186839","marketDefinition":{"bspMarket":false,"turnInPlayEnabled":true,"persistenceEnabled":true,"marketBaseRate":5.0,"eventId":"29680287","eventTypeId":"2","numberOfWinners":1,"bettingType":"ODDS","marketType":"SET_WINNER","marketTime":"2020-02-02T03:00:00.000Z","suspendTime":"2020-02-02T03:00:00.000Z","bspReconciled":false,"complete":true,"inPlay":false,"crossMatching":true,"runnersVoidable":false,"numberOfActiveRunners":2,"betDelay":0,"status":"OPEN","runners":[{"status":"ACTIVE","sortPriority":1,"id":8173434,"name":"Taro Daniel"},{"status":"ACTIVE","sortPriority":2,"id":8639275,"name":"Yannick Hanfmann"}],"regulators":["MR_INT"],"countryCode":"AU","discountAllowed":true,"timezone":"UTC","openDate":"2020-02-02T02:30:00.000Z","version":3147905869,"name":"Set 1 Winner","eventName":"Daniel v Hanfmann"},"rc":[{"batb":[[0,1.78,117.89],[1,1.74,25.58],[2,1.01,10.51]],"ltp":0.0,"tv":0.0,"id":8639275}]}]}
{"op":"mcm","clk":"1003071944","pt":1580602615018,"mc":[{"id":"1.168186839","marketDefinition":{"bspMarket":false,"turnInPlayEnabled":true,"persistenceEnabled":true,"marketBaseRate":5.0,"eventId":"29680287","eventTypeId":"2","numberOfWinners":1,"bettingType":"ODDS","marketType":"SET_WINNER","marketTime":"2020-02-02T03:00:00.000Z","suspendTime":"2020-02-02T03:00:00.000Z","bspReconciled":false,"complete":true,"inPlay":false,"crossMatching":true,"runnersVoidable":false,"numberOfActiveRunners":2,"betDelay":0,"status":"OPEN","runners":[{"status":"ACTIVE","sortPriority":1,"id":8173434,"name":"Taro Daniel"},{"status":"ACTIVE","sortPriority":2,"id":8639275,"name":"Yannick Hanfmann"}],"regulators":["MR_INT"],"countryCode":"AU","discountAllowed":true,"timezone":"UTC","openDate":"2020-02-02T03:00:00.000Z","version":3147905869,"name":"Set 1 Winner","eventName":"Daniel v Hanfmann"}}]}
{"op":"mcm","clk":"1003139403","pt":1580603482240,"mc":[{"id":"1.168186839","rc":[{"batb":[[1,1.01,10.51],[2,1.01,0]],"ltp":0.0,"tv":0.0,"id":8639275},{"batb":[[1,1.01,10.51],[2,1.01,0]],"ltp":0.0,"tv":0.0,"id":8173434}]}]}
{"op":"mcm","clk":"1003139451","pt":1580603482811,"mc":[{"id":"1.168186839","rc":[{"batb":[[1,1.76,24.91],[2,1.01,10.51]],"ltp":0.0,"tv":0.0,"id":8639275},{"batb":[[1,1.81,23.37],[2,1.01,10.51]],"ltp":0.0,"tv":0.0,"id":8173434}]}]}
{"op":"mcm","clk":"1003183801","pt":1580604057533,"mc":[{"id":"1.168186839","rc":[{"batb":[[2,1.01,11.01]],"ltp":0.0,"tv":0.0,"id":8639275},{"batb":[[2,1.01,11.01]],"ltp":0.0,"tv":0.0,"id":8173434}]}]}
{"op":"mcm","clk":"1003187782","pt":1580604124607,"mc":[{"id":"1.168186839","rc":[{"batb":[[0,1.84,108.72]],"ltp":0.0,"tv":0.0,"id":8173434}]}]}
{"op":"mcm","clk":"1003218385","pt":1580604631616,"mc":[{"id":"1.168186839","rc":[{"batb":[[1,1.74,25.58]],"ltp":0.0,"tv":0.0,"id":8639275},{"batb":[[1,1.83,22.81]],"ltp":0.0,"tv":0.0,"id":8173434}]}]}
{"op":"mcm","clk":"1003241528","pt":1580605013215,"mc":[{"id":"1.168186839","marketDefinition":{"bspMarket":false,"turnInPlayEnabled":true,"persistenceEnabled":true,"marketBaseRate":5.0,"eventId":"29680287","eventTypeId":"2","numberOfWinners":1,"bettingType":"ODDS","marketType":"SET_WINNER","marketTime":"2020-02-02T02:54:00.000Z","suspendTime":"2020-02-02T02:54:00.000Z","bspReconciled":false,"complete":true,"inPlay":false,"crossMatching":true,"runnersVoidable":false,"numberOfActiveRunners":2,"betDelay":0,"status":"OPEN","runners":[{"status":"ACTIVE","sortPriority":1,"id":8173434,"name":"Taro Daniel"},{"status":"ACTIVE","sortPriority":2,"id":8639275,"name":"Yannick Hanfmann"}],"regulators":["MR_INT"],"countryCode":"AU","discountAllowed":true,"timezone":"UTC","openDate":"2020-02-02T03:00:00.000Z","version":3147960792,"name":"Set 1 Winner","eventName":"Daniel v Hanfmann"}}]}
{"op":"mcm","clk":"1003241745","pt":1580605016220,"mc":[{"id":"1.168186839","marketDefinition":{"bspMarket":false,"turnInPlayEnabled":true,"persistenceEnabled":true,"marketBaseRate":5.0,"eventId":"29680287","eventTypeId":"2","numberOfWinners":1,"bettingType":"ODDS","marketType":"SET_WINNER","marketTime":"2020-02-02T02:54:00.000Z","suspendTime":"2020-02-02T02:54:00.000Z","bspReconciled":false,"complete":true,"inPlay":false,"crossMatching":true,"runnersVoidable":false,"numberOfActiveRunners":2,"betDelay":0,"status":"OPEN","runners":[{"status":"ACTIVE","sortPriority":1,"id":8173434,"name":"Taro Daniel"},{"status":"ACTIVE","sortPriority":2,"id":8639275,"name":"Yannick Hanfmann"}],"regulators":["MR_INT"],"countryCode":"AU","discountAllowed":true,"timezone":"UTC","openDate":"2020-02-02T02:54:00.000Z","version":3147960792,"name":"Set 1 Winner","eventName":"Daniel v Hanfmann"}}]}
{"op":"mcm","clk":"1003254284","pt":1580605235609,"mc":[{"id":"1.168186839","rc":[{"batb":[[0,1.79,2]],"ltp":0.0,"tv":0.0,"id":8639275},{"batb":[[0,1.85,2]],"ltp":0.0,"tv":0.0,"id":8173434}]}]}
{"op":"mcm","clk":"1003254371","pt":1580605236642,"mc":[{"id":"1.168186839","rc":[{"batb":[[0,1.82,115.14],[1,1.79,2],[2,1.74,25.58]],"ltp":0.0,"tv":0.0,"id":8639275},{"batb":[[0,1.9,104.06],[1,1.85,2],[2,1.83,22.81]],"ltp":0.0,"tv":0.0,"id":8173434}]}]}
{"op":"mcm","clk":"1003254866","pt":1580605245455,"mc":[{"id":"1.168186839","rc":[{"batb":[[0,1.84,113.97],[1,1.83,2.02]],"ltp":0.0,"tv":0.0,"id":8639275},{"batb":[[0,1.92,102.94],[1,1.91,2.02]],"ltp":0.0,"tv":0.0,"id":8173434}]}]}
{"op":"mcm","clk":"1003431170","pt":1580607650189,"mc":[{"id":"1.168186839","rc":[{"batb":[[0,1.85,4.02]],"ltp":0.0,"tv":0.0,"id":8639275},{"batb":[[0,1.94,101.92],[1,1.93,4.02],[2,1.91,2.02]],"ltp":0.0,"tv":0.0,"id":8173434}]}]}
{"op":"mcm","clk":"1003436874","pt":1580607724533,"mc":[{"id":"1.168186839","rc":[{"batb":[[0,1.93,4.02],[1,1.91,2.02],[2,1.83,22.81]],"ltp":0.0,"tv":0.0,"id":8173434}]}]}
{"op":"mcm","clk":"1003436887","pt":1580607724739,"mc":[{"id":"1.168186839","rc":[{"batb":[[0,1.94,101.92],[1,1.93,4.02],[2,1.91,2.02]],"ltp":0.0,"tv":0.0,"id":8173434}]}]}
{"op":"mcm","clk":"1003475643","pt":1580608249428,"mc":[{"id":"1.168186839","rc":[{"batb":[[0,1.85,2.02]],"ltp":0.0,"tv":0.0,"id":8639275},{"batb":[[1,1.93,2.02]],"ltp":0.0,"tv":0.0,"id":8173434}]}]}
{"op":"mcm","clk":"1003485445","pt":1580608399938,"mc":[{"id":"1.168186839","rc":[{"trd":[[1.94,3.54]],"batb":[[0,1.94,100.15]],"ltp":1.94,"tv":3.53,"id":8173434}],"tv":3.53}]}
{"op":"mcm","clk":"1003488611","pt":1580608443670,"mc":[{"id":"1.168186839","rc":[{"batb":[[2,1.01,11.02]],"ltp":0.0,"tv":0.0,"id":8639275}]}]}
{"op":"mcm","clk":"1003536819","pt":1580609188583,"mc":[{"id":"1.168186839","rc":[{"batb":[[0,1.86,1.35],[1,1.85,2.02],[2,1.83,2.02]],"ltp":0.0,"tv":0.0,"id":8639275},{"batb":[[0,1.95,1.29],[1,1.94,100.15],[2,1.93,2.02]],"ltp":1.94,"tv":3.53,"id":8173434}]}]}
{"op":"mcm","clk":"1003536891","pt":1580609189555,"mc":[{"id":"1.168186839","rc":[{"batb":[[1,1.93,2.02],[2,1.91,2.02]],"ltp":1.94,"tv":3.53,"id":8173434}]}]}
{"op":"mcm","clk":"1003692209","pt":1580611334536,"mc":[{"id":"1.168186839","rc":[{"batb":[[0,1.96,99.63],[1,1.95,1.29],[2,1.93,2.02]],"ltp":1.94,"tv":3.53,"id":8173434}]}]}
{"op":"mcm","clk":"1003693266","pt":1580611350579,"mc":[{"id":"1.168186839","rc":[{"batb":[[1,1.93,2.02],[2,1.91,2.02]],"ltp":1.94,"tv":3.53,"id":8173434}]}]}
{"op":"mcm","clk":"1003693307","pt":1580611351146,"mc":[{"id":"1.168186839","rc":[{"batb":[[0,1.98,98.49],[1,1.97,1.28],[2,1.93,2.02]],"ltp":1.94,"tv":3.53,"id":8173434}]}]}
{"op":"mcm","clk":"1003695126","pt":1580611381504,"mc":[{"id":"1.168186839","rc":[{"batb":[[0,1.99,1.27],[1,1.98,98.49]],"ltp":1.94,"tv":3.53,"id":8173434}]}]}
{"op":"mcm","clk":"1003695212","pt":1580611383306,"mc":[{"id":"1.168186839","rc":[{"batb":[[0,1.99,99.26],[1,1.93,2.02],[2,1.91,2.02]],"ltp":1.94,"tv":3.53,"id":8173434}]}]}
{"op":"mcm","clk":"1003743479","pt":1580612213601,"mc":[{"id":"1.168186839","marketDefinition":{"bspMarket":false,"turnInPlayEnabled":true,"persistenceEnabled":true,"marketBaseRate":5.0,"eventId":"29680287","eventTypeId":"2","numberOfWinners":1,"bettingType":"ODDS","marketType":"SET_WINNER","marketTime":"2020-02-02T03:09:00.000Z","suspendTime":"2020-02-02T03:09:00.000Z","bspReconciled":false,"complete":true,"inPlay":false,"crossMatching":true,"runnersVoidable":false,"numberOfActiveRunners":2,"betDelay":0,"status":"OPEN","runners":[{"status":"ACTIVE","sortPriority":1,"id":8173434,"name":"Taro Daniel"},{"status":"ACTIVE","sortPriority":2,"id":8639275,"name":"Yannick Hanfmann"}],"regulators":["MR_INT"],"countryCode":"AU","discountAllowed":true,"timezone":"UTC","openDate":"2020-02-02T02:54:00.000Z","version":3148075164,"name":"Set 1 Winner","eventName":"Daniel v Hanfmann"}}]}
{"op":"mcm","clk":"1003743595","pt":1580612215470,"mc":[{"id":"1.168186839","marketDefinition":{"bspMarket":false,"turnInPlayEnabled":true,"persistenceEnabled":true,"marketBaseRate":5.0,"eventId":"29680287","eventTypeId":"2","numberOfWinners":1,"bettingType":"ODDS","marketType":"SET_WINNER","marketTime":"2020-02-02T03:09:00.000Z","suspendTime":"2020-02-02T03:09:00.000Z","bspReconciled":false,"complete":true,"inPlay":false,"crossMatching":true,"runnersVoidable":false,"numberOfActiveRunners":2,"betDelay":0,"status":"OPEN","runners":[{"status":"ACTIVE","sortPriority":1,"id":8173434,"name":"Taro Daniel"},{"status":"ACTIVE","sortPriority":2,"id":8639275,"name":"Yannick Hanfmann"}],"regulators":["MR_INT"],"countryCode":"AU","discountAllowed":true,"timezone":"UTC","openDate":"2020-02-02T03:09:00.000Z","version":3148075164,"name":"Set 1 Winner","eventName":"Daniel v Hanfmann"}}]}
{"op":"mcm","clk":"1003792313","pt":1580613113519,"mc":[{"id":"1.168186839","marketDefinition":{"bspMarket":false,"turnInPlayEnabled":true,"persistenceEnabled":true,"marketBaseRate":5.0,"eventId":"29680287","eventTypeId":"2","numberOfWinners":1,"bettingType":"ODDS","marketType":"SET_WINNER","marketTime":"2020-02-02T03:24:00.000Z","suspendTime":"2020-02-02T03:24:00.000Z","bspReconciled":false,"complete":true,"inPlay":false,"crossMatching":true,"runnersVoidable":false,"numberOfActiveRunners":2,"betDelay":0,"status":"OPEN","runners":[{"status":"ACTIVE","sortPriority":1,"id":8173434,"name":"Taro Daniel"},{"status":"ACTIVE","sortPriority":2,"id":8639275,"name":"Yannick Hanfmann"}],"regulators":["MR_INT"],"countryCode":"AU","discountAllowed":true,"timezone":"UTC","openDate":"2020-02-02T03:09:00.000Z","version":3148099995,"name":"Set 1 Winner","eventName":"Daniel v Hanfmann"}}]}
{"op":"mcm","clk":"1003792394","pt":1580613115526,"mc":[{"id":"1.168186839","marketDefinition":{"bspMarket":false,"turnInPlayEnabled":true,"persistenceEnabled":true,"marketBaseRate":5.0,"eventId":"29680287","eventTypeId":"2","numberOfWinners":1,"bettingType":"ODDS","marketType":"SET_WINNER","marketTime":"2020-02-02T03:24:00.000Z","suspendTime":"2020-02-02T03:24:00.000Z","bspReconciled":false,"complete":true,"inPlay":false,"crossMatching":true,"runnersVoidable":false,"numberOfActiveRunners":2,"betDelay":0,"status":"OPEN","runners":[{"status":"ACTIVE","sortPriority":1,"id":8173434,"name":"Taro Daniel"},{"status":"ACTIVE","sortPriority":2,"id":8639275,"name":"Yannick Hanfmann"}],"regulators":["MR_INT"],"countryCode":"AU","discountAllowed":true,"timezone":"UTC","openDate":"2020-02-02T03:24:00.000Z","version":3148099995,"name":"Set 1 Winner","eventName":"Daniel v Hanfmann"}}]}
{"op":"mcm","clk":"1003804069","pt":1580613413219,"mc":[{"id":"1.168186839","marketDefinition":{"bspMarket":false,"turnInPlayEnabled":true,"persistenceEnabled":true,"marketBaseRate":5.0,"eventId":"29680287","eventTypeId":"2","numberOfWinners":1,"bettingType":"ODDS","marketType":"SET_WINNER","marketTime":"2020-02-02T03:33:00.000Z","suspendTime":"2020-02-02T03:33:00.000Z","bspReconciled":false,"complete":true,"inPlay":false,"crossMatching":true,"runnersVoidable":false,"numberOfActiveRunners":2,"betDelay":0,"status":"OPEN","runners":[{"status":"ACTIVE","sortPriority":1,"id":8173434,"name":"Taro Daniel"},{"status":"ACTIVE","sortPriority":2,"id":8639275,"name":"Yannick Hanfmann"}],"regulators":["MR_INT"],"countryCode":"AU","discountAllowed":true,"timezone":"UTC","openDate":"2020-02-02T03:24:00.000Z","version":3148104073,"name":"Set 1 Winner","eventName":"Daniel v Hanfmann"}}]}
{"op":"mcm","clk":"1003804278","pt":1580613417227,"mc":[{"id":"1.168186839","marketDefinition":{"bspMarket":false,"turnInPlayEnabled":true,"persistenceEnabled":true,"marketBaseRate":5.0,"eventId":"29680287","eventTypeId":"2","numberOfWinners":1,"bettingType":"ODDS","marketType":"SET_WINNER","marketTime":"2020-02-02T03:33:00.000Z","suspendTime":"2020-02-02T03:33:00.000Z","bspReconciled":false,"complete":true,"inPlay":false,"crossMatching":true,"runnersVoidable":false,"numberOfActiveRunners":2,"betDelay":0,"status":"OPEN","runners":[{"status":"ACTIVE","sortPriority":1,"id":8173434,"name":"Taro Daniel"},{"status":"ACTIVE","sortPriority":2,"id":8639275,"name":"Yannick Hanfmann"}],"regulators":["MR_INT"],"countryCode":"AU","discountAllowed":true,"timezone":"UTC","openDate":"2020-02-02T03:33:00.000Z","version":3148104073,"name":"Set 1 Winner","eventName":"Daniel v Hanfmann"}}]}
{"op":"mcm","clk":"1003822810","pt":1580613890533,"mc":[{"id":"1.168186839","rc":[{"batb":[[0,2,99.7],[1,1.99,1.27],[2,1.93,2.02]],"ltp":1.94,"tv":3.53,"id":8173434}]}]}
{"op":"mcm","clk":"1003823335","pt":1580613901642,"mc":[{"id":"1.168186839","rc":[{"batb":[[1,1.93,2.02],[2,1.91,2.02]],"ltp":1.94,"tv":3.53,"id":8173434}]}]}
{"op":"mcm","clk":"1003823370","pt":1580613902251,"mc":[{"id":"1.168186839","rc":[{"batb":[[0,2.02,99.95]],"ltp":1.94,"tv":3.53,"id":8173434}]}]}
{"op":"mcm","clk":"1003844122","pt":1580614313152,"mc":[{"id":"1.168186839","marketDefinition":{"bspMarket":false,"turnInPlayEnabled":true,"persistenceEnabled":true,"marketBaseRate":5.0,"eventId":"29680287","eventTypeId":"2","numberOfWinners":1,"bettingType":"ODDS","marketType":"SET_WINNER","marketTime":"2020-02-02T03:48:00.000Z","suspendTime":"2020-02-02T03:48:00.000Z","bspReconciled":false,"complete":true,"inPlay":false,"crossMatching":true,"runnersVoidable":false,"numberOfActiveRunners":2,"betDelay":0,"status":"OPEN","runners":[{"status":"ACTIVE","sortPriority":1,"id":8173434,"name":"Taro Daniel"},{"status":"ACTIVE","sortPriority":2,"id":8639275,"name":"Yannick Hanfmann"}],"regulators":["MR_INT"],"countryCode":"AU","discountAllowed":true,"timezone":"UTC","openDate":"2020-02-02T03:33:00.000Z","version":3148118354,"name":"Set 1 Winner","eventName":"Daniel v Hanfmann"}}]}
{"op":"mcm","clk":"1003844287","pt":1580614316160,"mc":[{"id":"1.168186839","marketDefinition":{"bspMarket":false,"turnInPlayEnabled":true,"persistenceEnabled":true,"marketBaseRate":5.0,"eventId":"29680287","eventTypeId":"2","numberOfWinners":1,"bettingType":"ODDS","marketType":"SET_WINNER","marketTime":"2020-02-02T03:48:00.000Z","suspendTime":"2020-02-02T03:48:00.000Z","bspReconciled":false,"complete":true,"inPlay":false,"crossMatching":true,"runnersVoidable":false,"numberOfActiveRunners":2,"betDelay":0,"status":"OPEN","runners":[{"status":"ACTIVE","sortPriority":1,"id":8173434,"name":"Taro Daniel"},{"status":"ACTIVE","sortPriority":2,"id":8639275,"name":"Yannick Hanfmann"}],"regulators":["MR_INT"],"countryCode":"AU","discountAllowed":true,"timezone":"UTC","openDate":"2020-02-02T03:48:00.000Z","version":3148118354,"name":"Set 1 Winner","eventName":"Daniel v Hanfmann"}}]}
{"op":"mcm","clk":"1003854839","pt":1580614507617,"mc":[{"id":"1.168186839","rc":[{"batb":[[0,2.02,1.25]],"ltp":1.94,"tv":3.53,"id":8173434}]}]}
{"op":"mcm","clk":"1003884924","pt":1580615213127,"mc":[{"id":"1.168186839","marketDefinition":{"bspMarket":false,"turnInPlayEnabled":true,"persistenceEnabled":true,"marketBaseRate":5.0,"eventId":"29680287","eventTypeId":"2","numberOfWinners":1,"bettingType":"ODDS","marketType":"SET_WINNER","marketTime":"2020-02-02T04:03:00.000Z","suspendTime":"2020-02-02T04:03:00.000Z","bspReconciled":false,"complete":true,"inPlay":false,"crossMatching":true,"runnersVoidable":false,"numberOfActiveRunners":2,"betDelay":0,"status":"OPEN","runners":[{"status":"ACTIVE","sortPriority":1,"id":8173434,"name":"Taro Daniel"},{"status":"ACTIVE","sortPriority":2,"id":8639275,"name":"Yannick Hanfmann"}],"regulators":["MR_INT"],"countryCode":"AU","discountAllowed":true,"timezone":"UTC","openDate":"2020-02-02T03:48:00.000Z","version":3148131914,"name":"Set 1 Winner","eventName":"Daniel v Hanfmann"}}]}
{"op":"mcm","clk":"1003885260","pt":1580615222147,"mc":[{"id":"1.168186839","marketDefinition":{"bspMarket":false,"turnInPlayEnabled":true,"persistenceEnabled":true,"marketBaseRate":5.0,"eventId":"29680287","eventTypeId":"2","numberOfWinners":1,"bettingType":"ODDS","marketType":"SET_WINNER","marketTime":"2020-02-02T04:03:00.000Z","suspendTime":"2020-02-02T04:03:00.000Z","bspReconciled":false,"complete":true,"inPlay":false,"crossMatching":true,"runnersVoidable":false,"numberOfActiveRunners":2,"betDelay":0,"status":"OPEN","runners":[{"status":"ACTIVE","sortPriority":1,"id":8173434,"name":"Taro Daniel"},{"status":"ACTIVE","sortPriority":2,"id":8639275,"name":"Yannick Hanfmann"}],"regulators":["MR_INT"],"countryCode":"AU","discountAllowed":true,"timezone":"UTC","openDate":"2020-02-02T04:03:00.000Z","version":3148131914,"name":"Set 1 Winner","eventName":"Daniel v Hanfmann"}}]}
{"op":"mcm","clk":"1003917285","pt":1580616113068,"mc":[{"id":"1.168186839","marketDefinition":{"bspMarket":false,"turnInPlayEnabled":true,"persistenceEnabled":true,"marketBaseRate":5.0,"eventId":"29680287","eventTypeId":"2","numberOfWinners":1,"bettingType":"ODDS","marketType":"SET_WINNER","marketTime":"2020-02-02T04:18:00.000Z","suspendTime":"2020-02-02T04:18:00.000Z","bspReconciled":false,"complete":true,"inPlay":false,"crossMatching":true,"runnersVoidable":false,"numberOfActiveRunners":2,"betDelay":0,"status":"OPEN","runners":[{"status":"ACTIVE","sortPriority":1,"id":8173434,"name":"Taro Daniel"},{"status":"ACTIVE","sortPriority":2,"id":8639275,"name":"Yannick Hanfmann"}],"regulators":["MR_INT"],"countryCode":"AU","discountAllowed":true,"timezone":"UTC","openDate":"2020-02-02T04:03:00.000Z","version":3148141597,"name":"Set 1 Winner","eventName":"Daniel v Hanfmann"}}]}
{"op":"mcm","clk":"1003917423","pt":1580616116074,"mc":[{"id":"1.168186839","marketDefinition":{"bspMarket":false,"turnInPlayEnabled":true,"persistenceEnabled":true,"marketBaseRate":5.0,"eventId":"29680287","eventTypeId":"2","numberOfWinners":1,"bettingType":"ODDS","marketType":"SET_WINNER","marketTime":"2020-02-02T04:18:00.000Z","suspendTime":"2020-02-02T04:18:00.000Z","bspReconciled":false,"complete":true,"inPlay":false,"crossMatching":true,"runnersVoidable":false,"numberOfActiveRunners":2,"betDelay":0,"status":"OPEN","runners":[{"status":"ACTIVE","sortPriority":1,"id":8173434,"name":"Taro Daniel"},{"status":"ACTIVE","sortPriority":2,"id":8639275,"name":"Yannick Hanfmann"}],"regulators":["MR_INT"],"countryCode":"AU","discountAllowed":true,"timezone":"UTC","openDate":"2020-02-02T04:18:00.000Z","version":3148141597,"name":"Set 1 Winner","eventName":"Daniel v Hanfmann"}}]}
{"op":"mcm","clk":"1003958135","pt":1580617013090,"mc":[{"id":"1.168186839","marketDefinition":{"bspMarket":false,"turnInPlayEnabled":true,"persistenceEnabled":true,"marketBaseRate":5.0,"eventId":"29680287","eventTypeId":"2","numberOfWinners":1,"bettingType":"ODDS","marketType":"SET_WINNER","marketTime":"2020-02-02T04:33:00.000Z","suspendTime":"2020-02-02T04:33:00.000Z","bspReconciled":false,"complete":true,"inPlay":false,"crossMatching":true,"runnersVoidable":false,"numberOfActiveRunners":2,"betDelay":0,"status":"OPEN","runners":[{"status":"ACTIVE","sortPriority":1,"id":8173434,"name":"Taro Daniel"},{"status":"ACTIVE","sortPriority":2,"id":8639275,"name":"Yannick Hanfmann"}],"regulators":["MR_INT"],"countryCode":"AU","discountAllowed":true,"timezone":"UTC","openDate":"2020-02-02T04:18:00.000Z","version":3148155792,"name":"Set 1 Winner","eventName":"Daniel v Hanfmann"}}]}
{"op":"mcm","clk":"1003958235","pt":1580617015095,"mc":[{"id":"1.168186839","marketDefinition":{"bspMarket":false,"turnInPlayEnabled":true,"persistenceEnabled":true,"marketBaseRate":5.0,"eventId":"29680287","eventTypeId":"2","numberOfWinners":1,"bettingType":"ODDS","marketType":"SET_WINNER","marketTime":"2020-02-02T04:33:00.000Z","suspendTime":"2020-02-02T04:33:00.000Z","bspReconciled":false,"complete":true,"inPlay":false,"crossMatching":true,"runnersVoidable":false,"numberOfActiveRunners":2,"betDelay":0,"status":"OPEN","runners":[{"status":"ACTIVE","sortPriority":1,"id":8173434,"name":"Taro Daniel"},{"status":"ACTIVE","sortPriority":2,"id":8639275,"name":"Yannick Hanfmann"}],"regulators":["MR_INT"],"countryCode":"AU","discountAllowed":true,"timezone":"UTC","openDate":"2020-02-02T04:33:00.000Z","version":3148155792,"name":"Set 1 Winner","eventName":"Daniel v Hanfmann"}}]}
{"op":"mcm","clk":"1003999254","pt":1580617912895,"mc":[{"id":"1.168186839","marketDefinition":{"bspMarket":false,"turnInPlayEnabled":true,"persistenceEnabled":true,"marketBaseRate":5.0,"eventId":"29680287","eventTypeId":"2","numberOfWinners":1,"bettingType":"ODDS","marketType":"SET_WINNER","marketTime":"2020-02-02T04:48:00.000Z","suspendTime":"2020-02-02T04:48:00.000Z","bspReconciled":false,"complete":true,"inPlay":false,"crossMatching":true,"runnersVoidable":false,"numberOfActiveRunners":2,"betDelay":0,"status":"OPEN","runners":[{"status":"ACTIVE","sortPriority":1,"id":8173434,"name":"Taro Daniel"},{"status":"ACTIVE","sortPriority":2,"id":8639275,"name":"Yannick Hanfmann"}],"regulators":["MR_INT"],"countryCode":"AU","discountAllowed":true,"timezone":"UTC","openDate":"2020-02-02T04:33:00.000Z","version":3148160049,"name":"Set 1 Winner","eventName":"Daniel v Hanfmann"}}]}
{"op":"mcm","clk":"1003999478","pt":1580617916902,"mc":[{"id":"1.168186839","marketDefinition":{"bspMarket":false,"turnInPlayEnabled":true,"persistenceEnabled":true,"marketBaseRate":5.0,"eventId":"29680287","eventTypeId":"2","numberOfWinners":1,"bettingType":"ODDS","marketType":"SET_WINNER","marketTime":"2020-02-02T04:48:00.000Z","suspendTime":"2020-02-02T04:48:00.000Z","bspReconciled":false,"complete":true,"inPlay":false,"crossMatching":true,"runnersVoidable":false,"numberOfActiveRunners":2,"betDelay":0,"status":"OPEN","runners":[{"status":"ACTIVE","sortPriority":1,"id":8173434,"name":"Taro Daniel"},{"status":"ACTIVE","sortPriority":2,"id":8639275,"name":"Yannick Hanfmann"}],"regulators":["MR_INT"],"countryCode":"AU","discountAllowed":true,"timezone":"UTC","openDate":"2020-02-02T04:48:00.000Z","version":3148160049,"name":"Set 1 Winner","eventName":"Daniel v Hanfmann"}}]}
{"op":"mcm","clk":"1004042103","pt":1580618812677,"mc":[{"id":"1.168186839","marketDefinition":{"bspMarket":false,"turnInPlayEnabled":true,"persistenceEnabled":true,"marketBaseRate":5.0,"eventId":"29680287","eventTypeId":"2","numberOfWinners":1,"bettingType":"ODDS","marketType":"SET_WINNER","marketTime":"2020-02-02T05:03:00.000Z","suspendTime":"2020-02-02T05:03:00.000Z","bspReconciled":false,"complete":true,"inPlay":false,"crossMatching":true,"runnersVoidable":false,"numberOfActiveRunners":2,"betDelay":0,"status":"OPEN","runners":[{"status":"ACTIVE","sortPriority":1,"id":8173434,"name":"Taro Daniel"},{"status":"ACTIVE","sortPriority":2,"id":8639275,"name":"Yannick Hanfmann"}],"regulators":["MR_INT"],"countryCode":"AU","discountAllowed":true,"timezone":"UTC","openDate":"2020-02-02T04:48:00.000Z","version":3148167220,"name":"Set 1 Winner","eventName":"Daniel v Hanfmann"}}]}
{"op":"mcm","clk":"1004043048","pt":1580618830708,"mc":[{"id":"1.168186839","marketDefinition":{"bspMarket":false,"turnInPlayEnabled":true,"persistenceEnabled":true,"marketBaseRate":5.0,"eventId":"29680287","eventTypeId":"2","numberOfWinners":1,"bettingType":"ODDS","marketType":"SET_WINNER","marketTime":"2020-02-02T05:03:00.000Z","suspendTime":"2020-02-02T05:03:00.000Z","bspReconciled":false,"complete":true,"inPlay":false,"crossMatching":true,"runnersVoidable":false,"numberOfActiveRunners":2,"betDelay":0,"status":"OPEN","runners":[{"status":"ACTIVE","sortPriority":1,"id":8173434,"name":"Taro Daniel"},{"status":"ACTIVE","sortPriority":2,"id":8639275,"name":"Yannick Hanfmann"}],"regulators":["MR_INT"],"countryCode":"AU","discountAllowed":true,"timezone":"UTC","openDate":"2020-02-02T05:03:00.000Z","version":3148167220,"name":"Set 1 Winner","eventName":"Daniel v Hanfmann"}}]}
{"op":"mcm","clk":"1004069740","pt":1580619530017,"mc":[{"id":"1.168186839","rc":[{"batb":[[0,2.02,99.47]],"ltp":1.94,"tv":3.53,"id":8173434}]}]}
{"op":"mcm","clk":"1004076105","pt":1580619713479,"mc":[{"id":"1.168186839","marketDefinition":{"bspMarket":false,"turnInPlayEnabled":true,"persistenceEnabled":true,"marketBaseRate":5.0,"eventId":"29680287","eventTypeId":"2","numberOfWinners":1,"bettingType":"ODDS","marketType":"SET_WINNER","marketTime":"2020-02-02T05:18:00.000Z","suspendTime":"2020-02-02T05:18:00.000Z","bspReconciled":false,"complete":true,"inPlay":false,"crossMatching":true,"runnersVoidable":false,"numberOfActiveRunners":2,"betDelay":0,"status":"OPEN","runners":[{"status":"ACTIVE","sortPriority":1,"id":8173434,"name":"Taro Daniel"},{"status":"ACTIVE","sortPriority":2,"id":8639275,"name":"Yannick Hanfmann"}],"regulators":["MR_INT"],"countryCode":"AU","discountAllowed":true,"timezone":"UTC","openDate":"2020-02-02T05:03:00.000Z","version":3148176198,"name":"Set 1 Winner","eventName":"Daniel v Hanfmann"}}]}
{"op":"mcm","clk":"1004076270","pt":1580619716486,"mc":[{"id":"1.168186839","marketDefinition":{"bspMarket":false,"turnInPlayEnabled":true,"persistenceEnabled":true,"marketBaseRate":5.0,"eventId":"29680287","eventTypeId":"2","numberOfWinners":1,"bettingType":"ODDS","marketType":"SET_WINNER","marketTime":"2020-02-02T05:18:00.000Z","suspendTime":"2020-02-02T05:18:00.000Z","bspReconciled":false,"complete":true,"inPlay":false,"crossMatching":true,"runnersVoidable":false,"numberOfActiveRunners":2,"betDelay":0,"status":"OPEN","runners":[{"status":"ACTIVE","sortPriority":1,"id":8173434,"name":"Taro Daniel"},{"status":"ACTIVE","sortPriority":2,"id":8639275,"name":"Yannick Hanfmann"}],"regulators":["MR_INT"],"countryCode":"AU","discountAllowed":true,"timezone":"UTC","openDate":"2020-02-02T05:18:00.000Z","version":3148176198,"name":"Set 1 Winner","eventName":"Daniel v Hanfmann"}}]}
{"op":"mcm","clk":"1004095033","pt":1580620195896,"mc":[{"id":"1.168186839","rc":[{"batb":[[0,2.02,1.25]],"ltp":1.94,"tv":3.53,"id":8173434}]}]}
{"op":"mcm","clk":"1004095074","pt":1580620197187,"mc":[{"id":"1.168186839","rc":[{"batb":[[0,2.02,99.47]],"ltp":1.94,"tv":3.53,"id":8173434}]}]}
{"op":"mcm","clk":"1004111507","pt":1580620613279,"mc":[{"id":"1.168186839","marketDefinition":{"bspMarket":false,"turnInPlayEnabled":true,"persistenceEnabled":true,"marketBaseRate":5.0,"eventId":"29680287","eventTypeId":"2","numberOfWinners":1,"bettingType":"ODDS","marketType":"SET_WINNER","marketTime":"2020-02-02T05:33:00.000Z","suspendTime":"2020-02-02T05:33:00.000Z","bspReconciled":false,"complete":true,"inPlay":false,"crossMatching":true,"runnersVoidable":false,"numberOfActiveRunners":2,"betDelay":0,"status":"OPEN","runners":[{"status":"ACTIVE","sortPriority":1,"id":8173434,"name":"Taro Daniel"},{"status":"ACTIVE","sortPriority":2,"id":8639275,"name":"Yannick Hanfmann"}],"regulators":["MR_INT"],"countryCode":"AU","discountAllowed":true,"timezone":"UTC","openDate":"2020-02-02T05:18:00.000Z","version":3148190106,"name":"Set 1 Winner","eventName":"Daniel v Hanfmann"}}]}
{"op":"mcm","clk":"1004111685","pt":1580620616285,"mc":[{"id":"1.168186839","marketDefinition":{"bspMarket":false,"turnInPlayEnabled":true,"persistenceEnabled":true,"marketBaseRate":5.0,"eventId":"29680287","eventTypeId":"2","numberOfWinners":1,"bettingType":"ODDS","marketType":"SET_WINNER","marketTime":"2020-02-02T05:33:00.000Z","suspendTime":"2020-02-02T05:33:00.000Z","bspReconciled":false,"complete":true,"inPlay":false,"crossMatching":true,"runnersVoidable":false,"numberOfActiveRunners":2,"betDelay":0,"status":"OPEN","runners":[{"status":"ACTIVE","sortPriority":1,"id":8173434,"name":"Taro Daniel"},{"status":"ACTIVE","sortPriority":2,"id":8639275,"name":"Yannick Hanfmann"}],"regulators":["MR_INT"],"countryCode":"AU","discountAllowed":true,"timezone":"UTC","openDate":"2020-02-02T05:33:00.000Z","version":3148190106,"name":"Set 1 Winner","eventName":"Daniel v Hanfmann"}}]}
{"op":"mcm","clk":"1004140274","pt":1580621179857,"mc":[{"id":"1.168186839","rc":[{"batb":[[0,2.02,1.25]],"ltp":1.94,"tv":3.53,"id":8173434}]}]}
{"op":"mcm","clk":"1004141699","pt":1580621210678,"mc":[{"id":"1.168186839","rc":[{"batb":[[0,2.02,99.47]],"ltp":1.94,"tv":3.53,"id":8173434}]}]}
{"op":"mcm","clk":"1004151850","pt":1580621513271,"mc":[{"id":"1.168186839","marketDefinition":{"bspMarket":false,"turnInPlayEnabled":true,"persistenceEnabled":true,"marketBaseRate":5.0,"eventId":"29680287","eventTypeId":"2","numberOfWinners":1,"bettingType":"ODDS","marketType":"SET_WINNER","marketTime":"2020-02-02T05:48:00.000Z","suspendTime":"2020-02-02T05:48:00.000Z","bspReconciled":false,"complete":true,"inPlay":false,"crossMatching":true,"runnersVoidable":false,"numberOfActiveRunners":2,"betDelay":0,"status":"OPEN","runners":[{"status":"ACTIVE","sortPriority":1,"id":8173434,"name":"Taro Daniel"},{"status":"ACTIVE","sortPriority":2,"id":8639275,"name":"Yannick Hanfmann"}],"regulators":["MR_INT"],"countryCode":"AU","discountAllowed":true,"timezone":"UTC","openDate":"2020-02-02T05:33:00.000Z","version":3148205938,"name":"Set 1 Winner","eventName":"Daniel v Hanfmann"}}]}
{"op":"mcm","clk":"1004151955","pt":1580621516276,"mc":[{"id":"1.168186839","marketDefinition":{"bspMarket":false,"turnInPlayEnabled":true,"persistenceEnabled":true,"marketBaseRate":5.0,"eventId":"29680287","eventTypeId":"2","numberOfWinners":1,"bettingType":"ODDS","marketType":"SET_WINNER","marketTime":"2020-02-02T05:48:00.000Z","suspendTime":"2020-02-02T05:48:00.000Z","bspReconciled":false,"complete":true,"inPlay":false,"crossMatching":true,"runnersVoidable":false,"numberOfActiveRunners":2,"betDelay":0,"status":"OPEN","runners":[{"status":"ACTIVE","sortPriority":1,"id":8173434,"name":"Taro Daniel"},{"status":"ACTIVE","sortPriority":2,"id":8639275,"name":"Yannick Hanfmann"}],"regulators":["MR_INT"],"countryCode":"AU","discountAllowed":true,"timezone":"UTC","openDate":"2020-02-02T05:48:00.000Z","version":3148205938,"name":"Set 1 Winner","eventName":"Daniel v Hanfmann"}}]}
{"op":"mcm","clk":"1004155339","pt":1580621595024,"mc":[{"id":"1.168186839","rc":[{"trd":[[2.02,3.2]],"batb":[[0,2.02,97.87]],"ltp":2.02,"tv":6.74,"id":8173434}],"tv":6.74}]}
{"op":"mcm","clk":"1004170043","pt":1580621990016,"mc":[{"id":"1.168186839","rc":[{"batb":[[0,1.93,2.02],[1,1.91,2.02],[2,1.9,166.67]],"ltp":2.02,"tv":6.74,"id":8173434}]}]}
{"op":"mcm","clk":"1004170420","pt":1580622000809,"mc":[{"id":"1.168186839","rc":[{"batb":[[0,1.97,100.17],[1,1.93,2.02],[2,1.91,2.02]],"ltp":2.02,"tv":6.74,"id":8173434}]}]}
{"op":"mcm","clk":"1004176593","pt":1580622211023,"mc":[{"id":"1.168186839","rc":[{"batb":[[0,1.99,99.11],[1,1.98,1.28],[2,1.93,2.02]],"ltp":2.02,"tv":6.74,"id":8173434}]}]}
{"op":"mcm","clk":"1004177438","pt":1580622240489,"mc":[{"id":"1.168186839","rc":[{"batb":[[1,1.93,2.02],[2,1.91,2.02]],"ltp":2.02,"tv":6.74,"id":8173434}]}]}
{"op":"mcm","clk":"1004177458","pt":1580622241470,"mc":[{"id":"1.168186839","rc":[{"batb":[[0,2.02,97.74],[1,2,1.26],[2,1.93,2.02]],"ltp":2.02,"tv":6.74,"id":8173434}]}]}
{"op":"mcm","clk":"1004178252","pt":1580622270523,"mc":[{"id":"1.168186839","rc":[{"batb":[[1,1.93,2.02],[2,1.91,2.02]],"ltp":2.02,"tv":6.74,"id":8173434}]}]}
{"op":"mcm","clk":"1004178275","pt":1580622271089,"mc":[{"id":"1.168186839","rc":[{"batb":[[0,2.04,1.24]],"ltp":2.02,"tv":6.74,"id":8173434}]}]}
{"op":"mcm","clk":"1004183498","pt":1580622413114,"mc":[{"id":"1.168186839","marketDefinition":{"bspMarket":false,"turnInPlayEnabled":true,"persistenceEnabled":true,"marketBaseRate":5.0,"eventId":"29680287","eventTypeId":"2","numberOfWinners":1,"bettingType":"ODDS","marketType":"SET_WINNER","marketTime":"2020-02-02T06:03:00.000Z","suspendTime":"2020-02-02T06:03:00.000Z","bspReconciled":false,"complete":true,"inPlay":false,"crossMatching":true,"runnersVoidable":false,"numberOfActiveRunners":2,"betDelay":0,"status":"OPEN","runners":[{"status":"ACTIVE","sortPriority":1,"id":8173434,"name":"Taro Daniel"},{"status":"ACTIVE","sortPriority":2,"id":8639275,"name":"Yannick Hanfmann"}],"regulators":["MR_INT"],"countryCode":"AU","discountAllowed":true,"timezone":"UTC","openDate":"2020-02-02T05:48:00.000Z","version":3148212365,"name":"Set 1 Winner","eventName":"Daniel v Hanfmann"}}]}
{"op":"mcm","clk":"1004184590","pt":1580622440175,"mc":[{"id":"1.168186839","marketDefinition":{"bspMarket":false,"turnInPlayEnabled":true,"persistenceEnabled":true,"marketBaseRate":5.0,"eventId":"29680287","eventTypeId":"2","numberOfWinners":1,"bettingType":"ODDS","marketType":"SET_WINNER","marketTime":"2020-02-02T06:03:00.000Z","suspendTime":"2020-02-02T06:03:00.000Z","bspReconciled":false,"complete":true,"inPlay":false,"crossMatching":true,"runnersVoidable":false,"numberOfActiveRunners":2,"betDelay":0,"status":"OPEN","runners":[{"status":"ACTIVE","sortPriority":1,"id":8173434,"name":"Taro Daniel"},{"status":"ACTIVE","sortPriority":2,"id":8639275,"name":"Yannick Hanfmann"}],"regulators":["MR_INT"],"countryCode":"AU","discountAllowed":true,"timezone":"UTC","openDate":"2020-02-02T06:03:00.000Z","version":3148212365,"name":"Set 1 Winner","eventName":"Daniel v Hanfmann"}}]}
{"op":"mcm","clk":"1004211888","pt":1580623312961,"mc":[{"id":"1.168186839","marketDefinition":{"bspMarket":false,"turnInPlayEnabled":true,"persistenceEnabled":true,"marketBaseRate":5.0,"eventId":"29680287","eventTypeId":"2","numberOfWinners":1,"bettingType":"ODDS","marketType":"SET_WINNER","marketTime":"2020-02-02T06:18:00.000Z","suspendTime":"2020-02-02T06:18:00.000Z","bspReconciled":false,"complete":true,"inPlay":false,"crossMatching":true,"runnersVoidable":false,"numberOfActiveRunners":2,"betDelay":0,"status":"OPEN","runners":[{"status":"ACTIVE","sortPriority":1,"id":8173434,"name":"Taro Daniel"},{"status":"ACTIVE","sortPriority":2,"id":8639275,"name":"Yannick Hanfmann"}],"regulators":["MR_INT"],"countryCode":"AU","discountAllowed":true,"timezone":"UTC","openDate":"2020-02-02T06:03:00.000Z","version":3148224739,"name":"Set 1 Winner","eventName":"Daniel v Hanfmann"}}]}
{"op":"mcm","clk":"1004211992","pt":1580623315969,"mc":[{"id":"1.168186839","marketDefinition":{"bspMarket":false,"turnInPlayEnabled":true,"persistenceEnabled":true,"marketBaseRate":5.0,"eventId":"29680287","eventTypeId":"2","numberOfWinners":1,"bettingType":"ODDS","marketType":"SET_WINNER","marketTime":"2020-02-02T06:18:00.000Z","suspendTime":"2020-02-02T06:18:00.000Z","bspReconciled":false,"complete":true,"inPlay":false,"crossMatching":true,"runnersVoidable":false,"numberOfActiveRunners":2,"betDelay":0,"status":"OPEN","runners":[{"status":"ACTIVE","sortPriority":1,"id":8173434,"name":"Taro Daniel"},{"status":"ACTIVE","sortPriority":2,"id":8639275,"name":"Yannick Hanfmann"}],"regulators":["MR_INT"],"countryCode":"AU","discountAllowed":true,"timezone":"UTC","openDate":"2020-02-02T06:18:00.000Z","version":3148224739,"name":"Set 1 Winner","eventName":"Daniel v Hanfmann"}}]}
{"op":"mcm","clk":"1004239219","pt":1580624212832,"mc":[{"id":"1.168186839","marketDefinition":{"bspMarket":false,"turnInPlayEnabled":true,"persistenceEnabled":true,"marketBaseRate":5.0,"eventId":"29680287","eventTypeId":"2","numberOfWinners":1,"bettingType":"ODDS","marketType":"SET_WINNER","marketTime":"2020-02-02T06:33:00.000Z","suspendTime":"2020-02-02T06:33:00.000Z","bspReconciled":false,"complete":true,"inPlay":false,"crossMatching":true,"runnersVoidable":false,"numberOfActiveRunners":2,"betDelay":0,"status":"OPEN","runners":[{"status":"ACTIVE","sortPriority":1,"id":8173434,"name":"Taro Daniel"},{"status":"ACTIVE","sortPriority":2,"id":8639275,"name":"Yannick Hanfmann"}],"regulators":["MR_INT"],"countryCode":"AU","discountAllowed":true,"timezone":"UTC","openDate":"2020-02-02T06:18:00.000Z","version":3148240054,"name":"Set 1 Winner","eventName":"Daniel v Hanfmann"}}]}
{"op":"mcm","clk":"1004239304","pt":1580624215838,"mc":[{"id":"1.168186839","marketDefinition":{"bspMarket":false,"turnInPlayEnabled":true,"persistenceEnabled":true,"marketBaseRate":5.0,"eventId":"29680287","eventTypeId":"2","numberOfWinners":1,"bettingType":"ODDS","marketType":"SET_WINNER","marketTime":"2020-02-02T06:33:00.000Z","suspendTime":"2020-02-02T06:33:00.000Z","bspReconciled":false,"complete":true,"inPlay":false,"crossMatching":true,"runnersVoidable":false,"numberOfActiveRunners":2,"betDelay":0,"status":"OPEN","runners":[{"status":"ACTIVE","sortPriority":1,"id":8173434,"name":"Taro Daniel"},{"status":"ACTIVE","sortPriority":2,"id":8639275,"name":"Yannick Hanfmann"}],"regulators":["MR_INT"],"countryCode":"AU","discountAllowed":true,"timezone":"UTC","openDate":"2020-02-02T06:33:00.000Z","version":3148240054,"name":"Set 1 Winner","eventName":"Daniel v Hanfmann"}}]}
{"op":"mcm","clk":"1004267027","pt":1580625113633,"mc":[{"id":"1.168186839","marketDefinition":{"bspMarket":false,"turnInPlayEnabled":true,"persistenceEnabled":true,"marketBaseRate":5.0,"eventId":"29680287","eventTypeId":"2","numberOfWinners":1,"bettingType":"ODDS","marketType":"SET_WINNER","marketTime":"2020-02-02T06:48:00.000Z","suspendTime":"2020-02-02T06:48:00.000Z","bspReconciled":false,"complete":true,"inPlay":false,"crossMatching":true,"runnersVoidable":false,"numberOfActiveRunners":2,"betDelay":0,"status":"OPEN","runners":[{"status":"ACTIVE","sortPriority":1,"id":8173434,"name":"Taro Daniel"},{"status":"ACTIVE","sortPriority":2,"id":8639275,"name":"Yannick Hanfmann"}],"regulators":["MR_INT"],"countryCode":"AU","discountAllowed":true,"timezone":"UTC","openDate":"2020-02-02T06:33:00.000Z","version":3148248256,"name":"Set 1 Winner","eventName":"Daniel v Hanfmann"}}]}
{"op":"mcm","clk":"1004267120","pt":1580625115637,"mc":[{"id":"1.168186839","marketDefinition":{"bspMarket":false,"turnInPlayEnabled":true,"persistenceEnabled":true,"marketBaseRate":5.0,"eventId":"29680287","eventTypeId":"2","numberOfWinners":1,"bettingType":"ODDS","marketType":"SET_WINNER","marketTime":"2020-02-02T06:48:00.000Z","suspendTime":"2020-02-02T06:48:00.000Z","bspReconciled":false,"complete":true,"inPlay":false,"crossMatching":true,"runnersVoidable":false,"numberOfActiveRunners":2,"betDelay":0,"status":"OPEN","runners":[{"status":"ACTIVE","sortPriority":1,"id":8173434,"name":"Taro Daniel"},{"status":"ACTIVE","sortPriority":2,"id":8639275,"name":"Yannick Hanfmann"}],"regulators":["MR_INT"],"countryCode":"AU","discountAllowed":true,"timezone":"UTC","openDate":"2020-02-02T06:48:00.000Z","version":3148248256,"name":"Set 1 Winner","eventName":"Daniel v Hanfmann"}}]}
{"op":"mcm","clk":"1004280009","pt":1580625538410,"mc":[{"id":"1.168186839","rc":[{"batb":[[2,1.84,37.77]],"ltp":0.0,"tv":0.0,"id":8639275},{"batb":[[0,2.04,55.13]],"ltp":2.02,"tv":6.74,"id":8173434}]}]}
{"op":"mcm","clk":"1004280815","pt":1580625558658,"mc":[{"id":"1.168186839","rc":[{"batb":[[2,1.84,37.61]],"ltp":0.0,"tv":0.0,"id":8639275},{"trd":[[2.04,19.26]],"batb":[[0,2.04,45.5]],"ltp":2.04,"tv":25.99,"id":8173434}],"tv":25.99}]}
{"op":"mcm","clk":"1004286954","pt":1580625713660,"mc":[{"id":"1.168186839","marketDefinition":{"bspMarket":false,"turnInPlayEnabled":true,"persistenceEnabled":true,"marketBaseRate":5.0,"eventId":"29680287","eventTypeId":"2","numberOfWinners":1,"bettingType":"ODDS","marketType":"SET_WINNER","marketTime":"2020-02-02T06:37:00.000Z","suspendTime":"2020-02-02T06:37:00.000Z","bspReconciled":false,"complete":true,"inPlay":false,"crossMatching":true,"runnersVoidable":false,"numberOfActiveRunners":2,"betDelay":0,"status":"OPEN","runners":[{"status":"ACTIVE","sortPriority":1,"id":8173434,"name":"Taro Daniel"},{"status":"ACTIVE","sortPriority":2,"id":8639275,"name":"Yannick Hanfmann"}],"regulators":["MR_INT"],"countryCode":"AU","discountAllowed":true,"timezone":"UTC","openDate":"2020-02-02T06:48:00.000Z","version":3148253845,"name":"Set 1 Winner","eventName":"Daniel v Hanfmann"}}]}
{"op":"mcm","clk":"1004287082","pt":1580625716763,"mc":[{"id":"1.168186839","marketDefinition":{"bspMarket":false,"turnInPlayEnabled":true,"persistenceEnabled":true,"marketBaseRate":5.0,"eventId":"29680287","eventTypeId":"2","numberOfWinners":1,"bettingType":"ODDS","marketType":"SET_WINNER","marketTime":"2020-02-02T06:37:00.000Z","suspendTime":"2020-02-02T06:37:00.000Z","bspReconciled":false,"complete":true,"inPlay":false,"crossMatching":true,"runnersVoidable":false,"numberOfActiveRunners":2,"betDelay":0,"status":"OPEN","runners":[{"status":"ACTIVE","sortPriority":1,"id":8173434,"name":"Taro Daniel"},{"status":"ACTIVE","sortPriority":2,"id":8639275,"name":"Yannick Hanfmann"}],"regulators":["MR_INT"],"countryCode":"AU","discountAllowed":true,"timezone":"UTC","openDate":"2020-02-02T06:37:00.000Z","version":3148253845,"name":"Set 1 Winner","eventName":"Daniel v Hanfmann"}}]}
{"op":"mcm","clk":"1004295533","pt":1580626084688,"mc":[{"id":"1.168186839","marketDefinition":{"bspMarket":false,"turnInPlayEnabled":true,"persistenceEnabled":true,"marketBaseRate":5.0,"eventId":"29680287","eventTypeId":"2","numberOfWinners":1,"bettingType":"ODDS","marketType":"SET_WINNER","marketTime":"2020-02-02T06:37:00.000Z","suspendTime":"2020-02-02T06:37:00.000Z","bspReconciled":false,"complete":true,"inPlay":false,"crossMatching":true,"runnersVoidable":false,"numberOfActiveRunners":2,"betDelay":0,"status":"OPEN","runners":[{"status":"ACTIVE","sortPriority":1,"id":8173434,"name":"Taro Daniel"},{"status":"ACTIVE","sortPriority":2,"id":8639275,"name":"Yannick Hanfmann"}],"regulators":["MR_INT"],"countryCode":"AU","discountAllowed":true,"timezone":"UTC","openDate":"2020-02-02T06:37:00.000Z","version":3148253845,"name":"Set 1 Winner","eventName":"Daniel v Hanfmann"},"rc":[{"batb":[[2,1.83,2.02]],"ltp":0.0,"tv":0.0,"id":8639275},{"batb":[[0,1.93,2.02],[1,1.91,2.02],[2,1.9,166.67]],"ltp":2.04,"tv":25.99,"id":8173434}]}]}
{"op":"mcm","clk":"1004295537","pt":1580626084788,"mc":[{"id":"1.168186839","marketDefinition":{"bspMarket":false,"turnInPlayEnabled":true,"persistenceEnabled":true,"marketBaseRate":5.0,"eventId":"29680287","eventTypeId":"2","numberOfWinners":1,"bettingType":"ODDS","marketType":"SET_WINNER","marketTime":"2020-02-02T06:37:00.000Z","suspendTime":"2020-02-02T06:37:00.000Z","bspReconciled":false,"complete":true,"inPlay":true,"crossMatching":true,"runnersVoidable":false,"numberOfActiveRunners":2,"betDelay":3,"status":"OPEN","runners":[{"status":"ACTIVE","sortPriority":1,"id":8173434,"name":"Taro Daniel"},{"status":"ACTIVE","sortPriority":2,"id":8639275,"name":"Yannick Hanfmann"}],"regulators":["MR_INT"],"countryCode":"AU","discountAllowed":true,"timezone":"UTC","openDate":"2020-02-02T06:37:00.000Z","version":3148255380,"name":"Set 1 Winner","eventName":"Daniel v Hanfmann"},"rc":[{"batb":[[0,1.01,10.52],[1,1.85,0],[2,1.83,0]],"ltp":0.0,"tv":0.0,"id":8639275},{"batb":[[0,1.01,10.52],[1,1.91,0],[2,1.9,0]],"ltp":2.04,"tv":25.99,"id":8173434}]}]}
{"op":"mcm","clk":"1004296060","pt":1580626109100,"mc":[{"id":"1.168186839","rc":[{"batb":[[0,1.7,266.77],[1,1.68,446.84],[2,1.01,10.52]],"batl":[[0,2.06,225.02],[1,2.08,230.7]],"ltp":0.0,"tv":0.0,"id":8639275}]}]}
{"op":"mcm","clk":"1004296187","pt":1580626115286,"mc":[{"id":"1.168186839","rc":[{"batb":[[0,1.01,10.52],[1,1.68,0],[2,1.01,0]],"ltp":0.0,"tv":0.0,"id":8639275}]}]}
{"op":"mcm","clk":"1004296272","pt":1580626118669,"mc":[{"id":"1.168186839","rc":[{"batb":[[0,1.94,286.66],[1,1.92,287.63],[2,1.01,10.52]],"batl":[[0,2.04,369.96],[1,2.06,237.28]],"ltp":2.04,"tv":25.99,"id":8173434}]}]}
{"op":"mcm","clk":"1004296289","pt":1580626119281,"mc":[{"id":"1.168186839","rc":[{"batb":[[0,1.94,32.42],[1,1.8,41.47],[2,1.01,10.52]],"ltp":0.0,"tv":0.0,"id":8639275},{"batb":[[0,1.95,62.95],[1,1.94,286.66],[2,1.92,287.63]],"ltp":2.04,"tv":25.99,"id":8173434}]}]}
{"op":"mcm","clk":"1004296563","pt":1580626129620,"mc":[{"id":"1.168186839","rc":[{"batb":[[1,1.88,35.25],[2,1.01,10.52]],"ltp":2.04,"tv":25.99,"id":8173434}]}]}
{"op":"mcm","clk":"1004296590","pt":1580626130693,"mc":[{"id":"1.168186839","rc":[{"batb":[[0,1.8,41.47],[1,1.01,10.52],[2,1.01,0]],"ltp":0.0,"tv":0.0,"id":8639275},{"batb":[[0,1.88,35.25],[1,1.01,10.52],[2,1.01,0]],"ltp":2.04,"tv":25.99,"id":8173434}]}]}
{"op":"mcm","clk":"1004296633","pt":1580626132638,"mc":[{"id":"1.168186839","rc":[{"batb":[[1,1.86,239.09],[2,1.84,329.17]],"batl":[[0,2.22,276.87],[1,2.24,187.1]],"ltp":2.04,"tv":25.99,"id":8173434}]}]}
{"op":"mcm","clk":"1004297068","pt":1580626149618,"mc":[{"id":"1.168186839","rc":[{"batl":[[0,1.94,285.66],[1,1.96,274.85]],"ltp":2.04,"tv":25.99,"id":8173434}]}]}
{"op":"mcm","clk":"1004297097","pt":1580626150543,"mc":[{"id":"1.168186839","rc":[{"batb":[[0,2,57.83],[1,1.9,34.38],[2,1.01,10.52]],"ltp":0.0,"tv":0.0,"id":8639275},{"batb":[[2,1.84,367.17]],"ltp":2.04,"tv":25.99,"id":8173434}]}]}
{"op":"mcm","clk":"1004297492","pt":1580626166357,"mc":[{"id":"1.168186839","rc":[{"batb":[[1,1.84,38],[2,1.01,10.52]],"ltp":2.04,"tv":25.99,"id":8173434}]}]}
{"op":"mcm","clk":"1004297511","pt":1580626167587,"mc":[{"id":"1.168186839","rc":[{"batb":[[0,1.9,34.38],[1,1.01,10.52],[2,1.01,0]],"ltp":0.0,"tv":0.0,"id":8639275},{"batb":[[0,1.84,38],[1,1.01,10.52],[2,1.01,0]],"ltp":2.04,"tv":25.99,"id":8173434}]}]}
{"op":"mcm","clk":"1004297535","pt":1580626168667,"mc":[{"id":"1.168186839","rc":[{"batb":[[0,1.85,277.98],[1,1.84,38],[2,1.83,335.28]],"batl":[[0,1.93,265.31],[1,1.95,279.33]],"ltp":2.04,"tv":25.99,"id":8173434}]}]}
{"op":"mcm","clk":"1004297541","pt":1580626168975,"mc":[{"id":"1.168186839","rc":[{"batb":[[0,1.84,38],[1,1.01,10.52],[2,1.83,0]],"ltp":2.04,"tv":25.99,"id":8173434}]}]}
{"op":"mcm","clk":"1004297612","pt":1580626170670,"mc":[{"id":"1.168186839","rc":[{"batb":[[0,1.91,33.83],[1,1.9,34.38],[2,1.01,10.52]],"ltp":0.0,"tv":0.0,"id":8639275},{"batb":[[1,1.83,38.63],[2,1.8,268.52]],"batl":[[0,2.04,263.03],[1,2.06,237.39]],"ltp":2.04,"tv":25.99,"id":8173434}]}]}
{"op":"mcm","clk":"1004297616","pt":1580626170773,"mc":[{"id":"1.168186839","rc":[{"batb":[[1,1.01,10.52],[2,1.01,0]],"ltp":0.0,"tv":0.0,"id":8639275},{"batb":[[0,1.83,38.63],[1,1.8,268.52],[2,1.78,367.19]],"ltp":2.04,"tv":25.99,"id":8173434}]}]}
{"op":"mcm","clk":"1004298405","pt":1580626195611,"mc":[{"id":"1.168186839","rc":[{"batb":[[1,1.01,10.52],[2,1.78,0]],"ltp":2.04,"tv":25.99,"id":8173434}]}]}
{"op":"mcm","clk":"1004298517","pt":1580626198685,"mc":[{"id":"1.168186839","rc":[{"batb":[[0,1.95,258.33],[1,1.93,283.11],[2,1.83,38.63]],"ltp":2.04,"tv":25.99,"id":8173434}]}]}
{"op":"mcm","clk":"1004298549","pt":1580626199604,"mc":[{"id":"1.168186839","rc":[{"batb":[[1,1.74,45.71],[2,1.01,10.52]],"ltp":0.0,"tv":0.0,"id":8639275},{"batb":[[0,1.98,60.35],[1,1.95,258.33],[2,1.93,283.11]],"ltp":2.04,"tv":25.99,"id":8173434}]}]}
{"op":"mcm","clk":"1004299292","pt":1580626219649,"mc":[{"id":"1.168186839","rc":[{"batb":[[0,1.74,45.71],[1,1.01,10.52],[2,1.01,0]],"ltp":0.0,"tv":0.0,"id":8639275},{"batb":[[0,1.9,34.38],[1,1.01,10.52],[2,1.93,0]],"ltp":2.04,"tv":25.99,"id":8173434}]}]}
{"op":"mcm","clk":"1004299378","pt":1580626222667,"mc":[{"id":"1.168186839","rc":[{"batb":[[0,1.75,45.16],[1,1.74,45.71],[2,1.01,10.52]],"ltp":0.0,"tv":0.0,"id":8639275},{"batb":[[1,1.89,34.78],[2,1.85,262.67]],"batl":[[0,2.26,184.28],[1,2.28,178.06]],"ltp":2.04,"tv":25.99,"id":8173434}]}]}
{"op":"mcm","clk":"1004299387","pt":1580626222872,"mc":[{"id":"1.168186839","rc":[{"batb":[[1,1.01,10.52],[2,1.01,0]],"ltp":0.0,"tv":0.0,"id":8639275},{"batb":[[0,1.89,34.78],[1,1.85,262.67],[2,1.83,335.27]],"ltp":2.04,"tv":25.99,"id":8173434}]}]}
{"op":"mcm","clk":"1004299616","pt":1580626230351,"mc":[{"id":"1.168186839","rc":[{"batb":[[1,1.01,10.52],[2,1.83,0]],"ltp":2.04,"tv":25.99,"id":8173434}]}]}
{"op":"mcm","clk":"1004299720","pt":1580626233538,"mc":[{"id":"1.168186839","rc":[{"batb":[[0,1.79,299.04],[1,1.77,373.95],[2,1.75,45.16]],"batl":[[0,1.87,350.83],[1,1.89,306.89]],"ltp":0.0,"tv":0.0,"id":8639275}]}]}
{"op":"mcm","clk":"1004299741","pt":1580626234256,"mc":[{"id":"1.168186839","rc":[{"batb":[[0,2.18,44.53],[1,1.99,58.85],[2,1.01,10.52]],"ltp":2.04,"tv":25.99,"id":8173434}]}]}
{"op":"mcm","clk":"1004300412","pt":1580626253680,"mc":[{"id":"1.168186839","rc":[{"batb":[[0,1.5,78.92],[1,1.01,10.52],[2,1.75,0]],"ltp":0.0,"tv":0.0,"id":8639275},{"batb":[[0,1.99,58.85],[1,1.01,10.52],[2,1.01,0]],"ltp":2.04,"tv":25.99,"id":8173434}]}]}
{"op":"mcm","clk":"1004300507","pt":1580626256303,"mc":[{"id":"1.168186839","rc":[{"batb":[[0,1.55,401.76],[1,1.54,310.23],[2,1.5,78.92]],"batl":[[0,2.06,199.53],[1,2.08,230.79]],"ltp":0.0,"tv":0.0,"id":8639275},{"batb":[[0,2,58.62]],"ltp":2.04,"tv":25.99,"id":8173434}]}]}
{"op":"mcm","clk":"1004301202","pt":1580626281138,"mc":[{"id":"1.168186839","rc":[{"batb":[[0,1.5,78.92],[1,1.01,10.52],[2,1.5,0]],"ltp":0.0,"tv":0.0,"id":8639275}]}]}
{"op":"mcm","clk":"1004301313","pt":1580626284625,"mc":[{"id":"1.168186839","rc":[{"batb":[[0,1.9,34.78],[1,1.72,47.68],[2,1.5,78.92]],"ltp":0.0,"tv":0.0,"id":8639275},{"batb":[[1,1.94,259.61],[2,1.92,287.72]],"batl":[[0,2.04,396.2],[1,2.06,237.39]],"ltp":2.04,"tv":25.99,"id":8173434}]}]}
{"op":"mcm","clk":"1004301342","pt":1580626285648,"mc":[{"id":"1.168186839","rc":[{"batb":[[2,1.01,10.52]],"ltp":0.0,"tv":0.0,"id":8639275}]}]}
{"op":"mcm","clk":"1004301377","pt":1580626287748,"mc":[{"id":"1.168186839","rc":[{"batb":[[2,1.65,686.73]],"ltp":0.0,"tv":0.0,"id":8639275}]}]}
{"op":"mcm","clk":"1004301777","pt":1580626301665,"mc":[{"id":"1.168186839","rc":[{"batb":[[2,1.01,10.52]],"ltp":0.0,"tv":0.0,"id":8639275},{"batb":[[1,1.9,33.99],[2,1.01,10.52]],"ltp":2.04,"tv":25.99,"id":8173434}]}]}
{"op":"mcm","clk":"1004301781","pt":1580626301766,"mc":[{"id":"1.168186839","rc":[{"batb":[[0,1.72,47.68],[1,1.01,10.52],[2,1.01,0]],"ltp":0.0,"tv":0.0,"id":8639275},{"batb":[[0,1.9,33.99],[1,1.01,10.52],[2,1.01,0]],"ltp":2.04,"tv":25.99,"id":8173434}]}]}
{"op":"mcm","clk":"1004301860","pt":1580626304586,"mc":[{"id":"1.168186839","rc":[{"batb":[[1,1.83,226.26],[2,1.81,347.44]],"batl":[[0,2.28,191.45],[1,2.3,173.82]],"ltp":2.04,"tv":25.99,"id":8173434}]}]}
{"op":"mcm","clk":"1004301882","pt":1580626305461,"mc":[{"id":"1.168186839","rc":[{"batb":[[1,1.01,10.52],[2,1.81,0]],"ltp":2.04,"tv":25.99,"id":8173434}]}]}
{"op":"mcm","clk":"1004301985","pt":1580626308588,"mc":[{"id":"1.168186839","rc":[{"batb":[[0,1.93,274.11],[1,1.91,292.47],[2,1.72,47.68]],"batl":[[0,2.02,276.57],[1,2.04,244.17]],"ltp":0.0,"tv":0.0,"id":8639275}]}]}
{"op":"mcm","clk":"1004302099","pt":1580626312182,"mc":[{"id":"1.168186839","rc":[{"batb":[[0,1.72,47.68],[1,1.01,10.52],[2,1.72,0]],"ltp":0.0,"tv":0.0,"id":8639275}]}]}
{"op":"mcm","clk":"1004302252","pt":1580626316397,"mc":[{"id":"1.168186839","rc":[{"batb":[[0,1.78,283.06],[1,1.76,380.97],[2,1.72,47.68]],"batl":[[0,2.22,320.14],[1,2.24,187.3]],"ltp":0.0,"tv":0.0,"id":8639275}]}]}
{"op":"mcm","clk":"1004302338","pt":1580626318398,"mc":[{"id":"1.168186839","rc":[{"batb":[[0,1.72,47.68],[1,1.01,10.52],[2,1.72,0]],"ltp":0.0,"tv":0.0,"id":8639275}]}]}
{"op":"mcm","clk":"1004302451","pt":1580626321692,"mc":[{"id":"1.168186839","rc":[{"batb":[[0,1.99,60.03],[1,1.91,34.31],[2,1.01,10.52]],"ltp":0.0,"tv":0.0,"id":8639275},{"trd":[[1.9,67.98]],"batb":[[0,1.83,212.04],[1,1.81,347.43],[2,1.72,46.89]],"ltp":1.9,"tv":93.97,"id":8173434}],"tv":93.97}]}
{"op":"mcm","clk":"1004302557","pt":1580626324517,"mc":[{"id":"1.168186839","rc":[{"batl":[[0,1.91,349.33],[1,1.93,288.12]],"ltp":1.9,"tv":93.97,"id":8173434}]}]}
{"op":"mcm","clk":"1004302569","pt":1580626324824,"mc":[{"id":"1.168186839","rc":[{"batb":[[2,1.74,404.28]],"ltp":0.0,"tv":0.0,"id":8639275}]}]}
{"op":"mcm","clk":"1004302720","pt":1580626329591,"mc":[{"id":"1.168186839","rc":[{"batb":[[0,2.02,59.09],[1,1.99,60.03],[2,1.94,33.75]],"ltp":0.0,"tv":0.0,"id":8639275},{"batb":[[0,1.89,34.54],[1,1.83,212.04],[2,1.81,347.43]],"ltp":1.9,"tv":93.97,"id":8173434}]}]}
{"op":"mcm","clk":"1004302750","pt":1580626330612,"mc":[{"id":"1.168186839","rc":[{"batb":[[1,1.94,33.75],[2,1.74,404.28]],"ltp":0.0,"tv":0.0,"id":8639275},{"batb":[[1,1.84,21.97],[2,1.83,212.04]],"ltp":1.9,"tv":93.97,"id":8173434}]}]}
{"op":"mcm","clk":"1004303712","pt":1580626358250,"mc":[{"id":"1.168186839","rc":[{"batb":[[1,1.71,47.6],[2,1.52,425.49]],"ltp":1.9,"tv":93.97,"id":8173434}]}]}
{"op":"mcm","clk":"1004303810","pt":1580626360663,"mc":[{"id":"1.168186839","rc":[{"batl":[[0,2.08,18.36]],"ltp":0.0,"tv":0.0,"id":8639275}]}]}
{"op":"mcm","clk":"1004303850","pt":1580626361643,"mc":[{"id":"1.168186839","rc":[{"batb":[[2,1.66,433.3]],"batl":[[0,2.02,263.3],[1,2.04,244.24]],"ltp":1.9,"tv":93.97,"id":8173434}]}]}
{"op":"mcm","clk":"1004304518","pt":1580626378491,"mc":[{"id":"1.168186839","rc":[{"batb":[[0,1.94,33.75],[1,1.74,404.28],[2,1.01,10.52]],"ltp":0.0,"tv":0.0,"id":8639275},{"batb":[[0,1.71,47.6],[1,1.66,433.3],[2,1.65,240.41]],"ltp":1.9,"tv":93.97,"id":8173434}]}]}
{"op":"mcm","clk":"1004304742","pt":1580626384615,"mc":[{"id":"1.168186839","rc":[{"batb":[[1,1.52,425.49],[2,1.01,10.52]],"ltp":1.9,"tv":93.97,"id":8173434}]}]}
{"op":"mcm","clk":"1004304807","pt":1580626386522,"mc":[{"id":"1.168186839","rc":[{"batb":[[1,1.01,10.52],[2,1.01,0]],"ltp":1.9,"tv":93.97,"id":8173434}]}]}
{"op":"mcm","clk":"1004304838","pt":1580626387297,"mc":[{"id":"1.168186839","rc":[{"batb":[[0,1.93,288.17],[1,1.91,292.47],[2,1.71,47.6]],"ltp":1.9,"tv":93.97,"id":8173434}]}]}
{"op":"mcm","clk":"1004304876","pt":1580626388322,"mc":[{"id":"1.168186839","rc":[{"batb":[[1,1.87,38],[2,1.74,404.28]],"ltp":0.0,"tv":0.0,"id":8639275},{"batb":[[0,1.98,60.51],[1,1.93,288.17],[2,1.91,292.47]],"ltp":1.9,"tv":93.97,"id":8173434}]}]}
{"op":"mcm","clk":"1004305248","pt":1580626398117,"mc":[{"id":"1.168186839","rc":[{"batb":[[0,1.87,38],[1,1.74,404.28],[2,1.01,10.52]],"ltp":0.0,"tv":0.0,"id":8639275},{"batb":[[0,1.83,38.63],[1,1.58,416.47],[2,1.01,10.52]],"ltp":1.9,"tv":93.97,"id":8173434}]}]}
{"op":"mcm","clk":"1004305376","pt":1580626401617,"mc":[{"id":"1.168186839","rc":[{"batb":[[0,1.88,37.53]],"ltp":0.0,"tv":0.0,"id":8639275},{"batb":[[0,1.83,38.32],[1,1.79,227.82],[2,1.77,374.07]],"batl":[[0,2.12,268.05],[1,2.14,212.71]],"ltp":1.9,"tv":93.97,"id":8173434}]}]}
{"op":"mcm","clk":"1004305511","pt":1580626404150,"mc":[{"id":"1.168186839","rc":[{"batb":[[1,1.58,416.47],[2,1.01,10.52]],"ltp":1.9,"tv":93.97,"id":8173434}]}]}
{"op":"mcm","clk":"1004305600","pt":1580626406629,"mc":[{"id":"1.168186839","rc":[{"batb":[[1,1.01,10.52],[2,1.01,0]],"ltp":1.9,"tv":93.97,"id":8173434}]}]}
{"op":"mcm","clk":"1004305645","pt":1580626407663,"mc":[{"id":"1.168186839","rc":[{"batb":[[0,1.89,346.45],[1,1.88,37.53],[2,1.87,312.73]],"batl":[[0,1.98,269.89],[1,2,258.8]],"ltp":0.0,"tv":0.0,"id":8639275},{"batb":[[0,2.04,54.29],[1,1.93,32.42],[2,1.83,38.32]],"ltp":1.9,"tv":93.97,"id":8173434}]}]}
{"op":"mcm","clk":"1004305665","pt":1580626408235,"mc":[{"id":"1.168186839","rc":[{"batb":[[2,1.01,10.52]],"ltp":1.9,"tv":93.97,"id":8173434}]}]}
{"op":"mcm","clk":"1004305792","pt":1580626410653,"mc":[{"id":"1.168186839","rc":[{"batb":[[2,1.67,409.76]],"ltp":1.9,"tv":93.97,"id":8173434}]}]}
{"op":"mcm","clk":"1004306216","pt":1580626421464,"mc":[{"id":"1.168186839","rc":[{"batb":[[0,1.83,40.6],[1,1.58,416.47],[2,1.01,10.52]],"ltp":0.0,"tv":0.0,"id":8639275},{"batb":[[0,1.93,32.42],[1,1.67,409.76],[2,1.01,10.52]],"ltp":1.9,"tv":93.97,"id":8173434}]}]}
{"op":"mcm","clk":"1004306319","pt":1580626424446,"mc":[{"id":"1.168186839","rc":[{"batb":[[0,1.84,316.47],[1,1.83,40.6],[2,1.82,341.19]],"batl":[[0,2.1,296.56],[1,2.12,218.53]],"ltp":0.0,"tv":0.0,"id":8639275}]}]}
{"op":"mcm","clk":"1004306382","pt":1580626426455,"mc":[{"id":"1.168186839","rc":[{"batb":[[0,1.84,219.32]],"ltp":0.0,"tv":0.0,"id":8639275}]}]}
{"op":"mcm","clk":"1004306474","pt":1580626429179,"mc":[{"id":"1.168186839","rc":[{"batl":[[0,2.1,382.26]],"ltp":0.0,"tv":0.0,"id":8639275}]}]}
{"op":"mcm","clk":"1004306606","pt":1580626433560,"mc":[{"id":"1.168186839","rc":[{"batb":[[0,1.83,40.6],[1,1.58,416.47],[2,1.01,10.52]],"ltp":0.0,"tv":0.0,"id":8639275}]}]}
{"op":"mcm","clk":"1004306643","pt":1580626434688,"mc":[{"id":"1.168186839","rc":[{"batb":[[1,1.01,10.52],[2,1.01,0]],"ltp":0.0,"tv":0.0,"id":8639275}]}]}
{"op":"mcm","clk":"1004306719","pt":1580626436661,"mc":[{"id":"1.168186839","rc":[{"batb":[[1,1.92,258.36],[2,1.9,297.43]],"batl":[[0,2.02,430.76],[1,2.04,244.28]],"ltp":1.9,"tv":93.97,"id":8173434}]}]}
{"op":"mcm","clk":"1004306761","pt":1580626437587,"mc":[{"id":"1.168186839","rc":[{"batb":[[0,1.98,31.87],[1,1.9,36.35],[2,1.86,149.68]],"ltp":0.0,"tv":0.0,"id":8639275},{"batb":[[0,1.94,32.1]],"ltp":1.9,"tv":93.97,"id":8173434}]}]}
{"op":"mcm","clk":"1004306792","pt":1580626438306,"mc":[{"id":"1.168186839","rc":[{"batb":[[2,1.67,409.76]],"ltp":0.0,"tv":0.0,"id":8639275}]}]}
{"op":"mcm","clk":"1004307246","pt":1580626451320,"mc":[{"id":"1.168186839","rc":[{"batb":[[0,1.9,36.35],[1,1.67,409.76],[2,1.01,10.52]],"ltp":0.0,"tv":0.0,"id":8639275},{"batb":[[0,1.77,43.04],[1,1.67,409.76],[2,1.01,10.52]],"ltp":1.9,"tv":93.97,"id":8173434}]}]}
{"op":"mcm","clk":"1004307363","pt":1580626454523,"mc":[{"id":"1.168186839","rc":[{"batb":[[1,1.75,320.29],[2,1.73,404.37]],"batl":[[0,2.12,194.81],[1,2.14,212.75]],"ltp":1.9,"tv":93.97,"id":8173434}]}]}
{"op":"mcm","clk":"1004307815","pt":1580626469326,"mc":[{"id":"1.168186839","rc":[{"batb":[[1,1.67,409.76],[2,1.01,10.52]],"ltp":1.9,"tv":93.97,"id":8173434}]}]}
{"op":"mcm","clk":"1004307909","pt":1580626472639,"mc":[{"id":"1.168186839","rc":[{"batb":[[1,1.89,262.12],[2,1.87,312.77]],"batl":[[0,1.97,219],[1,1.99,262.84]],"ltp":0.0,"tv":0.0,"id":8639275},{"batb":[[0,1.78,654.39],[1,1.77,43.04],[2,1.67,409.76]],"ltp":1.9,"tv":93.97,"id":8173434}]}]}
{"op":"mcm","clk":"1004307949","pt":1580626473362,"mc":[{"id":"1.168186839","rc":[{"batb":[[0,2.02,56.1],[1,1.92,32.97]],"ltp":1.9,"tv":93.97,"id":8173434}]}]}
{"op":"mcm","clk":"1004308594","pt":1580626491684,"mc":[{"id":"1.168186839","rc":[{"batb":[[0,1.85,39.26],[1,1.67,409.76],[2,1.01,10.52]],"ltp":0.0,"tv":0.0,"id":8639275},{"batb":[[0,1.92,32.97],[1,1.67,409.76],[2,1.01,10.52]],"ltp":1.9,"tv":93.97,"id":8173434}]}]}
{"op":"mcm","clk":"1004308677","pt":1580626494566,"mc":[{"id":"1.168186839","rc":[{"batb":[[1,1.84,275.09],[2,1.82,341.3]],"batl":[[0,2.08,226.9],[1,2.1,224.59]],"ltp":0.0,"tv":0.0,"id":8639275},{"batb":[[0,1.93,32.65]],"ltp":1.9,"tv":93.97,"id":8173434}]}]}
{"op":"mcm","clk":"1004308874","pt":1580626500163,"mc":[{"id":"1.168186839","rc":[{"batb":[[1,1.67,409.76],[2,1.01,10.52]],"ltp":0.0,"tv":0.0,"id":8639275}]}]}
{"op":"mcm","clk":"1004309000","pt":1580626503510,"mc":[{"id":"1.168186839","rc":[{"batb":[[0,1.98,62.47],[1,1.91,35.8],[2,1.85,39.26]],"ltp":0.0,"tv":0.0,"id":8639275},{"batb":[[1,1.92,331.75],[2,1.9,297.46]],"batl":[[0,2.02,361.07],[1,2.04,244.29]],"ltp":1.9,"tv":93.97,"id":8173434}]}]}
{"op":"mcm","clk":"1004309032","pt":1580626504382,"mc":[{"id":"1.168186839","rc":[{"batb":[[2,1.86,138.54]],"ltp":0.0,"tv":0.0,"id":8639275}]}]}
{"op":"mcm","clk":"1004309723","pt":1580626522421,"mc":[{"id":"1.168186839","rc":[{"batb":[[0,1.91,35.8],[1,1.67,409.76],[2,1.01,10.52]],"ltp":0.0,"tv":0.0,"id":8639275},{"batb":[[0,1.74,45.32],[1,1.67,409.76],[2,1.01,10.52]],"ltp":1.9,"tv":93.97,"id":8173434}]}]}
{"op":"mcm","clk":"1004309815","pt":1580626524631,"mc":[{"id":"1.168186839","rc":[{"batb":[[0,1.74,274.48],[1,1.72,412.13],[2,1.67,409.76]],"batl":[[0,2.16,366.76],[1,2.18,202.04]],"ltp":1.9,"tv":93.97,"id":8173434}]}]}
{"op":"mcm","clk":"1004310019","pt":1580626529531,"mc":[{"id":"1.168186839","rc":[{"batb":[[0,1.74,45.32],[1,1.67,409.76],[2,1.01,10.52]],"ltp":1.9,"tv":93.97,"id":8173434}]}]}
{"op":"mcm","clk":"1004310140","pt":1580626532511,"mc":[{"id":"1.168186839","rc":[{"batb":[[1,1.87,297.54],[2,1.85,323.74]],"batl":[[0,1.95,214.97],[1,1.97,270.89]],"ltp":0.0,"tv":0.0,"id":8639275},{"batb":[[0,2.02,56.89],[1,1.92,33.13],[2,1.67,409.76]],"ltp":1.9,"tv":93.97,"id":8173434}]}]}
{"op":"mcm","clk":"1004310867","pt":1580626552471,"mc":[{"id":"1.168186839","rc":[{"trd":[[1.95,27.12]],"batl":[[0,1.95,187.85]],"ltp":1.95,"tv":27.12,"id":8639275},{"trd":[[2.04,45.18]],"ltp":2.04,"tv":119.9,"id":8173434}],"tv":147.02}]}
{"op":"mcm","clk":"1004311202","pt":1580626559470,"mc":[{"id":"1.168186839","rc":[{"batb":[[0,1.71,50.36],[1,1.67,409.76],[2,1.01,10.52]],"ltp":1.95,"tv":27.12,"id":8639275},{"batb":[[0,1.92,32.81],[1,1.67,409.76],[2,1.01,10.52]],"ltp":2.04,"tv":119.9,"id":8173434}]}]}
{"op":"mcm","clk":"1004311300","pt":1580626562456,"mc":[{"id":"1.168186839","rc":[{"batb":[[1,1.69,428.52],[2,1.67,867.04]],"batl":[[0,2.08,194.86],[1,2.1,224.55]],"ltp":1.95,"tv":27.12,"id":8639275}]}]}
{"op":"mcm","clk":"1004311346","pt":1580626563693,"mc":[{"id":"1.168186839","rc":[{"batb":[[1,1.67,409.76],[2,1.01,10.52]],"ltp":1.95,"tv":27.12,"id":8639275}]}]}
{"op":"mcm","clk":"1004311456","pt":1580626566687,"mc":[{"id":"1.168186839","rc":[{"batb":[[0,1.83,346.21],[1,1.81,347.59],[2,1.71,50.36]],"batl":[[0,1.91,233.58],[1,1.93,288.17]],"ltp":1.95,"tv":27.12,"id":8639275}]}]}
{"op":"mcm","clk":"1004311560","pt":1580626570699,"mc":[{"id":"1.168186839","rc":[{"batb":[[0,1.71,50.36],[1,1.67,409.76],[2,1.01,10.52]],"ltp":1.95,"tv":27.12,"id":8639275}]}]}
{"op":"mcm","clk":"1004311777","pt":1580626573699,"mc":[{"id":"1.168186839","rc":[{"batb":[[1,1.69,428.88],[2,1.67,867.04]],"batl":[[0,2.08,194.57],[1,2.1,224.55]],"ltp":1.95,"tv":27.12,"id":8639275}]}]}
{"op":"mcm","clk":"1004311859","pt":1580626576065,"mc":[{"id":"1.168186839","rc":[{"batb":[[1,1.67,409.76],[2,1.01,10.52]],"ltp":1.95,"tv":27.12,"id":8639275}]}]}
{"op":"mcm","clk":"1004311922","pt":1580626578684,"mc":[{"id":"1.168186839","rc":[{"batb":[[0,1.92,329.52],[1,1.9,297.42],[2,1.67,409.76]],"batl":[[0,2.02,394.24],[1,2.04,244.27]],"ltp":2.04,"tv":119.9,"id":8173434}]}]}
{"op":"mcm","clk":"1004311950","pt":1580626579505,"mc":[{"id":"1.168186839","rc":[{"batb":[[0,1.98,62.24],[1,1.84,40.21],[2,1.71,50.36]],"ltp":1.95,"tv":27.12,"id":8639275},{"batb":[[2,1.85,36.9]],"ltp":2.04,"tv":119.9,"id":8173434}]}]}
{"op":"mcm","clk":"1004311982","pt":1580626580603,"mc":[{"id":"1.168186839","rc":[{"batb":[[2,1.67,409.76]],"ltp":1.95,"tv":27.12,"id":8639275}]}]}
{"op":"mcm","clk":"1004312644","pt":1580626594501,"mc":[{"id":"1.168186839","rc":[{"batb":[[0,1.84,40.21],[1,1.67,409.76],[2,1.01,10.52]],"ltp":1.95,"tv":27.12,"id":8639275},{"batb":[[0,1.85,36.9],[1,1.67,409.76],[2,1.01,10.52]],"ltp":2.04,"tv":119.9,"id":8173434}]}]}
{"op":"mcm","clk":"1004312771","pt":1580626599436,"mc":[{"id":"1.168186839","rc":[{"batb":[[0,1.95,333.67],[1,1.93,283.18],[2,1.85,36.9]],"batl":[[0,2.04,191.25],[1,2.06,237.42]],"ltp":2.04,"tv":119.9,"id":8173434}]}]}
{"op":"mcm","clk":"1004312933","pt":1580626604538,"mc":[{"id":"1.168186839","rc":[{"batb":[[0,1.85,36.9],[1,1.67,409.76],[2,1.01,10.52]],"ltp":2.04,"tv":119.9,"id":8173434}]}]}
{"op":"mcm","clk":"1004313021","pt":1580626607434,"mc":[{"id":"1.168186839","rc":[{"batb":[[1,1.83,360.03],[2,1.81,347.68]],"batl":[[0,2.2,195.29],[1,2.22,191.82]],"ltp":2.04,"tv":119.9,"id":8173434}]}]}
{"op":"mcm","clk":"1004313385","pt":1580626618646,"mc":[{"id":"1.168186839","rc":[{"batb":[[1,1.01,10.52],[2,1.01,0]],"ltp":1.95,"tv":27.12,"id":8639275}]}]}
{"op":"mcm","clk":"1004313417","pt":1580626619472,"mc":[{"id":"1.168186839","rc":[{"batl":[[0,1.91,220.73],[1,1.93,288.27]],"ltp":2.04,"tv":119.9,"id":8173434}]}]}
{"op":"mcm","clk":"1004313444","pt":1580626620243,"mc":[{"id":"1.168186839","rc":[{"batb":[[0,2.06,55.23],[1,1.96,33.05],[2,1.01,10.52]],"ltp":1.95,"tv":27.12,"id":8639275},{"batb":[[2,1.81,387.65]],"ltp":2.04,"tv":119.9,"id":8173434}]}]}
{"op":"mcm","clk":"1004313484","pt":1580626621642,"mc":[{"id":"1.168186839","rc":[{"batb":[[2,1.74,404.28]],"ltp":1.95,"tv":27.12,"id":8639275}]}]}
{"op":"mcm","clk":"1004313992","pt":1580626636482,"mc":[{"id":"1.168186839","rc":[{"batb":[[0,1.96,33.05],[1,1.74,404.28],[2,1.01,10.52]],"ltp":1.95,"tv":27.12,"id":8639275},{"batb":[[0,1.81,39.97],[1,1.52,425.49],[2,1.01,10.52]],"ltp":2.04,"tv":119.9,"id":8173434}]}]}
{"op":"mcm","clk":"1004314198","pt":1580626642294,"mc":[{"id":"1.168186839","rc":[{"batb":[[0,1.85,350.68],[1,1.83,335.41],[2,1.81,39.97]],"batl":[[0,1.94,336.28],[1,1.96,275]],"ltp":2.04,"tv":119.9,"id":8173434}]}]}
{"op":"mcm","clk":"1004314356","pt":1580626647692,"mc":[{"id":"1.168186839","rc":[{"batb":[[0,1.81,39.97],[1,1.52,425.49],[2,1.01,10.52]],"ltp":2.04,"tv":119.9,"id":8173434}]}]}
{"op":"mcm","clk":"1004314439","pt":1580626650418,"mc":[{"id":"1.168186839","rc":[{"batb":[[1,1.78,324.75],[2,1.76,381.45]],"batl":[[0,2.04,415.16],[1,2.06,237.43]],"ltp":2.04,"tv":119.9,"id":8173434}]}]}
{"op":"mcm","clk":"1004314581","pt":1580626655740,"mc":[{"id":"1.168186839","rc":[{"batb":[[1,1.52,425.49],[2,1.01,10.52]],"ltp":2.04,"tv":119.9,"id":8173434}]}]}
{"op":"mcm","clk":"1004314624","pt":1580626657441,"mc":[{"id":"1.168186839","rc":[{"batb":[[1,1.01,10.52],[2,1.01,0]],"ltp":2.04,"tv":119.9,"id":8173434}]}]}
{"op":"mcm","clk":"1004314665","pt":1580626658624,"mc":[{"id":"1.168186839","rc":[{"batb":[[0,1.94,239.97],[1,1.92,287.79],[2,1.81,39.97]],"ltp":2.04,"tv":119.9,"id":8173434}]}]}
{"op":"mcm","clk":"1004314693","pt":1580626659651,"mc":[{"id":"1.168186839","rc":[{"batb":[[1,1.77,45.16],[2,1.74,404.28]],"ltp":1.95,"tv":27.12,"id":8639275},{"batb":[[0,1.96,61.84],[1,1.94,239.97],[2,1.92,287.79]],"ltp":2.04,"tv":119.9,"id":8173434}]}]}
{"op":"mcm","clk":"1004315335","pt":1580626678678,"mc":[{"id":"1.168186839","rc":[{"batb":[[0,1.77,45.16],[1,1.74,404.28],[2,1.01,10.52]],"ltp":1.95,"tv":27.12,"id":8639275},{"batb":[[0,1.87,35.56],[1,1.58,416.47],[2,1.01,10.52]],"ltp":2.04,"tv":119.9,"id":8173434}]}]}
{"op":"mcm","clk":"1004315440","pt":1580626681498,"mc":[{"id":"1.168186839","rc":[{"batb":[[1,1.83,313.7],[2,1.81,347.59]],"batl":[[0,2.28,333.15],[1,2.3,174.16]],"ltp":2.04,"tv":119.9,"id":8173434}]}]}
{"op":"mcm","clk":"1004315452","pt":1580626681858,"mc":[{"id":"1.168186839","rc":[{"batb":[[1,1.58,416.47],[2,1.01,10.52]],"ltp":2.04,"tv":119.9,"id":8173434}]}]}
{"op":"mcm","clk":"1004315491","pt":1580626683498,"mc":[{"id":"1.168186839","rc":[{"batb":[[1,1.01,10.52],[2,1.01,0]],"ltp":1.95,"tv":27.12,"id":8639275},{"batb":[[1,1.01,10.52],[2,1.01,0]],"ltp":2.04,"tv":119.9,"id":8173434}]}]}
{"op":"mcm","clk":"1004315557","pt":1580626685602,"mc":[{"id":"1.168186839","rc":[{"batb":[[0,1.93,323.17],[1,1.91,292.57],[2,1.77,45.16]],"batl":[[0,2.02,230.13],[1,2.04,244.26]],"ltp":1.95,"tv":27.12,"id":8639275}]}]}
{"op":"mcm","clk":"1004315611","pt":1580626687290,"mc":[{"id":"1.168186839","rc":[{"batb":[[1,1.62,415.43],[2,1.01,10.52]],"ltp":2.04,"tv":119.9,"id":8173434}]}]}
{"op":"mcm","clk":"1004315672","pt":1580626688986,"mc":[{"id":"1.168186839","rc":[{"batb":[[0,1.77,45.16],[1,1.62,415.43],[2,1.01,10.52]],"ltp":1.95,"tv":27.12,"id":8639275}]}]}
{"op":"mcm","clk":"1004315837","pt":1580626694474,"mc":[{"id":"1.168186839","rc":[{"batb":[[1,1.01,10.52],[2,1.01,0]],"ltp":1.95,"tv":27.12,"id":8639275}]}]}
{"op":"mcm","clk":"1004315872","pt":1580626695602,"mc":[{"id":"1.168186839","rc":[{"batb":[[1,1.83,313.1],[2,1.81,347.59]],"batl":[[0,1.91,265.41],[1,1.93,288.21]],"ltp":2.04,"tv":119.9,"id":8173434}]}]}
{"op":"mcm","clk":"1004315905","pt":1580626696588,"mc":[{"id":"1.168186839","rc":[{"batb":[[0,2.04,57.28],[1,1.93,34.38],[2,1.01,10.52]],"ltp":1.95,"tv":27.12,"id":8639275},{"batb":[[1,1.83,351.5]],"ltp":2.04,"tv":119.9,"id":8173434}]}]}
{"op":"mcm","clk":"1004315953","pt":1580626698281,"mc":[{"id":"1.168186839","rc":[{"batb":[[2,1.7,409.32]],"ltp":1.95,"tv":27.12,"id":8639275}]}]}
{"op":"mcm","clk":"1004316412","pt":1580626715305,"mc":[{"id":"1.168186839","rc":[{"batb":[[0,1.93,34.38],[1,1.7,409.32],[2,1.01,10.52]],"ltp":1.95,"tv":27.12,"id":8639275},{"batb":[[0,1.83,38.4],[1,1.62,415.43],[2,1.01,10.52]],"ltp":2.04,"tv":119.9,"id":8173434}]}]}
{"op":"mcm","clk":"1004316497","pt":1580626718343,"mc":[{"id":"1.168186839","rc":[{"batb":[[1,1.78,334.85],[2,1.76,381.53]],"batl":[[0,2.02,298.81],[1,2.04,244.28]],"ltp":2.04,"tv":119.9,"id":8173434}]}]}
{"op":"mcm","clk":"1004316526","pt":1580626719523,"mc":[{"id":"1.168186839","rc":[{"batb":[[1,1.62,415.43],[2,1.01,10.52]],"ltp":2.04,"tv":119.9,"id":8173434}]}]}
{"op":"mcm","clk":"1004316597","pt":1580626722644,"mc":[{"id":"1.168186839","rc":[{"batb":[[0,1.85,285.88],[1,1.83,373.72],[2,1.62,415.43]],"batl":[[0,1.93,257.87],[1,1.95,279.36]],"ltp":2.04,"tv":119.9,"id":8173434}]}]}
{"op":"mcm","clk":"1004316641","pt":1580626725562,"mc":[{"id":"1.168186839","rc":[{"batb":[[0,1.83,38.4],[1,1.62,415.43],[2,1.01,10.52]],"ltp":2.04,"tv":119.9,"id":8173434}]}]}
{"op":"mcm","clk":"1004316727","pt":1580626729253,"mc":[{"id":"1.168186839","rc":[{"batb":[[1,1.78,334.85],[2,1.76,381.53]],"batl":[[0,2.02,298.81],[1,2.04,244.28]],"ltp":2.04,"tv":119.9,"id":8173434}]}]}
{"op":"mcm","clk":"1004316764","pt":1580626730951,"mc":[{"id":"1.168186839","rc":[{"batb":[[1,1.62,415.43],[2,1.01,10.52]],"ltp":2.04,"tv":119.9,"id":8173434}]}]}
{"op":"mcm","clk":"1004316866","pt":1580626734652,"mc":[{"id":"1.168186839","rc":[{"batb":[[1,1.75,47.29],[2,1.7,409.32]],"ltp":1.95,"tv":27.12,"id":8639275},{"batb":[[0,1.99,59.4],[1,1.93,251.27],[2,1.91,292.54]],"ltp":2.04,"tv":119.9,"id":8173434}]}]}
{"op":"mcm","clk":"1004317362","pt":1580626753570,"mc":[{"id":"1.168186839","rc":[{"batb":[[1,1.88,35.09],[2,1.62,415.43]],"ltp":2.04,"tv":119.9,"id":8173434}]}]}
{"op":"mcm","clk":"1004317366","pt":1580626753876,"mc":[{"id":"1.168186839","rc":[{"batb":[[0,1.75,46.97],[1,1.7,409.32],[2,1.01,10.52]],"ltp":1.95,"tv":27.12,"id":8639275},{"batb":[[0,1.88,35.09],[1,1.62,415.43],[2,1.01,10.52]],"ltp":2.04,"tv":119.9,"id":8173434}]}]}
{"op":"mcm","clk":"1004317432","pt":1580626756700,"mc":[{"id":"1.168186839","rc":[{"batb":[[1,1.81,305.98],[2,1.79,360.56]],"batl":[[0,2.3,280.62],[1,2.32,170.02]],"ltp":2.04,"tv":119.9,"id":8173434}]}]}
{"op":"mcm","clk":"1004317681","pt":1580626763615,"mc":[{"id":"1.168186839","rc":[{"batl":[[0,1.89,307.75],[1,1.91,297.44]],"ltp":2.04,"tv":119.9,"id":8173434}]}]}
{"op":"mcm","clk":"1004317709","pt":1580626764499,"mc":[{"id":"1.168186839","rc":[{"batb":[[0,2.02,57.83],[1,1.95,33.6],[2,1.7,409.32]],"ltp":1.95,"tv":27.12,"id":8639275}]}]}
{"op":"mcm","clk":"1004317940","pt":1580626774631,"mc":[{"id":"1.168186839","rc":[{"batb":[[0,2.04,57.75],[1,2.02,57.83],[2,1.95,33.6]],"ltp":1.95,"tv":27.12,"id":8639275}]}]}
{"op":"mcm","clk":"1004317950","pt":1580626775405,"mc":[{"id":"1.168186839","rc":[{"batb":[[1,1.95,33.6],[2,1.7,409.32]],"ltp":1.95,"tv":27.12,"id":8639275}]}]}
{"op":"mcm","clk":"1004320396","pt":1580626842640,"mc":[{"id":"1.168186839","rc":[{"batb":[[0,1.95,33.6],[1,1.7,409.32],[2,1.01,10.52]],"ltp":1.95,"tv":27.12,"id":8639275},{"batb":[[0,1.69,49.73],[1,1.62,415.43],[2,1.01,10.52]],"ltp":2.04,"tv":119.9,"id":8173434}]}]}
{"op":"mcm","clk":"1004320500","pt":1580626846827,"mc":[{"id":"1.168186839","rc":[{"batb":[[1,1.01,10.52],[2,1.01,0]],"ltp":2.04,"tv":119.9,"id":8173434}]}]}
{"op":"mcm","clk":"1004320532","pt":1580626848532,"mc":[{"id":"1.168186839","rc":[{"batb":[[0,1.77,375.26],[1,1.75,388.98],[2,1.69,49.73]],"batl":[[0,1.85,319.7],[1,1.87,317.5]],"ltp":2.04,"tv":119.9,"id":8173434}]}]}
{"op":"mcm","clk":"1004320632","pt":1580626850678,"mc":[{"id":"1.168186839","rc":[{"batb":[[0,1.69,49.73],[1,1.52,425.49],[2,1.01,10.52]],"ltp":2.04,"tv":119.9,"id":8173434}]}]}
{"op":"mcm","clk":"1004320776","pt":1580626853768,"mc":[{"id":"1.168186839","rc":[{"batb":[[1,1.64,349.62],[2,1.63,250.87]],"batl":[[0,2.02,387.79],[1,2.04,244.24]],"ltp":2.04,"tv":119.9,"id":8173434}]}]}
{"op":"mcm","clk":"1004320898","pt":1580626855943,"mc":[{"id":"1.168186839","rc":[{"batb":[[1,1.52,425.49],[2,1.01,10.52]],"ltp":2.04,"tv":119.9,"id":8173434}]}]}
{"op":"mcm","clk":"1004321070","pt":1580626858677,"mc":[{"id":"1.168186839","rc":[{"batb":[[1,1.01,10.52],[2,1.01,0]],"ltp":2.04,"tv":119.9,"id":8173434}]}]}
{"op":"mcm","clk":"1004321142","pt":1580626859660,"mc":[{"id":"1.168186839","rc":[{"batb":[[1,1.88,37.77],[2,1.7,409.32]],"ltp":1.95,"tv":27.12,"id":8639275},{"batb":[[0,1.97,60.82],[1,1.92,303.49],[2,1.9,297.4]],"ltp":2.04,"tv":119.9,"id":8173434}]}]}
{"op":"mcm","clk":"1004321475","pt":1580626868572,"mc":[{"id":"1.168186839","rc":[{"batb":[[0,1.88,37.77],[1,1.7,409.32],[2,1.01,10.52]],"ltp":1.95,"tv":27.12,"id":8639275},{"batb":[[0,1.92,303.49],[1,1.9,297.4],[2,1.82,39.34]],"ltp":2.04,"tv":119.9,"id":8173434}]}]}
{"op":"mcm","clk":"1004321496","pt":1580626869292,"mc":[{"id":"1.168186839","rc":[{"batb":[[0,1.82,39.34],[1,1.58,416.47],[2,1.01,10.52]],"ltp":2.04,"tv":119.9,"id":8173434}]}]}
{"op":"mcm","clk":"1004321613","pt":1580626872688,"mc":[{"id":"1.168186839","rc":[{"batb":[[1,1.77,284.48],[2,1.75,388.71]],"batl":[[0,2.12,315.36],[1,2.14,212.8]],"ltp":2.04,"tv":119.9,"id":8173434}]}]}
{"op":"mcm","clk":"1004321701","pt":1580626876493,"mc":[{"id":"1.168186839","rc":[{"batb":[[1,1.01,10.52],[2,1.01,0]],"ltp":1.95,"tv":27.12,"id":8639275}]}]}
{"op":"mcm","clk":"1004321734","pt":1580626877678,"mc":[{"id":"1.168186839","rc":[{"batb":[[1,1.83,40.76],[2,1.01,10.52]],"ltp":1.95,"tv":27.12,"id":8639275},{"batb":[[0,2.04,53.9],[1,1.93,32.34],[2,1.77,284.48]],"ltp":2.04,"tv":119.9,"id":8173434}]}]}
{"op":"mcm","clk":"1004321755","pt":1580626878599,"mc":[{"id":"1.168186839","rc":[{"batb":[[2,1.01,10.52]],"ltp":2.04,"tv":119.9,"id":8173434}]}]}
{"op":"mcm","clk":"1004321787","pt":1580626879781,"mc":[{"id":"1.168186839","rc":[{"batb":[[2,1.58,416.47]],"ltp":1.95,"tv":27.12,"id":8639275},{"batb":[[2,1.67,409.76]],"ltp":2.04,"tv":119.9,"id":8173434}]}]}
{"op":"mcm","clk":"1004321815","pt":1580626881477,"mc":[{"id":"1.168186839","rc":[{"batb":[[0,1.9,244.05],[1,1.88,345.22],[2,1.83,40.76]],"batl":[[0,1.98,221.93],[1,2,258.91]],"ltp":1.95,"tv":27.12,"id":8639275}]}]}
{"op":"mcm","clk":"1004321920","pt":1580626886615,"mc":[{"id":"1.168186839","rc":[{"batb":[[0,1.88,37.77],[1,1.83,40.76],[2,1.58,416.47]],"ltp":1.95,"tv":27.12,"id":8639275}]}]}
{"op":"mcm","clk":"1004321931","pt":1580626887027,"mc":[{"id":"1.168186839","rc":[{"batb":[[0,1.83,40.76],[1,1.58,416.47],[2,1.01,10.52]],"ltp":1.95,"tv":27.12,"id":8639275},{"batb":[[0,1.93,32.34],[1,1.67,409.76],[2,1.01,10.52]],"ltp":2.04,"tv":119.9,"id":8173434}]}]}
{"op":"mcm","clk":"1004322018","pt":1580626889701,"mc":[{"id":"1.168186839","rc":[{"batb":[[0,1.84,325.78],[1,1.83,40.76],[2,1.82,341.31]],"batl":[[0,2.12,393.6],[1,2.14,212.86]],"ltp":1.95,"tv":27.12,"id":8639275}]}]}
{"op":"mcm","clk":"1004322259","pt":1580626902231,"mc":[{"id":"1.168186839","rc":[{"batb":[[0,1.83,40.76],[1,1.58,416.47],[2,1.01,10.52]],"ltp":1.95,"tv":27.12,"id":8639275}]}]}
{"op":"mcm","clk":"1004322304","pt":1580626904125,"mc":[{"id":"1.168186839","rc":[{"batb":[[1,1.01,10.52],[2,1.01,0]],"ltp":1.95,"tv":27.12,"id":8639275}]}]}
{"op":"mcm","clk":"1004322339","pt":1580626905618,"mc":[{"id":"1.168186839","rc":[{"batb":[[0,1.98,63.02],[1,1.91,35.72],[2,1.89,136.32]],"ltp":1.95,"tv":27.12,"id":8639275},{"batb":[[1,1.9,331.29],[2,1.88,307.55]],"batl":[[0,1.99,268.7],[1,2.02,378.98]],"ltp":2.04,"tv":119.9,"id":8173434}]}]}
{"op":"mcm","clk":"1004322346","pt":1580626905819,"mc":[{"id":"1.168186839","rc":[{"batb":[[2,1.01,10.52]],"ltp":1.95,"tv":27.12,"id":8639275}]}]}
{"op":"mcm","clk":"1004322411","pt":1580626908229,"mc":[{"id":"1.168186839","rc":[{"batb":[[2,1.67,409.76]],"ltp":1.95,"tv":27.12,"id":8639275}]}]}
{"op":"mcm","clk":"1004322680","pt":1580626918147,"mc":[{"id":"1.168186839","rc":[{"batb":[[0,1.91,35.72],[1,1.67,409.76],[2,1.01,10.52]],"ltp":1.95,"tv":27.12,"id":8639275},{"batb":[[0,1.74,45.32],[1,1.67,409.76],[2,1.01,10.52]],"ltp":2.04,"tv":119.9,"id":8173434}]}]}
{"op":"mcm","clk":"1004322778","pt":1580626921064,"mc":[{"id":"1.168186839","rc":[{"batb":[[1,1.73,246.83],[2,1.71,420.44]],"batl":[[0,2.12,302.33],[1,2.14,212.78]],"ltp":2.04,"tv":119.9,"id":8173434}]}]}
{"op":"mcm","clk":"1004322837","pt":1580626922555,"mc":[{"id":"1.168186839","rc":[{"batb":[[1,1.67,409.76],[2,1.01,10.52]],"ltp":2.04,"tv":119.9,"id":8173434}]}]}
{"op":"mcm","clk":"1004323005","pt":1580626929638,"mc":[{"id":"1.168186839","rc":[{"batb":[[1,1.73,246.93],[2,1.71,420.44]],"batl":[[0,2.12,302.24],[1,2.14,212.78]],"ltp":2.04,"tv":119.9,"id":8173434}]}]}
{"op":"mcm","clk":"1004323049","pt":1580626933681,"mc":[{"id":"1.168186839","rc":[{"batb":[[1,1.67,409.76],[2,1.01,10.52]],"ltp":2.04,"tv":119.9,"id":8173434}]}]}
{"op":"mcm","clk":"1004323105","pt":1580626936652,"mc":[{"id":"1.168186839","rc":[{"batb":[[1,1.9,229.32],[2,1.88,307.43]],"batl":[[0,1.98,236],[1,2,258.91]],"ltp":1.95,"tv":27.12,"id":8639275},{"batb":[[0,2,57.04],[1,1.91,33.75],[2,1.67,409.76]],"ltp":2.04,"tv":119.9,"id":8173434}]}]}
{"op":"mcm","clk":"1004323264","pt":1580626944683,"mc":[{"id":"1.168186839","rc":[{"batb":[[0,1.86,38.87],[1,1.67,409.76],[2,1.01,10.52]],"ltp":1.95,"tv":27.12,"id":8639275},{"batb":[[0,1.91,33.75],[1,1.67,409.76],[2,1.01,10.52]],"ltp":2.04,"tv":119.9,"id":8173434}]}]}
{"op":"mcm","clk":"1004323315","pt":1580626947396,"mc":[{"id":"1.168186839","rc":[{"batb":[[1,1.84,373.47],[2,1.82,341.42]],"batl":[[0,2.1,274.06],[1,2.12,218.55]],"ltp":1.95,"tv":27.12,"id":8639275}]}]}
{"op":"mcm","clk":"1004323328","pt":1580626947906,"mc":[{"id":"1.168186839","rc":[{"batb":[[1,1.67,409.76],[2,1.01,10.52]],"ltp":1.95,"tv":27.12,"id":8639275}]}]}
{"op":"mcm","clk":"1004323431","pt":1580626951697,"mc":[{"id":"1.168186839","rc":[{"batb":[[0,2,60.59],[1,1.92,35.17],[2,1.88,136.96]],"ltp":1.95,"tv":27.12,"id":8639275},{"batb":[[0,1.91,321.62],[1,1.89,302.38],[2,1.71,47.6]],"batl":[[0,2,294.21],[1,2.02,251.42]],"ltp":2.04,"tv":119.9,"id":8173434}]}]}
{"op":"mcm","clk":"1004323775","pt":1580626963580,"mc":[{"id":"1.168186839","rc":[{"batb":[[0,1.92,35.17],[1,1.67,409.76],[2,1.01,10.52]],"ltp":1.95,"tv":27.12,"id":8639275},{"batb":[[0,1.71,47.6],[1,1.67,409.76],[2,1.01,10.52]],"ltp":2.04,"tv":119.9,"id":8173434}]}]}
{"op":"mcm","clk":"1004323931","pt":1580626969633,"mc":[{"id":"1.168186839","rc":[{"batb":[[0,1.87,244.06],[1,1.85,323.68],[2,1.71,47.6]],"batl":[[0,1.95,266.19],[1,1.97,270.87]],"ltp":2.04,"tv":119.9,"id":8173434}]}]}
{"op":"mcm","clk":"1004323987","pt":1580626971634,"mc":[{"id":"1.168186839","rc":[{"batb":[[0,1.71,47.6],[1,1.67,409.76],[2,1.01,10.52]],"ltp":2.04,"tv":119.9,"id":8173434}]}]}
{"op":"mcm","clk":"1004324050","pt":1580626974404,"mc":[{"id":"1.168186839","rc":[{"batb":[[0,1.71,420.75],[1,1.69,438.49],[2,1.67,409.76]],"batl":[[0,2.14,233.56],[1,2.16,207.2]],"ltp":2.04,"tv":119.9,"id":8173434}]}]}
{"op":"mcm","clk":"1004324351","pt":1580626986431,"mc":[{"id":"1.168186839","rc":[{"batb":[[1,1.01,10.52],[2,1.01,0]],"ltp":1.95,"tv":27.12,"id":8639275},{"batb":[[2,1.01,10.52]],"ltp":2.04,"tv":119.9,"id":8173434}]}]}
{"op":"mcm","clk":"1004324382","pt":1580626987661,"mc":[{"id":"1.168186839","rc":[{"batl":[[0,1.78,277.87],[1,1.8,358.35]],"ltp":2.04,"tv":119.9,"id":8173434}]}]}
{"op":"mcm","clk":"1004324413","pt":1580626988634,"mc":[{"id":"1.168186839","rc":[{"batb":[[0,2.28,42.09],[1,2.04,57.44],[2,1.01,10.52]],"ltp":1.95,"tv":27.12,"id":8639275},{"batb":[[2,1.46,87.66]],"ltp":2.04,"tv":119.9,"id":8173434}]}]}
{"op":"mcm","clk":"1004324476","pt":1580626990172,"mc":[{"id":"1.168186839","rc":[{"batb":[[2,1.82,401.24]],"ltp":1.95,"tv":27.12,"id":8639275},{"batb":[[2,1.46,523.36]],"ltp":2.04,"tv":119.9,"id":8173434}]}]}
{"op":"mcm","clk":"1004324966","pt":1580627008681,"mc":[{"id":"1.168186839","rc":[{"batb":[[0,2.04,57.44],[1,1.82,401.24],[2,1.01,10.52]],"ltp":1.95,"tv":27.12,"id":8639275},{"batb":[[0,1.46,523.36],[1,1.01,10.51],[2,1.46,0]],"ltp":2.04,"tv":119.9,"id":8173434}]}]}
{"op":"mcm","clk":"1004325039","pt":1580627011605,"mc":[{"id":"1.168186839","rc":[{"batb":[[0,1.47,318.39],[1,1.46,908.83],[2,1.01,10.51]],"batl":[[0,1.98,250.8],[1,2,258.94]],"ltp":2.04,"tv":119.9,"id":8173434}]}]}
{"op":"mcm","clk":"1004325160","pt":1580627016385,"mc":[{"id":"1.168186839","rc":[{"batb":[[1,1.01,10.52],[2,1.01,0]],"ltp":1.95,"tv":27.12,"id":8639275},{"batb":[[1,1.46,473.13]],"ltp":2.04,"tv":119.9,"id":8173434}]}]}
{"op":"mcm","clk":"1004325201","pt":1580627017673,"mc":[{"id":"1.168186839","rc":[{"batl":[[0,1.52,552.51],[1,1.53,312.73]],"ltp":2.04,"tv":119.9,"id":8173434}]}]}
{"op":"mcm","clk":"1004325234","pt":1580627018698,"mc":[{"id":"1.168186839","rc":[{"batb":[[0,2.94,52.09],[1,2.32,40.36],[2,1.01,10.52]],"ltp":1.95,"tv":27.12,"id":8639275},{"batb":[[2,1.13,362.57]],"ltp":2.04,"tv":119.9,"id":8173434}]}]}
{"op":"mcm","clk":"1004325277","pt":1580627020600,"mc":[{"id":"1.168186839","rc":[{"batb":[[2,2.12,388.65]],"ltp":1.95,"tv":27.12,"id":8639275},{"batb":[[2,1.31,477.51]],"ltp":2.04,"tv":119.9,"id":8173434}]}]}
{"op":"mcm","clk":"1004325672","pt":1580627034496,"mc":[{"id":"1.168186839","rc":[{"batb":[[0,2.32,40.36],[1,2.12,388.65],[2,1.01,10.52]],"ltp":1.95,"tv":27.12,"id":8639275},{"batb":[[0,1.31,477.52],[1,1.13,362.57],[2,1.01,10.51]],"ltp":2.04,"tv":119.9,"id":8173434}]}]}
{"op":"mcm","clk":"1004325692","pt":1580627035622,"mc":[{"id":"1.168186839","rc":[{"batb":[[1,1.01,10.52],[2,1.01,0]],"ltp":1.95,"tv":27.12,"id":8639275},{"batb":[[0,1.13,362.58],[1,1.01,10.51],[2,1.01,0]],"ltp":2.04,"tv":119.9,"id":8173434}]}]}
{"op":"mcm","clk":"1004325748","pt":1580627037628,"mc":[{"id":"1.168186839","rc":[{"batb":[[0,1.19,1062.74],[1,1.18,1100.26],[2,1.13,362.57]],"batl":[[0,1.77,332.01],[1,1.79,364.64]],"ltp":2.04,"tv":119.9,"id":8173434}]}]}
{"op":"mcm","clk":"1004325769","pt":1580627038241,"mc":[{"id":"1.168186839","rc":[{"batb":[[0,2.3,40.52]],"ltp":1.95,"tv":27.12,"id":8639275},{"batb":[[2,1.13,361.54]],"ltp":2.04,"tv":119.9,"id":8173434}]}]}
{"op":"mcm","clk":"1004326019","pt":1580627045912,"mc":[{"id":"1.168186839","rc":[{"batb":[[0,1.13,361.55],[1,1.01,10.51],[2,1.13,0]],"ltp":2.04,"tv":119.9,"id":8173434}]}]}
{"op":"mcm","clk":"1004326122","pt":1580627049531,"mc":[{"id":"1.168186839","rc":[{"batb":[[1,2.06,55.31],[2,1.01,10.52]],"ltp":1.95,"tv":27.12,"id":8639275},{"batb":[[0,1.7,388.68],[1,1.68,447.55],[2,1.44,90.81]],"ltp":2.04,"tv":119.9,"id":8173434}]}]}
{"op":"mcm","clk":"1004326154","pt":1580627050616,"mc":[{"id":"1.168186839","rc":[{"batb":[[2,1.82,401.24]],"ltp":1.95,"tv":27.12,"id":8639275},{"batb":[[2,1.46,435.71]],"ltp":2.04,"tv":119.9,"id":8173434}]}]}
{"op":"mcm","clk":"1004326395","pt":1580627062350,"mc":[{"id":"1.168186839","rc":[{"batb":[[0,2.06,55.31],[1,1.82,401.24],[2,1.01,10.52]],"ltp":1.95,"tv":27.12,"id":8639275},{"batb":[[0,1.46,435.71],[1,1.44,90.8],[2,1.01,10.51]],"ltp":2.04,"tv":119.9,"id":8173434}]}]}
{"op":"mcm","clk":"1004326469","pt":1580627065623,"mc":[{"id":"1.168186839","rc":[{"batb":[[0,1.46,845.81],[1,1.45,397.62],[2,1.44,90.8]],"batl":[[0,1.97,314.66],[1,1.99,262.78]],"ltp":2.04,"tv":119.9,"id":8173434}]}]}
{"op":"mcm","clk":"1004326577","pt":1580627069661,"mc":[{"id":"1.168186839","rc":[{"batb":[[0,1.46,435.71],[1,1.44,90.8],[2,1.01,10.51]],"ltp":2.04,"tv":119.9,"id":8173434}]}]}
{"op":"mcm","clk":"1004326605","pt":1580627070628,"mc":[{"id":"1.168186839","rc":[{"batb":[[1,1.01,10.52],[2,1.01,0]],"ltp":1.95,"tv":27.12,"id":8639275},{"batb":[[0,1.44,90.81],[1,1.01,10.51],[2,1.01,0]],"ltp":2.04,"tv":119.9,"id":8173434}]}]}
{"op":"mcm","clk":"1004326666","pt":1580627072265,"mc":[{"id":"1.168186839","rc":[{"batb":[[0,1.88,317.6],[1,1.86,318.2],[2,1.44,90.81]],"ltp":2.04,"tv":119.9,"id":8173434}]}]}
{"op":"mcm","clk":"1004326707","pt":1580627073551,"mc":[{"id":"1.168186839","rc":[{"batb":[[1,1.97,32.65],[2,1.01,10.52]],"ltp":1.95,"tv":27.12,"id":8639275},{"batb":[[2,1.85,36.82]],"ltp":2.04,"tv":119.9,"id":8173434}]}]}
{"op":"mcm","clk":"1004326744","pt":1580627074835,"mc":[{"id":"1.168186839","rc":[{"batb":[[2,1.67,409.76]],"ltp":1.95,"tv":27.12,"id":8639275}]}]}
{"op":"mcm","clk":"1004327144","pt":1580627086691,"mc":[{"id":"1.168186839","rc":[{"batb":[[0,1.97,32.65],[1,1.67,409.76],[2,1.01,10.52]],"ltp":1.95,"tv":27.12,"id":8639275},{"batb":[[0,1.67,51.62],[1,1.58,416.47],[2,1.01,10.52]],"ltp":2.04,"tv":119.9,"id":8173434}]}]}
{"op":"mcm","clk":"1004327255","pt":1580627089658,"mc":[{"id":"1.168186839","rc":[{"batb":[[0,1.69,296.97],[1,1.67,508.48],[2,1.58,416.47]],"batl":[[0,2.12,361.93],[1,2.14,212.83]],"ltp":2.04,"tv":119.9,"id":8173434}]}]}
{"op":"mcm","clk":"1004327309","pt":1580627091089,"mc":[{"id":"1.168186839","rc":[{"batb":[[0,1.67,51.62],[1,1.58,416.47],[2,1.01,10.52]],"ltp":2.04,"tv":119.9,"id":8173434}]}]}
{"op":"mcm","clk":"1004327417","pt":1580627094580,"mc":[{"id":"1.168186839","rc":[{"batb":[[0,1.84,290.84],[1,1.82,341.32],[2,1.67,51.62]],"batl":[[0,1.92,269.61],[1,1.94,283.69]],"ltp":2.04,"tv":119.9,"id":8173434}]}]}
{"op":"mcm","clk":"1004327527","pt":1580627097563,"mc":[{"id":"1.168186839","rc":[{"batb":[[0,1.67,51.62],[1,1.58,416.47],[2,1.01,10.52]],"ltp":2.04,"tv":119.9,"id":8173434}]}]}
{"op":"mcm","clk":"1004327588","pt":1580627099669,"mc":[{"id":"1.168186839","rc":[{"batb":[[0,1.69,296.97],[1,1.67,508.48],[2,1.58,416.47]],"batl":[[0,2.12,361.93],[1,2.14,212.83]],"ltp":2.04,"tv":119.9,"id":8173434}]}]}
{"op":"mcm","clk":"1004327865","pt":1580627106789,"mc":[{"id":"1.168186839","rc":[{"batb":[[1,1.01,10.52],[2,1.01,0]],"ltp":1.95,"tv":27.12,"id":8639275},{"batb":[[2,1.01,10.52]],"ltp":2.04,"tv":119.9,"id":8173434}]}]}
{"op":"mcm","clk":"1004327922","pt":1580627108485,"mc":[{"id":"1.168186839","rc":[{"batl":[[0,1.76,394.96],[1,1.78,371.07]],"ltp":2.04,"tv":119.9,"id":8173434}]}]}
{"op":"mcm","clk":"1004327959","pt":1580627109406,"mc":[{"id":"1.168186839","rc":[{"batb":[[0,2.36,38.48],[1,2.1,53.03],[2,1.01,10.52]],"ltp":1.95,"tv":27.12,"id":8639275},{"batb":[[2,1.43,94.82]],"ltp":2.04,"tv":119.9,"id":8173434}]}]}
{"op":"mcm","clk":"1004328024","pt":1580627111205,"mc":[{"id":"1.168186839","rc":[{"batb":[[2,1.82,401.24]],"ltp":1.95,"tv":27.12,"id":8639275},{"batb":[[2,1.46,435.71]],"ltp":2.04,"tv":119.9,"id":8173434}]}]}
{"op":"mcm","clk":"1004328472","pt":1580627122616,"mc":[{"id":"1.168186839","rc":[{"batb":[[0,2.1,53.03],[1,1.82,401.24],[2,1.01,10.52]],"ltp":1.95,"tv":27.12,"id":8639275},{"batb":[[0,1.46,435.71],[1,1.43,94.81],[2,1.01,10.51]],"ltp":2.04,"tv":119.9,"id":8173434}]}]}
{"op":"mcm","clk":"1004328562","pt":1580627125434,"mc":[{"id":"1.168186839","rc":[{"batb":[[1,1.45,500.8],[2,1.44,410.38]],"batl":[[0,1.95,249.1],[1,1.97,270.88]],"ltp":2.04,"tv":119.9,"id":8173434}]}]}
{"op":"mcm","clk":"1004328591","pt":1580627126409,"mc":[{"id":"1.168186839","rc":[{"batb":[[1,1.43,94.81],[2,1.01,10.51]],"ltp":2.04,"tv":119.9,"id":8173434}]}]}
{"op":"mcm","clk":"1004328678","pt":1580627128623,"mc":[{"id":"1.168186839","rc":[{"batb":[[0,1.43,94.82],[1,1.01,10.51],[2,1.01,0]],"ltp":2.04,"tv":119.9,"id":8173434}]}]}
{"op":"mcm","clk":"1004328716","pt":1580627129700,"mc":[{"id":"1.168186839","rc":[{"batb":[[1,1.98,62.63],[2,1.82,401.24]],"ltp":1.95,"tv":27.12,"id":8639275},{"batb":[[0,1.87,261.93],[1,1.85,323.68],[2,1.83,38.32]],"ltp":2.04,"tv":119.9,"id":8173434}]}]}
{"op":"mcm","clk":"1004329157","pt":1580627141626,"mc":[{"id":"1.168186839","rc":[{"batb":[[0,1.98,62.63],[1,1.82,401.24],[2,1.01,10.52]],"ltp":1.95,"tv":27.12,"id":8639275},{"trd":[[1.87,4.72]],"batb":[[0,1.65,53.82],[1,1.55,420.5],[2,1.01,10.52]],"ltp":1.87,"tv":124.62,"id":8173434}],"tv":151.74}]}
{"op":"mcm","clk":"1004329263","pt":1580627144138,"mc":[{"id":"1.168186839","rc":[{"batb":[[0,1.68,266.93],[1,1.66,466.52],[2,1.65,53.82]],"batl":[[0,2.1,313.92],[1,2.12,218.57]],"ltp":1.87,"tv":124.62,"id":8173434}]}]}
{"op":"mcm","clk":"1004330148","pt":1580627171473,"mc":[{"id":"1.168186839","rc":[{"batb":[[0,1.65,53.82],[1,1.55,420.5],[2,1.01,10.52]],"ltp":1.87,"tv":124.62,"id":8173434}]}]}
{"op":"mcm","clk":"1004330208","pt":1580627172967,"mc":[{"id":"1.168186839","rc":[{"batb":[[1,1.01,10.52],[2,1.01,0]],"ltp":1.95,"tv":27.12,"id":8639275},{"batb":[[1,1.01,10.52],[2,1.01,0]],"ltp":1.87,"tv":124.62,"id":8173434}]}]}
{"op":"mcm","clk":"1004330284","pt":1580627174565,"mc":[{"id":"1.168186839","rc":[{"batb":[[1,1.91,332.52],[2,1.89,302.37]],"batl":[[0,2,251.53],[1,2.02,251.38]],"ltp":1.95,"tv":27.12,"id":8639275}]}]}
{"op":"mcm","clk":"1004330328","pt":1580627175652,"mc":[{"id":"1.168186839","rc":[{"batb":[[0,1.93,32.57],[1,1.83,38.32],[2,1.01,10.52]],"ltp":1.87,"tv":124.62,"id":8173434}]}]}
{"op":"mcm","clk":"1004330401","pt":1580627177294,"mc":[{"id":"1.168186839","rc":[{"batb":[[2,1.62,415.43]],"ltp":1.87,"tv":124.62,"id":8173434}]}]}
{"op":"mcm","clk":"1004330423","pt":1580627178168,"mc":[{"id":"1.168186839","rc":[{"batb":[[2,1.72,652.09]],"ltp":1.87,"tv":124.62,"id":8173434}]}]}
{"op":"mcm","clk":"1004331413","pt":1580627208521,"mc":[{"id":"1.168186839","rc":[{"trd":[[2,7.57]],"batl":[[0,2,243.96]],"ltp":2.0,"tv":34.69,"id":8639275},{"trd":[[2,7.57]],"ltp":2.0,"tv":132.19,"id":8173434}],"tv":166.88}]}
{"op":"mcm","clk":"1004331522","pt":1580627211625,"mc":[{"id":"1.168186839","rc":[{"batb":[[1,1.77,44.93],[2,1.62,415.43]],"ltp":2.0,"tv":34.69,"id":8639275}]}]}
{"op":"mcm","clk":"1004331628","pt":1580627214619,"mc":[{"id":"1.168186839","rc":[{"batb":[[2,1.71,406.15]],"batl":[[0,2.16,323.53],[1,2.18,201.95]],"ltp":2.0,"tv":34.69,"id":8639275},{"batl":[[0,2,2.53]],"ltp":2.0,"tv":132.19,"id":8173434}]}]}
{"op":"mcm","clk":"1004331660","pt":1580627215548,"mc":[{"id":"1.168186839","rc":[{"batb":[[0,1.77,44.93],[1,1.71,406.15],[2,1.69,438.4]],"ltp":2.0,"tv":34.69,"id":8639275},{"batb":[[0,1.83,38.32],[1,1.62,415.43],[2,1.01,10.52]],"ltp":2.0,"tv":132.19,"id":8173434}]}]}
{"op":"mcm","clk":"1004331797","pt":1580627218950,"mc":[{"id":"1.168186839","rc":[{"batb":[[1,1.62,415.43],[2,1.01,10.52]],"ltp":2.0,"tv":34.69,"id":8639275}]}]}
{"op":"mcm","clk":"1004331851","pt":1580627220242,"mc":[{"id":"1.168186839","rc":[{"batb":[[1,1.01,10.52],[2,1.01,0]],"ltp":2.0,"tv":132.19,"id":8173434}]}]}
{"op":"mcm","clk":"1004331953","pt":1580627222108,"mc":[{"id":"1.168186839","rc":[{"trd":[[2,10.1]],"batb":[[0,1.87,298.53],[1,1.85,323.68],[2,1.77,44.93]],"batl":[[0,1.95,211.42],[1,1.97,270.84]],"ltp":2.0,"tv":37.22,"id":8639275},{"trd":[[2,10.11]],"ltp":2.0,"tv":134.73,"id":8173434}],"tv":171.95}]}
{"op":"mcm","clk":"1004332051","pt":1580627224326,"mc":[{"id":"1.168186839","rc":[{"batb":[[1,1.67,409.76],[2,1.01,10.52]],"ltp":2.0,"tv":134.73,"id":8173434}]}]}
{"op":"mcm","clk":"1004332163","pt":1580627227124,"mc":[{"id":"1.168186839","rc":[{"batb":[[0,1.77,44.93],[1,1.62,415.43],[2,1.01,10.52]],"ltp":2.0,"tv":37.22,"id":8639275}]}]}
{"op":"mcm","clk":"1004332301","pt":1580627230538,"mc":[{"id":"1.168186839","rc":[{"batb":[[1,1.71,419.4],[2,1.69,438.43]],"batl":[[0,2.16,313.06],[1,2.18,201.95]],"ltp":2.0,"tv":37.22,"id":8639275}]}]}
{"op":"mcm","clk":"1004332915","pt":1580627247523,"mc":[{"id":"1.168186839","rc":[{"batb":[[1,1.01,10.52],[2,1.01,0]],"ltp":2.0,"tv":134.73,"id":8173434}]}]}
{"op":"mcm","clk":"1004332948","pt":1580627248543,"mc":[{"id":"1.168186839","rc":[{"batb":[[1,1.52,76.32],[2,1.01,10.52]],"ltp":2.0,"tv":37.22,"id":8639275},{"batb":[[0,2.18,44.77],[1,2,58.7],[2,1.01,10.52]],"ltp":2.0,"tv":134.73,"id":8173434}]}]}
{"op":"mcm","clk":"1004333051","pt":1580627251521,"mc":[{"id":"1.168186839","rc":[{"batb":[[1,1.72,240.64],[2,1.7,428.64]],"batl":[[0,1.79,380.94],[1,1.81,351.33]],"ltp":2.0,"tv":37.22,"id":8639275},{"batb":[[2,1.77,402.27]],"ltp":2.0,"tv":134.73,"id":8173434}]}]}
{"op":"mcm","clk":"1004333777","pt":1580627270619,"mc":[{"id":"1.168186839","rc":[{"batb":[[0,1.52,76.32],[1,1.5,426.9],[2,1.01,10.52]],"ltp":2.0,"tv":37.22,"id":8639275},{"batb":[[0,2,58.7],[1,1.77,402.27],[2,1.01,10.52]],"ltp":2.0,"tv":134.73,"id":8173434}]}]}
{"op":"mcm","clk":"1004333903","pt":1580627273403,"mc":[{"id":"1.168186839","rc":[{"batb":[[1,1.5,952.47],[2,1.49,354.92]],"batl":[[0,1.96,329.58],[1,1.98,266.6]],"ltp":2.0,"tv":37.22,"id":8639275}]}]}
{"op":"mcm","clk":"1004333983","pt":1580627275100,"mc":[{"id":"1.168186839","rc":[{"batb":[[1,1.5,426.9],[2,1.01,10.52]],"ltp":2.0,"tv":37.22,"id":8639275}]}]}
{"op":"mcm","clk":"1004334032","pt":1580627277313,"mc":[{"id":"1.168186839","rc":[{"batb":[[1,1.01,10.52],[2,1.01,0]],"ltp":2.0,"tv":37.22,"id":8639275}]}]}
{"op":"mcm","clk":"1004334078","pt":1580627278597,"mc":[{"id":"1.168186839","rc":[{"batb":[[0,1.92,34.86],[1,1.87,319.37],[2,1.85,323.64]],"ltp":2.0,"tv":37.22,"id":8639275},{"batb":[[1,1.87,36.12],[2,1.77,402.27]],"ltp":2.0,"tv":134.73,"id":8173434}]}]}
{"op":"mcm","clk":"1004334868","pt":1580627298570,"mc":[{"id":"1.168186839","rc":[{"trd":[[1.96,56.75]],"batb":[[0,1.66,55.39],[1,1.58,416.47],[2,1.01,10.52]],"ltp":1.96,"tv":93.97,"id":8639275},{"trd":[[2.04,99.7]],"batb":[[0,1.87,36.12],[1,1.77,402.27],[2,1.01,10.52]],"ltp":2.04,"tv":189.25,"id":8173434}],"tv":283.22}]}
{"op":"mcm","clk":"1004335109","pt":1580627305468,"mc":[{"id":"1.168186839","rc":[{"batb":[[0,1.82,323.28],[1,1.8,353.74],[2,1.66,55.39]],"batl":[[0,1.9,272.35],[1,1.92,292.54]],"ltp":1.96,"tv":93.97,"id":8639275}]}]}
{"op":"mcm","clk":"1004335263","pt":1580627309441,"mc":[{"id":"1.168186839","rc":[{"batb":[[0,1.66,55.39],[1,1.58,416.47],[2,1.01,10.52]],"ltp":1.96,"tv":93.97,"id":8639275}]}]}
{"op":"mcm","clk":"1004335365","pt":1580627312380,"mc":[{"id":"1.168186839","rc":[{"batb":[[1,1.64,341.5],[2,1.63,250.49]],"batl":[[0,2.14,235.59],[1,2.16,207.17]],"ltp":1.96,"tv":93.97,"id":8639275}]}]}
{"op":"mcm","clk":"1004335767","pt":1580627325855,"mc":[{"id":"1.168186839","rc":[{"batb":[[1,1.58,416.47],[2,1.01,10.52]],"ltp":1.96,"tv":93.97,"id":8639275}]}]}
{"op":"mcm","clk":"1004335867","pt":1580627328697,"mc":[{"id":"1.168186839","rc":[{"batb":[[1,1.01,10.52],[2,1.01,0]],"ltp":1.96,"tv":93.97,"id":8639275},{"batb":[[1,1.01,10.52],[2,1.01,0]],"ltp":2.04,"tv":189.25,"id":8173434}]}]}
{"op":"mcm","clk":"1004335900","pt":1580627329675,"mc":[{"id":"1.168186839","rc":[{"batb":[[0,2.04,56.57],[1,1.86,38.71],[2,1.01,10.52]],"ltp":1.96,"tv":93.97,"id":8639275},{"batb":[[0,1.88,224.47],[1,1.87,36.12],[2,1.86,318.03]],"batl":[[0,1.96,269.58],[1,1.98,266.75]],"ltp":2.04,"tv":189.25,"id":8173434}]}]}
{"op":"mcm","clk":"1004336031","pt":1580627332679,"mc":[{"id":"1.168186839","rc":[{"batb":[[2,1.7,409.32]],"ltp":1.96,"tv":93.97,"id":8639275}]}]}
{"op":"mcm","clk":"1004336521","pt":1580627347297,"mc":[{"id":"1.168186839","rc":[{"batb":[[0,1.86,38.71],[1,1.7,409.32],[2,1.01,10.52]],"ltp":1.96,"tv":93.97,"id":8639275},{"batb":[[0,1.78,42.25],[1,1.55,420.5],[2,1.01,10.52]],"ltp":2.04,"tv":189.25,"id":8173434}]}]}
{"op":"mcm","clk":"1004336620","pt":1580627350395,"mc":[{"id":"1.168186839","rc":[{"batb":[[1,1.77,272.14],[2,1.75,388.59]],"batl":[[0,2.22,345.13],[1,2.24,187.2]],"ltp":2.04,"tv":189.25,"id":8173434}]}]}
{"op":"mcm","clk":"1004336758","pt":1580627354108,"mc":[{"id":"1.168186839","rc":[{"batb":[[1,1.55,420.5],[2,1.01,10.52]],"ltp":2.04,"tv":189.25,"id":8173434}]}]}
{"op":"mcm","clk":"1004336820","pt":1580627356532,"mc":[{"id":"1.168186839","rc":[{"batb":[[1,1.01,10.52],[2,1.01,0]],"ltp":1.96,"tv":93.97,"id":8639275},{"batb":[[1,1.01,10.52],[2,1.01,0]],"ltp":2.04,"tv":189.25,"id":8173434}]}]}
{"op":"mcm","clk":"1004336838","pt":1580627357407,"mc":[{"id":"1.168186839","rc":[{"batb":[[1,1.83,242.47],[2,1.81,347.22]],"batl":[[0,1.91,331.84],[1,1.93,287.87]],"ltp":1.96,"tv":93.97,"id":8639275},{"batb":[[0,2.06,52.48],[1,1.88,35.25],[2,1.78,42.25]],"ltp":2.04,"tv":189.25,"id":8173434}]}]}
{"op":"mcm","clk":"1004336872","pt":1580627358389,"mc":[{"id":"1.168186839","rc":[{"batb":[[2,1.01,10.52]],"ltp":2.04,"tv":189.25,"id":8173434}]}]}
{"op":"mcm","clk":"1004336920","pt":1580627360293,"mc":[{"id":"1.168186839","rc":[{"batb":[[2,1.67,409.76]],"ltp":2.04,"tv":189.25,"id":8173434}]}]}
{"op":"mcm","clk":"1004337432","pt":1580627374657,"mc":[{"id":"1.168186839","rc":[{"batb":[[0,1.58,416.47],[1,1.53,74.67],[2,1.01,10.52]],"ltp":1.96,"tv":93.97,"id":8639275},{"batb":[[0,1.88,35.25],[1,1.67,409.76],[2,1.01,10.52]],"ltp":2.04,"tv":189.25,"id":8173434}]}]}
{"op":"mcm","clk":"1004337533","pt":1580627377448,"mc":[{"id":"1.168186839","rc":[{"batb":[[1,1.53,598.12],[2,1.52,327.41]],"batl":[[0,2.16,271.85],[1,2.18,201.9]],"ltp":1.96,"tv":93.97,"id":8639275}]}]}
{"op":"mcm","clk":"1004337564","pt":1580627378021,"mc":[{"id":"1.168186839","rc":[{"batb":[[1,1.53,74.67],[2,1.01,10.52]],"ltp":1.96,"tv":93.97,"id":8639275}]}]}
{"op":"mcm","clk":"1004337722","pt":1580627382635,"mc":[{"id":"1.168186839","rc":[{"batb":[[0,1.76,304.55],[1,1.74,396.02],[2,1.58,416.47]],"ltp":1.96,"tv":93.97,"id":8639275}]}]}
{"op":"mcm","clk":"1004337834","pt":1580627385634,"mc":[{"id":"1.168186839","rc":[{"batb":[[0,1.76,367.69]],"batl":[[0,1.84,346],[1,1.86,322.32]],"ltp":1.96,"tv":93.97,"id":8639275}]}]}
{"op":"mcm","clk":"1004337840","pt":1580627385945,"mc":[{"id":"1.168186839","rc":[{"batb":[[0,1.58,416.47],[1,1.53,74.67],[2,1.01,10.52]],"ltp":1.96,"tv":93.97,"id":8639275}]}]}
{"op":"mcm","clk":"1004337980","pt":1580627390072,"mc":[{"id":"1.168186839","rc":[{"batb":[[1,1.54,277.12],[2,1.53,392.14]],"batl":[[0,2.16,220.26],[1,2.18,201.84]],"ltp":1.96,"tv":93.97,"id":8639275}]}]}
{"op":"mcm","clk":"1004338839","pt":1580627414173,"mc":[{"id":"1.168186839","rc":[{"batb":[[1,1.53,74.67],[2,1.01,10.52]],"ltp":1.96,"tv":93.97,"id":8639275}]}]}
{"op":"mcm","clk":"1004338925","pt":1580627416697,"mc":[{"id":"1.168186839","rc":[{"batb":[[0,1.53,74.67],[1,1.01,10.52],[2,1.01,0]],"ltp":1.96,"tv":93.97,"id":8639275},{"batb":[[1,1.01,10.52],[2,1.01,0]],"ltp":2.04,"tv":189.25,"id":8173434}]}]}
{"op":"mcm","clk":"1004338962","pt":1580627417622,"mc":[{"id":"1.168186839","rc":[{"batb":[[0,2.02,57.83],[1,1.82,41.15],[2,1.53,74.67]],"ltp":1.96,"tv":93.97,"id":8639275},{"batb":[[1,1.86,289.02],[2,1.84,329.36]],"batl":[[0,1.94,238.65],[1,1.96,275.03]],"ltp":2.04,"tv":189.25,"id":8173434}]}]}
{"op":"mcm","clk":"1004338999","pt":1580627418507,"mc":[{"id":"1.168186839","rc":[{"batb":[[2,1.01,10.52]],"ltp":1.96,"tv":93.97,"id":8639275}]}]}
{"op":"mcm","clk":"1004339084","pt":1580627420415,"mc":[{"id":"1.168186839","rc":[{"batb":[[2,1.64,681.07]],"ltp":1.96,"tv":93.97,"id":8639275}]}]}
{"op":"mcm","clk":"1004339131","pt":1580627421398,"mc":[{"id":"1.168186839","rc":[{"batb":[[2,1.7,409.32]],"ltp":1.96,"tv":93.97,"id":8639275}]}]}
{"op":"mcm","clk":"1004339703","pt":1580627437701,"mc":[{"id":"1.168186839","rc":[{"batb":[[0,1.82,41.15],[1,1.7,409.32],[2,1.01,10.52]],"ltp":1.96,"tv":93.97,"id":8639275},{"batb":[[0,1.78,42.02],[1,1.55,420.5],[2,1.01,10.52]],"ltp":2.04,"tv":189.25,"id":8173434}]}]}
{"op":"mcm","clk":"1004339799","pt":1580627440449,"mc":[{"id":"1.168186839","rc":[{"batb":[[1,1.74,321.04],[2,1.72,412.46]],"batl":[[0,2.22,188.56],[1,2.24,186.94]],"ltp":2.04,"tv":189.25,"id":8173434}]}]}
{"op":"mcm","clk":"1004339909","pt":1580627445037,"mc":[{"id":"1.168186839","rc":[{"batb":[[1,1.55,420.5],[2,1.01,10.52]],"ltp":2.04,"tv":189.25,"id":8173434}]}]}
{"op":"mcm","clk":"1004339998","pt":1580627447659,"mc":[{"id":"1.168186839","rc":[{"batb":[[1,1.01,10.52],[2,1.01,0]],"ltp":1.96,"tv":93.97,"id":8639275},{"batb":[[1,1.01,10.52],[2,1.01,0]],"ltp":2.04,"tv":189.25,"id":8173434}]}]}
{"op":"mcm","clk":"1004340026","pt":1580627448531,"mc":[{"id":"1.168186839","rc":[{"batb":[[0,1.82,265.5],[1,1.8,353.44],[2,1.51,77.97]],"batl":[[0,1.89,216.94],[1,1.91,297.25]],"ltp":1.96,"tv":93.97,"id":8639275},{"batb":[[0,2.12,49.18],[1,1.9,33.99],[2,1.78,42.02]],"ltp":2.04,"tv":189.25,"id":8173434}]}]}
{"op":"mcm","clk":"1004340036","pt":1580627448737,"mc":[{"id":"1.168186839","rc":[{"batb":[[2,1.01,10.52]],"ltp":2.04,"tv":189.25,"id":8173434}]}]}
{"op":"mcm","clk":"1004340116","pt":1580627450949,"mc":[{"id":"1.168186839","rc":[{"batb":[[2,1.55,420.5]],"ltp":1.96,"tv":93.97,"id":8639275},{"batb":[[2,1.7,409.32]],"ltp":2.04,"tv":189.25,"id":8173434}]}]}
{"op":"mcm","clk":"1004340862","pt":1580627469343,"mc":[{"id":"1.168186839","rc":[{"batb":[[0,1.55,420.5],[1,1.51,77.97],[2,1.01,10.52]],"ltp":1.96,"tv":93.97,"id":8639275},{"batb":[[0,1.9,33.99],[1,1.7,409.32],[2,1.01,10.52]],"ltp":2.04,"tv":189.25,"id":8173434}]}]}
{"op":"mcm","clk":"1004340979","pt":1580627472384,"mc":[{"id":"1.168186839","rc":[{"batb":[[1,1.53,297.92],[2,1.52,325.9]],"batl":[[0,2.14,204.87],[1,2.16,207.15]],"ltp":1.96,"tv":93.97,"id":8639275}]}]}
{"op":"mcm","clk":"1004341195","pt":1580627475554,"mc":[{"id":"1.168186839","rc":[{"batb":[[1,1.51,77.97],[2,1.01,10.52]],"ltp":1.96,"tv":93.97,"id":8639275}]}]}
{"op":"mcm","clk":"1004341255","pt":1580627476992,"mc":[{"id":"1.168186839","rc":[{"batb":[[0,1.51,77.97],[1,1.01,10.52],[2,1.01,0]],"ltp":1.96,"tv":93.97,"id":8639275},{"batb":[[1,1.01,10.52],[2,1.01,0]],"ltp":2.04,"tv":189.25,"id":8173434}]}]}
{"op":"mcm","clk":"1004341303","pt":1580627478694,"mc":[{"id":"1.168186839","rc":[{"batb":[[1,1.87,347.72],[2,1.85,323.71]],"batl":[[0,1.96,303.03],[1,1.98,266.73]],"ltp":2.04,"tv":189.25,"id":8173434}]}]}
{"op":"mcm","clk":"1004341326","pt":1580627479462,"mc":[{"id":"1.168186839","rc":[{"batb":[[0,2,60.03],[1,1.79,43.43],[2,1.01,10.52]],"ltp":1.96,"tv":93.97,"id":8639275}]}]}
{"op":"mcm","clk":"1004341352","pt":1580627480497,"mc":[{"id":"1.168186839","rc":[{"batb":[[2,1.67,409.76]],"ltp":1.96,"tv":93.97,"id":8639275}]}]}
{"op":"mcm","clk":"1004341998","pt":1580627492508,"mc":[{"id":"1.168186839","rc":[{"batb":[[0,1.79,43.43],[1,1.67,409.76],[2,1.01,10.52]],"ltp":1.96,"tv":93.97,"id":8639275},{"batb":[[0,1.8,40.36],[1,1.58,416.47],[2,1.01,10.52]],"ltp":2.04,"tv":189.25,"id":8173434}]}]}
{"op":"mcm","clk":"1004342331","pt":1580627498495,"mc":[{"id":"1.168186839","rc":[{"batb":[[0,1.92,294.7],[1,1.9,297.28],[2,1.8,40.36]],"batl":[[0,2.02,395.78],[1,2.04,244.18]],"ltp":2.04,"tv":189.25,"id":8173434}]}]}
{"op":"mcm","clk":"1004342589","pt":1580627505099,"mc":[{"id":"1.168186839","rc":[{"batb":[[0,1.8,40.36],[1,1.58,416.47],[2,1.01,10.52]],"ltp":2.04,"tv":189.25,"id":8173434}]}]}
{"op":"mcm","clk":"1004342678","pt":1580627508029,"mc":[{"id":"1.168186839","rc":[{"batb":[[1,1.75,324.14],[2,1.73,404.37]],"batl":[[0,2.24,175.61],[1,2.26,182.37]],"ltp":2.04,"tv":189.25,"id":8173434}]}]}
{"op":"mcm","clk":"1004343785","pt":1580627541828,"mc":[{"id":"1.168186839","rc":[{"batb":[[1,1.58,416.47],[2,1.01,10.52]],"ltp":2.04,"tv":189.25,"id":8173434}]}]}
{"op":"mcm","clk":"1004343898","pt":1580627545376,"mc":[{"id":"1.168186839","rc":[{"batb":[[0,1.87,347.02],[1,1.85,323.71],[2,1.8,40.36]],"batl":[[0,1.96,303.7],[1,1.98,266.73]],"ltp":2.04,"tv":189.25,"id":8173434}]}]}
{"op":"mcm","clk":"1004344356","pt":1580627561567,"mc":[{"id":"1.168186839","rc":[{"batb":[[0,1.8,40.36],[1,1.58,416.47],[2,1.01,10.52]],"ltp":2.04,"tv":189.25,"id":8173434}]}]}
{"op":"mcm","clk":"1004344499","pt":1580627567155,"mc":[{"id":"1.168186839","rc":[{"batb":[[0,1.92,294.01],[1,1.9,297.28],[2,1.8,40.36]],"batl":[[0,2.02,396.43],[1,2.04,244.19]],"ltp":2.04,"tv":189.25,"id":8173434}]}]}
{"op":"mcm","clk":"1004344719","pt":1580627574478,"mc":[{"id":"1.168186839","rc":[{"batb":[[0,1.8,40.36],[1,1.58,416.47],[2,1.01,10.52]],"ltp":2.04,"tv":189.25,"id":8173434}]}]}
{"op":"mcm","clk":"1004344805","pt":1580627577195,"mc":[{"id":"1.168186839","rc":[{"batb":[[1,1.75,323.38],[2,1.73,404.38]],"batl":[[0,2.24,176.2],[1,2.26,182.37]],"ltp":2.04,"tv":189.25,"id":8173434}]}]}
{"op":"mcm","clk":"1004344886","pt":1580627579299,"mc":[{"id":"1.168186839","rc":[{"batb":[[1,1.58,416.47],[2,1.01,10.52]],"ltp":2.04,"tv":189.25,"id":8173434}]}]}
{"op":"mcm","clk":"1004344926","pt":1580627580379,"mc":[{"id":"1.168186839","rc":[{"batb":[[1,1.01,10.52],[2,1.01,0]],"ltp":1.96,"tv":93.97,"id":8639275},{"batb":[[1,1.01,10.52],[2,1.01,0]],"ltp":2.04,"tv":189.25,"id":8173434}]}]}
{"op":"mcm","clk":"1004344997","pt":1580627582638,"mc":[{"id":"1.168186839","rc":[{"batb":[[0,1.8,334.17],[1,1.79,43.43],[2,1.78,366.98]],"batl":[[0,1.88,298.13],[1,1.9,301.93]],"ltp":1.96,"tv":93.97,"id":8639275}]}]}
{"op":"mcm","clk":"1004345046","pt":1580627583613,"mc":[{"id":"1.168186839","rc":[{"batb":[[0,2.16,46.5],[1,1.93,32.65],[2,1.01,10.52]],"ltp":2.04,"tv":189.25,"id":8173434}]}]}
{"op":"mcm","clk":"1004345075","pt":1580627584277,"mc":[{"id":"1.168186839","rc":[{"batb":[[0,1.79,43.43],[1,1.55,420.5],[2,1.5,81.2]],"ltp":1.96,"tv":93.97,"id":8639275},{"batb":[[2,1.7,409.32]],"ltp":2.04,"tv":189.25,"id":8173434}]}]}
{"op":"mcm","clk":"1004345715","pt":1580627601319,"mc":[{"id":"1.168186839","rc":[{"batb":[[0,1.55,420.5],[1,1.5,81.2],[2,1.01,10.52]],"ltp":1.96,"tv":93.97,"id":8639275},{"batb":[[0,1.93,32.65],[1,1.7,409.32],[2,1.01,10.52]],"ltp":2.04,"tv":189.25,"id":8173434}]}]}
{"op":"mcm","clk":"1004346365","pt":1580627619419,"mc":[{"id":"1.168186839","rc":[{"batb":[[0,1.5,81.2],[1,1.01,10.52],[2,1.01,0]],"ltp":1.96,"tv":93.97,"id":8639275},{"batb":[[1,1.01,10.52],[2,1.01,0]],"ltp":2.04,"tv":189.25,"id":8173434}]}]}
{"op":"mcm","clk":"1004346442","pt":1580627621521,"mc":[{"id":"1.168186839","rc":[{"batb":[[0,1.98,62.55],[1,1.78,44.77],[2,1.6,13.19]],"ltp":1.96,"tv":93.97,"id":8639275},{"batb":[[1,1.82,38.87],[2,1.01,10.52]],"ltp":2.04,"tv":189.25,"id":8173434}]}]}
{"op":"mcm","clk":"1004346528","pt":1580627623520,"mc":[{"id":"1.168186839","rc":[{"batb":[[2,1.67,409.76]],"ltp":1.96,"tv":93.97,"id":8639275},{"batb":[[2,1.58,416.47]],"ltp":2.04,"tv":189.25,"id":8173434}]}]}
{"op":"mcm","clk":"1004346614","pt":1580627626342,"mc":[{"id":"1.168186839","rc":[{"batb":[[1,1.89,244.2],[2,1.87,312.66]],"batl":[[0,1.97,236.06],[1,1.99,262.8]],"ltp":2.04,"tv":189.25,"id":8173434}]}]}
{"op":"mcm","clk":"1004347245","pt":1580627639445,"mc":[{"id":"1.168186839","rc":[{"batb":[[0,1.78,44.77],[1,1.67,409.76],[2,1.01,10.52]],"ltp":1.96,"tv":93.97,"id":8639275},{"batb":[[0,1.82,38.87],[1,1.58,416.47],[2,1.01,10.52]],"ltp":2.04,"tv":189.25,"id":8173434}]}]}
{"op":"mcm","clk":"1004347405","pt":1580627642678,"mc":[{"id":"1.168186839","rc":[{"batb":[[0,1.79,43.9]],"ltp":1.96,"tv":93.97,"id":8639275},{"batb":[[0,1.81,39.66],[1,1.76,322.94],[2,1.74,396.53]],"batl":[[0,2.28,343.36],[1,2.3,174.04]],"ltp":2.04,"tv":189.25,"id":8173434}]}]}
{"op":"mcm","clk":"1004348270","pt":1580627662397,"mc":[{"id":"1.168186839","rc":[{"batb":[[1,1.01,10.52],[2,1.01,0]],"ltp":1.96,"tv":93.97,"id":8639275}]}]}
{"op":"mcm","clk":"1004348341","pt":1580627663681,"mc":[{"id":"1.168186839","rc":[{"batl":[[0,1.83,225.44],[1,1.85,328.61]],"ltp":2.04,"tv":189.25,"id":8173434}]}]}
{"op":"mcm","clk":"1004348437","pt":1580627665686,"mc":[{"id":"1.168186839","rc":[{"batb":[[0,2.12,51.22],[1,1.99,61.77],[2,1.01,10.52]],"ltp":1.96,"tv":93.97,"id":8639275}]}]}
{"op":"mcm","clk":"1004348449","pt":1580627665992,"mc":[{"id":"1.168186839","rc":[{"batb":[[2,1.77,402.27]],"ltp":1.96,"tv":93.97,"id":8639275}]}]}
{"op":"mcm","clk":"1004350100","pt":1580627703837,"mc":[{"id":"1.168186839","rc":[{"batl":[[0,1.84,373.6],[1,1.86,322.71]],"ltp":2.04,"tv":189.25,"id":8173434}]}]}
{"op":"mcm","clk":"1004352060","pt":1580627755097,"mc":[{"id":"1.168186839","rc":[{"batb":[[0,1.99,61.77],[1,1.77,402.27],[2,1.01,10.52]],"ltp":1.96,"tv":93.97,"id":8639275},{"batb":[[0,1.62,57.75],[1,1.58,416.47],[2,1.01,10.52]],"ltp":2.04,"tv":189.25,"id":8173434}]}]}
{"op":"mcm","clk":"1004352187","pt":1580627758698,"mc":[{"id":"1.168186839","rc":[{"batb":[[1,1.59,263.45],[2,1.58,697.78]],"batl":[[0,1.96,222.62],[1,1.98,266.74]],"ltp":2.04,"tv":189.25,"id":8173434}]}]}
{"op":"mcm","clk":"1004352435","pt":1580627765691,"mc":[{"id":"1.168186839","rc":[{"batb":[[1,1.01,10.52],[2,1.01,0]],"ltp":1.96,"tv":93.97,"id":8639275},{"batb":[[2,1.58,281.31]],"ltp":2.04,"tv":189.25,"id":8173434}]}]}
{"op":"mcm","clk":"1004352469","pt":1580627766614,"mc":[{"id":"1.168186839","rc":[{"batb":[[0,2.46,33.91],[1,2.2,46.11],[2,1.99,61.77]],"ltp":1.96,"tv":93.97,"id":8639275},{"batl":[[0,1.64,237.3],[1,1.65,238.71]],"ltp":2.04,"tv":189.25,"id":8173434}]}]}
{"op":"mcm","clk":"1004352495","pt":1580627767489,"mc":[{"id":"1.168186839","rc":[{"batb":[[2,1.01,10.52]],"ltp":1.96,"tv":93.97,"id":8639275}]}]}
{"op":"mcm","clk":"1004352559","pt":1580627769546,"mc":[{"id":"1.168186839","rc":[{"batb":[[2,1.97,394.86]],"ltp":1.96,"tv":93.97,"id":8639275}]}]}
{"op":"mcm","clk":"1004352773","pt":1580627775611,"mc":[{"id":"1.168186839","rc":[{"batb":[[1,1.41,99.78],[2,1.38,448.45]],"ltp":2.04,"tv":189.25,"id":8173434}]}]}
{"op":"mcm","clk":"1004352813","pt":1580627776533,"mc":[{"id":"1.168186839","rc":[{"batb":[[0,2.2,46.11],[1,1.97,394.86],[2,1.01,10.52]],"ltp":1.96,"tv":93.97,"id":8639275},{"batb":[[0,1.41,99.78],[1,1.38,448.45],[2,1.01,10.51]],"ltp":2.04,"tv":189.25,"id":8173434}]}]}
{"op":"mcm","clk":"1004352905","pt":1580627778665,"mc":[{"id":"1.168186839","rc":[{"batb":[[1,1.4,379.25],[2,1.39,479.88]],"batl":[[0,1.79,280.9],[1,1.81,352.04]],"ltp":2.04,"tv":189.25,"id":8173434}]}]}
{"op":"mcm","clk":"1004353455","pt":1580627795609,"mc":[{"id":"1.168186839","rc":[{"batb":[[1,1.38,448.45],[2,1.01,10.51]],"ltp":2.04,"tv":189.25,"id":8173434}]}]}
{"op":"mcm","clk":"1004353561","pt":1580627798510,"mc":[{"id":"1.168186839","rc":[{"batb":[[1,1.01,10.52],[2,1.01,0]],"ltp":1.96,"tv":93.97,"id":8639275},{"trd":[[1.48,0.02]],"batb":[[0,1.41,99.77],[1,1.4,379.25],[2,1.39,479.88]],"batl":[[0,1.44,441.73],[1,1.45,388.95],[2,1.7,811.85]],"ltp":1.48,"tv":189.27,"id":8173434}],"tv":283.24}]}
{"op":"mcm","clk":"1004353603","pt":1580627799691,"mc":[{"id":"1.168186839","rc":[{"batb":[[0,3.15,44.14],[1,2.68,27.07],[2,1.01,10.52]],"ltp":1.96,"tv":93.97,"id":8639275}]}]}
{"op":"mcm","clk":"1004353677","pt":1580627802011,"mc":[{"id":"1.168186839","rc":[{"batb":[[2,2.3,385.09]],"ltp":1.96,"tv":93.97,"id":8639275},{"batl":[[2,1.7,0]],"ltp":1.48,"tv":189.27,"id":8173434}]}]}
{"op":"mcm","clk":"1004354272","pt":1580627818416,"mc":[{"id":"1.168186839","rc":[{"batb":[[0,2.68,27.07],[1,2.3,385.09],[2,1.01,10.52]],"ltp":1.96,"tv":93.97,"id":8639275},{"batb":[[0,1.25,505.09],[1,1.22,211.58],[2,1.01,10.51]],"ltp":1.48,"tv":189.27,"id":8173434}]}]}
{"op":"mcm","clk":"1004354385","pt":1580627821555,"mc":[{"id":"1.168186839","rc":[{"batb":[[1,1.23,1158.71],[2,1.22,1143.44]],"batl":[[0,1.57,364.06],[1,1.58,278.37]],"ltp":1.48,"tv":189.27,"id":8173434}]}]}
{"op":"mcm","clk":"1004354643","pt":1580627828555,"mc":[{"id":"1.168186839","rc":[{"trd":[[1.57,19.16]],"batl":[[0,1.57,354.48]],"ltp":1.57,"tv":208.43,"id":8173434}],"tv":302.4}]}
{"op":"mcm","clk":"1004354680","pt":1580627829432,"mc":[{"id":"1.168186839","rc":[{"batb":[[1,1.22,211.58],[2,1.01,10.51]],"ltp":1.57,"tv":208.43,"id":8173434}]}]}
{"op":"mcm","clk":"1004354802","pt":1580627832536,"mc":[{"id":"1.168186839","rc":[{"batb":[[1,1.01,10.52],[2,1.01,0]],"ltp":1.96,"tv":93.97,"id":8639275},{"batb":[[0,1.52,335.81],[1,1.51,335.92],[2,1.22,211.58]],"ltp":1.57,"tv":208.43,"id":8173434}]}]}
{"op":"mcm","clk":"1004354860","pt":1580627833662,"mc":[{"id":"1.168186839","rc":[{"batb":[[1,2.3,41.39],[2,1.01,10.52]],"ltp":1.96,"tv":93.97,"id":8639275},{"batb":[[0,1.54,69.4],[1,1.52,335.81],[2,1.51,335.92]],"ltp":1.57,"tv":208.43,"id":8173434}]}]}
{"op":"mcm","clk":"1004354973","pt":1580627836340,"mc":[{"id":"1.168186839","rc":[{"batb":[[2,2.04,394.09]],"ltp":1.96,"tv":93.97,"id":8639275}]}]}
{"op":"mcm","clk":"1004355218","pt":1580627842356,"mc":[{"id":"1.168186839","rc":[{"trd":[[2.74,0.04]],"ltp":2.74,"tv":94.0,"id":8639275},{"trd":[[1.57,19.23]],"batl":[[0,1.57,354.41]],"ltp":1.57,"tv":208.5,"id":8173434}],"tv":302.5}]}
{"op":"mcm","clk":"1004355274","pt":1580627843646,"mc":[{"id":"1.168186839","rc":[{"trd":[[1.54,39.18]],"batb":[[0,1.54,49.81]],"ltp":1.54,"tv":247.68,"id":8173434}],"tv":341.68}]}
{"op":"mcm","clk":"1004355599","pt":1580627852598,"mc":[{"id":"1.168186839","rc":[{"batb":[[0,2.3,41.39],[1,2.04,394.09],[2,1.01,10.52]],"ltp":2.74,"tv":94.0,"id":8639275},{"batb":[[0,1.34,465.43],[1,1.3,150.28],[2,1.01,10.51]],"ltp":1.54,"tv":247.68,"id":8173434}]}]}
{"op":"mcm","clk":"1004355736","pt":1580627855544,"mc":[{"id":"1.168186839","rc":[{"batb":[[0,2.3,41.07]],"ltp":2.74,"tv":94.0,"id":8639275},{"batb":[[1,1.29,151.23]],"ltp":1.54,"tv":247.68,"id":8173434}]}]}
{"op":"mcm","clk":"1004355859","pt":1580627858681,"mc":[{"id":"1.168186839","rc":[{"batb":[[0,1.47,399.65],[1,1.46,386.36],[2,1.34,465.43]],"batl":[[0,1.52,478.16],[1,1.53,313.46]],"ltp":1.54,"tv":247.68,"id":8173434}]}]}
{"op":"mcm","clk":"1004356050","pt":1580627863570,"mc":[{"id":"1.168186839","rc":[{"batb":[[0,1.34,465.43],[1,1.29,151.23],[2,1.01,10.51]],"ltp":1.54,"tv":247.68,"id":8173434}]}]}
{"op":"mcm","clk":"1004356129","pt":1580627866864,"mc":[{"id":"1.168186839","rc":[{"batb":[[1,1.3,754.46],[2,1.29,856.31]],"batl":[[0,1.75,338.52],[1,1.77,378.19]],"ltp":1.54,"tv":247.68,"id":8173434}]}]}
{"op":"mcm","clk":"1004356803","pt":1580627884518,"mc":[{"id":"1.168186839","rc":[{"batb":[[1,1.01,10.52],[2,1.01,0]],"ltp":2.74,"tv":94.0,"id":8639275},{"batb":[[0,1.3,754.46],[1,1.29,856.31],[2,1.01,10.51]],"ltp":1.54,"tv":247.68,"id":8173434}]}]}
{"op":"mcm","clk":"1004356845","pt":1580627885700,"mc":[{"id":"1.168186839","rc":[{"batb":[[0,3.95,51.06],[1,3.05,47.29],[2,1.01,10.52]],"ltp":2.74,"tv":94.0,"id":8639275},{"batb":[[2,1.1,497.74]],"batl":[[0,1.34,715.13],[1,1.35,531.46],[2,1.66,956.75]],"ltp":1.54,"tv":247.68,"id":8173434}]}]}
{"op":"mcm","clk":"1004356923","pt":1580627887798,"mc":[{"id":"1.168186839","rc":[{"batb":[[2,2.52,381.46]],"ltp":2.74,"tv":94.0,"id":8639275},{"batb":[[2,1.2,530.86]],"ltp":1.54,"tv":247.68,"id":8173434}]}]}
{"op":"mcm","clk":"1004357276","pt":1580627894620,"mc":[{"id":"1.168186839","rc":[{"trd":[[1.3,60.58]],"batb":[[0,1.3,724.17]],"ltp":1.3,"tv":308.26,"id":8173434}],"tv":402.26}]}
{"op":"mcm","clk":"1004357773","pt":1580627905536,"mc":[{"id":"1.168186839","rc":[{"batb":[[0,3.05,47.29],[1,2.52,381.46],[2,1.01,10.52]],"ltp":2.74,"tv":94.0,"id":8639275},{"trd":[[1.34,6.06]],"batb":[[1,1.29,705.08]],"batl":[[0,1.34,712.1],[2,1.66,0]],"ltp":1.34,"tv":314.31,"id":8173434}],"tv":408.32}]}
{"op":"mcm","clk":"1004357834","pt":1580627906611,"mc":[{"id":"1.168186839","rc":[{"batb":[[0,1.2,530.86],[1,1.1,494.59],[2,1.01,10.51]],"ltp":1.34,"tv":314.31,"id":8173434}]}]}
{"op":"mcm","clk":"1004357902","pt":1580627907633,"mc":[{"id":"1.168186839","rc":[{"batb":[[1,1.01,10.52],[2,1.01,0]],"ltp":2.74,"tv":94.0,"id":8639275},{"batb":[[0,1.1,494.59],[1,1.01,10.51],[2,1.01,0]],"ltp":1.34,"tv":314.31,"id":8173434}]}]}
{"op":"mcm","clk":"1004358070","pt":1580627910652,"mc":[{"id":"1.168186839","rc":[{"batb":[[0,1.14,1041.82],[1,1.13,1216.3],[2,1.1,494.59]],"batl":[[0,1.47,448.85],[1,1.48,357.57]],"ltp":1.34,"tv":314.31,"id":8173434}]}]}
{"op":"mcm","clk":"1004358235","pt":1580627914247,"mc":[{"id":"1.168186839","rc":[{"batl":[[0,1.3,110.98],[1,1.47,448.85],[2,1.48,357.57]],"ltp":1.34,"tv":314.31,"id":8173434}]}]}
{"op":"mcm","clk":"1004358324","pt":1580627916553,"mc":[{"id":"1.168186839","rc":[{"batl":[[0,1.47,448.85],[1,1.48,357.57],[2,1.48,0]],"ltp":1.34,"tv":314.31,"id":8173434}]}]}
{"op":"mcm","clk":"1004358672","pt":1580627924548,"mc":[{"id":"1.168186839","rc":[{"batb":[[0,1.1,494.59],[1,1.01,10.51],[2,1.1,0]],"ltp":1.34,"tv":314.31,"id":8173434}]}]}
{"op":"mcm","clk":"1004358803","pt":1580627927678,"mc":[{"id":"1.168186839","rc":[{"batb":[[0,1.42,674.11],[1,1.41,452.45],[2,1.1,494.59]],"ltp":1.34,"tv":314.31,"id":8173434}]}]}
{"op":"mcm","clk":"1004358844","pt":1580627928554,"mc":[{"id":"1.168186839","rc":[{"batb":[[1,2.34,39.81],[2,1.01,10.52]],"ltp":2.74,"tv":94.0,"id":8639275},{"batb":[[0,1.43,93.87],[1,1.42,674.11],[2,1.41,452.45]],"ltp":1.34,"tv":314.31,"id":8173434}]}]}
{"op":"mcm","clk":"1004358944","pt":1580627930668,"mc":[{"id":"1.168186839","rc":[{"batb":[[2,2.22,384.52]],"ltp":2.74,"tv":94.0,"id":8639275}]}]}
{"op":"mcm","clk":"1004358997","pt":1580627932258,"mc":[{"id":"1.168186839","rc":[{"batb":[[1,1.42,547.19]],"ltp":1.34,"tv":314.31,"id":8173434}]}]}
{"op":"mcm","clk":"1004359131","pt":1580627935387,"mc":[{"id":"1.168186839","rc":[{"batl":[[0,1.47,571.56]],"ltp":1.34,"tv":314.31,"id":8173434}]}]}
{"op":"mcm","clk":"1004359189","pt":1580627936568,"mc":[{"id":"1.168186839","rc":[{"batb":[[1,1.42,480.65]],"batl":[[0,1.47,370.59],[1,1.48,0]],"ltp":1.34,"tv":314.31,"id":8173434}]}]}
{"op":"mcm","clk":"1004359336","pt":1580627939380,"mc":[{"id":"1.168186839","rc":[{"batl":[[0,1.46,267.09],[1,1.47,370.59]],"ltp":1.34,"tv":314.31,"id":8173434}]}]}
{"op":"mcm","clk":"1004359432","pt":1580627941482,"mc":[{"id":"1.168186839","rc":[{"batb":[[1,1.41,452.45],[2,1.28,485.89]],"ltp":1.34,"tv":314.31,"id":8173434}]}]}
{"op":"mcm","clk":"1004359595","pt":1580627944658,"mc":[{"id":"1.168186839","rc":[{"batb":[[1,1.41,472.4],[2,1.4,471.73]],"batl":[[0,1.46,384.58],[1,1.47,0]],"ltp":1.34,"tv":314.31,"id":8173434}]}]}
{"op":"mcm","clk":"1004359710","pt":1580627947574,"mc":[{"id":"1.168186839","rc":[{"batb":[[0,2.34,39.26],[1,1.01,10.52],[2,2.22,0]],"ltp":2.74,"tv":94.0,"id":8639275},{"batb":[[0,1.1,484.21],[1,1.01,10.51],[2,1.4,0]],"ltp":1.34,"tv":314.31,"id":8173434}]}]}
{"op":"mcm","clk":"1004359803","pt":1580627949690,"mc":[{"id":"1.168186839","rc":[{"batb":[[0,1.14,380.71],[1,1.13,1644.08],[2,1.1,484.21]],"ltp":1.34,"tv":314.31,"id":8173434}]}]}
{"op":"mcm","clk":"1004359901","pt":1580627951582,"mc":[{"id":"1.168186839","rc":[{"batb":[[1,1.13,1841.45]],"batl":[[0,1.7,248.26],[1,1.72,422.07]],"ltp":1.34,"tv":314.31,"id":8173434}]}]}
{"op":"mcm","clk":"1004361430","pt":1580627989327,"mc":[{"id":"1.168186839","rc":[{"batl":[[0,1.16,1512.07],[1,1.17,690.7]],"ltp":1.34,"tv":314.31,"id":8173434}]}]}
{"op":"mcm","clk":"1004361479","pt":1580627990459,"mc":[{"id":"1.168186839","rc":[{"trd":[[8.2,16.84]],"batb":[[0,5.7,21.64]],"ltp":8.2,"tv":110.84,"id":8639275},{"trd":[[1.14,121.11]],"batb":[[0,1.13,1841.45],[1,1.1,484.21],[2,1.07,712.07]],"ltp":1.14,"tv":435.42,"id":8173434}],"tv":546.27}]}
{"op":"mcm","clk":"1004361594","pt":1580627992629,"mc":[{"id":"1.168186839","rc":[{"batb":[[1,3.15,373.59],[2,1.01,10.52]],"ltp":8.2,"tv":110.84,"id":8639275},{"batb":[[2,1.09,779.05]],"ltp":1.14,"tv":435.42,"id":8173434}]}]}
{"op":"mcm","clk":"1004361635","pt":1580627993550,"mc":[{"id":"1.168186839","rc":[{"batb":[[0,1.13,2181.28],[2,1.07,712.07]],"ltp":1.14,"tv":435.42,"id":8173434}]}]}
{"op":"mcm","clk":"1004362026","pt":1580628002338,"mc":[{"id":"1.168186839","rc":[{"batb":[[0,1.13,1841.48]],"ltp":1.14,"tv":435.42,"id":8173434}]}]}
{"op":"mcm","clk":"1004362136","pt":1580628004658,"mc":[{"id":"1.168186839","rc":[{"trd":[[1.13,596.54]],"batb":[[0,1.14,338.03],[1,1.13,1543.21],[2,1.1,484.21]],"batl":[[1,1.17,543.44]],"ltp":1.13,"tv":1031.96,"id":8173434}],"tv":1142.81}]}
{"op":"mcm","clk":"1004362182","pt":1580628005681,"mc":[{"id":"1.168186839","rc":[{"trd":[[1.13,1116.54]],"batb":[[0,1.13,1283.21],[1,1.1,484.21],[2,1.07,712.07]],"batl":[[0,1.16,1409.09],[1,1.17,0]],"ltp":1.13,"tv":1551.96,"id":8173434}],"tv":1662.81}]}
{"op":"mcm","clk":"1004362280","pt":1580628007684,"mc":[{"id":"1.168186839","rc":[{"batb":[[0,1.13,1813.69]],"batl":[[0,1.16,1557.63]],"ltp":1.13,"tv":1551.96,"id":8173434}]}]}
{"op":"mcm","clk":"1004362326","pt":1580628008463,"mc":[{"id":"1.168186839","rc":[{"batb":[[0,1.13,1978.41]],"batl":[[0,1.15,347.3],[1,1.16,1409.09]],"ltp":1.13,"tv":1551.96,"id":8173434}]}]}
{"op":"mcm","clk":"1004362933","pt":1580628019664,"mc":[{"id":"1.168186839","rc":[{"trd":[[1.13,1158.58]],"batb":[[0,1.13,1957.39]],"ltp":1.13,"tv":1594.01,"id":8173434}],"tv":1704.85}]}
{"op":"mcm","clk":"1004363005","pt":1580628020664,"mc":[{"id":"1.168186839","rc":[{"trd":[[1.13,2009.71]],"batb":[[0,1.13,1531.74]],"ltp":1.13,"tv":2445.14,"id":8173434}],"tv":2555.99}]}
{"op":"mcm","clk":"1004363147","pt":1580628022625,"mc":[{"id":"1.168186839","rc":[{"batl":[[2,1.35,80.5]],"ltp":1.13,"tv":2445.14,"id":8173434}]}]}
{"op":"mcm","clk":"1004363213","pt":1580628023907,"mc":[{"id":"1.168186839","rc":[{"batb":[[0,1.13,1814.73],[1,1.12,456.68],[2,1.1,484.21]],"batl":[[0,1.15,508.07]],"ltp":1.13,"tv":2445.14,"id":8173434}]}]}
{"op":"mcm","clk":"1004363281","pt":1580628025298,"mc":[{"id":"1.168186839","rc":[{"trd":[[1.15,52.46]],"batl":[[0,1.15,481.84]],"ltp":1.15,"tv":2497.6,"id":8173434}],"tv":2608.45}]}
{"op":"mcm","clk":"1004363332","pt":1580628026689,"mc":[{"id":"1.168186839","rc":[{"batb":[[0,1.1,484.21],[1,1.07,712.07],[2,1.01,10.51]],"batl":[[0,1.35,80.5],[1,1.16,0],[2,1.35,0]],"ltp":1.15,"tv":2497.6,"id":8173434}]}]}
{"op":"mcm","clk":"1004363381","pt":1580628027515,"mc":[{"id":"1.168186839","rc":[{"batb":[[0,1.07,712.07],[1,1.01,10.51],[2,1.01,0]],"ltp":1.15,"tv":2497.6,"id":8173434}]}]}
{"op":"mcm","clk":"1004363481","pt":1580628029670,"mc":[{"id":"1.168186839","rc":[{"batb":[[0,1.1,581.37],[1,1.09,1763.87],[2,1.07,712.07]],"batl":[[0,1.23,411.15],[1,1.24,880.52]],"ltp":1.15,"tv":2497.6,"id":8173434}]}]}
{"op":"mcm","clk":"1004363521","pt":1580628030695,"mc":[{"id":"1.168186839","rc":[{"batb":[[0,5.5,22.9]],"ltp":8.2,"tv":110.84,"id":8639275},{"batb":[[0,1.07,686.58],[1,1.01,10.51],[2,1.07,0]],"ltp":1.15,"tv":2497.6,"id":8173434}]}]}
{"op":"mcm","clk":"1004363675","pt":1580628034602,"mc":[{"id":"1.168186839","rc":[{"batb":[[0,1.15,646.39],[1,1.14,1595.42],[2,1.07,686.58]],"batl":[[0,1.17,1113.65],[1,1.18,1067.09]],"ltp":1.15,"tv":2497.6,"id":8173434}]}]}
{"op":"mcm","clk":"1004363706","pt":1580628035627,"mc":[{"id":"1.168186839","rc":[{"batb":[[2,1.11,199.56]],"ltp":1.15,"tv":2497.6,"id":8173434}]}]}
{"op":"mcm","clk":"1004363847","pt":1580628038398,"mc":[{"id":"1.168186839","rc":[{"batb":[[0,1.11,199.56],[1,1.07,686.58],[2,1.01,10.51]],"ltp":1.15,"tv":2497.6,"id":8173434}]}]}
{"op":"mcm","clk":"1004363961","pt":1580628040608,"mc":[{"id":"1.168186839","rc":[{"batb":[[1,1.1,581.37],[2,1.09,1763.87]],"batl":[[0,1.23,411.15],[1,1.24,880.53]],"ltp":1.15,"tv":2497.6,"id":8173434}]}]}
{"op":"mcm","clk":"1004364469","pt":1580628054612,"mc":[{"id":"1.168186839","rc":[{"batb":[[1,1.01,10.52],[2,1.01,0]],"ltp":8.2,"tv":110.84,"id":8639275},{"batb":[[0,1.1,581.37],[1,1.09,1763.87],[2,1.07,686.58]],"ltp":1.15,"tv":2497.6,"id":8173434}]}]}
{"op":"mcm","clk":"1004364512","pt":1580628055533,"mc":[{"id":"1.168186839","rc":[{"batl":[[0,1.11,577.38],[1,1.12,1715.38]],"ltp":1.15,"tv":2497.6,"id":8173434}]}]}
{"op":"mcm","clk":"1004364549","pt":1580628056402,"mc":[{"id":"1.168186839","rc":[{"batb":[[0,10.5,24.47],[1,7.4,23.53],[2,1.01,10.52]],"ltp":8.2,"tv":110.84,"id":8639275}]}]}
{"op":"mcm","clk":"1004364633","pt":1580628058610,"mc":[{"id":"1.168186839","rc":[{"batb":[[2,3.5,585.04]],"ltp":8.2,"tv":110.84,"id":8639275}]}]}
{"op":"mcm","clk":"1004364960","pt":1580628065539,"mc":[{"id":"1.168186839","rc":[{"trd":[[1.1,14.5]],"batb":[[0,1.1,574.12]],"ltp":1.1,"tv":2512.1,"id":8173434}],"tv":2622.95}]}
{"op":"mcm","clk":"1004365101","pt":1580628068674,"mc":[{"id":"1.168186839","rc":[{"trd":[[1.1,311.92]],"batb":[[0,1.1,425.41]],"ltp":1.1,"tv":2809.53,"id":8173434}],"tv":2920.37}]}
{"op":"mcm","clk":"1004365386","pt":1580628072266,"mc":[{"id":"1.168186839","rc":[{"batb":[[0,1.1,531.03]],"ltp":1.1,"tv":2809.53,"id":8173434}]}]}
{"op":"mcm","clk":"1004365586","pt":1580628076676,"mc":[{"id":"1.168186839","rc":[{"batb":[[0,7.4,23.53],[1,3.5,585.04],[2,1.01,10.52]],"ltp":8.2,"tv":110.84,"id":8639275},{"batb":[[0,1.06,454.97],[1,1.05,966.06],[2,1.01,10.51]],"ltp":1.1,"tv":2809.53,"id":8173434}]}]}
{"op":"mcm","clk":"1004365716","pt":1580628079645,"mc":[{"id":"1.168186839","rc":[{"batb":[[0,7.2,23.92]],"ltp":8.2,"tv":110.84,"id":8639275},{"batb":[[0,1.07,2207.52],[1,1.06,454.97],[2,1.05,955.12]],"batl":[[0,1.17,1171.03],[1,1.18,1010.19]],"ltp":1.1,"tv":2809.53,"id":8173434}]}]}
{"op":"mcm","clk":"1004365763","pt":1580628080668,"mc":[{"id":"1.168186839","rc":[{"batb":[[0,1.05,955.12],[1,1.01,10.51],[2,1.05,0]],"ltp":1.1,"tv":2809.53,"id":8173434}]}]}
{"op":"mcm","clk":"1004365835","pt":1580628082565,"mc":[{"id":"1.168186839","rc":[{"batb":[[0,1.11,456.26],[1,1.1,1868.8],[2,1.05,955.12]],"batl":[[0,1.12,492.62],[1,1.13,1779.11]],"ltp":1.1,"tv":2809.53,"id":8173434}]}]}
{"op":"mcm","clk":"1004365908","pt":1580628084156,"mc":[{"id":"1.168186839","rc":[{"batb":[[2,1.07,361.83]],"ltp":1.1,"tv":2809.53,"id":8173434}]}]}
{"op":"mcm","clk":"1004365943","pt":1580628085336,"mc":[{"id":"1.168186839","rc":[{"trd":[[1.11,168.04]],"batb":[[0,1.11,372.24]],"ltp":1.11,"tv":2977.57,"id":8173434}],"tv":3088.41}]}
{"op":"mcm","clk":"1004366019","pt":1580628087492,"mc":[{"id":"1.168186839","rc":[{"trd":[[1.11,193.24]],"batb":[[0,1.07,361.83],[1,1.05,955.12],[2,1.01,10.51]],"ltp":1.11,"tv":3002.77,"id":8173434}],"tv":3113.61}]}
{"op":"mcm","clk":"1004366053","pt":1580628088261,"mc":[{"id":"1.168186839","rc":[{"trd":[[7.2,0.62]],"batb":[[0,7.2,23.3]],"ltp":7.2,"tv":111.46,"id":8639275},{"trd":[[1.17,3.79]],"ltp":1.17,"tv":3006.55,"id":8173434}],"tv":3118.02}]}
{"op":"mcm","clk":"1004366211","pt":1580628090371,"mc":[{"id":"1.168186839","rc":[{"batb":[[0,1.07,2537.28]],"batl":[[0,1.17,1200.16],[1,1.18,981.31]],"ltp":1.17,"tv":3006.55,"id":8173434}]}]}
{"op":"mcm","clk":"1004366659","pt":1580628095660,"mc":[{"id":"1.168186839","rc":[{"batb":[[0,1.07,2175.45]],"ltp":1.17,"tv":3006.55,"id":8173434}]}]}
{"op":"mcm","clk":"1004366758","pt":1580628097664,"mc":[{"id":"1.168186839","rc":[{"batb":[[0,14,13.85],[1,10,28.72],[2,7.2,23.3]],"ltp":7.2,"tv":111.46,"id":8639275},{"batb":[[2,1.04,1224.45]],"batl":[[0,1.09,2350.58]],"ltp":1.17,"tv":3006.55,"id":8173434}]}]}
{"op":"mcm","clk":"1004366792","pt":1580628098383,"mc":[{"id":"1.168186839","rc":[{"batb":[[2,3.5,585.04]],"ltp":7.2,"tv":111.46,"id":8639275},{"batb":[[1,1.05,954.25]],"ltp":1.17,"tv":3006.55,"id":8173434}]}]}
{"op":"mcm","clk":"1004366850","pt":1580628099663,"mc":[{"id":"1.168186839","rc":[{"batb":[[2,1.04,1954.49]],"ltp":1.17,"tv":3006.55,"id":8173434}]}]}
{"op":"mcm","clk":"1004367119","pt":1580628106395,"mc":[{"id":"1.168186839","rc":[{"trd":[[14,0.18]],"batb":[[0,14,13.67]],"ltp":14.0,"tv":111.63,"id":8639275},{"trd":[[1.08,2.27]],"ltp":1.08,"tv":3008.83,"id":8173434}],"tv":3120.46}]}
{"op":"mcm","clk":"1004367483","pt":1580628113694,"mc":[{"id":"1.168186839","rc":[{"batb":[[0,1.05,954.25],[1,1.04,1954.49],[2,1.01,10.51]],"ltp":1.08,"tv":3008.83,"id":8173434}]}]}
{"op":"mcm","clk":"1004367538","pt":1580628114517,"mc":[{"id":"1.168186839","rc":[{"batb":[[0,10,28.72],[1,3.5,585.04],[2,1.01,10.52]],"ltp":14.0,"tv":111.63,"id":8639275},{"batb":[[0,1.04,1953.71],[1,1.01,10.51],[2,1.01,0]],"ltp":1.08,"tv":3008.83,"id":8173434}]}]}
{"op":"mcm","clk":"1004367652","pt":1580628116621,"mc":[{"id":"1.168186839","rc":[{"batb":[[0,1.06,469.8],[1,1.05,1965.85],[2,1.04,1953.71]],"batl":[[0,1.12,2019.47]],"ltp":1.08,"tv":3008.83,"id":8173434}]}]}
{"op":"mcm","clk":"1004368036","pt":1580628125596,"mc":[{"id":"1.168186839","rc":[{"batl":[[0,1.07,29.88],[1,1.12,2019.47]],"ltp":1.08,"tv":3008.83,"id":8173434}]}]}
{"op":"mcm","clk":"1004368250","pt":1580628130619,"mc":[{"id":"1.168186839","rc":[{"batb":[[0,1.04,1953.71],[1,1.01,10.51],[2,1.04,0]],"batl":[[1,1.12,0]],"ltp":1.08,"tv":3008.83,"id":8173434}]}]}
{"op":"mcm","clk":"1004368288","pt":1580628131749,"mc":[{"id":"1.168186839","rc":[{"batb":[[0,1.04,1223.66]],"ltp":1.08,"tv":3008.83,"id":8173434}]}]}
{"op":"mcm","clk":"1004368385","pt":1580628133637,"mc":[{"id":"1.168186839","rc":[{"trd":[[1.07,59.77]],"batb":[[0,1.1,1147.64],[1,1.09,1162.24],[2,1.04,1223.66]],"batl":[[0,1.12,2019.47]],"ltp":1.07,"tv":3068.59,"id":8173434}],"tv":3180.23}]}
{"op":"mcm","clk":"1004368419","pt":1580628134209,"mc":[{"id":"1.168186839","rc":[{"batb":[[1,6.4,31.47],[2,3.5,585.04]],"ltp":14.0,"tv":111.63,"id":8639275},{"batb":[[2,1.08,624.58]],"ltp":1.07,"tv":3068.59,"id":8173434}]}]}
{"op":"mcm","clk":"1004369456","pt":1580628157258,"mc":[{"id":"1.168186839","rc":[{"batb":[[0,6.4,31.47],[1,3.5,585.04],[2,1.01,10.52]],"ltp":14.0,"tv":111.63,"id":8639275},{"batb":[[0,1.07,361.83],[1,1.05,965.43],[2,1.01,10.51]],"ltp":1.07,"tv":3068.59,"id":8173434}]}]}
{"op":"mcm","clk":"1004369677","pt":1580628162656,"mc":[{"id":"1.168186839","rc":[{"batb":[[0,1.11,1541.77],[1,1.1,773.43],[2,1.07,361.83]],"batl":[[0,1.13,1343.12],[1,1.14,916.14]],"ltp":1.07,"tv":3068.59,"id":8173434}]}]}
{"op":"mcm","clk":"1004369923","pt":1580628169284,"mc":[{"id":"1.168186839","rc":[{"batb":[[0,1.07,361.83],[1,1.05,965.43],[2,1.01,10.51]],"ltp":1.07,"tv":3068.59,"id":8173434}]}]}
{"op":"mcm","clk":"1004370008","pt":1580628171758,"mc":[{"id":"1.168186839","rc":[{"batb":[[0,1.07,1173.36],[1,1.06,1597.92],[2,1.05,965.43]],"batl":[[0,1.18,341.48],[1,1.19,1165.9]],"ltp":1.07,"tv":3068.59,"id":8173434}]}]}
{"op":"mcm","clk":"1004370192","pt":1580628176502,"mc":[{"id":"1.168186839","rc":[{"batb":[[0,1.07,361.83],[1,1.05,965.43],[2,1.01,10.51]],"ltp":1.07,"tv":3068.59,"id":8173434}]}]}
{"op":"mcm","clk":"1004370260","pt":1580628178096,"mc":[{"id":"1.168186839","rc":[{"batb":[[0,1.05,965.43],[1,1.01,10.51],[2,1.01,0]],"ltp":1.07,"tv":3068.59,"id":8173434}]}]}
{"op":"mcm","clk":"1004370334","pt":1580628179487,"mc":[{"id":"1.168186839","rc":[{"batb":[[0,1.16,1314.95],[1,1.15,901.56],[2,1.05,965.43]],"ltp":1.07,"tv":3068.59,"id":8173434}]}]}
{"op":"mcm","clk":"1004370363","pt":1580628180001,"mc":[{"id":"1.168186839","rc":[{"batb":[[1,3.75,28.56],[2,3.5,585.04]],"ltp":14.0,"tv":111.63,"id":8639275},{"batb":[[1,1.15,1235.8],[2,1.07,650.62]],"ltp":1.07,"tv":3068.59,"id":8173434}]}]}
{"op":"mcm","clk":"1004370459","pt":1580628182212,"mc":[{"id":"1.168186839","rc":[{"batb":[[2,1.11,211.24]],"ltp":1.07,"tv":3068.59,"id":8173434}]}]}
{"op":"mcm","clk":"1004371172","pt":1580628197437,"mc":[{"id":"1.168186839","rc":[{"batl":[[0,1.19,1165.9],[1,1.19,0]],"ltp":1.07,"tv":3068.59,"id":8173434}]}]}
{"op":"mcm","clk":"1004371280","pt":1580628199701,"mc":[{"id":"1.168186839","rc":[{"batb":[[0,1.18,30.29],[1,1.16,1314.95],[2,1.15,1235.8]],"ltp":1.07,"tv":3068.59,"id":8173434}]}]}
{"op":"mcm","clk":"1004371323","pt":1580628200625,"mc":[{"id":"1.168186839","rc":[{"batb":[[0,3.75,28.4],[1,3.5,585.04],[2,1.01,10.52]],"ltp":14.0,"tv":111.63,"id":8639275},{"batb":[[1,1.11,211.24],[2,1.07,650.62]],"ltp":1.07,"tv":3068.59,"id":8173434}]}]}
{"op":"mcm","clk":"1004371440","pt":1580628203302,"mc":[{"id":"1.168186839","rc":[{"batb":[[2,1.09,2350.58]],"batl":[[0,1.34,298.45],[1,1.35,556.84]],"ltp":1.07,"tv":3068.59,"id":8173434}]}]}
{"op":"mcm","clk":"1004371775","pt":1580628211639,"mc":[{"id":"1.168186839","rc":[{"batb":[[1,1.09,2350.58],[2,1.07,650.62]],"ltp":1.07,"tv":3068.59,"id":8173434}]}]}
{"op":"mcm","clk":"1004371806","pt":1580628212515,"mc":[{"id":"1.168186839","rc":[{"batb":[[0,10.5,26.67],[1,6.2,33.99],[2,3.75,28.4]],"ltp":14.0,"tv":111.63,"id":8639275},{"trd":[[1.18,60.58]],"batb":[[0,1.09,2350.58],[1,1.07,650.62],[2,1.04,1091.24]],"batl":[[0,1.11,1345.03],[1,1.12,924.57]],"ltp":1.18,"tv":3129.17,"id":8173434}],"tv":3240.81}]}
{"op":"mcm","clk":"1004371823","pt":1580628212822,"mc":[{"id":"1.168186839","rc":[{"batb":[[2,3.5,585.04]],"ltp":14.0,"tv":111.63,"id":8639275}]}]}
{"op":"mcm","clk":"1004371933","pt":1580628215648,"mc":[{"id":"1.168186839","rc":[{"batb":[[2,1.06,454.97]],"ltp":1.18,"tv":3129.17,"id":8173434}]}]}
{"op":"mcm","clk":"1004372292","pt":1580628224455,"mc":[{"id":"1.168186839","rc":[{"batb":[[0,6.2,33.99],[1,3.5,585.04],[2,1.01,10.52]],"ltp":14.0,"tv":111.63,"id":8639275},{"trd":[[1.11,325.85]],"batb":[[0,1.06,454.97],[1,1.04,1091.24],[2,1.01,10.51]],"ltp":1.11,"tv":3261.78,"id":8173434}],"tv":3373.42}]}
{"op":"mcm","clk":"1004372465","pt":1580628228362,"mc":[{"id":"1.168186839","rc":[{"batb":[[0,1.04,1091.24],[1,1.01,10.51],[2,1.01,0]],"ltp":1.11,"tv":3261.78,"id":8173434}]}]}
{"op":"mcm","clk":"1004372539","pt":1580628229655,"mc":[{"id":"1.168186839","rc":[{"batb":[[0,1.11,699.65],[1,1.1,1623.2],[2,1.04,1091.24]],"batl":[[0,1.13,2063.94]],"ltp":1.11,"tv":3261.78,"id":8173434}]}]}
{"op":"mcm","clk":"1004372599","pt":1580628231464,"mc":[{"id":"1.168186839","rc":[{"batb":[[2,1.07,377.83]],"ltp":1.11,"tv":3261.78,"id":8173434}]}]}
{"op":"mcm","clk":"1004372761","pt":1580628235540,"mc":[{"id":"1.168186839","rc":[{"batb":[[0,1.07,377.83],[1,1.04,1091.24],[2,1.01,10.51]],"ltp":1.11,"tv":3261.78,"id":8173434}]}]}
{"op":"mcm","clk":"1004372816","pt":1580628237081,"mc":[{"id":"1.168186839","rc":[{"batb":[[1,1.01,10.52],[2,1.01,0]],"ltp":14.0,"tv":111.63,"id":8639275},{"batb":[[0,1.04,1091.24],[1,1.01,10.51],[2,1.01,0]],"ltp":1.11,"tv":3261.78,"id":8173434}]}]}
{"op":"mcm","clk":"1004372854","pt":1580628238365,"mc":[{"id":"1.168186839","rc":[{"batb":[[0,1.06,638.62],[1,1.05,1795.42],[2,1.04,1091.24]],"batl":[[0,1.19,904.14],[1,1.2,1077.75]],"ltp":1.11,"tv":3261.78,"id":8173434}]}]}
{"op":"mcm","clk":"1004373411","pt":1580628259701,"mc":[{"id":"1.168186839","rc":[{"batb":[[0,15.5,11.02],[1,14,13.14],[2,1.01,10.52]],"ltp":14.0,"tv":111.63,"id":8639275},{"batl":[[0,1.07,1966.84],[1,1.08,423.73]],"ltp":1.11,"tv":3261.78,"id":8173434}]}]}
{"op":"mcm","clk":"1004373463","pt":1580628261086,"mc":[{"id":"1.168186839","rc":[{"batb":[[2,3.85,567.38]],"ltp":14.0,"tv":111.63,"id":8639275}]}]}
{"op":"mcm","clk":"1004373826","pt":1580628275098,"mc":[{"id":"1.168186839","rc":[{"trd":[[1.07,67.34]],"batl":[[0,1.07,1963.05]],"ltp":1.07,"tv":3269.36,"id":8173434}],"tv":3380.99}]}
{"op":"mcm","clk":"1004373955","pt":1580628279518,"mc":[{"id":"1.168186839","rc":[{"trd":[[1.06,406]],"batb":[[0,1.06,435.62]],"batl":[[1,1.08,0]],"ltp":1.06,"tv":3675.36,"id":8173434}],"tv":3786.99}]}
{"op":"mcm","clk":"1004374023","pt":1580628282244,"mc":[{"id":"1.168186839","rc":[{"batb":[[0,1.06,563.74],[1,1.05,1868]],"batl":[[0,1.07,2038.08]],"ltp":1.06,"tv":3675.36,"id":8173434}]}]}
{"op":"mcm","clk":"1004374173","pt":1580628287041,"mc":[{"id":"1.168186839","rc":[{"trd":[[1.06,779.04]],"batb":[[0,1.06,377.22]],"ltp":1.06,"tv":4048.4,"id":8173434}],"tv":4160.04}]}
{"op":"mcm","clk":"1004374289","pt":1580628290529,"mc":[{"id":"1.168186839","rc":[{"batb":[[0,1.06,496.38],[1,1.05,1939.03]],"batl":[[0,1.07,2107.8]],"ltp":1.06,"tv":4048.4,"id":8173434}]}]}
{"op":"mcm","clk":"1004375130","pt":1580628314585,"mc":[{"id":"1.168186839","rc":[{"batl":[[0,1.07,3452.11]],"ltp":1.06,"tv":4048.4,"id":8173434}]}]}
{"op":"mcm","clk":"1004376027","pt":1580628339391,"mc":[{"id":"1.168186839","rc":[{"batb":[[0,14,13.14],[1,3.85,567.38],[2,1.01,10.52]],"ltp":14.0,"tv":111.63,"id":8639275},{"batb":[[0,1.03,2445.65],[1,1.01,10.51],[2,1.04,0]],"batl":[[0,1.07,1344.31]],"ltp":1.06,"tv":4048.4,"id":8173434}]}]}
{"op":"mcm","clk":"1004376149","pt":1580628342515,"mc":[{"id":"1.168186839","rc":[{"batb":[[0,1.04,2463.61],[1,1.03,2445.65],[2,1.01,10.51]],"batl":[[1,1.08,2129.92]],"ltp":1.06,"tv":4048.4,"id":8173434}]}]}
{"op":"mcm","clk":"1004376203","pt":1580628343489,"mc":[{"id":"1.168186839","rc":[{"batb":[[0,1.03,2445.65],[1,1.01,10.51],[2,1.01,0]],"batl":[[1,1.08,0]],"ltp":1.06,"tv":4048.4,"id":8173434}]}]}
{"op":"mcm","clk":"1004376218","pt":1580628343999,"mc":[{"id":"1.168186839","rc":[{"batl":[[0,1.06,8.4],[1,1.07,1344.31]],"ltp":1.06,"tv":4048.4,"id":8173434}]}]}
{"op":"mcm","clk":"1004376347","pt":1580628347632,"mc":[{"id":"1.168186839","rc":[{"batb":[[0,1.05,2440.15],[1,1.03,2445.65],[2,1.01,10.51]],"batl":[[1,1.07,3738.85]],"ltp":1.06,"tv":4048.4,"id":8173434}]}]}
{"op":"mcm","clk":"1004376537","pt":1580628352699,"mc":[{"id":"1.168186839","rc":[{"batb":[[0,1.03,2445.65],[1,1.01,10.51],[2,1.01,0]],"batl":[[1,1.07,1344.31]],"ltp":1.06,"tv":4048.4,"id":8173434}]}]}
{"op":"mcm","clk":"1004376767","pt":1580628356608,"mc":[{"id":"1.168186839","rc":[{"batb":[[0,1.04,2463.61],[1,1.03,2445.65],[2,1.01,10.51]],"batl":[[2,1.08,2129.91]],"ltp":1.06,"tv":4048.4,"id":8173434}]}]}
{"op":"mcm","clk":"1004376962","pt":1580628360048,"mc":[{"id":"1.168186839","rc":[{"batl":[[2,1.08,0]],"ltp":1.06,"tv":4048.4,"id":8173434}]}]}
{"op":"mcm","clk":"1004377065","pt":1580628362618,"mc":[{"id":"1.168186839","rc":[{"batb":[[1,1.03,1429.49]],"ltp":1.06,"tv":4048.4,"id":8173434}]}]}
{"op":"mcm","clk":"1004377082","pt":1580628363029,"mc":[{"id":"1.168186839","rc":[{"batl":[[0,1.06,2425.53]],"ltp":1.06,"tv":4048.4,"id":8173434}]}]}
{"op":"mcm","clk":"1004377165","pt":1580628364648,"mc":[{"id":"1.168186839","rc":[{"batb":[[0,18.5,14.08],[1,16,9.91],[2,3.85,567.38]],"ltp":14.0,"tv":111.63,"id":8639275}]}]}
{"op":"mcm","clk":"1004377281","pt":1580628366924,"mc":[{"id":"1.168186839","rc":[{"batb":[[2,1.02,1575.76]],"ltp":1.06,"tv":4048.4,"id":8173434}]}]}
{"op":"mcm","clk":"1004377493","pt":1580628371641,"mc":[{"id":"1.168186839","rc":[{"batb":[[0,16,9.91],[1,3.85,567.38],[2,1.01,10.52]],"ltp":14.0,"tv":111.63,"id":8639275},{"batb":[[0,1.02,1575.76],[1,1.01,10.51],[2,1.02,0]],"batl":[[0,1.06,8.4]],"ltp":1.06,"tv":4048.4,"id":8173434}]}]}
{"op":"mcm","clk":"1004377624","pt":1580628374051,"mc":[{"id":"1.168186839","rc":[{"batb":[[0,1.02,4087.68]],"batl":[[1,1.07,3738.85]],"ltp":1.06,"tv":4048.4,"id":8173434}]}]}
{"op":"mcm","clk":"1004377922","pt":1580628379450,"mc":[{"id":"1.168186839","rc":[{"batl":[[1,1.07,2394.54]],"ltp":1.06,"tv":4048.4,"id":8173434}]}]}
{"op":"mcm","clk":"1004378058","pt":1580628382478,"mc":[{"id":"1.168186839","rc":[{"batl":[[0,1.05,1344.31],[1,1.06,8.4],[2,1.07,2394.54]],"ltp":1.06,"tv":4048.4,"id":8173434}]}]}
{"op":"mcm","clk":"1004378086","pt":1580628383149,"mc":[{"id":"1.168186839","rc":[{"batl":[[2,1.07,0]],"ltp":1.06,"tv":4048.4,"id":8173434}]}]}
{"op":"mcm","clk":"1004378193","pt":1580628385678,"mc":[{"id":"1.168186839","rc":[{"batb":[[0,1.02,2511.92]],"ltp":1.06,"tv":4048.4,"id":8173434}]}]}
{"op":"mcm","clk":"1004378276","pt":1580628386661,"mc":[{"id":"1.168186839","rc":[{"batb":[[0,26,8.65],[1,20,11.02],[2,16,9.91]],"ltp":14.0,"tv":111.63,"id":8639275},{"batl":[[0,1.04,2463.61],[1,1.05,1344.31],[2,1.06,8.4]],"ltp":1.06,"tv":4048.4,"id":8173434}]}]}
{"op":"mcm","clk":"1004378386","pt":1580628387690,"mc":[{"id":"1.168186839","rc":[{"batb":[[2,3.85,567.38]],"ltp":14.0,"tv":111.63,"id":8639275}]}]}
{"op":"mcm","clk":"1004378454","pt":1580628389590,"mc":[{"id":"1.168186839","rc":[{"batl":[[0,160,33.99]],"ltp":14.0,"tv":111.63,"id":8639275}]}]}
{"op":"mcm","clk":"1004379112","pt":1580628398575,"mc":[{"id":"1.168186839","rc":[{"batb":[[0,20,11.02],[1,3.85,567.38],[2,1.01,10.52]],"ltp":14.0,"tv":111.63,"id":8639275},{"batb":[[0,1.01,10.51],[1,1.01,0]],"batl":[[0,1.05,1344.31],[1,1.06,8.4],[2,1.06,0]],"ltp":1.06,"tv":4048.4,"id":8173434}]}]}
{"op":"mcm","clk":"1004379151","pt":1580628399604,"mc":[{"id":"1.168186839","rc":[{"batb":[[1,1.01,10.52],[2,1.01,0]],"ltp":14.0,"tv":111.63,"id":8639275}]}]}
{"op":"mcm","clk":"1004379218","pt":1580628401299,"mc":[{"id":"1.168186839","rc":[{"batb":[[0,1.01,2547.29]],"batl":[[0,1.05,3784.46]],"ltp":1.06,"tv":4048.4,"id":8173434}]}]}
{"op":"mcm","clk":"1004379268","pt":1580628402591,"mc":[{"id":"1.168186839","rc":[{"batb":[[0,1.01,10.51]],"batl":[[0,1.05,1344.31]],"ltp":1.06,"tv":4048.4,"id":8173434}]}]}
{"op":"mcm","clk":"1004379301","pt":1580628403418,"mc":[{"id":"1.168186839","rc":[{"trd":[[1.01,21.01]],"batl":[[0,1.01,776.31],[1,1.05,1344.31],[2,1.06,8.4]],"ltp":1.01,"tv":4069.41,"id":8173434}],"tv":4181.05}]}
{"op":"mcm","clk":"1004379378","pt":1580628405581,"mc":[{"id":"1.168186839","rc":[{"trd":[[1.01,1573.59]],"batb":[[0,1.02,1735.66]],"batl":[[0,1.03,2194.67]],"ltp":1.01,"tv":5621.99,"id":8173434}],"tv":5733.62}]}
{"op":"mcm","clk":"1004379469","pt":1580628408309,"mc":[{"id":"1.168186839","rc":[{"batl":[[0,1.05,1344.31],[1,1.06,8.4],[2,1.06,0]],"ltp":1.01,"tv":5621.99,"id":8173434}]}]}
{"op":"mcm","clk":"1004379563","pt":1580628411293,"mc":[{"id":"1.168186839","rc":[{"batb":[[0,1.01,2536.78]],"batl":[[0,1.05,3784.46]],"ltp":1.01,"tv":5621.99,"id":8173434}]}]}
{"op":"mcm","clk":"1004379788","pt":1580628417417,"mc":[{"id":"1.168186839","rc":[{"batb":[[0,1.04,798.26],[1,1.03,1681.51]],"ltp":1.01,"tv":5621.99,"id":8173434}]}]}
{"op":"mcm","clk":"1004379808","pt":1580628418032,"mc":[{"id":"1.168186839","rc":[{"batb":[[1,17,8.81],[2,1.01,10.52]],"ltp":14.0,"tv":111.63,"id":8639275},{"batb":[[2,1.02,1660.74]],"ltp":1.01,"tv":5621.99,"id":8173434}]}]}
{"op":"mcm","clk":"1004379848","pt":1580628419429,"mc":[{"id":"1.168186839","rc":[{"batb":[[2,4.1,558.44]],"ltp":14.0,"tv":111.63,"id":8639275}]}]}
{"op":"mcm","clk":"1004380257","pt":1580628430664,"mc":[{"id":"1.168186839","rc":[{"batb":[[0,17,8.81],[1,4.1,558.44],[2,1.01,10.52]],"ltp":14.0,"tv":111.63,"id":8639275},{"batb":[[2,1.01,3259.62]],"ltp":1.01,"tv":5621.99,"id":8173434}]}]}
{"op":"mcm","clk":"1004380294","pt":1580628431648,"mc":[{"id":"1.168186839","rc":[{"batb":[[1,1.01,10.52],[2,1.01,0]],"ltp":14.0,"tv":111.63,"id":8639275},{"batl":[[0,1.05,1344.31]],"ltp":1.01,"tv":5621.99,"id":8173434}]}]}
{"op":"mcm","clk":"1004380408","pt":1580628434523,"mc":[{"id":"1.168186839","rc":[{"batb":[[0,1.01,2536.78]],"batl":[[1,1.06,920.42],[2,1.07,1491.04]],"ltp":1.01,"tv":5621.99,"id":8173434}]}]}
{"op":"mcm","clk":"1004380960","pt":1580628451290,"mc":[{"id":"1.168186839","rc":[{"batl":[[1,1.06,8.4],[2,1.07,0]],"ltp":1.01,"tv":5621.99,"id":8173434}]}]}
{"op":"mcm","clk":"1004381053","pt":1580628453669,"mc":[{"id":"1.168186839","rc":[{"batl":[[0,1.03,2487.53],[1,1.05,1344.31],[2,1.06,8.4]],"ltp":1.01,"tv":5621.99,"id":8173434}]}]}
{"op":"mcm","clk":"1004381083","pt":1580628454490,"mc":[{"id":"1.168186839","rc":[{"batb":[[0,30,2.87],[1,24,5.92],[2,1.01,10.52]],"ltp":14.0,"tv":111.63,"id":8639275}]}]}
{"op":"mcm","clk":"1004381137","pt":1580628456393,"mc":[{"id":"1.168186839","rc":[{"batb":[[2,4.4,547.35]],"ltp":14.0,"tv":111.63,"id":8639275}]}]}
{"op":"mcm","clk":"1004381413","pt":1580628464180,"mc":[{"id":"1.168186839","rc":[{"batb":[[0,24,5.92],[1,4.4,547.35],[2,1.01,10.52]],"ltp":14.0,"tv":111.63,"id":8639275},{"batl":[[0,1.05,1344.31],[1,1.06,8.4],[2,1.06,0]],"ltp":1.01,"tv":5621.99,"id":8173434}]}]}
{"op":"mcm","clk":"1004381433","pt":1580628465059,"mc":[{"id":"1.168186839","rc":[{"batb":[[1,1.01,10.52],[2,1.01,0]],"ltp":14.0,"tv":111.63,"id":8639275}]}]}
{"op":"mcm","clk":"1004381520","pt":1580628467687,"mc":[{"id":"1.168186839","rc":[{"batl":[[0,1.04,2463.61],[1,1.05,1344.31],[2,1.06,8.4]],"ltp":1.01,"tv":5621.99,"id":8173434}]}]}
{"op":"mcm","clk":"1004381728","pt":1580628472697,"mc":[{"id":"1.168186839","rc":[{"batb":[[0,1.03,2469.56]],"ltp":1.01,"tv":5621.99,"id":8173434}]}]}
{"op":"mcm","clk":"1004381751","pt":1580628473414,"mc":[{"id":"1.168186839","rc":[{"batb":[[1,17,8.58],[2,1.01,10.52]],"ltp":14.0,"tv":111.63,"id":8639275},{"batb":[[1,1.02,2149.9]],"ltp":1.01,"tv":5621.99,"id":8173434}]}]}
{"op":"mcm","clk":"1004381782","pt":1580628474598,"mc":[{"id":"1.168186839","rc":[{"batb":[[2,4.2,553.7]],"ltp":14.0,"tv":111.63,"id":8639275},{"batb":[[2,1.01,3333.85]],"ltp":1.01,"tv":5621.99,"id":8173434}]}]}
{"op":"mcm","clk":"1004382237","pt":1580628485691,"mc":[{"id":"1.168186839","rc":[{"batb":[[2,1.01,4926.34]],"ltp":1.01,"tv":5621.99,"id":8173434}]}]}
{"op":"mcm","clk":"1004382314","pt":1580628487692,"mc":[{"id":"1.168186839","rc":[{"trd":[[1.04,7.58]],"batl":[[0,1.04,2459.82]],"ltp":1.04,"tv":5629.56,"id":8173434}],"tv":5741.2}]}
{"op":"mcm","clk":"1004382527","pt":1580628493614,"mc":[{"id":"1.168186839","rc":[{"batb":[[0,17,8.58],[1,4.2,553.7],[2,1.01,10.52]],"ltp":14.0,"tv":111.63,"id":8639275},{"batb":[[0,1.01,3333.85],[1,1.02,0],[2,1.01,0]],"batl":[[0,1.06,8.4],[1,1.05,0],[2,1.06,0]],"ltp":1.04,"tv":5629.56,"id":8173434}]}]}
{"op":"mcm","clk":"1004382537","pt":1580628493924,"mc":[{"id":"1.168186839","rc":[{"batb":[[1,1.01,10.52],[2,1.01,0]],"ltp":14.0,"tv":111.63,"id":8639275}]}]}
{"op":"mcm","clk":"1004382698","pt":1580628497600,"mc":[{"id":"1.168186839","rc":[{"batl":[[0,1.03,1344.31],[1,1.06,8.4]],"ltp":1.04,"tv":5629.56,"id":8173434}]}]}
{"op":"mcm","clk":"1004382747","pt":1580628498531,"mc":[{"id":"1.168186839","rc":[{"batb":[[0,1.02,2511.92]],"batl":[[0,1.03,3761.33]],"ltp":1.04,"tv":5629.56,"id":8173434}]}]}
{"op":"mcm","clk":"1004382841","pt":1580628500540,"mc":[{"id":"1.168186839","rc":[{"batb":[[1,4.3,548.35],[2,1.01,10.52]],"batl":[[0,160,33.99]],"ltp":14.0,"tv":111.63,"id":8639275}]}]}
{"op":"mcm","clk":"1004382935","pt":1580628502243,"mc":[{"id":"1.168186839","rc":[{"batl":[[0,1.03,1344.31]],"ltp":1.04,"tv":5629.56,"id":8173434}]}]}
{"op":"mcm","clk":"1004383019","pt":1580628503843,"mc":[{"id":"1.168186839","rc":[{"batb":[[1,1.01,10.52],[2,1.01,0]],"ltp":14.0,"tv":111.63,"id":8639275}]}]}
{"op":"mcm","clk":"1004383052","pt":1580628505229,"mc":[{"id":"1.168186839","rc":[{"batl":[[1,1.06,1189.17],[2,1.07,1224.8]],"ltp":1.04,"tv":5629.56,"id":8173434}]}]}
{"op":"mcm","clk":"1004383140","pt":1580628508110,"mc":[{"id":"1.168186839","rc":[{"batl":[[0,1.03,1393.69]],"ltp":1.04,"tv":5629.56,"id":8173434}]}]}
{"op":"mcm","clk":"1004383298","pt":1580628512660,"mc":[{"id":"1.168186839","rc":[{"batl":[[1,1.06,8.4],[2,1.07,0]],"ltp":1.04,"tv":5629.56,"id":8173434}]}]}
{"op":"mcm","clk":"1004383340","pt":1580628513533,"mc":[{"id":"1.168186839","marketDefinition":{"bspMarket":false,"turnInPlayEnabled":true,"persistenceEnabled":true,"marketBaseRate":5.0,"eventId":"29680287","eventTypeId":"2","numberOfWinners":1,"bettingType":"ODDS","marketType":"SET_WINNER","marketTime":"2020-02-02T06:37:00.000Z","suspendTime":"2020-02-02T06:37:00.000Z","bspReconciled":false,"complete":true,"inPlay":true,"crossMatching":true,"runnersVoidable":false,"numberOfActiveRunners":2,"betDelay":3,"status":"SUSPENDED","runners":[{"status":"ACTIVE","sortPriority":1,"id":8173434,"name":"Taro Daniel"},{"status":"ACTIVE","sortPriority":2,"id":8639275,"name":"Yannick Hanfmann"}],"regulators":["MR_INT"],"countryCode":"AU","discountAllowed":true,"timezone":"UTC","openDate":"2020-02-02T06:37:00.000Z","version":3148286154,"name":"Set 1 Winner","eventName":"Daniel v Hanfmann"},"rc":[{"batb":[[0,1.01,10.52],[1,1.01,0]],"ltp":14.0,"tv":111.63,"id":8639275}]}]}
{"op":"mcm","clk":"1004383636","pt":1580628522964,"mc":[{"id":"1.168186839","rc":[{"batl":[[0,1.03,49.38]],"ltp":1.04,"tv":5629.56,"id":8173434}]}]}
{"op":"mcm","clk":"1004383751","pt":1580628526872,"mc":[{"id":"1.168186839","rc":[{"batl":[[1,1.06,0]],"ltp":1.04,"tv":5629.56,"id":8173434}]}]}
{"op":"mcm","clk":"1004384484","pt":1580628546295,"mc":[{"id":"1.168186839","tv":0.0}]}
{"op":"mcm","clk":"1004384541","pt":1580628547580,"mc":[{"id":"1.168186839","marketDefinition":{"bspMarket":false,"turnInPlayEnabled":true,"persistenceEnabled":true,"marketBaseRate":5.0,"eventId":"29680287","eventTypeId":"2","numberOfWinners":1,"bettingType":"ODDS","marketType":"SET_WINNER","marketTime":"2020-02-02T06:37:00.000Z","suspendTime":"2020-02-02T06:37:00.000Z","bspReconciled":false,"complete":true,"inPlay":true,"crossMatching":false,"runnersVoidable":false,"numberOfActiveRunners":0,"betDelay":3,"status":"CLOSED","settledTime":"2020-02-02T07:29:04.000Z","runners":[{"status":"WINNER","sortPriority":1,"id":8173434,"name":"Taro Daniel"},{"status":"LOSER","sortPriority":2,"id":8639275,"name":"Yannick Hanfmann"}],"regulators":["MR_INT"],"countryCode":"AU","discountAllowed":true,"timezone":"UTC","openDate":"2020-02-02T06:37:00.000Z","version":3148286209,"name":"Set 1 Winner","eventName":"Daniel v Hanfmann"}}]}
