{"op":"mcm","clk":"993170579","pt":1580537866635,"mc":[{"id":"1.168186838","marketDefinition":{"bspMarket":false,"turnInPlayEnabled":true,"persistenceEnabled":true,"marketBaseRate":5.0,"eventId":"29680287","eventTypeId":"2","numberOfWinners":1,"bettingType":"ODDS","marketType":"SET_BETTING","marketTime":"2020-02-02T02:00:00.000Z","suspendTime":"2020-02-02T02:00:00.000Z","bspReconciled":false,"complete":true,"inPlay":false,"crossMatching":false,"runnersVoidable":false,"numberOfActiveRunners":4,"betDelay":0,"status":"OPEN","runners":[{"status":"ACTIVE","sortPriority":1,"id":531005,"name":"Daniel 2 - 0"},{"status":"ACTIVE","sortPriority":2,"id":531006,"name":"Daniel 2 - 1"},{"status":"ACTIVE","sortPriority":3,"id":8679736,"name":"Hanfmann 2 - 0"},{"status":"ACTIVE","sortPriority":4,"id":8679737,"name":"Hanfmann 2 - 1"}],"regulators":["MR_INT"],"countryCode":"AU","discountAllowed":false,"timezone":"UTC","openDate":"2020-02-02T02:00:00.000Z","version":3144541439,"name":"Set Betting","eventName":"Daniel v Hanfmann"}}]}
{"op":"mcm","clk":"993170622","pt":1580537867691,"mc":[{"id":"1.168186838","marketDefinition":{"bspMarket":false,"turnInPlayEnabled":true,"persistenceEnabled":true,"marketBaseRate":5.0,"eventId":"29680287","eventTypeId":"2","numberOfWinners":1,"bettingType":"ODDS","marketType":"SET_BETTING","marketTime":"2020-02-02T02:00:00.000Z","suspendTime":"2020-02-02T02:00:00.000Z","bspReconciled":false,"complete":true,"inPlay":false,"crossMatching":false,"runnersVoidable":false,"numberOfActiveRunners":4,"betDelay":0,"status":"OPEN","runners":[{"status":"ACTIVE","sortPriority":1,"id":531005,"name":"Daniel 2 - 0"},{"status":"ACTIVE","sortPriority":2,"id":531006,"name":"Daniel 2 - 1"},{"status":"ACTIVE","sortPriority":3,"id":8679736,"name":"Hanfmann 2 - 0"},{"status":"ACTIVE","sortPriority":4,"id":8679737,"name":"Hanfmann 2 - 1"}],"regulators":["MR_INT"],"countryCode":"AU","discountAllowed":true,"timezone":"UTC","openDate":"2020-02-02T02:00:00.000Z","version":3144541439,"name":"Set Betting","eventName":"Daniel v Hanfmann"}}]}
{"op":"mcm","clk":"993355327","pt":1580541143395,"mc":[{"id":"1.168186838","rc":[{"batb":[[0,1.02,2]],"ltp":0.0,"tv":0.0,"id":8679736},{"batb":[[0,1.02,2]],"ltp":0.0,"tv":0.0,"id":8679737},{"batb":[[0,1.02,2]],"ltp":0.0,"tv":0.0,"id":531006},{"batb":[[0,1.02,2]],"ltp":0.0,"tv":0.0,"id":531005}]}]}
{"op":"mcm","clk":"994994086","pt":1580554910776,"mc":[{"id":"1.168186838","rc":[{"batb":[[0,2.5,30.29],[1,1.02,2]],"ltp":0.0,"tv":0.0,"id":8679736}]}]}
{"op":"mcm","clk":"995420441","pt":1580556859488,"mc":[{"id":"1.168186838","rc":[{"batb":[[0,2.38,30.29]],"ltp":0.0,"tv":0.0,"id":8679736},{"batb":[[0,2.74,30.29],[1,1.02,2]],"ltp":0.0,"tv":0.0,"id":531005}]}]}
{"op":"mcm","clk":"996509328","pt":1580562460649,"mc":[{"id":"1.168186838","rc":[{"batb":[[0,1.02,2],[1,1.02,0]],"ltp":0.0,"tv":0.0,"id":8679736},{"batb":[[0,2.86,30.29]],"ltp":0.0,"tv":0.0,"id":531005}]}]}
{"op":"mcm","clk":"996509348","pt":1580562460722,"mc":[{"id":"1.168186838","rc":[{"batb":[[0,2.3,30.29],[1,1.02,2]],"ltp":0.0,"tv":0.0,"id":8679736}]}]}
{"op":"mcm","clk":"996586095","pt":1580562825623,"mc":[{"id":"1.168186838","rc":[{"batb":[[0,1.02,2],[1,1.02,0]],"ltp":0.0,"tv":0.0,"id":8679736},{"batb":[[0,2.9,30.29]],"ltp":0.0,"tv":0.0,"id":531005}]}]}
{"op":"mcm","clk":"996586123","pt":1580562825802,"mc":[{"id":"1.168186838","rc":[{"batb":[[0,2.26,30.29],[1,1.02,2]],"ltp":0.0,"tv":0.0,"id":8679736}]}]}
{"op":"mcm","clk":"996661524","pt":1580563191535,"mc":[{"id":"1.168186838","rc":[{"batb":[[0,2.84,30.29]],"ltp":0.0,"tv":0.0,"id":531005}]}]}
{"op":"mcm","clk":"996661688","pt":1580563192253,"mc":[{"id":"1.168186838","rc":[{"batb":[[0,2.3,30.29]],"ltp":0.0,"tv":0.0,"id":8679736}]}]}
{"op":"mcm","clk":"998768267","pt":1580572079014,"mc":[{"id":"1.168186838","rc":[{"batb":[[0,2.4,30.29]],"ltp":0.0,"tv":0.0,"id":8679736}]}]}
{"op":"mcm","clk":"999109070","pt":1580573579324,"mc":[{"id":"1.168186838","rc":[{"batb":[[0,2.54,101.12],[1,2.4,30.29],[2,1.02,2]],"batl":[[0,4.2,369.83]],"ltp":0.0,"tv":0.0,"id":8679736},{"batb":[[0,3.75,68.15],[1,1.02,2]],"batl":[[0,8,319.9]],"ltp":0.0,"tv":0.0,"id":8679737},{"batb":[[0,3.4,75.21],[1,1.02,2]],"batl":[[0,9.8,256.82]],"ltp":0.0,"tv":0.0,"id":531006},{"batb":[[0,2.96,86.63],[1,2.84,30.29],[2,1.02,2]],"batl":[[0,5.7,409.15]],"ltp":0.0,"tv":0.0,"id":531005}]}]}
{"op":"mcm","clk":"999132432","pt":1580573662618,"mc":[{"id":"1.168186838","rc":[{"batb":[[1,1.02,2],[2,1.02,0]],"ltp":0.0,"tv":0.0,"id":531005}]}]}
{"op":"mcm","clk":"999132736","pt":1580573663599,"mc":[{"id":"1.168186838","rc":[{"batb":[[0,2.56,30.29],[1,2.54,101.12]],"ltp":0.0,"tv":0.0,"id":8679736},{"batb":[[0,3,85.57],[1,2.98,30.29],[2,1.02,2]],"ltp":0.0,"tv":0.0,"id":531005}]}]}
{"op":"mcm","clk":"999132817","pt":1580573663921,"mc":[{"id":"1.168186838","rc":[{"batb":[[0,2.7,94.92],[1,2.56,30.29]],"ltp":0.0,"tv":0.0,"id":8679736}]}]}
{"op":"mcm","clk":"999166960","pt":1580573784412,"mc":[{"id":"1.168186838","rc":[{"batb":[[0,3.05,30.29],[1,3,85.57]],"ltp":0.0,"tv":0.0,"id":531005}]}]}
{"op":"mcm","clk":"999167303","pt":1580573785644,"mc":[{"id":"1.168186838","rc":[{"batb":[[0,2.78,92.16],[1,2.72,30.29]],"ltp":0.0,"tv":0.0,"id":8679736},{"batb":[[0,3.15,81.23],[1,3.05,30.29]],"ltp":0.0,"tv":0.0,"id":531005}]}]}
{"op":"mcm","clk":"999201290","pt":1580573906615,"mc":[{"id":"1.168186838","rc":[{"batb":[[1,1.02,2],[2,1.02,0]],"ltp":0.0,"tv":0.0,"id":8679736},{"batb":[[0,3.2,110.26],[1,1.02,2],[2,1.02,0]],"ltp":0.0,"tv":0.0,"id":531005}]}]}
{"op":"mcm","clk":"999234524","pt":1580574028244,"mc":[{"id":"1.168186838","rc":[{"batb":[[0,3.25,30.29]],"ltp":0.0,"tv":0.0,"id":531005}]}]}
{"op":"mcm","clk":"999268410","pt":1580574149564,"mc":[{"id":"1.168186838","rc":[{"batb":[[0,2.84,30.29]],"ltp":0.0,"tv":0.0,"id":531005}]}]}
{"op":"mcm","clk":"999268600","pt":1580574150535,"mc":[{"id":"1.168186838","rc":[{"batb":[[0,3,85.57],[1,2.84,30.29],[2,1.02,2]],"ltp":0.0,"tv":0.0,"id":531005}]}]}
{"op":"mcm","clk":"999299955","pt":1580574271613,"mc":[{"id":"1.168186838","rc":[{"batb":[[0,3.15,81.23],[1,3.05,30.29]],"ltp":0.0,"tv":0.0,"id":531005}]}]}
{"op":"mcm","clk":"999331873","pt":1580574393379,"mc":[{"id":"1.168186838","rc":[{"batb":[[0,3.2,110.26],[1,1.02,2],[2,1.02,0]],"ltp":0.0,"tv":0.0,"id":531005}]}]}
{"op":"mcm","clk":"999362033","pt":1580574514640,"mc":[{"id":"1.168186838","rc":[{"batb":[[0,3.2,79.97]],"ltp":0.0,"tv":0.0,"id":531005}]}]}
{"op":"mcm","clk":"999362087","pt":1580574514930,"mc":[{"id":"1.168186838","rc":[{"batb":[[0,3.25,30.29]],"ltp":0.0,"tv":0.0,"id":531005}]}]}
{"op":"mcm","clk":"999391922","pt":1580574636427,"mc":[{"id":"1.168186838","rc":[{"batb":[[0,2.84,30.29]],"ltp":0.0,"tv":0.0,"id":531005}]}]}
{"op":"mcm","clk":"999392636","pt":1580574639365,"mc":[{"id":"1.168186838","rc":[{"batb":[[0,3.05,84.09],[1,2.84,30.29],[2,1.02,2]],"ltp":0.0,"tv":0.0,"id":531005}]}]}
{"op":"mcm","clk":"999424514","pt":1580574758533,"mc":[{"id":"1.168186838","rc":[{"batb":[[0,3.1,30.29],[1,1.02,2],[2,1.02,0]],"ltp":0.0,"tv":0.0,"id":531005}]}]}
{"op":"mcm","clk":"999424567","pt":1580574758750,"mc":[{"id":"1.168186838","rc":[{"batb":[[0,3.15,81.23],[1,3.1,30.29],[2,1.02,2]],"ltp":0.0,"tv":0.0,"id":531005}]}]}
{"op":"mcm","clk":"999456870","pt":1580574880439,"mc":[{"id":"1.168186838","rc":[{"batb":[[0,3.2,110.26],[1,1.02,2],[2,1.02,0]],"ltp":0.0,"tv":0.0,"id":531005}]}]}
{"op":"mcm","clk":"999487178","pt":1580575001685,"mc":[{"id":"1.168186838","rc":[{"batb":[[0,3.25,30.29],[1,3.2,79.97],[2,1.02,2]],"ltp":0.0,"tv":0.0,"id":531005}]}]}
{"op":"mcm","clk":"999487287","pt":1580575002087,"mc":[{"id":"1.168186838","rc":[{"batb":[[1,1.02,2],[2,1.02,0]],"ltp":0.0,"tv":0.0,"id":531005}]}]}
{"op":"mcm","clk":"999518010","pt":1580575124541,"mc":[{"id":"1.168186838","rc":[{"batb":[[0,3.05,84.09],[1,2.84,30.29],[2,1.02,2]],"ltp":0.0,"tv":0.0,"id":531005}]}]}
{"op":"mcm","clk":"999547753","pt":1580575246448,"mc":[{"id":"1.168186838","rc":[{"batb":[[0,3.15,81.23],[1,3.1,30.29]],"ltp":0.0,"tv":0.0,"id":531005}]}]}
{"op":"mcm","clk":"999575865","pt":1580575367609,"mc":[{"id":"1.168186838","rc":[{"batb":[[0,3.2,30.29],[1,3.15,81.23]],"ltp":0.0,"tv":0.0,"id":531005}]}]}
{"op":"mcm","clk":"999575956","pt":1580575367991,"mc":[{"id":"1.168186838","rc":[{"batb":[[0,3.2,110.26],[1,1.02,2],[2,1.02,0]],"ltp":0.0,"tv":0.0,"id":531005}]}]}
{"op":"mcm","clk":"999617372","pt":1580575556644,"mc":[{"id":"1.168186838","rc":[{"batb":[[0,3.25,30.29]],"ltp":0.0,"tv":0.0,"id":531005}]}]}
{"op":"mcm","clk":"999640935","pt":1580575678591,"mc":[{"id":"1.168186838","rc":[{"batb":[[0,2.84,30.29],[1,2.66,96.34],[2,1.02,2]],"ltp":0.0,"tv":0.0,"id":531005}]}]}
{"op":"mcm","clk":"999641003","pt":1580575678968,"mc":[{"id":"1.168186838","rc":[{"batb":[[0,2.86,89.68],[1,2.84,30.29]],"ltp":0.0,"tv":0.0,"id":531005}]}]}
{"op":"mcm","clk":"999661291","pt":1580575799634,"mc":[{"id":"1.168186838","rc":[{"batb":[[1,1.02,2],[2,1.02,0]],"ltp":0.0,"tv":0.0,"id":531005}]}]}
{"op":"mcm","clk":"999661487","pt":1580575800653,"mc":[{"id":"1.168186838","rc":[{"batb":[[0,3.1,82.54],[1,2.88,30.28],[2,1.02,2]],"ltp":0.0,"tv":0.0,"id":531005}]}]}
{"op":"mcm","clk":"999681842","pt":1580575922641,"mc":[{"id":"1.168186838","rc":[{"batb":[[0,3.2,79.97],[1,3.15,30.29]],"ltp":0.0,"tv":0.0,"id":531005}]}]}
{"op":"mcm","clk":"999701268","pt":1580576044678,"mc":[{"id":"1.168186838","rc":[{"batb":[[0,3.25,30.29],[1,1.02,2],[2,1.02,0]],"ltp":0.0,"tv":0.0,"id":531005}]}]}
{"op":"mcm","clk":"999719149","pt":1580576166670,"mc":[{"id":"1.168186838","rc":[{"batb":[[0,2.84,30.29]],"ltp":0.0,"tv":0.0,"id":531005}]}]}
{"op":"mcm","clk":"999719160","pt":1580576166752,"mc":[{"id":"1.168186838","rc":[{"batb":[[0,2.86,89.68],[1,2.84,30.29],[2,1.02,2]],"ltp":0.0,"tv":0.0,"id":531005}]}]}
{"op":"mcm","clk":"999733918","pt":1580576288632,"mc":[{"id":"1.168186838","rc":[{"batb":[[1,1.02,2],[2,1.02,0]],"ltp":0.0,"tv":0.0,"id":531005}]}]}
{"op":"mcm","clk":"999734052","pt":1580576289587,"mc":[{"id":"1.168186838","rc":[{"batb":[[0,2.9,88.36],[1,2.88,30.28],[2,1.02,2]],"ltp":0.0,"tv":0.0,"id":531005}]}]}
{"op":"mcm","clk":"999748745","pt":1580576410371,"mc":[{"id":"1.168186838","rc":[{"batb":[[1,1.02,2],[2,1.02,0]],"ltp":0.0,"tv":0.0,"id":531005}]}]}
{"op":"mcm","clk":"999748876","pt":1580576411245,"mc":[{"id":"1.168186838","rc":[{"batb":[[0,3,85.57],[1,2.92,30.29],[2,1.02,2]],"ltp":0.0,"tv":0.0,"id":531005}]}]}
{"op":"mcm","clk":"999765481","pt":1580576532512,"mc":[{"id":"1.168186838","rc":[{"batb":[[0,3.05,30.29],[1,3,85.57]],"ltp":0.0,"tv":0.0,"id":531005}]}]}
{"op":"mcm","clk":"999765537","pt":1580576532932,"mc":[{"id":"1.168186838","rc":[{"batb":[[0,3.1,82.54],[1,3.05,30.29]],"ltp":0.0,"tv":0.0,"id":531005}]}]}
{"op":"mcm","clk":"999783945","pt":1580576656623,"mc":[{"id":"1.168186838","rc":[{"batb":[[0,3.2,79.97],[1,3.15,30.29]],"ltp":0.0,"tv":0.0,"id":531005}]}]}
{"op":"mcm","clk":"999802879","pt":1580576777661,"mc":[{"id":"1.168186838","rc":[{"batb":[[0,3.25,30.29],[1,3.2,79.97]],"ltp":0.0,"tv":0.0,"id":531005}]}]}
{"op":"mcm","clk":"999802933","pt":1580576777919,"mc":[{"id":"1.168186838","rc":[{"batb":[[1,1.02,2],[2,1.02,0]],"ltp":0.0,"tv":0.0,"id":531005}]}]}
{"op":"mcm","clk":"999820863","pt":1580576899594,"mc":[{"id":"1.168186838","rc":[{"batb":[[0,2.84,30.29]],"ltp":0.0,"tv":0.0,"id":531005}]}]}
{"op":"mcm","clk":"999820907","pt":1580576899873,"mc":[{"id":"1.168186838","rc":[{"batb":[[0,3.1,82.54],[1,2.84,30.29],[2,1.02,2]],"ltp":0.0,"tv":0.0,"id":531005}]}]}
{"op":"mcm","clk":"999839329","pt":1580577021580,"mc":[{"id":"1.168186838","rc":[{"batb":[[0,3.15,30.29],[1,1.02,2],[2,1.02,0]],"ltp":0.0,"tv":0.0,"id":531005}]}]}
{"op":"mcm","clk":"999839367","pt":1580577021776,"mc":[{"id":"1.168186838","rc":[{"batb":[[0,3.2,79.97],[1,3.15,30.29],[2,1.02,2]],"ltp":0.0,"tv":0.0,"id":531005}]}]}
{"op":"mcm","clk":"999857785","pt":1580577143332,"mc":[{"id":"1.168186838","rc":[{"batb":[[0,3.25,30.29],[1,1.02,2],[2,1.02,0]],"ltp":0.0,"tv":0.0,"id":531005}]}]}
{"op":"mcm","clk":"999863404","pt":1580577179485,"mc":[{"id":"1.168186838","rc":[{"batb":[[0,1.02,2],[1,1.02,0]],"ltp":0.0,"tv":0.0,"id":8679737},{"batb":[[0,1.02,2],[1,1.02,0]],"ltp":0.0,"tv":0.0,"id":531006},{"batl":[[0,5.1,457.15]],"ltp":0.0,"tv":0.0,"id":531005}]}]}
{"op":"mcm","clk":"999863554","pt":1580577180458,"mc":[{"id":"1.168186838","rc":[{"batb":[[0,2.5,102.82]],"batl":[[0,4.8,323.77]],"ltp":0.0,"tv":0.0,"id":8679736},{"batb":[[0,3.25,78.73],[1,1.02,2]],"batl":[[0,8.4,304.49]],"ltp":0.0,"tv":0.0,"id":8679737},{"batb":[[0,3.55,71.99],[1,1.02,2]],"batl":[[0,9.8,256.82]],"ltp":0.0,"tv":0.0,"id":531006}]}]}
{"op":"mcm","clk":"999876290","pt":1580577264665,"mc":[{"id":"1.168186838","rc":[{"batb":[[0,2.84,30.29]],"ltp":0.0,"tv":0.0,"id":531005}]}]}
{"op":"mcm","clk":"999876443","pt":1580577265688,"mc":[{"id":"1.168186838","rc":[{"batb":[[0,2.64,97.32],[1,2.52,30.29],[2,1.02,2]],"ltp":0.0,"tv":0.0,"id":8679736},{"batb":[[0,2.9,88.36],[1,2.84,30.29],[2,1.02,2]],"ltp":0.0,"tv":0.0,"id":531005}]}]}
{"op":"mcm","clk":"999895255","pt":1580577386561,"mc":[{"id":"1.168186838","rc":[{"batb":[[0,2.92,30.29],[1,2.9,88.36]],"ltp":0.0,"tv":0.0,"id":531005}]}]}
{"op":"mcm","clk":"999895415","pt":1580577387649,"mc":[{"id":"1.168186838","rc":[{"batb":[[0,2.66,30.29],[1,2.64,97.32]],"ltp":0.0,"tv":0.0,"id":8679736},{"batb":[[0,2.94,87.09],[1,2.92,30.29]],"ltp":0.0,"tv":0.0,"id":531005}]}]}
{"op":"mcm","clk":"999895469","pt":1580577388027,"mc":[{"id":"1.168186838","rc":[{"batb":[[0,2.7,94.92],[1,2.66,30.29]],"ltp":0.0,"tv":0.0,"id":8679736}]}]}
{"op":"mcm","clk":"999914171","pt":1580577509555,"mc":[{"id":"1.168186838","rc":[{"batb":[[0,2.96,30.29],[1,1.02,2],[2,1.02,0]],"ltp":0.0,"tv":0.0,"id":531005}]}]}
{"op":"mcm","clk":"999914279","pt":1580577510310,"mc":[{"id":"1.168186838","rc":[{"batb":[[0,2.74,93.52],[1,2.72,30.29]],"ltp":0.0,"tv":0.0,"id":8679736},{"batb":[[0,3,85.57],[1,2.96,30.29],[2,1.02,2]],"ltp":0.0,"tv":0.0,"id":531005}]}]}
{"op":"mcm","clk":"999932853","pt":1580577631572,"mc":[{"id":"1.168186838","rc":[{"batb":[[0,2.76,30.29],[1,2.74,93.52]],"ltp":0.0,"tv":0.0,"id":8679736},{"batb":[[0,3.1,82.54],[1,3.05,30.29]],"ltp":0.0,"tv":0.0,"id":531005}]}]}
{"op":"mcm","clk":"999932932","pt":1580577632108,"mc":[{"id":"1.168186838","rc":[{"batb":[[0,2.78,92.16],[1,2.76,30.29]],"ltp":0.0,"tv":0.0,"id":8679736}]}]}
{"op":"mcm","clk":"999951032","pt":1580577752617,"mc":[{"id":"1.168186838","rc":[{"batb":[[0,3.15,30.29],[1,3.1,82.54]],"ltp":0.0,"tv":0.0,"id":531005}]}]}
{"op":"mcm","clk":"999951137","pt":1580577753417,"mc":[{"id":"1.168186838","rc":[{"batb":[[1,1.02,2],[2,1.02,0]],"ltp":0.0,"tv":0.0,"id":8679736},{"batb":[[0,3.2,79.97],[1,3.15,30.29]],"ltp":0.0,"tv":0.0,"id":531005}]}]}
{"op":"mcm","clk":"999969928","pt":1580577874471,"mc":[{"id":"1.168186838","rc":[{"batb":[[0,3.25,30.29],[1,3.2,79.97]],"ltp":0.0,"tv":0.0,"id":531005}]}]}
{"op":"mcm","clk":"999969979","pt":1580577874739,"mc":[{"id":"1.168186838","rc":[{"batb":[[1,1.02,2],[2,1.02,0]],"ltp":0.0,"tv":0.0,"id":531005}]}]}
{"op":"mcm","clk":"999988990","pt":1580577996604,"mc":[{"id":"1.168186838","rc":[{"batb":[[0,2.88,88.96],[1,2.84,30.29],[2,1.02,2]],"ltp":0.0,"tv":0.0,"id":531005}]}]}
{"op":"mcm","clk":"1000007652","pt":1580578118165,"mc":[{"id":"1.168186838","rc":[{"batb":[[0,2.94,87.09],[1,2.9,30.29]],"ltp":0.0,"tv":0.0,"id":531005}]}]}
{"op":"mcm","clk":"1000026762","pt":1580578239558,"mc":[{"id":"1.168186838","rc":[{"batb":[[0,2.96,30.29],[1,2.94,87.09]],"ltp":0.0,"tv":0.0,"id":531005}]}]}
{"op":"mcm","clk":"1000026845","pt":1580578239983,"mc":[{"id":"1.168186838","rc":[{"batb":[[0,3.1,82.54],[1,2.96,30.29]],"ltp":0.0,"tv":0.0,"id":531005}]}]}
{"op":"mcm","clk":"1000047364","pt":1580578362606,"mc":[{"id":"1.168186838","rc":[{"batb":[[0,3.15,30.29],[1,3.1,82.54]],"ltp":0.0,"tv":0.0,"id":531005}]}]}
{"op":"mcm","clk":"1000047432","pt":1580578362985,"mc":[{"id":"1.168186838","rc":[{"batb":[[0,3.2,79.97],[1,3.15,30.29]],"ltp":0.0,"tv":0.0,"id":531005}]}]}
{"op":"mcm","clk":"1000068232","pt":1580578484599,"mc":[{"id":"1.168186838","rc":[{"batb":[[0,3.25,30.29],[1,3.2,79.97]],"ltp":0.0,"tv":0.0,"id":531005}]}]}
{"op":"mcm","clk":"1000068263","pt":1580578484812,"mc":[{"id":"1.168186838","rc":[{"batb":[[1,1.02,2],[2,1.02,0]],"ltp":0.0,"tv":0.0,"id":531005}]}]}
{"op":"mcm","clk":"1000090002","pt":1580578606518,"mc":[{"id":"1.168186838","rc":[{"batb":[[0,2.84,30.29],[1,2.62,98.04],[2,1.02,2]],"ltp":0.0,"tv":0.0,"id":531005}]}]}
{"op":"mcm","clk":"1000090082","pt":1580578606945,"mc":[{"id":"1.168186838","rc":[{"batb":[[0,3,85.57],[1,2.84,30.29]],"ltp":0.0,"tv":0.0,"id":531005}]}]}
{"op":"mcm","clk":"1000110372","pt":1580578728351,"mc":[{"id":"1.168186838","rc":[{"batb":[[0,3.1,82.54],[1,3.05,30.29]],"ltp":0.0,"tv":0.0,"id":531005}]}]}
{"op":"mcm","clk":"1000129678","pt":1580578849491,"mc":[{"id":"1.168186838","rc":[{"batb":[[0,3.15,30.29],[1,3.1,82.54]],"ltp":0.0,"tv":0.0,"id":531005}]}]}
{"op":"mcm","clk":"1000129796","pt":1580578850184,"mc":[{"id":"1.168186838","rc":[{"batb":[[0,3.2,79.97],[1,3.15,30.29]],"ltp":0.0,"tv":0.0,"id":531005}]}]}
{"op":"mcm","clk":"1000149733","pt":1580578971512,"mc":[{"id":"1.168186838","rc":[{"batb":[[0,3.25,30.29],[1,1.02,2],[2,1.02,0]],"ltp":0.0,"tv":0.0,"id":531005}]}]}
{"op":"mcm","clk":"1000167959","pt":1580579093405,"mc":[{"id":"1.168186838","rc":[{"batb":[[0,3.05,84.09],[1,2.84,30.29],[2,1.02,2]],"ltp":0.0,"tv":0.0,"id":531005}]}]}
{"op":"mcm","clk":"1000186974","pt":1580579215232,"mc":[{"id":"1.168186838","rc":[{"batb":[[0,3.15,81.23],[1,3.1,30.29]],"ltp":0.0,"tv":0.0,"id":531005}]}]}
{"op":"mcm","clk":"1000204220","pt":1580579336637,"mc":[{"id":"1.168186838","rc":[{"batb":[[0,3.2,30.29],[1,3.15,81.23]],"ltp":0.0,"tv":0.0,"id":531005}]}]}
{"op":"mcm","clk":"1000204294","pt":1580579337116,"mc":[{"id":"1.168186838","rc":[{"batb":[[0,3.2,110.26],[1,1.02,2],[2,1.02,0]],"ltp":0.0,"tv":0.0,"id":531005}]}]}
{"op":"mcm","clk":"1000221858","pt":1580579458389,"mc":[{"id":"1.168186838","rc":[{"batb":[[0,3.25,30.29]],"ltp":0.0,"tv":0.0,"id":531005}]}]}
{"op":"mcm","clk":"1000239995","pt":1580579580577,"mc":[{"id":"1.168186838","rc":[{"batb":[[0,2.86,89.68],[1,2.84,30.29],[2,1.02,2]],"ltp":0.0,"tv":0.0,"id":531005}]}]}
{"op":"mcm","clk":"1000256324","pt":1580579701436,"mc":[{"id":"1.168186838","rc":[{"batb":[[1,1.02,2],[2,1.02,0]],"ltp":0.0,"tv":0.0,"id":531005}]}]}
{"op":"mcm","clk":"1000256481","pt":1580579702671,"mc":[{"id":"1.168186838","rc":[{"batb":[[0,2.88,30.28]],"ltp":0.0,"tv":0.0,"id":531005}]}]}
{"op":"mcm","clk":"1000256514","pt":1580579703090,"mc":[{"id":"1.168186838","rc":[{"batb":[[0,2.9,88.36],[1,2.88,30.28],[2,1.02,2]],"ltp":0.0,"tv":0.0,"id":531005}]}]}
{"op":"mcm","clk":"1000271812","pt":1580579823696,"mc":[{"id":"1.168186838","rc":[{"batb":[[0,2.92,30.29],[1,2.9,88.36]],"ltp":0.0,"tv":0.0,"id":531005}]}]}
{"op":"mcm","clk":"1000271877","pt":1580579824066,"mc":[{"id":"1.168186838","rc":[{"batb":[[0,2.96,86.63],[1,2.92,30.29]],"ltp":0.0,"tv":0.0,"id":531005}]}]}
{"op":"mcm","clk":"1000304589","pt":1580580066528,"mc":[{"id":"1.168186838","rc":[{"batb":[[0,2.98,30.29],[1,2.96,86.63]],"ltp":0.0,"tv":0.0,"id":531005}]}]}
{"op":"mcm","clk":"1000304666","pt":1580580066916,"mc":[{"id":"1.168186838","rc":[{"batb":[[0,3.05,84.09],[1,2.98,30.29]],"ltp":0.0,"tv":0.0,"id":531005}]}]}
{"op":"mcm","clk":"1000322236","pt":1580580188616,"mc":[{"id":"1.168186838","rc":[{"batb":[[0,3.15,81.23],[1,3.1,30.29]],"ltp":0.0,"tv":0.0,"id":531005}]}]}
{"op":"mcm","clk":"1000339034","pt":1580580310398,"mc":[{"id":"1.168186838","rc":[{"batb":[[0,3.2,110.26],[1,1.02,2],[2,1.02,0]],"ltp":0.0,"tv":0.0,"id":531005}]}]}
{"op":"mcm","clk":"1000356916","pt":1580580431558,"mc":[{"id":"1.168186838","rc":[{"batb":[[0,3.25,30.29],[1,3.2,79.97],[2,1.02,2]],"ltp":0.0,"tv":0.0,"id":531005}]}]}
{"op":"mcm","clk":"1000356960","pt":1580580431788,"mc":[{"id":"1.168186838","rc":[{"batb":[[1,1.02,2],[2,1.02,0]],"ltp":0.0,"tv":0.0,"id":531005}]}]}
{"op":"mcm","clk":"1000376029","pt":1580580553597,"mc":[{"id":"1.168186838","rc":[{"batb":[[0,2.84,30.29],[1,2.7,94.92],[2,1.02,2]],"ltp":0.0,"tv":0.0,"id":531005}]}]}
{"op":"mcm","clk":"1000376089","pt":1580580553997,"mc":[{"id":"1.168186838","rc":[{"batb":[[0,2.92,87.69],[1,2.84,30.29]],"ltp":0.0,"tv":0.0,"id":531005}]}]}
{"op":"mcm","clk":"1000395871","pt":1580580675449,"mc":[{"id":"1.168186838","rc":[{"batb":[[0,3,85.57],[1,2.94,30.29]],"ltp":0.0,"tv":0.0,"id":531005}]}]}
{"op":"mcm","clk":"1000411292","pt":1580580780133,"mc":[{"id":"1.168186838","rc":[{"batb":[[0,1.02,2],[1,1.02,0]],"batl":[[0,9,284.44]],"ltp":0.0,"tv":0.0,"id":8679737},{"batb":[[0,1.02,2],[1,1.02,0]],"ltp":0.0,"tv":0.0,"id":531006},{"batl":[[0,5.5,423.97]],"ltp":0.0,"tv":0.0,"id":531005}]}]}
{"op":"mcm","clk":"1000411453","pt":1580580781123,"mc":[{"id":"1.168186838","rc":[{"batb":[[0,1.02,2],[1,1.02,0]],"batl":[[0,4,388.49]],"ltp":0.0,"tv":0.0,"id":8679736}]}]}
{"op":"mcm","clk":"1000411549","pt":1580580781724,"mc":[{"id":"1.168186838","rc":[{"batb":[[0,2.46,104.38],[1,1.02,2]],"ltp":0.0,"tv":0.0,"id":8679736}]}]}
{"op":"mcm","clk":"1000413834","pt":1580580796675,"mc":[{"id":"1.168186838","rc":[{"batb":[[0,3.05,30.29],[1,3,85.57]],"ltp":0.0,"tv":0.0,"id":531005}]}]}
{"op":"mcm","clk":"1000413977","pt":1580580797648,"mc":[{"id":"1.168186838","rc":[{"batb":[[0,2.5,102.82],[1,2.48,30.29],[2,1.02,2]],"ltp":0.0,"tv":0.0,"id":8679736},{"batb":[[0,3.1,82.54],[1,3.05,30.29]],"ltp":0.0,"tv":0.0,"id":531005}]}]}
{"op":"mcm","clk":"1000433082","pt":1580580918689,"mc":[{"id":"1.168186838","rc":[{"batb":[[0,3.2,79.97],[1,3.15,30.29]],"ltp":0.0,"tv":0.0,"id":531005}]}]}
{"op":"mcm","clk":"1000433185","pt":1580580919336,"mc":[{"id":"1.168186838","rc":[{"batb":[[0,2.56,100.33],[1,2.52,30.29]],"ltp":0.0,"tv":0.0,"id":8679736}]}]}
{"op":"mcm","clk":"1000450282","pt":1580581040587,"mc":[{"id":"1.168186838","rc":[{"batb":[[1,1.02,2],[2,1.02,0]],"ltp":0.0,"tv":0.0,"id":8679736},{"batb":[[0,3.25,30.29],[1,1.02,2],[2,1.02,0]],"ltp":0.0,"tv":0.0,"id":531005}]}]}
{"op":"mcm","clk":"1000450385","pt":1580581041235,"mc":[{"id":"1.168186838","rc":[{"batb":[[0,2.64,97.32],[1,2.58,30.29],[2,1.02,2]],"ltp":0.0,"tv":0.0,"id":8679736}]}]}
{"op":"mcm","clk":"1000467224","pt":1580581161689,"mc":[{"id":"1.168186838","rc":[{"batb":[[0,1.02,2],[1,1.02,0]],"ltp":0.0,"tv":0.0,"id":531005}]}]}
{"op":"mcm","clk":"1000467339","pt":1580581162598,"mc":[{"id":"1.168186838","rc":[{"batb":[[0,2.66,30.29],[1,1.02,2],[2,1.02,0]],"ltp":0.0,"tv":0.0,"id":8679736},{"batb":[[0,2.86,89.68],[1,2.84,30.29],[2,1.02,2]],"ltp":0.0,"tv":0.0,"id":531005}]}]}
{"op":"mcm","clk":"1000467374","pt":1580581162791,"mc":[{"id":"1.168186838","rc":[{"batb":[[0,2.74,93.52],[1,2.66,30.29],[2,1.02,2]],"ltp":0.0,"tv":0.0,"id":8679736}]}]}
{"op":"mcm","clk":"1000483416","pt":1580581283593,"mc":[{"id":"1.168186838","rc":[{"batb":[[1,1.02,2],[2,1.02,0]],"ltp":0.0,"tv":0.0,"id":531005}]}]}
{"op":"mcm","clk":"1000483665","pt":1580581285505,"mc":[{"id":"1.168186838","rc":[{"batb":[[0,3.1,82.54],[1,2.88,30.28],[2,1.02,2]],"ltp":0.0,"tv":0.0,"id":531005}]}]}
{"op":"mcm","clk":"1000483901","pt":1580581287384,"mc":[{"id":"1.168186838","rc":[{"batb":[[0,2.78,92.16],[1,2.76,30.29]],"ltp":0.0,"tv":0.0,"id":8679736}]}]}
{"op":"mcm","clk":"1000500099","pt":1580581405885,"mc":[{"id":"1.168186838","rc":[{"batb":[[1,1.02,2],[2,1.02,0]],"ltp":0.0,"tv":0.0,"id":531005}]}]}
{"op":"mcm","clk":"1000500276","pt":1580581407285,"mc":[{"id":"1.168186838","rc":[{"batb":[[1,1.02,2],[2,1.02,0]],"ltp":0.0,"tv":0.0,"id":8679736},{"batb":[[0,3.2,79.97],[1,3.15,30.29],[2,1.02,2]],"ltp":0.0,"tv":0.0,"id":531005}]}]}
{"op":"mcm","clk":"1000515795","pt":1580581527631,"mc":[{"id":"1.168186838","rc":[{"batb":[[0,3.25,30.29],[1,3.2,79.97]],"ltp":0.0,"tv":0.0,"id":531005}]}]}
{"op":"mcm","clk":"1000515827","pt":1580581527904,"mc":[{"id":"1.168186838","rc":[{"batb":[[1,1.02,2],[2,1.02,0]],"ltp":0.0,"tv":0.0,"id":531005}]}]}
{"op":"mcm","clk":"1000531858","pt":1580581649506,"mc":[{"id":"1.168186838","rc":[{"batb":[[0,2.84,30.29]],"ltp":0.0,"tv":0.0,"id":531005}]}]}
{"op":"mcm","clk":"1000531951","pt":1580581650229,"mc":[{"id":"1.168186838","rc":[{"batb":[[0,2.92,87.69],[1,2.84,30.29],[2,1.02,2]],"ltp":0.0,"tv":0.0,"id":531005}]}]}
{"op":"mcm","clk":"1000548688","pt":1580581771536,"mc":[{"id":"1.168186838","rc":[{"batb":[[0,2.96,86.63],[1,2.94,30.29]],"ltp":0.0,"tv":0.0,"id":531005}]}]}
{"op":"mcm","clk":"1000566833","pt":1580581893203,"mc":[{"id":"1.168186838","rc":[{"batb":[[0,3.05,84.09],[1,2.98,30.29]],"ltp":0.0,"tv":0.0,"id":531005}]}]}
{"op":"mcm","clk":"1000587364","pt":1580582018627,"mc":[{"id":"1.168186838","rc":[{"batb":[[0,3.1,30.29],[1,1.02,2],[2,1.02,0]],"ltp":0.0,"tv":0.0,"id":531005}]}]}
{"op":"mcm","clk":"1000587392","pt":1580582018874,"mc":[{"id":"1.168186838","rc":[{"batb":[[0,3.15,81.23],[1,3.1,30.29],[2,1.02,2]],"ltp":0.0,"tv":0.0,"id":531005}]}]}
{"op":"mcm","clk":"1000608841","pt":1580582141544,"mc":[{"id":"1.168186838","rc":[{"batb":[[0,3.2,30.29],[1,1.02,2],[2,1.02,0]],"ltp":0.0,"tv":0.0,"id":531005}]}]}
{"op":"mcm","clk":"1000608867","pt":1580582141719,"mc":[{"id":"1.168186838","rc":[{"batb":[[0,3.2,110.26]],"ltp":0.0,"tv":0.0,"id":531005}]}]}
{"op":"mcm","clk":"1000627776","pt":1580582265226,"mc":[{"id":"1.168186838","rc":[{"batb":[[0,3.25,30.29]],"ltp":0.0,"tv":0.0,"id":531005}]}]}
{"op":"mcm","clk":"1000649843","pt":1580582386664,"mc":[{"id":"1.168186838","rc":[{"batb":[[0,2.84,30.29]],"ltp":0.0,"tv":0.0,"id":531005}]}]}
{"op":"mcm","clk":"1000649951","pt":1580582387275,"mc":[{"id":"1.168186838","rc":[{"batb":[[0,2.96,86.63],[1,2.84,30.29],[2,1.02,2]],"ltp":0.0,"tv":0.0,"id":531005}]}]}
{"op":"mcm","clk":"1000670048","pt":1580582508691,"mc":[{"id":"1.168186838","rc":[{"batb":[[0,3.1,82.54],[1,2.98,30.29]],"ltp":0.0,"tv":0.0,"id":531005}]}]}
{"op":"mcm","clk":"1000690624","pt":1580582630289,"mc":[{"id":"1.168186838","rc":[{"batb":[[0,3.2,79.97],[1,3.15,30.29]],"ltp":0.0,"tv":0.0,"id":531005}]}]}
{"op":"mcm","clk":"1000712004","pt":1580582751664,"mc":[{"id":"1.168186838","rc":[{"batb":[[0,3.25,30.29],[1,3.2,79.97]],"ltp":0.0,"tv":0.0,"id":531005}]}]}
{"op":"mcm","clk":"1000712059","pt":1580582751981,"mc":[{"id":"1.168186838","rc":[{"batb":[[1,1.02,2],[2,1.02,0]],"ltp":0.0,"tv":0.0,"id":531005}]}]}
{"op":"mcm","clk":"1000731388","pt":1580582873342,"mc":[{"id":"1.168186838","rc":[{"batb":[[0,2.84,30.29]],"ltp":0.0,"tv":0.0,"id":531005}]}]}
{"op":"mcm","clk":"1000731510","pt":1580582873971,"mc":[{"id":"1.168186838","rc":[{"batb":[[0,3.05,84.09],[1,2.84,30.29],[2,1.02,2]],"ltp":0.0,"tv":0.0,"id":531005}]}]}
{"op":"mcm","clk":"1000750941","pt":1580582995369,"mc":[{"id":"1.168186838","rc":[{"batb":[[0,3.15,81.23],[1,3.1,30.29]],"ltp":0.0,"tv":0.0,"id":531005}]}]}
{"op":"mcm","clk":"1000772330","pt":1580583116697,"mc":[{"id":"1.168186838","rc":[{"batb":[[0,3.2,30.29],[1,3.15,81.23]],"ltp":0.0,"tv":0.0,"id":531005}]}]}
{"op":"mcm","clk":"1000772394","pt":1580583117098,"mc":[{"id":"1.168186838","rc":[{"batb":[[0,3.2,110.26],[1,1.02,2],[2,1.02,0]],"ltp":0.0,"tv":0.0,"id":531005}]}]}
{"op":"mcm","clk":"1000792804","pt":1580583238578,"mc":[{"id":"1.168186838","rc":[{"batb":[[0,3.25,30.29],[1,3.2,79.97],[2,1.02,2]],"ltp":0.0,"tv":0.0,"id":531005}]}]}
{"op":"mcm","clk":"1000792855","pt":1580583238787,"mc":[{"id":"1.168186838","rc":[{"batb":[[1,1.02,2],[2,1.02,0]],"ltp":0.0,"tv":0.0,"id":531005}]}]}
{"op":"mcm","clk":"1000814215","pt":1580583360275,"mc":[{"id":"1.168186838","rc":[{"batb":[[0,3,85.57],[1,2.84,30.29],[2,1.02,2]],"ltp":0.0,"tv":0.0,"id":531005}]}]}
{"op":"mcm","clk":"1000833212","pt":1580583481638,"mc":[{"id":"1.168186838","rc":[{"batb":[[0,3.05,30.29],[1,3,85.57]],"ltp":0.0,"tv":0.0,"id":531005}]}]}
{"op":"mcm","clk":"1000833299","pt":1580583482123,"mc":[{"id":"1.168186838","rc":[{"batb":[[0,3.1,82.54],[1,3.05,30.29]],"ltp":0.0,"tv":0.0,"id":531005}]}]}
{"op":"mcm","clk":"1000852484","pt":1580583603485,"mc":[{"id":"1.168186838","rc":[{"batb":[[0,3.15,30.29],[1,3.1,82.54]],"ltp":0.0,"tv":0.0,"id":531005}]}]}
{"op":"mcm","clk":"1000852946","pt":1580583605125,"mc":[{"id":"1.168186838","rc":[{"batb":[[0,3.2,79.97],[1,3.15,30.29]],"ltp":0.0,"tv":0.0,"id":531005}]}]}
{"op":"mcm","clk":"1000876556","pt":1580583725475,"mc":[{"id":"1.168186838","rc":[{"batb":[[0,3.25,30.29],[1,1.02,2],[2,1.02,0]],"ltp":0.0,"tv":0.0,"id":531005}]}]}
{"op":"mcm","clk":"1000898959","pt":1580583846670,"mc":[{"id":"1.168186838","rc":[{"batb":[[0,1.02,2],[1,1.02,0]],"ltp":0.0,"tv":0.0,"id":531005}]}]}
{"op":"mcm","clk":"1000899124","pt":1580583847594,"mc":[{"id":"1.168186838","rc":[{"batb":[[0,2.9,88.36],[1,2.84,30.29],[2,1.02,2]],"ltp":0.0,"tv":0.0,"id":531005}]}]}
{"op":"mcm","clk":"1000922433","pt":1580583968692,"mc":[{"id":"1.168186838","rc":[{"batb":[[0,2.92,30.29],[1,2.9,88.36]],"ltp":0.0,"tv":0.0,"id":531005}]}]}
{"op":"mcm","clk":"1000922519","pt":1580583969126,"mc":[{"id":"1.168186838","rc":[{"batb":[[0,2.94,87.09],[1,2.92,30.29]],"ltp":0.0,"tv":0.0,"id":531005}]}]}
{"op":"mcm","clk":"1000947442","pt":1580584090494,"mc":[{"id":"1.168186838","rc":[{"batb":[[0,3,85.57],[1,2.96,30.29]],"ltp":0.0,"tv":0.0,"id":531005}]}]}
{"op":"mcm","clk":"1000972908","pt":1580584211690,"mc":[{"id":"1.168186838","rc":[{"batb":[[0,3.05,30.29],[1,3,85.57]],"ltp":0.0,"tv":0.0,"id":531005}]}]}
{"op":"mcm","clk":"1000973008","pt":1580584212188,"mc":[{"id":"1.168186838","rc":[{"batb":[[0,3.1,82.54],[1,3.05,30.29]],"ltp":0.0,"tv":0.0,"id":531005}]}]}
{"op":"mcm","clk":"1000998257","pt":1580584333594,"mc":[{"id":"1.168186838","rc":[{"batb":[[0,3.15,30.29],[1,1.02,2],[2,1.02,0]],"ltp":0.0,"tv":0.0,"id":531005}]}]}
{"op":"mcm","clk":"1000998280","pt":1580584333704,"mc":[{"id":"1.168186838","rc":[{"batb":[[0,3.2,79.97],[1,3.15,30.29],[2,1.02,2]],"ltp":0.0,"tv":0.0,"id":531005}]}]}
{"op":"mcm","clk":"1001007064","pt":1580584380517,"mc":[{"id":"1.168186838","rc":[{"batb":[[0,3.35,76.47],[1,1.02,2]],"batl":[[0,6.4,399.39]],"ltp":0.0,"tv":0.0,"id":8679737}]}]}
{"op":"mcm","clk":"1001007224","pt":1580584381409,"mc":[{"id":"1.168186838","rc":[{"batl":[[0,4.7,330.65]],"ltp":0.0,"tv":0.0,"id":8679736}]}]}
{"op":"mcm","clk":"1001007456","pt":1580584382503,"mc":[{"id":"1.168186838","rc":[{"batb":[[0,2.34,109.72]],"ltp":0.0,"tv":0.0,"id":8679736}]}]}
{"op":"mcm","clk":"1001020755","pt":1580584455616,"mc":[{"id":"1.168186838","rc":[{"batb":[[0,3.25,30.29],[1,3.2,79.97]],"batl":[[0,5.8,402.35]],"ltp":0.0,"tv":0.0,"id":531005}]}]}
{"op":"mcm","clk":"1001020865","pt":1580584456213,"mc":[{"id":"1.168186838","rc":[{"batb":[[0,2.48,103.51],[1,2.4,30.29],[2,1.02,2]],"ltp":0.0,"tv":0.0,"id":8679736},{"batb":[[1,1.02,2],[2,1.02,0]],"ltp":0.0,"tv":0.0,"id":531005}]}]}
{"op":"mcm","clk":"1001043699","pt":1580584576700,"mc":[{"id":"1.168186838","rc":[{"batb":[[0,1.02,2],[1,1.02,0]],"ltp":0.0,"tv":0.0,"id":531005}]}]}
{"op":"mcm","clk":"1001043884","pt":1580584577588,"mc":[{"id":"1.168186838","rc":[{"batb":[[0,2.5,30.29],[1,2.48,103.51]],"ltp":0.0,"tv":0.0,"id":8679736},{"batb":[[0,2.84,30.29],[1,2.74,93.52],[2,1.02,2]],"ltp":0.0,"tv":0.0,"id":531005}]}]}
{"op":"mcm","clk":"1001043954","pt":1580584577969,"mc":[{"id":"1.168186838","rc":[{"batb":[[0,2.66,96.34],[1,2.5,30.29]],"ltp":0.0,"tv":0.0,"id":8679736}]}]}
{"op":"mcm","clk":"1001067344","pt":1580584699675,"mc":[{"id":"1.168186838","rc":[{"batb":[[1,1.02,2],[2,1.02,0]],"ltp":0.0,"tv":0.0,"id":8679736}]}]}
{"op":"mcm","clk":"1001067454","pt":1580584700164,"mc":[{"id":"1.168186838","rc":[{"batb":[[0,2.74,93.52],[1,2.68,30.29],[2,1.02,2]],"ltp":0.0,"tv":0.0,"id":8679736}]}]}
{"op":"mcm","clk":"1001089103","pt":1580584821576,"mc":[{"id":"1.168186838","rc":[{"batb":[[0,2.78,92.16],[1,2.76,30.29]],"ltp":0.0,"tv":0.0,"id":8679736}]}]}
{"op":"mcm","clk":"1001111741","pt":1580584942739,"mc":[{"id":"1.168186838","rc":[{"batb":[[1,1.02,2],[2,1.02,0]],"ltp":0.0,"tv":0.0,"id":8679736}]}]}
{"op":"mcm","clk":"1001135559","pt":1580585064576,"mc":[{"id":"1.168186838","rc":[{"batb":[[0,2.76,30.29]],"ltp":0.0,"tv":0.0,"id":531005}]}]}
{"op":"mcm","clk":"1001135735","pt":1580585065477,"mc":[{"id":"1.168186838","rc":[{"batb":[[0,2.8,121.77]],"ltp":0.0,"tv":0.0,"id":8679736}]}]}
{"op":"mcm","clk":"1001160095","pt":1580585186411,"mc":[{"id":"1.168186838","rc":[{"batb":[[0,2.82,30.29]],"ltp":0.0,"tv":0.0,"id":8679736}]}]}
{"op":"mcm","clk":"1001184604","pt":1580585308578,"mc":[{"id":"1.168186838","rc":[{"batb":[[0,2.48,30.29]],"ltp":0.0,"tv":0.0,"id":8679736}]}]}
{"op":"mcm","clk":"1001184639","pt":1580585308825,"mc":[{"id":"1.168186838","rc":[{"batb":[[0,2.5,102.82],[1,2.48,30.29],[2,1.02,2]],"ltp":0.0,"tv":0.0,"id":8679736}]}]}
{"op":"mcm","clk":"1001207186","pt":1580585430402,"mc":[{"id":"1.168186838","rc":[{"batb":[[0,2.58,99.56],[1,2.52,30.29]],"ltp":0.0,"tv":0.0,"id":8679736}]}]}
{"op":"mcm","clk":"1001229429","pt":1580585551641,"mc":[{"id":"1.168186838","rc":[{"batb":[[0,2.6,30.29],[1,1.02,2],[2,1.02,0]],"ltp":0.0,"tv":0.0,"id":8679736}]}]}
{"op":"mcm","clk":"1001229505","pt":1580585551965,"mc":[{"id":"1.168186838","rc":[{"batb":[[0,2.62,98.04],[1,2.6,30.29],[2,1.02,2]],"ltp":0.0,"tv":0.0,"id":8679736}]}]}
{"op":"mcm","clk":"1001246376","pt":1580585635869,"mc":[{"id":"1.168186838","rc":[{"batb":[[0,3.6,70.99],[1,1.02,2]],"batl":[[0,10.5,239.73]],"ltp":0.0,"tv":0.0,"id":531006}]}]}
{"op":"mcm","clk":"1001253883","pt":1580585674473,"mc":[{"id":"1.168186838","rc":[{"batb":[[0,2.7,94.92],[1,2.64,30.29]],"ltp":0.0,"tv":0.0,"id":8679736}]}]}
{"op":"mcm","clk":"1001269481","pt":1580585754637,"mc":[{"id":"1.168186838","rc":[{"batl":[[0,5.8,44.47]],"ltp":0.0,"tv":0.0,"id":531005}]}]}
{"op":"mcm","clk":"1001277847","pt":1580585795580,"mc":[{"id":"1.168186838","rc":[{"batb":[[1,1.02,2],[2,1.02,0]],"ltp":0.0,"tv":0.0,"id":8679736}]}]}
{"op":"mcm","clk":"1001278005","pt":1580585796290,"mc":[{"id":"1.168186838","rc":[{"batb":[[0,2.76,92.98],[1,2.72,30.29],[2,1.02,2]],"ltp":0.0,"tv":0.0,"id":8679736}]}]}
{"op":"mcm","clk":"1001301875","pt":1580585917590,"mc":[{"id":"1.168186838","rc":[{"batb":[[0,2.78,30.29],[1,1.02,2],[2,1.02,0]],"ltp":0.0,"tv":0.0,"id":8679736}]}]}
{"op":"mcm","clk":"1001301918","pt":1580585917754,"mc":[{"id":"1.168186838","rc":[{"batb":[[0,2.8,91.48],[1,2.78,30.29],[2,1.02,2]],"ltp":0.0,"tv":0.0,"id":8679736}]}]}
{"op":"mcm","clk":"1001309247","pt":1580585955632,"mc":[{"id":"1.168186838","rc":[{"batl":[[0,5.8,388.82]],"ltp":0.0,"tv":0.0,"id":531005}]}]}
{"op":"mcm","clk":"1001326481","pt":1580586039285,"mc":[{"id":"1.168186838","rc":[{"batb":[[0,2.82,121.32],[1,1.02,2],[2,1.02,0]],"ltp":0.0,"tv":0.0,"id":8679736}]}]}
{"op":"mcm","clk":"1001350408","pt":1580586161218,"mc":[{"id":"1.168186838","rc":[{"batb":[[0,2.84,30.29]],"ltp":0.0,"tv":0.0,"id":8679736}]}]}
{"op":"mcm","clk":"1001372547","pt":1580586282622,"mc":[{"id":"1.168186838","rc":[{"batb":[[0,2.48,30.29],[1,2.36,108.93],[2,1.02,2]],"ltp":0.0,"tv":0.0,"id":8679736}]}]}
{"op":"mcm","clk":"1001372595","pt":1580586282952,"mc":[{"id":"1.168186838","rc":[{"batb":[[0,2.6,98.59],[1,2.48,30.29]],"ltp":0.0,"tv":0.0,"id":8679736}]}]}
{"op":"mcm","clk":"1001392931","pt":1580586404339,"mc":[{"id":"1.168186838","rc":[{"batb":[[0,2.72,94.34],[1,2.62,30.29]],"ltp":0.0,"tv":0.0,"id":8679736}]}]}
{"op":"mcm","clk":"1001412084","pt":1580586525692,"mc":[{"id":"1.168186838","rc":[{"batb":[[1,1.02,2],[2,1.02,0]],"ltp":0.0,"tv":0.0,"id":8679736}]}]}
{"op":"mcm","clk":"1001412243","pt":1580586526603,"mc":[{"id":"1.168186838","rc":[{"batb":[[0,2.74,30.29]],"ltp":0.0,"tv":0.0,"id":8679736}]}]}
{"op":"mcm","clk":"1001412271","pt":1580586526723,"mc":[{"id":"1.168186838","rc":[{"batb":[[0,2.76,92.98],[1,2.74,30.29],[2,1.02,2]],"ltp":0.0,"tv":0.0,"id":8679736}]}]}
{"op":"mcm","clk":"1001431848","pt":1580586647470,"mc":[{"id":"1.168186838","rc":[{"batb":[[0,2.78,30.29],[1,2.76,92.98]],"ltp":0.0,"tv":0.0,"id":8679736}]}]}
{"op":"mcm","clk":"1001431945","pt":1580586647890,"mc":[{"id":"1.168186838","rc":[{"batb":[[0,2.8,91.48],[1,2.78,30.29]],"ltp":0.0,"tv":0.0,"id":8679736}]}]}
{"op":"mcm","clk":"1001451220","pt":1580586769500,"mc":[{"id":"1.168186838","rc":[{"batb":[[0,2.82,121.32],[1,1.02,2],[2,1.02,0]],"ltp":0.0,"tv":0.0,"id":8679736}]}]}
{"op":"mcm","clk":"1001470610","pt":1580586891609,"mc":[{"id":"1.168186838","rc":[{"batb":[[0,2.84,30.29]],"ltp":0.0,"tv":0.0,"id":8679736}]}]}
{"op":"mcm","clk":"1001490918","pt":1580587012406,"mc":[{"id":"1.168186838","rc":[{"batb":[[0,2.48,30.29]],"ltp":0.0,"tv":0.0,"id":8679736}]}]}
{"op":"mcm","clk":"1001491050","pt":1580587013053,"mc":[{"id":"1.168186838","rc":[{"batb":[[0,2.62,98.04],[1,2.48,30.29],[2,1.02,2]],"ltp":0.0,"tv":0.0,"id":8679736}]}]}
{"op":"mcm","clk":"1001511476","pt":1580587135233,"mc":[{"id":"1.168186838","rc":[{"batb":[[0,2.64,30.29],[1,2.62,98.04]],"ltp":0.0,"tv":0.0,"id":8679736}]}]}
{"op":"mcm","clk":"1001512075","pt":1580587138934,"mc":[{"id":"1.168186838","rc":[{"batb":[[0,2.74,93.52],[1,2.64,30.29]],"ltp":0.0,"tv":0.0,"id":8679736}]}]}
{"op":"mcm","clk":"1001531985","pt":1580587257235,"mc":[{"id":"1.168186838","rc":[{"batb":[[0,2.78,92.16],[1,2.76,30.29]],"ltp":0.0,"tv":0.0,"id":8679736}]}]}
{"op":"mcm","clk":"1001553149","pt":1580587378604,"mc":[{"id":"1.168186838","rc":[{"batb":[[0,2.8,30.29],[1,2.78,92.16]],"ltp":0.0,"tv":0.0,"id":8679736}]}]}
{"op":"mcm","clk":"1001553229","pt":1580587378976,"mc":[{"id":"1.168186838","rc":[{"batb":[[0,2.82,91.03],[1,2.8,30.29]],"ltp":0.0,"tv":0.0,"id":8679736}]}]}
{"op":"mcm","clk":"1001575177","pt":1580587500604,"mc":[{"id":"1.168186838","rc":[{"batb":[[0,2.84,30.29],[1,1.02,2],[2,1.02,0]],"ltp":0.0,"tv":0.0,"id":8679736}]}]}
{"op":"mcm","clk":"1001598952","pt":1580587622508,"mc":[{"id":"1.168186838","rc":[{"batb":[[0,2.46,30.29]],"ltp":0.0,"tv":0.0,"id":8679736}]}]}
{"op":"mcm","clk":"1001599069","pt":1580587622845,"mc":[{"id":"1.168186838","rc":[{"batb":[[0,2.6,98.59],[1,2.46,30.29],[2,1.02,2]],"ltp":0.0,"tv":0.0,"id":8679736}]}]}
{"op":"mcm","clk":"1001623646","pt":1580587743683,"mc":[{"id":"1.168186838","rc":[{"batb":[[0,2.62,30.29],[1,2.6,98.59]],"ltp":0.0,"tv":0.0,"id":8679736}]}]}
{"op":"mcm","clk":"1001623775","pt":1580587744279,"mc":[{"id":"1.168186838","rc":[{"batb":[[0,2.8,91.48],[1,2.62,30.29]],"ltp":0.0,"tv":0.0,"id":8679736}]}]}
{"op":"mcm","clk":"1001649159","pt":1580587865625,"mc":[{"id":"1.168186838","rc":[{"batb":[[0,2.82,30.29],[1,1.02,2],[2,1.02,0]],"ltp":0.0,"tv":0.0,"id":8679736}]}]}
{"op":"mcm","clk":"1001649203","pt":1580587865831,"mc":[{"id":"1.168186838","rc":[{"batb":[[0,2.82,121.32]],"ltp":0.0,"tv":0.0,"id":8679736}]}]}
{"op":"mcm","clk":"1001672374","pt":1580587980527,"mc":[{"id":"1.168186838","rc":[{"batb":[[0,1.02,2],[1,1.02,0]],"ltp":0.0,"tv":0.0,"id":8679737}]}]}
{"op":"mcm","clk":"1001673757","pt":1580587987267,"mc":[{"id":"1.168186838","rc":[{"batb":[[0,2.84,30.29]],"ltp":0.0,"tv":0.0,"id":8679736}]}]}
{"op":"mcm","clk":"1001688164","pt":1580588056461,"mc":[{"id":"1.168186838","rc":[{"batl":[[0,4.3,523.95]],"ltp":0.0,"tv":0.0,"id":531005}]}]}
{"op":"mcm","clk":"1001698739","pt":1580588108634,"mc":[{"id":"1.168186838","rc":[{"batb":[[0,1.02,2],[1,1.02,0]],"ltp":0.0,"tv":0.0,"id":8679736}]}]}
{"op":"mcm","clk":"1001698833","pt":1580588109124,"mc":[{"id":"1.168186838","rc":[{"batb":[[0,2.58,99.56],[1,2.46,30.29],[2,1.02,2]],"batl":[[0,3.9,398.15]],"ltp":0.0,"tv":0.0,"id":8679736}]}]}
{"op":"mcm","clk":"1001712859","pt":1580588177489,"mc":[{"id":"1.168186838","rc":[{"batb":[[0,2.78,92.16],[1,2.76,30.29]],"ltp":0.0,"tv":0.0,"id":531005}]}]}
{"op":"mcm","clk":"1001723563","pt":1580588230661,"mc":[{"id":"1.168186838","rc":[{"batb":[[0,2.8,30.29],[1,1.02,2],[2,1.02,0]],"ltp":0.0,"tv":0.0,"id":531005}]}]}
{"op":"mcm","clk":"1001723749","pt":1580588231537,"mc":[{"id":"1.168186838","rc":[{"batb":[[0,2.6,30.29],[1,1.02,2],[2,1.02,0]],"ltp":0.0,"tv":0.0,"id":8679736},{"batb":[[0,2.9,88.36],[1,2.8,30.29],[2,1.02,2]],"ltp":0.0,"tv":0.0,"id":531005}]}]}
{"op":"mcm","clk":"1001723789","pt":1580588231779,"mc":[{"id":"1.168186838","rc":[{"batb":[[0,2.64,97.32],[1,2.6,30.29],[2,1.02,2]],"ltp":0.0,"tv":0.0,"id":8679736}]}]}
{"op":"mcm","clk":"1001746253","pt":1580588353599,"mc":[{"id":"1.168186838","rc":[{"batb":[[0,2.66,30.29],[1,2.64,97.32]],"ltp":0.0,"tv":0.0,"id":8679736},{"batb":[[0,2.94,87.09],[1,2.92,30.29]],"ltp":0.0,"tv":0.0,"id":531005}]}]}
{"op":"mcm","clk":"1001746343","pt":1580588353983,"mc":[{"id":"1.168186838","rc":[{"batb":[[0,2.72,94.34],[1,2.66,30.29]],"ltp":0.0,"tv":0.0,"id":8679736}]}]}
{"op":"mcm","clk":"1001767282","pt":1580588473674,"mc":[{"id":"1.168186838","rc":[{"batb":[[1,1.02,2],[2,1.02,0]],"ltp":0.0,"tv":0.0,"id":531005}]}]}
{"op":"mcm","clk":"1001767445","pt":1580588474656,"mc":[{"id":"1.168186838","rc":[{"batb":[[0,2.74,30.29],[1,1.02,2],[2,1.02,0]],"ltp":0.0,"tv":0.0,"id":8679736},{"batb":[[0,3,85.57],[1,2.96,30.29],[2,1.02,2]],"ltp":0.0,"tv":0.0,"id":531005}]}]}
{"op":"mcm","clk":"1001767487","pt":1580588474863,"mc":[{"id":"1.168186838","rc":[{"batb":[[0,2.76,92.98],[1,2.74,30.29],[2,1.02,2]],"ltp":0.0,"tv":0.0,"id":8679736}]}]}
{"op":"mcm","clk":"1001788629","pt":1580588595653,"mc":[{"id":"1.168186838","rc":[{"batb":[[0,3.05,30.29],[1,1.02,2],[2,1.02,0]],"ltp":0.0,"tv":0.0,"id":531005}]}]}
{"op":"mcm","clk":"1001788782","pt":1580588596577,"mc":[{"id":"1.168186838","rc":[{"batb":[[0,2.8,91.48],[1,2.78,30.29]],"ltp":0.0,"tv":0.0,"id":8679736},{"batb":[[0,3.1,82.54],[1,3.05,30.29],[2,1.02,2]],"ltp":0.0,"tv":0.0,"id":531005}]}]}
{"op":"mcm","clk":"1001810240","pt":1580588717650,"mc":[{"id":"1.168186838","rc":[{"batb":[[0,3.15,111.52],[1,1.02,2],[2,1.02,0]],"ltp":0.0,"tv":0.0,"id":531005}]}]}
{"op":"mcm","clk":"1001810358","pt":1580588718237,"mc":[{"id":"1.168186838","rc":[{"batb":[[0,2.82,121.32],[1,1.02,2],[2,1.02,0]],"ltp":0.0,"tv":0.0,"id":8679736}]}]}
{"op":"mcm","clk":"1001831889","pt":1580588838681,"mc":[{"id":"1.168186838","rc":[{"batb":[[0,3.2,30.29],[1,3.15,81.23],[2,1.02,2]],"ltp":0.0,"tv":0.0,"id":531005}]}]}
{"op":"mcm","clk":"1001832013","pt":1580588839417,"mc":[{"id":"1.168186838","rc":[{"batb":[[0,2.84,30.29],[1,2.82,91.03],[2,1.02,2]],"ltp":0.0,"tv":0.0,"id":8679736},{"batb":[[1,1.02,2],[2,1.02,0]],"ltp":0.0,"tv":0.0,"id":531005}]}]}
{"op":"mcm","clk":"1001832069","pt":1580588839739,"mc":[{"id":"1.168186838","rc":[{"batb":[[1,1.02,2],[2,1.02,0]],"ltp":0.0,"tv":0.0,"id":8679736}]}]}
{"op":"mcm","clk":"1001853590","pt":1580588960574,"mc":[{"id":"1.168186838","rc":[{"batb":[[0,2.8,91.48],[1,2.76,30.29],[2,1.02,2]],"ltp":0.0,"tv":0.0,"id":531005}]}]}
{"op":"mcm","clk":"1001853736","pt":1580588961369,"mc":[{"id":"1.168186838","rc":[{"batb":[[0,2.56,100.33],[1,2.46,30.29],[2,1.02,2]],"ltp":0.0,"tv":0.0,"id":8679736}]}]}
{"op":"mcm","clk":"1001876662","pt":1580589082673,"mc":[{"id":"1.168186838","rc":[{"batb":[[0,3,85.57],[1,2.82,30.29]],"ltp":0.0,"tv":0.0,"id":531005}]}]}
{"op":"mcm","clk":"1001876787","pt":1580589083283,"mc":[{"id":"1.168186838","rc":[{"batb":[[0,2.76,92.98],[1,2.58,30.29]],"ltp":0.0,"tv":0.0,"id":8679736}]}]}
{"op":"mcm","clk":"1001898740","pt":1580589203684,"mc":[{"id":"1.168186838","rc":[{"batb":[[1,1.02,2],[2,1.02,0]],"ltp":0.0,"tv":0.0,"id":531005}]}]}
{"op":"mcm","clk":"1001898900","pt":1580589204592,"mc":[{"id":"1.168186838","rc":[{"batb":[[0,2.78,30.29],[1,2.76,92.98]],"ltp":0.0,"tv":0.0,"id":8679736},{"batb":[[0,3.1,82.54],[1,3.05,30.29],[2,1.02,2]],"ltp":0.0,"tv":0.0,"id":531005}]}]}
{"op":"mcm","clk":"1001898981","pt":1580589205078,"mc":[{"id":"1.168186838","rc":[{"batb":[[0,2.8,91.48],[1,2.78,30.29]],"ltp":0.0,"tv":0.0,"id":8679736}]}]}
{"op":"mcm","clk":"1001904016","pt":1580589235798,"mc":[{"id":"1.168186838","rc":[{"batb":[[0,1.02,2],[1,1.02,0]],"ltp":0.0,"tv":0.0,"id":531006}]}]}
{"op":"mcm","clk":"1001918503","pt":1580589325488,"mc":[{"id":"1.168186838","rc":[{"batb":[[0,3.15,30.29],[1,3.1,82.54]],"ltp":0.0,"tv":0.0,"id":531005}]}]}
{"op":"mcm","clk":"1001918648","pt":1580589326502,"mc":[{"id":"1.168186838","rc":[{"batb":[[0,2.82,121.32],[1,1.02,2],[2,1.02,0]],"ltp":0.0,"tv":0.0,"id":8679736},{"batb":[[0,3.15,111.52],[1,1.02,2],[2,1.02,0]],"ltp":0.0,"tv":0.0,"id":531005}]}]}
{"op":"mcm","clk":"1001937894","pt":1580589447456,"mc":[{"id":"1.168186838","rc":[{"batb":[[0,3.2,30.29]],"ltp":0.0,"tv":0.0,"id":531005}]}]}
{"op":"mcm","clk":"1001938004","pt":1580589448049,"mc":[{"id":"1.168186838","rc":[{"batb":[[0,2.84,30.29]],"ltp":0.0,"tv":0.0,"id":8679736}]}]}
{"op":"mcm","clk":"1001958833","pt":1580589570507,"mc":[{"id":"1.168186838","rc":[{"batb":[[0,2.46,30.29]],"ltp":0.0,"tv":0.0,"id":8679736},{"batb":[[0,2.84,90.22],[1,2.76,30.29],[2,1.02,2]],"ltp":0.0,"tv":0.0,"id":531005}]}]}
{"op":"mcm","clk":"1001958860","pt":1580589570719,"mc":[{"id":"1.168186838","rc":[{"batb":[[0,2.72,94.34],[1,2.46,30.29],[2,1.02,2]],"ltp":0.0,"tv":0.0,"id":8679736}]}]}
{"op":"mcm","clk":"1001979608","pt":1580589692547,"mc":[{"id":"1.168186838","rc":[{"batb":[[0,2.74,30.29],[1,2.72,94.34]],"ltp":0.0,"tv":0.0,"id":8679736},{"batb":[[0,2.88,88.96],[1,2.86,30.29]],"ltp":0.0,"tv":0.0,"id":531005}]}]}
{"op":"mcm","clk":"1001979689","pt":1580589693060,"mc":[{"id":"1.168186838","rc":[{"batb":[[0,2.76,92.98],[1,2.74,30.29]],"ltp":0.0,"tv":0.0,"id":8679736}]}]}
{"op":"mcm","clk":"1001999392","pt":1580589813643,"mc":[{"id":"1.168186838","rc":[{"batb":[[1,1.02,2],[2,1.02,0]],"ltp":0.0,"tv":0.0,"id":531005}]}]}
{"op":"mcm","clk":"1001999531","pt":1580589814480,"mc":[{"id":"1.168186838","rc":[{"batb":[[0,2.78,30.29],[1,2.76,92.98]],"ltp":0.0,"tv":0.0,"id":8679736},{"batb":[[0,2.96,86.63],[1,2.9,30.29],[2,1.02,2]],"ltp":0.0,"tv":0.0,"id":531005}]}]}
{"op":"mcm","clk":"1001999609","pt":1580589814962,"mc":[{"id":"1.168186838","rc":[{"batb":[[0,2.8,91.48],[1,2.78,30.29]],"ltp":0.0,"tv":0.0,"id":8679736}]}]}
{"op":"mcm","clk":"1002019401","pt":1580589935681,"mc":[{"id":"1.168186838","rc":[{"batb":[[0,2.82,30.29],[1,1.02,2],[2,1.02,0]],"ltp":0.0,"tv":0.0,"id":8679736},{"batb":[[0,3.05,84.09],[1,2.98,30.29]],"ltp":0.0,"tv":0.0,"id":531005}]}]}
{"op":"mcm","clk":"1002019419","pt":1580589935781,"mc":[{"id":"1.168186838","rc":[{"batb":[[0,2.82,121.32]],"ltp":0.0,"tv":0.0,"id":8679736}]}]}
{"op":"mcm","clk":"1002040033","pt":1580590056537,"mc":[{"id":"1.168186838","rc":[{"batb":[[0,3.1,30.29],[1,3.05,84.09]],"ltp":0.0,"tv":0.0,"id":531005}]}]}
{"op":"mcm","clk":"1002040179","pt":1580590057338,"mc":[{"id":"1.168186838","rc":[{"batb":[[0,2.84,30.29]],"ltp":0.0,"tv":0.0,"id":8679736},{"batb":[[0,3.15,81.23],[1,3.1,30.29]],"ltp":0.0,"tv":0.0,"id":531005}]}]}
{"op":"mcm","clk":"1002045450","pt":1580590088774,"mc":[{"id":"1.168186838","rc":[{"batl":[[0,4.3,60.23]],"ltp":0.0,"tv":0.0,"id":531005}]}]}
{"op":"mcm","clk":"1002056653","pt":1580590162712,"mc":[{"id":"1.168186838","rc":[{"batl":[[0,4.3,541.85]],"ltp":0.0,"tv":0.0,"id":531005}]}]}
{"op":"mcm","clk":"1002059010","pt":1580590178541,"mc":[{"id":"1.168186838","rc":[{"batb":[[0,3.2,30.29],[1,1.02,2],[2,1.02,0]],"ltp":0.0,"tv":0.0,"id":531005}]}]}
{"op":"mcm","clk":"1002059127","pt":1580590179224,"mc":[{"id":"1.168186838","rc":[{"batb":[[0,2.54,101.12],[1,2.46,30.29],[2,1.02,2]],"ltp":0.0,"tv":0.0,"id":8679736}]}]}
{"op":"mcm","clk":"1002076290","pt":1580590300641,"mc":[{"id":"1.168186838","rc":[{"batb":[[0,2.56,30.29],[1,2.54,101.12]],"ltp":0.0,"tv":0.0,"id":8679736},{"batb":[[0,2.76,30.29],[1,2.64,97.32],[2,1.02,2]],"ltp":0.0,"tv":0.0,"id":531005}]}]}
{"op":"mcm","clk":"1002076327","pt":1580590300956,"mc":[{"id":"1.168186838","rc":[{"batb":[[0,2.64,97.32],[1,2.56,30.29]],"ltp":0.0,"tv":0.0,"id":8679736},{"batb":[[0,2.78,92.16],[1,2.76,30.29]],"ltp":0.0,"tv":0.0,"id":531005}]}]}
{"op":"mcm","clk":"1002091654","pt":1580590421683,"mc":[{"id":"1.168186838","rc":[{"batb":[[0,2.8,30.29],[1,2.78,92.16]],"ltp":0.0,"tv":0.0,"id":531005}]}]}
{"op":"mcm","clk":"1002091764","pt":1580590422692,"mc":[{"id":"1.168186838","rc":[{"batb":[[0,2.66,30.29],[1,1.02,2],[2,1.02,0]],"ltp":0.0,"tv":0.0,"id":8679736},{"batb":[[0,2.86,89.68],[1,2.8,30.29]],"ltp":0.0,"tv":0.0,"id":531005}]}]}
{"op":"mcm","clk":"1002091771","pt":1580590422780,"mc":[{"id":"1.168186838","rc":[{"batb":[[0,2.72,94.34],[1,2.66,30.29],[2,1.02,2]],"ltp":0.0,"tv":0.0,"id":8679736}]}]}
{"op":"mcm","clk":"1002106436","pt":1580590543243,"mc":[{"id":"1.168186838","rc":[{"batb":[[1,1.02,2],[2,1.02,0]],"ltp":0.0,"tv":0.0,"id":531005}]}]}
{"op":"mcm","clk":"1002106570","pt":1580590544656,"mc":[{"id":"1.168186838","rc":[{"batb":[[0,2.74,30.29],[1,2.72,94.34]],"ltp":0.0,"tv":0.0,"id":8679736},{"batb":[[0,2.98,85.9],[1,2.88,30.28],[2,1.02,2]],"ltp":0.0,"tv":0.0,"id":531005}]}]}
{"op":"mcm","clk":"1002106607","pt":1580590545025,"mc":[{"id":"1.168186838","rc":[{"batb":[[0,2.76,92.98],[1,2.74,30.29]],"ltp":0.0,"tv":0.0,"id":8679736}]}]}
{"op":"mcm","clk":"1002119061","pt":1580590665688,"mc":[{"id":"1.168186838","rc":[{"batb":[[0,3.05,84.09],[1,3,30.29]],"ltp":0.0,"tv":0.0,"id":531005}]}]}
{"op":"mcm","clk":"1002119112","pt":1580590666268,"mc":[{"id":"1.168186838","rc":[{"batb":[[0,2.8,91.48],[1,2.78,30.29]],"ltp":0.0,"tv":0.0,"id":8679736}]}]}
{"op":"mcm","clk":"1002131590","pt":1580590786652,"mc":[{"id":"1.168186838","rc":[{"batb":[[0,3.1,30.29],[1,3.05,84.09]],"ltp":0.0,"tv":0.0,"id":531005}]}]}
{"op":"mcm","clk":"1002131680","pt":1580590787441,"mc":[{"id":"1.168186838","rc":[{"batb":[[0,2.82,30.29],[1,1.02,2],[2,1.02,0]],"ltp":0.0,"tv":0.0,"id":8679736},{"batb":[[0,3.15,81.23],[1,3.1,30.29]],"ltp":0.0,"tv":0.0,"id":531005}]}]}
{"op":"mcm","clk":"1002146321","pt":1580590908492,"mc":[{"id":"1.168186838","rc":[{"batb":[[0,3.2,30.29],[1,1.02,2],[2,1.02,0]],"ltp":0.0,"tv":0.0,"id":531005}]}]}
{"op":"mcm","clk":"1002146404","pt":1580590909279,"mc":[{"id":"1.168186838","rc":[{"batb":[[0,2.54,101.12],[1,2.46,30.29],[2,1.02,2]],"ltp":0.0,"tv":0.0,"id":8679736}]}]}
{"op":"mcm","clk":"1002160145","pt":1580591030673,"mc":[{"id":"1.168186838","rc":[{"batb":[[1,1.02,2],[2,1.02,0]],"ltp":0.0,"tv":0.0,"id":8679736},{"batb":[[0,2.84,90.22],[1,2.76,30.29],[2,1.02,2]],"ltp":0.0,"tv":0.0,"id":531005}]}]}
{"op":"mcm","clk":"1002160209","pt":1580591031256,"mc":[{"id":"1.168186838","rc":[{"batb":[[0,2.64,97.32],[1,2.56,30.29],[2,1.02,2]],"ltp":0.0,"tv":0.0,"id":8679736}]}]}
{"op":"mcm","clk":"1002174178","pt":1580591151599,"mc":[{"id":"1.168186838","rc":[{"batb":[[0,2.86,30.29],[1,2.84,90.22]],"ltp":0.0,"tv":0.0,"id":531005}]}]}
{"op":"mcm","clk":"1002174282","pt":1580591152589,"mc":[{"id":"1.168186838","rc":[{"batb":[[0,2.66,30.29],[1,1.02,2],[2,1.02,0]],"ltp":0.0,"tv":0.0,"id":8679736},{"batb":[[0,2.9,88.36],[1,2.86,30.29]],"ltp":0.0,"tv":0.0,"id":531005}]}]}
{"op":"mcm","clk":"1002174310","pt":1580591152806,"mc":[{"id":"1.168186838","rc":[{"batb":[[0,2.68,95.61],[1,2.66,30.29],[2,1.02,2]],"ltp":0.0,"tv":0.0,"id":8679736}]}]}
{"op":"mcm","clk":"1002188828","pt":1580591273663,"mc":[{"id":"1.168186838","rc":[{"batb":[[0,2.92,30.29],[1,1.02,2],[2,1.02,0]],"ltp":0.0,"tv":0.0,"id":531005}]}]}
{"op":"mcm","clk":"1002188976","pt":1580591274672,"mc":[{"id":"1.168186838","rc":[{"batb":[[1,1.02,2],[2,1.02,0]],"ltp":0.0,"tv":0.0,"id":8679736},{"batb":[[0,3,85.57],[1,2.92,30.29],[2,1.02,2]],"ltp":0.0,"tv":0.0,"id":531005}]}]}
{"op":"mcm","clk":"1002189088","pt":1580591275564,"mc":[{"id":"1.168186838","rc":[{"batb":[[0,2.72,94.34],[1,2.7,30.28],[2,1.02,2]],"ltp":0.0,"tv":0.0,"id":8679736}]}]}
{"op":"mcm","clk":"1002204185","pt":1580591395518,"mc":[{"id":"1.168186838","rc":[{"batb":[[0,3.05,30.29],[1,1.02,2],[2,1.02,0]],"ltp":0.0,"tv":0.0,"id":531005}]}]}
{"op":"mcm","clk":"1002204322","pt":1580591396634,"mc":[{"id":"1.168186838","rc":[{"batb":[[0,2.74,30.29],[1,1.02,2],[2,1.02,0]],"ltp":0.0,"tv":0.0,"id":8679736},{"batb":[[0,3.1,82.54],[1,3.05,30.29],[2,1.02,2]],"ltp":0.0,"tv":0.0,"id":531005}]}]}
{"op":"mcm","clk":"1002204349","pt":1580591396799,"mc":[{"id":"1.168186838","rc":[{"batb":[[0,2.76,92.98],[1,2.74,30.29],[2,1.02,2]],"ltp":0.0,"tv":0.0,"id":8679736}]}]}
{"op":"mcm","clk":"1002217764","pt":1580591516644,"mc":[{"id":"1.168186838","rc":[{"batb":[[0,3.15,30.29],[1,3.1,82.54]],"ltp":0.0,"tv":0.0,"id":531005}]}]}
{"op":"mcm","clk":"1002217868","pt":1580591517585,"mc":[{"id":"1.168186838","rc":[{"batb":[[0,2.78,30.29],[1,1.02,2],[2,1.02,0]],"ltp":0.0,"tv":0.0,"id":8679736},{"batb":[[0,3.15,111.52],[1,1.02,2],[2,1.02,0]],"ltp":0.0,"tv":0.0,"id":531005}]}]}
{"op":"mcm","clk":"1002217889","pt":1580591517750,"mc":[{"id":"1.168186838","rc":[{"batb":[[0,2.8,91.48],[1,2.78,30.29],[2,1.02,2]],"ltp":0.0,"tv":0.0,"id":8679736}]}]}
{"op":"mcm","clk":"1002230785","pt":1580591638507,"mc":[{"id":"1.168186838","rc":[{"batb":[[0,3.2,30.29]],"ltp":0.0,"tv":0.0,"id":531005}]}]}
{"op":"mcm","clk":"1002230858","pt":1580591639141,"mc":[{"id":"1.168186838","rc":[{"batb":[[0,2.82,30.29],[1,1.02,2],[2,1.02,0]],"ltp":0.0,"tv":0.0,"id":8679736}]}]}
{"op":"mcm","clk":"1002232524","pt":1580591656914,"mc":[{"id":"1.168186838","rc":[{"batl":[[0,5.1,457.15]],"ltp":0.0,"tv":0.0,"id":531005}]}]}
{"op":"mcm","clk":"1002242373","pt":1580591760600,"mc":[{"id":"1.168186838","rc":[{"batb":[[0,2.76,30.29]],"ltp":0.0,"tv":0.0,"id":531005}]}]}
{"op":"mcm","clk":"1002242455","pt":1580591761502,"mc":[{"id":"1.168186838","rc":[{"batb":[[0,2.62,98.04],[1,2.46,30.29],[2,1.02,2]],"batl":[[0,4.7,330.65]],"ltp":0.0,"tv":0.0,"id":8679736},{"batb":[[0,2.78,92.16],[1,2.76,30.29],[2,1.02,2]],"ltp":0.0,"tv":0.0,"id":531005}]}]}
{"op":"mcm","clk":"1002255250","pt":1580591882650,"mc":[{"id":"1.168186838","rc":[{"batb":[[1,1.02,2],[2,1.02,0]],"ltp":0.0,"tv":0.0,"id":531005}]}]}
{"op":"mcm","clk":"1002255359","pt":1580591883537,"mc":[{"id":"1.168186838","rc":[{"batb":[[0,2.64,30.29],[1,2.62,98.04]],"ltp":0.0,"tv":0.0,"id":8679736},{"batb":[[0,2.98,85.9],[1,2.8,30.29],[2,1.02,2]],"ltp":0.0,"tv":0.0,"id":531005}]}]}
{"op":"mcm","clk":"1002255454","pt":1580591884257,"mc":[{"id":"1.168186838","rc":[{"batb":[[0,2.68,95.61],[1,2.64,30.29]],"ltp":0.0,"tv":0.0,"id":8679736}]}]}
{"op":"mcm","clk":"1002270145","pt":1580592004615,"mc":[{"id":"1.168186838","rc":[{"batb":[[0,3,30.29],[1,1.02,2],[2,1.02,0]],"ltp":0.0,"tv":0.0,"id":531005}]}]}
{"op":"mcm","clk":"1002270277","pt":1580592005534,"mc":[{"id":"1.168186838","rc":[{"batb":[[0,2.7,30.28],[1,2.68,95.61]],"ltp":0.0,"tv":0.0,"id":8679736},{"batb":[[0,3.05,84.09],[1,3,30.29],[2,1.02,2]],"ltp":0.0,"tv":0.0,"id":531005}]}]}
{"op":"mcm","clk":"1002270332","pt":1580592005952,"mc":[{"id":"1.168186838","rc":[{"batb":[[0,2.76,92.98],[1,2.7,30.28]],"ltp":0.0,"tv":0.0,"id":8679736}]}]}
{"op":"mcm","clk":"1002284475","pt":1580592126483,"mc":[{"id":"1.168186838","rc":[{"batb":[[0,3.15,81.23],[1,3.1,30.29]],"ltp":0.0,"tv":0.0,"id":531005}]}]}
{"op":"mcm","clk":"1002284597","pt":1580592127700,"mc":[{"id":"1.168186838","rc":[{"batb":[[0,2.8,91.48],[1,2.78,30.29]],"ltp":0.0,"tv":0.0,"id":8679736}]}]}
{"op":"mcm","clk":"1002297575","pt":1580592248565,"mc":[{"id":"1.168186838","rc":[{"batb":[[0,2.82,30.29],[1,2.8,91.48]],"ltp":0.0,"tv":0.0,"id":8679736},{"batb":[[0,3.2,30.29],[1,1.02,2],[2,1.02,0]],"ltp":0.0,"tv":0.0,"id":531005}]}]}
{"op":"mcm","clk":"1002297978","pt":1580592252548,"mc":[{"id":"1.168186838","rc":[{"batb":[[1,1.02,2],[2,1.02,0]],"ltp":0.0,"tv":0.0,"id":8679736}]}]}
{"op":"mcm","clk":"1002310706","pt":1580592369508,"mc":[{"id":"1.168186838","rc":[{"batb":[[0,2.86,89.68],[1,2.76,30.29],[2,1.02,2]],"ltp":0.0,"tv":0.0,"id":531005}]}]}
{"op":"mcm","clk":"1002310818","pt":1580592370504,"mc":[{"id":"1.168186838","rc":[{"batb":[[0,2.6,98.59],[1,2.46,30.29],[2,1.02,2]],"ltp":0.0,"tv":0.0,"id":8679736}]}]}
{"op":"mcm","clk":"1002323561","pt":1580592491507,"mc":[{"id":"1.168186838","rc":[{"batb":[[0,2.88,30.28],[1,2.86,89.68]],"ltp":0.0,"tv":0.0,"id":531005}]}]}
{"op":"mcm","clk":"1002323649","pt":1580592492608,"mc":[{"id":"1.168186838","rc":[{"batb":[[0,2.66,96.34],[1,2.62,30.29]],"ltp":0.0,"tv":0.0,"id":8679736},{"batb":[[0,3.05,84.09],[1,2.88,30.28]],"ltp":0.0,"tv":0.0,"id":531005}]}]}
{"op":"mcm","clk":"1002334846","pt":1580592612655,"mc":[{"id":"1.168186838","rc":[{"batb":[[1,1.02,2],[2,1.02,0]],"ltp":0.0,"tv":0.0,"id":531005}]}]}
{"op":"mcm","clk":"1002334944","pt":1580592613549,"mc":[{"id":"1.168186838","rc":[{"batb":[[0,3.15,81.23],[1,3.1,30.29],[2,1.02,2]],"ltp":0.0,"tv":0.0,"id":531005}]}]}
{"op":"mcm","clk":"1002335021","pt":1580592614277,"mc":[{"id":"1.168186838","rc":[{"batb":[[0,2.76,92.98],[1,2.68,30.29]],"ltp":0.0,"tv":0.0,"id":8679736}]}]}
{"op":"mcm","clk":"1002347020","pt":1580592734538,"mc":[{"id":"1.168186838","rc":[{"batb":[[0,3.2,30.29],[1,3.15,81.23]],"ltp":0.0,"tv":0.0,"id":531005}]}]}
{"op":"mcm","clk":"1002347139","pt":1580592735661,"mc":[{"id":"1.168186838","rc":[{"batb":[[1,1.02,2],[2,1.02,0]],"ltp":0.0,"tv":0.0,"id":8679736},{"batb":[[1,1.02,2],[2,1.02,0]],"ltp":0.0,"tv":0.0,"id":531005}]}]}
{"op":"mcm","clk":"1002347189","pt":1580592736120,"mc":[{"id":"1.168186838","rc":[{"batb":[[0,2.8,91.48],[1,2.78,30.29],[2,1.02,2]],"ltp":0.0,"tv":0.0,"id":8679736}]}]}
{"op":"mcm","clk":"1002359186","pt":1580592856609,"mc":[{"id":"1.168186838","rc":[{"batb":[[0,2.76,30.29],[1,2.58,99.56],[2,1.02,2]],"ltp":0.0,"tv":0.0,"id":531005}]}]}
{"op":"mcm","clk":"1002359241","pt":1580592857082,"mc":[{"id":"1.168186838","rc":[{"batb":[[0,2.82,30.29],[1,1.02,2],[2,1.02,0]],"ltp":0.0,"tv":0.0,"id":8679736},{"batb":[[0,2.8,91.48],[1,2.76,30.29]],"ltp":0.0,"tv":0.0,"id":531005}]}]}
{"op":"mcm","clk":"1002371800","pt":1580592978528,"mc":[{"id":"1.168186838","rc":[{"batb":[[0,2.46,30.29]],"ltp":0.0,"tv":0.0,"id":8679736},{"batb":[[0,2.9,88.36],[1,2.82,30.29]],"ltp":0.0,"tv":0.0,"id":531005}]}]}
{"op":"mcm","clk":"1002371853","pt":1580592979084,"mc":[{"id":"1.168186838","rc":[{"batb":[[0,2.64,97.32],[1,2.46,30.29],[2,1.02,2]],"ltp":0.0,"tv":0.0,"id":8679736}]}]}
{"op":"mcm","clk":"1002378609","pt":1580593047654,"mc":[{"id":"1.168186838","rc":[{"batl":[[0,4.7,54.65]],"ltp":0.0,"tv":0.0,"id":8679736},{"batb":[[0,3.2,80.32],[1,1.02,2]],"batl":[[0,7.8,327.72]],"ltp":0.0,"tv":0.0,"id":8679737},{"batl":[[0,5.1,50.65]],"ltp":0.0,"tv":0.0,"id":531005}]}]}
{"op":"mcm","clk":"1002378711","pt":1580593048647,"mc":[{"id":"1.168186838","rc":[{"batb":[[0,3.65,70.13],[1,1.02,2]],"batl":[[0,8.6,293.76]],"ltp":0.0,"tv":0.0,"id":531006}]}]}
{"op":"mcm","clk":"1002384046","pt":1580593099628,"mc":[{"id":"1.168186838","rc":[{"batb":[[0,2.92,30.29],[1,1.02,2],[2,1.02,0]],"ltp":0.0,"tv":0.0,"id":531005}]}]}
{"op":"mcm","clk":"1002384120","pt":1580593100306,"mc":[{"id":"1.168186838","rc":[{"batb":[[0,2.78,92.66],[1,2.66,30.29]],"ltp":0.0,"tv":0.0,"id":8679736},{"batb":[[0,2.94,87.09],[1,2.92,30.29],[2,1.02,2]],"ltp":0.0,"tv":0.0,"id":531005}]}]}
{"op":"mcm","clk":"1002389791","pt":1580593156918,"mc":[{"id":"1.168186838","rc":[{"batl":[[0,5.1,427.15]],"ltp":0.0,"tv":0.0,"id":531005}]}]}
{"op":"mcm","clk":"1002396148","pt":1580593221493,"mc":[{"id":"1.168186838","rc":[{"batb":[[0,2.96,30.29],[1,2.94,87.09]],"ltp":0.0,"tv":0.0,"id":531005}]}]}
{"op":"mcm","clk":"1002396267","pt":1580593222545,"mc":[{"id":"1.168186838","rc":[{"batb":[[0,2.82,91.42],[1,2.8,30.29]],"ltp":0.0,"tv":0.0,"id":8679736},{"batb":[[0,2.98,85.9],[1,2.96,30.29]],"ltp":0.0,"tv":0.0,"id":531005}]}]}
{"op":"mcm","clk":"1002399969","pt":1580593261155,"mc":[{"id":"1.168186838","rc":[{"batl":[[0,4.7,344.05]],"ltp":0.0,"tv":0.0,"id":8679736}]}]}
{"op":"mcm","clk":"1002407873","pt":1580593343659,"mc":[{"id":"1.168186838","rc":[{"batb":[[0,2.84,30.29],[1,1.02,2],[2,1.02,0]],"ltp":0.0,"tv":0.0,"id":8679736},{"batb":[[0,3.05,84.09],[1,3,30.29]],"ltp":0.0,"tv":0.0,"id":531005}]}]}
{"op":"mcm","clk":"1002407881","pt":1580593343762,"mc":[{"id":"1.168186838","rc":[{"batb":[[0,2.84,121.01]],"ltp":0.0,"tv":0.0,"id":8679736}]}]}
{"op":"mcm","clk":"1002419399","pt":1580593464546,"mc":[{"id":"1.168186838","rc":[{"batb":[[0,3.1,30.29],[1,3.05,84.09]],"ltp":0.0,"tv":0.0,"id":531005}]}]}
{"op":"mcm","clk":"1002419484","pt":1580593465443,"mc":[{"id":"1.168186838","rc":[{"batb":[[0,2.86,30.29]],"ltp":0.0,"tv":0.0,"id":8679736},{"batb":[[0,3.1,112.83],[1,1.02,2],[2,1.02,0]],"ltp":0.0,"tv":0.0,"id":531005}]}]}
{"op":"mcm","clk":"1002430558","pt":1580593587614,"mc":[{"id":"1.168186838","rc":[{"batb":[[0,2.46,30.29]],"ltp":0.0,"tv":0.0,"id":8679736},{"batb":[[0,3.15,30.29]],"ltp":0.0,"tv":0.0,"id":531005}]}]}
{"op":"mcm","clk":"1002430603","pt":1580593588095,"mc":[{"id":"1.168186838","rc":[{"batb":[[0,2.48,104.01],[1,2.46,30.29],[2,1.02,2]],"ltp":0.0,"tv":0.0,"id":8679736}]}]}
{"op":"mcm","clk":"1002439961","pt":1580593708591,"mc":[{"id":"1.168186838","rc":[{"batb":[[0,2.5,30.29],[1,2.48,104.01]],"ltp":0.0,"tv":0.0,"id":8679736},{"batb":[[0,2.88,88.96],[1,2.76,30.29],[2,1.02,2]],"ltp":0.0,"tv":0.0,"id":531005}]}]}
{"op":"mcm","clk":"1002439979","pt":1580593708898,"mc":[{"id":"1.168186838","rc":[{"batb":[[0,2.54,101.62],[1,2.5,30.29]],"ltp":0.0,"tv":0.0,"id":8679736}]}]}
{"op":"mcm","clk":"1002448890","pt":1580593829541,"mc":[{"id":"1.168186838","rc":[{"batb":[[0,2.9,30.29],[1,2.88,88.96]],"ltp":0.0,"tv":0.0,"id":531005}]}]}
{"op":"mcm","clk":"1002448958","pt":1580593830573,"mc":[{"id":"1.168186838","rc":[{"batb":[[0,2.7,95.32],[1,2.56,30.29]],"ltp":0.0,"tv":0.0,"id":8679736},{"batb":[[0,2.98,85.9],[1,2.9,30.29]],"ltp":0.0,"tv":0.0,"id":531005}]}]}
{"op":"mcm","clk":"1002458285","pt":1580593951429,"mc":[{"id":"1.168186838","rc":[{"batb":[[0,3.05,84.09],[1,3,30.29]],"ltp":0.0,"tv":0.0,"id":531005}]}]}
{"op":"mcm","clk":"1002458334","pt":1580593952103,"mc":[{"id":"1.168186838","rc":[{"batb":[[0,2.74,94.02],[1,2.72,30.29]],"ltp":0.0,"tv":0.0,"id":8679736}]}]}
{"op":"mcm","clk":"1002468225","pt":1580594073617,"mc":[{"id":"1.168186838","rc":[{"batb":[[0,2.76,30.29],[1,2.74,94.02]],"ltp":0.0,"tv":0.0,"id":8679736},{"batb":[[0,3.1,112.83],[1,1.02,2],[2,1.02,0]],"ltp":0.0,"tv":0.0,"id":531005}]}]}
{"op":"mcm","clk":"1002468254","pt":1580594073986,"mc":[{"id":"1.168186838","rc":[{"batb":[[0,2.82,91.42],[1,2.76,30.29]],"ltp":0.0,"tv":0.0,"id":8679736}]}]}
{"op":"mcm","clk":"1002477414","pt":1580594194558,"mc":[{"id":"1.168186838","rc":[{"batb":[[0,3.15,30.29],[1,3.1,82.54],[2,1.02,2]],"ltp":0.0,"tv":0.0,"id":531005}]}]}
{"op":"mcm","clk":"1002477485","pt":1580594195453,"mc":[{"id":"1.168186838","rc":[{"batb":[[0,2.84,121.01],[1,1.02,2],[2,1.02,0]],"ltp":0.0,"tv":0.0,"id":8679736},{"batb":[[1,1.02,2],[2,1.02,0]],"ltp":0.0,"tv":0.0,"id":531005}]}]}
{"op":"mcm","clk":"1002485447","pt":1580594302357,"mc":[{"id":"1.168186838","rc":[{"batb":[[0,3.15,111.52]],"batl":[[0,5.1,50.65]],"ltp":0.0,"tv":0.0,"id":531005}]}]}
{"op":"mcm","clk":"1002486451","pt":1580594317595,"mc":[{"id":"1.168186838","rc":[{"batb":[[0,3.2,30.29]],"ltp":0.0,"tv":0.0,"id":531005}]}]}
{"op":"mcm","clk":"1002486491","pt":1580594318272,"mc":[{"id":"1.168186838","rc":[{"batb":[[0,2.86,30.29]],"ltp":0.0,"tv":0.0,"id":8679736}]}]}
{"op":"mcm","clk":"1002489008","pt":1580594356945,"mc":[{"id":"1.168186838","rc":[{"batl":[[0,5.1,442.23]],"ltp":0.0,"tv":0.0,"id":531005}]}]}
{"op":"mcm","clk":"1002494741","pt":1580594439523,"mc":[{"id":"1.168186838","rc":[{"batb":[[0,2.48,30.29]],"ltp":0.0,"tv":0.0,"id":8679736},{"batb":[[0,2.82,91.03],[1,2.74,30.29],[2,1.02,2]],"ltp":0.0,"tv":0.0,"id":531005}]}]}
{"op":"mcm","clk":"1002494778","pt":1580594439923,"mc":[{"id":"1.168186838","rc":[{"batb":[[0,2.52,102.24],[1,2.48,30.29],[2,1.02,2]],"ltp":0.0,"tv":0.0,"id":8679736}]}]}
{"op":"mcm","clk":"1002503555","pt":1580594560572,"mc":[{"id":"1.168186838","rc":[{"batb":[[0,2.84,30.29],[1,2.82,91.03]],"ltp":0.0,"tv":0.0,"id":531005}]}]}
{"op":"mcm","clk":"1002503634","pt":1580594561511,"mc":[{"id":"1.168186838","rc":[{"batb":[[0,2.58,99.87],[1,2.54,30.29]],"ltp":0.0,"tv":0.0,"id":8679736},{"batb":[[0,2.96,86.63],[1,2.84,30.29]],"ltp":0.0,"tv":0.0,"id":531005}]}]}
{"op":"mcm","clk":"1002511314","pt":1580594682649,"mc":[{"id":"1.168186838","rc":[{"batb":[[0,3,85.57],[1,2.98,30.29]],"ltp":0.0,"tv":0.0,"id":531005}]}]}
{"op":"mcm","clk":"1002511353","pt":1580594683273,"mc":[{"id":"1.168186838","rc":[{"batb":[[0,2.7,95.32],[1,2.6,30.29]],"ltp":0.0,"tv":0.0,"id":8679736}]}]}
{"op":"mcm","clk":"1002518831","pt":1580594804694,"mc":[{"id":"1.168186838","rc":[{"batb":[[0,2.72,30.29],[1,2.7,95.32]],"ltp":0.0,"tv":0.0,"id":8679736},{"batb":[[0,3.1,82.54],[1,3.05,30.29]],"ltp":0.0,"tv":0.0,"id":531005}]}]}
{"op":"mcm","clk":"1002518854","pt":1580594805002,"mc":[{"id":"1.168186838","rc":[{"batb":[[0,2.74,94.02],[1,2.72,30.29]],"ltp":0.0,"tv":0.0,"id":8679736}]}]}
{"op":"mcm","clk":"1002526635","pt":1580594925611,"mc":[{"id":"1.168186838","rc":[{"batb":[[0,3.15,30.29],[1,3.1,82.54]],"ltp":0.0,"tv":0.0,"id":531005}]}]}
{"op":"mcm","clk":"1002526711","pt":1580594926618,"mc":[{"id":"1.168186838","rc":[{"batb":[[0,2.76,30.29],[1,1.02,2],[2,1.02,0]],"ltp":0.0,"tv":0.0,"id":8679736},{"batb":[[0,3.15,111.52],[1,1.02,2],[2,1.02,0]],"ltp":0.0,"tv":0.0,"id":531005}]}]}
{"op":"mcm","clk":"1002526727","pt":1580594926818,"mc":[{"id":"1.168186838","rc":[{"batb":[[0,2.8,91.93],[1,2.76,30.29],[2,1.02,2]],"ltp":0.0,"tv":0.0,"id":8679736}]}]}
{"op":"mcm","clk":"1002535742","pt":1580595048676,"mc":[{"id":"1.168186838","rc":[{"batb":[[0,2.82,30.29],[1,1.02,2],[2,1.02,0]],"ltp":0.0,"tv":0.0,"id":8679736},{"batb":[[0,3.2,30.29]],"ltp":0.0,"tv":0.0,"id":531005}]}]}
{"op":"mcm","clk":"1002535750","pt":1580595048783,"mc":[{"id":"1.168186838","rc":[{"batb":[[0,2.84,90.72],[1,2.82,30.29],[2,1.02,2]],"ltp":0.0,"tv":0.0,"id":8679736}]}]}
{"op":"mcm","clk":"1002545752","pt":1580595169663,"mc":[{"id":"1.168186838","rc":[{"batb":[[0,2.86,30.29],[1,1.02,2],[2,1.02,0]],"ltp":0.0,"tv":0.0,"id":8679736},{"batb":[[0,2.94,87.09],[1,2.74,30.29],[2,1.02,2]],"ltp":0.0,"tv":0.0,"id":531005}]}]}
{"op":"mcm","clk":"1002553385","pt":1580595257917,"mc":[{"id":"1.168186838","rc":[{"batl":[[0,4.4,512.04]],"ltp":0.0,"tv":0.0,"id":531005}]}]}
{"op":"mcm","clk":"1002556030","pt":1580595290609,"mc":[{"id":"1.168186838","rc":[{"batb":[[0,2.96,30.29],[1,2.94,87.09]],"ltp":0.0,"tv":0.0,"id":531005}]}]}
{"op":"mcm","clk":"1002556129","pt":1580595291605,"mc":[{"id":"1.168186838","rc":[{"batb":[[0,2.72,94.84],[1,2.48,30.29],[2,1.02,2]],"ltp":0.0,"tv":0.0,"id":8679736},{"batb":[[0,3,85.57],[1,2.96,30.29]],"ltp":0.0,"tv":0.0,"id":531005}]}]}
{"op":"mcm","clk":"1002566023","pt":1580595412633,"mc":[{"id":"1.168186838","rc":[{"batb":[[0,3.05,30.29],[1,1.02,2],[2,1.02,0]],"ltp":0.0,"tv":0.0,"id":531005}]}]}
{"op":"mcm","clk":"1002566081","pt":1580595413355,"mc":[{"id":"1.168186838","rc":[{"batb":[[0,2.76,93.23],[1,2.74,30.29]],"ltp":0.0,"tv":0.0,"id":8679736},{"batb":[[0,3.1,82.54],[1,3.05,30.29],[2,1.02,2]],"ltp":0.0,"tv":0.0,"id":531005}]}]}
{"op":"mcm","clk":"1002575428","pt":1580595534673,"mc":[{"id":"1.168186838","rc":[{"batb":[[0,2.78,30.29],[1,2.76,93.23]],"ltp":0.0,"tv":0.0,"id":8679736},{"batb":[[0,3.15,111.52],[1,1.02,2],[2,1.02,0]],"ltp":0.0,"tv":0.0,"id":531005}]}]}
{"op":"mcm","clk":"1002575456","pt":1580595534942,"mc":[{"id":"1.168186838","rc":[{"batb":[[0,2.8,91.93],[1,2.78,30.29]],"ltp":0.0,"tv":0.0,"id":8679736}]}]}
{"op":"mcm","clk":"1002584055","pt":1580595655625,"mc":[{"id":"1.168186838","rc":[{"batb":[[0,3.2,30.29],[1,3.15,81.23],[2,1.02,2]],"ltp":0.0,"tv":0.0,"id":531005}]}]}
{"op":"mcm","clk":"1002584123","pt":1580595656611,"mc":[{"id":"1.168186838","rc":[{"batb":[[0,2.84,90.72],[1,2.82,30.29]],"ltp":0.0,"tv":0.0,"id":8679736},{"batb":[[1,1.02,2],[2,1.02,0]],"ltp":0.0,"tv":0.0,"id":531005}]}]}
{"op":"mcm","clk":"1002592064","pt":1580595777637,"mc":[{"id":"1.168186838","rc":[{"batb":[[0,2.74,30.29]],"ltp":0.0,"tv":0.0,"id":531005}]}]}
{"op":"mcm","clk":"1002592107","pt":1580595778463,"mc":[{"id":"1.168186838","rc":[{"batb":[[0,2.86,30.29],[1,1.02,2],[2,1.02,0]],"ltp":0.0,"tv":0.0,"id":8679736},{"batb":[[0,2.82,91.03],[1,2.74,30.29],[2,1.02,2]],"ltp":0.0,"tv":0.0,"id":531005}]}]}
{"op":"mcm","clk":"1002600621","pt":1580595899697,"mc":[{"id":"1.168186838","rc":[{"batb":[[0,2.48,30.29]],"ltp":0.0,"tv":0.0,"id":8679736},{"batb":[[0,2.96,86.63],[1,2.84,30.29]],"ltp":0.0,"tv":0.0,"id":531005}]}]}
{"op":"mcm","clk":"1002600673","pt":1580595900164,"mc":[{"id":"1.168186838","rc":[{"batb":[[0,2.56,100.83],[1,2.48,30.29],[2,1.02,2]],"ltp":0.0,"tv":0.0,"id":8679736}]}]}
{"op":"mcm","clk":"1002608571","pt":1580596020657,"mc":[{"id":"1.168186838","rc":[{"batb":[[0,2.98,30.29],[1,2.96,86.63]],"ltp":0.0,"tv":0.0,"id":531005}]}]}
{"op":"mcm","clk":"1002608619","pt":1580596021588,"mc":[{"id":"1.168186838","rc":[{"batb":[[0,2.7,95.32],[1,2.58,30.29]],"ltp":0.0,"tv":0.0,"id":8679736},{"batb":[[0,3.05,84.09],[1,2.98,30.29]],"ltp":0.0,"tv":0.0,"id":531005}]}]}
{"op":"mcm","clk":"1002617468","pt":1580596142580,"mc":[{"id":"1.168186838","rc":[{"batb":[[0,3.1,30.29],[1,3.05,84.09]],"ltp":0.0,"tv":0.0,"id":531005}]}]}
{"op":"mcm","clk":"1002617580","pt":1580596143571,"mc":[{"id":"1.168186838","rc":[{"batb":[[0,2.74,94.02],[1,2.72,30.29]],"ltp":0.0,"tv":0.0,"id":8679736},{"batb":[[0,3.15,81.23],[1,3.1,30.29]],"ltp":0.0,"tv":0.0,"id":531005}]}]}
{"op":"mcm","clk":"1002635964","pt":1580596406754,"mc":[{"id":"1.168186838","rc":[{"batb":[[1,1.02,2],[2,1.02,0]],"ltp":0.0,"tv":0.0,"id":531005}]}]}
{"op":"mcm","clk":"1002636031","pt":1580596407952,"mc":[{"id":"1.168186838","rc":[{"batb":[[1,1.02,2],[2,1.02,0]],"ltp":0.0,"tv":0.0,"id":8679736}]}]}
{"op":"mcm","clk":"1002647506","pt":1580596578692,"mc":[{"id":"1.168186838","rc":[{"batb":[[0,3.2,30.29]],"ltp":0.0,"tv":0.0,"id":531005}]}]}
{"op":"mcm","clk":"1002647544","pt":1580596579266,"mc":[{"id":"1.168186838","rc":[{"batb":[[0,2.78,92.66],[1,2.76,30.29],[2,1.02,2]],"ltp":0.0,"tv":0.0,"id":8679736}]}]}
{"op":"mcm","clk":"1002651366","pt":1580596648011,"mc":[{"id":"1.168186838","rc":[{"batb":[[0,1.02,2],[1,1.02,0]],"ltp":0.0,"tv":0.0,"id":8679737},{"batb":[[0,1.02,2],[1,1.02,0]],"ltp":0.0,"tv":0.0,"id":531006}]}]}
{"op":"mcm","clk":"1002654389","pt":1580596700555,"mc":[{"id":"1.168186838","rc":[{"batb":[[0,2.74,30.29],[1,2.6,98.59],[2,1.02,2]],"ltp":0.0,"tv":0.0,"id":531005}]}]}
{"op":"mcm","clk":"1002654415","pt":1580596701381,"mc":[{"id":"1.168186838","rc":[{"batb":[[0,2.82,91.42],[1,2.8,30.29]],"ltp":0.0,"tv":0.0,"id":8679736},{"batb":[[0,2.8,91.48],[1,2.74,30.29]],"ltp":0.0,"tv":0.0,"id":531005}]}]}
{"op":"mcm","clk":"1002661382","pt":1580596822617,"mc":[{"id":"1.168186838","rc":[{"batb":[[1,1.02,2],[2,1.02,0]],"ltp":0.0,"tv":0.0,"id":8679736},{"batb":[[0,2.88,88.96],[1,2.82,30.29]],"ltp":0.0,"tv":0.0,"id":531005}]}]}
{"op":"mcm","clk":"1002661414","pt":1580596823034,"mc":[{"id":"1.168186838","rc":[{"batb":[[0,2.84,121.01]],"ltp":0.0,"tv":0.0,"id":8679736}]}]}
{"op":"mcm","clk":"1002669149","pt":1580596944582,"mc":[{"id":"1.168186838","rc":[{"batb":[[0,2.86,30.29]],"ltp":0.0,"tv":0.0,"id":8679736},{"batb":[[0,2.92,87.69],[1,2.9,30.29]],"ltp":0.0,"tv":0.0,"id":531005}]}]}
{"op":"mcm","clk":"1002676269","pt":1580597065544,"mc":[{"id":"1.168186838","rc":[{"batb":[[0,2.94,30.29],[1,2.92,87.69]],"ltp":0.0,"tv":0.0,"id":531005}]}]}
{"op":"mcm","clk":"1002676320","pt":1580597066424,"mc":[{"id":"1.168186838","rc":[{"batb":[[0,2.66,96.78],[1,2.48,30.29],[2,1.02,2]],"ltp":0.0,"tv":0.0,"id":8679736},{"batb":[[0,2.96,86.63],[1,2.94,30.29]],"ltp":0.0,"tv":0.0,"id":531005}]}]}
{"op":"mcm","clk":"1002683539","pt":1580597187570,"mc":[{"id":"1.168186838","rc":[{"batb":[[0,3,85.57],[1,2.98,30.29]],"ltp":0.0,"tv":0.0,"id":531005}]}]}
{"op":"mcm","clk":"1002683575","pt":1580597188195,"mc":[{"id":"1.168186838","rc":[{"batb":[[0,2.8,91.93],[1,2.68,30.29]],"ltp":0.0,"tv":0.0,"id":8679736}]}]}
{"op":"mcm","clk":"1002690322","pt":1580597309634,"mc":[{"id":"1.168186838","rc":[{"batb":[[0,2.82,30.29],[1,2.8,91.93]],"ltp":0.0,"tv":0.0,"id":8679736},{"batb":[[0,3.1,82.54],[1,3.05,30.29]],"ltp":0.0,"tv":0.0,"id":531005}]}]}
{"op":"mcm","clk":"1002690340","pt":1580597309944,"mc":[{"id":"1.168186838","rc":[{"batb":[[0,2.84,90.72],[1,2.82,30.29]],"ltp":0.0,"tv":0.0,"id":8679736}]}]}
{"op":"mcm","clk":"1002697342","pt":1580597430575,"mc":[{"id":"1.168186838","rc":[{"batb":[[0,3.15,30.29],[1,3.1,82.54]],"ltp":0.0,"tv":0.0,"id":531005}]}]}
{"op":"mcm","clk":"1002697382","pt":1580597431456,"mc":[{"id":"1.168186838","rc":[{"batb":[[0,2.86,30.29],[1,1.02,2],[2,1.02,0]],"ltp":0.0,"tv":0.0,"id":8679736},{"batb":[[0,3.15,111.52],[1,1.02,2],[2,1.02,0]],"ltp":0.0,"tv":0.0,"id":531005}]}]}
{"op":"mcm","clk":"1002704957","pt":1580597552461,"mc":[{"id":"1.168186838","rc":[{"batb":[[0,3.2,30.29]],"ltp":0.0,"tv":0.0,"id":531005}]}]}
{"op":"mcm","clk":"1002705005","pt":1580597553238,"mc":[{"id":"1.168186838","rc":[{"batb":[[0,2.56,100.83],[1,2.48,30.29],[2,1.02,2]],"ltp":0.0,"tv":0.0,"id":8679736}]}]}
{"op":"mcm","clk":"1002712508","pt":1580597674612,"mc":[{"id":"1.168186838","rc":[{"batb":[[0,2.58,30.29],[1,1.02,2],[2,1.02,0]],"ltp":0.0,"tv":0.0,"id":8679736},{"batb":[[0,2.88,88.96],[1,2.76,30.29],[2,1.02,2]],"ltp":0.0,"tv":0.0,"id":531005}]}]}
{"op":"mcm","clk":"1002712518","pt":1580597674818,"mc":[{"id":"1.168186838","rc":[{"batb":[[0,2.66,96.78],[1,2.58,30.29],[2,1.02,2]],"ltp":0.0,"tv":0.0,"id":8679736}]}]}
{"op":"mcm","clk":"1002720526","pt":1580597795649,"mc":[{"id":"1.168186838","rc":[{"batb":[[0,2.9,30.29],[1,1.02,2],[2,1.02,0]],"ltp":0.0,"tv":0.0,"id":531005}]}]}
{"op":"mcm","clk":"1002720588","pt":1580597796372,"mc":[{"id":"1.168186838","rc":[{"batb":[[0,2.72,94.84],[1,2.68,30.29]],"ltp":0.0,"tv":0.0,"id":8679736},{"batb":[[0,2.92,87.69],[1,2.9,30.29],[2,1.02,2]],"ltp":0.0,"tv":0.0,"id":531005}]}]}
{"op":"mcm","clk":"1002728303","pt":1580597917503,"mc":[{"id":"1.168186838","rc":[{"batb":[[0,3.05,84.09],[1,2.94,30.29]],"ltp":0.0,"tv":0.0,"id":531005}]}]}
{"op":"mcm","clk":"1002728355","pt":1580597918284,"mc":[{"id":"1.168186838","rc":[{"batb":[[0,2.8,91.93],[1,2.74,30.29]],"ltp":0.0,"tv":0.0,"id":8679736}]}]}
{"op":"mcm","clk":"1002736673","pt":1580598039625,"mc":[{"id":"1.168186838","rc":[{"batb":[[0,3.15,81.23],[1,3.1,30.29]],"ltp":0.0,"tv":0.0,"id":531005}]}]}
{"op":"mcm","clk":"1002736731","pt":1580598040250,"mc":[{"id":"1.168186838","rc":[{"batb":[[0,2.84,90.72],[1,2.82,30.29]],"ltp":0.0,"tv":0.0,"id":8679736}]}]}
{"op":"mcm","clk":"1002744952","pt":1580598160517,"mc":[{"id":"1.168186838","rc":[{"batb":[[0,3.2,30.29],[1,3.15,81.23]],"ltp":0.0,"tv":0.0,"id":531005}]}]}
{"op":"mcm","clk":"1002745007","pt":1580598161406,"mc":[{"id":"1.168186838","rc":[{"batb":[[0,2.86,30.29],[1,1.02,2],[2,1.02,0]],"ltp":0.0,"tv":0.0,"id":8679736},{"batb":[[1,1.02,2],[2,1.02,0]],"ltp":0.0,"tv":0.0,"id":531005}]}]}
{"op":"mcm","clk":"1002753156","pt":1580598282652,"mc":[{"id":"1.168186838","rc":[{"batb":[[0,1.02,2],[1,1.02,0]],"ltp":0.0,"tv":0.0,"id":8679736},{"batb":[[0,3.1,82.54],[1,2.76,30.29],[2,1.02,2]],"ltp":0.0,"tv":0.0,"id":531005}]}]}
{"op":"mcm","clk":"1002753199","pt":1580598283169,"mc":[{"id":"1.168186838","rc":[{"batb":[[0,2.56,100.33],[1,2.48,30.29],[2,1.02,2]],"ltp":0.0,"tv":0.0,"id":8679736}]}]}
{"op":"mcm","clk":"1002760889","pt":1580598403687,"mc":[{"id":"1.168186838","rc":[{"batb":[[1,1.02,2],[2,1.02,0]],"ltp":0.0,"tv":0.0,"id":531005}]}]}
{"op":"mcm","clk":"1002760966","pt":1580598404671,"mc":[{"id":"1.168186838","rc":[{"batb":[[0,2.74,93.52],[1,2.58,30.29]],"ltp":0.0,"tv":0.0,"id":8679736},{"batb":[[0,3.15,111.52]],"ltp":0.0,"tv":0.0,"id":531005}]}]}
{"op":"mcm","clk":"1002769088","pt":1580598516045,"mc":[{"id":"1.168186838","rc":[{"batl":[[0,4.7,54.95]],"ltp":0.0,"tv":0.0,"id":8679736}]}]}
{"op":"mcm","clk":"1002769852","pt":1580598525431,"mc":[{"id":"1.168186838","rc":[{"batb":[[0,3.15,81.23]],"ltp":0.0,"tv":0.0,"id":531005}]}]}
{"op":"mcm","clk":"1002769919","pt":1580598526522,"mc":[{"id":"1.168186838","rc":[{"batb":[[0,2.8,91.48],[1,2.76,30.29]],"ltp":0.0,"tv":0.0,"id":8679736}]}]}
{"op":"mcm","clk":"1002778414","pt":1580598647590,"mc":[{"id":"1.168186838","rc":[{"batb":[[0,2.82,121.32],[1,1.02,2],[2,1.02,0]],"ltp":0.0,"tv":0.0,"id":8679736}]}]}
{"op":"mcm","clk":"1002779560","pt":1580598662423,"mc":[{"id":"1.168186838","rc":[{"batl":[[0,4.7,330.65]],"ltp":0.0,"tv":0.0,"id":8679736}]}]}
{"op":"mcm","clk":"1002787834","pt":1580598769011,"mc":[{"id":"1.168186838","rc":[{"batb":[[0,2.84,30.29]],"ltp":0.0,"tv":0.0,"id":8679736}]}]}
{"op":"mcm","clk":"1002797426","pt":1580598890453,"mc":[{"id":"1.168186838","rc":[{"batb":[[0,2.5,30.29]],"ltp":0.0,"tv":0.0,"id":8679736}]}]}
{"op":"mcm","clk":"1002797458","pt":1580598891075,"mc":[{"id":"1.168186838","rc":[{"batb":[[0,2.56,100.33],[1,2.5,30.29],[2,1.02,2]],"ltp":0.0,"tv":0.0,"id":8679736}]}]}
{"op":"mcm","clk":"1002806219","pt":1580599012676,"mc":[{"id":"1.168186838","rc":[{"batb":[[0,2.78,92.16],[1,2.58,30.29]],"batl":[[0,4.8,323.77]],"ltp":0.0,"tv":0.0,"id":8679736}]}]}
{"op":"mcm","clk":"1002814479","pt":1580599134304,"mc":[{"id":"1.168186838","rc":[{"batb":[[0,2.82,91.03],[1,2.8,30.29]],"ltp":0.0,"tv":0.0,"id":8679736}]}]}
{"op":"mcm","clk":"1002823617","pt":1580599255553,"mc":[{"id":"1.168186838","rc":[{"batb":[[0,2.84,30.29],[1,2.82,91.03]],"ltp":0.0,"tv":0.0,"id":8679736}]}]}
{"op":"mcm","clk":"1002823644","pt":1580599255871,"mc":[{"id":"1.168186838","rc":[{"batb":[[1,1.02,2],[2,1.02,0]],"ltp":0.0,"tv":0.0,"id":8679736}]}]}
{"op":"mcm","clk":"1002832793","pt":1580599377693,"mc":[{"id":"1.168186838","rc":[{"batb":[[0,2.5,30.29]],"ltp":0.0,"tv":0.0,"id":8679736}]}]}
{"op":"mcm","clk":"1002832801","pt":1580599377795,"mc":[{"id":"1.168186838","rc":[{"batb":[[0,2.56,100.33],[1,2.5,30.29],[2,1.02,2]],"ltp":0.0,"tv":0.0,"id":8679736}]}]}
{"op":"mcm","clk":"1002841084","pt":1580599499232,"mc":[{"id":"1.168186838","rc":[{"batb":[[0,2.6,98.59],[1,2.58,30.29]],"ltp":0.0,"tv":0.0,"id":8679736}]}]}
{"op":"mcm","clk":"1002850143","pt":1580599621332,"mc":[{"id":"1.168186838","rc":[{"batb":[[0,2.7,94.92],[1,2.62,30.29]],"ltp":0.0,"tv":0.0,"id":8679736}]}]}
{"op":"mcm","clk":"1002859627","pt":1580599742659,"mc":[{"id":"1.168186838","rc":[{"batb":[[0,2.72,30.29],[1,1.02,2],[2,1.02,0]],"ltp":0.0,"tv":0.0,"id":8679736}]}]}
{"op":"mcm","clk":"1002859642","pt":1580599742858,"mc":[{"id":"1.168186838","rc":[{"batb":[[0,2.76,92.98],[1,2.72,30.29],[2,1.02,2]],"ltp":0.0,"tv":0.0,"id":8679736}]}]}
{"op":"mcm","clk":"1002869919","pt":1580599864520,"mc":[{"id":"1.168186838","rc":[{"batb":[[0,2.8,91.48],[1,2.78,30.29]],"ltp":0.0,"tv":0.0,"id":8679736}]}]}
{"op":"mcm","clk":"1002879017","pt":1580599985636,"mc":[{"id":"1.168186838","rc":[{"batb":[[0,2.82,30.29],[1,2.8,91.48]],"ltp":0.0,"tv":0.0,"id":8679736}]}]}
{"op":"mcm","clk":"1002879041","pt":1580599986044,"mc":[{"id":"1.168186838","rc":[{"batb":[[0,2.82,121.32],[1,1.02,2],[2,1.02,0]],"ltp":0.0,"tv":0.0,"id":8679736}]}]}
{"op":"mcm","clk":"1002887301","pt":1580600107558,"mc":[{"id":"1.168186838","rc":[{"batb":[[0,2.84,30.29]],"ltp":0.0,"tv":0.0,"id":8679736}]}]}
{"op":"mcm","clk":"1002895199","pt":1580600229395,"mc":[{"id":"1.168186838","rc":[{"batb":[[0,2.66,96.34],[1,2.5,30.29],[2,1.02,2]],"ltp":0.0,"tv":0.0,"id":8679736}]}]}
{"op":"mcm","clk":"1002902996","pt":1580600351681,"mc":[{"id":"1.168186838","rc":[{"batb":[[0,2.7,94.92],[1,2.68,30.29]],"ltp":0.0,"tv":0.0,"id":8679736}]}]}
{"op":"mcm","clk":"1002911157","pt":1580600472629,"mc":[{"id":"1.168186838","rc":[{"batb":[[0,2.78,92.16],[1,2.72,30.29]],"ltp":0.0,"tv":0.0,"id":8679736}]}]}
{"op":"mcm","clk":"1002913591","pt":1580600511640,"mc":[{"id":"1.168186838","marketDefinition":{"bspMarket":false,"turnInPlayEnabled":true,"persistenceEnabled":true,"marketBaseRate":5.0,"eventId":"29680287","eventTypeId":"2","numberOfWinners":1,"bettingType":"ODDS","marketType":"SET_BETTING","marketTime":"2020-02-02T02:30:00.000Z","suspendTime":"2020-02-02T02:30:00.000Z","bspReconciled":false,"complete":true,"inPlay":false,"crossMatching":false,"runnersVoidable":false,"numberOfActiveRunners":4,"betDelay":0,"status":"OPEN","runners":[{"status":"ACTIVE","sortPriority":1,"id":531005,"name":"Daniel 2 - 0"},{"status":"ACTIVE","sortPriority":2,"id":531006,"name":"Daniel 2 - 1"},{"status":"ACTIVE","sortPriority":3,"id":8679736,"name":"Hanfmann 2 - 0"},{"status":"ACTIVE","sortPriority":4,"id":8679737,"name":"Hanfmann 2 - 1"}],"regulators":["MR_INT"],"countryCode":"AU","discountAllowed":true,"timezone":"UTC","openDate":"2020-02-02T02:00:00.000Z","version":3147850875,"name":"Set Betting","eventName":"Daniel v Hanfmann"}}]}
{"op":"mcm","clk":"1002913961","pt":1580600516653,"mc":[{"id":"1.168186838","marketDefinition":{"bspMarket":false,"turnInPlayEnabled":true,"persistenceEnabled":true,"marketBaseRate":5.0,"eventId":"29680287","eventTypeId":"2","numberOfWinners":1,"bettingType":"ODDS","marketType":"SET_BETTING","marketTime":"2020-02-02T02:30:00.000Z","suspendTime":"2020-02-02T02:30:00.000Z","bspReconciled":false,"complete":true,"inPlay":false,"crossMatching":false,"runnersVoidable":false,"numberOfActiveRunners":4,"betDelay":0,"status":"OPEN","runners":[{"status":"ACTIVE","sortPriority":1,"id":531005,"name":"Daniel 2 - 0"},{"status":"ACTIVE","sortPriority":2,"id":531006,"name":"Daniel 2 - 1"},{"status":"ACTIVE","sortPriority":3,"id":8679736,"name":"Hanfmann 2 - 0"},{"status":"ACTIVE","sortPriority":4,"id":8679737,"name":"Hanfmann 2 - 1"}],"regulators":["MR_INT"],"countryCode":"AU","discountAllowed":true,"timezone":"UTC","openDate":"2020-02-02T02:30:00.000Z","version":3147850875,"name":"Set Betting","eventName":"Daniel v Hanfmann"}}]}
{"op":"mcm","clk":"1002914458","pt":1580600524200,"mc":[{"id":"1.168186838","rc":[{"batb":[[0,3.3,77.58],[1,1.02,2]],"batl":[[0,8.2,311.88]],"ltp":0.0,"tv":0.0,"id":8679737},{"batb":[[0,3.4,75.21],[1,1.02,2]],"batl":[[0,6.6,382.56]],"ltp":0.0,"tv":0.0,"id":531006},{"batl":[[0,5.4,417.54]],"ltp":0.0,"tv":0.0,"id":531005}]}]}
{"op":"mcm","clk":"1002919479","pt":1580600594299,"mc":[{"id":"1.168186838","rc":[{"batb":[[0,2.82,91.03],[1,2.8,30.29]],"ltp":0.0,"tv":0.0,"id":8679736}]}]}
{"op":"mcm","clk":"1002926622","pt":1580600715594,"mc":[{"id":"1.168186838","rc":[{"batb":[[1,1.02,2],[2,1.02,0]],"ltp":0.0,"tv":0.0,"id":8679736}]}]}
{"op":"mcm","clk":"1002926647","pt":1580600716013,"mc":[{"id":"1.168186838","rc":[{"batb":[[0,2.84,30.29]],"ltp":0.0,"tv":0.0,"id":8679736}]}]}
{"op":"mcm","clk":"1002934458","pt":1580600837541,"mc":[{"id":"1.168186838","rc":[{"batb":[[0,2.5,30.29],[1,2.44,105.17],[2,1.02,2]],"ltp":0.0,"tv":0.0,"id":8679736}]}]}
{"op":"mcm","clk":"1002934481","pt":1580600837852,"mc":[{"id":"1.168186838","rc":[{"batb":[[0,2.54,101.12],[1,2.5,30.29]],"ltp":0.0,"tv":0.0,"id":8679736}]}]}
{"op":"mcm","clk":"1002942866","pt":1580600959495,"mc":[{"id":"1.168186838","rc":[{"batb":[[0,2.66,96.34],[1,2.56,30.29]],"ltp":0.0,"tv":0.0,"id":8679736}]}]}
{"op":"mcm","clk":"1002951067","pt":1580601080621,"mc":[{"id":"1.168186838","rc":[{"batb":[[1,1.02,2],[2,1.02,0]],"ltp":0.0,"tv":0.0,"id":8679736}]}]}
{"op":"mcm","clk":"1002951113","pt":1580601081140,"mc":[{"id":"1.168186838","rc":[{"batb":[[0,2.76,92.98],[1,2.68,30.29],[2,1.02,2]],"ltp":0.0,"tv":0.0,"id":8679736}]}]}
{"op":"mcm","clk":"1002959741","pt":1580601202683,"mc":[{"id":"1.168186838","rc":[{"batb":[[0,2.8,91.48],[1,2.78,30.29]],"ltp":0.0,"tv":0.0,"id":8679736}]}]}
{"op":"mcm","clk":"1002968043","pt":1580601324433,"mc":[{"id":"1.168186838","rc":[{"batb":[[0,2.82,121.32],[1,1.02,2],[2,1.02,0]],"ltp":0.0,"tv":0.0,"id":8679736}]}]}
{"op":"mcm","clk":"1002976867","pt":1580601445681,"mc":[{"id":"1.168186838","rc":[{"batb":[[0,2.82,91.03]],"ltp":0.0,"tv":0.0,"id":8679736}]}]}
{"op":"mcm","clk":"1002976901","pt":1580601445989,"mc":[{"id":"1.168186838","rc":[{"batb":[[0,2.84,30.29]],"ltp":0.0,"tv":0.0,"id":8679736}]}]}
{"op":"mcm","clk":"1002985881","pt":1580601567615,"mc":[{"id":"1.168186838","rc":[{"batb":[[0,2.5,30.29],[1,2.44,105.17],[2,1.02,2]],"ltp":0.0,"tv":0.0,"id":8679736}]}]}
{"op":"mcm","clk":"1002985909","pt":1580601567924,"mc":[{"id":"1.168186838","rc":[{"batb":[[0,2.54,101.12],[1,2.5,30.29]],"ltp":0.0,"tv":0.0,"id":8679736}]}]}
{"op":"mcm","clk":"1002994087","pt":1580601689420,"mc":[{"id":"1.168186838","rc":[{"batb":[[0,2.6,98.59],[1,2.56,30.29]],"ltp":0.0,"tv":0.0,"id":8679736}]}]}
{"op":"mcm","clk":"1003002101","pt":1580601811072,"mc":[{"id":"1.168186838","rc":[{"batb":[[0,2.68,95.61],[1,2.62,30.29]],"ltp":0.0,"tv":0.0,"id":8679736}]}]}
{"op":"mcm","clk":"1003006949","pt":1580601883087,"mc":[{"id":"1.168186838","rc":[{"batb":[[0,2.7,94.92]],"ltp":0.0,"tv":0.0,"id":531005}]}]}
{"op":"mcm","clk":"1003009834","pt":1580601932592,"mc":[{"id":"1.168186838","rc":[{"batb":[[0,2.72,30.29],[1,2.7,94.92],[2,1.02,2]],"ltp":0.0,"tv":0.0,"id":531005}]}]}
{"op":"mcm","clk":"1003009895","pt":1580601933672,"mc":[{"id":"1.168186838","rc":[{"batb":[[0,2.7,30.28],[1,2.68,95.61]],"ltp":0.0,"tv":0.0,"id":8679736},{"batb":[[0,2.74,93.52],[1,2.72,30.29]],"ltp":0.0,"tv":0.0,"id":531005}]}]}
{"op":"mcm","clk":"1003009916","pt":1580601934010,"mc":[{"id":"1.168186838","rc":[{"batb":[[0,2.72,94.34],[1,2.7,30.28]],"ltp":0.0,"tv":0.0,"id":8679736}]}]}
{"op":"mcm","clk":"1003020064","pt":1580602054650,"mc":[{"id":"1.168186838","rc":[{"batb":[[1,1.02,2],[2,1.02,0]],"ltp":0.0,"tv":0.0,"id":8679736},{"batb":[[0,2.88,88.96],[1,2.76,30.29]],"ltp":0.0,"tv":0.0,"id":531005}]}]}
{"op":"mcm","clk":"1003020151","pt":1580602055480,"mc":[{"id":"1.168186838","rc":[{"batb":[[0,2.76,92.98],[1,2.74,30.29],[2,1.02,2]],"ltp":0.0,"tv":0.0,"id":8679736}]}]}
{"op":"mcm","clk":"1003020494","pt":1580602058769,"mc":[{"id":"1.168186838","rc":[{"batl":[[0,6.6,39.06]],"ltp":0.0,"tv":0.0,"id":531006},{"batl":[[0,5.4,47.79]],"ltp":0.0,"tv":0.0,"id":531005}]}]}
{"op":"mcm","clk":"1003031540","pt":1580602175656,"mc":[{"id":"1.168186838","rc":[{"batb":[[1,1.02,2],[2,1.02,0]],"ltp":0.0,"tv":0.0,"id":531005}]}]}
{"op":"mcm","clk":"1003031649","pt":1580602176648,"mc":[{"id":"1.168186838","rc":[{"batb":[[0,2.78,30.29],[1,1.02,2],[2,1.02,0]],"ltp":0.0,"tv":0.0,"id":8679736},{"batb":[[0,3.1,82.54],[1,2.9,30.29],[2,1.02,2]],"ltp":0.0,"tv":0.0,"id":531005}]}]}
{"op":"mcm","clk":"1003031661","pt":1580602176748,"mc":[{"id":"1.168186838","rc":[{"batb":[[0,2.8,91.48],[1,2.78,30.29],[2,1.02,2]],"ltp":0.0,"tv":0.0,"id":8679736}]}]}
{"op":"mcm","clk":"1003038208","pt":1580602247975,"mc":[{"id":"1.168186838","rc":[{"batb":[[0,2.78,122.45],[1,1.02,2],[2,1.02,0]],"ltp":0.0,"tv":0.0,"id":8679736}]}]}
{"op":"mcm","clk":"1003042649","pt":1580602297478,"mc":[{"id":"1.168186838","rc":[{"batb":[[0,3.15,30.29],[1,3.1,82.54]],"ltp":0.0,"tv":0.0,"id":531005}]}]}
{"op":"mcm","clk":"1003042752","pt":1580602298463,"mc":[{"id":"1.168186838","rc":[{"batb":[[0,2.8,30.29]],"ltp":0.0,"tv":0.0,"id":8679736},{"batb":[[0,3.2,79.97],[1,3.15,30.29]],"ltp":0.0,"tv":0.0,"id":531005}]}]}
{"op":"mcm","clk":"1003045218","pt":1580602326516,"mc":[{"id":"1.168186838","rc":[{"batl":[[0,6.6,381.33]],"ltp":0.0,"tv":0.0,"id":531006},{"batl":[[0,5.4,431.79]],"ltp":0.0,"tv":0.0,"id":531005}]}]}
{"op":"mcm","clk":"1003049014","pt":1580602368404,"mc":[{"id":"1.168186838","rc":[{"batl":[[0,8.2,31.43]],"ltp":0.0,"tv":0.0,"id":8679737}]}]}
{"op":"mcm","clk":"1003049854","pt":1580602377680,"mc":[{"id":"1.168186838","rc":[{"batl":[[0,4.3,346.75]],"ltp":0.0,"tv":0.0,"id":8679736}]}]}
{"op":"mcm","clk":"1003053890","pt":1580602419688,"mc":[{"id":"1.168186838","rc":[{"batb":[[0,2.5,30.29]],"ltp":0.0,"tv":0.0,"id":8679736},{"batb":[[1,1.02,2],[2,1.02,0]],"ltp":0.0,"tv":0.0,"id":531005}]}]}
{"op":"mcm","clk":"1003053908","pt":1580602419893,"mc":[{"id":"1.168186838","rc":[{"batb":[[0,2.6,98.59],[1,2.5,30.29],[2,1.02,2]],"ltp":0.0,"tv":0.0,"id":8679736}]}]}
{"op":"mcm","clk":"1003064084","pt":1580602527569,"mc":[{"id":"1.168186838","rc":[{"batb":[[2,1.01,0.51]],"ltp":0.0,"tv":0.0,"id":8679737},{"batb":[[2,1.01,0.51]],"ltp":0.0,"tv":0.0,"id":531006},{"batb":[[2,1.01,0.51]],"ltp":0.0,"tv":0.0,"id":531005}]}]}
{"op":"mcm","clk":"1003065165","pt":1580602540683,"mc":[{"id":"1.168186838","rc":[{"batb":[[1,1.02,2],[2,1.01,0.51]],"ltp":0.0,"tv":0.0,"id":8679736}]}]}
{"op":"mcm","clk":"1003065208","pt":1580602541201,"mc":[{"id":"1.168186838","rc":[{"batb":[[0,2.66,96.34],[1,2.62,30.29],[2,1.02,2]],"ltp":0.0,"tv":0.0,"id":8679736}]}]}
{"op":"mcm","clk":"1003065607","pt":1580602545813,"mc":[{"id":"1.168186838","marketDefinition":{"bspMarket":false,"turnInPlayEnabled":true,"persistenceEnabled":true,"marketBaseRate":5.0,"eventId":"29680287","eventTypeId":"2","numberOfWinners":1,"bettingType":"ODDS","marketType":"SET_BETTING","marketTime":"2020-02-02T02:30:00.000Z","suspendTime":"2020-02-02T02:30:00.000Z","bspReconciled":false,"complete":true,"inPlay":false,"crossMatching":true,"runnersVoidable":false,"numberOfActiveRunners":4,"betDelay":0,"status":"OPEN","runners":[{"status":"ACTIVE","sortPriority":1,"id":531005,"name":"Daniel 2 - 0"},{"status":"ACTIVE","sortPriority":2,"id":531006,"name":"Daniel 2 - 1"},{"status":"ACTIVE","sortPriority":3,"id":8679736,"name":"Hanfmann 2 - 0"},{"status":"ACTIVE","sortPriority":4,"id":8679737,"name":"Hanfmann 2 - 1"}],"regulators":["MR_INT"],"countryCode":"AU","discountAllowed":true,"timezone":"UTC","openDate":"2020-02-02T02:30:00.000Z","version":3147850875,"name":"Set Betting","eventName":"Daniel v Hanfmann"}}]}
{"op":"mcm","clk":"1003071724","pt":1580602612426,"mc":[{"id":"1.168186838","marketDefinition":{"bspMarket":false,"turnInPlayEnabled":true,"persistenceEnabled":true,"marketBaseRate":5.0,"eventId":"29680287","eventTypeId":"2","numberOfWinners":1,"bettingType":"ODDS","marketType":"SET_BETTING","marketTime":"2020-02-02T03:00:00.000Z","suspendTime":"2020-02-02T03:00:00.000Z","bspReconciled":false,"complete":true,"inPlay":false,"crossMatching":true,"runnersVoidable":false,"numberOfActiveRunners":4,"betDelay":0,"status":"OPEN","runners":[{"status":"ACTIVE","sortPriority":1,"id":531005,"name":"Daniel 2 - 0"},{"status":"ACTIVE","sortPriority":2,"id":531006,"name":"Daniel 2 - 1"},{"status":"ACTIVE","sortPriority":3,"id":8679736,"name":"Hanfmann 2 - 0"},{"status":"ACTIVE","sortPriority":4,"id":8679737,"name":"Hanfmann 2 - 1"}],"regulators":["MR_INT"],"countryCode":"AU","discountAllowed":true,"timezone":"UTC","openDate":"2020-02-02T02:30:00.000Z","version":3147905867,"name":"Set Betting","eventName":"Daniel v Hanfmann"}}]}
{"op":"mcm","clk":"1003071944","pt":1580602615018,"mc":[{"id":"1.168186838","marketDefinition":{"bspMarket":false,"turnInPlayEnabled":true,"persistenceEnabled":true,"marketBaseRate":5.0,"eventId":"29680287","eventTypeId":"2","numberOfWinners":1,"bettingType":"ODDS","marketType":"SET_BETTING","marketTime":"2020-02-02T03:00:00.000Z","suspendTime":"2020-02-02T03:00:00.000Z","bspReconciled":false,"complete":true,"inPlay":false,"crossMatching":true,"runnersVoidable":false,"numberOfActiveRunners":4,"betDelay":0,"status":"OPEN","runners":[{"status":"ACTIVE","sortPriority":1,"id":531005,"name":"Daniel 2 - 0"},{"status":"ACTIVE","sortPriority":2,"id":531006,"name":"Daniel 2 - 1"},{"status":"ACTIVE","sortPriority":3,"id":8679736,"name":"Hanfmann 2 - 0"},{"status":"ACTIVE","sortPriority":4,"id":8679737,"name":"Hanfmann 2 - 1"}],"regulators":["MR_INT"],"countryCode":"AU","discountAllowed":true,"timezone":"UTC","openDate":"2020-02-02T03:00:00.000Z","version":3147905867,"name":"Set Betting","eventName":"Daniel v Hanfmann"}}]}
{"op":"mcm","clk":"1003073145","pt":1580602626879,"mc":[{"id":"1.168186838","rc":[{"batl":[[0,8,321.34]],"ltp":0.0,"tv":0.0,"id":8679737}]}]}
{"op":"mcm","clk":"1003076370","pt":1580602663330,"mc":[{"id":"1.168186838","rc":[{"batb":[[0,2.72,94.34],[1,2.68,30.29]],"ltp":0.0,"tv":0.0,"id":8679736}]}]}
{"op":"mcm","clk":"1003085963","pt":1580602784631,"mc":[{"id":"1.168186838","rc":[{"batb":[[0,2.76,92.98],[1,2.74,30.29]],"ltp":0.0,"tv":0.0,"id":8679736}]}]}
{"op":"mcm","clk":"1003094545","pt":1580602906124,"mc":[{"id":"1.168186838","rc":[{"batb":[[0,2.78,122.45],[1,1.02,2],[2,1.01,0.51]],"ltp":0.0,"tv":0.0,"id":8679736}]}]}
{"op":"mcm","clk":"1003103246","pt":1580603027507,"mc":[{"id":"1.168186838","rc":[{"batb":[[0,2.8,30.29],[1,2.78,92.16],[2,1.02,2]],"ltp":0.0,"tv":0.0,"id":8679736}]}]}
{"op":"mcm","clk":"1003103266","pt":1580603027818,"mc":[{"id":"1.168186838","rc":[{"batb":[[1,1.02,2],[2,1.01,0.51]],"ltp":0.0,"tv":0.0,"id":8679736}]}]}
{"op":"mcm","clk":"1003112037","pt":1580603149394,"mc":[{"id":"1.168186838","rc":[{"batb":[[0,2.68,95.86],[1,2.5,30.29],[2,1.02,2]],"ltp":0.0,"tv":0.0,"id":8679736}]}]}
{"op":"mcm","clk":"1003121583","pt":1580603271668,"mc":[{"id":"1.168186838","rc":[{"batb":[[0,2.72,94.34],[1,2.7,30.28]],"ltp":0.0,"tv":0.0,"id":8679736}]}]}
{"op":"mcm","clk":"1003131922","pt":1580603392444,"mc":[{"id":"1.168186838","rc":[{"batb":[[1,1.02,2],[2,1.01,0.51]],"ltp":0.0,"tv":0.0,"id":8679736}]}]}
{"op":"mcm","clk":"1003132015","pt":1580603393631,"mc":[{"id":"1.168186838","rc":[{"batb":[[0,2.74,30.29]],"ltp":0.0,"tv":0.0,"id":8679736}]}]}
{"op":"mcm","clk":"1003132023","pt":1580603393736,"mc":[{"id":"1.168186838","rc":[{"batb":[[0,2.76,92.98],[1,2.74,30.29],[2,1.02,2]],"ltp":0.0,"tv":0.0,"id":8679736}]}]}
{"op":"mcm","clk":"1003142180","pt":1580603514478,"mc":[{"id":"1.168186838","rc":[{"batb":[[0,2.78,122.45],[1,1.02,2],[2,1.01,0.51]],"ltp":0.0,"tv":0.0,"id":8679736}]}]}
{"op":"mcm","clk":"1003152535","pt":1580603637015,"mc":[{"id":"1.168186838","rc":[{"batb":[[0,2.8,30.29]],"ltp":0.0,"tv":0.0,"id":8679736}]}]}
{"op":"mcm","clk":"1003163057","pt":1580603758588,"mc":[{"id":"1.168186838","rc":[{"batb":[[0,2.52,30.29]],"ltp":0.0,"tv":0.0,"id":8679736}]}]}
{"op":"mcm","clk":"1003163099","pt":1580603759056,"mc":[{"id":"1.168186838","rc":[{"batb":[[0,2.56,100.33],[1,2.52,30.29],[2,1.02,2]],"ltp":0.0,"tv":0.0,"id":8679736}]}]}
{"op":"mcm","clk":"1003167836","pt":1580603813365,"mc":[{"id":"1.168186838","rc":[{"batl":[[0,4.5,345.27]],"ltp":0.0,"tv":0.0,"id":8679736},{"batl":[[0,8,32.44]],"ltp":0.0,"tv":0.0,"id":8679737}]}]}
{"op":"mcm","clk":"1003168951","pt":1580603826882,"mc":[{"id":"1.168186838","rc":[{"batl":[[0,8,319.9]],"ltp":0.0,"tv":0.0,"id":8679737}]}]}
{"op":"mcm","clk":"1003172402","pt":1580603880555,"mc":[{"id":"1.168186838","rc":[{"batb":[[0,2.72,94.34],[1,2.58,30.29]],"ltp":0.0,"tv":0.0,"id":8679736}]}]}
{"op":"mcm","clk":"1003172831","pt":1580603886435,"mc":[{"id":"1.168186838","rc":[{"batl":[[0,4.5,57.31]],"ltp":0.0,"tv":0.0,"id":8679736},{"batb":[[0,2.62,98.04]],"ltp":0.0,"tv":0.0,"id":531005}]}]}
{"op":"mcm","clk":"1003172888","pt":1580603887163,"mc":[{"id":"1.168186838","rc":[{"batl":[[0,5.2,433.76]],"ltp":0.0,"tv":0.0,"id":531005}]}]}
{"op":"mcm","clk":"1003180174","pt":1580604001687,"mc":[{"id":"1.168186838","rc":[{"batb":[[0,2.7,30.28],[1,2.62,98.04],[2,1.02,2]],"ltp":0.0,"tv":0.0,"id":531005}]}]}
{"op":"mcm","clk":"1003180244","pt":1580604002664,"mc":[{"id":"1.168186838","rc":[{"batb":[[0,2.76,92.98],[1,2.74,30.29]],"ltp":0.0,"tv":0.0,"id":8679736},{"batb":[[0,3,85.57],[1,2.7,30.28]],"ltp":0.0,"tv":0.0,"id":531005}]}]}
{"op":"mcm","clk":"1003183549","pt":1580604053714,"mc":[{"id":"1.168186838","rc":[{"batl":[[0,5.2,49.63]],"ltp":0.0,"tv":0.0,"id":531005}]}]}
{"op":"mcm","clk":"1003183729","pt":1580604056546,"mc":[{"id":"1.168186838","rc":[{"batb":[[2,1.01,1.01]],"ltp":0.0,"tv":0.0,"id":8679737},{"batb":[[2,1.01,1.01]],"batl":[[0,9.6,263.21]],"ltp":0.0,"tv":0.0,"id":531006}]}]}
{"op":"mcm","clk":"1003187139","pt":1580604113424,"mc":[{"id":"1.168186838","rc":[{"batl":[[0,4.5,359.53]],"ltp":0.0,"tv":0.0,"id":8679736}]}]}
{"op":"mcm","clk":"1003187782","pt":1580604124607,"mc":[{"id":"1.168186838","rc":[{"batb":[[0,3.4,75.21]],"ltp":0.0,"tv":0.0,"id":8679737},{"batb":[[0,3.3,77.58]],"ltp":0.0,"tv":0.0,"id":531006},{"batb":[[0,3.05,30.29],[1,3,85.57]],"ltp":0.0,"tv":0.0,"id":531005}]}]}
{"op":"mcm","clk":"1003187838","pt":1580604125532,"mc":[{"id":"1.168186838","rc":[{"batb":[[0,2.82,91.03],[1,2.78,30.29]],"ltp":0.0,"tv":0.0,"id":8679736},{"batb":[[0,3.1,82.54],[1,3.05,30.29]],"ltp":0.0,"tv":0.0,"id":531005}]}]}
{"op":"mcm","clk":"1003187907","pt":1580604126919,"mc":[{"id":"1.168186838","rc":[{"batl":[[0,5.2,418.98]],"ltp":0.0,"tv":0.0,"id":531005}]}]}
{"op":"mcm","clk":"1003194943","pt":1580604245552,"mc":[{"id":"1.168186838","rc":[{"batb":[[0,3.15,30.29],[1,1.02,2],[2,1.01,1.01]],"ltp":0.0,"tv":0.0,"id":531005}]}]}
{"op":"mcm","clk":"1003194999","pt":1580604246324,"mc":[{"id":"1.168186838","rc":[{"batb":[[0,2.84,120.51],[1,1.02,2],[2,1.01,1.01]],"ltp":0.0,"tv":0.0,"id":8679736}]}]}
{"op":"mcm","clk":"1003202509","pt":1580604367501,"mc":[{"id":"1.168186838","rc":[{"batb":[[0,2.78,92.16],[1,2.7,30.28],[2,1.02,2]],"ltp":0.0,"tv":0.0,"id":531005}]}]}
{"op":"mcm","clk":"1003202537","pt":1580604368117,"mc":[{"id":"1.168186838","rc":[{"batb":[[0,2.86,30.29]],"ltp":0.0,"tv":0.0,"id":8679736}]}]}
{"op":"mcm","clk":"1003209185","pt":1580604488582,"mc":[{"id":"1.168186838","rc":[{"batb":[[1,1.02,2],[2,1.01,1.01]],"ltp":0.0,"tv":0.0,"id":531005}]}]}
{"op":"mcm","clk":"1003209244","pt":1580604489664,"mc":[{"id":"1.168186838","rc":[{"batb":[[0,1.02,2],[1,1.01,1.01],[2,1.01,0]],"ltp":0.0,"tv":0.0,"id":8679736},{"batb":[[0,2.86,89.68],[1,2.8,30.29],[2,1.02,2]],"ltp":0.0,"tv":0.0,"id":531005}]}]}
{"op":"mcm","clk":"1003209262","pt":1580604489971,"mc":[{"id":"1.168186838","rc":[{"batb":[[0,2.72,94.34],[1,2.52,30.29],[2,1.02,2]],"ltp":0.0,"tv":0.0,"id":8679736}]}]}
{"op":"mcm","clk":"1003216929","pt":1580604610237,"mc":[{"id":"1.168186838","rc":[{"batb":[[1,1.02,2],[2,1.01,1.01]],"ltp":0.0,"tv":0.0,"id":531005}]}]}
{"op":"mcm","clk":"1003217046","pt":1580604611632,"mc":[{"id":"1.168186838","rc":[{"batb":[[0,2.74,30.29],[1,1.02,2],[2,1.01,1.01]],"ltp":0.0,"tv":0.0,"id":8679736},{"batb":[[0,2.92,87.69],[1,2.88,30.28],[2,1.02,2]],"ltp":0.0,"tv":0.0,"id":531005}]}]}
{"op":"mcm","clk":"1003217055","pt":1580604611734,"mc":[{"id":"1.168186838","rc":[{"batb":[[0,2.76,92.98],[1,2.74,30.29],[2,1.02,2]],"ltp":0.0,"tv":0.0,"id":8679736}]}]}
{"op":"mcm","clk":"1003225122","pt":1580604732645,"mc":[{"id":"1.168186838","rc":[{"batb":[[0,3,85.57],[1,2.94,30.29]],"ltp":0.0,"tv":0.0,"id":531005}]}]}
{"op":"mcm","clk":"1003225172","pt":1580604733364,"mc":[{"id":"1.168186838","rc":[{"batb":[[0,2.8,91.48],[1,2.78,30.29]],"ltp":0.0,"tv":0.0,"id":8679736}]}]}
{"op":"mcm","clk":"1003232886","pt":1580604853624,"mc":[{"id":"1.168186838","rc":[{"batb":[[0,3.05,30.29],[1,3,85.57]],"ltp":0.0,"tv":0.0,"id":531005}]}]}
{"op":"mcm","clk":"1003232948","pt":1580604854653,"mc":[{"id":"1.168186838","rc":[{"batb":[[0,2.82,30.29],[1,2.8,91.48]],"ltp":0.0,"tv":0.0,"id":8679736},{"batb":[[0,3.1,82.54],[1,3.05,30.29]],"ltp":0.0,"tv":0.0,"id":531005}]}]}
{"op":"mcm","clk":"1003232968","pt":1580604854963,"mc":[{"id":"1.168186838","rc":[{"batb":[[0,2.84,90.22],[1,2.82,30.29]],"ltp":0.0,"tv":0.0,"id":8679736}]}]}
{"op":"mcm","clk":"1003239102","pt":1580604975404,"mc":[{"id":"1.168186838","rc":[{"batb":[[0,3.15,30.29],[1,3.1,82.54]],"ltp":0.0,"tv":0.0,"id":531005}]}]}
{"op":"mcm","clk":"1003239161","pt":1580604976323,"mc":[{"id":"1.168186838","rc":[{"batb":[[0,2.86,30.29],[1,1.02,2],[2,1.01,1.01]],"ltp":0.0,"tv":0.0,"id":8679736},{"batb":[[1,1.02,2],[2,1.01,1.01]],"ltp":0.0,"tv":0.0,"id":531005}]}]}
{"op":"mcm","clk":"1003241528","pt":1580605013215,"mc":[{"id":"1.168186838","marketDefinition":{"bspMarket":false,"turnInPlayEnabled":true,"persistenceEnabled":true,"marketBaseRate":5.0,"eventId":"29680287","eventTypeId":"2","numberOfWinners":1,"bettingType":"ODDS","marketType":"SET_BETTING","marketTime":"2020-02-02T02:54:00.000Z","suspendTime":"2020-02-02T02:54:00.000Z","bspReconciled":false,"complete":true,"inPlay":false,"crossMatching":true,"runnersVoidable":false,"numberOfActiveRunners":4,"betDelay":0,"status":"OPEN","runners":[{"status":"ACTIVE","sortPriority":1,"id":531005,"name":"Daniel 2 - 0"},{"status":"ACTIVE","sortPriority":2,"id":531006,"name":"Daniel 2 - 1"},{"status":"ACTIVE","sortPriority":3,"id":8679736,"name":"Hanfmann 2 - 0"},{"status":"ACTIVE","sortPriority":4,"id":8679737,"name":"Hanfmann 2 - 1"}],"regulators":["MR_INT"],"countryCode":"AU","discountAllowed":true,"timezone":"UTC","openDate":"2020-02-02T03:00:00.000Z","version":3147960790,"name":"Set Betting","eventName":"Daniel v Hanfmann"}}]}
{"op":"mcm","clk":"1003241745","pt":1580605016220,"mc":[{"id":"1.168186838","marketDefinition":{"bspMarket":false,"turnInPlayEnabled":true,"persistenceEnabled":true,"marketBaseRate":5.0,"eventId":"29680287","eventTypeId":"2","numberOfWinners":1,"bettingType":"ODDS","marketType":"SET_BETTING","marketTime":"2020-02-02T02:54:00.000Z","suspendTime":"2020-02-02T02:54:00.000Z","bspReconciled":false,"complete":true,"inPlay":false,"crossMatching":true,"runnersVoidable":false,"numberOfActiveRunners":4,"betDelay":0,"status":"OPEN","runners":[{"status":"ACTIVE","sortPriority":1,"id":531005,"name":"Daniel 2 - 0"},{"status":"ACTIVE","sortPriority":2,"id":531006,"name":"Daniel 2 - 1"},{"status":"ACTIVE","sortPriority":3,"id":8679736,"name":"Hanfmann 2 - 0"},{"status":"ACTIVE","sortPriority":4,"id":8679737,"name":"Hanfmann 2 - 1"}],"regulators":["MR_INT"],"countryCode":"AU","discountAllowed":true,"timezone":"UTC","openDate":"2020-02-02T02:54:00.000Z","version":3147960790,"name":"Set Betting","eventName":"Daniel v Hanfmann"}}]}
{"op":"mcm","clk":"1003242176","pt":1580605022593,"mc":[{"id":"1.168186838","rc":[{"batb":[[0,1.02,2],[1,1.01,1.01],[2,1.01,0]],"ltp":0.0,"tv":0.0,"id":8679737},{"batb":[[0,1.02,2],[1,1.01,1.01],[2,1.01,0]],"ltp":0.0,"tv":0.0,"id":531006}]}]}
{"op":"mcm","clk":"1003242220","pt":1580605023461,"mc":[{"id":"1.168186838","rc":[{"batb":[[0,3.2,79.97],[1,1.02,2],[2,1.01,1.01]],"batl":[[0,7,365.47]],"ltp":0.0,"tv":0.0,"id":8679737},{"batb":[[0,3.45,74.21],[1,1.02,2],[2,1.01,1.01]],"batl":[[0,9.6,263.21]],"ltp":0.0,"tv":0.0,"id":531006},{"batl":[[0,4.7,463.61]],"ltp":0.0,"tv":0.0,"id":531005}]}]}
{"op":"mcm","clk":"1003246330","pt":1580605097684,"mc":[{"id":"1.168186838","rc":[{"batb":[[0,2.52,30.29]],"ltp":0.0,"tv":0.0,"id":8679736},{"batb":[[0,2.86,89.68],[1,2.72,30.29],[2,1.02,2]],"ltp":0.0,"tv":0.0,"id":531005}]}]}
{"op":"mcm","clk":"1003246339","pt":1580605097990,"mc":[{"id":"1.168186838","rc":[{"batb":[[0,2.52,132.28]],"batl":[[0,4.8,337.17]],"ltp":0.0,"tv":0.0,"id":8679736}]}]}
{"op":"mcm","clk":"1003253075","pt":1580605218596,"mc":[{"id":"1.168186838","rc":[{"batb":[[1,1.02,2],[2,1.01,1.01]],"ltp":0.0,"tv":0.0,"id":531005}]}]}
{"op":"mcm","clk":"1003253137","pt":1580605219682,"mc":[{"id":"1.168186838","rc":[{"batb":[[0,2.52,101.99]],"ltp":0.0,"tv":0.0,"id":8679736},{"batb":[[0,2.92,87.69],[1,2.88,30.28],[2,1.02,2]],"ltp":0.0,"tv":0.0,"id":531005}]}]}
{"op":"mcm","clk":"1003253168","pt":1580605220095,"mc":[{"id":"1.168186838","rc":[{"batb":[[0,2.7,94.92],[1,2.54,30.29],[2,1.02,2]],"ltp":0.0,"tv":0.0,"id":8679736}]}]}
{"op":"mcm","clk":"1003254371","pt":1580605236642,"mc":[{"id":"1.168186838","rc":[{"batb":[[0,2.72,2]],"ltp":0.0,"tv":0.0,"id":8679736},{"batb":[[0,3.25,2]],"ltp":0.0,"tv":0.0,"id":8679737},{"batb":[[0,3.5,2]],"ltp":0.0,"tv":0.0,"id":531006},{"batb":[[0,2.94,2]],"ltp":0.0,"tv":0.0,"id":531005}]}]}
{"op":"mcm","clk":"1003254381","pt":1580605236745,"mc":[{"id":"1.168186838","rc":[{"batb":[[0,2.78,92.16],[1,2.72,2],[2,2.54,30.29]],"ltp":0.0,"tv":0.0,"id":8679736},{"batb":[[0,3.65,70.13],[1,3.25,2],[2,1.02,2]],"ltp":0.0,"tv":0.0,"id":8679737},{"batb":[[0,3.6,70.99],[1,3.5,2],[2,1.02,2]],"ltp":0.0,"tv":0.0,"id":531006},{"batb":[[0,3,85.57],[1,2.94,2],[2,2.88,30.28]],"ltp":0.0,"tv":0.0,"id":531005}]}]}
{"op":"mcm","clk":"1003255833","pt":1580605258644,"mc":[{"id":"1.168186838","rc":[{"batl":[[0,4.7,479.45]],"ltp":0.0,"tv":0.0,"id":531005}]}]}
{"op":"mcm","clk":"1003261610","pt":1580605340305,"mc":[{"id":"1.168186838","rc":[{"batb":[[2,1.02,2]],"ltp":0.0,"tv":0.0,"id":531005}]}]}
{"op":"mcm","clk":"1003261711","pt":1580605341691,"mc":[{"id":"1.168186838","rc":[{"batb":[[0,2.8,30.29],[2,1.02,2]],"ltp":0.0,"tv":0.0,"id":8679736},{"batb":[[0,3.1,82.54],[1,3.05,30.29],[2,2.94,2]],"ltp":0.0,"tv":0.0,"id":531005}]}]}
{"op":"mcm","clk":"1003261721","pt":1580605341794,"mc":[{"id":"1.168186838","rc":[{"batb":[[0,2.82,91.03],[1,2.8,30.29],[2,2.72,2]],"ltp":0.0,"tv":0.0,"id":8679736}]}]}
{"op":"mcm","clk":"1003269931","pt":1580605462658,"mc":[{"id":"1.168186838","rc":[{"batb":[[0,2.84,30.29],[1,2.82,91.03]],"ltp":0.0,"tv":0.0,"id":8679736},{"batb":[[0,3.15,111.52],[1,2.94,2],[2,1.02,2]],"ltp":0.0,"tv":0.0,"id":531005}]}]}
{"op":"mcm","clk":"1003269956","pt":1580605463020,"mc":[{"id":"1.168186838","rc":[{"batb":[[0,2.84,120.51],[1,2.72,2],[2,1.02,2]],"ltp":0.0,"tv":0.0,"id":8679736}]}]}
{"op":"mcm","clk":"1003272650","pt":1580605498571,"mc":[{"id":"1.168186838","rc":[{"batb":[[0,3.15,30.29]],"batl":[[0,4.7,55.13]],"ltp":0.0,"tv":0.0,"id":531005}]}]}
{"op":"mcm","clk":"1003276977","pt":1580605558045,"mc":[{"id":"1.168186838","rc":[{"batl":[[0,4.7,463.61]],"ltp":0.0,"tv":0.0,"id":531005}]}]}
{"op":"mcm","clk":"1003278841","pt":1580605583697,"mc":[{"id":"1.168186838","rc":[{"batb":[[0,2.94,2],[1,2.72,30.29]],"ltp":0.0,"tv":0.0,"id":531005}]}]}
{"op":"mcm","clk":"1003278921","pt":1580605584680,"mc":[{"id":"1.168186838","rc":[{"batb":[[0,2.86,30.29]],"ltp":0.0,"tv":0.0,"id":8679736},{"batb":[[0,2.96,86.63],[1,2.94,2],[2,2.72,30.29]],"ltp":0.0,"tv":0.0,"id":531005}]}]}
{"op":"mcm","clk":"1003287218","pt":1580605705638,"mc":[{"id":"1.168186838","rc":[{"batb":[[2,1.02,2]],"ltp":0.0,"tv":0.0,"id":531005}]}]}
{"op":"mcm","clk":"1003287286","pt":1580605706665,"mc":[{"id":"1.168186838","rc":[{"batb":[[0,2.78,92.16],[2,2.52,30.29]],"ltp":0.0,"tv":0.0,"id":8679736},{"batb":[[0,3.05,84.09],[1,2.98,30.29],[2,2.94,2]],"ltp":0.0,"tv":0.0,"id":531005}]}]}
{"op":"mcm","clk":"1003295871","pt":1580605827419,"mc":[{"id":"1.168186838","rc":[{"batb":[[0,3.1,112.83],[1,2.94,2],[2,1.02,2]],"ltp":0.0,"tv":0.0,"id":531005}]}]}
{"op":"mcm","clk":"1003295931","pt":1580605828244,"mc":[{"id":"1.168186838","rc":[{"batb":[[0,2.82,91.03],[1,2.8,30.29],[2,2.72,2]],"ltp":0.0,"tv":0.0,"id":8679736}]}]}
{"op":"mcm","clk":"1003296474","pt":1580605836632,"mc":[{"id":"1.168186838","rc":[{"batb":[[2,1.02,2]],"ltp":0.0,"tv":0.0,"id":8679736},{"batb":[[1,1.02,2],[2,1.01,1.01]],"ltp":0.0,"tv":0.0,"id":8679737},{"batb":[[1,1.02,2],[2,1.01,1.01]],"ltp":0.0,"tv":0.0,"id":531006},{"batb":[[1,1.02,2],[2,1.01,1.01]],"ltp":0.0,"tv":0.0,"id":531005}]}]}
{"op":"mcm","clk":"1003297041","pt":1580605845490,"mc":[{"id":"1.168186838","rc":[{"batb":[[0,2.84,2],[1,2.82,91.03],[2,2.8,30.29]],"ltp":0.0,"tv":0.0,"id":8679736},{"batb":[[0,3.7,2],[1,3.65,70.13],[2,1.02,2]],"ltp":0.0,"tv":0.0,"id":8679737},{"batb":[[0,3.65,2],[1,3.6,70.99],[2,1.02,2]],"ltp":0.0,"tv":0.0,"id":531006},{"batb":[[0,3.15,2],[1,3.1,112.83],[2,1.02,2]],"ltp":0.0,"tv":0.0,"id":531005}]}]}
{"op":"mcm","clk":"1003297070","pt":1580605845856,"mc":[{"id":"1.168186838","rc":[{"batb":[[0,2.84,92.22],[1,2.8,30.29],[2,1.02,2]],"ltp":0.0,"tv":0.0,"id":8679736},{"batb":[[0,3.8,67.23],[1,3.7,2]],"ltp":0.0,"tv":0.0,"id":8679737},{"batb":[[0,3.7,69.12],[1,3.65,2]],"ltp":0.0,"tv":0.0,"id":531006},{"batb":[[1,3.1,30.29]],"ltp":0.0,"tv":0.0,"id":531005}]}]}
{"op":"mcm","clk":"1003297961","pt":1580605859676,"mc":[{"id":"1.168186838","rc":[{"batl":[[0,7,37.06]],"ltp":0.0,"tv":0.0,"id":8679737}]}]}
{"op":"mcm","clk":"1003297977","pt":1580605859983,"mc":[{"id":"1.168186838","rc":[{"batl":[[0,7,363.9]],"ltp":0.0,"tv":0.0,"id":8679737}]}]}
{"op":"mcm","clk":"1003304205","pt":1580605949609,"mc":[{"id":"1.168186838","rc":[{"batb":[[1,1.02,2],[2,1.01,1.01]],"ltp":0.0,"tv":0.0,"id":531005}]}]}
{"op":"mcm","clk":"1003304281","pt":1580605950538,"mc":[{"id":"1.168186838","rc":[{"batb":[[0,2.86,30.29],[1,2.84,2]],"ltp":0.0,"tv":0.0,"id":8679736},{"batb":[[1,2.72,30.29],[2,1.02,2]],"ltp":0.0,"tv":0.0,"id":531005}]}]}
{"op":"mcm","clk":"1003312606","pt":1580606071587,"mc":[{"id":"1.168186838","rc":[{"batb":[[0,2.84,92.22],[1,2.52,30.29]],"ltp":0.0,"tv":0.0,"id":8679736}]}]}
{"op":"mcm","clk":"1003321307","pt":1580606193251,"mc":[{"id":"1.168186838","rc":[{"batb":[[0,2.86,30.29],[1,2.84,2]],"ltp":0.0,"tv":0.0,"id":8679736}]}]}
{"op":"mcm","clk":"1003331204","pt":1580606314612,"mc":[{"id":"1.168186838","rc":[{"batb":[[0,2.84,2],[1,1.02,2],[2,1.01,1.01]],"ltp":0.0,"tv":0.0,"id":8679736}]}]}
{"op":"mcm","clk":"1003331237","pt":1580606314923,"mc":[{"id":"1.168186838","rc":[{"batb":[[0,2.84,92.22],[1,2.52,30.29],[2,1.02,2]],"ltp":0.0,"tv":0.0,"id":8679736}]}]}
{"op":"mcm","clk":"1003340307","pt":1580606436507,"mc":[{"id":"1.168186838","rc":[{"batb":[[0,2.86,30.29],[1,2.84,2]],"ltp":0.0,"tv":0.0,"id":8679736}]}]}
{"op":"mcm","clk":"1003340962","pt":1580606445491,"mc":[{"id":"1.168186838","rc":[{"batb":[[1,1.02,2],[2,1.01,1.01]],"ltp":0.0,"tv":0.0,"id":8679736},{"batb":[[1,1.02,2],[2,1.01,1.01]],"ltp":0.0,"tv":0.0,"id":8679737},{"batb":[[1,1.02,2],[2,1.01,1.01]],"ltp":0.0,"tv":0.0,"id":531006},{"batb":[[0,2.76,92.98]],"ltp":0.0,"tv":0.0,"id":531005}]}]}
{"op":"mcm","clk":"1003341294","pt":1580606450607,"mc":[{"id":"1.168186838","rc":[{"batb":[[0,2.88,2],[1,2.86,30.29],[2,1.02,2]],"ltp":0.0,"tv":0.0,"id":8679736},{"batb":[[0,3.85,2],[1,3.8,67.23],[2,1.02,2]],"ltp":0.0,"tv":0.0,"id":8679737},{"batb":[[0,3.75,2],[1,3.7,69.12],[2,1.02,2]],"ltp":0.0,"tv":0.0,"id":531006},{"batb":[[0,2.78,2],[1,2.76,92.98],[2,2.72,30.29]],"ltp":0.0,"tv":0.0,"id":531005}]}]}
{"op":"mcm","clk":"1003341313","pt":1580606450917,"mc":[{"id":"1.168186838","rc":[{"batb":[[0,3.9,65.56],[1,3.85,2]],"ltp":0.0,"tv":0.0,"id":8679737},{"batb":[[0,3.85,66.37],[1,3.75,2]],"ltp":0.0,"tv":0.0,"id":531006},{"batb":[[0,2.84,90.22],[1,2.78,2]],"ltp":0.0,"tv":0.0,"id":531005}]}]}
{"op":"mcm","clk":"1003348383","pt":1580606558422,"mc":[{"id":"1.168186838","rc":[{"batb":[[0,2.9,88.36],[1,2.86,30.29],[2,2.78,2]],"ltp":0.0,"tv":0.0,"id":531005}]}]}
{"op":"mcm","clk":"1003348409","pt":1580606558835,"mc":[{"id":"1.168186838","rc":[{"batb":[[1,2.52,30.29]],"ltp":0.0,"tv":0.0,"id":8679736}]}]}
{"op":"mcm","clk":"1003356525","pt":1580606680205,"mc":[{"id":"1.168186838","rc":[{"batb":[[0,2.96,86.63],[1,2.92,30.29]],"ltp":0.0,"tv":0.0,"id":531005}]}]}
{"op":"mcm","clk":"1003365810","pt":1580606801452,"mc":[{"id":"1.168186838","rc":[{"batb":[[0,2.98,30.29],[1,2.96,86.63]],"ltp":0.0,"tv":0.0,"id":531005}]}]}
{"op":"mcm","clk":"1003365841","pt":1580606801864,"mc":[{"id":"1.168186838","rc":[{"batb":[[0,3,85.57],[1,2.98,30.29]],"ltp":0.0,"tv":0.0,"id":531005}]}]}
{"op":"mcm","clk":"1003376167","pt":1580606923425,"mc":[{"id":"1.168186838","rc":[{"batb":[[0,3.1,82.54],[1,3.05,30.29]],"ltp":0.0,"tv":0.0,"id":531005}]}]}
{"op":"mcm","clk":"1003385842","pt":1580607044684,"mc":[{"id":"1.168186838","rc":[{"batb":[[1,2.78,2],[2,1.02,2]],"ltp":0.0,"tv":0.0,"id":531005}]}]}
{"op":"mcm","clk":"1003385871","pt":1580607045097,"mc":[{"id":"1.168186838","rc":[{"batb":[[0,3.15,30.29]],"ltp":0.0,"tv":0.0,"id":531005}]}]}
{"op":"mcm","clk":"1003386313","pt":1580607050406,"mc":[{"id":"1.168186838","rc":[{"batb":[[0,2.52,30.29],[1,1.02,2],[2,1.01,1.01]],"ltp":0.0,"tv":0.0,"id":8679736},{"batb":[[1,1.02,2],[2,1.01,1.01]],"ltp":0.0,"tv":0.0,"id":8679737},{"batb":[[1,1.02,2],[2,1.01,1.01]],"ltp":0.0,"tv":0.0,"id":531006},{"batb":[[1,1.02,2],[2,1.01,1.01]],"ltp":0.0,"tv":0.0,"id":531005}]}]}
{"op":"mcm","clk":"1003386358","pt":1580607050886,"mc":[{"id":"1.168186838","rc":[{"batb":[[0,2.54,101.12],[1,2.52,30.29],[2,1.02,2]],"ltp":0.0,"tv":0.0,"id":8679736}]}]}
{"op":"mcm","clk":"1003386596","pt":1580607053398,"mc":[{"id":"1.168186838","rc":[{"batb":[[0,2.6,98.59],[1,2.56,2],[2,2.52,30.29]],"ltp":0.0,"tv":0.0,"id":8679736},{"batb":[[0,4,64.07],[1,3.95,2],[2,1.02,2]],"ltp":0.0,"tv":0.0,"id":8679737},{"batb":[[0,4,64.07],[1,3.9,2],[2,1.02,2]],"ltp":0.0,"tv":0.0,"id":531006},{"batb":[[0,3.2,2],[1,3.15,30.29],[2,1.02,2]],"ltp":0.0,"tv":0.0,"id":531005}]}]}
{"op":"mcm","clk":"1003395397","pt":1580607167608,"mc":[{"id":"1.168186838","rc":[{"batb":[[0,2.62,30.29],[1,2.6,98.59],[2,2.56,2]],"ltp":0.0,"tv":0.0,"id":8679736},{"batb":[[1,2.72,30.29]],"ltp":0.0,"tv":0.0,"id":531005}]}]}
{"op":"mcm","clk":"1003395415","pt":1580607167913,"mc":[{"id":"1.168186838","rc":[{"batb":[[0,2.66,96.34],[1,2.62,30.29]],"ltp":0.0,"tv":0.0,"id":8679736}]}]}
{"op":"mcm","clk":"1003404130","pt":1580607288487,"mc":[{"id":"1.168186838","rc":[{"batb":[[0,2.72,94.34],[1,2.68,30.29]],"ltp":0.0,"tv":0.0,"id":8679736}]}]}
{"op":"mcm","clk":"1003413267","pt":1580607409656,"mc":[{"id":"1.168186838","rc":[{"batb":[[1,2.56,2],[2,1.02,2]],"ltp":0.0,"tv":0.0,"id":8679736}]}]}
{"op":"mcm","clk":"1003413300","pt":1580607410067,"mc":[{"id":"1.168186838","rc":[{"batb":[[0,2.76,92.98],[1,2.74,30.29],[2,2.56,2]],"ltp":0.0,"tv":0.0,"id":8679736}]}]}
{"op":"mcm","clk":"1003422104","pt":1580607531601,"mc":[{"id":"1.168186838","rc":[{"batb":[[0,2.78,30.29],[1,2.56,2],[2,1.02,2]],"ltp":0.0,"tv":0.0,"id":8679736}]}]}
{"op":"mcm","clk":"1003422113","pt":1580607531713,"mc":[{"id":"1.168186838","rc":[{"batb":[[0,2.82,91.03],[1,2.78,30.29],[2,2.56,2]],"ltp":0.0,"tv":0.0,"id":8679736}]}]}
{"op":"mcm","clk":"1003431343","pt":1580607652662,"mc":[{"id":"1.168186838","rc":[{"batb":[[2,1.02,2]],"ltp":0.0,"tv":0.0,"id":8679736},{"batb":[[1,1.02,2],[2,1.01,1.01]],"ltp":0.0,"tv":0.0,"id":8679737}]}]}
{"op":"mcm","clk":"1003431410","pt":1580607653492,"mc":[{"id":"1.168186838","rc":[{"batb":[[0,2.84,120.51],[1,1.02,2],[2,1.01,1.01]],"ltp":0.0,"tv":0.0,"id":8679736},{"batb":[[1,1.02,2],[2,1.01,1.01]],"ltp":0.0,"tv":0.0,"id":531006},{"batb":[[0,2.76,92.98]],"ltp":0.0,"tv":0.0,"id":531005}]}]}
{"op":"mcm","clk":"1003431888","pt":1580607659660,"mc":[{"id":"1.168186838","rc":[{"batb":[[0,2.86,2],[1,2.84,120.51],[2,1.02,2]],"ltp":0.0,"tv":0.0,"id":8679736},{"batb":[[0,4.1,2],[1,4,64.07],[2,1.02,2]],"ltp":0.0,"tv":0.0,"id":8679737}]}]}
{"op":"mcm","clk":"1003431932","pt":1580607660285,"mc":[{"id":"1.168186838","rc":[{"batb":[[1,2.84,30.29]],"ltp":0.0,"tv":0.0,"id":8679736},{"batb":[[0,4.1,64.34],[1,1.02,2],[2,1.01,1.01]],"ltp":0.0,"tv":0.0,"id":8679737},{"batb":[[0,4.2,60.77],[1,4.1,2],[2,1.02,2]],"ltp":0.0,"tv":0.0,"id":531006},{"batb":[[0,2.96,86.63],[1,2.78,2],[2,2.72,30.29]],"ltp":0.0,"tv":0.0,"id":531005}]}]}
{"op":"mcm","clk":"1003440907","pt":1580607775528,"mc":[{"id":"1.168186838","rc":[{"batb":[[1,2.52,30.29]],"ltp":0.0,"tv":0.0,"id":8679736},{"batb":[[0,3,85.57],[1,2.98,30.29],[2,2.78,2]],"ltp":0.0,"tv":0.0,"id":531005}]}]}
{"op":"mcm","clk":"1003441691","pt":1580607785727,"mc":[{"id":"1.168186838","rc":[{"batl":[[0,7,37.06]],"ltp":0.0,"tv":0.0,"id":8679737},{"batl":[[0,4.7,54.95]],"ltp":0.0,"tv":0.0,"id":531005}]}]}
{"op":"mcm","clk":"1003449945","pt":1580607897483,"mc":[{"id":"1.168186838","rc":[{"batb":[[0,3.1,82.54],[1,3.05,30.29]],"ltp":0.0,"tv":0.0,"id":531005}]}]}
{"op":"mcm","clk":"1003454432","pt":1580607958073,"mc":[{"id":"1.168186838","rc":[{"batl":[[0,4.7,479.45]],"ltp":0.0,"tv":0.0,"id":531005}]}]}
{"op":"mcm","clk":"1003454567","pt":1580607959949,"mc":[{"id":"1.168186838","rc":[{"batl":[[0,7,365.47]],"ltp":0.0,"tv":0.0,"id":8679737}]}]}
{"op":"mcm","clk":"1003455993","pt":1580607978676,"mc":[{"id":"1.168186838","rc":[{"batb":[[0,2.88,2.02],[1,2.86,2],[2,2.52,30.29]],"ltp":0.0,"tv":0.0,"id":8679736},{"batb":[[0,4.2,2.02],[1,4.1,2],[2,1.02,2]],"ltp":0.0,"tv":0.0,"id":8679737},{"batb":[[0,3.15,2.02]],"ltp":0.0,"tv":0.0,"id":531005}]}]}
{"op":"mcm","clk":"1003456038","pt":1580607979197,"mc":[{"id":"1.168186838","rc":[{"batb":[[0,3.15,83.25]],"ltp":0.0,"tv":0.0,"id":531005}]}]}
{"op":"mcm","clk":"1003458447","pt":1580608013538,"mc":[{"id":"1.168186838","rc":[{"batl":[[0,4.8,53.77]],"ltp":0.0,"tv":0.0,"id":8679736}]}]}
{"op":"mcm","clk":"1003458844","pt":1580608018641,"mc":[{"id":"1.168186838","rc":[{"batb":[[0,3.2,30.29],[1,3.15,2.02]],"ltp":0.0,"tv":0.0,"id":531005}]}]}
{"op":"mcm","clk":"1003459561","pt":1580608027831,"mc":[{"id":"1.168186838","rc":[{"batl":[[0,4.8,323.77]],"ltp":0.0,"tv":0.0,"id":8679736}]}]}
{"op":"mcm","clk":"1003465563","pt":1580608110558,"mc":[{"id":"1.168186838","rc":[{"batl":[[0,9.6,26.81]],"ltp":0.0,"tv":0.0,"id":531006},{"batl":[[0,4.7,54.95]],"ltp":0.0,"tv":0.0,"id":531005}]}]}
{"op":"mcm","clk":"1003467492","pt":1580608140068,"mc":[{"id":"1.168186838","rc":[{"batb":[[0,3.15,83.25],[1,2.78,2],[2,2.72,30.29]],"ltp":0.0,"tv":0.0,"id":531005}]}]}
{"op":"mcm","clk":"1003476185","pt":1580608258142,"mc":[{"id":"1.168186838","rc":[{"batl":[[0,4.7,495.95]],"ltp":0.0,"tv":0.0,"id":531005}]}]}
{"op":"mcm","clk":"1003476271","pt":1580608259634,"mc":[{"id":"1.168186838","rc":[{"batb":[[1,2.52,30.29],[2,1.02,2]],"ltp":0.0,"tv":0.0,"id":8679736},{"batb":[[1,1.02,2],[2,1.01,1.01]],"ltp":0.0,"tv":0.0,"id":8679737},{"batb":[[1,1.02,2],[2,1.01,1.01]],"ltp":0.0,"tv":0.0,"id":531006},{"batb":[[1,2.72,30.29],[2,1.02,2]],"ltp":0.0,"tv":0.0,"id":531005}]}]}
{"op":"mcm","clk":"1003476370","pt":1580608261537,"mc":[{"id":"1.168186838","rc":[{"batb":[[0,3.2,30.29],[1,3.15,83.25]],"ltp":0.0,"tv":0.0,"id":531005}]}]}
{"op":"mcm","clk":"1003476388","pt":1580608261846,"mc":[{"id":"1.168186838","rc":[{"batb":[[0,3.2,110.26],[1,3.15,2.02]],"ltp":0.0,"tv":0.0,"id":531005}]}]}
{"op":"mcm","clk":"1003480207","pt":1580608323028,"mc":[{"id":"1.168186838","rc":[{"batl":[[0,9.6,262.16]],"ltp":0.0,"tv":0.0,"id":531006}]}]}
{"op":"mcm","clk":"1003484353","pt":1580608384496,"mc":[{"id":"1.168186838","rc":[{"batb":[[0,3.2,79.97]],"ltp":0.0,"tv":0.0,"id":531005}]}]}
{"op":"mcm","clk":"1003484587","pt":1580608387687,"mc":[{"id":"1.168186838","rc":[{"batl":[[0,7,37.06]],"ltp":0.0,"tv":0.0,"id":8679737}]}]}
{"op":"mcm","clk":"1003496457","pt":1580608560034,"mc":[{"id":"1.168186838","rc":[{"batl":[[0,7,367.11]],"ltp":0.0,"tv":0.0,"id":8679737}]}]}
{"op":"mcm","clk":"1003496745","pt":1580608563997,"mc":[{"id":"1.168186838","rc":[{"batl":[[0,4.8,53.77]],"ltp":0.0,"tv":0.0,"id":8679736},{"batl":[[0,4.7,529.55]],"ltp":0.0,"tv":0.0,"id":531005}]}]}
{"op":"mcm","clk":"1003500476","pt":1580608623620,"mc":[{"id":"1.168186838","rc":[{"batb":[[0,1.02,2],[1,1.01,1.01],[2,1.01,0]],"ltp":0.0,"tv":0.0,"id":531006}]}]}
{"op":"mcm","clk":"1003500758","pt":1580608627796,"mc":[{"id":"1.168186838","rc":[{"batl":[[0,4.8,310.72]],"ltp":0.0,"tv":0.0,"id":8679736}]}]}
{"op":"mcm","clk":"1003505212","pt":1580608698883,"mc":[{"id":"1.168186838","rc":[{"batl":[[0,3.75,397.3]],"ltp":0.0,"tv":0.0,"id":8679736}]}]}
{"op":"mcm","clk":"1003515590","pt":1580608858810,"mc":[{"id":"1.168186838","rc":[{"batl":[[0,5,498.07]],"ltp":0.0,"tv":0.0,"id":531005}]}]}
{"op":"mcm","clk":"1003531887","pt":1580609107936,"mc":[{"id":"1.168186838","rc":[{"batb":[[0,2.9,2.02],[1,2.88,2.02],[2,2.52,30.29]],"ltp":0.0,"tv":0.0,"id":8679736},{"batb":[[0,3.25,2.02]],"ltp":0.0,"tv":0.0,"id":531005}]}]}
{"op":"mcm","clk":"1003532031","pt":1580609110149,"mc":[{"id":"1.168186838","rc":[{"batl":[[0,3.75,68.78]],"ltp":0.0,"tv":0.0,"id":8679736},{"batl":[[0,5,51.83]],"ltp":0.0,"tv":0.0,"id":531005}]}]}
{"op":"mcm","clk":"1003532277","pt":1580609114060,"mc":[{"id":"1.168186838","rc":[{"batb":[[2,2.72,30.29]],"ltp":0.0,"tv":0.0,"id":531005}]}]}
{"op":"mcm","clk":"1003535100","pt":1580609158950,"mc":[{"id":"1.168186838","rc":[{"batl":[[0,5,466.46]],"ltp":0.0,"tv":0.0,"id":531005}]}]}
{"op":"mcm","clk":"1003539399","pt":1580609227909,"mc":[{"id":"1.168186838","rc":[{"batl":[[0,3.75,414.02]],"ltp":0.0,"tv":0.0,"id":8679736}]}]}
{"op":"mcm","clk":"1003548149","pt":1580609350852,"mc":[{"id":"1.168186838","rc":[{"batl":[[0,3.75,68.78]],"ltp":0.0,"tv":0.0,"id":8679736}]}]}
{"op":"mcm","clk":"1003556181","pt":1580609460270,"mc":[{"id":"1.168186838","rc":[{"batl":[[0,7.2,356.73]],"ltp":0.0,"tv":0.0,"id":8679737}]}]}
{"op":"mcm","clk":"1003561258","pt":1580609527896,"mc":[{"id":"1.168186838","rc":[{"batl":[[0,3.75,397.3]],"ltp":0.0,"tv":0.0,"id":8679736}]}]}
{"op":"mcm","clk":"1003575040","pt":1580609722472,"mc":[{"id":"1.168186838","rc":[{"batb":[[2,1.02,2]],"ltp":0.0,"tv":0.0,"id":531005}]}]}
{"op":"mcm","clk":"1003575082","pt":1580609723090,"mc":[{"id":"1.168186838","rc":[{"batb":[[2,1.02,2]],"ltp":0.0,"tv":0.0,"id":8679736}]}]}
{"op":"mcm","clk":"1003582183","pt":1580609828013,"mc":[{"id":"1.168186838","rc":[{"batb":[[0,3.35,76.47],[1,1.02,2],[2,1.01,1.01]],"batl":[[0,9.8,256.82]],"ltp":0.0,"tv":0.0,"id":531006}]}]}
{"op":"mcm","clk":"1003618540","pt":1580610314015,"mc":[{"id":"1.168186838","rc":[{"batl":[[0,3.75,68.78]],"ltp":0.0,"tv":0.0,"id":8679736},{"batl":[[0,7.2,35.83]],"ltp":0.0,"tv":0.0,"id":8679737}]}]}
{"op":"mcm","clk":"1003622323","pt":1580610360458,"mc":[{"id":"1.168186838","rc":[{"batl":[[0,7.2,355.13]],"ltp":0.0,"tv":0.0,"id":8679737}]}]}
{"op":"mcm","clk":"1003664339","pt":1580610915817,"mc":[{"id":"1.168186838","rc":[{"batl":[[0,7.2,35.83]],"ltp":0.0,"tv":0.0,"id":8679737},{"batl":[[0,5,51.83]],"ltp":0.0,"tv":0.0,"id":531005}]}]}
{"op":"mcm","clk":"1003667179","pt":1580610958992,"mc":[{"id":"1.168186838","rc":[{"batl":[[0,5,498.07]],"ltp":0.0,"tv":0.0,"id":531005}]}]}
{"op":"mcm","clk":"1003667274","pt":1580610960484,"mc":[{"id":"1.168186838","rc":[{"batl":[[0,7.2,356.73]],"ltp":0.0,"tv":0.0,"id":8679737}]}]}
{"op":"mcm","clk":"1003683039","pt":1580611183088,"mc":[{"id":"1.168186838","rc":[{"batl":[[0,5,17.73],[1,7.2,356.73]],"ltp":0.0,"tv":0.0,"id":8679737}]}]}
{"op":"mcm","clk":"1003683851","pt":1580611196580,"mc":[{"id":"1.168186838","rc":[{"batl":[[0,5.1,17.73],[1,9.8,256.82]],"ltp":0.0,"tv":0.0,"id":531006}]}]}
{"op":"mcm","clk":"1003692398","pt":1580611337670,"mc":[{"id":"1.168186838","rc":[{"batl":[[1,7.2,0]],"ltp":0.0,"tv":0.0,"id":8679737},{"batl":[[1,9.8,0]],"ltp":0.0,"tv":0.0,"id":531006},{"batb":[[0,3.25,80.75]],"ltp":0.0,"tv":0.0,"id":531005}]}]}
{"op":"mcm","clk":"1003701985","pt":1580611505446,"mc":[{"id":"1.168186838","rc":[{"batb":[[2,2.82,6]],"ltp":0.0,"tv":0.0,"id":8679736},{"batb":[[0,4.3,5],[1,4.2,2.02],[2,1.02,2]],"ltp":0.0,"tv":0.0,"id":8679737},{"batb":[[0,3.4,5],[1,3.35,76.47],[2,1.02,2]],"ltp":0.0,"tv":0.0,"id":531006},{"batb":[[0,3.3,5],[1,3.25,80.75],[2,3.15,2.02]],"ltp":0.0,"tv":0.0,"id":531005}]}]}
{"op":"mcm","clk":"1003705549","pt":1580611566134,"mc":[{"id":"1.168186838","rc":[{"batl":[[0,2.96,6]],"ltp":0.0,"tv":0.0,"id":8679736},{"batl":[[1,5.2,4]],"ltp":0.0,"tv":0.0,"id":8679737},{"batl":[[1,5.9,4]],"ltp":0.0,"tv":0.0,"id":531006},{"batl":[[0,4.9,5],[1,5,498.07]],"ltp":0.0,"tv":0.0,"id":531005}]}]}
{"op":"mcm","clk":"1003728712","pt":1580611988668,"mc":[{"id":"1.168186838","rc":[{"batb":[[0,3.35,76.47],[1,1.02,2],[2,1.01,1.01]],"ltp":0.0,"tv":0.0,"id":531006},{"batb":[[0,3.25,2.02],[1,3.15,2.02],[2,1.02,2]],"batl":[[1,5,0]],"ltp":0.0,"tv":0.0,"id":531005}]}]}
{"op":"mcm","clk":"1003728780","pt":1580611989592,"mc":[{"id":"1.168186838","rc":[{"batb":[[2,1.02,2]],"ltp":0.0,"tv":0.0,"id":8679736},{"batb":[[0,4.2,2.02],[1,1.02,2],[2,1.01,1.01]],"ltp":0.0,"tv":0.0,"id":8679737},{"batb":[[0,3.95,64.71]],"batl":[[1,5.9,0]],"ltp":0.0,"tv":0.0,"id":531006},{"batb":[[0,3.25,80.75]],"batl":[[0,4.7,529.55]],"ltp":0.0,"tv":0.0,"id":531005}]}]}
{"op":"mcm","clk":"1003728819","pt":1580611990005,"mc":[{"id":"1.168186838","rc":[{"batl":[[1,5.2,0]],"ltp":0.0,"tv":0.0,"id":8679737}]}]}
{"op":"mcm","clk":"1003728977","pt":1580611992072,"mc":[{"id":"1.168186838","rc":[{"batb":[[2,2.8,6]],"ltp":0.0,"tv":0.0,"id":8679736},{"batb":[[0,4.3,5],[1,4.2,2.02],[2,1.02,2]],"ltp":0.0,"tv":0.0,"id":8679737},{"batb":[[0,4,5],[1,3.95,64.71],[2,1.02,2]],"ltp":0.0,"tv":0.0,"id":531006},{"batb":[[0,3.3,5],[1,3.25,2.02],[2,3.15,2.02]],"ltp":0.0,"tv":0.0,"id":531005}]}]}
{"op":"mcm","clk":"1003732695","pt":1580612052589,"mc":[{"id":"1.168186838","rc":[{"batl":[[0,2.96,6]],"ltp":0.0,"tv":0.0,"id":8679736},{"batl":[[1,5.1,4]],"ltp":0.0,"tv":0.0,"id":8679737},{"batl":[[1,5.8,4]],"ltp":0.0,"tv":0.0,"id":531006},{"batl":[[0,4.6,5],[1,4.7,529.55]],"ltp":0.0,"tv":0.0,"id":531005}]}]}
{"op":"mcm","clk":"1003732719","pt":1580612052895,"mc":[{"id":"1.168186838","rc":[{"batl":[[0,4.4,565.44],[1,4.6,5]],"ltp":0.0,"tv":0.0,"id":531005}]}]}
{"op":"mcm","clk":"1003736567","pt":1580612113145,"mc":[{"id":"1.168186838","rc":[{"batl":[[0,4.3,5],[1,4.4,565.44]],"ltp":0.0,"tv":0.0,"id":531005}]}]}
{"op":"mcm","clk":"1003743479","pt":1580612213601,"mc":[{"id":"1.168186838","marketDefinition":{"bspMarket":false,"turnInPlayEnabled":true,"persistenceEnabled":true,"marketBaseRate":5.0,"eventId":"29680287","eventTypeId":"2","numberOfWinners":1,"bettingType":"ODDS","marketType":"SET_BETTING","marketTime":"2020-02-02T03:09:00.000Z","suspendTime":"2020-02-02T03:09:00.000Z","bspReconciled":false,"complete":true,"inPlay":false,"crossMatching":true,"runnersVoidable":false,"numberOfActiveRunners":4,"betDelay":0,"status":"OPEN","runners":[{"status":"ACTIVE","sortPriority":1,"id":531005,"name":"Daniel 2 - 0"},{"status":"ACTIVE","sortPriority":2,"id":531006,"name":"Daniel 2 - 1"},{"status":"ACTIVE","sortPriority":3,"id":8679736,"name":"Hanfmann 2 - 0"},{"status":"ACTIVE","sortPriority":4,"id":8679737,"name":"Hanfmann 2 - 1"}],"regulators":["MR_INT"],"countryCode":"AU","discountAllowed":true,"timezone":"UTC","openDate":"2020-02-02T02:54:00.000Z","version":3148075162,"name":"Set Betting","eventName":"Daniel v Hanfmann"},"rc":[{"batb":[[1,1.02,2],[2,1.01,1.01]],"ltp":0.0,"tv":0.0,"id":531006},{"batl":[[1,4.4,0]],"ltp":0.0,"tv":0.0,"id":531005}]}]}
{"op":"mcm","clk":"1003743485","pt":1580612213704,"mc":[{"id":"1.168186838","rc":[{"batb":[[0,4.1,62.34],[1,4,5],[2,1.02,2]],"ltp":0.0,"tv":0.0,"id":531006},{"batl":[[0,4.3,583.55]],"ltp":0.0,"tv":0.0,"id":531005}]}]}
{"op":"mcm","clk":"1003743595","pt":1580612215470,"mc":[{"id":"1.168186838","marketDefinition":{"bspMarket":false,"turnInPlayEnabled":true,"persistenceEnabled":true,"marketBaseRate":5.0,"eventId":"29680287","eventTypeId":"2","numberOfWinners":1,"bettingType":"ODDS","marketType":"SET_BETTING","marketTime":"2020-02-02T03:09:00.000Z","suspendTime":"2020-02-02T03:09:00.000Z","bspReconciled":false,"complete":true,"inPlay":false,"crossMatching":true,"runnersVoidable":false,"numberOfActiveRunners":4,"betDelay":0,"status":"OPEN","runners":[{"status":"ACTIVE","sortPriority":1,"id":531005,"name":"Daniel 2 - 0"},{"status":"ACTIVE","sortPriority":2,"id":531006,"name":"Daniel 2 - 1"},{"status":"ACTIVE","sortPriority":3,"id":8679736,"name":"Hanfmann 2 - 0"},{"status":"ACTIVE","sortPriority":4,"id":8679737,"name":"Hanfmann 2 - 1"}],"regulators":["MR_INT"],"countryCode":"AU","discountAllowed":true,"timezone":"UTC","openDate":"2020-02-02T03:09:00.000Z","version":3148075162,"name":"Set Betting","eventName":"Daniel v Hanfmann"}}]}
{"op":"mcm","clk":"1003758672","pt":1580612458932,"mc":[{"id":"1.168186838","rc":[{"batl":[[0,4.3,5]],"ltp":0.0,"tv":0.0,"id":531005}]}]}
{"op":"mcm","clk":"1003760124","pt":1580612480773,"mc":[{"id":"1.168186838","rc":[{"batl":[[0,4.3,583.55]],"ltp":0.0,"tv":0.0,"id":531005}]}]}
{"op":"mcm","clk":"1003792313","pt":1580613113519,"mc":[{"id":"1.168186838","marketDefinition":{"bspMarket":false,"turnInPlayEnabled":true,"persistenceEnabled":true,"marketBaseRate":5.0,"eventId":"29680287","eventTypeId":"2","numberOfWinners":1,"bettingType":"ODDS","marketType":"SET_BETTING","marketTime":"2020-02-02T03:24:00.000Z","suspendTime":"2020-02-02T03:24:00.000Z","bspReconciled":false,"complete":true,"inPlay":false,"crossMatching":true,"runnersVoidable":false,"numberOfActiveRunners":4,"betDelay":0,"status":"OPEN","runners":[{"status":"ACTIVE","sortPriority":1,"id":531005,"name":"Daniel 2 - 0"},{"status":"ACTIVE","sortPriority":2,"id":531006,"name":"Daniel 2 - 1"},{"status":"ACTIVE","sortPriority":3,"id":8679736,"name":"Hanfmann 2 - 0"},{"status":"ACTIVE","sortPriority":4,"id":8679737,"name":"Hanfmann 2 - 1"}],"regulators":["MR_INT"],"countryCode":"AU","discountAllowed":true,"timezone":"UTC","openDate":"2020-02-02T03:09:00.000Z","version":3148099993,"name":"Set Betting","eventName":"Daniel v Hanfmann"}}]}
{"op":"mcm","clk":"1003792394","pt":1580613115526,"mc":[{"id":"1.168186838","marketDefinition":{"bspMarket":false,"turnInPlayEnabled":true,"persistenceEnabled":true,"marketBaseRate":5.0,"eventId":"29680287","eventTypeId":"2","numberOfWinners":1,"bettingType":"ODDS","marketType":"SET_BETTING","marketTime":"2020-02-02T03:24:00.000Z","suspendTime":"2020-02-02T03:24:00.000Z","bspReconciled":false,"complete":true,"inPlay":false,"crossMatching":true,"runnersVoidable":false,"numberOfActiveRunners":4,"betDelay":0,"status":"OPEN","runners":[{"status":"ACTIVE","sortPriority":1,"id":531005,"name":"Daniel 2 - 0"},{"status":"ACTIVE","sortPriority":2,"id":531006,"name":"Daniel 2 - 1"},{"status":"ACTIVE","sortPriority":3,"id":8679736,"name":"Hanfmann 2 - 0"},{"status":"ACTIVE","sortPriority":4,"id":8679737,"name":"Hanfmann 2 - 1"}],"regulators":["MR_INT"],"countryCode":"AU","discountAllowed":true,"timezone":"UTC","openDate":"2020-02-02T03:24:00.000Z","version":3148099993,"name":"Set Betting","eventName":"Daniel v Hanfmann"}}]}
{"op":"mcm","clk":"1003792598","pt":1580613120624,"mc":[{"id":"1.168186838","rc":[{"batb":[[0,4.2,60.77]],"ltp":0.0,"tv":0.0,"id":531006}]}]}
{"op":"mcm","clk":"1003804069","pt":1580613413219,"mc":[{"id":"1.168186838","marketDefinition":{"bspMarket":false,"turnInPlayEnabled":true,"persistenceEnabled":true,"marketBaseRate":5.0,"eventId":"29680287","eventTypeId":"2","numberOfWinners":1,"bettingType":"ODDS","marketType":"SET_BETTING","marketTime":"2020-02-02T03:33:00.000Z","suspendTime":"2020-02-02T03:33:00.000Z","bspReconciled":false,"complete":true,"inPlay":false,"crossMatching":true,"runnersVoidable":false,"numberOfActiveRunners":4,"betDelay":0,"status":"OPEN","runners":[{"status":"ACTIVE","sortPriority":1,"id":531005,"name":"Daniel 2 - 0"},{"status":"ACTIVE","sortPriority":2,"id":531006,"name":"Daniel 2 - 1"},{"status":"ACTIVE","sortPriority":3,"id":8679736,"name":"Hanfmann 2 - 0"},{"status":"ACTIVE","sortPriority":4,"id":8679737,"name":"Hanfmann 2 - 1"}],"regulators":["MR_INT"],"countryCode":"AU","discountAllowed":true,"timezone":"UTC","openDate":"2020-02-02T03:24:00.000Z","version":3148104071,"name":"Set Betting","eventName":"Daniel v Hanfmann"}}]}
{"op":"mcm","clk":"1003804278","pt":1580613417227,"mc":[{"id":"1.168186838","marketDefinition":{"bspMarket":false,"turnInPlayEnabled":true,"persistenceEnabled":true,"marketBaseRate":5.0,"eventId":"29680287","eventTypeId":"2","numberOfWinners":1,"bettingType":"ODDS","marketType":"SET_BETTING","marketTime":"2020-02-02T03:33:00.000Z","suspendTime":"2020-02-02T03:33:00.000Z","bspReconciled":false,"complete":true,"inPlay":false,"crossMatching":true,"runnersVoidable":false,"numberOfActiveRunners":4,"betDelay":0,"status":"OPEN","runners":[{"status":"ACTIVE","sortPriority":1,"id":531005,"name":"Daniel 2 - 0"},{"status":"ACTIVE","sortPriority":2,"id":531006,"name":"Daniel 2 - 1"},{"status":"ACTIVE","sortPriority":3,"id":8679736,"name":"Hanfmann 2 - 0"},{"status":"ACTIVE","sortPriority":4,"id":8679737,"name":"Hanfmann 2 - 1"}],"regulators":["MR_INT"],"countryCode":"AU","discountAllowed":true,"timezone":"UTC","openDate":"2020-02-02T03:33:00.000Z","version":3148104071,"name":"Set Betting","eventName":"Daniel v Hanfmann"}}]}
{"op":"mcm","clk":"1003844122","pt":1580614313152,"mc":[{"id":"1.168186838","marketDefinition":{"bspMarket":false,"turnInPlayEnabled":true,"persistenceEnabled":true,"marketBaseRate":5.0,"eventId":"29680287","eventTypeId":"2","numberOfWinners":1,"bettingType":"ODDS","marketType":"SET_BETTING","marketTime":"2020-02-02T03:48:00.000Z","suspendTime":"2020-02-02T03:48:00.000Z","bspReconciled":false,"complete":true,"inPlay":false,"crossMatching":true,"runnersVoidable":false,"numberOfActiveRunners":4,"betDelay":0,"status":"OPEN","runners":[{"status":"ACTIVE","sortPriority":1,"id":531005,"name":"Daniel 2 - 0"},{"status":"ACTIVE","sortPriority":2,"id":531006,"name":"Daniel 2 - 1"},{"status":"ACTIVE","sortPriority":3,"id":8679736,"name":"Hanfmann 2 - 0"},{"status":"ACTIVE","sortPriority":4,"id":8679737,"name":"Hanfmann 2 - 1"}],"regulators":["MR_INT"],"countryCode":"AU","discountAllowed":true,"timezone":"UTC","openDate":"2020-02-02T03:33:00.000Z","version":3148118352,"name":"Set Betting","eventName":"Daniel v Hanfmann"}}]}
{"op":"mcm","clk":"1003844287","pt":1580614316160,"mc":[{"id":"1.168186838","marketDefinition":{"bspMarket":false,"turnInPlayEnabled":true,"persistenceEnabled":true,"marketBaseRate":5.0,"eventId":"29680287","eventTypeId":"2","numberOfWinners":1,"bettingType":"ODDS","marketType":"SET_BETTING","marketTime":"2020-02-02T03:48:00.000Z","suspendTime":"2020-02-02T03:48:00.000Z","bspReconciled":false,"complete":true,"inPlay":false,"crossMatching":true,"runnersVoidable":false,"numberOfActiveRunners":4,"betDelay":0,"status":"OPEN","runners":[{"status":"ACTIVE","sortPriority":1,"id":531005,"name":"Daniel 2 - 0"},{"status":"ACTIVE","sortPriority":2,"id":531006,"name":"Daniel 2 - 1"},{"status":"ACTIVE","sortPriority":3,"id":8679736,"name":"Hanfmann 2 - 0"},{"status":"ACTIVE","sortPriority":4,"id":8679737,"name":"Hanfmann 2 - 1"}],"regulators":["MR_INT"],"countryCode":"AU","discountAllowed":true,"timezone":"UTC","openDate":"2020-02-02T03:48:00.000Z","version":3148118352,"name":"Set Betting","eventName":"Daniel v Hanfmann"}}]}
{"op":"mcm","clk":"1003884924","pt":1580615213127,"mc":[{"id":"1.168186838","marketDefinition":{"bspMarket":false,"turnInPlayEnabled":true,"persistenceEnabled":true,"marketBaseRate":5.0,"eventId":"29680287","eventTypeId":"2","numberOfWinners":1,"bettingType":"ODDS","marketType":"SET_BETTING","marketTime":"2020-02-02T04:03:00.000Z","suspendTime":"2020-02-02T04:03:00.000Z","bspReconciled":false,"complete":true,"inPlay":false,"crossMatching":true,"runnersVoidable":false,"numberOfActiveRunners":4,"betDelay":0,"status":"OPEN","runners":[{"status":"ACTIVE","sortPriority":1,"id":531005,"name":"Daniel 2 - 0"},{"status":"ACTIVE","sortPriority":2,"id":531006,"name":"Daniel 2 - 1"},{"status":"ACTIVE","sortPriority":3,"id":8679736,"name":"Hanfmann 2 - 0"},{"status":"ACTIVE","sortPriority":4,"id":8679737,"name":"Hanfmann 2 - 1"}],"regulators":["MR_INT"],"countryCode":"AU","discountAllowed":true,"timezone":"UTC","openDate":"2020-02-02T03:48:00.000Z","version":3148131912,"name":"Set Betting","eventName":"Daniel v Hanfmann"}}]}
{"op":"mcm","clk":"1003885260","pt":1580615222147,"mc":[{"id":"1.168186838","marketDefinition":{"bspMarket":false,"turnInPlayEnabled":true,"persistenceEnabled":true,"marketBaseRate":5.0,"eventId":"29680287","eventTypeId":"2","numberOfWinners":1,"bettingType":"ODDS","marketType":"SET_BETTING","marketTime":"2020-02-02T04:03:00.000Z","suspendTime":"2020-02-02T04:03:00.000Z","bspReconciled":false,"complete":true,"inPlay":false,"crossMatching":true,"runnersVoidable":false,"numberOfActiveRunners":4,"betDelay":0,"status":"OPEN","runners":[{"status":"ACTIVE","sortPriority":1,"id":531005,"name":"Daniel 2 - 0"},{"status":"ACTIVE","sortPriority":2,"id":531006,"name":"Daniel 2 - 1"},{"status":"ACTIVE","sortPriority":3,"id":8679736,"name":"Hanfmann 2 - 0"},{"status":"ACTIVE","sortPriority":4,"id":8679737,"name":"Hanfmann 2 - 1"}],"regulators":["MR_INT"],"countryCode":"AU","discountAllowed":true,"timezone":"UTC","openDate":"2020-02-02T04:03:00.000Z","version":3148131912,"name":"Set Betting","eventName":"Daniel v Hanfmann"}}]}
{"op":"mcm","clk":"1003917285","pt":1580616113068,"mc":[{"id":"1.168186838","marketDefinition":{"bspMarket":false,"turnInPlayEnabled":true,"persistenceEnabled":true,"marketBaseRate":5.0,"eventId":"29680287","eventTypeId":"2","numberOfWinners":1,"bettingType":"ODDS","marketType":"SET_BETTING","marketTime":"2020-02-02T04:18:00.000Z","suspendTime":"2020-02-02T04:18:00.000Z","bspReconciled":false,"complete":true,"inPlay":false,"crossMatching":true,"runnersVoidable":false,"numberOfActiveRunners":4,"betDelay":0,"status":"OPEN","runners":[{"status":"ACTIVE","sortPriority":1,"id":531005,"name":"Daniel 2 - 0"},{"status":"ACTIVE","sortPriority":2,"id":531006,"name":"Daniel 2 - 1"},{"status":"ACTIVE","sortPriority":3,"id":8679736,"name":"Hanfmann 2 - 0"},{"status":"ACTIVE","sortPriority":4,"id":8679737,"name":"Hanfmann 2 - 1"}],"regulators":["MR_INT"],"countryCode":"AU","discountAllowed":true,"timezone":"UTC","openDate":"2020-02-02T04:03:00.000Z","version":3148141595,"name":"Set Betting","eventName":"Daniel v Hanfmann"}}]}
{"op":"mcm","clk":"1003917423","pt":1580616116074,"mc":[{"id":"1.168186838","marketDefinition":{"bspMarket":false,"turnInPlayEnabled":true,"persistenceEnabled":true,"marketBaseRate":5.0,"eventId":"29680287","eventTypeId":"2","numberOfWinners":1,"bettingType":"ODDS","marketType":"SET_BETTING","marketTime":"2020-02-02T04:18:00.000Z","suspendTime":"2020-02-02T04:18:00.000Z","bspReconciled":false,"complete":true,"inPlay":false,"crossMatching":true,"runnersVoidable":false,"numberOfActiveRunners":4,"betDelay":0,"status":"OPEN","runners":[{"status":"ACTIVE","sortPriority":1,"id":531005,"name":"Daniel 2 - 0"},{"status":"ACTIVE","sortPriority":2,"id":531006,"name":"Daniel 2 - 1"},{"status":"ACTIVE","sortPriority":3,"id":8679736,"name":"Hanfmann 2 - 0"},{"status":"ACTIVE","sortPriority":4,"id":8679737,"name":"Hanfmann 2 - 1"}],"regulators":["MR_INT"],"countryCode":"AU","discountAllowed":true,"timezone":"UTC","openDate":"2020-02-02T04:18:00.000Z","version":3148141595,"name":"Set Betting","eventName":"Daniel v Hanfmann"}}]}
{"op":"mcm","clk":"1003958135","pt":1580617013090,"mc":[{"id":"1.168186838","marketDefinition":{"bspMarket":false,"turnInPlayEnabled":true,"persistenceEnabled":true,"marketBaseRate":5.0,"eventId":"29680287","eventTypeId":"2","numberOfWinners":1,"bettingType":"ODDS","marketType":"SET_BETTING","marketTime":"2020-02-02T04:33:00.000Z","suspendTime":"2020-02-02T04:33:00.000Z","bspReconciled":false,"complete":true,"inPlay":false,"crossMatching":true,"runnersVoidable":false,"numberOfActiveRunners":4,"betDelay":0,"status":"OPEN","runners":[{"status":"ACTIVE","sortPriority":1,"id":531005,"name":"Daniel 2 - 0"},{"status":"ACTIVE","sortPriority":2,"id":531006,"name":"Daniel 2 - 1"},{"status":"ACTIVE","sortPriority":3,"id":8679736,"name":"Hanfmann 2 - 0"},{"status":"ACTIVE","sortPriority":4,"id":8679737,"name":"Hanfmann 2 - 1"}],"regulators":["MR_INT"],"countryCode":"AU","discountAllowed":true,"timezone":"UTC","openDate":"2020-02-02T04:18:00.000Z","version":3148155790,"name":"Set Betting","eventName":"Daniel v Hanfmann"}}]}
{"op":"mcm","clk":"1003958201","pt":1580617014156,"mc":[{"id":"1.168186838","rc":[{"batb":[[0,4,5],[1,1.02,2],[2,1.01,1.01]],"ltp":0.0,"tv":0.0,"id":531006},{"batl":[[0,4.3,5]],"ltp":0.0,"tv":0.0,"id":531005}]}]}
{"op":"mcm","clk":"1003958235","pt":1580617015095,"mc":[{"id":"1.168186838","marketDefinition":{"bspMarket":false,"turnInPlayEnabled":true,"persistenceEnabled":true,"marketBaseRate":5.0,"eventId":"29680287","eventTypeId":"2","numberOfWinners":1,"bettingType":"ODDS","marketType":"SET_BETTING","marketTime":"2020-02-02T04:33:00.000Z","suspendTime":"2020-02-02T04:33:00.000Z","bspReconciled":false,"complete":true,"inPlay":false,"crossMatching":true,"runnersVoidable":false,"numberOfActiveRunners":4,"betDelay":0,"status":"OPEN","runners":[{"status":"ACTIVE","sortPriority":1,"id":531005,"name":"Daniel 2 - 0"},{"status":"ACTIVE","sortPriority":2,"id":531006,"name":"Daniel 2 - 1"},{"status":"ACTIVE","sortPriority":3,"id":8679736,"name":"Hanfmann 2 - 0"},{"status":"ACTIVE","sortPriority":4,"id":8679737,"name":"Hanfmann 2 - 1"}],"regulators":["MR_INT"],"countryCode":"AU","discountAllowed":true,"timezone":"UTC","openDate":"2020-02-02T04:33:00.000Z","version":3148155790,"name":"Set Betting","eventName":"Daniel v Hanfmann"}}]}
{"op":"mcm","clk":"1003958806","pt":1580617025686,"mc":[{"id":"1.168186838","rc":[{"batb":[[0,4.3,59.38],[1,4,5],[2,1.02,2]],"ltp":0.0,"tv":0.0,"id":531006},{"batl":[[0,4.3,583.55]],"ltp":0.0,"tv":0.0,"id":531005}]}]}
{"op":"mcm","clk":"1003968423","pt":1580617237672,"mc":[{"id":"1.168186838","rc":[{"batb":[[2,1.02,2]],"ltp":0.0,"tv":0.0,"id":8679736},{"batb":[[0,4.2,2.02],[1,1.02,2],[2,1.01,1.01]],"ltp":0.0,"tv":0.0,"id":8679737},{"batb":[[1,1.02,2],[2,1.01,1.01]],"ltp":0.0,"tv":0.0,"id":531006},{"batb":[[0,3.25,2.02],[1,3.15,2.02],[2,1.02,2]],"ltp":0.0,"tv":0.0,"id":531005}]}]}
{"op":"mcm","clk":"1003968441","pt":1580617238082,"mc":[{"id":"1.168186838","rc":[{"batb":[[0,2.9,8.02]],"ltp":0.0,"tv":0.0,"id":8679736},{"batb":[[0,4.3,5],[1,4.2,2.02],[2,1.02,2]],"ltp":0.0,"tv":0.0,"id":8679737},{"batb":[[0,4.4,5],[1,4.3,59.38],[2,1.02,2]],"ltp":0.0,"tv":0.0,"id":531006},{"batb":[[0,3.3,5],[1,3.25,2.02],[2,3.15,2.02]],"ltp":0.0,"tv":0.0,"id":531005}]}]}
{"op":"mcm","clk":"1003971031","pt":1580617298619,"mc":[{"id":"1.168186838","rc":[{"batl":[[1,5.8,0]],"ltp":0.0,"tv":0.0,"id":531006}]}]}
{"op":"mcm","clk":"1003971090","pt":1580617299647,"mc":[{"id":"1.168186838","rc":[{"batl":[[0,3.2,5]],"ltp":0.0,"tv":0.0,"id":8679736},{"batl":[[1,5.2,4]],"ltp":0.0,"tv":0.0,"id":8679737},{"batl":[[1,5.6,4]],"ltp":0.0,"tv":0.0,"id":531006},{"batl":[[0,4.2,5],[1,4.3,578.55]],"ltp":0.0,"tv":0.0,"id":531005}]}]}
{"op":"mcm","clk":"1003971107","pt":1580617299955,"mc":[{"id":"1.168186838","rc":[{"batb":[[0,4.4,63.01],[1,1.02,2],[2,1.01,1.01]],"ltp":0.0,"tv":0.0,"id":531006}]}]}
{"op":"mcm","clk":"1003980604","pt":1580617502042,"mc":[{"id":"1.168186838","rc":[{"batl":[[0,4.2,66.43],[1,4.3,0]],"ltp":0.0,"tv":0.0,"id":531005}]}]}
{"op":"mcm","clk":"1003986376","pt":1580617625520,"mc":[{"id":"1.168186838","rc":[{"batl":[[0,4.2,559.63]],"ltp":0.0,"tv":0.0,"id":531005}]}]}
{"op":"mcm","clk":"1003990185","pt":1580617722533,"mc":[{"id":"1.168186838","rc":[{"batb":[[0,2.9,2.02]],"ltp":0.0,"tv":0.0,"id":8679736},{"batb":[[0,4.2,2.02],[1,1.02,2],[2,1.01,1.01]],"ltp":0.0,"tv":0.0,"id":8679737},{"batb":[[0,4.4,58.01]],"ltp":0.0,"tv":0.0,"id":531006},{"batb":[[0,3.25,2.02],[1,3.15,2.02],[2,1.02,2]],"batl":[[0,4.2,554.63]],"ltp":0.0,"tv":0.0,"id":531005}]}]}
{"op":"mcm","clk":"1003990214","pt":1580617723253,"mc":[{"id":"1.168186838","rc":[{"batl":[[1,5.2,0]],"ltp":0.0,"tv":0.0,"id":8679737},{"batl":[[1,5.6,0]],"ltp":0.0,"tv":0.0,"id":531006}]}]}
{"op":"mcm","clk":"1003990271","pt":1580617725212,"mc":[{"id":"1.168186838","rc":[{"batb":[[0,2.92,6],[1,2.9,2.02],[2,2.88,2.02]],"ltp":0.0,"tv":0.0,"id":8679736},{"batb":[[0,4.3,5],[1,4.2,2.02],[2,1.02,2]],"ltp":0.0,"tv":0.0,"id":8679737},{"batb":[[0,4.5,5],[1,4.4,58.01],[2,1.02,2]],"ltp":0.0,"tv":0.0,"id":531006},{"batb":[[0,3.3,5],[1,3.25,2.02],[2,3.15,2.02]],"ltp":0.0,"tv":0.0,"id":531005}]}]}
{"op":"mcm","clk":"1003993032","pt":1580617785907,"mc":[{"id":"1.168186838","rc":[{"batl":[[0,3.2,5]],"ltp":0.0,"tv":0.0,"id":8679736},{"batl":[[1,5.2,4]],"ltp":0.0,"tv":0.0,"id":8679737},{"batl":[[1,5.6,4]],"ltp":0.0,"tv":0.0,"id":531006},{"batl":[[0,4.1,5],[1,4.2,554.63]],"ltp":0.0,"tv":0.0,"id":531005}]}]}
{"op":"mcm","clk":"1003999254","pt":1580617912895,"mc":[{"id":"1.168186838","marketDefinition":{"bspMarket":false,"turnInPlayEnabled":true,"persistenceEnabled":true,"marketBaseRate":5.0,"eventId":"29680287","eventTypeId":"2","numberOfWinners":1,"bettingType":"ODDS","marketType":"SET_BETTING","marketTime":"2020-02-02T04:48:00.000Z","suspendTime":"2020-02-02T04:48:00.000Z","bspReconciled":false,"complete":true,"inPlay":false,"crossMatching":true,"runnersVoidable":false,"numberOfActiveRunners":4,"betDelay":0,"status":"OPEN","runners":[{"status":"ACTIVE","sortPriority":1,"id":531005,"name":"Daniel 2 - 0"},{"status":"ACTIVE","sortPriority":2,"id":531006,"name":"Daniel 2 - 1"},{"status":"ACTIVE","sortPriority":3,"id":8679736,"name":"Hanfmann 2 - 0"},{"status":"ACTIVE","sortPriority":4,"id":8679737,"name":"Hanfmann 2 - 1"}],"regulators":["MR_INT"],"countryCode":"AU","discountAllowed":true,"timezone":"UTC","openDate":"2020-02-02T04:33:00.000Z","version":3148160047,"name":"Set Betting","eventName":"Daniel v Hanfmann"}}]}
{"op":"mcm","clk":"1003999478","pt":1580617916902,"mc":[{"id":"1.168186838","marketDefinition":{"bspMarket":false,"turnInPlayEnabled":true,"persistenceEnabled":true,"marketBaseRate":5.0,"eventId":"29680287","eventTypeId":"2","numberOfWinners":1,"bettingType":"ODDS","marketType":"SET_BETTING","marketTime":"2020-02-02T04:48:00.000Z","suspendTime":"2020-02-02T04:48:00.000Z","bspReconciled":false,"complete":true,"inPlay":false,"crossMatching":true,"runnersVoidable":false,"numberOfActiveRunners":4,"betDelay":0,"status":"OPEN","runners":[{"status":"ACTIVE","sortPriority":1,"id":531005,"name":"Daniel 2 - 0"},{"status":"ACTIVE","sortPriority":2,"id":531006,"name":"Daniel 2 - 1"},{"status":"ACTIVE","sortPriority":3,"id":8679736,"name":"Hanfmann 2 - 0"},{"status":"ACTIVE","sortPriority":4,"id":8679737,"name":"Hanfmann 2 - 1"}],"regulators":["MR_INT"],"countryCode":"AU","discountAllowed":true,"timezone":"UTC","openDate":"2020-02-02T04:48:00.000Z","version":3148160047,"name":"Set Betting","eventName":"Daniel v Hanfmann"}}]}
{"op":"mcm","clk":"1004000110","pt":1580617929893,"mc":[{"id":"1.168186838","rc":[{"batb":[[1,1.02,2],[2,1.01,1.01]],"ltp":0.0,"tv":0.0,"id":531006},{"batl":[[1,4.2,0]],"ltp":0.0,"tv":0.0,"id":531005}]}]}
{"op":"mcm","clk":"1004030041","pt":1580618570615,"mc":[{"id":"1.168186838","rc":[{"batb":[[0,2.9,2.02],[1,2.88,2.02],[2,1.02,2]],"ltp":0.0,"tv":0.0,"id":8679736},{"batb":[[0,4.2,2.02],[1,1.02,2],[2,1.01,1.01]],"ltp":0.0,"tv":0.0,"id":8679737},{"batb":[[0,1.02,2],[1,1.01,1.01],[2,1.01,0]],"ltp":0.0,"tv":0.0,"id":531006},{"batb":[[0,3.25,2.02],[1,3.15,2.02],[2,1.02,2]],"ltp":0.0,"tv":0.0,"id":531005}]}]}
{"op":"mcm","clk":"1004030060","pt":1580618571026,"mc":[{"id":"1.168186838","rc":[{"batb":[[0,2.9,8.02]],"ltp":0.0,"tv":0.0,"id":8679736},{"batb":[[0,4.3,5],[1,4.2,2.02],[2,1.02,2]],"ltp":0.0,"tv":0.0,"id":8679737},{"batb":[[0,1.03,137],[1,1.02,2],[2,1.01,1.01]],"ltp":0.0,"tv":0.0,"id":531006},{"batb":[[0,3.3,5],[1,3.25,2.02],[2,3.15,2.02]],"ltp":0.0,"tv":0.0,"id":531005}]}]}
{"op":"mcm","clk":"1004033302","pt":1580618631587,"mc":[{"id":"1.168186838","rc":[{"batl":[[1,5.6,0]],"ltp":0.0,"tv":0.0,"id":531006}]}]}
{"op":"mcm","clk":"1004033349","pt":1580618632365,"mc":[{"id":"1.168186838","rc":[{"batl":[[0,3.1,5]],"ltp":0.0,"tv":0.0,"id":8679736},{"batl":[[1,5.1,4]],"ltp":0.0,"tv":0.0,"id":8679737},{"batl":[[1,5.6,4]],"ltp":0.0,"tv":0.0,"id":531006},{"batl":[[0,3.85,5]],"ltp":0.0,"tv":0.0,"id":531005}]}]}
{"op":"mcm","clk":"1004042103","pt":1580618812677,"mc":[{"id":"1.168186838","marketDefinition":{"bspMarket":false,"turnInPlayEnabled":true,"persistenceEnabled":true,"marketBaseRate":5.0,"eventId":"29680287","eventTypeId":"2","numberOfWinners":1,"bettingType":"ODDS","marketType":"SET_BETTING","marketTime":"2020-02-02T05:03:00.000Z","suspendTime":"2020-02-02T05:03:00.000Z","bspReconciled":false,"complete":true,"inPlay":false,"crossMatching":true,"runnersVoidable":false,"numberOfActiveRunners":4,"betDelay":0,"status":"OPEN","runners":[{"status":"ACTIVE","sortPriority":1,"id":531005,"name":"Daniel 2 - 0"},{"status":"ACTIVE","sortPriority":2,"id":531006,"name":"Daniel 2 - 1"},{"status":"ACTIVE","sortPriority":3,"id":8679736,"name":"Hanfmann 2 - 0"},{"status":"ACTIVE","sortPriority":4,"id":8679737,"name":"Hanfmann 2 - 1"}],"regulators":["MR_INT"],"countryCode":"AU","discountAllowed":true,"timezone":"UTC","openDate":"2020-02-02T04:48:00.000Z","version":3148167218,"name":"Set Betting","eventName":"Daniel v Hanfmann"}}]}
{"op":"mcm","clk":"1004042879","pt":1580618827244,"mc":[{"id":"1.168186838","rc":[{"batb":[[0,3.6,70.99],[1,1.03,137],[2,1.02,2]],"ltp":0.0,"tv":0.0,"id":531006}]}]}
{"op":"mcm","clk":"1004043048","pt":1580618830708,"mc":[{"id":"1.168186838","marketDefinition":{"bspMarket":false,"turnInPlayEnabled":true,"persistenceEnabled":true,"marketBaseRate":5.0,"eventId":"29680287","eventTypeId":"2","numberOfWinners":1,"bettingType":"ODDS","marketType":"SET_BETTING","marketTime":"2020-02-02T05:03:00.000Z","suspendTime":"2020-02-02T05:03:00.000Z","bspReconciled":false,"complete":true,"inPlay":false,"crossMatching":true,"runnersVoidable":false,"numberOfActiveRunners":4,"betDelay":0,"status":"OPEN","runners":[{"status":"ACTIVE","sortPriority":1,"id":531005,"name":"Daniel 2 - 0"},{"status":"ACTIVE","sortPriority":2,"id":531006,"name":"Daniel 2 - 1"},{"status":"ACTIVE","sortPriority":3,"id":8679736,"name":"Hanfmann 2 - 0"},{"status":"ACTIVE","sortPriority":4,"id":8679737,"name":"Hanfmann 2 - 1"}],"regulators":["MR_INT"],"countryCode":"AU","discountAllowed":true,"timezone":"UTC","openDate":"2020-02-02T05:03:00.000Z","version":3148167218,"name":"Set Betting","eventName":"Daniel v Hanfmann"}}]}
{"op":"mcm","clk":"1004076105","pt":1580619713479,"mc":[{"id":"1.168186838","marketDefinition":{"bspMarket":false,"turnInPlayEnabled":true,"persistenceEnabled":true,"marketBaseRate":5.0,"eventId":"29680287","eventTypeId":"2","numberOfWinners":1,"bettingType":"ODDS","marketType":"SET_BETTING","marketTime":"2020-02-02T05:18:00.000Z","suspendTime":"2020-02-02T05:18:00.000Z","bspReconciled":false,"complete":true,"inPlay":false,"crossMatching":true,"runnersVoidable":false,"numberOfActiveRunners":4,"betDelay":0,"status":"OPEN","runners":[{"status":"ACTIVE","sortPriority":1,"id":531005,"name":"Daniel 2 - 0"},{"status":"ACTIVE","sortPriority":2,"id":531006,"name":"Daniel 2 - 1"},{"status":"ACTIVE","sortPriority":3,"id":8679736,"name":"Hanfmann 2 - 0"},{"status":"ACTIVE","sortPriority":4,"id":8679737,"name":"Hanfmann 2 - 1"}],"regulators":["MR_INT"],"countryCode":"AU","discountAllowed":true,"timezone":"UTC","openDate":"2020-02-02T05:03:00.000Z","version":3148176196,"name":"Set Betting","eventName":"Daniel v Hanfmann"}}]}
{"op":"mcm","clk":"1004076270","pt":1580619716486,"mc":[{"id":"1.168186838","marketDefinition":{"bspMarket":false,"turnInPlayEnabled":true,"persistenceEnabled":true,"marketBaseRate":5.0,"eventId":"29680287","eventTypeId":"2","numberOfWinners":1,"bettingType":"ODDS","marketType":"SET_BETTING","marketTime":"2020-02-02T05:18:00.000Z","suspendTime":"2020-02-02T05:18:00.000Z","bspReconciled":false,"complete":true,"inPlay":false,"crossMatching":true,"runnersVoidable":false,"numberOfActiveRunners":4,"betDelay":0,"status":"OPEN","runners":[{"status":"ACTIVE","sortPriority":1,"id":531005,"name":"Daniel 2 - 0"},{"status":"ACTIVE","sortPriority":2,"id":531006,"name":"Daniel 2 - 1"},{"status":"ACTIVE","sortPriority":3,"id":8679736,"name":"Hanfmann 2 - 0"},{"status":"ACTIVE","sortPriority":4,"id":8679737,"name":"Hanfmann 2 - 1"}],"regulators":["MR_INT"],"countryCode":"AU","discountAllowed":true,"timezone":"UTC","openDate":"2020-02-02T05:18:00.000Z","version":3148176196,"name":"Set Betting","eventName":"Daniel v Hanfmann"}}]}
{"op":"mcm","clk":"1004111507","pt":1580620613279,"mc":[{"id":"1.168186838","marketDefinition":{"bspMarket":false,"turnInPlayEnabled":true,"persistenceEnabled":true,"marketBaseRate":5.0,"eventId":"29680287","eventTypeId":"2","numberOfWinners":1,"bettingType":"ODDS","marketType":"SET_BETTING","marketTime":"2020-02-02T05:33:00.000Z","suspendTime":"2020-02-02T05:33:00.000Z","bspReconciled":false,"complete":true,"inPlay":false,"crossMatching":true,"runnersVoidable":false,"numberOfActiveRunners":4,"betDelay":0,"status":"OPEN","runners":[{"status":"ACTIVE","sortPriority":1,"id":531005,"name":"Daniel 2 - 0"},{"status":"ACTIVE","sortPriority":2,"id":531006,"name":"Daniel 2 - 1"},{"status":"ACTIVE","sortPriority":3,"id":8679736,"name":"Hanfmann 2 - 0"},{"status":"ACTIVE","sortPriority":4,"id":8679737,"name":"Hanfmann 2 - 1"}],"regulators":["MR_INT"],"countryCode":"AU","discountAllowed":true,"timezone":"UTC","openDate":"2020-02-02T05:18:00.000Z","version":3148190104,"name":"Set Betting","eventName":"Daniel v Hanfmann"}}]}
{"op":"mcm","clk":"1004111685","pt":1580620616285,"mc":[{"id":"1.168186838","marketDefinition":{"bspMarket":false,"turnInPlayEnabled":true,"persistenceEnabled":true,"marketBaseRate":5.0,"eventId":"29680287","eventTypeId":"2","numberOfWinners":1,"bettingType":"ODDS","marketType":"SET_BETTING","marketTime":"2020-02-02T05:33:00.000Z","suspendTime":"2020-02-02T05:33:00.000Z","bspReconciled":false,"complete":true,"inPlay":false,"crossMatching":true,"runnersVoidable":false,"numberOfActiveRunners":4,"betDelay":0,"status":"OPEN","runners":[{"status":"ACTIVE","sortPriority":1,"id":531005,"name":"Daniel 2 - 0"},{"status":"ACTIVE","sortPriority":2,"id":531006,"name":"Daniel 2 - 1"},{"status":"ACTIVE","sortPriority":3,"id":8679736,"name":"Hanfmann 2 - 0"},{"status":"ACTIVE","sortPriority":4,"id":8679737,"name":"Hanfmann 2 - 1"}],"regulators":["MR_INT"],"countryCode":"AU","discountAllowed":true,"timezone":"UTC","openDate":"2020-02-02T05:33:00.000Z","version":3148190104,"name":"Set Betting","eventName":"Daniel v Hanfmann"}}]}
{"op":"mcm","clk":"1004127733","pt":1580620927270,"mc":[{"id":"1.168186838","rc":[{"batl":[[0,5.1,21.73],[1,5.1,0]],"ltp":0.0,"tv":0.0,"id":8679737},{"batl":[[0,5.1,10.13]],"ltp":0.0,"tv":0.0,"id":531006}]}]}
{"op":"mcm","clk":"1004128248","pt":1580620937123,"mc":[{"id":"1.168186838","rc":[{"batl":[[0,5.1,14.13]],"ltp":0.0,"tv":0.0,"id":8679737}]}]}
{"op":"mcm","clk":"1004151850","pt":1580621513271,"mc":[{"id":"1.168186838","marketDefinition":{"bspMarket":false,"turnInPlayEnabled":true,"persistenceEnabled":true,"marketBaseRate":5.0,"eventId":"29680287","eventTypeId":"2","numberOfWinners":1,"bettingType":"ODDS","marketType":"SET_BETTING","marketTime":"2020-02-02T05:48:00.000Z","suspendTime":"2020-02-02T05:48:00.000Z","bspReconciled":false,"complete":true,"inPlay":false,"crossMatching":true,"runnersVoidable":false,"numberOfActiveRunners":4,"betDelay":0,"status":"OPEN","runners":[{"status":"ACTIVE","sortPriority":1,"id":531005,"name":"Daniel 2 - 0"},{"status":"ACTIVE","sortPriority":2,"id":531006,"name":"Daniel 2 - 1"},{"status":"ACTIVE","sortPriority":3,"id":8679736,"name":"Hanfmann 2 - 0"},{"status":"ACTIVE","sortPriority":4,"id":8679737,"name":"Hanfmann 2 - 1"}],"regulators":["MR_INT"],"countryCode":"AU","discountAllowed":true,"timezone":"UTC","openDate":"2020-02-02T05:33:00.000Z","version":3148205936,"name":"Set Betting","eventName":"Daniel v Hanfmann"}}]}
{"op":"mcm","clk":"1004151955","pt":1580621516276,"mc":[{"id":"1.168186838","marketDefinition":{"bspMarket":false,"turnInPlayEnabled":true,"persistenceEnabled":true,"marketBaseRate":5.0,"eventId":"29680287","eventTypeId":"2","numberOfWinners":1,"bettingType":"ODDS","marketType":"SET_BETTING","marketTime":"2020-02-02T05:48:00.000Z","suspendTime":"2020-02-02T05:48:00.000Z","bspReconciled":false,"complete":true,"inPlay":false,"crossMatching":true,"runnersVoidable":false,"numberOfActiveRunners":4,"betDelay":0,"status":"OPEN","runners":[{"status":"ACTIVE","sortPriority":1,"id":531005,"name":"Daniel 2 - 0"},{"status":"ACTIVE","sortPriority":2,"id":531006,"name":"Daniel 2 - 1"},{"status":"ACTIVE","sortPriority":3,"id":8679736,"name":"Hanfmann 2 - 0"},{"status":"ACTIVE","sortPriority":4,"id":8679737,"name":"Hanfmann 2 - 1"}],"regulators":["MR_INT"],"countryCode":"AU","discountAllowed":true,"timezone":"UTC","openDate":"2020-02-02T05:48:00.000Z","version":3148205936,"name":"Set Betting","eventName":"Daniel v Hanfmann"}}]}
{"op":"mcm","clk":"1004183498","pt":1580622413114,"mc":[{"id":"1.168186838","marketDefinition":{"bspMarket":false,"turnInPlayEnabled":true,"persistenceEnabled":true,"marketBaseRate":5.0,"eventId":"29680287","eventTypeId":"2","numberOfWinners":1,"bettingType":"ODDS","marketType":"SET_BETTING","marketTime":"2020-02-02T06:03:00.000Z","suspendTime":"2020-02-02T06:03:00.000Z","bspReconciled":false,"complete":true,"inPlay":false,"crossMatching":true,"runnersVoidable":false,"numberOfActiveRunners":4,"betDelay":0,"status":"OPEN","runners":[{"status":"ACTIVE","sortPriority":1,"id":531005,"name":"Daniel 2 - 0"},{"status":"ACTIVE","sortPriority":2,"id":531006,"name":"Daniel 2 - 1"},{"status":"ACTIVE","sortPriority":3,"id":8679736,"name":"Hanfmann 2 - 0"},{"status":"ACTIVE","sortPriority":4,"id":8679737,"name":"Hanfmann 2 - 1"}],"regulators":["MR_INT"],"countryCode":"AU","discountAllowed":true,"timezone":"UTC","openDate":"2020-02-02T05:48:00.000Z","version":3148212363,"name":"Set Betting","eventName":"Daniel v Hanfmann"}}]}
{"op":"mcm","clk":"1004184031","pt":1580622427229,"mc":[{"id":"1.168186838","rc":[{"batb":[[0,1.03,137],[1,1.02,2],[2,1.01,1.01]],"ltp":0.0,"tv":0.0,"id":531006}]}]}
{"op":"mcm","clk":"1004184068","pt":1580622428106,"mc":[{"id":"1.168186838","rc":[{"batb":[[0,3.65,70.13],[1,1.03,137],[2,1.02,2]],"ltp":0.0,"tv":0.0,"id":531006}]}]}
{"op":"mcm","clk":"1004184590","pt":1580622440175,"mc":[{"id":"1.168186838","marketDefinition":{"bspMarket":false,"turnInPlayEnabled":true,"persistenceEnabled":true,"marketBaseRate":5.0,"eventId":"29680287","eventTypeId":"2","numberOfWinners":1,"bettingType":"ODDS","marketType":"SET_BETTING","marketTime":"2020-02-02T06:03:00.000Z","suspendTime":"2020-02-02T06:03:00.000Z","bspReconciled":false,"complete":true,"inPlay":false,"crossMatching":true,"runnersVoidable":false,"numberOfActiveRunners":4,"betDelay":0,"status":"OPEN","runners":[{"status":"ACTIVE","sortPriority":1,"id":531005,"name":"Daniel 2 - 0"},{"status":"ACTIVE","sortPriority":2,"id":531006,"name":"Daniel 2 - 1"},{"status":"ACTIVE","sortPriority":3,"id":8679736,"name":"Hanfmann 2 - 0"},{"status":"ACTIVE","sortPriority":4,"id":8679737,"name":"Hanfmann 2 - 1"}],"regulators":["MR_INT"],"countryCode":"AU","discountAllowed":true,"timezone":"UTC","openDate":"2020-02-02T06:03:00.000Z","version":3148212363,"name":"Set Betting","eventName":"Daniel v Hanfmann"}}]}
{"op":"mcm","clk":"1004211888","pt":1580623312961,"mc":[{"id":"1.168186838","marketDefinition":{"bspMarket":false,"turnInPlayEnabled":true,"persistenceEnabled":true,"marketBaseRate":5.0,"eventId":"29680287","eventTypeId":"2","numberOfWinners":1,"bettingType":"ODDS","marketType":"SET_BETTING","marketTime":"2020-02-02T06:18:00.000Z","suspendTime":"2020-02-02T06:18:00.000Z","bspReconciled":false,"complete":true,"inPlay":false,"crossMatching":true,"runnersVoidable":false,"numberOfActiveRunners":4,"betDelay":0,"status":"OPEN","runners":[{"status":"ACTIVE","sortPriority":1,"id":531005,"name":"Daniel 2 - 0"},{"status":"ACTIVE","sortPriority":2,"id":531006,"name":"Daniel 2 - 1"},{"status":"ACTIVE","sortPriority":3,"id":8679736,"name":"Hanfmann 2 - 0"},{"status":"ACTIVE","sortPriority":4,"id":8679737,"name":"Hanfmann 2 - 1"}],"regulators":["MR_INT"],"countryCode":"AU","discountAllowed":true,"timezone":"UTC","openDate":"2020-02-02T06:03:00.000Z","version":3148224737,"name":"Set Betting","eventName":"Daniel v Hanfmann"}}]}
{"op":"mcm","clk":"1004211992","pt":1580623315969,"mc":[{"id":"1.168186838","marketDefinition":{"bspMarket":false,"turnInPlayEnabled":true,"persistenceEnabled":true,"marketBaseRate":5.0,"eventId":"29680287","eventTypeId":"2","numberOfWinners":1,"bettingType":"ODDS","marketType":"SET_BETTING","marketTime":"2020-02-02T06:18:00.000Z","suspendTime":"2020-02-02T06:18:00.000Z","bspReconciled":false,"complete":true,"inPlay":false,"crossMatching":true,"runnersVoidable":false,"numberOfActiveRunners":4,"betDelay":0,"status":"OPEN","runners":[{"status":"ACTIVE","sortPriority":1,"id":531005,"name":"Daniel 2 - 0"},{"status":"ACTIVE","sortPriority":2,"id":531006,"name":"Daniel 2 - 1"},{"status":"ACTIVE","sortPriority":3,"id":8679736,"name":"Hanfmann 2 - 0"},{"status":"ACTIVE","sortPriority":4,"id":8679737,"name":"Hanfmann 2 - 1"}],"regulators":["MR_INT"],"countryCode":"AU","discountAllowed":true,"timezone":"UTC","openDate":"2020-02-02T06:18:00.000Z","version":3148224737,"name":"Set Betting","eventName":"Daniel v Hanfmann"}}]}
{"op":"mcm","clk":"1004212442","pt":1580623329109,"mc":[{"id":"1.168186838","rc":[{"batb":[[0,1.03,137],[1,1.02,2],[2,1.01,1.01]],"ltp":0.0,"tv":0.0,"id":531006}]}]}
{"op":"mcm","clk":"1004212476","pt":1580623330035,"mc":[{"id":"1.168186838","rc":[{"batb":[[0,3.8,67.23],[1,1.03,137],[2,1.02,2]],"ltp":0.0,"tv":0.0,"id":531006}]}]}
{"op":"mcm","clk":"1004230019","pt":1580623909722,"mc":[{"id":"1.168186838","rc":[{"batb":[[2,1.8,22.79]],"ltp":0.0,"tv":0.0,"id":8679737}]}]}
{"op":"mcm","clk":"1004232069","pt":1580623980299,"mc":[{"id":"1.168186838","rc":[{"batb":[[1,1.8,22.79],[2,1.03,137]],"ltp":0.0,"tv":0.0,"id":531006}]}]}
{"op":"mcm","clk":"1004239219","pt":1580624212832,"mc":[{"id":"1.168186838","marketDefinition":{"bspMarket":false,"turnInPlayEnabled":true,"persistenceEnabled":true,"marketBaseRate":5.0,"eventId":"29680287","eventTypeId":"2","numberOfWinners":1,"bettingType":"ODDS","marketType":"SET_BETTING","marketTime":"2020-02-02T06:33:00.000Z","suspendTime":"2020-02-02T06:33:00.000Z","bspReconciled":false,"complete":true,"inPlay":false,"crossMatching":true,"runnersVoidable":false,"numberOfActiveRunners":4,"betDelay":0,"status":"OPEN","runners":[{"status":"ACTIVE","sortPriority":1,"id":531005,"name":"Daniel 2 - 0"},{"status":"ACTIVE","sortPriority":2,"id":531006,"name":"Daniel 2 - 1"},{"status":"ACTIVE","sortPriority":3,"id":8679736,"name":"Hanfmann 2 - 0"},{"status":"ACTIVE","sortPriority":4,"id":8679737,"name":"Hanfmann 2 - 1"}],"regulators":["MR_INT"],"countryCode":"AU","discountAllowed":true,"timezone":"UTC","openDate":"2020-02-02T06:18:00.000Z","version":3148240052,"name":"Set Betting","eventName":"Daniel v Hanfmann"}}]}
{"op":"mcm","clk":"1004239304","pt":1580624215838,"mc":[{"id":"1.168186838","marketDefinition":{"bspMarket":false,"turnInPlayEnabled":true,"persistenceEnabled":true,"marketBaseRate":5.0,"eventId":"29680287","eventTypeId":"2","numberOfWinners":1,"bettingType":"ODDS","marketType":"SET_BETTING","marketTime":"2020-02-02T06:33:00.000Z","suspendTime":"2020-02-02T06:33:00.000Z","bspReconciled":false,"complete":true,"inPlay":false,"crossMatching":true,"runnersVoidable":false,"numberOfActiveRunners":4,"betDelay":0,"status":"OPEN","runners":[{"status":"ACTIVE","sortPriority":1,"id":531005,"name":"Daniel 2 - 0"},{"status":"ACTIVE","sortPriority":2,"id":531006,"name":"Daniel 2 - 1"},{"status":"ACTIVE","sortPriority":3,"id":8679736,"name":"Hanfmann 2 - 0"},{"status":"ACTIVE","sortPriority":4,"id":8679737,"name":"Hanfmann 2 - 1"}],"regulators":["MR_INT"],"countryCode":"AU","discountAllowed":true,"timezone":"UTC","openDate":"2020-02-02T06:33:00.000Z","version":3148240052,"name":"Set Betting","eventName":"Daniel v Hanfmann"}}]}
{"op":"mcm","clk":"1004239692","pt":1580624230043,"mc":[{"id":"1.168186838","rc":[{"batb":[[0,4.1,62.34]],"ltp":0.0,"tv":0.0,"id":531006}]}]}
{"op":"mcm","clk":"1004248513","pt":1580624485508,"mc":[{"id":"1.168186838","rc":[{"batb":[[0,2.9,2.02]],"ltp":0.0,"tv":0.0,"id":8679736},{"batb":[[0,4.2,2.02],[1,1.8,22.79],[2,1.02,2]],"ltp":0.0,"tv":0.0,"id":8679737},{"batb":[[2,1.02,2]],"ltp":0.0,"tv":0.0,"id":531006},{"batb":[[0,3.25,2.02],[1,3.15,2.02],[2,1.02,2]],"ltp":0.0,"tv":0.0,"id":531005}]}]}
{"op":"mcm","clk":"1004248537","pt":1580624486433,"mc":[{"id":"1.168186838","rc":[{"batl":[[0,5.1,10.13]],"ltp":0.0,"tv":0.0,"id":8679737},{"batl":[[1,5.6,0]],"ltp":0.0,"tv":0.0,"id":531006}]}]}
{"op":"mcm","clk":"1004248621","pt":1580624489822,"mc":[{"id":"1.168186838","rc":[{"batb":[[2,2.82,6]],"ltp":0.0,"tv":0.0,"id":8679736},{"batb":[[0,4.3,5],[1,4.2,2.02],[2,1.8,22.79]],"ltp":0.0,"tv":0.0,"id":8679737},{"batb":[[0,4.2,5],[1,4.1,62.34],[2,1.8,22.79]],"ltp":0.0,"tv":0.0,"id":531006},{"batb":[[0,3.3,5],[1,3.25,2.02],[2,3.15,2.02]],"ltp":0.0,"tv":0.0,"id":531005}]}]}
{"op":"mcm","clk":"1004250474","pt":1580624551318,"mc":[{"id":"1.168186838","rc":[{"batl":[[0,3.1,5]],"ltp":0.0,"tv":0.0,"id":8679736},{"batl":[[1,5.2,4]],"ltp":0.0,"tv":0.0,"id":8679737},{"batb":[[0,4.3,59.38],[1,4.2,5]],"batl":[[1,5.7,4]],"ltp":0.0,"tv":0.0,"id":531006},{"batl":[[0,3.9,5]],"ltp":0.0,"tv":0.0,"id":531005}]}]}
{"op":"mcm","clk":"1004253920","pt":1580624662255,"mc":[{"id":"1.168186838","rc":[{"trd":[[3.1,3.6]],"batl":[[0,3.1,1.4]],"ltp":3.1,"tv":3.6,"id":8679736},{"trd":[[4.4,2.53]],"ltp":4.4,"tv":2.53,"id":8679737},{"trd":[[5.1,2.18]],"batl":[[0,5.1,7.95]],"ltp":5.1,"tv":2.18,"id":531006},{"trd":[[3.9,2.86]],"batl":[[0,3.9,2.14]],"ltp":3.9,"tv":2.86,"id":531005}],"tv":11.17}]}
{"op":"mcm","clk":"1004261569","pt":1580624913658,"mc":[{"id":"1.168186838","rc":[{"batl":[[1,5.7,0]],"ltp":5.1,"tv":2.18,"id":531006}]}]}
{"op":"mcm","clk":"1004261580","pt":1580624914323,"mc":[{"id":"1.168186838","rc":[{"batl":[[0,3.15,5]],"ltp":3.1,"tv":3.6,"id":8679736},{"batl":[[0,5.1,14.13],[1,5.2,0]],"ltp":4.4,"tv":2.53,"id":8679737},{"batl":[[1,5.6,4]],"ltp":5.1,"tv":2.18,"id":531006},{"batl":[[0,3.8,5]],"ltp":3.9,"tv":2.86,"id":531005}]}]}
{"op":"mcm","clk":"1004262775","pt":1580624966913,"mc":[{"id":"1.168186838","rc":[{"batb":[[0,4.2,5],[1,1.8,22.79],[2,1.02,2]],"ltp":5.1,"tv":2.18,"id":531006}]}]}
{"op":"mcm","clk":"1004267027","pt":1580625113633,"mc":[{"id":"1.168186838","marketDefinition":{"bspMarket":false,"turnInPlayEnabled":true,"persistenceEnabled":true,"marketBaseRate":5.0,"eventId":"29680287","eventTypeId":"2","numberOfWinners":1,"bettingType":"ODDS","marketType":"SET_BETTING","marketTime":"2020-02-02T06:48:00.000Z","suspendTime":"2020-02-02T06:48:00.000Z","bspReconciled":false,"complete":true,"inPlay":false,"crossMatching":true,"runnersVoidable":false,"numberOfActiveRunners":4,"betDelay":0,"status":"OPEN","runners":[{"status":"ACTIVE","sortPriority":1,"id":531005,"name":"Daniel 2 - 0"},{"status":"ACTIVE","sortPriority":2,"id":531006,"name":"Daniel 2 - 1"},{"status":"ACTIVE","sortPriority":3,"id":8679736,"name":"Hanfmann 2 - 0"},{"status":"ACTIVE","sortPriority":4,"id":8679737,"name":"Hanfmann 2 - 1"}],"regulators":["MR_INT"],"countryCode":"AU","discountAllowed":true,"timezone":"UTC","openDate":"2020-02-02T06:33:00.000Z","version":3148248254,"name":"Set Betting","eventName":"Daniel v Hanfmann"}}]}
{"op":"mcm","clk":"1004267120","pt":1580625115637,"mc":[{"id":"1.168186838","marketDefinition":{"bspMarket":false,"turnInPlayEnabled":true,"persistenceEnabled":true,"marketBaseRate":5.0,"eventId":"29680287","eventTypeId":"2","numberOfWinners":1,"bettingType":"ODDS","marketType":"SET_BETTING","marketTime":"2020-02-02T06:48:00.000Z","suspendTime":"2020-02-02T06:48:00.000Z","bspReconciled":false,"complete":true,"inPlay":false,"crossMatching":true,"runnersVoidable":false,"numberOfActiveRunners":4,"betDelay":0,"status":"OPEN","runners":[{"status":"ACTIVE","sortPriority":1,"id":531005,"name":"Daniel 2 - 0"},{"status":"ACTIVE","sortPriority":2,"id":531006,"name":"Daniel 2 - 1"},{"status":"ACTIVE","sortPriority":3,"id":8679736,"name":"Hanfmann 2 - 0"},{"status":"ACTIVE","sortPriority":4,"id":8679737,"name":"Hanfmann 2 - 1"}],"regulators":["MR_INT"],"countryCode":"AU","discountAllowed":true,"timezone":"UTC","openDate":"2020-02-02T06:48:00.000Z","version":3148248254,"name":"Set Betting","eventName":"Daniel v Hanfmann"}}]}
{"op":"mcm","clk":"1004280009","pt":1580625538410,"mc":[{"id":"1.168186838","rc":[{"batb":[[0,2.96,49.41],[1,2.9,2.02],[2,2.88,2.02]],"batl":[[1,3.25,47.45]],"ltp":3.1,"tv":3.6,"id":8679736},{"batb":[[0,4.3,44.03]],"batl":[[0,4.9,37.14],[1,5.1,14.13]],"ltp":4.4,"tv":2.53,"id":8679737},{"batb":[[0,4.8,30.69],[1,4.2,5],[2,1.8,22.79]],"batl":[[1,5.5,29.35],[2,5.6,4]],"ltp":5.1,"tv":2.18,"id":531006},{"batb":[[0,3.55,30.76],[1,3.3,5],[2,3.25,2.02]],"batl":[[1,4,29.82]],"ltp":3.9,"tv":2.86,"id":531005}]}]}
{"op":"mcm","clk":"1004280815","pt":1580625558658,"mc":[{"id":"1.168186838","rc":[{"batb":[[0,2.96,49.25]],"batl":[[1,3.25,47.29]],"ltp":3.1,"tv":3.6,"id":8679736}]}]}
{"op":"mcm","clk":"1004286954","pt":1580625713660,"mc":[{"id":"1.168186838","marketDefinition":{"bspMarket":false,"turnInPlayEnabled":true,"persistenceEnabled":true,"marketBaseRate":5.0,"eventId":"29680287","eventTypeId":"2","numberOfWinners":1,"bettingType":"ODDS","marketType":"SET_BETTING","marketTime":"2020-02-02T06:37:00.000Z","suspendTime":"2020-02-02T06:37:00.000Z","bspReconciled":false,"complete":true,"inPlay":false,"crossMatching":true,"runnersVoidable":false,"numberOfActiveRunners":4,"betDelay":0,"status":"OPEN","runners":[{"status":"ACTIVE","sortPriority":1,"id":531005,"name":"Daniel 2 - 0"},{"status":"ACTIVE","sortPriority":2,"id":531006,"name":"Daniel 2 - 1"},{"status":"ACTIVE","sortPriority":3,"id":8679736,"name":"Hanfmann 2 - 0"},{"status":"ACTIVE","sortPriority":4,"id":8679737,"name":"Hanfmann 2 - 1"}],"regulators":["MR_INT"],"countryCode":"AU","discountAllowed":true,"timezone":"UTC","openDate":"2020-02-02T06:48:00.000Z","version":3148253843,"name":"Set Betting","eventName":"Daniel v Hanfmann"}}]}
{"op":"mcm","clk":"1004287082","pt":1580625716763,"mc":[{"id":"1.168186838","marketDefinition":{"bspMarket":false,"turnInPlayEnabled":true,"persistenceEnabled":true,"marketBaseRate":5.0,"eventId":"29680287","eventTypeId":"2","numberOfWinners":1,"bettingType":"ODDS","marketType":"SET_BETTING","marketTime":"2020-02-02T06:37:00.000Z","suspendTime":"2020-02-02T06:37:00.000Z","bspReconciled":false,"complete":true,"inPlay":false,"crossMatching":true,"runnersVoidable":false,"numberOfActiveRunners":4,"betDelay":0,"status":"OPEN","runners":[{"status":"ACTIVE","sortPriority":1,"id":531005,"name":"Daniel 2 - 0"},{"status":"ACTIVE","sortPriority":2,"id":531006,"name":"Daniel 2 - 1"},{"status":"ACTIVE","sortPriority":3,"id":8679736,"name":"Hanfmann 2 - 0"},{"status":"ACTIVE","sortPriority":4,"id":8679737,"name":"Hanfmann 2 - 1"}],"regulators":["MR_INT"],"countryCode":"AU","discountAllowed":true,"timezone":"UTC","openDate":"2020-02-02T06:37:00.000Z","version":3148253843,"name":"Set Betting","eventName":"Daniel v Hanfmann"}}]}
{"op":"mcm","clk":"1004295533","pt":1580626084688,"mc":[{"id":"1.168186838","marketDefinition":{"bspMarket":false,"turnInPlayEnabled":true,"persistenceEnabled":true,"marketBaseRate":5.0,"eventId":"29680287","eventTypeId":"2","numberOfWinners":1,"bettingType":"ODDS","marketType":"SET_BETTING","marketTime":"2020-02-02T06:37:00.000Z","suspendTime":"2020-02-02T06:37:00.000Z","bspReconciled":false,"complete":true,"inPlay":true,"crossMatching":true,"runnersVoidable":false,"numberOfActiveRunners":4,"betDelay":3,"status":"OPEN","runners":[{"status":"ACTIVE","sortPriority":1,"id":531005,"name":"Daniel 2 - 0"},{"status":"ACTIVE","sortPriority":2,"id":531006,"name":"Daniel 2 - 1"},{"status":"ACTIVE","sortPriority":3,"id":8679736,"name":"Hanfmann 2 - 0"},{"status":"ACTIVE","sortPriority":4,"id":8679737,"name":"Hanfmann 2 - 1"}],"regulators":["MR_INT"],"countryCode":"AU","discountAllowed":true,"timezone":"UTC","openDate":"2020-02-02T06:37:00.000Z","version":3148255326,"name":"Set Betting","eventName":"Daniel v Hanfmann"},"rc":[{"batb":[[0,1.01,1.41],[1,2.9,0],[2,2.88,0]],"ltp":3.1,"tv":3.6,"id":8679736},{"batb":[[0,1.8,22.79],[1,1.01,0.51],[2,1.8,0]],"batl":[[0,5.1,10.13],[1,5.1,0]],"ltp":4.4,"tv":2.53,"id":8679737},{"batb":[[0,1.8,22.79],[1,1.01,0.51],[2,1.8,0]],"batl":[[1,5.5,0],[2,5.6,0]],"ltp":5.1,"tv":2.18,"id":531006},{"batb":[[0,1.01,1.41],[1,3.3,0],[2,3.25,0]],"ltp":3.9,"tv":2.86,"id":531005}]}]}
{"op":"mcm","clk":"1004296060","pt":1580626109100,"mc":[{"id":"1.168186838","rc":[{"batb":[[0,2.74,114.6],[1,2.7,114.38],[2,1.01,1.41]],"ltp":3.1,"tv":3.6,"id":8679736},{"batb":[[0,4.4,69.46],[1,4.3,90.53],[2,1.8,22.79]],"ltp":4.4,"tv":2.53,"id":8679737},{"batb":[[0,4.9,51.05],[1,4.8,70.62],[2,1.8,22.79]],"ltp":5.1,"tv":2.18,"id":531006},{"batb":[[0,3.4,128.29],[1,3.35,82.45],[2,1.01,1.41]],"ltp":3.9,"tv":2.86,"id":531005}]}]}
{"op":"mcm","clk":"1004296187","pt":1580626115286,"mc":[{"id":"1.168186838","rc":[{"batb":[[0,1.01,1.41],[1,2.7,0],[2,1.01,0]],"ltp":3.1,"tv":3.6,"id":8679736}]}]}
{"op":"mcm","clk":"1004296272","pt":1580626118669,"mc":[{"id":"1.168186838","rc":[{"batb":[[0,3.2,103.32],[1,3.15,96.26],[2,1.01,1.41]],"ltp":3.1,"tv":3.6,"id":8679736}]}]}
{"op":"mcm","clk":"1004296289","pt":1580626119281,"mc":[{"id":"1.168186838","rc":[{"batb":[[2,3.1,43.2]],"batl":[[0,3.45,41.62],[1,3.6,37.22]],"ltp":3.1,"tv":3.6,"id":8679736},{"batb":[[1,4.3,130.19]],"batl":[[0,5,36.9],[1,5.1,10.13]],"ltp":4.4,"tv":2.53,"id":8679737},{"batb":[[2,4.7,31.39]],"batl":[[1,5.5,29.43]],"ltp":5.1,"tv":2.18,"id":531006},{"batb":[[1,3.35,117.7],[2,3.25,38.87]],"batl":[[0,3.75,34.07],[1,4.2,27.3]],"ltp":3.9,"tv":2.86,"id":531005}]}]}
{"op":"mcm","clk":"1004296563","pt":1580626129620,"mc":[{"id":"1.168186838","rc":[{"batb":[[0,3.1,43.2],[1,2.88,21.32],[2,1.01,1.41]],"ltp":3.1,"tv":3.6,"id":8679736},{"batb":[[0,3.35,35.25],[1,3.25,38.87],[2,1.01,1.41]],"ltp":3.9,"tv":2.86,"id":531005}]}]}
{"op":"mcm","clk":"1004296590","pt":1580626130693,"mc":[{"id":"1.168186838","rc":[{"batb":[[0,2.88,21.32],[1,1.01,1.41],[2,1.01,0]],"batl":[[0,3.6,37.22],[1,3.6,0]],"ltp":3.1,"tv":3.6,"id":8679736},{"batb":[[0,3.25,38.87],[1,1.01,1.41],[2,1.01,0]],"batl":[[0,4.2,27.3],[1,4.2,0]],"ltp":3.9,"tv":2.86,"id":531005}]}]}
{"op":"mcm","clk":"1004296633","pt":1580626132638,"mc":[{"id":"1.168186838","rc":[{"batb":[[0,2.96,75.78],[1,2.92,93.72],[2,2.88,21.32]],"ltp":3.1,"tv":3.6,"id":8679736},{"batb":[[0,3.25,162.69],[1,3.2,92.36],[2,1.01,1.41]],"ltp":3.9,"tv":2.86,"id":531005}]}]}
{"op":"mcm","clk":"1004296985","pt":1580626146648,"mc":[{"id":"1.168186838","rc":[{"batb":[[0,2.88,21.32],[1,1.01,1.41],[2,2.88,0]],"ltp":3.1,"tv":3.6,"id":8679736}]}]}
{"op":"mcm","clk":"1004297068","pt":1580626149618,"mc":[{"id":"1.168186838","rc":[{"batb":[[0,3.35,124.9],[1,3.3,85.6],[2,2.88,21.32]],"ltp":3.1,"tv":3.6,"id":8679736}]}]}
{"op":"mcm","clk":"1004297097","pt":1580626150543,"mc":[{"id":"1.168186838","rc":[{"batb":[[2,3.25,38.55]],"batl":[[1,3.75,34.78]],"ltp":3.1,"tv":3.6,"id":8679736},{"batb":[[1,4.3,90.53],[2,4.2,40.13]],"batl":[[0,4.9,37.14]],"ltp":4.4,"tv":2.53,"id":8679737},{"batb":[[2,3.15,41.86]],"batl":[[0,3.6,37.53],[1,3.85,31.79]],"ltp":3.9,"tv":2.86,"id":531005}]}]}
{"op":"mcm","clk":"1004297311","pt":1580626158928,"mc":[{"id":"1.168186838","rc":[{"batb":[[0,4.8,70.62],[1,4.7,31.39],[2,1.8,22.79]],"ltp":5.1,"tv":2.18,"id":531006}]}]}
{"op":"mcm","clk":"1004297413","pt":1580626162671,"mc":[{"id":"1.168186838","rc":[{"batb":[[0,4.8,111.3],[1,4.7,104.45]],"ltp":5.1,"tv":2.18,"id":531006}]}]}
{"op":"mcm","clk":"1004297492","pt":1580626166357,"mc":[{"id":"1.168186838","rc":[{"batb":[[0,3.35,83.26],[1,3.25,38.55],[2,3.05,46.11]],"ltp":3.1,"tv":3.6,"id":8679736},{"batb":[[0,4.8,86.21]],"ltp":5.1,"tv":2.18,"id":531006},{"batb":[[0,3.25,116.61]],"ltp":3.9,"tv":2.86,"id":531005}]}]}
{"op":"mcm","clk":"1004297511","pt":1580626167587,"mc":[{"id":"1.168186838","rc":[{"batb":[[0,3.05,46.11],[1,1.01,1.41],[2,3.05,0]],"batl":[[0,3.75,34.78],[1,3.75,0]],"ltp":3.1,"tv":3.6,"id":8679736},{"batb":[[0,3.15,41.86],[1,1.01,1.41],[2,3.15,0]],"batl":[[0,3.85,31.79],[1,3.85,0]],"ltp":3.9,"tv":2.86,"id":531005}]}]}
{"op":"mcm","clk":"1004297535","pt":1580626168667,"mc":[{"id":"1.168186838","rc":[{"batb":[[0,3.4,83.83],[1,3.05,46.11],[2,1.01,1.41]],"ltp":3.1,"tv":3.6,"id":8679736},{"batb":[[0,4.4,86.65]],"ltp":4.4,"tv":2.53,"id":8679737}]}]}
{"op":"mcm","clk":"1004297541","pt":1580626168975,"mc":[{"id":"1.168186838","rc":[{"batb":[[0,3.05,46.11],[1,1.01,1.41],[2,1.01,0]],"ltp":3.1,"tv":3.6,"id":8679736}]}]}
{"op":"mcm","clk":"1004297612","pt":1580626170670,"mc":[{"id":"1.168186838","rc":[{"batb":[[0,3.2,76.62],[1,3.15,96.96],[2,3.05,45.08]],"batl":[[0,3.75,33.99]],"ltp":3.1,"tv":3.6,"id":8679736},{"batb":[[1,4.3,129.79],[2,1.8,22.79]],"batl":[[0,5,36.35]],"ltp":4.4,"tv":2.53,"id":8679737},{"batl":[[1,5.4,30.29]],"ltp":5.1,"tv":2.18,"id":531006},{"batb":[[0,3.15,78.42],[1,3.1,142.82],[2,1.01,1.41]],"ltp":3.9,"tv":2.86,"id":531005}]}]}
{"op":"mcm","clk":"1004298405","pt":1580626195611,"mc":[{"id":"1.168186838","rc":[{"batb":[[0,3.1,42.88],[1,1.01,1.41],[2,1.01,0]],"ltp":3.9,"tv":2.86,"id":531005}]}]}
{"op":"mcm","clk":"1004298517","pt":1580626198685,"mc":[{"id":"1.168186838","rc":[{"batb":[[0,4.8,101.34]],"ltp":5.1,"tv":2.18,"id":531006},{"batb":[[0,3.45,71.42],[1,3.4,79.63],[2,3.1,42.88]],"ltp":3.9,"tv":2.86,"id":531005}]}]}
{"op":"mcm","clk":"1004298549","pt":1580626199604,"mc":[{"id":"1.168186838","rc":[{"batl":[[0,3.4,43.35],[1,3.6,38]],"ltp":3.1,"tv":3.6,"id":8679736},{"batl":[[0,5,36.04]],"ltp":4.4,"tv":2.53,"id":8679737},{"batl":[[1,5.4,30.06]],"ltp":5.1,"tv":2.18,"id":531006},{"batb":[[0,3.45,105.1],[2,3.3,37.69]],"batl":[[1,4.3,49.41]],"ltp":3.9,"tv":2.86,"id":531005}]}]}
{"op":"mcm","clk":"1004299292","pt":1580626219649,"mc":[{"id":"1.168186838","rc":[{"batb":[[0,2.8,22.66],[1,1.01,1.41],[2,3.05,0]],"batl":[[0,3.6,38],[1,3.6,0]],"ltp":3.1,"tv":3.6,"id":8679736},{"batb":[[0,3.3,37.69],[1,1.01,1.41],[2,3.3,0]],"batl":[[0,4.3,49.41],[1,4.3,0]],"ltp":3.9,"tv":2.86,"id":531005}]}]}
{"op":"mcm","clk":"1004299378","pt":1580626222667,"mc":[{"id":"1.168186838","rc":[{"batb":[[0,2.9,98.34],[1,2.86,99.09],[2,2.82,22.35]],"ltp":3.1,"tv":3.6,"id":8679736},{"batb":[[2,4.6,32.73]],"ltp":5.1,"tv":2.18,"id":531006},{"batb":[[1,3.25,138.71],[2,3.2,92.16]],"ltp":3.9,"tv":2.86,"id":531005}]}]}
{"op":"mcm","clk":"1004299387","pt":1580626222872,"mc":[{"id":"1.168186838","rc":[{"batl":[[0,3.6,37.37]],"ltp":3.1,"tv":3.6,"id":8679736},{"batb":[[1,4.3,129.16]],"batl":[[0,5,35.49]],"ltp":4.4,"tv":2.53,"id":8679737},{"batb":[[1,4.7,73.06]],"ltp":5.1,"tv":2.18,"id":531006},{"batb":[[0,3.25,138.71],[1,3.2,92.16],[2,1.01,1.41]],"ltp":3.9,"tv":2.86,"id":531005}]}]}
{"op":"mcm","clk":"1004299616","pt":1580626230351,"mc":[{"id":"1.168186838","rc":[{"batb":[[0,4.8,70.62],[1,4.6,32.73],[2,1.8,22.79]],"ltp":5.1,"tv":2.18,"id":531006},{"batb":[[0,3.25,38.4],[1,1.01,1.41],[2,1.01,0]],"ltp":3.9,"tv":2.86,"id":531005}]}]}
{"op":"mcm","clk":"1004299720","pt":1580626233538,"mc":[{"id":"1.168186838","rc":[{"batb":[[0,4.4,125.8]],"ltp":4.4,"tv":2.53,"id":8679737},{"batb":[[0,4.9,43.78],[1,4.8,70.62],[2,4.6,32.73]],"ltp":5.1,"tv":2.18,"id":531006},{"batb":[[0,3.8,107.31],[1,3.75,62.55],[2,3.25,38.4]],"ltp":3.9,"tv":2.86,"id":531005}]}]}
{"op":"mcm","clk":"1004299741","pt":1580626234256,"mc":[{"id":"1.168186838","rc":[{"batl":[[0,3.1,21.95],[1,3.35,44.61]],"ltp":3.1,"tv":3.6,"id":8679736},{"batb":[[0,4.4,163.02],[1,4.3,128.61]],"batl":[[0,5.1,10.13],[1,5.2,33.75]],"ltp":4.4,"tv":2.53,"id":8679737},{"batb":[[2,4.7,32.18]],"ltp":5.1,"tv":2.18,"id":531006},{"batb":[[0,3.8,133.98],[2,3.5,32.81]],"batl":[[1,5.5,29.11]],"ltp":3.9,"tv":2.86,"id":531005}]}]}
{"op":"mcm","clk":"1004300076","pt":1580626243573,"mc":[{"id":"1.168186838","rc":[{"trd":[[3.8,156.69]],"batb":[[0,3.8,55.64]],"ltp":3.8,"tv":159.54,"id":531005}],"tv":167.86}]}
{"op":"mcm","clk":"1004300160","pt":1580626246457,"mc":[{"id":"1.168186838","rc":[{"batb":[[0,3.8,118.87]],"ltp":3.8,"tv":159.54,"id":531005}]}]}
{"op":"mcm","clk":"1004300412","pt":1580626253680,"mc":[{"id":"1.168186838","rc":[{"batb":[[0,2.42,33.91],[1,1.01,1.41],[2,2.82,0]],"batl":[[0,3.35,44.61],[1,3.35,0]],"ltp":3.1,"tv":3.6,"id":8679736},{"batb":[[0,4.4,86.65]],"ltp":4.4,"tv":2.53,"id":8679737},{"batb":[[0,3.5,32.81],[1,1.01,1.41],[2,3.5,0]],"batl":[[0,5.5,29.11],[1,5.5,0]],"ltp":3.8,"tv":159.54,"id":531005}]}]}
{"op":"mcm","clk":"1004300507","pt":1580626256303,"mc":[{"id":"1.168186838","rc":[{"batb":[[0,2.5,147.24],[1,2.46,147.02],[2,2.4,34.07]],"ltp":3.1,"tv":3.6,"id":8679736},{"batl":[[0,5.1,44.04],[1,5.2,0]],"ltp":4.4,"tv":2.53,"id":8679737},{"batb":[[2,4.7,32.02]],"ltp":5.1,"tv":2.18,"id":531006},{"batb":[[0,3.5,32.57],[1,3.4,136.86],[2,3.35,81.8]],"batl":[[0,5.5,28.88]],"ltp":3.8,"tv":159.54,"id":531005}]}]}
{"op":"mcm","clk":"1004301202","pt":1580626281138,"mc":[{"id":"1.168186838","rc":[{"batb":[[0,2.4,34.07],[1,1.01,1.41],[2,2.4,0]],"ltp":3.1,"tv":3.6,"id":8679736},{"batb":[[1,1.01,1.41],[2,3.35,0]],"ltp":3.8,"tv":159.54,"id":531005}]}]}
{"op":"mcm","clk":"1004301313","pt":1580626284625,"mc":[{"id":"1.168186838","rc":[{"batb":[[0,3.2,86.49],[1,3.15,96.93],[2,3,46.58]],"batl":[[1,3.55,39.42]],"ltp":3.1,"tv":3.6,"id":8679736},{"batl":[[0,5,35.96],[1,5.1,44.04]],"ltp":4.4,"tv":2.53,"id":8679737},{"batl":[[2,5.5,29.51]],"ltp":5.1,"tv":2.18,"id":531006},{"batb":[[1,3.4,136.86],[2,3.35,81.8]],"batl":[[0,3.9,31.55],[1,4.4,47.13],[2,5.5,28.88]],"ltp":3.8,"tv":159.54,"id":531005}]}]}
{"op":"mcm","clk":"1004301342","pt":1580626285648,"mc":[{"id":"1.168186838","rc":[{"batl":[[1,5.1,10.13]],"ltp":4.4,"tv":2.53,"id":8679737},{"batb":[[2,4.7,31.63]],"batl":[[1,5.5,29.51],[2,5.5,0]],"ltp":5.1,"tv":2.18,"id":531006},{"batl":[[2,5.5,0]],"ltp":3.8,"tv":159.54,"id":531005}]}]}
{"op":"mcm","clk":"1004301777","pt":1580626301665,"mc":[{"id":"1.168186838","rc":[{"batb":[[0,3,46.58],[1,2.76,23.84],[2,1.01,1.41]],"ltp":3.1,"tv":3.6,"id":8679736},{"batb":[[0,4.4,69.46]],"ltp":4.4,"tv":2.53,"id":8679737},{"batb":[[0,4.8,70.62],[1,4.7,31.63],[2,1.8,22.79]],"ltp":5.1,"tv":2.18,"id":531006},{"batb":[[1,3.3,37.22],[2,1.01,1.41]],"ltp":3.8,"tv":159.54,"id":531005}]}]}
{"op":"mcm","clk":"1004301781","pt":1580626301766,"mc":[{"id":"1.168186838","rc":[{"batb":[[0,2.76,23.84],[1,1.01,1.41],[2,1.01,0]],"batl":[[0,3.55,39.42],[1,3.55,0]],"ltp":3.1,"tv":3.6,"id":8679736},{"batb":[[0,3.3,37.22],[1,1.01,1.41],[2,1.01,0]],"batl":[[0,4.4,47.13],[1,4.4,0]],"ltp":3.8,"tv":159.54,"id":531005}]}]}
{"op":"mcm","clk":"1004301860","pt":1580626304586,"mc":[{"id":"1.168186838","rc":[{"batb":[[0,2.88,78.48],[1,2.84,101.08],[2,2.76,23.84]],"ltp":3.1,"tv":3.6,"id":8679736},{"batb":[[0,4.8,105.27],[1,4.7,104.44]],"ltp":5.1,"tv":2.18,"id":531006},{"batb":[[1,3.2,138.92],[2,3.15,95.29]],"ltp":3.8,"tv":159.54,"id":531005}]}]}
{"op":"mcm","clk":"1004301882","pt":1580626305461,"mc":[{"id":"1.168186838","rc":[{"batb":[[0,2.76,23.84],[1,1.01,1.41],[2,2.76,0]],"ltp":3.1,"tv":3.6,"id":8679736},{"batb":[[0,4.8,70.62],[1,4.7,31.63]],"ltp":5.1,"tv":2.18,"id":531006},{"batb":[[1,1.01,1.41],[2,3.15,0]],"ltp":3.8,"tv":159.54,"id":531005}]}]}
{"op":"mcm","clk":"1004301985","pt":1580626308588,"mc":[{"id":"1.168186838","rc":[{"batb":[[0,3.1,147.72],[1,3.05,104.5],[2,2.76,23.84]],"ltp":3.1,"tv":3.6,"id":8679736},{"batb":[[0,4.4,93.98]],"ltp":4.4,"tv":2.53,"id":8679737},{"batb":[[0,4.9,45.43],[1,4.8,70.62],[2,4.7,31.63]],"ltp":5.1,"tv":2.18,"id":531006},{"batb":[[0,3.5,98.01],[1,3.45,76.45],[2,3.3,37.22]],"ltp":3.8,"tv":159.54,"id":531005}]}]}
{"op":"mcm","clk":"1004302099","pt":1580626312182,"mc":[{"id":"1.168186838","rc":[{"batb":[[0,2.76,23.84],[1,1.01,1.41],[2,2.76,0]],"ltp":3.1,"tv":3.6,"id":8679736},{"batb":[[0,4.4,69.46]],"ltp":4.4,"tv":2.53,"id":8679737},{"batb":[[0,4.8,70.62],[1,4.7,31.63],[2,1.8,22.79]],"ltp":5.1,"tv":2.18,"id":531006},{"batb":[[0,3.3,37.22],[1,1.01,1.41],[2,3.3,0]],"ltp":3.8,"tv":159.54,"id":531005}]}]}
{"op":"mcm","clk":"1004302252","pt":1580626316397,"mc":[{"id":"1.168186838","rc":[{"batb":[[0,2.88,84.02],[1,2.84,101.09],[2,2.76,23.84]],"ltp":3.1,"tv":3.6,"id":8679736},{"batb":[[0,4.8,102.23],[1,4.7,104.44]],"ltp":5.1,"tv":2.18,"id":531006},{"batb":[[1,3.2,133.67],[2,3.15,95.29]],"ltp":3.8,"tv":159.54,"id":531005}]}]}
{"op":"mcm","clk":"1004302338","pt":1580626318398,"mc":[{"id":"1.168186838","rc":[{"batb":[[0,2.76,23.84],[1,1.01,1.41],[2,2.76,0]],"ltp":3.1,"tv":3.6,"id":8679736}]}]}
{"op":"mcm","clk":"1004302451","pt":1580626321692,"mc":[{"id":"1.168186838","rc":[{"batb":[[0,3.4,127.47],[1,3.35,82.96],[2,3.2,40.84]],"batl":[[1,4,29.27]],"ltp":3.1,"tv":3.6,"id":8679736},{"batl":[[1,5.4,30.21]],"ltp":5.1,"tv":2.18,"id":531006},{"batl":[[0,3.65,35.96],[1,3.85,31.79]],"ltp":3.8,"tv":159.54,"id":531005}]}]}
{"op":"mcm","clk":"1004302720","pt":1580626329591,"mc":[{"id":"1.168186838","rc":[{"batl":[[2,4.1,28.88]],"ltp":3.1,"tv":3.6,"id":8679736}]}]}
{"op":"mcm","clk":"1004302750","pt":1580626330612,"mc":[{"id":"1.168186838","rc":[{"batb":[[2,3.2,40.29]],"batl":[[0,3.55,38.87],[1,4.1,28.88],[2,4.1,0]],"ltp":3.1,"tv":3.6,"id":8679736}]}]}
{"op":"mcm","clk":"1004303712","pt":1580626358250,"mc":[{"id":"1.168186838","rc":[{"batb":[[0,3.2,40.29],[1,3.05,45.64],[2,1.01,1.41]],"ltp":3.1,"tv":3.6,"id":8679736},{"batb":[[0,4.3,128.61],[1,1.8,22.79],[2,1.01,0.51]],"ltp":4.4,"tv":2.53,"id":8679737},{"batb":[[1,2.98,48.39],[2,1.01,1.41]],"ltp":3.8,"tv":159.54,"id":531005}]}]}
{"op":"mcm","clk":"1004303850","pt":1580626361643,"mc":[{"id":"1.168186838","rc":[{"batb":[[0,3.2,160.25],[1,3.15,96.65],[2,3.05,45.64]],"ltp":3.1,"tv":3.6,"id":8679736},{"batb":[[0,4.3,168.37],[1,4.2,95.26],[2,1.8,22.79]],"ltp":4.4,"tv":2.53,"id":8679737},{"batb":[[2,2.92,104.31]],"ltp":3.8,"tv":159.54,"id":531005}]}]}
{"op":"mcm","clk":"1004304572","pt":1580626379676,"mc":[{"id":"1.168186838","rc":[{"batb":[[0,3.2,119.96]],"batl":[[0,4.1,28.88],[1,4.1,0]],"ltp":3.1,"tv":3.6,"id":8679736},{"batb":[[0,2.98,48.39],[1,2.92,104.31],[2,2.88,96.25]],"batl":[[0,3.85,31.79],[1,3.85,0]],"ltp":3.8,"tv":159.54,"id":531005}]}]}
{"op":"mcm","clk":"1004304742","pt":1580626384615,"mc":[{"id":"1.168186838","rc":[{"batb":[[0,4.3,129.13],[1,1.8,22.79],[2,1.01,0.51]],"ltp":4.4,"tv":2.53,"id":8679737},{"batb":[[1,1.01,1.41],[2,2.88,0]],"ltp":3.8,"tv":159.54,"id":531005}]}]}
{"op":"mcm","clk":"1004304838","pt":1580626387297,"mc":[{"id":"1.168186838","rc":[{"batb":[[0,4.4,78.79],[1,4.3,129.13],[2,1.8,22.79]],"ltp":4.4,"tv":2.53,"id":8679737},{"batb":[[0,3.4,121.29],[1,3.35,81.92],[2,2.98,48.39]],"ltp":3.8,"tv":159.54,"id":531005}]}]}
{"op":"mcm","clk":"1004304876","pt":1580626388322,"mc":[{"id":"1.168186838","rc":[{"batl":[[0,3.4,43.83],[1,3.75,34.7]],"ltp":3.1,"tv":3.6,"id":8679736},{"batb":[[0,3.45,33.28],[1,3.4,121.29],[2,3.35,81.92]],"batl":[[1,4.1,28.95]],"ltp":3.8,"tv":159.54,"id":531005}]}]}
{"op":"mcm","clk":"1004305248","pt":1580626398117,"mc":[{"id":"1.168186838","rc":[{"batb":[[0,2.94,50.28],[1,1.01,1.41],[2,3.05,0]],"batl":[[0,3.75,34.7],[1,3.75,0]],"ltp":3.1,"tv":3.6,"id":8679736},{"batb":[[0,4.4,62.34]],"ltp":4.4,"tv":2.53,"id":8679737},{"batb":[[0,3.15,41.78],[1,1.01,1.41],[2,3.35,0]],"batl":[[0,4.1,28.95],[1,4.1,0]],"ltp":3.8,"tv":159.54,"id":531005}]}]}
{"op":"mcm","clk":"1004305376","pt":1580626401617,"mc":[{"id":"1.168186838","rc":[{"batb":[[0,3.05,132.41],[1,3,109.11],[2,2.96,49.65]],"batl":[[0,3.7,35.41]],"ltp":3.1,"tv":3.6,"id":8679736},{"batb":[[0,3.15,120.76],[1,3.1,99.72],[2,1.01,1.41]],"batl":[[0,4,29.19]],"ltp":3.8,"tv":159.54,"id":531005}]}]}
{"op":"mcm","clk":"1004305511","pt":1580626404150,"mc":[{"id":"1.168186838","rc":[{"batb":[[0,3.15,41.39],[1,1.01,1.41],[2,1.01,0]],"ltp":3.8,"tv":159.54,"id":531005}]}]}
{"op":"mcm","clk":"1004305645","pt":1580626407663,"mc":[{"id":"1.168186838","rc":[{"batl":[[0,3.25,47.68],[1,3.5,40.52],[2,3.7,35.41]],"ltp":3.1,"tv":3.6,"id":8679736},{"batb":[[0,4.4,88.07]],"ltp":4.4,"tv":2.53,"id":8679737},{"batb":[[0,3.6,106.23],[1,3.55,71.49],[2,3.35,35.96]],"batl":[[1,4.2,26.99]],"ltp":3.8,"tv":159.54,"id":531005}]}]}
{"op":"mcm","clk":"1004305665","pt":1580626408235,"mc":[{"id":"1.168186838","rc":[{"batl":[[2,3.7,0]],"ltp":3.1,"tv":3.6,"id":8679736},{"batl":[[1,5.4,30.06]],"ltp":5.1,"tv":2.18,"id":531006}]}]}
{"op":"mcm","clk":"1004306216","pt":1580626421464,"mc":[{"id":"1.168186838","rc":[{"batb":[[0,2.88,21.32],[1,1.01,1.41],[2,2.96,0]],"batl":[[0,3.5,40.52],[1,3.5,0]],"ltp":3.1,"tv":3.6,"id":8679736},{"batb":[[0,3.35,35.96],[1,1.01,1.41],[2,3.35,0]],"batl":[[0,4.2,26.99],[1,4.2,0]],"ltp":3.8,"tv":159.54,"id":531005}]}]}
{"op":"mcm","clk":"1004306319","pt":1580626424446,"mc":[{"id":"1.168186838","rc":[{"batb":[[0,2.98,81.16],[1,2.94,92.56],[2,2.88,21.32]],"ltp":3.1,"tv":3.6,"id":8679736},{"batb":[[0,3.35,164.25],[1,3.3,84.94],[2,1.01,1.41]],"ltp":3.8,"tv":159.54,"id":531005}]}]}
{"op":"mcm","clk":"1004306382","pt":1580626426455,"mc":[{"id":"1.168186838","rc":[{"batb":[[0,2.88,21.32],[1,1.01,1.41],[2,2.88,0]],"ltp":3.1,"tv":3.6,"id":8679736},{"batb":[[0,4.4,62.34]],"ltp":4.4,"tv":2.53,"id":8679737},{"batb":[[0,4.8,70.65],[1,4.7,31.63]],"ltp":5.1,"tv":2.18,"id":531006},{"batb":[[0,3.35,118.62],[1,1.01,1.41],[2,1.01,0]],"ltp":3.8,"tv":159.54,"id":531005}]}]}
{"op":"mcm","clk":"1004306474","pt":1580626429179,"mc":[{"id":"1.168186838","rc":[{"batb":[[0,2.96,90.39],[1,2.92,93.85],[2,2.88,21.32]],"ltp":3.1,"tv":3.6,"id":8679736},{"batb":[[0,4.9,46.26],[1,4.8,70.65],[2,4.7,31.63]],"ltp":5.1,"tv":2.18,"id":531006},{"batb":[[0,3.4,79.44],[1,3.35,118.62],[2,1.01,1.41]],"ltp":3.8,"tv":159.54,"id":531005}]}]}
{"op":"mcm","clk":"1004306606","pt":1580626433560,"mc":[{"id":"1.168186838","rc":[{"batb":[[0,2.88,21.32],[1,1.01,1.41],[2,2.88,0]],"ltp":3.1,"tv":3.6,"id":8679736}]}]}
{"op":"mcm","clk":"1004306719","pt":1580626436661,"mc":[{"id":"1.168186838","rc":[{"batb":[[0,3.25,74.15],[1,3.2,93.08],[2,2.88,21.32]],"ltp":3.1,"tv":3.6,"id":8679736}]}]}
{"op":"mcm","clk":"1004306761","pt":1580626437587,"mc":[{"id":"1.168186838","rc":[{"batb":[[2,3.1,42.65]],"batl":[[0,3.45,41.15],[1,3.9,31.39]],"ltp":3.1,"tv":3.6,"id":8679736},{"batb":[[1,3.35,118.07],[2,3.05,45.56]],"batl":[[0,3.75,34.23],[1,3.95,30.29]],"ltp":3.8,"tv":159.54,"id":531005}]}]}
{"op":"mcm","clk":"1004307246","pt":1580626451320,"mc":[{"id":"1.168186838","rc":[{"batb":[[0,3,47.92],[1,1.01,1.41],[2,3.1,0]],"batl":[[0,3.9,31.39],[1,3.9,0]],"ltp":3.1,"tv":3.6,"id":8679736},{"batb":[[0,4.3,129.13],[1,1.8,22.79],[2,1.01,0.51]],"ltp":4.4,"tv":2.53,"id":8679737},{"batb":[[0,4.8,70.65],[1,4.7,31.63],[2,1.8,22.79]],"ltp":5.1,"tv":2.18,"id":531006},{"batb":[[0,3.05,45.56],[1,1.01,1.41],[2,3.05,0]],"batl":[[0,3.95,30.29],[1,3.95,0]],"ltp":3.8,"tv":159.54,"id":531005}]}]}
{"op":"mcm","clk":"1004307363","pt":1580626454523,"mc":[{"id":"1.168186838","rc":[{"batb":[[0,3.05,125.48],[1,3,156.79],[2,1.01,1.41]],"ltp":3.1,"tv":3.6,"id":8679736},{"batb":[[0,4.3,166.95],[1,4.2,94.94],[2,1.8,22.79]],"ltp":4.4,"tv":2.53,"id":8679737},{"batb":[[0,4.8,109.95],[1,4.7,104.71]],"ltp":5.1,"tv":2.18,"id":531006},{"batb":[[0,3.05,202.84],[1,3,108.01],[2,1.01,1.41]],"ltp":3.8,"tv":159.54,"id":531005}]}]}
{"op":"mcm","clk":"1004307815","pt":1580626469326,"mc":[{"id":"1.168186838","rc":[{"batb":[[0,4.3,129.13],[1,1.8,22.79],[2,1.01,0.51]],"ltp":4.4,"tv":2.53,"id":8679737},{"batb":[[0,4.8,70.62],[1,4.7,31.63]],"ltp":5.1,"tv":2.18,"id":531006},{"batb":[[0,3.05,45.56],[1,1.01,1.41],[2,1.01,0]],"ltp":3.8,"tv":159.54,"id":531005}]}]}
{"op":"mcm","clk":"1004307909","pt":1580626472639,"mc":[{"id":"1.168186838","rc":[{"batb":[[0,4.4,75.84],[1,4.3,129.13],[2,1.8,22.79]],"ltp":4.4,"tv":2.53,"id":8679737},{"batb":[[0,4.9,50.78],[1,4.8,70.62],[2,4.7,31.63]],"ltp":5.1,"tv":2.18,"id":531006},{"batb":[[0,3.6,83.51],[1,3.55,71.75],[2,3.05,45.56]],"ltp":3.8,"tv":159.54,"id":531005}]}]}
{"op":"mcm","clk":"1004307949","pt":1580626473362,"mc":[{"id":"1.168186838","rc":[{"batb":[[2,2.9,51.69]],"batl":[[0,3.3,46.11],[1,3.55,39.5]],"ltp":3.1,"tv":3.6,"id":8679736},{"batb":[[1,3.55,102.99],[2,3.3,36.98]],"batl":[[1,4.1,28.09]],"ltp":3.8,"tv":159.54,"id":531005}]}]}
{"op":"mcm","clk":"1004308594","pt":1580626491684,"mc":[{"id":"1.168186838","rc":[{"batb":[[0,2.9,51.69],[1,1.01,1.41],[2,2.9,0]],"batl":[[0,3.55,39.5],[1,3.55,0]],"ltp":3.1,"tv":3.6,"id":8679736},{"batb":[[0,4.8,70.62],[1,4.7,31.63],[2,1.8,22.79]],"ltp":5.1,"tv":2.18,"id":531006},{"batb":[[0,3.3,36.98],[1,1.01,1.41],[2,3.3,0]],"batl":[[0,4.1,28.09],[1,4.1,0]],"ltp":3.8,"tv":159.54,"id":531005}]}]}
{"op":"mcm","clk":"1004308677","pt":1580626494566,"mc":[{"id":"1.168186838","rc":[{"batb":[[0,2.98,83.45],[1,2.94,92.29],[2,2.9,51.69]],"batl":[[0,3.5,40.05]],"ltp":3.1,"tv":3.6,"id":8679736},{"batb":[[0,4.8,108.27],[1,4.7,104.58]],"batl":[[1,5.5,29.74]],"ltp":5.1,"tv":2.18,"id":531006},{"batb":[[0,3.4,67.51],[1,3.35,119.28],[2,1.01,1.41]],"batl":[[0,4.1,27.7]],"ltp":3.8,"tv":159.54,"id":531005}]}]}
{"op":"mcm","clk":"1004308874","pt":1580626500163,"mc":[{"id":"1.168186838","rc":[{"batb":[[0,2.9,51.69],[1,1.01,1.41],[2,2.9,0]],"ltp":3.1,"tv":3.6,"id":8679736}]}]}
{"op":"mcm","clk":"1004309000","pt":1580626503510,"mc":[{"id":"1.168186838","rc":[{"batb":[[0,3.25,83.08],[1,3.2,93],[2,3.15,41.54]],"batl":[[1,4,29.74]],"ltp":3.1,"tv":3.6,"id":8679736},{"batl":[[1,5.4,30.06],[2,5.5,29.74]],"ltp":5.1,"tv":2.18,"id":531006},{"batb":[[2,3,48.07]],"batl":[[0,3.7,35.25],[1,3.9,31.32],[2,4.1,27.7]],"ltp":3.8,"tv":159.54,"id":531005}]}]}
{"op":"mcm","clk":"1004309032","pt":1580626504382,"mc":[{"id":"1.168186838","rc":[{"batl":[[2,5.5,0]],"ltp":5.1,"tv":2.18,"id":531006},{"batl":[[2,4.1,0]],"ltp":3.8,"tv":159.54,"id":531005}]}]}
{"op":"mcm","clk":"1004309723","pt":1580626522421,"mc":[{"id":"1.168186838","rc":[{"batb":[[0,3,46.82],[1,1.01,1.41],[2,3.15,0]],"batl":[[0,4,29.74],[1,4,0]],"ltp":3.1,"tv":3.6,"id":8679736},{"batb":[[0,4.4,46.7]],"ltp":4.4,"tv":2.53,"id":8679737},{"batb":[[0,3,48.07],[1,1.01,1.41],[2,3,0]],"batl":[[0,3.9,31.32],[1,3.9,0]],"ltp":3.8,"tv":159.54,"id":531005}]}]}
{"op":"mcm","clk":"1004309815","pt":1580626524631,"mc":[{"id":"1.168186838","rc":[{"batb":[[0,3.05,93.86],[1,3,155.98],[2,1.01,1.41]],"ltp":3.1,"tv":3.6,"id":8679736},{"batb":[[0,3.05,74.58],[1,3,156.84],[2,1.01,1.41]],"ltp":3.8,"tv":159.54,"id":531005}]}]}
{"op":"mcm","clk":"1004310019","pt":1580626529531,"mc":[{"id":"1.168186838","rc":[{"batb":[[1,4.3,128.61]],"ltp":4.4,"tv":2.53,"id":8679737},{"batb":[[0,3,48.07],[1,1.01,1.41],[2,1.01,0]],"ltp":3.8,"tv":159.54,"id":531005}]}]}
{"op":"mcm","clk":"1004310140","pt":1580626532511,"mc":[{"id":"1.168186838","rc":[{"batb":[[2,2.72,24.47]],"batl":[[0,3.35,45.01],[1,3.55,39.42]],"ltp":3.1,"tv":3.6,"id":8679736},{"batb":[[0,4.4,90.25]],"ltp":4.4,"tv":2.53,"id":8679737},{"batl":[[1,5.5,29.58]],"ltp":5.1,"tv":2.18,"id":531006},{"batb":[[0,3.6,111.08],[1,3.55,71.5],[2,3.5,32.34]],"batl":[[1,4.5,45.16]],"ltp":3.8,"tv":159.54,"id":531005}]}]}
{"op":"mcm","clk":"1004311202","pt":1580626559470,"mc":[{"id":"1.168186838","rc":[{"batb":[[0,2.72,24.47],[1,1.01,1.41],[2,2.72,0]],"batl":[[0,3.55,39.42],[1,3.55,0]],"ltp":3.1,"tv":3.6,"id":8679736},{"batb":[[0,4.4,67.02]],"ltp":4.4,"tv":2.53,"id":8679737},{"batb":[[0,3.3,36.59],[1,1.01,1.41],[2,3.5,0]],"batl":[[0,4.5,45.16],[1,4.5,0]],"ltp":3.8,"tv":159.54,"id":531005}]}]}
{"op":"mcm","clk":"1004311300","pt":1580626562456,"mc":[{"id":"1.168186838","rc":[{"batb":[[0,2.76,75.12],[1,2.72,137.25],[2,1.01,1.41]],"batl":[[0,3.5,39.97]],"ltp":3.1,"tv":3.6,"id":8679736},{"batb":[[1,4.3,90.53],[2,4.2,39.97]],"ltp":4.4,"tv":2.53,"id":8679737},{"batb":[[1,4.7,104.27]],"batl":[[1,5.5,29.19]],"ltp":5.1,"tv":2.18,"id":531006},{"batb":[[0,3.4,67.85],[1,3.35,118.78],[2,1.01,1.41]],"batl":[[0,4.6,44.46]],"ltp":3.8,"tv":159.54,"id":531005}]}]}
{"op":"mcm","clk":"1004311346","pt":1580626563693,"mc":[{"id":"1.168186838","rc":[{"batb":[[0,2.72,24.47],[1,1.01,1.41],[2,1.01,0]],"ltp":3.1,"tv":3.6,"id":8679736},{"batb":[[0,3.35,36.04],[1,1.01,1.41],[2,1.01,0]],"ltp":3.8,"tv":159.54,"id":531005}]}]}
{"op":"mcm","clk":"1004311456","pt":1580626566687,"mc":[{"id":"1.168186838","rc":[{"batb":[[0,2.98,108.65],[1,2.94,92.13],[2,2.72,24.47]],"ltp":3.1,"tv":3.6,"id":8679736},{"batb":[[0,4.4,98.26]],"ltp":4.4,"tv":2.53,"id":8679737},{"batb":[[0,3.7,89.9],[1,3.65,67.03],[2,3.35,36.04]],"ltp":3.8,"tv":159.54,"id":531005}]}]}
{"op":"mcm","clk":"1004311560","pt":1580626570699,"mc":[{"id":"1.168186838","rc":[{"batb":[[0,2.72,24.47],[1,1.01,1.41],[2,2.72,0]],"ltp":3.1,"tv":3.6,"id":8679736},{"batb":[[0,4.4,67.1]],"ltp":4.4,"tv":2.53,"id":8679737},{"batb":[[0,3.35,36.04],[1,1.01,1.41],[2,3.35,0]],"ltp":3.8,"tv":159.54,"id":531005}]}]}
{"op":"mcm","clk":"1004311777","pt":1580626573699,"mc":[{"id":"1.168186838","rc":[{"batb":[[0,2.76,75.25],[1,2.72,137.25],[2,1.01,1.41]],"ltp":3.1,"tv":3.6,"id":8679736},{"batb":[[0,3.4,67.73],[1,3.35,118.78],[2,1.01,1.41]],"ltp":3.8,"tv":159.54,"id":531005}]}]}
{"op":"mcm","clk":"1004311859","pt":1580626576065,"mc":[{"id":"1.168186838","rc":[{"batb":[[0,2.72,24.47],[1,1.01,1.41],[2,1.01,0]],"ltp":3.1,"tv":3.6,"id":8679736}]}]}
{"op":"mcm","clk":"1004311922","pt":1580626578684,"mc":[{"id":"1.168186838","rc":[{"batb":[[0,3.25,99.07],[1,3.2,92.87],[2,2.72,24.47]],"ltp":3.1,"tv":3.6,"id":8679736}]}]}
{"op":"mcm","clk":"1004311950","pt":1580626579505,"mc":[{"id":"1.168186838","rc":[{"batb":[[2,3.15,41.47]],"batl":[[1,3.65,35.96]],"ltp":3.1,"tv":3.6,"id":8679736},{"batl":[[0,4.9,37.45],[1,5,35.96],[2,5.1,10.13]],"ltp":4.4,"tv":2.53,"id":8679737},{"batb":[[2,3.2,40.13]],"batl":[[0,3.7,34.86],[1,4.1,27.46],[2,4.6,44.46]],"ltp":3.8,"tv":159.54,"id":531005}]}]}
{"op":"mcm","clk":"1004311982","pt":1580626580603,"mc":[{"id":"1.168186838","rc":[{"batl":[[1,5.1,10.13],[2,5.1,0]],"ltp":4.4,"tv":2.53,"id":8679737},{"batl":[[2,4.6,0]],"ltp":3.8,"tv":159.54,"id":531005}]}]}
{"op":"mcm","clk":"1004312644","pt":1580626594501,"mc":[{"id":"1.168186838","rc":[{"batb":[[0,2.9,52.32],[1,1.01,1.41],[2,3.15,0]],"batl":[[0,3.65,35.96],[1,3.65,0]],"ltp":3.1,"tv":3.6,"id":8679736},{"batb":[[0,4.4,67.02]],"ltp":4.4,"tv":2.53,"id":8679737},{"batb":[[0,4.8,93]],"ltp":5.1,"tv":2.18,"id":531006},{"batb":[[0,3.2,40.13],[1,1.01,1.41],[2,3.2,0]],"batl":[[0,4.1,27.46],[1,4.1,0]],"ltp":3.8,"tv":159.54,"id":531005}]}]}
{"op":"mcm","clk":"1004312771","pt":1580626599436,"mc":[{"id":"1.168186838","rc":[{"batb":[[0,3.2,81.52],[1,3.15,96.73],[2,2.9,52.32]],"ltp":3.1,"tv":3.6,"id":8679736},{"batb":[[0,3.45,86.6],[1,3.4,79.63],[2,3.2,40.13]],"ltp":3.8,"tv":159.54,"id":531005}]}]}
{"op":"mcm","clk":"1004312933","pt":1580626604538,"mc":[{"id":"1.168186838","rc":[{"batb":[[0,2.9,52.32],[1,1.01,1.41],[2,2.9,0]],"ltp":3.1,"tv":3.6,"id":8679736},{"batb":[[0,3.2,40.13],[1,1.01,1.41],[2,3.2,0]],"ltp":3.8,"tv":159.54,"id":531005}]}]}
{"op":"mcm","clk":"1004313021","pt":1580626607434,"mc":[{"id":"1.168186838","rc":[{"batb":[[0,2.98,84.99],[1,2.94,92.3],[2,2.9,52.32]],"ltp":3.1,"tv":3.6,"id":8679736},{"batb":[[0,3.2,177.21],[1,3.15,95.65],[2,1.01,1.41]],"ltp":3.8,"tv":159.54,"id":531005}]}]}
{"op":"mcm","clk":"1004313301","pt":1580626616378,"mc":[{"id":"1.168186838","rc":[{"batb":[[0,2.9,52.32],[1,1.01,1.41],[2,2.9,0]],"ltp":3.1,"tv":3.6,"id":8679736}]}]}
{"op":"mcm","clk":"1004313417","pt":1580626619472,"mc":[{"id":"1.168186838","rc":[{"batb":[[0,3.45,65.34],[1,3.4,80.3],[2,2.9,52.32]],"ltp":3.1,"tv":3.6,"id":8679736}]}]}
{"op":"mcm","clk":"1004313444","pt":1580626620243,"mc":[{"id":"1.168186838","rc":[{"batb":[[2,3.3,37.22]],"batl":[[1,3.85,32.65]],"ltp":3.1,"tv":3.6,"id":8679736},{"batb":[[2,3.1,43.04]],"batl":[[0,3.55,38.71],[1,3.8,32.73]],"ltp":3.8,"tv":159.54,"id":531005}]}]}
{"op":"mcm","clk":"1004313992","pt":1580626636482,"mc":[{"id":"1.168186838","rc":[{"batb":[[0,3.05,44.46],[1,1.01,1.41],[2,3.3,0]],"batl":[[0,3.85,32.65],[1,3.85,0]],"ltp":3.1,"tv":3.6,"id":8679736},{"batb":[[0,4.4,50.86]],"ltp":4.4,"tv":2.53,"id":8679737},{"batb":[[0,3.1,43.04],[1,1.01,1.41],[2,3.1,0]],"batl":[[0,3.8,32.73],[1,3.8,0]],"ltp":3.8,"tv":159.54,"id":531005}]}]}
{"op":"mcm","clk":"1004314198","pt":1580626642294,"mc":[{"id":"1.168186838","rc":[{"batb":[[0,3.4,70.93],[1,3.35,83.2],[2,3.05,44.46]],"ltp":3.1,"tv":3.6,"id":8679736},{"batb":[[0,3.25,115.53],[1,3.2,92.16],[2,3.1,43.04]],"ltp":3.8,"tv":159.54,"id":531005}]}]}
{"op":"mcm","clk":"1004314356","pt":1580626647692,"mc":[{"id":"1.168186838","rc":[{"batb":[[0,3.05,44.46],[1,1.01,1.41],[2,3.05,0]],"ltp":3.1,"tv":3.6,"id":8679736},{"batb":[[0,3.1,43.04],[1,1.01,1.41],[2,3.1,0]],"ltp":3.8,"tv":159.54,"id":531005}]}]}
{"op":"mcm","clk":"1004314439","pt":1580626650418,"mc":[{"id":"1.168186838","rc":[{"batb":[[0,3.2,119.67],[1,3.15,96.38],[2,3.05,44.46]],"ltp":3.1,"tv":3.6,"id":8679736},{"batb":[[0,3.1,176.11],[1,3.05,103.76],[2,1.01,1.41]],"ltp":3.8,"tv":159.54,"id":531005}]}]}
{"op":"mcm","clk":"1004314581","pt":1580626655740,"mc":[{"id":"1.168186838","rc":[{"batb":[[0,3.1,43.04],[1,1.01,1.41],[2,1.01,0]],"ltp":3.8,"tv":159.54,"id":531005}]}]}
{"op":"mcm","clk":"1004314665","pt":1580626658624,"mc":[{"id":"1.168186838","rc":[{"batb":[[0,4.8,109.35]],"ltp":5.1,"tv":2.18,"id":531006},{"batb":[[0,3.4,139.34],[1,3.35,82.08],[2,3.1,43.04]],"ltp":3.8,"tv":159.54,"id":531005}]}]}
{"op":"mcm","clk":"1004314693","pt":1580626659651,"mc":[{"id":"1.168186838","rc":[{"batl":[[0,3.4,42.8],[1,3.6,37.77]],"ltp":3.1,"tv":3.6,"id":8679736},{"batl":[[0,4.9,36.98]],"ltp":4.4,"tv":2.53,"id":8679737},{"batb":[[1,4.7,104.11]],"batl":[[1,5.5,29.03]],"ltp":5.1,"tv":2.18,"id":531006},{"batb":[[0,3.45,33.83],[1,3.4,139.34],[2,3.35,82.08]],"batl":[[1,4.4,48.47]],"ltp":3.8,"tv":159.54,"id":531005}]}]}
{"op":"mcm","clk":"1004315335","pt":1580626678678,"mc":[{"id":"1.168186838","rc":[{"batb":[[0,2.78,23.13],[1,1.01,1.41],[2,3.05,0]],"batl":[[0,3.6,37.77],[1,3.6,0]],"ltp":3.1,"tv":3.6,"id":8679736},{"batb":[[0,4.3,90.53],[1,4.2,39.97],[2,1.8,22.79]],"ltp":4.4,"tv":2.53,"id":8679737},{"batb":[[0,3.25,38.4],[1,1.01,1.41],[2,3.35,0]],"batl":[[0,4.4,48.47],[1,4.4,0]],"ltp":3.8,"tv":159.54,"id":531005}]}]}
{"op":"mcm","clk":"1004315440","pt":1580626681498,"mc":[{"id":"1.168186838","rc":[{"batb":[[0,2.9,95.5],[1,2.86,98.95],[2,2.78,23.13]],"ltp":3.1,"tv":3.6,"id":8679736},{"batb":[[0,4.3,131.05],[1,4.2,134.85]],"ltp":4.4,"tv":2.53,"id":8679737},{"batb":[[0,3.25,102.22],[1,3.2,92.64],[2,1.01,1.41]],"ltp":3.8,"tv":159.54,"id":531005}]}]}
{"op":"mcm","clk":"1004315452","pt":1580626681858,"mc":[{"id":"1.168186838","rc":[{"batb":[[0,2.78,23.13],[1,1.01,1.41],[2,2.78,0]],"ltp":3.1,"tv":3.6,"id":8679736},{"batb":[[0,4.3,91.03],[1,4.2,39.97]],"ltp":4.4,"tv":2.53,"id":8679737},{"batb":[[0,3.25,38.4],[1,1.01,1.41],[2,1.01,0]],"ltp":3.8,"tv":159.54,"id":531005}]}]}
