{"op":"mcm","clk":"993170579","pt":1580537866635,"mc":[{"id":"1.168186837","marketDefinition":{"bspMarket":false,"turnInPlayEnabled":true,"persistenceEnabled":true,"marketBaseRate":5.0,"eventId":"29680287","eventTypeId":"2","numberOfWinners":1,"bettingType":"ODDS","marketType":"MATCH_ODDS","marketTime":"2020-02-02T02:00:00.000Z","suspendTime":"2020-02-02T02:00:00.000Z","bspReconciled":false,"complete":true,"inPlay":false,"crossMatching":false,"runnersVoidable":false,"numberOfActiveRunners":2,"betDelay":0,"status":"OPEN","runners":[{"status":"ACTIVE","sortPriority":1,"id":8173434,"name":"Taro Daniel"},{"status":"ACTIVE","sortPriority":2,"id":8639275,"name":"Yannick Hanfmann"}],"regulators":["MR_INT"],"countryCode":"AU","discountAllowed":false,"timezone":"UTC","openDate":"2020-02-02T02:00:00.000Z","version":3144541453,"name":"Match Odds","eventName":"Daniel v Hanfmann"},"rc":[{"batb":[[0,1.01,30]],"ltp":0.0,"tv":0.0,"id":8639275},{"batb":[[0,1.01,30]],"ltp":0.0,"tv":0.0,"id":8173434}]}]}
{"op":"mcm","clk":"993170622","pt":1580537867691,"mc":[{"id":"1.168186837","marketDefinition":{"bspMarket":false,"turnInPlayEnabled":true,"persistenceEnabled":true,"marketBaseRate":5.0,"eventId":"29680287","eventTypeId":"2","numberOfWinners":1,"bettingType":"ODDS","marketType":"MATCH_ODDS","marketTime":"2020-02-02T02:00:00.000Z","suspendTime":"2020-02-02T02:00:00.000Z","bspReconciled":false,"complete":true,"inPlay":false,"crossMatching":false,"runnersVoidable":false,"numberOfActiveRunners":2,"betDelay":0,"status":"OPEN","runners":[{"status":"ACTIVE","sortPriority":1,"id":8173434,"name":"Taro Daniel"},{"status":"ACTIVE","sortPriority":2,"id":8639275,"name":"Yannick Hanfmann"}],"regulators":["MR_INT"],"countryCode":"AU","discountAllowed":true,"timezone":"UTC","openDate":"2020-02-02T02:00:00.000Z","version":3144541453,"name":"Match Odds","eventName":"Daniel v Hanfmann"}}]}
{"op":"mcm","clk":"993171330","pt":1580537883488,"mc":[{"id":"1.168186837","rc":[{"batb":[[0,1.01,282.92]],"ltp":0.0,"tv":0.0,"id":8639275},{"batb":[[0,1.05,152.2],[1,1.04,168.86],[2,1.03,190.07]],"ltp":0.0,"tv":0.0,"id":8173434}]}]}
{"op":"mcm","clk":"993171469","pt":1580537886587,"mc":[{"id":"1.168186837","rc":[{"batb":[[0,1.01,346.52]],"ltp":0.0,"tv":0.0,"id":8639275},{"batb":[[2,1.03,237.77]],"ltp":0.0,"tv":0.0,"id":8173434}]}]}
{"op":"mcm","clk":"993172833","pt":1580537918635,"mc":[{"id":"1.168186837","rc":[{"batb":[[0,1.01,646.52]],"ltp":0.0,"tv":0.0,"id":8639275}]}]}
{"op":"mcm","clk":"993173018","pt":1580537922338,"mc":[{"id":"1.168186837","rc":[{"batb":[[0,1.01,346.52]],"ltp":0.0,"tv":0.0,"id":8639275}]}]}
{"op":"mcm","clk":"993194444","pt":1580538191617,"mc":[{"id":"1.168186837","rc":[{"batb":[[0,1.02,151.45],[1,1.01,346.52]],"batl":[[0,990,1.51]],"ltp":0.0,"tv":0.0,"id":8639275},{"batl":[[0,990,1.51]],"ltp":0.0,"tv":0.0,"id":8173434}]}]}
{"op":"mcm","clk":"993194459","pt":1580538191926,"mc":[{"id":"1.168186837","rc":[{"batb":[[0,1.06,50.48],[1,1.05,152.2],[2,1.04,168.86]],"ltp":0.0,"tv":0.0,"id":8173434}]}]}
{"op":"mcm","clk":"993195492","pt":1580538217524,"mc":[{"id":"1.168186837","marketDefinition":{"bspMarket":false,"turnInPlayEnabled":true,"persistenceEnabled":true,"marketBaseRate":5.0,"eventId":"29680287","eventTypeId":"2","numberOfWinners":1,"bettingType":"ODDS","marketType":"MATCH_ODDS","marketTime":"2020-02-02T02:00:00.000Z","suspendTime":"2020-02-02T02:00:00.000Z","bspReconciled":false,"complete":true,"inPlay":false,"crossMatching":true,"runnersVoidable":false,"numberOfActiveRunners":2,"betDelay":0,"status":"OPEN","runners":[{"status":"ACTIVE","sortPriority":1,"id":8173434,"name":"Taro Daniel"},{"status":"ACTIVE","sortPriority":2,"id":8639275,"name":"Yannick Hanfmann"}],"regulators":["MR_INT"],"countryCode":"AU","discountAllowed":true,"timezone":"UTC","openDate":"2020-02-02T02:00:00.000Z","version":3144541453,"name":"Match Odds","eventName":"Daniel v Hanfmann"}}]}
{"op":"mcm","clk":"993197700","pt":1580538274429,"mc":[{"id":"1.168186837","rc":[{"batb":[[0,1.13,75.72],[1,1.02,151.45],[2,1.01,346.52]],"ltp":0.0,"tv":0.0,"id":8639275},{"batb":[[0,1.09,75.72],[1,1.06,50.48],[2,1.05,152.2]],"ltp":0.0,"tv":0.0,"id":8173434}]}]}
{"op":"mcm","clk":"993211509","pt":1580538616662,"mc":[{"id":"1.168186837","rc":[{"batb":[[2,1.01,326.52]],"ltp":0.0,"tv":0.0,"id":8639275}]}]}
{"op":"mcm","clk":"993355327","pt":1580541143395,"mc":[{"id":"1.168186837","rc":[{"batl":[[0,990,3.71]],"ltp":0.0,"tv":0.0,"id":8639275},{"batl":[[0,990,3.71]],"ltp":0.0,"tv":0.0,"id":8173434}]}]}
{"op":"mcm","clk":"993493935","pt":1580543134463,"mc":[{"id":"1.168186837","rc":[{"batb":[[1,1.03,8.4],[2,1.02,176.65]],"ltp":0.0,"tv":0.0,"id":8639275}]}]}
{"op":"mcm","clk":"994037142","pt":1580548737153,"mc":[{"id":"1.168186837","rc":[{"batb":[[2,1.02,176.85]],"ltp":0.0,"tv":0.0,"id":8639275}]}]}
{"op":"mcm","clk":"994192783","pt":1580550078867,"mc":[{"id":"1.168186837","rc":[{"batb":[[0,1.09,77.72]],"ltp":0.0,"tv":0.0,"id":8173434}]}]}
{"op":"mcm","clk":"994258742","pt":1580550647138,"mc":[{"id":"1.168186837","rc":[{"batl":[[0,95,15.9],[1,990,3.71]],"ltp":0.0,"tv":0.0,"id":8639275},{"batl":[[0,95,15.9],[1,990,3.71]],"ltp":0.0,"tv":0.0,"id":8173434}]}]}
{"op":"mcm","clk":"994353385","pt":1580551365529,"mc":[{"id":"1.168186837","rc":[{"batb":[[0,1.88,21.71],[1,1.13,75.72],[2,1.03,8.4]],"ltp":0.0,"tv":0.0,"id":8639275},{"batb":[[0,1.61,27.86],[1,1.09,77.72],[2,1.06,50.48]],"ltp":0.0,"tv":0.0,"id":8173434}]}]}
{"op":"mcm","clk":"994353565","pt":1580551367310,"mc":[{"id":"1.168186837","rc":[{"batb":[[0,1.82,11.42]],"ltp":0.0,"tv":0.0,"id":8639275},{"batb":[[0,1.48,15.51]],"ltp":0.0,"tv":0.0,"id":8173434}]}]}
{"op":"mcm","clk":"994353874","pt":1580551370446,"mc":[{"id":"1.168186837","rc":[{"batb":[[0,1.13,75.72],[1,1.03,8.4],[2,1.02,176.85]],"ltp":0.0,"tv":0.0,"id":8639275},{"batb":[[0,1.09,77.72],[1,1.06,50.48],[2,1.05,152.2]],"ltp":0.0,"tv":0.0,"id":8173434}]}]}
{"op":"mcm","clk":"994354080","pt":1580551372114,"mc":[{"id":"1.168186837","rc":[{"batb":[[0,1.79,22.74],[1,1.13,75.72],[2,1.03,8.4]],"ltp":0.0,"tv":0.0,"id":8639275},{"batb":[[0,1.67,24.47],[1,1.09,77.72],[2,1.06,50.48]],"ltp":0.0,"tv":0.0,"id":8173434}]}]}
{"op":"mcm","clk":"994354525","pt":1580551376352,"mc":[{"id":"1.168186837","rc":[{"batb":[[0,1.88,37.86],[1,1.79,22.74],[2,1.13,75.72]],"ltp":0.0,"tv":0.0,"id":8639275},{"batb":[[0,1.84,37.86],[1,1.67,24.47],[2,1.09,77.72]],"ltp":0.0,"tv":0.0,"id":8173434}]}]}
{"op":"mcm","clk":"994354596","pt":1580551377034,"mc":[{"id":"1.168186837","rc":[{"batb":[[0,1.88,59.57],[1,1.13,75.72],[2,1.03,8.4]],"ltp":0.0,"tv":0.0,"id":8639275},{"batb":[[0,1.86,22.04],[1,1.84,37.86]],"ltp":0.0,"tv":0.0,"id":8173434}]}]}
{"op":"mcm","clk":"994354698","pt":1580551378030,"mc":[{"id":"1.168186837","rc":[{"batb":[[0,1.88,37.86]],"ltp":0.0,"tv":0.0,"id":8639275}]}]}
{"op":"mcm","clk":"994355034","pt":1580551380658,"mc":[{"id":"1.168186837","rc":[{"batb":[[0,1.13,75.72],[1,1.03,8.4],[2,1.02,176.85]],"ltp":0.0,"tv":0.0,"id":8639275},{"batb":[[1,1.09,77.72],[2,1.06,50.48]],"ltp":0.0,"tv":0.0,"id":8173434}]}]}
{"op":"mcm","clk":"994355047","pt":1580551380763,"mc":[{"id":"1.168186837","rc":[{"batb":[[1,1.85,37.86],[2,1.09,77.72]],"ltp":0.0,"tv":0.0,"id":8173434}]}]}
{"op":"mcm","clk":"994355331","pt":1580551382674,"mc":[{"id":"1.168186837","rc":[{"batb":[[1,1.84,37.86]],"ltp":0.0,"tv":0.0,"id":8173434}]}]}
{"op":"mcm","clk":"994355363","pt":1580551382895,"mc":[{"id":"1.168186837","rc":[{"batb":[[0,1.73,38.62],[1,1.13,75.72],[2,1.03,8.4]],"ltp":0.0,"tv":0.0,"id":8639275}]}]}
{"op":"mcm","clk":"994355595","pt":1580551384405,"mc":[{"id":"1.168186837","rc":[{"batb":[[0,1.81,38.62]],"ltp":0.0,"tv":0.0,"id":8639275},{"batb":[[1,1.09,77.72],[2,1.06,50.48]],"ltp":0.0,"tv":0.0,"id":8173434}]}]}
{"op":"mcm","clk":"994357494","pt":1580551396790,"mc":[{"id":"1.168186837","rc":[{"batb":[[1,1.84,36.35],[2,1.09,77.72]],"ltp":0.0,"tv":0.0,"id":8173434}]}]}
{"op":"mcm","clk":"994365972","pt":1580551458207,"mc":[{"id":"1.168186837","rc":[{"batb":[[0,1.94,36.35],[1,1.86,22.04]],"ltp":0.0,"tv":0.0,"id":8173434}]}]}
{"op":"mcm","clk":"994380175","pt":1580551549063,"mc":[{"id":"1.168186837","rc":[{"batb":[[0,1.84,43.29],[1,1.81,38.62],[2,1.13,75.72]],"ltp":0.0,"tv":0.0,"id":8639275},{"batb":[[0,1.98,41.37],[1,1.94,36.35],[2,1.86,22.04]],"ltp":0.0,"tv":0.0,"id":8173434}]}]}
{"op":"mcm","clk":"994526075","pt":1580552326571,"mc":[{"id":"1.168186837","rc":[{"batl":[[0,12,3.36],[1,95,15.9],[2,990,3.71]],"ltp":0.0,"tv":0.0,"id":8639275}]}]}
{"op":"mcm","clk":"994526103","pt":1580552326732,"mc":[{"id":"1.168186837","rc":[{"batl":[[0,12.5,3.36],[1,95,15.9],[2,990,3.71]],"ltp":0.0,"tv":0.0,"id":8173434}]}]}
{"op":"mcm","clk":"994529473","pt":1580552346410,"mc":[{"id":"1.168186837","rc":[{"batl":[[0,1.93,15.14],[1,12,3.36],[2,95,15.9]],"ltp":0.0,"tv":0.0,"id":8639275}]}]}
{"op":"mcm","clk":"994529553","pt":1580552346814,"mc":[{"id":"1.168186837","rc":[{"batb":[[2,1.09,77.72]],"ltp":0.0,"tv":0.0,"id":8173434}]}]}
{"op":"mcm","clk":"994539439","pt":1580552398899,"mc":[{"id":"1.168186837","rc":[{"batl":[[1,95,15.9],[2,990,3.71]],"ltp":0.0,"tv":0.0,"id":8639275}]}]}
{"op":"mcm","clk":"994607269","pt":1580552713346,"mc":[{"id":"1.168186837","rc":[{"batl":[[0,95,15.9],[1,990,3.71],[2,990,0]],"ltp":0.0,"tv":0.0,"id":8639275}]}]}
{"op":"mcm","clk":"994608769","pt":1580552721592,"mc":[{"id":"1.168186837","rc":[{"batb":[[1,1.13,75.72],[2,1.03,8.4]],"ltp":0.0,"tv":0.0,"id":8639275}]}]}
{"op":"mcm","clk":"994609865","pt":1580552728599,"mc":[{"id":"1.168186837","rc":[{"batl":[[0,12,3.36],[1,95,15.9],[2,990,3.71]],"ltp":0.0,"tv":0.0,"id":8639275}]}]}
{"op":"mcm","clk":"994755260","pt":1580553514868,"mc":[{"id":"1.168186837","rc":[{"batb":[[0,1.84,45.07]],"ltp":0.0,"tv":0.0,"id":8639275},{"batb":[[0,1.98,39.72]],"ltp":0.0,"tv":0.0,"id":8173434}]}]}
{"op":"mcm","clk":"994978558","pt":1580554835672,"mc":[{"id":"1.168186837","rc":[{"batb":[[1,1.77,35.59],[2,1.13,75.72]],"ltp":0.0,"tv":0.0,"id":8639275},{"batb":[[0,1.99,36.35],[1,1.98,39.72]],"ltp":0.0,"tv":0.0,"id":8173434}]}]}
{"op":"mcm","clk":"994991040","pt":1580554896141,"mc":[{"id":"1.168186837","rc":[{"batb":[[0,2,31.01],[1,1.99,36.35]],"ltp":0.0,"tv":0.0,"id":8173434}]}]}
{"op":"mcm","clk":"995012075","pt":1580554991549,"mc":[{"id":"1.168186837","rc":[{"batb":[[2,1.67,42.95]],"ltp":0.0,"tv":0.0,"id":8639275},{"batb":[[2,1.85,33.86]],"ltp":0.0,"tv":0.0,"id":8173434}]}]}
{"op":"mcm","clk":"995035811","pt":1580555102386,"mc":[{"id":"1.168186837","rc":[{"batb":[[2,1.68,42.31]],"ltp":0.0,"tv":0.0,"id":8639275}]}]}
{"op":"mcm","clk":"995036442","pt":1580555104979,"mc":[{"id":"1.168186837","rc":[{"batb":[[1,1.78,35.59]],"ltp":0.0,"tv":0.0,"id":8639275},{"batb":[[1,1.98,36.35]],"ltp":0.0,"tv":0.0,"id":8173434}]}]}
{"op":"mcm","clk":"995080187","pt":1580555263689,"mc":[{"id":"1.168186837","rc":[{"batb":[[1,1.85,33.86],[2,1.09,77.72]],"ltp":0.0,"tv":0.0,"id":8173434}]}]}
{"op":"mcm","clk":"995080389","pt":1580555264505,"mc":[{"id":"1.168186837","rc":[{"batb":[[1,1.78,65.88]],"ltp":0.0,"tv":0.0,"id":8639275},{"batb":[[1,1.98,59.06],[2,1.85,33.86]],"ltp":0.0,"tv":0.0,"id":8173434}]}]}
{"op":"mcm","clk":"995088317","pt":1580555303514,"mc":[{"id":"1.168186837","rc":[{"batb":[[0,1.99,35.32]],"ltp":0.0,"tv":0.0,"id":8173434}]}]}
{"op":"mcm","clk":"995587470","pt":1580557645194,"mc":[{"id":"1.168186837","rc":[{"batb":[[0,1.84,43.29]],"ltp":0.0,"tv":0.0,"id":8639275}]}]}
{"op":"mcm","clk":"995704593","pt":1580558322356,"mc":[{"id":"1.168186837","rc":[{"batb":[[0,1.99,65.06]],"ltp":0.0,"tv":0.0,"id":8173434}]}]}
{"op":"mcm","clk":"995772865","pt":1580558753657,"mc":[{"id":"1.168186837","rc":[{"batb":[[0,1.99,74.88]],"ltp":0.0,"tv":0.0,"id":8173434}]}]}
{"op":"mcm","clk":"995773155","pt":1580558755421,"mc":[{"id":"1.168186837","rc":[{"batb":[[2,1.68,55.68]],"ltp":0.0,"tv":0.0,"id":8639275},{"batb":[[2,1.85,44.54]],"ltp":0.0,"tv":0.0,"id":8173434}]}]}
{"op":"mcm","clk":"995894784","pt":1580559345790,"mc":[{"id":"1.168186837","rc":[{"batb":[[0,1.86,310.46],[1,1.84,43.29],[2,1.78,65.88]],"ltp":0.0,"tv":0.0,"id":8639275}]}]}
{"op":"mcm","clk":"995915782","pt":1580559464277,"mc":[{"id":"1.168186837","rc":[{"batb":[[0,1.87,28.53],[1,1.86,310.46]],"ltp":0.0,"tv":0.0,"id":8639275}]}]}
{"op":"mcm","clk":"996010879","pt":1580559948344,"mc":[{"id":"1.168186837","rc":[{"batl":[[0,2,7.57],[1,12,3.36],[2,95,15.9]],"ltp":0.0,"tv":0.0,"id":8639275}]}]}
{"op":"mcm","clk":"996010950","pt":1580559948739,"mc":[{"id":"1.168186837","rc":[{"batb":[[0,1.99,35.32]],"ltp":0.0,"tv":0.0,"id":8173434}]}]}
{"op":"mcm","clk":"996011472","pt":1580559951548,"mc":[{"id":"1.168186837","rc":[{"batl":[[0,1.99,7.57],[1,2,7.57],[2,12,3.36]],"ltp":0.0,"tv":0.0,"id":8639275}]}]}
{"op":"mcm","clk":"996011996","pt":1580559954880,"mc":[{"id":"1.168186837","rc":[{"batl":[[1,12,3.36],[2,95,15.9]],"ltp":0.0,"tv":0.0,"id":8639275}]}]}
{"op":"mcm","clk":"996022103","pt":1580560010777,"mc":[{"id":"1.168186837","rc":[{"batl":[[1,95,15.9],[2,990,3.71]],"ltp":0.0,"tv":0.0,"id":8639275}]}]}
{"op":"mcm","clk":"996039900","pt":1580560109668,"mc":[{"id":"1.168186837","rc":[{"batb":[[0,2.02,22.91]],"ltp":0.0,"tv":0.0,"id":8173434}]}]}
{"op":"mcm","clk":"996444852","pt":1580562212288,"mc":[{"id":"1.168186837","rc":[{"batb":[[2,1.71,213.5]],"ltp":0.0,"tv":0.0,"id":8173434}]}]}
{"op":"mcm","clk":"996444972","pt":1580562212874,"mc":[{"id":"1.168186837","rc":[{"batb":[[2,1.85,56.13]],"ltp":0.0,"tv":0.0,"id":8173434}]}]}
{"op":"mcm","clk":"996488029","pt":1580562414544,"mc":[{"id":"1.168186837","rc":[{"trd":[[1.87,57]],"batb":[[0,1.86,310.5],[1,1.78,65.88],[2,1.61,213.5]],"ltp":1.87,"tv":56.99,"id":8639275},{"batb":[[1,2,195.17],[2,1.98,59.06]],"ltp":0.0,"tv":0.0,"id":8173434}],"tv":56.99}]}
{"op":"mcm","clk":"996488169","pt":1580562415150,"mc":[{"id":"1.168186837","rc":[{"trd":[[1.86,229.72],[1.87,57.06]],"batb":[[0,1.86,195.61],[2,1.61,291.71]],"ltp":1.86,"tv":286.77,"id":8639275}],"tv":286.77}]}
{"op":"mcm","clk":"996488557","pt":1580562416922,"mc":[{"id":"1.168186837","rc":[{"batb":[[2,1.61,213.5]],"ltp":1.86,"tv":286.77,"id":8639275}]}]}
{"op":"mcm","clk":"996488741","pt":1580562418091,"mc":[{"id":"1.168186837","rc":[{"batb":[[1,1.61,213.5],[2,1.58,82.25]],"ltp":1.86,"tv":286.77,"id":8639275},{"batb":[[0,2.02,81.98],[2,1.97,49.18]],"ltp":0.0,"tv":0.0,"id":8173434}]}]}
{"op":"mcm","clk":"996489029","pt":1580562419272,"mc":[{"id":"1.168186837","rc":[{"batb":[[2,1.41,7.57]],"ltp":1.86,"tv":286.77,"id":8639275},{"batb":[[2,1.71,213.5]],"ltp":0.0,"tv":0.0,"id":8173434}]}]}
{"op":"mcm","clk":"996489215","pt":1580562420054,"mc":[{"id":"1.168186837","rc":[{"batb":[[1,1.61,291.71]],"ltp":1.86,"tv":286.77,"id":8639275},{"batb":[[0,2.02,22.91],[2,1.92,51.86]],"ltp":0.0,"tv":0.0,"id":8173434}]}]}
{"op":"mcm","clk":"996489758","pt":1580562422343,"mc":[{"id":"1.168186837","rc":[{"batb":[[1,1.7,68.15],[2,1.61,291.71]],"ltp":1.86,"tv":286.77,"id":8639275},{"batb":[[1,2,252.72]],"ltp":0.0,"tv":0.0,"id":8173434}]}]}
{"op":"mcm","clk":"996490173","pt":1580562424237,"mc":[{"id":"1.168186837","rc":[{"batb":[[1,1.79,45.02],[2,1.7,68.15]],"ltp":1.86,"tv":286.77,"id":8639275},{"batb":[[0,2.06,50.74],[1,2.04,40.48],[2,2,252.72]],"ltp":0.0,"tv":0.0,"id":8173434}]}]}
{"op":"mcm","clk":"996541463","pt":1580562610638,"mc":[{"id":"1.168186837","rc":[{"batb":[[2,2,195.17]],"ltp":0.0,"tv":0.0,"id":8173434}]}]}
{"op":"mcm","clk":"996541508","pt":1580562610841,"mc":[{"id":"1.168186837","rc":[{"batb":[[2,2.02,57.55]],"ltp":0.0,"tv":0.0,"id":8173434}]}]}
{"op":"mcm","clk":"996557101","pt":1580562683098,"mc":[{"id":"1.168186837","rc":[{"batb":[[0,2.08,24.77],[1,2.06,50.74]],"ltp":0.0,"tv":0.0,"id":8173434}]}]}
{"op":"mcm","clk":"996578165","pt":1580562785731,"mc":[{"id":"1.168186837","rc":[{"trd":[[1.86,458.28]],"batb":[[0,1.86,81.33]],"ltp":1.86,"tv":515.34,"id":8639275},{"batb":[[1,2.02,57.55],[2,2,195.17]],"ltp":0.0,"tv":0.0,"id":8173434}],"tv":515.34}]}
{"op":"mcm","clk":"996578595","pt":1580562787671,"mc":[{"id":"1.168186837","rc":[{"trd":[[1.79,90.04],[1.86,620.94]],"batb":[[0,1.84,125.98],[1,1.7,68.15],[2,1.61,213.5]],"ltp":1.79,"tv":768.03,"id":8639275},{"batb":[[2,2,242.88]],"ltp":0.0,"tv":0.0,"id":8173434}],"tv":768.03}]}
{"op":"mcm","clk":"996578723","pt":1580562788340,"mc":[{"id":"1.168186837","rc":[{"batb":[[1,1.61,213.5],[2,1.56,85.19]],"ltp":1.79,"tv":768.03,"id":8639275}]}]}
{"op":"mcm","clk":"996578923","pt":1580562789327,"mc":[{"id":"1.168186837","rc":[{"batb":[[2,1.41,7.57]],"ltp":1.79,"tv":768.03,"id":8639275},{"batb":[[1,2,195.17],[2,1.71,213.5]],"ltp":0.0,"tv":0.0,"id":8173434}]}]}
{"op":"mcm","clk":"996579064","pt":1580562790034,"mc":[{"id":"1.168186837","rc":[{"trd":[[1.84,54.65]],"batb":[[0,1.84,98.66],[2,1.59,80.86]],"ltp":1.84,"tv":822.68,"id":8639275},{"batb":[[2,1.94,50.75]],"ltp":0.0,"tv":0.0,"id":8173434}],"tv":822.68}]}
{"op":"mcm","clk":"996579986","pt":1580562795125,"mc":[{"id":"1.168186837","rc":[{"batb":[[0,2.12,50.29],[1,2.08,24.77],[2,2,195.17]],"ltp":0.0,"tv":0.0,"id":8173434}]}]}
{"op":"mcm","clk":"996580182","pt":1580562796169,"mc":[{"id":"1.168186837","rc":[{"batb":[[1,1.76,47.03],[2,1.61,213.5]],"ltp":1.84,"tv":822.68,"id":8639275},{"batb":[[1,2.08,39.04]],"ltp":0.0,"tv":0.0,"id":8173434}]}]}
{"op":"mcm","clk":"996581322","pt":1580562801651,"mc":[{"id":"1.168186837","rc":[{"batl":[[0,1.87,7.57],[1,1.99,7.57],[2,95,15.9]],"ltp":1.84,"tv":822.68,"id":8639275}]}]}
{"op":"mcm","clk":"996581995","pt":1580562805176,"mc":[{"id":"1.168186837","rc":[{"batl":[[0,1.99,7.57],[1,95,15.9],[2,990,3.71]],"ltp":1.84,"tv":822.68,"id":8639275}]}]}
{"op":"mcm","clk":"996599844","pt":1580562890506,"mc":[{"id":"1.168186837","rc":[{"batb":[[0,2.14,17.11],[1,2,195.17],[2,1.94,50.75]],"ltp":0.0,"tv":0.0,"id":8173434}]}]}
{"op":"mcm","clk":"996631939","pt":1580563044487,"mc":[{"id":"1.168186837","rc":[{"batb":[[2,1.61,291.71]],"ltp":1.84,"tv":822.68,"id":8639275},{"batb":[[2,1.93,51.29]],"ltp":0.0,"tv":0.0,"id":8173434}]}]}
{"op":"mcm","clk":"996641624","pt":1580563093065,"mc":[{"id":"1.168186837","rc":[{"batb":[[0,2.08,39.04]],"ltp":0.0,"tv":0.0,"id":8173434}]}]}
{"op":"mcm","clk":"996641779","pt":1580563093762,"mc":[{"id":"1.168186837","rc":[{"batb":[[0,2.1,49.94],[1,2.08,39.04],[2,2,195.17]],"ltp":0.0,"tv":0.0,"id":8173434}]}]}
{"op":"mcm","clk":"996642319","pt":1580563096370,"mc":[{"id":"1.168186837","rc":[{"batb":[[0,2.08,39.04],[1,2,195.17],[2,1.93,51.29]],"ltp":0.0,"tv":0.0,"id":8173434}]}]}
{"op":"mcm","clk":"996642791","pt":1580563098656,"mc":[{"id":"1.168186837","rc":[{"batb":[[2,1.61,213.5]],"ltp":1.84,"tv":822.68,"id":8639275},{"batb":[[2,1.71,213.5]],"ltp":0.0,"tv":0.0,"id":8173434}]}]}
{"op":"mcm","clk":"996642914","pt":1580563099278,"mc":[{"id":"1.168186837","rc":[{"batb":[[2,1.63,75.72]],"ltp":1.84,"tv":822.68,"id":8639275},{"batb":[[0,2.08,88.85],[2,1.91,52.42]],"ltp":0.0,"tv":0.0,"id":8173434}]}]}
{"op":"mcm","clk":"996686340","pt":1580563307223,"mc":[{"id":"1.168186837","rc":[{"batb":[[1,1.91,52.42],[2,1.71,213.5]],"ltp":0.0,"tv":0.0,"id":8173434}]}]}
{"op":"mcm","clk":"996858697","pt":1580564102364,"mc":[{"id":"1.168186837","rc":[{"batb":[[0,2.08,128.35]],"ltp":0.0,"tv":0.0,"id":8173434}]}]}
{"op":"mcm","clk":"996859517","pt":1580564106587,"mc":[{"id":"1.168186837","rc":[{"batb":[[2,1.65,131.64]],"ltp":1.84,"tv":822.68,"id":8639275},{"batb":[[1,1.94,91.03]],"ltp":0.0,"tv":0.0,"id":8173434}]}]}
{"op":"mcm","clk":"996940498","pt":1580564446364,"mc":[{"id":"1.168186837","rc":[{"trd":[[1.84,81.53]],"batb":[[0,1.84,85.21]],"ltp":1.84,"tv":849.56,"id":8639275}],"tv":849.56}]}
{"op":"mcm","clk":"997157518","pt":1580565650569,"mc":[{"id":"1.168186837","rc":[{"batb":[[1,2.06,56.79],[2,1.94,91.03]],"ltp":0.0,"tv":0.0,"id":8173434}]}]}
{"op":"mcm","clk":"997157570","pt":1580565650858,"mc":[{"id":"1.168186837","rc":[{"batb":[[2,1.72,66.64]],"ltp":1.84,"tv":849.56,"id":8639275}]}]}
{"op":"mcm","clk":"997372741","pt":1580566572855,"mc":[{"id":"1.168186837","rc":[{"batl":[[0,95,15.9],[1,990,3.71],[2,1000,0.02]],"ltp":1.84,"tv":849.56,"id":8639275}]}]}
{"op":"mcm","clk":"997379969","pt":1580566602115,"mc":[{"id":"1.168186837","rc":[{"batl":[[0,11.5,3.36],[1,95,15.9],[2,990,3.71]],"ltp":1.84,"tv":849.56,"id":8639275}]}]}
{"op":"mcm","clk":"997405090","pt":1580566699628,"mc":[{"id":"1.168186837","rc":[{"batb":[[0,2.08,39.04]],"ltp":0.0,"tv":0.0,"id":8173434}]}]}
{"op":"mcm","clk":"997405153","pt":1580566699918,"mc":[{"id":"1.168186837","rc":[{"batb":[[0,2.08,128.85]],"ltp":0.0,"tv":0.0,"id":8173434}]}]}
{"op":"mcm","clk":"997501023","pt":1580567075798,"mc":[{"id":"1.168186837","rc":[{"batl":[[0,1.92,8.49],[1,11.5,3.36],[2,95,15.9]],"ltp":1.84,"tv":849.56,"id":8639275}]}]}
{"op":"mcm","clk":"997501372","pt":1580567077026,"mc":[{"id":"1.168186837","rc":[{"batb":[[0,2.08,39.04]],"ltp":0.0,"tv":0.0,"id":8173434}]}]}
{"op":"mcm","clk":"997501741","pt":1580567078184,"mc":[{"id":"1.168186837","rc":[{"batl":[[0,11.5,3.36],[1,95,15.9],[2,990,3.71]],"ltp":1.84,"tv":849.56,"id":8639275}]}]}
{"op":"mcm","clk":"997534240","pt":1580567209196,"mc":[{"id":"1.168186837","rc":[{"batb":[[0,2.08,128.85]],"ltp":0.0,"tv":0.0,"id":8173434}]}]}
{"op":"mcm","clk":"997559880","pt":1580567315420,"mc":[{"id":"1.168186837","rc":[{"batl":[[0,1.92,8.49],[1,11.5,3.36],[2,95,15.9]],"ltp":1.84,"tv":849.56,"id":8639275}]}]}
{"op":"mcm","clk":"997578923","pt":1580567395524,"mc":[{"id":"1.168186837","rc":[{"batl":[[1,95,15.9],[2,990,3.71]],"ltp":1.84,"tv":849.56,"id":8639275},{"batb":[[0,2.08,39.04]],"ltp":0.0,"tv":0.0,"id":8173434}]}]}
{"op":"mcm","clk":"997579098","pt":1580567396287,"mc":[{"id":"1.168186837","rc":[{"batl":[[0,95,15.9],[1,990,3.71],[2,1000,0.02]],"ltp":1.84,"tv":849.56,"id":8639275}]}]}
{"op":"mcm","clk":"997582502","pt":1580567408943,"mc":[{"id":"1.168186837","rc":[{"batb":[[0,2.08,128.85]],"ltp":0.0,"tv":0.0,"id":8173434}]}]}
{"op":"mcm","clk":"997607246","pt":1580567512770,"mc":[{"id":"1.168186837","rc":[{"batl":[[0,11.5,3.36],[1,95,15.9],[2,990,3.71]],"ltp":1.84,"tv":849.56,"id":8639275}]}]}
{"op":"mcm","clk":"997617624","pt":1580567553999,"mc":[{"id":"1.168186837","rc":[{"trd":[[1.84,84.89]],"batb":[[0,1.84,83.53]],"ltp":1.84,"tv":852.92,"id":8639275}],"tv":852.92}]}
{"op":"mcm","clk":"997618248","pt":1580567556322,"mc":[{"id":"1.168186837","rc":[{"batl":[[0,1.92,8.53],[1,11.5,3.36],[2,95,15.9]],"ltp":1.84,"tv":852.92,"id":8639275}]}]}
{"op":"mcm","clk":"997636276","pt":1580567627478,"mc":[{"id":"1.168186837","rc":[{"batl":[[1,95,15.9],[2,990,3.71]],"ltp":1.84,"tv":852.92,"id":8639275}]}]}
{"op":"mcm","clk":"997636333","pt":1580567627728,"mc":[{"id":"1.168186837","rc":[{"batb":[[0,2.08,39.04]],"ltp":0.0,"tv":0.0,"id":8173434}]}]}
{"op":"mcm","clk":"997636981","pt":1580567630235,"mc":[{"id":"1.168186837","rc":[{"batl":[[0,95,15.9],[1,990,3.71],[2,1000,0.02]],"ltp":1.84,"tv":852.92,"id":8639275}]}]}
{"op":"mcm","clk":"997651605","pt":1580567687427,"mc":[{"id":"1.168186837","rc":[{"batb":[[1,1.8,2],[2,1.76,47.03]],"ltp":1.84,"tv":852.92,"id":8639275}]}]}
{"op":"mcm","clk":"997651734","pt":1580567687917,"mc":[{"id":"1.168186837","rc":[{"batb":[[0,2.08,128.85]],"ltp":0.0,"tv":0.0,"id":8173434}]}]}
{"op":"mcm","clk":"997653412","pt":1580567694548,"mc":[{"id":"1.168186837","rc":[{"batl":[[0,1.96,2],[1,95,15.9],[2,990,3.71]],"ltp":1.84,"tv":852.92,"id":8639275}]}]}
{"op":"mcm","clk":"997663900","pt":1580567735421,"mc":[{"id":"1.168186837","rc":[{"batl":[[0,1.92,8.53],[1,1.96,2],[2,95,15.9]],"ltp":1.84,"tv":852.92,"id":8639275}]}]}
{"op":"mcm","clk":"997869378","pt":1580568572662,"mc":[{"id":"1.168186837","rc":[{"batb":[[0,1.86,2.27],[1,1.84,83.53],[2,1.8,2]],"ltp":1.84,"tv":852.92,"id":8639275}]}]}
{"op":"mcm","clk":"997869625","pt":1580568573755,"mc":[{"id":"1.168186837","rc":[{"batb":[[0,2.08,39.04]],"ltp":0.0,"tv":0.0,"id":8173434}]}]}
{"op":"mcm","clk":"997869860","pt":1580568574707,"mc":[{"id":"1.168186837","rc":[{"batl":[[0,1.96,2],[1,95,15.9],[2,990,3.71]],"ltp":1.84,"tv":852.92,"id":8639275}]}]}
{"op":"mcm","clk":"997870364","pt":1580568576974,"mc":[{"id":"1.168186837","rc":[{"batl":[[0,1.92,3.79],[1,1.96,2],[2,95,15.9]],"ltp":1.84,"tv":852.92,"id":8639275}]}]}
{"op":"mcm","clk":"997879330","pt":1580568616692,"mc":[{"id":"1.168186837","rc":[{"trd":[[1.86,625.48]],"batb":[[0,1.84,83.53],[1,1.8,2],[2,1.72,66.64]],"ltp":1.86,"tv":857.46,"id":8639275},{"batb":[[0,2.08,37.06]],"ltp":0.0,"tv":0.0,"id":8173434}],"tv":857.46}]}
{"op":"mcm","clk":"997879350","pt":1580568616830,"mc":[{"id":"1.168186837","rc":[{"batb":[[2,1.77,43.02]],"ltp":1.86,"tv":857.46,"id":8639275}]}]}
{"op":"mcm","clk":"997892736","pt":1580568677377,"mc":[{"id":"1.168186837","rc":[{"batl":[[0,1.9,2.27],[1,1.92,3.79],[2,1.96,2]],"ltp":1.86,"tv":857.46,"id":8639275}]}]}
{"op":"mcm","clk":"997940294","pt":1580568897430,"mc":[{"id":"1.168186837","rc":[{"batl":[[0,1.87,3.79],[1,1.9,2.27],[2,1.92,3.79]],"ltp":1.86,"tv":857.46,"id":8639275}]}]}
{"op":"mcm","clk":"997958805","pt":1580568978664,"mc":[{"id":"1.168186837","rc":[{"batl":[[0,1.86,2.27],[1,1.87,3.79]],"ltp":1.86,"tv":857.46,"id":8639275}]}]}
{"op":"mcm","clk":"998003955","pt":1580569177107,"mc":[{"id":"1.168186837","rc":[{"trd":[[1.86,627.75]],"batl":[[0,1.87,3.79],[1,1.92,3.79],[2,1.96,2]],"ltp":1.86,"tv":859.73,"id":8639275},{"trd":[[2.16,1.96]],"batl":[[0,2.16,86.65],[1,12.5,3.36],[2,95,15.9]],"ltp":2.16,"tv":1.95,"id":8173434}],"tv":861.69}]}
{"op":"mcm","clk":"998006457","pt":1580569187438,"mc":[{"id":"1.168186837","rc":[{"batl":[[1,95,15.9],[2,990,3.71]],"ltp":2.16,"tv":1.95,"id":8173434}]}]}
{"op":"mcm","clk":"998009335","pt":1580569199296,"mc":[{"id":"1.168186837","rc":[{"trd":[[2.16,18.56]],"batl":[[0,2.16,78.35]],"ltp":2.16,"tv":18.55,"id":8173434}],"tv":878.29}]}
{"op":"mcm","clk":"998009622","pt":1580569200633,"mc":[{"id":"1.168186837","rc":[{"batb":[[2,1.72,66.64]],"ltp":1.86,"tv":859.73,"id":8639275}]}]}
{"op":"mcm","clk":"998009829","pt":1580569201288,"mc":[{"id":"1.168186837","rc":[{"batb":[[2,1.78,46.67]],"ltp":1.86,"tv":859.73,"id":8639275},{"batb":[[0,2.08,28.63]],"ltp":2.16,"tv":18.55,"id":8173434}]}]}
{"op":"mcm","clk":"998092200","pt":1580569535479,"mc":[{"id":"1.168186837","rc":[{"batl":[[0,1.92,3.79],[1,1.96,2],[2,95,15.9]],"ltp":1.86,"tv":859.73,"id":8639275}]}]}
{"op":"mcm","clk":"998184632","pt":1580569876760,"mc":[{"id":"1.168186837","rc":[{"batl":[[0,1.96,2],[1,95,15.9],[2,990,3.71]],"ltp":1.86,"tv":859.73,"id":8639275}]}]}
{"op":"mcm","clk":"998210565","pt":1580569976258,"mc":[{"id":"1.168186837","rc":[{"batb":[[0,2.08,118.44]],"ltp":2.16,"tv":18.55,"id":8173434}]}]}
{"op":"mcm","clk":"998283670","pt":1580570255618,"mc":[{"id":"1.168186837","rc":[{"batl":[[0,1.92,8.6],[1,1.96,2],[2,95,15.9]],"ltp":1.86,"tv":859.73,"id":8639275}]}]}
{"op":"mcm","clk":"998317143","pt":1580570390879,"mc":[{"id":"1.168186837","rc":[{"batb":[[0,2.08,28.63]],"ltp":2.16,"tv":18.55,"id":8173434}]}]}
{"op":"mcm","clk":"998317555","pt":1580570392587,"mc":[{"id":"1.168186837","rc":[{"batl":[[0,1.96,2],[1,95,15.9],[2,990,3.71]],"ltp":1.86,"tv":859.73,"id":8639275}]}]}
{"op":"mcm","clk":"998355497","pt":1580570538959,"mc":[{"id":"1.168186837","rc":[{"batb":[[0,2.08,118.44]],"ltp":2.16,"tv":18.55,"id":8173434}]}]}
{"op":"mcm","clk":"998359846","pt":1580570555481,"mc":[{"id":"1.168186837","rc":[{"batl":[[0,1.92,8.6],[1,1.96,2],[2,95,15.9]],"ltp":1.86,"tv":859.73,"id":8639275}]}]}
{"op":"mcm","clk":"998368174","pt":1580570586512,"mc":[{"id":"1.168186837","rc":[{"batb":[[0,2.08,28.63]],"ltp":2.16,"tv":18.55,"id":8173434}]}]}
{"op":"mcm","clk":"998368783","pt":1580570588810,"mc":[{"id":"1.168186837","rc":[{"batl":[[0,1.96,2],[1,95,15.9],[2,990,3.71]],"ltp":1.86,"tv":859.73,"id":8639275}]}]}
{"op":"mcm","clk":"998422747","pt":1580570788985,"mc":[{"id":"1.168186837","rc":[{"batb":[[0,2.08,118.44]],"ltp":2.16,"tv":18.55,"id":8173434}]}]}
{"op":"mcm","clk":"998440694","pt":1580570856170,"mc":[{"id":"1.168186837","rc":[{"batl":[[0,1.92,8.6],[1,1.96,2],[2,95,15.9]],"ltp":1.86,"tv":859.73,"id":8639275}]}]}
{"op":"mcm","clk":"998477404","pt":1580570992876,"mc":[{"id":"1.168186837","rc":[{"batb":[[0,2.08,28.63]],"ltp":2.16,"tv":18.55,"id":8173434}]}]}
{"op":"mcm","clk":"998478206","pt":1580570996145,"mc":[{"id":"1.168186837","rc":[{"batl":[[0,1.96,2],[1,95,15.9],[2,990,3.71]],"ltp":1.86,"tv":859.73,"id":8639275}]}]}
{"op":"mcm","clk":"998487329","pt":1580571029649,"mc":[{"id":"1.168186837","rc":[{"batb":[[0,2.08,153.19]],"ltp":2.16,"tv":18.55,"id":8173434}]}]}
{"op":"mcm","clk":"998487835","pt":1580571031530,"mc":[{"id":"1.168186837","rc":[{"batb":[[2,1.99,119.32]],"ltp":2.16,"tv":18.55,"id":8173434}]}]}
{"op":"mcm","clk":"998522617","pt":1580571155707,"mc":[{"id":"1.168186837","rc":[{"batl":[[0,1.92,8.6],[1,1.96,2],[2,95,15.9]],"ltp":1.86,"tv":859.73,"id":8639275}]}]}
{"op":"mcm","clk":"998535420","pt":1580571200818,"mc":[{"id":"1.168186837","rc":[{"batb":[[0,2.08,28.63]],"ltp":2.16,"tv":18.55,"id":8173434}]}]}
{"op":"mcm","clk":"998536518","pt":1580571204797,"mc":[{"id":"1.168186837","rc":[{"batl":[[0,1.96,2],[1,95,15.9],[2,990,3.71]],"ltp":1.86,"tv":859.73,"id":8639275}]}]}
{"op":"mcm","clk":"998820949","pt":1580572315920,"mc":[{"id":"1.168186837","rc":[{"batb":[[0,2.08,153.19]],"ltp":2.16,"tv":18.55,"id":8173434}]}]}
{"op":"mcm","clk":"998821204","pt":1580572317209,"mc":[{"id":"1.168186837","rc":[{"batl":[[0,1.92,8.6],[1,1.96,2],[2,95,15.9]],"ltp":1.86,"tv":859.73,"id":8639275}]}]}
{"op":"mcm","clk":"998822194","pt":1580572321515,"mc":[{"id":"1.168186837","rc":[{"batb":[[0,2.08,28.63]],"ltp":2.16,"tv":18.55,"id":8173434}]}]}
{"op":"mcm","clk":"998822361","pt":1580572322216,"mc":[{"id":"1.168186837","rc":[{"batl":[[0,1.96,2],[1,95,15.9],[2,990,3.71]],"ltp":1.86,"tv":859.73,"id":8639275}]}]}
{"op":"mcm","clk":"998822568","pt":1580572323199,"mc":[{"id":"1.168186837","rc":[{"batb":[[0,2.08,153.19]],"ltp":2.16,"tv":18.55,"id":8173434}]}]}
{"op":"mcm","clk":"998848166","pt":1580572459968,"mc":[{"id":"1.168186837","rc":[{"batl":[[0,1.92,8.6],[1,1.96,2],[2,95,15.9]],"ltp":1.86,"tv":859.73,"id":8639275}]}]}
{"op":"mcm","clk":"998853440","pt":1580572488615,"mc":[{"id":"1.168186837","rc":[{"batl":[[0,1.91,3.79],[1,1.92,8.6],[2,1.96,2]],"ltp":1.86,"tv":859.73,"id":8639275},{"batb":[[0,2.08,28.63]],"ltp":2.16,"tv":18.55,"id":8173434}]}]}
{"op":"mcm","clk":"998853557","pt":1580572489305,"mc":[{"id":"1.168186837","rc":[{"batl":[[1,1.96,2],[2,95,15.9]],"ltp":1.86,"tv":859.73,"id":8639275}]}]}
{"op":"mcm","clk":"998854339","pt":1580572493404,"mc":[{"id":"1.168186837","rc":[{"batl":[[0,1.92,3.79]],"ltp":1.86,"tv":859.73,"id":8639275}]}]}
{"op":"mcm","clk":"998996034","pt":1580573156797,"mc":[{"id":"1.168186837","rc":[{"batl":[[0,1.92,7.57]],"ltp":1.86,"tv":859.73,"id":8639275}]}]}
{"op":"mcm","clk":"998996983","pt":1580573160431,"mc":[{"id":"1.168186837","rc":[{"batl":[[0,1.96,2],[1,95,15.9],[2,990,3.71]],"ltp":1.86,"tv":859.73,"id":8639275}]}]}
{"op":"mcm","clk":"998997092","pt":1580573160792,"mc":[{"id":"1.168186837","rc":[{"batl":[[0,1.92,3.79],[1,1.96,2],[2,95,15.9]],"ltp":1.86,"tv":859.73,"id":8639275}]}]}
{"op":"mcm","clk":"999042662","pt":1580573332524,"mc":[{"id":"1.168186837","rc":[{"batl":[[0,1.92,7.57]],"ltp":1.86,"tv":859.73,"id":8639275}]}]}
{"op":"mcm","clk":"999975899","pt":1580577910842,"mc":[{"id":"1.168186837","rc":[{"batl":[[0,1.96,2],[1,95,15.9],[2,990,3.71]],"ltp":1.86,"tv":859.73,"id":8639275}]}]}
{"op":"mcm","clk":"999977991","pt":1580577923629,"mc":[{"id":"1.168186837","rc":[{"batl":[[0,1.92,3.79],[1,1.96,2],[2,95,15.9]],"ltp":1.86,"tv":859.73,"id":8639275}]}]}
{"op":"mcm","clk":"999978037","pt":1580577924047,"mc":[{"id":"1.168186837","rc":[{"batb":[[0,2.08,153.19]],"ltp":2.16,"tv":18.55,"id":8173434}]}]}
{"op":"mcm","clk":"999978270","pt":1580577925544,"mc":[{"id":"1.168186837","rc":[{"batl":[[0,1.92,12.38]],"ltp":1.86,"tv":859.73,"id":8639275},{"batb":[[0,2.08,28.63]],"ltp":2.16,"tv":18.55,"id":8173434}]}]}
{"op":"mcm","clk":"999978418","pt":1580577926651,"mc":[{"id":"1.168186837","rc":[{"batl":[[0,1.92,3.79]],"ltp":1.86,"tv":859.73,"id":8639275}]}]}
{"op":"mcm","clk":"1000162487","pt":1580579056363,"mc":[{"id":"1.168186837","rc":[{"batb":[[1,1.8,6.2]],"batl":[[0,1.92,7.99]],"ltp":1.86,"tv":859.73,"id":8639275},{"batb":[[0,2.08,32.83]],"batl":[[1,2.18,4.2],[2,95,15.9]],"ltp":2.16,"tv":18.55,"id":8173434}]}]}
{"op":"mcm","clk":"1000168533","pt":1580579096588,"mc":[{"id":"1.168186837","rc":[{"batb":[[2,1.72,66.64]],"ltp":1.86,"tv":859.73,"id":8639275}]}]}
{"op":"mcm","clk":"1000168569","pt":1580579096798,"mc":[{"id":"1.168186837","rc":[{"batb":[[1,1.81,28.68],[2,1.8,6.2]],"ltp":1.86,"tv":859.73,"id":8639275}]}]}
{"op":"mcm","clk":"1000280139","pt":1580579888816,"mc":[{"id":"1.168186837","rc":[{"batl":[[0,1.92,11.77]],"ltp":1.86,"tv":859.73,"id":8639275}]}]}
{"op":"mcm","clk":"1000289655","pt":1580579961874,"mc":[{"id":"1.168186837","rc":[{"batb":[[0,1.84,87.73],[2,1.8,2]],"ltp":1.86,"tv":859.73,"id":8639275}]}]}
{"op":"mcm","clk":"1000297464","pt":1580580017136,"mc":[{"id":"1.168186837","rc":[{"batb":[[1,1.8,2],[2,1.72,66.64]],"ltp":1.86,"tv":859.73,"id":8639275}]}]}
{"op":"mcm","clk":"1000297504","pt":1580580018060,"mc":[{"id":"1.168186837","rc":[{"batb":[[2,1.78,46.67]],"ltp":1.86,"tv":859.73,"id":8639275}]}]}
{"op":"mcm","clk":"1000346242","pt":1580580360400,"mc":[{"id":"1.168186837","rc":[{"batb":[[1,2,56.79]],"ltp":2.16,"tv":18.55,"id":8173434}]}]}
{"op":"mcm","clk":"1000353131","pt":1580580407115,"mc":[{"id":"1.168186837","rc":[{"batb":[[1,2.06,56.79]],"ltp":2.16,"tv":18.55,"id":8173434}]}]}
{"op":"mcm","clk":"1000427619","pt":1580580884206,"mc":[{"id":"1.168186837","rc":[{"batl":[[0,1.92,19.35]],"ltp":1.86,"tv":859.73,"id":8639275}]}]}
{"op":"mcm","clk":"1000428059","pt":1580580887213,"mc":[{"id":"1.168186837","rc":[{"batl":[[0,1.92,4.2]],"ltp":1.86,"tv":859.73,"id":8639275}]}]}
{"op":"mcm","clk":"1000591497","pt":1580582042674,"mc":[{"id":"1.168186837","rc":[{"batb":[[2,1.99,182.04]],"ltp":2.16,"tv":18.55,"id":8173434}]}]}
{"op":"mcm","clk":"1000629055","pt":1580582273175,"mc":[{"id":"1.168186837","rc":[{"batb":[[0,1.84,83.53]],"batl":[[0,1.96,2],[1,95,15.9],[2,990,2.2]],"ltp":1.86,"tv":859.73,"id":8639275},{"batb":[[0,2.08,28.63]],"batl":[[1,95,15.9],[2,990,2.2]],"ltp":2.16,"tv":18.55,"id":8173434}]}]}
{"op":"mcm","clk":"1000773765","pt":1580583125415,"mc":[{"id":"1.168186837","rc":[{"batb":[[0,2.08,218.19]],"ltp":2.16,"tv":18.55,"id":8173434}]}]}
{"op":"mcm","clk":"1000773854","pt":1580583125892,"mc":[{"id":"1.168186837","rc":[{"batl":[[0,1.92,8.6],[1,1.96,2],[2,95,15.9]],"ltp":1.86,"tv":859.73,"id":8639275}]}]}
{"op":"mcm","clk":"1000923219","pt":1580583972709,"mc":[{"id":"1.168186837","rc":[{"batb":[[0,2.08,28.63]],"ltp":2.16,"tv":18.55,"id":8173434}]}]}
{"op":"mcm","clk":"1000923468","pt":1580583973820,"mc":[{"id":"1.168186837","rc":[{"batl":[[0,1.96,2],[1,95,15.9],[2,990,2.2]],"ltp":1.86,"tv":859.73,"id":8639275}]}]}
{"op":"mcm","clk":"1000961266","pt":1580584156584,"mc":[{"id":"1.168186837","rc":[{"batl":[[0,1.92,8.6],[1,1.96,2],[2,95,15.9]],"ltp":1.86,"tv":859.73,"id":8639275},{"batb":[[0,2.08,218.19]],"ltp":2.16,"tv":18.55,"id":8173434}]}]}
{"op":"mcm","clk":"1000961817","pt":1580584159191,"mc":[{"id":"1.168186837","rc":[{"batb":[[0,2.08,28.63]],"ltp":2.16,"tv":18.55,"id":8173434}]}]}
{"op":"mcm","clk":"1000962128","pt":1580584160400,"mc":[{"id":"1.168186837","rc":[{"batl":[[0,1.96,2],[1,95,15.9],[2,990,2.2]],"ltp":1.86,"tv":859.73,"id":8639275}]}]}
{"op":"mcm","clk":"1000963347","pt":1580584165985,"mc":[{"id":"1.168186837","rc":[{"batb":[[0,2.08,218.19]],"ltp":2.16,"tv":18.55,"id":8173434}]}]}
{"op":"mcm","clk":"1000968658","pt":1580584191737,"mc":[{"id":"1.168186837","rc":[{"batl":[[0,1.92,8.6],[1,1.96,2],[2,95,15.9]],"ltp":1.86,"tv":859.73,"id":8639275}]}]}
{"op":"mcm","clk":"1000973500","pt":1580584214281,"mc":[{"id":"1.168186837","rc":[{"batb":[[0,2.08,28.63]],"ltp":2.16,"tv":18.55,"id":8173434}]}]}
{"op":"mcm","clk":"1000973924","pt":1580584216114,"mc":[{"id":"1.168186837","rc":[{"batl":[[0,1.96,2],[1,95,15.9],[2,990,2.2]],"ltp":1.86,"tv":859.73,"id":8639275}]}]}
{"op":"mcm","clk":"1000974114","pt":1580584216997,"mc":[{"id":"1.168186837","rc":[{"batb":[[0,2.08,218.19]],"ltp":2.16,"tv":18.55,"id":8173434}]}]}
{"op":"mcm","clk":"1000976184","pt":1580584226816,"mc":[{"id":"1.168186837","rc":[{"batl":[[0,1.92,8.6],[1,1.96,2],[2,95,15.9]],"ltp":1.86,"tv":859.73,"id":8639275}]}]}
{"op":"mcm","clk":"1001008882","pt":1580584390200,"mc":[{"id":"1.168186837","rc":[{"batb":[[0,2.08,28.63]],"ltp":2.16,"tv":18.55,"id":8173434}]}]}
{"op":"mcm","clk":"1001009020","pt":1580584391020,"mc":[{"id":"1.168186837","rc":[{"batl":[[0,1.96,2],[1,95,15.9],[2,990,2.2]],"ltp":1.86,"tv":859.73,"id":8639275}]}]}
{"op":"mcm","clk":"1001020755","pt":1580584455616,"mc":[{"id":"1.168186837","rc":[{"batl":[[0,1.92,8.6],[1,1.96,2],[2,95,15.9]],"ltp":1.86,"tv":859.73,"id":8639275},{"batb":[[0,2.08,218.19]],"ltp":2.16,"tv":18.55,"id":8173434}]}]}
{"op":"mcm","clk":"1001024082","pt":1580584473449,"mc":[{"id":"1.168186837","rc":[{"batb":[[1,2,56.79]],"ltp":2.16,"tv":18.55,"id":8173434}]}]}
{"op":"mcm","clk":"1001024579","pt":1580584476183,"mc":[{"id":"1.168186837","rc":[{"batb":[[0,2.08,28.63]],"ltp":2.16,"tv":18.55,"id":8173434}]}]}
{"op":"mcm","clk":"1001024834","pt":1580584477573,"mc":[{"id":"1.168186837","rc":[{"batl":[[0,1.96,2],[1,95,15.9],[2,990,2.2]],"ltp":1.86,"tv":859.73,"id":8639275},{"batb":[[0,2.08,218.19]],"ltp":2.16,"tv":18.55,"id":8173434}]}]}
{"op":"mcm","clk":"1001029355","pt":1580584501224,"mc":[{"id":"1.168186837","rc":[{"batl":[[0,1.92,8.58],[1,1.96,2],[2,95,15.9]],"ltp":1.86,"tv":859.73,"id":8639275}]}]}
{"op":"mcm","clk":"1001031883","pt":1580584514653,"mc":[{"id":"1.168186837","rc":[{"batb":[[0,2.08,28.63],[1,2.06,56.79]],"ltp":2.16,"tv":18.55,"id":8173434}]}]}
{"op":"mcm","clk":"1001032153","pt":1580584516127,"mc":[{"id":"1.168186837","rc":[{"batl":[[0,1.96,2],[1,95,15.9],[2,990,2.2]],"ltp":1.86,"tv":859.73,"id":8639275}]}]}
{"op":"mcm","clk":"1001033143","pt":1580584521174,"mc":[{"id":"1.168186837","rc":[{"batb":[[0,2.08,218.19]],"ltp":2.16,"tv":18.55,"id":8173434}]}]}
{"op":"mcm","clk":"1001038636","pt":1580584550716,"mc":[{"id":"1.168186837","rc":[{"batl":[[0,1.92,8.51],[1,1.96,2],[2,95,15.9]],"ltp":1.86,"tv":859.73,"id":8639275}]}]}
{"op":"mcm","clk":"1001066571","pt":1580584695341,"mc":[{"id":"1.168186837","rc":[{"batb":[[0,2.08,28.63]],"ltp":2.16,"tv":18.55,"id":8173434}]}]}
{"op":"mcm","clk":"1001066772","pt":1580584696547,"mc":[{"id":"1.168186837","rc":[{"batl":[[0,1.96,2],[1,95,15.9],[2,990,2.2]],"ltp":1.86,"tv":859.73,"id":8639275}]}]}
{"op":"mcm","clk":"1001110452","pt":1580584935575,"mc":[{"id":"1.168186837","rc":[{"batb":[[0,2.08,218.19]],"ltp":2.16,"tv":18.55,"id":8173434}]}]}
{"op":"mcm","clk":"1001110621","pt":1580584936451,"mc":[{"id":"1.168186837","rc":[{"batl":[[0,1.92,8.6],[1,1.96,2],[2,95,15.9]],"ltp":1.86,"tv":859.73,"id":8639275}]}]}
{"op":"mcm","clk":"1001118237","pt":1580584978278,"mc":[{"id":"1.168186837","rc":[{"batb":[[0,2.08,28.63]],"batl":[[0,95,15.9],[1,990,2.2],[2,1000,0.02]],"ltp":2.16,"tv":18.55,"id":8173434}]}]}
{"op":"mcm","clk":"1001118359","pt":1580584978971,"mc":[{"id":"1.168186837","rc":[{"batl":[[0,1.96,2],[1,95,15.9],[2,990,2.2]],"ltp":1.86,"tv":859.73,"id":8639275}]}]}
{"op":"mcm","clk":"1001119694","pt":1580584985544,"mc":[{"id":"1.168186837","rc":[{"trd":[[2.08,147.29]],"batb":[[0,2.06,56.79],[1,1.99,182.04],[2,1.77,59]],"ltp":2.08,"tv":165.85,"id":8173434}],"tv":1025.59}]}
{"op":"mcm","clk":"1001119866","pt":1580584986466,"mc":[{"id":"1.168186837","rc":[{"batb":[[0,1.85,22.29],[1,1.84,83.53],[2,1.8,2]],"ltp":1.86,"tv":859.73,"id":8639275},{"batb":[[0,2.08,204.11],[1,2.06,56.79],[2,1.99,182.04]],"ltp":2.08,"tv":165.85,"id":8173434}]}]}
{"op":"mcm","clk":"1001121150","pt":1580584992846,"mc":[{"id":"1.168186837","rc":[{"batb":[[0,2.08,14.55]],"ltp":2.08,"tv":165.85,"id":8173434}]}]}
{"op":"mcm","clk":"1001121593","pt":1580584995078,"mc":[{"id":"1.168186837","rc":[{"batb":[[2,1.92,127.19]],"ltp":2.08,"tv":165.85,"id":8173434}]}]}
{"op":"mcm","clk":"1001121841","pt":1580584996376,"mc":[{"id":"1.168186837","rc":[{"batb":[[2,1.97,185.79]],"ltp":2.08,"tv":165.85,"id":8173434}]}]}
{"op":"mcm","clk":"1001122529","pt":1580584999892,"mc":[{"id":"1.168186837","rc":[{"batb":[[1,2.04,56.79]],"ltp":2.08,"tv":165.85,"id":8173434}]}]}
{"op":"mcm","clk":"1001125398","pt":1580585014215,"mc":[{"id":"1.168186837","rc":[{"batb":[[2,1.92,127.19]],"ltp":2.08,"tv":165.85,"id":8173434}]}]}
{"op":"mcm","clk":"1001125684","pt":1580585015536,"mc":[{"id":"1.168186837","rc":[{"batb":[[2,1.95,189.71]],"ltp":2.08,"tv":165.85,"id":8173434}]}]}
{"op":"mcm","clk":"1001125920","pt":1580585016681,"mc":[{"id":"1.168186837","rc":[{"batb":[[1,1.95,189.71],[2,1.92,127.19]],"ltp":2.08,"tv":165.85,"id":8173434}]}]}
{"op":"mcm","clk":"1001125940","pt":1580585016788,"mc":[{"id":"1.168186837","rc":[{"batb":[[1,2.04,56.79],[2,1.95,189.71]],"ltp":2.08,"tv":165.85,"id":8173434}]}]}
{"op":"mcm","clk":"1001126269","pt":1580585018407,"mc":[{"id":"1.168186837","rc":[{"batb":[[1,1.93,193.78],[2,1.92,127.19]],"ltp":2.08,"tv":165.85,"id":8173434}]}]}
{"op":"mcm","clk":"1001127450","pt":1580585024320,"mc":[{"id":"1.168186837","rc":[{"batb":[[1,1.99,57.55],[2,1.95,127.19]],"batl":[[0,13.5,3.36],[1,95,15.9],[2,990,2.2]],"ltp":2.08,"tv":165.85,"id":8173434}]}]}
{"op":"mcm","clk":"1001139345","pt":1580585083699,"mc":[{"id":"1.168186837","rc":[{"batb":[[0,2.02,38.38]],"ltp":2.08,"tv":165.85,"id":8173434}]}]}
{"op":"mcm","clk":"1001161092","pt":1580585191011,"mc":[{"id":"1.168186837","rc":[{"trd":[[1.96,2]],"batl":[[0,95,15.9],[1,990,2.2],[2,1000,0.02]],"ltp":1.96,"tv":861.73,"id":8639275},{"trd":[[2.04,3.38]],"ltp":2.04,"tv":169.23,"id":8173434}],"tv":1030.97}]}
{"op":"mcm","clk":"1001164650","pt":1580585208322,"mc":[{"id":"1.168186837","rc":[{"batl":[[0,11.5,3.36],[1,95,15.9],[2,990,2.2]],"ltp":1.96,"tv":861.73,"id":8639275}]}]}
{"op":"mcm","clk":"1001182477","pt":1580585297362,"mc":[{"id":"1.168186837","rc":[{"trd":[[2.02,76.74]],"batb":[[0,1.99,57.55],[1,1.95,127.19],[2,1.93,193.78]],"batl":[[0,2.02,5.84],[1,13.5,3.36],[2,95,15.9]],"ltp":2.02,"tv":245.97,"id":8173434}],"tv":1107.71}]}
{"op":"mcm","clk":"1001182669","pt":1580585298548,"mc":[{"id":"1.168186837","rc":[{"batl":[[0,2.04,8.62],[1,11.5,3.36],[2,95,15.9]],"ltp":1.96,"tv":861.73,"id":8639275},{"trd":[[2.02,88.22]],"batb":[[0,1.97,57.55],[1,1.96,8.85],[2,1.95,127.19]],"batl":[[0,13.5,3.47],[1,95,15.9],[2,990,2.2]],"ltp":2.02,"tv":257.45,"id":8173434}],"tv":1119.19}]}
{"op":"mcm","clk":"1001182821","pt":1580585299338,"mc":[{"id":"1.168186837","rc":[{"batb":[[0,1.87,44.44]],"ltp":1.96,"tv":861.73,"id":8639275},{"batb":[[0,1.98,216.77],[1,1.97,57.55]],"ltp":2.02,"tv":257.45,"id":8173434}]}]}
{"op":"mcm","clk":"1001184186","pt":1580585306551,"mc":[{"id":"1.168186837","rc":[{"batb":[[0,1.99,57.55],[1,1.98,216.77]],"ltp":2.02,"tv":257.45,"id":8173434}]}]}
{"op":"mcm","clk":"1001185129","pt":1580585311440,"mc":[{"id":"1.168186837","rc":[{"batb":[[0,2,189.92],[1,1.99,66.12],[2,1.98,25.01]],"batl":[[0,13.5,3.36]],"ltp":2.02,"tv":257.45,"id":8173434}]}]}
{"op":"mcm","clk":"1001185411","pt":1580585313258,"mc":[{"id":"1.168186837","rc":[{"batl":[[0,1.99,8.62]],"ltp":1.96,"tv":861.73,"id":8639275},{"batb":[[1,1.99,57.55]],"ltp":2.02,"tv":257.45,"id":8173434}]}]}
{"op":"mcm","clk":"1001187003","pt":1580585322281,"mc":[{"id":"1.168186837","rc":[{"batl":[[1,95,15.9],[2,990,2.2]],"ltp":1.96,"tv":861.73,"id":8639275},{"batb":[[0,1.99,57.55],[1,1.98,25.01],[2,1.95,127.19]],"ltp":2.02,"tv":257.45,"id":8173434}]}]}
{"op":"mcm","clk":"1001187211","pt":1580585323568,"mc":[{"id":"1.168186837","rc":[{"batl":[[0,95,15.9],[1,990,2.2],[2,1000,0.02]],"ltp":1.96,"tv":861.73,"id":8639275}]}]}
{"op":"mcm","clk":"1001194163","pt":1580585363406,"mc":[{"id":"1.168186837","rc":[{"batl":[[0,2.04,8.62],[1,95,15.9],[2,990,2.2]],"ltp":1.96,"tv":861.73,"id":8639275},{"batb":[[2,1.96,8.85]],"ltp":2.02,"tv":257.45,"id":8173434}]}]}
{"op":"mcm","clk":"1001194242","pt":1580585363891,"mc":[{"id":"1.168186837","rc":[{"batb":[[0,2,189.92],[1,1.99,57.55],[2,1.98,25.01]],"ltp":2.02,"tv":257.45,"id":8173434}]}]}
{"op":"mcm","clk":"1001194486","pt":1580585365221,"mc":[{"id":"1.168186837","rc":[{"batl":[[0,95,15.9],[1,990,2.2],[2,1000,0.02]],"ltp":1.96,"tv":861.73,"id":8639275}]}]}
{"op":"mcm","clk":"1001195199","pt":1580585368808,"mc":[{"id":"1.168186837","rc":[{"batb":[[0,1.88,25.81],[1,1.87,44.44],[2,1.84,83.53]],"ltp":1.96,"tv":861.73,"id":8639275},{"batb":[[0,2,206.3],[2,1.95,127.19]],"ltp":2.02,"tv":257.45,"id":8173434}]}]}
{"op":"mcm","clk":"1001196726","pt":1580585376924,"mc":[{"id":"1.168186837","rc":[{"batl":[[0,1.99,8.62],[1,95,15.9],[2,990,2.2]],"ltp":1.96,"tv":861.73,"id":8639275},{"batb":[[0,2.02,8.4],[1,2,206.3],[2,1.99,57.55]],"ltp":2.02,"tv":257.45,"id":8173434}]}]}
{"op":"mcm","clk":"1001204603","pt":1580585417201,"mc":[{"id":"1.168186837","rc":[{"batb":[[1,2,16.38]],"ltp":2.02,"tv":257.45,"id":8173434}]}]}
{"op":"mcm","clk":"1001204888","pt":1580585419284,"mc":[{"id":"1.168186837","rc":[{"batl":[[0,95,15.9],[1,990,2.2],[2,1000,0.02]],"ltp":1.96,"tv":861.73,"id":8639275},{"batb":[[0,2,16.38],[1,1.99,57.55],[2,1.95,127.19]],"ltp":2.02,"tv":257.45,"id":8173434}]}]}
{"op":"mcm","clk":"1001205305","pt":1580585421125,"mc":[{"id":"1.168186837","rc":[{"batb":[[0,2,206.3]],"ltp":2.02,"tv":257.45,"id":8173434}]}]}
{"op":"mcm","clk":"1001208375","pt":1580585436941,"mc":[{"id":"1.168186837","rc":[{"batl":[[0,11.5,3.36],[1,95,15.9],[2,990,2.2]],"ltp":1.96,"tv":861.73,"id":8639275}]}]}
{"op":"mcm","clk":"1001209299","pt":1580585441763,"mc":[{"id":"1.168186837","rc":[{"batl":[[0,1.99,8.62],[1,11.5,3.36],[2,95,15.9]],"ltp":1.96,"tv":861.73,"id":8639275},{"batb":[[0,2.02,8.4],[1,2,206.3],[2,1.99,57.55]],"ltp":2.02,"tv":257.45,"id":8173434}]}]}
{"op":"mcm","clk":"1001210858","pt":1580585449860,"mc":[{"id":"1.168186837","rc":[{"batb":[[1,2,16.38]],"ltp":2.02,"tv":257.45,"id":8173434}]}]}
{"op":"mcm","clk":"1001211076","pt":1580585451058,"mc":[{"id":"1.168186837","rc":[{"batl":[[0,11.5,3.36],[1,95,15.9],[2,990,2.2]],"ltp":1.96,"tv":861.73,"id":8639275},{"batb":[[0,2,16.38],[1,1.99,57.55],[2,1.95,127.19]],"ltp":2.02,"tv":257.45,"id":8173434}]}]}
{"op":"mcm","clk":"1001220303","pt":1580585503409,"mc":[{"id":"1.168186837","rc":[{"batb":[[0,1.89,34.07],[1,1.88,25.81]],"ltp":1.96,"tv":861.73,"id":8639275}]}]}
{"op":"mcm","clk":"1001220525","pt":1580585504634,"mc":[{"id":"1.168186837","rc":[{"trd":[[1.89,33.18]],"batb":[[0,1.89,17.48]],"ltp":1.89,"tv":894.92,"id":8639275},{"batb":[[0,2,221.75]],"ltp":2.02,"tv":257.45,"id":8173434}],"tv":1152.37}]}
{"op":"mcm","clk":"1001221372","pt":1580585508725,"mc":[{"id":"1.168186837","rc":[{"batl":[[0,1.99,8.95],[1,11.5,3.36],[2,95,15.9]],"ltp":1.89,"tv":894.92,"id":8639275},{"batb":[[0,2.02,8.4],[1,2,221.75],[2,1.99,57.55]],"ltp":2.02,"tv":257.45,"id":8173434}]}]}
{"op":"mcm","clk":"1001227243","pt":1580585540217,"mc":[{"id":"1.168186837","rc":[{"batb":[[1,2,31.83]],"ltp":2.02,"tv":257.45,"id":8173434}]}]}
{"op":"mcm","clk":"1001227618","pt":1580585542011,"mc":[{"id":"1.168186837","rc":[{"batl":[[0,11.5,3.36],[1,95,15.9],[2,990,2.2]],"ltp":1.89,"tv":894.92,"id":8639275},{"batb":[[0,2,31.83],[1,1.99,57.55],[2,1.95,127.19]],"ltp":2.02,"tv":257.45,"id":8173434}]}]}
{"op":"mcm","clk":"1001245331","pt":1580585630440,"mc":[{"id":"1.168186837","rc":[{"trd":[[2,17.69]],"batb":[[0,2,22.99]],"ltp":2.0,"tv":275.13,"id":8173434}],"tv":1170.06}]}
{"op":"mcm","clk":"1001245642","pt":1580585631942,"mc":[{"id":"1.168186837","rc":[{"batb":[[0,2,212.91]],"ltp":2.0,"tv":275.13,"id":8173434}]}]}
{"op":"mcm","clk":"1001245975","pt":1580585633661,"mc":[{"id":"1.168186837","rc":[{"batb":[[0,1.9,25.24],[1,1.89,26.96],[2,1.88,25.81]],"batl":[[0,1.99,8.95],[1,11.5,3.36],[2,95,15.9]],"ltp":1.89,"tv":894.92,"id":8639275},{"batb":[[0,2.02,8.4],[1,2,212.91],[2,1.99,57.55]],"ltp":2.0,"tv":275.13,"id":8173434}]}]}
{"op":"mcm","clk":"1001246134","pt":1580585634466,"mc":[{"id":"1.168186837","rc":[{"batb":[[2,1.84,83.53]],"ltp":1.89,"tv":894.92,"id":8639275},{"batb":[[1,2,22.99]],"ltp":2.0,"tv":275.13,"id":8173434}]}]}
{"op":"mcm","clk":"1001246270","pt":1580585635253,"mc":[{"id":"1.168186837","rc":[{"batl":[[0,11.5,3.36],[1,95,15.9],[2,990,2.2]],"ltp":1.89,"tv":894.92,"id":8639275},{"batb":[[0,2,22.99],[1,1.99,57.55],[2,1.95,127.19]],"ltp":2.0,"tv":275.13,"id":8173434}]}]}
{"op":"mcm","clk":"1001247271","pt":1580585640621,"mc":[{"id":"1.168186837","rc":[{"batb":[[1,1.84,83.53],[2,1.8,2]],"ltp":1.89,"tv":894.92,"id":8639275}]}]}
{"op":"mcm","clk":"1001247355","pt":1580585641023,"mc":[{"id":"1.168186837","rc":[{"batb":[[0,1.91,17.01],[1,1.9,25.24],[2,1.84,83.53]],"ltp":1.89,"tv":894.92,"id":8639275},{"batb":[[0,2,212.91]],"ltp":2.0,"tv":275.13,"id":8173434}]}]}
{"op":"mcm","clk":"1001247847","pt":1580585643324,"mc":[{"id":"1.168186837","rc":[{"batb":[[1,1.84,83.53],[2,1.8,2]],"ltp":1.89,"tv":894.92,"id":8639275}]}]}
{"op":"mcm","clk":"1001249038","pt":1580585649537,"mc":[{"id":"1.168186837","rc":[{"batl":[[0,1.99,22.72],[1,11.5,3.36],[2,95,15.9]],"ltp":1.89,"tv":894.92,"id":8639275}]}]}
{"op":"mcm","clk":"1001250564","pt":1580585657233,"mc":[{"id":"1.168186837","rc":[{"batb":[[0,2,22.99]],"ltp":2.0,"tv":275.13,"id":8173434}]}]}
{"op":"mcm","clk":"1001251876","pt":1580585664150,"mc":[{"id":"1.168186837","rc":[{"batl":[[0,2,22.72]],"ltp":1.89,"tv":894.92,"id":8639275}]}]}
{"op":"mcm","clk":"1001252229","pt":1580585665778,"mc":[{"id":"1.168186837","rc":[{"batl":[[1,95,15.9],[2,990,2.2]],"ltp":1.89,"tv":894.92,"id":8639275}]}]}
{"op":"mcm","clk":"1001265473","pt":1580585734581,"mc":[{"id":"1.168186837","rc":[{"batl":[[1,2.04,22.72],[2,95,15.9]],"ltp":1.89,"tv":894.92,"id":8639275}]}]}
{"op":"mcm","clk":"1001265788","pt":1580585736170,"mc":[{"id":"1.168186837","rc":[{"batl":[[1,95,15.9],[2,990,2.2]],"ltp":1.89,"tv":894.92,"id":8639275}]}]}
{"op":"mcm","clk":"1001272671","pt":1580585769898,"mc":[{"id":"1.168186837","rc":[{"batb":[[0,1.86,42.61]],"ltp":1.89,"tv":894.92,"id":8639275}]}]}
{"op":"mcm","clk":"1001317130","pt":1580585994338,"mc":[{"id":"1.168186837","rc":[{"trd":[[2,34.49]],"batb":[[0,2,14.59]],"ltp":2.0,"tv":291.94,"id":8173434}],"tv":1186.86}]}
{"op":"mcm","clk":"1001317284","pt":1580585995140,"mc":[{"id":"1.168186837","rc":[{"batb":[[0,1.88,40.84]],"ltp":1.89,"tv":894.92,"id":8639275}]}]}
{"op":"mcm","clk":"1001322838","pt":1580586021510,"mc":[{"id":"1.168186837","rc":[{"batb":[[0,2,204.51]],"ltp":2.0,"tv":291.94,"id":8173434}]}]}
{"op":"mcm","clk":"1001323056","pt":1580586022491,"mc":[{"id":"1.168186837","rc":[{"batl":[[0,1.99,8.95],[1,2,22.72],[2,95,15.9]],"ltp":1.89,"tv":894.92,"id":8639275},{"batb":[[0,2.02,8.4],[1,2,204.51],[2,1.99,57.55]],"ltp":2.0,"tv":291.94,"id":8173434}]}]}
{"op":"mcm","clk":"1001354168","pt":1580586181192,"mc":[{"id":"1.168186837","rc":[{"batb":[[1,2,14.59]],"ltp":2.0,"tv":291.94,"id":8173434}]}]}
{"op":"mcm","clk":"1001354297","pt":1580586181900,"mc":[{"id":"1.168186837","rc":[{"batl":[[0,2,22.72],[1,95,15.9],[2,990,2.2]],"ltp":1.89,"tv":894.92,"id":8639275},{"batb":[[0,2,14.59],[1,1.99,57.55],[2,1.93,193.78]],"ltp":2.0,"tv":291.94,"id":8173434}]}]}
{"op":"mcm","clk":"1001393381","pt":1580586407057,"mc":[{"id":"1.168186837","rc":[{"batb":[[0,2,204.51]],"ltp":2.0,"tv":291.94,"id":8173434}]}]}
{"op":"mcm","clk":"1001393573","pt":1580586408299,"mc":[{"id":"1.168186837","rc":[{"batl":[[0,1.99,8.95],[1,2,22.72],[2,95,15.9]],"ltp":1.89,"tv":894.92,"id":8639275},{"batb":[[0,2.02,8.4],[1,2,204.51],[2,1.99,57.55]],"ltp":2.0,"tv":291.94,"id":8173434}]}]}
{"op":"mcm","clk":"1001447256","pt":1580586743443,"mc":[{"id":"1.168186837","rc":[{"batb":[[1,2,14.59]],"ltp":2.0,"tv":291.94,"id":8173434}]}]}
{"op":"mcm","clk":"1001447377","pt":1580586744236,"mc":[{"id":"1.168186837","rc":[{"batl":[[0,2,22.72],[1,95,15.9],[2,990,2.2]],"ltp":1.89,"tv":894.92,"id":8639275},{"batb":[[0,2,14.59],[1,1.99,57.55],[2,1.93,193.78]],"ltp":2.0,"tv":291.94,"id":8173434}]}]}
{"op":"mcm","clk":"1001499741","pt":1580587063394,"mc":[{"id":"1.168186837","rc":[{"batb":[[0,2.04,184.62],[1,2,14.59],[2,1.99,57.55]],"ltp":2.0,"tv":291.94,"id":8173434}]}]}
{"op":"mcm","clk":"1001499962","pt":1580587064569,"mc":[{"id":"1.168186837","rc":[{"batb":[[0,1.85,14.73]],"batl":[[0,1.96,8.95],[1,2,22.72],[2,95,15.9]],"ltp":1.89,"tv":894.92,"id":8639275},{"batb":[[0,2.06,28.97],[1,2.04,184.62]],"ltp":2.0,"tv":291.94,"id":8173434}]}]}
{"op":"mcm","clk":"1001500044","pt":1580587064943,"mc":[{"id":"1.168186837","rc":[{"batl":[[0,1.95,193.3],[1,1.96,8.95],[2,2,22.72]],"ltp":1.89,"tv":894.92,"id":8639275},{"batb":[[1,1.99,57.55],[2,1.93,193.78]],"ltp":2.0,"tv":291.94,"id":8173434}]}]}
{"op":"mcm","clk":"1001500310","pt":1580587066380,"mc":[{"id":"1.168186837","rc":[{"batl":[[1,2,22.72],[2,95,15.9]],"ltp":1.89,"tv":894.92,"id":8639275}]}]}
{"op":"mcm","clk":"1001500410","pt":1580587066969,"mc":[{"id":"1.168186837","rc":[{"batl":[[0,2,22.72],[1,95,15.9],[2,990,2.2]],"ltp":1.89,"tv":894.92,"id":8639275},{"batb":[[0,2.06,211.88]],"ltp":2.0,"tv":291.94,"id":8173434}]}]}
{"op":"mcm","clk":"1001502703","pt":1580587080172,"mc":[{"id":"1.168186837","rc":[{"batl":[[0,1.94,8.95],[1,2,22.72],[2,95,15.9]],"ltp":1.89,"tv":894.92,"id":8639275}]}]}
{"op":"mcm","clk":"1001540095","pt":1580587305512,"mc":[{"id":"1.168186837","rc":[{"batl":[[0,1.94,203.2]],"ltp":1.89,"tv":894.92,"id":8639275},{"batb":[[0,2.06,28.97]],"ltp":2.0,"tv":291.94,"id":8173434}]}]}
{"op":"mcm","clk":"1001540287","pt":1580587306479,"mc":[{"id":"1.168186837","rc":[{"trd":[[1.85,11.28]],"batb":[[0,1.85,9.09]],"ltp":1.85,"tv":906.2,"id":8639275},{"batb":[[0,2.08,4.97],[1,2.06,28.97],[2,1.99,57.55]],"ltp":2.0,"tv":291.94,"id":8173434}],"tv":1198.14}]}
{"op":"mcm","clk":"1001540385","pt":1580587307010,"mc":[{"id":"1.168186837","rc":[{"batl":[[0,1.94,8.95]],"ltp":1.85,"tv":906.2,"id":8639275}]}]}
{"op":"mcm","clk":"1001540602","pt":1580587308243,"mc":[{"id":"1.168186837","rc":[{"batl":[[0,2,22.72],[1,95,15.9],[2,990,2.2]],"ltp":1.85,"tv":906.2,"id":8639275}]}]}
{"op":"mcm","clk":"1001546723","pt":1580587343242,"mc":[{"id":"1.168186837","rc":[{"batb":[[0,2.06,216.85],[1,1.99,57.55],[2,1.93,193.78]],"ltp":2.0,"tv":291.94,"id":8173434}]}]}
{"op":"mcm","clk":"1001546931","pt":1580587344487,"mc":[{"id":"1.168186837","rc":[{"trd":[[1.85,18.54]],"batb":[[0,1.84,83.53],[1,1.8,2],[2,1.78,45.81]],"batl":[[0,1.94,9.13],[1,2,22.72],[2,95,15.9]],"ltp":1.85,"tv":913.46,"id":8639275},{"batb":[[0,2.06,220.03]],"ltp":2.0,"tv":291.94,"id":8173434}],"tv":1205.4}]}
{"op":"mcm","clk":"1001553629","pt":1580587381214,"mc":[{"id":"1.168186837","rc":[{"batl":[[0,1.94,203.38]],"ltp":1.85,"tv":913.46,"id":8639275},{"batb":[[0,2.06,37.12]],"ltp":2.0,"tv":291.94,"id":8173434}]}]}
{"op":"mcm","clk":"1001561203","pt":1580587422606,"mc":[{"id":"1.168186837","rc":[{"batl":[[0,1.94,179.88]],"ltp":1.85,"tv":913.46,"id":8639275}]}]}
{"op":"mcm","clk":"1001564582","pt":1580587441162,"mc":[{"id":"1.168186837","rc":[{"batb":[[2,1.77,59]],"ltp":2.0,"tv":291.94,"id":8173434}]}]}
{"op":"mcm","clk":"1001564836","pt":1580587442521,"mc":[{"id":"1.168186837","rc":[{"batb":[[2,1.93,193.78]],"ltp":2.0,"tv":291.94,"id":8173434}]}]}
{"op":"mcm","clk":"1001565615","pt":1580587446642,"mc":[{"id":"1.168186837","rc":[{"batb":[[1,1.93,193.78],[2,1.77,59]],"ltp":2.0,"tv":291.94,"id":8173434}]}]}
{"op":"mcm","clk":"1001565639","pt":1580587446756,"mc":[{"id":"1.168186837","rc":[{"batb":[[2,1.78,112.44]],"ltp":1.85,"tv":913.46,"id":8639275},{"batb":[[1,2,57.55],[2,1.93,193.78]],"ltp":2.0,"tv":291.94,"id":8173434}]}]}
{"op":"mcm","clk":"1001667521","pt":1580587956593,"mc":[{"id":"1.168186837","rc":[{"batl":[[0,1.94,170.07]],"ltp":1.85,"tv":913.46,"id":8639275}]}]}
{"op":"mcm","clk":"1001727730","pt":1580588252024,"mc":[{"id":"1.168186837","rc":[{"trd":[[2.06,20]],"batb":[[0,2.06,27.12]],"ltp":2.06,"tv":311.94,"id":8173434}],"tv":1225.4}]}
{"op":"mcm","clk":"1001727950","pt":1580588253121,"mc":[{"id":"1.168186837","rc":[{"batb":[[0,1.85,16.59],[1,1.84,83.53],[2,1.8,2]],"ltp":1.85,"tv":913.46,"id":8639275}]}]}
{"op":"mcm","clk":"1001732746","pt":1580588279369,"mc":[{"id":"1.168186837","rc":[{"trd":[[1.85,32.28]],"batb":[[0,1.85,9.71]],"ltp":1.85,"tv":927.2,"id":8639275}],"tv":1239.14}]}
{"op":"mcm","clk":"1001732946","pt":1580588280573,"mc":[{"id":"1.168186837","rc":[{"batb":[[0,2.08,6.26],[1,2.06,27.12],[2,2,57.55]],"ltp":2.06,"tv":311.94,"id":8173434}]}]}
{"op":"mcm","clk":"1001735589","pt":1580588294618,"mc":[{"id":"1.168186837","rc":[{"batl":[[0,1.94,9.13]],"ltp":1.85,"tv":927.2,"id":8639275},{"batl":[[0,2.1,37.86],[1,13.5,3.36],[2,95,15.9]],"ltp":2.06,"tv":311.94,"id":8173434}]}]}
{"op":"mcm","clk":"1001735676","pt":1580588295113,"mc":[{"id":"1.168186837","rc":[{"trd":[[2.1,75.72]],"batl":[[0,13.5,3.36],[1,95,15.9],[2,990,2.2]],"ltp":2.1,"tv":387.66,"id":8173434}],"tv":1314.86}]}
{"op":"mcm","clk":"1001735838","pt":1580588295985,"mc":[{"id":"1.168186837","rc":[{"batl":[[0,2,22.72],[1,95,15.9],[2,990,2.2]],"ltp":1.85,"tv":927.2,"id":8639275}]}]}
{"op":"mcm","clk":"1001737478","pt":1580588304896,"mc":[{"id":"1.168186837","rc":[{"batl":[[0,2.2,37.86],[1,13.5,3.36],[2,95,15.9]],"ltp":2.1,"tv":387.66,"id":8173434}]}]}
{"op":"mcm","clk":"1001737665","pt":1580588305930,"mc":[{"id":"1.168186837","rc":[{"batl":[[0,2.18,8.4],[1,2.2,37.86],[2,13.5,3.36]],"ltp":2.1,"tv":387.66,"id":8173434}]}]}
{"op":"mcm","clk":"1001739490","pt":1580588316343,"mc":[{"id":"1.168186837","rc":[{"batl":[[1,13.5,3.36],[2,95,15.9]],"ltp":2.1,"tv":387.66,"id":8173434}]}]}
{"op":"mcm","clk":"1001739721","pt":1580588317638,"mc":[{"id":"1.168186837","rc":[{"trd":[[1.85,40.02]],"batb":[[0,1.84,83.53],[1,1.8,2],[2,1.78,66.64]],"ltp":1.85,"tv":934.94,"id":8639275},{"batb":[[0,2.08,139.07]],"ltp":2.1,"tv":387.66,"id":8173434}],"tv":1322.6}]}
{"op":"mcm","clk":"1001739845","pt":1580588318451,"mc":[{"id":"1.168186837","rc":[{"batb":[[2,1.79,40.08]],"batl":[[0,1.92,9.12],[1,2,22.72],[2,95,15.9]],"ltp":1.85,"tv":934.94,"id":8639275},{"batb":[[0,2.08,142.46]],"batl":[[0,13.5,3.36],[1,95,15.9],[2,990,2.2]],"ltp":2.1,"tv":387.66,"id":8173434}]}]}
{"op":"mcm","clk":"1001761123","pt":1580588438614,"mc":[{"id":"1.168186837","rc":[{"batl":[[0,1.92,152.93]],"ltp":1.85,"tv":934.94,"id":8639275},{"batb":[[0,2.08,9.65]],"ltp":2.1,"tv":387.66,"id":8173434}]}]}
{"op":"mcm","clk":"1001765607","pt":1580588463923,"mc":[{"id":"1.168186837","rc":[{"batb":[[0,2.1,19.37],[1,2.08,9.65]],"ltp":2.1,"tv":387.66,"id":8173434}]}]}
{"op":"mcm","clk":"1001778111","pt":1580588536536,"mc":[{"id":"1.168186837","rc":[{"batl":[[0,2,22.72],[1,95,15.9],[2,990,2.2]],"ltp":1.85,"tv":934.94,"id":8639275}]}]}
{"op":"mcm","clk":"1001790522","pt":1580588606483,"mc":[{"id":"1.168186837","rc":[{"batb":[[0,2,57.55],[1,1.93,193.78],[2,1.77,59]],"ltp":2.1,"tv":387.66,"id":8173434}]}]}
{"op":"mcm","clk":"1001790635","pt":1580588607078,"mc":[{"id":"1.168186837","rc":[{"batb":[[0,2.08,132.81],[1,2.06,36.78],[2,2,57.55]],"ltp":2.1,"tv":387.66,"id":8173434}]}]}
{"op":"mcm","clk":"1001790880","pt":1580588608295,"mc":[{"id":"1.168186837","rc":[{"batl":[[0,1.92,9.35],[1,2,22.72],[2,95,15.9]],"ltp":1.85,"tv":934.94,"id":8639275}]}]}
{"op":"mcm","clk":"1001803395","pt":1580588679066,"mc":[{"id":"1.168186837","rc":[{"batl":[[0,1.92,153.16]],"ltp":1.85,"tv":934.94,"id":8639275},{"batb":[[0,2.06,36.78],[1,2,57.55],[2,1.93,193.78]],"ltp":2.1,"tv":387.66,"id":8173434}]}]}
{"op":"mcm","clk":"1001813537","pt":1580588736011,"mc":[{"id":"1.168186837","rc":[{"trd":[[1.92,2.91]],"batl":[[0,1.92,150.25]],"ltp":1.92,"tv":937.85,"id":8639275},{"trd":[[2.08,149.98]],"ltp":2.08,"tv":390.34,"id":8173434}],"tv":1328.19}]}
{"op":"mcm","clk":"1001815532","pt":1580588746200,"mc":[{"id":"1.168186837","rc":[{"batb":[[0,2.1,21.53]],"ltp":2.08,"tv":390.34,"id":8173434}]}]}
{"op":"mcm","clk":"1001846126","pt":1580588919410,"mc":[{"id":"1.168186837","rc":[{"batl":[[0,1.92,6.44]],"ltp":1.92,"tv":937.85,"id":8639275}]}]}
{"op":"mcm","clk":"1001846231","pt":1580588920033,"mc":[{"id":"1.168186837","rc":[{"batl":[[0,2,22.72],[1,95,15.9],[2,990,2.2]],"ltp":1.92,"tv":937.85,"id":8639275}]}]}
{"op":"mcm","clk":"1001866930","pt":1580589031316,"mc":[{"id":"1.168186837","rc":[{"batb":[[0,2.06,36.78],[1,2.02,136.74],[2,2,57.55]],"ltp":2.08,"tv":390.34,"id":8173434}]}]}
{"op":"mcm","clk":"1001891088","pt":1580589159565,"mc":[{"id":"1.168186837","rc":[{"batb":[[1,2,57.55],[2,1.93,193.78]],"ltp":2.08,"tv":390.34,"id":8173434}]}]}
{"op":"mcm","clk":"1001891125","pt":1580589159768,"mc":[{"id":"1.168186837","rc":[{"batb":[[0,2.08,132.81],[1,2.06,36.78],[2,2,57.55]],"ltp":2.08,"tv":390.34,"id":8173434}]}]}
{"op":"mcm","clk":"1001893310","pt":1580589172165,"mc":[{"id":"1.168186837","rc":[{"batb":[[0,2.1,21.53],[1,2.08,132.81]],"ltp":2.08,"tv":390.34,"id":8173434}]}]}
{"op":"mcm","clk":"1001910177","pt":1580589272952,"mc":[{"id":"1.168186837","rc":[{"batb":[[1,2,57.55],[2,1.93,193.78]],"ltp":2.08,"tv":390.34,"id":8173434}]}]}
{"op":"mcm","clk":"1001916543","pt":1580589314279,"mc":[{"id":"1.168186837","rc":[{"batb":[[0,2.06,36.78],[1,2.04,135.37],[2,2,57.55]],"ltp":2.08,"tv":390.34,"id":8173434}]}]}
{"op":"mcm","clk":"1001930332","pt":1580589400201,"mc":[{"id":"1.168186837","rc":[{"batb":[[0,2.08,132.81],[1,2.06,36.78]],"ltp":2.08,"tv":390.34,"id":8173434}]}]}
{"op":"mcm","clk":"1001938728","pt":1580589452266,"mc":[{"id":"1.168186837","rc":[{"batb":[[0,2.1,21.53],[1,2.08,132.81]],"ltp":2.08,"tv":390.34,"id":8173434}]}]}
{"op":"mcm","clk":"1001948962","pt":1580589512536,"mc":[{"id":"1.168186837","rc":[{"batb":[[1,2,57.55],[2,1.93,193.78]],"ltp":2.08,"tv":390.34,"id":8173434}]}]}
{"op":"mcm","clk":"1001962479","pt":1580589592633,"mc":[{"id":"1.168186837","rc":[{"batb":[[0,2.06,36.78]],"ltp":2.08,"tv":390.34,"id":8173434}]}]}
{"op":"mcm","clk":"1002043214","pt":1580590075062,"mc":[{"id":"1.168186837","rc":[{"batl":[[0,1.9,10],[1,2,22.72],[2,95,15.9]],"ltp":1.92,"tv":937.85,"id":8639275}]}]}
{"op":"mcm","clk":"1002044142","pt":1580590080678,"mc":[{"id":"1.168186837","rc":[{"batl":[[0,2,22.72],[1,95,15.9],[2,990,2.2]],"ltp":1.92,"tv":937.85,"id":8639275}]}]}
{"op":"mcm","clk":"1002044165","pt":1580590080841,"mc":[{"id":"1.168186837","rc":[{"trd":[[1.84,104.89]],"batb":[[0,1.84,73.53]],"ltp":1.84,"tv":957.85,"id":8639275}],"tv":1348.19}]}
{"op":"mcm","clk":"1002089093","pt":1580590399671,"mc":[{"id":"1.168186837","rc":[{"batb":[[2,1.79,37.14]],"ltp":1.84,"tv":957.85,"id":8639275},{"batb":[[0,2.06,39.32]],"ltp":2.08,"tv":390.34,"id":8173434}]}]}
{"op":"mcm","clk":"1002089111","pt":1580590399873,"mc":[{"id":"1.168186837","rc":[{"batb":[[0,2.08,132.81],[1,2.06,39.32],[2,2,57.55]],"ltp":2.08,"tv":390.34,"id":8173434}]}]}
{"op":"mcm","clk":"1002107668","pt":1580590555433,"mc":[{"id":"1.168186837","rc":[{"batb":[[0,2.1,24.05],[1,2,57.55],[2,1.93,193.78]],"ltp":2.08,"tv":390.34,"id":8173434}]}]}
{"op":"mcm","clk":"1002121977","pt":1580590695629,"mc":[{"id":"1.168186837","rc":[{"batb":[[0,2.08,132.81],[1,2.06,39.32],[2,2,57.55]],"ltp":2.08,"tv":390.34,"id":8173434}]}]}
{"op":"mcm","clk":"1002128737","pt":1580590760319,"mc":[{"id":"1.168186837","rc":[{"batl":[[0,2.8,42.22],[1,13.5,3.36],[2,95,15.9]],"ltp":2.08,"tv":390.34,"id":8173434}]}]}
{"op":"mcm","clk":"1002129334","pt":1580590766318,"mc":[{"id":"1.168186837","rc":[{"batl":[[0,13.5,3.36],[1,95,15.9],[2,990,2.2]],"ltp":2.08,"tv":390.34,"id":8173434}]}]}
{"op":"mcm","clk":"1002134618","pt":1580590811106,"mc":[{"id":"1.168186837","rc":[{"batl":[[0,2.8,25.33],[1,13.5,3.36],[2,95,15.9]],"ltp":2.08,"tv":390.34,"id":8173434}]}]}
{"op":"mcm","clk":"1002134864","pt":1580590813279,"mc":[{"id":"1.168186837","rc":[{"batl":[[1,95,15.9],[2,990,2.2]],"ltp":2.08,"tv":390.34,"id":8173434}]}]}
{"op":"mcm","clk":"1002135247","pt":1580590816409,"mc":[{"id":"1.168186837","rc":[{"batl":[[0,95,15.9],[1,990,2.2],[2,1000,0.02]],"ltp":2.08,"tv":390.34,"id":8173434}]}]}
{"op":"mcm","clk":"1002137738","pt":1580590837291,"mc":[{"id":"1.168186837","rc":[{"batb":[[0,2.1,24.05],[1,2,57.55],[2,1.93,193.78]],"ltp":2.08,"tv":390.34,"id":8173434}]}]}
{"op":"mcm","clk":"1002141167","pt":1580590865039,"mc":[{"id":"1.168186837","rc":[{"trd":[[2.1,84.12]],"batb":[[0,2.1,19.85]],"ltp":2.1,"tv":398.74,"id":8173434}],"tv":1356.59}]}
{"op":"mcm","clk":"1002141379","pt":1580590866656,"mc":[{"id":"1.168186837","rc":[{"batb":[[2,1.79,41.98]],"ltp":1.84,"tv":957.85,"id":8639275},{"batb":[[0,2.06,35.14]],"ltp":2.1,"tv":398.74,"id":8173434}]}]}
{"op":"mcm","clk":"1002141431","pt":1580590867030,"mc":[{"id":"1.168186837","rc":[{"batb":[[0,2.08,132.81],[1,2.06,35.14],[2,2,57.55]],"ltp":2.1,"tv":398.74,"id":8173434}]}]}
{"op":"mcm","clk":"1002145578","pt":1580590902309,"mc":[{"id":"1.168186837","rc":[{"batb":[[0,1.84,77.1]],"ltp":1.84,"tv":957.85,"id":8639275}]}]}
{"op":"mcm","clk":"1002146746","pt":1580590912287,"mc":[{"id":"1.168186837","rc":[{"batl":[[0,13,3.36],[1,95,15.9],[2,990,2.2]],"ltp":2.1,"tv":398.74,"id":8173434}]}]}
{"op":"mcm","clk":"1002154446","pt":1580590980406,"mc":[{"id":"1.168186837","rc":[{"batb":[[0,2.1,19.9],[1,2.08,132.81]],"ltp":2.1,"tv":398.74,"id":8173434}]}]}
{"op":"mcm","clk":"1002154483","pt":1580590980727,"mc":[{"id":"1.168186837","rc":[{"batb":[[1,2,57.55],[2,1.93,193.78]],"ltp":2.1,"tv":398.74,"id":8173434}]}]}
{"op":"mcm","clk":"1002170457","pt":1580591122495,"mc":[{"id":"1.168186837","rc":[{"batb":[[0,2.06,35.14]],"ltp":2.1,"tv":398.74,"id":8173434}]}]}
{"op":"mcm","clk":"1002170514","pt":1580591122972,"mc":[{"id":"1.168186837","rc":[{"batb":[[0,2.08,132.81],[1,2.06,35.14],[2,2,57.55]],"ltp":2.1,"tv":398.74,"id":8173434}]}]}
{"op":"mcm","clk":"1002187453","pt":1580591262267,"mc":[{"id":"1.168186837","rc":[{"batb":[[0,2.1,19.9],[1,2,57.55],[2,1.93,193.78]],"ltp":2.1,"tv":398.74,"id":8173434}]}]}
{"op":"mcm","clk":"1002205262","pt":1580591404525,"mc":[{"id":"1.168186837","rc":[{"batb":[[0,2.06,35.14]],"ltp":2.1,"tv":398.74,"id":8173434}]}]}
{"op":"mcm","clk":"1002205345","pt":1580591405229,"mc":[{"id":"1.168186837","rc":[{"batb":[[0,2.08,132.81],[1,2.06,35.14],[2,2,57.55]],"ltp":2.1,"tv":398.74,"id":8173434}]}]}
{"op":"mcm","clk":"1002220950","pt":1580591547206,"mc":[{"id":"1.168186837","rc":[{"batb":[[0,2.1,19.9],[1,2,57.55],[2,1.93,193.78]],"ltp":2.1,"tv":398.74,"id":8173434}]}]}
{"op":"mcm","clk":"1002235510","pt":1580591689676,"mc":[{"id":"1.168186837","rc":[{"batb":[[0,2.08,132.81],[1,2.06,35.14],[2,2,57.55]],"ltp":2.1,"tv":398.74,"id":8173434}]}]}
{"op":"mcm","clk":"1002242174","pt":1580591758285,"mc":[{"id":"1.168186837","rc":[{"batb":[[0,1.87,2.53],[1,1.84,77.1],[2,1.8,2]],"ltp":1.84,"tv":957.85,"id":8639275}]}]}
{"op":"mcm","clk":"1002243294","pt":1580591771496,"mc":[{"id":"1.168186837","rc":[{"batb":[[1,1.84,73.53]],"ltp":1.84,"tv":957.85,"id":8639275}]}]}
{"op":"mcm","clk":"1002248577","pt":1580591828092,"mc":[{"id":"1.168186837","rc":[{"batb":[[0,2.1,19.9],[1,2.08,132.81]],"ltp":2.1,"tv":398.74,"id":8173434}]}]}
{"op":"mcm","clk":"1002250246","pt":1580591843618,"mc":[{"id":"1.168186837","rc":[{"batb":[[1,2,57.55],[2,1.93,193.78]],"ltp":2.1,"tv":398.74,"id":8173434}]}]}
{"op":"mcm","clk":"1002264638","pt":1580591960159,"mc":[{"id":"1.168186837","rc":[{"batb":[[0,2.06,169.22]],"ltp":2.1,"tv":398.74,"id":8173434}]}]}
{"op":"mcm","clk":"1002360842","pt":1580592872507,"mc":[{"id":"1.168186837","rc":[{"batb":[[2,1.77,59]],"ltp":2.1,"tv":398.74,"id":8173434}]}]}
{"op":"mcm","clk":"1002360911","pt":1580592873230,"mc":[{"id":"1.168186837","rc":[{"batb":[[2,1.94,252.14]],"ltp":2.1,"tv":398.74,"id":8173434}]}]}
{"op":"mcm","clk":"1002378490","pt":1580593046657,"mc":[{"id":"1.168186837","rc":[{"batb":[[1,1.86,40.93],[2,1.84,73.53]],"ltp":1.84,"tv":957.85,"id":8639275},{"trd":[[2.06,907.62]],"batb":[[0,2.02,16.32],[1,2,308.1]],"batl":[[0,2.06,236.93],[1,13,3.36],[2,95,15.9]],"ltp":2.06,"tv":1286.36,"id":8173434}],"tv":2244.21}]}
{"op":"mcm","clk":"1002378609","pt":1580593047654,"mc":[{"id":"1.168186837","rc":[{"batb":[[0,1.95,12.68],[1,1.87,2.53],[2,1.86,40.93]],"ltp":1.84,"tv":957.85,"id":8639275},{"trd":[[2.06,1039.62]],"batb":[[0,2.02,26.14],[1,2,57.55]],"batl":[[0,2.04,9.81],[1,2.06,170.93],[2,13,3.36]],"ltp":2.06,"tv":1418.37,"id":8173434}],"tv":2376.22}]}
{"op":"mcm","clk":"1002378711","pt":1580593048647,"mc":[{"id":"1.168186837","rc":[{"batb":[[0,2.02,16.32]],"ltp":2.06,"tv":1418.37,"id":8173434}]}]}
{"op":"mcm","clk":"1002378992","pt":1580593051436,"mc":[{"id":"1.168186837","rc":[{"batb":[[0,1.87,2.53],[1,1.86,40.93],[2,1.84,73.53]],"ltp":1.84,"tv":957.85,"id":8639275},{"batl":[[0,13,3.36],[1,95,15.9],[2,990,2.2]],"ltp":2.06,"tv":1418.37,"id":8173434}]}]}
{"op":"mcm","clk":"1002379748","pt":1580593058468,"mc":[{"id":"1.168186837","rc":[{"batb":[[2,1.85,3.02]],"ltp":1.84,"tv":957.85,"id":8639275}]}]}
{"op":"mcm","clk":"1002426797","pt":1580593543870,"mc":[{"id":"1.168186837","rc":[{"batb":[[0,2.02,15.82]],"ltp":2.06,"tv":1418.37,"id":8173434}]}]}
{"op":"mcm","clk":"1002441618","pt":1580593730601,"mc":[{"id":"1.168186837","rc":[{"trd":[[2.02,133.59]],"batb":[[0,2,57.55],[1,1.94,252.14],[2,1.88,34.58]],"ltp":2.02,"tv":1463.74,"id":8173434}],"tv":2421.59}]}
{"op":"mcm","clk":"1002441653","pt":1580593731014,"mc":[{"id":"1.168186837","rc":[{"batb":[[0,1.89,42.43],[1,1.87,2.53]],"ltp":1.84,"tv":957.85,"id":8639275},{"batb":[[1,1.95,30.45],[2,1.94,252.14]],"ltp":2.02,"tv":1463.74,"id":8173434}]}]}
{"op":"mcm","clk":"1002441805","pt":1580593732635,"mc":[{"id":"1.168186837","rc":[{"batb":[[2,1.88,34.58]],"ltp":2.02,"tv":1463.74,"id":8173434}]}]}
{"op":"mcm","clk":"1002441859","pt":1580593733214,"mc":[{"id":"1.168186837","rc":[{"batb":[[2,1.93,254.85]],"ltp":2.02,"tv":1463.74,"id":8173434}]}]}
{"op":"mcm","clk":"1002447369","pt":1580593809437,"mc":[{"id":"1.168186837","rc":[{"trd":[[1.89,82.2]],"batb":[[0,1.89,17.92]],"ltp":1.89,"tv":1006.87,"id":8639275},{"batb":[[1,1.94,35.1]],"ltp":2.02,"tv":1463.74,"id":8173434}],"tv":2470.61}]}
{"op":"mcm","clk":"1002447415","pt":1580593810164,"mc":[{"id":"1.168186837","rc":[{"batb":[[0,1.87,2.53],[1,1.85,42.3],[2,1.84,73.53]],"ltp":1.89,"tv":1006.87,"id":8639275},{"batb":[[0,2.02,22.85],[1,2,57.55]],"ltp":2.02,"tv":1463.74,"id":8173434}]}]}
{"op":"mcm","clk":"1002480545","pt":1580594234797,"mc":[{"id":"1.168186837","rc":[{"trd":[[1.87,62.12]],"batb":[[0,1.85,42.3],[1,1.84,73.53],[2,1.8,2]],"batl":[[0,1.87,18.48],[1,2,22.72],[2,95,15.9]],"ltp":1.87,"tv":1011.93,"id":8639275}],"tv":2475.67}]}
{"op":"mcm","clk":"1002480684","pt":1580594236412,"mc":[{"id":"1.168186837","rc":[{"trd":[[1.85,90.02],[1.87,76.24]],"batb":[[0,1.85,17.31]],"batl":[[0,1.87,11.42]],"ltp":1.87,"tv":1076.04,"id":8639275}],"tv":2539.79}]}
{"op":"mcm","clk":"1002480741","pt":1580594236991,"mc":[{"id":"1.168186837","rc":[{"batb":[[0,1.85,10.54]],"ltp":1.87,"tv":1076.04,"id":8639275},{"batb":[[0,2.04,40.67]],"ltp":2.02,"tv":1463.74,"id":8173434}]}]}
{"op":"mcm","clk":"1002492617","pt":1580594410609,"mc":[{"id":"1.168186837","rc":[{"trd":[[1.85,102.02]],"batb":[[0,1.84,73.53],[1,1.8,34.74],[2,1.79,66.64]],"ltp":1.85,"tv":1088.04,"id":8639275},{"batb":[[0,2.06,37.94],[1,1.98,57.55]],"ltp":2.02,"tv":1463.74,"id":8173434}],"tv":2551.78}]}
{"op":"mcm","clk":"1002492655","pt":1580594410978,"mc":[{"id":"1.168186837","rc":[{"batb":[[1,2.02,34.24],[2,1.98,57.55]],"ltp":2.02,"tv":1463.74,"id":8173434}]}]}
{"op":"mcm","clk":"1002497288","pt":1580594473569,"mc":[{"id":"1.168186837","rc":[{"batb":[[1,1.98,57.55],[2,1.93,254.85]],"ltp":2.02,"tv":1463.74,"id":8173434}]}]}
{"op":"mcm","clk":"1002501867","pt":1580594537462,"mc":[{"id":"1.168186837","rc":[{"batl":[[1,2.02,22.72]],"ltp":1.85,"tv":1088.04,"id":8639275}]}]}
{"op":"mcm","clk":"1002510074","pt":1580594664053,"mc":[{"id":"1.168186837","rc":[{"batl":[[1,1.94,2.27],[2,2.02,22.72]],"ltp":1.85,"tv":1088.04,"id":8639275}]}]}
{"op":"mcm","clk":"1002510350","pt":1580594668415,"mc":[{"id":"1.168186837","rc":[{"batl":[[1,2.02,22.72],[2,95,15.9]],"ltp":1.85,"tv":1088.04,"id":8639275}]}]}
{"op":"mcm","clk":"1002511846","pt":1580594691153,"mc":[{"id":"1.168186837","rc":[{"batl":[[0,2.2,4.54],[1,13,3.36],[2,95,15.9]],"ltp":2.02,"tv":1463.74,"id":8173434}]}]}
{"op":"mcm","clk":"1002512482","pt":1580594700792,"mc":[{"id":"1.168186837","rc":[{"batl":[[1,95,15.9],[2,990,2.2]],"ltp":2.02,"tv":1463.74,"id":8173434}]}]}
{"op":"mcm","clk":"1002549638","pt":1580595214058,"mc":[{"id":"1.168186837","rc":[{"trd":[[1.84,110.11]],"batb":[[0,1.84,70.92],[1,1.82,2.63],[2,1.8,34.74]],"ltp":1.84,"tv":1093.26,"id":8639275}],"tv":2557.01}]}
{"op":"mcm","clk":"1002583982","pt":1580595654542,"mc":[{"id":"1.168186837","rc":[{"trd":[[1.87,99.08]],"batb":[[0,1.88,11.12],[1,1.85,38.14],[2,1.84,70.92]],"batl":[[0,2.02,22.72],[1,95,15.9],[2,990,2.2]],"ltp":1.87,"tv":1116.1,"id":8639275},{"batb":[[0,1.99,36.65]],"ltp":2.02,"tv":1463.74,"id":8173434}],"tv":2579.84}]}
{"op":"mcm","clk":"1002584055","pt":1580595655625,"mc":[{"id":"1.168186837","rc":[{"trd":[[1.88,6.34]],"batb":[[0,1.88,7.95]],"ltp":1.88,"tv":1122.44,"id":8639275},{"batb":[[0,1.99,285.76]],"ltp":2.02,"tv":1463.74,"id":8173434}],"tv":2586.18}]}
{"op":"mcm","clk":"1002584123","pt":1580595656611,"mc":[{"id":"1.168186837","rc":[{"batl":[[0,2,11.23],[1,2.02,22.72],[2,95,15.9]],"ltp":1.88,"tv":1122.44,"id":8639275},{"batb":[[0,2,14.79],[1,1.99,285.76],[2,1.98,57.55]],"ltp":2.02,"tv":1463.74,"id":8173434}]}]}
{"op":"mcm","clk":"1002585754","pt":1580595680585,"mc":[{"id":"1.168186837","rc":[{"batb":[[0,2.02,23.9],[1,2,14.79]],"ltp":2.02,"tv":1463.74,"id":8173434}]}]}
{"op":"mcm","clk":"1002585837","pt":1580595681982,"mc":[{"id":"1.168186837","rc":[{"batl":[[0,2.02,22.72],[1,95,15.9],[2,990,2.2]],"ltp":1.88,"tv":1122.44,"id":8639275},{"batb":[[1,1.98,57.55],[2,1.93,254.85]],"ltp":2.02,"tv":1463.74,"id":8173434}]}]}
{"op":"mcm","clk":"1002588914","pt":1580595727550,"mc":[{"id":"1.168186837","rc":[{"batl":[[0,2.12,17.11],[1,2.2,4.54],[2,95,15.9]],"ltp":2.02,"tv":1463.74,"id":8173434}]}]}
{"op":"mcm","clk":"1002588942","pt":1580595728065,"mc":[{"id":"1.168186837","rc":[{"trd":[[2.12,21.64]],"batl":[[0,2.12,6.29]],"ltp":2.12,"tv":1485.38,"id":8173434}],"tv":2607.82}]}
{"op":"mcm","clk":"1002594712","pt":1580595814313,"mc":[{"id":"1.168186837","rc":[{"batb":[[0,1.99,36.65]],"ltp":2.12,"tv":1485.38,"id":8173434}]}]}
{"op":"mcm","clk":"1002594767","pt":1580595815039,"mc":[{"id":"1.168186837","rc":[{"trd":[[2.12,29.3]],"batl":[[0,2.12,2.46]],"ltp":2.12,"tv":1493.04,"id":8173434}],"tv":2615.49}]}
{"op":"mcm","clk":"1002622879","pt":1580596218422,"mc":[{"id":"1.168186837","rc":[{"batb":[[0,2,249.33],[1,1.99,36.65],[2,1.98,57.55]],"ltp":2.12,"tv":1493.04,"id":8173434}]}]}
{"op":"mcm","clk":"1002622934","pt":1580596219302,"mc":[{"id":"1.168186837","rc":[{"trd":[[1.88,9.92],[1.89,84.96]],"batb":[[0,1.88,6.16]],"ltp":1.88,"tv":1128.78,"id":8639275},{"trd":[[2.12,31.76]],"batl":[[0,2.2,4.54],[1,95,15.9],[2,990,2.2]],"ltp":2.12,"tv":1495.51,"id":8173434}],"tv":2624.29}]}
{"op":"mcm","clk":"1002622985","pt":1580596220450,"mc":[{"id":"1.168186837","rc":[{"batl":[[0,1.99,11.28],[1,2.02,22.72],[2,95,15.9]],"ltp":1.88,"tv":1128.78,"id":8639275},{"batb":[[0,2.02,12.28],[1,2,249.33],[2,1.99,36.65]],"ltp":2.12,"tv":1495.51,"id":8173434}]}]}
{"op":"mcm","clk":"1002623491","pt":1580596227134,"mc":[{"id":"1.168186837","rc":[{"batb":[[2,1.99,94.2]],"ltp":2.12,"tv":1495.51,"id":8173434}]}]}
{"op":"mcm","clk":"1002626336","pt":1580596267390,"mc":[{"id":"1.168186837","rc":[{"batl":[[0,1.99,34]],"ltp":1.88,"tv":1128.78,"id":8639275}]}]}
{"op":"mcm","clk":"1002626394","pt":1580596268304,"mc":[{"id":"1.168186837","rc":[{"trd":[[1.88,17.74]],"batb":[[0,1.88,2.25]],"ltp":1.88,"tv":1136.6,"id":8639275}],"tv":2632.11}]}
{"op":"mcm","clk":"1002632647","pt":1580596355385,"mc":[{"id":"1.168186837","rc":[{"batl":[[0,1.99,22.72]],"ltp":1.88,"tv":1136.6,"id":8639275},{"batb":[[0,2.02,23.9],[1,1.99,57.55],[2,1.94,252.14]],"ltp":2.12,"tv":1495.51,"id":8173434}]}]}
{"op":"mcm","clk":"1002635234","pt":1580596395198,"mc":[{"id":"1.168186837","rc":[{"trd":[[2.02,137.59]],"batb":[[0,2.02,21.9]],"ltp":2.02,"tv":1499.5,"id":8173434}],"tv":2636.11}]}
{"op":"mcm","clk":"1002635280","pt":1580596396027,"mc":[{"id":"1.168186837","rc":[{"batb":[[1,1.85,40.29]],"ltp":1.88,"tv":1136.6,"id":8639275}]}]}
{"op":"mcm","clk":"1002642201","pt":1580596496692,"mc":[{"id":"1.168186837","rc":[{"batl":[[0,2.02,22.72],[1,95,15.9],[2,990,2.2]],"ltp":1.88,"tv":1136.6,"id":8639275}]}]}
{"op":"mcm","clk":"1002649914","pt":1580596622631,"mc":[{"id":"1.168186837","rc":[{"batb":[[0,1.99,57.55],[1,1.94,252.14],[2,1.77,59]],"ltp":2.02,"tv":1499.5,"id":8173434}]}]}
{"op":"mcm","clk":"1002649980","pt":1580596623664,"mc":[{"id":"1.168186837","rc":[{"batl":[[0,1.99,11.37],[1,2.02,22.72],[2,95,15.9]],"ltp":1.88,"tv":1136.6,"id":8639275},{"batb":[[0,2.02,14.34],[1,2,30.35],[2,1.99,57.55]],"ltp":2.02,"tv":1499.5,"id":8173434}]}]}
{"op":"mcm","clk":"1002650025","pt":1580596624442,"mc":[{"id":"1.168186837","rc":[{"batl":[[0,2.02,22.72],[1,95,15.9],[2,990,2.2]],"ltp":1.88,"tv":1136.6,"id":8639275},{"batb":[[0,2,279.68],[1,1.99,57.55],[2,1.94,252.14]],"ltp":2.02,"tv":1499.5,"id":8173434}]}]}
{"op":"mcm","clk":"1002653890","pt":1580596691646,"mc":[{"id":"1.168186837","rc":[{"batl":[[0,1.99,11.37],[1,2.02,22.72],[2,95,15.9]],"ltp":1.88,"tv":1136.6,"id":8639275},{"batb":[[0,2.02,14.13],[1,2,279.68],[2,1.99,57.55]],"ltp":2.02,"tv":1499.5,"id":8173434}]}]}
{"op":"mcm","clk":"1002653906","pt":1580596691852,"mc":[{"id":"1.168186837","rc":[{"batb":[[1,2,30.35]],"ltp":2.02,"tv":1499.5,"id":8173434}]}]}
{"op":"mcm","clk":"1002654028","pt":1580596693560,"mc":[{"id":"1.168186837","rc":[{"batl":[[0,2.02,22.72],[1,95,15.9],[2,990,2.2]],"ltp":1.88,"tv":1136.6,"id":8639275},{"batb":[[0,2,279.68],[1,1.99,57.55],[2,1.94,252.14]],"ltp":2.02,"tv":1499.5,"id":8173434}]}]}
{"op":"mcm","clk":"1002657814","pt":1580596761969,"mc":[{"id":"1.168186837","rc":[{"batl":[[0,1.99,11.37],[1,2.02,22.72],[2,95,15.9]],"ltp":1.88,"tv":1136.6,"id":8639275},{"batb":[[0,2.02,12.91],[1,2,30.35],[2,1.99,57.55]],"ltp":2.02,"tv":1499.5,"id":8173434}]}]}
{"op":"mcm","clk":"1002657901","pt":1580596763572,"mc":[{"id":"1.168186837","rc":[{"batl":[[0,2.02,22.72],[1,95,15.9],[2,990,2.2]],"ltp":1.88,"tv":1136.6,"id":8639275},{"batb":[[0,2,30.35],[1,1.99,57.55],[2,1.94,252.14]],"ltp":2.02,"tv":1499.5,"id":8173434}]}]}
{"op":"mcm","clk":"1002657917","pt":1580596763777,"mc":[{"id":"1.168186837","rc":[{"batb":[[0,2,279.68]],"ltp":2.02,"tv":1499.5,"id":8173434}]}]}
{"op":"mcm","clk":"1002662305","pt":1580596835529,"mc":[{"id":"1.168186837","rc":[{"batl":[[0,1.99,11.37],[1,2.02,22.72],[2,95,15.9]],"ltp":1.88,"tv":1136.6,"id":8639275},{"batb":[[0,2.02,14.42],[1,2,30.35],[2,1.99,57.55]],"ltp":2.02,"tv":1499.5,"id":8173434}]}]}
{"op":"mcm","clk":"1002662396","pt":1580596837036,"mc":[{"id":"1.168186837","rc":[{"batl":[[0,2.02,22.72],[1,95,15.9],[2,990,2.2]],"ltp":1.88,"tv":1136.6,"id":8639275},{"batb":[[0,2,279.68],[1,1.99,57.55],[2,1.94,252.14]],"ltp":2.02,"tv":1499.5,"id":8173434}]}]}
{"op":"mcm","clk":"1002667024","pt":1580596907502,"mc":[{"id":"1.168186837","rc":[{"batl":[[0,1.99,11.37],[1,2.02,22.72],[2,95,15.9]],"ltp":1.88,"tv":1136.6,"id":8639275},{"batb":[[0,2.02,13.93],[1,2,279.68],[2,1.99,57.55]],"ltp":2.02,"tv":1499.5,"id":8173434}]}]}
{"op":"mcm","clk":"1002667085","pt":1580596908643,"mc":[{"id":"1.168186837","rc":[{"batl":[[0,2.02,22.72],[1,95,15.9],[2,990,2.2]],"ltp":1.88,"tv":1136.6,"id":8639275},{"batb":[[0,2,279.68],[1,1.99,57.55],[2,1.94,252.14]],"ltp":2.02,"tv":1499.5,"id":8173434}]}]}
{"op":"mcm","clk":"1002671336","pt":1580596979609,"mc":[{"id":"1.168186837","rc":[{"batl":[[0,1.99,11.37],[1,2.02,22.72],[2,95,15.9]],"ltp":1.88,"tv":1136.6,"id":8639275},{"batb":[[0,2.02,12.97],[1,2,279.68],[2,1.99,57.55]],"ltp":2.02,"tv":1499.5,"id":8173434}]}]}
{"op":"mcm","clk":"1002671349","pt":1580596979815,"mc":[{"id":"1.168186837","rc":[{"batb":[[1,2,30.35]],"ltp":2.02,"tv":1499.5,"id":8173434}]}]}
{"op":"mcm","clk":"1002671461","pt":1580596981428,"mc":[{"id":"1.168186837","rc":[{"batl":[[0,2.02,22.72],[1,95,15.9],[2,990,2.2]],"ltp":1.88,"tv":1136.6,"id":8639275},{"batb":[[0,2,279.68],[1,1.99,57.55],[2,1.94,252.14]],"ltp":2.02,"tv":1499.5,"id":8173434}]}]}
{"op":"mcm","clk":"1002675449","pt":1580597051603,"mc":[{"id":"1.168186837","rc":[{"batl":[[0,1.99,11.37],[1,2.02,22.72],[2,95,15.9]],"ltp":1.88,"tv":1136.6,"id":8639275},{"batb":[[0,2.02,12.88],[1,2,279.68],[2,1.99,57.55]],"ltp":2.02,"tv":1499.5,"id":8173434}]}]}
{"op":"mcm","clk":"1002675464","pt":1580597051911,"mc":[{"id":"1.168186837","rc":[{"batb":[[1,2,30.35]],"ltp":2.02,"tv":1499.5,"id":8173434}]}]}
{"op":"mcm","clk":"1002675544","pt":1580597053105,"mc":[{"id":"1.168186837","rc":[{"batl":[[0,2.02,22.72],[1,95,15.9],[2,990,2.2]],"ltp":1.88,"tv":1136.6,"id":8639275},{"batb":[[0,2,279.68],[1,1.99,57.55],[2,1.94,252.14]],"ltp":2.02,"tv":1499.5,"id":8173434}]}]}
{"op":"mcm","clk":"1002679994","pt":1580597124685,"mc":[{"id":"1.168186837","rc":[{"batl":[[0,1.99,11.37],[1,2.02,22.72],[2,95,15.9]],"ltp":1.88,"tv":1136.6,"id":8639275},{"batb":[[0,2.02,12.91],[1,2,30.35],[2,1.99,57.55]],"ltp":2.02,"tv":1499.5,"id":8173434}]}]}
{"op":"mcm","clk":"1002680103","pt":1580597126397,"mc":[{"id":"1.168186837","rc":[{"batl":[[0,2.02,22.72],[1,95,15.9],[2,990,2.2]],"ltp":1.88,"tv":1136.6,"id":8639275},{"batb":[[0,2,30.35],[1,1.99,57.55],[2,1.94,252.14]],"ltp":2.02,"tv":1499.5,"id":8173434}]}]}
{"op":"mcm","clk":"1002680113","pt":1580597126707,"mc":[{"id":"1.168186837","rc":[{"batb":[[0,2,279.68]],"ltp":2.02,"tv":1499.5,"id":8173434}]}]}
{"op":"mcm","clk":"1002683931","pt":1580597195699,"mc":[{"id":"1.168186837","rc":[{"batl":[[0,1.99,11.37],[1,2.02,22.72],[2,95,15.9]],"ltp":1.88,"tv":1136.6,"id":8639275},{"batb":[[0,2.02,14.15],[1,2,30.35],[2,1.99,57.55]],"ltp":2.02,"tv":1499.5,"id":8173434}]}]}
{"op":"mcm","clk":"1002683968","pt":1580597196585,"mc":[{"id":"1.168186837","rc":[{"batl":[[0,2.02,22.72],[1,95,15.9],[2,990,2.2]],"ltp":1.88,"tv":1136.6,"id":8639275},{"batb":[[0,2,279.68],[1,1.99,57.55],[2,1.94,252.14]],"ltp":2.02,"tv":1499.5,"id":8173434}]}]}
{"op":"mcm","clk":"1002685708","pt":1580597231433,"mc":[{"id":"1.168186837","rc":[{"batb":[[0,2.02,5.9],[1,2,30.35],[2,1.99,57.55]],"ltp":2.02,"tv":1499.5,"id":8173434}]}]}
{"op":"mcm","clk":"1002704499","pt":1580597546033,"mc":[{"id":"1.168186837","rc":[{"trd":[[2.02,141.39]],"batb":[[0,2.02,4]],"ltp":2.02,"tv":1503.31,"id":8173434}],"tv":2639.91}]}
{"op":"mcm","clk":"1002733434","pt":1580597995175,"mc":[{"id":"1.168186837","rc":[{"batb":[[2,1.82,2.63]],"ltp":1.88,"tv":1136.6,"id":8639275}]}]}
{"op":"mcm","clk":"1002733940","pt":1580598001091,"mc":[{"id":"1.168186837","rc":[{"batb":[[1,1.85,110.86]],"ltp":1.88,"tv":1136.6,"id":8639275}]}]}
{"op":"mcm","clk":"1002734037","pt":1580598001966,"mc":[{"id":"1.168186837","rc":[{"batb":[[1,1.86,8.72],[2,1.85,110.86]],"ltp":1.88,"tv":1136.6,"id":8639275}]}]}
{"op":"mcm","clk":"1002738045","pt":1580598059269,"mc":[{"id":"1.168186837","rc":[{"batb":[[1,1.86,10.9],[2,1.85,113.03]],"batl":[[0,2.02,24.97],[1,2.04,2],[2,95,15.9]],"ltp":1.88,"tv":1136.6,"id":8639275},{"batb":[[2,1.99,59.55]],"batl":[[1,2.22,2],[2,2.24,2.07]],"ltp":2.02,"tv":1503.31,"id":8173434}]}]}
{"op":"mcm","clk":"1002738406","pt":1580598063640,"mc":[{"id":"1.168186837","rc":[{"trd":[[1.88,19.99]],"batb":[[0,1.86,25.06],[1,1.85,110.86],[2,1.84,2.22]],"batl":[[0,1.99,15.27],[1,2.02,24.97],[2,2.04,2]],"ltp":1.88,"tv":1138.85,"id":8639275},{"trd":[[2.14,1.98],[2.16,34.23]],"batb":[[0,2.02,19.04]],"batl":[[0,2.16,151.96],[1,2.2,6.57],[2,2.22,2]],"ltp":2.16,"tv":1520.96,"id":8173434}],"tv":2659.81}]}
{"op":"mcm","clk":"1002738417","pt":1580598063745,"mc":[{"id":"1.168186837","rc":[{"batl":[[0,2.16,161.23]],"ltp":2.16,"tv":1520.96,"id":8173434}]}]}
{"op":"mcm","clk":"1002738831","pt":1580598069572,"mc":[{"id":"1.168186837","rc":[{"batl":[[2,2.04,2.13]],"ltp":1.88,"tv":1138.85,"id":8639275}]}]}
{"op":"mcm","clk":"1002739622","pt":1580598079564,"mc":[{"id":"1.168186837","rc":[{"batl":[[0,1.99,515.27],[2,95,15.9]],"ltp":1.88,"tv":1138.85,"id":8639275},{"batl":[[2,95,15.9]],"ltp":2.16,"tv":1520.96,"id":8173434}]}]}
{"op":"mcm","clk":"1002739713","pt":1580598080600,"mc":[{"id":"1.168186837","rc":[{"batl":[[0,1.98,11.04],[1,1.99,515.27],[2,2,2]],"ltp":1.88,"tv":1138.85,"id":8639275},{"batb":[[0,2.02,32.38]],"batl":[[2,2.22,2.07]],"ltp":2.16,"tv":1520.96,"id":8173434}]}]}
{"op":"mcm","clk":"1002740296","pt":1580598088613,"mc":[{"id":"1.168186837","rc":[{"batl":[[1,1.99,15.27]],"ltp":1.88,"tv":1138.85,"id":8639275}]}]}
{"op":"mcm","clk":"1002740337","pt":1580598089128,"mc":[{"id":"1.168186837","rc":[{"batl":[[0,1.98,511.04]],"ltp":1.88,"tv":1138.85,"id":8639275},{"batl":[[2,2.22,2.16]],"ltp":2.16,"tv":1520.96,"id":8173434}]}]}
{"op":"mcm","clk":"1002741080","pt":1580598100629,"mc":[{"id":"1.168186837","rc":[{"batb":[[0,1.87,59.17],[1,1.86,25.06],[2,1.85,70.57]],"ltp":1.88,"tv":1138.85,"id":8639275},{"batb":[[0,2.04,27.62],[1,2.02,32.38]],"ltp":2.16,"tv":1520.96,"id":8173434}]}]}
{"op":"mcm","clk":"1002741175","pt":1580598101565,"mc":[{"id":"1.168186837","rc":[{"trd":[[1.87,167.78]],"batb":[[0,1.87,158.82],[2,1.85,72.61]],"batl":[[1,1.99,17.48]],"ltp":1.87,"tv":1207.55,"id":8639275},{"trd":[[2.16,124.74]],"batb":[[2,2,2]],"batl":[[0,2.2,6.57],[1,2.22,2.16],[2,95,15.9]],"ltp":2.16,"tv":1611.46,"id":8173434}],"tv":2819.02}]}
{"op":"mcm","clk":"1002741277","pt":1580598102650,"mc":[{"id":"1.168186837","rc":[{"batb":[[0,1.88,10.85],[1,1.86,18.52],[2,1.85,72.74]],"ltp":1.87,"tv":1207.55,"id":8639275},{"batb":[[0,2.04,38.88]],"batl":[[2,2.24,2]],"ltp":2.16,"tv":1611.46,"id":8173434}]}]}
{"op":"mcm","clk":"1002741286","pt":1580598102753,"mc":[{"id":"1.168186837","rc":[{"batl":[[0,2.18,2.03],[1,2.2,6.57],[2,2.22,2.16]],"ltp":2.16,"tv":1611.46,"id":8173434}]}]}
{"op":"mcm","clk":"1002741391","pt":1580598104415,"mc":[{"id":"1.168186837","rc":[{"batb":[[0,1.87,147.85],[1,1.86,16.34],[2,1.85,72.57]],"ltp":1.87,"tv":1207.55,"id":8639275},{"batb":[[0,2.04,42.19]],"batl":[[0,2.2,6.57],[1,2.22,2.16],[2,2.24,2]],"ltp":2.16,"tv":1611.46,"id":8173434}]}]}
{"op":"mcm","clk":"1002741871","pt":1580598112632,"mc":[{"id":"1.168186837","rc":[{"batl":[[0,1.98,11.04]],"ltp":1.87,"tv":1207.55,"id":8639275}]}]}
{"op":"mcm","clk":"1002741905","pt":1580598113147,"mc":[{"id":"1.168186837","rc":[{"batl":[[0,1.97,500],[1,1.98,11.04],[2,1.99,17.48]],"ltp":1.87,"tv":1207.55,"id":8639275},{"batl":[[1,2.22,2.07],[2,95,15.9]],"ltp":2.16,"tv":1611.46,"id":8173434}]}]}
{"op":"mcm","clk":"1002742063","pt":1580598115429,"mc":[{"id":"1.168186837","rc":[{"batl":[[0,1.96,9.96],[1,1.97,500],[2,1.98,2.16]],"ltp":1.87,"tv":1207.55,"id":8639275}]}]}
{"op":"mcm","clk":"1002743801","pt":1580598141462,"mc":[{"id":"1.168186837","rc":[{"trd":[[1.87,357.78]],"batb":[[0,1.87,52.85]],"ltp":1.87,"tv":1397.55,"id":8639275}],"tv":3009.02}]}
{"op":"mcm","clk":"1002743875","pt":1580598142596,"mc":[{"id":"1.168186837","rc":[{"batb":[[0,1.87,97.66]],"batl":[[1,1.97,502],[2,1.98,2.25]],"ltp":1.87,"tv":1397.55,"id":8639275},{"batb":[[0,2.06,2.48],[1,2.04,42.19],[2,2.02,34.62]],"ltp":2.16,"tv":1611.46,"id":8173434}]}]}
{"op":"mcm","clk":"1002744016","pt":1580598145069,"mc":[{"id":"1.168186837","rc":[{"batb":[[0,2.06,17.52],[2,2.02,19.57]],"ltp":2.16,"tv":1611.46,"id":8173434}]}]}
{"op":"mcm","clk":"1002744665","pt":1580598155614,"mc":[{"id":"1.168186837","rc":[{"batb":[[0,1.88,16.34],[1,1.87,52.85],[2,1.86,2.18]],"batl":[[0,1.96,25.23]],"ltp":1.87,"tv":1397.55,"id":8639275},{"batl":[[0,2.18,2.03],[1,2.2,4.54]],"ltp":2.16,"tv":1611.46,"id":8173434}]}]}
{"op":"mcm","clk":"1002744675","pt":1580598155792,"mc":[{"id":"1.168186837","rc":[{"batl":[[1,2.2,6.57]],"ltp":2.16,"tv":1611.46,"id":8173434}]}]}
{"op":"mcm","clk":"1002746040","pt":1580598176533,"mc":[{"id":"1.168186837","rc":[{"trd":[[1.88,42.52]],"batb":[[0,1.88,5.08]],"batl":[[2,1.98,2.03]],"ltp":1.88,"tv":1420.08,"id":8639275},{"batb":[[0,2.06,17.23]],"ltp":2.16,"tv":1611.46,"id":8173434}],"tv":3031.55}]}
{"op":"mcm","clk":"1002746725","pt":1580598186541,"mc":[{"id":"1.168186837","rc":[{"batb":[[0,1.87,97.66],[1,1.85,72.74],[2,1.84,2]],"batl":[[0,1.96,20.76],[2,2.02,22.72]],"ltp":1.88,"tv":1420.08,"id":8639275},{"batl":[[0,2.2,4.54],[1,2.22,2.16]],"ltp":2.16,"tv":1611.46,"id":8173434}]}]}
{"op":"mcm","clk":"1002746742","pt":1580598186749,"mc":[{"id":"1.168186837","rc":[{"batl":[[2,1.98,2.17]],"ltp":1.88,"tv":1420.08,"id":8639275},{"batl":[[0,2.2,6.57]],"ltp":2.16,"tv":1611.46,"id":8173434}]}]}
{"op":"mcm","clk":"1002750168","pt":1580598233581,"mc":[{"id":"1.168186837","rc":[{"trd":[[1.87,494.82]],"batb":[[0,1.87,29.14]],"batl":[[2,1.98,2.07]],"ltp":1.87,"tv":1557.12,"id":8639275},{"batl":[[1,2.22,2.03]],"ltp":2.16,"tv":1611.46,"id":8173434}],"tv":3168.59}]}
{"op":"mcm","clk":"1002750221","pt":1580598234408,"mc":[{"id":"1.168186837","rc":[{"batb":[[0,1.86,37.18],[1,1.85,70.57],[2,1.84,2.22]],"ltp":1.87,"tv":1557.12,"id":8639275},{"batl":[[0,2.2,4.54],[2,2.24,2]],"ltp":2.16,"tv":1611.46,"id":8173434}]}]}
{"op":"mcm","clk":"1002750321","pt":1580598236186,"mc":[{"id":"1.168186837","rc":[{"batb":[[0,1.88,19.04],[1,1.86,2.18],[2,1.85,72.74]],"ltp":1.87,"tv":1557.12,"id":8639275},{"batb":[[0,2.06,38.75]],"batl":[[0,2.18,2.03],[1,2.2,6.57],[2,2.22,2.03]],"ltp":2.16,"tv":1611.46,"id":8173434}]}]}
{"op":"mcm","clk":"1002750391","pt":1580598237473,"mc":[{"id":"1.168186837","rc":[{"batb":[[2,2.02,6.24]],"ltp":2.16,"tv":1611.46,"id":8173434}]}]}
{"op":"mcm","clk":"1002750646","pt":1580598241268,"mc":[{"id":"1.168186837","rc":[{"batl":[[2,1.98,2.04]],"ltp":1.87,"tv":1557.12,"id":8639275},{"batl":[[0,2.18,2.75],[2,95,15.9]],"ltp":2.16,"tv":1611.46,"id":8173434}]}]}
{"op":"mcm","clk":"1002752047","pt":1580598263637,"mc":[{"id":"1.168186837","rc":[{"trd":[[1.88,69.38]],"batb":[[0,1.88,5.61],[2,1.85,72.61]],"batl":[[0,1.94,10.8],[1,1.96,12.08],[2,1.97,502]],"ltp":1.88,"tv":1583.98,"id":8639275}],"tv":3195.45}]}
{"op":"mcm","clk":"1002752133","pt":1580598264628,"mc":[{"id":"1.168186837","rc":[{"batb":[[0,1.86,26.4],[1,1.85,70.57],[2,1.84,2.16]],"batl":[[1,1.95,2.1],[2,1.96,12.08]],"ltp":1.88,"tv":1583.98,"id":8639275},{"batb":[[0,2.08,27.16],[1,2.06,38.75],[2,2.04,13.38]],"batl":[[0,2.2,5.26],[1,2.22,2.16],[2,2.24,2.23]],"ltp":2.16,"tv":1611.46,"id":8173434}]}]}
{"op":"mcm","clk":"1002753679","pt":1580598291560,"mc":[{"id":"1.168186837","rc":[{"trd":[[1.86,664.57]],"batb":[[0,1.86,7.99]],"ltp":1.86,"tv":1620.8,"id":8639275},{"batl":[[2,2.24,2.11]],"ltp":2.16,"tv":1611.46,"id":8173434}],"tv":3232.26}]}
{"op":"mcm","clk":"1002753785","pt":1580598293647,"mc":[{"id":"1.168186837","rc":[{"batb":[[0,1.85,70.57],[1,1.84,2.16],[2,1.83,2.03]],"ltp":1.86,"tv":1620.8,"id":8639275},{"batb":[[0,2.08,43.47]],"ltp":2.16,"tv":1611.46,"id":8173434}]}]}
{"op":"mcm","clk":"1002753801","pt":1580598293859,"mc":[{"id":"1.168186837","rc":[{"batb":[[1,1.83,2.03],[2,1.82,4.66]],"ltp":1.86,"tv":1620.8,"id":8639275}]}]}
{"op":"mcm","clk":"1002753883","pt":1580598295370,"mc":[{"id":"1.168186837","rc":[{"batl":[[0,1.95,2.1],[1,1.96,2.12],[2,1.97,500]],"ltp":1.86,"tv":1620.8,"id":8639275},{"batb":[[0,2.08,53.09],[1,2.06,24],[2,2.04,2.12]],"batl":[[0,2.2,4.54]],"ltp":2.16,"tv":1611.46,"id":8173434}]}]}
{"op":"mcm","clk":"1002754010","pt":1580598297451,"mc":[{"id":"1.168186837","rc":[{"batl":[[1,1.96,2.07]],"ltp":1.86,"tv":1620.8,"id":8639275},{"batb":[[0,2.08,43.47]],"batl":[[2,2.24,2.23]],"ltp":2.16,"tv":1611.46,"id":8173434}]}]}
{"op":"mcm","clk":"1002754093","pt":1580598298658,"mc":[{"id":"1.168186837","rc":[{"batl":[[1,1.96,10.93]],"ltp":1.86,"tv":1620.8,"id":8639275}]}]}
{"op":"mcm","clk":"1002754814","pt":1580598310452,"mc":[{"id":"1.168186837","rc":[{"batb":[[2,2.04,11.93]],"ltp":2.16,"tv":1611.46,"id":8173434}]}]}
{"op":"mcm","clk":"1002754840","pt":1580598310979,"mc":[{"id":"1.168186837","rc":[{"batl":[[1,1.96,10.96]],"ltp":1.86,"tv":1620.8,"id":8639275},{"batl":[[2,2.24,2.11]],"ltp":2.16,"tv":1611.46,"id":8173434}]}]}
{"op":"mcm","clk":"1002755873","pt":1580598327588,"mc":[{"id":"1.168186837","rc":[{"trd":[[1.85,197.48],[1.86,667.41]],"batb":[[0,1.85,22.84]],"batl":[[0,1.94,10.91],[1,1.95,2.1],[2,1.96,10.98]],"ltp":1.85,"tv":1719.1,"id":8639275},{"trd":[[2.16,125.55]],"batb":[[1,2.06,38.75]],"batl":[[2,2.24,2.19]],"ltp":2.16,"tv":1612.28,"id":8173434}],"tv":3331.39}]}
{"op":"mcm","clk":"1002755907","pt":1580598328203,"mc":[{"id":"1.168186837","rc":[{"batl":[[2,1.96,2.12]],"ltp":1.85,"tv":1719.1,"id":8639275},{"batb":[[2,2.04,2.12]],"ltp":2.16,"tv":1612.28,"id":8173434}]}]}
{"op":"mcm","clk":"1002758546","pt":1580598367668,"mc":[{"id":"1.168186837","rc":[{"trd":[[1.85,228.72]],"batb":[[0,1.85,7.22],[1,1.83,42.64]],"ltp":1.85,"tv":1750.34,"id":8639275},{"batl":[[2,2.24,2.03]],"ltp":2.16,"tv":1612.28,"id":8173434}],"tv":3362.63}]}
{"op":"mcm","clk":"1002759164","pt":1580598377252,"mc":[{"id":"1.168186837","rc":[{"batb":[[0,2.08,53.09]],"ltp":2.16,"tv":1612.28,"id":8173434}]}]}
{"op":"mcm","clk":"1002759203","pt":1580598377977,"mc":[{"id":"1.168186837","rc":[{"batl":[[2,1.96,2.02]],"ltp":1.85,"tv":1750.34,"id":8639275},{"batl":[[2,2.24,2.23]],"ltp":2.16,"tv":1612.28,"id":8173434}]}]}
{"op":"mcm","clk":"1002759561","pt":1580598383677,"mc":[{"id":"1.168186837","rc":[{"batl":[[2,1.96,2.12]],"ltp":1.85,"tv":1750.34,"id":8639275}]}]}
{"op":"mcm","clk":"1002760630","pt":1580598400692,"mc":[{"id":"1.168186837","rc":[{"trd":[[1.85,238.66]],"batb":[[0,1.85,2.24],[2,1.82,2.63]],"batl":[[0,1.92,10.91],[2,1.97,500]],"ltp":1.85,"tv":1760.29,"id":8639275},{"batl":[[2,95,15.9]],"ltp":2.16,"tv":1612.28,"id":8173434}],"tv":3372.57}]}
{"op":"mcm","clk":"1002760682","pt":1580598401169,"mc":[{"id":"1.168186837","rc":[{"batb":[[2,1.82,4.66]],"batl":[[1,1.94,2.05],[2,1.95,2.1]],"ltp":1.85,"tv":1760.29,"id":8639275},{"batl":[[1,2.24,2.23],[2,2.26,2.02]],"ltp":2.16,"tv":1612.28,"id":8173434}]}]}
{"op":"mcm","clk":"1002761935","pt":1580598417675,"mc":[{"id":"1.168186837","rc":[{"batl":[[1,1.93,2.07],[2,1.94,2.05]],"ltp":1.85,"tv":1760.29,"id":8639275},{"batb":[[0,2.1,14.75],[1,2.08,53.09],[2,2.06,26.08]],"ltp":2.16,"tv":1612.28,"id":8173434}]}]}
{"op":"mcm","clk":"1002761955","pt":1580598417986,"mc":[{"id":"1.168186837","rc":[{"batl":[[2,1.94,2.08]],"ltp":1.85,"tv":1760.29,"id":8639275}]}]}
{"op":"mcm","clk":"1002764408","pt":1580598452630,"mc":[{"id":"1.168186837","rc":[{"batl":[[0,1.92,11.94]],"ltp":1.85,"tv":1760.29,"id":8639275},{"batb":[[0,2.1,14.47]],"ltp":2.16,"tv":1612.28,"id":8173434}]}]}
{"op":"mcm","clk":"1002767876","pt":1580598498508,"mc":[{"id":"1.168186837","rc":[{"batl":[[2,1.94,2.06]],"ltp":1.85,"tv":1760.29,"id":8639275},{"batb":[[0,2.1,23.01],[2,2.06,2.08]],"ltp":2.16,"tv":1612.28,"id":8173434}]}]}
{"op":"mcm","clk":"1002767911","pt":1580598498818,"mc":[{"id":"1.168186837","rc":[{"batb":[[1,2.08,43.47]],"ltp":2.16,"tv":1612.28,"id":8173434}]}]}
{"op":"mcm","clk":"1002768939","pt":1580598513336,"mc":[{"id":"1.168186837","rc":[{"batl":[[2,1.94,2.08]],"ltp":1.85,"tv":1760.29,"id":8639275}]}]}
{"op":"mcm","clk":"1002770320","pt":1580598533373,"mc":[{"id":"1.168186837","rc":[{"batl":[[2,1.94,2.07]],"ltp":1.85,"tv":1760.29,"id":8639275}]}]}
{"op":"mcm","clk":"1002779722","pt":1580598664504,"mc":[{"id":"1.168186837","rc":[{"batl":[[2,1.94,2.08]],"ltp":1.85,"tv":1760.29,"id":8639275}]}]}
{"op":"mcm","clk":"1002785782","pt":1580598742526,"mc":[{"id":"1.168186837","rc":[{"batb":[[1,1.84,9.69],[2,1.83,42.64]],"batl":[[1,1.94,2.08],[2,1.95,2.1]],"ltp":1.85,"tv":1760.29,"id":8639275},{"trd":[[2.1,131.31]],"batb":[[0,2.08,43.47],[1,2.04,2.12],[2,2.02,6.19]],"batl":[[2,2.26,2]],"ltp":2.1,"tv":1659.47,"id":8173434}],"tv":3419.76}]}
{"op":"mcm","clk":"1002785804","pt":1580598742823,"mc":[{"id":"1.168186837","rc":[{"batb":[[1,2.04,11.93]],"ltp":2.1,"tv":1659.47,"id":8173434}]}]}
{"op":"mcm","clk":"1002791303","pt":1580598813678,"mc":[{"id":"1.168186837","rc":[{"batb":[[0,2.1,14.47],[1,2.08,43.47],[2,2.06,2.08]],"ltp":2.1,"tv":1659.47,"id":8173434}]}]}
{"op":"mcm","clk":"1002791389","pt":1580598814571,"mc":[{"id":"1.168186837","rc":[{"batl":[[1,1.93,2.07],[2,1.94,2.08]],"ltp":1.85,"tv":1760.29,"id":8639275},{"batl":[[2,2.26,2.02]],"ltp":2.1,"tv":1659.47,"id":8173434}]}]}
{"op":"mcm","clk":"1002798250","pt":1580598902690,"mc":[{"id":"1.168186837","rc":[{"batl":[[2,1.97,500]],"ltp":1.85,"tv":1760.29,"id":8639275}]}]}
{"op":"mcm","clk":"1002798266","pt":1580598902849,"mc":[{"id":"1.168186837","rc":[{"batl":[[2,1.94,2.01]],"ltp":1.85,"tv":1760.29,"id":8639275}]}]}
{"op":"mcm","clk":"1002830448","pt":1580599344291,"mc":[{"id":"1.168186837","rc":[{"batl":[[2,1.94,2.08]],"ltp":1.85,"tv":1760.29,"id":8639275}]}]}
{"op":"mcm","clk":"1002866813","pt":1580599827583,"mc":[{"id":"1.168186837","rc":[{"batl":[[0,2.18,13.94],[1,2.2,4.54],[2,2.24,2.23]],"ltp":2.1,"tv":1659.47,"id":8173434}]}]}
{"op":"mcm","clk":"1002866887","pt":1580599828295,"mc":[{"id":"1.168186837","rc":[{"batl":[[2,2.22,2.03]],"ltp":2.1,"tv":1659.47,"id":8173434}]}]}
{"op":"mcm","clk":"1002871325","pt":1580599881646,"mc":[{"id":"1.168186837","rc":[{"batl":[[2,2.28,18.48]],"ltp":1.85,"tv":1760.29,"id":8639275}]}]}
{"op":"mcm","clk":"1002871395","pt":1580599882532,"mc":[{"id":"1.168186837","rc":[{"batl":[[2,1.94,2.08]],"ltp":1.85,"tv":1760.29,"id":8639275},{"trd":[[2.18,19.53]],"batl":[[0,2.18,4.18]],"ltp":2.18,"tv":1679.0,"id":8173434}],"tv":3439.29}]}
{"op":"mcm","clk":"1002871734","pt":1580599887053,"mc":[{"id":"1.168186837","rc":[{"batb":[[0,2.1,10.97]],"batl":[[0,2.2,4.54],[1,2.24,2.23],[2,2.26,2.02]],"ltp":2.18,"tv":1679.0,"id":8173434}]}]}
{"op":"mcm","clk":"1002880053","pt":1580600000671,"mc":[{"id":"1.168186837","rc":[{"trd":[[2.18,27.07]],"batl":[[0,2.18,1.29],[1,2.2,4.54],[2,2.22,2.07]],"ltp":2.18,"tv":1686.54,"id":8173434}],"tv":3446.83}]}
{"op":"mcm","clk":"1002880068","pt":1580600000982,"mc":[{"id":"1.168186837","rc":[{"batl":[[2,2.22,2.16]],"ltp":2.18,"tv":1686.54,"id":8173434}]}]}
{"op":"mcm","clk":"1002880862","pt":1580600013329,"mc":[{"id":"1.168186837","rc":[{"batb":[[0,2.1,14.47]],"batl":[[0,2.2,4.54],[1,2.24,2.23],[2,2.26,2.02]],"ltp":2.18,"tv":1686.54,"id":8173434}]}]}
{"op":"mcm","clk":"1002888836","pt":1580600131391,"mc":[{"id":"1.168186837","rc":[{"batl":[[0,2.18,1.43],[1,2.2,4.54],[2,2.22,2.16]],"ltp":2.18,"tv":1686.54,"id":8173434}]}]}
{"op":"mcm","clk":"1002910053","pt":1580600456634,"mc":[{"id":"1.168186837","rc":[{"batl":[[0,1.93,2.07],[1,2.28,18.48],[2,95,15.9]],"ltp":1.85,"tv":1760.29,"id":8639275},{"batb":[[0,2.08,43.47],[1,2.04,2.12],[2,2.02,2.24]],"batl":[[0,2.2,4.54],[1,2.24,2.11],[2,2.26,2.02]],"ltp":2.18,"tv":1686.54,"id":8173434}]}]}
{"op":"mcm","clk":"1002910084","pt":1580600456898,"mc":[{"id":"1.168186837","rc":[{"batl":[[0,1.95,2],[1,1.96,2.12],[2,2.28,18.48]],"ltp":1.85,"tv":1760.29,"id":8639275}]}]}
{"op":"mcm","clk":"1002910191","pt":1580600458612,"mc":[{"id":"1.168186837","rc":[{"batl":[[0,1.92,11.94],[1,1.93,2.04],[2,1.94,2.08]],"ltp":1.85,"tv":1760.29,"id":8639275},{"batb":[[0,2.1,14.47],[1,2.08,43.47],[2,2.06,2.08]],"ltp":2.18,"tv":1686.54,"id":8173434}]}]}
{"op":"mcm","clk":"1002910266","pt":1580600459539,"mc":[{"id":"1.168186837","rc":[{"batl":[[0,2.18,1.78],[1,2.2,4.54],[2,2.22,2]],"ltp":2.18,"tv":1686.54,"id":8173434}]}]}
{"op":"mcm","clk":"1002913591","pt":1580600511640,"mc":[{"id":"1.168186837","marketDefinition":{"bspMarket":false,"turnInPlayEnabled":true,"persistenceEnabled":true,"marketBaseRate":5.0,"eventId":"29680287","eventTypeId":"2","numberOfWinners":1,"bettingType":"ODDS","marketType":"MATCH_ODDS","marketTime":"2020-02-02T02:30:00.000Z","suspendTime":"2020-02-02T02:30:00.000Z","bspReconciled":false,"complete":true,"inPlay":false,"crossMatching":true,"runnersVoidable":false,"numberOfActiveRunners":2,"betDelay":0,"status":"OPEN","runners":[{"status":"ACTIVE","sortPriority":1,"id":8173434,"name":"Taro Daniel"},{"status":"ACTIVE","sortPriority":2,"id":8639275,"name":"Yannick Hanfmann"}],"regulators":["MR_INT"],"countryCode":"AU","discountAllowed":true,"timezone":"UTC","openDate":"2020-02-02T02:00:00.000Z","version":3147850873,"name":"Match Odds","eventName":"Daniel v Hanfmann"}}]}
{"op":"mcm","clk":"1002913961","pt":1580600516653,"mc":[{"id":"1.168186837","marketDefinition":{"bspMarket":false,"turnInPlayEnabled":true,"persistenceEnabled":true,"marketBaseRate":5.0,"eventId":"29680287","eventTypeId":"2","numberOfWinners":1,"bettingType":"ODDS","marketType":"MATCH_ODDS","marketTime":"2020-02-02T02:30:00.000Z","suspendTime":"2020-02-02T02:30:00.000Z","bspReconciled":false,"complete":true,"inPlay":false,"crossMatching":true,"runnersVoidable":false,"numberOfActiveRunners":2,"betDelay":0,"status":"OPEN","runners":[{"status":"ACTIVE","sortPriority":1,"id":8173434,"name":"Taro Daniel"},{"status":"ACTIVE","sortPriority":2,"id":8639275,"name":"Yannick Hanfmann"}],"regulators":["MR_INT"],"countryCode":"AU","discountAllowed":true,"timezone":"UTC","openDate":"2020-02-02T02:30:00.000Z","version":3147850873,"name":"Match Odds","eventName":"Daniel v Hanfmann"}}]}
{"op":"mcm","clk":"1002919479","pt":1580600594299,"mc":[{"id":"1.168186837","rc":[{"batl":[[2,1.94,4.16]],"ltp":1.85,"tv":1760.29,"id":8639275}]}]}
{"op":"mcm","clk":"1002942247","pt":1580600950683,"mc":[{"id":"1.168186837","rc":[{"trd":[[1.91,50.07]],"batb":[[0,1.89,2],[1,1.88,2],[2,1.85,2.24]],"batl":[[1,1.94,2.08],[2,1.95,2.1]],"ltp":1.91,"tv":1810.36,"id":8639275},{"trd":[[2.1,145.79]],"batb":[[0,2.08,43.47],[1,2.04,2.12],[2,2.02,2.22]],"ltp":2.1,"tv":1701.01,"id":8173434}],"tv":3511.37}]}
{"op":"mcm","clk":"1002942335","pt":1580600951672,"mc":[{"id":"1.168186837","rc":[{"batb":[[0,1.85,2.24],[1,1.84,9.69],[2,1.83,42.64]],"ltp":1.91,"tv":1810.36,"id":8639275},{"batl":[[2,2.22,2.07]],"ltp":2.1,"tv":1701.01,"id":8173434}]}]}
{"op":"mcm","clk":"1002947535","pt":1580601029344,"mc":[{"id":"1.168186837","rc":[{"batl":[[0,1.95,2.1],[1,1.96,2.12],[2,2.28,18.48]],"ltp":1.91,"tv":1810.36,"id":8639275},{"batb":[[2,2.02,2.09]],"batl":[[0,2.2,4.54],[1,2.24,2.23],[2,2.26,2.02]],"ltp":2.1,"tv":1701.01,"id":8173434}]}]}
{"op":"mcm","clk":"1002947677","pt":1580601031355,"mc":[{"id":"1.168186837","rc":[{"batl":[[0,1.92,11.94],[1,1.93,2.07],[2,1.94,2.08]],"ltp":1.91,"tv":1810.36,"id":8639275},{"batb":[[0,2.1,14.47],[1,2.08,43.47],[2,2.06,2.08]],"batl":[[0,2.18,13.94],[1,2.2,4.54],[2,2.22,2.07]],"ltp":2.1,"tv":1701.01,"id":8173434}]}]}
{"op":"mcm","clk":"1002948221","pt":1580601039679,"mc":[{"id":"1.168186837","rc":[{"batl":[[2,1.94,2]],"ltp":1.91,"tv":1810.36,"id":8639275},{"trd":[[2.18,46.14]],"batl":[[0,2.18,4.41]],"ltp":2.18,"tv":1720.08,"id":8173434}],"tv":3530.45}]}
{"op":"mcm","clk":"1002948238","pt":1580601039987,"mc":[{"id":"1.168186837","rc":[{"batb":[[0,2.1,10.31]],"ltp":2.18,"tv":1720.08,"id":8173434}]}]}
{"op":"mcm","clk":"1002949007","pt":1580601051470,"mc":[{"id":"1.168186837","rc":[{"batl":[[0,2.2,4.54],[1,2.24,2.23],[2,2.26,2.02]],"ltp":2.18,"tv":1720.08,"id":8173434}]}]}
{"op":"mcm","clk":"1002949083","pt":1580601052558,"mc":[{"id":"1.168186837","rc":[{"batl":[[2,2.28,18.48]],"ltp":1.91,"tv":1810.36,"id":8639275}]}]}
{"op":"mcm","clk":"1002949130","pt":1580601053179,"mc":[{"id":"1.168186837","rc":[{"batl":[[2,1.94,2.08]],"ltp":1.91,"tv":1810.36,"id":8639275}]}]}
{"op":"mcm","clk":"1002949266","pt":1580601055469,"mc":[{"id":"1.168186837","rc":[{"batb":[[0,1.85,9.37]],"ltp":1.91,"tv":1810.36,"id":8639275},{"batl":[[1,2.22,2.03],[2,2.24,2.23]],"ltp":2.18,"tv":1720.08,"id":8173434}]}]}
{"op":"mcm","clk":"1002950719","pt":1580601075542,"mc":[{"id":"1.168186837","rc":[{"batb":[[0,1.85,2.24],[1,1.84,16.81]],"ltp":1.91,"tv":1810.36,"id":8639275},{"batl":[[1,2.24,2.23],[2,2.26,2.02]],"ltp":2.18,"tv":1720.08,"id":8173434}]}]}
{"op":"mcm","clk":"1002956041","pt":1580601147627,"mc":[{"id":"1.168186837","rc":[{"batl":[[2,1.94,2.04]],"ltp":1.91,"tv":1810.36,"id":8639275},{"batl":[[0,2.18,6.92],[1,2.2,4.54],[2,2.22,2.03]],"ltp":2.18,"tv":1720.08,"id":8173434}]}]}
{"op":"mcm","clk":"1002959816","pt":1580601203698,"mc":[{"id":"1.168186837","rc":[{"batl":[[2,1.94,2.06]],"ltp":1.91,"tv":1810.36,"id":8639275},{"trd":[[2.18,55]],"batl":[[0,2.18,2.5]],"ltp":2.18,"tv":1728.94,"id":8173434}],"tv":3539.3}]}
{"op":"mcm","clk":"1002960289","pt":1580601210613,"mc":[{"id":"1.168186837","rc":[{"batb":[[1,1.84,11.79]],"batl":[[2,1.94,2]],"ltp":1.91,"tv":1810.36,"id":8639275},{"batb":[[0,2.1,14.47]],"batl":[[0,2.2,4.54],[1,2.24,2.23],[2,2.26,2.02]],"ltp":2.18,"tv":1728.94,"id":8173434}]}]}
{"op":"mcm","clk":"1002960881","pt":1580601218683,"mc":[{"id":"1.168186837","rc":[{"batb":[[1,1.84,9.69]],"batl":[[2,1.94,2.08]],"ltp":1.91,"tv":1810.36,"id":8639275}]}]}
{"op":"mcm","clk":"1002968312","pt":1580601328665,"mc":[{"id":"1.168186837","rc":[{"batl":[[0,2.2,5.3],[1,2.22,2.16],[2,2.24,2.23]],"ltp":2.18,"tv":1728.94,"id":8173434}]}]}
{"op":"mcm","clk":"1002989361","pt":1580601615603,"mc":[{"id":"1.168186837","rc":[{"batl":[[2,2.28,18.48]],"ltp":1.91,"tv":1810.36,"id":8639275},{"trd":[[2.1,155.53]],"batb":[[0,2.1,9.6]],"batl":[[2,2.28,18.48]],"ltp":2.1,"tv":1738.69,"id":8173434}],"tv":3549.05}]}
{"op":"mcm","clk":"1002989419","pt":1580601616582,"mc":[{"id":"1.168186837","rc":[{"batl":[[2,1.94,4.1]],"ltp":1.91,"tv":1810.36,"id":8639275},{"batb":[[0,2.1,5.16]],"batl":[[2,2.24,4.46]],"ltp":2.1,"tv":1738.69,"id":8173434}]}]}
{"op":"mcm","clk":"1002992014","pt":1580601656546,"mc":[{"id":"1.168186837","rc":[{"batb":[[0,2.1,10.03]],"ltp":2.1,"tv":1738.69,"id":8173434}]}]}
{"op":"mcm","clk":"1002992058","pt":1580601657062,"mc":[{"id":"1.168186837","rc":[{"batl":[[2,1.94,2.08]],"ltp":1.91,"tv":1810.36,"id":8639275},{"batl":[[2,2.24,2.15]],"ltp":2.1,"tv":1738.69,"id":8173434}]}]}
{"op":"mcm","clk":"1002993668","pt":1580601682581,"mc":[{"id":"1.168186837","rc":[{"batl":[[1,2.24,2.15],[2,2.26,2.02]],"ltp":2.1,"tv":1738.69,"id":8173434}]}]}
{"op":"mcm","clk":"1003019790","pt":1580602051644,"mc":[{"id":"1.168186837","rc":[{"batb":[[0,1.85,6.17],[1,1.84,13.64]],"batl":[[0,1.91,3.81],[1,1.92,15.72],[2,1.93,2.07]],"ltp":1.91,"tv":1810.36,"id":8639275},{"batb":[[0,2.12,3.43],[1,2.1,13.5],[2,2.08,45.53]],"batl":[[0,2.2,8.61],[1,2.22,3.27],[2,2.24,2.15]],"ltp":2.1,"tv":1738.69,"id":8173434}]}]}
{"op":"mcm","clk":"1003019885","pt":1580602052676,"mc":[{"id":"1.168186837","rc":[{"trd":[[1.85,247.8]],"batb":[[0,1.84,13.64],[1,1.83,44.58],[2,1.82,4.66]],"batl":[[1,1.92,17.78]],"ltp":1.85,"tv":1819.5,"id":8639275},{"batl":[[2,2.24,2.23]],"ltp":2.1,"tv":1738.69,"id":8173434}],"tv":3558.19}]}
{"op":"mcm","clk":"1003020234","pt":1580602056261,"mc":[{"id":"1.168186837","rc":[{"batl":[[0,1.9,11.94],[1,1.91,3.81],[2,1.92,5.84]],"ltp":1.85,"tv":1819.5,"id":8639275}]}]}
{"op":"mcm","clk":"1003020362","pt":1580602057567,"mc":[{"id":"1.168186837","rc":[{"batl":[[0,1.9,15.77]],"ltp":1.85,"tv":1819.5,"id":8639275},{"batb":[[1,2.1,23.03]],"ltp":2.1,"tv":1738.69,"id":8173434}]}]}
{"op":"mcm","clk":"1003020462","pt":1580602058507,"mc":[{"id":"1.168186837","rc":[{"batl":[[0,1.89,3.85],[1,1.9,15.77],[2,1.91,5.86]],"ltp":1.85,"tv":1819.5,"id":8639275}]}]}
{"op":"mcm","clk":"1003021321","pt":1580602066675,"mc":[{"id":"1.168186837","rc":[{"batb":[[1,2.1,13]],"ltp":2.1,"tv":1738.69,"id":8173434}]}]}
{"op":"mcm","clk":"1003021422","pt":1580602067599,"mc":[{"id":"1.168186837","rc":[{"batb":[[0,1.85,3.92],[1,1.84,13.64],[2,1.83,44.58]],"ltp":1.85,"tv":1819.5,"id":8639275},{"batb":[[1,2.1,3.46]],"ltp":2.1,"tv":1738.69,"id":8173434}]}]}
{"op":"mcm","clk":"1003021514","pt":1580602068282,"mc":[{"id":"1.168186837","rc":[{"batb":[[2,1.83,46.61]],"ltp":1.85,"tv":1819.5,"id":8639275},{"batl":[[1,2.22,5.43]],"ltp":2.1,"tv":1738.69,"id":8173434}]}]}
{"op":"mcm","clk":"1003023081","pt":1580602084326,"mc":[{"id":"1.168186837","rc":[{"batl":[[1,2.22,3.27]],"ltp":2.1,"tv":1738.69,"id":8173434}]}]}
{"op":"mcm","clk":"1003023787","pt":1580602091515,"mc":[{"id":"1.168186837","rc":[{"batb":[[2,2.08,2.06]],"ltp":2.1,"tv":1738.69,"id":8173434}]}]}
{"op":"mcm","clk":"1003025668","pt":1580602110639,"mc":[{"id":"1.168186837","rc":[{"batl":[[1,1.9,17.82]],"ltp":1.85,"tv":1819.5,"id":8639275},{"batb":[[0,2.14,9.85],[1,2.12,3.43],[2,2.1,5.5]],"ltp":2.1,"tv":1738.69,"id":8173434}]}]}
{"op":"mcm","clk":"1003025733","pt":1580602111252,"mc":[{"id":"1.168186837","rc":[{"batb":[[0,2.14,13.24]],"ltp":2.1,"tv":1738.69,"id":8173434}]}]}
{"op":"mcm","clk":"1003026871","pt":1580602123603,"mc":[{"id":"1.168186837","rc":[{"batl":[[0,1.88,11.94],[1,1.89,3.85],[2,1.9,5.87]],"ltp":1.85,"tv":1819.5,"id":8639275}]}]}
{"op":"mcm","clk":"1003026975","pt":1580602124690,"mc":[{"id":"1.168186837","rc":[{"batl":[[0,1.88,15.81]],"ltp":1.85,"tv":1819.5,"id":8639275}]}]}
{"op":"mcm","clk":"1003027055","pt":1580602125470,"mc":[{"id":"1.168186837","rc":[{"batl":[[0,1.87,3.89],[1,1.88,15.81],[2,1.89,5.89]],"ltp":1.85,"tv":1819.5,"id":8639275}]}]}
{"op":"mcm","clk":"1003028654","pt":1580602143612,"mc":[{"id":"1.168186837","rc":[{"batb":[[0,1.85,8.42]],"batl":[[0,1.87,6.89]],"ltp":1.85,"tv":1819.5,"id":8639275}]}]}
{"op":"mcm","clk":"1003028737","pt":1580602144608,"mc":[{"id":"1.168186837","rc":[{"batl":[[1,2.22,5.43],[2,2.28,18.48]],"ltp":2.1,"tv":1738.69,"id":8173434}]}]}
{"op":"mcm","clk":"1003028745","pt":1580602144714,"mc":[{"id":"1.168186837","rc":[{"batl":[[2,2.24,2.03]],"ltp":2.1,"tv":1738.69,"id":8173434}]}]}
{"op":"mcm","clk":"1003032937","pt":1580602189679,"mc":[{"id":"1.168186837","rc":[{"batl":[[0,1.87,18.83],[1,1.88,3.86]],"ltp":1.85,"tv":1819.5,"id":8639275},{"batb":[[0,2.16,9.85],[1,2.14,3.39],[2,2.12,3.43]],"batl":[[0,2.18,3.34],[1,2.2,14.12],[2,2.22,5.43]],"ltp":2.1,"tv":1738.69,"id":8173434}]}]}
{"op":"mcm","clk":"1003033028","pt":1580602190576,"mc":[{"id":"1.168186837","rc":[{"batb":[[0,1.85,4.5]],"batl":[[0,1.86,3.92],[1,1.87,18.83],[2,1.88,3.86]],"ltp":1.85,"tv":1819.5,"id":8639275},{"batb":[[0,2.16,13.22],[2,2.12,5.47]],"ltp":2.1,"tv":1738.69,"id":8173434}]}]}
{"op":"mcm","clk":"1003033081","pt":1580602191156,"mc":[{"id":"1.168186837","rc":[{"batl":[[2,1.88,5.9]],"ltp":1.85,"tv":1819.5,"id":8639275}]}]}
{"op":"mcm","clk":"1003035413","pt":1580602217617,"mc":[{"id":"1.168186837","rc":[{"trd":[[1.86,675.24]],"batb":[[1,1.84,3.95]],"batl":[[0,1.87,18.83],[1,1.88,3.86],[2,1.89,5.89]],"ltp":1.86,"tv":1827.33,"id":8639275},{"trd":[[2.16,145.54]],"batb":[[0,2.16,3.23]],"ltp":2.16,"tv":1758.68,"id":8173434}],"tv":3586.01}]}
{"op":"mcm","clk":"1003035493","pt":1580602218552,"mc":[{"id":"1.168186837","rc":[{"trd":[[1.85,253.92]],"batb":[[0,1.85,1.44],[2,1.83,38.66]],"ltp":1.85,"tv":1833.45,"id":8639275},{"batb":[[0,2.14,3.39],[1,2.12,3.43],[2,2.1,5.5]],"ltp":2.16,"tv":1758.68,"id":8173434}],"tv":3592.13}]}
{"op":"mcm","clk":"1003036392","pt":1580602228653,"mc":[{"id":"1.168186837","rc":[{"batl":[[0,1.87,19.15]],"ltp":1.85,"tv":1833.45,"id":8639275}]}]}
{"op":"mcm","clk":"1003040317","pt":1580602270608,"mc":[{"id":"1.168186837","rc":[{"batb":[[0,2.14,7.66]],"ltp":2.16,"tv":1758.68,"id":8173434}]}]}
{"op":"mcm","clk":"1003041902","pt":1580602289661,"mc":[{"id":"1.168186837","rc":[{"batb":[[0,2.14,17.6]],"ltp":2.16,"tv":1758.68,"id":8173434}]}]}
{"op":"mcm","clk":"1003045758","pt":1580602332393,"mc":[{"id":"1.168186837","rc":[{"trd":[[2.18,59.62]],"batl":[[0,2.18,1.03],[2,2.22,5.27]],"ltp":2.18,"tv":1763.3,"id":8173434}],"tv":3596.75}]}
{"op":"mcm","clk":"1003045873","pt":1580602333545,"mc":[{"id":"1.168186837","rc":[{"batl":[[0,1.86,3.92],[1,1.87,19.15],[2,1.88,5.9]],"ltp":1.85,"tv":1833.45,"id":8639275},{"batb":[[0,2.16,3.38],[1,2.14,17.6],[2,2.12,5.47]],"batl":[[0,2.2,14.12],[1,2.22,3.27],[2,2.24,2.23]],"ltp":2.18,"tv":1763.3,"id":8173434}]}]}
{"op":"mcm","clk":"1003045982","pt":1580602334631,"mc":[{"id":"1.168186837","rc":[{"batl":[[1,1.87,6.89]],"ltp":1.85,"tv":1833.45,"id":8639275}]}]}
{"op":"mcm","clk":"1003045995","pt":1580602334735,"mc":[{"id":"1.168186837","rc":[{"batb":[[2,1.83,55.27]],"ltp":1.85,"tv":1833.45,"id":8639275}]}]}
{"op":"mcm","clk":"1003046252","pt":1580602337400,"mc":[{"id":"1.168186837","rc":[{"batb":[[1,2.14,3.39]],"ltp":2.18,"tv":1763.3,"id":8173434}]}]}
{"op":"mcm","clk":"1003049634","pt":1580602375391,"mc":[{"id":"1.168186837","rc":[{"batl":[[0,1.86,16.24]],"ltp":1.85,"tv":1833.45,"id":8639275}]}]}
{"op":"mcm","clk":"1003053102","pt":1580602410694,"mc":[{"id":"1.168186837","rc":[{"batb":[[1,1.84,20.56],[2,1.83,38.66]],"ltp":1.85,"tv":1833.45,"id":8639275}]}]}
{"op":"mcm","clk":"1003060585","pt":1580602489616,"mc":[{"id":"1.168186837","rc":[{"batb":[[2,1.83,3.97]],"ltp":1.85,"tv":1833.45,"id":8639275}]}]}
{"op":"mcm","clk":"1003061656","pt":1580602501230,"mc":[{"id":"1.168186837","rc":[{"batb":[[1,1.84,3.95],[2,1.83,20.58]],"ltp":1.85,"tv":1833.45,"id":8639275},{"batl":[[0,2.2,7.85]],"ltp":2.18,"tv":1763.3,"id":8173434}]}]}
{"op":"mcm","clk":"1003071724","pt":1580602612426,"mc":[{"id":"1.168186837","marketDefinition":{"bspMarket":false,"turnInPlayEnabled":true,"persistenceEnabled":true,"marketBaseRate":5.0,"eventId":"29680287","eventTypeId":"2","numberOfWinners":1,"bettingType":"ODDS","marketType":"MATCH_ODDS","marketTime":"2020-02-02T03:00:00.000Z","suspendTime":"2020-02-02T03:00:00.000Z","bspReconciled":false,"complete":true,"inPlay":false,"crossMatching":true,"runnersVoidable":false,"numberOfActiveRunners":2,"betDelay":0,"status":"OPEN","runners":[{"status":"ACTIVE","sortPriority":1,"id":8173434,"name":"Taro Daniel"},{"status":"ACTIVE","sortPriority":2,"id":8639275,"name":"Yannick Hanfmann"}],"regulators":["MR_INT"],"countryCode":"AU","discountAllowed":true,"timezone":"UTC","openDate":"2020-02-02T02:30:00.000Z","version":3147905865,"name":"Match Odds","eventName":"Daniel v Hanfmann"}}]}
{"op":"mcm","clk":"1003071944","pt":1580602615018,"mc":[{"id":"1.168186837","marketDefinition":{"bspMarket":false,"turnInPlayEnabled":true,"persistenceEnabled":true,"marketBaseRate":5.0,"eventId":"29680287","eventTypeId":"2","numberOfWinners":1,"bettingType":"ODDS","marketType":"MATCH_ODDS","marketTime":"2020-02-02T03:00:00.000Z","suspendTime":"2020-02-02T03:00:00.000Z","bspReconciled":false,"complete":true,"inPlay":false,"crossMatching":true,"runnersVoidable":false,"numberOfActiveRunners":2,"betDelay":0,"status":"OPEN","runners":[{"status":"ACTIVE","sortPriority":1,"id":8173434,"name":"Taro Daniel"},{"status":"ACTIVE","sortPriority":2,"id":8639275,"name":"Yannick Hanfmann"}],"regulators":["MR_INT"],"countryCode":"AU","discountAllowed":true,"timezone":"UTC","openDate":"2020-02-02T03:00:00.000Z","version":3147905865,"name":"Match Odds","eventName":"Daniel v Hanfmann"}}]}
{"op":"mcm","clk":"1003072854","pt":1580602624040,"mc":[{"id":"1.168186837","rc":[{"batb":[[1,1.84,27.58]],"ltp":1.85,"tv":1833.45,"id":8639275}]}]}
{"op":"mcm","clk":"1003072936","pt":1580602624822,"mc":[{"id":"1.168186837","rc":[{"batb":[[1,1.84,44.19],[2,1.83,3.97]],"ltp":1.85,"tv":1833.45,"id":8639275},{"batl":[[0,2.2,21.66]],"ltp":2.18,"tv":1763.3,"id":8173434}]}]}
{"op":"mcm","clk":"1003080015","pt":1580602706474,"mc":[{"id":"1.168186837","rc":[{"batb":[[1,1.84,27.58]],"batl":[[0,1.86,3.92]],"ltp":1.85,"tv":1833.45,"id":8639275},{"batl":[[0,2.2,7.85]],"ltp":2.18,"tv":1763.3,"id":8173434}]}]}
{"op":"mcm","clk":"1003080115","pt":1580602707870,"mc":[{"id":"1.168186837","rc":[{"batb":[[1,1.84,44.1]],"batl":[[0,1.86,16.24]],"ltp":1.85,"tv":1833.45,"id":8639275},{"batl":[[0,2.2,21.66]],"ltp":2.18,"tv":1763.3,"id":8173434}]}]}
{"op":"mcm","clk":"1003128404","pt":1580603348669,"mc":[{"id":"1.168186837","rc":[{"trd":[[1.84,126.45],[1.85,256.8]],"batb":[[0,1.84,35.93],[1,1.83,3.97],[2,1.82,4.66]],"ltp":1.84,"tv":1852.67,"id":8639275}],"tv":3615.97}]}
{"op":"mcm","clk":"1003128471","pt":1580603349545,"mc":[{"id":"1.168186837","rc":[{"batb":[[2,1.82,8.64]],"batl":[[0,1.85,3.91],[1,1.86,16.24],[2,1.87,8.92]],"ltp":1.84,"tv":1852.67,"id":8639275}]}]}
{"op":"mcm","clk":"1003134417","pt":1580603422642,"mc":[{"id":"1.168186837","rc":[{"batb":[[0,1.84,39.87]],"batl":[[0,1.86,16.24],[1,1.87,6.89],[2,1.88,5.9]],"ltp":1.84,"tv":1852.67,"id":8639275}]}]}
{"op":"mcm","clk":"1003139265","pt":1580603480634,"mc":[{"id":"1.168186837","rc":[{"trd":[[1.86,707.59]],"batl":[[0,1.87,6.97],[1,1.88,3.86],[2,1.89,2.04]],"ltp":1.86,"tv":1885.01,"id":8639275},{"trd":[[2.16,151.98]],"batb":[[0,2.14,3.55],[1,2.12,3.43],[2,2.1,3.46]],"ltp":2.16,"tv":1769.74,"id":8173434}],"tv":3654.75}]}
{"op":"mcm","clk":"1003139353","pt":1580603481620,"mc":[{"id":"1.168186837","rc":[{"batb":[[0,1.85,3.92],[1,1.84,39.87],[2,1.83,6]],"batl":[[0,1.87,3.08],[2,1.89,5.87]],"ltp":1.86,"tv":1885.01,"id":8639275},{"batb":[[0,2.14,3.39],[2,2.1,5.5]],"batl":[[0,2.18,3.33],[1,2.2,21.66],[2,2.22,5.43]],"ltp":2.16,"tv":1769.74,"id":8173434}]}]}
{"op":"mcm","clk":"1003139774","pt":1580603486344,"mc":[{"id":"1.168186837","rc":[{"batb":[[0,1.85,20.43],[1,1.84,23.35]],"batl":[[0,1.87,3],[1,1.88,3.95]],"ltp":1.86,"tv":1885.01,"id":8639275},{"batl":[[0,2.18,17.14],[1,2.2,7.85]],"ltp":2.16,"tv":1769.74,"id":8173434}]}]}
{"op":"mcm","clk":"1003140144","pt":1580603490639,"mc":[{"id":"1.168186837","rc":[{"batb":[[0,1.86,3.9],[1,1.85,20.43],[2,1.84,23.35]],"ltp":1.86,"tv":1885.01,"id":8639275}]}]}
{"op":"mcm","clk":"1003140221","pt":1580603491416,"mc":[{"id":"1.168186837","rc":[{"batb":[[2,1.84,25.51]],"ltp":1.86,"tv":1885.01,"id":8639275}]}]}
{"op":"mcm","clk":"1003145143","pt":1580603547678,"mc":[{"id":"1.168186837","rc":[{"trd":[[1.86,712.11]],"batb":[[0,1.86,1.64]],"ltp":1.86,"tv":1889.53,"id":8639275}],"tv":3659.27}]}
{"op":"mcm","clk":"1003145205","pt":1580603548501,"mc":[{"id":"1.168186837","rc":[{"batb":[[0,1.85,20.43],[1,1.84,23.35],[2,1.83,6]],"batl":[[0,1.87,6.88]],"ltp":1.86,"tv":1889.53,"id":8639275}]}]}
{"op":"mcm","clk":"1003145385","pt":1580603550989,"mc":[{"id":"1.168186837","rc":[{"batl":[[1,1.88,20.03]],"ltp":1.86,"tv":1889.53,"id":8639275}]}]}
{"op":"mcm","clk":"1003146186","pt":1580603561432,"mc":[{"id":"1.168186837","rc":[{"batb":[[0,1.85,3.92],[1,1.84,39.87]],"batl":[[1,1.88,3.86]],"ltp":1.86,"tv":1889.53,"id":8639275},{"batb":[[0,2.14,17.6]],"batl":[[0,2.18,3.33],[1,2.2,21.66]],"ltp":2.16,"tv":1769.74,"id":8173434}]}]}
{"op":"mcm","clk":"1003146693","pt":1580603567607,"mc":[{"id":"1.168186837","rc":[{"batb":[[0,1.85,15.36]],"ltp":1.86,"tv":1889.53,"id":8639275},{"batb":[[2,2.1,41.39]],"ltp":2.16,"tv":1769.74,"id":8173434}]}]}
{"op":"mcm","clk":"1003148084","pt":1580603584430,"mc":[{"id":"1.168186837","rc":[{"batb":[[0,2.14,3.39]],"ltp":2.16,"tv":1769.74,"id":8173434}]}]}
{"op":"mcm","clk":"1003151804","pt":1580603628507,"mc":[{"id":"1.168186837","rc":[{"batb":[[0,1.85,31.88],[1,1.84,23.35]],"ltp":1.86,"tv":1889.53,"id":8639275}]}]}
{"op":"mcm","clk":"1003152197","pt":1580603633183,"mc":[{"id":"1.168186837","rc":[{"batl":[[0,2.18,17.14],[1,2.2,7.85]],"ltp":2.16,"tv":1769.74,"id":8173434}]}]}
{"op":"mcm","clk":"1003158422","pt":1580603703591,"mc":[{"id":"1.168186837","rc":[{"batb":[[2,2.1,5.5]],"ltp":2.16,"tv":1769.74,"id":8173434}]}]}
{"op":"mcm","clk":"1003158464","pt":1580603704003,"mc":[{"id":"1.168186837","rc":[{"trd":[[1.85,303.81]],"batb":[[0,1.85,8.38]],"ltp":1.85,"tv":1936.54,"id":8639275}],"tv":3706.28}]}
{"op":"mcm","clk":"1003158605","pt":1580603705502,"mc":[{"id":"1.168186837","rc":[{"batl":[[0,2.18,17.15]],"ltp":2.16,"tv":1769.74,"id":8173434}]}]}
{"op":"mcm","clk":"1003158727","pt":1580603706699,"mc":[{"id":"1.168186837","rc":[{"batb":[[0,1.85,19.8]],"batl":[[0,1.87,15.02]],"ltp":1.85,"tv":1936.54,"id":8639275}]}]}
{"op":"mcm","clk":"1003158805","pt":1580603707422,"mc":[{"id":"1.168186837","rc":[{"batl":[[0,1.86,3.91],[1,1.87,15.02],[2,1.88,5.9]],"ltp":1.85,"tv":1936.54,"id":8639275},{"batb":[[1,2.12,5.46]],"ltp":2.16,"tv":1769.74,"id":8173434}]}]}
{"op":"mcm","clk":"1003158889","pt":1580603708304,"mc":[{"id":"1.168186837","rc":[{"batb":[[0,1.85,23.73]],"batl":[[0,1.87,15.02],[1,1.88,3.86],[2,1.89,5.87]],"ltp":1.85,"tv":1936.54,"id":8639275},{"batb":[[1,2.12,3.43]],"ltp":2.16,"tv":1769.74,"id":8173434}]}]}
{"op":"mcm","clk":"1003165619","pt":1580603786696,"mc":[{"id":"1.168186837","rc":[{"trd":[[1.87,524.86]],"batb":[[0,1.87,45.77],[1,1.85,25.9],[2,1.84,25.57]],"batl":[[0,1.88,3.86],[1,1.89,3.83],[2,1.9,2.05]],"ltp":1.87,"tv":1966.58,"id":8639275},{"batl":[[1,2.2,9.85],[2,2.22,3.27]],"ltp":2.16,"tv":1769.74,"id":8173434}],"tv":3736.32}]}
{"op":"mcm","clk":"1003165651","pt":1580603787005,"mc":[{"id":"1.168186837","rc":[{"batb":[[1,1.86,3.91],[2,1.85,25.9]],"batl":[[0,1.89,3.83],[1,1.9,3.83],[2,1.91,2.05]],"ltp":1.87,"tv":1966.58,"id":8639275},{"batb":[[0,2.12,3.43],[1,2.1,3.46],[2,2.08,11.68]],"batl":[[2,2.22,5.34]],"ltp":2.16,"tv":1769.74,"id":8173434}]}]}
{"op":"mcm","clk":"1003166090","pt":1580603792504,"mc":[{"id":"1.168186837","rc":[{"batb":[[2,1.85,33.95]],"ltp":1.87,"tv":1966.58,"id":8639275},{"batl":[[2,2.22,3.27]],"ltp":2.16,"tv":1769.74,"id":8173434}]}]}
{"op":"mcm","clk":"1003166109","pt":1580603792714,"mc":[{"id":"1.168186837","rc":[{"batl":[[0,2.16,3.37],[1,2.18,17.15],[2,2.2,9.85]],"ltp":2.16,"tv":1769.74,"id":8173434}]}]}
{"op":"mcm","clk":"1003166948","pt":1580603802647,"mc":[{"id":"1.168186837","rc":[{"batb":[[1,1.86,6.09],[2,1.85,17.52]],"ltp":1.87,"tv":1966.58,"id":8639275},{"batl":[[0,2.14,13.81],[1,2.16,3.37],[2,2.18,5.37]],"ltp":2.16,"tv":1769.74,"id":8173434}]}]}
{"op":"mcm","clk":"1003167040","pt":1580603803433,"mc":[{"id":"1.168186837","rc":[{"batb":[[1,1.86,3.91],[2,1.85,17.39]],"batl":[[0,1.9,3.83],[1,1.91,3.81],[2,1.92,2.06]],"ltp":1.87,"tv":1966.58,"id":8639275}]}]}
{"op":"mcm","clk":"1003167690","pt":1580603811660,"mc":[{"id":"1.168186837","rc":[{"batb":[[2,2.08,26.29]],"ltp":2.16,"tv":1769.74,"id":8173434}]}]}
{"op":"mcm","clk":"1003167765","pt":1580603812541,"mc":[{"id":"1.168186837","rc":[{"batb":[[0,1.87,49.66]],"ltp":1.87,"tv":1966.58,"id":8639275},{"batb":[[0,2.1,3.46],[1,2.08,29.79],[2,2.06,68.33]],"ltp":2.16,"tv":1769.74,"id":8173434}]}]}
{"op":"mcm","clk":"1003167836","pt":1580603813365,"mc":[{"id":"1.168186837","rc":[{"batb":[[1,2.08,27.73]],"ltp":2.16,"tv":1769.74,"id":8173434}]}]}
{"op":"mcm","clk":"1003169844","pt":1580603839694,"mc":[{"id":"1.168186837","rc":[{"batb":[[2,1.85,5.96]],"ltp":1.87,"tv":1966.58,"id":8639275},{"batb":[[0,2.1,39.36],[1,2.08,18.11],[2,2.06,2.01]],"ltp":2.16,"tv":1769.74,"id":8173434}]}]}
{"op":"mcm","clk":"1003170520","pt":1580603850617,"mc":[{"id":"1.168186837","rc":[{"batb":[[0,1.88,16.16],[1,1.87,49.66],[2,1.86,5.91]],"ltp":1.87,"tv":1966.58,"id":8639275}]}]}
{"op":"mcm","clk":"1003170596","pt":1580603851699,"mc":[{"id":"1.168186837","rc":[{"batl":[[0,2.16,17.18],[1,2.18,5.37],[2,2.2,9.88]],"ltp":2.16,"tv":1769.74,"id":8173434}]}]}
{"op":"mcm","clk":"1003170647","pt":1580603852622,"mc":[{"id":"1.168186837","rc":[{"trd":[[1.88,93.76]],"batb":[[0,1.88,3.98]],"ltp":1.88,"tv":1990.96,"id":8639275},{"batl":[[0,2.14,3.4],[1,2.16,17.18],[2,2.18,5.37]],"ltp":2.16,"tv":1769.74,"id":8173434}],"tv":3760.7}]}
{"op":"mcm","clk":"1003170887","pt":1580603856598,"mc":[{"id":"1.168186837","rc":[{"batl":[[0,1.9,15.89]],"ltp":1.88,"tv":1990.96,"id":8639275}]}]}
{"op":"mcm","clk":"1003170935","pt":1580603857112,"mc":[{"id":"1.168186837","rc":[{"batb":[[0,1.88,7.85]],"ltp":1.88,"tv":1990.96,"id":8639275}]}]}
{"op":"mcm","clk":"1003171765","pt":1580603870513,"mc":[{"id":"1.168186837","rc":[{"batb":[[0,1.88,3.87],[1,1.87,53.64]],"batl":[[0,1.89,12.05],[1,1.9,3.83],[2,1.91,3.81]],"ltp":1.88,"tv":1990.96,"id":8639275}]}]}
{"op":"mcm","clk":"1003171847","pt":1580603871542,"mc":[{"id":"1.168186837","rc":[{"batl":[[2,1.91,5.86]],"ltp":1.88,"tv":1990.96,"id":8639275},{"batb":[[1,2.08,20.17],[2,2.06,2.08]],"ltp":2.16,"tv":1769.74,"id":8173434}]}]}
{"op":"mcm","clk":"1003171897","pt":1580603872217,"mc":[{"id":"1.168186837","rc":[{"batb":[[0,1.87,53.64],[1,1.86,3.91],[2,1.85,5.96]],"ltp":1.88,"tv":1990.96,"id":8639275},{"batb":[[0,2.12,3.44],[1,2.1,39.36],[2,2.08,20.17]],"ltp":2.16,"tv":1769.74,"id":8173434}]}]}
{"op":"mcm","clk":"1003171971","pt":1580603873339,"mc":[{"id":"1.168186837","rc":[{"batl":[[0,1.89,15.9]],"ltp":1.88,"tv":1990.96,"id":8639275},{"batb":[[1,2.1,48.9]],"ltp":2.16,"tv":1769.74,"id":8173434}]}]}
{"op":"mcm","clk":"1003172270","pt":1580603878648,"mc":[{"id":"1.168186837","rc":[{"trd":[[1.89,100.87]],"batb":[[0,1.87,55.68],[1,1.86,5.91]],"batl":[[0,1.9,3.83],[1,1.91,3.81],[2,1.92,2.06]],"ltp":1.89,"tv":2006.87,"id":8639275},{"trd":[[2.12,52.83]],"batb":[[0,2.1,48.9],[1,2.08,18.11],[2,2.06,2.08]],"batl":[[0,2.12,209.54],[1,2.14,3.4],[2,2.16,19.4]],"ltp":2.12,"tv":1790.8,"id":8173434}],"tv":3797.67}]}
{"op":"mcm","clk":"1003172326","pt":1580603879527,"mc":[{"id":"1.168186837","rc":[{"batb":[[0,1.88,3.87],[1,1.87,55.68],[2,1.86,5.91]],"batl":[[0,1.92,3.79],[1,1.93,2.07],[2,1.94,2.08]],"ltp":1.89,"tv":2006.87,"id":8639275},{"batb":[[0,2.1,45.44],[2,2.06,5.62]],"ltp":2.12,"tv":1790.8,"id":8173434}]}]}
{"op":"mcm","clk":"1003172402","pt":1580603880555,"mc":[{"id":"1.168186837","rc":[{"batb":[[0,1.9,9.87],[1,1.88,5.87],[2,1.87,55.68]],"batl":[[1,1.93,5.84]],"ltp":1.89,"tv":2006.87,"id":8639275},{"batb":[[0,2.1,35.9]],"ltp":2.12,"tv":1790.8,"id":8173434}]}]}
{"op":"mcm","clk":"1003172626","pt":1580603883654,"mc":[{"id":"1.168186837","rc":[{"batl":[[0,2.14,3.4],[1,2.16,19.4],[2,2.18,5.37]],"ltp":2.12,"tv":1790.8,"id":8173434}]}]}
{"op":"mcm","clk":"1003172687","pt":1580603884431,"mc":[{"id":"1.168186837","rc":[{"trd":[[1.92,6.7]],"batb":[[0,1.9,2],[1,1.89,2.05],[2,1.88,5.87]],"batl":[[0,1.93,3.77],[1,1.95,2.05],[2,1.96,2]],"ltp":1.92,"tv":2010.66,"id":8639275},{"trd":[[2.08,226.66],[2.1,227.34]],"batb":[[0,2.06,3.54],[1,2.02,2.14],[2,2,2]],"batl":[[0,2.08,133.54],[1,2.12,2.05],[2,2.14,5.51]],"ltp":2.08,"tv":1939.29,"id":8173434}],"tv":3949.95}]}
{"op":"mcm","clk":"1003172771","pt":1580603885660,"mc":[{"id":"1.168186837","rc":[{"batb":[[1,1.89,5.91],[2,1.88,51.03]],"batl":[[0,1.96,3.72],[1,1.97,3.71],[2,1.98,2.13]],"ltp":1.92,"tv":2010.66,"id":8639275},{"batb":[[0,2.04,3.57],[1,2.02,3.61]],"ltp":2.08,"tv":1939.29,"id":8173434}]}]}
{"op":"mcm","clk":"1003172831","pt":1580603886435,"mc":[{"id":"1.168186837","rc":[{"batb":[[2,1.88,49.03]],"ltp":1.92,"tv":2010.66,"id":8639275},{"batl":[[1,2.12,5.49]],"ltp":2.08,"tv":1939.29,"id":8173434}]}]}
{"op":"mcm","clk":"1003173006","pt":1580603888649,"mc":[{"id":"1.168186837","rc":[{"batb":[[2,1.88,51.24]],"ltp":1.92,"tv":2010.66,"id":8639275},{"batl":[[0,2.06,133.54]],"ltp":2.08,"tv":1939.29,"id":8173434}]}]}
{"op":"mcm","clk":"1003173079","pt":1580603889537,"mc":[{"id":"1.168186837","rc":[{"trd":[[1.95,10.82]],"batb":[[0,1.95,5.02],[1,1.93,2.08],[2,1.92,2.07]],"batl":[[0,1.97,3.71],[1,1.98,3.68],[2,1.99,2.25]],"ltp":1.95,"tv":2021.48,"id":8639275},{"batb":[[0,2.02,3.61],[1,2,3.65],[2,1.99,12.06]],"batl":[[1,2.1,2.05],[2,2.12,5.65]],"ltp":2.08,"tv":1939.29,"id":8173434}],"tv":3960.77}]}
{"op":"mcm","clk":"1003173135","pt":1580603890385,"mc":[{"id":"1.168186837","rc":[{"batl":[[0,1.98,3.68],[1,1.99,3.66],[2,2,2]],"ltp":1.95,"tv":2021.48,"id":8639275}]}]}
{"op":"mcm","clk":"1003173405","pt":1580603893566,"mc":[{"id":"1.168186837","rc":[{"trd":[[1.98,3.68],[1.99,3.66],[2,2]],"batb":[[0,1.98,2],[1,1.97,2],[2,1.95,5.02]],"batl":[[0,2.02,2],[1,2.1,3.62],[2,2.28,18.48]],"ltp":2.0,"tv":2030.82,"id":8639275},{"trd":[[2,281.49],[2.02,152.22]],"batb":[[0,1.99,12.06],[1,1.98,83.77],[2,1.97,2.17]],"batl":[[0,2.04,2],[1,2.06,2],[2,2.12,3.44]],"ltp":2.0,"tv":2197.12,"id":8173434}],"tv":4227.94}]}
{"op":"mcm","clk":"1003173494","pt":1580603894659,"mc":[{"id":"1.168186837","rc":[{"batb":[[0,1.94,2],[1,1.93,2.08],[2,1.92,2.07]],"batl":[[0,2.02,3.62],[1,2.04,3.58],[2,2.1,3.62]],"ltp":2.0,"tv":2030.82,"id":8639275},{"batb":[[0,1.98,85.2],[1,1.97,5.88],[2,1.96,2.13]],"batl":[[0,2.1,5.53],[1,2.12,5.65],[2,2.14,5.4]],"ltp":2.0,"tv":2197.12,"id":8173434}]}]}
{"op":"mcm","clk":"1003173548","pt":1580603895373,"mc":[{"id":"1.168186837","rc":[{"batb":[[0,1.91,3.82],[1,1.9,3.84],[2,1.89,5.86]],"ltp":2.0,"tv":2030.82,"id":8639275},{"batb":[[1,1.97,3.71]],"batl":[[0,2.1,3.48],[1,2.12,3.44]],"ltp":2.0,"tv":2197.12,"id":8173434}]}]}
{"op":"mcm","clk":"1003173585","pt":1580603895842,"mc":[{"id":"1.168186837","rc":[{"batl":[[0,2.02,8.85]],"ltp":2.0,"tv":2030.82,"id":8639275}]}]}
{"op":"mcm","clk":"1003173786","pt":1580603898684,"mc":[{"id":"1.168186837","rc":[{"batl":[[0,2.1,46.08]],"ltp":2.0,"tv":2197.12,"id":8173434}]}]}
{"op":"mcm","clk":"1003174037","pt":1580603902563,"mc":[{"id":"1.168186837","rc":[{"batb":[[1,1.9,5.9]],"ltp":2.0,"tv":2030.82,"id":8639275},{"batl":[[0,2.08,3.51],[1,2.1,46.08],[2,2.12,5.65]],"ltp":2.0,"tv":2197.12,"id":8173434}]}]}
{"op":"mcm","clk":"1003174069","pt":1580603902972,"mc":[{"id":"1.168186837","rc":[{"batb":[[2,1.89,5.91]],"ltp":2.0,"tv":2030.82,"id":8639275}]}]}
{"op":"mcm","clk":"1003174785","pt":1580603912559,"mc":[{"id":"1.168186837","rc":[{"batl":[[0,2.08,17.32]],"ltp":2.0,"tv":2197.12,"id":8173434}]}]}
{"op":"mcm","clk":"1003175953","pt":1580603931699,"mc":[{"id":"1.168186837","rc":[{"batb":[[2,1.89,3.86]],"ltp":2.0,"tv":2030.82,"id":8639275}]}]}
{"op":"mcm","clk":"1003175969","pt":1580603931902,"mc":[{"id":"1.168186837","rc":[{"batb":[[2,1.89,5.86]],"ltp":2.0,"tv":2030.82,"id":8639275}]}]}
{"op":"mcm","clk":"1003176082","pt":1580603933394,"mc":[{"id":"1.168186837","rc":[{"batb":[[0,1.92,4.26],[1,1.91,7.88],[2,1.9,3.84]],"ltp":2.0,"tv":2030.82,"id":8639275},{"batl":[[0,2.06,3.55],[1,2.08,17.32],[2,2.1,50.18]],"ltp":2.0,"tv":2197.12,"id":8173434}]}]}
{"op":"mcm","clk":"1003176175","pt":1580603934681,"mc":[{"id":"1.168186837","rc":[{"batb":[[0,1.92,8.07]],"ltp":2.0,"tv":2030.82,"id":8639275},{"batb":[[0,1.99,3.67],[1,1.98,85.2],[2,1.97,5.71]],"ltp":2.0,"tv":2197.12,"id":8173434}]}]}
{"op":"mcm","clk":"1003176655","pt":1580603942612,"mc":[{"id":"1.168186837","rc":[{"batb":[[0,1.92,5.88],[1,1.91,5.82]],"ltp":2.0,"tv":2030.82,"id":8639275},{"batb":[[0,1.99,13.73]],"batl":[[2,2.1,48.13]],"ltp":2.0,"tv":2197.12,"id":8173434}]}]}
{"op":"mcm","clk":"1003176710","pt":1580603943533,"mc":[{"id":"1.168186837","rc":[{"batb":[[1,1.91,21.73]],"ltp":2.0,"tv":2030.82,"id":8639275},{"batb":[[0,2,3.65],[1,1.99,13.73],[2,1.98,87.46]],"ltp":2.0,"tv":2197.12,"id":8173434}]}]}
{"op":"mcm","clk":"1003177376","pt":1580603954433,"mc":[{"id":"1.168186837","rc":[{"batl":[[0,2,15.2],[1,2.02,8.85],[2,2.04,3.58]],"ltp":2.0,"tv":2030.82,"id":8639275}]}]}
{"op":"mcm","clk":"1003177404","pt":1580603954845,"mc":[{"id":"1.168186837","rc":[{"batb":[[1,1.91,21.79]],"batl":[[0,1.99,3.67],[1,2,18.85],[2,2.02,8.85]],"ltp":2.0,"tv":2030.82,"id":8639275}]}]}
{"op":"mcm","clk":"1003178032","pt":1580603965614,"mc":[{"id":"1.168186837","rc":[{"batl":[[0,1.99,18.87],[1,2,3.65]],"ltp":2.0,"tv":2030.82,"id":8639275}]}]}
{"op":"mcm","clk":"1003178061","pt":1580603966029,"mc":[{"id":"1.168186837","rc":[{"batl":[[0,2.06,17.36],[1,2.08,3.51]],"ltp":2.0,"tv":2197.12,"id":8173434}]}]}
{"op":"mcm","clk":"1003178172","pt":1580603967625,"mc":[{"id":"1.168186837","rc":[{"batb":[[0,1.94,5.86],[1,1.93,5.87],[2,1.92,3.81]],"ltp":2.0,"tv":2030.82,"id":8639275},{"batl":[[1,2.08,5.58],[2,2.1,46.08]],"ltp":2.0,"tv":2197.12,"id":8173434}]}]}
{"op":"mcm","clk":"1003178222","pt":1580603968343,"mc":[{"id":"1.168186837","rc":[{"batb":[[2,1.92,5.88]],"ltp":2.0,"tv":2030.82,"id":8639275},{"batl":[[0,2.04,3.59],[1,2.06,17.36],[2,2.08,5.58]],"ltp":2.0,"tv":2197.12,"id":8173434}]}]}
{"op":"mcm","clk":"1003178294","pt":1580603969562,"mc":[{"id":"1.168186837","rc":[{"batl":[[0,2.06,17.36],[1,2.08,3.51],[2,2.1,48.13]],"ltp":2.0,"tv":2197.12,"id":8173434}]}]}
{"op":"mcm","clk":"1003178364","pt":1580603970644,"mc":[{"id":"1.168186837","rc":[{"batb":[[0,1.94,5.77]],"ltp":2.0,"tv":2030.82,"id":8639275},{"batl":[[1,2.08,5.51]],"ltp":2.0,"tv":2197.12,"id":8173434}]}]}
{"op":"mcm","clk":"1003178428","pt":1580603971622,"mc":[{"id":"1.168186837","rc":[{"batb":[[0,1.94,5.86],[1,1.93,5.79]],"ltp":2.0,"tv":2030.82,"id":8639275},{"batl":[[0,2.04,3.59],[1,2.06,17.36],[2,2.08,5.51]],"ltp":2.0,"tv":2197.12,"id":8173434}]}]}
{"op":"mcm","clk":"1003178603","pt":1580603974650,"mc":[{"id":"1.168186837","rc":[{"batb":[[2,1.92,3.81]],"ltp":2.0,"tv":2030.82,"id":8639275},{"trd":[[2.04,10.56],[2.06,1055.94]],"batb":[[2,1.98,5.95]],"batl":[[0,2.06,9.2],[1,2.08,3.51],[2,2.1,48.13]],"ltp":2.06,"tv":2220.6,"id":8173434}],"tv":4251.43}]}
{"op":"mcm","clk":"1003178665","pt":1580603975531,"mc":[{"id":"1.168186837","rc":[{"batb":[[0,1.94,3.77],[1,1.93,3.79],[2,1.92,6]],"batl":[[0,1.98,3.7],[1,1.99,18.87],[2,2,3.65]],"ltp":2.0,"tv":2030.82,"id":8639275},{"batb":[[0,2.02,39.07],[1,2,3.65],[2,1.99,15.73]],"batl":[[0,2.06,12.76]],"ltp":2.06,"tv":2220.6,"id":8173434}]}]}
{"op":"mcm","clk":"1003178684","pt":1580603975940,"mc":[{"id":"1.168186837","rc":[{"batb":[[2,1.99,5.67]],"ltp":2.06,"tv":2220.6,"id":8173434}]}]}
{"op":"mcm","clk":"1003179088","pt":1580603984477,"mc":[{"id":"1.168186837","rc":[{"batb":[[2,1.99,20.71]],"ltp":2.06,"tv":2220.6,"id":8173434}]}]}
{"op":"mcm","clk":"1003179146","pt":1580603985353,"mc":[{"id":"1.168186837","rc":[{"batl":[[2,2,8.93]],"ltp":2.0,"tv":2030.82,"id":8639275},{"batb":[[1,2,13.66]],"ltp":2.06,"tv":2220.6,"id":8173434}]}]}
{"op":"mcm","clk":"1003179386","pt":1580603989575,"mc":[{"id":"1.168186837","rc":[{"batl":[[0,2.06,9.19]],"ltp":2.06,"tv":2220.6,"id":8173434}]}]}
{"op":"mcm","clk":"1003180932","pt":1580604013684,"mc":[{"id":"1.168186837","rc":[{"batb":[[1,1.93,19.7]],"ltp":2.0,"tv":2030.82,"id":8639275}]}]}
{"op":"mcm","clk":"1003180952","pt":1580604013991,"mc":[{"id":"1.168186837","rc":[{"trd":[[2.06,1069.73]],"batl":[[0,2.06,2.29]],"ltp":2.06,"tv":2234.4,"id":8173434}],"tv":4265.22}]}
{"op":"mcm","clk":"1003181064","pt":1580604015591,"mc":[{"id":"1.168186837","rc":[{"batb":[[0,2.04,3.59],[1,2.02,39.07],[2,2,15.66]],"ltp":2.06,"tv":2234.4,"id":8173434}]}]}
{"op":"mcm","clk":"1003182251","pt":1580604034611,"mc":[{"id":"1.168186837","rc":[{"batb":[[1,1.93,3.79]],"batl":[[1,1.99,3.67]],"ltp":2.0,"tv":2030.82,"id":8639275}]}]}
{"op":"mcm","clk":"1003182312","pt":1580604035539,"mc":[{"id":"1.168186837","rc":[{"batl":[[2,2,3.65]],"ltp":2.0,"tv":2030.82,"id":8639275},{"batb":[[2,2,5.65]],"ltp":2.06,"tv":2234.4,"id":8173434}]}]}
{"op":"mcm","clk":"1003182383","pt":1580604036619,"mc":[{"id":"1.168186837","rc":[{"batb":[[0,2.02,39.07],[1,2,3.65],[2,1.99,7.67]],"ltp":2.06,"tv":2234.4,"id":8173434}]}]}
{"op":"mcm","clk":"1003182421","pt":1580604037135,"mc":[{"id":"1.168186837","rc":[{"batb":[[0,2.04,3.59],[1,2.02,39.07],[2,2,5.65]],"ltp":2.06,"tv":2234.4,"id":8173434}]}]}
{"op":"mcm","clk":"1003182480","pt":1580604038009,"mc":[{"id":"1.168186837","rc":[{"batb":[[0,2.02,39.07],[1,2,3.65],[2,1.99,7.67]],"ltp":2.06,"tv":2234.4,"id":8173434}]}]}
{"op":"mcm","clk":"1003182874","pt":1580604043507,"mc":[{"id":"1.168186837","rc":[{"batl":[[0,1.98,19.04]],"ltp":2.0,"tv":2030.82,"id":8639275},{"batb":[[0,2.02,54.11]],"ltp":2.06,"tv":2234.4,"id":8173434}]}]}
{"op":"mcm","clk":"1003182923","pt":1580604044225,"mc":[{"id":"1.168186837","rc":[{"batl":[[0,1.97,3.71],[1,1.98,19.04],[2,1.99,3.67]],"ltp":2.0,"tv":2030.82,"id":8639275},{"batb":[[2,1.99,15.73]],"ltp":2.06,"tv":2234.4,"id":8173434}]}]}
{"op":"mcm","clk":"1003183052","pt":1580604046131,"mc":[{"id":"1.168186837","rc":[{"batb":[[2,1.99,5.67]],"ltp":2.06,"tv":2234.4,"id":8173434}]}]}
{"op":"mcm","clk":"1003183729","pt":1580604056546,"mc":[{"id":"1.168186837","rc":[{"batb":[[0,2.02,64.02]],"ltp":2.06,"tv":2234.4,"id":8173434}]}]}
{"op":"mcm","clk":"1003183801","pt":1580604057533,"mc":[{"id":"1.168186837","rc":[{"batl":[[1,1.98,24.37]],"ltp":2.0,"tv":2030.82,"id":8639275}]}]}
{"op":"mcm","clk":"1003183845","pt":1580604058554,"mc":[{"id":"1.168186837","rc":[{"batb":[[1,1.93,19.54]],"ltp":2.0,"tv":2030.82,"id":8639275}]}]}
{"op":"mcm","clk":"1003185564","pt":1580604086567,"mc":[{"id":"1.168186837","rc":[{"batl":[[0,2.06,6.9]],"ltp":2.06,"tv":2234.4,"id":8173434}]}]}
{"op":"mcm","clk":"1003185616","pt":1580604087389,"mc":[{"id":"1.168186837","rc":[{"batb":[[1,1.93,3.79],[2,1.92,21.74]],"batl":[[0,1.98,24.37],[1,1.99,3.67],[2,2,3.65]],"ltp":2.0,"tv":2030.82,"id":8639275}]}]}
{"op":"mcm","clk":"1003189726","pt":1580604158184,"mc":[{"id":"1.168186837","rc":[{"batb":[[1,1.93,19.54],[2,1.92,6]],"ltp":2.0,"tv":2030.82,"id":8639275},{"trd":[[2.06,1078.97]],"batl":[[0,2.06,2.28]],"ltp":2.06,"tv":2243.64,"id":8173434}],"tv":4274.47}]}
{"op":"mcm","clk":"1003189808","pt":1580604159573,"mc":[{"id":"1.168186837","rc":[{"batl":[[0,1.97,3.72],[1,1.98,24.37],[2,1.99,3.67]],"ltp":2.0,"tv":2030.82,"id":8639275},{"batb":[[0,2.04,3.6],[1,2.02,64.02],[2,2,5.65]],"batl":[[0,2.06,5.84]],"ltp":2.06,"tv":2243.64,"id":8173434}]}]}
{"op":"mcm","clk":"1003190069","pt":1580604163663,"mc":[{"id":"1.168186837","rc":[{"batl":[[0,1.97,19.07],[1,1.98,9.02]],"ltp":2.0,"tv":2030.82,"id":8639275},{"batl":[[0,2.06,3.56]],"ltp":2.06,"tv":2243.64,"id":8173434}]}]}
{"op":"mcm","clk":"1003190188","pt":1580604165462,"mc":[{"id":"1.168186837","rc":[{"batl":[[0,1.96,3.74],[1,1.97,19.07],[2,1.98,9.02]],"ltp":2.0,"tv":2030.82,"id":8639275}]}]}
{"op":"mcm","clk":"1003190241","pt":1580604166693,"mc":[{"id":"1.168186837","rc":[{"batl":[[0,1.97,19.07],[1,1.98,9.02],[2,1.99,3.67]],"ltp":2.0,"tv":2030.82,"id":8639275},{"batb":[[0,2.02,64.02],[1,2,3.65],[2,1.99,5.67]],"ltp":2.06,"tv":2243.64,"id":8173434}]}]}
{"op":"mcm","clk":"1003190285","pt":1580604167567,"mc":[{"id":"1.168186837","rc":[{"batb":[[0,2.02,54.11],[1,2,13.66]],"ltp":2.06,"tv":2243.64,"id":8173434}]}]}
{"op":"mcm","clk":"1003190354","pt":1580604169055,"mc":[{"id":"1.168186837","rc":[{"batl":[[1,1.98,3.7],[2,1.99,8.97]],"ltp":2.0,"tv":2030.82,"id":8639275}]}]}
{"op":"mcm","clk":"1003192265","pt":1580604200188,"mc":[{"id":"1.168186837","rc":[{"batl":[[0,2.06,5.84]],"ltp":2.06,"tv":2243.64,"id":8173434}]}]}
{"op":"mcm","clk":"1003208682","pt":1580604480688,"mc":[{"id":"1.168186837","rc":[{"batl":[[0,1.96,3.76],[1,1.97,19.07],[2,1.98,3.7]],"ltp":2.0,"tv":2030.82,"id":8639275},{"trd":[[2.06,1086.78]],"batb":[[0,2.04,3.6],[1,2.02,54.11],[2,2,13.66]],"batl":[[0,2.06,5.51],[2,2.1,46.08]],"ltp":2.06,"tv":2251.44,"id":8173434}],"tv":4282.27}]}
{"op":"mcm","clk":"1003208721","pt":1580604481358,"mc":[{"id":"1.168186837","rc":[{"batb":[[2,2,15.66]],"batl":[[2,2.1,48.13]],"ltp":2.06,"tv":2251.44,"id":8173434}]}]}
{"op":"mcm","clk":"1003208844","pt":1580604483374,"mc":[{"id":"1.168186837","rc":[{"batl":[[0,2.06,5.17]],"ltp":2.06,"tv":2251.44,"id":8173434}]}]}
{"op":"mcm","clk":"1003210525","pt":1580604513487,"mc":[{"id":"1.168186837","rc":[{"batl":[[0,2.06,5.51]],"ltp":2.06,"tv":2251.44,"id":8173434}]}]}
{"op":"mcm","clk":"1003211587","pt":1580604531037,"mc":[{"id":"1.168186837","rc":[{"batl":[[0,1.97,19.07],[1,1.98,3.7],[2,1.99,8.97]],"ltp":2.0,"tv":2030.82,"id":8639275}]}]}
{"op":"mcm","clk":"1003211637","pt":1580604532119,"mc":[{"id":"1.168186837","rc":[{"batb":[[0,2.02,54.11],[1,2,13.66],[2,1.99,5.67]],"ltp":2.06,"tv":2251.44,"id":8173434}]}]}
{"op":"mcm","clk":"1003215427","pt":1580604588690,"mc":[{"id":"1.168186837","rc":[{"trd":[[2.06,1094.6]],"batl":[[0,2.06,1.6],[2,2.1,46.08]],"ltp":2.06,"tv":2259.26,"id":8173434}],"tv":4290.09}]}
{"op":"mcm","clk":"1003215490","pt":1580604589511,"mc":[{"id":"1.168186837","rc":[{"batl":[[0,1.96,3.76],[1,1.97,19.07],[2,1.98,3.7]],"ltp":2.0,"tv":2030.82,"id":8639275},{"batb":[[0,2.04,3.61],[1,2.02,54.11],[2,2,15.66]],"ltp":2.06,"tv":2259.26,"id":8173434}]}]}
{"op":"mcm","clk":"1003215728","pt":1580604592610,"mc":[{"id":"1.168186837","rc":[{"batb":[[1,1.93,3.79],[2,1.92,21.74]],"ltp":2.0,"tv":2030.82,"id":8639275},{"batl":[[0,2.08,4.76],[1,2.1,46.08],[2,2.12,2.05]],"ltp":2.06,"tv":2259.26,"id":8173434}]}]}
{"op":"mcm","clk":"1003215977","pt":1580604596700,"mc":[{"id":"1.168186837","rc":[{"batl":[[0,2.06,1.25],[1,2.08,3.51],[2,2.1,46.08]],"ltp":2.06,"tv":2259.26,"id":8173434}]}]}
{"op":"mcm","clk":"1003217728","pt":1580604621629,"mc":[{"id":"1.168186837","rc":[{"batl":[[0,2.08,4.76],[1,2.1,46.08],[2,2.12,2.05]],"ltp":2.06,"tv":2259.26,"id":8173434}]}]}
{"op":"mcm","clk":"1003219941","pt":1580604655682,"mc":[{"id":"1.168186837","rc":[{"batl":[[0,2.08,5.1]],"ltp":2.06,"tv":2259.26,"id":8173434}]}]}
{"op":"mcm","clk":"1003237054","pt":1580604934660,"mc":[{"id":"1.168186837","rc":[{"trd":[[1.94,4.74]],"batb":[[0,1.94,1.4]],"ltp":1.94,"tv":2035.56,"id":8639275}],"tv":4294.83}]}
{"op":"mcm","clk":"1003237102","pt":1580604935638,"mc":[{"id":"1.168186837","rc":[{"batb":[[0,1.93,3.79],[1,1.92,19.55],[2,1.91,33.63]],"ltp":1.94,"tv":2035.56,"id":8639275}]}]}
{"op":"mcm","clk":"1003238097","pt":1580604957683,"mc":[{"id":"1.168186837","rc":[{"batl":[[1,1.97,3.72]],"ltp":1.94,"tv":2035.56,"id":8639275},{"batb":[[1,2.02,39.07]],"ltp":2.06,"tv":2259.26,"id":8173434}]}]}
{"op":"mcm","clk":"1003238146","pt":1580604958599,"mc":[{"id":"1.168186837","rc":[{"batl":[[0,1.95,3.79],[1,1.96,19.1],[2,1.97,3.72]],"ltp":1.94,"tv":2035.56,"id":8639275},{"batb":[[0,2.04,18.66]],"ltp":2.06,"tv":2259.26,"id":8173434}]}]}
{"op":"mcm","clk":"1003238189","pt":1580604959482,"mc":[{"id":"1.168186837","rc":[{"batb":[[0,2.04,28.47],[2,2,5.65]],"ltp":2.06,"tv":2259.26,"id":8173434}]}]}
{"op":"mcm","clk":"1003241528","pt":1580605013215,"mc":[{"id":"1.168186837","marketDefinition":{"bspMarket":false,"turnInPlayEnabled":true,"persistenceEnabled":true,"marketBaseRate":5.0,"eventId":"29680287","eventTypeId":"2","numberOfWinners":1,"bettingType":"ODDS","marketType":"MATCH_ODDS","marketTime":"2020-02-02T02:54:00.000Z","suspendTime":"2020-02-02T02:54:00.000Z","bspReconciled":false,"complete":true,"inPlay":false,"crossMatching":true,"runnersVoidable":false,"numberOfActiveRunners":2,"betDelay":0,"status":"OPEN","runners":[{"status":"ACTIVE","sortPriority":1,"id":8173434,"name":"Taro Daniel"},{"status":"ACTIVE","sortPriority":2,"id":8639275,"name":"Yannick Hanfmann"}],"regulators":["MR_INT"],"countryCode":"AU","discountAllowed":true,"timezone":"UTC","openDate":"2020-02-02T03:00:00.000Z","version":3147960788,"name":"Match Odds","eventName":"Daniel v Hanfmann"}}]}
{"op":"mcm","clk":"1003241745","pt":1580605016220,"mc":[{"id":"1.168186837","marketDefinition":{"bspMarket":false,"turnInPlayEnabled":true,"persistenceEnabled":true,"marketBaseRate":5.0,"eventId":"29680287","eventTypeId":"2","numberOfWinners":1,"bettingType":"ODDS","marketType":"MATCH_ODDS","marketTime":"2020-02-02T02:54:00.000Z","suspendTime":"2020-02-02T02:54:00.000Z","bspReconciled":false,"complete":true,"inPlay":false,"crossMatching":true,"runnersVoidable":false,"numberOfActiveRunners":2,"betDelay":0,"status":"OPEN","runners":[{"status":"ACTIVE","sortPriority":1,"id":8173434,"name":"Taro Daniel"},{"status":"ACTIVE","sortPriority":2,"id":8639275,"name":"Yannick Hanfmann"}],"regulators":["MR_INT"],"countryCode":"AU","discountAllowed":true,"timezone":"UTC","openDate":"2020-02-02T02:54:00.000Z","version":3147960788,"name":"Match Odds","eventName":"Daniel v Hanfmann"}}]}
{"op":"mcm","clk":"1003242176","pt":1580605022593,"mc":[{"id":"1.168186837","rc":[{"batl":[[0,1.95,19.14],[1,1.96,3.76]],"ltp":1.94,"tv":2035.56,"id":8639275}]}]}
{"op":"mcm","clk":"1003254819","pt":1580605244627,"mc":[{"id":"1.168186837","rc":[{"trd":[[1.93,4.86]],"batb":[[0,1.92,19.55],[1,1.91,31.57],[2,1.9,2.06]],"ltp":1.93,"tv":2040.42,"id":8639275}],"tv":4299.69}]}
{"op":"mcm","clk":"1003254866","pt":1580605245455,"mc":[{"id":"1.168186837","rc":[{"batl":[[0,1.94,3.82],[1,1.95,19.14],[2,1.96,3.76]],"ltp":1.93,"tv":2040.42,"id":8639275},{"batb":[[0,2.06,3.6],[1,2.04,28.47],[2,2.02,41.14]],"ltp":2.06,"tv":2259.26,"id":8173434}]}]}
{"op":"mcm","clk":"1003255776","pt":1580605257564,"mc":[{"id":"1.168186837","rc":[{"batl":[[0,1.95,19.14],[1,1.96,3.76],[2,1.97,3.72]],"ltp":1.93,"tv":2040.42,"id":8639275}]}]}
{"op":"mcm","clk":"1003255833","pt":1580605258644,"mc":[{"id":"1.168186837","rc":[{"batb":[[0,1.93,3.84],[1,1.92,3.81],[2,1.91,49.32]],"batl":[[0,1.95,3.79],[1,1.96,19.1]],"ltp":1.93,"tv":2040.42,"id":8639275}]}]}
{"op":"mcm","clk":"1003255883","pt":1580605259669,"mc":[{"id":"1.168186837","rc":[{"batb":[[0,2.04,28.47],[1,2.02,41.14],[2,2,5.65]],"ltp":2.06,"tv":2259.26,"id":8173434}]}]}
{"op":"mcm","clk":"1003255972","pt":1580605260648,"mc":[{"id":"1.168186837","rc":[{"batb":[[0,2.04,18.66],[1,2.02,39.07]],"ltp":2.06,"tv":2259.26,"id":8173434}]}]}
{"op":"mcm","clk":"1003255981","pt":1580605260751,"mc":[{"id":"1.168186837","rc":[{"batb":[[1,2.02,48.97]],"ltp":2.06,"tv":2259.26,"id":8173434}]}]}
{"op":"mcm","clk":"1003256529","pt":1580605268580,"mc":[{"id":"1.168186837","rc":[{"trd":[[1.93,9.72]],"batb":[[0,1.92,3.81],[1,1.91,47.32],[2,1.9,2.06]],"ltp":1.93,"tv":2045.28,"id":8639275},{"batb":[[0,2.06,3.6],[1,2.04,18.66],[2,2.02,51.21]],"ltp":2.06,"tv":2259.26,"id":8173434}],"tv":4304.54}]}
{"op":"mcm","clk":"1003258571","pt":1580605299692,"mc":[{"id":"1.168186837","rc":[{"batb":[[0,1.91,47.32],[1,1.9,5.97],[2,1.89,2.05]],"ltp":1.93,"tv":2045.28,"id":8639275},{"trd":[[2.08,234.78]],"batl":[[0,2.08,1.04],[2,2.12,3.5]],"ltp":2.08,"tv":2267.38,"id":8173434}],"tv":4312.66}]}
{"op":"mcm","clk":"1003258626","pt":1580605300507,"mc":[{"id":"1.168186837","rc":[{"batb":[[0,1.92,3.86],[1,1.91,47.32],[2,1.9,5.97]],"ltp":1.93,"tv":2045.28,"id":8639275}]}]}
{"op":"mcm","clk":"1003258899","pt":1580605304305,"mc":[{"id":"1.168186837","rc":[{"batl":[[0,2.1,60.01],[1,2.12,3.5],[2,2.14,2.18]],"ltp":2.08,"tv":2267.38,"id":8173434}]}]}
{"op":"mcm","clk":"1003259921","pt":1580605317450,"mc":[{"id":"1.168186837","rc":[{"batb":[[0,1.92,19.61],[1,1.91,31.57]],"ltp":1.93,"tv":2045.28,"id":8639275}]}]}
{"op":"mcm","clk":"1003263312","pt":1580605364622,"mc":[{"id":"1.168186837","rc":[{"trd":[[2.06,1101.8]],"batb":[[0,2.04,18.66],[1,2.02,51.21],[2,2,5.65]],"batl":[[0,2.06,5.24],[1,2.1,60.01],[2,2.12,3.5]],"ltp":2.06,"tv":2274.59,"id":8173434}],"tv":4319.87}]}
{"op":"mcm","clk":"1003263356","pt":1580605365294,"mc":[{"id":"1.168186837","rc":[{"batb":[[0,1.93,3.85],[1,1.92,21.61],[2,1.91,33.63]],"batl":[[0,1.96,19.1],[1,1.97,3.72],[2,1.99,5.3]],"ltp":1.93,"tv":2045.28,"id":8639275},{"batb":[[1,2.02,48.97]],"batl":[[0,2.06,8.84],[1,2.08,3.57],[2,2.1,62.6]],"ltp":2.06,"tv":2274.59,"id":8173434}]}]}
{"op":"mcm","clk":"1003263563","pt":1580605368397,"mc":[{"id":"1.168186837","rc":[{"batl":[[0,1.96,3.76],[2,1.98,15.35]],"ltp":1.93,"tv":2045.28,"id":8639275},{"batb":[[0,2.04,3.61]],"batl":[[0,2.06,5.24],[1,2.08,18.18],[2,2.1,48.13]],"ltp":2.06,"tv":2274.59,"id":8173434}]}]}
{"op":"mcm","clk":"1003263628","pt":1580605369320,"mc":[{"id":"1.168186837","rc":[{"batb":[[1,2.02,39.07]],"batl":[[0,2.06,8.84]],"ltp":2.06,"tv":2274.59,"id":8173434}]}]}
{"op":"mcm","clk":"1003264296","pt":1580605380652,"mc":[{"id":"1.168186837","rc":[{"trd":[[1.96,3.7]],"batl":[[0,1.96,2.06]],"ltp":1.96,"tv":2046.97,"id":8639275},{"trd":[[2.04,19.41]],"batb":[[0,2.02,39.07],[1,2,5.65],[2,1.99,2]],"batl":[[0,2.06,3.6]],"ltp":2.04,"tv":2283.44,"id":8173434}],"tv":4330.42}]}
{"op":"mcm","clk":"1003264376","pt":1580605381552,"mc":[{"id":"1.168186837","rc":[{"batb":[[0,1.93,19.6],[1,1.92,3.86]],"batl":[[0,1.98,19.1],[1,1.99,3.73],[2,2.28,18.48]],"ltp":1.96,"tv":2046.97,"id":8639275},{"batb":[[1,2,3.65]],"batl":[[0,2.08,18.18],[1,2.1,46.08],[2,2.12,5.5]],"ltp":2.04,"tv":2283.44,"id":8173434}]}]}
{"op":"mcm","clk":"1003264414","pt":1580605382123,"mc":[{"id":"1.168186837","rc":[{"batb":[[0,1.94,3.83],[1,1.93,19.6],[2,1.92,6.05]],"ltp":1.96,"tv":2046.97,"id":8639275}]}]}
{"op":"mcm","clk":"1003265491","pt":1580605398682,"mc":[{"id":"1.168186837","rc":[{"batb":[[1,1.93,3.85],[2,1.92,21.8]],"ltp":1.96,"tv":2046.97,"id":8639275}]}]}
{"op":"mcm","clk":"1003265569","pt":1580605399666,"mc":[{"id":"1.168186837","rc":[{"batl":[[0,2.06,3.6],[1,2.08,18.18],[2,2.1,48.08]],"ltp":2.04,"tv":2283.44,"id":8173434}]}]}
{"op":"mcm","clk":"1003265935","pt":1580605405589,"mc":[{"id":"1.168186837","rc":[{"batl":[[0,1.98,3.76],[1,1.99,19.08]],"ltp":1.96,"tv":2046.97,"id":8639275},{"batb":[[0,2.02,54.11]],"ltp":2.04,"tv":2283.44,"id":8173434}]}]}
{"op":"mcm","clk":"1003265989","pt":1580605406168,"mc":[{"id":"1.168186837","rc":[{"trd":[[2.06,1106.68]],"batl":[[0,2.06,1.17],[2,2.1,46.08]],"ltp":2.06,"tv":2288.32,"id":8173434}],"tv":4335.29}]}
{"op":"mcm","clk":"1003266102","pt":1580605407564,"mc":[{"id":"1.168186837","rc":[{"batb":[[0,2.04,3.65],[1,2.02,64.02],[2,2,5.65]],"batl":[[0,2.08,18.18],[1,2.1,46.08],[2,2.12,5.71]],"ltp":2.06,"tv":2288.32,"id":8173434}]}]}
{"op":"mcm","clk":"1003266212","pt":1580605409169,"mc":[{"id":"1.168186837","rc":[{"batl":[[0,1.98,9.08]],"ltp":1.96,"tv":2046.97,"id":8639275}]}]}
{"op":"mcm","clk":"1003266972","pt":1580605419672,"mc":[{"id":"1.168186837","rc":[{"batl":[[0,2.06,3.6],[1,2.08,18.18],[2,2.1,48.13]],"ltp":2.06,"tv":2288.32,"id":8173434}]}]}
{"op":"mcm","clk":"1003270200","pt":1580605466549,"mc":[{"id":"1.168186837","rc":[{"batl":[[0,1.97,15.35],[1,1.98,9.08],[2,1.99,3.73]],"ltp":1.96,"tv":2046.97,"id":8639275}]}]}
{"op":"mcm","clk":"1003270283","pt":1580605467641,"mc":[{"id":"1.168186837","rc":[{"batl":[[0,1.97,19.12]],"ltp":1.96,"tv":2046.97,"id":8639275},{"trd":[[2.04,26.7]],"batb":[[0,2.02,64.02],[1,2,5.65],[2,1.99,2]],"batl":[[0,2.04,7.42],[1,2.06,3.6],[2,2.08,18.18]],"ltp":2.04,"tv":2295.6,"id":8173434}],"tv":4342.58}]}
{"op":"mcm","clk":"1003270355","pt":1580605468463,"mc":[{"id":"1.168186837","rc":[{"batb":[[0,1.94,5.92],[1,1.93,5.93],[2,1.92,19.61]],"batl":[[0,1.97,15.35]],"ltp":1.96,"tv":2046.97,"id":8639275},{"batb":[[1,2,3.65]],"batl":[[2,2.08,20.37]],"ltp":2.04,"tv":2295.6,"id":8173434}]}]}
{"op":"mcm","clk":"1003270475","pt":1580605469860,"mc":[{"id":"1.168186837","rc":[{"batb":[[0,2.02,54.11],[1,2,13.66]],"ltp":2.04,"tv":2295.6,"id":8173434}]}]}
{"op":"mcm","clk":"1003270610","pt":1580605471664,"mc":[{"id":"1.168186837","rc":[{"batl":[[1,1.98,3.76],[2,1.99,9.03]],"ltp":1.96,"tv":2046.97,"id":8639275}]}]}
{"op":"mcm","clk":"1003270764","pt":1580605473373,"mc":[{"id":"1.168186837","rc":[{"batl":[[0,1.98,3.76],[1,1.99,24.38],[2,2.28,18.48]],"ltp":1.96,"tv":2046.97,"id":8639275},{"batb":[[0,2.02,39.07]],"batl":[[0,2.04,11.07]],"ltp":2.04,"tv":2295.6,"id":8173434}]}]}
{"op":"mcm","clk":"1003270864","pt":1580605474460,"mc":[{"id":"1.168186837","rc":[{"batb":[[0,1.94,3.83],[1,1.93,3.85],[2,1.92,21.68]],"ltp":1.96,"tv":2046.97,"id":8639275},{"trd":[[2.02,167.07]],"batb":[[0,2.02,31.64]],"batl":[[0,2.06,3.6],[1,2.08,18.18],[2,2.1,48.13]],"ltp":2.02,"tv":2310.45,"id":8173434}],"tv":4357.43}]}
{"op":"mcm","clk":"1003270925","pt":1580605475241,"mc":[{"id":"1.168186837","rc":[{"batl":[[1,1.99,19.08]],"ltp":1.96,"tv":2046.97,"id":8639275},{"batb":[[1,2,3.65]],"ltp":2.02,"tv":2310.45,"id":8173434}]}]}
{"op":"mcm","clk":"1003275236","pt":1580605533551,"mc":[{"id":"1.168186837","rc":[{"batl":[[0,1.98,19.1],[1,1.99,3.73]],"ltp":1.96,"tv":2046.97,"id":8639275},{"batb":[[0,2.02,46.69]],"ltp":2.02,"tv":2310.45,"id":8173434}]}]}
{"op":"mcm","clk":"1003275309","pt":1580605534530,"mc":[{"id":"1.168186837","rc":[{"batl":[[0,1.97,3.78],[1,1.98,19.1],[2,1.99,3.73]],"ltp":1.96,"tv":2046.97,"id":8639275},{"trd":[[2.06,1111.58]],"batb":[[0,2.04,3.65],[1,2.02,46.69],[2,2,5.65]],"batl":[[0,2.08,18.18],[1,2.1,46.08],[2,2.12,4.05]],"ltp":2.06,"tv":2315.35,"id":8173434}],"tv":4362.33}]}
{"op":"mcm","clk":"1003278086","pt":1580605573654,"mc":[{"id":"1.168186837","rc":[{"batl":[[0,2.06,3.61],[1,2.08,18.18],[2,2.1,48.13]],"ltp":2.06,"tv":2315.35,"id":8173434}]}]}
{"op":"mcm","clk":"1003278921","pt":1580605584680,"mc":[{"id":"1.168186837","rc":[{"batb":[[1,2.02,18.66]],"ltp":2.06,"tv":2315.35,"id":8173434}]}]}
{"op":"mcm","clk":"1003292057","pt":1580605774578,"mc":[{"id":"1.168186837","rc":[{"trd":[[1.97,11.34],[1.98,41.9]],"batb":[[0,1.98,18.92],[1,1.96,2.13],[2,1.95,2.11]],"batl":[[0,1.99,3.73],[1,2.28,18.48],[2,95,15.9]],"ltp":1.98,"tv":2096.53,"id":8639275},{"trd":[[2.04,30.34]],"batb":[[0,2.02,18.66],[1,2,3.65],[2,1.99,2]],"batl":[[1,2.08,20.37]],"ltp":2.04,"tv":2319.0,"id":8173434}],"tv":4415.54}]}
{"op":"mcm","clk":"1003292105","pt":1580605775151,"mc":[{"id":"1.168186837","rc":[{"trd":[[1.98,71.62]],"batb":[[0,1.98,4.06],[2,1.95,5.94]],"batl":[[0,2,3.73],[1,2.02,3.7],[2,2.28,18.48]],"ltp":1.98,"tv":2126.25,"id":8639275},{"batb":[[0,2.02,15.04],[2,1.99,5.76]],"batl":[[2,2.1,50.18]],"ltp":2.04,"tv":2319.0,"id":8173434}],"tv":4445.26}]}
{"op":"mcm","clk":"1003292352","pt":1580605778665,"mc":[{"id":"1.168186837","rc":[{"trd":[[1.98,79.74]],"batb":[[0,1.96,2.13],[1,1.95,5.94],[2,1.94,5.92]],"batl":[[0,1.98,18.66],[1,2,3.73],[2,2.02,3.7]],"ltp":1.98,"tv":2134.37,"id":8639275}],"tv":4453.38}]}
{"op":"mcm","clk":"1003292396","pt":1580605779182,"mc":[{"id":"1.168186837","rc":[{"batb":[[0,1.95,3.83],[1,1.94,3.83],[2,1.93,5.93]],"batl":[[1,1.99,3.76],[2,2,3.73]],"ltp":1.98,"tv":2134.37,"id":8639275},{"batl":[[1,2.08,18.18]],"ltp":2.04,"tv":2319.0,"id":8173434}]}]}
{"op":"mcm","clk":"1003293281","pt":1580605792658,"mc":[{"id":"1.168186837","rc":[{"batb":[[2,1.93,21.68]],"ltp":1.98,"tv":2134.37,"id":8639275}]}]}
{"op":"mcm","clk":"1003293308","pt":1580605793068,"mc":[{"id":"1.168186837","rc":[{"batl":[[2,2.1,48.13]],"ltp":2.04,"tv":2319.0,"id":8173434}]}]}
{"op":"mcm","clk":"1003293465","pt":1580605795282,"mc":[{"id":"1.168186837","rc":[{"batb":[[0,1.95,7.95]],"ltp":1.98,"tv":2134.37,"id":8639275}]}]}
{"op":"mcm","clk":"1003293678","pt":1580605798681,"mc":[{"id":"1.168186837","rc":[{"batl":[[0,2.06,18.23],[1,2.08,3.57]],"ltp":2.04,"tv":2319.0,"id":8173434}]}]}
{"op":"mcm","clk":"1003293760","pt":1580605799671,"mc":[{"id":"1.168186837","rc":[{"batl":[[0,2.04,3.66],[1,2.06,18.23],[2,2.08,5.76]],"ltp":2.04,"tv":2319.0,"id":8173434}]}]}
{"op":"mcm","clk":"1003293805","pt":1580605800288,"mc":[{"id":"1.168186837","rc":[{"batb":[[1,1.94,5.92],[2,1.93,21.6]],"ltp":1.98,"tv":2134.37,"id":8639275}]}]}
{"op":"mcm","clk":"1003294398","pt":1580605807807,"mc":[{"id":"1.168186837","rc":[{"batb":[[2,1.93,21.68]],"ltp":1.98,"tv":2134.37,"id":8639275}]}]}
{"op":"mcm","clk":"1003294612","pt":1580605810292,"mc":[{"id":"1.168186837","rc":[{"batl":[[0,1.99,3.76],[1,2,22.39],[2,2.02,3.7]],"ltp":1.98,"tv":2134.37,"id":8639275}]}]}
{"op":"mcm","clk":"1003295138","pt":1580605817609,"mc":[{"id":"1.168186837","rc":[{"batb":[[0,2,3.65],[1,1.99,5.76],[2,1.98,2.26]],"ltp":2.04,"tv":2319.0,"id":8173434}]}]}
{"op":"mcm","clk":"1003295216","pt":1580605818591,"mc":[{"id":"1.168186837","rc":[{"batb":[[1,1.99,3.76]],"ltp":2.04,"tv":2319.0,"id":8173434}]}]}
{"op":"mcm","clk":"1003295596","pt":1580605823694,"mc":[{"id":"1.168186837","rc":[{"batl":[[1,2.06,3.61]],"ltp":2.04,"tv":2319.0,"id":8173434}]}]}
{"op":"mcm","clk":"1003295622","pt":1580605824004,"mc":[{"id":"1.168186837","rc":[{"batb":[[2,1.93,21.6]],"ltp":1.98,"tv":2134.37,"id":8639275},{"batl":[[1,2.06,4.66]],"ltp":2.04,"tv":2319.0,"id":8173434}]}]}
{"op":"mcm","clk":"1003296341","pt":1580605834656,"mc":[{"id":"1.168186837","rc":[{"batb":[[2,1.93,5.85]],"ltp":1.98,"tv":2134.37,"id":8639275}]}]}
{"op":"mcm","clk":"1003296401","pt":1580605835638,"mc":[{"id":"1.168186837","rc":[{"batb":[[0,1.95,23.7],[2,1.93,8.01]],"ltp":1.98,"tv":2134.37,"id":8639275}]}]}
{"op":"mcm","clk":"1003296474","pt":1580605836632,"mc":[{"id":"1.168186837","rc":[{"trd":[[1.96,11.36]],"batb":[[1,1.94,3.83]],"ltp":1.96,"tv":2142.04,"id":8639275},{"trd":[[2.04,37.67]],"batl":[[0,2.06,4.66],[1,2.08,3.57],[2,2.1,50.18]],"ltp":2.04,"tv":2326.33,"id":8173434}],"tv":4468.37}]}
{"op":"mcm","clk":"1003296593","pt":1580605838645,"mc":[{"id":"1.168186837","rc":[{"batb":[[0,2.02,20.73],[1,2,3.65],[2,1.99,5.76]],"ltp":2.04,"tv":2326.33,"id":8173434}]}]}
{"op":"mcm","clk":"1003296635","pt":1580605839265,"mc":[{"id":"1.168186837","rc":[{"batb":[[0,2.02,24.44]],"ltp":2.04,"tv":2326.33,"id":8173434}]}]}
{"op":"mcm","clk":"1003296734","pt":1580605840663,"mc":[{"id":"1.168186837","rc":[{"batl":[[2,2.1,48.13]],"ltp":2.04,"tv":2326.33,"id":8173434}]}]}
{"op":"mcm","clk":"1003296740","pt":1580605840767,"mc":[{"id":"1.168186837","rc":[{"batb":[[2,1.93,5.93]],"ltp":1.96,"tv":2142.04,"id":8639275}]}]}
{"op":"mcm","clk":"1003298089","pt":1580605861688,"mc":[{"id":"1.168186837","rc":[{"batb":[[0,1.95,7.95]],"ltp":1.96,"tv":2142.04,"id":8639275}]}]}
{"op":"mcm","clk":"1003298129","pt":1580605862207,"mc":[{"id":"1.168186837","rc":[{"batb":[[1,1.94,19.58]],"ltp":1.96,"tv":2142.04,"id":8639275}]}]}
{"op":"mcm","clk":"1003299224","pt":1580605877505,"mc":[{"id":"1.168186837","rc":[{"batb":[[0,2.02,39.48]],"ltp":2.04,"tv":2326.33,"id":8173434}]}]}
{"op":"mcm","clk":"1003299272","pt":1580605878122,"mc":[{"id":"1.168186837","rc":[{"trd":[[1.95,22.42]],"batb":[[0,1.95,2.15]],"ltp":1.95,"tv":2153.64,"id":8639275}],"tv":4479.97}]}
{"op":"mcm","clk":"1003299406","pt":1580605879627,"mc":[{"id":"1.168186837","rc":[{"batb":[[0,2.04,3.68],[1,2.02,39.48],[2,2,5.65]],"ltp":2.04,"tv":2326.33,"id":8173434}]}]}
{"op":"mcm","clk":"1003299445","pt":1580605880044,"mc":[{"id":"1.168186837","rc":[{"batl":[[1,2,27.67]],"ltp":1.95,"tv":2153.64,"id":8639275}]}]}
{"op":"mcm","clk":"1003299745","pt":1580605883605,"mc":[{"id":"1.168186837","rc":[{"batb":[[1,1.94,3.83]],"ltp":1.95,"tv":2153.64,"id":8639275}]}]}
{"op":"mcm","clk":"1003299786","pt":1580605884016,"mc":[{"id":"1.168186837","rc":[{"batb":[[2,1.93,21.68]],"ltp":1.95,"tv":2153.64,"id":8639275}]}]}
{"op":"mcm","clk":"1003301424","pt":1580605907666,"mc":[{"id":"1.168186837","rc":[{"batb":[[2,1.93,21.61]],"ltp":1.95,"tv":2153.64,"id":8639275}]}]}
{"op":"mcm","clk":"1003301458","pt":1580605908081,"mc":[{"id":"1.168186837","rc":[{"batb":[[0,1.95,6.01]],"ltp":1.95,"tv":2153.64,"id":8639275}]}]}
{"op":"mcm","clk":"1003301520","pt":1580605908962,"mc":[{"id":"1.168186837","rc":[{"batb":[[0,2.02,39.48],[1,2,3.65],[2,1.99,15.81]],"ltp":2.04,"tv":2326.33,"id":8173434}]}]}
{"op":"mcm","clk":"1003301628","pt":1580605910559,"mc":[{"id":"1.168186837","rc":[{"batl":[[0,1.99,19.03]],"ltp":1.95,"tv":2153.64,"id":8639275},{"batb":[[2,1.99,5.76]],"ltp":2.04,"tv":2326.33,"id":8173434}]}]}
{"op":"mcm","clk":"1003301682","pt":1580605911590,"mc":[{"id":"1.168186837","rc":[{"batb":[[0,2.02,49.39]],"ltp":2.04,"tv":2326.33,"id":8173434}]}]}
{"op":"mcm","clk":"1003301702","pt":1580605911951,"mc":[{"id":"1.168186837","rc":[{"batl":[[0,1.98,3.8],[1,1.99,19.03],[2,2,27.67]],"ltp":1.95,"tv":2153.64,"id":8639275}]}]}
{"op":"mcm","clk":"1003304095","pt":1580605948114,"mc":[{"id":"1.168186837","rc":[{"batb":[[1,1.94,19.51],[2,1.93,5.93]],"ltp":1.95,"tv":2153.64,"id":8639275}]}]}
{"op":"mcm","clk":"1003305532","pt":1580605969341,"mc":[{"id":"1.168186837","rc":[{"trd":[[1.95,32.38]],"batb":[[0,1.95,1.03],[1,1.94,19.43],[2,1.93,3.85]],"batl":[[0,1.98,19.07],[1,1.99,3.76]],"ltp":1.95,"tv":2163.6,"id":8639275}],"tv":4489.93}]}
{"op":"mcm","clk":"1003305594","pt":1580605970368,"mc":[{"id":"1.168186837","rc":[{"batb":[[0,1.94,19.43],[1,1.93,3.85],[2,1.92,2]],"batl":[[0,1.97,3.82],[1,1.98,19.07],[2,1.99,3.76]],"ltp":1.95,"tv":2163.6,"id":8639275},{"batb":[[0,2.04,3.69],[1,2.02,49.39],[2,2,5.65]],"ltp":2.04,"tv":2326.33,"id":8173434}]}]}
{"op":"mcm","clk":"1003306030","pt":1580605977294,"mc":[{"id":"1.168186837","rc":[{"batb":[[0,2.04,18.73],[1,2.02,34.35]],"ltp":2.04,"tv":2326.33,"id":8173434}]}]}
{"op":"mcm","clk":"1003306739","pt":1580605989190,"mc":[{"id":"1.168186837","rc":[{"batb":[[0,1.94,3.83],[1,1.93,19.45]],"ltp":1.95,"tv":2163.6,"id":8639275},{"batb":[[0,2.04,3.69],[1,2.02,49.39]],"ltp":2.04,"tv":2326.33,"id":8173434}]}]}
{"op":"mcm","clk":"1003306820","pt":1580605990500,"mc":[{"id":"1.168186837","rc":[{"batb":[[0,2.02,49.39],[1,2,3.65],[2,1.99,5.76]],"ltp":2.04,"tv":2326.33,"id":8173434}]}]}
{"op":"mcm","clk":"1003308750","pt":1580606018427,"mc":[{"id":"1.168186837","rc":[{"trd":[[2.02,184.63]],"batb":[[0,2.02,40.61]],"ltp":2.02,"tv":2343.89,"id":8173434}],"tv":4507.49}]}
{"op":"mcm","clk":"1003308807","pt":1580606019099,"mc":[{"id":"1.168186837","rc":[{"batb":[[0,2.02,28.66]],"ltp":2.02,"tv":2343.89,"id":8173434}]}]}
{"op":"mcm","clk":"1003308920","pt":1580606020700,"mc":[{"id":"1.168186837","rc":[{"batb":[[1,1.93,19.53]],"ltp":1.95,"tv":2163.6,"id":8639275},{"batb":[[0,2.02,18.76]],"ltp":2.02,"tv":2343.89,"id":8173434}]}]}
{"op":"mcm","clk":"1003334466","pt":1580606356689,"mc":[{"id":"1.168186837","rc":[{"trd":[[2.06,1118.3]],"batl":[[0,2.06,1.3],[2,2.1,46.08]],"ltp":2.06,"tv":2350.61,"id":8173434}],"tv":4514.22}]}
{"op":"mcm","clk":"1003334554","pt":1580606357672,"mc":[{"id":"1.168186837","rc":[{"batb":[[0,1.93,3.85],[1,1.92,3.94],[2,1.91,54.52]],"ltp":1.95,"tv":2163.6,"id":8639275},{"batb":[[0,2.04,3.71],[1,2.02,18.76],[2,2,5.65]],"batl":[[0,2.08,4.62],[1,2.1,46.08],[2,2.12,2]],"ltp":2.06,"tv":2350.61,"id":8173434}]}]}
{"op":"mcm","clk":"1003336281","pt":1580606380627,"mc":[{"id":"1.168186837","rc":[{"batb":[[1,1.92,19.7]],"ltp":1.95,"tv":2163.6,"id":8639275}]}]}
{"op":"mcm","clk":"1003341557","pt":1580606454533,"mc":[{"id":"1.168186837","rc":[{"trd":[[1.94,9.8]],"batb":[[0,1.94,1.38],[1,1.93,37.06],[2,1.92,21.7]],"ltp":1.94,"tv":2168.66,"id":8639275}],"tv":4519.27}]}
{"op":"mcm","clk":"1003341629","pt":1580606455516,"mc":[{"id":"1.168186837","rc":[{"batb":[[0,1.93,37.06],[1,1.92,19.7],[2,1.91,2.06]],"ltp":1.94,"tv":2168.66,"id":8639275}]}]}
{"op":"mcm","clk":"1003341836","pt":1580606458601,"mc":[{"id":"1.168186837","rc":[{"batb":[[0,1.94,15.76],[1,1.93,37.06],[2,1.92,6.01]],"ltp":1.94,"tv":2168.66,"id":8639275},{"batl":[[0,2.06,1.05],[1,2.08,3.57],[2,2.1,46.08]],"ltp":2.06,"tv":2350.61,"id":8173434}]}]}
{"op":"mcm","clk":"1003342387","pt":1580606466451,"mc":[{"id":"1.168186837","rc":[{"batb":[[0,1.94,19.67]],"ltp":1.94,"tv":2168.66,"id":8639275}]}]}
{"op":"mcm","clk":"1003343208","pt":1580606478634,"mc":[{"id":"1.168186837","rc":[{"batb":[[0,1.94,19.51]],"ltp":1.94,"tv":2168.66,"id":8639275}]}]}
{"op":"mcm","clk":"1003349451","pt":1580606576547,"mc":[{"id":"1.168186837","rc":[{"batb":[[1,1.93,3.85]],"ltp":1.94,"tv":2168.66,"id":8639275}]}]}
{"op":"mcm","clk":"1003349530","pt":1580606577690,"mc":[{"id":"1.168186837","rc":[{"trd":[[1.94,18.73]],"batb":[[0,1.93,3.85],[1,1.92,21.61],[2,1.91,54.52]],"ltp":1.94,"tv":2177.58,"id":8639275},{"trd":[[2.06,1119.35]],"batl":[[0,2.08,3.57],[1,2.1,46.08],[2,2.12,2]],"ltp":2.06,"tv":2351.66,"id":8173434}],"tv":4529.25}]}
{"op":"mcm","clk":"1003349541","pt":1580606577850,"mc":[{"id":"1.168186837","rc":[{"batb":[[1,1.92,19.54]],"ltp":1.94,"tv":2177.58,"id":8639275}]}]}
{"op":"mcm","clk":"1003350621","pt":1580606594572,"mc":[{"id":"1.168186837","rc":[{"batl":[[0,2.08,17.15]],"ltp":2.06,"tv":2351.66,"id":8173434}]}]}
{"op":"mcm","clk":"1003350937","pt":1580606599292,"mc":[{"id":"1.168186837","rc":[{"batb":[[1,1.92,19.7]],"ltp":1.94,"tv":2177.58,"id":8639275}]}]}
{"op":"mcm","clk":"1003357861","pt":1580606698623,"mc":[{"id":"1.168186837","rc":[{"trd":[[1.93,14.82]],"batb":[[0,1.93,34.51],[2,1.91,2.06]],"ltp":1.93,"tv":2182.69,"id":8639275}],"tv":4534.35}]}
{"op":"mcm","clk":"1003357916","pt":1580606699243,"mc":[{"id":"1.168186837","rc":[{"batb":[[0,1.93,33.21],[2,1.91,6.04]],"ltp":1.93,"tv":2182.69,"id":8639275}]}]}
{"op":"mcm","clk":"1003358596","pt":1580606708554,"mc":[{"id":"1.168186837","rc":[{"batb":[[0,1.94,15.6],[1,1.93,33.21],[2,1.92,3.94]],"ltp":1.93,"tv":2182.69,"id":8639275}]}]}
{"op":"mcm","clk":"1003358692","pt":1580606709543,"mc":[{"id":"1.168186837","rc":[{"batb":[[1,1.93,37.15],[2,1.92,5.94]],"ltp":1.93,"tv":2182.69,"id":8639275},{"batl":[[0,2.06,13.57],[1,2.08,3.57],[2,2.1,48.13]],"ltp":2.06,"tv":2351.66,"id":8173434}]}]}
{"op":"mcm","clk":"1003360301","pt":1580606730551,"mc":[{"id":"1.168186837","rc":[{"batb":[[0,1.94,19.52]],"ltp":1.93,"tv":2182.69,"id":8639275},{"batl":[[0,2.06,17.26]],"ltp":2.06,"tv":2351.66,"id":8173434}]}]}
{"op":"mcm","clk":"1003367628","pt":1580606822188,"mc":[{"id":"1.168186837","rc":[{"batb":[[1,1.93,3.94],[2,1.92,48.69]],"ltp":1.93,"tv":2182.69,"id":8639275}]}]}
{"op":"mcm","clk":"1003367751","pt":1580606823477,"mc":[{"id":"1.168186837","rc":[{"batb":[[0,1.93,19.54],[1,1.92,46.69],[2,1.91,6.04]],"batl":[[1,1.98,3.8],[2,1.99,19.03]],"ltp":1.93,"tv":2182.69,"id":8639275},{"trd":[[2.06,1126.73]],"batb":[[1,2.02,3.71],[2,2,20.7]],"batl":[[0,2.08,17.15],[1,2.1,46.08],[2,2.12,2]],"ltp":2.06,"tv":2359.04,"id":8173434}],"tv":4541.73}]}
{"op":"mcm","clk":"1003369530","pt":1580606845611,"mc":[{"id":"1.168186837","rc":[{"batb":[[0,1.93,19.62]],"ltp":1.93,"tv":2182.69,"id":8639275}]}]}
{"op":"mcm","clk":"1003371835","pt":1580606874238,"mc":[{"id":"1.168186837","rc":[{"batl":[[1,1.98,19.07],[2,1.99,3.76]],"ltp":1.93,"tv":2182.69,"id":8639275},{"batb":[[1,2.02,18.76],[2,2,5.65]],"ltp":2.06,"tv":2359.04,"id":8173434}]}]}
{"op":"mcm","clk":"1003374421","pt":1580606903688,"mc":[{"id":"1.168186837","rc":[{"trd":[[1.94,23.87]],"batb":[[0,1.94,1.36],[1,1.93,19.62],[2,1.92,48.88]],"ltp":1.94,"tv":2187.83,"id":8639275}],"tv":4546.87}]}
{"op":"mcm","clk":"1003374477","pt":1580606904304,"mc":[{"id":"1.168186837","rc":[{"batb":[[0,1.93,19.62],[1,1.92,46.69],[2,1.91,6.04]],"ltp":1.94,"tv":2187.83,"id":8639275}]}]}
{"op":"mcm","clk":"1003377449","pt":1580606938572,"mc":[{"id":"1.168186837","rc":[{"batb":[[0,1.94,3.93],[1,1.93,19.62],[2,1.92,48.76]],"ltp":1.94,"tv":2187.83,"id":8639275}]}]}
{"op":"mcm","clk":"1003394299","pt":1580607152517,"mc":[{"id":"1.168186837","rc":[{"trd":[[1.94,29.04]],"batb":[[0,1.93,19.62],[1,1.92,46.69],[2,1.91,6.04]],"ltp":1.94,"tv":2193.01,"id":8639275}],"tv":4552.05}]}
{"op":"mcm","clk":"1003401588","pt":1580607253555,"mc":[{"id":"1.168186837","rc":[{"batb":[[0,1.94,3.95],[1,1.93,19.62],[2,1.92,48.69]],"ltp":1.94,"tv":2193.01,"id":8639275}]}]}
{"op":"mcm","clk":"1003401649","pt":1580607254274,"mc":[{"id":"1.168186837","rc":[{"trd":[[1.94,34.24]],"batb":[[0,1.94,1.35],[2,1.92,46.69]],"ltp":1.94,"tv":2198.2,"id":8639275}],"tv":4557.25}]}
{"op":"mcm","clk":"1003401694","pt":1580607254843,"mc":[{"id":"1.168186837","rc":[{"batb":[[0,1.93,19.62],[1,1.92,46.69],[2,1.91,6.04]],"ltp":1.94,"tv":2198.2,"id":8639275}]}]}
{"op":"mcm","clk":"1003409454","pt":1580607357614,"mc":[{"id":"1.168186837","rc":[{"batb":[[0,1.94,3.96],[1,1.93,19.62],[2,1.92,48.69]],"ltp":1.94,"tv":2198.2,"id":8639275}]}]}
{"op":"mcm","clk":"1003409501","pt":1580607358231,"mc":[{"id":"1.168186837","rc":[{"trd":[[1.94,39.44]],"batb":[[0,1.94,1.36],[2,1.92,46.69]],"ltp":1.94,"tv":2203.4,"id":8639275}],"tv":4562.44}]}
{"op":"mcm","clk":"1003409587","pt":1580607359421,"mc":[{"id":"1.168186837","rc":[{"batb":[[0,1.93,15.68],[1,1.92,46.69],[2,1.91,6.04]],"ltp":1.94,"tv":2203.4,"id":8639275}]}]}
{"op":"mcm","clk":"1003409672","pt":1580607360605,"mc":[{"id":"1.168186837","rc":[{"batb":[[0,1.93,19.66]],"ltp":1.94,"tv":2203.4,"id":8639275}]}]}
{"op":"mcm","clk":"1003419467","pt":1580607494573,"mc":[{"id":"1.168186837","rc":[{"batb":[[0,1.93,3.98]],"batl":[[1,1.98,3.8]],"ltp":1.94,"tv":2203.4,"id":8639275},{"batb":[[1,2.02,3.71]],"batl":[[0,2.08,3.57]],"ltp":2.06,"tv":2359.04,"id":8173434}]}]}
{"op":"mcm","clk":"1003419509","pt":1580607495191,"mc":[{"id":"1.168186837","rc":[{"trd":[[1.93,20.06]],"batb":[[0,1.93,1.36],[2,1.91,3.98]],"ltp":1.93,"tv":2208.64,"id":8639275}],"tv":4567.69}]}
{"op":"mcm","clk":"1003419620","pt":1580607496577,"mc":[{"id":"1.168186837","rc":[{"batb":[[0,1.92,42.75],[1,1.91,3.98],[2,1.9,6.05]],"ltp":1.93,"tv":2208.64,"id":8639275},{"batl":[[0,2.1,46.08],[1,2.12,3.63],[2,2.14,2.18]],"ltp":2.06,"tv":2359.04,"id":8173434}]}]}
{"op":"mcm","clk":"1003419648","pt":1580607497093,"mc":[{"id":"1.168186837","rc":[{"batb":[[0,1.92,46.76]],"ltp":1.93,"tv":2208.64,"id":8639275}]}]}
{"op":"mcm","clk":"1003420119","pt":1580607503688,"mc":[{"id":"1.168186837","rc":[{"batb":[[0,1.93,15.68],[1,1.92,46.76],[2,1.91,6.04]],"batl":[[1,1.98,19.14]],"ltp":1.93,"tv":2208.64,"id":8639275},{"batb":[[1,2.02,18.76]],"batl":[[0,2.08,14.61],[1,2.1,46.08],[2,2.12,5.84]],"ltp":2.06,"tv":2359.04,"id":8173434}]}]}
{"op":"mcm","clk":"1003421006","pt":1580607516580,"mc":[{"id":"1.168186837","rc":[{"batl":[[0,2.08,18.32]],"ltp":2.06,"tv":2359.04,"id":8173434}]}]}
{"op":"mcm","clk":"1003423075","pt":1580607546534,"mc":[{"id":"1.168186837","rc":[{"batb":[[0,1.93,19.67]],"ltp":1.93,"tv":2208.64,"id":8639275}]}]}
{"op":"mcm","clk":"1003423112","pt":1580607547053,"mc":[{"id":"1.168186837","rc":[{"trd":[[1.93,53.28]],"batb":[[0,1.93,3.08]],"ltp":1.93,"tv":2241.86,"id":8639275}],"tv":4600.9}]}
{"op":"mcm","clk":"1003423184","pt":1580607548035,"mc":[{"id":"1.168186837","rc":[{"batb":[[0,1.92,46.76],[1,1.91,3.98],[2,1.9,6.11]],"ltp":1.93,"tv":2241.86,"id":8639275},{"batl":[[0,2.08,14.61]],"ltp":2.06,"tv":2359.04,"id":8173434}]}]}
{"op":"mcm","clk":"1003423572","pt":1580607553674,"mc":[{"id":"1.168186837","rc":[{"batb":[[0,1.93,3.99],[1,1.92,46.76],[2,1.91,3.98]],"ltp":1.93,"tv":2241.86,"id":8639275},{"batl":[[0,2.08,18.32]],"ltp":2.06,"tv":2359.04,"id":8173434}]}]}
{"op":"mcm","clk":"1003423615","pt":1580607554241,"mc":[{"id":"1.168186837","rc":[{"batb":[[2,1.91,6.04]],"ltp":1.93,"tv":2241.86,"id":8639275}]}]}
{"op":"mcm","clk":"1003428320","pt":1580607613497,"mc":[{"id":"1.168186837","rc":[{"batb":[[0,1.93,19.74]],"ltp":1.93,"tv":2241.86,"id":8639275}]}]}
{"op":"mcm","clk":"1003428417","pt":1580607614633,"mc":[{"id":"1.168186837","rc":[{"trd":[[1.93,86.59]],"batb":[[0,1.93,3.09]],"batl":[[1,1.98,16.14]],"ltp":1.93,"tv":2275.17,"id":8639275}],"tv":4634.21}]}
{"op":"mcm","clk":"1003428484","pt":1580607615510,"mc":[{"id":"1.168186837","rc":[{"batb":[[1,1.92,42.75]],"ltp":1.93,"tv":2275.17,"id":8639275},{"batl":[[0,2.08,14.61]],"ltp":2.06,"tv":2359.04,"id":8173434}]}]}
{"op":"mcm","clk":"1003428537","pt":1580607616228,"mc":[{"id":"1.168186837","rc":[{"batb":[[1,1.92,46.77]],"ltp":1.93,"tv":2275.17,"id":8639275}]}]}
{"op":"mcm","clk":"1003429200","pt":1580607625645,"mc":[{"id":"1.168186837","rc":[{"batb":[[0,1.92,46.77],[1,1.91,6.04],[2,1.9,6.11]],"ltp":1.93,"tv":2275.17,"id":8639275}]}]}
{"op":"mcm","clk":"1003429263","pt":1580607626466,"mc":[{"id":"1.168186837","rc":[{"batb":[[0,1.92,42.75],[1,1.91,3.98]],"ltp":1.93,"tv":2275.17,"id":8639275}]}]}
{"op":"mcm","clk":"1003429302","pt":1580607627031,"mc":[{"id":"1.168186837","rc":[{"batb":[[0,1.92,46.77]],"ltp":1.93,"tv":2275.17,"id":8639275}]}]}
{"op":"mcm","clk":"1003430060","pt":1580607636649,"mc":[{"id":"1.168186837","rc":[{"batb":[[0,1.93,3.09],[1,1.92,46.77],[2,1.91,6.04]],"ltp":1.93,"tv":2275.17,"id":8639275}]}]}
{"op":"mcm","clk":"1003430564","pt":1580607642672,"mc":[{"id":"1.168186837","rc":[{"batl":[[1,1.98,3.8]],"ltp":1.93,"tv":2275.17,"id":8639275}]}]}
{"op":"mcm","clk":"1003430639","pt":1580607643344,"mc":[{"id":"1.168186837","rc":[{"batb":[[0,1.93,7.09]],"batl":[[0,1.96,3.94],[1,1.97,16.16],[2,1.98,3.8]],"ltp":1.93,"tv":2275.17,"id":8639275},{"batl":[[0,2.08,18.33]],"ltp":2.06,"tv":2359.04,"id":8173434}]}]}
{"op":"mcm","clk":"1003431265","pt":1580607651677,"mc":[{"id":"1.168186837","rc":[{"batb":[[1,2.02,3.71]],"ltp":2.06,"tv":2359.04,"id":8173434}]}]}
{"op":"mcm","clk":"1003432623","pt":1580607669537,"mc":[{"id":"1.168186837","rc":[{"trd":[[1.93,98.89]],"batb":[[0,1.92,47.71],[1,1.91,3.98],[2,1.9,6.11]],"ltp":1.93,"tv":2287.46,"id":8639275}],"tv":4646.51}]}
{"op":"mcm","clk":"1003432657","pt":1580607669882,"mc":[{"id":"1.168186837","rc":[{"batb":[[0,1.92,42.75]],"ltp":1.93,"tv":2287.46,"id":8639275},{"batl":[[0,2.08,14.61]],"ltp":2.06,"tv":2359.04,"id":8173434}]}]}
{"op":"mcm","clk":"1003432800","pt":1580607671600,"mc":[{"id":"1.168186837","rc":[{"batl":[[1,1.97,3.82]],"ltp":1.93,"tv":2287.46,"id":8639275}]}]}
{"op":"mcm","clk":"1003432905","pt":1580607672480,"mc":[{"id":"1.168186837","rc":[{"batl":[[0,1.95,16.3],[1,1.96,3.94],[2,1.97,3.82]],"ltp":1.93,"tv":2287.46,"id":8639275}]}]}
{"op":"mcm","clk":"1003432999","pt":1580607673674,"mc":[{"id":"1.168186837","rc":[{"batb":[[0,1.92,46.77]],"batl":[[0,1.94,3.98],[1,1.95,16.3],[2,1.96,3.94]],"ltp":1.93,"tv":2287.46,"id":8639275}]}]}
{"op":"mcm","clk":"1003433077","pt":1580607674609,"mc":[{"id":"1.168186837","rc":[{"batb":[[1,2.02,5.94]],"batl":[[0,2.1,46.08],[1,2.12,5.84],[2,2.14,2.04]],"ltp":2.06,"tv":2359.04,"id":8173434}]}]}
{"op":"mcm","clk":"1003433145","pt":1580607675490,"mc":[{"id":"1.168186837","rc":[{"batl":[[0,2.1,60.69],[1,2.12,3.63]],"ltp":2.06,"tv":2359.04,"id":8173434}]}]}
{"op":"mcm","clk":"1003433522","pt":1580607680590,"mc":[{"id":"1.168186837","rc":[{"trd":[[1.94,47.4],[1.95,45.87]],"batb":[[0,1.92,4.02],[1,1.91,45.66]],"batl":[[0,1.95,9.56],[1,1.96,3.94],[2,1.97,3.82]],"ltp":1.95,"tv":2308.92,"id":8639275},{"batb":[[1,2.02,26]],"batl":[[0,2.08,3.71],[1,2.1,60.69],[2,2.12,5.63]],"ltp":2.06,"tv":2359.04,"id":8173434}],"tv":4667.96}]}
{"op":"mcm","clk":"1003434011","pt":1580607687637,"mc":[{"id":"1.168186837","rc":[{"batb":[[0,1.92,16.75]],"ltp":1.95,"tv":2308.92,"id":8639275}]}]}
{"op":"mcm","clk":"1003434609","pt":1580607695525,"mc":[{"id":"1.168186837","rc":[{"batb":[[0,2.04,18.6]],"ltp":2.06,"tv":2359.04,"id":8173434}]}]}
{"op":"mcm","clk":"1003434714","pt":1580607696607,"mc":[{"id":"1.168186837","rc":[{"batl":[[0,1.95,6.07]],"ltp":1.95,"tv":2308.92,"id":8639275},{"batb":[[0,2.06,3.76],[1,2.04,18.6],[2,2.02,38.08]],"ltp":2.06,"tv":2359.04,"id":8173434}]}]}
{"op":"mcm","clk":"1003434779","pt":1580607697432,"mc":[{"id":"1.168186837","rc":[{"batl":[[0,2.1,60.69],[1,2.12,3.63],[2,2.14,2.11]],"ltp":2.06,"tv":2359.04,"id":8173434}]}]}
{"op":"mcm","clk":"1003435096","pt":1580607701653,"mc":[{"id":"1.168186837","rc":[{"batl":[[0,1.95,12.81]],"ltp":1.95,"tv":2308.92,"id":8639275}]}]}
{"op":"mcm","clk":"1003439141","pt":1580607752625,"mc":[{"id":"1.168186837","rc":[{"batb":[[0,1.92,19.85]],"ltp":1.95,"tv":2308.92,"id":8639275}]}]}
{"op":"mcm","clk":"1003439182","pt":1580607753193,"mc":[{"id":"1.168186837","rc":[{"trd":[[1.92,40.15]],"batb":[[0,1.92,3.13]],"ltp":1.92,"tv":2342.37,"id":8639275}],"tv":4701.42}]}
{"op":"mcm","clk":"1003439294","pt":1580607754597,"mc":[{"id":"1.168186837","rc":[{"batb":[[1,1.91,41.67]],"batl":[[0,1.95,19.55]],"ltp":1.92,"tv":2342.37,"id":8639275},{"batl":[[0,2.1,57.21],[2,2.14,5.73]],"ltp":2.06,"tv":2359.04,"id":8173434}]}]}
{"op":"mcm","clk":"1003439381","pt":1580607755631,"mc":[{"id":"1.168186837","rc":[{"batb":[[1,1.91,45.72]],"batl":[[0,1.94,3.99],[1,1.95,19.55],[2,1.96,3.94]],"ltp":1.92,"tv":2342.37,"id":8639275},{"batl":[[0,2.08,14.61],[1,2.1,46.29],[2,2.12,5.63]],"ltp":2.06,"tv":2359.04,"id":8173434}]}]}
{"op":"mcm","clk":"1003439882","pt":1580607762029,"mc":[{"id":"1.168186837","rc":[{"batb":[[0,1.92,2.1]],"ltp":1.92,"tv":2342.37,"id":8639275}]}]}
{"op":"mcm","clk":"1003440012","pt":1580607763937,"mc":[{"id":"1.168186837","rc":[{"batb":[[1,2.04,3.71]],"batl":[[0,2.1,60.9],[1,2.12,3.63],[2,2.14,5.8]],"ltp":2.06,"tv":2359.04,"id":8173434}]}]}
{"op":"mcm","clk":"1003441157","pt":1580607778615,"mc":[{"id":"1.168186837","rc":[{"batl":[[0,1.94,19.66],[1,1.95,3.97]],"ltp":1.92,"tv":2342.37,"id":8639275}]}]}
{"op":"mcm","clk":"1003441231","pt":1580607779650,"mc":[{"id":"1.168186837","rc":[{"batb":[[0,1.91,47.83],[1,1.9,4.05],[2,1.89,6.14]],"batl":[[0,1.93,4.02],[1,1.94,19.66],[2,1.95,3.97]],"ltp":1.92,"tv":2342.37,"id":8639275}]}]}
{"op":"mcm","clk":"1003441357","pt":1580607781347,"mc":[{"id":"1.168186837","rc":[{"batl":[[0,1.94,19.66],[1,1.95,3.97],[2,1.96,3.94]],"ltp":1.92,"tv":2342.37,"id":8639275}]}]}
{"op":"mcm","clk":"1003441497","pt":1580607783151,"mc":[{"id":"1.168186837","rc":[{"batl":[[0,1.93,4.02],[1,1.94,19.66],[2,1.95,3.97]],"ltp":1.92,"tv":2342.37,"id":8639275}]}]}
{"op":"mcm","clk":"1003442610","pt":1580607798663,"mc":[{"id":"1.168186837","rc":[{"trd":[[1.93,106.92],[1.94,65.71]],"batb":[[0,1.92,4.03],[1,1.91,34.59],[2,1.9,4.05]],"batl":[[0,1.94,3.99],[1,1.95,3.97],[2,1.96,3.94]],"ltp":1.94,"tv":2368.71,"id":8639275},{"batb":[[2,2.02,40.69]],"ltp":2.06,"tv":2359.04,"id":8173434}],"tv":4727.76}]}
{"op":"mcm","clk":"1003442675","pt":1580607799387,"mc":[{"id":"1.168186837","rc":[{"trd":[[1.91,101.99],[1.92,48.21]],"batb":[[0,1.91,8.63],[1,1.9,4.05],[2,1.89,6.14]],"batl":[[1,1.95,14.47]],"ltp":1.91,"tv":2428.7,"id":8639275}],"tv":4787.74}]}
{"op":"mcm","clk":"1003442769","pt":1580607800487,"mc":[{"id":"1.168186837","rc":[{"batb":[[0,1.91,6.15]],"ltp":1.91,"tv":2428.7,"id":8639275},{"batb":[[1,2.04,27.9],[2,2.02,50.6]],"ltp":2.06,"tv":2359.04,"id":8173434}]}]}
{"op":"mcm","clk":"1003443652","pt":1580607813701,"mc":[{"id":"1.168186837","rc":[{"batl":[[0,1.94,19.66]],"ltp":1.91,"tv":2428.7,"id":8639275}]}]}
{"op":"mcm","clk":"1003443683","pt":1580607814062,"mc":[{"id":"1.168186837","rc":[{"batl":[[1,1.95,3.97]],"ltp":1.91,"tv":2428.7,"id":8639275},{"batb":[[0,2.06,18.51]],"ltp":2.06,"tv":2359.04,"id":8173434}]}]}
{"op":"mcm","clk":"1003443762","pt":1580607815196,"mc":[{"id":"1.168186837","rc":[{"batl":[[0,1.93,4.02],[1,1.94,19.66],[2,1.95,3.97]],"ltp":1.91,"tv":2428.7,"id":8639275}]}]}
{"op":"mcm","clk":"1003444852","pt":1580607829619,"mc":[{"id":"1.168186837","rc":[{"batb":[[0,1.91,2.1]],"batl":[[0,1.93,15.67],[1,1.94,3.99]],"ltp":1.91,"tv":2428.7,"id":8639275},{"batb":[[0,2.08,3.73],[1,2.06,18.51],[2,2.04,29.9]],"ltp":2.06,"tv":2359.04,"id":8173434}]}]}
{"op":"mcm","clk":"1003444886","pt":1580607830133,"mc":[{"id":"1.168186837","rc":[{"batl":[[0,1.93,19.68]],"ltp":1.91,"tv":2428.7,"id":8639275}]}]}
{"op":"mcm","clk":"1003445803","pt":1580607842136,"mc":[{"id":"1.168186837","rc":[{"batb":[[0,1.91,14.87]],"ltp":1.91,"tv":2428.7,"id":8639275}]}]}
{"op":"mcm","clk":"1003445893","pt":1580607843315,"mc":[{"id":"1.168186837","rc":[{"batl":[[0,2.1,60.91]],"ltp":2.06,"tv":2359.04,"id":8173434}]}]}
{"op":"mcm","clk":"1003445977","pt":1580607844243,"mc":[{"id":"1.168186837","rc":[{"trd":[[1.91,126.71]],"batb":[[0,1.91,2.51]],"ltp":1.91,"tv":2453.41,"id":8639275},{"batl":[[0,2.1,57.21]],"ltp":2.06,"tv":2359.04,"id":8173434}],"tv":4812.46}]}
{"op":"mcm","clk":"1003446318","pt":1580607848425,"mc":[{"id":"1.168186837","rc":[{"batb":[[0,1.9,4.05],[1,1.89,4.09],[2,1.88,2.21]],"batl":[[0,1.93,19.76]],"ltp":1.91,"tv":2453.41,"id":8639275},{"batl":[[0,2.1,50.48]],"ltp":2.06,"tv":2359.04,"id":8173434}]}]}
{"op":"mcm","clk":"1003446417","pt":1580607849609,"mc":[{"id":"1.168186837","rc":[{"batl":[[0,1.92,4.04],[1,1.93,19.76],[2,1.94,3.99]],"ltp":1.91,"tv":2453.41,"id":8639275}]}]}
{"op":"mcm","clk":"1003447695","pt":1580607866256,"mc":[{"id":"1.168186837","rc":[{"batb":[[1,2.06,3.76]],"ltp":2.06,"tv":2359.04,"id":8173434}]}]}
{"op":"mcm","clk":"1003452883","pt":1580607935539,"mc":[{"id":"1.168186837","rc":[{"trd":[[1.91,139.1]],"batb":[[0,1.91,1.41],[1,1.9,4.05],[2,1.89,4.09]],"ltp":1.91,"tv":2465.81,"id":8639275}],"tv":4824.85}]}
{"op":"mcm","clk":"1003453010","pt":1580607937556,"mc":[{"id":"1.168186837","rc":[{"batb":[[0,1.9,4.05],[1,1.89,4.09],[2,1.88,2.21]],"ltp":1.91,"tv":2465.81,"id":8639275},{"batl":[[0,2.1,44.84]],"ltp":2.06,"tv":2359.04,"id":8173434}]}]}
{"op":"mcm","clk":"1003455993","pt":1580607978676,"mc":[{"id":"1.168186837","rc":[{"batl":[[1,1.93,4.02]],"ltp":1.91,"tv":2465.81,"id":8639275},{"trd":[[2.1,301.86]],"batl":[[0,2.1,5.34]],"ltp":2.1,"tv":2433.56,"id":8173434}],"tv":4899.37}]}
{"op":"mcm","clk":"1003456038","pt":1580607979197,"mc":[{"id":"1.168186837","rc":[{"batl":[[0,1.93,4.02],[1,1.94,3.99],[2,1.95,3.97]],"ltp":1.91,"tv":2465.81,"id":8639275}]}]}
{"op":"mcm","clk":"1003458291","pt":1580608011531,"mc":[{"id":"1.168186837","rc":[{"batl":[[0,1.92,19.89],[1,1.93,4.02],[2,1.94,3.99]],"ltp":1.91,"tv":2465.81,"id":8639275},{"batl":[[1,2.12,5.83]],"ltp":2.1,"tv":2433.56,"id":8173434}]}]}
{"op":"mcm","clk":"1003458369","pt":1580608012616,"mc":[{"id":"1.168186837","rc":[{"batb":[[0,1.89,4.09],[1,1.88,4.14],[2,1.87,2.04]],"ltp":1.91,"tv":2465.81,"id":8639275}]}]}
{"op":"mcm","clk":"1003458447","pt":1580608013538,"mc":[{"id":"1.168186837","rc":[{"batb":[[1,1.88,6.27]],"ltp":1.91,"tv":2465.81,"id":8639275}]}]}
{"op":"mcm","clk":"1003458561","pt":1580608015035,"mc":[{"id":"1.168186837","rc":[{"batb":[[0,2.08,18.34]],"batl":[[1,2.12,3.63]],"ltp":2.1,"tv":2433.56,"id":8173434}]}]}
{"op":"mcm","clk":"1003458764","pt":1580608017662,"mc":[{"id":"1.168186837","rc":[{"batb":[[2,1.86,55.52]],"ltp":1.91,"tv":2465.81,"id":8639275},{"trd":[[2.1,310.74]],"batl":[[0,2.12,4.53],[1,2.14,3.62],[2,2.16,2.16]],"ltp":2.1,"tv":2442.44,"id":8173434}],"tv":4908.25}]}
{"op":"mcm","clk":"1003458844","pt":1580608018641,"mc":[{"id":"1.168186837","rc":[{"batb":[[0,1.88,4.14],[1,1.87,2.04],[2,1.86,55.38]],"ltp":1.91,"tv":2465.81,"id":8639275},{"batl":[[0,2.14,4.52],[1,2.16,3.6],[2,2.18,2]],"ltp":2.1,"tv":2442.44,"id":8173434}]}]}
{"op":"mcm","clk":"1003458873","pt":1580608019060,"mc":[{"id":"1.168186837","rc":[{"batb":[[1,1.87,4.17]],"ltp":1.91,"tv":2465.81,"id":8639275}]}]}
{"op":"mcm","clk":"1003459959","pt":1580608033442,"mc":[{"id":"1.168186837","rc":[{"batl":[[0,1.91,15.83],[1,1.92,4.06],[2,1.93,4.02]],"ltp":1.91,"tv":2465.81,"id":8639275},{"batl":[[1,2.16,5.73]],"ltp":2.1,"tv":2442.44,"id":8173434}]}]}
{"op":"mcm","clk":"1003460711","pt":1580608043499,"mc":[{"id":"1.168186837","rc":[{"batb":[[1,1.87,5.58]],"ltp":1.91,"tv":2465.81,"id":8639275}]}]}
{"op":"mcm","clk":"1003460787","pt":1580608044373,"mc":[{"id":"1.168186837","rc":[{"batl":[[0,1.91,19.91]],"ltp":1.91,"tv":2465.81,"id":8639275}]}]}
{"op":"mcm","clk":"1003460866","pt":1580608045473,"mc":[{"id":"1.168186837","rc":[{"trd":[[2.1,312.54]],"batb":[[0,2.1,2.81],[1,2.08,18.34],[2,2.06,5.84]],"batl":[[0,2.14,3.62]],"ltp":2.1,"tv":2444.24,"id":8173434}],"tv":4910.05}]}
{"op":"mcm","clk":"1003460965","pt":1580608046707,"mc":[{"id":"1.168186837","rc":[{"batb":[[2,2.06,15.56]],"ltp":2.1,"tv":2444.24,"id":8173434}]}]}
{"op":"mcm","clk":"1003461454","pt":1580608054486,"mc":[{"id":"1.168186837","rc":[{"batl":[[0,1.91,19.99]],"ltp":1.91,"tv":2465.81,"id":8639275},{"batl":[[0,2.14,5.75],[1,2.16,3.6]],"ltp":2.1,"tv":2444.24,"id":8173434}]}]}
{"op":"mcm","clk":"1003461887","pt":1580608060614,"mc":[{"id":"1.168186837","rc":[{"trd":[[1.88,100.87]],"batb":[[0,1.87,6.17],[1,1.86,53.34],[2,1.85,2]],"ltp":1.88,"tv":2472.91,"id":8639275},{"batb":[[0,2.1,17.43],[1,2.08,3.73],[2,2.06,5.84]],"ltp":2.1,"tv":2444.24,"id":8173434}],"tv":4917.15}]}
{"op":"mcm","clk":"1003461959","pt":1580608061489,"mc":[{"id":"1.168186837","rc":[{"batb":[[0,1.87,1.41],[1,1.86,57.54],[2,1.85,6.39]],"ltp":1.88,"tv":2472.91,"id":8639275},{"batl":[[0,2.14,2.13],[2,2.18,5.58]],"ltp":2.1,"tv":2444.24,"id":8173434}]}]}
{"op":"mcm","clk":"1003462024","pt":1580608062515,"mc":[{"id":"1.168186837","rc":[{"batb":[[2,1.85,4.22]],"batl":[[0,1.9,4.1],[1,1.91,19.99],[2,1.92,4.06]],"ltp":1.88,"tv":2472.91,"id":8639275},{"batl":[[0,2.16,5.73],[1,2.18,3.58],[2,2.2,2.03]],"ltp":2.1,"tv":2444.24,"id":8173434}]}]}
{"op":"mcm","clk":"1003463780","pt":1580608085543,"mc":[{"id":"1.168186837","rc":[{"batl":[[1,1.91,4.08]],"ltp":1.88,"tv":2472.91,"id":8639275}]}]}
{"op":"mcm","clk":"1003465422","pt":1580608108652,"mc":[{"id":"1.168186837","rc":[{"batl":[[0,1.89,16.08],[1,1.9,4.1],[2,1.91,4.08]],"ltp":1.88,"tv":2472.91,"id":8639275},{"trd":[[2.16,160.88]],"batb":[[1,2.08,5.79],[2,2.06,3.76]],"batl":[[0,2.16,1.28]],"ltp":2.16,"tv":2453.14,"id":8173434}],"tv":4926.06}]}
{"op":"mcm","clk":"1003465472","pt":1580608109376,"mc":[{"id":"1.168186837","rc":[{"batb":[[1,1.86,53.34]],"ltp":1.88,"tv":2472.91,"id":8639275},{"batb":[[2,2.06,5.79]],"batl":[[2,2.2,5.58]],"ltp":2.16,"tv":2453.14,"id":8173434}]}]}
{"op":"mcm","clk":"1003465563","pt":1580608110558,"mc":[{"id":"1.168186837","rc":[{"batb":[[0,1.86,53.77],[1,1.85,4.22],[2,1.84,6.46]],"ltp":1.88,"tv":2472.91,"id":8639275},{"batb":[[0,2.12,4.55],[1,2.1,2.81],[2,2.08,5.79]],"batl":[[0,2.18,4],[1,2.2,3.55],[2,2.22,2.16]],"ltp":2.16,"tv":2453.14,"id":8173434}]}]}
{"op":"mcm","clk":"1003465620","pt":1580608111536,"mc":[{"id":"1.168186837","rc":[{"batl":[[0,1.89,20.22]],"ltp":1.88,"tv":2472.91,"id":8639275}]}]}
{"op":"mcm","clk":"1003469097","pt":1580608161610,"mc":[{"id":"1.168186837","rc":[{"batb":[[0,1.86,57.97]],"ltp":1.88,"tv":2472.91,"id":8639275}]}]}
{"op":"mcm","clk":"1003469154","pt":1580608162533,"mc":[{"id":"1.168186837","rc":[{"trd":[[1.86,812.97],[1.87,525.72]],"batb":[[0,1.86,7.12]],"ltp":1.86,"tv":2574.62,"id":8639275}],"tv":5027.77}]}
{"op":"mcm","clk":"1003469226","pt":1580608163511,"mc":[{"id":"1.168186837","rc":[{"batb":[[0,1.85,4.22],[1,1.84,4.24],[2,1.83,2.03]],"ltp":1.86,"tv":2574.62,"id":8639275},{"batb":[[1,2.1,44.04]],"ltp":2.16,"tv":2453.14,"id":8173434}]}]}
{"op":"mcm","clk":"1003469273","pt":1580608164131,"mc":[{"id":"1.168186837","rc":[{"trd":[[1.89,101.26]],"batl":[[0,1.89,20.02]],"ltp":1.89,"tv":2575.02,"id":8639275},{"batb":[[2,2.08,29.13]],"ltp":2.16,"tv":2453.14,"id":8173434}],"tv":5028.17}]}
{"op":"mcm","clk":"1003469387","pt":1580608165628,"mc":[{"id":"1.168186837","rc":[{"batb":[[1,2.1,53.58]],"ltp":2.16,"tv":2453.14,"id":8173434}]}]}
{"op":"mcm","clk":"1003469542","pt":1580608167538,"mc":[{"id":"1.168186837","rc":[{"batl":[[0,1.88,4.16],[1,1.89,20.02],[2,1.9,9.65]],"ltp":1.89,"tv":2575.02,"id":8639275}]}]}
{"op":"mcm","clk":"1003469788","pt":1580608170547,"mc":[{"id":"1.168186837","rc":[{"batl":[[0,2.18,3.58]],"ltp":2.16,"tv":2453.14,"id":8173434}]}]}
{"op":"mcm","clk":"1003469949","pt":1580608172529,"mc":[{"id":"1.168186837","rc":[{"batl":[[0,1.87,15.88],[1,1.88,4.16],[2,1.89,4.13]],"ltp":1.89,"tv":2575.02,"id":8639275},{"batb":[[1,2.1,55.62]],"ltp":2.16,"tv":2453.14,"id":8173434}]}]}
{"op":"mcm","clk":"1003470079","pt":1580608174030,"mc":[{"id":"1.168186837","rc":[{"batb":[[0,1.84,4.24],[1,1.83,4.28],[2,1.82,4.66]],"ltp":1.89,"tv":2575.02,"id":8639275},{"batl":[[0,2.2,3.55],[1,2.22,3.52],[2,2.24,2.23]],"ltp":2.16,"tv":2453.14,"id":8173434}]}]}
{"op":"mcm","clk":"1003470171","pt":1580608175019,"mc":[{"id":"1.168186837","rc":[{"batb":[[0,1.83,4.28],[1,1.82,6.93],[2,1.81,60.64]],"ltp":1.89,"tv":2575.02,"id":8639275},{"batl":[[0,2.2,242.98]],"ltp":2.16,"tv":2453.14,"id":8173434}]}]}
{"op":"mcm","clk":"1003470785","pt":1580608183651,"mc":[{"id":"1.168186837","rc":[{"batl":[[0,1.87,16.25]],"ltp":1.89,"tv":2575.02,"id":8639275}]}]}
{"op":"mcm","clk":"1003470864","pt":1580608184643,"mc":[{"id":"1.168186837","rc":[{"batl":[[0,1.87,20.44]],"ltp":1.89,"tv":2575.02,"id":8639275}]}]}
{"op":"mcm","clk":"1003471501","pt":1580608193448,"mc":[{"id":"1.168186837","rc":[{"batl":[[0,1.87,4.18],[1,1.88,20.32]],"ltp":1.89,"tv":2575.02,"id":8639275},{"batb":[[2,2.08,29.08]],"ltp":2.16,"tv":2453.14,"id":8173434}]}]}
{"op":"mcm","clk":"1003471551","pt":1580608194067,"mc":[{"id":"1.168186837","rc":[{"batb":[[2,2.08,5.74]],"ltp":2.16,"tv":2453.14,"id":8173434}]}]}
{"op":"mcm","clk":"1003473220","pt":1580608216583,"mc":[{"id":"1.168186837","rc":[{"batb":[[2,2.08,3.73]],"ltp":2.16,"tv":2453.14,"id":8173434}]}]}
{"op":"mcm","clk":"1003473230","pt":1580608216786,"mc":[{"id":"1.168186837","rc":[{"batb":[[2,2.08,5.79]],"ltp":2.16,"tv":2453.14,"id":8173434}]}]}
{"op":"mcm","clk":"1003478269","pt":1580608290506,"mc":[{"id":"1.168186837","rc":[{"batb":[[0,1.84,28.99],[1,1.83,4.28],[2,1.82,8.93]],"ltp":1.89,"tv":2575.02,"id":8639275}]}]}
{"op":"mcm","clk":"1003478583","pt":1580608295495,"mc":[{"id":"1.168186837","rc":[{"batl":[[0,2.18,1.06],[1,2.2,3.55],[2,2.22,3.52]],"ltp":2.16,"tv":2453.14,"id":8173434}]}]}
{"op":"mcm","clk":"1003478719","pt":1580608297608,"mc":[{"id":"1.168186837","rc":[{"batb":[[2,2.08,3.73]],"batl":[[0,2.2,4.61],[1,2.22,3.52],[2,2.24,2.23]],"ltp":2.16,"tv":2453.14,"id":8173434}]}]}
{"op":"mcm","clk":"1003478795","pt":1580608298689,"mc":[{"id":"1.168186837","rc":[{"batl":[[0,1.87,20.35],[1,1.88,4.16]],"ltp":1.89,"tv":2575.02,"id":8639275},{"batb":[[2,2.08,5.79]],"ltp":2.16,"tv":2453.14,"id":8173434}]}]}
{"op":"mcm","clk":"1003479038","pt":1580608302620,"mc":[{"id":"1.168186837","rc":[{"batb":[[1,2.1,53.58]],"ltp":2.16,"tv":2453.14,"id":8173434}]}]}
{"op":"mcm","clk":"1003479105","pt":1580608303501,"mc":[{"id":"1.168186837","rc":[{"batb":[[0,1.84,24.73]],"ltp":1.89,"tv":2575.02,"id":8639275},{"batb":[[0,2.12,6.59],[1,2.1,55.59],[2,2.08,3.73]],"ltp":2.16,"tv":2453.14,"id":8173434}]}]}
{"op":"mcm","clk":"1003479173","pt":1580608304694,"mc":[{"id":"1.168186837","rc":[{"batb":[[0,1.84,28.99]],"batl":[[0,1.86,4.22],[1,1.87,20.35],[2,1.88,4.16]],"ltp":1.89,"tv":2575.02,"id":8639275},{"batb":[[0,2.12,4.55],[1,2.1,46.05],[2,2.08,5.79]],"ltp":2.16,"tv":2453.14,"id":8173434}]}]}
{"op":"mcm","clk":"1003479225","pt":1580608305505,"mc":[{"id":"1.168186837","rc":[{"batb":[[0,1.84,24.73]],"batl":[[0,1.87,20.35],[1,1.88,4.16],[2,1.89,4.13]],"ltp":1.89,"tv":2575.02,"id":8639275},{"batb":[[0,2.12,6.55]],"ltp":2.16,"tv":2453.14,"id":8173434}]}]}
{"op":"mcm","clk":"1003479271","pt":1580608306234,"mc":[{"id":"1.168186837","rc":[{"batb":[[0,1.84,28.99]],"batl":[[0,1.86,4.22],[1,1.87,20.35],[2,1.88,4.16]],"ltp":1.89,"tv":2575.02,"id":8639275},{"batb":[[0,2.12,6.59]],"ltp":2.16,"tv":2453.14,"id":8173434}]}]}
{"op":"mcm","clk":"1003479303","pt":1580608306714,"mc":[{"id":"1.168186837","rc":[{"batb":[[0,1.84,24.73]],"ltp":1.89,"tv":2575.02,"id":8639275}]}]}
{"op":"mcm","clk":"1003479415","pt":1580608308698,"mc":[{"id":"1.168186837","rc":[{"batb":[[0,2.14,4.53],[1,2.12,15.16],[2,2.1,46.08]],"ltp":2.16,"tv":2453.14,"id":8173434}]}]}
{"op":"mcm","clk":"1003479961","pt":1580608318610,"mc":[{"id":"1.168186837","rc":[{"batl":[[0,1.86,20.38],[1,1.87,4.18]],"ltp":1.89,"tv":2575.02,"id":8639275},{"batb":[[2,2.1,44.04]],"ltp":2.16,"tv":2453.14,"id":8173434}]}]}
{"op":"mcm","clk":"1003479988","pt":1580608319228,"mc":[{"id":"1.168186837","rc":[{"batb":[[2,2.1,46.08]],"ltp":2.16,"tv":2453.14,"id":8173434}]}]}
{"op":"mcm","clk":"1003480731","pt":1580608332519,"mc":[{"id":"1.168186837","rc":[{"batl":[[0,1.86,20.56]],"ltp":1.89,"tv":2575.02,"id":8639275},{"batb":[[2,2.1,44.04]],"ltp":2.16,"tv":2453.14,"id":8173434}]}]}
{"op":"mcm","clk":"1003480746","pt":1580608332724,"mc":[{"id":"1.168186837","rc":[{"batb":[[2,2.1,46.07]],"ltp":2.16,"tv":2453.14,"id":8173434}]}]}
{"op":"mcm","clk":"1003482530","pt":1580608359577,"mc":[{"id":"1.168186837","rc":[{"trd":[[1.85,312.15]],"ltp":1.85,"tv":2583.36,"id":8639275},{"batb":[[2,2.1,46.08]],"ltp":2.16,"tv":2453.14,"id":8173434}],"tv":5036.51}]}
{"op":"mcm","clk":"1003482614","pt":1580608360675,"mc":[{"id":"1.168186837","rc":[{"trd":[[1.86,854.03]],"batb":[[0,1.85,4.24],[1,1.84,29],[2,1.83,4.28]],"batl":[[0,1.87,4.22],[1,1.88,4.16],[2,1.9,5.55]],"ltp":1.86,"tv":2624.42,"id":8639275},{"batb":[[1,2.12,13.12]],"ltp":2.16,"tv":2453.14,"id":8173434}],"tv":5077.57}]}
{"op":"mcm","clk":"1003482690","pt":1580608361467,"mc":[{"id":"1.168186837","rc":[{"batb":[[2,1.83,6.31]],"ltp":1.86,"tv":2624.42,"id":8639275},{"batl":[[1,2.22,5.59]],"ltp":2.16,"tv":2453.14,"id":8173434}]}]}
{"op":"mcm","clk":"1003482743","pt":1580608362099,"mc":[{"id":"1.168186837","rc":[{"batl":[[2,2,18.66]],"ltp":1.86,"tv":2624.42,"id":8639275},{"batb":[[1,2.12,3.68]],"ltp":2.16,"tv":2453.14,"id":8173434}]}]}
{"op":"mcm","clk":"1003483353","pt":1580608370574,"mc":[{"id":"1.168186837","rc":[{"batb":[[0,1.85,20.67]],"batl":[[0,1.87,4.18],[1,1.88,4.19]],"ltp":1.86,"tv":2624.42,"id":8639275},{"batl":[[0,2.18,17.54],[1,2.2,3.55],[2,2.22,5.59]],"ltp":2.16,"tv":2453.14,"id":8173434}]}]}
{"op":"mcm","clk":"1003484353","pt":1580608384496,"mc":[{"id":"1.168186837","rc":[{"batl":[[1,1.88,20.32]],"ltp":1.86,"tv":2624.42,"id":8639275}]}]}
{"op":"mcm","clk":"1003484402","pt":1580608385215,"mc":[{"id":"1.168186837","rc":[{"batl":[[2,1.9,5.55]],"ltp":1.86,"tv":2624.42,"id":8639275}]}]}
{"op":"mcm","clk":"1003485870","pt":1580608406614,"mc":[{"id":"1.168186837","rc":[{"trd":[[1.85,320.63]],"batb":[[0,1.84,29],[1,1.83,6.31],[2,1.82,6.93]],"batl":[[0,1.87,20.44],[1,1.88,4.16]],"ltp":1.85,"tv":2632.9,"id":8639275},{"batl":[[0,2.18,3.6]],"ltp":2.16,"tv":2453.14,"id":8173434}],"tv":5086.05}]}
{"op":"mcm","clk":"1003485942","pt":1580608407643,"mc":[{"id":"1.168186837","rc":[{"batb":[[0,1.84,41.15],[1,1.83,4.28],[2,1.82,8.96]],"batl":[[0,1.86,4.23],[1,1.87,20.44],[2,1.88,4.16]],"ltp":1.85,"tv":2632.9,"id":8639275},{"batb":[[1,2.12,5.72]],"batl":[[0,2.2,17.48],[1,2.22,3.52],[2,2.24,2]],"ltp":2.16,"tv":2453.14,"id":8173434}]}]}
{"op":"mcm","clk":"1003486007","pt":1580608408516,"mc":[{"id":"1.168186837","rc":[{"batb":[[1,2.12,15.16]],"ltp":2.16,"tv":2453.14,"id":8173434}]}]}
{"op":"mcm","clk":"1003486929","pt":1580608421665,"mc":[{"id":"1.168186837","rc":[{"trd":[[1.86,862.39]],"batl":[[0,1.87,20.48],[1,1.88,4.16],[2,1.9,5.55]],"ltp":1.86,"tv":2641.27,"id":8639275},{"batb":[[2,2.1,44.04]],"ltp":2.16,"tv":2453.14,"id":8173434}],"tv":5094.42}]}
{"op":"mcm","clk":"1003487004","pt":1580608422586,"mc":[{"id":"1.168186837","rc":[{"batb":[[0,1.84,45.43]],"batl":[[0,1.87,20.44]],"ltp":1.86,"tv":2641.27,"id":8639275},{"batb":[[1,2.12,3.68],[2,2.1,46.08]],"batl":[[0,2.18,3.6],[1,2.2,17.48],[2,2.22,5.68]],"ltp":2.16,"tv":2453.14,"id":8173434}]}]}
{"op":"mcm","clk":"1003487095","pt":1580608423569,"mc":[{"id":"1.168186837","rc":[{"batb":[[0,1.85,4.25],[1,1.84,45.43],[2,1.83,6.31]],"ltp":1.86,"tv":2641.27,"id":8639275}]}]}
{"op":"mcm","clk":"1003487175","pt":1580608424553,"mc":[{"id":"1.168186837","rc":[{"trd":[[1.86,870.76]],"batb":[[0,1.84,45.43],[1,1.83,4.28],[2,1.82,8.96]],"batl":[[0,1.87,20.48]],"ltp":1.86,"tv":2649.63,"id":8639275},{"batb":[[1,2.12,5.69]],"batl":[[0,2.2,17.48],[1,2.22,5.68],[2,2.24,2.23]],"ltp":2.16,"tv":2453.14,"id":8173434}],"tv":5102.78}]}
{"op":"mcm","clk":"1003487231","pt":1580608425378,"mc":[{"id":"1.168186837","rc":[{"batb":[[0,1.85,4.25],[1,1.84,45.43],[2,1.83,6.31]],"batl":[[0,1.87,20.44]],"ltp":1.86,"tv":2649.63,"id":8639275},{"batb":[[1,2.12,3.68]],"batl":[[0,2.18,3.6],[1,2.2,17.48],[2,2.22,5.59]],"ltp":2.16,"tv":2453.14,"id":8173434}]}]}
{"op":"mcm","clk":"1003488533","pt":1580608442689,"mc":[{"id":"1.168186837","rc":[{"trd":[[1.85,327.83]],"batb":[[0,1.85,12.83],[1,1.84,29]],"batl":[[0,1.86,4.23],[1,1.87,20.44],[2,1.88,4.16]],"ltp":1.85,"tv":2656.83,"id":8639275},{"batl":[[0,2.18,17.54],[1,2.2,3.55]],"ltp":2.16,"tv":2453.14,"id":8173434}],"tv":5109.98}]}
{"op":"mcm","clk":"1003488611","pt":1580608443670,"mc":[{"id":"1.168186837","rc":[{"trd":[[1.86,879.12]],"batl":[[0,1.86,16.3],[1,1.87,4.18]],"ltp":1.86,"tv":2665.19,"id":8639275},{"batb":[[1,2.12,5.72]],"ltp":2.16,"tv":2453.14,"id":8173434}],"tv":5118.34}]}
{"op":"mcm","clk":"1003488675","pt":1580608444698,"mc":[{"id":"1.168186837","rc":[{"trd":[[1.86,911.46]],"batl":[[0,1.87,4.32],[1,1.88,4.16],[2,1.9,5.55]],"ltp":1.86,"tv":2697.54,"id":8639275},{"batb":[[1,2.12,3.68]],"ltp":2.16,"tv":2453.14,"id":8173434}],"tv":5150.69}]}
{"op":"mcm","clk":"1003488712","pt":1580608445163,"mc":[{"id":"1.168186837","rc":[{"batb":[[0,1.85,17.08]],"ltp":1.86,"tv":2697.54,"id":8639275}]}]}
{"op":"mcm","clk":"1003488771","pt":1580608445988,"mc":[{"id":"1.168186837","rc":[{"batl":[[2,2,18.66]],"ltp":1.86,"tv":2697.54,"id":8639275}]}]}
{"op":"mcm","clk":"1003489037","pt":1580608449191,"mc":[{"id":"1.168186837","rc":[{"batl":[[0,1.87,4.18]],"ltp":1.86,"tv":2697.54,"id":8639275}]}]}
{"op":"mcm","clk":"1003489753","pt":1580608458697,"mc":[{"id":"1.168186837","rc":[{"batl":[[1,1.88,11.5]],"ltp":1.86,"tv":2697.54,"id":8639275}]}]}
{"op":"mcm","clk":"1003492639","pt":1580608502469,"mc":[{"id":"1.168186837","rc":[{"batb":[[0,1.85,20.68]],"ltp":1.86,"tv":2697.54,"id":8639275}]}]}
{"op":"mcm","clk":"1003492673","pt":1580608503034,"mc":[{"id":"1.168186837","rc":[{"trd":[[1.85,363.88]],"batb":[[0,1.85,2.66]],"ltp":1.85,"tv":2733.59,"id":8639275},{"batl":[[0,2.18,13.94]],"ltp":2.16,"tv":2453.14,"id":8173434}],"tv":5186.73}]}
{"op":"mcm","clk":"1003492858","pt":1580608506471,"mc":[{"id":"1.168186837","rc":[{"batl":[[1,1.88,20.32]],"ltp":1.85,"tv":2733.59,"id":8639275}]}]}
{"op":"mcm","clk":"1003492988","pt":1580608508567,"mc":[{"id":"1.168186837","rc":[{"batl":[[2,1.9,5.55]],"ltp":1.85,"tv":2733.59,"id":8639275}]}]}
{"op":"mcm","clk":"1003493528","pt":1580608516684,"mc":[{"id":"1.168186837","rc":[{"batb":[[0,1.85,1.49]],"ltp":1.85,"tv":2733.59,"id":8639275}]}]}
{"op":"mcm","clk":"1003493544","pt":1580608516899,"mc":[{"id":"1.168186837","rc":[{"batb":[[2,1.83,4.28]],"ltp":1.85,"tv":2733.59,"id":8639275}]}]}
{"op":"mcm","clk":"1003494013","pt":1580608524694,"mc":[{"id":"1.168186837","rc":[{"batb":[[0,1.84,29],[1,1.83,4.28],[2,1.82,8.96]],"batl":[[0,1.86,4.24],[1,1.87,20.44],[2,1.88,4.16]],"ltp":1.85,"tv":2733.59,"id":8639275},{"batl":[[0,2.2,3.55],[1,2.22,5.59],[2,2.24,2.23]],"ltp":2.16,"tv":2453.14,"id":8173434}]}]}
{"op":"mcm","clk":"1003494088","pt":1580608525573,"mc":[{"id":"1.168186837","rc":[{"trd":[[1.86,919.83]],"batb":[[0,1.85,4.26],[1,1.84,30.5],[2,1.83,6.28]],"batl":[[0,1.87,20.44],[1,1.88,4.16],[2,1.9,5.55]],"ltp":1.86,"tv":2741.95,"id":8639275},{"batl":[[0,2.18,3.62],[1,2.2,17.48],[2,2.22,5.59]],"ltp":2.16,"tv":2453.14,"id":8173434}],"tv":5195.1}]}
{"op":"mcm","clk":"1003496348","pt":1580608558698,"mc":[{"id":"1.168186837","rc":[{"batb":[[0,1.85,1.49],[1,1.84,29]],"batl":[[0,1.86,4.24],[1,1.87,20.44],[2,1.88,4.16]],"ltp":1.86,"tv":2741.95,"id":8639275},{"trd":[[2.18,65.02]],"batl":[[0,2.2,18.41],[1,2.22,5.59],[2,2.24,2.23]],"ltp":2.18,"tv":2458.54,"id":8173434}],"tv":5200.5}]}
{"op":"mcm","clk":"1003496410","pt":1580608559421,"mc":[{"id":"1.168186837","rc":[{"batb":[[1,1.84,24.73],[2,1.83,4.28]],"ltp":1.86,"tv":2741.95,"id":8639275},{"batb":[[1,2.12,5.72]],"batl":[[0,2.2,17.48],[1,2.22,3.52]],"ltp":2.18,"tv":2458.54,"id":8173434}]}]}
{"op":"mcm","clk":"1003496457","pt":1580608560034,"mc":[{"id":"1.168186837","rc":[{"batb":[[1,2.12,15.16]],"ltp":2.18,"tv":2458.54,"id":8173434}]}]}
{"op":"mcm","clk":"1003496573","pt":1580608561637,"mc":[{"id":"1.168186837","rc":[{"batl":[[0,1.86,20.5],[1,1.87,4.18]],"ltp":1.86,"tv":2741.95,"id":8639275}]}]}
{"op":"mcm","clk":"1003496896","pt":1580608566612,"mc":[{"id":"1.168186837","rc":[{"batb":[[0,1.84,24.73],[1,1.83,4.28],[2,1.82,8.96]],"ltp":1.86,"tv":2741.95,"id":8639275}]}]}
{"op":"mcm","clk":"1003496910","pt":1580608566817,"mc":[{"id":"1.168186837","rc":[{"batb":[[0,1.84,30.51]],"ltp":1.86,"tv":2741.95,"id":8639275}]}]}
{"op":"mcm","clk":"1003497655","pt":1580608579519,"mc":[{"id":"1.168186837","rc":[{"batb":[[0,1.84,44.28]],"batl":[[0,1.86,20.58]],"ltp":1.86,"tv":2741.95,"id":8639275}]}]}
{"op":"mcm","clk":"1003501305","pt":1580608636626,"mc":[{"id":"1.168186837","rc":[{"trd":[[1.86,939.35]],"batl":[[0,1.86,1.06]],"ltp":1.86,"tv":2761.47,"id":8639275},{"trd":[[2.16,179.43]],"batb":[[0,2.14,3.66]],"ltp":2.16,"tv":2477.09,"id":8173434}],"tv":5238.56}]}
{"op":"mcm","clk":"1003501372","pt":1580608637701,"mc":[{"id":"1.168186837","rc":[{"batb":[[0,1.85,4.28],[1,1.84,44.28],[2,1.83,6.31]],"ltp":1.86,"tv":2761.47,"id":8639275},{"batb":[[1,2.12,13.12]],"batl":[[0,2.18,3.63],[1,2.2,17.48],[2,2.22,5.59]],"ltp":2.16,"tv":2477.09,"id":8173434}]}]}
{"op":"mcm","clk":"1003501416","pt":1580608638423,"mc":[{"id":"1.168186837","rc":[{"batb":[[1,2.12,3.68]],"ltp":2.16,"tv":2477.09,"id":8173434}]}]}
{"op":"mcm","clk":"1003501858","pt":1580608645642,"mc":[{"id":"1.168186837","rc":[{"batb":[[0,1.85,20.7]],"ltp":1.86,"tv":2761.47,"id":8639275}]}]}
{"op":"mcm","clk":"1003501904","pt":1580608646262,"mc":[{"id":"1.168186837","rc":[{"batb":[[1,1.84,29.02]],"batl":[[0,1.87,4.18],[1,1.88,4.16],[2,2,18.66]],"ltp":1.86,"tv":2761.47,"id":8639275},{"batl":[[0,2.18,17.57],[1,2.2,3.55]],"ltp":2.16,"tv":2477.09,"id":8173434}]}]}
{"op":"mcm","clk":"1003502445","pt":1580608655047,"mc":[{"id":"1.168186837","rc":[{"batb":[[1,1.84,4.29]],"ltp":1.86,"tv":2761.47,"id":8639275}]}]}
{"op":"mcm","clk":"1003502538","pt":1580608656642,"mc":[{"id":"1.168186837","rc":[{"batb":[[0,1.85,4.28]],"batl":[[0,1.87,9.99]],"ltp":1.86,"tv":2761.47,"id":8639275}]}]}
{"op":"mcm","clk":"1003502563","pt":1580608657047,"mc":[{"id":"1.168186837","rc":[{"batb":[[1,1.84,20.72]],"batl":[[0,1.87,4.18],[1,1.88,9.96]],"ltp":1.86,"tv":2761.47,"id":8639275}]}]}
{"op":"mcm","clk":"1003502940","pt":1580608663569,"mc":[{"id":"1.168186837","rc":[{"trd":[[1.85,371.12]],"batb":[[0,1.84,20.72],[1,1.83,4.28],[2,1.82,56.02]],"ltp":1.85,"tv":2768.71,"id":8639275},{"batl":[[0,2.18,13.94]],"ltp":2.16,"tv":2477.09,"id":8173434}],"tv":5245.8}]}
{"op":"mcm","clk":"1003503069","pt":1580608665673,"mc":[{"id":"1.168186837","rc":[{"batb":[[0,1.83,20.7],[1,1.82,53.99],[2,1.81,2.08]],"ltp":1.85,"tv":2768.71,"id":8639275},{"batl":[[0,2.2,17.48],[1,2.22,3.52],[2,2.24,2.23]],"ltp":2.16,"tv":2477.09,"id":8173434}]}]}
{"op":"mcm","clk":"1003503755","pt":1580608676673,"mc":[{"id":"1.168186837","rc":[{"batl":[[1,1.88,4.16]],"ltp":1.85,"tv":2768.71,"id":8639275}]}]}
{"op":"mcm","clk":"1003503787","pt":1580608677140,"mc":[{"id":"1.168186837","rc":[{"batl":[[0,1.87,9.99]],"ltp":1.85,"tv":2768.71,"id":8639275}]}]}
{"op":"mcm","clk":"1003504780","pt":1580608692609,"mc":[{"id":"1.168186837","rc":[{"batb":[[0,1.84,4.3],[1,1.83,20.7],[2,1.82,56.02]],"ltp":1.85,"tv":2768.71,"id":8639275}]}]}
{"op":"mcm","clk":"1003507723","pt":1580608739435,"mc":[{"id":"1.168186837","rc":[{"trd":[[1.85,375.85]],"batl":[[0,1.87,10.16]],"ltp":1.85,"tv":2773.45,"id":8639275}],"tv":5250.54}]}
