{"op":"mcm","clk":"988026418","pt":1580473742115,"mc":[{"id":"1.168135798","marketDefinition":{"bspMarket":false,"turnInPlayEnabled":true,"persistenceEnabled":true,"marketBaseRate":5.0,"eventId":"29678823","eventTypeId":"2","numberOfWinners":1,"bettingType":"ODDS","marketType":"SET_WINNER","marketTime":"2020-02-02T08:30:00.000Z","suspendTime":"2020-02-02T08:30:00.000Z","bspReconciled":false,"complete":true,"inPlay":false,"crossMatching":false,"runnersVoidable":false,"numberOfActiveRunners":2,"betDelay":0,"status":"OPEN","runners":[{"status":"ACTIVE","sortPriority":1,"id":5720747,"name":"Dominic Thiem"},{"status":"ACTIVE","sortPriority":2,"id":2249229,"name":"Novak Djokovic"}],"regulators":["MR_INT"],"countryCode":"AU","discountAllowed":false,"timezone":"GMT","openDate":"2020-02-02T08:30:00.000Z","version":3143005247,"name":"Set 3 Winner","eventName":"Thiem v Djokovic"},"rc":[{"batb":[[0,1.01,20]],"ltp":0.0,"tv":0.0,"id":2249229},{"batb":[[0,1.01,20]],"ltp":0.0,"tv":0.0,"id":5720747}]}]}
{"op":"mcm","clk":"988026715","pt":1580473744836,"mc":[{"id":"1.168135798","marketDefinition":{"bspMarket":false,"turnInPlayEnabled":true,"persistenceEnabled":true,"marketBaseRate":5.0,"eventId":"29678823","eventTypeId":"2","numberOfWinners":1,"bettingType":"ODDS","marketType":"SET_WINNER","marketTime":"2020-02-02T08:30:00.000Z","suspendTime":"2020-02-02T08:30:00.000Z","bspReconciled":false,"complete":true,"inPlay":false,"crossMatching":false,"runnersVoidable":false,"numberOfActiveRunners":2,"betDelay":0,"status":"OPEN","runners":[{"status":"ACTIVE","sortPriority":1,"id":5720747,"name":"Dominic Thiem"},{"status":"ACTIVE","sortPriority":2,"id":2249229,"name":"Novak Djokovic"}],"regulators":["MR_INT"],"countryCode":"AU","discountAllowed":true,"timezone":"GMT","openDate":"2020-02-02T08:30:00.000Z","version":3143005247,"name":"Set 3 Winner","eventName":"Thiem v Djokovic"}}]}
{"op":"mcm","clk":"988033919","pt":1580473818253,"mc":[{"id":"1.168135798","rc":[{"batb":[[0,1.01,10]],"ltp":0.0,"tv":0.0,"id":2249229},{"batb":[[0,1.01,10]],"ltp":0.0,"tv":0.0,"id":5720747}]}]}
{"op":"mcm","clk":"989799750","pt":1580491425702,"mc":[{"id":"1.168135798","rc":[{"batb":[[0,1.01,11.68]],"ltp":0.0,"tv":0.0,"id":2249229},{"batb":[[0,1.01,11.68]],"ltp":0.0,"tv":0.0,"id":5720747}]}]}
{"op":"mcm","clk":"989799825","pt":1580491426319,"mc":[{"id":"1.168135798","rc":[{"batb":[[0,1.01,10.2]],"ltp":0.0,"tv":0.0,"id":2249229},{"batb":[[0,1.01,10.2]],"ltp":0.0,"tv":0.0,"id":5720747}]}]}
{"op":"mcm","clk":"991991594","pt":1580511707738,"mc":[{"id":"1.168135798","rc":[{"batb":[[0,1.01,10.71]],"ltp":0.0,"tv":0.0,"id":2249229},{"batb":[[0,1.01,10.71]],"ltp":0.0,"tv":0.0,"id":5720747}]}]}
{"op":"mcm","clk":"992004218","pt":1580511983757,"mc":[{"id":"1.168135798","rc":[{"batb":[[0,1.01,11.21]],"ltp":0.0,"tv":0.0,"id":2249229},{"batb":[[0,1.01,11.21]],"ltp":0.0,"tv":0.0,"id":5720747}]}]}
{"op":"mcm","clk":"992859043","pt":1580531894609,"mc":[{"id":"1.168135798","rc":[{"batb":[[0,1.02,2780.76],[1,1.01,2791.57]],"ltp":0.0,"tv":0.0,"id":2249229},{"batb":[[0,1.02,2780.76],[1,1.01,2791.57]],"ltp":0.0,"tv":0.0,"id":5720747}]}]}
{"op":"mcm","clk":"992859544","pt":1580531911833,"mc":[{"id":"1.168135798","marketDefinition":{"bspMarket":false,"turnInPlayEnabled":true,"persistenceEnabled":true,"marketBaseRate":5.0,"eventId":"29678823","eventTypeId":"2","numberOfWinners":1,"bettingType":"ODDS","marketType":"SET_WINNER","marketTime":"2020-02-02T08:30:00.000Z","suspendTime":"2020-02-02T08:30:00.000Z","bspReconciled":false,"complete":true,"inPlay":false,"crossMatching":true,"runnersVoidable":false,"numberOfActiveRunners":2,"betDelay":0,"status":"OPEN","runners":[{"status":"ACTIVE","sortPriority":1,"id":5720747,"name":"Dominic Thiem"},{"status":"ACTIVE","sortPriority":2,"id":2249229,"name":"Novak Djokovic"}],"regulators":["MR_INT"],"countryCode":"AU","discountAllowed":true,"timezone":"GMT","openDate":"2020-02-02T08:30:00.000Z","version":3143005247,"name":"Set 3 Winner","eventName":"Thiem v Djokovic"}}]}
{"op":"mcm","clk":"993080405","pt":1580536224793,"mc":[{"id":"1.168135798","rc":[{"batb":[[0,1.36,800],[1,1.02,2780.76],[2,1.01,2791.57]],"ltp":0.0,"tv":0.0,"id":2249229}]}]}
{"op":"mcm","clk":"993211320","pt":1580538611690,"mc":[{"id":"1.168135798","rc":[{"batb":[[0,1.37,6],[1,1.36,800],[2,1.02,2780.76]],"ltp":0.0,"tv":0.0,"id":2249229}]}]}
{"op":"mcm","clk":"996559663","pt":1580562694813,"mc":[{"id":"1.168135798","rc":[{"batb":[[0,1.38,857.46],[1,1.37,6],[2,1.36,800]],"ltp":0.0,"tv":0.0,"id":2249229},{"batb":[[0,2.58,218.56],[1,1.02,2780.76],[2,1.01,2791.57]],"ltp":0.0,"tv":0.0,"id":5720747}]}]}
{"op":"mcm","clk":"996613828","pt":1580562956938,"mc":[{"id":"1.168135798","rc":[{"batb":[[0,1.37,6],[1,1.36,800],[2,1.02,2780.76]],"ltp":0.0,"tv":0.0,"id":2249229}]}]}
{"op":"mcm","clk":"996614206","pt":1580562958722,"mc":[{"id":"1.168135798","rc":[{"batb":[[0,1.38,964.88],[1,1.37,6],[2,1.36,800]],"ltp":0.0,"tv":0.0,"id":2249229}]}]}
{"op":"mcm","clk":"996620498","pt":1580562988834,"mc":[{"id":"1.168135798","rc":[{"batb":[[0,1.37,6],[1,1.36,800],[2,1.02,2780.76]],"ltp":0.0,"tv":0.0,"id":2249229}]}]}
{"op":"mcm","clk":"997015445","pt":1580564804133,"mc":[{"id":"1.168135798","rc":[{"batb":[[0,1.02,2780.76],[1,1.01,2791.57],[2,1.01,0]],"ltp":0.0,"tv":0.0,"id":5720747}]}]}
{"op":"mcm","clk":"997015688","pt":1580564805454,"mc":[{"id":"1.168135798","rc":[{"batb":[[0,1.38,857.46],[1,1.37,6],[2,1.36,800]],"ltp":0.0,"tv":0.0,"id":2249229},{"batb":[[0,2.48,227.51],[1,1.02,2780.76],[2,1.01,2791.57]],"ltp":0.0,"tv":0.0,"id":5720747}]}]}
{"op":"mcm","clk":"997118019","pt":1580565414505,"mc":[{"id":"1.168135798","rc":[{"batb":[[0,1.37,6],[1,1.36,800],[2,1.02,2780.76]],"ltp":0.0,"tv":0.0,"id":2249229},{"batb":[[0,1.02,2780.76],[1,1.01,2791.57],[2,1.01,0]],"ltp":0.0,"tv":0.0,"id":5720747}]}]}
{"op":"mcm","clk":"997118266","pt":1580565415799,"mc":[{"id":"1.168135798","rc":[{"batb":[[0,1.38,857.46],[1,1.37,6],[2,1.36,800]],"ltp":0.0,"tv":0.0,"id":2249229},{"batb":[[0,2.5,225.76],[1,1.02,2780.76],[2,1.01,2791.57]],"ltp":0.0,"tv":0.0,"id":5720747}]}]}
{"op":"mcm","clk":"997156099","pt":1580565642745,"mc":[{"id":"1.168135798","rc":[{"batb":[[0,1.02,2780.76],[1,1.01,2791.57],[2,1.01,0]],"ltp":0.0,"tv":0.0,"id":5720747}]}]}
{"op":"mcm","clk":"997156207","pt":1580565643336,"mc":[{"id":"1.168135798","rc":[{"batb":[[0,2.5,225.76],[1,1.02,2780.76],[2,1.01,2791.57]],"ltp":0.0,"tv":0.0,"id":5720747}]}]}
{"op":"mcm","clk":"997284152","pt":1580566251677,"mc":[{"id":"1.168135798","rc":[{"batb":[[0,2.74,205.79]],"ltp":0.0,"tv":0.0,"id":5720747}]}]}
{"op":"mcm","clk":"997298124","pt":1580566305109,"mc":[{"id":"1.168135798","rc":[{"batb":[[0,1.37,6],[1,1.36,800],[2,1.02,2780.76]],"ltp":0.0,"tv":0.0,"id":2249229}]}]}
{"op":"mcm","clk":"997298569","pt":1580566306709,"mc":[{"id":"1.168135798","rc":[{"batb":[[0,1.38,964.88],[1,1.37,6],[2,1.36,800]],"ltp":0.0,"tv":0.0,"id":2249229}]}]}
{"op":"mcm","clk":"997423649","pt":1580566774345,"mc":[{"id":"1.168135798","rc":[{"batb":[[0,1.37,6],[1,1.36,800],[2,1.02,2780.76]],"ltp":0.0,"tv":0.0,"id":2249229}]}]}
{"op":"mcm","clk":"997423879","pt":1580566775929,"mc":[{"id":"1.168135798","rc":[{"batb":[[0,1.38,857.46],[1,1.37,6],[2,1.36,800]],"ltp":0.0,"tv":0.0,"id":2249229}]}]}
{"op":"mcm","clk":"997533622","pt":1580567206750,"mc":[{"id":"1.168135798","rc":[{"batb":[[0,1.37,6],[1,1.36,800],[2,1.02,2780.76]],"ltp":0.0,"tv":0.0,"id":2249229}]}]}
{"op":"mcm","clk":"997533850","pt":1580567207560,"mc":[{"id":"1.168135798","rc":[{"batb":[[0,1.38,964.88],[1,1.37,6],[2,1.36,800]],"ltp":0.0,"tv":0.0,"id":2249229}]}]}
{"op":"mcm","clk":"997643638","pt":1580567655788,"mc":[{"id":"1.168135798","rc":[{"batb":[[0,1.37,6],[1,1.36,800],[2,1.02,2780.76]],"ltp":0.0,"tv":0.0,"id":2249229}]}]}
{"op":"mcm","clk":"997643825","pt":1580567656562,"mc":[{"id":"1.168135798","rc":[{"batb":[[0,1.38,857.46],[1,1.37,6],[2,1.36,800]],"ltp":0.0,"tv":0.0,"id":2249229}]}]}
{"op":"mcm","clk":"997720926","pt":1580567966005,"mc":[{"id":"1.168135798","rc":[{"batb":[[0,1.37,6],[1,1.36,800],[2,1.02,2780.76]],"ltp":0.0,"tv":0.0,"id":2249229}]}]}
{"op":"mcm","clk":"997889105","pt":1580568661357,"mc":[{"id":"1.168135798","rc":[{"batb":[[0,1.02,2780.76],[1,1.01,2791.57],[2,1.01,0]],"ltp":0.0,"tv":0.0,"id":5720747}]}]}
{"op":"mcm","clk":"997889318","pt":1580568662242,"mc":[{"id":"1.168135798","rc":[{"batb":[[0,1.38,964.88],[1,1.37,6],[2,1.36,800]],"ltp":0.0,"tv":0.0,"id":2249229},{"batb":[[0,2.48,227.51],[1,1.02,2780.76],[2,1.01,2791.57]],"ltp":0.0,"tv":0.0,"id":5720747}]}]}
{"op":"mcm","clk":"997957160","pt":1580568971709,"mc":[{"id":"1.168135798","rc":[{"batb":[[0,1.37,6],[1,1.36,800],[2,1.02,2780.76]],"ltp":0.0,"tv":0.0,"id":2249229},{"batb":[[0,1.02,2780.76],[1,1.01,2791.57],[2,1.01,0]],"ltp":0.0,"tv":0.0,"id":5720747}]}]}
{"op":"mcm","clk":"997957307","pt":1580568972285,"mc":[{"id":"1.168135798","rc":[{"batb":[[0,1.38,964.88],[1,1.37,6],[2,1.36,800]],"ltp":0.0,"tv":0.0,"id":2249229}]}]}
{"op":"mcm","clk":"997957510","pt":1580568973117,"mc":[{"id":"1.168135798","rc":[{"batb":[[0,2.54,222.12],[1,1.02,2780.76],[2,1.01,2791.57]],"ltp":0.0,"tv":0.0,"id":5720747}]}]}
{"op":"mcm","clk":"998031570","pt":1580569292546,"mc":[{"id":"1.168135798","rc":[{"batb":[[0,1.38,857.46]],"ltp":0.0,"tv":0.0,"id":2249229}]}]}
{"op":"mcm","clk":"998035844","pt":1580569310584,"mc":[{"id":"1.168135798","rc":[{"batb":[[0,1.37,6],[1,1.36,800],[2,1.02,2780.76]],"ltp":0.0,"tv":0.0,"id":2249229}]}]}
{"op":"mcm","clk":"998036022","pt":1580569311308,"mc":[{"id":"1.168135798","rc":[{"batb":[[0,1.38,857.46],[1,1.37,6],[2,1.36,800]],"ltp":0.0,"tv":0.0,"id":2249229}]}]}
{"op":"mcm","clk":"998110141","pt":1580569600824,"mc":[{"id":"1.168135798","rc":[{"batb":[[0,1.37,6],[1,1.36,800],[2,1.02,2780.76]],"ltp":0.0,"tv":0.0,"id":2249229}]}]}
{"op":"mcm","clk":"998110418","pt":1580569601831,"mc":[{"id":"1.168135798","rc":[{"batb":[[0,1.38,857.46],[1,1.37,6],[2,1.36,800]],"ltp":0.0,"tv":0.0,"id":2249229}]}]}
{"op":"mcm","clk":"998193994","pt":1580569912196,"mc":[{"id":"1.168135798","rc":[{"batb":[[0,1.37,6],[1,1.36,800],[2,1.02,2780.76]],"ltp":0.0,"tv":0.0,"id":2249229}]}]}
{"op":"mcm","clk":"998194187","pt":1580569913026,"mc":[{"id":"1.168135798","rc":[{"batb":[[0,1.38,857.46],[1,1.37,6],[2,1.36,800]],"ltp":0.0,"tv":0.0,"id":2249229}]}]}
{"op":"mcm","clk":"998296994","pt":1580570308283,"mc":[{"id":"1.168135798","rc":[{"batb":[[0,1.37,6],[1,1.36,800],[2,1.02,2780.76]],"ltp":0.0,"tv":0.0,"id":2249229}]}]}
{"op":"mcm","clk":"998297282","pt":1580570309506,"mc":[{"id":"1.168135798","rc":[{"batb":[[0,1.38,857.46],[1,1.37,6],[2,1.36,800]],"ltp":0.0,"tv":0.0,"id":2249229}]}]}
{"op":"mcm","clk":"998353125","pt":1580570530263,"mc":[{"id":"1.168135798","rc":[{"batb":[[0,1.37,6],[1,1.36,800],[2,1.02,2780.76]],"ltp":0.0,"tv":0.0,"id":2249229},{"batb":[[0,1.02,2780.76],[1,1.01,2791.57],[2,1.01,0]],"ltp":0.0,"tv":0.0,"id":5720747}]}]}
{"op":"mcm","clk":"1000967146","pt":1580584184243,"mc":[{"id":"1.168135798","rc":[{"batb":[[0,1.43,14],[1,1.37,6],[2,1.36,800]],"ltp":0.0,"tv":0.0,"id":2249229}]}]}
{"op":"mcm","clk":"1000967311","pt":1580584185022,"mc":[{"id":"1.168135798","rc":[{"batb":[[0,2.72,207.34],[1,1.02,2780.76],[2,1.01,2791.57]],"ltp":0.0,"tv":0.0,"id":5720747}]}]}
{"op":"mcm","clk":"1001339839","pt":1580586107548,"mc":[{"id":"1.168135798","rc":[{"batb":[[0,2.54,222.12]],"ltp":0.0,"tv":0.0,"id":5720747}]}]}
{"op":"mcm","clk":"1001419824","pt":1580586572804,"mc":[{"id":"1.168135798","rc":[{"batb":[[0,2.6,216.79]],"ltp":0.0,"tv":0.0,"id":5720747}]}]}
{"op":"mcm","clk":"1001752648","pt":1580588389746,"mc":[{"id":"1.168135798","rc":[{"batb":[[0,1.02,2780.76],[1,1.01,2791.57],[2,1.01,0]],"ltp":0.0,"tv":0.0,"id":5720747}]}]}
{"op":"mcm","clk":"1002482691","pt":1580594263555,"mc":[{"id":"1.168135798","rc":[{"batb":[[0,2.62,215.33],[1,2.5,41.31],[2,1.02,2780.76]],"ltp":0.0,"tv":0.0,"id":5720747}]}]}
{"op":"mcm","clk":"1002483826","pt":1580594278758,"mc":[{"id":"1.168135798","rc":[{"batb":[[0,2.8,201.18],[1,2.7,41.31]],"ltp":0.0,"tv":0.0,"id":5720747}]}]}
{"op":"mcm","clk":"1002484340","pt":1580594285372,"mc":[{"id":"1.168135798","rc":[{"batb":[[0,2.92,192.94],[1,2.9,41.31]],"ltp":0.0,"tv":0.0,"id":5720747}]}]}
{"op":"mcm","clk":"1002484638","pt":1580594289368,"mc":[{"id":"1.168135798","rc":[{"batb":[[0,3,229.19],[1,1.02,2780.76],[2,1.01,2791.57]],"ltp":0.0,"tv":0.0,"id":5720747}]}]}
{"op":"mcm","clk":"1002602901","pt":1580595932737,"mc":[{"id":"1.168135798","rc":[{"batb":[[1,1.36,800],[2,1.02,2780.76]],"ltp":0.0,"tv":0.0,"id":2249229}]}]}
{"op":"mcm","clk":"1002709408","pt":1580597622560,"mc":[{"id":"1.168135798","rc":[{"batb":[[0,3,41.31]],"ltp":0.0,"tv":0.0,"id":5720747}]}]}
{"op":"mcm","clk":"1002709436","pt":1580597623027,"mc":[{"id":"1.168135798","rc":[{"batb":[[0,3,229.19]],"ltp":0.0,"tv":0.0,"id":5720747}]}]}
{"op":"mcm","clk":"1002710514","pt":1580597640456,"mc":[{"id":"1.168135798","rc":[{"batb":[[0,3,41.31]],"ltp":0.0,"tv":0.0,"id":5720747}]}]}
{"op":"mcm","clk":"1003035207","pt":1580602215235,"mc":[{"id":"1.168135798","rc":[{"batb":[[0,1.44,756.17],[1,1.43,14],[2,1.36,800]],"ltp":0.0,"tv":0.0,"id":2249229}]}]}
{"op":"mcm","clk":"1003036214","pt":1580602226430,"mc":[{"id":"1.168135798","rc":[{"batb":[[0,1.43,14],[1,1.36,800],[2,1.02,2780.76]],"ltp":0.0,"tv":0.0,"id":2249229}]}]}
{"op":"mcm","clk":"1003038059","pt":1580602246370,"mc":[{"id":"1.168135798","rc":[{"batb":[[0,1.44,756.17],[1,1.43,14],[2,1.36,800]],"ltp":0.0,"tv":0.0,"id":2249229}]}]}
{"op":"mcm","clk":"1003038801","pt":1580602254364,"mc":[{"id":"1.168135798","rc":[{"batb":[[0,1.43,14],[1,1.36,800],[2,1.02,2780.76]],"ltp":0.0,"tv":0.0,"id":2249229}]}]}
{"op":"mcm","clk":"1003039762","pt":1580602264610,"mc":[{"id":"1.168135798","rc":[{"batb":[[0,1.44,756.17],[1,1.43,14],[2,1.36,800]],"ltp":0.0,"tv":0.0,"id":2249229}]}]}
{"op":"mcm","clk":"1003064392","pt":1580602531258,"mc":[{"id":"1.168135798","rc":[{"batb":[[0,1.43,14],[1,1.36,800],[2,1.02,2780.76]],"ltp":0.0,"tv":0.0,"id":2249229}]}]}
{"op":"mcm","clk":"1003064475","pt":1580602532493,"mc":[{"id":"1.168135798","rc":[{"batb":[[0,1.44,850.92],[1,1.43,14],[2,1.36,800]],"ltp":0.0,"tv":0.0,"id":2249229}]}]}
{"op":"mcm","clk":"1003161677","pt":1580603741539,"mc":[{"id":"1.168135798","rc":[{"batb":[[0,1.43,14],[1,1.36,800],[2,1.02,2780.76]],"ltp":0.0,"tv":0.0,"id":2249229}]}]}
{"op":"mcm","clk":"1003387987","pt":1580607070797,"mc":[{"id":"1.168135798","rc":[{"batb":[[0,1.43,14.01]],"ltp":0.0,"tv":0.0,"id":2249229},{"batb":[[1,1.02,2780.77]],"ltp":0.0,"tv":0.0,"id":5720747}]}]}
{"op":"mcm","clk":"1003469679","pt":1580608169309,"mc":[{"id":"1.168135798","rc":[{"batb":[[0,3,8.26]],"ltp":0.0,"tv":0.0,"id":5720747}]}]}
{"op":"mcm","clk":"1003469814","pt":1580608170813,"mc":[{"id":"1.168135798","rc":[{"batb":[[0,1.44,756.18],[1,1.43,14],[2,1.36,800]],"ltp":0.0,"tv":0.0,"id":2249229}]}]}
{"op":"mcm","clk":"1003510142","pt":1580608779524,"mc":[{"id":"1.168135798","rc":[{"batb":[[0,1.43,14.01],[1,1.36,800],[2,1.02,2780.76]],"ltp":0.0,"tv":0.0,"id":2249229}]}]}
{"op":"mcm","clk":"1003700915","pt":1580611485430,"mc":[{"id":"1.168135798","rc":[{"batb":[[2,1.01,2793.57]],"ltp":0.0,"tv":0.0,"id":5720747}]}]}
{"op":"mcm","clk":"1003701710","pt":1580611500442,"mc":[{"id":"1.168135798","rc":[{"batb":[[2,1.01,2793.58]],"ltp":0.0,"tv":0.0,"id":5720747}]}]}
{"op":"mcm","clk":"1003702429","pt":1580611513974,"mc":[{"id":"1.168135798","rc":[{"batb":[[0,1.43,14.02]],"ltp":0.0,"tv":0.0,"id":2249229},{"batb":[[1,1.02,2780.78],[2,1.01,2791.57]],"ltp":0.0,"tv":0.0,"id":5720747}]}]}
{"op":"mcm","clk":"1003913514","pt":1580616032064,"mc":[{"id":"1.168135798","rc":[{"batb":[[0,1.44,850.94],[1,1.43,14],[2,1.36,800]],"ltp":0.0,"tv":0.0,"id":2249229}]}]}
{"op":"mcm","clk":"1003938269","pt":1580616636980,"mc":[{"id":"1.168135798","rc":[{"batb":[[0,1.43,14.02],[1,1.36,800],[2,1.02,2780.76]],"ltp":0.0,"tv":0.0,"id":2249229}]}]}
{"op":"mcm","clk":"1004387470","pt":1580628620684,"mc":[{"id":"1.168135798","rc":[{"trd":[[1.49,0.01]],"batb":[[0,1.44,2.01],[1,1.43,14],[2,1.36,800]],"ltp":1.49,"tv":0.01,"id":2249229},{"batb":[[0,3.05,2],[1,3,8.26],[2,1.02,2780.78]],"ltp":0.0,"tv":0.0,"id":5720747}],"tv":0.01}]}
{"op":"mcm","clk":"1004387494","pt":1580628621299,"mc":[{"id":"1.168135798","rc":[{"batb":[[0,1.44,852.93]],"ltp":1.49,"tv":0.01,"id":2249229}]}]}
{"op":"mcm","clk":"1004411255","pt":1580629220799,"mc":[{"id":"1.168135798","rc":[{"batb":[[0,1.44,850.93]],"ltp":1.49,"tv":0.01,"id":2249229},{"batb":[[0,3,8.26],[1,1.02,2780.78],[2,1.01,2791.57]],"ltp":0.0,"tv":0.0,"id":5720747}]}]}
{"op":"mcm","clk":"1004411662","pt":1580629229425,"mc":[{"id":"1.168135798","rc":[{"batb":[[0,1.45,2.01]],"ltp":1.49,"tv":0.01,"id":2249229},{"batb":[[0,3.05,2],[1,3,8.26],[2,1.02,2780.78]],"ltp":0.0,"tv":0.0,"id":5720747}]}]}
{"op":"mcm","clk":"1004434241","pt":1580629757377,"mc":[{"id":"1.168135798","rc":[{"trd":[[1.43,1.06],[1.45,4],[1.48,0.02]],"batb":[[0,1.43,13.47],[1,1.36,800],[2,1.02,2780.76]],"ltp":1.43,"tv":5.08,"id":2249229}],"tv":5.08}]}
{"op":"mcm","clk":"1004437518","pt":1580629828662,"mc":[{"id":"1.168135798","rc":[{"batb":[[0,3,8.26],[1,1.02,2780.78],[2,1.01,2791.57]],"ltp":0.0,"tv":0.0,"id":5720747}]}]}
{"op":"mcm","clk":"1004437580","pt":1580629829791,"mc":[{"id":"1.168135798","rc":[{"batb":[[0,1.44,850.92],[1,1.43,13.47],[2,1.36,800]],"ltp":1.43,"tv":5.08,"id":2249229}]}]}
{"op":"mcm","clk":"1004438521","pt":1580629849714,"mc":[{"id":"1.168135798","rc":[{"batb":[[0,1.45,2],[1,1.44,850.92],[2,1.43,13.47]],"ltp":1.43,"tv":5.08,"id":2249229},{"batb":[[0,3.05,2],[1,3,8.26],[2,1.02,2780.78]],"ltp":0.0,"tv":0.0,"id":5720747}]}]}
{"op":"mcm","clk":"1004438576","pt":1580629850691,"mc":[{"id":"1.168135798","rc":[{"batb":[[1,1.43,13.47],[2,1.36,800]],"ltp":1.43,"tv":5.08,"id":2249229}]}]}
{"op":"mcm","clk":"1004466098","pt":1580630449719,"mc":[{"id":"1.168135798","rc":[{"batb":[[0,1.44,850.92]],"ltp":1.43,"tv":5.08,"id":2249229},{"batb":[[0,3,8.26],[1,1.02,2780.78],[2,1.01,2791.57]],"ltp":0.0,"tv":0.0,"id":5720747}]}]}
{"op":"mcm","clk":"1004466735","pt":1580630462814,"mc":[{"id":"1.168135798","rc":[{"batb":[[0,1.45,2]],"ltp":1.43,"tv":5.08,"id":2249229},{"batb":[[0,3.05,2],[1,3,8.26],[2,1.02,2780.78]],"ltp":0.0,"tv":0.0,"id":5720747}]}]}
{"op":"mcm","clk":"1004493398","pt":1580631062746,"mc":[{"id":"1.168135798","rc":[{"batb":[[0,1.44,850.92]],"ltp":1.43,"tv":5.08,"id":2249229},{"batb":[[0,3,8.26],[1,1.02,2780.78],[2,1.01,2791.57]],"ltp":0.0,"tv":0.0,"id":5720747}]}]}
{"op":"mcm","clk":"1004494482","pt":1580631084743,"mc":[{"id":"1.168135798","rc":[{"batb":[[0,1.45,2]],"ltp":1.43,"tv":5.08,"id":2249229},{"batb":[[0,3.05,2],[1,3,8.26],[2,1.02,2780.78]],"ltp":0.0,"tv":0.0,"id":5720747}]}]}
{"op":"mcm","clk":"1004499154","pt":1580631191806,"mc":[{"id":"1.168135798","rc":[{"batb":[[0,1.46,814.38],[1,1.45,2],[2,1.43,13.47]],"ltp":1.43,"tv":5.08,"id":2249229}]}]}
{"op":"mcm","clk":"1004511339","pt":1580631482286,"mc":[{"id":"1.168135798","rc":[{"batb":[[0,1.46,26.38]],"ltp":1.43,"tv":5.08,"id":2249229}]}]}
{"op":"mcm","clk":"1004511693","pt":1580631490597,"mc":[{"id":"1.168135798","rc":[{"batb":[[0,1.46,703.88]],"ltp":1.43,"tv":5.08,"id":2249229}]}]}
{"op":"mcm","clk":"1004520523","pt":1580631684642,"mc":[{"id":"1.168135798","rc":[{"batb":[[1,1.43,13.47],[2,1.36,800]],"ltp":1.43,"tv":5.08,"id":2249229},{"batb":[[0,3,8.26],[1,1.02,2780.78],[2,1.01,2791.57]],"ltp":0.0,"tv":0.0,"id":5720747}]}]}
{"op":"mcm","clk":"1004543113","pt":1580632204517,"mc":[{"id":"1.168135798","rc":[{"batb":[[0,1.43,13.47],[1,1.36,800],[2,1.02,2780.76]],"ltp":1.43,"tv":5.08,"id":2249229}]}]}
{"op":"mcm","clk":"1004544170","pt":1580632227758,"mc":[{"id":"1.168135798","rc":[{"batb":[[0,1.44,2],[1,1.43,13.47],[2,1.36,800]],"ltp":1.43,"tv":5.08,"id":2249229},{"batb":[[0,3.05,2],[1,3,8.26],[2,1.02,2780.78]],"ltp":0.0,"tv":0.0,"id":5720747}]}]}
{"op":"mcm","clk":"1004546929","pt":1580632286339,"mc":[{"id":"1.168135798","rc":[{"batb":[[0,1.43,13.47],[1,1.36,800],[2,1.02,2780.76]],"ltp":1.43,"tv":5.08,"id":2249229},{"batb":[[0,3,8.26],[1,1.02,2780.78],[2,1.01,2791.57]],"ltp":0.0,"tv":0.0,"id":5720747}]}]}
{"op":"mcm","clk":"1004547332","pt":1580632294332,"mc":[{"id":"1.168135798","rc":[{"batb":[[0,1.44,1.75],[1,1.43,13.47],[2,1.36,800]],"ltp":1.43,"tv":5.08,"id":2249229},{"batb":[[0,3,9.08]],"ltp":0.0,"tv":0.0,"id":5720747}]}]}
{"op":"mcm","clk":"1004547385","pt":1580632295768,"mc":[{"id":"1.168135798","rc":[{"batb":[[0,1.44,3.75]],"ltp":1.43,"tv":5.08,"id":2249229},{"batb":[[0,3.05,2.82],[1,3,8.26],[2,1.02,2780.78]],"ltp":0.0,"tv":0.0,"id":5720747}]}]}
{"op":"mcm","clk":"1004550114","pt":1580632355520,"mc":[{"id":"1.168135798","rc":[{"batb":[[0,1.44,1.75]],"ltp":1.43,"tv":5.08,"id":2249229},{"batb":[[0,3,9.08],[1,1.02,2780.78],[2,1.01,2791.57]],"ltp":0.0,"tv":0.0,"id":5720747}]}]}
{"op":"mcm","clk":"1004550580","pt":1580632364434,"mc":[{"id":"1.168135798","rc":[{"batb":[[0,1.44,3.75]],"ltp":1.43,"tv":5.08,"id":2249229},{"batb":[[0,3.05,2.82],[1,3,8.26],[2,1.02,2780.78]],"ltp":0.0,"tv":0.0,"id":5720747}]}]}
{"op":"mcm","clk":"1004553357","pt":1580632423794,"mc":[{"id":"1.168135798","rc":[{"batb":[[0,1.44,1.75]],"ltp":1.43,"tv":5.08,"id":2249229},{"batb":[[0,3,9.08],[1,1.02,2780.78],[2,1.01,2791.57]],"ltp":0.0,"tv":0.0,"id":5720747}]}]}
{"op":"mcm","clk":"1004553758","pt":1580632432812,"mc":[{"id":"1.168135798","rc":[{"batb":[[0,1.44,3.75]],"ltp":1.43,"tv":5.08,"id":2249229},{"batb":[[0,3.05,2.82],[1,3,8.26],[2,1.02,2780.78]],"ltp":0.0,"tv":0.0,"id":5720747}]}]}
{"op":"mcm","clk":"1004556103","pt":1580632491492,"mc":[{"id":"1.168135798","rc":[{"batb":[[0,1.44,1.75]],"ltp":1.43,"tv":5.08,"id":2249229},{"batb":[[0,3,9.08],[1,1.02,2780.78],[2,1.01,2791.57]],"ltp":0.0,"tv":0.0,"id":5720747}]}]}
{"op":"mcm","clk":"1004556438","pt":1580632499619,"mc":[{"id":"1.168135798","rc":[{"batb":[[0,1.44,3.75]],"ltp":1.43,"tv":5.08,"id":2249229},{"batb":[[0,3.05,2.82],[1,3,8.26],[2,1.02,2780.78]],"ltp":0.0,"tv":0.0,"id":5720747}]}]}
{"op":"mcm","clk":"1004558905","pt":1580632558804,"mc":[{"id":"1.168135798","rc":[{"batb":[[0,1.44,1.75]],"ltp":1.43,"tv":5.08,"id":2249229},{"batb":[[0,3,9.08],[1,1.02,2780.78],[2,1.01,2791.57]],"ltp":0.0,"tv":0.0,"id":5720747}]}]}
{"op":"mcm","clk":"1004565524","pt":1580632723791,"mc":[{"id":"1.168135798","rc":[{"batl":[[0,1.5,50.65]],"ltp":1.43,"tv":5.08,"id":2249229}]}]}
{"op":"mcm","clk":"1004575383","pt":1580632930738,"mc":[{"id":"1.168135798","rc":[{"trd":[[1.43,27.99],[1.44,3.49]],"batb":[[0,1.36,800],[1,1.02,2780.76],[2,1.01,2791.57]],"batl":[[0,1.43,2.47],[1,1.5,50.65]],"ltp":1.43,"tv":35.5,"id":2249229}],"tv":35.5}]}
{"op":"mcm","clk":"1004586386","pt":1580633151547,"mc":[{"id":"1.168135798","marketDefinition":{"bspMarket":false,"turnInPlayEnabled":true,"persistenceEnabled":true,"marketBaseRate":5.0,"eventId":"29678823","eventTypeId":"2","numberOfWinners":1,"bettingType":"ODDS","marketType":"SET_WINNER","marketTime":"2020-02-02T08:30:00.000Z","suspendTime":"2020-02-02T08:30:00.000Z","bspReconciled":false,"complete":true,"inPlay":true,"crossMatching":true,"runnersVoidable":false,"numberOfActiveRunners":2,"betDelay":3,"status":"OPEN","runners":[{"status":"ACTIVE","sortPriority":1,"id":5720747,"name":"Dominic Thiem"},{"status":"ACTIVE","sortPriority":2,"id":2249229,"name":"Novak Djokovic"}],"regulators":["MR_INT"],"countryCode":"AU","discountAllowed":true,"timezone":"GMT","openDate":"2020-02-02T08:30:00.000Z","version":3148327191,"name":"Set 3 Winner","eventName":"Thiem v Djokovic"},"rc":[{"batb":[[0,1.02,2780.76],[1,1.01,2791.06],[2,1.01,0]],"ltp":1.43,"tv":35.5,"id":2249229},{"batb":[[0,1.02,2780.78],[1,1.01,2791.06],[2,1.01,0]],"ltp":0.0,"tv":0.0,"id":5720747}]}]}
{"op":"mcm","clk":"1004601200","pt":1580633480760,"mc":[{"id":"1.168135798","rc":[{"batb":[[0,1.36,34.83],[1,1.02,2780.76],[2,1.01,2791.06]],"ltp":1.43,"tv":35.5,"id":2249229}]}]}
{"op":"mcm","clk":"1004601456","pt":1580633486616,"mc":[{"id":"1.168135798","rc":[{"batb":[[0,1.68,39.38],[1,1.02,2780.78],[2,1.01,2791.06]],"ltp":0.0,"tv":0.0,"id":5720747}]}]}
{"op":"mcm","clk":"1004617593","pt":1580633840724,"mc":[{"id":"1.168135798","rc":[{"batb":[[0,1.22,34.83]],"ltp":1.43,"tv":35.5,"id":2249229}]}]}
{"op":"mcm","clk":"1004617759","pt":1580633843805,"mc":[{"id":"1.168135798","rc":[{"batb":[[0,1.3,34.83],[1,1.22,34.83],[2,1.02,2780.76]],"ltp":1.43,"tv":35.5,"id":2249229}]}]}
{"op":"mcm","clk":"1004619647","pt":1580633879738,"mc":[{"id":"1.168135798","rc":[{"batb":[[0,1.3,18.93]],"ltp":1.43,"tv":35.5,"id":2249229}]}]}
{"op":"mcm","clk":"1004629344","pt":1580634044671,"mc":[{"id":"1.168135798","rc":[{"batb":[[1,1.4,90.89],[2,1.02,2780.76]],"ltp":0.0,"tv":0.0,"id":5720747}]}]}
{"op":"mcm","clk":"1004704594","pt":1580635614718,"mc":[{"id":"1.168135798","rc":[{"batb":[[0,1.8,21.2],[1,1.68,39.38],[2,1.4,90.89]],"ltp":0.0,"tv":0.0,"id":5720747}]}]}
{"op":"mcm","clk":"1004721781","pt":1580636028724,"mc":[{"id":"1.168135798","rc":[{"batb":[[0,1.3,49.22]],"ltp":1.43,"tv":35.5,"id":2249229}]}]}
{"op":"mcm","clk":"1004728529","pt":1580636190486,"mc":[{"id":"1.168135798","rc":[{"batb":[[0,1.34,15.14],[1,1.3,41.65],[2,1.22,34.83]],"ltp":1.43,"tv":35.5,"id":2249229}]}]}
{"op":"mcm","clk":"1004734192","pt":1580636328632,"mc":[{"id":"1.168135798","rc":[{"batb":[[2,1.23,516.48]],"ltp":1.43,"tv":35.5,"id":2249229},{"batb":[[0,2.38,382.3],[1,1.8,21.2],[2,1.68,39.38]],"ltp":0.0,"tv":0.0,"id":5720747}]}]}
{"op":"mcm","clk":"1004734480","pt":1580636333747,"mc":[{"id":"1.168135798","rc":[{"batl":[[0,1000,3.04]],"ltp":1.43,"tv":35.5,"id":2249229}]}]}
{"op":"mcm","clk":"1004734680","pt":1580636337734,"mc":[{"id":"1.168135798","rc":[{"trd":[[1.34,0.03]],"batb":[[0,1.34,15.13]],"ltp":1.34,"tv":35.53,"id":2249229}],"tv":35.53}]}
{"op":"mcm","clk":"1004735047","pt":1580636345736,"mc":[{"id":"1.168135798","rc":[{"batb":[[0,1.34,15.14]],"ltp":1.34,"tv":35.53,"id":2249229}]}]}
{"op":"mcm","clk":"1004735149","pt":1580636347750,"mc":[{"id":"1.168135798","rc":[{"batl":[[0,1.7,18.17]],"ltp":1.34,"tv":35.53,"id":2249229}]}]}
{"op":"mcm","clk":"1004740211","pt":1580636452413,"mc":[{"id":"1.168135798","rc":[{"batb":[[0,1.3,41.66],[1,1.23,516.48],[2,1.22,34.83]],"ltp":1.34,"tv":35.53,"id":2249229}]}]}
{"op":"mcm","clk":"1004741074","pt":1580636467771,"mc":[{"id":"1.168135798","rc":[{"batl":[[0,1.7,18.19]],"ltp":1.34,"tv":35.53,"id":2249229}]}]}
{"op":"mcm","clk":"1004743571","pt":1580636510742,"mc":[{"id":"1.168135798","rc":[{"batb":[[2,1.05,16.8]],"ltp":1.34,"tv":35.53,"id":2249229}]}]}
{"op":"mcm","clk":"1004743761","pt":1580636513571,"mc":[{"id":"1.168135798","rc":[{"batb":[[1,1.24,34.83],[2,1.23,516.48]],"ltp":1.34,"tv":35.53,"id":2249229}]}]}
{"op":"mcm","clk":"1004744564","pt":1580636526762,"mc":[{"id":"1.168135798","rc":[{"batb":[[0,1.3,31.82]],"ltp":1.34,"tv":35.53,"id":2249229}]}]}
{"op":"mcm","clk":"1004748946","pt":1580636606685,"mc":[{"id":"1.168135798","rc":[{"batb":[[0,1.3,24.25]],"ltp":1.34,"tv":35.53,"id":2249229}]}]}
{"op":"mcm","clk":"1004750932","pt":1580636654585,"mc":[{"id":"1.168135798","rc":[{"batl":[[0,1.5,1135.86],[1,1.7,18.17]],"ltp":1.34,"tv":35.53,"id":2249229}]}]}
{"op":"mcm","clk":"1004754701","pt":1580636736640,"mc":[{"id":"1.168135798","rc":[{"batb":[[2,1.05,16.8]],"ltp":1.34,"tv":35.53,"id":2249229}]}]}
{"op":"mcm","clk":"1004754899","pt":1580636740752,"mc":[{"id":"1.168135798","rc":[{"batb":[[1,1.25,505.09],[2,1.24,34.83]],"ltp":1.34,"tv":35.53,"id":2249229}]}]}
{"op":"mcm","clk":"1004755561","pt":1580636756470,"mc":[{"id":"1.168135798","rc":[{"batb":[[2,1.05,16.8]],"ltp":1.34,"tv":35.53,"id":2249229}]}]}
{"op":"mcm","clk":"1004755723","pt":1580636759788,"mc":[{"id":"1.168135798","rc":[{"batb":[[1,1.26,34.83],[2,1.25,505.09]],"ltp":1.34,"tv":35.53,"id":2249229}]}]}
{"op":"mcm","clk":"1004755857","pt":1580636762777,"mc":[{"id":"1.168135798","rc":[{"batl":[[0,1.5,1135.85]],"ltp":1.34,"tv":35.53,"id":2249229}]}]}
{"op":"mcm","clk":"1004756018","pt":1580636766795,"mc":[{"id":"1.168135798","rc":[{"batl":[[0,1.5,1135.86]],"ltp":1.34,"tv":35.53,"id":2249229}]}]}
{"op":"mcm","clk":"1004759402","pt":1580636844647,"mc":[{"id":"1.168135798","rc":[{"batb":[[2,1.05,16.8]],"ltp":1.34,"tv":35.53,"id":2249229}]}]}
{"op":"mcm","clk":"1004759636","pt":1580636848739,"mc":[{"id":"1.168135798","rc":[{"batb":[[1,1.28,485.89],[2,1.26,34.83]],"ltp":1.34,"tv":35.53,"id":2249229}]}]}
{"op":"mcm","clk":"1004767145","pt":1580636987783,"mc":[{"id":"1.168135798","rc":[{"batb":[[1,1.26,34.83],[2,1.05,16.8]],"ltp":1.34,"tv":35.53,"id":2249229},{"batb":[[0,1.8,21.2],[1,1.68,39.38],[2,1.4,90.89]],"ltp":0.0,"tv":0.0,"id":5720747}]}]}
{"op":"mcm","clk":"1004767827","pt":1580636999776,"mc":[{"id":"1.168135798","rc":[{"batb":[[1,1.28,485.89],[2,1.26,34.83]],"ltp":1.34,"tv":35.53,"id":2249229},{"batb":[[0,2.22,384.52],[1,1.8,21.2],[2,1.68,39.38]],"ltp":0.0,"tv":0.0,"id":5720747}]}]}
{"op":"mcm","clk":"1004768588","pt":1580637011796,"mc":[{"id":"1.168135798","rc":[{"batl":[[2,1.78,24.23]],"ltp":1.34,"tv":35.53,"id":2249229}]}]}
{"op":"mcm","clk":"1004771646","pt":1580637066811,"mc":[{"id":"1.168135798","rc":[{"batb":[[0,1.31,12.13],[1,1.3,24.23],[2,1.28,485.89]],"ltp":1.34,"tv":35.53,"id":2249229}]}]}
{"op":"mcm","clk":"1004773370","pt":1580637103761,"mc":[{"id":"1.168135798","rc":[{"batb":[[2,1.26,34.83]],"ltp":1.34,"tv":35.53,"id":2249229}]}]}
{"op":"mcm","clk":"1004773629","pt":1580637108753,"mc":[{"id":"1.168135798","rc":[{"batb":[[0,1.31,489.64]],"ltp":1.34,"tv":35.53,"id":2249229}]}]}
{"op":"mcm","clk":"1004776329","pt":1580637153775,"mc":[{"id":"1.168135798","rc":[{"batb":[[0,1.33,18.95],[1,1.31,489.62],[2,1.3,24.23]],"ltp":1.34,"tv":35.53,"id":2249229}]}]}
{"op":"mcm","clk":"1004780098","pt":1580637228791,"mc":[{"id":"1.168135798","rc":[{"batl":[[0,3.3,29.97]],"ltp":0.0,"tv":0.0,"id":5720747}]}]}
{"op":"mcm","clk":"1004784546","pt":1580637318742,"mc":[{"id":"1.168135798","rc":[{"batb":[[1,1.31,12.12]],"batl":[[0,1.7,18.19],[1,1.78,24.23],[2,1.78,0]],"ltp":1.34,"tv":35.53,"id":2249229}]}]}
{"op":"mcm","clk":"1004784718","pt":1580637322541,"mc":[{"id":"1.168135798","rc":[{"batb":[[0,1.34,265],[1,1.33,18.93],[2,1.31,12.12]],"ltp":1.34,"tv":35.53,"id":2249229}]}]}
{"op":"mcm","clk":"1004785067","pt":1580637329785,"mc":[{"id":"1.168135798","rc":[{"batb":[[0,1.35,18.17],[1,1.34,265],[2,1.33,18.93]],"ltp":1.34,"tv":35.53,"id":2249229}]}]}
{"op":"mcm","clk":"1004785143","pt":1580637331748,"mc":[{"id":"1.168135798","rc":[{"batl":[[0,1.66,1514.48],[1,1.7,18.17],[2,1.78,24.23]],"ltp":1.34,"tv":35.53,"id":2249229}]}]}
{"op":"mcm","clk":"1004785883","pt":1580637348799,"mc":[{"id":"1.168135798","rc":[{"batb":[[0,1.4,227.17],[1,1.35,18.17],[2,1.34,265]],"ltp":1.34,"tv":35.53,"id":2249229}]}]}
{"op":"mcm","clk":"1004794449","pt":1580637489793,"mc":[{"id":"1.168135798","rc":[{"batb":[[2,1.33,18.95]],"ltp":1.34,"tv":35.53,"id":2249229},{"batb":[[0,1.8,21.2],[1,1.68,39.38],[2,1.4,90.89]],"ltp":0.0,"tv":0.0,"id":5720747}]}]}
{"op":"mcm","clk":"1004795914","pt":1580637517758,"mc":[{"id":"1.168135798","rc":[{"batb":[[2,1.34,278.82]],"ltp":1.34,"tv":35.53,"id":2249229},{"batb":[[0,2.04,656.02],[1,1.8,21.2],[2,1.68,39.38]],"ltp":0.0,"tv":0.0,"id":5720747}]}]}
{"op":"mcm","clk":"1004799079","pt":1580637572627,"mc":[{"id":"1.168135798","rc":[{"batb":[[2,1.33,18.95]],"ltp":1.34,"tv":35.53,"id":2249229},{"batb":[[0,1.8,21.2],[1,1.68,39.38],[2,1.4,90.89]],"ltp":0.0,"tv":0.0,"id":5720747}]}]}
{"op":"mcm","clk":"1004800120","pt":1580637589594,"mc":[{"id":"1.168135798","rc":[{"batb":[[2,1.34,278.61]],"ltp":1.34,"tv":35.53,"id":2249229},{"batb":[[0,2.04,655.87],[1,1.8,21.2],[2,1.68,39.38]],"ltp":0.0,"tv":0.0,"id":5720747}]}]}
{"op":"mcm","clk":"1004800730","pt":1580637599763,"mc":[{"id":"1.168135798","rc":[{"batl":[[0,1.66,1514.46]],"ltp":1.34,"tv":35.53,"id":2249229}]}]}
{"op":"mcm","clk":"1004800963","pt":1580637601798,"mc":[{"id":"1.168135798","rc":[{"batl":[[1,1.7,15.14]],"ltp":1.34,"tv":35.53,"id":2249229}]}]}
{"op":"mcm","clk":"1004801077","pt":1580637602802,"mc":[{"id":"1.168135798","rc":[{"batl":[[0,1.66,1514.48]],"ltp":1.34,"tv":35.53,"id":2249229}]}]}
{"op":"mcm","clk":"1004801311","pt":1580637605206,"mc":[{"id":"1.168135798","rc":[{"batl":[[1,1.78,24.23],[2,1.78,0]],"ltp":1.34,"tv":35.53,"id":2249229}]}]}
{"op":"mcm","clk":"1004801607","pt":1580637608697,"mc":[{"id":"1.168135798","rc":[{"batl":[[0,1.64,15.16],[1,1.66,1514.46],[2,1.78,24.23]],"ltp":1.34,"tv":35.53,"id":2249229}]}]}
{"op":"mcm","clk":"1004805540","pt":1580637664307,"mc":[{"id":"1.168135798","rc":[{"trd":[[1.4,0.03]],"batb":[[0,1.4,227.15]],"ltp":1.4,"tv":35.56,"id":2249229}],"tv":35.56}]}
{"op":"mcm","clk":"1004806574","pt":1580637678544,"mc":[{"id":"1.168135798","rc":[{"batb":[[0,1.4,227.17]],"ltp":1.4,"tv":35.56,"id":2249229}]}]}
{"op":"mcm","clk":"1004829493","pt":1580638012745,"mc":[{"id":"1.168135798","rc":[{"batb":[[0,1.35,18.19],[1,1.34,278.61],[2,1.33,18.93]],"batl":[[1,1.78,24.23],[2,1.78,0]],"ltp":1.4,"tv":35.56,"id":2249229}]}]}
{"op":"mcm","clk":"1004830686","pt":1580638031791,"mc":[{"id":"1.168135798","rc":[{"batb":[[0,1.8,21.2],[1,1.68,39.38],[2,1.4,90.89]],"ltp":0.0,"tv":0.0,"id":5720747}]}]}
{"op":"mcm","clk":"1004830958","pt":1580638035746,"mc":[{"id":"1.168135798","rc":[{"batb":[[0,2.12,205.29],[1,1.8,21.2],[2,1.68,39.38]],"ltp":0.0,"tv":0.0,"id":5720747}]}]}
{"op":"mcm","clk":"1004831896","pt":1580638048597,"mc":[{"id":"1.168135798","rc":[{"batl":[[0,1.78,24.25],[1,1.78,0]],"ltp":1.4,"tv":35.56,"id":2249229}]}]}
{"op":"mcm","clk":"1004832093","pt":1580638051788,"mc":[{"id":"1.168135798","rc":[{"batl":[[0,1.69,15.16],[1,1.78,24.23]],"ltp":1.4,"tv":35.56,"id":2249229}]}]}
{"op":"mcm","clk":"1004835678","pt":1580638106757,"mc":[{"id":"1.168135798","rc":[{"batb":[[0,2.16,19.69],[1,2.12,205.29],[2,1.8,21.2]],"ltp":0.0,"tv":0.0,"id":5720747}]}]}
{"op":"mcm","clk":"1004835741","pt":1580638107797,"mc":[{"id":"1.168135798","rc":[{"batl":[[0,1.78,24.25],[1,1.78,0]],"ltp":1.4,"tv":35.56,"id":2249229}]}]}
{"op":"mcm","clk":"1004855549","pt":1580638377436,"mc":[{"id":"1.168135798","rc":[{"trd":[[1.35,9.96],[1.4,0.07]],"batb":[[0,1.35,13.19]],"ltp":1.35,"tv":45.56,"id":2249229}],"tv":45.56}]}
{"op":"mcm","clk":"1004856811","pt":1580638393765,"mc":[{"id":"1.168135798","rc":[{"batl":[[0,1.55,4.18],[1,1.78,24.23]],"ltp":1.35,"tv":45.56,"id":2249229}]}]}
{"op":"mcm","clk":"1004859143","pt":1580638426124,"mc":[{"id":"1.168135798","rc":[{"batl":[[1,1.78,19.69]],"ltp":1.35,"tv":45.56,"id":2249229}]}]}
{"op":"mcm","clk":"1004863922","pt":1580638482695,"mc":[{"id":"1.168135798","rc":[{"batb":[[1,1.33,18.95],[2,1.31,12.12]],"ltp":1.35,"tv":45.56,"id":2249229},{"batb":[[1,1.8,21.2],[2,1.68,39.38]],"ltp":0.0,"tv":0.0,"id":5720747}]}]}
{"op":"mcm","clk":"1004865201","pt":1580638496595,"mc":[{"id":"1.168135798","rc":[{"batb":[[2,1.31,313.21]],"ltp":1.35,"tv":45.56,"id":2249229},{"batb":[[1,2.12,648.87],[2,1.8,21.2]],"ltp":0.0,"tv":0.0,"id":5720747}]}]}
{"op":"mcm","clk":"1004866793","pt":1580638514624,"mc":[{"id":"1.168135798","rc":[{"batb":[[1,1.31,313.22],[2,1.3,24.23]],"ltp":1.35,"tv":45.56,"id":2249229}]}]}
{"op":"mcm","clk":"1004875385","pt":1580638626754,"mc":[{"id":"1.168135798","rc":[{"batb":[[1,1.8,21.2],[2,1.68,39.38]],"ltp":0.0,"tv":0.0,"id":5720747}]}]}
{"op":"mcm","clk":"1004875831","pt":1580638631770,"mc":[{"id":"1.168135798","rc":[{"batb":[[1,2.12,205.29],[2,1.8,21.2]],"ltp":0.0,"tv":0.0,"id":5720747}]}]}
{"op":"mcm","clk":"1004877798","pt":1580638657792,"mc":[{"id":"1.168135798","rc":[{"batb":[[0,1.31,313.22],[1,1.3,24.23],[2,1.26,34.83]],"ltp":1.35,"tv":45.56,"id":2249229}]}]}
{"op":"mcm","clk":"1004878081","pt":1580638661710,"mc":[{"id":"1.168135798","rc":[{"batb":[[0,1.33,13.21],[1,1.31,313.21],[2,1.3,24.23]],"ltp":1.35,"tv":45.56,"id":2249229}]}]}
{"op":"mcm","clk":"1004878734","pt":1580638671708,"mc":[{"id":"1.168135798","rc":[{"batb":[[1,1.31,12.12]],"ltp":1.35,"tv":45.56,"id":2249229}]}]}
{"op":"mcm","clk":"1004879211","pt":1580638678717,"mc":[{"id":"1.168135798","rc":[{"batb":[[0,1.31,12.13],[1,1.3,24.23],[2,1.26,34.83]],"ltp":1.35,"tv":45.56,"id":2249229}]}]}
{"op":"mcm","clk":"1004892981","pt":1580638846734,"mc":[{"id":"1.168135798","rc":[{"batb":[[0,3,8.4],[1,2.16,19.69],[2,2.12,205.29]],"ltp":0.0,"tv":0.0,"id":5720747}]}]}
{"op":"mcm","clk":"1004894228","pt":1580638860746,"mc":[{"id":"1.168135798","rc":[{"batl":[[0,1.78,19.7],[1,1.78,0]],"ltp":1.35,"tv":45.56,"id":2249229}]}]}
{"op":"mcm","clk":"1004894512","pt":1580638863745,"mc":[{"id":"1.168135798","rc":[{"batl":[[0,1.49,4.16],[1,1.78,19.7]],"ltp":1.35,"tv":45.56,"id":2249229}]}]}
{"op":"mcm","clk":"1004903239","pt":1580638967666,"mc":[{"id":"1.168135798","rc":[{"batb":[[2,1.8,21.2]],"ltp":0.0,"tv":0.0,"id":5720747}]}]}
{"op":"mcm","clk":"1004903897","pt":1580638975795,"mc":[{"id":"1.168135798","rc":[{"batb":[[2,2.12,327.42]],"ltp":0.0,"tv":0.0,"id":5720747}]}]}
{"op":"mcm","clk":"1004905253","pt":1580638991762,"mc":[{"id":"1.168135798","rc":[{"trd":[[1.49,4.17]],"batl":[[0,1.78,19.7],[1,1.78,0]],"ltp":1.49,"tv":49.73,"id":2249229},{"trd":[[3,18.87]],"batb":[[0,2.16,19.69],[1,2.12,327.42],[2,1.8,21.2]],"ltp":3.0,"tv":18.87,"id":5720747}],"tv":68.6}]}
{"op":"mcm","clk":"1004906986","pt":1580639004781,"mc":[{"id":"1.168135798","rc":[{"batb":[[0,1.34,13.65],[1,1.31,12.12],[2,1.3,24.23]],"ltp":1.49,"tv":49.73,"id":2249229}]}]}
{"op":"mcm","clk":"1004908401","pt":1580639016547,"mc":[{"id":"1.168135798","rc":[{"batb":[[0,2.5,13.44],[1,2.16,19.69],[2,2.12,327.42]],"ltp":3.0,"tv":18.87,"id":5720747}]}]}
{"op":"mcm","clk":"1004910536","pt":1580639034579,"mc":[{"id":"1.168135798","rc":[{"batb":[[1,1.31,35.17]],"ltp":1.49,"tv":49.73,"id":2249229}]}]}
{"op":"mcm","clk":"1004911643","pt":1580639043808,"mc":[{"id":"1.168135798","rc":[{"batl":[[0,1.65,12.13],[1,1.78,19.69]],"ltp":1.49,"tv":49.73,"id":2249229}]}]}
{"op":"mcm","clk":"1004914605","pt":1580639073817,"mc":[{"id":"1.168135798","rc":[{"batb":[[1,1.31,12.12]],"ltp":1.49,"tv":49.73,"id":2249229},{"batl":[[0,3.35,7.56]],"ltp":3.0,"tv":18.87,"id":5720747}]}]}
{"op":"mcm","clk":"1004915200","pt":1580639079768,"mc":[{"id":"1.168135798","rc":[{"batb":[[1,1.31,35.17]],"ltp":1.49,"tv":49.73,"id":2249229}]}]}
{"op":"mcm","clk":"1004915568","pt":1580639083752,"mc":[{"id":"1.168135798","rc":[{"batb":[[1,1.31,12.12]],"ltp":1.49,"tv":49.73,"id":2249229}]}]}
{"op":"mcm","clk":"1004915650","pt":1580639084740,"mc":[{"id":"1.168135798","rc":[{"batb":[[0,2.16,19.69],[1,2.12,327.42],[2,1.8,21.2]],"ltp":3.0,"tv":18.87,"id":5720747}]}]}
{"op":"mcm","clk":"1004915910","pt":1580639087637,"mc":[{"id":"1.168135798","rc":[{"batb":[[0,2.62,13.44],[1,2.16,19.69],[2,2.12,327.42]],"ltp":3.0,"tv":18.87,"id":5720747}]}]}
{"op":"mcm","clk":"1004918122","pt":1580639110691,"mc":[{"id":"1.168135798","rc":[{"batb":[[0,1.34,50.74]],"ltp":1.49,"tv":49.73,"id":2249229}]}]}
{"op":"mcm","clk":"1004920489","pt":1580639134728,"mc":[{"id":"1.168135798","rc":[{"batb":[[0,1.34,13.65]],"ltp":1.49,"tv":49.73,"id":2249229}]}]}
{"op":"mcm","clk":"1004920722","pt":1580639136811,"mc":[{"id":"1.168135798","rc":[{"batb":[[0,2.16,19.69],[1,2.12,327.42],[2,1.8,21.2]],"ltp":3.0,"tv":18.87,"id":5720747}]}]}
{"op":"mcm","clk":"1004921142","pt":1580639140632,"mc":[{"id":"1.168135798","rc":[{"batb":[[0,2.64,13.44],[1,2.16,19.69],[2,2.12,327.42]],"batl":[[0,3.3,7.56]],"ltp":3.0,"tv":18.87,"id":5720747}]}]}
{"op":"mcm","clk":"1004921270","pt":1580639141736,"mc":[{"id":"1.168135798","rc":[{"batb":[[2,1.8,21.2]],"ltp":3.0,"tv":18.87,"id":5720747}]}]}
{"op":"mcm","clk":"1004923067","pt":1580639159666,"mc":[{"id":"1.168135798","rc":[{"batb":[[2,2.04,368.81]],"ltp":3.0,"tv":18.87,"id":5720747}]}]}
{"op":"mcm","clk":"1004923173","pt":1580639160739,"mc":[{"id":"1.168135798","rc":[{"batb":[[0,1.34,57.53]],"ltp":1.49,"tv":49.73,"id":2249229}]}]}
{"op":"mcm","clk":"1004924307","pt":1580639170736,"mc":[{"id":"1.168135798","rc":[{"batb":[[0,1.34,13.65]],"ltp":1.49,"tv":49.73,"id":2249229}]}]}
{"op":"mcm","clk":"1004926207","pt":1580639188471,"mc":[{"id":"1.168135798","rc":[{"batb":[[0,1.34,58.34]],"ltp":1.49,"tv":49.73,"id":2249229}]}]}
{"op":"mcm","clk":"1004927132","pt":1580639196783,"mc":[{"id":"1.168135798","rc":[{"batl":[[0,1.78,19.7],[1,1.78,0]],"ltp":1.49,"tv":49.73,"id":2249229}]}]}
{"op":"mcm","clk":"1004928732","pt":1580639211691,"mc":[{"id":"1.168135798","rc":[{"batb":[[0,1.34,13.65]],"ltp":1.49,"tv":49.73,"id":2249229}]}]}
{"op":"mcm","clk":"1004929462","pt":1580639217614,"mc":[{"id":"1.168135798","rc":[{"batb":[[0,1.34,57.66]],"ltp":1.49,"tv":49.73,"id":2249229}]}]}
{"op":"mcm","clk":"1004929915","pt":1580639221803,"mc":[{"id":"1.168135798","rc":[{"batb":[[0,1.34,13.65]],"ltp":1.49,"tv":49.73,"id":2249229}]}]}
{"op":"mcm","clk":"1004930991","pt":1580639230629,"mc":[{"id":"1.168135798","rc":[{"batb":[[0,1.34,60.23]],"ltp":1.49,"tv":49.73,"id":2249229}]}]}
{"op":"mcm","clk":"1004932188","pt":1580639240559,"mc":[{"id":"1.168135798","rc":[{"batb":[[0,1.45,3.79],[1,1.34,60.23],[2,1.31,12.12]],"ltp":1.49,"tv":49.73,"id":2249229}]}]}
{"op":"mcm","clk":"1004933486","pt":1580639250732,"mc":[{"id":"1.168135798","rc":[{"batb":[[1,1.34,13.65]],"ltp":1.49,"tv":49.73,"id":2249229}]}]}
{"op":"mcm","clk":"1004934186","pt":1580639257732,"mc":[{"id":"1.168135798","rc":[{"batb":[[1,1.34,58.96]],"ltp":1.49,"tv":49.73,"id":2249229}]}]}
{"op":"mcm","clk":"1004934604","pt":1580639261774,"mc":[{"id":"1.168135798","rc":[{"batb":[[1,1.34,13.65]],"ltp":1.49,"tv":49.73,"id":2249229}]}]}
{"op":"mcm","clk":"1004935492","pt":1580639270760,"mc":[{"id":"1.168135798","rc":[{"batb":[[0,1.51,528.51],[1,1.5,523.35],[2,1.45,3.79]],"batl":[[0,1.56,592.41],[1,1.57,431.99],[2,1.78,19.69]],"ltp":1.49,"tv":49.73,"id":2249229}]}]}
{"op":"mcm","clk":"1004938336","pt":1580639298714,"mc":[{"id":"1.168135798","rc":[{"batb":[[0,2.16,19.69],[1,2.04,368.81],[2,1.8,21.2]],"ltp":3.0,"tv":18.87,"id":5720747}]}]}
{"op":"mcm","clk":"1004939764","pt":1580639312757,"mc":[{"id":"1.168135798","rc":[{"batb":[[0,2.82,8.4],[1,2.16,19.69],[2,2.04,368.81]],"ltp":3.0,"tv":18.87,"id":5720747}]}]}
{"op":"mcm","clk":"1004943343","pt":1580639348496,"mc":[{"id":"1.168135798","rc":[{"batb":[[0,1.45,3.79],[1,1.34,13.65],[2,1.31,12.12]],"batl":[[0,1.78,19.7],[1,1.57,0],[2,1.78,0]],"ltp":1.49,"tv":49.73,"id":2249229}]}]}
{"op":"mcm","clk":"1004943709","pt":1580639351815,"mc":[{"id":"1.168135798","rc":[{"batb":[[0,1.46,412.99],[1,1.45,605.42],[2,1.34,13.65]],"batl":[[0,1.69,586.72],[1,1.71,642.63],[2,1.78,19.69]],"ltp":1.49,"tv":49.73,"id":2249229}]}]}
{"op":"mcm","clk":"1004944152","pt":1580639356701,"mc":[{"id":"1.168135798","rc":[{"batb":[[1,1.45,601.63]],"ltp":1.49,"tv":49.73,"id":2249229}]}]}
{"op":"mcm","clk":"1004944469","pt":1580639359811,"mc":[{"id":"1.168135798","rc":[{"trd":[[1.55,3.8]],"batl":[[0,1.69,586.7]],"ltp":1.55,"tv":53.53,"id":2249229},{"trd":[[2.82,2.08]],"batb":[[0,2.82,6.33]],"ltp":2.82,"tv":20.94,"id":5720747}],"tv":74.47}]}
{"op":"mcm","clk":"1004944957","pt":1580639364601,"mc":[{"id":"1.168135798","rc":[{"trd":[[1.46,150]],"batb":[[0,1.46,337.99]],"ltp":1.46,"tv":203.53,"id":2249229}],"tv":224.47}]}
{"op":"mcm","clk":"1004945141","pt":1580639366641,"mc":[{"id":"1.168135798","rc":[{"batb":[[0,1.45,601.63],[1,1.34,13.65],[2,1.31,12.12]],"ltp":1.46,"tv":203.53,"id":2249229}]}]}
{"op":"mcm","clk":"1004945422","pt":1580639369747,"mc":[{"id":"1.168135798","rc":[{"batb":[[0,1.49,16.97],[1,1.45,601.63],[2,1.34,13.65]],"ltp":1.46,"tv":203.53,"id":2249229}]}]}
{"op":"mcm","clk":"1004945659","pt":1580639371815,"mc":[{"id":"1.168135798","rc":[{"batb":[[1,1.45,994.14],[2,1.44,624.71]],"ltp":1.46,"tv":203.53,"id":2249229}]}]}
{"op":"mcm","clk":"1004946073","pt":1580639375752,"mc":[{"id":"1.168135798","rc":[{"trd":[[2.82,14.72]],"batb":[[0,2.16,19.69],[1,2.04,368.81],[2,1.8,21.2]],"batl":[[0,2.82,11.36]],"ltp":2.82,"tv":33.59,"id":5720747}],"tv":237.12}]}
{"op":"mcm","clk":"1004946162","pt":1580639376652,"mc":[{"id":"1.168135798","rc":[{"trd":[[1.54,20.81]],"batl":[[0,1.54,1.91],[1,1.69,586.7],[2,1.71,642.63]],"ltp":1.54,"tv":224.34,"id":2249229},{"trd":[[2.82,26.08]],"ltp":2.82,"tv":44.95,"id":5720747}],"tv":269.29}]}
{"op":"mcm","clk":"1004946578","pt":1580639380749,"mc":[{"id":"1.168135798","rc":[{"batl":[[0,3,36.21]],"ltp":2.82,"tv":44.95,"id":5720747}]}]}
{"op":"mcm","clk":"1004946992","pt":1580639384652,"mc":[{"id":"1.168135798","rc":[{"batb":[[0,1.45,994.14],[1,1.44,624.71],[2,1.34,13.65]],"ltp":1.54,"tv":224.34,"id":2249229}]}]}
{"op":"mcm","clk":"1004947096","pt":1580639385758,"mc":[{"id":"1.168135798","rc":[{"batb":[[0,1.45,601.66],[1,1.34,13.65],[2,1.31,12.12]],"ltp":1.54,"tv":224.34,"id":2249229}]}]}
{"op":"mcm","clk":"1004947389","pt":1580639388748,"mc":[{"id":"1.168135798","rc":[{"batb":[[0,2.46,119.75],[1,2.16,19.69],[2,2.04,368.81]],"ltp":2.82,"tv":44.95,"id":5720747}]}]}
{"op":"mcm","clk":"1004947467","pt":1580639389640,"mc":[{"id":"1.168135798","rc":[{"trd":[[1.5,72.41]],"batb":[[0,1.46,190.03],[1,1.45,601.66],[2,1.34,13.65]],"batl":[[0,1.5,11.7],[1,1.54,1.91],[2,1.69,586.7]],"ltp":1.5,"tv":296.74,"id":2249229},{"trd":[[3,55.08]],"ltp":3.0,"tv":81.15,"id":5720747}],"tv":377.9}]}
{"op":"mcm","clk":"1004947584","pt":1580639390741,"mc":[{"id":"1.168135798","rc":[{"batb":[[0,1.46,586.92]],"batl":[[0,1.5,211.7]],"ltp":1.5,"tv":296.74,"id":2249229}]}]}
{"op":"mcm","clk":"1004947837","pt":1580639393666,"mc":[{"id":"1.168135798","rc":[{"batb":[[0,1.46,966.99]],"ltp":1.5,"tv":296.74,"id":2249229}]}]}
{"op":"mcm","clk":"1004948665","pt":1580639401761,"mc":[{"id":"1.168135798","rc":[{"batl":[[0,1.5,287.43]],"ltp":1.5,"tv":296.74,"id":2249229}]}]}
{"op":"mcm","clk":"1004949302","pt":1580639406769,"mc":[{"id":"1.168135798","rc":[{"trd":[[1.5,137.44]],"batl":[[0,1.5,254.91]],"ltp":1.5,"tv":361.77,"id":2249229}],"tv":442.93}]}
{"op":"mcm","clk":"1004949509","pt":1580639408789,"mc":[{"id":"1.168135798","rc":[{"trd":[[1.5,271.87]],"batl":[[0,1.5,187.69]],"ltp":1.5,"tv":496.21,"id":2249229}],"tv":577.37}]}
{"op":"mcm","clk":"1004949624","pt":1580639409791,"mc":[{"id":"1.168135798","rc":[{"batl":[[0,1.5,111.97]],"ltp":1.5,"tv":496.21,"id":2249229}]}]}
{"op":"mcm","clk":"1004949965","pt":1580639412793,"mc":[{"id":"1.168135798","rc":[{"trd":[[1.46,301.45]],"batb":[[0,1.46,891.26]],"ltp":1.46,"tv":647.66,"id":2249229}],"tv":728.82}]}
{"op":"mcm","clk":"1004950798","pt":1580639420690,"mc":[{"id":"1.168135798","rc":[{"batb":[[0,3.05,36.25],[1,2.46,119.75],[2,2.16,19.69]],"ltp":3.0,"tv":81.15,"id":5720747}]}]}
{"op":"mcm","clk":"1004951015","pt":1580639422784,"mc":[{"id":"1.168135798","rc":[{"trd":[[1.49,71.39]],"ltp":1.49,"tv":714.88,"id":2249229},{"trd":[[3.05,32.84]],"batb":[[0,3.05,3.41]],"ltp":3.05,"tv":113.99,"id":5720747}],"tv":828.87}]}
{"op":"mcm","clk":"1004951934","pt":1580639432804,"mc":[{"id":"1.168135798","rc":[{"trd":[[1.49,76.43]],"ltp":1.49,"tv":719.92,"id":2249229},{"trd":[[3.05,35.3]],"batb":[[0,2.46,120.7],[1,2.16,19.69],[2,2.04,368.81]],"ltp":3.05,"tv":116.45,"id":5720747}],"tv":836.38}]}
{"op":"mcm","clk":"1004952034","pt":1580639433792,"mc":[{"id":"1.168135798","rc":[{"batb":[[0,1.47,831.79],[1,1.46,891.26],[2,1.45,601.66]],"ltp":1.49,"tv":719.92,"id":2249229}]}]}
{"op":"mcm","clk":"1004952674","pt":1580639440817,"mc":[{"id":"1.168135798","rc":[{"batb":[[0,1.48,364.23],[1,1.47,831.79],[2,1.46,891.26]],"ltp":1.49,"tv":719.92,"id":2249229}]}]}
{"op":"mcm","clk":"1004953879","pt":1580639452746,"mc":[{"id":"1.168135798","rc":[{"trd":[[1.5,274.75]],"batl":[[0,1.5,109.09]],"ltp":1.5,"tv":722.8,"id":2249229},{"trd":[[3,56.52],[3.05,37.2]],"batb":[[0,2.46,119.75]],"ltp":3.0,"tv":119.79,"id":5720747}],"tv":842.6}]}
{"op":"mcm","clk":"1004953979","pt":1580639453744,"mc":[{"id":"1.168135798","rc":[{"batl":[[0,1.54,1.91],[1,1.69,586.7],[2,1.71,642.63]],"ltp":1.5,"tv":722.8,"id":2249229}]}]}
{"op":"mcm","clk":"1004954398","pt":1580639457723,"mc":[{"id":"1.168135798","rc":[{"trd":[[1.48,218.21]],"batb":[[0,1.48,255.13]],"ltp":1.48,"tv":940.98,"id":2249229}],"tv":1060.78}]}
{"op":"mcm","clk":"1004954486","pt":1580639458658,"mc":[{"id":"1.168135798","rc":[{"batb":[[2,1.46,396.89]],"ltp":1.48,"tv":940.98,"id":2249229}]}]}
{"op":"mcm","clk":"1004955050","pt":1580639463548,"mc":[{"id":"1.168135798","rc":[{"batb":[[0,3,53.82],[1,2.46,119.75],[2,2.16,19.69]],"ltp":3.0,"tv":119.79,"id":5720747}]}]}
{"op":"mcm","clk":"1004955271","pt":1580639465744,"mc":[{"id":"1.168135798","rc":[{"batl":[[0,1.53,25],[1,1.54,1.91],[2,1.69,586.7]],"ltp":1.48,"tv":940.98,"id":2249229},{"batb":[[2,2.04,368.81]],"ltp":3.0,"tv":119.79,"id":5720747}]}]}
{"op":"mcm","clk":"1004956337","pt":1580639476711,"mc":[{"id":"1.168135798","rc":[{"trd":[[1.5,308.36]],"ltp":1.5,"tv":974.59,"id":2249229},{"trd":[[3,73.32]],"batb":[[0,3,37.02]],"ltp":3.0,"tv":136.6,"id":5720747}],"tv":1111.2}]}
{"op":"mcm","clk":"1004956518","pt":1580639478416,"mc":[{"id":"1.168135798","rc":[{"trd":[[1.5,331.05]],"ltp":1.5,"tv":997.28,"id":2249229},{"trd":[[3,84.67]],"batb":[[0,3,25.67]],"ltp":3.0,"tv":147.94,"id":5720747}],"tv":1145.23}]}
{"op":"mcm","clk":"1004957443","pt":1580639487792,"mc":[{"id":"1.168135798","rc":[{"batl":[[0,1.54,1.91],[1,1.69,586.7],[2,1.71,642.63]],"ltp":1.5,"tv":997.28,"id":2249229}]}]}
{"op":"mcm","clk":"1004957742","pt":1580639490732,"mc":[{"id":"1.168135798","rc":[{"batl":[[0,1.5,25],[1,1.54,1.91],[2,1.69,586.7]],"ltp":1.5,"tv":997.28,"id":2249229}]}]}
{"op":"mcm","clk":"1004957803","pt":1580639491516,"mc":[{"id":"1.168135798","rc":[{"trd":[[1.5,390.49]],"batl":[[0,1.54,1.91],[1,1.69,586.7],[2,1.71,642.63]],"ltp":1.5,"tv":1056.73,"id":2249229},{"trd":[[3,89.39]],"batb":[[0,3,20.95]],"ltp":3.0,"tv":152.66,"id":5720747}],"tv":1209.4}]}
{"op":"mcm","clk":"1004958366","pt":1580639497618,"mc":[{"id":"1.168135798","rc":[{"trd":[[1.5,424.27]],"ltp":1.5,"tv":1090.5,"id":2249229},{"trd":[[3,106.28]],"batb":[[0,3,4.06]],"ltp":3.0,"tv":169.55,"id":5720747}],"tv":1260.06}]}
{"op":"mcm","clk":"1004958634","pt":1580639500603,"mc":[{"id":"1.168135798","rc":[{"trd":[[1.5,432.39]],"batb":[[0,1.5,26.32],[1,1.48,255.13],[2,1.47,831.79]],"ltp":1.5,"tv":1098.63,"id":2249229},{"trd":[[3,110.34]],"batb":[[0,2.46,119.75],[1,2.04,368.81],[2,1.4,43.94]],"ltp":3.0,"tv":173.61,"id":5720747}],"tv":1272.25}]}
{"op":"mcm","clk":"1004959768","pt":1580639511734,"mc":[{"id":"1.168135798","rc":[{"batb":[[2,1.46,396.89]],"ltp":1.5,"tv":1098.63,"id":2249229}]}]}
{"op":"mcm","clk":"1004959878","pt":1580639512736,"mc":[{"id":"1.168135798","rc":[{"batb":[[0,2.5,116.55],[1,2.46,119.75],[2,2.04,368.81]],"ltp":3.0,"tv":173.61,"id":5720747}]}]}
{"op":"mcm","clk":"1004960578","pt":1580639518650,"mc":[{"id":"1.168135798","rc":[{"batb":[[2,1.47,371.98]],"ltp":1.5,"tv":1098.63,"id":2249229}]}]}
{"op":"mcm","clk":"1004961308","pt":1580639525780,"mc":[{"id":"1.168135798","rc":[{"trd":[[1.54,22.72]],"batl":[[0,1.69,586.7],[1,1.71,642.63],[2,1.71,0]],"ltp":1.54,"tv":1100.53,"id":2249229},{"trd":[[2.5,37.94],[2.84,1.03]],"batb":[[0,2.5,97.58]],"ltp":2.5,"tv":212.59,"id":5720747}],"tv":1313.13}]}
{"op":"mcm","clk":"1004962098","pt":1580639531760,"mc":[{"id":"1.168135798","rc":[{"batb":[[0,1.55,30.6],[1,1.5,26.32],[2,1.48,255.13]],"ltp":1.54,"tv":1100.53,"id":2249229},{"trd":[[2.5,233.1]],"batb":[[0,2.46,119.75],[1,2.04,368.81],[2,1.4,43.94]],"batl":[[0,2.5,152.42]],"ltp":2.5,"tv":407.75,"id":5720747}],"tv":1508.29}]}
{"op":"mcm","clk":"1004962587","pt":1580639536796,"mc":[{"id":"1.168135798","rc":[{"trd":[[1.66,37.86]],"ltp":1.66,"tv":1138.4,"id":2249229},{"trd":[[2.5,491.35]],"batl":[[0,2.5,10.73]],"ltp":2.5,"tv":665.99,"id":5720747}],"tv":1804.39}]}
{"op":"mcm","clk":"1004962783","pt":1580639538783,"mc":[{"id":"1.168135798","rc":[{"trd":[[1.66,54.02]],"batl":[[0,1.64,358.57],[1,1.69,586.7],[2,1.71,642.63]],"ltp":1.66,"tv":1154.55,"id":2249229},{"trd":[[2.5,502.08]],"batb":[[0,2.5,116.55],[1,2.46,119.75],[2,2.04,368.81]],"ltp":2.5,"tv":676.72,"id":5720747}],"tv":1831.28}]}
{"op":"mcm","clk":"1004962869","pt":1580639539690,"mc":[{"id":"1.168135798","rc":[{"batl":[[0,1.64,190.53]],"ltp":1.66,"tv":1154.55,"id":2249229}]}]}
{"op":"mcm","clk":"1004962978","pt":1580639540778,"mc":[{"id":"1.168135798","rc":[{"batb":[[0,1.5,26.32],[1,1.48,255.13],[2,1.47,371.98]],"ltp":1.66,"tv":1154.55,"id":2249229}]}]}
{"op":"mcm","clk":"1004963238","pt":1580639543486,"mc":[{"id":"1.168135798","rc":[{"batl":[[1,1.66,100],[2,1.69,586.7]],"ltp":1.66,"tv":1154.55,"id":2249229}]}]}
{"op":"mcm","clk":"1004963369","pt":1580639544764,"mc":[{"id":"1.168135798","rc":[{"batl":[[0,1.66,100],[1,1.69,586.7],[2,1.71,642.63]],"ltp":1.66,"tv":1154.55,"id":2249229}]}]}
{"op":"mcm","clk":"1004963558","pt":1580639546692,"mc":[{"id":"1.168135798","rc":[{"batb":[[0,1.56,373.57],[1,1.5,26.32],[2,1.48,255.13]],"batl":[[0,1.69,586.7],[1,1.71,642.63],[2,1.71,0]],"ltp":1.66,"tv":1154.55,"id":2249229}]}]}
{"op":"mcm","clk":"1004964873","pt":1580639558716,"mc":[{"id":"1.168135798","rc":[{"trd":[[1.56,4]],"batb":[[0,1.56,371.57]],"ltp":1.56,"tv":1158.55,"id":2249229}],"tv":1835.28}]}
{"op":"mcm","clk":"1004965438","pt":1580639562690,"mc":[{"id":"1.168135798","rc":[{"batl":[[0,1.63,100]],"ltp":1.56,"tv":1158.55,"id":2249229}]}]}
{"op":"mcm","clk":"1004965536","pt":1580639563683,"mc":[{"id":"1.168135798","rc":[{"trd":[[1.56,19.15]],"batb":[[0,1.56,364]],"ltp":1.56,"tv":1173.7,"id":2249229}],"tv":1850.43}]}
{"op":"mcm","clk":"1004965649","pt":1580639564716,"mc":[{"id":"1.168135798","rc":[{"batl":[[1,1.69,594.31],[2,1.71,642.74]],"ltp":1.56,"tv":1173.7,"id":2249229}]}]}
{"op":"mcm","clk":"1004966258","pt":1580639570815,"mc":[{"id":"1.168135798","rc":[{"batb":[[0,2.04,368.81],[1,1.4,43.94],[2,1.05,16.8]],"ltp":2.5,"tv":676.72,"id":5720747}]}]}
{"op":"mcm","clk":"1004966346","pt":1580639571803,"mc":[{"id":"1.168135798","rc":[{"trd":[[1.63,200]],"batb":[[0,1.63,276.93],[1,1.62,388.66],[2,1.58,149.2]],"batl":[[0,1.69,594.31],[1,1.71,642.74],[2,1.71,0]],"ltp":1.63,"tv":1373.7,"id":2249229}],"tv":2050.43}]}
{"op":"mcm","clk":"1004966520","pt":1580639573740,"mc":[{"id":"1.168135798","rc":[{"batb":[[0,1.62,388.66],[1,1.56,364],[2,1.5,26.32]],"ltp":1.63,"tv":1373.7,"id":2249229}]}]}
{"op":"mcm","clk":"1004966604","pt":1580639574744,"mc":[{"id":"1.168135798","rc":[{"batl":[[0,1.69,491.99]],"ltp":1.63,"tv":1373.7,"id":2249229}]}]}
{"op":"mcm","clk":"1004966792","pt":1580639576642,"mc":[{"id":"1.168135798","rc":[{"trd":[[1.69,703.72]],"batb":[[0,1.62,388.78],[1,1.5,26.32],[2,1.42,88.47]],"batl":[[0,1.69,140.14]],"ltp":1.69,"tv":2077.42,"id":2249229}],"tv":2754.14}]}
{"op":"mcm","clk":"1004966886","pt":1580639577435,"mc":[{"id":"1.168135798","rc":[{"trd":[[1.63,211.7]],"batb":[[0,1.63,477.77],[1,1.62,388.78],[2,1.5,26.32]],"ltp":1.63,"tv":2089.11,"id":2249229}],"tv":2765.84}]}
{"op":"mcm","clk":"1004967187","pt":1580639580424,"mc":[{"id":"1.168135798","rc":[{"batb":[[2,1.55,317.87]],"ltp":1.63,"tv":2089.11,"id":2249229}]}]}
{"op":"mcm","clk":"1004967301","pt":1580639581750,"mc":[{"id":"1.168135798","rc":[{"batb":[[0,1.63,588.04]],"batl":[[0,1.69,391.39]],"ltp":1.63,"tv":2089.11,"id":2249229}]}]}
{"op":"mcm","clk":"1004967387","pt":1580639582755,"mc":[{"id":"1.168135798","rc":[{"batb":[[0,2.2,145.69],[1,2.04,368.81],[2,1.4,43.94]],"ltp":2.5,"tv":676.72,"id":5720747}]}]}
{"op":"mcm","clk":"1004967563","pt":1580639584743,"mc":[{"id":"1.168135798","rc":[{"trd":[[1.63,215.06]],"batb":[[0,1.55,317.87],[1,1.5,26.32],[2,1.42,88.47]],"ltp":1.63,"tv":2092.47,"id":2249229},{"batb":[[0,2.62,25.31],[1,2.2,145.69],[2,2.04,368.81]],"ltp":2.5,"tv":676.72,"id":5720747}],"tv":2769.2}]}
{"op":"mcm","clk":"1004967846","pt":1580639587727,"mc":[{"id":"1.168135798","rc":[{"batb":[[1,1.54,544.5],[2,1.53,482.83]],"batl":[[0,1.93,456.6],[1,1.95,422.93]],"ltp":1.63,"tv":2092.47,"id":2249229}]}]}
{"op":"mcm","clk":"1004968109","pt":1580639590662,"mc":[{"id":"1.168135798","rc":[{"trd":[[2.62,50.62]],"batb":[[0,2.2,145.69],[1,2.04,368.81],[2,1.4,43.94]],"batl":[[0,2.44,274.69]],"ltp":2.62,"tv":727.34,"id":5720747}],"tv":2819.82}]}
{"op":"mcm","clk":"1004968231","pt":1580639591762,"mc":[{"id":"1.168135798","rc":[{"batb":[[1,1.5,26.32],[2,1.42,88.47]],"ltp":1.63,"tv":2092.47,"id":2249229}]}]}
{"op":"mcm","clk":"1004968339","pt":1580639592764,"mc":[{"id":"1.168135798","rc":[{"batb":[[0,1.56,312.2],[1,1.55,317.87],[2,1.5,26.32]],"ltp":1.63,"tv":2092.47,"id":2249229}]}]}
{"op":"mcm","clk":"1004968450","pt":1580639593765,"mc":[{"id":"1.168135798","rc":[{"trd":[[1.69,733.72]],"ltp":1.69,"tv":2122.47,"id":2249229},{"trd":[[2.44,20.78]],"batb":[[1,2.1,158.94],[2,2.08,161.88]],"batl":[[0,2.44,253.91]],"ltp":2.44,"tv":748.12,"id":5720747}],"tv":2870.6}]}
{"op":"mcm","clk":"1004968627","pt":1580639595660,"mc":[{"id":"1.168135798","rc":[{"batb":[[0,2.1,158.94],[1,2.08,161.88],[2,1.4,43.94]],"ltp":2.44,"tv":748.12,"id":5720747}]}]}
{"op":"mcm","clk":"1004968878","pt":1580639597764,"mc":[{"id":"1.168135798","rc":[{"batb":[[2,1.85,671.16]],"ltp":2.44,"tv":748.12,"id":5720747}]}]}
{"op":"mcm","clk":"1004969136","pt":1580639600644,"mc":[{"id":"1.168135798","rc":[{"batb":[[2,1.54,543]],"batl":[[0,1.93,457.82],[1,1.95,422.93]],"ltp":1.69,"tv":2122.47,"id":2249229}]}]}
{"op":"mcm","clk":"1004969249","pt":1580639601759,"mc":[{"id":"1.168135798","rc":[{"batl":[[0,3,10]],"ltp":2.44,"tv":748.12,"id":5720747}]}]}
{"op":"mcm","clk":"1004969357","pt":1580639602666,"mc":[{"id":"1.168135798","rc":[{"trd":[[1.57,44.49]],"batb":[[0,1.57,43.22],[1,1.56,312.2],[2,1.55,317.87]],"ltp":1.57,"tv":2166.96,"id":2249229},{"trd":[[2.76,25.31]],"ltp":2.76,"tv":773.43,"id":5720747}],"tv":2940.4}]}
{"op":"mcm","clk":"1004970609","pt":1580639616807,"mc":[{"id":"1.168135798","rc":[{"batl":[[0,1.77,6.72],[1,1.93,457.82],[2,1.95,422.93]],"ltp":1.57,"tv":2166.96,"id":2249229}]}]}
{"op":"mcm","clk":"1004971046","pt":1580639621629,"mc":[{"id":"1.168135798","rc":[{"trd":[[1.77,2.28]],"batl":[[0,1.77,4.44]],"ltp":1.77,"tv":2169.24,"id":2249229},{"trd":[[2.28,1.77]],"ltp":2.28,"tv":775.2,"id":5720747}],"tv":2944.44}]}
{"op":"mcm","clk":"1004971775","pt":1580639629799,"mc":[{"id":"1.168135798","rc":[{"batl":[[0,1.93,457.82],[1,1.95,422.93],[2,1.95,0]],"ltp":1.77,"tv":2169.24,"id":2249229}]}]}
{"op":"mcm","clk":"1004971979","pt":1580639632522,"mc":[{"id":"1.168135798","rc":[{"batl":[[0,1.8,4.44],[1,1.93,457.82],[2,1.95,422.93]],"ltp":1.77,"tv":2169.24,"id":2249229}]}]}
{"op":"mcm","clk":"1004972051","pt":1580639633510,"mc":[{"id":"1.168135798","rc":[{"batl":[[1,1.93,0],[2,1.95,0]],"ltp":1.77,"tv":2169.24,"id":2249229}]}]}
{"op":"mcm","clk":"1004972153","pt":1580639634812,"mc":[{"id":"1.168135798","rc":[{"batb":[[0,1.56,312.2],[1,1.55,317.87],[2,1.54,543]],"ltp":1.77,"tv":2169.24,"id":2249229}]}]}
{"op":"mcm","clk":"1004972229","pt":1580639635797,"mc":[{"id":"1.168135798","rc":[{"batb":[[0,1.54,543],[1,1.53,482.83],[2,1.5,26.32]],"batl":[[0,1.63,86.54],[1,1.8,4.44]],"ltp":1.77,"tv":2169.24,"id":2249229},{"batb":[[2,1.4,43.94]],"ltp":2.28,"tv":775.2,"id":5720747}]}]}
{"op":"mcm","clk":"1004972299","pt":1580639636739,"mc":[{"id":"1.168135798","rc":[{"batl":[[0,1.59,432.62],[1,1.6,403.05],[2,1.63,86.54]],"ltp":1.77,"tv":2169.24,"id":2249229}]}]}
{"op":"mcm","clk":"1004972530","pt":1580639639614,"mc":[{"id":"1.168135798","rc":[{"batb":[[2,2,643.99]],"ltp":2.28,"tv":775.2,"id":5720747}]}]}
{"op":"mcm","clk":"1004972607","pt":1580639640721,"mc":[{"id":"1.168135798","rc":[{"batb":[[0,2,643.99],[1,1.4,43.94],[2,1.07,37.09]],"ltp":2.28,"tv":775.2,"id":5720747}]}]}
{"op":"mcm","clk":"1004972777","pt":1580639642806,"mc":[{"id":"1.168135798","rc":[{"trd":[[1.54,113.44]],"batb":[[0,1.54,497.64]],"batl":[[2,1.8,4.44]],"ltp":1.54,"tv":2259.96,"id":2249229},{"batb":[[0,2.4,124.88],[1,2,643.99],[2,1.4,43.94]],"ltp":2.28,"tv":775.2,"id":5720747}],"tv":3035.16}]}
{"op":"mcm","clk":"1004972914","pt":1580639644746,"mc":[{"id":"1.168135798","rc":[{"batb":[[1,2.3,134.49],[2,2,643.99]],"ltp":2.28,"tv":775.2,"id":5720747}]}]}
{"op":"mcm","clk":"1004973181","pt":1580639647720,"mc":[{"id":"1.168135798","rc":[{"batb":[[2,1.44,397.34]],"ltp":1.54,"tv":2259.96,"id":2249229}]}]}
{"op":"mcm","clk":"1004973265","pt":1580639648761,"mc":[{"id":"1.168135798","rc":[{"batb":[[0,1.44,397.34],[1,1.36,85.95],[2,1.3,24.25]],"batl":[[0,1.8,4.44],[1,1.6,0],[2,1.8,0]],"ltp":1.54,"tv":2259.96,"id":2249229}]}]}
{"op":"mcm","clk":"1004973377","pt":1580639649759,"mc":[{"id":"1.168135798","rc":[{"batb":[[0,2.9,25.31],[1,2.4,124.88],[2,2.3,134.49]],"ltp":2.28,"tv":775.2,"id":5720747}]}]}
{"op":"mcm","clk":"1004973469","pt":1580639650546,"mc":[{"id":"1.168135798","rc":[{"trd":[[1.53,26.32]],"ltp":1.53,"tv":2286.28,"id":2249229},{"trd":[[2.9,13.89]],"batb":[[0,2.9,11.42]],"ltp":2.9,"tv":789.09,"id":5720747}],"tv":3075.37}]}
{"op":"mcm","clk":"1004973569","pt":1580639651641,"mc":[{"id":"1.168135798","rc":[{"batb":[[0,1.47,513.83],[1,1.46,584.22],[2,1.44,397.34]],"batl":[[0,1.77,498.64],[1,1.79,552.42],[2,1.8,4.44]],"ltp":1.53,"tv":2286.28,"id":2249229}]}]}
{"op":"mcm","clk":"1004973847","pt":1580639654727,"mc":[{"id":"1.168135798","rc":[{"batl":[[2,1.8,0]],"ltp":1.53,"tv":2286.28,"id":2249229}]}]}
{"op":"mcm","clk":"1004973946","pt":1580639655768,"mc":[{"id":"1.168135798","rc":[{"batb":[[0,2.4,124.88],[1,2.3,134.49],[2,2,643.99]],"ltp":2.9,"tv":789.09,"id":5720747}]}]}
{"op":"mcm","clk":"1004974047","pt":1580639656764,"mc":[{"id":"1.168135798","rc":[{"batb":[[0,1.48,104.16],[1,1.47,513.83],[2,1.46,584.22]],"ltp":1.53,"tv":2286.28,"id":2249229}]}]}
{"op":"mcm","clk":"1004974213","pt":1580639658748,"mc":[{"id":"1.168135798","rc":[{"batb":[[0,1.48,468.39]],"ltp":1.53,"tv":2286.28,"id":2249229}]}]}
{"op":"mcm","clk":"1004974280","pt":1580639659743,"mc":[{"id":"1.168135798","rc":[{"batb":[[0,1.48,832.62]],"ltp":1.53,"tv":2286.28,"id":2249229},{"batl":[[0,2.9,17.68],[1,3,10]],"ltp":2.9,"tv":789.09,"id":5720747}]}]}
{"op":"mcm","clk":"1004974443","pt":1580639661736,"mc":[{"id":"1.168135798","rc":[{"batb":[[0,1.48,728.46]],"batl":[[0,1.71,50]],"ltp":1.53,"tv":2286.28,"id":2249229},{"batl":[[0,2.9,250]],"ltp":2.9,"tv":789.09,"id":5720747}]}]}
{"op":"mcm","clk":"1004974531","pt":1580639662732,"mc":[{"id":"1.168135798","rc":[{"batb":[[0,1.47,513.83],[1,1.46,584.22],[2,1.3,24.25]],"batl":[[0,1.53,103.34],[1,1.71,50]],"ltp":1.53,"tv":2286.28,"id":2249229},{"batb":[[2,1.4,43.94]],"ltp":2.9,"tv":789.09,"id":5720747}]}]}
{"op":"mcm","clk":"1004974615","pt":1580639663774,"mc":[{"id":"1.168135798","rc":[{"trd":[[1.52,476.97]],"batl":[[0,1.52,344.9],[1,1.53,577.28],[2,1.71,50]],"ltp":1.52,"tv":2763.25,"id":2249229},{"trd":[[2.9,263.89]],"batl":[[0,3,10],[1,3,0]],"ltp":2.9,"tv":1039.09,"id":5720747}],"tv":3802.34}]}
{"op":"mcm","clk":"1004974847","pt":1580639666749,"mc":[{"id":"1.168135798","rc":[{"batb":[[2,2.18,619.1]],"ltp":2.9,"tv":1039.09,"id":5720747}]}]}
{"op":"mcm","clk":"1004974914","pt":1580639667742,"mc":[{"id":"1.168135798","rc":[{"trd":[[1.5,440.26]],"ltp":1.5,"tv":2771.12,"id":2249229},{"trd":[[3,114.27]],"batl":[[0,3,6.07]],"ltp":3.0,"tv":1043.02,"id":5720747}],"tv":3814.14}]}
{"op":"mcm","clk":"1004974996","pt":1580639668777,"mc":[{"id":"1.168135798","rc":[{"batb":[[0,1.47,662]],"batl":[[0,1.52,678.74],[1,1.53,473.94],[2,1.71,0]],"ltp":1.5,"tv":2771.12,"id":2249229},{"batb":[[0,2.18,619.1],[1,1.4,43.94],[2,1.07,37.09]],"ltp":3.0,"tv":1043.02,"id":5720747}]}]}
{"op":"mcm","clk":"1004975059","pt":1580639669560,"mc":[{"id":"1.168135798","rc":[{"trd":[[3,126.41]],"batb":[[0,3,5.95],[1,2.18,619.1],[2,1.4,43.94]],"ltp":3.0,"tv":1055.16,"id":5720747}],"tv":3826.28}]}
{"op":"mcm","clk":"1004975174","pt":1580639670767,"mc":[{"id":"1.168135798","rc":[{"batb":[[2,1.4,437.08]],"ltp":1.5,"tv":2771.12,"id":2249229}]}]}
{"op":"mcm","clk":"1004975252","pt":1580639671663,"mc":[{"id":"1.168135798","rc":[{"trd":[[1.5,447.98]],"ltp":1.5,"tv":2778.84,"id":2249229},{"trd":[[3,130.27]],"batb":[[0,3,2.09],[1,2.6,109.27],[2,2.18,619.1]],"ltp":3.0,"tv":1059.01,"id":5720747}],"tv":3837.86}]}
{"op":"mcm","clk":"1004975612","pt":1580639675759,"mc":[{"id":"1.168135798","rc":[{"batb":[[0,1.4,437.08],[1,1.3,24.25],[2,1.29,79.93]],"batl":[[0,1.52,75.72],[1,1.53,0]],"ltp":1.5,"tv":2778.84,"id":2249229},{"batb":[[0,2.6,109.27],[1,2.18,619.1],[2,1.4,43.94]],"ltp":3.0,"tv":1059.01,"id":5720747}]}]}
{"op":"mcm","clk":"1004975780","pt":1580639677808,"mc":[{"id":"1.168135798","rc":[{"trd":[[1.52,477.29]],"batl":[[0,1.52,75.56]],"ltp":1.52,"tv":2779.16,"id":2249229}],"tv":3838.17}]}
{"op":"mcm","clk":"1004975874","pt":1580639678799,"mc":[{"id":"1.168135798","rc":[{"trd":[[1.52,484.8]],"batl":[[0,1.52,68.05]],"ltp":1.52,"tv":2786.67,"id":2249229},{"trd":[[2.92,3.91]],"ltp":2.92,"tv":1062.92,"id":5720747}],"tv":3849.6}]}
{"op":"mcm","clk":"1004975951","pt":1580639679795,"mc":[{"id":"1.168135798","rc":[{"batl":[[0,3,17.68]],"ltp":2.92,"tv":1062.92,"id":5720747}]}]}
{"op":"mcm","clk":"1004976034","pt":1580639680798,"mc":[{"id":"1.168135798","rc":[{"batb":[[0,1.42,976.37],[1,1.41,682.98],[2,1.4,437.08]],"batl":[[0,1.63,597.32],[1,1.64,367.83]],"ltp":1.52,"tv":2786.67,"id":2249229}]}]}
{"op":"mcm","clk":"1004976217","pt":1580639682809,"mc":[{"id":"1.168135798","rc":[{"batb":[[0,1.4,437.08],[1,1.3,24.25],[2,1.26,34.83]],"batl":[[0,2,1.68],[1,1.64,0]],"ltp":1.52,"tv":2786.67,"id":2249229}]}]}
{"op":"mcm","clk":"1004976383","pt":1580639684820,"mc":[{"id":"1.168135798","rc":[{"batb":[[0,1.3,24.25],[1,1.26,34.83],[2,1.14,9.24]],"ltp":1.52,"tv":2786.67,"id":2249229}]}]}
{"op":"mcm","clk":"1004976476","pt":1580639685817,"mc":[{"id":"1.168135798","rc":[{"batb":[[0,1.43,406.58],[1,1.3,24.25],[2,1.26,34.83]],"ltp":1.52,"tv":2786.67,"id":2249229}]}]}
{"op":"mcm","clk":"1004976572","pt":1580639686820,"mc":[{"id":"1.168135798","rc":[{"batb":[[0,1.43,813.17],[1,1.33,80.42],[2,1.3,24.23]],"ltp":1.52,"tv":2786.67,"id":2249229}]}]}
{"op":"mcm","clk":"1004976666","pt":1580639687746,"mc":[{"id":"1.168135798","rc":[{"batb":[[1,1.42,976.37],[2,1.41,682.98]],"batl":[[0,1.63,597.32],[1,1.64,367.83],[2,2,1.68]],"ltp":1.52,"tv":2786.67,"id":2249229},{"batb":[[0,2.18,619.1],[1,1.4,43.94],[2,1.07,37.09]],"ltp":2.92,"tv":1062.92,"id":5720747}]}]}
{"op":"mcm","clk":"1004976806","pt":1580639689480,"mc":[{"id":"1.168135798","rc":[{"batb":[[0,2.62,107.92],[1,2.18,619.1],[2,1.4,43.94]],"ltp":2.92,"tv":1062.92,"id":5720747}]}]}
{"op":"mcm","clk":"1004977021","pt":1580639691806,"mc":[{"id":"1.168135798","rc":[{"batb":[[1,2.6,109.27],[2,2.18,619.1]],"ltp":2.92,"tv":1062.92,"id":5720747}]}]}
{"op":"mcm","clk":"1004977413","pt":1580639696311,"mc":[{"id":"1.168135798","rc":[{"batb":[[0,1.44,113.63],[1,1.43,813.17],[2,1.42,976.37]],"ltp":1.52,"tv":2786.67,"id":2249229}]}]}
{"op":"mcm","clk":"1004977521","pt":1580639697788,"mc":[{"id":"1.168135798","rc":[{"batl":[[0,1.61,50],[1,1.63,597.32],[2,1.64,367.83]],"ltp":1.52,"tv":2786.67,"id":2249229}]}]}
{"op":"mcm","clk":"1004977847","pt":1580639701727,"mc":[{"id":"1.168135798","rc":[{"batl":[[0,1.5,75.72],[1,1.61,50],[2,1.63,597.32]],"ltp":1.52,"tv":2786.67,"id":2249229}]}]}
{"op":"mcm","clk":"1004978410","pt":1580639707725,"mc":[{"id":"1.168135798","rc":[{"batl":[[0,1.61,50],[1,1.63,597.32],[2,1.64,367.83]],"ltp":1.52,"tv":2786.67,"id":2249229}]}]}
{"op":"mcm","clk":"1004979036","pt":1580639713554,"mc":[{"id":"1.168135798","rc":[{"batb":[[2,1.33,80.42]],"ltp":1.52,"tv":2786.67,"id":2249229}]}]}
{"op":"mcm","clk":"1004979154","pt":1580639714653,"mc":[{"id":"1.168135798","rc":[{"batl":[[0,1.63,597.32],[1,1.64,367.83],[2,2,1.68]],"ltp":1.52,"tv":2786.67,"id":2249229},{"batb":[[0,2.18,619.1],[1,1.4,43.94],[2,1.07,37.09]],"ltp":2.92,"tv":1062.92,"id":5720747}]}]}
{"op":"mcm","clk":"1004979270","pt":1580639715753,"mc":[{"id":"1.168135798","rc":[{"batb":[[0,1.54,191.37],[1,1.44,113.63],[2,1.43,813.17]],"ltp":1.52,"tv":2786.67,"id":2249229}]}]}
{"op":"mcm","clk":"1004979379","pt":1580639716650,"mc":[{"id":"1.168135798","rc":[{"batb":[[0,1.57,634.58],[1,1.56,447.54],[2,1.54,191.37]],"ltp":1.52,"tv":2786.67,"id":2249229}]}]}
{"op":"mcm","clk":"1004979852","pt":1580639721550,"mc":[{"id":"1.168135798","rc":[{"batb":[[2,1.5,349.66]],"ltp":1.52,"tv":2786.67,"id":2249229}]}]}
{"op":"mcm","clk":"1004980282","pt":1580639725764,"mc":[{"id":"1.168135798","rc":[{"batb":[[0,2.2,145.69],[1,2.18,619.1],[2,1.4,43.94]],"ltp":2.92,"tv":1062.92,"id":5720747}]}]}
{"op":"mcm","clk":"1004980469","pt":1580639727765,"mc":[{"id":"1.168135798","rc":[{"trd":[[1.57,61.29]],"batb":[[0,1.57,626.18]],"ltp":1.57,"tv":2803.47,"id":2249229}],"tv":3866.4}]}
{"op":"mcm","clk":"1004980660","pt":1580639729556,"mc":[{"id":"1.168135798","rc":[{"batb":[[0,1.5,349.66],[1,1.36,77.45],[2,1.3,24.25]],"batl":[[0,2,1.68],[1,3.9,1.68],[2,2,0]],"ltp":1.57,"tv":2803.47,"id":2249229}]}]}
{"op":"mcm","clk":"1004980935","pt":1580639732291,"mc":[{"id":"1.168135798","rc":[{"trd":[[1.5,457.98]],"batb":[[0,1.5,344.66]],"ltp":1.5,"tv":2813.47,"id":2249229}],"tv":3876.4}]}
{"op":"mcm","clk":"1004981194","pt":1580639734770,"mc":[{"id":"1.168135798","rc":[{"batb":[[1,1.47,448.19],[2,1.46,582.73]],"batl":[[0,1.91,523.58],[1,1.93,435.82],[2,2,1.68]],"ltp":1.5,"tv":2813.47,"id":2249229}]}]}
{"op":"mcm","clk":"1004981758","pt":1580639740787,"mc":[{"id":"1.168135798","rc":[{"batb":[[1,1.48,364.23],[2,1.47,448.19]],"ltp":1.5,"tv":2813.47,"id":2249229}]}]}
{"op":"mcm","clk":"1004981845","pt":1580639741778,"mc":[{"id":"1.168135798","rc":[{"batb":[[2,2.1,158.94]],"ltp":2.92,"tv":1062.92,"id":5720747}]}]}
{"op":"mcm","clk":"1004982932","pt":1580639752595,"mc":[{"id":"1.168135798","rc":[{"trd":[[2.2,27.26]],"batb":[[0,2.2,132.06]],"ltp":2.2,"tv":1090.18,"id":5720747}],"tv":3903.66}]}
{"op":"mcm","clk":"1004983334","pt":1580639756784,"mc":[{"id":"1.168135798","rc":[{"batb":[[2,1.36,77.45]],"ltp":1.5,"tv":2813.47,"id":2249229}]}]}
{"op":"mcm","clk":"1004983518","pt":1580639758673,"mc":[{"id":"1.168135798","rc":[{"batb":[[0,2.18,619.1],[1,1.4,43.94],[2,1.07,37.09]],"ltp":2.2,"tv":1090.18,"id":5720747}]}]}
{"op":"mcm","clk":"1004983626","pt":1580639759715,"mc":[{"id":"1.168135798","rc":[{"batb":[[0,1.83,356.01],[1,1.81,525.63],[2,1.7,13.23]],"ltp":1.5,"tv":2813.47,"id":2249229},{"batb":[[0,1.4,43.94],[1,1.07,37.09],[2,1.06,43.26]],"ltp":2.2,"tv":1090.18,"id":5720747}]}]}
{"op":"mcm","clk":"1004983739","pt":1580639760773,"mc":[{"id":"1.168135798","rc":[{"trd":[[1.83,200]],"batb":[[0,1.83,256.01]],"ltp":1.83,"tv":3013.47,"id":2249229}],"tv":4103.66}]}
{"op":"mcm","clk":"1004983923","pt":1580639762814,"mc":[{"id":"1.168135798","rc":[{"batl":[[0,2,1.68],[1,3.9,1.68],[2,2,0]],"ltp":1.83,"tv":3013.47,"id":2249229}]}]}
{"op":"mcm","clk":"1004983999","pt":1580639763604,"mc":[{"id":"1.168135798","rc":[{"batb":[[2,1.52,95.03]],"ltp":1.83,"tv":3013.47,"id":2249229},{"batb":[[0,1.74,695.82],[1,1.4,43.94],[2,1.07,37.09]],"ltp":2.2,"tv":1090.18,"id":5720747}]}]}
{"op":"mcm","clk":"1004984230","pt":1580639765805,"mc":[{"id":"1.168135798","rc":[{"batb":[[0,1.86,12.09],[1,1.83,256.01],[2,1.81,525.63]],"batl":[[0,1.9,328.01],[1,1.92,443.11],[2,2,1.68]],"ltp":1.83,"tv":3013.47,"id":2249229}]}]}
{"op":"mcm","clk":"1004984314","pt":1580639766706,"mc":[{"id":"1.168135798","rc":[{"batb":[[1,1.83,334.1]],"ltp":1.83,"tv":3013.47,"id":2249229}]}]}
{"op":"mcm","clk":"1004984405","pt":1580639767813,"mc":[{"id":"1.168135798","rc":[{"trd":[[1.83,310.29],[1.86,12.09]],"batb":[[0,1.83,223.81],[1,1.81,525.63],[2,1.69,253.38]],"ltp":1.83,"tv":3135.85,"id":2249229},{"trd":[[2.18,10.32],[2.22,90.92]],"ltp":2.22,"tv":1191.42,"id":5720747}],"tv":4327.27}]}
{"op":"mcm","clk":"1004984504","pt":1580639768808,"mc":[{"id":"1.168135798","rc":[{"batb":[[0,1.69,253.38],[1,1.52,95.03],[2,1.3,24.25]],"ltp":1.83,"tv":3135.85,"id":2249229}]}]}
{"op":"mcm","clk":"1004984574","pt":1580639769694,"mc":[{"id":"1.168135798","rc":[{"batb":[[0,1.85,205.68],[1,1.74,695.82],[2,1.4,43.94]],"ltp":2.22,"tv":1191.42,"id":5720747}]}]}
{"op":"mcm","clk":"1004984655","pt":1580639770789,"mc":[{"id":"1.168135798","rc":[{"batb":[[0,1.74,695.82],[1,1.4,43.94],[2,1.07,37.09]],"ltp":2.22,"tv":1191.42,"id":5720747}]}]}
{"op":"mcm","clk":"1004984752","pt":1580639771723,"mc":[{"id":"1.168135798","rc":[{"batb":[[0,1.82,564.64],[1,1.8,535.79],[2,1.69,253.38]],"batl":[[0,2,1.68],[1,3.9,1.68],[2,2,0]],"ltp":1.83,"tv":3135.85,"id":2249229},{"batb":[[0,1.76,230.04],[1,1.74,695.82],[2,1.4,43.94]],"ltp":2.22,"tv":1191.42,"id":5720747}]}]}
{"op":"mcm","clk":"1004984844","pt":1580639772717,"mc":[{"id":"1.168135798","rc":[{"batb":[[0,1.69,253.38],[1,1.52,95.03],[2,1.3,24.25]],"ltp":1.83,"tv":3135.85,"id":2249229}]}]}
{"op":"mcm","clk":"1004985033","pt":1580639774723,"mc":[{"id":"1.168135798","rc":[{"batb":[[1,1.58,463.38],[2,1.57,436.21]],"batl":[[1,2.76,305.71],[2,2.8,315.8]],"ltp":1.83,"tv":3135.85,"id":2249229},{"batl":[[0,2.1,34.45]],"ltp":2.22,"tv":1191.42,"id":5720747}]}]}
{"op":"mcm","clk":"1004985129","pt":1580639775718,"mc":[{"id":"1.168135798","rc":[{"batl":[[0,2.1,39.45]],"ltp":2.22,"tv":1191.42,"id":5720747}]}]}
{"op":"mcm","clk":"1004985316","pt":1580639777697,"mc":[{"id":"1.168135798","rc":[{"batl":[[0,2.1,5]],"ltp":2.22,"tv":1191.42,"id":5720747}]}]}
{"op":"mcm","clk":"1004985507","pt":1580639779724,"mc":[{"id":"1.168135798","rc":[{"trd":[[2,1.68]],"batl":[[0,2.76,305.71],[1,2.8,315.8],[2,3.9,1.68]],"ltp":2.0,"tv":3137.53,"id":2249229},{"trd":[[2,1.68]],"batl":[[0,1.85,36.18],[1,2.1,5]],"ltp":2.0,"tv":1193.1,"id":5720747}],"tv":4330.64}]}
{"op":"mcm","clk":"1004985599","pt":1580639780726,"mc":[{"id":"1.168135798","rc":[{"batb":[[0,1.74,695.82],[1,1.4,43.94],[2,1.07,37.09]],"ltp":2.0,"tv":1193.1,"id":5720747}]}]}
{"op":"mcm","clk":"1004985700","pt":1580639781720,"mc":[{"id":"1.168135798","rc":[{"batl":[[1,2,34.45],[2,2.1,5]],"ltp":2.0,"tv":1193.1,"id":5720747}]}]}
{"op":"mcm","clk":"1004985807","pt":1580639782818,"mc":[{"id":"1.168135798","rc":[{"batb":[[0,1.58,463.38],[1,1.57,436.21],[2,1.52,95.03]],"ltp":2.0,"tv":3137.53,"id":2249229},{"batb":[[1,1.4,28.79]],"ltp":2.0,"tv":1193.1,"id":5720747}]}]}
{"op":"mcm","clk":"1004985879","pt":1580639783750,"mc":[{"id":"1.168135798","rc":[{"batb":[[2,1.35,7.41]],"ltp":2.0,"tv":1193.1,"id":5720747}]}]}
{"op":"mcm","clk":"1004985963","pt":1580639784731,"mc":[{"id":"1.168135798","rc":[{"trd":[[1.87,3.43],[1.9,5.53],[2,36.13],[2.16,30.99]],"batb":[[0,1.59,84.74],[1,1.58,463.38],[2,1.57,436.21]],"batl":[[0,1.86,25.6],[1,2.76,305.71],[2,2.8,315.8]],"ltp":1.87,"tv":3211.93,"id":2249229},{"trd":[[1.85,36.18],[2,36.13],[2.1,5],[2.14,3]],"batl":[[0,1000,2.17],[1,2,0],[2,2.1,0]],"ltp":2.14,"tv":1271.73,"id":5720747}],"tv":4483.66}]}
{"op":"mcm","clk":"1004986053","pt":1580639785725,"mc":[{"id":"1.168135798","rc":[{"batb":[[0,1.59,381.06]],"batl":[[1,1.96,32.56],[2,2.76,305.71]],"ltp":1.87,"tv":3211.93,"id":2249229}]}]}
{"op":"mcm","clk":"1004986152","pt":1580639786714,"mc":[{"id":"1.168135798","rc":[{"batb":[[0,1.6,291.39],[1,1.59,381.06],[2,1.58,463.38]],"batl":[[1,2.76,305.71],[2,2.8,315.8]],"ltp":1.87,"tv":3211.93,"id":2249229},{"batb":[[0,1.4,28.79],[1,1.35,7.41],[2,1.25,10.38]],"ltp":2.14,"tv":1271.73,"id":5720747}]}]}
{"op":"mcm","clk":"1004986249","pt":1580639787715,"mc":[{"id":"1.168135798","rc":[{"batl":[[0,2.74,50]],"ltp":1.87,"tv":3211.93,"id":2249229}]}]}
{"op":"mcm","clk":"1004986339","pt":1580639788750,"mc":[{"id":"1.168135798","rc":[{"batb":[[2,1.3,24.25]],"batl":[[1,3.9,1.68],[2,2.8,0]],"ltp":1.87,"tv":3211.93,"id":2249229},{"batl":[[0,1.72,0.17]],"ltp":2.14,"tv":1271.73,"id":5720747}]}]}
{"op":"mcm","clk":"1004986556","pt":1580639790751,"mc":[{"id":"1.168135798","rc":[{"trd":[[2.38,0.12]],"batb":[[0,1.94,423.44],[1,1.92,435.4],[2,1.6,291.39]],"batl":[[0,2.04,579.97],[1,2.06,359.18],[2,2.74,50]],"ltp":2.38,"tv":3212.05,"id":2249229},{"trd":[[1.72,0.17]],"ltp":1.72,"tv":1271.9,"id":5720747}],"tv":4483.95}]}
{"op":"mcm","clk":"1004986650","pt":1580639791739,"mc":[{"id":"1.168135798","rc":[{"batb":[[0,1.6,291.39],[1,1.59,381.06],[2,1.3,24.25]],"batl":[[0,2.74,50],[1,3.9,1.68],[2,2.74,0]],"ltp":2.38,"tv":3212.05,"id":2249229}]}]}
{"op":"mcm","clk":"1004986737","pt":1580639792729,"mc":[{"id":"1.168135798","rc":[{"batb":[[1,1.59,296.32],[2,1.56,111.05]],"ltp":2.38,"tv":3212.05,"id":2249229},{"batb":[[0,1.68,709.5],[1,1.4,28.79],[2,1.35,7.41]],"ltp":1.72,"tv":1271.9,"id":5720747}]}]}
{"op":"mcm","clk":"1004986812","pt":1580639793727,"mc":[{"id":"1.168135798","rc":[{"batb":[[2,1.58,464.57]],"batl":[[1,2.76,305.02],[2,2.8,315.8]],"ltp":2.38,"tv":3212.05,"id":2249229}]}]}
{"op":"mcm","clk":"1004986961","pt":1580639795342,"mc":[{"id":"1.168135798","rc":[{"batb":[[0,1.61,81.96],[1,1.6,291.39],[2,1.59,296.32]],"ltp":2.38,"tv":3212.05,"id":2249229}]}]}
{"op":"mcm","clk":"1004989515","pt":1580639821789,"mc":[{"id":"1.168135798","rc":[{"batb":[[0,1.6,291.39],[1,1.59,296.32],[2,1.58,464.57]],"ltp":2.38,"tv":3212.05,"id":2249229}]}]}
{"op":"mcm","clk":"1004989634","pt":1580639822792,"mc":[{"id":"1.168135798","rc":[{"batl":[[1,3.9,1.68],[2,2.8,0]],"ltp":2.38,"tv":3212.05,"id":2249229}]}]}
{"op":"mcm","clk":"1004989822","pt":1580639824783,"mc":[{"id":"1.168135798","rc":[{"batb":[[0,1.58,464.57],[1,1.57,436.22],[2,1.56,111.05]],"ltp":2.38,"tv":3212.05,"id":2249229}]}]}
{"op":"mcm","clk":"1004989934","pt":1580639825790,"mc":[{"id":"1.168135798","rc":[{"batb":[[2,1.3,24.25]],"batl":[[0,1.64,709.88],[1,1.65,359.86],[2,2.74,50]],"ltp":2.38,"tv":3212.05,"id":2249229},{"batb":[[0,1.4,28.79],[1,1.35,7.41],[2,1.28,9.27]],"ltp":1.72,"tv":1271.9,"id":5720747}]}]}
{"op":"mcm","clk":"1004990028","pt":1580639826783,"mc":[{"id":"1.168135798","rc":[{"batl":[[2,3.9,1.68]],"ltp":2.38,"tv":3212.05,"id":2249229}]}]}
{"op":"mcm","clk":"1004990301","pt":1580639829599,"mc":[{"id":"1.168135798","rc":[{"batb":[[2,1.39,83.12]],"ltp":2.38,"tv":3212.05,"id":2249229},{"batb":[[0,1.95,652.3],[1,1.4,28.79],[2,1.35,7.41]],"ltp":1.72,"tv":1271.9,"id":5720747}]}]}
{"op":"mcm","clk":"1004990920","pt":1580639835784,"mc":[{"id":"1.168135798","rc":[{"batb":[[0,2.1,158.94],[1,2,174.83],[2,1.95,652.3]],"ltp":1.72,"tv":1271.9,"id":5720747}]}]}
{"op":"mcm","clk":"1004991103","pt":1580639837819,"mc":[{"id":"1.168135798","rc":[{"batb":[[0,1.46,380.07],[1,1.39,83.12],[2,1.3,24.25]],"batl":[[0,3.9,1.68],[1,1.65,0],[2,3.9,0]],"ltp":2.38,"tv":3212.05,"id":2249229}]}]}
{"op":"mcm","clk":"1004991389","pt":1580639840802,"mc":[{"id":"1.168135798","rc":[{"batb":[[0,1.47,715.94],[1,1.46,965.15],[2,1.39,83.12]],"batl":[[0,1.91,312.87],[1,1.93,436.23],[2,3.9,1.68]],"ltp":2.38,"tv":3212.05,"id":2249229}]}]}
{"op":"mcm","clk":"1004991489","pt":1580639841801,"mc":[{"id":"1.168135798","rc":[{"trd":[[2.76,60.68]],"batb":[[0,2.76,8.88],[1,2.1,158.94],[2,2,174.83]],"ltp":2.76,"tv":1307.27,"id":5720747}],"tv":4519.32}]}
{"op":"mcm","clk":"1004991750","pt":1580639844709,"mc":[{"id":"1.168135798","rc":[{"batb":[[2,1.95,652.3]],"ltp":2.76,"tv":1307.27,"id":5720747}]}]}
{"op":"mcm","clk":"1004991908","pt":1580639846815,"mc":[{"id":"1.168135798","rc":[{"batb":[[1,1.46,585.08]],"ltp":2.38,"tv":3212.05,"id":2249229}]}]}
{"op":"mcm","clk":"1004992097","pt":1580639848795,"mc":[{"id":"1.168135798","rc":[{"batb":[[0,1.48,364.23],[1,1.47,715.94],[2,1.46,585.08]],"ltp":2.38,"tv":3212.05,"id":2249229}]}]}
{"op":"mcm","clk":"1004992181","pt":1580639849625,"mc":[{"id":"1.168135798","rc":[{"batb":[[0,1.48,728.46],[1,1.39,83.12],[2,1.3,24.25]],"batl":[[0,3.9,1.68],[1,1.93,0],[2,3.9,0]],"ltp":2.38,"tv":3212.05,"id":2249229}]}]}
{"op":"mcm","clk":"1004992289","pt":1580639850718,"mc":[{"id":"1.168135798","rc":[{"batb":[[1,2.12,156.1],[2,2.1,158.94]],"ltp":2.76,"tv":1307.27,"id":5720747}]}]}
{"op":"mcm","clk":"1004992378","pt":1580639851705,"mc":[{"id":"1.168135798","rc":[{"batb":[[1,1.3,24.25],[2,1.26,34.83]],"ltp":2.38,"tv":3212.05,"id":2249229},{"batb":[[1,1.95,652.3],[2,1.4,28.79]],"ltp":2.76,"tv":1307.27,"id":5720747}]}]}
{"op":"mcm","clk":"1004992476","pt":1580639852807,"mc":[{"id":"1.168135798","rc":[{"trd":[[1.57,76.91]],"batb":[[0,1.62,649.52],[1,1.61,397.73],[2,1.48,728.46]],"batl":[[0,1.68,354.79],[1,1.7,655.45],[2,3.9,1.68]],"ltp":1.57,"tv":3227.67,"id":2249229},{"trd":[[2.76,69.56]],"batb":[[0,1.95,652.3],[1,1.4,28.79],[2,1.35,7.41]],"ltp":2.76,"tv":1316.15,"id":5720747}],"tv":4543.83}]}
{"op":"mcm","clk":"1004992579","pt":1580639853814,"mc":[{"id":"1.168135798","rc":[{"batb":[[0,1.48,728.46],[1,1.3,24.25],[2,1.26,34.83]],"batl":[[0,3.9,1.68],[1,1.7,0],[2,3.9,0]],"ltp":1.57,"tv":3227.67,"id":2249229}]}]}
{"op":"mcm","clk":"1004992673","pt":1580639854808,"mc":[{"id":"1.168135798","rc":[{"batb":[[0,1.49,102.04],[1,1.48,728.46],[2,1.3,24.25]],"ltp":1.57,"tv":3227.67,"id":2249229}]}]}
{"op":"mcm","clk":"1004992770","pt":1580639855631,"mc":[{"id":"1.168135798","rc":[{"batb":[[2,1.42,89.28]],"ltp":1.57,"tv":3227.67,"id":2249229}]}]}
{"op":"mcm","clk":"1004993184","pt":1580639859748,"mc":[{"id":"1.168135798","rc":[{"batb":[[2,1.47,712.89]],"batl":[[0,1.91,315.36],[1,1.93,436.24],[2,3.9,1.68]],"ltp":1.57,"tv":3227.67,"id":2249229}]}]}
{"op":"mcm","clk":"1004993570","pt":1580639862636,"mc":[{"id":"1.168135798","rc":[{"batl":[[0,2.76,8.8]],"ltp":2.76,"tv":1316.15,"id":5720747}]}]}
{"op":"mcm","clk":"1004993834","pt":1580639865683,"mc":[{"id":"1.168135798","rc":[{"batb":[[0,2.1,158.94],[1,1.95,652.3],[2,1.4,28.79]],"ltp":2.76,"tv":1316.15,"id":5720747}]}]}
{"op":"mcm","clk":"1004993952","pt":1580639866787,"mc":[{"id":"1.168135798","rc":[{"batb":[[0,1.48,728.46],[1,1.42,89.28],[2,1.3,24.25]],"batl":[[0,3.9,1.68],[1,1.93,0],[2,3.9,0]],"ltp":1.57,"tv":3227.67,"id":2249229},{"batb":[[0,2.1,317.87]],"ltp":2.76,"tv":1316.15,"id":5720747}]}]}
{"op":"mcm","clk":"1004994152","pt":1580639867775,"mc":[{"id":"1.168135798","rc":[{"batb":[[0,1.95,652.3],[1,1.4,28.79],[2,1.35,7.41]],"ltp":2.76,"tv":1316.15,"id":5720747}]}]}
{"op":"mcm","clk":"1004994340","pt":1580639869555,"mc":[{"id":"1.168135798","rc":[{"batb":[[1,1.3,24.25],[2,1.26,34.83]],"ltp":1.57,"tv":3227.67,"id":2249229},{"batb":[[0,1.4,28.79],[1,1.35,7.41],[2,1.28,9.27]],"ltp":2.76,"tv":1316.15,"id":5720747}]}]}
{"op":"mcm","clk":"1004994449","pt":1580639870758,"mc":[{"id":"1.168135798","rc":[{"batb":[[0,1.84,318.45],[1,1.82,516.35],[2,1.48,728.46]],"batl":[[0,1.91,315.36],[1,1.93,436.24],[2,3.9,1.68]],"ltp":1.57,"tv":3227.67,"id":2249229}]}]}
{"op":"mcm","clk":"1004994690","pt":1580639873754,"mc":[{"id":"1.168135798","rc":[{"batb":[[2,1.52,95.03]],"ltp":1.57,"tv":3227.67,"id":2249229},{"batb":[[0,1.74,695.82],[1,1.4,18.95],[2,1.35,7.41]],"ltp":2.76,"tv":1316.15,"id":5720747}]}]}
{"op":"mcm","clk":"1004994879","pt":1580639875793,"mc":[{"id":"1.168135798","rc":[{"batl":[[0,3.9,1.68],[1,1.93,0],[2,3.9,0]],"ltp":1.57,"tv":3227.67,"id":2249229}]}]}
{"op":"mcm","clk":"1004994972","pt":1580639876781,"mc":[{"id":"1.168135798","rc":[{"batb":[[2,1.66,264.9]],"ltp":1.57,"tv":3227.67,"id":2249229}]}]}
{"op":"mcm","clk":"1004995153","pt":1580639878770,"mc":[{"id":"1.168135798","rc":[{"trd":[[1.84,121.04]],"batb":[[0,1.84,318.55]],"batl":[[0,1.92,418.37],[1,1.94,429.2],[2,3.9,1.68]],"ltp":1.84,"tv":3348.71,"id":2249229},{"trd":[[2.2,128.49]],"ltp":2.2,"tv":1417.39,"id":5720747}],"tv":4766.1}]}
{"op":"mcm","clk":"1004995405","pt":1580639881706,"mc":[{"id":"1.168135798","rc":[{"batb":[[0,1.84,405.83]],"ltp":1.84,"tv":3348.71,"id":2249229}]}]}
{"op":"mcm","clk":"1004995520","pt":1580639882811,"mc":[{"id":"1.168135798","rc":[{"batb":[[0,1.66,264.9],[1,1.52,95.03],[2,1.3,24.25]],"batl":[[0,3.9,1.68],[1,1.94,0],[2,3.9,0]],"ltp":1.84,"tv":3348.71,"id":2249229}]}]}
{"op":"mcm","clk":"1004995807","pt":1580639885795,"mc":[{"id":"1.168135798","rc":[{"batb":[[0,1.67,74.62],[1,1.66,264.9],[2,1.52,95.03]],"ltp":1.84,"tv":3348.71,"id":2249229}]}]}
{"op":"mcm","clk":"1004995998","pt":1580639887784,"mc":[{"id":"1.168135798","rc":[{"batb":[[2,1.59,539.26]],"batl":[[0,2.78,225.49],[1,2.82,310.02],[2,3.9,1.68]],"ltp":1.84,"tv":3348.71,"id":2249229}]}]}
{"op":"mcm","clk":"1004996247","pt":1580639890805,"mc":[{"id":"1.168135798","rc":[{"batb":[[1,1.59,539.26],[2,1.58,425.82]],"ltp":1.84,"tv":3348.71,"id":2249229}]}]}
{"op":"mcm","clk":"1004996438","pt":1580639892676,"mc":[{"id":"1.168135798","rc":[{"batb":[[1,1.6,291.39],[2,1.59,539.26]],"batl":[[0,2.76,50],[1,2.78,225.49],[2,2.82,310.02]],"ltp":1.84,"tv":3348.71,"id":2249229},{"trd":[[1.74,10]],"batb":[[0,1.4,18.95],[1,1.35,7.41],[2,1.28,9.27]],"ltp":1.74,"tv":1427.39,"id":5720747}],"tv":4776.1}]}
{"op":"mcm","clk":"1004996518","pt":1580639893724,"mc":[{"id":"1.168135798","rc":[{"batb":[[1,1.61,286.61],[2,1.6,291.39]],"ltp":1.84,"tv":3348.71,"id":2249229}]}]}
{"op":"mcm","clk":"1004996709","pt":1580639895808,"mc":[{"id":"1.168135798","rc":[{"batb":[[0,1.58,301.43],[1,1.57,306.72],[2,1.4,18.95]],"ltp":1.74,"tv":1427.39,"id":5720747}]}]}
{"op":"mcm","clk":"1004996781","pt":1580639896790,"mc":[{"id":"1.168135798","rc":[{"batl":[[0,3.9,1.68],[1,2.78,0],[2,2.82,0]],"ltp":1.84,"tv":3348.71,"id":2249229}]}]}
{"op":"mcm","clk":"1004997026","pt":1580639899610,"mc":[{"id":"1.168135798","rc":[{"batb":[[2,1.56,482.39]],"batl":[[0,1.61,400.85],[1,1.62,384.43],[2,2.76,8.8]],"ltp":1.74,"tv":1427.39,"id":5720747}]}]}
{"op":"mcm","clk":"1004997141","pt":1580639900809,"mc":[{"id":"1.168135798","rc":[{"batb":[[0,1.89,159.67]],"ltp":1.84,"tv":3348.71,"id":2249229},{"batb":[[0,1.56,482.39],[1,1.55,457.39],[2,1.42,662.57]],"batl":[[0,1.62,384.43],[1,2.76,8.8],[2,2.76,0]],"ltp":1.74,"tv":1427.39,"id":5720747}]}]}
{"op":"mcm","clk":"1004997233","pt":1580639901801,"mc":[{"id":"1.168135798","rc":[{"batl":[[1,2.76,0]],"ltp":1.74,"tv":1427.39,"id":5720747}]}]}
{"op":"mcm","clk":"1004997332","pt":1580639902683,"mc":[{"id":"1.168135798","rc":[{"batb":[[0,1.42,662.57],[1,1.4,18.93],[2,1.35,7.41]],"ltp":1.74,"tv":1427.39,"id":5720747}]}]}
{"op":"mcm","clk":"1004997408","pt":1580639903515,"mc":[{"id":"1.168135798","rc":[{"batb":[[1,1.35,7.41],[2,1.28,9.27]],"ltp":1.74,"tv":1427.39,"id":5720747}]}]}
{"op":"mcm","clk":"1004997511","pt":1580639904727,"mc":[{"id":"1.168135798","rc":[{"batb":[[1,1.3,24.25],[2,1.26,34.83]],"ltp":1.84,"tv":3348.71,"id":2249229},{"batb":[[0,1.44,5.92],[1,1.42,662.55],[2,1.35,7.41]],"ltp":1.74,"tv":1427.39,"id":5720747}]}]}
{"op":"mcm","clk":"1004997871","pt":1580639908804,"mc":[{"id":"1.168135798","rc":[{"batb":[[0,2.1,158.94],[1,1.89,159.67],[2,1.3,24.25]],"ltp":1.84,"tv":3348.71,"id":2249229}]}]}
{"op":"mcm","clk":"1004997958","pt":1580639909743,"mc":[{"id":"1.168135798","rc":[{"batb":[[0,1.56,580.69],[1,1.55,457.44],[2,1.44,5.92]],"batl":[[0,1.62,688.36],[1,1.63,374.59]],"ltp":1.74,"tv":1427.39,"id":5720747}]}]}
{"op":"mcm","clk":"1004998056","pt":1580639910733,"mc":[{"id":"1.168135798","rc":[{"batb":[[1,1.93,168.04],[2,1.89,159.67]],"ltp":1.84,"tv":3348.71,"id":2249229}]}]}
{"op":"mcm","clk":"1004998161","pt":1580639911722,"mc":[{"id":"1.168135798","rc":[{"batb":[[1,1.96,168.04],[2,1.93,168.04]],"ltp":1.84,"tv":3348.71,"id":2249229},{"batb":[[0,1.44,5.92],[1,1.42,662.55],[2,1.35,7.41]],"ltp":1.74,"tv":1427.39,"id":5720747}]}]}
{"op":"mcm","clk":"1004998333","pt":1580639913760,"mc":[{"id":"1.168135798","rc":[{"batb":[[0,2.12,168.04],[1,2.1,158.94],[2,1.96,168.04]],"ltp":1.84,"tv":3348.71,"id":2249229}]}]}
{"op":"mcm","clk":"1004998442","pt":1580639914809,"mc":[{"id":"1.168135798","rc":[{"batb":[[0,1.48,661.25],[1,1.47,566.34],[2,1.44,5.9]],"batl":[[0,1.78,401.05],[1,1.8,541.09]],"ltp":1.74,"tv":1427.39,"id":5720747}]}]}
{"op":"mcm","clk":"1004998532","pt":1580639915747,"mc":[{"id":"1.168135798","rc":[{"batb":[[2,1.45,388.51]],"ltp":1.74,"tv":1427.39,"id":5720747}]}]}
{"op":"mcm","clk":"1004998700","pt":1580639917742,"mc":[{"id":"1.168135798","rc":[{"batb":[[0,1.62,2],[1,1.48,661.25],[2,1.47,566.34]],"ltp":1.74,"tv":1427.39,"id":5720747}]}]}
{"op":"mcm","clk":"1004998906","pt":1580639919774,"mc":[{"id":"1.168135798","rc":[{"batb":[[0,2.32,132.45],[1,2.3,134.49],[2,2.1,158.94]],"ltp":1.84,"tv":3348.71,"id":2249229}]}]}
{"op":"mcm","clk":"1004999011","pt":1580639920773,"mc":[{"id":"1.168135798","rc":[{"batb":[[1,1.5,349.66],[2,1.48,661.25]],"ltp":1.74,"tv":1427.39,"id":5720747}]}]}
{"op":"mcm","clk":"1004999112","pt":1580639921761,"mc":[{"id":"1.168135798","rc":[{"batb":[[2,1.89,159.67]],"ltp":1.84,"tv":3348.71,"id":2249229},{"batb":[[1,1.5,699.32]],"ltp":1.74,"tv":1427.39,"id":5720747}]}]}
{"op":"mcm","clk":"1004999222","pt":1580639922757,"mc":[{"id":"1.168135798","rc":[{"trd":[[2.32,4]],"batb":[[0,2.32,130.45]],"ltp":2.32,"tv":3352.71,"id":2249229}],"tv":4780.1}]}
{"op":"mcm","clk":"1004999340","pt":1580639923747,"mc":[{"id":"1.168135798","rc":[{"trd":[[1.5,396.01],[1.62,4]],"batb":[[0,1.5,501.31],[1,1.48,661.25],[2,1.47,566.34]],"ltp":1.5,"tv":1827.4,"id":5720747}],"tv":5180.11}]}
{"op":"mcm","clk":"1004999423","pt":1580639924751,"mc":[{"id":"1.168135798","rc":[{"trd":[[2.32,19.15]],"batb":[[0,2.32,122.87]],"ltp":2.32,"tv":3367.86,"id":2249229}],"tv":5195.26}]}
{"op":"mcm","clk":"1004999532","pt":1580639925754,"mc":[{"id":"1.168135798","rc":[{"trd":[[2.32,42.66]],"batb":[[0,2.32,99.36]],"ltp":2.32,"tv":3391.38,"id":2249229},{"trd":[[1.76,31]],"ltp":1.76,"tv":1858.4,"id":5720747}],"tv":5249.78}]}
{"op":"mcm","clk":"1004999706","pt":1580639927783,"mc":[{"id":"1.168135798","rc":[{"batb":[[0,2.34,1260.29],[1,2.32,99.36],[2,2.3,134.49]],"ltp":2.32,"tv":3391.38,"id":2249229}]}]}
{"op":"mcm","clk":"1004999851","pt":1580639929352,"mc":[{"id":"1.168135798","rc":[{"batl":[[0,1.62,2],[1,1.78,401.05],[2,1.8,541.09]],"ltp":1.76,"tv":1858.4,"id":5720747}]}]}
{"op":"mcm","clk":"1005000019","pt":1580639932811,"mc":[{"id":"1.168135798","rc":[{"batb":[[0,2.7,81.57],[1,2.34,1260.29],[2,2.32,99.36]],"batl":[[0,2.76,3.79],[1,3.9,1.68]],"ltp":2.32,"tv":3391.38,"id":2249229},{"batl":[[1,1.74,104.18],[2,1.78,401.05]],"ltp":1.76,"tv":1858.4,"id":5720747}]}]}
{"op":"mcm","clk":"1005000250","pt":1580639933802,"mc":[{"id":"1.168135798","rc":[{"batb":[[0,1.52,213.41],[1,1.51,98.03],[2,1.5,501.31]],"batl":[[1,1.72,208.37],[2,1.73,104.18]],"ltp":1.76,"tv":1858.4,"id":5720747}]}]}
{"op":"mcm","clk":"1005000582","pt":1580639936780,"mc":[{"id":"1.168135798","rc":[{"trd":[[2.7,75.73]],"batb":[[0,2.7,43.71]],"ltp":2.7,"tv":3467.1,"id":2249229}],"tv":5325.5}]}
{"op":"mcm","clk":"1005000673","pt":1580639937813,"mc":[{"id":"1.168135798","rc":[{"batl":[[0,1.72,208.37],[1,1.73,104.18],[2,1.74,104.18]],"ltp":1.76,"tv":1858.4,"id":5720747}]}]}
{"op":"mcm","clk":"1005000760","pt":1580639938715,"mc":[{"id":"1.168135798","rc":[{"trd":[[2.76,2.82]],"batl":[[0,3.9,2.64],[1,3.9,0]],"ltp":2.76,"tv":3469.93,"id":2249229},{"trd":[[1.56,5]],"ltp":1.56,"tv":1863.4,"id":5720747}],"tv":5333.33}]}
{"op":"mcm","clk":"1005000858","pt":1580639939813,"mc":[{"id":"1.168135798","rc":[{"batl":[[0,3.9,1.68]],"ltp":2.76,"tv":3469.93,"id":2249229},{"batl":[[0,1.71,50],[1,1.72,208.37],[2,1.73,104.18]],"ltp":1.56,"tv":1863.4,"id":5720747}]}]}
{"op":"mcm","clk":"1005000949","pt":1580639940807,"mc":[{"id":"1.168135798","rc":[{"trd":[[1.52,3.6]],"batb":[[0,1.52,211.61]],"ltp":1.52,"tv":1866.99,"id":5720747}],"tv":5336.92}]}
{"op":"mcm","clk":"1005001141","pt":1580639942808,"mc":[{"id":"1.168135798","rc":[{"trd":[[2.7,81.65]],"batb":[[0,2.7,40.75]],"ltp":2.7,"tv":3475.85,"id":2249229}],"tv":5342.85}]}
{"op":"mcm","clk":"1005001598","pt":1580639947610,"mc":[{"id":"1.168135798","rc":[{"trd":[[1.52,150.02]],"batb":[[0,1.52,138.4]],"ltp":1.52,"tv":2013.42,"id":5720747}],"tv":5489.27}]}
{"op":"mcm","clk":"1005001906","pt":1580639950783,"mc":[{"id":"1.168135798","rc":[{"batb":[[1,2.36,128.55],[2,2.34,1260.29]],"ltp":2.7,"tv":3475.85,"id":2249229}]}]}
{"op":"mcm","clk":"1005001996","pt":1580639951780,"mc":[{"id":"1.168135798","rc":[{"trd":[[1.52,154.02]],"batb":[[0,1.52,136.4]],"ltp":1.52,"tv":2017.42,"id":5720747}],"tv":5493.27}]}
{"op":"mcm","clk":"1005002185","pt":1580639953686,"mc":[{"id":"1.168135798","rc":[{"batb":[[2,2.32,99.36]],"ltp":2.7,"tv":3475.85,"id":2249229}]}]}
{"op":"mcm","clk":"1005002487","pt":1580639956802,"mc":[{"id":"1.168135798","rc":[{"batl":[[2,1.78,401.05]],"ltp":1.52,"tv":2017.42,"id":5720747}]}]}
{"op":"mcm","clk":"1005002652","pt":1580639958785,"mc":[{"id":"1.168135798","rc":[{"trd":[[1.52,274.02]],"batb":[[0,1.52,76.4]],"ltp":1.52,"tv":2137.42,"id":5720747}],"tv":5613.27}]}
{"op":"mcm","clk":"1005002745","pt":1580639959792,"mc":[{"id":"1.168135798","rc":[{"trd":[[2.7,82.83]],"batb":[[0,2.7,39.57]],"ltp":2.7,"tv":3477.03,"id":2249229},{"trd":[[1.59,2]],"ltp":1.59,"tv":2139.42,"id":5720747}],"tv":5616.45}]}
{"op":"mcm","clk":"1005002817","pt":1580639960682,"mc":[{"id":"1.168135798","rc":[{"batb":[[0,1.53,329.87],[1,1.52,76.4],[2,1.51,98.03]],"ltp":1.59,"tv":2139.42,"id":5720747}]}]}
{"op":"mcm","clk":"1005002915","pt":1580639961800,"mc":[{"id":"1.168135798","rc":[{"trd":[[2.7,83.82]],"batb":[[0,2.7,38.58]],"ltp":2.7,"tv":3478.02,"id":2249229},{"trd":[[1.59,3.68]],"ltp":1.59,"tv":2141.1,"id":5720747}],"tv":5619.12}]}
{"op":"mcm","clk":"1005003027","pt":1580639962799,"mc":[{"id":"1.168135798","rc":[{"trd":[[2.7,160.97]],"batb":[[0,2.36,128.55],[1,2.32,99.36],[2,2.3,134.49]],"batl":[[0,3.9,2.65]],"ltp":2.7,"tv":3555.17,"id":2249229},{"batb":[[1,1.51,98.03],[2,1.5,501.31]],"ltp":1.59,"tv":2141.1,"id":5720747}],"tv":5696.27}]}
{"op":"mcm","clk":"1005003143","pt":1580639963793,"mc":[{"id":"1.168135798","rc":[{"trd":[[2.7,161.94]],"batl":[[0,3.9,1.68]],"ltp":2.7,"tv":3556.14,"id":2249229},{"trd":[[1.53,299.6],[1.58,1.65]],"batb":[[0,1.53,180.07]],"batl":[[0,1.68,120.16],[1,1.71,50],[2,1.72,208.37]],"ltp":1.53,"tv":2442.35,"id":5720747}],"tv":5998.49}]}
{"op":"mcm","clk":"1005003402","pt":1580639966736,"mc":[{"id":"1.168135798","rc":[{"batl":[[2,1.78,401.05]],"ltp":1.53,"tv":2442.35,"id":5720747}]}]}
{"op":"mcm","clk":"1005003669","pt":1580639969728,"mc":[{"id":"1.168135798","rc":[{"batb":[[0,2.76,83.04],[1,2.36,128.55],[2,2.32,99.36]],"ltp":2.7,"tv":3556.14,"id":2249229}]}]}
{"op":"mcm","clk":"1005003751","pt":1580639970726,"mc":[{"id":"1.168135798","rc":[{"batl":[[1,1.78,401.05],[2,1.8,541.09]],"ltp":1.53,"tv":2442.35,"id":5720747}]}]}
{"op":"mcm","clk":"1005003854","pt":1580639971820,"mc":[{"id":"1.168135798","rc":[{"batb":[[0,1.51,98.03],[1,1.5,501.31],[2,1.44,5.92]],"ltp":1.53,"tv":2442.35,"id":5720747}]}]}
{"op":"mcm","clk":"1005003938","pt":1580639972757,"mc":[{"id":"1.168135798","rc":[{"trd":[[2.76,8.11]],"batb":[[0,2.76,77.76]],"ltp":2.76,"tv":3561.42,"id":2249229},{"trd":[[1.57,9.29]],"ltp":1.57,"tv":2451.64,"id":5720747}],"tv":6013.06}]}
{"op":"mcm","clk":"1005004030","pt":1580639973748,"mc":[{"id":"1.168135798","rc":[{"batb":[[0,1.89,159.67],[1,1.3,24.25],[2,1.26,34.83]],"ltp":2.76,"tv":3561.42,"id":2249229}]}]}
{"op":"mcm","clk":"1005004126","pt":1580639974736,"mc":[{"id":"1.168135798","rc":[{"batb":[[0,1.3,24.25],[1,1.26,34.83],[2,1.14,9.24]],"ltp":2.76,"tv":3561.42,"id":2249229},{"batb":[[0,1.66,258.42],[1,1.52,180.07],[2,1.51,98.03]],"ltp":1.57,"tv":2451.64,"id":5720747}]}]}
{"op":"mcm","clk":"1005004202","pt":1580639975729,"mc":[{"id":"1.168135798","rc":[{"batb":[[0,1.71,581.25],[1,1.69,662.18],[2,1.66,258.42]],"batl":[[0,1.78,411.42],[1,1.8,541.13]],"ltp":1.57,"tv":2451.64,"id":5720747}]}]}
{"op":"mcm","clk":"1005004294","pt":1580639976718,"mc":[{"id":"1.168135798","rc":[{"batb":[[0,1.71,481.11]],"ltp":1.57,"tv":2451.64,"id":5720747}]}]}
{"op":"mcm","clk":"1005004381","pt":1580639977716,"mc":[{"id":"1.168135798","rc":[{"batl":[[0,2.7,21.2],[1,3.9,1.68]],"ltp":2.76,"tv":3561.42,"id":2249229},{"batl":[[2,1.83,110.31]],"ltp":1.57,"tv":2451.64,"id":5720747}]}]}
{"op":"mcm","clk":"1005004481","pt":1580639978756,"mc":[{"id":"1.168135798","rc":[{"batb":[[0,1.74,175.41],[1,1.3,24.25],[2,1.26,34.83]],"ltp":2.76,"tv":3561.42,"id":2249229}]}]}
{"op":"mcm","clk":"1005004664","pt":1580639980748,"mc":[{"id":"1.168135798","rc":[{"batb":[[2,1.52,687.56]],"batl":[[0,1.76,114.7],[1,1.78,508.18],[2,1.8,541.13]],"ltp":1.57,"tv":2451.64,"id":5720747}]}]}
{"op":"mcm","clk":"1005004742","pt":1580639981633,"mc":[{"id":"1.168135798","rc":[{"trd":[[2.42,88.69]],"ltp":2.42,"tv":3650.11,"id":2249229},{"trd":[[1.71,125.5]],"batb":[[0,1.71,355.61]],"ltp":1.71,"tv":2577.14,"id":5720747}],"tv":6227.25}]}
{"op":"mcm","clk":"1005004828","pt":1580639982734,"mc":[{"id":"1.168135798","rc":[{"batb":[[2,1.59,296.32]],"ltp":1.71,"tv":2577.14,"id":5720747}]}]}
{"op":"mcm","clk":"1005005023","pt":1580639984765,"mc":[{"id":"1.168135798","rc":[{"batb":[[0,2,174.83],[1,1.74,175.41],[2,1.3,24.25]],"ltp":2.42,"tv":3650.11,"id":2249229},{"batb":[[2,1.6,104.18]],"ltp":1.71,"tv":2577.14,"id":5720747}]}]}
{"op":"mcm","clk":"1005005122","pt":1580639985757,"mc":[{"id":"1.168135798","rc":[{"batb":[[0,1.71,444.78]],"ltp":1.71,"tv":2577.14,"id":5720747}]}]}
{"op":"mcm","clk":"1005005314","pt":1580639987745,"mc":[{"id":"1.168135798","rc":[{"batb":[[0,1.6,104.18],[1,1.59,296.32],[2,1.52,687.56]],"batl":[[1,1.83,110.31],[2,1.8,0]],"ltp":1.71,"tv":2577.14,"id":5720747}]}]}
{"op":"mcm","clk":"1005005627","pt":1580639990777,"mc":[{"id":"1.168135798","rc":[{"batb":[[0,1.61,286.61],[1,1.6,104.18],[2,1.59,296.32]],"batl":[[0,1.83,110.31],[1,1.83,0]],"ltp":1.71,"tv":2577.14,"id":5720747}]}]}
{"op":"mcm","clk":"1005005828","pt":1580639992763,"mc":[{"id":"1.168135798","rc":[{"batb":[[1,1.59,296.32],[2,1.52,687.56]],"batl":[[0,1.74,7.57],[1,1.83,110.31]],"ltp":1.71,"tv":2577.14,"id":5720747}]}]}
{"op":"mcm","clk":"1005005932","pt":1580639993762,"mc":[{"id":"1.168135798","rc":[{"trd":[[2.34,5.63]],"batl":[[0,2.3,32.23],[1,2.7,21.2],[2,3.9,1.68]],"ltp":2.34,"tv":3655.74,"id":2249229},{"trd":[[1.74,17.57]],"batb":[[2,1.58,645.4]],"batl":[[0,1.83,110.31],[1,2.06,545.1],[2,2.08,349.04]],"ltp":1.74,"tv":2584.71,"id":5720747}],"tv":6240.45}]}
{"op":"mcm","clk":"1005006208","pt":1580639996682,"mc":[{"id":"1.168135798","rc":[{"batb":[[0,1.74,175.41],[1,1.3,24.25],[2,1.26,34.83]],"batl":[[0,2.7,21.2],[1,3.9,1.68],[2,3.9,0]],"ltp":2.34,"tv":3655.74,"id":2249229}]}]}
{"op":"mcm","clk":"1005006317","pt":1580639997781,"mc":[{"id":"1.168135798","rc":[{"batb":[[2,1.52,687.56]],"ltp":1.74,"tv":2584.71,"id":5720747}]}]}
{"op":"mcm","clk":"1005006423","pt":1580639998768,"mc":[{"id":"1.168135798","rc":[{"batb":[[0,1.97,180.24],[1,1.95,184.03],[2,1.74,175.41]],"ltp":2.34,"tv":3655.74,"id":2249229}]}]}
{"op":"mcm","clk":"1005006540","pt":1580639999757,"mc":[{"id":"1.168135798","rc":[{"batb":[[0,1.74,175.41],[1,1.3,24.25],[2,1.26,34.83]],"ltp":2.34,"tv":3655.74,"id":2249229}]}]}
{"op":"mcm","clk":"1005006647","pt":1580640000755,"mc":[{"id":"1.168135798","rc":[{"batb":[[0,1.3,24.25],[1,1.26,34.83],[2,1.14,9.24]],"ltp":2.34,"tv":3655.74,"id":2249229},{"batb":[[0,1.86,115.27],[1,1.61,286.61],[2,1.59,296.32]],"ltp":1.74,"tv":2584.71,"id":5720747}]}]}
{"op":"mcm","clk":"1005006747","pt":1580640001791,"mc":[{"id":"1.168135798","rc":[{"batl":[[0,2.2,22.17],[1,2.7,21.2],[2,3.9,1.68]],"ltp":2.34,"tv":3655.74,"id":2249229},{"batb":[[1,1.76,4.2],[2,1.7,71.42]],"ltp":1.74,"tv":2584.71,"id":5720747}]}]}
{"op":"mcm","clk":"1005006837","pt":1580640002791,"mc":[{"id":"1.168135798","rc":[{"batb":[[0,1.95,437.37],[1,1.93,428.1],[2,1.3,24.25]],"batl":[[0,2.04,362.04],[1,2.06,358.88],[2,2.2,22.17]],"ltp":2.34,"tv":3655.74,"id":2249229}]}]}
{"op":"mcm","clk":"1005006991","pt":1580640004675,"mc":[{"id":"1.168135798","rc":[{"batb":[[2,1.3,22.73]],"ltp":2.34,"tv":3655.74,"id":2249229}]}]}
{"op":"mcm","clk":"1005007091","pt":1580640005779,"mc":[{"id":"1.168135798","rc":[{"batb":[[2,1.62,162.47]],"ltp":2.34,"tv":3655.74,"id":2249229},{"batb":[[2,1.62,668.38]],"ltp":1.74,"tv":2584.71,"id":5720747}]}]}
{"op":"mcm","clk":"1005007181","pt":1580640006770,"mc":[{"id":"1.168135798","rc":[{"batb":[[0,1.76,4.2],[1,1.62,668.38],[2,1.61,286.61]],"ltp":1.74,"tv":2584.71,"id":5720747}]}]}
{"op":"mcm","clk":"1005007278","pt":1580640007765,"mc":[{"id":"1.168135798","rc":[{"batb":[[0,1.75,233.11],[1,1.62,162.47],[2,1.3,22.73]],"batl":[[0,2.7,21.2],[1,3.9,1.68],[2,2.2,0]],"ltp":2.34,"tv":3655.74,"id":2249229},{"batb":[[2,1.44,5.92]],"batl":[[0,2.02,82.34]],"ltp":1.74,"tv":2584.71,"id":5720747}]}]}
{"op":"mcm","clk":"1005007441","pt":1580640009796,"mc":[{"id":"1.168135798","rc":[{"trd":[[2.02,3.38]],"batl":[[0,2.02,80.65]],"ltp":2.02,"tv":2588.08,"id":5720747}],"tv":6243.83}]}
{"op":"mcm","clk":"1005007537","pt":1580640010801,"mc":[{"id":"1.168135798","rc":[{"trd":[[1.98,22.17]],"ltp":1.98,"tv":3677.91,"id":2249229},{"trd":[[2.02,25.1]],"batb":[[0,1.87,200.96],[1,1.76,4.2]],"batl":[[0,2.02,58.92],[1,2.06,359.11],[2,2.24,82.34]],"ltp":2.02,"tv":2609.81,"id":5720747}],"tv":6287.72}]}
{"op":"mcm","clk":"1005007620","pt":1580640011691,"mc":[{"id":"1.168135798","rc":[{"batb":[[1,1.81,215.84],[2,1.76,4.2]],"ltp":2.02,"tv":2609.81,"id":5720747}]}]}
{"op":"mcm","clk":"1005007723","pt":1580640012787,"mc":[{"id":"1.168135798","rc":[{"batb":[[2,1.77,82.34]],"ltp":2.02,"tv":2609.81,"id":5720747}]}]}
{"op":"mcm","clk":"1005007809","pt":1580640013778,"mc":[{"id":"1.168135798","rc":[{"batb":[[0,1.95,455.42],[1,1.93,428.26],[2,1.81,215.84]],"batl":[[1,2.04,345.69]],"ltp":2.02,"tv":2609.81,"id":5720747}]}]}
{"op":"mcm","clk":"1005007897","pt":1580640014778,"mc":[{"id":"1.168135798","rc":[{"batb":[[0,1.81,215.84],[1,1.77,82.34],[2,1.76,4.2]],"batl":[[1,2.24,82.34],[2,2.24,0]],"ltp":2.02,"tv":2609.81,"id":5720747}]}]}
{"op":"mcm","clk":"1005008115","pt":1580640016778,"mc":[{"id":"1.168135798","rc":[{"batb":[[0,1.88,82.34],[1,1.81,215.84],[2,1.77,643.2]],"batl":[[2,2.46,410.32]],"ltp":2.02,"tv":2609.81,"id":5720747}]}]}
{"op":"mcm","clk":"1005008200","pt":1580640017704,"mc":[{"id":"1.168135798","rc":[{"batb":[[0,1.81,215.84],[1,1.77,560.86],[2,1.76,4.2]],"ltp":2.02,"tv":2609.81,"id":5720747}]}]}
{"op":"mcm","clk":"1005008300","pt":1580640018797,"mc":[{"id":"1.168135798","rc":[{"batb":[[0,1.62,162.47],[1,1.3,22.73],[2,1.26,34.83]],"ltp":1.98,"tv":3677.91,"id":2249229}]}]}
{"op":"mcm","clk":"1005008388","pt":1580640019792,"mc":[{"id":"1.168135798","rc":[{"batl":[[1,2.46,410.32],[2,2.5,423.77]],"ltp":2.02,"tv":2609.81,"id":5720747}]}]}
{"op":"mcm","clk":"1005008487","pt":1580640020786,"mc":[{"id":"1.168135798","rc":[{"batb":[[1,1.78,224.14],[2,1.77,560.86]],"ltp":2.02,"tv":2609.81,"id":5720747}]}]}
{"op":"mcm","clk":"1005008582","pt":1580640021791,"mc":[{"id":"1.168135798","rc":[{"trd":[[1.98,24.44]],"ltp":1.98,"tv":3680.18,"id":2249229},{"trd":[[2.02,27.33]],"batl":[[0,2.02,56.7]],"ltp":2.02,"tv":2612.04,"id":5720747}],"tv":6292.22}]}
{"op":"mcm","clk":"1005008681","pt":1580640022800,"mc":[{"id":"1.168135798","rc":[{"batb":[[0,1.7,249.76],[1,1.62,162.47],[2,1.3,22.73]],"ltp":1.98,"tv":3680.18,"id":2249229}]}]}
{"op":"mcm","clk":"1005008789","pt":1580640023797,"mc":[{"id":"1.168135798","rc":[{"batb":[[1,1.69,253.38],[2,1.62,162.47]],"ltp":1.98,"tv":3680.18,"id":2249229}]}]}
{"op":"mcm","clk":"1005008878","pt":1580640024790,"mc":[{"id":"1.168135798","rc":[{"trd":[[1.98,63.45]],"ltp":1.98,"tv":3719.19,"id":2249229},{"trd":[[2.02,65.57]],"batl":[[0,2.02,18.46]],"ltp":2.02,"tv":2650.28,"id":5720747}],"tv":6369.47}]}
{"op":"mcm","clk":"1005009085","pt":1580640026725,"mc":[{"id":"1.168135798","rc":[{"batb":[[0,1.98,3.5],[1,1.81,215.84],[2,1.78,224.14]],"ltp":2.02,"tv":2650.28,"id":5720747}]}]}
{"op":"mcm","clk":"1005009516","pt":1580640030722,"mc":[{"id":"1.168135798","rc":[{"batl":[[1,2.46,0],[2,2.5,0]],"ltp":2.02,"tv":2650.28,"id":5720747}]}]}
{"op":"mcm","clk":"1005009609","pt":1580640031713,"mc":[{"id":"1.168135798","rc":[{"batb":[[2,1.3,22.73]],"ltp":1.98,"tv":3719.19,"id":2249229}]}]}
{"op":"mcm","clk":"1005009921","pt":1580640034820,"mc":[{"id":"1.168135798","rc":[{"trd":[[1.98,82.28]],"batl":[[0,1.98,56.89],[1,2.7,21.2],[2,3.9,1.68]],"ltp":1.98,"tv":3738.02,"id":2249229},{"trd":[[2.02,84.03]],"ltp":2.02,"tv":2668.73,"id":5720747}],"tv":6406.76}]}
{"op":"mcm","clk":"1005010370","pt":1580640039631,"mc":[{"id":"1.168135798","rc":[{"trd":[[1.98,100.23]],"batl":[[0,1.98,38.94]],"ltp":1.98,"tv":3755.97,"id":2249229},{"trd":[[2.02,101.62]],"batb":[[1,1.78,224.14],[2,1.76,4.2]],"ltp":2.02,"tv":2686.33,"id":5720747}],"tv":6442.3}]}
{"op":"mcm","clk":"1005010458","pt":1580640040635,"mc":[{"id":"1.168135798","rc":[{"batb":[[2,1.44,5.92]],"ltp":2.02,"tv":2686.33,"id":5720747}]}]}
{"op":"mcm","clk":"1005010617","pt":1580640042726,"mc":[{"id":"1.168135798","rc":[{"batb":[[0,1.9,379.37],[1,1.88,465],[2,1.7,249.76]],"batl":[[0,1.98,374.11],[1,2,391.54],[2,2.7,21.2]],"ltp":1.98,"tv":3755.97,"id":2249229}]}]}
{"op":"mcm","clk":"1005010719","pt":1580640043719,"mc":[{"id":"1.168135798","rc":[{"batb":[[0,1.3,22.73],[1,1.26,34.83],[2,1.14,9.24]],"batl":[[0,1.98,38.94],[1,2.7,21.2],[2,3.9,1.68]],"ltp":1.98,"tv":3755.97,"id":2249229}]}]}
{"op":"mcm","clk":"1005010891","pt":1580640045732,"mc":[{"id":"1.168135798","rc":[{"trd":[[1.98,102.56]],"batl":[[0,1.98,36.61]],"ltp":1.98,"tv":3758.3,"id":2249229},{"trd":[[2.02,103.91]],"ltp":2.02,"tv":2688.61,"id":5720747}],"tv":6446.92}]}
{"op":"mcm","clk":"1005011037","pt":1580640047719,"mc":[{"id":"1.168135798","rc":[{"batb":[[0,1.78,82.34],[1,1.7,249.76],[2,1.3,22.73]],"ltp":1.98,"tv":3758.3,"id":2249229}]}]}
{"op":"mcm","clk":"1005011109","pt":1580640048642,"mc":[{"id":"1.168135798","rc":[{"batb":[[2,1.69,661.95]],"batl":[[1,2.3,460.46],[2,2.32,257.44]],"ltp":1.98,"tv":3758.3,"id":2249229}]}]}
{"op":"mcm","clk":"1005011321","pt":1580640050741,"mc":[{"id":"1.168135798","rc":[{"batb":[[1,1.79,221.3],[2,1.78,224.14]],"ltp":2.02,"tv":2688.61,"id":5720747}]}]}
{"op":"mcm","clk":"1005011475","pt":1580640052647,"mc":[{"id":"1.168135798","rc":[{"batb":[[1,1.72,82.34],[2,1.7,249.76]],"ltp":1.98,"tv":3758.3,"id":2249229}]}]}
{"op":"mcm","clk":"1005011719","pt":1580640055727,"mc":[{"id":"1.168135798","rc":[{"batl":[[0,2.7,21.2],[1,3.9,1.68],[2,2.32,0]],"ltp":1.98,"tv":3758.3,"id":2249229}]}]}
{"op":"mcm","clk":"1005011898","pt":1580640057654,"mc":[{"id":"1.168135798","rc":[{"batb":[[1,1.44,5.92],[2,1.4,6.49]],"batl":[[0,2.02,22.72]],"ltp":2.02,"tv":2688.61,"id":5720747}]}]}
{"op":"mcm","clk":"1005012038","pt":1580640058749,"mc":[{"id":"1.168135798","rc":[{"trd":[[1.98,7]],"batb":[[0,1.77,573.98],[1,1.75,588.74],[2,1.44,5.92]],"batl":[[0,1.85,489.24],[1,1.87,480.64],[2,1.88,95.64]],"ltp":1.98,"tv":2695.62,"id":5720747}],"tv":6453.92}]}
{"op":"mcm","clk":"1005012196","pt":1580640060664,"mc":[{"id":"1.168135798","rc":[{"batb":[[0,1.7,249.76],[1,1.69,253.38],[2,1.3,22.73]],"ltp":1.98,"tv":3758.3,"id":2249229},{"batl":[[2,2.02,22.72]],"ltp":1.98,"tv":2695.62,"id":5720747}]}]}
{"op":"mcm","clk":"1005012300","pt":1580640061653,"mc":[{"id":"1.168135798","rc":[{"batl":[[2,2.02,0]],"ltp":1.98,"tv":2695.62,"id":5720747}]}]}
{"op":"mcm","clk":"1005012394","pt":1580640062766,"mc":[{"id":"1.168135798","rc":[{"batb":[[2,1.68,170]],"ltp":1.98,"tv":3758.3,"id":2249229},{"batb":[[2,1.56,683.84]],"ltp":1.98,"tv":2695.62,"id":5720747}]}]}
{"op":"mcm","clk":"1005012492","pt":1580640063785,"mc":[{"id":"1.168135798","rc":[{"batb":[[0,1.68,170],[1,1.3,22.73],[2,1.26,34.83]],"ltp":1.98,"tv":3758.3,"id":2249229},{"trd":[[1.85,117.62]],"batl":[[0,1.85,448.52]],"ltp":1.85,"tv":2777.05,"id":5720747}],"tv":6535.36}]}
{"op":"mcm","clk":"1005012585","pt":1580640064734,"mc":[{"id":"1.168135798","rc":[{"batb":[[2,1.62,281.99]],"batl":[[2,1.97,22.72]],"ltp":1.85,"tv":2777.05,"id":5720747}]}]}
{"op":"mcm","clk":"1005012734","pt":1580640066778,"mc":[{"id":"1.168135798","rc":[{"batb":[[0,1.9,194.26],[1,1.68,170],[2,1.3,22.73]],"ltp":1.98,"tv":3758.3,"id":2249229}]}]}
{"op":"mcm","clk":"1005012951","pt":1580640068806,"mc":[{"id":"1.168135798","rc":[{"trd":[[2.16,31.02]],"ltp":2.16,"tv":3758.33,"id":2249229},{"trd":[[1.85,117.66]],"batl":[[0,1.85,448.48]],"ltp":1.85,"tv":2777.09,"id":5720747}],"tv":6535.43}]}
{"op":"mcm","clk":"1005013018","pt":1580640069670,"mc":[{"id":"1.168135798","rc":[{"batb":[[2,1.47,1125.69]],"ltp":2.16,"tv":3758.33,"id":2249229}]}]}
{"op":"mcm","clk":"1005013114","pt":1580640070767,"mc":[{"id":"1.168135798","rc":[{"batl":[[2,1.97,0]],"ltp":1.85,"tv":2777.09,"id":5720747}]}]}
{"op":"mcm","clk":"1005013196","pt":1580640071775,"mc":[{"id":"1.168135798","rc":[{"trd":[[2.16,38.41]],"batl":[[0,2.16,50],[1,2.7,21.2],[2,3.9,1.68]],"ltp":2.16,"tv":3765.72,"id":2249229},{"trd":[[1.85,126.29]],"batb":[[0,1.62,281.99],[1,1.56,683.84],[2,1.5,5.19]],"ltp":1.85,"tv":2785.72,"id":5720747}],"tv":6551.45}]}
{"op":"mcm","clk":"1005013430","pt":1580640074792,"mc":[{"id":"1.168135798","rc":[{"batl":[[0,2.16,95.43]],"ltp":2.16,"tv":3765.72,"id":2249229},{"batb":[[1,1.6,762.77],[2,1.59,417.28]],"batl":[[0,2.24,265.99],[1,2.26,275.87]],"ltp":1.85,"tv":2785.72,"id":5720747}]}]}
{"op":"mcm","clk":"1005013763","pt":1580640077694,"mc":[{"id":"1.168135798","rc":[{"trd":[[2.16,44.93]],"batb":[[0,1.68,170],[1,1.47,1125.69],[2,1.3,22.73]],"batl":[[0,2.16,38.91]],"ltp":2.16,"tv":3772.24,"id":2249229},{"trd":[[1.86,7.57]],"ltp":1.86,"tv":2793.29,"id":5720747}],"tv":6565.54}]}
{"op":"mcm","clk":"1005013837","pt":1580640078802,"mc":[{"id":"1.168135798","rc":[{"batb":[[1,1.61,286.61],[2,1.6,762.77]],"ltp":1.86,"tv":2793.29,"id":5720747}]}]}
{"op":"mcm","clk":"1005013895","pt":1580640079696,"mc":[{"id":"1.168135798","rc":[{"batb":[[0,1.81,215.84],[1,1.68,170],[2,1.47,1125.69]],"ltp":2.16,"tv":3772.24,"id":2249229}]}]}
{"op":"mcm","clk":"1005013994","pt":1580640080792,"mc":[{"id":"1.168135798","rc":[{"batb":[[0,1.83,210.64],[1,1.81,215.84],[2,1.68,170]],"ltp":2.16,"tv":3772.24,"id":2249229}]}]}
{"op":"mcm","clk":"1005014280","pt":1580640083772,"mc":[{"id":"1.168135798","rc":[{"batl":[[0,2.7,21.2],[1,3.9,1.68],[2,3.9,0]],"ltp":2.16,"tv":3772.24,"id":2249229}]}]}
{"op":"mcm","clk":"1005014555","pt":1580640086791,"mc":[{"id":"1.168135798","rc":[{"batl":[[0,3.9,1.68],[1,3.9,0]],"ltp":2.16,"tv":3772.24,"id":2249229}]}]}
{"op":"mcm","clk":"1005014738","pt":1580640088785,"mc":[{"id":"1.168135798","rc":[{"batb":[[2,1.47,1125.69]],"ltp":2.16,"tv":3772.24,"id":2249229},{"batb":[[0,1.6,762.77],[1,1.59,417.28],[2,1.5,5.19]],"batl":[[0,1.67,686.79],[1,1.69,667.23],[2,1.71,99.14]],"ltp":1.86,"tv":2793.29,"id":5720747}]}]}
{"op":"mcm","clk":"1005014830","pt":1580640089786,"mc":[{"id":"1.168135798","rc":[{"trd":[[1.67,0.62]],"batl":[[0,1.67,346.3],[1,1.71,99.14],[2,1.71,0]],"ltp":1.67,"tv":2793.92,"id":5720747}],"tv":6566.16}]}
{"op":"mcm","clk":"1005014934","pt":1580640090790,"mc":[{"id":"1.168135798","rc":[{"batb":[[0,1.6,406.12],[1,1.5,5.19],[2,1.44,5.92]],"batl":[[0,1.66,347.05],[1,1.67,346.3],[2,1.71,99.14]],"ltp":1.67,"tv":2793.92,"id":5720747}]}]}
{"op":"mcm","clk":"1005015023","pt":1580640091786,"mc":[{"id":"1.168135798","rc":[{"batl":[[0,1.67,346.3],[1,1.71,99.14],[2,1.71,0]],"ltp":1.67,"tv":2793.92,"id":5720747}]}]}
{"op":"mcm","clk":"1005015101","pt":1580640092715,"mc":[{"id":"1.168135798","rc":[{"batb":[[0,1.85,187.98],[1,1.83,210.64],[2,1.81,215.84]],"ltp":2.16,"tv":3772.24,"id":2249229},{"batb":[[2,1.44,721.96]],"ltp":1.67,"tv":2793.92,"id":5720747}]}]}
{"op":"mcm","clk":"1005015211","pt":1580640093814,"mc":[{"id":"1.168135798","rc":[{"batb":[[1,1.47,1125.69],[2,1.3,22.73]],"ltp":2.16,"tv":3772.24,"id":2249229}]}]}
{"op":"mcm","clk":"1005015296","pt":1580640094795,"mc":[{"id":"1.168135798","rc":[{"trd":[[2.48,7.57]],"ltp":2.48,"tv":3779.81,"id":2249229},{"trd":[[1.67,11.87]],"batb":[[1,1.5,354.85]],"batl":[[0,1.67,335.05],[1,1.71,0]],"ltp":1.67,"tv":2805.17,"id":5720747}],"tv":6584.98}]}
{"op":"mcm","clk":"1005015388","pt":1580640095786,"mc":[{"id":"1.168135798","rc":[{"batb":[[0,1.61,393.65],[1,1.6,406.12],[2,1.5,354.85]],"batl":[[0,1.67,640.39],[1,1.69,667.24]],"ltp":1.67,"tv":2805.17,"id":5720747}]}]}
{"op":"mcm","clk":"1005015485","pt":1580640096820,"mc":[{"id":"1.168135798","rc":[{"batb":[[0,2.1,158.94],[1,1.85,187.98],[2,1.47,1125.69]],"ltp":2.48,"tv":3779.81,"id":2249229},{"trd":[[1.67,15.25]],"batl":[[0,1.67,638.7]],"ltp":1.67,"tv":2808.54,"id":5720747}],"tv":6588.36}]}
{"op":"mcm","clk":"1005015957","pt":1580640101731,"mc":[{"id":"1.168135798","rc":[{"trd":[[2.48,57.57]],"ltp":2.48,"tv":3829.81,"id":2249229},{"trd":[[1.67,89.5]],"batb":[[0,1.5,354.85],[1,1.44,721.96],[2,1.4,6.49]],"ltp":1.67,"tv":2882.79,"id":5720747}],"tv":6712.61}]}
{"op":"mcm","clk":"1005016143","pt":1580640103729,"mc":[{"id":"1.168135798","rc":[{"batl":[[0,2.48,5],[1,3.9,1.68]],"ltp":2.48,"tv":3829.81,"id":2249229}]}]}
{"op":"mcm","clk":"1005016326","pt":1580640105720,"mc":[{"id":"1.168135798","rc":[{"batl":[[0,2.48,8]],"ltp":2.48,"tv":3829.81,"id":2249229}]}]}
{"op":"mcm","clk":"1005016428","pt":1580640106710,"mc":[{"id":"1.168135798","rc":[{"batb":[[1,1.47,547.54],[2,1.46,584.03]],"batl":[[0,1.99,461.73],[1,2.02,573.23]],"ltp":1.67,"tv":2882.79,"id":5720747}]}]}
{"op":"mcm","clk":"1005016638","pt":1580640108743,"mc":[{"id":"1.168135798","rc":[{"trd":[[2.48,65.74]],"batl":[[0,3.9,1.68],[1,3.9,0]],"ltp":2.48,"tv":3837.98,"id":2249229},{"trd":[[1.67,101.13]],"batl":[[0,1.61,114.91],[1,1.99,461.73],[2,2.02,573.23]],"ltp":1.67,"tv":2894.42,"id":5720747}],"tv":6732.41}]}
{"op":"mcm","clk":"1005016726","pt":1580640109638,"mc":[{"id":"1.168135798","rc":[{"batb":[[0,2.68,16.15],[1,2.1,158.94],[2,1.85,187.98]],"ltp":2.48,"tv":3837.98,"id":2249229}]}]}
{"op":"mcm","clk":"1005016937","pt":1580640111741,"mc":[{"id":"1.168135798","rc":[{"batb":[[2,2.02,171.4]],"ltp":2.48,"tv":3837.98,"id":2249229}]}]}
{"op":"mcm","clk":"1005017042","pt":1580640112729,"mc":[{"id":"1.168135798","rc":[{"batb":[[2,2.04,168.11]],"ltp":2.48,"tv":3837.98,"id":2249229}]}]}
{"op":"mcm","clk":"1005017145","pt":1580640113729,"mc":[{"id":"1.168135798","rc":[{"batb":[[1,1.48,364.25],[2,1.47,547.52]],"ltp":1.67,"tv":2894.42,"id":5720747}]}]}
{"op":"mcm","clk":"1005017331","pt":1580640115547,"mc":[{"id":"1.168135798","rc":[{"trd":[[2.68,28.77]],"batb":[[0,2.68,1.76]],"ltp":2.68,"tv":3866.76,"id":2249229},{"batl":[[1,1.67,3.79],[2,1.99,461.73]],"ltp":1.67,"tv":2894.42,"id":5720747}],"tv":6761.18}]}
{"op":"mcm","clk":"1005017432","pt":1580640116720,"mc":[{"id":"1.168135798","rc":[{"batb":[[0,2.1,158.94],[1,2.04,168.11],[2,2.02,171.4]],"ltp":2.68,"tv":3866.76,"id":2249229}]}]}
{"op":"mcm","clk":"1005017710","pt":1580640118753,"mc":[{"id":"1.168135798","rc":[{"batl":[[1,1.67,8.13]],"ltp":1.67,"tv":2894.42,"id":5720747}]}]}
{"op":"mcm","clk":"1005017890","pt":1580640119750,"mc":[{"id":"1.168135798","rc":[{"batl":[[0,2.68,21.2],[1,3.9,1.68]],"ltp":2.68,"tv":3866.76,"id":2249229}]}]}
{"op":"mcm","clk":"1005018125","pt":1580640121748,"mc":[{"id":"1.168135798","rc":[{"trd":[[2.62,8.4]],"ltp":2.62,"tv":3875.16,"id":2249229},{"trd":[[1.61,13.67]],"batl":[[0,1.61,101.24]],"ltp":1.61,"tv":2908.09,"id":5720747}],"tv":6783.26}]}
{"op":"mcm","clk":"1005018207","pt":1580640122547,"mc":[{"id":"1.168135798","rc":[{"batl":[[0,3.9,1.68],[1,3.9,0]],"ltp":2.62,"tv":3875.16,"id":2249229}]}]}
{"op":"mcm","clk":"1005018536","pt":1580640125654,"mc":[{"id":"1.168135798","rc":[{"batl":[[1,1.99,461.73],[2,2.02,573.23]],"ltp":1.61,"tv":2908.09,"id":5720747}]}]}
{"op":"mcm","clk":"1005019090","pt":1580640130673,"mc":[{"id":"1.168135798","rc":[{"trd":[[2.62,37.18]],"ltp":2.62,"tv":3903.94,"id":2249229},{"trd":[[1.61,60.5]],"batl":[[0,1.61,54.41]],"ltp":1.61,"tv":2954.92,"id":5720747}],"tv":6858.86}]}
{"op":"mcm","clk":"1005019464","pt":1580640133662,"mc":[{"id":"1.168135798","rc":[{"trd":[[1.5,402.07]],"batb":[[0,1.5,351.82]],"ltp":1.5,"tv":2960.98,"id":5720747}],"tv":6864.92}]}
{"op":"mcm","clk":"1005019980","pt":1580640137246,"mc":[{"id":"1.168135798","rc":[{"trd":[[2.1,158.94]],"batb":[[0,2.04,168.11],[1,2.02,171.4],[2,1.85,187.98]],"ltp":2.1,"tv":4062.87,"id":2249229},{"trd":[[1.61,169.32],[1.91,174.74]],"batb":[[0,1.91,190.95],[1,1.5,351.82],[2,1.48,364.25]],"ltp":1.91,"tv":3244.54,"id":5720747}],"tv":7307.42}]}
{"op":"mcm","clk":"1005020152","pt":1580640138651,"mc":[{"id":"1.168135798","rc":[{"batb":[[0,1.5,2.16],[1,1.47,547.54],[2,1.46,584.03]],"ltp":1.91,"tv":3244.54,"id":5720747}]}]}
{"op":"mcm","clk":"1005020275","pt":1580640139770,"mc":[{"id":"1.168135798","rc":[{"batb":[[2,1.47,1125.69]],"ltp":2.1,"tv":4062.87,"id":2249229},{"trd":[[1.63,158.72],[1.79,840.19]],"batl":[[0,1.52,394.97],[1,1.53,473.84]],"ltp":1.63,"tv":4243.45,"id":5720747}],"tv":8306.33}]}
{"op":"mcm","clk":"1005020389","pt":1580640140670,"mc":[{"id":"1.168135798","rc":[{"batb":[[1,1.44,5.92],[2,1.4,6.49]],"ltp":1.63,"tv":4243.45,"id":5720747}]}]}
{"op":"mcm","clk":"1005020620","pt":1580640142760,"mc":[{"id":"1.168135798","rc":[{"batb":[[0,1.7,420.1],[1,1.5,2.16],[2,1.44,5.92]],"ltp":1.63,"tv":4243.45,"id":5720747}]}]}
{"op":"mcm","clk":"1005020891","pt":1580640144752,"mc":[{"id":"1.168135798","rc":[{"batb":[[1,1.62,420.1],[2,1.5,2.16]],"ltp":1.63,"tv":4243.45,"id":5720747}]}]}
{"op":"mcm","clk":"1005021018","pt":1580640145764,"mc":[{"id":"1.168135798","rc":[{"batb":[[1,1.67,420.1],[2,1.62,420.1]],"ltp":1.63,"tv":4243.45,"id":5720747}]}]}
{"op":"mcm","clk":"1005021143","pt":1580640146649,"mc":[{"id":"1.168135798","rc":[{"batb":[[0,1.47,1125.69],[1,1.3,22.73],[2,1.26,34.83]],"ltp":2.1,"tv":4062.87,"id":2249229},{"batb":[[0,1.99,89.19],[1,1.7,420.1],[2,1.67,420.1]],"ltp":1.63,"tv":4243.45,"id":5720747}]}]}
{"op":"mcm","clk":"1005021285","pt":1580640147752,"mc":[{"id":"1.168135798","rc":[{"batb":[[0,1.62,162.47],[1,1.47,1125.69],[2,1.3,22.73]],"ltp":2.1,"tv":4062.87,"id":2249229}]}]}
{"op":"mcm","clk":"1005021429","pt":1580640148793,"mc":[{"id":"1.168135798","rc":[{"trd":[[2.02,87.87],[2.4,33.54]],"batb":[[0,1.47,1125.69],[1,1.3,22.73],[2,1.26,34.83]],"ltp":2.4,"tv":4184.28,"id":2249229},{"trd":[[1.72,46.97],[1.99,89.19]],"batb":[[0,1.72,373.3]],"ltp":1.72,"tv":4379.44,"id":5720747}],"tv":8563.73}]}
{"op":"mcm","clk":"1005021705","pt":1580640150785,"mc":[{"id":"1.168135798","rc":[{"batl":[[0,1.97,65.66]],"ltp":1.72,"tv":4379.44,"id":5720747}]}]}
{"op":"mcm","clk":"1005021977","pt":1580640152780,"mc":[{"id":"1.168135798","rc":[{"batl":[[0,1.9,11.43],[1,1.91,7.26],[2,1.97,65.66]],"ltp":1.72,"tv":4379.44,"id":5720747}]}]}
{"op":"mcm","clk":"1005022096","pt":1580640153788,"mc":[{"id":"1.168135798","rc":[{"trd":[[1.9,22.86],[1.91,189.26]],"batb":[[0,1.92,298.09],[1,1.9,449.43],[2,1.72,373.3]],"batl":[[0,1.97,65.66],[1,2,352.78],[2,2.02,380.03]],"ltp":1.91,"tv":4416.82,"id":5720747}],"tv":8601.11}]}
{"op":"mcm","clk":"1005022238","pt":1580640154775,"mc":[{"id":"1.168135798","rc":[{"batb":[[2,1.76,336.23]],"batl":[[0,2,352.78],[1,2.02,380.03],[2,2.02,0]],"ltp":1.91,"tv":4416.82,"id":5720747}]}]}
{"op":"mcm","clk":"1005022463","pt":1580640156756,"mc":[{"id":"1.168135798","rc":[{"batb":[[0,1.73,50],[1,1.72,373.3],[2,1.7,420.1]],"ltp":1.91,"tv":4416.82,"id":5720747}]}]}
{"op":"mcm","clk":"1005022685","pt":1580640158792,"mc":[{"id":"1.168135798","rc":[{"trd":[[1.92,134.76]],"batb":[[0,1.98,231.49],[1,1.73,50],[2,1.72,373.3]],"batl":[[0,1.99,3.03]],"ltp":1.92,"tv":4551.58,"id":5720747}],"tv":8735.87}]}
{"op":"mcm","clk":"1005022798","pt":1580640159786,"mc":[{"id":"1.168135798","rc":[{"batl":[[0,1.99,633.08],[1,2.84,272.46],[2,2.88,294.65]],"ltp":1.92,"tv":4551.58,"id":5720747}]}]}
{"op":"mcm","clk":"1005023526","pt":1580640164780,"mc":[{"id":"1.168135798","rc":[{"batb":[[0,1.55,317.87],[1,1.47,1125.69],[2,1.3,22.73]],"batl":[[0,2.4,2.73],[1,3.9,1.68]],"ltp":2.4,"tv":4184.28,"id":2249229}]}]}
{"op":"mcm","clk":"1005023660","pt":1580640165783,"mc":[{"id":"1.168135798","rc":[{"batb":[[0,1.75,420.1],[1,1.74,420.1],[2,1.73,50]],"ltp":1.92,"tv":4551.58,"id":5720747}]}]}
{"op":"mcm","clk":"1005023829","pt":1580640166765,"mc":[{"id":"1.168135798","rc":[{"batb":[[2,1.72,373.3]],"ltp":1.92,"tv":4551.58,"id":5720747}]}]}
{"op":"mcm","clk":"1005023960","pt":1580640167803,"mc":[{"id":"1.168135798","rc":[{"batl":[[0,2.02,1.77],[1,2.4,2.73],[2,3.9,1.68]],"ltp":2.4,"tv":4184.28,"id":2249229}]}]}
{"op":"mcm","clk":"1005024084","pt":1580640168777,"mc":[{"id":"1.168135798","rc":[{"trd":[[1.99,553.89]],"batl":[[0,1.99,400.74]],"ltp":1.99,"tv":5016.28,"id":5720747}],"tv":9200.57}]}
{"op":"mcm","clk":"1005024229","pt":1580640169786,"mc":[{"id":"1.168135798","rc":[{"batl":[[1,3.9,1.68],[2,3.9,0]],"ltp":2.4,"tv":4184.28,"id":2249229}]}]}
{"op":"mcm","clk":"1005024823","pt":1580640173715,"mc":[{"id":"1.168135798","rc":[{"trd":[[2,37.81]],"ltp":2.0,"tv":4185.96,"id":2249229},{"trd":[[1.99,555.57]],"batl":[[0,1.99,399.05]],"ltp":1.99,"tv":5017.97,"id":5720747}],"tv":9203.94}]}
{"op":"mcm","clk":"1005025416","pt":1580640177714,"mc":[{"id":"1.168135798","rc":[{"trd":[[2.02,89.6]],"batl":[[0,3.9,1.72],[1,3.9,0]],"ltp":2.02,"tv":4187.7,"id":2249229},{"trd":[[1.98,8.77]],"batb":[[0,1.76,460.08],[1,1.75,420.1],[2,1.74,420.1]],"ltp":1.98,"tv":5019.74,"id":5720747}],"tv":9207.44}]}
{"op":"mcm","clk":"1005026276","pt":1580640183613,"mc":[{"id":"1.168135798","rc":[{"batl":[[0,3.4,2.04],[1,3.9,1.68]],"ltp":2.02,"tv":4187.7,"id":2249229},{"batb":[[1,1.63,367.63],[2,1.62,386.98]],"ltp":1.98,"tv":5019.74,"id":5720747}]}]}
{"op":"mcm","clk":"1005026422","pt":1580640184817,"mc":[{"id":"1.168135798","rc":[{"trd":[[2,47.81]],"batl":[[0,3.4,2]],"ltp":2.0,"tv":4197.7,"id":2249229},{"trd":[[1.99,565.62]],"batl":[[0,1.99,389],[1,2.84,0],[2,2.88,0]],"ltp":1.99,"tv":5029.79,"id":5720747}],"tv":9227.49}]}
{"op":"mcm","clk":"1005026562","pt":1580640185804,"mc":[{"id":"1.168135798","rc":[{"batb":[[0,1.63,367.63],[1,1.62,386.98],[2,1.61,32.26]],"batl":[[0,1.79,840.19],[1,1.99,389]],"ltp":1.99,"tv":5029.79,"id":5720747}]}]}
{"op":"mcm","clk":"1005026708","pt":1580640186818,"mc":[{"id":"1.168135798","rc":[{"batl":[[0,1.69,595.64],[1,1.71,639.88],[2,1.79,840.35]],"ltp":1.99,"tv":5029.79,"id":5720747}]}]}
{"op":"mcm","clk":"1005027308","pt":1580640190725,"mc":[{"id":"1.168135798","rc":[{"batb":[[0,1.85,275.35],[1,1.55,317.87],[2,1.47,1125.69]],"ltp":2.0,"tv":4197.7,"id":2249229}]}]}
{"op":"mcm","clk":"1005027436","pt":1580640191516,"mc":[{"id":"1.168135798","rc":[{"batb":[[1,1.47,1125.69],[2,1.3,22.73]],"ltp":2.0,"tv":4197.7,"id":2249229}]}]}
{"op":"mcm","clk":"1005028236","pt":1580640196805,"mc":[{"id":"1.168135798","rc":[{"batl":[[2,1.76,0.16]],"ltp":1.99,"tv":5029.79,"id":5720747}]}]}
{"op":"mcm","clk":"1005028798","pt":1580640199728,"mc":[{"id":"1.168135798","rc":[{"trd":[[2.44,32.74]],"batb":[[0,2.02,171.4],[1,1.85,275.35],[2,1.47,1125.69]],"ltp":2.44,"tv":4230.44,"id":2249229},{"trd":[[1.69,47.27]],"batb":[[0,1.61,32.26],[1,1.6,840.19],[2,1.54,840.19]],"batl":[[0,1.71,452.71],[1,1.76,0.16],[2,1.76,0]],"ltp":1.69,"tv":5077.06,"id":5720747}],"tv":9307.5}]}
{"op":"mcm","clk":"1005029244","pt":1580640202816,"mc":[{"id":"1.168135798","rc":[{"batb":[[1,1.54,840.19],[2,1.5,2.16]],"ltp":1.69,"tv":5077.06,"id":5720747}]}]}
{"op":"mcm","clk":"1005029386","pt":1580640203814,"mc":[{"id":"1.168135798","rc":[{"batb":[[1,1.55,50],[2,1.54,840.19]],"ltp":1.69,"tv":5077.06,"id":5720747}]}]}
{"op":"mcm","clk":"1005029520","pt":1580640204719,"mc":[{"id":"1.168135798","rc":[{"batb":[[1,1.9,194.26],[2,1.85,275.35]],"ltp":2.44,"tv":4230.44,"id":2249229},{"batb":[[0,1.55,50],[1,1.54,840.19],[2,1.5,2.16]],"ltp":1.69,"tv":5077.06,"id":5720747}]}]}
{"op":"mcm","clk":"1005029687","pt":1580640205802,"mc":[{"id":"1.168135798","rc":[{"batl":[[0,2.44,50],[1,3.4,2],[2,3.9,1.68]],"ltp":2.44,"tv":4230.44,"id":2249229},{"batl":[[1,2.02,449.58],[2,2.04,369.15]],"ltp":1.69,"tv":5077.06,"id":5720747}]}]}
{"op":"mcm","clk":"1005029858","pt":1580640206809,"mc":[{"id":"1.168135798","rc":[{"batb":[[0,1.9,194.26],[1,1.85,275.35],[2,1.47,1125.69]],"ltp":2.44,"tv":4230.44,"id":2249229},{"batb":[[2,1.51,840.19]],"ltp":1.69,"tv":5077.06,"id":5720747}]}]}
{"op":"mcm","clk":"1005030130","pt":1580640208808,"mc":[{"id":"1.168135798","rc":[{"batl":[[0,3.4,2],[1,3.9,1.68],[2,3.9,0]],"ltp":2.44,"tv":4230.44,"id":2249229}]}]}
{"op":"mcm","clk":"1005030233","pt":1580640209749,"mc":[{"id":"1.168135798","rc":[{"batb":[[0,1.85,275.35],[1,1.47,1125.69],[2,1.3,22.73]],"ltp":2.44,"tv":4230.44,"id":2249229}]}]}
{"op":"mcm","clk":"1005030389","pt":1580640210816,"mc":[{"id":"1.168135798","rc":[{"trd":[[2.82,1.19]],"ltp":2.82,"tv":4231.63,"id":2249229},{"trd":[[1.55,2.17]],"batb":[[0,1.55,47.83]],"ltp":1.55,"tv":5079.23,"id":5720747}],"tv":9310.86}]}
{"op":"mcm","clk":"1005030510","pt":1580640211809,"mc":[{"id":"1.168135798","rc":[{"batb":[[0,1.99,176.6]],"ltp":2.82,"tv":4231.63,"id":2249229},{"batl":[[0,1.61,5]],"ltp":1.55,"tv":5079.23,"id":5720747}]}]}
{"op":"mcm","clk":"1005030654","pt":1580640212820,"mc":[{"id":"1.168135798","rc":[{"trd":[[2.4,80.47],[2.62,40.25]],"batb":[[0,1.99,353.19]],"ltp":2.4,"tv":4281.63,"id":2249229},{"trd":[[1.61,174.32],[1.71,191.36]],"batl":[[0,1.69,392.19],[1,1.76,0.16],[2,2.04,0]],"ltp":1.71,"tv":5150.09,"id":5720747}],"tv":9431.73}]}
{"op":"mcm","clk":"1005030781","pt":1580640213719,"mc":[{"id":"1.168135798","rc":[{"batl":[[0,1.76,0.16],[1,1.76,0]],"ltp":1.71,"tv":5150.09,"id":5720747}]}]}
{"op":"mcm","clk":"1005030923","pt":1580640214721,"mc":[{"id":"1.168135798","rc":[{"batb":[[0,1.57,840.19],[1,1.56,840.19],[2,1.55,47.83]],"ltp":1.71,"tv":5150.09,"id":5720747}]}]}
{"op":"mcm","clk":"1005031059","pt":1580640215764,"mc":[{"id":"1.168135798","rc":[{"batb":[[0,1.71,30],[1,1.57,840.19],[2,1.56,840.19]],"ltp":1.71,"tv":5150.09,"id":5720747}]}]}
{"op":"mcm","clk":"1005031163","pt":1580640216730,"mc":[{"id":"1.168135798","rc":[{"batb":[[0,2,22.17],[1,1.99,353.19],[2,1.47,1125.69]],"ltp":2.4,"tv":4281.63,"id":2249229},{"trd":[[1.71,251.37]],"batb":[[0,1.57,840.19],[1,1.56,840.19],[2,1.54,840.19]],"batl":[[0,1.71,356.84],[1,1.76,0.16]],"ltp":1.71,"tv":5210.09,"id":5720747}],"tv":9491.73}]}
{"op":"mcm","clk":"1005031411","pt":1580640218769,"mc":[{"id":"1.168135798","rc":[{"batb":[[2,1.8,275.9]],"ltp":2.4,"tv":4281.63,"id":2249229}]}]}
{"op":"mcm","clk":"1005031987","pt":1580640222755,"mc":[{"id":"1.168135798","rc":[{"batl":[[1,2.02,461.91],[2,2.04,369.19]],"ltp":1.71,"tv":5210.09,"id":5720747}]}]}
{"op":"mcm","clk":"1005032119","pt":1580640223650,"mc":[{"id":"1.168135798","rc":[{"batb":[[2,1.47,1125.69]],"ltp":2.4,"tv":4281.63,"id":2249229}]}]}
{"op":"mcm","clk":"1005032418","pt":1580640225751,"mc":[{"id":"1.168135798","rc":[{"batb":[[0,1.5,2.16],[1,1.48,1344.93],[2,1.47,567.4]],"ltp":1.71,"tv":5210.09,"id":5720747}]}]}
{"op":"mcm","clk":"1005032849","pt":1580640228746,"mc":[{"id":"1.168135798","rc":[{"batl":[[0,1.57,840.19],[1,1.71,356.84],[2,1.76,0.16]],"ltp":1.71,"tv":5210.09,"id":5720747}]}]}
{"op":"mcm","clk":"1005032966","pt":1580640229774,"mc":[{"id":"1.168135798","rc":[{"trd":[[2.74,2]],"ltp":2.74,"tv":4283.63,"id":2249229},{"trd":[[1.57,12.78]],"batl":[[0,1.57,836.71],[1,1.63,840.19],[2,1.71,356.84]],"ltp":1.57,"tv":5213.58,"id":5720747}],"tv":9497.22}]}
{"op":"mcm","clk":"1005033238","pt":1580640231775,"mc":[{"id":"1.168135798","rc":[{"batb":[[1,1.48,763.33]],"batl":[[0,1.53,520.53],[1,1.54,462.34],[2,1.57,836.71]],"ltp":1.57,"tv":5213.58,"id":5720747}]}]}
{"op":"mcm","clk":"1005033343","pt":1580640232766,"mc":[{"id":"1.168135798","rc":[{"trd":[[2.88,6.29]],"ltp":2.88,"tv":4289.93,"id":2249229},{"trd":[[1.53,311.45]],"batb":[[1,1.49,50.01],[2,1.48,763.32]],"batl":[[0,1.53,406.9]],"ltp":1.53,"tv":5225.43,"id":5720747}],"tv":9515.36}]}
{"op":"mcm","clk":"1005033469","pt":1580640233668,"mc":[{"id":"1.168135798","rc":[{"batb":[[1,1.47,1125.69],[2,1.3,22.73]],"ltp":2.88,"tv":4289.93,"id":2249229}]}]}
{"op":"mcm","clk":"1005033616","pt":1580640234775,"mc":[{"id":"1.168135798","rc":[{"batb":[[0,2.78,98.22],[1,2,296.88],[2,1.47,1125.69]],"ltp":2.88,"tv":4289.93,"id":2249229}]}]}
{"op":"mcm","clk":"1005033733","pt":1580640235749,"mc":[{"id":"1.168135798","rc":[{"trd":[[1.53,383.71]],"batl":[[0,1.53,370.77]],"ltp":1.53,"tv":5297.69,"id":5720747}],"tv":9587.62}]}
{"op":"mcm","clk":"1005033868","pt":1580640236798,"mc":[{"id":"1.168135798","rc":[{"batb":[[0,2,296.88],[1,1.47,1125.69],[2,1.3,22.73]],"ltp":2.88,"tv":4289.93,"id":2249229},{"batb":[[2,1.48,872.2]],"ltp":1.53,"tv":5297.69,"id":5720747}]}]}
{"op":"mcm","clk":"1005034150","pt":1580640238770,"mc":[{"id":"1.168135798","rc":[{"batb":[[0,2.6,109.27],[1,2,296.88],[2,1.47,1125.69]],"ltp":2.88,"tv":4289.93,"id":2249229}]}]}
{"op":"mcm","clk":"1005034435","pt":1580640240752,"mc":[{"id":"1.168135798","rc":[{"batb":[[0,2,296.88],[1,1.47,1125.69],[2,1.3,22.73]],"ltp":2.88,"tv":4289.93,"id":2249229}]}]}
{"op":"mcm","clk":"1005035058","pt":1580640244781,"mc":[{"id":"1.168135798","rc":[{"batb":[[2,1.46,840.2]],"batl":[[0,1.57,836.71],[1,1.63,840.19],[2,1.71,356.84]],"ltp":1.53,"tv":5297.69,"id":5720747}]}]}
{"op":"mcm","clk":"1005035419","pt":1580640247813,"mc":[{"id":"1.168135798","rc":[{"batb":[[0,2,22.17]],"ltp":2.88,"tv":4289.93,"id":2249229},{"batb":[[0,1.5,84.5]],"ltp":1.53,"tv":5297.69,"id":5720747}]}]}
{"op":"mcm","clk":"1005035537","pt":1580640248792,"mc":[{"id":"1.168135798","rc":[{"batb":[[0,1.51,82.34],[1,1.5,84.5],[2,1.49,50.01]],"batl":[[0,1.76,0.16],[1,1.63,0],[2,1.71,0]],"ltp":1.53,"tv":5297.69,"id":5720747}]}]}
{"op":"mcm","clk":"1005035771","pt":1580640250778,"mc":[{"id":"1.168135798","rc":[{"batb":[[1,1.5,924.69]],"ltp":1.53,"tv":5297.69,"id":5720747}]}]}
{"op":"mcm","clk":"1005036027","pt":1580640252767,"mc":[{"id":"1.168135798","rc":[{"batb":[[2,1.46,840.21]],"batl":[[0,1.63,370.99],[1,1.76,0.16]],"ltp":1.53,"tv":5297.69,"id":5720747}]}]}
{"op":"mcm","clk":"1005036275","pt":1580640254797,"mc":[{"id":"1.168135798","rc":[{"batb":[[2,1.47,840.21]],"batl":[[1,1.69,82.34],[2,1.76,0.16]],"ltp":1.53,"tv":5297.69,"id":5720747}]}]}
{"op":"mcm","clk":"1005036391","pt":1580640255795,"mc":[{"id":"1.168135798","rc":[{"batb":[[1,1.5,84.5]],"batl":[[2,1.7,460.74]],"ltp":1.53,"tv":5297.69,"id":5720747}]}]}
{"op":"mcm","clk":"1005036614","pt":1580640257783,"mc":[{"id":"1.168135798","rc":[{"batl":[[0,1.62,82.34],[1,1.63,370.99],[2,1.69,82.34]],"ltp":1.53,"tv":5297.69,"id":5720747}]}]}
{"op":"mcm","clk":"1005036992","pt":1580640260817,"mc":[{"id":"1.168135798","rc":[{"batb":[[2,1.44,5.92]],"ltp":1.53,"tv":5297.69,"id":5720747}]}]}
{"op":"mcm","clk":"1005037098","pt":1580640261722,"mc":[{"id":"1.168135798","rc":[{"batb":[[0,1.5,2.16],[1,1.44,5.92],[2,1.4,990.64]],"ltp":1.53,"tv":5297.69,"id":5720747}]}]}
{"op":"mcm","clk":"1005037187","pt":1580640262570,"mc":[{"id":"1.168135798","rc":[{"trd":[[1.5,406.39]],"batb":[[0,1.44,5.92],[1,1.4,990.64],[2,1.39,725.89]],"batl":[[0,1.5,838.04],[1,1.62,82.34],[2,1.63,370.99]],"ltp":1.5,"tv":5302.01,"id":5720747}],"tv":9591.94}]}
{"op":"mcm","clk":"1005037446","pt":1580640264809,"mc":[{"id":"1.168135798","rc":[{"batb":[[0,2.44,121.41],[1,2,22.17],[2,1.47,1125.69]],"ltp":2.88,"tv":4289.93,"id":2249229},{"trd":[[1.48,0.02],[1.49,0.02]],"batb":[[0,1.44,5.9]],"batl":[[0,1.45,870.55],[1,1.46,566.86],[2,1.5,838.04]],"ltp":1.48,"tv":5302.05,"id":5720747}],"tv":9591.98}]}
{"op":"mcm","clk":"1005037580","pt":1580640265799,"mc":[{"id":"1.168135798","rc":[{"batb":[[0,2.44,242.82]],"ltp":2.88,"tv":4289.93,"id":2249229},{"trd":[[1.45,61.19]],"batl":[[0,1.45,839.95]],"ltp":1.45,"tv":5363.23,"id":5720747}],"tv":9653.17}]}
{"op":"mcm","clk":"1005037804","pt":1580640267727,"mc":[{"id":"1.168135798","rc":[{"batb":[[1,2.18,136.43],[2,2,22.17]],"ltp":2.88,"tv":4289.93,"id":2249229},{"trd":[[1.45,98.2]],"batl":[[0,1.45,821.44],[2,1.76,0.16]],"ltp":1.45,"tv":5400.25,"id":5720747}],"tv":9690.18}]}
{"op":"mcm","clk":"1005037911","pt":1580640268513,"mc":[{"id":"1.168135798","rc":[{"trd":[[1.45,101.18]],"batl":[[0,1.45,819.95]],"ltp":1.45,"tv":5403.23,"id":5720747}],"tv":9693.16}]}
{"op":"mcm","clk":"1005038062","pt":1580640269720,"mc":[{"id":"1.168135798","rc":[{"batb":[[0,2.18,136.43],[1,2,22.17],[2,1.47,1125.69]],"ltp":2.88,"tv":4289.93,"id":2249229},{"batb":[[0,1.4,990.64],[1,1.39,725.89],[2,1.38,6.83]],"batl":[[0,1.44,417.69],[1,1.45,819.95],[2,1.46,566.86]],"ltp":1.45,"tv":5403.23,"id":5720747}]}]}
{"op":"mcm","clk":"1005038314","pt":1580640271743,"mc":[{"id":"1.168135798","rc":[{"trd":[[1.44,7.54]],"batb":[[0,1.41,6.33],[1,1.4,990.64],[2,1.39,725.89]],"batl":[[0,1.44,413.92]],"ltp":1.44,"tv":5410.77,"id":5720747}],"tv":9700.7}]}
{"op":"mcm","clk":"1005038655","pt":1580640274560,"mc":[{"id":"1.168135798","rc":[{"trd":[[1.44,11.88]],"batl":[[0,1.44,411.75]],"ltp":1.44,"tv":5415.11,"id":5720747}],"tv":9705.04}]}
{"op":"mcm","clk":"1005038789","pt":1580640275714,"mc":[{"id":"1.168135798","rc":[{"trd":[[1.44,19.45]],"batl":[[0,1.44,407.97]],"ltp":1.44,"tv":5422.68,"id":5720747}],"tv":9712.61}]}
{"op":"mcm","clk":"1005039047","pt":1580640277760,"mc":[{"id":"1.168135798","rc":[{"trd":[[1.44,19.55]],"batl":[[0,1.44,407.91]],"ltp":1.44,"tv":5422.78,"id":5720747}],"tv":9712.71}]}
{"op":"mcm","clk":"1005039172","pt":1580640278745,"mc":[{"id":"1.168135798","rc":[{"trd":[[3.25,1.68]],"ltp":3.25,"tv":4291.61,"id":2249229},{"trd":[[1.44,23.34]],"batb":[[1,1.4,6.49],[2,1.38,6.83]],"batl":[[0,1.44,404.13],[1,1.76,0.16],[2,1.46,0]],"ltp":1.44,"tv":5426.57,"id":5720747}],"tv":9718.18}]}
{"op":"mcm","clk":"1005039445","pt":1580640280741,"mc":[{"id":"1.168135798","rc":[{"trd":[[3.25,101.68]],"ltp":3.25,"tv":4391.61,"id":2249229},{"trd":[[1.44,249.04]],"batl":[[0,1.44,178.43]],"ltp":1.44,"tv":5652.26,"id":5720747}],"tv":10043.88}]}
{"op":"mcm","clk":"1005039709","pt":1580640282772,"mc":[{"id":"1.168135798","rc":[{"trd":[[3.25,105.88]],"ltp":3.25,"tv":4395.81,"id":2249229},{"trd":[[1.44,258.51]],"batl":[[0,1.44,168.95]],"ltp":1.44,"tv":5661.74,"id":5720747}],"tv":10057.55}]}
{"op":"mcm","clk":"1005039803","pt":1580640283763,"mc":[{"id":"1.168135798","rc":[{"batl":[[1,1.49,601.54],[2,1.5,510.27]],"ltp":1.44,"tv":5661.74,"id":5720747}]}]}
{"op":"mcm","clk":"1005040070","pt":1580640285737,"mc":[{"id":"1.168135798","rc":[{"batl":[[0,1.49,601.54],[1,1.5,510.27],[2,1.76,0.16]],"ltp":1.44,"tv":5661.74,"id":5720747}]}]}
{"op":"mcm","clk":"1005040196","pt":1580640286774,"mc":[{"id":"1.168135798","rc":[{"batb":[[0,1.42,10],[1,1.41,6.33],[2,1.4,6.49]],"ltp":1.44,"tv":5661.74,"id":5720747}]}]}
{"op":"mcm","clk":"1005040323","pt":1580640287768,"mc":[{"id":"1.168135798","rc":[{"trd":[[3.35,11.6]],"batl":[[0,3.35,4.2],[1,3.4,2],[2,3.9,1.68]],"ltp":3.35,"tv":4407.41,"id":2249229}],"tv":10069.16}]}
{"op":"mcm","clk":"1005040438","pt":1580640288760,"mc":[{"id":"1.168135798","rc":[{"batl":[[0,1.48,164.38],[1,1.49,601.54],[2,1.5,510.27]],"ltp":1.44,"tv":5661.74,"id":5720747}]}]}
{"op":"mcm","clk":"1005041171","pt":1580640293780,"mc":[{"id":"1.168135798","rc":[{"batb":[[0,1.44,10],[1,1.42,10],[2,1.41,6.33]],"batl":[[1,1.76,0.16],[2,1.5,0]],"ltp":1.44,"tv":5661.74,"id":5720747}]}]}
{"op":"mcm","clk":"1005041298","pt":1580640294778,"mc":[{"id":"1.168135798","rc":[{"batl":[[0,1.47,50],[1,1.48,164.38],[2,1.76,0.16]],"ltp":1.44,"tv":5661.74,"id":5720747}]}]}
{"op":"mcm","clk":"1005041442","pt":1580640295780,"mc":[{"id":"1.168135798","rc":[{"trd":[[3.35,15.8],[3.4,2]],"batl":[[0,3.9,1.68],[1,3.4,0],[2,3.9,0]],"ltp":3.4,"tv":4413.61,"id":2249229},{"trd":[[1.4,12.97],[1.41,17.48],[1.42,29.9],[1.44,278.51]],"batb":[[0,1.38,6.83],[1,1.35,7.41],[2,1.29,630.5]],"batl":[[0,1.4,792.66],[1,1.47,50],[2,1.48,164.38]],"ltp":1.4,"tv":5742.09,"id":5720747}],"tv":10155.71}]}
{"op":"mcm","clk":"1005041567","pt":1580640296774,"mc":[{"id":"1.168135798","rc":[{"batb":[[0,2,22.17],[1,1.47,1125.69],[2,1.3,22.73]],"ltp":3.4,"tv":4413.61,"id":2249229},{"trd":[[1.38,13.66]],"batb":[[0,1.35,7.41],[1,1.33,1239.84],[2,1.32,938.79]],"batl":[[0,1.37,631.74],[1,1.38,726.17],[2,1.4,792.66]],"ltp":1.38,"tv":5755.75,"id":5720747}],"tv":10169.37}]}
{"op":"mcm","clk":"1005041698","pt":1580640297773,"mc":[{"id":"1.168135798","rc":[{"trd":[[3.7,195]],"ltp":3.7,"tv":4608.61,"id":2249229},{"trd":[[1.37,526.64]],"batl":[[0,1.37,105.1]],"ltp":1.37,"tv":6282.39,"id":5720747}],"tv":10891.01}]}
{"op":"mcm","clk":"1005041825","pt":1580640298762,"mc":[{"id":"1.168135798","rc":[{"batl":[[2,1.47,50]],"ltp":1.37,"tv":6282.39,"id":5720747}]}]}
{"op":"mcm","clk":"1005041921","pt":1580640299655,"mc":[{"id":"1.168135798","rc":[{"trd":[[1.38,33.66]],"batb":[[1,1.33,890.22],[2,1.3,840.19]],"batl":[[0,1.38,716.17],[1,1.48,164.38],[2,1.76,0.16]],"ltp":1.38,"tv":6302.39,"id":5720747}],"tv":10911.01}]}
{"op":"mcm","clk":"1005042063","pt":1580640300765,"mc":[{"id":"1.168135798","rc":[{"batb":[[0,1.33,890.22],[1,1.3,840.19],[2,1.29,840.19]],"ltp":1.38,"tv":6302.39,"id":5720747}]}]}
{"op":"mcm","clk":"1005042222","pt":1580640301760,"mc":[{"id":"1.168135798","rc":[{"batb":[[0,2.32,159.53],[1,2,22.17],[2,1.47,1125.69]],"ltp":3.7,"tv":4608.61,"id":2249229},{"trd":[[1.38,53.66]],"batl":[[0,1.38,706.17],[1,1.41,10],[2,1.48,164.38]],"ltp":1.38,"tv":6322.39,"id":5720747}],"tv":10931.01}]}
{"op":"mcm","clk":"1005042568","pt":1580640303770,"mc":[{"id":"1.168135798","rc":[{"batb":[[0,1.34,634.39],[1,1.33,890.22],[2,1.3,840.19]],"batl":[[0,1.38,1071.57],[1,1.39,694.02],[2,1.41,10]],"ltp":1.38,"tv":6322.39,"id":5720747}]}]}
{"op":"mcm","clk":"1005042736","pt":1580640304771,"mc":[{"id":"1.168135798","rc":[{"batb":[[0,1.34,684.39]],"ltp":1.38,"tv":6322.39,"id":5720747}]}]}
{"op":"mcm","clk":"1005043038","pt":1580640306776,"mc":[{"id":"1.168135798","rc":[{"batb":[[0,1.37,13.44],[1,1.34,684.39],[2,1.33,890.22]],"ltp":1.38,"tv":6322.39,"id":5720747}]}]}
{"op":"mcm","clk":"1005043564","pt":1580640309812,"mc":[{"id":"1.168135798","rc":[{"batb":[[0,3.2,79.47],[1,2.32,159.53],[2,2,22.17]],"ltp":3.7,"tv":4608.61,"id":2249229},{"batb":[[1,1.34,50],[2,1.3,840.19]],"batl":[[0,1.41,10],[1,1.48,164.38],[2,1.76,0.16]],"ltp":1.38,"tv":6322.39,"id":5720747}]}]}
{"op":"mcm","clk":"1005043691","pt":1580640310808,"mc":[{"id":"1.168135798","rc":[{"batl":[[0,3.6,100],[1,3.9,1.68]],"ltp":3.7,"tv":4608.61,"id":2249229},{"batb":[[1,1.3,840.19],[2,1.29,840.19]],"ltp":1.38,"tv":6322.39,"id":5720747}]}]}
{"op":"mcm","clk":"1005043845","pt":1580640311808,"mc":[{"id":"1.168135798","rc":[{"trd":[[3.6,8.43]],"batl":[[0,3.6,91.57]],"ltp":3.6,"tv":4617.04,"id":2249229},{"trd":[[1.38,75.66]],"batb":[[0,1.38,1.77]],"ltp":1.38,"tv":6344.39,"id":5720747}],"tv":10961.44}]}
{"op":"mcm","clk":"1005043975","pt":1580640312697,"mc":[{"id":"1.168135798","rc":[{"trd":[[3.6,30.37]],"batl":[[0,3.6,69.63]],"ltp":3.6,"tv":4638.98,"id":2249229},{"trd":[[1.38,136.43]],"batb":[[0,1.3,840.19],[1,1.29,840.19],[2,1.28,9.27]],"ltp":1.38,"tv":6405.16,"id":5720747}],"tv":11044.15}]}
{"op":"mcm","clk":"1005044132","pt":1580640313804,"mc":[{"id":"1.168135798","rc":[{"trd":[[3.6,40.86]],"batl":[[0,3.6,59.14]],"ltp":3.6,"tv":4649.47,"id":2249229},{"trd":[[1.38,163.78]],"ltp":1.38,"tv":6432.52,"id":5720747}],"tv":11081.99}]}
{"op":"mcm","clk":"1005044440","pt":1580640315694,"mc":[{"id":"1.168135798","rc":[{"trd":[[3.6,44.69]],"batl":[[0,3.6,55.31]],"ltp":3.6,"tv":4653.3,"id":2249229},{"trd":[[1.38,173.78]],"ltp":1.38,"tv":6442.52,"id":5720747}],"tv":11095.82}]}
{"op":"mcm","clk":"1005044899","pt":1580640318799,"mc":[{"id":"1.168135798","rc":[{"trd":[[1.41,37.48]],"batb":[[0,1.41,3.93],[1,1.3,840.19],[2,1.29,840.19]],"batl":[[0,1.42,123.82]],"ltp":1.41,"tv":6462.52,"id":5720747}],"tv":11115.82}]}
{"op":"mcm","clk":"1005045035","pt":1580640319813,"mc":[{"id":"1.168135798","rc":[{"trd":[[3.6,100]],"batl":[[0,3.9,1.68],[1,3.9,0]],"ltp":3.6,"tv":4708.61,"id":2249229},{"trd":[[1.38,318.07],[1.41,45.34]],"batb":[[0,1.3,840.19],[1,1.29,840.19],[2,1.28,9.27]],"batl":[[0,1.37,7.5],[1,1.42,123.82],[2,1.48,164.38]],"ltp":1.38,"tv":6614.67,"id":5720747}],"tv":11323.28}]}
{"op":"mcm","clk":"1005045154","pt":1580640320808,"mc":[{"id":"1.168135798","rc":[{"trd":[[1.37,526.8]],"batl":[[0,1.37,7.42]],"ltp":1.37,"tv":6614.83,"id":5720747}],"tv":11323.45}]}
{"op":"mcm","clk":"1005045325","pt":1580640321814,"mc":[{"id":"1.168135798","rc":[{"batl":[[0,1.42,123.82],[1,1.48,164.38],[2,1.76,0.16]],"ltp":1.37,"tv":6614.83,"id":5720747}]}]}
{"op":"mcm","clk":"1005045491","pt":1580640322789,"mc":[{"id":"1.168135798","rc":[{"batb":[[0,3.3,152.03],[1,3.2,79.47],[2,2.32,159.53]],"ltp":3.6,"tv":4708.61,"id":2249229},{"batl":[[0,1.41,124.7],[1,1.42,123.82],[2,1.48,164.38]],"ltp":1.37,"tv":6614.83,"id":5720747}]}]}
{"op":"mcm","clk":"1005045606","pt":1580640323719,"mc":[{"id":"1.168135798","rc":[{"batb":[[1,2.32,159.53],[2,2,22.17]],"ltp":3.6,"tv":4708.61,"id":2249229},{"trd":[[1.36,20]],"batl":[[0,1.36,10],[1,1.41,124.7],[2,1.42,123.82]],"ltp":1.36,"tv":6634.83,"id":5720747}],"tv":11343.45}]}
{"op":"mcm","clk":"1005045774","pt":1580640324819,"mc":[{"id":"1.168135798","rc":[{"batb":[[0,1.28,9.27],[1,1.25,10.38],[2,1.24,650.84]],"ltp":1.36,"tv":6634.83,"id":5720747}]}]}
{"op":"mcm","clk":"1005045928","pt":1580640325820,"mc":[{"id":"1.168135798","rc":[{"batb":[[1,1.25,1000.89],[2,1.24,1974.18]],"ltp":1.36,"tv":6634.83,"id":5720747}]}]}
{"op":"mcm","clk":"1005046051","pt":1580640326818,"mc":[{"id":"1.168135798","rc":[{"trd":[[3.9,1.68]],"ltp":3.9,"tv":4710.29,"id":2249229},{"trd":[[1.34,4.89]],"batl":[[0,1.34,835.3],[1,1.36,10],[2,1.41,124.7]],"ltp":1.34,"tv":6639.72,"id":5720747}],"tv":11350.02}]}
{"op":"mcm","clk":"1005046201","pt":1580640327819,"mc":[{"id":"1.168135798","rc":[{"batb":[[0,1.31,8.37],[1,1.28,9.27],[2,1.25,1000.89]],"batl":[[1,1.37,840.19]],"ltp":1.34,"tv":6639.72,"id":5720747}]}]}
{"op":"mcm","clk":"1005046323","pt":1580640328815,"mc":[{"id":"1.168135798","rc":[{"batb":[[0,1.28,9.27],[1,1.25,1000.89],[2,1.24,1974.18]],"batl":[[0,1.34,941.95]],"ltp":1.34,"tv":6639.72,"id":5720747}]}]}
{"op":"mcm","clk":"1005046469","pt":1580640329813,"mc":[{"id":"1.168135798","rc":[{"batb":[[1,2,22.17],[2,1.47,1125.69]],"ltp":3.9,"tv":4710.29,"id":2249229},{"batb":[[2,1.24,1323.34]],"batl":[[0,1.34,934.45]],"ltp":1.34,"tv":6639.72,"id":5720747}]}]}
{"op":"mcm","clk":"1005046607","pt":1580640330814,"mc":[{"id":"1.168135798","rc":[{"trd":[[1.28,18.54]],"batb":[[0,1.25,1000.89],[1,1.24,1323.34],[2,1.22,29.53]],"batl":[[0,1.28,922.4],[1,1.29,1001.08],[2,1.33,10]],"ltp":1.28,"tv":6658.26,"id":5720747}],"tv":11368.55}]}
{"op":"mcm","clk":"1005046746","pt":1580640331809,"mc":[{"id":"1.168135798","rc":[{"trd":[[1.28,37.12]],"batb":[[0,1.26,50],[1,1.25,1000.89],[2,1.24,1323.34]],"batl":[[0,1.28,913.11]],"ltp":1.28,"tv":6676.84,"id":5720747}],"tv":11387.13}]}
{"op":"mcm","clk":"1005047040","pt":1580640333790,"mc":[{"id":"1.168135798","rc":[{"trd":[[4.5,11.58]],"batb":[[0,2.56,249.94]],"ltp":4.5,"tv":4721.87,"id":2249229},{"trd":[[1.28,77.82]],"batl":[[0,1.28,872.41]],"ltp":1.28,"tv":6717.54,"id":5720747}],"tv":11439.41}]}
{"op":"mcm","clk":"1005047395","pt":1580640336718,"mc":[{"id":"1.168135798","rc":[{"batb":[[0,3.95,59.26],[1,2.56,249.94],[2,2,22.17]],"ltp":4.5,"tv":4721.87,"id":2249229}]}]}
{"op":"mcm","clk":"1005047524","pt":1580640337710,"mc":[{"id":"1.168135798","rc":[{"trd":[[4.5,21.58]],"batb":[[0,4,58.28],[1,3.95,59.26],[2,2.56,249.94]],"ltp":4.5,"tv":4731.87,"id":2249229},{"trd":[[1.28,112.98]],"batl":[[0,1.28,837.25]],"ltp":1.28,"tv":6752.7,"id":5720747}],"tv":11484.57}]}
{"op":"mcm","clk":"1005047779","pt":1580640339807,"mc":[{"id":"1.168135798","rc":[{"batl":[[2,1.34,835.3]],"ltp":1.28,"tv":6752.7,"id":5720747}]}]}
{"op":"mcm","clk":"1005048076","pt":1580640341736,"mc":[{"id":"1.168135798","rc":[{"trd":[[1.26,97.52]],"batb":[[0,1.26,1.24],[1,1.25,30.38],[2,1.22,29.53]],"batl":[[0,1.34,835.3],[1,1.37,840.19],[2,1.76,0.16]],"ltp":1.26,"tv":6850.22,"id":5720747}],"tv":11582.09}]}
{"op":"mcm","clk":"1005048209","pt":1580640342734,"mc":[{"id":"1.168135798","rc":[{"trd":[[1.25,17.52],[1.26,100]],"batb":[[0,1.25,21.62],[1,1.22,29.53],[2,1.21,840.19]],"ltp":1.25,"tv":6870.23,"id":5720747}],"tv":11602.1}]}
{"op":"mcm","clk":"1005048345","pt":1580640343739,"mc":[{"id":"1.168135798","rc":[{"batb":[[0,1.25,20]],"batl":[[0,1.28,5],[1,1.34,835.3],[2,1.37,840.19]],"ltp":1.25,"tv":6870.23,"id":5720747}]}]}
{"op":"mcm","clk":"1005048476","pt":1580640344727,"mc":[{"id":"1.168135798","rc":[{"trd":[[4.5,23]],"batl":[[0,4.5,8.58]],"ltp":4.5,"tv":4733.29,"id":2249229},{"trd":[[1.28,117.98]],"batl":[[0,1.34,835.3],[1,1.37,840.19],[2,1.76,0.16]],"ltp":1.28,"tv":6875.23,"id":5720747}],"tv":11608.52}]}
{"op":"mcm","clk":"1005048597","pt":1580640345722,"mc":[{"id":"1.168135798","rc":[{"batl":[[1,4.8,11]],"ltp":4.5,"tv":4733.29,"id":2249229}]}]}
{"op":"mcm","clk":"1005048720","pt":1580640346716,"mc":[{"id":"1.168135798","rc":[{"trd":[[4.5,28.46]],"batl":[[0,4.5,3.12]],"ltp":4.5,"tv":4738.75,"id":2249229},{"trd":[[1.28,137.19]],"batb":[[0,1.26,20],[1,1.25,20],[2,1.22,29.53]],"ltp":1.28,"tv":6894.44,"id":5720747}],"tv":11633.19}]}
{"op":"mcm","clk":"1005048855","pt":1580640347814,"mc":[{"id":"1.168135798","rc":[{"batl":[[0,1.34,1553.02],[1,1.35,800.18],[2,1.37,840.19]],"ltp":1.28,"tv":6894.44,"id":5720747}]}]}
{"op":"mcm","clk":"1005049103","pt":1580640349742,"mc":[{"id":"1.168135798","rc":[{"batl":[[0,1.33,35],[1,1.34,1553.02],[2,1.35,800.18]],"ltp":1.28,"tv":6894.44,"id":5720747}]}]}
{"op":"mcm","clk":"1005049311","pt":1580640351719,"mc":[{"id":"1.168135798","rc":[{"batb":[[0,1.28,8],[1,1.26,20],[2,1.25,20]],"ltp":1.28,"tv":6894.44,"id":5720747}]}]}
{"op":"mcm","clk":"1005049419","pt":1580640352612,"mc":[{"id":"1.168135798","rc":[{"trd":[[4.5,29.74]],"batl":[[0,4.5,1.84]],"ltp":4.5,"tv":4740.03,"id":2249229},{"trd":[[1.28,157.69]],"batb":[[0,1.26,20],[1,1.25,20],[2,1.22,29.53]],"ltp":1.28,"tv":6914.94,"id":5720747}],"tv":11654.97}]}
{"op":"mcm","clk":"1005049562","pt":1580640353818,"mc":[{"id":"1.168135798","rc":[{"trd":[[4,77.24]],"batb":[[0,4,19.66]],"ltp":4.0,"tv":4817.27,"id":2249229},{"batl":[[1,1.34,717.72]],"ltp":1.28,"tv":6914.94,"id":5720747}],"tv":11732.21}]}
{"op":"mcm","clk":"1005049700","pt":1580640354817,"mc":[{"id":"1.168135798","rc":[{"trd":[[4,87.24]],"batb":[[0,4,14.66]],"ltp":4.0,"tv":4827.27,"id":2249229},{"batl":[[0,1.34,717.72],[1,1.35,800.18],[2,1.76,0.16]],"ltp":1.28,"tv":6914.94,"id":5720747}],"tv":11742.21}]}
{"op":"mcm","clk":"1005049946","pt":1580640356751,"mc":[{"id":"1.168135798","rc":[{"trd":[[1.29,22.72]],"batb":[[0,1.29,828.84],[1,1.27,840.19],[2,1.26,20]],"ltp":1.29,"tv":6937.65,"id":5720747}],"tv":11764.93}]}
{"op":"mcm","clk":"1005050074","pt":1580640357745,"mc":[{"id":"1.168135798","rc":[{"batb":[[0,1.27,840.19],[1,1.26,20],[2,1.25,20]],"ltp":1.29,"tv":6937.65,"id":5720747}]}]}
{"op":"mcm","clk":"1005050188","pt":1580640358745,"mc":[{"id":"1.168135798","rc":[{"batb":[[0,2.56,249.94],[1,2,22.17],[2,1.47,1125.69]],"ltp":4.0,"tv":4827.27,"id":2249229},{"batb":[[0,1.31,508.26],[1,1.3,1001.07],[2,1.28,381.09]],"ltp":1.29,"tv":6937.65,"id":5720747}]}]}
{"op":"mcm","clk":"1005050323","pt":1580640359744,"mc":[{"id":"1.168135798","rc":[{"batl":[[0,4.2,21],[1,4.5,1.84],[2,4.8,11]],"ltp":4.0,"tv":4827.27,"id":2249229},{"batb":[[1,1.3,1135.29]],"batl":[[2,1.4,20]],"ltp":1.29,"tv":6937.65,"id":5720747}]}]}
{"op":"mcm","clk":"1005050462","pt":1580640360763,"mc":[{"id":"1.168135798","rc":[{"batl":[[0,4,30.39],[1,4.2,21],[2,4.5,1.84]],"ltp":4.0,"tv":4827.27,"id":2249229},{"trd":[[1.34,23.47]],"batb":[[1,1.3,1001.07]],"batl":[[0,1.34,708.43]],"ltp":1.34,"tv":6956.23,"id":5720747}],"tv":11783.5}]}
{"op":"mcm","clk":"1005050844","pt":1580640363757,"mc":[{"id":"1.168135798","rc":[{"batb":[[0,1.33,131.19],[1,1.31,508.26],[2,1.3,1001.07]],"ltp":1.34,"tv":6956.23,"id":5720747}]}]}
{"op":"mcm","clk":"1005051314","pt":1580640366754,"mc":[{"id":"1.168135798","rc":[{"trd":[[1.33,40]],"batb":[[0,1.31,508.26],[1,1.3,1001.07],[2,1.27,840.19]],"ltp":1.33,"tv":6996.23,"id":5720747}],"tv":11823.5}]}
{"op":"mcm","clk":"1005051436","pt":1580640367747,"mc":[{"id":"1.168135798","rc":[{"trd":[[4,109.16]],"batl":[[0,4,8.47]],"ltp":4.0,"tv":4849.19,"id":2249229},{"trd":[[1.33,106]],"ltp":1.33,"tv":7062.23,"id":5720747}],"tv":11911.43}]}
{"op":"mcm","clk":"1005051600","pt":1580640368745,"mc":[{"id":"1.168135798","rc":[{"batl":[[0,4.2,21],[1,4.5,1.84],[2,4.8,11]],"ltp":4.0,"tv":4849.19,"id":2249229}]}]}
{"op":"mcm","clk":"1005051893","pt":1580640370737,"mc":[{"id":"1.168135798","rc":[{"trd":[[1.34,283.88]],"batl":[[0,1.34,578.23]],"ltp":1.34,"tv":7322.65,"id":5720747}],"tv":12171.84}]}
{"op":"mcm","clk":"1005052038","pt":1580640371767,"mc":[{"id":"1.168135798","rc":[{"trd":[[3.9,10.15]],"batl":[[0,4,50],[1,4.2,21],[2,4.5,1.84]],"ltp":3.9,"tv":4857.66,"id":2249229},{"trd":[[1.34,308.55]],"batl":[[0,1.34,553.56]],"ltp":1.34,"tv":7347.32,"id":5720747}],"tv":12204.98}]}
{"op":"mcm","clk":"1005052180","pt":1580640372764,"mc":[{"id":"1.168135798","rc":[{"trd":[[4,109.92]],"batl":[[0,3.9,100],[1,4,49.24],[2,4.2,21]],"ltp":4.0,"tv":4858.42,"id":2249229},{"trd":[[1.33,108.27]],"batb":[[0,1.27,840.19],[1,1.26,840.19],[2,1.25,860.19]],"batl":[[0,1.39,35],[1,1.4,20],[2,1.4,0]],"ltp":1.33,"tv":7349.59,"id":5720747}],"tv":12208.01}]}
{"op":"mcm","clk":"1005052892","pt":1580640377752,"mc":[{"id":"1.168135798","rc":[{"batl":[[0,4,49.24],[1,4.2,21],[2,4.5,1.84]],"ltp":4.0,"tv":4858.42,"id":2249229},{"batl":[[0,1.34,137.26],[1,1.39,35],[2,1.4,20]],"ltp":1.33,"tv":7349.59,"id":5720747}]}]}
{"op":"mcm","clk":"1005053130","pt":1580640379778,"mc":[{"id":"1.168135798","rc":[{"trd":[[4,159.16]],"batb":[[0,3.8,7],[1,2.56,249.94],[2,2,22.17]],"batl":[[0,4.2,21],[1,4.5,1.84],[2,4.8,11]],"ltp":4.0,"tv":4907.66,"id":2249229},{"trd":[[1.33,256.36]],"ltp":1.33,"tv":7497.68,"id":5720747}],"tv":12405.34}]}
{"op":"mcm","clk":"1005053284","pt":1580640380770,"mc":[{"id":"1.168135798","rc":[{"batl":[[0,1.34,139.26]],"ltp":1.33,"tv":7497.68,"id":5720747}]}]}
{"op":"mcm","clk":"1005053411","pt":1580640381768,"mc":[{"id":"1.168135798","rc":[{"batb":[[1,3.4,72.85],[2,2.56,249.94]],"ltp":4.0,"tv":4907.66,"id":2249229}]}]}
{"op":"mcm","clk":"1005053532","pt":1580640382751,"mc":[{"id":"1.168135798","rc":[{"batb":[[1,3.4,145.69]],"ltp":4.0,"tv":4907.66,"id":2249229}]}]}
{"op":"mcm","clk":"1005054383","pt":1580640388790,"mc":[{"id":"1.168135798","rc":[{"trd":[[1.34,336.41]],"batl":[[0,1.34,123.33]],"ltp":1.34,"tv":7525.54,"id":5720747}],"tv":12433.2}]}
{"op":"mcm","clk":"1005054769","pt":1580640391784,"mc":[{"id":"1.168135798","rc":[{"trd":[[4.2,0.62]],"batl":[[0,4.2,20.38]],"ltp":4.2,"tv":4908.28,"id":2249229},{"trd":[[1.31,2],[1.34,353.22]],"batl":[[0,1.34,114.93]],"ltp":1.31,"tv":7544.34,"id":5720747}],"tv":12452.63}]}
{"op":"mcm","clk":"1005055989","pt":1580640401707,"mc":[{"id":"1.168135798","rc":[{"trd":[[1.34,359.22]],"batb":[[0,1.25,20],[1,1.23,797.4],[2,1.2,731.62]],"batl":[[0,1.34,111.93]],"ltp":1.34,"tv":7550.34,"id":5720747}],"tv":12458.63}]}
{"op":"mcm","clk":"1005056382","pt":1580640404771,"mc":[{"id":"1.168135798","rc":[{"trd":[[4.2,21],[4.5,31.58]],"batl":[[0,4.8,11],[1,4.5,0],[2,4.8,0]],"ltp":4.5,"tv":4930.5,"id":2249229},{"trd":[[1.28,164.16],[1.31,67.34]],"batb":[[2,1.2,12.98]],"batl":[[0,1.27,768.38],[1,1.34,111.93],[2,1.39,35]],"ltp":1.28,"tv":7622.16,"id":5720747}],"tv":12552.66}]}
{"op":"mcm","clk":"1005056496","pt":1580640405760,"mc":[{"id":"1.168135798","rc":[{"batl":[[1,1.3,840.19],[2,1.34,111.93]],"ltp":1.28,"tv":7622.16,"id":5720747}]}]}
{"op":"mcm","clk":"1005056646","pt":1580640406817,"mc":[{"id":"1.168135798","rc":[{"trd":[[4.8,11]],"ltp":4.8,"tv":4941.5,"id":2249229},{"trd":[[1.25,57.52],[1.26,141.91]],"batb":[[0,1.23,797.4],[1,1.2,12.98],[2,1.15,17.31]],"batl":[[0,1.25,44.8],[1,1.27,768.38],[2,1.3,840.19]],"ltp":1.25,"tv":7704.06,"id":5720747}],"tv":12645.56}]}
{"op":"mcm","clk":"1005056793","pt":1580640407813,"mc":[{"id":"1.168135798","rc":[{"batb":[[2,2,22.17]],"ltp":4.8,"tv":4941.5,"id":2249229},{"trd":[[1.23,1594.8]],"batb":[[0,1.2,1571.81],[1,1.19,1736.01]],"batl":[[0,1.23,1243.22],[1,1.25,44.8],[2,1.27,768.38]],"ltp":1.23,"tv":9298.86,"id":5720747}],"tv":14240.37}]}
{"op":"mcm","clk":"1005056938","pt":1580640408819,"mc":[{"id":"1.168135798","rc":[{"batb":[[0,1.2,731.61]],"ltp":1.23,"tv":9298.86,"id":5720747}]}]}
{"op":"mcm","clk":"1005057090","pt":1580640409818,"mc":[{"id":"1.168135798","rc":[{"batl":[[1,1.25,9.84]],"ltp":1.23,"tv":9298.86,"id":5720747}]}]}
{"op":"mcm","clk":"1005057212","pt":1580640410608,"mc":[{"id":"1.168135798","rc":[{"batb":[[0,2,22.17],[1,1.47,1125.69],[2,1.3,22.73]],"ltp":4.8,"tv":4941.5,"id":2249229},{"batl":[[1,1.27,768.38],[2,1.3,840.19]],"ltp":1.23,"tv":9298.86,"id":5720747}]}]}
{"op":"mcm","clk":"1005057373","pt":1580640411768,"mc":[{"id":"1.168135798","rc":[{"batb":[[0,1.2,959.74]],"batl":[[0,1.22,491.16],[1,1.23,1243.22],[2,1.27,768.38]],"ltp":1.23,"tv":9298.86,"id":5720747}]}]}
{"op":"mcm","clk":"1005057501","pt":1580640412813,"mc":[{"id":"1.168135798","rc":[{"batb":[[0,2.74,612.8],[1,2,22.17],[2,1.47,1125.69]],"ltp":4.8,"tv":4941.5,"id":2249229},{"batb":[[2,1.16,840.19]],"ltp":1.23,"tv":9298.86,"id":5720747}]}]}
{"op":"mcm","clk":"1005057640","pt":1580640413812,"mc":[{"id":"1.168135798","rc":[{"trd":[[1.22,126.5]],"batl":[[0,1.22,427.91]],"ltp":1.22,"tv":9425.36,"id":5720747}],"tv":14366.87}]}
{"op":"mcm","clk":"1005058281","pt":1580640418712,"mc":[{"id":"1.168135798","rc":[{"batl":[[0,1.22,594.76]],"ltp":1.22,"tv":9425.36,"id":5720747}]}]}
{"op":"mcm","clk":"1005058430","pt":1580640419713,"mc":[{"id":"1.168135798","rc":[{"batb":[[0,1.2,12.98],[1,1.16,840.19],[2,1.15,33.74]],"batl":[[0,1.27,768.38],[1,1.3,840.19],[2,1.34,111.93]],"ltp":1.22,"tv":9425.36,"id":5720747}]}]}
{"op":"mcm","clk":"1005058611","pt":1580640420807,"mc":[{"id":"1.168135798","rc":[{"trd":[[1.2,25.96]],"batb":[[0,1.16,840.19],[1,1.15,33.74],[2,1.13,840.19]],"batl":[[0,1.2,11.13],[1,1.27,768.38],[2,1.3,840.19]],"ltp":1.2,"tv":9451.33,"id":5720747}],"tv":14392.83}]}
{"op":"mcm","clk":"1005058729","pt":1580640421801,"mc":[{"id":"1.168135798","rc":[{"trd":[[1.2,48.23]],"batb":[[0,1.22,4.01],[1,1.16,840.19],[2,1.15,33.74]],"batl":[[0,1.27,768.38],[1,1.3,840.19],[2,1.34,111.93]],"ltp":1.2,"tv":9473.59,"id":5720747}],"tv":14415.09}]}
{"op":"mcm","clk":"1005059088","pt":1580640424727,"mc":[{"id":"1.168135798","rc":[{"batl":[[1,1.29,552.86],[2,1.3,1806.29]],"ltp":1.2,"tv":9473.59,"id":5720747}]}]}
{"op":"mcm","clk":"1005059233","pt":1580640425721,"mc":[{"id":"1.168135798","rc":[{"batb":[[1,1.17,40.27],[2,1.16,840.19]],"batl":[[0,1.26,70],[1,1.27,768.38],[2,1.29,552.86]],"ltp":1.2,"tv":9473.59,"id":5720747}]}]}
{"op":"mcm","clk":"1005059351","pt":1580640426723,"mc":[{"id":"1.168135798","rc":[{"batb":[[1,1.17,90.27]],"ltp":1.2,"tv":9473.59,"id":5720747}]}]}
{"op":"mcm","clk":"1005059589","pt":1580640428720,"mc":[{"id":"1.168135798","rc":[{"batl":[[0,1.26,101.56]],"ltp":1.2,"tv":9473.59,"id":5720747}]}]}
{"op":"mcm","clk":"1005059713","pt":1580640429624,"mc":[{"id":"1.168135798","rc":[{"batb":[[0,2,22.17],[1,1.47,1125.69],[2,1.3,22.73]],"ltp":4.8,"tv":4941.5,"id":2249229},{"batb":[[1,1.2,50],[2,1.17,90.27]],"ltp":1.2,"tv":9473.59,"id":5720747}]}]}
{"op":"mcm","clk":"1005059994","pt":1580640431819,"mc":[{"id":"1.168135798","rc":[{"batl":[[0,1.26,31.56]],"ltp":1.2,"tv":9473.59,"id":5720747}]}]}
{"op":"mcm","clk":"1005060227","pt":1580640433810,"mc":[{"id":"1.168135798","rc":[{"trd":[[1.16,102.94],[1.17,180.55],[1.2,148.23],[1.22,134.53]],"batb":[[0,1.16,788.72],[1,1.15,17.31],[2,1.13,840.19]],"ltp":1.16,"tv":9865.11,"id":5720747}],"tv":14806.61}]}
{"op":"mcm","clk":"1005060365","pt":1580640434807,"mc":[{"id":"1.168135798","rc":[{"batb":[[0,5,43.71],[1,2,22.17],[2,1.47,1125.69]],"ltp":4.8,"tv":4941.5,"id":2249229}]}]}
{"op":"mcm","clk":"1005060495","pt":1580640435806,"mc":[{"id":"1.168135798","rc":[{"batl":[[0,1.26,101.56]],"ltp":1.16,"tv":9865.11,"id":5720747}]}]}
{"op":"mcm","clk":"1005060598","pt":1580640436742,"mc":[{"id":"1.168135798","rc":[{"trd":[[5,0.69]],"batb":[[0,5,43.02],[1,4.5,49.95],[2,2,22.17]],"ltp":5.0,"tv":4942.19,"id":2249229},{"trd":[[1.25,60.28]],"ltp":1.25,"tv":9867.86,"id":5720747}],"tv":14810.05}]}
{"op":"mcm","clk":"1005060838","pt":1580640438742,"mc":[{"id":"1.168135798","rc":[{"trd":[[5,22.07]],"batb":[[0,5,21.64]],"ltp":5.0,"tv":4963.57,"id":2249229},{"trd":[[1.25,145.8]],"batb":[[0,1.16,1628.92],[1,1.15,857.5]],"batl":[[0,1.26,70]],"ltp":1.25,"tv":9953.39,"id":5720747}],"tv":14916.96}]}
{"op":"mcm","clk":"1005060988","pt":1580640439740,"mc":[{"id":"1.168135798","rc":[{"batl":[[0,1.22,20],[1,1.23,50],[2,1.26,70]],"ltp":1.25,"tv":9953.39,"id":5720747}]}]}
{"op":"mcm","clk":"1005061223","pt":1580640441729,"mc":[{"id":"1.168135798","rc":[{"trd":[[5,25.99],[5.3,11.6],[5.5,4.44]],"batb":[[0,4.5,49.95],[1,2,22.17],[2,1.47,1125.69]],"ltp":5.0,"tv":4983.53,"id":2249229},{"trd":[[1.22,154.53],[1.23,1644.8]],"batl":[[0,1.23,25],[1,1.26,70],[2,1.27,768.38]],"ltp":1.23,"tv":10023.39,"id":5720747}],"tv":15006.92}]}
{"op":"mcm","clk":"1005061323","pt":1580640442721,"mc":[{"id":"1.168135798","rc":[{"batl":[[1,1.24,32.07],[2,1.26,70]],"ltp":1.23,"tv":10023.39,"id":5720747}]}]}
{"op":"mcm","clk":"1005061431","pt":1580640443718,"mc":[{"id":"1.168135798","rc":[{"batb":[[0,1.2,69.79],[1,1.16,1628.92],[2,1.15,857.5]],"ltp":1.23,"tv":10023.39,"id":5720747}]}]}
{"op":"mcm","clk":"1005061748","pt":1580640445819,"mc":[{"id":"1.168135798","rc":[{"trd":[[6,13.96],[7.4,91.07]],"ltp":7.4,"tv":5088.55,"id":2249229},{"trd":[[1.16,683.89],[1.2,218.01]],"batb":[[0,1.16,1047.97],[1,1.15,857.5],[2,1.13,840.19]],"ltp":1.16,"tv":10674.13,"id":5720747}],"tv":15762.68}]}
{"op":"mcm","clk":"1005061847","pt":1580640446649,"mc":[{"id":"1.168135798","rc":[{"trd":[[1.23,1644.89]],"batl":[[0,1.23,24.96],[2,1.25,92.65]],"ltp":1.23,"tv":10674.21,"id":5720747}],"tv":15762.77}]}
{"op":"mcm","clk":"1005061965","pt":1580640447744,"mc":[{"id":"1.168135798","rc":[{"trd":[[5.3,14.33]],"ltp":5.3,"tv":5091.28,"id":2249229},{"trd":[[1.23,1656.67]],"batl":[[0,1.23,13.18]],"ltp":1.23,"tv":10685.99,"id":5720747}],"tv":15777.28}]}
{"op":"mcm","clk":"1005062200","pt":1580640449725,"mc":[{"id":"1.168135798","rc":[{"batl":[[1,1.25,92.65],[2,1.28,70]],"ltp":1.23,"tv":10685.99,"id":5720747}]}]}
{"op":"mcm","clk":"1005062580","pt":1580640452820,"mc":[{"id":"1.168135798","rc":[{"batb":[[0,1.2,8.17],[1,1.16,1047.97],[2,1.15,857.5]],"ltp":1.23,"tv":10685.99,"id":5720747}]}]}
{"op":"mcm","clk":"1005062770","pt":1580640454746,"mc":[{"id":"1.168135798","rc":[{"trd":[[1.16,2667.56],[1.2,234.35]],"batb":[[0,1.16,56.13],[1,1.15,857.5],[2,1.13,840.19]],"ltp":1.16,"tv":12685.99,"id":5720747}],"tv":17777.28}]}
{"op":"mcm","clk":"1005062866","pt":1580640455637,"mc":[{"id":"1.168135798","rc":[{"batl":[[0,1.22,647.31],[1,1.23,13.18],[2,1.25,92.65]],"ltp":1.16,"tv":12685.99,"id":5720747}]}]}
{"op":"mcm","clk":"1005063126","pt":1580640457723,"mc":[{"id":"1.168135798","rc":[{"batb":[[0,4.5,99.9]],"ltp":5.3,"tv":5091.28,"id":2249229}]}]}
{"op":"mcm","clk":"1005063352","pt":1580640459758,"mc":[{"id":"1.168135798","rc":[{"batl":[[0,1.23,13.18],[1,1.28,70],[2,1.29,552.86]],"ltp":1.16,"tv":12685.99,"id":5720747}]}]}
{"op":"mcm","clk":"1005063729","pt":1580640462757,"mc":[{"id":"1.168135798","rc":[{"batb":[[0,1.17,840.19],[1,1.16,56.13],[2,1.15,857.5]],"ltp":1.16,"tv":12685.99,"id":5720747}]}]}
{"op":"mcm","clk":"1005063970","pt":1580640464739,"mc":[{"id":"1.168135798","rc":[{"trd":[[1.17,188.54]],"batb":[[0,1.17,836.2]],"batl":[[1,1.27,31.31],[2,1.28,70]],"ltp":1.17,"tv":12693.99,"id":5720747}],"tv":17785.28}]}
{"op":"mcm","clk":"1005064426","pt":1580640468756,"mc":[{"id":"1.168135798","rc":[{"batl":[[2,1.29,552.86]],"ltp":1.17,"tv":12693.99,"id":5720747}]}]}
{"op":"mcm","clk":"1005064545","pt":1580640469752,"mc":[{"id":"1.168135798","rc":[{"batb":[[0,1.17,1676.39]],"ltp":1.17,"tv":12693.99,"id":5720747}]}]}
{"op":"mcm","clk":"1005064648","pt":1580640470748,"mc":[{"id":"1.168135798","rc":[{"batb":[[0,1.18,388.88],[1,1.17,1676.39],[2,1.16,56.13]],"ltp":1.17,"tv":12693.99,"id":5720747}]}]}
{"op":"mcm","clk":"1005064743","pt":1580640471674,"mc":[{"id":"1.168135798","rc":[{"trd":[[1.18,161.32]],"batb":[[0,1.18,308.22]],"ltp":1.18,"tv":12855.31,"id":5720747}],"tv":17946.6}]}
{"op":"mcm","clk":"1005064870","pt":1580640472771,"mc":[{"id":"1.168135798","rc":[{"batb":[[0,2,22.17],[1,1.47,1125.69],[2,1.3,22.73]],"ltp":5.3,"tv":5091.28,"id":2249229}]}]}
{"op":"mcm","clk":"1005064995","pt":1580640473773,"mc":[{"id":"1.168135798","rc":[{"trd":[[1.23,1683.03]],"batb":[[0,1.26,1237.09],[1,1.25,1263.45],[2,1.18,308.22]],"batl":[[0,1.27,31.31],[1,1.29,552.86],[2,1.3,966.1]],"ltp":1.23,"tv":12881.67,"id":5720747}],"tv":17972.96}]}
{"op":"mcm","clk":"1005065194","pt":1580640475752,"mc":[{"id":"1.168135798","rc":[{"batb":[[2,1.17,1676.39]],"batl":[[0,1.29,552.86],[1,1.3,966.1],[2,1.3,0]],"ltp":1.23,"tv":12881.67,"id":5720747}]}]}
{"op":"mcm","clk":"1005065288","pt":1580640476691,"mc":[{"id":"1.168135798","rc":[{"batb":[[0,2.56,631.13],[1,2,22.17],[2,1.47,1125.69]],"batl":[[0,4.9,11.36]],"ltp":5.3,"tv":5091.28,"id":2249229}]}]}
{"op":"mcm","clk":"1005065562","pt":1580640478801,"mc":[{"id":"1.168135798","rc":[{"trd":[[1.25,783.5],[1.26,2616.09]],"batb":[[0,1.25,944.6],[1,1.17,1676.39],[2,1.16,56.13]],"batl":[[0,1.26,75.53],[1,1.29,552.86],[2,1.3,966.1]],"ltp":1.25,"tv":15993.55,"id":5720747}],"tv":21084.84}]}
{"op":"mcm","clk":"1005065928","pt":1580640481811,"mc":[{"id":"1.168135798","rc":[{"trd":[[1.26,2767.15]],"batb":[[0,1.26,728.25],[1,1.25,1263.48],[2,1.15,17.31]],"batl":[[0,1.29,990.8],[1,1.3,966.1],[2,1.3,0]],"ltp":1.26,"tv":16144.61,"id":5720747}],"tv":21235.9}]}
{"op":"mcm","clk":"1005066202","pt":1580640483807,"mc":[{"id":"1.168135798","rc":[{"batb":[[0,1.26,738.07]],"ltp":1.26,"tv":16144.61,"id":5720747}]}]}
{"op":"mcm","clk":"1005066321","pt":1580640484786,"mc":[{"id":"1.168135798","rc":[{"batb":[[0,3.7,64.75],[1,2.56,631.13],[2,2,22.17]],"ltp":5.3,"tv":5091.28,"id":2249229},{"trd":[[1.26,2830.77]],"batb":[[0,1.26,706.26]],"ltp":1.26,"tv":16208.23,"id":5720747}],"tv":21299.52}]}
{"op":"mcm","clk":"1005066432","pt":1580640485716,"mc":[{"id":"1.168135798","rc":[{"batb":[[2,1.16,840.19]],"ltp":1.26,"tv":16208.23,"id":5720747}]}]}
{"op":"mcm","clk":"1005066570","pt":1580640486815,"mc":[{"id":"1.168135798","rc":[{"batb":[[0,1.26,9.82],[1,1.16,840.19],[2,1.15,17.31]],"batl":[[0,1.41,840.19],[1,1.3,0]],"ltp":1.26,"tv":16208.23,"id":5720747}]}]}
{"op":"mcm","clk":"1005066690","pt":1580640487813,"mc":[{"id":"1.168135798","rc":[{"batb":[[1,1.16,915.19]],"ltp":1.26,"tv":16208.23,"id":5720747}]}]}
{"op":"mcm","clk":"1005066823","pt":1580640488813,"mc":[{"id":"1.168135798","rc":[{"batb":[[1,1.16,990.19]],"ltp":1.26,"tv":16208.23,"id":5720747}]}]}
{"op":"mcm","clk":"1005066963","pt":1580640489803,"mc":[{"id":"1.168135798","rc":[{"batl":[[0,4.4,9]],"ltp":5.3,"tv":5091.28,"id":2249229}]}]}
{"op":"mcm","clk":"1005067070","pt":1580640490789,"mc":[{"id":"1.168135798","rc":[{"batl":[[0,4.4,29]],"ltp":5.3,"tv":5091.28,"id":2249229}]}]}
{"op":"mcm","clk":"1005067183","pt":1580640491780,"mc":[{"id":"1.168135798","rc":[{"batb":[[1,1.17,75],[2,1.16,990.19]],"batl":[[0,1.37,70],[1,1.41,840.19]],"ltp":1.26,"tv":16208.23,"id":5720747}]}]}
{"op":"mcm","clk":"1005067299","pt":1580640492781,"mc":[{"id":"1.168135798","rc":[{"batl":[[1,1.41,1593.96],[2,1.42,638.83]],"ltp":1.26,"tv":16208.23,"id":5720747}]}]}
{"op":"mcm","clk":"1005067415","pt":1580640493815,"mc":[{"id":"1.168135798","rc":[{"batl":[[0,4.4,9]],"ltp":5.3,"tv":5091.28,"id":2249229}]}]}
{"op":"mcm","clk":"1005067536","pt":1580640494799,"mc":[{"id":"1.168135798","rc":[{"batb":[[1,2,22.17],[2,1.47,1125.69]],"ltp":5.3,"tv":5091.28,"id":2249229},{"batb":[[0,1.17,75],[1,1.16,990.19],[2,1.15,17.31]],"batl":[[0,1.37,910.19],[1,1.41,840.19],[2,1.42,0]],"ltp":1.26,"tv":16208.23,"id":5720747}]}]}
{"op":"mcm","clk":"1005067660","pt":1580640495790,"mc":[{"id":"1.168135798","rc":[{"batb":[[0,2,22.17],[1,1.47,1125.69],[2,1.3,22.73]],"ltp":5.3,"tv":5091.28,"id":2249229}]}]}
{"op":"mcm","clk":"1005067874","pt":1580640497730,"mc":[{"id":"1.168135798","rc":[{"batb":[[0,3.45,71.36],[1,2,22.17],[2,1.47,1125.69]],"ltp":5.3,"tv":5091.28,"id":2249229}]}]}
{"op":"mcm","clk":"1005067996","pt":1580640498729,"mc":[{"id":"1.168135798","rc":[{"batb":[[0,3.5,69.93],[1,3.45,71.36],[2,2,22.17]],"ltp":5.3,"tv":5091.28,"id":2249229},{"batb":[[0,1.23,10.06],[1,1.17,75],[2,1.16,990.19]],"ltp":1.26,"tv":16208.23,"id":5720747}]}]}
{"op":"mcm","clk":"1005068129","pt":1580640499717,"mc":[{"id":"1.168135798","rc":[{"batb":[[1,1.17,85.54]],"batl":[[0,1.28,7.57],[1,1.37,910.19],[2,1.41,840.19]],"ltp":1.26,"tv":16208.23,"id":5720747}]}]}
{"op":"mcm","clk":"1005068268","pt":1580640500819,"mc":[{"id":"1.168135798","rc":[{"trd":[[3.7,205.68]],"batb":[[2,2.68,612.87]],"ltp":3.7,"tv":5101.96,"id":2249229},{"trd":[[1.37,555.65]],"batl":[[0,1.37,881.34],[1,1.41,840.19],[2,1.41,0]],"ltp":1.37,"tv":16237.08,"id":5720747}],"tv":21339.05}]}
{"op":"mcm","clk":"1005068381","pt":1580640501809,"mc":[{"id":"1.168135798","rc":[{"batb":[[1,1.19,82.34],[2,1.17,85.54]],"ltp":1.37,"tv":16237.08,"id":5720747}]}]}
{"op":"mcm","clk":"1005068479","pt":1580640502804,"mc":[{"id":"1.168135798","rc":[{"batl":[[0,1.37,840.19],[1,1.41,1593.96],[2,1.42,638.83]],"ltp":1.37,"tv":16237.08,"id":5720747}]}]}
{"op":"mcm","clk":"1005068671","pt":1580640504729,"mc":[{"id":"1.168135798","rc":[{"batb":[[2,1.17,1113.96]],"ltp":1.37,"tv":16237.08,"id":5720747}]}]}
{"op":"mcm","clk":"1005068809","pt":1580640505721,"mc":[{"id":"1.168135798","rc":[{"batb":[[0,1.3,30.4],[1,1.23,10.06],[2,1.19,82.34]],"ltp":1.37,"tv":16237.08,"id":5720747}]}]}
{"op":"mcm","clk":"1005068931","pt":1580640506818,"mc":[{"id":"1.168135798","rc":[{"batl":[[0,1.36,840.19],[1,1.37,840.19],[2,1.41,1593.96]],"ltp":1.37,"tv":16237.08,"id":5720747}]}]}
{"op":"mcm","clk":"1005069049","pt":1580640507812,"mc":[{"id":"1.168135798","rc":[{"batb":[[2,2,22.17]],"ltp":3.7,"tv":5101.96,"id":2249229}]}]}
{"op":"mcm","clk":"1005069384","pt":1580640510721,"mc":[{"id":"1.168135798","rc":[{"trd":[[1.3,20]],"batb":[[0,1.3,20.4],[1,1.19,82.34],[2,1.17,75]],"ltp":1.3,"tv":16257.08,"id":5720747}],"tv":21359.05}]}
{"op":"mcm","clk":"1005069535","pt":1580640511755,"mc":[{"id":"1.168135798","rc":[{"trd":[[1.3,60.8]],"batb":[[0,1.19,82.34],[1,1.17,75],[2,1.16,150]],"batl":[[0,1.28,6.86],[1,1.36,840.19],[2,1.37,840.19]],"ltp":1.3,"tv":16297.88,"id":5720747}],"tv":21399.85}]}
{"op":"mcm","clk":"1005069664","pt":1580640512747,"mc":[{"id":"1.168135798","rc":[{"batb":[[0,1.17,75],[1,1.16,150],[2,1.12,21.63]],"ltp":1.3,"tv":16297.88,"id":5720747}]}]}
{"op":"mcm","clk":"1005069786","pt":1580640513744,"mc":[{"id":"1.168135798","rc":[{"batb":[[2,1.1,1210.21]],"batl":[[0,1.19,840.19],[1,1.24,840.19],[2,1.28,6.86]],"ltp":1.3,"tv":16297.88,"id":5720747}]}]}
{"op":"mcm","clk":"1005069913","pt":1580640514740,"mc":[{"id":"1.168135798","rc":[{"batb":[[0,1.1,1210.21],[1,1.09,2302.55],[2,1.05,68.71]],"batl":[[0,1.14,212.57],[1,1.19,840.19],[2,1.24,840.19]],"ltp":1.3,"tv":16297.88,"id":5720747}]}]}
{"op":"mcm","clk":"1005070023","pt":1580640515741,"mc":[{"id":"1.168135798","rc":[{"batl":[[0,1.12,3217.99],[1,1.14,212.57],[2,1.19,840.19]],"ltp":1.3,"tv":16297.88,"id":5720747}]}]}
{"op":"mcm","clk":"1005070262","pt":1580640517722,"mc":[{"id":"1.168135798","rc":[{"batb":[[0,2,22.17],[1,1.47,1125.69],[2,1.3,22.73]],"ltp":3.7,"tv":5101.96,"id":2249229},{"batl":[[2,1.28,6.86]],"ltp":1.3,"tv":16297.88,"id":5720747}]}]}
{"op":"mcm","clk":"1005070385","pt":1580640518762,"mc":[{"id":"1.168135798","rc":[{"batb":[[0,3.25,573.51],[1,2,22.17],[2,1.47,1125.69]],"ltp":3.7,"tv":5101.96,"id":2249229},{"batb":[[2,1.08,152.32]],"ltp":1.3,"tv":16297.88,"id":5720747}]}]}
{"op":"mcm","clk":"1005070606","pt":1580640520726,"mc":[{"id":"1.168135798","rc":[{"batb":[[0,1.11,11.15],[1,1.1,1210.21],[2,1.09,2302.55]],"ltp":1.3,"tv":16297.88,"id":5720747}]}]}
{"op":"mcm","clk":"1005070735","pt":1580640521767,"mc":[{"id":"1.168135798","rc":[{"batl":[[1,1.28,6.86],[2,1.28,0]],"ltp":1.3,"tv":16297.88,"id":5720747}]}]}
{"op":"mcm","clk":"1005070863","pt":1580640522756,"mc":[{"id":"1.168135798","rc":[{"trd":[[1.11,22.3]],"batb":[[0,1.1,1210.21],[1,1.09,2302.55],[2,1.08,152.32]],"batl":[[0,1.11,22.63],[1,1.12,3217.99],[2,1.28,6.86]],"ltp":1.11,"tv":16320.18,"id":5720747}],"tv":21422.15}]}
{"op":"mcm","clk":"1005071442","pt":1580640526754,"mc":[{"id":"1.168135798","rc":[{"trd":[[1.11,29.88]],"batl":[[0,1.11,18.84]],"ltp":1.11,"tv":16327.75,"id":5720747}],"tv":21429.72}]}
{"op":"mcm","clk":"1005071909","pt":1580640530777,"mc":[{"id":"1.168135798","rc":[{"trd":[[1.11,56.76]],"batl":[[0,1.11,5.4]],"ltp":1.11,"tv":16354.64,"id":5720747}],"tv":21456.61}]}
{"op":"mcm","clk":"1005072157","pt":1580640532749,"mc":[{"id":"1.168135798","rc":[{"trd":[[9.8,2.09]],"ltp":9.8,"tv":5104.06,"id":2249229},{"trd":[[1.1,337.35],[1.11,124.81],[1.12,19.06]],"batb":[[0,1.1,1041.53]],"batl":[[0,1.12,3208.46],[1,1.28,6.86],[2,1.28,0]],"ltp":1.1,"tv":16779.1,"id":5720747}],"tv":21883.16}]}
{"op":"mcm","clk":"1005072279","pt":1580640533785,"mc":[{"id":"1.168135798","rc":[{"batl":[[0,10,4.2]],"ltp":9.8,"tv":5104.06,"id":2249229},{"batb":[[0,1.1,1042.1]],"ltp":1.1,"tv":16779.1,"id":5720747}]}]}
{"op":"mcm","clk":"1005072407","pt":1580640534781,"mc":[{"id":"1.168135798","rc":[{"trd":[[10,0.71]],"batl":[[0,10,3.49]],"ltp":10.0,"tv":5104.77,"id":2249229},{"trd":[[1.11,132.38]],"batb":[[0,1.1,1041.53]],"ltp":1.11,"tv":16786.67,"id":5720747}],"tv":21891.45}]}
{"op":"mcm","clk":"1005072519","pt":1580640535770,"mc":[{"id":"1.168135798","rc":[{"batl":[[0,1.12,2815]],"ltp":1.11,"tv":16786.67,"id":5720747}]}]}
{"op":"mcm","clk":"1005072634","pt":1580640536766,"mc":[{"id":"1.168135798","rc":[{"batb":[[0,1.11,25],[1,1.1,1041.53],[2,1.09,2302.55]],"ltp":1.11,"tv":16786.67,"id":5720747}]}]}
{"op":"mcm","clk":"1005072774","pt":1580640537761,"mc":[{"id":"1.168135798","rc":[{"batl":[[0,10,13.49]],"ltp":10.0,"tv":5104.77,"id":2249229}]}]}
{"op":"mcm","clk":"1005072922","pt":1580640538755,"mc":[{"id":"1.168135798","rc":[{"trd":[[10,14.2]],"ltp":10.0,"tv":5118.26,"id":2249229},{"trd":[[1.11,303.88]],"batb":[[0,1.1,1041.53],[1,1.09,2472.52],[2,1.08,152.32]],"batl":[[0,1.11,426.4],[1,1.12,2815],[2,1.28,6.86]],"ltp":1.11,"tv":16958.17,"id":5720747}],"tv":22076.44}]}
{"op":"mcm","clk":"1005073078","pt":1580640539793,"mc":[{"id":"1.168135798","rc":[{"batl":[[0,10.5,3]],"ltp":10.0,"tv":5118.26,"id":2249229},{"trd":[[1.1,1137.35]],"batb":[[0,1.1,641.53]],"ltp":1.1,"tv":17758.17,"id":5720747}],"tv":22876.44}]}
{"op":"mcm","clk":"1005073202","pt":1580640540780,"mc":[{"id":"1.168135798","rc":[{"batl":[[0,1.11,626.4]],"ltp":1.1,"tv":17758.17,"id":5720747}]}]}
{"op":"mcm","clk":"1005073335","pt":1580640541778,"mc":[{"id":"1.168135798","rc":[{"trd":[[1.11,549.37]],"batb":[[0,1.1,651.53]],"batl":[[0,1.11,503.66]],"ltp":1.11,"tv":18003.66,"id":5720747}],"tv":23121.92}]}
{"op":"mcm","clk":"1005073615","pt":1580640543763,"mc":[{"id":"1.168135798","rc":[{"batb":[[0,6,34.97],[1,3.25,573.51],[2,2,22.17]],"ltp":10.0,"tv":5118.26,"id":2249229}]}]}
{"op":"mcm","clk":"1005073746","pt":1580640544799,"mc":[{"id":"1.168135798","rc":[{"trd":[[10,24.2]],"ltp":10.0,"tv":5128.26,"id":2249229},{"trd":[[1.11,720.26]],"batb":[[0,1.1,922.25],[1,1.09,2610.34],[2,1.07,2497.59]],"batl":[[0,1.11,655.36]],"ltp":1.11,"tv":18174.55,"id":5720747}],"tv":23302.82}]}
{"op":"mcm","clk":"1005074126","pt":1580640547767,"mc":[{"id":"1.168135798","rc":[{"trd":[[1.1,1207.93]],"batb":[[0,1.1,886.96]],"ltp":1.1,"tv":18245.13,"id":5720747}],"tv":23373.39}]}
{"op":"mcm","clk":"1005074403","pt":1580640549794,"mc":[{"id":"1.168135798","rc":[{"trd":[[10,27.2]],"ltp":10.0,"tv":5131.26,"id":2249229},{"trd":[[1.1,1375.97],[1.11,879.9]],"batb":[[0,1.1,802.94]],"batl":[[0,1.11,562.03]],"ltp":1.1,"tv":18572.81,"id":5720747}],"tv":23704.07}]}
{"op":"mcm","clk":"1005074539","pt":1580640550781,"mc":[{"id":"1.168135798","rc":[{"trd":[[1.11,887.47]],"batl":[[0,1.11,827.2]],"ltp":1.11,"tv":18580.38,"id":5720747}],"tv":23711.65}]}
{"op":"mcm","clk":"1005074675","pt":1580640551785,"mc":[{"id":"1.168135798","rc":[{"batl":[[0,1.11,847.88]],"ltp":1.11,"tv":18580.38,"id":5720747}]}]}
{"op":"mcm","clk":"1005074809","pt":1580640552729,"mc":[{"id":"1.168135798","rc":[{"trd":[[10,73.41]],"ltp":10.0,"tv":5177.47,"id":2249229},{"trd":[[1.11,1303.78]],"batl":[[0,1.11,431.57]],"ltp":1.11,"tv":18996.69,"id":5720747}],"tv":24174.17}]}
{"op":"mcm","clk":"1005074960","pt":1580640553719,"mc":[{"id":"1.168135798","rc":[{"trd":[[1.1,1407.59]],"batb":[[0,1.1,787.13]],"ltp":1.1,"tv":19028.32,"id":5720747}],"tv":24205.79}]}
{"op":"mcm","clk":"1005075103","pt":1580640554812,"mc":[{"id":"1.168135798","rc":[{"trd":[[1.1,1522.31],[1.11,1340.94]],"batb":[[0,1.1,729.77],[2,1.07,2694.32]],"batl":[[0,1.11,412.99]],"ltp":1.1,"tv":19180.19,"id":5720747}],"tv":24357.67}]}
{"op":"mcm","clk":"1005075397","pt":1580640556791,"mc":[{"id":"1.168135798","rc":[{"batb":[[0,1.1,907.84]],"batl":[[0,1.11,672.63]],"ltp":1.1,"tv":19180.19,"id":5720747}]}]}
{"op":"mcm","clk":"1005075517","pt":1580640557718,"mc":[{"id":"1.168135798","rc":[{"trd":[[1.1,1530.31],[1.11,1360.94]],"batb":[[0,1.1,903.84]],"batl":[[0,1.11,662.63]],"ltp":1.11,"tv":19208.19,"id":5720747}],"tv":24385.67}]}
{"op":"mcm","clk":"1005075671","pt":1580640558819,"mc":[{"id":"1.168135798","rc":[{"trd":[[1.1,1829.39],[1.11,1372.76]],"batb":[[0,1.1,754.3]],"batl":[[0,1.11,656.72]],"ltp":1.1,"tv":19519.09,"id":5720747}],"tv":24696.57}]}
{"op":"mcm","clk":"1005075912","pt":1580640560811,"mc":[{"id":"1.168135798","rc":[{"batb":[[0,1.1,830.02]],"ltp":1.1,"tv":19519.09,"id":5720747}]}]}
{"op":"mcm","clk":"1005076136","pt":1580640562791,"mc":[{"id":"1.168135798","rc":[{"batl":[[0,1.11,732.49]],"ltp":1.1,"tv":19519.09,"id":5720747}]}]}
{"op":"mcm","clk":"1005076235","pt":1580640563728,"mc":[{"id":"1.168135798","rc":[{"batb":[[0,1.1,1001.27]],"ltp":1.1,"tv":19519.09,"id":5720747}]}]}
{"op":"mcm","clk":"1005076363","pt":1580640564816,"mc":[{"id":"1.168135798","rc":[{"batb":[[0,3.25,573.51],[1,2,22.17],[2,1.47,1125.69]],"ltp":10.0,"tv":5177.47,"id":2249229},{"trd":[[1.1,2052.89],[1.11,1495.78]],"batb":[[0,1.1,889.52]],"batl":[[0,1.11,670.98]],"ltp":1.11,"tv":19865.61,"id":5720747}],"tv":25043.08}]}
{"op":"mcm","clk":"1005076497","pt":1580640565803,"mc":[{"id":"1.168135798","rc":[{"batl":[[0,10.5,37.81]],"ltp":10.0,"tv":5177.47,"id":2249229}]}]}
{"op":"mcm","clk":"1005076731","pt":1580640567729,"mc":[{"id":"1.168135798","rc":[{"batl":[[2,1.28,9.13]],"ltp":1.11,"tv":19865.61,"id":5720747}]}]}
{"op":"mcm","clk":"1005076856","pt":1580640568724,"mc":[{"id":"1.168135798","rc":[{"trd":[[10,78.41]],"ltp":10.0,"tv":5182.47,"id":2249229},{"trd":[[1.11,1540.83]],"batl":[[0,1.11,792.47]],"ltp":1.11,"tv":19910.66,"id":5720747}],"tv":25093.13}]}
{"op":"mcm","clk":"1005077267","pt":1580640571814,"mc":[{"id":"1.168135798","rc":[{"trd":[[1.11,1541.94]],"batl":[[0,1.11,791.92]],"ltp":1.11,"tv":19911.77,"id":5720747}],"tv":25094.24}]}
{"op":"mcm","clk":"1005077392","pt":1580640572814,"mc":[{"id":"1.168135798","rc":[{"trd":[[10,82.61]],"ltp":10.0,"tv":5186.67,"id":2249229},{"trd":[[1.11,1583.57]],"batl":[[0,1.11,752.18]],"ltp":1.11,"tv":19953.4,"id":5720747}],"tv":25140.07}]}
{"op":"mcm","clk":"1005077506","pt":1580640573812,"mc":[{"id":"1.168135798","rc":[{"trd":[[10,92.61]],"ltp":10.0,"tv":5196.67,"id":2249229},{"trd":[[1.11,1673.66]],"batl":[[0,1.11,662.09]],"ltp":1.11,"tv":20043.49,"id":5720747}],"tv":25240.16}]}
{"op":"mcm","clk":"1005077621","pt":1580640574811,"mc":[{"id":"1.168135798","rc":[{"trd":[[1.11,1693.66]],"batl":[[0,1.11,652.09]],"ltp":1.11,"tv":20063.49,"id":5720747}],"tv":25260.16}]}
{"op":"mcm","clk":"1005078101","pt":1580640578724,"mc":[{"id":"1.168135798","rc":[{"batb":[[1,1.47,1125.69],[2,1.3,22.73]],"ltp":10.0,"tv":5196.67,"id":2249229},{"batb":[[0,1.1,1021.54]],"batl":[[0,1.11,781.99]],"ltp":1.11,"tv":20063.49,"id":5720747}]}]}
{"op":"mcm","clk":"1005078225","pt":1580640579774,"mc":[{"id":"1.168135798","rc":[{"trd":[[10,104.61]],"ltp":10.0,"tv":5208.67,"id":2249229},{"trd":[[1.11,1801.77]],"batl":[[0,1.11,673.88]],"ltp":1.11,"tv":20171.6,"id":5720747}],"tv":25380.27}]}
{"op":"mcm","clk":"1005078619","pt":1580640582763,"mc":[{"id":"1.168135798","rc":[{"batb":[[1,1.3,22.73],[2,1.26,34.83]],"ltp":10.0,"tv":5208.67,"id":2249229}]}]}
{"op":"mcm","clk":"1005078728","pt":1580640583652,"mc":[{"id":"1.168135798","rc":[{"trd":[[1.11,1823.77]],"batl":[[0,1.11,662.88]],"ltp":1.11,"tv":20193.6,"id":5720747}],"tv":25402.27}]}
{"op":"mcm","clk":"1005079385","pt":1580640588739,"mc":[{"id":"1.168135798","rc":[{"trd":[[1.11,3149.55]],"batb":[[0,1.11,635.98],[1,1.1,1021.54],[2,1.09,2610.34]],"batl":[[0,1.12,2815],[1,1.28,9.13],[2,1.28,0]],"ltp":1.11,"tv":21519.38,"id":5720747}],"tv":26728.05}]}
{"op":"mcm","clk":"1005079511","pt":1580640589630,"mc":[{"id":"1.168135798","rc":[{"batb":[[0,1.11,735.98],[2,1.09,2472.52]],"ltp":1.11,"tv":21519.38,"id":5720747}]}]}
{"op":"mcm","clk":"1005079907","pt":1580640592764,"mc":[{"id":"1.168135798","rc":[{"batb":[[1,1.1,85.72],[2,1.07,2694.32]],"batl":[[0,1.28,9.13],[1,1.28,0]],"ltp":1.11,"tv":21519.38,"id":5720747}]}]}
{"op":"mcm","clk":"1005080036","pt":1580640593753,"mc":[{"id":"1.168135798","rc":[{"trd":[[1.11,4497.69]],"batb":[[0,1.11,61.91]],"ltp":1.11,"tv":22867.52,"id":5720747}],"tv":28076.19}]}
{"op":"mcm","clk":"1005080738","pt":1580640598773,"mc":[{"id":"1.168135798","rc":[{"batb":[[2,1.07,6291.28]],"batl":[[0,1.16,1337.62],[1,1.17,1869.99],[2,1.28,9.13]],"ltp":1.11,"tv":22867.52,"id":5720747}]}]}
{"op":"mcm","clk":"1005081303","pt":1580640602777,"mc":[{"id":"1.168135798","rc":[{"trd":[[1.11,4519.69]],"batb":[[0,1.11,50.91]],"ltp":1.11,"tv":22889.52,"id":5720747}],"tv":28098.19}]}
{"op":"mcm","clk":"1005081436","pt":1580640603774,"mc":[{"id":"1.168135798","rc":[{"batb":[[0,1.12,420.1],[1,1.11,50.91],[2,1.1,85.72]],"ltp":1.11,"tv":22889.52,"id":5720747}]}]}
{"op":"mcm","clk":"1005081703","pt":1580640605776,"mc":[{"id":"1.168135798","rc":[{"batb":[[0,1.11,50.91],[1,1.1,85.72],[2,1.07,6291.28]],"ltp":1.11,"tv":22889.52,"id":5720747}]}]}
{"op":"mcm","clk":"1005082402","pt":1580640610699,"mc":[{"id":"1.168135798","rc":[{"trd":[[1.16,2670.1]],"batb":[[1,1.1,10]],"batl":[[0,1.16,1336.35]],"ltp":1.16,"tv":22892.06,"id":5720747}],"tv":28100.73}]}
{"op":"mcm","clk":"1005082660","pt":1580640612797,"mc":[{"id":"1.168135798","rc":[{"batl":[[0,1.12,52],[1,1.16,1336.35],[2,1.17,1869.99]],"ltp":1.16,"tv":22892.06,"id":5720747}]}]}
{"op":"mcm","clk":"1005082769","pt":1580640613582,"mc":[{"id":"1.168135798","rc":[{"batb":[[0,1.11,126.63],[2,1.08,860.19]],"ltp":1.16,"tv":22892.06,"id":5720747}]}]}
{"op":"mcm","clk":"1005083062","pt":1580640615558,"mc":[{"id":"1.168135798","rc":[{"trd":[[1.12,123.06],[1.16,3322.27]],"batl":[[0,1.16,1010.26],[1,1.17,1869.99],[2,1.28,9.13]],"ltp":1.16,"tv":23648.23,"id":5720747}],"tv":28856.91}]}
{"op":"mcm","clk":"1005083951","pt":1580640621768,"mc":[{"id":"1.168135798","rc":[{"batl":[[0,1.16,1850.45]],"ltp":1.16,"tv":23648.23,"id":5720747}]}]}
{"op":"mcm","clk":"1005084071","pt":1580640622792,"mc":[{"id":"1.168135798","rc":[{"batb":[[0,1.11,50.91]],"batl":[[0,1.16,2073.99]],"ltp":1.16,"tv":23648.23,"id":5720747}]}]}
{"op":"mcm","clk":"1005084186","pt":1580640623784,"mc":[{"id":"1.168135798","rc":[{"batb":[[0,1.12,840.19],[1,1.11,50.91],[2,1.1,10]],"ltp":1.16,"tv":23648.23,"id":5720747}]}]}
{"op":"mcm","clk":"1005084316","pt":1580640624727,"mc":[{"id":"1.168135798","rc":[{"batb":[[1,1.11,891.1]],"ltp":1.16,"tv":23648.23,"id":5720747}]}]}
{"op":"mcm","clk":"1005084599","pt":1580640626804,"mc":[{"id":"1.168135798","rc":[{"batb":[[0,7.4,27.32],[1,3.25,573.51],[2,1.3,22.73]],"ltp":10.0,"tv":5208.67,"id":2249229}]}]}
{"op":"mcm","clk":"1005084730","pt":1580640627793,"mc":[{"id":"1.168135798","rc":[{"batb":[[0,7.4,54.63]],"ltp":10.0,"tv":5208.67,"id":2249229}]}]}
{"op":"mcm","clk":"1005085156","pt":1580640630781,"mc":[{"id":"1.168135798","rc":[{"batl":[[0,1.16,1233.8]],"ltp":1.16,"tv":23648.23,"id":5720747}]}]}
{"op":"mcm","clk":"1005085241","pt":1580640631422,"mc":[{"id":"1.168135798","rc":[{"batl":[[0,1.13,949],[1,1.16,1233.8],[2,1.17,1869.99]],"ltp":1.16,"tv":23648.23,"id":5720747}]}]}
{"op":"mcm","clk":"1005085655","pt":1580640634714,"mc":[{"id":"1.168135798","rc":[{"batb":[[0,3.25,573.51],[1,1.3,22.73],[2,1.26,34.83]],"ltp":10.0,"tv":5208.67,"id":2249229}]}]}
{"op":"mcm","clk":"1005085799","pt":1580640635730,"mc":[{"id":"1.168135798","rc":[{"trd":[[1.13,1898]],"batb":[[0,1.14,648.52],[1,1.13,2634.5],[2,1.12,840.19]],"batl":[[0,1.16,1233.8],[1,1.17,1869.99],[2,1.28,9.13]],"ltp":1.13,"tv":25546.23,"id":5720747}],"tv":30754.91}]}
{"op":"mcm","clk":"1005085953","pt":1580640636708,"mc":[{"id":"1.168135798","rc":[{"trd":[[1.14,2.02]],"batb":[[0,1.14,647.51],[2,1.12,1680.39]],"ltp":1.14,"tv":25548.26,"id":5720747}],"tv":30756.93}]}
{"op":"mcm","clk":"1005086260","pt":1580640638741,"mc":[{"id":"1.168135798","rc":[{"trd":[[1.14,135.45]],"batb":[[0,1.14,1265.28],[1,1.13,2901.37]],"batl":[[0,1.16,1491.17]],"ltp":1.14,"tv":25681.68,"id":5720747}],"tv":30890.35}]}
{"op":"mcm","clk":"1005086528","pt":1580640640638,"mc":[{"id":"1.168135798","rc":[{"batb":[[0,1.14,1132.05]],"batl":[[1,1.17,1614.87]],"ltp":1.14,"tv":25681.68,"id":5720747}]}]}
{"op":"mcm","clk":"1005086951","pt":1580640643811,"mc":[{"id":"1.168135798","rc":[{"trd":[[1.14,179.45],[1.16,3335.4]],"batb":[[0,1.14,1110.05],[1,1.13,3106.78]],"batl":[[0,1.16,1682.53]],"ltp":1.16,"tv":25738.8,"id":5720747}],"tv":30947.47}]}
{"op":"mcm","clk":"1005087408","pt":1580640647721,"mc":[{"id":"1.168135798","rc":[{"trd":[[7.2,2.52]],"ltp":7.2,"tv":5211.19,"id":2249229},{"trd":[[1.16,3351.05]],"batb":[[0,1.13,842.88],[1,1.12,1680.39],[2,1.11,840.19]],"batl":[[0,1.28,9.13],[1,1.17,0],[2,1.28,0]],"ltp":1.16,"tv":25754.45,"id":5720747}],"tv":30965.64}]}
{"op":"mcm","clk":"1005087640","pt":1580640649814,"mc":[{"id":"1.168135798","rc":[{"batb":[[0,1.13,2.69]],"ltp":1.16,"tv":25754.45,"id":5720747}]}]}
{"op":"mcm","clk":"1005087755","pt":1580640650803,"mc":[{"id":"1.168135798","rc":[{"batb":[[1,1.11,840.19],[2,1.1,850.19]],"ltp":1.16,"tv":25754.45,"id":5720747}]}]}
{"op":"mcm","clk":"1005087867","pt":1580640651817,"mc":[{"id":"1.168135798","rc":[{"batb":[[0,1.16,100],[1,1.13,2.69],[2,1.11,840.19]],"ltp":1.16,"tv":25754.45,"id":5720747}]}]}
{"op":"mcm","clk":"1005087962","pt":1580640652757,"mc":[{"id":"1.168135798","rc":[{"batl":[[0,1.23,1518.54],[1,1.24,1260.38],[2,1.28,9.13]],"ltp":1.16,"tv":25754.45,"id":5720747}]}]}
{"op":"mcm","clk":"1005088075","pt":1580640653746,"mc":[{"id":"1.168135798","rc":[{"batl":[[2,1.25,100]],"ltp":1.16,"tv":25754.45,"id":5720747}]}]}
{"op":"mcm","clk":"1005088313","pt":1580640655724,"mc":[{"id":"1.168135798","rc":[{"batl":[[2,1.28,9.13]],"ltp":1.16,"tv":25754.45,"id":5720747}]}]}
{"op":"mcm","clk":"1005088423","pt":1580640656715,"mc":[{"id":"1.168135798","rc":[{"batl":[[0,1.27,840.19],[1,1.28,9.13],[2,1.28,0]],"ltp":1.16,"tv":25754.45,"id":5720747}]}]}
{"op":"mcm","clk":"1005088537","pt":1580640657751,"mc":[{"id":"1.168135798","rc":[{"batb":[[2,1.11,1476.55]],"ltp":1.16,"tv":25754.45,"id":5720747}]}]}
{"op":"mcm","clk":"1005088660","pt":1580640658737,"mc":[{"id":"1.168135798","rc":[{"batb":[[0,5.4,39.73],[1,3.25,573.51],[2,1.3,22.73]],"ltp":7.2,"tv":5211.19,"id":2249229},{"batb":[[2,1.12,840.19]],"ltp":1.16,"tv":25754.45,"id":5720747}]}]}
{"op":"mcm","clk":"1005088784","pt":1580640659731,"mc":[{"id":"1.168135798","rc":[{"batb":[[0,5.4,79.47]],"ltp":7.2,"tv":5211.19,"id":2249229},{"batl":[[0,1.22,100],[1,1.27,840.19],[2,1.28,9.13]],"ltp":1.16,"tv":25754.45,"id":5720747}]}]}
{"op":"mcm","clk":"1005088880","pt":1580640660617,"mc":[{"id":"1.168135798","rc":[{"batl":[[0,7.2,7.6]],"ltp":7.2,"tv":5211.19,"id":2249229},{"batl":[[0,1.27,840.19],[1,1.28,9.13],[2,1.28,0]],"ltp":1.16,"tv":25754.45,"id":5720747}]}]}
{"op":"mcm","clk":"1005089004","pt":1580640661714,"mc":[{"id":"1.168135798","rc":[{"batl":[[0,1.26,70],[1,1.27,840.19],[2,1.28,9.13]],"ltp":1.16,"tv":25754.45,"id":5720747}]}]}
{"op":"mcm","clk":"1005089110","pt":1580640662761,"mc":[{"id":"1.168135798","rc":[{"trd":[[5.4,0.46]],"batb":[[0,5.4,79.01]],"ltp":5.4,"tv":5211.65,"id":2249229},{"trd":[[1.23,1685.03]],"ltp":1.23,"tv":25756.45,"id":5720747}],"tv":30968.1}]}
{"op":"mcm","clk":"1005089599","pt":1580640666766,"mc":[{"id":"1.168135798","rc":[{"batl":[[0,1.23,1490.79],[1,1.24,1260.42],[2,1.26,70]],"ltp":1.23,"tv":25756.45,"id":5720747}]}]}
{"op":"mcm","clk":"1005089999","pt":1580640669759,"mc":[{"id":"1.168135798","rc":[{"batl":[[2,1.27,840.19]],"ltp":1.23,"tv":25756.45,"id":5720747}]}]}
{"op":"mcm","clk":"1005090480","pt":1580640673763,"mc":[{"id":"1.168135798","rc":[{"trd":[[1.16,3356.05]],"batb":[[0,1.16,97.5]],"batl":[[0,1.23,1560.79]],"ltp":1.16,"tv":25761.45,"id":5720747}],"tv":30973.1}]}
{"op":"mcm","clk":"1005090606","pt":1580640674745,"mc":[{"id":"1.168135798","rc":[{"trd":[[5.4,5.72]],"batb":[[0,5.4,76.38]],"ltp":5.4,"tv":5216.91,"id":2249229},{"batb":[[1,1.12,840.19],[2,1.11,1546.09]],"ltp":1.16,"tv":25761.45,"id":5720747}],"tv":30978.37}]}
{"op":"mcm","clk":"1005090857","pt":1580640676764,"mc":[{"id":"1.168135798","rc":[{"trd":[[5.4,9.72]],"batb":[[0,5.4,74.38]],"ltp":5.4,"tv":5220.91,"id":2249229},{"trd":[[1.23,1689.03]],"batl":[[0,1.22,2.27],[1,1.23,1558.79],[2,1.24,1260.42]],"ltp":1.23,"tv":25765.45,"id":5720747}],"tv":30986.37}]}
{"op":"mcm","clk":"1005090968","pt":1580640677751,"mc":[{"id":"1.168135798","rc":[{"batb":[[1,1.11,705.89],[2,1.1,3508.86]],"ltp":1.23,"tv":25765.45,"id":5720747}]}]}
{"op":"mcm","clk":"1005091079","pt":1580640678790,"mc":[{"id":"1.168135798","rc":[{"batb":[[1,1.11,69.53],[2,1.1,10]],"batl":[[1,1.23,70],[2,1.27,840.19]],"ltp":1.23,"tv":25765.45,"id":5720747}]}]}
{"op":"mcm","clk":"1005091190","pt":1580640679580,"mc":[{"id":"1.168135798","rc":[{"trd":[[7.2,10.12]],"ltp":7.2,"tv":5228.51,"id":2249229},{"trd":[[1.16,3598.24]],"batb":[[0,1.11,69.53],[1,1.1,10],[2,1.08,20]],"batl":[[0,1.14,695.5],[1,1.22,2.27],[2,1.23,70]],"ltp":1.16,"tv":26007.65,"id":5720747}],"tv":31236.16}]}
{"op":"mcm","clk":"1005091337","pt":1580640680783,"mc":[{"id":"1.168135798","rc":[{"trd":[[1.14,226.02]],"batb":[[0,1.1,10],[1,1.08,20],[2,1.05,68.71]],"batl":[[0,1.16,844.4]],"ltp":1.14,"tv":26054.23,"id":5720747}],"tv":31282.74}]}
{"op":"mcm","clk":"1005091564","pt":1580640682690,"mc":[{"id":"1.168135798","rc":[{"batb":[[0,1.1,3508.86]],"batl":[[0,1.12,1323.31],[1,1.13,2101.19],[2,1.16,844.4]],"ltp":1.14,"tv":26054.23,"id":5720747}]}]}
{"op":"mcm","clk":"1005091694","pt":1580640683791,"mc":[{"id":"1.168135798","rc":[{"trd":[[9.2,90]],"ltp":9.2,"tv":5318.51,"id":2249229},{"trd":[[1.12,862.35]],"batl":[[0,1.12,584.02],[1,1.13,2094.37]],"ltp":1.12,"tv":26793.52,"id":5720747}],"tv":32112.03}]}
{"op":"mcm","clk":"1005091826","pt":1580640684784,"mc":[{"id":"1.168135798","rc":[{"batb":[[2,1.07,196.73]],"ltp":1.12,"tv":26793.52,"id":5720747}]}]}
{"op":"mcm","clk":"1005091932","pt":1580640685676,"mc":[{"id":"1.168135798","rc":[{"batb":[[0,1.1,3685.59]],"batl":[[2,1.16,840.19]],"ltp":1.12,"tv":26793.52,"id":5720747}]}]}
{"op":"mcm","clk":"1005092159","pt":1580640687663,"mc":[{"id":"1.168135798","rc":[{"batb":[[0,1.11,175.13],[1,1.1,3685.59],[2,1.08,20]],"batl":[[0,1.12,1111.35],[1,1.13,2304.46]],"ltp":1.12,"tv":26793.52,"id":5720747}]}]}
{"op":"mcm","clk":"1005092262","pt":1580640688797,"mc":[{"id":"1.168135798","rc":[{"batb":[[0,3.25,573.51],[1,1.3,22.73],[2,1.26,34.83]],"ltp":9.2,"tv":5318.51,"id":2249229}]}]}
{"op":"mcm","clk":"1005092489","pt":1580640690807,"mc":[{"id":"1.168135798","rc":[{"trd":[[9.2,92]],"ltp":9.2,"tv":5320.51,"id":2249229},{"trd":[[1.12,878.78]],"batl":[[0,1.12,1094.92]],"ltp":1.12,"tv":26809.95,"id":5720747}],"tv":32130.46}]}
{"op":"mcm","clk":"1005092620","pt":1580640691809,"mc":[{"id":"1.168135798","rc":[{"trd":[[1.11,4536.49],[1.12,929.6]],"batb":[[0,1.11,166.73],[2,1.09,840.19]],"batl":[[0,1.12,1069.51]],"ltp":1.12,"tv":26877.57,"id":5720747}],"tv":32198.08}]}
{"op":"mcm","clk":"1005092733","pt":1580640692805,"mc":[{"id":"1.168135798","rc":[{"trd":[[1.12,939.8]],"batl":[[0,1.12,1064.41]],"ltp":1.12,"tv":26887.77,"id":5720747}],"tv":32208.28}]}
{"op":"mcm","clk":"1005092819","pt":1580640693803,"mc":[{"id":"1.168135798","rc":[{"batb":[[1,1.1,186.73]],"batl":[[0,1.16,840.19],[1,1.19,840.19],[2,1.22,2.27]],"ltp":1.12,"tv":26887.77,"id":5720747}]}]}
{"op":"mcm","clk":"1005092929","pt":1580640694795,"mc":[{"id":"1.168135798","rc":[{"batb":[[0,7.4,27.32],[1,3.25,573.51],[2,1.3,22.73]],"ltp":9.2,"tv":5320.51,"id":2249229}]}]}
{"op":"mcm","clk":"1005093020","pt":1580640695810,"mc":[{"id":"1.168135798","rc":[{"batl":[[0,9.2,1.77]],"ltp":9.2,"tv":5320.51,"id":2249229},{"trd":[[1.11,4556.49]],"batb":[[0,1.11,156.73]],"ltp":1.11,"tv":26907.76,"id":5720747}],"tv":32228.28}]}
{"op":"mcm","clk":"1005093137","pt":1580640696804,"mc":[{"id":"1.168135798","rc":[{"batb":[[0,1.12,50],[1,1.11,156.73],[2,1.1,186.73]],"ltp":1.11,"tv":26907.76,"id":5720747}]}]}
{"op":"mcm","clk":"1005093467","pt":1580640699785,"mc":[{"id":"1.168135798","rc":[{"trd":[[1.12,945.8]],"batb":[[0,1.12,122.72]],"batl":[[1,1.18,1116.41],[2,1.19,2499.73]],"ltp":1.12,"tv":26913.76,"id":5720747}],"tv":32234.28}]}
{"op":"mcm","clk":"1005093836","pt":1580640702814,"mc":[{"id":"1.168135798","rc":[{"batb":[[0,3.25,573.51],[1,1.3,22.73],[2,1.26,34.83]],"ltp":9.2,"tv":5320.51,"id":2249229},{"batl":[[1,1.19,840.19],[2,1.22,2.27]],"ltp":1.12,"tv":26913.76,"id":5720747}]}]}
{"op":"mcm","clk":"1005094103","pt":1580640704811,"mc":[{"id":"1.168135798","rc":[{"batb":[[0,6.6,62.44],[1,3.25,573.51],[2,1.3,22.73]],"ltp":9.2,"tv":5320.51,"id":2249229}]}]}
{"op":"mcm","clk":"1005094215","pt":1580640705802,"mc":[{"id":"1.168135798","rc":[{"batb":[[1,1.11,3624.07]],"batl":[[0,1.13,718.37],[1,1.14,2366.74],[2,1.16,840.19]],"ltp":1.12,"tv":26913.76,"id":5720747}]}]}
{"op":"mcm","clk":"1005094319","pt":1580640706795,"mc":[{"id":"1.168135798","rc":[{"trd":[[1.12,965.8]],"batb":[[0,1.12,112.72],[1,1.11,156.73]],"batl":[[0,1.16,840.19],[1,1.19,840.19],[2,1.22,2.27]],"ltp":1.12,"tv":26933.76,"id":5720747}],"tv":32254.28}]}
{"op":"mcm","clk":"1005094888","pt":1580640711804,"mc":[{"id":"1.168135798","rc":[{"batl":[[1,1.18,1118.07],[2,1.19,2499.73]],"ltp":1.12,"tv":26933.76,"id":5720747}]}]}
{"op":"mcm","clk":"1005095623","pt":1580640717717,"mc":[{"id":"1.168135798","rc":[{"trd":[[1.16,3628.54]],"batl":[[0,1.16,825.05]],"ltp":1.16,"tv":26964.06,"id":5720747}],"tv":32284.57}]}
{"op":"mcm","clk":"1005096268","pt":1580640722741,"mc":[{"id":"1.168135798","rc":[{"batb":[[0,7,10],[1,6.6,62.44],[2,3.25,573.51]],"ltp":9.2,"tv":5320.51,"id":2249229}]}]}
{"op":"mcm","clk":"1005097355","pt":1580640732636,"mc":[{"id":"1.168135798","rc":[{"trd":[[1.12,969.16]],"batb":[[0,1.12,111.04],[1,1.1,10],[2,1.08,894.99]],"ltp":1.12,"tv":26967.42,"id":5720747}],"tv":32287.93}]}
{"op":"mcm","clk":"1005097476","pt":1580640733739,"mc":[{"id":"1.168135798","rc":[{"batb":[[2,1.08,20]],"ltp":1.12,"tv":26967.42,"id":5720747}]}]}
{"op":"mcm","clk":"1005097686","pt":1580640735555,"mc":[{"id":"1.168135798","rc":[{"trd":[[1.12,1191.25]],"batb":[[0,1.1,10],[1,1.08,20],[2,1.07,3793.69]],"batl":[[0,1.11,729.15],[1,1.16,825.05],[2,1.18,1118.07]],"ltp":1.12,"tv":27189.51,"id":5720747}],"tv":32510.03}]}
{"op":"mcm","clk":"1005097807","pt":1580640736543,"mc":[{"id":"1.168135798","rc":[{"batl":[[0,1.12,1244.8]],"ltp":1.12,"tv":27189.51,"id":5720747}]}]}
{"op":"mcm","clk":"1005097947","pt":1580640737743,"mc":[{"id":"1.168135798","rc":[{"batl":[[0,1.12,404.61]],"ltp":1.12,"tv":27189.51,"id":5720747}]}]}
{"op":"mcm","clk":"1005098368","pt":1580640741748,"mc":[{"id":"1.168135798","rc":[{"batb":[[1,1.08,312.52]],"batl":[[0,1.16,825.05],[1,1.18,1118.07],[2,1.19,2499.73]],"ltp":1.12,"tv":27189.51,"id":5720747}]}]}
{"op":"mcm","clk":"1005098478","pt":1580640742741,"mc":[{"id":"1.168135798","rc":[{"batb":[[2,1.07,196.73]],"batl":[[1,1.19,840.19],[2,1.22,2.27]],"ltp":1.12,"tv":27189.51,"id":5720747}]}]}
{"op":"mcm","clk":"1005098697","pt":1580640744729,"mc":[{"id":"1.168135798","rc":[{"batl":[[0,12,27.73]],"ltp":9.2,"tv":5320.51,"id":2249229},{"trd":[[1.1,2072.89]],"batb":[[0,1.08,312.52],[1,1.07,196.73],[2,1.06,840.19]],"batl":[[0,1.1,394.61],[1,1.16,825.05],[2,1.19,840.19]],"ltp":1.1,"tv":27209.51,"id":5720747}],"tv":32530.03}]}
{"op":"mcm","clk":"1005099168","pt":1580640748749,"mc":[{"id":"1.168135798","rc":[{"batl":[[0,1.16,825.05],[1,1.19,840.19],[2,1.22,2.27]],"ltp":1.1,"tv":27209.51,"id":5720747}]}]}
{"op":"mcm","clk":"1005099396","pt":1580640750573,"mc":[{"id":"1.168135798","rc":[{"batb":[[2,1.3,22.73]],"batl":[[0,11,18.48],[1,12,27.73]],"ltp":9.2,"tv":5320.51,"id":2249229},{"batb":[[1,1.06,840.19],[2,1.05,68.71]],"ltp":1.1,"tv":27209.51,"id":5720747}]}]}
{"op":"mcm","clk":"1005099633","pt":1580640752762,"mc":[{"id":"1.168135798","rc":[{"trd":[[11,18.48],[12,19.06]],"batl":[[0,12,8.67],[1,12,0]],"ltp":12.0,"tv":5358.05,"id":2249229},{"trd":[[1.09,209.77],[1.1,2257.73]],"ltp":1.09,"tv":27604.12,"id":5720747}],"tv":32962.18}]}
{"op":"mcm","clk":"1005099759","pt":1580640753757,"mc":[{"id":"1.168135798","rc":[{"batb":[[0,1.1,50],[1,1.08,312.52],[2,1.06,840.19]],"ltp":1.09,"tv":27604.12,"id":5720747}]}]}
{"op":"mcm","clk":"1005100007","pt":1580640755786,"mc":[{"id":"1.168135798","rc":[{"batb":[[0,1.1,52.69]],"batl":[[0,1.22,2.27],[1,1.28,6.86],[2,1.22,0]],"ltp":1.09,"tv":27604.12,"id":5720747}]}]}
{"op":"mcm","clk":"1005100118","pt":1580640756776,"mc":[{"id":"1.168135798","rc":[{"trd":[[12,27.73]],"ltp":12.0,"tv":5366.72,"id":2249229},{"trd":[[1.09,305.22],[1.1,2363.11]],"batb":[[0,1.08,312.52],[1,1.06,840.19],[2,1.05,68.71]],"batl":[[0,1.09,3212.64],[1,1.22,2.27],[2,1.28,6.86]],"ltp":1.09,"tv":27804.95,"id":5720747}],"tv":33171.68}]}
{"op":"mcm","clk":"1005100231","pt":1580640757765,"mc":[{"id":"1.168135798","rc":[{"trd":[[1.09,3666]],"batl":[[0,1.09,1532.25]],"ltp":1.09,"tv":31165.73,"id":5720747}],"tv":36532.46}]}
{"op":"mcm","clk":"1005100366","pt":1580640758755,"mc":[{"id":"1.168135798","rc":[{"batb":[[1,1.3,22.73],[2,1.26,34.83]],"ltp":12.0,"tv":5366.72,"id":2249229}]}]}
{"op":"mcm","clk":"1005100484","pt":1580640759795,"mc":[{"id":"1.168135798","rc":[{"trd":[[12,29.49]],"ltp":12.0,"tv":5368.49,"id":2249229},{"trd":[[1.09,3685.48]],"batl":[[0,1.09,1512.77]],"ltp":1.09,"tv":31185.21,"id":5720747}],"tv":36553.7}]}
{"op":"mcm","clk":"1005100607","pt":1580640760791,"mc":[{"id":"1.168135798","rc":[{"trd":[[1.09,3688.84]],"batl":[[0,1.09,1511.09]],"ltp":1.09,"tv":31188.57,"id":5720747}],"tv":36557.06}]}
{"op":"mcm","clk":"1005100730","pt":1580640761787,"mc":[{"id":"1.168135798","rc":[{"trd":[[1.09,6711.02]],"batb":[[0,1.09,169.3],[1,1.08,312.52],[2,1.06,840.19]],"batl":[[0,1.22,2.27],[1,1.28,6.86],[2,1.28,0]],"ltp":1.09,"tv":34210.75,"id":5720747}],"tv":39579.24}]}
{"op":"mcm","clk":"1005100862","pt":1580640762780,"mc":[{"id":"1.168135798","rc":[{"batb":[[0,1.09,1849.69]],"ltp":1.09,"tv":34210.75,"id":5720747}]}]}
{"op":"mcm","clk":"1005100979","pt":1580640763784,"mc":[{"id":"1.168135798","rc":[{"batb":[[0,1.09,2689.88],[2,1.06,854.19]],"ltp":1.09,"tv":34210.75,"id":5720747}]}]}
{"op":"mcm","clk":"1005101080","pt":1580640764570,"mc":[{"id":"1.168135798","rc":[{"batb":[[0,1.09,3530.08]],"ltp":1.09,"tv":34210.75,"id":5720747}]}]}
{"op":"mcm","clk":"1005101233","pt":1580640765768,"mc":[{"id":"1.168135798","rc":[{"batb":[[0,1.09,4370.27]],"ltp":1.09,"tv":34210.75,"id":5720747}]}]}
{"op":"mcm","clk":"1005101354","pt":1580640766802,"mc":[{"id":"1.168135798","rc":[{"batl":[[0,13,9.24]],"ltp":12.0,"tv":5368.49,"id":2249229},{"batb":[[0,1.1,200],[1,1.09,4370.27],[2,1.08,312.52]],"ltp":1.09,"tv":34210.75,"id":5720747}]}]}
{"op":"mcm","clk":"1005101512","pt":1580640767692,"mc":[{"id":"1.168135798","rc":[{"batb":[[2,1.08,1152.72]],"ltp":1.09,"tv":34210.75,"id":5720747}]}]}
{"op":"mcm","clk":"1005101635","pt":1580640768785,"mc":[{"id":"1.168135798","rc":[{"batb":[[0,1.09,4370.27],[1,1.08,1152.72],[2,1.06,854.19]],"ltp":1.09,"tv":34210.75,"id":5720747}]}]}
{"op":"mcm","clk":"1005101866","pt":1580640770770,"mc":[{"id":"1.168135798","rc":[{"batb":[[0,1.08,1152.72],[1,1.06,854.19],[2,1.05,168.71]],"ltp":1.09,"tv":34210.75,"id":5720747}]}]}
{"op":"mcm","clk":"1005102017","pt":1580640771703,"mc":[{"id":"1.168135798","rc":[{"batl":[[0,1.15,840.19],[1,1.16,840.19],[2,1.22,2.27]],"ltp":1.09,"tv":34210.75,"id":5720747}]}]}
{"op":"mcm","clk":"1005102228","pt":1580640773778,"mc":[{"id":"1.168135798","rc":[{"batb":[[1,1.07,840.19],[2,1.06,854.19]],"ltp":1.09,"tv":34210.75,"id":5720747}]}]}
{"op":"mcm","clk":"1005102784","pt":1580640778812,"mc":[{"id":"1.168135798","rc":[{"trd":[[7.6,2]],"ltp":7.6,"tv":5370.49,"id":2249229},{"trd":[[1.15,13.22]],"batl":[[0,1.15,826.98]],"ltp":1.15,"tv":34223.97,"id":5720747}],"tv":39594.46}]}
{"op":"mcm","clk":"1005103115","pt":1580640781688,"mc":[{"id":"1.168135798","rc":[{"batb":[[1,1.07,4437.15]],"batl":[[2,1.18,1118.07]],"ltp":1.15,"tv":34223.97,"id":5720747}]}]}
{"op":"mcm","clk":"1005103359","pt":1580640783725,"mc":[{"id":"1.168135798","rc":[{"batb":[[0,1.09,2520.58],[1,1.08,1152.72],[2,1.07,6957.74]],"ltp":1.15,"tv":34223.97,"id":5720747}]}]}
{"op":"mcm","clk":"1005103564","pt":1580640785405,"mc":[{"id":"1.168135798","rc":[{"batb":[[0,1.09,2909.46]],"ltp":1.15,"tv":34223.97,"id":5720747}]}]}
{"op":"mcm","clk":"1005104307","pt":1580640791799,"mc":[{"id":"1.168135798","rc":[{"batl":[[0,1.18,1118.07],[1,1.19,1659.54],[2,1.22,2.27]],"ltp":1.15,"tv":34223.97,"id":5720747}]}]}
{"op":"mcm","clk":"1005104518","pt":1580640793820,"mc":[{"id":"1.168135798","rc":[{"batb":[[2,1.07,3360.78]],"ltp":1.15,"tv":34223.97,"id":5720747}]}]}
{"op":"mcm","clk":"1005104779","pt":1580640795792,"mc":[{"id":"1.168135798","rc":[{"batb":[[0,1.11,2520.58],[1,1.1,2520.58],[2,1.09,2909.46]],"ltp":1.15,"tv":34223.97,"id":5720747}]}]}
{"op":"mcm","clk":"1005104851","pt":1580640796519,"mc":[{"id":"1.168135798","rc":[{"batb":[[0,1.16,1142.03],[1,1.15,2194.78],[2,1.11,2520.58]],"ltp":1.15,"tv":34223.97,"id":5720747}]}]}
{"op":"mcm","clk":"1005105208","pt":1580640799649,"mc":[{"id":"1.168135798","rc":[{"batb":[[1,3,598.18],[2,1.3,22.73]],"ltp":7.6,"tv":5370.49,"id":2249229},{"batb":[[2,1.11,2590.12]],"ltp":1.15,"tv":34223.97,"id":5720747}]}]}
{"op":"mcm","clk":"1005105441","pt":1580640801805,"mc":[{"id":"1.168135798","rc":[{"trd":[[1.15,3203.24],[1.16,5912.59]],"batb":[[0,1.15,599.77],[1,1.11,2590.12],[2,1.1,2870.57]],"ltp":1.15,"tv":39698.04,"id":5720747}],"tv":45068.54}]}
{"op":"mcm","clk":"1005105546","pt":1580640802739,"mc":[{"id":"1.168135798","rc":[{"batb":[[1,1.11,2908.3]],"batl":[[1,1.19,1201.49]],"ltp":1.15,"tv":39698.04,"id":5720747}]}]}
{"op":"mcm","clk":"1005105775","pt":1580640804728,"mc":[{"id":"1.168135798","rc":[{"batb":[[1,5,43.71],[2,3,598.18]],"ltp":7.6,"tv":5370.49,"id":2249229}]}]}
{"op":"mcm","clk":"1005105892","pt":1580640805650,"mc":[{"id":"1.168135798","rc":[{"batb":[[0,1.15,2522.65],[1,1.14,831.31],[2,1.11,2908.3]],"batl":[[0,1.18,2049.97]],"ltp":1.15,"tv":39698.04,"id":5720747}]}]}
{"op":"mcm","clk":"1005106229","pt":1580640808737,"mc":[{"id":"1.168135798","rc":[{"batb":[[0,1.15,9.93],[1,1.11,2908.3],[2,1.1,2870.57]],"batl":[[0,1.22,2.27],[1,1.28,6.86],[2,1.22,0]],"ltp":1.15,"tv":39698.04,"id":5720747}]}]}
{"op":"mcm","clk":"1005106430","pt":1580640810730,"mc":[{"id":"1.168135798","rc":[{"batl":[[1,1.24,2520.58],[2,1.28,6.86]],"ltp":1.15,"tv":39698.04,"id":5720747}]}]}
{"op":"mcm","clk":"1005106539","pt":1580640811729,"mc":[{"id":"1.168135798","rc":[{"trd":[[7,1]],"batb":[[0,7,9]],"ltp":7.0,"tv":5371.49,"id":2249229},{"trd":[[1.17,194.54]],"batb":[[1,1.11,4710.87],[2,1.1,4550.47]],"batl":[[2,1.27,1408.44]],"ltp":1.17,"tv":39704.04,"id":5720747}],"tv":45075.54}]}
{"op":"mcm","clk":"1005106888","pt":1580640814756,"mc":[{"id":"1.168135798","rc":[{"batb":[[1,3,598.18],[2,1.3,22.73]],"ltp":7.0,"tv":5371.49,"id":2249229}]}]}
{"op":"mcm","clk":"1005107009","pt":1580640815755,"mc":[{"id":"1.168135798","rc":[{"trd":[[7,1.5]],"batb":[[0,7,8.5]],"ltp":7.0,"tv":5371.99,"id":2249229},{"trd":[[1.17,197.54]],"ltp":1.17,"tv":39707.04,"id":5720747}],"tv":45079.04}]}
{"op":"mcm","clk":"1005107123","pt":1580640816746,"mc":[{"id":"1.168135798","rc":[{"batb":[[1,4.8,46.01],[2,3,598.18]],"ltp":7.0,"tv":5371.99,"id":2249229},{"batb":[[1,1.11,2908.3],[2,1.1,2870.57]],"batl":[[2,1.28,6.86]],"ltp":1.17,"tv":39707.04,"id":5720747}]}]}
{"op":"mcm","clk":"1005107244","pt":1580640817737,"mc":[{"id":"1.168135798","rc":[{"batb":[[0,1.15,2530.52],[1,1.14,2520.58],[2,1.11,2908.3]],"ltp":1.17,"tv":39707.04,"id":5720747}]}]}
{"op":"mcm","clk":"1005107336","pt":1580640818568,"mc":[{"id":"1.168135798","rc":[{"trd":[[7,18.5]],"batb":[[0,4.8,92.02],[1,3,598.18],[2,1.3,22.73]],"batl":[[0,7,41.5]],"ltp":7.0,"tv":5388.99,"id":2249229}],"tv":45096.04}]}
{"op":"mcm","clk":"1005107463","pt":1580640819665,"mc":[{"id":"1.168135798","rc":[{"trd":[[1.17,597.54]],"ltp":1.17,"tv":40107.04,"id":5720747}],"tv":45496.04}]}
{"op":"mcm","clk":"1005107727","pt":1580640821752,"mc":[{"id":"1.168135798","rc":[{"batl":[[0,6.8,7.57],[1,7,41.5]],"ltp":7.0,"tv":5388.99,"id":2249229}]}]}
{"op":"mcm","clk":"1005107868","pt":1580640822746,"mc":[{"id":"1.168135798","rc":[{"trd":[[7,20.49]],"batl":[[0,7,39.51],[1,7,0]],"ltp":7.0,"tv":5390.98,"id":2249229},{"trd":[[1.16,5924.59]],"batb":[[2,1.11,4710.87]],"batl":[[2,1.27,1408.44]],"ltp":1.16,"tv":40119.04,"id":5720747}],"tv":45510.03}]}
{"op":"mcm","clk":"1005108261","pt":1580640825772,"mc":[{"id":"1.168135798","rc":[{"batb":[[0,1.17,5],[1,1.15,2530.52],[2,1.14,2520.58]],"ltp":1.16,"tv":40119.04,"id":5720747}]}]}
{"op":"mcm","clk":"1005108509","pt":1580640827759,"mc":[{"id":"1.168135798","rc":[{"batb":[[0,1.15,2530.52],[1,1.14,2520.58],[2,1.11,4710.87]],"ltp":1.16,"tv":40119.04,"id":5720747}]}]}
