{"op":"mcm","clk":"988026418","pt":1580473742115,"mc":[{"id":"1.168135786","marketDefinition":{"bspMarket":false,"turnInPlayEnabled":true,"persistenceEnabled":true,"marketBaseRate":5.0,"eventId":"29678823","eventTypeId":"2","numberOfWinners":1,"bettingType":"ODDS","marketType":"SET_WINNER","marketTime":"2020-02-02T08:30:00.000Z","suspendTime":"2020-02-02T08:30:00.000Z","bspReconciled":false,"complete":true,"inPlay":false,"crossMatching":false,"runnersVoidable":false,"numberOfActiveRunners":2,"betDelay":0,"status":"OPEN","runners":[{"status":"ACTIVE","sortPriority":1,"id":5720747,"name":"Dominic Thiem"},{"status":"ACTIVE","sortPriority":2,"id":2249229,"name":"Novak Djokovic"}],"regulators":["MR_INT"],"countryCode":"AU","discountAllowed":false,"timezone":"GMT","openDate":"2020-02-02T08:30:00.000Z","version":3143005249,"name":"Set 1 Winner","eventName":"Thiem v Djokovic"},"rc":[{"batb":[[0,1.01,20]],"ltp":0.0,"tv":0.0,"id":2249229},{"batb":[[0,1.01,20]],"ltp":0.0,"tv":0.0,"id":5720747}]}]}
{"op":"mcm","clk":"988026715","pt":1580473744836,"mc":[{"id":"1.168135786","marketDefinition":{"bspMarket":false,"turnInPlayEnabled":true,"persistenceEnabled":true,"marketBaseRate":5.0,"eventId":"29678823","eventTypeId":"2","numberOfWinners":1,"bettingType":"ODDS","marketType":"SET_WINNER","marketTime":"2020-02-02T08:30:00.000Z","suspendTime":"2020-02-02T08:30:00.000Z","bspReconciled":false,"complete":true,"inPlay":false,"crossMatching":false,"runnersVoidable":false,"numberOfActiveRunners":2,"betDelay":0,"status":"OPEN","runners":[{"status":"ACTIVE","sortPriority":1,"id":5720747,"name":"Dominic Thiem"},{"status":"ACTIVE","sortPriority":2,"id":2249229,"name":"Novak Djokovic"}],"regulators":["MR_INT"],"countryCode":"AU","discountAllowed":true,"timezone":"GMT","openDate":"2020-02-02T08:30:00.000Z","version":3143005249,"name":"Set 1 Winner","eventName":"Thiem v Djokovic"}}]}
{"op":"mcm","clk":"988033857","pt":1580473817659,"mc":[{"id":"1.168135786","rc":[{"batb":[[0,1.01,10]],"ltp":0.0,"tv":0.0,"id":2249229},{"batb":[[0,1.01,10]],"ltp":0.0,"tv":0.0,"id":5720747}]}]}
{"op":"mcm","clk":"988043387","pt":1580473906280,"mc":[{"id":"1.168135786","rc":[{"batb":[[0,1.16,10],[1,1.01,10]],"ltp":0.0,"tv":0.0,"id":2249229}]}]}
{"op":"mcm","clk":"988149162","pt":1580474823831,"mc":[{"id":"1.168135786","rc":[{"batb":[[0,1.4,61.98],[1,1.16,10],[2,1.01,10]],"ltp":0.0,"tv":0.0,"id":2249229},{"batb":[[0,2.74,14.25],[1,1.01,10]],"ltp":0.0,"tv":0.0,"id":5720747}]}]}
{"op":"mcm","clk":"988152651","pt":1580474858790,"mc":[{"id":"1.168135786","marketDefinition":{"bspMarket":false,"turnInPlayEnabled":true,"persistenceEnabled":true,"marketBaseRate":5.0,"eventId":"29678823","eventTypeId":"2","numberOfWinners":1,"bettingType":"ODDS","marketType":"SET_WINNER","marketTime":"2020-02-02T08:30:00.000Z","suspendTime":"2020-02-02T08:30:00.000Z","bspReconciled":false,"complete":true,"inPlay":false,"crossMatching":true,"runnersVoidable":false,"numberOfActiveRunners":2,"betDelay":0,"status":"OPEN","runners":[{"status":"ACTIVE","sortPriority":1,"id":5720747,"name":"Dominic Thiem"},{"status":"ACTIVE","sortPriority":2,"id":2249229,"name":"Novak Djokovic"}],"regulators":["MR_INT"],"countryCode":"AU","discountAllowed":true,"timezone":"GMT","openDate":"2020-02-02T08:30:00.000Z","version":3143005249,"name":"Set 1 Winner","eventName":"Thiem v Djokovic"}}]}
{"op":"mcm","clk":"988158687","pt":1580474922991,"mc":[{"id":"1.168135786","rc":[{"batb":[[0,1.16,10],[1,1.01,10],[2,1.01,0]],"ltp":0.0,"tv":0.0,"id":2249229},{"batb":[[0,1.01,10],[1,1.01,0]],"ltp":0.0,"tv":0.0,"id":5720747}]}]}
{"op":"mcm","clk":"988227517","pt":1580475589553,"mc":[{"id":"1.168135786","rc":[{"batb":[[0,1.4,61.98],[1,1.16,10],[2,1.01,10]],"ltp":0.0,"tv":0.0,"id":2249229},{"batb":[[0,2.74,14.25],[1,1.01,10]],"ltp":0.0,"tv":0.0,"id":5720747}]}]}
{"op":"mcm","clk":"988240089","pt":1580475712338,"mc":[{"id":"1.168135786","rc":[{"batb":[[0,1.42,86.63],[1,1.4,61.98],[2,1.16,10]],"ltp":0.0,"tv":0.0,"id":2249229},{"batb":[[0,2.78,40.16],[1,2.74,14.25],[2,1.01,10]],"ltp":0.0,"tv":0.0,"id":5720747}]}]}
{"op":"mcm","clk":"988240292","pt":1580475713824,"mc":[{"id":"1.168135786","rc":[{"batb":[[2,1.39,19.53]],"ltp":0.0,"tv":0.0,"id":2249229},{"batb":[[2,2.44,7.62]],"ltp":0.0,"tv":0.0,"id":5720747}]}]}
{"op":"mcm","clk":"988244748","pt":1580475744796,"mc":[{"id":"1.168135786","rc":[{"batb":[[2,1.16,10]],"ltp":0.0,"tv":0.0,"id":2249229},{"batb":[[2,1.01,10]],"ltp":0.0,"tv":0.0,"id":5720747}]}]}
{"op":"mcm","clk":"988244823","pt":1580475745378,"mc":[{"id":"1.168135786","rc":[{"batb":[[2,1.39,19.53]],"ltp":0.0,"tv":0.0,"id":2249229},{"batb":[[2,2.44,7.62]],"ltp":0.0,"tv":0.0,"id":5720747}]}]}
{"op":"mcm","clk":"988268738","pt":1580475949682,"mc":[{"id":"1.168135786","rc":[{"batb":[[0,2.74,14.25],[1,2.44,7.62],[2,1.01,10]],"ltp":0.0,"tv":0.0,"id":5720747}]}]}
{"op":"mcm","clk":"988268758","pt":1580475949850,"mc":[{"id":"1.168135786","rc":[{"batb":[[0,2.74,54.04]],"ltp":0.0,"tv":0.0,"id":5720747}]}]}
{"op":"mcm","clk":"988269053","pt":1580475952792,"mc":[{"id":"1.168135786","rc":[{"batb":[[2,1.16,10]],"ltp":0.0,"tv":0.0,"id":2249229},{"batb":[[1,1.01,10],[2,1.01,0]],"ltp":0.0,"tv":0.0,"id":5720747}]}]}
{"op":"mcm","clk":"988269155","pt":1580475953700,"mc":[{"id":"1.168135786","rc":[{"batb":[[1,1.4,81.03]],"ltp":0.0,"tv":0.0,"id":2249229},{"batb":[[1,2.4,7.62],[2,1.01,10]],"ltp":0.0,"tv":0.0,"id":5720747}]}]}
{"op":"mcm","clk":"988289225","pt":1580476055552,"mc":[{"id":"1.168135786","rc":[{"batb":[[1,1.4,61.98]],"ltp":0.0,"tv":0.0,"id":2249229},{"batb":[[1,1.01,10],[2,1.01,0]],"ltp":0.0,"tv":0.0,"id":5720747}]}]}
{"op":"mcm","clk":"988289294","pt":1580476056183,"mc":[{"id":"1.168135786","rc":[{"batb":[[2,1.37,20.59]],"ltp":0.0,"tv":0.0,"id":2249229},{"batb":[[1,2.5,7.62],[2,1.01,10]],"ltp":0.0,"tv":0.0,"id":5720747}]}]}
{"op":"mcm","clk":"988292388","pt":1580476083499,"mc":[{"id":"1.168135786","rc":[{"batb":[[0,1.4,61.98],[1,1.37,20.59],[2,1.16,10]],"ltp":0.0,"tv":0.0,"id":2249229},{"batb":[[0,2.74,14.25]],"ltp":0.0,"tv":0.0,"id":5720747}]}]}
{"op":"mcm","clk":"988294140","pt":1580476098738,"mc":[{"id":"1.168135786","rc":[{"batb":[[0,1.42,89.44],[1,1.4,61.98],[2,1.37,20.59]],"ltp":0.0,"tv":0.0,"id":2249229},{"batb":[[0,2.84,40.72],[1,2.74,14.25],[2,2.5,7.62]],"ltp":0.0,"tv":0.0,"id":5720747}]}]}
{"op":"mcm","clk":"988296320","pt":1580476118689,"mc":[{"id":"1.168135786","rc":[{"batb":[[2,1.36,21.16]],"ltp":0.0,"tv":0.0,"id":2249229},{"batb":[[2,2.54,7.62]],"ltp":0.0,"tv":0.0,"id":5720747}]}]}
{"op":"mcm","clk":"988313120","pt":1580476261785,"mc":[{"id":"1.168135786","rc":[{"batb":[[0,1.4,61.98],[1,1.36,21.16],[2,1.16,10]],"ltp":0.0,"tv":0.0,"id":2249229},{"batb":[[0,2.84,44.47]],"ltp":0.0,"tv":0.0,"id":5720747}]}]}
{"op":"mcm","clk":"988313424","pt":1580476264637,"mc":[{"id":"1.168135786","rc":[{"batb":[[1,1.16,10],[2,1.01,10]],"ltp":0.0,"tv":0.0,"id":2249229},{"batb":[[2,1.01,10]],"ltp":0.0,"tv":0.0,"id":5720747}]}]}
{"op":"mcm","clk":"988313499","pt":1580476265017,"mc":[{"id":"1.168135786","rc":[{"batb":[[1,1.32,23.81],[2,1.16,10]],"ltp":0.0,"tv":0.0,"id":2249229},{"batb":[[1,2.74,21.87]],"ltp":0.0,"tv":0.0,"id":5720747}]}]}
{"op":"mcm","clk":"988313755","pt":1580476267027,"mc":[{"id":"1.168135786","rc":[{"batb":[[0,1.4,157.74]],"ltp":0.0,"tv":0.0,"id":2249229}]}]}
{"op":"mcm","clk":"988313961","pt":1580476268724,"mc":[{"id":"1.168135786","rc":[{"batb":[[1,1.34,22.41]],"ltp":0.0,"tv":0.0,"id":2249229},{"batb":[[1,2.74,14.25],[2,2.62,7.62]],"ltp":0.0,"tv":0.0,"id":5720747}]}]}
{"op":"mcm","clk":"988316083","pt":1580476286178,"mc":[{"id":"1.168135786","rc":[{"batb":[[1,1.16,10],[2,1.01,10]],"ltp":0.0,"tv":0.0,"id":2249229},{"batb":[[2,1.01,10]],"ltp":0.0,"tv":0.0,"id":5720747}]}]}
{"op":"mcm","clk":"988316173","pt":1580476286864,"mc":[{"id":"1.168135786","rc":[{"batb":[[1,1.34,22.41],[2,1.16,10]],"ltp":0.0,"tv":0.0,"id":2249229},{"batb":[[2,2.64,7.62]],"ltp":0.0,"tv":0.0,"id":5720747}]}]}
{"op":"mcm","clk":"988316429","pt":1580476289254,"mc":[{"id":"1.168135786","rc":[{"batb":[[0,1.4,541.84]],"ltp":0.0,"tv":0.0,"id":2249229},{"batb":[[0,2.84,213.47]],"ltp":0.0,"tv":0.0,"id":5720747}]}]}
{"op":"mcm","clk":"988318645","pt":1580476308500,"mc":[{"id":"1.168135786","rc":[{"batb":[[0,1.4,61.98]],"ltp":0.0,"tv":0.0,"id":2249229},{"batb":[[0,2.84,216.22]],"ltp":0.0,"tv":0.0,"id":5720747}]}]}
{"op":"mcm","clk":"988318940","pt":1580476311434,"mc":[{"id":"1.168135786","rc":[{"batb":[[1,1.16,10],[2,1.01,10]],"ltp":0.0,"tv":0.0,"id":2249229},{"batb":[[2,1.01,10]],"ltp":0.0,"tv":0.0,"id":5720747}]}]}
{"op":"mcm","clk":"988319066","pt":1580476312608,"mc":[{"id":"1.168135786","rc":[{"batb":[[1,1.36,105.81],[2,1.16,10]],"ltp":0.0,"tv":0.0,"id":2249229},{"batb":[[0,2.84,236.92]],"ltp":0.0,"tv":0.0,"id":5720747}]}]}
{"op":"mcm","clk":"988326631","pt":1580476376246,"mc":[{"id":"1.168135786","rc":[{"batb":[[0,1.41,470.89],[1,1.4,61.98],[2,1.36,105.81]],"ltp":0.0,"tv":0.0,"id":2249229},{"batb":[[0,2.84,230.67]],"ltp":0.0,"tv":0.0,"id":5720747}]}]}
{"op":"mcm","clk":"988326897","pt":1580476378452,"mc":[{"id":"1.168135786","rc":[{"batb":[[2,1.16,10]],"ltp":0.0,"tv":0.0,"id":2249229},{"batb":[[0,2.84,209.97]],"ltp":0.0,"tv":0.0,"id":5720747}]}]}
{"op":"mcm","clk":"988326969","pt":1580476379033,"mc":[{"id":"1.168135786","rc":[{"batb":[[2,1.37,102.96]],"ltp":0.0,"tv":0.0,"id":2249229},{"batb":[[1,2.76,21.64],[2,2.74,14.25]],"ltp":0.0,"tv":0.0,"id":5720747}]}]}
{"op":"mcm","clk":"988365317","pt":1580476720606,"mc":[{"id":"1.168135786","rc":[{"batb":[[2,1.16,10]],"ltp":0.0,"tv":0.0,"id":2249229},{"batb":[[1,2.74,14.25],[2,1.01,10]],"ltp":0.0,"tv":0.0,"id":5720747}]}]}
{"op":"mcm","clk":"988365386","pt":1580476721203,"mc":[{"id":"1.168135786","rc":[{"batb":[[2,1.37,102.96]],"ltp":0.0,"tv":0.0,"id":2249229},{"batb":[[1,2.74,36.15]],"ltp":0.0,"tv":0.0,"id":5720747}]}]}
{"op":"mcm","clk":"988380770","pt":1580476851644,"mc":[{"id":"1.168135786","rc":[{"batb":[[2,1.16,10]],"ltp":0.0,"tv":0.0,"id":2249229},{"batb":[[1,2.74,14.25]],"ltp":0.0,"tv":0.0,"id":5720747}]}]}
{"op":"mcm","clk":"988380844","pt":1580476852294,"mc":[{"id":"1.168135786","rc":[{"batb":[[2,1.38,100.24]],"ltp":0.0,"tv":0.0,"id":2249229},{"batb":[[1,2.74,36.15]],"ltp":0.0,"tv":0.0,"id":5720747}]}]}
{"op":"mcm","clk":"988382678","pt":1580476867393,"mc":[{"id":"1.168135786","rc":[{"batb":[[0,1.4,61.98],[1,1.38,100.24],[2,1.16,10]],"ltp":0.0,"tv":0.0,"id":2249229},{"batb":[[0,2.74,36.15],[1,1.01,10],[2,1.01,0]],"ltp":0.0,"tv":0.0,"id":5720747}]}]}
{"op":"mcm","clk":"988384033","pt":1580476878519,"mc":[{"id":"1.168135786","rc":[{"batb":[[0,1.41,465.06],[1,1.4,61.98],[2,1.38,100.24]],"ltp":0.0,"tv":0.0,"id":2249229}]}]}
{"op":"mcm","clk":"988384176","pt":1580476879686,"mc":[{"id":"1.168135786","rc":[{"batb":[[0,2.78,213.66],[1,2.74,36.15],[2,1.01,10]],"ltp":0.0,"tv":0.0,"id":5720747}]}]}
{"op":"mcm","clk":"988475535","pt":1580477600412,"mc":[{"id":"1.168135786","rc":[{"batb":[[2,1.16,10]],"ltp":0.0,"tv":0.0,"id":2249229},{"batb":[[1,2.74,14.25]],"ltp":0.0,"tv":0.0,"id":5720747}]}]}
{"op":"mcm","clk":"988475598","pt":1580477601049,"mc":[{"id":"1.168135786","rc":[{"batb":[[2,1.37,102.96]],"ltp":0.0,"tv":0.0,"id":2249229},{"batb":[[1,2.74,36.15]],"ltp":0.0,"tv":0.0,"id":5720747}]}]}
{"op":"mcm","clk":"988493800","pt":1580477772538,"mc":[{"id":"1.168135786","rc":[{"batb":[[2,1.38,100.24]],"ltp":0.0,"tv":0.0,"id":2249229},{"batb":[[1,2.74,14.25],[2,2.72,22.15]],"ltp":0.0,"tv":0.0,"id":5720747}]}]}
{"op":"mcm","clk":"988495314","pt":1580477786818,"mc":[{"id":"1.168135786","rc":[{"batb":[[0,1.42,7.21],[1,1.41,465.06],[2,1.4,61.98]],"ltp":0.0,"tv":0.0,"id":2249229}]}]}
{"op":"mcm","clk":"988495389","pt":1580477787508,"mc":[{"id":"1.168135786","rc":[{"batb":[[0,1.42,467.65],[1,1.4,61.98],[2,1.38,100.24]],"ltp":0.0,"tv":0.0,"id":2249229}]}]}
{"op":"mcm","clk":"988512572","pt":1580477867659,"mc":[{"id":"1.168135786","rc":[{"batb":[[1,2.74,36.15],[2,1.01,10]],"ltp":0.0,"tv":0.0,"id":5720747}]}]}
{"op":"mcm","clk":"988512729","pt":1580477869163,"mc":[{"id":"1.168135786","rc":[{"batb":[[0,1.42,7.21]],"ltp":0.0,"tv":0.0,"id":2249229},{"batb":[[0,2.74,36.15],[1,1.01,10],[2,1.01,0]],"ltp":0.0,"tv":0.0,"id":5720747}]}]}
{"op":"mcm","clk":"988514654","pt":1580477888595,"mc":[{"id":"1.168135786","rc":[{"batb":[[0,1.42,469.15]],"ltp":0.0,"tv":0.0,"id":2249229},{"batb":[[0,2.84,209.22],[1,2.74,36.15],[2,1.01,10]],"ltp":0.0,"tv":0.0,"id":5720747}]}]}
{"op":"mcm","clk":"988515326","pt":1580477896498,"mc":[{"id":"1.168135786","rc":[{"batb":[[0,1.42,7.21]],"ltp":0.0,"tv":0.0,"id":2249229},{"batb":[[0,2.74,36.15],[1,1.01,10],[2,1.01,0]],"ltp":0.0,"tv":0.0,"id":5720747}]}]}
{"op":"mcm","clk":"988516123","pt":1580477903889,"mc":[{"id":"1.168135786","rc":[{"batb":[[0,1.42,469.15]],"ltp":0.0,"tv":0.0,"id":2249229},{"batb":[[0,2.8,212.03],[1,2.74,36.15],[2,1.01,10]],"ltp":0.0,"tv":0.0,"id":5720747}]}]}
{"op":"mcm","clk":"988665183","pt":1580479466094,"mc":[{"id":"1.168135786","rc":[{"batb":[[0,1.42,7.2],[2,1.38,100.11]],"ltp":0.0,"tv":0.0,"id":2249229},{"batb":[[0,2.74,36.12],[1,1.01,10],[2,1.01,0]],"ltp":0.0,"tv":0.0,"id":5720747}]}]}
{"op":"mcm","clk":"988665985","pt":1580479474698,"mc":[{"id":"1.168135786","rc":[{"batb":[[0,1.42,469.14]],"ltp":0.0,"tv":0.0,"id":2249229},{"batb":[[0,2.76,215.23],[1,2.74,36.12],[2,1.01,10]],"ltp":0.0,"tv":0.0,"id":5720747}]}]}
{"op":"mcm","clk":"988737827","pt":1580480226735,"mc":[{"id":"1.168135786","rc":[{"batb":[[0,1.42,7.2]],"ltp":0.0,"tv":0.0,"id":2249229}]}]}
{"op":"mcm","clk":"988738135","pt":1580480229513,"mc":[{"id":"1.168135786","rc":[{"batb":[[2,1.16,10]],"ltp":0.0,"tv":0.0,"id":2249229},{"batb":[[1,2.74,14.25]],"ltp":0.0,"tv":0.0,"id":5720747}]}]}
{"op":"mcm","clk":"988738249","pt":1580480230720,"mc":[{"id":"1.168135786","rc":[{"batb":[[2,1.38,100.11]],"ltp":0.0,"tv":0.0,"id":2249229},{"batb":[[1,2.74,36.12]],"ltp":0.0,"tv":0.0,"id":5720747}]}]}
{"op":"mcm","clk":"988742324","pt":1580480276401,"mc":[{"id":"1.168135786","rc":[{"batb":[[0,2.74,36.12],[1,1.01,10],[2,1.01,0]],"ltp":0.0,"tv":0.0,"id":5720747}]}]}
{"op":"mcm","clk":"988742939","pt":1580480282521,"mc":[{"id":"1.168135786","rc":[{"batb":[[0,2.78,214.48],[1,2.74,36.12],[2,1.01,10]],"ltp":0.0,"tv":0.0,"id":5720747}]}]}
{"op":"mcm","clk":"988788670","pt":1580480676209,"mc":[{"id":"1.168135786","rc":[{"batb":[[2,1.16,10]],"ltp":0.0,"tv":0.0,"id":2249229},{"batb":[[1,2.74,14.25]],"ltp":0.0,"tv":0.0,"id":5720747}]}]}
{"op":"mcm","clk":"988788724","pt":1580480676828,"mc":[{"id":"1.168135786","rc":[{"batb":[[2,1.37,102.81]],"ltp":0.0,"tv":0.0,"id":2249229},{"batb":[[1,2.76,21.61],[2,2.74,14.25]],"ltp":0.0,"tv":0.0,"id":5720747}]}]}
{"op":"mcm","clk":"988807859","pt":1580480911200,"mc":[{"id":"1.168135786","rc":[{"batb":[[0,1.41,470.89],[2,1.38,7.2]],"ltp":0.0,"tv":0.0,"id":2249229}]}]}
{"op":"mcm","clk":"989049775","pt":1580483702344,"mc":[{"id":"1.168135786","rc":[{"batb":[[0,1.4,542.34],[1,1.38,7.2],[2,1.37,102.81]],"ltp":0.0,"tv":0.0,"id":2249229},{"batb":[[0,2.78,218.48]],"ltp":0.0,"tv":0.0,"id":5720747}]}]}
{"op":"mcm","clk":"989049953","pt":1580483704720,"mc":[{"id":"1.168135786","rc":[{"batb":[[2,1.36,105.67]],"ltp":0.0,"tv":0.0,"id":2249229},{"batb":[[0,2.8,21.14],[1,2.74,14.25],[2,1.01,10]],"ltp":0.0,"tv":0.0,"id":5720747}]}]}
{"op":"mcm","clk":"989049964","pt":1580483704827,"mc":[{"id":"1.168135786","rc":[{"batb":[[0,2.84,213.72],[1,2.8,21.14],[2,2.74,14.25]],"ltp":0.0,"tv":0.0,"id":5720747}]}]}
{"op":"mcm","clk":"989063534","pt":1580483882960,"mc":[{"id":"1.168135786","rc":[{"batb":[[0,2.8,21.14],[1,2.74,14.25],[2,1.01,10]],"ltp":0.0,"tv":0.0,"id":5720747}]}]}
{"op":"mcm","clk":"989063650","pt":1580483884660,"mc":[{"id":"1.168135786","rc":[{"batb":[[0,2.94,207.92],[1,2.8,21.14],[2,2.74,14.25]],"ltp":0.0,"tv":0.0,"id":5720747}]}]}
{"op":"mcm","clk":"989067588","pt":1580483931504,"mc":[{"id":"1.168135786","rc":[{"batb":[[0,1.41,7.2],[1,1.4,61.98]],"ltp":0.0,"tv":0.0,"id":2249229}]}]}
{"op":"mcm","clk":"989239292","pt":1580485920504,"mc":[{"id":"1.168135786","rc":[{"batb":[[1,2.84,20.67]],"ltp":0.0,"tv":0.0,"id":5720747}]}]}
{"op":"mcm","clk":"989240942","pt":1580485945440,"mc":[{"id":"1.168135786","rc":[{"batb":[[2,1.35,108.69]],"ltp":0.0,"tv":0.0,"id":2249229},{"batb":[[1,2.86,20.45]],"ltp":0.0,"tv":0.0,"id":5720747}]}]}
{"op":"mcm","clk":"989251981","pt":1580485971472,"mc":[{"id":"1.168135786","rc":[{"batl":[[0,10,10]],"ltp":0.0,"tv":0.0,"id":2249229}]}]}
{"op":"mcm","clk":"989252803","pt":1580485983291,"mc":[{"id":"1.168135786","rc":[{"batb":[[0,2.94,211.42]],"ltp":0.0,"tv":0.0,"id":5720747}]}]}
{"op":"mcm","clk":"989252872","pt":1580485984187,"mc":[{"id":"1.168135786","rc":[{"batl":[[0,2,10]],"ltp":0.0,"tv":0.0,"id":2249229}]}]}
{"op":"mcm","clk":"989340032","pt":1580486852178,"mc":[{"id":"1.168135786","rc":[{"batb":[[0,1.41,7.19],[2,1.35,108.39]],"ltp":0.0,"tv":0.0,"id":2249229},{"batb":[[1,2.86,20.39]],"ltp":0.0,"tv":0.0,"id":5720747}]}]}
{"op":"mcm","clk":"989363381","pt":1580487077532,"mc":[{"id":"1.168135786","rc":[{"batb":[[0,1.4,61.98],[1,1.36,7.19]],"ltp":0.0,"tv":0.0,"id":2249229}]}]}
{"op":"mcm","clk":"989402454","pt":1580487485323,"mc":[{"id":"1.168135786","rc":[{"batb":[[0,2.88,215.71]],"ltp":0.0,"tv":0.0,"id":5720747}]}]}
{"op":"mcm","clk":"989411939","pt":1580487600772,"mc":[{"id":"1.168135786","rc":[{"batb":[[0,2.86,20.39],[1,2.74,14.25],[2,1.01,10]],"ltp":0.0,"tv":0.0,"id":5720747}]}]}
{"op":"mcm","clk":"989411990","pt":1580487601254,"mc":[{"id":"1.168135786","rc":[{"batb":[[0,2.88,212.96],[1,2.86,20.39],[2,2.74,14.25]],"ltp":0.0,"tv":0.0,"id":5720747}]}]}
{"op":"mcm","clk":"989412197","pt":1580487603696,"mc":[{"id":"1.168135786","rc":[{"batb":[[2,1.16,10]],"ltp":0.0,"tv":0.0,"id":2249229},{"batb":[[1,2.74,14.25],[2,1.01,10]],"ltp":0.0,"tv":0.0,"id":5720747}]}]}
{"op":"mcm","clk":"989412251","pt":1580487604277,"mc":[{"id":"1.168135786","rc":[{"batb":[[2,1.35,108.39]],"ltp":0.0,"tv":0.0,"id":2249229},{"batb":[[1,2.84,20.61],[2,2.74,14.25]],"ltp":0.0,"tv":0.0,"id":5720747}]}]}
{"op":"mcm","clk":"989488668","pt":1580488355583,"mc":[{"id":"1.168135786","rc":[{"batb":[[2,1.16,10]],"ltp":0.0,"tv":0.0,"id":2249229},{"batb":[[1,2.74,14.25],[2,1.01,10]],"ltp":0.0,"tv":0.0,"id":5720747}]}]}
{"op":"mcm","clk":"989488716","pt":1580488356207,"mc":[{"id":"1.168135786","rc":[{"batb":[[2,1.35,108.39]],"ltp":0.0,"tv":0.0,"id":2249229},{"batb":[[1,2.86,20.39],[2,2.74,14.25]],"ltp":0.0,"tv":0.0,"id":5720747}]}]}
{"op":"mcm","clk":"989491269","pt":1580488385503,"mc":[{"id":"1.168135786","rc":[{"batb":[[0,2.88,215.71]],"ltp":0.0,"tv":0.0,"id":5720747}]}]}
{"op":"mcm","clk":"989620902","pt":1580489762561,"mc":[{"id":"1.168135786","rc":[{"batb":[[0,2.88,212.71]],"ltp":0.0,"tv":0.0,"id":5720747}]}]}
{"op":"mcm","clk":"989621225","pt":1580489766439,"mc":[{"id":"1.168135786","rc":[{"batb":[[2,1.16,10]],"ltp":0.0,"tv":0.0,"id":2249229},{"batb":[[1,2.74,14.25],[2,1.01,10]],"ltp":0.0,"tv":0.0,"id":5720747}]}]}
{"op":"mcm","clk":"989621302","pt":1580489767331,"mc":[{"id":"1.168135786","rc":[{"batb":[[2,1.35,108.39]],"ltp":0.0,"tv":0.0,"id":2249229},{"batb":[[1,2.84,20.61],[2,2.74,14.25]],"ltp":0.0,"tv":0.0,"id":5720747}]}]}
{"op":"mcm","clk":"989622821","pt":1580489787583,"mc":[{"id":"1.168135786","rc":[{"batb":[[0,2.84,20.61],[1,2.74,14.25],[2,1.01,10]],"ltp":0.0,"tv":0.0,"id":5720747}]}]}
{"op":"mcm","clk":"989623451","pt":1580489795568,"mc":[{"id":"1.168135786","rc":[{"batb":[[0,2.98,207.76],[1,2.84,20.61],[2,2.74,14.25]],"ltp":0.0,"tv":0.0,"id":5720747}]}]}
{"op":"mcm","clk":"989624923","pt":1580489816595,"mc":[{"id":"1.168135786","rc":[{"batb":[[0,2.84,20.61],[1,2.74,14.25],[2,1.01,10]],"ltp":0.0,"tv":0.0,"id":5720747}]}]}
{"op":"mcm","clk":"989625379","pt":1580489822714,"mc":[{"id":"1.168135786","rc":[{"batb":[[0,2.86,216.68],[1,2.84,20.61],[2,2.74,14.25]],"ltp":0.0,"tv":0.0,"id":5720747}]}]}
{"op":"mcm","clk":"989694294","pt":1580490500178,"mc":[{"id":"1.168135786","rc":[{"batb":[[1,1.35,108.39],[2,1.16,10]],"ltp":0.0,"tv":0.0,"id":2249229}]}]}
{"op":"mcm","clk":"989953767","pt":1580492709870,"mc":[{"id":"1.168135786","rc":[{"batb":[[0,1.41,100],[1,1.4,61.98],[2,1.35,108.39]],"ltp":0.0,"tv":0.0,"id":2249229}]}]}
{"op":"mcm","clk":"989954567","pt":1580492717587,"mc":[{"id":"1.168135786","rc":[{"batb":[[0,2.88,50],[1,2.86,216.68],[2,2.84,20.61]],"ltp":0.0,"tv":0.0,"id":5720747}]}]}
{"op":"mcm","clk":"989954617","pt":1580492718010,"mc":[{"id":"1.168135786","rc":[{"batb":[[0,2.98,207.76],[1,2.88,50]],"ltp":0.0,"tv":0.0,"id":5720747}]}]}
{"op":"mcm","clk":"990032628","pt":1580493423673,"mc":[{"id":"1.168135786","rc":[{"batb":[[0,2.88,50],[1,2.84,20.61],[2,2.74,14.25]],"ltp":0.0,"tv":0.0,"id":5720747}]}]}
{"op":"mcm","clk":"990045221","pt":1580493584582,"mc":[{"id":"1.168135786","rc":[{"batb":[[1,1.4,67.94]],"ltp":0.0,"tv":0.0,"id":2249229},{"batb":[[2,2.74,15.62]],"ltp":0.0,"tv":0.0,"id":5720747}]}]}
{"op":"mcm","clk":"990045265","pt":1580493585160,"mc":[{"id":"1.168135786","rc":[{"batb":[[0,2.98,207.76],[1,2.88,50],[2,2.84,20.61]],"ltp":0.0,"tv":0.0,"id":5720747}]}]}
{"op":"mcm","clk":"990083014","pt":1580494001455,"mc":[{"id":"1.168135786","rc":[{"batb":[[0,1.42,6.71],[1,1.41,100],[2,1.4,67.94]],"ltp":0.0,"tv":0.0,"id":2249229},{"batb":[[2,2.84,20.59]],"ltp":0.0,"tv":0.0,"id":5720747}]}]}
{"op":"mcm","clk":"990432797","pt":1580497185137,"mc":[{"id":"1.168135786","rc":[{"batb":[[0,2.88,50],[1,2.84,20.59],[2,2.74,15.62]],"ltp":0.0,"tv":0.0,"id":5720747}]}]}
{"op":"mcm","clk":"991045160","pt":1580501252131,"mc":[{"id":"1.168135786","rc":[{"batb":[[0,1.42,6.7]],"ltp":0.0,"tv":0.0,"id":2249229},{"batb":[[1,2.84,20.58]],"ltp":0.0,"tv":0.0,"id":5720747}]}]}
{"op":"mcm","clk":"991806450","pt":1580508452143,"mc":[{"id":"1.168135786","rc":[{"batb":[[0,1.42,6.7]],"ltp":0.0,"tv":0.0,"id":2249229},{"batb":[[1,2.84,20.57]],"ltp":0.0,"tv":0.0,"id":5720747}]}]}
{"op":"mcm","clk":"991991690","pt":1580511709642,"mc":[{"id":"1.168135786","rc":[{"batb":[[0,2.9,213.46],[1,2.88,50],[2,2.84,20.57]],"ltp":0.0,"tv":0.0,"id":5720747}]}]}
{"op":"mcm","clk":"992042918","pt":1580512675428,"mc":[{"id":"1.168135786","rc":[{"batb":[[0,2.9,208.36]],"ltp":0.0,"tv":0.0,"id":5720747}]}]}
{"op":"mcm","clk":"992043009","pt":1580512677537,"mc":[{"id":"1.168135786","rc":[{"batb":[[2,2.8,21.04]],"ltp":0.0,"tv":0.0,"id":5720747}]}]}
{"op":"mcm","clk":"992163686","pt":1580515309425,"mc":[{"id":"1.168135786","rc":[{"batb":[[0,2.88,50],[1,2.8,21.04],[2,2.74,15.62]],"ltp":0.0,"tv":0.0,"id":5720747}]}]}
{"op":"mcm","clk":"992268718","pt":1580518266708,"mc":[{"id":"1.168135786","rc":[{"batb":[[0,2.96,206.63],[1,2.88,50],[2,2.8,21.04]],"ltp":0.0,"tv":0.0,"id":5720747}]}]}
{"op":"mcm","clk":"992390178","pt":1580521591207,"mc":[{"id":"1.168135786","rc":[{"batb":[[0,2.96,203.63]],"ltp":0.0,"tv":0.0,"id":5720747}]}]}
{"op":"mcm","clk":"992390229","pt":1580521593484,"mc":[{"id":"1.168135786","rc":[{"batb":[[2,2.74,15.62]],"ltp":0.0,"tv":0.0,"id":5720747}]}]}
{"op":"mcm","clk":"992390241","pt":1580521594313,"mc":[{"id":"1.168135786","rc":[{"batb":[[2,2.8,21.04]],"ltp":0.0,"tv":0.0,"id":5720747}]}]}
{"op":"mcm","clk":"992396631","pt":1580521867516,"mc":[{"id":"1.168135786","rc":[{"batb":[[0,2.92,208.69]],"ltp":0.0,"tv":0.0,"id":5720747}]}]}
{"op":"mcm","clk":"992547373","pt":1580525467534,"mc":[{"id":"1.168135786","rc":[{"batb":[[0,2.88,50],[1,2.8,21.04],[2,2.74,15.62]],"ltp":0.0,"tv":0.0,"id":5720747}]}]}
{"op":"mcm","clk":"992547837","pt":1580525484348,"mc":[{"id":"1.168135786","rc":[{"batb":[[0,2.9,210.06],[1,2.88,50],[2,2.8,21.04]],"ltp":0.0,"tv":0.0,"id":5720747}]}]}
{"op":"mcm","clk":"992661794","pt":1580528146772,"mc":[{"id":"1.168135786","rc":[{"batb":[[2,2.82,20.8]],"ltp":0.0,"tv":0.0,"id":5720747}]}]}
{"op":"mcm","clk":"992705956","pt":1580529084432,"mc":[{"id":"1.168135786","rc":[{"batb":[[0,2.88,50],[1,2.82,20.8],[2,2.74,15.62]],"ltp":0.0,"tv":0.0,"id":5720747}]}]}
{"op":"mcm","clk":"992961928","pt":1580533910071,"mc":[{"id":"1.168135786","rc":[{"trd":[[1.42,13.4]],"batb":[[0,1.41,100],[1,1.4,67.94],[2,1.36,105.17]],"batl":[[0,1.42,43.95],[1,2,10]],"ltp":1.42,"tv":13.39,"id":2249229}],"tv":13.39}]}
{"op":"mcm","clk":"992963045","pt":1580533935205,"mc":[{"id":"1.168135786","rc":[{"batl":[[0,2,10],[1,2,0]],"ltp":1.42,"tv":13.39,"id":2249229},{"batb":[[0,2.92,210.19],[1,2.88,50],[2,2.82,20.8]],"ltp":0.0,"tv":0.0,"id":5720747}]}]}
{"op":"mcm","clk":"992963802","pt":1580533952708,"mc":[{"id":"1.168135786","rc":[{"batl":[[0,1.46,50.65],[1,2,10]],"ltp":1.42,"tv":13.39,"id":2249229},{"batb":[[0,2.88,50],[1,2.82,20.8],[2,2.74,15.62]],"ltp":0.0,"tv":0.0,"id":5720747}]}]}
{"op":"mcm","clk":"992964865","pt":1580533984223,"mc":[{"id":"1.168135786","rc":[{"trd":[[1.41,87.16]],"batb":[[0,1.41,56.4]],"ltp":1.41,"tv":100.55,"id":2249229}],"tv":100.55}]}
{"op":"mcm","clk":"992985362","pt":1580534476550,"mc":[{"id":"1.168135786","rc":[{"trd":[[1.41,188.51]],"batb":[[0,1.41,5.7]],"ltp":1.41,"tv":201.9,"id":2249229}],"tv":201.9}]}
{"op":"mcm","clk":"992987569","pt":1580534532122,"mc":[{"id":"1.168135786","rc":[{"batl":[[0,1.42,50.65],[1,1.46,50.65],[2,2,10]],"ltp":1.41,"tv":201.9,"id":2249229}]}]}
{"op":"mcm","clk":"992998963","pt":1580534566426,"mc":[{"id":"1.168135786","rc":[{"batl":[[0,1.46,50.65],[1,2,10],[2,2,0]],"ltp":1.41,"tv":201.9,"id":2249229}]}]}
{"op":"mcm","clk":"993001482","pt":1580534640586,"mc":[{"id":"1.168135786","rc":[{"batl":[[0,1.42,50.65],[1,1.46,50.65],[2,2,10]],"ltp":1.41,"tv":201.9,"id":2249229}]}]}
{"op":"mcm","clk":"993001821","pt":1580534651463,"mc":[{"id":"1.168135786","rc":[{"batl":[[1,1.43,50.65],[2,1.46,50.65]],"ltp":1.41,"tv":201.9,"id":2249229}]}]}
{"op":"mcm","clk":"993002145","pt":1580534661297,"mc":[{"id":"1.168135786","rc":[{"batl":[[2,1.44,50.65]],"ltp":1.41,"tv":201.9,"id":2249229}]}]}
{"op":"mcm","clk":"993003419","pt":1580534694639,"mc":[{"id":"1.168135786","rc":[{"trd":[[1.41,199.9]],"batb":[[0,1.4,553.35],[1,1.36,105.17],[2,1.16,10]],"batl":[[0,1.41,44.96],[1,1.42,50.65],[2,1.43,50.65]],"ltp":1.41,"tv":213.3,"id":2249229}],"tv":213.3}]}
{"op":"mcm","clk":"993004888","pt":1580534732140,"mc":[{"id":"1.168135786","rc":[{"batl":[[2,2,10]],"ltp":1.41,"tv":213.3,"id":2249229}]}]}
{"op":"mcm","clk":"993005050","pt":1580534735344,"mc":[{"id":"1.168135786","rc":[{"batl":[[1,2,10],[2,2,0]],"ltp":1.41,"tv":213.3,"id":2249229}]}]}
{"op":"mcm","clk":"993005211","pt":1580534738644,"mc":[{"id":"1.168135786","rc":[{"batl":[[0,2,10],[1,2,0]],"ltp":1.41,"tv":213.3,"id":2249229}]}]}
{"op":"mcm","clk":"993005223","pt":1580534738952,"mc":[{"id":"1.168135786","rc":[{"batb":[[0,2.9,211.46],[1,2.88,50],[2,2.82,20.8]],"ltp":0.0,"tv":0.0,"id":5720747}]}]}
{"op":"mcm","clk":"993008395","pt":1580534820050,"mc":[{"id":"1.168135786","rc":[{"batl":[[0,1.42,50.65],[1,2,10]],"ltp":1.41,"tv":213.3,"id":2249229},{"batb":[[0,2.88,50],[1,2.82,20.8],[2,2.74,15.62]],"ltp":0.0,"tv":0.0,"id":5720747}]}]}
{"op":"mcm","clk":"993009259","pt":1580534844812,"mc":[{"id":"1.168135786","rc":[{"batl":[[0,2,10],[1,2,0]],"ltp":1.41,"tv":213.3,"id":2249229}]}]}
{"op":"mcm","clk":"993009273","pt":1580534845222,"mc":[{"id":"1.168135786","rc":[{"batb":[[0,2.98,205.76],[1,2.88,50],[2,2.82,20.8]],"ltp":0.0,"tv":0.0,"id":5720747}]}]}
{"op":"mcm","clk":"993011407","pt":1580534897818,"mc":[{"id":"1.168135786","rc":[{"trd":[[1.4,805.75]],"batb":[[0,1.36,105.17],[1,1.16,10],[2,1.02,2780.76]],"ltp":1.4,"tv":1019.05,"id":2249229}],"tv":1019.05}]}
{"op":"mcm","clk":"993011448","pt":1580534898796,"mc":[{"id":"1.168135786","rc":[{"batb":[[0,1.37,496.31],[1,1.36,105.17],[2,1.31,87.67]],"ltp":1.4,"tv":1019.05,"id":2249229},{"batb":[[0,2.98,137.76]],"ltp":0.0,"tv":0.0,"id":5720747}]}]}
{"op":"mcm","clk":"993011473","pt":1580534899715,"mc":[{"id":"1.168135786","rc":[{"batb":[[1,1.31,87.67],[2,1.16,10]],"ltp":1.4,"tv":1019.05,"id":2249229},{"batb":[[2,2.74,15.62]],"ltp":0.0,"tv":0.0,"id":5720747}]}]}
{"op":"mcm","clk":"993011488","pt":1580534900331,"mc":[{"id":"1.168135786","rc":[{"batb":[[1,1.35,108.18],[2,1.31,87.67]],"ltp":1.4,"tv":1019.05,"id":2249229},{"batb":[[2,2.86,20.35]],"ltp":0.0,"tv":0.0,"id":5720747}]}]}
{"op":"mcm","clk":"993024035","pt":1580535191771,"mc":[{"id":"1.168135786","rc":[{"batb":[[0,1.38,7.01]],"ltp":1.4,"tv":1019.05,"id":2249229},{"batb":[[0,3.05,136.09],[1,3,3.17],[2,2.88,50]],"ltp":0.0,"tv":0.0,"id":5720747}]}]}
{"op":"mcm","clk":"993024039","pt":1580535191877,"mc":[{"id":"1.168135786","rc":[{"batb":[[0,1.38,509.68]],"ltp":1.4,"tv":1019.05,"id":2249229}]}]}
{"op":"mcm","clk":"993067637","pt":1580535933791,"mc":[{"id":"1.168135786","rc":[{"batb":[[0,1.39,10.75],[1,1.38,7.01],[2,1.35,108.18]],"batl":[[0,1.48,10.19],[1,2,10]],"ltp":1.4,"tv":1019.05,"id":2249229},{"batb":[[0,3,3.17],[1,2.88,50],[2,2.86,20.35]],"batl":[[0,3.6,8.4]],"ltp":0.0,"tv":0.0,"id":5720747}]}]}
{"op":"mcm","clk":"993067644","pt":1580535933892,"mc":[{"id":"1.168135786","rc":[{"batl":[[0,1.48,290.93]],"ltp":1.4,"tv":1019.05,"id":2249229}]}]}
{"op":"mcm","clk":"993067721","pt":1580535935187,"mc":[{"id":"1.168135786","rc":[{"batb":[[0,1.38,509.68],[1,1.35,108.18],[2,1.31,87.67]],"ltp":1.4,"tv":1019.05,"id":2249229}]}]}
{"op":"mcm","clk":"993070153","pt":1580535980057,"mc":[{"id":"1.168135786","rc":[{"batb":[[0,1.39,9.26],[1,1.38,7.01],[2,1.35,108.18]],"ltp":1.4,"tv":1019.05,"id":2249229},{"batl":[[0,3.6,8.4]],"ltp":0.0,"tv":0.0,"id":5720747}]}]}
{"op":"mcm","clk":"993070210","pt":1580535981662,"mc":[{"id":"1.168135786","rc":[{"batb":[[0,1.38,7.01],[1,1.35,108.18],[2,1.31,87.67]],"ltp":1.4,"tv":1019.05,"id":2249229}]}]}
{"op":"mcm","clk":"993070222","pt":1580535981970,"mc":[{"id":"1.168135786","rc":[{"batb":[[0,1.38,509.68]],"ltp":1.4,"tv":1019.05,"id":2249229}]}]}
{"op":"mcm","clk":"993072578","pt":1580536025376,"mc":[{"id":"1.168135786","rc":[{"batb":[[0,1.39,8.68],[1,1.38,7.01],[2,1.35,108.18]],"ltp":1.4,"tv":1019.05,"id":2249229},{"batl":[[0,3.6,8.4]],"ltp":0.0,"tv":0.0,"id":5720747}]}]}
{"op":"mcm","clk":"993072679","pt":1580536027569,"mc":[{"id":"1.168135786","rc":[{"batb":[[0,1.38,7.01],[1,1.35,108.18],[2,1.31,87.67]],"ltp":1.4,"tv":1019.05,"id":2249229},{"batl":[[0,3.6,192.51]],"ltp":0.0,"tv":0.0,"id":5720747}]}]}
{"op":"mcm","clk":"993073052","pt":1580536035770,"mc":[{"id":"1.168135786","rc":[{"batl":[[0,3.55,8.4],[1,3.6,192.51]],"ltp":0.0,"tv":0.0,"id":5720747}]}]}
{"op":"mcm","clk":"993073060","pt":1580536035975,"mc":[{"id":"1.168135786","rc":[{"batl":[[1,3.6,0]],"ltp":0.0,"tv":0.0,"id":5720747}]}]}
{"op":"mcm","clk":"993073160","pt":1580536037883,"mc":[{"id":"1.168135786","rc":[{"batb":[[0,1.38,509.68]],"ltp":1.4,"tv":1019.05,"id":2249229}]}]}
{"op":"mcm","clk":"993074631","pt":1580536072616,"mc":[{"id":"1.168135786","rc":[{"batb":[[0,1.39,9.95],[1,1.38,509.68],[2,1.35,108.18]],"ltp":1.4,"tv":1019.05,"id":2249229},{"batl":[[0,3.6,8.4]],"ltp":0.0,"tv":0.0,"id":5720747}]}]}
{"op":"mcm","clk":"993074644","pt":1580536072923,"mc":[{"id":"1.168135786","rc":[{"batb":[[1,1.38,7.01]],"ltp":1.4,"tv":1019.05,"id":2249229}]}]}
{"op":"mcm","clk":"993074702","pt":1580536074622,"mc":[{"id":"1.168135786","rc":[{"batb":[[0,1.38,509.68],[1,1.35,108.18],[2,1.31,87.67]],"ltp":1.4,"tv":1019.05,"id":2249229}]}]}
{"op":"mcm","clk":"993076408","pt":1580536119657,"mc":[{"id":"1.168135786","rc":[{"batb":[[0,1.39,8.7],[1,1.38,509.68],[2,1.35,108.18]],"ltp":1.4,"tv":1019.05,"id":2249229},{"batl":[[0,3.6,8.4]],"ltp":0.0,"tv":0.0,"id":5720747}]}]}
{"op":"mcm","clk":"993076416","pt":1580536119857,"mc":[{"id":"1.168135786","rc":[{"batb":[[1,1.38,7.01]],"ltp":1.4,"tv":1019.05,"id":2249229}]}]}
{"op":"mcm","clk":"993076485","pt":1580536121659,"mc":[{"id":"1.168135786","rc":[{"batb":[[0,1.38,509.68],[1,1.35,108.18],[2,1.31,87.67]],"ltp":1.4,"tv":1019.05,"id":2249229}]}]}
{"op":"mcm","clk":"993078158","pt":1580536166803,"mc":[{"id":"1.168135786","rc":[{"batb":[[0,1.39,9.76],[1,1.38,509.68],[2,1.35,108.18]],"ltp":1.4,"tv":1019.05,"id":2249229},{"batl":[[0,3.6,8.4]],"ltp":0.0,"tv":0.0,"id":5720747}]}]}
{"op":"mcm","clk":"993078162","pt":1580536166906,"mc":[{"id":"1.168135786","rc":[{"batb":[[1,1.38,7.01]],"ltp":1.4,"tv":1019.05,"id":2249229}]}]}
{"op":"mcm","clk":"993078234","pt":1580536168813,"mc":[{"id":"1.168135786","rc":[{"batb":[[0,1.38,7.01],[1,1.35,108.18],[2,1.31,87.67]],"ltp":1.4,"tv":1019.05,"id":2249229},{"batl":[[0,3.6,192.51]],"ltp":0.0,"tv":0.0,"id":5720747}]}]}
{"op":"mcm","clk":"993078307","pt":1580536170420,"mc":[{"id":"1.168135786","rc":[{"batl":[[0,3.55,8.4]],"ltp":0.0,"tv":0.0,"id":5720747}]}]}
{"op":"mcm","clk":"993078378","pt":1580536172130,"mc":[{"id":"1.168135786","rc":[{"batb":[[0,1.38,509.68]],"ltp":1.4,"tv":1019.05,"id":2249229}]}]}
{"op":"mcm","clk":"993078900","pt":1580536188761,"mc":[{"id":"1.168135786","rc":[{"batb":[[0,1.39,2000],[1,1.38,7.01],[2,1.35,108.18]],"ltp":1.4,"tv":1019.05,"id":2249229}]}]}
{"op":"mcm","clk":"993078928","pt":1580536189566,"mc":[{"id":"1.168135786","rc":[{"batb":[[0,1.4,8.51],[1,1.39,2000],[2,1.38,7.01]],"ltp":1.4,"tv":1019.05,"id":2249229}]}]}
{"op":"mcm","clk":"993080142","pt":1580536216581,"mc":[{"id":"1.168135786","rc":[{"batl":[[0,3.55,8.4]],"ltp":0.0,"tv":0.0,"id":5720747}]}]}
{"op":"mcm","clk":"993205046","pt":1580538445717,"mc":[{"id":"1.168135786","rc":[{"batl":[[0,1.48,431.18]],"ltp":1.4,"tv":1019.05,"id":2249229}]}]}
{"op":"mcm","clk":"993211285","pt":1580538610810,"mc":[{"id":"1.168135786","rc":[{"batl":[[0,1.48,10.19]],"ltp":1.4,"tv":1019.05,"id":2249229},{"batb":[[0,3.1,204.11]],"ltp":0.0,"tv":0.0,"id":5720747}]}]}
{"op":"mcm","clk":"993211320","pt":1580538611690,"mc":[{"id":"1.168135786","rc":[{"batb":[[2,1.35,108.18]],"ltp":1.4,"tv":1019.05,"id":2249229}]}]}
{"op":"mcm","clk":"993412453","pt":1580542031797,"mc":[{"id":"1.168135786","rc":[{"batb":[[0,3.1,200.94]],"ltp":0.0,"tv":0.0,"id":5720747}]}]}
{"op":"mcm","clk":"993413468","pt":1580542046714,"mc":[{"id":"1.168135786","rc":[{"batl":[[0,1.48,431.18]],"ltp":1.4,"tv":1019.05,"id":2249229},{"batb":[[0,2.88,50],[1,2.86,20.35],[2,2.74,15.62]],"ltp":0.0,"tv":0.0,"id":5720747}]}]}
{"op":"mcm","clk":"993629163","pt":1580544680460,"mc":[{"id":"1.168135786","rc":[{"batl":[[0,1.48,425.18]],"ltp":1.4,"tv":1019.05,"id":2249229}]}]}
{"op":"mcm","clk":"993705148","pt":1580545448794,"mc":[{"id":"1.168135786","rc":[{"batl":[[0,1.48,10.19]],"ltp":1.4,"tv":1019.05,"id":2249229},{"batb":[[0,3.1,3.07],[1,2.88,50],[2,2.86,20.35]],"ltp":0.0,"tv":0.0,"id":5720747}]}]}
{"op":"mcm","clk":"993705159","pt":1580545448895,"mc":[{"id":"1.168135786","rc":[{"batb":[[0,3.1,201.91]],"ltp":0.0,"tv":0.0,"id":5720747}]}]}
{"op":"mcm","clk":"993722426","pt":1580545647345,"mc":[{"id":"1.168135786","rc":[{"batb":[[0,3.1,3.07]],"ltp":0.0,"tv":0.0,"id":5720747}]}]}
{"op":"mcm","clk":"993722592","pt":1580545649051,"mc":[{"id":"1.168135786","rc":[{"batl":[[0,2,10],[1,2,0]],"ltp":1.4,"tv":1019.05,"id":2249229},{"batb":[[0,3.1,201.91]],"ltp":0.0,"tv":0.0,"id":5720747}]}]}
{"op":"mcm","clk":"993722728","pt":1580545650650,"mc":[{"id":"1.168135786","rc":[{"batl":[[0,1.47,8.9],[1,2,10]],"ltp":1.4,"tv":1019.05,"id":2249229},{"batb":[[0,3.1,3.07]],"ltp":0.0,"tv":0.0,"id":5720747}]}]}
{"op":"mcm","clk":"993722877","pt":1580545652665,"mc":[{"id":"1.168135786","rc":[{"batl":[[0,2,10],[1,2,0]],"ltp":1.4,"tv":1019.05,"id":2249229}]}]}
{"op":"mcm","clk":"993722890","pt":1580545652824,"mc":[{"id":"1.168135786","rc":[{"batb":[[0,3.1,201.91]],"ltp":0.0,"tv":0.0,"id":5720747}]}]}
{"op":"mcm","clk":"993731599","pt":1580545765736,"mc":[{"id":"1.168135786","rc":[{"batl":[[0,1.47,10.19],[1,2,10]],"ltp":1.4,"tv":1019.05,"id":2249229}]}]}
{"op":"mcm","clk":"993731616","pt":1580545765942,"mc":[{"id":"1.168135786","rc":[{"batb":[[0,3.1,3.07]],"ltp":0.0,"tv":0.0,"id":5720747}]}]}
{"op":"mcm","clk":"993731878","pt":1580545767761,"mc":[{"id":"1.168135786","rc":[{"batl":[[0,2,10],[1,2,0]],"ltp":1.4,"tv":1019.05,"id":2249229},{"batb":[[0,3.1,201.91]],"ltp":0.0,"tv":0.0,"id":5720747}]}]}
{"op":"mcm","clk":"993741905","pt":1580545887507,"mc":[{"id":"1.168135786","rc":[{"batl":[[0,1.47,9.51],[1,2,10]],"ltp":1.4,"tv":1019.05,"id":2249229},{"batb":[[0,3.1,3.07]],"ltp":0.0,"tv":0.0,"id":5720747}]}]}
{"op":"mcm","clk":"993742001","pt":1580545888803,"mc":[{"id":"1.168135786","rc":[{"batl":[[0,2,10],[1,2,0]],"ltp":1.4,"tv":1019.05,"id":2249229}]}]}
{"op":"mcm","clk":"993742018","pt":1580545889009,"mc":[{"id":"1.168135786","rc":[{"batb":[[0,3.1,201.91]],"ltp":0.0,"tv":0.0,"id":5720747}]}]}
{"op":"mcm","clk":"993745434","pt":1580545931664,"mc":[{"id":"1.168135786","rc":[{"batb":[[0,3.1,349.71]],"ltp":0.0,"tv":0.0,"id":5720747}]}]}
{"op":"mcm","clk":"993752323","pt":1580546008565,"mc":[{"id":"1.168135786","rc":[{"batl":[[0,1.47,9.14],[1,2,10]],"ltp":1.4,"tv":1019.05,"id":2249229},{"batb":[[0,3.1,3.07]],"ltp":0.0,"tv":0.0,"id":5720747}]}]}
{"op":"mcm","clk":"993752426","pt":1580546010167,"mc":[{"id":"1.168135786","rc":[{"batl":[[0,2,10],[1,2,0]],"ltp":1.4,"tv":1019.05,"id":2249229},{"batb":[[0,3.1,351.21]],"ltp":0.0,"tv":0.0,"id":5720747}]}]}
{"op":"mcm","clk":"993762515","pt":1580546130652,"mc":[{"id":"1.168135786","rc":[{"batl":[[0,1.47,8.53],[1,2,10]],"ltp":1.4,"tv":1019.05,"id":2249229},{"batb":[[0,3.1,3.07]],"ltp":0.0,"tv":0.0,"id":5720747}]}]}
{"op":"mcm","clk":"993762685","pt":1580546132719,"mc":[{"id":"1.168135786","rc":[{"batl":[[0,2,10],[1,2,0]],"ltp":1.4,"tv":1019.05,"id":2249229}]}]}
{"op":"mcm","clk":"993762704","pt":1580546132925,"mc":[{"id":"1.168135786","rc":[{"batb":[[0,3.1,351.21]],"ltp":0.0,"tv":0.0,"id":5720747}]}]}
{"op":"mcm","clk":"993782645","pt":1580546252503,"mc":[{"id":"1.168135786","rc":[{"batl":[[0,1.47,10.19],[1,2,10]],"ltp":1.4,"tv":1019.05,"id":2249229},{"batb":[[0,3.1,3.07]],"ltp":0.0,"tv":0.0,"id":5720747}]}]}
{"op":"mcm","clk":"993782743","pt":1580546253806,"mc":[{"id":"1.168135786","rc":[{"batl":[[0,2,10],[1,2,0]],"ltp":1.4,"tv":1019.05,"id":2249229}]}]}
{"op":"mcm","clk":"993782758","pt":1580546254016,"mc":[{"id":"1.168135786","rc":[{"batb":[[0,3.1,351.21]],"ltp":0.0,"tv":0.0,"id":5720747}]}]}
{"op":"mcm","clk":"993793409","pt":1580546371586,"mc":[{"id":"1.168135786","rc":[{"batl":[[0,1.47,8.46],[1,2,10]],"ltp":1.4,"tv":1019.05,"id":2249229},{"batb":[[0,3.1,3.07]],"ltp":0.0,"tv":0.0,"id":5720747}]}]}
{"op":"mcm","clk":"993793558","pt":1580546373292,"mc":[{"id":"1.168135786","rc":[{"batl":[[0,2,10],[1,2,0]],"ltp":1.4,"tv":1019.05,"id":2249229},{"batb":[[0,3.1,351.21]],"ltp":0.0,"tv":0.0,"id":5720747}]}]}
{"op":"mcm","clk":"993804578","pt":1580546492819,"mc":[{"id":"1.168135786","rc":[{"batl":[[0,1.47,10.19],[1,2,10]],"ltp":1.4,"tv":1019.05,"id":2249229}]}]}
{"op":"mcm","clk":"993804604","pt":1580546493008,"mc":[{"id":"1.168135786","rc":[{"batb":[[0,3.1,3.07]],"ltp":0.0,"tv":0.0,"id":5720747}]}]}
{"op":"mcm","clk":"993804791","pt":1580546494720,"mc":[{"id":"1.168135786","rc":[{"batl":[[0,2,10],[1,2,0]],"ltp":1.4,"tv":1019.05,"id":2249229},{"batb":[[0,3.1,351.21]],"ltp":0.0,"tv":0.0,"id":5720747}]}]}
{"op":"mcm","clk":"993815837","pt":1580546613479,"mc":[{"id":"1.168135786","rc":[{"batl":[[0,1.47,9.69],[1,2,10]],"ltp":1.4,"tv":1019.05,"id":2249229},{"batb":[[0,3.1,3.07]],"ltp":0.0,"tv":0.0,"id":5720747}]}]}
{"op":"mcm","clk":"993815934","pt":1580546614774,"mc":[{"id":"1.168135786","rc":[{"batl":[[0,2,10],[1,2,0]],"ltp":1.4,"tv":1019.05,"id":2249229}]}]}
{"op":"mcm","clk":"993815950","pt":1580546614983,"mc":[{"id":"1.168135786","rc":[{"batb":[[0,3.1,351.21]],"ltp":0.0,"tv":0.0,"id":5720747}]}]}
{"op":"mcm","clk":"993826361","pt":1580546733341,"mc":[{"id":"1.168135786","rc":[{"batl":[[0,1.47,10.19],[1,2,10]],"ltp":1.4,"tv":1019.05,"id":2249229},{"batb":[[0,3.1,3.07]],"ltp":0.0,"tv":0.0,"id":5720747}]}]}
{"op":"mcm","clk":"993826500","pt":1580546735080,"mc":[{"id":"1.168135786","rc":[{"batl":[[0,2,10],[1,2,0]],"ltp":1.4,"tv":1019.05,"id":2249229},{"batb":[[0,3.1,351.21]],"ltp":0.0,"tv":0.0,"id":5720747}]}]}
{"op":"mcm","clk":"993836553","pt":1580546853537,"mc":[{"id":"1.168135786","rc":[{"batl":[[0,1.47,8.63],[1,2,10]],"ltp":1.4,"tv":1019.05,"id":2249229},{"batb":[[0,3.1,3.07]],"ltp":0.0,"tv":0.0,"id":5720747}]}]}
{"op":"mcm","clk":"993836688","pt":1580546855552,"mc":[{"id":"1.168135786","rc":[{"batl":[[0,2,10],[1,2,0]],"ltp":1.4,"tv":1019.05,"id":2249229},{"batb":[[0,3.1,351.21]],"ltp":0.0,"tv":0.0,"id":5720747}]}]}
{"op":"mcm","clk":"993845767","pt":1580546973271,"mc":[{"id":"1.168135786","rc":[{"batl":[[0,1.47,8.91],[1,2,10]],"ltp":1.4,"tv":1019.05,"id":2249229},{"batb":[[0,3.1,3.07]],"ltp":0.0,"tv":0.0,"id":5720747}]}]}
{"op":"mcm","clk":"993845890","pt":1580546974674,"mc":[{"id":"1.168135786","rc":[{"batl":[[0,2,10],[1,2,0]],"ltp":1.4,"tv":1019.05,"id":2249229}]}]}
{"op":"mcm","clk":"993845916","pt":1580546974981,"mc":[{"id":"1.168135786","rc":[{"batb":[[0,3.1,351.21]],"ltp":0.0,"tv":0.0,"id":5720747}]}]}
{"op":"mcm","clk":"993855646","pt":1580547092429,"mc":[{"id":"1.168135786","rc":[{"batl":[[0,1.47,9.24],[1,2,10]],"ltp":1.4,"tv":1019.05,"id":2249229},{"batb":[[0,3.1,3.07]],"ltp":0.0,"tv":0.0,"id":5720747}]}]}
{"op":"mcm","clk":"993855798","pt":1580547094556,"mc":[{"id":"1.168135786","rc":[{"batl":[[0,2,10],[1,2,0]],"ltp":1.4,"tv":1019.05,"id":2249229},{"batb":[[0,3.1,351.21]],"ltp":0.0,"tv":0.0,"id":5720747}]}]}
{"op":"mcm","clk":"993874941","pt":1580547209695,"mc":[{"id":"1.168135786","rc":[{"batl":[[0,1.47,8.54],[1,2,10]],"ltp":1.4,"tv":1019.05,"id":2249229},{"batb":[[0,3.1,3.07]],"ltp":0.0,"tv":0.0,"id":5720747}]}]}
{"op":"mcm","clk":"993875119","pt":1580547211688,"mc":[{"id":"1.168135786","rc":[{"batl":[[0,2,10],[1,2,0]],"ltp":1.4,"tv":1019.05,"id":2249229},{"batb":[[0,3.1,351.21]],"ltp":0.0,"tv":0.0,"id":5720747}]}]}
{"op":"mcm","clk":"993885343","pt":1580547326776,"mc":[{"id":"1.168135786","rc":[{"batl":[[0,1.47,10.19],[1,2,10]],"ltp":1.4,"tv":1019.05,"id":2249229},{"batb":[[0,3.1,3.07]],"ltp":0.0,"tv":0.0,"id":5720747}]}]}
{"op":"mcm","clk":"993885507","pt":1580547328551,"mc":[{"id":"1.168135786","rc":[{"batl":[[0,2,10],[1,2,0]],"ltp":1.4,"tv":1019.05,"id":2249229},{"batb":[[0,3.1,351.21]],"ltp":0.0,"tv":0.0,"id":5720747}]}]}
{"op":"mcm","clk":"993896268","pt":1580547443333,"mc":[{"id":"1.168135786","rc":[{"batl":[[0,1.47,10.19],[1,2,10]],"ltp":1.4,"tv":1019.05,"id":2249229},{"batb":[[0,3.1,3.07]],"ltp":0.0,"tv":0.0,"id":5720747}]}]}
{"op":"mcm","clk":"993896431","pt":1580547445147,"mc":[{"id":"1.168135786","rc":[{"batl":[[0,2,10],[1,2,0]],"ltp":1.4,"tv":1019.05,"id":2249229},{"batb":[[0,3.1,351.21]],"ltp":0.0,"tv":0.0,"id":5720747}]}]}
{"op":"mcm","clk":"993905708","pt":1580547561160,"mc":[{"id":"1.168135786","rc":[{"batl":[[0,1.47,9.22],[1,2,10]],"ltp":1.4,"tv":1019.05,"id":2249229},{"batb":[[0,3.1,3.07]],"ltp":0.0,"tv":0.0,"id":5720747}]}]}
{"op":"mcm","clk":"993905819","pt":1580547562777,"mc":[{"id":"1.168135786","rc":[{"batl":[[0,2,10],[1,2,0]],"ltp":1.4,"tv":1019.05,"id":2249229},{"batb":[[0,3.1,351.21]],"ltp":0.0,"tv":0.0,"id":5720747}]}]}
{"op":"mcm","clk":"993910125","pt":1580547610212,"mc":[{"id":"1.168135786","rc":[{"batl":[[0,1.47,9.25],[1,2,10]],"ltp":1.4,"tv":1019.05,"id":2249229},{"batb":[[0,3.1,3.07]],"ltp":0.0,"tv":0.0,"id":5720747}]}]}
{"op":"mcm","clk":"993910267","pt":1580547611620,"mc":[{"id":"1.168135786","rc":[{"batl":[[0,2,10],[1,2,0]],"ltp":1.4,"tv":1019.05,"id":2249229}]}]}
{"op":"mcm","clk":"993910291","pt":1580547611827,"mc":[{"id":"1.168135786","rc":[{"batb":[[0,3.1,351.21]],"ltp":0.0,"tv":0.0,"id":5720747}]}]}
{"op":"mcm","clk":"993911004","pt":1580547619763,"mc":[{"id":"1.168135786","rc":[{"batl":[[0,1.47,9.83],[1,2,10]],"ltp":1.4,"tv":1019.05,"id":2249229},{"batb":[[0,3.1,3.07]],"ltp":0.0,"tv":0.0,"id":5720747}]}]}
{"op":"mcm","clk":"993911118","pt":1580547621123,"mc":[{"id":"1.168135786","rc":[{"batl":[[0,2,10],[1,2,0]],"ltp":1.4,"tv":1019.05,"id":2249229},{"batb":[[0,3.1,351.21]],"ltp":0.0,"tv":0.0,"id":5720747}]}]}
{"op":"mcm","clk":"993928082","pt":1580547780652,"mc":[{"id":"1.168135786","rc":[{"batl":[[0,1.47,8.67],[1,2,10]],"ltp":1.4,"tv":1019.05,"id":2249229},{"batb":[[0,3.1,3.07]],"ltp":0.0,"tv":0.0,"id":5720747}]}]}
{"op":"mcm","clk":"993928275","pt":1580547782261,"mc":[{"id":"1.168135786","rc":[{"batl":[[0,2,10],[1,2,0]],"ltp":1.4,"tv":1019.05,"id":2249229},{"batb":[[0,3.1,351.21]],"ltp":0.0,"tv":0.0,"id":5720747}]}]}
{"op":"mcm","clk":"993946497","pt":1580547961802,"mc":[{"id":"1.168135786","rc":[{"batl":[[0,1.47,8.61],[1,2,10]],"ltp":1.4,"tv":1019.05,"id":2249229},{"batb":[[0,3.1,3.07]],"ltp":0.0,"tv":0.0,"id":5720747}]}]}
{"op":"mcm","clk":"993946721","pt":1580547963798,"mc":[{"id":"1.168135786","rc":[{"batl":[[0,2,10],[1,2,0]],"ltp":1.4,"tv":1019.05,"id":2249229},{"batb":[[0,3.1,351.21]],"ltp":0.0,"tv":0.0,"id":5720747}]}]}
{"op":"mcm","clk":"993972078","pt":1580548140717,"mc":[{"id":"1.168135786","rc":[{"batl":[[0,1.47,8.49],[1,2,10]],"ltp":1.4,"tv":1019.05,"id":2249229},{"batb":[[0,3.1,3.07]],"ltp":0.0,"tv":0.0,"id":5720747}]}]}
{"op":"mcm","clk":"993972291","pt":1580548143329,"mc":[{"id":"1.168135786","rc":[{"batl":[[0,2,10],[1,2,0]],"ltp":1.4,"tv":1019.05,"id":2249229},{"batb":[[0,3.1,351.21]],"ltp":0.0,"tv":0.0,"id":5720747}]}]}
{"op":"mcm","clk":"993996838","pt":1580548381696,"mc":[{"id":"1.168135786","rc":[{"batl":[[0,1.47,8.75],[1,2,10]],"ltp":1.4,"tv":1019.05,"id":2249229}]}]}
{"op":"mcm","clk":"993996863","pt":1580548381905,"mc":[{"id":"1.168135786","rc":[{"batb":[[0,3.1,3.07]],"ltp":0.0,"tv":0.0,"id":5720747}]}]}
{"op":"mcm","clk":"993997060","pt":1580548383618,"mc":[{"id":"1.168135786","rc":[{"batl":[[0,2,10],[1,2,0]],"ltp":1.4,"tv":1019.05,"id":2249229}]}]}
{"op":"mcm","clk":"993997093","pt":1580548383885,"mc":[{"id":"1.168135786","rc":[{"batb":[[0,3.1,351.21]],"ltp":0.0,"tv":0.0,"id":5720747}]}]}
{"op":"mcm","clk":"994047974","pt":1580548844115,"mc":[{"id":"1.168135786","rc":[{"batb":[[0,1.4,76.45]],"ltp":1.4,"tv":1019.05,"id":2249229}]}]}
{"op":"mcm","clk":"994048244","pt":1580548846500,"mc":[{"id":"1.168135786","rc":[{"batb":[[0,3.1,348.14]],"ltp":0.0,"tv":0.0,"id":5720747}]}]}
{"op":"mcm","clk":"994072201","pt":1580548980784,"mc":[{"id":"1.168135786","rc":[{"batl":[[0,1.47,9.44],[1,2,10]],"ltp":1.4,"tv":1019.05,"id":2249229},{"batb":[[0,2.88,50],[1,2.86,20.35],[2,1.02,2780.76]],"ltp":0.0,"tv":0.0,"id":5720747}]}]}
{"op":"mcm","clk":"994072505","pt":1580548983508,"mc":[{"id":"1.168135786","rc":[{"batl":[[0,2,10],[1,2,0]],"ltp":1.4,"tv":1019.05,"id":2249229},{"batb":[[0,2.94,367.42],[1,2.88,50],[2,2.86,20.35]],"ltp":0.0,"tv":0.0,"id":5720747}]}]}
{"op":"mcm","clk":"994090621","pt":1580549160813,"mc":[{"id":"1.168135786","rc":[{"batl":[[0,1.51,10.19],[1,2,10]],"ltp":1.4,"tv":1019.05,"id":2249229},{"batb":[[0,2.88,50],[1,2.86,20.35],[2,1.02,2780.76]],"ltp":0.0,"tv":0.0,"id":5720747}]}]}
{"op":"mcm","clk":"994090647","pt":1580549161021,"mc":[{"id":"1.168135786","rc":[{"batl":[[0,1.5,719.91],[1,1.51,10.19],[2,2,10]],"ltp":1.4,"tv":1019.05,"id":2249229},{"batb":[[2,2.74,15.62]],"ltp":0.0,"tv":0.0,"id":5720747}]}]}
{"op":"mcm","clk":"994090787","pt":1580549162492,"mc":[{"id":"1.168135786","rc":[{"batl":[[1,2,10],[2,2,0]],"ltp":1.4,"tv":1019.05,"id":2249229}]}]}
{"op":"mcm","clk":"994139597","pt":1580549641577,"mc":[{"id":"1.168135786","rc":[{"batl":[[0,1.48,729.74],[1,1.49,10.19],[2,2,10]],"ltp":1.4,"tv":1019.05,"id":2249229}]}]}
{"op":"mcm","clk":"994139815","pt":1580549643767,"mc":[{"id":"1.168135786","rc":[{"batl":[[1,2,10],[2,2,0]],"ltp":1.4,"tv":1019.05,"id":2249229}]}]}
{"op":"mcm","clk":"994145385","pt":1580549701326,"mc":[{"id":"1.168135786","rc":[{"batl":[[0,1.47,9.17]],"ltp":1.4,"tv":1019.05,"id":2249229}]}]}
{"op":"mcm","clk":"994145656","pt":1580549703550,"mc":[{"id":"1.168135786","rc":[{"batl":[[0,2,10],[1,2,0]],"ltp":1.4,"tv":1019.05,"id":2249229}]}]}
{"op":"mcm","clk":"994145701","pt":1580549703918,"mc":[{"id":"1.168135786","rc":[{"batb":[[0,2.98,362.26],[1,2.88,50],[2,2.86,20.35]],"ltp":0.0,"tv":0.0,"id":5720747}]}]}
{"op":"mcm","clk":"994151516","pt":1580549760738,"mc":[{"id":"1.168135786","rc":[{"batl":[[0,1.5,10.19],[1,2,10]],"ltp":1.4,"tv":1019.05,"id":2249229}]}]}
{"op":"mcm","clk":"994151556","pt":1580549761154,"mc":[{"id":"1.168135786","rc":[{"batl":[[0,1.49,724.93],[1,1.5,10.19],[2,2,10]],"ltp":1.4,"tv":1019.05,"id":2249229},{"batb":[[0,2.88,50],[1,2.86,20.35],[2,1.02,2780.76]],"ltp":0.0,"tv":0.0,"id":5720747}]}]}
{"op":"mcm","clk":"994151698","pt":1580549762558,"mc":[{"id":"1.168135786","rc":[{"batl":[[0,1.48,738.25],[1,2,10],[2,2,0]],"ltp":1.4,"tv":1019.05,"id":2249229}]}]}
{"op":"mcm","clk":"994151974","pt":1580549765426,"mc":[{"id":"1.168135786","rc":[{"batb":[[2,2.74,15.62]],"ltp":0.0,"tv":0.0,"id":5720747}]}]}
{"op":"mcm","clk":"994512231","pt":1580552255019,"mc":[{"id":"1.168135786","rc":[{"batb":[[0,1.4,8.51]],"ltp":1.4,"tv":1019.05,"id":2249229},{"batb":[[0,2.88,64.45],[2,1.02,2780.76]],"ltp":0.0,"tv":0.0,"id":5720747}]}]}
{"op":"mcm","clk":"994553408","pt":1580552472555,"mc":[{"id":"1.168135786","rc":[{"batb":[[0,3.1,3.07],[1,2.88,64.45],[2,2.86,20.35]],"ltp":0.0,"tv":0.0,"id":5720747}]}]}
{"op":"mcm","clk":"994553479","pt":1580552472928,"mc":[{"id":"1.168135786","rc":[{"batl":[[0,1.48,8.51]],"ltp":1.4,"tv":1019.05,"id":2249229},{"batb":[[0,3.1,351.21]],"ltp":0.0,"tv":0.0,"id":5720747}]}]}
{"op":"mcm","clk":"994554158","pt":1580552476580,"mc":[{"id":"1.168135786","rc":[{"batb":[[1,2.88,50]],"ltp":0.0,"tv":0.0,"id":5720747}]}]}
{"op":"mcm","clk":"994905340","pt":1580554419081,"mc":[{"id":"1.168135786","rc":[{"batb":[[0,1.4,138.74]],"ltp":1.4,"tv":1019.05,"id":2249229}]}]}
{"op":"mcm","clk":"995247250","pt":1580556072468,"mc":[{"id":"1.168135786","rc":[{"batb":[[0,3.1,348.14]],"ltp":0.0,"tv":0.0,"id":5720747}]}]}
{"op":"mcm","clk":"995278081","pt":1580556174646,"mc":[{"id":"1.168135786","rc":[{"batl":[[0,1.47,200],[1,1.48,8.51],[2,2,10]],"ltp":1.4,"tv":1019.05,"id":2249229}]}]}
{"op":"mcm","clk":"995278125","pt":1580556174927,"mc":[{"id":"1.168135786","rc":[{"batb":[[0,2.88,50],[1,2.86,20.35],[2,1.02,2780.76]],"ltp":0.0,"tv":0.0,"id":5720747}]}]}
{"op":"mcm","clk":"995278362","pt":1580556176224,"mc":[{"id":"1.168135786","rc":[{"batl":[[1,2,10],[2,2,0]],"ltp":1.4,"tv":1019.05,"id":2249229}]}]}
{"op":"mcm","clk":"995278908","pt":1580556179051,"mc":[{"id":"1.168135786","rc":[{"batb":[[0,2.88,64.45]],"ltp":0.0,"tv":0.0,"id":5720747}]}]}
{"op":"mcm","clk":"995454675","pt":1580557020795,"mc":[{"id":"1.168135786","rc":[{"batl":[[0,1.46,8.67],[1,1.47,200],[2,2,10]],"ltp":1.4,"tv":1019.05,"id":2249229}]}]}
{"op":"mcm","clk":"995745454","pt":1580558584511,"mc":[{"id":"1.168135786","rc":[{"batb":[[0,1.4,8.51]],"ltp":1.4,"tv":1019.05,"id":2249229}]}]}
{"op":"mcm","clk":"996209280","pt":1580560980307,"mc":[{"id":"1.168135786","rc":[{"batb":[[2,1.16,10]],"ltp":1.4,"tv":1019.05,"id":2249229},{"batb":[[1,1.02,2780.76],[2,1.01,2791.57]],"ltp":0.0,"tv":0.0,"id":5720747}]}]}
{"op":"mcm","clk":"996209404","pt":1580560980924,"mc":[{"id":"1.168135786","rc":[{"batb":[[2,1.36,184.26]],"ltp":1.4,"tv":1019.05,"id":2249229},{"batb":[[0,2.88,99.74]],"ltp":0.0,"tv":0.0,"id":5720747}]}]}
{"op":"mcm","clk":"997844598","pt":1580568467580,"mc":[{"id":"1.168135786","rc":[{"batb":[[2,1.16,10]],"ltp":1.4,"tv":1019.05,"id":2249229},{"batb":[[0,2.88,64.45]],"ltp":0.0,"tv":0.0,"id":5720747}]}]}
{"op":"mcm","clk":"997844744","pt":1580568468157,"mc":[{"id":"1.168135786","rc":[{"batb":[[2,1.36,184.26]],"ltp":1.4,"tv":1019.05,"id":2249229},{"batb":[[1,2.86,35.67],[2,1.02,2780.76]],"ltp":0.0,"tv":0.0,"id":5720747}]}]}
{"op":"mcm","clk":"999926010","pt":1580577587607,"mc":[{"id":"1.168135786","rc":[{"batb":[[0,1.4,852.27]],"ltp":1.4,"tv":1019.05,"id":2249229}]}]}
{"op":"mcm","clk":"999926306","pt":1580577589531,"mc":[{"id":"1.168135786","rc":[{"batb":[[0,1.4,8.51]],"ltp":1.4,"tv":1019.05,"id":2249229},{"batl":[[0,3.45,8.4]],"ltp":0.0,"tv":0.0,"id":5720747}]}]}
{"op":"mcm","clk":"999926474","pt":1580577590723,"mc":[{"id":"1.168135786","rc":[{"batb":[[2,1.16,10]],"ltp":1.4,"tv":1019.05,"id":2249229},{"batb":[[1,1.02,2780.76],[2,1.01,2791.57]],"batl":[[0,3.55,8.4]],"ltp":0.0,"tv":0.0,"id":5720747}]}]}
{"op":"mcm","clk":"999926527","pt":1580577592129,"mc":[{"id":"1.168135786","rc":[{"batb":[[0,1.4,852.27],[2,1.37,179.28]],"ltp":1.4,"tv":1019.05,"id":2249229},{"batb":[[1,2.86,35.67],[2,1.02,2780.76]],"ltp":0.0,"tv":0.0,"id":5720747}]}]}
{"op":"mcm","clk":"999941694","pt":1580577690249,"mc":[{"id":"1.168135786","rc":[{"batl":[[0,3.45,8.4]],"ltp":0.0,"tv":0.0,"id":5720747}]}]}
{"op":"mcm","clk":"999942280","pt":1580577694152,"mc":[{"id":"1.168135786","rc":[{"batb":[[0,1.4,8.51]],"ltp":1.4,"tv":1019.05,"id":2249229}]}]}
{"op":"mcm","clk":"999942516","pt":1580577695637,"mc":[{"id":"1.168135786","rc":[{"batb":[[0,1.4,852.27]],"ltp":1.4,"tv":1019.05,"id":2249229},{"batl":[[0,3.55,8.4]],"ltp":0.0,"tv":0.0,"id":5720747}]}]}
{"op":"mcm","clk":"999956657","pt":1580577791809,"mc":[{"id":"1.168135786","rc":[{"batb":[[0,1.4,8.51]],"ltp":1.4,"tv":1019.05,"id":2249229},{"batl":[[0,3.45,8.4]],"ltp":0.0,"tv":0.0,"id":5720747}]}]}
{"op":"mcm","clk":"999956888","pt":1580577793330,"mc":[{"id":"1.168135786","rc":[{"batb":[[0,1.4,852.27]],"ltp":1.4,"tv":1019.05,"id":2249229}]}]}
{"op":"mcm","clk":"999973227","pt":1580577895205,"mc":[{"id":"1.168135786","rc":[{"batb":[[0,1.4,8.51]],"ltp":1.4,"tv":1019.05,"id":2249229},{"batl":[[0,3.45,8.4]],"ltp":0.0,"tv":0.0,"id":5720747}]}]}
{"op":"mcm","clk":"999973493","pt":1580577896788,"mc":[{"id":"1.168135786","rc":[{"batb":[[0,1.4,852.27]],"ltp":1.4,"tv":1019.05,"id":2249229},{"batl":[[0,3.55,8.4]],"ltp":0.0,"tv":0.0,"id":5720747}]}]}
{"op":"mcm","clk":"999988871","pt":1580577995730,"mc":[{"id":"1.168135786","rc":[{"batl":[[0,3.45,8.4]],"ltp":0.0,"tv":0.0,"id":5720747}]}]}
{"op":"mcm","clk":"999988890","pt":1580577995945,"mc":[{"id":"1.168135786","rc":[{"batb":[[0,1.4,8.51]],"ltp":1.4,"tv":1019.05,"id":2249229}]}]}
{"op":"mcm","clk":"999989121","pt":1580577997512,"mc":[{"id":"1.168135786","rc":[{"batb":[[0,1.4,852.27]],"ltp":1.4,"tv":1019.05,"id":2249229},{"batl":[[0,3.55,8.4]],"ltp":0.0,"tv":0.0,"id":5720747}]}]}
{"op":"mcm","clk":"1000004428","pt":1580578096336,"mc":[{"id":"1.168135786","rc":[{"batb":[[0,1.4,8.51]],"ltp":1.4,"tv":1019.05,"id":2249229},{"batl":[[0,3.45,8.4]],"ltp":0.0,"tv":0.0,"id":5720747}]}]}
{"op":"mcm","clk":"1000004656","pt":1580578097600,"mc":[{"id":"1.168135786","rc":[{"batb":[[0,1.4,852.27]],"ltp":1.4,"tv":1019.05,"id":2249229},{"batl":[[0,3.55,8.4]],"ltp":0.0,"tv":0.0,"id":5720747}]}]}
{"op":"mcm","clk":"1000020206","pt":1580578200069,"mc":[{"id":"1.168135786","rc":[{"batb":[[0,1.4,8.51]],"ltp":1.4,"tv":1019.05,"id":2249229},{"batl":[[0,3.45,8.4]],"ltp":0.0,"tv":0.0,"id":5720747}]}]}
{"op":"mcm","clk":"1000020469","pt":1580578201616,"mc":[{"id":"1.168135786","rc":[{"batl":[[0,3.55,8.4]],"ltp":0.0,"tv":0.0,"id":5720747}]}]}
{"op":"mcm","clk":"1000020578","pt":1580578202181,"mc":[{"id":"1.168135786","rc":[{"batb":[[0,1.4,852.27]],"ltp":1.4,"tv":1019.05,"id":2249229}]}]}
{"op":"mcm","clk":"1000037608","pt":1580578304312,"mc":[{"id":"1.168135786","rc":[{"batb":[[0,1.4,8.51]],"ltp":1.4,"tv":1019.05,"id":2249229},{"batl":[[0,3.45,8.4]],"ltp":0.0,"tv":0.0,"id":5720747}]}]}
{"op":"mcm","clk":"1000037831","pt":1580578305748,"mc":[{"id":"1.168135786","rc":[{"batb":[[0,1.4,852.27]],"ltp":1.4,"tv":1019.05,"id":2249229},{"batl":[[0,3.55,8.4]],"ltp":0.0,"tv":0.0,"id":5720747}]}]}
{"op":"mcm","clk":"1000054656","pt":1580578407739,"mc":[{"id":"1.168135786","rc":[{"batb":[[0,1.4,8.51]],"ltp":1.4,"tv":1019.05,"id":2249229},{"batl":[[0,3.45,8.4]],"ltp":0.0,"tv":0.0,"id":5720747}]}]}
{"op":"mcm","clk":"1000054915","pt":1580578409353,"mc":[{"id":"1.168135786","rc":[{"batb":[[0,1.4,852.27]],"ltp":1.4,"tv":1019.05,"id":2249229},{"batl":[[0,3.55,8.4]],"ltp":0.0,"tv":0.0,"id":5720747}]}]}
{"op":"mcm","clk":"1000073356","pt":1580578513673,"mc":[{"id":"1.168135786","rc":[{"batb":[[0,1.4,8.51]],"ltp":1.4,"tv":1019.05,"id":2249229},{"batl":[[0,3.45,8.4]],"ltp":0.0,"tv":0.0,"id":5720747}]}]}
{"op":"mcm","clk":"1000073714","pt":1580578515467,"mc":[{"id":"1.168135786","rc":[{"batb":[[0,1.4,852.27]],"ltp":1.4,"tv":1019.05,"id":2249229},{"batl":[[0,3.55,8.4]],"ltp":0.0,"tv":0.0,"id":5720747}]}]}
{"op":"mcm","clk":"1000092587","pt":1580578620567,"mc":[{"id":"1.168135786","rc":[{"batl":[[0,3.45,8.4]],"ltp":0.0,"tv":0.0,"id":5720747}]}]}
{"op":"mcm","clk":"1000092633","pt":1580578620892,"mc":[{"id":"1.168135786","rc":[{"batb":[[0,1.4,8.51]],"ltp":1.4,"tv":1019.05,"id":2249229}]}]}
{"op":"mcm","clk":"1000092985","pt":1580578622737,"mc":[{"id":"1.168135786","rc":[{"batb":[[0,1.4,852.27]],"ltp":1.4,"tv":1019.05,"id":2249229},{"batl":[[0,3.55,8.4]],"ltp":0.0,"tv":0.0,"id":5720747}]}]}
{"op":"mcm","clk":"1000110819","pt":1580578731180,"mc":[{"id":"1.168135786","rc":[{"batb":[[0,1.4,8.51]],"ltp":1.4,"tv":1019.05,"id":2249229},{"batl":[[0,3.45,8.4]],"ltp":0.0,"tv":0.0,"id":5720747}]}]}
{"op":"mcm","clk":"1000111118","pt":1580578732958,"mc":[{"id":"1.168135786","rc":[{"batb":[[0,1.4,852.27]],"ltp":1.4,"tv":1019.05,"id":2249229},{"batl":[[0,3.55,8.4]],"ltp":0.0,"tv":0.0,"id":5720747}]}]}
{"op":"mcm","clk":"1000128368","pt":1580578840749,"mc":[{"id":"1.168135786","rc":[{"batb":[[0,1.4,8.51]],"ltp":1.4,"tv":1019.05,"id":2249229},{"batl":[[0,3.45,8.4]],"ltp":0.0,"tv":0.0,"id":5720747}]}]}
{"op":"mcm","clk":"1000128592","pt":1580578842060,"mc":[{"id":"1.168135786","rc":[{"batb":[[0,1.4,852.27]],"ltp":1.4,"tv":1019.05,"id":2249229},{"batl":[[0,3.55,8.4]],"ltp":0.0,"tv":0.0,"id":5720747}]}]}
{"op":"mcm","clk":"1000146171","pt":1580578949297,"mc":[{"id":"1.168135786","rc":[{"batb":[[0,1.4,8.51]],"ltp":1.4,"tv":1019.05,"id":2249229},{"batl":[[0,3.45,8.4]],"ltp":0.0,"tv":0.0,"id":5720747}]}]}
{"op":"mcm","clk":"1000146394","pt":1580578950694,"mc":[{"id":"1.168135786","rc":[{"batb":[[0,1.4,852.27]],"ltp":1.4,"tv":1019.05,"id":2249229}]}]}
{"op":"mcm","clk":"1000162543","pt":1580579056643,"mc":[{"id":"1.168135786","rc":[{"batb":[[0,1.4,8.51]],"ltp":1.4,"tv":1019.05,"id":2249229},{"batl":[[0,3.45,8.4]],"ltp":0.0,"tv":0.0,"id":5720747}]}]}
{"op":"mcm","clk":"1000162766","pt":1580579058249,"mc":[{"id":"1.168135786","rc":[{"batb":[[0,1.4,852.27]],"ltp":1.4,"tv":1019.05,"id":2249229},{"batl":[[0,3.55,8.4]],"ltp":0.0,"tv":0.0,"id":5720747}]}]}
{"op":"mcm","clk":"1000179599","pt":1580579165991,"mc":[{"id":"1.168135786","rc":[{"batl":[[0,3.45,8.4]],"ltp":0.0,"tv":0.0,"id":5720747}]}]}
{"op":"mcm","clk":"1000180103","pt":1580579169062,"mc":[{"id":"1.168135786","rc":[{"batb":[[0,1.4,8.51]],"ltp":1.4,"tv":1019.05,"id":2249229}]}]}
{"op":"mcm","clk":"1000180364","pt":1580579170589,"mc":[{"id":"1.168135786","rc":[{"batb":[[0,1.4,852.27]],"ltp":1.4,"tv":1019.05,"id":2249229},{"batl":[[0,3.55,8.4]],"ltp":0.0,"tv":0.0,"id":5720747}]}]}
{"op":"mcm","clk":"1000196053","pt":1580579279227,"mc":[{"id":"1.168135786","rc":[{"batb":[[0,1.4,8.51]],"ltp":1.4,"tv":1019.05,"id":2249229},{"batl":[[0,3.45,8.4]],"ltp":0.0,"tv":0.0,"id":5720747}]}]}
{"op":"mcm","clk":"1000196335","pt":1580579281210,"mc":[{"id":"1.168135786","rc":[{"batb":[[0,1.4,852.27]],"ltp":1.4,"tv":1019.05,"id":2249229},{"batl":[[0,3.55,8.4]],"ltp":0.0,"tv":0.0,"id":5720747}]}]}
{"op":"mcm","clk":"1000212236","pt":1580579392730,"mc":[{"id":"1.168135786","rc":[{"batb":[[0,1.4,8.51]],"ltp":1.4,"tv":1019.05,"id":2249229},{"batl":[[0,3.45,8.4]],"ltp":0.0,"tv":0.0,"id":5720747}]}]}
{"op":"mcm","clk":"1000212500","pt":1580579394921,"mc":[{"id":"1.168135786","rc":[{"batl":[[0,3.55,8.4]],"ltp":0.0,"tv":0.0,"id":5720747}]}]}
{"op":"mcm","clk":"1000212857","pt":1580579397686,"mc":[{"id":"1.168135786","rc":[{"batb":[[0,1.4,852.27]],"ltp":1.4,"tv":1019.05,"id":2249229}]}]}
{"op":"mcm","clk":"1000228679","pt":1580579505752,"mc":[{"id":"1.168135786","rc":[{"batl":[[0,3.45,8.4]],"ltp":0.0,"tv":0.0,"id":5720747}]}]}
{"op":"mcm","clk":"1000228703","pt":1580579505965,"mc":[{"id":"1.168135786","rc":[{"batb":[[0,1.4,8.51]],"ltp":1.4,"tv":1019.05,"id":2249229}]}]}
{"op":"mcm","clk":"1000228920","pt":1580579507588,"mc":[{"id":"1.168135786","rc":[{"batb":[[0,1.4,852.27]],"ltp":1.4,"tv":1019.05,"id":2249229}]}]}
{"op":"mcm","clk":"1000245675","pt":1580579620328,"mc":[{"id":"1.168135786","rc":[{"batb":[[0,1.4,8.51]],"ltp":1.4,"tv":1019.05,"id":2249229},{"batl":[[0,3.45,8.4]],"ltp":0.0,"tv":0.0,"id":5720747}]}]}
{"op":"mcm","clk":"1000245853","pt":1580579621611,"mc":[{"id":"1.168135786","rc":[{"batb":[[0,1.4,852.27]],"ltp":1.4,"tv":1019.05,"id":2249229},{"batl":[[0,3.55,8.4]],"ltp":0.0,"tv":0.0,"id":5720747}]}]}
{"op":"mcm","clk":"1000260459","pt":1580579734456,"mc":[{"id":"1.168135786","rc":[{"batb":[[0,1.4,8.51]],"ltp":1.4,"tv":1019.05,"id":2249229},{"batl":[[0,3.45,8.4]],"ltp":0.0,"tv":0.0,"id":5720747}]}]}
{"op":"mcm","clk":"1000260602","pt":1580579735676,"mc":[{"id":"1.168135786","rc":[{"batl":[[0,3.55,8.4]],"ltp":0.0,"tv":0.0,"id":5720747}]}]}
{"op":"mcm","clk":"1000260630","pt":1580579735839,"mc":[{"id":"1.168135786","rc":[{"batb":[[0,1.4,852.27]],"ltp":1.4,"tv":1019.05,"id":2249229}]}]}
{"op":"mcm","clk":"1000275058","pt":1580579848353,"mc":[{"id":"1.168135786","rc":[{"batb":[[0,1.4,8.51]],"ltp":1.4,"tv":1019.05,"id":2249229},{"batl":[[0,3.45,8.4]],"ltp":0.0,"tv":0.0,"id":5720747}]}]}
{"op":"mcm","clk":"1000275345","pt":1580579850539,"mc":[{"id":"1.168135786","rc":[{"batb":[[0,1.4,852.27]],"ltp":1.4,"tv":1019.05,"id":2249229},{"batl":[[0,3.55,8.4]],"ltp":0.0,"tv":0.0,"id":5720747}]}]}
{"op":"mcm","clk":"1000289575","pt":1580579961296,"mc":[{"id":"1.168135786","rc":[{"batb":[[0,1.4,8.51]],"ltp":1.4,"tv":1019.05,"id":2249229},{"batl":[[0,3.45,8.4]],"ltp":0.0,"tv":0.0,"id":5720747}]}]}
{"op":"mcm","clk":"1000289780","pt":1580579962784,"mc":[{"id":"1.168135786","rc":[{"batb":[[0,1.4,852.27]],"ltp":1.4,"tv":1019.05,"id":2249229}]}]}
{"op":"mcm","clk":"1000293159","pt":1580579986742,"mc":[{"id":"1.168135786","rc":[{"batb":[[0,2.88,65.7]],"ltp":0.0,"tv":0.0,"id":5720747}]}]}
{"op":"mcm","clk":"1000296396","pt":1580580009471,"mc":[{"id":"1.168135786","rc":[{"batb":[[0,1.4,8.51]],"ltp":1.4,"tv":1019.05,"id":2249229},{"batl":[[0,3.45,8.4]],"ltp":0.0,"tv":0.0,"id":5720747}]}]}
{"op":"mcm","clk":"1000296613","pt":1580580011147,"mc":[{"id":"1.168135786","rc":[{"batb":[[0,1.4,852.27]],"ltp":1.4,"tv":1019.05,"id":2249229},{"batl":[[0,3.55,8.4]],"ltp":0.0,"tv":0.0,"id":5720747}]}]}
{"op":"mcm","clk":"1000303751","pt":1580580060715,"mc":[{"id":"1.168135786","rc":[{"batb":[[0,1.4,8.51]],"ltp":1.4,"tv":1019.05,"id":2249229},{"batl":[[0,3.45,8.4]],"ltp":0.0,"tv":0.0,"id":5720747}]}]}
{"op":"mcm","clk":"1000303963","pt":1580580062121,"mc":[{"id":"1.168135786","rc":[{"batb":[[0,1.4,852.27]],"ltp":1.4,"tv":1019.05,"id":2249229},{"batl":[[0,3.55,8.4]],"ltp":0.0,"tv":0.0,"id":5720747}]}]}
{"op":"mcm","clk":"1000312382","pt":1580580121210,"mc":[{"id":"1.168135786","rc":[{"batb":[[0,1.4,8.51]],"ltp":1.4,"tv":1019.05,"id":2249229},{"batl":[[0,3.45,8.4]],"ltp":0.0,"tv":0.0,"id":5720747}]}]}
{"op":"mcm","clk":"1000312638","pt":1580580122803,"mc":[{"id":"1.168135786","rc":[{"batb":[[0,1.4,852.27]],"ltp":1.4,"tv":1019.05,"id":2249229},{"batl":[[0,3.55,8.4]],"ltp":0.0,"tv":0.0,"id":5720747}]}]}
{"op":"mcm","clk":"1000322043","pt":1580580187211,"mc":[{"id":"1.168135786","rc":[{"batb":[[0,1.4,8.51]],"ltp":1.4,"tv":1019.05,"id":2249229},{"batl":[[0,3.45,8.4]],"ltp":0.0,"tv":0.0,"id":5720747}]}]}
{"op":"mcm","clk":"1000322244","pt":1580580188616,"mc":[{"id":"1.168135786","rc":[{"batb":[[0,1.4,852.27]],"ltp":1.4,"tv":1019.05,"id":2249229}]}]}
{"op":"mcm","clk":"1000331486","pt":1580580254596,"mc":[{"id":"1.168135786","rc":[{"batb":[[0,1.4,8.51]],"ltp":1.4,"tv":1019.05,"id":2249229},{"batl":[[0,3.45,8.4]],"ltp":0.0,"tv":0.0,"id":5720747}]}]}
{"op":"mcm","clk":"1000331677","pt":1580580256008,"mc":[{"id":"1.168135786","rc":[{"batb":[[0,1.4,852.27]],"ltp":1.4,"tv":1019.05,"id":2249229},{"batl":[[0,3.55,8.4]],"ltp":0.0,"tv":0.0,"id":5720747}]}]}
{"op":"mcm","clk":"1000340943","pt":1580580322809,"mc":[{"id":"1.168135786","rc":[{"batb":[[0,1.4,8.51]],"ltp":1.4,"tv":1019.05,"id":2249229},{"batl":[[0,3.45,8.4]],"ltp":0.0,"tv":0.0,"id":5720747}]}]}
{"op":"mcm","clk":"1000341145","pt":1580580324208,"mc":[{"id":"1.168135786","rc":[{"batb":[[0,1.4,852.27]],"ltp":1.4,"tv":1019.05,"id":2249229}]}]}
{"op":"mcm","clk":"1000350918","pt":1580580392393,"mc":[{"id":"1.168135786","rc":[{"batb":[[0,1.4,8.51]],"ltp":1.4,"tv":1019.05,"id":2249229},{"batl":[[0,3.45,8.4]],"ltp":0.0,"tv":0.0,"id":5720747}]}]}
{"op":"mcm","clk":"1000351128","pt":1580580393885,"mc":[{"id":"1.168135786","rc":[{"batb":[[0,1.4,852.27]],"ltp":1.4,"tv":1019.05,"id":2249229},{"batl":[[0,3.55,8.4]],"ltp":0.0,"tv":0.0,"id":5720747}]}]}
{"op":"mcm","clk":"1000361952","pt":1580580463722,"mc":[{"id":"1.168135786","rc":[{"batb":[[0,1.4,8.51]],"ltp":1.4,"tv":1019.05,"id":2249229},{"batl":[[0,3.45,8.4]],"ltp":0.0,"tv":0.0,"id":5720747}]}]}
{"op":"mcm","clk":"1000362150","pt":1580580465020,"mc":[{"id":"1.168135786","rc":[{"batb":[[0,1.4,852.27]],"ltp":1.4,"tv":1019.05,"id":2249229}]}]}
{"op":"mcm","clk":"1000372296","pt":1580580530746,"mc":[{"id":"1.168135786","rc":[{"batb":[[0,1.4,8.51]],"ltp":1.4,"tv":1019.05,"id":2249229},{"batl":[[0,3.45,8.4]],"ltp":0.0,"tv":0.0,"id":5720747}]}]}
{"op":"mcm","clk":"1000372587","pt":1580580532426,"mc":[{"id":"1.168135786","rc":[{"batb":[[0,1.4,852.27]],"ltp":1.4,"tv":1019.05,"id":2249229},{"batl":[[0,3.55,8.4]],"ltp":0.0,"tv":0.0,"id":5720747}]}]}
{"op":"mcm","clk":"1000382747","pt":1580580593437,"mc":[{"id":"1.168135786","rc":[{"batb":[[0,1.4,8.51]],"ltp":1.4,"tv":1019.05,"id":2249229},{"batl":[[0,3.45,8.4]],"ltp":0.0,"tv":0.0,"id":5720747}]}]}
{"op":"mcm","clk":"1000383080","pt":1580580595124,"mc":[{"id":"1.168135786","rc":[{"batb":[[0,1.4,852.27]],"ltp":1.4,"tv":1019.05,"id":2249229}]}]}
{"op":"mcm","clk":"1000392670","pt":1580580655536,"mc":[{"id":"1.168135786","rc":[{"batl":[[0,3.45,8.4]],"ltp":0.0,"tv":0.0,"id":5720747}]}]}
{"op":"mcm","clk":"1000392722","pt":1580580655850,"mc":[{"id":"1.168135786","rc":[{"batb":[[0,1.4,8.51]],"ltp":1.4,"tv":1019.05,"id":2249229}]}]}
{"op":"mcm","clk":"1000392954","pt":1580580657266,"mc":[{"id":"1.168135786","rc":[{"batb":[[0,1.4,852.27]],"ltp":1.4,"tv":1019.05,"id":2249229},{"batl":[[0,3.55,8.4]],"ltp":0.0,"tv":0.0,"id":5720747}]}]}
{"op":"mcm","clk":"1000401553","pt":1580580715733,"mc":[{"id":"1.168135786","rc":[{"batl":[[0,3.45,8.4]],"ltp":0.0,"tv":0.0,"id":5720747}]}]}
{"op":"mcm","clk":"1000401579","pt":1580580715896,"mc":[{"id":"1.168135786","rc":[{"batb":[[0,1.4,8.51]],"ltp":1.4,"tv":1019.05,"id":2249229}]}]}
{"op":"mcm","clk":"1000401811","pt":1580580717405,"mc":[{"id":"1.168135786","rc":[{"batb":[[0,1.4,852.27]],"ltp":1.4,"tv":1019.05,"id":2249229}]}]}
{"op":"mcm","clk":"1000410889","pt":1580580777547,"mc":[{"id":"1.168135786","rc":[{"batl":[[0,3.45,8.4]],"ltp":0.0,"tv":0.0,"id":5720747}]}]}
{"op":"mcm","clk":"1000410957","pt":1580580777982,"mc":[{"id":"1.168135786","rc":[{"batb":[[0,1.4,8.51]],"ltp":1.4,"tv":1019.05,"id":2249229}]}]}
{"op":"mcm","clk":"1000411150","pt":1580580779224,"mc":[{"id":"1.168135786","rc":[{"batb":[[0,1.4,852.27]],"ltp":1.4,"tv":1019.05,"id":2249229},{"batl":[[0,3.55,8.4]],"ltp":0.0,"tv":0.0,"id":5720747}]}]}
{"op":"mcm","clk":"1000420293","pt":1580580838724,"mc":[{"id":"1.168135786","rc":[{"batl":[[0,3.45,8.4]],"ltp":0.0,"tv":0.0,"id":5720747}]}]}
{"op":"mcm","clk":"1000420338","pt":1580580839042,"mc":[{"id":"1.168135786","rc":[{"batb":[[0,1.4,8.51]],"ltp":1.4,"tv":1019.05,"id":2249229}]}]}
{"op":"mcm","clk":"1000420626","pt":1580580840731,"mc":[{"id":"1.168135786","rc":[{"batb":[[0,1.4,852.27]],"ltp":1.4,"tv":1019.05,"id":2249229},{"batl":[[0,3.55,8.4]],"ltp":0.0,"tv":0.0,"id":5720747}]}]}
{"op":"mcm","clk":"1000430164","pt":1580580900647,"mc":[{"id":"1.168135786","rc":[{"batb":[[0,1.4,8.51]],"ltp":1.4,"tv":1019.05,"id":2249229},{"batl":[[0,3.45,8.4]],"ltp":0.0,"tv":0.0,"id":5720747}]}]}
{"op":"mcm","clk":"1000430483","pt":1580580902341,"mc":[{"id":"1.168135786","rc":[{"batb":[[0,1.4,852.27]],"ltp":1.4,"tv":1019.05,"id":2249229},{"batl":[[0,3.55,8.4]],"ltp":0.0,"tv":0.0,"id":5720747}]}]}
{"op":"mcm","clk":"1000439767","pt":1580580963279,"mc":[{"id":"1.168135786","rc":[{"batb":[[0,1.4,8.51]],"ltp":1.4,"tv":1019.05,"id":2249229},{"batl":[[0,3.45,8.4]],"ltp":0.0,"tv":0.0,"id":5720747}]}]}
{"op":"mcm","clk":"1000440153","pt":1580580965961,"mc":[{"id":"1.168135786","rc":[{"batb":[[0,1.4,852.27]],"ltp":1.4,"tv":1019.05,"id":2249229},{"batl":[[0,3.55,8.4]],"ltp":0.0,"tv":0.0,"id":5720747}]}]}
{"op":"mcm","clk":"1000448288","pt":1580581025427,"mc":[{"id":"1.168135786","rc":[{"batb":[[0,1.4,8.51]],"ltp":1.4,"tv":1019.05,"id":2249229},{"batl":[[0,3.45,8.4]],"ltp":0.0,"tv":0.0,"id":5720747}]}]}
{"op":"mcm","clk":"1000448583","pt":1580581027729,"mc":[{"id":"1.168135786","rc":[{"batb":[[0,1.4,852.27]],"ltp":1.4,"tv":1019.05,"id":2249229}]}]}
{"op":"mcm","clk":"1000457045","pt":1580581087713,"mc":[{"id":"1.168135786","rc":[{"batl":[[0,3.45,8.4]],"ltp":0.0,"tv":0.0,"id":5720747}]}]}
{"op":"mcm","clk":"1000457101","pt":1580581088040,"mc":[{"id":"1.168135786","rc":[{"batb":[[0,1.4,8.51]],"ltp":1.4,"tv":1019.05,"id":2249229}]}]}
{"op":"mcm","clk":"1000457339","pt":1580581089733,"mc":[{"id":"1.168135786","rc":[{"batb":[[0,1.4,852.27]],"ltp":1.4,"tv":1019.05,"id":2249229},{"batl":[[0,3.55,8.4]],"ltp":0.0,"tv":0.0,"id":5720747}]}]}
{"op":"mcm","clk":"1000465430","pt":1580581148739,"mc":[{"id":"1.168135786","rc":[{"batl":[[0,3.45,8.4]],"ltp":0.0,"tv":0.0,"id":5720747}]}]}
{"op":"mcm","clk":"1000465527","pt":1580581149550,"mc":[{"id":"1.168135786","rc":[{"batb":[[0,1.4,8.51]],"ltp":1.4,"tv":1019.05,"id":2249229}]}]}
{"op":"mcm","clk":"1000465618","pt":1580581150243,"mc":[{"id":"1.168135786","rc":[{"batb":[[0,1.4,852.27]],"ltp":1.4,"tv":1019.05,"id":2249229}]}]}
{"op":"mcm","clk":"1000473474","pt":1580581208529,"mc":[{"id":"1.168135786","rc":[{"batl":[[0,3.45,8.4]],"ltp":0.0,"tv":0.0,"id":5720747}]}]}
{"op":"mcm","clk":"1000473511","pt":1580581208846,"mc":[{"id":"1.168135786","rc":[{"batb":[[0,1.4,8.51]],"ltp":1.4,"tv":1019.05,"id":2249229}]}]}
{"op":"mcm","clk":"1000473756","pt":1580581210472,"mc":[{"id":"1.168135786","rc":[{"batb":[[0,1.4,852.27]],"ltp":1.4,"tv":1019.05,"id":2249229},{"batl":[[0,3.55,8.4]],"ltp":0.0,"tv":0.0,"id":5720747}]}]}
{"op":"mcm","clk":"1000481439","pt":1580581268645,"mc":[{"id":"1.168135786","rc":[{"batl":[[0,3.45,8.4]],"ltp":0.0,"tv":0.0,"id":5720747}]}]}
{"op":"mcm","clk":"1000481540","pt":1580581268978,"mc":[{"id":"1.168135786","rc":[{"batb":[[0,1.4,8.51]],"ltp":1.4,"tv":1019.05,"id":2249229}]}]}
{"op":"mcm","clk":"1000481705","pt":1580581270285,"mc":[{"id":"1.168135786","rc":[{"batb":[[0,1.4,852.27]],"ltp":1.4,"tv":1019.05,"id":2249229},{"batl":[[0,3.55,8.4]],"ltp":0.0,"tv":0.0,"id":5720747}]}]}
{"op":"mcm","clk":"1000489190","pt":1580581327690,"mc":[{"id":"1.168135786","rc":[{"batb":[[0,1.4,8.51]],"ltp":1.4,"tv":1019.05,"id":2249229},{"batl":[[0,3.45,8.4]],"ltp":0.0,"tv":0.0,"id":5720747}]}]}
{"op":"mcm","clk":"1000489418","pt":1580581329244,"mc":[{"id":"1.168135786","rc":[{"batb":[[0,1.4,852.27]],"ltp":1.4,"tv":1019.05,"id":2249229},{"batl":[[0,3.55,8.4]],"ltp":0.0,"tv":0.0,"id":5720747}]}]}
{"op":"mcm","clk":"1000497747","pt":1580581387671,"mc":[{"id":"1.168135786","rc":[{"batl":[[0,3.45,8.4]],"ltp":0.0,"tv":0.0,"id":5720747}]}]}
{"op":"mcm","clk":"1000497794","pt":1580581387941,"mc":[{"id":"1.168135786","rc":[{"batb":[[0,1.4,8.51]],"ltp":1.4,"tv":1019.05,"id":2249229}]}]}
{"op":"mcm","clk":"1000498033","pt":1580581389548,"mc":[{"id":"1.168135786","rc":[{"batb":[[0,1.4,852.27]],"ltp":1.4,"tv":1019.05,"id":2249229}]}]}
{"op":"mcm","clk":"1000505666","pt":1580581446780,"mc":[{"id":"1.168135786","rc":[{"batl":[[0,3.45,8.4]],"ltp":0.0,"tv":0.0,"id":5720747}]}]}
{"op":"mcm","clk":"1000505703","pt":1580581447060,"mc":[{"id":"1.168135786","rc":[{"batb":[[0,1.4,8.51]],"ltp":1.4,"tv":1019.05,"id":2249229}]}]}
{"op":"mcm","clk":"1000505854","pt":1580581448082,"mc":[{"id":"1.168135786","rc":[{"batb":[[0,1.4,852.27]],"ltp":1.4,"tv":1019.05,"id":2249229},{"batl":[[0,3.55,8.4]],"ltp":0.0,"tv":0.0,"id":5720747}]}]}
{"op":"mcm","clk":"1000513237","pt":1580581505773,"mc":[{"id":"1.168135786","rc":[{"batb":[[0,1.4,8.51]],"ltp":1.4,"tv":1019.05,"id":2249229},{"batl":[[0,3.45,8.4]],"ltp":0.0,"tv":0.0,"id":5720747}]}]}
{"op":"mcm","clk":"1000513442","pt":1580581507207,"mc":[{"id":"1.168135786","rc":[{"batb":[[0,1.4,852.27]],"ltp":1.4,"tv":1019.05,"id":2249229},{"batl":[[0,3.55,8.4]],"ltp":0.0,"tv":0.0,"id":5720747}]}]}
{"op":"mcm","clk":"1000520526","pt":1580581564770,"mc":[{"id":"1.168135786","rc":[{"batb":[[0,1.4,8.51]],"ltp":1.4,"tv":1019.05,"id":2249229},{"batl":[[0,3.45,8.4]],"ltp":0.0,"tv":0.0,"id":5720747}]}]}
{"op":"mcm","clk":"1000520806","pt":1580581566766,"mc":[{"id":"1.168135786","rc":[{"batl":[[0,3.55,8.4]],"ltp":0.0,"tv":0.0,"id":5720747}]}]}
{"op":"mcm","clk":"1000520840","pt":1580581567079,"mc":[{"id":"1.168135786","rc":[{"batb":[[0,1.4,852.27]],"ltp":1.4,"tv":1019.05,"id":2249229}]}]}
{"op":"mcm","clk":"1000528136","pt":1580581623553,"mc":[{"id":"1.168135786","rc":[{"batl":[[0,3.45,8.4]],"ltp":0.0,"tv":0.0,"id":5720747}]}]}
{"op":"mcm","clk":"1000528186","pt":1580581623870,"mc":[{"id":"1.168135786","rc":[{"batb":[[0,1.4,8.51]],"ltp":1.4,"tv":1019.05,"id":2249229}]}]}
{"op":"mcm","clk":"1000528354","pt":1580581625158,"mc":[{"id":"1.168135786","rc":[{"batb":[[0,1.4,852.27]],"ltp":1.4,"tv":1019.05,"id":2249229}]}]}
{"op":"mcm","clk":"1000536553","pt":1580581682564,"mc":[{"id":"1.168135786","rc":[{"batb":[[0,1.4,8.51]],"ltp":1.4,"tv":1019.05,"id":2249229},{"batl":[[0,3.45,8.4]],"ltp":0.0,"tv":0.0,"id":5720747}]}]}
{"op":"mcm","clk":"1000536692","pt":1580581683773,"mc":[{"id":"1.168135786","rc":[{"batl":[[0,3.55,8.4]],"ltp":0.0,"tv":0.0,"id":5720747}]}]}
{"op":"mcm","clk":"1000536712","pt":1580581683904,"mc":[{"id":"1.168135786","rc":[{"batb":[[0,1.4,852.27]],"ltp":1.4,"tv":1019.05,"id":2249229}]}]}
{"op":"mcm","clk":"1000544421","pt":1580581742306,"mc":[{"id":"1.168135786","rc":[{"batb":[[0,1.4,8.51]],"ltp":1.4,"tv":1019.05,"id":2249229},{"batl":[[0,3.45,8.4]],"ltp":0.0,"tv":0.0,"id":5720747}]}]}
{"op":"mcm","clk":"1000544657","pt":1580581743692,"mc":[{"id":"1.168135786","rc":[{"batb":[[0,1.4,852.27]],"ltp":1.4,"tv":1019.05,"id":2249229},{"batl":[[0,3.55,8.4]],"ltp":0.0,"tv":0.0,"id":5720747}]}]}
{"op":"mcm","clk":"1000554226","pt":1580581807715,"mc":[{"id":"1.168135786","rc":[{"batb":[[0,1.4,8.51]],"ltp":1.4,"tv":1019.05,"id":2249229},{"batl":[[0,3.45,8.4]],"ltp":0.0,"tv":0.0,"id":5720747}]}]}
{"op":"mcm","clk":"1000554617","pt":1580581809799,"mc":[{"id":"1.168135786","rc":[{"batb":[[0,1.4,852.27]],"ltp":1.4,"tv":1019.05,"id":2249229},{"batl":[[0,3.55,8.4]],"ltp":0.0,"tv":0.0,"id":5720747}]}]}
{"op":"mcm","clk":"1000564147","pt":1580581873289,"mc":[{"id":"1.168135786","rc":[{"batb":[[0,1.4,8.51]],"ltp":1.4,"tv":1019.05,"id":2249229},{"batl":[[0,3.45,8.4]],"ltp":0.0,"tv":0.0,"id":5720747}]}]}
{"op":"mcm","clk":"1000564369","pt":1580581874865,"mc":[{"id":"1.168135786","rc":[{"batb":[[0,1.4,852.27]],"ltp":1.4,"tv":1019.05,"id":2249229}]}]}
{"op":"mcm","clk":"1000574421","pt":1580581940678,"mc":[{"id":"1.168135786","rc":[{"batl":[[0,3.45,8.4]],"ltp":0.0,"tv":0.0,"id":5720747}]}]}
{"op":"mcm","clk":"1000574521","pt":1580581941273,"mc":[{"id":"1.168135786","rc":[{"batb":[[0,1.4,8.51]],"ltp":1.4,"tv":1019.05,"id":2249229}]}]}
{"op":"mcm","clk":"1000574748","pt":1580581942685,"mc":[{"id":"1.168135786","rc":[{"batl":[[0,3.55,8.4]],"ltp":0.0,"tv":0.0,"id":5720747}]}]}
{"op":"mcm","clk":"1000574794","pt":1580581942908,"mc":[{"id":"1.168135786","rc":[{"batb":[[0,1.4,852.27]],"ltp":1.4,"tv":1019.05,"id":2249229}]}]}
{"op":"mcm","clk":"1000586217","pt":1580582011489,"mc":[{"id":"1.168135786","rc":[{"batb":[[0,1.4,8.51]],"ltp":1.4,"tv":1019.05,"id":2249229},{"batl":[[0,3.45,8.4]],"ltp":0.0,"tv":0.0,"id":5720747}]}]}
{"op":"mcm","clk":"1000586455","pt":1580582012996,"mc":[{"id":"1.168135786","rc":[{"batb":[[0,1.4,852.27]],"ltp":1.4,"tv":1019.05,"id":2249229}]}]}
{"op":"mcm","clk":"1000598833","pt":1580582083798,"mc":[{"id":"1.168135786","rc":[{"batb":[[0,1.4,8.51]],"ltp":1.4,"tv":1019.05,"id":2249229},{"batl":[[0,3.45,8.4]],"ltp":0.0,"tv":0.0,"id":5720747}]}]}
{"op":"mcm","clk":"1000599071","pt":1580582085241,"mc":[{"id":"1.168135786","rc":[{"batb":[[0,1.4,852.27]],"ltp":1.4,"tv":1019.05,"id":2249229},{"batl":[[0,3.55,8.4]],"ltp":0.0,"tv":0.0,"id":5720747}]}]}
{"op":"mcm","clk":"1000611332","pt":1580582156664,"mc":[{"id":"1.168135786","rc":[{"batb":[[0,1.4,8.51]],"ltp":1.4,"tv":1019.05,"id":2249229},{"batl":[[0,3.45,8.4]],"ltp":0.0,"tv":0.0,"id":5720747}]}]}
{"op":"mcm","clk":"1000611522","pt":1580582157773,"mc":[{"id":"1.168135786","rc":[{"batl":[[0,3.55,8.4]],"ltp":0.0,"tv":0.0,"id":5720747}]}]}
{"op":"mcm","clk":"1000611550","pt":1580582157953,"mc":[{"id":"1.168135786","rc":[{"batb":[[0,1.4,852.27]],"ltp":1.4,"tv":1019.05,"id":2249229}]}]}
{"op":"mcm","clk":"1000621877","pt":1580582227650,"mc":[{"id":"1.168135786","rc":[{"batb":[[0,1.4,8.51]],"ltp":1.4,"tv":1019.05,"id":2249229},{"batl":[[0,3.45,8.4]],"ltp":0.0,"tv":0.0,"id":5720747}]}]}
{"op":"mcm","clk":"1000622059","pt":1580582228857,"mc":[{"id":"1.168135786","rc":[{"batb":[[0,1.4,852.27]],"ltp":1.4,"tv":1019.05,"id":2249229}]}]}
{"op":"mcm","clk":"1000633515","pt":1580582299813,"mc":[{"id":"1.168135786","rc":[{"batl":[[0,3.45,8.4]],"ltp":0.0,"tv":0.0,"id":5720747}]}]}
{"op":"mcm","clk":"1000633569","pt":1580582300103,"mc":[{"id":"1.168135786","rc":[{"batb":[[0,1.4,8.51]],"ltp":1.4,"tv":1019.05,"id":2249229}]}]}
{"op":"mcm","clk":"1000633870","pt":1580582301815,"mc":[{"id":"1.168135786","rc":[{"batb":[[0,1.4,852.27]],"ltp":1.4,"tv":1019.05,"id":2249229},{"batl":[[0,3.55,8.4]],"ltp":0.0,"tv":0.0,"id":5720747}]}]}
{"op":"mcm","clk":"1000647468","pt":1580582373667,"mc":[{"id":"1.168135786","rc":[{"batl":[[0,3.45,8.4]],"ltp":0.0,"tv":0.0,"id":5720747}]}]}
{"op":"mcm","clk":"1000647512","pt":1580582373938,"mc":[{"id":"1.168135786","rc":[{"batb":[[0,1.4,8.51]],"ltp":1.4,"tv":1019.05,"id":2249229}]}]}
{"op":"mcm","clk":"1000647759","pt":1580582375472,"mc":[{"id":"1.168135786","rc":[{"batb":[[0,1.4,852.27]],"ltp":1.4,"tv":1019.05,"id":2249229},{"batl":[[0,3.55,8.4]],"ltp":0.0,"tv":0.0,"id":5720747}]}]}
{"op":"mcm","clk":"1000660450","pt":1580582449748,"mc":[{"id":"1.168135786","rc":[{"batb":[[0,1.4,8.51]],"ltp":1.4,"tv":1019.05,"id":2249229},{"batl":[[0,3.45,8.4]],"ltp":0.0,"tv":0.0,"id":5720747}]}]}
{"op":"mcm","clk":"1000660635","pt":1580582450759,"mc":[{"id":"1.168135786","rc":[{"batl":[[0,3.55,8.4]],"ltp":0.0,"tv":0.0,"id":5720747}]}]}
{"op":"mcm","clk":"1000660692","pt":1580582451087,"mc":[{"id":"1.168135786","rc":[{"batb":[[0,1.4,852.27]],"ltp":1.4,"tv":1019.05,"id":2249229}]}]}
{"op":"mcm","clk":"1000672633","pt":1580582524354,"mc":[{"id":"1.168135786","rc":[{"batb":[[0,1.4,8.51]],"ltp":1.4,"tv":1019.05,"id":2249229},{"batl":[[0,3.45,8.4]],"ltp":0.0,"tv":0.0,"id":5720747}]}]}
{"op":"mcm","clk":"1000673030","pt":1580582526639,"mc":[{"id":"1.168135786","rc":[{"batb":[[0,1.4,852.27]],"ltp":1.4,"tv":1019.05,"id":2249229},{"batl":[[0,3.55,8.4]],"ltp":0.0,"tv":0.0,"id":5720747}]}]}
{"op":"mcm","clk":"1000685128","pt":1580582597740,"mc":[{"id":"1.168135786","rc":[{"batl":[[0,3.45,8.4]],"ltp":0.0,"tv":0.0,"id":5720747}]}]}
{"op":"mcm","clk":"1000685240","pt":1580582598365,"mc":[{"id":"1.168135786","rc":[{"batb":[[0,1.4,8.51]],"ltp":1.4,"tv":1019.05,"id":2249229}]}]}
{"op":"mcm","clk":"1000685411","pt":1580582599443,"mc":[{"id":"1.168135786","rc":[{"batb":[[0,1.4,852.27]],"ltp":1.4,"tv":1019.05,"id":2249229}]}]}
{"op":"mcm","clk":"1000694342","pt":1580582651538,"mc":[{"id":"1.168135786","rc":[{"batb":[[0,1.41,363],[1,1.4,852.27],[2,1.39,2000]],"batl":[[0,1.46,358.67]],"ltp":1.4,"tv":1019.05,"id":2249229}]}]}
{"op":"mcm","clk":"1000694544","pt":1580582652735,"mc":[{"id":"1.168135786","rc":[{"batb":[[1,1.39,2000],[2,1.37,179.28]],"ltp":1.4,"tv":1019.05,"id":2249229}]}]}
{"op":"mcm","clk":"1000694577","pt":1580582652943,"mc":[{"id":"1.168135786","rc":[{"batb":[[0,1.42,24.87],[1,1.41,363],[2,1.39,2000]],"ltp":1.4,"tv":1019.05,"id":2249229},{"batl":[[0,3.4,8.4]],"ltp":0.0,"tv":0.0,"id":5720747}]}]}
{"op":"mcm","clk":"1000696006","pt":1580582661235,"mc":[{"id":"1.168135786","rc":[{"batb":[[0,3.3,7.27],[1,2.88,65.7],[2,2.86,35.67]],"ltp":0.0,"tv":0.0,"id":5720747}]}]}
{"op":"mcm","clk":"1000700518","pt":1580582688536,"mc":[{"id":"1.168135786","rc":[{"batb":[[0,2.88,65.7],[1,2.86,35.67],[2,1.02,2780.76]],"ltp":0.0,"tv":0.0,"id":5720747}]}]}
{"op":"mcm","clk":"1000706310","pt":1580582719964,"mc":[{"id":"1.168135786","rc":[{"trd":[[3.4,14.23]],"batl":[[0,3.4,1.29]],"ltp":3.4,"tv":14.23,"id":5720747}],"tv":1033.29}]}
{"op":"mcm","clk":"1000960875","pt":1580584154680,"mc":[{"id":"1.168135786","rc":[{"batb":[[0,1.43,14],[1,1.42,24.87],[2,1.41,363]],"ltp":1.4,"tv":1019.05,"id":2249229}]}]}
{"op":"mcm","clk":"1000996116","pt":1580584322802,"mc":[{"id":"1.168135786","rc":[{"trd":[[1.46,16.97]],"batl":[[0,1.46,341.7]],"ltp":1.46,"tv":1036.02,"id":2249229},{"trd":[[3.15,7.87]],"ltp":3.15,"tv":22.1,"id":5720747}],"tv":1058.12}]}
{"op":"mcm","clk":"1000996353","pt":1580584323994,"mc":[{"id":"1.168135786","rc":[{"batb":[[1,1.42,34.86]],"ltp":1.46,"tv":1036.02,"id":2249229}]}]}
{"op":"mcm","clk":"1001563118","pt":1580587432827,"mc":[{"id":"1.168135786","rc":[{"batl":[[1,2,10],[2,2,0]],"ltp":1.46,"tv":1036.02,"id":2249229}]}]}
{"op":"mcm","clk":"1001999536","pt":1580589814480,"mc":[{"id":"1.168135786","rc":[{"batb":[[0,3.2,15],[1,2.88,65.7],[2,2.86,35.67]],"ltp":3.15,"tv":22.1,"id":5720747}]}]}
{"op":"mcm","clk":"1002086036","pt":1580590375340,"mc":[{"id":"1.168135786","rc":[{"batb":[[0,3.2,25]],"ltp":3.15,"tv":22.1,"id":5720747}]}]}
{"op":"mcm","clk":"1002091365","pt":1580590419591,"mc":[{"id":"1.168135786","rc":[{"batb":[[0,3.25,10],[1,3.2,15],[2,2.88,65.7]],"ltp":3.15,"tv":22.1,"id":5720747}]}]}
{"op":"mcm","clk":"1002091879","pt":1580590423713,"mc":[{"id":"1.168135786","rc":[{"batb":[[2,2.88,50]],"ltp":3.15,"tv":22.1,"id":5720747}]}]}
{"op":"mcm","clk":"1002094504","pt":1580590445611,"mc":[{"id":"1.168135786","rc":[{"batb":[[0,3.3,10]],"ltp":3.15,"tv":22.1,"id":5720747}]}]}
{"op":"mcm","clk":"1002115851","pt":1580590632157,"mc":[{"id":"1.168135786","rc":[{"trd":[[3.3,5]],"batb":[[0,3.3,7.5]],"ltp":3.3,"tv":27.1,"id":5720747}],"tv":1063.12}]}
{"op":"mcm","clk":"1002116052","pt":1580590634257,"mc":[{"id":"1.168135786","rc":[{"batb":[[2,2.88,65.7]],"ltp":3.3,"tv":27.1,"id":5720747}]}]}
{"op":"mcm","clk":"1002148458","pt":1580590927304,"mc":[{"id":"1.168135786","rc":[{"trd":[[3.3,20]],"batb":[[0,3.2,15],[1,2.88,65.7],[2,2.86,35.67]],"ltp":3.3,"tv":42.1,"id":5720747}],"tv":1078.13}]}
{"op":"mcm","clk":"1002148973","pt":1580590931638,"mc":[{"id":"1.168135786","rc":[{"batl":[[0,3.3,15.14],[1,3.4,1.29]],"ltp":3.3,"tv":42.1,"id":5720747}]}]}
{"op":"mcm","clk":"1002213853","pt":1580591478530,"mc":[{"id":"1.168135786","rc":[{"batl":[[0,3.4,1.29],[1,3.4,0]],"ltp":3.3,"tv":42.1,"id":5720747}]}]}
{"op":"mcm","clk":"1002218781","pt":1580591526755,"mc":[{"id":"1.168135786","rc":[{"trd":[[3.2,10]],"batb":[[0,3.2,10]],"ltp":3.2,"tv":52.1,"id":5720747}],"tv":1088.13}]}
{"op":"mcm","clk":"1002444984","pt":1580593774668,"mc":[{"id":"1.168135786","rc":[{"batb":[[1,1.42,9.99]],"ltp":1.46,"tv":1036.02,"id":2249229},{"batl":[[0,3.25,12.66]],"ltp":3.2,"tv":52.1,"id":5720747}]}]}
{"op":"mcm","clk":"1002444994","pt":1580593774876,"mc":[{"id":"1.168135786","rc":[{"trd":[[3.25,24.03]],"batl":[[0,3.25,0.65]],"ltp":3.25,"tv":76.13,"id":5720747}],"tv":1112.16}]}
{"op":"mcm","clk":"1002445084","pt":1580593776482,"mc":[{"id":"1.168135786","rc":[{"batb":[[1,1.42,20.23]],"ltp":1.46,"tv":1036.02,"id":2249229},{"batb":[[0,3.2,17.56]],"ltp":3.25,"tv":76.13,"id":5720747}]}]}
{"op":"mcm","clk":"1002446459","pt":1580593796601,"mc":[{"id":"1.168135786","rc":[{"trd":[[3.2,11.3]],"batb":[[0,3.2,16.91]],"ltp":3.2,"tv":77.44,"id":5720747}],"tv":1113.46}]}
{"op":"mcm","clk":"1002449252","pt":1580593834484,"mc":[{"id":"1.168135786","rc":[{"batb":[[0,1.44,53],[1,1.43,14],[2,1.42,20.23]],"ltp":1.46,"tv":1036.02,"id":2249229}]}]}
{"op":"mcm","clk":"1002449317","pt":1580593835349,"mc":[{"id":"1.168135786","rc":[{"batb":[[2,1.42,10.24]],"ltp":1.46,"tv":1036.02,"id":2249229},{"batb":[[1,2.88,50]],"ltp":3.2,"tv":77.44,"id":5720747}]}]}
{"op":"mcm","clk":"1002499064","pt":1580594498109,"mc":[{"id":"1.168135786","rc":[{"trd":[[3.2,45.11]],"batb":[[0,2.88,50],[1,2.86,35.67],[2,1.02,2780.76]],"batl":[[0,3.2,8.43]],"ltp":3.2,"tv":111.24,"id":5720747}],"tv":1147.27}]}
{"op":"mcm","clk":"1002499141","pt":1580594499231,"mc":[{"id":"1.168135786","rc":[{"batb":[[0,1.44,61.79],[2,1.41,363]],"ltp":1.46,"tv":1036.02,"id":2249229}]}]}
{"op":"mcm","clk":"1002499333","pt":1580594502115,"mc":[{"id":"1.168135786","rc":[{"batb":[[0,2.88,65.7]],"ltp":3.2,"tv":111.24,"id":5720747}]}]}
{"op":"mcm","clk":"1002516756","pt":1580594769380,"mc":[{"id":"1.168135786","rc":[{"batb":[[0,1.44,8.79]],"ltp":1.46,"tv":1036.02,"id":2249229}]}]}
{"op":"mcm","clk":"1002516825","pt":1580594770269,"mc":[{"id":"1.168135786","rc":[{"batb":[[0,1.43,14],[1,1.41,363],[2,1.39,2000]],"ltp":1.46,"tv":1036.02,"id":2249229}]}]}
{"op":"mcm","clk":"1002517786","pt":1580594786089,"mc":[{"id":"1.168135786","rc":[{"trd":[[1.46,122.17]],"batl":[[0,1.46,289.1]],"ltp":1.46,"tv":1141.22,"id":2249229}],"tv":1252.47}]}
{"op":"mcm","clk":"1002522246","pt":1580594857781,"mc":[{"id":"1.168135786","rc":[{"trd":[[1.46,411.27]],"batl":[[0,2,10],[1,2,0]],"ltp":1.46,"tv":1430.32,"id":2249229},{"trd":[[3.15,141.87]],"ltp":3.15,"tv":245.24,"id":5720747}],"tv":1675.57}]}
{"op":"mcm","clk":"1002522269","pt":1580594858194,"mc":[{"id":"1.168135786","rc":[{"trd":[[3.2,61.11]],"batb":[[0,2.9,525.36],[1,2.88,65.7],[2,2.86,35.67]],"batl":[[0,3.2,0.44]],"ltp":3.2,"tv":261.25,"id":5720747}],"tv":1691.57}]}
{"op":"mcm","clk":"1002522337","pt":1580594859505,"mc":[{"id":"1.168135786","rc":[{"batb":[[1,1.42,18.95],[2,1.41,363]],"ltp":1.46,"tv":1430.32,"id":2249229},{"batl":[[0,3.4,8.84]],"ltp":3.2,"tv":261.25,"id":5720747}]}]}
{"op":"mcm","clk":"1002522548","pt":1580594863263,"mc":[{"id":"1.168135786","rc":[{"batb":[[1,2.88,50]],"ltp":3.2,"tv":261.25,"id":5720747}]}]}
{"op":"mcm","clk":"1002547532","pt":1580595189134,"mc":[{"id":"1.168135786","rc":[{"batb":[[0,1.44,67.1],[1,1.43,14],[2,1.42,18.95]],"ltp":1.46,"tv":1430.32,"id":2249229}]}]}
{"op":"mcm","clk":"1002554729","pt":1580595274447,"mc":[{"id":"1.168135786","rc":[{"batb":[[0,1.43,14],[1,1.42,18.95],[2,1.41,363]],"ltp":1.46,"tv":1430.32,"id":2249229}]}]}
{"op":"mcm","clk":"1002602700","pt":1580595929813,"mc":[{"id":"1.168135786","rc":[{"batb":[[0,2.94,518.09],[1,2.92,3.26],[2,2.88,50]],"ltp":3.2,"tv":261.25,"id":5720747}]}]}
{"op":"mcm","clk":"1002602714","pt":1580595930021,"mc":[{"id":"1.168135786","rc":[{"batb":[[1,1.42,25.1]],"ltp":1.46,"tv":1430.32,"id":2249229}]}]}
{"op":"mcm","clk":"1002727389","pt":1580597902774,"mc":[{"id":"1.168135786","rc":[{"batb":[[0,1.44,1082.92],[1,1.43,14],[2,1.42,25.1]],"ltp":1.46,"tv":1430.32,"id":2249229},{"batb":[[0,2.92,3.26],[1,2.88,50],[2,2.86,35.67]],"ltp":3.2,"tv":261.25,"id":5720747}]}]}
{"op":"mcm","clk":"1002727467","pt":1580597903798,"mc":[{"id":"1.168135786","rc":[{"batb":[[0,1.45,20.34],[2,1.42,6.15]],"ltp":1.46,"tv":1430.32,"id":2249229},{"batb":[[0,2.98,187.76],[1,2.92,3.26],[2,2.88,50]],"batl":[[0,3.25,8.84]],"ltp":3.2,"tv":261.25,"id":5720747}]}]}
{"op":"mcm","clk":"1002727487","pt":1580597904056,"mc":[{"id":"1.168135786","rc":[{"batb":[[2,1.42,186.45]],"ltp":1.46,"tv":1430.32,"id":2249229}]}]}
{"op":"mcm","clk":"1002727617","pt":1580597905970,"mc":[{"id":"1.168135786","rc":[{"batb":[[0,1.43,14],[1,1.42,186.45],[2,1.41,363]],"ltp":1.46,"tv":1430.32,"id":2249229},{"batl":[[0,3.2,0.44]],"ltp":3.2,"tv":261.25,"id":5720747}]}]}
{"op":"mcm","clk":"1002728230","pt":1580597916267,"mc":[{"id":"1.168135786","rc":[{"batb":[[0,1.43,37.33]],"ltp":1.46,"tv":1430.32,"id":2249229}]}]}
{"op":"mcm","clk":"1002732460","pt":1580597981435,"mc":[{"id":"1.168135786","rc":[{"batb":[[1,2.88,50],[2,2.74,16.96]],"ltp":3.2,"tv":261.25,"id":5720747}]}]}
{"op":"mcm","clk":"1002732549","pt":1580597982740,"mc":[{"id":"1.168135786","rc":[{"batb":[[1,1.42,180.3]],"ltp":1.46,"tv":1430.32,"id":2249229}]}]}
{"op":"mcm","clk":"1002761042","pt":1580598405767,"mc":[{"id":"1.168135786","rc":[{"batl":[[0,3.2,482.87]],"ltp":3.2,"tv":261.25,"id":5720747}]}]}
{"op":"mcm","clk":"1002761183","pt":1580598407784,"mc":[{"id":"1.168135786","rc":[{"batb":[[0,1.46,17.84],[1,1.43,14],[2,1.42,180.3]],"ltp":1.46,"tv":1430.32,"id":2249229},{"batl":[[0,3.15,8.4],[1,3.2,482.87]],"ltp":3.2,"tv":261.25,"id":5720747}]}]}
{"op":"mcm","clk":"1002761219","pt":1580598408303,"mc":[{"id":"1.168135786","rc":[{"batb":[[2,1.41,363]],"ltp":1.46,"tv":1430.32,"id":2249229},{"batl":[[1,3.2,0.44]],"ltp":3.2,"tv":261.25,"id":5720747}]}]}
{"op":"mcm","clk":"1002761295","pt":1580598409493,"mc":[{"id":"1.168135786","rc":[{"batb":[[0,1.43,190.1],[1,1.41,363],[2,1.4,73.81]],"ltp":1.46,"tv":1430.32,"id":2249229},{"batl":[[0,3.2,482.87],[1,3.2,0]],"ltp":3.2,"tv":261.25,"id":5720747}]}]}
{"op":"mcm","clk":"1002765411","pt":1580598465556,"mc":[{"id":"1.168135786","rc":[{"batb":[[0,1.46,19.08],[1,1.43,190.1],[2,1.41,363]],"ltp":1.46,"tv":1430.32,"id":2249229},{"batl":[[0,3.15,8.4],[1,3.2,0.44]],"ltp":3.2,"tv":261.25,"id":5720747}]}]}
{"op":"mcm","clk":"1002765515","pt":1580598467163,"mc":[{"id":"1.168135786","rc":[{"batb":[[0,1.44,8.79]],"ltp":1.46,"tv":1430.32,"id":2249229},{"batl":[[0,3.2,482.87],[1,3.2,0]],"ltp":3.2,"tv":261.25,"id":5720747}]}]}
{"op":"mcm","clk":"1002765621","pt":1580598468779,"mc":[{"id":"1.168135786","rc":[{"batb":[[0,1.43,190.1],[1,1.41,363],[2,1.4,73.81]],"ltp":1.46,"tv":1430.32,"id":2249229}]}]}
{"op":"mcm","clk":"1002769770","pt":1580598524433,"mc":[{"id":"1.168135786","rc":[{"batb":[[0,1.46,17.67],[1,1.43,190.1],[2,1.41,363]],"ltp":1.46,"tv":1430.32,"id":2249229},{"batl":[[0,3.15,8.4],[1,3.2,0.44]],"ltp":3.2,"tv":261.25,"id":5720747}]}]}
{"op":"mcm","clk":"1002769905","pt":1580598526213,"mc":[{"id":"1.168135786","rc":[{"batb":[[0,1.43,190.1],[1,1.41,363],[2,1.4,73.81]],"ltp":1.46,"tv":1430.32,"id":2249229},{"batl":[[0,3.2,482.87],[1,3.2,0]],"ltp":3.2,"tv":261.25,"id":5720747}]}]}
{"op":"mcm","clk":"1002773789","pt":1580598581775,"mc":[{"id":"1.168135786","rc":[{"batb":[[0,1.46,17.27],[1,1.43,190.1],[2,1.41,363]],"ltp":1.46,"tv":1430.32,"id":2249229},{"batl":[[0,3.15,8.4],[1,3.2,0.44]],"ltp":3.2,"tv":261.25,"id":5720747}]}]}
{"op":"mcm","clk":"1002773909","pt":1580598583519,"mc":[{"id":"1.168135786","rc":[{"batb":[[0,1.44,8.79]],"ltp":1.46,"tv":1430.32,"id":2249229},{"batl":[[0,3.2,482.87],[1,3.2,0]],"ltp":3.2,"tv":261.25,"id":5720747}]}]}
{"op":"mcm","clk":"1002774008","pt":1580598585120,"mc":[{"id":"1.168135786","rc":[{"batb":[[0,1.43,190.1],[1,1.41,363],[2,1.4,73.81]],"ltp":1.46,"tv":1430.32,"id":2249229}]}]}
{"op":"mcm","clk":"1002776089","pt":1580598614327,"mc":[{"id":"1.168135786","rc":[{"trd":[[3.2,97.24]],"ltp":3.2,"tv":297.37,"id":5720747}],"tv":1727.7}]}
{"op":"mcm","clk":"1002776194","pt":1580598615641,"mc":[{"id":"1.168135786","rc":[{"batb":[[0,1.44,9.86],[1,1.43,190.1],[2,1.41,363]],"ltp":1.46,"tv":1430.32,"id":2249229},{"batl":[[0,3.4,8.4]],"ltp":3.2,"tv":297.37,"id":5720747}]}]}
{"op":"mcm","clk":"1002776219","pt":1580598616056,"mc":[{"id":"1.168135786","rc":[{"batb":[[0,1.45,1065.01],[1,1.44,9.86],[2,1.43,190.1]],"ltp":1.46,"tv":1430.32,"id":2249229}]}]}
{"op":"mcm","clk":"1002776290","pt":1580598617047,"mc":[{"id":"1.168135786","rc":[{"batb":[[1,1.43,190.1],[2,1.41,363]],"ltp":1.46,"tv":1430.32,"id":2249229}]}]}
{"op":"mcm","clk":"1002776672","pt":1580598622625,"mc":[{"id":"1.168135786","rc":[{"batb":[[0,1.43,190.1],[1,1.41,363],[2,1.39,2000]],"ltp":1.46,"tv":1430.32,"id":2249229},{"trd":[[3.2,106.39]],"batb":[[0,2.88,50],[1,2.74,16.96],[2,2.68,45.07]],"batl":[[0,3.2,4.09]],"ltp":3.2,"tv":306.52,"id":5720747}],"tv":1736.85}]}
{"op":"mcm","clk":"1002776796","pt":1580598624749,"mc":[{"id":"1.168135786","rc":[{"batb":[[2,1.4,73.81]],"ltp":1.46,"tv":1430.32,"id":2249229}]}]}
{"op":"mcm","clk":"1002776851","pt":1580598625580,"mc":[{"id":"1.168135786","rc":[{"batb":[[0,2.92,191.44],[1,2.88,50],[2,2.74,16.96]],"ltp":3.2,"tv":306.52,"id":5720747}]}]}
{"op":"mcm","clk":"1002777743","pt":1580598638150,"mc":[{"id":"1.168135786","rc":[{"batb":[[0,1.44,1072.67],[1,1.43,190.1],[2,1.41,363]],"ltp":1.46,"tv":1430.32,"id":2249229}]}]}
{"op":"mcm","clk":"1002777784","pt":1580598638871,"mc":[{"id":"1.168135786","rc":[{"batb":[[0,1.45,33.17],[1,1.44,1072.67],[2,1.43,190.1]],"ltp":1.46,"tv":1430.32,"id":2249229},{"batl":[[0,3.25,8.4]],"ltp":3.2,"tv":306.52,"id":5720747}]}]}
{"op":"mcm","clk":"1002800341","pt":1580598930802,"mc":[{"id":"1.168135786","rc":[{"batb":[[0,2.92,27.44]],"ltp":3.2,"tv":306.52,"id":5720747}]}]}
{"op":"mcm","clk":"1002800397","pt":1580598931534,"mc":[{"id":"1.168135786","rc":[{"batb":[[0,2.92,146.94]],"ltp":3.2,"tv":306.52,"id":5720747}]}]}
{"op":"mcm","clk":"1002822084","pt":1580599235338,"mc":[{"id":"1.168135786","rc":[{"batb":[[0,2.88,50],[1,2.74,16.96],[2,2.68,45.07]],"ltp":3.2,"tv":306.52,"id":5720747}]}]}
{"op":"mcm","clk":"1002823114","pt":1580599249262,"mc":[{"id":"1.168135786","rc":[{"batb":[[0,2.96,144.88],[1,2.88,50],[2,2.74,16.96]],"ltp":3.2,"tv":306.52,"id":5720747}]}]}
{"op":"mcm","clk":"1002840196","pt":1580599486546,"mc":[{"id":"1.168135786","rc":[{"batb":[[0,2.96,188.88]],"ltp":3.2,"tv":306.52,"id":5720747}]}]}
{"op":"mcm","clk":"1002861127","pt":1580599762352,"mc":[{"id":"1.168135786","rc":[{"trd":[[2.96,16]],"batb":[[0,2.88,50],[1,2.74,16.96],[2,2.68,45.07]],"ltp":2.96,"tv":322.52,"id":5720747}],"tv":1752.85}]}
{"op":"mcm","clk":"1002862320","pt":1580599778108,"mc":[{"id":"1.168135786","rc":[{"batb":[[0,2.96,170.38],[1,2.88,50],[2,2.74,16.96]],"ltp":2.96,"tv":322.52,"id":5720747}]}]}
{"op":"mcm","clk":"1002863794","pt":1580599795542,"mc":[{"id":"1.168135786","rc":[{"batb":[[0,2.9,150.36]],"ltp":2.96,"tv":322.52,"id":5720747}]}]}
{"op":"mcm","clk":"1002870354","pt":1580599869740,"mc":[{"id":"1.168135786","rc":[{"batb":[[1,1.43,190.1],[2,1.41,363]],"ltp":1.46,"tv":1430.32,"id":2249229}]}]}
{"op":"mcm","clk":"1002870410","pt":1580599870320,"mc":[{"id":"1.168135786","rc":[{"batb":[[0,1.45,1618.78]],"ltp":1.46,"tv":1430.32,"id":2249229}]}]}
{"op":"mcm","clk":"1002924997","pt":1580600688680,"mc":[{"id":"1.168135786","rc":[{"batb":[[0,1.45,33.17]],"ltp":1.46,"tv":1430.32,"id":2249229},{"batb":[[0,2.88,50],[1,2.74,16.96],[2,2.68,45.07]],"ltp":2.96,"tv":322.52,"id":5720747}]}]}
{"op":"mcm","clk":"1002925045","pt":1580600689458,"mc":[{"id":"1.168135786","rc":[{"batb":[[0,1.45,1597.81],[1,1.44,19.28],[2,1.43,190.1]],"ltp":1.46,"tv":1430.32,"id":2249229},{"batb":[[0,2.94,148.42],[1,2.88,50],[2,2.74,16.96]],"ltp":2.96,"tv":322.52,"id":5720747}]}]}
{"op":"mcm","clk":"1002925161","pt":1580600691781,"mc":[{"id":"1.168135786","rc":[{"batb":[[0,1.46,19.48],[1,1.43,14],[2,1.42,180.3]],"ltp":1.46,"tv":1430.32,"id":2249229},{"batl":[[0,3.2,8.4]],"ltp":2.96,"tv":322.52,"id":5720747}]}]}
{"op":"mcm","clk":"1002925218","pt":1580600692768,"mc":[{"id":"1.168135786","rc":[{"batb":[[0,1.43,14],[1,1.42,180.3],[2,1.41,363]],"ltp":1.46,"tv":1430.32,"id":2249229}]}]}
{"op":"mcm","clk":"1002925243","pt":1580600693176,"mc":[{"id":"1.168135786","rc":[{"batb":[[0,1.44,1609.17],[1,1.43,22.86],[2,1.42,180.3]],"ltp":1.46,"tv":1430.32,"id":2249229}]}]}
{"op":"mcm","clk":"1002925341","pt":1580600694679,"mc":[{"id":"1.168135786","rc":[{"batb":[[1,1.43,14]],"ltp":1.46,"tv":1430.32,"id":2249229}]}]}
{"op":"mcm","clk":"1002925380","pt":1580600695291,"mc":[{"id":"1.168135786","rc":[{"batb":[[0,1.45,1618.25]],"ltp":1.46,"tv":1430.32,"id":2249229},{"batl":[[0,3.25,8.4]],"ltp":2.96,"tv":322.52,"id":5720747}]}]}
{"op":"mcm","clk":"1002926631","pt":1580600715704,"mc":[{"id":"1.168135786","rc":[{"batb":[[0,1.45,20.44]],"ltp":1.46,"tv":1430.32,"id":2249229},{"batb":[[0,2.88,50],[1,2.74,16.96],[2,2.7,44.54]],"ltp":2.96,"tv":322.52,"id":5720747}]}]}
{"op":"mcm","clk":"1002926752","pt":1580600717709,"mc":[{"id":"1.168135786","rc":[{"batb":[[0,1.43,28],[1,1.42,180.3],[2,1.41,363]],"ltp":1.46,"tv":1430.32,"id":2249229}]}]}
{"op":"mcm","clk":"1002926789","pt":1580600718437,"mc":[{"id":"1.168135786","rc":[{"batb":[[1,1.41,363],[2,1.39,2000]],"ltp":1.46,"tv":1430.32,"id":2249229},{"batb":[[2,1.02,2780.76]],"ltp":2.96,"tv":322.52,"id":5720747}]}]}
{"op":"mcm","clk":"1002926869","pt":1580600719727,"mc":[{"id":"1.168135786","rc":[{"batb":[[0,1.43,204.1]],"ltp":1.46,"tv":1430.32,"id":2249229},{"batb":[[2,2.68,45.07]],"ltp":2.96,"tv":322.52,"id":5720747}]}]}
{"op":"mcm","clk":"1002926917","pt":1580600720515,"mc":[{"id":"1.168135786","rc":[{"batb":[[2,1.4,73.81]],"ltp":1.46,"tv":1430.32,"id":2249229}]}]}
{"op":"mcm","clk":"1002928552","pt":1580600747979,"mc":[{"id":"1.168135786","rc":[{"batb":[[0,1.44,9.75],[1,1.43,204.1],[2,1.41,363]],"ltp":1.46,"tv":1430.32,"id":2249229}]}]}
{"op":"mcm","clk":"1003029851","pt":1580602157420,"mc":[{"id":"1.168135786","rc":[{"batb":[[0,1.45,1587.61],[1,1.44,9.75],[2,1.43,204.1]],"ltp":1.46,"tv":1430.32,"id":2249229}]}]}
{"op":"mcm","clk":"1003029956","pt":1580602158535,"mc":[{"id":"1.168135786","rc":[{"batb":[[0,1.46,19.27],[1,1.43,190.1],[2,1.41,363]],"ltp":1.46,"tv":1430.32,"id":2249229},{"batl":[[0,3.2,8.4]],"ltp":2.96,"tv":322.52,"id":5720747}]}]}
{"op":"mcm","clk":"1003030068","pt":1580602159812,"mc":[{"id":"1.168135786","rc":[{"batb":[[0,1.43,190.1],[1,1.41,363],[2,1.4,73.81]],"ltp":1.46,"tv":1430.32,"id":2249229}]}]}
{"op":"mcm","clk":"1003030084","pt":1580602160014,"mc":[{"id":"1.168135786","rc":[{"batb":[[0,1.44,1617.13],[1,1.43,190.1],[2,1.41,363]],"ltp":1.46,"tv":1430.32,"id":2249229}]}]}
{"op":"mcm","clk":"1003030224","pt":1580602161633,"mc":[{"id":"1.168135786","rc":[{"batl":[[0,3.25,8.4]],"ltp":2.96,"tv":322.52,"id":5720747}]}]}
{"op":"mcm","clk":"1003031449","pt":1580602174662,"mc":[{"id":"1.168135786","rc":[{"batb":[[0,1.44,18.21]],"ltp":1.46,"tv":1430.32,"id":2249229}]}]}
{"op":"mcm","clk":"1003034006","pt":1580602202094,"mc":[{"id":"1.168135786","rc":[{"batb":[[0,1.45,1587.61],[1,1.44,18.21],[2,1.43,190.1]],"ltp":1.46,"tv":1430.32,"id":2249229}]}]}
{"op":"mcm","clk":"1003034108","pt":1580602203079,"mc":[{"id":"1.168135786","rc":[{"batb":[[1,1.43,190.1],[2,1.41,363]],"ltp":1.46,"tv":1430.32,"id":2249229}]}]}
{"op":"mcm","clk":"1003034270","pt":1580602204798,"mc":[{"id":"1.168135786","rc":[{"batb":[[0,1.46,18.5]],"ltp":1.46,"tv":1430.32,"id":2249229},{"batl":[[0,3.2,8.4]],"ltp":2.96,"tv":322.52,"id":5720747}]}]}
{"op":"mcm","clk":"1003034425","pt":1580602206402,"mc":[{"id":"1.168135786","rc":[{"batb":[[0,1.44,1598.92]],"ltp":1.46,"tv":1430.32,"id":2249229}]}]}
{"op":"mcm","clk":"1003034554","pt":1580602207808,"mc":[{"id":"1.168135786","rc":[{"batb":[[0,1.45,32.25]],"ltp":1.46,"tv":1430.32,"id":2249229}]}]}
{"op":"mcm","clk":"1003034563","pt":1580602207911,"mc":[{"id":"1.168135786","rc":[{"batb":[[0,1.45,1619.86]],"ltp":1.46,"tv":1430.32,"id":2249229}]}]}
{"op":"mcm","clk":"1003038992","pt":1580602256176,"mc":[{"id":"1.168135786","rc":[{"batl":[[0,3.2,8.4]],"ltp":2.96,"tv":322.52,"id":5720747}]}]}
{"op":"mcm","clk":"1003105180","pt":1580603056091,"mc":[{"id":"1.168135786","rc":[{"trd":[[1.54,2]],"ltp":1.54,"tv":1432.32,"id":2249229},{"trd":[[2.88,1.07]],"batb":[[0,2.88,48.93]],"ltp":2.88,"tv":323.59,"id":5720747}],"tv":1755.92}]}
{"op":"mcm","clk":"1003121948","pt":1580603275344,"mc":[{"id":"1.168135786","rc":[{"batb":[[0,3,41.31],[1,2.88,48.93],[2,2.74,16.96]],"ltp":2.88,"tv":323.59,"id":5720747}]}]}
{"op":"mcm","clk":"1003141680","pt":1580603508569,"mc":[{"id":"1.168135786","rc":[{"batb":[[1,1.43,14],[2,1.42,180.3]],"ltp":1.54,"tv":1432.32,"id":2249229}]}]}
{"op":"mcm","clk":"1003145197","pt":1580603548398,"mc":[{"id":"1.168135786","rc":[{"batb":[[2,1.41,363]],"ltp":1.54,"tv":1432.32,"id":2249229}]}]}
{"op":"mcm","clk":"1003145299","pt":1580603549696,"mc":[{"id":"1.168135786","rc":[{"batb":[[2,1.42,180.3]],"ltp":1.54,"tv":1432.32,"id":2249229}]}]}
{"op":"mcm","clk":"1003237607","pt":1580604948092,"mc":[{"id":"1.168135786","rc":[{"batb":[[0,1.45,32.25]],"ltp":1.54,"tv":1432.32,"id":2249229}]}]}
{"op":"mcm","clk":"1003237686","pt":1580604949785,"mc":[{"id":"1.168135786","rc":[{"batb":[[0,1.44,1634.67],[1,1.43,22.86]],"ltp":1.54,"tv":1432.32,"id":2249229}]}]}
{"op":"mcm","clk":"1003237762","pt":1580604951781,"mc":[{"id":"1.168135786","rc":[{"batb":[[0,1.45,20.26],[1,1.43,14],[2,1.41,547.69]],"ltp":1.54,"tv":1432.32,"id":2249229},{"batb":[[2,2.74,60.48]],"batl":[[0,3.25,8.4]],"ltp":2.88,"tv":323.59,"id":5720747}]}]}
{"op":"mcm","clk":"1003237830","pt":1580604953169,"mc":[{"id":"1.168135786","rc":[{"batb":[[0,1.44,1634.67],[2,1.42,8.91]],"ltp":1.54,"tv":1432.32,"id":2249229}]}]}
{"op":"mcm","clk":"1003237985","pt":1580604955678,"mc":[{"id":"1.168135786","rc":[{"batb":[[2,1.41,547.69]],"ltp":1.54,"tv":1432.32,"id":2249229}]}]}
{"op":"mcm","clk":"1003240551","pt":1580604997738,"mc":[{"id":"1.168135786","rc":[{"batb":[[0,1.45,19.11]],"ltp":1.54,"tv":1432.32,"id":2249229},{"batl":[[0,3.25,8.4]],"ltp":2.88,"tv":323.59,"id":5720747}]}]}
{"op":"mcm","clk":"1003240664","pt":1580604999649,"mc":[{"id":"1.168135786","rc":[{"batb":[[0,1.44,1624.42]],"ltp":1.54,"tv":1432.32,"id":2249229}]}]}
{"op":"mcm","clk":"1003240848","pt":1580605002563,"mc":[{"id":"1.168135786","rc":[{"batb":[[2,1.42,180.3]],"ltp":1.54,"tv":1432.32,"id":2249229},{"batb":[[2,2.74,16.96]],"ltp":2.88,"tv":323.59,"id":5720747}]}]}
{"op":"mcm","clk":"1003243302","pt":1580605042332,"mc":[{"id":"1.168135786","rc":[{"batb":[[0,1.44,1571.17]],"ltp":1.54,"tv":1432.32,"id":2249229}]}]}
{"op":"mcm","clk":"1003243382","pt":1580605043715,"mc":[{"id":"1.168135786","rc":[{"batb":[[1,1.43,190.1],[2,1.41,363]],"ltp":1.54,"tv":1432.32,"id":2249229}]}]}
{"op":"mcm","clk":"1003243429","pt":1580605044690,"mc":[{"id":"1.168135786","rc":[{"batb":[[0,1.46,1549.38],[1,1.45,33.42],[2,1.43,190.1]],"ltp":1.54,"tv":1432.32,"id":2249229},{"batl":[[0,3.25,8.4]],"ltp":2.88,"tv":323.59,"id":5720747}]}]}
{"op":"mcm","clk":"1003243512","pt":1580605046232,"mc":[{"id":"1.168135786","rc":[{"batb":[[1,1.43,190.1],[2,1.41,363]],"ltp":1.54,"tv":1432.32,"id":2249229},{"batl":[[0,3.15,8.4]],"ltp":2.88,"tv":323.59,"id":5720747}]}]}
{"op":"mcm","clk":"1003243981","pt":1580605054806,"mc":[{"id":"1.168135786","rc":[{"batb":[[0,1.47,17.87],[1,1.46,1549.38],[2,1.43,190.1]],"ltp":1.54,"tv":1432.32,"id":2249229}]}]}
{"op":"mcm","clk":"1003243995","pt":1580605055014,"mc":[{"id":"1.168135786","rc":[{"batb":[[1,1.43,190.1],[2,1.41,363]],"ltp":1.54,"tv":1432.32,"id":2249229}]}]}
{"op":"mcm","clk":"1003244109","pt":1580605056809,"mc":[{"id":"1.168135786","rc":[{"batb":[[0,1.44,1587.21]],"ltp":1.54,"tv":1432.32,"id":2249229}]}]}
{"op":"mcm","clk":"1003246017","pt":1580605091800,"mc":[{"id":"1.168135786","rc":[{"batb":[[0,1.45,25],[1,1.44,1587.21],[2,1.43,190.1]],"ltp":1.54,"tv":1432.32,"id":2249229},{"batl":[[0,3.25,8.4]],"ltp":2.88,"tv":323.59,"id":5720747}]}]}
{"op":"mcm","clk":"1003246045","pt":1580605092159,"mc":[{"id":"1.168135786","rc":[{"batb":[[0,1.46,1556.38],[1,1.45,25],[2,1.44,8.79]],"ltp":1.54,"tv":1432.32,"id":2249229}]}]}
{"op":"mcm","clk":"1003246101","pt":1580605093292,"mc":[{"id":"1.168135786","rc":[{"batb":[[1,1.43,190.1],[2,1.41,363]],"ltp":1.54,"tv":1432.32,"id":2249229},{"batl":[[0,3.15,8.4]],"ltp":2.88,"tv":323.59,"id":5720747}]}]}
{"op":"mcm","clk":"1003246572","pt":1580605102403,"mc":[{"id":"1.168135786","rc":[{"batb":[[0,1.47,18.92]],"ltp":1.54,"tv":1432.32,"id":2249229}]}]}
{"op":"mcm","clk":"1003246695","pt":1580605104711,"mc":[{"id":"1.168135786","rc":[{"batb":[[0,1.44,1587.21]],"ltp":1.54,"tv":1432.32,"id":2249229}]}]}
{"op":"mcm","clk":"1003248726","pt":1580605141736,"mc":[{"id":"1.168135786","rc":[{"batb":[[0,1.45,23.19],[1,1.44,8.79],[2,1.43,190.1]],"ltp":1.54,"tv":1432.32,"id":2249229},{"batl":[[0,3.25,8.4]],"ltp":2.88,"tv":323.59,"id":5720747}]}]}
{"op":"mcm","clk":"1003248735","pt":1580605141844,"mc":[{"id":"1.168135786","rc":[{"batb":[[0,1.46,1556.38],[1,1.45,23.19],[2,1.44,8.79]],"ltp":1.54,"tv":1432.32,"id":2249229}]}]}
{"op":"mcm","clk":"1003248802","pt":1580605143178,"mc":[{"id":"1.168135786","rc":[{"batb":[[1,1.43,190.1],[2,1.41,363]],"ltp":1.54,"tv":1432.32,"id":2249229},{"batl":[[0,3.15,8.4]],"ltp":2.88,"tv":323.59,"id":5720747}]}]}
{"op":"mcm","clk":"1003249269","pt":1580605151665,"mc":[{"id":"1.168135786","rc":[{"batb":[[0,1.47,18.95]],"ltp":1.54,"tv":1432.32,"id":2249229}]}]}
{"op":"mcm","clk":"1003249352","pt":1580605153149,"mc":[{"id":"1.168135786","rc":[{"batb":[[0,1.44,1587.21]],"ltp":1.54,"tv":1432.32,"id":2249229}]}]}
{"op":"mcm","clk":"1003251388","pt":1580605191333,"mc":[{"id":"1.168135786","rc":[{"batb":[[0,1.46,1556.38],[1,1.45,25.1],[2,1.44,8.79]],"ltp":1.54,"tv":1432.32,"id":2249229},{"batl":[[0,3.25,8.4]],"ltp":2.88,"tv":323.59,"id":5720747}]}]}
{"op":"mcm","clk":"1003251449","pt":1580605192514,"mc":[{"id":"1.168135786","rc":[{"batb":[[1,1.43,190.1],[2,1.41,363]],"ltp":1.54,"tv":1432.32,"id":2249229},{"batl":[[0,3.15,8.4]],"ltp":2.88,"tv":323.59,"id":5720747}]}]}
{"op":"mcm","clk":"1003252173","pt":1580605204231,"mc":[{"id":"1.168135786","rc":[{"batb":[[0,1.47,18.38]],"ltp":1.54,"tv":1432.32,"id":2249229}]}]}
{"op":"mcm","clk":"1003252293","pt":1580605205638,"mc":[{"id":"1.168135786","rc":[{"batb":[[0,1.44,1587.21]],"ltp":1.54,"tv":1432.32,"id":2249229}]}]}
{"op":"mcm","clk":"1003253701","pt":1580605227520,"mc":[{"id":"1.168135786","rc":[{"batb":[[0,1.46,1556.38],[1,1.45,24.26],[2,1.44,8.79]],"ltp":1.54,"tv":1432.32,"id":2249229},{"batl":[[0,3.25,8.4]],"ltp":2.88,"tv":323.59,"id":5720747}]}]}
{"op":"mcm","clk":"1003253773","pt":1580605228712,"mc":[{"id":"1.168135786","rc":[{"batb":[[1,1.43,190.1],[2,1.41,363]],"ltp":1.54,"tv":1432.32,"id":2249229}]}]}
{"op":"mcm","clk":"1003255016","pt":1580605247212,"mc":[{"id":"1.168135786","rc":[{"batl":[[0,3.15,8.4]],"ltp":2.88,"tv":323.59,"id":5720747}]}]}
{"op":"mcm","clk":"1003255213","pt":1580605250147,"mc":[{"id":"1.168135786","rc":[{"batb":[[0,1.46,1539.38]],"ltp":1.54,"tv":1432.32,"id":2249229}]}]}
{"op":"mcm","clk":"1003255496","pt":1580605253757,"mc":[{"id":"1.168135786","rc":[{"batb":[[0,1.43,14],[1,1.41,363],[2,1.39,2000]],"ltp":1.54,"tv":1432.32,"id":2249229},{"batl":[[0,3.15,721.9]],"ltp":2.88,"tv":323.59,"id":5720747}]}]}
{"op":"mcm","clk":"1003255564","pt":1580605254530,"mc":[{"id":"1.168135786","rc":[{"batb":[[0,1.44,172.1],[1,1.43,14],[2,1.41,363]],"ltp":1.54,"tv":1432.32,"id":2249229}]}]}
{"op":"mcm","clk":"1003256003","pt":1580605261055,"mc":[{"id":"1.168135786","rc":[{"batb":[[0,1.47,1547.85],[1,1.44,172.1],[2,1.43,14]],"ltp":1.54,"tv":1432.32,"id":2249229},{"batl":[[0,3.15,8.4]],"ltp":2.88,"tv":323.59,"id":5720747}]}]}
{"op":"mcm","clk":"1003257373","pt":1580605281267,"mc":[{"id":"1.168135786","rc":[{"batb":[[0,1.47,19.18]],"ltp":1.54,"tv":1432.32,"id":2249229}]}]}
{"op":"mcm","clk":"1003257434","pt":1580605282290,"mc":[{"id":"1.168135786","rc":[{"batb":[[0,1.45,1586.16]],"ltp":1.54,"tv":1432.32,"id":2249229}]}]}
{"op":"mcm","clk":"1003257518","pt":1580605283620,"mc":[{"id":"1.168135786","rc":[{"batb":[[1,1.43,190.1],[2,1.41,363]],"ltp":1.54,"tv":1432.32,"id":2249229}]}]}
{"op":"mcm","clk":"1003257536","pt":1580605283881,"mc":[{"id":"1.168135786","rc":[{"batl":[[0,3.2,8.4]],"ltp":2.88,"tv":323.59,"id":5720747}]}]}
{"op":"mcm","clk":"1003276409","pt":1580605549951,"mc":[{"id":"1.168135786","rc":[{"trd":[[3,18.17]],"batb":[[0,3,32.22]],"ltp":3.0,"tv":341.76,"id":5720747}],"tv":1774.09}]}
{"op":"mcm","clk":"1003312979","pt":1580606076595,"mc":[{"id":"1.168135786","rc":[{"trd":[[1.45,101.35]],"batb":[[0,1.43,190.1],[1,1.41,363],[2,1.39,2000]],"ltp":1.45,"tv":1533.67,"id":2249229}],"tv":1875.44}]}
{"op":"mcm","clk":"1003313106","pt":1580606078709,"mc":[{"id":"1.168135786","rc":[{"batb":[[0,1.44,1583.17],[1,1.43,190.1],[2,1.41,363]],"ltp":1.45,"tv":1533.67,"id":2249229},{"batl":[[0,3.4,8.4]],"ltp":3.0,"tv":341.76,"id":5720747}]}]}
{"op":"mcm","clk":"1003313206","pt":1580606080310,"mc":[{"id":"1.168135786","rc":[{"batl":[[0,3.25,8.4]],"ltp":3.0,"tv":341.76,"id":5720747}]}]}
{"op":"mcm","clk":"1003317457","pt":1580606141708,"mc":[{"id":"1.168135786","rc":[{"trd":[[1.44,22.29]],"batb":[[0,1.44,1572.02]],"ltp":1.44,"tv":1555.96,"id":2249229}],"tv":1897.73}]}
{"op":"mcm","clk":"1003317501","pt":1580606142275,"mc":[{"id":"1.168135786","rc":[{"batb":[[0,1.43,190.1],[1,1.41,363],[2,1.39,2000]],"ltp":1.44,"tv":1555.96,"id":2249229},{"batl":[[0,3.2,712.18],[1,3.25,8.4]],"ltp":3.0,"tv":341.76,"id":5720747}]}]}
{"op":"mcm","clk":"1003317607","pt":1580606143716,"mc":[{"id":"1.168135786","rc":[{"batl":[[1,3.25,0]],"ltp":3.0,"tv":341.76,"id":5720747}]}]}
{"op":"mcm","clk":"1003317649","pt":1580606144181,"mc":[{"id":"1.168135786","rc":[{"batl":[[0,3.15,732.07]],"ltp":3.0,"tv":341.76,"id":5720747}]}]}
{"op":"mcm","clk":"1003317831","pt":1580606146510,"mc":[{"id":"1.168135786","rc":[{"batb":[[2,1.4,73.81]],"ltp":1.44,"tv":1555.96,"id":2249229}]}]}
{"op":"mcm","clk":"1003387847","pt":1580607068883,"mc":[{"id":"1.168135786","rc":[{"batb":[[0,1.43,190.11]],"ltp":1.44,"tv":1555.96,"id":2249229}]}]}
{"op":"mcm","clk":"1003401808","pt":1580607256286,"mc":[{"id":"1.168135786","rc":[{"batb":[[0,1.43,14.01]],"ltp":1.44,"tv":1555.96,"id":2249229}]}]}
{"op":"mcm","clk":"1003401859","pt":1580607256854,"mc":[{"id":"1.168135786","rc":[{"batb":[[0,1.43,190.11]],"ltp":1.44,"tv":1555.96,"id":2249229}]}]}
{"op":"mcm","clk":"1003435609","pt":1580607708743,"mc":[{"id":"1.168135786","rc":[{"batl":[[0,2,10.42]],"ltp":1.44,"tv":1555.96,"id":2249229}]}]}
{"op":"mcm","clk":"1003435667","pt":1580607709516,"mc":[{"id":"1.168135786","rc":[{"batl":[[1,1000,2.1]],"ltp":1.44,"tv":1555.96,"id":2249229}]}]}
{"op":"mcm","clk":"1003435766","pt":1580607710751,"mc":[{"id":"1.168135786","rc":[{"batl":[[0,1.76,1.26],[1,2,10.42],[2,1000,1.68]],"ltp":1.44,"tv":1555.96,"id":2249229}]}]}
{"op":"mcm","clk":"1003435838","pt":1580607711524,"mc":[{"id":"1.168135786","rc":[{"batl":[[1,1.82,1.26],[2,2,10.42]],"ltp":1.44,"tv":1555.96,"id":2249229}]}]}
{"op":"mcm","clk":"1003436006","pt":1580607713633,"mc":[{"id":"1.168135786","rc":[{"batl":[[2,2,10.84]],"ltp":1.44,"tv":1555.96,"id":2249229}]}]}
{"op":"mcm","clk":"1003436090","pt":1580607714663,"mc":[{"id":"1.168135786","rc":[{"batl":[[2,1.92,1.26]],"ltp":1.44,"tv":1555.96,"id":2249229}]}]}
{"op":"mcm","clk":"1003452981","pt":1580607937140,"mc":[{"id":"1.168135786","rc":[{"trd":[[3,82.61]],"batb":[[0,2.88,48.93],[1,2.74,16.96],[2,2.68,45.07]],"batl":[[0,3,35.78],[1,3.15,8.4]],"ltp":3.0,"tv":406.2,"id":5720747}],"tv":1962.17}]}
{"op":"mcm","clk":"1003453038","pt":1580607937916,"mc":[{"id":"1.168135786","rc":[{"batl":[[0,1.53,9.68],[1,1.76,1.26],[2,1.82,1.26]],"ltp":1.44,"tv":1555.96,"id":2249229},{"batl":[[1,3.15,0]],"ltp":3.0,"tv":406.2,"id":5720747}]}]}
{"op":"mcm","clk":"1003480905","pt":1580608335456,"mc":[{"id":"1.168135786","rc":[{"batb":[[0,1.43,14.01]],"ltp":1.44,"tv":1555.96,"id":2249229},{"batb":[[2,1.02,2780.77]],"ltp":3.0,"tv":406.2,"id":5720747}]}]}
{"op":"mcm","clk":"1003480951","pt":1580608336128,"mc":[{"id":"1.168135786","rc":[{"batb":[[0,1.43,190.11]],"ltp":1.44,"tv":1555.96,"id":2249229},{"batb":[[2,2.7,44.54]],"ltp":3.0,"tv":406.2,"id":5720747}]}]}
{"op":"mcm","clk":"1003496436","pt":1580608559726,"mc":[{"id":"1.168135786","rc":[{"batb":[[0,1.43,14.01],[1,1.42,180.3],[2,1.41,363]],"ltp":1.44,"tv":1555.96,"id":2249229},{"batb":[[1,2.74,60.48],[2,1.02,2780.77]],"ltp":3.0,"tv":406.2,"id":5720747}]}]}
{"op":"mcm","clk":"1003499860","pt":1580608614174,"mc":[{"id":"1.168135786","rc":[{"batl":[[0,1.53,1417.52]],"ltp":1.44,"tv":1555.96,"id":2249229}]}]}
{"op":"mcm","clk":"1003499957","pt":1580608615511,"mc":[{"id":"1.168135786","rc":[{"batb":[[1,1.41,363],[2,1.4,73.81]],"ltp":1.44,"tv":1555.96,"id":2249229},{"batb":[[1,2.74,16.96]],"ltp":3.0,"tv":406.2,"id":5720747}]}]}
{"op":"mcm","clk":"1003500017","pt":1580608616589,"mc":[{"id":"1.168135786","rc":[{"batb":[[1,1.42,180.3],[2,1.41,363]],"batl":[[0,1.52,15.57],[1,1.53,9.68],[2,1.76,1.26]],"ltp":1.44,"tv":1555.96,"id":2249229},{"batb":[[1,2.74,60.48]],"ltp":3.0,"tv":406.2,"id":5720747}]}]}
{"op":"mcm","clk":"1003500127","pt":1580608618187,"mc":[{"id":"1.168135786","rc":[{"batl":[[0,1.53,1417.52],[1,1.76,1.26],[2,1.82,1.26]],"ltp":1.44,"tv":1555.96,"id":2249229}]}]}
{"op":"mcm","clk":"1003501986","pt":1580608647340,"mc":[{"id":"1.168135786","rc":[{"batl":[[0,1.52,15.57],[1,1.53,9.68],[2,1.76,1.26]],"ltp":1.44,"tv":1555.96,"id":2249229}]}]}
{"op":"mcm","clk":"1003502099","pt":1580608649237,"mc":[{"id":"1.168135786","rc":[{"batl":[[0,1.53,1417.52],[1,1.76,1.26],[2,1.82,1.26]],"ltp":1.44,"tv":1555.96,"id":2249229}]}]}
{"op":"mcm","clk":"1003503854","pt":1580608678070,"mc":[{"id":"1.168135786","rc":[{"batl":[[0,1.52,15.57],[1,1.53,9.68],[2,1.76,1.26]],"ltp":1.44,"tv":1555.96,"id":2249229}]}]}
{"op":"mcm","clk":"1003503957","pt":1580608679560,"mc":[{"id":"1.168135786","rc":[{"batl":[[0,1.53,1417.52],[1,1.76,1.26],[2,1.82,1.26]],"ltp":1.44,"tv":1555.96,"id":2249229}]}]}
{"op":"mcm","clk":"1003505922","pt":1580608709691,"mc":[{"id":"1.168135786","rc":[{"batl":[[0,1.52,15.57],[1,1.53,1417.52],[2,1.76,1.26]],"ltp":1.44,"tv":1555.96,"id":2249229}]}]}
{"op":"mcm","clk":"1003505934","pt":1580608709898,"mc":[{"id":"1.168135786","rc":[{"batl":[[1,1.53,9.68]],"ltp":1.44,"tv":1555.96,"id":2249229}]}]}
{"op":"mcm","clk":"1003506041","pt":1580608711496,"mc":[{"id":"1.168135786","rc":[{"batl":[[0,1.53,1417.52],[1,1.76,1.26],[2,1.82,1.26]],"ltp":1.44,"tv":1555.96,"id":2249229}]}]}
{"op":"mcm","clk":"1003507831","pt":1580608741177,"mc":[{"id":"1.168135786","rc":[{"batl":[[0,1.52,15.57],[1,1.53,9.68],[2,1.76,1.26]],"ltp":1.44,"tv":1555.96,"id":2249229}]}]}
{"op":"mcm","clk":"1003507928","pt":1580608742671,"mc":[{"id":"1.168135786","rc":[{"batl":[[0,1.53,1417.52],[1,1.76,1.26],[2,1.82,1.26]],"ltp":1.44,"tv":1555.96,"id":2249229}]}]}
{"op":"mcm","clk":"1003509762","pt":1580608773194,"mc":[{"id":"1.168135786","rc":[{"batl":[[0,1.52,15.57],[1,1.53,9.68],[2,1.76,1.26]],"ltp":1.44,"tv":1555.96,"id":2249229}]}]}
{"op":"mcm","clk":"1003509838","pt":1580608774689,"mc":[{"id":"1.168135786","rc":[{"batl":[[0,1.53,1417.52],[1,1.76,1.26],[2,1.82,1.26]],"ltp":1.44,"tv":1555.96,"id":2249229}]}]}
{"op":"mcm","clk":"1003512092","pt":1580608807762,"mc":[{"id":"1.168135786","rc":[{"batl":[[0,1.52,15.57],[1,1.53,9.68],[2,1.76,1.26]],"ltp":1.44,"tv":1555.96,"id":2249229}]}]}
{"op":"mcm","clk":"1003512189","pt":1580608809054,"mc":[{"id":"1.168135786","rc":[{"batl":[[0,1.53,1417.52],[1,1.76,1.26],[2,1.82,1.26]],"ltp":1.44,"tv":1555.96,"id":2249229}]}]}
{"op":"mcm","clk":"1003512838","pt":1580608817254,"mc":[{"id":"1.168135786","rc":[{"batl":[[0,1.52,15.57],[1,1.53,9.68],[2,1.76,1.26]],"ltp":1.44,"tv":1555.96,"id":2249229}]}]}
{"op":"mcm","clk":"1003512948","pt":1580608818748,"mc":[{"id":"1.168135786","rc":[{"batl":[[0,1.53,1417.52],[1,1.76,1.26],[2,1.82,1.26]],"ltp":1.44,"tv":1555.96,"id":2249229}]}]}
{"op":"mcm","clk":"1003514135","pt":1580608836286,"mc":[{"id":"1.168135786","rc":[{"batl":[[0,1.52,15.57],[1,1.53,9.68],[2,1.76,1.26]],"ltp":1.44,"tv":1555.96,"id":2249229}]}]}
{"op":"mcm","clk":"1003514233","pt":1580608837780,"mc":[{"id":"1.168135786","rc":[{"batl":[[0,1.53,1417.52],[1,1.76,1.26],[2,1.82,1.26]],"ltp":1.44,"tv":1555.96,"id":2249229}]}]}
{"op":"mcm","clk":"1003514782","pt":1580608846266,"mc":[{"id":"1.168135786","rc":[{"trd":[[1.5,15.74]],"ltp":1.5,"tv":1571.7,"id":2249229},{"trd":[[3,90.48]],"batl":[[0,3,27.91]],"ltp":3.0,"tv":414.07,"id":5720747}],"tv":1985.78}]}
{"op":"mcm","clk":"1003515748","pt":1580608860724,"mc":[{"id":"1.168135786","rc":[{"batl":[[0,1.52,15.72],[1,1.53,9.68],[2,1.76,1.26]],"ltp":1.5,"tv":1571.7,"id":2249229}]}]}
{"op":"mcm","clk":"1003515885","pt":1580608862432,"mc":[{"id":"1.168135786","rc":[{"batl":[[0,1.53,1417.52],[1,1.76,1.26],[2,1.82,1.26]],"ltp":1.5,"tv":1571.7,"id":2249229}]}]}
{"op":"mcm","clk":"1003517448","pt":1580608884436,"mc":[{"id":"1.168135786","rc":[{"batl":[[0,1.52,15.72],[1,1.53,9.68],[2,1.76,1.26]],"ltp":1.5,"tv":1571.7,"id":2249229}]}]}
{"op":"mcm","clk":"1003517525","pt":1580608885722,"mc":[{"id":"1.168135786","rc":[{"batl":[[0,1.53,9.68],[1,1.76,1.26],[2,1.82,1.26]],"ltp":1.5,"tv":1571.7,"id":2249229}]}]}
{"op":"mcm","clk":"1003517540","pt":1580608885929,"mc":[{"id":"1.168135786","rc":[{"batl":[[0,1.53,1417.52]],"ltp":1.5,"tv":1571.7,"id":2249229}]}]}
{"op":"mcm","clk":"1003519725","pt":1580608912700,"mc":[{"id":"1.168135786","rc":[{"batl":[[0,1.52,15.72],[1,1.53,9.68],[2,1.76,1.26]],"ltp":1.5,"tv":1571.7,"id":2249229}]}]}
{"op":"mcm","clk":"1003519844","pt":1580608914201,"mc":[{"id":"1.168135786","rc":[{"batl":[[0,1.53,1417.52],[1,1.76,1.26],[2,1.82,1.26]],"ltp":1.5,"tv":1571.7,"id":2249229}]}]}
{"op":"mcm","clk":"1003522456","pt":1580608952637,"mc":[{"id":"1.168135786","rc":[{"batl":[[0,1.52,15.72],[1,1.53,9.68],[2,1.76,1.26]],"ltp":1.5,"tv":1571.7,"id":2249229}]}]}
{"op":"mcm","clk":"1003522566","pt":1580608954244,"mc":[{"id":"1.168135786","rc":[{"batl":[[0,1.53,1417.52],[1,1.76,1.26],[2,1.82,1.26]],"ltp":1.5,"tv":1571.7,"id":2249229}]}]}
{"op":"mcm","clk":"1003524618","pt":1580608988690,"mc":[{"id":"1.168135786","rc":[{"batl":[[0,1.52,15.72],[1,1.53,1417.52],[2,1.76,1.26]],"ltp":1.5,"tv":1571.7,"id":2249229}]}]}
{"op":"mcm","clk":"1003524633","pt":1580608988895,"mc":[{"id":"1.168135786","rc":[{"batl":[[1,1.53,9.68]],"ltp":1.5,"tv":1571.7,"id":2249229}]}]}
{"op":"mcm","clk":"1003524723","pt":1580608990492,"mc":[{"id":"1.168135786","rc":[{"batl":[[0,1.53,1417.52],[1,1.76,1.26],[2,1.82,1.26]],"ltp":1.5,"tv":1571.7,"id":2249229}]}]}
{"op":"mcm","clk":"1003527068","pt":1580609031731,"mc":[{"id":"1.168135786","rc":[{"batl":[[0,1.52,15.72],[1,1.53,1417.52],[2,1.76,1.26]],"ltp":1.5,"tv":1571.7,"id":2249229}]}]}
{"op":"mcm","clk":"1003527080","pt":1580609031936,"mc":[{"id":"1.168135786","rc":[{"batl":[[1,1.53,9.68]],"ltp":1.5,"tv":1571.7,"id":2249229}]}]}
{"op":"mcm","clk":"1003527147","pt":1580609033267,"mc":[{"id":"1.168135786","rc":[{"batl":[[0,1.53,1417.52],[1,1.76,1.26],[2,1.82,1.26]],"ltp":1.5,"tv":1571.7,"id":2249229}]}]}
{"op":"mcm","clk":"1003529613","pt":1580609072614,"mc":[{"id":"1.168135786","rc":[{"batl":[[0,1.52,15.72],[1,1.53,9.68],[2,1.76,1.26]],"ltp":1.5,"tv":1571.7,"id":2249229}]}]}
{"op":"mcm","clk":"1003529726","pt":1580609074214,"mc":[{"id":"1.168135786","rc":[{"batl":[[0,1.53,1417.52],[1,1.76,1.26],[2,1.82,1.26]],"ltp":1.5,"tv":1571.7,"id":2249229}]}]}
{"op":"mcm","clk":"1003531847","pt":1580609107364,"mc":[{"id":"1.168135786","rc":[{"batl":[[0,1.52,15.72],[1,1.53,9.68],[2,1.76,1.26]],"ltp":1.5,"tv":1571.7,"id":2249229}]}]}
{"op":"mcm","clk":"1003531947","pt":1580609109064,"mc":[{"id":"1.168135786","rc":[{"batl":[[0,1.53,1417.52],[1,1.76,1.26],[2,1.82,1.26]],"ltp":1.5,"tv":1571.7,"id":2249229}]}]}
{"op":"mcm","clk":"1003534124","pt":1580609143502,"mc":[{"id":"1.168135786","rc":[{"batl":[[0,1.52,15.72],[1,1.53,9.68],[2,1.76,1.26]],"ltp":1.5,"tv":1571.7,"id":2249229}]}]}
{"op":"mcm","clk":"1003534233","pt":1580609145102,"mc":[{"id":"1.168135786","rc":[{"batl":[[0,1.53,1417.52],[1,1.76,1.26],[2,1.82,1.26]],"ltp":1.5,"tv":1571.7,"id":2249229}]}]}
{"op":"mcm","clk":"1003536043","pt":1580609175741,"mc":[{"id":"1.168135786","rc":[{"batl":[[0,1.52,15.72],[1,1.53,9.68],[2,1.76,1.26]],"ltp":1.5,"tv":1571.7,"id":2249229}]}]}
{"op":"mcm","clk":"1003536156","pt":1580609177440,"mc":[{"id":"1.168135786","rc":[{"batl":[[0,1.53,1417.52],[1,1.76,1.26],[2,1.82,1.26]],"ltp":1.5,"tv":1571.7,"id":2249229}]}]}
{"op":"mcm","clk":"1003538610","pt":1580609216500,"mc":[{"id":"1.168135786","rc":[{"batl":[[0,1.52,15.72],[1,1.53,9.68],[2,1.76,1.26]],"ltp":1.5,"tv":1571.7,"id":2249229}]}]}
{"op":"mcm","clk":"1003538686","pt":1580609217680,"mc":[{"id":"1.168135786","rc":[{"batl":[[0,1.53,9.68],[1,1.76,1.26],[2,1.82,1.26]],"ltp":1.5,"tv":1571.7,"id":2249229}]}]}
{"op":"mcm","clk":"1003538704","pt":1580609217989,"mc":[{"id":"1.168135786","rc":[{"batl":[[0,1.53,1417.52]],"ltp":1.5,"tv":1571.7,"id":2249229}]}]}
{"op":"mcm","clk":"1003541287","pt":1580609254266,"mc":[{"id":"1.168135786","rc":[{"batl":[[0,1.52,15.58],[1,1.53,9.68],[2,1.76,1.26]],"ltp":1.5,"tv":1571.7,"id":2249229}]}]}
{"op":"mcm","clk":"1003541399","pt":1580609255664,"mc":[{"id":"1.168135786","rc":[{"batl":[[0,1.53,1417.52],[1,1.76,1.26],[2,1.82,1.26]],"ltp":1.5,"tv":1571.7,"id":2249229}]}]}
{"op":"mcm","clk":"1003544375","pt":1580609296810,"mc":[{"id":"1.168135786","rc":[{"batl":[[0,1.52,15.72],[1,1.53,9.68],[2,1.76,1.26]],"ltp":1.5,"tv":1571.7,"id":2249229}]}]}
{"op":"mcm","clk":"1003544439","pt":1580609297687,"mc":[{"id":"1.168135786","rc":[{"batl":[[0,1.53,1417.52],[1,1.76,1.26],[2,1.82,1.26]],"ltp":1.5,"tv":1571.7,"id":2249229}]}]}
{"op":"mcm","clk":"1003547459","pt":1580609341757,"mc":[{"id":"1.168135786","rc":[{"batl":[[0,1.52,15.72],[1,1.53,9.68],[2,1.76,1.26]],"ltp":1.5,"tv":1571.7,"id":2249229}]}]}
{"op":"mcm","clk":"1003547568","pt":1580609343362,"mc":[{"id":"1.168135786","rc":[{"batl":[[0,1.53,1417.52],[1,1.76,1.26],[2,1.82,1.26]],"ltp":1.5,"tv":1571.7,"id":2249229}]}]}
{"op":"mcm","clk":"1003550877","pt":1580609388817,"mc":[{"id":"1.168135786","rc":[{"batl":[[0,1.52,15.59],[1,1.53,9.68],[2,1.76,1.26]],"ltp":1.5,"tv":1571.7,"id":2249229}]}]}
{"op":"mcm","clk":"1003550993","pt":1580609390414,"mc":[{"id":"1.168135786","rc":[{"batl":[[0,1.53,1417.52],[1,1.76,1.26],[2,1.82,1.26]],"ltp":1.5,"tv":1571.7,"id":2249229}]}]}
{"op":"mcm","clk":"1003554096","pt":1580609433162,"mc":[{"id":"1.168135786","rc":[{"batl":[[0,1.52,15.72],[1,1.53,9.68],[2,1.76,1.26]],"ltp":1.5,"tv":1571.7,"id":2249229}]}]}
{"op":"mcm","clk":"1003554193","pt":1580609434351,"mc":[{"id":"1.168135786","rc":[{"batl":[[0,1.53,1417.52],[1,1.76,1.26],[2,1.82,1.26]],"ltp":1.5,"tv":1571.7,"id":2249229}]}]}
{"op":"mcm","clk":"1003557449","pt":1580609476031,"mc":[{"id":"1.168135786","rc":[{"batl":[[0,1.52,15.72],[1,1.53,9.68],[2,1.76,1.26]],"ltp":1.5,"tv":1571.7,"id":2249229}]}]}
{"op":"mcm","clk":"1003557537","pt":1580609477426,"mc":[{"id":"1.168135786","rc":[{"batl":[[0,1.53,1417.52],[1,1.76,1.26],[2,1.82,1.26]],"ltp":1.5,"tv":1571.7,"id":2249229}]}]}
{"op":"mcm","clk":"1003560610","pt":1580609519666,"mc":[{"id":"1.168135786","rc":[{"batl":[[0,1.52,15.72],[1,1.53,9.68],[2,1.76,1.26]],"ltp":1.5,"tv":1571.7,"id":2249229}]}]}
{"op":"mcm","clk":"1003560695","pt":1580609520754,"mc":[{"id":"1.168135786","rc":[{"batl":[[0,1.53,9.68],[1,1.76,1.26],[2,1.82,1.26]],"ltp":1.5,"tv":1571.7,"id":2249229}]}]}
{"op":"mcm","clk":"1003560708","pt":1580609520962,"mc":[{"id":"1.168135786","rc":[{"batl":[[0,1.53,1417.52]],"ltp":1.5,"tv":1571.7,"id":2249229}]}]}
{"op":"mcm","clk":"1003564029","pt":1580609563795,"mc":[{"id":"1.168135786","rc":[{"batl":[[0,1.52,15.72],[1,1.53,1417.52],[2,1.76,1.26]],"ltp":1.5,"tv":1571.7,"id":2249229}]}]}
{"op":"mcm","clk":"1003564035","pt":1580609563899,"mc":[{"id":"1.168135786","rc":[{"batl":[[1,1.53,9.68]],"ltp":1.5,"tv":1571.7,"id":2249229}]}]}
{"op":"mcm","clk":"1003564149","pt":1580609565596,"mc":[{"id":"1.168135786","rc":[{"batl":[[0,1.53,1417.52],[1,1.76,1.26],[2,1.82,1.26]],"ltp":1.5,"tv":1571.7,"id":2249229}]}]}
{"op":"mcm","clk":"1003567110","pt":1580609608763,"mc":[{"id":"1.168135786","rc":[{"batl":[[0,1.52,15.72],[1,1.53,1417.52],[2,1.76,1.26]],"ltp":1.5,"tv":1571.7,"id":2249229}]}]}
{"op":"mcm","clk":"1003567126","pt":1580609608967,"mc":[{"id":"1.168135786","rc":[{"batl":[[1,1.53,9.68]],"ltp":1.5,"tv":1571.7,"id":2249229}]}]}
{"op":"mcm","clk":"1003567244","pt":1580609610614,"mc":[{"id":"1.168135786","rc":[{"batl":[[0,1.53,1417.52],[1,1.76,1.26],[2,1.82,1.26]],"ltp":1.5,"tv":1571.7,"id":2249229}]}]}
{"op":"mcm","clk":"1003570195","pt":1580609651624,"mc":[{"id":"1.168135786","rc":[{"batl":[[0,1.52,15.72],[1,1.53,1417.52],[2,1.76,1.26]],"ltp":1.5,"tv":1571.7,"id":2249229}]}]}
{"op":"mcm","clk":"1003570209","pt":1580609651828,"mc":[{"id":"1.168135786","rc":[{"batl":[[1,1.53,9.68]],"ltp":1.5,"tv":1571.7,"id":2249229}]}]}
{"op":"mcm","clk":"1003570323","pt":1580609653429,"mc":[{"id":"1.168135786","rc":[{"batl":[[0,1.53,1417.52],[1,1.76,1.26],[2,1.82,1.26]],"ltp":1.5,"tv":1571.7,"id":2249229}]}]}
{"op":"mcm","clk":"1003573229","pt":1580609695262,"mc":[{"id":"1.168135786","rc":[{"batl":[[0,1.52,15.72],[1,1.53,9.68],[2,1.76,1.26]],"ltp":1.5,"tv":1571.7,"id":2249229}]}]}
{"op":"mcm","clk":"1003573323","pt":1580609696759,"mc":[{"id":"1.168135786","rc":[{"batl":[[0,1.53,9.68],[1,1.76,1.26],[2,1.82,1.26]],"ltp":1.5,"tv":1571.7,"id":2249229}]}]}
{"op":"mcm","clk":"1003573335","pt":1580609696962,"mc":[{"id":"1.168135786","rc":[{"batl":[[0,1.53,1417.52]],"ltp":1.5,"tv":1571.7,"id":2249229}]}]}
{"op":"mcm","clk":"1003576085","pt":1580609737792,"mc":[{"id":"1.168135786","rc":[{"batl":[[0,1.52,15.69],[1,1.53,9.68],[2,1.76,1.26]],"ltp":1.5,"tv":1571.7,"id":2249229}]}]}
{"op":"mcm","clk":"1003576202","pt":1580609739190,"mc":[{"id":"1.168135786","rc":[{"batl":[[0,1.53,1417.52],[1,1.76,1.26],[2,1.82,1.26]],"ltp":1.5,"tv":1571.7,"id":2249229}]}]}
{"op":"mcm","clk":"1003578972","pt":1580609778649,"mc":[{"id":"1.168135786","rc":[{"batl":[[0,1.52,15.71],[1,1.53,1417.52],[2,1.76,1.26]],"ltp":1.5,"tv":1571.7,"id":2249229}]}]}
{"op":"mcm","clk":"1003579030","pt":1580609779677,"mc":[{"id":"1.168135786","rc":[{"batl":[[0,1.53,9.68],[1,1.76,1.26],[2,1.82,1.26]],"ltp":1.5,"tv":1571.7,"id":2249229}]}]}
{"op":"mcm","clk":"1003579045","pt":1580609779886,"mc":[{"id":"1.168135786","rc":[{"batl":[[0,1.53,1417.52]],"ltp":1.5,"tv":1571.7,"id":2249229}]}]}
{"op":"mcm","clk":"1003581741","pt":1580609821418,"mc":[{"id":"1.168135786","rc":[{"batl":[[0,1.52,15.68],[1,1.53,9.68],[2,1.76,1.26]],"ltp":1.5,"tv":1571.7,"id":2249229}]}]}
{"op":"mcm","clk":"1003581836","pt":1580609822811,"mc":[{"id":"1.168135786","rc":[{"batl":[[0,1.53,1417.52],[1,1.76,1.26],[2,1.82,1.26]],"ltp":1.5,"tv":1571.7,"id":2249229}]}]}
{"op":"mcm","clk":"1003584489","pt":1580609863676,"mc":[{"id":"1.168135786","rc":[{"batl":[[0,1.52,15.72],[1,1.53,9.68],[2,1.76,1.26]],"ltp":1.5,"tv":1571.7,"id":2249229}]}]}
{"op":"mcm","clk":"1003584591","pt":1580609865064,"mc":[{"id":"1.168135786","rc":[{"batl":[[0,1.53,1417.52],[1,1.76,1.26],[2,1.82,1.26]],"ltp":1.5,"tv":1571.7,"id":2249229}]}]}
{"op":"mcm","clk":"1003587328","pt":1580609904699,"mc":[{"id":"1.168135786","rc":[{"batl":[[0,1.52,15.72],[1,1.53,1417.52],[2,1.76,1.26]],"ltp":1.5,"tv":1571.7,"id":2249229}]}]}
{"op":"mcm","clk":"1003587342","pt":1580609904950,"mc":[{"id":"1.168135786","rc":[{"batl":[[1,1.53,9.68]],"ltp":1.5,"tv":1571.7,"id":2249229}]}]}
{"op":"mcm","clk":"1003587435","pt":1580609906237,"mc":[{"id":"1.168135786","rc":[{"batl":[[0,1.53,1417.52],[1,1.76,1.26],[2,1.82,1.26]],"ltp":1.5,"tv":1571.7,"id":2249229}]}]}
{"op":"mcm","clk":"1003590564","pt":1580609948485,"mc":[{"id":"1.168135786","rc":[{"batl":[[0,1.52,15.72],[1,1.53,9.68],[2,1.76,1.26]],"ltp":1.5,"tv":1571.7,"id":2249229}]}]}
{"op":"mcm","clk":"1003590668","pt":1580609949785,"mc":[{"id":"1.168135786","rc":[{"batl":[[0,1.53,9.68],[1,1.76,1.26],[2,1.82,1.26]],"ltp":1.5,"tv":1571.7,"id":2249229}]}]}
{"op":"mcm","clk":"1003590718","pt":1580609950402,"mc":[{"id":"1.168135786","rc":[{"batl":[[0,1.53,1417.52]],"ltp":1.5,"tv":1571.7,"id":2249229}]}]}
{"op":"mcm","clk":"1003594453","pt":1580609995423,"mc":[{"id":"1.168135786","rc":[{"batl":[[0,1.52,15.68],[1,1.53,9.68],[2,1.76,1.26]],"ltp":1.5,"tv":1571.7,"id":2249229}]}]}
{"op":"mcm","clk":"1003594557","pt":1580609996717,"mc":[{"id":"1.168135786","rc":[{"batl":[[0,1.53,9.68],[1,1.76,1.26],[2,1.82,1.26]],"ltp":1.5,"tv":1571.7,"id":2249229}]}]}
{"op":"mcm","clk":"1003594570","pt":1580609996922,"mc":[{"id":"1.168135786","rc":[{"batl":[[0,1.53,1417.52]],"ltp":1.5,"tv":1571.7,"id":2249229}]}]}
{"op":"mcm","clk":"1003598198","pt":1580610040783,"mc":[{"id":"1.168135786","rc":[{"batl":[[0,1.52,15.72],[1,1.53,1417.52],[2,1.76,1.26]],"ltp":1.5,"tv":1571.7,"id":2249229}]}]}
{"op":"mcm","clk":"1003598216","pt":1580610040990,"mc":[{"id":"1.168135786","rc":[{"batl":[[1,1.53,9.68]],"ltp":1.5,"tv":1571.7,"id":2249229}]}]}
{"op":"mcm","clk":"1003598340","pt":1580610042379,"mc":[{"id":"1.168135786","rc":[{"batl":[[0,1.53,1417.52],[1,1.76,1.26],[2,1.82,1.26]],"ltp":1.5,"tv":1571.7,"id":2249229}]}]}
{"op":"mcm","clk":"1003602233","pt":1580610091253,"mc":[{"id":"1.168135786","rc":[{"batl":[[0,1.52,15.72],[1,1.53,9.68],[2,1.76,1.26]],"ltp":1.5,"tv":1571.7,"id":2249229}]}]}
{"op":"mcm","clk":"1003602345","pt":1580610092651,"mc":[{"id":"1.168135786","rc":[{"batl":[[0,1.53,1417.52],[1,1.76,1.26],[2,1.82,1.26]],"ltp":1.5,"tv":1571.7,"id":2249229}]}]}
{"op":"mcm","clk":"1003605858","pt":1580610140615,"mc":[{"id":"1.168135786","rc":[{"batl":[[0,1.52,15.72],[1,1.53,9.68],[2,1.76,1.26]],"ltp":1.5,"tv":1571.7,"id":2249229}]}]}
{"op":"mcm","clk":"1003605979","pt":1580610142412,"mc":[{"id":"1.168135786","rc":[{"batl":[[0,1.53,1417.52],[1,1.76,1.26],[2,1.82,1.26]],"ltp":1.5,"tv":1571.7,"id":2249229}]}]}
{"op":"mcm","clk":"1003609149","pt":1580610188662,"mc":[{"id":"1.168135786","rc":[{"batl":[[0,1.52,15.72],[1,1.53,9.68],[2,1.76,1.26]],"ltp":1.5,"tv":1571.7,"id":2249229}]}]}
{"op":"mcm","clk":"1003609253","pt":1580610190259,"mc":[{"id":"1.168135786","rc":[{"batl":[[0,1.53,1417.52],[1,1.76,1.26],[2,1.82,1.26]],"ltp":1.5,"tv":1571.7,"id":2249229}]}]}
{"op":"mcm","clk":"1003612627","pt":1580610239431,"mc":[{"id":"1.168135786","rc":[{"batl":[[0,1.52,15.72],[1,1.53,9.68],[2,1.76,1.26]],"ltp":1.5,"tv":1571.7,"id":2249229}]}]}
{"op":"mcm","clk":"1003612720","pt":1580610240723,"mc":[{"id":"1.168135786","rc":[{"batl":[[0,1.53,9.68],[1,1.76,1.26],[2,1.82,1.26]],"ltp":1.5,"tv":1571.7,"id":2249229}]}]}
{"op":"mcm","clk":"1003612736","pt":1580610240972,"mc":[{"id":"1.168135786","rc":[{"batl":[[0,1.53,1417.52]],"ltp":1.5,"tv":1571.7,"id":2249229}]}]}
{"op":"mcm","clk":"1003616709","pt":1580610290674,"mc":[{"id":"1.168135786","rc":[{"batl":[[0,1.52,15.72],[1,1.53,9.68],[2,1.76,1.26]],"ltp":1.5,"tv":1571.7,"id":2249229}]}]}
{"op":"mcm","clk":"1003616785","pt":1580610291705,"mc":[{"id":"1.168135786","rc":[{"batl":[[0,1.53,9.68],[1,1.76,1.26],[2,1.82,1.26]],"ltp":1.5,"tv":1571.7,"id":2249229}]}]}
{"op":"mcm","clk":"1003616807","pt":1580610291913,"mc":[{"id":"1.168135786","rc":[{"batl":[[0,1.53,1417.52]],"ltp":1.5,"tv":1571.7,"id":2249229}]}]}
{"op":"mcm","clk":"1003620677","pt":1580610340529,"mc":[{"id":"1.168135786","rc":[{"batl":[[0,1.52,15.72],[1,1.53,9.68],[2,1.76,1.26]],"ltp":1.5,"tv":1571.7,"id":2249229}]}]}
{"op":"mcm","clk":"1003620780","pt":1580610341721,"mc":[{"id":"1.168135786","rc":[{"batl":[[0,1.53,9.68],[1,1.76,1.26],[2,1.82,1.26]],"ltp":1.5,"tv":1571.7,"id":2249229}]}]}
{"op":"mcm","clk":"1003620810","pt":1580610342032,"mc":[{"id":"1.168135786","rc":[{"batl":[[0,1.53,1417.52]],"ltp":1.5,"tv":1571.7,"id":2249229}]}]}
{"op":"mcm","clk":"1003621043","pt":1580610344733,"mc":[{"id":"1.168135786","rc":[{"batl":[[0,1.53,9.68]],"ltp":1.5,"tv":1571.7,"id":2249229}]}]}
{"op":"mcm","clk":"1003639546","pt":1580610573828,"mc":[{"id":"1.168135786","rc":[{"batb":[[0,2.9,2],[1,2.88,48.93],[2,2.74,60.48]],"ltp":3.0,"tv":414.07,"id":5720747}]}]}
{"op":"mcm","clk":"1003639778","pt":1580610576720,"mc":[{"id":"1.168135786","rc":[{"batb":[[0,2.92,2]],"ltp":3.0,"tv":414.07,"id":5720747}]}]}
{"op":"mcm","clk":"1003639995","pt":1580610579627,"mc":[{"id":"1.168135786","rc":[{"batb":[[0,2.94,2]],"ltp":3.0,"tv":414.07,"id":5720747}]}]}
{"op":"mcm","clk":"1003640459","pt":1580610585338,"mc":[{"id":"1.168135786","rc":[{"batb":[[0,2.96,2]],"ltp":3.0,"tv":414.07,"id":5720747}]}]}
{"op":"mcm","clk":"1003640747","pt":1580610588952,"mc":[{"id":"1.168135786","rc":[{"batb":[[0,2.98,2]],"ltp":3.0,"tv":414.07,"id":5720747}]}]}
{"op":"mcm","clk":"1003641102","pt":1580610593480,"mc":[{"id":"1.168135786","rc":[{"batb":[[0,2.88,48.93],[1,2.74,60.48],[2,1.02,2780.77]],"ltp":3.0,"tv":414.07,"id":5720747}]}]}
{"op":"mcm","clk":"1003641865","pt":1580610603775,"mc":[{"id":"1.168135786","rc":[{"batb":[[1,2.74,68.97]],"ltp":3.0,"tv":414.07,"id":5720747}]}]}
{"op":"mcm","clk":"1003645121","pt":1580610648452,"mc":[{"id":"1.168135786","rc":[{"batl":[[0,1.53,1417.52]],"ltp":1.5,"tv":1571.7,"id":2249229}]}]}
{"op":"mcm","clk":"1003645189","pt":1580610649486,"mc":[{"id":"1.168135786","rc":[{"batb":[[1,1.41,363],[2,1.4,110.71]],"batl":[[0,1.52,15.72],[1,1.53,9.68],[2,1.76,1.26]],"ltp":1.5,"tv":1571.7,"id":2249229},{"batb":[[1,2.74,25.45]],"ltp":3.0,"tv":414.07,"id":5720747}]}]}
{"op":"mcm","clk":"1003645230","pt":1580610650054,"mc":[{"id":"1.168135786","rc":[{"batb":[[1,1.42,180.3],[2,1.41,363]],"ltp":1.5,"tv":1571.7,"id":2249229},{"batb":[[1,2.74,68.97]],"ltp":3.0,"tv":414.07,"id":5720747}]}]}
{"op":"mcm","clk":"1003645314","pt":1580610651242,"mc":[{"id":"1.168135786","rc":[{"batl":[[0,1.53,1417.52],[1,1.76,1.26],[2,1.82,1.26]],"ltp":1.5,"tv":1571.7,"id":2249229}]}]}
{"op":"mcm","clk":"1003649204","pt":1580610700807,"mc":[{"id":"1.168135786","rc":[{"batl":[[0,1.52,15.72],[1,1.53,9.68],[2,1.76,1.26]],"ltp":1.5,"tv":1571.7,"id":2249229}]}]}
{"op":"mcm","clk":"1003649354","pt":1580610702625,"mc":[{"id":"1.168135786","rc":[{"batl":[[0,1.53,9.68],[1,1.76,1.26],[2,1.82,1.26]],"ltp":1.5,"tv":1571.7,"id":2249229}]}]}
{"op":"mcm","clk":"1003649372","pt":1580610702831,"mc":[{"id":"1.168135786","rc":[{"batl":[[0,1.53,1417.52]],"ltp":1.5,"tv":1571.7,"id":2249229}]}]}
{"op":"mcm","clk":"1003653169","pt":1580610751186,"mc":[{"id":"1.168135786","rc":[{"batl":[[0,1.52,15.72],[1,1.53,9.68],[2,1.76,1.26]],"ltp":1.5,"tv":1571.7,"id":2249229}]}]}
{"op":"mcm","clk":"1003653279","pt":1580610752686,"mc":[{"id":"1.168135786","rc":[{"batl":[[0,1.53,1417.52],[1,1.76,1.26],[2,1.82,1.26]],"ltp":1.5,"tv":1571.7,"id":2249229}]}]}
{"op":"mcm","clk":"1003656536","pt":1580610801563,"mc":[{"id":"1.168135786","rc":[{"batl":[[0,1.52,15.72],[1,1.53,1417.52],[2,1.76,1.26]],"ltp":1.5,"tv":1571.7,"id":2249229}]}]}
{"op":"mcm","clk":"1003656558","pt":1580610801865,"mc":[{"id":"1.168135786","rc":[{"batl":[[1,1.53,9.68]],"ltp":1.5,"tv":1571.7,"id":2249229}]}]}
{"op":"mcm","clk":"1003656657","pt":1580610803464,"mc":[{"id":"1.168135786","rc":[{"batl":[[0,1.53,1417.52],[1,1.76,1.26],[2,1.82,1.26]],"ltp":1.5,"tv":1571.7,"id":2249229}]}]}
{"op":"mcm","clk":"1003659731","pt":1580610851633,"mc":[{"id":"1.168135786","rc":[{"batl":[[0,1.52,15.72],[1,1.53,1417.52],[2,1.76,1.26]],"ltp":1.5,"tv":1571.7,"id":2249229}]}]}
{"op":"mcm","clk":"1003659747","pt":1580610851839,"mc":[{"id":"1.168135786","rc":[{"batl":[[1,1.53,9.68]],"ltp":1.5,"tv":1571.7,"id":2249229}]}]}
{"op":"mcm","clk":"1003659865","pt":1580610853439,"mc":[{"id":"1.168135786","rc":[{"batl":[[0,1.53,1417.52],[1,1.76,1.26],[2,1.82,1.26]],"ltp":1.5,"tv":1571.7,"id":2249229}]}]}
{"op":"mcm","clk":"1003660798","pt":1580610866750,"mc":[{"id":"1.168135786","rc":[{"batl":[[0,1.53,1878.35]],"ltp":1.5,"tv":1571.7,"id":2249229}]}]}
{"op":"mcm","clk":"1003663181","pt":1580610901191,"mc":[{"id":"1.168135786","rc":[{"batl":[[0,1.52,15.72],[1,1.53,9.68],[2,1.76,1.26]],"ltp":1.5,"tv":1571.7,"id":2249229}]}]}
{"op":"mcm","clk":"1003663304","pt":1580610902482,"mc":[{"id":"1.168135786","rc":[{"batl":[[0,1.53,1886.98],[1,1.76,1.26],[2,1.82,1.26]],"ltp":1.5,"tv":1571.7,"id":2249229}]}]}
{"op":"mcm","clk":"1003666697","pt":1580610951683,"mc":[{"id":"1.168135786","rc":[{"batl":[[0,1.52,15.72],[1,1.53,1886.98],[2,1.76,1.26]],"ltp":1.5,"tv":1571.7,"id":2249229}]}]}
{"op":"mcm","clk":"1003666710","pt":1580610951889,"mc":[{"id":"1.168135786","rc":[{"batl":[[1,1.53,9.68]],"ltp":1.5,"tv":1571.7,"id":2249229}]}]}
{"op":"mcm","clk":"1003666833","pt":1580610953694,"mc":[{"id":"1.168135786","rc":[{"batl":[[0,1.53,1886.98],[1,1.76,1.26],[2,1.82,1.26]],"ltp":1.5,"tv":1571.7,"id":2249229}]}]}
{"op":"mcm","clk":"1003670183","pt":1580611002745,"mc":[{"id":"1.168135786","rc":[{"batl":[[0,1.52,15.72],[1,1.53,1886.98],[2,1.76,1.26]],"ltp":1.5,"tv":1571.7,"id":2249229}]}]}
{"op":"mcm","clk":"1003670195","pt":1580611002849,"mc":[{"id":"1.168135786","rc":[{"batl":[[1,1.53,9.68]],"ltp":1.5,"tv":1571.7,"id":2249229}]}]}
{"op":"mcm","clk":"1003670303","pt":1580611004340,"mc":[{"id":"1.168135786","rc":[{"batl":[[0,1.53,1886.98],[1,1.76,1.26],[2,1.82,1.26]],"ltp":1.5,"tv":1571.7,"id":2249229}]}]}
{"op":"mcm","clk":"1003673852","pt":1580611053801,"mc":[{"id":"1.168135786","rc":[{"batl":[[0,1.52,15.72],[1,1.53,9.68],[2,1.76,1.26]],"ltp":1.5,"tv":1571.7,"id":2249229}]}]}
{"op":"mcm","clk":"1003673972","pt":1580611055407,"mc":[{"id":"1.168135786","rc":[{"batl":[[0,1.53,1886.98],[1,1.76,1.26],[2,1.82,1.26]],"ltp":1.5,"tv":1571.7,"id":2249229}]}]}
{"op":"mcm","clk":"1003677262","pt":1580611102751,"mc":[{"id":"1.168135786","rc":[{"batl":[[0,1.52,15.72],[1,1.53,1886.98],[2,1.76,1.26]],"ltp":1.5,"tv":1571.7,"id":2249229}]}]}
{"op":"mcm","clk":"1003677280","pt":1580611102960,"mc":[{"id":"1.168135786","rc":[{"batl":[[1,1.53,9.68]],"ltp":1.5,"tv":1571.7,"id":2249229}]}]}
{"op":"mcm","clk":"1003677373","pt":1580611104351,"mc":[{"id":"1.168135786","rc":[{"batl":[[0,1.53,1886.98],[1,1.76,1.26],[2,1.82,1.26]],"ltp":1.5,"tv":1571.7,"id":2249229}]}]}
{"op":"mcm","clk":"1003680852","pt":1580611151737,"mc":[{"id":"1.168135786","rc":[{"batl":[[0,1.52,15.72],[1,1.53,9.68],[2,1.76,1.26]],"ltp":1.5,"tv":1571.7,"id":2249229}]}]}
{"op":"mcm","clk":"1003680974","pt":1580611153438,"mc":[{"id":"1.168135786","rc":[{"batl":[[0,1.53,1886.98],[1,1.76,1.26],[2,1.82,1.26]],"ltp":1.5,"tv":1571.7,"id":2249229}]}]}
{"op":"mcm","clk":"1003684093","pt":1580611200495,"mc":[{"id":"1.168135786","rc":[{"batl":[[0,1.52,15.72],[1,1.53,1886.98],[2,1.76,1.26]],"ltp":1.5,"tv":1571.7,"id":2249229}]}]}
{"op":"mcm","clk":"1003684169","pt":1580611201786,"mc":[{"id":"1.168135786","rc":[{"batl":[[1,1.53,9.68]],"ltp":1.5,"tv":1571.7,"id":2249229}]}]}
{"op":"mcm","clk":"1003684200","pt":1580611202202,"mc":[{"id":"1.168135786","rc":[{"batl":[[0,1.53,1886.98],[1,1.76,1.26],[2,1.82,1.26]],"ltp":1.5,"tv":1571.7,"id":2249229}]}]}
{"op":"mcm","clk":"1003687027","pt":1580611250143,"mc":[{"id":"1.168135786","rc":[{"batl":[[0,1.52,15.72],[1,1.53,1886.98],[2,1.76,1.26]],"ltp":1.5,"tv":1571.7,"id":2249229}]}]}
{"op":"mcm","clk":"1003687094","pt":1580611251024,"mc":[{"id":"1.168135786","rc":[{"batl":[[1,1.53,9.68]],"ltp":1.5,"tv":1571.7,"id":2249229}]}]}
{"op":"mcm","clk":"1003687161","pt":1580611252259,"mc":[{"id":"1.168135786","rc":[{"batl":[[0,1.53,9.68],[1,1.76,1.26],[2,1.82,1.26]],"ltp":1.5,"tv":1571.7,"id":2249229}]}]}
{"op":"mcm","clk":"1003687284","pt":1580611253546,"mc":[{"id":"1.168135786","rc":[{"batl":[[0,1.53,1886.98]],"ltp":1.5,"tv":1571.7,"id":2249229}]}]}
{"op":"mcm","clk":"1003689858","pt":1580611297611,"mc":[{"id":"1.168135786","rc":[{"batl":[[0,3,77.91]],"ltp":3.0,"tv":414.07,"id":5720747}]}]}
{"op":"mcm","clk":"1003689929","pt":1580611298687,"mc":[{"id":"1.168135786","rc":[{"batl":[[0,1.52,15.72],[1,1.53,9.68],[2,1.76,1.26]],"ltp":1.5,"tv":1571.7,"id":2249229}]}]}
{"op":"mcm","clk":"1003690036","pt":1580611300532,"mc":[{"id":"1.168135786","rc":[{"batl":[[0,1.53,1886.98],[1,1.76,1.26],[2,1.82,1.26]],"ltp":1.5,"tv":1571.7,"id":2249229}]}]}
{"op":"mcm","clk":"1003693015","pt":1580611347686,"mc":[{"id":"1.168135786","rc":[{"batl":[[0,1.52,15.72],[1,1.53,1886.98],[2,1.76,1.26]],"ltp":1.5,"tv":1571.7,"id":2249229}]}]}
{"op":"mcm","clk":"1003693170","pt":1580611349573,"mc":[{"id":"1.168135786","rc":[{"batl":[[1,1.53,9.68]],"ltp":1.5,"tv":1571.7,"id":2249229}]}]}
{"op":"mcm","clk":"1003693284","pt":1580611350783,"mc":[{"id":"1.168135786","rc":[{"batl":[[0,1.53,1886.98],[1,1.76,1.26],[2,1.82,1.26]],"ltp":1.5,"tv":1571.7,"id":2249229}]}]}
{"op":"mcm","clk":"1003693904","pt":1580611361299,"mc":[{"id":"1.168135786","rc":[{"trd":[[1.5,171.23]],"ltp":1.5,"tv":1727.2,"id":2249229},{"trd":[[3,168.31]],"batl":[[0,3,0.08]],"ltp":3.0,"tv":491.9,"id":5720747}],"tv":2219.1}]}
{"op":"mcm","clk":"1003693991","pt":1580611362793,"mc":[{"id":"1.168135786","rc":[{"batl":[[0,3.4,8.48]],"ltp":3.0,"tv":491.9,"id":5720747}]}]}
{"op":"mcm","clk":"1003694009","pt":1580611363100,"mc":[{"id":"1.168135786","rc":[{"batb":[[0,1.44,2101.43],[1,1.43,14],[2,1.42,180.3]],"ltp":1.5,"tv":1727.2,"id":2249229}]}]}
{"op":"mcm","clk":"1003694106","pt":1580611364695,"mc":[{"id":"1.168135786","rc":[{"batb":[[0,1.43,14.01],[1,1.42,180.3],[2,1.41,363]],"ltp":1.5,"tv":1727.2,"id":2249229},{"batl":[[0,3.25,8.48]],"ltp":3.0,"tv":491.9,"id":5720747}]}]}
{"op":"mcm","clk":"1003694120","pt":1580611364898,"mc":[{"id":"1.168135786","rc":[{"batl":[[0,3.25,939.34]],"ltp":3.0,"tv":491.9,"id":5720747}]}]}
{"op":"mcm","clk":"1003695355","pt":1580611385525,"mc":[{"id":"1.168135786","rc":[{"batb":[[2,1.49,2]],"ltp":3.0,"tv":491.9,"id":5720747}]}]}
{"op":"mcm","clk":"1003695823","pt":1580611394623,"mc":[{"id":"1.168135786","rc":[{"batl":[[0,1.52,17.28],[1,1.53,1886.98],[2,1.76,1.26]],"ltp":1.5,"tv":1727.2,"id":2249229}]}]}
{"op":"mcm","clk":"1003695872","pt":1580611394830,"mc":[{"id":"1.168135786","rc":[{"batl":[[1,1.53,9.68]],"ltp":1.5,"tv":1727.2,"id":2249229}]}]}
{"op":"mcm","clk":"1003695967","pt":1580611396421,"mc":[{"id":"1.168135786","rc":[{"batl":[[0,1.53,1886.98],[1,1.76,1.26],[2,1.82,1.26]],"ltp":1.5,"tv":1727.2,"id":2249229}]}]}
{"op":"mcm","clk":"1003696111","pt":1580611399722,"mc":[{"id":"1.168135786","rc":[{"batb":[[2,1.49,2.01]],"ltp":3.0,"tv":491.9,"id":5720747}]}]}
{"op":"mcm","clk":"1003696704","pt":1580611412049,"mc":[{"id":"1.168135786","rc":[{"batb":[[0,1.43,14.02]],"ltp":1.5,"tv":1727.2,"id":2249229},{"batb":[[2,1.02,2780.78]],"ltp":3.0,"tv":491.9,"id":5720747}]}]}
{"op":"mcm","clk":"1003698101","pt":1580611436670,"mc":[{"id":"1.168135786","rc":[{"batl":[[0,3.2,5.08],[1,3.25,8.4]],"ltp":3.0,"tv":491.9,"id":5720747}]}]}
{"op":"mcm","clk":"1003698172","pt":1580611438262,"mc":[{"id":"1.168135786","rc":[{"batl":[[1,3.25,0]],"ltp":3.0,"tv":491.9,"id":5720747}]}]}
{"op":"mcm","clk":"1003698345","pt":1580611441297,"mc":[{"id":"1.168135786","rc":[{"batl":[[0,1.52,16.04],[1,1.53,9.68],[2,1.76,1.26]],"ltp":1.5,"tv":1727.2,"id":2249229}]}]}
{"op":"mcm","clk":"1003698451","pt":1580611442791,"mc":[{"id":"1.168135786","rc":[{"batl":[[0,1.53,9.68],[1,1.76,1.26],[2,1.82,1.26]],"ltp":1.5,"tv":1727.2,"id":2249229}]}]}
{"op":"mcm","clk":"1003698465","pt":1580611442997,"mc":[{"id":"1.168135786","rc":[{"batl":[[0,1.53,1886.98]],"ltp":1.5,"tv":1727.2,"id":2249229}]}]}
{"op":"mcm","clk":"1003701044","pt":1580611487743,"mc":[{"id":"1.168135786","rc":[{"batl":[[0,1.52,17.28],[1,1.53,9.68],[2,1.76,1.26]],"ltp":1.5,"tv":1727.2,"id":2249229}]}]}
{"op":"mcm","clk":"1003701127","pt":1580611489234,"mc":[{"id":"1.168135786","rc":[{"batl":[[0,1.53,1886.98],[1,1.76,1.26],[2,1.82,1.26]],"ltp":1.5,"tv":1727.2,"id":2249229}]}]}
{"op":"mcm","clk":"1003702372","pt":1580611512788,"mc":[{"id":"1.168135786","rc":[{"batb":[[0,1.45,162.1],[1,1.43,14],[2,1.42,180.3]],"ltp":1.5,"tv":1727.2,"id":2249229}]}]}
{"op":"mcm","clk":"1003703445","pt":1580611533588,"mc":[{"id":"1.168135786","rc":[{"batl":[[0,1.52,16.16],[1,1.53,9.68],[2,1.76,1.26]],"ltp":1.5,"tv":1727.2,"id":2249229}]}]}
{"op":"mcm","clk":"1003703605","pt":1580611536313,"mc":[{"id":"1.168135786","rc":[{"batl":[[0,1.53,1886.98],[1,1.76,1.26],[2,1.82,1.26]],"ltp":1.5,"tv":1727.2,"id":2249229}]}]}
{"op":"mcm","clk":"1003706356","pt":1580611579068,"mc":[{"id":"1.168135786","rc":[{"batl":[[0,1.52,17.28],[1,1.53,9.68],[2,1.76,1.26]],"ltp":1.5,"tv":1727.2,"id":2249229}]}]}
{"op":"mcm","clk":"1003706458","pt":1580611580564,"mc":[{"id":"1.168135786","rc":[{"batl":[[0,1.53,1886.98],[1,1.76,1.26],[2,1.82,1.26]],"ltp":1.5,"tv":1727.2,"id":2249229}]}]}
{"op":"mcm","clk":"1003708985","pt":1580611623728,"mc":[{"id":"1.168135786","rc":[{"batl":[[0,1.52,16.17],[1,1.53,1886.98],[2,1.76,1.26]],"ltp":1.5,"tv":1727.2,"id":2249229}]}]}
{"op":"mcm","clk":"1003708999","pt":1580611623935,"mc":[{"id":"1.168135786","rc":[{"batl":[[1,1.53,9.68]],"ltp":1.5,"tv":1727.2,"id":2249229}]}]}
{"op":"mcm","clk":"1003709126","pt":1580611626300,"mc":[{"id":"1.168135786","rc":[{"batl":[[0,1.53,1886.98],[1,1.76,1.26],[2,1.82,1.26]],"ltp":1.5,"tv":1727.2,"id":2249229}]}]}
{"op":"mcm","clk":"1003711711","pt":1580611670500,"mc":[{"id":"1.168135786","rc":[{"batl":[[0,1.52,15.65],[1,1.53,9.68],[2,1.76,1.26]],"ltp":1.5,"tv":1727.2,"id":2249229}]}]}
{"op":"mcm","clk":"1003711795","pt":1580611671783,"mc":[{"id":"1.168135786","rc":[{"batl":[[0,1.53,9.68],[1,1.76,1.26],[2,1.82,1.26]],"ltp":1.5,"tv":1727.2,"id":2249229}]}]}
{"op":"mcm","clk":"1003711806","pt":1580611672088,"mc":[{"id":"1.168135786","rc":[{"batl":[[0,1.53,1886.98]],"ltp":1.5,"tv":1727.2,"id":2249229}]}]}
{"op":"mcm","clk":"1003714075","pt":1580611715710,"mc":[{"id":"1.168135786","rc":[{"batl":[[0,1.52,16.9],[1,1.53,9.68],[2,1.76,1.26]],"ltp":1.5,"tv":1727.2,"id":2249229}]}]}
{"op":"mcm","clk":"1003714168","pt":1580611717358,"mc":[{"id":"1.168135786","rc":[{"batl":[[0,1.53,1886.98],[1,1.76,1.26],[2,1.82,1.26]],"ltp":1.5,"tv":1727.2,"id":2249229}]}]}
{"op":"mcm","clk":"1003716489","pt":1580611760707,"mc":[{"id":"1.168135786","rc":[{"batl":[[0,1.52,16.47],[1,1.53,9.68],[2,1.76,1.26]],"ltp":1.5,"tv":1727.2,"id":2249229}]}]}
{"op":"mcm","clk":"1003716580","pt":1580611762100,"mc":[{"id":"1.168135786","rc":[{"batl":[[0,1.53,1886.98],[1,1.76,1.26],[2,1.82,1.26]],"ltp":1.5,"tv":1727.2,"id":2249229}]}]}
{"op":"mcm","clk":"1003718674","pt":1580611805142,"mc":[{"id":"1.168135786","rc":[{"batl":[[0,1.52,15.59],[1,1.53,9.68],[2,1.76,1.26]],"ltp":1.5,"tv":1727.2,"id":2249229}]}]}
{"op":"mcm","clk":"1003718756","pt":1580611806630,"mc":[{"id":"1.168135786","rc":[{"batl":[[0,1.53,9.68],[1,1.76,1.26],[2,1.82,1.26]],"ltp":1.5,"tv":1727.2,"id":2249229}]}]}
{"op":"mcm","clk":"1003718772","pt":1580611806939,"mc":[{"id":"1.168135786","rc":[{"batl":[[0,1.53,1886.98]],"ltp":1.5,"tv":1727.2,"id":2249229}]}]}
{"op":"mcm","clk":"1003720941","pt":1580611849799,"mc":[{"id":"1.168135786","rc":[{"batl":[[0,1.52,17.28],[1,1.53,1886.98],[2,1.76,1.26]],"ltp":1.5,"tv":1727.2,"id":2249229}]}]}
{"op":"mcm","clk":"1003720953","pt":1580611850002,"mc":[{"id":"1.168135786","rc":[{"batl":[[1,1.53,9.68]],"ltp":1.5,"tv":1727.2,"id":2249229}]}]}
{"op":"mcm","clk":"1003721010","pt":1580611851091,"mc":[{"id":"1.168135786","rc":[{"batl":[[0,1.53,9.68],[1,1.76,1.26],[2,1.82,1.26]],"ltp":1.5,"tv":1727.2,"id":2249229}]}]}
{"op":"mcm","clk":"1003721057","pt":1580611852320,"mc":[{"id":"1.168135786","rc":[{"batl":[[0,1.53,1886.98]],"ltp":1.5,"tv":1727.2,"id":2249229}]}]}
{"op":"mcm","clk":"1003723335","pt":1580611894544,"mc":[{"id":"1.168135786","rc":[{"batl":[[0,1.52,16.05],[1,1.53,1886.98],[2,1.76,1.26]],"ltp":1.5,"tv":1727.2,"id":2249229}]}]}
{"op":"mcm","clk":"1003723385","pt":1580611895268,"mc":[{"id":"1.168135786","rc":[{"batl":[[1,1.53,9.68]],"ltp":1.5,"tv":1727.2,"id":2249229}]}]}
{"op":"mcm","clk":"1003723459","pt":1580611896555,"mc":[{"id":"1.168135786","rc":[{"batl":[[0,1.53,9.68],[1,1.76,1.26],[2,1.82,1.26]],"ltp":1.5,"tv":1727.2,"id":2249229}]}]}
{"op":"mcm","clk":"1003723543","pt":1580611898244,"mc":[{"id":"1.168135786","rc":[{"batl":[[0,1.53,1886.98]],"ltp":1.5,"tv":1727.2,"id":2249229}]}]}
{"op":"mcm","clk":"1003725710","pt":1580611937338,"mc":[{"id":"1.168135786","rc":[{"batl":[[0,1.52,15.96],[1,1.53,9.68],[2,1.76,1.26]],"ltp":1.5,"tv":1727.2,"id":2249229}]}]}
{"op":"mcm","clk":"1003725803","pt":1580611938735,"mc":[{"id":"1.168135786","rc":[{"batl":[[0,1.53,9.68],[1,1.76,1.26],[2,1.82,1.26]],"ltp":1.5,"tv":1727.2,"id":2249229}]}]}
{"op":"mcm","clk":"1003725815","pt":1580611938939,"mc":[{"id":"1.168135786","rc":[{"batl":[[0,1.53,1886.98]],"ltp":1.5,"tv":1727.2,"id":2249229}]}]}
{"op":"mcm","clk":"1003728268","pt":1580611981476,"mc":[{"id":"1.168135786","rc":[{"batl":[[0,1.52,15.89],[1,1.53,9.68],[2,1.76,1.26]],"ltp":1.5,"tv":1727.2,"id":2249229}]}]}
{"op":"mcm","clk":"1003728356","pt":1580611982659,"mc":[{"id":"1.168135786","rc":[{"batl":[[0,1.53,9.68],[1,1.76,1.26],[2,1.82,1.26]],"ltp":1.5,"tv":1727.2,"id":2249229}]}]}
{"op":"mcm","clk":"1003728370","pt":1580611982864,"mc":[{"id":"1.168135786","rc":[{"batl":[[0,1.53,1886.98]],"ltp":1.5,"tv":1727.2,"id":2249229}]}]}
{"op":"mcm","clk":"1003730973","pt":1580612025331,"mc":[{"id":"1.168135786","rc":[{"batl":[[0,1.52,16.49],[1,1.53,9.68],[2,1.76,1.26]],"ltp":1.5,"tv":1727.2,"id":2249229}]}]}
{"op":"mcm","clk":"1003731069","pt":1580612027039,"mc":[{"id":"1.168135786","rc":[{"batl":[[0,1.53,1886.98],[1,1.76,1.26],[2,1.82,1.26]],"ltp":1.5,"tv":1727.2,"id":2249229}]}]}
{"op":"mcm","clk":"1003733647","pt":1580612067725,"mc":[{"id":"1.168135786","rc":[{"batl":[[0,1.52,17.28],[1,1.53,1886.98],[2,1.76,1.26]],"ltp":1.5,"tv":1727.2,"id":2249229}]}]}
{"op":"mcm","clk":"1003733665","pt":1580612067979,"mc":[{"id":"1.168135786","rc":[{"batl":[[1,1.53,9.68]],"ltp":1.5,"tv":1727.2,"id":2249229}]}]}
{"op":"mcm","clk":"1003733760","pt":1580612069528,"mc":[{"id":"1.168135786","rc":[{"batl":[[0,1.53,1886.98],[1,1.76,1.26],[2,1.82,1.26]],"ltp":1.5,"tv":1727.2,"id":2249229}]}]}
{"op":"mcm","clk":"1003736380","pt":1580612110255,"mc":[{"id":"1.168135786","rc":[{"batl":[[0,1.52,17.28],[1,1.53,9.68],[2,1.76,1.26]],"ltp":1.5,"tv":1727.2,"id":2249229}]}]}
{"op":"mcm","clk":"1003736464","pt":1580612111544,"mc":[{"id":"1.168135786","rc":[{"batl":[[0,1.53,1886.98],[1,1.76,1.26],[2,1.82,1.26]],"ltp":1.5,"tv":1727.2,"id":2249229}]}]}
{"op":"mcm","clk":"1003739312","pt":1580612153521,"mc":[{"id":"1.168135786","rc":[{"batl":[[0,1.52,17.28],[1,1.53,9.68],[2,1.76,1.26]],"ltp":1.5,"tv":1727.2,"id":2249229}]}]}
{"op":"mcm","clk":"1003739411","pt":1580612154751,"mc":[{"id":"1.168135786","rc":[{"batl":[[0,1.53,9.68],[1,1.76,1.26],[2,1.82,1.26]],"ltp":1.5,"tv":1727.2,"id":2249229}]}]}
{"op":"mcm","clk":"1003739430","pt":1580612154908,"mc":[{"id":"1.168135786","rc":[{"batl":[[0,1.53,1886.98]],"ltp":1.5,"tv":1727.2,"id":2249229}]}]}
{"op":"mcm","clk":"1003742271","pt":1580612195667,"mc":[{"id":"1.168135786","rc":[{"batl":[[0,1.52,17.22],[1,1.53,1886.98],[2,1.76,1.26]],"ltp":1.5,"tv":1727.2,"id":2249229}]}]}
{"op":"mcm","clk":"1003742290","pt":1580612195876,"mc":[{"id":"1.168135786","rc":[{"batl":[[1,1.53,9.68]],"ltp":1.5,"tv":1727.2,"id":2249229}]}]}
{"op":"mcm","clk":"1003742422","pt":1580612197575,"mc":[{"id":"1.168135786","rc":[{"batl":[[0,1.53,9.68],[1,1.76,1.26],[2,1.82,1.26]],"ltp":1.5,"tv":1727.2,"id":2249229}]}]}
{"op":"mcm","clk":"1003742449","pt":1580612197882,"mc":[{"id":"1.168135786","rc":[{"batl":[[0,1.53,1886.98]],"ltp":1.5,"tv":1727.2,"id":2249229}]}]}
{"op":"mcm","clk":"1003744984","pt":1580612238228,"mc":[{"id":"1.168135786","rc":[{"batl":[[0,1.52,17.28],[1,1.53,9.68],[2,1.76,1.26]],"ltp":1.5,"tv":1727.2,"id":2249229}]}]}
{"op":"mcm","clk":"1003745067","pt":1580612239615,"mc":[{"id":"1.168135786","rc":[{"batl":[[0,1.53,1886.98],[1,1.76,1.26],[2,1.82,1.26]],"ltp":1.5,"tv":1727.2,"id":2249229}]}]}
{"op":"mcm","clk":"1003747182","pt":1580612279707,"mc":[{"id":"1.168135786","rc":[{"batl":[[0,1.52,17.28],[1,1.53,1886.98],[2,1.76,1.26]],"ltp":1.5,"tv":1727.2,"id":2249229}]}]}
{"op":"mcm","clk":"1003747193","pt":1580612279861,"mc":[{"id":"1.168135786","rc":[{"batl":[[1,1.53,9.68]],"ltp":1.5,"tv":1727.2,"id":2249229}]}]}
{"op":"mcm","clk":"1003747270","pt":1580612281398,"mc":[{"id":"1.168135786","rc":[{"batl":[[0,1.53,1886.98],[1,1.76,1.26],[2,1.82,1.26]],"ltp":1.5,"tv":1727.2,"id":2249229}]}]}
{"op":"mcm","clk":"1003749514","pt":1580612321551,"mc":[{"id":"1.168135786","rc":[{"batl":[[0,1.52,17.2],[1,1.53,9.68],[2,1.76,1.26]],"ltp":1.5,"tv":1727.2,"id":2249229}]}]}
{"op":"mcm","clk":"1003749593","pt":1580612322783,"mc":[{"id":"1.168135786","rc":[{"batl":[[0,1.53,9.68],[1,1.76,1.26],[2,1.82,1.26]],"ltp":1.5,"tv":1727.2,"id":2249229}]}]}
{"op":"mcm","clk":"1003749610","pt":1580612322941,"mc":[{"id":"1.168135786","rc":[{"batl":[[0,1.53,1886.98]],"ltp":1.5,"tv":1727.2,"id":2249229}]}]}
{"op":"mcm","clk":"1003752191","pt":1580612361794,"mc":[{"id":"1.168135786","rc":[{"batl":[[0,1.52,17.28],[1,1.53,1886.98],[2,1.76,1.26]],"ltp":1.5,"tv":1727.2,"id":2249229}]}]}
{"op":"mcm","clk":"1003752204","pt":1580612362001,"mc":[{"id":"1.168135786","rc":[{"batl":[[1,1.53,9.68]],"ltp":1.5,"tv":1727.2,"id":2249229}]}]}
{"op":"mcm","clk":"1003752294","pt":1580612363285,"mc":[{"id":"1.168135786","rc":[{"batl":[[0,1.53,1886.98],[1,1.76,1.26],[2,1.82,1.26]],"ltp":1.5,"tv":1727.2,"id":2249229}]}]}
{"op":"mcm","clk":"1003755496","pt":1580612409260,"mc":[{"id":"1.168135786","rc":[{"batl":[[0,1.52,17.28],[1,1.53,9.68],[2,1.76,1.26]],"ltp":1.5,"tv":1727.2,"id":2249229}]}]}
{"op":"mcm","clk":"1003755579","pt":1580612410346,"mc":[{"id":"1.168135786","rc":[{"batl":[[0,1.53,1886.98],[1,1.76,1.26],[2,1.82,1.26]],"ltp":1.5,"tv":1727.2,"id":2249229}]}]}
{"op":"mcm","clk":"1003756573","pt":1580612426678,"mc":[{"id":"1.168135786","rc":[{"batl":[[0,1.52,16.51],[1,1.53,1886.98],[2,1.76,1.26]],"ltp":1.5,"tv":1727.2,"id":2249229}]}]}
{"op":"mcm","clk":"1003756590","pt":1580612426986,"mc":[{"id":"1.168135786","rc":[{"batl":[[1,1.53,9.68]],"ltp":1.5,"tv":1727.2,"id":2249229}]}]}
{"op":"mcm","clk":"1003756664","pt":1580612428374,"mc":[{"id":"1.168135786","rc":[{"batl":[[0,1.53,1886.98],[1,1.76,1.26],[2,1.82,1.26]],"ltp":1.5,"tv":1727.2,"id":2249229}]}]}
{"op":"mcm","clk":"1003758364","pt":1580612454744,"mc":[{"id":"1.168135786","rc":[{"batl":[[0,1.52,17.01],[1,1.53,9.68],[2,1.76,1.26]],"ltp":1.5,"tv":1727.2,"id":2249229}]}]}
{"op":"mcm","clk":"1003758488","pt":1580612456243,"mc":[{"id":"1.168135786","rc":[{"batl":[[0,1.53,1886.98],[1,1.76,1.26],[2,1.82,1.26]],"ltp":1.5,"tv":1727.2,"id":2249229}]}]}
{"op":"mcm","clk":"1003759877","pt":1580612477267,"mc":[{"id":"1.168135786","rc":[{"batl":[[0,1.52,17.22],[1,1.53,9.68],[2,1.76,1.26]],"ltp":1.5,"tv":1727.2,"id":2249229}]}]}
{"op":"mcm","clk":"1003759986","pt":1580612478654,"mc":[{"id":"1.168135786","rc":[{"batl":[[0,1.53,9.68],[1,1.76,1.26],[2,1.82,1.26]],"ltp":1.5,"tv":1727.2,"id":2249229}]}]}
{"op":"mcm","clk":"1003759997","pt":1580612478859,"mc":[{"id":"1.168135786","rc":[{"batl":[[0,1.53,1886.98]],"ltp":1.5,"tv":1727.2,"id":2249229}]}]}
{"op":"mcm","clk":"1003761794","pt":1580612504690,"mc":[{"id":"1.168135786","rc":[{"batl":[[0,1.52,17.28],[1,1.53,9.68],[2,1.76,1.26]],"ltp":1.5,"tv":1727.2,"id":2249229}]}]}
{"op":"mcm","clk":"1003761875","pt":1580612505808,"mc":[{"id":"1.168135786","rc":[{"batl":[[0,1.53,9.68],[1,1.76,1.26],[2,1.82,1.26]],"ltp":1.5,"tv":1727.2,"id":2249229}]}]}
{"op":"mcm","clk":"1003761892","pt":1580612506017,"mc":[{"id":"1.168135786","rc":[{"batl":[[0,1.53,1886.98]],"ltp":1.5,"tv":1727.2,"id":2249229}]}]}
{"op":"mcm","clk":"1003764132","pt":1580612537650,"mc":[{"id":"1.168135786","rc":[{"batl":[[0,1.52,17.28],[1,1.53,9.68],[2,1.76,1.26]],"ltp":1.5,"tv":1727.2,"id":2249229}]}]}
{"op":"mcm","clk":"1003764239","pt":1580612539246,"mc":[{"id":"1.168135786","rc":[{"batl":[[0,1.53,1886.98],[1,1.76,1.26],[2,1.82,1.26]],"ltp":1.5,"tv":1727.2,"id":2249229}]}]}
{"op":"mcm","clk":"1003766665","pt":1580612577494,"mc":[{"id":"1.168135786","rc":[{"batl":[[0,1.52,17.28],[1,1.53,9.68],[2,1.76,1.26]],"ltp":1.5,"tv":1727.2,"id":2249229}]}]}
{"op":"mcm","clk":"1003766776","pt":1580612579398,"mc":[{"id":"1.168135786","rc":[{"batl":[[0,1.53,1886.98],[1,1.76,1.26],[2,1.82,1.26]],"ltp":1.5,"tv":1727.2,"id":2249229}]}]}
{"op":"mcm","clk":"1003768299","pt":1580612609114,"mc":[{"id":"1.168135786","rc":[{"batl":[[0,1.52,17.28],[1,1.53,9.68],[2,1.76,1.26]],"ltp":1.5,"tv":1727.2,"id":2249229}]}]}
{"op":"mcm","clk":"1003768388","pt":1580612610601,"mc":[{"id":"1.168135786","rc":[{"batl":[[0,1.53,1886.98],[1,1.76,1.26],[2,1.82,1.26]],"ltp":1.5,"tv":1727.2,"id":2249229}]}]}
{"op":"mcm","clk":"1003770295","pt":1580612641656,"mc":[{"id":"1.168135786","rc":[{"batl":[[0,1.52,16.68],[1,1.53,9.68],[2,1.76,1.26]],"ltp":1.5,"tv":1727.2,"id":2249229}]}]}
{"op":"mcm","clk":"1003770389","pt":1580612643254,"mc":[{"id":"1.168135786","rc":[{"batl":[[0,1.53,1886.98],[1,1.76,1.26],[2,1.82,1.26]],"ltp":1.5,"tv":1727.2,"id":2249229}]}]}
{"op":"mcm","clk":"1003770599","pt":1580612646461,"mc":[{"id":"1.168135786","rc":[{"trd":[[1.5,171.39]],"batl":[[0,1.5,8.68],[1,1.53,9.68],[2,1.76,1.26]],"ltp":1.5,"tv":1727.36,"id":2249229},{"trd":[[3,168.39]],"batl":[[0,3.2,5]],"ltp":3.0,"tv":491.98,"id":5720747}],"tv":2219.34}]}
{"op":"mcm","clk":"1003783315","pt":1580612868959,"mc":[{"id":"1.168135786","rc":[{"trd":[[1.49,0.02]],"batb":[[0,1.45,162.09]],"batl":[[0,1.49,8.67]],"ltp":1.49,"tv":1727.38,"id":2249229}],"tv":2219.36}]}
{"op":"mcm","clk":"1003784359","pt":1580612893315,"mc":[{"id":"1.168135786","rc":[{"trd":[[1.48,0.02]],"batb":[[0,1.45,162.08]],"batl":[[0,1.47,8.66]],"ltp":1.48,"tv":1727.4,"id":2249229}],"tv":2219.39}]}
{"op":"mcm","clk":"1003785476","pt":1580612926671,"mc":[{"id":"1.168135786","rc":[{"batl":[[0,1.53,1886.98],[1,1.76,1.26],[2,1.82,1.26]],"ltp":1.48,"tv":1727.4,"id":2249229}]}]}
{"op":"mcm","clk":"1003785537","pt":1580612928371,"mc":[{"id":"1.168135786","rc":[{"batl":[[0,1.52,16.38],[1,1.53,9.68],[2,1.76,1.26]],"ltp":1.48,"tv":1727.4,"id":2249229}]}]}
{"op":"mcm","clk":"1003785594","pt":1580612929660,"mc":[{"id":"1.168135786","rc":[{"batl":[[0,1.53,9.68],[1,1.76,1.26],[2,1.82,1.26]],"ltp":1.48,"tv":1727.4,"id":2249229}]}]}
{"op":"mcm","clk":"1003785603","pt":1580612929864,"mc":[{"id":"1.168135786","rc":[{"batl":[[0,1.53,1886.98]],"ltp":1.48,"tv":1727.4,"id":2249229}]}]}
{"op":"mcm","clk":"1003786299","pt":1580612949368,"mc":[{"id":"1.168135786","rc":[{"batl":[[0,1.52,16.32],[1,1.53,9.68],[2,1.76,1.26]],"ltp":1.48,"tv":1727.4,"id":2249229}]}]}
{"op":"mcm","clk":"1003786362","pt":1580612950803,"mc":[{"id":"1.168135786","rc":[{"batl":[[0,1.53,9.68],[1,1.76,1.26],[2,1.82,1.26]],"ltp":1.48,"tv":1727.4,"id":2249229}]}]}
{"op":"mcm","clk":"1003786369","pt":1580612951011,"mc":[{"id":"1.168135786","rc":[{"batl":[[0,1.53,1886.98]],"ltp":1.48,"tv":1727.4,"id":2249229}]}]}
{"op":"mcm","clk":"1003787259","pt":1580612971048,"mc":[{"id":"1.168135786","rc":[{"batl":[[0,1.52,16.17],[1,1.53,9.68],[2,1.76,1.26]],"ltp":1.48,"tv":1727.4,"id":2249229}]}]}
{"op":"mcm","clk":"1003787358","pt":1580612972817,"mc":[{"id":"1.168135786","rc":[{"batl":[[0,1.53,1886.98],[1,1.76,1.26],[2,1.82,1.26]],"ltp":1.48,"tv":1727.4,"id":2249229}]}]}
{"op":"mcm","clk":"1003787423","pt":1580612974306,"mc":[{"id":"1.168135786","rc":[{"batl":[[0,1.47,8.66],[1,1.53,9.68],[2,1.76,1.26]],"ltp":1.48,"tv":1727.4,"id":2249229}]}]}
{"op":"mcm","clk":"1003788001","pt":1580612990167,"mc":[{"id":"1.168135786","rc":[{"batl":[[0,1.46,8.66]],"ltp":1.48,"tv":1727.4,"id":2249229}]}]}
{"op":"mcm","clk":"1003788480","pt":1580613005298,"mc":[{"id":"1.168135786","rc":[{"trd":[[1.45,118.67]],"batb":[[0,1.45,153.42]],"batl":[[0,1.53,1886.98],[1,1.76,1.26],[2,1.82,1.26]],"ltp":1.45,"tv":1744.72,"id":2249229}],"tv":2236.71}]}
{"op":"mcm","clk":"1003788533","pt":1580613006488,"mc":[{"id":"1.168135786","rc":[{"batl":[[0,1.52,15.73],[1,1.53,9.68],[2,1.76,1.26]],"ltp":1.45,"tv":1744.72,"id":2249229}]}]}
{"op":"mcm","clk":"1003788561","pt":1580613007704,"mc":[{"id":"1.168135786","rc":[{"batl":[[0,1.53,9.68],[1,1.76,1.26],[2,1.82,1.26]],"ltp":1.45,"tv":1744.72,"id":2249229}]}]}
{"op":"mcm","clk":"1003788567","pt":1580613007891,"mc":[{"id":"1.168135786","rc":[{"batl":[[0,1.53,1886.98]],"ltp":1.45,"tv":1744.72,"id":2249229}]}]}
{"op":"mcm","clk":"1003789247","pt":1580613028728,"mc":[{"id":"1.168135786","rc":[{"batl":[[0,1.52,16.85],[1,1.53,1886.98],[2,1.76,1.26]],"ltp":1.45,"tv":1744.72,"id":2249229}]}]}
{"op":"mcm","clk":"1003789257","pt":1580613029036,"mc":[{"id":"1.168135786","rc":[{"batl":[[1,1.53,9.68]],"ltp":1.45,"tv":1744.72,"id":2249229}]}]}
{"op":"mcm","clk":"1003789298","pt":1580613030533,"mc":[{"id":"1.168135786","rc":[{"batl":[[0,1.53,1886.98],[1,1.76,1.26],[2,1.82,1.26]],"ltp":1.45,"tv":1744.72,"id":2249229}]}]}
{"op":"mcm","clk":"1003790029","pt":1580613052777,"mc":[{"id":"1.168135786","rc":[{"batl":[[0,1.52,17.01],[1,1.53,1886.98],[2,1.76,1.26]],"ltp":1.45,"tv":1744.72,"id":2249229}]}]}
{"op":"mcm","clk":"1003790040","pt":1580613052982,"mc":[{"id":"1.168135786","rc":[{"batl":[[1,1.53,9.68]],"ltp":1.45,"tv":1744.72,"id":2249229}]}]}
{"op":"mcm","clk":"1003790105","pt":1580613054168,"mc":[{"id":"1.168135786","rc":[{"batl":[[0,1.53,1886.98],[1,1.76,1.26],[2,1.82,1.26]],"ltp":1.45,"tv":1744.72,"id":2249229}]}]}
{"op":"mcm","clk":"1003790832","pt":1580613074727,"mc":[{"id":"1.168135786","rc":[{"batl":[[0,1.52,16.48],[1,1.53,1886.98],[2,1.76,1.26]],"ltp":1.45,"tv":1744.72,"id":2249229}]}]}
{"op":"mcm","clk":"1003790845","pt":1580613074933,"mc":[{"id":"1.168135786","rc":[{"batl":[[1,1.53,9.68]],"ltp":1.45,"tv":1744.72,"id":2249229}]}]}
{"op":"mcm","clk":"1003790899","pt":1580613076227,"mc":[{"id":"1.168135786","rc":[{"batl":[[0,1.53,1886.98],[1,1.76,1.26],[2,1.82,1.26]],"ltp":1.45,"tv":1744.72,"id":2249229}]}]}
{"op":"mcm","clk":"1003791728","pt":1580613098467,"mc":[{"id":"1.168135786","rc":[{"batl":[[0,1.52,15.8],[1,1.53,9.68],[2,1.76,1.26]],"ltp":1.45,"tv":1744.72,"id":2249229}]}]}
{"op":"mcm","clk":"1003791810","pt":1580613100684,"mc":[{"id":"1.168135786","rc":[{"batl":[[0,1.53,1886.98],[1,1.76,1.26],[2,1.82,1.26]],"ltp":1.45,"tv":1744.72,"id":2249229}]}]}
{"op":"mcm","clk":"1003792599","pt":1580613120624,"mc":[{"id":"1.168135786","rc":[{"batl":[[0,1.52,17.21],[1,1.53,1886.98],[2,1.76,1.26]],"ltp":1.45,"tv":1744.72,"id":2249229}]}]}
{"op":"mcm","clk":"1003792606","pt":1580613120833,"mc":[{"id":"1.168135786","rc":[{"batl":[[1,1.53,9.68]],"ltp":1.45,"tv":1744.72,"id":2249229}]}]}
{"op":"mcm","clk":"1003792666","pt":1580613122227,"mc":[{"id":"1.168135786","rc":[{"batl":[[0,1.53,1886.98],[1,1.76,1.26],[2,1.82,1.26]],"ltp":1.45,"tv":1744.72,"id":2249229}]}]}
{"op":"mcm","clk":"1003793531","pt":1580613144175,"mc":[{"id":"1.168135786","rc":[{"batl":[[0,1.52,16.27],[1,1.53,9.68],[2,1.76,1.26]],"ltp":1.45,"tv":1744.72,"id":2249229}]}]}
{"op":"mcm","clk":"1003793584","pt":1580613145681,"mc":[{"id":"1.168135786","rc":[{"batl":[[0,1.53,1886.98],[1,1.76,1.26],[2,1.82,1.26]],"ltp":1.45,"tv":1744.72,"id":2249229}]}]}
{"op":"mcm","clk":"1003794459","pt":1580613167404,"mc":[{"id":"1.168135786","rc":[{"batl":[[0,1.52,17.45],[1,1.53,9.68],[2,1.76,1.26]],"ltp":1.45,"tv":1744.72,"id":2249229}]}]}
{"op":"mcm","clk":"1003794512","pt":1580613168591,"mc":[{"id":"1.168135786","rc":[{"batl":[[0,1.53,9.68],[1,1.76,1.26],[2,1.82,1.26]],"ltp":1.45,"tv":1744.72,"id":2249229}]}]}
{"op":"mcm","clk":"1003794526","pt":1580613168903,"mc":[{"id":"1.168135786","rc":[{"batl":[[0,1.53,1886.98]],"ltp":1.45,"tv":1744.72,"id":2249229}]}]}
{"op":"mcm","clk":"1003795382","pt":1580613189634,"mc":[{"id":"1.168135786","rc":[{"batl":[[0,1.52,16.38],[1,1.53,9.68],[2,1.76,1.26]],"ltp":1.45,"tv":1744.72,"id":2249229}]}]}
{"op":"mcm","clk":"1003795437","pt":1580613191034,"mc":[{"id":"1.168135786","rc":[{"batl":[[0,1.53,1886.98],[1,1.76,1.26],[2,1.82,1.26]],"ltp":1.45,"tv":1744.72,"id":2249229}]}]}
{"op":"mcm","clk":"1003796336","pt":1580613215173,"mc":[{"id":"1.168135786","rc":[{"batl":[[0,1.52,17.05],[1,1.53,9.68],[2,1.76,1.26]],"ltp":1.45,"tv":1744.72,"id":2249229}]}]}
{"op":"mcm","clk":"1003796404","pt":1580613216773,"mc":[{"id":"1.168135786","rc":[{"batl":[[0,1.53,1886.98],[1,1.76,1.26],[2,1.82,1.26]],"ltp":1.45,"tv":1744.72,"id":2249229}]}]}
{"op":"mcm","clk":"1003797282","pt":1580613240615,"mc":[{"id":"1.168135786","rc":[{"batl":[[0,1.52,15.7],[1,1.53,9.68],[2,1.76,1.26]],"ltp":1.45,"tv":1744.72,"id":2249229}]}]}
{"op":"mcm","clk":"1003797313","pt":1580613241701,"mc":[{"id":"1.168135786","rc":[{"batl":[[0,1.53,9.68],[1,1.76,1.26],[2,1.82,1.26]],"ltp":1.45,"tv":1744.72,"id":2249229}]}]}
{"op":"mcm","clk":"1003797325","pt":1580613242013,"mc":[{"id":"1.168135786","rc":[{"batl":[[0,1.53,1886.98]],"ltp":1.45,"tv":1744.72,"id":2249229}]}]}
{"op":"mcm","clk":"1003798169","pt":1580613265341,"mc":[{"id":"1.168135786","rc":[{"batl":[[0,1.52,16.64],[1,1.53,9.68],[2,1.76,1.26]],"ltp":1.45,"tv":1744.72,"id":2249229}]}]}
{"op":"mcm","clk":"1003798221","pt":1580613266680,"mc":[{"id":"1.168135786","rc":[{"batl":[[0,1.53,9.68],[1,1.76,1.26],[2,1.82,1.26]],"ltp":1.45,"tv":1744.72,"id":2249229}]}]}
{"op":"mcm","clk":"1003798229","pt":1580613266835,"mc":[{"id":"1.168135786","rc":[{"batl":[[0,1.53,1886.98]],"ltp":1.45,"tv":1744.72,"id":2249229}]}]}
{"op":"mcm","clk":"1003799237","pt":1580613291212,"mc":[{"id":"1.168135786","rc":[{"batl":[[0,1.52,16.61],[1,1.53,9.68],[2,1.76,1.26]],"ltp":1.45,"tv":1744.72,"id":2249229}]}]}
{"op":"mcm","clk":"1003799309","pt":1580613292813,"mc":[{"id":"1.168135786","rc":[{"batl":[[0,1.53,1886.98],[1,1.76,1.26],[2,1.82,1.26]],"ltp":1.45,"tv":1744.72,"id":2249229}]}]}
{"op":"mcm","clk":"1003800312","pt":1580613316436,"mc":[{"id":"1.168135786","rc":[{"batl":[[0,1.52,17.45],[1,1.53,9.68],[2,1.76,1.26]],"ltp":1.45,"tv":1744.72,"id":2249229}]}]}
{"op":"mcm","clk":"1003800354","pt":1580613317716,"mc":[{"id":"1.168135786","rc":[{"batl":[[0,1.53,1886.98],[1,1.76,1.26],[2,1.82,1.26]],"ltp":1.45,"tv":1744.72,"id":2249229}]}]}
{"op":"mcm","clk":"1003801395","pt":1580613342277,"mc":[{"id":"1.168135786","rc":[{"batl":[[0,1.52,15.91],[1,1.53,9.68],[2,1.76,1.26]],"ltp":1.45,"tv":1744.72,"id":2249229}]}]}
{"op":"mcm","clk":"1003801455","pt":1580613343662,"mc":[{"id":"1.168135786","rc":[{"batl":[[0,1.53,1886.98],[1,1.76,1.26],[2,1.82,1.26]],"ltp":1.45,"tv":1744.72,"id":2249229}]}]}
{"op":"mcm","clk":"1003802333","pt":1580613367700,"mc":[{"id":"1.168135786","rc":[{"batl":[[0,1.52,16.82],[1,1.53,9.68],[2,1.76,1.26]],"ltp":1.45,"tv":1744.72,"id":2249229}]}]}
{"op":"mcm","clk":"1003802383","pt":1580613368787,"mc":[{"id":"1.168135786","rc":[{"batl":[[0,1.53,9.68],[1,1.76,1.26],[2,1.82,1.26]],"ltp":1.45,"tv":1744.72,"id":2249229}]}]}
{"op":"mcm","clk":"1003802391","pt":1580613368989,"mc":[{"id":"1.168135786","rc":[{"batl":[[0,1.53,1886.98]],"ltp":1.45,"tv":1744.72,"id":2249229}]}]}
{"op":"mcm","clk":"1003803276","pt":1580613393670,"mc":[{"id":"1.168135786","rc":[{"batl":[[0,1.52,17.06],[1,1.53,1886.98],[2,1.76,1.26]],"ltp":1.45,"tv":1744.72,"id":2249229}]}]}
{"op":"mcm","clk":"1003803282","pt":1580613393830,"mc":[{"id":"1.168135786","rc":[{"batl":[[1,1.53,9.68]],"ltp":1.45,"tv":1744.72,"id":2249229}]}]}
{"op":"mcm","clk":"1003803337","pt":1580613395368,"mc":[{"id":"1.168135786","rc":[{"batl":[[0,1.53,1886.98],[1,1.76,1.26],[2,1.82,1.26]],"ltp":1.45,"tv":1744.72,"id":2249229}]}]}
{"op":"mcm","clk":"1003804480","pt":1580613421079,"mc":[{"id":"1.168135786","rc":[{"batl":[[0,1.52,17.45],[1,1.53,9.68],[2,1.76,1.26]],"ltp":1.45,"tv":1744.72,"id":2249229}]}]}
{"op":"mcm","clk":"1003804550","pt":1580613422375,"mc":[{"id":"1.168135786","rc":[{"batl":[[0,1.53,1886.98],[1,1.76,1.26],[2,1.82,1.26]],"ltp":1.45,"tv":1744.72,"id":2249229}]}]}
{"op":"mcm","clk":"1003805677","pt":1580613447619,"mc":[{"id":"1.168135786","rc":[{"batl":[[0,1.52,16.18],[1,1.53,1886.98],[2,1.76,1.26]],"ltp":1.45,"tv":1744.72,"id":2249229}]}]}
{"op":"mcm","clk":"1003805686","pt":1580613447826,"mc":[{"id":"1.168135786","rc":[{"batl":[[1,1.53,9.68]],"ltp":1.45,"tv":1744.72,"id":2249229}]}]}
{"op":"mcm","clk":"1003805745","pt":1580613449321,"mc":[{"id":"1.168135786","rc":[{"batl":[[0,1.53,1886.98],[1,1.76,1.26],[2,1.82,1.26]],"ltp":1.45,"tv":1744.72,"id":2249229}]}]}
{"op":"mcm","clk":"1003806533","pt":1580613474677,"mc":[{"id":"1.168135786","rc":[{"batl":[[0,1.52,16.82],[1,1.53,9.68],[2,1.76,1.26]],"ltp":1.45,"tv":1744.72,"id":2249229}]}]}
{"op":"mcm","clk":"1003806598","pt":1580613476381,"mc":[{"id":"1.168135786","rc":[{"batl":[[0,1.53,1886.98],[1,1.76,1.26],[2,1.82,1.26]],"ltp":1.45,"tv":1744.72,"id":2249229}]}]}
{"op":"mcm","clk":"1003807383","pt":1580613500592,"mc":[{"id":"1.168135786","rc":[{"batl":[[0,1.52,17.45],[1,1.53,9.68],[2,1.76,1.26]],"ltp":1.45,"tv":1744.72,"id":2249229}]}]}
{"op":"mcm","clk":"1003807444","pt":1580613502295,"mc":[{"id":"1.168135786","rc":[{"batl":[[0,1.53,1886.98],[1,1.76,1.26],[2,1.82,1.26]],"ltp":1.45,"tv":1744.72,"id":2249229}]}]}
{"op":"mcm","clk":"1003808173","pt":1580613526943,"mc":[{"id":"1.168135786","rc":[{"batl":[[0,1.52,15.64],[1,1.53,9.68],[2,1.76,1.26]],"ltp":1.45,"tv":1744.72,"id":2249229}]}]}
{"op":"mcm","clk":"1003808227","pt":1580613528540,"mc":[{"id":"1.168135786","rc":[{"batl":[[0,1.53,1886.98],[1,1.76,1.26],[2,1.82,1.26]],"ltp":1.45,"tv":1744.72,"id":2249229}]}]}
{"op":"mcm","clk":"1003809121","pt":1580613553375,"mc":[{"id":"1.168135786","rc":[{"batl":[[0,1.52,17.28],[1,1.53,9.68],[2,1.76,1.26]],"ltp":1.45,"tv":1744.72,"id":2249229}]}]}
{"op":"mcm","clk":"1003809159","pt":1580613554562,"mc":[{"id":"1.168135786","rc":[{"batl":[[0,1.53,9.68],[1,1.76,1.26],[2,1.82,1.26]],"ltp":1.45,"tv":1744.72,"id":2249229}]}]}
{"op":"mcm","clk":"1003809166","pt":1580613554868,"mc":[{"id":"1.168135786","rc":[{"batl":[[0,1.53,1886.98]],"ltp":1.45,"tv":1744.72,"id":2249229}]}]}
{"op":"mcm","clk":"1003810032","pt":1580613579744,"mc":[{"id":"1.168135786","rc":[{"batl":[[0,1.52,17.45],[1,1.53,9.68],[2,1.76,1.26]],"ltp":1.45,"tv":1744.72,"id":2249229}]}]}
{"op":"mcm","clk":"1003810088","pt":1580613581344,"mc":[{"id":"1.168135786","rc":[{"batl":[[0,1.53,1886.98],[1,1.76,1.26],[2,1.82,1.26]],"ltp":1.45,"tv":1744.72,"id":2249229}]}]}
{"op":"mcm","clk":"1003810971","pt":1580613604752,"mc":[{"id":"1.168135786","rc":[{"batl":[[0,1.52,16.97],[1,1.53,1886.98],[2,1.76,1.26]],"ltp":1.45,"tv":1744.72,"id":2249229}]}]}
{"op":"mcm","clk":"1003810977","pt":1580613604957,"mc":[{"id":"1.168135786","rc":[{"batl":[[1,1.53,9.68]],"ltp":1.45,"tv":1744.72,"id":2249229}]}]}
{"op":"mcm","clk":"1003811025","pt":1580613606350,"mc":[{"id":"1.168135786","rc":[{"batl":[[0,1.53,1886.98],[1,1.76,1.26],[2,1.82,1.26]],"ltp":1.45,"tv":1744.72,"id":2249229}]}]}
{"op":"mcm","clk":"1003811956","pt":1580613631156,"mc":[{"id":"1.168135786","rc":[{"batl":[[0,1.52,16.75],[1,1.53,9.68],[2,1.76,1.26]],"ltp":1.45,"tv":1744.72,"id":2249229}]}]}
{"op":"mcm","clk":"1003812009","pt":1580613632594,"mc":[{"id":"1.168135786","rc":[{"batl":[[0,1.53,1886.98],[1,1.76,1.26],[2,1.82,1.26]],"ltp":1.45,"tv":1744.72,"id":2249229}]}]}
{"op":"mcm","clk":"1003812972","pt":1580613656804,"mc":[{"id":"1.168135786","rc":[{"batl":[[0,1.52,17.45],[1,1.53,1886.98],[2,1.76,1.26]],"ltp":1.45,"tv":1744.72,"id":2249229}]}]}
{"op":"mcm","clk":"1003813013","pt":1580613657733,"mc":[{"id":"1.168135786","rc":[{"batl":[[0,1.53,9.68],[1,1.76,1.26],[2,1.82,1.26]],"ltp":1.45,"tv":1744.72,"id":2249229}]}]}
{"op":"mcm","clk":"1003813031","pt":1580613657992,"mc":[{"id":"1.168135786","rc":[{"batl":[[0,1.53,1886.98]],"ltp":1.45,"tv":1744.72,"id":2249229}]}]}
{"op":"mcm","clk":"1003813949","pt":1580613682763,"mc":[{"id":"1.168135786","rc":[{"batl":[[0,1.52,16.02],[1,1.53,9.68],[2,1.76,1.26]],"ltp":1.45,"tv":1744.72,"id":2249229}]}]}
{"op":"mcm","clk":"1003813991","pt":1580613683744,"mc":[{"id":"1.168135786","rc":[{"batl":[[0,1.53,9.68],[1,1.76,1.26],[2,1.82,1.26]],"ltp":1.45,"tv":1744.72,"id":2249229}]}]}
{"op":"mcm","clk":"1003813999","pt":1580613683949,"mc":[{"id":"1.168135786","rc":[{"batl":[[0,1.53,1886.98]],"ltp":1.45,"tv":1744.72,"id":2249229}]}]}
{"op":"mcm","clk":"1003814916","pt":1580613708392,"mc":[{"id":"1.168135786","rc":[{"batl":[[0,1.52,16.69],[1,1.53,9.68],[2,1.76,1.26]],"ltp":1.45,"tv":1744.72,"id":2249229}]}]}
{"op":"mcm","clk":"1003814975","pt":1580613709755,"mc":[{"id":"1.168135786","rc":[{"batl":[[0,1.53,1886.98],[1,1.76,1.26],[2,1.82,1.26]],"ltp":1.45,"tv":1744.72,"id":2249229}]}]}
{"op":"mcm","clk":"1003815844","pt":1580613733714,"mc":[{"id":"1.168135786","rc":[{"batl":[[0,1.52,17.45],[1,1.53,9.68],[2,1.76,1.26]],"ltp":1.45,"tv":1744.72,"id":2249229}]}]}
{"op":"mcm","clk":"1003815878","pt":1580613734696,"mc":[{"id":"1.168135786","rc":[{"batl":[[0,1.53,9.68],[1,1.76,1.26],[2,1.82,1.26]],"ltp":1.45,"tv":1744.72,"id":2249229}]}]}
{"op":"mcm","clk":"1003815903","pt":1580613735517,"mc":[{"id":"1.168135786","rc":[{"batl":[[0,1.53,1886.98]],"ltp":1.45,"tv":1744.72,"id":2249229}]}]}
{"op":"mcm","clk":"1003816890","pt":1580613759721,"mc":[{"id":"1.168135786","rc":[{"batl":[[0,1.52,17.45],[1,1.53,1886.98],[2,1.76,1.26]],"ltp":1.45,"tv":1744.72,"id":2249229}]}]}
{"op":"mcm","clk":"1003816898","pt":1580613759927,"mc":[{"id":"1.168135786","rc":[{"batl":[[1,1.53,9.68]],"ltp":1.45,"tv":1744.72,"id":2249229}]}]}
{"op":"mcm","clk":"1003816992","pt":1580613761528,"mc":[{"id":"1.168135786","rc":[{"batl":[[0,1.53,1886.98],[1,1.76,1.26],[2,1.82,1.26]],"ltp":1.45,"tv":1744.72,"id":2249229}]}]}
{"op":"mcm","clk":"1003818011","pt":1580613785668,"mc":[{"id":"1.168135786","rc":[{"batl":[[0,1.52,16.08],[1,1.53,1886.98],[2,1.76,1.26]],"ltp":1.45,"tv":1744.72,"id":2249229}]}]}
{"op":"mcm","clk":"1003818020","pt":1580613785872,"mc":[{"id":"1.168135786","rc":[{"batl":[[1,1.53,9.68]],"ltp":1.45,"tv":1744.72,"id":2249229}]}]}
{"op":"mcm","clk":"1003818086","pt":1580613787266,"mc":[{"id":"1.168135786","rc":[{"batl":[[0,1.53,1886.98],[1,1.76,1.26],[2,1.82,1.26]],"ltp":1.45,"tv":1744.72,"id":2249229}]}]}
{"op":"mcm","clk":"1003819323","pt":1580613812720,"mc":[{"id":"1.168135786","rc":[{"batl":[[0,1.52,15.71],[1,1.53,1886.98],[2,1.76,1.26]],"ltp":1.45,"tv":1744.72,"id":2249229}]}]}
{"op":"mcm","clk":"1003819374","pt":1580613813592,"mc":[{"id":"1.168135786","rc":[{"batl":[[1,1.53,9.68]],"ltp":1.45,"tv":1744.72,"id":2249229}]}]}
{"op":"mcm","clk":"1003819419","pt":1580613814316,"mc":[{"id":"1.168135786","rc":[{"batl":[[0,1.53,1886.98],[1,1.76,1.26],[2,1.82,1.26]],"ltp":1.45,"tv":1744.72,"id":2249229}]}]}
{"op":"mcm","clk":"1003819983","pt":1580613825618,"mc":[{"id":"1.168135786","rc":[{"batl":[[0,1.52,3.04],[1,1.53,9.68],[2,1.76,1.26]],"ltp":1.45,"tv":1744.72,"id":2249229}]}]}
{"op":"mcm","clk":"1003976875","pt":1580617423748,"mc":[{"id":"1.168135786","rc":[{"batl":[[2,1.73,1.26]],"ltp":1.45,"tv":1744.72,"id":2249229}]}]}
{"op":"mcm","clk":"1003976923","pt":1580617424675,"mc":[{"id":"1.168135786","rc":[{"batl":[[2,1.6,1.26]],"ltp":1.45,"tv":1744.72,"id":2249229}]}]}
{"op":"mcm","clk":"1003997783","pt":1580617883749,"mc":[{"id":"1.168135786","rc":[{"batl":[[0,1.52,3.46]],"ltp":1.45,"tv":1744.72,"id":2249229}]}]}
{"op":"mcm","clk":"1003997821","pt":1580617884518,"mc":[{"id":"1.168135786","rc":[{"batl":[[0,1.51,1.68],[1,1.52,3.04],[2,1.53,9.68]],"ltp":1.45,"tv":1744.72,"id":2249229}]}]}
{"op":"mcm","clk":"1003997879","pt":1580617885756,"mc":[{"id":"1.168135786","rc":[{"batl":[[1,1.52,3.46]],"ltp":1.45,"tv":1744.72,"id":2249229}]}]}
{"op":"mcm","clk":"1004010903","pt":1580618152752,"mc":[{"id":"1.168135786","rc":[{"batb":[[0,2.9,106.77],[1,2.88,48.93],[2,2.74,68.97]],"ltp":3.0,"tv":491.98,"id":5720747}]}]}
{"op":"mcm","clk":"1004010947","pt":1580618153678,"mc":[{"id":"1.168135786","rc":[{"batl":[[1,1.52,19.71]],"ltp":1.45,"tv":1744.72,"id":2249229}]}]}
{"op":"mcm","clk":"1004079857","pt":1580619799666,"mc":[{"id":"1.168135786","rc":[{"batb":[[2,1.41,363]],"ltp":1.45,"tv":1744.72,"id":2249229},{"batb":[[2,2.74,25.45]],"ltp":3.0,"tv":491.98,"id":5720747}]}]}
{"op":"mcm","clk":"1004079889","pt":1580619800386,"mc":[{"id":"1.168135786","rc":[{"batb":[[2,1.42,180.3]],"ltp":1.45,"tv":1744.72,"id":2249229},{"batb":[[2,2.74,68.97]],"ltp":3.0,"tv":491.98,"id":5720747}]}]}
{"op":"mcm","clk":"1004095836","pt":1580620218537,"mc":[{"id":"1.168135786","rc":[{"trd":[[1.45,134.4]],"batb":[[0,1.45,145.56]],"ltp":1.45,"tv":1760.45,"id":2249229}],"tv":2252.44}]}
{"op":"mcm","clk":"1004152090","pt":1580621519595,"mc":[{"id":"1.168135786","rc":[{"batb":[[2,1.41,363]],"ltp":1.45,"tv":1760.45,"id":2249229},{"batb":[[2,2.74,25.45]],"ltp":3.0,"tv":491.98,"id":5720747}]}]}
{"op":"mcm","clk":"1004152114","pt":1580621520217,"mc":[{"id":"1.168135786","rc":[{"batb":[[2,1.42,180.3]],"ltp":1.45,"tv":1760.45,"id":2249229},{"batb":[[2,2.74,68.97]],"ltp":3.0,"tv":491.98,"id":5720747}]}]}
{"op":"mcm","clk":"1004154441","pt":1580621570500,"mc":[{"id":"1.168135786","rc":[{"batb":[[2,2.74,25.45]],"ltp":3.0,"tv":491.98,"id":5720747}]}]}
{"op":"mcm","clk":"1004155072","pt":1580621586321,"mc":[{"id":"1.168135786","rc":[{"batb":[[2,1.41,363]],"ltp":1.45,"tv":1760.45,"id":2249229}]}]}
{"op":"mcm","clk":"1004155096","pt":1580621586891,"mc":[{"id":"1.168135786","rc":[{"batb":[[2,1.42,180.3]],"ltp":1.45,"tv":1760.45,"id":2249229},{"batb":[[2,2.74,68.97]],"ltp":3.0,"tv":491.98,"id":5720747}]}]}
{"op":"mcm","clk":"1004172774","pt":1580622079479,"mc":[{"id":"1.168135786","rc":[{"trd":[[1.45,185.05]],"batb":[[0,1.45,120.24]],"ltp":1.45,"tv":1811.1,"id":2249229}],"tv":2303.09}]}
{"op":"mcm","clk":"1004193415","pt":1580622696012,"mc":[{"id":"1.168135786","rc":[{"trd":[[1.51,1.68],[1.52,19.71]],"batl":[[0,1.53,9.68],[1,1.56,1.68],[2,1.6,1.26]],"ltp":1.52,"tv":1832.49,"id":2249229},{"trd":[[2.9,48.7],[2.92,10.25],[2.96,16.86]],"batb":[[0,2.9,82.42]],"ltp":2.9,"tv":551.79,"id":5720747}],"tv":2384.28}]}
{"op":"mcm","clk":"1004193467","pt":1580622697704,"mc":[{"id":"1.168135786","rc":[{"batb":[[0,1.46,8.86],[1,1.45,120.24],[2,1.43,14]],"ltp":1.52,"tv":1832.49,"id":2249229}]}]}
{"op":"mcm","clk":"1004197291","pt":1580622823734,"mc":[{"id":"1.168135786","rc":[{"batb":[[0,1.46,26.81]],"batl":[[0,1.52,17.95],[1,1.53,9.68],[2,1.56,1.68]],"ltp":1.52,"tv":1832.49,"id":2249229},{"batb":[[0,2.92,9.35],[1,2.9,82.42],[2,2.88,48.93]],"batl":[[0,3.2,13.16]],"ltp":2.9,"tv":551.79,"id":5720747}]}]}
{"op":"mcm","clk":"1004201333","pt":1580622971340,"mc":[{"id":"1.168135786","rc":[{"trd":[[1.46,464.92]],"batb":[[0,1.45,120.24],[1,1.43,14],[2,1.42,180.3]],"batl":[[0,1.46,3872.91],[1,1.52,17.95],[2,1.53,9.68]],"ltp":1.46,"tv":1886.14,"id":2249229},{"trd":[[3.2,131.37]],"batl":[[0,3.2,0.67]],"ltp":3.2,"tv":576.77,"id":5720747}],"tv":2462.91}]}
{"op":"mcm","clk":"1004201383","pt":1580622972928,"mc":[{"id":"1.168135786","rc":[{"batl":[[2,1.56,1.68]],"ltp":1.46,"tv":1886.14,"id":2249229}]}]}
{"op":"mcm","clk":"1004201541","pt":1580622977867,"mc":[{"id":"1.168135786","rc":[{"batl":[[1,1.52,17.24]],"ltp":1.46,"tv":1886.14,"id":2249229},{"batb":[[0,2.92,8.21]],"ltp":3.2,"tv":576.77,"id":5720747}]}]}
{"op":"mcm","clk":"1004202008","pt":1580622991862,"mc":[{"id":"1.168135786","rc":[{"batl":[[0,1.52,17.24],[1,1.56,1.68],[2,1.6,1.26]],"ltp":1.46,"tv":1886.14,"id":2249229}]}]}
{"op":"mcm","clk":"1004202036","pt":1580622992942,"mc":[{"id":"1.168135786","rc":[{"batl":[[0,1.52,30.73]],"ltp":1.46,"tv":1886.14,"id":2249229}]}]}
{"op":"mcm","clk":"1004203040","pt":1580623028310,"mc":[{"id":"1.168135786","rc":[{"batl":[[0,1.52,44.23]],"ltp":1.46,"tv":1886.14,"id":2249229}]}]}
{"op":"mcm","clk":"1004203748","pt":1580623058058,"mc":[{"id":"1.168135786","rc":[{"batb":[[0,2.94,8.21]],"ltp":3.2,"tv":576.77,"id":5720747}]}]}
{"op":"mcm","clk":"1004203982","pt":1580623065555,"mc":[{"id":"1.168135786","rc":[{"batb":[[0,1.46,428.59],[1,1.45,120.24],[2,1.43,14]],"ltp":1.46,"tv":1886.14,"id":2249229}]}]}
{"op":"mcm","clk":"1004204027","pt":1580623066632,"mc":[{"id":"1.168135786","rc":[{"batl":[[0,3.15,8.4]],"ltp":3.2,"tv":576.77,"id":5720747}]}]}
{"op":"mcm","clk":"1004204782","pt":1580623089977,"mc":[{"id":"1.168135786","rc":[{"batb":[[0,2.94,8.15]],"ltp":3.2,"tv":576.77,"id":5720747}]}]}
{"op":"mcm","clk":"1004205735","pt":1580623126346,"mc":[{"id":"1.168135786","rc":[{"batb":[[0,2.96,33.73],[1,2.94,8.15],[2,2.9,82.42]],"ltp":3.2,"tv":576.77,"id":5720747}]}]}
{"op":"mcm","clk":"1004209073","pt":1580623231498,"mc":[{"id":"1.168135786","rc":[{"batb":[[2,1.43,190.1]],"ltp":1.46,"tv":1886.14,"id":2249229}]}]}
{"op":"mcm","clk":"1004235340","pt":1580624087788,"mc":[{"id":"1.168135786","rc":[{"batb":[[2,1.43,14]],"ltp":1.46,"tv":1886.14,"id":2249229}]}]}
{"op":"mcm","clk":"1004235361","pt":1580624088408,"mc":[{"id":"1.168135786","rc":[{"batb":[[2,1.43,190.1]],"ltp":1.46,"tv":1886.14,"id":2249229}]}]}
{"op":"mcm","clk":"1004243401","pt":1580624343838,"mc":[{"id":"1.168135786","rc":[{"batb":[[0,2.94,8.15],[1,2.9,82.42],[2,2.88,48.93]],"ltp":3.2,"tv":576.77,"id":5720747}]}]}
{"op":"mcm","clk":"1004245701","pt":1580624413719,"mc":[{"id":"1.168135786","rc":[{"batb":[[2,1.43,14]],"ltp":1.46,"tv":1886.14,"id":2249229}]}]}
{"op":"mcm","clk":"1004245729","pt":1580624414386,"mc":[{"id":"1.168135786","rc":[{"batb":[[2,1.43,190.1]],"ltp":1.46,"tv":1886.14,"id":2249229}]}]}
{"op":"mcm","clk":"1004250655","pt":1580624556658,"mc":[{"id":"1.168135786","rc":[{"batl":[[0,1.52,94.88]],"ltp":1.46,"tv":1886.14,"id":2249229}]}]}
{"op":"mcm","clk":"1004252957","pt":1580624630769,"mc":[{"id":"1.168135786","rc":[{"batl":[[0,1.52,77.64]],"ltp":1.46,"tv":1886.14,"id":2249229},{"batb":[[0,2.9,82.42],[1,2.88,48.93],[2,2.74,25.45]],"ltp":3.2,"tv":576.77,"id":5720747}]}]}
{"op":"mcm","clk":"1004253146","pt":1580624637670,"mc":[{"id":"1.168135786","rc":[{"batl":[[0,1.51,17.36],[1,1.52,77.64],[2,1.56,1.68]],"ltp":1.46,"tv":1886.14,"id":2249229},{"batb":[[0,2.94,8.15],[1,2.9,82.42],[2,2.88,48.93]],"ltp":3.2,"tv":576.77,"id":5720747}]}]}
{"op":"mcm","clk":"1004254836","pt":1580624696720,"mc":[{"id":"1.168135786","rc":[{"batl":[[0,1.52,77.64],[1,1.56,1.68],[2,1.6,1.26]],"ltp":1.46,"tv":1886.14,"id":2249229},{"batb":[[0,2.9,82.42],[1,2.88,48.93],[2,2.74,25.45]],"ltp":3.2,"tv":576.77,"id":5720747}]}]}
{"op":"mcm","clk":"1004256859","pt":1580624759300,"mc":[{"id":"1.168135786","rc":[{"batl":[[0,3.1,25.33],[1,3.15,8.4]],"ltp":3.2,"tv":576.77,"id":5720747}]}]}
{"op":"mcm","clk":"1004259449","pt":1580624843148,"mc":[{"id":"1.168135786","rc":[{"batl":[[0,1.51,17.36],[1,1.52,77.64],[2,1.56,1.68]],"ltp":1.46,"tv":1886.14,"id":2249229},{"batb":[[0,2.94,8.15],[1,2.9,82.42],[2,2.88,48.93]],"ltp":3.2,"tv":576.77,"id":5720747}]}]}
{"op":"mcm","clk":"1004260985","pt":1580624894420,"mc":[{"id":"1.168135786","rc":[{"batl":[[0,1.52,77.64],[1,1.56,1.68],[2,1.6,1.26]],"ltp":1.46,"tv":1886.14,"id":2249229},{"batb":[[0,2.9,82.42],[1,2.88,48.93],[2,2.74,25.45]],"ltp":3.2,"tv":576.77,"id":5720747}]}]}
{"op":"mcm","clk":"1004261465","pt":1580624909449,"mc":[{"id":"1.168135786","rc":[{"batl":[[0,1.51,17.36],[1,1.52,77.64],[2,1.56,1.68]],"ltp":1.46,"tv":1886.14,"id":2249229},{"batb":[[0,2.94,8.15],[1,2.9,82.42],[2,2.88,48.93]],"ltp":3.2,"tv":576.77,"id":5720747}]}]}
{"op":"mcm","clk":"1004263633","pt":1580625000570,"mc":[{"id":"1.168135786","rc":[{"batl":[[1,1.52,64.14]],"ltp":1.46,"tv":1886.14,"id":2249229},{"batl":[[1,3.15,0]],"ltp":3.2,"tv":576.77,"id":5720747}]}]}
{"op":"mcm","clk":"1004270170","pt":1580625221443,"mc":[{"id":"1.168135786","rc":[{"batl":[[0,1.52,64.14],[1,1.56,1.68],[2,1.6,1.26]],"ltp":1.46,"tv":1886.14,"id":2249229},{"batb":[[0,2.9,82.42],[1,2.88,48.93],[2,2.74,33.93]],"ltp":3.2,"tv":576.77,"id":5720747}]}]}
{"op":"mcm","clk":"1004270865","pt":1580625241379,"mc":[{"id":"1.168135786","rc":[{"batl":[[0,1.51,17.36],[1,1.52,64.14],[2,1.56,1.68]],"ltp":1.46,"tv":1886.14,"id":2249229},{"batb":[[0,2.94,8.15],[1,2.9,82.42],[2,2.88,48.93]],"ltp":3.2,"tv":576.77,"id":5720747}]}]}
{"op":"mcm","clk":"1004283881","pt":1580625632633,"mc":[{"id":"1.168135786","rc":[{"batl":[[0,1.51,17.78]],"ltp":1.46,"tv":1886.14,"id":2249229}]}]}
{"op":"mcm","clk":"1004283906","pt":1580625633761,"mc":[{"id":"1.168135786","rc":[{"batl":[[0,1.51,18.2]],"ltp":1.46,"tv":1886.14,"id":2249229}]}]}
{"op":"mcm","clk":"1004283942","pt":1580625634736,"mc":[{"id":"1.168135786","rc":[{"batl":[[0,1.5,1.26],[1,1.51,17.78],[2,1.52,64.14]],"ltp":1.46,"tv":1886.14,"id":2249229}]}]}
{"op":"mcm","clk":"1004283967","pt":1580625635456,"mc":[{"id":"1.168135786","rc":[{"batl":[[1,1.51,18.2],[2,1.52,64.56]],"ltp":1.46,"tv":1886.14,"id":2249229}]}]}
{"op":"mcm","clk":"1004284012","pt":1580625636737,"mc":[{"id":"1.168135786","rc":[{"batl":[[2,1.52,64.98]],"ltp":1.46,"tv":1886.14,"id":2249229}]}]}
{"op":"mcm","clk":"1004287408","pt":1580625726103,"mc":[{"id":"1.168135786","rc":[{"batb":[[0,2.96,2.53],[1,2.94,8.15],[2,2.9,82.42]],"ltp":3.2,"tv":576.77,"id":5720747}]}]}
{"op":"mcm","clk":"1004289066","pt":1580625795451,"mc":[{"id":"1.168135786","rc":[{"batl":[[1,1.51,68.85],[2,1.52,14.33]],"ltp":1.46,"tv":1886.14,"id":2249229}]}]}
{"op":"mcm","clk":"1004289261","pt":1580625806065,"mc":[{"id":"1.168135786","rc":[{"batb":[[0,2.98,8.15],[1,2.96,2.53]],"ltp":3.2,"tv":576.77,"id":5720747}]}]}
{"op":"mcm","clk":"1004289287","pt":1580625806989,"mc":[{"id":"1.168135786","rc":[{"batl":[[2,1.53,1.68]],"ltp":1.46,"tv":1886.14,"id":2249229}]}]}
{"op":"mcm","clk":"1004289714","pt":1580625832118,"mc":[{"id":"1.168135786","rc":[{"batb":[[0,2.98,8.04]],"ltp":3.2,"tv":576.77,"id":5720747}]}]}
{"op":"mcm","clk":"1004290198","pt":1580625858284,"mc":[{"id":"1.168135786","rc":[{"trd":[[1.5,172.65]],"batl":[[0,1.51,68.85],[1,1.53,1.68],[2,1.55,1.26]],"ltp":1.5,"tv":1887.4,"id":2249229},{"trd":[[2.98,16.08],[3,169.02]],"batb":[[0,2.96,2.53],[1,2.9,82.42],[2,2.88,48.93]],"batl":[[0,2.98,1.46],[1,3.1,25.33]],"ltp":2.98,"tv":593.47,"id":5720747}],"tv":2480.88}]}
{"op":"mcm","clk":"1004290308","pt":1580625864476,"mc":[{"id":"1.168135786","rc":[{"batb":[[0,2.96,4.49]],"ltp":2.98,"tv":593.47,"id":5720747}]}]}
{"op":"mcm","clk":"1004291523","pt":1580625931169,"mc":[{"id":"1.168135786","rc":[{"batb":[[0,2.96,12.59]],"ltp":2.98,"tv":593.47,"id":5720747}]}]}
{"op":"mcm","clk":"1004293471","pt":1580626010009,"mc":[{"id":"1.168135786","rc":[{"trd":[[1.5,175.57]],"batl":[[0,1.5,89.97],[1,1.51,68.85],[2,1.53,1.68]],"ltp":1.5,"tv":1890.31,"id":2249229},{"trd":[[2.98,17.54]],"batl":[[0,3.1,25.33],[1,3.1,0]],"ltp":2.98,"tv":594.94,"id":5720747}],"tv":2485.25}]}
{"op":"mcm","clk":"1004293606","pt":1580626015298,"mc":[{"id":"1.168135786","rc":[{"batb":[[0,2.98,10.01],[1,2.96,2.53],[2,2.9,82.42]],"ltp":2.98,"tv":594.94,"id":5720747}]}]}
{"op":"mcm","clk":"1004293738","pt":1580626021504,"mc":[{"id":"1.168135786","rc":[{"batl":[[0,1.49,17.36],[1,1.5,89.97],[2,1.51,51.49]],"ltp":1.5,"tv":1890.31,"id":2249229}]}]}
{"op":"mcm","clk":"1004293751","pt":1580626022222,"mc":[{"id":"1.168135786","rc":[{"trd":[[1.49,34.75]],"batl":[[0,1.5,89.97],[1,1.51,117.8],[2,1.53,1.68]],"ltp":1.49,"tv":1925.05,"id":2249229}],"tv":2519.99}]}
{"op":"mcm","clk":"1004294122","pt":1580626035939,"mc":[{"id":"1.168135786","rc":[{"trd":[[3.1,38.66]],"batl":[[0,3.1,6.01]],"ltp":3.1,"tv":633.59,"id":5720747}],"tv":2558.64}]}
{"op":"mcm","clk":"1004294360","pt":1580626044768,"mc":[{"id":"1.168135786","rc":[{"batb":[[0,1.47,19.25],[1,1.46,428.59],[2,1.45,120.24]],"ltp":1.49,"tv":1925.05,"id":2249229},{"batl":[[1,3.2,9]],"ltp":3.1,"tv":633.59,"id":5720747}]}]}
{"op":"mcm","clk":"1004295362","pt":1580626079503,"mc":[{"id":"1.168135786","rc":[{"batb":[[0,3,10.01]],"ltp":3.1,"tv":633.59,"id":5720747}]}]}
{"op":"mcm","clk":"1004295663","pt":1580626091435,"mc":[{"id":"1.168135786","rc":[{"batl":[[0,1.49,19.99],[1,1.5,89.97],[2,1.51,117.8]],"ltp":1.49,"tv":1925.05,"id":2249229}]}]}
{"op":"mcm","clk":"1004322668","pt":1580626917564,"mc":[{"id":"1.168135786","rc":[{"batl":[[0,1.48,78.68],[1,1.49,19.99],[2,1.5,89.97]],"ltp":1.49,"tv":1925.05,"id":2249229}]}]}
{"op":"mcm","clk":"1004322807","pt":1580626921632,"mc":[{"id":"1.168135786","rc":[{"batb":[[0,1.46,447.84],[1,1.45,120.24],[2,1.43,190.1]],"ltp":1.49,"tv":1925.05,"id":2249229},{"batb":[[0,3.05,10.01]],"batl":[[1,1000,9]],"ltp":3.1,"tv":633.59,"id":5720747}]}]}
{"op":"mcm","clk":"1004323042","pt":1580626932762,"mc":[{"id":"1.168135786","rc":[{"batl":[[0,1.48,98.67],[1,1.5,89.97],[2,1.51,117.8]],"ltp":1.49,"tv":1925.05,"id":2249229}]}]}
{"op":"mcm","clk":"1004325727","pt":1580627036803,"mc":[{"id":"1.168135786","rc":[{"batb":[[2,1.43,14]],"ltp":1.49,"tv":1925.05,"id":2249229}]}]}
{"op":"mcm","clk":"1004325744","pt":1580627037420,"mc":[{"id":"1.168135786","rc":[{"batb":[[2,1.43,190.1]],"ltp":1.49,"tv":1925.05,"id":2249229}]}]}
{"op":"mcm","clk":"1004331097","pt":1580627199192,"mc":[{"id":"1.168135786","rc":[{"trd":[[3.1,50.67]],"batb":[[0,3.1,28.94],[1,3.05,10.01],[2,2.96,2.53]],"batl":[[0,1000,9],[1,1000,0]],"ltp":3.1,"tv":645.61,"id":5720747}],"tv":2570.66}]}
{"op":"mcm","clk":"1004331233","pt":1580627203114,"mc":[{"id":"1.168135786","rc":[{"batb":[[0,3.1,38.95],[1,2.96,2.53],[2,2.9,82.42]],"ltp":3.1,"tv":645.61,"id":5720747}]}]}
{"op":"mcm","clk":"1004337276","pt":1580627369627,"mc":[{"id":"1.168135786","rc":[{"trd":[[3.1,68.66]],"batb":[[0,3.1,29.96]],"ltp":3.1,"tv":663.6,"id":5720747}],"tv":2588.65}]}
{"op":"mcm","clk":"1004343420","pt":1580627531651,"mc":[{"id":"1.168135786","rc":[{"trd":[[3.1,114.21]],"batb":[[0,3.1,7.19],[1,2.88,48.93],[2,2.72,44.03]],"ltp":3.1,"tv":709.14,"id":5720747}],"tv":2634.19}]}
{"op":"mcm","clk":"1004343592","pt":1580627536641,"mc":[{"id":"1.168135786","rc":[{"batb":[[0,3.05,7.19],[2,2.74,33.93]],"batl":[[0,3.15,2.78],[1,1000,9]],"ltp":3.1,"tv":709.14,"id":5720747}]}]}
{"op":"mcm","clk":"1004344957","pt":1580627581612,"mc":[{"id":"1.168135786","rc":[{"batb":[[0,1.46,428.59]],"batl":[[0,1.48,78.68]],"ltp":1.49,"tv":1925.05,"id":2249229},{"batb":[[0,2.88,48.93],[1,2.74,33.93],[2,2.72,44.03]],"ltp":3.1,"tv":709.14,"id":5720747}]}]}
{"op":"mcm","clk":"1004345417","pt":1580627593515,"mc":[{"id":"1.168135786","rc":[{"batb":[[0,1.46,449.57]],"batl":[[0,1.48,96.03]],"ltp":1.49,"tv":1925.05,"id":2249229},{"batb":[[0,3.05,5.03],[1,2.88,48.93],[2,2.74,33.93]],"batl":[[0,3.15,2.78]],"ltp":3.1,"tv":709.14,"id":5720747}]}]}
{"op":"mcm","clk":"1004346594","pt":1580627625624,"mc":[{"id":"1.168135786","rc":[{"batb":[[0,3.05,7.9]],"ltp":3.1,"tv":709.14,"id":5720747}]}]}
{"op":"mcm","clk":"1004349943","pt":1580627700754,"mc":[{"id":"1.168135786","rc":[{"batb":[[0,1.46,428.59]],"batl":[[0,1.48,78.68]],"ltp":1.49,"tv":1925.05,"id":2249229},{"batb":[[0,2.88,48.93],[1,2.74,33.93],[2,2.72,44.03]],"ltp":3.1,"tv":709.14,"id":5720747}]}]}
{"op":"mcm","clk":"1004350687","pt":1580627718745,"mc":[{"id":"1.168135786","rc":[{"batb":[[0,1.46,449.67]],"batl":[[0,1.48,96.13]],"ltp":1.49,"tv":1925.05,"id":2249229},{"batb":[[0,3.05,7.95],[1,2.88,48.93],[2,2.74,33.93]],"batl":[[0,3.15,2.78]],"ltp":3.1,"tv":709.14,"id":5720747}]}]}
{"op":"mcm","clk":"1004351514","pt":1580627739172,"mc":[{"id":"1.168135786","rc":[{"batb":[[0,1.46,21.08]],"ltp":1.49,"tv":1925.05,"id":2249229}]}]}
{"op":"mcm","clk":"1004351976","pt":1580627752781,"mc":[{"id":"1.168135786","rc":[{"batb":[[0,1.45,120.24],[1,1.43,190.1],[2,1.41,363]],"ltp":1.49,"tv":1925.05,"id":2249229}]}]}
{"op":"mcm","clk":"1004351994","pt":1580627753293,"mc":[{"id":"1.168135786","rc":[{"batb":[[1,1.44,21.08],[2,1.43,190.1]],"ltp":1.49,"tv":1925.05,"id":2249229},{"batl":[[0,3.2,952.55]],"ltp":3.1,"tv":709.14,"id":5720747}]}]}
{"op":"mcm","clk":"1004352622","pt":1580627771550,"mc":[{"id":"1.168135786","rc":[{"batl":[[0,1.48,78.68],[1,1.49,17.44],[2,1.5,89.97]],"ltp":1.49,"tv":1925.05,"id":2249229}]}]}
{"op":"mcm","clk":"1004353330","pt":1580627791196,"mc":[{"id":"1.168135786","rc":[{"trd":[[1.45,191.1]],"batb":[[0,1.45,117.21]],"ltp":1.45,"tv":1931.1,"id":2249229}],"tv":2640.25}]}
{"op":"mcm","clk":"1004353365","pt":1580627792219,"mc":[{"id":"1.168135786","rc":[{"batl":[[0,3.15,2.78]],"ltp":3.1,"tv":709.14,"id":5720747}]}]}
{"op":"mcm","clk":"1004353869","pt":1580627807818,"mc":[{"id":"1.168135786","rc":[{"batl":[[1,3.3,2.65]],"ltp":3.1,"tv":709.14,"id":5720747}]}]}
{"op":"mcm","clk":"1004353883","pt":1580627808124,"mc":[{"id":"1.168135786","rc":[{"batb":[[0,1.45,2213.22]],"ltp":1.45,"tv":1931.1,"id":2249229},{"batl":[[0,1000,2.78],[1,3.3,0]],"ltp":3.1,"tv":709.14,"id":5720747}]}]}
{"op":"mcm","clk":"1004354100","pt":1580627813736,"mc":[{"id":"1.168135786","rc":[{"batb":[[0,3.1,7.95]],"ltp":3.1,"tv":709.14,"id":5720747}]}]}
{"op":"mcm","clk":"1004354687","pt":1580627829637,"mc":[{"id":"1.168135786","rc":[{"batb":[[0,1.45,2234.3],[1,1.43,190.1],[2,1.41,363]],"batl":[[0,1.48,96.13],[1,1.5,89.97],[2,1.51,117.8]],"ltp":1.45,"tv":1931.1,"id":2249229}]}]}
{"op":"mcm","clk":"1004354816","pt":1580627832741,"mc":[{"id":"1.168135786","rc":[{"batb":[[0,1.45,138.29]],"ltp":1.45,"tv":1931.1,"id":2249229}]}]}
{"op":"mcm","clk":"1004354823","pt":1580627832845,"mc":[{"id":"1.168135786","rc":[{"batl":[[0,3.2,2.73],[1,1000,2.78]],"ltp":3.1,"tv":709.14,"id":5720747}]}]}
{"op":"mcm","clk":"1004354955","pt":1580627835722,"mc":[{"id":"1.168135786","rc":[{"batb":[[1,1.43,14],[2,1.42,180.3]],"ltp":1.45,"tv":1931.1,"id":2249229},{"batb":[[2,2.74,77.45]],"ltp":3.1,"tv":709.14,"id":5720747}]}]}
{"op":"mcm","clk":"1004355670","pt":1580627853789,"mc":[{"id":"1.168135786","rc":[{"batb":[[0,1.45,117.21],[1,1.43,35.08]],"ltp":1.45,"tv":1931.1,"id":2249229},{"batl":[[0,3.3,2.73]],"ltp":3.1,"tv":709.14,"id":5720747}]}]}
{"op":"mcm","clk":"1004356496","pt":1580627876899,"mc":[{"id":"1.168135786","rc":[{"batl":[[0,3.35,2.61]],"ltp":3.1,"tv":709.14,"id":5720747}]}]}
{"op":"mcm","clk":"1004362940","pt":1580628019766,"mc":[{"id":"1.168135786","rc":[{"batb":[[1,1.43,14]],"batl":[[0,1.48,78.68]],"ltp":1.45,"tv":1931.1,"id":2249229},{"batb":[[0,2.88,48.93],[1,2.74,77.45],[2,1.02,2780.78]],"ltp":3.1,"tv":709.14,"id":5720747}]}]}
{"op":"mcm","clk":"1004363830","pt":1580628038092,"mc":[{"id":"1.168135786","rc":[{"batb":[[1,1.43,35.32]],"batl":[[0,1.48,96.36]],"ltp":1.45,"tv":1931.1,"id":2249229},{"batb":[[0,3.1,7.88],[1,2.88,48.93],[2,2.74,77.45]],"batl":[[0,3.35,2.61]],"ltp":3.1,"tv":709.14,"id":5720747}]}]}
{"op":"mcm","clk":"1004364813","pt":1580628062462,"mc":[{"id":"1.168135786","rc":[{"batb":[[1,1.44,134.2],[2,1.43,35.32]],"ltp":1.45,"tv":1931.1,"id":2249229},{"batb":[[2,2.74,43.52]],"ltp":3.1,"tv":709.14,"id":5720747}]}]}
{"op":"mcm","clk":"1004365402","pt":1580628072523,"mc":[{"id":"1.168135786","rc":[{"batb":[[1,1.43,35.32],[2,1.42,180.3]],"ltp":1.45,"tv":1931.1,"id":2249229},{"batb":[[2,2.74,77.45]],"ltp":3.1,"tv":709.14,"id":5720747}]}]}
{"op":"mcm","clk":"1004366946","pt":1580628102279,"mc":[{"id":"1.168135786","rc":[{"batb":[[1,1.43,14]],"batl":[[0,1.48,78.68]],"ltp":1.45,"tv":1931.1,"id":2249229},{"batb":[[0,2.88,48.93],[1,2.74,77.45],[2,1.02,2780.78]],"ltp":3.1,"tv":709.14,"id":5720747}]}]}
{"op":"mcm","clk":"1004370666","pt":1580628186219,"mc":[{"id":"1.168135786","rc":[{"batb":[[1,1.43,35.43]],"batl":[[0,1.48,96.48]],"ltp":1.45,"tv":1931.1,"id":2249229},{"batb":[[0,3.1,7.93],[1,2.88,48.93],[2,2.74,77.45]],"batl":[[0,3.25,2.69]],"ltp":3.1,"tv":709.14,"id":5720747}]}]}
{"op":"mcm","clk":"1004371562","pt":1580628206698,"mc":[{"id":"1.168135786","rc":[{"batl":[[0,1000,2.69]],"ltp":3.1,"tv":709.14,"id":5720747}]}]}
{"op":"mcm","clk":"1004372729","pt":1580628234353,"mc":[{"id":"1.168135786","rc":[{"batl":[[0,3.35,2.61],[1,1000,2.69]],"ltp":3.1,"tv":709.14,"id":5720747}]}]}
{"op":"mcm","clk":"1004374260","pt":1580628289553,"mc":[{"id":"1.168135786","rc":[{"batb":[[1,1.43,14]],"batl":[[0,1.48,78.68]],"ltp":1.45,"tv":1931.1,"id":2249229},{"batb":[[0,2.88,48.93],[1,2.74,77.45],[2,1.02,2780.78]],"ltp":3.1,"tv":709.14,"id":5720747}]}]}
{"op":"mcm","clk":"1004374363","pt":1580628292729,"mc":[{"id":"1.168135786","rc":[{"batb":[[1,1.43,35.51]],"batl":[[0,1.48,96.56]],"ltp":1.45,"tv":1931.1,"id":2249229},{"batb":[[0,3.1,7.97],[1,2.88,48.93],[2,2.74,77.45]],"batl":[[0,3.35,2.61]],"ltp":3.1,"tv":709.14,"id":5720747}]}]}
{"op":"mcm","clk":"1004381107","pt":1580628455265,"mc":[{"id":"1.168135786","rc":[{"batb":[[0,1.46,3.14],[1,1.45,117.21],[2,1.43,35.51]],"ltp":1.45,"tv":1931.1,"id":2249229}]}]}
{"op":"mcm","clk":"1004383832","pt":1580628529644,"mc":[{"id":"1.168135786","rc":[{"batb":[[0,1.46,675.56]],"ltp":1.45,"tv":1931.1,"id":2249229}]}]}
{"op":"mcm","clk":"1004383878","pt":1580628530776,"mc":[{"id":"1.168135786","rc":[{"batb":[[0,3.05,7.97]],"ltp":3.1,"tv":709.14,"id":5720747}]}]}
{"op":"mcm","clk":"1004383925","pt":1580628531572,"mc":[{"id":"1.168135786","rc":[{"batb":[[2,2.74,33.93]],"ltp":3.1,"tv":709.14,"id":5720747}]}]}
{"op":"mcm","clk":"1004383981","pt":1580628532759,"mc":[{"id":"1.168135786","rc":[{"batb":[[2,2.76,43.03]],"ltp":3.1,"tv":709.14,"id":5720747}]}]}
{"op":"mcm","clk":"1004384352","pt":1580628542782,"mc":[{"id":"1.168135786","rc":[{"batb":[[0,1.46,697.07],[2,1.43,14]],"ltp":1.45,"tv":1931.1,"id":2249229}]}]}
{"op":"mcm","clk":"1004384388","pt":1580628543610,"mc":[{"id":"1.168135786","rc":[{"batl":[[0,3.15,2.61]],"ltp":3.1,"tv":709.14,"id":5720747}]}]}
{"op":"mcm","clk":"1004385379","pt":1580628569815,"mc":[{"id":"1.168135786","rc":[{"batl":[[0,3.15,2.78]],"ltp":3.1,"tv":709.14,"id":5720747}]}]}
{"op":"mcm","clk":"1004386122","pt":1580628590263,"mc":[{"id":"1.168135786","rc":[{"batb":[[2,2.74,33.93]],"ltp":3.1,"tv":709.14,"id":5720747}]}]}
{"op":"mcm","clk":"1004390642","pt":1580628696355,"mc":[{"id":"1.168135786","rc":[{"trd":[[1.46,540.64]],"batb":[[0,1.46,659.21]],"ltp":1.46,"tv":2006.82,"id":2249229}],"tv":2715.97}]}
{"op":"mcm","clk":"1004392898","pt":1580628751209,"mc":[{"id":"1.168135786","rc":[{"trd":[[1.46,726.14]],"batb":[[0,1.46,566.47]],"ltp":1.46,"tv":2192.32,"id":2249229}],"tv":2901.46}]}
{"op":"mcm","clk":"1004397857","pt":1580628875765,"mc":[{"id":"1.168135786","rc":[{"batl":[[0,1.48,78.91]],"ltp":1.46,"tv":2192.32,"id":2249229}]}]}
{"op":"mcm","clk":"1004399436","pt":1580628922767,"mc":[{"id":"1.168135786","rc":[{"trd":[[1.47,0.47],[1.48,52.48]],"batl":[[0,1.48,52.45]],"ltp":1.48,"tv":2245.25,"id":2249229}],"tv":2954.39}]}
{"op":"mcm","clk":"1004399710","pt":1580628929265,"mc":[{"id":"1.168135786","rc":[{"batl":[[0,1.48,70.35]],"ltp":1.48,"tv":2245.25,"id":2249229}]}]}
{"op":"mcm","clk":"1004401601","pt":1580628981664,"mc":[{"id":"1.168135786","rc":[{"batl":[[0,1.48,70.62]],"ltp":1.48,"tv":2245.25,"id":2249229}]}]}
{"op":"mcm","clk":"1004417202","pt":1580629364657,"mc":[{"id":"1.168135786","rc":[{"batl":[[0,3.15,657.78]],"ltp":3.1,"tv":709.14,"id":5720747}]}]}
{"op":"mcm","clk":"1004417343","pt":1580629367887,"mc":[{"id":"1.168135786","rc":[{"batl":[[0,1.48,52.45],[1,1.49,18.34],[2,1.5,89.97]],"ltp":1.48,"tv":2245.25,"id":2249229}]}]}
{"op":"mcm","clk":"1004425618","pt":1580629568419,"mc":[{"id":"1.168135786","rc":[{"batb":[[0,1.46,567.39]],"ltp":1.48,"tv":2245.25,"id":2249229},{"batb":[[0,3.05,8.5]],"ltp":3.1,"tv":709.14,"id":5720747}]}]}
{"op":"mcm","clk":"1004426671","pt":1580629593742,"mc":[{"id":"1.168135786","rc":[{"trd":[[1.46,731.21]],"batb":[[0,1.46,564.85]],"ltp":1.46,"tv":2250.31,"id":2249229}],"tv":2959.46}]}
{"op":"mcm","clk":"1004433568","pt":1580629744385,"mc":[{"id":"1.168135786","rc":[{"trd":[[1.46,736.28]],"batb":[[0,1.46,562.32]],"ltp":1.46,"tv":2255.38,"id":2249229}],"tv":2964.53}]}
{"op":"mcm","clk":"1004439269","pt":1580629864816,"mc":[{"id":"1.168135786","rc":[{"trd":[[1.48,157.01]],"batl":[[0,1.49,18.52],[1,1.5,89.97],[2,1.51,117.8]],"ltp":1.48,"tv":2359.91,"id":2249229}],"tv":3069.06}]}
{"op":"mcm","clk":"1004439316","pt":1580629865796,"mc":[{"id":"1.168135786","rc":[{"batb":[[0,1.47,22.43],[1,1.46,539.88],[2,1.45,117.21]],"ltp":1.48,"tv":2359.91,"id":2249229},{"batb":[[0,3,8.5]],"batl":[[0,3.1,2.78],[1,3.15,655]],"ltp":3.1,"tv":709.14,"id":5720747}]}]}
{"op":"mcm","clk":"1004443021","pt":1580629957125,"mc":[{"id":"1.168135786","rc":[{"batl":[[0,3.1,967.03]],"ltp":3.1,"tv":709.14,"id":5720747}]}]}
{"op":"mcm","clk":"1004443131","pt":1580629960336,"mc":[{"id":"1.168135786","rc":[{"batl":[[0,1.5,90.16],[1,1.51,117.8],[2,1.53,1.68]],"ltp":1.48,"tv":2359.91,"id":2249229},{"batb":[[0,2.88,48.93],[1,2.74,33.93],[2,2.56,8.5]],"ltp":3.1,"tv":709.14,"id":5720747}]}]}
{"op":"mcm","clk":"1004444005","pt":1580629983065,"mc":[{"id":"1.168135786","rc":[{"batb":[[2,2.54,8.5]],"ltp":3.1,"tv":709.14,"id":5720747}]}]}
{"op":"mcm","clk":"1004445159","pt":1580630010701,"mc":[{"id":"1.168135786","rc":[{"batl":[[0,3.1,2.78]],"ltp":3.1,"tv":709.14,"id":5720747}]}]}
{"op":"mcm","clk":"1004445581","pt":1580630020994,"mc":[{"id":"1.168135786","rc":[{"batl":[[0,1.49,18.52],[1,1.5,89.97],[2,1.51,117.8]],"ltp":1.48,"tv":2359.91,"id":2249229}]}]}
{"op":"mcm","clk":"1004446544","pt":1580630043727,"mc":[{"id":"1.168135786","rc":[{"batb":[[0,3,8.5],[1,2.88,48.93],[2,2.74,33.93]],"batl":[[0,3.1,967.03]],"ltp":3.1,"tv":709.14,"id":5720747}]}]}
{"op":"mcm","clk":"1004446886","pt":1580630050761,"mc":[{"id":"1.168135786","rc":[{"batl":[[0,1.5,90.16],[1,1.51,117.8],[2,1.53,1.68]],"ltp":1.48,"tv":2359.91,"id":2249229},{"batb":[[0,2.88,48.93],[1,2.74,33.93],[2,2.56,8.5]],"ltp":3.1,"tv":709.14,"id":5720747}]}]}
{"op":"mcm","clk":"1004447098","pt":1580630056145,"mc":[{"id":"1.168135786","rc":[{"batb":[[2,2.54,8.5]],"ltp":3.1,"tv":709.14,"id":5720747}]}]}
{"op":"mcm","clk":"1004447356","pt":1580630062255,"mc":[{"id":"1.168135786","rc":[{"batb":[[0,1.46,539.88],[1,1.45,117.21],[2,1.43,14]],"ltp":1.48,"tv":2359.91,"id":2249229},{"batb":[[2,1.02,2780.78]],"batl":[[0,3.1,964.25]],"ltp":3.1,"tv":709.14,"id":5720747}]}]}
{"op":"mcm","clk":"1004447621","pt":1580630068757,"mc":[{"id":"1.168135786","rc":[{"trd":[[1.48,157.19],[1.5,200.77]],"batb":[[0,1.47,22.43],[1,1.46,539.88],[2,1.45,117.21]],"batl":[[0,1.5,64.77]],"ltp":1.5,"tv":2385.3,"id":2249229},{"trd":[[3,181.63],[3.05,0.09]],"batl":[[0,3.05,2.78],[1,3.1,964.25],[2,3.15,655]],"ltp":3.0,"tv":721.84,"id":5720747}],"tv":3107.14}]}
