{"op":"mcm","clk":"988026418","pt":1580473742115,"mc":[{"id":"1.168136161","marketDefinition":{"bspMarket":false,"turnInPlayEnabled":true,"persistenceEnabled":true,"marketBaseRate":5.0,"eventId":"29678823","eventTypeId":"2","numberOfWinners":1,"bettingType":"ODDS","marketType":"MOST_ACES","marketTime":"2020-02-02T08:30:00.000Z","suspendTime":"2020-02-02T08:30:00.000Z","bspReconciled":false,"complete":true,"inPlay":false,"crossMatching":false,"runnersVoidable":false,"numberOfActiveRunners":2,"betDelay":0,"status":"OPEN","runners":[{"status":"ACTIVE","sortPriority":1,"id":5720747,"name":"Dominic Thiem"},{"status":"ACTIVE","sortPriority":2,"id":2249229,"name":"Novak Djokovic"}],"regulators":["MR_INT"],"countryCode":"AU","discountAllowed":false,"timezone":"GMT","openDate":"2020-02-02T08:30:00.000Z","version":3143005244,"name":"Most Aces","eventName":"Thiem v Djokovic"}}]}
{"op":"mcm","clk":"988026715","pt":1580473744836,"mc":[{"id":"1.168136161","marketDefinition":{"bspMarket":false,"turnInPlayEnabled":true,"persistenceEnabled":true,"marketBaseRate":5.0,"eventId":"29678823","eventTypeId":"2","numberOfWinners":1,"bettingType":"ODDS","marketType":"MOST_ACES","marketTime":"2020-02-02T08:30:00.000Z","suspendTime":"2020-02-02T08:30:00.000Z","bspReconciled":false,"complete":true,"inPlay":false,"crossMatching":false,"runnersVoidable":false,"numberOfActiveRunners":2,"betDelay":0,"status":"OPEN","runners":[{"status":"ACTIVE","sortPriority":1,"id":5720747,"name":"Dominic Thiem"},{"status":"ACTIVE","sortPriority":2,"id":2249229,"name":"Novak Djokovic"}],"regulators":["MR_INT"],"countryCode":"AU","discountAllowed":true,"timezone":"GMT","openDate":"2020-02-02T08:30:00.000Z","version":3143005244,"name":"Most Aces","eventName":"Thiem v Djokovic"}}]}
{"op":"mcm","clk":"991991744","pt":1580511710728,"mc":[{"id":"1.168136161","rc":[{"batb":[[0,1.01,0.51]],"ltp":0.0,"tv":0.0,"id":2249229},{"batb":[[0,1.01,0.51]],"ltp":0.0,"tv":0.0,"id":5720747}]}]}
{"op":"mcm","clk":"992004377","pt":1580511987459,"mc":[{"id":"1.168136161","rc":[{"batb":[[0,1.01,1.01]],"ltp":0.0,"tv":0.0,"id":2249229},{"batb":[[0,1.01,1.01]],"ltp":0.0,"tv":0.0,"id":5720747}]}]}
{"op":"mcm","clk":"992325768","pt":1580519749907,"mc":[{"id":"1.168136161","rc":[{"batb":[[0,2,82.62],[1,1.01,1.01]],"ltp":0.0,"tv":0.0,"id":5720747}]}]}
{"op":"mcm","clk":"992325883","pt":1580519754179,"mc":[{"id":"1.168136161","rc":[{"batb":[[0,1.3,82.62],[1,1.01,1.01]],"ltp":0.0,"tv":0.0,"id":2249229}]}]}
{"op":"mcm","clk":"992326095","pt":1580519763345,"mc":[{"id":"1.168136161","rc":[{"batb":[[0,1.4,82.62]],"ltp":0.0,"tv":0.0,"id":2249229}]}]}
{"op":"mcm","clk":"992467910","pt":1580523745192,"mc":[{"id":"1.168136161","rc":[{"batb":[[0,2.5,1013.02],[1,2,82.62],[2,1.01,1.01]],"ltp":0.0,"tv":0.0,"id":5720747}]}]}
{"op":"mcm","clk":"992483050","pt":1580523940124,"mc":[{"id":"1.168136161","rc":[{"batb":[[0,2,82.62],[1,1.01,1.01],[2,1.01,0]],"ltp":0.0,"tv":0.0,"id":5720747}]}]}
{"op":"mcm","clk":"993274617","pt":1580539835780,"mc":[{"id":"1.168136161","rc":[{"batb":[[0,2.02,101.3],[1,2,82.62],[2,1.01,1.01]],"ltp":0.0,"tv":0.0,"id":5720747}]}]}
{"op":"mcm","clk":"993412618","pt":1580542034084,"mc":[{"id":"1.168136161","rc":[{"batb":[[0,2.04,6.1],[1,2.02,101.3],[2,2,82.62]],"ltp":0.0,"tv":0.0,"id":5720747}]}]}
{"op":"mcm","clk":"993414338","pt":1580542059267,"mc":[{"id":"1.168136161","marketDefinition":{"bspMarket":false,"turnInPlayEnabled":true,"persistenceEnabled":true,"marketBaseRate":5.0,"eventId":"29678823","eventTypeId":"2","numberOfWinners":1,"bettingType":"ODDS","marketType":"MOST_ACES","marketTime":"2020-02-02T08:30:00.000Z","suspendTime":"2020-02-02T08:30:00.000Z","bspReconciled":false,"complete":true,"inPlay":false,"crossMatching":true,"runnersVoidable":false,"numberOfActiveRunners":2,"betDelay":0,"status":"OPEN","runners":[{"status":"ACTIVE","sortPriority":1,"id":5720747,"name":"Dominic Thiem"},{"status":"ACTIVE","sortPriority":2,"id":2249229,"name":"Novak Djokovic"}],"regulators":["MR_INT"],"countryCode":"AU","discountAllowed":true,"timezone":"GMT","openDate":"2020-02-02T08:30:00.000Z","version":3143005244,"name":"Most Aces","eventName":"Thiem v Djokovic"}}]}
{"op":"mcm","clk":"993715791","pt":1580545570316,"mc":[{"id":"1.168136161","rc":[{"batb":[[0,2.06,101.3],[1,2.04,6.1]],"ltp":0.0,"tv":0.0,"id":5720747}]}]}
{"op":"mcm","clk":"994043778","pt":1580548802036,"mc":[{"id":"1.168136161","rc":[{"batb":[[0,2.2,82.62],[1,2.06,101.3],[2,2.04,6.1]],"ltp":0.0,"tv":0.0,"id":5720747}]}]}
{"op":"mcm","clk":"994048419","pt":1580548848120,"mc":[{"id":"1.168136161","rc":[{"batb":[[0,2.22,6.1],[1,2.2,82.62],[2,2.06,101.3]],"ltp":0.0,"tv":0.0,"id":5720747}]}]}
{"op":"mcm","clk":"994899522","pt":1580554373960,"mc":[{"id":"1.168136161","rc":[{"batb":[[0,2.24,101.3],[1,2.22,6.1],[2,2.2,82.62]],"ltp":0.0,"tv":0.0,"id":5720747}]}]}
{"op":"mcm","clk":"994975725","pt":1580554822178,"mc":[{"id":"1.168136161","rc":[{"batb":[[0,2.5,506.51],[1,2.24,101.3],[2,2.22,6.1]],"ltp":0.0,"tv":0.0,"id":5720747}]}]}
{"op":"mcm","clk":"994990049","pt":1580554891328,"mc":[{"id":"1.168136161","rc":[{"batb":[[0,1.5,841.28],[1,1.4,82.62],[2,1.01,1.01]],"ltp":0.0,"tv":0.0,"id":2249229}]}]}
{"op":"mcm","clk":"995230623","pt":1580555991080,"mc":[{"id":"1.168136161","rc":[{"batb":[[0,1.51,168.04],[1,1.5,841.28],[2,1.4,82.62]],"ltp":0.0,"tv":0.0,"id":2249229}]}]}
{"op":"mcm","clk":"995247974","pt":1580556075801,"mc":[{"id":"1.168136161","rc":[{"batb":[[0,1.52,7.26],[1,1.51,168.04],[2,1.5,841.28]],"ltp":0.0,"tv":0.0,"id":2249229},{"batb":[[0,2.52,6.1],[1,2.5,506.51],[2,2.24,101.3]],"ltp":0.0,"tv":0.0,"id":5720747}]}]}
{"op":"mcm","clk":"995283605","pt":1580556203569,"mc":[{"id":"1.168136161","rc":[{"batb":[[1,2.24,101.3],[2,2.2,82.62]],"ltp":0.0,"tv":0.0,"id":5720747}]}]}
{"op":"mcm","clk":"995284808","pt":1580556209477,"mc":[{"id":"1.168136161","rc":[{"batb":[[2,1.01,1.01]],"ltp":0.0,"tv":0.0,"id":5720747}]}]}
{"op":"mcm","clk":"995649771","pt":1580557954556,"mc":[{"id":"1.168136161","rc":[{"trd":[[1.66,9.27]],"batb":[[0,1.66,8.59],[1,1.52,7.26],[2,1.51,168.04]],"ltp":1.66,"tv":9.26,"id":2249229},{"trd":[[2.52,6.1]],"batb":[[0,2.24,101.3],[1,1.01,1.01],[2,1.01,0]],"ltp":2.52,"tv":6.1,"id":5720747}],"tv":15.37}]}
{"op":"mcm","clk":"995661046","pt":1580558030611,"mc":[{"id":"1.168136161","rc":[{"batb":[[1,1.6,21],[2,1.52,7.26]],"ltp":1.66,"tv":9.26,"id":2249229}]}]}
{"op":"mcm","clk":"995664010","pt":1580558049264,"mc":[{"id":"1.168136161","rc":[{"batb":[[1,1.52,7.26],[2,1.51,168.04]],"ltp":1.66,"tv":9.26,"id":2249229}]}]}
{"op":"mcm","clk":"996057318","pt":1580560207636,"mc":[{"id":"1.168136161","rc":[{"batb":[[1,1.52,57.26]],"ltp":1.66,"tv":9.26,"id":2249229}]}]}
{"op":"mcm","clk":"996059369","pt":1580560218764,"mc":[{"id":"1.168136161","rc":[{"batb":[[0,1.66,849.87]],"ltp":1.66,"tv":9.26,"id":2249229}]}]}
{"op":"mcm","clk":"996456991","pt":1580562270246,"mc":[{"id":"1.168136161","rc":[{"trd":[[1.66,16.51]],"batb":[[0,1.66,842.63]],"ltp":1.66,"tv":16.5,"id":2249229},{"trd":[[2.52,10.87]],"ltp":2.52,"tv":10.87,"id":5720747}],"tv":27.38}]}
{"op":"mcm","clk":"996754405","pt":1580563582571,"mc":[{"id":"1.168136161","rc":[{"trd":[[1.81,1.34]],"batb":[[0,1.66,841.28]],"ltp":1.81,"tv":17.85,"id":2249229},{"trd":[[2.24,1.08]],"batb":[[0,2.24,100.22]],"ltp":2.24,"tv":11.95,"id":5720747}],"tv":29.81}]}
{"op":"mcm","clk":"996843512","pt":1580564028634,"mc":[{"id":"1.168136161","rc":[{"batb":[[0,1.67,7.26],[1,1.66,841.28],[2,1.52,50]],"ltp":1.81,"tv":17.85,"id":2249229}]}]}
{"op":"mcm","clk":"997126959","pt":1580565470593,"mc":[{"id":"1.168136161","rc":[{"batb":[[1,1.8,111.43],[2,1.01,1.01]],"ltp":2.24,"tv":11.95,"id":5720747}]}]}
{"op":"mcm","clk":"997237200","pt":1580566047367,"mc":[{"id":"1.168136161","rc":[{"batb":[[2,1.51,168.04]],"ltp":1.81,"tv":17.85,"id":2249229}]}]}
{"op":"mcm","clk":"997656946","pt":1580567708354,"mc":[{"id":"1.168136161","rc":[{"trd":[[1.67,7.26]],"batb":[[0,1.66,841.28],[1,1.51,168.04],[2,1.01,1.01]],"ltp":1.67,"tv":25.11,"id":2249229},{"trd":[[2.5,4.85]],"batb":[[0,2.5,47.32],[1,2.24,100.22],[2,1.8,111.43]],"ltp":2.5,"tv":16.8,"id":5720747}],"tv":41.92}]}
{"op":"mcm","clk":"997669801","pt":1580567759074,"mc":[{"id":"1.168136161","rc":[{"trd":[[1.66,88.42]],"batb":[[0,1.66,769.37]],"ltp":1.66,"tv":97.03,"id":2249229},{"trd":[[2.52,58.2]],"batb":[[0,2.24,100.22],[1,1.8,111.43],[2,1.01,1.01]],"ltp":2.52,"tv":64.12,"id":5720747}],"tv":161.15}]}
{"op":"mcm","clk":"997672403","pt":1580567769261,"mc":[{"id":"1.168136161","rc":[{"trd":[[1.66,781.15]],"batb":[[0,1.66,76.64]],"ltp":1.66,"tv":789.76,"id":2249229},{"trd":[[2.52,514.05]],"ltp":2.52,"tv":519.98,"id":5720747}],"tv":1309.74}]}
{"op":"mcm","clk":"997673960","pt":1580567775454,"mc":[{"id":"1.168136161","rc":[{"trd":[[1.66,804.24]],"batb":[[0,1.66,53.55]],"ltp":1.66,"tv":812.84,"id":2249229},{"trd":[[2.52,529.25]],"ltp":2.52,"tv":535.18,"id":5720747}],"tv":1348.03}]}
{"op":"mcm","clk":"997692277","pt":1580567847723,"mc":[{"id":"1.168136161","rc":[{"trd":[[1.66,827.33]],"batb":[[0,1.66,30.46]],"ltp":1.66,"tv":835.93,"id":2249229},{"trd":[[2.52,544.45]],"ltp":2.52,"tv":550.37,"id":5720747}],"tv":1386.31}]}
{"op":"mcm","clk":"997738126","pt":1580568035716,"mc":[{"id":"1.168136161","rc":[{"batl":[[0,1.8,8.4]],"ltp":1.66,"tv":835.93,"id":2249229}]}]}
{"op":"mcm","clk":"998112576","pt":1580569609735,"mc":[{"id":"1.168136161","rc":[{"trd":[[1.66,857.22]],"batb":[[0,1.51,168.61],[1,1.01,1.01],[2,1.01,0]],"ltp":1.66,"tv":865.82,"id":2249229},{"trd":[[2.52,564.13]],"ltp":2.52,"tv":570.06,"id":5720747}],"tv":1435.88}]}
{"op":"mcm","clk":"998205148","pt":1580569955043,"mc":[{"id":"1.168136161","rc":[{"batb":[[0,1.52,11.01],[1,1.51,168.04],[2,1.01,1.01]],"ltp":1.66,"tv":865.82,"id":2249229}]}]}
{"op":"mcm","clk":"998682681","pt":1580571745674,"mc":[{"id":"1.168136161","rc":[{"batb":[[1,1.8,84.08]],"ltp":2.52,"tv":570.06,"id":5720747}]}]}
{"op":"mcm","clk":"998683712","pt":1580571750301,"mc":[{"id":"1.168136161","rc":[{"batb":[[0,2.24,61.29]],"ltp":2.52,"tv":570.06,"id":5720747}]}]}
{"op":"mcm","clk":"999822449","pt":1580576910682,"mc":[{"id":"1.168136161","rc":[{"batb":[[0,2.3,43.67],[1,2.24,61.29],[2,1.8,84.08]],"ltp":2.52,"tv":570.06,"id":5720747}]}]}
{"op":"mcm","clk":"999937615","pt":1580577664222,"mc":[{"id":"1.168136161","rc":[{"batb":[[0,1.52,10.44]],"ltp":1.66,"tv":865.82,"id":2249229}]}]}
{"op":"mcm","clk":"999939346","pt":1580577675527,"mc":[{"id":"1.168136161","rc":[{"batb":[[0,1.6,420.26],[1,1.52,10.44],[2,1.51,168.04]],"ltp":1.66,"tv":865.82,"id":2249229}]}]}
{"op":"mcm","clk":"999939427","pt":1580577676016,"mc":[{"id":"1.168136161","rc":[{"batb":[[0,1.61,9.37],[1,1.6,420.26]],"ltp":1.66,"tv":865.82,"id":2249229},{"batl":[[0,2.66,8.4]],"ltp":2.52,"tv":570.06,"id":5720747}]}]}
{"op":"mcm","clk":"999958984","pt":1580577807148,"mc":[{"id":"1.168136161","rc":[{"batb":[[0,1.61,429.63],[1,1.51,168.04],[2,1.01,1.01]],"ltp":1.66,"tv":865.82,"id":2249229}]}]}
{"op":"mcm","clk":"999959200","pt":1580577808747,"mc":[{"id":"1.168136161","rc":[{"batl":[[0,2.62,8.4]],"ltp":2.52,"tv":570.06,"id":5720747}]}]}
{"op":"mcm","clk":"999989121","pt":1580577997512,"mc":[{"id":"1.168136161","rc":[{"batb":[[0,1.62,7.17],[1,1.61,429.63],[2,1.51,168.04]],"ltp":1.66,"tv":865.82,"id":2249229}]}]}
{"op":"mcm","clk":"1000079786","pt":1580578549091,"mc":[{"id":"1.168136161","rc":[{"trd":[[1.62,3.36]],"batb":[[0,1.62,5.49]],"ltp":1.62,"tv":869.18,"id":2249229}],"tv":1439.25}]}
{"op":"mcm","clk":"1000994687","pt":1580584315411,"mc":[{"id":"1.168136161","rc":[{"batl":[[0,1.69,11]],"ltp":1.62,"tv":869.18,"id":2249229}]}]}
{"op":"mcm","clk":"1000999981","pt":1580584342625,"mc":[{"id":"1.168136161","rc":[{"batl":[[0,1.66,5],[1,1.69,11]],"ltp":1.62,"tv":869.18,"id":2249229}]}]}
{"op":"mcm","clk":"1001036413","pt":1580584537757,"mc":[{"id":"1.168136161","rc":[{"batl":[[0,1.69,11],[1,1.69,0]],"ltp":1.62,"tv":869.18,"id":2249229}]}]}
{"op":"mcm","clk":"1001178349","pt":1580585276085,"mc":[{"id":"1.168136161","rc":[{"batb":[[0,1.63,64],[1,1.62,5.49],[2,1.61,429.63]],"ltp":1.62,"tv":869.18,"id":2249229}]}]}
{"op":"mcm","clk":"1001192272","pt":1580585352118,"mc":[{"id":"1.168136161","rc":[{"batl":[[0,2.58,23],[1,2.62,8.4]],"ltp":2.52,"tv":570.06,"id":5720747}]}]}
{"op":"mcm","clk":"1001192425","pt":1580585353005,"mc":[{"id":"1.168136161","rc":[{"batb":[[2,1.61,420.26]],"ltp":1.62,"tv":869.18,"id":2249229}]}]}
{"op":"mcm","clk":"1001426094","pt":1580586612903,"mc":[{"id":"1.168136161","rc":[{"batb":[[0,2.32,68.9],[1,2.3,43.67],[2,2.24,61.29]],"ltp":2.52,"tv":570.06,"id":5720747}]}]}
{"op":"mcm","clk":"1001532041","pt":1580587257561,"mc":[{"id":"1.168136161","rc":[{"batb":[[0,2.34,6],[1,2.32,68.9],[2,2.3,43.67]],"ltp":2.52,"tv":570.06,"id":5720747}]}]}
{"op":"mcm","clk":"1001533308","pt":1580587265665,"mc":[{"id":"1.168136161","rc":[{"batb":[[0,1.64,8],[1,1.63,64],[2,1.62,5.49]],"ltp":1.62,"tv":869.18,"id":2249229}]}]}
{"op":"mcm","clk":"1001533480","pt":1580587266747,"mc":[{"id":"1.168136161","rc":[{"batb":[[2,1.62,9.49]],"ltp":1.62,"tv":869.18,"id":2249229}]}]}
{"op":"mcm","clk":"1001746811","pt":1580588356729,"mc":[{"id":"1.168136161","rc":[{"batb":[[2,1.62,4]],"ltp":1.62,"tv":869.18,"id":2249229}]}]}
{"op":"mcm","clk":"1001826395","pt":1580588807058,"mc":[{"id":"1.168136161","rc":[{"trd":[[2.32,4.81],[2.34,12]],"batb":[[0,2.32,66.49],[1,2.3,43.67],[2,2.26,3]],"ltp":2.32,"tv":586.86,"id":5720747}],"tv":1456.05}]}
{"op":"mcm","clk":"1001971944","pt":1580589647374,"mc":[{"id":"1.168136161","rc":[{"batl":[[0,2.62,8.4],[1,2.62,0]],"ltp":2.32,"tv":586.86,"id":5720747}]}]}
{"op":"mcm","clk":"1001972109","pt":1580589648263,"mc":[{"id":"1.168136161","rc":[{"batb":[[2,1.62,12.92]],"ltp":1.62,"tv":869.18,"id":2249229}]}]}
{"op":"mcm","clk":"1002009268","pt":1580589875802,"mc":[{"id":"1.168136161","rc":[{"trd":[[1.64,8]],"batb":[[0,1.63,64],[1,1.62,12.92],[2,1.61,420.26]],"ltp":1.64,"tv":877.18,"id":2249229},{"trd":[[2.58,5.09]],"batb":[[0,2.58,4.98],[1,2.32,66.49],[2,2.3,43.67]],"ltp":2.58,"tv":591.95,"id":5720747}],"tv":1469.14}]}
{"op":"mcm","clk":"1002012952","pt":1580589898219,"mc":[{"id":"1.168136161","rc":[{"batb":[[0,2.32,66.49],[1,2.3,43.67],[2,2.26,3]],"ltp":2.58,"tv":591.95,"id":5720747}]}]}
{"op":"mcm","clk":"1002048530","pt":1580590109537,"mc":[{"id":"1.168136161","rc":[{"trd":[[1.63,7.25]],"batb":[[0,1.63,56.75]],"ltp":1.63,"tv":884.43,"id":2249229},{"trd":[[2.6,4.54]],"ltp":2.6,"tv":596.5,"id":5720747}],"tv":1480.93}]}
{"op":"mcm","clk":"1002140290","pt":1580590857610,"mc":[{"id":"1.168136161","rc":[{"batb":[[1,1.62,19.21]],"ltp":1.63,"tv":884.43,"id":2249229}]}]}
{"op":"mcm","clk":"1002213990","pt":1580591479943,"mc":[{"id":"1.168136161","rc":[{"batb":[[1,2.26,3],[2,2.24,61.29]],"ltp":2.6,"tv":596.5,"id":5720747}]}]}
{"op":"mcm","clk":"1002248589","pt":1580591828194,"mc":[{"id":"1.168136161","rc":[{"batb":[[0,2.36,61.29],[1,2.32,66.49],[2,2.26,3]],"ltp":2.6,"tv":596.5,"id":5720747}]}]}
{"op":"mcm","clk":"1002411698","pt":1580593382519,"mc":[{"id":"1.168136161","rc":[{"batb":[[1,1.62,12.92]],"ltp":1.63,"tv":884.43,"id":2249229}]}]}
{"op":"mcm","clk":"1002586593","pt":1580595693215,"mc":[{"id":"1.168136161","rc":[{"batb":[[0,2.56,26.74],[1,2.36,61.29],[2,2.32,66.49]],"ltp":2.6,"tv":596.5,"id":5720747}]}]}
{"op":"mcm","clk":"1002598775","pt":1580595873516,"mc":[{"id":"1.168136161","rc":[{"batb":[[0,1.64,50],[1,1.63,56.75],[2,1.62,12.92]],"ltp":1.63,"tv":884.43,"id":2249229}]}]}
{"op":"mcm","clk":"1002598826","pt":1580595874340,"mc":[{"id":"1.168136161","rc":[{"batb":[[2,1.62,4]],"ltp":1.63,"tv":884.43,"id":2249229}]}]}
{"op":"mcm","clk":"1002724166","pt":1580597854533,"mc":[{"id":"1.168136161","rc":[{"batb":[[0,2.36,61.29],[1,2.32,66.49],[2,2.26,3]],"ltp":2.6,"tv":596.5,"id":5720747}]}]}
{"op":"mcm","clk":"1002732680","pt":1580597984336,"mc":[{"id":"1.168136161","rc":[{"batb":[[0,2.38,50.65],[1,2.36,61.29],[2,2.32,66.49]],"ltp":2.6,"tv":596.5,"id":5720747}]}]}
{"op":"mcm","clk":"1002795392","pt":1580598863830,"mc":[{"id":"1.168136161","rc":[{"batl":[[0,1.72,33.73]],"ltp":1.63,"tv":884.43,"id":2249229}]}]}
{"op":"mcm","clk":"1002843345","pt":1580599531893,"mc":[{"id":"1.168136161","rc":[{"trd":[[1.64,34]],"batb":[[0,1.64,37]],"ltp":1.64,"tv":910.43,"id":2249229}],"tv":1506.93}]}
{"op":"mcm","clk":"1002851286","pt":1580599636730,"mc":[{"id":"1.168136161","rc":[{"batb":[[0,2.56,26.74],[1,2.38,50.65],[2,2.36,61.29]],"ltp":2.6,"tv":596.5,"id":5720747}]}]}
{"op":"mcm","clk":"1002851982","pt":1580599645372,"mc":[{"id":"1.168136161","rc":[{"trd":[[2.56,8.4]],"batb":[[0,2.56,22.54]],"ltp":2.56,"tv":604.9,"id":5720747}],"tv":1515.33}]}
{"op":"mcm","clk":"1002973963","pt":1580601407780,"mc":[{"id":"1.168136161","rc":[{"trd":[[1.64,71]],"batb":[[0,1.63,56.75],[1,1.62,4],[2,1.61,420.26]],"ltp":1.64,"tv":947.43,"id":2249229},{"trd":[[2.58,28.59]],"batb":[[0,2.58,29.15],[1,2.56,22.54],[2,2.38,50.65]],"ltp":2.58,"tv":628.39,"id":5720747}],"tv":1575.83}]}
{"op":"mcm","clk":"1002974003","pt":1580601408444,"mc":[{"id":"1.168136161","rc":[{"batb":[[1,1.62,14.55]],"ltp":1.64,"tv":947.43,"id":2249229}]}]}
{"op":"mcm","clk":"1002977841","pt":1580601458390,"mc":[{"id":"1.168136161","rc":[{"batb":[[0,2.58,28.97]],"ltp":2.58,"tv":628.39,"id":5720747}]}]}
{"op":"mcm","clk":"1002978462","pt":1580601467000,"mc":[{"id":"1.168136161","rc":[{"trd":[[1.63,53.51]],"batb":[[0,1.63,10.49]],"ltp":1.63,"tv":993.69,"id":2249229},{"trd":[[2.6,33.52]],"batb":[[0,2.56,22.54],[1,2.38,50.65],[2,2.36,61.29]],"ltp":2.6,"tv":657.37,"id":5720747}],"tv":1651.06}]}
{"op":"mcm","clk":"1003007994","pt":1580601901510,"mc":[{"id":"1.168136161","rc":[{"trd":[[1.63,63.51]],"batb":[[0,1.63,5.49]],"ltp":1.63,"tv":1003.69,"id":2249229}],"tv":1661.06}]}
{"op":"mcm","clk":"1003047749","pt":1580602353765,"mc":[{"id":"1.168136161","rc":[{"trd":[[1.63,69]],"batb":[[0,1.62,14.55],[1,1.61,420.26],[2,1.55,4]],"ltp":1.63,"tv":1009.18,"id":2249229},{"trd":[[2.6,36.95]],"batb":[[0,2.6,6.49],[1,2.56,22.54],[2,2.38,50.65]],"ltp":2.6,"tv":660.8,"id":5720747}],"tv":1669.99}]}
{"op":"mcm","clk":"1003076559","pt":1580602665512,"mc":[{"id":"1.168136161","rc":[{"batl":[[0,1.64,64],[1,1.72,33.73]],"ltp":1.63,"tv":1009.18,"id":2249229}]}]}
{"op":"mcm","clk":"1003088093","pt":1580602814983,"mc":[{"id":"1.168136161","rc":[{"trd":[[1.62,10.44]],"batb":[[0,1.62,11.01]],"ltp":1.62,"tv":1016.26,"id":2249229}],"tv":1677.07}]}
{"op":"mcm","clk":"1003175213","pt":1580603919763,"mc":[{"id":"1.168136161","rc":[{"batb":[[0,1.62,95.03]],"ltp":1.62,"tv":1016.26,"id":2249229}]}]}
{"op":"mcm","clk":"1003176020","pt":1580603932621,"mc":[{"id":"1.168136161","rc":[{"trd":[[2.6,41.24]],"batb":[[0,2.6,4.35]],"ltp":2.6,"tv":665.09,"id":5720747}],"tv":1681.35}]}
{"op":"mcm","clk":"1003266657","pt":1580605415182,"mc":[{"id":"1.168136161","rc":[{"trd":[[1.62,44.04]],"batb":[[0,1.62,78.23]],"ltp":1.62,"tv":1049.86,"id":2249229}],"tv":1714.96}]}
{"op":"mcm","clk":"1003266764","pt":1580605416783,"mc":[{"id":"1.168136161","rc":[{"batl":[[0,1.64,74.43]],"ltp":1.62,"tv":1049.86,"id":2249229}]}]}
{"op":"mcm","clk":"1003276349","pt":1580605549126,"mc":[{"id":"1.168136161","rc":[{"trd":[[1.62,74.04]],"batb":[[0,1.62,63.23]],"ltp":1.62,"tv":1079.86,"id":2249229}],"tv":1744.96}]}
{"op":"mcm","clk":"1003673231","pt":1580611045297,"mc":[{"id":"1.168136161","rc":[{"trd":[[1.61,57.63],[1.62,137.27]],"batb":[[0,1.61,362.63],[1,1.55,4],[2,1.01,0.51]],"ltp":1.61,"tv":1200.73,"id":2249229},{"trd":[[2.62,55.85],[2.64,35.11]],"ltp":2.64,"tv":756.05,"id":5720747}],"tv":1956.78}]}
{"op":"mcm","clk":"1003675515","pt":1580611077834,"mc":[{"id":"1.168136161","rc":[{"batb":[[2,1.4,466.31]],"ltp":1.61,"tv":1200.73,"id":2249229},{"batb":[[2,2.4,186.52]],"ltp":2.64,"tv":756.05,"id":5720747}]}]}
{"op":"mcm","clk":"1003707302","pt":1580611595269,"mc":[{"id":"1.168136161","rc":[{"batb":[[2,1.5,2.53]],"ltp":1.61,"tv":1200.73,"id":2249229}]}]}
{"op":"mcm","clk":"1003711471","pt":1580611665880,"mc":[{"id":"1.168136161","rc":[{"batl":[[0,1.64,10.43]],"ltp":1.61,"tv":1200.73,"id":2249229}]}]}
{"op":"mcm","clk":"1003711537","pt":1580611666963,"mc":[{"id":"1.168136161","rc":[{"batl":[[0,1.72,33.73],[1,1.72,0]],"ltp":1.61,"tv":1200.73,"id":2249229}]}]}
{"op":"mcm","clk":"1004133715","pt":1580621040042,"mc":[{"id":"1.168136161","rc":[{"batb":[[0,1.61,504.32]],"ltp":1.61,"tv":1200.73,"id":2249229}]}]}
{"op":"mcm","clk":"1004162687","pt":1580621804864,"mc":[{"id":"1.168136161","rc":[{"trd":[[1.61,77.81]],"batb":[[0,1.61,494.23]],"ltp":1.61,"tv":1220.9,"id":2249229}],"tv":1976.96}]}
{"op":"mcm","clk":"1004304671","pt":1580626382714,"mc":[{"id":"1.168136161","rc":[{"batb":[[0,2.6,58.04]],"ltp":2.64,"tv":756.05,"id":5720747}]}]}
{"op":"mcm","clk":"1004304712","pt":1580626383998,"mc":[{"id":"1.168136161","rc":[{"batl":[[0,1.62,10.55],[1,1.72,33.73]],"ltp":1.61,"tv":1220.9,"id":2249229}]}]}
{"op":"mcm","clk":"1004304776","pt":1580626385698,"mc":[{"id":"1.168136161","rc":[{"batb":[[1,2.58,8.54],[2,2.56,22.54]],"ltp":2.64,"tv":756.05,"id":5720747}]}]}
{"op":"mcm","clk":"1004314469","pt":1580626651809,"mc":[{"id":"1.168136161","rc":[{"batl":[[0,1.72,33.73],[1,1.72,0]],"ltp":1.61,"tv":1220.9,"id":2249229},{"trd":[[2.6,52.38]],"batb":[[0,2.6,52.47],[1,2.56,22.54],[2,2.4,186.52]],"ltp":2.6,"tv":767.2,"id":5720747}],"tv":1988.1}]}
{"op":"mcm","clk":"1004314470","pt":1580626651909,"mc":[{"id":"1.168136161","rc":[{"batl":[[0,1.63,10.49],[1,1.72,33.73]],"ltp":1.61,"tv":1220.9,"id":2249229}]}]}
{"op":"mcm","clk":"1004314514","pt":1580626653411,"mc":[{"id":"1.168136161","rc":[{"batl":[[0,1.64,10.43]],"ltp":1.61,"tv":1220.9,"id":2249229}]}]}
{"op":"mcm","clk":"1004364767","pt":1580628061637,"mc":[{"id":"1.168136161","rc":[{"trd":[[2.6,103.03]],"batb":[[0,2.6,27.14]],"ltp":2.6,"tv":817.85,"id":5720747}],"tv":2038.75}]}
{"op":"mcm","clk":"1004364883","pt":1580628063641,"mc":[{"id":"1.168136161","rc":[{"batl":[[0,1.72,33.73],[1,1.72,0]],"ltp":1.61,"tv":1220.9,"id":2249229}]}]}
{"op":"mcm","clk":"1004468957","pt":1580630514016,"mc":[{"id":"1.168136161","rc":[{"batb":[[0,1.62,4.2],[1,1.61,494.23],[2,1.55,4]],"ltp":1.61,"tv":1220.9,"id":2249229}]}]}
{"op":"mcm","clk":"1004479245","pt":1580630738354,"mc":[{"id":"1.168136161","rc":[{"batb":[[2,2.44,62.5]],"ltp":2.6,"tv":817.85,"id":5720747}]}]}
{"op":"mcm","clk":"1004489038","pt":1580630974451,"mc":[{"id":"1.168136161","rc":[{"trd":[[1.61,108.46],[1.62,141.47]],"batb":[[0,1.61,474.2],[1,1.55,4],[2,1.5,2.53]],"ltp":1.61,"tv":1255.75,"id":2249229},{"trd":[[2.62,58.45],[2.64,40.85]],"ltp":2.64,"tv":826.18,"id":5720747}],"tv":2081.94}]}
{"op":"mcm","clk":"1004492709","pt":1580631048684,"mc":[{"id":"1.168136161","rc":[{"trd":[[1.61,112]],"batb":[[0,1.61,472.43]],"ltp":1.61,"tv":1259.29,"id":2249229}],"tv":2085.48}]}
{"op":"mcm","clk":"1004513191","pt":1580631528425,"mc":[{"id":"1.168136161","rc":[{"trd":[[1.63,71]],"ltp":1.63,"tv":1261.29,"id":2249229},{"trd":[[2.6,104.29]],"batb":[[0,2.6,25.89]],"ltp":2.6,"tv":827.43,"id":5720747}],"tv":2088.73}]}
{"op":"mcm","clk":"1004525814","pt":1580631815743,"mc":[{"id":"1.168136161","rc":[{"batb":[[0,1.62,245.1],[1,1.61,472.43],[2,1.55,4]],"ltp":1.63,"tv":1261.29,"id":2249229}]}]}
{"op":"mcm","clk":"1004528535","pt":1580631873811,"mc":[{"id":"1.168136161","rc":[{"trd":[[1.63,112.34]],"batb":[[0,1.63,431.08],[1,1.62,245.1]],"ltp":1.63,"tv":1302.64,"id":2249229},{"trd":[[2.6,130.18]],"batb":[[0,2.56,22.54],[1,2.44,62.5],[2,2.4,186.52]],"ltp":2.6,"tv":853.33,"id":5720747}],"tv":2155.97}]}
{"op":"mcm","clk":"1004529133","pt":1580631885743,"mc":[{"id":"1.168136161","rc":[{"batl":[[0,2.6,25]],"ltp":2.6,"tv":853.33,"id":5720747}]}]}
{"op":"mcm","clk":"1004531000","pt":1580631921789,"mc":[{"id":"1.168136161","rc":[{"trd":[[2.56,52.38]],"batb":[[0,2.44,63.06],[1,2.4,186.52],[2,2.26,3]],"ltp":2.56,"tv":897.3,"id":5720747}],"tv":2199.94}]}
{"op":"mcm","clk":"1004532980","pt":1580631962220,"mc":[{"id":"1.168136161","rc":[{"trd":[[2.44,48.88],[2.56,53.5]],"batb":[[0,2.44,38.06]],"ltp":2.44,"tv":947.3,"id":5720747}],"tv":2249.95}]}
{"op":"mcm","clk":"1004538326","pt":1580632080767,"mc":[{"id":"1.168136161","rc":[{"trd":[[1.63,264.38]],"batb":[[0,1.63,355.03]],"ltp":1.63,"tv":1454.67,"id":2249229}],"tv":2401.98}]}
{"op":"mcm","clk":"1004539981","pt":1580632121585,"mc":[{"id":"1.168136161","rc":[{"batb":[[0,2.5,26.38],[1,2.44,38.06],[2,2.4,186.52]],"ltp":2.44,"tv":947.3,"id":5720747}]}]}
{"op":"mcm","clk":"1004541427","pt":1580632160773,"mc":[{"id":"1.168136161","rc":[{"batb":[[2,1.6,253.25]],"ltp":1.63,"tv":1454.67,"id":2249229}]}]}
{"op":"mcm","clk":"1004541918","pt":1580632176678,"mc":[{"id":"1.168136161","rc":[{"batl":[[0,2.52,125]],"ltp":2.44,"tv":947.3,"id":5720747}]}]}
{"op":"mcm","clk":"1004542031","pt":1580632180477,"mc":[{"id":"1.168136161","rc":[{"batb":[[1,1.6,253.25],[2,1.55,4]],"ltp":1.63,"tv":1454.67,"id":2249229}]}]}
{"op":"mcm","clk":"1004542812","pt":1580632198792,"mc":[{"id":"1.168136161","rc":[{"trd":[[1.67,27.26]],"ltp":1.67,"tv":1474.67,"id":2249229},{"trd":[[2.5,18.19],[2.52,590.22]],"batb":[[0,2.44,38.06],[1,2.4,186.52],[2,2.28,117.19]],"batl":[[0,2.52,111.95]],"ltp":2.52,"tv":986.73,"id":5720747}],"tv":2461.41}]}
{"op":"mcm","clk":"1004545348","pt":1580632254670,"mc":[{"id":"1.168136161","rc":[{"trd":[[2.52,643.01]],"batl":[[0,2.52,85.54]],"ltp":2.52,"tv":1039.53,"id":5720747}],"tv":2514.2}]}
{"op":"mcm","clk":"1004550170","pt":1580632356710,"mc":[{"id":"1.168136161","rc":[{"trd":[[2.44,69.15]],"batb":[[0,2.44,27.92]],"ltp":2.44,"tv":1059.8,"id":5720747}],"tv":2534.47}]}
{"op":"mcm","clk":"1004561615","pt":1580632626743,"mc":[{"id":"1.168136161","rc":[{"batb":[[0,1.64,500],[1,1.63,355.03],[2,1.6,253.25]],"ltp":1.67,"tv":1474.67,"id":2249229}]}]}
{"op":"mcm","clk":"1004565599","pt":1580632725589,"mc":[{"id":"1.168136161","rc":[{"batb":[[2,1.61,500]],"ltp":1.67,"tv":1474.67,"id":2249229}]}]}
{"op":"mcm","clk":"1004566805","pt":1580632752727,"mc":[{"id":"1.168136161","rc":[{"batb":[[1,1.61,500],[2,1.6,253.25]],"ltp":1.67,"tv":1474.67,"id":2249229}]}]}
{"op":"mcm","clk":"1004566846","pt":1580632753753,"mc":[{"id":"1.168136161","rc":[{"batb":[[0,1.65,355.03],[1,1.64,500],[2,1.61,500]],"ltp":1.67,"tv":1474.67,"id":2249229}]}]}
{"op":"mcm","clk":"1004568867","pt":1580632804729,"mc":[{"id":"1.168136161","rc":[{"batb":[[0,1.64,500],[1,1.61,500],[2,1.6,253.25]],"ltp":1.67,"tv":1474.67,"id":2249229}]}]}
{"op":"mcm","clk":"1004586061","pt":1580633145702,"mc":[{"id":"1.168136161","rc":[{"batl":[[0,1.69,64]],"ltp":1.67,"tv":1474.67,"id":2249229}]}]}
{"op":"mcm","clk":"1004586386","pt":1580633151547,"mc":[{"id":"1.168136161","marketDefinition":{"bspMarket":false,"turnInPlayEnabled":true,"persistenceEnabled":true,"marketBaseRate":5.0,"eventId":"29678823","eventTypeId":"2","numberOfWinners":1,"bettingType":"ODDS","marketType":"MOST_ACES","marketTime":"2020-02-02T08:30:00.000Z","suspendTime":"2020-02-02T08:30:00.000Z","bspReconciled":false,"complete":true,"inPlay":true,"crossMatching":true,"runnersVoidable":false,"numberOfActiveRunners":2,"betDelay":3,"status":"OPEN","runners":[{"status":"ACTIVE","sortPriority":1,"id":5720747,"name":"Dominic Thiem"},{"status":"ACTIVE","sortPriority":2,"id":2249229,"name":"Novak Djokovic"}],"regulators":["MR_INT"],"countryCode":"AU","discountAllowed":true,"timezone":"GMT","openDate":"2020-02-02T08:30:00.000Z","version":3148327251,"name":"Most Aces","eventName":"Thiem v Djokovic"},"rc":[{"batb":[[0,1.6,253.25],[1,1.01,0.51],[2,1.6,0]],"ltp":1.67,"tv":1474.67,"id":2249229},{"batb":[[0,1.01,0.51],[1,2.4,0],[2,2.28,0]],"ltp":2.44,"tv":1059.8,"id":5720747}]}]}
{"op":"mcm","clk":"1004593309","pt":1580633309432,"mc":[{"id":"1.168136161","rc":[{"trd":[[1.6,3.36]],"batb":[[0,1.6,251.58]],"ltp":1.6,"tv":1478.03,"id":2249229}],"tv":2537.83}]}
{"op":"mcm","clk":"1004603049","pt":1580633526670,"mc":[{"id":"1.168136161","rc":[{"trd":[[1.6,23.35]],"batb":[[0,1.6,241.59]],"ltp":1.6,"tv":1498.02,"id":2249229}],"tv":2557.82}]}
{"op":"mcm","clk":"1004604417","pt":1580633560400,"mc":[{"id":"1.168136161","rc":[{"trd":[[1.6,43.33]],"batb":[[0,1.6,231.6]],"ltp":1.6,"tv":1518.0,"id":2249229}],"tv":2577.81}]}
{"op":"mcm","clk":"1004631056","pt":1580634072765,"mc":[{"id":"1.168136161","rc":[{"batl":[[0,1.75,32]],"ltp":1.6,"tv":1518.0,"id":2249229}]}]}
{"op":"mcm","clk":"1004679668","pt":1580635067656,"mc":[{"id":"1.168136161","rc":[{"trd":[[1.75,5.57]],"batl":[[0,1.75,26.43]],"ltp":1.75,"tv":1523.57,"id":2249229},{"trd":[[2.32,9.01]],"ltp":2.32,"tv":1064.0,"id":5720747}],"tv":2587.58}]}
{"op":"mcm","clk":"1004679877","pt":1580635071580,"mc":[{"id":"1.168136161","rc":[{"batb":[[0,1.74,5.57],[1,1.6,231.6],[2,1.01,0.51]],"ltp":1.75,"tv":1523.57,"id":2249229}]}]}
{"op":"mcm","clk":"1004687420","pt":1580635220820,"mc":[{"id":"1.168136161","rc":[{"trd":[[1.75,58.43]],"batb":[[0,1.75,8.5],[1,1.74,5.57],[2,1.6,231.6]],"ltp":1.75,"tv":1576.44,"id":2249229}],"tv":2640.44}]}
{"op":"mcm","clk":"1004687566","pt":1580635223717,"mc":[{"id":"1.168136161","rc":[{"batb":[[0,1.74,32],[1,1.6,231.6],[2,1.01,0.51]],"ltp":1.75,"tv":1576.44,"id":2249229}]}]}
{"op":"mcm","clk":"1004690518","pt":1580635286805,"mc":[{"id":"1.168136161","rc":[{"batb":[[0,1.6,231.6],[1,1.01,0.51],[2,1.01,0]],"ltp":1.75,"tv":1576.44,"id":2249229}]}]}
{"op":"mcm","clk":"1004691483","pt":1580635307750,"mc":[{"id":"1.168136161","rc":[{"batl":[[0,1.79,32]],"ltp":1.75,"tv":1576.44,"id":2249229}]}]}
{"op":"mcm","clk":"1004692413","pt":1580635327557,"mc":[{"id":"1.168136161","rc":[{"batl":[[0,2.26,4.2]],"ltp":2.32,"tv":1064.0,"id":5720747}]}]}
{"op":"mcm","clk":"1004692520","pt":1580635330546,"mc":[{"id":"1.168136161","rc":[{"batl":[[0,1.8,16]],"ltp":1.75,"tv":1576.44,"id":2249229}]}]}
{"op":"mcm","clk":"1004692961","pt":1580635343775,"mc":[{"id":"1.168136161","rc":[{"trd":[[1.8,5.23]],"batl":[[0,1.8,10.77]],"ltp":1.8,"tv":1581.67,"id":2249229},{"trd":[[2.24,5.28]],"ltp":2.24,"tv":1068.2,"id":5720747}],"tv":2649.87}]}
{"op":"mcm","clk":"1004693484","pt":1580635359777,"mc":[{"id":"1.168136161","rc":[{"batl":[[0,2.5,106]],"ltp":2.24,"tv":1068.2,"id":5720747}]}]}
{"op":"mcm","clk":"1004693705","pt":1580635364677,"mc":[{"id":"1.168136161","rc":[{"trd":[[1.8,16]],"ltp":1.8,"tv":1592.44,"id":2249229},{"trd":[[2.24,13.94]],"batl":[[0,2.24,12.35],[1,2.5,106]],"ltp":2.24,"tv":1076.85,"id":5720747}],"tv":2669.29}]}
{"op":"mcm","clk":"1004694051","pt":1580635375429,"mc":[{"id":"1.168136161","rc":[{"batl":[[1,2.5,0]],"ltp":2.24,"tv":1076.85,"id":5720747}]}]}
{"op":"mcm","clk":"1004694403","pt":1580635384744,"mc":[{"id":"1.168136161","rc":[{"batl":[[0,1.94,4]],"ltp":1.8,"tv":1592.44,"id":2249229}]}]}
{"op":"mcm","clk":"1004694493","pt":1580635387728,"mc":[{"id":"1.168136161","rc":[{"batl":[[0,2.1,106],[1,2.24,12.35]],"ltp":2.24,"tv":1076.85,"id":5720747}]}]}
{"op":"mcm","clk":"1004694806","pt":1580635396624,"mc":[{"id":"1.168136161","rc":[{"trd":[[1.94,4]],"ltp":1.94,"tv":1596.44,"id":2249229},{"trd":[[2.06,3.76]],"batl":[[0,2.06,1.3],[1,2.1,106],[2,2.24,12.35]],"ltp":2.06,"tv":1080.62,"id":5720747}],"tv":2677.06}]}
{"op":"mcm","clk":"1004694842","pt":1580635397774,"mc":[{"id":"1.168136161","rc":[{"trd":[[2.06,6.37],[2.1,24.82]],"batl":[[0,2.1,93.59],[1,2.24,12.35],[2,2.24,0]],"ltp":2.1,"tv":1108.04,"id":5720747}],"tv":2704.48}]}
{"op":"mcm","clk":"1004695067","pt":1580635403540,"mc":[{"id":"1.168136161","rc":[{"batl":[[1,2.24,0]],"ltp":2.1,"tv":1108.04,"id":5720747}]}]}
{"op":"mcm","clk":"1004695265","pt":1580635408640,"mc":[{"id":"1.168136161","rc":[{"trd":[[2.1,24.87]],"batl":[[0,2.1,93.56]],"ltp":2.1,"tv":1108.1,"id":5720747}],"tv":2704.54}]}
{"op":"mcm","clk":"1004695690","pt":1580635418664,"mc":[{"id":"1.168136161","rc":[{"batb":[[0,1.92,4],[1,1.6,231.6],[2,1.01,0.51]],"ltp":1.94,"tv":1596.44,"id":2249229}]}]}
{"op":"mcm","clk":"1004696258","pt":1580635433790,"mc":[{"id":"1.168136161","rc":[{"batl":[[0,2.24,4]],"ltp":1.94,"tv":1596.44,"id":2249229}]}]}
{"op":"mcm","clk":"1004705042","pt":1580635623528,"mc":[{"id":"1.168136161","rc":[{"batl":[[0,2.02,93.56]],"ltp":2.1,"tv":1108.1,"id":5720747}]}]}
{"op":"mcm","clk":"1004709558","pt":1580635737759,"mc":[{"id":"1.168136161","rc":[{"trd":[[2.24,4]],"ltp":2.24,"tv":1600.44,"id":2249229},{"trd":[[1.8,4.97]],"batl":[[0,2.02,93.65]],"ltp":1.8,"tv":1113.07,"id":5720747}],"tv":2713.51}]}
{"op":"mcm","clk":"1004710823","pt":1580635769996,"mc":[{"id":"1.168136161","rc":[{"batl":[[0,1.8,0.09]],"ltp":1.8,"tv":1113.07,"id":5720747}]}]}
{"op":"mcm","clk":"1004711569","pt":1580635788831,"mc":[{"id":"1.168136161","rc":[{"batl":[[0,1.99,104.09]],"ltp":1.8,"tv":1113.07,"id":5720747}]}]}
{"op":"mcm","clk":"1004714865","pt":1580635871735,"mc":[{"id":"1.168136161","rc":[{"batl":[[0,1.8,3.88],[1,1.99,104]],"ltp":1.8,"tv":1113.07,"id":5720747}]}]}
{"op":"mcm","clk":"1004716369","pt":1580635910763,"mc":[{"id":"1.168136161","rc":[{"batl":[[0,1.99,104.09],[1,1.99,0]],"ltp":1.8,"tv":1113.07,"id":5720747}]}]}
{"op":"mcm","clk":"1004738059","pt":1580636407758,"mc":[{"id":"1.168136161","rc":[{"batl":[[0,1.97,16.9],[1,1.99,104]],"ltp":1.8,"tv":1113.07,"id":5720747}]}]}
{"op":"mcm","clk":"1004742616","pt":1580636496804,"mc":[{"id":"1.168136161","rc":[{"trd":[[1.8,5.16],[1.97,8.22]],"batl":[[0,1.97,12.7]],"ltp":1.97,"tv":1121.47,"id":5720747}],"tv":2721.91}]}
{"op":"mcm","clk":"1004744564","pt":1580636526762,"mc":[{"id":"1.168136161","rc":[{"batb":[[0,1.9,4.26],[1,1.01,0.51]],"ltp":1.97,"tv":1121.47,"id":5720747}]}]}
{"op":"mcm","clk":"1004750554","pt":1580636644752,"mc":[{"id":"1.168136161","rc":[{"batl":[[1,1.99,0]],"ltp":1.97,"tv":1121.47,"id":5720747}]}]}
{"op":"mcm","clk":"1004757192","pt":1580636794754,"mc":[{"id":"1.168136161","rc":[{"trd":[[1.9,8.52]],"batb":[[0,1.01,0.51],[1,1.01,0]],"batl":[[0,1.97,12.76]],"ltp":1.9,"tv":1129.99,"id":5720747}],"tv":2730.43}]}
{"op":"mcm","clk":"1004757261","pt":1580636796560,"mc":[{"id":"1.168136161","rc":[{"batl":[[0,1.97,12.7]],"ltp":1.9,"tv":1129.99,"id":5720747}]}]}
{"op":"mcm","clk":"1004760160","pt":1580636857778,"mc":[{"id":"1.168136161","rc":[{"batl":[[0,1.8,16.8]],"ltp":1.9,"tv":1129.99,"id":5720747}]}]}
{"op":"mcm","clk":"1004764140","pt":1580636935677,"mc":[{"id":"1.168136161","rc":[{"batl":[[0,1.7,16.8]],"ltp":1.9,"tv":1129.99,"id":5720747}]}]}
{"op":"mcm","clk":"1004787322","pt":1580637375629,"mc":[{"id":"1.168136161","rc":[{"batl":[[0,1.6,16.8]],"ltp":1.9,"tv":1129.99,"id":5720747}]}]}
{"op":"mcm","clk":"1004801663","pt":1580637609622,"mc":[{"id":"1.168136161","rc":[{"batl":[[0,1.6,16.8]],"ltp":1.9,"tv":1129.99,"id":5720747}]}]}
{"op":"mcm","clk":"1004804430","pt":1580637649384,"mc":[{"id":"1.168136161","rc":[{"batb":[[0,1.09,8.94],[1,1.01,0.51]],"ltp":1.9,"tv":1129.99,"id":5720747}]}]}
{"op":"mcm","clk":"1004810214","pt":1580637725721,"mc":[{"id":"1.168136161","rc":[{"batb":[[0,1.01,0.51],[1,1.01,0]],"ltp":1.9,"tv":1129.99,"id":5720747}]}]}
{"op":"mcm","clk":"1004816775","pt":1580637812787,"mc":[{"id":"1.168136161","rc":[{"batl":[[0,1.5,16.8]],"ltp":1.9,"tv":1129.99,"id":5720747}]}]}
{"op":"mcm","clk":"1004847339","pt":1580638274621,"mc":[{"id":"1.168136161","rc":[{"batb":[[0,1.14,8.55],[1,1.01,0.51]],"ltp":1.9,"tv":1129.99,"id":5720747}]}]}
{"op":"mcm","clk":"1004852020","pt":1580638331802,"mc":[{"id":"1.168136161","rc":[{"batb":[[0,1.01,0.51],[1,1.01,0]],"ltp":1.9,"tv":1129.99,"id":5720747}]}]}
{"op":"mcm","clk":"1005146111","pt":1580641128732,"mc":[{"id":"1.168136161","rc":[{"batb":[[1,1.01,0.51],[2,1.01,0]],"ltp":2.24,"tv":1600.44,"id":2249229}]}]}
{"op":"mcm","clk":"1005154244","pt":1580641188743,"mc":[{"id":"1.168136161","rc":[{"batl":[[0,1.8,16.8]],"ltp":1.9,"tv":1129.99,"id":5720747}]}]}
{"op":"mcm","clk":"1005224907","pt":1580641556730,"mc":[{"id":"1.168136161","rc":[{"batl":[[0,1.7,16.8]],"ltp":1.9,"tv":1129.99,"id":5720747}]}]}
{"op":"mcm","clk":"1005397207","pt":1580642472812,"mc":[{"id":"1.168136161","rc":[{"batl":[[0,1.6,16.8]],"ltp":1.9,"tv":1129.99,"id":5720747}]}]}
{"op":"mcm","clk":"1005510055","pt":1580643076803,"mc":[{"id":"1.168136161","rc":[{"batl":[[0,1.4,16.8]],"ltp":1.9,"tv":1129.99,"id":5720747}]}]}
{"op":"mcm","clk":"1005579587","pt":1580643430777,"mc":[{"id":"1.168136161","rc":[{"batl":[[0,1.3,16.8]],"ltp":1.9,"tv":1129.99,"id":5720747}]}]}
{"op":"mcm","clk":"1005675243","pt":1580643910653,"mc":[{"id":"1.168136161","rc":[{"batl":[[0,1.24,16.8]],"ltp":1.9,"tv":1129.99,"id":5720747}]}]}
{"op":"mcm","clk":"1005717110","pt":1580644172787,"mc":[{"id":"1.168136161","rc":[{"batl":[[0,1.2,16.8]],"ltp":1.9,"tv":1129.99,"id":5720747}]}]}
{"op":"mcm","clk":"1005792034","pt":1580644741810,"mc":[{"id":"1.168136161","rc":[{"trd":[[6,2.53]],"ltp":6.0,"tv":1602.97,"id":2249229},{"trd":[[1.2,12.68]],"batl":[[0,1.2,4.13]],"ltp":1.2,"tv":1142.67,"id":5720747}],"tv":2745.64}]}
{"op":"mcm","clk":"1005969918","pt":1580645735714,"mc":[{"id":"1.168136161","rc":[{"batl":[[0,1.1,16.8],[1,1.2,4.13]],"ltp":1.2,"tv":1142.67,"id":5720747}]}]}
{"op":"mcm","clk":"1006303049","pt":1580647552777,"mc":[{"id":"1.168136161","marketDefinition":{"bspMarket":false,"turnInPlayEnabled":true,"persistenceEnabled":true,"marketBaseRate":5.0,"eventId":"29678823","eventTypeId":"2","numberOfWinners":1,"bettingType":"ODDS","marketType":"MOST_ACES","marketTime":"2020-02-02T08:30:00.000Z","suspendTime":"2020-02-02T08:30:00.000Z","bspReconciled":false,"complete":true,"inPlay":true,"crossMatching":true,"runnersVoidable":false,"numberOfActiveRunners":2,"betDelay":3,"status":"SUSPENDED","runners":[{"status":"ACTIVE","sortPriority":1,"id":5720747,"name":"Dominic Thiem"},{"status":"ACTIVE","sortPriority":2,"id":2249229,"name":"Novak Djokovic"}],"regulators":["MR_INT"],"countryCode":"AU","discountAllowed":true,"timezone":"GMT","openDate":"2020-02-02T08:30:00.000Z","version":3148760510,"name":"Most Aces","eventName":"Thiem v Djokovic"}}]}
{"op":"mcm","clk":"1006334597","pt":1580647751236,"mc":[{"id":"1.168136161","tv":0.0}]}
{"op":"mcm","clk":"1006334749","pt":1580647752264,"mc":[{"id":"1.168136161","marketDefinition":{"bspMarket":false,"turnInPlayEnabled":true,"persistenceEnabled":true,"marketBaseRate":5.0,"eventId":"29678823","eventTypeId":"2","numberOfWinners":1,"bettingType":"ODDS","marketType":"MOST_ACES","marketTime":"2020-02-02T08:30:00.000Z","suspendTime":"2020-02-02T08:30:00.000Z","bspReconciled":false,"complete":true,"inPlay":true,"crossMatching":false,"runnersVoidable":false,"numberOfActiveRunners":0,"betDelay":3,"status":"CLOSED","settledTime":"2020-02-02T12:49:09.000Z","runners":[{"status":"WINNER","sortPriority":1,"id":5720747,"name":"Dominic Thiem"},{"status":"LOSER","sortPriority":2,"id":2249229,"name":"Novak Djokovic"}],"regulators":["MR_INT"],"countryCode":"AU","discountAllowed":true,"timezone":"GMT","openDate":"2020-02-02T08:30:00.000Z","version":3148769108,"name":"Most Aces","eventName":"Thiem v Djokovic"}}]}
