{"op":"mcm","clk":"988026418","pt":1580473742115,"mc":[{"id":"1.168135753","marketDefinition":{"bspMarket":false,"turnInPlayEnabled":true,"persistenceEnabled":true,"marketBaseRate":5.0,"eventId":"29678823","eventTypeId":"2","numberOfWinners":1,"bettingType":"ODDS","marketType":"PLAYER_B_WIN_A_SET","marketTime":"2020-02-02T08:30:00.000Z","suspendTime":"2020-02-02T08:30:00.000Z","bspReconciled":false,"complete":true,"inPlay":false,"crossMatching":false,"runnersVoidable":false,"numberOfActiveRunners":2,"betDelay":0,"status":"OPEN","runners":[{"status":"ACTIVE","sortPriority":1,"id":41364,"name":"Yes"},{"status":"ACTIVE","sortPriority":2,"id":41365,"name":"No"}],"regulators":["MR_INT"],"countryCode":"AU","discountAllowed":false,"timezone":"GMT","openDate":"2020-02-02T08:30:00.000Z","version":3143005237,"name":"Djokovic To Win A Set?","eventName":"Thiem v Djokovic"}}]}
{"op":"mcm","clk":"988026715","pt":1580473744836,"mc":[{"id":"1.168135753","marketDefinition":{"bspMarket":false,"turnInPlayEnabled":true,"persistenceEnabled":true,"marketBaseRate":5.0,"eventId":"29678823","eventTypeId":"2","numberOfWinners":1,"bettingType":"ODDS","marketType":"PLAYER_B_WIN_A_SET","marketTime":"2020-02-02T08:30:00.000Z","suspendTime":"2020-02-02T08:30:00.000Z","bspReconciled":false,"complete":true,"inPlay":false,"crossMatching":false,"runnersVoidable":false,"numberOfActiveRunners":2,"betDelay":0,"status":"OPEN","runners":[{"status":"ACTIVE","sortPriority":1,"id":41364,"name":"Yes"},{"status":"ACTIVE","sortPriority":2,"id":41365,"name":"No"}],"regulators":["MR_INT"],"countryCode":"AU","discountAllowed":true,"timezone":"GMT","openDate":"2020-02-02T08:30:00.000Z","version":3143005237,"name":"Djokovic To Win A Set?","eventName":"Thiem v Djokovic"}}]}
{"op":"mcm","clk":"988136389","pt":1580474704661,"mc":[{"id":"1.168135753","rc":[{"batb":[[0,1.01,5098.4]],"ltp":0.0,"tv":0.0,"id":41364}]}]}
{"op":"mcm","clk":"988136853","pt":1580474709149,"mc":[{"id":"1.168135753","rc":[{"batb":[[0,1.02,5098.4],[1,1.01,5098.4]],"ltp":0.0,"tv":0.0,"id":41364}]}]}
{"op":"mcm","clk":"988137561","pt":1580474714618,"mc":[{"id":"1.168135753","rc":[{"batb":[[0,1.03,2039.36],[1,1.02,5098.4],[2,1.01,5098.4]],"ltp":0.0,"tv":0.0,"id":41364}]}]}
{"op":"mcm","clk":"988267946","pt":1580475941256,"mc":[{"id":"1.168135753","rc":[{"batb":[[0,1.12,2039.36]],"ltp":0.0,"tv":0.0,"id":41365}]}]}
{"op":"mcm","clk":"988461134","pt":1580477473126,"mc":[{"id":"1.168135753","rc":[{"batl":[[0,2.9,37.84]],"ltp":0.0,"tv":0.0,"id":41364}]}]}
{"op":"mcm","clk":"988687353","pt":1580479652167,"mc":[{"id":"1.168135753","rc":[{"batb":[[0,1.03,2039.88],[1,1.02,5099.7],[2,1.01,5099.7]],"batl":[[0,2.9,37.85]],"ltp":0.0,"tv":0.0,"id":41364},{"batb":[[0,1.12,2039.88]],"ltp":0.0,"tv":0.0,"id":41365}]}]}
{"op":"mcm","clk":"988828294","pt":1580481146307,"mc":[{"id":"1.168135753","rc":[{"batl":[[0,2,6.12],[1,2.9,37.85]],"ltp":0.0,"tv":0.0,"id":41364}]}]}
{"op":"mcm","clk":"988887215","pt":1580481691034,"mc":[{"id":"1.168135753","rc":[{"batb":[[0,1.04,1784.45],[1,1.03,2039.88],[2,1.02,5099.7]],"ltp":0.0,"tv":0.0,"id":41364}]}]}
{"op":"mcm","clk":"989188952","pt":1580485268623,"mc":[{"id":"1.168135753","rc":[{"batl":[[0,32,54]],"ltp":0.0,"tv":0.0,"id":41365}]}]}
{"op":"mcm","clk":"989189468","pt":1580485275365,"mc":[{"id":"1.168135753","marketDefinition":{"bspMarket":false,"turnInPlayEnabled":true,"persistenceEnabled":true,"marketBaseRate":5.0,"eventId":"29678823","eventTypeId":"2","numberOfWinners":1,"bettingType":"ODDS","marketType":"PLAYER_B_WIN_A_SET","marketTime":"2020-02-02T08:30:00.000Z","suspendTime":"2020-02-02T08:30:00.000Z","bspReconciled":false,"complete":true,"inPlay":false,"crossMatching":true,"runnersVoidable":false,"numberOfActiveRunners":2,"betDelay":0,"status":"OPEN","runners":[{"status":"ACTIVE","sortPriority":1,"id":41364,"name":"Yes"},{"status":"ACTIVE","sortPriority":2,"id":41365,"name":"No"}],"regulators":["MR_INT"],"countryCode":"AU","discountAllowed":true,"timezone":"GMT","openDate":"2020-02-02T08:30:00.000Z","version":3143005237,"name":"Djokovic To Win A Set?","eventName":"Thiem v Djokovic"}}]}
{"op":"mcm","clk":"989340032","pt":1580486852178,"mc":[{"id":"1.168135753","rc":[{"batb":[[0,1.04,1777.47],[1,1.03,2031.9],[2,1.02,5079.75]],"batl":[[0,2,6.1],[1,2.9,37.84]],"ltp":0.0,"tv":0.0,"id":41364},{"batb":[[0,1.12,2031.9]],"ltp":0.0,"tv":0.0,"id":41365}]}]}
{"op":"mcm","clk":"990094308","pt":1580494052126,"mc":[{"id":"1.168135753","rc":[{"batb":[[0,1.04,1775.75],[1,1.03,2029.94],[2,1.02,5074.85]],"batl":[[0,2,6.09],[1,2.9,37.79]],"ltp":0.0,"tv":0.0,"id":41364},{"batb":[[0,1.12,2029.94]],"ltp":0.0,"tv":0.0,"id":41365}]}]}
{"op":"mcm","clk":"991045160","pt":1580501252131,"mc":[{"id":"1.168135753","rc":[{"batb":[[0,1.04,1774.85],[1,1.03,2028.91],[2,1.02,5072.28]],"batl":[[0,2,6.09],[1,2.9,37.8]],"ltp":0.0,"tv":0.0,"id":41364},{"batb":[[0,1.12,2028.91]],"ltp":0.0,"tv":0.0,"id":41365}]}]}
{"op":"mcm","clk":"991391729","pt":1580503476663,"mc":[{"id":"1.168135753","rc":[{"batl":[[0,1.35,20.29],[1,2,6.09],[2,2.9,37.8]],"ltp":0.0,"tv":0.0,"id":41364}]}]}
{"op":"mcm","clk":"991483641","pt":1580504355828,"mc":[{"id":"1.168135753","rc":[{"trd":[[1.04,8.4]],"batb":[[0,1.04,1770.65]],"ltp":1.04,"tv":8.39,"id":41364}],"tv":8.39}]}
{"op":"mcm","clk":"991806450","pt":1580508452143,"mc":[{"id":"1.168135753","rc":[{"trd":[[1.04,8.39]],"batb":[[0,1.04,1768.14],[1,1.03,2026.03],[2,1.02,5065.09]],"batl":[[0,1.35,20.26],[1,2,6.08],[2,2.9,37.81]],"ltp":1.04,"tv":8.39,"id":41364},{"batb":[[0,1.12,2026.03]],"ltp":0.0,"tv":0.0,"id":41365}],"tv":8.39}]}
{"op":"mcm","clk":"991991690","pt":1580511709642,"mc":[{"id":"1.168135753","rc":[{"batb":[[1,1.01,2.53]],"ltp":0.0,"tv":0.0,"id":41365}]}]}
{"op":"mcm","clk":"991991744","pt":1580511710728,"mc":[{"id":"1.168135753","rc":[{"batb":[[1,1.01,0.51]],"ltp":0.0,"tv":0.0,"id":41365}]}]}
{"op":"mcm","clk":"992004319","pt":1580511986381,"mc":[{"id":"1.168135753","rc":[{"batb":[[1,1.01,3.04]],"ltp":0.0,"tv":0.0,"id":41365}]}]}
{"op":"mcm","clk":"992004377","pt":1580511987459,"mc":[{"id":"1.168135753","rc":[{"batb":[[1,1.01,1.01]],"ltp":0.0,"tv":0.0,"id":41365}]}]}
{"op":"mcm","clk":"992048575","pt":1580512813534,"mc":[{"id":"1.168135753","rc":[{"batb":[[0,3.9,50.65],[1,1.12,2026.03],[2,1.01,1.01]],"ltp":0.0,"tv":0.0,"id":41365}]}]}
{"op":"mcm","clk":"992543428","pt":1580525362227,"mc":[{"id":"1.168135753","rc":[{"batl":[[0,1.12,107.38],[1,1.35,20.26],[2,2,6.08]],"ltp":1.04,"tv":8.39,"id":41364}]}]}
{"op":"mcm","clk":"993875119","pt":1580547211688,"mc":[{"id":"1.168135753","rc":[{"batb":[[0,1.05,2.52],[1,1.04,1768.14],[2,1.03,2026.03]],"ltp":1.04,"tv":8.39,"id":41364}]}]}
{"op":"mcm","clk":"994347815","pt":1580551313505,"mc":[{"id":"1.168135753","rc":[{"batb":[[0,1.04,1768.14],[1,1.03,2026.03],[2,1.02,5065.09]],"ltp":1.04,"tv":8.39,"id":41364}]}]}
{"op":"mcm","clk":"997583802","pt":1580567414241,"mc":[{"id":"1.168135753","rc":[{"batl":[[0,1.1,5535],[1,1.12,107.38],[2,1.35,20.26]],"ltp":1.04,"tv":8.39,"id":41364}]}]}
{"op":"mcm","clk":"998508935","pt":1580571109350,"mc":[{"id":"1.168135753","rc":[{"batb":[[0,1.05,3.36],[1,1.04,1768.14],[2,1.03,2026.03]],"ltp":1.04,"tv":8.39,"id":41364}]}]}
{"op":"mcm","clk":"999937969","pt":1580577666629,"mc":[{"id":"1.168135753","rc":[{"batb":[[0,1.04,1768.14],[1,1.03,2026.03],[2,1.02,5065.09]],"ltp":1.04,"tv":8.39,"id":41364}]}]}
{"op":"mcm","clk":"1000417450","pt":1580580820390,"mc":[{"id":"1.168135753","rc":[{"batl":[[0,1.06,1893.08],[1,1.1,5535],[2,1.12,107.38]],"ltp":1.04,"tv":8.39,"id":41364}]}]}
{"op":"mcm","clk":"1001566558","pt":1580587451852,"mc":[{"id":"1.168135753","rc":[{"batl":[[0,1.05,100],[1,1.06,1893.08],[2,1.1,5535]],"ltp":1.04,"tv":8.39,"id":41364}]}]}
{"op":"mcm","clk":"1002096715","pt":1580590463850,"mc":[{"id":"1.168135753","rc":[{"batl":[[2,1.08,1.93]],"ltp":1.04,"tv":8.39,"id":41364}]}]}
{"op":"mcm","clk":"1002148779","pt":1580590930119,"mc":[{"id":"1.168135753","rc":[{"trd":[[1.04,32.38]],"batb":[[0,1.04,1756.15]],"ltp":1.04,"tv":32.38,"id":41364}],"tv":32.38}]}
{"op":"mcm","clk":"1002447586","pt":1580593812239,"mc":[{"id":"1.168135753","rc":[{"trd":[[1.04,546.32]],"batb":[[0,1.04,1499.31]],"ltp":1.04,"tv":546.32,"id":41364}],"tv":546.32}]}
{"op":"mcm","clk":"1002483141","pt":1580594269252,"mc":[{"id":"1.168135753","rc":[{"trd":[[1.04,556.58]],"batb":[[0,1.04,1494.19]],"ltp":1.04,"tv":556.57,"id":41364}],"tv":556.57}]}
{"op":"mcm","clk":"1002527702","pt":1580594940511,"mc":[{"id":"1.168135753","rc":[{"batb":[[0,1.04,1719.14]],"ltp":1.04,"tv":556.57,"id":41364}]}]}
{"op":"mcm","clk":"1002558536","pt":1580595319445,"mc":[{"id":"1.168135753","rc":[{"batl":[[0,1.06,1893.08],[1,1.08,1.93],[2,1.1,5535]],"ltp":1.04,"tv":556.57,"id":41364}]}]}
{"op":"mcm","clk":"1002562162","pt":1580595364677,"mc":[{"id":"1.168135753","rc":[{"batb":[[0,18,14.69],[1,3.9,50.65],[2,1.12,2026.03]],"ltp":0.0,"tv":0.0,"id":41365}]}]}
{"op":"mcm","clk":"1002686765","pt":1580597251043,"mc":[{"id":"1.168135753","rc":[{"batl":[[0,1.05,117.92],[1,1.06,1893.08],[2,1.08,1.93]],"ltp":1.04,"tv":556.57,"id":41364}]}]}
{"op":"mcm","clk":"1002693017","pt":1580597356500,"mc":[{"id":"1.168135753","rc":[{"trd":[[1.05,6.72]],"batl":[[0,1.05,114.56]],"ltp":1.05,"tv":563.3,"id":41364}],"tv":563.3}]}
{"op":"mcm","clk":"1002746608","pt":1580598185246,"mc":[{"id":"1.168135753","rc":[{"batb":[[1,1.12,2026.03],[2,1.01,1.01]],"ltp":0.0,"tv":0.0,"id":41365}]}]}
{"op":"mcm","clk":"1002797148","pt":1580598886460,"mc":[{"id":"1.168135753","rc":[{"trd":[[1.05,235.72]],"batb":[[0,1.05,1405.09],[1,1.04,1719.14],[2,1.03,2026.03]],"batl":[[0,1.06,1893.08],[1,1.08,1.93],[2,1.1,5535]],"ltp":1.05,"tv":792.3,"id":41364}],"tv":792.3}]}
{"op":"mcm","clk":"1002812311","pt":1580599105512,"mc":[{"id":"1.168135753","rc":[{"batb":[[1,1.04,2225.64]],"ltp":1.05,"tv":792.3,"id":41364}]}]}
{"op":"mcm","clk":"1002963952","pt":1580601264586,"mc":[{"id":"1.168135753","rc":[{"trd":[[1.06,4033.67]],"batb":[[0,1.06,391.95],[1,1.05,1405.09],[2,1.04,2225.64]],"batl":[[0,1.08,1.93],[1,1.1,5535],[2,1.12,107.38]],"ltp":1.06,"tv":4825.97,"id":41364},{"trd":[[18,14.69]],"batb":[[0,1.12,2026.03],[1,1.01,1.01],[2,1.01,0]],"batl":[[0,18,15.2],[1,32,54]],"ltp":18.0,"tv":14.68,"id":41365}],"tv":4840.66}]}
{"op":"mcm","clk":"1002970497","pt":1580601359685,"mc":[{"id":"1.168135753","rc":[{"batl":[[0,19.5,15.2]],"ltp":18.0,"tv":14.68,"id":41365}]}]}
{"op":"mcm","clk":"1002978380","pt":1580601465914,"mc":[{"id":"1.168135753","rc":[{"batb":[[2,1.04,2732.15]],"ltp":1.06,"tv":4825.97,"id":41364}]}]}
{"op":"mcm","clk":"1003083305","pt":1580602749171,"mc":[{"id":"1.168135753","rc":[{"batb":[[0,15.5,5.57],[1,1.12,2026.03],[2,1.01,1.01]],"ltp":18.0,"tv":14.68,"id":41365}]}]}
{"op":"mcm","clk":"1003083799","pt":1580602755471,"mc":[{"id":"1.168135753","rc":[{"batb":[[1,15,6.08],[2,1.12,2026.03]],"ltp":18.0,"tv":14.68,"id":41365}]}]}
{"op":"mcm","clk":"1003084209","pt":1580602760777,"mc":[{"id":"1.168135753","rc":[{"batb":[[2,14.5,6.08]],"ltp":18.0,"tv":14.68,"id":41365}]}]}
{"op":"mcm","clk":"1003086935","pt":1580602799174,"mc":[{"id":"1.168135753","rc":[{"trd":[[1.06,4037.03]],"batb":[[0,1.06,390.28]],"ltp":1.06,"tv":4829.32,"id":41364}],"tv":4844.01}]}
{"op":"mcm","clk":"1003181876","pt":1580604028226,"mc":[{"id":"1.168135753","rc":[{"trd":[[1.06,4040.38]],"batb":[[0,1.06,388.6]],"ltp":1.06,"tv":4832.68,"id":41364}],"tv":4847.37}]}
{"op":"mcm","clk":"1003205578","pt":1580604422658,"mc":[{"id":"1.168135753","rc":[{"batb":[[0,1.05,1405.09],[1,1.04,2732.15],[2,1.03,2026.03]],"ltp":1.06,"tv":4832.68,"id":41364}]}]}
{"op":"mcm","clk":"1003269322","pt":1580605454534,"mc":[{"id":"1.168135753","rc":[{"batb":[[2,1.01,1.01]],"batl":[[2,1.35,20.26]],"ltp":1.06,"tv":4832.68,"id":41364}]}]}
{"op":"mcm","clk":"1003286732","pt":1580605697327,"mc":[{"id":"1.168135753","rc":[{"batl":[[0,1.06,11.14],[1,1.08,1.93],[2,1.1,5535]],"ltp":1.06,"tv":4832.68,"id":41364}]}]}
{"op":"mcm","clk":"1003320107","pt":1580606176818,"mc":[{"id":"1.168135753","rc":[{"trd":[[1.05,239.08]],"batb":[[0,1.05,1403.41]],"ltp":1.05,"tv":4836.04,"id":41364}],"tv":4850.73}]}
{"op":"mcm","clk":"1003332976","pt":1580606336749,"mc":[{"id":"1.168135753","rc":[{"batl":[[0,1.08,1.93],[1,1.1,5535],[2,1.35,20.26]],"ltp":1.05,"tv":4836.04,"id":41364}]}]}
{"op":"mcm","clk":"1003350909","pt":1580606598929,"mc":[{"id":"1.168135753","rc":[{"batl":[[1,1.35,20.26],[2,2.9,37.81]],"ltp":1.05,"tv":4836.04,"id":41364}]}]}
{"op":"mcm","clk":"1003414328","pt":1580607423681,"mc":[{"id":"1.168135753","rc":[{"batl":[[0,18,111.36],[1,19.5,15.2],[2,32,54]],"ltp":18.0,"tv":14.68,"id":41365}]}]}
{"op":"mcm","clk":"1003486599","pt":1580608417127,"mc":[{"id":"1.168135753","rc":[{"batb":[[0,16,1.51],[1,15.5,5.57],[2,15,6.08]],"ltp":18.0,"tv":14.68,"id":41365}]}]}
{"op":"mcm","clk":"1003605519","pt":1580610135708,"mc":[{"id":"1.168135753","rc":[{"trd":[[1.05,2062.51]],"batb":[[0,1.05,491.69]],"ltp":1.05,"tv":6659.47,"id":41364}],"tv":6674.16}]}
{"op":"mcm","clk":"1003680923","pt":1580611152721,"mc":[{"id":"1.168135753","rc":[{"batl":[[0,1.06,900],[1,1.08,1.93],[2,1.35,20.26]],"ltp":1.05,"tv":6659.47,"id":41364}]}]}
{"op":"mcm","clk":"1003680974","pt":1580611153438,"mc":[{"id":"1.168135753","rc":[{"batb":[[0,1.05,603.72]],"ltp":1.05,"tv":6659.47,"id":41364},{"batb":[[0,16.5,7.12],[1,16,1.51],[2,15.5,5.57]],"ltp":18.0,"tv":14.68,"id":41365}]}]}
{"op":"mcm","clk":"1003687284","pt":1580611253546,"mc":[{"id":"1.168135753","rc":[{"trd":[[18,17.72]],"batb":[[0,16,7.23],[1,15.5,5.57],[2,15,6.08]],"batl":[[0,18,109.84]],"ltp":18.0,"tv":17.71,"id":41365}],"tv":6677.19}]}
{"op":"mcm","clk":"1003711370","pt":1580611663778,"mc":[{"id":"1.168135753","rc":[{"batb":[[2,1.01,3.01]],"ltp":1.05,"tv":6659.47,"id":41364}]}]}
{"op":"mcm","clk":"1003711979","pt":1580611675479,"mc":[{"id":"1.168135753","rc":[{"batb":[[2,1.01,3.09]],"ltp":1.05,"tv":6659.47,"id":41364}]}]}
{"op":"mcm","clk":"1003712484","pt":1580611685221,"mc":[{"id":"1.168135753","rc":[{"trd":[[1.06,4040.54]],"batb":[[2,1.01,3.01]],"batl":[[0,1.06,899.92]],"ltp":1.06,"tv":6659.63,"id":41364}],"tv":6677.35}]}
{"op":"mcm","clk":"1003712807","pt":1580611691332,"mc":[{"id":"1.168135753","rc":[{"batb":[[2,1.01,1.01]],"ltp":1.06,"tv":6659.63,"id":41364}]}]}
{"op":"mcm","clk":"1003884946","pt":1580615213290,"mc":[{"id":"1.168135753","rc":[{"trd":[[1.05,2085.08]],"batb":[[0,1.05,592.44]],"ltp":1.05,"tv":6682.2,"id":41364}],"tv":6699.92}]}
{"op":"mcm","clk":"1004147115","pt":1580621369421,"mc":[{"id":"1.168135753","rc":[{"trd":[[1.05,2236.45]],"batb":[[0,1.05,516.79]],"ltp":1.05,"tv":6833.57,"id":41364}],"tv":6851.29}]}
{"op":"mcm","clk":"1004198868","pt":1580622880000,"mc":[{"id":"1.168135753","rc":[{"trd":[[1.05,2249.95]],"batb":[[0,1.05,510.04]],"ltp":1.05,"tv":6847.07,"id":41364}],"tv":6864.79}]}
{"op":"mcm","clk":"1004258909","pt":1580624824806,"mc":[{"id":"1.168135753","rc":[{"trd":[[1.05,5435.97]],"batb":[[0,1.04,2732.15],[1,1.01,1.01],[2,1.01,0]],"batl":[[0,1.05,2063.54],[1,1.06,899.92],[2,1.08,1.93]],"ltp":1.05,"tv":10033.09,"id":41364},{"trd":[[18,127.56],[19.5,15.2]],"batl":[[0,32,54],[1,19.5,0],[2,32,0]],"ltp":19.5,"tv":142.75,"id":41365}],"tv":10175.84}]}
{"op":"mcm","clk":"1004284876","pt":1580625662577,"mc":[{"id":"1.168135753","rc":[{"trd":[[1.04,607.23]],"batb":[[0,1.04,2706.83]],"ltp":1.04,"tv":10083.74,"id":41364}],"tv":10226.5}]}
{"op":"mcm","clk":"1004294205","pt":1580626038555,"mc":[{"id":"1.168135753","rc":[{"trd":[[1.05,9560.96]],"batb":[[0,1.05,471.09],[1,1.04,2706.83],[2,1.01,1.01]],"batl":[[0,1.06,899.92],[1,1.08,1.93],[2,1.35,20.26]],"ltp":1.05,"tv":14208.73,"id":41364}],"tv":14351.48}]}
{"op":"mcm","clk":"1004295136","pt":1580626070790,"mc":[{"id":"1.168135753","rc":[{"batb":[[0,1.05,724.35]],"ltp":1.05,"tv":14208.73,"id":41364}]}]}
{"op":"mcm","clk":"1004316285","pt":1580626710527,"mc":[{"id":"1.168135753","rc":[{"trd":[[1.06,4138.98]],"batl":[[0,1.06,850.7]],"ltp":1.06,"tv":14307.17,"id":41364}],"tv":14449.92}]}
{"op":"mcm","clk":"1004335511","pt":1580627316364,"mc":[{"id":"1.168135753","rc":[{"trd":[[1.05,9590]],"batb":[[0,1.05,709.83]],"ltp":1.05,"tv":14336.21,"id":41364}],"tv":14478.97}]}
{"op":"mcm","clk":"1004338634","pt":1580627408809,"mc":[{"id":"1.168135753","rc":[{"trd":[[1.05,9613.3]],"batb":[[0,1.05,698.18]],"ltp":1.05,"tv":14359.51,"id":41364}],"tv":14502.27}]}
{"op":"mcm","clk":"1004364962","pt":1580628065539,"mc":[{"id":"1.168135753","rc":[{"batb":[[0,18,6.98],[1,16,7.23],[2,15.5,5.57]],"ltp":19.5,"tv":142.75,"id":41365}]}]}
{"op":"mcm","clk":"1004365754","pt":1580628080363,"mc":[{"id":"1.168135753","rc":[{"trd":[[1.05,9615.3]],"batb":[[0,1.05,697.18]],"ltp":1.05,"tv":14361.51,"id":41364}],"tv":14504.27}]}
{"op":"mcm","clk":"1004374035","pt":1580628282706,"mc":[{"id":"1.168135753","rc":[{"batl":[[0,1.06,854.9]],"ltp":1.05,"tv":14361.51,"id":41364}]}]}
{"op":"mcm","clk":"1004376407","pt":1580628349217,"mc":[{"id":"1.168135753","rc":[{"trd":[[1.05,9669.55]],"batb":[[0,1.05,670.06]],"ltp":1.05,"tv":14415.76,"id":41364}],"tv":14558.52}]}
{"op":"mcm","clk":"1004377314","pt":1580628367128,"mc":[{"id":"1.168135753","rc":[{"trd":[[1.05,9693.77]],"batb":[[0,1.05,657.95]],"ltp":1.05,"tv":14439.98,"id":41364}],"tv":14582.74}]}
{"op":"mcm","clk":"1004381495","pt":1580628466861,"mc":[{"id":"1.168135753","rc":[{"trd":[[1.05,9739.59]],"batb":[[0,1.05,635.05]],"ltp":1.05,"tv":14485.8,"id":41364}],"tv":14628.56}]}
{"op":"mcm","clk":"1004396206","pt":1580628830827,"mc":[{"id":"1.168135753","rc":[{"trd":[[1.05,9935.89]],"batb":[[0,1.05,536.89]],"ltp":1.05,"tv":14682.1,"id":41364}],"tv":14824.86}]}
{"op":"mcm","clk":"1004427109","pt":1580629602570,"mc":[{"id":"1.168135753","rc":[{"batl":[[0,1.06,1254.9]],"ltp":1.05,"tv":14682.1,"id":41364}]}]}
{"op":"mcm","clk":"1004433720","pt":1580629747264,"mc":[{"id":"1.168135753","rc":[{"batb":[[2,1.01,169.68]],"ltp":1.05,"tv":14682.1,"id":41364}]}]}
{"op":"mcm","clk":"1004434566","pt":1580629765509,"mc":[{"id":"1.168135753","rc":[{"batb":[[2,1.02,88.64]],"ltp":1.05,"tv":14682.1,"id":41364}]}]}
{"op":"mcm","clk":"1004456506","pt":1580630253518,"mc":[{"id":"1.168135753","rc":[{"trd":[[1.05,10162.94]],"batb":[[0,1.05,423.43]],"ltp":1.05,"tv":14909.15,"id":41364}],"tv":15051.91}]}
{"op":"mcm","clk":"1004459215","pt":1580630312512,"mc":[{"id":"1.168135753","rc":[{"trd":[[1.05,10373.55]],"batb":[[0,1.05,318.12]],"ltp":1.05,"tv":15119.76,"id":41364}],"tv":15262.52}]}
{"op":"mcm","clk":"1004478168","pt":1580630712720,"mc":[{"id":"1.168135753","rc":[{"trd":[[1.05,10384.9]],"batb":[[0,1.05,312.45]],"ltp":1.05,"tv":15131.11,"id":41364}],"tv":15273.87}]}
{"op":"mcm","clk":"1004497493","pt":1580631154382,"mc":[{"id":"1.168135753","rc":[{"batl":[[0,1.06,854.9]],"ltp":1.05,"tv":15131.11,"id":41364}]}]}
{"op":"mcm","clk":"1004516202","pt":1580631593930,"mc":[{"id":"1.168135753","rc":[{"batb":[[0,1.05,788.64]],"ltp":1.05,"tv":15131.11,"id":41364}]}]}
{"op":"mcm","clk":"1004516240","pt":1580631595107,"mc":[{"id":"1.168135753","rc":[{"batl":[[1,1.07,467.28],[2,1.08,1.93]],"ltp":1.05,"tv":15131.11,"id":41364}]}]}
{"op":"mcm","clk":"1004536137","pt":1580632021493,"mc":[{"id":"1.168135753","rc":[{"trd":[[1.05,10688.81]],"batb":[[0,1.05,636.69]],"ltp":1.05,"tv":15435.02,"id":41364}],"tv":15577.77}]}
{"op":"mcm","clk":"1004540061","pt":1580632124609,"mc":[{"id":"1.168135753","rc":[{"batl":[[0,1.06,965.87]],"ltp":1.05,"tv":15435.02,"id":41364},{"batb":[[0,18,1.32],[1,15.5,5.57],[2,15,6.08]],"ltp":19.5,"tv":142.75,"id":41365}]}]}
{"op":"mcm","clk":"1004541811","pt":1580632172764,"mc":[{"id":"1.168135753","rc":[{"trd":[[1.05,10912.76]],"batb":[[0,1.05,524.77]],"batl":[[0,1.06,854.9]],"ltp":1.05,"tv":15658.97,"id":41364}],"tv":15801.72}]}
{"op":"mcm","clk":"1004552928","pt":1580632413605,"mc":[{"id":"1.168135753","rc":[{"batl":[[0,1.06,915.9]],"ltp":1.05,"tv":15658.97,"id":41364}]}]}
{"op":"mcm","clk":"1004553132","pt":1580632418702,"mc":[{"id":"1.168135753","rc":[{"batl":[[0,1.06,854.9]],"ltp":1.05,"tv":15658.97,"id":41364}]}]}
{"op":"mcm","clk":"1004554094","pt":1580632441320,"mc":[{"id":"1.168135753","rc":[{"trd":[[1.05,10962.9]],"batb":[[0,1.05,499.7]],"ltp":1.05,"tv":15709.11,"id":41364}],"tv":15851.87}]}
{"op":"mcm","clk":"1004554129","pt":1580632442408,"mc":[{"id":"1.168135753","rc":[{"batl":[[0,1.06,915.9]],"ltp":1.05,"tv":15709.11,"id":41364}]}]}
{"op":"mcm","clk":"1004554195","pt":1580632445149,"mc":[{"id":"1.168135753","rc":[{"batb":[[1,1.04,4573.74]],"ltp":1.05,"tv":15709.11,"id":41364}]}]}
{"op":"mcm","clk":"1004563441","pt":1580632672818,"mc":[{"id":"1.168135753","rc":[{"trd":[[1.05,11007.47]],"batb":[[0,1.05,477.41]],"ltp":1.05,"tv":15753.68,"id":41364}],"tv":15896.44}]}
{"op":"mcm","clk":"1004568702","pt":1580632800306,"mc":[{"id":"1.168135753","rc":[{"batb":[[0,1.05,1.22]],"batl":[[1,1.08,1.93],[2,1.35,20.26]],"ltp":1.05,"tv":15753.68,"id":41364}]}]}
{"op":"mcm","clk":"1004573962","pt":1580632904709,"mc":[{"id":"1.168135753","rc":[{"trd":[[1.05,11009.91]],"batb":[[0,1.04,4573.74],[1,1.02,88.64],[2,1.01,169.68]],"batl":[[0,1.05,13.93],[1,1.06,915.9],[2,1.08,1.93]],"ltp":1.05,"tv":15756.12,"id":41364}],"tv":15898.88}]}
{"op":"mcm","clk":"1004582403","pt":1580633068629,"mc":[{"id":"1.168135753","rc":[{"batb":[[0,1.04,2879.93]],"ltp":1.05,"tv":15756.12,"id":41364},{"batb":[[0,15.5,5.57],[1,15,6.08],[2,14.5,6.08]],"ltp":19.5,"tv":142.75,"id":41365}]}]}
{"op":"mcm","clk":"1004582864","pt":1580633077751,"mc":[{"id":"1.168135753","rc":[{"trd":[[1.04,746.01]],"batb":[[0,1.04,2810.54]],"ltp":1.04,"tv":15894.91,"id":41364}],"tv":16037.66}]}
{"op":"mcm","clk":"1004586386","pt":1580633151547,"mc":[{"id":"1.168135753","marketDefinition":{"bspMarket":false,"turnInPlayEnabled":true,"persistenceEnabled":true,"marketBaseRate":5.0,"eventId":"29678823","eventTypeId":"2","numberOfWinners":1,"bettingType":"ODDS","marketType":"PLAYER_B_WIN_A_SET","marketTime":"2020-02-02T08:30:00.000Z","suspendTime":"2020-02-02T08:30:00.000Z","bspReconciled":false,"complete":true,"inPlay":true,"crossMatching":true,"runnersVoidable":false,"numberOfActiveRunners":2,"betDelay":3,"status":"OPEN","runners":[{"status":"ACTIVE","sortPriority":1,"id":41364,"name":"Yes"},{"status":"ACTIVE","sortPriority":2,"id":41365,"name":"No"}],"regulators":["MR_INT"],"countryCode":"AU","discountAllowed":true,"timezone":"GMT","openDate":"2020-02-02T08:30:00.000Z","version":3148327221,"name":"Djokovic To Win A Set?","eventName":"Thiem v Djokovic"},"rc":[{"batb":[[0,1.02,88.64],[1,1.01,169.17],[2,1.01,0]],"batl":[[1,1.08,1.93],[2,1.08,0]],"ltp":1.04,"tv":15894.91,"id":41364},{"batb":[[0,1.01,0.52],[1,15,0],[2,14.5,0]],"ltp":19.5,"tv":142.75,"id":41365}]}]}
{"op":"mcm","clk":"1004603088","pt":1580633527695,"mc":[{"id":"1.168135753","rc":[{"batb":[[0,1.02,103.03]],"ltp":1.04,"tv":15894.91,"id":41364}]}]}
{"op":"mcm","clk":"1004619887","pt":1580633884765,"mc":[{"id":"1.168135753","rc":[{"batb":[[1,1.01,171.45]],"ltp":1.04,"tv":15894.91,"id":41364}]}]}
{"op":"mcm","clk":"1004620591","pt":1580633898607,"mc":[{"id":"1.168135753","rc":[{"batb":[[1,1.01,169.17]],"ltp":1.04,"tv":15894.91,"id":41364}]}]}
{"op":"mcm","clk":"1004623164","pt":1580633944785,"mc":[{"id":"1.168135753","rc":[{"batb":[[0,1.02,88.64]],"ltp":1.04,"tv":15894.91,"id":41364}]}]}
{"op":"mcm","clk":"1004627246","pt":1580634011650,"mc":[{"id":"1.168135753","rc":[{"batl":[[1,1.08,0]],"ltp":1.04,"tv":15894.91,"id":41364}]}]}
{"op":"mcm","clk":"1004628598","pt":1580634032783,"mc":[{"id":"1.168135753","rc":[{"trd":[[1.02,177.37]],"batb":[[0,1.01,169.17],[1,1.01,0]],"batl":[[0,1.02,698.08],[1,1.05,13.93]],"ltp":1.02,"tv":16072.28,"id":41364}],"tv":16215.04}]}
{"op":"mcm","clk":"1004647583","pt":1580634416660,"mc":[{"id":"1.168135753","rc":[{"trd":[[1.01,15.13]],"batb":[[0,1.01,161.61]],"ltp":1.01,"tv":16087.41,"id":41364}],"tv":16230.17}]}
{"op":"mcm","clk":"1004653823","pt":1580634551191,"mc":[{"id":"1.168135753","rc":[{"batl":[[0,1.02,824.74]],"ltp":1.01,"tv":16087.41,"id":41364}]}]}
{"op":"mcm","clk":"1004654950","pt":1580634577517,"mc":[{"id":"1.168135753","rc":[{"batl":[[1,1.03,154.52],[2,1.05,13.93]],"ltp":1.01,"tv":16087.41,"id":41364}]}]}
{"op":"mcm","clk":"1004665580","pt":1580634802774,"mc":[{"id":"1.168135753","rc":[{"batl":[[0,1.02,698.08]],"ltp":1.01,"tv":16087.41,"id":41364}]}]}
{"op":"mcm","clk":"1004665718","pt":1580634805608,"mc":[{"id":"1.168135753","rc":[{"trd":[[1.01,268.32]],"batb":[[0,1.01,35.09]],"ltp":1.01,"tv":16340.6,"id":41364}],"tv":16483.36}]}
{"op":"mcm","clk":"1004666290","pt":1580634815689,"mc":[{"id":"1.168135753","rc":[{"batl":[[1,1.05,13.93],[2,1.05,0]],"ltp":1.01,"tv":16340.6,"id":41364}]}]}
{"op":"mcm","clk":"1004666477","pt":1580634818518,"mc":[{"id":"1.168135753","rc":[{"batl":[[0,1.02,852.61]],"ltp":1.01,"tv":16340.6,"id":41364}]}]}
{"op":"mcm","clk":"1004668850","pt":1580634859657,"mc":[{"id":"1.168135753","rc":[{"batl":[[0,1.02,698.08]],"ltp":1.01,"tv":16340.6,"id":41364}]}]}
{"op":"mcm","clk":"1004669033","pt":1580634862605,"mc":[{"id":"1.168135753","rc":[{"trd":[[1.01,338.53]],"batl":[[0,1.01,119.4],[1,1.02,698.08],[2,1.05,13.93]],"ltp":1.01,"tv":16410.81,"id":41364}],"tv":16553.56}]}
{"op":"mcm","clk":"1004669556","pt":1580634871807,"mc":[{"id":"1.168135753","rc":[{"batl":[[0,1.02,698.08],[1,1.05,13.93],[2,1.05,0]],"ltp":1.01,"tv":16410.81,"id":41364}]}]}
{"op":"mcm","clk":"1004669719","pt":1580634874705,"mc":[{"id":"1.168135753","rc":[{"batl":[[0,1.02,817.49]],"ltp":1.01,"tv":16410.81,"id":41364}]}]}
{"op":"mcm","clk":"1004672316","pt":1580634925033,"mc":[{"id":"1.168135753","rc":[{"batl":[[0,1.02,698.08]],"ltp":1.01,"tv":16410.81,"id":41364}]}]}
{"op":"mcm","clk":"1004672507","pt":1580634928745,"mc":[{"id":"1.168135753","rc":[{"batl":[[0,1.01,119.4],[1,1.02,698.08],[2,1.05,13.93]],"ltp":1.01,"tv":16410.81,"id":41364}]}]}
{"op":"mcm","clk":"1004677590","pt":1580635026720,"mc":[{"id":"1.168135753","rc":[{"trd":[[1.01,367.3]],"batl":[[0,1.01,105.01]],"ltp":1.01,"tv":16439.58,"id":41364}],"tv":16582.34}]}
{"op":"mcm","clk":"1004678253","pt":1580635039621,"mc":[{"id":"1.168135753","rc":[{"trd":[[1.01,388.51]],"batl":[[0,1.01,94.41]],"ltp":1.01,"tv":16460.79,"id":41364}],"tv":16603.54}]}
{"op":"mcm","clk":"1004679727","pt":1580635068682,"mc":[{"id":"1.168135753","rc":[{"trd":[[1.01,399.11]],"batl":[[0,1.01,89.11]],"ltp":1.01,"tv":16471.39,"id":41364}],"tv":16614.14}]}
{"op":"mcm","clk":"1004681042","pt":1580635092591,"mc":[{"id":"1.168135753","rc":[{"trd":[[1.01,421.82]],"batl":[[0,1.01,77.75]],"ltp":1.01,"tv":16494.1,"id":41364}],"tv":16636.86}]}
{"op":"mcm","clk":"1004681148","pt":1580635094598,"mc":[{"id":"1.168135753","rc":[{"batl":[[1,1.05,13.93],[2,1.05,0]],"ltp":1.01,"tv":16494.1,"id":41364}]}]}
{"op":"mcm","clk":"1004681318","pt":1580635097794,"mc":[{"id":"1.168135753","rc":[{"batl":[[2,2,698.08]],"ltp":1.01,"tv":16494.1,"id":41364}]}]}
{"op":"mcm","clk":"1004681612","pt":1580635102799,"mc":[{"id":"1.168135753","rc":[{"batl":[[0,1.05,13.93],[1,2,698.08],[2,2,0]],"ltp":1.01,"tv":16494.1,"id":41364}]}]}
{"op":"mcm","clk":"1004681789","pt":1580635105518,"mc":[{"id":"1.168135753","rc":[{"batl":[[0,1.02,77.75],[1,1.05,13.93],[2,2,698.08]],"ltp":1.01,"tv":16494.1,"id":41364}]}]}
{"op":"mcm","clk":"1004684863","pt":1580635164783,"mc":[{"id":"1.168135753","rc":[{"trd":[[1.02,332.88]],"batb":[[0,1.02,5.43]],"batl":[[0,1.05,13.93],[1,2,698.08],[2,2,0]],"ltp":1.02,"tv":16649.61,"id":41364}],"tv":16792.36}]}
{"op":"mcm","clk":"1004724670","pt":1580636099251,"mc":[{"id":"1.168135753","rc":[{"batl":[[1,2,0]],"ltp":1.02,"tv":16649.61,"id":41364}]}]}
{"op":"mcm","clk":"1004724786","pt":1580636102360,"mc":[{"id":"1.168135753","rc":[{"batl":[[0,1.01,698.08],[1,1.05,13.93]],"ltp":1.02,"tv":16649.61,"id":41364}]}]}
{"op":"mcm","clk":"1004728061","pt":1580636178649,"mc":[{"id":"1.168135753","rc":[{"batl":[[0,1.05,13.93],[1,1.05,0]],"ltp":1.02,"tv":16649.61,"id":41364}]}]}
{"op":"mcm","clk":"1004728198","pt":1580636181757,"mc":[{"id":"1.168135753","rc":[{"batl":[[0,1.02,698.08],[1,1.05,13.93]],"ltp":1.02,"tv":16649.61,"id":41364}]}]}
{"op":"mcm","clk":"1004734350","pt":1580636331627,"mc":[{"id":"1.168135753","rc":[{"batl":[[0,1.05,13.93],[1,1.05,0]],"ltp":1.02,"tv":16649.61,"id":41364}]}]}
{"op":"mcm","clk":"1004734534","pt":1580636334732,"mc":[{"id":"1.168135753","rc":[{"batl":[[0,1.01,698.08],[1,1.05,13.93]],"ltp":1.02,"tv":16649.61,"id":41364}]}]}
{"op":"mcm","clk":"1004734625","pt":1580636336757,"mc":[{"id":"1.168135753","marketDefinition":{"bspMarket":false,"turnInPlayEnabled":true,"persistenceEnabled":true,"marketBaseRate":5.0,"eventId":"29678823","eventTypeId":"2","numberOfWinners":1,"bettingType":"ODDS","marketType":"PLAYER_B_WIN_A_SET","marketTime":"2020-02-02T08:30:00.000Z","suspendTime":"2020-02-02T08:30:00.000Z","bspReconciled":false,"complete":true,"inPlay":true,"crossMatching":true,"runnersVoidable":false,"numberOfActiveRunners":2,"betDelay":3,"status":"SUSPENDED","runners":[{"status":"ACTIVE","sortPriority":1,"id":41364,"name":"Yes"},{"status":"ACTIVE","sortPriority":2,"id":41365,"name":"No"}],"regulators":["MR_INT"],"countryCode":"AU","discountAllowed":true,"timezone":"GMT","openDate":"2020-02-02T08:30:00.000Z","version":3148352670,"name":"Djokovic To Win A Set?","eventName":"Thiem v Djokovic"}}]}
{"op":"mcm","clk":"1004736206","pt":1580636370808,"mc":[{"id":"1.168135753","marketDefinition":{"bspMarket":false,"turnInPlayEnabled":true,"persistenceEnabled":true,"marketBaseRate":5.0,"eventId":"29678823","eventTypeId":"2","numberOfWinners":1,"bettingType":"ODDS","marketType":"PLAYER_B_WIN_A_SET","marketTime":"2020-02-02T08:30:00.000Z","suspendTime":"2020-02-02T08:30:00.000Z","bspReconciled":false,"complete":true,"inPlay":true,"crossMatching":false,"runnersVoidable":false,"numberOfActiveRunners":0,"betDelay":3,"status":"CLOSED","settledTime":"2020-02-02T09:39:27.000Z","runners":[{"status":"WINNER","sortPriority":1,"id":41364,"name":"Yes"},{"status":"LOSER","sortPriority":2,"id":41365,"name":"No"}],"regulators":["MR_INT"],"countryCode":"AU","discountAllowed":true,"timezone":"GMT","openDate":"2020-02-02T08:30:00.000Z","version":3148352959,"name":"Djokovic To Win A Set?","eventName":"Thiem v Djokovic"},"tv":0.0}]}
