{"op":"mcm","clk":"1005692288","pt":1580644004772,"mc":[{"id":"1.168135803","rc":[{"trd":[[1.7,929.85]],"ltp":1.7,"tv":8841.21,"id":2249229},{"trd":[[2.42,11.49]],"batl":[[0,2.42,85.06]],"ltp":2.42,"tv":4588.72,"id":5720747}],"tv":13429.93}]}
{"op":"mcm","clk":"1005692827","pt":1580644007762,"mc":[{"id":"1.168135803","rc":[{"trd":[[1.7,962.85]],"ltp":1.7,"tv":8874.21,"id":2249229},{"trd":[[2.42,34.67]],"batl":[[0,2.42,61.88]],"ltp":2.42,"tv":4611.9,"id":5720747}],"tv":13486.12}]}
{"op":"mcm","clk":"1005693303","pt":1580644010782,"mc":[{"id":"1.168135803","rc":[{"trd":[[1.7,977.47]],"ltp":1.7,"tv":8888.83,"id":2249229},{"trd":[[2.42,44.94]],"batl":[[0,2.42,51.61]],"ltp":2.42,"tv":4622.17,"id":5720747}],"tv":13511.0}]}
{"op":"mcm","clk":"1005694042","pt":1580644015774,"mc":[{"id":"1.168135803","rc":[{"trd":[[1.7,994.28]],"ltp":1.7,"tv":8905.63,"id":2249229},{"trd":[[2.42,56.74]],"batl":[[0,2.42,39.81]],"ltp":2.42,"tv":4633.98,"id":5720747}],"tv":13539.61}]}
{"op":"mcm","clk":"1005695157","pt":1580644022790,"mc":[{"id":"1.168135803","rc":[{"batl":[[0,2.32,10],[1,2.42,39.81],[2,3,93.26]],"ltp":2.42,"tv":4633.98,"id":5720747}]}]}
{"op":"mcm","clk":"1005695785","pt":1580644026796,"mc":[{"id":"1.168135803","rc":[{"batl":[[0,2.42,39.81],[1,3,93.26],[2,3,0]],"ltp":2.42,"tv":4633.98,"id":5720747}]}]}
{"op":"mcm","clk":"1005697943","pt":1580644039812,"mc":[{"id":"1.168135803","rc":[{"trd":[[1.59,485.75]],"batb":[[0,1.59,339.75]],"ltp":1.59,"tv":8952.79,"id":2249229}],"tv":13586.77}]}
{"op":"mcm","clk":"1005698619","pt":1580644043814,"mc":[{"id":"1.168135803","rc":[{"batl":[[0,1.99,252.88],[1,2.02,434.62],[2,2.02,0]],"ltp":1.59,"tv":8952.79,"id":2249229}]}]}
{"op":"mcm","clk":"1005698783","pt":1580644044818,"mc":[{"id":"1.168135803","rc":[{"batl":[[0,2.28,1.77]],"ltp":2.42,"tv":4633.98,"id":5720747}]}]}
{"op":"mcm","clk":"1005698940","pt":1580644045783,"mc":[{"id":"1.168135803","rc":[{"batb":[[0,1.44,102.86],[1,1.3,10.02],[2,1.22,8.86]],"ltp":1.59,"tv":8952.79,"id":2249229}]}]}
{"op":"mcm","clk":"1005699095","pt":1580644046807,"mc":[{"id":"1.168135803","rc":[{"trd":[[1.78,2.26]],"batl":[[0,1.72,9.09]],"ltp":1.78,"tv":8955.06,"id":2249229},{"trd":[[2.28,1.77]],"ltp":2.28,"tv":4635.74,"id":5720747}],"tv":13590.81}]}
{"op":"mcm","clk":"1005699248","pt":1580644047813,"mc":[{"id":"1.168135803","rc":[{"batb":[[0,1.3,10.02],[1,1.22,8.86],[2,1.2,5]],"ltp":1.78,"tv":8955.06,"id":2249229},{"batb":[[0,1.49,14.01],[1,1.25,29.54],[2,1.05,16.8]],"ltp":2.28,"tv":4635.74,"id":5720747}]}]}
{"op":"mcm","clk":"1005699409","pt":1580644048711,"mc":[{"id":"1.168135803","rc":[{"trd":[[1.72,376.26],[1.85,4.54]],"batb":[[0,1.91,273.35],[1,1.89,346.67],[2,1.85,153.71]],"batl":[[0,1.99,258.19],[1,2.02,434.64]],"ltp":1.85,"tv":8977.78,"id":2249229}],"tv":13613.53}]}
{"op":"mcm","clk":"1005699605","pt":1580644049730,"mc":[{"id":"1.168135803","rc":[{"batb":[[0,1.85,153.71],[1,1.3,10.02],[2,1.22,8.86]],"ltp":1.85,"tv":8977.78,"id":2249229}]}]}
{"op":"mcm","clk":"1005700115","pt":1580644052700,"mc":[{"id":"1.168135803","rc":[{"trd":[[1.88,191.16],[1.9,752.19]],"batb":[[0,1.88,257.08],[1,1.56,109.44],[2,1.3,10.02]],"batl":[[0,1.98,227.78],[1,2,297.08]],"ltp":1.88,"tv":9813.44,"id":2249229},{"batb":[[0,1.68,691.94],[1,1.49,14.01],[2,1.25,29.54]],"ltp":2.28,"tv":4635.74,"id":5720747}],"tv":14449.19}]}
{"op":"mcm","clk":"1005700294","pt":1580644053724,"mc":[{"id":"1.168135803","rc":[{"batb":[[0,1.56,109.44],[1,1.3,10.02],[2,1.22,8.86]],"ltp":1.88,"tv":9813.44,"id":2249229}]}]}
{"op":"mcm","clk":"1005700480","pt":1580644054732,"mc":[{"id":"1.168135803","rc":[{"batl":[[0,1.98,71.53]],"ltp":1.88,"tv":9813.44,"id":2249229}]}]}
{"op":"mcm","clk":"1005700963","pt":1580644057805,"mc":[{"id":"1.168135803","rc":[{"batl":[[0,1.85,10.72],[1,1.98,71.53]],"ltp":1.88,"tv":9813.44,"id":2249229}]}]}
{"op":"mcm","clk":"1005701104","pt":1580644058815,"mc":[{"id":"1.168135803","rc":[{"trd":[[1.85,25.98]],"batb":[[0,1.88,287.42],[1,1.86,365.16],[2,1.56,109.44]],"batl":[[0,1.96,285.47],[1,1.98,306.4]],"ltp":1.85,"tv":9834.88,"id":2249229}],"tv":14470.63}]}
{"op":"mcm","clk":"1005701374","pt":1580644060728,"mc":[{"id":"1.168135803","rc":[{"batb":[[0,1.56,109.44],[1,1.3,10.02],[2,1.22,8.86]],"ltp":1.85,"tv":9834.88,"id":2249229}]}]}
{"op":"mcm","clk":"1005701833","pt":1580644063748,"mc":[{"id":"1.168135803","rc":[{"batb":[[0,1.71,256.83],[1,1.69,508.77],[2,1.56,109.44]],"batl":[[0,2.46,285.41],[1,2.5,315.5]],"ltp":1.85,"tv":9834.88,"id":2249229}]}]}
{"op":"mcm","clk":"1005702169","pt":1580644065726,"mc":[{"id":"1.168135803","rc":[{"batl":[[0,1.88,93.26],[1,2.46,285.41],[2,2.5,315.5]],"ltp":1.85,"tv":9834.88,"id":2249229}]}]}
{"op":"mcm","clk":"1005702602","pt":1580644068740,"mc":[{"id":"1.168135803","rc":[{"batb":[[0,1.72,69.44],[1,1.71,256.83],[2,1.69,508.77]],"ltp":1.85,"tv":9834.88,"id":2249229}]}]}
{"op":"mcm","clk":"1005702736","pt":1580644069757,"mc":[{"id":"1.168135803","rc":[{"batb":[[0,1.71,256.83],[1,1.69,508.77],[2,1.3,10.02]],"batl":[[0,1.77,303.56],[1,1.79,564.65]],"ltp":1.85,"tv":9834.88,"id":2249229},{"batb":[[0,1.49,14.01],[1,1.25,29.54],[2,1.05,16.8]],"ltp":2.28,"tv":4635.74,"id":5720747}]}]}
{"op":"mcm","clk":"1005702897","pt":1580644070742,"mc":[{"id":"1.168135803","rc":[{"batl":[[1,1.79,424.34]],"ltp":1.85,"tv":9834.88,"id":2249229}]}]}
{"op":"mcm","clk":"1005703241","pt":1580644072770,"mc":[{"id":"1.168135803","rc":[{"batl":[[2,2.4,279.78]],"ltp":1.85,"tv":9834.88,"id":2249229}]}]}
{"op":"mcm","clk":"1005703402","pt":1580644073732,"mc":[{"id":"1.168135803","rc":[{"batb":[[2,1.48,103.38]],"ltp":1.85,"tv":9834.88,"id":2249229},{"batb":[[0,1.8,661.09],[1,1.49,14.01],[2,1.25,29.54]],"ltp":2.28,"tv":4635.74,"id":5720747}]}]}
{"op":"mcm","clk":"1005703896","pt":1580644076744,"mc":[{"id":"1.168135803","rc":[{"batl":[[2,2,3.79]],"ltp":1.85,"tv":9834.88,"id":2249229}]}]}
{"op":"mcm","clk":"1005704613","pt":1580644081766,"mc":[{"id":"1.168135803","rc":[{"trd":[[1.71,49.4]],"batb":[[0,1.48,103.38],[1,1.3,10.02],[2,1.22,8.86]],"batl":[[0,2,3.79],[1,2.4,279.78],[2,2,0]],"ltp":1.71,"tv":9868.48,"id":2249229}],"tv":14504.23}]}
{"op":"mcm","clk":"1005704890","pt":1580644083746,"mc":[{"id":"1.168135803","rc":[{"batl":[[1,2.4,0]],"ltp":1.71,"tv":9868.48,"id":2249229}]}]}
{"op":"mcm","clk":"1005705300","pt":1580644086750,"mc":[{"id":"1.168135803","rc":[{"batb":[[0,1.58,416.58],[1,1.57,339.39],[2,1.48,103.38]],"batl":[[1,2.12,405.14],[2,2.14,242.67]],"ltp":1.71,"tv":9868.48,"id":2249229}]}]}
{"op":"mcm","clk":"1005705721","pt":1580644089774,"mc":[{"id":"1.168135803","rc":[{"batl":[[1,2.12,0],[2,2.14,0]],"ltp":1.71,"tv":9868.48,"id":2249229}]}]}
{"op":"mcm","clk":"1005705994","pt":1580644091783,"mc":[{"id":"1.168135803","rc":[{"batl":[[0,1.95,279.78],[1,2,3.79]],"ltp":1.71,"tv":9868.48,"id":2249229}]}]}
{"op":"mcm","clk":"1005706155","pt":1580644092754,"mc":[{"id":"1.168135803","rc":[{"batb":[[2,1.3,10.02]],"batl":[[0,1.64,531.44],[1,1.65,280.23],[2,1.95,279.78]],"ltp":1.71,"tv":9868.48,"id":2249229},{"batb":[[0,1.49,14.01],[1,1.25,29.54],[2,1.05,16.8]],"ltp":2.28,"tv":4635.74,"id":5720747}]}]}
{"op":"mcm","clk":"1005706721","pt":1580644096760,"mc":[{"id":"1.168135803","rc":[{"batb":[[2,1.39,105.44]],"ltp":1.71,"tv":9868.48,"id":2249229},{"batb":[[0,1.95,640.7],[1,1.49,14.01],[2,1.25,29.54]],"ltp":2.28,"tv":4635.74,"id":5720747}]}]}
{"op":"mcm","clk":"1005706840","pt":1580644097701,"mc":[{"id":"1.168135803","rc":[{"batl":[[0,1.64,465.43]],"ltp":1.71,"tv":9868.48,"id":2249229}]}]}
{"op":"mcm","clk":"1005707192","pt":1580644099785,"mc":[{"id":"1.168135803","rc":[{"batb":[[0,1.58,483.21]],"ltp":1.71,"tv":9868.48,"id":2249229}]}]}
{"op":"mcm","clk":"1005707359","pt":1580644100698,"mc":[{"id":"1.168135803","rc":[{"batl":[[0,1.64,373.77]],"ltp":1.71,"tv":9868.48,"id":2249229}]}]}
{"op":"mcm","clk":"1005707794","pt":1580644103758,"mc":[{"id":"1.168135803","rc":[{"trd":[[1.64,185.42]],"batl":[[0,1.64,339.32]],"ltp":1.64,"tv":9937.38,"id":2249229}],"tv":14573.13}]}
{"op":"mcm","clk":"1005707931","pt":1580644104761,"mc":[{"id":"1.168135803","rc":[{"batb":[[0,1.58,91.62],[1,1.39,105.44],[2,1.3,10.02]],"batl":[[0,1.95,279.78],[1,2,3.79],[2,1.95,0]],"ltp":1.64,"tv":9937.38,"id":2249229}]}]}
{"op":"mcm","clk":"1005708047","pt":1580644105675,"mc":[{"id":"1.168135803","rc":[{"batb":[[0,1.39,105.44],[1,1.3,10.02],[2,1.22,8.86]],"batl":[[0,2,3.79],[1,2,0]],"ltp":1.64,"tv":9937.38,"id":2249229}]}]}
{"op":"mcm","clk":"1005708370","pt":1580644107810,"mc":[{"id":"1.168135803","rc":[{"batb":[[0,1.51,363.14],[1,1.5,408.89],[2,1.4,125]],"batl":[[0,1.83,255.35],[1,1.85,380.17],[2,2,3.79]],"ltp":1.64,"tv":9937.38,"id":2249229}]}]}
{"op":"mcm","clk":"1005708639","pt":1580644109796,"mc":[{"id":"1.168135803","rc":[{"batb":[[0,1.4,125],[1,1.39,105.44],[2,1.3,10.02]],"batl":[[0,2,3.79],[1,1.85,0],[2,2,0]],"ltp":1.64,"tv":9937.38,"id":2249229}]}]}
{"op":"mcm","clk":"1005708778","pt":1580644110796,"mc":[{"id":"1.168135803","rc":[{"batl":[[0,2.56,5]],"ltp":2.28,"tv":4635.74,"id":5720747}]}]}
{"op":"mcm","clk":"1005708871","pt":1580644111578,"mc":[{"id":"1.168135803","rc":[{"batl":[[0,1.8,373.05],[1,2,3.79]],"ltp":1.64,"tv":9937.38,"id":2249229}]}]}
{"op":"mcm","clk":"1005709035","pt":1580644112793,"mc":[{"id":"1.168135803","rc":[{"batb":[[0,1.3,10.02],[1,1.22,8.86],[2,1.2,5]],"ltp":1.64,"tv":9937.38,"id":2249229}]}]}
{"op":"mcm","clk":"1005709163","pt":1580644113781,"mc":[{"id":"1.168135803","rc":[{"batb":[[0,1.52,96.15],[1,1.3,10.02],[2,1.22,8.86]],"ltp":1.64,"tv":9937.38,"id":2249229}]}]}
{"op":"mcm","clk":"1005709540","pt":1580644116672,"mc":[{"id":"1.168135803","rc":[{"batb":[[1,1.42,105.33],[2,1.3,10.02]],"ltp":1.64,"tv":9937.38,"id":2249229}]}]}
{"op":"mcm","clk":"1005709704","pt":1580644117778,"mc":[{"id":"1.168135803","rc":[{"batb":[[1,1.51,363.14],[2,1.5,408.89]],"batl":[[1,1.83,255.35],[2,1.85,380.17]],"ltp":1.64,"tv":9937.38,"id":2249229}]}]}
{"op":"mcm","clk":"1005710125","pt":1580644120813,"mc":[{"id":"1.168135803","rc":[{"batb":[[1,1.42,105.33],[2,1.3,10.02]],"batl":[[1,2,3.79],[2,1.85,0]],"ltp":1.64,"tv":9937.38,"id":2249229}]}]}
{"op":"mcm","clk":"1005710273","pt":1580644121807,"mc":[{"id":"1.168135803","rc":[{"batl":[[1,2,0]],"ltp":1.64,"tv":9937.38,"id":2249229}]}]}
{"op":"mcm","clk":"1005710553","pt":1580644123795,"mc":[{"id":"1.168135803","rc":[{"trd":[[1.64,193.22]],"batb":[[0,1.3,10.02],[1,1.22,8.86],[2,1.2,5]],"batl":[[0,1.6,132.51],[1,1.8,373.05]],"ltp":1.64,"tv":9945.19,"id":2249229},{"trd":[[2.56,5]],"ltp":2.56,"tv":4640.74,"id":5720747}],"tv":14585.94}]}
{"op":"mcm","clk":"1005710668","pt":1580644124795,"mc":[{"id":"1.168135803","rc":[{"batb":[[0,1.51,363.14],[1,1.5,408.89],[2,1.3,10.02]],"batl":[[0,1.56,547.97],[1,1.57,337.76],[2,1.6,132.51]],"ltp":1.64,"tv":9945.19,"id":2249229}]}]}
{"op":"mcm","clk":"1005710941","pt":1580644126799,"mc":[{"id":"1.168135803","rc":[{"batl":[[2,1.8,373.05]],"ltp":1.64,"tv":9945.19,"id":2249229}]}]}
{"op":"mcm","clk":"1005711069","pt":1580644127797,"mc":[{"id":"1.168135803","rc":[{"batb":[[2,1.36,105.44]],"ltp":1.64,"tv":9945.19,"id":2249229}]}]}
{"op":"mcm","clk":"1005711350","pt":1580644129789,"mc":[{"id":"1.168135803","rc":[{"trd":[[1.56,134.41]],"batl":[[0,1.56,539.76]],"ltp":1.56,"tv":9961.61,"id":2249229}],"tv":14602.35}]}
{"op":"mcm","clk":"1005712294","pt":1580644136818,"mc":[{"id":"1.168135803","rc":[{"trd":[[1.56,217.89]],"batb":[[0,1.36,105.44],[1,1.3,10.02],[2,1.22,8.86]],"batl":[[0,1.8,373.05],[1,1.57,0],[2,1.8,0]],"ltp":1.56,"tv":10045.08,"id":2249229}],"tv":14685.83}]}
{"op":"mcm","clk":"1005712958","pt":1580644141811,"mc":[{"id":"1.168135803","rc":[{"batl":[[0,2.1,3.79]],"ltp":1.56,"tv":10045.08,"id":2249229}]}]}
{"op":"mcm","clk":"1005713071","pt":1580644142711,"mc":[{"id":"1.168135803","rc":[{"batb":[[0,1.48,461.52],[1,1.47,439.17],[2,1.36,105.44]],"batl":[[0,1.63,328.88],[1,1.64,286.61],[2,2.1,3.79]],"ltp":1.56,"tv":10045.08,"id":2249229}]}]}
{"op":"mcm","clk":"1005713209","pt":1580644143819,"mc":[{"id":"1.168135803","rc":[{"batl":[[0,2.78,2.52]],"ltp":2.56,"tv":4640.74,"id":5720747}]}]}
{"op":"mcm","clk":"1005713458","pt":1580644145708,"mc":[{"id":"1.168135803","rc":[{"batl":[[0,2.1,3.79],[1,1.64,0],[2,2.1,0]],"ltp":1.56,"tv":10045.08,"id":2249229}]}]}
{"op":"mcm","clk":"1005713722","pt":1580644147740,"mc":[{"id":"1.168135803","rc":[{"batb":[[0,1.49,14.01],[1,1.25,29.54],[2,1.05,16.8]],"ltp":2.56,"tv":4640.74,"id":5720747}]}]}
{"op":"mcm","clk":"1005713861","pt":1580644148740,"mc":[{"id":"1.168135803","rc":[{"trd":[[1.56,222.39]],"batl":[[0,1.5,135.82],[1,1.53,581.55],[2,1.54,364.04]],"ltp":1.56,"tv":10049.58,"id":2249229},{"trd":[[2.78,5.32]],"ltp":2.78,"tv":4643.26,"id":5720747}],"tv":14692.85}]}
{"op":"mcm","clk":"1005714258","pt":1580644151732,"mc":[{"id":"1.168135803","rc":[{"batb":[[0,2.08,672.17],[1,1.49,14.01],[2,1.25,29.54]],"ltp":2.78,"tv":4643.26,"id":5720747}]}]}
{"op":"mcm","clk":"1005714383","pt":1580644152731,"mc":[{"id":"1.168135803","rc":[{"batl":[[0,1.53,581.55],[1,1.54,364.04],[2,2.1,3.79]],"ltp":1.56,"tv":10049.58,"id":2249229}]}]}
{"op":"mcm","clk":"1005714794","pt":1580644155726,"mc":[{"id":"1.168135803","rc":[{"trd":[[1.53,119.75]],"batl":[[0,1.53,576.96]],"ltp":1.53,"tv":10058.76,"id":2249229}],"tv":14702.03}]}
{"op":"mcm","clk":"1005715499","pt":1580644160769,"mc":[{"id":"1.168135803","rc":[{"trd":[[1.48,8.89]],"batb":[[0,1.5,280],[1,1.48,457.1],[2,1.47,439.17]],"ltp":1.48,"tv":10067.6,"id":2249229}],"tv":14710.87}]}
{"op":"mcm","clk":"1005716464","pt":1580644167751,"mc":[{"id":"1.168135803","rc":[{"trd":[[1.53,138.57]],"batl":[[0,1.53,558.14]],"ltp":1.53,"tv":10086.42,"id":2249229},{"trd":[[2.88,10]],"ltp":2.88,"tv":4653.26,"id":5720747}],"tv":14739.69}]}
{"op":"mcm","clk":"1005716971","pt":1580644171750,"mc":[{"id":"1.168135803","rc":[{"batl":[[0,3,20]],"ltp":2.88,"tv":4653.26,"id":5720747}]}]}
{"op":"mcm","clk":"1005717110","pt":1580644172787,"mc":[{"id":"1.168135803","rc":[{"trd":[[1.5,59.8]],"batb":[[0,1.5,275.12]],"ltp":1.5,"tv":10096.17,"id":2249229},{"batl":[[0,2.98,93.26],[1,3,20]],"ltp":2.88,"tv":4653.26,"id":5720747}],"tv":14749.44}]}
{"op":"mcm","clk":"1005717378","pt":1580644174779,"mc":[{"id":"1.168135803","rc":[{"trd":[[1.53,146.1]],"batl":[[0,1.53,550.61]],"ltp":1.53,"tv":10103.7,"id":2249229},{"trd":[[2.88,14]],"ltp":2.88,"tv":4657.26,"id":5720747}],"tv":14760.97}]}
{"op":"mcm","clk":"1005717513","pt":1580644175776,"mc":[{"id":"1.168135803","rc":[{"trd":[[2.98,3.58]],"batl":[[0,2.98,91.47]],"ltp":2.98,"tv":4660.84,"id":5720747}],"tv":14764.55}]}
{"op":"mcm","clk":"1005718502","pt":1580644183793,"mc":[{"id":"1.168135803","rc":[{"trd":[[1.53,696.71]],"batl":[[0,1.54,364.04],[1,2.1,3.79],[2,2.1,0]],"ltp":1.53,"tv":10654.31,"id":2249229},{"trd":[[2.88,306.51]],"batl":[[0,2.88,5.76],[1,2.98,91.47],[2,3,20]],"ltp":2.88,"tv":4953.35,"id":5720747}],"tv":15607.67}]}
{"op":"mcm","clk":"1005718882","pt":1580644186778,"mc":[{"id":"1.168135803","rc":[{"trd":[[1.53,707.54]],"batb":[[1,1.48,614.34]],"batl":[[0,1.53,414.81],[1,1.54,364.04],[2,2.1,3.79]],"ltp":1.53,"tv":10665.14,"id":2249229},{"trd":[[2.88,312.27]],"batl":[[0,2.98,91.47],[1,3,20],[2,3,0]],"ltp":2.88,"tv":4959.11,"id":5720747}],"tv":15624.26}]}
{"op":"mcm","clk":"1005719504","pt":1580644191675,"mc":[{"id":"1.168135803","rc":[{"batl":[[2,2.1,0]],"ltp":1.53,"tv":10665.14,"id":2249229}]}]}
{"op":"mcm","clk":"1005719775","pt":1580644193776,"mc":[{"id":"1.168135803","rc":[{"batl":[[1,3,0]],"ltp":2.88,"tv":4959.11,"id":5720747}]}]}
{"op":"mcm","clk":"1005721921","pt":1580644208820,"mc":[{"id":"1.168135803","rc":[{"trd":[[1.53,718.94]],"batl":[[0,1.53,403.41]],"ltp":1.53,"tv":10676.54,"id":2249229},{"trd":[[2.88,318.33]],"batl":[[0,2.96,20],[1,2.98,91.47]],"ltp":2.88,"tv":4965.17,"id":5720747}],"tv":15641.72}]}
{"op":"mcm","clk":"1005722461","pt":1580644212720,"mc":[{"id":"1.168135803","rc":[{"trd":[[1.51,35.36]],"batl":[[0,1.53,478.58]],"ltp":1.51,"tv":10711.9,"id":2249229},{"trd":[[2.96,18.05]],"batl":[[0,2.96,1.95]],"ltp":2.96,"tv":4983.22,"id":5720747}],"tv":15695.13}]}
{"op":"mcm","clk":"1005722931","pt":1580644215630,"mc":[{"id":"1.168135803","rc":[{"batb":[[0,1.48,614.34],[1,1.47,439.17],[2,1.36,105.44]],"ltp":1.51,"tv":10711.9,"id":2249229}]}]}
{"op":"mcm","clk":"1005723931","pt":1580644221609,"mc":[{"id":"1.168135803","rc":[{"trd":[[1.53,737.76]],"batl":[[0,1.53,459.76]],"ltp":1.53,"tv":10730.72,"id":2249229},{"trd":[[2.88,328.33]],"ltp":2.88,"tv":4993.22,"id":5720747}],"tv":15723.95}]}
{"op":"mcm","clk":"1005724752","pt":1580644226686,"mc":[{"id":"1.168135803","rc":[{"batb":[[0,1.36,105.44],[1,1.3,10.02],[2,1.22,8.86]],"ltp":1.53,"tv":10730.72,"id":2249229}]}]}
{"op":"mcm","clk":"1005725027","pt":1580644228743,"mc":[{"id":"1.168135803","rc":[{"batb":[[0,1.36,938.15],[1,1.35,660.4],[2,1.3,10.02]],"batl":[[0,1.62,542.53],[1,1.63,294.92]],"ltp":1.53,"tv":10730.72,"id":2249229}]}]}
{"op":"mcm","clk":"1005725192","pt":1580644229737,"mc":[{"id":"1.168135803","rc":[{"batl":[[0,2.98,91.47],[1,2.98,0]],"ltp":2.88,"tv":4993.22,"id":5720747}]}]}
{"op":"mcm","clk":"1005725931","pt":1580644234775,"mc":[{"id":"1.168135803","rc":[{"batl":[[2,1.77,5.3]],"ltp":1.53,"tv":10730.72,"id":2249229}]}]}
{"op":"mcm","clk":"1005726216","pt":1580644236730,"mc":[{"id":"1.168135803","rc":[{"batb":[[0,1.53,10],[1,1.36,938.15],[2,1.35,660.4]],"ltp":1.53,"tv":10730.72,"id":2249229}]}]}
{"op":"mcm","clk":"1005729039","pt":1580644256697,"mc":[{"id":"1.168135803","rc":[{"batb":[[1,1.36,832.71]],"ltp":1.53,"tv":10730.72,"id":2249229},{"batb":[[0,1.49,14.01],[1,1.25,29.54],[2,1.05,16.8]],"ltp":2.88,"tv":4993.22,"id":5720747}]}]}
{"op":"mcm","clk":"1005730688","pt":1580644268367,"mc":[{"id":"1.168135803","rc":[{"trd":[[1.53,757.75]],"batb":[[0,1.36,832.71],[1,1.35,660.4],[2,1.3,10.02]],"batl":[[0,1.5,55.86],[1,1.62,542.53],[2,1.63,294.92]],"ltp":1.53,"tv":10750.71,"id":2249229}],"tv":15743.93}]}
{"op":"mcm","clk":"1005731526","pt":1580644274803,"mc":[{"id":"1.168135803","rc":[{"batb":[[0,1.3,10.02],[1,1.22,8.86],[2,1.2,5]],"ltp":1.53,"tv":10750.71,"id":2249229}]}]}
{"op":"mcm","clk":"1005731918","pt":1580644277599,"mc":[{"id":"1.168135803","rc":[{"trd":[[1.5,171.58]],"batb":[[0,1.56,483.79],[1,1.55,359.86],[2,1.54,216.37]],"batl":[[0,1.62,542.53],[1,1.63,294.92],[2,1.77,5.3]],"ltp":1.5,"tv":10862.48,"id":2249229}],"tv":15855.71}]}
{"op":"mcm","clk":"1005732206","pt":1580644279795,"mc":[{"id":"1.168135803","rc":[{"batb":[[2,1.3,10.02]],"ltp":1.5,"tv":10862.48,"id":2249229}]}]}
{"op":"mcm","clk":"1005732328","pt":1580644280704,"mc":[{"id":"1.168135803","rc":[{"batb":[[2,1.39,178.03]],"ltp":1.5,"tv":10862.48,"id":2249229},{"batb":[[0,1.95,692.09],[1,1.49,14.01],[2,1.25,29.54]],"batl":[[0,2.96,37.86]],"ltp":2.88,"tv":4993.22,"id":5720747}]}]}
{"op":"mcm","clk":"1005732608","pt":1580644282586,"mc":[{"id":"1.168135803","rc":[{"trd":[[1.56,329.91]],"batb":[[0,1.56,430.03]],"ltp":1.56,"tv":10970.01,"id":2249229}],"tv":15963.23}]}
{"op":"mcm","clk":"1005733843","pt":1580644290684,"mc":[{"id":"1.168135803","rc":[{"batb":[[0,1.39,178.03],[1,1.3,10.02],[2,1.22,8.86]],"batl":[[0,1.77,5.3],[1,1.63,0],[2,1.77,0]],"ltp":1.56,"tv":10970.01,"id":2249229}]}]}
{"op":"mcm","clk":"1005734132","pt":1580644292802,"mc":[{"id":"1.168135803","rc":[{"batb":[[0,1.46,336.79],[1,1.45,471.36],[2,1.39,178.03]],"batl":[[0,1.69,438.73],[1,1.71,503.18],[2,1.77,5.3]],"ltp":1.56,"tv":10970.01,"id":2249229}]}]}
{"op":"mcm","clk":"1005735415","pt":1580644301710,"mc":[{"id":"1.168135803","rc":[{"batl":[[0,1.77,5.3],[1,1.71,0],[2,1.77,0]],"ltp":1.56,"tv":10970.01,"id":2249229}]}]}
{"op":"mcm","clk":"1005735714","pt":1580644303817,"mc":[{"id":"1.168135803","rc":[{"batl":[[0,1.54,147.03],[1,1.77,5.3]],"ltp":1.56,"tv":10970.01,"id":2249229},{"batl":[[0,3.3,2]],"ltp":2.88,"tv":4993.22,"id":5720747}]}]}
{"op":"mcm","clk":"1005735822","pt":1580644304710,"mc":[{"id":"1.168135803","rc":[{"batb":[[2,1.3,10.02]],"batl":[[0,1.5,389.68],[1,1.51,393.34],[2,1.54,147.03]],"ltp":1.56,"tv":10970.01,"id":2249229},{"batb":[[0,1.49,14.01],[1,1.25,29.54],[2,1.05,16.8]],"ltp":2.88,"tv":4993.22,"id":5720747}]}]}
{"op":"mcm","clk":"1005736493","pt":1580644309731,"mc":[{"id":"1.168135803","rc":[{"batb":[[2,1.33,182.03]],"batl":[[2,1.77,5.3]],"ltp":1.56,"tv":10970.01,"id":2249229},{"batb":[[0,2.08,667.28],[1,1.49,14.01],[2,1.25,29.54]],"ltp":2.88,"tv":4993.22,"id":5720747}]}]}
{"op":"mcm","clk":"1005737469","pt":1580644316732,"mc":[{"id":"1.168135803","rc":[{"trd":[[1.5,561.26]],"batb":[[0,1.33,182.03],[1,1.3,10],[2,1.22,8.86]],"batl":[[0,1.77,5.3],[1,1.51,0],[2,1.77,0]],"ltp":1.5,"tv":11359.69,"id":2249229},{"trd":[[3,220.57]],"batl":[[0,3,227.35]],"ltp":3.0,"tv":5188.07,"id":5720747}],"tv":16547.76}]}
{"op":"mcm","clk":"1005737874","pt":1580644319713,"mc":[{"id":"1.168135803","rc":[{"batb":[[1,1.31,763.15],[2,1.3,10]],"batl":[[0,1.61,386.15],[1,1.62,301.7],[2,1.77,5.3]],"ltp":1.5,"tv":11359.69,"id":2249229},{"batl":[[0,3,282.8]],"ltp":3.0,"tv":5188.07,"id":5720747}]}]}
{"op":"mcm","clk":"1005738139","pt":1580644321753,"mc":[{"id":"1.168135803","rc":[{"trd":[[1.5,563.15]],"batb":[[1,1.32,451.94],[2,1.31,763.15]],"ltp":1.5,"tv":11361.59,"id":2249229},{"trd":[[3,221.52]],"batl":[[0,3,281.85]],"ltp":3.0,"tv":5189.02,"id":5720747}],"tv":16550.61}]}
{"op":"mcm","clk":"1005738559","pt":1580644324720,"mc":[{"id":"1.168135803","rc":[{"batl":[[0,3,226.4]],"ltp":3.0,"tv":5189.02,"id":5720747}]}]}
{"op":"mcm","clk":"1005739347","pt":1580644330643,"mc":[{"id":"1.168135803","rc":[{"batl":[[0,3,276.4]],"ltp":3.0,"tv":5189.02,"id":5720747}]}]}
{"op":"mcm","clk":"1005739832","pt":1580644334774,"mc":[{"id":"1.168135803","rc":[{"batl":[[0,3,50]],"ltp":3.0,"tv":5189.02,"id":5720747}]}]}
{"op":"mcm","clk":"1005740058","pt":1580644336674,"mc":[{"id":"1.168135803","rc":[{"batb":[[1,1.3,10],[2,1.22,8.86]],"batl":[[0,1.77,5.3],[1,1.62,0],[2,1.77,0]],"ltp":1.5,"tv":11361.59,"id":2249229}]}]}
{"op":"mcm","clk":"1005740179","pt":1580644337569,"mc":[{"id":"1.168135803","rc":[{"batl":[[0,2.58,226.4],[1,3,50]],"ltp":3.0,"tv":5189.02,"id":5720747}]}]}
{"op":"mcm","clk":"1005740295","pt":1580644338577,"mc":[{"id":"1.168135803","rc":[{"batb":[[0,1.49,14.01],[1,1.25,29.54],[2,1.05,16.8]],"ltp":3.0,"tv":5189.02,"id":5720747}]}]}
{"op":"mcm","clk":"1005740732","pt":1580644341581,"mc":[{"id":"1.168135803","rc":[{"trd":[[1.5,663.14],[1.63,366.72]],"ltp":1.5,"tv":11819.92,"id":2249229},{"trd":[[2.58,276.4],[3,271.52]],"ltp":3.0,"tv":5465.41,"id":5720747}],"tv":17285.34}]}
{"op":"mcm","clk":"1005740898","pt":1580644342788,"mc":[{"id":"1.168135803","rc":[{"batb":[[0,2.18,656.08],[1,1.49,14.01],[2,1.25,29.54]],"ltp":3.0,"tv":5465.41,"id":5720747}]}]}
{"op":"mcm","clk":"1005740999","pt":1580644343573,"mc":[{"id":"1.168135803","rc":[{"batl":[[0,1.5,37.86],[1,1.63,358.33],[2,1.77,5.3]],"ltp":1.5,"tv":11819.92,"id":2249229}]}]}
{"op":"mcm","clk":"1005741159","pt":1580644344785,"mc":[{"id":"1.168135803","rc":[{"batb":[[1,1.32,513.02],[2,1.31,763.23]],"batl":[[0,1.62,301.63],[1,1.77,5.3],[2,1.77,0]],"ltp":1.5,"tv":11819.92,"id":2249229}]}]}
{"op":"mcm","clk":"1005741420","pt":1580644346788,"mc":[{"id":"1.168135803","rc":[{"batb":[[1,1.32,731.99]],"batl":[[0,1.62,465.91],[1,1.63,293.95],[2,1.77,5.3]],"ltp":1.5,"tv":11819.92,"id":2249229}]}]}
{"op":"mcm","clk":"1005741685","pt":1580644348788,"mc":[{"id":"1.168135803","rc":[{"batb":[[1,1.55,18.93],[2,1.49,14.01]],"ltp":3.0,"tv":5465.41,"id":5720747}]}]}
{"op":"mcm","clk":"1005741803","pt":1580644349474,"mc":[{"id":"1.168135803","rc":[{"batl":[[0,1.77,5.3],[1,1.63,0],[2,1.77,0]],"ltp":1.5,"tv":11819.92,"id":2249229}]}]}
{"op":"mcm","clk":"1005742074","pt":1580644351680,"mc":[{"id":"1.168135803","rc":[{"batl":[[0,1.42,147.03],[1,1.44,147.03],[2,1.77,5.3]],"ltp":1.5,"tv":11819.92,"id":2249229}]}]}
{"op":"mcm","clk":"1005742206","pt":1580644352796,"mc":[{"id":"1.168135803","rc":[{"batb":[[0,1.32,732.01],[1,1.31,763.23],[2,1.22,8.86]],"batl":[[0,1.36,840.91],[1,1.37,586.69],[2,1.42,147.03]],"ltp":1.5,"tv":11819.92,"id":2249229},{"batb":[[0,1.55,18.93],[1,1.49,14.01],[2,1.25,29.54]],"ltp":3.0,"tv":5465.41,"id":5720747}]}]}
{"op":"mcm","clk":"1005742581","pt":1580644355798,"mc":[{"id":"1.168135803","rc":[{"batl":[[0,1.36,761.93],[2,1.77,5.3]],"ltp":1.5,"tv":11819.92,"id":2249229}]}]}
{"op":"mcm","clk":"1005742716","pt":1580644356800,"mc":[{"id":"1.168135803","rc":[{"batb":[[2,1.23,213.34]],"ltp":1.5,"tv":11819.92,"id":2249229},{"batb":[[0,2.4,627.38],[1,1.55,18.93],[2,1.49,14.01]],"ltp":3.0,"tv":5465.41,"id":5720747}]}]}
{"op":"mcm","clk":"1005742940","pt":1580644358798,"mc":[{"id":"1.168135803","rc":[{"batb":[[0,1.32,813.67]],"ltp":1.5,"tv":11819.92,"id":2249229}]}]}
{"op":"mcm","clk":"1005743296","pt":1580644361801,"mc":[{"id":"1.168135803","rc":[{"trd":[[1.36,0.04]],"batl":[[0,1.36,761.91]],"ltp":1.36,"tv":11819.96,"id":2249229}],"tv":17285.38}]}
{"op":"mcm","clk":"1005743696","pt":1580644364800,"mc":[{"id":"1.168135803","rc":[{"batb":[[0,1.23,213.36],[1,1.22,8.86],[2,1.2,5]],"batl":[[0,1.77,5.3],[1,1.37,0],[2,1.77,0]],"ltp":1.36,"tv":11819.96,"id":2249229}]}]}
{"op":"mcm","clk":"1005743963","pt":1580644366816,"mc":[{"id":"1.168135803","rc":[{"trd":[[1.34,0.06],[1.36,5.55]],"batb":[[0,1.23,213.34]],"batl":[[0,1.33,6.23],[1,1.77,5.3]],"ltp":1.34,"tv":11825.5,"id":2249229},{"trd":[[3.75,2]],"ltp":3.75,"tv":5467.41,"id":5720747}],"tv":17292.92}]}
{"op":"mcm","clk":"1005744074","pt":1580644367809,"mc":[{"id":"1.168135803","rc":[{"trd":[[1.33,4.54]],"batl":[[0,1.33,3.97],[1,1.49,671.96],[2,1.5,398.77]],"ltp":1.33,"tv":11830.04,"id":2249229}],"tv":17297.46}]}
{"op":"mcm","clk":"1005744623","pt":1580644371808,"mc":[{"id":"1.168135803","rc":[{"batl":[[0,1.32,15.14],[1,1.33,3.97],[2,1.49,671.96]],"ltp":1.33,"tv":11830.04,"id":2249229}]}]}
{"op":"mcm","clk":"1005744881","pt":1580644373721,"mc":[{"id":"1.168135803","rc":[{"trd":[[1.32,15.14],[1.33,8.51]],"batl":[[0,1.49,671.96],[1,1.5,398.77],[2,1.77,5.3]],"ltp":1.33,"tv":11849.15,"id":2249229},{"trd":[[4,1.32],[4.1,4.88]],"batl":[[0,4,13.8]],"ltp":4.0,"tv":5473.61,"id":5720747}],"tv":17322.77}]}
{"op":"mcm","clk":"1005745046","pt":1580644374820,"mc":[{"id":"1.168135803","rc":[{"batb":[[0,1.22,8.86],[1,1.2,5],[2,1.12,16.24]],"batl":[[0,1.77,5.3],[1,1.5,0],[2,1.77,0]],"ltp":1.33,"tv":11849.15,"id":2249229},{"batb":[[0,1.55,18.93],[1,1.49,14.01],[2,1.25,29.54]],"ltp":4.0,"tv":5473.61,"id":5720747}]}]}
{"op":"mcm","clk":"1005745180","pt":1580644375813,"mc":[{"id":"1.168135803","rc":[{"batl":[[0,4,50.77]],"ltp":4.0,"tv":5473.61,"id":5720747}]}]}
{"op":"mcm","clk":"1005745302","pt":1580644376762,"mc":[{"id":"1.168135803","rc":[{"trd":[[1.33,161.2]],"batb":[[0,1.29,528.22],[1,1.28,860.48],[2,1.22,8.86]],"batl":[[0,1.32,477.55],[1,1.33,677.37],[2,1.77,5.3]],"ltp":1.33,"tv":12001.84,"id":2249229},{"trd":[[4,52.09]],"ltp":4.0,"tv":5524.38,"id":5720747}],"tv":17526.23}]}
{"op":"mcm","clk":"1005745430","pt":1580644377818,"mc":[{"id":"1.168135803","rc":[{"batb":[[0,1.22,8.86],[1,1.2,5],[2,1.12,16.24]],"batl":[[0,1.77,5.3],[1,1.33,0],[2,1.77,0]],"ltp":1.33,"tv":12001.84,"id":2249229}]}]}
{"op":"mcm","clk":"1005745558","pt":1580644378745,"mc":[{"id":"1.168135803","rc":[{"batl":[[0,1.33,12.12],[1,1.77,5.3]],"ltp":1.33,"tv":12001.84,"id":2249229}]}]}
{"op":"mcm","clk":"1005745673","pt":1580644379735,"mc":[{"id":"1.168135803","rc":[{"batb":[[2,1.19,248.93]],"batl":[[0,1.77,5.3],[1,1.77,0]],"ltp":1.33,"tv":12001.84,"id":2249229},{"batb":[[0,2.56,618.08],[1,1.55,18.93],[2,1.49,14.01]],"ltp":4.0,"tv":5524.38,"id":5720747}]}]}
{"op":"mcm","clk":"1005746047","pt":1580644382731,"mc":[{"id":"1.168135803","rc":[{"batl":[[0,1.49,607.87],[1,1.5,398.67],[2,1.77,5.3]],"ltp":1.33,"tv":12001.84,"id":2249229}]}]}
{"op":"mcm","clk":"1005746309","pt":1580644384739,"mc":[{"id":"1.168135803","rc":[{"batb":[[2,1.17,383.56]],"ltp":1.33,"tv":12001.84,"id":2249229},{"batb":[[0,1.55,18.93],[1,1.49,14.01],[2,1.25,29.54]],"ltp":4.0,"tv":5524.38,"id":5720747}]}]}
{"op":"mcm","clk":"1005746677","pt":1580644387733,"mc":[{"id":"1.168135803","rc":[{"batb":[[0,1.2,5],[1,1.17,383.56],[2,1.16,1658.17]],"batl":[[0,1.77,5.3],[1,1.5,0],[2,1.77,0]],"ltp":1.33,"tv":12001.84,"id":2249229}]}]}
{"op":"mcm","clk":"1005747024","pt":1580644390731,"mc":[{"id":"1.168135803","rc":[{"trd":[[1.2,10]],"batb":[[0,1.16,1658.17],[1,1.12,16.24],[2,1.1,30]],"batl":[[0,1.19,1176.6],[1,1.2,1207.78],[2,1.23,147.03]],"ltp":1.2,"tv":12011.84,"id":2249229}],"tv":17536.23}]}
{"op":"mcm","clk":"1005747168","pt":1580644391727,"mc":[{"id":"1.168135803","rc":[{"batl":[[0,1.19,1024.12]],"ltp":1.2,"tv":12011.84,"id":2249229}]}]}
{"op":"mcm","clk":"1005747390","pt":1580644393737,"mc":[{"id":"1.168135803","rc":[{"batb":[[0,1.16,1658.57],[2,1.11,371.88]],"ltp":1.2,"tv":12011.84,"id":2249229},{"batb":[[0,3,587],[1,1.55,18.93],[2,1.49,14.01]],"ltp":4.0,"tv":5524.38,"id":5720747}]}]}
{"op":"mcm","clk":"1005747509","pt":1580644394732,"mc":[{"id":"1.168135803","rc":[{"batb":[[0,1.17,544.35],[1,1.16,1658.57],[2,1.12,16.24]],"ltp":1.2,"tv":12011.84,"id":2249229}]}]}
{"op":"mcm","clk":"1005747635","pt":1580644395783,"mc":[{"id":"1.168135803","rc":[{"batl":[[2,1.77,5.3]],"ltp":1.2,"tv":12011.84,"id":2249229}]}]}
{"op":"mcm","clk":"1005748690","pt":1580644403676,"mc":[{"id":"1.168135803","rc":[{"batb":[[0,1.12,16.24],[1,1.11,371.88],[2,1.07,27.84]],"batl":[[0,1.77,5.3],[1,1.2,0],[2,1.77,0]],"ltp":1.2,"tv":12011.84,"id":2249229}]}]}
{"op":"mcm","clk":"1005748954","pt":1580644405781,"mc":[{"id":"1.168135803","rc":[{"batl":[[0,6.2,9.24]],"ltp":4.0,"tv":5524.38,"id":5720747}]}]}
{"op":"mcm","clk":"1005749069","pt":1580644406761,"mc":[{"id":"1.168135803","rc":[{"batl":[[0,1.29,817.1],[1,1.3,752.94],[2,1.77,5.3]],"ltp":1.2,"tv":12011.84,"id":2249229}]}]}
{"op":"mcm","clk":"1005749322","pt":1580644408766,"mc":[{"id":"1.168135803","rc":[{"batb":[[1,1.07,27.84],[2,1.05,55.77]],"ltp":1.2,"tv":12011.84,"id":2249229},{"batb":[[0,1.55,18.93],[1,1.49,14.01],[2,1.25,29.54]],"ltp":4.0,"tv":5524.38,"id":5720747}]}]}
{"op":"mcm","clk":"1005749709","pt":1580644411762,"mc":[{"id":"1.168135803","rc":[{"batb":[[0,1.07,27.84],[1,1.05,55.77],[2,1.04,69.72]],"ltp":1.2,"tv":12011.84,"id":2249229},{"batl":[[0,7,18.48]],"ltp":4.0,"tv":5524.38,"id":5720747}]}]}
{"op":"mcm","clk":"1005749836","pt":1580644412762,"mc":[{"id":"1.168135803","rc":[{"batb":[[0,1.05,55.77],[1,1.04,69.72],[2,1.03,92.98]],"ltp":1.2,"tv":12011.84,"id":2249229}]}]}
{"op":"mcm","clk":"1005750119","pt":1580644414772,"mc":[{"id":"1.168135803","rc":[{"trd":[[1.26,84.02]],"batb":[[0,1.26,560.88],[1,1.25,983.9],[2,1.22,668.33]],"ltp":1.26,"tv":12095.86,"id":2249229}],"tv":17620.25}]}
{"op":"mcm","clk":"1005750500","pt":1580644417769,"mc":[{"id":"1.168135803","rc":[{"batb":[[0,2.68,598.49],[1,1.55,18.93],[2,1.49,14.01]],"ltp":4.0,"tv":5524.38,"id":5720747}]}]}
{"op":"mcm","clk":"1005750747","pt":1580644419760,"mc":[{"id":"1.168135803","rc":[{"batb":[[2,1.17,288.43]],"ltp":1.26,"tv":12095.86,"id":2249229}]}]}
{"op":"mcm","clk":"1005751282","pt":1580644423772,"mc":[{"id":"1.168135803","rc":[{"trd":[[1.26,109.87]],"batb":[[0,1.26,547.96]],"ltp":1.26,"tv":12121.71,"id":2249229}],"tv":17646.1}]}
{"op":"mcm","clk":"1005751416","pt":1580644424762,"mc":[{"id":"1.168135803","rc":[{"trd":[[1.29,94.57]],"batl":[[0,1.29,722.53]],"ltp":1.29,"tv":12216.28,"id":2249229},{"trd":[[4.4,27.73]],"ltp":4.4,"tv":5552.11,"id":5720747}],"tv":17768.39}]}
{"op":"mcm","clk":"1005751661","pt":1580644426806,"mc":[{"id":"1.168135803","rc":[{"batb":[[0,1.17,288.43],[1,1.05,55.77],[2,1.04,69.72]],"batl":[[0,1.77,5.3],[1,1.3,0],[2,1.77,0]],"ltp":1.29,"tv":12216.28,"id":2249229}]}]}
{"op":"mcm","clk":"1005751931","pt":1580644428810,"mc":[{"id":"1.168135803","rc":[{"trd":[[1.29,176.02]],"ltp":1.29,"tv":12297.73,"id":2249229},{"trd":[[4.4,51.61]],"batl":[[0,4.4,26.12]],"ltp":4.4,"tv":5575.99,"id":5720747}],"tv":17873.72}]}
{"op":"mcm","clk":"1005752611","pt":1580644433787,"mc":[{"id":"1.168135803","rc":[{"batb":[[0,1.29,3],[1,1.17,288.43],[2,1.05,55.77]],"batl":[[0,1.49,687.55],[1,1.5,396.52],[2,1.77,5.3]],"ltp":1.29,"tv":12297.73,"id":2249229},{"batl":[[1,4.8,20]],"ltp":4.4,"tv":5575.99,"id":5720747}]}]}
{"op":"mcm","clk":"1005752848","pt":1580644435777,"mc":[{"id":"1.168135803","rc":[{"trd":[[1.29,229.02]],"batb":[[0,1.17,288.43],[1,1.05,55.77],[2,1.04,2890]],"ltp":1.29,"tv":12350.73,"id":2249229},{"trd":[[4.4,65.39]],"batl":[[0,4.4,12.34]],"ltp":4.4,"tv":5589.77,"id":5720747}],"tv":17940.5}]}
{"op":"mcm","clk":"1005753211","pt":1580644438725,"mc":[{"id":"1.168135803","rc":[{"batb":[[0,1.05,55.77],[1,1.04,2890],[2,1.03,92.98]],"ltp":1.29,"tv":12350.73,"id":2249229},{"batb":[[0,1.55,18.93],[1,1.49,14.01],[2,1.25,29.54]],"batl":[[1,4.8,0]],"ltp":4.4,"tv":5589.77,"id":5720747}]}]}
{"op":"mcm","clk":"1005753322","pt":1580644439614,"mc":[{"id":"1.168135803","rc":[{"batb":[[1,1.04,69.72]],"batl":[[0,1.77,5.3],[1,1.5,0],[2,1.77,0]],"ltp":1.29,"tv":12350.73,"id":2249229}]}]}
{"op":"mcm","clk":"1005753664","pt":1580644442722,"mc":[{"id":"1.168135803","rc":[{"trd":[[1.29,271.11]],"ltp":1.29,"tv":12392.82,"id":2249229},{"trd":[[4.4,77.73]],"ltp":4.4,"tv":5602.11,"id":5720747}],"tv":17994.93}]}
{"op":"mcm","clk":"1005753774","pt":1580644443714,"mc":[{"id":"1.168135803","rc":[{"batl":[[0,1.28,100],[1,1.77,5.3]],"ltp":1.29,"tv":12392.82,"id":2249229}]}]}
{"op":"mcm","clk":"1005754133","pt":1580644446813,"mc":[{"id":"1.168135803","rc":[{"batb":[[0,1.15,311.17],[1,1.05,55.77],[2,1.04,2890]],"batl":[[1,1.49,677.36],[2,1.5,396.5]],"ltp":1.29,"tv":12392.82,"id":2249229},{"batb":[[0,2.74,593.11],[1,1.55,18.93],[2,1.49,14.01]],"ltp":4.4,"tv":5602.11,"id":5720747}]}]}
{"op":"mcm","clk":"1005754399","pt":1580644448753,"mc":[{"id":"1.168135803","rc":[{"batb":[[0,1.05,55.77],[1,1.04,2890],[2,1.03,92.98]],"ltp":1.29,"tv":12392.82,"id":2249229},{"batb":[[0,1.55,18.93],[1,1.49,14.01],[2,1.25,29.54]],"ltp":4.4,"tv":5602.11,"id":5720747}]}]}
{"op":"mcm","clk":"1005754936","pt":1580644452746,"mc":[{"id":"1.168135803","rc":[{"batl":[[1,1.77,5.3],[2,1.5,0]],"ltp":1.29,"tv":12392.82,"id":2249229}]}]}
{"op":"mcm","clk":"1005755241","pt":1580644454748,"mc":[{"id":"1.168135803","rc":[{"trd":[[1.28,100]],"batl":[[0,1.77,5.3],[1,1.77,0]],"ltp":1.28,"tv":12492.82,"id":2249229},{"trd":[[4.5,28.44]],"ltp":4.5,"tv":5630.55,"id":5720747}],"tv":18123.37}]}
{"op":"mcm","clk":"1005755373","pt":1580644455745,"mc":[{"id":"1.168135803","rc":[{"batl":[[0,1.06,2707.03],[1,1.09,147.03],[2,1.77,5.3]],"ltp":1.28,"tv":12492.82,"id":2249229}]}]}
{"op":"mcm","clk":"1005755772","pt":1580644458737,"mc":[{"id":"1.168135803","rc":[{"batb":[[1,1.04,4783.08]],"ltp":1.28,"tv":12492.82,"id":2249229}]}]}
{"op":"mcm","clk":"1005755907","pt":1580644459734,"mc":[{"id":"1.168135803","rc":[{"batl":[[2,1.29,26.5]],"ltp":1.28,"tv":12492.82,"id":2249229},{"batb":[[0,4,574.86],[1,1.55,18.93],[2,1.49,14.01]],"ltp":4.5,"tv":5630.55,"id":5720747}]}]}
{"op":"mcm","clk":"1005756036","pt":1580644460721,"mc":[{"id":"1.168135803","rc":[{"trd":[[1.05,55.77]],"batb":[[0,1.04,4783.08],[1,1.03,92.98],[2,1.02,4497.09]],"batl":[[1,1.29,26.5],[2,1.77,5.3]],"ltp":1.05,"tv":12548.59,"id":2249229},{"trd":[[21,2.79]],"ltp":21.0,"tv":5633.34,"id":5720747}],"tv":18181.93}]}
{"op":"mcm","clk":"1005756278","pt":1580644462745,"mc":[{"id":"1.168135803","rc":[{"trd":[[1.06,7.58]],"batb":[[1,1.03,3746.14]],"batl":[[0,1.06,2703.24]],"ltp":1.06,"tv":12556.17,"id":2249229}],"tv":18189.51}]}
{"op":"mcm","clk":"1005756398","pt":1580644463738,"mc":[{"id":"1.168135803","rc":[{"batb":[[0,1.04,2890]],"ltp":1.06,"tv":12556.17,"id":2249229}]}]}
{"op":"mcm","clk":"1005756509","pt":1580644464764,"mc":[{"id":"1.168135803","rc":[{"batb":[[0,1.05,25],[1,1.04,2890],[2,1.03,3746.14]],"ltp":1.06,"tv":12556.17,"id":2249229}]}]}
{"op":"mcm","clk":"1005756608","pt":1580644465759,"mc":[{"id":"1.168135803","rc":[{"batb":[[0,1.05,50]],"ltp":1.06,"tv":12556.17,"id":2249229},{"batb":[[0,18.5,3.76],[1,4,574.86],[2,1.55,18.93]],"ltp":21.0,"tv":5633.34,"id":5720747}]}]}
{"op":"mcm","clk":"1005756853","pt":1580644467740,"mc":[{"id":"1.168135803","rc":[{"trd":[[1.06,38.56]],"batb":[[1,1.04,69.72]],"batl":[[0,1.29,26.5],[1,1.77,5.3],[2,1.77,0]],"ltp":1.06,"tv":12587.15,"id":2249229}],"tv":18220.49}]}
{"op":"mcm","clk":"1005757088","pt":1580644469771,"mc":[{"id":"1.168135803","rc":[{"batb":[[0,4,574.86],[1,1.55,18.93],[2,1.49,14.01]],"ltp":21.0,"tv":5633.34,"id":5720747}]}]}
{"op":"mcm","clk":"1005757492","pt":1580644472772,"mc":[{"id":"1.168135803","rc":[{"batl":[[0,1.11,775.82],[1,1.12,1793.11],[2,1.29,26.5]],"ltp":1.06,"tv":12587.15,"id":2249229}]}]}
{"op":"mcm","clk":"1005757622","pt":1580644473758,"mc":[{"id":"1.168135803","rc":[{"trd":[[1.04,75.99],[1.05,155.77]],"batb":[[0,1.06,5],[1,1.04,31.73]],"ltp":1.04,"tv":12763.14,"id":2249229}],"tv":18396.49}]}
{"op":"mcm","clk":"1005757767","pt":1580644474756,"mc":[{"id":"1.168135803","rc":[{"batb":[[2,1.03,6017.84]],"ltp":1.04,"tv":12763.14,"id":2249229}]}]}
{"op":"mcm","clk":"1005757891","pt":1580644475804,"mc":[{"id":"1.168135803","rc":[{"trd":[[1.06,48.56]],"batb":[[0,1.04,31.73],[1,1.03,6017.84],[2,1.02,7310.27]],"batl":[[0,1.05,3],[1,1.11,775.82],[2,1.12,1793.11]],"ltp":1.06,"tv":12773.14,"id":2249229}],"tv":18406.49}]}
{"op":"mcm","clk":"1005758018","pt":1580644476766,"mc":[{"id":"1.168135803","rc":[{"trd":[[1.05,161.77],[1.11,0.36]],"batl":[[0,1.05,32.72],[1,1.11,775.64]],"ltp":1.11,"tv":12779.5,"id":2249229}],"tv":18412.85}]}
{"op":"mcm","clk":"1005758115","pt":1580644477759,"mc":[{"id":"1.168135803","rc":[{"batb":[[1,1.03,3746.14]],"ltp":1.11,"tv":12779.5,"id":2249229}]}]}
{"op":"mcm","clk":"1005758220","pt":1580644478747,"mc":[{"id":"1.168135803","rc":[{"batl":[[1,1.1,16.79],[2,1.11,775.64]],"ltp":1.11,"tv":12779.5,"id":2249229}]}]}
{"op":"mcm","clk":"1005758364","pt":1580644479785,"mc":[{"id":"1.168135803","rc":[{"trd":[[1.04,92.8]],"batb":[[0,1.04,23.32]],"ltp":1.04,"tv":12796.31,"id":2249229}],"tv":18429.65}]}
{"op":"mcm","clk":"1005758615","pt":1580644481782,"mc":[{"id":"1.168135803","rc":[{"batl":[[0,1.05,12.38],[1,1.09,200],[2,1.1,16.79]],"ltp":1.04,"tv":12796.31,"id":2249229}]}]}
{"op":"mcm","clk":"1005758734","pt":1580644482774,"mc":[{"id":"1.168135803","rc":[{"batb":[[1,2.7,25.7],[2,1.55,18.93]],"ltp":21.0,"tv":5633.34,"id":5720747}]}]}
{"op":"mcm","clk":"1005758981","pt":1580644484779,"mc":[{"id":"1.168135803","rc":[{"trd":[[1.04,133.49],[1.05,178.57]],"batb":[[0,1.04,2.97]],"batl":[[0,1.05,41.87]],"ltp":1.04,"tv":12853.8,"id":2249229}],"tv":18487.15}]}
{"op":"mcm","clk":"1005759255","pt":1580644486794,"mc":[{"id":"1.168135803","rc":[{"trd":[[1.04,136.85]],"batb":[[0,1.04,1.29]],"ltp":1.04,"tv":12857.16,"id":2249229}],"tv":18490.51}]}
{"op":"mcm","clk":"1005759383","pt":1580644487798,"mc":[{"id":"1.168135803","rc":[{"trd":[[1.05,189.93]],"batl":[[0,1.05,36.19],[2,1.11,775.64]],"ltp":1.05,"tv":12868.52,"id":2249229}],"tv":18501.87}]}
{"op":"mcm","clk":"1005759511","pt":1580644488785,"mc":[{"id":"1.168135803","rc":[{"trd":[[1.04,139.44]],"batb":[[0,1.03,3746.14],[1,1.02,7310.27],[2,1.01,5769.19]],"batl":[[0,1.04,20.71],[1,1.05,36.19],[2,1.08,10.49]],"ltp":1.04,"tv":12871.11,"id":2249229}],"tv":18504.45}]}
{"op":"mcm","clk":"1005759655","pt":1580644489777,"mc":[{"id":"1.168135803","rc":[{"trd":[[1.04,180.86],[1.05,262.31]],"batb":[[0,1.05,27.12],[1,1.03,3746.14],[2,1.02,7310.27]],"batl":[[0,1.08,20.99],[1,1.09,200],[2,1.11,775.64]],"ltp":1.05,"tv":12984.9,"id":2249229}],"tv":18618.25}]}
{"op":"mcm","clk":"1005759892","pt":1580644491770,"mc":[{"id":"1.168135803","rc":[{"batl":[[0,1.06,10],[1,1.08,20.99],[2,1.09,200]],"ltp":1.05,"tv":12984.9,"id":2249229}]}]}
{"op":"mcm","clk":"1005760035","pt":1580644492779,"mc":[{"id":"1.168135803","rc":[{"batb":[[0,1.05,77.77],[2,1.02,5692.71]],"ltp":1.05,"tv":12984.9,"id":2249229},{"batb":[[0,2.7,25.7],[1,1.55,18.93],[2,1.49,14.01]],"ltp":21.0,"tv":5633.34,"id":5720747}]}]}
{"op":"mcm","clk":"1005760162","pt":1580644493767,"mc":[{"id":"1.168135803","rc":[{"trd":[[1.06,68.55],[1.08,41.96],[1.09,36.03]],"batl":[[0,1.09,181.98],[1,1.11,775.64],[2,1.12,1793.11]],"ltp":1.09,"tv":13082.9,"id":2249229}],"tv":18716.24}]}
{"op":"mcm","clk":"1005760407","pt":1580644495769,"mc":[{"id":"1.168135803","rc":[{"trd":[[1.09,36.43]],"batl":[[0,1.09,181.78]],"ltp":1.09,"tv":13083.29,"id":2249229}],"tv":18716.64}]}
{"op":"mcm","clk":"1005760553","pt":1580644496785,"mc":[{"id":"1.168135803","rc":[{"batl":[[1,1.29,26.5],[2,1.77,5.3]],"ltp":1.09,"tv":13083.29,"id":2249229}]}]}
{"op":"mcm","clk":"1005760685","pt":1580644497785,"mc":[{"id":"1.168135803","rc":[{"batb":[[0,1.05,102.77],[1,1.03,92.98],[2,1.02,2952.84]],"ltp":1.09,"tv":13083.29,"id":2249229}]}]}
{"op":"mcm","clk":"1005760807","pt":1580644498777,"mc":[{"id":"1.168135803","rc":[{"trd":[[1.09,37.35]],"batb":[[1,1.04,21],[2,1.03,92.98]],"batl":[[0,1.09,181.32]],"ltp":1.09,"tv":13084.21,"id":2249229}],"tv":18717.56}]}
{"op":"mcm","clk":"1005760928","pt":1580644499703,"mc":[{"id":"1.168135803","rc":[{"trd":[[1.03,185.95],[1.04,222.86],[1.05,467.9]],"batb":[[0,1.02,2952.84],[1,1.01,5769.19],[2,1.03,0]],"batl":[[0,1.03,2252.05],[1,1.06,147.03],[2,1.08,25]],"ltp":1.03,"tv":13517.75,"id":2249229}],"tv":19151.09}]}
{"op":"mcm","clk":"1005761295","pt":1580644502707,"mc":[{"id":"1.168135803","rc":[{"batb":[[0,4.3,562.81],[1,2.7,25.7],[2,1.55,18.93]],"batl":[[0,160,34.17]],"ltp":21.0,"tv":5633.34,"id":5720747}]}]}
{"op":"mcm","clk":"1005761448","pt":1580644503808,"mc":[{"id":"1.168135803","rc":[{"batl":[[0,1.03,2400.86]],"ltp":1.03,"tv":13517.75,"id":2249229}]}]}
{"op":"mcm","clk":"1005761598","pt":1580644504817,"mc":[{"id":"1.168135803","rc":[{"trd":[[1.03,343.56]],"batb":[[0,1.02,3052.84]],"batl":[[0,1.03,2322.03],[1,1.05,16.8],[2,1.09,181.32]],"ltp":1.03,"tv":13675.36,"id":2249229}],"tv":19308.71}]}
{"op":"mcm","clk":"1005761729","pt":1580644505814,"mc":[{"id":"1.168135803","rc":[{"batb":[[0,1.02,3202.84]],"batl":[[1,1.05,41.99]],"ltp":1.03,"tv":13675.36,"id":2249229}]}]}
{"op":"mcm","clk":"1005761982","pt":1580644507802,"mc":[{"id":"1.168135803","rc":[{"trd":[[1.03,2343.56]],"batl":[[0,1.03,1322.03]],"ltp":1.03,"tv":15675.36,"id":2249229}],"tv":21308.71}]}
{"op":"mcm","clk":"1005762103","pt":1580644508793,"mc":[{"id":"1.168135803","rc":[{"trd":[[1.03,2512.44]],"batl":[[0,1.03,1237.59]],"ltp":1.03,"tv":15844.24,"id":2249229}],"tv":21477.59}]}
{"op":"mcm","clk":"1005762360","pt":1580644510748,"mc":[{"id":"1.168135803","rc":[{"trd":[[1.02,218.8],[1.03,3512.44]],"batb":[[0,1.02,3093.44]],"batl":[[0,1.03,737.59]],"ltp":1.02,"tv":17063.05,"id":2249229}],"tv":22696.39}]}
{"op":"mcm","clk":"1005762500","pt":1580644511789,"mc":[{"id":"1.168135803","rc":[{"trd":[[1.03,3560.53]],"batl":[[0,1.03,713.55]],"ltp":1.03,"tv":17111.13,"id":2249229}],"tv":22744.47}]}
{"op":"mcm","clk":"1005762625","pt":1580644512805,"mc":[{"id":"1.168135803","rc":[{"batb":[[0,1.02,280.26]],"batl":[[0,1.05,41.99],[1,1.09,181.32],[2,1.1,84.02]],"ltp":1.03,"tv":17111.13,"id":2249229}]}]}
{"op":"mcm","clk":"1005762744","pt":1580644513727,"mc":[{"id":"1.168135803","rc":[{"batl":[[0,1.05,45.99]],"ltp":1.03,"tv":17111.13,"id":2249229}]}]}
{"op":"mcm","clk":"1005762853","pt":1580644514625,"mc":[{"id":"1.168135803","rc":[{"batl":[[0,1.05,12.4]],"ltp":1.03,"tv":17111.13,"id":2249229}]}]}
{"op":"mcm","clk":"1005762984","pt":1580644515728,"mc":[{"id":"1.168135803","rc":[{"batl":[[0,1.04,21],[1,1.05,12.4],[2,1.09,181.32]],"ltp":1.03,"tv":17111.13,"id":2249229}]}]}
{"op":"mcm","clk":"1005763242","pt":1580644517746,"mc":[{"id":"1.168135803","rc":[{"trd":[[1.02,235.61]],"batb":[[0,1.03,15],[1,1.02,271.85],[2,1.01,5769.19]],"ltp":1.02,"tv":17127.93,"id":2249229}],"tv":22761.28}]}
{"op":"mcm","clk":"1005763400","pt":1580644518817,"mc":[{"id":"1.168135803","rc":[{"batb":[[2,1.01,7525.67]],"batl":[[2,1.06,14]],"ltp":1.02,"tv":17127.93,"id":2249229}]}]}
{"op":"mcm","clk":"1005763540","pt":1580644519804,"mc":[{"id":"1.168135803","rc":[{"batb":[[0,1.03,265]],"batl":[[1,1.05,8.4]],"ltp":1.02,"tv":17127.93,"id":2249229},{"batb":[[0,2.7,25.7],[1,1.55,18.93],[2,1.49,14.01]],"ltp":21.0,"tv":5633.34,"id":5720747}]}]}
{"op":"mcm","clk":"1005763652","pt":1580644520748,"mc":[{"id":"1.168135803","rc":[{"trd":[[1.03,3575.03]],"batb":[[0,1.03,257.75]],"ltp":1.03,"tv":17142.43,"id":2249229}],"tv":22775.78}]}
{"op":"mcm","clk":"1005763777","pt":1580644521754,"mc":[{"id":"1.168135803","rc":[{"trd":[[1.03,3589.03]],"batb":[[0,1.03,250.75]],"batl":[[1,1.05,25.2]],"ltp":1.03,"tv":17156.43,"id":2249229}],"tv":22789.78}]}
{"op":"mcm","clk":"1005763905","pt":1580644522737,"mc":[{"id":"1.168135803","rc":[{"batb":[[2,1.01,2045.91]],"batl":[[0,1.04,25]],"ltp":1.03,"tv":17156.43,"id":2249229}]}]}
{"op":"mcm","clk":"1005764162","pt":1580644524753,"mc":[{"id":"1.168135803","rc":[{"trd":[[1.02,779.31],[1.03,3590.53],[1.04,223.61]],"batb":[[0,1.01,2045.91],[1,1.02,0],[2,1.01,0]],"batl":[[0,1.02,2541.33],[1,1.03,146.29],[2,1.04,24.62]],"ltp":1.02,"tv":17702.39,"id":2249229}],"tv":23335.74}]}
{"op":"mcm","clk":"1005764275","pt":1580644525712,"mc":[{"id":"1.168135803","rc":[{"trd":[[1.02,828.05]],"batl":[[0,1.02,2516.96],[1,1.03,166.73]],"ltp":1.02,"tv":17751.13,"id":2249229}],"tv":23384.48}]}
{"op":"mcm","clk":"1005764536","pt":1580644527819,"mc":[{"id":"1.168135803","rc":[{"batb":[[0,4.6,561.43],[1,2.7,25.7],[2,1.55,18.93]],"ltp":21.0,"tv":5633.34,"id":5720747}]}]}
{"op":"mcm","clk":"1005764646","pt":1580644528802,"mc":[{"id":"1.168135803","rc":[{"trd":[[1.02,962.48]],"batb":[[0,1.01,2189.9]],"batl":[[0,1.02,2721.59]],"ltp":1.02,"tv":17885.57,"id":2249229}],"tv":23518.91}]}
{"op":"mcm","clk":"1005764756","pt":1580644529749,"mc":[{"id":"1.168135803","rc":[{"batl":[[0,1.02,2923.06],[1,1.03,20.45]],"ltp":1.02,"tv":17885.57,"id":2249229}]}]}
{"op":"mcm","clk":"1005764877","pt":1580644530767,"mc":[{"id":"1.168135803","rc":[{"trd":[[1.02,965.86]],"batl":[[0,1.02,2921.37]],"ltp":1.02,"tv":17888.95,"id":2249229}],"tv":23522.29}]}
{"op":"mcm","clk":"1005765238","pt":1580644533817,"mc":[{"id":"1.168135803","rc":[{"batl":[[1,1.04,24.62],[2,1.05,206.52]],"ltp":1.02,"tv":17888.95,"id":2249229}]}]}
{"op":"mcm","clk":"1005765588","pt":1580644536753,"mc":[{"id":"1.168135803","rc":[{"trd":[[1.01,204],[1.02,971.92]],"batb":[[0,1.01,2087.91]],"batl":[[0,1.02,2918.34]],"ltp":1.01,"tv":18099.0,"id":2249229}],"tv":23732.35}]}
{"op":"mcm","clk":"1005765718","pt":1580644537757,"mc":[{"id":"1.168135803","rc":[{"trd":[[1.01,245.32]],"batb":[[0,1.01,166.78]],"batl":[[0,1.02,201.47]],"ltp":1.01,"tv":18140.32,"id":2249229}],"tv":23773.67}]}
{"op":"mcm","clk":"1005765964","pt":1580644539747,"mc":[{"id":"1.168135803","rc":[{"trd":[[1.02,973.44]],"batl":[[0,1.02,200.71]],"ltp":1.02,"tv":18141.84,"id":2249229}],"tv":23775.18}]}
{"op":"mcm","clk":"1005766079","pt":1580644540740,"mc":[{"id":"1.168135803","rc":[{"trd":[[1.02,1057.88]],"batl":[[0,1.02,158.49]],"ltp":1.02,"tv":18226.28,"id":2249229}],"tv":23859.62}]}
{"op":"mcm","clk":"1005766221","pt":1580644541756,"mc":[{"id":"1.168135803","rc":[{"batl":[[0,1.02,200.49],[1,1.04,2783.7]],"ltp":1.02,"tv":18226.28,"id":2249229}]}]}
{"op":"mcm","clk":"1005766337","pt":1580644542772,"mc":[{"id":"1.168135803","rc":[{"trd":[[1.02,1457.88]],"batl":[[0,1.04,2784.19],[1,1.05,206.52],[2,1.06,14]],"ltp":1.02,"tv":18626.28,"id":2249229},{"batb":[[0,2.7,25.7],[1,1.55,18.93],[2,1.49,14.01]],"ltp":21.0,"tv":5633.34,"id":5720747}],"tv":24259.63}]}
{"op":"mcm","clk":"1005766452","pt":1580644543768,"mc":[{"id":"1.168135803","rc":[{"batl":[[0,1.01,46.63],[1,1.04,2784.19],[2,1.05,206.52]],"ltp":1.02,"tv":18626.28,"id":2249229}]}]}
{"op":"mcm","clk":"1005766580","pt":1580644544764,"mc":[{"id":"1.168135803","rc":[{"batl":[[1,1.04,2783.7]],"ltp":1.02,"tv":18626.28,"id":2249229}]}]}
{"op":"mcm","clk":"1005766807","pt":1580644546762,"mc":[{"id":"1.168135803","rc":[{"batl":[[1,1.03,28],[2,1.04,2783.7]],"ltp":1.02,"tv":18626.28,"id":2249229}]}]}
{"op":"mcm","clk":"1005766927","pt":1580644547755,"mc":[{"id":"1.168135803","rc":[{"batl":[[1,1.02,10],[2,1.03,28]],"ltp":1.02,"tv":18626.28,"id":2249229}]}]}
{"op":"mcm","clk":"1005767170","pt":1580644549748,"mc":[{"id":"1.168135803","rc":[{"trd":[[1.01,338.58]],"batb":[[0,1.01,28.37]],"batl":[[0,1.02,191.32],[1,1.03,28],[2,1.04,2783.7]],"ltp":1.01,"tv":18719.54,"id":2249229}],"tv":24352.89}]}
{"op":"mcm","clk":"1005767429","pt":1580644551743,"mc":[{"id":"1.168135803","rc":[{"trd":[[1.02,1512.36]],"batl":[[0,1.02,164.08]],"ltp":1.02,"tv":18774.02,"id":2249229}],"tv":24407.37}]}
{"op":"mcm","clk":"1005767843","pt":1580644554747,"mc":[{"id":"1.168135803","rc":[{"batl":[[1,1.03,56.01]],"ltp":1.02,"tv":18774.02,"id":2249229}]}]}
{"op":"mcm","clk":"1005768072","pt":1580644556784,"mc":[{"id":"1.168135803","rc":[{"batl":[[2,1.04,2779.7]],"ltp":1.02,"tv":18774.02,"id":2249229}]}]}
{"op":"mcm","clk":"1005768350","pt":1580644558788,"mc":[{"id":"1.168135803","rc":[{"batl":[[0,1.01,37.39],[1,1.02,164.08],[2,1.03,56.01]],"ltp":1.02,"tv":18774.02,"id":2249229}]}]}
{"op":"mcm","clk":"1005768747","pt":1580644561768,"mc":[{"id":"1.168135803","rc":[{"batl":[[0,1.01,2878.43]],"ltp":1.02,"tv":18774.02,"id":2249229}]}]}
{"op":"mcm","clk":"1005769032","pt":1580644563780,"mc":[{"id":"1.168135803","rc":[{"batl":[[0,1.01,2878.61]],"ltp":1.02,"tv":18774.02,"id":2249229}]}]}
{"op":"mcm","clk":"1005769301","pt":1580644565788,"mc":[{"id":"1.168135803","rc":[{"batb":[[0,4.8,547.77],[1,2.7,25.7],[2,1.55,18.93]],"ltp":21.0,"tv":5633.34,"id":5720747}]}]}
{"op":"mcm","clk":"1005769565","pt":1580644567792,"mc":[{"id":"1.168135803","rc":[{"batl":[[0,1.01,11231.08]],"ltp":1.02,"tv":18774.02,"id":2249229}]}]}
{"op":"mcm","clk":"1005769849","pt":1580644569790,"mc":[{"id":"1.168135803","rc":[{"trd":[[1.01,558.75]],"batl":[[0,1.01,11159.38]],"ltp":1.01,"tv":18994.2,"id":2249229}],"tv":24627.54}]}
{"op":"mcm","clk":"1005769989","pt":1580644570799,"mc":[{"id":"1.168135803","rc":[{"batl":[[0,1.01,11155.59]],"ltp":1.01,"tv":18994.2,"id":2249229}]}]}
{"op":"mcm","clk":"1005770262","pt":1580644572805,"mc":[{"id":"1.168135803","rc":[{"batl":[[0,1.01,11155.3]],"ltp":1.01,"tv":18994.2,"id":2249229}]}]}
{"op":"mcm","clk":"1005771371","pt":1580644580725,"mc":[{"id":"1.168135803","rc":[{"batb":[[0,2.7,25.7],[1,1.55,18.93],[2,1.49,14.01]],"ltp":21.0,"tv":5633.34,"id":5720747}]}]}
{"op":"mcm","clk":"1005771543","pt":1580644581802,"mc":[{"id":"1.168135803","rc":[{"batl":[[0,1.01,11344.75]],"ltp":1.01,"tv":18994.2,"id":2249229}]}]}
{"op":"mcm","clk":"1005771835","pt":1580644583812,"mc":[{"id":"1.168135803","rc":[{"batl":[[0,1.01,8576.41]],"ltp":1.01,"tv":18994.2,"id":2249229}]}]}
{"op":"mcm","clk":"1005773137","pt":1580644592716,"mc":[{"id":"1.168135803","rc":[{"batb":[[0,140,1.89],[1,2.7,25.7],[2,1.55,18.93]],"ltp":21.0,"tv":5633.34,"id":5720747}]}]}
{"op":"mcm","clk":"1005773680","pt":1580644596815,"mc":[{"id":"1.168135803","rc":[{"batl":[[0,1.01,8538.02]],"ltp":1.01,"tv":18994.2,"id":2249229}]}]}
{"op":"mcm","clk":"1005773931","pt":1580644598818,"mc":[{"id":"1.168135803","rc":[{"batb":[[0,200,3.03],[1,140,1.89],[2,2.7,25.7]],"ltp":21.0,"tv":5633.34,"id":5720747}]}]}
{"op":"mcm","clk":"1005774427","pt":1580644602718,"mc":[{"id":"1.168135803","marketDefinition":{"bspMarket":false,"turnInPlayEnabled":true,"persistenceEnabled":true,"marketBaseRate":5.0,"eventId":"29678823","eventTypeId":"2","numberOfWinners":1,"bettingType":"ODDS","marketType":"SET_WINNER","marketTime":"2020-02-02T08:30:00.000Z","suspendTime":"2020-02-02T08:30:00.000Z","bspReconciled":false,"complete":true,"inPlay":true,"crossMatching":true,"runnersVoidable":false,"numberOfActiveRunners":2,"betDelay":3,"status":"SUSPENDED","runners":[{"status":"ACTIVE","sortPriority":1,"id":5720747,"name":"Dominic Thiem"},{"status":"ACTIVE","sortPriority":2,"id":2249229,"name":"Novak Djokovic"}],"regulators":["MR_INT"],"countryCode":"AU","discountAllowed":true,"timezone":"GMT","openDate":"2020-02-02T08:30:00.000Z","version":3148627414,"name":"Set 4 Winner","eventName":"Thiem v Djokovic"}}]}
{"op":"mcm","clk":"1005774861","pt":1580644605737,"mc":[{"id":"1.168135803","rc":[{"batl":[[0,1.01,8348.57]],"ltp":1.01,"tv":18994.2,"id":2249229},{"batb":[[1,2.7,25.7],[2,1.55,18.93]],"ltp":21.0,"tv":5633.34,"id":5720747}]}]}
{"op":"mcm","clk":"1005775126","pt":1580644607739,"mc":[{"id":"1.168135803","rc":[{"batb":[[0,2.7,25.7],[1,1.55,18.93],[2,1.49,14.01]],"ltp":21.0,"tv":5633.34,"id":5720747}]}]}
{"op":"mcm","clk":"1005775259","pt":1580644608739,"mc":[{"id":"1.168135803","rc":[{"batb":[[1,1.49,14.01],[2,1.05,16.81]],"ltp":21.0,"tv":5633.34,"id":5720747}]}]}
{"op":"mcm","clk":"1005776193","pt":1580644615756,"mc":[{"id":"1.168135803","rc":[{"batl":[[0,1.01,786.82]],"ltp":1.01,"tv":18994.2,"id":2249229}]}]}
{"op":"mcm","clk":"1005779432","pt":1580644641800,"mc":[{"id":"1.168135803","tv":0.0}]}
{"op":"mcm","clk":"1005779580","pt":1580644642794,"mc":[{"id":"1.168135803","marketDefinition":{"bspMarket":false,"turnInPlayEnabled":true,"persistenceEnabled":true,"marketBaseRate":5.0,"eventId":"29678823","eventTypeId":"2","numberOfWinners":1,"bettingType":"ODDS","marketType":"SET_WINNER","marketTime":"2020-02-02T08:30:00.000Z","suspendTime":"2020-02-02T08:30:00.000Z","bspReconciled":false,"complete":true,"inPlay":true,"crossMatching":false,"runnersVoidable":false,"numberOfActiveRunners":0,"betDelay":3,"status":"CLOSED","settledTime":"2020-02-02T11:57:15.000Z","runners":[{"status":"LOSER","sortPriority":1,"id":5720747,"name":"Dominic Thiem"},{"status":"WINNER","sortPriority":2,"id":2249229,"name":"Novak Djokovic"}],"regulators":["MR_INT"],"countryCode":"AU","discountAllowed":true,"timezone":"GMT","openDate":"2020-02-02T08:30:00.000Z","version":3148629545,"name":"Set 4 Winner","eventName":"Thiem v Djokovic"}}]}
