{"op":"mcm","clk":"988026418","pt":1580473742115,"mc":[{"id":"1.168135752","marketDefinition":{"bspMarket":false,"turnInPlayEnabled":true,"persistenceEnabled":true,"marketBaseRate":5.0,"eventId":"29678823","eventTypeId":"2","numberOfWinners":1,"bettingType":"ODDS","marketType":"PLAYER_A_WIN_A_SET","marketTime":"2020-02-02T08:30:00.000Z","suspendTime":"2020-02-02T08:30:00.000Z","bspReconciled":false,"complete":true,"inPlay":false,"crossMatching":false,"runnersVoidable":false,"numberOfActiveRunners":2,"betDelay":0,"status":"OPEN","runners":[{"status":"ACTIVE","sortPriority":1,"id":41364,"name":"Yes"},{"status":"ACTIVE","sortPriority":2,"id":41365,"name":"No"}],"regulators":["MR_INT"],"countryCode":"AU","discountAllowed":false,"timezone":"GMT","openDate":"2020-02-02T08:30:00.000Z","version":3143005253,"name":"Thiem To Win A Set?","eventName":"Thiem v Djokovic"}}]}
{"op":"mcm","clk":"988026715","pt":1580473744836,"mc":[{"id":"1.168135752","marketDefinition":{"bspMarket":false,"turnInPlayEnabled":true,"persistenceEnabled":true,"marketBaseRate":5.0,"eventId":"29678823","eventTypeId":"2","numberOfWinners":1,"bettingType":"ODDS","marketType":"PLAYER_A_WIN_A_SET","marketTime":"2020-02-02T08:30:00.000Z","suspendTime":"2020-02-02T08:30:00.000Z","bspReconciled":false,"complete":true,"inPlay":false,"crossMatching":false,"runnersVoidable":false,"numberOfActiveRunners":2,"betDelay":0,"status":"OPEN","runners":[{"status":"ACTIVE","sortPriority":1,"id":41364,"name":"Yes"},{"status":"ACTIVE","sortPriority":2,"id":41365,"name":"No"}],"regulators":["MR_INT"],"countryCode":"AU","discountAllowed":true,"timezone":"GMT","openDate":"2020-02-02T08:30:00.000Z","version":3143005253,"name":"Thiem To Win A Set?","eventName":"Thiem v Djokovic"}}]}
{"op":"mcm","clk":"988134662","pt":1580474689003,"mc":[{"id":"1.168135752","rc":[{"batb":[[0,1.25,509.84]],"ltp":0.0,"tv":0.0,"id":41364}]}]}
{"op":"mcm","clk":"988465876","pt":1580477515477,"mc":[{"id":"1.168135752","rc":[{"batl":[[0,2.3,25.23]],"ltp":0.0,"tv":0.0,"id":41364}]}]}
{"op":"mcm","clk":"988469454","pt":1580477545251,"mc":[{"id":"1.168135752","rc":[{"batb":[[0,1.26,96.7],[1,1.25,509.84]],"ltp":0.0,"tv":0.0,"id":41364}]}]}
{"op":"mcm","clk":"988495817","pt":1580477791137,"mc":[{"id":"1.168135752","rc":[{"batb":[[0,1.27,6.24],[1,1.26,96.7],[2,1.25,509.84]],"ltp":0.0,"tv":0.0,"id":41364}]}]}
{"op":"mcm","clk":"988687353","pt":1580479652167,"mc":[{"id":"1.168135752","rc":[{"batb":[[0,1.27,6.23],[1,1.26,96.72],[2,1.25,509.97]],"batl":[[0,2.3,25.23]],"ltp":0.0,"tv":0.0,"id":41364}]}]}
{"op":"mcm","clk":"988827190","pt":1580481133776,"mc":[{"id":"1.168135752","rc":[{"batb":[[0,1.28,509.97],[1,1.27,6.23],[2,1.26,96.72]],"ltp":0.0,"tv":0.0,"id":41364}]}]}
{"op":"mcm","clk":"988827573","pt":1580481138102,"mc":[{"id":"1.168135752","rc":[{"batl":[[0,2,22.44],[1,2.3,25.23]],"ltp":0.0,"tv":0.0,"id":41364}]}]}
{"op":"mcm","clk":"988890381","pt":1580481727811,"mc":[{"id":"1.168135752","rc":[{"batb":[[0,1.29,136.17],[1,1.28,509.97],[2,1.27,6.23]],"ltp":0.0,"tv":0.0,"id":41364}]}]}
{"op":"mcm","clk":"988893516","pt":1580481763252,"mc":[{"id":"1.168135752","marketDefinition":{"bspMarket":false,"turnInPlayEnabled":true,"persistenceEnabled":true,"marketBaseRate":5.0,"eventId":"29678823","eventTypeId":"2","numberOfWinners":1,"bettingType":"ODDS","marketType":"PLAYER_A_WIN_A_SET","marketTime":"2020-02-02T08:30:00.000Z","suspendTime":"2020-02-02T08:30:00.000Z","bspReconciled":false,"complete":true,"inPlay":false,"crossMatching":true,"runnersVoidable":false,"numberOfActiveRunners":2,"betDelay":0,"status":"OPEN","runners":[{"status":"ACTIVE","sortPriority":1,"id":41364,"name":"Yes"},{"status":"ACTIVE","sortPriority":2,"id":41365,"name":"No"}],"regulators":["MR_INT"],"countryCode":"AU","discountAllowed":true,"timezone":"GMT","openDate":"2020-02-02T08:30:00.000Z","version":3143005253,"name":"Thiem To Win A Set?","eventName":"Thiem v Djokovic"}}]}
{"op":"mcm","clk":"988953708","pt":1580482521040,"mc":[{"id":"1.168135752","rc":[{"batb":[[0,2.02,51]],"ltp":0.0,"tv":0.0,"id":41365}]}]}
{"op":"mcm","clk":"989068610","pt":1580483943796,"mc":[{"id":"1.168135752","rc":[{"batb":[[0,1.3,6.23],[1,1.29,136.17],[2,1.28,509.97]],"ltp":0.0,"tv":0.0,"id":41364}]}]}
{"op":"mcm","clk":"989188303","pt":1580485260119,"mc":[{"id":"1.168135752","rc":[{"batl":[[0,3.3,161]],"ltp":0.0,"tv":0.0,"id":41365}]}]}
{"op":"mcm","clk":"989340032","pt":1580486852178,"mc":[{"id":"1.168135752","rc":[{"batb":[[0,1.3,6.21],[1,1.29,135.63],[2,1.28,507.98]],"batl":[[0,2,22.35],[1,2.3,25.23]],"ltp":0.0,"tv":0.0,"id":41364},{"batb":[[0,2.02,50.8]],"ltp":0.0,"tv":0.0,"id":41365}]}]}
{"op":"mcm","clk":"989363586","pt":1580487079951,"mc":[{"id":"1.168135752","rc":[{"batb":[[0,1.44,6.21]],"ltp":0.0,"tv":0.0,"id":41364}]}]}
{"op":"mcm","clk":"990094308","pt":1580494052126,"mc":[{"id":"1.168135752","rc":[{"batb":[[0,1.44,6.21],[1,1.29,135.5],[2,1.28,507.49]],"batl":[[0,2,22.33],[1,2.3,25.2]],"ltp":0.0,"tv":0.0,"id":41364},{"batb":[[0,2.02,50.75]],"ltp":0.0,"tv":0.0,"id":41365}]}]}
{"op":"mcm","clk":"991045160","pt":1580501252131,"mc":[{"id":"1.168135752","rc":[{"batb":[[0,1.44,6.2],[1,1.29,135.43],[2,1.28,507.23]],"batl":[[0,2,22.32],[1,2.3,25.2]],"ltp":0.0,"tv":0.0,"id":41364},{"batb":[[0,2.02,50.72]],"ltp":0.0,"tv":0.0,"id":41365}]}]}
{"op":"mcm","clk":"991384020","pt":1580503416682,"mc":[{"id":"1.168135752","rc":[{"batl":[[0,1.9,11.16],[1,2,22.32],[2,2.3,25.2]],"ltp":0.0,"tv":0.0,"id":41364}]}]}
{"op":"mcm","clk":"991387862","pt":1580503446814,"mc":[{"id":"1.168135752","rc":[{"batb":[[0,1.5,20.29],[1,1.44,6.2],[2,1.29,135.43]],"ltp":0.0,"tv":0.0,"id":41364}]}]}
{"op":"mcm","clk":"991806450","pt":1580508452143,"mc":[{"id":"1.168135752","rc":[{"batb":[[0,1.5,20.26],[2,1.29,135.24]],"batl":[[0,1.9,11.14],[1,2,22.29],[2,2.3,25.21]],"ltp":0.0,"tv":0.0,"id":41364},{"batb":[[0,2.02,50.65]],"ltp":0.0,"tv":0.0,"id":41365}]}]}
{"op":"mcm","clk":"991991655","pt":1580511708815,"mc":[{"id":"1.168135752","rc":[{"batb":[[1,1.01,0.51]],"ltp":0.0,"tv":0.0,"id":41365}]}]}
{"op":"mcm","clk":"992004256","pt":1580511984580,"mc":[{"id":"1.168135752","rc":[{"batb":[[1,1.01,3.04]],"ltp":0.0,"tv":0.0,"id":41365}]}]}
{"op":"mcm","clk":"992004295","pt":1580511985664,"mc":[{"id":"1.168135752","rc":[{"batb":[[1,1.01,1.01]],"ltp":0.0,"tv":0.0,"id":41365}]}]}
{"op":"mcm","clk":"992049061","pt":1580512825033,"mc":[{"id":"1.168135752","rc":[{"batb":[[0,2.12,126.63],[1,2.02,50.65],[2,1.01,1.01]],"ltp":0.0,"tv":0.0,"id":41365}]}]}
{"op":"mcm","clk":"992610335","pt":1580526774725,"mc":[{"id":"1.168135752","rc":[{"batl":[[0,1.9,26.66]],"ltp":0.0,"tv":0.0,"id":41364}]}]}
{"op":"mcm","clk":"992610608","pt":1580526783762,"mc":[{"id":"1.168135752","rc":[{"batl":[[0,1.89,15.52],[1,1.9,11.14],[2,2,22.29]],"ltp":0.0,"tv":0.0,"id":41364}]}]}
{"op":"mcm","clk":"992610831","pt":1580526790652,"mc":[{"id":"1.168135752","rc":[{"batl":[[0,1.83,15.52]],"ltp":0.0,"tv":0.0,"id":41364}]}]}
{"op":"mcm","clk":"992611057","pt":1580526797059,"mc":[{"id":"1.168135752","rc":[{"batl":[[0,1.77,15.52]],"ltp":0.0,"tv":0.0,"id":41364}]}]}
{"op":"mcm","clk":"992611302","pt":1580526803154,"mc":[{"id":"1.168135752","rc":[{"batl":[[0,1.72,15.52]],"ltp":0.0,"tv":0.0,"id":41364}]}]}
{"op":"mcm","clk":"992611643","pt":1580526815180,"mc":[{"id":"1.168135752","rc":[{"batl":[[0,1.69,15.52]],"ltp":0.0,"tv":0.0,"id":41364}]}]}
{"op":"mcm","clk":"992611963","pt":1580526824967,"mc":[{"id":"1.168135752","rc":[{"batl":[[0,1.65,15.52]],"ltp":0.0,"tv":0.0,"id":41364}]}]}
{"op":"mcm","clk":"992612186","pt":1580526831578,"mc":[{"id":"1.168135752","rc":[{"batl":[[0,1.62,15.52]],"ltp":0.0,"tv":0.0,"id":41364}]}]}
{"op":"mcm","clk":"992612533","pt":1580526840725,"mc":[{"id":"1.168135752","rc":[{"batl":[[0,1.9,11.14],[1,2,22.29],[2,2.3,25.21]],"ltp":0.0,"tv":0.0,"id":41364}]}]}
{"op":"mcm","clk":"992612537","pt":1580526840823,"mc":[{"id":"1.168135752","rc":[{"batl":[[0,1.59,15.52],[1,1.9,11.14],[2,2,22.29]],"ltp":0.0,"tv":0.0,"id":41364}]}]}
{"op":"mcm","clk":"992612730","pt":1580526847620,"mc":[{"id":"1.168135752","rc":[{"batl":[[0,1.57,15.52]],"ltp":0.0,"tv":0.0,"id":41364}]}]}
{"op":"mcm","clk":"992612936","pt":1580526853803,"mc":[{"id":"1.168135752","rc":[{"batl":[[0,1.55,15.52]],"ltp":0.0,"tv":0.0,"id":41364}]}]}
{"op":"mcm","clk":"992613134","pt":1580526860748,"mc":[{"id":"1.168135752","rc":[{"batl":[[0,1.9,11.14],[1,2,22.29],[2,2.3,25.21]],"ltp":0.0,"tv":0.0,"id":41364}]}]}
{"op":"mcm","clk":"992613138","pt":1580526860851,"mc":[{"id":"1.168135752","rc":[{"batl":[[0,1.52,15.52],[1,1.9,11.14],[2,2,22.29]],"ltp":0.0,"tv":0.0,"id":41364}]}]}
{"op":"mcm","clk":"992613370","pt":1580526868038,"mc":[{"id":"1.168135752","rc":[{"batl":[[0,1.51,15.52]],"ltp":0.0,"tv":0.0,"id":41364}]}]}
{"op":"mcm","clk":"992613664","pt":1580526877132,"mc":[{"id":"1.168135752","rc":[{"trd":[[1.5,31.02]],"batb":[[0,1.5,4.76]],"batl":[[0,1.9,11.14],[1,2,22.29],[2,2.3,25.21]],"ltp":1.5,"tv":31.02,"id":41364}],"tv":31.02}]}
{"op":"mcm","clk":"992646026","pt":1580527558371,"mc":[{"id":"1.168135752","rc":[{"batb":[[0,2.14,50.65],[1,2.12,126.63]],"ltp":0.0,"tv":0.0,"id":41365}]}]}
{"op":"mcm","clk":"992980091","pt":1580534355041,"mc":[{"id":"1.168135752","rc":[{"batb":[[0,2.16,126.63],[1,2.14,50.65]],"ltp":0.0,"tv":0.0,"id":41365}]}]}
{"op":"mcm","clk":"993297630","pt":1580540112224,"mc":[{"id":"1.168135752","rc":[{"batb":[[1,1.44,141.44],[2,1.28,506.51]],"ltp":1.5,"tv":31.02,"id":41364}]}]}
{"op":"mcm","clk":"993367925","pt":1580541395660,"mc":[{"id":"1.168135752","rc":[{"batl":[[0,1.86,49.79],[1,1.9,11.14],[2,2,22.29]],"ltp":1.5,"tv":31.02,"id":41364}]}]}
{"op":"mcm","clk":"993662443","pt":1580545052364,"mc":[{"id":"1.168135752","rc":[{"batl":[[0,3,161],[1,3.3,161]],"ltp":0.0,"tv":0.0,"id":41365}]}]}
{"op":"mcm","clk":"993705311","pt":1580545450606,"mc":[{"id":"1.168135752","rc":[{"batb":[[0,1.51,6.2],[1,1.5,4.76],[2,1.44,135.24]],"ltp":1.5,"tv":31.02,"id":41364}]}]}
{"op":"mcm","clk":"993711587","pt":1580545522147,"mc":[{"id":"1.168135752","rc":[{"batl":[[0,1.9,11.14],[1,2,22.29],[2,2.3,25.21]],"ltp":1.5,"tv":31.02,"id":41364}]}]}
{"op":"mcm","clk":"995347541","pt":1580556520042,"mc":[{"id":"1.168135752","rc":[{"batb":[[0,2.18,50.65],[1,2.16,126.63]],"ltp":0.0,"tv":0.0,"id":41365}]}]}
{"op":"mcm","clk":"995925662","pt":1580559522000,"mc":[{"id":"1.168135752","rc":[{"trd":[[2.18,21.33]],"batb":[[0,2.18,39.99]],"ltp":2.18,"tv":21.32,"id":41365}],"tv":52.35}]}
{"op":"mcm","clk":"995926865","pt":1580559528890,"mc":[{"id":"1.168135752","rc":[{"trd":[[1.85,0.01]],"ltp":1.85,"tv":31.03,"id":41364},{"trd":[[2.18,21.34]],"batb":[[0,2.18,39.98]],"ltp":2.18,"tv":21.33,"id":41365}],"tv":52.37}]}
{"op":"mcm","clk":"995982642","pt":1580559786483,"mc":[{"id":"1.168135752","rc":[{"batb":[[0,1.51,21.34]],"ltp":1.85,"tv":31.03,"id":41364}]}]}
{"op":"mcm","clk":"997157542","pt":1580565650683,"mc":[{"id":"1.168135752","rc":[{"batl":[[0,2.96,50.65],[1,3,161],[2,3.3,161]],"ltp":2.18,"tv":21.33,"id":41365}]}]}
{"op":"mcm","clk":"997587401","pt":1580567430048,"mc":[{"id":"1.168135752","rc":[{"batb":[[0,2.2,833],[1,2.18,39.98],[2,2.16,126.63]],"ltp":2.18,"tv":21.33,"id":41365}]}]}
{"op":"mcm","clk":"997725850","pt":1580567986793,"mc":[{"id":"1.168135752","rc":[{"batb":[[0,1.52,6.2],[1,1.51,15.14],[2,1.5,4.76]],"ltp":1.85,"tv":31.03,"id":41364}]}]}
{"op":"mcm","clk":"997726024","pt":1580567987498,"mc":[{"id":"1.168135752","rc":[{"batb":[[0,2.22,5.75],[1,2.2,833],[2,2.18,39.98]],"ltp":2.18,"tv":21.33,"id":41365}]}]}
{"op":"mcm","clk":"997768313","pt":1580568160222,"mc":[{"id":"1.168135752","rc":[{"batl":[[0,1.82,50.65],[1,1.9,11.14],[2,2,22.29]],"ltp":1.85,"tv":31.03,"id":41364}]}]}
{"op":"mcm","clk":"997851182","pt":1580568494183,"mc":[{"id":"1.168135752","rc":[{"batl":[[0,1.81,50.65]],"ltp":1.85,"tv":31.03,"id":41364}]}]}
{"op":"mcm","clk":"999052349","pt":1580573368478,"mc":[{"id":"1.168135752","rc":[{"batb":[[0,2.24,833],[1,2.22,5.75]],"ltp":2.18,"tv":21.33,"id":41365}]}]}
{"op":"mcm","clk":"999419387","pt":1580574739404,"mc":[{"id":"1.168135752","rc":[{"batb":[[0,2.26,5.75],[1,2.24,833]],"ltp":2.18,"tv":21.33,"id":41365}]}]}
{"op":"mcm","clk":"1000165756","pt":1580579078070,"mc":[{"id":"1.168135752","rc":[{"trd":[[1.52,5.06]],"batb":[[0,1.52,3.67]],"ltp":1.52,"tv":36.09,"id":41364}],"tv":57.43}]}
{"op":"mcm","clk":"1001696823","pt":1580588099612,"mc":[{"id":"1.168135752","rc":[{"batb":[[0,1.55,466.31],[1,1.52,3.67],[2,1.51,15.14]],"ltp":1.52,"tv":36.09,"id":41364}]}]}
{"op":"mcm","clk":"1001746982","pt":1580588357804,"mc":[{"id":"1.168135752","rc":[{"batb":[[0,1.56,3.67],[1,1.55,466.31]],"ltp":1.52,"tv":36.09,"id":41364}]}]}
{"op":"mcm","clk":"1001761143","pt":1580588438726,"mc":[{"id":"1.168135752","rc":[{"batl":[[0,1.61,15.9],[1,1.81,50.65],[2,1.9,11.14]],"ltp":1.52,"tv":36.09,"id":41364}]}]}
{"op":"mcm","clk":"1001762255","pt":1580588445025,"mc":[{"id":"1.168135752","rc":[{"batl":[[0,1.6,15.9]],"ltp":1.52,"tv":36.09,"id":41364}]}]}
{"op":"mcm","clk":"1001762858","pt":1580588448523,"mc":[{"id":"1.168135752","rc":[{"batl":[[0,1.59,15.9]],"ltp":1.52,"tv":36.09,"id":41364}]}]}
{"op":"mcm","clk":"1001763635","pt":1580588452737,"mc":[{"id":"1.168135752","rc":[{"batl":[[0,1.58,15.9]],"ltp":1.52,"tv":36.09,"id":41364}]}]}
{"op":"mcm","clk":"1001764485","pt":1580588457523,"mc":[{"id":"1.168135752","rc":[{"batl":[[0,1.57,15.9]],"ltp":1.52,"tv":36.09,"id":41364}]}]}
{"op":"mcm","clk":"1001765438","pt":1580588462939,"mc":[{"id":"1.168135752","rc":[{"trd":[[1.56,7.34]],"batb":[[0,1.55,466.31],[1,1.51,15.14],[2,1.5,4.76]],"batl":[[0,1.56,12.23]],"ltp":1.56,"tv":43.43,"id":41364}],"tv":64.77}]}
{"op":"mcm","clk":"1001766971","pt":1580588471754,"mc":[{"id":"1.168135752","rc":[{"trd":[[1.55,24.46]],"batb":[[0,1.55,454.07]],"batl":[[0,1.81,50.65],[1,1.9,11.14],[2,2,22.29]],"ltp":1.55,"tv":67.9,"id":41364}],"tv":89.23}]}
{"op":"mcm","clk":"1001921244","pt":1580589342486,"mc":[{"id":"1.168135752","rc":[{"batl":[[0,2.78,8.44],[1,2.96,50.65],[2,3,161]],"ltp":2.18,"tv":21.33,"id":41365}]}]}
{"op":"mcm","clk":"1001925870","pt":1580589372050,"mc":[{"id":"1.168135752","rc":[{"batl":[[0,2.76,8.44],[1,2.78,8.44],[2,2.96,50.65]],"ltp":2.18,"tv":21.33,"id":41365}]}]}
{"op":"mcm","clk":"1002140312","pt":1580590857877,"mc":[{"id":"1.168135752","rc":[{"batb":[[0,1.56,7.39],[1,1.55,454.07],[2,1.51,15.14]],"ltp":1.55,"tv":67.9,"id":41364}]}]}
{"op":"mcm","clk":"1002466645","pt":1580594055448,"mc":[{"id":"1.168135752","rc":[{"batb":[[0,2.26,45.73],[2,2.16,126.63]],"ltp":2.18,"tv":21.33,"id":41365}]}]}
{"op":"mcm","clk":"1002537074","pt":1580595065370,"mc":[{"id":"1.168135752","rc":[{"trd":[[1.56,25.28]],"batb":[[0,1.55,454.07],[1,1.51,15.14],[2,1.5,4.76]],"ltp":1.56,"tv":85.83,"id":41364},{"trd":[[2.76,1.79]],"batl":[[0,2.76,6.65]],"ltp":2.76,"tv":23.12,"id":41365}],"tv":108.96}]}
{"op":"mcm","clk":"1002700461","pt":1580597483591,"mc":[{"id":"1.168135752","rc":[{"trd":[[1.56,27.78]],"ltp":1.56,"tv":88.33,"id":41364},{"trd":[[2.76,3.2]],"batl":[[0,2.76,5.24]],"ltp":2.76,"tv":24.53,"id":41365}],"tv":112.87}]}
{"op":"mcm","clk":"1002732460","pt":1580597981435,"mc":[{"id":"1.168135752","rc":[{"batb":[[0,1.56,6.19],[1,1.55,454.07],[2,1.51,15.14]],"ltp":1.56,"tv":88.33,"id":41364}]}]}
{"op":"mcm","clk":"1002746042","pt":1580598176533,"mc":[{"id":"1.168135752","rc":[{"batb":[[0,2.28,126.63],[1,2.26,45.73],[2,2.24,833]],"ltp":2.76,"tv":24.53,"id":41365}]}]}
{"op":"mcm","clk":"1002749812","pt":1580598227967,"mc":[{"id":"1.168135752","rc":[{"batb":[[0,2.3,39.98],[1,2.28,126.63],[2,2.26,5.75]],"ltp":2.76,"tv":24.53,"id":41365}]}]}
{"op":"mcm","clk":"1002840980","pt":1580599497561,"mc":[{"id":"1.168135752","rc":[{"batb":[[0,2.34,22],[1,2.3,39.98],[2,2.28,126.63]],"ltp":2.76,"tv":24.53,"id":41365}]}]}
{"op":"mcm","clk":"1002895854","pt":1580600237071,"mc":[{"id":"1.168135752","rc":[{"trd":[[1.56,32.84]],"batb":[[0,1.56,3.67]],"ltp":1.56,"tv":93.39,"id":41364}],"tv":117.93}]}
{"op":"mcm","clk":"1002906190","pt":1580600402538,"mc":[{"id":"1.168135752","rc":[{"trd":[[1.56,63.51]],"batb":[[0,1.55,454.07],[1,1.51,15.14],[2,1.5,4.76]],"ltp":1.56,"tv":124.06,"id":41364},{"trd":[[2.76,8.44],[2.78,7.89]],"batl":[[0,2.96,51.2],[1,3,161],[2,2.96,0]],"ltp":2.78,"tv":37.66,"id":41365}],"tv":161.72}]}
{"op":"mcm","clk":"1002907650","pt":1580600424599,"mc":[{"id":"1.168135752","rc":[{"trd":[[1.55,68.52],[1.56,64.48]],"batb":[[0,1.55,432.05]],"ltp":1.55,"tv":169.09,"id":41364},{"trd":[[2.78,8.44]],"batl":[[0,2.96,50.65]],"ltp":2.78,"tv":38.2,"id":41365}],"tv":207.3}]}
{"op":"mcm","clk":"1002911415","pt":1580600476457,"mc":[{"id":"1.168135752","rc":[{"trd":[[1.55,268.52]],"batb":[[0,1.55,332.05]],"ltp":1.55,"tv":369.09,"id":41364}],"tv":407.3}]}
{"op":"mcm","clk":"1002921720","pt":1580600629815,"mc":[{"id":"1.168135752","rc":[{"batb":[[0,2.36,5.75],[1,2.34,22],[2,2.3,39.98]],"ltp":2.78,"tv":38.2,"id":41365}]}]}
{"op":"mcm","clk":"1002922900","pt":1580600649217,"mc":[{"id":"1.168135752","rc":[{"batl":[[0,1.59,170],[1,1.81,50.65],[2,1.9,11.14]],"ltp":1.55,"tv":369.09,"id":41364}]}]}
{"op":"mcm","clk":"1002929638","pt":1580600765072,"mc":[{"id":"1.168135752","rc":[{"batl":[[1,1.6,500],[2,1.81,50.65]],"ltp":1.55,"tv":369.09,"id":41364}]}]}
{"op":"mcm","clk":"1002941856","pt":1580600945187,"mc":[{"id":"1.168135752","rc":[{"trd":[[1.55,273.53]],"batb":[[0,1.55,329.54]],"ltp":1.55,"tv":374.09,"id":41364}],"tv":412.3}]}
{"op":"mcm","clk":"1002942555","pt":1580600954780,"mc":[{"id":"1.168135752","rc":[{"trd":[[1.55,278.53]],"batb":[[0,1.55,327.04]],"ltp":1.55,"tv":379.1,"id":41364}],"tv":417.31}]}
{"op":"mcm","clk":"1002964054","pt":1580601266293,"mc":[{"id":"1.168135752","rc":[{"trd":[[1.59,51.66]],"batl":[[0,1.59,144.16]],"ltp":1.59,"tv":430.75,"id":41364}],"tv":468.96}]}
{"op":"mcm","clk":"1003119926","pt":1580603254811,"mc":[{"id":"1.168135752","rc":[{"batb":[[0,2.34,22],[1,2.3,39.98],[2,1.01,1.01]],"ltp":2.78,"tv":38.2,"id":41365}]}]}
{"op":"mcm","clk":"1003153230","pt":1580603644743,"mc":[{"id":"1.168135752","rc":[{"batl":[[1,1.81,50.65],[2,1.9,11.14]],"ltp":1.59,"tv":430.75,"id":41364}]}]}
{"op":"mcm","clk":"1003153239","pt":1580603644837,"mc":[{"id":"1.168135752","rc":[{"batl":[[1,1.61,500],[2,1.81,50.65]],"ltp":1.59,"tv":430.75,"id":41364}]}]}
{"op":"mcm","clk":"1003192697","pt":1580604208018,"mc":[{"id":"1.168135752","rc":[{"batb":[[0,2.7,39.98],[1,2.34,22]],"ltp":2.78,"tv":38.2,"id":41365}]}]}
{"op":"mcm","clk":"1003219349","pt":1580604646774,"mc":[{"id":"1.168135752","rc":[{"batb":[[0,2.34,22],[1,1.01,1.01],[2,1.01,0]],"ltp":2.78,"tv":38.2,"id":41365}]}]}
{"op":"mcm","clk":"1003219359","pt":1580604646830,"mc":[{"id":"1.168135752","rc":[{"batb":[[0,2.64,39.98],[1,2.34,22],[2,1.01,1.01]],"ltp":2.78,"tv":38.2,"id":41365}]}]}
{"op":"mcm","clk":"1003268198","pt":1580605438124,"mc":[{"id":"1.168135752","rc":[{"trd":[[1.55,312.14]],"batb":[[0,1.55,310.23]],"ltp":1.55,"tv":464.36,"id":41364}],"tv":502.57}]}
{"op":"mcm","clk":"1003319270","pt":1580606166111,"mc":[{"id":"1.168135752","rc":[{"trd":[[1.55,347.5]],"batb":[[0,1.55,292.55]],"ltp":1.55,"tv":499.73,"id":41364}],"tv":537.94}]}
{"op":"mcm","clk":"1003326920","pt":1580606263344,"mc":[{"id":"1.168135752","rc":[{"batb":[[0,1.55,307.54]],"ltp":1.55,"tv":499.73,"id":41364}]}]}
{"op":"mcm","clk":"1003380228","pt":1580606973158,"mc":[{"id":"1.168135752","rc":[{"batl":[[0,1.58,50.65],[1,1.59,144.16],[2,1.61,500]],"ltp":1.55,"tv":499.73,"id":41364}]}]}
{"op":"mcm","clk":"1003471791","pt":1580608197370,"mc":[{"id":"1.168135752","rc":[{"trd":[[1.55,349.1]],"batb":[[0,1.55,306.74]],"ltp":1.55,"tv":501.33,"id":41364}],"tv":539.54}]}
{"op":"mcm","clk":"1003505455","pt":1580608702613,"mc":[{"id":"1.168135752","rc":[{"batl":[[0,1.59,144.16],[1,1.61,500],[2,1.9,11.14]],"ltp":1.55,"tv":501.33,"id":41364}]}]}
{"op":"mcm","clk":"1003518093","pt":1580608893276,"mc":[{"id":"1.168135752","rc":[{"batb":[[0,1.55,291.75]],"ltp":1.55,"tv":501.33,"id":41364}]}]}
{"op":"mcm","clk":"1003534777","pt":1580609153805,"mc":[{"id":"1.168135752","rc":[{"batb":[[0,2.68,39.98]],"ltp":2.78,"tv":38.2,"id":41365}]}]}
{"op":"mcm","clk":"1003555678","pt":1580609453872,"mc":[{"id":"1.168135752","rc":[{"batb":[[0,2.7,50.14],[1,2.68,39.98],[2,2.34,22]],"ltp":2.78,"tv":38.2,"id":41365}]}]}
{"op":"mcm","clk":"1003574270","pt":1580609710490,"mc":[{"id":"1.168135752","rc":[{"trd":[[1.55,865.31]],"batb":[[0,1.55,33.57]],"ltp":1.55,"tv":1017.53,"id":41364}],"tv":1055.74}]}
{"op":"mcm","clk":"1003581693","pt":1580609820798,"mc":[{"id":"1.168135752","rc":[{"batl":[[1,1.6,15.2],[2,1.61,500]],"ltp":1.55,"tv":1017.53,"id":41364}]}]}
{"op":"mcm","clk":"1003587033","pt":1580609900415,"mc":[{"id":"1.168135752","rc":[{"trd":[[1.55,898.89]],"batb":[[0,1.51,15.14],[1,1.5,4.76],[2,1.44,135.24]],"ltp":1.55,"tv":1051.11,"id":41364},{"trd":[[2.82,18.44]],"batb":[[0,2.7,50.45]],"ltp":2.82,"tv":56.64,"id":41365}],"tv":1107.75}]}
{"op":"mcm","clk":"1003587243","pt":1580609903611,"mc":[{"id":"1.168135752","rc":[{"batb":[[0,2.7,50.14]],"ltp":2.82,"tv":56.64,"id":41365}]}]}
{"op":"mcm","clk":"1003587574","pt":1580609908444,"mc":[{"id":"1.168135752","rc":[{"batl":[[0,1.55,37.86],[1,1.59,144.16],[2,1.6,15.2]],"ltp":1.55,"tv":1051.11,"id":41364}]}]}
{"op":"mcm","clk":"1003588642","pt":1580609922751,"mc":[{"id":"1.168135752","rc":[{"batb":[[0,2.72,50.65],[1,2.7,50.14],[2,2.68,39.98]],"ltp":2.82,"tv":56.64,"id":41365}]}]}
{"op":"mcm","clk":"1003590718","pt":1580609950402,"mc":[{"id":"1.168135752","rc":[{"batb":[[0,1.51,49.18]],"ltp":1.55,"tv":1051.11,"id":41364}]}]}
{"op":"mcm","clk":"1003643305","pt":1580610623213,"mc":[{"id":"1.168135752","rc":[{"trd":[[1.51,75.69]],"batb":[[0,1.51,11.35]],"batl":[[0,1.59,144.16],[1,1.6,15.2],[2,1.61,500]],"ltp":1.51,"tv":1126.8,"id":41364}],"tv":1183.44}]}
{"op":"mcm","clk":"1003655121","pt":1580610780429,"mc":[{"id":"1.168135752","rc":[{"batb":[[0,2.74,8.1],[1,2.72,50.65],[2,2.7,50.14]],"ltp":2.82,"tv":56.64,"id":41365}]}]}
{"op":"mcm","clk":"1003667974","pt":1580610970205,"mc":[{"id":"1.168135752","rc":[{"batb":[[0,1.52,8.54],[1,1.51,11.35],[2,1.5,4.76]],"batl":[[0,1.58,11.27],[1,1.59,144.16],[2,1.6,15.2]],"ltp":1.51,"tv":1126.8,"id":41364},{"batl":[[1,2.98,8.4],[2,3,161]],"ltp":2.82,"tv":56.64,"id":41365}]}]}
{"op":"mcm","clk":"1003705837","pt":1580611571061,"mc":[{"id":"1.168135752","rc":[{"trd":[[1.52,21.28]],"batb":[[0,1.51,11.78],[1,1.5,4.76],[2,1.44,135.24]],"ltp":1.52,"tv":1143.02,"id":41364}],"tv":1199.66}]}
{"op":"mcm","clk":"1003708859","pt":1580611621830,"mc":[{"id":"1.168135752","rc":[{"batb":[[2,1.49,2]],"ltp":1.52,"tv":1143.02,"id":41364}]}]}
{"op":"mcm","clk":"1003709598","pt":1580611633536,"mc":[{"id":"1.168135752","rc":[{"batb":[[2,1.49,2.01]],"ltp":1.52,"tv":1143.02,"id":41364}]}]}
{"op":"mcm","clk":"1003710318","pt":1580611645435,"mc":[{"id":"1.168135752","rc":[{"batb":[[2,2.68,90.13]],"ltp":2.82,"tv":56.64,"id":41365}]}]}
{"op":"mcm","clk":"1003710353","pt":1580611645952,"mc":[{"id":"1.168135752","rc":[{"batb":[[2,1.44,135.25]],"ltp":1.52,"tv":1143.02,"id":41364}]}]}
{"op":"mcm","clk":"1003777869","pt":1580612774757,"mc":[{"id":"1.168135752","rc":[{"trd":[[1.51,160.05],[1.52,22.14]],"batb":[[0,1.5,4.76],[1,1.44,135.25],[2,1.26,96.62]],"batl":[[0,1.58,23.55]],"ltp":1.51,"tv":1228.24,"id":41364},{"trd":[[2.96,31.45]],"batl":[[0,2.96,19.2]],"ltp":2.96,"tv":88.1,"id":41365}],"tv":1316.34}]}
{"op":"mcm","clk":"1003830508","pt":1580614049117,"mc":[{"id":"1.168135752","rc":[{"batb":[[0,2.76,4.05],[1,2.74,8.1],[2,2.72,50.65]],"ltp":2.96,"tv":88.1,"id":41365}]}]}
{"op":"mcm","clk":"1003850519","pt":1580614424538,"mc":[{"id":"1.168135752","rc":[{"batl":[[0,1.56,18.23],[1,1.58,23.55],[2,1.59,144.16]],"ltp":1.51,"tv":1228.24,"id":41364}]}]}
{"op":"mcm","clk":"1003876768","pt":1580614948595,"mc":[{"id":"1.168135752","rc":[{"trd":[[1.51,180.31]],"ltp":1.51,"tv":1248.5,"id":41364},{"trd":[[2.96,41.79]],"batl":[[0,2.96,8.86]],"ltp":2.96,"tv":98.43,"id":41365}],"tv":1346.94}]}
{"op":"mcm","clk":"1003919158","pt":1580616157006,"mc":[{"id":"1.168135752","rc":[{"batl":[[0,1.55,3],[1,1.56,18.23],[2,1.58,23.55]],"ltp":1.51,"tv":1248.5,"id":41364}]}]}
{"op":"mcm","clk":"1003921064","pt":1580616206724,"mc":[{"id":"1.168135752","rc":[{"batl":[[0,1.54,3]],"ltp":1.51,"tv":1248.5,"id":41364}]}]}
{"op":"mcm","clk":"1003921987","pt":1580616238500,"mc":[{"id":"1.168135752","rc":[{"batl":[[0,1.53,3]],"ltp":1.51,"tv":1248.5,"id":41364}]}]}
{"op":"mcm","clk":"1003948508","pt":1580616844260,"mc":[{"id":"1.168135752","rc":[{"batl":[[0,1.52,18.23],[1,1.53,3]],"ltp":1.51,"tv":1248.5,"id":41364}]}]}
{"op":"mcm","clk":"1003948556","pt":1580616845035,"mc":[{"id":"1.168135752","rc":[{"batl":[[2,1.58,11.27]],"ltp":1.51,"tv":1248.5,"id":41364}]}]}
{"op":"mcm","clk":"1003949158","pt":1580616854725,"mc":[{"id":"1.168135752","rc":[{"batl":[[0,1.52,20.26]],"ltp":1.51,"tv":1248.5,"id":41364}]}]}
{"op":"mcm","clk":"1004002622","pt":1580617976179,"mc":[{"id":"1.168135752","rc":[{"batl":[[0,1.53,3],[1,1.58,11.27],[2,1.59,144.16]],"ltp":1.51,"tv":1248.5,"id":41364}]}]}
{"op":"mcm","clk":"1004002715","pt":1580617978081,"mc":[{"id":"1.168135752","rc":[{"batl":[[1,1.58,23.75]],"ltp":1.51,"tv":1248.5,"id":41364}]}]}
{"op":"mcm","clk":"1004007123","pt":1580618065792,"mc":[{"id":"1.168135752","rc":[{"batl":[[1,1.59,144.16],[2,1.6,15.2]],"ltp":1.51,"tv":1248.5,"id":41364},{"batb":[[0,2.76,54.7],[2,2.68,90.13]],"ltp":2.96,"tv":98.43,"id":41365}]}]}
{"op":"mcm","clk":"1004007127","pt":1580618065895,"mc":[{"id":"1.168135752","rc":[{"batl":[[1,1.56,8.33],[2,1.59,144.16]],"ltp":1.51,"tv":1248.5,"id":41364}]}]}
{"op":"mcm","clk":"1004043772","pt":1580618846163,"mc":[{"id":"1.168135752","rc":[{"batb":[[0,2.78,8.1],[1,2.76,54.7]],"ltp":2.96,"tv":98.43,"id":41365}]}]}
{"op":"mcm","clk":"1004043827","pt":1580618847650,"mc":[{"id":"1.168135752","rc":[{"batl":[[1,1.56,16.74]],"ltp":1.51,"tv":1248.5,"id":41364}]}]}
{"op":"mcm","clk":"1004049427","pt":1580618973639,"mc":[{"id":"1.168135752","rc":[{"batl":[[1,1.56,8.41]],"ltp":1.51,"tv":1248.5,"id":41364},{"batb":[[0,2.8,8.1]],"ltp":2.96,"tv":98.43,"id":41365}]}]}
{"op":"mcm","clk":"1004049660","pt":1580618980163,"mc":[{"id":"1.168135752","rc":[{"batb":[[0,2.78,8.1]],"ltp":2.96,"tv":98.43,"id":41365}]}]}
{"op":"mcm","clk":"1004049731","pt":1580618981757,"mc":[{"id":"1.168135752","rc":[{"batl":[[1,1.56,16.96]],"ltp":1.51,"tv":1248.5,"id":41364}]}]}
{"op":"mcm","clk":"1004093746","pt":1580620153909,"mc":[{"id":"1.168135752","rc":[{"trd":[[1.51,197.53]],"ltp":1.51,"tv":1265.72,"id":41364},{"trd":[[2.96,50.57]],"batl":[[0,2.98,8.48],[1,3,161],[2,3,0]],"ltp":2.96,"tv":107.22,"id":41365}],"tv":1372.94}]}
{"op":"mcm","clk":"1004115028","pt":1580620684663,"mc":[{"id":"1.168135752","rc":[{"batb":[[1,1.27,135.25]],"ltp":1.51,"tv":1265.72,"id":41364},{"batb":[[0,2.76,54.7],[1,2.6,50.14],[2,2.34,22]],"ltp":2.96,"tv":107.22,"id":41365}]}]}
{"op":"mcm","clk":"1004115090","pt":1580620685693,"mc":[{"id":"1.168135752","rc":[{"batl":[[1,1.56,8.41]],"ltp":1.51,"tv":1265.72,"id":41364}]}]}
{"op":"mcm","clk":"1004141676","pt":1580621210317,"mc":[{"id":"1.168135752","rc":[{"trd":[[1.5,122.15],[1.51,197.68]],"batb":[[0,1.27,135.25],[1,1.26,96.62],[2,1.01,1.01]],"ltp":1.5,"tv":1356.99,"id":41364},{"trd":[[2.96,50.65],[2.98,8.4],[3,32.5]],"batl":[[0,3,128.5],[1,3,0]],"ltp":3.0,"tv":148.19,"id":41365}],"tv":1505.19}]}
{"op":"mcm","clk":"1004146041","pt":1580621336256,"mc":[{"id":"1.168135752","rc":[{"trd":[[1.5,159.96]],"ltp":1.5,"tv":1394.8,"id":41364},{"trd":[[3,51.4]],"batl":[[0,3,109.6]],"ltp":3.0,"tv":167.09,"id":41365}],"tv":1561.9}]}
{"op":"mcm","clk":"1004197552","pt":1580622831467,"mc":[{"id":"1.168135752","rc":[{"trd":[[1.5,261.26]],"ltp":1.5,"tv":1496.1,"id":41364},{"trd":[[3,102.1]],"batl":[[0,3,58.9]],"ltp":3.0,"tv":217.79,"id":41365}],"tv":1713.9}]}
{"op":"mcm","clk":"1004206511","pt":1580623152055,"mc":[{"id":"1.168135752","rc":[{"batb":[[0,1.5,44.98],[1,1.27,135.25],[2,1.26,96.62]],"ltp":1.5,"tv":1496.1,"id":41364}]}]}
{"op":"mcm","clk":"1004210311","pt":1580623269242,"mc":[{"id":"1.168135752","rc":[{"trd":[[1.5,276.41]],"batb":[[0,1.5,37.4]],"ltp":1.5,"tv":1511.25,"id":41364}],"tv":1729.05}]}
{"op":"mcm","clk":"1004239390","pt":1580624219501,"mc":[{"id":"1.168135752","rc":[{"batb":[[0,2.8,50.65],[1,2.76,54.7],[2,2.6,50.14]],"ltp":3.0,"tv":217.79,"id":41365}]}]}
{"op":"mcm","clk":"1004239407","pt":1580624220712,"mc":[{"id":"1.168135752","rc":[{"batb":[[1,2.78,9.01],[2,2.76,54.7]],"ltp":3.0,"tv":217.79,"id":41365}]}]}
{"op":"mcm","clk":"1004244293","pt":1580624372011,"mc":[{"id":"1.168135752","rc":[{"batb":[[0,1.27,135.25],[1,1.26,96.62],[2,1.01,1.01]],"ltp":1.5,"tv":1511.25,"id":41364}]}]}
{"op":"mcm","clk":"1004256466","pt":1580624751074,"mc":[{"id":"1.168135752","rc":[{"batb":[[0,1.51,102.5],[1,1.27,135.25],[2,1.26,96.62]],"ltp":1.5,"tv":1511.25,"id":41364}]}]}
{"op":"mcm","clk":"1004286151","pt":1580625691145,"mc":[{"id":"1.168135752","rc":[{"batb":[[2,2.76,4.05]],"ltp":3.0,"tv":217.79,"id":41365}]}]}
{"op":"mcm","clk":"1004286206","pt":1580625692119,"mc":[{"id":"1.168135752","rc":[{"batb":[[1,2.76,4.05],[2,2.6,50.14]],"ltp":3.0,"tv":217.79,"id":41365}]}]}
{"op":"mcm","clk":"1004299772","pt":1580626235081,"mc":[{"id":"1.168135752","rc":[{"batb":[[0,2.76,4.05],[1,2.6,50.14],[2,2.34,22]],"ltp":3.0,"tv":217.79,"id":41365}]}]}
{"op":"mcm","clk":"1004299860","pt":1580626237087,"mc":[{"id":"1.168135752","rc":[{"batl":[[1,1.58,8.22]],"ltp":1.5,"tv":1511.25,"id":41364}]}]}
{"op":"mcm","clk":"1004299917","pt":1580626238675,"mc":[{"id":"1.168135752","rc":[{"batb":[[1,2.7,9.28],[2,2.6,50.14]],"ltp":3.0,"tv":217.79,"id":41365}]}]}
{"op":"mcm","clk":"1004300214","pt":1580626248089,"mc":[{"id":"1.168135752","rc":[{"batl":[[0,2.96,50.65],[1,3,58.9]],"ltp":3.0,"tv":217.79,"id":41365}]}]}
{"op":"mcm","clk":"1004302091","pt":1580626311976,"mc":[{"id":"1.168135752","rc":[{"batl":[[1,1.57,289.87],[2,1.58,8.22]],"ltp":1.5,"tv":1511.25,"id":41364}]}]}
{"op":"mcm","clk":"1004302145","pt":1580626313572,"mc":[{"id":"1.168135752","rc":[{"batl":[[1,1.56,8.33],[2,1.57,289.87]],"ltp":1.5,"tv":1511.25,"id":41364},{"batb":[[0,2.76,13.13],[1,2.6,50.14],[2,2.34,22]],"ltp":3.0,"tv":217.79,"id":41365}]}]}
{"op":"mcm","clk":"1004302739","pt":1580626330102,"mc":[{"id":"1.168135752","rc":[{"batl":[[1,1.56,298.19],[2,1.59,144.16]],"ltp":1.5,"tv":1511.25,"id":41364}]}]}
{"op":"mcm","clk":"1004302773","pt":1580626331738,"mc":[{"id":"1.168135752","rc":[{"batb":[[0,2.76,4.05]],"ltp":3.0,"tv":217.79,"id":41365}]}]}
{"op":"mcm","clk":"1004302780","pt":1580626331897,"mc":[{"id":"1.168135752","rc":[{"batb":[[0,2.8,8.94],[1,2.76,4.05],[2,2.6,50.14]],"ltp":3.0,"tv":217.79,"id":41365}]}]}
{"op":"mcm","clk":"1004304123","pt":1580626369092,"mc":[{"id":"1.168135752","rc":[{"trd":[[1.53,5.07]],"batl":[[0,1.56,298.65],[1,1.59,144.16],[2,1.6,15.2]],"ltp":1.53,"tv":1516.32,"id":41364}],"tv":1734.12}]}
{"op":"mcm","clk":"1004323640","pt":1580626958485,"mc":[{"id":"1.168135752","rc":[{"batl":[[0,2.94,39.34],[1,2.96,50.65],[2,3,58.9]],"ltp":3.0,"tv":217.79,"id":41365}]}]}
{"op":"mcm","clk":"1004324326","pt":1580626985460,"mc":[{"id":"1.168135752","rc":[{"batl":[[0,2.94,89.99],[1,3,58.9],[2,3,0]],"ltp":3.0,"tv":217.79,"id":41365}]}]}
{"op":"mcm","clk":"1004333753","pt":1580627269637,"mc":[{"id":"1.168135752","rc":[{"batl":[[0,1.53,11.7],[1,1.56,298.19],[2,1.59,144.16]],"ltp":1.53,"tv":1516.32,"id":41364}]}]}
{"op":"mcm","clk":"1004334023","pt":1580627276798,"mc":[{"id":"1.168135752","rc":[{"trd":[[1.51,217.68]],"batb":[[0,1.51,92.51]],"ltp":1.51,"tv":1536.32,"id":41364}],"tv":1754.12}]}
{"op":"mcm","clk":"1004343114","pt":1580627522304,"mc":[{"id":"1.168135752","rc":[{"trd":[[1.53,16.53]],"batl":[[0,1.56,298.44],[1,1.59,144.16],[2,1.6,15.2]],"ltp":1.53,"tv":1547.77,"id":41364},{"trd":[[2.88,6.08]],"ltp":2.88,"tv":223.87,"id":41365}],"tv":1771.65}]}
{"op":"mcm","clk":"1004355327","pt":1580627845034,"mc":[{"id":"1.168135752","rc":[{"batl":[[0,1.53,10.33],[1,1.56,298.19],[2,1.59,144.16]],"ltp":1.53,"tv":1547.77,"id":41364}]}]}
{"op":"mcm","clk":"1004369564","pt":1580628159670,"mc":[{"id":"1.168135752","rc":[{"batl":[[0,1.54,10.33]],"ltp":1.53,"tv":1547.77,"id":41364}]}]}
{"op":"mcm","clk":"1004371414","pt":1580628202734,"mc":[{"id":"1.168135752","rc":[{"batl":[[0,2.92,50.65],[1,2.94,39.34],[2,3,58.9]],"ltp":2.88,"tv":223.87,"id":41365}]}]}
{"op":"mcm","clk":"1004373034","pt":1580628246170,"mc":[{"id":"1.168135752","rc":[{"batb":[[1,1.26,96.63],[2,1.01,1.01]],"ltp":1.53,"tv":1547.77,"id":41364},{"batb":[[2,2.34,22]],"ltp":2.88,"tv":223.87,"id":41365}]}]}
{"op":"mcm","clk":"1004377549","pt":1580628373072,"mc":[{"id":"1.168135752","rc":[{"trd":[[1.52,112.25]],"ltp":1.52,"tv":1637.88,"id":41364},{"trd":[[2.92,46.86]],"batl":[[0,2.92,3.79]],"ltp":2.92,"tv":270.73,"id":41365}],"tv":1908.62}]}
{"op":"mcm","clk":"1004383488","pt":1580628519055,"mc":[{"id":"1.168135752","rc":[{"batl":[[0,2.92,29.12]],"ltp":2.92,"tv":270.73,"id":41365}]}]}
{"op":"mcm","clk":"1004388876","pt":1580628655723,"mc":[{"id":"1.168135752","rc":[{"batb":[[0,1.52,92.51]],"ltp":1.52,"tv":1637.88,"id":41364}]}]}
{"op":"mcm","clk":"1004389532","pt":1580628671005,"mc":[{"id":"1.168135752","rc":[{"batl":[[0,2.92,25.33]],"ltp":2.92,"tv":270.73,"id":41365}]}]}
{"op":"mcm","clk":"1004396403","pt":1580628835721,"mc":[{"id":"1.168135752","rc":[{"trd":[[1.52,150.11]],"batb":[[0,1.52,73.58]],"ltp":1.52,"tv":1675.75,"id":41364}],"tv":1946.48}]}
{"op":"mcm","clk":"1004400468","pt":1580628951808,"mc":[{"id":"1.168135752","rc":[{"batl":[[0,1.54,28.82]],"ltp":1.52,"tv":1675.75,"id":41364}]}]}
{"op":"mcm","clk":"1004400850","pt":1580628962721,"mc":[{"id":"1.168135752","rc":[{"trd":[[1.53,16.78],[1.54,18.46]],"batl":[[0,1.54,10.11]],"ltp":1.54,"tv":1694.45,"id":41364},{"trd":[[2.84,10],[2.88,6.21]],"ltp":2.84,"tv":280.86,"id":41365}],"tv":1975.32}]}
{"op":"mcm","clk":"1004402236","pt":1580628999285,"mc":[{"id":"1.168135752","rc":[{"trd":[[1.52,172.83]],"batb":[[0,1.52,62.22]],"ltp":1.52,"tv":1717.17,"id":41364}],"tv":1998.04}]}
{"op":"mcm","clk":"1004402338","pt":1580629001763,"mc":[{"id":"1.168135752","rc":[{"batb":[[0,1.53,15.2],[1,1.52,62.22],[2,1.26,96.63]],"ltp":1.52,"tv":1717.17,"id":41364}]}]}
{"op":"mcm","clk":"1004403933","pt":1580629043934,"mc":[{"id":"1.168135752","rc":[{"batl":[[0,1.54,21.87]],"ltp":1.52,"tv":1717.17,"id":41364}]}]}
{"op":"mcm","clk":"1004409863","pt":1580629185854,"mc":[{"id":"1.168135752","rc":[{"trd":[[1.53,21.84]],"batb":[[0,1.53,12.66]],"ltp":1.53,"tv":1722.24,"id":41364}],"tv":2003.1}]}
{"op":"mcm","clk":"1004413079","pt":1580629272754,"mc":[{"id":"1.168135752","rc":[{"trd":[[1.53,47.17]],"batb":[[0,1.52,62.22],[1,1.26,96.63],[2,1.01,1.01]],"batl":[[0,1.53,12.66],[1,1.54,21.87],[2,1.56,298.19]],"ltp":1.53,"tv":1747.56,"id":41364}],"tv":2028.43}]}
{"op":"mcm","clk":"1004415823","pt":1580629327816,"mc":[{"id":"1.168135752","rc":[{"trd":[[1.52,198.17]],"batb":[[0,1.52,49.54]],"batl":[[0,1.54,21.87],[1,1.56,298.19],[2,1.59,144.16]],"ltp":1.52,"tv":1772.9,"id":41364}],"tv":2053.77}]}
{"op":"mcm","clk":"1004419630","pt":1580629424427,"mc":[{"id":"1.168135752","rc":[{"batl":[[0,1.54,25.23]],"ltp":1.52,"tv":1772.9,"id":41364}]}]}
{"op":"mcm","clk":"1004433236","pt":1580629738471,"mc":[{"id":"1.168135752","rc":[{"trd":[[1.54,43.69],[1.56,362.67]],"batl":[[0,1.59,144.16],[1,1.6,15.2],[2,1.61,500]],"ltp":1.56,"tv":2096.33,"id":41364},{"trd":[[2.78,175.6],[2.8,17.87],[2.84,23.66]],"batb":[[0,2.76,4.05],[1,2.34,22],[2,1.01,1.02]],"batl":[[0,2.78,147.58],[1,2.92,25.33],[2,2.94,39.34]],"ltp":2.78,"tv":479.56,"id":41365}],"tv":2575.89}]}
{"op":"mcm","clk":"1004433462","pt":1580629742583,"mc":[{"id":"1.168135752","rc":[{"batl":[[0,2.92,25.33],[1,2.94,39.34],[2,3,58.9]],"ltp":2.78,"tv":479.56,"id":41365}]}]}
{"op":"mcm","clk":"1004434932","pt":1580629773319,"mc":[{"id":"1.168135752","rc":[{"trd":[[1.59,195.82]],"batl":[[0,1.6,15.2],[1,1.61,500],[2,1.9,11.14]],"ltp":1.59,"tv":2240.49,"id":41364},{"trd":[[2.68,85.44],[2.76,16.54]],"batb":[[0,2.34,22],[1,1.01,1.02],[2,1.01,0]],"batl":[[0,2.68,22.95],[1,2.92,25.33],[2,2.94,39.34]],"ltp":2.68,"tv":573.1,"id":41365}],"tv":2813.6}]}
{"op":"mcm","clk":"1004435162","pt":1580629778620,"mc":[{"id":"1.168135752","rc":[{"batl":[[0,2.92,25.33],[1,2.94,39.34],[2,3,58.9]],"ltp":2.68,"tv":573.1,"id":41365}]}]}
{"op":"mcm","clk":"1004435248","pt":1580629780220,"mc":[{"id":"1.168135752","rc":[{"batb":[[0,1.53,2],[1,1.52,49.54],[2,1.26,96.63]],"ltp":1.59,"tv":2240.49,"id":41364},{"batb":[[0,2.68,2],[1,2.34,22],[2,1.01,1.02]],"ltp":2.68,"tv":573.1,"id":41365}]}]}
{"op":"mcm","clk":"1004437752","pt":1580629833793,"mc":[{"id":"1.168135752","rc":[{"batl":[[0,1.56,181.48],[1,1.6,15.2],[2,1.61,500]],"ltp":1.59,"tv":2240.49,"id":41364}]}]}
{"op":"mcm","clk":"1004445517","pt":1580630019397,"mc":[{"id":"1.168135752","rc":[{"batl":[[1,3,58.9],[2,3,0]],"ltp":2.68,"tv":573.1,"id":41365}]}]}
{"op":"mcm","clk":"1004447473","pt":1580630064939,"mc":[{"id":"1.168135752","rc":[{"batl":[[0,2.82,39.34],[1,2.92,25.33],[2,3,58.9]],"ltp":2.68,"tv":573.1,"id":41365}]}]}
{"op":"mcm","clk":"1004448396","pt":1580630088676,"mc":[{"id":"1.168135752","rc":[{"trd":[[1.54,115.73]],"batl":[[0,1.54,52.96],[1,1.56,181.48],[2,1.6,15.2]],"ltp":1.54,"tv":2312.53,"id":41364},{"trd":[[2.82,57.78]],"batl":[[0,2.92,25.33],[1,3,58.9],[2,3,0]],"ltp":2.82,"tv":612.45,"id":41365}],"tv":2924.98}]}
{"op":"mcm","clk":"1004449476","pt":1580630112354,"mc":[{"id":"1.168135752","rc":[{"trd":[[1.54,168.69]],"batl":[[0,1.56,181.48],[1,1.6,15.2],[2,1.61,500]],"ltp":1.54,"tv":2365.49,"id":41364},{"trd":[[2.84,52.38]],"ltp":2.84,"tv":641.16,"id":41365}],"tv":3006.66}]}
{"op":"mcm","clk":"1004452232","pt":1580630170809,"mc":[{"id":"1.168135752","rc":[{"batb":[[0,1.53,5.5]],"ltp":1.54,"tv":2365.49,"id":41364}]}]}
{"op":"mcm","clk":"1004453492","pt":1580630193237,"mc":[{"id":"1.168135752","rc":[{"batb":[[0,1.54,3.5],[1,1.53,2],[2,1.52,49.54]],"ltp":1.54,"tv":2365.49,"id":41364}]}]}
{"op":"mcm","clk":"1004457573","pt":1580630275682,"mc":[{"id":"1.168135752","rc":[{"batl":[[0,2.9,25.33]],"ltp":2.84,"tv":641.16,"id":41365}]}]}
{"op":"mcm","clk":"1004462208","pt":1580630379414,"mc":[{"id":"1.168135752","rc":[{"batb":[[1,1.52,49.54],[2,1.26,96.63]],"ltp":1.54,"tv":2365.49,"id":41364}]}]}
{"op":"mcm","clk":"1004462283","pt":1580630380701,"mc":[{"id":"1.168135752","rc":[{"batb":[[0,2.34,22],[1,1.01,1.02],[2,1.01,0]],"ltp":2.84,"tv":641.16,"id":41365}]}]}
{"op":"mcm","clk":"1004463705","pt":1580630406070,"mc":[{"id":"1.168135752","rc":[{"batb":[[0,1.55,3.5]],"ltp":1.54,"tv":2365.49,"id":41364}]}]}
{"op":"mcm","clk":"1004465349","pt":1580630433805,"mc":[{"id":"1.168135752","rc":[{"trd":[[1.55,905.88]],"batb":[[0,1.52,49.54],[1,1.26,96.63],[2,1.01,1.01]],"batl":[[0,1.56,181.53]],"ltp":1.55,"tv":2372.48,"id":41364}],"tv":3013.65}]}
{"op":"mcm","clk":"1004465487","pt":1580630436593,"mc":[{"id":"1.168135752","rc":[{"batl":[[0,1.56,181.48]],"ltp":1.55,"tv":2372.48,"id":41364}]}]}
{"op":"mcm","clk":"1004466006","pt":1580630447714,"mc":[{"id":"1.168135752","rc":[{"batb":[[0,1.53,3.55],[1,1.52,49.54],[2,1.26,96.63]],"ltp":1.55,"tv":2372.48,"id":41364}]}]}
{"op":"mcm","clk":"1004467254","pt":1580630474743,"mc":[{"id":"1.168135752","rc":[{"trd":[[1.53,54.26]],"batb":[[0,1.52,49.54],[1,1.26,96.63],[2,1.01,1.01]],"batl":[[0,1.53,21.45],[1,1.56,181.48],[2,1.6,15.2]],"ltp":1.53,"tv":2379.58,"id":41364}],"tv":3020.75}]}
{"op":"mcm","clk":"1004467466","pt":1580630480389,"mc":[{"id":"1.168135752","rc":[{"trd":[[1.52,241.07]],"batb":[[0,1.52,28.09]],"batl":[[0,1.56,181.48],[1,1.6,15.2],[2,1.61,500]],"ltp":1.52,"tv":2422.48,"id":41364}],"tv":3063.65}]}
{"op":"mcm","clk":"1004467514","pt":1580630481673,"mc":[{"id":"1.168135752","rc":[{"batb":[[0,1.53,27.73],[1,1.52,28.09],[2,1.26,96.63]],"ltp":1.52,"tv":2422.48,"id":41364}]}]}
{"op":"mcm","clk":"1004471790","pt":1580630570076,"mc":[{"id":"1.168135752","rc":[{"trd":[[1.56,462.01]],"batl":[[0,1.56,131.81]],"ltp":1.56,"tv":2521.82,"id":41364}],"tv":3162.99}]}
{"op":"mcm","clk":"1004472773","pt":1580630594324,"mc":[{"id":"1.168135752","rc":[{"batl":[[0,1.56,143.57]],"ltp":1.56,"tv":2521.82,"id":41364}]}]}
{"op":"mcm","clk":"1004473600","pt":1580630615657,"mc":[{"id":"1.168135752","rc":[{"trd":[[1.53,62.04]],"batb":[[0,1.53,23.84]],"ltp":1.53,"tv":2529.6,"id":41364}],"tv":3170.77}]}
{"op":"mcm","clk":"1004477367","pt":1580630694708,"mc":[{"id":"1.168135752","rc":[{"batb":[[0,1.54,166.67],[1,1.53,23.84],[2,1.52,28.09]],"ltp":1.53,"tv":2529.6,"id":41364},{"batb":[[1,2.18,76.27],[2,1.01,1.02]],"ltp":2.84,"tv":641.16,"id":41365}]}]}
{"op":"mcm","clk":"1004487103","pt":1580630930004,"mc":[{"id":"1.168135752","rc":[{"trd":[[1.54,173.75]],"batb":[[0,1.54,164.14]],"ltp":1.54,"tv":2534.66,"id":41364}],"tv":3175.83}]}
{"op":"mcm","clk":"1004494677","pt":1580631088475,"mc":[{"id":"1.168135752","rc":[{"trd":[[1.54,177.11]],"batb":[[0,1.54,162.46]],"ltp":1.54,"tv":2538.03,"id":41364}],"tv":3179.19}]}
{"op":"mcm","clk":"1004500226","pt":1580631215705,"mc":[{"id":"1.168135752","rc":[{"trd":[[1.54,265.11]],"batb":[[0,1.54,118.46]],"ltp":1.54,"tv":2626.03,"id":41364}],"tv":3267.19}]}
{"op":"mcm","clk":"1004501523","pt":1580631247566,"mc":[{"id":"1.168135752","rc":[{"trd":[[1.54,465.11]],"batb":[[0,1.54,18.46]],"ltp":1.54,"tv":2826.03,"id":41364}],"tv":3467.19}]}
{"op":"mcm","clk":"1004501582","pt":1580631249779,"mc":[{"id":"1.168135752","rc":[{"batl":[[0,2.86,25.33]],"ltp":2.84,"tv":641.16,"id":41365}]}]}
{"op":"mcm","clk":"1004510998","pt":1580631474060,"mc":[{"id":"1.168135752","rc":[{"trd":[[1.56,749.1]],"batl":[[0,1.6,15.23],[1,1.61,500],[2,1.9,11.14]],"ltp":1.56,"tv":3113.11,"id":41364}],"tv":3754.28}]}
{"op":"mcm","clk":"1004511986","pt":1580631499190,"mc":[{"id":"1.168135752","rc":[{"batb":[[0,1.55,2],[1,1.54,18.46],[2,1.53,23.84]],"ltp":1.56,"tv":3113.11,"id":41364},{"batb":[[0,2.68,2],[1,2.34,22],[2,2.18,76.27]],"ltp":2.84,"tv":641.16,"id":41365}]}]}
{"op":"mcm","clk":"1004513592","pt":1580631537142,"mc":[{"id":"1.168135752","rc":[{"batb":[[1,2.64,19.75],[2,2.34,22]],"ltp":2.84,"tv":641.16,"id":41365}]}]}
{"op":"mcm","clk":"1004515076","pt":1580631569706,"mc":[{"id":"1.168135752","rc":[{"batb":[[1,2.66,50.65],[2,2.64,19.75]],"ltp":2.84,"tv":641.16,"id":41365}]}]}
{"op":"mcm","clk":"1004515744","pt":1580631583598,"mc":[{"id":"1.168135752","rc":[{"batl":[[0,1.56,13.39],[1,1.6,15.2],[2,1.61,500]],"ltp":1.56,"tv":3113.11,"id":41364},{"batb":[[0,2.68,21.75],[2,2.34,22]],"ltp":2.84,"tv":641.16,"id":41365}]}]}
{"op":"mcm","clk":"1004518281","pt":1580631638088,"mc":[{"id":"1.168135752","rc":[{"trd":[[1.56,775.78]],"batl":[[0,1.6,15.25],[1,1.61,500],[2,1.9,11.14]],"ltp":1.56,"tv":3139.8,"id":41364}],"tv":3780.96}]}
{"op":"mcm","clk":"1004518492","pt":1580631642482,"mc":[{"id":"1.168135752","rc":[{"trd":[[1.55,905.94]],"batb":[[0,1.55,1.97],[2,1.26,96.63]],"batl":[[0,1.6,15.2]],"ltp":1.55,"tv":3139.85,"id":41364}],"tv":3781.02}]}
{"op":"mcm","clk":"1004521455","pt":1580631706459,"mc":[{"id":"1.168135752","rc":[{"trd":[[1.54,471.31],[1.55,909.88]],"batb":[[0,1.54,15.36],[1,1.26,96.63],[2,1.01,1.01]],"ltp":1.54,"tv":3149.99,"id":41364}],"tv":3791.15}]}
{"op":"mcm","clk":"1004522295","pt":1580631724682,"mc":[{"id":"1.168135752","rc":[{"batb":[[0,1.54,115.36]],"ltp":1.54,"tv":3149.99,"id":41364}]}]}
{"op":"mcm","clk":"1004522472","pt":1580631728669,"mc":[{"id":"1.168135752","rc":[{"trd":[[1.54,488.11]],"batb":[[0,1.54,106.96]],"ltp":1.54,"tv":3166.79,"id":41364}],"tv":3807.96}]}
{"op":"mcm","clk":"1004525435","pt":1580631806661,"mc":[{"id":"1.168135752","rc":[{"trd":[[1.54,498.25]],"batb":[[0,1.54,101.89]],"ltp":1.54,"tv":3176.92,"id":41364}],"tv":3818.09}]}
{"op":"mcm","clk":"1004525651","pt":1580631811734,"mc":[{"id":"1.168135752","rc":[{"trd":[[1.54,698.25]],"batb":[[0,1.54,1.89]],"ltp":1.54,"tv":3376.92,"id":41364}],"tv":4018.09}]}
{"op":"mcm","clk":"1004526176","pt":1580631824568,"mc":[{"id":"1.168135752","rc":[{"batb":[[0,2.68,72.4],[1,2.34,22],[2,2.18,76.27]],"ltp":2.84,"tv":641.16,"id":41365}]}]}
{"op":"mcm","clk":"1004526888","pt":1580631840199,"mc":[{"id":"1.168135752","rc":[{"trd":[[1.53,109.38],[1.54,702.02]],"batb":[[0,1.26,96.63],[1,1.01,1.01],[2,1.01,0]],"batl":[[0,1.53,52.07],[1,1.6,15.2],[2,1.61,500]],"ltp":1.53,"tv":3428.04,"id":41364},{"trd":[[2.86,25.33]],"batl":[[0,3,58.9],[1,3,0]],"ltp":2.86,"tv":666.49,"id":41365}],"tv":4094.53}]}
{"op":"mcm","clk":"1004527293","pt":1580631848589,"mc":[{"id":"1.168135752","rc":[{"trd":[[1.53,213.58]],"batb":[[0,1.53,693.97],[1,1.26,96.63],[2,1.01,1.01]],"batl":[[0,1.6,15.2],[1,1.61,500],[2,1.9,11.14]],"ltp":1.53,"tv":3532.24,"id":41364}],"tv":4198.73}]}
{"op":"mcm","clk":"1004527857","pt":1580631860317,"mc":[{"id":"1.168135752","rc":[{"batb":[[0,1.52,693.97]],"ltp":1.53,"tv":3532.24,"id":41364}]}]}
{"op":"mcm","clk":"1004528535","pt":1580631873811,"mc":[{"id":"1.168135752","rc":[{"batb":[[0,1.53,1.65],[1,1.52,693.97],[2,1.26,96.63]],"ltp":1.53,"tv":3532.24,"id":41364}]}]}
{"op":"mcm","clk":"1004529133","pt":1580631885743,"mc":[{"id":"1.168135752","rc":[{"trd":[[1.53,216.94]],"batb":[[0,1.53,86.97]],"ltp":1.53,"tv":3535.6,"id":41364}],"tv":4202.09}]}
{"op":"mcm","clk":"1004531894","pt":1580631938784,"mc":[{"id":"1.168135752","rc":[{"batb":[[0,2.7,56],[1,2.68,72.4],[2,2.34,22]],"ltp":2.86,"tv":666.49,"id":41365}]}]}
{"op":"mcm","clk":"1004532767","pt":1580631957694,"mc":[{"id":"1.168135752","rc":[{"trd":[[1.53,222.94]],"batb":[[0,1.53,83.97]],"ltp":1.53,"tv":3541.6,"id":41364}],"tv":4208.09}]}
{"op":"mcm","clk":"1004533309","pt":1580631967529,"mc":[{"id":"1.168135752","rc":[{"batb":[[0,2.72,56]],"ltp":2.86,"tv":666.49,"id":41365}]}]}
{"op":"mcm","clk":"1004536450","pt":1580632028791,"mc":[{"id":"1.168135752","rc":[{"trd":[[1.53,272.94]],"batb":[[0,1.53,58.97]],"ltp":1.53,"tv":3591.6,"id":41364}],"tv":4258.09}]}
{"op":"mcm","clk":"1004536769","pt":1580632038519,"mc":[{"id":"1.168135752","rc":[{"trd":[[1.53,280.94]],"batb":[[0,1.53,54.97]],"ltp":1.53,"tv":3599.6,"id":41364}],"tv":4266.09}]}
{"op":"mcm","clk":"1004537172","pt":1580632048431,"mc":[{"id":"1.168135752","rc":[{"batb":[[0,2.74,56]],"ltp":2.86,"tv":666.49,"id":41365}]}]}
{"op":"mcm","clk":"1004537592","pt":1580632060241,"mc":[{"id":"1.168135752","rc":[{"trd":[[2.74,50]],"batb":[[0,2.74,31]],"ltp":2.74,"tv":716.49,"id":41365}],"tv":4316.09}]}
{"op":"mcm","clk":"1004538714","pt":1580632090567,"mc":[{"id":"1.168135752","rc":[{"batb":[[0,2.74,46]],"ltp":2.74,"tv":716.49,"id":41365}]}]}
{"op":"mcm","clk":"1004539052","pt":1580632098795,"mc":[{"id":"1.168135752","rc":[{"batb":[[1,2.68,70.4]],"ltp":2.74,"tv":716.49,"id":41365}]}]}
{"op":"mcm","clk":"1004539731","pt":1580632114686,"mc":[{"id":"1.168135752","rc":[{"batb":[[0,2.7,46]],"ltp":2.74,"tv":716.49,"id":41365}]}]}
{"op":"mcm","clk":"1004539932","pt":1580632119997,"mc":[{"id":"1.168135752","rc":[{"trd":[[1.53,302.02]],"batb":[[0,1.53,44.43]],"ltp":1.53,"tv":3620.68,"id":41364}],"tv":4337.18}]}
{"op":"mcm","clk":"1004540543","pt":1580632137738,"mc":[{"id":"1.168135752","rc":[{"batb":[[0,2.72,46],[1,2.7,50.65],[2,2.68,19.75]],"ltp":2.74,"tv":716.49,"id":41365}]}]}
{"op":"mcm","clk":"1004540573","pt":1580632138311,"mc":[{"id":"1.168135752","rc":[{"trd":[[2.7,101.3],[2.72,91.95]],"batb":[[0,2.68,19.75],[1,2.34,22],[2,2.18,76.27]],"batl":[[0,2.7,106],[1,3,58.9]],"ltp":2.7,"tv":909.74,"id":41365}],"tv":4530.43}]}
{"op":"mcm","clk":"1004541030","pt":1580632150565,"mc":[{"id":"1.168135752","rc":[{"batl":[[0,3,58.9],[1,3,0]],"ltp":2.7,"tv":909.74,"id":41365}]}]}
{"op":"mcm","clk":"1004541427","pt":1580632160773,"mc":[{"id":"1.168135752","rc":[{"batb":[[0,1.54,2],[1,1.53,44.43],[2,1.52,693.97]],"ltp":1.53,"tv":3620.68,"id":41364},{"batb":[[0,2.7,2],[1,2.68,19.75],[2,2.34,22]],"ltp":2.7,"tv":909.74,"id":41365}]}]}
{"op":"mcm","clk":"1004541556","pt":1580632163770,"mc":[{"id":"1.168135752","rc":[{"trd":[[2.68,120.96],[2.7,105.3]],"batb":[[0,2.68,2],[1,2.34,22],[2,2.18,76.27]],"ltp":2.68,"tv":949.25,"id":41365}],"tv":4569.94}]}
{"op":"mcm","clk":"1004541682","pt":1580632167775,"mc":[{"id":"1.168135752","rc":[{"batb":[[0,2.68,8]],"ltp":2.68,"tv":949.25,"id":41365}]}]}
{"op":"mcm","clk":"1004542168","pt":1580632183670,"mc":[{"id":"1.168135752","rc":[{"batb":[[0,1.54,46.43],[1,1.52,693.97],[2,1.26,96.63]],"ltp":1.53,"tv":3620.68,"id":41364}]}]}
{"op":"mcm","clk":"1004543276","pt":1580632207716,"mc":[{"id":"1.168135752","rc":[{"batl":[[0,2.84,50.65],[1,3,58.9]],"ltp":2.68,"tv":949.25,"id":41365}]}]}
{"op":"mcm","clk":"1004543827","pt":1580632219764,"mc":[{"id":"1.168135752","rc":[{"batb":[[0,1.54,44.43]],"ltp":1.53,"tv":3620.68,"id":41364}]}]}
{"op":"mcm","clk":"1004543903","pt":1580632221620,"mc":[{"id":"1.168135752","rc":[{"trd":[[2.68,136.94]],"batb":[[0,2.34,22],[1,2.18,76.27],[2,1.01,1.02]],"batl":[[0,2.68,42.66],[1,2.84,50.65],[2,3,58.9]],"ltp":2.68,"tv":965.24,"id":41365}],"tv":4585.92}]}
{"op":"mcm","clk":"1004544126","pt":1580632226731,"mc":[{"id":"1.168135752","rc":[{"trd":[[1.54,760.84],[1.59,267.73]],"batb":[[0,1.54,15.01]],"ltp":1.54,"tv":3751.4,"id":41364},{"trd":[[2.68,179.61]],"batl":[[0,2.84,50.65],[1,3,58.9],[2,3,0]],"ltp":2.68,"tv":1007.9,"id":41365}],"tv":4759.31}]}
{"op":"mcm","clk":"1004544210","pt":1580632228633,"mc":[{"id":"1.168135752","rc":[{"batb":[[0,1.55,2],[1,1.54,15.01],[2,1.52,693.97]],"ltp":1.54,"tv":3751.4,"id":41364},{"batb":[[0,2.68,2],[1,2.34,22],[2,2.18,76.27]],"ltp":2.68,"tv":1007.9,"id":41365}]}]}
{"op":"mcm","clk":"1004544897","pt":1580632244777,"mc":[{"id":"1.168135752","rc":[{"batb":[[0,2.7,17],[1,2.68,2],[2,2.34,22]],"ltp":2.68,"tv":1007.9,"id":41365}]}]}
{"op":"mcm","clk":"1004545231","pt":1580632251782,"mc":[{"id":"1.168135752","rc":[{"batl":[[0,1.61,500],[1,1.9,11.14],[2,2.3,25.21]],"ltp":1.54,"tv":3751.4,"id":41364}]}]}
{"op":"mcm","clk":"1004545279","pt":1580632252812,"mc":[{"id":"1.168135752","rc":[{"batl":[[0,1.59,15.2],[1,1.61,500],[2,1.9,11.14]],"ltp":1.54,"tv":3751.4,"id":41364}]}]}
{"op":"mcm","clk":"1004545442","pt":1580632256791,"mc":[{"id":"1.168135752","rc":[{"batl":[[0,1.59,25.33]],"ltp":1.54,"tv":3751.4,"id":41364}]}]}
{"op":"mcm","clk":"1004545679","pt":1580632261488,"mc":[{"id":"1.168135752","rc":[{"batl":[[0,1.58,10.13],[1,1.59,15.2],[2,1.61,500]],"ltp":1.54,"tv":3751.4,"id":41364}]}]}
{"op":"mcm","clk":"1004546610","pt":1580632279642,"mc":[{"id":"1.168135752","rc":[{"batb":[[0,1.55,36.7]],"ltp":1.54,"tv":3751.4,"id":41364}]}]}
{"op":"mcm","clk":"1004547007","pt":1580632287731,"mc":[{"id":"1.168135752","rc":[{"batb":[[0,1.55,34.7]],"ltp":1.54,"tv":3751.4,"id":41364},{"batb":[[1,2.34,22],[2,2.18,76.27]],"ltp":2.68,"tv":1007.9,"id":41365}]}]}
{"op":"mcm","clk":"1004547853","pt":1580632307062,"mc":[{"id":"1.168135752","rc":[{"batb":[[0,2.72,17]],"ltp":2.68,"tv":1007.9,"id":41365}]}]}
{"op":"mcm","clk":"1004548298","pt":1580632316573,"mc":[{"id":"1.168135752","rc":[{"batl":[[0,1.56,15.2],[1,1.58,10.13]],"ltp":1.54,"tv":3751.4,"id":41364}]}]}
{"op":"mcm","clk":"1004549149","pt":1580632334797,"mc":[{"id":"1.168135752","rc":[{"batl":[[0,2.82,50.65]],"ltp":2.68,"tv":1007.9,"id":41365}]}]}
{"op":"mcm","clk":"1004549316","pt":1580632337786,"mc":[{"id":"1.168135752","rc":[{"trd":[[1.56,790.98]],"batl":[[0,1.58,10.13],[1,1.61,500],[2,1.9,11.14]],"ltp":1.56,"tv":3766.6,"id":41364},{"trd":[[2.78,184.14]],"batl":[[0,2.82,51.11]],"ltp":2.78,"tv":1016.44,"id":41365}],"tv":4783.04}]}
{"op":"mcm","clk":"1004549436","pt":1580632340819,"mc":[{"id":"1.168135752","rc":[{"batl":[[0,2.82,50.65]],"ltp":2.78,"tv":1016.44,"id":41365}]}]}
{"op":"mcm","clk":"1004549864","pt":1580632349599,"mc":[{"id":"1.168135752","rc":[{"batb":[[0,1.55,49.71],[1,1.52,693.97],[2,1.26,96.63]],"ltp":1.56,"tv":3766.6,"id":41364}]}]}
{"op":"mcm","clk":"1004550481","pt":1580632362630,"mc":[{"id":"1.168135752","rc":[{"batb":[[0,2.72,24]],"ltp":2.78,"tv":1016.44,"id":41365}]}]}
{"op":"mcm","clk":"1004551757","pt":1580632389770,"mc":[{"id":"1.168135752","rc":[{"trd":[[1.55,985.84]],"batb":[[0,1.55,11.74]],"ltp":1.55,"tv":3842.56,"id":41364}],"tv":4859.01}]}
{"op":"mcm","clk":"1004551813","pt":1580632390749,"mc":[{"id":"1.168135752","rc":[{"batb":[[0,2.74,24]],"ltp":2.78,"tv":1016.44,"id":41365}]}]}
{"op":"mcm","clk":"1004552663","pt":1580632407568,"mc":[{"id":"1.168135752","rc":[{"batb":[[1,2.64,15.2],[2,2.34,22]],"ltp":2.78,"tv":1016.44,"id":41365}]}]}
{"op":"mcm","clk":"1004553702","pt":1580632431626,"mc":[{"id":"1.168135752","rc":[{"batl":[[0,1.57,10.13]],"ltp":1.55,"tv":3842.56,"id":41364}]}]}
{"op":"mcm","clk":"1004554567","pt":1580632455448,"mc":[{"id":"1.168135752","rc":[{"batb":[[1,2.7,186.52],[2,2.64,15.2]],"ltp":2.78,"tv":1016.44,"id":41365}]}]}
{"op":"mcm","clk":"1004555053","pt":1580632468449,"mc":[{"id":"1.168135752","rc":[{"batl":[[0,1.56,10.13]],"ltp":1.55,"tv":3842.56,"id":41364}]}]}
{"op":"mcm","clk":"1004555572","pt":1580632479495,"mc":[{"id":"1.168135752","rc":[{"batb":[[1,2.66,186.52]],"ltp":2.78,"tv":1016.44,"id":41365}]}]}
{"op":"mcm","clk":"1004556700","pt":1580632506703,"mc":[{"id":"1.168135752","rc":[{"trd":[[1.55,1009.31]],"batb":[[0,1.52,693.97],[1,1.26,96.63],[2,1.01,1.01]],"batl":[[0,1.55,38.93],[1,1.56,10.13],[2,1.61,500]],"ltp":1.55,"tv":3866.03,"id":41364}],"tv":4882.48}]}
{"op":"mcm","clk":"1004557056","pt":1580632515810,"mc":[{"id":"1.168135752","rc":[{"batl":[[0,1.56,10.13],[1,1.61,500],[2,1.9,11.14]],"ltp":1.55,"tv":3866.03,"id":41364}]}]}
{"op":"mcm","clk":"1004557092","pt":1580632516735,"mc":[{"id":"1.168135752","rc":[{"trd":[[1.54,799.76]],"ltp":1.54,"tv":3904.96,"id":41364},{"trd":[[2.82,79.04]],"batl":[[0,2.82,29.39]],"ltp":2.82,"tv":1037.7,"id":41365}],"tv":4942.66}]}
{"op":"mcm","clk":"1004558154","pt":1580632541282,"mc":[{"id":"1.168135752","rc":[{"batl":[[0,1.56,22.79]],"ltp":1.54,"tv":3904.96,"id":41364}]}]}
{"op":"mcm","clk":"1004559723","pt":1580632578982,"mc":[{"id":"1.168135752","rc":[{"batl":[[0,1.56,43.05]],"ltp":1.54,"tv":3904.96,"id":41364}]}]}
{"op":"mcm","clk":"1004559973","pt":1580632584784,"mc":[{"id":"1.168135752","rc":[{"batl":[[0,1.55,20.26],[1,1.56,22.79],[2,1.61,500]],"ltp":1.54,"tv":3904.96,"id":41364}]}]}
{"op":"mcm","clk":"1004561310","pt":1580632618355,"mc":[{"id":"1.168135752","rc":[{"trd":[[1.55,1029.44]],"batl":[[0,1.56,22.92],[1,1.61,500],[2,1.9,11.14]],"ltp":1.55,"tv":3925.08,"id":41364},{"trd":[[2.8,29.01]],"ltp":2.8,"tv":1048.84,"id":41365}],"tv":4973.93}]}
{"op":"mcm","clk":"1004562435","pt":1580632647714,"mc":[{"id":"1.168135752","rc":[{"batl":[[0,1.56,22.79]],"ltp":1.55,"tv":3925.08,"id":41364}]}]}
{"op":"mcm","clk":"1004563902","pt":1580632685626,"mc":[{"id":"1.168135752","rc":[{"trd":[[1.56,836.56]],"batb":[[0,1.56,83.57],[1,1.52,693.97],[2,1.26,96.63]],"batl":[[0,1.61,500],[1,1.9,11.14],[2,2.3,25.21]],"ltp":1.56,"tv":3970.67,"id":41364}],"tv":5019.52}]}
{"op":"mcm","clk":"1004564378","pt":1580632696742,"mc":[{"id":"1.168135752","rc":[{"batb":[[0,1.57,83.57]],"ltp":1.56,"tv":3970.67,"id":41364}]}]}
{"op":"mcm","clk":"1004564415","pt":1580632697669,"mc":[{"id":"1.168135752","rc":[{"trd":[[1.58,41.58]],"batb":[[0,1.58,41.99]],"ltp":1.58,"tv":4012.25,"id":41364},{"trd":[[2.74,74]],"batb":[[0,2.66,186.52],[1,2.64,15.2],[2,2.34,22]],"ltp":2.74,"tv":1072.84,"id":41365}],"tv":5085.1}]}
{"op":"mcm","clk":"1004564687","pt":1580632703593,"mc":[{"id":"1.168135752","rc":[{"batb":[[0,1.59,41.99]],"ltp":1.58,"tv":4012.25,"id":41364}]}]}
{"op":"mcm","clk":"1004564738","pt":1580632704677,"mc":[{"id":"1.168135752","rc":[{"batb":[[0,1.6,41.99]],"ltp":1.58,"tv":4012.25,"id":41364}]}]}
{"op":"mcm","clk":"1004564779","pt":1580632705754,"mc":[{"id":"1.168135752","rc":[{"trd":[[1.61,84.03]],"batb":[[0,1.52,693.97],[1,1.26,96.63],[2,1.01,1.01]],"batl":[[0,1.61,457.96]],"ltp":1.61,"tv":4096.28,"id":41364}],"tv":5169.13}]}
{"op":"mcm","clk":"1004565564","pt":1580632724716,"mc":[{"id":"1.168135752","rc":[{"batb":[[0,2.68,15.2],[1,2.66,186.52]],"ltp":2.74,"tv":1072.84,"id":41365}]}]}
{"op":"mcm","clk":"1004566086","pt":1580632735799,"mc":[{"id":"1.168135752","rc":[{"batb":[[1,2.64,186.52]],"ltp":2.74,"tv":1072.84,"id":41365}]}]}
{"op":"mcm","clk":"1004566165","pt":1580632737796,"mc":[{"id":"1.168135752","rc":[{"batl":[[0,1.9,11.14],[1,2.3,25.21],[2,2.3,0]],"ltp":1.61,"tv":4096.28,"id":41364}]}]}
{"op":"mcm","clk":"1004566237","pt":1580632739805,"mc":[{"id":"1.168135752","rc":[{"trd":[[1.52,275.87]],"batb":[[0,1.52,659.17]],"ltp":1.52,"tv":4131.08,"id":41364},{"trd":[[2.82,137.82],[2.94,17.98]],"batl":[[0,3,58.9],[1,3,0]],"ltp":2.94,"tv":1149.6,"id":41365}],"tv":5280.69}]}
{"op":"mcm","clk":"1004566332","pt":1580632742427,"mc":[{"id":"1.168135752","rc":[{"batl":[[0,1.6,25.33],[1,1.9,11.14],[2,2.3,25.21]],"ltp":1.52,"tv":4131.08,"id":41364}]}]}
{"op":"mcm","clk":"1004566474","pt":1580632745820,"mc":[{"id":"1.168135752","rc":[{"batb":[[0,1.53,1.65],[1,1.52,659.17],[2,1.26,96.63]],"ltp":1.52,"tv":4131.08,"id":41364},{"batb":[[0,2.68,16.13]],"ltp":2.94,"tv":1149.6,"id":41365}]}]}
{"op":"mcm","clk":"1004566548","pt":1580632747420,"mc":[{"id":"1.168135752","rc":[{"trd":[[1.52,275.94],[1.53,305.32]],"batb":[[0,1.52,659.13],[1,1.26,96.63],[2,1.01,1.01]],"ltp":1.52,"tv":4134.45,"id":41364}],"tv":5284.05}]}
{"op":"mcm","clk":"1004566805","pt":1580632752727,"mc":[{"id":"1.168135752","rc":[{"batb":[[0,2.68,66.78]],"ltp":2.94,"tv":1149.6,"id":41365}]}]}
{"op":"mcm","clk":"1004569833","pt":1580632823627,"mc":[{"id":"1.168135752","rc":[{"batb":[[0,2.68,117.43]],"ltp":2.94,"tv":1149.6,"id":41365}]}]}
{"op":"mcm","clk":"1004570941","pt":1580632848648,"mc":[{"id":"1.168135752","rc":[{"batl":[[0,1.57,10.64],[1,1.6,25.33],[2,1.9,11.14]],"ltp":1.52,"tv":4134.45,"id":41364}]}]}
{"op":"mcm","clk":"1004571491","pt":1580632858798,"mc":[{"id":"1.168135752","rc":[{"batl":[[0,1.57,11.14]],"ltp":1.52,"tv":4134.45,"id":41364}]}]}
{"op":"mcm","clk":"1004572719","pt":1580632881808,"mc":[{"id":"1.168135752","rc":[{"batl":[[0,1.56,10.64],[1,1.6,25.83]],"ltp":1.52,"tv":4134.45,"id":41364}]}]}
{"op":"mcm","clk":"1004573646","pt":1580632899640,"mc":[{"id":"1.168135752","rc":[{"batl":[[0,1.55,10.64]],"ltp":1.52,"tv":4134.45,"id":41364}]}]}
{"op":"mcm","clk":"1004575961","pt":1580632940658,"mc":[{"id":"1.168135752","rc":[{"batl":[[1,1.6,25.33]],"ltp":1.52,"tv":4134.45,"id":41364}]}]}
{"op":"mcm","clk":"1004576333","pt":1580632948502,"mc":[{"id":"1.168135752","rc":[{"trd":[[1.55,1039.5]],"batl":[[0,1.6,25.9],[1,1.9,11.14],[2,2.3,25.21]],"ltp":1.55,"tv":4144.51,"id":41364},{"trd":[[2.8,34.58]],"ltp":2.8,"tv":1155.17,"id":41365}],"tv":5299.69}]}
{"op":"mcm","clk":"1004576655","pt":1580632955112,"mc":[{"id":"1.168135752","rc":[{"batl":[[0,1.6,25.33]],"ltp":1.55,"tv":4144.51,"id":41364}]}]}
{"op":"mcm","clk":"1004578063","pt":1580632985634,"mc":[{"id":"1.168135752","rc":[{"batl":[[0,2.92,25.33],[1,3,58.9]],"ltp":2.8,"tv":1155.17,"id":41365}]}]}
{"op":"mcm","clk":"1004578115","pt":1580632986814,"mc":[{"id":"1.168135752","rc":[{"trd":[[2.68,192.94],[2.7,107.16]],"batb":[[0,2.68,109.83]],"ltp":2.68,"tv":1170.37,"id":41365}],"tv":5314.89}]}
{"op":"mcm","clk":"1004578833","pt":1580632996715,"mc":[{"id":"1.168135752","rc":[{"batb":[[0,1.53,11.65],[1,1.52,659.13],[2,1.26,96.63]],"ltp":1.55,"tv":4144.51,"id":41364}]}]}
{"op":"mcm","clk":"1004582113","pt":1580633062698,"mc":[{"id":"1.168135752","rc":[{"batl":[[0,2.9,25.33]],"ltp":2.68,"tv":1170.37,"id":41365}]}]}
{"op":"mcm","clk":"1004582158","pt":1580633063629,"mc":[{"id":"1.168135752","rc":[{"trd":[[2.68,203.07]],"batb":[[0,2.68,104.77]],"ltp":2.68,"tv":1180.5,"id":41365}],"tv":5325.02}]}
{"op":"mcm","clk":"1004583259","pt":1580633085535,"mc":[{"id":"1.168135752","rc":[{"batb":[[0,1.53,20.26]],"ltp":1.55,"tv":4144.51,"id":41364}]}]}
{"op":"mcm","clk":"1004583692","pt":1580633094568,"mc":[{"id":"1.168135752","rc":[{"batb":[[0,2.68,101.3]],"ltp":2.68,"tv":1180.5,"id":41365}]}]}
{"op":"mcm","clk":"1004585258","pt":1580633128782,"mc":[{"id":"1.168135752","rc":[{"batl":[[0,1.59,20.26],[1,1.6,25.33],[2,1.9,11.14]],"ltp":1.55,"tv":4144.51,"id":41364}]}]}
{"op":"mcm","clk":"1004585730","pt":1580633138784,"mc":[{"id":"1.168135752","rc":[{"batl":[[0,1.58,20.26]],"ltp":1.55,"tv":4144.51,"id":41364}]}]}
{"op":"mcm","clk":"1004586386","pt":1580633151547,"mc":[{"id":"1.168135752","marketDefinition":{"bspMarket":false,"turnInPlayEnabled":true,"persistenceEnabled":true,"marketBaseRate":5.0,"eventId":"29678823","eventTypeId":"2","numberOfWinners":1,"bettingType":"ODDS","marketType":"PLAYER_A_WIN_A_SET","marketTime":"2020-02-02T08:30:00.000Z","suspendTime":"2020-02-02T08:30:00.000Z","bspReconciled":false,"complete":true,"inPlay":true,"crossMatching":true,"runnersVoidable":false,"numberOfActiveRunners":2,"betDelay":3,"status":"OPEN","runners":[{"status":"ACTIVE","sortPriority":1,"id":41364,"name":"Yes"},{"status":"ACTIVE","sortPriority":2,"id":41365,"name":"No"}],"regulators":["MR_INT"],"countryCode":"AU","discountAllowed":true,"timezone":"GMT","openDate":"2020-02-02T08:30:00.000Z","version":3148327199,"name":"Thiem To Win A Set?","eventName":"Thiem v Djokovic"},"rc":[{"batb":[[1,1.01,0.52],[2,1.26,0]],"batl":[[0,1.6,25.33],[1,1.6,0],[2,1.9,0]],"ltp":1.55,"tv":4144.51,"id":41364},{"batb":[[0,1.01,0.52],[1,2.64,0],[2,2.34,0]],"ltp":2.68,"tv":1180.5,"id":41365}]}]}
{"op":"mcm","clk":"1004593503","pt":1580633313811,"mc":[{"id":"1.168135752","rc":[{"trd":[[1.6,8.3]],"batl":[[0,1.6,17.02]],"ltp":1.6,"tv":4152.81,"id":41364},{"trd":[[2.66,5]],"ltp":2.66,"tv":1185.5,"id":41365}],"tv":5338.32}]}
{"op":"mcm","clk":"1004594360","pt":1580633334760,"mc":[{"id":"1.168135752","rc":[{"trd":[[1.53,308.83]],"batb":[[0,1.53,18.5]],"ltp":1.53,"tv":4156.33,"id":41364}],"tv":5341.83}]}
{"op":"mcm","clk":"1004604200","pt":1580633554693,"mc":[{"id":"1.168135752","rc":[{"batl":[[0,1.78,17.02]],"ltp":1.53,"tv":4156.33,"id":41364}]}]}
{"op":"mcm","clk":"1004605626","pt":1580633590755,"mc":[{"id":"1.168135752","rc":[{"trd":[[1.53,345.86]],"batb":[[0,1.01,0.52],[1,1.01,0]],"batl":[[0,1.53,2.48],[1,1.78,17.02]],"ltp":1.53,"tv":4193.36,"id":41364}],"tv":5378.86}]}
{"op":"mcm","clk":"1004605941","pt":1580633598554,"mc":[{"id":"1.168135752","rc":[{"batl":[[0,1.78,17.02],[1,1.78,0]],"ltp":1.53,"tv":4193.36,"id":41364}]}]}
{"op":"mcm","clk":"1004617223","pt":1580633833725,"mc":[{"id":"1.168135752","rc":[{"trd":[[1.78,13.66]],"batl":[[0,1.78,10.2]],"ltp":1.78,"tv":4207.02,"id":41364}],"tv":5392.52}]}
{"op":"mcm","clk":"1004618124","pt":1580633851714,"mc":[{"id":"1.168135752","rc":[{"trd":[[1.78,27.32]],"batl":[[0,1.78,3.37]],"ltp":1.78,"tv":4220.68,"id":41364}],"tv":5406.18}]}
{"op":"mcm","clk":"1004619693","pt":1580633880757,"mc":[{"id":"1.168135752","rc":[{"trd":[[1.78,33.39]],"batl":[[0,1.78,0.33]],"ltp":1.78,"tv":4226.75,"id":41364}],"tv":5412.25}]}
{"op":"mcm","clk":"1004623983","pt":1580633957795,"mc":[{"id":"1.168135752","rc":[{"trd":[[1.78,34.06]],"batb":[[0,1.01,0.94]],"ltp":1.78,"tv":4227.42,"id":41364}],"tv":5412.92}]}
{"op":"mcm","clk":"1004625816","pt":1580633990713,"mc":[{"id":"1.168135752","rc":[{"batb":[[0,1.01,0.52]],"ltp":1.78,"tv":4227.42,"id":41364}]}]}
{"op":"mcm","clk":"1004626268","pt":1580634000122,"mc":[{"id":"1.168135752","rc":[{"batl":[[0,3.5,210.05]],"ltp":1.78,"tv":4227.42,"id":41364}]}]}
{"op":"mcm","clk":"1004628471","pt":1580634030664,"mc":[{"id":"1.168135752","rc":[{"batl":[[0,3.4,12.66],[1,3.5,210.05]],"ltp":1.78,"tv":4227.42,"id":41364}]}]}
{"op":"mcm","clk":"1004629281","pt":1580634043793,"mc":[{"id":"1.168135752","rc":[{"batl":[[1,3.5,0]],"ltp":1.78,"tv":4227.42,"id":41364}]}]}
{"op":"mcm","clk":"1004649088","pt":1580634443815,"mc":[{"id":"1.168135752","rc":[{"batl":[[0,2,10],[1,3.4,12.66]],"ltp":1.78,"tv":4227.42,"id":41364}]}]}
{"op":"mcm","clk":"1004655478","pt":1580634588768,"mc":[{"id":"1.168135752","rc":[{"trd":[[2,10]],"batl":[[0,3.4,12.66],[1,3.4,0]],"ltp":2.0,"tv":4237.42,"id":41364},{"trd":[[2,10]],"ltp":2.0,"tv":1195.5,"id":41365}],"tv":5432.92}]}
{"op":"mcm","clk":"1004657717","pt":1580634642806,"mc":[{"id":"1.168135752","rc":[{"batb":[[0,1.45,15.15],[1,1.01,0.51]],"ltp":2.0,"tv":1195.5,"id":41365}]}]}
{"op":"mcm","clk":"1004662238","pt":1580634735637,"mc":[{"id":"1.168135752","rc":[{"batb":[[0,1.1,26.51],[1,1.01,0.51]],"ltp":2.0,"tv":4237.42,"id":41364}]}]}
{"op":"mcm","clk":"1004736043","pt":1580636366740,"mc":[{"id":"1.168135752","rc":[{"batl":[[0,3.2,12.66]],"ltp":2.0,"tv":4237.42,"id":41364}]}]}
{"op":"mcm","clk":"1004736256","pt":1580636371792,"mc":[{"id":"1.168135752","rc":[{"batl":[[0,3,84.02],[1,3.2,12.66]],"ltp":2.0,"tv":4237.42,"id":41364}]}]}
{"op":"mcm","clk":"1004736720","pt":1580636381711,"mc":[{"id":"1.168135752","rc":[{"batb":[[0,1.52,22.72],[1,1.01,0.52]],"ltp":2.0,"tv":1195.5,"id":41365}]}]}
{"op":"mcm","clk":"1004739332","pt":1580636433611,"mc":[{"id":"1.168135752","rc":[{"batl":[[0,2.8,84.02],[1,3,84.02],[2,3.2,12.66]],"ltp":2.0,"tv":4237.42,"id":41364}]}]}
{"op":"mcm","clk":"1004740635","pt":1580636460758,"mc":[{"id":"1.168135752","rc":[{"batl":[[0,3,84.02],[1,3.2,12.66],[2,3.2,0]],"ltp":2.0,"tv":4237.42,"id":41364}]}]}
{"op":"mcm","clk":"1004741476","pt":1580636476793,"mc":[{"id":"1.168135752","rc":[{"batl":[[0,2,168.04],[1,3,84.02],[2,3.2,12.66]],"ltp":2.0,"tv":4237.42,"id":41364}]}]}
{"op":"mcm","clk":"1004742424","pt":1580636492714,"mc":[{"id":"1.168135752","rc":[{"batl":[[1,3.2,12.66],[2,3.2,0]],"ltp":2.0,"tv":4237.42,"id":41364}]}]}
{"op":"mcm","clk":"1004743206","pt":1580636504818,"mc":[{"id":"1.168135752","rc":[{"batb":[[0,1.3,30.3],[1,1.1,26.5],[2,1.01,0.51]],"ltp":2.0,"tv":4237.42,"id":41364}]}]}
{"op":"mcm","clk":"1004746624","pt":1580636562655,"mc":[{"id":"1.168135752","rc":[{"batl":[[0,3.2,12.66],[1,3.2,0]],"ltp":2.0,"tv":4237.42,"id":41364}]}]}
{"op":"mcm","clk":"1004747832","pt":1580636585761,"mc":[{"id":"1.168135752","rc":[{"batb":[[0,1.1,26.51],[1,1.01,0.51],[2,1.01,0]],"ltp":2.0,"tv":4237.42,"id":41364}]}]}
{"op":"mcm","clk":"1004748049","pt":1580636589793,"mc":[{"id":"1.168135752","rc":[{"batb":[[0,1.5,30.29],[1,1.1,26.51],[2,1.01,0.51]],"ltp":2.0,"tv":4237.42,"id":41364}]}]}
{"op":"mcm","clk":"1004748301","pt":1580636593576,"mc":[{"id":"1.168135752","rc":[{"batb":[[0,1.01,0.52],[1,1.01,0]],"ltp":2.0,"tv":1195.5,"id":41365}]}]}
{"op":"mcm","clk":"1004748449","pt":1580636596683,"mc":[{"id":"1.168135752","rc":[{"batb":[[0,1.46,22.73],[1,1.01,0.51]],"ltp":2.0,"tv":1195.5,"id":41365}]}]}
{"op":"mcm","clk":"1004761208","pt":1580636877706,"mc":[{"id":"1.168135752","rc":[{"batb":[[0,1.5,26.5]],"ltp":2.0,"tv":4237.42,"id":41364}]}]}
{"op":"mcm","clk":"1004761395","pt":1580636881814,"mc":[{"id":"1.168135752","rc":[{"batb":[[0,1.01,0.52],[1,1.01,0]],"ltp":2.0,"tv":1195.5,"id":41365}]}]}
{"op":"mcm","clk":"1004761555","pt":1580636884799,"mc":[{"id":"1.168135752","rc":[{"batb":[[0,1.48,22.73],[1,1.01,0.51]],"ltp":2.0,"tv":1195.5,"id":41365}]}]}
{"op":"mcm","clk":"1004769476","pt":1580637027728,"mc":[{"id":"1.168135752","rc":[{"trd":[[1.5,327.08]],"batb":[[0,1.5,1.15]],"ltp":1.5,"tv":4288.09,"id":41364}],"tv":5483.6}]}
{"op":"mcm","clk":"1004769732","pt":1580637032438,"mc":[{"id":"1.168135752","rc":[{"batb":[[0,1.1,26.51],[1,1.01,0.51],[2,1.01,0]],"ltp":1.5,"tv":4288.09,"id":41364}]}]}
{"op":"mcm","clk":"1004771189","pt":1580637056782,"mc":[{"id":"1.168135752","rc":[{"batb":[[0,2.1,16.66],[1,1.48,22.73],[2,1.01,0.51]],"ltp":2.0,"tv":1195.5,"id":41365}]}]}
{"op":"mcm","clk":"1004772038","pt":1580637073807,"mc":[{"id":"1.168135752","rc":[{"batb":[[0,1.2,18.94],[1,1.1,26.5],[2,1.01,0.51]],"ltp":1.5,"tv":4288.09,"id":41364}]}]}
{"op":"mcm","clk":"1004773464","pt":1580637105764,"mc":[{"id":"1.168135752","rc":[{"batb":[[0,1.48,22.73],[1,1.01,0.51],[2,1.01,0]],"ltp":2.0,"tv":1195.5,"id":41365}]}]}
{"op":"mcm","clk":"1004773629","pt":1580637108753,"mc":[{"id":"1.168135752","rc":[{"batb":[[0,2.2,16.66],[1,1.48,22.73],[2,1.01,0.51]],"ltp":2.0,"tv":1195.5,"id":41365}]}]}
{"op":"mcm","clk":"1004776791","pt":1580637162068,"mc":[{"id":"1.168135752","rc":[{"trd":[[1.2,37.86],[1.49,0.02]],"batb":[[0,1.1,26.5],[1,1.01,0.51],[2,1.01,0]],"batl":[[0,1.2,31.06],[1,3.2,12.66]],"ltp":1.2,"tv":4325.97,"id":41364}],"tv":5521.48}]}
{"op":"mcm","clk":"1004777328","pt":1580637171617,"mc":[{"id":"1.168135752","rc":[{"trd":[[1.2,99.98]],"batb":[[0,1.2,6.8],[1,1.1,26.5],[2,1.01,0.51]],"batl":[[0,3.2,12.66],[1,3.2,0]],"ltp":1.2,"tv":4388.1,"id":41364}],"tv":5583.6}]}
{"op":"mcm","clk":"1004778068","pt":1580637185717,"mc":[{"id":"1.168135752","rc":[{"batl":[[0,1.6,21.2],[1,3.2,12.66]],"ltp":1.2,"tv":4388.1,"id":41364}]}]}
{"op":"mcm","clk":"1004778431","pt":1580637192644,"mc":[{"id":"1.168135752","rc":[{"batb":[[2,1.01,64.87]],"ltp":1.2,"tv":4388.1,"id":41364}]}]}
{"op":"mcm","clk":"1004779530","pt":1580637216747,"mc":[{"id":"1.168135752","rc":[{"batb":[[0,1.1,26.5],[1,1.01,64.87],[2,1.01,0]],"ltp":1.2,"tv":4388.1,"id":41364}]}]}
{"op":"mcm","clk":"1004779999","pt":1580637226786,"mc":[{"id":"1.168135752","rc":[{"batl":[[0,3.2,12.66],[1,3.2,0]],"ltp":1.2,"tv":4388.1,"id":41364}]}]}
{"op":"mcm","clk":"1004780055","pt":1580637227765,"mc":[{"id":"1.168135752","rc":[{"batl":[[0,1.5,27.26],[1,3.2,12.66]],"ltp":1.2,"tv":4388.1,"id":41364}]}]}
{"op":"mcm","clk":"1004780520","pt":1580637236815,"mc":[{"id":"1.168135752","rc":[{"batb":[[1,1.02,74.21],[2,1.01,64.87]],"ltp":1.2,"tv":4388.1,"id":41364}]}]}
{"op":"mcm","clk":"1004781402","pt":1580637254751,"mc":[{"id":"1.168135752","rc":[{"batl":[[0,3.2,12.66],[1,3.2,0]],"ltp":1.2,"tv":4388.1,"id":41364}]}]}
{"op":"mcm","clk":"1004781554","pt":1580637257750,"mc":[{"id":"1.168135752","rc":[{"batl":[[0,1.44,27.26],[1,3.2,12.66]],"ltp":1.2,"tv":4388.1,"id":41364}]}]}
{"op":"mcm","clk":"1004781661","pt":1580637259760,"mc":[{"id":"1.168135752","rc":[{"trd":[[1.44,50]],"batl":[[0,1.44,2.26]],"ltp":1.44,"tv":4438.1,"id":41364}],"tv":5633.61}]}
{"op":"mcm","clk":"1004782147","pt":1580637269631,"mc":[{"id":"1.168135752","rc":[{"trd":[[1.44,52.44]],"batl":[[0,1.44,1.04]],"ltp":1.44,"tv":4440.54,"id":41364}],"tv":5636.05}]}
{"op":"mcm","clk":"1004782285","pt":1580637272769,"mc":[{"id":"1.168135752","rc":[{"batl":[[0,3.2,12.66],[1,3.2,0]],"ltp":1.44,"tv":4440.54,"id":41364}]}]}
{"op":"mcm","clk":"1004782825","pt":1580637283685,"mc":[{"id":"1.168135752","rc":[{"batb":[[0,1.48,22.73],[1,1.01,0.51],[2,1.01,0]],"ltp":2.0,"tv":1195.5,"id":41365}]}]}
{"op":"mcm","clk":"1004783457","pt":1580637296776,"mc":[{"id":"1.168135752","rc":[{"batl":[[0,1.58,28.77],[1,3.2,12.66]],"ltp":1.44,"tv":4440.54,"id":41364}]}]}
{"op":"mcm","clk":"1004783889","pt":1580637305725,"mc":[{"id":"1.168135752","rc":[{"batb":[[0,1.14,30.29],[1,1.1,26.5],[2,1.02,74.21]],"ltp":1.44,"tv":4440.54,"id":41364}]}]}
{"op":"mcm","clk":"1004784546","pt":1580637318742,"mc":[{"id":"1.168135752","rc":[{"batl":[[0,3.2,12.66],[1,3.2,0]],"ltp":1.44,"tv":4440.54,"id":41364}]}]}
{"op":"mcm","clk":"1004784678","pt":1580637321764,"mc":[{"id":"1.168135752","rc":[{"batl":[[0,1.44,28.77],[1,3.2,12.66]],"ltp":1.44,"tv":4440.54,"id":41364}]}]}
{"op":"mcm","clk":"1004785528","pt":1580637340608,"mc":[{"id":"1.168135752","rc":[{"trd":[[1.44,108.19]],"batl":[[0,3.2,13.55],[1,3.2,0]],"ltp":1.44,"tv":4496.29,"id":41364}],"tv":5691.79}]}
{"op":"mcm","clk":"1004785924","pt":1580637349729,"mc":[{"id":"1.168135752","rc":[{"batb":[[0,1.1,26.5],[1,1.02,74.21],[2,1.01,64.87]],"ltp":1.44,"tv":4496.29,"id":41364}]}]}
{"op":"mcm","clk":"1004786075","pt":1580637352519,"mc":[{"id":"1.168135752","rc":[{"batb":[[0,1.2,30.29],[1,1.1,26.5],[2,1.02,74.21]],"ltp":1.44,"tv":4496.29,"id":41364}]}]}
{"op":"mcm","clk":"1004787439","pt":1580637377744,"mc":[{"id":"1.168135752","rc":[{"batb":[[0,1.2,18.93]],"batl":[[0,1.44,6.94],[1,3.2,12.66]],"ltp":1.44,"tv":4496.29,"id":41364}]}]}
{"op":"mcm","clk":"1004789384","pt":1580637403764,"mc":[{"id":"1.168135752","rc":[{"batb":[[0,1.1,26.5],[1,1.02,74.21],[2,1.01,64.87]],"ltp":1.44,"tv":4496.29,"id":41364}]}]}
{"op":"mcm","clk":"1004790042","pt":1580637415792,"mc":[{"id":"1.168135752","rc":[{"trd":[[1.44,114.96]],"batl":[[0,3.2,12.84],[1,3.2,0]],"ltp":1.44,"tv":4503.06,"id":41364},{"trd":[[3.25,3]],"ltp":3.25,"tv":1198.5,"id":41365}],"tv":5701.56}]}
{"op":"mcm","clk":"1004791041","pt":1580637428807,"mc":[{"id":"1.168135752","rc":[{"batl":[[0,1.68,3.96],[1,3.2,12.66]],"ltp":1.44,"tv":4503.06,"id":41364}]}]}
{"op":"mcm","clk":"1004792865","pt":1580637460697,"mc":[{"id":"1.168135752","rc":[{"batb":[[0,1.15,22.72],[1,1.1,26.5],[2,1.02,74.21]],"ltp":1.44,"tv":4503.06,"id":41364}]}]}
{"op":"mcm","clk":"1004794046","pt":1580637482281,"mc":[{"id":"1.168135752","rc":[{"batl":[[0,1.68,3.79]],"ltp":1.44,"tv":4503.06,"id":41364}]}]}
{"op":"mcm","clk":"1004794238","pt":1580637485732,"mc":[{"id":"1.168135752","rc":[{"batb":[[0,1.1,26.5],[1,1.02,74.21],[2,1.01,64.87]],"ltp":1.44,"tv":4503.06,"id":41364}]}]}
{"op":"mcm","clk":"1004794398","pt":1580637488715,"mc":[{"id":"1.168135752","rc":[{"batb":[[0,1.2,22.72],[1,1.1,26.5],[2,1.02,74.21]],"ltp":1.44,"tv":4503.06,"id":41364}]}]}
{"op":"mcm","clk":"1004795797","pt":1580637515646,"mc":[{"id":"1.168135752","rc":[{"batl":[[0,3.2,12.66],[1,3.2,0]],"ltp":1.44,"tv":4503.06,"id":41364}]}]}
{"op":"mcm","clk":"1004795972","pt":1580637518737,"mc":[{"id":"1.168135752","rc":[{"batb":[[0,1.1,26.5],[1,1.02,74.21],[2,1.01,64.87]],"batl":[[0,1.44,3.79],[1,3.2,12.66]],"ltp":1.44,"tv":4503.06,"id":41364}]}]}
{"op":"mcm","clk":"1004797572","pt":1580637546784,"mc":[{"id":"1.168135752","rc":[{"batl":[[0,1.2,1.01],[1,1.44,3.79],[2,3.2,12.66]],"ltp":1.44,"tv":4503.06,"id":41364}]}]}
{"op":"mcm","clk":"1004797916","pt":1580637553690,"mc":[{"id":"1.168135752","rc":[{"trd":[[1.2,106.04]],"batl":[[0,1.44,4.31],[1,3.2,12.66],[2,3.2,0]],"ltp":1.2,"tv":4509.11,"id":41364}],"tv":5707.62}]}
{"op":"mcm","clk":"1004798388","pt":1580637561748,"mc":[{"id":"1.168135752","rc":[{"batl":[[0,3.2,13.18],[1,3.2,0]],"ltp":1.2,"tv":4509.11,"id":41364}]}]}
{"op":"mcm","clk":"1004798568","pt":1580637564747,"mc":[{"id":"1.168135752","rc":[{"batl":[[0,1.42,4.31],[1,3.2,12.66]],"ltp":1.2,"tv":4509.11,"id":41364}]}]}
{"op":"mcm","clk":"1004802655","pt":1580637623549,"mc":[{"id":"1.168135752","rc":[{"batb":[[0,1.1,21.2]],"ltp":1.2,"tv":4509.11,"id":41364}]}]}
{"op":"mcm","clk":"1004803615","pt":1580637637569,"mc":[{"id":"1.168135752","rc":[{"batb":[[0,2,16.66],[1,1.48,22.73],[2,1.01,0.51]],"ltp":3.25,"tv":1198.5,"id":41365}]}]}
{"op":"mcm","clk":"1004818798","pt":1580637841755,"mc":[{"id":"1.168135752","rc":[{"batl":[[0,3.2,13.18],[1,3.2,0]],"ltp":1.2,"tv":4509.11,"id":41364}]}]}
{"op":"mcm","clk":"1004818972","pt":1580637844763,"mc":[{"id":"1.168135752","rc":[{"batl":[[0,1.38,4.31],[1,3.2,12.66]],"ltp":1.2,"tv":4509.11,"id":41364}]}]}
{"op":"mcm","clk":"1004827161","pt":1580637976756,"mc":[{"id":"1.168135752","rc":[{"batb":[[0,2,10.6]],"ltp":3.25,"tv":1198.5,"id":41365}]}]}
{"op":"mcm","clk":"1004829370","pt":1580638010815,"mc":[{"id":"1.168135752","rc":[{"batl":[[0,3.2,13.18],[1,3.2,0]],"ltp":1.2,"tv":4509.11,"id":41364}]}]}
{"op":"mcm","clk":"1004829561","pt":1580638013733,"mc":[{"id":"1.168135752","rc":[{"batl":[[0,1.48,4.31],[1,3.2,12.66]],"ltp":1.2,"tv":4509.11,"id":41364},{"batb":[[0,2,7.57]],"ltp":3.25,"tv":1198.5,"id":41365}]}]}
{"op":"mcm","clk":"1004830190","pt":1580638023773,"mc":[{"id":"1.168135752","rc":[{"trd":[[1.2,107.08]],"batb":[[0,1.2,3.26],[1,1.1,21.2],[2,1.02,74.21]],"batl":[[0,1.48,3.79]],"ltp":1.2,"tv":4510.15,"id":41364}],"tv":5708.66}]}
{"op":"mcm","clk":"1004832594","pt":1580638059704,"mc":[{"id":"1.168135752","rc":[{"batb":[[0,1.1,21.2],[1,1.02,74.21],[2,1.01,64.87]],"ltp":1.2,"tv":4510.15,"id":41364}]}]}
{"op":"mcm","clk":"1004832713","pt":1580638061696,"mc":[{"id":"1.168135752","rc":[{"batl":[[0,3.2,12.66],[1,3.2,0]],"ltp":1.2,"tv":4510.15,"id":41364}]}]}
{"op":"mcm","clk":"1004832765","pt":1580638062795,"mc":[{"id":"1.168135752","rc":[{"batb":[[0,1.15,3.26],[1,1.1,21.2],[2,1.02,74.21]],"ltp":1.2,"tv":4510.15,"id":41364}]}]}
{"op":"mcm","clk":"1004832879","pt":1580638064786,"mc":[{"id":"1.168135752","rc":[{"batl":[[0,1.38,3.79],[1,3.2,12.66]],"ltp":1.2,"tv":4510.15,"id":41364}]}]}
{"op":"mcm","clk":"1004834365","pt":1580638086772,"mc":[{"id":"1.168135752","rc":[{"batb":[[0,1.1,21.2],[1,1.02,74.21],[2,1.01,64.87]],"ltp":1.2,"tv":4510.15,"id":41364}]}]}
{"op":"mcm","clk":"1004834878","pt":1580638094734,"mc":[{"id":"1.168135752","rc":[{"batl":[[0,3.2,12.66],[1,3.2,0]],"ltp":1.2,"tv":4510.15,"id":41364}]}]}
{"op":"mcm","clk":"1004835146","pt":1580638098785,"mc":[{"id":"1.168135752","rc":[{"batl":[[0,1.29,3.79]],"ltp":1.2,"tv":4510.15,"id":41364}]}]}
{"op":"mcm","clk":"1004837460","pt":1580638133721,"mc":[{"id":"1.168135752","rc":[{"batb":[[0,1.02,74.21],[1,1.01,64.87],[2,1.01,0]],"ltp":1.2,"tv":4510.15,"id":41364}]}]}
{"op":"mcm","clk":"1004837579","pt":1580638135642,"mc":[{"id":"1.168135752","rc":[{"batb":[[0,1.02,48.46]],"ltp":1.2,"tv":4510.15,"id":41364}]}]}
{"op":"mcm","clk":"1004837704","pt":1580638137719,"mc":[{"id":"1.168135752","rc":[{"batb":[[0,1.01,64.87],[1,1.01,0]],"ltp":1.2,"tv":4510.15,"id":41364}]}]}
{"op":"mcm","clk":"1004837888","pt":1580638140622,"mc":[{"id":"1.168135752","rc":[{"batb":[[0,1.05,48.46],[1,1.01,64.87]],"ltp":1.2,"tv":4510.15,"id":41364}]}]}
{"op":"mcm","clk":"1004838268","pt":1580638145725,"mc":[{"id":"1.168135752","rc":[{"batb":[[0,2,22.72]],"ltp":3.25,"tv":1198.5,"id":41365}]}]}
{"op":"mcm","clk":"1004840207","pt":1580638172656,"mc":[{"id":"1.168135752","rc":[{"batb":[[0,1.06,58.76],[1,1.05,48.46],[2,1.01,64.87]],"ltp":1.2,"tv":4510.15,"id":41364}]}]}
{"op":"mcm","clk":"1004841106","pt":1580638184802,"mc":[{"id":"1.168135752","rc":[{"batb":[[0,1.07,15.14],[1,1.06,58.76],[2,1.05,48.46]],"ltp":1.2,"tv":4510.15,"id":41364}]}]}
{"op":"mcm","clk":"1004841475","pt":1580638189793,"mc":[{"id":"1.168135752","rc":[{"batb":[[2,1.01,64.87]],"ltp":1.2,"tv":4510.15,"id":41364}]}]}
{"op":"mcm","clk":"1004849216","pt":1580638297650,"mc":[{"id":"1.168135752","rc":[{"batb":[[0,2,19.69]],"ltp":3.25,"tv":1198.5,"id":41365}]}]}
{"op":"mcm","clk":"1004849272","pt":1580638298582,"mc":[{"id":"1.168135752","rc":[{"batb":[[0,2,12.12]],"ltp":3.25,"tv":1198.5,"id":41365}]}]}
{"op":"mcm","clk":"1004854337","pt":1580638360352,"mc":[{"id":"1.168135752","rc":[{"batb":[[0,1.15,2.53],[1,1.07,15.14],[2,1.06,58.76]],"ltp":1.2,"tv":4510.15,"id":41364}]}]}
{"op":"mcm","clk":"1004865487","pt":1580638499716,"mc":[{"id":"1.168135752","rc":[{"batl":[[0,1.38,3.79]],"ltp":1.2,"tv":4510.15,"id":41364}]}]}
{"op":"mcm","clk":"1004865894","pt":1580638503616,"mc":[{"id":"1.168135752","rc":[{"batb":[[0,2,9.09]],"ltp":3.25,"tv":1198.5,"id":41365}]}]}
{"op":"mcm","clk":"1004872105","pt":1580638585301,"mc":[{"id":"1.168135752","rc":[{"batb":[[0,1.07,15.14],[1,1.06,58.76],[2,1.01,64.87]],"ltp":1.2,"tv":4510.15,"id":41364}]}]}
{"op":"mcm","clk":"1004872333","pt":1580638588664,"mc":[{"id":"1.168135752","rc":[{"batb":[[0,1.1,2.53],[1,1.07,15.14],[2,1.06,58.76]],"ltp":1.2,"tv":4510.15,"id":41364}]}]}
{"op":"mcm","clk":"1004876918","pt":1580638645672,"mc":[{"id":"1.168135752","rc":[{"batl":[[0,1.48,3.79]],"ltp":1.2,"tv":4510.15,"id":41364}]}]}
{"op":"mcm","clk":"1004877076","pt":1580638647760,"mc":[{"id":"1.168135752","rc":[{"batb":[[0,1.48,22.73],[1,1.01,0.51],[2,1.01,0]],"ltp":3.25,"tv":1198.5,"id":41365}]}]}
{"op":"mcm","clk":"1004877271","pt":1580638650756,"mc":[{"id":"1.168135752","rc":[{"batb":[[0,1.7,9.09],[1,1.48,22.73],[2,1.01,0.51]],"ltp":3.25,"tv":1198.5,"id":41365}]}]}
{"op":"mcm","clk":"1004878596","pt":1580638669775,"mc":[{"id":"1.168135752","rc":[{"batb":[[0,1.11,100],[1,1.1,2.53],[2,1.07,15.14]],"ltp":1.2,"tv":4510.15,"id":41364}]}]}
{"op":"mcm","clk":"1004879781","pt":1580638685806,"mc":[{"id":"1.168135752","rc":[{"batb":[[0,1.2,18.17],[1,1.11,100],[2,1.1,2.53]],"ltp":1.2,"tv":4510.15,"id":41364}]}]}
{"op":"mcm","clk":"1004880731","pt":1580638696755,"mc":[{"id":"1.168135752","rc":[{"batb":[[2,1.07,15.14]],"ltp":1.2,"tv":4510.15,"id":41364}]}]}
{"op":"mcm","clk":"1004881421","pt":1580638704759,"mc":[{"id":"1.168135752","rc":[{"batb":[[1,1.12,24.23],[2,1.11,100]],"ltp":1.2,"tv":4510.15,"id":41364}]}]}
{"op":"mcm","clk":"1004882363","pt":1580638715647,"mc":[{"id":"1.168135752","rc":[{"batl":[[0,1.68,4.54]],"ltp":1.2,"tv":4510.15,"id":41364},{"batb":[[0,1.48,22.73],[1,1.01,0.51],[2,1.01,0]],"ltp":3.25,"tv":1198.5,"id":41365}]}]}
{"op":"mcm","clk":"1004887110","pt":1580638774728,"mc":[{"id":"1.168135752","rc":[{"trd":[[1.68,6.07]],"batl":[[0,1.68,1.51]],"ltp":1.68,"tv":4516.23,"id":41364}],"tv":5714.73}]}
{"op":"mcm","clk":"1004888610","pt":1580638792454,"mc":[{"id":"1.168135752","rc":[{"batl":[[0,1.8,3.03]],"ltp":1.68,"tv":4516.23,"id":41364}]}]}
{"op":"mcm","clk":"1004889234","pt":1580638800752,"mc":[{"id":"1.168135752","rc":[{"batb":[[1,1.2,28.77],[2,1.01,0.51]],"ltp":3.25,"tv":1198.5,"id":41365}]}]}
{"op":"mcm","clk":"1004890094","pt":1580638811569,"mc":[{"id":"1.168135752","rc":[{"batb":[[0,1.2,13.63]],"ltp":1.68,"tv":4516.23,"id":41364}]}]}
{"op":"mcm","clk":"1004891816","pt":1580638832820,"mc":[{"id":"1.168135752","rc":[{"trd":[[1.8,2.49]],"batl":[[0,1.8,0.54]],"ltp":1.8,"tv":4518.72,"id":41364},{"trd":[[2.24,2]],"ltp":2.24,"tv":1200.5,"id":41365}],"tv":5719.22}]}
{"op":"mcm","clk":"1004893952","pt":1580638857764,"mc":[{"id":"1.168135752","rc":[{"batl":[[0,1.8,1.51]],"ltp":1.8,"tv":4518.72,"id":41364}]}]}
{"op":"mcm","clk":"1004894512","pt":1580638863745,"mc":[{"id":"1.168135752","rc":[{"batb":[[2,1.07,15.14]],"ltp":1.8,"tv":4518.72,"id":41364}]}]}
{"op":"mcm","clk":"1004895151","pt":1580638871655,"mc":[{"id":"1.168135752","rc":[{"batb":[[0,1.12,24.23],[1,1.07,15.14],[2,1.01,64.87]],"ltp":1.8,"tv":4518.72,"id":41364}]}]}
{"op":"mcm","clk":"1004895404","pt":1580638874554,"mc":[{"id":"1.168135752","rc":[{"batb":[[0,1.12,16.66]],"ltp":1.8,"tv":4518.72,"id":41364}]}]}
{"op":"mcm","clk":"1004897366","pt":1580638898612,"mc":[{"id":"1.168135752","rc":[{"batb":[[0,1.13,55.72],[1,1.12,16.66],[2,1.07,15.14]],"ltp":1.8,"tv":4518.72,"id":41364}]}]}
{"op":"mcm","clk":"1004899464","pt":1580638924531,"mc":[{"id":"1.168135752","rc":[{"batb":[[1,1.07,15.14],[2,1.01,64.87]],"ltp":1.8,"tv":4518.72,"id":41364}]}]}
{"op":"mcm","clk":"1004900783","pt":1580638939727,"mc":[{"id":"1.168135752","rc":[{"batl":[[0,1.65,3.03]],"ltp":1.8,"tv":4518.72,"id":41364}]}]}
{"op":"mcm","clk":"1004901234","pt":1580638944727,"mc":[{"id":"1.168135752","rc":[{"batb":[[0,1.07,15.14],[1,1.01,64.87],[2,1.01,0]],"ltp":1.8,"tv":4518.72,"id":41364}]}]}
{"op":"mcm","clk":"1004901493","pt":1580638947760,"mc":[{"id":"1.168135752","rc":[{"batb":[[0,1.08,55.72],[1,1.07,15.14],[2,1.01,64.87]],"ltp":1.8,"tv":4518.72,"id":41364}]}]}
{"op":"mcm","clk":"1004903160","pt":1580638966777,"mc":[{"id":"1.168135752","rc":[{"batb":[[0,1.09,15.14],[1,1.08,55.72],[2,1.07,15.14]],"ltp":1.8,"tv":4518.72,"id":41364}]}]}
{"op":"mcm","clk":"1004903400","pt":1580638969798,"mc":[{"id":"1.168135752","rc":[{"batb":[[2,1.01,64.87]],"ltp":1.8,"tv":4518.72,"id":41364}]}]}
{"op":"mcm","clk":"1004903634","pt":1580638972709,"mc":[{"id":"1.168135752","rc":[{"batb":[[2,1.04,15.14]],"ltp":1.8,"tv":4518.72,"id":41364}]}]}
{"op":"mcm","clk":"1004904283","pt":1580638980814,"mc":[{"id":"1.168135752","rc":[{"batb":[[0,1.08,55.72],[1,1.04,15.14],[2,1.01,64.87]],"ltp":1.8,"tv":4518.72,"id":41364}]}]}
{"op":"mcm","clk":"1004904382","pt":1580638981814,"mc":[{"id":"1.168135752","rc":[{"batb":[[1,1.01,64.87],[2,1.01,0]],"ltp":1.8,"tv":4518.72,"id":41364}]}]}
{"op":"mcm","clk":"1004910688","pt":1580639035783,"mc":[{"id":"1.168135752","rc":[{"trd":[[1.08,19.99]],"batb":[[0,1.08,45.73]],"ltp":1.08,"tv":4538.71,"id":41364}],"tv":5739.21}]}
{"op":"mcm","clk":"1004913210","pt":1580639058613,"mc":[{"id":"1.168135752","rc":[{"batb":[[0,1.09,3.79],[1,1.08,45.73],[2,1.01,64.87]],"ltp":1.08,"tv":4538.71,"id":41364}]}]}
{"op":"mcm","clk":"1004923471","pt":1580639163475,"mc":[{"id":"1.168135752","rc":[{"batb":[[0,1.08,45.73],[1,1.01,64.87],[2,1.01,0]],"ltp":1.08,"tv":4538.71,"id":41364}]}]}
{"op":"mcm","clk":"1004923724","pt":1580639165745,"mc":[{"id":"1.168135752","rc":[{"batb":[[1,1.01,0.51]],"ltp":1.08,"tv":4538.71,"id":41364}]}]}
{"op":"mcm","clk":"1004924743","pt":1580639174739,"mc":[{"id":"1.168135752","rc":[{"batb":[[0,1.01,0.51],[1,1.01,0]],"ltp":1.08,"tv":4538.71,"id":41364}]}]}
{"op":"mcm","clk":"1004924851","pt":1580639175634,"mc":[{"id":"1.168135752","rc":[{"batb":[[0,1.48,68.16]],"ltp":2.24,"tv":1200.5,"id":41365}]}]}
{"op":"mcm","clk":"1004925072","pt":1580639177723,"mc":[{"id":"1.168135752","rc":[{"batb":[[0,1.03,45.73],[1,1.01,0.51]],"ltp":1.08,"tv":4538.71,"id":41364}]}]}
{"op":"mcm","clk":"1004926368","pt":1580639189743,"mc":[{"id":"1.168135752","rc":[{"batb":[[0,1.01,0.51],[1,1.01,0]],"ltp":1.08,"tv":4538.71,"id":41364}]}]}
{"op":"mcm","clk":"1004926621","pt":1580639192787,"mc":[{"id":"1.168135752","rc":[{"batl":[[0,1.2,3.79],[1,1.65,3.03]],"ltp":1.08,"tv":4538.71,"id":41364}]}]}
{"op":"mcm","clk":"1004937657","pt":1580639291802,"mc":[{"id":"1.168135752","rc":[{"trd":[[1.01,1.02]],"batl":[[0,1.01,587.49],[1,1.2,3.79],[2,1.65,3.03]],"ltp":1.01,"tv":4539.72,"id":41364}],"tv":5740.23}]}
{"op":"mcm","clk":"1004937727","pt":1580639292734,"mc":[{"id":"1.168135752","rc":[{"batl":[[0,1.01,651.85]],"ltp":1.01,"tv":4539.72,"id":41364}]}]}
{"op":"mcm","clk":"1004937927","pt":1580639294727,"mc":[{"id":"1.168135752","rc":[{"batl":[[0,1.01,587.49]],"ltp":1.01,"tv":4539.72,"id":41364}]}]}
{"op":"mcm","clk":"1005003479","pt":1580639967623,"mc":[{"id":"1.168135752","rc":[{"trd":[[1.01,4.38]],"batl":[[0,1.01,585.81]],"ltp":1.01,"tv":4543.08,"id":41364}],"tv":5743.59}]}
{"op":"mcm","clk":"1005080582","pt":1580640597782,"mc":[{"id":"1.168135752","rc":[{"trd":[[1.01,6.78]],"batl":[[0,1.01,584.61]],"ltp":1.01,"tv":4545.49,"id":41364}],"tv":5745.99}]}
{"op":"mcm","clk":"1005192179","pt":1580641396720,"mc":[{"id":"1.168135752","rc":[{"batl":[[0,1.2,3.79],[1,1.65,3.03],[2,1.65,0]],"ltp":1.01,"tv":4545.49,"id":41364}]}]}
{"op":"mcm","clk":"1005192786","pt":1580641399810,"mc":[{"id":"1.168135752","rc":[{"batl":[[0,1.19,584.61],[1,1.2,3.79],[2,1.65,3.03]],"ltp":1.01,"tv":4545.49,"id":41364}]}]}
{"op":"mcm","clk":"1005197105","pt":1580641420751,"mc":[{"id":"1.168135752","rc":[{"batb":[[2,1.01,2.51]],"ltp":2.24,"tv":1200.5,"id":41365}]}]}
{"op":"mcm","clk":"1005197300","pt":1580641421759,"mc":[{"id":"1.168135752","rc":[{"batb":[[2,1.01,0.51]],"ltp":2.24,"tv":1200.5,"id":41365}]}]}
{"op":"mcm","clk":"1005197898","pt":1580641424670,"mc":[{"id":"1.168135752","rc":[{"batb":[[0,1.49,2],[1,1.48,68.15],[2,1.2,28.77]],"ltp":2.24,"tv":1200.5,"id":41365}]}]}
{"op":"mcm","clk":"1005200441","pt":1580641436792,"mc":[{"id":"1.168135752","rc":[{"batl":[[0,1.2,3.79],[1,1.65,3.03],[2,1.65,0]],"ltp":1.01,"tv":4545.49,"id":41364}]}]}
{"op":"mcm","clk":"1005201065","pt":1580641439770,"mc":[{"id":"1.168135752","rc":[{"batl":[[0,1.2,588.4]],"ltp":1.01,"tv":4545.49,"id":41364}]}]}
{"op":"mcm","clk":"1005215011","pt":1580641509794,"mc":[{"id":"1.168135752","rc":[{"batb":[[0,8,22.72],[1,1.49,2],[2,1.48,68.15]],"ltp":2.24,"tv":1200.5,"id":41365}]}]}
{"op":"mcm","clk":"1005326512","pt":1580642091747,"mc":[{"id":"1.168135752","marketDefinition":{"bspMarket":false,"turnInPlayEnabled":true,"persistenceEnabled":true,"marketBaseRate":5.0,"eventId":"29678823","eventTypeId":"2","numberOfWinners":1,"bettingType":"ODDS","marketType":"PLAYER_A_WIN_A_SET","marketTime":"2020-02-02T08:30:00.000Z","suspendTime":"2020-02-02T08:30:00.000Z","bspReconciled":false,"complete":true,"inPlay":true,"crossMatching":true,"runnersVoidable":false,"numberOfActiveRunners":2,"betDelay":3,"status":"SUSPENDED","runners":[{"status":"ACTIVE","sortPriority":1,"id":41364,"name":"Yes"},{"status":"ACTIVE","sortPriority":2,"id":41365,"name":"No"}],"regulators":["MR_INT"],"countryCode":"AU","discountAllowed":true,"timezone":"GMT","openDate":"2020-02-02T08:30:00.000Z","version":3148512799,"name":"Thiem To Win A Set?","eventName":"Thiem v Djokovic"}}]}
{"op":"mcm","clk":"1005332737","pt":1580642125820,"mc":[{"id":"1.168135752","tv":0.0}]}
{"op":"mcm","clk":"1005332900","pt":1580642126720,"mc":[{"id":"1.168135752","marketDefinition":{"bspMarket":false,"turnInPlayEnabled":true,"persistenceEnabled":true,"marketBaseRate":5.0,"eventId":"29678823","eventTypeId":"2","numberOfWinners":1,"bettingType":"ODDS","marketType":"PLAYER_A_WIN_A_SET","marketTime":"2020-02-02T08:30:00.000Z","suspendTime":"2020-02-02T08:30:00.000Z","bspReconciled":false,"complete":true,"inPlay":true,"crossMatching":false,"runnersVoidable":false,"numberOfActiveRunners":0,"betDelay":3,"status":"CLOSED","settledTime":"2020-02-02T11:15:20.000Z","runners":[{"status":"WINNER","sortPriority":1,"id":41364,"name":"Yes"},{"status":"LOSER","sortPriority":2,"id":41365,"name":"No"}],"regulators":["MR_INT"],"countryCode":"AU","discountAllowed":true,"timezone":"GMT","openDate":"2020-02-02T08:30:00.000Z","version":3148513199,"name":"Thiem To Win A Set?","eventName":"Thiem v Djokovic"}}]}
