{"op":"mcm","clk":"988026418","pt":1580473742115,"mc":[{"id":"1.168135750","marketDefinition":{"bspMarket":false,"turnInPlayEnabled":true,"persistenceEnabled":true,"marketBaseRate":5.0,"eventId":"29678823","eventTypeId":"2","numberOfWinners":1,"bettingType":"ODDS","marketType":"SET_CORRECT_SCORE","marketTime":"2020-02-02T08:30:00.000Z","suspendTime":"2020-02-02T08:30:00.000Z","bspReconciled":false,"complete":true,"inPlay":false,"crossMatching":false,"runnersVoidable":false,"numberOfActiveRunners":14,"betDelay":0,"status":"OPEN","runners":[{"status":"ACTIVE","sortPriority":1,"id":5720737,"name":"Thiem 6 - 0"},{"status":"ACTIVE","sortPriority":2,"id":5720739,"name":"Thiem 6 - 1"},{"status":"ACTIVE","sortPriority":3,"id":5720734,"name":"Thiem 6 - 2"},{"status":"ACTIVE","sortPriority":4,"id":5720735,"name":"Thiem 6 - 3"},{"status":"ACTIVE","sortPriority":5,"id":5720732,"name":"Thiem 6 - 4"},{"status":"ACTIVE","sortPriority":6,"id":5720736,"name":"Thiem 7 - 5"},{"status":"ACTIVE","sortPriority":7,"id":5720738,"name":"Thiem 7 - 6"},{"status":"ACTIVE","sortPriority":8,"id":2764717,"name":"Djokovic 6 - 0"},{"status":"ACTIVE","sortPriority":9,"id":2764710,"name":"Djokovic 6 - 1"},{"status":"ACTIVE","sortPriority":10,"id":2764714,"name":"Djokovic 6 - 2"},{"status":"ACTIVE","sortPriority":11,"id":2764711,"name":"Djokovic 6 - 3"},{"status":"ACTIVE","sortPriority":12,"id":2764720,"name":"Djokovic 6 - 4"},{"status":"ACTIVE","sortPriority":13,"id":2764715,"name":"Djokovic 7 - 5"},{"status":"ACTIVE","sortPriority":14,"id":2764722,"name":"Djokovic 7 - 6"}],"regulators":["MR_INT"],"countryCode":"AU","discountAllowed":false,"timezone":"GMT","openDate":"2020-02-02T08:30:00.000Z","version":3143005236,"name":"Set 1 - Correct Score","eventName":"Thiem v Djokovic"}}]}
{"op":"mcm","clk":"988026715","pt":1580473744836,"mc":[{"id":"1.168135750","marketDefinition":{"bspMarket":false,"turnInPlayEnabled":true,"persistenceEnabled":true,"marketBaseRate":5.0,"eventId":"29678823","eventTypeId":"2","numberOfWinners":1,"bettingType":"ODDS","marketType":"SET_CORRECT_SCORE","marketTime":"2020-02-02T08:30:00.000Z","suspendTime":"2020-02-02T08:30:00.000Z","bspReconciled":false,"complete":true,"inPlay":false,"crossMatching":false,"runnersVoidable":false,"numberOfActiveRunners":14,"betDelay":0,"status":"OPEN","runners":[{"status":"ACTIVE","sortPriority":1,"id":5720737,"name":"Thiem 6 - 0"},{"status":"ACTIVE","sortPriority":2,"id":5720739,"name":"Thiem 6 - 1"},{"status":"ACTIVE","sortPriority":3,"id":5720734,"name":"Thiem 6 - 2"},{"status":"ACTIVE","sortPriority":4,"id":5720735,"name":"Thiem 6 - 3"},{"status":"ACTIVE","sortPriority":5,"id":5720732,"name":"Thiem 6 - 4"},{"status":"ACTIVE","sortPriority":6,"id":5720736,"name":"Thiem 7 - 5"},{"status":"ACTIVE","sortPriority":7,"id":5720738,"name":"Thiem 7 - 6"},{"status":"ACTIVE","sortPriority":8,"id":2764717,"name":"Djokovic 6 - 0"},{"status":"ACTIVE","sortPriority":9,"id":2764710,"name":"Djokovic 6 - 1"},{"status":"ACTIVE","sortPriority":10,"id":2764714,"name":"Djokovic 6 - 2"},{"status":"ACTIVE","sortPriority":11,"id":2764711,"name":"Djokovic 6 - 3"},{"status":"ACTIVE","sortPriority":12,"id":2764720,"name":"Djokovic 6 - 4"},{"status":"ACTIVE","sortPriority":13,"id":2764715,"name":"Djokovic 7 - 5"},{"status":"ACTIVE","sortPriority":14,"id":2764722,"name":"Djokovic 7 - 6"}],"regulators":["MR_INT"],"countryCode":"AU","discountAllowed":true,"timezone":"GMT","openDate":"2020-02-02T08:30:00.000Z","version":3143005236,"name":"Set 1 - Correct Score","eventName":"Thiem v Djokovic"}}]}
{"op":"mcm","clk":"988156516","pt":1580474901484,"mc":[{"id":"1.168135750","rc":[{"batl":[[0,7,50.98]],"ltp":0.0,"tv":0.0,"id":2764711}]}]}
{"op":"mcm","clk":"988156980","pt":1580474906171,"mc":[{"id":"1.168135750","rc":[{"batl":[[0,32,10.71]],"ltp":0.0,"tv":0.0,"id":2764710}]}]}
{"op":"mcm","clk":"988157472","pt":1580474911494,"mc":[{"id":"1.168135750","rc":[{"batl":[[0,12,28.04]],"ltp":0.0,"tv":0.0,"id":5720732}]}]}
{"op":"mcm","clk":"988171615","pt":1580475016752,"mc":[{"id":"1.168135750","rc":[{"batb":[[0,3,108.09]],"ltp":0.0,"tv":0.0,"id":2764711}]}]}
{"op":"mcm","clk":"988183003","pt":1580475148201,"mc":[{"id":"1.168135750","rc":[{"batl":[[0,15,10.71]],"ltp":0.0,"tv":0.0,"id":2764722}]}]}
{"op":"mcm","clk":"988191713","pt":1580475153687,"mc":[{"id":"1.168135750","rc":[{"batl":[[0,25,10.71]],"ltp":0.0,"tv":0.0,"id":5720738}]}]}
{"op":"mcm","clk":"988192337","pt":1580475160516,"mc":[{"id":"1.168135750","rc":[{"batb":[[0,2.5,101.97]],"ltp":0.0,"tv":0.0,"id":5720737}]}]}
{"op":"mcm","clk":"988193008","pt":1580475168142,"mc":[{"id":"1.168135750","rc":[{"batb":[[0,1.6,112.16]],"ltp":0.0,"tv":0.0,"id":2764717}]}]}
{"op":"mcm","clk":"988225025","pt":1580475557850,"mc":[{"id":"1.168135750","rc":[{"batb":[[0,4,61.69]],"ltp":0.0,"tv":0.0,"id":2764720}]}]}
{"op":"mcm","clk":"988337204","pt":1580476468825,"mc":[{"id":"1.168135750","rc":[{"batb":[[0,10,100]],"ltp":0.0,"tv":0.0,"id":2764710},{"batb":[[0,3.5,285.71],[1,3,108.09]],"ltp":0.0,"tv":0.0,"id":2764711},{"batb":[[0,5,200],[1,4,61.69]],"ltp":0.0,"tv":0.0,"id":2764720},{"batb":[[0,60,16.67]],"ltp":0.0,"tv":0.0,"id":5720739},{"batb":[[0,9,111.11]],"ltp":0.0,"tv":0.0,"id":2764714},{"batb":[[0,6,166.67]],"ltp":0.0,"tv":0.0,"id":5720738},{"batb":[[0,10,100]],"ltp":0.0,"tv":0.0,"id":2764715},{"batb":[[0,34,29.41],[1,1.6,112.16]],"ltp":0.0,"tv":0.0,"id":2764717},{"batb":[[0,12,83.33]],"ltp":0.0,"tv":0.0,"id":5720735},{"batb":[[0,21,47.62]],"ltp":0.0,"tv":0.0,"id":5720734},{"batb":[[0,100,10],[1,2.5,101.97]],"ltp":0.0,"tv":0.0,"id":5720737},{"batb":[[0,17,58.82]],"ltp":0.0,"tv":0.0,"id":5720736},{"batb":[[0,5.5,181.82]],"ltp":0.0,"tv":0.0,"id":2764722},{"batb":[[0,7,142.86]],"ltp":0.0,"tv":0.0,"id":5720732}]}]}
{"op":"mcm","clk":"988341550","pt":1580476508348,"mc":[{"id":"1.168135750","rc":[{"batl":[[0,20,53],[1,32,10.71]],"ltp":0.0,"tv":0.0,"id":2764710},{"batl":[[0,4.8,563],[1,7,50.98]],"ltp":0.0,"tv":0.0,"id":2764711},{"batl":[[0,50,53]],"ltp":0.0,"tv":0.0,"id":5720734},{"batl":[[0,9,483],[1,12,28.04]],"ltp":0.0,"tv":0.0,"id":5720732}]}]}
{"op":"mcm","clk":"988342343","pt":1580476515361,"mc":[{"id":"1.168135750","rc":[{"batb":[[0,6.6,142.86]],"ltp":0.0,"tv":0.0,"id":5720732}]}]}
{"op":"mcm","clk":"988355740","pt":1580476628837,"mc":[{"id":"1.168135750","rc":[{"batb":[[0,4,50.98],[1,3.5,285.71],[2,3,108.09]],"ltp":0.0,"tv":0.0,"id":2764711}]}]}
{"op":"mcm","clk":"988403541","pt":1580476974552,"mc":[{"id":"1.168135750","rc":[{"batl":[[0,4.7,300],[1,4.8,563],[2,7,50.98]],"ltp":0.0,"tv":0.0,"id":2764711}]}]}
{"op":"mcm","clk":"988411995","pt":1580477048054,"mc":[{"id":"1.168135750","rc":[{"batl":[[1,5,563]],"ltp":0.0,"tv":0.0,"id":2764711}]}]}
{"op":"mcm","clk":"988413056","pt":1580477057101,"mc":[{"id":"1.168135750","rc":[{"trd":[[4.7,241.41]],"batl":[[0,4.7,179.2]],"ltp":4.7,"tv":241.4,"id":2764711}],"tv":241.4}]}
{"op":"mcm","clk":"988437143","pt":1580477259535,"mc":[{"id":"1.168135750","rc":[{"trd":[[4.7,343.46]],"batl":[[0,4.7,128.13]],"ltp":4.7,"tv":343.46,"id":2764711}],"tv":343.46}]}
{"op":"mcm","clk":"988438295","pt":1580477269059,"mc":[{"id":"1.168135750","rc":[{"batb":[[0,4,28.04]],"ltp":4.7,"tv":343.46,"id":2764711}]}]}
{"op":"mcm","clk":"988452629","pt":1580477399871,"mc":[{"id":"1.168135750","rc":[{"trd":[[4.7,384.29]],"batl":[[0,4.7,107.7]],"ltp":4.7,"tv":384.28,"id":2764711}],"tv":384.28}]}
{"op":"mcm","clk":"988453252","pt":1580477405309,"mc":[{"id":"1.168135750","rc":[{"batb":[[0,4,6.12]],"ltp":4.7,"tv":384.28,"id":2764711}]}]}
{"op":"mcm","clk":"988454189","pt":1580477414012,"mc":[{"id":"1.168135750","rc":[{"batb":[[0,11,10.71],[1,9,111.11]],"ltp":0.0,"tv":0.0,"id":2764714}]}]}
{"op":"mcm","clk":"988458127","pt":1580477450038,"mc":[{"id":"1.168135750","rc":[{"batl":[[0,4.7,457.7]],"ltp":4.7,"tv":384.28,"id":2764711}]}]}
{"op":"mcm","clk":"988458431","pt":1580477452688,"mc":[{"id":"1.168135750","rc":[{"batl":[[1,4.8,563],[2,5,563]],"ltp":4.7,"tv":384.28,"id":2764711}]}]}
{"op":"mcm","clk":"988522164","pt":1580477963442,"mc":[{"id":"1.168135750","rc":[{"trd":[[4.7,405.15]],"batl":[[0,4.7,447.27]],"ltp":4.7,"tv":405.14,"id":2764711}],"tv":405.14}]}
{"op":"mcm","clk":"988557375","pt":1580478294384,"mc":[{"id":"1.168135750","rc":[{"trd":[[9,6.7]],"batl":[[0,9,479.65]],"ltp":9.0,"tv":6.7,"id":5720732}],"tv":411.84}]}
{"op":"mcm","clk":"988627719","pt":1580479043666,"mc":[{"id":"1.168135750","rc":[{"batl":[[0,8.8,70],[1,9,479.65],[2,12,28.04]],"ltp":9.0,"tv":6.7,"id":5720732}]}]}
{"op":"mcm","clk":"988628954","pt":1580479062373,"mc":[{"id":"1.168135750","rc":[{"batl":[[0,4.6,200],[1,4.7,447.27],[2,4.8,563]],"ltp":4.7,"tv":405.14,"id":2764711}]}]}
{"op":"mcm","clk":"988629035","pt":1580479063667,"mc":[{"id":"1.168135750","marketDefinition":{"bspMarket":false,"turnInPlayEnabled":true,"persistenceEnabled":true,"marketBaseRate":5.0,"eventId":"29678823","eventTypeId":"2","numberOfWinners":1,"bettingType":"ODDS","marketType":"SET_CORRECT_SCORE","marketTime":"2020-02-02T08:30:00.000Z","suspendTime":"2020-02-02T08:30:00.000Z","bspReconciled":false,"complete":true,"inPlay":false,"crossMatching":true,"runnersVoidable":false,"numberOfActiveRunners":14,"betDelay":0,"status":"OPEN","runners":[{"status":"ACTIVE","sortPriority":1,"id":5720737,"name":"Thiem 6 - 0"},{"status":"ACTIVE","sortPriority":2,"id":5720739,"name":"Thiem 6 - 1"},{"status":"ACTIVE","sortPriority":3,"id":5720734,"name":"Thiem 6 - 2"},{"status":"ACTIVE","sortPriority":4,"id":5720735,"name":"Thiem 6 - 3"},{"status":"ACTIVE","sortPriority":5,"id":5720732,"name":"Thiem 6 - 4"},{"status":"ACTIVE","sortPriority":6,"id":5720736,"name":"Thiem 7 - 5"},{"status":"ACTIVE","sortPriority":7,"id":5720738,"name":"Thiem 7 - 6"},{"status":"ACTIVE","sortPriority":8,"id":2764717,"name":"Djokovic 6 - 0"},{"status":"ACTIVE","sortPriority":9,"id":2764710,"name":"Djokovic 6 - 1"},{"status":"ACTIVE","sortPriority":10,"id":2764714,"name":"Djokovic 6 - 2"},{"status":"ACTIVE","sortPriority":11,"id":2764711,"name":"Djokovic 6 - 3"},{"status":"ACTIVE","sortPriority":12,"id":2764720,"name":"Djokovic 6 - 4"},{"status":"ACTIVE","sortPriority":13,"id":2764715,"name":"Djokovic 7 - 5"},{"status":"ACTIVE","sortPriority":14,"id":2764722,"name":"Djokovic 7 - 6"}],"regulators":["MR_INT"],"countryCode":"AU","discountAllowed":true,"timezone":"GMT","openDate":"2020-02-02T08:30:00.000Z","version":3143005236,"name":"Set 1 - Correct Score","eventName":"Thiem v Djokovic"}}]}
{"op":"mcm","clk":"988687353","pt":1580479652167,"mc":[{"id":"1.168135750","rc":[{"batl":[[1,32,10.71]],"ltp":0.0,"tv":0.0,"id":2764710},{"trd":[[4.7,405.19]],"batb":[[0,4,6.12],[2,3,108.11]],"ltp":4.7,"tv":405.19,"id":2764711},{"batb":[[1,4,61.71]],"ltp":0.0,"tv":0.0,"id":2764720},{"batb":[[0,11,10.71]],"ltp":0.0,"tv":0.0,"id":2764714},{"batl":[[0,25,10.71]],"ltp":0.0,"tv":0.0,"id":5720738},{"batb":[[1,1.6,112.19]],"ltp":0.0,"tv":0.0,"id":2764717},{"batb":[[1,2.5,101.99]],"ltp":0.0,"tv":0.0,"id":5720737},{"batl":[[0,15,10.71]],"ltp":0.0,"tv":0.0,"id":2764722},{"batl":[[2,12,28.05]],"ltp":9.0,"tv":6.7,"id":5720732}],"tv":411.89}]}
{"op":"mcm","clk":"988731395","pt":1580480158154,"mc":[{"id":"1.168135750","rc":[{"trd":[[8.8,16]],"batl":[[0,8.8,62]],"ltp":8.8,"tv":22.7,"id":5720732}],"tv":427.89}]}
{"op":"mcm","clk":"988739437","pt":1580480244741,"mc":[{"id":"1.168135750","rc":[{"trd":[[8.8,22.86]],"batl":[[0,8.8,58.57]],"ltp":8.8,"tv":29.56,"id":5720732}],"tv":434.75}]}
{"op":"mcm","clk":"988753209","pt":1580480389369,"mc":[{"id":"1.168135750","rc":[{"batb":[[0,4.1,12.17],[1,4,6.12],[2,3.5,285.71]],"ltp":4.7,"tv":405.19,"id":2764711}]}]}
{"op":"mcm","clk":"988798975","pt":1580480799835,"mc":[{"id":"1.168135750","rc":[{"batl":[[0,8.8,50]],"ltp":8.8,"tv":29.56,"id":5720732}]}]}
{"op":"mcm","clk":"988800206","pt":1580480816649,"mc":[{"id":"1.168135750","rc":[{"batl":[[0,15,15],[1,20,53],[2,32,10.71]],"ltp":0.0,"tv":0.0,"id":2764710}]}]}
{"op":"mcm","clk":"988801355","pt":1580480831277,"mc":[{"id":"1.168135750","rc":[{"batl":[[0,4.6,210]],"ltp":4.7,"tv":405.19,"id":2764711}]}]}
{"op":"mcm","clk":"988815476","pt":1580481006643,"mc":[{"id":"1.168135750","rc":[{"batb":[[1,3.5,285.71],[2,3,108.11]],"ltp":4.7,"tv":405.19,"id":2764711},{"batb":[[1,4,0]],"ltp":0.0,"tv":0.0,"id":2764720}]}]}
{"op":"mcm","clk":"988905710","pt":1580481914460,"mc":[{"id":"1.168135750","rc":[{"batb":[[0,10.5,3.04],[1,10,100]],"ltp":0.0,"tv":0.0,"id":2764710}]}]}
{"op":"mcm","clk":"988909195","pt":1580481958028,"mc":[{"id":"1.168135750","rc":[{"batb":[[0,6.4,5.33],[1,6,166.67]],"ltp":0.0,"tv":0.0,"id":5720738}]}]}
{"op":"mcm","clk":"988958254","pt":1580482598032,"mc":[{"id":"1.168135750","rc":[{"trd":[[15,18.4]],"batl":[[0,15,5.8]],"ltp":15.0,"tv":18.4,"id":2764710}],"tv":453.15}]}
{"op":"mcm","clk":"988965630","pt":1580482718103,"mc":[{"id":"1.168135750","rc":[{"trd":[[15,26.92]],"batl":[[0,15,1.54]],"ltp":15.0,"tv":26.92,"id":2764710}],"tv":461.67}]}
{"op":"mcm","clk":"988993128","pt":1580483067987,"mc":[{"id":"1.168135750","rc":[{"batb":[[0,6.8,5.33],[1,5,200]],"ltp":0.0,"tv":0.0,"id":2764720}]}]}
{"op":"mcm","clk":"989142985","pt":1580484809087,"mc":[{"id":"1.168135750","rc":[{"batb":[[0,7.4,5.33],[1,6.6,142.86]],"ltp":8.8,"tv":29.56,"id":5720732}]}]}
{"op":"mcm","clk":"989154920","pt":1580484965238,"mc":[{"id":"1.168135750","rc":[{"trd":[[4.6,15.44]],"batl":[[0,4.6,202.28]],"ltp":4.6,"tv":420.63,"id":2764711}],"tv":477.11}]}
{"op":"mcm","clk":"989187029","pt":1580485243004,"mc":[{"id":"1.168135750","rc":[{"trd":[[8.8,29.72]],"batl":[[0,8.8,46.57]],"ltp":8.8,"tv":36.42,"id":5720732}],"tv":483.97}]}
{"op":"mcm","clk":"989240529","pt":1580485939427,"mc":[{"id":"1.168135750","rc":[{"trd":[[4.6,35.83]],"batl":[[0,4.6,192.09]],"ltp":4.6,"tv":441.02,"id":2764711}],"tv":504.36}]}
{"op":"mcm","clk":"989340032","pt":1580486852178,"mc":[{"id":"1.168135750","rc":[{"batb":[[0,10.5,3.03]],"batl":[[2,32,10.67]],"ltp":15.0,"tv":26.92,"id":2764710},{"trd":[[4.6,35.79],[4.7,404.44]],"batb":[[0,4.1,12.14],[2,3,107.69]],"ltp":4.6,"tv":440.23,"id":2764711},{"batb":[[0,6.8,5.31]],"ltp":0.0,"tv":0.0,"id":2764720},{"batb":[[0,11,10.67]],"ltp":0.0,"tv":0.0,"id":2764714},{"batb":[[0,6.4,5.31]],"batl":[[0,25,10.67]],"ltp":0.0,"tv":0.0,"id":5720738},{"batb":[[1,1.6,111.75]],"ltp":0.0,"tv":0.0,"id":2764717},{"batb":[[1,2.5,101.6]],"ltp":0.0,"tv":0.0,"id":5720737},{"batl":[[0,15,10.67]],"ltp":0.0,"tv":0.0,"id":2764722},{"batb":[[0,7.4,5.31]],"batl":[[2,12,27.94]],"ltp":8.8,"tv":36.42,"id":5720732}],"tv":503.57}]}
{"op":"mcm","clk":"989409066","pt":1580487562622,"mc":[{"id":"1.168135750","rc":[{"batb":[[0,4.3,8],[1,4.1,12.14],[2,3.5,285.71]],"ltp":4.6,"tv":440.23,"id":2764711}]}]}
{"op":"mcm","clk":"989424583","pt":1580487748765,"mc":[{"id":"1.168135750","rc":[{"batb":[[0,10.5,8.5],[1,10,100]],"ltp":0.0,"tv":0.0,"id":2764715}]}]}
{"op":"mcm","clk":"989486866","pt":1580488335248,"mc":[{"id":"1.168135750","rc":[{"batb":[[1,3.5,285.71],[2,3,107.69]],"ltp":4.6,"tv":440.23,"id":2764711}]}]}
{"op":"mcm","clk":"989589249","pt":1580489498535,"mc":[{"id":"1.168135750","rc":[{"batb":[[0,11,25.16],[1,10.5,3.03],[2,10,100]],"ltp":15.0,"tv":26.92,"id":2764710}]}]}
{"op":"mcm","clk":"989859411","pt":1580491958436,"mc":[{"id":"1.168135750","rc":[{"batb":[[0,3.5,285.71],[1,3,107.69],[2,3,0]],"ltp":4.6,"tv":440.23,"id":2764711},{"batb":[[0,10,100],[1,10,0]],"ltp":0.0,"tv":0.0,"id":2764715}]}]}
{"op":"mcm","clk":"989934285","pt":1580492516177,"mc":[{"id":"1.168135750","rc":[{"batb":[[0,3.85,11.38],[1,3.5,285.71],[2,3,107.69]],"ltp":4.6,"tv":440.23,"id":2764711}]}]}
{"op":"mcm","clk":"990083072","pt":1580494002141,"mc":[{"id":"1.168135750","rc":[{"batb":[[1,10.5,3.03]],"batl":[[2,32,10.66]],"ltp":15.0,"tv":26.92,"id":2764710},{"trd":[[4.6,35.78],[4.7,404.26]],"batb":[[0,3.85,11.37],[1,3.55,3.52],[2,3.5,285.71]],"ltp":4.6,"tv":440.03,"id":2764711},{"batb":[[0,6.8,5.3]],"ltp":0.0,"tv":0.0,"id":2764720},{"batb":[[0,11,10.66]],"ltp":0.0,"tv":0.0,"id":2764714},{"batb":[[0,6.4,5.3]],"batl":[[0,25,10.66]],"ltp":0.0,"tv":0.0,"id":5720738},{"batb":[[1,1.6,111.65]],"ltp":0.0,"tv":0.0,"id":2764717},{"batb":[[1,2.5,101.5]],"ltp":0.0,"tv":0.0,"id":5720737},{"batl":[[0,15,10.66]],"ltp":0.0,"tv":0.0,"id":2764722},{"batb":[[0,7.4,5.3]],"batl":[[2,12,27.91]],"ltp":8.8,"tv":36.42,"id":5720732}],"tv":503.37}]}
{"op":"mcm","clk":"990325653","pt":1580496202763,"mc":[{"id":"1.168135750","rc":[{"trd":[[8.8,46.3]],"batl":[[0,8.8,38.28]],"ltp":8.8,"tv":53.0,"id":5720732}],"tv":519.95}]}
{"op":"mcm","clk":"990340066","pt":1580496357966,"mc":[{"id":"1.168135750","rc":[{"batb":[[0,8.6,8.45],[1,7.4,5.3],[2,6.6,142.86]],"ltp":8.8,"tv":53.0,"id":5720732}]}]}
{"op":"mcm","clk":"990362372","pt":1580496615173,"mc":[{"id":"1.168135750","rc":[{"trd":[[8.8,53.48]],"batl":[[0,8.8,34.69]],"ltp":8.8,"tv":60.18,"id":5720732}],"tv":527.13}]}
{"op":"mcm","clk":"990373606","pt":1580496722109,"mc":[{"id":"1.168135750","rc":[{"trd":[[8.8,60.62]],"batl":[[0,8.8,31.12]],"ltp":8.8,"tv":67.32,"id":5720732}],"tv":534.27}]}
{"op":"mcm","clk":"990393298","pt":1580496810960,"mc":[{"id":"1.168135750","rc":[{"batb":[[0,8.6,12.09]],"ltp":8.8,"tv":67.32,"id":5720732}]}]}
{"op":"mcm","clk":"991045160","pt":1580501252131,"mc":[{"id":"1.168135750","rc":[{"batb":[[1,10.5,3.03]],"batl":[[2,32,10.65]],"ltp":15.0,"tv":26.92,"id":2764710},{"trd":[[4.6,35.77],[4.7,404.16]],"batb":[[0,3.85,11.36],[1,3.55,3.51]],"ltp":4.6,"tv":439.93,"id":2764711},{"batb":[[0,6.8,5.3]],"ltp":0.0,"tv":0.0,"id":2764720},{"batb":[[0,11,10.65]],"ltp":0.0,"tv":0.0,"id":2764714},{"batb":[[0,6.4,5.3]],"batl":[[0,25,10.65]],"ltp":0.0,"tv":0.0,"id":5720738},{"batb":[[1,1.6,111.59]],"ltp":0.0,"tv":0.0,"id":2764717},{"batb":[[1,2.5,101.45]],"ltp":0.0,"tv":0.0,"id":5720737},{"batl":[[0,15,10.65]],"ltp":0.0,"tv":0.0,"id":2764722},{"batb":[[1,7.4,5.3]],"batl":[[2,12,27.9]],"ltp":8.8,"tv":67.32,"id":5720732}],"tv":534.17}]}
{"op":"mcm","clk":"991060824","pt":1580501335789,"mc":[{"id":"1.168135750","rc":[{"trd":[[8.8,100.62]],"batl":[[0,8.8,11.12]],"ltp":8.8,"tv":107.32,"id":5720732}],"tv":574.17}]}
{"op":"mcm","clk":"991318859","pt":1580502992370,"mc":[{"id":"1.168135750","rc":[{"batb":[[0,14,5.1],[1,11,25.16],[2,10.5,3.03]],"ltp":15.0,"tv":26.92,"id":2764710}]}]}
{"op":"mcm","clk":"991319966","pt":1580503000007,"mc":[{"id":"1.168135750","rc":[{"trd":[[4.6,103.74]],"batl":[[0,4.6,158.11]],"ltp":4.6,"tv":507.9,"id":2764711}],"tv":642.14}]}
{"op":"mcm","clk":"991325999","pt":1580503042534,"mc":[{"id":"1.168135750","rc":[{"batb":[[0,11,25.16],[1,10.5,3.03],[2,10,100]],"ltp":15.0,"tv":26.92,"id":2764710}]}]}
{"op":"mcm","clk":"991339134","pt":1580503068383,"mc":[{"id":"1.168135750","rc":[{"trd":[[8.8,121.02]],"batl":[[0,9,480.57],[1,12,27.9],[2,12,0]],"ltp":8.8,"tv":127.72,"id":5720732}],"tv":662.54}]}
{"op":"mcm","clk":"991349061","pt":1580503137508,"mc":[{"id":"1.168135750","rc":[{"trd":[[8.8,122.86],[9,45.68]],"batl":[[0,9,460.16]],"ltp":9.0,"tv":168.54,"id":5720732}],"tv":703.36}]}
{"op":"mcm","clk":"991389138","pt":1580503456415,"mc":[{"id":"1.168135750","rc":[{"batl":[[0,4.5,393],[1,4.6,158.11],[2,4.7,447.27]],"ltp":4.6,"tv":507.9,"id":2764711}]}]}
{"op":"mcm","clk":"991429300","pt":1580503805525,"mc":[{"id":"1.168135750","rc":[{"trd":[[4.5,22.82]],"batl":[[0,4.5,381.59]],"ltp":4.5,"tv":530.72,"id":2764711}],"tv":726.18}]}
{"op":"mcm","clk":"991496232","pt":1580504511685,"mc":[{"id":"1.168135750","rc":[{"batb":[[1,3.5,285.71],[2,3,107.53]],"ltp":4.5,"tv":530.72,"id":2764711}]}]}
{"op":"mcm","clk":"991592424","pt":1580505630920,"mc":[{"id":"1.168135750","rc":[{"trd":[[4.5,38.44]],"batl":[[0,4.5,373.78]],"ltp":4.5,"tv":546.34,"id":2764711}],"tv":741.8}]}
{"op":"mcm","clk":"991600680","pt":1580505721472,"mc":[{"id":"1.168135750","rc":[{"trd":[[9,61.82]],"batl":[[0,9,452.09]],"ltp":9.0,"tv":184.68,"id":5720732}],"tv":757.94}]}
{"op":"mcm","clk":"991634028","pt":1580506035432,"mc":[{"id":"1.168135750","rc":[{"trd":[[9,68.78]],"batl":[[0,9,448.61]],"ltp":9.0,"tv":191.64,"id":5720732}],"tv":764.9}]}
{"op":"mcm","clk":"991635910","pt":1580506071385,"mc":[{"id":"1.168135750","rc":[{"batl":[[0,48,12.68],[1,50,53]],"ltp":0.0,"tv":0.0,"id":5720734}]}]}
{"op":"mcm","clk":"991644247","pt":1580506213947,"mc":[{"id":"1.168135750","rc":[{"trd":[[9,75.74]],"batl":[[0,9,445.13]],"ltp":9.0,"tv":198.6,"id":5720732}],"tv":771.86}]}
{"op":"mcm","clk":"991692143","pt":1580506785806,"mc":[{"id":"1.168135750","rc":[{"trd":[[4.5,69.89]],"batl":[[0,4.5,358.06]],"ltp":4.5,"tv":577.78,"id":2764711}],"tv":803.3}]}
{"op":"mcm","clk":"991772101","pt":1580507988383,"mc":[{"id":"1.168135750","rc":[{"trd":[[9,122.52]],"batl":[[0,9,421.74]],"ltp":9.0,"tv":245.38,"id":5720732}],"tv":850.08}]}
{"op":"mcm","clk":"991792731","pt":1580508336964,"mc":[{"id":"1.168135750","rc":[{"batl":[[2,32,10.64]],"ltp":15.0,"tv":26.92,"id":2764710},{"trd":[[4.5,85.65],[4.6,103.68],[4.7,403.89]],"batb":[[0,3.85,11.36],[2,3,107.38]],"batl":[[0,4.5,350.16]],"ltp":4.5,"tv":593.21,"id":2764711},{"batb":[[0,11,10.64]],"ltp":0.0,"tv":0.0,"id":2764714},{"batl":[[0,25,10.64]],"ltp":0.0,"tv":0.0,"id":5720738},{"batb":[[1,1.6,111.43]],"ltp":0.0,"tv":0.0,"id":2764717},{"batl":[[0,48,12.66]],"ltp":0.0,"tv":0.0,"id":5720734},{"batb":[[1,2.5,101.3]],"ltp":0.0,"tv":0.0,"id":5720737},{"batl":[[0,15,10.64]],"ltp":0.0,"tv":0.0,"id":2764722},{"batl":[[1,12,27.86]],"ltp":9.0,"tv":245.38,"id":5720732}],"tv":865.51}]}
{"op":"mcm","clk":"991816437","pt":1580508563654,"mc":[{"id":"1.168135750","rc":[{"trd":[[4.5,106.65]],"batl":[[0,4.5,339.66]],"ltp":4.5,"tv":614.21,"id":2764711}],"tv":886.51}]}
{"op":"mcm","clk":"991871858","pt":1580509425991,"mc":[{"id":"1.168135750","rc":[{"trd":[[9,138.66]],"batl":[[0,9,413.67]],"ltp":9.0,"tv":261.52,"id":5720732}],"tv":902.65}]}
{"op":"mcm","clk":"991879272","pt":1580509569923,"mc":[{"id":"1.168135750","rc":[{"trd":[[9,145.62]],"batl":[[0,9,410.19]],"ltp":9.0,"tv":268.48,"id":5720732}],"tv":909.61}]}
{"op":"mcm","clk":"991905149","pt":1580510146932,"mc":[{"id":"1.168135750","rc":[{"batl":[[0,4.4,8.4],[1,4.5,339.66],[2,4.6,158.11]],"ltp":4.5,"tv":614.21,"id":2764711},{"batl":[[0,8.8,8.4],[1,9,410.19],[2,12,27.86]],"ltp":9.0,"tv":268.48,"id":5720732}]}]}
{"op":"mcm","clk":"991991744","pt":1580511710728,"mc":[{"id":"1.168135750","rc":[{"batb":[[2,1.01,2.53]],"ltp":0.0,"tv":0.0,"id":2764720},{"batb":[[1,1.01,2.53]],"ltp":0.0,"tv":0.0,"id":5720739},{"batb":[[2,1.01,2.53]],"ltp":0.0,"tv":0.0,"id":2764714},{"batb":[[1,1.01,2.53]],"ltp":0.0,"tv":0.0,"id":2764715},{"batb":[[2,1.01,2.53]],"ltp":0.0,"tv":0.0,"id":5720738},{"batb":[[2,1.01,2.53]],"ltp":0.0,"tv":0.0,"id":2764717},{"batb":[[1,1.01,2.53]],"ltp":0.0,"tv":0.0,"id":5720735},{"batb":[[1,1.01,2.53]],"ltp":0.0,"tv":0.0,"id":5720734},{"batb":[[2,1.01,2.53]],"ltp":0.0,"tv":0.0,"id":5720737},{"batb":[[1,1.01,2.53]],"ltp":0.0,"tv":0.0,"id":5720736},{"batb":[[1,1.01,2.53]],"ltp":0.0,"tv":0.0,"id":2764722}]}]}
{"op":"mcm","clk":"991991785","pt":1580511711652,"mc":[{"id":"1.168135750","rc":[{"batb":[[2,1.01,0.51]],"ltp":0.0,"tv":0.0,"id":2764720},{"batb":[[1,1.01,0.51]],"ltp":0.0,"tv":0.0,"id":5720739},{"batb":[[2,1.01,0.51]],"ltp":0.0,"tv":0.0,"id":2764714},{"batb":[[1,1.01,0.51]],"ltp":0.0,"tv":0.0,"id":2764715},{"batb":[[2,1.01,0.51]],"ltp":0.0,"tv":0.0,"id":5720738},{"batb":[[2,1.01,0.51]],"ltp":0.0,"tv":0.0,"id":2764717},{"batb":[[1,1.01,0.51]],"ltp":0.0,"tv":0.0,"id":5720735},{"batb":[[1,1.01,0.51]],"ltp":0.0,"tv":0.0,"id":5720734},{"batb":[[2,1.01,0.51]],"ltp":0.0,"tv":0.0,"id":5720737},{"batb":[[1,1.01,0.51]],"ltp":0.0,"tv":0.0,"id":5720736},{"batb":[[1,1.01,0.51]],"ltp":0.0,"tv":0.0,"id":2764722}]}]}
{"op":"mcm","clk":"992004377","pt":1580511987459,"mc":[{"id":"1.168135750","rc":[{"batb":[[2,1.01,3.04]],"ltp":0.0,"tv":0.0,"id":2764720},{"batb":[[1,1.01,3.04]],"ltp":0.0,"tv":0.0,"id":5720739},{"batb":[[2,1.01,3.04]],"ltp":0.0,"tv":0.0,"id":2764714},{"batb":[[1,1.01,3.04]],"ltp":0.0,"tv":0.0,"id":2764715},{"batb":[[2,1.01,3.04]],"ltp":0.0,"tv":0.0,"id":5720738},{"batb":[[2,1.01,3.04]],"ltp":0.0,"tv":0.0,"id":2764717},{"batb":[[1,1.01,3.04]],"ltp":0.0,"tv":0.0,"id":5720735},{"batb":[[1,1.01,3.04]],"ltp":0.0,"tv":0.0,"id":5720734},{"batb":[[2,1.01,3.04]],"ltp":0.0,"tv":0.0,"id":5720737},{"batb":[[1,1.01,3.04]],"ltp":0.0,"tv":0.0,"id":5720736},{"batb":[[1,1.01,3.04]],"ltp":0.0,"tv":0.0,"id":2764722}]}]}
{"op":"mcm","clk":"992004431","pt":1580511988487,"mc":[{"id":"1.168135750","rc":[{"batb":[[2,1.01,1.01]],"ltp":0.0,"tv":0.0,"id":2764720},{"batb":[[1,1.01,1.01]],"ltp":0.0,"tv":0.0,"id":5720739},{"batb":[[2,1.01,1.01]],"ltp":0.0,"tv":0.0,"id":2764714},{"batb":[[1,1.01,1.01]],"ltp":0.0,"tv":0.0,"id":2764715},{"batb":[[2,1.01,1.01]],"ltp":0.0,"tv":0.0,"id":5720738},{"batb":[[2,1.01,1.01]],"ltp":0.0,"tv":0.0,"id":2764717},{"batb":[[1,1.01,1.01]],"ltp":0.0,"tv":0.0,"id":5720735},{"batb":[[1,1.01,1.01]],"ltp":0.0,"tv":0.0,"id":5720734},{"batb":[[2,1.01,1.01]],"ltp":0.0,"tv":0.0,"id":5720737},{"batb":[[1,1.01,1.01]],"ltp":0.0,"tv":0.0,"id":5720736},{"batb":[[1,1.01,1.01]],"ltp":0.0,"tv":0.0,"id":2764722}]}]}
{"op":"mcm","clk":"992035340","pt":1580512497227,"mc":[{"id":"1.168135750","rc":[{"trd":[[8.8,139.44]],"batl":[[0,9,410.3],[1,12,27.86],[2,12,0]],"ltp":8.8,"tv":285.06,"id":5720732}],"tv":926.19}]}
{"op":"mcm","clk":"992035379","pt":1580512498204,"mc":[{"id":"1.168135750","rc":[{"batl":[[0,9,410.19]],"ltp":8.8,"tv":285.06,"id":5720732}]}]}
{"op":"mcm","clk":"992045970","pt":1580512753736,"mc":[{"id":"1.168135750","rc":[{"trd":[[9,152.6]],"batl":[[0,9,406.7]],"ltp":9.0,"tv":292.04,"id":5720732}],"tv":933.17}]}
{"op":"mcm","clk":"992256638","pt":1580517739170,"mc":[{"id":"1.168135750","rc":[{"trd":[[4.4,16.79],[4.5,196.28]],"batl":[[0,4.5,294.82],[1,4.6,158.11],[2,4.7,447.27]],"ltp":4.5,"tv":720.64,"id":2764711}],"tv":1039.6}]}
{"op":"mcm","clk":"992257666","pt":1580517784504,"mc":[{"id":"1.168135750","rc":[{"trd":[[4.5,249.49]],"batl":[[0,4.5,268.2]],"ltp":4.5,"tv":773.85,"id":2764711}],"tv":1092.81}]}
{"op":"mcm","clk":"992259404","pt":1580517850211,"mc":[{"id":"1.168135750","rc":[{"trd":[[4.5,270.78]],"batl":[[0,4.5,257.55]],"ltp":4.5,"tv":795.13,"id":2764711}],"tv":1114.1}]}
{"op":"mcm","clk":"992411863","pt":1580522061381,"mc":[{"id":"1.168135750","rc":[{"batb":[[1,10,100],[2,1.01,1.01]],"ltp":15.0,"tv":26.92,"id":2764710},{"batb":[[0,3.55,10.41]],"ltp":4.5,"tv":795.13,"id":2764711},{"batb":[[0,5,200],[1,1.01,1.01],[2,1.01,0]],"ltp":0.0,"tv":0.0,"id":2764720},{"batb":[[0,6,166.67],[1,1.01,1.01],[2,1.01,0]],"ltp":0.0,"tv":0.0,"id":5720738},{"batb":[[1,6.6,142.86],[2,1.01,1.01]],"ltp":9.0,"tv":292.04,"id":5720732}]}]}
{"op":"mcm","clk":"992426620","pt":1580522591348,"mc":[{"id":"1.168135750","rc":[{"batb":[[0,3.7,53.18],[1,3.55,10.41],[2,3.5,285.71]],"ltp":4.5,"tv":795.13,"id":2764711}]}]}
{"op":"mcm","clk":"992522790","pt":1580524786148,"mc":[{"id":"1.168135750","rc":[{"batb":[[1,3.55,14.19]],"ltp":4.5,"tv":795.13,"id":2764711}]}]}
{"op":"mcm","clk":"992694064","pt":1580528808756,"mc":[{"id":"1.168135750","rc":[{"batb":[[0,60,17.22]],"ltp":0.0,"tv":0.0,"id":5720739},{"batb":[[0,100,10.33]],"ltp":0.0,"tv":0.0,"id":5720737}]}]}
{"op":"mcm","clk":"992694123","pt":1580528809584,"mc":[{"id":"1.168135750","rc":[{"batb":[[0,11.5,3.14],[1,11,25.16],[2,10,100]],"ltp":15.0,"tv":26.92,"id":2764710},{"batb":[[0,3.75,9.64],[1,3.7,53.18],[2,3.55,14.19]],"ltp":4.5,"tv":795.13,"id":2764711},{"batb":[[0,5.1,7.08],[1,5,200],[2,1.01,1.01]],"ltp":0.0,"tv":0.0,"id":2764720},{"batb":[[0,11.5,3.14],[1,11,10.64],[2,9,111.11]],"ltp":0.0,"tv":0.0,"id":2764714},{"batb":[[0,10.5,3.44],[1,10,100],[2,1.01,1.01]],"ltp":0.0,"tv":0.0,"id":2764715},{"batb":[[0,6.2,5.83],[1,6,166.67],[2,1.01,1.01]],"ltp":0.0,"tv":0.0,"id":5720738},{"batb":[[0,36,1],[1,34,29.41],[2,1.6,111.43]],"ltp":0.0,"tv":0.0,"id":2764717},{"batb":[[0,12.5,2.89],[1,12,83.33],[2,1.01,1.01]],"ltp":0.0,"tv":0.0,"id":5720735},{"batb":[[0,22,1.64],[1,21,47.62],[2,1.01,1.01]],"ltp":0.0,"tv":0.0,"id":5720734},{"batb":[[0,17.5,2.07],[1,17,58.82],[2,1.01,1.01]],"ltp":0.0,"tv":0.0,"id":5720736},{"batb":[[0,5.6,6.45],[1,5.5,181.82],[2,1.01,1.01]],"ltp":0.0,"tv":0.0,"id":2764722},{"batb":[[0,8.6,16.29]],"ltp":9.0,"tv":292.04,"id":5720732}]}]}
{"op":"mcm","clk":"992733801","pt":1580529609756,"mc":[{"id":"1.168135750","rc":[{"trd":[[4.5,322.03]],"batl":[[0,4.5,231.91]],"ltp":4.5,"tv":846.38,"id":2764711}],"tv":1165.35}]}
{"op":"mcm","clk":"992866709","pt":1580532122851,"mc":[{"id":"1.168135750","rc":[{"trd":[[4.5,428.45]],"batl":[[0,4.5,178.67]],"ltp":4.5,"tv":952.81,"id":2764711}],"tv":1271.77}]}
{"op":"mcm","clk":"992919673","pt":1580533179534,"mc":[{"id":"1.168135750","rc":[{"batb":[[1,10,100],[2,1.01,1.01]],"ltp":15.0,"tv":26.92,"id":2764710}]}]}
{"op":"mcm","clk":"992937870","pt":1580533585887,"mc":[{"id":"1.168135750","rc":[{"batb":[[0,3.85,11.36],[1,3.75,9.64],[2,3.7,53.18]],"ltp":4.5,"tv":952.81,"id":2764711}]}]}
{"op":"mcm","clk":"992938058","pt":1580533589904,"mc":[{"id":"1.168135750","rc":[{"batb":[[1,3.7,53.18],[2,3.55,14.19]],"ltp":4.5,"tv":952.81,"id":2764711}]}]}
{"op":"mcm","clk":"992939037","pt":1580533613327,"mc":[{"id":"1.168135750","rc":[{"batb":[[0,3.9,9.27],[1,3.85,11.36],[2,3.7,53.18]],"ltp":4.5,"tv":952.81,"id":2764711}]}]}
{"op":"mcm","clk":"993030709","pt":1580535341472,"mc":[{"id":"1.168135750","rc":[{"trd":[[4.5,463.19]],"batl":[[0,4.5,161.3]],"ltp":4.5,"tv":987.54,"id":2764711}],"tv":1306.51}]}
{"op":"mcm","clk":"993120500","pt":1580536916431,"mc":[{"id":"1.168135750","rc":[{"trd":[[9,204.29]],"batl":[[0,9,380.84]],"ltp":9.0,"tv":343.73,"id":5720732}],"tv":1358.2}]}
{"op":"mcm","clk":"993250746","pt":1580539326817,"mc":[{"id":"1.168135750","rc":[{"trd":[[4.5,785.62],[4.6,419.74]],"batb":[[0,4.6,425.48],[1,3.9,9.27],[2,3.85,11.36]],"batl":[[0,4.7,447.27],[1,4.8,563],[2,5,563]],"ltp":4.6,"tv":1626.04,"id":2764711}],"tv":1996.69}]}
{"op":"mcm","clk":"993250791","pt":1580539328050,"mc":[{"id":"1.168135750","rc":[{"batb":[[0,4.6,433.52]],"ltp":4.6,"tv":1626.04,"id":2764711}]}]}
{"op":"mcm","clk":"993250863","pt":1580539329850,"mc":[{"id":"1.168135750","rc":[{"batb":[[1,3.85,11.36],[2,3.7,53.18]],"ltp":4.6,"tv":1626.04,"id":2764711}]}]}
{"op":"mcm","clk":"993251592","pt":1580539344380,"mc":[{"id":"1.168135750","rc":[{"trd":[[4.7,1255.28]],"batb":[[0,4.6,8.04]],"batl":[[0,4.7,21.36]],"ltp":4.7,"tv":2477.43,"id":2764711}],"tv":2848.09}]}
{"op":"mcm","clk":"993251611","pt":1580539344851,"mc":[{"id":"1.168135750","rc":[{"batb":[[0,3.85,11.36],[1,3.7,53.18],[2,3.5,285.71]],"ltp":4.7,"tv":2477.43,"id":2764711}]}]}
{"op":"mcm","clk":"993251844","pt":1580539349571,"mc":[{"id":"1.168135750","rc":[{"batb":[[0,3.9,9.27],[1,3.85,11.36],[2,3.7,53.18]],"ltp":4.7,"tv":2477.43,"id":2764711}]}]}
{"op":"mcm","clk":"993305024","pt":1580540251260,"mc":[{"id":"1.168135750","rc":[{"batl":[[0,24,6.08],[1,25,10.64]],"ltp":0.0,"tv":0.0,"id":5720738}]}]}
{"op":"mcm","clk":"993305614","pt":1580540264487,"mc":[{"id":"1.168135750","rc":[{"batl":[[0,40,4.05]],"ltp":0.0,"tv":0.0,"id":5720736}]}]}
{"op":"mcm","clk":"993306270","pt":1580540278905,"mc":[{"id":"1.168135750","rc":[{"batl":[[0,80,3.04]],"ltp":0.0,"tv":0.0,"id":5720735}]}]}
{"op":"mcm","clk":"993400003","pt":1580541838359,"mc":[{"id":"1.168135750","rc":[{"trd":[[4.7,1268.47]],"batl":[[0,4.7,14.76]],"ltp":4.7,"tv":2490.62,"id":2764711}],"tv":2861.28}]}
{"op":"mcm","clk":"993409973","pt":1580541995460,"mc":[{"id":"1.168135750","rc":[{"trd":[[9,222.98]],"batl":[[0,9,371.49]],"ltp":9.0,"tv":362.42,"id":5720732}],"tv":2879.97}]}
{"op":"mcm","clk":"993565887","pt":1580543967247,"mc":[{"id":"1.168135750","rc":[{"trd":[[9,239.18]],"batl":[[0,9,363.39]],"ltp":9.0,"tv":378.62,"id":5720732}],"tv":2896.17}]}
{"op":"mcm","clk":"993583010","pt":1580544163190,"mc":[{"id":"1.168135750","rc":[{"trd":[[9,246.16]],"batl":[[0,9,359.9]],"ltp":9.0,"tv":385.6,"id":5720732}],"tv":2903.15}]}
{"op":"mcm","clk":"993595249","pt":1580544336832,"mc":[{"id":"1.168135750","rc":[{"batl":[[0,9.2,16.71],[1,24,6.08],[2,25,10.64]],"ltp":0.0,"tv":0.0,"id":5720738}]}]}
{"op":"mcm","clk":"993596029","pt":1580544347439,"mc":[{"id":"1.168135750","rc":[{"batl":[[0,7.8,14.69],[1,15,10.64]],"ltp":0.0,"tv":0.0,"id":2764722}]}]}
{"op":"mcm","clk":"993596701","pt":1580544356048,"mc":[{"id":"1.168135750","rc":[{"batb":[[0,5.4,27.86],[1,5.1,7.08],[2,5,200]],"ltp":0.0,"tv":0.0,"id":2764720}]}]}
{"op":"mcm","clk":"993597028","pt":1580544361026,"mc":[{"id":"1.168135750","rc":[{"batb":[[1,5,200],[2,1.01,1.01]],"ltp":0.0,"tv":0.0,"id":2764720}]}]}
{"op":"mcm","clk":"993597452","pt":1580544366963,"mc":[{"id":"1.168135750","rc":[{"batl":[[0,16,14.69]],"ltp":0.0,"tv":0.0,"id":2764715}]}]}
{"op":"mcm","clk":"993598340","pt":1580544381057,"mc":[{"id":"1.168135750","rc":[{"batb":[[0,5.5,6.57],[1,5.4,27.86],[2,5,200]],"ltp":0.0,"tv":0.0,"id":2764720}]}]}
{"op":"mcm","clk":"993601130","pt":1580544423810,"mc":[{"id":"1.168135750","rc":[{"batl":[[0,34,12.16],[1,40,4.05]],"ltp":0.0,"tv":0.0,"id":5720736}]}]}
{"op":"mcm","clk":"993623450","pt":1580544602075,"mc":[{"id":"1.168135750","rc":[{"trd":[[9,262.36]],"batl":[[0,9,351.8]],"ltp":9.0,"tv":401.8,"id":5720732}],"tv":2919.35}]}
{"op":"mcm","clk":"993623856","pt":1580544607491,"mc":[{"id":"1.168135750","rc":[{"batb":[[0,5.6,27.86],[1,5.5,6.57]],"ltp":0.0,"tv":0.0,"id":2764720}]}]}
{"op":"mcm","clk":"993624408","pt":1580544614695,"mc":[{"id":"1.168135750","rc":[{"batb":[[1,5,200],[2,1.01,1.01]],"ltp":0.0,"tv":0.0,"id":2764720}]}]}
{"op":"mcm","clk":"993625840","pt":1580544635042,"mc":[{"id":"1.168135750","rc":[{"batb":[[0,5.7,6.34],[1,5.6,27.86],[2,5,200]],"ltp":0.0,"tv":0.0,"id":2764720}]}]}
{"op":"mcm","clk":"993627303","pt":1580544654343,"mc":[{"id":"1.168135750","rc":[{"batb":[[0,12,19.25],[1,11.5,3.14],[2,10,100]],"ltp":15.0,"tv":26.92,"id":2764710}]}]}
{"op":"mcm","clk":"993627516","pt":1580544657546,"mc":[{"id":"1.168135750","rc":[{"batb":[[1,10,100],[2,1.01,1.01]],"ltp":15.0,"tv":26.92,"id":2764710}]}]}
{"op":"mcm","clk":"993628936","pt":1580544677566,"mc":[{"id":"1.168135750","rc":[{"batb":[[0,12.5,2.89],[1,12,19.25],[2,10,100]],"ltp":15.0,"tv":26.92,"id":2764710}]}]}
{"op":"mcm","clk":"993642564","pt":1580544846820,"mc":[{"id":"1.168135750","rc":[{"trd":[[9,269.34]],"batl":[[0,9,348.31]],"ltp":9.0,"tv":408.78,"id":5720732}],"tv":2926.33}]}
{"op":"mcm","clk":"993677453","pt":1580545231185,"mc":[{"id":"1.168135750","rc":[{"trd":[[9.2,17.41]],"batl":[[0,9.2,8.01]],"ltp":9.2,"tv":17.41,"id":5720738}],"tv":2943.74}]}
{"op":"mcm","clk":"993704904","pt":1580545446502,"mc":[{"id":"1.168135750","rc":[{"trd":[[9.2,25.03]],"batl":[[0,9.2,4.21]],"ltp":9.2,"tv":25.02,"id":5720738}],"tv":2951.35}]}
{"op":"mcm","clk":"993730130","pt":1580545746091,"mc":[{"id":"1.168135750","rc":[{"trd":[[9,285.54]],"batl":[[0,9,340.21]],"ltp":9.0,"tv":424.98,"id":5720732}],"tv":2967.55}]}
{"op":"mcm","clk":"993784762","pt":1580546271119,"mc":[{"id":"1.168135750","rc":[{"trd":[[9.2,32.68]],"batl":[[0,24,6.46],[1,25,10.64],[2,25,0]],"ltp":9.2,"tv":32.67,"id":5720738}],"tv":2975.21}]}
{"op":"mcm","clk":"994324549","pt":1580551123872,"mc":[{"id":"1.168135750","rc":[{"batb":[[0,13,8],[1,12.5,2.89],[2,12,83.33]],"ltp":0.0,"tv":0.0,"id":5720735},{"batb":[[0,22,5.64]],"ltp":0.0,"tv":0.0,"id":5720734},{"trd":[[9,310.54]],"batl":[[0,9,327.71]],"ltp":9.0,"tv":449.98,"id":5720732}],"tv":3000.21}]}
{"op":"mcm","clk":"994324872","pt":1580551126173,"mc":[{"id":"1.168135750","rc":[{"batb":[[1,12,83.33],[2,1.01,1.01]],"ltp":0.0,"tv":0.0,"id":5720735}]}]}
{"op":"mcm","clk":"994326783","pt":1580551142637,"mc":[{"id":"1.168135750","rc":[{"batb":[[0,13.5,2.68],[1,13,8],[2,12,83.33]],"ltp":0.0,"tv":0.0,"id":5720735}]}]}
{"op":"mcm","clk":"994345144","pt":1580551293005,"mc":[{"id":"1.168135750","rc":[{"batb":[[0,13,8],[1,12.5,2.89],[2,12,19.25]],"ltp":15.0,"tv":26.92,"id":2764710},{"batb":[[0,3.9,43.27]],"ltp":4.7,"tv":2490.62,"id":2764711},{"batb":[[0,5.7,27.34]],"ltp":0.0,"tv":0.0,"id":2764720},{"batb":[[0,12,9],[1,11.5,3.14],[2,11,10.64]],"ltp":0.0,"tv":0.0,"id":2764714},{"batb":[[0,11,10],[1,10.5,3.44],[2,10,100]],"ltp":0.0,"tv":0.0,"id":2764715},{"batb":[[0,6.4,18],[1,6.2,5.83],[2,6,166.67]],"ltp":9.2,"tv":32.67,"id":5720738},{"batb":[[0,36,3]],"ltp":0.0,"tv":0.0,"id":2764717},{"batb":[[0,18,5],[1,17.5,2.07],[2,17,58.82]],"ltp":0.0,"tv":0.0,"id":5720736},{"batb":[[0,5.6,27.45]],"ltp":0.0,"tv":0.0,"id":2764722}]}]}
{"op":"mcm","clk":"994345807","pt":1580551296683,"mc":[{"id":"1.168135750","rc":[{"batb":[[1,12,19.25],[2,10,100]],"ltp":15.0,"tv":26.92,"id":2764710},{"batb":[[1,11,10.64],[2,9,111.11]],"ltp":0.0,"tv":0.0,"id":2764714},{"batb":[[1,10,100],[2,1.01,1.01]],"ltp":0.0,"tv":0.0,"id":2764715},{"batb":[[1,6,166.67],[2,1.01,1.01]],"ltp":9.2,"tv":32.67,"id":5720738},{"batb":[[1,17,58.82],[2,1.01,1.01]],"ltp":0.0,"tv":0.0,"id":5720736}]}]}
{"op":"mcm","clk":"994347815","pt":1580551313505,"mc":[{"id":"1.168135750","rc":[{"batb":[[0,13.5,2.68],[1,13,8],[2,12,19.25]],"ltp":15.0,"tv":26.92,"id":2764710},{"batb":[[0,12.5,2.89],[1,12,9],[2,11,10.64]],"ltp":0.0,"tv":0.0,"id":2764714},{"batb":[[0,11.5,3.14],[1,11,10],[2,10,100]],"ltp":0.0,"tv":0.0,"id":2764715},{"batb":[[0,6.6,5.48],[1,6.4,18],[2,6,166.67]],"ltp":9.2,"tv":32.67,"id":5720738},{"batb":[[0,18.5,1.95],[1,18,5],[2,17,58.82]],"ltp":0.0,"tv":0.0,"id":5720736}]}]}
{"op":"mcm","clk":"994756949","pt":1580553524880,"mc":[{"id":"1.168135750","rc":[{"batb":[[2,10,100]],"ltp":15.0,"tv":26.92,"id":2764710},{"batb":[[1,5,200],[2,1.01,1.01]],"ltp":0.0,"tv":0.0,"id":2764720}]}]}
{"op":"mcm","clk":"994792134","pt":1580553736850,"mc":[{"id":"1.168135750","rc":[{"batl":[[0,8.8,50.65],[1,9,327.71],[2,12,27.86]],"ltp":9.0,"tv":449.98,"id":5720732}]}]}
{"op":"mcm","clk":"994880781","pt":1580554315768,"mc":[{"id":"1.168135750","rc":[{"batl":[[1,19.5,25.33],[2,20,53]],"ltp":15.0,"tv":26.92,"id":2764710}]}]}
{"op":"mcm","clk":"995085451","pt":1580555288646,"mc":[{"id":"1.168135750","rc":[{"trd":[[8.8,155.38]],"batl":[[0,8.8,42.69]],"ltp":8.8,"tv":465.91,"id":5720732}],"tv":3016.14}]}
{"op":"mcm","clk":"995125745","pt":1580555492316,"mc":[{"id":"1.168135750","rc":[{"trd":[[16,6.99]],"batl":[[0,16,11.19]],"ltp":16.0,"tv":6.99,"id":2764715}],"tv":3023.13}]}
{"op":"mcm","clk":"995196119","pt":1580555829769,"mc":[{"id":"1.168135750","rc":[{"trd":[[8.8,162.21]],"batl":[[0,8.8,39.27]],"ltp":8.8,"tv":472.75,"id":5720732}],"tv":3029.97}]}
{"op":"mcm","clk":"995213913","pt":1580555908380,"mc":[{"id":"1.168135750","rc":[{"trd":[[4.7,1297.98],[4.8,11.04]],"batl":[[0,4.8,557.48],[1,5,563],[2,7,50.65]],"ltp":4.8,"tv":2531.16,"id":2764711}],"tv":3070.51}]}
{"op":"mcm","clk":"995331523","pt":1580556441179,"mc":[{"id":"1.168135750","rc":[{"batb":[[0,4.1,11.36],[1,3.9,43.27]],"ltp":4.8,"tv":2531.16,"id":2764711}]}]}
{"op":"mcm","clk":"995332482","pt":1580556445978,"mc":[{"id":"1.168135750","rc":[{"batb":[[1,3.9,34]],"ltp":4.8,"tv":2531.16,"id":2764711}]}]}
{"op":"mcm","clk":"995335713","pt":1580556462097,"mc":[{"id":"1.168135750","rc":[{"batb":[[0,4.2,8.6],[1,4.1,11.36],[2,3.9,34]],"ltp":4.8,"tv":2531.16,"id":2764711}]}]}
{"op":"mcm","clk":"995354781","pt":1580556554784,"mc":[{"id":"1.168135750","rc":[{"batb":[[0,14,14.18],[1,13.5,2.68],[2,13,8]],"ltp":15.0,"tv":26.92,"id":2764710}]}]}
{"op":"mcm","clk":"995355809","pt":1580556559891,"mc":[{"id":"1.168135750","rc":[{"batb":[[1,13,8],[2,10,100]],"ltp":15.0,"tv":26.92,"id":2764710}]}]}
{"op":"mcm","clk":"995359246","pt":1580556575818,"mc":[{"id":"1.168135750","rc":[{"batb":[[0,14.5,2.5],[1,14,14.18],[2,13,8]],"ltp":15.0,"tv":26.92,"id":2764710}]}]}
{"op":"mcm","clk":"995360306","pt":1580556580746,"mc":[{"id":"1.168135750","rc":[{"batl":[[0,24,6.08]],"ltp":9.2,"tv":32.67,"id":5720738}]}]}
{"op":"mcm","clk":"995360344","pt":1580556580946,"mc":[{"id":"1.168135750","rc":[{"batl":[[0,24,6.46]],"ltp":9.2,"tv":32.67,"id":5720738}]}]}
{"op":"mcm","clk":"995363904","pt":1580556597288,"mc":[{"id":"1.168135750","rc":[{"trd":[[8.6,32.57]],"batb":[[0,6.6,142.86],[1,1.01,1.01],[2,1.01,0]],"batl":[[0,8.8,39.71]],"ltp":8.6,"tv":505.32,"id":5720732}],"tv":3103.08}]}
{"op":"mcm","clk":"995364341","pt":1580556599346,"mc":[{"id":"1.168135750","rc":[{"batb":[[0,6.8,10.73],[1,6.6,142.86],[2,1.01,1.01]],"ltp":8.6,"tv":505.32,"id":5720732}]}]}
{"op":"mcm","clk":"995366084","pt":1580556607186,"mc":[{"id":"1.168135750","rc":[{"batl":[[0,38,5.57],[1,48,12.66],[2,50,53]],"ltp":0.0,"tv":0.0,"id":5720734}]}]}
{"op":"mcm","clk":"995367989","pt":1580556615907,"mc":[{"id":"1.168135750","rc":[{"batb":[[0,5.8,22.29],[1,5.7,27.34],[2,5,200]],"ltp":0.0,"tv":0.0,"id":2764720}]}]}
{"op":"mcm","clk":"995368798","pt":1580556619691,"mc":[{"id":"1.168135750","rc":[{"batb":[[1,5.7,21]],"ltp":0.0,"tv":0.0,"id":2764720}]}]}
{"op":"mcm","clk":"995370397","pt":1580556627301,"mc":[{"id":"1.168135750","rc":[{"batl":[[0,24,6.08]],"ltp":9.2,"tv":32.67,"id":5720738}]}]}
{"op":"mcm","clk":"995371791","pt":1580556634002,"mc":[{"id":"1.168135750","rc":[{"batb":[[0,4.3,11.36],[1,4.2,8.6]],"ltp":4.8,"tv":2531.16,"id":2764711}]}]}
{"op":"mcm","clk":"995372194","pt":1580556635899,"mc":[{"id":"1.168135750","rc":[{"batb":[[0,5.9,6.13],[1,5.8,22.29],[2,5.7,21]],"ltp":0.0,"tv":0.0,"id":2764720}]}]}
{"op":"mcm","clk":"995373004","pt":1580556639724,"mc":[{"id":"1.168135750","rc":[{"batb":[[1,3.9,34],[2,3.7,53.18]],"ltp":4.8,"tv":2531.16,"id":2764711}]}]}
{"op":"mcm","clk":"995380030","pt":1580556671581,"mc":[{"id":"1.168135750","rc":[{"batb":[[0,4.4,8.21],[1,4.3,11.36],[2,3.9,34]],"ltp":4.8,"tv":2531.16,"id":2764711}]}]}
{"op":"mcm","clk":"995384043","pt":1580556690620,"mc":[{"id":"1.168135750","rc":[{"batb":[[1,3.9,34],[2,3.7,53.18]],"ltp":4.8,"tv":2531.16,"id":2764711}]}]}
{"op":"mcm","clk":"995385992","pt":1580556698718,"mc":[{"id":"1.168135750","rc":[{"batb":[[0,4.5,6.82],[1,4.4,8.21],[2,3.9,34]],"ltp":4.8,"tv":2531.16,"id":2764711}]}]}
{"op":"mcm","clk":"995386746","pt":1580556702241,"mc":[{"id":"1.168135750","rc":[{"batb":[[1,3.9,34],[2,3.7,53.18]],"ltp":4.8,"tv":2531.16,"id":2764711}]}]}
{"op":"mcm","clk":"995390160","pt":1580556718275,"mc":[{"id":"1.168135750","rc":[{"batb":[[0,4.6,7.86],[1,4.5,6.82],[2,3.9,34]],"ltp":4.8,"tv":2531.16,"id":2764711}]}]}
{"op":"mcm","clk":"995392876","pt":1580556731070,"mc":[{"id":"1.168135750","rc":[{"batb":[[1,3.9,34],[2,3.7,53.18]],"ltp":4.8,"tv":2531.16,"id":2764711}]}]}
{"op":"mcm","clk":"995394120","pt":1580556737206,"mc":[{"id":"1.168135750","rc":[{"batb":[[0,4.7,3.03],[1,4.6,7.86],[2,3.9,34]],"ltp":4.8,"tv":2531.16,"id":2764711}]}]}
{"op":"mcm","clk":"995398711","pt":1580556758990,"mc":[{"id":"1.168135750","rc":[{"batb":[[2,4.3,8.33]],"ltp":4.8,"tv":2531.16,"id":2764711}]}]}
{"op":"mcm","clk":"995556485","pt":1580557479148,"mc":[{"id":"1.168135750","rc":[{"batb":[[0,7.4,13.51],[1,5.9,6.13],[2,5.8,22.29]],"ltp":0.0,"tv":0.0,"id":2764720},{"batb":[[1,50,2],[2,1.01,1.01]],"ltp":0.0,"tv":0.0,"id":5720739},{"batb":[[2,11,19.73]],"ltp":0.0,"tv":0.0,"id":2764714},{"batb":[[0,12,8.33],[1,11.5,3.14],[2,11,10]],"ltp":16.0,"tv":6.99,"id":2764715},{"batb":[[0,8,12.5],[1,6.6,5.48],[2,6.4,18]],"ltp":9.2,"tv":32.67,"id":5720738},{"batb":[[0,50,2],[1,36,3],[2,34,29.41]],"ltp":0.0,"tv":0.0,"id":2764717},{"batb":[[0,22,4.55],[1,13.5,2.68],[2,13,8]],"ltp":0.0,"tv":0.0,"id":5720735},{"batb":[[0,25,4],[1,22,5.64],[2,21,47.62]],"ltp":0.0,"tv":0.0,"id":5720734},{"batb":[[1,50,2],[2,2.5,101.3]],"ltp":0.0,"tv":0.0,"id":5720737},{"batb":[[0,25,4],[1,18.5,1.95],[2,18,5]],"ltp":0.0,"tv":0.0,"id":5720736},{"batb":[[2,5,20]],"ltp":0.0,"tv":0.0,"id":2764722},{"batb":[[0,7,14.29],[1,6.8,10.73],[2,6.6,142.86]],"ltp":8.6,"tv":505.32,"id":5720732}]}]}
{"op":"mcm","clk":"995556926","pt":1580557481345,"mc":[{"id":"1.168135750","rc":[{"batb":[[1,5.8,22.29],[2,5.7,21]],"ltp":0.0,"tv":0.0,"id":2764720},{"batb":[[1,11,10],[2,10,100]],"ltp":16.0,"tv":6.99,"id":2764715},{"batb":[[1,6.4,18],[2,6,166.67]],"ltp":9.2,"tv":32.67,"id":5720738},{"batb":[[1,36,2]],"ltp":0.0,"tv":0.0,"id":2764717},{"batb":[[1,13,8],[2,12,83.33]],"ltp":0.0,"tv":0.0,"id":5720735},{"batb":[[1,22,4]],"ltp":0.0,"tv":0.0,"id":5720734},{"batb":[[1,18,5],[2,17,58.82]],"ltp":0.0,"tv":0.0,"id":5720736}]}]}
{"op":"mcm","clk":"995560129","pt":1580557497784,"mc":[{"id":"1.168135750","rc":[{"batb":[[0,7.6,4.76],[1,7.4,13.51],[2,5.8,22.29]],"ltp":0.0,"tv":0.0,"id":2764720},{"batb":[[0,12.5,2.89],[1,12,8.33],[2,11,10]],"ltp":16.0,"tv":6.99,"id":2764715},{"batb":[[0,8.2,4.4],[1,8,12.5],[2,6.4,18]],"ltp":9.2,"tv":32.67,"id":5720738},{"batb":[[0,50,2.66]],"ltp":0.0,"tv":0.0,"id":2764717},{"batb":[[0,23,1.57],[1,22,4.55],[2,13,8]],"ltp":0.0,"tv":0.0,"id":5720735},{"batb":[[0,26,1.39],[1,25,4],[2,22,4]],"ltp":0.0,"tv":0.0,"id":5720734},{"batb":[[0,26,1.39],[1,25,4],[2,18,5]],"ltp":0.0,"tv":0.0,"id":5720736}]}]}
{"op":"mcm","clk":"995756756","pt":1580558658562,"mc":[{"id":"1.168135750","rc":[{"trd":[[8.6,33.45],[8.8,177.33]],"batl":[[0,8.8,31.72]],"ltp":8.8,"tv":521.31,"id":5720732}],"tv":3119.07}]}
{"op":"mcm","clk":"995800813","pt":1580558852936,"mc":[{"id":"1.168135750","rc":[{"trd":[[8.8,193.32]],"batl":[[0,8.8,23.72]],"ltp":8.8,"tv":537.3,"id":5720732}],"tv":3135.06}]}
{"op":"mcm","clk":"995824508","pt":1580558977506,"mc":[{"id":"1.168135750","rc":[{"trd":[[8.8,200.17]],"batl":[[0,8.8,20.3]],"ltp":8.8,"tv":544.16,"id":5720732}],"tv":3141.92}]}
{"op":"mcm","clk":"995849854","pt":1580559112952,"mc":[{"id":"1.168135750","rc":[{"trd":[[16,14.21]],"batl":[[0,16,7.59]],"ltp":16.0,"tv":14.21,"id":2764715}],"tv":3149.13}]}
{"op":"mcm","clk":"995910816","pt":1580559437824,"mc":[{"id":"1.168135750","rc":[{"batb":[[0,7,44.68]],"ltp":8.8,"tv":544.16,"id":5720732}]}]}
{"op":"mcm","clk":"995915392","pt":1580559461967,"mc":[{"id":"1.168135750","rc":[{"batl":[[0,8.8,50.69]],"ltp":8.8,"tv":544.16,"id":5720732}]}]}
{"op":"mcm","clk":"995929816","pt":1580559545947,"mc":[{"id":"1.168135750","rc":[{"trd":[[4.7,1304.03]],"batb":[[0,4.6,7.86],[1,4.3,8.33],[2,3.9,34]],"batl":[[0,4.7,19.26],[1,4.8,557.48],[2,5,563]],"ltp":4.7,"tv":2537.21,"id":2764711}],"tv":3155.19}]}
{"op":"mcm","clk":"996270637","pt":1580561292982,"mc":[{"id":"1.168135750","rc":[{"batl":[[0,36,5.57]],"ltp":0.0,"tv":0.0,"id":5720734}]}]}
{"op":"mcm","clk":"996272737","pt":1580561304305,"mc":[{"id":"1.168135750","rc":[{"batb":[[2,5.7,21]],"ltp":0.0,"tv":0.0,"id":2764720}]}]}
{"op":"mcm","clk":"996275978","pt":1580561320700,"mc":[{"id":"1.168135750","rc":[{"batl":[[0,29,8.1],[1,80,3.04]],"ltp":0.0,"tv":0.0,"id":5720735}]}]}
{"op":"mcm","clk":"996278989","pt":1580561337071,"mc":[{"id":"1.168135750","rc":[{"batl":[[1,38,4.05],[2,48,12.66]],"ltp":0.0,"tv":0.0,"id":5720734}]}]}
{"op":"mcm","clk":"996352150","pt":1580561701456,"mc":[{"id":"1.168135750","rc":[{"trd":[[4.7,1320.04]],"batl":[[0,4.7,11.26]],"ltp":4.7,"tv":2553.22,"id":2764711}],"tv":3171.19}]}
{"op":"mcm","clk":"996370256","pt":1580561807694,"mc":[{"id":"1.168135750","rc":[{"batl":[[0,9.6,11.14],[1,24,6.08],[2,25,10.64]],"ltp":9.2,"tv":32.67,"id":5720738}]}]}
{"op":"mcm","clk":"996826181","pt":1580563945801,"mc":[{"id":"1.168135750","rc":[{"trd":[[5.6,8.4]],"batb":[[0,5.6,23.25]],"ltp":5.6,"tv":8.4,"id":2764722}],"tv":3179.59}]}
{"op":"mcm","clk":"996830725","pt":1580563966964,"mc":[{"id":"1.168135750","rc":[{"trd":[[12.5,5.78]],"batb":[[0,12,8.33],[1,11,10],[2,10,100]],"batl":[[0,12.5,1.31],[1,16,7.59]],"ltp":12.5,"tv":19.99,"id":2764715}],"tv":3185.37}]}
{"op":"mcm","clk":"997082403","pt":1580565190297,"mc":[{"id":"1.168135750","rc":[{"trd":[[8.8,202.11]],"batl":[[0,8.8,49.72]],"ltp":8.8,"tv":546.09,"id":5720732}],"tv":3187.31}]}
{"op":"mcm","clk":"997329040","pt":1580566420992,"mc":[{"id":"1.168135750","rc":[{"trd":[[9.6,16.75]],"batl":[[0,9.6,2.77]],"ltp":9.6,"tv":49.43,"id":5720738}],"tv":3204.06}]}
{"op":"mcm","clk":"997455381","pt":1580566895806,"mc":[{"id":"1.168135750","rc":[{"trd":[[8.8,208.96]],"batl":[[0,8.8,46.3]],"ltp":8.8,"tv":552.94,"id":5720732}],"tv":3210.92}]}
{"op":"mcm","clk":"997496910","pt":1580567059003,"mc":[{"id":"1.168135750","rc":[{"trd":[[5.6,28.4]],"batb":[[0,5.6,13.25]],"ltp":5.6,"tv":28.4,"id":2764722}],"tv":3230.92}]}
{"op":"mcm","clk":"997624197","pt":1580567580603,"mc":[{"id":"1.168135750","rc":[{"trd":[[7.8,21.19]],"batl":[[0,7.8,4.1]],"ltp":7.8,"tv":49.59,"id":2764722}],"tv":3252.11}]}
{"op":"mcm","clk":"998086225","pt":1580569512039,"mc":[{"id":"1.168135750","rc":[{"batb":[[0,8,6.08],[1,7,44.68],[2,6.8,10.73]],"ltp":8.8,"tv":552.94,"id":5720732}]}]}
{"op":"mcm","clk":"998091033","pt":1580569530954,"mc":[{"id":"1.168135750","rc":[{"trd":[[15,30]],"batb":[[0,15,2.01],[1,14.5,2.5],[2,14,14.18]],"batl":[[0,19.5,25.33],[1,20,53],[2,32,10.64]],"ltp":15.0,"tv":29.99,"id":2764710}],"tv":3255.19}]}
{"op":"mcm","clk":"998091863","pt":1580569534164,"mc":[{"id":"1.168135750","rc":[{"batb":[[1,14,14.18],[2,13,8]],"ltp":15.0,"tv":29.99,"id":2764710}]}]}
{"op":"mcm","clk":"998095951","pt":1580569550078,"mc":[{"id":"1.168135750","rc":[{"batb":[[0,15.5,2.33],[1,15,2.01],[2,14,14.18]],"ltp":15.0,"tv":29.99,"id":2764710}]}]}
{"op":"mcm","clk":"998097151","pt":1580569554804,"mc":[{"id":"1.168135750","rc":[{"batb":[[0,14,6.08],[1,12.5,2.89],[2,12,9]],"ltp":0.0,"tv":0.0,"id":2764714}]}]}
{"op":"mcm","clk":"998097676","pt":1580569556672,"mc":[{"id":"1.168135750","rc":[{"batb":[[1,12,9],[2,11,19.73]],"ltp":0.0,"tv":0.0,"id":2764714}]}]}
{"op":"mcm","clk":"998105594","pt":1580569584996,"mc":[{"id":"1.168135750","rc":[{"batb":[[0,14.5,2.5],[1,14,6.08],[2,12,9]],"ltp":0.0,"tv":0.0,"id":2764714}]}]}
{"op":"mcm","clk":"998535639","pt":1580571201597,"mc":[{"id":"1.168135750","rc":[{"trd":[[8.8,221.62]],"batl":[[0,8.8,39.97]],"ltp":8.8,"tv":565.61,"id":5720732}],"tv":3267.85}]}
{"op":"mcm","clk":"999000236","pt":1580573172789,"mc":[{"id":"1.168135750","rc":[{"batb":[[2,3.8,44.57]],"ltp":4.7,"tv":2553.22,"id":2764711},{"batb":[[2,5,200]],"ltp":0.0,"tv":0.0,"id":2764720},{"batb":[[2,11,19.73]],"ltp":0.0,"tv":0.0,"id":2764714},{"batb":[[1,10,100],[2,1.01,1.01]],"ltp":12.5,"tv":19.99,"id":2764715},{"batb":[[2,6,166.67]],"ltp":9.6,"tv":49.43,"id":5720738},{"batb":[[1,34,29.41],[2,1.6,111.43]],"ltp":0.0,"tv":0.0,"id":2764717},{"batb":[[2,12,83.33]],"ltp":0.0,"tv":0.0,"id":5720735},{"batb":[[2,21,47.62]],"ltp":0.0,"tv":0.0,"id":5720734},{"batb":[[2,17,58.82]],"ltp":0.0,"tv":0.0,"id":5720736}]}]}
{"op":"mcm","clk":"999000251","pt":1580573172900,"mc":[{"id":"1.168135750","rc":[{"batb":[[0,16,8],[1,15.5,2.33],[2,15,2.01]],"ltp":15.0,"tv":29.99,"id":2764710},{"trd":[[4.7,1342.57],[4.8,56.5]],"batl":[[0,4.8,534.75],[1,5,563],[2,7,50.65]],"ltp":4.8,"tv":2621.21,"id":2764711},{"batb":[[0,7.8,21],[1,7.6,4.76],[2,7.4,13.51]],"ltp":0.0,"tv":0.0,"id":2764720},{"batb":[[0,15,9],[1,14.5,2.5],[2,14,6.08]],"ltp":0.0,"tv":0.0,"id":2764714},{"trd":[[12.5,8.4]],"batb":[[0,12.5,8.69],[1,12,8.33],[2,10,100]],"batl":[[0,16,7.59],[1,16,0]],"ltp":12.5,"tv":22.61,"id":2764715},{"batb":[[0,8.4,18],[1,8.2,4.4],[2,8,12.5]],"ltp":9.6,"tv":49.43,"id":5720738},{"batb":[[0,50,4.66]],"ltp":0.0,"tv":0.0,"id":2764717},{"batb":[[0,23,9.57]],"ltp":0.0,"tv":0.0,"id":5720735},{"batb":[[0,26,5.39]],"ltp":0.0,"tv":0.0,"id":5720734},{"batb":[[0,26,6.39]],"ltp":0.0,"tv":0.0,"id":5720736}],"tv":3338.46}]}
{"op":"mcm","clk":"999000668","pt":1580573174494,"mc":[{"id":"1.168135750","rc":[{"batb":[[1,15,2.01],[2,14,14.18]],"ltp":15.0,"tv":29.99,"id":2764710},{"batb":[[1,7.4,13.51],[2,5,200]],"ltp":0.0,"tv":0.0,"id":2764720},{"batb":[[1,14,6.08],[2,11,19.73]],"ltp":0.0,"tv":0.0,"id":2764714},{"batb":[[1,8,12.5],[2,6,166.67]],"ltp":9.6,"tv":49.43,"id":5720738}]}]}
{"op":"mcm","clk":"999004886","pt":1580573191251,"mc":[{"id":"1.168135750","rc":[{"batb":[[0,16.5,2.19],[1,16,8],[2,15,2.01]],"ltp":15.0,"tv":29.99,"id":2764710},{"batb":[[0,8,4.52],[1,7.8,21],[2,7.4,13.51]],"ltp":0.0,"tv":0.0,"id":2764720},{"batb":[[0,15.5,2.33],[1,15,9],[2,14,6.08]],"ltp":0.0,"tv":0.0,"id":2764714},{"batb":[[0,8.6,4.2],[1,8.4,18],[2,8,12.5]],"ltp":9.6,"tv":49.43,"id":5720738}]}]}
{"op":"mcm","clk":"999016986","pt":1580573234481,"mc":[{"id":"1.168135750","rc":[{"batb":[[1,16,6]],"ltp":15.0,"tv":29.99,"id":2764710},{"batb":[[1,7.8,14]],"ltp":0.0,"tv":0.0,"id":2764720},{"batb":[[1,15,7]],"ltp":0.0,"tv":0.0,"id":2764714},{"batb":[[1,8.4,13]],"ltp":9.6,"tv":49.43,"id":5720738},{"batb":[[0,23,5.57]],"ltp":0.0,"tv":0.0,"id":5720735},{"batb":[[0,26,5.39]],"ltp":0.0,"tv":0.0,"id":5720736}]}]}
{"op":"mcm","clk":"999095158","pt":1580573528723,"mc":[{"id":"1.168135750","rc":[{"trd":[[8.8,237.5]],"batl":[[0,8.8,32.04]],"ltp":8.8,"tv":581.48,"id":5720732}],"tv":3354.33}]}
{"op":"mcm","clk":"999118904","pt":1580573615185,"mc":[{"id":"1.168135750","rc":[{"trd":[[8.8,253.37]],"batl":[[0,8.8,24.1]],"ltp":8.8,"tv":597.35,"id":5720732}],"tv":3370.2}]}
{"op":"mcm","clk":"999163442","pt":1580573772155,"mc":[{"id":"1.168135750","rc":[{"trd":[[16,21.43]],"batl":[[0,16,3.98]],"ltp":16.0,"tv":29.82,"id":2764715}],"tv":3377.42}]}
{"op":"mcm","clk":"999232892","pt":1580574022888,"mc":[{"id":"1.168135750","rc":[{"trd":[[8.8,260.17]],"batl":[[0,8.8,20.71]],"ltp":8.8,"tv":604.15,"id":5720732}],"tv":3384.22}]}
{"op":"mcm","clk":"999496378","pt":1580575038318,"mc":[{"id":"1.168135750","rc":[{"trd":[[8,12.16]],"batb":[[0,7,44.68],[1,6.8,10.73],[2,6.6,142.86]],"batl":[[0,8,118.92],[1,8.8,20.71],[2,9,327.71]],"ltp":8.0,"tv":616.31,"id":5720732}],"tv":3396.38}]}
{"op":"mcm","clk":"999500372","pt":1580575054889,"mc":[{"id":"1.168135750","rc":[{"trd":[[16.5,4.38]],"batb":[[0,16,6],[1,15,2.01],[2,14,14.18]],"batl":[[0,16.5,47.81],[1,19.5,25.33],[2,20,53]],"ltp":16.5,"tv":34.38,"id":2764710}],"tv":3400.76}]}
{"op":"mcm","clk":"999504627","pt":1580575072015,"mc":[{"id":"1.168135750","rc":[{"batl":[[0,30,15],[1,36,5.57],[2,38,4.05]],"ltp":0.0,"tv":0.0,"id":5720734}]}]}
{"op":"mcm","clk":"999647212","pt":1580575714527,"mc":[{"id":"1.168135750","rc":[{"batl":[[0,6,10.13],[1,7.8,4.1],[2,15,10.64]],"ltp":7.8,"tv":49.59,"id":2764722}]}]}
{"op":"mcm","clk":"999699864","pt":1580576036373,"mc":[{"id":"1.168135750","rc":[{"trd":[[30,28.09]],"batl":[[0,36,6.52],[1,38,4.05],[2,48,12.66]],"ltp":30.0,"tv":28.09,"id":5720734}],"tv":3428.85}]}
{"op":"mcm","clk":"999721699","pt":1580576186380,"mc":[{"id":"1.168135750","rc":[{"batb":[[0,7.8,3.68],[1,7,44.68],[2,6.8,10.73]],"ltp":8.0,"tv":616.31,"id":5720732}]}]}
{"op":"mcm","clk":"999904633","pt":1580577444877,"mc":[{"id":"1.168135750","rc":[{"trd":[[8,29.58]],"batl":[[0,8,110.21]],"ltp":8.0,"tv":633.73,"id":5720732}],"tv":3446.27}]}
{"op":"mcm","clk":"1000050586","pt":1580578382408,"mc":[{"id":"1.168135750","rc":[{"trd":[[8,36.94]],"batb":[[0,7,44.68],[1,6.8,10.73],[2,6.6,142.86]],"batl":[[0,8,106.53]],"ltp":8.0,"tv":641.09,"id":5720732}],"tv":3453.63}]}
{"op":"mcm","clk":"1000162020","pt":1580579053464,"mc":[{"id":"1.168135750","rc":[{"trd":[[6,17.13]],"batl":[[0,6,1.57]],"ltp":6.0,"tv":66.72,"id":2764722}],"tv":3470.76}]}
{"op":"mcm","clk":"1000175887","pt":1580579142063,"mc":[{"id":"1.168135750","rc":[{"trd":[[16,28.32]],"batl":[[0,16,0.54]],"ltp":16.0,"tv":36.72,"id":2764715}],"tv":3477.66}]}
{"op":"mcm","clk":"1000239899","pt":1580579579800,"mc":[{"id":"1.168135750","rc":[{"batl":[[0,19.5,25.33],[1,20,53],[2,32,10.64]],"ltp":16.5,"tv":34.38,"id":2764710}]}]}
{"op":"mcm","clk":"1000239911","pt":1580579579860,"mc":[{"id":"1.168135750","rc":[{"trd":[[16,12]],"batb":[[0,15,2.01],[1,14,14.18],[2,11,9.09]],"batl":[[0,16,41.81],[1,19.5,25.33],[2,20,53]],"ltp":16.0,"tv":46.38,"id":2764710}],"tv":3489.66}]}
{"op":"mcm","clk":"1000242685","pt":1580579599215,"mc":[{"id":"1.168135750","rc":[{"trd":[[8,54.42]],"batl":[[0,8,97.79]],"ltp":8.0,"tv":658.57,"id":5720732}],"tv":3507.14}]}
{"op":"mcm","clk":"1000287432","pt":1580579944864,"mc":[{"id":"1.168135750","rc":[{"trd":[[16,19.36]],"batl":[[0,16,38.13]],"ltp":16.0,"tv":53.74,"id":2764710}],"tv":3514.5}]}
{"op":"mcm","clk":"1000312207","pt":1580580120113,"mc":[{"id":"1.168135750","rc":[{"trd":[[29,8.49]],"batl":[[0,29,3.86]],"ltp":29.0,"tv":8.49,"id":5720735}],"tv":3522.99}]}
{"op":"mcm","clk":"1000436665","pt":1580580942310,"mc":[{"id":"1.168135750","rc":[{"batl":[[1,7.4,10],[2,7.8,4.1]],"ltp":6.0,"tv":66.72,"id":2764722}]}]}
{"op":"mcm","clk":"1000439656","pt":1580580962480,"mc":[{"id":"1.168135750","rc":[{"batl":[[0,9.2,7],[1,9.6,2.77],[2,24,6.08]],"ltp":9.6,"tv":49.43,"id":5720738}]}]}
{"op":"mcm","clk":"1000455634","pt":1580581077916,"mc":[{"id":"1.168135750","rc":[{"batl":[[0,4.7,363],[1,4.8,534.75],[2,5,563]],"ltp":4.8,"tv":2621.21,"id":2764711}]}]}
{"op":"mcm","clk":"1000493290","pt":1580581356219,"mc":[{"id":"1.168135750","rc":[{"trd":[[8,71.84]],"batl":[[0,8,89.08]],"ltp":8.0,"tv":675.99,"id":5720732}],"tv":3540.41}]}
{"op":"mcm","clk":"1000511630","pt":1580581492162,"mc":[{"id":"1.168135750","rc":[{"trd":[[8,89.26]],"batl":[[0,8,80.37]],"ltp":8.0,"tv":693.41,"id":5720732}],"tv":3557.83}]}
{"op":"mcm","clk":"1000531030","pt":1580581644087,"mc":[{"id":"1.168135750","rc":[{"trd":[[9.2,42.88]],"batl":[[0,9.2,1.9]],"ltp":9.2,"tv":59.63,"id":5720738}],"tv":3568.03}]}
{"op":"mcm","clk":"1000554617","pt":1580581809799,"mc":[{"id":"1.168135750","rc":[{"trd":[[8,99.46]],"batl":[[0,8,75.27]],"ltp":8.0,"tv":703.61,"id":5720732}],"tv":3578.23}]}
{"op":"mcm","clk":"1000559594","pt":1580581842810,"mc":[{"id":"1.168135750","rc":[{"batl":[[1,9.4,2],[2,9.6,2.77]],"ltp":9.2,"tv":59.63,"id":5720738}]}]}
{"op":"mcm","clk":"1000725474","pt":1580582833719,"mc":[{"id":"1.168135750","rc":[{"trd":[[8,116.94]],"batl":[[0,8,66.53]],"ltp":8.0,"tv":721.09,"id":5720732}],"tv":3595.71}]}
{"op":"mcm","clk":"1000813444","pt":1580583355756,"mc":[{"id":"1.168135750","rc":[{"trd":[[8,124.42]],"batl":[[0,8,62.79]],"ltp":8.0,"tv":728.57,"id":5720732}],"tv":3603.19}]}
{"op":"mcm","clk":"1000839380","pt":1580583521611,"mc":[{"id":"1.168135750","rc":[{"trd":[[4.7,1351.05]],"batl":[[0,4.7,358.76]],"ltp":4.7,"tv":2629.69,"id":2764711}],"tv":3611.67}]}
{"op":"mcm","clk":"1001163972","pt":1580585205034,"mc":[{"id":"1.168135750","rc":[{"trd":[[8,141.9]],"batl":[[0,8,54.05]],"ltp":8.0,"tv":746.05,"id":5720732}],"tv":3629.15}]}
{"op":"mcm","clk":"1001209808","pt":1580585444552,"mc":[{"id":"1.168135750","rc":[{"trd":[[9.2,46.68],[9.4,3.68]],"batl":[[0,9.6,2.93],[1,24,6.08],[2,25,10.64]],"ltp":9.4,"tv":67.11,"id":5720738}],"tv":3636.63}]}
{"op":"mcm","clk":"1001430200","pt":1580586637270,"mc":[{"id":"1.168135750","rc":[{"batb":[[2,3.85,48.45]],"ltp":4.7,"tv":2629.69,"id":2764711},{"batb":[[0,8,27.84]],"ltp":0.0,"tv":0.0,"id":2764720}]}]}
{"op":"mcm","clk":"1001433678","pt":1580586658735,"mc":[{"id":"1.168135750","rc":[{"trd":[[8,159.32]],"batl":[[0,8,45.34]],"ltp":8.0,"tv":763.47,"id":5720732}],"tv":3654.05}]}
{"op":"mcm","clk":"1001490109","pt":1580587007699,"mc":[{"id":"1.168135750","rc":[{"trd":[[8,166.78]],"batl":[[0,8,41.61]],"ltp":8.0,"tv":770.93,"id":5720732}],"tv":3661.51}]}
{"op":"mcm","clk":"1001585621","pt":1580587554535,"mc":[{"id":"1.168135750","rc":[{"batb":[[1,1.01,1.01],[2,1.01,0]],"ltp":0.0,"tv":0.0,"id":5720739}]}]}
{"op":"mcm","clk":"1001585838","pt":1580587555611,"mc":[{"id":"1.168135750","rc":[{"batb":[[1,21,47.62],[2,1.01,1.01]],"ltp":30.0,"tv":28.09,"id":5720734}]}]}
{"op":"mcm","clk":"1001586081","pt":1580587556862,"mc":[{"id":"1.168135750","rc":[{"batb":[[1,12,83.33],[2,1.01,1.01]],"ltp":29.0,"tv":8.49,"id":5720735}]}]}
{"op":"mcm","clk":"1001586326","pt":1580587558145,"mc":[{"id":"1.168135750","rc":[{"batb":[[0,7,30.39]],"ltp":8.0,"tv":770.93,"id":5720732}]}]}
{"op":"mcm","clk":"1001586758","pt":1580587560461,"mc":[{"id":"1.168135750","rc":[{"batb":[[2,10,100]],"ltp":16.0,"tv":53.74,"id":2764710}]}]}
{"op":"mcm","clk":"1001587579","pt":1580587564629,"mc":[{"id":"1.168135750","rc":[{"batb":[[2,5,200]],"ltp":0.0,"tv":0.0,"id":2764720}]}]}
{"op":"mcm","clk":"1001770638","pt":1580588493451,"mc":[{"id":"1.168135750","rc":[{"trd":[[9.4,4],[9.6,22.29]],"batb":[[0,9.6,5.47],[1,8.6,4.2],[2,8.4,13]],"batl":[[0,24,6.08],[1,25,10.64],[2,25,0]],"ltp":9.6,"tv":72.97,"id":5720738}],"tv":3667.37}]}
{"op":"mcm","clk":"1001771463","pt":1580588498428,"mc":[{"id":"1.168135750","rc":[{"batb":[[1,8.4,13],[2,8,12.5]],"ltp":9.6,"tv":72.97,"id":5720738}]}]}
{"op":"mcm","clk":"1001774334","pt":1580588514448,"mc":[{"id":"1.168135750","rc":[{"batb":[[0,9.8,3.69],[1,9.6,5.47],[2,8.4,13]],"ltp":9.6,"tv":72.97,"id":5720738}]}]}
{"op":"mcm","clk":"1001811844","pt":1580588726459,"mc":[{"id":"1.168135750","rc":[{"batb":[[1,8.4,13],[2,8,12.5]],"ltp":9.6,"tv":72.97,"id":5720738}]}]}
{"op":"mcm","clk":"1001815622","pt":1580588746736,"mc":[{"id":"1.168135750","rc":[{"trd":[[9.8,5.72]],"batb":[[0,8.4,13.83],[1,8,12.5],[2,6,166.67]],"ltp":9.8,"tv":78.68,"id":5720738}],"tv":3673.09}]}
{"op":"mcm","clk":"1001863966","pt":1580589016592,"mc":[{"id":"1.168135750","rc":[{"trd":[[4.6,429.87]],"batb":[[0,4.6,2.79]],"ltp":4.6,"tv":2639.82,"id":2764711}],"tv":3683.22}]}
{"op":"mcm","clk":"1001866015","pt":1580589026800,"mc":[{"id":"1.168135750","rc":[{"batb":[[1,14.5,5.15],[2,14,14.18]],"ltp":16.0,"tv":53.74,"id":2764710},{"batb":[[0,4.6,19.05]],"ltp":4.6,"tv":2639.82,"id":2764711},{"batb":[[0,13,5.76],[1,12.5,8.69],[2,12,8.33]],"ltp":16.0,"tv":36.72,"id":2764715},{"batb":[[0,5.7,13.12],[1,5.6,13.25],[2,5.5,181.82]],"ltp":6.0,"tv":66.72,"id":2764722},{"batb":[[0,7.2,10.38],[1,7,30.39],[2,6.8,10.73]],"ltp":8.0,"tv":770.93,"id":5720732}]}]}
{"op":"mcm","clk":"1002109181","pt":1580590569794,"mc":[{"id":"1.168135750","rc":[{"batb":[[0,15,19.73]],"ltp":16.0,"tv":53.74,"id":2764710},{"batb":[[0,4.6,94.45]],"ltp":4.6,"tv":2639.82,"id":2764711},{"batb":[[2,7.4,40.52]],"ltp":0.0,"tv":0.0,"id":2764720},{"batb":[[0,80,2.53],[1,60,17.22],[2,1.01,1.01]],"ltp":0.0,"tv":0.0,"id":5720739},{"batb":[[2,14,25.33]],"ltp":0.0,"tv":0.0,"id":2764714},{"batb":[[0,13.5,18.23],[1,13,5.76],[2,12.5,8.69]],"ltp":16.0,"tv":36.72,"id":2764715},{"batb":[[0,8.4,48.27]],"ltp":9.8,"tv":78.68,"id":5720738},{"batb":[[0,55,5.72],[1,50,4],[2,34,29.41]],"ltp":0.0,"tv":0.0,"id":2764717},{"batb":[[0,23,18.23]],"ltp":29.0,"tv":8.49,"id":5720735},{"trd":[[30,29.99]],"batb":[[0,30,5.13],[1,26,5.39],[2,21,47.62]],"batl":[[0,36,5.57]],"ltp":30.0,"tv":29.98,"id":5720734},{"batb":[[1,25,14.13]],"ltp":0.0,"tv":0.0,"id":5720736},{"batb":[[0,5.8,48.62],[1,5.7,13.12],[2,5.6,13.25]],"ltp":6.0,"tv":66.72,"id":2764722},{"trd":[[8,237.72]],"batl":[[0,8,6.12]],"ltp":8.0,"tv":841.87,"id":5720732}],"tv":3756.06}]}
{"op":"mcm","clk":"1002109290","pt":1580590570903,"mc":[{"id":"1.168135750","rc":[{"batb":[[1,60,16.67]],"ltp":0.0,"tv":0.0,"id":5720739},{"batb":[[1,12.5,8.69],[2,12,8.33]],"ltp":16.0,"tv":36.72,"id":2764715},{"batb":[[1,26,4]],"ltp":30.0,"tv":29.98,"id":5720734},{"batb":[[1,5.6,13.25],[2,5.5,181.82]],"ltp":6.0,"tv":66.72,"id":2764722}]}]}
{"op":"mcm","clk":"1002111178","pt":1580590587296,"mc":[{"id":"1.168135750","rc":[{"batb":[[0,85,1.3],[1,80,2.53],[2,60,16.67]],"ltp":0.0,"tv":0.0,"id":5720739},{"batb":[[0,14,5.34],[1,13.5,18.23],[2,12.5,8.69]],"ltp":16.0,"tv":36.72,"id":2764715},{"batb":[[0,32,3.47],[1,30,5.13],[2,26,4]],"ltp":30.0,"tv":29.98,"id":5720734},{"batb":[[0,5.9,12.67],[1,5.8,48.62],[2,5.6,13.25]],"ltp":6.0,"tv":66.72,"id":2764722}]}]}
{"op":"mcm","clk":"1002112133","pt":1580590596195,"mc":[{"id":"1.168135750","rc":[{"batb":[[1,80,3.04]],"ltp":0.0,"tv":0.0,"id":5720739},{"batb":[[0,150,1.77],[1,100,10.33],[2,50,2]],"ltp":0.0,"tv":0.0,"id":5720737}]}]}
{"op":"mcm","clk":"1002112450","pt":1580590599521,"mc":[{"id":"1.168135750","rc":[{"batb":[[1,100,10]],"ltp":0.0,"tv":0.0,"id":5720737}]}]}
{"op":"mcm","clk":"1002114169","pt":1580590615504,"mc":[{"id":"1.168135750","rc":[{"batb":[[0,85,1.81],[1,80,2.53]],"ltp":0.0,"tv":0.0,"id":5720739},{"batb":[[0,34,5.13],[1,32,3.47]],"ltp":30.0,"tv":29.98,"id":5720734}]}]}
{"op":"mcm","clk":"1002114749","pt":1580590621637,"mc":[{"id":"1.168135750","rc":[{"batb":[[0,150,2.24]],"ltp":0.0,"tv":0.0,"id":5720737}]}]}
{"op":"mcm","clk":"1002117999","pt":1580590654380,"mc":[{"id":"1.168135750","rc":[{"batb":[[1,13.5,20.26]],"ltp":16.0,"tv":36.72,"id":2764715},{"batb":[[1,5.8,50.65]],"ltp":6.0,"tv":66.72,"id":2764722}]}]}
{"op":"mcm","clk":"1002119056","pt":1580590665592,"mc":[{"id":"1.168135750","rc":[{"batb":[[0,14,7.37],[1,13.5,18.23]],"ltp":16.0,"tv":36.72,"id":2764715},{"trd":[[6,20.27]],"batb":[[0,5.9,13.13],[1,5.8,48.62]],"batl":[[0,7.4,10],[1,7.8,4.1],[2,15,10.64]],"ltp":6.0,"tv":69.86,"id":2764722}],"tv":3759.2}]}
{"op":"mcm","clk":"1002119419","pt":1580590668994,"mc":[{"id":"1.168135750","rc":[{"trd":[[15,53.59]],"batb":[[0,15,7.94]],"ltp":15.0,"tv":77.33,"id":2764710}],"tv":3782.8}]}
{"op":"mcm","clk":"1002120072","pt":1580590675802,"mc":[{"id":"1.168135750","rc":[{"batb":[[0,14,25.6],[1,12.5,8.69],[2,12,8.33]],"ltp":16.0,"tv":36.72,"id":2764715},{"batb":[[0,5.9,61.75],[1,5.6,13.25],[2,5.5,181.82]],"ltp":6.0,"tv":69.86,"id":2764722}]}]}
{"op":"mcm","clk":"1002122056","pt":1580590696211,"mc":[{"id":"1.168135750","rc":[{"trd":[[15,61.46]],"batb":[[0,15,4.01]],"ltp":15.0,"tv":85.2,"id":2764710},{"trd":[[4.6,516.39]],"batb":[[0,4.6,51.21]],"ltp":4.6,"tv":2726.34,"id":2764711}],"tv":3877.18}]}
{"op":"mcm","clk":"1002122235","pt":1580590697827,"mc":[{"id":"1.168135750","rc":[{"batb":[[0,4.6,43.16]],"ltp":4.6,"tv":2726.34,"id":2764711}]}]}
{"op":"mcm","clk":"1002141385","pt":1580590866656,"mc":[{"id":"1.168135750","rc":[{"trd":[[5.9,19.08],[6,21.19]],"batb":[[0,5.9,51.76]],"ltp":5.9,"tv":89.85,"id":2764722}],"tv":3897.18}]}
{"op":"mcm","clk":"1002149572","pt":1580590937065,"mc":[{"id":"1.168135750","rc":[{"trd":[[4.7,1355.05]],"batl":[[0,4.7,356.76]],"ltp":4.7,"tv":2730.34,"id":2764711}],"tv":3901.18}]}
{"op":"mcm","clk":"1002189013","pt":1580591274983,"mc":[{"id":"1.168135750","rc":[{"batl":[[0,15.5,38.13]],"ltp":15.0,"tv":85.2,"id":2764710}]}]}
{"op":"mcm","clk":"1002215456","pt":1580591494343,"mc":[{"id":"1.168135750","rc":[{"trd":[[8,249.96]],"batb":[[0,8,2.59],[1,7.2,10.38],[2,7,30.39]],"batl":[[0,8.8,20.71],[1,9,327.71],[2,12,27.86]],"ltp":8.0,"tv":854.11,"id":5720732}],"tv":3913.42}]}
{"op":"mcm","clk":"1002216000","pt":1580591499830,"mc":[{"id":"1.168135750","rc":[{"batb":[[1,7,30.39],[2,6.8,10.73]],"ltp":8.0,"tv":854.11,"id":5720732}]}]}
{"op":"mcm","clk":"1002217703","pt":1580591515977,"mc":[{"id":"1.168135750","rc":[{"batb":[[0,8.2,9.12],[1,8,2.59],[2,7,30.39]],"ltp":8.0,"tv":854.11,"id":5720732}]}]}
{"op":"mcm","clk":"1002242998","pt":1580591768208,"mc":[{"id":"1.168135750","rc":[{"trd":[[15.5,7.92]],"batl":[[0,15.5,34.17]],"ltp":15.5,"tv":93.12,"id":2764710}],"tv":3921.34}]}
{"op":"mcm","clk":"1002261542","pt":1580591934443,"mc":[{"id":"1.168135750","rc":[{"trd":[[15.5,25.04]],"batl":[[0,15.5,25.61]],"ltp":15.5,"tv":110.24,"id":2764710}],"tv":3938.46}]}
{"op":"mcm","clk":"1002303022","pt":1580592298991,"mc":[{"id":"1.168135750","rc":[{"trd":[[15.5,32.96]],"batl":[[0,15.5,21.65]],"ltp":15.5,"tv":118.16,"id":2764710}],"tv":3946.38}]}
{"op":"mcm","clk":"1002489792","pt":1580594369460,"mc":[{"id":"1.168135750","rc":[{"trd":[[100,0.06],[150,3.54],[160,0.94]],"batb":[[0,100,9.97],[1,50,2],[2,2.5,101.3]],"ltp":100.0,"tv":4.54,"id":5720737}],"tv":3950.92}]}
{"op":"mcm","clk":"1002490339","pt":1580594378267,"mc":[{"id":"1.168135750","rc":[{"batb":[[0,100,10.14]],"ltp":100.0,"tv":4.54,"id":5720737}]}]}
{"op":"mcm","clk":"1002490666","pt":1580594383555,"mc":[{"id":"1.168135750","rc":[{"trd":[[80,0.92],[85,2.6],[100,1.01]],"batb":[[0,80,2.07],[1,60,16.67],[2,1.01,1.01]],"ltp":80.0,"tv":4.54,"id":5720739}],"tv":3955.46}]}
{"op":"mcm","clk":"1002491328","pt":1580594393585,"mc":[{"id":"1.168135750","rc":[{"trd":[[34,4.54]],"batb":[[0,34,2.86]],"ltp":34.0,"tv":34.52,"id":5720734}],"tv":3960.0}]}
{"op":"mcm","clk":"1002492037","pt":1580594403267,"mc":[{"id":"1.168135750","rc":[{"trd":[[23,4.54]],"batb":[[0,23,15.96]],"ltp":23.0,"tv":13.03,"id":5720735}],"tv":3964.55}]}
{"op":"mcm","clk":"1002492739","pt":1580594412798,"mc":[{"id":"1.168135750","rc":[{"batb":[[0,24,3.12],[1,23,15.96],[2,12,83.33]],"ltp":23.0,"tv":13.03,"id":5720735}]}]}
{"op":"mcm","clk":"1002494077","pt":1580594430815,"mc":[{"id":"1.168135750","rc":[{"trd":[[55,4.54]],"batb":[[0,55,3.45]],"ltp":55.0,"tv":4.53,"id":2764717}],"tv":3969.08}]}
{"op":"mcm","clk":"1002495400","pt":1580594447450,"mc":[{"id":"1.168135750","rc":[{"batb":[[0,60,1.25],[1,55,3.45],[2,50,4]],"ltp":55.0,"tv":4.53,"id":2764717}]}]}
{"op":"mcm","clk":"1002525919","pt":1580594916196,"mc":[{"id":"1.168135750","rc":[{"trd":[[4.7,1594.81]],"batl":[[0,4.7,236.82]],"ltp":4.7,"tv":2970.1,"id":2764711}],"tv":4208.84}]}
{"op":"mcm","clk":"1002566156","pt":1580595414056,"mc":[{"id":"1.168135750","rc":[{"trd":[[15.5,75.64]],"batl":[[0,19.5,25.63],[1,20,53],[2,32,10.64]],"ltp":15.5,"tv":160.84,"id":2764710}],"tv":4251.52}]}
{"op":"mcm","clk":"1002566360","pt":1580595416153,"mc":[{"id":"1.168135750","rc":[{"batb":[[1,14,14.18],[2,10,100]],"ltp":15.5,"tv":160.84,"id":2764710}]}]}
{"op":"mcm","clk":"1002567820","pt":1580595432780,"mc":[{"id":"1.168135750","rc":[{"trd":[[15.5,76.24]],"batb":[[0,15.5,4.52],[1,15,4.01],[2,14,14.18]],"batl":[[0,19.5,25.33]],"ltp":15.5,"tv":161.44,"id":2764710}],"tv":4252.13}]}
{"op":"mcm","clk":"1002642237","pt":1580596497281,"mc":[{"id":"1.168135750","rc":[{"trd":[[4.7,1643.85]],"batl":[[0,4.7,212.29]],"ltp":4.7,"tv":3019.14,"id":2764711}],"tv":4301.17}]}
{"op":"mcm","clk":"1002664098","pt":1580596864264,"mc":[{"id":"1.168135750","rc":[{"trd":[[4.6,596.35]],"batb":[[0,4.6,3.21]],"ltp":4.6,"tv":3099.1,"id":2764711}],"tv":4381.12}]}
{"op":"mcm","clk":"1002664561","pt":1580596869076,"mc":[{"id":"1.168135750","rc":[{"batl":[[0,4.7,512.29]],"ltp":4.6,"tv":3099.1,"id":2764711}]}]}
{"op":"mcm","clk":"1002665317","pt":1580596877988,"mc":[{"id":"1.168135750","rc":[{"batl":[[0,15,53]],"ltp":0.0,"tv":0.0,"id":2764720}]}]}
{"op":"mcm","clk":"1002665543","pt":1580596882686,"mc":[{"id":"1.168135750","rc":[{"batl":[[0,30,53]],"ltp":0.0,"tv":0.0,"id":2764714}]}]}
{"op":"mcm","clk":"1002665858","pt":1580596888802,"mc":[{"id":"1.168135750","rc":[{"trd":[[34,8.54]],"batb":[[0,32,4.34],[1,26,4],[2,21,47.62]],"ltp":34.0,"tv":38.52,"id":5720734}],"tv":4385.12}]}
{"op":"mcm","clk":"1002667180","pt":1580596910413,"mc":[{"id":"1.168135750","rc":[{"batl":[[0,8.6,93],[1,8.8,20.71],[2,9,327.71]],"ltp":8.0,"tv":854.11,"id":5720732}]}]}
{"op":"mcm","clk":"1002667610","pt":1580596917736,"mc":[{"id":"1.168135750","rc":[{"batl":[[2,9,207.71]],"ltp":8.0,"tv":854.11,"id":5720732}]}]}
{"op":"mcm","clk":"1002730849","pt":1580597958635,"mc":[{"id":"1.168135750","rc":[{"batl":[[0,6.8,29.41],[1,7.4,10],[2,7.8,4.1]],"ltp":5.9,"tv":89.85,"id":2764722}]}]}
{"op":"mcm","clk":"1002840980","pt":1580599497561,"mc":[{"id":"1.168135750","rc":[{"trd":[[8.4,4.34],[9.8,7.38]],"batb":[[0,8.4,45.27]],"ltp":8.4,"tv":84.69,"id":5720738}],"tv":4391.12}]}
{"op":"mcm","clk":"1002841420","pt":1580599504035,"mc":[{"id":"1.168135750","rc":[{"trd":[[5.9,27.08]],"batb":[[0,5.9,47.75]],"ltp":5.9,"tv":97.86,"id":2764722}],"tv":4399.13}]}
{"op":"mcm","clk":"1002841699","pt":1580599508026,"mc":[{"id":"1.168135750","rc":[{"batb":[[0,8.6,8.7],[1,8.4,45.27],[2,8,12.5]],"ltp":8.4,"tv":84.69,"id":5720738}]}]}
{"op":"mcm","clk":"1002872805","pt":1580599900789,"mc":[{"id":"1.168135750","rc":[{"batb":[[0,9,8.5],[1,8,27.84],[2,7.8,14]],"ltp":0.0,"tv":0.0,"id":2764720}]}]}
{"op":"mcm","clk":"1002872954","pt":1580599902780,"mc":[{"id":"1.168135750","rc":[{"batb":[[1,8,23.32]],"ltp":0.0,"tv":0.0,"id":2764720}]}]}
{"op":"mcm","clk":"1002874087","pt":1580599918769,"mc":[{"id":"1.168135750","rc":[{"batb":[[0,9.2,12.06],[1,9,8.5],[2,8,23.32]],"ltp":0.0,"tv":0.0,"id":2764720}]}]}
{"op":"mcm","clk":"1002887552","pt":1580600111347,"mc":[{"id":"1.168135750","rc":[{"batb":[[0,9.4,8.5],[1,9.2,12.06]],"ltp":0.0,"tv":0.0,"id":2764720}]}]}
{"op":"mcm","clk":"1002887786","pt":1580600114974,"mc":[{"id":"1.168135750","rc":[{"batb":[[1,8,23.32],[2,7.8,14]],"ltp":0.0,"tv":0.0,"id":2764720}]}]}
{"op":"mcm","clk":"1002888762","pt":1580600130197,"mc":[{"id":"1.168135750","rc":[{"batb":[[0,9.6,11.55],[1,9.4,8.5],[2,8,23.32]],"ltp":0.0,"tv":0.0,"id":2764720}]}]}
{"op":"mcm","clk":"1002918283","pt":1580600578345,"mc":[{"id":"1.168135750","rc":[{"trd":[[8.6,53.85]],"batl":[[0,8.6,82.8]],"ltp":8.6,"tv":874.51,"id":5720732}],"tv":4419.53}]}
{"op":"mcm","clk":"1002953716","pt":1580601117016,"mc":[{"id":"1.168135750","rc":[{"trd":[[8.6,98.95]],"batl":[[0,8.6,60.25]],"ltp":8.6,"tv":919.61,"id":5720732}],"tv":4464.63}]}
{"op":"mcm","clk":"1002955983","pt":1580601146735,"mc":[{"id":"1.168135750","rc":[{"batb":[[0,9.8,8.5],[1,9.6,11.55]],"ltp":0.0,"tv":0.0,"id":2764720}]}]}
{"op":"mcm","clk":"1002956171","pt":1580601149526,"mc":[{"id":"1.168135750","rc":[{"batb":[[1,8,23.32],[2,7.8,14]],"ltp":0.0,"tv":0.0,"id":2764720}]}]}
{"op":"mcm","clk":"1002957299","pt":1580601165748,"mc":[{"id":"1.168135750","rc":[{"batb":[[0,10,11.09],[1,9.8,8.5],[2,8,23.32]],"ltp":0.0,"tv":0.0,"id":2764720}]}]}
{"op":"mcm","clk":"1002993361","pt":1580601677357,"mc":[{"id":"1.168135750","rc":[{"trd":[[5.9,37.08]],"batb":[[0,5.9,42.76]],"ltp":5.9,"tv":107.85,"id":2764722}],"tv":4474.62}]}
{"op":"mcm","clk":"1002997895","pt":1580601749250,"mc":[{"id":"1.168135750","rc":[{"batl":[[0,36,7.6]],"ltp":34.0,"tv":38.52,"id":5720734}]}]}
{"op":"mcm","clk":"1003001644","pt":1580601804695,"mc":[{"id":"1.168135750","rc":[{"trd":[[8.6,140.5]],"batl":[[0,8.6,39.46]],"ltp":8.6,"tv":961.17,"id":5720732}],"tv":4516.18}]}
{"op":"mcm","clk":"1003008557","pt":1580601911531,"mc":[{"id":"1.168135750","rc":[{"trd":[[8.6,156.28]],"batl":[[0,8.6,31.57]],"ltp":8.6,"tv":976.95,"id":5720732}],"tv":4531.96}]}
{"op":"mcm","clk":"1003010254","pt":1580601939692,"mc":[{"id":"1.168135750","rc":[{"batb":[[1,8,23.32],[2,7.8,14]],"ltp":0.0,"tv":0.0,"id":2764720}]}]}
{"op":"mcm","clk":"1003032543","pt":1580602185776,"mc":[{"id":"1.168135750","rc":[{"trd":[[8.6,163]],"batl":[[0,8.6,28.21]],"ltp":8.6,"tv":983.67,"id":5720732}],"tv":4538.68}]}
{"op":"mcm","clk":"1003113570","pt":1580603169704,"mc":[{"id":"1.168135750","rc":[{"trd":[[8.6,169.54]],"batl":[[0,8.6,24.94]],"ltp":8.6,"tv":990.21,"id":5720732}],"tv":4545.22}]}
{"op":"mcm","clk":"1003174224","pt":1580603905298,"mc":[{"id":"1.168135750","rc":[{"batb":[[2,3.8,44.57]],"ltp":4.6,"tv":3099.1,"id":2764711},{"batb":[[1,7.8,14],[2,7.4,40.52]],"ltp":0.0,"tv":0.0,"id":2764720}]}]}
{"op":"mcm","clk":"1003234228","pt":1580604878780,"mc":[{"id":"1.168135750","rc":[{"trd":[[5.9,41.27]],"batb":[[0,5.9,40.66]],"ltp":5.9,"tv":112.05,"id":2764722}],"tv":4549.41}]}
{"op":"mcm","clk":"1003236931","pt":1580604930956,"mc":[{"id":"1.168135750","rc":[{"batl":[[2,32,0]],"ltp":15.5,"tv":161.44,"id":2764710},{"batb":[[2,14,19.25]],"ltp":0.0,"tv":0.0,"id":2764714},{"batl":[[1,25,0]],"ltp":8.4,"tv":84.69,"id":5720738},{"batb":[[2,1.01,1.01]],"ltp":100.0,"tv":4.54,"id":5720737}]}]}
{"op":"mcm","clk":"1003384704","pt":1580607029464,"mc":[{"id":"1.168135750","rc":[{"batl":[[0,6.2,30],[1,6.8,29.41],[2,7.4,10]],"ltp":5.9,"tv":112.05,"id":2764722}]}]}
{"op":"mcm","clk":"1003385333","pt":1580607037763,"mc":[{"id":"1.168135750","rc":[{"batl":[[0,6,30]],"ltp":5.9,"tv":112.05,"id":2764722}]}]}
{"op":"mcm","clk":"1003386434","pt":1580607051199,"mc":[{"id":"1.168135750","rc":[{"trd":[[5.9,101.24]],"batb":[[0,5.9,10.69]],"batl":[[0,6.8,29.41],[1,7.4,10],[2,7.8,4.1]],"ltp":5.9,"tv":172.02,"id":2764722}],"tv":4609.38}]}
{"op":"mcm","clk":"1003387564","pt":1580607065413,"mc":[{"id":"1.168135750","rc":[{"batl":[[0,9,20],[1,24,6.08]],"ltp":8.4,"tv":84.69,"id":5720738}]}]}
{"op":"mcm","clk":"1003387987","pt":1580607070797,"mc":[{"id":"1.168135750","rc":[{"batl":[[0,8.8,20]],"ltp":8.4,"tv":84.69,"id":5720738}]}]}
{"op":"mcm","clk":"1003388431","pt":1580607076299,"mc":[{"id":"1.168135750","rc":[{"trd":[[8.6,17.4]],"batb":[[0,8.4,45.27],[1,8,12.5],[2,6,166.67]],"batl":[[0,8.6,11.3]],"ltp":8.6,"tv":102.08,"id":5720738}],"tv":4626.78}]}
{"op":"mcm","clk":"1003389159","pt":1580607085312,"mc":[{"id":"1.168135750","rc":[{"trd":[[8.4,26.94]],"batb":[[0,8.4,33.97]],"batl":[[0,24,6.08],[1,24,0]],"ltp":8.4,"tv":124.68,"id":5720738}],"tv":4649.38}]}
{"op":"mcm","clk":"1003468548","pt":1580608154433,"mc":[{"id":"1.168135750","rc":[{"batb":[[2,10,114.18]],"ltp":15.5,"tv":161.44,"id":2764710}]}]}
{"op":"mcm","clk":"1003469814","pt":1580608170813,"mc":[{"id":"1.168135750","rc":[{"batl":[[2,7.8,0]],"ltp":5.9,"tv":172.02,"id":2764722}]}]}
{"op":"mcm","clk":"1003470357","pt":1580608177659,"mc":[{"id":"1.168135750","rc":[{"trd":[[4.6,602.76]],"batb":[[0,4.3,8.33],[1,3.8,44.57],[2,3.5,285.71]],"batl":[[0,4.7,512.63]],"ltp":4.6,"tv":3105.51,"id":2764711}],"tv":4655.79}]}
{"op":"mcm","clk":"1003470929","pt":1580608185367,"mc":[{"id":"1.168135750","rc":[{"batl":[[0,4.7,512.29]],"ltp":4.6,"tv":3105.51,"id":2764711}]}]}
{"op":"mcm","clk":"1003472677","pt":1580608209683,"mc":[{"id":"1.168135750","rc":[{"batl":[[0,32,12.16]],"ltp":0.0,"tv":0.0,"id":5720736}]}]}
{"op":"mcm","clk":"1003490893","pt":1580608475013,"mc":[{"id":"1.168135750","rc":[{"trd":[[4.7,1659.59]],"batl":[[0,4.7,504.42]],"ltp":4.7,"tv":3121.25,"id":2764711}],"tv":4671.53}]}
{"op":"mcm","clk":"1003504134","pt":1580608682282,"mc":[{"id":"1.168135750","rc":[{"batl":[[0,4.6,12.66],[1,4.7,504.42],[2,4.8,534.75]],"ltp":4.7,"tv":3121.25,"id":2764711}]}]}
{"op":"mcm","clk":"1003512581","pt":1580608814162,"mc":[{"id":"1.168135750","rc":[{"trd":[[8.6,176.22]],"batl":[[0,8.6,21.6]],"ltp":8.6,"tv":996.89,"id":5720732}],"tv":4678.21}]}
{"op":"mcm","clk":"1003513599","pt":1580608827872,"mc":[{"id":"1.168135750","rc":[{"trd":[[10,22.17]],"batb":[[0,7.8,14],[1,7.4,40.52],[2,5,200]],"batl":[[0,15,53.07]],"ltp":10.0,"tv":22.16,"id":2764720}],"tv":4700.38}]}
{"op":"mcm","clk":"1003513881","pt":1580608832461,"mc":[{"id":"1.168135750","rc":[{"batl":[[0,4.7,504.42],[1,4.8,534.75],[2,5,563]],"ltp":4.7,"tv":3121.25,"id":2764711},{"batl":[[0,15,53]],"ltp":10.0,"tv":22.16,"id":2764720}]}]}
{"op":"mcm","clk":"1003514913","pt":1580608848272,"mc":[{"id":"1.168135750","rc":[{"batb":[[0,8,13.68],[1,7.8,14],[2,7.4,40.52]],"ltp":10.0,"tv":22.16,"id":2764720}]}]}
{"op":"mcm","clk":"1003516058","pt":1580608864908,"mc":[{"id":"1.168135750","rc":[{"batl":[[0,4.6,12.66],[1,4.7,504.42],[2,4.8,534.75]],"ltp":4.7,"tv":3121.25,"id":2764711}]}]}
{"op":"mcm","clk":"1003520272","pt":1580608919731,"mc":[{"id":"1.168135750","rc":[{"batl":[[0,29,8.92]],"ltp":23.0,"tv":13.03,"id":5720735}]}]}
{"op":"mcm","clk":"1003565854","pt":1580609589428,"mc":[{"id":"1.168135750","rc":[{"trd":[[32,6.93],[34,10.27]],"batb":[[0,26,4],[1,21,47.62],[2,1.01,1.01]],"batl":[[0,32,1.24],[1,36,2.03],[2,38,4.05]],"ltp":32.0,"tv":47.19,"id":5720734}],"tv":4709.05}]}
{"op":"mcm","clk":"1003566715","pt":1580609602766,"mc":[{"id":"1.168135750","rc":[{"batl":[[0,48,12.66],[1,50,53],[2,38,0]],"ltp":32.0,"tv":47.19,"id":5720734}]}]}
{"op":"mcm","clk":"1003566719","pt":1580609602868,"mc":[{"id":"1.168135750","rc":[{"batl":[[0,34,3.27],[1,36,4.05],[2,48,12.66]],"ltp":32.0,"tv":47.19,"id":5720734}]}]}
{"op":"mcm","clk":"1003567277","pt":1580609611079,"mc":[{"id":"1.168135750","rc":[{"batl":[[0,34,4.79]],"ltp":32.0,"tv":47.19,"id":5720734}]}]}
{"op":"mcm","clk":"1003704419","pt":1580611549199,"mc":[{"id":"1.168135750","rc":[{"batl":[[0,11,2.53],[1,24,6.08]],"ltp":8.4,"tv":124.68,"id":5720738},{"batl":[[1,7.4,12.53]],"ltp":5.9,"tv":172.02,"id":2764722}]}]}
{"op":"mcm","clk":"1003879009","pt":1580615017406,"mc":[{"id":"1.168135750","rc":[{"batl":[[0,9.8,10.13],[1,11,2.53],[2,24,6.08]],"ltp":8.4,"tv":124.68,"id":5720738}]}]}
{"op":"mcm","clk":"1003880251","pt":1580615065481,"mc":[{"id":"1.168135750","rc":[{"batl":[[0,34,6.31]],"ltp":32.0,"tv":47.19,"id":5720734}]}]}
{"op":"mcm","clk":"1003899275","pt":1580615683827,"mc":[{"id":"1.168135750","rc":[{"trd":[[4.6,618.69]],"batl":[[0,4.6,4.7]],"ltp":4.6,"tv":3137.19,"id":2764711}],"tv":4724.98}]}
{"op":"mcm","clk":"1003907704","pt":1580615915764,"mc":[{"id":"1.168135750","rc":[{"trd":[[9.8,14.02]],"batl":[[0,9.8,6.81]],"ltp":9.8,"tv":131.32,"id":5720738}],"tv":4731.62}]}
{"op":"mcm","clk":"1003925215","pt":1580616326503,"mc":[{"id":"1.168135750","rc":[{"trd":[[4.6,628.1]],"batb":[[0,4.6,3.31],[1,4.3,8.33],[2,3.8,44.57]],"batl":[[0,4.7,504.42],[1,4.8,534.75],[2,5,563]],"ltp":4.6,"tv":3146.6,"id":2764711}],"tv":4741.03}]}
{"op":"mcm","clk":"1003937554","pt":1580616620884,"mc":[{"id":"1.168135750","rc":[{"trd":[[4.7,1666.05]],"batl":[[0,4.7,501.19]],"ltp":4.7,"tv":3153.06,"id":2764711}],"tv":4747.49}]}
{"op":"mcm","clk":"1003949065","pt":1580616853059,"mc":[{"id":"1.168135750","rc":[{"batb":[[1,4.3,20.99]],"ltp":4.7,"tv":3153.06,"id":2764711}]}]}
{"op":"mcm","clk":"1004030819","pt":1580618585218,"mc":[{"id":"1.168135750","rc":[{"trd":[[4.7,1681.75]],"batl":[[0,4.7,493.34]],"ltp":4.7,"tv":3168.76,"id":2764711}],"tv":4763.19}]}
{"op":"mcm","clk":"1004050652","pt":1580619006708,"mc":[{"id":"1.168135750","rc":[{"trd":[[9.8,20.67]],"batl":[[0,9.8,3.48]],"ltp":9.8,"tv":137.98,"id":5720738}],"tv":4769.85}]}
{"op":"mcm","clk":"1004059959","pt":1580619259581,"mc":[{"id":"1.168135750","rc":[{"batl":[[0,1000,2.53]],"ltp":16.0,"tv":36.72,"id":2764715}]}]}
{"op":"mcm","clk":"1004060418","pt":1580619272178,"mc":[{"id":"1.168135750","rc":[{"batl":[[0,1000,2.53]],"ltp":55.0,"tv":4.53,"id":2764717}]}]}
{"op":"mcm","clk":"1004087505","pt":1580619992504,"mc":[{"id":"1.168135750","rc":[{"trd":[[24,5.07]],"batb":[[0,23,16.54],[1,12,83.33],[2,1.01,1.01]],"ltp":24.0,"tv":18.1,"id":5720735}],"tv":4774.92}]}
{"op":"mcm","clk":"1004087846","pt":1580619999805,"mc":[{"id":"1.168135750","rc":[{"trd":[[8.2,5.07]],"batb":[[0,8.2,6.58]],"ltp":8.2,"tv":1001.96,"id":5720732}],"tv":4779.99}]}
{"op":"mcm","clk":"1004088065","pt":1580620003924,"mc":[{"id":"1.168135750","rc":[{"trd":[[26,5.07]],"batb":[[0,26,2.85]],"ltp":26.0,"tv":5.06,"id":5720736}],"tv":4785.06}]}
{"op":"mcm","clk":"1004088527","pt":1580620013933,"mc":[{"id":"1.168135750","rc":[{"batb":[[0,27,2.77],[1,26,2.85],[2,25,14.13]],"ltp":26.0,"tv":5.06,"id":5720736}]}]}
{"op":"mcm","clk":"1004088784","pt":1580620020286,"mc":[{"id":"1.168135750","rc":[{"trd":[[8.4,37.07]],"batb":[[0,8.4,28.91]],"ltp":8.4,"tv":148.11,"id":5720738}],"tv":4795.19}]}
{"op":"mcm","clk":"1004174432","pt":1580622140961,"mc":[{"id":"1.168135750","rc":[{"batb":[[0,4.3,20.99],[1,3.8,44.57],[2,3.5,285.71]],"ltp":4.7,"tv":3168.76,"id":2764711}]}]}
{"op":"mcm","clk":"1004182056","pt":1580622374553,"mc":[{"id":"1.168135750","rc":[{"trd":[[8.4,44.67]],"batb":[[0,8.4,25.11]],"ltp":8.4,"tv":155.71,"id":5720738}],"tv":4802.78}]}
{"op":"mcm","clk":"1004203196","pt":1580623035533,"mc":[{"id":"1.168135750","rc":[{"batb":[[2,10.5,1.61]],"batl":[[0,19.5,26.15],[2,1000,2.53]],"ltp":15.5,"tv":161.44,"id":2764710},{"batb":[[0,8.2,2.13],[1,8,13.68],[2,7.8,14]],"batl":[[1,1000,3.17]],"ltp":10.0,"tv":22.16,"id":2764720},{"batb":[[1,60,16.88],[2,1.5,2.53]],"ltp":80.0,"tv":4.54,"id":5720739},{"batb":[[2,14.5,1.13]],"batl":[[0,30,53.55],[1,1000,2.53]],"ltp":0.0,"tv":0.0,"id":2764714},{"batb":[[0,14.5,1.13],[1,14,25.6],[2,12.5,8.69]],"ltp":16.0,"tv":36.72,"id":2764715},{"batl":[[2,24,6.81]],"ltp":8.4,"tv":155.71,"id":5720738},{"batb":[[0,60,1.51]],"ltp":55.0,"tv":4.53,"id":2764717},{"batl":[[1,80,3.3],[2,1000,2.53]],"ltp":24.0,"tv":18.1,"id":5720735},{"batb":[[1,21,48.35],[2,1.5,2.53]],"batl":[[2,48,12.99]],"ltp":32.0,"tv":47.19,"id":5720734},{"batb":[[0,100,10.28],[2,1.5,2.53]],"ltp":100.0,"tv":4.54,"id":5720737},{"batl":[[2,1000,2.76]],"ltp":26.0,"tv":5.06,"id":5720736},{"batb":[[1,5.7,3.26],[2,5.6,13.25]],"batl":[[2,13.5,1.23]],"ltp":5.9,"tv":172.02,"id":2764722},{"batb":[[2,7.2,2.47]],"ltp":8.2,"tv":1001.96,"id":5720732}]}]}
{"op":"mcm","clk":"1004203694","pt":1580623056052,"mc":[{"id":"1.168135750","rc":[{"batb":[[2,11,1.61]],"ltp":15.5,"tv":161.44,"id":2764710}]}]}
{"op":"mcm","clk":"1004204655","pt":1580623087152,"mc":[{"id":"1.168135750","rc":[{"batb":[[1,5.6,13.25],[2,5.5,181.82]],"ltp":5.9,"tv":172.02,"id":2764722}]}]}
{"op":"mcm","clk":"1004206702","pt":1580623159275,"mc":[{"id":"1.168135750","rc":[{"batb":[[2,11.5,1.61]],"ltp":15.5,"tv":161.44,"id":2764710}]}]}
{"op":"mcm","clk":"1004208735","pt":1580623221559,"mc":[{"id":"1.168135750","rc":[{"batl":[[0,25,11.24],[1,30,53.55],[2,1000,2.53]],"ltp":0.0,"tv":0.0,"id":2764714}]}]}
{"op":"mcm","clk":"1004208910","pt":1580623227276,"mc":[{"id":"1.168135750","rc":[{"batl":[[2,13,1.23]],"ltp":5.9,"tv":172.02,"id":2764722}]}]}
{"op":"mcm","clk":"1004209979","pt":1580623259229,"mc":[{"id":"1.168135750","rc":[{"batb":[[2,12,1.61]],"ltp":15.5,"tv":161.44,"id":2764710}]}]}
{"op":"mcm","clk":"1004213319","pt":1580623355472,"mc":[{"id":"1.168135750","rc":[{"batb":[[2,12.5,1.61]],"ltp":15.5,"tv":161.44,"id":2764710}]}]}
{"op":"mcm","clk":"1004214831","pt":1580623400632,"mc":[{"id":"1.168135750","rc":[{"batl":[[0,6.6,15.2],[1,6.8,29.41],[2,7.4,12.53]],"ltp":5.9,"tv":172.02,"id":2764722}]}]}
{"op":"mcm","clk":"1004214902","pt":1580623402530,"mc":[{"id":"1.168135750","rc":[{"batb":[[0,15,1.13]],"ltp":16.0,"tv":36.72,"id":2764715}]}]}
{"op":"mcm","clk":"1004216639","pt":1580623454527,"mc":[{"id":"1.168135750","rc":[{"batb":[[2,13,1.61]],"ltp":15.5,"tv":161.44,"id":2764710}]}]}
{"op":"mcm","clk":"1004217652","pt":1580623488494,"mc":[{"id":"1.168135750","rc":[{"batb":[[2,10.5,1.61]],"ltp":15.5,"tv":161.44,"id":2764710}]}]}
{"op":"mcm","clk":"1004220805","pt":1580623588603,"mc":[{"id":"1.168135750","rc":[{"batb":[[2,11,1.61]],"ltp":15.5,"tv":161.44,"id":2764710}]}]}
{"op":"mcm","clk":"1004222683","pt":1580623655013,"mc":[{"id":"1.168135750","rc":[{"trd":[[5.9,111.68]],"batb":[[0,5.9,5.48]],"ltp":5.9,"tv":182.46,"id":2764722}],"tv":4813.22}]}
{"op":"mcm","clk":"1004222884","pt":1580623663818,"mc":[{"id":"1.168135750","rc":[{"batb":[[0,14.5,1.13]],"ltp":16.0,"tv":36.72,"id":2764715}]}]}
{"op":"mcm","clk":"1004223559","pt":1580623690770,"mc":[{"id":"1.168135750","rc":[{"batb":[[2,11.5,1.61]],"ltp":15.5,"tv":161.44,"id":2764710}]}]}
{"op":"mcm","clk":"1004228741","pt":1580623881064,"mc":[{"id":"1.168135750","rc":[{"batb":[[2,12,1.61]],"ltp":15.5,"tv":161.44,"id":2764710}]}]}
{"op":"mcm","clk":"1004231853","pt":1580623973023,"mc":[{"id":"1.168135750","rc":[{"batb":[[2,12.5,1.61]],"ltp":15.5,"tv":161.44,"id":2764710}]}]}
{"op":"mcm","clk":"1004234649","pt":1580624067178,"mc":[{"id":"1.168135750","rc":[{"batb":[[2,13,1.61]],"ltp":15.5,"tv":161.44,"id":2764710}]}]}
{"op":"mcm","clk":"1004235480","pt":1580624092687,"mc":[{"id":"1.168135750","rc":[{"batb":[[2,10.5,1.61]],"ltp":15.5,"tv":161.44,"id":2764710}]}]}
{"op":"mcm","clk":"1004238627","pt":1580624189345,"mc":[{"id":"1.168135750","rc":[{"batb":[[2,11,1.61]],"ltp":15.5,"tv":161.44,"id":2764710}]}]}
{"op":"mcm","clk":"1004241511","pt":1580624287431,"mc":[{"id":"1.168135750","rc":[{"batb":[[2,11.5,1.61]],"ltp":15.5,"tv":161.44,"id":2764710}]}]}
{"op":"mcm","clk":"1004244470","pt":1580624377559,"mc":[{"id":"1.168135750","rc":[{"batb":[[2,12,1.61]],"ltp":15.5,"tv":161.44,"id":2764710}]}]}
{"op":"mcm","clk":"1004245869","pt":1580624417631,"mc":[{"id":"1.168135750","rc":[{"batl":[[0,30,53.55],[1,1000,2.53],[2,1000,0]],"ltp":0.0,"tv":0.0,"id":2764714}]}]}
{"op":"mcm","clk":"1004247962","pt":1580624470570,"mc":[{"id":"1.168135750","rc":[{"batb":[[2,12.5,1.61]],"ltp":15.5,"tv":161.44,"id":2764710}]}]}
{"op":"mcm","clk":"1004250973","pt":1580624565744,"mc":[{"id":"1.168135750","rc":[{"batb":[[2,10,114.18]],"ltp":15.5,"tv":161.44,"id":2764710}]}]}
{"op":"mcm","clk":"1004250977","pt":1580624565850,"mc":[{"id":"1.168135750","rc":[{"batb":[[2,13,1.61]],"ltp":15.5,"tv":161.44,"id":2764710}]}]}
{"op":"mcm","clk":"1004251695","pt":1580624589811,"mc":[{"id":"1.168135750","rc":[{"batb":[[2,10.5,1.61]],"ltp":15.5,"tv":161.44,"id":2764710}]}]}
{"op":"mcm","clk":"1004252957","pt":1580624630769,"mc":[{"id":"1.168135750","rc":[{"batb":[[2,10,114.18]],"batl":[[0,19.5,25.33],[2,1000,0]],"ltp":15.5,"tv":161.44,"id":2764710},{"batb":[[0,8,13.68],[1,7.8,14],[2,7.4,40.52]],"batl":[[1,1000,0]],"ltp":10.0,"tv":22.16,"id":2764720},{"batb":[[1,60,16.67],[2,1.01,1.01]],"ltp":80.0,"tv":4.54,"id":5720739},{"batb":[[2,14,19.25]],"batl":[[0,30,53],[1,1000,0]],"ltp":0.0,"tv":0.0,"id":2764714},{"batb":[[0,14,25.6],[1,12.5,8.69],[2,12,8.33]],"ltp":16.0,"tv":36.72,"id":2764715},{"batl":[[2,24,6.08]],"ltp":8.4,"tv":155.71,"id":5720738},{"batb":[[0,60,1.25]],"ltp":55.0,"tv":4.53,"id":2764717},{"batl":[[1,80,3.04],[2,1000,0]],"ltp":24.0,"tv":18.1,"id":5720735},{"batb":[[1,21,47.62],[2,1.01,1.01]],"batl":[[2,48,12.66]],"ltp":32.0,"tv":47.19,"id":5720734},{"batb":[[0,100,10.14],[2,1.01,1.01]],"ltp":100.0,"tv":4.54,"id":5720737},{"batl":[[2,1000,0]],"ltp":26.0,"tv":5.06,"id":5720736},{"batb":[[2,7,30.39]],"ltp":8.2,"tv":1001.96,"id":5720732}]}]}
{"op":"mcm","clk":"1004253308","pt":1580624641694,"mc":[{"id":"1.168135750","rc":[{"batl":[[2,1000,2.53]],"ltp":15.5,"tv":161.44,"id":2764710},{"batl":[[1,1000,2.53]],"ltp":10.0,"tv":22.16,"id":2764720},{"batb":[[2,1.5,2.53]],"ltp":80.0,"tv":4.54,"id":5720739},{"batl":[[1,1000,2.53]],"ltp":0.0,"tv":0.0,"id":2764714},{"batl":[[2,1000,2.53]],"ltp":24.0,"tv":18.1,"id":5720735},{"batb":[[2,1.5,2.53]],"ltp":32.0,"tv":47.19,"id":5720734},{"batb":[[2,1.5,2.53]],"ltp":100.0,"tv":4.54,"id":5720737},{"batl":[[2,1000,2.53]],"ltp":26.0,"tv":5.06,"id":5720736},{"batb":[[2,7.2,2.63]],"ltp":8.2,"tv":1001.96,"id":5720732}]}]}
{"op":"mcm","clk":"1004253336","pt":1580624642315,"mc":[{"id":"1.168135750","rc":[{"batb":[[2,10.5,1.72]],"batl":[[0,19.5,26.21]],"ltp":15.5,"tv":161.44,"id":2764710},{"batb":[[0,8.2,2.27],[1,8,13.68],[2,7.8,14]],"batl":[[1,1000,3.21]],"ltp":10.0,"tv":22.16,"id":2764720},{"batb":[[1,60,16.89]],"ltp":80.0,"tv":4.54,"id":5720739},{"batb":[[2,14.5,1.21]],"batl":[[0,30,53.58]],"ltp":0.0,"tv":0.0,"id":2764714},{"batb":[[0,14.5,1.21],[1,14,25.6],[2,12.5,8.69]],"ltp":16.0,"tv":36.72,"id":2764715},{"batl":[[2,24,6.86]],"ltp":8.4,"tv":155.71,"id":5720738},{"batb":[[0,60,1.53]],"ltp":55.0,"tv":4.53,"id":2764717},{"batl":[[1,80,3.32]],"ltp":24.0,"tv":18.1,"id":5720735},{"batb":[[1,21,48.4]],"batl":[[2,48,13.01]],"ltp":32.0,"tv":47.19,"id":5720734},{"batb":[[0,100,10.29]],"ltp":100.0,"tv":4.54,"id":5720737},{"batl":[[2,1000,2.77]],"ltp":26.0,"tv":5.06,"id":5720736}]}]}
{"op":"mcm","clk":"1004253854","pt":1580624659737,"mc":[{"id":"1.168135750","rc":[{"batl":[[2,48,12.66]],"ltp":32.0,"tv":47.19,"id":5720734}]}]}
{"op":"mcm","clk":"1004253859","pt":1580624659840,"mc":[{"id":"1.168135750","rc":[{"batl":[[2,48,13.01]],"ltp":32.0,"tv":47.19,"id":5720734}]}]}
{"op":"mcm","clk":"1004254386","pt":1580624680753,"mc":[{"id":"1.168135750","rc":[{"batb":[[2,10,114.18]],"ltp":15.5,"tv":161.44,"id":2764710}]}]}
{"op":"mcm","clk":"1004254394","pt":1580624680859,"mc":[{"id":"1.168135750","rc":[{"batb":[[2,11,1.72]],"ltp":15.5,"tv":161.44,"id":2764710}]}]}
{"op":"mcm","clk":"1004254747","pt":1580624693780,"mc":[{"id":"1.168135750","rc":[{"batb":[[2,10,114.18]],"batl":[[0,19.5,25.33],[2,1000,0]],"ltp":15.5,"tv":161.44,"id":2764710},{"batb":[[0,8,13.68],[1,7.8,14],[2,7.4,40.52]],"batl":[[1,1000,0]],"ltp":10.0,"tv":22.16,"id":2764720},{"batb":[[1,60,16.67],[2,1.01,1.01]],"ltp":80.0,"tv":4.54,"id":5720739},{"batb":[[2,14,19.25]],"batl":[[0,30,53],[1,1000,0]],"ltp":0.0,"tv":0.0,"id":2764714},{"batb":[[0,14,25.6],[1,12.5,8.69],[2,12,8.33]],"ltp":16.0,"tv":36.72,"id":2764715},{"batl":[[2,24,6.08]],"ltp":8.4,"tv":155.71,"id":5720738},{"batb":[[0,60,1.25]],"ltp":55.0,"tv":4.53,"id":2764717},{"batl":[[1,80,3.04],[2,1000,0]],"ltp":24.0,"tv":18.1,"id":5720735},{"batb":[[1,21,47.62],[2,1.01,1.01]],"batl":[[2,48,12.66]],"ltp":32.0,"tv":47.19,"id":5720734},{"batb":[[0,100,10.14],[2,1.01,1.01]],"ltp":100.0,"tv":4.54,"id":5720737},{"batl":[[2,1000,0]],"ltp":26.0,"tv":5.06,"id":5720736},{"batb":[[2,7,30.39]],"ltp":8.2,"tv":1001.96,"id":5720732}]}]}
{"op":"mcm","clk":"1004259532","pt":1580624845815,"mc":[{"id":"1.168135750","rc":[{"batl":[[2,1000,2.53]],"ltp":15.5,"tv":161.44,"id":2764710},{"batl":[[1,1000,2.53]],"ltp":10.0,"tv":22.16,"id":2764720},{"batb":[[2,1.5,2.53]],"ltp":80.0,"tv":4.54,"id":5720739},{"batl":[[1,1000,2.53]],"ltp":0.0,"tv":0.0,"id":2764714},{"batl":[[2,1000,2.53]],"ltp":24.0,"tv":18.1,"id":5720735},{"batb":[[2,1.5,2.53]],"ltp":32.0,"tv":47.19,"id":5720734},{"batb":[[2,1.5,2.53]],"ltp":100.0,"tv":4.54,"id":5720737},{"batl":[[2,1000,2.53]],"ltp":26.0,"tv":5.06,"id":5720736},{"batb":[[2,7.2,2.65]],"ltp":8.2,"tv":1001.96,"id":5720732}]}]}
{"op":"mcm","clk":"1004259544","pt":1580624846428,"mc":[{"id":"1.168135750","rc":[{"batb":[[2,10.5,1.73]],"batl":[[0,19.5,26.22]],"ltp":15.5,"tv":161.44,"id":2764710},{"batb":[[0,8.2,2.29],[1,8,13.68],[2,7.8,14]],"batl":[[1,1000,3.22]],"ltp":10.0,"tv":22.16,"id":2764720},{"batb":[[1,60,16.89]],"ltp":80.0,"tv":4.54,"id":5720739},{"batb":[[2,14.5,1.22]],"batl":[[0,30,53.59]],"ltp":0.0,"tv":0.0,"id":2764714},{"batb":[[0,14.5,1.22],[1,14,25.6],[2,12.5,8.69]],"ltp":16.0,"tv":36.72,"id":2764715},{"batl":[[2,24,6.86]],"ltp":8.4,"tv":155.71,"id":5720738},{"batb":[[0,60,1.53]],"ltp":55.0,"tv":4.53,"id":2764717},{"batl":[[1,80,3.32]],"ltp":24.0,"tv":18.1,"id":5720735},{"batb":[[1,21,48.41]],"batl":[[2,48,13.01]],"ltp":32.0,"tv":47.19,"id":5720734},{"batb":[[0,100,10.29]],"ltp":100.0,"tv":4.54,"id":5720737},{"batl":[[2,1000,2.77]],"ltp":26.0,"tv":5.06,"id":5720736}]}]}
{"op":"mcm","clk":"1004260108","pt":1580624864247,"mc":[{"id":"1.168135750","rc":[{"batb":[[2,11,1.73]],"ltp":15.5,"tv":161.44,"id":2764710}]}]}
{"op":"mcm","clk":"1004260804","pt":1580624889011,"mc":[{"id":"1.168135750","rc":[{"batb":[[2,10,114.18]],"batl":[[0,19.5,25.33],[2,1000,0]],"ltp":15.5,"tv":161.44,"id":2764710},{"batb":[[0,8,13.68],[1,7.8,14],[2,7.4,40.52]],"batl":[[1,1000,0]],"ltp":10.0,"tv":22.16,"id":2764720},{"batb":[[1,60,16.67],[2,1.01,1.01]],"ltp":80.0,"tv":4.54,"id":5720739},{"batb":[[2,14,19.25]],"batl":[[0,30,53],[1,1000,0]],"ltp":0.0,"tv":0.0,"id":2764714},{"batb":[[0,14,25.6],[1,12.5,8.69],[2,12,8.33]],"ltp":16.0,"tv":36.72,"id":2764715},{"batl":[[2,24,6.08]],"ltp":8.4,"tv":155.71,"id":5720738},{"batb":[[0,60,1.25]],"ltp":55.0,"tv":4.53,"id":2764717},{"batl":[[1,80,3.04],[2,1000,0]],"ltp":24.0,"tv":18.1,"id":5720735},{"batb":[[1,21,47.62],[2,1.01,1.01]],"batl":[[2,48,12.66]],"ltp":32.0,"tv":47.19,"id":5720734},{"batb":[[0,100,10.14],[2,1.01,1.01]],"ltp":100.0,"tv":4.54,"id":5720737},{"batl":[[2,1000,0]],"ltp":26.0,"tv":5.06,"id":5720736},{"batb":[[2,7,30.39]],"ltp":8.2,"tv":1001.96,"id":5720732}]}]}
{"op":"mcm","clk":"1004261465","pt":1580624909449,"mc":[{"id":"1.168135750","rc":[{"batb":[[2,10.5,1.74]],"batl":[[0,19.5,26.22],[2,1000,2.53]],"ltp":15.5,"tv":161.44,"id":2764710},{"batb":[[0,8.2,2.29],[1,8,13.68],[2,7.8,14]],"batl":[[1,1000,3.22]],"ltp":10.0,"tv":22.16,"id":2764720},{"batb":[[1,60,16.89],[2,1.5,2.53]],"ltp":80.0,"tv":4.54,"id":5720739},{"batb":[[2,14.5,1.22]],"batl":[[0,30,53.59],[1,1000,2.53]],"ltp":0.0,"tv":0.0,"id":2764714},{"batb":[[0,14.5,1.22],[1,14,25.6],[2,12.5,8.69]],"ltp":16.0,"tv":36.72,"id":2764715},{"batl":[[2,24,6.86]],"ltp":8.4,"tv":155.71,"id":5720738},{"batb":[[0,60,1.53]],"ltp":55.0,"tv":4.53,"id":2764717},{"batl":[[1,80,3.32],[2,1000,2.53]],"ltp":24.0,"tv":18.1,"id":5720735},{"batb":[[1,21,48.41],[2,1.5,2.53]],"batl":[[2,48,13.01]],"ltp":32.0,"tv":47.19,"id":5720734},{"batb":[[0,100,10.29],[2,1.5,2.53]],"ltp":100.0,"tv":4.54,"id":5720737},{"batl":[[2,1000,2.77]],"ltp":26.0,"tv":5.06,"id":5720736},{"batb":[[2,7.2,2.66]],"ltp":8.2,"tv":1001.96,"id":5720732}]}]}
{"op":"mcm","clk":"1004262538","pt":1580624956221,"mc":[{"id":"1.168135750","rc":[{"batb":[[2,11,1.74]],"ltp":15.5,"tv":161.44,"id":2764710}]}]}
{"op":"mcm","clk":"1004265135","pt":1580625051384,"mc":[{"id":"1.168135750","rc":[{"batb":[[2,11.5,1.74]],"ltp":15.5,"tv":161.44,"id":2764710}]}]}
{"op":"mcm","clk":"1004268163","pt":1580625153449,"mc":[{"id":"1.168135750","rc":[{"batb":[[2,12,1.74]],"ltp":15.5,"tv":161.44,"id":2764710}]}]}
{"op":"mcm","clk":"1004268336","pt":1580625159756,"mc":[{"id":"1.168135750","rc":[{"batl":[[0,16,6.08],[1,1000,2.53]],"ltp":16.0,"tv":36.72,"id":2764715}]}]}
{"op":"mcm","clk":"1004268608","pt":1580625170645,"mc":[{"id":"1.168135750","rc":[{"batb":[[0,14,25.6],[1,12.5,8.69],[2,12,8.33]],"batl":[[1,1000,5.68]],"ltp":16.0,"tv":36.72,"id":2764715},{"batb":[[0,8.6,2.19],[1,8.4,25.11],[2,8,12.5]],"ltp":8.4,"tv":155.71,"id":5720738}]}]}
{"op":"mcm","clk":"1004268901","pt":1580625182497,"mc":[{"id":"1.168135750","rc":[{"trd":[[27,5.54]],"batb":[[0,26,2.85],[1,25,14.13],[2,17,58.82]],"batl":[[0,27,1.28],[1,32,12.16],[2,40,4.05]],"ltp":27.0,"tv":10.61,"id":5720736}],"tv":4818.76}]}
{"op":"mcm","clk":"1004269236","pt":1580625194729,"mc":[{"id":"1.168135750","rc":[{"trd":[[26,7.63]],"batb":[[0,26,1.57]],"batl":[[0,32,12.16],[1,40,4.05],[2,1000,2.77]],"ltp":26.0,"tv":13.17,"id":5720736}],"tv":4821.33}]}
{"op":"mcm","clk":"1004271162","pt":1580625251478,"mc":[{"id":"1.168135750","rc":[{"batb":[[2,12.5,1.74]],"ltp":15.5,"tv":161.44,"id":2764710}]}]}
{"op":"mcm","clk":"1004272125","pt":1580625284543,"mc":[{"id":"1.168135750","rc":[{"trd":[[8.6,21.39]],"batb":[[0,8.4,25.31],[1,8,12.5],[2,6,166.67]],"ltp":8.6,"tv":159.7,"id":5720738}],"tv":4825.32}]}
{"op":"mcm","clk":"1004272254","pt":1580625289738,"mc":[{"id":"1.168135750","rc":[{"batl":[[0,19.5,25.33]],"ltp":15.5,"tv":161.44,"id":2764710},{"batl":[[1,1000,2.53]],"ltp":10.0,"tv":22.16,"id":2764720},{"batl":[[0,30,53]],"ltp":0.0,"tv":0.0,"id":2764714},{"batl":[[1,1000,5.07]],"ltp":16.0,"tv":36.72,"id":2764715},{"batb":[[0,8.4,25.11]],"batl":[[2,24,6.08]],"ltp":8.6,"tv":159.7,"id":5720738},{"batl":[[2,48,12.66]],"ltp":32.0,"tv":47.19,"id":5720734}]}]}
{"op":"mcm","clk":"1004272258","pt":1580625289839,"mc":[{"id":"1.168135750","rc":[{"batl":[[0,19.5,25.41]],"ltp":15.5,"tv":161.44,"id":2764710},{"batl":[[1,1000,2.61]],"ltp":10.0,"tv":22.16,"id":2764720},{"batl":[[0,30,53.06]],"ltp":0.0,"tv":0.0,"id":2764714},{"batl":[[1,1000,5.13]],"ltp":16.0,"tv":36.72,"id":2764715},{"batl":[[2,24,7.03]],"ltp":8.6,"tv":159.7,"id":5720738},{"batl":[[2,48,12.7]],"ltp":32.0,"tv":47.19,"id":5720734}]}]}
{"op":"mcm","clk":"1004272677","pt":1580625303161,"mc":[{"id":"1.168135750","rc":[{"batl":[[0,6.4,2],[1,6.6,15.2],[2,6.8,29.41]],"ltp":5.9,"tv":182.46,"id":2764722}]}]}
{"op":"mcm","clk":"1004272848","pt":1580625308267,"mc":[{"id":"1.168135750","rc":[{"batl":[[0,6.2,2]],"ltp":5.9,"tv":182.46,"id":2764722}]}]}
{"op":"mcm","clk":"1004274384","pt":1580625351754,"mc":[{"id":"1.168135750","rc":[{"batb":[[2,10,114.18]],"ltp":15.5,"tv":161.44,"id":2764710}]}]}
{"op":"mcm","clk":"1004274417","pt":1580625352537,"mc":[{"id":"1.168135750","rc":[{"batb":[[2,13,1.23]],"ltp":15.5,"tv":161.44,"id":2764710}]}]}
{"op":"mcm","clk":"1004274773","pt":1580625362576,"mc":[{"id":"1.168135750","rc":[{"batb":[[2,10.5,1.23]],"ltp":15.5,"tv":161.44,"id":2764710}]}]}
{"op":"mcm","clk":"1004276366","pt":1580625414836,"mc":[{"id":"1.168135750","rc":[{"batb":[[0,8.4,25.32]],"ltp":8.6,"tv":159.7,"id":5720738}]}]}
{"op":"mcm","clk":"1004277143","pt":1580625445726,"mc":[{"id":"1.168135750","rc":[{"batb":[[2,10,114.18]],"batl":[[0,19.5,25.33],[2,1000,0]],"ltp":15.5,"tv":161.44,"id":2764710},{"batb":[[0,8,13.68],[1,7.8,14],[2,7.4,40.52]],"batl":[[1,1000,0]],"ltp":10.0,"tv":22.16,"id":2764720},{"batb":[[1,60,16.67],[2,1.01,1.01]],"ltp":80.0,"tv":4.54,"id":5720739},{"batb":[[2,14,19.25]],"batl":[[0,30,53],[1,1000,0]],"ltp":0.0,"tv":0.0,"id":2764714},{"batl":[[1,1000,2.53]],"ltp":16.0,"tv":36.72,"id":2764715},{"batb":[[0,8.4,25.11]],"batl":[[2,24,6.08]],"ltp":8.6,"tv":159.7,"id":5720738},{"batb":[[0,60,1.25]],"ltp":55.0,"tv":4.53,"id":2764717},{"batl":[[1,80,3.04],[2,1000,0]],"ltp":24.0,"tv":18.1,"id":5720735},{"batb":[[1,21,47.62],[2,1.01,1.01]],"batl":[[2,48,12.66]],"ltp":32.0,"tv":47.19,"id":5720734},{"batb":[[0,100,10.14],[2,1.01,1.01]],"ltp":100.0,"tv":4.54,"id":5720737},{"batl":[[2,1000,0]],"ltp":26.0,"tv":13.17,"id":5720736},{"batb":[[2,7,30.39]],"ltp":8.2,"tv":1001.96,"id":5720732}]}]}
{"op":"mcm","clk":"1004278012","pt":1580625478648,"mc":[{"id":"1.168135750","rc":[{"batl":[[2,1000,2.53]],"ltp":15.5,"tv":161.44,"id":2764710},{"batl":[[1,1000,2.53]],"ltp":10.0,"tv":22.16,"id":2764720},{"batb":[[2,1.5,2.53]],"ltp":80.0,"tv":4.54,"id":5720739},{"batl":[[1,1000,2.53]],"ltp":0.0,"tv":0.0,"id":2764714},{"batl":[[1,1000,5.07]],"ltp":16.0,"tv":36.72,"id":2764715},{"batl":[[2,1000,2.53]],"ltp":24.0,"tv":18.1,"id":5720735},{"batb":[[2,1.5,2.53]],"ltp":32.0,"tv":47.19,"id":5720734},{"batb":[[2,1.5,2.53]],"ltp":100.0,"tv":4.54,"id":5720737},{"batl":[[2,1000,2.53]],"ltp":26.0,"tv":13.17,"id":5720736}]}]}
{"op":"mcm","clk":"1004278029","pt":1580625479159,"mc":[{"id":"1.168135750","rc":[{"batb":[[2,10.5,1.57]],"batl":[[0,19.5,25.42]],"ltp":15.5,"tv":161.44,"id":2764710},{"batb":[[0,8.2,2.07],[1,8,13.68],[2,7.8,14]],"batl":[[1,1000,2.62]],"ltp":10.0,"tv":22.16,"id":2764720},{"batb":[[1,60,16.87]],"ltp":80.0,"tv":4.54,"id":5720739},{"batb":[[2,14.5,1.1]],"batl":[[0,30,53.06]],"ltp":0.0,"tv":0.0,"id":2764714},{"batl":[[1,1000,5.13]],"ltp":16.0,"tv":36.72,"id":2764715},{"batb":[[0,8.4,25.33]],"batl":[[2,24,7.03]],"ltp":8.6,"tv":159.7,"id":5720738},{"batb":[[0,60,1.51]],"ltp":55.0,"tv":4.53,"id":2764717},{"batl":[[1,80,3.07]],"ltp":24.0,"tv":18.1,"id":5720735},{"batb":[[1,21,48.33]],"batl":[[2,48,12.7]],"ltp":32.0,"tv":47.19,"id":5720734},{"batb":[[0,100,10.27]],"ltp":100.0,"tv":4.54,"id":5720737},{"batl":[[2,1000,2.56]],"ltp":26.0,"tv":13.17,"id":5720736},{"batb":[[2,7.2,2.4]],"ltp":8.2,"tv":1001.96,"id":5720732}]}]}
{"op":"mcm","clk":"1004278470","pt":1580625494764,"mc":[{"id":"1.168135750","rc":[{"batb":[[2,10,114.18]],"ltp":15.5,"tv":161.44,"id":2764710}]}]}
{"op":"mcm","clk":"1004278477","pt":1580625494869,"mc":[{"id":"1.168135750","rc":[{"batb":[[2,11,1.57]],"ltp":15.5,"tv":161.44,"id":2764710}]}]}
{"op":"mcm","clk":"1004282330","pt":1580625592802,"mc":[{"id":"1.168135750","rc":[{"batb":[[2,10,114.18]],"ltp":15.5,"tv":161.44,"id":2764710}]}]}
{"op":"mcm","clk":"1004282384","pt":1580625593788,"mc":[{"id":"1.168135750","rc":[{"batb":[[2,11.5,1.57]],"ltp":15.5,"tv":161.44,"id":2764710}]}]}
{"op":"mcm","clk":"1004283525","pt":1580625622737,"mc":[{"id":"1.168135750","rc":[{"trd":[[24,6.23]],"batb":[[0,23,15.96]],"batl":[[0,24,1.96],[1,29,8.92],[2,80,3.07]],"ltp":24.0,"tv":19.26,"id":5720735}],"tv":4826.48}]}
{"op":"mcm","clk":"1004283565","pt":1580625623716,"mc":[{"id":"1.168135750","rc":[{"batl":[[0,29,8.92],[1,80,3.07],[2,1000,2.53]],"ltp":24.0,"tv":19.26,"id":5720735}]}]}
{"op":"mcm","clk":"1004286033","pt":1580625689045,"mc":[{"id":"1.168135750","rc":[{"batb":[[2,12,1.57]],"ltp":15.5,"tv":161.44,"id":2764710}]}]}
{"op":"mcm","clk":"1004288517","pt":1580625774121,"mc":[{"id":"1.168135750","rc":[{"batb":[[2,12.5,1.57]],"ltp":15.5,"tv":161.44,"id":2764710}]}]}
{"op":"mcm","clk":"1004289676","pt":1580625829908,"mc":[{"id":"1.168135750","rc":[{"batb":[[2,2,2.53]],"ltp":100.0,"tv":4.54,"id":5720737}]}]}
{"op":"mcm","clk":"1004289888","pt":1580625840755,"mc":[{"id":"1.168135750","rc":[{"batb":[[2,2,4.05]],"ltp":100.0,"tv":4.54,"id":5720737}]}]}
{"op":"mcm","clk":"1004290221","pt":1580625859772,"mc":[{"id":"1.168135750","rc":[{"batb":[[0,150,1.52],[1,100,10.27],[2,50,2]],"ltp":100.0,"tv":4.54,"id":5720737}]}]}
{"op":"mcm","clk":"1004290257","pt":1580625861266,"mc":[{"id":"1.168135750","rc":[{"batb":[[2,13,1.57]],"ltp":15.5,"tv":161.44,"id":2764710}]}]}
{"op":"mcm","clk":"1004290600","pt":1580625883702,"mc":[{"id":"1.168135750","rc":[{"batb":[[2,10.5,1.57]],"ltp":15.5,"tv":161.44,"id":2764710}]}]}
{"op":"mcm","clk":"1004292580","pt":1580625973447,"mc":[{"id":"1.168135750","rc":[{"batb":[[2,11,1.57]],"ltp":15.5,"tv":161.44,"id":2764710}]}]}
{"op":"mcm","clk":"1004293138","pt":1580625996772,"mc":[{"id":"1.168135750","rc":[{"batb":[[0,15.5,6.04]],"ltp":15.5,"tv":161.44,"id":2764710}]}]}
{"op":"mcm","clk":"1004293775","pt":1580626023204,"mc":[{"id":"1.168135750","rc":[{"batl":[[1,55,2.53],[2,1000,2.53]],"ltp":0.0,"tv":0.0,"id":2764714}]}]}
{"op":"mcm","clk":"1004293847","pt":1580626026543,"mc":[{"id":"1.168135750","rc":[{"batl":[[1,55,3.04]],"ltp":0.0,"tv":0.0,"id":2764714}]}]}
{"op":"mcm","clk":"1004294289","pt":1580626042247,"mc":[{"id":"1.168135750","rc":[{"batl":[[0,30,53.57],[1,1000,2.53],[2,1000,0]],"ltp":0.0,"tv":0.0,"id":2764714}]}]}
{"op":"mcm","clk":"1004294729","pt":1580626056495,"mc":[{"id":"1.168135750","rc":[{"batb":[[2,11.5,1.57]],"ltp":15.5,"tv":161.44,"id":2764710}]}]}
{"op":"mcm","clk":"1004294783","pt":1580626058390,"mc":[{"id":"1.168135750","rc":[{"trd":[[8.2,18.22]],"batb":[[0,8,2.59],[1,7.2,2.4],[2,7,30.39]],"batl":[[0,8.2,3.56],[1,8.6,21.6],[2,8.8,20.71]],"ltp":8.2,"tv":1015.11,"id":5720732}],"tv":4839.63}]}
{"op":"mcm","clk":"1004294966","pt":1580626064795,"mc":[{"id":"1.168135750","rc":[{"batl":[[0,19.5,25.33]],"ltp":15.5,"tv":161.44,"id":2764710},{"batb":[[1,7,30.39],[2,6.8,10.73]],"batl":[[2,8.8,20.97]],"ltp":8.2,"tv":1015.11,"id":5720732}]}]}
{"op":"mcm","clk":"1004295111","pt":1580626069817,"mc":[{"id":"1.168135750","rc":[{"batb":[[0,4.4,18.71],[1,4.3,20.99],[2,3.8,44.57]],"ltp":4.7,"tv":3168.76,"id":2764711},{"batb":[[0,8.4,9.81],[1,8.2,2.07],[2,8,13.68]],"ltp":10.0,"tv":22.16,"id":2764720},{"batb":[[0,80,3.05]],"ltp":80.0,"tv":4.54,"id":5720739},{"batb":[[0,8.6,9.79],[1,8.4,25.11],[2,8,12.5]],"ltp":8.6,"tv":159.7,"id":5720738},{"batb":[[0,24,3.43],[1,23,15.96],[2,12,83.33]],"ltp":24.0,"tv":19.26,"id":5720735},{"batb":[[0,27,3.04],[1,26,4],[2,21,48.33]],"ltp":32.0,"tv":47.19,"id":5720734},{"batb":[[0,26,4.74]],"ltp":26.0,"tv":13.17,"id":5720736},{"batb":[[0,5.9,19.43]],"ltp":5.9,"tv":182.46,"id":2764722},{"batb":[[0,8,12.88]],"batl":[[0,8.6,21.6],[1,8.8,20.97],[2,9,207.71]],"ltp":8.2,"tv":1015.11,"id":5720732}]}]}
{"op":"mcm","clk":"1004295136","pt":1580626070790,"mc":[{"id":"1.168135750","rc":[{"trd":[[8,257.08]],"batb":[[0,8,9.33]],"ltp":8.0,"tv":1022.23,"id":5720732}],"tv":4846.74}]}
{"op":"mcm","clk":"1004295155","pt":1580626071505,"mc":[{"id":"1.168135750","rc":[{"batb":[[1,5.7,3.25],[2,5.6,13.25]],"ltp":5.9,"tv":182.46,"id":2764722},{"batl":[[1,8.8,20.71]],"ltp":8.0,"tv":1022.23,"id":5720732}]}]}
{"op":"mcm","clk":"1004295557","pt":1580626085441,"mc":[{"id":"1.168135750","rc":[{"trd":[[8.4,19.6]],"batb":[[0,8.2,2.07],[1,8,13.68],[2,7.8,14]],"batl":[[0,15,53.33]],"ltp":8.4,"tv":41.76,"id":2764720}],"tv":4866.34}]}
{"op":"mcm","clk":"1004295734","pt":1580626094764,"mc":[{"id":"1.168135750","rc":[{"batb":[[0,27,3.75],[2,21,47.62]],"ltp":32.0,"tv":47.19,"id":5720734}]}]}
{"op":"mcm","clk":"1004295738","pt":1580626094867,"mc":[{"id":"1.168135750","rc":[{"batb":[[0,26,5.35]],"ltp":26.0,"tv":13.17,"id":5720736}]}]}
{"op":"mcm","clk":"1004295918","pt":1580626102745,"mc":[{"id":"1.168135750","rc":[{"batl":[[0,15,53]],"ltp":8.4,"tv":41.76,"id":2764720}]}]}
{"op":"mcm","clk":"1004295921","pt":1580626102848,"mc":[{"id":"1.168135750","rc":[{"trd":[[8.2,0.67]],"batb":[[0,8.2,1.73]],"ltp":8.2,"tv":42.43,"id":2764720}],"tv":4867.01}]}
{"op":"mcm","clk":"1004296043","pt":1580626108692,"mc":[{"id":"1.168135750","rc":[{"batl":[[1,55,2.62],[2,1000,2.53]],"ltp":8.2,"tv":42.43,"id":2764720}]}]}
{"op":"mcm","clk":"1004296081","pt":1580626109616,"mc":[{"id":"1.168135750","rc":[{"batb":[[0,80,3.25],[1,60,16.67]],"ltp":80.0,"tv":4.54,"id":5720739}]}]}
{"op":"mcm","clk":"1004296138","pt":1580626113188,"mc":[{"id":"1.168135750","rc":[{"batl":[[1,55,3.13]],"ltp":8.2,"tv":42.43,"id":2764720}]}]}
{"op":"mcm","clk":"1004296242","pt":1580626117586,"mc":[{"id":"1.168135750","rc":[{"batb":[[0,80,3.05],[1,60,16.87]],"ltp":80.0,"tv":4.54,"id":5720739}]}]}
{"op":"mcm","clk":"1004296384","pt":1580626123419,"mc":[{"id":"1.168135750","rc":[{"batl":[[0,15,53.51],[1,1000,2.62],[2,1000,0]],"ltp":8.2,"tv":42.43,"id":2764720}]}]}
{"op":"mcm","clk":"1004296748","pt":1580626136604,"mc":[{"id":"1.168135750","rc":[{"batb":[[2,12,1.57]],"batl":[[0,19.5,25.46]],"ltp":15.5,"tv":161.44,"id":2764710},{"batl":[[0,15,53.59],[1,1000,2.53]],"ltp":8.2,"tv":42.43,"id":2764720}]}]}
{"op":"mcm","clk":"1004296945","pt":1580626144754,"mc":[{"id":"1.168135750","rc":[{"batb":[[1,5.6,13.25],[2,5.5,181.82]],"ltp":5.9,"tv":182.46,"id":2764722}]}]}
{"op":"mcm","clk":"1004296950","pt":1580626144856,"mc":[{"id":"1.168135750","rc":[{"batb":[[1,7.2,2.42],[2,7,30.39]],"ltp":8.0,"tv":1022.23,"id":5720732}]}]}
{"op":"mcm","clk":"1004297570","pt":1580626169748,"mc":[{"id":"1.168135750","rc":[{"batl":[[0,15,53.51]],"ltp":8.2,"tv":42.43,"id":2764720}]}]}
{"op":"mcm","clk":"1004297578","pt":1580626169954,"mc":[{"id":"1.168135750","rc":[{"batl":[[0,15,53.69]],"ltp":8.2,"tv":42.43,"id":2764720}]}]}
{"op":"mcm","clk":"1004298451","pt":1580626196789,"mc":[{"id":"1.168135750","rc":[{"batb":[[0,8,13.68],[1,7.8,14],[2,7.4,40.52]],"ltp":8.2,"tv":42.43,"id":2764720}]}]}
{"op":"mcm","clk":"1004298457","pt":1580626196893,"mc":[{"id":"1.168135750","rc":[{"batb":[[0,8.2,2.07],[1,8,13.68],[2,7.8,14]],"ltp":8.2,"tv":42.43,"id":2764720}]}]}
{"op":"mcm","clk":"1004298550","pt":1580626199604,"mc":[{"id":"1.168135750","rc":[{"batl":[[0,9.8,3.99]],"ltp":8.6,"tv":159.7,"id":5720738},{"batl":[[1,6.6,15.7]],"ltp":5.9,"tv":182.46,"id":2764722}]}]}
{"op":"mcm","clk":"1004299105","pt":1580626214727,"mc":[{"id":"1.168135750","rc":[{"batb":[[2,12.5,1.57]],"ltp":15.5,"tv":161.44,"id":2764710},{"batb":[[0,80,3.25],[1,60,16.67]],"ltp":80.0,"tv":4.54,"id":5720739}]}]}
{"op":"mcm","clk":"1004299298","pt":1580626219751,"mc":[{"id":"1.168135750","rc":[{"batb":[[0,80,3.05]],"ltp":80.0,"tv":4.54,"id":5720739}]}]}
{"op":"mcm","clk":"1004299302","pt":1580626219854,"mc":[{"id":"1.168135750","rc":[{"batb":[[1,60,16.87]],"ltp":80.0,"tv":4.54,"id":5720739}]}]}
{"op":"mcm","clk":"1004300973","pt":1580626270720,"mc":[{"id":"1.168135750","rc":[{"batb":[[1,100,10.14]],"ltp":100.0,"tv":4.54,"id":5720737}]}]}
{"op":"mcm","clk":"1004300977","pt":1580626270827,"mc":[{"id":"1.168135750","rc":[{"batb":[[1,100,10.27]],"ltp":100.0,"tv":4.54,"id":5720737}]}]}
{"op":"mcm","clk":"1004301398","pt":1580626288773,"mc":[{"id":"1.168135750","rc":[{"batl":[[0,30,53.06]],"ltp":0.0,"tv":0.0,"id":2764714}]}]}
{"op":"mcm","clk":"1004301421","pt":1580626289752,"mc":[{"id":"1.168135750","rc":[{"batl":[[0,30,53.57]],"ltp":0.0,"tv":0.0,"id":2764714},{"batb":[[1,100,10.14]],"ltp":100.0,"tv":4.54,"id":5720737}]}]}
{"op":"mcm","clk":"1004301425","pt":1580626289852,"mc":[{"id":"1.168135750","rc":[{"batb":[[1,100,10.27]],"ltp":100.0,"tv":4.54,"id":5720737}]}]}
{"op":"mcm","clk":"1004301617","pt":1580626295763,"mc":[{"id":"1.168135750","rc":[{"batb":[[2,10,114.18]],"ltp":15.5,"tv":161.44,"id":2764710}]}]}
{"op":"mcm","clk":"1004301621","pt":1580626295864,"mc":[{"id":"1.168135750","rc":[{"batb":[[2,13,1.57]],"ltp":15.5,"tv":161.44,"id":2764710}]}]}
{"op":"mcm","clk":"1004301737","pt":1580626300174,"mc":[{"id":"1.168135750","rc":[{"batb":[[0,160,1.52]],"ltp":100.0,"tv":4.54,"id":5720737}]}]}
{"op":"mcm","clk":"1004302084","pt":1580626311773,"mc":[{"id":"1.168135750","rc":[{"batb":[[2,10,114.18]],"ltp":15.5,"tv":161.44,"id":2764710}]}]}
{"op":"mcm","clk":"1004302091","pt":1580626311976,"mc":[{"id":"1.168135750","rc":[{"batb":[[2,10.5,1.57]],"ltp":15.5,"tv":161.44,"id":2764710}]}]}
{"op":"mcm","clk":"1004302456","pt":1580626321797,"mc":[{"id":"1.168135750","rc":[{"batb":[[1,60,16.67]],"ltp":80.0,"tv":4.54,"id":5720739}]}]}
{"op":"mcm","clk":"1004302460","pt":1580626321900,"mc":[{"id":"1.168135750","rc":[{"batb":[[0,80,3.25]],"ltp":80.0,"tv":4.54,"id":5720739}]}]}
{"op":"mcm","clk":"1004302695","pt":1580626328817,"mc":[{"id":"1.168135750","rc":[{"batb":[[0,80,3.05]],"ltp":80.0,"tv":4.54,"id":5720739}]}]}
{"op":"mcm","clk":"1004302700","pt":1580626328919,"mc":[{"id":"1.168135750","rc":[{"batb":[[1,60,16.87]],"ltp":80.0,"tv":4.54,"id":5720739}]}]}
{"op":"mcm","clk":"1004303690","pt":1580626357578,"mc":[{"id":"1.168135750","rc":[{"batb":[[0,4.5,12.66],[1,4.4,18.71],[2,4.3,8.33]],"ltp":4.7,"tv":3168.76,"id":2764711}]}]}
{"op":"mcm","clk":"1004303998","pt":1580626365753,"mc":[{"id":"1.168135750","rc":[{"batb":[[0,26,4.74]],"ltp":26.0,"tv":13.17,"id":5720736}]}]}
{"op":"mcm","clk":"1004305322","pt":1580626400020,"mc":[{"id":"1.168135750","rc":[{"batb":[[2,11,1.57]],"ltp":15.5,"tv":161.44,"id":2764710}]}]}
{"op":"mcm","clk":"1004306308","pt":1580626424035,"mc":[{"id":"1.168135750","rc":[{"batb":[[0,80,3.25],[1,60,16.67]],"ltp":80.0,"tv":4.54,"id":5720739}]}]}
{"op":"mcm","clk":"1004306630","pt":1580626434177,"mc":[{"id":"1.168135750","rc":[{"batb":[[0,80,3.05],[1,60,16.87]],"ltp":80.0,"tv":4.54,"id":5720739}]}]}
{"op":"mcm","clk":"1004308218","pt":1580626480450,"mc":[{"id":"1.168135750","rc":[{"batb":[[2,11.5,1.57]],"ltp":15.5,"tv":161.44,"id":2764710}]}]}
{"op":"mcm","clk":"1004310330","pt":1580626537747,"mc":[{"id":"1.168135750","rc":[{"batb":[[0,80,3.25],[1,60,16.67]],"ltp":80.0,"tv":4.54,"id":5720739}]}]}
{"op":"mcm","clk":"1004310597","pt":1580626545124,"mc":[{"id":"1.168135750","rc":[{"batb":[[0,80,3.05],[1,60,16.87]],"ltp":80.0,"tv":4.54,"id":5720739}]}]}
{"op":"mcm","clk":"1004311252","pt":1580626561269,"mc":[{"id":"1.168135750","rc":[{"batb":[[2,12,1.57]],"ltp":15.5,"tv":161.44,"id":2764710}]}]}
{"op":"mcm","clk":"1004311573","pt":1580626570960,"mc":[{"id":"1.168135750","rc":[{"batl":[[0,20,53.13],[1,1000,2.53],[2,1000,0]],"ltp":15.5,"tv":161.44,"id":2764710}]}]}
{"op":"mcm","clk":"1004312470","pt":1580626589499,"mc":[{"id":"1.168135750","rc":[{"batb":[[2,7,60.78]],"ltp":8.0,"tv":1022.23,"id":5720732}]}]}
{"op":"mcm","clk":"1004313355","pt":1580626617666,"mc":[{"id":"1.168135750","rc":[{"batl":[[1,8.8,51.1]],"ltp":8.0,"tv":1022.23,"id":5720732}]}]}
{"op":"mcm","clk":"1004314118","pt":1580626639622,"mc":[{"id":"1.168135750","rc":[{"batb":[[2,12.5,1.57]],"ltp":15.5,"tv":161.44,"id":2764710},{"batb":[[0,80,3.25],[1,60,16.67]],"ltp":80.0,"tv":4.54,"id":5720739}]}]}
{"op":"mcm","clk":"1004314317","pt":1580626646409,"mc":[{"id":"1.168135750","rc":[{"batb":[[0,80,3.05],[1,60,16.87]],"ltp":80.0,"tv":4.54,"id":5720739}]}]}
{"op":"mcm","clk":"1004315247","pt":1580626676162,"mc":[{"id":"1.168135750","rc":[{"batl":[[0,15,2.53],[1,16,6.08],[2,1000,5.13]],"ltp":16.0,"tv":36.72,"id":2764715},{"batl":[[0,28,2.53],[1,32,12.16],[2,40,4.05]],"ltp":26.0,"tv":13.17,"id":5720736}]}]}
{"op":"mcm","clk":"1004316396","pt":1580626714433,"mc":[{"id":"1.168135750","rc":[{"batb":[[2,13,1.57]],"ltp":15.5,"tv":161.44,"id":2764710}]}]}
{"op":"mcm","clk":"1004316707","pt":1580626728539,"mc":[{"id":"1.168135750","rc":[{"batb":[[2,10.5,1.57]],"ltp":15.5,"tv":161.44,"id":2764710}]}]}
{"op":"mcm","clk":"1004317119","pt":1580626743656,"mc":[{"id":"1.168135750","rc":[{"batb":[[0,80,3.25],[1,60,16.67]],"ltp":80.0,"tv":4.54,"id":5720739}]}]}
{"op":"mcm","clk":"1004317546","pt":1580626760508,"mc":[{"id":"1.168135750","rc":[{"batb":[[0,80,3.05],[1,60,16.87]],"ltp":80.0,"tv":4.54,"id":5720739}]}]}
{"op":"mcm","clk":"1004317736","pt":1580626765994,"mc":[{"id":"1.168135750","rc":[{"batl":[[0,29,10.7],[1,30,53],[2,1000,2.53]],"ltp":0.0,"tv":0.0,"id":2764714}]}]}
{"op":"mcm","clk":"1004319190","pt":1580626806481,"mc":[{"id":"1.168135750","rc":[{"batb":[[2,11,1.57]],"ltp":15.5,"tv":161.44,"id":2764710}]}]}
{"op":"mcm","clk":"1004320082","pt":1580626835442,"mc":[{"id":"1.168135750","rc":[{"trd":[[14,10.13]],"batb":[[0,14,20.54]],"ltp":14.0,"tv":46.85,"id":2764715}],"tv":4877.14}]}
{"op":"mcm","clk":"1004320372","pt":1580626841720,"mc":[{"id":"1.168135750","rc":[{"trd":[[5.9,121.81]],"batb":[[0,5.9,14.37]],"ltp":5.9,"tv":192.59,"id":2764722}],"tv":4887.27}]}
{"op":"mcm","clk":"1004320637","pt":1580626850678,"mc":[{"id":"1.168135750","rc":[{"trd":[[8,6],[8.2,4.8]],"batb":[[0,8,10.68],[1,7.8,14],[2,7.4,40.52]],"ltp":8.0,"tv":52.56,"id":2764720}],"tv":4897.4}]}
{"op":"mcm","clk":"1004320890","pt":1580626855738,"mc":[{"id":"1.168135750","rc":[{"batl":[[0,14.5,1.86],[1,15,53],[2,1000,2.53]],"ltp":8.0,"tv":52.56,"id":2764720},{"batb":[[0,80,3.25],[1,60,16.67]],"ltp":80.0,"tv":4.54,"id":5720739}]}]}
{"op":"mcm","clk":"1004321385","pt":1580626865594,"mc":[{"id":"1.168135750","rc":[{"batb":[[0,80,3.05],[1,60,16.87]],"ltp":80.0,"tv":4.54,"id":5720739}]}]}
{"op":"mcm","clk":"1004322058","pt":1580626891707,"mc":[{"id":"1.168135750","rc":[{"batb":[[2,11.5,1.57]],"ltp":15.5,"tv":161.44,"id":2764710}]}]}
{"op":"mcm","clk":"1004323703","pt":1580626960694,"mc":[{"id":"1.168135750","rc":[{"batb":[[0,80,3.25],[1,60,16.67]],"ltp":80.0,"tv":4.54,"id":5720739}]}]}
{"op":"mcm","clk":"1004323851","pt":1580626966710,"mc":[{"id":"1.168135750","rc":[{"batb":[[2,12,1.57]],"ltp":15.5,"tv":161.44,"id":2764710},{"batb":[[0,80,3.05],[1,60,16.87]],"ltp":80.0,"tv":4.54,"id":5720739}]}]}
{"op":"mcm","clk":"1004324080","pt":1580626975832,"mc":[{"id":"1.168135750","rc":[{"batb":[[0,8,10.75]],"ltp":8.0,"tv":52.56,"id":2764720}]}]}
{"op":"mcm","clk":"1004324352","pt":1580626986431,"mc":[{"id":"1.168135750","rc":[{"batb":[[2,7,30.39]],"ltp":8.0,"tv":1022.23,"id":5720732}]}]}
{"op":"mcm","clk":"1004324798","pt":1580627002478,"mc":[{"id":"1.168135750","rc":[{"batb":[[2,6.8,10.73]],"ltp":8.0,"tv":1022.23,"id":5720732}]}]}
{"op":"mcm","clk":"1004324894","pt":1580627005757,"mc":[{"id":"1.168135750","rc":[{"batb":[[1,6.8,10.73],[2,6.6,142.86]],"ltp":8.0,"tv":1022.23,"id":5720732}]}]}
{"op":"mcm","clk":"1004324898","pt":1580627005861,"mc":[{"id":"1.168135750","rc":[{"batb":[[1,7,2.42],[2,6.8,10.73]],"ltp":8.0,"tv":1022.23,"id":5720732}]}]}
{"op":"mcm","clk":"1004325416","pt":1580627025723,"mc":[{"id":"1.168135750","rc":[{"batb":[[0,8,10.68]],"ltp":8.0,"tv":52.56,"id":2764720}]}]}
{"op":"mcm","clk":"1004325419","pt":1580627025825,"mc":[{"id":"1.168135750","rc":[{"batb":[[0,8,10.75]],"ltp":8.0,"tv":52.56,"id":2764720}]}]}
{"op":"mcm","clk":"1004325573","pt":1580627031724,"mc":[{"id":"1.168135750","rc":[{"batb":[[1,100,10.14]],"ltp":100.0,"tv":4.54,"id":5720737}]}]}
{"op":"mcm","clk":"1004325616","pt":1580627032702,"mc":[{"id":"1.168135750","rc":[{"batb":[[1,100,10.27]],"ltp":100.0,"tv":4.54,"id":5720737}]}]}
{"op":"mcm","clk":"1004325928","pt":1580627043137,"mc":[{"id":"1.168135750","rc":[{"batb":[[2,12.5,1.57]],"ltp":15.5,"tv":161.44,"id":2764710}]}]}
{"op":"mcm","clk":"1004326404","pt":1580627062914,"mc":[{"id":"1.168135750","rc":[{"batb":[[0,80,3.25],[1,60,16.67]],"ltp":80.0,"tv":4.54,"id":5720739}]}]}
{"op":"mcm","clk":"1004326646","pt":1580627071752,"mc":[{"id":"1.168135750","rc":[{"batb":[[0,80,3.05]],"ltp":80.0,"tv":4.54,"id":5720739}]}]}
{"op":"mcm","clk":"1004326674","pt":1580627072572,"mc":[{"id":"1.168135750","rc":[{"batb":[[1,60,16.87]],"ltp":80.0,"tv":4.54,"id":5720739}]}]}
{"op":"mcm","clk":"1004328144","pt":1580627113986,"mc":[{"id":"1.168135750","rc":[{"batb":[[2,13,1.57]],"ltp":15.5,"tv":161.44,"id":2764710}]}]}
{"op":"mcm","clk":"1004328629","pt":1580627127333,"mc":[{"id":"1.168135750","rc":[{"batb":[[2,10.5,1.57]],"ltp":15.5,"tv":161.44,"id":2764710}]}]}
{"op":"mcm","clk":"1004329979","pt":1580627165557,"mc":[{"id":"1.168135750","rc":[{"batb":[[0,80,3.25],[1,60,16.67]],"ltp":80.0,"tv":4.54,"id":5720739}]}]}
{"op":"mcm","clk":"1004330348","pt":1580627176059,"mc":[{"id":"1.168135750","rc":[{"batb":[[0,80,3.05],[1,60,16.87]],"ltp":80.0,"tv":4.54,"id":5720739}]}]}
{"op":"mcm","clk":"1004331269","pt":1580627204098,"mc":[{"id":"1.168135750","rc":[{"batb":[[2,11,1.57]],"ltp":15.5,"tv":161.44,"id":2764710}]}]}
{"op":"mcm","clk":"1004333772","pt":1580627270513,"mc":[{"id":"1.168135750","rc":[{"batb":[[0,80,3.25],[1,60,16.67]],"ltp":80.0,"tv":4.54,"id":5720739}]}]}
{"op":"mcm","clk":"1004334023","pt":1580627276798,"mc":[{"id":"1.168135750","rc":[{"batb":[[2,11.5,1.57]],"ltp":15.5,"tv":161.44,"id":2764710},{"batb":[[0,80,3.05],[1,60,16.87]],"ltp":80.0,"tv":4.54,"id":5720739}]}]}
{"op":"mcm","clk":"1004336584","pt":1580627349205,"mc":[{"id":"1.168135750","rc":[{"batb":[[2,12,1.57]],"ltp":15.5,"tv":161.44,"id":2764710}]}]}
{"op":"mcm","clk":"1004337014","pt":1580627363230,"mc":[{"id":"1.168135750","rc":[{"batb":[[0,80,3.25],[1,60,16.67]],"ltp":80.0,"tv":4.54,"id":5720739}]}]}
{"op":"mcm","clk":"1004337303","pt":1580627370402,"mc":[{"id":"1.168135750","rc":[{"batb":[[0,80,3.05],[1,60,16.87]],"ltp":80.0,"tv":4.54,"id":5720739}]}]}
{"op":"mcm","clk":"1004337693","pt":1580627381757,"mc":[{"id":"1.168135750","rc":[{"trd":[[15,13.99],[15.5,4.65]],"batb":[[0,14.5,1.1],[1,14,19.25],[2,9,111.11]],"batl":[[0,15,5.88],[1,29,10.7],[2,30,53]],"ltp":15.0,"tv":18.64,"id":2764714}],"tv":4916.05}]}
{"op":"mcm","clk":"1004337873","pt":1580627386568,"mc":[{"id":"1.168135750","rc":[{"batb":[[0,14,19.25],[1,9,111.11],[2,1.5,2.53]],"ltp":15.0,"tv":18.64,"id":2764714},{"batb":[[0,24,4.03]],"ltp":24.0,"tv":19.26,"id":5720735},{"batb":[[0,26,5.28]],"ltp":26.0,"tv":13.17,"id":5720736}]}]}
{"op":"mcm","clk":"1004338061","pt":1580627392762,"mc":[{"id":"1.168135750","rc":[{"batb":[[0,14.5,10.84],[1,14,19.25],[2,9,111.11]],"ltp":15.0,"tv":18.64,"id":2764714}]}]}
{"op":"mcm","clk":"1004338122","pt":1580627394780,"mc":[{"id":"1.168135750","rc":[{"batl":[[0,29,10.7],[1,30,53],[2,1000,2.53]],"ltp":15.0,"tv":18.64,"id":2764714}]}]}
{"op":"mcm","clk":"1004338305","pt":1580627400250,"mc":[{"id":"1.168135750","rc":[{"batb":[[0,24,3.43]],"ltp":24.0,"tv":19.26,"id":5720735},{"batb":[[0,26,4.74]],"ltp":26.0,"tv":13.17,"id":5720736}]}]}
{"op":"mcm","clk":"1004339148","pt":1580627421708,"mc":[{"id":"1.168135750","rc":[{"batb":[[2,12.5,1.57]],"ltp":15.5,"tv":161.44,"id":2764710}]}]}
{"op":"mcm","clk":"1004339436","pt":1580627430531,"mc":[{"id":"1.168135750","rc":[{"trd":[[8,16.99],[8.2,4.95]],"batb":[[0,8,5.18]],"ltp":8.0,"tv":63.71,"id":2764720}],"tv":4927.19}]}
{"op":"mcm","clk":"1004340501","pt":1580627460424,"mc":[{"id":"1.168135750","rc":[{"batb":[[0,80,3.25],[1,60,16.67]],"ltp":80.0,"tv":4.54,"id":5720739}]}]}
{"op":"mcm","clk":"1004340749","pt":1580627466774,"mc":[{"id":"1.168135750","rc":[{"batb":[[0,80,3.05],[1,60,16.87]],"ltp":80.0,"tv":4.54,"id":5720739},{"batb":[[0,14.5,11.82]],"ltp":15.0,"tv":18.64,"id":2764714},{"batb":[[0,26,5.28]],"ltp":26.0,"tv":13.17,"id":5720736}]}]}
{"op":"mcm","clk":"1004341825","pt":1580627489606,"mc":[{"id":"1.168135750","rc":[{"batb":[[2,13,1.57]],"ltp":15.5,"tv":161.44,"id":2764710}]}]}
{"op":"mcm","clk":"1004342572","pt":1580627504482,"mc":[{"id":"1.168135750","rc":[{"batb":[[2,10.5,1.57]],"ltp":15.5,"tv":161.44,"id":2764710}]}]}
{"op":"mcm","clk":"1004344181","pt":1580627554638,"mc":[{"id":"1.168135750","rc":[{"batb":[[0,8,5.22]],"ltp":8.0,"tv":63.71,"id":2764720},{"batb":[[0,80,3.25],[1,60,16.67]],"ltp":80.0,"tv":4.54,"id":5720739}]}]}
{"op":"mcm","clk":"1004344438","pt":1580627565669,"mc":[{"id":"1.168135750","rc":[{"batb":[[0,80,3.05],[1,60,16.87]],"ltp":80.0,"tv":4.54,"id":5720739}]}]}
{"op":"mcm","clk":"1004345009","pt":1580627582690,"mc":[{"id":"1.168135750","rc":[{"batb":[[2,10,114.18]],"batl":[[0,20,53],[1,1000,0]],"ltp":15.5,"tv":161.44,"id":2764710},{"batb":[[0,8,5.18]],"batl":[[0,15,53.51],[1,15,0],[2,1000,0]],"ltp":8.0,"tv":63.71,"id":2764720},{"batb":[[1,60,16.67],[2,1.01,1.01]],"ltp":80.0,"tv":4.54,"id":5720739},{"batb":[[0,14.5,10.84]],"batl":[[0,29,10.64],[2,1000,0]],"ltp":15.0,"tv":18.64,"id":2764714},{"batl":[[2,1000,2.53]],"ltp":14.0,"tv":46.85,"id":2764715},{"batb":[[0,8.6,9.57]],"batl":[[2,24,6.08]],"ltp":8.6,"tv":159.7,"id":5720738},{"batb":[[0,60,1.25]],"ltp":55.0,"tv":4.53,"id":2764717},{"batl":[[1,80,3.04],[2,1000,0]],"ltp":24.0,"tv":19.26,"id":5720735},{"batb":[[0,27,3.04]],"batl":[[2,48,12.66]],"ltp":32.0,"tv":47.19,"id":5720734},{"batb":[[1,100,10.14]],"ltp":100.0,"tv":4.54,"id":5720737},{"batb":[[0,26,4.74]],"ltp":26.0,"tv":13.17,"id":5720736},{"batb":[[1,6.8,10.73],[2,6.6,142.86]],"ltp":8.0,"tv":1022.23,"id":5720732}]}]}
{"op":"mcm","clk":"1004345237","pt":1580627588693,"mc":[{"id":"1.168135750","rc":[{"batl":[[1,1000,2.66]],"ltp":15.5,"tv":161.44,"id":2764710},{"batl":[[1,1000,3.94]],"ltp":8.0,"tv":63.71,"id":2764720},{"batb":[[2,1.5,2.53]],"ltp":80.0,"tv":4.54,"id":5720739},{"batl":[[2,1000,2.62]],"ltp":15.0,"tv":18.64,"id":2764714},{"batl":[[2,1000,5.15]],"ltp":14.0,"tv":46.85,"id":2764715},{"batl":[[2,1000,2.58]],"ltp":24.0,"tv":19.26,"id":5720735}]}]}
{"op":"mcm","clk":"1004345257","pt":1580627589309,"mc":[{"id":"1.168135750","rc":[{"batb":[[2,10.5,1.45]],"batl":[[0,20,53.13],[1,1000,2.53]],"ltp":15.5,"tv":161.44,"id":2764710},{"batb":[[0,8,5.24]],"batl":[[0,14.5,1.91],[1,15,53],[2,1000,2.53]],"ltp":8.0,"tv":63.71,"id":2764720},{"batb":[[0,14.5,11.82]],"batl":[[0,29,10.72],[2,1000,2.53]],"ltp":15.0,"tv":18.64,"id":2764714},{"batb":[[0,8.6,9.98]],"batl":[[2,24,7.03]],"ltp":8.6,"tv":159.7,"id":5720738},{"batb":[[0,60,1.48]],"ltp":55.0,"tv":4.53,"id":2764717},{"batl":[[1,80,3.08],[2,1000,2.53]],"ltp":24.0,"tv":19.26,"id":5720735},{"batl":[[2,48,12.71]],"ltp":32.0,"tv":47.19,"id":5720734},{"batb":[[1,100,10.25]],"ltp":100.0,"tv":4.54,"id":5720737},{"batb":[[0,26,5.29]],"ltp":26.0,"tv":13.17,"id":5720736},{"batb":[[1,7,2.29],[2,6.8,10.73]],"ltp":8.0,"tv":1022.23,"id":5720732}]}]}
{"op":"mcm","clk":"1004345633","pt":1580627598804,"mc":[{"id":"1.168135750","rc":[{"batb":[[1,60,16.86]],"ltp":80.0,"tv":4.54,"id":5720739}]}]}
{"op":"mcm","clk":"1004345957","pt":1580627607688,"mc":[{"id":"1.168135750","rc":[{"batb":[[2,11,1.45]],"ltp":15.5,"tv":161.44,"id":2764710}]}]}
{"op":"mcm","clk":"1004346627","pt":1580627626754,"mc":[{"id":"1.168135750","rc":[{"batb":[[1,100,10.14]],"ltp":100.0,"tv":4.54,"id":5720737}]}]}
{"op":"mcm","clk":"1004346633","pt":1580627626856,"mc":[{"id":"1.168135750","rc":[{"batb":[[1,100,10.25]],"ltp":100.0,"tv":4.54,"id":5720737}]}]}
{"op":"mcm","clk":"1004347908","pt":1580627654788,"mc":[{"id":"1.168135750","rc":[{"batb":[[1,60,16.67]],"ltp":80.0,"tv":4.54,"id":5720739}]}]}
{"op":"mcm","clk":"1004347926","pt":1580627655147,"mc":[{"id":"1.168135750","rc":[{"batb":[[0,80,3.23]],"ltp":80.0,"tv":4.54,"id":5720739}]}]}
{"op":"mcm","clk":"1004348393","pt":1580627664811,"mc":[{"id":"1.168135750","rc":[{"batb":[[0,80,3.05],[1,60,16.86]],"ltp":80.0,"tv":4.54,"id":5720739}]}]}
{"op":"mcm","clk":"1004349273","pt":1580627684787,"mc":[{"id":"1.168135750","rc":[{"batb":[[2,11.5,1.45]],"ltp":15.5,"tv":161.44,"id":2764710}]}]}
{"op":"mcm","clk":"1004350189","pt":1580627705840,"mc":[{"id":"1.168135750","rc":[{"batb":[[2,10,114.18]],"batl":[[0,20,53],[1,1000,0]],"ltp":15.5,"tv":161.44,"id":2764710},{"batb":[[0,8,5.18]],"batl":[[0,15,53.51],[1,15,0],[2,1000,0]],"ltp":8.0,"tv":63.71,"id":2764720},{"batb":[[1,60,16.67],[2,1.01,1.01]],"ltp":80.0,"tv":4.54,"id":5720739},{"batb":[[0,14.5,10.84]],"batl":[[0,29,10.64],[2,1000,0]],"ltp":15.0,"tv":18.64,"id":2764714},{"batl":[[2,1000,2.53]],"ltp":14.0,"tv":46.85,"id":2764715},{"batb":[[0,8.6,9.57]],"batl":[[2,24,6.08]],"ltp":8.6,"tv":159.7,"id":5720738},{"batb":[[0,60,1.25]],"ltp":55.0,"tv":4.53,"id":2764717},{"batl":[[1,80,3.04],[2,1000,0]],"ltp":24.0,"tv":19.26,"id":5720735},{"batl":[[2,48,12.66]],"ltp":32.0,"tv":47.19,"id":5720734},{"batb":[[1,100,10.14]],"ltp":100.0,"tv":4.54,"id":5720737},{"batb":[[0,26,4.74]],"ltp":26.0,"tv":13.17,"id":5720736},{"batb":[[1,6.8,10.73],[2,6.6,142.86]],"ltp":8.0,"tv":1022.23,"id":5720732}]}]}
{"op":"mcm","clk":"1004350530","pt":1580627714646,"mc":[{"id":"1.168135750","rc":[{"batl":[[1,1000,2.53]],"ltp":15.5,"tv":161.44,"id":2764710},{"batl":[[1,1000,2.53]],"ltp":8.0,"tv":63.71,"id":2764720},{"batb":[[2,1.5,2.53]],"ltp":80.0,"tv":4.54,"id":5720739},{"batl":[[2,1000,2.53]],"ltp":15.0,"tv":18.64,"id":2764714},{"batl":[[2,1000,5.07]],"ltp":14.0,"tv":46.85,"id":2764715},{"batl":[[2,1000,2.53]],"ltp":24.0,"tv":19.26,"id":5720735}]}]}
{"op":"mcm","clk":"1004350571","pt":1580627715721,"mc":[{"id":"1.168135750","rc":[{"batl":[[0,20,53.13]],"ltp":15.5,"tv":161.44,"id":2764710},{"batb":[[0,8,5.25]],"batl":[[0,14.5,1.91],[1,15,53],[2,1000,2.53]],"ltp":8.0,"tv":63.71,"id":2764720},{"batb":[[0,80,3.22]],"ltp":80.0,"tv":4.54,"id":5720739},{"batb":[[0,14.5,11.83]],"batl":[[0,29,10.72]],"ltp":15.0,"tv":18.64,"id":2764714},{"batl":[[2,1000,5.16]],"ltp":14.0,"tv":46.85,"id":2764715},{"batb":[[0,8.6,9.99]],"batl":[[2,24,7.03]],"ltp":8.6,"tv":159.7,"id":5720738},{"batb":[[0,60,1.48]],"ltp":55.0,"tv":4.53,"id":2764717},{"batl":[[1,80,3.08]],"ltp":24.0,"tv":19.26,"id":5720735},{"batl":[[2,48,12.72]],"ltp":32.0,"tv":47.19,"id":5720734},{"batb":[[1,100,10.24]],"ltp":100.0,"tv":4.54,"id":5720737},{"batb":[[0,26,5.29]],"ltp":26.0,"tv":13.17,"id":5720736},{"batb":[[1,7,2.3],[2,6.8,10.73]],"ltp":8.0,"tv":1022.23,"id":5720732}]}]}
{"op":"mcm","clk":"1004350605","pt":1580627716750,"mc":[{"id":"1.168135750","rc":[{"batb":[[0,80,3.05]],"ltp":80.0,"tv":4.54,"id":5720739},{"batb":[[1,100,10.14]],"ltp":100.0,"tv":4.54,"id":5720737}]}]}
{"op":"mcm","clk":"1004350616","pt":1580627716964,"mc":[{"id":"1.168135750","rc":[{"batb":[[2,10.5,1.46]],"ltp":15.5,"tv":161.44,"id":2764710},{"batb":[[1,60,16.85]],"ltp":80.0,"tv":4.54,"id":5720739},{"batb":[[1,100,10.24]],"ltp":100.0,"tv":4.54,"id":5720737}]}]}
{"op":"mcm","clk":"1004352293","pt":1580627761987,"mc":[{"id":"1.168135750","rc":[{"batb":[[2,11,1.46]],"ltp":15.5,"tv":161.44,"id":2764710}]}]}
{"op":"mcm","clk":"1004353959","pt":1580627810028,"mc":[{"id":"1.168135750","rc":[{"batb":[[0,80,3.22],[1,60,16.67]],"ltp":80.0,"tv":4.54,"id":5720739}]}]}
{"op":"mcm","clk":"1004354402","pt":1580627822027,"mc":[{"id":"1.168135750","rc":[{"batb":[[0,80,3.05],[1,60,16.85]],"ltp":80.0,"tv":4.54,"id":5720739}]}]}
{"op":"mcm","clk":"1004354955","pt":1580627835722,"mc":[{"id":"1.168135750","rc":[{"batb":[[2,11.5,1.46]],"ltp":15.5,"tv":161.44,"id":2764710}]}]}
{"op":"mcm","clk":"1004357576","pt":1580627901128,"mc":[{"id":"1.168135750","rc":[{"batb":[[2,12,1.46]],"ltp":15.5,"tv":161.44,"id":2764710}]}]}
{"op":"mcm","clk":"1004357897","pt":1580627907529,"mc":[{"id":"1.168135750","rc":[{"batb":[[0,80,3.22],[1,60,16.67]],"ltp":80.0,"tv":4.54,"id":5720739}]}]}
{"op":"mcm","clk":"1004358609","pt":1580627923380,"mc":[{"id":"1.168135750","rc":[{"batb":[[0,80,3.05],[1,60,16.85]],"ltp":80.0,"tv":4.54,"id":5720739}]}]}
{"op":"mcm","clk":"1004360911","pt":1580627976707,"mc":[{"id":"1.168135750","rc":[{"batb":[[2,12.5,1.46]],"ltp":15.5,"tv":161.44,"id":2764710}]}]}
{"op":"mcm","clk":"1004362415","pt":1580628010266,"mc":[{"id":"1.168135750","rc":[{"batb":[[0,80,3.22],[1,60,16.67]],"ltp":80.0,"tv":4.54,"id":5720739}]}]}
{"op":"mcm","clk":"1004362666","pt":1580628015259,"mc":[{"id":"1.168135750","rc":[{"batb":[[0,80,3.05],[1,60,16.85]],"ltp":80.0,"tv":4.54,"id":5720739}]}]}
{"op":"mcm","clk":"1004363890","pt":1580628039224,"mc":[{"id":"1.168135750","rc":[{"batb":[[2,13,1.46]],"ltp":15.5,"tv":161.44,"id":2764710}]}]}
{"op":"mcm","clk":"1004364213","pt":1580628047731,"mc":[{"id":"1.168135750","rc":[{"batl":[[0,990,2],[1,1000,2.53]],"ltp":55.0,"tv":4.53,"id":2764717}]}]}
{"op":"mcm","clk":"1004364767","pt":1580628061637,"mc":[{"id":"1.168135750","rc":[{"batb":[[2,10.5,1.46]],"ltp":15.5,"tv":161.44,"id":2764710}]}]}
{"op":"mcm","clk":"1004366700","pt":1580628096482,"mc":[{"id":"1.168135750","rc":[{"batb":[[0,80,3.22],[1,60,16.67]],"ltp":80.0,"tv":4.54,"id":5720739}]}]}
{"op":"mcm","clk":"1004367349","pt":1580628111680,"mc":[{"id":"1.168135750","rc":[{"batb":[[0,80,3.05],[1,60,16.85]],"ltp":80.0,"tv":4.54,"id":5720739}]}]}
{"op":"mcm","clk":"1004367643","pt":1580628116416,"mc":[{"id":"1.168135750","rc":[{"batl":[[0,980,2]],"ltp":55.0,"tv":4.53,"id":2764717}]}]}
{"op":"mcm","clk":"1004369133","pt":1580628149364,"mc":[{"id":"1.168135750","rc":[{"batb":[[2,11,1.46]],"ltp":15.5,"tv":161.44,"id":2764710}]}]}
{"op":"mcm","clk":"1004371022","pt":1580628193682,"mc":[{"id":"1.168135750","rc":[{"batb":[[0,80,3.22],[1,60,16.67]],"ltp":80.0,"tv":4.54,"id":5720739}]}]}
{"op":"mcm","clk":"1004371233","pt":1580628198725,"mc":[{"id":"1.168135750","rc":[{"batb":[[0,80,3.05],[1,60,16.85]],"ltp":80.0,"tv":4.54,"id":5720739}]}]}
{"op":"mcm","clk":"1004372576","pt":1580628230640,"mc":[{"id":"1.168135750","rc":[{"batb":[[2,11.5,1.46]],"ltp":15.5,"tv":161.44,"id":2764710}]}]}
{"op":"mcm","clk":"1004373213","pt":1580628252515,"mc":[{"id":"1.168135750","rc":[{"batb":[[2,10,114.18]],"batl":[[0,20,53],[1,1000,0]],"ltp":15.5,"tv":161.44,"id":2764710},{"batb":[[0,8,5.18]],"batl":[[0,15,53.51],[1,15,0],[2,1000,0]],"ltp":8.0,"tv":63.71,"id":2764720},{"batb":[[1,60,16.67],[2,1.01,1.01]],"ltp":80.0,"tv":4.54,"id":5720739},{"batb":[[0,14.5,10.84]],"batl":[[0,29,10.64],[2,1000,0]],"ltp":15.0,"tv":18.64,"id":2764714},{"batl":[[2,1000,2.53]],"ltp":14.0,"tv":46.85,"id":2764715},{"batb":[[0,8.6,9.57]],"batl":[[2,24,6.08]],"ltp":8.6,"tv":159.7,"id":5720738},{"batb":[[0,60,1.25]],"ltp":55.0,"tv":4.53,"id":2764717},{"batl":[[1,80,3.04],[2,1000,0]],"ltp":24.0,"tv":19.26,"id":5720735},{"batl":[[2,48,12.66]],"ltp":32.0,"tv":47.19,"id":5720734},{"batb":[[1,100,10.14]],"ltp":100.0,"tv":4.54,"id":5720737},{"batb":[[0,26,4.74]],"ltp":26.0,"tv":13.17,"id":5720736},{"batb":[[1,6.8,10.73],[2,6.6,142.86]],"ltp":8.0,"tv":1022.23,"id":5720732}]}]}
{"op":"mcm","clk":"1004373765","pt":1580628272530,"mc":[{"id":"1.168135750","rc":[{"batl":[[1,1000,2.68]],"ltp":15.5,"tv":161.44,"id":2764710},{"batl":[[1,1000,3.94]],"ltp":8.0,"tv":63.71,"id":2764720},{"batb":[[2,1.5,2.73]],"ltp":80.0,"tv":4.54,"id":5720739},{"batl":[[2,1000,2.63]],"ltp":15.0,"tv":18.64,"id":2764714},{"batl":[[2,1000,5.17]],"ltp":14.0,"tv":46.85,"id":2764715},{"batl":[[2,1000,2.58]],"ltp":24.0,"tv":19.26,"id":5720735}]}]}
{"op":"mcm","clk":"1004373781","pt":1580628273096,"mc":[{"id":"1.168135750","rc":[{"batb":[[2,10.5,1.49]],"batl":[[0,20,53.15],[1,1000,2.53]],"ltp":15.5,"tv":161.44,"id":2764710},{"batb":[[0,8,5.3]],"batl":[[0,14.5,1.91],[1,15,53],[2,1000,2.53]],"ltp":8.0,"tv":63.71,"id":2764720},{"batb":[[1,60,16.86],[2,1.5,2.53]],"ltp":80.0,"tv":4.54,"id":5720739},{"batb":[[0,15,1.01],[1,14.5,10.84],[2,14,19.25]],"batl":[[0,29,10.74],[2,1000,2.53]],"ltp":15.0,"tv":18.64,"id":2764714},{"batb":[[0,8.6,10.03]],"batl":[[2,24,7.03]],"ltp":8.6,"tv":159.7,"id":5720738},{"batb":[[0,60,1.5]],"ltp":55.0,"tv":4.53,"id":2764717},{"batl":[[1,80,3.09],[2,1000,2.53]],"ltp":24.0,"tv":19.26,"id":5720735},{"batl":[[2,48,12.72]],"ltp":32.0,"tv":47.19,"id":5720734},{"batb":[[1,100,10.26]],"ltp":100.0,"tv":4.54,"id":5720737},{"batb":[[0,26,5.3]],"ltp":26.0,"tv":13.17,"id":5720736},{"batb":[[1,7,2.37],[2,6.8,10.73]],"ltp":8.0,"tv":1022.23,"id":5720732}]}]}
{"op":"mcm","clk":"1004374419","pt":1580628294526,"mc":[{"id":"1.168135750","rc":[{"batb":[[2,11,1.49]],"ltp":15.5,"tv":161.44,"id":2764710}]}]}
{"op":"mcm","clk":"1004374806","pt":1580628306645,"mc":[{"id":"1.168135750","rc":[{"batb":[[0,80,3.24],[1,60,16.67]],"ltp":80.0,"tv":4.54,"id":5720739}]}]}
{"op":"mcm","clk":"1004375017","pt":1580628311564,"mc":[{"id":"1.168135750","rc":[{"batb":[[0,80,3.05],[1,60,16.86]],"ltp":80.0,"tv":4.54,"id":5720739}]}]}
{"op":"mcm","clk":"1004375882","pt":1580628335802,"mc":[{"id":"1.168135750","rc":[{"batb":[[0,27,3.59]],"ltp":32.0,"tv":47.19,"id":5720734}]}]}
{"op":"mcm","clk":"1004375914","pt":1580628336574,"mc":[{"id":"1.168135750","rc":[{"batb":[[0,27,3.04]],"ltp":32.0,"tv":47.19,"id":5720734}]}]}
{"op":"mcm","clk":"1004376283","pt":1580628345588,"mc":[{"id":"1.168135750","rc":[{"batl":[[0,1000,4.56]],"ltp":80.0,"tv":4.54,"id":5720739}]}]}
{"op":"mcm","clk":"1004377066","pt":1580628362618,"mc":[{"id":"1.168135750","rc":[{"batb":[[2,11.5,1.49]],"ltp":15.5,"tv":161.44,"id":2764710}]}]}
{"op":"mcm","clk":"1004378534","pt":1580628390675,"mc":[{"id":"1.168135750","rc":[{"batb":[[2,10,114.18]],"batl":[[0,20,53],[1,1000,0]],"ltp":15.5,"tv":161.44,"id":2764710},{"batb":[[0,8,5.18]],"batl":[[0,15,53.51],[1,15,0],[2,1000,0]],"ltp":8.0,"tv":63.71,"id":2764720},{"batb":[[1,60,16.67],[2,1.01,1.01]],"ltp":80.0,"tv":4.54,"id":5720739},{"batb":[[0,14.5,10.84],[1,14,19.25],[2,9,111.11]],"batl":[[0,29,10.64],[2,1000,0]],"ltp":15.0,"tv":18.64,"id":2764714},{"batl":[[2,1000,2.53]],"ltp":14.0,"tv":46.85,"id":2764715},{"batb":[[0,8.6,9.57]],"batl":[[2,24,6.08]],"ltp":8.6,"tv":159.7,"id":5720738},{"batb":[[0,60,1.25]],"ltp":55.0,"tv":4.53,"id":2764717},{"batl":[[1,80,3.04],[2,1000,0]],"ltp":24.0,"tv":19.26,"id":5720735},{"batl":[[2,48,12.66]],"ltp":32.0,"tv":47.19,"id":5720734},{"batb":[[1,100,10.14]],"ltp":100.0,"tv":4.54,"id":5720737},{"batb":[[0,26,4.74]],"ltp":26.0,"tv":13.17,"id":5720736},{"batb":[[1,6.8,10.73],[2,6.6,142.86]],"ltp":8.0,"tv":1022.23,"id":5720732}]}]}
{"op":"mcm","clk":"1004379633","pt":1580628413707,"mc":[{"id":"1.168135750","rc":[{"batl":[[1,1000,2.62]],"ltp":15.5,"tv":161.44,"id":2764710},{"batl":[[1,1000,3.94]],"ltp":8.0,"tv":63.71,"id":2764720},{"batb":[[2,1.5,2.73]],"ltp":80.0,"tv":4.54,"id":5720739},{"batl":[[2,1000,2.64]],"ltp":15.0,"tv":18.64,"id":2764714},{"batl":[[2,1000,5.17]],"ltp":14.0,"tv":46.85,"id":2764715},{"batl":[[2,1000,2.59]],"ltp":24.0,"tv":19.26,"id":5720735}]}]}
{"op":"mcm","clk":"1004379656","pt":1580628414323,"mc":[{"id":"1.168135750","rc":[{"batb":[[2,10.5,1.5]],"ltp":15.5,"tv":161.44,"id":2764710},{"batb":[[0,8,5.31]],"batl":[[0,14.5,1.91],[1,15,53],[2,1000,2.53]],"ltp":8.0,"tv":63.71,"id":2764720},{"batb":[[1,60,16.86],[2,1.5,2.53]],"ltp":80.0,"tv":4.54,"id":5720739},{"batb":[[0,15,1.02],[1,14.5,10.84],[2,14,19.25]],"batl":[[0,29,10.74],[2,1000,2.53]],"ltp":15.0,"tv":18.64,"id":2764714},{"batb":[[0,8.6,10.04]],"batl":[[2,24,7.03]],"ltp":8.6,"tv":159.7,"id":5720738},{"batb":[[0,60,1.5]],"ltp":55.0,"tv":4.53,"id":2764717},{"batl":[[1,80,3.09],[2,1000,2.53]],"ltp":24.0,"tv":19.26,"id":5720735},{"batl":[[2,48,12.73]],"ltp":32.0,"tv":47.19,"id":5720734},{"batb":[[1,100,10.26]],"ltp":100.0,"tv":4.54,"id":5720737},{"batb":[[0,26,5.31]],"ltp":26.0,"tv":13.17,"id":5720736},{"batb":[[1,7,2.38],[2,6.8,10.73]],"ltp":8.0,"tv":1022.23,"id":5720732}]}]}
{"op":"mcm","clk":"1004379945","pt":1580628421600,"mc":[{"id":"1.168135750","rc":[{"batl":[[0,900,2]],"ltp":55.0,"tv":4.53,"id":2764717}]}]}
{"op":"mcm","clk":"1004380199","pt":1580628428756,"mc":[{"id":"1.168135750","rc":[{"batb":[[2,11,1.5]],"ltp":15.5,"tv":161.44,"id":2764710}]}]}
{"op":"mcm","clk":"1004380768","pt":1580628444734,"mc":[{"id":"1.168135750","rc":[{"batb":[[0,80,3.24],[1,60,16.67]],"ltp":80.0,"tv":4.54,"id":5720739}]}]}
{"op":"mcm","clk":"1004381294","pt":1580628460778,"mc":[{"id":"1.168135750","rc":[{"batb":[[0,80,3.05],[1,60,16.86]],"ltp":80.0,"tv":4.54,"id":5720739}]}]}
{"op":"mcm","clk":"1004382284","pt":1580628486616,"mc":[{"id":"1.168135750","rc":[{"batl":[[0,880,2],[1,900,2],[2,1000,2.53]],"ltp":55.0,"tv":4.53,"id":2764717}]}]}
{"op":"mcm","clk":"1004382760","pt":1580628498735,"mc":[{"id":"1.168135750","rc":[{"batb":[[2,10,114.18]],"ltp":15.5,"tv":161.44,"id":2764710},{"batl":[[0,14.5,9.51]],"ltp":8.0,"tv":63.71,"id":2764720}]}]}
{"op":"mcm","clk":"1004382805","pt":1580628499815,"mc":[{"id":"1.168135750","rc":[{"batb":[[2,11.5,1.5]],"ltp":15.5,"tv":161.44,"id":2764710}]}]}
{"op":"mcm","clk":"1004383981","pt":1580628532759,"mc":[{"id":"1.168135750","rc":[{"batb":[[0,80,3.24],[1,60,16.67]],"ltp":80.0,"tv":4.54,"id":5720739}]}]}
{"op":"mcm","clk":"1004384129","pt":1580628537755,"mc":[{"id":"1.168135750","rc":[{"batb":[[0,80,3.05]],"ltp":80.0,"tv":4.54,"id":5720739}]}]}
{"op":"mcm","clk":"1004384175","pt":1580628538704,"mc":[{"id":"1.168135750","rc":[{"batb":[[1,60,16.86]],"ltp":80.0,"tv":4.54,"id":5720739}]}]}
{"op":"mcm","clk":"1004384211","pt":1580628539687,"mc":[{"id":"1.168135750","rc":[{"batl":[[0,500,3],[1,880,2],[2,900,2]],"ltp":55.0,"tv":4.53,"id":2764717}]}]}
{"op":"mcm","clk":"1004385197","pt":1580628564926,"mc":[{"id":"1.168135750","rc":[{"batb":[[2,12,1.5]],"ltp":15.5,"tv":161.44,"id":2764710}]}]}
{"op":"mcm","clk":"1004386921","pt":1580628608785,"mc":[{"id":"1.168135750","rc":[{"batb":[[1,60,16.67]],"ltp":80.0,"tv":4.54,"id":5720739}]}]}
{"op":"mcm","clk":"1004386931","pt":1580628608889,"mc":[{"id":"1.168135750","rc":[{"batb":[[0,80,3.24]],"ltp":80.0,"tv":4.54,"id":5720739}]}]}
{"op":"mcm","clk":"1004387412","pt":1580628619812,"mc":[{"id":"1.168135750","rc":[{"batb":[[0,8.2,2],[1,8,5.31],[2,7.8,14]],"ltp":8.0,"tv":63.71,"id":2764720}]}]}
{"op":"mcm","clk":"1004387658","pt":1580628625987,"mc":[{"id":"1.168135750","rc":[{"batb":[[2,12.5,1.5]],"ltp":15.5,"tv":161.44,"id":2764710},{"batb":[[0,80,3.05],[1,60,16.86]],"ltp":80.0,"tv":4.54,"id":5720739}]}]}
{"op":"mcm","clk":"1004388431","pt":1580628646812,"mc":[{"id":"1.168135750","rc":[{"batb":[[1,100,10.14]],"ltp":100.0,"tv":4.54,"id":5720737}]}]}
{"op":"mcm","clk":"1004388435","pt":1580628646916,"mc":[{"id":"1.168135750","rc":[{"batb":[[1,100,10.26]],"ltp":100.0,"tv":4.54,"id":5720737}]}]}
{"op":"mcm","clk":"1004390066","pt":1580628683019,"mc":[{"id":"1.168135750","rc":[{"batb":[[2,13,1.5]],"ltp":15.5,"tv":161.44,"id":2764710}]}]}
{"op":"mcm","clk":"1004390759","pt":1580628699749,"mc":[{"id":"1.168135750","rc":[{"batb":[[2,10.5,1.5]],"ltp":15.5,"tv":161.44,"id":2764710},{"batb":[[0,80,3.24],[1,60,16.67]],"ltp":80.0,"tv":4.54,"id":5720739}]}]}
{"op":"mcm","clk":"1004391040","pt":1580628707785,"mc":[{"id":"1.168135750","rc":[{"batb":[[0,4.5,75.58]],"ltp":4.7,"tv":3168.76,"id":2764711}]}]}
{"op":"mcm","clk":"1004391343","pt":1580628715105,"mc":[{"id":"1.168135750","rc":[{"batb":[[0,80,3.05],[1,60,16.86]],"ltp":80.0,"tv":4.54,"id":5720739}]}]}
{"op":"mcm","clk":"1004391804","pt":1580628725599,"mc":[{"id":"1.168135750","rc":[{"batb":[[2,21,48.18]],"ltp":32.0,"tv":47.19,"id":5720734}]}]}
{"op":"mcm","clk":"1004393808","pt":1580628772126,"mc":[{"id":"1.168135750","rc":[{"batb":[[2,11,1.5]],"ltp":15.5,"tv":161.44,"id":2764710}]}]}
{"op":"mcm","clk":"1004394501","pt":1580628786282,"mc":[{"id":"1.168135750","rc":[{"batb":[[0,80,3.24],[1,60,16.67]],"ltp":80.0,"tv":4.54,"id":5720739}]}]}
{"op":"mcm","clk":"1004395081","pt":1580628799196,"mc":[{"id":"1.168135750","rc":[{"batb":[[0,80,3.05],[1,60,16.86]],"ltp":80.0,"tv":4.54,"id":5720739}]}]}
{"op":"mcm","clk":"1004395256","pt":1580628803490,"mc":[{"id":"1.168135750","rc":[{"batb":[[0,27,3.6],[2,21,47.62]],"ltp":32.0,"tv":47.19,"id":5720734}]}]}
{"op":"mcm","clk":"1004396430","pt":1580628836339,"mc":[{"id":"1.168135750","rc":[{"batb":[[2,11.5,1.5]],"ltp":15.5,"tv":161.44,"id":2764710}]}]}
{"op":"mcm","clk":"1004397730","pt":1580628872283,"mc":[{"id":"1.168135750","rc":[{"batb":[[0,80,3.24],[1,60,16.67]],"ltp":80.0,"tv":4.54,"id":5720739}]}]}
{"op":"mcm","clk":"1004398053","pt":1580628882612,"mc":[{"id":"1.168135750","rc":[{"batb":[[0,80,3.05],[1,60,16.86]],"ltp":80.0,"tv":4.54,"id":5720739}]}]}
{"op":"mcm","clk":"1004398814","pt":1580628903546,"mc":[{"id":"1.168135750","rc":[{"batb":[[2,12,1.5]],"ltp":15.5,"tv":161.44,"id":2764710}]}]}
{"op":"mcm","clk":"1004400542","pt":1580628954640,"mc":[{"id":"1.168135750","rc":[{"batb":[[0,80,3.24],[1,60,16.67]],"ltp":80.0,"tv":4.54,"id":5720739}]}]}
{"op":"mcm","clk":"1004400932","pt":1580628964524,"mc":[{"id":"1.168135750","rc":[{"batb":[[2,12.5,1.5]],"ltp":15.5,"tv":161.44,"id":2764710},{"batb":[[0,80,3.05],[1,60,16.86]],"ltp":80.0,"tv":4.54,"id":5720739}]}]}
{"op":"mcm","clk":"1004402985","pt":1580629018506,"mc":[{"id":"1.168135750","rc":[{"batb":[[2,13,1.5]],"ltp":15.5,"tv":161.44,"id":2764710}]}]}
{"op":"mcm","clk":"1004403291","pt":1580629027512,"mc":[{"id":"1.168135750","rc":[{"batb":[[2,10.5,1.5]],"ltp":15.5,"tv":161.44,"id":2764710}]}]}
{"op":"mcm","clk":"1004403457","pt":1580629031512,"mc":[{"id":"1.168135750","rc":[{"batb":[[0,80,3.24],[1,60,16.67]],"ltp":80.0,"tv":4.54,"id":5720739}]}]}
{"op":"mcm","clk":"1004403473","pt":1580629031920,"mc":[{"id":"1.168135750","rc":[{"trd":[[14,30.39]],"batb":[[0,14,10.41]],"ltp":14.0,"tv":67.11,"id":2764715}],"tv":4947.45}]}
{"op":"mcm","clk":"1004403655","pt":1580629036445,"mc":[{"id":"1.168135750","rc":[{"batb":[[0,80,3.05],[1,60,16.86]],"ltp":80.0,"tv":4.54,"id":5720739}]}]}
{"op":"mcm","clk":"1004403862","pt":1580629042041,"mc":[{"id":"1.168135750","rc":[{"batb":[[0,14.5,5.68],[1,14,10.41],[2,12.5,8.69]],"ltp":14.0,"tv":67.11,"id":2764715}]}]}
{"op":"mcm","clk":"1004405573","pt":1580629086588,"mc":[{"id":"1.168135750","rc":[{"batb":[[2,11,1.5]],"ltp":15.5,"tv":161.44,"id":2764710}]}]}
{"op":"mcm","clk":"1004406235","pt":1580629101613,"mc":[{"id":"1.168135750","rc":[{"batb":[[0,80,3.24],[1,60,16.67]],"ltp":80.0,"tv":4.54,"id":5720739}]}]}
{"op":"mcm","clk":"1004406356","pt":1580629102635,"mc":[{"id":"1.168135750","rc":[{"batl":[[0,29,5.07]],"ltp":24.0,"tv":19.26,"id":5720735}]}]}
{"op":"mcm","clk":"1004406483","pt":1580629105455,"mc":[{"id":"1.168135750","rc":[{"batl":[[0,34,4.79]],"ltp":32.0,"tv":47.19,"id":5720734}]}]}
{"op":"mcm","clk":"1004406510","pt":1580629106130,"mc":[{"id":"1.168135750","rc":[{"batl":[[0,34,3.27]],"ltp":32.0,"tv":47.19,"id":5720734}]}]}
{"op":"mcm","clk":"1004406561","pt":1580629106956,"mc":[{"id":"1.168135750","rc":[{"batl":[[0,34,2.03]],"ltp":32.0,"tv":47.19,"id":5720734}]}]}
{"op":"mcm","clk":"1004406606","pt":1580629107935,"mc":[{"id":"1.168135750","rc":[{"batl":[[1,48,12.73],[2,50,53]],"ltp":32.0,"tv":47.19,"id":5720734}]}]}
{"op":"mcm","clk":"1004406677","pt":1580629109705,"mc":[{"id":"1.168135750","rc":[{"batb":[[0,80,3.05],[1,60,16.86]],"ltp":80.0,"tv":4.54,"id":5720739},{"batb":[[0,26,4.74]],"ltp":26.0,"tv":13.17,"id":5720736}]}]}
{"op":"mcm","clk":"1004406773","pt":1580629111584,"mc":[{"id":"1.168135750","rc":[{"batl":[[0,48,12.73],[1,50,53],[2,1000,2.53]],"ltp":32.0,"tv":47.19,"id":5720734}]}]}
{"op":"mcm","clk":"1004406857","pt":1580629113638,"mc":[{"id":"1.168135750","rc":[{"batl":[[1,40,4.05],[2,1000,2.58]],"ltp":26.0,"tv":13.17,"id":5720736}]}]}
{"op":"mcm","clk":"1004406980","pt":1580629116672,"mc":[{"id":"1.168135750","rc":[{"batb":[[0,60,1.25],[1,55,3.7]],"ltp":55.0,"tv":4.53,"id":2764717}]}]}
{"op":"mcm","clk":"1004408278","pt":1580629147684,"mc":[{"id":"1.168135750","rc":[{"batb":[[2,11.5,1.5]],"ltp":15.5,"tv":161.44,"id":2764710}]}]}
{"op":"mcm","clk":"1004408845","pt":1580629161838,"mc":[{"id":"1.168135750","rc":[{"batb":[[0,26,5.33]],"ltp":26.0,"tv":13.17,"id":5720736}]}]}
{"op":"mcm","clk":"1004409524","pt":1580629176813,"mc":[{"id":"1.168135750","rc":[{"batb":[[0,80,3.24],[1,60,16.67]],"ltp":80.0,"tv":4.54,"id":5720739}]}]}
{"op":"mcm","clk":"1004409615","pt":1580629179640,"mc":[{"id":"1.168135750","rc":[{"batl":[[0,1000,2.53],[1,880,0],[2,900,0]],"ltp":55.0,"tv":4.53,"id":2764717}]}]}
{"op":"mcm","clk":"1004409730","pt":1580629182366,"mc":[{"id":"1.168135750","rc":[{"batl":[[0,9.8,11.65]],"ltp":8.6,"tv":159.7,"id":5720738}]}]}
{"op":"mcm","clk":"1004409786","pt":1580629183749,"mc":[{"id":"1.168135750","rc":[{"batb":[[0,80,3.05],[1,60,16.86]],"ltp":80.0,"tv":4.54,"id":5720739},{"batb":[[0,8.6,9.57]],"ltp":8.6,"tv":159.7,"id":5720738}]}]}
{"op":"mcm","clk":"1004410591","pt":1580629204785,"mc":[{"id":"1.168135750","rc":[{"batb":[[2,12,1.5]],"ltp":15.5,"tv":161.44,"id":2764710},{"batb":[[0,60,1.5],[1,55,3.45]],"ltp":55.0,"tv":4.53,"id":2764717},{"batb":[[1,100,10.14]],"ltp":100.0,"tv":4.54,"id":5720737}]}]}
{"op":"mcm","clk":"1004410627","pt":1580629205658,"mc":[{"id":"1.168135750","rc":[{"batl":[[2,16.5,1.04]],"ltp":8.6,"tv":159.7,"id":5720738},{"batb":[[1,100,10.26]],"ltp":100.0,"tv":4.54,"id":5720737}]}]}
{"op":"mcm","clk":"1004411020","pt":1580629215569,"mc":[{"id":"1.168135750","rc":[{"batl":[[0,11.5,11.65],[1,14.5,9],[2,15,53]],"ltp":8.0,"tv":63.71,"id":2764720}]}]}
{"op":"mcm","clk":"1004411171","pt":1580629218797,"mc":[{"id":"1.168135750","rc":[{"batl":[[1,1000,2.53]],"ltp":15.5,"tv":161.44,"id":2764710},{"batl":[[1,80,3.04]],"ltp":24.0,"tv":19.26,"id":5720735},{"batb":[[1,100,10.14]],"ltp":100.0,"tv":4.54,"id":5720737}]}]}
{"op":"mcm","clk":"1004411202","pt":1580629219514,"mc":[{"id":"1.168135750","rc":[{"batl":[[1,1000,2.62]],"ltp":15.5,"tv":161.44,"id":2764710},{"batb":[[0,8,5.31],[1,7.8,14],[2,7.4,40.52]],"ltp":8.0,"tv":63.71,"id":2764720},{"batl":[[1,80,3.09]],"ltp":24.0,"tv":19.26,"id":5720735},{"batb":[[1,100,10.26]],"ltp":100.0,"tv":4.54,"id":5720737}]}]}
{"op":"mcm","clk":"1004411559","pt":1580629227382,"mc":[{"id":"1.168135750","rc":[{"batb":[[0,8.2,2],[1,8,5.31],[2,7.8,14]],"ltp":8.0,"tv":63.71,"id":2764720}]}]}
{"op":"mcm","clk":"1004412011","pt":1580629238815,"mc":[{"id":"1.168135750","rc":[{"batl":[[2,24,6.08]],"ltp":8.6,"tv":159.7,"id":5720738}]}]}
{"op":"mcm","clk":"1004412032","pt":1580629239530,"mc":[{"id":"1.168135750","rc":[{"batl":[[2,15.5,1.04]],"ltp":8.6,"tv":159.7,"id":5720738}]}]}
{"op":"mcm","clk":"1004412399","pt":1580629252049,"mc":[{"id":"1.168135750","rc":[{"batb":[[0,80,3.24],[1,60,16.67]],"ltp":80.0,"tv":4.54,"id":5720739}]}]}
{"op":"mcm","clk":"1004412576","pt":1580629259038,"mc":[{"id":"1.168135750","rc":[{"batb":[[2,12.5,1.5]],"ltp":15.5,"tv":161.44,"id":2764710},{"batb":[[0,80,3.05],[1,60,16.86]],"ltp":80.0,"tv":4.54,"id":5720739},{"batl":[[2,15.5,1.11]],"ltp":8.6,"tv":159.7,"id":5720738}]}]}
{"op":"mcm","clk":"1004414870","pt":1580629308805,"mc":[{"id":"1.168135750","rc":[{"batb":[[1,100,10.14]],"ltp":100.0,"tv":4.54,"id":5720737}]}]}
{"op":"mcm","clk":"1004414897","pt":1580629309629,"mc":[{"id":"1.168135750","rc":[{"batb":[[1,100,10.26]],"ltp":100.0,"tv":4.54,"id":5720737}]}]}
{"op":"mcm","clk":"1004415357","pt":1580629316514,"mc":[{"id":"1.168135750","rc":[{"batb":[[2,13,1.5]],"ltp":15.5,"tv":161.44,"id":2764710}]}]}
{"op":"mcm","clk":"1004415565","pt":1580629321926,"mc":[{"id":"1.168135750","rc":[{"batb":[[0,80,3.24],[1,60,16.67]],"ltp":80.0,"tv":4.54,"id":5720739}]}]}
{"op":"mcm","clk":"1004415746","pt":1580629326218,"mc":[{"id":"1.168135750","rc":[{"batb":[[2,4.3,18.1]],"ltp":4.7,"tv":3168.76,"id":2764711},{"batb":[[2,7.8,19.39]],"ltp":8.0,"tv":63.71,"id":2764720},{"batb":[[2,13,3.23]],"ltp":14.0,"tv":67.11,"id":2764715},{"batb":[[2,8,17.75]],"ltp":8.6,"tv":159.7,"id":5720738},{"batb":[[2,13,3.23]],"ltp":24.0,"tv":19.26,"id":5720735},{"batb":[[2,22,1.91]],"ltp":32.0,"tv":47.19,"id":5720734},{"batb":[[2,18,2.34]],"ltp":26.0,"tv":13.17,"id":5720736},{"batb":[[1,5.6,20.75]],"ltp":5.9,"tv":192.59,"id":2764722},{"batb":[[1,7,8.38]],"ltp":8.0,"tv":1022.23,"id":5720732}]}]}
{"op":"mcm","clk":"1004415823","pt":1580629327816,"mc":[{"id":"1.168135750","rc":[{"batb":[[2,11,3.82]],"ltp":15.5,"tv":161.44,"id":2764710},{"batb":[[0,80,3.05]],"ltp":80.0,"tv":4.54,"id":5720739}]}]}
{"op":"mcm","clk":"1004415829","pt":1580629327917,"mc":[{"id":"1.168135750","rc":[{"batb":[[1,60,16.86]],"ltp":80.0,"tv":4.54,"id":5720739}]}]}
{"op":"mcm","clk":"1004418091","pt":1580629387686,"mc":[{"id":"1.168135750","rc":[{"batb":[[2,11.5,1.5]],"ltp":15.5,"tv":161.44,"id":2764710}]}]}
{"op":"mcm","clk":"1004418277","pt":1580629392103,"mc":[{"id":"1.168135750","rc":[{"batb":[[0,80,3.24],[1,60,16.67]],"ltp":80.0,"tv":4.54,"id":5720739}]}]}
{"op":"mcm","clk":"1004418563","pt":1580629398121,"mc":[{"id":"1.168135750","rc":[{"batb":[[0,80,3.05],[1,60,16.86]],"ltp":80.0,"tv":4.54,"id":5720739}]}]}
{"op":"mcm","clk":"1004418610","pt":1580629399413,"mc":[{"id":"1.168135750","rc":[{"trd":[[24,11.3]],"batb":[[0,23,16.85],[1,13,3.23],[2,12,83.33]],"ltp":24.0,"tv":24.33,"id":5720735}],"tv":4952.52}]}
{"op":"mcm","clk":"1004419935","pt":1580629431560,"mc":[{"id":"1.168135750","rc":[{"batl":[[0,6.2,7.07]],"ltp":5.9,"tv":192.59,"id":2764722}]}]}
{"op":"mcm","clk":"1004419968","pt":1580629432334,"mc":[{"id":"1.168135750","rc":[{"batl":[[2,15,1.11]],"ltp":8.6,"tv":159.7,"id":5720738},{"batb":[[0,24,1.53],[1,23,15.96],[2,13,3.23]],"ltp":24.0,"tv":24.33,"id":5720735}]}]}
{"op":"mcm","clk":"1004420345","pt":1580629442149,"mc":[{"id":"1.168135750","rc":[{"batb":[[2,12,1.5]],"ltp":15.5,"tv":161.44,"id":2764710}]}]}
{"op":"mcm","clk":"1004420964","pt":1580629459164,"mc":[{"id":"1.168135750","rc":[{"batb":[[0,80,3.24],[1,60,16.67]],"ltp":80.0,"tv":4.54,"id":5720739}]}]}
{"op":"mcm","clk":"1004421149","pt":1580629464289,"mc":[{"id":"1.168135750","rc":[{"batb":[[0,80,3.05],[1,60,16.86]],"ltp":80.0,"tv":4.54,"id":5720739}]}]}
{"op":"mcm","clk":"1004422136","pt":1580629490728,"mc":[{"id":"1.168135750","rc":[{"trd":[[4.5,936.86]],"batb":[[0,4.4,18.71],[1,4.3,18.1],[2,3.8,44.57]],"batl":[[0,4.5,487.34],[1,4.7,493.34],[2,4.8,534.75]],"ltp":4.5,"tv":3320.0,"id":2764711}],"tv":5103.77}]}
{"op":"mcm","clk":"1004422249","pt":1580629493338,"mc":[{"id":"1.168135750","rc":[{"batb":[[2,12.5,1.5]],"ltp":15.5,"tv":161.44,"id":2764710}]}]}
{"op":"mcm","clk":"1004422286","pt":1580629494317,"mc":[{"id":"1.168135750","rc":[{"batl":[[0,8.4,93],[1,8.6,21.6],[2,8.8,51.1]],"ltp":8.0,"tv":1022.23,"id":5720732}]}]}
{"op":"mcm","clk":"1004422319","pt":1580629495445,"mc":[{"id":"1.168135750","rc":[{"batb":[[0,8.6,10.11]],"batl":[[2,14.5,1.11]],"ltp":8.6,"tv":159.7,"id":5720738}]}]}
{"op":"mcm","clk":"1004423038","pt":1580629511546,"mc":[{"id":"1.168135750","rc":[{"batl":[[2,14.5,1.19]],"ltp":8.6,"tv":159.7,"id":5720738}]}]}
{"op":"mcm","clk":"1004423698","pt":1580629526454,"mc":[{"id":"1.168135750","rc":[{"batb":[[0,80,3.24],[1,60,16.67]],"ltp":80.0,"tv":4.54,"id":5720739}]}]}
{"op":"mcm","clk":"1004423886","pt":1580629531367,"mc":[{"id":"1.168135750","rc":[{"batb":[[0,80,3.05],[1,60,16.86]],"ltp":80.0,"tv":4.54,"id":5720739}]}]}
{"op":"mcm","clk":"1004424573","pt":1580629546399,"mc":[{"id":"1.168135750","rc":[{"batb":[[2,13,1.5]],"ltp":15.5,"tv":161.44,"id":2764710}]}]}
{"op":"mcm","clk":"1004425047","pt":1580629556299,"mc":[{"id":"1.168135750","rc":[{"batb":[[2,11.5,1.5]],"ltp":15.5,"tv":161.44,"id":2764710}]}]}
{"op":"mcm","clk":"1004426546","pt":1580629590820,"mc":[{"id":"1.168135750","rc":[{"batb":[[0,80,3.24],[1,60,16.67]],"ltp":80.0,"tv":4.54,"id":5720739}]}]}
{"op":"mcm","clk":"1004426761","pt":1580629595435,"mc":[{"id":"1.168135750","rc":[{"batb":[[0,80,3.05],[1,60,16.86]],"ltp":80.0,"tv":4.54,"id":5720739}]}]}
{"op":"mcm","clk":"1004426788","pt":1580629595948,"mc":[{"id":"1.168135750","rc":[{"batb":[[1,4.3,9.77]],"ltp":4.5,"tv":3320.0,"id":2764711}]}]}
{"op":"mcm","clk":"1004427343","pt":1580629608373,"mc":[{"id":"1.168135750","rc":[{"batb":[[2,12,1.5]],"ltp":15.5,"tv":161.44,"id":2764710}]}]}
{"op":"mcm","clk":"1004429251","pt":1580629651666,"mc":[{"id":"1.168135750","rc":[{"batl":[[0,19.5,7.6],[1,20,53],[2,1000,2.62]],"ltp":15.5,"tv":161.44,"id":2764710}]}]}
{"op":"mcm","clk":"1004429396","pt":1580629654546,"mc":[{"id":"1.168135750","rc":[{"batb":[[0,80,3.24],[1,60,16.67]],"ltp":80.0,"tv":4.54,"id":5720739}]}]}
{"op":"mcm","clk":"1004429450","pt":1580629655635,"mc":[{"id":"1.168135750","rc":[{"batb":[[0,80,3.05],[1,60,16.86]],"ltp":80.0,"tv":4.54,"id":5720739}]}]}
{"op":"mcm","clk":"1004429690","pt":1580629660565,"mc":[{"id":"1.168135750","rc":[{"batb":[[2,12.5,1.5]],"ltp":15.5,"tv":161.44,"id":2764710}]}]}
{"op":"mcm","clk":"1004430378","pt":1580629674650,"mc":[{"id":"1.168135750","rc":[{"batl":[[0,23,7.6],[1,29,10.24],[2,30,53]],"ltp":15.0,"tv":18.64,"id":2764714}]}]}
{"op":"mcm","clk":"1004430561","pt":1580629678755,"mc":[{"id":"1.168135750","rc":[{"batb":[[0,14.5,6.77]],"ltp":14.0,"tv":67.11,"id":2764715},{"batl":[[2,14,1.19]],"ltp":8.6,"tv":159.7,"id":5720738}]}]}
{"op":"mcm","clk":"1004431848","pt":1580629708624,"mc":[{"id":"1.168135750","rc":[{"batb":[[2,13,1.5]],"ltp":15.5,"tv":161.44,"id":2764710}]}]}
{"op":"mcm","clk":"1004432066","pt":1580629713616,"mc":[{"id":"1.168135750","rc":[{"batb":[[0,80,3.24],[1,60,16.67]],"ltp":80.0,"tv":4.54,"id":5720739}]}]}
{"op":"mcm","clk":"1004432481","pt":1580629722560,"mc":[{"id":"1.168135750","rc":[{"batb":[[2,11.5,1.5]],"ltp":15.5,"tv":161.44,"id":2764710}]}]}
{"op":"mcm","clk":"1004432649","pt":1580629726566,"mc":[{"id":"1.168135750","rc":[{"batb":[[0,80,3.05],[1,60,16.86]],"ltp":80.0,"tv":4.54,"id":5720739}]}]}
{"op":"mcm","clk":"1004434890","pt":1580629772600,"mc":[{"id":"1.168135750","rc":[{"batb":[[2,12,1.5]],"ltp":15.5,"tv":161.44,"id":2764710}]}]}
{"op":"mcm","clk":"1004435761","pt":1580629789734,"mc":[{"id":"1.168135750","rc":[{"batb":[[0,80,3.24],[1,60,16.67]],"ltp":80.0,"tv":4.54,"id":5720739}]}]}
{"op":"mcm","clk":"1004436133","pt":1580629797820,"mc":[{"id":"1.168135750","rc":[{"batb":[[0,80,3.05],[1,60,16.86]],"ltp":80.0,"tv":4.54,"id":5720739}]}]}
{"op":"mcm","clk":"1004436428","pt":1580629803630,"mc":[{"id":"1.168135750","rc":[{"batl":[[0,9,10.13],[1,9.8,11.65],[2,11,2.53]],"ltp":8.6,"tv":159.7,"id":5720738}]}]}
{"op":"mcm","clk":"1004436511","pt":1580629805733,"mc":[{"id":"1.168135750","rc":[{"batb":[[0,8.6,9.57]],"ltp":8.6,"tv":159.7,"id":5720738}]}]}
{"op":"mcm","clk":"1004437377","pt":1580629825785,"mc":[{"id":"1.168135750","rc":[{"batb":[[2,12.5,1.5]],"ltp":15.5,"tv":161.44,"id":2764710}]}]}
{"op":"mcm","clk":"1004437424","pt":1580629826763,"mc":[{"id":"1.168135750","rc":[{"batb":[[0,8,5.31],[1,7.8,19.39],[2,7.4,40.52]],"ltp":8.0,"tv":63.71,"id":2764720}]}]}
{"op":"mcm","clk":"1004438437","pt":1580629848375,"mc":[{"id":"1.168135750","rc":[{"batb":[[0,8.2,2],[1,8,5.31],[2,7.8,19.39]],"ltp":8.0,"tv":63.71,"id":2764720}]}]}
{"op":"mcm","clk":"1004438758","pt":1580629853720,"mc":[{"id":"1.168135750","rc":[{"batb":[[1,60,16.67]],"ltp":80.0,"tv":4.54,"id":5720739}]}]}
{"op":"mcm","clk":"1004438767","pt":1580629853822,"mc":[{"id":"1.168135750","rc":[{"batb":[[0,80,3.24]],"ltp":80.0,"tv":4.54,"id":5720739}]}]}
{"op":"mcm","clk":"1004439150","pt":1580629861788,"mc":[{"id":"1.168135750","rc":[{"batb":[[0,80,3.05]],"ltp":80.0,"tv":4.54,"id":5720739}]}]}
{"op":"mcm","clk":"1004439159","pt":1580629861890,"mc":[{"id":"1.168135750","rc":[{"batb":[[1,60,16.86]],"ltp":80.0,"tv":4.54,"id":5720739}]}]}
{"op":"mcm","clk":"1004439836","pt":1580629877721,"mc":[{"id":"1.168135750","rc":[{"batb":[[2,11,3.82]],"ltp":15.5,"tv":161.44,"id":2764710},{"batb":[[1,100,10.14]],"ltp":100.0,"tv":4.54,"id":5720737}]}]}
{"op":"mcm","clk":"1004439890","pt":1580629878642,"mc":[{"id":"1.168135750","rc":[{"batb":[[2,13,1.5]],"ltp":15.5,"tv":161.44,"id":2764710},{"batb":[[1,100,10.26]],"ltp":100.0,"tv":4.54,"id":5720737}]}]}
{"op":"mcm","clk":"1004440319","pt":1580629888729,"mc":[{"id":"1.168135750","rc":[{"batb":[[2,11,3.82]],"ltp":15.5,"tv":161.44,"id":2764710},{"batb":[[1,100,10.14]],"ltp":100.0,"tv":4.54,"id":5720737}]}]}
{"op":"mcm","clk":"1004440326","pt":1580629888831,"mc":[{"id":"1.168135750","rc":[{"batb":[[2,11.5,1.5]],"ltp":15.5,"tv":161.44,"id":2764710},{"batb":[[1,100,10.26]],"ltp":100.0,"tv":4.54,"id":5720737}]}]}
{"op":"mcm","clk":"1004441925","pt":1580629926771,"mc":[{"id":"1.168135750","rc":[{"batl":[[2,1000,2.53]],"ltp":15.5,"tv":161.44,"id":2764710},{"batb":[[1,60,16.67]],"ltp":80.0,"tv":4.54,"id":5720739},{"batl":[[1,80,3.04]],"ltp":24.0,"tv":24.33,"id":5720735}]}]}
{"op":"mcm","clk":"1004441928","pt":1580629926870,"mc":[{"id":"1.168135750","rc":[{"batl":[[2,1000,2.62]],"ltp":15.5,"tv":161.44,"id":2764710},{"batb":[[0,80,3.24]],"ltp":80.0,"tv":4.54,"id":5720739},{"batl":[[1,80,3.09]],"ltp":24.0,"tv":24.33,"id":5720735}]}]}
{"op":"mcm","clk":"1004442091","pt":1580629930984,"mc":[{"id":"1.168135750","rc":[{"batb":[[0,80,3.05],[1,60,16.86]],"ltp":80.0,"tv":4.54,"id":5720739}]}]}
{"op":"mcm","clk":"1004442353","pt":1580629938781,"mc":[{"id":"1.168135750","rc":[{"batb":[[2,12,1.5]],"ltp":15.5,"tv":161.44,"id":2764710}]}]}
{"op":"mcm","clk":"1004442873","pt":1580629952809,"mc":[{"id":"1.168135750","rc":[{"batb":[[1,100,10.14]],"ltp":100.0,"tv":4.54,"id":5720737}]}]}
{"op":"mcm","clk":"1004442908","pt":1580629953734,"mc":[{"id":"1.168135750","rc":[{"batb":[[1,100,10.26]],"ltp":100.0,"tv":4.54,"id":5720737}]}]}
{"op":"mcm","clk":"1004444005","pt":1580629983065,"mc":[{"id":"1.168135750","rc":[{"batb":[[2,12.5,1.5]],"ltp":15.5,"tv":161.44,"id":2764710}]}]}
{"op":"mcm","clk":"1004444289","pt":1580629990065,"mc":[{"id":"1.168135750","rc":[{"batb":[[0,80,3.24],[1,60,16.67]],"ltp":80.0,"tv":4.54,"id":5720739}]}]}
{"op":"mcm","clk":"1004444617","pt":1580629997685,"mc":[{"id":"1.168135750","rc":[{"batb":[[0,80,3.05],[1,60,16.86]],"ltp":80.0,"tv":4.54,"id":5720739}]}]}
{"op":"mcm","clk":"1004445195","pt":1580630011579,"mc":[{"id":"1.168135750","rc":[{"trd":[[8,275.72]],"batb":[[0,7,8.38],[1,6.8,10.73],[2,6.6,142.86]],"batl":[[0,8,117.31],[1,8.4,93],[2,8.6,21.6]],"ltp":8.0,"tv":1040.87,"id":5720732}],"tv":5122.41}]}
{"op":"mcm","clk":"1004445362","pt":1580630015691,"mc":[{"id":"1.168135750","rc":[{"batb":[[2,11.5,1.5]],"ltp":15.5,"tv":161.44,"id":2764710},{"batb":[[0,14.5,11.86],[1,14,19.25],[2,9.2,4.56]],"ltp":15.0,"tv":18.64,"id":2764714},{"batb":[[0,27,3.04],[2,22,2.46]],"ltp":32.0,"tv":47.19,"id":5720734},{"batb":[[1,5.7,3.15],[2,5.6,20.75]],"ltp":5.9,"tv":192.59,"id":2764722},{"batl":[[1,8.4,93.48]],"ltp":8.0,"tv":1040.87,"id":5720732}]}]}
{"op":"mcm","clk":"1004445613","pt":1580630021917,"mc":[{"id":"1.168135750","rc":[{"batl":[[1,8.4,93]],"ltp":8.0,"tv":1040.87,"id":5720732}]}]}
{"op":"mcm","clk":"1004445746","pt":1580630025414,"mc":[{"id":"1.168135750","rc":[{"trd":[[4.5,953.72]],"batl":[[0,4.5,478.91]],"ltp":4.5,"tv":3336.86,"id":2764711}],"tv":5139.27}]}
{"op":"mcm","clk":"1004447190","pt":1580630058050,"mc":[{"id":"1.168135750","rc":[{"trd":[[19.5,0.25]],"batl":[[0,19.5,7.34]],"ltp":19.5,"tv":161.69,"id":2764710},{"trd":[[4.5,954.82]],"batl":[[0,4.5,477.81]],"ltp":4.5,"tv":3337.96,"id":2764711},{"trd":[[9.8,0.51]],"batl":[[0,11.5,11.14]],"ltp":9.8,"tv":64.21,"id":2764720},{"trd":[[1000,0.01]],"batl":[[0,1000,4.55]],"ltp":1000.0,"tv":4.54,"id":5720739},{"trd":[[19.5,0.25]],"batl":[[0,23,7.34]],"ltp":19.5,"tv":18.9,"id":2764714},{"trd":[[15,0.33]],"batl":[[0,15,2.2]],"ltp":15.0,"tv":67.44,"id":2764715},{"trd":[[9,0.55]],"batl":[[0,9,9.58]],"ltp":9.0,"tv":160.25,"id":5720738},{"trd":[[1000,0.01]],"batl":[[0,1000,2.53]],"ltp":1000.0,"tv":4.54,"id":2764717},{"trd":[[29,8.67]],"batl":[[0,29,4.89]],"ltp":29.0,"tv":24.5,"id":5720735},{"trd":[[26,8],[27,6.26]],"batb":[[0,22,2.46],[1,21,47.62],[2,1.5,2.53]],"batl":[[0,26,5.44],[1,48,12.73],[2,50,53]],"ltp":26.0,"tv":61.45,"id":5720734},{"trd":[[28,0.18]],"batl":[[0,28,2.36]],"ltp":28.0,"tv":13.35,"id":5720736},{"trd":[[6.2,0.8]],"batl":[[0,6.2,6.27]],"ltp":6.2,"tv":193.39,"id":2764722},{"trd":[[8,276.34]],"batl":[[0,8,116.69]],"ltp":8.0,"tv":1041.49,"id":5720732}],"tv":5158.3}]}
{"op":"mcm","clk":"1004447356","pt":1580630062255,"mc":[{"id":"1.168135750","rc":[{"batb":[[0,14.5,1.02]],"ltp":19.5,"tv":18.9,"id":2764714}]}]}
{"op":"mcm","clk":"1004447563","pt":1580630067466,"mc":[{"id":"1.168135750","rc":[{"batb":[[0,80,3.24],[1,60,16.67]],"ltp":1000.0,"tv":4.54,"id":5720739}]}]}
{"op":"mcm","clk":"1004448063","pt":1580630078761,"mc":[{"id":"1.168135750","rc":[{"batb":[[0,15.5,10.14],[1,14.5,1.02],[2,14,19.25]],"ltp":19.5,"tv":18.9,"id":2764714}]}]}
{"op":"mcm","clk":"1004448157","pt":1580630081348,"mc":[{"id":"1.168135750","rc":[{"trd":[[4.3,19.53],[4.4,54.2]],"batb":[[0,3.8,44.57],[1,3.5,285.71],[2,1.01,1.01]],"batl":[[0,4.3,98.18],[1,4.5,477.81],[2,4.7,493.34]],"ltp":4.3,"tv":3394.89,"id":2764711}],"tv":5215.24}]}
{"op":"mcm","clk":"1004448284","pt":1580630084761,"mc":[{"id":"1.168135750","rc":[{"batb":[[0,15.5,1.52]],"ltp":19.5,"tv":161.69,"id":2764710},{"batb":[[0,14.5,1.02],[1,14,19.25],[2,9.2,4.56]],"ltp":19.5,"tv":18.9,"id":2764714}]}]}
{"op":"mcm","clk":"1004448342","pt":1580630086664,"mc":[{"id":"1.168135750","rc":[{"trd":[[4.3,24.6]],"batl":[[0,4.3,95.64]],"ltp":4.3,"tv":3399.96,"id":2764711}],"tv":5220.3}]}
{"op":"mcm","clk":"1004448454","pt":1580630090373,"mc":[{"id":"1.168135750","rc":[{"batl":[[1,4.6,477.81]],"ltp":4.3,"tv":3399.96,"id":2764711}]}]}
{"op":"mcm","clk":"1004448507","pt":1580630091312,"mc":[{"id":"1.168135750","rc":[{"batb":[[2,11,3.82]],"ltp":19.5,"tv":161.69,"id":2764710},{"batl":[[1,4.4,1.01],[2,4.6,477.81]],"ltp":4.3,"tv":3399.96,"id":2764711},{"batb":[[0,14,19.25],[1,9.6,1.02]],"ltp":19.5,"tv":18.9,"id":2764714},{"batb":[[0,23,16.85],[1,13,3.88],[2,12,83.33]],"ltp":29.0,"tv":24.5,"id":5720735},{"batb":[[0,7,6],[1,6.8,13.11]],"ltp":8.0,"tv":1041.49,"id":5720732}]}]}
{"op":"mcm","clk":"1004448640","pt":1580630094094,"mc":[{"id":"1.168135750","rc":[{"batl":[[1,4.6,477.81],[2,4.7,493.34]],"ltp":4.3,"tv":3399.96,"id":2764711}]}]}
{"op":"mcm","clk":"1004448834","pt":1580630098210,"mc":[{"id":"1.168135750","rc":[{"batb":[[0,14.5,5.68],[2,13.5,1.09]],"ltp":15.0,"tv":67.44,"id":2764715}]}]}
{"op":"mcm","clk":"1004449569","pt":1580630114518,"mc":[{"id":"1.168135750","rc":[{"trd":[[15.5,79.06],[16,21.12],[16.5,22.84],[18,0.27]],"batb":[[0,15,4.12],[1,11,3.82],[2,10.5,1.5]],"ltp":15.5,"tv":185.0,"id":2764710},{"trd":[[4.3,32.29]],"batl":[[0,4.3,87.96]],"ltp":4.3,"tv":3407.65,"id":2764711},{"trd":[[11.5,2.88]],"batl":[[0,11.5,8.27]],"ltp":11.5,"tv":67.09,"id":2764720},{"trd":[[1000,0.04]],"batl":[[0,1000,4.52]],"ltp":1000.0,"tv":4.58,"id":5720739},{"trd":[[19.5,0.51],[23,1.22]],"batb":[[0,18.5,8.49],[1,14,19.25],[2,9.6,1.02]],"batl":[[0,23,5.87]],"ltp":23.0,"tv":20.37,"id":2764714},{"trd":[[15,2.53]],"batl":[[0,16,6.08],[1,1000,5.17],[2,1000,0]],"ltp":15.0,"tv":69.64,"id":2764715},{"trd":[[9,4.22]],"batl":[[0,9,5.91]],"ltp":9.0,"tv":163.93,"id":5720738},{"trd":[[1000,0.04]],"batl":[[0,1000,2.49]],"ltp":1000.0,"tv":4.57,"id":2764717},{"trd":[[29,9.81]],"batl":[[0,29,3.75]],"ltp":29.0,"tv":25.64,"id":5720735},{"trd":[[26,9.26]],"batl":[[0,26,4.18]],"ltp":26.0,"tv":62.71,"id":5720734},{"trd":[[28,1.36]],"batl":[[0,28,1.18]],"ltp":28.0,"tv":14.53,"id":5720736},{"trd":[[6.2,6.13]],"batl":[[0,6.4,1.44],[1,6.6,15.2]],"ltp":6.2,"tv":198.72,"id":2764722},{"trd":[[8,280.47]],"batl":[[0,8,112.56]],"ltp":8.0,"tv":1045.62,"id":5720732}],"tv":5274.64}]}
{"op":"mcm","clk":"1004450497","pt":1580630134358,"mc":[{"id":"1.168135750","rc":[{"batl":[[0,4.2,1.07],[1,4.3,87.96],[2,4.6,477.81]],"ltp":4.3,"tv":3407.65,"id":2764711}]}]}
{"op":"mcm","clk":"1004451173","pt":1580630148765,"mc":[{"id":"1.168135750","rc":[{"batb":[[0,14.5,6.77],[2,13,3.23]],"ltp":15.0,"tv":69.64,"id":2764715}]}]}
{"op":"mcm","clk":"1004451204","pt":1580630149462,"mc":[{"id":"1.168135750","rc":[{"trd":[[4.2,2.14],[4.3,48.32]],"batl":[[0,4.3,79.94],[1,4.6,477.81],[2,4.7,493.34]],"ltp":4.3,"tv":3425.82,"id":2764711}],"tv":5292.81}]}
{"op":"mcm","clk":"1004451309","pt":1580630151663,"mc":[{"id":"1.168135750","rc":[{"batl":[[0,48,3.81],[1,80,3.04]],"ltp":29.0,"tv":25.64,"id":5720735}]}]}
{"op":"mcm","clk":"1004451610","pt":1580630158397,"mc":[{"id":"1.168135750","rc":[{"batb":[[0,3.85,1.16],[1,3.8,44.57],[2,3.5,285.71]],"ltp":4.3,"tv":3425.82,"id":2764711},{"batb":[[0,14.5,5.68],[1,14,11.5]],"ltp":15.0,"tv":69.64,"id":2764715},{"batl":[[0,48,3.75],[1,80,3.09]],"ltp":29.0,"tv":25.64,"id":5720735}]}]}
{"op":"mcm","clk":"1004451926","pt":1580630164317,"mc":[{"id":"1.168135750","rc":[{"batb":[[0,85,1.17],[1,80,2.07],[2,60,16.67]],"ltp":1000.0,"tv":4.58,"id":5720739},{"batb":[[1,14,10.41],[2,13.5,1.09]],"ltp":15.0,"tv":69.64,"id":2764715}]}]}
{"op":"mcm","clk":"1004452347","pt":1580630173228,"mc":[{"id":"1.168135750","rc":[{"batb":[[2,10.5,49.12]],"ltp":15.5,"tv":185.0,"id":2764710},{"batb":[[0,85,7.05]],"ltp":1000.0,"tv":4.58,"id":5720739},{"batb":[[1,14.5,34.48],[2,14,19.25]],"ltp":23.0,"tv":20.37,"id":2764714},{"batb":[[0,14.5,40.16]],"ltp":15.0,"tv":69.64,"id":2764715},{"batb":[[0,8.6,67.71]],"ltp":9.0,"tv":163.93,"id":5720738},{"batb":[[0,60,9.83]],"ltp":1000.0,"tv":4.57,"id":2764717},{"batb":[[0,24,21.72],[1,23,15.96],[2,13,3.88]],"ltp":29.0,"tv":25.64,"id":5720735},{"batb":[[0,22,25.19]],"ltp":26.0,"tv":62.71,"id":5720734},{"batb":[[1,110,4.84],[2,100,9.97]],"ltp":100.0,"tv":4.54,"id":5720737},{"batb":[[0,27,18.52],[1,26,5.33],[2,25,14.13]],"ltp":28.0,"tv":14.53,"id":5720736},{"batb":[[0,6,83.33],[1,5.9,14.37],[2,5.7,3.15]],"ltp":6.2,"tv":198.72,"id":2764722},{"batb":[[0,7,77.43]],"ltp":8.0,"tv":1045.62,"id":5720732}]}]}
{"op":"mcm","clk":"1004452646","pt":1580630177532,"mc":[{"id":"1.168135750","rc":[{"batb":[[1,26,2.16]],"ltp":28.0,"tv":14.53,"id":5720736},{"batb":[[1,5.7,3.56],[2,5.6,20.75]],"ltp":6.2,"tv":198.72,"id":2764722}]}]}
{"op":"mcm","clk":"1004452917","pt":1580630183427,"mc":[{"id":"1.168135750","rc":[{"batb":[[0,27,19.11],[1,26,1.57]],"ltp":28.0,"tv":14.53,"id":5720736},{"batb":[[1,5.6,21.16],[2,5.5,181.82]],"ltp":6.2,"tv":198.72,"id":2764722},{"batb":[[1,6.8,10.73]],"ltp":8.0,"tv":1045.62,"id":5720732}]}]}
{"op":"mcm","clk":"1004453492","pt":1580630193237,"mc":[{"id":"1.168135750","rc":[{"trd":[[28,3.71]],"batb":[[0,28,1.76],[1,27,19.11],[2,26,1.57]],"batl":[[0,40,4.05],[1,1000,2.58],[2,1000,0]],"ltp":28.0,"tv":16.88,"id":5720736},{"trd":[[6.2,8]],"batb":[[0,6.2,12.35],[1,6,83.33],[2,5.6,21.16]],"batl":[[0,6.6,15.7],[1,6.8,29.41],[2,7.4,12.53]],"ltp":6.2,"tv":200.58,"id":2764722}],"tv":5297.03}]}
{"op":"mcm","clk":"1004454412","pt":1580630212143,"mc":[{"id":"1.168135750","rc":[{"batb":[[2,13,3.23]],"ltp":15.0,"tv":69.64,"id":2764715}]}]}
{"op":"mcm","clk":"1004454723","pt":1580630218456,"mc":[{"id":"1.168135750","rc":[{"batl":[[1,4.6,478.48]],"ltp":4.3,"tv":3425.82,"id":2764711}]}]}
{"op":"mcm","clk":"1004454847","pt":1580630221360,"mc":[{"id":"1.168135750","rc":[{"batb":[[0,24,22.36],[2,13,3.23]],"ltp":29.0,"tv":25.64,"id":5720735}]}]}
{"op":"mcm","clk":"1004456320","pt":1580630249507,"mc":[{"id":"1.168135750","rc":[{"batl":[[1,4.6,477.81]],"ltp":4.3,"tv":3425.82,"id":2764711},{"batb":[[1,15,1.02],[2,14.5,34.48]],"ltp":23.0,"tv":20.37,"id":2764714}]}]}
{"op":"mcm","clk":"1004456811","pt":1580630258635,"mc":[{"id":"1.168135750","rc":[{"batl":[[1,4.6,478.48]],"ltp":4.3,"tv":3425.82,"id":2764711}]}]}
{"op":"mcm","clk":"1004457406","pt":1580630271464,"mc":[{"id":"1.168135750","rc":[{"batb":[[0,28,2.36],[1,27,18.52]],"ltp":28.0,"tv":16.88,"id":5720736}]}]}
{"op":"mcm","clk":"1004458157","pt":1580630290274,"mc":[{"id":"1.168135750","rc":[{"batl":[[1,4.6,477.81]],"ltp":4.3,"tv":3425.82,"id":2764711}]}]}
{"op":"mcm","clk":"1004458370","pt":1580630295104,"mc":[{"id":"1.168135750","rc":[{"trd":[[26,17.26]],"batl":[[0,48,12.91],[1,50,53],[2,1000,2.53]],"ltp":26.0,"tv":70.71,"id":5720734}],"tv":5305.02}]}
{"op":"mcm","clk":"1004458585","pt":1580630298709,"mc":[{"id":"1.168135750","rc":[{"batl":[[1,4.6,478.48]],"ltp":4.3,"tv":3425.82,"id":2764711}]}]}
{"op":"mcm","clk":"1004460400","pt":1580630338531,"mc":[{"id":"1.168135750","rc":[{"batl":[[0,4.2,323],[1,4.3,79.94],[2,4.6,478.48]],"ltp":4.3,"tv":3425.82,"id":2764711}]}]}
{"op":"mcm","clk":"1004460733","pt":1580630346477,"mc":[{"id":"1.168135750","rc":[{"batl":[[2,4.6,477.81]],"ltp":4.3,"tv":3425.82,"id":2764711}]}]}
{"op":"mcm","clk":"1004461165","pt":1580630357559,"mc":[{"id":"1.168135750","rc":[{"trd":[[19.5,7.83]],"batl":[[0,19.5,3.56]],"ltp":19.5,"tv":192.57,"id":2764710}],"tv":5312.6}]}
{"op":"mcm","clk":"1004466006","pt":1580630447714,"mc":[{"id":"1.168135750","rc":[{"batb":[[0,8,5.31],[1,7.8,19.39],[2,7.4,40.52]],"ltp":11.5,"tv":67.09,"id":2764720}]}]}
{"op":"mcm","clk":"1004466402","pt":1580630455620,"mc":[{"id":"1.168135750","rc":[{"batb":[[2,10.5,47.62]],"batl":[[2,1000,0]],"ltp":19.5,"tv":192.57,"id":2764710},{"batb":[[0,3.8,44.57],[1,3.5,285.71],[2,3,166.67]],"ltp":4.3,"tv":3425.82,"id":2764711},{"batb":[[0,8,5.18]],"batl":[[1,14.5,7.6]],"ltp":11.5,"tv":67.09,"id":2764720},{"batb":[[0,85,6.85]],"ltp":1000.0,"tv":4.58,"id":5720739},{"batb":[[1,14.5,34.48],[2,14,19.25]],"batl":[[1,29,10.13]],"ltp":23.0,"tv":20.37,"id":2764714},{"batl":[[1,1000,2.53]],"ltp":15.0,"tv":69.64,"id":2764715},{"batb":[[0,60,9.58]],"ltp":1000.0,"tv":4.57,"id":2764717},{"batb":[[0,24,21.72]],"batl":[[1,80,3.04],[2,1000,0]],"ltp":29.0,"tv":25.64,"id":5720735},{"batb":[[0,22,24.64],[2,1.01,1.01]],"batl":[[0,48,12.85],[2,1000,0]],"ltp":26.0,"tv":70.71,"id":5720734},{"batb":[[1,110,4.72]],"ltp":100.0,"tv":4.54,"id":5720737},{"batb":[[0,28,1.76]],"batl":[[1,1000,0]],"ltp":28.0,"tv":16.88,"id":5720736}]}]}
{"op":"mcm","clk":"1004466674","pt":1580630461738,"mc":[{"id":"1.168135750","rc":[{"batb":[[0,3.85,2],[1,3.8,44.57],[2,3.5,285.71]],"ltp":4.3,"tv":3425.82,"id":2764711}]}]}
{"op":"mcm","clk":"1004466735","pt":1580630462814,"mc":[{"id":"1.168135750","rc":[{"batb":[[0,8.2,2],[1,8,5.18],[2,7.8,19.39]],"ltp":11.5,"tv":67.09,"id":2764720}]}]}
{"op":"mcm","clk":"1004467677","pt":1580630485786,"mc":[{"id":"1.168135750","rc":[{"batl":[[2,1000,2.63]],"ltp":19.5,"tv":192.57,"id":2764710},{"batl":[[1,1000,5.16]],"ltp":15.0,"tv":69.64,"id":2764715},{"batl":[[2,1000,2.57]],"ltp":29.0,"tv":25.64,"id":5720735},{"batb":[[2,1.5,3.05]],"batl":[[2,1000,2.58]],"ltp":26.0,"tv":70.71,"id":5720734},{"batl":[[1,1000,2.57]],"ltp":28.0,"tv":16.88,"id":5720736}]}]}
{"op":"mcm","clk":"1004467698","pt":1580630486203,"mc":[{"id":"1.168135750","rc":[{"batb":[[1,11,4.96]],"ltp":19.5,"tv":192.57,"id":2764710},{"batb":[[0,3.85,3.16]],"ltp":4.3,"tv":3425.82,"id":2764711},{"batl":[[1,14.5,9]],"ltp":11.5,"tv":67.09,"id":2764720},{"batb":[[0,85,6.97]],"ltp":1000.0,"tv":4.58,"id":5720739},{"batb":[[1,14.5,35.29]],"batl":[[1,29,10.22]],"ltp":23.0,"tv":20.37,"id":2764714},{"batb":[[0,60,9.75]],"ltp":1000.0,"tv":4.57,"id":2764717},{"batb":[[0,24,22.2]],"batl":[[1,80,3.07],[2,1000,2.53]],"ltp":29.0,"tv":25.64,"id":5720735},{"batb":[[0,22,25.15],[2,1.5,2.53]],"batl":[[0,48,12.9],[2,1000,2.53]],"ltp":26.0,"tv":70.71,"id":5720734},{"batb":[[1,110,4.81]],"ltp":100.0,"tv":4.54,"id":5720737},{"batb":[[0,28,2.18]],"ltp":28.0,"tv":16.88,"id":5720736}]}]}
{"op":"mcm","clk":"1004468059","pt":1580630494067,"mc":[{"id":"1.168135750","rc":[{"batl":[[0,9,6.41],[1,9.8,11.14]],"ltp":9.0,"tv":163.93,"id":5720738},{"trd":[[6.2,9.01]],"batb":[[0,6.2,11.85]],"batl":[[0,6.6,15.2]],"ltp":6.2,"tv":201.59,"id":2764722}],"tv":5313.61}]}
{"op":"mcm","clk":"1004468166","pt":1580630496794,"mc":[{"id":"1.168135750","rc":[{"batb":[[1,8,5.4]],"ltp":11.5,"tv":67.09,"id":2764720}]}]}
{"op":"mcm","clk":"1004469519","pt":1580630526537,"mc":[{"id":"1.168135750","rc":[{"batl":[[0,1000,2.53]],"ltp":100.0,"tv":4.54,"id":5720737}]}]}
{"op":"mcm","clk":"1004469645","pt":1580630529020,"mc":[{"id":"1.168135750","rc":[{"batl":[[0,1000,3.04]],"ltp":100.0,"tv":4.54,"id":5720737}]}]}
{"op":"mcm","clk":"1004469901","pt":1580630533250,"mc":[{"id":"1.168135750","rc":[{"batl":[[0,1000,0.51]],"ltp":100.0,"tv":4.54,"id":5720737}]}]}
{"op":"mcm","clk":"1004470408","pt":1580630542326,"mc":[{"id":"1.168135750","rc":[{"batl":[[0,1000,7.05]],"ltp":1000.0,"tv":4.58,"id":5720739}]}]}
{"op":"mcm","clk":"1004470619","pt":1580630546384,"mc":[{"id":"1.168135750","rc":[{"batl":[[0,1000,7.56]],"ltp":1000.0,"tv":4.58,"id":5720739}]}]}
{"op":"mcm","clk":"1004470846","pt":1580630550770,"mc":[{"id":"1.168135750","rc":[{"batl":[[0,1000,5.02]],"ltp":1000.0,"tv":4.58,"id":5720739}]}]}
{"op":"mcm","clk":"1004471191","pt":1580630557392,"mc":[{"id":"1.168135750","rc":[{"batl":[[0,990,0.51]],"ltp":100.0,"tv":4.54,"id":5720737}]}]}
{"op":"mcm","clk":"1004472898","pt":1580630597756,"mc":[{"id":"1.168135750","rc":[{"batl":[[0,1000,5.02]],"ltp":1000.0,"tv":4.57,"id":2764717}]}]}
{"op":"mcm","clk":"1004473062","pt":1580630601923,"mc":[{"id":"1.168135750","rc":[{"batl":[[0,1000,5.53]],"ltp":1000.0,"tv":4.57,"id":2764717}]}]}
{"op":"mcm","clk":"1004473304","pt":1580630608147,"mc":[{"id":"1.168135750","rc":[{"batl":[[0,1000,3]],"ltp":1000.0,"tv":4.57,"id":2764717}]}]}
{"op":"mcm","clk":"1004474469","pt":1580630635803,"mc":[{"id":"1.168135750","rc":[{"trd":[[8.2,8.95]],"batb":[[0,8,5.4],[1,7.8,19.39],[2,7.4,40.52]],"ltp":8.2,"tv":71.09,"id":2764720}],"tv":5317.61}]}
{"op":"mcm","clk":"1004474755","pt":1580630642090,"mc":[{"id":"1.168135750","rc":[{"trd":[[8,292.58]],"batl":[[0,8,106.5]],"ltp":8.0,"tv":1057.73,"id":5720732}],"tv":5329.72}]}
{"op":"mcm","clk":"1004474855","pt":1580630643794,"mc":[{"id":"1.168135750","rc":[{"batb":[[0,8,5.18]],"ltp":8.2,"tv":71.09,"id":2764720}]}]}
{"op":"mcm","clk":"1004474861","pt":1580630643894,"mc":[{"id":"1.168135750","rc":[{"batb":[[2,7.4,40.74]],"ltp":8.2,"tv":71.09,"id":2764720}]}]}
{"op":"mcm","clk":"1004476644","pt":1580630677771,"mc":[{"id":"1.168135750","rc":[{"batb":[[0,17,5.63],[1,15,4.12],[2,11,4.96]],"ltp":19.5,"tv":192.57,"id":2764710},{"batb":[[2,3.5,321.71]],"ltp":4.3,"tv":3425.82,"id":2764711},{"batb":[[0,8,18.04]],"ltp":8.2,"tv":71.09,"id":2764720},{"batb":[[0,85,7.67]],"ltp":1000.0,"tv":4.58,"id":5720739},{"batb":[[1,17,5.63],[2,14.5,35.29]],"ltp":23.0,"tv":20.37,"id":2764714},{"batb":[[2,13,10.73]],"ltp":15.0,"tv":69.64,"id":2764715},{"batb":[[0,65,1.58],[1,60,9.58],[2,55,3.45]],"ltp":1000.0,"tv":4.57,"id":2764717},{"batb":[[0,29,3.21],[1,24,22.2],[2,23,15.96]],"ltp":29.0,"tv":25.64,"id":5720735},{"trd":[[26,17.62]],"batb":[[0,42,2.02],[1,22,25.15],[2,21,47.62]],"batl":[[0,48,12.71]],"ltp":26.0,"tv":71.07,"id":5720734},{"batb":[[0,29,3.21],[1,28,2.18],[2,27,18.52]],"ltp":28.0,"tv":16.88,"id":5720736},{"batb":[[0,7.4,14.06],[1,7,77.43],[2,6.8,10.73]],"ltp":8.0,"tv":1057.73,"id":5720732}],"tv":5330.09}]}
{"op":"mcm","clk":"1004476671","pt":1580630678490,"mc":[{"id":"1.168135750","rc":[{"batb":[[1,7.2,10.13],[2,7,77.43]],"ltp":8.0,"tv":1057.73,"id":5720732}]}]}
{"op":"mcm","clk":"1004476740","pt":1580630679797,"mc":[{"id":"1.168135750","rc":[{"batb":[[1,7.2,11.97]],"ltp":8.0,"tv":1057.73,"id":5720732}]}]}
{"op":"mcm","clk":"1004476788","pt":1580630680466,"mc":[{"id":"1.168135750","rc":[{"batb":[[1,24,21.31]],"ltp":29.0,"tv":25.64,"id":5720735},{"batb":[[1,27,18.94],[2,26,1.57]],"ltp":28.0,"tv":16.88,"id":5720736}]}]}
{"op":"mcm","clk":"1004477079","pt":1580630688974,"mc":[{"id":"1.168135750","rc":[{"batb":[[0,8,18.26],[2,7.4,40.52]],"ltp":8.2,"tv":71.09,"id":2764720}]}]}
{"op":"mcm","clk":"1004477457","pt":1580630696669,"mc":[{"id":"1.168135750","rc":[{"batb":[[0,29,3.92]],"ltp":29.0,"tv":25.64,"id":5720735}]}]}
{"op":"mcm","clk":"1004477468","pt":1580630696868,"mc":[{"id":"1.168135750","rc":[{"batb":[[0,30,1.65],[1,29,3.21],[2,27,18.94]],"ltp":28.0,"tv":16.88,"id":5720736}]}]}
{"op":"mcm","clk":"1004477514","pt":1580630697897,"mc":[{"id":"1.168135750","rc":[{"batb":[[1,7.2,10.13]],"ltp":8.0,"tv":1057.73,"id":5720732}]}]}
{"op":"mcm","clk":"1004478018","pt":1580630709417,"mc":[{"id":"1.168135750","rc":[{"batb":[[2,11,3.82]],"ltp":19.5,"tv":192.57,"id":2764710},{"batb":[[2,14.5,34.48]],"ltp":23.0,"tv":20.37,"id":2764714},{"batb":[[1,24,20.83]],"ltp":29.0,"tv":25.64,"id":5720735},{"batb":[[1,22,24.64]],"ltp":26.0,"tv":71.07,"id":5720734},{"batb":[[2,27,18.52]],"ltp":28.0,"tv":16.88,"id":5720736}]}]}
{"op":"mcm","clk":"1004481228","pt":1580630783542,"mc":[{"id":"1.168135750","rc":[{"trd":[[4.2,20.22]],"batl":[[0,4.2,313.96]],"ltp":4.2,"tv":3443.9,"id":2764711}],"tv":5348.17}]}
{"op":"mcm","clk":"1004481995","pt":1580630802103,"mc":[{"id":"1.168135750","rc":[{"trd":[[9,14.35]],"batl":[[0,9,1.35]],"ltp":9.0,"tv":174.06,"id":5720738}],"tv":5358.3}]}
{"op":"mcm","clk":"1004482230","pt":1580630808776,"mc":[{"id":"1.168135750","rc":[{"batl":[[2,1000,2.53]],"ltp":19.5,"tv":192.57,"id":2764710},{"batl":[[1,1000,5.07]],"ltp":15.0,"tv":69.64,"id":2764715},{"batl":[[1,1000,2.53]],"ltp":28.0,"tv":16.88,"id":5720736}]}]}
{"op":"mcm","clk":"1004483470","pt":1580630839434,"mc":[{"id":"1.168135750","rc":[{"trd":[[8,333.1]],"batl":[[0,8,86.24]],"ltp":8.0,"tv":1098.25,"id":5720732}],"tv":5398.82}]}
{"op":"mcm","clk":"1004484014","pt":1580630852672,"mc":[{"id":"1.168135750","rc":[{"trd":[[7,154.36],[7.2,20.25],[7.4,28.11]],"batb":[[0,6.6,143.07],[1,6,60.78],[2,1.5,2.53]],"ltp":7.0,"tv":1300.97,"id":5720732}],"tv":5601.53}]}
{"op":"mcm","clk":"1004484390","pt":1580630862790,"mc":[{"id":"1.168135750","rc":[{"batl":[[2,55,2.53]],"ltp":26.0,"tv":71.07,"id":5720734}]}]}
{"op":"mcm","clk":"1004484631","pt":1580630868789,"mc":[{"id":"1.168135750","rc":[{"batl":[[2,55,3.04]],"ltp":26.0,"tv":71.07,"id":5720734}]}]}
{"op":"mcm","clk":"1004485005","pt":1580630877792,"mc":[{"id":"1.168135750","rc":[{"trd":[[42,1.02]],"batb":[[0,42,1.51]],"batl":[[2,1000,2.53]],"ltp":42.0,"tv":72.09,"id":5720734},{"batl":[[1,8.2,50.65],[2,8.4,93]],"ltp":7.0,"tv":1300.97,"id":5720732}],"tv":5602.55}]}
{"op":"mcm","clk":"1004485053","pt":1580630879223,"mc":[{"id":"1.168135750","rc":[{"trd":[[9,17.05],[9.8,25.63]],"batl":[[0,9.8,8.67],[1,11,2.53],[2,14.5,1.19]],"ltp":9.8,"tv":181.71,"id":5720738}],"tv":5610.2}]}
{"op":"mcm","clk":"1004485200","pt":1580630882321,"mc":[{"id":"1.168135750","rc":[{"batb":[[0,4,100],[1,3.85,3.16],[2,3.8,44.57]],"ltp":4.2,"tv":3443.9,"id":2764711},{"trd":[[14.5,14.19]],"batb":[[0,14.5,33.06]],"ltp":14.5,"tv":83.83,"id":2764715}],"tv":5624.39}]}
{"op":"mcm","clk":"1004485285","pt":1580630884438,"mc":[{"id":"1.168135750","rc":[{"batl":[[2,14,1.19]],"ltp":9.8,"tv":181.71,"id":5720738}]}]}
{"op":"mcm","clk":"1004485450","pt":1580630888401,"mc":[{"id":"1.168135750","rc":[{"trd":[[8,27.12]],"batb":[[0,8,13.19]],"ltp":8.0,"tv":81.22,"id":2764720}],"tv":5634.52}]}
{"op":"mcm","clk":"1004485498","pt":1580630889540,"mc":[{"id":"1.168135750","rc":[{"batb":[[0,4.1,1.09],[1,4,100],[2,3.85,2]],"ltp":4.2,"tv":3443.9,"id":2764711}]}]}
{"op":"mcm","clk":"1004486067","pt":1580630904233,"mc":[{"id":"1.168135750","rc":[{"batl":[[0,880,0.51]],"ltp":100.0,"tv":4.54,"id":5720737}]}]}
{"op":"mcm","clk":"1004486114","pt":1580630905724,"mc":[{"id":"1.168135750","rc":[{"batb":[[0,85,7.55]],"ltp":1000.0,"tv":4.58,"id":5720739}]}]}
{"op":"mcm","clk":"1004486160","pt":1580630907264,"mc":[{"id":"1.168135750","rc":[{"trd":[[4,107.27],[4.1,2.19]],"batb":[[0,4,46.34],[1,3.85,2],[2,3.8,44.57]],"ltp":4.0,"tv":3553.35,"id":2764711}],"tv":5743.98}]}
{"op":"mcm","clk":"1004486340","pt":1580630911848,"mc":[{"id":"1.168135750","rc":[{"batb":[[2,5,3.04]],"ltp":7.0,"tv":1300.97,"id":5720732}]}]}
{"op":"mcm","clk":"1004486472","pt":1580630914850,"mc":[{"id":"1.168135750","rc":[{"batb":[[0,8,13.08]],"ltp":8.0,"tv":81.22,"id":2764720},{"batl":[[0,80,3.07],[1,1000,2.53],[2,1000,0]],"ltp":29.0,"tv":25.64,"id":5720735}]}]}
{"op":"mcm","clk":"1004486832","pt":1580630923802,"mc":[{"id":"1.168135750","rc":[{"batl":[[2,14.5,1.19]],"ltp":9.8,"tv":181.71,"id":5720738},{"batl":[[0,80,3.04]],"ltp":29.0,"tv":25.64,"id":5720735}]}]}
{"op":"mcm","clk":"1004486845","pt":1580630923957,"mc":[{"id":"1.168135750","rc":[{"batb":[[2,5,5.07]],"ltp":7.0,"tv":1300.97,"id":5720732}]}]}
{"op":"mcm","clk":"1004487095","pt":1580630929799,"mc":[{"id":"1.168135750","rc":[{"batl":[[0,4.1,79.94],[1,4.2,313.96]],"ltp":4.0,"tv":3553.35,"id":2764711},{"batb":[[0,6.2,142.86]],"ltp":7.0,"tv":1300.97,"id":5720732}]}]}
{"op":"mcm","clk":"1004487217","pt":1580630932789,"mc":[{"id":"1.168135750","rc":[{"batl":[[1,95,2.53],[2,1000,2.53]],"ltp":29.0,"tv":25.64,"id":5720735},{"batb":[[2,5,2.03]],"ltp":7.0,"tv":1300.97,"id":5720732}]}]}
{"op":"mcm","clk":"1004487323","pt":1580630936276,"mc":[{"id":"1.168135750","rc":[{"batl":[[0,7.8,71],[1,8,86.24],[2,8.2,50.65]],"ltp":7.0,"tv":1300.97,"id":5720732}]}]}
{"op":"mcm","clk":"1004487369","pt":1580630937613,"mc":[{"id":"1.168135750","rc":[{"batl":[[1,95,2.79]],"ltp":29.0,"tv":25.64,"id":5720735}]}]}
{"op":"mcm","clk":"1004487410","pt":1580630938797,"mc":[{"id":"1.168135750","rc":[{"batb":[[2,1.5,2.53]],"ltp":7.0,"tv":1300.97,"id":5720732}]}]}
{"op":"mcm","clk":"1004487416","pt":1580630938898,"mc":[{"id":"1.168135750","rc":[{"trd":[[7.8,4.06]],"batl":[[0,7.8,68.97]],"ltp":7.8,"tv":1305.02,"id":5720732}],"tv":5748.04}]}
{"op":"mcm","clk":"1004487678","pt":1580630945143,"mc":[{"id":"1.168135750","rc":[{"batl":[[0,80,3.29],[1,1000,2.53],[2,1000,0]],"ltp":29.0,"tv":25.64,"id":5720735}]}]}
{"op":"mcm","clk":"1004488135","pt":1580630955319,"mc":[{"id":"1.168135750","rc":[{"batl":[[2,14,1.19]],"ltp":9.8,"tv":181.71,"id":5720738}]}]}
{"op":"mcm","clk":"1004489342","pt":1580630981066,"mc":[{"id":"1.168135750","rc":[{"batb":[[0,6.4,2],[1,6.2,142.86],[2,6,60.78]],"ltp":7.8,"tv":1305.02,"id":5720732}]}]}
{"op":"mcm","clk":"1004489526","pt":1580630984573,"mc":[{"id":"1.168135750","rc":[{"batb":[[0,3.95,46.34]],"ltp":4.0,"tv":3553.35,"id":2764711}]}]}
{"op":"mcm","clk":"1004489683","pt":1580630987409,"mc":[{"id":"1.168135750","rc":[{"batl":[[2,14.5,1.19]],"ltp":9.8,"tv":181.71,"id":5720738}]}]}
{"op":"mcm","clk":"1004490363","pt":1580631000739,"mc":[{"id":"1.168135750","rc":[{"trd":[[110,1.83],[120,0.19],[160,3.98]],"batb":[[0,110,3.8],[1,100,9.97],[2,50,2]],"ltp":110.0,"tv":9.61,"id":5720737}],"tv":5753.1}]}
{"op":"mcm","clk":"1004490546","pt":1580631004408,"mc":[{"id":"1.168135750","rc":[{"trd":[[4.1,20.7]],"batl":[[0,4.1,70.69]],"ltp":4.1,"tv":3571.86,"id":2764711}],"tv":5771.61}]}
{"op":"mcm","clk":"1004490822","pt":1580631009733,"mc":[{"id":"1.168135750","rc":[{"batb":[[0,110,4.34]],"ltp":110.0,"tv":9.61,"id":5720737}]}]}
{"op":"mcm","clk":"1004490987","pt":1580631012470,"mc":[{"id":"1.168135750","rc":[{"batl":[[1,95,2.53],[2,1000,2.53]],"ltp":28.0,"tv":16.88,"id":5720736}]}]}
{"op":"mcm","clk":"1004491224","pt":1580631017768,"mc":[{"id":"1.168135750","rc":[{"batl":[[1,95,3.04]],"ltp":28.0,"tv":16.88,"id":5720736}]}]}
{"op":"mcm","clk":"1004491607","pt":1580631025771,"mc":[{"id":"1.168135750","rc":[{"trd":[[17,10.14]],"batb":[[0,15,4.68],[1,11,3.82],[2,10.5,47.62]],"ltp":17.0,"tv":202.71,"id":2764710},{"batl":[[0,40,4.56],[1,1000,2.53],[2,1000,0]],"ltp":28.0,"tv":16.88,"id":5720736}],"tv":5781.75}]}
{"op":"mcm","clk":"1004492495","pt":1580631044202,"mc":[{"id":"1.168135750","rc":[{"batb":[[0,6.4,10.05]],"ltp":7.8,"tv":1305.02,"id":5720732}]}]}
{"op":"mcm","clk":"1004492608","pt":1580631046724,"mc":[{"id":"1.168135750","rc":[{"trd":[[16,35.84]],"batl":[[0,16,2.32]],"ltp":16.0,"tv":91.35,"id":2764715}],"tv":5789.26}]}
{"op":"mcm","clk":"1004492858","pt":1580631052336,"mc":[{"id":"1.168135750","rc":[{"batb":[[0,6.4,25.79]],"ltp":7.8,"tv":1305.02,"id":5720732}]}]}
{"op":"mcm","clk":"1004492980","pt":1580631054612,"mc":[{"id":"1.168135750","rc":[{"batl":[[1,1000,2.53]],"ltp":16.0,"tv":91.35,"id":2764715},{"batl":[[2,24,7.06]],"ltp":9.8,"tv":181.71,"id":5720738}]}]}
{"op":"mcm","clk":"1004493334","pt":1580631061722,"mc":[{"id":"1.168135750","rc":[{"batb":[[1,3.8,44.57],[2,3.5,321.71]],"ltp":4.1,"tv":3571.86,"id":2764711}]}]}
{"op":"mcm","clk":"1004493678","pt":1580631068720,"mc":[{"id":"1.168135750","rc":[{"trd":[[22,7.11],[42,4.04]],"batb":[[0,22,21.08],[1,21,47.62],[2,1.5,2.53]],"ltp":22.0,"tv":82.22,"id":5720734}],"tv":5799.4}]}
{"op":"mcm","clk":"1004494271","pt":1580631080442,"mc":[{"id":"1.168135750","rc":[{"trd":[[29,16.22],[30,1.43]],"batb":[[0,24,20.83],[1,23,15.96],[2,13,3.23]],"batl":[[0,29,1.14],[1,80,3.29],[2,1000,2.53]],"ltp":29.0,"tv":33.49,"id":5720735}],"tv":5807.24}]}
{"op":"mcm","clk":"1004494817","pt":1580631091164,"mc":[{"id":"1.168135750","rc":[{"batb":[[1,10.5,47.62],[2,10,114.18]],"ltp":17.0,"tv":202.71,"id":2764710},{"batb":[[1,7.8,14]],"ltp":8.0,"tv":81.22,"id":2764720},{"batb":[[2,13,7.5]],"ltp":16.0,"tv":91.35,"id":2764715},{"batb":[[2,8,12.5]],"ltp":9.8,"tv":181.71,"id":5720738},{"batb":[[2,12,83.33]],"ltp":29.0,"tv":33.49,"id":5720735},{"batb":[[2,5.6,13.66]],"ltp":6.2,"tv":201.59,"id":2764722}]}]}
{"op":"mcm","clk":"1004495191","pt":1580631098773,"mc":[{"id":"1.168135750","rc":[{"batl":[[1,4.6,477.81],[2,4.7,493.34]],"ltp":4.1,"tv":3571.86,"id":2764711},{"batl":[[1,21,2.53],[2,1000,2.53]],"ltp":16.0,"tv":91.35,"id":2764715},{"batl":[[0,34,2.53],[1,40,4.56],[2,1000,2.53]],"ltp":28.0,"tv":16.88,"id":5720736}]}]}
{"op":"mcm","clk":"1004495672","pt":1580631110793,"mc":[{"id":"1.168135750","rc":[{"batl":[[2,1000,0]],"ltp":17.0,"tv":202.71,"id":2764710},{"batb":[[0,8,12.86]],"batl":[[1,14.5,7.6]],"ltp":8.0,"tv":81.22,"id":2764720},{"batl":[[1,29,10.13]],"ltp":23.0,"tv":20.37,"id":2764714},{"batl":[[2,24,6.08]],"ltp":9.8,"tv":181.71,"id":5720738},{"batb":[[0,65,1.41]],"ltp":1000.0,"tv":4.57,"id":2764717},{"batl":[[2,1000,0]],"ltp":29.0,"tv":33.49,"id":5720735},{"batb":[[2,1.01,1.01]],"batl":[[0,48,12.66],[2,1000,0]],"ltp":22.0,"tv":82.22,"id":5720734},{"trd":[[29,6.42],[30,3.29]],"batb":[[0,27,18.52],[1,26,1.57],[2,25,14.13]],"batl":[[0,34,2.75],[2,1000,0]],"ltp":29.0,"tv":26.59,"id":5720736}],"tv":5816.95}]}
{"op":"mcm","clk":"1004495817","pt":1580631113717,"mc":[{"id":"1.168135750","rc":[{"batb":[[1,11,3.82],[2,10.5,47.62]],"ltp":17.0,"tv":202.71,"id":2764710},{"batb":[[2,7.6,5.53]],"ltp":8.0,"tv":81.22,"id":2764720},{"batb":[[2,15,2.8]],"ltp":23.0,"tv":20.37,"id":2764714},{"batb":[[0,15,2.8],[1,14.5,33.06],[2,14,10.41]],"ltp":16.0,"tv":91.35,"id":2764715},{"batb":[[0,8.8,4.77],[1,8.6,67.71],[2,8.4,25.11]],"ltp":9.8,"tv":181.71,"id":5720738},{"batb":[[0,25,1.68],[1,24,20.83],[2,23,15.96]],"ltp":29.0,"tv":33.49,"id":5720735},{"batb":[[0,6.2,18.62]],"ltp":6.2,"tv":201.59,"id":2764722}]}]}
{"op":"mcm","clk":"1004495991","pt":1580631117626,"mc":[{"id":"1.168135750","rc":[{"batb":[[1,8.6,58.14]],"ltp":9.8,"tv":181.71,"id":5720738}]}]}
{"op":"mcm","clk":"1004496164","pt":1580631122400,"mc":[{"id":"1.168135750","rc":[{"batl":[[2,55,2.53]],"ltp":16.0,"tv":91.35,"id":2764715}]}]}
{"op":"mcm","clk":"1004496310","pt":1580631126610,"mc":[{"id":"1.168135750","rc":[{"batl":[[2,55,3.04]],"ltp":16.0,"tv":91.35,"id":2764715}]}]}
{"op":"mcm","clk":"1004496557","pt":1580631133223,"mc":[{"id":"1.168135750","rc":[{"batb":[[0,9,9.15],[1,8.8,4.77],[2,8.6,58.14]],"ltp":9.8,"tv":181.71,"id":5720738}]}]}
{"op":"mcm","clk":"1004496793","pt":1580631139613,"mc":[{"id":"1.168135750","rc":[{"batl":[[1,21,3.04],[2,1000,2.53]],"ltp":16.0,"tv":91.35,"id":2764715}]}]}
{"op":"mcm","clk":"1004496971","pt":1580631143741,"mc":[{"id":"1.168135750","rc":[{"batl":[[1,14.5,9]],"ltp":8.0,"tv":81.22,"id":2764720},{"batl":[[2,24,7.06]],"ltp":9.8,"tv":181.71,"id":5720738}]}]}
{"op":"mcm","clk":"1004497017","pt":1580631144767,"mc":[{"id":"1.168135750","rc":[{"batb":[[0,8,28.6]],"ltp":8.0,"tv":81.22,"id":2764720}]}]}
{"op":"mcm","clk":"1004497427","pt":1580631152733,"mc":[{"id":"1.168135750","rc":[{"batl":[[1,4.5,9.34],[2,4.6,477.81]],"ltp":4.1,"tv":3571.86,"id":2764711},{"batl":[[0,46,1.68],[1,48,12.66],[2,50,53]],"ltp":22.0,"tv":82.22,"id":5720734},{"batl":[[0,7.6,5.55],[1,7.8,68.97],[2,8,86.24]],"ltp":7.8,"tv":1305.02,"id":5720732}]}]}
{"op":"mcm","clk":"1004497534","pt":1580631155668,"mc":[{"id":"1.168135750","rc":[{"batl":[[1,4.5,25.08]],"ltp":4.1,"tv":3571.86,"id":2764711}]}]}
{"op":"mcm","clk":"1004498409","pt":1580631176580,"mc":[{"id":"1.168135750","rc":[{"batl":[[0,7.6,21.28]],"ltp":7.8,"tv":1305.02,"id":5720732}]}]}
{"op":"mcm","clk":"1004498817","pt":1580631185683,"mc":[{"id":"1.168135750","rc":[{"batl":[[1,14.5,7.6]],"ltp":8.0,"tv":81.22,"id":2764720},{"batl":[[2,24,6.08]],"ltp":9.8,"tv":181.71,"id":5720738}]}]}
{"op":"mcm","clk":"1004499819","pt":1580631206343,"mc":[{"id":"1.168135750","rc":[{"trd":[[7.6,1.38]],"batl":[[0,7.6,20.59]],"ltp":7.6,"tv":1306.4,"id":5720732}],"tv":5818.33}]}
{"op":"mcm","clk":"1004500039","pt":1580631211629,"mc":[{"id":"1.168135750","rc":[{"batl":[[1,14.5,9]],"ltp":8.0,"tv":81.22,"id":2764720},{"batl":[[2,24,7.06]],"ltp":9.8,"tv":181.71,"id":5720738}]}]}
{"op":"mcm","clk":"1004500372","pt":1580631218748,"mc":[{"id":"1.168135750","rc":[{"batl":[[1,14,1.4],[2,14.5,7.6]],"ltp":8.0,"tv":81.22,"id":2764720}]}]}
{"op":"mcm","clk":"1004500625","pt":1580631224730,"mc":[{"id":"1.168135750","rc":[{"batb":[[0,6.6,2.53],[1,6.4,25.79],[2,6.2,142.86]],"ltp":7.6,"tv":1306.4,"id":5720732}]}]}
{"op":"mcm","clk":"1004500754","pt":1580631227765,"mc":[{"id":"1.168135750","rc":[{"batb":[[0,3.95,130]],"ltp":4.1,"tv":3571.86,"id":2764711}]}]}
{"op":"mcm","clk":"1004501027","pt":1580631235484,"mc":[{"id":"1.168135750","rc":[{"batb":[[0,6.6,10.59],[1,6.4,17.74]],"ltp":7.6,"tv":1306.4,"id":5720732}]}]}
{"op":"mcm","clk":"1004501322","pt":1580631241566,"mc":[{"id":"1.168135750","rc":[{"batl":[[0,11,15.74],[1,11.5,8.27],[2,14,1.4]],"ltp":8.0,"tv":81.22,"id":2764720}]}]}
{"op":"mcm","clk":"1004501555","pt":1580631248800,"mc":[{"id":"1.168135750","rc":[{"trd":[[4.1,27.5]],"batl":[[0,4.1,67.29]],"ltp":4.1,"tv":3578.66,"id":2764711}],"tv":5825.13}]}
{"op":"mcm","clk":"1004501772","pt":1580631253208,"mc":[{"id":"1.168135750","rc":[{"batl":[[0,34,3.25],[1,40,4.05]],"ltp":29.0,"tv":26.59,"id":5720736}]}]}
{"op":"mcm","clk":"1004502077","pt":1580631261721,"mc":[{"id":"1.168135750","rc":[{"batl":[[2,24,6.08]],"ltp":9.8,"tv":181.71,"id":5720738}]}]}
{"op":"mcm","clk":"1004502131","pt":1580631262804,"mc":[{"id":"1.168135750","rc":[{"batl":[[2,24,7.06]],"ltp":9.8,"tv":181.71,"id":5720738}]}]}
{"op":"mcm","clk":"1004502213","pt":1580631264607,"mc":[{"id":"1.168135750","rc":[{"trd":[[4.1,34.49]],"batl":[[0,4.1,63.8]],"ltp":4.1,"tv":3585.65,"id":2764711}],"tv":5832.12}]}
{"op":"mcm","clk":"1004502422","pt":1580631269726,"mc":[{"id":"1.168135750","rc":[{"batl":[[2,14.5,7.6]],"ltp":8.0,"tv":81.22,"id":2764720}]}]}
{"op":"mcm","clk":"1004502452","pt":1580631270396,"mc":[{"id":"1.168135750","rc":[{"batl":[[0,11,17.14]],"ltp":8.0,"tv":81.22,"id":2764720}]}]}
{"op":"mcm","clk":"1004502988","pt":1580631284349,"mc":[{"id":"1.168135750","rc":[{"trd":[[4.1,42.39]],"batl":[[0,4.1,59.85]],"ltp":4.1,"tv":3593.55,"id":2764711}],"tv":5840.02}]}
{"op":"mcm","clk":"1004503114","pt":1580631287746,"mc":[{"id":"1.168135750","rc":[{"batl":[[0,11,15.74]],"ltp":8.0,"tv":81.22,"id":2764720}]}]}
{"op":"mcm","clk":"1004503155","pt":1580631288621,"mc":[{"id":"1.168135750","rc":[{"batl":[[2,13.5,1.4]],"ltp":8.0,"tv":81.22,"id":2764720}]}]}
{"op":"mcm","clk":"1004503349","pt":1580631293470,"mc":[{"id":"1.168135750","rc":[{"trd":[[7.6,18.87]],"batl":[[0,7.6,11.85]],"ltp":7.6,"tv":1323.9,"id":5720732}],"tv":5857.51}]}
{"op":"mcm","clk":"1004503389","pt":1580631294345,"mc":[{"id":"1.168135750","rc":[{"batb":[[0,7,4.22],[1,6.6,10.59],[2,6.4,17.74]],"ltp":7.6,"tv":1323.9,"id":5720732}]}]}
{"op":"mcm","clk":"1004503445","pt":1580631295737,"mc":[{"id":"1.168135750","rc":[{"batb":[[1,6.8,45.59],[2,6.6,10.59]],"ltp":7.6,"tv":1323.9,"id":5720732}]}]}
{"op":"mcm","clk":"1004503658","pt":1580631301741,"mc":[{"id":"1.168135750","rc":[{"batl":[[0,11,17.14],[2,14.5,7.6]],"ltp":8.0,"tv":81.22,"id":2764720}]}]}
{"op":"mcm","clk":"1004503707","pt":1580631303447,"mc":[{"id":"1.168135750","rc":[{"batb":[[2,5.6,29.4]],"ltp":6.2,"tv":201.59,"id":2764722}]}]}
{"op":"mcm","clk":"1004503817","pt":1580631306248,"mc":[{"id":"1.168135750","rc":[{"batb":[[2,5.6,45.13]],"ltp":6.2,"tv":201.59,"id":2764722}]}]}
{"op":"mcm","clk":"1004504024","pt":1580631311756,"mc":[{"id":"1.168135750","rc":[{"batb":[[1,6.8,40.52]],"ltp":7.6,"tv":1323.9,"id":5720732}]}]}
{"op":"mcm","clk":"1004504147","pt":1580631314380,"mc":[{"id":"1.168135750","rc":[{"batl":[[0,11,17.59]],"ltp":8.0,"tv":81.22,"id":2764720}]}]}
{"op":"mcm","clk":"1004504329","pt":1580631319468,"mc":[{"id":"1.168135750","rc":[{"batb":[[0,7.2,40.52],[1,7,4.22]],"ltp":7.6,"tv":1323.9,"id":5720732}]}]}
{"op":"mcm","clk":"1004504828","pt":1580631330363,"mc":[{"id":"1.168135750","rc":[{"batl":[[0,610,0.51]],"ltp":110.0,"tv":9.61,"id":5720737}]}]}
{"op":"mcm","clk":"1004504874","pt":1580631331755,"mc":[{"id":"1.168135750","rc":[{"batb":[[2,1.01,1.01]],"ltp":110.0,"tv":9.61,"id":5720737},{"batb":[[2,25,10.13]],"ltp":29.0,"tv":26.59,"id":5720736}]}]}
{"op":"mcm","clk":"1004505228","pt":1580631340050,"mc":[{"id":"1.168135750","rc":[{"batl":[[0,10.5,1.85],[1,11,15.74],[2,11.5,8.27]],"ltp":8.0,"tv":81.22,"id":2764720}]}]}
{"op":"mcm","clk":"1004505499","pt":1580631346862,"mc":[{"id":"1.168135750","rc":[{"batb":[[2,6.6,2.53]],"ltp":7.6,"tv":1323.9,"id":5720732}]}]}
{"op":"mcm","clk":"1004505649","pt":1580631350356,"mc":[{"id":"1.168135750","rc":[{"batl":[[0,10.5,1.93]],"ltp":8.0,"tv":81.22,"id":2764720},{"batl":[[2,16.5,1.04]],"ltp":9.8,"tv":181.71,"id":5720738}]}]}
{"op":"mcm","clk":"1004508402","pt":1580631411683,"mc":[{"id":"1.168135750","rc":[{"batb":[[2,6.6,8.9]],"ltp":7.6,"tv":1323.9,"id":5720732}]}]}
{"op":"mcm","clk":"1004508796","pt":1580631420695,"mc":[{"id":"1.168135750","rc":[{"batb":[[1,3.7,44.57]],"ltp":4.1,"tv":3593.55,"id":2764711}]}]}
{"op":"mcm","clk":"1004509121","pt":1580631427805,"mc":[{"id":"1.168135750","rc":[{"batb":[[0,7,44.74],[1,6.6,8.9],[2,6.4,17.74]],"ltp":7.6,"tv":1323.9,"id":5720732}]}]}
{"op":"mcm","clk":"1004509721","pt":1580631442635,"mc":[{"id":"1.168135750","rc":[{"batb":[[0,7,75.13]],"ltp":7.6,"tv":1323.9,"id":5720732}]}]}
{"op":"mcm","clk":"1004509924","pt":1580631447811,"mc":[{"id":"1.168135750","rc":[{"batb":[[0,7.2,4.22],[1,7,70.91],[2,6.6,8.9]],"ltp":7.6,"tv":1323.9,"id":5720732}]}]}
{"op":"mcm","clk":"1004509953","pt":1580631448633,"mc":[{"id":"1.168135750","rc":[{"batl":[[0,990,5.07],[1,1000,2.49]],"ltp":1000.0,"tv":4.57,"id":2764717}]}]}
{"op":"mcm","clk":"1004510040","pt":1580631450537,"mc":[{"id":"1.168135750","rc":[{"trd":[[7.6,26.31]],"batb":[[1,7,74.95]],"batl":[[0,7.6,8.13]],"ltp":7.6,"tv":1331.34,"id":5720732}],"tv":5864.95}]}
{"op":"mcm","clk":"1004510172","pt":1580631453735,"mc":[{"id":"1.168135750","rc":[{"trd":[[7.6,42.56],[7.8,139.84]],"batb":[[1,7,83.77]],"batl":[[0,7.8,1.04],[1,8,86.24],[2,8.2,66.39]],"ltp":7.8,"tv":1483.37,"id":5720732}],"tv":6016.99}]}
{"op":"mcm","clk":"1004510211","pt":1580631454559,"mc":[{"id":"1.168135750","rc":[{"batb":[[0,7.2,9.59]],"ltp":7.8,"tv":1483.37,"id":5720732}]}]}
{"op":"mcm","clk":"1004510250","pt":1580631455643,"mc":[{"id":"1.168135750","rc":[{"batb":[[1,7,114.16]],"ltp":7.8,"tv":1483.37,"id":5720732}]}]}
{"op":"mcm","clk":"1004510282","pt":1580631456418,"mc":[{"id":"1.168135750","rc":[{"batl":[[2,17,1.04]],"ltp":9.8,"tv":181.71,"id":5720738},{"batb":[[0,7.2,22.45],[1,7,101.3]],"ltp":7.8,"tv":1483.37,"id":5720732}]}]}
{"op":"mcm","clk":"1004510536","pt":1580631462765,"mc":[{"id":"1.168135750","rc":[{"batb":[[0,7.2,62.97],[1,7,60.78]],"ltp":7.8,"tv":1483.37,"id":5720732}]}]}
{"op":"mcm","clk":"1004511848","pt":1580631494867,"mc":[{"id":"1.168135750","rc":[{"trd":[[18.5,6.74]],"batb":[[0,18.5,5.13]],"ltp":18.5,"tv":27.11,"id":2764714}],"tv":6023.73}]}
{"op":"mcm","clk":"1004512202","pt":1580631504385,"mc":[{"id":"1.168135750","rc":[{"batl":[[0,20,5.62],[1,23,5.87],[2,29,10.13]],"ltp":18.5,"tv":27.11,"id":2764714}]}]}
{"op":"mcm","clk":"1004512274","pt":1580631506180,"mc":[{"id":"1.168135750","rc":[{"batb":[[2,6.8,15.74]],"ltp":7.8,"tv":1483.37,"id":5720732}]}]}
{"op":"mcm","clk":"1004512314","pt":1580631507310,"mc":[{"id":"1.168135750","rc":[{"batl":[[2,16.5,1.04]],"ltp":9.8,"tv":181.71,"id":5720738}]}]}
{"op":"mcm","clk":"1004512815","pt":1580631519794,"mc":[{"id":"1.168135750","rc":[{"batb":[[0,8.8,2.12],[1,8,28.6],[2,7.8,14]],"ltp":8.0,"tv":81.22,"id":2764720}]}]}
{"op":"mcm","clk":"1004513262","pt":1580631529819,"mc":[{"id":"1.168135750","rc":[{"batl":[[0,7.8,84.04]],"ltp":7.8,"tv":1483.37,"id":5720732}]}]}
{"op":"mcm","clk":"1004514313","pt":1580631552946,"mc":[{"id":"1.168135750","rc":[{"batb":[[0,7.4,30.39],[1,7.2,62.97],[2,7,60.78]],"ltp":7.8,"tv":1483.37,"id":5720732}]}]}
{"op":"mcm","clk":"1004514617","pt":1580631559671,"mc":[{"id":"1.168135750","rc":[{"batb":[[1,7.2,57.61]],"ltp":7.8,"tv":1483.37,"id":5720732}]}]}
{"op":"mcm","clk":"1004516418","pt":1580631598820,"mc":[{"id":"1.168135750","rc":[{"batb":[[0,9,2],[1,8.8,2.12],[2,8,28.6]],"ltp":8.0,"tv":81.22,"id":2764720}]}]}
{"op":"mcm","clk":"1004516864","pt":1580631608352,"mc":[{"id":"1.168135750","rc":[{"batl":[[0,9.8,7.66]],"ltp":9.8,"tv":181.71,"id":5720738}]}]}
{"op":"mcm","clk":"1004517333","pt":1580631617736,"mc":[{"id":"1.168135750","rc":[{"batb":[[0,9.2,2.12],[1,9,2]],"ltp":8.0,"tv":81.22,"id":2764720}]}]}
{"op":"mcm","clk":"1004519220","pt":1580631657609,"mc":[{"id":"1.168135750","rc":[{"batb":[[1,7.2,17.08]],"ltp":7.8,"tv":1483.37,"id":5720732}]}]}
{"op":"mcm","clk":"1004520260","pt":1580631678814,"mc":[{"id":"1.168135750","rc":[{"trd":[[15,6.8]],"batb":[[0,14.5,33.72],[1,14,10.41],[2,13,7.5]],"ltp":15.0,"tv":95.61,"id":2764715}],"tv":6027.99}]}
{"op":"mcm","clk":"1004521260","pt":1580631701619,"mc":[{"id":"1.168135750","rc":[{"batb":[[0,4,5.07],[1,3.95,130],[2,3.7,44.57]],"ltp":4.1,"tv":3593.55,"id":2764711}]}]}
{"op":"mcm","clk":"1004522237","pt":1580631723289,"mc":[{"id":"1.168135750","rc":[{"trd":[[9,27.05]],"batb":[[0,9,4.15]],"ltp":9.0,"tv":191.71,"id":5720738}],"tv":6037.99}]}
{"op":"mcm","clk":"1004523452","pt":1580631752808,"mc":[{"id":"1.168135750","rc":[{"trd":[[6.2,19.14]],"batb":[[0,6.2,13.55]],"ltp":6.2,"tv":211.73,"id":2764722}],"tv":6048.12}]}
{"op":"mcm","clk":"1004523550","pt":1580631755809,"mc":[{"id":"1.168135750","rc":[{"trd":[[6.2,34.34]],"batb":[[0,6.2,5.95]],"ltp":6.2,"tv":226.93,"id":2764722}],"tv":6063.33}]}
{"op":"mcm","clk":"1004523761","pt":1580631760802,"mc":[{"id":"1.168135750","rc":[{"batb":[[0,23,3.87],[1,22,21.08],[2,21,47.62]],"ltp":22.0,"tv":82.22,"id":5720734}]}]}
{"op":"mcm","clk":"1004523786","pt":1580631761317,"mc":[{"id":"1.168135750","rc":[{"batb":[[0,15.5,6.42],[1,15,4.01],[2,11,3.82]],"ltp":17.0,"tv":202.71,"id":2764710},{"batb":[[0,4,27.33]],"ltp":4.1,"tv":3593.55,"id":2764711},{"batb":[[0,9.4,9.47],[1,9.2,2.12],[2,9,2]],"ltp":8.0,"tv":81.22,"id":2764720},{"batb":[[0,15,6.6],[1,14.5,33.06],[2,14,10.41]],"ltp":15.0,"tv":95.61,"id":2764715},{"batb":[[0,26,3.43],[1,25,1.68],[2,24,20.83]],"ltp":29.0,"tv":33.49,"id":5720735},{"batb":[[0,28,3.18],[1,27,18.52],[2,26,1.57]],"ltp":29.0,"tv":26.59,"id":5720736},{"batb":[[1,7.2,29.46]],"ltp":7.8,"tv":1483.37,"id":5720732}]}]}
{"op":"mcm","clk":"1004523847","pt":1580631762599,"mc":[{"id":"1.168135750","rc":[{"batl":[[2,16,1.04]],"ltp":9.0,"tv":191.71,"id":5720738}]}]}
