{"op":"mcm","clk":"988026418","pt":1580473742115,"mc":[{"id":"1.168135792","marketDefinition":{"bspMarket":false,"turnInPlayEnabled":true,"persistenceEnabled":true,"marketBaseRate":5.0,"eventId":"29678823","eventTypeId":"2","numberOfWinners":1,"bettingType":"ODDS","marketType":"SET_WINNER","marketTime":"2020-02-02T08:30:00.000Z","suspendTime":"2020-02-02T08:30:00.000Z","bspReconciled":false,"complete":true,"inPlay":false,"crossMatching":false,"runnersVoidable":false,"numberOfActiveRunners":2,"betDelay":0,"status":"OPEN","runners":[{"status":"ACTIVE","sortPriority":1,"id":5720747,"name":"Dominic Thiem"},{"status":"ACTIVE","sortPriority":2,"id":2249229,"name":"Novak Djokovic"}],"regulators":["MR_INT"],"countryCode":"AU","discountAllowed":false,"timezone":"GMT","openDate":"2020-02-02T08:30:00.000Z","version":3143005239,"name":"Set 2 Winner","eventName":"Thiem v Djokovic"},"rc":[{"batb":[[0,1.01,20]],"ltp":0.0,"tv":0.0,"id":2249229},{"batb":[[0,1.01,20]],"ltp":0.0,"tv":0.0,"id":5720747}]}]}
{"op":"mcm","clk":"988026715","pt":1580473744836,"mc":[{"id":"1.168135792","marketDefinition":{"bspMarket":false,"turnInPlayEnabled":true,"persistenceEnabled":true,"marketBaseRate":5.0,"eventId":"29678823","eventTypeId":"2","numberOfWinners":1,"bettingType":"ODDS","marketType":"SET_WINNER","marketTime":"2020-02-02T08:30:00.000Z","suspendTime":"2020-02-02T08:30:00.000Z","bspReconciled":false,"complete":true,"inPlay":false,"crossMatching":false,"runnersVoidable":false,"numberOfActiveRunners":2,"betDelay":0,"status":"OPEN","runners":[{"status":"ACTIVE","sortPriority":1,"id":5720747,"name":"Dominic Thiem"},{"status":"ACTIVE","sortPriority":2,"id":2249229,"name":"Novak Djokovic"}],"regulators":["MR_INT"],"countryCode":"AU","discountAllowed":true,"timezone":"GMT","openDate":"2020-02-02T08:30:00.000Z","version":3143005239,"name":"Set 2 Winner","eventName":"Thiem v Djokovic"}}]}
{"op":"mcm","clk":"988033919","pt":1580473818253,"mc":[{"id":"1.168135792","rc":[{"batb":[[0,1.01,10]],"ltp":0.0,"tv":0.0,"id":2249229},{"batb":[[0,1.01,10]],"ltp":0.0,"tv":0.0,"id":5720747}]}]}
{"op":"mcm","clk":"988149156","pt":1580474823727,"mc":[{"id":"1.168135792","rc":[{"batb":[[0,1.36,68.87],[1,1.01,10]],"ltp":0.0,"tv":0.0,"id":2249229},{"batb":[[0,2.88,13.18],[1,1.01,10]],"ltp":0.0,"tv":0.0,"id":5720747}]}]}
{"op":"mcm","clk":"988152651","pt":1580474858790,"mc":[{"id":"1.168135792","marketDefinition":{"bspMarket":false,"turnInPlayEnabled":true,"persistenceEnabled":true,"marketBaseRate":5.0,"eventId":"29678823","eventTypeId":"2","numberOfWinners":1,"bettingType":"ODDS","marketType":"SET_WINNER","marketTime":"2020-02-02T08:30:00.000Z","suspendTime":"2020-02-02T08:30:00.000Z","bspReconciled":false,"complete":true,"inPlay":false,"crossMatching":true,"runnersVoidable":false,"numberOfActiveRunners":2,"betDelay":0,"status":"OPEN","runners":[{"status":"ACTIVE","sortPriority":1,"id":5720747,"name":"Dominic Thiem"},{"status":"ACTIVE","sortPriority":2,"id":2249229,"name":"Novak Djokovic"}],"regulators":["MR_INT"],"countryCode":"AU","discountAllowed":true,"timezone":"GMT","openDate":"2020-02-02T08:30:00.000Z","version":3143005239,"name":"Set 2 Winner","eventName":"Thiem v Djokovic"}}]}
{"op":"mcm","clk":"988158687","pt":1580474922991,"mc":[{"id":"1.168135792","rc":[{"batb":[[0,1.01,10],[1,1.01,0]],"ltp":0.0,"tv":0.0,"id":2249229},{"batb":[[0,1.01,10],[1,1.01,0]],"ltp":0.0,"tv":0.0,"id":5720747}]}]}
{"op":"mcm","clk":"988227517","pt":1580475589553,"mc":[{"id":"1.168135792","rc":[{"batb":[[0,1.36,68.87],[1,1.01,10]],"ltp":0.0,"tv":0.0,"id":2249229},{"batb":[[0,2.88,13.18],[1,1.01,10]],"ltp":0.0,"tv":0.0,"id":5720747}]}]}
{"op":"mcm","clk":"989799646","pt":1580491424608,"mc":[{"id":"1.168135792","rc":[{"batb":[[1,1.01,10.2]],"ltp":0.0,"tv":0.0,"id":2249229},{"batb":[[1,1.01,10.2]],"ltp":0.0,"tv":0.0,"id":5720747}]}]}
{"op":"mcm","clk":"990045221","pt":1580493584582,"mc":[{"id":"1.168135792","rc":[{"batb":[[0,1.36,75.49]],"ltp":0.0,"tv":0.0,"id":2249229},{"batb":[[0,2.88,14.45]],"ltp":0.0,"tv":0.0,"id":5720747}]}]}
{"op":"mcm","clk":"991991594","pt":1580511707738,"mc":[{"id":"1.168135792","rc":[{"batb":[[1,1.01,12.73]],"ltp":0.0,"tv":0.0,"id":2249229},{"batb":[[1,1.01,12.73]],"ltp":0.0,"tv":0.0,"id":5720747}]}]}
{"op":"mcm","clk":"991991655","pt":1580511708815,"mc":[{"id":"1.168135792","rc":[{"batb":[[1,1.01,10.71]],"ltp":0.0,"tv":0.0,"id":2249229},{"batb":[[1,1.01,10.71]],"ltp":0.0,"tv":0.0,"id":5720747}]}]}
{"op":"mcm","clk":"992004218","pt":1580511983757,"mc":[{"id":"1.168135792","rc":[{"batb":[[1,1.01,13.24]],"ltp":0.0,"tv":0.0,"id":2249229},{"batb":[[1,1.01,13.24]],"ltp":0.0,"tv":0.0,"id":5720747}]}]}
{"op":"mcm","clk":"992004256","pt":1580511984580,"mc":[{"id":"1.168135792","rc":[{"batb":[[1,1.01,11.21]],"ltp":0.0,"tv":0.0,"id":2249229},{"batb":[[1,1.01,11.21]],"ltp":0.0,"tv":0.0,"id":5720747}]}]}
{"op":"mcm","clk":"992859043","pt":1580531894609,"mc":[{"id":"1.168135792","rc":[{"batb":[[1,1.02,2780.76],[2,1.01,2791.57]],"ltp":0.0,"tv":0.0,"id":2249229},{"batb":[[1,1.02,2780.76],[2,1.01,2791.57]],"ltp":0.0,"tv":0.0,"id":5720747}]}]}
{"op":"mcm","clk":"993079520","pt":1580536204154,"mc":[{"id":"1.168135792","rc":[{"batb":[[0,1.39,670],[1,1.36,75.49],[2,1.02,2780.76]],"ltp":0.0,"tv":0.0,"id":2249229}]}]}
{"op":"mcm","clk":"993211132","pt":1580538607503,"mc":[{"id":"1.168135792","rc":[{"batb":[[0,1.4,7.28],[1,1.39,670],[2,1.36,75.49]],"ltp":0.0,"tv":0.0,"id":2249229}]}]}
{"op":"mcm","clk":"996559663","pt":1580562694813,"mc":[{"id":"1.168135792","rc":[{"batb":[[0,2.92,192.94],[1,2.88,14.45],[2,1.02,2780.76]],"ltp":0.0,"tv":0.0,"id":5720747}]}]}
{"op":"mcm","clk":"996646506","pt":1580563116451,"mc":[{"id":"1.168135792","rc":[{"batb":[[0,2.88,14.45],[1,1.02,2780.76],[2,1.01,2791.57]],"ltp":0.0,"tv":0.0,"id":5720747}]}]}
{"op":"mcm","clk":"996646728","pt":1580563117491,"mc":[{"id":"1.168135792","rc":[{"batb":[[0,2.94,148.42],[1,2.88,14.45],[2,1.02,2780.76]],"ltp":0.0,"tv":0.0,"id":5720747}]}]}
{"op":"mcm","clk":"996864934","pt":1580564132792,"mc":[{"id":"1.168135792","rc":[{"batb":[[0,2.9,194.16]],"ltp":0.0,"tv":0.0,"id":5720747}]}]}
{"op":"mcm","clk":"997003655","pt":1580564742589,"mc":[{"id":"1.168135792","rc":[{"batb":[[0,2.88,14.45],[1,1.02,2780.76],[2,1.01,2791.57]],"ltp":0.0,"tv":0.0,"id":5720747}]}]}
{"op":"mcm","clk":"997004012","pt":1580564744060,"mc":[{"id":"1.168135792","rc":[{"batb":[[0,2.96,190.38],[1,2.88,14.45],[2,1.02,2780.76]],"ltp":0.0,"tv":0.0,"id":5720747}]}]}
{"op":"mcm","clk":"997063274","pt":1580565080551,"mc":[{"id":"1.168135792","rc":[{"batb":[[0,2.88,14.45],[1,1.02,2780.76],[2,1.01,2791.57]],"ltp":0.0,"tv":0.0,"id":5720747}]}]}
{"op":"mcm","clk":"997063503","pt":1580565081827,"mc":[{"id":"1.168135792","rc":[{"batb":[[0,2.9,150.46],[1,2.88,14.45],[2,1.02,2780.76]],"ltp":0.0,"tv":0.0,"id":5720747}]}]}
{"op":"mcm","clk":"997081796","pt":1580565186578,"mc":[{"id":"1.168135792","rc":[{"batb":[[0,2.88,14.45],[1,1.02,2780.76],[2,1.01,2791.57]],"ltp":0.0,"tv":0.0,"id":5720747}]}]}
{"op":"mcm","clk":"997081928","pt":1580565187290,"mc":[{"id":"1.168135792","rc":[{"batb":[[0,2.94,191.59],[1,2.88,14.45],[2,1.02,2780.76]],"ltp":0.0,"tv":0.0,"id":5720747}]}]}
{"op":"mcm","clk":"997156099","pt":1580565642745,"mc":[{"id":"1.168135792","rc":[{"batb":[[0,2.88,14.45],[1,1.02,2780.76],[2,1.01,2791.57]],"ltp":0.0,"tv":0.0,"id":5720747}]}]}
{"op":"mcm","clk":"997156289","pt":1580565643872,"mc":[{"id":"1.168135792","rc":[{"batb":[[0,2.98,146.32],[1,2.88,14.45],[2,1.02,2780.76]],"ltp":0.0,"tv":0.0,"id":5720747}]}]}
{"op":"mcm","clk":"997490872","pt":1580567035670,"mc":[{"id":"1.168135792","rc":[{"batb":[[0,3,159.17],[1,1.02,2780.76],[2,1.01,2791.57]],"ltp":0.0,"tv":0.0,"id":5720747}]}]}
{"op":"mcm","clk":"997500935","pt":1580567075507,"mc":[{"id":"1.168135792","rc":[{"batb":[[0,3,145.59],[1,2.88,14.45],[2,1.02,2780.76]],"ltp":0.0,"tv":0.0,"id":5720747}]}]}
{"op":"mcm","clk":"997538316","pt":1580567225709,"mc":[{"id":"1.168135792","rc":[{"batb":[[0,2.9,194.16]],"ltp":0.0,"tv":0.0,"id":5720747}]}]}
{"op":"mcm","clk":"998353125","pt":1580570530263,"mc":[{"id":"1.168135792","rc":[{"batb":[[0,2.88,14.45],[1,1.02,2780.76],[2,1.01,2791.57]],"ltp":0.0,"tv":0.0,"id":5720747}]}]}
{"op":"mcm","clk":"1000246714","pt":1580579627729,"mc":[{"id":"1.168135792","rc":[{"batb":[[0,2.94,148.42],[1,2.88,14.45],[2,1.02,2780.76]],"ltp":0.0,"tv":0.0,"id":5720747}]}]}
{"op":"mcm","clk":"1000293159","pt":1580579986742,"mc":[{"id":"1.168135792","rc":[{"batb":[[2,1.36,82.01]],"ltp":0.0,"tv":0.0,"id":2249229},{"batb":[[1,2.88,15.7]],"ltp":0.0,"tv":0.0,"id":5720747}]}]}
{"op":"mcm","clk":"1000402496","pt":1580580722146,"mc":[{"id":"1.168135792","rc":[{"batb":[[0,2.88,15.7],[1,1.02,2780.76],[2,1.01,2791.57]],"ltp":0.0,"tv":0.0,"id":5720747}]}]}
{"op":"mcm","clk":"1000402632","pt":1580580723027,"mc":[{"id":"1.168135792","rc":[{"batb":[[0,2.94,191.59],[1,2.88,15.7],[2,1.02,2780.76]],"ltp":0.0,"tv":0.0,"id":5720747}]}]}
{"op":"mcm","clk":"1000448185","pt":1580581024743,"mc":[{"id":"1.168135792","rc":[{"batb":[[0,2.88,15.7],[1,1.02,2780.76],[2,1.01,2791.57]],"ltp":0.0,"tv":0.0,"id":5720747}]}]}
{"op":"mcm","clk":"1000963967","pt":1580584168789,"mc":[{"id":"1.168135792","rc":[{"batb":[[0,1.43,14],[1,1.4,7.28],[2,1.39,670]],"ltp":0.0,"tv":0.0,"id":2249229},{"batb":[[0,2.96,190.38],[1,2.88,15.7],[2,1.02,2780.76]],"ltp":0.0,"tv":0.0,"id":5720747}]}]}
{"op":"mcm","clk":"1001095936","pt":1580584857520,"mc":[{"id":"1.168135792","rc":[{"batb":[[0,2.88,15.7],[1,1.02,2780.76],[2,1.01,2791.57]],"ltp":0.0,"tv":0.0,"id":5720747}]}]}
{"op":"mcm","clk":"1001096046","pt":1580584858115,"mc":[{"id":"1.168135792","rc":[{"batb":[[0,2.92,149.44],[1,2.88,15.7],[2,1.02,2780.76]],"ltp":0.0,"tv":0.0,"id":5720747}]}]}
{"op":"mcm","clk":"1001097384","pt":1580584864844,"mc":[{"id":"1.168135792","rc":[{"batb":[[0,2.88,15.7],[1,1.02,2780.76],[2,1.01,2791.57]],"ltp":0.0,"tv":0.0,"id":5720747}]}]}
{"op":"mcm","clk":"1001097762","pt":1580584866743,"mc":[{"id":"1.168135792","rc":[{"batb":[[0,2.92,149.44],[1,2.88,15.7],[2,1.02,2780.76]],"ltp":0.0,"tv":0.0,"id":5720747}]}]}
{"op":"mcm","clk":"1001157905","pt":1580585175693,"mc":[{"id":"1.168135792","rc":[{"batb":[[0,2.88,15.7],[1,1.02,2780.76],[2,1.01,2791.57]],"ltp":0.0,"tv":0.0,"id":5720747}]}]}
{"op":"mcm","clk":"1001158367","pt":1580585177767,"mc":[{"id":"1.168135792","rc":[{"batb":[[0,2.92,171.44],[1,2.88,15.7],[2,1.02,2780.76]],"ltp":0.0,"tv":0.0,"id":5720747}]}]}
{"op":"mcm","clk":"1001536699","pt":1580587286071,"mc":[{"id":"1.168135792","rc":[{"batb":[[0,2.88,15.7],[1,1.02,2780.76],[2,1.01,2791.57]],"ltp":0.0,"tv":0.0,"id":5720747}]}]}
{"op":"mcm","clk":"1001536816","pt":1580587286865,"mc":[{"id":"1.168135792","rc":[{"batb":[[0,2.92,171.44],[1,2.88,15.7],[2,1.02,2780.76]],"ltp":0.0,"tv":0.0,"id":5720747}]}]}
{"op":"mcm","clk":"1001716785","pt":1580588196612,"mc":[{"id":"1.168135792","rc":[{"batb":[[0,2.88,15.7],[1,1.02,2780.76],[2,1.01,2791.57]],"ltp":0.0,"tv":0.0,"id":5720747}]}]}
{"op":"mcm","clk":"1002481808","pt":1580594251419,"mc":[{"id":"1.168135792","rc":[{"batb":[[0,3,186.9],[1,2.88,15.7],[2,1.02,2780.76]],"ltp":0.0,"tv":0.0,"id":5720747}]}]}
{"op":"mcm","clk":"1002545699","pt":1580595169082,"mc":[{"id":"1.168135792","rc":[{"batb":[[1,2.74,16.96]],"ltp":0.0,"tv":0.0,"id":5720747}]}]}
{"op":"mcm","clk":"1002550068","pt":1580595219268,"mc":[{"id":"1.168135792","rc":[{"batb":[[1,1.4,81.09]],"ltp":0.0,"tv":0.0,"id":2249229}]}]}
{"op":"mcm","clk":"1002554729","pt":1580595274447,"mc":[{"id":"1.168135792","rc":[{"batb":[[1,1.4,7.28]],"ltp":0.0,"tv":0.0,"id":2249229},{"batb":[[1,2.88,15.7]],"ltp":0.0,"tv":0.0,"id":5720747}]}]}
{"op":"mcm","clk":"1002602518","pt":1580595927226,"mc":[{"id":"1.168135792","rc":[{"batb":[[1,1.39,670],[2,1.36,82.01]],"ltp":0.0,"tv":0.0,"id":2249229}]}]}
{"op":"mcm","clk":"1002710514","pt":1580597640456,"mc":[{"id":"1.168135792","rc":[{"batb":[[0,3,41.31]],"ltp":0.0,"tv":0.0,"id":5720747}]}]}
{"op":"mcm","clk":"1002804835","pt":1580598992165,"mc":[{"id":"1.168135792","rc":[{"batb":[[0,3,186.9]],"ltp":0.0,"tv":0.0,"id":5720747}]}]}
{"op":"mcm","clk":"1002840196","pt":1580599486546,"mc":[{"id":"1.168135792","rc":[{"batb":[[0,3,41.31]],"ltp":0.0,"tv":0.0,"id":5720747}]}]}
{"op":"mcm","clk":"1003035160","pt":1580602214814,"mc":[{"id":"1.168135792","rc":[{"batb":[[0,1.44,756.17],[1,1.43,14],[2,1.39,670]],"ltp":0.0,"tv":0.0,"id":2249229}]}]}
{"op":"mcm","clk":"1003036214","pt":1580602226430,"mc":[{"id":"1.168135792","rc":[{"batb":[[0,1.43,14],[1,1.39,670],[2,1.36,74.45]],"ltp":0.0,"tv":0.0,"id":2249229}]}]}
{"op":"mcm","clk":"1003036574","pt":1580602230258,"mc":[{"id":"1.168135792","rc":[{"batb":[[2,1.36,82.01]],"ltp":0.0,"tv":0.0,"id":2249229}]}]}
{"op":"mcm","clk":"1003038059","pt":1580602246370,"mc":[{"id":"1.168135792","rc":[{"batb":[[0,1.44,756.17],[1,1.43,14],[2,1.39,670]],"ltp":0.0,"tv":0.0,"id":2249229}]}]}
{"op":"mcm","clk":"1003038801","pt":1580602254364,"mc":[{"id":"1.168135792","rc":[{"batb":[[0,1.43,14],[1,1.39,670],[2,1.36,74.45]],"ltp":0.0,"tv":0.0,"id":2249229}]}]}
{"op":"mcm","clk":"1003038909","pt":1580602255394,"mc":[{"id":"1.168135792","rc":[{"batb":[[0,1.44,756.17],[1,1.43,14],[2,1.39,670]],"ltp":0.0,"tv":0.0,"id":2249229}]}]}
{"op":"mcm","clk":"1003064392","pt":1580602531258,"mc":[{"id":"1.168135792","rc":[{"batb":[[0,1.43,14],[1,1.39,670],[2,1.36,74.45]],"ltp":0.0,"tv":0.0,"id":2249229}]}]}
{"op":"mcm","clk":"1003064475","pt":1580602532493,"mc":[{"id":"1.168135792","rc":[{"batb":[[0,1.44,850.92],[1,1.43,14],[2,1.39,670]],"ltp":0.0,"tv":0.0,"id":2249229}]}]}
{"op":"mcm","clk":"1003161677","pt":1580603741539,"mc":[{"id":"1.168135792","rc":[{"batb":[[0,1.43,14],[1,1.39,670],[2,1.02,2780.76]],"ltp":0.0,"tv":0.0,"id":2249229}]}]}
{"op":"mcm","clk":"1003161930","pt":1580603744443,"mc":[{"id":"1.168135792","rc":[{"batb":[[2,1.36,82.01]],"ltp":0.0,"tv":0.0,"id":2249229}]}]}
{"op":"mcm","clk":"1003387987","pt":1580607070797,"mc":[{"id":"1.168135792","rc":[{"batb":[[0,1.43,14.01]],"ltp":0.0,"tv":0.0,"id":2249229},{"batb":[[2,1.02,2780.77]],"ltp":0.0,"tv":0.0,"id":5720747}]}]}
{"op":"mcm","clk":"1003469484","pt":1580608166712,"mc":[{"id":"1.168135792","rc":[{"batb":[[0,1.44,756.18],[1,1.43,14],[2,1.39,670]],"ltp":0.0,"tv":0.0,"id":2249229},{"batb":[[0,3,8.26]],"ltp":0.0,"tv":0.0,"id":5720747}]}]}
{"op":"mcm","clk":"1003509911","pt":1580608776078,"mc":[{"id":"1.168135792","rc":[{"batb":[[0,1.43,14.01],[1,1.39,670],[2,1.36,74.43]],"ltp":0.0,"tv":0.0,"id":2249229}]}]}
{"op":"mcm","clk":"1003510063","pt":1580608778393,"mc":[{"id":"1.168135792","rc":[{"batb":[[2,1.36,82.01]],"ltp":0.0,"tv":0.0,"id":2249229}]}]}
{"op":"mcm","clk":"1003641865","pt":1580610603775,"mc":[{"id":"1.168135792","rc":[{"batb":[[0,1.44,850.93],[1,1.43,14],[2,1.39,670]],"ltp":0.0,"tv":0.0,"id":2249229},{"batb":[[1,2.88,23.55]],"ltp":0.0,"tv":0.0,"id":5720747}]}]}
{"op":"mcm","clk":"1003679795","pt":1580611137784,"mc":[{"id":"1.168135792","rc":[{"batb":[[0,1.44,756.18]],"ltp":0.0,"tv":0.0,"id":2249229}]}]}
{"op":"mcm","clk":"1003699895","pt":1580611466811,"mc":[{"id":"1.168135792","rc":[{"batb":[[0,1.44,756.19]],"ltp":0.0,"tv":0.0,"id":2249229},{"batb":[[2,1.02,2780.78]],"ltp":0.0,"tv":0.0,"id":5720747}]}]}
{"op":"mcm","clk":"1003703500","pt":1580611534716,"mc":[{"id":"1.168135792","rc":[{"batl":[[0,1.5,50.65]],"ltp":0.0,"tv":0.0,"id":2249229}]}]}
{"op":"mcm","clk":"1003751249","pt":1580612347672,"mc":[{"id":"1.168135792","rc":[{"batb":[[0,1.43,14.02],[1,1.39,670],[2,1.36,123.02]],"ltp":0.0,"tv":0.0,"id":2249229}]}]}
{"op":"mcm","clk":"1003913514","pt":1580616032064,"mc":[{"id":"1.168135792","rc":[{"batb":[[0,1.44,850.94],[1,1.43,14],[2,1.39,670]],"ltp":0.0,"tv":0.0,"id":2249229}]}]}
{"op":"mcm","clk":"1003938269","pt":1580616636980,"mc":[{"id":"1.168135792","rc":[{"batb":[[0,1.43,14.02],[1,1.39,670],[2,1.36,123.02]],"ltp":0.0,"tv":0.0,"id":2249229}]}]}
{"op":"mcm","clk":"1004263779","pt":1580625004695,"mc":[{"id":"1.168135792","rc":[{"batb":[[2,1.36,164.02]],"ltp":0.0,"tv":0.0,"id":2249229},{"batb":[[1,2.88,31.4]],"ltp":0.0,"tv":0.0,"id":5720747}]}]}
{"op":"mcm","clk":"1004290543","pt":1580625880417,"mc":[{"id":"1.168135792","rc":[{"trd":[[1.5,3.76]],"batl":[[0,1.5,46.89]],"ltp":1.5,"tv":3.75,"id":2249229},{"trd":[[3,18.39]],"batb":[[0,2.88,31.4],[1,1.02,2780.78],[2,1.01,2791.57]],"ltp":3.0,"tv":18.39,"id":5720747}],"tv":22.15}]}
{"op":"mcm","clk":"1004290557","pt":1580625881804,"mc":[{"id":"1.168135792","rc":[{"batb":[[0,1.44,850.94],[1,1.43,14],[2,1.39,670]],"ltp":1.5,"tv":3.75,"id":2249229}]}]}
{"op":"mcm","clk":"1004292012","pt":1580625951524,"mc":[{"id":"1.168135792","rc":[{"batb":[[0,1.43,14.02],[1,1.39,670],[2,1.36,164.02]],"ltp":1.5,"tv":3.75,"id":2249229}]}]}
{"op":"mcm","clk":"1004295136","pt":1580626070790,"mc":[{"id":"1.168135792","rc":[{"batl":[[0,1.53,46.89]],"ltp":1.5,"tv":3.75,"id":2249229}]}]}
{"op":"mcm","clk":"1004298595","pt":1580626200783,"mc":[{"id":"1.168135792","rc":[{"batb":[[1,1.4,7],[2,1.39,670]],"ltp":1.5,"tv":3.75,"id":2249229}]}]}
{"op":"mcm","clk":"1004298612","pt":1580626201400,"mc":[{"id":"1.168135792","rc":[{"batb":[[0,1.44,850.94],[1,1.43,14],[2,1.4,7]],"ltp":1.5,"tv":3.75,"id":2249229}]}]}
{"op":"mcm","clk":"1004312470","pt":1580626589499,"mc":[{"id":"1.168135792","rc":[{"batb":[[0,1.45,21.22]],"ltp":1.5,"tv":3.75,"id":2249229}]}]}
{"op":"mcm","clk":"1004312590","pt":1580626593005,"mc":[{"id":"1.168135792","rc":[{"batb":[[2,1.4,31.24]],"ltp":1.5,"tv":3.75,"id":2249229}]}]}
{"op":"mcm","clk":"1004312699","pt":1580626596511,"mc":[{"id":"1.168135792","rc":[{"batb":[[0,1.44,872.14]],"ltp":1.5,"tv":3.75,"id":2249229}]}]}
{"op":"mcm","clk":"1004312870","pt":1580626602631,"mc":[{"id":"1.168135792","rc":[{"batb":[[1,1.62,39.38],[2,1.02,2780.78]],"ltp":3.0,"tv":18.39,"id":5720747}]}]}
{"op":"mcm","clk":"1004364813","pt":1580628062462,"mc":[{"id":"1.168135792","rc":[{"batb":[[2,1.4,178.86]],"ltp":1.5,"tv":3.75,"id":2249229},{"batb":[[0,2.74,33.93]],"ltp":3.0,"tv":18.39,"id":5720747}]}]}
{"op":"mcm","clk":"1004387470","pt":1580628620684,"mc":[{"id":"1.168135792","rc":[{"batb":[[0,1.45,2.02],[1,1.44,21.2],[2,1.43,14]],"ltp":1.5,"tv":3.75,"id":2249229},{"batb":[[0,2.9,2],[1,2.74,33.93],[2,1.62,39.38]],"ltp":3.0,"tv":18.39,"id":5720747}]}]}
{"op":"mcm","clk":"1004411202","pt":1580629219514,"mc":[{"id":"1.168135792","rc":[{"batb":[[0,1.44,21.22],[1,1.43,14],[2,1.4,178.86]],"ltp":1.5,"tv":3.75,"id":2249229},{"batb":[[0,2.74,33.93],[1,1.62,39.38],[2,1.02,2780.78]],"ltp":3.0,"tv":18.39,"id":5720747}]}]}
{"op":"mcm","clk":"1004411255","pt":1580629220799,"mc":[{"id":"1.168135792","rc":[{"batb":[[0,1.44,872.14]],"ltp":1.5,"tv":3.75,"id":2249229}]}]}
{"op":"mcm","clk":"1004411623","pt":1580629228504,"mc":[{"id":"1.168135792","rc":[{"batb":[[0,1.45,2.02],[1,1.44,21.2],[2,1.43,14]],"ltp":1.5,"tv":3.75,"id":2249229},{"batb":[[0,2.9,2],[1,2.74,33.93],[2,1.62,39.38]],"ltp":3.0,"tv":18.39,"id":5720747}]}]}
{"op":"mcm","clk":"1004433867","pt":1580629750049,"mc":[{"id":"1.168135792","rc":[{"trd":[[1.53,1.01]],"batl":[[0,1.53,45.88]],"ltp":1.53,"tv":4.77,"id":2249229},{"trd":[[2.88,0.54],[2.9,4]],"batb":[[0,2.74,33.93],[1,1.62,39.38],[2,1.02,2780.78]],"ltp":2.88,"tv":22.92,"id":5720747}],"tv":27.69}]}
{"op":"mcm","clk":"1004437472","pt":1580629827686,"mc":[{"id":"1.168135792","rc":[{"batb":[[0,1.44,21.22],[1,1.43,14],[2,1.4,178.86]],"ltp":1.53,"tv":4.77,"id":2249229}]}]}
{"op":"mcm","clk":"1004437518","pt":1580629828662,"mc":[{"id":"1.168135792","rc":[{"batb":[[0,1.44,872.14]],"ltp":1.53,"tv":4.77,"id":2249229}]}]}
{"op":"mcm","clk":"1004438521","pt":1580629849714,"mc":[{"id":"1.168135792","rc":[{"batb":[[0,1.45,2.02],[1,1.44,21.2],[2,1.43,14]],"ltp":1.53,"tv":4.77,"id":2249229},{"batb":[[0,2.9,2],[1,2.74,33.93],[2,1.62,39.38]],"ltp":2.88,"tv":22.92,"id":5720747}]}]}
{"op":"mcm","clk":"1004446659","pt":1580630046316,"mc":[{"id":"1.168135792","rc":[{"batb":[[0,1.47,680.02],[1,1.45,2],[2,1.44,21.2]],"ltp":1.53,"tv":4.77,"id":2249229}]}]}
{"op":"mcm","clk":"1004466047","pt":1580630448542,"mc":[{"id":"1.168135792","rc":[{"batb":[[1,1.44,21.2],[2,1.43,14]],"ltp":1.53,"tv":4.77,"id":2249229},{"batb":[[0,2.74,33.93],[1,1.62,39.38],[2,1.02,2780.78]],"ltp":2.88,"tv":22.92,"id":5720747}]}]}
{"op":"mcm","clk":"1004466735","pt":1580630462814,"mc":[{"id":"1.168135792","rc":[{"batb":[[0,1.48,2.02],[1,1.47,680],[2,1.44,21.2]],"ltp":1.53,"tv":4.77,"id":2249229},{"batb":[[0,2.9,2],[1,2.74,33.93],[2,1.62,39.38]],"ltp":2.88,"tv":22.92,"id":5720747}]}]}
{"op":"mcm","clk":"1004493334","pt":1580631061722,"mc":[{"id":"1.168135792","rc":[{"batb":[[0,1.47,680.02],[1,1.44,21.2],[2,1.43,14]],"ltp":1.53,"tv":4.77,"id":2249229},{"batb":[[0,2.74,33.93],[1,1.62,39.38],[2,1.02,2780.78]],"ltp":2.88,"tv":22.92,"id":5720747}]}]}
{"op":"mcm","clk":"1004494482","pt":1580631084743,"mc":[{"id":"1.168135792","rc":[{"batb":[[0,1.48,2.02],[1,1.47,680],[2,1.44,21.2]],"ltp":1.53,"tv":4.77,"id":2249229},{"batb":[[0,2.9,2],[1,2.74,33.93],[2,1.62,39.38]],"ltp":2.88,"tv":22.92,"id":5720747}]}]}
{"op":"mcm","clk":"1004504570","pt":1580631324769,"mc":[{"id":"1.168135792","rc":[{"batl":[[0,1.5,2127.37],[1,1.53,45.88]],"ltp":1.53,"tv":4.77,"id":2249229}]}]}
{"op":"mcm","clk":"1004510040","pt":1580631450537,"mc":[{"id":"1.168135792","rc":[{"batb":[[0,1.48,783.03]],"ltp":1.53,"tv":4.77,"id":2249229}]}]}
{"op":"mcm","clk":"1004520477","pt":1580631683617,"mc":[{"id":"1.168135792","rc":[{"batb":[[0,1.48,781.03]],"ltp":1.53,"tv":4.77,"id":2249229},{"batb":[[0,2.74,33.93],[1,1.62,39.38],[2,1.02,2780.78]],"ltp":2.88,"tv":22.92,"id":5720747}]}]}
{"op":"mcm","clk":"1004538751","pt":1580632091700,"mc":[{"id":"1.168135792","rc":[{"batl":[[0,3.1,16.71]],"ltp":2.88,"tv":22.92,"id":5720747}]}]}
{"op":"mcm","clk":"1004540084","pt":1580632125491,"mc":[{"id":"1.168135792","rc":[{"batb":[[0,1.47,680.02],[1,1.44,21.2],[2,1.43,14]],"ltp":1.53,"tv":4.77,"id":2249229}]}]}
{"op":"mcm","clk":"1004540125","pt":1580632126720,"mc":[{"id":"1.168135792","rc":[{"batl":[[0,3.1,348.27]],"ltp":2.88,"tv":22.92,"id":5720747}]}]}
{"op":"mcm","clk":"1004540870","pt":1580632146558,"mc":[{"id":"1.168135792","rc":[{"batb":[[1,2.68,89.29],[2,1.62,39.38]],"ltp":2.88,"tv":22.92,"id":5720747}]}]}
{"op":"mcm","clk":"1004543113","pt":1580632204517,"mc":[{"id":"1.168135792","rc":[{"batl":[[0,3.1,16.71]],"ltp":2.88,"tv":22.92,"id":5720747}]}]}
{"op":"mcm","clk":"1004551665","pt":1580632387767,"mc":[{"id":"1.168135792","rc":[{"trd":[[1.5,62.57]],"batl":[[0,1.5,2068.56]],"ltp":1.5,"tv":63.58,"id":2249229},{"trd":[[3,47.77]],"ltp":3.0,"tv":52.3,"id":5720747}],"tv":115.88}]}
{"op":"mcm","clk":"1004558929","pt":1580632559410,"mc":[{"id":"1.168135792","rc":[{"trd":[[3.05,31.73]],"batl":[[0,3.05,0.86]],"ltp":3.05,"tv":84.02,"id":5720747}],"tv":147.61}]}
{"op":"mcm","clk":"1004564738","pt":1580632704677,"mc":[{"id":"1.168135792","rc":[{"trd":[[1.49,0.02]],"batb":[[0,1.47,680.01]],"batl":[[0,1.49,45.87],[1,1.5,2068.56]],"ltp":1.49,"tv":63.6,"id":2249229}],"tv":147.63}]}
{"op":"mcm","clk":"1004574288","pt":1580632911236,"mc":[{"id":"1.168135792","rc":[{"trd":[[1.48,1.8]],"batb":[[0,1.47,680]],"batl":[[0,1.48,15.89],[1,1.49,45.87],[2,1.5,2068.56]],"ltp":1.48,"tv":65.4,"id":2249229},{"trd":[[3.05,32.59]],"ltp":3.05,"tv":84.88,"id":5720747}],"tv":150.28}]}
{"op":"mcm","clk":"1004581474","pt":1580633049781,"mc":[{"id":"1.168135792","rc":[{"batl":[[0,1.48,61.76],[1,1.5,2068.56],[2,1.55,4.33]],"ltp":1.48,"tv":65.4,"id":2249229}]}]}
{"op":"mcm","clk":"1004584685","pt":1580633116776,"mc":[{"id":"1.168135792","rc":[{"trd":[[1.48,48.77]],"batl":[[0,1.48,14.78]],"ltp":1.48,"tv":112.37,"id":2249229},{"trd":[[3.05,55.38]],"ltp":3.05,"tv":107.68,"id":5720747}],"tv":220.06}]}
{"op":"mcm","clk":"1004585827","pt":1580633140803,"mc":[{"id":"1.168135792","rc":[{"batl":[[0,1.49,14.78]],"ltp":1.48,"tv":112.37,"id":2249229}]}]}
{"op":"mcm","clk":"1004586386","pt":1580633151547,"mc":[{"id":"1.168135792","marketDefinition":{"bspMarket":false,"turnInPlayEnabled":true,"persistenceEnabled":true,"marketBaseRate":5.0,"eventId":"29678823","eventTypeId":"2","numberOfWinners":1,"bettingType":"ODDS","marketType":"SET_WINNER","marketTime":"2020-02-02T08:30:00.000Z","suspendTime":"2020-02-02T08:30:00.000Z","bspReconciled":false,"complete":true,"inPlay":true,"crossMatching":true,"runnersVoidable":false,"numberOfActiveRunners":2,"betDelay":3,"status":"OPEN","runners":[{"status":"ACTIVE","sortPriority":1,"id":5720747,"name":"Dominic Thiem"},{"status":"ACTIVE","sortPriority":2,"id":2249229,"name":"Novak Djokovic"}],"regulators":["MR_INT"],"countryCode":"AU","discountAllowed":true,"timezone":"GMT","openDate":"2020-02-02T08:30:00.000Z","version":3148327248,"name":"Set 2 Winner","eventName":"Thiem v Djokovic"},"rc":[{"batb":[[0,1.4,24.23],[1,1.02,2780.76],[2,1.01,2791.06]],"batl":[[0,1.55,4.33],[1,1.5,0],[2,1.55,0]],"ltp":1.48,"tv":112.37,"id":2249229},{"batb":[[0,1.62,39.38],[1,1.02,2780.78],[2,1.01,2791.06]],"ltp":3.05,"tv":107.68,"id":5720747}]}]}
{"op":"mcm","clk":"1004587933","pt":1580633183372,"mc":[{"id":"1.168135792","rc":[{"batb":[[1,1.05,16.8],[2,1.02,2780.76]],"ltp":1.48,"tv":112.37,"id":2249229}]}]}
{"op":"mcm","clk":"1004588000","pt":1580633184772,"mc":[{"id":"1.168135792","rc":[{"batb":[[2,1.04,21]],"ltp":1.48,"tv":112.37,"id":2249229}]}]}
{"op":"mcm","clk":"1004588184","pt":1580633188734,"mc":[{"id":"1.168135792","rc":[{"batb":[[1,1.05,16.82],[2,1.02,2780.76]],"ltp":3.05,"tv":107.68,"id":5720747}]}]}
{"op":"mcm","clk":"1004588235","pt":1580633189744,"mc":[{"id":"1.168135792","rc":[{"batb":[[2,1.04,21]],"ltp":3.05,"tv":107.68,"id":5720747}]}]}
{"op":"mcm","clk":"1004594587","pt":1580633339742,"mc":[{"id":"1.168135792","rc":[{"trd":[[1.4,48.46]],"batb":[[0,1.05,16.8],[1,1.04,21],[2,1.03,28]],"batl":[[0,1.4,9.54],[1,1.55,4.33]],"ltp":1.4,"tv":160.84,"id":2249229}],"tv":268.52}]}
{"op":"mcm","clk":"1004594800","pt":1580633343653,"mc":[{"id":"1.168135792","rc":[{"batl":[[0,1.55,4.33],[1,1.55,0]],"ltp":1.4,"tv":160.84,"id":2249229}]}]}
{"op":"mcm","clk":"1004595273","pt":1580633352656,"mc":[{"id":"1.168135792","rc":[{"batb":[[0,1.22,39.38],[1,1.05,16.8],[2,1.04,21]],"ltp":1.4,"tv":160.84,"id":2249229}]}]}
{"op":"mcm","clk":"1004595528","pt":1580633357676,"mc":[{"id":"1.168135792","rc":[{"batl":[[0,1.52,21.2],[1,1.55,4.33]],"ltp":1.4,"tv":160.84,"id":2249229}]}]}
{"op":"mcm","clk":"1004597818","pt":1580633403760,"mc":[{"id":"1.168135792","rc":[{"batb":[[0,1.32,21.96],[1,1.22,39.38],[2,1.05,16.8]],"ltp":1.4,"tv":160.84,"id":2249229}]}]}
{"op":"mcm","clk":"1004597861","pt":1580633404737,"mc":[{"id":"1.168135792","rc":[{"batl":[[2,1.95,409.86]],"ltp":1.4,"tv":160.84,"id":2249229},{"batl":[[0,3.9,158.24]],"ltp":3.05,"tv":107.68,"id":5720747}]}]}
{"op":"mcm","clk":"1004598975","pt":1580633428467,"mc":[{"id":"1.168135792","rc":[{"batb":[[0,1.35,28.77],[1,1.32,21.96],[2,1.22,39.38]],"ltp":1.4,"tv":160.84,"id":2249229}]}]}
{"op":"mcm","clk":"1004599218","pt":1580633434674,"mc":[{"id":"1.168135792","rc":[{"batb":[[0,2.1,19.69],[1,1.62,39.38],[2,1.05,16.82]],"ltp":3.05,"tv":107.68,"id":5720747}]}]}
{"op":"mcm","clk":"1004599330","pt":1580633437394,"mc":[{"id":"1.168135792","rc":[{"batl":[[0,3.8,8.78],[1,3.9,158.24]],"ltp":3.05,"tv":107.68,"id":5720747}]}]}
{"op":"mcm","clk":"1004599785","pt":1580633448569,"mc":[{"id":"1.168135792","rc":[{"batb":[[0,1.36,15.9],[1,1.35,28.77],[2,1.32,21.96]],"ltp":1.4,"tv":160.84,"id":2249229}]}]}
{"op":"mcm","clk":"1004607169","pt":1580633629801,"mc":[{"id":"1.168135792","rc":[{"batl":[[2,1.95,0]],"ltp":1.4,"tv":160.84,"id":2249229},{"batl":[[1,3.9,0]],"ltp":3.05,"tv":107.68,"id":5720747}]}]}
{"op":"mcm","clk":"1004607334","pt":1580633633690,"mc":[{"id":"1.168135792","rc":[{"batl":[[2,1.82,469.11]],"ltp":1.4,"tv":160.84,"id":2249229},{"batl":[[1,4.6,136.05]],"ltp":3.05,"tv":107.68,"id":5720747}]}]}
{"op":"mcm","clk":"1004608534","pt":1580633659752,"mc":[{"id":"1.168135792","rc":[{"batl":[[1,4.6,0]],"ltp":3.05,"tv":107.68,"id":5720747}]}]}
{"op":"mcm","clk":"1004608732","pt":1580633663763,"mc":[{"id":"1.168135792","rc":[{"batl":[[1,4.2,148.03]],"ltp":3.05,"tv":107.68,"id":5720747}]}]}
{"op":"mcm","clk":"1004612182","pt":1580633737772,"mc":[{"id":"1.168135792","rc":[{"batl":[[1,4.2,0]],"ltp":3.05,"tv":107.68,"id":5720747}]}]}
{"op":"mcm","clk":"1004612313","pt":1580633740543,"mc":[{"id":"1.168135792","rc":[{"batl":[[1,4.9,126.27]],"ltp":3.05,"tv":107.68,"id":5720747}]}]}
{"op":"mcm","clk":"1004614560","pt":1580633783812,"mc":[{"id":"1.168135792","rc":[{"batl":[[2,1.82,0]],"ltp":1.4,"tv":160.84,"id":2249229}]}]}
{"op":"mcm","clk":"1004614772","pt":1580633787740,"mc":[{"id":"1.168135792","rc":[{"batl":[[2,1.73,527.57]],"ltp":1.4,"tv":160.84,"id":2249229}]}]}
{"op":"mcm","clk":"1004615179","pt":1580633795547,"mc":[{"id":"1.168135792","rc":[{"batl":[[0,1.55,4.33],[1,1.73,527.57],[2,1.73,0]],"ltp":1.4,"tv":160.84,"id":2249229}]}]}
{"op":"mcm","clk":"1004615354","pt":1580633798776,"mc":[{"id":"1.168135792","rc":[{"batl":[[0,1.5,21.2],[1,1.55,4.33],[2,1.73,527.57]],"ltp":1.4,"tv":160.84,"id":2249229}]}]}
{"op":"mcm","clk":"1004616849","pt":1580633826686,"mc":[{"id":"1.168135792","rc":[{"batb":[[0,1.35,28.77],[1,1.32,21.96],[2,1.22,39.38]],"ltp":1.4,"tv":160.84,"id":2249229}]}]}
{"op":"mcm","clk":"1004617122","pt":1580633831715,"mc":[{"id":"1.168135792","rc":[{"batb":[[2,1.05,16.8]],"ltp":1.4,"tv":160.84,"id":2249229}]}]}
{"op":"mcm","clk":"1004617273","pt":1580633834604,"mc":[{"id":"1.168135792","rc":[{"batb":[[2,1.26,39.38]],"ltp":1.4,"tv":160.84,"id":2249229}]}]}
{"op":"mcm","clk":"1004618613","pt":1580633861727,"mc":[{"id":"1.168135792","rc":[{"batl":[[1,4.9,0]],"ltp":3.05,"tv":107.68,"id":5720747}]}]}
{"op":"mcm","clk":"1004618839","pt":1580633865741,"mc":[{"id":"1.168135792","rc":[{"batl":[[1,5.5,115.06]],"ltp":3.05,"tv":107.68,"id":5720747}]}]}
{"op":"mcm","clk":"1004619829","pt":1580633883534,"mc":[{"id":"1.168135792","rc":[{"batb":[[1,1.32,14.39]],"ltp":1.4,"tv":160.84,"id":2249229}]}]}
{"op":"mcm","clk":"1004624202","pt":1580633961796,"mc":[{"id":"1.168135792","rc":[{"batl":[[0,1.55,4.33],[1,1.73,527.57],[2,1.73,0]],"ltp":1.4,"tv":160.84,"id":2249229}]}]}
{"op":"mcm","clk":"1004624372","pt":1580633964819,"mc":[{"id":"1.168135792","rc":[{"batl":[[0,1.49,21.2],[1,1.55,4.33],[2,1.73,527.57]],"ltp":1.4,"tv":160.84,"id":2249229}]}]}
{"op":"mcm","clk":"1004624802","pt":1580633972480,"mc":[{"id":"1.168135792","rc":[{"batb":[[0,2.4,16.66],[1,2.1,19.69],[2,1.62,39.38]],"ltp":3.05,"tv":107.68,"id":5720747}]}]}
{"op":"mcm","clk":"1004625568","pt":1580633986602,"mc":[{"id":"1.168135792","rc":[{"batb":[[0,1.32,14.39],[1,1.26,39.38],[2,1.05,16.8]],"ltp":1.4,"tv":160.84,"id":2249229}]}]}
{"op":"mcm","clk":"1004632190","pt":1580634090673,"mc":[{"id":"1.168135792","rc":[{"batb":[[1,1.3,1514.46],[2,1.26,39.38]],"ltp":1.4,"tv":160.84,"id":2249229}]}]}
{"op":"mcm","clk":"1004635654","pt":1580634161431,"mc":[{"id":"1.168135792","rc":[{"batb":[[1,1.31,15.9],[2,1.3,1514.46]],"ltp":1.4,"tv":160.84,"id":2249229}]}]}
{"op":"mcm","clk":"1004642974","pt":1580634322763,"mc":[{"id":"1.168135792","rc":[{"batl":[[1,5.5,0]],"ltp":3.05,"tv":107.68,"id":5720747}]}]}
{"op":"mcm","clk":"1004643151","pt":1580634327582,"mc":[{"id":"1.168135792","rc":[{"batl":[[1,5.3,93.19]],"ltp":3.05,"tv":107.68,"id":5720747}]}]}
{"op":"mcm","clk":"1004644094","pt":1580634347817,"mc":[{"id":"1.168135792","rc":[{"batl":[[0,1.49,21.96]],"ltp":1.4,"tv":160.84,"id":2249229}]}]}
{"op":"mcm","clk":"1004647550","pt":1580634415782,"mc":[{"id":"1.168135792","rc":[{"batb":[[0,1.31,15.9],[1,1.3,1514.46],[2,1.26,39.38]],"ltp":1.4,"tv":160.84,"id":2249229}]}]}
{"op":"mcm","clk":"1004653975","pt":1580634554794,"mc":[{"id":"1.168135792","rc":[{"batl":[[0,1.55,5.08],[1,1.73,527.57],[2,1.73,0]],"ltp":1.4,"tv":160.84,"id":2249229}]}]}
{"op":"mcm","clk":"1004654056","pt":1580634556700,"mc":[{"id":"1.168135792","rc":[{"batl":[[0,1.55,4.33]],"ltp":1.4,"tv":160.84,"id":2249229}]}]}
{"op":"mcm","clk":"1004654105","pt":1580634557789,"mc":[{"id":"1.168135792","rc":[{"batl":[[0,1.48,21.2],[1,1.55,4.33],[2,1.73,527.57]],"ltp":1.4,"tv":160.84,"id":2249229}]}]}
{"op":"mcm","clk":"1004654175","pt":1580634559607,"mc":[{"id":"1.168135792","rc":[{"batl":[[0,1.48,21.96]],"ltp":1.4,"tv":160.84,"id":2249229}]}]}
{"op":"mcm","clk":"1004656699","pt":1580634618606,"mc":[{"id":"1.168135792","rc":[{"trd":[[3.8,9.06]],"batl":[[0,3.8,4.25]],"ltp":3.8,"tv":116.74,"id":5720747}],"tv":277.58}]}
{"op":"mcm","clk":"1004659760","pt":1580634688565,"mc":[{"id":"1.168135792","rc":[{"batl":[[1,5.3,0]],"ltp":3.8,"tv":116.74,"id":5720747}]}]}
{"op":"mcm","clk":"1004659974","pt":1580634692451,"mc":[{"id":"1.168135792","rc":[{"batl":[[1,4.9,126.27]],"ltp":3.8,"tv":116.74,"id":5720747}]}]}
{"op":"mcm","clk":"1004664750","pt":1580634788763,"mc":[{"id":"1.168135792","rc":[{"batl":[[1,4.9,0]],"ltp":3.8,"tv":116.74,"id":5720747}]}]}
{"op":"mcm","clk":"1004664994","pt":1580634792769,"mc":[{"id":"1.168135792","rc":[{"batl":[[1,5.5,115.06]],"ltp":3.8,"tv":116.74,"id":5720747}]}]}
{"op":"mcm","clk":"1004673735","pt":1580634951597,"mc":[{"id":"1.168135792","rc":[{"batl":[[0,1.47,18.75],[1,1.48,21.96],[2,1.55,4.33]],"ltp":1.4,"tv":160.84,"id":2249229}]}]}
{"op":"mcm","clk":"1004674765","pt":1580634973606,"mc":[{"id":"1.168135792","rc":[{"batl":[[1,1.55,5.08],[2,1.73,527.57]],"ltp":1.4,"tv":160.84,"id":2249229}]}]}
{"op":"mcm","clk":"1004674823","pt":1580634974809,"mc":[{"id":"1.168135792","rc":[{"batl":[[1,1.55,4.33]],"ltp":1.4,"tv":160.84,"id":2249229}]}]}
{"op":"mcm","clk":"1004674890","pt":1580634976514,"mc":[{"id":"1.168135792","rc":[{"batl":[[0,1.46,21.2],[1,1.47,18.75],[2,1.55,4.33]],"ltp":1.4,"tv":160.84,"id":2249229}]}]}
{"op":"mcm","clk":"1004674989","pt":1580634978625,"mc":[{"id":"1.168135792","rc":[{"batl":[[0,1.46,21.96]],"ltp":1.4,"tv":160.84,"id":2249229}]}]}
{"op":"mcm","clk":"1004676876","pt":1580635013764,"mc":[{"id":"1.168135792","rc":[{"batl":[[1,1.55,4.33],[2,1.73,527.57]],"ltp":1.4,"tv":160.84,"id":2249229}]}]}
{"op":"mcm","clk":"1004677101","pt":1580635017777,"mc":[{"id":"1.168135792","rc":[{"batl":[[0,1.55,5.08],[1,1.73,527.57],[2,1.73,0]],"ltp":1.4,"tv":160.84,"id":2249229}]}]}
{"op":"mcm","clk":"1004677215","pt":1580635019782,"mc":[{"id":"1.168135792","rc":[{"batl":[[0,1.55,4.33]],"ltp":1.4,"tv":160.84,"id":2249229}]}]}
{"op":"mcm","clk":"1004677268","pt":1580635020811,"mc":[{"id":"1.168135792","rc":[{"batl":[[0,1.48,21.2],[1,1.55,4.33],[2,1.73,527.57]],"ltp":1.4,"tv":160.84,"id":2249229}]}]}
{"op":"mcm","clk":"1004677370","pt":1580635022811,"mc":[{"id":"1.168135792","rc":[{"batl":[[0,1.48,21.96]],"ltp":1.4,"tv":160.84,"id":2249229}]}]}
{"op":"mcm","clk":"1004677738","pt":1580635029811,"mc":[{"id":"1.168135792","rc":[{"batl":[[1,5.5,0]],"ltp":3.8,"tv":116.74,"id":5720747}]}]}
{"op":"mcm","clk":"1004677880","pt":1580635032721,"mc":[{"id":"1.168135792","rc":[{"batl":[[1,4.9,125.74]],"ltp":3.8,"tv":116.74,"id":5720747}]}]}
{"op":"mcm","clk":"1004678059","pt":1580635035819,"mc":[{"id":"1.168135792","rc":[{"trd":[[1.48,70.73]],"batl":[[0,1.55,4.33],[1,1.73,527.57],[2,1.73,0]],"ltp":1.48,"tv":182.8,"id":2249229},{"trd":[[3.05,66.04]],"batl":[[0,3,14.34],[1,3.8,4.25],[2,4.9,125.74]],"ltp":3.05,"tv":127.4,"id":5720747}],"tv":310.2}]}
{"op":"mcm","clk":"1004678304","pt":1580635040807,"mc":[{"id":"1.168135792","rc":[{"trd":[[1.5,91.25]],"batl":[[0,1.45,12.87],[1,1.55,4.33],[2,1.73,527.57]],"ltp":1.5,"tv":211.47,"id":2249229},{"trd":[[3,62.11]],"batl":[[0,3.8,4.25],[1,4.9,125.74],[2,4.9,0]],"ltp":3.0,"tv":141.74,"id":5720747}],"tv":353.22}]}
{"op":"mcm","clk":"1004678335","pt":1580635041435,"mc":[{"id":"1.168135792","rc":[{"batl":[[0,1.55,4.33],[1,1.73,527.57],[2,1.73,0]],"ltp":1.5,"tv":211.47,"id":2249229}]}]}
{"op":"mcm","clk":"1004678457","pt":1580635043704,"mc":[{"id":"1.168135792","rc":[{"batl":[[0,1.5,4],[1,1.55,4.33],[2,1.73,527.57]],"ltp":1.5,"tv":211.47,"id":2249229}]}]}
{"op":"mcm","clk":"1004678505","pt":1580635044734,"mc":[{"id":"1.168135792","rc":[{"batl":[[0,1.55,4.33],[1,1.73,527.57],[2,1.73,0]],"ltp":1.5,"tv":211.47,"id":2249229}]}]}
{"op":"mcm","clk":"1004679508","pt":1580635063797,"mc":[{"id":"1.168135792","rc":[{"batb":[[0,1.36,19.69],[1,1.31,15.9],[2,1.3,1514.46]],"ltp":1.5,"tv":211.47,"id":2249229}]}]}
{"op":"mcm","clk":"1004680043","pt":1580635074591,"mc":[{"id":"1.168135792","rc":[{"batl":[[0,1.55,5.08]],"ltp":1.5,"tv":211.47,"id":2249229}]}]}
{"op":"mcm","clk":"1004683318","pt":1580635134729,"mc":[{"id":"1.168135792","rc":[{"batl":[[1,4.9,0]],"ltp":3.0,"tv":141.74,"id":5720747}]}]}
{"op":"mcm","clk":"1004683587","pt":1580635139721,"mc":[{"id":"1.168135792","rc":[{"batl":[[1,4.6,128.79]],"ltp":3.0,"tv":141.74,"id":5720747}]}]}
{"op":"mcm","clk":"1004685904","pt":1580635184771,"mc":[{"id":"1.168135792","rc":[{"batl":[[1,4.6,0]],"ltp":3.0,"tv":141.74,"id":5720747}]}]}
{"op":"mcm","clk":"1004686046","pt":1580635187770,"mc":[{"id":"1.168135792","rc":[{"batl":[[1,4.2,136.43]],"ltp":3.0,"tv":141.74,"id":5720747}]}]}
{"op":"mcm","clk":"1004687189","pt":1580635215816,"mc":[{"id":"1.168135792","rc":[{"batb":[[2,1.26,39.38]],"ltp":1.5,"tv":211.47,"id":2249229}]}]}
{"op":"mcm","clk":"1004691319","pt":1580635304621,"mc":[{"id":"1.168135792","rc":[{"batb":[[1,1.32,22.72],[2,1.31,15.9]],"ltp":1.5,"tv":211.47,"id":2249229}]}]}
{"op":"mcm","clk":"1004714410","pt":1580635859813,"mc":[{"id":"1.168135792","rc":[{"batl":[[2,1000,0.02]],"ltp":1.5,"tv":211.47,"id":2249229}]}]}
{"op":"mcm","clk":"1004714430","pt":1580635860435,"mc":[{"id":"1.168135792","rc":[{"batl":[[2,1000,0]],"ltp":1.5,"tv":211.47,"id":2249229}]}]}
{"op":"mcm","clk":"1004714581","pt":1580635863738,"mc":[{"id":"1.168135792","rc":[{"trd":[[1.36,0.03]],"batb":[[0,1.36,19.67]],"ltp":1.36,"tv":211.5,"id":2249229}],"tv":353.25}]}
{"op":"mcm","clk":"1004714865","pt":1580635871735,"mc":[{"id":"1.168135792","rc":[{"batb":[[0,1.36,19.69]],"ltp":1.36,"tv":211.5,"id":2249229}]}]}
{"op":"mcm","clk":"1004717000","pt":1580635923789,"mc":[{"id":"1.168135792","rc":[{"batl":[[1,4.2,0]],"ltp":3.0,"tv":141.74,"id":5720747}]}]}
{"op":"mcm","clk":"1004717024","pt":1580635924201,"mc":[{"id":"1.168135792","rc":[{"batl":[[1,1.73,0]],"ltp":1.36,"tv":211.5,"id":2249229}]}]}
{"op":"mcm","clk":"1004717768","pt":1580635939625,"mc":[{"id":"1.168135792","rc":[{"batl":[[1,1.82,469.11]],"ltp":1.36,"tv":211.5,"id":2249229},{"batl":[[1,4.6,136.05]],"ltp":3.0,"tv":141.74,"id":5720747}]}]}
{"op":"mcm","clk":"1004720361","pt":1580635996785,"mc":[{"id":"1.168135792","rc":[{"trd":[[1.53,1.77],[1.55,4.33]],"batl":[[0,1.82,469.11],[1,1.82,0]],"ltp":1.55,"tv":216.59,"id":2249229},{"trd":[[2.8,2.39],[2.88,0.94]],"batl":[[0,2.8,14.88],[1,3.8,4.25],[2,4.6,136.05]],"ltp":2.8,"tv":144.53,"id":5720747}],"tv":361.13}]}
{"op":"mcm","clk":"1004720628","pt":1580636002792,"mc":[{"id":"1.168135792","rc":[{"trd":[[1.55,31.23]],"ltp":1.55,"tv":243.49,"id":2249229},{"trd":[[2.8,17.28]],"batl":[[0,3.8,4.25],[1,4.6,136.05],[2,4.6,0]],"ltp":2.8,"tv":159.42,"id":5720747}],"tv":402.91}]}
{"op":"mcm","clk":"1004720724","pt":1580636004789,"mc":[{"id":"1.168135792","rc":[{"batl":[[0,1.55,7],[1,1.82,469.11]],"ltp":1.55,"tv":243.49,"id":2249229}]}]}
{"op":"mcm","clk":"1004720770","pt":1580636005817,"mc":[{"id":"1.168135792","rc":[{"batl":[[0,1.55,10]],"ltp":1.55,"tv":243.49,"id":2249229}]}]}
{"op":"mcm","clk":"1004720821","pt":1580636006696,"mc":[{"id":"1.168135792","rc":[{"batl":[[0,1.82,469.11],[1,1.82,0]],"ltp":1.55,"tv":243.49,"id":2249229}]}]}
{"op":"mcm","clk":"1004721003","pt":1580636010810,"mc":[{"id":"1.168135792","rc":[{"batb":[[1,2.24,24.23],[2,2.1,19.69]],"ltp":2.8,"tv":159.42,"id":5720747}]}]}
{"op":"mcm","clk":"1004722841","pt":1580636051587,"mc":[{"id":"1.168135792","rc":[{"batl":[[0,1.6,5],[1,1.82,469.11]],"ltp":1.55,"tv":243.49,"id":2249229}]}]}
{"op":"mcm","clk":"1004734021","pt":1580636324817,"mc":[{"id":"1.168135792","rc":[{"batl":[[1,1.82,0]],"ltp":1.55,"tv":243.49,"id":2249229},{"batl":[[1,4.6,0]],"ltp":2.8,"tv":159.42,"id":5720747}]}]}
{"op":"mcm","clk":"1004734061","pt":1580636325804,"mc":[{"id":"1.168135792","rc":[{"batb":[[1,1.35,1272.32],[2,1.34,888.57]],"batl":[[0,1.39,443.9],[1,1.4,697.83],[2,1.6,5]],"ltp":1.55,"tv":243.49,"id":2249229}]}]}
{"op":"mcm","clk":"1004734192","pt":1580636328632,"mc":[{"id":"1.168135792","rc":[{"batl":[[1,5.1,123.37]],"ltp":2.8,"tv":159.42,"id":5720747}]}]}
{"op":"mcm","clk":"1004734264","pt":1580636329818,"mc":[{"id":"1.168135792","rc":[{"batb":[[0,1.35,1272.34],[1,1.34,888.57],[2,1.32,22.72]],"ltp":1.55,"tv":243.49,"id":2249229}]}]}
{"op":"mcm","clk":"1004734567","pt":1580636335451,"mc":[{"id":"1.168135792","rc":[{"batb":[[0,1.35,845.35],[1,1.32,22.72],[2,1.31,15.9]],"ltp":1.55,"tv":243.49,"id":2249229}]}]}
{"op":"mcm","clk":"1004734734","pt":1580636338818,"mc":[{"id":"1.168135792","rc":[{"batb":[[0,1.36,438.55],[1,1.35,845.33],[2,1.32,22.72]],"ltp":1.55,"tv":243.49,"id":2249229}]}]}
{"op":"mcm","clk":"1004734855","pt":1580636341657,"mc":[{"id":"1.168135792","rc":[{"batb":[[0,1.36,1270.34]],"ltp":1.55,"tv":243.49,"id":2249229}]}]}
{"op":"mcm","clk":"1004734979","pt":1580636344751,"mc":[{"id":"1.168135792","rc":[{"trd":[[1.36,186.55]],"batb":[[0,1.36,345.29]],"ltp":1.36,"tv":430.01,"id":2249229}],"tv":589.43}]}
{"op":"mcm","clk":"1004735047","pt":1580636345736,"mc":[{"id":"1.168135792","rc":[{"batb":[[0,1.35,845.33],[1,1.32,22.72],[2,1.31,15.9]],"ltp":1.36,"tv":430.01,"id":2249229}]}]}
{"op":"mcm","clk":"1004735201","pt":1580636348672,"mc":[{"id":"1.168135792","rc":[{"trd":[[1.39,7.58]],"batb":[[0,1.35,1261.9],[1,1.34,888.58],[2,1.32,22.72]],"batl":[[0,1.39,440.11]],"ltp":1.39,"tv":437.59,"id":2249229}],"tv":597.01}]}
{"op":"mcm","clk":"1004735283","pt":1580636350685,"mc":[{"id":"1.168135792","rc":[{"batb":[[0,1.35,845.39],[1,1.32,22.72],[2,1.31,15.9]],"batl":[[0,1.4,697.83],[1,1.6,5],[2,1.75,510.77]],"ltp":1.39,"tv":437.59,"id":2249229}]}]}
{"op":"mcm","clk":"1004735342","pt":1580636351668,"mc":[{"id":"1.168135792","rc":[{"batb":[[0,1.36,420.1],[1,1.35,845.39],[2,1.32,22.72]],"ltp":1.39,"tv":437.59,"id":2249229}]}]}
{"op":"mcm","clk":"1004735449","pt":1580636353782,"mc":[{"id":"1.168135792","rc":[{"batb":[[0,1.36,898.24]],"batl":[[0,1.4,1086.04],[1,1.41,668.7],[2,1.6,5]],"ltp":1.39,"tv":437.59,"id":2249229}]}]}
{"op":"mcm","clk":"1004735716","pt":1580636359773,"mc":[{"id":"1.168135792","rc":[{"batl":[[0,1.38,5],[1,1.4,1086.04],[2,1.41,668.7]],"ltp":1.39,"tv":437.59,"id":2249229}]}]}
{"op":"mcm","clk":"1004735758","pt":1580636360699,"mc":[{"id":"1.168135792","rc":[{"trd":[[1.36,202.28]],"batb":[[0,1.36,890.37]],"ltp":1.36,"tv":453.32,"id":2249229}],"tv":612.74}]}
{"op":"mcm","clk":"1004735896","pt":1580636363793,"mc":[{"id":"1.168135792","rc":[{"batb":[[0,1.36,478.14]],"batl":[[0,1.4,1086.04],[1,1.41,668.7],[2,1.6,5]],"ltp":1.36,"tv":453.32,"id":2249229}]}]}
{"op":"mcm","clk":"1004736082","pt":1580636367818,"mc":[{"id":"1.168135792","rc":[{"trd":[[1.36,218]],"batb":[[0,1.36,470.28]],"ltp":1.36,"tv":469.04,"id":2249229}],"tv":628.46}]}
{"op":"mcm","clk":"1004736292","pt":1580636372723,"mc":[{"id":"1.168135792","rc":[{"batl":[[0,1.39,5],[1,1.4,1086.04],[2,1.41,668.7]],"ltp":1.36,"tv":469.04,"id":2249229}]}]}
{"op":"mcm","clk":"1004736514","pt":1580636377725,"mc":[{"id":"1.168135792","rc":[{"trd":[[1.36,225.58]],"batb":[[0,1.36,466.49]],"ltp":1.36,"tv":476.62,"id":2249229}],"tv":636.04}]}
{"op":"mcm","clk":"1004737929","pt":1580636404570,"mc":[{"id":"1.168135792","rc":[{"batb":[[0,1.32,22.72],[1,1.31,15.9],[2,1.26,39.38]],"batl":[[1,1.75,510.77],[2,1.41,0]],"ltp":1.36,"tv":476.62,"id":2249229}]}]}
{"op":"mcm","clk":"1004738362","pt":1580636413751,"mc":[{"id":"1.168135792","rc":[{"batb":[[0,1.32,1019.96],[1,1.31,1008.13]],"batl":[[1,1.49,725.43],[2,1.5,519.5]],"ltp":1.36,"tv":476.62,"id":2249229}]}]}
{"op":"mcm","clk":"1004739037","pt":1580636427716,"mc":[{"id":"1.168135792","rc":[{"trd":[[1.35,11.96]],"batl":[[0,1.35,9.7],[1,1.39,5],[2,1.49,725.43]],"ltp":1.35,"tv":488.58,"id":2249229},{"trd":[[3.8,13.31]],"batl":[[0,5.1,123.37],[1,5.1,0]],"ltp":3.8,"tv":163.67,"id":5720747}],"tv":652.26}]}
{"op":"mcm","clk":"1004739281","pt":1580636432581,"mc":[{"id":"1.168135792","rc":[{"batb":[[0,1.32,22.72],[1,1.31,15.9]],"batl":[[2,1.75,510.77]],"ltp":1.35,"tv":488.58,"id":2249229}]}]}
{"op":"mcm","clk":"1004739424","pt":1580636435721,"mc":[{"id":"1.168135792","rc":[{"batb":[[0,2.1,19.69],[1,1.62,39.38],[2,1.05,16.82]],"ltp":3.8,"tv":163.67,"id":5720747}]}]}
{"op":"mcm","clk":"1004739473","pt":1580636436799,"mc":[{"id":"1.168135792","rc":[{"batb":[[0,1.62,39.38],[1,1.05,16.82],[2,1.04,21]],"ltp":3.8,"tv":163.67,"id":5720747}]}]}
{"op":"mcm","clk":"1004739514","pt":1580636437722,"mc":[{"id":"1.168135792","rc":[{"batb":[[0,1.31,15.9],[1,1.26,39.38],[2,1.05,16.8]],"ltp":1.35,"tv":488.58,"id":2249229}]}]}
{"op":"mcm","clk":"1004739547","pt":1580636438594,"mc":[{"id":"1.168135792","rc":[{"batb":[[0,1.26,39.38],[1,1.05,16.8],[2,1.04,21]],"ltp":1.35,"tv":488.58,"id":2249229}]}]}
{"op":"mcm","clk":"1004739588","pt":1580636439620,"mc":[{"id":"1.168135792","rc":[{"batb":[[0,1.05,16.8],[1,1.04,21],[2,1.03,28]],"ltp":1.35,"tv":488.58,"id":2249229},{"batb":[[0,3.3,102],[1,1.62,39.38],[2,1.05,16.82]],"ltp":3.8,"tv":163.67,"id":5720747}]}]}
{"op":"mcm","clk":"1004739621","pt":1580636440543,"mc":[{"id":"1.168135792","rc":[{"batb":[[0,1.32,997.24],[1,1.31,992.23],[2,1.05,16.8]],"batl":[[2,1.49,725.43]],"ltp":1.35,"tv":488.58,"id":2249229}]}]}
{"op":"mcm","clk":"1004739788","pt":1580636443745,"mc":[{"id":"1.168135792","rc":[{"batl":[[1,1.36,5],[2,1.39,5]],"ltp":1.35,"tv":488.58,"id":2249229}]}]}
{"op":"mcm","clk":"1004739893","pt":1580636445602,"mc":[{"id":"1.168135792","rc":[{"trd":[[1.35,21.67]],"batb":[[2,1.26,18.17]],"batl":[[0,1.36,5],[1,1.39,5],[2,1.49,725.43]],"ltp":1.35,"tv":498.29,"id":2249229},{"trd":[[3.85,3.4]],"batl":[[0,3.85,1887.04],[1,5.1,123.37]],"ltp":3.85,"tv":167.07,"id":5720747}],"tv":665.36}]}
{"op":"mcm","clk":"1004740162","pt":1580636451635,"mc":[{"id":"1.168135792","rc":[{"batb":[[0,1.62,39.38],[1,1.05,16.82],[2,1.04,21]],"ltp":3.85,"tv":167.07,"id":5720747}]}]}
{"op":"mcm","clk":"1004740319","pt":1580636454726,"mc":[{"id":"1.168135792","rc":[{"batb":[[0,3.4,102],[1,1.62,39.38],[2,1.05,16.82]],"ltp":3.85,"tv":167.07,"id":5720747}]}]}
{"op":"mcm","clk":"1004741074","pt":1580636467771,"mc":[{"id":"1.168135792","rc":[{"batb":[[1,1.62,24.23]],"ltp":3.85,"tv":167.07,"id":5720747}]}]}
{"op":"mcm","clk":"1004741200","pt":1580636470757,"mc":[{"id":"1.168135792","rc":[{"batb":[[1,1.05,16.82],[2,1.04,21]],"ltp":3.85,"tv":167.07,"id":5720747}]}]}
{"op":"mcm","clk":"1004741236","pt":1580636471785,"mc":[{"id":"1.168135792","rc":[{"trd":[[1.35,119.13]],"ltp":1.35,"tv":595.75,"id":2249229},{"trd":[[3.85,37.58]],"batl":[[0,3.85,1852.86]],"ltp":3.85,"tv":201.25,"id":5720747}],"tv":797.0}]}
{"op":"mcm","clk":"1004741330","pt":1580636473692,"mc":[{"id":"1.168135792","rc":[{"batb":[[1,1.42,24.25],[2,1.05,16.8]],"ltp":3.85,"tv":201.25,"id":5720747}]}]}
{"op":"mcm","clk":"1004741389","pt":1580636474776,"mc":[{"id":"1.168135792","rc":[{"trd":[[1.36,230.12]],"batl":[[0,1.36,2.73]],"ltp":1.36,"tv":600.29,"id":2249229}],"tv":801.55}]}
{"op":"mcm","clk":"1004741616","pt":1580636479682,"mc":[{"id":"1.168135792","rc":[{"trd":[[1.35,126.7]],"ltp":1.35,"tv":607.86,"id":2249229},{"trd":[[3.85,40.24]],"batl":[[0,3.85,1850.2]],"ltp":3.85,"tv":203.9,"id":5720747}],"tv":811.77}]}
{"op":"mcm","clk":"1004741757","pt":1580636482612,"mc":[{"id":"1.168135792","rc":[{"trd":[[1.35,131.73]],"ltp":1.35,"tv":612.89,"id":2249229},{"trd":[[3.85,41.99]],"batl":[[0,3.85,1848.45]],"ltp":3.85,"tv":205.66,"id":5720747}],"tv":818.56}]}
{"op":"mcm","clk":"1004741828","pt":1580636483285,"mc":[{"id":"1.168135792","rc":[{"trd":[[1.36,235.58]],"batb":[[0,1.36,151.91],[1,1.32,997.24],[2,1.31,992.23]],"batl":[[0,1.39,5],[1,1.49,725.43],[2,1.5,519.5]],"ltp":1.36,"tv":618.35,"id":2249229}],"tv":824.02}]}
{"op":"mcm","clk":"1004742134","pt":1580636486808,"mc":[{"id":"1.168135792","rc":[{"batb":[[1,1.26,18.17],[2,1.05,16.8]],"batl":[[1,1.75,510.77],[2,1.5,0]],"ltp":1.36,"tv":618.35,"id":2249229}]}]}
{"op":"mcm","clk":"1004742178","pt":1580636487726,"mc":[{"id":"1.168135792","rc":[{"batl":[[1,5.1,0]],"ltp":3.85,"tv":205.66,"id":5720747}]}]}
{"op":"mcm","clk":"1004742337","pt":1580636490816,"mc":[{"id":"1.168135792","rc":[{"batb":[[0,1.42,24.25],[1,1.05,16.8],[2,1.04,21]],"batl":[[1,5.7,111.25]],"ltp":3.85,"tv":205.66,"id":5720747}]}]}
{"op":"mcm","clk":"1004742368","pt":1580636491432,"mc":[{"id":"1.168135792","rc":[{"trd":[[1.35,231.73],[1.36,539.4]],"batb":[[0,1.32,1026.42],[1,1.31,992.35],[2,1.26,18.17]],"batl":[[0,1.36,819.06],[1,1.37,761.42],[2,1.39,5]],"ltp":1.35,"tv":1022.17,"id":2249229},{"trd":[[3.85,77.05]],"batl":[[0,3.85,1813.38]],"ltp":3.85,"tv":240.72,"id":5720747}],"tv":1262.9}]}
{"op":"mcm","clk":"1004742472","pt":1580636493808,"mc":[{"id":"1.168135792","rc":[{"batl":[[0,1.36,624.38]],"ltp":1.35,"tv":1022.17,"id":2249229}]}]}
{"op":"mcm","clk":"1004742560","pt":1580636495721,"mc":[{"id":"1.168135792","rc":[{"batb":[[0,1.32,1385.61]],"ltp":1.35,"tv":1022.17,"id":2249229}]}]}
{"op":"mcm","clk":"1004742616","pt":1580636496804,"mc":[{"id":"1.168135792","rc":[{"trd":[[1.36,562.57]],"batb":[[0,1.32,1026.42],[1,1.26,18.17],[2,1.05,16.8]],"batl":[[0,1.36,492.39]],"ltp":1.36,"tv":1045.34,"id":2249229},{"trd":[[3.75,8.4]],"ltp":3.75,"tv":249.12,"id":5720747}],"tv":1294.47}]}
{"op":"mcm","clk":"1004743014","pt":1580636501819,"mc":[{"id":"1.168135792","rc":[{"trd":[[1.35,345.32]],"batb":[[0,1.26,18.17],[1,1.05,16.8],[2,1.04,21]],"batl":[[0,1.39,20],[1,1.75,510.77],[2,1.39,0]],"ltp":1.35,"tv":1158.93,"id":2249229},{"trd":[[3.85,116.88]],"batl":[[0,3.85,1773.56]],"ltp":3.85,"tv":288.95,"id":5720747}],"tv":1447.88}]}
{"op":"mcm","clk":"1004743502","pt":1580636509760,"mc":[{"id":"1.168135792","rc":[{"batb":[[0,1.3,1158.65],[1,1.29,1072.52],[2,1.26,18.17]],"batl":[[1,1.43,871.49],[2,1.44,607.44]],"ltp":1.35,"tv":1158.93,"id":2249229}]}]}
{"op":"mcm","clk":"1004744039","pt":1580636518583,"mc":[{"id":"1.168135792","rc":[{"trd":[[1.35,355.32]],"ltp":1.35,"tv":1168.93,"id":2249229},{"trd":[[3.85,120.38]],"batl":[[0,3.85,1770.06]],"ltp":3.85,"tv":292.45,"id":5720747}],"tv":1461.39}]}
{"op":"mcm","clk":"1004744434","pt":1580636524792,"mc":[{"id":"1.168135792","rc":[{"trd":[[1.35,378.03]],"ltp":1.35,"tv":1191.65,"id":2249229},{"trd":[[3.85,128.35]],"batl":[[0,3.85,1762.09]],"ltp":3.85,"tv":300.42,"id":5720747}],"tv":1492.07}]}
{"op":"mcm","clk":"1004744604","pt":1580636527485,"mc":[{"id":"1.168135792","rc":[{"batb":[[0,1.26,18.17],[1,1.05,16.8],[2,1.04,21]],"batl":[[1,1.75,510.77],[2,1.44,0]],"ltp":1.35,"tv":1191.65,"id":2249229}]}]}
{"op":"mcm","clk":"1004744732","pt":1580636529672,"mc":[{"id":"1.168135792","rc":[{"batl":[[1,1.75,0]],"ltp":1.35,"tv":1191.65,"id":2249229}]}]}
{"op":"mcm","clk":"1004744795","pt":1580636530762,"mc":[{"id":"1.168135792","rc":[{"trd":[[1.35,483.9]],"ltp":1.35,"tv":1297.51,"id":2249229},{"trd":[[3.85,165.47]],"batl":[[0,3.85,1724.97]],"ltp":3.85,"tv":337.54,"id":5720747}],"tv":1635.05}]}
{"op":"mcm","clk":"1004745008","pt":1580636533794,"mc":[{"id":"1.168135792","rc":[{"trd":[[1.35,2336.69]],"batb":[[0,1.3,1176.18],[1,1.29,1072.57],[2,1.05,16.8]],"batl":[[1,1.64,594.42]],"ltp":1.35,"tv":3150.3,"id":2249229},{"trd":[[3.85,815.15]],"batl":[[0,5.7,111.25],[1,5.7,0]],"ltp":3.85,"tv":987.22,"id":5720747}],"tv":4137.52}]}
{"op":"mcm","clk":"1004745077","pt":1580636534782,"mc":[{"id":"1.168135792","rc":[{"batb":[[0,1.3,1011.31],[1,1.05,16.8],[2,1.04,21]],"ltp":1.35,"tv":3150.3,"id":2249229}]}]}
{"op":"mcm","clk":"1004745239","pt":1580636536799,"mc":[{"id":"1.168135792","rc":[{"batb":[[1,1.24,18.17],[2,1.05,16.8]],"ltp":1.35,"tv":3150.3,"id":2249229}]}]}
{"op":"mcm","clk":"1004745467","pt":1580636539795,"mc":[{"id":"1.168135792","rc":[{"batb":[[0,1.33,107.45],[1,1.31,758.56],[2,1.3,1011.31]],"batl":[[0,1.34,464.09],[1,1.35,808.17],[2,1.39,20]],"ltp":1.35,"tv":3150.3,"id":2249229}]}]}
{"op":"mcm","clk":"1004745666","pt":1580636542696,"mc":[{"id":"1.168135792","rc":[{"batb":[[0,1.31,758.56],[1,1.3,1011.31],[2,1.24,18.17]],"ltp":1.35,"tv":3150.3,"id":2249229}]}]}
{"op":"mcm","clk":"1004745728","pt":1580636543783,"mc":[{"id":"1.168135792","rc":[{"batb":[[0,3.7,32.38],[1,1.42,24.25],[2,1.05,16.8]],"ltp":3.85,"tv":987.22,"id":5720747}]}]}
{"op":"mcm","clk":"1004745791","pt":1580636544714,"mc":[{"id":"1.168135792","rc":[{"trd":[[1.34,1.58]],"batb":[[0,1.24,18.17],[1,1.05,16.8],[2,1.04,21]],"batl":[[0,1.39,20],[1,1.64,594.42],[2,1.39,0]],"ltp":1.34,"tv":3151.88,"id":2249229}],"tv":4139.1}]}
{"op":"mcm","clk":"1004745838","pt":1580636545694,"mc":[{"id":"1.168135792","rc":[{"batb":[[0,1.34,106.65],[1,1.24,18.17],[2,1.05,16.8]],"ltp":1.34,"tv":3151.88,"id":2249229}]}]}
{"op":"mcm","clk":"1004746163","pt":1580636552724,"mc":[{"id":"1.168135792","rc":[{"trd":[[1.34,1.89]],"batb":[[0,1.34,106.49]],"ltp":1.34,"tv":3152.19,"id":2249229}],"tv":4139.42}]}
{"op":"mcm","clk":"1004746208","pt":1580636553818,"mc":[{"id":"1.168135792","rc":[{"batb":[[1,3.65,65.97],[2,1.42,24.25]],"ltp":3.85,"tv":987.22,"id":5720747}]}]}
{"op":"mcm","clk":"1004746253","pt":1580636554805,"mc":[{"id":"1.168135792","rc":[{"batb":[[1,1.29,1353.68],[2,1.28,1112.49]],"batl":[[0,1.38,667.68],[1,1.39,723.26],[2,1.64,594.42]],"ltp":1.34,"tv":3152.19,"id":2249229}]}]}
{"op":"mcm","clk":"1004746410","pt":1580636557800,"mc":[{"id":"1.168135792","rc":[{"batb":[[1,1.3,582.77],[2,1.29,1353.68]],"ltp":1.34,"tv":3152.19,"id":2249229}]}]}
{"op":"mcm","clk":"1004746568","pt":1580636561003,"mc":[{"id":"1.168135792","rc":[{"trd":[[3.7,4.54]],"batb":[[0,3.7,30.1]],"ltp":3.7,"tv":991.76,"id":5720747}],"tv":4143.96}]}
{"op":"mcm","clk":"1004746624","pt":1580636562655,"mc":[{"id":"1.168135792","rc":[{"batl":[[0,1.39,20],[1,1.64,594.42],[2,1.64,0]],"ltp":1.34,"tv":3152.19,"id":2249229}]}]}
{"op":"mcm","clk":"1004746686","pt":1580636563735,"mc":[{"id":"1.168135792","rc":[{"batb":[[0,1.3,582.77],[1,1.29,1353.68],[2,1.28,1112.49]],"ltp":1.34,"tv":3152.19,"id":2249229}]}]}
{"op":"mcm","clk":"1004746737","pt":1580636564719,"mc":[{"id":"1.168135792","rc":[{"batl":[[0,1.33,50],[1,1.39,20],[2,1.64,594.42]],"ltp":1.34,"tv":3152.19,"id":2249229}]}]}
{"op":"mcm","clk":"1004746766","pt":1580636565540,"mc":[{"id":"1.168135792","rc":[{"batl":[[1,1.34,70],[2,1.39,20]],"ltp":1.34,"tv":3152.19,"id":2249229}]}]}
{"op":"mcm","clk":"1004746819","pt":1580636566630,"mc":[{"id":"1.168135792","rc":[{"batb":[[0,1.31,108.94]],"ltp":1.34,"tv":3152.19,"id":2249229},{"batb":[[0,3.95,36.97],[1,3.7,30.1],[2,3.65,65.97]],"ltp":3.7,"tv":991.76,"id":5720747}]}]}
{"op":"mcm","clk":"1004746875","pt":1580636567720,"mc":[{"id":"1.168135792","rc":[{"batl":[[0,1.33,1029.49],[1,1.34,899.58]],"ltp":1.34,"tv":3152.19,"id":2249229}]}]}
{"op":"mcm","clk":"1004746977","pt":1580636569628,"mc":[{"id":"1.168135792","rc":[{"trd":[[1.33,30.08]],"batl":[[0,1.33,979.49],[1,1.34,829.58]],"ltp":1.33,"tv":3182.27,"id":2249229},{"trd":[[4,10]],"batb":[[0,3.7,30.1],[1,3.65,65.97],[2,1.42,24.25]],"ltp":4.0,"tv":1001.76,"id":5720747}],"tv":4184.04}]}
{"op":"mcm","clk":"1004747052","pt":1580636571339,"mc":[{"id":"1.168135792","rc":[{"batb":[[0,1.42,24.25],[1,1.05,16.8],[2,1.04,21]],"ltp":4.0,"tv":1001.76,"id":5720747}]}]}
{"op":"mcm","clk":"1004747130","pt":1580636572739,"mc":[{"id":"1.168135792","rc":[{"trd":[[1.31,39.84]],"batb":[[0,1.31,89.02]],"ltp":1.31,"tv":3222.11,"id":2249229}],"tv":4223.88}]}
{"op":"mcm","clk":"1004747198","pt":1580636573728,"mc":[{"id":"1.168135792","rc":[{"batb":[[0,3.85,61.34],[1,1.42,24.25],[2,1.05,16.8]],"ltp":4.0,"tv":1001.76,"id":5720747}]}]}
{"op":"mcm","clk":"1004747312","pt":1580636575744,"mc":[{"id":"1.168135792","rc":[{"batb":[[1,3.8,62.44],[2,1.42,24.25]],"ltp":4.0,"tv":1001.76,"id":5720747}]}]}
{"op":"mcm","clk":"1004747553","pt":1580636580649,"mc":[{"id":"1.168135792","rc":[{"batb":[[1,1.29,527.07]],"batl":[[0,1.39,20],[1,1.64,594.42],[2,1.39,0]],"ltp":1.31,"tv":3222.11,"id":2249229}]}]}
{"op":"mcm","clk":"1004747752","pt":1580636584470,"mc":[{"id":"1.168135792","rc":[{"trd":[[1.31,47.84]],"batb":[[0,1.31,85.02]],"ltp":1.31,"tv":3230.11,"id":2249229}],"tv":4231.88}]}
{"op":"mcm","clk":"1004747932","pt":1580636587675,"mc":[{"id":"1.168135792","rc":[{"batl":[[0,1.35,1190.64],[1,1.36,771.05],[2,1.39,20]],"ltp":1.31,"tv":3230.11,"id":2249229}]}]}
{"op":"mcm","clk":"1004748049","pt":1580636589793,"mc":[{"id":"1.168135792","rc":[{"trd":[[1.31,83.21]],"batb":[[0,1.31,67.33]],"ltp":1.31,"tv":3265.48,"id":2249229}],"tv":4267.25}]}
{"op":"mcm","clk":"1004748102","pt":1580636590678,"mc":[{"id":"1.168135792","rc":[{"batb":[[1,1.27,647.52],[2,1.26,672.43]],"batl":[[0,1.39,20],[1,1.64,594.42],[2,1.39,0]],"ltp":1.31,"tv":3265.48,"id":2249229}]}]}
{"op":"mcm","clk":"1004748301","pt":1580636593576,"mc":[{"id":"1.168135792","rc":[{"batb":[[0,1.27,647.52],[1,1.26,672.43],[2,1.24,18.17]],"ltp":1.31,"tv":3265.48,"id":2249229}]}]}
{"op":"mcm","clk":"1004748353","pt":1580636594667,"mc":[{"id":"1.168135792","rc":[{"batb":[[0,1.24,18.17],[1,1.05,16.8],[2,1.04,21]],"ltp":1.31,"tv":3265.48,"id":2249229}]}]}
{"op":"mcm","clk":"1004748449","pt":1580636596683,"mc":[{"id":"1.168135792","rc":[{"batb":[[0,1.3,67.85],[1,1.29,528.24],[2,1.28,1097.96]],"batl":[[0,1.32,872.38],[1,1.33,863.68],[2,1.39,20]],"ltp":1.31,"tv":3265.48,"id":2249229}]}]}
{"op":"mcm","clk":"1004748555","pt":1580636598807,"mc":[{"id":"1.168135792","rc":[{"batb":[[0,1.42,24.25],[1,1.05,16.8],[2,1.04,21]],"ltp":4.0,"tv":1001.76,"id":5720747}]}]}
{"op":"mcm","clk":"1004748708","pt":1580636601692,"mc":[{"id":"1.168135792","rc":[{"batb":[[2,1.28,1102.96]],"ltp":1.31,"tv":3265.48,"id":2249229}]}]}
{"op":"mcm","clk":"1004748760","pt":1580636602672,"mc":[{"id":"1.168135792","rc":[{"trd":[[1.32,47.04]],"batl":[[0,1.32,825.34]],"ltp":1.32,"tv":3312.52,"id":2249229},{"trd":[[4.1,15.14]],"batb":[[0,3.9,60.29],[1,1.42,24.25],[2,1.05,16.8]],"ltp":4.1,"tv":1016.91,"id":5720747}],"tv":4329.43}]}
{"op":"mcm","clk":"1004748808","pt":1580636603602,"mc":[{"id":"1.168135792","rc":[{"batb":[[1,3.85,61.34],[2,1.42,24.25]],"ltp":4.1,"tv":1016.91,"id":5720747}]}]}
{"op":"mcm","clk":"1004748946","pt":1580636606685,"mc":[{"id":"1.168135792","rc":[{"batb":[[0,1.29,646.05],[1,1.28,1102.96],[2,1.26,672.43]],"ltp":1.32,"tv":3312.52,"id":2249229}]}]}
{"op":"mcm","clk":"1004749106","pt":1580636609727,"mc":[{"id":"1.168135792","rc":[{"trd":[[1.32,180.68]],"batb":[[0,1.26,672.43],[1,1.25,699.32],[2,1.05,16.8]],"batl":[[0,1.39,20],[1,1.64,594.42],[2,1.39,0]],"ltp":1.32,"tv":3446.16,"id":2249229}],"tv":4463.07}]}
{"op":"mcm","clk":"1004749252","pt":1580636612813,"mc":[{"id":"1.168135792","rc":[{"batb":[[0,1.31,5],[1,1.26,672.43],[2,1.25,699.32]],"ltp":1.32,"tv":3446.16,"id":2249229}]}]}
{"op":"mcm","clk":"1004749888","pt":1580636626720,"mc":[{"id":"1.168135792","rc":[{"trd":[[1.31,90.49]],"batb":[[0,1.31,1.36]],"ltp":1.31,"tv":3453.44,"id":2249229}],"tv":4470.35}]}
{"op":"mcm","clk":"1004749911","pt":1580636627747,"mc":[{"id":"1.168135792","rc":[{"batl":[[0,1.37,978.24],[1,1.38,721.77],[2,1.39,20]],"ltp":1.31,"tv":3453.44,"id":2249229}]}]}
{"op":"mcm","clk":"1004750137","pt":1580636633750,"mc":[{"id":"1.168135792","rc":[{"trd":[[1.31,93.21]],"batb":[[0,1.26,672.43],[1,1.25,699.32],[2,1.23,987.25]],"batl":[[0,1.31,18.64],[1,1.37,978.24],[2,1.38,721.77]],"ltp":1.31,"tv":3456.16,"id":2249229}],"tv":4473.07}]}
{"op":"mcm","clk":"1004750240","pt":1580636636626,"mc":[{"id":"1.168135792","rc":[{"trd":[[1.31,130.49]],"batb":[[0,1.32,41.36],[1,1.26,672.43],[2,1.25,699.32]],"batl":[[0,1.37,978.24],[1,1.38,721.77],[2,1.39,20]],"ltp":1.31,"tv":3493.44,"id":2249229}],"tv":4510.35}]}
{"op":"mcm","clk":"1004750472","pt":1580636642739,"mc":[{"id":"1.168135792","rc":[{"batb":[[1,1.27,259.25],[2,1.26,672.43]],"ltp":1.31,"tv":3493.44,"id":2249229}]}]}
{"op":"mcm","clk":"1004750585","pt":1580636645780,"mc":[{"id":"1.168135792","rc":[{"batl":[[0,1.39,20],[1,1.64,594.42],[2,1.39,0]],"ltp":1.31,"tv":3493.44,"id":2249229}]}]}
{"op":"mcm","clk":"1004750778","pt":1580636650762,"mc":[{"id":"1.168135792","rc":[{"batb":[[0,1.27,259.25],[1,1.26,672.43],[2,1.25,699.32]],"ltp":1.31,"tv":3493.44,"id":2249229}]}]}
{"op":"mcm","clk":"1004750831","pt":1580636651792,"mc":[{"id":"1.168135792","rc":[{"batl":[[0,7,95.49]],"ltp":4.1,"tv":1016.91,"id":5720747}]}]}
{"op":"mcm","clk":"1004750899","pt":1580636653755,"mc":[{"id":"1.168135792","rc":[{"batl":[[0,1.37,928.16],[1,1.38,721.77],[2,1.39,20]],"ltp":1.31,"tv":3493.44,"id":2249229}]}]}
{"op":"mcm","clk":"1004750995","pt":1580636656798,"mc":[{"id":"1.168135792","rc":[{"batb":[[0,1.34,171],[1,1.27,259.25],[2,1.26,672.43]],"ltp":1.31,"tv":3493.44,"id":2249229}]}]}
{"op":"mcm","clk":"1004751135","pt":1580636659685,"mc":[{"id":"1.168135792","rc":[{"batb":[[2,1.23,1043.29]],"ltp":1.31,"tv":3493.44,"id":2249229}]}]}
{"op":"mcm","clk":"1004751179","pt":1580636660763,"mc":[{"id":"1.168135792","rc":[{"batb":[[1,1.23,1043.29],[2,1.22,1477.27]],"ltp":1.31,"tv":3493.44,"id":2249229}]}]}
{"op":"mcm","clk":"1004751213","pt":1580636661791,"mc":[{"id":"1.168135792","rc":[{"trd":[[1.34,172.89]],"batb":[[0,1.23,1043.29],[1,1.22,1477.27],[2,1.06,28]],"batl":[[0,1.33,37.86],[1,1.37,928.16],[2,1.38,721.77]],"ltp":1.34,"tv":3664.44,"id":2249229},{"trd":[[3.95,58.01]],"batb":[[0,3.95,1.25],[1,3.9,60.29],[2,3.85,61.34]],"ltp":3.95,"tv":1074.92,"id":5720747}],"tv":4739.37}]}
{"op":"mcm","clk":"1004751261","pt":1580636662775,"mc":[{"id":"1.168135792","rc":[{"batl":[[0,1.37,928.16],[1,1.38,721.77],[2,1.39,20]],"ltp":1.34,"tv":3664.44,"id":2249229}]}]}
{"op":"mcm","clk":"1004751388","pt":1580636665686,"mc":[{"id":"1.168135792","rc":[{"batb":[[0,1.42,24.25],[1,1.05,16.8],[2,1.04,21]],"ltp":3.95,"tv":1074.92,"id":5720747}]}]}
{"op":"mcm","clk":"1004751461","pt":1580636667380,"mc":[{"id":"1.168135792","rc":[{"batb":[[0,1.3,182.74],[1,1.23,1043.29],[2,1.22,1477.27]],"ltp":1.34,"tv":3664.44,"id":2249229}]}]}
{"op":"mcm","clk":"1004751526","pt":1580636668773,"mc":[{"id":"1.168135792","rc":[{"trd":[[1.35,2346.09]],"batl":[[0,1.33,65.3],[1,1.37,928.16],[2,1.38,721.77]],"ltp":1.35,"tv":3673.84,"id":2249229}],"tv":4748.77}]}
{"op":"mcm","clk":"1004751574","pt":1580636669808,"mc":[{"id":"1.168135792","rc":[{"batb":[[0,3.75,63.57],[1,1.42,24.25],[2,1.05,16.8]],"ltp":3.95,"tv":1074.92,"id":5720747}]}]}
{"op":"mcm","clk":"1004751708","pt":1580636672794,"mc":[{"id":"1.168135792","rc":[{"batb":[[1,1.24,728.46],[2,1.23,1043.29]],"ltp":1.35,"tv":3673.84,"id":2249229}]}]}
{"op":"mcm","clk":"1004751922","pt":1580636677744,"mc":[{"id":"1.168135792","rc":[{"batl":[[0,1.37,928.16],[1,1.38,721.77],[2,1.39,20]],"ltp":1.35,"tv":3673.84,"id":2249229}]}]}
{"op":"mcm","clk":"1004752060","pt":1580636680737,"mc":[{"id":"1.168135792","rc":[{"batb":[[2,1.23,919.15]],"ltp":1.35,"tv":3673.84,"id":2249229},{"batb":[[0,4,35],[1,3.75,63.57],[2,1.42,24.25]],"ltp":3.95,"tv":1074.92,"id":5720747}]}]}
{"op":"mcm","clk":"1004752235","pt":1580636684546,"mc":[{"id":"1.168135792","rc":[{"batb":[[2,1.06,28]],"batl":[[0,1.39,20],[1,1.64,594.42],[2,1.39,0]],"ltp":1.35,"tv":3673.84,"id":2249229}]}]}
{"op":"mcm","clk":"1004752435","pt":1580636689535,"mc":[{"id":"1.168135792","rc":[{"batb":[[1,1.42,24.25],[2,1.05,16.8]],"ltp":3.95,"tv":1074.92,"id":5720747}]}]}
{"op":"mcm","clk":"1004752523","pt":1580636691750,"mc":[{"id":"1.168135792","rc":[{"batb":[[0,1.33,789.22],[1,1.32,933.84],[2,1.3,182.74]],"batl":[[0,1.37,1023.89],[1,1.38,722.14],[2,1.39,20]],"ltp":1.35,"tv":3673.84,"id":2249229},{"trd":[[4,14.26]],"batb":[[0,4,32.87]],"ltp":4.0,"tv":1079.18,"id":5720747}],"tv":4753.02}]}
{"op":"mcm","clk":"1004752561","pt":1580636692724,"mc":[{"id":"1.168135792","rc":[{"trd":[[1.34,177.63]],"batb":[[2,1.06,28]],"ltp":1.34,"tv":3678.58,"id":2249229},{"trd":[[4,15.85]],"batb":[[0,4,31.28]],"ltp":4.0,"tv":1080.77,"id":5720747}],"tv":4759.35}]}
{"op":"mcm","clk":"1004752610","pt":1580636693764,"mc":[{"id":"1.168135792","rc":[{"batl":[[0,5.7,111.25]],"ltp":4.0,"tv":1080.77,"id":5720747}]}]}
{"op":"mcm","clk":"1004752681","pt":1580636695770,"mc":[{"id":"1.168135792","rc":[{"trd":[[1.34,271.01]],"batb":[[0,1.34,83.9],[1,1.33,789.22],[2,1.32,933.84]],"ltp":1.34,"tv":3771.96,"id":2249229},{"trd":[[4,47.13]],"batb":[[0,1.42,24.25],[1,1.05,16.8],[2,1.04,21]],"ltp":4.0,"tv":1112.05,"id":5720747}],"tv":4884.01}]}
{"op":"mcm","clk":"1004752797","pt":1580636698556,"mc":[{"id":"1.168135792","rc":[{"trd":[[1.33,53.7],[1.34,354.92]],"batb":[[0,1.33,765.6],[1,1.32,933.84],[2,1.28,624.4]],"ltp":1.33,"tv":3879.49,"id":2249229},{"trd":[[3.95,86.48],[4.1,22.81]],"ltp":4.1,"tv":1148.17,"id":5720747}],"tv":5027.66}]}
{"op":"mcm","clk":"1004752931","pt":1580636700777,"mc":[{"id":"1.168135792","rc":[{"batb":[[0,3.4,72.85],[1,1.42,24.25],[2,1.05,16.8]],"ltp":4.1,"tv":1148.17,"id":5720747}]}]}
{"op":"mcm","clk":"1004753296","pt":1580636705758,"mc":[{"id":"1.168135792","rc":[{"batb":[[0,1.28,624.4],[1,1.06,28],[2,1.05,50.39]],"batl":[[0,1.39,20],[1,1.64,594.42],[2,1.39,0]],"ltp":1.33,"tv":3879.49,"id":2249229}]}]}
{"op":"mcm","clk":"1004753630","pt":1580636712772,"mc":[{"id":"1.168135792","rc":[{"batb":[[0,1.28,1269.73],[1,1.27,1149.01],[2,1.06,28]],"batl":[[1,1.41,955.18],[2,1.42,637.42]],"ltp":1.33,"tv":3879.49,"id":2249229}]}]}
{"op":"mcm","clk":"1004754036","pt":1580636721817,"mc":[{"id":"1.168135792","rc":[{"batb":[[0,1.28,624.4],[1,1.06,28],[2,1.05,50.39]],"batl":[[1,1.64,594.42],[2,1.42,0]],"ltp":1.33,"tv":3879.49,"id":2249229}]}]}
{"op":"mcm","clk":"1004754180","pt":1580636724712,"mc":[{"id":"1.168135792","rc":[{"batb":[[0,1.32,735.47],[1,1.31,970.84],[2,1.28,624.4]],"batl":[[0,1.36,1178.98],[1,1.37,744.61],[2,1.39,20]],"ltp":1.33,"tv":3879.49,"id":2249229}]}]}
{"op":"mcm","clk":"1004754224","pt":1580636725701,"mc":[{"id":"1.168135792","rc":[{"batb":[[0,1.28,624.4],[1,1.06,28],[2,1.05,50.39]],"batl":[[0,1.39,20],[1,1.64,594.42],[2,1.39,0]],"ltp":1.33,"tv":3879.49,"id":2249229}]}]}
{"op":"mcm","clk":"1004754652","pt":1580636735648,"mc":[{"id":"1.168135792","rc":[{"batl":[[1,1.41,873.88],[2,1.42,637.47]],"ltp":1.33,"tv":3879.49,"id":2249229},{"batb":[[0,1.42,24.25],[1,1.05,16.8],[2,1.04,21]],"ltp":4.1,"tv":1148.17,"id":5720747}]}]}
{"op":"mcm","clk":"1004754701","pt":1580636736640,"mc":[{"id":"1.168135792","rc":[{"batb":[[0,1.37,556.58],[1,1.36,801.06],[2,1.28,624.4]],"ltp":1.33,"tv":3879.49,"id":2249229}]}]}
{"op":"mcm","clk":"1004754855","pt":1580636739626,"mc":[{"id":"1.168135792","rc":[{"trd":[[1.37,2.39]],"batb":[[0,1.37,554.19]],"ltp":1.37,"tv":3881.88,"id":2249229},{"trd":[[3.75,9.28]],"ltp":3.75,"tv":1149.05,"id":5720747}],"tv":5030.93}]}
{"op":"mcm","clk":"1004754899","pt":1580636740752,"mc":[{"id":"1.168135792","rc":[{"batl":[[0,5.1,123.37]],"ltp":3.75,"tv":1149.05,"id":5720747}]}]}
{"op":"mcm","clk":"1004755070","pt":1580636744630,"mc":[{"id":"1.168135792","rc":[{"batb":[[2,1.06,28]],"ltp":1.37,"tv":3881.88,"id":2249229}]}]}
{"op":"mcm","clk":"1004755086","pt":1580636745343,"mc":[{"id":"1.168135792","rc":[{"batb":[[2,1.33,529.79]],"ltp":1.37,"tv":3881.88,"id":2249229}]}]}
{"op":"mcm","clk":"1004755144","pt":1580636746635,"mc":[{"id":"1.168135792","rc":[{"batb":[[0,3.25,77.7],[1,1.42,24.25],[2,1.05,16.8]],"ltp":3.75,"tv":1149.05,"id":5720747}]}]}
{"op":"mcm","clk":"1004755261","pt":1580636749669,"mc":[{"id":"1.168135792","rc":[{"batb":[[0,1.33,529.79],[1,1.06,28],[2,1.05,50.39]],"batl":[[1,1.64,594.42],[2,1.42,0]],"ltp":1.37,"tv":3881.88,"id":2249229}]}]}
{"op":"mcm","clk":"1004755392","pt":1580636752555,"mc":[{"id":"1.168135792","rc":[{"batb":[[0,1.33,1230.78],[1,1.32,931.87],[2,1.06,28]],"batl":[[1,1.44,938.3],[2,1.45,583.29]],"ltp":1.37,"tv":3881.88,"id":2249229}]}]}
{"op":"mcm","clk":"1004755442","pt":1580636753741,"mc":[{"id":"1.168135792","rc":[{"trd":[[1.39,17.8]],"batl":[[0,1.39,9.78]],"ltp":1.39,"tv":3892.1,"id":2249229},{"trd":[[3.55,4]],"ltp":3.55,"tv":1153.05,"id":5720747}],"tv":5045.15}]}
{"op":"mcm","clk":"1004755672","pt":1580636758795,"mc":[{"id":"1.168135792","rc":[{"batb":[[0,1.33,529.79],[1,1.06,28],[2,1.05,50.39]],"batl":[[1,1.64,594.42],[2,1.45,0]],"ltp":1.39,"tv":3892.1,"id":2249229}]}]}
{"op":"mcm","clk":"1004755900","pt":1580636763767,"mc":[{"id":"1.168135792","rc":[{"batb":[[0,1.34,205.88],[1,1.33,529.79],[2,1.06,28]],"ltp":1.39,"tv":3892.1,"id":2249229}]}]}
{"op":"mcm","clk":"1004756049","pt":1580636767775,"mc":[{"id":"1.168135792","rc":[{"batb":[[1,1.33,1120.16],[2,1.32,931.87]],"batl":[[1,1.43,436.78],[2,1.44,606.37]],"ltp":1.39,"tv":3892.1,"id":2249229}]}]}
{"op":"mcm","clk":"1004756120","pt":1580636769780,"mc":[{"id":"1.168135792","rc":[{"batb":[[0,1.42,24.25],[1,1.05,16.8],[2,1.04,21]],"ltp":3.55,"tv":1153.05,"id":5720747}]}]}
{"op":"mcm","clk":"1004756154","pt":1580636770806,"mc":[{"id":"1.168135792","rc":[{"batb":[[1,1.33,529.79],[2,1.06,28]],"ltp":1.39,"tv":3892.1,"id":2249229}]}]}
{"op":"mcm","clk":"1004756290","pt":1580636773810,"mc":[{"id":"1.168135792","rc":[{"batb":[[2,1.31,5]],"ltp":1.39,"tv":3892.1,"id":2249229},{"batl":[[0,4.7,131.39]],"ltp":3.55,"tv":1153.05,"id":5720747}]}]}
{"op":"mcm","clk":"1004756368","pt":1580636775817,"mc":[{"id":"1.168135792","rc":[{"trd":[[1.39,37.36]],"batb":[[0,1.39,868.58],[1,1.38,752.83],[2,1.34,205.88]],"batl":[[0,1.43,436.78],[1,1.44,606.37],[2,1.64,594.42]],"ltp":1.39,"tv":3911.66,"id":2249229}],"tv":5064.71}]}
{"op":"mcm","clk":"1004756601","pt":1580636780721,"mc":[{"id":"1.168135792","rc":[{"batb":[[2,1.36,485.64]],"ltp":1.39,"tv":3911.66,"id":2249229}]}]}
{"op":"mcm","clk":"1004756673","pt":1580636782632,"mc":[{"id":"1.168135792","rc":[{"batb":[[0,3.15,81.32],[1,1.42,24.25],[2,1.05,16.8]],"ltp":3.55,"tv":1153.05,"id":5720747}]}]}
{"op":"mcm","clk":"1004756709","pt":1580636783613,"mc":[{"id":"1.168135792","rc":[{"batb":[[1,3.1,83.25],[2,1.42,24.25]],"ltp":3.55,"tv":1153.05,"id":5720747}]}]}
{"op":"mcm","clk":"1004756746","pt":1580636784638,"mc":[{"id":"1.168135792","rc":[{"batb":[[0,1.36,485.64],[1,1.34,205.88],[2,1.31,5]],"batl":[[0,1.64,594.42],[1,1.44,0],[2,1.64,0]],"ltp":1.39,"tv":3911.66,"id":2249229}]}]}
{"op":"mcm","clk":"1004757126","pt":1580636792754,"mc":[{"id":"1.168135792","rc":[{"batb":[[0,1.37,811.11],[1,1.36,1291.57],[2,1.34,205.88]],"batl":[[0,1.45,693.42],[1,1.46,639.81],[2,1.64,594.42]],"ltp":1.39,"tv":3911.66,"id":2249229}]}]}
{"op":"mcm","clk":"1004757223","pt":1580636795536,"mc":[{"id":"1.168135792","rc":[{"batb":[[0,1.36,485.64],[1,1.34,205.88],[2,1.31,5]],"batl":[[0,1.4,10],[1,1.64,594.42],[2,1.64,0]],"ltp":1.39,"tv":3911.66,"id":2249229}]}]}
{"op":"mcm","clk":"1004757261","pt":1580636796560,"mc":[{"id":"1.168135792","rc":[{"trd":[[1.36,662.57]],"batb":[[0,1.36,435.64]],"ltp":1.36,"tv":4011.66,"id":2249229}],"tv":5164.71}]}
{"op":"mcm","clk":"1004757299","pt":1580636797752,"mc":[{"id":"1.168135792","rc":[{"batb":[[0,1.42,24.25],[1,1.05,16.8],[2,1.04,21]],"ltp":3.55,"tv":1153.05,"id":5720747}]}]}
{"op":"mcm","clk":"1004757342","pt":1580636798731,"mc":[{"id":"1.168135792","rc":[{"trd":[[1.36,1533.82]],"batb":[[0,1.34,205.88],[1,1.31,5],[2,1.06,28]],"batl":[[0,1.36,64.39],[1,1.4,10],[2,1.64,594.42]],"ltp":1.36,"tv":4882.91,"id":2249229}],"tv":6035.96}]}
{"op":"mcm","clk":"1004757377","pt":1580636799660,"mc":[{"id":"1.168135792","rc":[{"batb":[[0,3.25,77.7],[1,1.42,24.25],[2,1.05,16.8]],"ltp":3.55,"tv":1153.05,"id":5720747}]}]}
{"op":"mcm","clk":"1004757428","pt":1580636800645,"mc":[{"id":"1.168135792","rc":[{"trd":[[1.36,1662.6],[1.4,68.46]],"batb":[[0,1.41,434.85],[1,1.4,699.92],[2,1.37,124.79]],"batl":[[0,1.45,695.73],[1,1.46,570.08]],"ltp":1.4,"tv":5031.69,"id":2249229},{"batb":[[0,1.42,24.25],[1,1.05,16.8],[2,1.04,21]],"ltp":3.55,"tv":1153.05,"id":5720747}],"tv":6184.74}]}
{"op":"mcm","clk":"1004757532","pt":1580636802761,"mc":[{"id":"1.168135792","rc":[{"batb":[[0,1.42,5.91],[1,1.41,434.85],[2,1.4,699.92]],"ltp":1.4,"tv":5031.69,"id":2249229}]}]}
{"op":"mcm","clk":"1004757555","pt":1580636803539,"mc":[{"id":"1.168135792","rc":[{"batb":[[0,1.41,434.85],[1,1.4,699.92],[2,1.31,5]],"ltp":1.4,"tv":5031.69,"id":2249229},{"batl":[[0,3.7,37.86],[1,4.7,131.39]],"ltp":3.55,"tv":1153.05,"id":5720747}]}]}
{"op":"mcm","clk":"1004757597","pt":1580636804766,"mc":[{"id":"1.168135792","rc":[{"batl":[[0,4.7,131.39],[1,4.7,0]],"ltp":3.55,"tv":1153.05,"id":5720747}]}]}
{"op":"mcm","clk":"1004757662","pt":1580636806777,"mc":[{"id":"1.168135792","rc":[{"trd":[[1.41,869.73]],"batb":[[0,1.4,699.92],[1,1.06,28],[2,1.05,50.39]],"batl":[[0,1.41,95.65],[1,1.45,695.73],[2,1.46,570.08]],"ltp":1.41,"tv":5901.42,"id":2249229}],"tv":7054.47}]}
{"op":"mcm","clk":"1004757705","pt":1580636807759,"mc":[{"id":"1.168135792","rc":[{"batb":[[1,1.38,460.08],[2,1.06,28]],"ltp":1.41,"tv":5901.42,"id":2249229}]}]}
{"op":"mcm","clk":"1004757736","pt":1580636808479,"mc":[{"id":"1.168135792","rc":[{"trd":[[1.4,80.96]],"batb":[[0,1.4,687.42]],"ltp":1.4,"tv":5913.92,"id":2249229},{"trd":[[3.5,5]],"ltp":3.5,"tv":1158.05,"id":5720747}],"tv":7071.97}]}
{"op":"mcm","clk":"1004757786","pt":1580636809672,"mc":[{"id":"1.168135792","rc":[{"batb":[[0,2.9,92.02],[1,1.42,24.25],[2,1.05,16.8]],"ltp":3.5,"tv":1158.05,"id":5720747}]}]}
{"op":"mcm","clk":"1004757831","pt":1580636810759,"mc":[{"id":"1.168135792","rc":[{"batb":[[0,1.38,460.08],[1,1.35,5]],"batl":[[1,1.64,594.42],[2,1.65,1.68]],"ltp":1.4,"tv":5913.92,"id":2249229}]}]}
{"op":"mcm","clk":"1004758171","pt":1580636818771,"mc":[{"id":"1.168135792","rc":[{"batb":[[1,1.36,951.57],[2,1.35,843.79]],"batl":[[1,1.56,603.59],[2,1.57,431.57]],"ltp":1.4,"tv":5913.92,"id":2249229}]}]}
{"op":"mcm","clk":"1004758269","pt":1580636820573,"mc":[{"id":"1.168135792","rc":[{"batb":[[1,1.37,472.52],[2,1.36,951.57]],"ltp":1.4,"tv":5913.92,"id":2249229}]}]}
{"op":"mcm","clk":"1004758321","pt":1580636821784,"mc":[{"id":"1.168135792","rc":[{"batb":[[0,1.37,472.52],[1,1.36,951.57],[2,1.35,843.79]],"ltp":1.4,"tv":5913.92,"id":2249229}]}]}
{"op":"mcm","clk":"1004758503","pt":1580636825708,"mc":[{"id":"1.168135792","rc":[{"batb":[[0,1.37,472.54]],"ltp":1.4,"tv":5913.92,"id":2249229},{"batb":[[0,1.42,24.25],[1,1.05,16.8],[2,1.04,21]],"ltp":3.5,"tv":1158.05,"id":5720747}]}]}
{"op":"mcm","clk":"1004758613","pt":1580636827787,"mc":[{"id":"1.168135792","rc":[{"batb":[[0,2.82,96.06],[1,2.8,97.13],[2,1.42,24.25]],"ltp":3.5,"tv":1158.05,"id":5720747}]}]}
{"op":"mcm","clk":"1004758678","pt":1580636829791,"mc":[{"id":"1.168135792","rc":[{"batl":[[0,1.41,33.54]],"ltp":1.4,"tv":5913.92,"id":2249229}]}]}
{"op":"mcm","clk":"1004758867","pt":1580636833597,"mc":[{"id":"1.168135792","rc":[{"batl":[[1,1.43,62.11],[2,1.56,603.59]],"ltp":1.4,"tv":5913.92,"id":2249229}]}]}
{"op":"mcm","clk":"1004759123","pt":1580636838813,"mc":[{"id":"1.168135792","rc":[{"trd":[[1.37,78.07],[1.4,81.01]],"batb":[[0,1.37,434.68]],"ltp":1.37,"tv":5989.64,"id":2249229}],"tv":7147.69}]}
{"op":"mcm","clk":"1004759362","pt":1580636843818,"mc":[{"id":"1.168135792","rc":[{"batl":[[1,1.56,603.59],[2,1.57,431.57]],"ltp":1.37,"tv":5989.64,"id":2249229}]}]}
{"op":"mcm","clk":"1004759402","pt":1580636844647,"mc":[{"id":"1.168135792","rc":[{"batb":[[1,1.35,5],[2,1.06,28]],"batl":[[0,1.56,603.59],[1,1.57,431.57],[2,1.65,1.68]],"ltp":1.37,"tv":5989.64,"id":2249229}]}]}
{"op":"mcm","clk":"1004759452","pt":1580636845731,"mc":[{"id":"1.168135792","rc":[{"batb":[[0,1.43,246.19],[1,1.37,434.68],[2,1.35,5]],"ltp":1.37,"tv":5989.64,"id":2249229},{"batb":[[0,1.42,24.25],[1,1.05,16.8],[2,1.04,21]],"ltp":3.5,"tv":1158.05,"id":5720747}]}]}
{"op":"mcm","clk":"1004759636","pt":1580636848739,"mc":[{"id":"1.168135792","rc":[{"batl":[[0,3.75,165.38]],"ltp":3.5,"tv":1158.05,"id":5720747}]}]}
{"op":"mcm","clk":"1004759685","pt":1580636849518,"mc":[{"id":"1.168135792","rc":[{"batb":[[0,1.51,507.18],[1,1.5,523.09],[2,1.43,246.19]],"ltp":1.37,"tv":5989.64,"id":2249229}]}]}
{"op":"mcm","clk":"1004759813","pt":1580636851639,"mc":[{"id":"1.168135792","rc":[{"batb":[[2,1.37,434.68]],"ltp":1.37,"tv":5989.64,"id":2249229}]}]}
{"op":"mcm","clk":"1004759874","pt":1580636852723,"mc":[{"id":"1.168135792","rc":[{"batb":[[2,1.35,5]],"ltp":1.37,"tv":5989.64,"id":2249229}]}]}
{"op":"mcm","clk":"1004759920","pt":1580636853644,"mc":[{"id":"1.168135792","rc":[{"trd":[[1.51,248.1]],"batb":[[0,1.51,383.13]],"ltp":1.51,"tv":6237.74,"id":2249229}],"tv":7395.8}]}
{"op":"mcm","clk":"1004759996","pt":1580636854725,"mc":[{"id":"1.168135792","rc":[{"batl":[[2,2,393.72]],"ltp":1.51,"tv":6237.74,"id":2249229}]}]}
{"op":"mcm","clk":"1004760037","pt":1580636855660,"mc":[{"id":"1.168135792","rc":[{"batb":[[2,1.44,397.34]],"ltp":1.51,"tv":6237.74,"id":2249229}]}]}
{"op":"mcm","clk":"1004760160","pt":1580636857778,"mc":[{"id":"1.168135792","rc":[{"batb":[[0,1.44,397.34],[1,1.35,5],[2,1.06,28]],"batl":[[0,2,393.72],[1,1.57,0],[2,2,0]],"ltp":1.51,"tv":6237.74,"id":2249229}]}]}
{"op":"mcm","clk":"1004760205","pt":1580636858450,"mc":[{"id":"1.168135792","rc":[{"batb":[[0,2.58,110.65],[1,1.42,24.25],[2,1.05,16.8]],"ltp":3.5,"tv":1158.05,"id":5720747}]}]}
{"op":"mcm","clk":"1004760381","pt":1580636861650,"mc":[{"id":"1.168135792","rc":[{"batl":[[0,1.51,3.54],[1,2,393.72]],"ltp":1.51,"tv":6237.74,"id":2249229}]}]}
{"op":"mcm","clk":"1004760442","pt":1580636862783,"mc":[{"id":"1.168135792","rc":[{"trd":[[1.51,248.86]],"batl":[[0,1.51,3.16]],"ltp":1.51,"tv":6238.5,"id":2249229}],"tv":7396.56}]}
{"op":"mcm","clk":"1004760602","pt":1580636865773,"mc":[{"id":"1.168135792","rc":[{"batb":[[1,1.43,587.71],[2,1.42,660.48]],"batl":[[1,1.78,555.38],[2,1.8,545]],"ltp":1.51,"tv":6238.5,"id":2249229}]}]}
{"op":"mcm","clk":"1004760745","pt":1580636868805,"mc":[{"id":"1.168135792","rc":[{"batl":[[1,1.6,2.8],[2,1.78,555.38]],"ltp":1.51,"tv":6238.5,"id":2249229},{"batb":[[0,1.42,24.25],[1,1.05,16.8],[2,1.04,21]],"ltp":3.5,"tv":1158.05,"id":5720747}]}]}
{"op":"mcm","clk":"1004760864","pt":1580636870760,"mc":[{"id":"1.168135792","rc":[{"batl":[[0,1.6,2.8],[1,1.78,555.38],[2,1.8,545]],"ltp":1.51,"tv":6238.5,"id":2249229},{"batb":[[0,2.32,132.45],[1,2.3,134.49],[2,1.42,24.25]],"ltp":3.5,"tv":1158.05,"id":5720747}]}]}
{"op":"mcm","clk":"1004760912","pt":1580636871787,"mc":[{"id":"1.168135792","rc":[{"batb":[[0,1.44,397.35]],"ltp":1.51,"tv":6238.5,"id":2249229}]}]}
{"op":"mcm","clk":"1004760961","pt":1580636872768,"mc":[{"id":"1.168135792","rc":[{"batl":[[1,2,393.72],[2,1.8,0]],"ltp":1.51,"tv":6238.5,"id":2249229}]}]}
{"op":"mcm","clk":"1004761063","pt":1580636874770,"mc":[{"id":"1.168135792","rc":[{"batb":[[0,1.43,587.72],[1,1.42,660.48],[2,1.35,5]],"batl":[[1,2,0]],"ltp":1.51,"tv":6238.5,"id":2249229}]}]}
{"op":"mcm","clk":"1004761118","pt":1580636875799,"mc":[{"id":"1.168135792","rc":[{"batb":[[0,1.43,587.71]],"batl":[[0,1.47,447.42],[1,1.48,543.36],[2,1.6,2.8]],"ltp":1.51,"tv":6238.5,"id":2249229}]}]}
{"op":"mcm","clk":"1004761258","pt":1580636878681,"mc":[{"id":"1.168135792","rc":[{"batb":[[0,1.43,587.72]],"ltp":1.51,"tv":6238.5,"id":2249229},{"batl":[[0,4.4,140.9]],"ltp":3.5,"tv":1158.05,"id":5720747}]}]}
{"op":"mcm","clk":"1004761395","pt":1580636881814,"mc":[{"id":"1.168135792","rc":[{"batb":[[0,1.42,24.25],[1,1.05,16.8],[2,1.04,21]],"ltp":3.5,"tv":1158.05,"id":5720747}]}]}
{"op":"mcm","clk":"1004761640","pt":1580636886810,"mc":[{"id":"1.168135792","rc":[{"trd":[[1.47,25.3]],"batl":[[0,1.47,434.77]],"ltp":1.47,"tv":6263.81,"id":2249229}],"tv":7421.86}]}
{"op":"mcm","clk":"1004761771","pt":1580636889624,"mc":[{"id":"1.168135792","rc":[{"batb":[[0,1.35,5.01],[1,1.06,28],[2,1.05,50.39]],"batl":[[0,1.6,2.8],[1,1.7,4.8],[2,1.85,454.83]],"ltp":1.47,"tv":6263.81,"id":2249229}]}]}
{"op":"mcm","clk":"1004761832","pt":1580636890805,"mc":[{"id":"1.168135792","rc":[{"trd":[[1.46,0.01]],"batb":[[0,1.35,5]],"ltp":1.46,"tv":6263.82,"id":2249229},{"trd":[[3.2,0.01]],"batb":[[0,3.35,2.26],[1,1.42,24.25],[2,1.05,16.8]],"ltp":3.2,"tv":1158.05,"id":5720747}],"tv":7421.88}]}
{"op":"mcm","clk":"1004762106","pt":1580636896726,"mc":[{"id":"1.168135792","rc":[{"batb":[[0,1.37,795.38],[1,1.36,808.11],[2,1.35,5]],"batl":[[1,1.63,402.37],[2,1.64,370.23]],"ltp":1.46,"tv":6263.82,"id":2249229}]}]}
{"op":"mcm","clk":"1004762151","pt":1580636897707,"mc":[{"id":"1.168135792","rc":[{"batb":[[0,1.35,5],[1,1.06,28],[2,1.05,50.39]],"batl":[[1,1.7,4.8],[2,1.85,454.83]],"ltp":1.46,"tv":6263.82,"id":2249229}]}]}
{"op":"mcm","clk":"1004762505","pt":1580636903819,"mc":[{"id":"1.168135792","rc":[{"trd":[[1.43,5.3]],"batb":[[0,1.45,105.81],[1,1.35,5],[2,1.06,28]],"ltp":1.43,"tv":6269.12,"id":2249229},{"trd":[[3.35,2.26]],"batb":[[0,1.42,24.25],[1,1.05,16.8],[2,1.04,21]],"ltp":3.35,"tv":1160.32,"id":5720747}],"tv":7429.44}]}
{"op":"mcm","clk":"1004762556","pt":1580636904747,"mc":[{"id":"1.168135792","rc":[{"batl":[[1,1.63,402.37],[2,1.64,370.23]],"ltp":1.43,"tv":6269.12,"id":2249229}]}]}
{"op":"mcm","clk":"1004762592","pt":1580636905618,"mc":[{"id":"1.168135792","rc":[{"batb":[[0,1.58,380.06],[1,1.57,437.79],[2,1.45,105.81]],"ltp":1.43,"tv":6269.12,"id":2249229}]}]}
{"op":"mcm","clk":"1004762639","pt":1580636906645,"mc":[{"id":"1.168135792","rc":[{"batb":[[0,1.57,437.79],[1,1.45,105.81],[2,1.35,5]],"ltp":1.43,"tv":6269.12,"id":2249229}]}]}
{"op":"mcm","clk":"1004762688","pt":1580636907723,"mc":[{"id":"1.168135792","rc":[{"batb":[[1,1.35,5],[2,1.06,28]],"ltp":1.43,"tv":6269.12,"id":2249229}]}]}
{"op":"mcm","clk":"1004762731","pt":1580636908647,"mc":[{"id":"1.168135792","rc":[{"batl":[[0,3.55,174.59]],"ltp":3.35,"tv":1160.32,"id":5720747}]}]}
{"op":"mcm","clk":"1004762788","pt":1580636909725,"mc":[{"id":"1.168135792","rc":[{"batb":[[0,1.57,779.52],[1,1.56,450.7],[2,1.35,5]],"ltp":1.43,"tv":6269.12,"id":2249229}]}]}
{"op":"mcm","clk":"1004762837","pt":1580636910748,"mc":[{"id":"1.168135792","rc":[{"batb":[[2,1.48,364.23]],"batl":[[0,1.58,4.8],[1,1.6,2.8],[2,1.63,402.37]],"ltp":1.43,"tv":6269.12,"id":2249229}]}]}
{"op":"mcm","clk":"1004762885","pt":1580636911725,"mc":[{"id":"1.168135792","rc":[{"batl":[[0,1.6,2.8],[1,1.63,402.37],[2,1.64,370.23]],"ltp":1.43,"tv":6269.12,"id":2249229}]}]}
{"op":"mcm","clk":"1004762941","pt":1580636912753,"mc":[{"id":"1.168135792","rc":[{"trd":[[1.57,9.66]],"batb":[[0,1.57,774.69]],"ltp":1.57,"tv":6278.78,"id":2249229}],"tv":7439.1}]}
{"op":"mcm","clk":"1004763136","pt":1580636916667,"mc":[{"id":"1.168135792","rc":[{"batl":[[0,1.58,3.54],[1,1.6,2.8],[2,1.63,402.37]],"ltp":1.57,"tv":6278.78,"id":2249229},{"batb":[[0,2.4,124.88],[1,1.42,24.25],[2,1.05,16.8]],"ltp":3.35,"tv":1160.32,"id":5720747}]}]}
{"op":"mcm","clk":"1004763182","pt":1580636917656,"mc":[{"id":"1.168135792","rc":[{"batb":[[0,1.48,364.23],[1,1.35,5],[2,1.22,4.16]],"batl":[[2,1.7,4.8]],"ltp":1.57,"tv":6278.78,"id":2249229}]}]}
{"op":"mcm","clk":"1004763338","pt":1580636920789,"mc":[{"id":"1.168135792","rc":[{"batl":[[0,3.35,70.2],[1,3.55,174.59]],"ltp":3.35,"tv":1160.32,"id":5720747}]}]}
{"op":"mcm","clk":"1004763610","pt":1580636925568,"mc":[{"id":"1.168135792","rc":[{"batb":[[1,1.46,508.73],[2,1.45,602.9]],"ltp":1.57,"tv":6278.78,"id":2249229}]}]}
{"op":"mcm","clk":"1004763935","pt":1580636931656,"mc":[{"id":"1.168135792","rc":[{"batb":[[1,1.35,5],[2,1.22,4.16]],"ltp":1.57,"tv":6278.78,"id":2249229},{"batb":[[0,1.42,24.25],[1,1.05,16.8],[2,1.04,21]],"batl":[[0,3.2,3],[1,3.35,70.2],[2,3.55,174.59]],"ltp":3.35,"tv":1160.32,"id":5720747}]}]}
{"op":"mcm","clk":"1004763991","pt":1580636932790,"mc":[{"id":"1.168135792","rc":[{"batl":[[2,3.55,0]],"ltp":3.35,"tv":1160.32,"id":5720747}]}]}
{"op":"mcm","clk":"1004764046","pt":1580636933772,"mc":[{"id":"1.168135792","rc":[{"batb":[[0,1.35,5],[1,1.22,4.16],[2,1.06,28]],"ltp":1.57,"tv":6278.78,"id":2249229},{"batb":[[0,2.02,171.4],[1,1.42,24.25],[2,1.05,16.8]],"ltp":3.35,"tv":1160.32,"id":5720747}]}]}
{"op":"mcm","clk":"1004764091","pt":1580636934698,"mc":[{"id":"1.168135792","rc":[{"batl":[[0,1.48,2.27]],"ltp":1.57,"tv":6278.78,"id":2249229},{"batb":[[0,2.04,168.11],[1,2.02,171.4],[2,1.42,24.25]],"ltp":3.35,"tv":1160.32,"id":5720747}]}]}
{"op":"mcm","clk":"1004764140","pt":1580636935677,"mc":[{"id":"1.168135792","rc":[{"batb":[[0,1.46,508.73],[1,1.45,602.9],[2,1.35,5]],"batl":[[1,1.51,861.15],[2,1.52,486.56]],"ltp":1.57,"tv":6278.78,"id":2249229}]}]}
{"op":"mcm","clk":"1004764207","pt":1580636936810,"mc":[{"id":"1.168135792","rc":[{"batb":[[0,1.42,24.25],[1,1.05,16.8],[2,1.04,21]],"batl":[[2,4,153.93]],"ltp":3.35,"tv":1160.32,"id":5720747}]}]}
{"op":"mcm","clk":"1004764533","pt":1580636942797,"mc":[{"id":"1.168135792","rc":[{"batl":[[0,1.48,7.27]],"ltp":1.57,"tv":6278.78,"id":2249229}]}]}
{"op":"mcm","clk":"1004764591","pt":1580636943786,"mc":[{"id":"1.168135792","rc":[{"batl":[[0,3.35,70.2],[1,4,153.93],[2,4,0]],"ltp":3.35,"tv":1160.32,"id":5720747}]}]}
{"op":"mcm","clk":"1004764633","pt":1580636944710,"mc":[{"id":"1.168135792","rc":[{"trd":[[1.48,85.28],[1.51,297.59]],"batl":[[0,1.51,836.79],[1,1.52,486.56],[2,1.6,2.8]],"ltp":1.51,"tv":6342.04,"id":2249229},{"batb":[[0,2.7,102.84],[1,1.42,24.25],[2,1.05,16.8]],"ltp":3.35,"tv":1160.32,"id":5720747}],"tv":7502.37}]}
{"op":"mcm","clk":"1004764695","pt":1580636945801,"mc":[{"id":"1.168135792","rc":[{"batb":[[0,1.35,5],[1,1.22,4.16],[2,1.06,28]],"batl":[[0,1.6,2.8],[1,1.7,4.8],[2,1.93,420.24]],"ltp":1.51,"tv":6342.04,"id":2249229}]}]}
{"op":"mcm","clk":"1004764824","pt":1580636947818,"mc":[{"id":"1.168135792","rc":[{"batb":[[0,1.36,485.64],[1,1.35,5],[2,1.22,4.16]],"ltp":1.51,"tv":6342.04,"id":2249229}]}]}
{"op":"mcm","clk":"1004765047","pt":1580636950615,"mc":[{"id":"1.168135792","rc":[{"batl":[[2,5,7.87]],"ltp":3.35,"tv":1160.32,"id":5720747}]}]}
{"op":"mcm","clk":"1004765156","pt":1580636952618,"mc":[{"id":"1.168135792","rc":[{"batb":[[0,1.37,645.74],[1,1.36,1292.22],[2,1.35,5]],"batl":[[2,1.77,601.46]],"ltp":1.51,"tv":6342.04,"id":2249229},{"batl":[[0,2.96,4.54],[1,3.35,70.2],[2,4,153.93]],"ltp":3.35,"tv":1160.32,"id":5720747}]}]}
{"op":"mcm","clk":"1004765198","pt":1580636953337,"mc":[{"id":"1.168135792","rc":[{"trd":[[1.51,306.5]],"batl":[[0,1.46,7.9],[1,1.6,2.8],[2,1.7,4.8]],"ltp":1.51,"tv":6350.95,"id":2249229},{"trd":[[2.96,4.54]],"batl":[[0,3.35,70.2],[1,4,153.93],[2,5,7.87]],"ltp":2.96,"tv":1164.86,"id":5720747}],"tv":7515.82}]}
{"op":"mcm","clk":"1004765519","pt":1580636959753,"mc":[{"id":"1.168135792","rc":[{"batb":[[1,1.36,806.58]],"ltp":1.51,"tv":6350.95,"id":2249229}]}]}
{"op":"mcm","clk":"1004765573","pt":1580636960739,"mc":[{"id":"1.168135792","rc":[{"batb":[[0,1.35,5],[1,1.22,4.16],[2,1.06,28]],"ltp":1.51,"tv":6350.95,"id":2249229}]}]}
{"op":"mcm","clk":"1004765683","pt":1580636962741,"mc":[{"id":"1.168135792","rc":[{"batb":[[0,1.38,460.08],[1,1.35,5],[2,1.22,4.16]],"ltp":1.51,"tv":6350.95,"id":2249229}]}]}
{"op":"mcm","clk":"1004765768","pt":1580636963737,"mc":[{"id":"1.168135792","rc":[{"trd":[[1.46,15.81]],"batb":[[0,1.5,611.7],[1,1.49,539.12],[2,1.38,460.08]],"batl":[[0,1.55,529.01],[1,1.56,442.99],[2,1.6,2.8]],"ltp":1.46,"tv":6366.75,"id":2249229}],"tv":7531.62}]}
{"op":"mcm","clk":"1004765828","pt":1580636964721,"mc":[{"id":"1.168135792","rc":[{"batb":[[0,1.38,460.08],[1,1.35,5],[2,1.22,4.16]],"batl":[[0,1.6,2.8],[1,1.7,4.8],[2,1.93,420.24]],"ltp":1.46,"tv":6366.75,"id":2249229},{"batb":[[0,1.42,24.25],[1,1.05,16.8],[2,1.04,21]],"ltp":2.96,"tv":1164.86,"id":5720747}]}]}
{"op":"mcm","clk":"1004765883","pt":1580636965754,"mc":[{"id":"1.168135792","rc":[{"batb":[[0,2.3,134.49],[1,1.42,24.25],[2,1.05,16.8]],"ltp":2.96,"tv":1164.86,"id":5720747}]}]}
{"op":"mcm","clk":"1004765930","pt":1580636966424,"mc":[{"id":"1.168135792","rc":[{"batb":[[0,2.32,132.45],[1,2.3,134.49],[2,1.42,24.25]],"ltp":2.96,"tv":1164.86,"id":5720747}]}]}
{"op":"mcm","clk":"1004766246","pt":1580636971746,"mc":[{"id":"1.168135792","rc":[{"batb":[[1,1.37,643.39],[2,1.36,806.57]],"batl":[[2,1.77,603.29]],"ltp":1.46,"tv":6366.75,"id":2249229}]}]}
{"op":"mcm","clk":"1004766497","pt":1580636976356,"mc":[{"id":"1.168135792","rc":[{"batl":[[0,1.7,4.8],[1,1.77,603.29],[2,1.79,554.78]],"ltp":1.46,"tv":6366.75,"id":2249229}]}]}
{"op":"mcm","clk":"1004766574","pt":1580636977750,"mc":[{"id":"1.168135792","rc":[{"batl":[[0,1.77,603.29],[1,1.79,554.78],[2,1.93,420.24]],"ltp":1.46,"tv":6366.75,"id":2249229}]}]}
{"op":"mcm","clk":"1004766643","pt":1580636978778,"mc":[{"id":"1.168135792","rc":[{"batb":[[0,1.43,116.27],[1,1.38,460.08],[2,1.37,643.39]],"ltp":1.46,"tv":6366.75,"id":2249229}]}]}
{"op":"mcm","clk":"1004766854","pt":1580636982749,"mc":[{"id":"1.168135792","rc":[{"batl":[[0,3.3,3],[1,3.35,70.2],[2,4,153.93]],"ltp":2.96,"tv":1164.86,"id":5720747}]}]}
{"op":"mcm","clk":"1004766959","pt":1580636984780,"mc":[{"id":"1.168135792","rc":[{"batl":[[0,1.74,5.67],[1,1.77,603.29],[2,1.79,554.78]],"ltp":1.46,"tv":6366.75,"id":2249229}]}]}
{"op":"mcm","clk":"1004767018","pt":1580636985769,"mc":[{"id":"1.168135792","rc":[{"batb":[[2,1.35,5]],"batl":[[1,1.93,420.24],[2,2,8.4]],"ltp":1.46,"tv":6366.75,"id":2249229}]}]}
{"op":"mcm","clk":"1004767145","pt":1580636987783,"mc":[{"id":"1.168135792","rc":[{"batl":[[1,2,8.4],[2,2,0]],"ltp":1.46,"tv":6366.75,"id":2249229},{"batl":[[2,5,7.87]],"ltp":2.96,"tv":1164.86,"id":5720747}]}]}
{"op":"mcm","clk":"1004767241","pt":1580636989589,"mc":[{"id":"1.168135792","rc":[{"batb":[[0,1.42,24.25],[1,1.05,16.8],[2,1.04,21]],"ltp":2.96,"tv":1164.86,"id":5720747}]}]}
{"op":"mcm","clk":"1004767627","pt":1580636996672,"mc":[{"id":"1.168135792","rc":[{"batl":[[1,1.77,598.28],[2,1.79,554.78]],"ltp":1.46,"tv":6366.75,"id":2249229}]}]}
{"op":"mcm","clk":"1004767699","pt":1580636997808,"mc":[{"id":"1.168135792","rc":[{"batb":[[0,1.7,408.44],[1,1.68,681.16],[2,1.43,116.27]],"ltp":1.46,"tv":6366.75,"id":2249229}]}]}
{"op":"mcm","clk":"1004767827","pt":1580636999776,"mc":[{"id":"1.168135792","rc":[{"batb":[[2,1.38,460.08]],"ltp":1.46,"tv":6366.75,"id":2249229}]}]}
{"op":"mcm","clk":"1004767881","pt":1580637000814,"mc":[{"id":"1.168135792","rc":[{"batl":[[0,3.1,206.56],[1,3.3,3],[2,3.35,70.2]],"ltp":2.96,"tv":1164.86,"id":5720747}]}]}
{"op":"mcm","clk":"1004768003","pt":1580637002682,"mc":[{"id":"1.168135792","rc":[{"batb":[[0,1.05,16.82],[1,1.04,21],[2,1.03,28]],"ltp":2.96,"tv":1164.86,"id":5720747}]}]}
{"op":"mcm","clk":"1004768215","pt":1580637005812,"mc":[{"id":"1.168135792","rc":[{"batb":[[2,1.35,5]],"ltp":1.46,"tv":6366.75,"id":2249229},{"batb":[[0,1.22,24.25],[1,1.05,16.8],[2,1.04,21]],"ltp":2.96,"tv":1164.86,"id":5720747}]}]}
{"op":"mcm","clk":"1004768325","pt":1580637007717,"mc":[{"id":"1.168135792","rc":[{"trd":[[1.7,16]],"batb":[[0,1.7,400.44]],"ltp":1.7,"tv":6382.75,"id":2249229}],"tv":7547.62}]}
{"op":"mcm","clk":"1004768461","pt":1580637009783,"mc":[{"id":"1.168135792","rc":[{"batb":[[0,1.35,5],[1,1.22,4.16],[2,1.06,28]],"batl":[[1,2,8.4],[2,1.79,0]],"ltp":1.7,"tv":6382.75,"id":2249229},{"batl":[[0,3.3,3],[1,3.35,70.2],[2,5,7.87]],"ltp":2.96,"tv":1164.86,"id":5720747}]}]}
{"op":"mcm","clk":"1004768522","pt":1580637010818,"mc":[{"id":"1.168135792","rc":[{"batb":[[0,1.55,317.87],[1,1.35,5],[2,1.22,4.16]],"batl":[[0,1.7,3.54],[1,1.74,5.67],[2,2,8.4]],"ltp":1.7,"tv":6382.75,"id":2249229}]}]}
{"op":"mcm","clk":"1004768647","pt":1580637012728,"mc":[{"id":"1.168135792","rc":[{"batb":[[1,1.47,436.23],[2,1.46,585.03]],"ltp":1.7,"tv":6382.75,"id":2249229}]}]}
{"op":"mcm","clk":"1004768719","pt":1580637013817,"mc":[{"id":"1.168135792","rc":[{"trd":[[1.55,53.23]],"batb":[[0,1.55,306.87]],"ltp":1.55,"tv":6404.75,"id":2249229}],"tv":7569.62}]}
{"op":"mcm","clk":"1004768779","pt":1580637014698,"mc":[{"id":"1.168135792","rc":[{"batb":[[1,1.35,5],[2,1.22,4.16]],"batl":[[0,1.7,213.58]],"ltp":1.55,"tv":6404.75,"id":2249229},{"batb":[[0,2.02,171.4],[1,1.22,24.25],[2,1.05,16.8]],"ltp":2.96,"tv":1164.86,"id":5720747}]}]}
{"op":"mcm","clk":"1004768893","pt":1580637016619,"mc":[{"id":"1.168135792","rc":[{"batl":[[0,2.76,236.95],[1,3.3,3],[2,3.35,70.2]],"ltp":2.96,"tv":1164.86,"id":5720747}]}]}
{"op":"mcm","clk":"1004768944","pt":1580637017805,"mc":[{"id":"1.168135792","rc":[{"trd":[[1.7,19.54],[1.74,5.67]],"batb":[[0,1.7,213.59],[1,1.55,306.87],[2,1.35,5]],"batl":[[0,2,8.4],[1,2.46,279.79],[2,2,0]],"ltp":1.74,"tv":6413.96,"id":2249229},{"trd":[[2.34,4.21],[2.42,2.49]],"batl":[[0,2.34,57.42],[1,2.76,236.95],[2,3.3,3]],"ltp":2.34,"tv":1171.56,"id":5720747}],"tv":7585.53}]}
{"op":"mcm","clk":"1004768981","pt":1580637018733,"mc":[{"id":"1.168135792","rc":[{"batb":[[0,1.55,306.87],[1,1.35,5],[2,1.22,4.16]],"ltp":1.74,"tv":6413.96,"id":2249229},{"batl":[[0,2.34,19.56]],"ltp":2.34,"tv":1171.56,"id":5720747}]}]}
{"op":"mcm","clk":"1004769037","pt":1580637019618,"mc":[{"id":"1.168135792","rc":[{"batb":[[1,1.47,455.66],[2,1.46,585.06]],"batl":[[2,2.7,364.69]],"ltp":1.74,"tv":6413.96,"id":2249229}]}]}
{"op":"mcm","clk":"1004769082","pt":1580637020402,"mc":[{"id":"1.168135792","rc":[{"batb":[[0,1.47,455.66],[1,1.46,585.06],[2,1.35,5]],"ltp":1.74,"tv":6413.96,"id":2249229}]}]}
{"op":"mcm","clk":"1004769215","pt":1580637022725,"mc":[{"id":"1.168135792","rc":[{"trd":[[2.34,17.85]],"batl":[[0,2.34,12.74]],"ltp":2.34,"tv":1185.2,"id":5720747}],"tv":7599.17}]}
{"op":"mcm","clk":"1004769323","pt":1580637024733,"mc":[{"id":"1.168135792","rc":[{"batb":[[0,1.57,306.72],[1,1.47,455.66],[2,1.46,585.06]],"ltp":1.74,"tv":6413.96,"id":2249229},{"batb":[[0,1.22,24.25],[1,1.05,16.8],[2,1.04,21]],"ltp":2.34,"tv":1185.2,"id":5720747}]}]}
{"op":"mcm","clk":"1004769416","pt":1580637026539,"mc":[{"id":"1.168135792","rc":[{"batb":[[0,1.48,364.23]],"ltp":1.74,"tv":6413.96,"id":2249229}]}]}
{"op":"mcm","clk":"1004769476","pt":1580637027728,"mc":[{"id":"1.168135792","rc":[{"trd":[[2,0.15]],"batl":[[0,2,8.33]],"ltp":2.0,"tv":6414.11,"id":2249229}],"tv":7599.32}]}
{"op":"mcm","clk":"1004769522","pt":1580637028758,"mc":[{"id":"1.168135792","rc":[{"batl":[[1,2.7,364.69],[2,2.74,338.99]],"ltp":2.0,"tv":6414.11,"id":2249229},{"batl":[[0,2.3,4],[1,2.34,12.74]],"ltp":2.34,"tv":1185.2,"id":5720747}]}]}
{"op":"mcm","clk":"1004769994","pt":1580637036775,"mc":[{"id":"1.168135792","rc":[{"trd":[[2,5.15]],"batl":[[0,2,3.33]],"ltp":2.0,"tv":6419.11,"id":2249229},{"trd":[[2,5]],"ltp":2.0,"tv":1190.2,"id":5720747}],"tv":7609.32}]}
{"op":"mcm","clk":"1004770124","pt":1580637038794,"mc":[{"id":"1.168135792","rc":[{"batl":[[0,2.3,3.5]],"ltp":2.0,"tv":1190.2,"id":5720747}]}]}
{"op":"mcm","clk":"1004770203","pt":1580637039792,"mc":[{"id":"1.168135792","rc":[{"trd":[[1.74,22.81],[1.76,4.57]],"batl":[[0,1.72,28.29],[1,2,3.33],[2,2.7,364.69]],"ltp":1.74,"tv":6440.82,"id":2249229},{"trd":[[2.3,3.5],[2.34,30.59]],"batl":[[0,3.3,3],[1,3.35,70.2],[2,5,7.87]],"ltp":2.34,"tv":1206.44,"id":5720747}],"tv":7647.27}]}
{"op":"mcm","clk":"1004770272","pt":1580637040759,"mc":[{"id":"1.168135792","rc":[{"batb":[[0,1.35,5],[1,1.22,4.16],[2,1.06,28]],"batl":[[2,2.7,0]],"ltp":1.74,"tv":6440.82,"id":2249229}]}]}
{"op":"mcm","clk":"1004770564","pt":1580637044752,"mc":[{"id":"1.168135792","rc":[{"batb":[[0,1.47,455.16],[1,1.46,585.06],[2,1.35,5]],"batl":[[0,1.52,849.5],[1,1.53,474.44],[2,1.72,28.29]],"ltp":1.74,"tv":6440.82,"id":2249229}]}]}
{"op":"mcm","clk":"1004770616","pt":1580637045676,"mc":[{"id":"1.168135792","rc":[{"batl":[[2,2,3.33]],"ltp":1.74,"tv":6440.82,"id":2249229}]}]}
{"op":"mcm","clk":"1004770673","pt":1580637046604,"mc":[{"id":"1.168135792","rc":[{"batl":[[2,1.93,420.24]],"ltp":1.74,"tv":6440.82,"id":2249229},{"batl":[[2,4,153.93]],"ltp":2.34,"tv":1206.44,"id":5720747}]}]}
{"op":"mcm","clk":"1004770752","pt":1580637047794,"mc":[{"id":"1.168135792","rc":[{"batl":[[0,3.35,70.2],[1,4,153.93],[2,5,7.87]],"ltp":2.34,"tv":1206.44,"id":5720747}]}]}
{"op":"mcm","clk":"1004770801","pt":1580637048669,"mc":[{"id":"1.168135792","rc":[{"trd":[[1.52,49.82]],"batl":[[0,1.52,824.59]],"ltp":1.52,"tv":6490.64,"id":2249229}],"tv":7697.09}]}
{"op":"mcm","clk":"1004770963","pt":1580637051778,"mc":[{"id":"1.168135792","rc":[{"batl":[[2,1.75,14.14]],"ltp":1.52,"tv":6490.64,"id":2249229}]}]}
{"op":"mcm","clk":"1004771236","pt":1580637057713,"mc":[{"id":"1.168135792","rc":[{"batb":[[0,1.35,5],[1,1.22,4.16],[2,1.06,28]],"batl":[[0,1.75,14.14],[1,1.93,420.24],[2,2,3.33]],"ltp":1.52,"tv":6490.64,"id":2249229}]}]}
{"op":"mcm","clk":"1004771695","pt":1580637067738,"mc":[{"id":"1.168135792","rc":[{"batl":[[1,5,7.87],[2,5,0]],"ltp":2.34,"tv":1206.44,"id":5720747}]}]}
{"op":"mcm","clk":"1004771797","pt":1580637069696,"mc":[{"id":"1.168135792","rc":[{"batb":[[0,1.51,613.27],[1,1.5,524.46],[2,1.35,5]],"batl":[[0,1.56,483.03],[1,1.57,432.69],[2,1.75,14.14]],"ltp":1.52,"tv":6490.64,"id":2249229}]}]}
{"op":"mcm","clk":"1004771930","pt":1580637071436,"mc":[{"id":"1.168135792","rc":[{"batb":[[0,1.35,5],[1,1.22,4.16],[2,1.06,28]],"batl":[[0,1.75,14.14],[1,1.93,420.24],[2,2,3.33]],"ltp":1.52,"tv":6490.64,"id":2249229},{"batl":[[1,3.75,165.38],[2,5,7.87]],"ltp":2.34,"tv":1206.44,"id":5720747}]}]}
{"op":"mcm","clk":"1004771988","pt":1580637072518,"mc":[{"id":"1.168135792","rc":[{"batl":[[0,1.63,2],[1,1.75,14.14],[2,1.93,420.24]],"ltp":1.52,"tv":6490.64,"id":2249229}]}]}
{"op":"mcm","clk":"1004772264","pt":1580637078740,"mc":[{"id":"1.168135792","rc":[{"batb":[[0,1.37,1170.35],[1,1.36,812.95],[2,1.35,5]],"batl":[[1,1.7,5.88],[2,1.75,14.14]],"ltp":1.52,"tv":6490.64,"id":2249229}]}]}
{"op":"mcm","clk":"1004772388","pt":1580637081548,"mc":[{"id":"1.168135792","rc":[{"batb":[[0,1.35,5],[1,1.22,4.16],[2,1.06,28]],"ltp":1.52,"tv":6490.64,"id":2249229}]}]}
{"op":"mcm","clk":"1004772593","pt":1580637085769,"mc":[{"id":"1.168135792","rc":[{"batl":[[2,1.93,420.24]],"ltp":1.52,"tv":6490.64,"id":2249229}]}]}
{"op":"mcm","clk":"1004772641","pt":1580637086745,"mc":[{"id":"1.168135792","rc":[{"batb":[[0,1.37,1170.35],[1,1.36,812.95],[2,1.35,5]],"batl":[[2,1.78,476.24]],"ltp":1.52,"tv":6490.64,"id":2249229}]}]}
{"op":"mcm","clk":"1004773156","pt":1580637099579,"mc":[{"id":"1.168135792","rc":[{"batb":[[0,1.35,5],[1,1.22,4.16],[2,1.06,28]],"batl":[[2,1.93,420.24]],"ltp":1.52,"tv":6490.64,"id":2249229}]}]}
{"op":"mcm","clk":"1004773271","pt":1580637101754,"mc":[{"id":"1.168135792","rc":[{"batl":[[0,1.7,5.88],[1,1.93,420.24],[2,2,3.33]],"ltp":1.52,"tv":6490.64,"id":2249229}]}]}
{"op":"mcm","clk":"1004773370","pt":1580637103761,"mc":[{"id":"1.168135792","rc":[{"batl":[[1,2,3.33],[2,2,0]],"ltp":1.52,"tv":6490.64,"id":2249229},{"batl":[[1,5,7.87],[2,5,0]],"ltp":2.34,"tv":1206.44,"id":5720747}]}]}
{"op":"mcm","clk":"1004773423","pt":1580637104782,"mc":[{"id":"1.168135792","rc":[{"batl":[[1,1.78,476.24],[2,1.8,545.41]],"ltp":1.52,"tv":6490.64,"id":2249229}]}]}
{"op":"mcm","clk":"1004773464","pt":1580637105764,"mc":[{"id":"1.168135792","rc":[{"trd":[[1.7,31.3]],"batb":[[0,1.71,496.04],[1,1.69,667.62],[2,1.35,5]],"batl":[[0,1.78,476.24],[1,1.8,545.41],[2,2,3.33]],"ltp":1.7,"tv":6502.4,"id":2249229}],"tv":7708.85}]}
{"op":"mcm","clk":"1004773629","pt":1580637108753,"mc":[{"id":"1.168135792","rc":[{"batl":[[0,3.1,206.56],[1,3.35,70.2],[2,5,7.87]],"ltp":2.34,"tv":1206.44,"id":5720747}]}]}
{"op":"mcm","clk":"1004774046","pt":1580637116764,"mc":[{"id":"1.168135792","rc":[{"batb":[[2,1.55,317.87]],"ltp":1.7,"tv":6502.4,"id":2249229}]}]}
{"op":"mcm","clk":"1004774106","pt":1580637117789,"mc":[{"id":"1.168135792","rc":[{"batb":[[0,1.55,317.87],[1,1.35,5],[2,1.22,4.16]],"batl":[[0,1.71,1.77],[1,2,3.33],[2,2.26,319.66]],"ltp":1.7,"tv":6502.4,"id":2249229}]}]}
{"op":"mcm","clk":"1004774152","pt":1580637118671,"mc":[{"id":"1.168135792","rc":[{"batb":[[0,2,174.83],[1,1.22,24.25],[2,1.05,16.8]],"ltp":2.34,"tv":1206.44,"id":5720747}]}]}
{"op":"mcm","clk":"1004774317","pt":1580637121802,"mc":[{"id":"1.168135792","rc":[{"batl":[[0,1.71,16.91]],"ltp":1.7,"tv":6502.4,"id":2249229}]}]}
{"op":"mcm","clk":"1004774370","pt":1580637122682,"mc":[{"id":"1.168135792","rc":[{"trd":[[1.71,10.52]],"batl":[[0,1.71,6.39]],"ltp":1.71,"tv":6512.92,"id":2249229},{"trd":[[2.4,7.5]],"ltp":2.4,"tv":1213.94,"id":5720747}],"tv":7726.87}]}
{"op":"mcm","clk":"1004774525","pt":1580637125721,"mc":[{"id":"1.168135792","rc":[{"batb":[[1,1.47,958.81],[2,1.46,588.88]],"ltp":1.71,"tv":6512.92,"id":2249229}]}]}
{"op":"mcm","clk":"1004774589","pt":1580637126803,"mc":[{"id":"1.168135792","rc":[{"trd":[[1.71,16.13]],"batl":[[0,2,4.11],[1,2.26,319.66],[2,2.72,362.97]],"ltp":1.71,"tv":6518.54,"id":2249229},{"trd":[[2.4,11.5]],"ltp":2.4,"tv":1217.94,"id":5720747}],"tv":7736.48}]}
{"op":"mcm","clk":"1004774713","pt":1580637128808,"mc":[{"id":"1.168135792","rc":[{"batb":[[0,1.22,24.25],[1,1.05,16.8],[2,1.04,21]],"ltp":2.4,"tv":1217.94,"id":5720747}]}]}
{"op":"mcm","clk":"1004774749","pt":1580637129630,"mc":[{"id":"1.168135792","rc":[{"batb":[[0,1.47,958.81],[1,1.46,588.88],[2,1.35,5]],"ltp":1.71,"tv":6518.54,"id":2249229}]}]}
{"op":"mcm","clk":"1004774907","pt":1580637131712,"mc":[{"id":"1.168135792","rc":[{"trd":[[1.71,16.91]],"batl":[[0,2,3.33]],"ltp":1.71,"tv":6519.31,"id":2249229},{"trd":[[2.4,12.06]],"batl":[[0,2.4,4.44],[1,3.1,206.56],[2,3.35,70.2]],"ltp":2.4,"tv":1218.5,"id":5720747}],"tv":7737.82}]}
{"op":"mcm","clk":"1004774992","pt":1580637132806,"mc":[{"id":"1.168135792","rc":[{"batl":[[1,2.72,362.97],[2,2.76,332.78]],"ltp":1.71,"tv":6519.31,"id":2249229},{"batl":[[1,3.35,70.2],[2,5,7.87]],"ltp":2.4,"tv":1218.5,"id":5720747}]}]}
{"op":"mcm","clk":"1004775160","pt":1580637135741,"mc":[{"id":"1.168135792","rc":[{"batl":[[1,2.72,0],[2,2.76,0]],"ltp":1.71,"tv":6519.31,"id":2249229}]}]}
{"op":"mcm","clk":"1004775339","pt":1580637138530,"mc":[{"id":"1.168135792","rc":[{"trd":[[1.71,23.14]],"batl":[[0,1.53,847.58],[1,1.54,462.76],[2,2,3.33]],"ltp":1.71,"tv":6525.54,"id":2249229},{"trd":[[2.4,16.5]],"batl":[[0,3.35,70.2],[1,5,7.87],[2,5,0]],"ltp":2.4,"tv":1222.94,"id":5720747}],"tv":7748.49}]}
{"op":"mcm","clk":"1004775488","pt":1580637140751,"mc":[{"id":"1.168135792","rc":[{"batl":[[0,1.53,477.47],[1,1.93,420.24]],"ltp":1.71,"tv":6525.54,"id":2249229},{"batl":[[1,4,153.93],[2,5,7.87]],"ltp":2.4,"tv":1222.94,"id":5720747}]}]}
{"op":"mcm","clk":"1004775566","pt":1580637141737,"mc":[{"id":"1.168135792","rc":[{"batl":[[1,1.56,3.79],[2,1.93,420.24]],"ltp":1.71,"tv":6525.54,"id":2249229}]}]}
{"op":"mcm","clk":"1004775617","pt":1580637142673,"mc":[{"id":"1.168135792","rc":[{"batl":[[1,1.93,420.24],[2,2,3.33]],"ltp":1.71,"tv":6525.54,"id":2249229}]}]}
{"op":"mcm","clk":"1004775690","pt":1580637143726,"mc":[{"id":"1.168135792","rc":[{"batl":[[0,1.52,438.58],[1,1.53,477.47],[2,1.93,420.24]],"ltp":1.71,"tv":6525.54,"id":2249229}]}]}
{"op":"mcm","clk":"1004775747","pt":1580637144552,"mc":[{"id":"1.168135792","rc":[{"trd":[[1.52,114.38]],"batl":[[0,1.52,374.02]],"ltp":1.52,"tv":6590.1,"id":2249229},{"trd":[[2.92,33.61]],"ltp":2.92,"tv":1256.55,"id":5720747}],"tv":7846.66}]}
{"op":"mcm","clk":"1004776186","pt":1580637151554,"mc":[{"id":"1.168135792","rc":[{"batb":[[0,1.35,5],[1,1.22,4.16],[2,1.06,28]],"batl":[[0,1.93,420.24],[1,2,3.33],[2,1.93,0]],"ltp":1.52,"tv":6590.1,"id":2249229}]}]}
{"op":"mcm","clk":"1004776433","pt":1580637155579,"mc":[{"id":"1.168135792","rc":[{"batb":[[0,1.52,5],[1,1.35,5],[2,1.22,4.16]],"ltp":1.52,"tv":6590.1,"id":2249229}]}]}
{"op":"mcm","clk":"1004776607","pt":1580637158672,"mc":[{"id":"1.168135792","rc":[{"batb":[[0,1.52,10.46]],"ltp":1.52,"tv":6590.1,"id":2249229}]}]}
{"op":"mcm","clk":"1004776659","pt":1580637159548,"mc":[{"id":"1.168135792","rc":[{"batb":[[1,1.38,827.39],[2,1.37,781.33]],"batl":[[0,1.79,412.86],[1,1.81,536.32],[2,1.93,420.24]],"ltp":1.52,"tv":6590.1,"id":2249229}]}]}
{"op":"mcm","clk":"1004777160","pt":1580637168787,"mc":[{"id":"1.168135792","rc":[{"batb":[[1,1.35,5],[2,1.22,4.16]],"batl":[[0,1.93,420.24],[1,2,3.33],[2,1.93,0]],"ltp":1.52,"tv":6590.1,"id":2249229}]}]}
{"op":"mcm","clk":"1004777217","pt":1580637169768,"mc":[{"id":"1.168135792","rc":[{"batl":[[0,2,3.33],[1,2,0]],"ltp":1.52,"tv":6590.1,"id":2249229},{"batl":[[1,5,7.87],[2,5,0]],"ltp":2.92,"tv":1256.55,"id":5720747}]}]}
{"op":"mcm","clk":"1004777440","pt":1580637173594,"mc":[{"id":"1.168135792","rc":[{"batb":[[0,1.72,535.52],[1,1.7,654.56],[2,1.52,10.46]],"batl":[[0,1.79,412.96],[1,1.81,536.33],[2,2,3.33]],"ltp":1.52,"tv":6590.1,"id":2249229},{"batl":[[0,3.1,206.56],[1,3.35,70.2],[2,5,7.87]],"ltp":2.92,"tv":1256.55,"id":5720747}]}]}
{"op":"mcm","clk":"1004777759","pt":1580637179798,"mc":[{"id":"1.168135792","rc":[{"batl":[[1,5,7.87],[2,5,0]],"ltp":2.92,"tv":1256.55,"id":5720747}]}]}
{"op":"mcm","clk":"1004777969","pt":1580637183706,"mc":[{"id":"1.168135792","rc":[{"batb":[[0,1.52,10.46],[1,1.35,5],[2,1.22,4.16]],"batl":[[0,2,3.33],[1,2.26,319.66],[2,2,0]],"ltp":1.52,"tv":6590.1,"id":2249229}]}]}
{"op":"mcm","clk":"1004778106","pt":1580637186640,"mc":[{"id":"1.168135792","rc":[{"batb":[[1,1.48,811.91],[2,1.47,571.54]],"batl":[[2,2.72,229.16]],"ltp":1.52,"tv":6590.1,"id":2249229}]}]}
{"op":"mcm","clk":"1004778306","pt":1580637190629,"mc":[{"id":"1.168135792","rc":[{"batb":[[0,2.4,2.27],[1,1.22,24.25],[2,1.05,16.8]],"ltp":2.92,"tv":1256.55,"id":5720747}]}]}
{"op":"mcm","clk":"1004778386","pt":1580637191819,"mc":[{"id":"1.168135792","rc":[{"batl":[[1,2.72,229.16],[2,2.76,332.09]],"ltp":1.52,"tv":6590.1,"id":2249229},{"batl":[[0,5,7.87],[1,5,0]],"ltp":2.92,"tv":1256.55,"id":5720747}]}]}
{"op":"mcm","clk":"1004778431","pt":1580637192644,"mc":[{"id":"1.168135792","rc":[{"trd":[[2.4,21.04]],"batb":[[0,1.22,24.25],[1,1.05,16.8],[2,1.04,21]],"batl":[[0,2.26,5.23],[1,5,7.87]],"ltp":2.4,"tv":1261.09,"id":5720747}],"tv":7851.2}]}
{"op":"mcm","clk":"1004778489","pt":1580637193730,"mc":[{"id":"1.168135792","rc":[{"batb":[[1,1.35,5],[2,1.22,4.16]],"batl":[[1,2.72,0],[2,2.76,0]],"ltp":1.52,"tv":6590.1,"id":2249229}]}]}
{"op":"mcm","clk":"1004778753","pt":1580637199725,"mc":[{"id":"1.168135792","rc":[{"batl":[[1,2.46,279.79]],"ltp":1.52,"tv":6590.1,"id":2249229},{"batl":[[1,2.76,236.95],[2,5,7.87]],"ltp":2.4,"tv":1261.09,"id":5720747}]}]}
{"op":"mcm","clk":"1004778874","pt":1580637202668,"mc":[{"id":"1.168135792","rc":[{"batb":[[1,1.48,807.46],[2,1.47,571.54]],"batl":[[2,2.72,232.31]],"ltp":1.52,"tv":6590.1,"id":2249229}]}]}
{"op":"mcm","clk":"1004778968","pt":1580637204736,"mc":[{"id":"1.168135792","rc":[{"batb":[[0,1.52,5]],"ltp":1.52,"tv":6590.1,"id":2249229}]}]}
{"op":"mcm","clk":"1004779072","pt":1580637206750,"mc":[{"id":"1.168135792","rc":[{"batl":[[1,2.4,70],[2,2.76,236.95]],"ltp":2.4,"tv":1261.09,"id":5720747}]}]}
{"op":"mcm","clk":"1004779101","pt":1580637207678,"mc":[{"id":"1.168135792","rc":[{"batb":[[0,1.7,5.46],[1,1.52,5],[2,1.48,807.46]],"batl":[[0,2.46,279.79],[1,2.72,232.31],[2,2.76,332.1]],"ltp":1.52,"tv":6590.1,"id":2249229}]}]}
{"op":"mcm","clk":"1004779210","pt":1580637209739,"mc":[{"id":"1.168135792","rc":[{"batb":[[2,1.35,5]],"batl":[[1,2.72,0],[2,2.76,0]],"ltp":1.52,"tv":6590.1,"id":2249229}]}]}
{"op":"mcm","clk":"1004779269","pt":1580637210774,"mc":[{"id":"1.168135792","rc":[{"batl":[[2,5,7.87]],"ltp":2.4,"tv":1261.09,"id":5720747}]}]}
{"op":"mcm","clk":"1004779304","pt":1580637211648,"mc":[{"id":"1.168135792","rc":[{"batl":[[1,5,7.87],[2,5,0]],"ltp":2.4,"tv":1261.09,"id":5720747}]}]}
{"op":"mcm","clk":"1004779343","pt":1580637212677,"mc":[{"id":"1.168135792","rc":[{"batb":[[0,1.8,62.5],[1,1.7,5.46],[2,1.52,5]],"ltp":1.52,"tv":6590.1,"id":2249229},{"batb":[[0,1.58,459.16],[1,1.57,440.92],[2,1.22,24.25]],"batl":[[0,1.64,713.13],[1,1.65,363.86],[2,2.26,5.23]],"ltp":2.4,"tv":1261.09,"id":5720747}]}]}
{"op":"mcm","clk":"1004779441","pt":1580637214740,"mc":[{"id":"1.168135792","rc":[{"batb":[[0,1.7,5.46],[1,1.52,5],[2,1.35,5]],"batl":[[0,3.55,174.59]],"ltp":1.52,"tv":6590.1,"id":2249229},{"batl":[[2,2.06,374.53]],"ltp":2.4,"tv":1261.09,"id":5720747}]}]}
{"op":"mcm","clk":"1004779578","pt":1580637217675,"mc":[{"id":"1.168135792","rc":[{"batb":[[0,1.59,4.45],[1,1.58,459.16],[2,1.57,440.92]],"ltp":2.4,"tv":1261.09,"id":5720747}]}]}
{"op":"mcm","clk":"1004779631","pt":1580637218769,"mc":[{"id":"1.168135792","rc":[{"batb":[[1,1.35,5],[2,1.22,4.16]],"ltp":1.52,"tv":6590.1,"id":2249229}]}]}
{"op":"mcm","clk":"1004779957","pt":1580637225606,"mc":[{"id":"1.168135792","rc":[{"trd":[[2.56,1.77]],"ltp":2.56,"tv":6591.87,"id":2249229},{"trd":[[1.64,2.76]],"batl":[[0,1.64,710.37]],"ltp":1.64,"tv":1263.85,"id":5720747}],"tv":7855.73}]}
{"op":"mcm","clk":"1004780055","pt":1580637227765,"mc":[{"id":"1.168135792","rc":[{"trd":[[2.56,7.07]],"ltp":2.56,"tv":6597.17,"id":2249229},{"trd":[[1.58,310.36],[1.59,8.91],[1.64,19.03]],"batb":[[0,1.58,303.98],[1,1.57,440.92],[2,1.22,24.25]],"batl":[[0,1.64,698.1]],"ltp":1.64,"tv":1599.39,"id":5720747}],"tv":8196.57}]}
{"op":"mcm","clk":"1004780098","pt":1580637228791,"mc":[{"id":"1.168135792","rc":[{"trd":[[1.58,451.46]],"batb":[[0,1.58,233.43]],"ltp":1.58,"tv":1740.49,"id":5720747}],"tv":8337.67}]}
{"op":"mcm","clk":"1004780152","pt":1580637229768,"mc":[{"id":"1.168135792","rc":[{"trd":[[2.56,31.3]],"ltp":2.56,"tv":6621.4,"id":2249229},{"trd":[[1.64,56.85]],"batl":[[0,1.64,660.28]],"ltp":1.64,"tv":1778.31,"id":5720747}],"tv":8399.72}]}
{"op":"mcm","clk":"1004780214","pt":1580637230804,"mc":[{"id":"1.168135792","rc":[{"trd":[[1.59,23.9],[1.64,101.91]],"batb":[[2,1.4,6.59]],"batl":[[0,1.64,637.74]],"ltp":1.64,"tv":1838.37,"id":5720747}],"tv":8459.78}]}
{"op":"mcm","clk":"1004780364","pt":1580637233787,"mc":[{"id":"1.168135792","rc":[{"trd":[[1.58,748.89]],"batb":[[0,1.58,84.72]],"ltp":1.58,"tv":2135.79,"id":5720747}],"tv":8757.2}]}
{"op":"mcm","clk":"1004780476","pt":1580637235794,"mc":[{"id":"1.168135792","rc":[{"batl":[[0,1.64,373.11],[1,2.06,374.53],[2,5,7.87]],"ltp":1.58,"tv":2135.79,"id":5720747}]}]}
{"op":"mcm","clk":"1004780573","pt":1580637237804,"mc":[{"id":"1.168135792","rc":[{"trd":[[1.64,102.73]],"batl":[[0,1.64,372.7]],"ltp":1.64,"tv":2136.62,"id":5720747}],"tv":8758.03}]}
{"op":"mcm","clk":"1004780632","pt":1580637238720,"mc":[{"id":"1.168135792","rc":[{"batb":[[0,1.58,432.78]],"ltp":1.64,"tv":2136.62,"id":5720747}]}]}
{"op":"mcm","clk":"1004780734","pt":1580637240725,"mc":[{"id":"1.168135792","rc":[{"batl":[[0,1.64,724.05],[1,1.65,363.92],[2,2.06,374.53]],"ltp":1.64,"tv":2136.62,"id":5720747}]}]}
{"op":"mcm","clk":"1004780781","pt":1580637241811,"mc":[{"id":"1.168135792","rc":[{"trd":[[1.58,763.89]],"batb":[[0,1.58,425.28]],"ltp":1.58,"tv":2151.62,"id":5720747}],"tv":8773.03}]}
{"op":"mcm","clk":"1004780869","pt":1580637243721,"mc":[{"id":"1.168135792","rc":[{"batl":[[0,1.64,610.52]],"ltp":1.58,"tv":2151.62,"id":5720747}]}]}
{"op":"mcm","clk":"1004780922","pt":1580637244804,"mc":[{"id":"1.168135792","rc":[{"batb":[[0,1.58,514.87]],"ltp":1.58,"tv":2151.62,"id":5720747}]}]}
{"op":"mcm","clk":"1004781045","pt":1580637247732,"mc":[{"id":"1.168135792","rc":[{"batb":[[0,1.59,50.65],[1,1.58,514.87],[2,1.57,440.92]],"ltp":1.58,"tv":2151.62,"id":5720747}]}]}
{"op":"mcm","clk":"1004781204","pt":1580637250737,"mc":[{"id":"1.168135792","rc":[{"batl":[[0,2.6,33.61],[1,3.55,174.59]],"ltp":2.56,"tv":6621.4,"id":2249229}]}]}
{"op":"mcm","clk":"1004781661","pt":1580637259760,"mc":[{"id":"1.168135792","rc":[{"batb":[[0,1.6,865.91],[1,1.59,50.65],[2,1.58,514.87]],"ltp":1.58,"tv":2151.62,"id":5720747}]}]}
{"op":"mcm","clk":"1004781708","pt":1580637260641,"mc":[{"id":"1.168135792","rc":[{"trd":[[1.64,106.27]],"batl":[[0,1.64,608.75]],"ltp":1.64,"tv":2155.15,"id":5720747}],"tv":8776.56}]}
{"op":"mcm","clk":"1004781753","pt":1580637261723,"mc":[{"id":"1.168135792","rc":[{"trd":[[2.56,35.09]],"ltp":2.56,"tv":6625.19,"id":2249229},{"trd":[[1.64,112.18]],"batl":[[0,1.64,602.84]],"ltp":1.64,"tv":2161.06,"id":5720747}],"tv":8786.26}]}
{"op":"mcm","clk":"1004781799","pt":1580637262762,"mc":[{"id":"1.168135792","rc":[{"batb":[[1,1.52,22.56],[2,1.35,5]],"ltp":2.56,"tv":6625.19,"id":2249229}]}]}
{"op":"mcm","clk":"1004781903","pt":1580637264819,"mc":[{"id":"1.168135792","rc":[{"trd":[[1.64,120.18]],"batl":[[0,1.64,598.84]],"ltp":1.64,"tv":2169.06,"id":5720747}],"tv":8794.26}]}
{"op":"mcm","clk":"1004781944","pt":1580637265752,"mc":[{"id":"1.168135792","rc":[{"trd":[[1.64,133.28]],"batl":[[0,1.64,592.29]],"ltp":1.64,"tv":2182.16,"id":5720747}],"tv":8807.36}]}
{"op":"mcm","clk":"1004782006","pt":1580637266748,"mc":[{"id":"1.168135792","rc":[{"batb":[[1,1.58,514.87],[2,1.57,440.92]],"ltp":1.64,"tv":2182.16,"id":5720747}]}]}
{"op":"mcm","clk":"1004782057","pt":1580637267723,"mc":[{"id":"1.168135792","rc":[{"trd":[[2.58,2]],"ltp":2.58,"tv":6627.19,"id":2249229},{"trd":[[1.63,3.17]],"batl":[[0,1.63,4.41],[1,1.64,592.29],[2,1.65,363.92]],"ltp":1.63,"tv":2185.33,"id":5720747}],"tv":8812.53}]}
{"op":"mcm","clk":"1004782111","pt":1580637268751,"mc":[{"id":"1.168135792","rc":[{"trd":[[2.56,131.31],[2.58,4.78]],"ltp":2.56,"tv":6726.19,"id":2249229},{"trd":[[1.63,7.57],[1.64,283.48]],"batb":[[1,1.58,645.73]],"batl":[[0,1.64,442.09],[1,1.65,363.92],[2,2.06,374.53]],"ltp":1.64,"tv":2339.94,"id":5720747}],"tv":9066.13}]}
{"op":"mcm","clk":"1004782200","pt":1580637270763,"mc":[{"id":"1.168135792","rc":[{"batb":[[0,1.63,50.65],[1,1.6,865.91],[2,1.58,645.73]],"ltp":1.64,"tv":2339.94,"id":5720747}]}]}
{"op":"mcm","clk":"1004782636","pt":1580637279770,"mc":[{"id":"1.168135792","rc":[{"trd":[[2.6,33.61]],"batl":[[0,3.55,174.59],[1,3.55,0]],"ltp":2.6,"tv":6759.8,"id":2249229},{"trd":[[1.6,640.72],[1.62,53.94],[1.63,108.92]],"batb":[[0,1.6,545.56],[1,1.58,645.73],[2,1.57,440.92]],"ltp":1.6,"tv":3135.94,"id":5720747}],"tv":9895.75}]}
{"op":"mcm","clk":"1004782890","pt":1580637284673,"mc":[{"id":"1.168135792","rc":[{"trd":[[2.56,133.31]],"ltp":2.56,"tv":6761.8,"id":2249229},{"trd":[[1.64,286.6]],"batl":[[0,1.64,438.97]],"ltp":1.64,"tv":3139.06,"id":5720747}],"tv":9900.87}]}
{"op":"mcm","clk":"1004782947","pt":1580637285655,"mc":[{"id":"1.168135792","rc":[{"trd":[[2.56,135.31]],"ltp":2.56,"tv":6763.8,"id":2249229},{"trd":[[1.64,289.72]],"batl":[[0,1.64,435.85]],"ltp":1.64,"tv":3142.18,"id":5720747}],"tv":9905.99}]}
{"op":"mcm","clk":"1004783207","pt":1580637290795,"mc":[{"id":"1.168135792","rc":[{"batb":[[1,1.4,6.59],[2,1.25,10.52]],"batl":[[0,2.06,374.53],[1,5,7.87],[2,2.06,0]],"ltp":1.64,"tv":3142.18,"id":5720747}]}]}
{"op":"mcm","clk":"1004783497","pt":1580637297806,"mc":[{"id":"1.168135792","rc":[{"batl":[[0,2.56,1.77],[1,3.55,174.59]],"ltp":2.56,"tv":6763.8,"id":2249229},{"trd":[[1.6,655.86]],"batb":[[0,1.6,537.99],[1,1.49,569.11],[2,1.48,556.11]],"batl":[[0,1.84,371.56],[1,1.86,493.05],[2,2.06,374.53]],"ltp":1.6,"tv":3157.33,"id":5720747}],"tv":9921.13}]}
{"op":"mcm","clk":"1004783550","pt":1580637298784,"mc":[{"id":"1.168135792","rc":[{"batb":[[1,1.4,6.59],[2,1.25,10.52]],"batl":[[0,2.06,374.53],[1,5,7.87],[2,2.06,0]],"ltp":1.6,"tv":3157.33,"id":5720747}]}]}
{"op":"mcm","clk":"1004783586","pt":1580637299707,"mc":[{"id":"1.168135792","rc":[{"batl":[[0,3.55,174.59],[1,3.55,0]],"ltp":2.56,"tv":6763.8,"id":2249229}]}]}
{"op":"mcm","clk":"1004783659","pt":1580637300819,"mc":[{"id":"1.168135792","rc":[{"batl":[[0,2.56,567.13],[1,3.55,174.59]],"ltp":2.56,"tv":6763.8,"id":2249229}]}]}
{"op":"mcm","clk":"1004783699","pt":1580637301437,"mc":[{"id":"1.168135792","rc":[{"trd":[[2.56,144.92]],"batl":[[0,2.56,557.52]],"ltp":2.56,"tv":6773.41,"id":2249229},{"trd":[[1.64,304.72]],"ltp":1.64,"tv":3172.33,"id":5720747}],"tv":9945.74}]}
{"op":"mcm","clk":"1004783757","pt":1580637302629,"mc":[{"id":"1.168135792","rc":[{"trd":[[1.94,200]],"ltp":1.94,"tv":6973.41,"id":2249229},{"trd":[[2.06,188.35]],"batl":[[0,2.06,186.19]],"ltp":2.06,"tv":3360.67,"id":5720747}],"tv":10334.09}]}
{"op":"mcm","clk":"1004783842","pt":1580637304434,"mc":[{"id":"1.168135792","rc":[{"batl":[[0,5,7.87],[1,5,0]],"ltp":2.06,"tv":3360.67,"id":5720747}]}]}
{"op":"mcm","clk":"1004783946","pt":1580637306812,"mc":[{"id":"1.168135792","rc":[{"batb":[[1,1.49,569.11],[2,1.48,556.11]],"batl":[[0,1.84,371.56],[1,1.86,493.05],[2,5,7.87]],"ltp":2.06,"tv":3360.67,"id":5720747}]}]}
{"op":"mcm","clk":"1004783999","pt":1580637307734,"mc":[{"id":"1.168135792","rc":[{"trd":[[2.56,554.92]],"batl":[[0,2.56,147.52]],"ltp":2.56,"tv":7383.41,"id":2249229},{"trd":[[1.64,944.72]],"ltp":1.64,"tv":4000.67,"id":5720747}],"tv":11384.09}]}
{"op":"mcm","clk":"1004784054","pt":1580637308728,"mc":[{"id":"1.168135792","rc":[{"trd":[[2.56,561.77]],"batl":[[0,2.56,140.67]],"ltp":2.56,"tv":7390.27,"id":2249229},{"trd":[[1.64,955.42]],"ltp":1.64,"tv":4011.38,"id":5720747}],"tv":11401.65}]}
{"op":"mcm","clk":"1004784271","pt":1580637312750,"mc":[{"id":"1.168135792","rc":[{"batl":[[0,2.5,7.39],[1,2.56,140.67],[2,3.55,174.59]],"ltp":2.56,"tv":7390.27,"id":2249229}]}]}
{"op":"mcm","clk":"1004784445","pt":1580637316669,"mc":[{"id":"1.168135792","rc":[{"trd":[[2.5,7.39],[2.56,581.56]],"batl":[[0,2.56,120.88],[1,3.55,174.59],[2,3.55,0]],"ltp":2.56,"tv":7417.44,"id":2249229},{"trd":[[1.64,986.31],[1.66,11.12]],"batl":[[0,5,7.87],[1,1.86,0],[2,5,0]],"ltp":1.64,"tv":4053.39,"id":5720747}],"tv":11470.83}]}
{"op":"mcm","clk":"1004784546","pt":1580637318742,"mc":[{"id":"1.168135792","rc":[{"trd":[[2.56,661.76]],"batl":[[0,2.56,40.68],[1,3.55,0]],"ltp":2.56,"tv":7497.64,"id":2249229},{"trd":[[1.64,1111.5]],"batb":[[0,1.49,569.11],[1,1.48,556.11],[2,1.4,6.57]],"ltp":1.64,"tv":4178.57,"id":5720747}],"tv":11676.22}]}
{"op":"mcm","clk":"1004784586","pt":1580637319669,"mc":[{"id":"1.168135792","rc":[{"trd":[[2.56,702.44]],"ltp":2.56,"tv":7538.32,"id":2249229},{"trd":[[1.64,1175]],"batl":[[0,1.54,578.77],[1,1.55,455.25],[2,5,7.87]],"ltp":1.64,"tv":4242.07,"id":5720747}],"tv":11780.4}]}
{"op":"mcm","clk":"1004784628","pt":1580637320752,"mc":[{"id":"1.168135792","rc":[{"batl":[[2,1.59,37.86]],"ltp":1.64,"tv":4242.07,"id":5720747}]}]}
{"op":"mcm","clk":"1004784678","pt":1580637321764,"mc":[{"id":"1.168135792","rc":[{"batl":[[2,1.93,219.22]],"ltp":1.64,"tv":4242.07,"id":5720747}]}]}
{"op":"mcm","clk":"1004784718","pt":1580637322541,"mc":[{"id":"1.168135792","rc":[{"batl":[[0,4,251.76]],"ltp":2.56,"tv":7538.32,"id":2249229}]}]}
{"op":"mcm","clk":"1004784785","pt":1580637323691,"mc":[{"id":"1.168135792","rc":[{"trd":[[1.54,266.64]],"batl":[[0,1.54,445.45]],"ltp":1.54,"tv":4508.72,"id":5720747}],"tv":12047.04}]}
{"op":"mcm","clk":"1004785067","pt":1580637329785,"mc":[{"id":"1.168135792","rc":[{"trd":[[2.84,7.39]],"ltp":2.84,"tv":7545.71,"id":2249229},{"trd":[[1.54,280.27]],"batl":[[0,1.54,431.82]],"ltp":1.54,"tv":4522.35,"id":5720747}],"tv":12068.06}]}
{"op":"mcm","clk":"1004785098","pt":1580637330762,"mc":[{"id":"1.168135792","rc":[{"batb":[[0,1.49,674.48]],"batl":[[0,1.54,527.14]],"ltp":1.54,"tv":4522.35,"id":5720747}]}]}
{"op":"mcm","clk":"1004785143","pt":1580637331748,"mc":[{"id":"1.168135792","rc":[{"trd":[[2.84,17.39]],"ltp":2.84,"tv":7555.71,"id":2249229},{"trd":[[1.54,298.71]],"batl":[[0,1.54,508.7]],"ltp":1.54,"tv":4540.79,"id":5720747}],"tv":12096.5}]}
{"op":"mcm","clk":"1004785181","pt":1580637332470,"mc":[{"id":"1.168135792","rc":[{"trd":[[2.84,26.73]],"ltp":2.84,"tv":7565.05,"id":2249229},{"trd":[[1.54,366.61]],"batl":[[0,1.54,466.13]],"ltp":1.54,"tv":4608.68,"id":5720747}],"tv":12173.74}]}
{"op":"mcm","clk":"1004785229","pt":1580637333660,"mc":[{"id":"1.168135792","rc":[{"batb":[[0,1.4,6.59],[1,1.25,10.52],[2,1.22,24.23]],"batl":[[0,1.93,219.22],[1,5,7.87],[2,1.93,0]],"ltp":1.54,"tv":4608.68,"id":5720747}]}]}
{"op":"mcm","clk":"1004785335","pt":1580637335772,"mc":[{"id":"1.168135792","rc":[{"batb":[[0,1.5,105.03],[1,1.4,6.59],[2,1.25,10.52]],"ltp":1.54,"tv":4608.68,"id":5720747}]}]}
{"op":"mcm","clk":"1004785657","pt":1580637343797,"mc":[{"id":"1.168135792","rc":[{"batb":[[0,2.1,7.39],[1,1.7,5.46],[2,1.52,22.56]],"ltp":2.84,"tv":7565.05,"id":2249229},{"trd":[[1.5,18.48]],"batb":[[0,1.5,95.79]],"ltp":1.5,"tv":4627.17,"id":5720747}],"tv":12192.22}]}
{"op":"mcm","clk":"1004785741","pt":1580637345804,"mc":[{"id":"1.168135792","rc":[{"trd":[[1.5,118.48]],"batb":[[0,1.5,45.79],[2,1.34,18.93]],"ltp":1.5,"tv":4727.17,"id":5720747}],"tv":12292.22}]}
{"op":"mcm","clk":"1004786075","pt":1580637352519,"mc":[{"id":"1.168135792","rc":[{"batb":[[1,1.42,912.43],[2,1.41,686.87]],"batl":[[0,1.68,529.65],[1,1.7,659.02],[2,1.93,219.22]],"ltp":1.5,"tv":4727.17,"id":5720747}]}]}
{"op":"mcm","clk":"1004786179","pt":1580637354736,"mc":[{"id":"1.168135792","rc":[{"batl":[[0,1.93,219.22],[1,5,7.87],[2,1.93,0]],"ltp":1.5,"tv":4727.17,"id":5720747}]}]}
{"op":"mcm","clk":"1004786233","pt":1580637355720,"mc":[{"id":"1.168135792","rc":[{"batb":[[0,1.42,912.43],[1,1.41,686.87],[2,1.4,6.57]],"batl":[[0,5,7.87],[1,5,0]],"ltp":1.5,"tv":4727.17,"id":5720747}]}]}
{"op":"mcm","clk":"1004786289","pt":1580637356808,"mc":[{"id":"1.168135792","rc":[{"batl":[[0,1.5,125.19],[1,1.91,1.68],[2,5,7.87]],"ltp":1.5,"tv":4727.17,"id":5720747}]}]}
{"op":"mcm","clk":"1004786321","pt":1580637357733,"mc":[{"id":"1.168135792","rc":[{"trd":[[1.48,0.02],[1.49,0.02]],"batb":[[0,1.42,912.41]],"batl":[[0,1.48,49.98],[1,1.5,125.19],[2,1.91,1.68]],"ltp":1.48,"tv":4727.21,"id":5720747}],"tv":12292.26}]}
{"op":"mcm","clk":"1004786407","pt":1580637359800,"mc":[{"id":"1.168135792","rc":[{"batl":[[0,4.7,214.73]],"ltp":2.84,"tv":7565.05,"id":2249229},{"batl":[[0,1.47,774.57],[1,1.48,542.81],[2,1.5,125.19]],"ltp":1.48,"tv":4727.21,"id":5720747}]}]}
{"op":"mcm","clk":"1004786575","pt":1580637362803,"mc":[{"id":"1.168135792","rc":[{"batl":[[2,1.8,269.05]],"ltp":1.48,"tv":4727.21,"id":5720747}]}]}
{"op":"mcm","clk":"1004786774","pt":1580637365743,"mc":[{"id":"1.168135792","rc":[{"trd":[[3.1,2]],"ltp":3.1,"tv":7567.05,"id":2249229},{"trd":[[1.47,4.22]],"batl":[[0,1.47,770.35]],"ltp":1.47,"tv":4731.43,"id":5720747}],"tv":12298.48}]}
{"op":"mcm","clk":"1004786939","pt":1580637368652,"mc":[{"id":"1.168135792","rc":[{"batb":[[0,1.44,37.21],[1,1.4,6.57],[2,1.35,7.51]],"batl":[[0,1.8,269.05],[1,1.91,1.68],[2,5,7.87]],"ltp":1.47,"tv":4731.43,"id":5720747}]}]}
{"op":"mcm","clk":"1004786995","pt":1580637369735,"mc":[{"id":"1.168135792","rc":[{"batb":[[0,1.44,37.23]],"ltp":1.47,"tv":4731.43,"id":5720747}]}]}
{"op":"mcm","clk":"1004787029","pt":1580637370513,"mc":[{"id":"1.168135792","rc":[{"trd":[[1.44,74.42],[1.47,4.26]],"batb":[[0,1.4,6.57],[1,1.35,7.51],[2,1.34,18.93]],"batl":[[0,1.42,74.52],[1,1.8,269.05],[2,1.91,1.68]],"ltp":1.44,"tv":4805.89,"id":5720747}],"tv":12372.94}]}
{"op":"mcm","clk":"1004787082","pt":1580637371646,"mc":[{"id":"1.168135792","rc":[{"trd":[[3.35,5]],"ltp":3.35,"tv":7572.05,"id":2249229},{"trd":[[1.42,11.8]],"batl":[[0,1.42,62.72]],"ltp":1.42,"tv":4817.68,"id":5720747}],"tv":12389.74}]}
{"op":"mcm","clk":"1004787211","pt":1580637373659,"mc":[{"id":"1.168135792","rc":[{"batl":[[2,5,7.87]],"ltp":1.42,"tv":4817.68,"id":5720747}]}]}
{"op":"mcm","clk":"1004787382","pt":1580637376661,"mc":[{"id":"1.168135792","rc":[{"batb":[[1,1.38,903.43],[2,1.37,784.38]],"batl":[[1,1.55,722.81],[2,1.56,443.28]],"ltp":1.42,"tv":4817.68,"id":5720747}]}]}
{"op":"mcm","clk":"1004787506","pt":1580637378728,"mc":[{"id":"1.168135792","rc":[{"batb":[[1,1.35,7.51],[2,1.34,18.93]],"batl":[[0,1.8,269.05],[1,5,7.87],[2,1.56,0]],"ltp":1.42,"tv":4817.68,"id":5720747}]}]}
{"op":"mcm","clk":"1004787783","pt":1580637381633,"mc":[{"id":"1.168135792","rc":[{"batl":[[0,4.4,229.01]],"ltp":3.35,"tv":7572.05,"id":2249229}]}]}
{"op":"mcm","clk":"1004787842","pt":1580637382766,"mc":[{"id":"1.168135792","rc":[{"trd":[[1.34,37.86],[1.35,15.02],[1.4,13.14]],"batb":[[0,1.29,9.07],[1,1.25,10.52],[2,1.22,24.23]],"batl":[[0,1.33,29.71],[1,1.8,269.05],[2,5,7.87]],"ltp":1.34,"tv":4883.71,"id":5720747}],"tv":12455.76}]}
{"op":"mcm","clk":"1004787947","pt":1580637384772,"mc":[{"id":"1.168135792","rc":[{"trd":[[1.33,59.42]],"batb":[[0,1.38,873.72],[1,1.37,784.38],[2,1.29,9.07]],"batl":[[0,1.55,722.81],[1,1.56,443.28],[2,1.8,269.05]],"ltp":1.33,"tv":4943.13,"id":5720747}],"tv":12515.18}]}
{"op":"mcm","clk":"1004788060","pt":1580637386739,"mc":[{"id":"1.168135792","rc":[{"batl":[[0,1.8,269.05],[1,5,7.87],[2,1.8,0]],"ltp":1.33,"tv":4943.13,"id":5720747}]}]}
{"op":"mcm","clk":"1004788109","pt":1580637387543,"mc":[{"id":"1.168135792","rc":[{"batb":[[2,1.33,379.36]],"batl":[[0,1.42,125.19],[1,1.8,269.05],[2,5,7.87]],"ltp":1.33,"tv":4943.13,"id":5720747}]}]}
{"op":"mcm","clk":"1004788232","pt":1580637389752,"mc":[{"id":"1.168135792","rc":[{"batb":[[0,1.7,5.46],[1,1.52,22.56],[2,1.35,5]],"ltp":3.35,"tv":7572.05,"id":2249229},{"batl":[[0,1.4,4.2],[1,1.42,632.07],[2,1.43,628.38]],"ltp":1.33,"tv":4943.13,"id":5720747}]}]}
{"op":"mcm","clk":"1004788352","pt":1580637391776,"mc":[{"id":"1.168135792","rc":[{"batl":[[0,5.1,202.82]],"ltp":3.35,"tv":7572.05,"id":2249229}]}]}
{"op":"mcm","clk":"1004788411","pt":1580637392453,"mc":[{"id":"1.168135792","rc":[{"batb":[[0,2.5,7.39],[1,1.7,5.46],[2,1.52,22.56]],"ltp":3.35,"tv":7572.05,"id":2249229}]}]}
{"op":"mcm","clk":"1004788517","pt":1580637393756,"mc":[{"id":"1.168135792","rc":[{"trd":[[1.38,36.34]],"batb":[[0,1.38,855.55],[2,1.29,9.07]],"batl":[[1,1.42,506.88]],"ltp":1.38,"tv":4979.47,"id":5720747}],"tv":12551.52}]}
{"op":"mcm","clk":"1004789003","pt":1580637398800,"mc":[{"id":"1.168135792","rc":[{"batb":[[2,1.3,3.36]],"ltp":1.38,"tv":4979.47,"id":5720747}]}]}
{"op":"mcm","clk":"1004789222","pt":1580637401799,"mc":[{"id":"1.168135792","rc":[{"batb":[[0,1.3,3.36],[1,1.29,9.07],[2,1.25,10.52]],"batl":[[1,1.8,270.73],[2,5,7.87]],"ltp":1.38,"tv":4979.47,"id":5720747}]}]}
{"op":"mcm","clk":"1004789440","pt":1580637404792,"mc":[{"id":"1.168135792","rc":[{"trd":[[1.38,36.37]],"batl":[[0,1.38,8.31],[1,1.4,4.2],[2,1.8,270.73]],"ltp":1.38,"tv":4979.5,"id":5720747}],"tv":12551.55}]}
{"op":"mcm","clk":"1004789493","pt":1580637405768,"mc":[{"id":"1.168135792","rc":[{"trd":[[1.38,43.95]],"batl":[[0,1.38,4.53]],"ltp":1.38,"tv":4987.07,"id":5720747}],"tv":12559.13}]}
{"op":"mcm","clk":"1004789583","pt":1580637407667,"mc":[{"id":"1.168135792","rc":[{"trd":[[1.3,4.18]],"batb":[[0,1.3,1.27],[2,1.26,75]],"ltp":1.3,"tv":4991.26,"id":5720747}],"tv":12563.31}]}
{"op":"mcm","clk":"1004789636","pt":1580637408794,"mc":[{"id":"1.168135792","rc":[{"trd":[[3.5,1.68],[3.6,1.73]],"batl":[[0,3.35,2.64],[1,5.1,202.82]],"ltp":3.5,"tv":7575.46,"id":2249229},{"trd":[[1.38,48.47],[1.4,17.34]],"batb":[[0,1.36,1087.19],[1,1.35,844.63],[2,1.3,1.27]],"batl":[[0,1.46,692.21],[1,1.47,558.16]],"ltp":1.4,"tv":4999.98,"id":5720747}],"tv":12575.45}]}
{"op":"mcm","clk":"1004789966","pt":1580637414810,"mc":[{"id":"1.168135792","rc":[{"trd":[[1.46,0.02]],"batl":[[0,1.46,692.2]],"ltp":1.46,"tv":5000.0,"id":5720747}],"tv":12575.47}]}
{"op":"mcm","clk":"1004790311","pt":1580637419813,"mc":[{"id":"1.168135792","rc":[{"batb":[[0,1.3,1.27],[1,1.29,9.07],[2,1.26,100]],"batl":[[0,1.8,270.73],[1,5,7.87],[2,1.8,0]],"ltp":1.46,"tv":5000.0,"id":5720747}]}]}
{"op":"mcm","clk":"1004790517","pt":1580637421702,"mc":[{"id":"1.168135792","rc":[{"batb":[[0,1.39,673.05],[1,1.38,754.85],[2,1.3,1.27]],"batl":[[0,1.43,637.02],[1,1.44,608.34],[2,1.8,270.73]],"ltp":1.46,"tv":5000.0,"id":5720747}]}]}
{"op":"mcm","clk":"1004790611","pt":1580637422724,"mc":[{"id":"1.168135792","rc":[{"batb":[[0,1.3,1.27],[1,1.29,9.07],[2,1.26,100]],"batl":[[0,1.8,270.73],[1,5,7.87],[2,1.8,0]],"ltp":1.46,"tv":5000.0,"id":5720747}]}]}
{"op":"mcm","clk":"1004790787","pt":1580637424733,"mc":[{"id":"1.168135792","rc":[{"batl":[[0,1.45,16.8],[1,1.8,270.73],[2,5,7.87]],"ltp":1.46,"tv":5000.0,"id":5720747}]}]}
{"op":"mcm","clk":"1004790922","pt":1580637426701,"mc":[{"id":"1.168135792","rc":[{"batl":[[0,5.1,202.82],[1,5.1,0]],"ltp":3.5,"tv":7575.46,"id":2249229}]}]}
{"op":"mcm","clk":"1004790985","pt":1580637427722,"mc":[{"id":"1.168135792","rc":[{"batb":[[0,1.32,441.53],[1,1.3,1.27],[2,1.29,9.07]],"ltp":1.46,"tv":5000.0,"id":5720747}]}]}
{"op":"mcm","clk":"1004791101","pt":1580637429639,"mc":[{"id":"1.168135792","rc":[{"batl":[[0,3.25,2.64],[1,5.1,202.82]],"ltp":3.5,"tv":7575.46,"id":2249229}]}]}
{"op":"mcm","clk":"1004791286","pt":1580637432618,"mc":[{"id":"1.168135792","rc":[{"batb":[[0,1.36,1082.79],[1,1.35,844.63],[2,1.33,151.51]],"batl":[[1,1.46,696.34],[2,1.47,558.17]],"ltp":1.46,"tv":5000.0,"id":5720747}]}]}
{"op":"mcm","clk":"1004791356","pt":1580637433746,"mc":[{"id":"1.168135792","rc":[{"trd":[[3.25,0.89]],"batl":[[0,3.25,1.76]],"ltp":3.25,"tv":7576.35,"id":2249229},{"trd":[[1.44,76.42]],"ltp":1.44,"tv":5002.0,"id":5720747}],"tv":12578.36}]}
{"op":"mcm","clk":"1004791409","pt":1580637434723,"mc":[{"id":"1.168135792","rc":[{"trd":[[3.25,2.64]],"batl":[[0,5.1,202.82],[1,5.1,0]],"ltp":3.25,"tv":7578.11,"id":2249229},{"trd":[[1.44,80.38]],"batl":[[0,1.44,46.04],[1,1.45,16.8],[2,1.46,696.34]],"ltp":1.44,"tv":5005.96,"id":5720747}],"tv":12584.08}]}
{"op":"mcm","clk":"1004791536","pt":1580637436755,"mc":[{"id":"1.168135792","rc":[{"batl":[[0,1.45,16.8],[1,1.46,696.34],[2,1.47,558.17]],"ltp":1.44,"tv":5005.96,"id":5720747}]}]}
{"op":"mcm","clk":"1004791741","pt":1580637440748,"mc":[{"id":"1.168135792","rc":[{"batb":[[2,1.32,441.53]],"ltp":1.44,"tv":5005.96,"id":5720747}]}]}
{"op":"mcm","clk":"1004791819","pt":1580637441728,"mc":[{"id":"1.168135792","rc":[{"trd":[[1.36,91.9]],"batb":[[0,1.36,1036.84]],"ltp":1.36,"tv":5097.86,"id":5720747}],"tv":12675.97}]}
{"op":"mcm","clk":"1004791877","pt":1580637442756,"mc":[{"id":"1.168135792","rc":[{"batl":[[0,3.25,2],[1,5.1,202.82]],"ltp":3.25,"tv":7578.11,"id":2249229}]}]}
{"op":"mcm","clk":"1004791967","pt":1580637444518,"mc":[{"id":"1.168135792","rc":[{"batb":[[0,1.32,441.53],[1,1.3,1.27],[2,1.29,9.07]],"batl":[[1,1.8,270.73],[2,5,7.87]],"ltp":1.36,"tv":5097.86,"id":5720747}]}]}
{"op":"mcm","clk":"1004792020","pt":1580637445550,"mc":[{"id":"1.168135792","rc":[{"batl":[[1,5.1,0]],"ltp":3.25,"tv":7578.11,"id":2249229}]}]}
{"op":"mcm","clk":"1004792080","pt":1580637446636,"mc":[{"id":"1.168135792","rc":[{"batb":[[0,1.4,312.97],[1,1.32,441.53],[2,1.3,1.27]],"ltp":1.36,"tv":5097.86,"id":5720747}]}]}
{"op":"mcm","clk":"1004792201","pt":1580637448759,"mc":[{"id":"1.168135792","rc":[{"trd":[[1.45,7.86]],"batl":[[0,1.45,12.87]],"ltp":1.45,"tv":5105.73,"id":5720747}],"tv":12683.84}]}
{"op":"mcm","clk":"1004792247","pt":1580637449637,"mc":[{"id":"1.168135792","rc":[{"batl":[[1,4.7,216.48]],"ltp":3.25,"tv":7578.11,"id":2249229},{"batb":[[0,1.41,1067.41],[1,1.4,1023.57],[2,1.32,441.53]],"batl":[[1,1.46,708.79],[2,1.47,558.18]],"ltp":1.45,"tv":5105.73,"id":5720747}]}]}
{"op":"mcm","clk":"1004792439","pt":1580637452727,"mc":[{"id":"1.168135792","rc":[{"batb":[[1,1.4,710.6]],"ltp":1.45,"tv":5105.73,"id":5720747}]}]}
{"op":"mcm","clk":"1004792603","pt":1580637455452,"mc":[{"id":"1.168135792","rc":[{"batb":[[2,1.34,123]],"ltp":1.45,"tv":5105.73,"id":5720747}]}]}
{"op":"mcm","clk":"1004792681","pt":1580637456738,"mc":[{"id":"1.168135792","rc":[{"trd":[[3.2,1.77]],"ltp":3.2,"tv":7579.87,"id":2249229},{"trd":[[1.45,11.77]],"batl":[[0,1.45,8.96]],"ltp":1.45,"tv":5109.63,"id":5720747}],"tv":12689.51}]}
{"op":"mcm","clk":"1004792818","pt":1580637459665,"mc":[{"id":"1.168135792","rc":[{"batb":[[0,1.34,123],[1,1.33,100],[2,1.32,441.53]],"batl":[[1,1.8,270.73],[2,5,7.87]],"ltp":1.45,"tv":5109.63,"id":5720747}]}]}
{"op":"mcm","clk":"1004792918","pt":1580637461576,"mc":[{"id":"1.168135792","rc":[{"batb":[[0,1.35,142.85],[1,1.34,123],[2,1.33,100]],"ltp":1.45,"tv":5109.63,"id":5720747}]}]}
{"op":"mcm","clk":"1004792988","pt":1580637462760,"mc":[{"id":"1.168135792","rc":[{"trd":[[1.45,18.97]],"batl":[[0,1.45,5.37]],"ltp":1.45,"tv":5116.83,"id":5720747}],"tv":12696.71}]}
{"op":"mcm","clk":"1004793245","pt":1580637467461,"mc":[{"id":"1.168135792","rc":[{"batb":[[0,1.38,576.44],[1,1.37,780],[2,1.35,142.85]],"batl":[[1,1.53,394.6],[2,1.54,466.58]],"ltp":1.45,"tv":5116.83,"id":5720747}]}]}
{"op":"mcm","clk":"1004794046","pt":1580637482281,"mc":[{"id":"1.168135792","rc":[{"batb":[[2,1.34,123]],"ltp":1.45,"tv":5116.83,"id":5720747}]}]}
{"op":"mcm","clk":"1004794398","pt":1580637488715,"mc":[{"id":"1.168135792","rc":[{"batl":[[1,1.54,466.58],[2,1.8,270.73]],"ltp":1.45,"tv":5116.83,"id":5720747}]}]}
{"op":"mcm","clk":"1004794449","pt":1580637489793,"mc":[{"id":"1.168135792","rc":[{"batl":[[1,4.7,0]],"ltp":3.2,"tv":7579.87,"id":2249229},{"batl":[[2,1.8,1.68]],"ltp":1.45,"tv":5116.83,"id":5720747}]}]}
{"op":"mcm","clk":"1004794495","pt":1580637490719,"mc":[{"id":"1.168135792","rc":[{"batb":[[0,1.34,123],[1,1.33,100],[2,1.32,441.53]],"batl":[[1,1.8,1.68],[2,5,7.87]],"ltp":1.45,"tv":5116.83,"id":5720747}]}]}
{"op":"mcm","clk":"1004794838","pt":1580637496637,"mc":[{"id":"1.168135792","rc":[{"batb":[[2,1.29,9.07]],"ltp":1.45,"tv":5116.83,"id":5720747}]}]}
{"op":"mcm","clk":"1004794897","pt":1580637497619,"mc":[{"id":"1.168135792","rc":[{"batb":[[1,1.29,9.07],[2,1.25,10.52]],"ltp":1.45,"tv":5116.83,"id":5720747}]}]}
{"op":"mcm","clk":"1004795057","pt":1580637500754,"mc":[{"id":"1.168135792","rc":[{"batb":[[0,1.35,100],[1,1.34,123],[2,1.29,9.07]],"ltp":1.45,"tv":5116.83,"id":5720747}]}]}
{"op":"mcm","clk":"1004795325","pt":1580637505748,"mc":[{"id":"1.168135792","rc":[{"trd":[[3.25,4.64]],"ltp":3.25,"tv":7581.87,"id":2249229},{"trd":[[1.44,84.89]],"batl":[[0,1.42,45.49],[1,1.45,5.37],[2,1.8,1.68]],"ltp":1.44,"tv":5121.34,"id":5720747}],"tv":12703.22}]}
{"op":"mcm","clk":"1004795492","pt":1580637509555,"mc":[{"id":"1.168135792","rc":[{"batl":[[2,5,7.87]],"ltp":1.44,"tv":5121.34,"id":5720747}]}]}
{"op":"mcm","clk":"1004795643","pt":1580637512755,"mc":[{"id":"1.168135792","rc":[{"batl":[[0,1.42,170.68]],"ltp":1.44,"tv":5121.34,"id":5720747}]}]}
{"op":"mcm","clk":"1004795682","pt":1580637513530,"mc":[{"id":"1.168135792","rc":[{"batb":[[0,1.38,637.11],[1,1.37,779.36],[2,1.35,100]],"batl":[[0,1.42,912.31],[1,1.43,624.37],[2,1.45,5.37]],"ltp":1.44,"tv":5121.34,"id":5720747}]}]}
{"op":"mcm","clk":"1004795742","pt":1580637514769,"mc":[{"id":"1.168135792","rc":[{"batb":[[2,1.34,123]],"ltp":1.44,"tv":5121.34,"id":5720747}]}]}
{"op":"mcm","clk":"1004795797","pt":1580637515646,"mc":[{"id":"1.168135792","rc":[{"batb":[[1,1.37,835.08]],"ltp":1.44,"tv":5121.34,"id":5720747}]}]}
{"op":"mcm","clk":"1004795854","pt":1580637516674,"mc":[{"id":"1.168135792","rc":[{"batl":[[0,5.1,199.87]],"ltp":3.25,"tv":7581.87,"id":2249229}]}]}
{"op":"mcm","clk":"1004795972","pt":1580637518737,"mc":[{"id":"1.168135792","rc":[{"batl":[[0,1.42,787.12]],"ltp":1.44,"tv":5121.34,"id":5720747}]}]}
{"op":"mcm","clk":"1004796034","pt":1580637519764,"mc":[{"id":"1.168135792","rc":[{"batl":[[0,1.42,741.63]],"ltp":1.44,"tv":5121.34,"id":5720747}]}]}
{"op":"mcm","clk":"1004796142","pt":1580637521765,"mc":[{"id":"1.168135792","rc":[{"batb":[[1,1.37,779.36]],"ltp":1.44,"tv":5121.34,"id":5720747}]}]}
{"op":"mcm","clk":"1004796187","pt":1580637522747,"mc":[{"id":"1.168135792","rc":[{"trd":[[1.42,20.94]],"batl":[[0,1.42,737.06]],"ltp":1.42,"tv":5130.48,"id":5720747}],"tv":12712.36}]}
{"op":"mcm","clk":"1004796319","pt":1580637524761,"mc":[{"id":"1.168135792","rc":[{"batb":[[0,1.39,55.72],[1,1.38,637.11],[2,1.37,779.36]],"ltp":1.42,"tv":5130.48,"id":5720747}]}]}
{"op":"mcm","clk":"1004796361","pt":1580637525688,"mc":[{"id":"1.168135792","rc":[{"trd":[[1.42,24.3]],"batl":[[0,1.42,735.38]],"ltp":1.42,"tv":5133.84,"id":5720747}],"tv":12715.72}]}
{"op":"mcm","clk":"1004796417","pt":1580637526669,"mc":[{"id":"1.168135792","rc":[{"batb":[[1,1.29,9.07],[2,1.27,100]],"batl":[[0,1.45,5.37],[1,1.75,287.36],[2,5,7.87]],"ltp":1.42,"tv":5133.84,"id":5720747}]}]}
{"op":"mcm","clk":"1004796464","pt":1580637527646,"mc":[{"id":"1.168135792","rc":[{"batl":[[0,3.35,19.51],[1,5.1,199.87]],"ltp":3.25,"tv":7581.87,"id":2249229},{"batb":[[2,1.25,10.52]],"ltp":1.42,"tv":5133.84,"id":5720747}]}]}
{"op":"mcm","clk":"1004796543","pt":1580637528780,"mc":[{"id":"1.168135792","rc":[{"batb":[[0,1.39,178.72]],"ltp":1.42,"tv":5133.84,"id":5720747}]}]}
{"op":"mcm","clk":"1004796674","pt":1580637530791,"mc":[{"id":"1.168135792","rc":[{"batb":[[2,1.25,110.52]],"ltp":1.42,"tv":5133.84,"id":5720747}]}]}
{"op":"mcm","clk":"1004796739","pt":1580637531775,"mc":[{"id":"1.168135792","rc":[{"batb":[[0,1.39,55.72],[2,1.25,112.2]],"ltp":1.42,"tv":5133.84,"id":5720747}]}]}
{"op":"mcm","clk":"1004796826","pt":1580637533577,"mc":[{"id":"1.168135792","rc":[{"batl":[[0,5.1,199.87],[1,5.1,0]],"ltp":3.25,"tv":7581.87,"id":2249229}]}]}
{"op":"mcm","clk":"1004796937","pt":1580637535791,"mc":[{"id":"1.168135792","rc":[{"batl":[[0,3.35,4],[1,5.1,199.87]],"ltp":3.25,"tv":7581.87,"id":2249229}]}]}
{"op":"mcm","clk":"1004797047","pt":1580637537798,"mc":[{"id":"1.168135792","rc":[{"batb":[[0,1.4,874.49],[1,1.39,55.72],[2,1.29,9.07]],"ltp":1.42,"tv":5133.84,"id":5720747}]}]}
{"op":"mcm","clk":"1004797288","pt":1580637541779,"mc":[{"id":"1.168135792","rc":[{"batb":[[2,1.31,1324.5]],"batl":[[1,1.46,803.91],[2,1.47,555.43]],"ltp":1.42,"tv":5133.84,"id":5720747}]}]}
{"op":"mcm","clk":"1004797345","pt":1580637542815,"mc":[{"id":"1.168135792","rc":[{"batl":[[0,5.1,199.87],[1,5.1,0]],"ltp":3.25,"tv":7581.87,"id":2249229},{"batb":[[0,1.44,143],[1,1.4,874.49],[2,1.39,55.72]],"ltp":1.42,"tv":5133.84,"id":5720747}]}]}
{"op":"mcm","clk":"1004797526","pt":1580637545806,"mc":[{"id":"1.168135792","rc":[{"trd":[[3.2,4.2]],"batl":[[0,3.2,1.57],[1,5.1,199.87]],"ltp":3.2,"tv":7584.3,"id":2249229},{"trd":[[1.45,24.33]],"batl":[[0,1.46,803.91],[1,1.47,555.43],[2,1.75,287.36]],"ltp":1.45,"tv":5139.21,"id":5720747}],"tv":12723.52}]}
{"op":"mcm","clk":"1004797572","pt":1580637546784,"mc":[{"id":"1.168135792","rc":[{"batb":[[2,1.31,1324.5]],"ltp":1.45,"tv":5139.21,"id":5720747}]}]}
{"op":"mcm","clk":"1004797625","pt":1580637547814,"mc":[{"id":"1.168135792","rc":[{"trd":[[3.2,5.77]],"batl":[[0,5.1,199.87],[1,5.1,0]],"ltp":3.2,"tv":7585.87,"id":2249229},{"trd":[[1.44,370.89],[1.45,27.8]],"batb":[[0,1.4,874.49],[1,1.29,9.07],[2,1.25,112.2]],"batl":[[0,1.44,28.73],[1,1.46,803.91],[2,1.47,555.43]],"ltp":1.44,"tv":5428.67,"id":5720747}],"tv":13014.55}]}
{"op":"mcm","clk":"1004797677","pt":1580637548688,"mc":[{"id":"1.168135792","rc":[{"batl":[[0,1.46,803.91],[1,1.47,555.43],[2,1.75,287.36]],"ltp":1.44,"tv":5428.67,"id":5720747}]}]}
{"op":"mcm","clk":"1004797727","pt":1580637549725,"mc":[{"id":"1.168135792","rc":[{"batl":[[0,3.2,12.6],[1,5.1,199.87]],"ltp":3.2,"tv":7585.87,"id":2249229},{"batb":[[2,1.25,110.52]],"ltp":1.44,"tv":5428.67,"id":5720747}]}]}
{"op":"mcm","clk":"1004797759","pt":1580637550500,"mc":[{"id":"1.168135792","rc":[{"batl":[[1,5.1,0]],"ltp":3.2,"tv":7585.87,"id":2249229},{"batb":[[0,1.41,953.68],[1,1.4,1581.64],[2,1.29,9.07]],"ltp":1.44,"tv":5428.67,"id":5720747}]}]}
{"op":"mcm","clk":"1004797817","pt":1580637551786,"mc":[{"id":"1.168135792","rc":[{"trd":[[1.46,247]],"batl":[[0,1.46,680.42]],"ltp":1.46,"tv":5675.65,"id":5720747}],"tv":13261.53}]}
{"op":"mcm","clk":"1004797864","pt":1580637552816,"mc":[{"id":"1.168135792","rc":[{"trd":[[3.2,6.73]],"batl":[[0,3.2,11.65]],"ltp":3.2,"tv":7586.83,"id":2249229},{"trd":[[1.45,29.9]],"ltp":1.45,"tv":5677.76,"id":5720747}],"tv":13264.59}]}
{"op":"mcm","clk":"1004797916","pt":1580637553690,"mc":[{"id":"1.168135792","rc":[{"batl":[[0,3.2,19.03]],"ltp":3.2,"tv":7586.83,"id":2249229},{"trd":[[1.46,250.84]],"batl":[[0,1.46,678.5]],"ltp":1.46,"tv":5681.6,"id":5720747}],"tv":13268.43}]}
{"op":"mcm","clk":"1004797958","pt":1580637554721,"mc":[{"id":"1.168135792","rc":[{"batl":[[1,4.7,213.33]],"ltp":3.2,"tv":7586.83,"id":2249229}]}]}
{"op":"mcm","clk":"1004798014","pt":1580637555602,"mc":[{"id":"1.168135792","rc":[{"batb":[[0,1.45,21.12],[1,1.41,953.68],[2,1.4,707.15]],"ltp":1.46,"tv":5681.6,"id":5720747}]}]}
{"op":"mcm","clk":"1004798075","pt":1580637556531,"mc":[{"id":"1.168135792","rc":[{"trd":[[3.2,25.76]],"batl":[[0,4.7,213.33],[1,4.7,0]],"ltp":3.2,"tv":7605.87,"id":2249229},{"trd":[[1.45,71.91]],"batb":[[0,1.41,953.68],[1,1.4,707.15],[2,1.29,9.07]],"batl":[[0,1.44,14.29],[1,1.46,678.5],[2,1.47,555.43]],"ltp":1.45,"tv":5723.6,"id":5720747}],"tv":13329.47}]}
{"op":"mcm","clk":"1004798213","pt":1580637558806,"mc":[{"id":"1.168135792","rc":[{"trd":[[1.44,399.48],[1.46,1607.84]],"batb":[[0,1.46,181.7],[1,1.41,953.68],[2,1.4,707.15]],"batl":[[0,1.47,555.43],[1,1.75,287.36],[2,5,7.87]],"ltp":1.46,"tv":7109.18,"id":5720747}],"tv":14715.05}]}
{"op":"mcm","clk":"1004798267","pt":1580637559736,"mc":[{"id":"1.168135792","rc":[{"trd":[[1.47,4.71]],"batb":[[0,1.46,202.68]],"batl":[[0,1.47,555.2]],"ltp":1.47,"tv":7109.64,"id":5720747}],"tv":14715.51}]}
{"op":"mcm","clk":"1004798337","pt":1580637560816,"mc":[{"id":"1.168135792","rc":[{"trd":[[3.15,30.29],[3.2,42.25]],"ltp":3.2,"tv":7652.65,"id":2249229},{"trd":[[1.46,1643.99]],"batb":[[0,1.46,166.54],[1,1.41,678.34],[2,1.29,9.07]],"ltp":1.46,"tv":7145.78,"id":5720747}],"tv":14798.43}]}
{"op":"mcm","clk":"1004798388","pt":1580637561748,"mc":[{"id":"1.168135792","rc":[{"batb":[[1,1.29,9.07],[2,1.25,110.52]],"batl":[[0,1.75,287.36],[1,5,7.87],[2,5,0]],"ltp":1.46,"tv":7145.78,"id":5720747}]}]}
{"op":"mcm","clk":"1004798441","pt":1580637562623,"mc":[{"id":"1.168135792","rc":[{"batb":[[0,1.46,222.21],[1,1.44,50.65],[2,1.29,9.07]],"ltp":1.46,"tv":7145.78,"id":5720747}]}]}
{"op":"mcm","clk":"1004798568","pt":1580637564747,"mc":[{"id":"1.168135792","rc":[{"batl":[[0,3.15,29.26],[1,4.7,213.33]],"ltp":3.2,"tv":7652.65,"id":2249229}]}]}
{"op":"mcm","clk":"1004798820","pt":1580637568760,"mc":[{"id":"1.168135792","rc":[{"batb":[[0,1.46,201.23],[2,1.37,534.79]],"batl":[[0,1.49,594.42],[1,1.5,511.71],[2,1.75,287.36]],"ltp":1.46,"tv":7145.78,"id":5720747}]}]}
{"op":"mcm","clk":"1004798885","pt":1580637569431,"mc":[{"id":"1.168135792","rc":[{"batl":[[0,4.7,213.33],[1,4.7,0]],"ltp":3.2,"tv":7652.65,"id":2249229}]}]}
{"op":"mcm","clk":"1004799021","pt":1580637571749,"mc":[{"id":"1.168135792","rc":[{"batb":[[2,1.32,8.22]],"batl":[[0,1.75,287.36],[1,5,7.87],[2,1.75,0]],"ltp":1.46,"tv":7145.78,"id":5720747}]}]}
{"op":"mcm","clk":"1004799079","pt":1580637572627,"mc":[{"id":"1.168135792","rc":[{"batl":[[0,5,7.87],[1,5,0]],"ltp":1.46,"tv":7145.78,"id":5720747}]}]}
{"op":"mcm","clk":"1004799135","pt":1580637573662,"mc":[{"id":"1.168135792","rc":[{"batb":[[0,1.46,145.56]],"ltp":1.46,"tv":7145.78,"id":5720747}]}]}
{"op":"mcm","clk":"1004799195","pt":1580637574746,"mc":[{"id":"1.168135792","rc":[{"batl":[[0,1.48,50],[1,5,7.87]],"ltp":1.46,"tv":7145.78,"id":5720747}]}]}
{"op":"mcm","clk":"1004799261","pt":1580637575726,"mc":[{"id":"1.168135792","rc":[{"batl":[[0,3,5]],"ltp":3.2,"tv":7652.65,"id":2249229},{"batb":[[0,1.32,8.22],[1,1.29,9.07],[2,1.25,110.52]],"batl":[[0,5,7.87],[1,5,0]],"ltp":1.46,"tv":7145.78,"id":5720747}]}]}
{"op":"mcm","clk":"1004799334","pt":1580637576757,"mc":[{"id":"1.168135792","rc":[{"trd":[[3,12.84]],"batb":[[0,3,11.15],[1,2.5,7.39],[2,1.7,5.46]],"ltp":3.0,"tv":7665.48,"id":2249229},{"trd":[[1.49,80.02],[1.5,144.15]],"ltp":1.5,"tv":7251.45,"id":5720747}],"tv":14916.94}]}
{"op":"mcm","clk":"1004799403","pt":1580637577740,"mc":[{"id":"1.168135792","rc":[{"batl":[[0,1.6,757.23],[1,5,7.87]],"ltp":1.5,"tv":7251.45,"id":5720747}]}]}
{"op":"mcm","clk":"1004799453","pt":1580637578773,"mc":[{"id":"1.168135792","rc":[{"trd":[[3,23.98]],"batb":[[0,2.5,7.39],[1,1.7,5.46],[2,1.52,22.56]],"ltp":3.0,"tv":7676.63,"id":2249229},{"trd":[[1.5,166.42]],"batb":[[0,1.5,28.38],[1,1.32,8.22],[2,1.29,9.07]],"ltp":1.5,"tv":7273.72,"id":5720747}],"tv":14950.35}]}
{"op":"mcm","clk":"1004799557","pt":1580637580736,"mc":[{"id":"1.168135792","rc":[{"batl":[[0,5,7.87],[1,5,0]],"ltp":1.5,"tv":7273.72,"id":5720747}]}]}
{"op":"mcm","clk":"1004799709","pt":1580637583665,"mc":[{"id":"1.168135792","rc":[{"trd":[[1.5,223.22]],"batb":[[0,1.32,8.22],[1,1.29,9.07],[2,1.25,110.52]],"batl":[[0,1.5,21.59],[1,5,7.87]],"ltp":1.5,"tv":7330.51,"id":5720747}],"tv":15007.15}]}
{"op":"mcm","clk":"1004799807","pt":1580637585774,"mc":[{"id":"1.168135792","rc":[{"batb":[[2,1.26,19.69]],"ltp":1.5,"tv":7330.51,"id":5720747}]}]}
{"op":"mcm","clk":"1004799916","pt":1580637586758,"mc":[{"id":"1.168135792","rc":[{"batb":[[0,2.7,7.39],[1,2.5,7.39],[2,1.7,5.46]],"ltp":3.0,"tv":7676.63,"id":2249229}]}]}
{"op":"mcm","clk":"1004799978","pt":1580637587583,"mc":[{"id":"1.168135792","rc":[{"batl":[[0,5,7.87],[1,5,0]],"ltp":1.5,"tv":7330.51,"id":5720747}]}]}
{"op":"mcm","clk":"1004800267","pt":1580637591766,"mc":[{"id":"1.168135792","rc":[{"batb":[[1,1.3,2.52],[2,1.29,9.07]],"ltp":1.5,"tv":7330.51,"id":5720747}]}]}
{"op":"mcm","clk":"1004800319","pt":1580637592796,"mc":[{"id":"1.168135792","rc":[{"batb":[[1,2.5,27.39]],"ltp":3.0,"tv":7676.63,"id":2249229},{"batb":[[0,1.5,4.22],[1,1.32,8.22],[2,1.3,2.52]],"ltp":1.5,"tv":7330.51,"id":5720747}]}]}
{"op":"mcm","clk":"1004800451","pt":1580637594784,"mc":[{"id":"1.168135792","rc":[{"batb":[[2,1.72,24.23]],"ltp":3.0,"tv":7676.63,"id":2249229},{"trd":[[1.5,231.65]],"batb":[[0,1.32,8.22],[1,1.3,2.52],[2,1.29,9.07]],"batl":[[0,1.44,120.97],[1,5,7.87]],"ltp":1.5,"tv":7338.95,"id":5720747}],"tv":15015.59}]}
{"op":"mcm","clk":"1004800490","pt":1580637595683,"mc":[{"id":"1.168135792","rc":[{"batb":[[0,1.37,534.79],[1,1.36,801.84],[2,1.32,8.22]],"batl":[[0,1.41,901.06],[1,1.42,638.33],[2,1.44,120.97]],"ltp":1.5,"tv":7338.95,"id":5720747}]}]}
{"op":"mcm","clk":"1004800550","pt":1580637596766,"mc":[{"id":"1.168135792","rc":[{"batl":[[0,5.1,201.18]],"ltp":3.0,"tv":7676.63,"id":2249229}]}]}
{"op":"mcm","clk":"1004800603","pt":1580637597800,"mc":[{"id":"1.168135792","rc":[{"batl":[[2,1.75,291.09]],"ltp":1.5,"tv":7338.95,"id":5720747}]}]}
{"op":"mcm","clk":"1004800672","pt":1580637598786,"mc":[{"id":"1.168135792","rc":[{"trd":[[1.41,201.16]],"batl":[[0,1.41,800.48]],"ltp":1.41,"tv":7540.11,"id":5720747}],"tv":15216.75}]}
{"op":"mcm","clk":"1004800820","pt":1580637600817,"mc":[{"id":"1.168135792","rc":[{"trd":[[1.41,210.14]],"batl":[[0,1.41,795.99]],"ltp":1.41,"tv":7549.09,"id":5720747}],"tv":15225.72}]}
{"op":"mcm","clk":"1004800963","pt":1580637601798,"mc":[{"id":"1.168135792","rc":[{"trd":[[1.41,227.02]],"batl":[[0,1.41,787.55]],"ltp":1.41,"tv":7565.97,"id":5720747}],"tv":15242.61}]}
{"op":"mcm","clk":"1004801077","pt":1580637602802,"mc":[{"id":"1.168135792","rc":[{"trd":[[3.75,31.93]],"ltp":3.75,"tv":7708.55,"id":2249229},{"trd":[[1.37,87.39]],"batb":[[0,1.37,447.4]],"batl":[[2,1.6,757.23]],"ltp":1.37,"tv":7653.36,"id":5720747}],"tv":15361.92}]}
{"op":"mcm","clk":"1004801150","pt":1580637603456,"mc":[{"id":"1.168135792","rc":[{"batb":[[0,1.39,4.34],[1,1.37,447.4],[2,1.36,801.84]],"ltp":1.37,"tv":7653.36,"id":5720747}]}]}
{"op":"mcm","clk":"1004801518","pt":1580637607807,"mc":[{"id":"1.168135792","rc":[{"batb":[[1,1.33,529.79],[2,1.32,8.22]],"batl":[[0,1.6,757.23],[1,1.75,291.09],[2,5,7.87]],"ltp":1.37,"tv":7653.36,"id":5720747}]}]}
{"op":"mcm","clk":"1004801755","pt":1580637610719,"mc":[{"id":"1.168135792","rc":[{"batb":[[0,3,87.42],[1,2.7,7.39],[2,2.5,27.39]],"ltp":3.75,"tv":7708.55,"id":2249229},{"batb":[[0,1.41,145.56],[1,1.39,4.34],[2,1.33,529.79]],"batl":[[0,1.46,887.93],[1,1.47,552.33],[2,1.6,757.23]],"ltp":1.37,"tv":7653.36,"id":5720747}]}]}
{"op":"mcm","clk":"1004801899","pt":1580637612690,"mc":[{"id":"1.168135792","rc":[{"batb":[[2,1.32,8.22]],"ltp":1.37,"tv":7653.36,"id":5720747}]}]}
{"op":"mcm","clk":"1004802048","pt":1580637614810,"mc":[{"id":"1.168135792","rc":[{"batb":[[0,2.7,7.39],[1,2.5,27.39],[2,1.72,24.23]],"ltp":3.75,"tv":7708.55,"id":2249229}]}]}
{"op":"mcm","clk":"1004802099","pt":1580637615530,"mc":[{"id":"1.168135792","rc":[{"batb":[[1,2.5,7.39]],"ltp":3.75,"tv":7708.55,"id":2249229}]}]}
{"op":"mcm","clk":"1004802180","pt":1580637616819,"mc":[{"id":"1.168135792","rc":[{"batl":[[0,1.45,50],[1,1.46,887.93],[2,1.47,552.33]],"ltp":1.37,"tv":7653.36,"id":5720747}]}]}
{"op":"mcm","clk":"1004802239","pt":1580637617599,"mc":[{"id":"1.168135792","rc":[{"batb":[[0,3.2,158.94],[1,2.7,7.39],[2,2.5,7.39]],"ltp":3.75,"tv":7708.55,"id":2249229}]}]}
{"op":"mcm","clk":"1004802308","pt":1580637618628,"mc":[{"id":"1.168135792","rc":[{"trd":[[1.45,80.35]],"batl":[[0,1.45,45.78]],"ltp":1.45,"tv":7661.81,"id":5720747}],"tv":15370.37}]}
{"op":"mcm","clk":"1004802728","pt":1580637624637,"mc":[{"id":"1.168135792","rc":[{"batl":[[0,1.46,887.93],[1,1.47,552.33],[2,1.6,757.23]],"ltp":1.45,"tv":7661.81,"id":5720747}]}]}
{"op":"mcm","clk":"1004802800","pt":1580637625628,"mc":[{"id":"1.168135792","rc":[{"batb":[[1,1.32,8.22],[2,1.3,582.77]],"ltp":1.45,"tv":7661.81,"id":5720747}]}]}
{"op":"mcm","clk":"1004802886","pt":1580637626721,"mc":[{"id":"1.168135792","rc":[{"batb":[[0,2.7,7.39],[1,2.5,7.39],[2,1.72,24.23]],"ltp":3.75,"tv":7708.55,"id":2249229}]}]}
{"op":"mcm","clk":"1004802955","pt":1580637627753,"mc":[{"id":"1.168135792","rc":[{"batb":[[0,1.42,298.07],[1,1.41,1001.21],[2,1.4,703.29]],"ltp":1.45,"tv":7661.81,"id":5720747}]}]}
{"op":"mcm","clk":"1004803029","pt":1580637628738,"mc":[{"id":"1.168135792","rc":[{"trd":[[1.46,1660.63]],"batl":[[0,1.46,879.61]],"ltp":1.46,"tv":7678.45,"id":5720747}],"tv":15387.01}]}
{"op":"mcm","clk":"1004803207","pt":1580637631776,"mc":[{"id":"1.168135792","rc":[{"batl":[[0,4.7,214.73]],"ltp":3.75,"tv":7708.55,"id":2249229}]}]}
{"op":"mcm","clk":"1004803285","pt":1580637632765,"mc":[{"id":"1.168135792","rc":[{"batb":[[1,1.41,855.65]],"ltp":1.46,"tv":7678.45,"id":5720747}]}]}
{"op":"mcm","clk":"1004803318","pt":1580637633237,"mc":[{"id":"1.168135792","rc":[{"batb":[[0,1.41,855.65],[1,1.4,703.29],[2,1.36,485.64]],"ltp":1.46,"tv":7678.45,"id":5720747}]}]}
{"op":"mcm","clk":"1004803466","pt":1580637635348,"mc":[{"id":"1.168135792","rc":[{"batb":[[0,3,87.42],[1,2.7,7.39],[2,2.5,7.39]],"ltp":3.75,"tv":7708.55,"id":2249229},{"trd":[[1.46,1951.74]],"batl":[[0,1.46,734.05]],"ltp":1.46,"tv":7969.56,"id":5720747}],"tv":15678.12}]}
{"op":"mcm","clk":"1004803746","pt":1580637639651,"mc":[{"id":"1.168135792","rc":[{"batb":[[0,3,174.83]],"ltp":3.75,"tv":7708.55,"id":2249229}]}]}
{"op":"mcm","clk":"1004803815","pt":1580637640538,"mc":[{"id":"1.168135792","rc":[{"trd":[[3.15,59.55]],"ltp":3.15,"tv":7737.81,"id":2249229},{"trd":[[1.46,2014.86]],"batb":[[0,1.45,2.27],[1,1.36,485.64],[2,1.32,8.22]],"batl":[[0,1.6,757.23],[1,1.75,291.09],[2,5,7.87]],"ltp":1.46,"tv":8032.68,"id":5720747}],"tv":15770.5}]}
{"op":"mcm","clk":"1004803885","pt":1580637641765,"mc":[{"id":"1.168135792","rc":[{"batl":[[0,3.75,2.88],[1,4.7,214.73]],"ltp":3.15,"tv":7737.81,"id":2249229}]}]}
{"op":"mcm","clk":"1004804020","pt":1580637643780,"mc":[{"id":"1.168135792","rc":[{"batl":[[0,3.15,15.14],[1,3.75,2.88],[2,4.7,214.73]],"ltp":3.15,"tv":7737.81,"id":2249229}]}]}
{"op":"mcm","clk":"1004804151","pt":1580637645651,"mc":[{"id":"1.168135792","rc":[{"trd":[[3,153.98]],"batb":[[0,3,109.83]],"ltp":3.0,"tv":7867.82,"id":2249229}],"tv":15900.5}]}
{"op":"mcm","clk":"1004804361","pt":1580637648584,"mc":[{"id":"1.168135792","rc":[{"batb":[[0,1.46,2],[1,1.45,2.27],[2,1.36,485.64]],"batl":[[0,1.49,410.02],[1,1.5,511.88],[2,1.6,757.23]],"ltp":1.46,"tv":8032.68,"id":5720747}]}]}
{"op":"mcm","clk":"1004804430","pt":1580637649384,"mc":[{"id":"1.168135792","rc":[{"batb":[[1,1.36,485.64],[2,1.35,946.96]],"ltp":1.46,"tv":8032.68,"id":5720747}]}]}
{"op":"mcm","clk":"1004804583","pt":1580637651396,"mc":[{"id":"1.168135792","rc":[{"batl":[[0,3.75,2.88],[1,4.7,214.73],[2,4.7,0]],"ltp":3.0,"tv":7867.82,"id":2249229}]}]}
{"op":"mcm","clk":"1004804689","pt":1580637652705,"mc":[{"id":"1.168135792","rc":[{"trd":[[1.49,347.79]],"batl":[[0,1.49,276.14]],"ltp":1.49,"tv":8300.45,"id":5720747}],"tv":16168.27}]}
{"op":"mcm","clk":"1004804760","pt":1580637653756,"mc":[{"id":"1.168135792","rc":[{"trd":[[3,440.61]],"batb":[[0,2.7,7.39],[1,2.5,7.39],[2,1.72,24.23]],"ltp":3.0,"tv":8154.44,"id":2249229},{"trd":[[1.49,482.85]],"batl":[[0,1.49,141.08]],"ltp":1.49,"tv":8435.51,"id":5720747}],"tv":16589.96}]}
{"op":"mcm","clk":"1004804816","pt":1580637654586,"mc":[{"id":"1.168135792","rc":[{"trd":[[3.05,15.14]],"ltp":3.05,"tv":8169.59,"id":2249229},{"trd":[[1.48,31.23]],"batl":[[0,1.48,18.79],[1,1.49,141.08],[2,1.5,511.88]],"ltp":1.48,"tv":8466.72,"id":5720747}],"tv":16636.31}]}
{"op":"mcm","clk":"1004804931","pt":1580637655787,"mc":[{"id":"1.168135792","rc":[{"batl":[[1,1.5,511.88],[2,1.6,757.23]],"ltp":1.48,"tv":8466.72,"id":5720747}]}]}
{"op":"mcm","clk":"1004805116","pt":1580637658491,"mc":[{"id":"1.168135792","rc":[{"batb":[[0,1.36,485.64],[1,1.35,946.96],[2,1.34,865.86]],"batl":[[0,1.5,511.88],[1,1.6,757.23],[2,1.75,291.09]],"ltp":1.48,"tv":8466.72,"id":5720747}]}]}
{"op":"mcm","clk":"1004805194","pt":1580637659581,"mc":[{"id":"1.168135792","rc":[{"batb":[[1,1.32,8.22],[2,1.29,9.07]],"batl":[[0,1.6,757.23],[1,1.75,291.09],[2,5,7.87]],"ltp":1.48,"tv":8466.72,"id":5720747}]}]}
{"op":"mcm","clk":"1004805264","pt":1580637660778,"mc":[{"id":"1.168135792","rc":[{"batb":[[0,1.46,225.67],[1,1.36,485.64],[2,1.32,8.22]],"ltp":1.48,"tv":8466.72,"id":5720747}]}]}
{"op":"mcm","clk":"1004805348","pt":1580637661717,"mc":[{"id":"1.168135792","rc":[{"batb":[[1,1.43,32.3],[2,1.36,485.64]],"ltp":1.48,"tv":8466.72,"id":5720747}]}]}
{"op":"mcm","clk":"1004805423","pt":1580637662598,"mc":[{"id":"1.168135792","rc":[{"batl":[[0,1.49,50],[1,1.6,757.23],[2,1.75,291.09]],"ltp":1.48,"tv":8466.72,"id":5720747}]}]}
{"op":"mcm","clk":"1004805483","pt":1580637663481,"mc":[{"id":"1.168135792","rc":[{"batl":[[0,1.49,100]],"ltp":1.48,"tv":8466.72,"id":5720747}]}]}
{"op":"mcm","clk":"1004805540","pt":1580637664307,"mc":[{"id":"1.168135792","rc":[{"batb":[[0,3,87.42],[1,2.7,7.39],[2,2.5,7.39]],"ltp":3.05,"tv":8169.59,"id":2249229},{"trd":[[1.46,2014.89]],"batb":[[0,1.46,225.66]],"ltp":1.46,"tv":8466.75,"id":5720747}],"tv":16636.34}]}
{"op":"mcm","clk":"1004805608","pt":1580637665298,"mc":[{"id":"1.168135792","rc":[{"batb":[[0,3,174.83]],"ltp":3.05,"tv":8169.59,"id":2249229}]}]}
{"op":"mcm","clk":"1004805716","pt":1580637666802,"mc":[{"id":"1.168135792","rc":[{"batb":[[1,1.36,485.64],[2,1.32,8.22]],"ltp":1.46,"tv":8466.75,"id":5720747}]}]}
{"op":"mcm","clk":"1004805775","pt":1580637667731,"mc":[{"id":"1.168135792","rc":[{"batb":[[2,1.35,1030.32]],"batl":[[1,1.5,844.47],[2,1.51,495.12]],"ltp":1.46,"tv":8466.75,"id":5720747}]}]}
{"op":"mcm","clk":"1004805927","pt":1580637670024,"mc":[{"id":"1.168135792","rc":[{"trd":[[1.49,486.85]],"batl":[[0,1.49,98]],"ltp":1.49,"tv":8470.75,"id":5720747}],"tv":16640.34}]}
{"op":"mcm","clk":"1004806175","pt":1580637673503,"mc":[{"id":"1.168135792","rc":[{"trd":[[1.46,2018.89]],"batb":[[0,1.46,223.66]],"ltp":1.46,"tv":8474.75,"id":5720747}],"tv":16644.34}]}
{"op":"mcm","clk":"1004806574","pt":1580637678544,"mc":[{"id":"1.168135792","rc":[{"batb":[[0,1.46,223.67]],"ltp":1.46,"tv":8474.75,"id":5720747}]}]}
{"op":"mcm","clk":"1004806787","pt":1580637681621,"mc":[{"id":"1.168135792","rc":[{"trd":[[3.2,47.25]],"ltp":3.2,"tv":8174.59,"id":2249229},{"trd":[[1.46,2029.85]],"batb":[[0,1.46,212.71]],"ltp":1.46,"tv":8485.71,"id":5720747}],"tv":16660.3}]}
{"op":"mcm","clk":"1004806859","pt":1580637682758,"mc":[{"id":"1.168135792","rc":[{"batb":[[2,1.32,8.22]],"batl":[[1,1.6,757.23],[2,1.75,291.09]],"ltp":1.46,"tv":8485.71,"id":5720747}]}]}
{"op":"mcm","clk":"1004806927","pt":1580637683643,"mc":[{"id":"1.168135792","rc":[{"batl":[[0,1.6,757.23],[1,1.75,291.09],[2,5,7.87]],"ltp":1.46,"tv":8485.71,"id":5720747}]}]}
{"op":"mcm","clk":"1004807001","pt":1580637684730,"mc":[{"id":"1.168135792","rc":[{"batl":[[1,4.7,0]],"ltp":3.2,"tv":8174.59,"id":2249229}]}]}
{"op":"mcm","clk":"1004807145","pt":1580637686564,"mc":[{"id":"1.168135792","rc":[{"batb":[[0,2.7,7.39],[1,2.5,7.39],[2,1.72,24.23]],"ltp":3.2,"tv":8174.59,"id":2249229}]}]}
{"op":"mcm","clk":"1004807329","pt":1580637688741,"mc":[{"id":"1.168135792","rc":[{"batl":[[1,4.4,230.52]],"ltp":3.2,"tv":8174.59,"id":2249229},{"trd":[[1.5,297.21]],"batb":[[1,1.45,611.83],[2,1.44,616.52]],"batl":[[0,1.5,776.14],[1,1.51,495.12],[2,1.6,757.23]],"ltp":1.5,"tv":8551.27,"id":5720747}],"tv":16725.86}]}
{"op":"mcm","clk":"1004807384","pt":1580637689523,"mc":[{"id":"1.168135792","rc":[{"batb":[[0,1.45,611.85],[1,1.44,616.52],[2,1.32,8.22]],"ltp":1.5,"tv":8551.27,"id":5720747}]}]}
{"op":"mcm","clk":"1004807647","pt":1580637693529,"mc":[{"id":"1.168135792","rc":[{"trd":[[1.5,711.25]],"batl":[[0,1.5,569.13]],"ltp":1.5,"tv":8965.3,"id":5720747}],"tv":17139.9}]}
{"op":"mcm","clk":"1004807810","pt":1580637695768,"mc":[{"id":"1.168135792","rc":[{"batb":[[0,2.86,93.99],[1,2.7,7.39],[2,2.5,7.39]],"ltp":3.2,"tv":8174.59,"id":2249229}]}]}
{"op":"mcm","clk":"1004807858","pt":1580637696386,"mc":[{"id":"1.168135792","rc":[{"batb":[[1,2.82,96.06],[2,2.7,7.39]],"ltp":3.2,"tv":8174.59,"id":2249229},{"batl":[[2,1.75,291.09]],"ltp":1.5,"tv":8965.3,"id":5720747}]}]}
{"op":"mcm","clk":"1004807942","pt":1580637697685,"mc":[{"id":"1.168135792","rc":[{"batb":[[2,1.4,437.08]],"batl":[[0,1.5,742.29]],"ltp":1.5,"tv":8965.3,"id":5720747}]}]}
{"op":"mcm","clk":"1004808006","pt":1580637698469,"mc":[{"id":"1.168135792","rc":[{"batb":[[0,1.4,437.09],[1,1.32,8.22],[2,1.29,9.07]],"batl":[[0,1.75,291.09],[1,5,7.87],[2,1.75,0]],"ltp":1.5,"tv":8965.3,"id":5720747}]}]}
{"op":"mcm","clk":"1004808512","pt":1580637704808,"mc":[{"id":"1.168135792","rc":[{"batb":[[2,1.3,100]],"ltp":1.5,"tv":8965.3,"id":5720747}]}]}
{"op":"mcm","clk":"1004808602","pt":1580637705694,"mc":[{"id":"1.168135792","rc":[{"batb":[[0,1.42,679.87],[1,1.41,676.31],[2,1.4,437.08]],"batl":[[0,1.51,418.64],[1,1.52,484.98],[2,1.75,291.09]],"ltp":1.5,"tv":8965.3,"id":5720747}]}]}
{"op":"mcm","clk":"1004808748","pt":1580637707803,"mc":[{"id":"1.168135792","rc":[{"batl":[[2,1.53,50]],"ltp":1.5,"tv":8965.3,"id":5720747}]}]}
{"op":"mcm","clk":"1004808896","pt":1580637709779,"mc":[{"id":"1.168135792","rc":[{"batb":[[2,1.32,8.22]],"ltp":1.5,"tv":8965.3,"id":5720747}]}]}
{"op":"mcm","clk":"1004808964","pt":1580637710712,"mc":[{"id":"1.168135792","rc":[{"batb":[[0,2.7,7.39],[1,2.5,7.39],[2,1.72,24.23]],"ltp":3.2,"tv":8174.59,"id":2249229},{"batb":[[0,1.43,406.6],[1,1.42,679.85],[2,1.41,676.31]],"batl":[[0,1.5,50],[1,1.51,418.64],[2,1.52,484.98]],"ltp":1.5,"tv":8965.3,"id":5720747}]}]}
{"op":"mcm","clk":"1004809047","pt":1580637711807,"mc":[{"id":"1.168135792","rc":[{"batb":[[0,1.43,813.18]],"ltp":1.5,"tv":8965.3,"id":5720747}]}]}
{"op":"mcm","clk":"1004809130","pt":1580637712795,"mc":[{"id":"1.168135792","rc":[{"batl":[[0,1.51,418.64],[1,1.52,484.98],[2,1.53,50]],"ltp":1.5,"tv":8965.3,"id":5720747}]}]}
{"op":"mcm","clk":"1004809202","pt":1580637713785,"mc":[{"id":"1.168135792","rc":[{"batb":[[1,1.32,8.22],[2,1.3,100]],"ltp":1.5,"tv":8965.3,"id":5720747}]}]}
{"op":"mcm","clk":"1004809245","pt":1580637714503,"mc":[{"id":"1.168135792","rc":[{"batl":[[2,1.75,291.09]],"ltp":1.5,"tv":8965.3,"id":5720747}]}]}
{"op":"mcm","clk":"1004809442","pt":1580637716596,"mc":[{"id":"1.168135792","rc":[{"trd":[[2.96,35.36]],"ltp":2.96,"tv":8209.95,"id":2249229},{"trd":[[1.51,69.35]],"batb":[[0,1.46,961.32],[1,1.45,600.8],[2,1.43,813.17]],"batl":[[0,1.51,349.29]],"ltp":1.51,"tv":9034.65,"id":5720747}],"tv":17244.61}]}
{"op":"mcm","clk":"1004809590","pt":1580637718712,"mc":[{"id":"1.168135792","rc":[{"batb":[[0,1.46,579.08],[1,1.43,813.17],[2,1.32,8.22]],"batl":[[0,1.52,484.98],[1,1.75,291.09],[2,5,7.87]],"ltp":1.51,"tv":9034.65,"id":5720747}]}]}
{"op":"mcm","clk":"1004809656","pt":1580637719596,"mc":[{"id":"1.168135792","rc":[{"batb":[[1,1.32,8.22],[2,1.3,100]],"ltp":1.51,"tv":9034.65,"id":5720747}]}]}
{"op":"mcm","clk":"1004809869","pt":1580637721654,"mc":[{"id":"1.168135792","rc":[{"trd":[[2.98,3.16]],"ltp":2.98,"tv":8213.11,"id":2249229},{"trd":[[1.51,75.59]],"batb":[[0,1.51,2.16],[1,1.46,579.08],[2,1.32,8.22]],"ltp":1.51,"tv":9040.9,"id":5720747}],"tv":17254.01}]}
{"op":"mcm","clk":"1004810034","pt":1580637723636,"mc":[{"id":"1.168135792","rc":[{"batl":[[0,2.96,25.21],[1,3.75,2.88],[2,4.4,230.52]],"ltp":2.98,"tv":8213.11,"id":2249229},{"batb":[[1,1.47,409.45],[2,1.46,579.08]],"batl":[[0,1.52,870.99],[1,1.53,469.63],[2,1.75,291.09]],"ltp":1.51,"tv":9040.9,"id":5720747}]}]}
{"op":"mcm","clk":"1004810305","pt":1580637726763,"mc":[{"id":"1.168135792","rc":[{"batl":[[0,3.75,2.88],[1,4.4,230.52],[2,4.4,0]],"ltp":2.98,"tv":8213.11,"id":2249229}]}]}
{"op":"mcm","clk":"1004810426","pt":1580637727820,"mc":[{"id":"1.168135792","rc":[{"trd":[[2.98,4.26]],"batb":[[0,2.98,35.04],[1,2.72,101.65],[2,2.7,7.39]],"ltp":2.98,"tv":8214.21,"id":2249229},{"trd":[[1.51,77.75]],"batb":[[0,1.47,409.45],[1,1.46,579.08],[2,1.42,416.26]],"ltp":1.51,"tv":9043.05,"id":5720747}],"tv":17257.26}]}
{"op":"mcm","clk":"1004810731","pt":1580637730752,"mc":[{"id":"1.168135792","rc":[{"trd":[[2.98,54.67]],"batb":[[0,2.98,9.83]],"ltp":2.98,"tv":8264.62,"id":2249229}],"tv":17307.68}]}
{"op":"mcm","clk":"1004811089","pt":1580637734759,"mc":[{"id":"1.168135792","rc":[{"batl":[[0,3,333],[1,3.75,2.88],[2,4.4,230.52]],"ltp":2.98,"tv":8264.62,"id":2249229}]}]}
{"op":"mcm","clk":"1004811952","pt":1580637744358,"mc":[{"id":"1.168135792","rc":[{"batb":[[0,2.98,22.43]],"ltp":2.98,"tv":8264.62,"id":2249229}]}]}
{"op":"mcm","clk":"1004812119","pt":1580637746658,"mc":[{"id":"1.168135792","rc":[{"trd":[[2.98,57.21]],"batb":[[0,2.98,19.9],[1,2.96,4.28],[2,2.72,101.65]],"ltp":2.98,"tv":8267.15,"id":2249229},{"trd":[[1.51,82.75]],"ltp":1.51,"tv":9048.05,"id":5720747}],"tv":17315.21}]}
{"op":"mcm","clk":"1004812271","pt":1580637748652,"mc":[{"id":"1.168135792","rc":[{"batb":[[0,2.98,12.6]],"ltp":2.98,"tv":8267.15,"id":2249229}]}]}
{"op":"mcm","clk":"1004812342","pt":1580637749584,"mc":[{"id":"1.168135792","rc":[{"trd":[[2.98,69.81]],"batb":[[0,2.96,4.28],[1,2.72,101.65],[2,2.7,7.39]],"ltp":2.98,"tv":8279.76,"id":2249229},{"trd":[[1.51,107.62]],"batb":[[0,1.51,9.72],[1,1.47,409.45],[2,1.46,579.08]],"ltp":1.51,"tv":9072.92,"id":5720747}],"tv":17352.69}]}
{"op":"mcm","clk":"1004812581","pt":1580637752660,"mc":[{"id":"1.168135792","rc":[{"trd":[[2.98,74.73],[3,445.35]],"batl":[[0,3,330.63]],"ltp":3.0,"tv":8289.42,"id":2249229},{"trd":[[1.51,117.34]],"batb":[[0,1.47,409.45],[1,1.46,579.08],[2,1.42,416.26]],"ltp":1.51,"tv":9082.65,"id":5720747}],"tv":17372.07}]}
{"op":"mcm","clk":"1004812872","pt":1580637756777,"mc":[{"id":"1.168135792","rc":[{"batb":[[0,2.72,101.65],[1,2.7,7.39],[2,2.5,7.39]],"ltp":3.0,"tv":8289.42,"id":2249229},{"batl":[[0,1.51,10.13],[1,1.52,870.99],[2,1.53,469.63]],"ltp":1.51,"tv":9082.65,"id":5720747}]}]}
{"op":"mcm","clk":"1004812935","pt":1580637757801,"mc":[{"id":"1.168135792","rc":[{"trd":[[3,447.79]],"batl":[[0,3,328.19]],"ltp":3.0,"tv":8291.86,"id":2249229},{"trd":[[1.5,716.12]],"ltp":1.5,"tv":9087.52,"id":5720747}],"tv":17379.38}]}
{"op":"mcm","clk":"1004813070","pt":1580637759578,"mc":[{"id":"1.168135792","rc":[{"batb":[[0,2.94,4.28],[1,2.72,101.65],[2,2.7,7.39]],"ltp":3.0,"tv":8291.86,"id":2249229}]}]}
{"op":"mcm","clk":"1004813162","pt":1580637760716,"mc":[{"id":"1.168135792","rc":[{"trd":[[3,450.29]],"batl":[[0,3,325.69]],"ltp":3.0,"tv":8294.36,"id":2249229},{"trd":[[1.5,721.12]],"ltp":1.5,"tv":9092.52,"id":5720747}],"tv":17386.88}]}
{"op":"mcm","clk":"1004813493","pt":1580637764789,"mc":[{"id":"1.168135792","rc":[{"trd":[[2.96,40.53]],"batl":[[0,2.96,10.56],[1,3,325.69],[2,3.75,2.88]],"ltp":2.96,"tv":8299.53,"id":2249229},{"trd":[[1.51,127.47]],"batl":[[0,1.52,870.99],[1,1.53,469.63],[2,1.75,291.09]],"ltp":1.51,"tv":9102.65,"id":5720747}],"tv":17402.19}]}
{"op":"mcm","clk":"1004813559","pt":1580637765727,"mc":[{"id":"1.168135792","rc":[{"trd":[[2.96,51.1],[3,453.14]],"batl":[[0,3,323.18],[1,3.75,2.88],[2,4.4,230.52]],"ltp":3.0,"tv":8312.94,"id":2249229},{"trd":[[1.5,725.45],[1.51,148.18]],"ltp":1.5,"tv":9127.68,"id":5720747}],"tv":17440.63}]}
{"op":"mcm","clk":"1004814068","pt":1580637772799,"mc":[{"id":"1.168135792","rc":[{"trd":[[3,454.4]],"batl":[[0,3,321.92]],"ltp":3.0,"tv":8314.2,"id":2249229},{"trd":[[1.5,727.97]],"ltp":1.5,"tv":9130.2,"id":5720747}],"tv":17444.41}]}
{"op":"mcm","clk":"1004814629","pt":1580637781228,"mc":[{"id":"1.168135792","rc":[{"trd":[[2.94,3.54]],"batb":[[0,2.94,2.51]],"ltp":2.94,"tv":8317.74,"id":2249229}],"tv":17447.95}]}
{"op":"mcm","clk":"1004815063","pt":1580637787757,"mc":[{"id":"1.168135792","rc":[{"trd":[[1.52,1554]],"batl":[[0,1.52,93.99]],"ltp":1.52,"tv":10684.2,"id":5720747}],"tv":19001.95}]}
{"op":"mcm","clk":"1004815490","pt":1580637793637,"mc":[{"id":"1.168135792","rc":[{"batb":[[0,1.47,705.3]],"batl":[[0,1.52,585.21]],"ltp":1.52,"tv":10684.2,"id":5720747}]}]}
{"op":"mcm","clk":"1004815551","pt":1580637794783,"mc":[{"id":"1.168135792","rc":[{"batb":[[0,1.42,416.28],[1,1.32,8.22],[2,1.3,103.36]],"batl":[[0,1.75,291.09],[1,5,7.87],[2,1.75,0]],"ltp":1.52,"tv":10684.2,"id":5720747}]}]}
{"op":"mcm","clk":"1004815600","pt":1580637795456,"mc":[{"id":"1.168135792","rc":[{"batl":[[0,1.52,33.93],[1,1.75,291.09],[2,5,7.87]],"ltp":1.52,"tv":10684.2,"id":5720747}]}]}
{"op":"mcm","clk":"1004815809","pt":1580637798565,"mc":[{"id":"1.168135792","rc":[{"batb":[[0,1.51,19],[1,1.42,416.28],[2,1.32,8.22]],"ltp":1.52,"tv":10684.2,"id":5720747}]}]}
{"op":"mcm","clk":"1004816005","pt":1580637801676,"mc":[{"id":"1.168135792","rc":[{"batb":[[2,2.5,7.39]],"ltp":2.94,"tv":8317.74,"id":2249229},{"batb":[[2,1.38,581.02]],"batl":[[1,1.72,544.28],[2,1.74,599.97]],"ltp":1.52,"tv":10684.2,"id":5720747}]}]}
{"op":"mcm","clk":"1004816170","pt":1580637804489,"mc":[{"id":"1.168135792","rc":[{"batb":[[0,2.94,9.9]],"ltp":2.94,"tv":8317.74,"id":2249229}]}]}
{"op":"mcm","clk":"1004816326","pt":1580637806656,"mc":[{"id":"1.168135792","rc":[{"trd":[[1.51,168.18]],"batb":[[0,1.51,9]],"ltp":1.51,"tv":10704.2,"id":5720747}],"tv":19021.95}]}
{"op":"mcm","clk":"1004816775","pt":1580637812787,"mc":[{"id":"1.168135792","rc":[{"trd":[[2.98,79.29]],"batb":[[0,2.94,10.34]],"ltp":2.98,"tv":8322.3,"id":2249229},{"trd":[[1.51,177.18]],"batb":[[0,1.42,416.28],[1,1.38,581.02],[2,1.37,767.95]],"ltp":1.51,"tv":10713.2,"id":5720747}],"tv":19035.51}]}
{"op":"mcm","clk":"1004817095","pt":1580637816791,"mc":[{"id":"1.168135792","rc":[{"batl":[[0,3.75,2.88],[1,4.4,230.52],[2,4.4,0]],"ltp":2.98,"tv":8322.3,"id":2249229}]}]}
{"op":"mcm","clk":"1004817441","pt":1580637821517,"mc":[{"id":"1.168135792","rc":[{"batb":[[0,1.38,581.04],[1,1.37,767.95],[2,1.32,8.22]],"batl":[[0,1.72,544.28],[1,1.74,599.97],[2,1.75,291.09]],"ltp":1.51,"tv":10713.2,"id":5720747}]}]}
{"op":"mcm","clk":"1004817554","pt":1580637823130,"mc":[{"id":"1.168135792","rc":[{"batb":[[0,1.39,448.3],[1,1.38,581.02],[2,1.37,767.95]],"ltp":1.51,"tv":10713.2,"id":5720747}]}]}
{"op":"mcm","clk":"1004817648","pt":1580637824596,"mc":[{"id":"1.168135792","rc":[{"batb":[[0,2.94,2.95]],"ltp":2.98,"tv":8322.3,"id":2249229}]}]}
{"op":"mcm","clk":"1004817736","pt":1580637825710,"mc":[{"id":"1.168135792","rc":[{"batb":[[1,2.5,7.39],[2,1.7,5.46]],"ltp":2.98,"tv":8322.3,"id":2249229},{"batb":[[1,1.32,8.22],[2,1.3,103.36]],"batl":[[0,1.75,291.09],[1,5,7.87],[2,1.75,0]],"ltp":1.51,"tv":10713.2,"id":5720747}]}]}
{"op":"mcm","clk":"1004817793","pt":1580637826645,"mc":[{"id":"1.168135792","rc":[{"batl":[[1,4.4,0]],"ltp":2.98,"tv":8322.3,"id":2249229}]}]}
{"op":"mcm","clk":"1004817869","pt":1580637827740,"mc":[{"id":"1.168135792","rc":[{"batb":[[2,2.4,124.88]],"ltp":2.98,"tv":8322.3,"id":2249229},{"batb":[[0,1.32,8.23],[1,1.3,103.36],[2,1.29,9.07]],"ltp":1.51,"tv":10713.2,"id":5720747}]}]}
{"op":"mcm","clk":"1004817942","pt":1580637828734,"mc":[{"id":"1.168135792","rc":[{"trd":[[2.94,8.57],[2.98,80.17]],"batb":[[0,2.5,7.39],[1,2.42,123.12]],"batl":[[0,2.94,16.01],[1,3.75,2.88]],"ltp":2.94,"tv":8328.2,"id":2249229}],"tv":19041.41}]}
{"op":"mcm","clk":"1004818069","pt":1580637830503,"mc":[{"id":"1.168135792","rc":[{"batl":[[2,5.1,201.18]],"ltp":2.94,"tv":8328.2,"id":2249229}]}]}
{"op":"mcm","clk":"1004818166","pt":1580637831700,"mc":[{"id":"1.168135792","rc":[{"trd":[[2.94,24.58]],"batl":[[0,3.75,2.88],[1,5.1,201.18],[2,5.1,0]],"ltp":2.94,"tv":8344.22,"id":2249229},{"trd":[[1.46,2029.89],[1.51,208.36]],"batb":[[0,1.38,575.68],[1,1.37,767.96],[2,1.32,8.22]],"batl":[[0,1.42,729.96],[1,1.43,615.01],[2,1.75,291.09]],"ltp":1.46,"tv":10744.42,"id":5720747}],"tv":19088.64}]}
{"op":"mcm","clk":"1004818231","pt":1580637832624,"mc":[{"id":"1.168135792","rc":[{"batb":[[1,1.7,5.46],[2,1.52,22.56]],"ltp":2.94,"tv":8344.22,"id":2249229}]}]}
{"op":"mcm","clk":"1004818423","pt":1580637835631,"mc":[{"id":"1.168135792","rc":[{"batb":[[0,3,87.42],[1,2.5,7.39],[2,1.7,5.46]],"ltp":2.94,"tv":8344.22,"id":2249229},{"batb":[[0,1.38,691.75]],"ltp":1.46,"tv":10744.42,"id":5720747}]}]}
{"op":"mcm","clk":"1004818488","pt":1580637836620,"mc":[{"id":"1.168135792","rc":[{"batb":[[1,2.92,91.06],[2,2.5,7.39]],"ltp":2.94,"tv":8344.22,"id":2249229}]}]}
{"op":"mcm","clk":"1004818549","pt":1580637837553,"mc":[{"id":"1.168135792","rc":[{"batl":[[0,1.42,596.21]],"ltp":1.46,"tv":10744.42,"id":5720747}]}]}
{"op":"mcm","clk":"1004818798","pt":1580637841755,"mc":[{"id":"1.168135792","rc":[{"batb":[[2,2.9,5.46]],"ltp":2.94,"tv":8344.22,"id":2249229},{"batb":[[0,1.32,8.22],[1,1.3,100],[2,1.29,9.07]],"batl":[[0,1.75,291.09],[1,5,7.87],[2,1.75,0]],"ltp":1.46,"tv":10744.42,"id":5720747}]}]}
{"op":"mcm","clk":"1004818972","pt":1580637844763,"mc":[{"id":"1.168135792","rc":[{"batb":[[1,1.31,563.97],[2,1.3,100]],"ltp":1.46,"tv":10744.42,"id":5720747}]}]}
{"op":"mcm","clk":"1004819119","pt":1580637847047,"mc":[{"id":"1.168135792","rc":[{"batl":[[0,1.38,1.68],[1,1.75,291.09],[2,5,7.87]],"ltp":1.46,"tv":10744.42,"id":5720747}]}]}
{"op":"mcm","clk":"1004819213","pt":1580637848554,"mc":[{"id":"1.168135792","rc":[{"batb":[[1,1.31,1854.56],[2,1.3,1109.82]],"batl":[[0,1.56,765.11],[1,1.57,424.36],[2,1.75,291.09]],"ltp":1.46,"tv":10744.42,"id":5720747}]}]}
{"op":"mcm","clk":"1004819285","pt":1580637849740,"mc":[{"id":"1.168135792","rc":[{"batb":[[0,1.32,164.46],[2,1.3,1009.82]],"ltp":1.46,"tv":10744.42,"id":5720747}]}]}
{"op":"mcm","clk":"1004819354","pt":1580637850775,"mc":[{"id":"1.168135792","rc":[{"batb":[[0,2.92,91.06],[1,2.9,5.46],[2,2.7,7.39]],"ltp":2.94,"tv":8344.22,"id":2249229}]}]}
{"op":"mcm","clk":"1004819478","pt":1580637852643,"mc":[{"id":"1.168135792","rc":[{"batb":[[0,2.9,5.46],[1,2.7,7.39],[2,2.5,7.39]],"ltp":2.94,"tv":8344.22,"id":2249229}]}]}
{"op":"mcm","clk":"1004819525","pt":1580637853633,"mc":[{"id":"1.168135792","rc":[{"batb":[[0,1.32,264.46]],"ltp":1.46,"tv":10744.42,"id":5720747}]}]}
{"op":"mcm","clk":"1004819576","pt":1580637854777,"mc":[{"id":"1.168135792","rc":[{"batb":[[1,2.82,96.06],[2,2.8,97.13]],"ltp":2.94,"tv":8344.22,"id":2249229}]}]}
{"op":"mcm","clk":"1004819698","pt":1580637856746,"mc":[{"id":"1.168135792","rc":[{"batb":[[0,1.32,164.46]],"ltp":1.46,"tv":10744.42,"id":5720747}]}]}
{"op":"mcm","clk":"1004819813","pt":1580637858766,"mc":[{"id":"1.168135792","rc":[{"batb":[[0,1.32,156.24]],"ltp":1.46,"tv":10744.42,"id":5720747}]}]}
{"op":"mcm","clk":"1004819930","pt":1580637859755,"mc":[{"id":"1.168135792","rc":[{"batb":[[0,1.33,100],[1,1.32,156.24],[2,1.31,1854.56]],"ltp":1.46,"tv":10744.42,"id":5720747}]}]}
{"op":"mcm","clk":"1004820077","pt":1580637861784,"mc":[{"id":"1.168135792","rc":[{"trd":[[3.75,34.81]],"batl":[[0,5.1,201.18],[1,5.1,0]],"ltp":3.75,"tv":8347.1,"id":2249229},{"trd":[[1.36,99.85]],"batl":[[0,1.36,4.87],[1,1.56,765.11],[2,1.57,424.36]],"ltp":1.36,"tv":10752.37,"id":5720747}],"tv":19099.47}]}
{"op":"mcm","clk":"1004820208","pt":1580637863756,"mc":[{"id":"1.168135792","rc":[{"batb":[[2,1.31,563.97]],"batl":[[1,1.75,291.09],[2,5,7.87]],"ltp":1.36,"tv":10752.37,"id":5720747}]}]}
{"op":"mcm","clk":"1004820437","pt":1580637868584,"mc":[{"id":"1.168135792","rc":[{"trd":[[3.75,36.57]],"batl":[[0,3.75,2.02],[1,5.1,201.18]],"ltp":3.75,"tv":8348.86,"id":2249229},{"trd":[[1.36,104.72]],"batl":[[0,1.75,291.09],[1,5,7.87],[2,5,0]],"ltp":1.36,"tv":10757.24,"id":5720747}],"tv":19106.11}]}
{"op":"mcm","clk":"1004820595","pt":1580637871806,"mc":[{"id":"1.168135792","rc":[{"batb":[[2,1.31,1854.56]],"batl":[[0,1.56,765.11],[1,1.57,424.36],[2,1.75,291.09]],"ltp":1.36,"tv":10757.24,"id":5720747}]}]}
{"op":"mcm","clk":"1004821176","pt":1580637881637,"mc":[{"id":"1.168135792","rc":[{"batb":[[2,1.31,563.97]],"ltp":1.36,"tv":10757.24,"id":5720747}]}]}
{"op":"mcm","clk":"1004821209","pt":1580637882308,"mc":[{"id":"1.168135792","rc":[{"batl":[[0,3.75,9.41]],"ltp":3.75,"tv":8348.86,"id":2249229}]}]}
{"op":"mcm","clk":"1004821286","pt":1580637883814,"mc":[{"id":"1.168135792","rc":[{"batb":[[1,2.7,7.39],[2,2.5,7.39]],"ltp":3.75,"tv":8348.86,"id":2249229},{"batb":[[0,1.43,291.14],[1,1.33,100],[2,1.32,156.24]],"ltp":1.36,"tv":10757.24,"id":5720747}]}]}
{"op":"mcm","clk":"1004821320","pt":1580637884331,"mc":[{"id":"1.168135792","rc":[{"batl":[[1,5.1,0]],"ltp":3.75,"tv":8348.86,"id":2249229},{"batb":[[0,1.5,795.36],[1,1.49,531.92],[2,1.43,291.14]],"batl":[[2,5,7.87]],"ltp":1.36,"tv":10757.24,"id":5720747}]}]}
{"op":"mcm","clk":"1004821565","pt":1580637888753,"mc":[{"id":"1.168135792","rc":[{"batl":[[1,4,251.76]],"ltp":3.75,"tv":8348.86,"id":2249229},{"batl":[[2,1.93,219.22]],"ltp":1.36,"tv":10757.24,"id":5720747}]}]}
{"op":"mcm","clk":"1004821673","pt":1580637890810,"mc":[{"id":"1.168135792","rc":[{"batb":[[2,1.44,397.34]],"ltp":1.36,"tv":10757.24,"id":5720747}]}]}
{"op":"mcm","clk":"1004822105","pt":1580637897753,"mc":[{"id":"1.168135792","rc":[{"batb":[[0,1.44,397.34],[1,1.4,437.08],[2,1.29,9.07]],"batl":[[0,1.93,219.22],[1,5,7.87],[2,1.93,0]],"ltp":1.36,"tv":10757.24,"id":5720747}]}]}
{"op":"mcm","clk":"1004822313","pt":1580637900670,"mc":[{"id":"1.168135792","rc":[{"batb":[[1,2.5,7.39],[2,2.3,134.49]],"ltp":3.75,"tv":8348.86,"id":2249229}]}]}
{"op":"mcm","clk":"1004822635","pt":1580637904781,"mc":[{"id":"1.168135792","rc":[{"batb":[[2,1.38,995.07]],"batl":[[0,1.82,430.99],[1,1.84,500.92],[2,1.93,219.22]],"ltp":1.36,"tv":10757.24,"id":5720747}]}]}
{"op":"mcm","clk":"1004822770","pt":1580637906541,"mc":[{"id":"1.168135792","rc":[{"batb":[[0,1.4,437.08],[1,1.38,995.07],[2,1.37,771.21]],"ltp":1.36,"tv":10757.24,"id":5720747}]}]}
{"op":"mcm","clk":"1004823056","pt":1580637910653,"mc":[{"id":"1.168135792","rc":[{"trd":[[2.9,10.6]],"batb":[[0,2.5,7.55],[1,2.3,134.49],[2,1.7,5.46]],"ltp":2.9,"tv":8359.47,"id":2249229},{"batb":[[1,1.39,448.28],[2,1.38,995.07]],"ltp":1.36,"tv":10757.24,"id":5720747}],"tv":19116.71}]}
{"op":"mcm","clk":"1004823216","pt":1580637912775,"mc":[{"id":"1.168135792","rc":[{"batb":[[2,2.24,140.99]],"ltp":2.9,"tv":8359.47,"id":2249229},{"batb":[[2,1.29,9.07]],"batl":[[0,1.93,219.22],[1,5,7.87],[2,1.93,0]],"ltp":1.36,"tv":10757.24,"id":5720747}]}]}
{"op":"mcm","clk":"1004823347","pt":1580637914683,"mc":[{"id":"1.168135792","rc":[{"batb":[[0,1.29,9.07],[1,1.28,3.36],[2,1.27,9.74]],"ltp":1.36,"tv":10757.24,"id":5720747}]}]}
{"op":"mcm","clk":"1004823414","pt":1580637915678,"mc":[{"id":"1.168135792","rc":[{"batl":[[1,4,0]],"ltp":2.9,"tv":8359.47,"id":2249229},{"batl":[[0,1.47,125.19],[1,1.6,50],[2,1.75,432.96]],"ltp":1.36,"tv":10757.24,"id":5720747}]}]}
{"op":"mcm","clk":"1004823547","pt":1580637917704,"mc":[{"id":"1.168135792","rc":[{"batb":[[1,1.7,5.46],[2,1.52,22.56]],"ltp":2.9,"tv":8359.47,"id":2249229},{"batb":[[0,1.38,995.07],[1,1.37,771.21],[2,1.29,9.07]],"batl":[[0,1.43,979.6],[1,1.44,593.53],[2,1.47,125.19]],"ltp":1.36,"tv":10757.24,"id":5720747}]}]}
{"op":"mcm","clk":"1004823694","pt":1580637919784,"mc":[{"id":"1.168135792","rc":[{"batl":[[1,5.1,201.18]],"ltp":2.9,"tv":8359.47,"id":2249229}]}]}
{"op":"mcm","clk":"1004823837","pt":1580637921809,"mc":[{"id":"1.168135792","rc":[{"batl":[[2,1.75,724.05]],"ltp":1.36,"tv":10757.24,"id":5720747}]}]}
{"op":"mcm","clk":"1004823899","pt":1580637922803,"mc":[{"id":"1.168135792","rc":[{"batb":[[0,2.7,103],[1,2.5,7.39],[2,1.7,5.46]],"ltp":2.9,"tv":8359.47,"id":2249229}]}]}
{"op":"mcm","clk":"1004823976","pt":1580637923695,"mc":[{"id":"1.168135792","rc":[{"batb":[[0,2.8,97.29],[1,2.7,102.84],[2,2.5,7.39]],"ltp":2.9,"tv":8359.47,"id":2249229}]}]}
{"op":"mcm","clk":"1004824121","pt":1580637925786,"mc":[{"id":"1.168135792","rc":[{"batb":[[2,1.3,582.77]],"ltp":1.36,"tv":10757.24,"id":5720747}]}]}
{"op":"mcm","clk":"1004824311","pt":1580637928809,"mc":[{"id":"1.168135792","rc":[{"batb":[[0,1.3,582.77],[1,1.29,9.07],[2,1.28,3.36]],"batl":[[0,1.75,724.05],[1,5,7.87],[2,1.75,0]],"ltp":1.36,"tv":10757.24,"id":5720747}]}]}
{"op":"mcm","clk":"1004824563","pt":1580637932612,"mc":[{"id":"1.168135792","rc":[{"batb":[[2,1.7,5.46]],"ltp":2.9,"tv":8359.47,"id":2249229}]}]}
{"op":"mcm","clk":"1004824719","pt":1580637935204,"mc":[{"id":"1.168135792","rc":[{"batb":[[1,2.7,110.23]],"ltp":2.9,"tv":8359.47,"id":2249229}]}]}
{"op":"mcm","clk":"1004824811","pt":1580637936620,"mc":[{"id":"1.168135792","rc":[{"batb":[[0,1.3,1923.19],[1,1.29,1063.16]],"batl":[[0,1.59,530.68],[1,1.6,397.26],[2,1.75,724.05]],"ltp":1.36,"tv":10757.24,"id":5720747}]}]}
{"op":"mcm","clk":"1004825004","pt":1580637939637,"mc":[{"id":"1.168135792","rc":[{"trd":[[2.8,19.37],[2.9,10.92]],"batb":[[0,2.8,87.44]],"ltp":2.8,"tv":8379.16,"id":2249229}],"tv":19136.4}]}
{"op":"mcm","clk":"1004825119","pt":1580637941618,"mc":[{"id":"1.168135792","rc":[{"batb":[[1,2.72,101.65],[2,2.7,110.23]],"ltp":2.8,"tv":8379.16,"id":2249229},{"batl":[[0,1.55,1.68],[1,1.59,530.68],[2,1.6,397.26]],"ltp":1.36,"tv":10757.24,"id":5720747}]}]}
{"op":"mcm","clk":"1004825181","pt":1580637942711,"mc":[{"id":"1.168135792","rc":[{"batb":[[0,2.72,101.65],[1,2.7,110.23],[2,1.7,5.46]],"ltp":2.8,"tv":8379.16,"id":2249229},{"batb":[[0,1.31,563.97],[1,1.3,1923.19],[2,1.29,1063.16]],"batl":[[0,1.51,34.59],[1,1.55,1.68],[2,1.59,530.68]],"ltp":1.36,"tv":10757.24,"id":5720747}]}]}
{"op":"mcm","clk":"1004825407","pt":1580637947023,"mc":[{"id":"1.168135792","rc":[{"batb":[[0,1.45,18.7],[1,1.31,563.97],[2,1.3,1923.19]],"ltp":1.36,"tv":10757.24,"id":5720747}]}]}
{"op":"mcm","clk":"1004825550","pt":1580637949720,"mc":[{"id":"1.168135792","rc":[{"batb":[[1,1.32,104.18],[2,1.31,563.97]],"batl":[[2,1.75,724.05]],"ltp":1.36,"tv":10757.24,"id":5720747}]}]}
{"op":"mcm","clk":"1004825670","pt":1580637952155,"mc":[{"id":"1.168135792","rc":[{"trd":[[1.45,113.67]],"batb":[[0,1.45,2.04]],"ltp":1.45,"tv":10790.56,"id":5720747}],"tv":19169.72}]}
{"op":"mcm","clk":"1004825744","pt":1580637953461,"mc":[{"id":"1.168135792","rc":[{"batl":[[0,3.75,2.02]],"ltp":2.8,"tv":8379.16,"id":2249229}]}]}
{"op":"mcm","clk":"1004825927","pt":1580637956642,"mc":[{"id":"1.168135792","rc":[{"batl":[[1,4,7.39],[2,5.1,201.18]],"ltp":2.8,"tv":8379.16,"id":2249229}]}]}
{"op":"mcm","clk":"1004825984","pt":1580637957625,"mc":[{"id":"1.168135792","rc":[{"batl":[[2,1.59,528.09]],"ltp":1.45,"tv":10790.56,"id":5720747}]}]}
{"op":"mcm","clk":"1004826350","pt":1580637963674,"mc":[{"id":"1.168135792","rc":[{"batl":[[2,1.75,724.05]],"ltp":1.45,"tv":10790.56,"id":5720747}]}]}
{"op":"mcm","clk":"1004826464","pt":1580637965746,"mc":[{"id":"1.168135792","rc":[{"batb":[[0,2.7,7.39],[1,1.7,5.46],[2,1.52,22.56]],"ltp":2.8,"tv":8379.16,"id":2249229},{"batb":[[0,1.45,280.24]],"ltp":1.45,"tv":10790.56,"id":5720747}]}]}
{"op":"mcm","clk":"1004826512","pt":1580637966473,"mc":[{"id":"1.168135792","rc":[{"batl":[[2,5.1,0]],"ltp":2.8,"tv":8379.16,"id":2249229},{"batl":[[2,1.75,432.96]],"ltp":1.45,"tv":10790.56,"id":5720747}]}]}
{"op":"mcm","clk":"1004826634","pt":1580637968774,"mc":[{"id":"1.168135792","rc":[{"trd":[[1.51,277.54]],"batb":[[0,1.54,350.79],[1,1.53,476.07],[2,1.45,280.24]],"batl":[[0,1.55,1.68],[1,1.59,528.09],[2,1.6,397.26]],"ltp":1.51,"tv":10859.74,"id":5720747}],"tv":19238.9}]}
{"op":"mcm","clk":"1004826745","pt":1580637970588,"mc":[{"id":"1.168135792","rc":[{"batl":[[1,4,259.15]],"ltp":2.8,"tv":8379.16,"id":2249229},{"batb":[[0,1.53,476.07],[1,1.45,280.24],[2,1.29,9.07]],"ltp":1.51,"tv":10859.74,"id":5720747}]}]}
{"op":"mcm","clk":"1004826823","pt":1580637971785,"mc":[{"id":"1.168135792","rc":[{"batb":[[1,1.51,98.03],[2,1.45,2.04]],"ltp":1.51,"tv":10859.74,"id":5720747}]}]}
{"op":"mcm","clk":"1004826883","pt":1580637972695,"mc":[{"id":"1.168135792","rc":[{"batb":[[1,1.45,2.04],[2,1.29,9.07]],"ltp":1.51,"tv":10859.74,"id":5720747}]}]}
{"op":"mcm","clk":"1004826948","pt":1580637973796,"mc":[{"id":"1.168135792","rc":[{"batb":[[0,1.53,854.44],[1,1.52,491.31],[2,1.45,2.04]],"ltp":1.51,"tv":10859.74,"id":5720747}]}]}
{"op":"mcm","clk":"1004827228","pt":1580637977796,"mc":[{"id":"1.168135792","rc":[{"batb":[[0,1.7,5.46],[1,1.52,22.56],[2,1.35,5]],"ltp":2.8,"tv":8379.16,"id":2249229}]}]}
{"op":"mcm","clk":"1004827349","pt":1580637979674,"mc":[{"id":"1.168135792","rc":[{"batb":[[0,1.45,2.04],[1,1.4,437.08],[2,1.29,9.07]],"batl":[[1,1.93,219.22],[2,5,7.87]],"ltp":1.51,"tv":10859.74,"id":5720747}]}]}
{"op":"mcm","clk":"1004827412","pt":1580637980767,"mc":[{"id":"1.168135792","rc":[{"batb":[[0,2.5,7.39],[1,1.7,5.46],[2,1.52,22.56]],"ltp":2.8,"tv":8379.16,"id":2249229}]}]}
{"op":"mcm","clk":"1004827474","pt":1580637981599,"mc":[{"id":"1.168135792","rc":[{"batb":[[1,2.16,150.72],[2,1.7,5.46]],"ltp":2.8,"tv":8379.16,"id":2249229}]}]}
{"op":"mcm","clk":"1004827677","pt":1580637984457,"mc":[{"id":"1.168135792","rc":[{"batl":[[0,1.93,219.22],[1,5,7.87],[2,5,0]],"ltp":1.51,"tv":10859.74,"id":5720747}]}]}
{"op":"mcm","clk":"1004827795","pt":1580637986379,"mc":[{"id":"1.168135792","rc":[{"batb":[[2,1.37,609.73]],"batl":[[1,2,471.96],[2,2.02,377.54]],"ltp":1.51,"tv":10859.74,"id":5720747}]}]}
{"op":"mcm","clk":"1004827954","pt":1580637988577,"mc":[{"id":"1.168135792","rc":[{"batb":[[1,1.7,5.46],[2,1.52,22.56]],"ltp":2.8,"tv":8379.16,"id":2249229}]}]}
{"op":"mcm","clk":"1004828148","pt":1580637991701,"mc":[{"id":"1.168135792","rc":[{"batb":[[1,2.1,158.94],[2,1.7,5.46]],"ltp":2.8,"tv":8379.16,"id":2249229}]}]}
{"op":"mcm","clk":"1004828201","pt":1580637992691,"mc":[{"id":"1.168135792","rc":[{"batb":[[2,2.02,171.4]],"batl":[[0,3,5],[1,3.75,2.02],[2,4,259.15]],"ltp":2.8,"tv":8379.16,"id":2249229}]}]}
{"op":"mcm","clk":"1004828331","pt":1580637994582,"mc":[{"id":"1.168135792","rc":[{"batb":[[2,1.38,460.08]],"ltp":1.51,"tv":10859.74,"id":5720747}]}]}
{"op":"mcm","clk":"1004828395","pt":1580637995519,"mc":[{"id":"1.168135792","rc":[{"batb":[[0,2.1,158.94],[1,2.02,171.4],[2,1.7,5.46]],"ltp":2.8,"tv":8379.16,"id":2249229}]}]}
{"op":"mcm","clk":"1004828457","pt":1580637996405,"mc":[{"id":"1.168135792","rc":[{"batl":[[1,5,7.87],[2,2.02,0]],"ltp":1.51,"tv":10859.74,"id":5720747}]}]}
{"op":"mcm","clk":"1004828522","pt":1580637997602,"mc":[{"id":"1.168135792","rc":[{"batl":[[2,4,7.39]],"ltp":2.8,"tv":8379.16,"id":2249229}]}]}
{"op":"mcm","clk":"1004828667","pt":1580637999677,"mc":[{"id":"1.168135792","rc":[{"batb":[[0,1.6,469.54],[1,1.59,411.55],[2,1.45,2.04]],"batl":[[0,1.66,569.6],[1,1.68,673.38],[2,1.93,219.22]],"ltp":1.51,"tv":10859.74,"id":5720747}]}]}
{"op":"mcm","clk":"1004828731","pt":1580638000614,"mc":[{"id":"1.168135792","rc":[{"batb":[[0,1.45,2.04],[1,1.4,437.08],[2,1.38,460.08]],"batl":[[0,1.93,219.22],[1,5,7.87],[2,1.93,0]],"ltp":1.51,"tv":10859.74,"id":5720747}]}]}
{"op":"mcm","clk":"1004828810","pt":1580638001704,"mc":[{"id":"1.168135792","rc":[{"batl":[[1,3.75,272.06]],"ltp":2.8,"tv":8379.16,"id":2249229}]}]}
{"op":"mcm","clk":"1004829237","pt":1580638008724,"mc":[{"id":"1.168135792","rc":[{"trd":[[3,458.11]],"batl":[[0,3,1.29],[1,3.75,2.02]],"ltp":3.0,"tv":8382.87,"id":2249229},{"trd":[[1.5,735.4]],"batl":[[0,5,7.87],[1,5,0]],"ltp":1.5,"tv":10867.16,"id":5720747}],"tv":19250.03}]}
{"op":"mcm","clk":"1004829294","pt":1580638009716,"mc":[{"id":"1.168135792","rc":[{"batb":[[0,1.7,5.46],[1,1.52,22.56],[2,1.35,5]],"ltp":3.0,"tv":8382.87,"id":2249229},{"batb":[[0,1.91,380.69],[1,1.89,454.28],[2,1.76,164.72]],"batl":[[0,2,471.96],[1,2.02,377.54],[2,5,7.87]],"ltp":1.5,"tv":10867.16,"id":5720747}]}]}
{"op":"mcm","clk":"1004829493","pt":1580638012745,"mc":[{"id":"1.168135792","rc":[{"batl":[[0,2.76,377.94],[1,3,1.29],[2,3.75,2.02]],"ltp":3.0,"tv":8382.87,"id":2249229},{"batl":[[2,2.46,120.27]],"ltp":1.5,"tv":10867.16,"id":5720747}]}]}
{"op":"mcm","clk":"1004829611","pt":1580638014612,"mc":[{"id":"1.168135792","rc":[{"batb":[[2,1.77,64.93]],"ltp":1.5,"tv":10867.16,"id":5720747}]}]}
{"op":"mcm","clk":"1004829734","pt":1580638016742,"mc":[{"id":"1.168135792","rc":[{"trd":[[2.1,7.39]],"ltp":2.1,"tv":8390.26,"id":2249229},{"trd":[[1.91,118.91]],"batb":[[0,1.91,317.16]],"ltp":1.91,"tv":10986.07,"id":5720747}],"tv":19376.33}]}
{"op":"mcm","clk":"1004829789","pt":1580638017730,"mc":[{"id":"1.168135792","rc":[{"trd":[[1.91,753.22]],"batb":[[0,1.89,454.28],[1,1.77,64.93],[2,1.29,9.07]],"batl":[[0,1.91,102.94]],"ltp":1.91,"tv":11620.39,"id":5720747}],"tv":20010.65}]}
{"op":"mcm","clk":"1004829912","pt":1580638019758,"mc":[{"id":"1.168135792","rc":[{"batb":[[0,1.29,9.07],[1,1.28,3.36],[2,1.27,9.74]],"ltp":1.91,"tv":11620.39,"id":5720747}]}]}
{"op":"mcm","clk":"1004829982","pt":1580638020751,"mc":[{"id":"1.168135792","rc":[{"batl":[[1,1.99,304.53],[2,2.02,569.27]],"ltp":1.91,"tv":11620.39,"id":5720747}]}]}
{"op":"mcm","clk":"1004830043","pt":1580638021637,"mc":[{"id":"1.168135792","rc":[{"batb":[[0,1.6,83.33],[1,1.29,9.07],[2,1.28,3.36]],"ltp":1.91,"tv":11620.39,"id":5720747}]}]}
{"op":"mcm","clk":"1004830120","pt":1580638022735,"mc":[{"id":"1.168135792","rc":[{"batb":[[0,2.1,5],[1,1.7,5.46],[2,1.52,22.56]],"ltp":2.1,"tv":8390.26,"id":2249229},{"batb":[[0,1.66,264.9],[1,1.6,83.33],[2,1.29,9.07]],"batl":[[1,2.46,120.27],[2,5,7.87]],"ltp":1.91,"tv":11620.39,"id":5720747}]}]}
{"op":"mcm","clk":"1004830249","pt":1580638024654,"mc":[{"id":"1.168135792","rc":[{"trd":[[2.08,0.62],[2.1,17.39]],"batb":[[0,1.7,5.46],[1,1.52,22.56],[2,1.35,5]],"ltp":2.08,"tv":8400.88,"id":2249229},{"trd":[[1.91,753.9]],"batb":[[0,1.72,104.18],[1,1.66,264.9],[2,1.6,83.33]],"batl":[[0,2.46,120.27],[1,5,7.87],[2,5,0]],"ltp":1.91,"tv":11621.06,"id":5720747}],"tv":20021.94}]}
{"op":"mcm","clk":"1004830316","pt":1580638025747,"mc":[{"id":"1.168135792","rc":[{"batl":[[1,3.2,186.93],[2,3.25,274.07]],"ltp":1.91,"tv":11621.06,"id":5720747}]}]}
{"op":"mcm","clk":"1004830360","pt":1580638026630,"mc":[{"id":"1.168135792","rc":[{"batb":[[1,1.68,73.52],[2,1.66,264.9]],"ltp":1.91,"tv":11621.06,"id":5720747}]}]}
{"op":"mcm","clk":"1004830429","pt":1580638027771,"mc":[{"id":"1.168135792","rc":[{"batb":[[2,1.6,83.33]],"ltp":1.91,"tv":11621.06,"id":5720747}]}]}
{"op":"mcm","clk":"1004830539","pt":1580638029671,"mc":[{"id":"1.168135792","rc":[{"batb":[[0,1.91,5],[1,1.73,68.49],[2,1.72,104.18]],"ltp":1.91,"tv":11621.06,"id":5720747}]}]}
{"op":"mcm","clk":"1004830686","pt":1580638031791,"mc":[{"id":"1.168135792","rc":[{"batl":[[0,3,1.29],[1,3.75,2.02],[2,4,7.39]],"ltp":2.08,"tv":8400.88,"id":2249229},{"batl":[[0,3.2,186.93],[1,3.25,274.07],[2,5,7.87]],"ltp":1.91,"tv":11621.06,"id":5720747}]}]}
{"op":"mcm","clk":"1004830751","pt":1580638032785,"mc":[{"id":"1.168135792","rc":[{"batb":[[0,1.73,68.49],[1,1.72,104.18],[2,1.68,73.52]],"ltp":1.91,"tv":11621.06,"id":5720747}]}]}
{"op":"mcm","clk":"1004830806","pt":1580638033771,"mc":[{"id":"1.168135792","rc":[{"batb":[[2,1.48,364.23]],"ltp":2.08,"tv":8400.88,"id":2249229}]}]}
{"op":"mcm","clk":"1004830884","pt":1580638034760,"mc":[{"id":"1.168135792","rc":[{"batb":[[1,1.68,73.52],[2,1.6,83.33]],"ltp":1.91,"tv":11621.06,"id":5720747}]}]}
{"op":"mcm","clk":"1004831459","pt":1580638042473,"mc":[{"id":"1.168135792","rc":[{"trd":[[1.73,55]],"batb":[[0,1.73,40.99]],"ltp":1.73,"tv":11676.05,"id":5720747}],"tv":20076.94}]}
{"op":"mcm","clk":"1004831540","pt":1580638043565,"mc":[{"id":"1.168135792","rc":[{"batb":[[0,1.68,73.52],[1,1.6,83.33],[2,1.57,306.72]],"ltp":1.73,"tv":11676.05,"id":5720747}]}]}
{"op":"mcm","clk":"1004832093","pt":1580638051788,"mc":[{"id":"1.168135792","rc":[{"batb":[[0,1.57,306.72],[1,1.54,580.92],[2,1.53,477.74]],"ltp":1.73,"tv":11676.05,"id":5720747}]}]}
{"op":"mcm","clk":"1004832228","pt":1580638053817,"mc":[{"id":"1.168135792","rc":[{"batl":[[0,5,7.87],[1,3.25,0],[2,5,0]],"ltp":1.73,"tv":11676.05,"id":5720747}]}]}
{"op":"mcm","clk":"1004832292","pt":1580638054809,"mc":[{"id":"1.168135792","rc":[{"batb":[[0,1.54,580.92],[1,1.53,477.74],[2,1.29,9.07]],"ltp":1.73,"tv":11676.05,"id":5720747}]}]}
{"op":"mcm","clk":"1004832356","pt":1580638055803,"mc":[{"id":"1.168135792","rc":[{"batl":[[0,1.6,742.62],[1,1.61,387.97],[2,1.68,125.19]],"ltp":1.73,"tv":11676.05,"id":5720747}]}]}
{"op":"mcm","clk":"1004832523","pt":1580638058398,"mc":[{"id":"1.168135792","rc":[{"batb":[[2,1.35,5]],"batl":[[2,4,259.15]],"ltp":2.08,"tv":8400.88,"id":2249229}]}]}
{"op":"mcm","clk":"1004832713","pt":1580638061696,"mc":[{"id":"1.168135792","rc":[{"trd":[[1.54,428.41]],"batb":[[0,1.54,550.02]],"batl":[[2,1.93,219.22]],"ltp":1.54,"tv":11737.85,"id":5720747}],"tv":20138.74}]}
{"op":"mcm","clk":"1004832816","pt":1580638063691,"mc":[{"id":"1.168135792","rc":[{"batb":[[0,2.1,158.94],[1,1.7,5.46],[2,1.52,22.56]],"ltp":2.08,"tv":8400.88,"id":2249229},{"trd":[[1.6,657.56]],"batl":[[0,1.6,741.77]],"ltp":1.6,"tv":11739.55,"id":5720747}],"tv":20140.43}]}
{"op":"mcm","clk":"1004832975","pt":1580638066817,"mc":[{"id":"1.168135792","rc":[{"batb":[[0,1.54,642.16],[2,1.4,437.08]],"ltp":1.6,"tv":11739.55,"id":5720747}]}]}
{"op":"mcm","clk":"1004833096","pt":1580638068738,"mc":[{"id":"1.168135792","rc":[{"batb":[[0,1.4,437.08],[1,1.29,9.07],[2,1.28,3.36]],"batl":[[0,1.93,219.22],[1,5,7.87],[2,1.93,0]],"ltp":1.6,"tv":11739.55,"id":5720747}]}]}
{"op":"mcm","clk":"1004833672","pt":1580638076783,"mc":[{"id":"1.168135792","rc":[{"batb":[[1,1.37,896.65],[2,1.36,797.92]],"batl":[[1,2.02,668.24],[2,2.04,366.75]],"ltp":1.6,"tv":11739.55,"id":5720747}]}]}
{"op":"mcm","clk":"1004834045","pt":1580638081769,"mc":[{"id":"1.168135792","rc":[{"batb":[[1,1.99,176.6],[2,1.7,5.46]],"ltp":2.08,"tv":8400.88,"id":2249229}]}]}
{"op":"mcm","clk":"1004834111","pt":1580638082764,"mc":[{"id":"1.168135792","rc":[{"batb":[[1,2,174.83],[2,1.99,176.6]],"ltp":2.08,"tv":8400.88,"id":2249229},{"batl":[[1,5,7.87],[2,2.04,0]],"ltp":1.6,"tv":11739.55,"id":5720747}]}]}
{"op":"mcm","clk":"1004834175","pt":1580638083751,"mc":[{"id":"1.168135792","rc":[{"batb":[[1,1.39,448.28],[2,1.37,896.65]],"ltp":1.6,"tv":11739.55,"id":5720747}]}]}
{"op":"mcm","clk":"1004834233","pt":1580638084783,"mc":[{"id":"1.168135792","rc":[{"trd":[[3,459.4]],"batl":[[0,3.75,2.02],[1,4,7.39],[2,4,0]],"ltp":3.0,"tv":8402.17,"id":2249229},{"trd":[[1.5,737.98]],"batb":[[0,1.37,896.65],[1,1.36,797.92],[2,1.29,9.07]],"batl":[[0,1.48,122.61]],"ltp":1.5,"tv":11742.13,"id":5720747}],"tv":20144.3}]}
{"op":"mcm","clk":"1004834282","pt":1580638085466,"mc":[{"id":"1.168135792","rc":[{"batl":[[0,1.41,535.37],[1,1.42,634.95],[2,1.48,122.61]],"ltp":1.5,"tv":11742.13,"id":5720747}]}]}
{"op":"mcm","clk":"1004834429","pt":1580638087754,"mc":[{"id":"1.168135792","rc":[{"batl":[[2,5,7.87]],"ltp":1.5,"tv":11742.13,"id":5720747}]}]}
{"op":"mcm","clk":"1004834490","pt":1580638088654,"mc":[{"id":"1.168135792","rc":[{"batl":[[2,5.1,201.18]],"ltp":3.0,"tv":8402.17,"id":2249229},{"batl":[[2,1.75,291.09]],"ltp":1.5,"tv":11742.13,"id":5720747}]}]}
{"op":"mcm","clk":"1004834599","pt":1580638090530,"mc":[{"id":"1.168135792","rc":[{"trd":[[1.41,232.5]],"batl":[[0,1.41,532.63]],"ltp":1.41,"tv":11747.61,"id":5720747}],"tv":20149.78}]}
{"op":"mcm","clk":"1004834739","pt":1580638092760,"mc":[{"id":"1.168135792","rc":[{"batb":[[0,1.7,5.46],[1,1.52,22.56],[2,1.35,5]],"ltp":3.0,"tv":8402.17,"id":2249229}]}]}
{"op":"mcm","clk":"1004834794","pt":1580638093637,"mc":[{"id":"1.168135792","rc":[{"trd":[[3.4,50]],"ltp":3.4,"tv":8452.17,"id":2249229},{"trd":[[1.41,353.07]],"batl":[[0,1.41,412.06]],"ltp":1.41,"tv":11868.18,"id":5720747}],"tv":20320.35}]}
{"op":"mcm","clk":"1004834987","pt":1580638096549,"mc":[{"id":"1.168135792","rc":[{"batl":[[1,5.1,201.18],[2,5.1,0]],"ltp":3.4,"tv":8452.17,"id":2249229}]}]}
{"op":"mcm","clk":"1004835146","pt":1580638098785,"mc":[{"id":"1.168135792","rc":[{"batb":[[0,2.5,116.55],[1,1.7,5.46],[2,1.52,22.56]],"ltp":3.4,"tv":8452.17,"id":2249229},{"batb":[[0,1.29,9.07],[1,1.28,3.36],[2,1.27,657.26]],"batl":[[0,1.75,291.09],[1,5,7.87],[2,1.75,0]],"ltp":1.41,"tv":11868.18,"id":5720747}]}]}
{"op":"mcm","clk":"1004835196","pt":1580638099466,"mc":[{"id":"1.168135792","rc":[{"batb":[[1,2.4,124.88],[2,1.7,5.46]],"ltp":3.4,"tv":8452.17,"id":2249229}]}]}
{"op":"mcm","clk":"1004835284","pt":1580638100662,"mc":[{"id":"1.168135792","rc":[{"batb":[[0,1.41,2],[1,1.29,9.07],[2,1.28,3.36]],"ltp":1.41,"tv":11868.18,"id":5720747}]}]}
{"op":"mcm","clk":"1004835367","pt":1580638101656,"mc":[{"id":"1.168135792","rc":[{"batb":[[2,1.28,1148.64]],"batl":[[0,1.61,635],[1,1.62,379.19],[2,1.75,291.09]],"ltp":1.41,"tv":11868.18,"id":5720747}]}]}
{"op":"mcm","clk":"1004835678","pt":1580638106757,"mc":[{"id":"1.168135792","rc":[{"batb":[[0,1.41,7]],"ltp":1.41,"tv":11868.18,"id":5720747}]}]}
{"op":"mcm","clk":"1004835741","pt":1580638107797,"mc":[{"id":"1.168135792","rc":[{"batb":[[0,1.7,5.46],[1,1.52,22.56],[2,1.35,5]],"ltp":3.4,"tv":8452.17,"id":2249229},{"batb":[[1,1.29,611.93]],"ltp":1.41,"tv":11868.18,"id":5720747}]}]}
{"op":"mcm","clk":"1004835812","pt":1580638108780,"mc":[{"id":"1.168135792","rc":[{"batb":[[1,1.29,1214.8]],"ltp":1.41,"tv":11868.18,"id":5720747}]}]}
{"op":"mcm","clk":"1004835943","pt":1580638110712,"mc":[{"id":"1.168135792","rc":[{"batb":[[0,2.66,105.32],[1,2.64,106.6],[2,1.7,5.46]],"ltp":3.4,"tv":8452.17,"id":2249229}]}]}
{"op":"mcm","clk":"1004836127","pt":1580638113775,"mc":[{"id":"1.168135792","rc":[{"batb":[[1,1.3,150],[2,1.29,1214.8]],"ltp":1.41,"tv":11868.18,"id":5720747}]}]}
{"op":"mcm","clk":"1004836366","pt":1580638117625,"mc":[{"id":"1.168135792","rc":[{"trd":[[1.41,358.07]],"batb":[[0,1.3,150],[1,1.29,1214.8],[2,1.28,1148.64]],"ltp":1.41,"tv":11873.18,"id":5720747}],"tv":20325.35}]}
{"op":"mcm","clk":"1004836811","pt":1580638124705,"mc":[{"id":"1.168135792","rc":[{"batl":[[0,1.75,291.09],[1,5,7.87],[2,1.75,0]],"ltp":1.41,"tv":11873.18,"id":5720747}]}]}
{"op":"mcm","clk":"1004836881","pt":1580638125791,"mc":[{"id":"1.168135792","rc":[{"batl":[[0,1.37,50],[1,1.75,291.09],[2,5,7.87]],"ltp":1.41,"tv":11873.18,"id":5720747}]}]}
{"op":"mcm","clk":"1004837017","pt":1580638127619,"mc":[{"id":"1.168135792","rc":[{"trd":[[3.75,38.6]],"ltp":3.75,"tv":8454.19,"id":2249229},{"trd":[[1.36,110.29]],"batb":[[0,1.29,9.07],[1,1.28,1148.64],[2,1.27,1153.59]],"batl":[[0,1.32,1253.79],[1,1.33,845.81],[2,1.37,50]],"ltp":1.36,"tv":11878.75,"id":5720747}],"tv":20332.94}]}
{"op":"mcm","clk":"1004837212","pt":1580638129637,"mc":[{"id":"1.168135792","rc":[{"batl":[[2,1.41,3.03]],"ltp":1.36,"tv":11878.75,"id":5720747}]}]}
{"op":"mcm","clk":"1004837335","pt":1580638131602,"mc":[{"id":"1.168135792","rc":[{"batl":[[0,6.4,165.88]],"ltp":3.75,"tv":8454.19,"id":2249229}]}]}
{"op":"mcm","clk":"1004837530","pt":1580638134808,"mc":[{"id":"1.168135792","rc":[{"trd":[[1.32,26.22]],"batl":[[0,1.32,1240.68]],"ltp":1.32,"tv":11904.97,"id":5720747}],"tv":20359.16}]}
{"op":"mcm","clk":"1004837579","pt":1580638135642,"mc":[{"id":"1.168135792","rc":[{"batb":[[0,1.7,5.46],[1,1.52,22.56],[2,1.35,5]],"ltp":3.75,"tv":8454.19,"id":2249229}]}]}
{"op":"mcm","clk":"1004837644","pt":1580638136727,"mc":[{"id":"1.168135792","rc":[{"trd":[[4.1,50]],"ltp":4.1,"tv":8504.19,"id":2249229},{"trd":[[1.32,181.52]],"batl":[[0,1.32,1085.38]],"ltp":1.32,"tv":12060.27,"id":5720747}],"tv":20564.46}]}
{"op":"mcm","clk":"1004837704","pt":1580638137719,"mc":[{"id":"1.168135792","rc":[{"batl":[[0,4.3,7.39],[1,6.4,165.88]],"ltp":4.1,"tv":8504.19,"id":2249229}]}]}
{"op":"mcm","clk":"1004837768","pt":1580638138806,"mc":[{"id":"1.168135792","rc":[{"batl":[[0,4.2,5.51],[1,4.3,7.39],[2,6.4,165.88]],"ltp":4.1,"tv":8504.19,"id":2249229},{"batb":[[0,1.3,2.28],[1,1.29,9.07],[2,1.28,1148.64]],"ltp":1.32,"tv":12060.27,"id":5720747}]}]}
{"op":"mcm","clk":"1004837888","pt":1580638140622,"mc":[{"id":"1.168135792","rc":[{"batb":[[2,1.28,3.36]],"batl":[[0,1.64,361.18],[1,5,7.87],[2,1.41,0]],"ltp":1.32,"tv":12060.27,"id":5720747}]}]}
{"op":"mcm","clk":"1004837963","pt":1580638141706,"mc":[{"id":"1.168135792","rc":[{"batb":[[0,3.5,69.93],[1,1.7,5.46],[2,1.52,22.56]],"ltp":4.1,"tv":8504.19,"id":2249229}]}]}
{"op":"mcm","clk":"1004838045","pt":1580638142805,"mc":[{"id":"1.168135792","rc":[{"batb":[[0,1.32,1.68],[1,1.3,2.28],[2,1.29,9.07]],"ltp":1.32,"tv":12060.27,"id":5720747}]}]}
{"op":"mcm","clk":"1004838190","pt":1580638144732,"mc":[{"id":"1.168135792","rc":[{"trd":[[4.2,3.15]],"batl":[[0,4.3,7.39],[1,6.4,165.88],[2,6.4,0]],"ltp":4.2,"tv":8507.34,"id":2249229},{"trd":[[1.31,10.1],[1.32,297.38]],"batb":[[0,1.3,2.28],[1,1.29,9.07],[2,1.28,3.36]],"ltp":1.31,"tv":12186.23,"id":5720747}],"tv":20693.57}]}
{"op":"mcm","clk":"1004838414","pt":1580638147709,"mc":[{"id":"1.168135792","rc":[{"batl":[[0,1.35,1223.3],[1,1.36,758.45],[2,1.64,361.18]],"ltp":1.31,"tv":12186.23,"id":5720747}]}]}
{"op":"mcm","clk":"1004838469","pt":1580638148543,"mc":[{"id":"1.168135792","rc":[{"trd":[[1.35,99.3]],"batl":[[0,1.35,1181.16]],"ltp":1.35,"tv":12270.51,"id":5720747}],"tv":20777.85}]}
{"op":"mcm","clk":"1004838673","pt":1580638151727,"mc":[{"id":"1.168135792","rc":[{"batl":[[0,6.4,165.88],[1,6.4,0]],"ltp":4.2,"tv":8507.34,"id":2249229},{"batb":[[0,1.32,20],[1,1.3,2.28],[2,1.29,9.07]],"ltp":1.35,"tv":12270.51,"id":5720747}]}]}
{"op":"mcm","clk":"1004838746","pt":1580638152660,"mc":[{"id":"1.168135792","rc":[{"batb":[[0,1.7,5.46],[1,1.52,22.56],[2,1.35,5]],"ltp":4.2,"tv":8507.34,"id":2249229}]}]}
{"op":"mcm","clk":"1004838832","pt":1580638153789,"mc":[{"id":"1.168135792","rc":[{"trd":[[1.35,115.68]],"batl":[[0,1.35,1172.97]],"ltp":1.35,"tv":12286.89,"id":5720747}],"tv":20794.23}]}
{"op":"mcm","clk":"1004838910","pt":1580638154686,"mc":[{"id":"1.168135792","rc":[{"batb":[[0,3.9,60.29],[1,1.7,5.46],[2,1.52,22.56]],"batl":[[0,4,7.39],[1,6.4,165.88]],"ltp":4.2,"tv":8507.34,"id":2249229}]}]}
{"op":"mcm","clk":"1004838998","pt":1580638155819,"mc":[{"id":"1.168135792","rc":[{"trd":[[1.35,133.66]],"batl":[[0,1.35,1163.98]],"ltp":1.35,"tv":12304.87,"id":5720747}],"tv":20812.21}]}
{"op":"mcm","clk":"1004839051","pt":1580638156652,"mc":[{"id":"1.168135792","rc":[{"batb":[[0,3.9,120.57]],"ltp":4.2,"tv":8507.34,"id":2249229}]}]}
{"op":"mcm","clk":"1004839103","pt":1580638157536,"mc":[{"id":"1.168135792","rc":[{"trd":[[1.35,153.66]],"batl":[[0,1.35,1153.98]],"ltp":1.35,"tv":12324.87,"id":5720747}],"tv":20832.21}]}
{"op":"mcm","clk":"1004839200","pt":1580638158752,"mc":[{"id":"1.168135792","rc":[{"batl":[[0,1.64,361.18],[1,5,7.87],[2,1.64,0]],"ltp":1.35,"tv":12324.87,"id":5720747}]}]}
{"op":"mcm","clk":"1004839268","pt":1580638159642,"mc":[{"id":"1.168135792","rc":[{"trd":[[3.9,0.02]],"batb":[[0,3.9,120.55]],"ltp":3.9,"tv":8507.36,"id":2249229},{"trd":[[1.35,153.72]],"ltp":1.35,"tv":12324.93,"id":5720747}],"tv":20832.29}]}
{"op":"mcm","clk":"1004839341","pt":1580638160534,"mc":[{"id":"1.168135792","rc":[{"trd":[[1.33,71.53]],"batb":[[0,1.33,1.91],[1,1.32,20],[2,1.3,2.28]],"ltp":1.33,"tv":12337.04,"id":5720747}],"tv":20844.4}]}
{"op":"mcm","clk":"1004839511","pt":1580638162750,"mc":[{"id":"1.168135792","rc":[{"batb":[[1,1.32,24.2]],"ltp":1.33,"tv":12337.04,"id":5720747}]}]}
{"op":"mcm","clk":"1004839711","pt":1580638165684,"mc":[{"id":"1.168135792","rc":[{"batl":[[0,1.35,1203.96],[1,1.36,758.44],[2,1.64,361.18]],"ltp":1.33,"tv":12337.04,"id":5720747}]}]}
{"op":"mcm","clk":"1004839779","pt":1580638166578,"mc":[{"id":"1.168135792","rc":[{"batb":[[1,1.52,22.56],[2,1.35,5]],"ltp":3.9,"tv":8507.36,"id":2249229},{"trd":[[1.35,304.96]],"batl":[[0,1.35,1128.34]],"ltp":1.35,"tv":12488.28,"id":5720747}],"tv":20995.64}]}
{"op":"mcm","clk":"1004839860","pt":1580638167778,"mc":[{"id":"1.168135792","rc":[{"batl":[[1,4.2,2],[2,6.4,165.88]],"ltp":3.9,"tv":8507.36,"id":2249229}]}]}
{"op":"mcm","clk":"1004839918","pt":1580638168565,"mc":[{"id":"1.168135792","rc":[{"trd":[[4,10.5]],"batl":[[0,4,2.14]],"ltp":4.0,"tv":8517.86,"id":2249229}],"tv":21006.14}]}
{"op":"mcm","clk":"1004839991","pt":1580638169769,"mc":[{"id":"1.168135792","rc":[{"trd":[[3.9,29.61]],"batb":[[0,3.9,105.75],[1,2.1,5.46],[2,1.52,22.56]],"ltp":3.9,"tv":8547.45,"id":2249229}],"tv":21035.74}]}
{"op":"mcm","clk":"1004840129","pt":1580638171555,"mc":[{"id":"1.168135792","rc":[{"trd":[[4,12.64]],"batl":[[0,4.2,2],[1,6.4,165.88],[2,6.4,0]],"ltp":4.0,"tv":8549.59,"id":2249229},{"trd":[[1.32,345.78],[1.33,81.78]],"batb":[[0,1.3,2.28],[1,1.29,9.07],[2,1.28,3.36]],"batl":[[0,1.32,37.46],[1,1.35,1128.34],[2,1.36,758.44]],"ltp":1.32,"tv":12546.93,"id":5720747}],"tv":21096.52}]}
{"op":"mcm","clk":"1004840262","pt":1580638173392,"mc":[{"id":"1.168135792","rc":[{"trd":[[1.32,360.92]],"batl":[[0,1.32,29.89]],"ltp":1.32,"tv":12562.07,"id":5720747}],"tv":21111.66}]}
{"op":"mcm","clk":"1004840408","pt":1580638175681,"mc":[{"id":"1.168135792","rc":[{"batb":[[0,1.29,9.07],[1,1.28,3.36],[2,1.27,9.74]],"batl":[[1,1.33,1.77],[2,1.35,1128.34]],"ltp":1.32,"tv":12562.07,"id":5720747}]}]}
{"op":"mcm","clk":"1004840642","pt":1580638178766,"mc":[{"id":"1.168135792","rc":[{"trd":[[1.32,420.7]],"batb":[[0,1.32,16.13],[1,1.29,9.07],[2,1.28,3.36]],"batl":[[0,1.33,1.77],[1,1.35,1128.34],[2,1.36,758.44]],"ltp":1.32,"tv":12621.85,"id":5720747}],"tv":21171.45}]}
{"op":"mcm","clk":"1004840719","pt":1580638179813,"mc":[{"id":"1.168135792","rc":[{"batl":[[1,1.64,361.18],[2,5,7.87]],"ltp":1.32,"tv":12621.85,"id":5720747}]}]}
{"op":"mcm","clk":"1004840778","pt":1580638180599,"mc":[{"id":"1.168135792","rc":[{"trd":[[3.9,35.92]],"batb":[[0,3.9,99.44]],"ltp":3.9,"tv":8555.9,"id":2249229},{"trd":[[1.33,85.32],[1.35,323.19]],"batl":[[0,1.64,361.18],[1,5,7.87],[2,5,0]],"ltp":1.35,"tv":12643.62,"id":5720747}],"tv":21199.53}]}
