{"op":"mcm","clk":"988026418","pt":1580473742115,"mc":[{"id":"1.168135749","marketDefinition":{"bspMarket":false,"turnInPlayEnabled":true,"persistenceEnabled":true,"marketBaseRate":5.0,"eventId":"29678823","eventTypeId":"2","numberOfWinners":1,"bettingType":"ODDS","marketType":"SET_BETTING","marketTime":"2020-02-02T08:30:00.000Z","suspendTime":"2020-02-02T08:30:00.000Z","bspReconciled":false,"complete":true,"inPlay":false,"crossMatching":false,"runnersVoidable":false,"numberOfActiveRunners":6,"betDelay":0,"status":"OPEN","runners":[{"status":"ACTIVE","sortPriority":1,"id":8204664,"name":"Thiem 3 - 0"},{"status":"ACTIVE","sortPriority":2,"id":8204663,"name":"Thiem 3 - 1"},{"status":"ACTIVE","sortPriority":3,"id":8204665,"name":"Thiem 3 - 2"},{"status":"ACTIVE","sortPriority":4,"id":1042124,"name":"Djokovic 3 - 0"},{"status":"ACTIVE","sortPriority":5,"id":1042125,"name":"Djokovic 3 - 1"},{"status":"ACTIVE","sortPriority":6,"id":1042126,"name":"Djokovic 3 - 2"}],"regulators":["MR_INT"],"countryCode":"AU","discountAllowed":false,"timezone":"GMT","openDate":"2020-02-02T08:30:00.000Z","version":3143005272,"name":"Set Betting","eventName":"Thiem v Djokovic"}}]}
{"op":"mcm","clk":"988026715","pt":1580473744836,"mc":[{"id":"1.168135749","marketDefinition":{"bspMarket":false,"turnInPlayEnabled":true,"persistenceEnabled":true,"marketBaseRate":5.0,"eventId":"29678823","eventTypeId":"2","numberOfWinners":1,"bettingType":"ODDS","marketType":"SET_BETTING","marketTime":"2020-02-02T08:30:00.000Z","suspendTime":"2020-02-02T08:30:00.000Z","bspReconciled":false,"complete":true,"inPlay":false,"crossMatching":false,"runnersVoidable":false,"numberOfActiveRunners":6,"betDelay":0,"status":"OPEN","runners":[{"status":"ACTIVE","sortPriority":1,"id":8204664,"name":"Thiem 3 - 0"},{"status":"ACTIVE","sortPriority":2,"id":8204663,"name":"Thiem 3 - 1"},{"status":"ACTIVE","sortPriority":3,"id":8204665,"name":"Thiem 3 - 2"},{"status":"ACTIVE","sortPriority":4,"id":1042124,"name":"Djokovic 3 - 0"},{"status":"ACTIVE","sortPriority":5,"id":1042125,"name":"Djokovic 3 - 1"},{"status":"ACTIVE","sortPriority":6,"id":1042126,"name":"Djokovic 3 - 2"}],"regulators":["MR_INT"],"countryCode":"AU","discountAllowed":true,"timezone":"GMT","openDate":"2020-02-02T08:30:00.000Z","version":3143005272,"name":"Set Betting","eventName":"Thiem v Djokovic"}}]}
{"op":"mcm","clk":"988040812","pt":1580473880844,"mc":[{"id":"1.168135749","rc":[{"batb":[[0,5,100]],"ltp":0.0,"tv":0.0,"id":8204664}]}]}
{"op":"mcm","clk":"988041657","pt":1580473889273,"mc":[{"id":"1.168135749","rc":[{"batb":[[0,5.2,169.78],[1,5,100]],"ltp":0.0,"tv":0.0,"id":8204664},{"batb":[[0,5,169.78]],"ltp":0.0,"tv":0.0,"id":8204665},{"batb":[[0,5,169.78]],"ltp":0.0,"tv":0.0,"id":8204663},{"batb":[[0,3,566.43]],"ltp":0.0,"tv":0.0,"id":1042125},{"batb":[[0,1.8,1132.86]],"ltp":0.0,"tv":0.0,"id":1042124},{"batb":[[0,4,282.96]],"ltp":0.0,"tv":0.0,"id":1042126}]}]}
{"op":"mcm","clk":"988042890","pt":1580473901978,"mc":[{"id":"1.168135749","rc":[{"batb":[[0,6,100],[1,5.2,169.78]],"ltp":0.0,"tv":0.0,"id":8204664}]}]}
{"op":"mcm","clk":"988057143","pt":1580474029645,"mc":[{"id":"1.168135749","rc":[{"batb":[[0,2,800],[1,1.8,1132.86]],"ltp":0.0,"tv":0.0,"id":1042124}]}]}
{"op":"mcm","clk":"988060745","pt":1580474061591,"mc":[{"id":"1.168135749","rc":[{"batb":[[0,2.02,509.84],[1,2,800],[2,1.8,1132.86]],"ltp":0.0,"tv":0.0,"id":1042124}]}]}
{"op":"mcm","clk":"988061474","pt":1580474067684,"mc":[{"id":"1.168135749","rc":[{"batl":[[0,1000,2.55]],"ltp":0.0,"tv":0.0,"id":8204664}]}]}
{"op":"mcm","clk":"988061864","pt":1580474071372,"mc":[{"id":"1.168135749","rc":[{"batl":[[0,3.9,52.98]],"ltp":0.0,"tv":0.0,"id":1042124}]}]}
{"op":"mcm","clk":"988062475","pt":1580474076877,"mc":[{"id":"1.168135749","marketDefinition":{"bspMarket":false,"turnInPlayEnabled":true,"persistenceEnabled":true,"marketBaseRate":5.0,"eventId":"29678823","eventTypeId":"2","numberOfWinners":1,"bettingType":"ODDS","marketType":"SET_BETTING","marketTime":"2020-02-02T08:30:00.000Z","suspendTime":"2020-02-02T08:30:00.000Z","bspReconciled":false,"complete":true,"inPlay":false,"crossMatching":true,"runnersVoidable":false,"numberOfActiveRunners":6,"betDelay":0,"status":"OPEN","runners":[{"status":"ACTIVE","sortPriority":1,"id":8204664,"name":"Thiem 3 - 0"},{"status":"ACTIVE","sortPriority":2,"id":8204663,"name":"Thiem 3 - 1"},{"status":"ACTIVE","sortPriority":3,"id":8204665,"name":"Thiem 3 - 2"},{"status":"ACTIVE","sortPriority":4,"id":1042124,"name":"Djokovic 3 - 0"},{"status":"ACTIVE","sortPriority":5,"id":1042125,"name":"Djokovic 3 - 1"},{"status":"ACTIVE","sortPriority":6,"id":1042126,"name":"Djokovic 3 - 2"}],"regulators":["MR_INT"],"countryCode":"AU","discountAllowed":true,"timezone":"GMT","openDate":"2020-02-02T08:30:00.000Z","version":3143005272,"name":"Set Betting","eventName":"Thiem v Djokovic"}}]}
{"op":"mcm","clk":"988115456","pt":1580474516773,"mc":[{"id":"1.168135749","rc":[{"batb":[[0,15.5,18.68],[1,6,100],[2,5.2,169.78]],"batl":[[0,24,17.11]],"ltp":0.0,"tv":0.0,"id":8204664},{"batb":[[0,8.8,33.6],[1,5,169.78]],"batl":[[0,13.5,28.68]],"ltp":0.0,"tv":0.0,"id":8204665},{"batb":[[0,10,32.19],[1,5,169.78]],"batl":[[0,15.5,24.42]],"ltp":0.0,"tv":0.0,"id":8204663},{"batb":[[0,3.15,95.73],[1,3,566.43]],"batl":[[0,4.8,76.85]],"ltp":0.0,"tv":0.0,"id":1042125},{"batb":[[0,2.3,124.36],[1,2.02,509.84],[2,2,800]],"batl":[[0,3.5,109.34]],"ltp":0.0,"tv":0.0,"id":1042124},{"batb":[[0,5.6,56.45],[1,4,282.96]],"batl":[[0,8.6,42.77]],"ltp":0.0,"tv":0.0,"id":1042126}]}]}
{"op":"mcm","clk":"988118146","pt":1580474541715,"mc":[{"id":"1.168135749","rc":[{"batb":[[0,3.2,50.98],[1,3.15,95.73],[2,3,566.43]],"ltp":0.0,"tv":0.0,"id":1042125}]}]}
{"op":"mcm","clk":"988118321","pt":1580474543140,"mc":[{"id":"1.168135749","rc":[{"batb":[[1,3,566.43],[2,3,0]],"ltp":0.0,"tv":0.0,"id":1042125}]}]}
{"op":"mcm","clk":"988118530","pt":1580474545119,"mc":[{"id":"1.168135749","rc":[{"batb":[[0,3.25,76.4],[1,3.2,50.98],[2,3,566.43]],"ltp":0.0,"tv":0.0,"id":1042125}]}]}
{"op":"mcm","clk":"988119065","pt":1580474549935,"mc":[{"id":"1.168135749","rc":[{"batb":[[0,5.8,22.43],[1,5.6,56.45],[2,4,282.96]],"ltp":0.0,"tv":0.0,"id":1042126}]}]}
{"op":"mcm","clk":"988119230","pt":1580474551438,"mc":[{"id":"1.168135749","rc":[{"batb":[[1,4,282.96],[2,4,0]],"ltp":0.0,"tv":0.0,"id":1042126}]}]}
{"op":"mcm","clk":"988119407","pt":1580474553124,"mc":[{"id":"1.168135749","rc":[{"batb":[[0,5.9,38.54],[1,5.8,22.43],[2,4,282.96]],"ltp":0.0,"tv":0.0,"id":1042126}]}]}
{"op":"mcm","clk":"988120000","pt":1580474558538,"mc":[{"id":"1.168135749","rc":[{"batb":[[0,6.2,10.71],[1,5.9,38.54],[2,5.8,22.43]],"ltp":0.0,"tv":0.0,"id":1042126}]}]}
{"op":"mcm","clk":"988120226","pt":1580474560430,"mc":[{"id":"1.168135749","rc":[{"batb":[[1,5.8,22.43],[2,4,282.96]],"ltp":0.0,"tv":0.0,"id":1042126}]}]}
{"op":"mcm","clk":"988120479","pt":1580474562744,"mc":[{"id":"1.168135749","rc":[{"batb":[[0,3.4,15.81],[1,3.25,76.4],[2,3.2,50.98]],"ltp":0.0,"tv":0.0,"id":1042125},{"batb":[[0,6.4,15.32],[1,6.2,10.71],[2,5.8,22.43]],"ltp":0.0,"tv":0.0,"id":1042126}]}]}
{"op":"mcm","clk":"988120588","pt":1580474563846,"mc":[{"id":"1.168135749","rc":[{"batb":[[1,3.2,50.98],[2,3,566.43]],"ltp":0.0,"tv":0.0,"id":1042125}]}]}
{"op":"mcm","clk":"988120791","pt":1580474565841,"mc":[{"id":"1.168135749","rc":[{"batb":[[0,3.45,43.8],[1,3.4,15.81],[2,3.2,50.98]],"ltp":0.0,"tv":0.0,"id":1042125}]}]}
{"op":"mcm","clk":"988154903","pt":1580474884343,"mc":[{"id":"1.168135749","rc":[{"batb":[[1,13,10],[2,6,100]],"ltp":0.0,"tv":0.0,"id":8204664},{"batb":[[1,8.4,10],[2,5,169.78]],"ltp":0.0,"tv":0.0,"id":8204665},{"batb":[[1,9.4,10],[2,5,169.78]],"ltp":0.0,"tv":0.0,"id":8204663},{"batb":[[0,3.6,10],[1,3.45,43.8],[2,3.4,15.81]],"ltp":0.0,"tv":0.0,"id":1042125},{"batb":[[0,2.5,16.53],[1,2.3,124.36],[2,2.02,509.84]],"ltp":0.0,"tv":0.0,"id":1042124}]}]}
{"op":"mcm","clk":"988155025","pt":1580474885754,"mc":[{"id":"1.168135749","rc":[{"batb":[[1,2.02,509.84],[2,2,800]],"ltp":0.0,"tv":0.0,"id":1042124}]}]}
{"op":"mcm","clk":"988155055","pt":1580474886054,"mc":[{"id":"1.168135749","rc":[{"batb":[[1,3.4,15.81],[2,3.2,50.98]],"ltp":0.0,"tv":0.0,"id":1042125}]}]}
{"op":"mcm","clk":"988155206","pt":1580474887564,"mc":[{"id":"1.168135749","rc":[{"batb":[[0,3.6,34.03]],"ltp":0.0,"tv":0.0,"id":1042125},{"batb":[[0,2.5,78.98]],"ltp":0.0,"tv":0.0,"id":1042124}]}]}
{"op":"mcm","clk":"988158687","pt":1580474922991,"mc":[{"id":"1.168135749","rc":[{"batb":[[1,6,100],[2,5.2,169.78]],"ltp":0.0,"tv":0.0,"id":8204664},{"batb":[[1,5,169.78],[2,5,0]],"ltp":0.0,"tv":0.0,"id":8204665},{"batb":[[1,5,169.78],[2,5,0]],"ltp":0.0,"tv":0.0,"id":8204663},{"batb":[[0,3.6,24.03]],"ltp":0.0,"tv":0.0,"id":1042125},{"batb":[[0,2.5,62.45]],"ltp":0.0,"tv":0.0,"id":1042124}]}]}
{"op":"mcm","clk":"988194033","pt":1580475181161,"mc":[{"id":"1.168135749","rc":[{"batb":[[2,5.2,0]],"ltp":0.0,"tv":0.0,"id":8204664},{"batb":[[1,5,0]],"ltp":0.0,"tv":0.0,"id":8204665},{"batb":[[1,5,0]],"ltp":0.0,"tv":0.0,"id":8204663},{"batb":[[1,3.4,0],[2,3.2,0]],"ltp":0.0,"tv":0.0,"id":1042125},{"batb":[[1,2,800],[2,2,0]],"ltp":0.0,"tv":0.0,"id":1042124},{"batb":[[1,6.2,0],[2,5.8,0]],"ltp":0.0,"tv":0.0,"id":1042126}]}]}
{"op":"mcm","clk":"988194385","pt":1580475185239,"mc":[{"id":"1.168135749","rc":[{"batl":[[0,4.4,10.71],[1,4.8,76.85]],"ltp":0.0,"tv":0.0,"id":1042125}]}]}
{"op":"mcm","clk":"988194498","pt":1580475186544,"mc":[{"id":"1.168135749","rc":[{"batl":[[1,4.8,0]],"ltp":0.0,"tv":0.0,"id":1042125}]}]}
{"op":"mcm","clk":"988194574","pt":1580475187363,"mc":[{"id":"1.168135749","rc":[{"batl":[[0,4.4,60.2]],"ltp":0.0,"tv":0.0,"id":1042125}]}]}
{"op":"mcm","clk":"988220178","pt":1580475497768,"mc":[{"id":"1.168135749","rc":[{"batb":[[2,1.01,0.08]],"ltp":0.0,"tv":0.0,"id":8204664}]}]}
{"op":"mcm","clk":"988220211","pt":1580475498085,"mc":[{"id":"1.168135749","rc":[{"trd":[[24,0.16]],"batb":[[2,1.01,0]],"batl":[[0,24,17.03]],"ltp":24.0,"tv":0.16,"id":8204664}],"tv":0.16}]}
{"op":"mcm","clk":"988220507","pt":1580475501804,"mc":[{"id":"1.168135749","rc":[{"batl":[[0,24,17.6]],"ltp":24.0,"tv":0.16,"id":8204664}]}]}
{"op":"mcm","clk":"988223401","pt":1580475538450,"mc":[{"id":"1.168135749","rc":[{"batb":[[0,2.6,208.79],[1,2.5,62.45],[2,2,800]],"batl":[[0,3.45,169.9],[1,3.5,109.34]],"ltp":0.0,"tv":0.0,"id":1042124}]}]}
{"op":"mcm","clk":"988223531","pt":1580475539725,"mc":[{"id":"1.168135749","rc":[{"batl":[[1,3.5,0]],"ltp":0.0,"tv":0.0,"id":1042124}]}]}
{"op":"mcm","clk":"988223544","pt":1580475539933,"mc":[{"id":"1.168135749","rc":[{"batb":[[1,2,800],[2,2,0]],"ltp":0.0,"tv":0.0,"id":1042124}]}]}
{"op":"mcm","clk":"988223656","pt":1580475541161,"mc":[{"id":"1.168135749","rc":[{"batl":[[0,3.2,183.03],[1,3.4,95.01]],"ltp":0.0,"tv":0.0,"id":1042124}]}]}
{"op":"mcm","clk":"988223791","pt":1580475542542,"mc":[{"id":"1.168135749","rc":[{"batb":[[0,2.64,205.82],[1,2.62,31.86],[2,2,800]],"batl":[[1,3.4,0]],"ltp":0.0,"tv":0.0,"id":1042124}]}]}
{"op":"mcm","clk":"988223889","pt":1580475543750,"mc":[{"id":"1.168135749","rc":[{"batb":[[0,2,800],[1,2.62,0],[2,2,0]],"batl":[[0,3.05,178.7],[1,3.15,61.65]],"ltp":0.0,"tv":0.0,"id":1042124}]}]}
{"op":"mcm","clk":"988223961","pt":1580475544643,"mc":[{"id":"1.168135749","rc":[{"batb":[[0,2.38,214.38],[1,2.3,127.73],[2,2,800]],"batl":[[1,3.15,0]],"ltp":0.0,"tv":0.0,"id":1042124}]}]}
{"op":"mcm","clk":"988224054","pt":1580475545748,"mc":[{"id":"1.168135749","rc":[{"batl":[[0,2.92,187.81],[1,3,38.97]],"ltp":0.0,"tv":0.0,"id":1042124}]}]}
{"op":"mcm","clk":"988224105","pt":1580475546434,"mc":[{"id":"1.168135749","rc":[{"batb":[[1,2,800],[2,2,0]],"ltp":0.0,"tv":0.0,"id":1042124}]}]}
{"op":"mcm","clk":"988224181","pt":1580475547437,"mc":[{"id":"1.168135749","rc":[{"batb":[[0,2.46,207.38],[1,2.4,92.51],[2,2,800]],"batl":[[1,3,0]],"ltp":0.0,"tv":0.0,"id":1042124}]}]}
{"op":"mcm","clk":"988224317","pt":1580475549164,"mc":[{"id":"1.168135749","rc":[{"batb":[[1,2,800],[2,2,0]],"batl":[[0,2.9,22.54],[1,2.92,187.81]],"ltp":0.0,"tv":0.0,"id":1042124}]}]}
{"op":"mcm","clk":"988224396","pt":1580475550370,"mc":[{"id":"1.168135749","rc":[{"batb":[[0,2.52,202.24],[1,2.48,68.07],[2,2,800]],"ltp":0.0,"tv":0.0,"id":1042124}]}]}
{"op":"mcm","clk":"988224588","pt":1580475552749,"mc":[{"id":"1.168135749","rc":[{"batb":[[0,2.54,51.61],[1,2,800],[2,2,0]],"ltp":0.0,"tv":0.0,"id":1042124}]}]}
{"op":"mcm","clk":"988224595","pt":1580475552843,"mc":[{"id":"1.168135749","rc":[{"batb":[[0,2.54,252.23]],"ltp":0.0,"tv":0.0,"id":1042124}]}]}
{"op":"mcm","clk":"988225778","pt":1580475567685,"mc":[{"id":"1.168135749","rc":[{"batl":[[0,23,91.03],[1,24,17.6]],"ltp":24.0,"tv":0.16,"id":8204664}]}]}
{"op":"mcm","clk":"988225867","pt":1580475568783,"mc":[{"id":"1.168135749","rc":[{"batl":[[1,24,0]],"ltp":24.0,"tv":0.16,"id":8204664}]}]}
{"op":"mcm","clk":"988225962","pt":1580475569890,"mc":[{"id":"1.168135749","rc":[{"batl":[[0,22,12.23],[1,23,91.03]],"ltp":24.0,"tv":0.16,"id":8204664}]}]}
{"op":"mcm","clk":"988227517","pt":1580475589553,"mc":[{"id":"1.168135749","rc":[{"batb":[[1,12,10],[2,6,100]],"ltp":24.0,"tv":0.16,"id":8204664},{"batb":[[0,9,10],[1,8.8,33.6]],"ltp":0.0,"tv":0.0,"id":8204665},{"batb":[[1,9.4,10]],"ltp":0.0,"tv":0.0,"id":8204663},{"batb":[[1,3.5,10]],"ltp":0.0,"tv":0.0,"id":1042125},{"batb":[[0,2.6,15.49],[1,2.54,252.23],[2,2,800]],"ltp":0.0,"tv":0.0,"id":1042124},{"batb":[[1,5,10]],"ltp":0.0,"tv":0.0,"id":1042126}]}]}
{"op":"mcm","clk":"988227620","pt":1580475590732,"mc":[{"id":"1.168135749","rc":[{"batb":[[1,2.54,51.61]],"ltp":0.0,"tv":0.0,"id":1042124}]}]}
{"op":"mcm","clk":"988227687","pt":1580475591423,"mc":[{"id":"1.168135749","rc":[{"batb":[[1,8.8,0]],"ltp":0.0,"tv":0.0,"id":8204665},{"batb":[[0,2.62,199.83],[1,2.6,15.49]],"ltp":0.0,"tv":0.0,"id":1042124}]}]}
{"op":"mcm","clk":"988227790","pt":1580475592625,"mc":[{"id":"1.168135749","rc":[{"batb":[[0,9.2,23.32],[1,9,10]],"ltp":0.0,"tv":0.0,"id":8204665},{"batb":[[0,2.64,27.28],[1,2.62,199.83],[2,2.6,15.49]],"batl":[[0,2.9,215.19],[1,2.92,0]],"ltp":0.0,"tv":0.0,"id":1042124}]}]}
{"op":"mcm","clk":"988227889","pt":1580475593732,"mc":[{"id":"1.168135749","rc":[{"batb":[[1,2.6,15.49],[2,2,800]],"ltp":0.0,"tv":0.0,"id":1042124}]}]}
{"op":"mcm","clk":"988228055","pt":1580475596322,"mc":[{"id":"1.168135749","rc":[{"batl":[[0,2.9,22.54]],"ltp":0.0,"tv":0.0,"id":1042124}]}]}
{"op":"mcm","clk":"988228097","pt":1580475596848,"mc":[{"id":"1.168135749","rc":[{"batb":[[0,2.66,202.78],[1,2.64,27.28],[2,2.6,15.49]],"ltp":0.0,"tv":0.0,"id":1042124}]}]}
{"op":"mcm","clk":"988228177","pt":1580475598018,"mc":[{"id":"1.168135749","rc":[{"batb":[[1,2.6,15.49],[2,2,800]],"ltp":0.0,"tv":0.0,"id":1042124}]}]}
{"op":"mcm","clk":"988228236","pt":1580475598823,"mc":[{"id":"1.168135749","rc":[{"batb":[[0,2.68,18.52],[1,2.66,202.78],[2,2.6,15.49]],"ltp":0.0,"tv":0.0,"id":1042124}]}]}
{"op":"mcm","clk":"988230041","pt":1580475616141,"mc":[{"id":"1.168135749","rc":[{"batl":[[0,22,104.03],[1,23,0]],"ltp":24.0,"tv":0.16,"id":8204664},{"batb":[[1,2.6,15.49],[2,2,800]],"ltp":0.0,"tv":0.0,"id":1042124}]}]}
{"op":"mcm","clk":"988231615","pt":1580475632411,"mc":[{"id":"1.168135749","rc":[{"batb":[[0,2.68,218.88]],"ltp":0.0,"tv":0.0,"id":1042124}]}]}
{"op":"mcm","clk":"988243184","pt":1580475733259,"mc":[{"id":"1.168135749","rc":[{"batl":[[0,22,12.23]],"ltp":24.0,"tv":0.16,"id":8204664},{"batb":[[0,2.68,18.52]],"ltp":0.0,"tv":0.0,"id":1042124}]}]}
{"op":"mcm","clk":"988244477","pt":1580475742488,"mc":[{"id":"1.168135749","rc":[{"batb":[[0,2.68,218.88]],"ltp":0.0,"tv":0.0,"id":1042124}]}]}
{"op":"mcm","clk":"988251626","pt":1580475791234,"mc":[{"id":"1.168135749","rc":[{"batb":[[0,2.68,18.52]],"ltp":0.0,"tv":0.0,"id":1042124}]}]}
{"op":"mcm","clk":"988266295","pt":1580475924997,"mc":[{"id":"1.168135749","rc":[{"batl":[[0,22,103.27]],"ltp":24.0,"tv":0.16,"id":8204664},{"batb":[[0,2.7,200.32],[1,2.68,18.52],[2,2.6,15.49]],"ltp":0.0,"tv":0.0,"id":1042124}]}]}
{"op":"mcm","clk":"988266417","pt":1580475926104,"mc":[{"id":"1.168135749","rc":[{"batb":[[1,2.6,15.49],[2,2,800]],"ltp":0.0,"tv":0.0,"id":1042124}]}]}
{"op":"mcm","clk":"988266575","pt":1580475927693,"mc":[{"id":"1.168135749","rc":[{"batb":[[0,2.7,214.65]],"ltp":0.0,"tv":0.0,"id":1042124}]}]}
{"op":"mcm","clk":"988267434","pt":1580475936243,"mc":[{"id":"1.168135749","rc":[{"batl":[[0,22,12.23]],"ltp":24.0,"tv":0.16,"id":8204664},{"batb":[[0,2.7,14.33]],"batl":[[0,2.88,192.29],[1,2.9,22.54]],"ltp":0.0,"tv":0.0,"id":1042124}]}]}
{"op":"mcm","clk":"988267570","pt":1580475937634,"mc":[{"id":"1.168135749","rc":[{"batl":[[1,2.9,0]],"ltp":0.0,"tv":0.0,"id":1042124}]}]}
{"op":"mcm","clk":"988267689","pt":1580475938738,"mc":[{"id":"1.168135749","rc":[{"batl":[[0,2.86,15.65],[1,2.88,192.29]],"ltp":0.0,"tv":0.0,"id":1042124}]}]}
{"op":"mcm","clk":"988268738","pt":1580475949682,"mc":[{"id":"1.168135749","rc":[{"batl":[[1,2.88,0]],"ltp":0.0,"tv":0.0,"id":1042124}]}]}
{"op":"mcm","clk":"988269962","pt":1580475961280,"mc":[{"id":"1.168135749","rc":[{"batb":[[1,2.62,30.47],[2,2.6,15.49]],"ltp":0.0,"tv":0.0,"id":1042124}]}]}
{"op":"mcm","clk":"988279122","pt":1580476039653,"mc":[{"id":"1.168135749","rc":[{"batl":[[0,22,103.59]],"ltp":24.0,"tv":0.16,"id":8204664},{"batb":[[0,2.7,214.65]],"ltp":0.0,"tv":0.0,"id":1042124}]}]}
{"op":"mcm","clk":"988279685","pt":1580476044423,"mc":[{"id":"1.168135749","rc":[{"batb":[[0,2.7,14.33]],"batl":[[0,2.84,193.03],[1,2.86,15.65]],"ltp":0.0,"tv":0.0,"id":1042124}]}]}
{"op":"mcm","clk":"988279816","pt":1580476045529,"mc":[{"id":"1.168135749","rc":[{"batl":[[1,2.86,0]],"ltp":0.0,"tv":0.0,"id":1042124}]}]}
{"op":"mcm","clk":"988279970","pt":1580476046738,"mc":[{"id":"1.168135749","rc":[{"batl":[[0,2.84,205.16]],"ltp":0.0,"tv":0.0,"id":1042124}]}]}
{"op":"mcm","clk":"988289983","pt":1580476062588,"mc":[{"id":"1.168135749","rc":[{"batl":[[0,2.84,12.13]],"ltp":0.0,"tv":0.0,"id":1042124}]}]}
{"op":"mcm","clk":"988290586","pt":1580476067698,"mc":[{"id":"1.168135749","rc":[{"trd":[[3.6,48.06]],"batb":[[0,3.5,10],[1,3.5,0]],"batl":[[0,3.6,61.53],[1,4.4,60.2]],"ltp":3.6,"tv":48.06,"id":1042125}],"tv":48.22}]}
{"op":"mcm","clk":"988290800","pt":1580476069489,"mc":[{"id":"1.168135749","rc":[{"batl":[[1,4.4,10.71]],"ltp":3.6,"tv":48.06,"id":1042125},{"batl":[[0,3.05,182.9]],"ltp":0.0,"tv":0.0,"id":1042124}]}]}
{"op":"mcm","clk":"988290916","pt":1580476070394,"mc":[{"id":"1.168135749","rc":[{"batb":[[0,3.5,31.97]],"batl":[[1,3.85,10.18],[2,4.4,10.71]],"ltp":3.6,"tv":48.06,"id":1042125},{"batl":[[1,3.5,93.13]],"ltp":0.0,"tv":0.0,"id":1042124}]}]}
{"op":"mcm","clk":"988291082","pt":1580476071809,"mc":[{"id":"1.168135749","rc":[{"batl":[[1,3.5,0]],"ltp":0.0,"tv":0.0,"id":1042124}]}]}
{"op":"mcm","clk":"988291190","pt":1580476072707,"mc":[{"id":"1.168135749","rc":[{"batl":[[0,3,32.58],[1,3.05,182.9]],"ltp":0.0,"tv":0.0,"id":1042124}]}]}
{"op":"mcm","clk":"988291238","pt":1580476073079,"mc":[{"id":"1.168135749","rc":[{"batl":[[0,2.96,188.62],[1,3,32.58]],"ltp":0.0,"tv":0.0,"id":1042124}]}]}
{"op":"mcm","clk":"988291418","pt":1580476074708,"mc":[{"id":"1.168135749","rc":[{"batl":[[1,3,0]],"ltp":0.0,"tv":0.0,"id":1042124}]}]}
{"op":"mcm","clk":"988291533","pt":1580476075612,"mc":[{"id":"1.168135749","rc":[{"batl":[[0,2.94,23.93],[1,2.96,188.62]],"ltp":0.0,"tv":0.0,"id":1042124}]}]}
{"op":"mcm","clk":"988291876","pt":1580476078892,"mc":[{"id":"1.168135749","rc":[{"batl":[[0,3.85,10.18],[1,4.4,10.71],[2,4.4,0]],"ltp":3.6,"tv":48.06,"id":1042125}]}]}
{"op":"mcm","clk":"988292388","pt":1580476083499,"mc":[{"id":"1.168135749","rc":[{"batl":[[0,22,12.23]],"ltp":24.0,"tv":0.16,"id":8204664},{"batb":[[1,2.6,15.49],[2,2,800]],"batl":[[1,2.96,0]],"ltp":0.0,"tv":0.0,"id":1042124}]}]}
{"op":"mcm","clk":"988293724","pt":1580476095512,"mc":[{"id":"1.168135749","rc":[{"trd":[[3.5,63.94]],"batl":[[0,3.5,29.56],[1,3.85,10.18],[2,4.4,10.71]],"ltp":3.5,"tv":112.0,"id":1042125}],"tv":112.16}]}
{"op":"mcm","clk":"988294140","pt":1580476098738,"mc":[{"id":"1.168135749","rc":[{"batl":[[0,22,103.59]],"ltp":24.0,"tv":0.16,"id":8204664},{"batb":[[0,3.1,39.57]],"ltp":3.5,"tv":112.0,"id":1042125}]}]}
{"op":"mcm","clk":"988294196","pt":1580476099231,"mc":[{"id":"1.168135749","rc":[{"batl":[[0,2.92,191.06],[1,2.94,23.93]],"ltp":0.0,"tv":0.0,"id":1042124}]}]}
{"op":"mcm","clk":"988294384","pt":1580476100759,"mc":[{"id":"1.168135749","rc":[{"batb":[[1,3.05,12.09]],"ltp":3.5,"tv":112.0,"id":1042125},{"batl":[[1,2.94,0]],"ltp":0.0,"tv":0.0,"id":1042124}]}]}
{"op":"mcm","clk":"988294536","pt":1580476101876,"mc":[{"id":"1.168135749","rc":[{"batl":[[0,2.9,14.23],[1,2.92,191.06]],"ltp":0.0,"tv":0.0,"id":1042124}]}]}
{"op":"mcm","clk":"988294730","pt":1580476103427,"mc":[{"id":"1.168135749","rc":[{"batl":[[0,3.85,10.18],[1,4.4,10.71],[2,4.4,0]],"ltp":3.5,"tv":112.0,"id":1042125}]}]}
{"op":"mcm","clk":"988295126","pt":1580476107250,"mc":[{"id":"1.168135749","rc":[{"batl":[[0,22,12.23]],"ltp":24.0,"tv":0.16,"id":8204664}]}]}
{"op":"mcm","clk":"988297219","pt":1580476126600,"mc":[{"id":"1.168135749","rc":[{"trd":[[10,20]],"batb":[[0,10,22.19]],"ltp":10.0,"tv":20.0,"id":8204663}],"tv":132.16}]}
{"op":"mcm","clk":"988297513","pt":1580476128981,"mc":[{"id":"1.168135749","rc":[{"batb":[[0,9.4,10],[1,9.4,0]],"ltp":10.0,"tv":20.0,"id":8204663}]}]}
{"op":"mcm","clk":"988297645","pt":1580476130061,"mc":[{"id":"1.168135749","rc":[{"batb":[[0,10,23.14],[1,9.4,10]],"ltp":10.0,"tv":20.0,"id":8204663}]}]}
{"op":"mcm","clk":"988298491","pt":1580476137807,"mc":[{"id":"1.168135749","rc":[{"batl":[[0,2.88,191.29],[1,2.92,0]],"ltp":0.0,"tv":0.0,"id":1042124}]}]}
{"op":"mcm","clk":"988298584","pt":1580476138808,"mc":[{"id":"1.168135749","rc":[{"batl":[[0,2.88,201.43]],"ltp":0.0,"tv":0.0,"id":1042124}]}]}
{"op":"mcm","clk":"988298793","pt":1580476141080,"mc":[{"id":"1.168135749","rc":[{"trd":[[3.1,39.12]],"batb":[[0,3.1,20.01]],"ltp":3.1,"tv":151.12,"id":1042125}],"tv":171.28}]}
{"op":"mcm","clk":"988299052","pt":1580476143496,"mc":[{"id":"1.168135749","rc":[{"batb":[[0,3.05,12.09],[1,3.05,0]],"ltp":3.1,"tv":151.12,"id":1042125}]}]}
{"op":"mcm","clk":"988299161","pt":1580476144516,"mc":[{"id":"1.168135749","rc":[{"batb":[[0,3.1,23.93],[1,3.05,12.09]],"ltp":3.1,"tv":151.12,"id":1042125}]}]}
{"op":"mcm","clk":"988300743","pt":1580476158304,"mc":[{"id":"1.168135749","rc":[{"batl":[[0,22,103.95]],"ltp":24.0,"tv":0.16,"id":8204664}]}]}
{"op":"mcm","clk":"988311126","pt":1580476244286,"mc":[{"id":"1.168135749","rc":[{"batl":[[0,2.88,191.29]],"ltp":0.0,"tv":0.0,"id":1042124}]}]}
{"op":"mcm","clk":"988311209","pt":1580476244981,"mc":[{"id":"1.168135749","rc":[{"batl":[[1,2.9,6.87]],"ltp":0.0,"tv":0.0,"id":1042124}]}]}
{"op":"mcm","clk":"988313120","pt":1580476261785,"mc":[{"id":"1.168135749","rc":[{"batb":[[0,9.6,34.48],[1,9.2,23.32],[2,9,10]],"batl":[[0,13,17.66],[1,13.5,28.68]],"ltp":0.0,"tv":0.0,"id":8204665},{"batb":[[0,10.5,8.41],[1,10,23.14],[2,9.4,10]],"batl":[[0,13.5,34.48],[1,15.5,24.42]],"ltp":10.0,"tv":20.0,"id":8204663},{"batb":[[0,3.55,58.02],[1,3.1,23.93],[2,3.05,12.09]],"batl":[[1,4.3,52.14],[2,4.4,10.71]],"ltp":3.1,"tv":151.12,"id":1042125},{"batb":[[0,6.6,40.36],[1,6.4,15.32],[2,5,10]],"batl":[[0,8.4,17.66],[1,8.6,42.77]],"ltp":0.0,"tv":0.0,"id":1042126}]}]}
{"op":"mcm","clk":"988313209","pt":1580476262707,"mc":[{"id":"1.168135749","rc":[{"batb":[[1,9,10],[2,9,0]],"batl":[[1,13.5,0]],"ltp":0.0,"tv":0.0,"id":8204665},{"batb":[[1,9.4,10],[2,9.4,0]],"batl":[[1,15.5,0]],"ltp":10.0,"tv":20.0,"id":8204663}]}]}
{"op":"mcm","clk":"988313293","pt":1580476263439,"mc":[{"id":"1.168135749","rc":[{"batb":[[1,3.05,12.09],[2,3.05,0]],"ltp":3.1,"tv":151.12,"id":1042125},{"batb":[[1,5,10],[2,5,0]],"batl":[[1,8.6,0]],"ltp":0.0,"tv":0.0,"id":1042126}]}]}
{"op":"mcm","clk":"988313424","pt":1580476264637,"mc":[{"id":"1.168135749","rc":[{"batl":[[0,12.5,14.03],[1,13,17.66]],"ltp":0.0,"tv":0.0,"id":8204665},{"batl":[[0,13,10.95],[1,13.5,34.48]],"ltp":10.0,"tv":20.0,"id":8204663},{"batl":[[0,8.2,20.71],[1,8.4,17.66]],"ltp":0.0,"tv":0.0,"id":1042126}]}]}
{"op":"mcm","clk":"988313499","pt":1580476265017,"mc":[{"id":"1.168135749","rc":[{"batb":[[0,9.8,14.27],[1,9.6,34.48],[2,9,10]],"ltp":0.0,"tv":0.0,"id":8204665},{"batb":[[0,11,9.74],[1,10.5,8.41],[2,9.4,10]],"ltp":10.0,"tv":20.0,"id":8204663},{"batb":[[0,3.6,3.33],[1,3.55,58.02],[2,3.05,12.09]],"ltp":3.1,"tv":151.12,"id":1042125},{"batb":[[0,6.6,55.02]],"ltp":0.0,"tv":0.0,"id":1042126}]}]}
{"op":"mcm","clk":"988314995","pt":1580476277420,"mc":[{"id":"1.168135749","rc":[{"batl":[[0,2.82,16.98]],"ltp":0.0,"tv":0.0,"id":1042124}]}]}
{"op":"mcm","clk":"988318645","pt":1580476308500,"mc":[{"id":"1.168135749","rc":[{"batl":[[0,22,12.23]],"ltp":24.0,"tv":0.16,"id":8204664}]}]}
{"op":"mcm","clk":"988323639","pt":1580476351299,"mc":[{"id":"1.168135749","rc":[{"batl":[[1,4.1,50],[2,4.3,52.14]],"ltp":3.1,"tv":151.12,"id":1042125}]}]}
{"op":"mcm","clk":"988324773","pt":1580476360922,"mc":[{"id":"1.168135749","rc":[{"batb":[[2,3.25,100]],"ltp":3.1,"tv":151.12,"id":1042125}]}]}
{"op":"mcm","clk":"988326631","pt":1580476376246,"mc":[{"id":"1.168135749","rc":[{"batb":[[2,1.02,2]],"ltp":0.0,"tv":0.0,"id":1042126}]}]}
{"op":"mcm","clk":"988328323","pt":1580476391147,"mc":[{"id":"1.168135749","rc":[{"batb":[[2,2.42,100]],"ltp":0.0,"tv":0.0,"id":1042124}]}]}
{"op":"mcm","clk":"988332755","pt":1580476430798,"mc":[{"id":"1.168135749","rc":[{"batl":[[2,14,24.39]],"ltp":0.0,"tv":0.0,"id":8204665},{"batb":[[2,9.6,26.07]],"ltp":10.0,"tv":20.0,"id":8204663},{"batl":[[1,4,14.3],[2,4.1,50]],"ltp":3.1,"tv":151.12,"id":1042125},{"batl":[[0,8,8.41],[1,8.2,20.71],[2,8.4,17.66]],"ltp":0.0,"tv":0.0,"id":1042126}]}]}
{"op":"mcm","clk":"988332853","pt":1580476431596,"mc":[{"id":"1.168135749","rc":[{"batl":[[1,8.4,17.66],[2,8.4,0]],"ltp":0.0,"tv":0.0,"id":1042126}]}]}
{"op":"mcm","clk":"988332961","pt":1580476432487,"mc":[{"id":"1.168135749","rc":[{"batl":[[0,7.8,14.9],[1,8,8.41],[2,8.4,17.66]],"ltp":0.0,"tv":0.0,"id":1042126}]}]}
{"op":"mcm","clk":"988334933","pt":1580476449010,"mc":[{"id":"1.168135749","rc":[{"batl":[[1,2.9,0]],"ltp":0.0,"tv":0.0,"id":1042124}]}]}
{"op":"mcm","clk":"988335042","pt":1580476449878,"mc":[{"id":"1.168135749","rc":[{"batl":[[1,2.94,6.73]],"ltp":0.0,"tv":0.0,"id":1042124}]}]}
{"op":"mcm","clk":"988336113","pt":1580476458499,"mc":[{"id":"1.168135749","rc":[{"batl":[[1,2.94,0]],"ltp":0.0,"tv":0.0,"id":1042124}]}]}
{"op":"mcm","clk":"988336166","pt":1580476458909,"mc":[{"id":"1.168135749","rc":[{"batl":[[1,2.92,7.56]],"ltp":0.0,"tv":0.0,"id":1042124}]}]}
{"op":"mcm","clk":"988339411","pt":1580476489343,"mc":[{"id":"1.168135749","rc":[{"batb":[[0,6.8,50],[1,6.6,55.02],[2,5,10]],"ltp":0.0,"tv":0.0,"id":1042126}]}]}
{"op":"mcm","clk":"988352703","pt":1580476601131,"mc":[{"id":"1.168135749","rc":[{"batb":[[1,9,10],[2,1.02,2]],"batl":[[1,13,0],[2,14,0]],"ltp":0.0,"tv":0.0,"id":8204665},{"batb":[[1,9.4,10],[2,1.02,2]],"batl":[[1,13.5,0]],"ltp":10.0,"tv":20.0,"id":8204663},{"batb":[[1,3.25,100],[2,3.05,12.09]],"batl":[[1,4.1,50],[2,4.4,10.71]],"ltp":3.1,"tv":151.12,"id":1042125},{"batb":[[1,6.6,14.66]],"batl":[[1,8,0],[2,8.4,0]],"ltp":0.0,"tv":0.0,"id":1042126}]}]}
{"op":"mcm","clk":"988371207","pt":1580476771585,"mc":[{"id":"1.168135749","rc":[{"batb":[[1,9.6,34.48],[2,9,10]],"batl":[[1,14,24.39]],"ltp":0.0,"tv":0.0,"id":8204665},{"batb":[[1,9.6,23.55],[2,9.4,10]],"batl":[[1,13.5,32.8]],"ltp":10.0,"tv":20.0,"id":8204663},{"batb":[[1,3.55,58.02],[2,3.25,100]],"batl":[[1,4,13.45],[2,4.1,50]],"ltp":3.1,"tv":151.12,"id":1042125},{"batb":[[0,7,26.91],[1,6.8,50],[2,6.6,14.66]],"batl":[[1,9,32.8]],"ltp":0.0,"tv":0.0,"id":1042126}]}]}
{"op":"mcm","clk":"988375058","pt":1580476804244,"mc":[{"id":"1.168135749","rc":[{"batl":[[0,2.82,308.45]],"ltp":0.0,"tv":0.0,"id":1042124}]}]}
{"op":"mcm","clk":"988377295","pt":1580476822709,"mc":[{"id":"1.168135749","rc":[{"batb":[[0,15.5,67.07]],"ltp":24.0,"tv":0.16,"id":8204664},{"batb":[[0,9.8,90.8]],"ltp":0.0,"tv":0.0,"id":8204665},{"batb":[[0,11,77.92]],"ltp":10.0,"tv":20.0,"id":8204663},{"batb":[[0,3.6,211.66]],"ltp":3.1,"tv":151.12,"id":1042125},{"batb":[[1,2.6,303.95]],"ltp":0.0,"tv":0.0,"id":1042124},{"batb":[[0,7,134.05]],"ltp":0.0,"tv":0.0,"id":1042126}]}]}
{"op":"mcm","clk":"988377824","pt":1580476827093,"mc":[{"id":"1.168135749","rc":[{"batb":[[1,6,100],[2,1.02,2]],"ltp":24.0,"tv":0.16,"id":8204664},{"batb":[[2,1.02,2]],"ltp":0.0,"tv":0.0,"id":8204665},{"batb":[[2,1.02,2]],"ltp":10.0,"tv":20.0,"id":8204663}]}]}
{"op":"mcm","clk":"988380383","pt":1580476848563,"mc":[{"id":"1.168135749","rc":[{"batl":[[0,2.82,16.98]],"ltp":0.0,"tv":0.0,"id":1042124}]}]}
{"op":"mcm","clk":"988380844","pt":1580476852294,"mc":[{"id":"1.168135749","rc":[{"batl":[[0,2.82,308.45]],"ltp":0.0,"tv":0.0,"id":1042124}]}]}
{"op":"mcm","clk":"988382678","pt":1580476867393,"mc":[{"id":"1.168135749","rc":[{"batl":[[0,2.82,16.98]],"ltp":0.0,"tv":0.0,"id":1042124}]}]}
{"op":"mcm","clk":"988384176","pt":1580476879686,"mc":[{"id":"1.168135749","rc":[{"batl":[[0,2.82,308.45]],"ltp":0.0,"tv":0.0,"id":1042124}]}]}
{"op":"mcm","clk":"988384612","pt":1580476883282,"mc":[{"id":"1.168135749","rc":[{"batl":[[0,2.82,16.98]],"ltp":0.0,"tv":0.0,"id":1042124}]}]}
{"op":"mcm","clk":"988391553","pt":1580476941784,"mc":[{"id":"1.168135749","rc":[{"batb":[[0,10,26.07],[1,9.8,90.8],[2,9.6,34.48]],"ltp":0.0,"tv":0.0,"id":8204665},{"batb":[[1,10.5,8.41],[2,9.6,23.55]],"ltp":10.0,"tv":20.0,"id":8204663},{"batb":[[0,3.65,41.2],[1,3.6,211.66],[2,3.55,58.02]],"ltp":3.1,"tv":151.12,"id":1042125}]}]}
{"op":"mcm","clk":"988391778","pt":1580476943674,"mc":[{"id":"1.168135749","rc":[{"batb":[[0,10,35.25],[1,9.8,76.53]],"ltp":0.0,"tv":0.0,"id":8204665}]}]}
{"op":"mcm","clk":"988419795","pt":1580477112008,"mc":[{"id":"1.168135749","rc":[{"batb":[[2,1.02,2]],"ltp":0.0,"tv":0.0,"id":8204665},{"batb":[[2,1.02,2]],"ltp":10.0,"tv":20.0,"id":8204663},{"batb":[[2,3.25,100]],"ltp":3.1,"tv":151.12,"id":1042125}]}]}
{"op":"mcm","clk":"988471540","pt":1580477563406,"mc":[{"id":"1.168135749","rc":[{"batb":[[1,2.62,346.64],[2,2.6,303.95]],"ltp":0.0,"tv":0.0,"id":1042124}]}]}
{"op":"mcm","clk":"988471645","pt":1580477564376,"mc":[{"id":"1.168135749","rc":[{"batb":[[2,2.6,288.46]],"ltp":0.0,"tv":0.0,"id":1042124}]}]}
{"op":"mcm","clk":"988474884","pt":1580477594246,"mc":[{"id":"1.168135749","rc":[{"batl":[[1,2.92,0]],"ltp":0.0,"tv":0.0,"id":1042124}]}]}
{"op":"mcm","clk":"988475015","pt":1580477595345,"mc":[{"id":"1.168135749","rc":[{"batl":[[1,2.9,6.87]],"ltp":0.0,"tv":0.0,"id":1042124}]}]}
{"op":"mcm","clk":"988484218","pt":1580477681458,"mc":[{"id":"1.168135749","rc":[{"batb":[[1,3.6,208.33]],"ltp":3.1,"tv":151.12,"id":1042125},{"batl":[[1,2.9,0]],"ltp":0.0,"tv":0.0,"id":1042124}]}]}
{"op":"mcm","clk":"988484338","pt":1580477682585,"mc":[{"id":"1.168135749","rc":[{"batb":[[0,3.65,43.3]],"ltp":3.1,"tv":151.12,"id":1042125},{"batl":[[1,2.94,6.73]],"ltp":0.0,"tv":0.0,"id":1042124}]}]}
{"op":"mcm","clk":"988487688","pt":1580477714121,"mc":[{"id":"1.168135749","rc":[{"batb":[[0,3.65,41.2]],"ltp":3.1,"tv":151.12,"id":1042125},{"batl":[[1,2.94,0]],"ltp":0.0,"tv":0.0,"id":1042124}]}]}
{"op":"mcm","clk":"988487790","pt":1580477715118,"mc":[{"id":"1.168135749","rc":[{"batb":[[1,3.6,211.75]],"ltp":3.1,"tv":151.12,"id":1042125},{"batl":[[1,2.92,7.56]],"ltp":0.0,"tv":0.0,"id":1042124}]}]}
{"op":"mcm","clk":"988501734","pt":1580477845620,"mc":[{"id":"1.168135749","rc":[{"batl":[[0,2.84,16.98]],"ltp":0.0,"tv":0.0,"id":1042124}]}]}
{"op":"mcm","clk":"988512284","pt":1580477864942,"mc":[{"id":"1.168135749","rc":[{"batl":[[0,2.82,388.75],[1,2.84,16.98],[2,2.92,7.56]],"ltp":0.0,"tv":0.0,"id":1042124}]}]}
{"op":"mcm","clk":"988512729","pt":1580477869163,"mc":[{"id":"1.168135749","rc":[{"batl":[[0,2.84,16.98],[1,2.92,7.56],[2,2.92,0]],"ltp":0.0,"tv":0.0,"id":1042124}]}]}
{"op":"mcm","clk":"988514654","pt":1580477888595,"mc":[{"id":"1.168135749","rc":[{"batl":[[0,2.84,404.51]],"ltp":0.0,"tv":0.0,"id":1042124}]}]}
{"op":"mcm","clk":"988515326","pt":1580477896498,"mc":[{"id":"1.168135749","rc":[{"batl":[[0,2.84,16.98]],"ltp":0.0,"tv":0.0,"id":1042124}]}]}
{"op":"mcm","clk":"988516123","pt":1580477903889,"mc":[{"id":"1.168135749","rc":[{"batl":[[0,2.84,404.51]],"ltp":0.0,"tv":0.0,"id":1042124}]}]}
{"op":"mcm","clk":"988523559","pt":1580477976743,"mc":[{"id":"1.168135749","rc":[{"batl":[[1,2.92,0]],"ltp":0.0,"tv":0.0,"id":1042124}]}]}
{"op":"mcm","clk":"988523584","pt":1580477977057,"mc":[{"id":"1.168135749","rc":[{"batb":[[1,3.6,208.33]],"ltp":3.1,"tv":151.12,"id":1042125}]}]}
{"op":"mcm","clk":"988523688","pt":1580477978060,"mc":[{"id":"1.168135749","rc":[{"batb":[[0,3.65,43.3]],"ltp":3.1,"tv":151.12,"id":1042125},{"batl":[[1,2.94,6.73]],"ltp":0.0,"tv":0.0,"id":1042124}]}]}
{"op":"mcm","clk":"988524737","pt":1580477988697,"mc":[{"id":"1.168135749","rc":[{"batb":[[0,3.65,41.2]],"ltp":3.1,"tv":151.12,"id":1042125}]}]}
{"op":"mcm","clk":"988524846","pt":1580477989665,"mc":[{"id":"1.168135749","rc":[{"batb":[[1,3.6,211.85]],"ltp":3.1,"tv":151.12,"id":1042125}]}]}
{"op":"mcm","clk":"988531250","pt":1580478047792,"mc":[{"id":"1.168135749","rc":[{"batl":[[1,2.94,0]],"ltp":0.0,"tv":0.0,"id":1042124}]}]}
{"op":"mcm","clk":"988531309","pt":1580478048479,"mc":[{"id":"1.168135749","rc":[{"batl":[[1,2.9,6.87]],"ltp":0.0,"tv":0.0,"id":1042124}]}]}
{"op":"mcm","clk":"988543958","pt":1580478171681,"mc":[{"id":"1.168135749","rc":[{"batb":[[0,10,43.66]],"batl":[[2,14.5,26.91]],"ltp":0.0,"tv":0.0,"id":8204665},{"batb":[[1,10.5,14.3]],"ltp":10.0,"tv":20.0,"id":8204663},{"batl":[[1,4,16.82]],"ltp":3.1,"tv":151.12,"id":1042125},{"batl":[[1,8.8,33.64],[2,9,32.8]],"ltp":0.0,"tv":0.0,"id":1042126}]}]}
{"op":"mcm","clk":"988547306","pt":1580478202039,"mc":[{"id":"1.168135749","rc":[{"batl":[[1,14.5,26.91],[2,14.5,0]],"ltp":0.0,"tv":0.0,"id":8204665},{"batl":[[1,13.5,26.07]],"ltp":10.0,"tv":20.0,"id":8204663},{"batb":[[0,3.65,35.32]],"ltp":3.1,"tv":151.12,"id":1042125},{"batl":[[2,9,0]],"ltp":0.0,"tv":0.0,"id":1042126}]}]}
{"op":"mcm","clk":"988569470","pt":1580478416211,"mc":[{"id":"1.168135749","rc":[{"batl":[[0,2.84,396.26]],"ltp":0.0,"tv":0.0,"id":1042124}]}]}
{"op":"mcm","clk":"988631022","pt":1580479090460,"mc":[{"id":"1.168135749","rc":[{"batl":[[0,20,87],[1,22,12.23]],"ltp":24.0,"tv":0.16,"id":8204664},{"batl":[[0,12.5,98],[1,13,10.95],[2,13.5,26.07]],"ltp":10.0,"tv":20.0,"id":8204663}]}]}
{"op":"mcm","clk":"988631184","pt":1580479092535,"mc":[{"id":"1.168135749","rc":[{"batl":[[1,22,0]],"ltp":24.0,"tv":0.16,"id":8204664}]}]}
{"op":"mcm","clk":"988631247","pt":1580479093227,"mc":[{"id":"1.168135749","rc":[{"batl":[[1,13.5,26.07],[2,13.5,0]],"ltp":10.0,"tv":20.0,"id":8204663}]}]}
{"op":"mcm","clk":"988631341","pt":1580479094359,"mc":[{"id":"1.168135749","rc":[{"batl":[[0,19.5,2.72],[1,20,87]],"ltp":24.0,"tv":0.16,"id":8204664},{"batl":[[0,12.5,104.04]],"ltp":10.0,"tv":20.0,"id":8204663}]}]}
{"op":"mcm","clk":"988634201","pt":1580479131722,"mc":[{"id":"1.168135749","rc":[{"batl":[[0,12,10.09],[1,12.5,104.04],[2,13.5,26.07]],"ltp":10.0,"tv":20.0,"id":8204663}]}]}
{"op":"mcm","clk":"988642705","pt":1580479242094,"mc":[{"id":"1.168135749","rc":[{"batb":[[0,10,43.66]],"batl":[[1,14.5,26.91]],"ltp":0.0,"tv":0.0,"id":8204665},{"batb":[[1,10.5,14.3]],"batl":[[0,12,10.09],[2,13.5,0]],"ltp":10.0,"tv":20.0,"id":8204663},{"batb":[[0,3.65,35.32]],"batl":[[1,4,16.82]],"ltp":3.1,"tv":151.12,"id":1042125},{"batb":[[1,2.62,346.17]],"batl":[[0,2.84,396.24]],"ltp":0.0,"tv":0.0,"id":1042124},{"batb":[[0,7,134.05]],"batl":[[1,8.8,33.64]],"ltp":0.0,"tv":0.0,"id":1042126}]}]}
{"op":"mcm","clk":"988665183","pt":1580479466094,"mc":[{"id":"1.168135749","rc":[{"batl":[[0,2.84,16.96]],"ltp":0.0,"tv":0.0,"id":1042124}]}]}
{"op":"mcm","clk":"988665985","pt":1580479474698,"mc":[{"id":"1.168135749","rc":[{"batl":[[0,2.82,384.47],[1,2.84,16.96],[2,2.9,6.87]],"ltp":0.0,"tv":0.0,"id":1042124}]}]}
{"op":"mcm","clk":"988707664","pt":1580479874349,"mc":[{"id":"1.168135749","rc":[{"trd":[[3.85,20.36]],"batb":[[0,3.85,9.43],[1,3.65,35.32],[2,3.6,211.85]],"batl":[[0,4,16.82],[1,4.1,50],[2,4.4,10.71]],"ltp":3.85,"tv":171.47,"id":1042125}],"tv":191.64}]}
{"op":"mcm","clk":"988707789","pt":1580479876269,"mc":[{"id":"1.168135749","rc":[{"batb":[[2,3.6,208.33]],"ltp":3.85,"tv":171.47,"id":1042125}]}]}
{"op":"mcm","clk":"988707844","pt":1580479877257,"mc":[{"id":"1.168135749","rc":[{"batb":[[1,3.65,39.08]],"batl":[[0,3.95,32.8],[1,4,16.82],[2,4.1,50]],"ltp":3.85,"tv":171.47,"id":1042125}]}]}
{"op":"mcm","clk":"988712933","pt":1580479942153,"mc":[{"id":"1.168135749","rc":[{"trd":[[3.85,39.22]],"batb":[[0,3.65,39.08],[1,3.6,208.33],[2,3.25,100]],"ltp":3.85,"tv":190.33,"id":1042125}],"tv":210.5}]}
{"op":"mcm","clk":"988731649","pt":1580480160767,"mc":[{"id":"1.168135749","rc":[{"trd":[[11,6]],"batb":[[0,11,74.92]],"ltp":11.0,"tv":26.0,"id":8204663}],"tv":216.5}]}
{"op":"mcm","clk":"988731908","pt":1580480163644,"mc":[{"id":"1.168135749","rc":[{"batb":[[0,11,68.18]],"ltp":11.0,"tv":26.0,"id":8204663}]}]}
{"op":"mcm","clk":"988731994","pt":1580480164683,"mc":[{"id":"1.168135749","rc":[{"batb":[[0,11.5,2.2],[1,11,68.18],[2,10.5,14.3]],"ltp":11.0,"tv":26.0,"id":8204663}]}]}
{"op":"mcm","clk":"988738449","pt":1580480233011,"mc":[{"id":"1.168135749","rc":[{"batl":[[0,2.82,377.36]],"ltp":0.0,"tv":0.0,"id":1042124}]}]}
{"op":"mcm","clk":"988742324","pt":1580480276401,"mc":[{"id":"1.168135749","rc":[{"batl":[[0,2.84,16.96],[1,2.9,6.87],[2,2.9,0]],"ltp":0.0,"tv":0.0,"id":1042124}]}]}
{"op":"mcm","clk":"988743024","pt":1580480283306,"mc":[{"id":"1.168135749","rc":[{"batl":[[0,2.82,380.25],[1,2.84,16.96],[2,2.9,6.87]],"ltp":0.0,"tv":0.0,"id":1042124}]}]}
{"op":"mcm","clk":"988759532","pt":1580480453141,"mc":[{"id":"1.168135749","rc":[{"batb":[[1,11,74.91]],"ltp":11.0,"tv":26.0,"id":8204663},{"batl":[[0,3.95,47.1]],"ltp":3.85,"tv":190.33,"id":1042125}]}]}
{"op":"mcm","clk":"988762644","pt":1580480482567,"mc":[{"id":"1.168135749","rc":[{"batb":[[2,1.02,2]],"batl":[[0,12,6.73]],"ltp":11.0,"tv":26.0,"id":8204663},{"batl":[[1,4.1,50],[2,4.4,10.71]],"ltp":3.85,"tv":190.33,"id":1042125}]}]}
{"op":"mcm","clk":"988766632","pt":1580480522907,"mc":[{"id":"1.168135749","rc":[{"batb":[[1,11,76.59]],"ltp":11.0,"tv":26.0,"id":8204663}]}]}
{"op":"mcm","clk":"988796870","pt":1580480774285,"mc":[{"id":"1.168135749","rc":[{"trd":[[3.65,20]],"batb":[[0,3.65,29.08]],"ltp":3.65,"tv":210.33,"id":1042125}],"tv":236.5}]}
{"op":"mcm","clk":"988803060","pt":1580480852901,"mc":[{"id":"1.168135749","rc":[{"batb":[[0,3.65,38.34]],"batl":[[0,3.95,49.62]],"ltp":3.65,"tv":210.33,"id":1042125}]}]}
{"op":"mcm","clk":"988983726","pt":1580482948463,"mc":[{"id":"1.168135749","rc":[{"batl":[[0,12,8.41]],"ltp":11.0,"tv":26.0,"id":8204663}]}]}
{"op":"mcm","clk":"988986198","pt":1580482977914,"mc":[{"id":"1.168135749","rc":[{"batb":[[1,11,74.91]],"ltp":11.0,"tv":26.0,"id":8204663}]}]}
{"op":"mcm","clk":"988986439","pt":1580482982607,"mc":[{"id":"1.168135749","rc":[{"batl":[[0,2.82,385.86]],"ltp":0.0,"tv":0.0,"id":1042124}]}]}
{"op":"mcm","clk":"989028064","pt":1580483404430,"mc":[{"id":"1.168135749","rc":[{"batl":[[2,2.9,0]],"ltp":0.0,"tv":0.0,"id":1042124}]}]}
{"op":"mcm","clk":"989028144","pt":1580483405341,"mc":[{"id":"1.168135749","rc":[{"batl":[[2,2.88,8.05]],"ltp":0.0,"tv":0.0,"id":1042124}]}]}
{"op":"mcm","clk":"989032771","pt":1580483465958,"mc":[{"id":"1.168135749","rc":[{"batl":[[2,2.88,0]],"ltp":0.0,"tv":0.0,"id":1042124}]}]}
{"op":"mcm","clk":"989032851","pt":1580483467068,"mc":[{"id":"1.168135749","rc":[{"batl":[[2,2.9,8.84]],"ltp":0.0,"tv":0.0,"id":1042124}]}]}
{"op":"mcm","clk":"989062928","pt":1580483875635,"mc":[{"id":"1.168135749","rc":[{"batl":[[2,2.9,0]],"ltp":0.0,"tv":0.0,"id":1042124}]}]}
{"op":"mcm","clk":"989062984","pt":1580483876525,"mc":[{"id":"1.168135749","rc":[{"batl":[[2,2.86,8.93]],"ltp":0.0,"tv":0.0,"id":1042124}]}]}
{"op":"mcm","clk":"989063650","pt":1580483884660,"mc":[{"id":"1.168135749","rc":[{"batl":[[0,2.84,16.96],[1,2.86,8.93],[2,2.86,0]],"ltp":0.0,"tv":0.0,"id":1042124}]}]}
{"op":"mcm","clk":"989063701","pt":1580483885150,"mc":[{"id":"1.168135749","rc":[{"batl":[[0,2.8,388.57],[1,2.84,16.96],[2,2.86,8.93]],"ltp":0.0,"tv":0.0,"id":1042124}]}]}
{"op":"mcm","clk":"989078135","pt":1580484070547,"mc":[{"id":"1.168135749","rc":[{"batl":[[2,2.86,0]],"ltp":0.0,"tv":0.0,"id":1042124}]}]}
{"op":"mcm","clk":"989078185","pt":1580484071229,"mc":[{"id":"1.168135749","rc":[{"batl":[[2,2.88,9.75]],"ltp":0.0,"tv":0.0,"id":1042124}]}]}
{"op":"mcm","clk":"989097557","pt":1580484206474,"mc":[{"id":"1.168135749","rc":[{"batl":[[2,2.88,0]],"ltp":0.0,"tv":0.0,"id":1042124}]}]}
{"op":"mcm","clk":"989097623","pt":1580484207314,"mc":[{"id":"1.168135749","rc":[{"batl":[[2,2.86,8.93]],"ltp":0.0,"tv":0.0,"id":1042124}]}]}
{"op":"mcm","clk":"989100175","pt":1580484240146,"mc":[{"id":"1.168135749","rc":[{"batl":[[2,2.86,0]],"ltp":0.0,"tv":0.0,"id":1042124}]}]}
{"op":"mcm","clk":"989100248","pt":1580484240938,"mc":[{"id":"1.168135749","rc":[{"batl":[[2,2.88,9.75]],"ltp":0.0,"tv":0.0,"id":1042124}]}]}
{"op":"mcm","clk":"989100991","pt":1580484250047,"mc":[{"id":"1.168135749","rc":[{"batl":[[1,8.6,1.68],[2,8.8,33.64]],"ltp":0.0,"tv":0.0,"id":1042126}]}]}
{"op":"mcm","clk":"989101761","pt":1580484259960,"mc":[{"id":"1.168135749","rc":[{"batl":[[1,8.6,3.36]],"ltp":0.0,"tv":0.0,"id":1042126}]}]}
{"op":"mcm","clk":"989102232","pt":1580484266380,"mc":[{"id":"1.168135749","rc":[{"batl":[[1,8.6,5.05]],"ltp":0.0,"tv":0.0,"id":1042126}]}]}
{"op":"mcm","clk":"989105543","pt":1580484307333,"mc":[{"id":"1.168135749","rc":[{"batl":[[0,7.6,1.68],[1,7.8,14.9],[2,8.6,1.68]],"ltp":0.0,"tv":0.0,"id":1042126}]}]}
{"op":"mcm","clk":"989105643","pt":1580484308720,"mc":[{"id":"1.168135749","rc":[{"batl":[[1,8.6,1.68],[2,8.8,33.64]],"ltp":0.0,"tv":0.0,"id":1042126}]}]}
{"op":"mcm","clk":"989105831","pt":1580484310729,"mc":[{"id":"1.168135749","rc":[{"batl":[[0,7.6,15.7]],"ltp":0.0,"tv":0.0,"id":1042126}]}]}
{"op":"mcm","clk":"989108938","pt":1580484349752,"mc":[{"id":"1.168135749","rc":[{"batl":[[1,8.4,23.55],[2,8.6,1.68]],"ltp":0.0,"tv":0.0,"id":1042126}]}]}
{"op":"mcm","clk":"989150832","pt":1580484914565,"mc":[{"id":"1.168135749","rc":[{"trd":[[2.8,19.78]],"batl":[[0,2.84,16.96],[1,2.88,9.75],[2,2.88,0]],"ltp":2.8,"tv":19.78,"id":1042124}],"tv":256.28}]}
{"op":"mcm","clk":"989150866","pt":1580484914983,"mc":[{"id":"1.168135749","rc":[{"batl":[[0,2.8,388.57],[1,2.84,16.96],[2,2.88,9.75]],"ltp":2.8,"tv":19.78,"id":1042124}]}]}
{"op":"mcm","clk":"989186149","pt":1580485231391,"mc":[{"id":"1.168135749","rc":[{"batl":[[2,2.88,0]],"ltp":2.8,"tv":19.78,"id":1042124}]}]}
{"op":"mcm","clk":"989186223","pt":1580485232327,"mc":[{"id":"1.168135749","rc":[{"batl":[[2,2.86,8.93]],"ltp":2.8,"tv":19.78,"id":1042124}]}]}
{"op":"mcm","clk":"989189570","pt":1580485276731,"mc":[{"id":"1.168135749","rc":[{"batl":[[2,2.86,0]],"ltp":2.8,"tv":19.78,"id":1042124}]}]}
{"op":"mcm","clk":"989189635","pt":1580485277452,"mc":[{"id":"1.168135749","rc":[{"batl":[[2,2.88,9.75]],"ltp":2.8,"tv":19.78,"id":1042124}]}]}
{"op":"mcm","clk":"989204046","pt":1580485470448,"mc":[{"id":"1.168135749","rc":[{"trd":[[15.5,100]],"batb":[[0,15.5,17.07]],"ltp":15.5,"tv":100.16,"id":8204664}],"tv":356.28}]}
{"op":"mcm","clk":"989204429","pt":1580485475060,"mc":[{"id":"1.168135749","rc":[{"batb":[[1,12,10],[2,6,100]],"ltp":15.5,"tv":100.16,"id":8204664}]}]}
{"op":"mcm","clk":"989205067","pt":1580485482780,"mc":[{"id":"1.168135749","rc":[{"trd":[[11.5,4.4]],"batb":[[0,11,74.91],[1,1.02,2],[2,1.02,0]],"batl":[[0,11.5,34.56],[1,12,8.41],[2,12.5,104.04]],"ltp":11.5,"tv":30.4,"id":8204663},{"batl":[[2,2.88,0]],"ltp":2.8,"tv":19.78,"id":1042124}],"tv":360.68}]}
{"op":"mcm","clk":"989205107","pt":1580485483319,"mc":[{"id":"1.168135749","rc":[{"batl":[[2,2.9,6.64]],"ltp":2.8,"tv":19.78,"id":1042124}]}]}
{"op":"mcm","clk":"989205321","pt":1580485485472,"mc":[{"id":"1.168135749","rc":[{"trd":[[11.5,8.52]],"batl":[[0,11.5,32.5]],"ltp":11.5,"tv":34.51,"id":8204663},{"batl":[[2,2.9,0]],"ltp":2.8,"tv":19.78,"id":1042124},{"batb":[[2,1.02,2]],"ltp":0.0,"tv":0.0,"id":1042126}],"tv":364.8}]}
{"op":"mcm","clk":"989205359","pt":1580485485990,"mc":[{"id":"1.168135749","rc":[{"batl":[[2,2.92,8.53]],"ltp":2.8,"tv":19.78,"id":1042124}]}]}
{"op":"mcm","clk":"989205485","pt":1580485487673,"mc":[{"id":"1.168135749","rc":[{"batl":[[0,12,8.41],[1,12.5,98],[2,12.5,0]],"ltp":11.5,"tv":34.51,"id":8204663},{"batb":[[1,6.8,55.85]],"ltp":0.0,"tv":0.0,"id":1042126}]}]}
{"op":"mcm","clk":"989205584","pt":1580485488813,"mc":[{"id":"1.168135749","rc":[{"batb":[[0,11.5,2],[1,11,74.91],[2,1.02,2]],"ltp":11.5,"tv":34.51,"id":8204663}]}]}
{"op":"mcm","clk":"989205592","pt":1580485488877,"mc":[{"id":"1.168135749","rc":[{"batl":[[0,12,12.07]],"ltp":11.5,"tv":34.51,"id":8204663}]}]}
{"op":"mcm","clk":"989206481","pt":1580485499321,"mc":[{"id":"1.168135749","rc":[{"trd":[[11,67],[11.5,12.52]],"batb":[[0,11,44.41],[1,1.02,2],[2,1.02,0]],"ltp":11.0,"tv":99.52,"id":8204663}],"tv":429.8}]}
{"op":"mcm","clk":"989206565","pt":1580485500329,"mc":[{"id":"1.168135749","rc":[{"batb":[[1,9.4,10],[2,1.02,2]],"ltp":11.0,"tv":99.52,"id":8204663}]}]}
{"op":"mcm","clk":"989206770","pt":1580485502400,"mc":[{"id":"1.168135749","rc":[{"batb":[[0,11,47.8]],"ltp":11.0,"tv":99.52,"id":8204663}]}]}
{"op":"mcm","clk":"989210341","pt":1580485543760,"mc":[{"id":"1.168135749","rc":[{"batl":[[0,12,8.41]],"ltp":11.0,"tv":99.52,"id":8204663}]}]}
{"op":"mcm","clk":"989210386","pt":1580485544383,"mc":[{"id":"1.168135749","rc":[{"batl":[[2,2.92,0]],"ltp":2.8,"tv":19.78,"id":1042124},{"batb":[[1,6.8,50]],"ltp":0.0,"tv":0.0,"id":1042126}]}]}
{"op":"mcm","clk":"989210423","pt":1580485544857,"mc":[{"id":"1.168135749","rc":[{"batb":[[2,6.6,14.8]],"ltp":0.0,"tv":0.0,"id":1042126}]}]}
{"op":"mcm","clk":"989210500","pt":1580485545845,"mc":[{"id":"1.168135749","rc":[{"batl":[[1,12.5,107.48]],"ltp":11.0,"tv":99.52,"id":8204663},{"batl":[[2,2.88,6.72]],"ltp":2.8,"tv":19.78,"id":1042124}]}]}
{"op":"mcm","clk":"989212864","pt":1580485574701,"mc":[{"id":"1.168135749","rc":[{"batl":[[2,2.88,0]],"ltp":2.8,"tv":19.78,"id":1042124}]}]}
{"op":"mcm","clk":"989212955","pt":1580485575808,"mc":[{"id":"1.168135749","rc":[{"batl":[[2,2.9,7.39]],"ltp":2.8,"tv":19.78,"id":1042124}]}]}
{"op":"mcm","clk":"989237307","pt":1580485891856,"mc":[{"id":"1.168135749","rc":[{"batb":[[0,11,49.48]],"ltp":11.0,"tv":99.52,"id":8204663}]}]}
{"op":"mcm","clk":"989239107","pt":1580485917694,"mc":[{"id":"1.168135749","rc":[{"batl":[[0,2.8,382.67]],"ltp":2.8,"tv":19.78,"id":1042124}]}]}
{"op":"mcm","clk":"989239367","pt":1580485921714,"mc":[{"id":"1.168135749","rc":[{"batl":[[0,12,6.73]],"ltp":11.0,"tv":99.52,"id":8204663}]}]}
{"op":"mcm","clk":"989250653","pt":1580485953731,"mc":[{"id":"1.168135749","rc":[{"batl":[[2,2.88,8.15]],"ltp":2.8,"tv":19.78,"id":1042124},{"batb":[[2,1.02,2]],"ltp":0.0,"tv":0.0,"id":1042126}]}]}
{"op":"mcm","clk":"989250673","pt":1580485954046,"mc":[{"id":"1.168135749","rc":[{"batb":[[1,6.8,56.38]],"ltp":0.0,"tv":0.0,"id":1042126}]}]}
{"op":"mcm","clk":"989255461","pt":1580486024852,"mc":[{"id":"1.168135749","rc":[{"batb":[[1,2.6,288.46],[2,2.42,100]],"ltp":2.8,"tv":19.78,"id":1042124}]}]}
{"op":"mcm","clk":"989255526","pt":1580486025953,"mc":[{"id":"1.168135749","rc":[{"batb":[[2,2.5,16.53]],"ltp":2.8,"tv":19.78,"id":1042124}]}]}
{"op":"mcm","clk":"989311307","pt":1580486642322,"mc":[{"id":"1.168135749","rc":[{"batb":[[0,10,43.66]],"batl":[[1,14.5,26.91]],"ltp":0.0,"tv":0.0,"id":8204665},{"batb":[[0,11,49.48]],"batl":[[0,12,6.73]],"ltp":11.0,"tv":99.52,"id":8204663},{"trd":[[3.65,20],[3.85,39.16]],"batb":[[0,3.65,38.33]],"batl":[[0,3.9,1.68],[1,3.95,49.62],[2,4.1,50]],"ltp":3.65,"tv":210.28,"id":1042125},{"batl":[[0,2.78,2.52],[1,2.8,382.67],[2,2.84,16.92]],"ltp":2.8,"tv":19.78,"id":1042124},{"batb":[[0,7,134.05]],"batl":[[1,8.4,23.55]],"ltp":0.0,"tv":0.0,"id":1042126}],"tv":429.74}]}
{"op":"mcm","clk":"989311396","pt":1580486643218,"mc":[{"id":"1.168135749","rc":[{"batl":[[1,3.95,16.82]],"ltp":3.65,"tv":210.28,"id":1042125}]}]}
{"op":"mcm","clk":"989311513","pt":1580486644320,"mc":[{"id":"1.168135749","rc":[{"batl":[[0,3.9,18.77]],"ltp":3.65,"tv":210.28,"id":1042125}]}]}
{"op":"mcm","clk":"989411939","pt":1580487600772,"mc":[{"id":"1.168135749","rc":[{"batl":[[1,2.84,16.92],[2,2.88,8.15]],"ltp":2.8,"tv":19.78,"id":1042124}]}]}
{"op":"mcm","clk":"989411990","pt":1580487601254,"mc":[{"id":"1.168135749","rc":[{"batl":[[0,2.78,387.27]],"ltp":2.8,"tv":19.78,"id":1042124}]}]}
{"op":"mcm","clk":"989484927","pt":1580488313628,"mc":[{"id":"1.168135749","rc":[{"batb":[[0,15.5,55.07]],"ltp":15.5,"tv":100.16,"id":8204664},{"batb":[[0,10.5,55],[1,10,43.66],[2,9.8,76.53]],"ltp":0.0,"tv":0.0,"id":8204665},{"batb":[[0,11,102.48]],"ltp":11.0,"tv":99.52,"id":8204663},{"batb":[[0,3.65,160.33]],"ltp":3.65,"tv":210.28,"id":1042125},{"batb":[[1,2.62,181],[2,2.6,288.46]],"ltp":2.8,"tv":19.78,"id":1042124},{"batb":[[0,7.2,58],[1,7,134.05],[2,6.8,56.38]],"ltp":0.0,"tv":0.0,"id":1042126}]}]}
{"op":"mcm","clk":"989485020","pt":1580488314647,"mc":[{"id":"1.168135749","rc":[{"batb":[[1,10,34.48]],"ltp":0.0,"tv":0.0,"id":8204665}]}]}
{"op":"mcm","clk":"989485161","pt":1580488316299,"mc":[{"id":"1.168135749","rc":[{"batb":[[1,6,100],[2,1.02,2]],"ltp":15.5,"tv":100.16,"id":8204664},{"batb":[[0,10.5,60.24]],"ltp":0.0,"tv":0.0,"id":8204665},{"batb":[[1,1.02,2],[2,1.02,0]],"ltp":11.0,"tv":99.52,"id":8204663}]}]}
{"op":"mcm","clk":"989489186","pt":1580488361708,"mc":[{"id":"1.168135749","rc":[{"batb":[[0,11,17.66],[1,10.5,60.24],[2,10,34.48]],"ltp":0.0,"tv":0.0,"id":8204665},{"batb":[[0,7.2,74.82]],"ltp":0.0,"tv":0.0,"id":1042126}]}]}
{"op":"mcm","clk":"989498239","pt":1580488471872,"mc":[{"id":"1.168135749","rc":[{"batb":[[2,9.8,76.53]],"ltp":0.0,"tv":0.0,"id":8204665},{"batb":[[1,7,107.14]],"ltp":0.0,"tv":0.0,"id":1042126}]}]}
{"op":"mcm","clk":"989502059","pt":1580488516269,"mc":[{"id":"1.168135749","rc":[{"batl":[[0,2.78,389.77]],"ltp":2.8,"tv":19.78,"id":1042124}]}]}
{"op":"mcm","clk":"989512546","pt":1580488634541,"mc":[{"id":"1.168135749","rc":[{"batl":[[0,2.78,577.27]],"ltp":2.8,"tv":19.78,"id":1042124}]}]}
{"op":"mcm","clk":"989537389","pt":1580488813396,"mc":[{"id":"1.168135749","rc":[{"batl":[[0,2.78,583.27]],"ltp":2.8,"tv":19.78,"id":1042124}]}]}
{"op":"mcm","clk":"989620902","pt":1580489762561,"mc":[{"id":"1.168135749","rc":[{"trd":[[2.7,28.3]],"batb":[[0,2.62,181.18],[1,2.6,288.46],[2,2.42,100]],"batl":[[0,2.78,2.52]],"ltp":2.7,"tv":48.08,"id":1042124}],"tv":458.04}]}
{"op":"mcm","clk":"989621014","pt":1580489763818,"mc":[{"id":"1.168135749","rc":[{"batl":[[2,2.88,0]],"ltp":2.7,"tv":48.08,"id":1042124}]}]}
{"op":"mcm","clk":"989621072","pt":1580489764663,"mc":[{"id":"1.168135749","rc":[{"batb":[[0,16,2],[1,15.5,55.07],[2,6,100]],"ltp":15.5,"tv":100.16,"id":8204664},{"batl":[[2,2.86,8.82]],"ltp":2.7,"tv":48.08,"id":1042124}]}]}
{"op":"mcm","clk":"989621225","pt":1580489766439,"mc":[{"id":"1.168135749","rc":[{"batb":[[0,2.62,181]],"ltp":2.7,"tv":48.08,"id":1042124}]}]}
{"op":"mcm","clk":"989621302","pt":1580489767331,"mc":[{"id":"1.168135749","rc":[{"batb":[[0,2.64,39.63],[1,2.62,181],[2,2.6,288.46]],"ltp":2.7,"tv":48.08,"id":1042124}]}]}
{"op":"mcm","clk":"989623235","pt":1580489792784,"mc":[{"id":"1.168135749","rc":[{"batb":[[0,11,104.16]],"batl":[[1,12.5,121.78]],"ltp":11.0,"tv":99.52,"id":8204663},{"batl":[[0,3.9,32.23]],"ltp":3.65,"tv":210.28,"id":1042125}]}]}
{"op":"mcm","clk":"989623539","pt":1580489796760,"mc":[{"id":"1.168135749","rc":[{"batl":[[0,2.72,576.16],[1,2.78,2.52],[2,2.84,16.92]],"ltp":2.7,"tv":48.08,"id":1042124}]}]}
{"op":"mcm","clk":"989624923","pt":1580489816595,"mc":[{"id":"1.168135749","rc":[{"batl":[[0,2.78,2.52],[1,2.84,16.92],[2,2.86,8.82]],"ltp":2.7,"tv":48.08,"id":1042124}]}]}
{"op":"mcm","clk":"989625379","pt":1580489822714,"mc":[{"id":"1.168135749","rc":[{"batl":[[0,2.76,567.77],[1,2.78,2.52],[2,2.84,16.92]],"ltp":2.7,"tv":48.08,"id":1042124}]}]}
{"op":"mcm","clk":"989625449","pt":1580489823608,"mc":[{"id":"1.168135749","rc":[{"batl":[[0,12.5,121.78],[1,12.5,0]],"ltp":11.0,"tv":99.52,"id":8204663},{"batl":[[1,4.1,50],[2,4.4,10.67]],"ltp":3.65,"tv":210.28,"id":1042125}]}]}
{"op":"mcm","clk":"989627146","pt":1580489846865,"mc":[{"id":"1.168135749","rc":[{"batl":[[0,3.75,15.74],[1,3.9,32.23],[2,4.1,50]],"ltp":3.65,"tv":210.28,"id":1042125}]}]}
{"op":"mcm","clk":"989821232","pt":1580491636590,"mc":[{"id":"1.168135749","rc":[{"trd":[[2.64,33.82]],"batb":[[0,2.64,22.73]],"batl":[[2,2.86,8.82]],"ltp":2.64,"tv":81.89,"id":1042124}],"tv":491.86}]}
{"op":"mcm","clk":"989821402","pt":1580491638488,"mc":[{"id":"1.168135749","rc":[{"batl":[[2,2.86,0]],"ltp":2.64,"tv":81.89,"id":1042124}]}]}
{"op":"mcm","clk":"989821514","pt":1580491639594,"mc":[{"id":"1.168135749","rc":[{"batb":[[0,2.62,181],[1,2.6,288.46],[2,2.42,100]],"batl":[[2,2.84,9.68]],"ltp":2.64,"tv":81.89,"id":1042124}]}]}
{"op":"mcm","clk":"989821637","pt":1580491640701,"mc":[{"id":"1.168135749","rc":[{"batb":[[0,2.64,32.27],[1,2.62,181],[2,2.6,288.46]],"ltp":2.64,"tv":81.89,"id":1042124}]}]}
{"op":"mcm","clk":"989925704","pt":1580492431790,"mc":[{"id":"1.168135749","rc":[{"batl":[[0,12.5,112.3]],"ltp":11.0,"tv":99.52,"id":8204663},{"batl":[[2,2.84,0]],"ltp":2.64,"tv":81.89,"id":1042124}]}]}
{"op":"mcm","clk":"989925881","pt":1580492433517,"mc":[{"id":"1.168135749","rc":[{"batl":[[1,13,8.97]],"ltp":11.0,"tv":99.52,"id":8204663},{"batl":[[2,2.8,9.61]],"ltp":2.64,"tv":81.89,"id":1042124}]}]}
{"op":"mcm","clk":"989926318","pt":1580492438125,"mc":[{"id":"1.168135749","rc":[{"batb":[[0,16,23]],"ltp":15.5,"tv":100.16,"id":8204664},{"batb":[[0,11,45.66]],"ltp":0.0,"tv":0.0,"id":8204665},{"batb":[[0,11,133.16]],"ltp":11.0,"tv":99.52,"id":8204663}]}]}
{"op":"mcm","clk":"989935492","pt":1580492527932,"mc":[{"id":"1.168135749","rc":[{"batl":[[0,2.68,6.6],[1,2.76,567.77],[2,2.78,2.52]],"ltp":2.64,"tv":81.89,"id":1042124}]}]}
{"op":"mcm","clk":"989944764","pt":1580492624377,"mc":[{"id":"1.168135749","rc":[{"batl":[[2,15,32.8]],"ltp":0.0,"tv":0.0,"id":8204665},{"batb":[[0,11,136.52]],"ltp":11.0,"tv":99.52,"id":8204663},{"batl":[[1,3.9,36.43]],"ltp":3.65,"tv":210.28,"id":1042125}]}]}
{"op":"mcm","clk":"989947795","pt":1580492654009,"mc":[{"id":"1.168135749","rc":[{"batl":[[1,15,32.8],[2,15,0]],"ltp":0.0,"tv":0.0,"id":8204665},{"batl":[[0,12.5,108.09]],"ltp":11.0,"tv":99.52,"id":8204663},{"batb":[[0,3.65,149.4]],"ltp":3.65,"tv":210.28,"id":1042125},{"batb":[[0,7.2,72.3]],"ltp":0.0,"tv":0.0,"id":1042126}]}]}
{"op":"mcm","clk":"989971169","pt":1580492873745,"mc":[{"id":"1.168135749","rc":[{"batb":[[2,1.02,2]],"batl":[[2,4.4,10.67]],"ltp":3.65,"tv":210.28,"id":1042125},{"batb":[[2,6.8,6.38]],"ltp":0.0,"tv":0.0,"id":1042126}]}]}
{"op":"mcm","clk":"989971202","pt":1580492874109,"mc":[{"id":"1.168135749","rc":[{"batl":[[0,2.68,591.24],[1,2.78,2.52],[2,2.8,9.61]],"ltp":2.64,"tv":81.89,"id":1042124}]}]}
{"op":"mcm","clk":"990094308","pt":1580494052126,"mc":[{"id":"1.168135749","rc":[{"batb":[[0,11,45.64]],"batl":[[1,15,32.75]],"ltp":0.0,"tv":0.0,"id":8204665},{"batb":[[0,11,136.51]],"batl":[[0,12.5,108.08]],"ltp":11.0,"tv":99.52,"id":8204663},{"trd":[[3.65,19.99],[3.85,39.14]],"batb":[[0,3.65,149.37]],"batl":[[0,3.75,15.73],[1,3.9,36.41],[2,4.4,10.66]],"ltp":3.65,"tv":210.24,"id":1042125},{"trd":[[2.64,33.8]],"batl":[[0,2.68,591.24],[1,2.78,2.52]],"ltp":2.64,"tv":81.87,"id":1042124},{"batb":[[0,7.2,72.28]],"batl":[[0,7.6,15.7],[1,8.4,23.52],[2,8.6,1.68]],"ltp":0.0,"tv":0.0,"id":1042126}],"tv":491.8}]}
{"op":"mcm","clk":"990124127","pt":1580494344851,"mc":[{"id":"1.168135749","rc":[{"trd":[[7.2,14]],"batb":[[0,7.2,65.28]],"ltp":7.2,"tv":14.0,"id":1042126}],"tv":505.8}]}
{"op":"mcm","clk":"990194573","pt":1580494958341,"mc":[{"id":"1.168135749","rc":[{"batl":[[1,13,0]],"ltp":11.0,"tv":99.52,"id":8204663},{"batl":[[2,2.8,0]],"ltp":2.64,"tv":81.87,"id":1042124}]}]}
{"op":"mcm","clk":"990194667","pt":1580494959331,"mc":[{"id":"1.168135749","rc":[{"batl":[[0,12.5,111.99]],"ltp":11.0,"tv":99.52,"id":8204663},{"batl":[[2,2.82,10.67]],"ltp":2.64,"tv":81.87,"id":1042124}]}]}
{"op":"mcm","clk":"990199107","pt":1580495007700,"mc":[{"id":"1.168135749","rc":[{"trd":[[16,4]],"batb":[[0,16,21]],"ltp":16.0,"tv":104.16,"id":8204664}],"tv":509.8}]}
{"op":"mcm","clk":"990244390","pt":1580495524589,"mc":[{"id":"1.168135749","rc":[{"batl":[[2,2.82,0]],"ltp":2.64,"tv":81.87,"id":1042124}]}]}
{"op":"mcm","clk":"990244509","pt":1580495525608,"mc":[{"id":"1.168135749","rc":[{"batl":[[2,2.84,9.41]],"ltp":2.64,"tv":81.87,"id":1042124}]}]}
{"op":"mcm","clk":"990272736","pt":1580495801671,"mc":[{"id":"1.168135749","rc":[{"batl":[[0,2.68,6.6]],"ltp":2.64,"tv":81.87,"id":1042124}]}]}
{"op":"mcm","clk":"990372994","pt":1580496717008,"mc":[{"id":"1.168135749","rc":[{"trd":[[19.5,4]],"batl":[[0,20,87.72],[1,20,0]],"ltp":19.5,"tv":108.16,"id":8204664}],"tv":513.8}]}
{"op":"mcm","clk":"990373262","pt":1580496719129,"mc":[{"id":"1.168135749","rc":[{"batb":[[0,16.5,2],[1,16,21],[2,15.5,55.07]],"ltp":19.5,"tv":108.16,"id":8204664}]}]}
{"op":"mcm","clk":"990373450","pt":1580496720742,"mc":[{"id":"1.168135749","rc":[{"batl":[[0,19.5,10.61],[1,20,87]],"ltp":19.5,"tv":108.16,"id":8204664}]}]}
{"op":"mcm","clk":"990419939","pt":1580497055667,"mc":[{"id":"1.168135749","rc":[{"trd":[[7.6,7.58]],"batl":[[0,7.6,11.91]],"ltp":7.6,"tv":21.57,"id":1042126}],"tv":521.38}]}
{"op":"mcm","clk":"990420309","pt":1580497058872,"mc":[{"id":"1.168135749","rc":[{"batl":[[0,8.4,23.52],[1,8.6,1.68],[2,9.4,1.68]],"ltp":7.6,"tv":21.57,"id":1042126}]}]}
{"op":"mcm","clk":"990420514","pt":1580497060545,"mc":[{"id":"1.168135749","rc":[{"batl":[[0,8.2,11.76],[1,8.4,23.52],[2,8.6,1.68]],"ltp":7.6,"tv":21.57,"id":1042126}]}]}
{"op":"mcm","clk":"990422858","pt":1580497083715,"mc":[{"id":"1.168135749","rc":[{"batl":[[0,12.5,108.08]],"ltp":11.0,"tv":99.52,"id":8204663},{"batl":[[2,2.84,0]],"ltp":2.64,"tv":81.87,"id":1042124}]}]}
{"op":"mcm","clk":"990423030","pt":1580497085199,"mc":[{"id":"1.168135749","rc":[{"batl":[[1,13,9.1]],"ltp":11.0,"tv":99.52,"id":8204663},{"batl":[[2,2.8,9.9]],"ltp":2.64,"tv":81.87,"id":1042124}]}]}
{"op":"mcm","clk":"990437516","pt":1580497223022,"mc":[{"id":"1.168135749","rc":[{"batl":[[1,8.6,1.68],[2,8.8,41.99]],"ltp":7.6,"tv":21.57,"id":1042126}]}]}
{"op":"mcm","clk":"990549275","pt":1580497945539,"mc":[{"id":"1.168135749","rc":[{"batb":[[0,2.62,181],[1,2.6,288.46],[2,2,1300]],"batl":[[2,2.8,0]],"ltp":2.64,"tv":81.87,"id":1042124},{"batb":[[2,1.02,2]],"ltp":7.6,"tv":21.57,"id":1042126}]}]}
{"op":"mcm","clk":"990549336","pt":1580497945913,"mc":[{"id":"1.168135749","rc":[{"batl":[[1,2.76,11.82],[2,2.78,2.52]],"ltp":2.64,"tv":81.87,"id":1042124}]}]}
{"op":"mcm","clk":"990549480","pt":1580497946826,"mc":[{"id":"1.168135749","rc":[{"batb":[[0,2.62,197.28]],"ltp":2.64,"tv":81.87,"id":1042124},{"batb":[[1,7,122.38]],"ltp":7.6,"tv":21.57,"id":1042126}]}]}
{"op":"mcm","clk":"990550246","pt":1580497951811,"mc":[{"id":"1.168135749","rc":[{"batl":[[1,3.9,19.32]],"ltp":3.65,"tv":210.24,"id":1042125},{"batb":[[0,2.62,181]],"batl":[[1,2.78,2.52],[2,2.78,0]],"ltp":2.64,"tv":81.87,"id":1042124},{"batb":[[1,7,107.14]],"ltp":7.6,"tv":21.57,"id":1042126}]}]}
{"op":"mcm","clk":"990550373","pt":1580497952635,"mc":[{"id":"1.168135749","rc":[{"batb":[[1,2.6,303.93]],"ltp":2.64,"tv":81.87,"id":1042124},{"batb":[[0,7.2,73.19]],"ltp":7.6,"tv":21.57,"id":1042126}]}]}
{"op":"mcm","clk":"990550420","pt":1580497952917,"mc":[{"id":"1.168135749","rc":[{"batl":[[2,3.95,11.66]],"ltp":3.65,"tv":210.24,"id":1042125},{"batl":[[1,2.72,9.46],[2,2.78,2.52]],"ltp":2.64,"tv":81.87,"id":1042124}]}]}
{"op":"mcm","clk":"990607469","pt":1580498333010,"mc":[{"id":"1.168135749","rc":[{"batb":[[1,16,23]],"ltp":19.5,"tv":108.16,"id":8204664}]}]}
{"op":"mcm","clk":"990607994","pt":1580498336823,"mc":[{"id":"1.168135749","rc":[{"batb":[[0,11,138.51]],"ltp":11.0,"tv":99.52,"id":8204663}]}]}
{"op":"mcm","clk":"990608324","pt":1580498339029,"mc":[{"id":"1.168135749","rc":[{"batb":[[0,11,47.64]],"ltp":0.0,"tv":0.0,"id":8204665}]}]}
{"op":"mcm","clk":"990608873","pt":1580498343017,"mc":[{"id":"1.168135749","rc":[{"batb":[[1,2.6,307.93]],"ltp":2.64,"tv":81.87,"id":1042124}]}]}
{"op":"mcm","clk":"990609071","pt":1580498344316,"mc":[{"id":"1.168135749","rc":[{"batb":[[0,2.62,185]],"ltp":2.64,"tv":81.87,"id":1042124}]}]}
{"op":"mcm","clk":"990609286","pt":1580498345729,"mc":[{"id":"1.168135749","rc":[{"batb":[[2,2.5,4]],"ltp":2.64,"tv":81.87,"id":1042124}]}]}
{"op":"mcm","clk":"990610320","pt":1580498353141,"mc":[{"id":"1.168135749","rc":[{"batb":[[0,3.65,152.37]],"ltp":3.65,"tv":210.24,"id":1042125}]}]}
{"op":"mcm","clk":"990610468","pt":1580498354284,"mc":[{"id":"1.168135749","rc":[{"batb":[[1,3.6,211.33]],"ltp":3.65,"tv":210.24,"id":1042125}]}]}
{"op":"mcm","clk":"990610649","pt":1580498355458,"mc":[{"id":"1.168135749","rc":[{"batb":[[2,3.35,3]],"ltp":3.65,"tv":210.24,"id":1042125}]}]}
{"op":"mcm","clk":"990612013","pt":1580498366079,"mc":[{"id":"1.168135749","rc":[{"batb":[[0,7.2,75.19]],"ltp":7.6,"tv":21.57,"id":1042126}]}]}
{"op":"mcm","clk":"990612166","pt":1580498367375,"mc":[{"id":"1.168135749","rc":[{"batb":[[1,7,109.14]],"ltp":7.6,"tv":21.57,"id":1042126}]}]}
{"op":"mcm","clk":"990612304","pt":1580498368562,"mc":[{"id":"1.168135749","rc":[{"batb":[[2,6,2]],"ltp":7.6,"tv":21.57,"id":1042126}]}]}
{"op":"mcm","clk":"990664603","pt":1580498671748,"mc":[{"id":"1.168135749","rc":[{"trd":[[11,83.8]],"batb":[[0,11,130.11]],"ltp":11.0,"tv":116.31,"id":8204663}],"tv":538.18}]}
{"op":"mcm","clk":"990729505","pt":1580499096443,"mc":[{"id":"1.168135749","rc":[{"batb":[[0,16.5,40],[2,15.5,17.07]],"ltp":19.5,"tv":108.16,"id":8204664}]}]}
{"op":"mcm","clk":"990730703","pt":1580499103646,"mc":[{"id":"1.168135749","rc":[{"batb":[[0,11,102.64],[1,10.5,5.24]],"ltp":0.0,"tv":0.0,"id":8204665}]}]}
{"op":"mcm","clk":"991045160","pt":1580501252131,"mc":[{"id":"1.168135749","rc":[{"batb":[[0,11,102.64]],"batl":[[1,15,32.76]],"ltp":0.0,"tv":0.0,"id":8204665},{"batb":[[0,11,130.11]],"ltp":11.0,"tv":116.31,"id":8204663},{"trd":[[3.85,39.13]],"batb":[[0,3.65,152.37]],"batl":[[0,3.75,15.75],[1,3.9,19.32]],"ltp":3.65,"tv":210.23,"id":1042125},{"trd":[[2.64,33.78]],"batl":[[0,2.68,6.59]],"ltp":2.64,"tv":81.86,"id":1042124},{"batb":[[0,7.2,75.19]],"batl":[[2,8.8,42]],"ltp":7.6,"tv":21.57,"id":1042126}],"tv":538.15}]}
{"op":"mcm","clk":"991091010","pt":1580501527805,"mc":[{"id":"1.168135749","rc":[{"trd":[[3.75,4.28]],"batl":[[0,3.75,13.61]],"ltp":3.75,"tv":214.51,"id":1042125}],"tv":542.44}]}
{"op":"mcm","clk":"991148232","pt":1580501877317,"mc":[{"id":"1.168135749","rc":[{"batb":[[0,17,50.39],[1,16.5,40],[2,16,23]],"ltp":19.5,"tv":108.16,"id":8204664}]}]}
{"op":"mcm","clk":"991148459","pt":1580501878749,"mc":[{"id":"1.168135749","rc":[{"batb":[[1,16.5,38]],"ltp":19.5,"tv":108.16,"id":8204664}]}]}
{"op":"mcm","clk":"991148724","pt":1580501880447,"mc":[{"id":"1.168135749","rc":[{"batb":[[0,17.5,2],[1,17,50.39],[2,16.5,38]],"ltp":19.5,"tv":108.16,"id":8204664}]}]}
{"op":"mcm","clk":"991250778","pt":1580502502512,"mc":[{"id":"1.168135749","rc":[{"trd":[[2.68,12]],"batl":[[0,2.72,10.05],[1,2.78,2.52],[2,2.78,0]],"ltp":2.68,"tv":93.86,"id":1042124}],"tv":554.44}]}
{"op":"mcm","clk":"991284604","pt":1580502746847,"mc":[{"id":"1.168135749","rc":[{"batl":[[0,2.64,10],[1,2.72,10.05],[2,2.78,2.52]],"ltp":2.68,"tv":93.86,"id":1042124}]}]}
{"op":"mcm","clk":"991368017","pt":1580503283047,"mc":[{"id":"1.168135749","rc":[{"batl":[[1,14.5,23.52],[2,15,32.76]],"ltp":0.0,"tv":0.0,"id":8204665},{"batl":[[0,12.5,111.44]],"ltp":11.0,"tv":116.31,"id":8204663},{"batb":[[0,3.65,161.61]],"ltp":3.75,"tv":214.51,"id":1042125},{"batb":[[0,7.2,77.71]],"ltp":7.6,"tv":21.57,"id":1042126}]}]}
{"op":"mcm","clk":"991370362","pt":1580503303132,"mc":[{"id":"1.168135749","rc":[{"trd":[[2.64,53.06]],"batl":[[0,2.72,10.41],[1,2.78,2.52],[2,2.78,0]],"ltp":2.64,"tv":113.14,"id":1042124}],"tv":573.71}]}
{"op":"mcm","clk":"991371561","pt":1580503312937,"mc":[{"id":"1.168135749","rc":[{"batl":[[2,15,0]],"ltp":0.0,"tv":0.0,"id":8204665},{"batb":[[0,11,126.75]],"ltp":11.0,"tv":116.31,"id":8204663},{"batl":[[1,3.9,15.96]],"ltp":3.75,"tv":214.51,"id":1042125}]}]}
{"op":"mcm","clk":"991372541","pt":1580503321562,"mc":[{"id":"1.168135749","rc":[{"batl":[[0,8,2.54],[1,8.2,11.76],[2,8.6,1.68]],"ltp":7.6,"tv":21.57,"id":1042126}]}]}
{"op":"mcm","clk":"991372692","pt":1580503322745,"mc":[{"id":"1.168135749","rc":[{"batl":[[1,8.6,1.68],[2,8.8,42]],"ltp":7.6,"tv":21.57,"id":1042126}]}]}
{"op":"mcm","clk":"991372812","pt":1580503323754,"mc":[{"id":"1.168135749","rc":[{"batl":[[0,8,8.51]],"ltp":7.6,"tv":21.57,"id":1042126}]}]}
{"op":"mcm","clk":"991375104","pt":1580503342077,"mc":[{"id":"1.168135749","rc":[{"batl":[[0,12,2.54],[1,12.5,111.44],[2,13,9.1]],"ltp":11.0,"tv":116.31,"id":8204663}]}]}
{"op":"mcm","clk":"991376923","pt":1580503356896,"mc":[{"id":"1.168135749","rc":[{"batl":[[0,12,2.54],[1,12.5,14.03],[2,14.5,23.52]],"ltp":0.0,"tv":0.0,"id":8204665}]}]}
{"op":"mcm","clk":"991377240","pt":1580503359510,"mc":[{"id":"1.168135749","rc":[{"batl":[[1,14.5,23.52],[2,14.5,0]],"ltp":0.0,"tv":0.0,"id":8204665}]}]}
{"op":"mcm","clk":"991377435","pt":1580503361207,"mc":[{"id":"1.168135749","rc":[{"batl":[[0,12,7.03]],"ltp":0.0,"tv":0.0,"id":8204665}]}]}
{"op":"mcm","clk":"991586106","pt":1580505548853,"mc":[{"id":"1.168135749","rc":[{"batl":[[2,15,33.6]],"ltp":0.0,"tv":0.0,"id":8204665}]}]}
{"op":"mcm","clk":"991588347","pt":1580505578805,"mc":[{"id":"1.168135749","rc":[{"batl":[[1,15,33.6],[2,15,0]],"ltp":0.0,"tv":0.0,"id":8204665},{"batb":[[0,7.2,75.19]],"ltp":7.6,"tv":21.57,"id":1042126}]}]}
{"op":"mcm","clk":"991639856","pt":1580506139493,"mc":[{"id":"1.168135749","rc":[{"batb":[[0,2.62,4],[2,2.56,181]],"ltp":2.64,"tv":113.14,"id":1042124}]}]}
{"op":"mcm","clk":"991639893","pt":1580506140213,"mc":[{"id":"1.168135749","rc":[{"batb":[[1,2.6,324.91]],"ltp":2.64,"tv":113.14,"id":1042124}]}]}
{"op":"mcm","clk":"991641251","pt":1580506159848,"mc":[{"id":"1.168135749","rc":[{"batl":[[0,19,5],[1,19.5,10.61],[2,20,87]],"ltp":19.5,"tv":108.16,"id":8204664}]}]}
{"op":"mcm","clk":"991641390","pt":1580506162131,"mc":[{"id":"1.168135749","rc":[{"batl":[[1,20,87],[2,20,0]],"ltp":19.5,"tv":108.16,"id":8204664}]}]}
{"op":"mcm","clk":"991641499","pt":1580506164252,"mc":[{"id":"1.168135749","rc":[{"batl":[[0,19,11.25]],"ltp":19.5,"tv":108.16,"id":8204664}]}]}
{"op":"mcm","clk":"991642387","pt":1580506181154,"mc":[{"id":"1.168135749","rc":[{"batl":[[2,38,2]],"ltp":19.5,"tv":108.16,"id":8204664}]}]}
{"op":"mcm","clk":"991782013","pt":1580508160396,"mc":[{"id":"1.168135749","rc":[{"batb":[[1,17,50.41]],"ltp":19.5,"tv":108.16,"id":8204664},{"batb":[[0,11,102.64]],"batl":[[0,12,7.02],[1,15,33.61]],"ltp":0.0,"tv":0.0,"id":8204665},{"trd":[[11,83.8]],"batb":[[0,11,126.75]],"batl":[[0,12,2.53],[1,12.5,111.44]],"ltp":11.0,"tv":116.32,"id":8204663},{"trd":[[3.65,19.99],[3.75,4.28],[3.85,39.12]],"batb":[[0,3.65,161.62]],"batl":[[0,3.75,13.6],[1,3.9,14.28]],"ltp":3.75,"tv":214.51,"id":1042125},{"trd":[[2.64,53.05],[2.68,11.99]],"batl":[[1,2.78,0]],"ltp":2.64,"tv":113.12,"id":1042124},{"batb":[[0,7.2,75.19]],"batl":[[0,8,8.5],[2,8.8,42.01]],"ltp":7.6,"tv":21.58,"id":1042126}],"tv":573.7}]}
{"op":"mcm","clk":"991871764","pt":1580509424189,"mc":[{"id":"1.168135749","rc":[{"trd":[[2.64,53.77],[2.68,13.18],[2.72,7.26]],"batl":[[0,2.72,5.83]],"ltp":2.72,"tv":122.28,"id":1042124}],"tv":582.86}]}
{"op":"mcm","clk":"991872052","pt":1580509430371,"mc":[{"id":"1.168135749","rc":[{"batl":[[0,2.88,34.98]],"ltp":2.72,"tv":122.28,"id":1042124}]}]}
{"op":"mcm","clk":"991876908","pt":1580509521348,"mc":[{"id":"1.168135749","rc":[{"batl":[[0,2.84,566.53],[1,2.88,34.98]],"ltp":2.72,"tv":122.28,"id":1042124}]}]}
{"op":"mcm","clk":"991876989","pt":1580509522689,"mc":[{"id":"1.168135749","rc":[{"batl":[[1,2.88,0]],"ltp":2.72,"tv":122.28,"id":1042124}]}]}
{"op":"mcm","clk":"991877085","pt":1580509524555,"mc":[{"id":"1.168135749","rc":[{"batl":[[0,2.82,26.18],[1,2.84,566.53]],"ltp":2.72,"tv":122.28,"id":1042124}]}]}
{"op":"mcm","clk":"991954353","pt":1580511066774,"mc":[{"id":"1.168135749","rc":[{"trd":[[3.65,46.35]],"batb":[[0,3.65,148.44]],"ltp":3.65,"tv":240.87,"id":1042125}],"tv":609.22}]}
{"op":"mcm","clk":"991957584","pt":1580511140066,"mc":[{"id":"1.168135749","rc":[{"batb":[[0,11,130.11]],"ltp":11.0,"tv":116.32,"id":8204663},{"batb":[[0,3.65,154.32]],"batl":[[1,3.9,17.64]],"ltp":3.65,"tv":240.87,"id":1042125},{"batb":[[0,7.2,77.71]],"ltp":7.6,"tv":21.58,"id":1042126}]}]}
{"op":"mcm","clk":"991967949","pt":1580511154916,"mc":[{"id":"1.168135749","rc":[{"trd":[[11,101.38]],"batb":[[0,11,121.32]],"ltp":11.0,"tv":133.89,"id":8204663}],"tv":626.8}]}
{"op":"mcm","clk":"991968719","pt":1580511170607,"mc":[{"id":"1.168135749","rc":[{"batl":[[1,12.5,108.08]],"ltp":11.0,"tv":133.89,"id":8204663},{"batb":[[0,3.65,153.13]],"ltp":3.65,"tv":240.87,"id":1042125}]}]}
{"op":"mcm","clk":"991977798","pt":1580511395796,"mc":[{"id":"1.168135749","rc":[{"trd":[[2.62,8]],"batb":[[0,2.6,324.91],[1,2.56,181],[2,2.5,4]],"batl":[[0,2.62,6],[1,2.82,26.18]],"ltp":2.62,"tv":130.28,"id":1042124}],"tv":634.8}]}
{"op":"mcm","clk":"991977858","pt":1580511396972,"mc":[{"id":"1.168135749","rc":[{"batl":[[1,2.82,0]],"ltp":2.62,"tv":130.28,"id":1042124}]}]}
{"op":"mcm","clk":"991977923","pt":1580511398767,"mc":[{"id":"1.168135749","rc":[{"trd":[[3.75,12.1]],"batl":[[0,3.75,9.69]],"ltp":3.75,"tv":248.69,"id":1042125},{"trd":[[2.62,19.66]],"batl":[[0,2.72,10.83]],"ltp":2.62,"tv":141.94,"id":1042124}],"tv":654.28}]}
{"op":"mcm","clk":"991978358","pt":1580511408492,"mc":[{"id":"1.168135749","rc":[{"batl":[[0,2.72,10.66]],"ltp":2.62,"tv":141.94,"id":1042124}]}]}
{"op":"mcm","clk":"991989132","pt":1580511647930,"mc":[{"id":"1.168135749","rc":[{"trd":[[3.65,52.41]],"batb":[[0,3.65,150.1]],"ltp":3.65,"tv":254.75,"id":1042125}],"tv":660.34}]}
{"op":"mcm","clk":"991989315","pt":1580511651742,"mc":[{"id":"1.168135749","rc":[{"batb":[[0,3.65,149.37]],"ltp":3.65,"tv":254.75,"id":1042125}]}]}
{"op":"mcm","clk":"991989407","pt":1580511653446,"mc":[{"id":"1.168135749","rc":[{"batb":[[0,3.7,10.71],[1,3.65,149.37],[2,3.6,211.33]],"ltp":3.65,"tv":254.75,"id":1042125}]}]}
{"op":"mcm","clk":"991991655","pt":1580511708815,"mc":[{"id":"1.168135749","rc":[{"batb":[[2,1.01,2.53]],"ltp":11.0,"tv":133.89,"id":8204663}]}]}
{"op":"mcm","clk":"991991690","pt":1580511709642,"mc":[{"id":"1.168135749","rc":[{"batb":[[2,1.01,0.51]],"ltp":11.0,"tv":133.89,"id":8204663}]}]}
{"op":"mcm","clk":"992004295","pt":1580511985664,"mc":[{"id":"1.168135749","rc":[{"batb":[[2,1.01,1.01]],"ltp":11.0,"tv":133.89,"id":8204663}]}]}
{"op":"mcm","clk":"992024017","pt":1580512224576,"mc":[{"id":"1.168135749","rc":[{"batb":[[0,2.62,5.07],[1,2.6,324.91],[2,2.56,181]],"ltp":2.62,"tv":141.94,"id":1042124}]}]}
{"op":"mcm","clk":"992080394","pt":1580513375330,"mc":[{"id":"1.168135749","rc":[{"trd":[[3.75,31.48]],"batb":[[0,3.75,43.93],[1,3.7,10.71],[2,3.65,149.37]],"batl":[[0,3.9,17.64],[1,3.95,11.66],[2,4.4,10.64]],"ltp":3.75,"tv":274.13,"id":1042125}],"tv":679.72}]}
{"op":"mcm","clk":"992080473","pt":1580513376993,"mc":[{"id":"1.168135749","rc":[{"batb":[[1,3.65,149.37],[2,3.6,211.33]],"ltp":3.75,"tv":274.13,"id":1042125}]}]}
{"op":"mcm","clk":"992080547","pt":1580513379003,"mc":[{"id":"1.168135749","rc":[{"batb":[[0,3.75,50.44]],"ltp":3.75,"tv":274.13,"id":1042125}]}]}
{"op":"mcm","clk":"992082607","pt":1580513424775,"mc":[{"id":"1.168135749","rc":[{"batb":[[1,3.7,17.64],[2,3.65,149.37]],"batl":[[2,4.2,67.22]],"ltp":3.75,"tv":274.13,"id":1042125}]}]}
{"op":"mcm","clk":"992086976","pt":1580513534701,"mc":[{"id":"1.168135749","rc":[{"batb":[[2,3.65,125]],"batl":[[0,3.95,11.66],[1,4.2,67.22],[2,4.4,10.64]],"ltp":3.75,"tv":274.13,"id":1042125}]}]}
{"op":"mcm","clk":"992155762","pt":1580515006246,"mc":[{"id":"1.168135749","rc":[{"batl":[[1,2.8,500]],"ltp":2.62,"tv":141.94,"id":1042124}]}]}
{"op":"mcm","clk":"992185694","pt":1580515680062,"mc":[{"id":"1.168135749","rc":[{"batl":[[1,2.8,0]],"ltp":2.62,"tv":141.94,"id":1042124}]}]}
{"op":"mcm","clk":"992227139","pt":1580516993763,"mc":[{"id":"1.168135749","rc":[{"trd":[[2.62,29.8]],"batb":[[0,2.6,324.91],[1,2.56,181],[2,2.5,4]],"batl":[[0,2.62,6.17],[1,2.72,10.66]],"ltp":2.62,"tv":152.08,"id":1042124}],"tv":689.85}]}
{"op":"mcm","clk":"992227593","pt":1580517006971,"mc":[{"id":"1.168135749","rc":[{"trd":[[3.75,110.18]],"batb":[[0,3.75,11.09]],"ltp":3.75,"tv":352.83,"id":1042125}],"tv":768.56}]}
{"op":"mcm","clk":"992228215","pt":1580517021211,"mc":[{"id":"1.168135749","rc":[{"trd":[[2.6,51.72]],"batb":[[0,2.6,299.05]],"ltp":2.6,"tv":203.8,"id":1042124}],"tv":820.28}]}
{"op":"mcm","clk":"992257102","pt":1580517763807,"mc":[{"id":"1.168135749","rc":[{"batl":[[0,3.9,100],[1,3.95,11.66],[2,4.2,67.22]],"ltp":3.75,"tv":352.83,"id":1042125}]}]}
{"op":"mcm","clk":"992257945","pt":1580517796730,"mc":[{"id":"1.168135749","rc":[{"batl":[[0,7.8,20],[1,8,8.5],[2,8.6,1.68]],"ltp":7.6,"tv":21.58,"id":1042126}]}]}
{"op":"mcm","clk":"992257965","pt":1580517797453,"mc":[{"id":"1.168135749","rc":[{"batl":[[1,8,2.53]],"ltp":7.6,"tv":21.58,"id":1042126}]}]}
{"op":"mcm","clk":"992257996","pt":1580517798648,"mc":[{"id":"1.168135749","rc":[{"batl":[[0,7.6,2],[1,7.8,20],[2,8,2.53]],"ltp":7.6,"tv":21.58,"id":1042126}]}]}
{"op":"mcm","clk":"992258808","pt":1580517829964,"mc":[{"id":"1.168135749","rc":[{"batl":[[0,3.9,117.64]],"ltp":3.75,"tv":352.83,"id":1042125},{"batl":[[2,8,16.82]],"ltp":7.6,"tv":21.58,"id":1042126}]}]}
{"op":"mcm","clk":"992261083","pt":1580517939993,"mc":[{"id":"1.168135749","rc":[{"batl":[[2,4.4,10.64]],"ltp":3.75,"tv":352.83,"id":1042125}]}]}
{"op":"mcm","clk":"992266566","pt":1580518182385,"mc":[{"id":"1.168135749","rc":[{"trd":[[2.62,40.38]],"batl":[[0,2.72,11.54],[1,2.72,0]],"ltp":2.62,"tv":214.38,"id":1042124}],"tv":830.86}]}
{"op":"mcm","clk":"992270077","pt":1580518325483,"mc":[{"id":"1.168135749","rc":[{"trd":[[7.2,54]],"batb":[[0,7.2,57.71]],"batl":[[1,8,16.82],[2,8.6,1.68]],"ltp":7.2,"tv":61.58,"id":1042126}],"tv":870.86}]}
{"op":"mcm","clk":"992283108","pt":1580518491386,"mc":[{"id":"1.168135749","rc":[{"batl":[[1,8,2.53]],"ltp":7.2,"tv":61.58,"id":1042126}]}]}
{"op":"mcm","clk":"992301516","pt":1580519159989,"mc":[{"id":"1.168135749","rc":[{"batl":[[0,3.85,2.27],[1,3.9,117.64],[2,3.95,11.66]],"ltp":3.75,"tv":352.83,"id":1042125}]}]}
{"op":"mcm","clk":"992316301","pt":1580519363489,"mc":[{"id":"1.168135749","rc":[{"batl":[[0,11.5,14.18],[1,12,7.02],[2,15,33.61]],"ltp":0.0,"tv":0.0,"id":8204665}]}]}
{"op":"mcm","clk":"992316331","pt":1580519364525,"mc":[{"id":"1.168135749","rc":[{"batl":[[1,12,2.53]],"ltp":0.0,"tv":0.0,"id":8204665}]}]}
{"op":"mcm","clk":"992316367","pt":1580519365403,"mc":[{"id":"1.168135749","rc":[{"batl":[[0,11.5,16.18]],"ltp":0.0,"tv":0.0,"id":8204665}]}]}
{"op":"mcm","clk":"992316577","pt":1580519373013,"mc":[{"id":"1.168135749","rc":[{"trd":[[11.5,20.16]],"batl":[[0,11.5,6.11],[2,13,10.08]],"ltp":11.5,"tv":20.15,"id":8204665}],"tv":891.02}]}
{"op":"mcm","clk":"992316706","pt":1580519377029,"mc":[{"id":"1.168135749","rc":[{"batl":[[0,11.5,2],[2,12.5,4.11]],"ltp":11.5,"tv":20.15,"id":8204665}]}]}
{"op":"mcm","clk":"992317456","pt":1580519403655,"mc":[{"id":"1.168135749","rc":[{"batl":[[0,12,10.64]],"ltp":11.0,"tv":133.89,"id":8204663}]}]}
{"op":"mcm","clk":"992317692","pt":1580519412583,"mc":[{"id":"1.168135749","rc":[{"batl":[[0,12,9.62]],"ltp":11.0,"tv":133.89,"id":8204663}]}]}
{"op":"mcm","clk":"992319503","pt":1580519483611,"mc":[{"id":"1.168135749","rc":[{"batb":[[0,11,85]],"ltp":11.5,"tv":20.15,"id":8204665},{"batb":[[0,11,107.88]],"batl":[[1,12.5,98]],"ltp":11.0,"tv":133.89,"id":8204663},{"batb":[[1,3.65,125],[2,3.6,211.33]],"batl":[[1,3.9,100]],"ltp":3.75,"tv":352.83,"id":1042125},{"batb":[[0,7.2,40.91]],"ltp":7.2,"tv":61.58,"id":1042126}]}]}
{"op":"mcm","clk":"992320167","pt":1580519513739,"mc":[{"id":"1.168135749","rc":[{"batb":[[0,11,98.44]],"ltp":11.5,"tv":20.15,"id":8204665},{"batb":[[0,11,121.32]],"batl":[[1,12.5,108.08]],"ltp":11.0,"tv":133.89,"id":8204663},{"batb":[[1,3.7,16.8],[2,3.65,125]],"batl":[[1,3.9,117.64]],"ltp":3.75,"tv":352.83,"id":1042125},{"batb":[[0,7.2,58.55]],"ltp":7.2,"tv":61.58,"id":1042126}]}]}
{"op":"mcm","clk":"992326237","pt":1580519769450,"mc":[{"id":"1.168135749","rc":[{"batl":[[1,12.5,112.28]],"ltp":11.0,"tv":133.89,"id":8204663},{"batb":[[1,3.7,26.89]],"ltp":3.75,"tv":352.83,"id":1042125}]}]}
{"op":"mcm","clk":"992326374","pt":1580519775852,"mc":[{"id":"1.168135749","rc":[{"batb":[[0,11,101.8]],"ltp":11.5,"tv":20.15,"id":8204665}]}]}
{"op":"mcm","clk":"992326424","pt":1580519778069,"mc":[{"id":"1.168135749","rc":[{"batb":[[1,3.7,17.64]],"ltp":3.75,"tv":352.83,"id":1042125}]}]}
{"op":"mcm","clk":"992331690","pt":1580519989068,"mc":[{"id":"1.168135749","rc":[{"batl":[[0,2.62,0.88]],"ltp":2.62,"tv":214.38,"id":1042124}]}]}
{"op":"mcm","clk":"992331711","pt":1580519990255,"mc":[{"id":"1.168135749","rc":[{"batl":[[0,2.74,12.24]],"ltp":2.62,"tv":214.38,"id":1042124}]}]}
{"op":"mcm","clk":"992335170","pt":1580520132111,"mc":[{"id":"1.168135749","rc":[{"batl":[[0,3.85,10.67]],"ltp":3.75,"tv":352.83,"id":1042125}]}]}
{"op":"mcm","clk":"992347586","pt":1580520239368,"mc":[{"id":"1.168135749","rc":[{"batl":[[0,3.85,110.67],[1,3.9,17.64]],"ltp":3.75,"tv":352.83,"id":1042125}]}]}
{"op":"mcm","clk":"992354353","pt":1580520499357,"mc":[{"id":"1.168135749","rc":[{"batl":[[0,2.62,0.88]],"ltp":2.62,"tv":214.38,"id":1042124}]}]}
{"op":"mcm","clk":"992354397","pt":1580520500860,"mc":[{"id":"1.168135749","rc":[{"batl":[[0,2.72,11.1]],"ltp":2.62,"tv":214.38,"id":1042124}]}]}
{"op":"mcm","clk":"992356072","pt":1580520554652,"mc":[{"id":"1.168135749","rc":[{"batl":[[0,2.62,0.88]],"ltp":2.62,"tv":214.38,"id":1042124}]}]}
{"op":"mcm","clk":"992356150","pt":1580520556459,"mc":[{"id":"1.168135749","rc":[{"batl":[[0,2.74,12.24]],"ltp":2.62,"tv":214.38,"id":1042124}]}]}
{"op":"mcm","clk":"992521736","pt":1580524756740,"mc":[{"id":"1.168135749","rc":[{"batl":[[2,13,0]],"ltp":11.0,"tv":133.89,"id":8204663}]}]}
{"op":"mcm","clk":"992521796","pt":1580524758436,"mc":[{"id":"1.168135749","rc":[{"batl":[[1,12.5,116.14]],"ltp":11.0,"tv":133.89,"id":8204663}]}]}
{"op":"mcm","clk":"992611892","pt":1580526822697,"mc":[{"id":"1.168135749","rc":[{"batb":[[0,17,50.41],[1,16.5,38],[2,16,23]],"ltp":19.5,"tv":108.16,"id":8204664},{"batl":[[0,2.62,0.88]],"ltp":2.62,"tv":214.38,"id":1042124},{"batb":[[0,7.2,50.64]],"ltp":7.2,"tv":61.58,"id":1042126}]}]}
{"op":"mcm","clk":"992611933","pt":1580526824093,"mc":[{"id":"1.168135749","rc":[{"batb":[[0,17,52.41]],"ltp":19.5,"tv":108.16,"id":8204664},{"batl":[[0,2.78,12.41]],"ltp":2.62,"tv":214.38,"id":1042124},{"batb":[[1,7,122.7]],"ltp":7.2,"tv":61.58,"id":1042126}]}]}
{"op":"mcm","clk":"992655772","pt":1580527900529,"mc":[{"id":"1.168135749","rc":[{"batl":[[0,3.85,10.67]],"ltp":3.75,"tv":352.83,"id":1042125}]}]}
{"op":"mcm","clk":"992655811","pt":1580527902334,"mc":[{"id":"1.168135749","rc":[{"batl":[[0,3.85,2.27]],"ltp":3.75,"tv":352.83,"id":1042125}]}]}
{"op":"mcm","clk":"992659643","pt":1580528051751,"mc":[{"id":"1.168135749","rc":[{"batl":[[1,3.95,11.66],[2,4.2,73.94]],"ltp":3.75,"tv":352.83,"id":1042125}]}]}
{"op":"mcm","clk":"992661720","pt":1580528143668,"mc":[{"id":"1.168135749","rc":[{"batl":[[0,2.78,593.16]],"ltp":2.62,"tv":214.38,"id":1042124}]}]}
{"op":"mcm","clk":"992661742","pt":1580528144548,"mc":[{"id":"1.168135749","rc":[{"batl":[[0,2.76,9.28],[1,2.78,592.28]],"ltp":2.62,"tv":214.38,"id":1042124}]}]}
{"op":"mcm","clk":"992661823","pt":1580528147754,"mc":[{"id":"1.168135749","rc":[{"batl":[[0,2.76,21.95],[1,2.78,11.53]],"ltp":2.62,"tv":214.38,"id":1042124}]}]}
{"op":"mcm","clk":"992661845","pt":1580528148690,"mc":[{"id":"1.168135749","rc":[{"batl":[[0,2.76,13.55]],"ltp":2.62,"tv":214.38,"id":1042124}]}]}
{"op":"mcm","clk":"992693971","pt":1580528807768,"mc":[{"id":"1.168135749","rc":[{"batb":[[0,17.5,1.25],[1,17,52.41],[2,16.5,38]],"ltp":19.5,"tv":108.16,"id":8204664},{"trd":[[11.5,23.96]],"batl":[[0,12,2.63],[1,12.5,4.11],[2,14.5,31.93]],"ltp":11.5,"tv":23.95,"id":8204665},{"batb":[[0,11,123.31]],"ltp":11.0,"tv":133.89,"id":8204663},{"batb":[[0,3.8,5.75],[1,3.75,11.09],[2,3.7,17.64]],"ltp":3.75,"tv":352.83,"id":1042125},{"trd":[[2.62,42.14]],"batb":[[0,2.62,7.45],[1,2.6,299.05],[2,2.56,181]],"batl":[[0,2.76,12.66]],"ltp":2.62,"tv":216.14,"id":1042124},{"batb":[[0,7.4,2.95],[1,7.2,50.64],[2,7,122.7]],"ltp":7.2,"tv":61.58,"id":1042126}],"tv":896.58}]}
{"op":"mcm","clk":"992694123","pt":1580528809584,"mc":[{"id":"1.168135749","rc":[{"batb":[[1,2.6,283.58]],"ltp":2.62,"tv":216.14,"id":1042124}]}]}
{"op":"mcm","clk":"992694232","pt":1580528811392,"mc":[{"id":"1.168135749","rc":[{"batl":[[0,12,2.53]],"ltp":11.5,"tv":23.95,"id":8204665},{"batb":[[0,2.62,28.16]],"ltp":2.62,"tv":216.14,"id":1042124}]}]}
{"op":"mcm","clk":"992694325","pt":1580528812679,"mc":[{"id":"1.168135749","rc":[{"batl":[[0,12,6.41]],"ltp":11.5,"tv":23.95,"id":8204665}]}]}
{"op":"mcm","clk":"992696534","pt":1580528859749,"mc":[{"id":"1.168135749","rc":[{"batl":[[0,2.74,582.75],[1,2.76,12.66],[2,2.78,11.53]],"ltp":2.62,"tv":216.14,"id":1042124}]}]}
{"op":"mcm","clk":"992696568","pt":1580528860516,"mc":[{"id":"1.168135749","rc":[{"batl":[[0,2.72,8.4],[1,2.74,582.75],[2,2.76,12.66]],"ltp":2.62,"tv":216.14,"id":1042124}]}]}
{"op":"mcm","clk":"992696925","pt":1580528870941,"mc":[{"id":"1.168135749","rc":[{"batl":[[2,4,42.85]],"ltp":3.75,"tv":352.83,"id":1042125}]}]}
{"op":"mcm","clk":"992701685","pt":1580528988093,"mc":[{"id":"1.168135749","rc":[{"batl":[[2,4.2,73.94]],"ltp":3.75,"tv":352.83,"id":1042125}]}]}
{"op":"mcm","clk":"992706813","pt":1580529105081,"mc":[{"id":"1.168135749","rc":[{"batl":[[2,4,40.33]],"ltp":3.75,"tv":352.83,"id":1042125}]}]}
{"op":"mcm","clk":"992720389","pt":1580529221738,"mc":[{"id":"1.168135749","rc":[{"batl":[[2,4.2,73.94]],"ltp":3.75,"tv":352.83,"id":1042125}]}]}
{"op":"mcm","clk":"992720547","pt":1580529227849,"mc":[{"id":"1.168135749","rc":[{"batl":[[1,2.76,12.66],[2,2.78,11.53]],"ltp":2.62,"tv":216.14,"id":1042124}]}]}
{"op":"mcm","clk":"992720600","pt":1580529229230,"mc":[{"id":"1.168135749","rc":[{"batl":[[0,2.76,12.66],[1,2.78,11.53],[2,2.78,0]],"ltp":2.62,"tv":216.14,"id":1042124}]}]}
{"op":"mcm","clk":"992723135","pt":1580529308126,"mc":[{"id":"1.168135749","rc":[{"batb":[[1,17,50.41]],"ltp":19.5,"tv":108.16,"id":8204664},{"batl":[[1,12.5,112.28]],"ltp":11.0,"tv":133.89,"id":8204663}]}]}
{"op":"mcm","clk":"992723170","pt":1580529309765,"mc":[{"id":"1.168135749","rc":[{"batl":[[2,13,9.09]],"ltp":11.0,"tv":133.89,"id":8204663},{"batb":[[0,2.62,7.45]],"batl":[[0,2.74,11.64],[1,2.76,12.66]],"ltp":2.62,"tv":216.14,"id":1042124},{"batb":[[2,7,109.14]],"ltp":7.2,"tv":61.58,"id":1042126}]}]}
{"op":"mcm","clk":"992723187","pt":1580529310644,"mc":[{"id":"1.168135749","rc":[{"batb":[[0,17.5,3.25]],"ltp":19.5,"tv":108.16,"id":8204664},{"batb":[[1,2.6,300.43]],"ltp":2.62,"tv":216.14,"id":1042124},{"batb":[[1,7.2,58.34]],"ltp":7.2,"tv":61.58,"id":1042126}]}]}
{"op":"mcm","clk":"992724050","pt":1580529338662,"mc":[{"id":"1.168135749","rc":[{"batl":[[2,4,42.01]],"ltp":3.75,"tv":352.83,"id":1042125}]}]}
{"op":"mcm","clk":"992727959","pt":1580529455646,"mc":[{"id":"1.168135749","rc":[{"batl":[[2,4.2,73.94]],"ltp":3.75,"tv":352.83,"id":1042125}]}]}
{"op":"mcm","clk":"992732255","pt":1580529572813,"mc":[{"id":"1.168135749","rc":[{"batl":[[2,4,41.17]],"ltp":3.75,"tv":352.83,"id":1042125}]}]}
{"op":"mcm","clk":"992737680","pt":1580529690506,"mc":[{"id":"1.168135749","rc":[{"batl":[[2,4.2,73.94]],"ltp":3.75,"tv":352.83,"id":1042125}]}]}
{"op":"mcm","clk":"992742690","pt":1580529807741,"mc":[{"id":"1.168135749","rc":[{"batl":[[2,4,42.01]],"ltp":3.75,"tv":352.83,"id":1042125}]}]}
{"op":"mcm","clk":"992745650","pt":1580529889989,"mc":[{"id":"1.168135749","rc":[{"batb":[[0,11,111.05]],"ltp":11.5,"tv":23.95,"id":8204665},{"batb":[[0,11,126.67]],"ltp":11.0,"tv":133.89,"id":8204663}]}]}
{"op":"mcm","clk":"992745891","pt":1580529897161,"mc":[{"id":"1.168135749","rc":[{"batb":[[0,11,134.23]],"batl":[[2,13,23.37]],"ltp":11.0,"tv":133.89,"id":8204663}]}]}
{"op":"mcm","clk":"992746102","pt":1580529903882,"mc":[{"id":"1.168135749","rc":[{"batl":[[2,15,31.93]],"ltp":11.5,"tv":23.95,"id":8204665},{"batl":[[1,12.5,98]],"ltp":11.0,"tv":133.89,"id":8204663},{"batb":[[2,3.65,151.89]],"batl":[[2,4.2,85.7]],"ltp":3.75,"tv":352.83,"id":1042125}]}]}
{"op":"mcm","clk":"992746571","pt":1580529915812,"mc":[{"id":"1.168135749","rc":[{"batl":[[2,4,49.57]],"ltp":3.75,"tv":352.83,"id":1042125}]}]}
{"op":"mcm","clk":"992747246","pt":1580529932840,"mc":[{"id":"1.168135749","rc":[{"batl":[[2,4.2,85.7]],"ltp":3.75,"tv":352.83,"id":1042125}]}]}
{"op":"mcm","clk":"992748109","pt":1580529954754,"mc":[{"id":"1.168135749","rc":[{"batl":[[2,4,52.09]],"ltp":3.75,"tv":352.83,"id":1042125}]}]}
{"op":"mcm","clk":"992749258","pt":1580529981724,"mc":[{"id":"1.168135749","rc":[{"batl":[[2,4.2,85.7]],"ltp":3.75,"tv":352.83,"id":1042125}]}]}
{"op":"mcm","clk":"992750399","pt":1580530018768,"mc":[{"id":"1.168135749","rc":[{"batl":[[2,4,49.57]],"ltp":3.75,"tv":352.83,"id":1042125}]}]}
{"op":"mcm","clk":"992761723","pt":1580530059931,"mc":[{"id":"1.168135749","rc":[{"batb":[[0,2.64,4.15],[1,2.62,7.45],[2,2.6,300.43]],"ltp":2.62,"tv":216.14,"id":1042124}]}]}
{"op":"mcm","clk":"992761872","pt":1580530064547,"mc":[{"id":"1.168135749","rc":[{"batb":[[1,2.6,300.43],[2,2.56,181]],"ltp":2.62,"tv":216.14,"id":1042124}]}]}
{"op":"mcm","clk":"992761939","pt":1580530066046,"mc":[{"id":"1.168135749","rc":[{"batl":[[2,4.2,85.7]],"ltp":3.75,"tv":352.83,"id":1042125}]}]}
{"op":"mcm","clk":"992762892","pt":1580530083905,"mc":[{"id":"1.168135749","rc":[{"batb":[[0,2.66,7.34],[1,2.64,4.15],[2,2.6,300.43]],"ltp":2.62,"tv":216.14,"id":1042124}]}]}
{"op":"mcm","clk":"992765683","pt":1580530122735,"mc":[{"id":"1.168135749","rc":[{"batl":[[2,4,49.57]],"ltp":3.75,"tv":352.83,"id":1042125}]}]}
{"op":"mcm","clk":"992769614","pt":1580530192228,"mc":[{"id":"1.168135749","rc":[{"batl":[[2,15,40.33]],"ltp":11.5,"tv":23.95,"id":8204665},{"batl":[[2,13,26.73]],"ltp":11.0,"tv":133.89,"id":8204663}]}]}
{"op":"mcm","clk":"992770661","pt":1580530211107,"mc":[{"id":"1.168135749","rc":[{"batl":[[2,4.2,85.7]],"ltp":3.75,"tv":352.83,"id":1042125}]}]}
{"op":"mcm","clk":"992771644","pt":1580530227821,"mc":[{"id":"1.168135749","rc":[{"batl":[[2,4,51.25]],"ltp":3.75,"tv":352.83,"id":1042125}]}]}
{"op":"mcm","clk":"992772658","pt":1580530249762,"mc":[{"id":"1.168135749","rc":[{"batl":[[2,4.2,85.7]],"ltp":3.75,"tv":352.83,"id":1042125}]}]}
{"op":"mcm","clk":"992773078","pt":1580530263334,"mc":[{"id":"1.168135749","rc":[{"batl":[[0,3.85,2.69]],"ltp":3.75,"tv":352.83,"id":1042125}]}]}
{"op":"mcm","clk":"992773196","pt":1580530266811,"mc":[{"id":"1.168135749","rc":[{"trd":[[3.8,0.84]],"batb":[[0,3.8,5.33]],"batl":[[0,3.85,2.27]],"ltp":3.8,"tv":353.67,"id":1042125}],"tv":897.42}]}
{"op":"mcm","clk":"992773553","pt":1580530276845,"mc":[{"id":"1.168135749","rc":[{"batl":[[2,4,51.25]],"ltp":3.8,"tv":353.67,"id":1042125}]}]}
{"op":"mcm","clk":"992775367","pt":1580530313702,"mc":[{"id":"1.168135749","rc":[{"batl":[[2,4.2,85.7]],"ltp":3.8,"tv":353.67,"id":1042125}]}]}
{"op":"mcm","clk":"992777433","pt":1580530360798,"mc":[{"id":"1.168135749","rc":[{"batl":[[2,4,48.73]],"ltp":3.8,"tv":353.67,"id":1042125},{"trd":[[7.4,5.9]],"batb":[[0,7.2,58.34],[1,7,109.14],[2,6,2]],"batl":[[0,7.4,5.92],[1,7.6,2],[2,8,2.53]],"ltp":7.4,"tv":67.47,"id":1042126}],"tv":903.32}]}
{"op":"mcm","clk":"992778605","pt":1580530376728,"mc":[{"id":"1.168135749","rc":[{"trd":[[3.8,11.49]],"batb":[[0,3.75,11.09],[1,3.65,151.89],[2,3.6,211.33]],"batl":[[0,3.8,7.97],[1,3.85,2.27],[2,3.95,11.66]],"ltp":3.8,"tv":364.32,"id":1042125}],"tv":913.97}]}
{"op":"mcm","clk":"992779394","pt":1580530389838,"mc":[{"id":"1.168135749","rc":[{"trd":[[2.66,14.68]],"batb":[[0,2.64,4.15],[1,2.6,300.43],[2,2.56,181]],"batl":[[0,2.66,5.96],[1,2.74,11.64],[2,2.76,12.66]],"ltp":2.66,"tv":230.82,"id":1042124}],"tv":928.64}]}
{"op":"mcm","clk":"992780295","pt":1580530405770,"mc":[{"id":"1.168135749","rc":[{"batb":[[0,11,113.19]],"ltp":11.5,"tv":23.95,"id":8204665},{"batb":[[0,3.75,17.37]],"ltp":3.8,"tv":364.32,"id":1042125},{"batb":[[0,2.64,13.07]],"ltp":2.66,"tv":230.82,"id":1042124},{"batb":[[0,7.2,61.61]],"ltp":7.4,"tv":67.47,"id":1042126}]}]}
{"op":"mcm","clk":"992780339","pt":1580530406543,"mc":[{"id":"1.168135749","rc":[{"trd":[[11,10.14]],"batb":[[0,11,108.12]],"ltp":11.0,"tv":34.09,"id":8204665}],"tv":938.78}]}
{"op":"mcm","clk":"992780933","pt":1580530416100,"mc":[{"id":"1.168135749","rc":[{"trd":[[12,12.83]],"batb":[[0,12,3.66],[1,11,108.12],[2,10.5,5.24]],"batl":[[0,12.5,4.11],[1,15,40.33],[2,15,0]],"ltp":12.0,"tv":46.92,"id":8204665},{"batl":[[2,3.9,40.33]],"ltp":3.8,"tv":364.32,"id":1042125}],"tv":951.61}]}
{"op":"mcm","clk":"992781082","pt":1580530419668,"mc":[{"id":"1.168135749","rc":[{"batb":[[0,11,82.07],[1,9.8,76.53],[2,1.02,2]],"batl":[[1,15,0]],"ltp":12.0,"tv":46.92,"id":8204665},{"batb":[[0,11,109.86]],"batl":[[2,13,9.09]],"ltp":11.0,"tv":133.89,"id":8204663},{"batb":[[1,3.65,125]],"batl":[[2,3.95,11.66]],"ltp":3.8,"tv":364.32,"id":1042125},{"batb":[[0,7.2,43.97]],"ltp":7.4,"tv":67.47,"id":1042126}]}]}
{"op":"mcm","clk":"992781135","pt":1580530420796,"mc":[{"id":"1.168135749","rc":[{"batb":[[0,11,94.12]],"batl":[[0,12,2],[1,12.5,4.11]],"ltp":12.0,"tv":46.92,"id":8204665},{"batb":[[0,11,117.42]],"ltp":11.0,"tv":133.89,"id":8204663}]}]}
{"op":"mcm","clk":"992781168","pt":1580530421570,"mc":[{"id":"1.168135749","rc":[{"batb":[[0,11,91.98]],"ltp":12.0,"tv":46.92,"id":8204665}]}]}
{"op":"mcm","clk":"992781220","pt":1580530422661,"mc":[{"id":"1.168135749","rc":[{"batb":[[0,11,117.19]],"batl":[[2,15,49.57]],"ltp":12.0,"tv":46.92,"id":8204665},{"batb":[[0,11,145.15]],"batl":[[2,13,26.73]],"ltp":11.0,"tv":133.89,"id":8204663},{"batb":[[1,3.65,160.29]],"batl":[[2,3.9,50.41]],"ltp":3.8,"tv":364.32,"id":1042125},{"batb":[[0,7.2,60.77]],"ltp":7.4,"tv":67.47,"id":1042126}]}]}
{"op":"mcm","clk":"992781268","pt":1580530423390,"mc":[{"id":"1.168135749","rc":[{"batb":[[0,11,125.59]],"ltp":12.0,"tv":46.92,"id":8204665},{"batb":[[0,7.2,69.17]],"ltp":7.4,"tv":67.47,"id":1042126}]}]}
{"op":"mcm","clk":"992781341","pt":1580530424785,"mc":[{"id":"1.168135749","rc":[{"trd":[[12,16.83]],"batb":[[0,12,11.44],[1,11,125.59],[2,9.8,76.53]],"batl":[[0,12.5,4.11],[1,15,49.57],[2,15.5,50.41]],"ltp":12.0,"tv":50.92,"id":8204665},{"batb":[[0,11,153.55]],"ltp":11.0,"tv":133.89,"id":8204663},{"batb":[[0,7.2,61.47]],"ltp":7.4,"tv":67.47,"id":1042126}],"tv":955.61}]}
{"op":"mcm","clk":"992781404","pt":1580530425563,"mc":[{"id":"1.168135749","rc":[{"batl":[[1,2.76,12.66],[2,2.76,0]],"ltp":2.66,"tv":230.82,"id":1042124}]}]}
{"op":"mcm","clk":"992781484","pt":1580530426764,"mc":[{"id":"1.168135749","rc":[{"batb":[[0,7.2,70.15]],"ltp":7.4,"tv":67.47,"id":1042126}]}]}
{"op":"mcm","clk":"992781560","pt":1580530428471,"mc":[{"id":"1.168135749","rc":[{"batl":[[1,2.72,9.25],[2,2.76,12.66]],"ltp":2.66,"tv":230.82,"id":1042124},{"batb":[[0,7.2,61.47]],"ltp":7.4,"tv":67.47,"id":1042126}]}]}
{"op":"mcm","clk":"992781601","pt":1580530429600,"mc":[{"id":"1.168135749","rc":[{"trd":[[12,20.83]],"batb":[[0,12,9.44]],"ltp":12.0,"tv":54.92,"id":8204665},{"batb":[[0,7.2,69.98]],"ltp":7.4,"tv":67.47,"id":1042126}],"tv":959.61}]}
{"op":"mcm","clk":"992781762","pt":1580530432900,"mc":[{"id":"1.168135749","rc":[{"batb":[[1,2.6,283.58]],"ltp":2.66,"tv":230.82,"id":1042124}]}]}
{"op":"mcm","clk":"992781838","pt":1580530434766,"mc":[{"id":"1.168135749","rc":[{"batb":[[2,2.58,17.53]],"ltp":2.66,"tv":230.82,"id":1042124}]}]}
{"op":"mcm","clk":"992781869","pt":1580530435690,"mc":[{"id":"1.168135749","rc":[{"batb":[[0,11,117.19],[1,9.8,76.53],[2,1.02,2]],"batl":[[2,15.5,0]],"ltp":12.0,"tv":54.92,"id":8204665},{"batb":[[0,11,141.79]],"ltp":11.0,"tv":133.89,"id":8204663},{"batl":[[2,3.95,11.66]],"ltp":3.8,"tv":364.32,"id":1042125}]}]}
{"op":"mcm","clk":"992781906","pt":1580530436716,"mc":[{"id":"1.168135749","rc":[{"batb":[[2,2.56,181]],"ltp":2.66,"tv":230.82,"id":1042124}]}]}
{"op":"mcm","clk":"992781931","pt":1580530437285,"mc":[{"id":"1.168135749","rc":[{"batb":[[0,7.2,61.47]],"ltp":7.4,"tv":67.47,"id":1042126}]}]}
{"op":"mcm","clk":"992781973","pt":1580530438420,"mc":[{"id":"1.168135749","rc":[{"batb":[[1,2.6,298.96]],"ltp":2.66,"tv":230.82,"id":1042124},{"batb":[[1,7,123.87]],"ltp":7.4,"tv":67.47,"id":1042126}]}]}
{"op":"mcm","clk":"992782103","pt":1580530441725,"mc":[{"id":"1.168135749","rc":[{"batb":[[0,11,119.33]],"ltp":12.0,"tv":54.92,"id":8204665}]}]}
{"op":"mcm","clk":"992782149","pt":1580530442705,"mc":[{"id":"1.168135749","rc":[{"batl":[[2,3.9,41.17]],"ltp":3.8,"tv":364.32,"id":1042125}]}]}
{"op":"mcm","clk":"992782265","pt":1580530445390,"mc":[{"id":"1.168135749","rc":[{"batb":[[1,2.6,283.58]],"ltp":2.66,"tv":230.82,"id":1042124},{"batb":[[1,7,109.14]],"ltp":7.4,"tv":67.47,"id":1042126}]}]}
{"op":"mcm","clk":"992782330","pt":1580530446321,"mc":[{"id":"1.168135749","rc":[{"batb":[[2,2.58,17.53]],"ltp":2.66,"tv":230.82,"id":1042124},{"batb":[[0,7.2,69.81]],"ltp":7.4,"tv":67.47,"id":1042126}]}]}
{"op":"mcm","clk":"992782683","pt":1580530454742,"mc":[{"id":"1.168135749","rc":[{"batl":[[2,3.95,11.66]],"ltp":3.8,"tv":364.32,"id":1042125}]}]}
{"op":"mcm","clk":"992783358","pt":1580530471656,"mc":[{"id":"1.168135749","rc":[{"batl":[[2,3.9,41.17]],"ltp":3.8,"tv":364.32,"id":1042125}]}]}
{"op":"mcm","clk":"992783638","pt":1580530478365,"mc":[{"id":"1.168135749","rc":[{"trd":[[3.75,126.13]],"batb":[[0,3.75,9.39]],"batl":[[0,3.85,2.27],[1,3.9,41.17],[2,3.95,11.66]],"ltp":3.75,"tv":380.28,"id":1042125}],"tv":975.56}]}
{"op":"mcm","clk":"992783776","pt":1580530481762,"mc":[{"id":"1.168135749","rc":[{"batl":[[2,4.2,126.03]],"ltp":3.75,"tv":380.28,"id":1042125}]}]}
{"op":"mcm","clk":"992783804","pt":1580530482641,"mc":[{"id":"1.168135749","rc":[{"batb":[[0,3.75,6.28]],"batl":[[1,3.9,51.5]],"ltp":3.75,"tv":380.28,"id":1042125},{"batb":[[2,2.56,181]],"ltp":2.66,"tv":230.82,"id":1042124}]}]}
{"op":"mcm","clk":"992783898","pt":1580530484446,"mc":[{"id":"1.168135749","rc":[{"batb":[[1,3.7,8.53],[2,3.65,160.29]],"ltp":3.75,"tv":380.28,"id":1042125},{"batb":[[1,2.6,299.59]],"batl":[[1,2.76,12.66],[2,2.76,0]],"ltp":2.66,"tv":230.82,"id":1042124}]}]}
{"op":"mcm","clk":"992783929","pt":1580530485267,"mc":[{"id":"1.168135749","rc":[{"batl":[[1,14.5,51.25],[2,15,49.57]],"ltp":12.0,"tv":54.92,"id":8204665},{"batl":[[2,13,35.14]],"ltp":11.0,"tv":133.89,"id":8204663},{"batb":[[2,3.65,165.33]],"ltp":3.75,"tv":380.28,"id":1042125}]}]}
{"op":"mcm","clk":"992783977","pt":1580530486360,"mc":[{"id":"1.168135749","rc":[{"batl":[[1,2.74,12.32],[2,2.76,12.66]],"ltp":2.66,"tv":230.82,"id":1042124}]}]}
{"op":"mcm","clk":"992784130","pt":1580530491570,"mc":[{"id":"1.168135749","rc":[{"trd":[[2.64,65.69]],"batb":[[0,2.64,7.11]],"batl":[[0,2.74,12.32],[1,2.76,12.66],[2,2.76,0]],"ltp":2.64,"tv":242.74,"id":1042124}],"tv":987.48}]}
{"op":"mcm","clk":"992784180","pt":1580530492868,"mc":[{"id":"1.168135749","rc":[{"batl":[[2,15,0]],"ltp":12.0,"tv":54.92,"id":8204665},{"batl":[[1,3.9,10.33]],"ltp":3.75,"tv":380.28,"id":1042125}]}]}
{"op":"mcm","clk":"992784544","pt":1580530501489,"mc":[{"id":"1.168135749","rc":[{"trd":[[7.2,65.84]],"batb":[[0,7.2,63.89]],"batl":[[0,7.6,2],[1,8,2.53],[2,8.6,1.68]],"ltp":7.2,"tv":79.31,"id":1042126}],"tv":999.32}]}
{"op":"mcm","clk":"992823022","pt":1580531193101,"mc":[{"id":"1.168135749","rc":[{"batb":[[0,7.2,55.55]],"ltp":7.2,"tv":79.31,"id":1042126}]}]}
{"op":"mcm","clk":"992823068","pt":1580531194492,"mc":[{"id":"1.168135749","rc":[{"batb":[[1,7,124.23]],"ltp":7.2,"tv":79.31,"id":1042126}]}]}
{"op":"mcm","clk":"992827183","pt":1580531304413,"mc":[{"id":"1.168135749","rc":[{"trd":[[11,105.38]],"batb":[[0,11,139.79]],"ltp":11.0,"tv":137.89,"id":8204663}],"tv":1003.32}]}
{"op":"mcm","clk":"992828790","pt":1580531357573,"mc":[{"id":"1.168135749","rc":[{"trd":[[11,14.14]],"batb":[[0,11,117.33]],"ltp":11.0,"tv":58.92,"id":8204665}],"tv":1007.32}]}
{"op":"mcm","clk":"992862141","pt":1580531989638,"mc":[{"id":"1.168135749","rc":[{"batl":[[0,2.74,595.07]],"ltp":2.64,"tv":242.74,"id":1042124}]}]}
{"op":"mcm","clk":"992862170","pt":1580531990261,"mc":[{"id":"1.168135749","rc":[{"batl":[[0,2.72,8.4],[1,2.74,595.07],[2,2.76,12.66]],"ltp":2.64,"tv":242.74,"id":1042124}]}]}
{"op":"mcm","clk":"992879254","pt":1580532447372,"mc":[{"id":"1.168135749","rc":[{"batb":[[0,17.5,41.25],[2,16,23]],"ltp":19.5,"tv":108.16,"id":8204664}]}]}
{"op":"mcm","clk":"992888545","pt":1580532670417,"mc":[{"id":"1.168135749","rc":[{"batb":[[0,11,85.4]],"batl":[[1,14.5,0]],"ltp":11.0,"tv":58.92,"id":8204665},{"batb":[[0,11,107.86]],"batl":[[2,13,9.09]],"ltp":11.0,"tv":137.89,"id":8204663},{"batb":[[2,3.65,125]],"batl":[[2,4.4,10.64]],"ltp":3.75,"tv":380.28,"id":1042125},{"batb":[[0,7.2,30.35]],"ltp":7.2,"tv":79.31,"id":1042126}]}]}
{"op":"mcm","clk":"992889827","pt":1580532700747,"mc":[{"id":"1.168135749","rc":[{"batb":[[0,11.5,17.64],[1,11,85.4],[2,9.8,76.53]],"batl":[[1,14.5,48.73]],"ltp":11.0,"tv":58.92,"id":8204665},{"batb":[[0,11.5,14.28],[1,11,107.86],[2,1.02,2]],"batl":[[1,12.5,111.44]],"ltp":11.0,"tv":137.89,"id":8204663},{"batb":[[2,3.65,167.01]],"batl":[[2,4.1,84.86]],"ltp":3.75,"tv":380.28,"id":1042125},{"batb":[[0,7.2,54.71]],"ltp":7.2,"tv":79.31,"id":1042126}]}]}
{"op":"mcm","clk":"992889904","pt":1580532702877,"mc":[{"id":"1.168135749","rc":[{"batb":[[1,11,104.47]],"ltp":11.0,"tv":137.89,"id":8204663}]}]}
{"op":"mcm","clk":"992889984","pt":1580532704756,"mc":[{"id":"1.168135749","rc":[{"trd":[[12,4]],"batl":[[0,12,7.63]],"ltp":12.0,"tv":141.89,"id":8204663}],"tv":1011.32}]}
{"op":"mcm","clk":"992889997","pt":1580532705170,"mc":[{"id":"1.168135749","rc":[{"batb":[[1,11,83.26]],"ltp":11.0,"tv":58.92,"id":8204665}]}]}
{"op":"mcm","clk":"992890100","pt":1580532707561,"mc":[{"id":"1.168135749","rc":[{"batl":[[2,13,0]],"ltp":12.0,"tv":141.89,"id":8204663}]}]}
{"op":"mcm","clk":"992890136","pt":1580532708489,"mc":[{"id":"1.168135749","rc":[{"trd":[[12,7.99]],"batl":[[0,12,5.63]],"ltp":12.0,"tv":145.89,"id":8204663}],"tv":1015.31}]}
{"op":"mcm","clk":"992890162","pt":1580532709359,"mc":[{"id":"1.168135749","rc":[{"batl":[[1,12.5,115.39]],"ltp":12.0,"tv":145.89,"id":8204663}]}]}
{"op":"mcm","clk":"992890227","pt":1580532711285,"mc":[{"id":"1.168135749","rc":[{"batl":[[1,4.1,84.86],[2,4.4,10.64]],"ltp":3.75,"tv":380.28,"id":1042125}]}]}
{"op":"mcm","clk":"992890279","pt":1580532712683,"mc":[{"id":"1.168135749","rc":[{"batb":[[0,11.5,16.44]],"ltp":12.0,"tv":145.89,"id":8204663},{"batl":[[1,3.95,15.53],[2,4.1,84.86]],"ltp":3.75,"tv":380.28,"id":1042125}]}]}
{"op":"mcm","clk":"992890768","pt":1580532725620,"mc":[{"id":"1.168135749","rc":[{"batb":[[0,11.5,18.06]],"ltp":11.0,"tv":58.92,"id":8204665},{"batb":[[0,11.5,16.86]],"ltp":12.0,"tv":145.89,"id":8204663}]}]}
{"op":"mcm","clk":"992891433","pt":1580532740738,"mc":[{"id":"1.168135749","rc":[{"batl":[[1,3.9,42.85],[2,3.95,15.53]],"ltp":3.75,"tv":380.28,"id":1042125}]}]}
{"op":"mcm","clk":"992907402","pt":1580532903356,"mc":[{"id":"1.168135749","rc":[{"batb":[[1,7,109.14]],"ltp":7.2,"tv":79.31,"id":1042126}]}]}
{"op":"mcm","clk":"992907512","pt":1580532905754,"mc":[{"id":"1.168135749","rc":[{"batb":[[0,7.2,62.37]],"ltp":7.2,"tv":79.31,"id":1042126}]}]}
{"op":"mcm","clk":"992912777","pt":1580533027548,"mc":[{"id":"1.168135749","rc":[{"batb":[[1,2.6,282.61]],"batl":[[1,2.74,12.32]],"ltp":2.64,"tv":242.74,"id":1042124}]}]}
{"op":"mcm","clk":"992912855","pt":1580533028951,"mc":[{"id":"1.168135749","rc":[{"batl":[[0,2.74,12.32],[1,2.76,12.66],[2,2.76,0]],"ltp":2.64,"tv":242.74,"id":1042124}]}]}
{"op":"mcm","clk":"992930314","pt":1580533429054,"mc":[{"id":"1.168135749","rc":[{"trd":[[7.2,81.04]],"batb":[[0,7.2,54.76]],"ltp":7.2,"tv":94.52,"id":1042126}],"tv":1030.52}]}
{"op":"mcm","clk":"992954104","pt":1580533741329,"mc":[{"id":"1.168135749","rc":[{"batb":[[0,11,83.67],[1,9.8,76.53],[2,1.02,2]],"batl":[[1,14.5,0]],"ltp":11.0,"tv":58.92,"id":8204665},{"batb":[[0,11.5,2.58]],"batl":[[1,12.5,101.95]],"ltp":12.0,"tv":145.89,"id":8204663},{"batb":[[2,3.65,125]],"batl":[[1,3.95,15.53],[2,4.4,10.64]],"ltp":3.75,"tv":380.28,"id":1042125},{"batb":[[0,7.2,30.4]],"ltp":7.2,"tv":94.52,"id":1042126}]}]}
{"op":"mcm","clk":"992955402","pt":1580533771772,"mc":[{"id":"1.168135749","rc":[{"batb":[[0,11.5,14.7],[1,11,83.26],[2,9.8,76.53]],"batl":[[1,14.5,50.41]],"ltp":11.0,"tv":58.92,"id":8204665},{"batb":[[1,11,131.36]],"batl":[[1,12.5,116.23]],"ltp":12.0,"tv":145.89,"id":8204663},{"batb":[[1,3.7,35.42]],"batl":[[1,3.9,31.93],[2,3.95,15.53]],"ltp":3.75,"tv":380.28,"id":1042125},{"batb":[[0,7.2,53.92]],"ltp":7.2,"tv":94.52,"id":1042126}]}]}
{"op":"mcm","clk":"993051441","pt":1580535589652,"mc":[{"id":"1.168135749","rc":[{"batl":[[0,2.74,595.07]],"ltp":2.64,"tv":242.74,"id":1042124}]}]}
{"op":"mcm","clk":"993051498","pt":1580535590734,"mc":[{"id":"1.168135749","rc":[{"batl":[[0,2.72,8.4],[1,2.74,595.07],[2,2.76,12.66]],"ltp":2.64,"tv":242.74,"id":1042124}]}]}
{"op":"mcm","clk":"993077667","pt":1580536152785,"mc":[{"id":"1.168135749","rc":[{"batl":[[0,12.5,204.11]],"ltp":11.0,"tv":58.92,"id":8204665},{"batb":[[1,3.7,146.42]],"ltp":3.75,"tv":380.28,"id":1042125},{"batb":[[0,2.64,773.11]],"ltp":2.64,"tv":242.74,"id":1042124},{"batb":[[0,7.4,177],[1,7.2,53.92],[2,7,109.14]],"ltp":7.2,"tv":94.52,"id":1042126}]}]}
{"op":"mcm","clk":"993077679","pt":1580536152991,"mc":[{"id":"1.168135749","rc":[{"batl":[[1,2.74,12.32]],"ltp":2.64,"tv":242.74,"id":1042124}]}]}
{"op":"mcm","clk":"993077728","pt":1580536153921,"mc":[{"id":"1.168135749","rc":[{"batl":[[0,2.74,12.32],[1,2.76,12.66],[2,2.76,0]],"ltp":2.64,"tv":242.74,"id":1042124}]}]}
{"op":"mcm","clk":"993077799","pt":1580536155996,"mc":[{"id":"1.168135749","rc":[{"batb":[[1,7.2,50.66]],"ltp":7.2,"tv":94.52,"id":1042126}]}]}
{"op":"mcm","clk":"993078530","pt":1580536176531,"mc":[{"id":"1.168135749","rc":[{"batb":[[0,7.4,177.65]],"ltp":7.2,"tv":94.52,"id":1042126}]}]}
{"op":"mcm","clk":"993081066","pt":1580536245015,"mc":[{"id":"1.168135749","rc":[{"batl":[[0,12.5,217.55]],"ltp":11.0,"tv":58.92,"id":8204665}]}]}
{"op":"mcm","clk":"993095112","pt":1580536354838,"mc":[{"id":"1.168135749","rc":[{"batl":[[1,14.5,0]],"ltp":11.0,"tv":58.92,"id":8204665}]}]}
{"op":"mcm","clk":"993215835","pt":1580538703226,"mc":[{"id":"1.168135749","rc":[{"batl":[[1,8,227.42]],"ltp":7.2,"tv":94.52,"id":1042126}]}]}
{"op":"mcm","clk":"993215863","pt":1580538704049,"mc":[{"id":"1.168135749","rc":[{"batl":[[1,7.8,8.4],[2,8,227.42]],"ltp":7.2,"tv":94.52,"id":1042126}]}]}
{"op":"mcm","clk":"993218663","pt":1580538776917,"mc":[{"id":"1.168135749","rc":[{"batl":[[2,8,252.63]],"ltp":7.2,"tv":94.52,"id":1042126}]}]}
{"op":"mcm","clk":"993241576","pt":1580539103569,"mc":[{"id":"1.168135749","rc":[{"batb":[[1,11,77.93]],"ltp":11.0,"tv":58.92,"id":8204665}]}]}
{"op":"mcm","clk":"993241611","pt":1580539104445,"mc":[{"id":"1.168135749","rc":[{"batb":[[1,3.7,137.89]],"ltp":3.75,"tv":380.28,"id":1042125},{"batb":[[1,2.6,266.6]],"batl":[[0,2.74,595.07]],"ltp":2.64,"tv":242.74,"id":1042124}]}]}
{"op":"mcm","clk":"993241676","pt":1580539105687,"mc":[{"id":"1.168135749","rc":[{"batl":[[0,2.72,8.4],[1,2.74,582.75],[2,2.76,12.66]],"ltp":2.64,"tv":242.74,"id":1042124}]}]}
{"op":"mcm","clk":"993241740","pt":1580539106777,"mc":[{"id":"1.168135749","rc":[{"batb":[[0,17.5,39.25]],"ltp":19.5,"tv":108.16,"id":8204664},{"batb":[[1,11,83.39]],"ltp":11.0,"tv":58.92,"id":8204665},{"batb":[[0,3.75,12.01]],"ltp":3.75,"tv":380.28,"id":1042125},{"batb":[[0,2.64,788.62]],"batl":[[1,2.76,12.66],[2,2.76,0]],"ltp":2.64,"tv":242.74,"id":1042124},{"batb":[[1,7.2,43]],"ltp":7.2,"tv":94.52,"id":1042126}]}]}
{"op":"mcm","clk":"993241768","pt":1580539107347,"mc":[{"id":"1.168135749","rc":[{"batl":[[1,12.5,118.75]],"ltp":12.0,"tv":145.89,"id":8204663},{"batl":[[0,2.76,12.66],[1,2.78,11.88]],"ltp":2.64,"tv":242.74,"id":1042124}]}]}
{"op":"mcm","clk":"993241802","pt":1580539108342,"mc":[{"id":"1.168135749","rc":[{"batb":[[1,17,52.41]],"ltp":19.5,"tv":108.16,"id":8204664},{"batb":[[2,7,122.46]],"ltp":7.2,"tv":94.52,"id":1042126}]}]}
{"op":"mcm","clk":"993259053","pt":1580539511766,"mc":[{"id":"1.168135749","rc":[{"batb":[[1,17,50.41]],"ltp":19.5,"tv":108.16,"id":8204664}]}]}
{"op":"mcm","clk":"993259089","pt":1580539512587,"mc":[{"id":"1.168135749","rc":[{"batb":[[1,11,77.93]],"ltp":11.0,"tv":58.92,"id":8204665},{"batb":[[0,2.64,773.11]],"batl":[[1,2.78,0]],"ltp":2.64,"tv":242.74,"id":1042124}]}]}
{"op":"mcm","clk":"993259139","pt":1580539513668,"mc":[{"id":"1.168135749","rc":[{"batl":[[0,2.74,9.69],[1,2.76,12.66],[2,2.8,8.4]],"ltp":2.64,"tv":242.74,"id":1042124},{"batb":[[2,7,109.14]],"ltp":7.2,"tv":94.52,"id":1042126}]}]}
{"op":"mcm","clk":"993259171","pt":1580539514393,"mc":[{"id":"1.168135749","rc":[{"batb":[[0,17.5,41.25]],"ltp":19.5,"tv":108.16,"id":8204664},{"batb":[[2,10.5,18.55]],"ltp":11.0,"tv":58.92,"id":8204665},{"batb":[[1,2.62,14.62],[2,2.6,266.6]],"ltp":2.64,"tv":242.74,"id":1042124},{"batb":[[1,7.2,50.95]],"ltp":7.2,"tv":94.52,"id":1042126}]}]}
{"op":"mcm","clk":"993264338","pt":1580539617809,"mc":[{"id":"1.168135749","rc":[{"batb":[[0,17.5,39.25]],"ltp":19.5,"tv":108.16,"id":8204664},{"batl":[[0,2.76,12.66],[1,2.8,8.4],[2,2.8,0]],"ltp":2.64,"tv":242.74,"id":1042124}]}]}
{"op":"mcm","clk":"993264394","pt":1580539618740,"mc":[{"id":"1.168135749","rc":[{"batb":[[2,9.8,76.53]],"ltp":11.0,"tv":58.92,"id":8204665},{"batb":[[1,2.6,266.6],[2,2.56,181]],"ltp":2.64,"tv":242.74,"id":1042124},{"batb":[[1,7.2,43]],"ltp":7.2,"tv":94.52,"id":1042126}]}]}
{"op":"mcm","clk":"993264418","pt":1580539619204,"mc":[{"id":"1.168135749","rc":[{"batl":[[1,2.78,11.88],[2,2.8,8.4]],"ltp":2.64,"tv":242.74,"id":1042124}]}]}
{"op":"mcm","clk":"993264471","pt":1580539620392,"mc":[{"id":"1.168135749","rc":[{"batb":[[1,17,52.41]],"ltp":19.5,"tv":108.16,"id":8204664},{"batb":[[1,11,83.39]],"ltp":11.0,"tv":58.92,"id":8204665},{"batb":[[0,2.64,788.62]],"ltp":2.64,"tv":242.74,"id":1042124},{"batb":[[2,7,122.46]],"ltp":7.2,"tv":94.52,"id":1042126}]}]}
{"op":"mcm","clk":"993289965","pt":1580539960068,"mc":[{"id":"1.168135749","rc":[{"batl":[[0,2.66,100],[1,2.76,12.66],[2,2.78,11.88]],"ltp":2.64,"tv":242.74,"id":1042124}]}]}
{"op":"mcm","clk":"993307360","pt":1580540305770,"mc":[{"id":"1.168135749","rc":[{"batl":[[0,18.5,11.14],[1,19,11.25],[2,20,87]],"ltp":19.5,"tv":108.16,"id":8204664}]}]}
{"op":"mcm","clk":"993307439","pt":1580540307365,"mc":[{"id":"1.168135749","rc":[{"batl":[[1,19,5]],"ltp":19.5,"tv":108.16,"id":8204664}]}]}
{"op":"mcm","clk":"993307508","pt":1580540309473,"mc":[{"id":"1.168135749","rc":[{"batl":[[0,18,3.91],[1,18.5,11.14],[2,19,5]],"ltp":19.5,"tv":108.16,"id":8204664}]}]}
{"op":"mcm","clk":"993309235","pt":1580540349145,"mc":[{"id":"1.168135749","rc":[{"trd":[[18,0.52]],"batl":[[0,18,3.65]],"ltp":18.0,"tv":108.68,"id":8204664}],"tv":1031.04}]}
{"op":"mcm","clk":"993309376","pt":1580540352368,"mc":[{"id":"1.168135749","rc":[{"batb":[[0,17.5,38]],"ltp":18.0,"tv":108.68,"id":8204664}]}]}
{"op":"mcm","clk":"993309400","pt":1580540352936,"mc":[{"id":"1.168135749","rc":[{"batl":[[0,18.5,11.14],[1,19,5],[2,20,87]],"ltp":18.0,"tv":108.68,"id":8204664}]}]}
{"op":"mcm","clk":"993309486","pt":1580540354841,"mc":[{"id":"1.168135749","rc":[{"batl":[[0,18,3.73],[1,18.5,11.14],[2,19,5]],"ltp":18.0,"tv":108.68,"id":8204664}]}]}
{"op":"mcm","clk":"993310154","pt":1580540368360,"mc":[{"id":"1.168135749","rc":[{"batl":[[0,18,14.87],[1,19,5],[2,20,87]],"ltp":18.0,"tv":108.68,"id":8204664}]}]}
{"op":"mcm","clk":"993310948","pt":1580540384307,"mc":[{"id":"1.168135749","rc":[{"batb":[[0,17.5,39.25]],"ltp":18.0,"tv":108.68,"id":8204664}]}]}
{"op":"mcm","clk":"993350155","pt":1580541025066,"mc":[{"id":"1.168135749","rc":[{"batl":[[0,3.85,39.57]],"ltp":3.75,"tv":380.28,"id":1042125}]}]}
{"op":"mcm","clk":"993515437","pt":1580543450242,"mc":[{"id":"1.168135749","rc":[{"trd":[[2.64,75.82]],"batb":[[0,2.64,783.55]],"ltp":2.64,"tv":252.87,"id":1042124}],"tv":1041.17}]}
{"op":"mcm","clk":"993515771","pt":1580543454748,"mc":[{"id":"1.168135749","rc":[{"batb":[[0,17.5,40.02]],"ltp":18.0,"tv":108.68,"id":8204664},{"trd":[[7.6,11.1]],"batl":[[0,7.8,8.64],[1,8,252.63],[2,8.6,1.68]],"ltp":7.6,"tv":98.04,"id":1042126}],"tv":1044.7}]}
{"op":"mcm","clk":"993515778","pt":1580543454848,"mc":[{"id":"1.168135749","rc":[{"batb":[[0,11.5,3.74]],"ltp":12.0,"tv":145.89,"id":8204663}]}]}
{"op":"mcm","clk":"993515858","pt":1580543456031,"mc":[{"id":"1.168135749","rc":[{"batl":[[2,2.78,0]],"ltp":2.64,"tv":252.87,"id":1042124}]}]}
{"op":"mcm","clk":"993516040","pt":1580543458664,"mc":[{"id":"1.168135749","rc":[{"batl":[[1,2.76,21.72]],"ltp":2.64,"tv":252.87,"id":1042124},{"batl":[[0,7.8,8.4]],"ltp":7.6,"tv":98.04,"id":1042126}]}]}
{"op":"mcm","clk":"993516139","pt":1580543460055,"mc":[{"id":"1.168135749","rc":[{"batl":[[0,7.6,2.71],[1,7.8,8.4],[2,8,252.63]],"ltp":7.6,"tv":98.04,"id":1042126}]}]}
{"op":"mcm","clk":"993521030","pt":1580543530527,"mc":[{"id":"1.168135749","rc":[{"trd":[[2.66,23.8]],"batl":[[0,2.66,95.44]],"ltp":2.66,"tv":261.99,"id":1042124}],"tv":1053.81}]}
{"op":"mcm","clk":"993567042","pt":1580543981747,"mc":[{"id":"1.168135749","rc":[{"batb":[[1,17,50.41]],"batl":[[0,18,11.14]],"ltp":18.0,"tv":108.68,"id":8204664},{"batl":[[2,4.4,10.64]],"ltp":3.75,"tv":380.28,"id":1042125},{"batl":[[1,2.76,12.66]],"ltp":2.66,"tv":261.99,"id":1042124}]}]}
{"op":"mcm","clk":"993567124","pt":1580543982772,"mc":[{"id":"1.168135749","rc":[{"batl":[[1,18.5,3.88],[2,19,5]],"ltp":18.0,"tv":108.68,"id":8204664},{"batb":[[0,3.75,6.28]],"batl":[[1,3.9,41.71]],"ltp":3.75,"tv":380.28,"id":1042125},{"batb":[[0,2.64,768.04]],"batl":[[1,2.74,12.02],[2,2.76,12.66]],"ltp":2.66,"tv":261.99,"id":1042124},{"batb":[[2,7,109.14]],"ltp":7.6,"tv":98.04,"id":1042126}]}]}
{"op":"mcm","clk":"993567213","pt":1580543984052,"mc":[{"id":"1.168135749","rc":[{"batb":[[0,17.5,42.02]],"ltp":18.0,"tv":108.68,"id":8204664},{"batb":[[1,3.7,146.65]],"ltp":3.75,"tv":380.28,"id":1042125},{"batb":[[1,2.6,282.98]],"ltp":2.66,"tv":261.99,"id":1042124},{"batb":[[1,7.2,51.63]],"ltp":7.6,"tv":98.04,"id":1042126}]}]}
{"op":"mcm","clk":"993567901","pt":1580543992673,"mc":[{"id":"1.168135749","rc":[{"trd":[[2.64,1611.91]],"batb":[[0,2.6,282.98],[1,2.56,181],[2,2.5,4]],"batl":[[0,2.64,191.96],[1,2.66,95.44],[2,2.74,12.02]],"ltp":2.64,"tv":1798.07,"id":1042124}],"tv":2589.9}]}
{"op":"mcm","clk":"993568142","pt":1580543995495,"mc":[{"id":"1.168135749","rc":[{"trd":[[18,1.13]],"batl":[[0,18,10.84]],"ltp":18.0,"tv":109.29,"id":8204664},{"batb":[[0,11.5,4.21]],"ltp":12.0,"tv":145.89,"id":8204663},{"batb":[[0,7.4,178.37]],"ltp":7.6,"tv":98.04,"id":1042126}],"tv":2590.5}]}
{"op":"mcm","clk":"993569815","pt":1580544014811,"mc":[{"id":"1.168135749","rc":[{"batl":[[0,2.62,15.74],[1,2.64,191.96],[2,2.66,95.44]],"ltp":2.64,"tv":1798.07,"id":1042124}]}]}
{"op":"mcm","clk":"993577664","pt":1580544108775,"mc":[{"id":"1.168135749","rc":[{"trd":[[2.62,73.61]],"batb":[[0,2.62,152.37],[1,2.6,282.98],[2,2.56,181]],"batl":[[0,2.64,191.96],[1,2.66,95.44],[2,2.74,12.02]],"ltp":2.62,"tv":1829.54,"id":1042124}],"tv":2621.97}]}
{"op":"mcm","clk":"993584933","pt":1580544187127,"mc":[{"id":"1.168135749","rc":[{"trd":[[7.6,16.53]],"batb":[[0,7.6,165.39],[1,7.4,178.37],[2,7.2,51.63]],"batl":[[0,7.8,8.4],[1,8,252.63],[2,8.6,1.68]],"ltp":7.6,"tv":103.46,"id":1042126}],"tv":2627.39}]}
{"op":"mcm","clk":"993585029","pt":1580544188527,"mc":[{"id":"1.168135749","rc":[{"batl":[[0,8,252.63],[1,8.6,1.68],[2,9.4,1.68]],"ltp":7.6,"tv":103.46,"id":1042126}]}]}
{"op":"mcm","clk":"993585278","pt":1580544192519,"mc":[{"id":"1.168135749","rc":[{"batl":[[0,7.8,2.57],[1,8,252.63],[2,8.6,1.68]],"ltp":7.6,"tv":103.46,"id":1042126}]}]}
{"op":"mcm","clk":"993585446","pt":1580544194839,"mc":[{"id":"1.168135749","rc":[{"batb":[[1,7.4,177]],"ltp":7.6,"tv":103.46,"id":1042126}]}]}
{"op":"mcm","clk":"993586367","pt":1580544209146,"mc":[{"id":"1.168135749","rc":[{"batb":[[0,3.75,258.43]],"ltp":3.75,"tv":380.28,"id":1042125}]}]}
{"op":"mcm","clk":"993587083","pt":1580544218793,"mc":[{"id":"1.168135749","rc":[{"batb":[[0,7.6,166.73]],"ltp":7.6,"tv":103.46,"id":1042126}]}]}
{"op":"mcm","clk":"993588849","pt":1580544244818,"mc":[{"id":"1.168135749","rc":[{"batb":[[0,3.75,6.28]],"ltp":3.75,"tv":380.28,"id":1042125},{"batb":[[0,7.6,1.34]],"ltp":7.6,"tv":103.46,"id":1042126}]}]}
{"op":"mcm","clk":"993590974","pt":1580544276571,"mc":[{"id":"1.168135749","rc":[{"batl":[[0,7.8,10.97]],"ltp":7.6,"tv":103.46,"id":1042126}]}]}
{"op":"mcm","clk":"993593661","pt":1580544317093,"mc":[{"id":"1.168135749","rc":[{"trd":[[2.64,1686.35]],"batl":[[0,2.64,154.72]],"ltp":2.64,"tv":1903.99,"id":1042124}],"tv":2701.84}]}
{"op":"mcm","clk":"993597933","pt":1580544375383,"mc":[{"id":"1.168135749","rc":[{"trd":[[2.64,1757.29]],"batl":[[0,2.64,119.23]],"ltp":2.64,"tv":1974.93,"id":1042124}],"tv":2772.78}]}
{"op":"mcm","clk":"993600871","pt":1580544419202,"mc":[{"id":"1.168135749","rc":[{"trd":[[2.64,1828.24]],"batl":[[0,2.64,83.74]],"ltp":2.64,"tv":2045.88,"id":1042124}],"tv":2843.73}]}
{"op":"mcm","clk":"993602925","pt":1580544451184,"mc":[{"id":"1.168135749","rc":[{"trd":[[2.64,1837.36]],"batl":[[0,2.64,79.18]],"ltp":2.64,"tv":2055.0,"id":1042124}],"tv":2852.85}]}
{"op":"mcm","clk":"993653318","pt":1580544962883,"mc":[{"id":"1.168135749","rc":[{"trd":[[2.64,1847.49]],"batl":[[0,2.64,74.11]],"ltp":2.64,"tv":2065.13,"id":1042124}],"tv":2862.98}]}
{"op":"mcm","clk":"993657688","pt":1580545004530,"mc":[{"id":"1.168135749","rc":[{"trd":[[3.75,131.2]],"batb":[[0,3.75,3.74]],"ltp":3.75,"tv":385.35,"id":1042125}],"tv":2868.05}]}
{"op":"mcm","clk":"993668791","pt":1580545119314,"mc":[{"id":"1.168135749","rc":[{"trd":[[2.64,1931.92]],"batl":[[0,2.64,31.88]],"ltp":2.64,"tv":2149.56,"id":1042124}],"tv":2952.47}]}
{"op":"mcm","clk":"993771752","pt":1580546239672,"mc":[{"id":"1.168135749","rc":[{"trd":[[17.5,4]],"batb":[[0,17.5,40.02]],"ltp":17.5,"tv":113.29,"id":8204664}],"tv":2956.47}]}
{"op":"mcm","clk":"993782645","pt":1580546252503,"mc":[{"id":"1.168135749","rc":[{"trd":[[11.5,18.52]],"batb":[[0,11.5,1.21]],"ltp":11.5,"tv":151.89,"id":8204663}],"tv":2962.48}]}
{"op":"mcm","clk":"993782957","pt":1580546256387,"mc":[{"id":"1.168135749","rc":[{"batb":[[0,11.5,3.21]],"ltp":11.5,"tv":151.89,"id":8204663}]}]}
{"op":"mcm","clk":"993796034","pt":1580546397794,"mc":[{"id":"1.168135749","rc":[{"trd":[[2.64,1995.65]],"batb":[[0,2.64,10.34],[1,2.62,152.37],[2,2.6,282.98]],"batl":[[0,2.66,95.44],[1,2.74,12.02],[2,2.76,12.66]],"ltp":2.64,"tv":2213.28,"id":1042124}],"tv":3026.2}]}
{"op":"mcm","clk":"993807947","pt":1580546528068,"mc":[{"id":"1.168135749","rc":[{"batl":[[2,4.2,3.93]],"ltp":3.75,"tv":385.35,"id":1042125}]}]}
{"op":"mcm","clk":"993846009","pt":1580546976170,"mc":[{"id":"1.168135749","rc":[{"trd":[[7.4,207.5],[7.6,19.2]],"batb":[[0,7.4,76.2],[1,7.2,51.63],[2,7,109.14]],"ltp":7.4,"tv":307.73,"id":1042126}],"tv":3230.47}]}
{"op":"mcm","clk":"993846517","pt":1580546981679,"mc":[{"id":"1.168135749","rc":[{"batl":[[0,7.8,318.49]],"ltp":7.4,"tv":307.73,"id":1042126}]}]}
{"op":"mcm","clk":"993851962","pt":1580547047667,"mc":[{"id":"1.168135749","rc":[{"trd":[[7.4,307.33]],"batb":[[0,7.4,26.28]],"ltp":7.4,"tv":407.57,"id":1042126}],"tv":3330.31}]}
{"op":"mcm","clk":"993852019","pt":1580547048492,"mc":[{"id":"1.168135749","rc":[{"trd":[[2.64,2016.34]],"batb":[[0,2.62,152.37],[1,2.6,282.98],[2,2.56,181]],"batl":[[0,2.64,89.65],[1,2.66,95.44],[2,2.74,12.02]],"ltp":2.64,"tv":2233.98,"id":1042124}],"tv":3351.0}]}
{"op":"mcm","clk":"993852413","pt":1580547053354,"mc":[{"id":"1.168135749","rc":[{"batl":[[0,7.8,10.97]],"ltp":7.4,"tv":407.57,"id":1042126}]}]}
{"op":"mcm","clk":"993944355","pt":1580547940784,"mc":[{"id":"1.168135749","rc":[{"batl":[[0,3.8,25.33],[1,3.85,39.57],[2,3.9,41.71]],"ltp":3.75,"tv":385.35,"id":1042125},{"batl":[[0,7.8,23.63]],"ltp":7.4,"tv":407.57,"id":1042126}]}]}
{"op":"mcm","clk":"993945957","pt":1580547955796,"mc":[{"id":"1.168135749","rc":[{"batl":[[2,3.9,67.03]],"ltp":3.75,"tv":385.35,"id":1042125}]}]}
{"op":"mcm","clk":"993946497","pt":1580547961802,"mc":[{"id":"1.168135749","rc":[{"batl":[[1,8,277.95]],"ltp":7.4,"tv":407.57,"id":1042126}]}]}
{"op":"mcm","clk":"994083379","pt":1580549090597,"mc":[{"id":"1.168135749","rc":[{"trd":[[2.64,2025.46]],"batl":[[0,2.64,85.09]],"ltp":2.64,"tv":2243.1,"id":1042124}],"tv":3360.12}]}
{"op":"mcm","clk":"994148928","pt":1580549734403,"mc":[{"id":"1.168135749","rc":[{"trd":[[3.8,54.15]],"batl":[[0,3.8,4]],"ltp":3.8,"tv":428.0,"id":1042125}],"tv":3402.78}]}
{"op":"mcm","clk":"994210999","pt":1580550254837,"mc":[{"id":"1.168135749","rc":[{"batl":[[0,7.6,24.98],[1,7.8,23.63],[2,8,277.95]],"ltp":7.4,"tv":407.57,"id":1042126}]}]}
{"op":"mcm","clk":"994211173","pt":1580550256616,"mc":[{"id":"1.168135749","rc":[{"batl":[[1,7.8,21.06]],"ltp":7.4,"tv":407.57,"id":1042126}]}]}
{"op":"mcm","clk":"994211298","pt":1580550257811,"mc":[{"id":"1.168135749","rc":[{"batl":[[0,7.6,26.98]],"ltp":7.4,"tv":407.57,"id":1042126}]}]}
{"op":"mcm","clk":"994306821","pt":1580550973390,"mc":[{"id":"1.168135749","rc":[{"batl":[[0,7.6,2]],"ltp":7.4,"tv":407.57,"id":1042126}]}]}
{"op":"mcm","clk":"994334596","pt":1580551210000,"mc":[{"id":"1.168135749","rc":[{"trd":[[11.5,22.52]],"batb":[[0,11.5,1.21]],"ltp":11.5,"tv":155.89,"id":8204663}],"tv":3406.78}]}
{"op":"mcm","clk":"994335185","pt":1580551214747,"mc":[{"id":"1.168135749","rc":[{"batb":[[0,11,131.36],[1,1.02,2],[2,1.01,1.01]],"ltp":11.5,"tv":155.89,"id":8204663}]}]}
{"op":"mcm","clk":"994335346","pt":1580551215958,"mc":[{"id":"1.168135749","rc":[{"batb":[[0,11.5,2],[1,11,131.36],[2,1.02,2]],"ltp":11.5,"tv":155.89,"id":8204663}]}]}
{"op":"mcm","clk":"994335794","pt":1580551219331,"mc":[{"id":"1.168135749","rc":[{"trd":[[18,5.14]],"batl":[[0,18,8.83]],"ltp":18.0,"tv":117.3,"id":8204664},{"batb":[[0,3.75,13.38]],"ltp":3.8,"tv":428.0,"id":1042125},{"batb":[[0,2.62,166.16]],"ltp":2.64,"tv":2243.1,"id":1042124},{"batb":[[0,7.4,31.16]],"ltp":7.4,"tv":407.57,"id":1042126}],"tv":3410.79}]}
{"op":"mcm","clk":"994336321","pt":1580551223165,"mc":[{"id":"1.168135749","rc":[{"trd":[[3.75,135.2]],"batb":[[0,3.75,11.38]],"ltp":3.75,"tv":432.0,"id":1042125}],"tv":3414.79}]}
{"op":"mcm","clk":"994339976","pt":1580551255044,"mc":[{"id":"1.168135749","rc":[{"batb":[[0,11.5,5.14]],"ltp":11.5,"tv":155.89,"id":8204663}]}]}
{"op":"mcm","clk":"994410363","pt":1580551670753,"mc":[{"id":"1.168135749","rc":[{"trd":[[2.62,87.23]],"batb":[[0,2.62,159.35]],"ltp":2.62,"tv":2256.71,"id":1042124}],"tv":3428.41}]}
{"op":"mcm","clk":"994461437","pt":1580551969022,"mc":[{"id":"1.168135749","rc":[{"trd":[[2.62,103.34]],"batb":[[0,2.62,151.29]],"ltp":2.62,"tv":2272.83,"id":1042124}],"tv":3444.52}]}
{"op":"mcm","clk":"994466087","pt":1580551994036,"mc":[{"id":"1.168135749","rc":[{"trd":[[3.75,157.96]],"batb":[[0,3.7,146.65],[1,3.65,125],[2,3.6,211.33]],"batl":[[0,3.75,1.68],[1,3.8,4],[2,3.85,39.57]],"ltp":3.75,"tv":454.76,"id":1042125}],"tv":3467.28}]}
{"op":"mcm","clk":"994466587","pt":1580551997156,"mc":[{"id":"1.168135749","rc":[{"trd":[[3.75,161.31],[3.8,62.14]],"batb":[[0,3.8,1.32],[1,3.7,146.65],[2,3.65,125]],"batl":[[0,3.85,39.57],[1,3.9,67.03],[2,4.2,3.93]],"ltp":3.8,"tv":466.11,"id":1042125}],"tv":3478.63}]}
{"op":"mcm","clk":"994510660","pt":1580552246225,"mc":[{"id":"1.168135749","rc":[{"trd":[[2.62,108.41]],"batb":[[0,2.62,148.76]],"ltp":2.62,"tv":2277.9,"id":1042124}],"tv":3483.7}]}
{"op":"mcm","clk":"994539132","pt":1580552397423,"mc":[{"id":"1.168135749","rc":[{"trd":[[7.4,369.62]],"batb":[[0,7.2,51.63],[1,7,109.14],[2,6,2]],"batl":[[0,7.4,120.82],[1,7.6,2],[2,7.8,21.06]],"ltp":7.4,"tv":469.86,"id":1042126}],"tv":3545.99}]}
{"op":"mcm","clk":"994539825","pt":1580552401005,"mc":[{"id":"1.168135749","rc":[{"batl":[[2,7.8,12.66]],"ltp":7.4,"tv":469.86,"id":1042126}]}]}
{"op":"mcm","clk":"994548679","pt":1580552448165,"mc":[{"id":"1.168135749","rc":[{"trd":[[7.2,188.24]],"batb":[[0,7,109.14],[1,6,2],[2,1.02,2]],"batl":[[0,7.2,67.25]],"ltp":7.2,"tv":577.05,"id":1042126}],"tv":3653.18}]}
{"op":"mcm","clk":"994549322","pt":1580552451457,"mc":[{"id":"1.168135749","rc":[{"batb":[[1,3.7,137.89]],"batl":[[1,3.9,57.25]],"ltp":3.8,"tv":466.11,"id":1042125}]}]}
{"op":"mcm","clk":"994549598","pt":1580552452803,"mc":[{"id":"1.168135749","rc":[{"batl":[[2,3.95,14.49]],"ltp":3.8,"tv":466.11,"id":1042125},{"trd":[[7.2,200.17]],"batl":[[0,7.2,61.29]],"ltp":7.2,"tv":588.98,"id":1042126}],"tv":3665.12}]}
{"op":"mcm","clk":"994550010","pt":1580552454877,"mc":[{"id":"1.168135749","rc":[{"batb":[[1,3.75,5.87],[2,3.7,137.89]],"ltp":3.8,"tv":466.11,"id":1042125}]}]}
{"op":"mcm","clk":"994550318","pt":1580552456702,"mc":[{"id":"1.168135749","rc":[{"batb":[[1,2.6,266.6]],"ltp":2.62,"tv":2277.9,"id":1042124}]}]}
{"op":"mcm","clk":"994550437","pt":1580552457304,"mc":[{"id":"1.168135749","rc":[{"batb":[[0,7,120.36]],"ltp":7.2,"tv":588.98,"id":1042126}]}]}
{"op":"mcm","clk":"994550624","pt":1580552458287,"mc":[{"id":"1.168135749","rc":[{"batb":[[0,2.62,162.66]],"ltp":2.62,"tv":2277.9,"id":1042124}]}]}
{"op":"mcm","clk":"994555780","pt":1580552485064,"mc":[{"id":"1.168135749","rc":[{"batb":[[2,3.7,145.45]],"ltp":3.8,"tv":466.11,"id":1042125},{"trd":[[7.2,233.76]],"batl":[[0,7.2,44.51],[2,7.8,39.55]],"ltp":7.2,"tv":622.57,"id":1042126}],"tv":3698.71}]}
{"op":"mcm","clk":"994561063","pt":1580552514803,"mc":[{"id":"1.168135749","rc":[{"batb":[[0,11,83.8],[1,9.8,76.53],[2,1.02,2]],"batl":[[0,12.5,204.11]],"ltp":11.0,"tv":58.92,"id":8204665},{"batb":[[1,11,104.47]],"batl":[[1,12.5,101.95]],"ltp":11.5,"tv":155.89,"id":8204663},{"batb":[[2,3.7,111]],"batl":[[1,3.9,25.33]],"ltp":3.8,"tv":466.11,"id":1042125},{"batl":[[2,7.8,12.66]],"ltp":7.2,"tv":622.57,"id":1042126}]}]}
{"op":"mcm","clk":"994564730","pt":1580552535254,"mc":[{"id":"1.168135749","rc":[{"batb":[[0,11.5,13.85],[1,11,83.39],[2,9.8,76.53]],"batl":[[1,13,23.53]],"ltp":11.0,"tv":58.92,"id":8204665},{"batb":[[0,11.5,19.43]],"batl":[[1,12.5,115.39]],"ltp":11.5,"tv":155.89,"id":8204663},{"batb":[[2,3.7,143.77]],"batl":[[1,3.9,48.85]],"ltp":3.8,"tv":466.11,"id":1042125},{"batb":[[0,7,143.89]],"batl":[[1,7.6,18.8]],"ltp":7.2,"tv":622.57,"id":1042126}]}]}
{"op":"mcm","clk":"994600641","pt":1580552675883,"mc":[{"id":"1.168135749","rc":[{"trd":[[2.64,2106.22]],"batl":[[0,2.64,44.69]],"ltp":2.64,"tv":2358.65,"id":1042124}],"tv":3779.46}]}
{"op":"mcm","clk":"994693158","pt":1580553205376,"mc":[{"id":"1.168135749","rc":[{"trd":[[18,8.89]],"batl":[[0,18,5.08]],"ltp":18.0,"tv":121.05,"id":8204664},{"trd":[[12.5,5.41]],"batl":[[0,12.5,198.7]],"ltp":12.5,"tv":64.32,"id":8204665},{"trd":[[12,13.62]],"batl":[[0,12.5,115.39],[1,12.5,0]],"ltp":12.0,"tv":161.52,"id":8204663},{"trd":[[3.85,56.7]],"batl":[[0,3.85,22]],"ltp":3.85,"tv":483.68,"id":1042125},{"trd":[[2.64,2131.85]],"batl":[[0,2.64,19.06]],"ltp":2.64,"tv":2384.28,"id":1042124},{"trd":[[7,299.47]],"batb":[[0,6,2],[1,1.02,2],[2,1.01,1.01]],"ltp":7.0,"tv":922.04,"id":1042126}],"tv":4136.93}]}
{"op":"mcm","clk":"994693261","pt":1580553205981,"mc":[{"id":"1.168135749","rc":[{"batb":[[0,6.4,17.41],[1,6,2],[2,5,10]],"ltp":7.0,"tv":922.04,"id":1042126}]}]}
{"op":"mcm","clk":"994693762","pt":1580553209113,"mc":[{"id":"1.168135749","rc":[{"batb":[[0,7,5.88],[1,6.4,17.41],[2,6,2]],"batl":[[1,7.6,16.8]],"ltp":7.0,"tv":922.04,"id":1042126}]}]}
{"op":"mcm","clk":"994694001","pt":1580553210498,"mc":[{"id":"1.168135749","rc":[{"batb":[[1,6,2],[2,5,10]],"batl":[[1,7.4,5.32],[2,7.6,16.8]],"ltp":7.0,"tv":922.04,"id":1042126}]}]}
{"op":"mcm","clk":"994694817","pt":1580553215109,"mc":[{"id":"1.168135749","rc":[{"trd":[[7,311.23]],"batb":[[0,6,2],[1,5,10],[2,1.02,2]],"batl":[[0,7,4.25],[1,7.2,44.51],[2,7.4,5.32]],"ltp":7.0,"tv":933.8,"id":1042126}],"tv":4148.69}]}
{"op":"mcm","clk":"994695515","pt":1580553218517,"mc":[{"id":"1.168135749","rc":[{"batb":[[0,11.5,16.28],[1,11,102.49]],"ltp":12.0,"tv":161.52,"id":8204663}]}]}
{"op":"mcm","clk":"994695742","pt":1580553219806,"mc":[{"id":"1.168135749","rc":[{"trd":[[7,318.54]],"batl":[[0,7.2,45.1],[1,7.4,5.32],[2,7.6,16.8]],"ltp":7.0,"tv":941.12,"id":1042126}],"tv":4156.0}]}
{"op":"mcm","clk":"994695804","pt":1580553220230,"mc":[{"id":"1.168135749","rc":[{"batb":[[0,6.4,17.41],[1,6,2],[2,5,10]],"ltp":7.0,"tv":941.12,"id":1042126}]}]}
{"op":"mcm","clk":"994696648","pt":1580553224322,"mc":[{"id":"1.168135749","rc":[{"batl":[[2,2.76,12.66]],"ltp":2.64,"tv":2384.28,"id":1042124},{"batb":[[0,6.8,7.15],[1,6.4,17.41],[2,6,2]],"ltp":7.0,"tv":941.12,"id":1042126}]}]}
{"op":"mcm","clk":"994696937","pt":1580553226033,"mc":[{"id":"1.168135749","rc":[{"batl":[[2,2.76,22.43]],"ltp":2.64,"tv":2384.28,"id":1042124}]}]}
{"op":"mcm","clk":"994698362","pt":1580553234741,"mc":[{"id":"1.168135749","rc":[{"batb":[[0,11.5,21.32]],"ltp":12.0,"tv":161.52,"id":8204663}]}]}
{"op":"mcm","clk":"994707786","pt":1580553291390,"mc":[{"id":"1.168135749","rc":[{"batb":[[0,6.8,9.15],[1,6,2],[2,5,10]],"ltp":7.0,"tv":941.12,"id":1042126}]}]}
{"op":"mcm","clk":"994708407","pt":1580553294982,"mc":[{"id":"1.168135749","rc":[{"batb":[[0,6.8,10.68]],"ltp":7.0,"tv":941.12,"id":1042126}]}]}
{"op":"mcm","clk":"994708630","pt":1580553296213,"mc":[{"id":"1.168135749","rc":[{"batb":[[0,11.5,18.06]],"ltp":12.5,"tv":64.32,"id":8204665},{"batb":[[2,3.7,152.17]],"ltp":3.85,"tv":483.68,"id":1042125},{"batb":[[0,6.8,35.89]],"batl":[[1,7.4,22.12]],"ltp":7.0,"tv":941.12,"id":1042126}]}]}
{"op":"mcm","clk":"994709589","pt":1580553301820,"mc":[{"id":"1.168135749","rc":[{"batb":[[0,6.8,32.36]],"ltp":7.0,"tv":941.12,"id":1042126}]}]}
{"op":"mcm","clk":"994709607","pt":1580553301882,"mc":[{"id":"1.168135749","rc":[{"trd":[[7,319.74]],"batb":[[0,6.8,33.29]],"batl":[[0,7.2,44.51]],"ltp":7.0,"tv":942.31,"id":1042126}],"tv":4157.2}]}
{"op":"mcm","clk":"994710782","pt":1580553308697,"mc":[{"id":"1.168135749","rc":[{"trd":[[7.2,235.62]],"batb":[[0,6.8,32.36]],"batl":[[0,7.2,43.58]],"ltp":7.2,"tv":944.17,"id":1042126}],"tv":4159.06}]}
{"op":"mcm","clk":"994713665","pt":1580553326114,"mc":[{"id":"1.168135749","rc":[{"batb":[[0,11,83.8],[1,9.8,76.53],[2,1.02,2]],"batl":[[1,13,0]],"ltp":12.5,"tv":64.32,"id":8204665},{"batb":[[0,11.5,7.03]],"batl":[[0,12.5,101.95]],"ltp":12.0,"tv":161.52,"id":8204663},{"batb":[[2,3.7,111]],"batl":[[1,3.9,25.33]],"ltp":3.85,"tv":483.68,"id":1042125},{"batb":[[0,6.8,7.15]],"batl":[[1,7.4,5.32],[2,7.8,12.66]],"ltp":7.2,"tv":944.17,"id":1042126}]}]}
{"op":"mcm","clk":"994720571","pt":1580553367083,"mc":[{"id":"1.168135749","rc":[{"batb":[[0,11.5,18.06],[1,11,83.39],[2,9.8,76.53]],"batl":[[1,13,17.64]],"ltp":12.5,"tv":64.32,"id":8204665},{"batb":[[0,11.5,20.48]],"batl":[[0,12.5,116.23]],"ltp":12.0,"tv":161.52,"id":8204663},{"batb":[[2,3.7,154.69]],"batl":[[1,3.9,51.37]],"ltp":3.85,"tv":483.68,"id":1042125},{"batb":[[0,6.8,34.04]],"batl":[[1,7.4,22.12]],"ltp":7.2,"tv":944.17,"id":1042126}]}]}
{"op":"mcm","clk":"994812497","pt":1580553857270,"mc":[{"id":"1.168135749","rc":[{"trd":[[7.2,322.82]],"batb":[[0,6.8,34.33]],"batl":[[0,7.4,22.12],[1,7.8,12.66],[2,8,252.75]],"ltp":7.2,"tv":1031.38,"id":1042126}],"tv":4246.26}]}
{"op":"mcm","clk":"994812779","pt":1580553859158,"mc":[{"id":"1.168135749","rc":[{"batb":[[0,6.8,34.04]],"ltp":7.2,"tv":1031.38,"id":1042126}]}]}
{"op":"mcm","clk":"994813732","pt":1580553865274,"mc":[{"id":"1.168135749","rc":[{"batb":[[0,7,58.31],[1,6.8,34.04],[2,6,2]],"ltp":7.2,"tv":1031.38,"id":1042126}]}]}
{"op":"mcm","clk":"994814821","pt":1580553871912,"mc":[{"id":"1.168135749","rc":[{"batb":[[1,3.75,173.98]],"ltp":3.85,"tv":483.68,"id":1042125}]}]}
{"op":"mcm","clk":"994823927","pt":1580553928016,"mc":[{"id":"1.168135749","rc":[{"batl":[[1,7.6,35.29],[2,7.8,12.66]],"ltp":7.2,"tv":1031.38,"id":1042126}]}]}
{"op":"mcm","clk":"994841207","pt":1580554038093,"mc":[{"id":"1.168135749","rc":[{"batl":[[0,7.4,5.32]],"ltp":7.2,"tv":1031.38,"id":1042126}]}]}
{"op":"mcm","clk":"994864841","pt":1580554198168,"mc":[{"id":"1.168135749","rc":[{"trd":[[11.5,42.79]],"batb":[[0,11.5,10.33]],"ltp":11.5,"tv":181.79,"id":8204663}],"tv":4266.53}]}
{"op":"mcm","clk":"994865434","pt":1580554202541,"mc":[{"id":"1.168135749","rc":[{"batl":[[1,19,5],[2,20,87]],"ltp":18.0,"tv":121.05,"id":8204664},{"batb":[[0,11.5,12.33]],"ltp":11.5,"tv":181.79,"id":8204663}]}]}
{"op":"mcm","clk":"994865646","pt":1580554203967,"mc":[{"id":"1.168135749","rc":[{"batl":[[1,19,10.79]],"ltp":18.0,"tv":121.05,"id":8204664}]}]}
{"op":"mcm","clk":"994868291","pt":1580554221785,"mc":[{"id":"1.168135749","rc":[{"trd":[[11.5,36.76]],"batb":[[0,11.5,11.65]],"ltp":11.5,"tv":77.12,"id":8204665}],"tv":4279.33}]}
{"op":"mcm","clk":"994869790","pt":1580554233075,"mc":[{"id":"1.168135749","rc":[{"batb":[[0,11.5,16.43]],"ltp":11.5,"tv":77.12,"id":8204665}]}]}
{"op":"mcm","clk":"994873401","pt":1580554259313,"mc":[{"id":"1.168135749","rc":[{"batb":[[0,11.5,4.77]],"batl":[[1,13,0]],"ltp":11.5,"tv":77.12,"id":8204665},{"batb":[[0,11.5,2]],"batl":[[0,12.5,101.95]],"ltp":11.5,"tv":181.79,"id":8204663},{"batb":[[2,3.7,111]],"batl":[[1,3.9,25.33]],"ltp":3.85,"tv":483.68,"id":1042125},{"batb":[[1,6.8,7.15]],"batl":[[1,7.8,12.66],[2,8,252.75]],"ltp":7.2,"tv":1031.38,"id":1042126}]}]}
{"op":"mcm","clk":"994877710","pt":1580554290744,"mc":[{"id":"1.168135749","rc":[{"batb":[[0,11.5,18.22]],"batl":[[0,12.5,212.98]],"ltp":11.5,"tv":77.12,"id":8204665},{"batb":[[0,11.5,16.28]],"batl":[[0,12.5,115.39]],"ltp":11.5,"tv":181.79,"id":8204663},{"batb":[[2,3.7,153.01]],"batl":[[2,3.95,58.18]],"ltp":3.85,"tv":483.68,"id":1042125},{"batb":[[1,6.8,39.92]],"batl":[[1,7.6,31.93],[2,7.8,12.66]],"ltp":7.2,"tv":1031.38,"id":1042126}]}]}
{"op":"mcm","clk":"994879220","pt":1580554302359,"mc":[{"id":"1.168135749","rc":[{"trd":[[11.5,72.23]],"batb":[[0,11,83.86],[1,9.8,76.53],[2,1.02,2]],"ltp":11.5,"tv":112.6,"id":8204665}],"tv":4314.81}]}
{"op":"mcm","clk":"994880063","pt":1580554309657,"mc":[{"id":"1.168135749","rc":[{"trd":[[11.5,75.34]],"batb":[[0,11,102.49],[1,1.02,2],[2,1.01,1.01]],"batl":[[0,11.5,1.46],[1,12.5,115.39]],"ltp":11.5,"tv":214.34,"id":8204663}],"tv":4347.35}]}
{"op":"mcm","clk":"994880496","pt":1580554313597,"mc":[{"id":"1.168135749","rc":[{"trd":[[11.5,78.27]],"batb":[[0,11,103.02]],"batl":[[0,12.5,115.39],[1,12.5,0]],"ltp":11.5,"tv":217.27,"id":8204663}],"tv":4350.29}]}
{"op":"mcm","clk":"994880852","pt":1580554316288,"mc":[{"id":"1.168135749","rc":[{"batb":[[0,11,102.49]],"ltp":11.5,"tv":217.27,"id":8204663},{"trd":[[2.64,2169.25]],"batl":[[0,2.66,95.8],[1,2.76,22.43],[2,3,7.87]],"ltp":2.64,"tv":2421.68,"id":1042124}],"tv":4387.69}]}
{"op":"mcm","clk":"994881950","pt":1580554324602,"mc":[{"id":"1.168135749","rc":[{"trd":[[3.75,172.67],[3.8,64.78]],"batb":[[0,3.75,168.3],[1,3.7,153.01],[2,3.65,125]],"ltp":3.75,"tv":497.68,"id":1042125}],"tv":4401.69}]}
{"op":"mcm","clk":"994882379","pt":1580554327898,"mc":[{"id":"1.168135749","rc":[{"batb":[[0,11.5,2],[1,11,102.49],[2,1.02,2]],"ltp":11.5,"tv":217.27,"id":8204663}]}]}
{"op":"mcm","clk":"994882968","pt":1580554330704,"mc":[{"id":"1.168135749","rc":[{"batb":[[0,11,108.23]],"batl":[[0,12.5,215.5]],"ltp":11.5,"tv":112.6,"id":8204665},{"batb":[[1,11,126.86]],"batl":[[0,12.5,118.75]],"ltp":11.5,"tv":217.27,"id":8204663},{"batb":[[0,3.75,191.63]],"ltp":3.75,"tv":497.68,"id":1042125}]}]}
{"op":"mcm","clk":"994883223","pt":1580554332180,"mc":[{"id":"1.168135749","rc":[{"batb":[[0,3.75,199.19]],"ltp":3.75,"tv":497.68,"id":1042125}]}]}
{"op":"mcm","clk":"994897906","pt":1580554361425,"mc":[{"id":"1.168135749","rc":[{"batb":[[0,11,107.76]],"ltp":11.5,"tv":112.6,"id":8204665},{"batb":[[1,3.7,111]],"batl":[[2,3.95,48.94]],"ltp":3.75,"tv":497.68,"id":1042125},{"batl":[[1,7.6,24.37]],"ltp":7.2,"tv":1031.38,"id":1042126}]}]}
{"op":"mcm","clk":"994903786","pt":1580554407358,"mc":[{"id":"1.168135749","rc":[{"batl":[[0,12,15.2],[1,12.5,118.75]],"ltp":11.5,"tv":217.27,"id":8204663}]}]}
{"op":"mcm","clk":"994905653","pt":1580554421500,"mc":[{"id":"1.168135749","rc":[{"batl":[[0,11.5,17.73],[1,12.5,215.5]],"ltp":11.5,"tv":112.6,"id":8204665}]}]}
{"op":"mcm","clk":"994905950","pt":1580554423575,"mc":[{"id":"1.168135749","rc":[{"trd":[[18,10.35]],"batl":[[0,18,3.63]],"ltp":18.0,"tv":122.51,"id":8204664},{"trd":[[11.5,74.51]],"batl":[[0,11.5,15.45]],"ltp":11.5,"tv":114.88,"id":8204665},{"trd":[[11.5,84.55]],"batb":[[0,11,126.86],[1,1.02,2],[2,1.01,1.01]],"ltp":11.5,"tv":223.55,"id":8204663},{"trd":[[3.85,63.52]],"batl":[[0,3.85,15.18]],"ltp":3.85,"tv":504.5,"id":1042125},{"trd":[[2.64,2169.61],[2.66,33.31]],"batl":[[0,2.66,85.93]],"ltp":2.66,"tv":2431.55,"id":1042124},{"trd":[[7.4,373.17]],"batl":[[0,7.4,1.77]],"ltp":7.4,"tv":1034.93,"id":1042126}],"tv":4431.94}]}
{"op":"mcm","clk":"994906572","pt":1580554427703,"mc":[{"id":"1.168135749","rc":[{"batb":[[1,6.8,32.77]],"batl":[[0,7.6,24.37],[1,7.8,12.66],[2,8,252.75]],"ltp":7.4,"tv":1034.93,"id":1042126}]}]}
{"op":"mcm","clk":"994906723","pt":1580554428704,"mc":[{"id":"1.168135749","rc":[{"batb":[[0,7,62.78]],"ltp":7.4,"tv":1034.93,"id":1042126}]}]}
{"op":"mcm","clk":"994906785","pt":1580554429074,"mc":[{"id":"1.168135749","rc":[{"batl":[[0,7.4,6.8],[1,7.6,24.37],[2,7.8,12.66]],"ltp":7.4,"tv":1034.93,"id":1042126}]}]}
{"op":"mcm","clk":"994908578","pt":1580554442605,"mc":[{"id":"1.168135749","rc":[{"trd":[[17.5,29.34]],"batb":[[0,17.5,27.34]],"ltp":17.5,"tv":147.85,"id":8204664}],"tv":4457.28}]}
{"op":"mcm","clk":"994913133","pt":1580554474533,"mc":[{"id":"1.168135749","rc":[{"trd":[[18,13.14]],"batl":[[0,19,11.63],[1,20,87],[2,38,2]],"ltp":18.0,"tv":150.64,"id":8204664},{"trd":[[11.5,78.88]],"batl":[[0,11.5,11.08]],"ltp":11.5,"tv":119.25,"id":8204665},{"trd":[[11.5,88.92]],"batl":[[0,11.5,10.82]],"ltp":11.5,"tv":227.92,"id":8204663},{"trd":[[3.85,76.59]],"batl":[[0,3.85,2.11]],"ltp":3.85,"tv":517.57,"id":1042125},{"trd":[[2.66,52.23]],"batl":[[0,2.66,67.01]],"ltp":2.66,"tv":2450.47,"id":1042124},{"trd":[[7.4,379.97]],"batl":[[0,7.6,24.37],[1,7.8,12.66],[2,8,252.75]],"ltp":7.4,"tv":1041.73,"id":1042126}],"tv":4507.61}]}
{"op":"mcm","clk":"994913921","pt":1580554479747,"mc":[{"id":"1.168135749","rc":[{"trd":[[18,13.59]],"batl":[[0,19,11.17]],"ltp":18.0,"tv":151.09,"id":8204664},{"trd":[[11.5,79.58]],"batl":[[0,11.5,10.37]],"ltp":11.5,"tv":119.95,"id":8204665},{"trd":[[11.5,89.63]],"batl":[[0,11.5,10.12]],"ltp":11.5,"tv":228.63,"id":8204663},{"trd":[[3.85,78.7]],"batl":[[0,3.9,25.33],[1,3.95,48.94],[2,4.2,3.93]],"ltp":3.85,"tv":519.68,"id":1042125},{"trd":[[2.66,55.28]],"batl":[[0,2.66,63.96]],"ltp":2.66,"tv":2453.52,"id":1042124},{"trd":[[7.4,381.07]],"batl":[[0,7.4,2.93],[1,7.6,24.37],[2,7.8,12.66]],"ltp":7.4,"tv":1042.83,"id":1042126}],"tv":4515.72}]}
{"op":"mcm","clk":"994914217","pt":1580554481551,"mc":[{"id":"1.168135749","rc":[{"batl":[[0,7.6,24.37],[1,7.8,12.66],[2,8,252.75]],"ltp":7.4,"tv":1042.83,"id":1042126}]}]}
{"op":"mcm","clk":"994914525","pt":1580554483872,"mc":[{"id":"1.168135749","rc":[{"batl":[[0,7.4,3.65],[1,7.6,24.37],[2,7.8,12.66]],"ltp":7.4,"tv":1042.83,"id":1042126}]}]}
{"op":"mcm","clk":"994922959","pt":1580554535922,"mc":[{"id":"1.168135749","rc":[{"batb":[[0,2.64,13.14],[1,2.62,162.66],[2,2.6,266.6]],"ltp":2.66,"tv":2453.52,"id":1042124}]}]}
{"op":"mcm","clk":"994925341","pt":1580554549820,"mc":[{"id":"1.168135749","rc":[{"trd":[[11,255.38]],"batb":[[0,11,51.86]],"ltp":11.0,"tv":378.63,"id":8204663}],"tv":4665.72}]}
{"op":"mcm","clk":"994925992","pt":1580554553515,"mc":[{"id":"1.168135749","rc":[{"batb":[[1,10,10],[2,1.02,2]],"ltp":11.0,"tv":378.63,"id":8204663}]}]}
{"op":"mcm","clk":"994926112","pt":1580554554248,"mc":[{"id":"1.168135749","rc":[{"batb":[[1,2.62,206.31]],"ltp":2.66,"tv":2453.52,"id":1042124}]}]}
{"op":"mcm","clk":"994927412","pt":1580554561642,"mc":[{"id":"1.168135749","rc":[{"trd":[[17.5,79.34]],"batb":[[0,17.5,2.34]],"ltp":17.5,"tv":201.09,"id":8204664}],"tv":4715.72}]}
{"op":"mcm","clk":"994933507","pt":1580554597057,"mc":[{"id":"1.168135749","rc":[{"trd":[[11.5,100.34]],"batb":[[0,11,108.38]],"batl":[[0,12.5,215.5],[1,12.5,0]],"ltp":11.5,"tv":140.7,"id":8204665}],"tv":4736.48}]}
{"op":"mcm","clk":"994933774","pt":1580554598665,"mc":[{"id":"1.168135749","rc":[{"batb":[[0,11,107.76]],"batl":[[1,17,2.52]],"ltp":11.5,"tv":140.7,"id":8204665}]}]}
{"op":"mcm","clk":"994936469","pt":1580554614299,"mc":[{"id":"1.168135749","rc":[{"batb":[[0,11,94.76]],"ltp":11.5,"tv":140.7,"id":8204665}]}]}
{"op":"mcm","clk":"994938173","pt":1580554624401,"mc":[{"id":"1.168135749","rc":[{"batb":[[0,2.64,194.14]],"ltp":2.66,"tv":2453.52,"id":1042124}]}]}
{"op":"mcm","clk":"994939157","pt":1580554629822,"mc":[{"id":"1.168135749","rc":[{"batb":[[1,2.62,192.52]],"ltp":2.66,"tv":2453.52,"id":1042124}]}]}
{"op":"mcm","clk":"994941988","pt":1580554645839,"mc":[{"id":"1.168135749","rc":[{"trd":[[2.66,82.43]],"batl":[[0,2.66,50.38]],"ltp":2.66,"tv":2480.68,"id":1042124}],"tv":4763.64}]}
{"op":"mcm","clk":"994945009","pt":1580554662738,"mc":[{"id":"1.168135749","rc":[{"batl":[[1,7.8,12.66],[2,8,252.75]],"ltp":7.4,"tv":1042.83,"id":1042126}]}]}
{"op":"mcm","clk":"994948519","pt":1580554680778,"mc":[{"id":"1.168135749","rc":[{"batb":[[0,11.5,3.59],[1,11,94.76],[2,9.8,76.53]],"ltp":11.5,"tv":140.7,"id":8204665},{"trd":[[11.5,96.8]],"batl":[[0,11.5,6.53]],"ltp":11.5,"tv":385.8,"id":8204663},{"trd":[[2.66,113.39]],"batl":[[0,2.66,34.9]],"ltp":2.66,"tv":2511.64,"id":1042124}],"tv":4801.77}]}
{"op":"mcm","clk":"994948535","pt":1580554680884,"mc":[{"id":"1.168135749","rc":[{"batb":[[0,3.8,10.83],[1,3.75,199.19],[2,3.7,111]],"ltp":3.85,"tv":519.68,"id":1042125},{"batb":[[0,7.2,5.71],[1,7,62.78],[2,6.8,32.77]],"ltp":7.4,"tv":1042.83,"id":1042126}]}]}
{"op":"mcm","clk":"994962341","pt":1580554757358,"mc":[{"id":"1.168135749","rc":[{"batl":[[1,7.8,53.83]],"ltp":7.4,"tv":1042.83,"id":1042126}]}]}
{"op":"mcm","clk":"994979063","pt":1580554838232,"mc":[{"id":"1.168135749","rc":[{"trd":[[2.66,174.98]],"batl":[[0,2.66,4.09]],"ltp":2.66,"tv":2573.23,"id":1042124}],"tv":4863.36}]}
{"op":"mcm","clk":"994991483","pt":1580554898255,"mc":[{"id":"1.168135749","rc":[{"batb":[[1,3.75,31.09]],"ltp":3.85,"tv":519.68,"id":1042125},{"batb":[[1,2.62,57.55]],"ltp":2.66,"tv":2573.23,"id":1042124},{"batb":[[1,7,4.47]],"ltp":7.4,"tv":1042.83,"id":1042126}]}]}
{"op":"mcm","clk":"994992211","pt":1580554902148,"mc":[{"id":"1.168135749","rc":[{"batl":[[0,2.66,105.39]],"ltp":2.66,"tv":2573.23,"id":1042124}]}]}
{"op":"mcm","clk":"994993071","pt":1580554906207,"mc":[{"id":"1.168135749","rc":[{"trd":[[2.66,385.86]],"batb":[[0,2.66,649.47],[1,2.64,194.14],[2,2.62,57.55]],"batl":[[0,2.76,22.43],[1,3,7.87],[2,3,0]],"ltp":2.66,"tv":2784.11,"id":1042124}],"tv":5074.24}]}
{"op":"mcm","clk":"994993769","pt":1580554909391,"mc":[{"id":"1.168135749","rc":[{"batb":[[1,2.64,181]],"ltp":2.66,"tv":2784.11,"id":1042124}]}]}
{"op":"mcm","clk":"995003056","pt":1580554949649,"mc":[{"id":"1.168135749","rc":[{"batl":[[0,2.7,50.65],[1,2.76,22.43],[2,3,7.87]],"ltp":2.66,"tv":2784.11,"id":1042124}]}]}
{"op":"mcm","clk":"995004381","pt":1580554955453,"mc":[{"id":"1.168135749","rc":[{"batb":[[0,2.68,16.77],[1,2.66,649.47],[2,2.64,181]],"ltp":2.66,"tv":2784.11,"id":1042124}]}]}
{"op":"mcm","clk":"995011490","pt":1580554988791,"mc":[{"id":"1.168135749","rc":[{"batb":[[0,3.8,98.67]],"ltp":3.85,"tv":519.68,"id":1042125}]}]}
{"op":"mcm","clk":"995013528","pt":1580554998583,"mc":[{"id":"1.168135749","rc":[{"trd":[[2.68,46.5]],"batb":[[0,2.66,649.58],[1,2.64,181],[2,2.62,57.55]],"ltp":2.68,"tv":2817.43,"id":1042124}],"tv":5107.56}]}
{"op":"mcm","clk":"995013710","pt":1580554999500,"mc":[{"id":"1.168135749","rc":[{"batb":[[0,2.66,649.47]],"ltp":2.68,"tv":2817.43,"id":1042124}]}]}
{"op":"mcm","clk":"995014099","pt":1580555001380,"mc":[{"id":"1.168135749","rc":[{"batl":[[1,2.74,16.3],[2,2.76,22.43]],"ltp":2.68,"tv":2817.43,"id":1042124}]}]}
{"op":"mcm","clk":"995015966","pt":1580555010722,"mc":[{"id":"1.168135749","rc":[{"trd":[[7.2,334.24]],"batb":[[0,7,4.47],[1,6.8,32.77],[2,6.2,84.02]],"batl":[[0,7.2,29.29],[1,7.4,3.65],[2,7.8,53.83]],"ltp":7.2,"tv":1054.25,"id":1042126}],"tv":5118.98}]}
{"op":"mcm","clk":"995016315","pt":1580555012587,"mc":[{"id":"1.168135749","rc":[{"batl":[[1,2.76,22.43],[2,3,7.87]],"ltp":2.68,"tv":2817.43,"id":1042124}]}]}
{"op":"mcm","clk":"995020938","pt":1580555035505,"mc":[{"id":"1.168135749","rc":[{"trd":[[11.5,107.51]],"batb":[[0,11,94.76],[1,9.8,76.53],[2,1.02,2]],"batl":[[0,11.5,16.41],[1,12.5,215.5],[2,17,2.52]],"ltp":11.5,"tv":147.88,"id":8204665}],"tv":5126.16}]}
{"op":"mcm","clk":"995022530","pt":1580555043541,"mc":[{"id":"1.168135749","rc":[{"trd":[[11,46.96]],"batb":[[0,11,78.35]],"batl":[[0,12.5,215.5],[1,17,2.52],[2,17,0]],"ltp":11.0,"tv":180.7,"id":8204665}],"tv":5158.98}]}
{"op":"mcm","clk":"995030372","pt":1580555078768,"mc":[{"id":"1.168135749","rc":[{"batb":[[2,6.6,50.41]],"batl":[[2,7.6,26.05]],"ltp":7.2,"tv":1054.25,"id":1042126}]}]}
{"op":"mcm","clk":"995035212","pt":1580555100024,"mc":[{"id":"1.168135749","rc":[{"trd":[[17,5.56],[17.5,84.02]],"batb":[[0,17,47.63],[1,16,23],[2,15.5,19.6]],"ltp":17.0,"tv":211.33,"id":8204664}],"tv":5169.22}]}
{"op":"mcm","clk":"995035543","pt":1580555101274,"mc":[{"id":"1.168135749","rc":[{"batl":[[0,19,5.38]],"ltp":17.0,"tv":211.33,"id":8204664}]}]}
{"op":"mcm","clk":"995035956","pt":1580555102989,"mc":[{"id":"1.168135749","rc":[{"batb":[[0,17.5,2],[1,17,47.63],[2,16,23]],"batl":[[0,18.5,4.09],[1,19,5],[2,20,87]],"ltp":17.0,"tv":211.33,"id":8204664}]}]}
{"op":"mcm","clk":"995036788","pt":1580555106304,"mc":[{"id":"1.168135749","rc":[{"trd":[[11,263.38]],"batb":[[0,11,47.86]],"ltp":11.0,"tv":393.8,"id":8204663}],"tv":5177.22}]}
{"op":"mcm","clk":"995037508","pt":1580555109390,"mc":[{"id":"1.168135749","rc":[{"batb":[[0,17.5,4.35]],"ltp":17.0,"tv":211.33,"id":8204664}]}]}
{"op":"mcm","clk":"995038135","pt":1580555112319,"mc":[{"id":"1.168135749","rc":[{"trd":[[11,58.96]],"batb":[[0,11,72.35]],"ltp":11.0,"tv":192.7,"id":8204665}],"tv":5189.22}]}
{"op":"mcm","clk":"995045998","pt":1580555151263,"mc":[{"id":"1.168135749","rc":[{"trd":[[7,327.74]],"batb":[[0,6.8,33.24],[1,6.6,50.41],[2,6.2,84.02]],"ltp":7.0,"tv":1062.25,"id":1042126}],"tv":5197.22}]}
{"op":"mcm","clk":"995046810","pt":1580555154663,"mc":[{"id":"1.168135749","rc":[{"batb":[[0,6.8,32.77]],"ltp":7.0,"tv":1062.25,"id":1042126}]}]}
{"op":"mcm","clk":"995046976","pt":1580555155541,"mc":[{"id":"1.168135749","rc":[{"batb":[[0,7,6.37],[1,6.8,32.77],[2,6.6,50.41]],"ltp":7.0,"tv":1062.25,"id":1042126}]}]}
{"op":"mcm","clk":"995053966","pt":1580555189011,"mc":[{"id":"1.168135749","rc":[{"batb":[[1,6.2,84.02],[2,6,2]],"ltp":7.0,"tv":1062.25,"id":1042126}]}]}
{"op":"mcm","clk":"995087411","pt":1580555298738,"mc":[{"id":"1.168135749","rc":[{"batb":[[0,17.5,2.35]],"batl":[[0,19,5.38],[1,20,87],[2,38,2]],"ltp":17.0,"tv":211.33,"id":8204664},{"batb":[[2,2.62,43.65]],"batl":[[1,2.76,12.66]],"ltp":2.68,"tv":2817.43,"id":1042124},{"batb":[[0,6.2,84.02],[1,6,2],[2,5,10]],"ltp":7.0,"tv":1062.25,"id":1042126}]}]}
{"op":"mcm","clk":"995087612","pt":1580555299758,"mc":[{"id":"1.168135749","rc":[{"batb":[[1,17,49.63]],"batl":[[0,18,3.86],[1,19,5],[2,20,87]],"ltp":17.0,"tv":211.33,"id":8204664},{"batb":[[0,2.66,667.59]],"batl":[[2,2.8,8.85]],"ltp":2.68,"tv":2817.43,"id":1042124},{"batb":[[0,6.6,17.9],[1,6.2,84.02],[2,6,2]],"ltp":7.0,"tv":1062.25,"id":1042126}]}]}
{"op":"mcm","clk":"995087668","pt":1580555300029,"mc":[{"id":"1.168135749","rc":[{"batb":[[0,6.6,69.15]],"ltp":7.0,"tv":1062.25,"id":1042126}]}]}
{"op":"mcm","clk":"995090369","pt":1580555314030,"mc":[{"id":"1.168135749","rc":[{"batb":[[2,3.7,233]],"ltp":3.85,"tv":519.68,"id":1042125}]}]}
{"op":"mcm","clk":"995109036","pt":1580555410300,"mc":[{"id":"1.168135749","rc":[{"batb":[[1,6,2],[2,1.02,2]],"ltp":7.0,"tv":1062.25,"id":1042126}]}]}
{"op":"mcm","clk":"995109917","pt":1580555414597,"mc":[{"id":"1.168135749","rc":[{"batb":[[2,5,10]],"ltp":7.0,"tv":1062.25,"id":1042126}]}]}
{"op":"mcm","clk":"995113356","pt":1580555432393,"mc":[{"id":"1.168135749","rc":[{"batb":[[0,6.8,66.64],[1,6.6,69.15],[2,6,2]],"ltp":7.0,"tv":1062.25,"id":1042126}]}]}
{"op":"mcm","clk":"995113803","pt":1580555434812,"mc":[{"id":"1.168135749","rc":[{"batb":[[0,6.8,77.12],[1,6.6,51.25]],"ltp":7.0,"tv":1062.25,"id":1042126}]}]}
{"op":"mcm","clk":"995123991","pt":1580555485302,"mc":[{"id":"1.168135749","rc":[{"batb":[[0,17.5,170.46]],"ltp":17.0,"tv":211.33,"id":8204664}]}]}
{"op":"mcm","clk":"995128773","pt":1580555506622,"mc":[{"id":"1.168135749","rc":[{"batl":[[0,7,37.99],[1,7.2,29.29],[2,7.4,3.65]],"ltp":7.0,"tv":1062.25,"id":1042126}]}]}
{"op":"mcm","clk":"995131842","pt":1580555520629,"mc":[{"id":"1.168135749","rc":[{"batb":[[0,6.8,109.88]],"ltp":7.0,"tv":1062.25,"id":1042126}]}]}
{"op":"mcm","clk":"995154905","pt":1580555631355,"mc":[{"id":"1.168135749","rc":[{"batb":[[1,6,2],[2,1.02,2]],"ltp":7.0,"tv":1062.25,"id":1042126}]}]}
{"op":"mcm","clk":"995161432","pt":1580555663387,"mc":[{"id":"1.168135749","rc":[{"trd":[[3.8,106.8]],"batb":[[0,3.8,77.66]],"ltp":3.8,"tv":561.69,"id":1042125}],"tv":5239.23}]}
{"op":"mcm","clk":"995163527","pt":1580555673794,"mc":[{"id":"1.168135749","rc":[{"trd":[[18,18.24]],"batl":[[0,18,1.54]],"ltp":18.0,"tv":215.98,"id":8204664},{"batb":[[0,11.5,3.65],[1,11,72.35],[2,9.8,76.53]],"ltp":11.0,"tv":192.7,"id":8204665},{"trd":[[11.5,104.09]],"batl":[[0,11.5,2.89]],"ltp":11.5,"tv":401.09,"id":8204663},{"batb":[[0,3.8,88.72]],"ltp":3.8,"tv":561.69,"id":1042125},{"batb":[[0,2.68,15.68],[1,2.66,667.59],[2,2.64,181]],"ltp":2.68,"tv":2817.43,"id":1042124}],"tv":5251.17}]}
{"op":"mcm","clk":"995163552","pt":1580555673919,"mc":[{"id":"1.168135749","rc":[{"batb":[[0,6.8,116.07]],"ltp":7.0,"tv":1062.25,"id":1042126}]}]}
{"op":"mcm","clk":"995163857","pt":1580555675415,"mc":[{"id":"1.168135749","rc":[{"batl":[[0,19,5],[1,20,87],[2,38,2]],"ltp":18.0,"tv":215.98,"id":8204664}]}]}
{"op":"mcm","clk":"995164071","pt":1580555676389,"mc":[{"id":"1.168135749","rc":[{"batl":[[0,18.5,5.72],[1,19,5],[2,20,87]],"ltp":18.0,"tv":215.98,"id":8204664}]}]}
{"op":"mcm","clk":"995168196","pt":1580555697052,"mc":[{"id":"1.168135749","rc":[{"trd":[[6.8,42.01]],"batb":[[0,6.8,95.06]],"ltp":6.8,"tv":1104.26,"id":1042126}],"tv":5293.18}]}
{"op":"mcm","clk":"995169138","pt":1580555701440,"mc":[{"id":"1.168135749","rc":[{"batb":[[2,5,10]],"ltp":6.8,"tv":1104.26,"id":1042126}]}]}
{"op":"mcm","clk":"995188953","pt":1580555798679,"mc":[{"id":"1.168135749","rc":[{"batl":[[2,3,7.87]],"ltp":2.68,"tv":2817.43,"id":1042124}]}]}
{"op":"mcm","clk":"995189247","pt":1580555799646,"mc":[{"id":"1.168135749","rc":[{"batb":[[1,17,47.63]],"ltp":18.0,"tv":215.98,"id":8204664},{"batb":[[1,11,66.89]],"ltp":11.0,"tv":192.7,"id":8204665},{"batb":[[1,2.66,649.47]],"batl":[[1,2.76,20.1]],"ltp":2.68,"tv":2817.43,"id":1042124}]}]}
{"op":"mcm","clk":"995189465","pt":1580555800892,"mc":[{"id":"1.168135749","rc":[{"batb":[[0,17.5,172.46]],"ltp":18.0,"tv":215.98,"id":8204664},{"batb":[[2,10.5,20.22]],"ltp":11.0,"tv":192.7,"id":8204665},{"batb":[[2,2.64,197.67]],"ltp":2.68,"tv":2817.43,"id":1042124}]}]}
{"op":"mcm","clk":"995206384","pt":1580555875564,"mc":[{"id":"1.168135749","rc":[{"batb":[[0,17.5,170.46]],"ltp":18.0,"tv":215.98,"id":8204664},{"batb":[[2,9.8,76.53]],"ltp":11.0,"tv":192.7,"id":8204665},{"batb":[[2,2.64,181]],"batl":[[1,2.76,12.66]],"ltp":2.68,"tv":2817.43,"id":1042124}]}]}
{"op":"mcm","clk":"995206666","pt":1580555876859,"mc":[{"id":"1.168135749","rc":[{"batb":[[1,17,49.63]],"ltp":18.0,"tv":215.98,"id":8204664},{"batb":[[1,11,72.84]],"ltp":11.0,"tv":192.7,"id":8204665},{"batb":[[1,2.66,667.2]],"batl":[[2,2.8,9.1]],"ltp":2.68,"tv":2817.43,"id":1042124}]}]}
{"op":"mcm","clk":"995211497","pt":1580555897734,"mc":[{"id":"1.168135749","rc":[{"batb":[[1,17,47.63]],"batl":[[0,19,5],[1,20,87],[2,38,2]],"ltp":18.0,"tv":215.98,"id":8204664}]}]}
{"op":"mcm","clk":"995211562","pt":1580555897957,"mc":[{"id":"1.168135749","rc":[{"batb":[[1,2.66,649.47]],"batl":[[2,3,7.87]],"ltp":2.68,"tv":2817.43,"id":1042124}]}]}
{"op":"mcm","clk":"995211903","pt":1580555899383,"mc":[{"id":"1.168135749","rc":[{"batl":[[0,19,10.64]],"ltp":18.0,"tv":215.98,"id":8204664},{"batl":[[1,2.76,21.67]],"ltp":2.68,"tv":2817.43,"id":1042124}]}]}
{"op":"mcm","clk":"995212003","pt":1580555899871,"mc":[{"id":"1.168135749","rc":[{"batb":[[0,17.5,172.46]],"ltp":18.0,"tv":215.98,"id":8204664}]}]}
{"op":"mcm","clk":"995262118","pt":1580556148098,"mc":[{"id":"1.168135749","rc":[{"batb":[[2,10.5,100]],"ltp":11.0,"tv":192.7,"id":8204665}]}]}
{"op":"mcm","clk":"995285873","pt":1580556215070,"mc":[{"id":"1.168135749","rc":[{"trd":[[2.68,77.86]],"batb":[[0,2.66,649.47],[1,2.64,181],[2,2.62,62.72]],"batl":[[0,2.68,434.32],[1,2.7,50.65],[2,2.76,21.67]],"ltp":2.68,"tv":2848.79,"id":1042124}],"tv":5324.54}]}
{"op":"mcm","clk":"995286153","pt":1580556216508,"mc":[{"id":"1.168135749","rc":[{"batl":[[0,2.68,450.98]],"ltp":2.68,"tv":2848.79,"id":1042124}]}]}
{"op":"mcm","clk":"995290215","pt":1580556236516,"mc":[{"id":"1.168135749","rc":[{"batb":[[0,17.5,170.46]],"ltp":18.0,"tv":215.98,"id":8204664},{"batb":[[2,2.62,43.65]],"batl":[[2,2.76,12.66]],"ltp":2.68,"tv":2848.79,"id":1042124}]}]}
{"op":"mcm","clk":"995290440","pt":1580556237612,"mc":[{"id":"1.168135749","rc":[{"batb":[[1,17,49.63]],"ltp":18.0,"tv":215.98,"id":8204664},{"batb":[[0,2.66,667.2]],"ltp":2.68,"tv":2848.79,"id":1042124}]}]}
{"op":"mcm","clk":"995457380","pt":1580557033598,"mc":[{"id":"1.168135749","rc":[{"batb":[[1,17,47.63]],"ltp":18.0,"tv":215.98,"id":8204664},{"batb":[[0,2.66,649.47]],"ltp":2.68,"tv":2848.79,"id":1042124}]}]}
{"op":"mcm","clk":"995457698","pt":1580557035072,"mc":[{"id":"1.168135749","rc":[{"batb":[[0,17.5,172.46]],"ltp":18.0,"tv":215.98,"id":8204664},{"batb":[[2,2.62,62.72]],"batl":[[2,2.76,21.67]],"ltp":2.68,"tv":2848.79,"id":1042124}]}]}
{"op":"mcm","clk":"995489053","pt":1580557135182,"mc":[{"id":"1.168135749","rc":[{"trd":[[3.8,111.87]],"batb":[[0,3.8,86.18]],"ltp":3.8,"tv":566.76,"id":1042125},{"trd":[[2.66,400.05]],"batb":[[0,2.66,642.37]],"ltp":2.66,"tv":2862.97,"id":1042124}],"tv":5343.79}]}
{"op":"mcm","clk":"995572526","pt":1580557563518,"mc":[{"id":"1.168135749","rc":[{"trd":[[2.66,1412.33]],"batb":[[0,2.66,136.23]],"ltp":2.66,"tv":3875.26,"id":1042124}],"tv":6356.08}]}
{"op":"mcm","clk":"995664568","pt":1580558052978,"mc":[{"id":"1.168135749","rc":[{"trd":[[2.66,1665.4]],"batb":[[0,2.66,9.7]],"ltp":2.66,"tv":4128.32,"id":1042124}],"tv":6609.14}]}
{"op":"mcm","clk":"995687295","pt":1580558201343,"mc":[{"id":"1.168135749","rc":[{"batl":[[0,12,1.69],[1,12.5,215.5],[2,17,2.52]],"ltp":11.0,"tv":192.7,"id":8204665},{"batl":[[0,3.85,3.38],[1,3.9,25.33],[2,3.95,48.94]],"ltp":3.8,"tv":566.76,"id":1042125}]}]}
{"op":"mcm","clk":"995759946","pt":1580558678730,"mc":[{"id":"1.168135749","rc":[{"trd":[[11.5,114.26]],"batb":[[0,11,73.11],[1,10.5,100],[2,9.8,76.53]],"ltp":11.5,"tv":199.44,"id":8204665}],"tv":6615.89}]}
{"op":"mcm","clk":"995860831","pt":1580559171968,"mc":[{"id":"1.168135749","rc":[{"trd":[[19,0.91]],"batl":[[0,19,9.73]],"ltp":19.0,"tv":216.89,"id":8204664},{"trd":[[12,22.28]],"batl":[[0,12.5,215.75],[1,17,2.52],[2,17,0]],"ltp":12.0,"tv":200.89,"id":8204665},{"trd":[[11.5,105.59]],"batl":[[0,11.5,1.39]],"ltp":11.5,"tv":402.59,"id":8204663},{"trd":[[3.8,288.79]],"batb":[[0,3.75,31.09],[1,3.7,233],[2,3.65,3]],"ltp":3.8,"tv":743.69,"id":1042125},{"trd":[[2.68,84.33]],"batl":[[0,2.68,444.51]],"ltp":2.68,"tv":4134.79,"id":1042124},{"trd":[[7,330.21]],"batl":[[0,7,35.52]],"ltp":7.0,"tv":1106.73,"id":1042126}],"tv":6805.61}]}
{"op":"mcm","clk":"995863269","pt":1580559183800,"mc":[{"id":"1.168135749","rc":[{"batb":[[0,11,52.06]],"ltp":11.5,"tv":402.59,"id":8204663},{"batb":[[0,3.75,43.4]],"ltp":3.8,"tv":743.69,"id":1042125},{"batb":[[1,2.64,198.5]],"ltp":2.68,"tv":4134.79,"id":1042124}]}]}
{"op":"mcm","clk":"995863297","pt":1580559183867,"mc":[{"id":"1.168135749","rc":[{"batb":[[0,6.8,101.86]],"ltp":7.0,"tv":1106.73,"id":1042126}]}]}
{"op":"mcm","clk":"995864574","pt":1580559190750,"mc":[{"id":"1.168135749","rc":[{"trd":[[2.68,168.78]],"batl":[[0,2.68,402.26]],"ltp":2.68,"tv":4219.25,"id":1042124}],"tv":6890.07}]}
{"op":"mcm","clk":"995875238","pt":1580559245330,"mc":[{"id":"1.168135749","rc":[{"batb":[[0,3.8,252.16],[1,3.75,43.4],[2,3.7,233]],"ltp":3.8,"tv":743.69,"id":1042125}]}]}
{"op":"mcm","clk":"995876327","pt":1580559250731,"mc":[{"id":"1.168135749","rc":[{"batb":[[1,3.75,31.09]],"ltp":3.8,"tv":743.69,"id":1042125}]}]}
{"op":"mcm","clk":"995879351","pt":1580559265968,"mc":[{"id":"1.168135749","rc":[{"batb":[[0,3.8,264.32]],"ltp":3.8,"tv":743.69,"id":1042125}]}]}
{"op":"mcm","clk":"995906368","pt":1580559412309,"mc":[{"id":"1.168135749","rc":[{"trd":[[2.66,1677.4]],"batb":[[0,2.66,3.7]],"ltp":2.66,"tv":4231.25,"id":1042124}],"tv":6902.06}]}
{"op":"mcm","clk":"995908461","pt":1580559424493,"mc":[{"id":"1.168135749","rc":[{"trd":[[3.85,85.45]],"batb":[[0,3.85,15.87],[1,3.8,264.32],[2,3.75,31.09]],"batl":[[0,3.9,25.33],[1,3.95,48.94],[2,4.2,3.93]],"ltp":3.85,"tv":750.44,"id":1042125}],"tv":6908.81}]}
{"op":"mcm","clk":"995911658","pt":1580559442258,"mc":[{"id":"1.168135749","rc":[{"batl":[[0,3.9,65.33]],"ltp":3.85,"tv":750.44,"id":1042125}]}]}
{"op":"mcm","clk":"996056393","pt":1580560202950,"mc":[{"id":"1.168135749","rc":[{"trd":[[6.8,63.33]],"batb":[[0,6.8,91.2]],"ltp":6.8,"tv":1128.05,"id":1042126}],"tv":6930.14}]}
{"op":"mcm","clk":"996059128","pt":1580560217455,"mc":[{"id":"1.168135749","rc":[{"trd":[[3.9,31.75]],"batb":[[0,3.8,264.32],[1,3.75,31.09],[2,3.7,233]],"batl":[[0,3.9,49.45]],"ltp":3.9,"tv":782.18,"id":1042125}],"tv":6961.88}]}
{"op":"mcm","clk":"996061192","pt":1580560229316,"mc":[{"id":"1.168135749","rc":[{"batl":[[2,4.1,42]],"ltp":3.9,"tv":782.18,"id":1042125}]}]}
{"op":"mcm","clk":"996064325","pt":1580560247295,"mc":[{"id":"1.168135749","rc":[{"trd":[[3.8,298.79]],"batb":[[0,3.8,259.32]],"ltp":3.8,"tv":792.18,"id":1042125}],"tv":6971.88}]}
{"op":"mcm","clk":"996066022","pt":1580560257134,"mc":[{"id":"1.168135749","rc":[{"batl":[[2,7.4,21.29]],"ltp":6.8,"tv":1128.05,"id":1042126}]}]}
{"op":"mcm","clk":"996066958","pt":1580560262917,"mc":[{"id":"1.168135749","rc":[{"trd":[[11,281.63]],"batb":[[0,11,42.93]],"ltp":11.0,"tv":420.84,"id":8204663}],"tv":6990.13}]}
{"op":"mcm","clk":"996068193","pt":1580560269752,"mc":[{"id":"1.168135749","rc":[{"trd":[[3.9,71.26]],"batl":[[0,3.9,29.69]],"ltp":3.9,"tv":831.7,"id":1042125}],"tv":7029.64}]}
{"op":"mcm","clk":"996069339","pt":1580560276265,"mc":[{"id":"1.168135749","rc":[{"trd":[[11,70.55],[11.5,114.81]],"batb":[[0,11,67.04]],"ltp":11.0,"tv":213.04,"id":8204665}],"tv":7041.8}]}
{"op":"mcm","clk":"996069786","pt":1580560278748,"mc":[{"id":"1.168135749","rc":[{"trd":[[3.9,130.61]],"batb":[[0,3.9,4.78],[1,3.8,259.32],[2,3.75,31.09]],"batl":[[0,3.95,48.94],[1,4.1,42],[2,4.2,3.93]],"ltp":3.9,"tv":891.05,"id":1042125}],"tv":7101.15}]}
{"op":"mcm","clk":"996071261","pt":1580560286150,"mc":[{"id":"1.168135749","rc":[{"batb":[[0,11,71.24]],"ltp":11.0,"tv":213.04,"id":8204665},{"batb":[[1,3.8,247.16]],"ltp":3.9,"tv":891.05,"id":1042125}]}]}
{"op":"mcm","clk":"996071439","pt":1580560287075,"mc":[{"id":"1.168135749","rc":[{"batl":[[0,12.5,213.23]],"ltp":11.0,"tv":213.04,"id":8204665}]}]}
{"op":"mcm","clk":"996072322","pt":1580560292102,"mc":[{"id":"1.168135749","rc":[{"batb":[[0,11.5,1.69],[1,11,71.24],[2,10.5,100]],"ltp":11.0,"tv":213.04,"id":8204665}]}]}
{"op":"mcm","clk":"996074030","pt":1580560301124,"mc":[{"id":"1.168135749","rc":[{"trd":[[11.5,108.37]],"batb":[[0,11,43.23]],"batl":[[0,12.5,118.75],[1,12.5,0]],"ltp":11.5,"tv":423.62,"id":8204663}],"tv":7103.93}]}
{"op":"mcm","clk":"996075060","pt":1580560306547,"mc":[{"id":"1.168135749","rc":[{"batb":[[0,3.9,5.79]],"ltp":3.9,"tv":891.05,"id":1042125}]}]}
{"op":"mcm","clk":"996078085","pt":1580560323054,"mc":[{"id":"1.168135749","rc":[{"batb":[[0,18,1.08],[1,17.5,172.46],[2,17,47.63]],"ltp":19.0,"tv":216.89,"id":8204664}]}]}
{"op":"mcm","clk":"996078955","pt":1580560327282,"mc":[{"id":"1.168135749","rc":[{"batl":[[1,4,50.41],[2,4.1,42]],"ltp":3.9,"tv":891.05,"id":1042125}]}]}
{"op":"mcm","clk":"996082224","pt":1580560344306,"mc":[{"id":"1.168135749","rc":[{"trd":[[11,309.5],[11.5,108.97]],"batb":[[0,11,28.99]],"ltp":11.0,"tv":452.09,"id":8204663}],"tv":7132.4}]}
{"op":"mcm","clk":"996088473","pt":1580560377298,"mc":[{"id":"1.168135749","rc":[{"trd":[[3.9,142.21]],"batb":[[0,3.8,247.16],[1,3.75,31.09],[2,3.7,233]],"batl":[[0,3.9,11.78],[1,3.95,14.49],[2,4,50.41]],"ltp":3.9,"tv":902.64,"id":1042125}],"tv":7143.99}]}
{"op":"mcm","clk":"996088898","pt":1580560379471,"mc":[{"id":"1.168135749","rc":[{"batb":[[0,3.8,259.32]],"ltp":3.9,"tv":902.64,"id":1042125}]}]}
{"op":"mcm","clk":"996090798","pt":1580560389513,"mc":[{"id":"1.168135749","rc":[{"batl":[[0,3.95,14.49],[1,4,50.41],[2,4.1,42]],"ltp":3.9,"tv":902.64,"id":1042125}]}]}
{"op":"mcm","clk":"996091976","pt":1580560396121,"mc":[{"id":"1.168135749","rc":[{"batb":[[0,17.5,172.46],[1,17,47.63],[2,16,23]],"ltp":19.0,"tv":216.89,"id":8204664}]}]}
{"op":"mcm","clk":"996092195","pt":1580560397108,"mc":[{"id":"1.168135749","rc":[{"batb":[[0,11,71.24],[1,10.5,100],[2,9.8,76.53]],"ltp":11.0,"tv":213.04,"id":8204665}]}]}
{"op":"mcm","clk":"996093223","pt":1580560402545,"mc":[{"id":"1.168135749","rc":[{"trd":[[3.8,333.95]],"batb":[[0,3.8,241.74]],"ltp":3.8,"tv":937.8,"id":1042125}],"tv":7179.15}]}
{"op":"mcm","clk":"996094976","pt":1580560412031,"mc":[{"id":"1.168135749","rc":[{"batl":[[0,12,1.62],[1,12.5,118.75]],"ltp":11.0,"tv":452.09,"id":8204663}]}]}
{"op":"mcm","clk":"996099619","pt":1580560436905,"mc":[{"id":"1.168135749","rc":[{"batb":[[1,10.5,40.33],[2,10,10]],"ltp":11.0,"tv":452.09,"id":8204663}]}]}
{"op":"mcm","clk":"996100461","pt":1580560441639,"mc":[{"id":"1.168135749","rc":[{"batb":[[2,1.02,2]],"ltp":11.0,"tv":452.09,"id":8204663}]}]}
{"op":"mcm","clk":"996103149","pt":1580560456249,"mc":[{"id":"1.168135749","rc":[{"batb":[[0,3.85,20.26],[1,3.8,241.74],[2,3.75,31.09]],"ltp":3.8,"tv":937.8,"id":1042125}]}]}
{"op":"mcm","clk":"996103799","pt":1580560459864,"mc":[{"id":"1.168135749","rc":[{"batb":[[1,3.8,229.58]],"ltp":3.8,"tv":937.8,"id":1042125}]}]}
{"op":"mcm","clk":"996106590","pt":1580560475267,"mc":[{"id":"1.168135749","rc":[{"batb":[[0,3.85,32.26]],"ltp":3.8,"tv":937.8,"id":1042125}]}]}
{"op":"mcm","clk":"996110371","pt":1580560496389,"mc":[{"id":"1.168135749","rc":[{"batb":[[0,3.9,20.26],[1,3.85,12],[2,3.8,229.58]],"ltp":3.8,"tv":937.8,"id":1042125}]}]}
{"op":"mcm","clk":"996112503","pt":1580560507843,"mc":[{"id":"1.168135749","rc":[{"batb":[[2,10,57.97]],"ltp":11.0,"tv":452.09,"id":8204663}]}]}
{"op":"mcm","clk":"996115764","pt":1580560525061,"mc":[{"id":"1.168135749","rc":[{"trd":[[3.95,28.97]],"batb":[[0,3.95,5.78]],"batl":[[0,4,50.41],[1,4.1,42],[2,4.2,3.93]],"ltp":3.95,"tv":966.77,"id":1042125}],"tv":7208.11}]}
{"op":"mcm","clk":"996116035","pt":1580560526556,"mc":[{"id":"1.168135749","rc":[{"batl":[[2,2.76,12.66]],"ltp":2.66,"tv":4231.25,"id":1042124}]}]}
{"op":"mcm","clk":"996116232","pt":1580560527561,"mc":[{"id":"1.168135749","rc":[{"trd":[[3.95,40.54]],"batb":[[0,3.85,12],[1,3.8,229.58],[2,3.75,31.09]],"batl":[[0,3.95,1.7],[1,4,50.41],[2,4.1,42]],"ltp":3.95,"tv":978.34,"id":1042125},{"batl":[[2,2.74,8.29]],"ltp":2.66,"tv":4231.25,"id":1042124}],"tv":7219.69}]}
{"op":"mcm","clk":"996116626","pt":1580560529677,"mc":[{"id":"1.168135749","rc":[{"batb":[[0,3.8,229.58],[1,3.75,23.53],[2,3.7,233]],"batl":[[0,4,50.41],[1,4.1,42],[2,4.2,3.93]],"ltp":3.95,"tv":978.34,"id":1042125}]}]}
{"op":"mcm","clk":"996116709","pt":1580560530161,"mc":[{"id":"1.168135749","rc":[{"batl":[[0,4,60.4]],"ltp":3.95,"tv":978.34,"id":1042125}]}]}
{"op":"mcm","clk":"996116951","pt":1580560531539,"mc":[{"id":"1.168135749","rc":[{"batb":[[0,3.8,238.38]],"ltp":3.95,"tv":978.34,"id":1042125}]}]}
{"op":"mcm","clk":"996119434","pt":1580560545211,"mc":[{"id":"1.168135749","rc":[{"batb":[[0,3.8,250.54]],"ltp":3.95,"tv":978.34,"id":1042125}]}]}
{"op":"mcm","clk":"996127067","pt":1580560587970,"mc":[{"id":"1.168135749","rc":[{"batb":[[0,11,4.62],[1,10,57.97],[2,1.02,2]],"ltp":11.0,"tv":452.09,"id":8204663}]}]}
{"op":"mcm","clk":"996127873","pt":1580560592555,"mc":[{"id":"1.168135749","rc":[{"batb":[[1,10,67.97]],"ltp":11.0,"tv":452.09,"id":8204663}]}]}
{"op":"mcm","clk":"996186551","pt":1580560859655,"mc":[{"id":"1.168135749","rc":[{"batb":[[0,17.5,170.46]],"ltp":19.0,"tv":216.89,"id":8204664},{"batl":[[2,2.76,12.66]],"ltp":2.66,"tv":4231.25,"id":1042124}]}]}
{"op":"mcm","clk":"996186655","pt":1580560860199,"mc":[{"id":"1.168135749","rc":[{"batb":[[2,2.62,43.65]],"ltp":2.66,"tv":4231.25,"id":1042124}]}]}
{"op":"mcm","clk":"996186842","pt":1580560861257,"mc":[{"id":"1.168135749","rc":[{"batb":[[1,17,49.63]],"ltp":19.0,"tv":216.89,"id":8204664},{"batb":[[0,2.66,17.55]],"ltp":2.66,"tv":4231.25,"id":1042124}]}]}
{"op":"mcm","clk":"996187501","pt":1580560864963,"mc":[{"id":"1.168135749","rc":[{"batb":[[1,17,51.63]],"ltp":19.0,"tv":216.89,"id":8204664},{"batb":[[0,2.66,31.4]],"ltp":2.66,"tv":4231.25,"id":1042124}]}]}
{"op":"mcm","clk":"996187807","pt":1580560866558,"mc":[{"id":"1.168135749","rc":[{"batb":[[1,17,47.63]],"ltp":19.0,"tv":216.89,"id":8204664}]}]}
{"op":"mcm","clk":"996187871","pt":1580560866885,"mc":[{"id":"1.168135749","rc":[{"batb":[[0,2.66,3.7]],"ltp":2.66,"tv":4231.25,"id":1042124}]}]}
{"op":"mcm","clk":"996188168","pt":1580560868567,"mc":[{"id":"1.168135749","rc":[{"batb":[[1,17,49.63]],"ltp":19.0,"tv":216.89,"id":8204664},{"batb":[[0,2.66,17.55]],"ltp":2.66,"tv":4231.25,"id":1042124}]}]}
{"op":"mcm","clk":"996206686","pt":1580560966718,"mc":[{"id":"1.168135749","rc":[{"trd":[[2.68,243.46]],"batl":[[0,2.68,364.9]],"ltp":2.68,"tv":4305.93,"id":1042124}],"tv":7294.37}]}
{"op":"mcm","clk":"996219583","pt":1580561032710,"mc":[{"id":"1.168135749","rc":[{"batb":[[1,17,47.63]],"ltp":19.0,"tv":216.89,"id":8204664}]}]}
{"op":"mcm","clk":"996219788","pt":1580561033689,"mc":[{"id":"1.168135749","rc":[{"batl":[[2,2.74,9.04]],"ltp":2.68,"tv":4305.93,"id":1042124}]}]}
{"op":"mcm","clk":"996219916","pt":1580561034414,"mc":[{"id":"1.168135749","rc":[{"batb":[[0,2.66,3.7]],"ltp":2.68,"tv":4305.93,"id":1042124}]}]}
{"op":"mcm","clk":"996220164","pt":1580561035676,"mc":[{"id":"1.168135749","rc":[{"batb":[[0,17.5,172.46]],"ltp":19.0,"tv":216.89,"id":8204664}]}]}
{"op":"mcm","clk":"996220458","pt":1580561037191,"mc":[{"id":"1.168135749","rc":[{"batb":[[2,2.62,58.7]],"ltp":2.68,"tv":4305.93,"id":1042124}]}]}
{"op":"mcm","clk":"996277631","pt":1580561329345,"mc":[{"id":"1.168135749","rc":[{"batb":[[2,3.7,264.93]],"batl":[[0,4,67.96]],"ltp":3.95,"tv":978.34,"id":1042125}]}]}
{"op":"mcm","clk":"996283009","pt":1580561359815,"mc":[{"id":"1.168135749","rc":[{"batl":[[1,12.5,116.23]],"ltp":11.0,"tv":452.09,"id":8204663}]}]}
{"op":"mcm","clk":"996283023","pt":1580561359917,"mc":[{"id":"1.168135749","rc":[{"batb":[[1,3.7,264.93],[2,3.65,3]],"ltp":3.95,"tv":978.34,"id":1042125},{"batl":[[2,7.4,3.65]],"ltp":6.8,"tv":1128.05,"id":1042126}]}]}
{"op":"mcm","clk":"996293778","pt":1580561421076,"mc":[{"id":"1.168135749","rc":[{"batb":[[1,3.75,588.37],[2,3.7,264.93]],"ltp":3.95,"tv":978.34,"id":1042125}]}]}
{"op":"mcm","clk":"996306168","pt":1580561492186,"mc":[{"id":"1.168135749","rc":[{"batb":[[0,18,3.79],[1,17.5,172.46],[2,17,47.63]],"ltp":19.0,"tv":216.89,"id":8204664}]}]}
{"op":"mcm","clk":"996314683","pt":1580561541626,"mc":[{"id":"1.168135749","rc":[{"batl":[[2,2.76,12.66]],"ltp":2.68,"tv":4305.93,"id":1042124}]}]}
{"op":"mcm","clk":"996314826","pt":1580561542552,"mc":[{"id":"1.168135749","rc":[{"batb":[[0,11,65.29]],"ltp":11.0,"tv":213.04,"id":8204665},{"batl":[[2,2.76,22.69]],"ltp":2.68,"tv":4305.93,"id":1042124}]}]}
{"op":"mcm","clk":"996315013","pt":1580561543672,"mc":[{"id":"1.168135749","rc":[{"batb":[[1,10.5,119.36]],"ltp":11.0,"tv":213.04,"id":8204665}]}]}
{"op":"mcm","clk":"996332428","pt":1580561582289,"mc":[{"id":"1.168135749","rc":[{"batb":[[0,2.66,25.99]],"ltp":2.68,"tv":4305.93,"id":1042124}]}]}
{"op":"mcm","clk":"996335622","pt":1580561601552,"mc":[{"id":"1.168135749","rc":[{"batb":[[0,2.66,3.7]],"ltp":2.68,"tv":4305.93,"id":1042124}]}]}
{"op":"mcm","clk":"996338005","pt":1580561615528,"mc":[{"id":"1.168135749","rc":[{"trd":[[6.8,245.64]],"batb":[[0,6,2],[1,5,10],[2,1.02,2]],"batl":[[0,6.8,2.59],[1,7,35.52],[2,7.2,29.29]],"ltp":6.8,"tv":1310.36,"id":1042126}],"tv":7476.68}]}
{"op":"mcm","clk":"996338280","pt":1580561617148,"mc":[{"id":"1.168135749","rc":[{"batl":[[0,7,35.52],[1,7.2,29.29],[2,7.4,3.65]],"ltp":6.8,"tv":1310.36,"id":1042126}]}]}
{"op":"mcm","clk":"996338415","pt":1580561617952,"mc":[{"id":"1.168135749","rc":[{"batb":[[2,2.62,43.65]],"ltp":2.68,"tv":4305.93,"id":1042124}]}]}
{"op":"mcm","clk":"996338630","pt":1580561619338,"mc":[{"id":"1.168135749","rc":[{"batb":[[1,2.64,213.27]],"ltp":2.68,"tv":4305.93,"id":1042124},{"batb":[[0,6.2,55.64],[1,6,2],[2,5,10]],"ltp":6.8,"tv":1310.36,"id":1042126}]}]}
{"op":"mcm","clk":"996339931","pt":1580561626645,"mc":[{"id":"1.168135749","rc":[{"batl":[[0,3.9,50.65],[1,4,67.96],[2,4.1,42]],"ltp":3.95,"tv":978.34,"id":1042125}]}]}
{"op":"mcm","clk":"996340179","pt":1580561628051,"mc":[{"id":"1.168135749","rc":[{"batb":[[0,6.2,34.52]],"ltp":6.8,"tv":1310.36,"id":1042126}]}]}
{"op":"mcm","clk":"996340462","pt":1580561629968,"mc":[{"id":"1.168135749","rc":[{"batb":[[0,6.6,10.36],[1,6.2,34.52],[2,6,2]],"ltp":6.8,"tv":1310.36,"id":1042126}]}]}
{"op":"mcm","clk":"996345431","pt":1580561660405,"mc":[{"id":"1.168135749","rc":[{"batb":[[0,11,30.67]],"ltp":11.0,"tv":452.09,"id":8204663},{"batb":[[2,3.7,275.85]],"batl":[[1,3.95,31.93],[2,4,67.96]],"ltp":3.95,"tv":978.34,"id":1042125},{"batb":[[1,6.4,50.41]],"batl":[[2,7.4,37.26]],"ltp":6.8,"tv":1310.36,"id":1042126}]}]}
{"op":"mcm","clk":"996346004","pt":1580561663927,"mc":[{"id":"1.168135749","rc":[{"batb":[[1,10,57.97]],"ltp":11.0,"tv":452.09,"id":8204663}]}]}
{"op":"mcm","clk":"996350510","pt":1580561691533,"mc":[{"id":"1.168135749","rc":[{"batb":[[0,11,40.92]],"batl":[[0,12.5,198.94]],"ltp":11.0,"tv":213.04,"id":8204665},{"batb":[[0,11,4.62],[1,1.02,2],[2,1.01,1.01]],"batl":[[1,12.5,101.95]],"ltp":11.0,"tv":452.09,"id":8204663},{"batb":[[2,3.7,233]],"batl":[[1,4,9.99],[2,4.1,42]],"ltp":3.95,"tv":978.34,"id":1042125},{"batb":[[1,6,2],[2,5,10]],"batl":[[2,7.4,3.65]],"ltp":6.8,"tv":1310.36,"id":1042126}]}]}
{"op":"mcm","clk":"996350971","pt":1580561694238,"mc":[{"id":"1.168135749","rc":[{"batb":[[1,10,10],[2,1.02,2]],"ltp":11.0,"tv":452.09,"id":8204663}]}]}
{"op":"mcm","clk":"996351550","pt":1580561697561,"mc":[{"id":"1.168135749","rc":[{"batb":[[0,6.6,178.47]],"ltp":6.8,"tv":1310.36,"id":1042126}]}]}
{"op":"mcm","clk":"996351821","pt":1580561699322,"mc":[{"id":"1.168135749","rc":[{"batb":[[2,1.02,2]],"ltp":6.8,"tv":1310.36,"id":1042126}]}]}
{"op":"mcm","clk":"996352324","pt":1580561702331,"mc":[{"id":"1.168135749","rc":[{"trd":[[3.9,242.11]],"batl":[[0,4,10.71],[1,4.1,42],[2,4.2,3.93]],"ltp":3.9,"tv":1078.24,"id":1042125}],"tv":7576.58}]}
{"op":"mcm","clk":"996353368","pt":1580561707928,"mc":[{"id":"1.168135749","rc":[{"batb":[[0,11.5,14.28],[1,11,40.92],[2,10.5,119.36]],"batl":[[0,12.5,212.39]],"ltp":11.0,"tv":213.04,"id":8204665},{"batb":[[0,11.5,13.44],[1,11,4.62],[2,10,10]],"batl":[[1,12.5,116.23]],"ltp":11.0,"tv":452.09,"id":8204663},{"batb":[[2,3.7,276.69]],"batl":[[0,3.95,33.49],[1,4,9.99],[2,4.1,42]],"ltp":3.9,"tv":1078.24,"id":1042125},{"batb":[[0,6.6,210.39]],"batl":[[2,7.4,36.42]],"ltp":6.8,"tv":1310.36,"id":1042126}]}]}
{"op":"mcm","clk":"996358370","pt":1580561738029,"mc":[{"id":"1.168135749","rc":[{"batb":[[2,10.5,42.01]],"ltp":11.0,"tv":452.09,"id":8204663},{"batl":[[1,4,58.72]],"ltp":3.9,"tv":1078.24,"id":1042125}]}]}
{"op":"mcm","clk":"996362356","pt":1580561762464,"mc":[{"id":"1.168135749","rc":[{"batb":[[0,2.66,676.12]],"ltp":2.68,"tv":4305.93,"id":1042124}]}]}
{"op":"mcm","clk":"996362889","pt":1580561765313,"mc":[{"id":"1.168135749","rc":[{"batb":[[1,2.64,195.77]],"ltp":2.68,"tv":4305.93,"id":1042124}]}]}
{"op":"mcm","clk":"996364958","pt":1580561777775,"mc":[{"id":"1.168135749","rc":[{"batb":[[0,11,40.92],[1,10.5,119.36],[2,9.8,76.53]],"batl":[[0,12.5,198.94]],"ltp":11.0,"tv":213.04,"id":8204665},{"batb":[[0,11,4.62],[1,10,10],[2,1.02,2]],"batl":[[1,12.5,101.95]],"ltp":11.0,"tv":452.09,"id":8204663},{"batb":[[2,3.7,233]],"batl":[[0,4,10.71],[1,4.1,42],[2,4.2,3.93]],"ltp":3.9,"tv":1078.24,"id":1042125},{"batb":[[0,6.6,178.47]],"batl":[[2,7.4,3.65]],"ltp":6.8,"tv":1310.36,"id":1042126}]}]}
{"op":"mcm","clk":"996365642","pt":1580561781550,"mc":[{"id":"1.168135749","rc":[{"batb":[[0,2.66,693.5]],"ltp":2.68,"tv":4305.93,"id":1042124}]}]}
{"op":"mcm","clk":"996373619","pt":1580561828120,"mc":[{"id":"1.168135749","rc":[{"batb":[[0,11.5,14.28],[1,11,40.92],[2,10.5,119.36]],"batl":[[0,12.5,212.39]],"ltp":11.0,"tv":213.04,"id":8204665},{"batb":[[1,10,67.97]],"batl":[[1,12.5,116.23]],"ltp":11.0,"tv":452.09,"id":8204663},{"batb":[[2,3.7,275.01]],"batl":[[0,4,61.97]],"ltp":3.9,"tv":1078.24,"id":1042125},{"batb":[[0,6.8,16.8],[1,6.6,178.47],[2,6,2]],"batl":[[2,7.4,38.94]],"ltp":6.8,"tv":1310.36,"id":1042126}]}]}
{"op":"mcm","clk":"996373961","pt":1580561830046,"mc":[{"id":"1.168135749","rc":[{"batb":[[1,6.6,168.11]],"ltp":6.8,"tv":1310.36,"id":1042126}]}]}
{"op":"mcm","clk":"996374161","pt":1580561831019,"mc":[{"id":"1.168135749","rc":[{"batb":[[0,6.8,22.66]],"ltp":6.8,"tv":1310.36,"id":1042126}]}]}
{"op":"mcm","clk":"996384761","pt":1580561890767,"mc":[{"id":"1.168135749","rc":[{"batb":[[1,17.5,170.46]],"ltp":19.0,"tv":216.89,"id":8204664},{"batb":[[2,10.5,100]],"ltp":11.0,"tv":213.04,"id":8204665},{"batl":[[2,2.76,12.66]],"ltp":2.68,"tv":4305.93,"id":1042124},{"batl":[[2,7.4,35.29]],"ltp":6.8,"tv":1310.36,"id":1042126}]}]}
{"op":"mcm","clk":"996384867","pt":1580561891421,"mc":[{"id":"1.168135749","rc":[{"batb":[[1,2.64,181]],"ltp":2.68,"tv":4305.93,"id":1042124},{"batl":[[1,7.2,36.57]],"ltp":6.8,"tv":1310.36,"id":1042126}]}]}
{"op":"mcm","clk":"996385070","pt":1580561892558,"mc":[{"id":"1.168135749","rc":[{"batb":[[2,17,49.63]],"ltp":19.0,"tv":216.89,"id":8204664},{"batb":[[1,11,46.75]],"ltp":11.0,"tv":213.04,"id":8204665},{"batb":[[0,2.66,709.31]],"ltp":2.68,"tv":4305.93,"id":1042124}]}]}
{"op":"mcm","clk":"996473715","pt":1580562347619,"mc":[{"id":"1.168135749","rc":[{"batl":[[0,4,606.29]],"ltp":3.9,"tv":1078.24,"id":1042125}]}]}
{"op":"mcm","clk":"996519656","pt":1580562509316,"mc":[{"id":"1.168135749","rc":[{"batb":[[2,17,47.63]],"ltp":19.0,"tv":216.89,"id":8204664},{"batl":[[1,7.2,29.29]],"ltp":6.8,"tv":1310.36,"id":1042126}]}]}
{"op":"mcm","clk":"996519945","pt":1580562510635,"mc":[{"id":"1.168135749","rc":[{"batb":[[1,11,40.92]],"ltp":11.0,"tv":213.04,"id":8204665},{"batb":[[0,2.66,693.5]],"ltp":2.68,"tv":4305.93,"id":1042124}]}]}
{"op":"mcm","clk":"996520230","pt":1580562511798,"mc":[{"id":"1.168135749","rc":[{"batb":[[1,17.5,172.46]],"ltp":19.0,"tv":216.89,"id":8204664},{"batb":[[2,10.5,119.8]],"ltp":11.0,"tv":213.04,"id":8204665},{"batb":[[1,2.64,195.77]],"batl":[[2,2.76,21.31]],"ltp":2.68,"tv":4305.93,"id":1042124},{"batl":[[2,7.4,46.41]],"ltp":6.8,"tv":1310.36,"id":1042126}]}]}
{"op":"mcm","clk":"996531186","pt":1580562561968,"mc":[{"id":"1.168135749","rc":[{"batl":[[0,3.95,34.46],[1,4,605.56],[2,4.1,42]],"ltp":3.9,"tv":1078.24,"id":1042125}]}]}
{"op":"mcm","clk":"996540466","pt":1580562606038,"mc":[{"id":"1.168135749","rc":[{"trd":[[2.68,310.35]],"batl":[[0,2.68,331.44]],"ltp":2.68,"tv":4372.82,"id":1042124}],"tv":7643.47}]}
{"op":"mcm","clk":"996554874","pt":1580562672703,"mc":[{"id":"1.168135749","rc":[{"batl":[[0,3.95,66.38],[1,4,61.24]],"ltp":3.9,"tv":1078.24,"id":1042125}]}]}
{"op":"mcm","clk":"996564870","pt":1580562718491,"mc":[{"id":"1.168135749","rc":[{"trd":[[3.9,243.57],[3.95,49.08]],"batl":[[0,3.95,61.39]],"ltp":3.95,"tv":1088.24,"id":1042125}],"tv":7653.46}]}
{"op":"mcm","clk":"996569040","pt":1580562738897,"mc":[{"id":"1.168135749","rc":[{"batl":[[0,3.9,506],[1,3.95,61.39],[2,4,61.24]],"ltp":3.95,"tv":1088.24,"id":1042125}]}]}
{"op":"mcm","clk":"996571489","pt":1580562751424,"mc":[{"id":"1.168135749","rc":[{"trd":[[19,7.21]],"batl":[[0,19,6.58]],"ltp":19.0,"tv":223.19,"id":8204664},{"batl":[[0,3.9,607.3]],"ltp":3.95,"tv":1088.24,"id":1042125}],"tv":7659.76}]}
{"op":"mcm","clk":"996577528","pt":1580562782126,"mc":[{"id":"1.168135749","rc":[{"batb":[[0,11,40.92],[1,10.5,119.8],[2,9.8,76.53]],"batl":[[0,12.5,198.94]],"ltp":11.0,"tv":213.04,"id":8204665},{"batb":[[1,10,10]],"batl":[[1,12.5,101.95]],"ltp":11.0,"tv":452.09,"id":8204663},{"batb":[[2,3.7,233]],"batl":[[1,3.95,29.46],[2,4,9.99]],"ltp":3.95,"tv":1088.24,"id":1042125},{"batb":[[0,6.8,5.86]],"batl":[[2,7.4,11.12]],"ltp":6.8,"tv":1310.36,"id":1042126}]}]}
{"op":"mcm","clk":"996600567","pt":1580562893841,"mc":[{"id":"1.168135749","rc":[{"batb":[[0,11.5,13.44],[1,11,40.92],[2,10.5,119.8]],"batl":[[0,12.5,213.23]],"ltp":11.0,"tv":213.04,"id":8204665},{"batb":[[1,10.5,42.01],[2,10,10]],"batl":[[1,12.5,115.39]],"ltp":11.0,"tv":452.09,"id":8204663},{"batb":[[2,3.7,275.01]],"batl":[[1,3.95,63.91]],"ltp":3.95,"tv":1088.24,"id":1042125},{"batb":[[0,6.8,23.5]],"batl":[[2,7.4,43.89]],"ltp":6.8,"tv":1310.36,"id":1042126}]}]}
{"op":"mcm","clk":"996650249","pt":1580563134866,"mc":[{"id":"1.168135749","rc":[{"trd":[[2.68,386.87]],"batl":[[0,2.68,293.16]],"ltp":2.68,"tv":4449.34,"id":1042124}],"tv":7736.29}]}
{"op":"mcm","clk":"996665417","pt":1580563209653,"mc":[{"id":"1.168135749","rc":[{"batb":[[1,17.5,170.46]],"ltp":19.0,"tv":223.19,"id":8204664},{"batb":[[2,10.5,100]],"ltp":11.0,"tv":213.04,"id":8204665},{"batl":[[2,2.76,12.66]],"ltp":2.68,"tv":4449.34,"id":1042124},{"batl":[[2,7.4,32.77]],"ltp":6.8,"tv":1310.36,"id":1042126}]}]}
{"op":"mcm","clk":"996665537","pt":1580563210305,"mc":[{"id":"1.168135749","rc":[{"batb":[[1,2.64,181]],"ltp":2.68,"tv":4449.34,"id":1042124}]}]}
{"op":"mcm","clk":"996665761","pt":1580563211423,"mc":[{"id":"1.168135749","rc":[{"batb":[[2,17,49.63]],"ltp":19.0,"tv":223.19,"id":8204664},{"batb":[[1,11,46.75]],"ltp":11.0,"tv":213.04,"id":8204665},{"batb":[[0,2.66,709.31]],"ltp":2.68,"tv":4449.34,"id":1042124},{"batl":[[1,7.2,36.57]],"ltp":6.8,"tv":1310.36,"id":1042126}]}]}
{"op":"mcm","clk":"996673463","pt":1580563246713,"mc":[{"id":"1.168135749","rc":[{"batb":[[2,17,47.63]],"ltp":19.0,"tv":223.19,"id":8204664},{"batb":[[1,11,40.92]],"ltp":11.0,"tv":213.04,"id":8204665}]}]}
{"op":"mcm","clk":"996673601","pt":1580563247321,"mc":[{"id":"1.168135749","rc":[{"batb":[[0,2.66,693.5]],"ltp":2.68,"tv":4449.34,"id":1042124},{"batl":[[1,7.2,29.29]],"ltp":6.8,"tv":1310.36,"id":1042126}]}]}
{"op":"mcm","clk":"996673851","pt":1580563248412,"mc":[{"id":"1.168135749","rc":[{"batb":[[1,17.5,172.46]],"ltp":19.0,"tv":223.19,"id":8204664},{"batb":[[2,10.5,119.8]],"ltp":11.0,"tv":213.04,"id":8204665},{"batb":[[1,2.64,195.77]],"batl":[[2,2.76,21.31]],"ltp":2.68,"tv":4449.34,"id":1042124},{"batl":[[2,7.4,43.89]],"ltp":6.8,"tv":1310.36,"id":1042126}]}]}
{"op":"mcm","clk":"996677312","pt":1580563263784,"mc":[{"id":"1.168135749","rc":[{"batl":[[2,2.76,12.66]],"ltp":2.68,"tv":4449.34,"id":1042124}]}]}
{"op":"mcm","clk":"996677438","pt":1580563264453,"mc":[{"id":"1.168135749","rc":[{"batb":[[2,10.5,100]],"ltp":11.0,"tv":213.04,"id":8204665},{"batb":[[1,2.64,181]],"ltp":2.68,"tv":4449.34,"id":1042124}]}]}
{"op":"mcm","clk":"996677641","pt":1580563265630,"mc":[{"id":"1.168135749","rc":[{"batb":[[1,11,49.31]],"ltp":11.0,"tv":213.04,"id":8204665},{"batb":[[2,2.62,60.73]],"batl":[[2,2.74,7.71]],"ltp":2.68,"tv":4449.34,"id":1042124}]}]}
{"op":"mcm","clk":"996710453","pt":1580563366539,"mc":[{"id":"1.168135749","rc":[{"trd":[[2.68,561.23]],"batl":[[0,2.68,205.98]],"ltp":2.68,"tv":4623.7,"id":1042124}],"tv":7910.64}]}
{"op":"mcm","clk":"996712415","pt":1580563375637,"mc":[{"id":"1.168135749","rc":[{"batb":[[0,11,29.62]],"ltp":11.0,"tv":452.09,"id":8204663}]}]}
{"op":"mcm","clk":"996713243","pt":1580563379497,"mc":[{"id":"1.168135749","rc":[{"batb":[[2,1.02,2]],"ltp":11.0,"tv":452.09,"id":8204663}]}]}
{"op":"mcm","clk":"996721053","pt":1580563415017,"mc":[{"id":"1.168135749","rc":[{"trd":[[2.68,640.77]],"batl":[[0,2.68,166.19]],"ltp":2.68,"tv":4703.23,"id":1042124}],"tv":7990.18}]}
{"op":"mcm","clk":"996727260","pt":1580563446179,"mc":[{"id":"1.168135749","rc":[{"batb":[[0,11.5,13.44],[1,11,29.62],[2,10.5,42.01]],"ltp":11.0,"tv":452.09,"id":8204663}]}]}
{"op":"mcm","clk":"996730227","pt":1580563460204,"mc":[{"id":"1.168135749","rc":[{"batb":[[1,11,74.31]],"ltp":11.0,"tv":213.04,"id":8204665}]}]}
{"op":"mcm","clk":"996734062","pt":1580563479991,"mc":[{"id":"1.168135749","rc":[{"batb":[[1,11,81.31]],"ltp":11.0,"tv":213.04,"id":8204665},{"batb":[[1,11,35.62]],"ltp":11.0,"tv":452.09,"id":8204663}]}]}
{"op":"mcm","clk":"996749031","pt":1580563555919,"mc":[{"id":"1.168135749","rc":[{"batb":[[2,1.02,2]],"ltp":11.0,"tv":452.09,"id":8204663}]}]}
{"op":"mcm","clk":"996749949","pt":1580563560502,"mc":[{"id":"1.168135749","rc":[{"batb":[[2,10,10]],"ltp":11.0,"tv":452.09,"id":8204663}]}]}
{"op":"mcm","clk":"996765386","pt":1580563638387,"mc":[{"id":"1.168135749","rc":[{"batl":[[0,12.5,212.98]],"ltp":11.0,"tv":213.04,"id":8204665}]}]}
{"op":"mcm","clk":"996768283","pt":1580563653708,"mc":[{"id":"1.168135749","rc":[{"batl":[[1,19.5,5],[2,20,87]],"ltp":19.0,"tv":223.19,"id":8204664}]}]}
{"op":"mcm","clk":"996814734","pt":1580563887613,"mc":[{"id":"1.168135749","rc":[{"batb":[[0,3.8,265.73]],"ltp":3.95,"tv":1088.24,"id":1042125}]}]}
{"op":"mcm","clk":"996819422","pt":1580563911922,"mc":[{"id":"1.168135749","rc":[{"trd":[[3.8,342.35]],"batb":[[0,3.8,261.53]],"ltp":3.8,"tv":1096.64,"id":1042125}],"tv":7998.58}]}
{"op":"mcm","clk":"996857633","pt":1580564097828,"mc":[{"id":"1.168135749","rc":[{"batb":[[0,3.8,262.03]],"ltp":3.8,"tv":1096.64,"id":1042125}]}]}
{"op":"mcm","clk":"996908342","pt":1580564292025,"mc":[{"id":"1.168135749","rc":[{"batb":[[0,3.85,15.7],[1,3.8,246.33],[2,3.75,588.37]],"ltp":3.8,"tv":1096.64,"id":1042125}]}]}
{"op":"mcm","clk":"997004760","pt":1580564747776,"mc":[{"id":"1.168135749","rc":[{"trd":[[2.68,650.77]],"batl":[[0,2.68,161.19]],"ltp":2.68,"tv":4713.23,"id":1042124}],"tv":8008.58}]}
{"op":"mcm","clk":"997007606","pt":1580564762686,"mc":[{"id":"1.168135749","rc":[{"trd":[[2.68,735.05]],"batl":[[0,2.68,119.03]],"ltp":2.68,"tv":4797.52,"id":1042124}],"tv":8092.86}]}
{"op":"mcm","clk":"997036504","pt":1580564920737,"mc":[{"id":"1.168135749","rc":[{"batb":[[0,6.8,443.77]],"ltp":6.8,"tv":1310.36,"id":1042126}]}]}
{"op":"mcm","clk":"997037336","pt":1580564925755,"mc":[{"id":"1.168135749","rc":[{"batb":[[1,6,2],[2,1.02,2]],"ltp":6.8,"tv":1310.36,"id":1042126}]}]}
{"op":"mcm","clk":"997084119","pt":1580565200830,"mc":[{"id":"1.168135749","rc":[{"batl":[[0,12,85.67]],"ltp":11.0,"tv":452.09,"id":8204663}]}]}
{"op":"mcm","clk":"997087732","pt":1580565224253,"mc":[{"id":"1.168135749","rc":[{"batb":[[0,6.8,275.66]],"ltp":6.8,"tv":1310.36,"id":1042126}]}]}
{"op":"mcm","clk":"997144981","pt":1580565582347,"mc":[{"id":"1.168135749","rc":[{"trd":[[6.8,364.88]],"batb":[[0,6.8,216.02]],"ltp":6.8,"tv":1429.6,"id":1042126}],"tv":8212.1}]}
{"op":"mcm","clk":"997145399","pt":1580565584744,"mc":[{"id":"1.168135749","rc":[{"batl":[[2,2.76,12.66]],"ltp":2.68,"tv":4797.52,"id":1042124},{"batl":[[2,7.4,32.77]],"ltp":6.8,"tv":1429.6,"id":1042126}]}]}
{"op":"mcm","clk":"997145516","pt":1580565585361,"mc":[{"id":"1.168135749","rc":[{"batb":[[0,6.8,219.54]],"ltp":6.8,"tv":1429.6,"id":1042126}]}]}
{"op":"mcm","clk":"997145703","pt":1580565586418,"mc":[{"id":"1.168135749","rc":[{"batl":[[2,2.76,22.19]],"ltp":2.68,"tv":4797.52,"id":1042124},{"batl":[[1,7.2,35.97]],"ltp":6.8,"tv":1429.6,"id":1042126}]}]}
{"op":"mcm","clk":"997157263","pt":1580565649164,"mc":[{"id":"1.168135749","rc":[{"batb":[[2,3.75,611.89]],"ltp":3.8,"tv":1096.64,"id":1042125},{"batb":[[1,6.6,26.05],[2,6,2]],"batl":[[1,7.2,62.86]],"ltp":6.8,"tv":1429.6,"id":1042126}]}]}
{"op":"mcm","clk":"997162848","pt":1580565679508,"mc":[{"id":"1.168135749","rc":[{"batl":[[2,7.8,12.66]],"ltp":6.8,"tv":1429.6,"id":1042126}]}]}
{"op":"mcm","clk":"997242140","pt":1580566069780,"mc":[{"id":"1.168135749","rc":[{"batb":[[1,3.8,286.33]],"ltp":3.8,"tv":1096.64,"id":1042125}]}]}
{"op":"mcm","clk":"997252963","pt":1580566116687,"mc":[{"id":"1.168135749","rc":[{"batb":[[1,17.5,170.46]],"ltp":19.0,"tv":223.19,"id":8204664},{"batl":[[2,2.76,12.66]],"ltp":2.68,"tv":4797.52,"id":1042124}]}]}
{"op":"mcm","clk":"997253137","pt":1580566117374,"mc":[{"id":"1.168135749","rc":[{"batb":[[2,2.62,43.65]],"ltp":2.68,"tv":4797.52,"id":1042124}]}]}
{"op":"mcm","clk":"997253385","pt":1580566118476,"mc":[{"id":"1.168135749","rc":[{"batb":[[2,17,49.63]],"ltp":19.0,"tv":223.19,"id":8204664},{"batb":[[0,2.66,710.45]],"ltp":2.68,"tv":4797.52,"id":1042124}]}]}
{"op":"mcm","clk":"997371141","pt":1580566566337,"mc":[{"id":"1.168135749","rc":[{"trd":[[3.85,116.87]],"batb":[[0,3.8,286.33],[1,3.75,611.89],[2,3.7,233]],"batl":[[0,3.85,34.28],[1,3.9,607.3],[2,3.95,63.91]],"ltp":3.85,"tv":1128.06,"id":1042125}],"tv":8243.52}]}
{"op":"mcm","clk":"997386653","pt":1580566628135,"mc":[{"id":"1.168135749","rc":[{"trd":[[3.8,410.91]],"batb":[[0,3.8,252.05]],"batl":[[0,3.9,607.3],[1,3.95,63.91],[2,4,9.99]],"ltp":3.8,"tv":1196.62,"id":1042125}],"tv":8312.08}]}
{"op":"mcm","clk":"997466810","pt":1580566939773,"mc":[{"id":"1.168135749","rc":[{"trd":[[3.8,430.91]],"batb":[[0,3.8,242.05]],"ltp":3.8,"tv":1216.63,"id":1042125}],"tv":8332.09}]}
{"op":"mcm","clk":"997506187","pt":1580567095643,"mc":[{"id":"1.168135749","rc":[{"batb":[[1,11,45.62],[2,1.02,2]],"ltp":11.0,"tv":452.09,"id":8204663}]}]}
{"op":"mcm","clk":"997514999","pt":1580567129543,"mc":[{"id":"1.168135749","rc":[{"batb":[[2,17,47.63]],"ltp":19.0,"tv":223.19,"id":8204664},{"batb":[[0,2.66,693.5]],"ltp":2.68,"tv":4797.52,"id":1042124}]}]}
{"op":"mcm","clk":"997515298","pt":1580567130743,"mc":[{"id":"1.168135749","rc":[{"batb":[[1,17.5,172.46]],"ltp":19.0,"tv":223.19,"id":8204664},{"batb":[[2,2.62,61.91]],"batl":[[2,2.76,22.19]],"ltp":2.68,"tv":4797.52,"id":1042124}]}]}
{"op":"mcm","clk":"997516287","pt":1580567135105,"mc":[{"id":"1.168135749","rc":[{"trd":[[2.66,3064.4]],"batb":[[0,2.64,181],[1,2.62,61.91],[2,2.6,266.6]],"batl":[[0,2.66,293.5],[1,2.68,119.03],[2,2.7,50.65]],"ltp":2.66,"tv":6184.51,"id":1042124}],"tv":9719.09}]}
{"op":"mcm","clk":"997560158","pt":1580567316539,"mc":[{"id":"1.168135749","rc":[{"batb":[[0,18.5,162.21],[1,18,3.79],[2,17.5,172.46]],"ltp":19.0,"tv":223.19,"id":8204664},{"batb":[[0,11.5,274.39]],"ltp":11.0,"tv":213.04,"id":8204665},{"batb":[[0,11.5,274.39],[1,11,35.62]],"ltp":11.0,"tv":452.09,"id":8204663},{"batb":[[0,3.85,779.44],[1,3.8,242.05],[2,3.75,611.89]],"ltp":3.8,"tv":1216.63,"id":1042125},{"batb":[[0,2.64,1317.69]],"ltp":2.66,"tv":6184.51,"id":1042124},{"trd":[[7,401.28]],"batb":[[0,7,393.14],[1,6.8,219.54],[2,6.6,26.05]],"batl":[[0,7.2,62.86],[1,7.8,12.66],[2,8,252.75]],"ltp":7.0,"tv":1500.67,"id":1042126}],"tv":9790.15}]}
{"op":"mcm","clk":"997560903","pt":1580567319703,"mc":[{"id":"1.168135749","rc":[{"batb":[[2,17.5,170.11]],"ltp":19.0,"tv":223.19,"id":8204664},{"batb":[[1,11,31.42]],"ltp":11.0,"tv":452.09,"id":8204663},{"batb":[[1,3.8,229.89]],"ltp":3.8,"tv":1216.63,"id":1042125}]}]}
{"op":"mcm","clk":"997564580","pt":1580567335794,"mc":[{"id":"1.168135749","rc":[{"trd":[[19,16.41]],"batl":[[0,19,1.98]],"ltp":19.0,"tv":232.4,"id":8204664},{"batb":[[0,11.5,278.41]],"ltp":11.0,"tv":452.09,"id":8204663}],"tv":9799.36}]}
{"op":"mcm","clk":"997564610","pt":1580567335890,"mc":[{"id":"1.168135749","rc":[{"batb":[[0,3.85,791.44]],"ltp":3.8,"tv":1216.63,"id":1042125}]}]}
{"op":"mcm","clk":"997565020","pt":1580567337600,"mc":[{"id":"1.168135749","rc":[{"batb":[[2,17.5,168.11]],"ltp":19.0,"tv":232.4,"id":8204664}]}]}
{"op":"mcm","clk":"997565198","pt":1580567338402,"mc":[{"id":"1.168135749","rc":[{"batl":[[0,19.5,5],[1,20,87],[2,38,2]],"ltp":19.0,"tv":232.4,"id":8204664}]}]}
{"op":"mcm","clk":"997565382","pt":1580567339073,"mc":[{"id":"1.168135749","rc":[{"batb":[[1,18,5.79]],"ltp":19.0,"tv":232.4,"id":8204664}]}]}
{"op":"mcm","clk":"997565635","pt":1580567340002,"mc":[{"id":"1.168135749","rc":[{"batl":[[0,19,3.34],[1,19.5,5],[2,20,87]],"ltp":19.0,"tv":232.4,"id":8204664}]}]}
{"op":"mcm","clk":"997626652","pt":1580567589911,"mc":[{"id":"1.168135749","rc":[{"trd":[[2.64,2179.61]],"batb":[[0,2.64,1312.69]],"ltp":2.64,"tv":6194.51,"id":1042124}],"tv":9809.36}]}
{"op":"mcm","clk":"997664500","pt":1580567737646,"mc":[{"id":"1.168135749","rc":[{"batb":[[1,18,3.79]],"ltp":19.0,"tv":232.4,"id":8204664},{"batb":[[1,11,72.92]],"ltp":11.0,"tv":213.04,"id":8204665}]}]}
{"op":"mcm","clk":"997664573","pt":1580567737919,"mc":[{"id":"1.168135749","rc":[{"batb":[[1,2.62,43.65]],"ltp":2.64,"tv":6194.51,"id":1042124}]}]}
{"op":"mcm","clk":"997664826","pt":1580567738916,"mc":[{"id":"1.168135749","rc":[{"batb":[[2,17.5,170.41]],"ltp":19.0,"tv":232.4,"id":8204664},{"batb":[[2,10.5,119.89]],"ltp":11.0,"tv":213.04,"id":8204665},{"batb":[[0,2.64,1327.88]],"ltp":2.64,"tv":6194.51,"id":1042124}]}]}
{"op":"mcm","clk":"997673960","pt":1580567775454,"mc":[{"id":"1.168135749","rc":[{"batb":[[2,10.5,100]],"ltp":11.0,"tv":213.04,"id":8204665}]}]}
{"op":"mcm","clk":"997674109","pt":1580567776081,"mc":[{"id":"1.168135749","rc":[{"batb":[[1,11,78.77]],"ltp":11.0,"tv":213.04,"id":8204665}]}]}
{"op":"mcm","clk":"997791426","pt":1580568253242,"mc":[{"id":"1.168135749","rc":[{"batb":[[1,17.5,170.41],[2,17,47.63]],"ltp":19.0,"tv":232.4,"id":8204664}]}]}
{"op":"mcm","clk":"997796731","pt":1580568274620,"mc":[{"id":"1.168135749","rc":[{"trd":[[19,23.09]],"batb":[[0,18.5,162.27]],"batl":[[0,19.5,5],[1,20,87],[2,38,2]],"ltp":19.0,"tv":239.07,"id":8204664}],"tv":9816.04}]}
{"op":"mcm","clk":"997797491","pt":1580568277813,"mc":[{"id":"1.168135749","rc":[{"trd":[[19,23.23]],"batb":[[0,18.5,162.21]],"batl":[[0,19,3.66],[1,19.5,5],[2,20,87]],"ltp":19.0,"tv":239.21,"id":8204664}],"tv":9816.18}]}
{"op":"mcm","clk":"997797766","pt":1580568278819,"mc":[{"id":"1.168135749","rc":[{"batl":[[0,19.5,5],[1,20,87],[2,38,2]],"ltp":19.0,"tv":239.21,"id":8204664}]}]}
{"op":"mcm","clk":"997798178","pt":1580568280576,"mc":[{"id":"1.168135749","rc":[{"batl":[[0,19,3.69],[1,19.5,5],[2,20,87]],"ltp":19.0,"tv":239.21,"id":8204664}]}]}
{"op":"mcm","clk":"997809091","pt":1580568324376,"mc":[{"id":"1.168135749","rc":[{"trd":[[3.85,158.87]],"batb":[[0,3.85,770.44]],"ltp":3.85,"tv":1258.62,"id":1042125},{"trd":[[2.64,2237.61]],"batb":[[0,2.64,1298.88]],"ltp":2.64,"tv":6252.51,"id":1042124}],"tv":9916.17}]}
{"op":"mcm","clk":"997939619","pt":1580568893862,"mc":[{"id":"1.168135749","rc":[{"trd":[[2.66,3144.53]],"batl":[[0,2.66,253.41]],"ltp":2.66,"tv":6332.65,"id":1042124}],"tv":9996.31}]}
{"op":"mcm","clk":"997975019","pt":1580569049656,"mc":[{"id":"1.168135749","rc":[{"trd":[[3.9,295.59]],"batl":[[0,3.9,581.29]],"ltp":3.9,"tv":1310.65,"id":1042125}],"tv":10048.34}]}
{"op":"mcm","clk":"998043453","pt":1580569343077,"mc":[{"id":"1.168135749","rc":[{"trd":[[2.66,3161.34]],"batl":[[0,2.66,245.01]],"ltp":2.66,"tv":6349.46,"id":1042124}],"tv":10065.14}]}
{"op":"mcm","clk":"998048102","pt":1580569362482,"mc":[{"id":"1.168135749","rc":[{"trd":[[2.66,3169.74]],"batl":[[0,2.66,240.81]],"ltp":2.66,"tv":6357.86,"id":1042124}],"tv":10073.55}]}
{"op":"mcm","clk":"998079624","pt":1580569486305,"mc":[{"id":"1.168135749","rc":[{"trd":[[2.66,3186.54]],"batl":[[0,2.66,232.41]],"ltp":2.66,"tv":6374.66,"id":1042124}],"tv":10090.35}]}
{"op":"mcm","clk":"998102605","pt":1580569574287,"mc":[{"id":"1.168135749","rc":[{"trd":[[2.66,3205.8]],"batl":[[0,2.66,222.78]],"ltp":2.66,"tv":6393.92,"id":1042124}],"tv":10109.61}]}
{"op":"mcm","clk":"998134199","pt":1580569690944,"mc":[{"id":"1.168135749","rc":[{"trd":[[2.66,3555.88]],"batl":[[0,2.66,47.74]],"ltp":2.66,"tv":6744.0,"id":1042124}],"tv":10459.68}]}
{"op":"mcm","clk":"998241716","pt":1580570094286,"mc":[{"id":"1.168135749","rc":[{"trd":[[3.9,481.7]],"batl":[[0,3.9,488.28]],"ltp":3.9,"tv":1496.76,"id":1042125}],"tv":10645.79}]}
{"op":"mcm","clk":"998309943","pt":1580570361008,"mc":[{"id":"1.168135749","rc":[{"batl":[[1,7.4,1.68],[2,7.8,12.66]],"ltp":7.0,"tv":1500.67,"id":1042126}]}]}
{"op":"mcm","clk":"998357913","pt":1580570547979,"mc":[{"id":"1.168135749","rc":[{"trd":[[7,471.6]],"batb":[[0,7,357.97]],"ltp":7.0,"tv":1570.98,"id":1042126}],"tv":10716.11}]}
{"op":"mcm","clk":"998428993","pt":1580570812919,"mc":[{"id":"1.168135749","rc":[{"trd":[[2.64,2437.61]],"batb":[[0,2.64,1198.88]],"ltp":2.64,"tv":6944.0,"id":1042124}],"tv":10916.11}]}
{"op":"mcm","clk":"998477533","pt":1580570993328,"mc":[{"id":"1.168135749","rc":[{"trd":[[3.9,667.8]],"batl":[[0,3.9,395.28]],"ltp":3.9,"tv":1682.86,"id":1042125}],"tv":11102.21}]}
{"op":"mcm","clk":"998635698","pt":1580571569804,"mc":[{"id":"1.168135749","rc":[{"trd":[[2.66,3626.82]],"batl":[[0,2.66,12.25]],"ltp":2.66,"tv":7014.94,"id":1042124}],"tv":11173.16}]}
{"op":"mcm","clk":"998744929","pt":1580571982582,"mc":[{"id":"1.168135749","rc":[{"trd":[[3.85,358.87]],"batb":[[0,3.85,670.44]],"ltp":3.85,"tv":1882.86,"id":1042125}],"tv":11373.16}]}
{"op":"mcm","clk":"998773495","pt":1580572100141,"mc":[{"id":"1.168135749","rc":[{"trd":[[3.85,394.02]],"batb":[[0,3.85,652.86]],"ltp":3.85,"tv":1918.02,"id":1042125}],"tv":11408.31}]}
{"op":"mcm","clk":"998785696","pt":1580572152780,"mc":[{"id":"1.168135749","rc":[{"trd":[[3.9,1040.01]],"batl":[[0,3.9,209.27]],"ltp":3.9,"tv":2290.23,"id":1042125}],"tv":11780.52}]}
{"op":"mcm","clk":"998789160","pt":1580572168799,"mc":[{"id":"1.168135749","rc":[{"trd":[[3.9,1086.53]],"batl":[[0,3.9,186.02]],"ltp":3.9,"tv":2336.75,"id":1042125}],"tv":11827.04}]}
{"op":"mcm","clk":"998942801","pt":1580572932202,"mc":[{"id":"1.168135749","rc":[{"batb":[[1,17.5,2.3]],"ltp":19.0,"tv":239.21,"id":8204664},{"batl":[[0,12,1.62]],"ltp":11.0,"tv":452.09,"id":8204663},{"batb":[[1,3.8,48.8],[2,3.75,23.53]],"ltp":3.9,"tv":2336.75,"id":1042125},{"batb":[[1,6.8,3.52]],"ltp":7.0,"tv":1570.98,"id":1042126}]}]}
{"op":"mcm","clk":"999244295","pt":1580574062272,"mc":[{"id":"1.168135749","rc":[{"trd":[[2.64,2442.73]],"batb":[[0,2.64,1196.32]],"ltp":2.64,"tv":7020.06,"id":1042124}],"tv":11832.16}]}
{"op":"mcm","clk":"999252557","pt":1580574092303,"mc":[{"id":"1.168135749","rc":[{"trd":[[3.85,402.41]],"batb":[[0,3.85,648.66]],"ltp":3.85,"tv":2345.14,"id":1042125}],"tv":11840.55}]}
{"op":"mcm","clk":"999304573","pt":1580574289098,"mc":[{"id":"1.168135749","rc":[{"trd":[[2.64,2611.03]],"batb":[[0,2.64,1112.12]],"ltp":2.64,"tv":7188.37,"id":1042124}],"tv":12008.86}]}
{"op":"mcm","clk":"999309215","pt":1580574306231,"mc":[{"id":"1.168135749","rc":[{"trd":[[3.85,503.77]],"batb":[[0,3.85,597.96]],"ltp":3.85,"tv":2446.5,"id":1042125}],"tv":12110.21}]}
{"op":"mcm","clk":"999637664","pt":1580575660467,"mc":[{"id":"1.168135749","rc":[{"trd":[[3.85,524.42]],"batb":[[0,3.85,587.63]],"ltp":3.85,"tv":2467.14,"id":1042125}],"tv":12130.86}]}
{"op":"mcm","clk":"999656828","pt":1580575772804,"mc":[{"id":"1.168135749","rc":[{"batb":[[1,17,47.63],[2,16,23]],"ltp":19.0,"tv":239.21,"id":8204664}]}]}
{"op":"mcm","clk":"999656895","pt":1580575773224,"mc":[{"id":"1.168135749","rc":[{"batb":[[0,2.64,1096.93]],"ltp":2.64,"tv":7188.37,"id":1042124}]}]}
{"op":"mcm","clk":"999657118","pt":1580575774692,"mc":[{"id":"1.168135749","rc":[{"batb":[[1,18,2.62],[2,17,47.63]],"ltp":19.0,"tv":239.21,"id":8204664},{"batb":[[1,2.62,60.49]],"ltp":2.64,"tv":7188.37,"id":1042124}]}]}
{"op":"mcm","clk":"999706568","pt":1580576077510,"mc":[{"id":"1.168135749","rc":[{"batb":[[1,17,47.63],[2,16,23]],"ltp":19.0,"tv":239.21,"id":8204664},{"batb":[[1,2.62,43.65]],"ltp":2.64,"tv":7188.37,"id":1042124}]}]}
{"op":"mcm","clk":"999706800","pt":1580576079190,"mc":[{"id":"1.168135749","rc":[{"batb":[[1,17.5,2.87],[2,17,47.63]],"ltp":19.0,"tv":239.21,"id":8204664},{"trd":[[2.66,3651.32]],"batb":[[0,2.66,3.32],[1,2.64,1096.93],[2,2.62,43.65]],"batl":[[0,2.68,119.03],[1,2.7,50.65],[2,2.76,12.66]],"ltp":2.66,"tv":7212.87,"id":1042124}],"tv":12155.36}]}
{"op":"mcm","clk":"999707078","pt":1580576080907,"mc":[{"id":"1.168135749","rc":[{"batb":[[0,2.64,1096.93],[1,2.62,43.65],[2,2.6,266.6]],"ltp":2.66,"tv":7212.87,"id":1042124}]}]}
{"op":"mcm","clk":"999707244","pt":1580576082015,"mc":[{"id":"1.168135749","rc":[{"batb":[[0,2.64,1113.94]],"ltp":2.66,"tv":7212.87,"id":1042124}]}]}
{"op":"mcm","clk":"999732364","pt":1580576275240,"mc":[{"id":"1.168135749","rc":[{"trd":[[2.64,2712.39]],"batb":[[0,2.64,1063.24]],"ltp":2.64,"tv":7314.22,"id":1042124}],"tv":12256.72}]}
{"op":"mcm","clk":"999780320","pt":1580576633501,"mc":[{"id":"1.168135749","rc":[{"batb":[[1,18,55.56],[2,17.5,2.87]],"ltp":19.0,"tv":239.21,"id":8204664},{"batb":[[1,11,169.68]],"ltp":11.0,"tv":213.04,"id":8204665},{"batb":[[1,11,122.33]],"ltp":11.0,"tv":452.09,"id":8204663},{"batb":[[1,3.8,311.96]],"ltp":3.85,"tv":2467.14,"id":1042125},{"batb":[[1,2.62,425.33]],"ltp":2.64,"tv":7314.22,"id":1042124},{"batb":[[1,6.8,150.58]],"ltp":7.0,"tv":1570.98,"id":1042126}]}]}
{"op":"mcm","clk":"999781067","pt":1580576638322,"mc":[{"id":"1.168135749","rc":[{"batb":[[1,11,165.48]],"ltp":11.0,"tv":213.04,"id":8204665}]}]}
{"op":"mcm","clk":"999783573","pt":1580576654316,"mc":[{"id":"1.168135749","rc":[{"batb":[[0,11.5,278.41]],"ltp":11.0,"tv":213.04,"id":8204665}]}]}
{"op":"mcm","clk":"999804913","pt":1580576790271,"mc":[{"id":"1.168135749","rc":[{"trd":[[2.64,2792.38]],"batb":[[0,2.64,1023.24]],"ltp":2.64,"tv":7394.22,"id":1042124}],"tv":12336.71}]}
{"op":"mcm","clk":"999816682","pt":1580576870628,"mc":[{"id":"1.168135749","rc":[{"batl":[[0,2.66,1.68],[1,2.68,119.03],[2,2.7,50.65]],"ltp":2.64,"tv":7394.22,"id":1042124}]}]}
{"op":"mcm","clk":"999881289","pt":1580577300025,"mc":[{"id":"1.168135749","rc":[{"batb":[[1,2.62,1080.33]],"ltp":2.64,"tv":7394.22,"id":1042124}]}]}
{"op":"mcm","clk":"999884815","pt":1580577320352,"mc":[{"id":"1.168135749","rc":[{"batb":[[2,6.6,903.05]],"ltp":7.0,"tv":1570.98,"id":1042126}]}]}
{"op":"mcm","clk":"999975920","pt":1580577910892,"mc":[{"id":"1.168135749","rc":[{"trd":[[18.5,20]],"batb":[[0,18.5,152.2]],"ltp":18.5,"tv":259.22,"id":8204664}],"tv":12356.72}]}
{"op":"mcm","clk":"999980823","pt":1580577941425,"mc":[{"id":"1.168135749","rc":[{"trd":[[11.5,158.98]],"batb":[[0,11.5,253.4]],"ltp":11.5,"tv":502.09,"id":8204663}],"tv":12406.72}]}
{"op":"mcm","clk":"999981040","pt":1580577942708,"mc":[{"id":"1.168135749","rc":[{"trd":[[11.5,134.81]],"batb":[[0,11.5,268.41]],"ltp":11.5,"tv":233.04,"id":8204665}],"tv":12426.72}]}
{"op":"mcm","clk":"999982819","pt":1580577955251,"mc":[{"id":"1.168135749","rc":[{"trd":[[11.5,178.98]],"batb":[[0,11.5,243.4]],"ltp":11.5,"tv":522.09,"id":8204663}],"tv":12446.72}]}
{"op":"mcm","clk":"999984593","pt":1580577966456,"mc":[{"id":"1.168135749","rc":[{"batb":[[0,11.5,264.97],[1,11,189.01]],"batl":[[0,12.5,216.34]],"ltp":11.5,"tv":233.04,"id":8204665},{"batb":[[1,11,149.22]],"batl":[[1,12.5,119.59]],"ltp":11.5,"tv":522.09,"id":8204663},{"batb":[[2,3.75,32.77]],"ltp":3.85,"tv":2467.14,"id":1042125}]}]}
{"op":"mcm","clk":"999988303","pt":1580577991711,"mc":[{"id":"1.168135749","rc":[{"trd":[[7,491.6]],"batb":[[0,7,347.97]],"ltp":7.0,"tv":1590.99,"id":1042126}],"tv":12466.73}]}
{"op":"mcm","clk":"999992776","pt":1580578022133,"mc":[{"id":"1.168135749","rc":[{"trd":[[3.85,528.82]],"batb":[[0,3.85,585.43]],"ltp":3.85,"tv":2471.55,"id":1042125}],"tv":12471.13}]}
{"op":"mcm","clk":"1000094292","pt":1580578629276,"mc":[{"id":"1.168135749","rc":[{"trd":[[2.66,3654.68],[2.68,751.69]],"batl":[[0,2.68,110.71],[1,2.7,50.65],[2,2.76,12.66]],"ltp":2.68,"tv":7414.22,"id":1042124}],"tv":12491.13}]}
{"op":"mcm","clk":"1000154303","pt":1580579002555,"mc":[{"id":"1.168135749","rc":[{"batb":[[0,2.66,588.37],[1,2.64,1023.24],[2,2.62,1080.33]],"ltp":2.68,"tv":7414.22,"id":1042124}]}]}
{"op":"mcm","clk":"1000240224","pt":1580579582173,"mc":[{"id":"1.168135749","rc":[{"trd":[[2.66,3774.69]],"batb":[[0,2.66,528.37]],"ltp":2.66,"tv":7534.22,"id":1042124}],"tv":12611.13}]}
{"op":"mcm","clk":"1000296613","pt":1580580011147,"mc":[{"id":"1.168135749","rc":[{"trd":[[2.68,822.65]],"batl":[[0,2.68,75.23]],"ltp":2.68,"tv":7605.18,"id":1042124}],"tv":12682.09}]}
{"op":"mcm","clk":"1000335023","pt":1580580282158,"mc":[{"id":"1.168135749","rc":[{"trd":[[3.85,538.82]],"batb":[[0,3.85,580.43]],"ltp":3.85,"tv":2481.54,"id":1042125}],"tv":12692.09}]}
{"op":"mcm","clk":"1000363227","pt":1580580472122,"mc":[{"id":"1.168135749","rc":[{"batl":[[0,12,74.97],[1,12.5,216.34],[2,17,2.52]],"ltp":11.5,"tv":233.04,"id":8204665},{"batl":[[0,12,76.58]],"ltp":11.5,"tv":522.09,"id":8204663}]}]}
{"op":"mcm","clk":"1000403588","pt":1580580729240,"mc":[{"id":"1.168135749","rc":[{"trd":[[2.68,840.91]],"batl":[[0,2.68,66.1]],"ltp":2.68,"tv":7623.44,"id":1042124}],"tv":12710.35}]}
{"op":"mcm","clk":"1000431374","pt":1580580907867,"mc":[{"id":"1.168135749","rc":[{"batl":[[0,3.9,216.02]],"ltp":3.85,"tv":2481.54,"id":1042125}]}]}
{"op":"mcm","clk":"1000449890","pt":1580581037352,"mc":[{"id":"1.168135749","rc":[{"trd":[[11.5,236.49]],"batb":[[0,11.5,214.13]],"ltp":11.5,"tv":334.72,"id":8204665}],"tv":12812.03}]}
{"op":"mcm","clk":"1000454707","pt":1580581071533,"mc":[{"id":"1.168135749","rc":[{"trd":[[3.9,1188.48]],"batl":[[0,3.9,165.07]],"ltp":3.9,"tv":2583.49,"id":1042125}],"tv":12913.98}]}
{"op":"mcm","clk":"1000477467","pt":1580581237911,"mc":[{"id":"1.168135749","rc":[{"batl":[[1,12.5,127.16]],"ltp":11.5,"tv":522.09,"id":8204663},{"batb":[[2,6.6,909.77]],"ltp":7.0,"tv":1590.99,"id":1042126}]}]}
{"op":"mcm","clk":"1000481439","pt":1580581268645,"mc":[{"id":"1.168135749","rc":[{"batb":[[1,11,182.28]],"ltp":11.5,"tv":334.72,"id":8204665},{"batb":[[1,11,139.13]],"ltp":11.5,"tv":522.09,"id":8204663},{"batl":[[1,3.95,52.99]],"ltp":3.9,"tv":2583.49,"id":1042125},{"batl":[[0,7.2,52.77]],"ltp":7.0,"tv":1590.99,"id":1042126}]}]}
{"op":"mcm","clk":"1000516364","pt":1580581532191,"mc":[{"id":"1.168135749","rc":[{"batl":[[0,19,53.69]],"ltp":18.5,"tv":259.22,"id":8204664}]}]}
{"op":"mcm","clk":"1000520636","pt":1580581565569,"mc":[{"id":"1.168135749","rc":[{"trd":[[18.5,40.01]],"batb":[[0,18.5,142.2]],"ltp":18.5,"tv":279.22,"id":8204664}],"tv":12933.98}]}
{"op":"mcm","clk":"1000521253","pt":1580581570167,"mc":[{"id":"1.168135749","rc":[{"trd":[[11.5,202.98]],"batb":[[0,11.5,231.4]],"ltp":11.5,"tv":546.1,"id":8204663}],"tv":12957.99}]}
{"op":"mcm","clk":"1000521805","pt":1580581574596,"mc":[{"id":"1.168135749","rc":[{"trd":[[11.5,248.09]],"batb":[[0,11.5,208.33]],"ltp":11.5,"tv":346.32,"id":8204665}],"tv":12969.59}]}
{"op":"mcm","clk":"1000527566","pt":1580581618952,"mc":[{"id":"1.168135749","rc":[{"trd":[[18.5,70.01]],"batb":[[0,18.5,127.2]],"ltp":18.5,"tv":309.22,"id":8204664}],"tv":12999.59}]}
{"op":"mcm","clk":"1000550951","pt":1580581787472,"mc":[{"id":"1.168135749","rc":[{"trd":[[2.66,4374.69]],"batb":[[0,2.66,228.37]],"ltp":2.66,"tv":8223.44,"id":1042124}],"tv":13599.59}]}
{"op":"mcm","clk":"1000634194","pt":1580582303638,"mc":[{"id":"1.168135749","rc":[{"trd":[[2.68,863.91]],"batl":[[0,2.68,54.6]],"ltp":2.68,"tv":8246.44,"id":1042124}],"tv":13622.59}]}
{"op":"mcm","clk":"1000651742","pt":1580582397493,"mc":[{"id":"1.168135749","rc":[{"trd":[[3.85,558.82]],"batb":[[0,3.85,570.43]],"ltp":3.85,"tv":2603.5,"id":1042125}],"tv":13642.59}]}
{"op":"mcm","clk":"1000652882","pt":1580582403697,"mc":[{"id":"1.168135749","rc":[{"trd":[[2.66,4381.68]],"batb":[[0,2.66,224.87]],"ltp":2.66,"tv":8253.44,"id":1042124}],"tv":13649.59}]}
{"op":"mcm","clk":"1000656490","pt":1580582424633,"mc":[{"id":"1.168135749","rc":[{"trd":[[2.66,4387.68]],"batb":[[0,2.66,221.87]],"ltp":2.66,"tv":8259.44,"id":1042124}],"tv":13655.59}]}
{"op":"mcm","clk":"1000658015","pt":1580582433622,"mc":[{"id":"1.168135749","rc":[{"trd":[[3.85,564.82]],"batb":[[0,3.85,567.43]],"ltp":3.85,"tv":2609.49,"id":1042125}],"tv":13661.59}]}
{"op":"mcm","clk":"1000658876","pt":1580582439240,"mc":[{"id":"1.168135749","rc":[{"trd":[[2.66,4391.68]],"batb":[[0,2.66,219.87]],"ltp":2.66,"tv":8263.44,"id":1042124}],"tv":13665.59}]}
{"op":"mcm","clk":"1000691728","pt":1580582636240,"mc":[{"id":"1.168135749","rc":[{"trd":[[2.66,4411.68]],"batb":[[0,2.66,209.87]],"ltp":2.66,"tv":8283.44,"id":1042124}],"tv":13685.59}]}
{"op":"mcm","clk":"1000773845","pt":1580583125785,"mc":[{"id":"1.168135749","rc":[{"trd":[[2.66,4421.68]],"batb":[[0,2.66,204.87]],"ltp":2.66,"tv":8293.44,"id":1042124}],"tv":13695.59}]}
