{"op":"mcm","clk":"988026418","pt":1580473742115,"mc":[{"id":"1.168135751","marketDefinition":{"bspMarket":false,"turnInPlayEnabled":true,"persistenceEnabled":true,"marketBaseRate":5.0,"eventId":"29678823","eventTypeId":"2","numberOfWinners":1,"bettingType":"ODDS","marketType":"NUMBER_OF_SETS","marketTime":"2020-02-02T08:30:00.000Z","suspendTime":"2020-02-02T08:30:00.000Z","bspReconciled":false,"complete":true,"inPlay":false,"crossMatching":false,"runnersVoidable":false,"numberOfActiveRunners":3,"betDelay":0,"status":"OPEN","runners":[{"status":"ACTIVE","sortPriority":1,"id":2996932,"name":"Three Sets"},{"status":"ACTIVE","sortPriority":2,"id":3064880,"name":"Four Sets"},{"status":"ACTIVE","sortPriority":3,"id":3064881,"name":"Five Sets"}],"regulators":["MR_INT"],"countryCode":"AU","discountAllowed":false,"timezone":"GMT","openDate":"2020-02-02T08:30:00.000Z","version":3143005243,"name":"Number of Sets?","eventName":"Thiem v Djokovic"}}]}
{"op":"mcm","clk":"988026715","pt":1580473744836,"mc":[{"id":"1.168135751","marketDefinition":{"bspMarket":false,"turnInPlayEnabled":true,"persistenceEnabled":true,"marketBaseRate":5.0,"eventId":"29678823","eventTypeId":"2","numberOfWinners":1,"bettingType":"ODDS","marketType":"NUMBER_OF_SETS","marketTime":"2020-02-02T08:30:00.000Z","suspendTime":"2020-02-02T08:30:00.000Z","bspReconciled":false,"complete":true,"inPlay":false,"crossMatching":false,"runnersVoidable":false,"numberOfActiveRunners":3,"betDelay":0,"status":"OPEN","runners":[{"status":"ACTIVE","sortPriority":1,"id":2996932,"name":"Three Sets"},{"status":"ACTIVE","sortPriority":2,"id":3064880,"name":"Four Sets"},{"status":"ACTIVE","sortPriority":3,"id":3064881,"name":"Five Sets"}],"regulators":["MR_INT"],"countryCode":"AU","discountAllowed":true,"timezone":"GMT","openDate":"2020-02-02T08:30:00.000Z","version":3143005243,"name":"Number of Sets?","eventName":"Thiem v Djokovic"}}]}
{"op":"mcm","clk":"988313120","pt":1580476261785,"mc":[{"id":"1.168135751","rc":[{"batb":[[0,2.14,83.25]],"batl":[[0,2.44,85.77]],"ltp":0.0,"tv":0.0,"id":2996932},{"batb":[[0,2.68,76.52]],"batl":[[0,3.15,66.43]],"ltp":0.0,"tv":0.0,"id":3064880},{"batb":[[0,4.1,57.18]],"batl":[[0,5.2,52.14]],"ltp":0.0,"tv":0.0,"id":3064881}]}]}
{"op":"mcm","clk":"988433330","pt":1580477227784,"mc":[{"id":"1.168135751","rc":[{"batb":[[0,2.4,9.5],[1,2.14,83.25]],"ltp":0.0,"tv":0.0,"id":2996932}]}]}
{"op":"mcm","clk":"988434583","pt":1580477238409,"mc":[{"id":"1.168135751","rc":[{"batb":[[0,2.42,9.5]],"ltp":0.0,"tv":0.0,"id":2996932}]}]}
{"op":"mcm","clk":"988435791","pt":1580477247718,"mc":[{"id":"1.168135751","rc":[{"trd":[[2.44,18.99]],"batb":[[0,2.14,83.25],[1,2.14,0]],"batl":[[0,2.44,76.29]],"ltp":2.44,"tv":18.98,"id":2996932}],"tv":18.98}]}
{"op":"mcm","clk":"988438757","pt":1580477272870,"mc":[{"id":"1.168135751","rc":[{"batb":[[1,3.5,2]],"ltp":0.0,"tv":0.0,"id":3064881}]}]}
{"op":"mcm","clk":"988439928","pt":1580477281802,"mc":[{"id":"1.168135751","rc":[{"batb":[[0,3.5,2],[1,3.5,0]],"ltp":0.0,"tv":0.0,"id":3064881}]}]}
{"op":"mcm","clk":"988440316","pt":1580477284903,"mc":[{"id":"1.168135751","rc":[{"batb":[[0,3.5,3.5]],"ltp":0.0,"tv":0.0,"id":3064881}]}]}
{"op":"mcm","clk":"988445222","pt":1580477332175,"mc":[{"id":"1.168135751","rc":[{"batb":[[0,2.16,85.77]],"batl":[[0,2.44,77.36]],"ltp":2.44,"tv":18.98,"id":2996932},{"batb":[[0,2.68,76.52]],"batl":[[0,3.15,74.84]],"ltp":0.0,"tv":0.0,"id":3064880},{"batb":[[0,4.1,58.02]],"batl":[[0,5.2,50.45]],"ltp":0.0,"tv":0.0,"id":3064881}]}]}
{"op":"mcm","clk":"988446886","pt":1580477346825,"mc":[{"id":"1.168135751","rc":[{"batb":[[1,3.7,2]],"ltp":0.0,"tv":0.0,"id":3064881}]}]}
{"op":"mcm","clk":"988456782","pt":1580477437125,"mc":[{"id":"1.168135751","rc":[{"batb":[[1,3.7,3.5]],"ltp":0.0,"tv":0.0,"id":3064881}]}]}
{"op":"mcm","clk":"988458431","pt":1580477452688,"mc":[{"id":"1.168135751","rc":[{"batb":[[1,3.7,1.5]],"ltp":0.0,"tv":0.0,"id":3064881}]}]}
{"op":"mcm","clk":"988461458","pt":1580477475616,"mc":[{"id":"1.168135751","rc":[{"batb":[[0,4.2,1.5],[1,4.1,58.02]],"ltp":0.0,"tv":0.0,"id":3064881}]}]}
{"op":"mcm","clk":"988543958","pt":1580478171681,"mc":[{"id":"1.168135751","rc":[{"batb":[[1,2.14,83.25]],"batl":[[0,2.44,85.77]],"ltp":2.44,"tv":18.98,"id":2996932},{"batb":[[1,4.1,68.95]],"ltp":0.0,"tv":0.0,"id":3064881}]}]}
{"op":"mcm","clk":"988547306","pt":1580478202039,"mc":[{"id":"1.168135751","rc":[{"batb":[[0,2.14,83.25],[1,2.14,0]],"ltp":2.44,"tv":18.98,"id":2996932}]}]}
{"op":"mcm","clk":"988687353","pt":1580479652167,"mc":[{"id":"1.168135751","rc":[{"trd":[[2.44,18.99]],"batb":[[0,2.14,83.26]],"batl":[[0,2.44,85.79]],"ltp":2.44,"tv":18.98,"id":2996932},{"batb":[[0,2.68,76.53]],"batl":[[0,3.15,74.85]],"ltp":0.0,"tv":0.0,"id":3064880},{"batb":[[1,4.1,68.97]],"batl":[[0,5.2,50.46]],"ltp":0.0,"tv":0.0,"id":3064881}],"tv":18.98}]}
{"op":"mcm","clk":"988759524","pt":1580480452818,"mc":[{"id":"1.168135751","rc":[{"batl":[[0,2.42,76.53],[1,2.44,85.79]],"ltp":2.44,"tv":18.98,"id":2996932}]}]}
{"op":"mcm","clk":"988762644","pt":1580480482567,"mc":[{"id":"1.168135751","rc":[{"batl":[[1,2.44,0]],"ltp":2.44,"tv":18.98,"id":2996932}]}]}
{"op":"mcm","clk":"988803060","pt":1580480852901,"mc":[{"id":"1.168135751","rc":[{"batb":[[0,2.16,85.79],[1,2.14,83.26]],"batl":[[1,2.44,84.95]],"ltp":2.44,"tv":18.98,"id":2996932},{"batb":[[1,2.66,74.85]],"ltp":0.0,"tv":0.0,"id":3064880},{"batl":[[1,5.3,58.03]],"ltp":0.0,"tv":0.0,"id":3064881}]}]}
{"op":"mcm","clk":"988805577","pt":1580480882961,"mc":[{"id":"1.168135751","rc":[{"batb":[[1,2.14,0]],"batl":[[0,2.44,84.95],[1,2.44,0]],"ltp":2.44,"tv":18.98,"id":2996932},{"batb":[[0,2.66,74.85],[1,2.66,0]],"ltp":0.0,"tv":0.0,"id":3064880},{"batl":[[0,5.3,58.03],[1,5.3,0]],"ltp":0.0,"tv":0.0,"id":3064881}]}]}
{"op":"mcm","clk":"988983726","pt":1580482948463,"mc":[{"id":"1.168135751","rc":[{"batb":[[0,2.66,84.1]],"batl":[[0,3.1,66.44],[1,3.15,74.85]],"ltp":0.0,"tv":0.0,"id":3064880},{"batl":[[0,5.2,49.62],[1,5.3,58.03]],"ltp":0.0,"tv":0.0,"id":3064881}]}]}
{"op":"mcm","clk":"988986198","pt":1580482977914,"mc":[{"id":"1.168135751","rc":[{"batl":[[1,3.15,0]],"ltp":0.0,"tv":0.0,"id":3064880},{"batl":[[1,5.3,0]],"ltp":0.0,"tv":0.0,"id":3064881}]}]}
{"op":"mcm","clk":"989237307","pt":1580485891856,"mc":[{"id":"1.168135751","rc":[{"batl":[[1,3.15,83.26]],"ltp":0.0,"tv":0.0,"id":3064880},{"batb":[[1,4.1,74.01]],"batl":[[1,5.3,58.03]],"ltp":0.0,"tv":0.0,"id":3064881}]}]}
{"op":"mcm","clk":"989239367","pt":1580485921714,"mc":[{"id":"1.168135751","rc":[{"batl":[[0,3.15,83.26],[1,3.15,0]],"ltp":0.0,"tv":0.0,"id":3064880},{"batl":[[0,5.3,58.03],[1,5.3,0]],"ltp":0.0,"tv":0.0,"id":3064881}]}]}
{"op":"mcm","clk":"989340032","pt":1580486852178,"mc":[{"id":"1.168135751","rc":[{"trd":[[2.44,18.99]],"batb":[[0,2.16,85.77]],"batl":[[0,2.44,84.93]],"ltp":2.44,"tv":18.98,"id":2996932},{"batb":[[0,2.66,84.09]],"batl":[[0,3.15,83.25]],"ltp":0.0,"tv":0.0,"id":3064880},{"batb":[[1,4.1,74]],"batl":[[0,5.3,58.02]],"ltp":0.0,"tv":0.0,"id":3064881}],"tv":18.98}]}
{"op":"mcm","clk":"989579687","pt":1580489360405,"mc":[{"id":"1.168135751","rc":[{"batb":[[0,2.18,14],[1,2.16,85.77]],"ltp":2.44,"tv":18.98,"id":2996932}]}]}
{"op":"mcm","clk":"989623235","pt":1580489792784,"mc":[{"id":"1.168135751","rc":[{"batb":[[2,2.14,85.77]],"ltp":2.44,"tv":18.98,"id":2996932}]}]}
{"op":"mcm","clk":"989625449","pt":1580489823608,"mc":[{"id":"1.168135751","rc":[{"batb":[[1,2.14,85.77],[2,2.14,0]],"ltp":2.44,"tv":18.98,"id":2996932}]}]}
{"op":"mcm","clk":"989944764","pt":1580492624377,"mc":[{"id":"1.168135751","rc":[{"batb":[[0,4.2,62.04]],"ltp":0.0,"tv":0.0,"id":3064881}]}]}
{"op":"mcm","clk":"989947795","pt":1580492654009,"mc":[{"id":"1.168135751","rc":[{"batb":[[1,4.1,0]],"ltp":0.0,"tv":0.0,"id":3064881}]}]}
{"op":"mcm","clk":"990094308","pt":1580494052126,"mc":[{"id":"1.168135751","rc":[{"trd":[[2.44,18.97]],"batb":[[1,2.14,85.66]],"batl":[[0,2.44,84.82]],"ltp":2.44,"tv":18.97,"id":2996932},{"batb":[[0,2.66,83.98]],"batl":[[0,3.15,83.14]],"ltp":0.0,"tv":0.0,"id":3064880},{"batb":[[0,4.2,61.97]],"batl":[[0,5.3,57.95]],"ltp":0.0,"tv":0.0,"id":3064881}],"tv":18.97}]}
{"op":"mcm","clk":"990600856","pt":1580498283537,"mc":[{"id":"1.168135751","rc":[{"batb":[[0,2.18,18]],"ltp":2.44,"tv":18.97,"id":2996932}]}]}
{"op":"mcm","clk":"990600996","pt":1580498284631,"mc":[{"id":"1.168135751","rc":[{"batb":[[1,2.16,4],[2,2.14,85.66]],"ltp":2.44,"tv":18.97,"id":2996932}]}]}
{"op":"mcm","clk":"990601813","pt":1580498290462,"mc":[{"id":"1.168135751","rc":[{"batb":[[0,2.7,4],[1,2.66,83.98]],"ltp":0.0,"tv":0.0,"id":3064880}]}]}
{"op":"mcm","clk":"990602036","pt":1580498292061,"mc":[{"id":"1.168135751","rc":[{"batb":[[1,2.68,4],[2,2.66,83.98]],"ltp":0.0,"tv":0.0,"id":3064880}]}]}
{"op":"mcm","clk":"990602291","pt":1580498294088,"mc":[{"id":"1.168135751","marketDefinition":{"bspMarket":false,"turnInPlayEnabled":true,"persistenceEnabled":true,"marketBaseRate":5.0,"eventId":"29678823","eventTypeId":"2","numberOfWinners":1,"bettingType":"ODDS","marketType":"NUMBER_OF_SETS","marketTime":"2020-02-02T08:30:00.000Z","suspendTime":"2020-02-02T08:30:00.000Z","bspReconciled":false,"complete":true,"inPlay":false,"crossMatching":true,"runnersVoidable":false,"numberOfActiveRunners":3,"betDelay":0,"status":"OPEN","runners":[{"status":"ACTIVE","sortPriority":1,"id":2996932,"name":"Three Sets"},{"status":"ACTIVE","sortPriority":2,"id":3064880,"name":"Four Sets"},{"status":"ACTIVE","sortPriority":3,"id":3064881,"name":"Five Sets"}],"regulators":["MR_INT"],"countryCode":"AU","discountAllowed":true,"timezone":"GMT","openDate":"2020-02-02T08:30:00.000Z","version":3143005243,"name":"Number of Sets?","eventName":"Thiem v Djokovic"}}]}
{"op":"mcm","clk":"990602994","pt":1580498299571,"mc":[{"id":"1.168135751","rc":[{"batb":[[0,4.4,2],[1,4.2,61.97]],"ltp":0.0,"tv":0.0,"id":3064881}]}]}
{"op":"mcm","clk":"990603135","pt":1580498300661,"mc":[{"id":"1.168135751","rc":[{"batb":[[1,4.3,2],[2,4.2,61.97]],"ltp":0.0,"tv":0.0,"id":3064881}]}]}
{"op":"mcm","clk":"990606176","pt":1580498323480,"mc":[{"id":"1.168135751","rc":[{"batb":[[0,2.2,57.95],[1,2.18,18],[2,2.16,4]],"ltp":2.44,"tv":18.97,"id":2996932}]}]}
{"op":"mcm","clk":"991045160","pt":1580501252131,"mc":[{"id":"1.168135751","rc":[{"batb":[[0,2.2,57.95]],"batl":[[0,2.44,84.83]],"ltp":2.44,"tv":18.97,"id":2996932},{"batb":[[2,2.66,83.99]],"batl":[[0,3.15,83.15]],"ltp":0.0,"tv":0.0,"id":3064880},{"batb":[[2,4.2,61.97]],"batl":[[0,5.3,57.95]],"ltp":0.0,"tv":0.0,"id":3064881}]}]}
{"op":"mcm","clk":"991371561","pt":1580503312937,"mc":[{"id":"1.168135751","rc":[{"batb":[[2,4.2,1.5]],"ltp":0.0,"tv":0.0,"id":3064881}]}]}
{"op":"mcm","clk":"991806450","pt":1580508452143,"mc":[{"id":"1.168135751","rc":[{"trd":[[2.44,18.98]],"batb":[[0,2.2,57.97]],"batl":[[0,2.44,84.86]],"ltp":2.44,"tv":18.97,"id":2996932},{"batb":[[2,2.66,84.02]],"batl":[[0,3.15,83.18]],"ltp":0.0,"tv":0.0,"id":3064880},{"batl":[[0,5.3,57.97]],"ltp":0.0,"tv":0.0,"id":3064881}],"tv":18.97}]}
{"op":"mcm","clk":"991957584","pt":1580511140066,"mc":[{"id":"1.168135751","rc":[{"batl":[[0,3.1,77.3],[1,3.15,83.18]],"ltp":0.0,"tv":0.0,"id":3064880},{"batb":[[2,4.2,61.15]],"ltp":0.0,"tv":0.0,"id":3064881}]}]}
{"op":"mcm","clk":"991968719","pt":1580511170607,"mc":[{"id":"1.168135751","rc":[{"batb":[[2,2.64,82.34]],"batl":[[1,3.15,0]],"ltp":0.0,"tv":0.0,"id":3064880}]}]}
{"op":"mcm","clk":"992319503","pt":1580519483611,"mc":[{"id":"1.168135751","rc":[{"batb":[[0,2.2,68.06]],"ltp":2.44,"tv":18.97,"id":2996932},{"batb":[[2,2.66,85.7]],"ltp":0.0,"tv":0.0,"id":3064880},{"batb":[[2,4.2,1.5]],"batl":[[0,5.2,57.97]],"ltp":0.0,"tv":0.0,"id":3064881}]}]}
{"op":"mcm","clk":"992326237","pt":1580519769450,"mc":[{"id":"1.168135751","rc":[{"batb":[[0,2.2,75.62]],"ltp":2.44,"tv":18.97,"id":2996932}]}]}
{"op":"mcm","clk":"992326374","pt":1580519775852,"mc":[{"id":"1.168135751","rc":[{"batl":[[0,3.1,82.34]],"ltp":0.0,"tv":0.0,"id":3064880}]}]}
{"op":"mcm","clk":"992745891","pt":1580529897161,"mc":[{"id":"1.168135751","rc":[{"batl":[[0,2.44,128.55]],"ltp":2.44,"tv":18.97,"id":2996932},{"batl":[[1,5.3,77.3]],"ltp":0.0,"tv":0.0,"id":3064881}]}]}
{"op":"mcm","clk":"992746102","pt":1580529903882,"mc":[{"id":"1.168135751","rc":[{"batl":[[0,5.3,77.3],[1,5.3,0]],"ltp":0.0,"tv":0.0,"id":3064881}]}]}
{"op":"mcm","clk":"992769497","pt":1580530189956,"mc":[{"id":"1.168135751","rc":[{"batb":[[2,4.2,78.8]],"ltp":0.0,"tv":0.0,"id":3064881}]}]}
{"op":"mcm","clk":"992769614","pt":1580530192228,"mc":[{"id":"1.168135751","rc":[{"batb":[[2,2.66,136.11]],"ltp":0.0,"tv":0.0,"id":3064880}]}]}
{"op":"mcm","clk":"992770661","pt":1580530211107,"mc":[{"id":"1.168135751","rc":[{"batb":[[2,4.2,1.5]],"ltp":0.0,"tv":0.0,"id":3064881}]}]}
{"op":"mcm","clk":"992780913","pt":1580530415791,"mc":[{"id":"1.168135751","rc":[{"batb":[[0,2.2,83.18]],"ltp":2.44,"tv":18.97,"id":2996932},{"batb":[[2,4.2,87.2]],"batl":[[0,5.3,84.86]],"ltp":0.0,"tv":0.0,"id":3064881}]}]}
{"op":"mcm","clk":"992781082","pt":1580530419668,"mc":[{"id":"1.168135751","rc":[{"batb":[[2,4.2,1.5]],"ltp":0.0,"tv":0.0,"id":3064881}]}]}
{"op":"mcm","clk":"992781135","pt":1580530420796,"mc":[{"id":"1.168135751","rc":[{"batl":[[0,3.1,131.91]],"ltp":0.0,"tv":0.0,"id":3064880}]}]}
{"op":"mcm","clk":"992781220","pt":1580530422661,"mc":[{"id":"1.168135751","rc":[{"batl":[[0,2.44,174.76]],"ltp":2.44,"tv":18.97,"id":2996932},{"batb":[[2,4.2,85.52]],"ltp":0.0,"tv":0.0,"id":3064881}]}]}
{"op":"mcm","clk":"992781268","pt":1580530423390,"mc":[{"id":"1.168135751","rc":[{"batb":[[2,2.66,163.84]],"ltp":0.0,"tv":0.0,"id":3064880},{"batb":[[2,4.2,129.21]],"ltp":0.0,"tv":0.0,"id":3064881}]}]}
{"op":"mcm","clk":"992781404","pt":1580530425563,"mc":[{"id":"1.168135751","rc":[{"batb":[[0,2.2,131.07]],"ltp":2.44,"tv":18.97,"id":2996932},{"batl":[[0,5.3,123.51]],"ltp":0.0,"tv":0.0,"id":3064881}]}]}
{"op":"mcm","clk":"992781869","pt":1580530435690,"mc":[{"id":"1.168135751","rc":[{"batb":[[2,4.2,1.5]],"ltp":0.0,"tv":0.0,"id":3064881}]}]}
{"op":"mcm","clk":"992888545","pt":1580532670417,"mc":[{"id":"1.168135751","rc":[{"batl":[[0,5.2,82.34]],"ltp":0.0,"tv":0.0,"id":3064881}]}]}
{"op":"mcm","clk":"993125278","pt":1580537034061,"mc":[{"id":"1.168135751","rc":[{"batl":[[0,4.8,2.03],[1,5.2,82.34]],"ltp":0.0,"tv":0.0,"id":3064881}]}]}
{"op":"mcm","clk":"994080620","pt":1580549064612,"mc":[{"id":"1.168135751","rc":[{"batb":[[1,4.3,3.5],[2,4.1,116.79]],"ltp":0.0,"tv":0.0,"id":3064881}]}]}
{"op":"mcm","clk":"994555780","pt":1580552485064,"mc":[{"id":"1.168135751","rc":[{"batl":[[1,2.46,160.48]],"ltp":2.44,"tv":18.97,"id":2996932},{"batl":[[1,3.15,164.68]],"ltp":0.0,"tv":0.0,"id":3064880},{"batl":[[1,5.2,133.59]],"ltp":0.0,"tv":0.0,"id":3064881}]}]}
{"op":"mcm","clk":"994561063","pt":1580552514803,"mc":[{"id":"1.168135751","rc":[{"batl":[[0,2.46,160.48],[1,2.46,0]],"ltp":2.44,"tv":18.97,"id":2996932},{"batb":[[2,2.54,4]],"batl":[[0,3.15,129.39],[1,3.15,0]],"ltp":0.0,"tv":0.0,"id":3064880},{"batb":[[2,3.8,2]],"batl":[[1,5.2,0]],"ltp":0.0,"tv":0.0,"id":3064881}]}]}
{"op":"mcm","clk":"994561138","pt":1580552515228,"mc":[{"id":"1.168135751","rc":[{"batb":[[0,2.18,18],[1,2.16,4],[2,2.04,4]],"ltp":2.44,"tv":18.97,"id":2996932}]}]}
{"op":"mcm","clk":"994562645","pt":1580552523133,"mc":[{"id":"1.168135751","rc":[{"batb":[[1,2.68,133.39]],"ltp":0.0,"tv":0.0,"id":3064880},{"batb":[[2,4,131.07]],"batl":[[1,5.1,82.34]],"ltp":0.0,"tv":0.0,"id":3064881}]}]}
{"op":"mcm","clk":"994564730","pt":1580552535254,"mc":[{"id":"1.168135751","rc":[{"batb":[[0,2.22,82.34],[1,2.18,18],[2,2.16,4]],"batl":[[0,2.42,125.19]],"ltp":2.44,"tv":18.97,"id":2996932},{"batl":[[0,3.05,84.86]],"ltp":0.0,"tv":0.0,"id":3064880},{"batb":[[2,4.2,84.02]],"ltp":0.0,"tv":0.0,"id":3064881}]}]}
{"op":"mcm","clk":"994582318","pt":1580552574705,"mc":[{"id":"1.168135751","rc":[{"batb":[[1,2.2,126.87],[2,2.18,18]],"batl":[[1,2.46,161.32]],"ltp":2.44,"tv":18.97,"id":2996932},{"batl":[[1,3.15,120.15]],"ltp":0.0,"tv":0.0,"id":3064880}]}]}
{"op":"mcm","clk":"994587287","pt":1580552601962,"mc":[{"id":"1.168135751","rc":[{"batb":[[0,2.2,126.87],[1,2.18,18],[2,2.16,4]],"batl":[[0,2.46,161.32],[1,2.46,0]],"ltp":2.44,"tv":18.97,"id":2996932},{"batl":[[0,3.15,120.15],[1,3.15,0]],"ltp":0.0,"tv":0.0,"id":3064880},{"batb":[[2,4,131.07]],"ltp":0.0,"tv":0.0,"id":3064881}]}]}
{"op":"mcm","clk":"994593907","pt":1580552639010,"mc":[{"id":"1.168135751","rc":[{"batb":[[0,2.24,76.46],[1,2.2,126.87],[2,2.18,18]],"batl":[[0,2.4,85.7],[1,2.46,161.32]],"ltp":2.44,"tv":18.97,"id":2996932},{"batl":[[0,3,66.38],[1,3.15,120.15]],"ltp":0.0,"tv":0.0,"id":3064880},{"batb":[[1,4.3,63.15]],"ltp":0.0,"tv":0.0,"id":3064881}]}]}
{"op":"mcm","clk":"994602279","pt":1580552685999,"mc":[{"id":"1.168135751","rc":[{"batb":[[0,2.2,126.87],[1,2.18,18],[2,2.16,4]],"batl":[[0,2.46,161.32],[1,2.46,0]],"ltp":2.44,"tv":18.97,"id":2996932},{"batl":[[0,3.15,120.15],[1,3.15,0]],"ltp":0.0,"tv":0.0,"id":3064880},{"batb":[[1,4.3,3.5]],"ltp":0.0,"tv":0.0,"id":3064881}]}]}
{"op":"mcm","clk":"994708630","pt":1580553296213,"mc":[{"id":"1.168135751","rc":[{"batb":[[1,2.68,161.96]],"ltp":0.0,"tv":0.0,"id":3064880},{"batl":[[1,5.1,115.95]],"ltp":0.0,"tv":0.0,"id":3064881}]}]}
{"op":"mcm","clk":"994873401","pt":1580554259313,"mc":[{"id":"1.168135751","rc":[{"batb":[[0,2.18,18],[1,2.16,4],[2,2.04,4]],"ltp":2.44,"tv":18.97,"id":2996932},{"batb":[[1,2.68,4]],"ltp":0.0,"tv":0.0,"id":3064880},{"batb":[[2,3.8,2]],"batl":[[1,5.1,0]],"ltp":0.0,"tv":0.0,"id":3064881}]}]}
{"op":"mcm","clk":"994877710","pt":1580554290744,"mc":[{"id":"1.168135751","rc":[{"batb":[[0,2.2,120.99],[1,2.18,18],[2,2.16,4]],"batl":[[0,2.46,131.07]],"ltp":2.44,"tv":18.97,"id":2996932},{"batb":[[1,2.68,171.2]],"batl":[[0,3.15,117.63]],"ltp":0.0,"tv":0.0,"id":3064880},{"batb":[[2,4,131.07]],"batl":[[1,5,85.7]],"ltp":0.0,"tv":0.0,"id":3064881}]}]}
{"op":"mcm","clk":"994882968","pt":1580554330704,"mc":[{"id":"1.168135751","rc":[{"batb":[[0,2.2,172.24]],"batl":[[1,2.48,161.32]],"ltp":2.44,"tv":18.97,"id":2996932}]}]}
{"op":"mcm","clk":"994897906","pt":1580554361425,"mc":[{"id":"1.168135751","rc":[{"batl":[[0,2.48,161.32],[1,2.48,0]],"ltp":2.44,"tv":18.97,"id":2996932}]}]}
{"op":"mcm","clk":"995482303","pt":1580557102670,"mc":[{"id":"1.168135751","rc":[{"batl":[[0,2.34,4.05],[1,2.48,161.32]],"ltp":2.44,"tv":18.97,"id":2996932}]}]}
{"op":"mcm","clk":"995629177","pt":1580557890034,"mc":[{"id":"1.168135751","rc":[{"batb":[[0,2.3,50.65],[1,2.2,172.24],[2,2.18,18]],"ltp":2.44,"tv":18.97,"id":2996932}]}]}
{"op":"mcm","clk":"995630609","pt":1580557899450,"mc":[{"id":"1.168135751","rc":[{"batb":[[0,2.2,172.24],[1,2.18,18],[2,2.16,4]],"ltp":2.44,"tv":18.97,"id":2996932}]}]}
{"op":"mcm","clk":"995635042","pt":1580557928211,"mc":[{"id":"1.168135751","rc":[{"batb":[[0,2.3,4.05],[1,2.2,172.24],[2,2.18,18]],"ltp":2.44,"tv":18.97,"id":2996932}]}]}
{"op":"mcm","clk":"995649771","pt":1580557954556,"mc":[{"id":"1.168135751","rc":[{"batb":[[0,2.2,172.24],[1,2.18,18],[2,2.16,4]],"ltp":2.44,"tv":18.97,"id":2996932}]}]}
{"op":"mcm","clk":"996059918","pt":1580560222088,"mc":[{"id":"1.168135751","rc":[{"batb":[[0,2.26,21.78],[1,2.2,172.24],[2,2.18,18]],"ltp":2.44,"tv":18.97,"id":2996932}]}]}
{"op":"mcm","clk":"996064325","pt":1580560247295,"mc":[{"id":"1.168135751","rc":[{"batb":[[0,2.2,172.24],[1,2.18,18],[2,2.16,4]],"ltp":2.44,"tv":18.97,"id":2996932}]}]}
{"op":"mcm","clk":"996066022","pt":1580560257134,"mc":[{"id":"1.168135751","rc":[{"batb":[[0,2.28,50.41],[1,2.2,172.24],[2,2.18,18]],"ltp":2.44,"tv":18.97,"id":2996932}]}]}
{"op":"mcm","clk":"996071439","pt":1580560287075,"mc":[{"id":"1.168135751","rc":[{"batb":[[0,2.2,120.15],[1,2.18,18],[2,2.16,4]],"ltp":2.44,"tv":18.97,"id":2996932}]}]}
{"op":"mcm","clk":"996122893","pt":1580560564719,"mc":[{"id":"1.168135751","rc":[{"batb":[[0,2.24,30.39],[1,2.2,120.15],[2,2.18,18]],"ltp":2.44,"tv":18.97,"id":2996932}]}]}
{"op":"mcm","clk":"996153661","pt":1580560678195,"mc":[{"id":"1.168135751","rc":[{"batb":[[0,2.26,68.9],[1,2.24,30.39],[2,2.2,120.15]],"ltp":2.44,"tv":18.97,"id":2996932}]}]}
{"op":"mcm","clk":"996158608","pt":1580560706332,"mc":[{"id":"1.168135751","rc":[{"batb":[[1,2.2,120.15],[2,2.18,18]],"ltp":2.44,"tv":18.97,"id":2996932}]}]}
{"op":"mcm","clk":"996171265","pt":1580560777956,"mc":[{"id":"1.168135751","rc":[{"batb":[[0,2.2,120.15],[1,2.18,18],[2,2.16,4]],"ltp":2.44,"tv":18.97,"id":2996932}]}]}
{"op":"mcm","clk":"996277631","pt":1580561329345,"mc":[{"id":"1.168135751","rc":[{"batb":[[0,2.2,163]],"ltp":2.44,"tv":18.97,"id":2996932}]}]}
{"op":"mcm","clk":"996283009","pt":1580561359815,"mc":[{"id":"1.168135751","rc":[{"batb":[[1,2.68,135.07]],"ltp":0.0,"tv":0.0,"id":3064880}]}]}
{"op":"mcm","clk":"996345431","pt":1580561660405,"mc":[{"id":"1.168135751","rc":[{"batb":[[1,2.68,161.96]],"ltp":0.0,"tv":0.0,"id":3064880},{"batl":[[1,5,120.15]],"ltp":0.0,"tv":0.0,"id":3064881}]}]}
{"op":"mcm","clk":"996350510","pt":1580561691533,"mc":[{"id":"1.168135751","rc":[{"batl":[[1,2.48,126.03]],"ltp":2.44,"tv":18.97,"id":2996932},{"batb":[[2,3.95,126.03]],"ltp":0.0,"tv":0.0,"id":3064881}]}]}
{"op":"mcm","clk":"996350587","pt":1580561691967,"mc":[{"id":"1.168135751","rc":[{"batb":[[0,2.18,18],[1,2.16,4],[2,2.04,4]],"batl":[[1,2.48,0]],"ltp":2.44,"tv":18.97,"id":2996932},{"batb":[[1,2.68,4]],"ltp":0.0,"tv":0.0,"id":3064880},{"batb":[[2,3.8,2]],"batl":[[1,5,0]],"ltp":0.0,"tv":0.0,"id":3064881}]}]}
{"op":"mcm","clk":"996353368","pt":1580561707928,"mc":[{"id":"1.168135751","rc":[{"batb":[[0,2.22,123.51],[1,2.18,18],[2,2.16,4]],"batl":[[1,2.46,131.91]],"ltp":2.44,"tv":18.97,"id":2996932},{"batb":[[0,2.7,128.35]],"batl":[[0,3.1,118.47]],"ltp":0.0,"tv":0.0,"id":3064880},{"batb":[[2,4.1,77.3]],"batl":[[1,4.9,85.7]],"ltp":0.0,"tv":0.0,"id":3064881}]}]}
{"op":"mcm","clk":"996358370","pt":1580561738029,"mc":[{"id":"1.168135751","rc":[{"batb":[[1,2.2,165.52],[2,2.18,18]],"batl":[[2,2.48,128.55]],"ltp":2.44,"tv":18.97,"id":2996932},{"batb":[[1,2.68,172.88]],"batl":[[1,3.15,117.63]],"ltp":0.0,"tv":0.0,"id":3064880},{"batl":[[2,5,124.35]],"ltp":0.0,"tv":0.0,"id":3064881}]}]}
{"op":"mcm","clk":"996364958","pt":1580561777775,"mc":[{"id":"1.168135751","rc":[{"batb":[[0,2.2,165.52],[1,2.18,18],[2,2.16,4]],"batl":[[1,2.48,128.55],[2,2.48,0]],"ltp":2.44,"tv":18.97,"id":2996932},{"batb":[[0,2.7,4]],"batl":[[0,3.15,117.63],[1,3.15,0]],"ltp":0.0,"tv":0.0,"id":3064880},{"batb":[[2,3.95,133.59]],"batl":[[1,5,124.35],[2,5,0]],"ltp":0.0,"tv":0.0,"id":3064881}]}]}
{"op":"mcm","clk":"997157263","pt":1580565649164,"mc":[{"id":"1.168135751","rc":[{"batl":[[2,2.5,167.2]],"ltp":2.44,"tv":18.97,"id":2996932},{"batl":[[1,4.9,85.7],[2,5,124.35]],"ltp":0.0,"tv":0.0,"id":3064881}]}]}
{"op":"mcm","clk":"997162848","pt":1580565679508,"mc":[{"id":"1.168135751","rc":[{"batl":[[1,2.5,167.2],[2,2.5,0]],"ltp":2.44,"tv":18.97,"id":2996932},{"batl":[[2,5,0]],"ltp":0.0,"tv":0.0,"id":3064881}]}]}
{"op":"mcm","clk":"997169885","pt":1580565719952,"mc":[{"id":"1.168135751","rc":[{"batl":[[1,2.46,123.51],[2,2.5,167.2]],"ltp":2.44,"tv":18.97,"id":2996932}]}]}
{"op":"mcm","clk":"997179644","pt":1580565770287,"mc":[{"id":"1.168135751","rc":[{"batl":[[1,2.5,167.2],[2,2.5,0]],"ltp":2.44,"tv":18.97,"id":2996932}]}]}
{"op":"mcm","clk":"998824868","pt":1580572334864,"mc":[{"id":"1.168135751","rc":[{"trd":[[2.34,2.34]],"batl":[[0,2.34,1.71]],"ltp":2.34,"tv":21.31,"id":2996932},{"trd":[[2.74,2]],"ltp":2.74,"tv":2.0,"id":3064880},{"trd":[[4.8,1.14]],"batl":[[0,4.9,86.58],[1,4.9,0]],"ltp":4.8,"tv":1.14,"id":3064881}],"tv":24.45}]}
{"op":"mcm","clk":"998827771","pt":1580572350385,"mc":[{"id":"1.168135751","rc":[{"trd":[[4.4,4]],"batb":[[0,4.3,3.5],[1,3.95,133.59],[2,3.8,2]],"ltp":4.4,"tv":5.14,"id":3064881}],"tv":28.45}]}
{"op":"mcm","clk":"999282923","pt":1580574205222,"mc":[{"id":"1.168135751","rc":[{"batl":[[0,4.9,85.7]],"ltp":4.4,"tv":5.14,"id":3064881}]}]}
{"op":"mcm","clk":"999984593","pt":1580577966456,"mc":[{"id":"1.168135751","rc":[{"batl":[[1,2.5,116.79]],"ltp":2.34,"tv":21.31,"id":2996932},{"batb":[[1,3.8,2],[2,2.1,8.61]],"ltp":4.4,"tv":5.14,"id":3064881}]}]}
{"op":"mcm","clk":"999988871","pt":1580577995730,"mc":[{"id":"1.168135751","rc":[{"batb":[[1,3.9,130.23],[2,3.8,2]],"ltp":4.4,"tv":5.14,"id":3064881}]}]}
{"op":"mcm","clk":"1000477467","pt":1580581237911,"mc":[{"id":"1.168135751","rc":[{"batl":[[0,4.9,125.19]],"ltp":4.4,"tv":5.14,"id":3064881}]}]}
{"op":"mcm","clk":"1000617163","pt":1580582195018,"mc":[{"id":"1.168135751","rc":[{"batb":[[0,2.2,185.52]],"ltp":2.34,"tv":21.31,"id":2996932}]}]}
{"op":"mcm","clk":"1001441545","pt":1580586707651,"mc":[{"id":"1.168135751","rc":[{"batb":[[0,4.3,23.92]],"ltp":4.4,"tv":5.14,"id":3064881}]}]}
{"op":"mcm","clk":"1001454851","pt":1580586793312,"mc":[{"id":"1.168135751","rc":[{"batb":[[1,4.2,43.69],[2,3.9,130.23]],"ltp":4.4,"tv":5.14,"id":3064881}]}]}
{"op":"mcm","clk":"1001465999","pt":1580586865332,"mc":[{"id":"1.168135751","rc":[{"trd":[[4.3,12.42]],"batb":[[0,4.3,17.71]],"ltp":4.3,"tv":17.56,"id":3064881}],"tv":40.87}]}
{"op":"mcm","clk":"1001472766","pt":1580586904193,"mc":[{"id":"1.168135751","rc":[{"batb":[[2,3.8,2]],"ltp":4.3,"tv":17.56,"id":3064881}]}]}
{"op":"mcm","clk":"1001549273","pt":1580587357793,"mc":[{"id":"1.168135751","rc":[{"batl":[[0,4.8,2.71],[1,4.9,125.19]],"ltp":4.3,"tv":17.56,"id":3064881}]}]}
{"op":"mcm","clk":"1001707744","pt":1580588152504,"mc":[{"id":"1.168135751","rc":[{"trd":[[4.3,24.84]],"batb":[[0,4.3,11.5]],"ltp":4.3,"tv":29.98,"id":3064881}],"tv":53.29}]}
{"op":"mcm","clk":"1001722204","pt":1580588223759,"mc":[{"id":"1.168135751","rc":[{"batb":[[2,3.9,120.99]],"ltp":4.3,"tv":29.98,"id":3064881}]}]}
{"op":"mcm","clk":"1001742840","pt":1580588334852,"mc":[{"id":"1.168135751","rc":[{"batb":[[1,3.9,120.99],[2,3.8,2]],"ltp":4.3,"tv":29.98,"id":3064881}]}]}
{"op":"mcm","clk":"1001885537","pt":1580589128617,"mc":[{"id":"1.168135751","rc":[{"batl":[[0,4.4,2.37],[1,4.8,2.71],[2,4.9,125.19]],"ltp":4.3,"tv":29.98,"id":3064881}]}]}
{"op":"mcm","clk":"1001904176","pt":1580589236708,"mc":[{"id":"1.168135751","rc":[{"batl":[[0,4.8,2.71],[1,4.9,125.19],[2,4.9,0]],"ltp":4.3,"tv":29.98,"id":3064881}]}]}
{"op":"mcm","clk":"1001904318","pt":1580589237506,"mc":[{"id":"1.168135751","rc":[{"trd":[[4.3,29.58]],"batb":[[0,4.3,9.13]],"ltp":4.3,"tv":34.72,"id":3064881}],"tv":58.03}]}
{"op":"mcm","clk":"1002126099","pt":1580590733596,"mc":[{"id":"1.168135751","rc":[{"trd":[[4.3,42.02]],"batb":[[0,4.3,2.91]],"ltp":4.3,"tv":47.15,"id":3064881}],"tv":70.47}]}
{"op":"mcm","clk":"1002128772","pt":1580590760683,"mc":[{"id":"1.168135751","rc":[{"batl":[[0,4.9,125.19],[1,4.9,0]],"ltp":4.3,"tv":47.15,"id":3064881}]}]}
{"op":"mcm","clk":"1002141470","pt":1580590867241,"mc":[{"id":"1.168135751","rc":[{"batl":[[1,2.5,172.24]],"ltp":2.34,"tv":21.31,"id":2996932},{"batb":[[0,2.7,121.63]],"ltp":2.74,"tv":2.0,"id":3064880}]}]}
{"op":"mcm","clk":"1002144953","pt":1580590896984,"mc":[{"id":"1.168135751","rc":[{"batb":[[1,2.68,4]],"ltp":2.74,"tv":2.0,"id":3064880}]}]}
{"op":"mcm","clk":"1002401541","pt":1580593278362,"mc":[{"id":"1.168135751","rc":[{"batb":[[0,2.3,4],[1,2.2,185.52],[2,2.18,18]],"ltp":2.34,"tv":21.31,"id":2996932}]}]}
{"op":"mcm","clk":"1002420088","pt":1580593472077,"mc":[{"id":"1.168135751","rc":[{"batb":[[0,2.7,165.32]],"batl":[[1,3.2,168.88]],"ltp":2.74,"tv":2.0,"id":3064880}]}]}
{"op":"mcm","clk":"1002420766","pt":1580593478939,"mc":[{"id":"1.168135751","rc":[{"batl":[[0,3.2,168.88],[1,3.2,0]],"ltp":2.74,"tv":2.0,"id":3064880}]}]}
{"op":"mcm","clk":"1002427961","pt":1580593557558,"mc":[{"id":"1.168135751","rc":[{"batb":[[0,2.3,42]],"ltp":2.34,"tv":21.31,"id":2996932}]}]}
{"op":"mcm","clk":"1002429706","pt":1580593577680,"mc":[{"id":"1.168135751","rc":[{"batb":[[1,2.2,20]],"ltp":2.34,"tv":21.31,"id":2996932}]}]}
{"op":"mcm","clk":"1002429733","pt":1580593577990,"mc":[{"id":"1.168135751","rc":[{"batb":[[0,2.3,85.69]],"ltp":2.34,"tv":21.31,"id":2996932}]}]}
{"op":"mcm","clk":"1002430317","pt":1580593584693,"mc":[{"id":"1.168135751","rc":[{"batb":[[1,2.22,116.79],[2,2.2,20]],"ltp":2.34,"tv":21.31,"id":2996932}]}]}
{"op":"mcm","clk":"1002431442","pt":1580593597416,"mc":[{"id":"1.168135751","rc":[{"batb":[[1,2.2,20],[2,2.18,18]],"ltp":2.34,"tv":21.31,"id":2996932}]}]}
{"op":"mcm","clk":"1002458115","pt":1580593949041,"mc":[{"id":"1.168135751","rc":[{"batb":[[0,2.7,132.55]],"ltp":2.74,"tv":2.0,"id":3064880}]}]}
{"op":"mcm","clk":"1002460358","pt":1580593979750,"mc":[{"id":"1.168135751","rc":[{"batl":[[0,3.15,129.39]],"ltp":2.74,"tv":2.0,"id":3064880}]}]}
{"op":"mcm","clk":"1002507310","pt":1580594621266,"mc":[{"id":"1.168135751","rc":[{"batb":[[0,2.3,91.57]],"ltp":2.34,"tv":21.31,"id":2996932}]}]}
{"op":"mcm","clk":"1002523004","pt":1580594870685,"mc":[{"id":"1.168135751","rc":[{"batl":[[1,2.5,120.99]],"ltp":2.34,"tv":21.31,"id":2996932},{"batb":[[0,2.7,4]],"ltp":2.74,"tv":2.0,"id":3064880}]}]}
{"op":"mcm","clk":"1002524928","pt":1580594900768,"mc":[{"id":"1.168135751","rc":[{"batb":[[1,2.68,177.92]],"ltp":2.74,"tv":2.0,"id":3064880}]}]}
{"op":"mcm","clk":"1002648838","pt":1580596602705,"mc":[{"id":"1.168135751","rc":[{"batb":[[0,2.3,101.65]],"batl":[[2,2.52,160.48]],"ltp":2.34,"tv":21.31,"id":2996932}]}]}
{"op":"mcm","clk":"1002650464","pt":1580596632855,"mc":[{"id":"1.168135751","rc":[{"batb":[[1,3.95,135.27],[2,3.9,120.99]],"ltp":4.3,"tv":47.15,"id":3064881}]}]}
{"op":"mcm","clk":"1002650926","pt":1580596640278,"mc":[{"id":"1.168135751","rc":[{"batl":[[2,2.52,0]],"ltp":2.34,"tv":21.31,"id":2996932},{"batb":[[1,2.68,123.31]],"ltp":2.74,"tv":2.0,"id":3064880},{"batb":[[2,3.8,2]],"batl":[[0,4.9,85.7]],"ltp":4.3,"tv":47.15,"id":3064881}]}]}
{"op":"mcm","clk":"1002655408","pt":1580596718783,"mc":[{"id":"1.168135751","rc":[{"batl":[[1,2.5,0]],"ltp":2.34,"tv":21.31,"id":2996932},{"batb":[[1,2.68,4]],"ltp":2.74,"tv":2.0,"id":3064880}]}]}
{"op":"mcm","clk":"1002655426","pt":1580596718991,"mc":[{"id":"1.168135751","rc":[{"batl":[[1,2.52,165.52]],"ltp":2.34,"tv":21.31,"id":2996932},{"batb":[[2,2.66,169.72]],"ltp":2.74,"tv":2.0,"id":3064880}]}]}
{"op":"mcm","clk":"1002655499","pt":1580596720279,"mc":[{"id":"1.168135751","rc":[{"batl":[[0,4.9,105.7]],"ltp":4.3,"tv":47.15,"id":3064881}]}]}
{"op":"mcm","clk":"1002673266","pt":1580597013337,"mc":[{"id":"1.168135751","rc":[{"batl":[[0,3.1,116.79],[1,3.15,129.39]],"ltp":2.74,"tv":2.0,"id":3064880}]}]}
{"op":"mcm","clk":"1002674928","pt":1580597042685,"mc":[{"id":"1.168135751","rc":[{"batl":[[1,3.15,0]],"ltp":2.74,"tv":2.0,"id":3064880}]}]}
{"op":"mcm","clk":"1002731935","pt":1580597974645,"mc":[{"id":"1.168135751","rc":[{"batb":[[0,2.3,116.78]],"ltp":2.34,"tv":21.31,"id":2996932}]}]}
{"op":"mcm","clk":"1002732460","pt":1580597981435,"mc":[{"id":"1.168135751","rc":[{"batb":[[1,2.68,9.24]],"ltp":2.74,"tv":2.0,"id":3064880}]}]}
{"op":"mcm","clk":"1002734381","pt":1580598004799,"mc":[{"id":"1.168135751","rc":[{"batl":[[1,2.52,125.19]],"ltp":2.34,"tv":21.31,"id":2996932},{"batb":[[2,2.64,161.32]],"ltp":2.74,"tv":2.0,"id":3064880}]}]}
{"op":"mcm","clk":"1002921720","pt":1580600629815,"mc":[{"id":"1.168135751","rc":[{"batb":[[1,2.68,4]],"ltp":2.74,"tv":2.0,"id":3064880}]}]}
{"op":"mcm","clk":"1002921737","pt":1580600630021,"mc":[{"id":"1.168135751","rc":[{"batb":[[2,2.66,5.24]],"ltp":2.74,"tv":2.0,"id":3064880}]}]}
{"op":"mcm","clk":"1002940774","pt":1580600929675,"mc":[{"id":"1.168135751","rc":[{"trd":[[2.34,5.77]],"batb":[[0,2.34,31.89],[1,2.3,116.78],[2,2.2,20]],"batl":[[0,2.52,125.19],[1,2.54,167.2]],"ltp":2.34,"tv":24.74,"id":2996932}],"tv":73.9}]}
{"op":"mcm","clk":"1002942887","pt":1580600959809,"mc":[{"id":"1.168135751","rc":[{"batb":[[0,2.3,116.78],[1,2.2,20],[2,2.18,18]],"batl":[[1,2.54,0]],"ltp":2.34,"tv":24.74,"id":2996932}]}]}
{"op":"mcm","clk":"1002943346","pt":1580600966791,"mc":[{"id":"1.168135751","rc":[{"batb":[[0,2.32,49.57],[1,2.3,116.78],[2,2.2,20]],"ltp":2.34,"tv":24.74,"id":2996932}]}]}
{"op":"mcm","clk":"1002944109","pt":1580600978810,"mc":[{"id":"1.168135751","rc":[{"batb":[[0,2.3,116.78],[1,2.2,20],[2,2.18,18]],"ltp":2.34,"tv":24.74,"id":2996932}]}]}
{"op":"mcm","clk":"1002951171","pt":1580601081919,"mc":[{"id":"1.168135751","rc":[{"batb":[[0,2.3,126.86]],"batl":[[1,2.54,157.96]],"ltp":2.34,"tv":24.74,"id":2996932}]}]}
{"op":"mcm","clk":"1002953349","pt":1580601111789,"mc":[{"id":"1.168135751","rc":[{"batl":[[0,2.54,157.96],[1,2.54,0]],"ltp":2.34,"tv":24.74,"id":2996932}]}]}
{"op":"mcm","clk":"1002960893","pt":1580601218788,"mc":[{"id":"1.168135751","rc":[{"trd":[[2.52,4.28]],"batb":[[0,2.52,16.72],[1,2.3,126.86],[2,2.2,20]],"ltp":2.52,"tv":29.02,"id":2996932},{"trd":[[2.7,4]],"batb":[[0,2.68,4],[1,2.66,5.24],[2,2.64,171.4]],"ltp":2.7,"tv":6.0,"id":3064880},{"trd":[[4.3,44.53]],"batb":[[0,3.95,135.67],[1,3.8,2],[2,2.1,8.61]],"ltp":4.3,"tv":49.66,"id":3064881}],"tv":84.69}]}
{"op":"mcm","clk":"1002961966","pt":1580601234608,"mc":[{"id":"1.168135751","rc":[{"trd":[[2.54,33.44]],"batb":[[0,2.3,126.86],[1,2.2,20],[2,2.18,18]],"batl":[[0,2.54,141.24]],"ltp":2.54,"tv":62.46,"id":2996932}],"tv":118.13}]}
{"op":"mcm","clk":"1002963781","pt":1580601261773,"mc":[{"id":"1.168135751","rc":[{"batl":[[0,2.54,117.71]],"ltp":2.54,"tv":62.46,"id":2996932},{"batb":[[2,2.64,115.95]],"ltp":2.7,"tv":6.0,"id":3064880}]}]}
{"op":"mcm","clk":"1003057184","pt":1580602453146,"mc":[{"id":"1.168135751","rc":[{"batl":[[0,4.8,20],[1,4.9,85.7]],"ltp":4.3,"tv":49.66,"id":3064881}]}]}
{"op":"mcm","clk":"1003066227","pt":1580602552839,"mc":[{"id":"1.168135751","rc":[{"batl":[[0,2.54,162.24]],"ltp":2.54,"tv":62.46,"id":2996932},{"batb":[[2,2.64,157.96]],"ltp":2.7,"tv":6.0,"id":3064880},{"batb":[[1,3.9,134.43],[2,3.8,2]],"batl":[[0,4.7,67.22],[1,4.8,20],[2,4.9,85.7]],"ltp":4.3,"tv":49.66,"id":3064881}]}]}
{"op":"mcm","clk":"1003069033","pt":1580602582793,"mc":[{"id":"1.168135751","rc":[{"batb":[[0,3.9,134.83],[1,3.8,2],[2,2.1,8.61]],"batl":[[2,4.9,0]],"ltp":4.3,"tv":49.66,"id":3064881}]}]}
{"op":"mcm","clk":"1003098908","pt":1580602967046,"mc":[{"id":"1.168135751","rc":[{"trd":[[2.54,74.7]],"batl":[[0,2.54,141.61]],"ltp":2.54,"tv":103.72,"id":2996932}],"tv":159.39}]}
{"op":"mcm","clk":"1003099392","pt":1580602973677,"mc":[{"id":"1.168135751","rc":[{"batl":[[1,2.56,165.52]],"ltp":2.54,"tv":103.72,"id":2996932}]}]}
{"op":"mcm","clk":"1003101602","pt":1580603004008,"mc":[{"id":"1.168135751","rc":[{"batl":[[0,2.56,165.52],[1,2.56,0]],"ltp":2.54,"tv":103.72,"id":2996932},{"batb":[[2,2.64,128.55]],"ltp":2.7,"tv":6.0,"id":3064880}]}]}
{"op":"mcm","clk":"1003119926","pt":1580603254811,"mc":[{"id":"1.168135751","rc":[{"batb":[[1,2.64,128.55],[2,2.54,4]],"ltp":2.7,"tv":6.0,"id":3064880}]}]}
{"op":"mcm","clk":"1003129162","pt":1580603357348,"mc":[{"id":"1.168135751","rc":[{"batl":[[0,2.5,19.67],[1,2.56,165.52]],"ltp":2.54,"tv":103.72,"id":2996932}]}]}
{"op":"mcm","clk":"1003132039","pt":1580603393942,"mc":[{"id":"1.168135751","rc":[{"batl":[[0,2.48,82.34],[1,2.5,19.67],[2,2.56,165.52]],"ltp":2.54,"tv":103.72,"id":2996932}]}]}
{"op":"mcm","clk":"1003140428","pt":1580603493845,"mc":[{"id":"1.168135751","rc":[{"batl":[[2,2.56,0]],"ltp":2.54,"tv":103.72,"id":2996932}]}]}
{"op":"mcm","clk":"1003168701","pt":1580603823883,"mc":[{"id":"1.168135751","rc":[{"batb":[[2,2.62,171.4]],"batl":[[0,3.1,163.84]],"ltp":2.7,"tv":6.0,"id":3064880}]}]}
{"op":"mcm","clk":"1003170715","pt":1580603853708,"mc":[{"id":"1.168135751","rc":[{"batb":[[1,2.62,171.4],[2,2.54,4]],"ltp":2.7,"tv":6.0,"id":3064880}]}]}
{"op":"mcm","clk":"1003175781","pt":1580603928817,"mc":[{"id":"1.168135751","rc":[{"batl":[[1,4.8,0]],"ltp":4.3,"tv":49.66,"id":3064881}]}]}
{"op":"mcm","clk":"1003175785","pt":1580603928917,"mc":[{"id":"1.168135751","rc":[{"batl":[[0,4.6,20],[1,4.7,67.22]],"ltp":4.3,"tv":49.66,"id":3064881}]}]}
{"op":"mcm","clk":"1003176754","pt":1580603944205,"mc":[{"id":"1.168135751","rc":[{"batl":[[0,3.05,117.63]],"ltp":2.7,"tv":6.0,"id":3064880},{"batl":[[0,4.5,24.37],[1,4.6,20]],"ltp":4.3,"tv":49.66,"id":3064881}]}]}
{"op":"mcm","clk":"1003178555","pt":1580603973726,"mc":[{"id":"1.168135751","rc":[{"batb":[[0,2.68,135.07]],"ltp":2.7,"tv":6.0,"id":3064880}]}]}
{"op":"mcm","clk":"1003180933","pt":1580604013684,"mc":[{"id":"1.168135751","rc":[{"batb":[[1,2.54,4],[2,1.01,1.01]],"ltp":2.7,"tv":6.0,"id":3064880}]}]}
{"op":"mcm","clk":"1003183587","pt":1580604054437,"mc":[{"id":"1.168135751","rc":[{"batl":[[0,4.5,44.37],[1,4.6,0]],"ltp":4.3,"tv":49.66,"id":3064881}]}]}
{"op":"mcm","clk":"1003202429","pt":1580604365805,"mc":[{"id":"1.168135751","rc":[{"batb":[[0,2.3,172.23]],"ltp":2.54,"tv":103.72,"id":2996932},{"batb":[[0,3.95,123.07],[1,3.9,134.43],[2,3.8,2]],"ltp":4.3,"tv":49.66,"id":3064881}]}]}
{"op":"mcm","clk":"1003202476","pt":1580604366732,"mc":[{"id":"1.168135751","rc":[{"batb":[[1,2.24,158.8],[2,2.2,20]],"ltp":2.54,"tv":103.72,"id":2996932}]}]}
{"op":"mcm","clk":"1003202883","pt":1580604373717,"mc":[{"id":"1.168135751","rc":[{"batb":[[1,2.2,20],[2,2.18,18]],"batl":[[0,2.48,76.46]],"ltp":2.54,"tv":103.72,"id":2996932},{"batb":[[0,2.68,88.02]],"ltp":2.7,"tv":6.0,"id":3064880},{"batb":[[0,3.9,134.83],[1,3.8,2],[2,2.1,8.61]],"ltp":4.3,"tv":49.66,"id":3064881}]}]}
{"op":"mcm","clk":"1003203194","pt":1580604380597,"mc":[{"id":"1.168135751","rc":[{"batl":[[0,4.5,52.77]],"ltp":4.3,"tv":49.66,"id":3064881}]}]}
{"op":"mcm","clk":"1003245895","pt":1580605089600,"mc":[{"id":"1.168135751","rc":[{"batb":[[0,2.32,159.64],[1,2.3,172.23],[2,2.2,20]],"ltp":2.54,"tv":103.72,"id":2996932}]}]}
{"op":"mcm","clk":"1003249269","pt":1580605151665,"mc":[{"id":"1.168135751","rc":[{"batb":[[0,2.34,68.9],[1,2.32,159.64],[2,2.3,172.23]],"ltp":2.54,"tv":103.72,"id":2996932}]}]}
{"op":"mcm","clk":"1003250718","pt":1580605178419,"mc":[{"id":"1.168135751","rc":[{"batb":[[0,2.36,159.64],[1,2.34,68.9]],"ltp":2.54,"tv":103.72,"id":2996932}]}]}
{"op":"mcm","clk":"1003256543","pt":1580605268685,"mc":[{"id":"1.168135751","rc":[{"batb":[[0,2.36,200.81]],"ltp":2.54,"tv":103.72,"id":2996932}]}]}
{"op":"mcm","clk":"1003264665","pt":1580605385841,"mc":[{"id":"1.168135751","rc":[{"batb":[[1,2.3,42],[2,2.2,20]],"ltp":2.54,"tv":103.72,"id":2996932}]}]}
{"op":"mcm","clk":"1003271969","pt":1580605489392,"mc":[{"id":"1.168135751","rc":[{"batb":[[0,2.36,41.17]],"ltp":2.54,"tv":103.72,"id":2996932}]}]}
{"op":"mcm","clk":"1003272972","pt":1580605502718,"mc":[{"id":"1.168135751","rc":[{"batb":[[1,2.32,84.02],[2,2.3,42]],"ltp":2.54,"tv":103.72,"id":2996932}]}]}
{"op":"mcm","clk":"1003281468","pt":1580605619622,"mc":[{"id":"1.168135751","rc":[{"batb":[[0,2.32,84.02],[1,2.3,42],[2,2.2,20]],"ltp":2.54,"tv":103.72,"id":2996932}]}]}
{"op":"mcm","clk":"1003316519","pt":1580606128450,"mc":[{"id":"1.168135751","rc":[{"trd":[[2.48,70.74]],"batl":[[0,2.48,41.08]],"ltp":2.48,"tv":174.46,"id":2996932}],"tv":230.13}]}
{"op":"mcm","clk":"1003322242","pt":1580606205185,"mc":[{"id":"1.168135751","rc":[{"batl":[[0,2.48,58.72]],"ltp":2.48,"tv":174.46,"id":2996932}]}]}
{"op":"mcm","clk":"1003337045","pt":1580606391720,"mc":[{"id":"1.168135751","rc":[{"batl":[[0,4.5,32.77]],"ltp":4.3,"tv":49.66,"id":3064881}]}]}
{"op":"mcm","clk":"1003337054","pt":1580606391821,"mc":[{"id":"1.168135751","rc":[{"batl":[[0,4.4,20],[1,4.5,32.77]],"ltp":4.3,"tv":49.66,"id":3064881}]}]}
{"op":"mcm","clk":"1003337877","pt":1580606403835,"mc":[{"id":"1.168135751","rc":[{"batb":[[0,2.72,68.9],[1,2.68,88.02],[2,2.54,4]],"ltp":2.7,"tv":6.0,"id":3064880}]}]}
{"op":"mcm","clk":"1003341997","pt":1580606460819,"mc":[{"id":"1.168135751","rc":[{"batb":[[1,2.68,4]],"ltp":2.7,"tv":6.0,"id":3064880}]}]}
{"op":"mcm","clk":"1003385495","pt":1580607039757,"mc":[{"id":"1.168135751","rc":[{"batl":[[0,3,11.65],[1,3.05,117.63]],"ltp":2.7,"tv":6.0,"id":3064880}]}]}
{"op":"mcm","clk":"1003407924","pt":1580607337292,"mc":[{"id":"1.168135751","rc":[{"trd":[[2.48,161.03]],"batl":[[0,2.48,13.58]],"ltp":2.48,"tv":264.75,"id":2996932}],"tv":320.42}]}
{"op":"mcm","clk":"1003408196","pt":1580607340700,"mc":[{"id":"1.168135751","rc":[{"batb":[[0,2.68,4],[1,2.54,4],[2,1.01,1.01]],"ltp":2.7,"tv":6.0,"id":3064880},{"batb":[[0,3.8,2.4],[1,2.1,8.61],[2,1.01,1.01]],"batl":[[1,4.5,0]],"ltp":4.3,"tv":49.66,"id":3064881}]}]}
{"op":"mcm","clk":"1003408223","pt":1580607341009,"mc":[{"id":"1.168135751","rc":[{"batb":[[0,2.32,125.19]],"batl":[[0,2.48,40.46]],"ltp":2.48,"tv":264.75,"id":2996932},{"batb":[[0,2.7,67.22],[1,2.68,4],[2,2.54,4]],"batl":[[1,3.05,164.68]],"ltp":2.7,"tv":6.0,"id":3064880},{"batb":[[0,3.85,118.03],[1,3.8,2],[2,2.1,8.61]],"batl":[[0,4.4,45.21]],"ltp":4.3,"tv":49.66,"id":3064881}]}]}
{"op":"mcm","clk":"1003420169","pt":1580607504413,"mc":[{"id":"1.168135751","rc":[{"trd":[[4.3,45.33]],"batb":[[0,3.85,117.63]],"batl":[[0,4.3,19.6],[1,4.4,25.21]],"ltp":4.3,"tv":50.46,"id":3064881}],"tv":321.22}]}
{"op":"mcm","clk":"1003420563","pt":1580607509874,"mc":[{"id":"1.168135751","rc":[{"batb":[[0,2.74,41.17],[1,2.7,67.22],[2,2.68,4]],"ltp":2.7,"tv":6.0,"id":3064880}]}]}
{"op":"mcm","clk":"1003424643","pt":1580607566773,"mc":[{"id":"1.168135751","rc":[{"batb":[[1,2.68,4],[2,2.54,4]],"ltp":2.7,"tv":6.0,"id":3064880}]}]}
{"op":"mcm","clk":"1003430046","pt":1580607636443,"mc":[{"id":"1.168135751","rc":[{"batl":[[1,2.5,0]],"ltp":2.48,"tv":264.75,"id":2996932}]}]}
{"op":"mcm","clk":"1003430920","pt":1580607646996,"mc":[{"id":"1.168135751","rc":[{"batl":[[0,4.4,25.21],[1,4.4,0]],"ltp":4.3,"tv":50.46,"id":3064881}]}]}
{"op":"mcm","clk":"1003432819","pt":1580607671811,"mc":[{"id":"1.168135751","rc":[{"trd":[[4.4,4.78]],"batl":[[0,4.4,24.82]],"ltp":4.4,"tv":51.24,"id":3064881}],"tv":321.99}]}
{"op":"mcm","clk":"1003435766","pt":1580607710751,"mc":[{"id":"1.168135751","rc":[{"batl":[[1,2.6,120.99]],"ltp":2.48,"tv":264.75,"id":2996932},{"batb":[[1,2.72,50.41],[2,2.68,4]],"ltp":2.7,"tv":6.0,"id":3064880},{"batl":[[1,4.8,82.34]],"ltp":4.4,"tv":51.24,"id":3064881}]}]}
{"op":"mcm","clk":"1003442586","pt":1580607798253,"mc":[{"id":"1.168135751","rc":[{"batl":[[0,2.6,120.99],[1,2.6,0]],"ltp":2.48,"tv":264.75,"id":2996932},{"batb":[[0,2.72,50.41],[1,2.68,4],[2,2.54,4]],"ltp":2.7,"tv":6.0,"id":3064880},{"batl":[[0,4.8,82.34],[1,4.8,0]],"ltp":4.4,"tv":51.24,"id":3064881}]}]}
{"op":"mcm","clk":"1003449727","pt":1580607894694,"mc":[{"id":"1.168135751","rc":[{"batb":[[2,2.6,168.04]],"ltp":2.7,"tv":6.0,"id":3064880}]}]}
{"op":"mcm","clk":"1003457672","pt":1580608001809,"mc":[{"id":"1.168135751","rc":[{"batb":[[0,2.68,4],[1,2.6,168.04],[2,2.54,4]],"ltp":2.7,"tv":6.0,"id":3064880}]}]}
{"op":"mcm","clk":"1003521563","pt":1580608938729,"mc":[{"id":"1.168135751","rc":[{"batl":[[1,2.62,178.12]],"ltp":2.48,"tv":264.75,"id":2996932},{"batl":[[0,4.8,126.87]],"ltp":4.4,"tv":51.24,"id":3064881}]}]}
{"op":"mcm","clk":"1003523557","pt":1580608969581,"mc":[{"id":"1.168135751","rc":[{"batl":[[0,2.62,178.12],[1,2.62,0]],"ltp":2.48,"tv":264.75,"id":2996932},{"batl":[[1,3.05,126.03]],"ltp":2.7,"tv":6.0,"id":3064880}]}]}
{"op":"mcm","clk":"1003528407","pt":1580609053694,"mc":[{"id":"1.168135751","rc":[{"batl":[[0,2.6,119.31],[1,2.62,178.12]],"ltp":2.48,"tv":264.75,"id":2996932}]}]}
{"op":"mcm","clk":"1003528827","pt":1580609060585,"mc":[{"id":"1.168135751","rc":[{"batl":[[1,2.62,0]],"ltp":2.48,"tv":264.75,"id":2996932},{"batl":[[0,4.8,83.18]],"ltp":4.4,"tv":51.24,"id":3064881}]}]}
{"op":"mcm","clk":"1003567873","pt":1580609620089,"mc":[{"id":"1.168135751","rc":[{"batl":[[0,2.9,336.08],[1,3,11.65],[2,3.05,126.03]],"ltp":2.7,"tv":6.0,"id":3064880}]}]}
{"op":"mcm","clk":"1003568702","pt":1580609632689,"mc":[{"id":"1.168135751","rc":[{"batl":[[0,4.4,252.06],[1,4.8,83.18]],"ltp":4.4,"tv":51.24,"id":3064881}]}]}
{"op":"mcm","clk":"1003569524","pt":1580609642705,"mc":[{"id":"1.168135751","rc":[{"batl":[[0,2.88,52.09],[1,2.9,336.08],[2,3,11.65]],"ltp":2.7,"tv":6.0,"id":3064880},{"batl":[[1,4.5,43.69],[2,4.8,83.18]],"ltp":4.4,"tv":51.24,"id":3064881}]}]}
{"op":"mcm","clk":"1003576490","pt":1580609742900,"mc":[{"id":"1.168135751","rc":[{"batb":[[0,2.36,76.46],[1,2.32,125.19],[2,2.3,42]],"ltp":2.48,"tv":264.75,"id":2996932},{"batl":[[0,4.4,275.58]],"ltp":4.4,"tv":51.24,"id":3064881}]}]}
{"op":"mcm","clk":"1003578544","pt":1580609772776,"mc":[{"id":"1.168135751","rc":[{"batb":[[1,2.3,42],[2,2.2,20]],"ltp":2.48,"tv":264.75,"id":2996932},{"batl":[[1,4.5,0],[2,4.8,0]],"ltp":4.4,"tv":51.24,"id":3064881}]}]}
{"op":"mcm","clk":"1003586279","pt":1580609889007,"mc":[{"id":"1.168135751","rc":[{"batl":[[0,2.86,50],[1,2.88,52.09],[2,2.9,336.08]],"ltp":2.7,"tv":6.0,"id":3064880}]}]}
{"op":"mcm","clk":"1003588642","pt":1580609922751,"mc":[{"id":"1.168135751","rc":[{"batl":[[0,2.86,82.77]],"ltp":2.7,"tv":6.0,"id":3064880}]}]}
{"op":"mcm","clk":"1003594234","pt":1580609992731,"mc":[{"id":"1.168135751","rc":[{"batl":[[1,2.9,336.08],[2,3,11.65]],"ltp":2.7,"tv":6.0,"id":3064880}]}]}
{"op":"mcm","clk":"1003600938","pt":1580610074529,"mc":[{"id":"1.168135751","rc":[{"trd":[[2.68,5.07]],"batb":[[0,2.68,1.46]],"ltp":2.68,"tv":11.07,"id":3064880}],"tv":327.07}]}
{"op":"mcm","clk":"1003601598","pt":1580610083055,"mc":[{"id":"1.168135751","rc":[{"trd":[[2.36,5.07]],"batb":[[0,2.36,73.92]],"ltp":2.36,"tv":269.82,"id":2996932}],"tv":332.14}]}
{"op":"mcm","clk":"1003615177","pt":1580610271175,"mc":[{"id":"1.168135751","rc":[{"batb":[[0,2.36,84.84]],"ltp":2.36,"tv":269.82,"id":2996932},{"batl":[[0,4.4,286.51]],"ltp":4.4,"tv":51.24,"id":3064881}]}]}
{"op":"mcm","clk":"1003615673","pt":1580610277779,"mc":[{"id":"1.168135751","rc":[{"batb":[[0,2.36,75.6]],"ltp":2.36,"tv":269.82,"id":2996932},{"batb":[[1,2.54,4],[2,1.01,1.01]],"batl":[[0,2.86,50]],"ltp":2.68,"tv":11.07,"id":3064880}]}]}
{"op":"mcm","clk":"1003616274","pt":1580610285299,"mc":[{"id":"1.168135751","rc":[{"batb":[[1,2.62,120.15],[2,2.54,4]],"batl":[[1,2.88,40.33],[2,2.9,336.08]],"ltp":2.68,"tv":11.07,"id":3064880}]}]}
{"op":"mcm","clk":"1003733372","pt":1580612063400,"mc":[{"id":"1.168135751","rc":[{"batb":[[1,2.34,64.33],[2,2.3,42]],"ltp":2.36,"tv":269.82,"id":2996932}]}]}
{"op":"mcm","clk":"1003765947","pt":1580612565761,"mc":[{"id":"1.168135751","rc":[{"batb":[[0,2.82,25.33],[1,2.68,1.46],[2,2.62,120.15]],"ltp":2.68,"tv":11.07,"id":3064880}]}]}
{"op":"mcm","clk":"1003766852","pt":1580612580583,"mc":[{"id":"1.168135751","rc":[{"batb":[[1,2.76,42.01],[2,2.68,1.46]],"ltp":2.68,"tv":11.07,"id":3064880}]}]}
{"op":"mcm","clk":"1003770236","pt":1580612640775,"mc":[{"id":"1.168135751","rc":[{"batb":[[0,2.76,42.01],[1,2.68,1.46],[2,2.62,120.15]],"ltp":2.68,"tv":11.07,"id":3064880}]}]}
{"op":"mcm","clk":"1003770295","pt":1580612641656,"mc":[{"id":"1.168135751","rc":[{"batb":[[0,2.84,25.33],[1,2.76,42.01],[2,2.68,1.46]],"ltp":2.68,"tv":11.07,"id":3064880}]}]}
{"op":"mcm","clk":"1003772470","pt":1580612675804,"mc":[{"id":"1.168135751","rc":[{"batb":[[0,2.76,42.01],[1,2.68,1.46],[2,2.62,120.15]],"ltp":2.68,"tv":11.07,"id":3064880}]}]}
{"op":"mcm","clk":"1003773182","pt":1580612688428,"mc":[{"id":"1.168135751","rc":[{"trd":[[2.86,60.81]],"batl":[[0,2.86,19.58]],"ltp":2.86,"tv":71.88,"id":3064880}],"tv":392.95}]}
{"op":"mcm","clk":"1003773612","pt":1580612697717,"mc":[{"id":"1.168135751","rc":[{"batb":[[0,2.68,1.46],[1,2.62,120.15],[2,2.54,4]],"ltp":2.86,"tv":71.88,"id":3064880}]}]}
{"op":"mcm","clk":"1003812598","pt":1580613648078,"mc":[{"id":"1.168135751","rc":[{"trd":[[2.6,16.8]],"batl":[[0,2.6,110.91]],"ltp":2.6,"tv":286.62,"id":2996932}],"tv":409.75}]}
{"op":"mcm","clk":"1003812664","pt":1580613649725,"mc":[{"id":"1.168135751","rc":[{"batl":[[0,2.86,43.11]],"ltp":2.86,"tv":71.88,"id":3064880}]}]}
{"op":"mcm","clk":"1003813853","pt":1580613679933,"mc":[{"id":"1.168135751","rc":[{"batl":[[0,2.6,133.59]],"ltp":2.6,"tv":286.62,"id":2996932}]}]}
{"op":"mcm","clk":"1003815331","pt":1580613719678,"mc":[{"id":"1.168135751","rc":[{"batl":[[1,2.9,336.08],[2,3,11.65]],"ltp":2.86,"tv":71.88,"id":3064880}]}]}
{"op":"mcm","clk":"1003819374","pt":1580613813592,"mc":[{"id":"1.168135751","rc":[{"trd":[[2.6,21.34]],"batl":[[0,2.6,131.32]],"ltp":2.6,"tv":291.16,"id":2996932}],"tv":414.29}]}
{"op":"mcm","clk":"1003875241","pt":1580614902227,"mc":[{"id":"1.168135751","rc":[{"batb":[[0,2.36,84]],"batl":[[1,2.62,164.68]],"ltp":2.6,"tv":291.16,"id":2996932},{"batb":[[2,2.6,164.68]],"batl":[[0,2.86,52.35]],"ltp":2.86,"tv":71.88,"id":3064880},{"batb":[[1,3.8,128.87]],"ltp":4.4,"tv":51.24,"id":3064881}]}]}
{"op":"mcm","clk":"1003876179","pt":1580614931786,"mc":[{"id":"1.168135751","rc":[{"batl":[[0,2.62,164.68],[1,2.62,0]],"ltp":2.6,"tv":291.16,"id":2996932},{"batb":[[1,2.6,164.68],[2,2.54,4]],"ltp":2.86,"tv":71.88,"id":3064880},{"batb":[[0,3.8,128.87],[1,2.1,8.61],[2,1.01,1.02]],"ltp":4.4,"tv":51.24,"id":3064881}]}]}
{"op":"mcm","clk":"1003994458","pt":1580617815369,"mc":[{"id":"1.168135751","rc":[{"batl":[[0,2.62,131.91]],"ltp":2.6,"tv":291.16,"id":2996932},{"batb":[[1,2.54,4],[2,1.01,1.02]],"batl":[[0,2.86,19.58]],"ltp":2.86,"tv":71.88,"id":3064880}]}]}
{"op":"mcm","clk":"1003995893","pt":1580617845183,"mc":[{"id":"1.168135751","rc":[{"batb":[[1,2.62,125.19],[2,2.54,4]],"batl":[[1,2.88,43.69],[2,2.9,336.08]],"ltp":2.86,"tv":71.88,"id":3064880},{"batl":[[0,4.4,292.39]],"ltp":4.4,"tv":51.24,"id":3064881}]}]}
{"op":"mcm","clk":"1004023474","pt":1580618445164,"mc":[{"id":"1.168135751","rc":[{"batb":[[1,2.62,171.4]],"ltp":2.86,"tv":71.88,"id":3064880}]}]}
{"op":"mcm","clk":"1004024890","pt":1580618474728,"mc":[{"id":"1.168135751","rc":[{"batl":[[1,2.88,33.61]],"ltp":2.86,"tv":71.88,"id":3064880}]}]}
{"op":"mcm","clk":"1004024929","pt":1580618475404,"mc":[{"id":"1.168135751","rc":[{"batb":[[0,2.34,64.33],[1,2.3,42],[2,2.2,20]],"ltp":2.6,"tv":291.16,"id":2996932},{"batb":[[1,2.54,4],[2,1.01,1.02]],"batl":[[1,2.9,336.08],[2,3,11.65]],"ltp":2.86,"tv":71.88,"id":3064880},{"batb":[[0,3.8,2]],"batl":[[0,4.4,252.06]],"ltp":4.4,"tv":51.24,"id":3064881}]}]}
{"op":"mcm","clk":"1004026798","pt":1580618511346,"mc":[{"id":"1.168135751","rc":[{"batb":[[0,2.38,67.22],[1,2.34,64.33],[2,2.3,42]],"batl":[[0,2.62,116.79]],"ltp":2.6,"tv":291.16,"id":2996932},{"batb":[[1,2.62,161.32],[2,2.54,4]],"batl":[[1,2.88,32.77],[2,2.9,336.08]],"ltp":2.86,"tv":71.88,"id":3064880},{"batb":[[0,3.8,133.07]],"batl":[[0,4.3,25.21],[1,4.4,252.06]],"ltp":4.4,"tv":51.24,"id":3064881}]}]}
{"op":"mcm","clk":"1004032924","pt":1580618624695,"mc":[{"id":"1.168135751","rc":[{"batb":[[0,2.7,107.03],[1,2.68,1.46],[2,2.62,161.32]],"ltp":2.86,"tv":71.88,"id":3064880}]}]}
{"op":"mcm","clk":"1004033262","pt":1580618630765,"mc":[{"id":"1.168135751","rc":[{"batb":[[0,2.72,68.06],[1,2.7,107.03],[2,2.68,1.46]],"ltp":2.86,"tv":71.88,"id":3064880}]}]}
{"op":"mcm","clk":"1004060679","pt":1580619278981,"mc":[{"id":"1.168135751","rc":[{"trd":[[2.62,16]],"batl":[[0,2.62,108.79]],"ltp":2.62,"tv":307.16,"id":2996932}],"tv":430.29}]}
{"op":"mcm","clk":"1004062155","pt":1580619317115,"mc":[{"id":"1.168135751","rc":[{"batl":[[0,4.3,50.21]],"ltp":4.4,"tv":51.24,"id":3064881}]}]}
{"op":"mcm","clk":"1004063545","pt":1580619360902,"mc":[{"id":"1.168135751","rc":[{"batb":[[0,2.38,73.94]],"ltp":2.62,"tv":307.16,"id":2996932},{"batl":[[1,2.88,42.85]],"ltp":2.86,"tv":71.88,"id":3064880}]}]}
{"op":"mcm","clk":"1004070082","pt":1580619540857,"mc":[{"id":"1.168135751","rc":[{"batl":[[0,2.62,131.47]],"ltp":2.62,"tv":307.16,"id":2996932}]}]}
{"op":"mcm","clk":"1004072307","pt":1580619611261,"mc":[{"id":"1.168135751","rc":[{"batb":[[0,2.72,59.65]],"batl":[[1,2.9,336.08],[2,3,11.65]],"ltp":2.86,"tv":71.88,"id":3064880},{"batl":[[0,4.3,25]],"ltp":4.4,"tv":51.24,"id":3064881}]}]}
{"op":"mcm","clk":"1004073275","pt":1580619640867,"mc":[{"id":"1.168135751","rc":[{"batb":[[0,2.38,84.02]],"batl":[[0,2.64,173.92]],"ltp":2.62,"tv":307.16,"id":2996932},{"batl":[[0,2.86,54.87]],"ltp":2.86,"tv":71.88,"id":3064880},{"batl":[[1,4.4,292.39]],"ltp":4.4,"tv":51.24,"id":3064881}]}]}
{"op":"mcm","clk":"1004081205","pt":1580619832731,"mc":[{"id":"1.168135751","rc":[{"trd":[[3.8,10.14]],"batb":[[0,3.8,128]],"ltp":3.8,"tv":61.38,"id":3064881}],"tv":440.43}]}
{"op":"mcm","clk":"1004085024","pt":1580619930653,"mc":[{"id":"1.168135751","rc":[{"batb":[[1,3.75,115.95],[2,2.1,8.61]],"batl":[[0,4.3,50.21]],"ltp":3.8,"tv":61.38,"id":3064881}]}]}
{"op":"mcm","clk":"1004086424","pt":1580619967689,"mc":[{"id":"1.168135751","rc":[{"batl":[[0,2.64,119.31]],"ltp":2.62,"tv":307.16,"id":2996932},{"batb":[[0,3.75,115.95],[1,2.1,8.61],[2,1.01,1.02]],"batl":[[1,4.4,252.06]],"ltp":3.8,"tv":61.38,"id":3064881}]}]}
{"op":"mcm","clk":"1004094862","pt":1580620190001,"mc":[{"id":"1.168135751","rc":[{"trd":[[2.38,101.36]],"batb":[[0,2.38,33.31]],"ltp":2.38,"tv":408.52,"id":2996932}],"tv":541.79}]}
{"op":"mcm","clk":"1004094903","pt":1580620191604,"mc":[{"id":"1.168135751","rc":[{"batl":[[0,2.86,19.58]],"ltp":2.86,"tv":71.88,"id":3064880},{"batb":[[0,2.1,8.61],[1,1.01,1.02],[2,1.01,0]],"batl":[[0,4.3,25]],"ltp":3.8,"tv":61.38,"id":3064881}]}]}
{"op":"mcm","clk":"1004094913","pt":1580620191867,"mc":[{"id":"1.168135751","rc":[{"batb":[[0,2.38,68.6]],"batl":[[0,2.62,159.64]],"ltp":2.38,"tv":408.52,"id":2996932},{"batb":[[0,2.72,77.3]],"batl":[[1,2.88,34.45],[2,2.9,336.08]],"ltp":2.86,"tv":71.88,"id":3064880},{"batb":[[0,3.8,133.59],[1,2.1,8.61],[2,1.01,1.02]],"batl":[[1,4.4,294.07]],"ltp":3.8,"tv":61.38,"id":3064881}]}]}
{"op":"mcm","clk":"1004108775","pt":1580620555948,"mc":[{"id":"1.168135751","rc":[{"batl":[[0,4.4,294.07],[1,4.4,0]],"ltp":3.8,"tv":61.38,"id":3064881}]}]}
{"op":"mcm","clk":"1004113418","pt":1580620649149,"mc":[{"id":"1.168135751","rc":[{"batl":[[0,2.62,131.91]],"ltp":2.38,"tv":408.52,"id":2996932},{"batb":[[0,2.1,8.61],[1,1.01,1.02],[2,1.01,0]],"ltp":3.8,"tv":61.38,"id":3064881}]}]}
{"op":"mcm","clk":"1004114732","pt":1580620678680,"mc":[{"id":"1.168135751","rc":[{"batb":[[0,3.75,132.75],[1,2.1,8.61],[2,1.01,1.02]],"batl":[[0,4.4,303.31]],"ltp":3.8,"tv":61.38,"id":3064881}]}]}
{"op":"mcm","clk":"1004151374","pt":1580621499102,"mc":[{"id":"1.168135751","rc":[{"batb":[[0,2.72,85.7]],"batl":[[2,2.9,378.93]],"ltp":2.86,"tv":71.88,"id":3064880}]}]}
{"op":"mcm","clk":"1004152454","pt":1580621528742,"mc":[{"id":"1.168135751","rc":[{"batl":[[1,2.9,378.93],[2,3,11.65]],"ltp":2.86,"tv":71.88,"id":3064880}]}]}
{"op":"mcm","clk":"1004158167","pt":1580621679148,"mc":[{"id":"1.168135751","rc":[{"batb":[[0,2.72,76.46]],"batl":[[1,2.9,336.08]],"ltp":2.86,"tv":71.88,"id":3064880}]}]}
{"op":"mcm","clk":"1004159300","pt":1580621710348,"mc":[{"id":"1.168135751","rc":[{"batb":[[0,2.38,73.64]],"ltp":2.38,"tv":408.52,"id":2996932},{"batl":[[1,2.88,32.77],[2,2.9,336.08]],"ltp":2.86,"tv":71.88,"id":3064880}]}]}
{"op":"mcm","clk":"1004159749","pt":1580621723279,"mc":[{"id":"1.168135751","rc":[{"batl":[[0,4.4,328.31]],"ltp":3.8,"tv":61.38,"id":3064881}]}]}
{"op":"mcm","clk":"1004167808","pt":1580621929848,"mc":[{"id":"1.168135751","rc":[{"batl":[[1,2.64,169.72]],"ltp":2.38,"tv":408.52,"id":2996932},{"batb":[[0,2.72,84.86]],"batl":[[2,2.9,379.77]],"ltp":2.86,"tv":71.88,"id":3064880},{"batl":[[0,4.4,336.71]],"ltp":3.8,"tv":61.38,"id":3064881}]}]}
{"op":"mcm","clk":"1004168967","pt":1580621960268,"mc":[{"id":"1.168135751","rc":[{"batl":[[0,2.64,169.72],[1,2.64,0]],"ltp":2.38,"tv":408.52,"id":2996932},{"batl":[[1,2.9,379.77],[2,3,11.65]],"ltp":2.86,"tv":71.88,"id":3064880}]}]}
{"op":"mcm","clk":"1004215804","pt":1580623430369,"mc":[{"id":"1.168135751","rc":[{"batb":[[2,2.3,38]],"ltp":2.38,"tv":408.52,"id":2996932}]}]}
{"op":"mcm","clk":"1004216300","pt":1580623443476,"mc":[{"id":"1.168135751","rc":[{"trd":[[2.64,6]],"batl":[[0,2.64,166.72]],"ltp":2.64,"tv":414.52,"id":2996932}],"tv":547.79}]}
{"op":"mcm","clk":"1004219719","pt":1580623549748,"mc":[{"id":"1.168135751","rc":[{"batl":[[1,2.88,26.05],[2,2.9,379.77]],"ltp":2.86,"tv":71.88,"id":3064880}]}]}
{"op":"mcm","clk":"1004220559","pt":1580623579803,"mc":[{"id":"1.168135751","rc":[{"batb":[[0,2.72,74.78]],"batl":[[2,2.9,336.08]],"ltp":2.86,"tv":71.88,"id":3064880}]}]}
{"op":"mcm","clk":"1004225928","pt":1580623788604,"mc":[{"id":"1.168135751","rc":[{"batb":[[0,2.44,78.51],[1,2.38,73.64],[2,2.34,64.33]],"ltp":2.64,"tv":414.52,"id":2996932}]}]}
{"op":"mcm","clk":"1004226240","pt":1580623800702,"mc":[{"id":"1.168135751","rc":[{"batb":[[1,2.42,42.85],[2,2.38,73.64]],"ltp":2.64,"tv":414.52,"id":2996932}]}]}
{"op":"mcm","clk":"1004226341","pt":1580623804552,"mc":[{"id":"1.168135751","rc":[{"batl":[[0,4.3,16.71],[1,4.4,336.71]],"ltp":3.8,"tv":61.38,"id":3064881}]}]}
{"op":"mcm","clk":"1004228797","pt":1580623881887,"mc":[{"id":"1.168135751","rc":[{"batb":[[2,2.34,64.33]],"ltp":2.64,"tv":414.52,"id":2996932}]}]}
{"op":"mcm","clk":"1004232975","pt":1580624010052,"mc":[{"id":"1.168135751","rc":[{"batl":[[0,4.4,336.71],[1,4.4,0]],"ltp":3.8,"tv":61.38,"id":3064881}]}]}
{"op":"mcm","clk":"1004250234","pt":1580624543218,"mc":[{"id":"1.168135751","rc":[{"trd":[[3.75,5.44]],"batb":[[0,3.75,130.03]],"ltp":3.75,"tv":66.82,"id":3064881}],"tv":553.23}]}
{"op":"mcm","clk":"1004252673","pt":1580624621652,"mc":[{"id":"1.168135751","rc":[{"batb":[[0,2.72,85.7]],"batl":[[2,2.9,378.93]],"ltp":2.86,"tv":71.88,"id":3064880}]}]}
{"op":"mcm","clk":"1004253639","pt":1580624651906,"mc":[{"id":"1.168135751","rc":[{"batl":[[1,2.9,378.93],[2,3,11.65]],"ltp":2.86,"tv":71.88,"id":3064880}]}]}
{"op":"mcm","clk":"1004260574","pt":1580624881775,"mc":[{"id":"1.168135751","rc":[{"batb":[[2,2.4,41.17]],"batl":[[0,2.62,169.72],[1,2.64,166.72]],"ltp":2.64,"tv":414.52,"id":2996932}]}]}
{"op":"mcm","clk":"1004260797","pt":1580624888702,"mc":[{"id":"1.168135751","rc":[{"batb":[[1,2.4,41.17],[2,2.34,64.33]],"batl":[[1,2.64,0]],"ltp":2.64,"tv":414.52,"id":2996932},{"batl":[[1,2.9,362.96]],"ltp":2.86,"tv":71.88,"id":3064880}]}]}
{"op":"mcm","clk":"1004263390","pt":1580624992070,"mc":[{"id":"1.168135751","rc":[{"batl":[[2,3,0]],"ltp":2.86,"tv":71.88,"id":3064880}]}]}
{"op":"mcm","clk":"1004274000","pt":1580625339719,"mc":[{"id":"1.168135751","rc":[{"trd":[[2.62,178]],"batl":[[0,2.62,88.72]],"ltp":2.62,"tv":576.52,"id":2996932}],"tv":715.23}]}
{"op":"mcm","clk":"1004274084","pt":1580625342544,"mc":[{"id":"1.168135751","rc":[{"batb":[[0,2.44,119.68]],"batl":[[1,2.66,135.27]],"ltp":2.62,"tv":576.52,"id":2996932},{"batl":[[1,2.88,34.45],[2,2.9,362.96]],"ltp":2.86,"tv":71.88,"id":3064880},{"batb":[[1,3.7,122.67],[2,2.1,8.61]],"batl":[[0,4.4,344.27]],"ltp":3.75,"tv":66.82,"id":3064881}]}]}
{"op":"mcm","clk":"1004274292","pt":1580625349541,"mc":[{"id":"1.168135751","rc":[{"batb":[[1,2.34,64.33],[2,2.3,38]],"batl":[[0,2.66,135.27],[1,2.66,0]],"ltp":2.62,"tv":576.52,"id":2996932},{"batb":[[0,2.72,66.38]],"batl":[[2,2.9,336.08]],"ltp":2.86,"tv":71.88,"id":3064880},{"batb":[[0,3.7,122.67],[1,2.1,8.61],[2,1.01,1.02]],"ltp":3.75,"tv":66.82,"id":3064881}]}]}
{"op":"mcm","clk":"1004276231","pt":1580625409535,"mc":[{"id":"1.168135751","rc":[{"batb":[[0,2.46,3.46],[1,2.44,119.68],[2,2.34,64.33]],"batl":[[0,2.64,3.29],[1,2.66,135.27]],"ltp":2.62,"tv":576.52,"id":2996932},{"batl":[[1,2.88,41.96]],"ltp":2.86,"tv":71.88,"id":3064880},{"batb":[[0,3.75,2.53],[1,3.7,122.67],[2,2.1,8.61]],"batl":[[0,4.3,6.03],[1,4.4,344.27]],"ltp":3.75,"tv":66.82,"id":3064881}]}]}
{"op":"mcm","clk":"1004283942","pt":1580625634736,"mc":[{"id":"1.168135751","rc":[{"batb":[[0,2.72,73.94]],"ltp":2.86,"tv":71.88,"id":3064880}]}]}
{"op":"mcm","clk":"1004301533","pt":1580626293248,"mc":[{"id":"1.168135751","rc":[{"batl":[[1,2.66,160.48]],"ltp":2.62,"tv":576.52,"id":2996932}]}]}
{"op":"mcm","clk":"1004302521","pt":1580626323394,"mc":[{"id":"1.168135751","rc":[{"batb":[[1,2.44,111.28]],"ltp":2.62,"tv":576.52,"id":2996932}]}]}
{"op":"mcm","clk":"1004312985","pt":1580626606245,"mc":[{"id":"1.168135751","rc":[{"batl":[[0,4,4.05],[1,4.3,6.03],[2,4.4,344.27]],"ltp":3.75,"tv":66.82,"id":3064881}]}]}
{"op":"mcm","clk":"1004313529","pt":1580626622781,"mc":[{"id":"1.168135751","rc":[{"trd":[[4,8.11]],"batb":[[0,4,28.71],[1,3.75,2.53],[2,3.7,122.67]],"batl":[[0,4.3,6.03],[1,4.4,344.27],[2,4.4,0]],"ltp":4.0,"tv":74.93,"id":3064881}],"tv":723.34}]}
{"op":"mcm","clk":"1004313836","pt":1580626631391,"mc":[{"id":"1.168135751","rc":[{"batb":[[0,2.74,3.1],[1,2.72,73.94],[2,2.7,107.03]],"ltp":2.86,"tv":71.88,"id":3064880},{"batl":[[0,4.4,344.27],[1,1000,6.03]],"ltp":4.0,"tv":74.93,"id":3064881}]}]}
{"op":"mcm","clk":"1004314118","pt":1580626639622,"mc":[{"id":"1.168135751","rc":[{"batl":[[0,2.6,3.29]],"ltp":2.62,"tv":576.52,"id":2996932},{"batb":[[1,3.7,122.67],[2,2.1,8.61]],"ltp":4.0,"tv":74.93,"id":3064881}]}]}
{"op":"mcm","clk":"1004314408","pt":1580626649340,"mc":[{"id":"1.168135751","rc":[{"batb":[[0,2.72,73.94],[1,2.7,107.03],[2,2.68,1.46]],"ltp":2.86,"tv":71.88,"id":3064880}]}]}
{"op":"mcm","clk":"1004316335","pt":1580626712632,"mc":[{"id":"1.168135751","rc":[{"batb":[[1,2.44,118.84]],"batl":[[0,2.6,86.47]],"ltp":2.62,"tv":576.52,"id":2996932}]}]}
{"op":"mcm","clk":"1004317119","pt":1580626743656,"mc":[{"id":"1.168135751","rc":[{"batl":[[1,2.66,0]],"ltp":2.62,"tv":576.52,"id":2996932},{"batb":[[0,3.7,122.67],[1,2.1,8.61],[2,1.5,2.53]],"ltp":4.0,"tv":74.93,"id":3064881}]}]}
{"op":"mcm","clk":"1004317159","pt":1580626745656,"mc":[{"id":"1.168135751","rc":[{"batl":[[0,2.6,83.18],[1,1000,3.29]],"ltp":2.62,"tv":576.52,"id":2996932},{"batb":[[0,2.74,3.1],[1,2.72,73.94],[2,2.7,107.03]],"ltp":2.86,"tv":71.88,"id":3064880},{"batb":[[0,3.75,2.53],[1,3.7,122.67],[2,2.1,8.61]],"batl":[[0,4.3,5.87],[1,4.4,344.27],[2,1000,6.03]],"ltp":4.0,"tv":74.93,"id":3064881}]}]}
{"op":"mcm","clk":"1004318133","pt":1580626782623,"mc":[{"id":"1.168135751","rc":[{"batl":[[1,2.66,120.15],[2,2.76,6.64]],"ltp":2.62,"tv":576.52,"id":2996932},{"batb":[[0,3.8,83.18],[1,3.75,2.53],[2,3.7,122.67]],"ltp":4.0,"tv":74.93,"id":3064881}]}]}
{"op":"mcm","clk":"1004319771","pt":1580626824526,"mc":[{"id":"1.168135751","rc":[{"batb":[[0,3.85,2.53],[1,3.8,83.18]],"ltp":4.0,"tv":74.93,"id":3064881}]}]}
{"op":"mcm","clk":"1004319974","pt":1580626832647,"mc":[{"id":"1.168135751","rc":[{"batb":[[1,2.44,111.28]],"batl":[[0,2.76,6.64],[1,1000,3.29],[2,2.76,0]],"ltp":2.62,"tv":576.52,"id":2996932},{"batl":[[1,2.88,7.52]],"ltp":2.86,"tv":71.88,"id":3064880},{"batb":[[2,2.1,8.61]],"ltp":4.0,"tv":74.93,"id":3064881}]}]}
{"op":"mcm","clk":"1004320046","pt":1580626834409,"mc":[{"id":"1.168135751","rc":[{"batb":[[0,2.72,73.94],[1,2.7,107.03],[2,2.68,1.46]],"ltp":2.86,"tv":71.88,"id":3064880}]}]}
{"op":"mcm","clk":"1004320637","pt":1580626850678,"mc":[{"id":"1.168135751","rc":[{"batl":[[0,2.7,6.64]],"ltp":2.62,"tv":576.52,"id":2996932}]}]}
{"op":"mcm","clk":"1004321288","pt":1580626862662,"mc":[{"id":"1.168135751","rc":[{"batl":[[0,2.64,130.23],[1,2.7,6.64],[2,1000,3.29]],"ltp":2.62,"tv":576.52,"id":2996932},{"batb":[[0,2.72,82.34]],"batl":[[2,2.9,368.01]],"ltp":2.86,"tv":71.88,"id":3064880},{"batb":[[2,3.7,133.59]],"batl":[[1,4.4,352.68]],"ltp":4.0,"tv":74.93,"id":3064881}]}]}
{"op":"mcm","clk":"1004321414","pt":1580626866571,"mc":[{"id":"1.168135751","rc":[{"batl":[[1,2.7,3.15]],"ltp":2.62,"tv":576.52,"id":2996932}]}]}
{"op":"mcm","clk":"1004322272","pt":1580626902695,"mc":[{"id":"1.168135751","rc":[{"batb":[[1,3.7,133.59],[2,2.1,8.61]],"ltp":4.0,"tv":74.93,"id":3064881}]}]}
{"op":"mcm","clk":"1004322373","pt":1580626906640,"mc":[{"id":"1.168135751","rc":[{"batb":[[0,2.74,3.1],[1,2.72,82.34],[2,2.7,107.03]],"ltp":2.86,"tv":71.88,"id":3064880},{"batb":[[0,3.75,2.53]],"ltp":4.0,"tv":74.93,"id":3064881}]}]}
{"op":"mcm","clk":"1004323052","pt":1580626933783,"mc":[{"id":"1.168135751","rc":[{"batl":[[0,2.62,3.15],[1,2.64,130.23]],"ltp":2.62,"tv":576.52,"id":2996932}]}]}
{"op":"mcm","clk":"1004326475","pt":1580627065726,"mc":[{"id":"1.168135751","rc":[{"batb":[[0,2.6,23.3],[1,2.46,3.46],[2,2.44,111.28]],"ltp":2.62,"tv":576.52,"id":2996932}]}]}
{"op":"mcm","clk":"1004326512","pt":1580627066851,"mc":[{"id":"1.168135751","rc":[{"batl":[[0,2.64,130.23],[1,1000,3.29],[2,1000,0]],"ltp":2.62,"tv":576.52,"id":2996932}]}]}
{"op":"mcm","clk":"1004326674","pt":1580627072572,"mc":[{"id":"1.168135751","rc":[{"trd":[[2.6,40.44]],"batb":[[0,2.6,13.75]],"ltp":2.6,"tv":595.62,"id":2996932}],"tv":742.44}]}
{"op":"mcm","clk":"1004326771","pt":1580627075657,"mc":[{"id":"1.168135751","rc":[{"trd":[[2.6,59.53]],"batb":[[0,2.6,4.2]],"ltp":2.6,"tv":614.71,"id":2996932}],"tv":761.53}]}
{"op":"mcm","clk":"1004326917","pt":1580627079774,"mc":[{"id":"1.168135751","rc":[{"trd":[[2.6,67.78]],"batb":[[0,2.46,3.54],[1,2.44,111.28],[2,2.34,64.33]],"ltp":2.6,"tv":622.96,"id":2996932}],"tv":769.78}]}
{"op":"mcm","clk":"1004327737","pt":1580627103588,"mc":[{"id":"1.168135751","rc":[{"batb":[[0,3.75,52.53]],"ltp":4.0,"tv":74.93,"id":3064881}]}]}
{"op":"mcm","clk":"1004328010","pt":1580627110897,"mc":[{"id":"1.168135751","rc":[{"batb":[[0,2.72,82.34],[1,2.7,107.03],[2,2.68,1.46]],"ltp":2.86,"tv":71.88,"id":3064880}]}]}
{"op":"mcm","clk":"1004328887","pt":1580627134828,"mc":[{"id":"1.168135751","rc":[{"batl":[[0,2.62,3.25],[1,2.64,130.23],[2,1000,3.29]],"ltp":2.6,"tv":622.96,"id":2996932}]}]}
{"op":"mcm","clk":"1004329128","pt":1580627140956,"mc":[{"id":"1.168135751","rc":[{"trd":[[3.75,56.12]],"batb":[[0,3.75,27.18]],"ltp":3.75,"tv":125.61,"id":3064881}],"tv":820.46}]}
{"op":"mcm","clk":"1004329338","pt":1580627146142,"mc":[{"id":"1.168135751","rc":[{"batb":[[0,3.75,27.22]],"batl":[[0,4.3,2.53]],"ltp":3.75,"tv":125.61,"id":3064881}]}]}
{"op":"mcm","clk":"1004329887","pt":1580627162773,"mc":[{"id":"1.168135751","rc":[{"batb":[[0,3.8,83.21],[1,3.75,27.18],[2,3.7,133.59]],"ltp":3.75,"tv":125.61,"id":3064881}]}]}
{"op":"mcm","clk":"1004333097","pt":1580627252816,"mc":[{"id":"1.168135751","rc":[{"batl":[[2,2.66,172.24]],"ltp":2.6,"tv":622.96,"id":2996932}]}]}
{"op":"mcm","clk":"1004334250","pt":1580627283812,"mc":[{"id":"1.168135751","rc":[{"batl":[[2,1000,3.29]],"ltp":2.6,"tv":622.96,"id":2996932},{"batb":[[2,2.1,8.61]],"ltp":3.75,"tv":125.61,"id":3064881}]}]}
{"op":"mcm","clk":"1004335765","pt":1580627325752,"mc":[{"id":"1.168135751","rc":[{"batl":[[2,2.66,176.44]],"ltp":2.6,"tv":622.96,"id":2996932}]}]}
{"op":"mcm","clk":"1004336033","pt":1580627332782,"mc":[{"id":"1.168135751","rc":[{"batl":[[1,2.66,176.44],[2,1000,3.29]],"ltp":2.6,"tv":622.96,"id":2996932}]}]}
{"op":"mcm","clk":"1004336228","pt":1580627339306,"mc":[{"id":"1.168135751","rc":[{"batl":[[0,2.64,3.25]],"ltp":2.6,"tv":622.96,"id":2996932}]}]}
{"op":"mcm","clk":"1004350001","pt":1580627701728,"mc":[{"id":"1.168135751","rc":[{"batb":[[0,2.44,111.36],[1,2.34,64.33],[2,2.3,38]],"batl":[[0,2.66,176.44],[1,2.66,0],[2,1000,0]],"ltp":2.6,"tv":622.96,"id":2996932},{"batl":[[1,2.9,368.01],[2,2.9,0]],"ltp":2.86,"tv":71.88,"id":3064880},{"batb":[[0,3.8,83.18]],"batl":[[0,4.4,352.68],[1,4.4,0],[2,1000,0]],"ltp":3.75,"tv":125.61,"id":3064881}]}]}
{"op":"mcm","clk":"1004350571","pt":1580627715721,"mc":[{"id":"1.168135751","rc":[{"batb":[[0,2.46,3.54],[1,2.44,111.28],[2,2.34,64.33]],"batl":[[0,2.64,3.87],[1,2.66,176.44]],"ltp":2.6,"tv":622.96,"id":2996932},{"batl":[[1,2.88,7.82],[2,2.9,368.01]],"ltp":2.86,"tv":71.88,"id":3064880},{"batb":[[0,3.85,2.53],[1,3.8,83.18],[2,3.75,27.18]],"batl":[[0,4.3,2.53],[1,4.4,352.68]],"ltp":3.75,"tv":125.61,"id":3064881}]}]}
{"op":"mcm","clk":"1004362143","pt":1580628004761,"mc":[{"id":"1.168135751","rc":[{"batb":[[2,2.3,38]],"ltp":2.6,"tv":622.96,"id":2996932}]}]}
{"op":"mcm","clk":"1004364928","pt":1580628064820,"mc":[{"id":"1.168135751","rc":[{"batb":[[0,2.48,26.93],[1,2.46,3.46],[2,2.44,111.28]],"ltp":2.6,"tv":622.96,"id":2996932}]}]}
{"op":"mcm","clk":"1004366011","pt":1580628087286,"mc":[{"id":"1.168135751","rc":[{"batb":[[0,2.5,3.54],[1,2.48,26.84]],"ltp":2.6,"tv":622.96,"id":2996932}]}]}
{"op":"mcm","clk":"1004366455","pt":1580628094379,"mc":[{"id":"1.168135751","rc":[{"trd":[[2.5,6.77],[2.6,67.94]],"batb":[[0,2.48,26.92],[1,2.44,111.28],[2,2.3,38]],"ltp":2.5,"tv":629.89,"id":2996932}],"tv":827.39}]}
{"op":"mcm","clk":"1004366644","pt":1580628095250,"mc":[{"id":"1.168135751","rc":[{"batl":[[0,2.64,3.21]],"ltp":2.5,"tv":629.89,"id":2996932},{"batb":[[2,2.1,8.61]],"ltp":3.75,"tv":125.61,"id":3064881}]}]}
{"op":"mcm","clk":"1004370827","pt":1580628189406,"mc":[{"id":"1.168135751","rc":[{"batb":[[0,2.48,26.84],[1,2.44,111.35]],"ltp":2.5,"tv":629.89,"id":2996932},{"batb":[[2,3.7,136.11]],"ltp":3.75,"tv":125.61,"id":3064881}]}]}
{"op":"mcm","clk":"1004371600","pt":1580628207624,"mc":[{"id":"1.168135751","rc":[{"trd":[[2.48,181.04]],"batb":[[0,2.48,16.84]],"ltp":2.48,"tv":649.9,"id":2996932}],"tv":847.39}]}
{"op":"mcm","clk":"1004371738","pt":1580628210711,"mc":[{"id":"1.168135751","rc":[{"trd":[[2.48,186.1]],"batb":[[0,2.48,14.31]],"ltp":2.48,"tv":654.96,"id":2996932}],"tv":852.46}]}
{"op":"mcm","clk":"1004374774","pt":1580628305775,"mc":[{"id":"1.168135751","rc":[{"batb":[[1,3.7,136.11],[2,2.1,8.61]],"ltp":3.75,"tv":125.61,"id":3064881}]}]}
{"op":"mcm","clk":"1004375094","pt":1580628313558,"mc":[{"id":"1.168135751","rc":[{"batb":[[0,3.75,2.53]],"ltp":3.75,"tv":125.61,"id":3064881}]}]}
{"op":"mcm","clk":"1004376005","pt":1580628338978,"mc":[{"id":"1.168135751","rc":[{"batb":[[0,3.75,52.53]],"ltp":3.75,"tv":125.61,"id":3064881}]}]}
{"op":"mcm","clk":"1004378191","pt":1580628385576,"mc":[{"id":"1.168135751","rc":[{"batb":[[1,2.44,111.28]],"batl":[[0,2.66,176.44],[1,2.66,0]],"ltp":2.48,"tv":654.96,"id":2996932},{"batl":[[1,2.9,368.01],[2,2.9,0]],"ltp":2.86,"tv":71.88,"id":3064880},{"batb":[[0,3.75,50]],"batl":[[0,4.4,352.68],[1,4.4,0]],"ltp":3.75,"tv":125.61,"id":3064881}]}]}
{"op":"mcm","clk":"1004380005","pt":1580628422941,"mc":[{"id":"1.168135751","rc":[{"batb":[[0,3.8,82.34],[1,3.75,50],[2,3.7,136.11]],"ltp":3.75,"tv":125.61,"id":3064881}]}]}
{"op":"mcm","clk":"1004381759","pt":1580628473568,"mc":[{"id":"1.168135751","rc":[{"batb":[[1,2.46,3.46],[2,2.44,111.28]],"batl":[[0,2.64,3.21],[1,2.66,176.44]],"ltp":2.48,"tv":654.96,"id":2996932},{"batl":[[1,2.88,8.68],[2,2.9,368.01]],"ltp":2.86,"tv":71.88,"id":3064880},{"batb":[[1,3.75,52.53]],"batl":[[0,4.3,2.53],[1,4.4,352.68]],"ltp":3.75,"tv":125.61,"id":3064881}]}]}
{"op":"mcm","clk":"1004383629","pt":1580628522655,"mc":[{"id":"1.168135751","rc":[{"batb":[[1,2.44,111.28],[2,2.3,38]],"batl":[[0,2.66,176.44],[1,2.66,0]],"ltp":2.48,"tv":654.96,"id":2996932},{"batl":[[1,2.9,368.01],[2,2.9,0]],"ltp":2.86,"tv":71.88,"id":3064880},{"batb":[[1,3.75,50]],"batl":[[0,4.4,352.68],[1,4.4,0]],"ltp":3.75,"tv":125.61,"id":3064881}]}]}
{"op":"mcm","clk":"1004384175","pt":1580628538704,"mc":[{"id":"1.168135751","rc":[{"batb":[[1,2.46,3.46],[2,2.44,111.28]],"batl":[[0,2.64,3.21],[1,2.66,176.44]],"ltp":2.48,"tv":654.96,"id":2996932},{"batl":[[1,2.88,8.71],[2,2.9,368.01]],"ltp":2.86,"tv":71.88,"id":3064880},{"batb":[[0,3.85,2.53],[1,3.8,82.34],[2,3.75,50]],"batl":[[0,4.3,2.53],[1,4.4,352.68]],"ltp":3.75,"tv":125.61,"id":3064881}]}]}
{"op":"mcm","clk":"1004384259","pt":1580628540768,"mc":[{"id":"1.168135751","rc":[{"batl":[[0,2.64,119.99]],"ltp":2.48,"tv":654.96,"id":2996932}]}]}
{"op":"mcm","clk":"1004385379","pt":1580628569815,"mc":[{"id":"1.168135751","rc":[{"batb":[[2,2.44,78.51]],"batl":[[1,2.66,0]],"ltp":2.48,"tv":654.96,"id":2996932}]}]}
{"op":"mcm","clk":"1004385660","pt":1580628576732,"mc":[{"id":"1.168135751","rc":[{"batb":[[1,2.44,78.51],[2,2.42,50.41]],"batl":[[0,2.64,116.79]],"ltp":2.48,"tv":654.96,"id":2996932},{"batl":[[1,2.9,368.01],[2,2.9,0]],"ltp":2.86,"tv":71.88,"id":3064880},{"batb":[[0,3.8,82.34],[1,3.75,50],[2,2.1,8.61]],"batl":[[0,4.4,352.68],[1,4.4,0]],"ltp":3.75,"tv":125.61,"id":3064881}]}]}
{"op":"mcm","clk":"1004385790","pt":1580628580749,"mc":[{"id":"1.168135751","rc":[{"batb":[[1,2.46,3.46],[2,2.44,78.51]],"batl":[[0,2.62,3.23],[1,2.64,116.79]],"ltp":2.48,"tv":654.96,"id":2996932},{"batl":[[1,2.88,8.37],[2,2.9,368.01]],"ltp":2.86,"tv":71.88,"id":3064880},{"batb":[[0,3.85,2.53],[1,3.8,82.34],[2,3.75,50]],"batl":[[0,4.3,2.53],[1,4.4,352.68]],"ltp":3.75,"tv":125.61,"id":3064881}]}]}
{"op":"mcm","clk":"1004387363","pt":1580628618677,"mc":[{"id":"1.168135751","rc":[{"batb":[[0,2.5,2],[1,2.48,14.31],[2,2.46,3.46]],"ltp":2.48,"tv":654.96,"id":2996932},{"batb":[[0,2.74,2],[1,2.72,82.34],[2,2.7,107.03]],"ltp":2.86,"tv":71.88,"id":3064880},{"batb":[[0,3.9,2],[1,3.85,2.53],[2,3.8,82.34]],"ltp":3.75,"tv":125.61,"id":3064881}]}]}
{"op":"mcm","clk":"1004391520","pt":1580628719778,"mc":[{"id":"1.168135751","rc":[{"batb":[[2,3.75,50]],"ltp":3.75,"tv":125.61,"id":3064881}]}]}
{"op":"mcm","clk":"1004392092","pt":1580628732091,"mc":[{"id":"1.168135751","rc":[{"batb":[[1,3.8,2.53]],"ltp":3.75,"tv":125.61,"id":3064881}]}]}
{"op":"mcm","clk":"1004394680","pt":1580628789801,"mc":[{"id":"1.168135751","rc":[{"batb":[[1,3.8,86.55]],"ltp":3.75,"tv":125.61,"id":3064881}]}]}
{"op":"mcm","clk":"1004404486","pt":1580629060083,"mc":[{"id":"1.168135751","rc":[{"batl":[[0,2.6,211.1],[1,2.62,3.23],[2,2.64,116.79]],"ltp":2.48,"tv":654.96,"id":2996932}]}]}
{"op":"mcm","clk":"1004404621","pt":1580629063362,"mc":[{"id":"1.168135751","rc":[{"batb":[[0,2.74,5.1]],"ltp":2.86,"tv":71.88,"id":3064880}]}]}
{"op":"mcm","clk":"1004405093","pt":1580629073505,"mc":[{"id":"1.168135751","rc":[{"batl":[[0,2.58,3.23],[1,2.6,211.1]],"ltp":2.48,"tv":654.96,"id":2996932}]}]}
{"op":"mcm","clk":"1004407099","pt":1580629119759,"mc":[{"id":"1.168135751","rc":[{"batl":[[0,2.58,88.93]],"ltp":2.48,"tv":654.96,"id":2996932}]}]}
{"op":"mcm","clk":"1004407577","pt":1580629130380,"mc":[{"id":"1.168135751","rc":[{"batl":[[0,2.58,300.02],[1,2.64,116.79],[2,2.64,0]],"ltp":2.48,"tv":654.96,"id":2996932}]}]}
{"op":"mcm","clk":"1004409936","pt":1580629187439,"mc":[{"id":"1.168135751","rc":[{"batb":[[2,2.1,8.61]],"ltp":3.75,"tv":125.61,"id":3064881}]}]}
{"op":"mcm","clk":"1004410793","pt":1580629209974,"mc":[{"id":"1.168135751","rc":[{"batl":[[1,2.64,0]],"ltp":2.48,"tv":654.96,"id":2996932}]}]}
{"op":"mcm","clk":"1004411171","pt":1580629218797,"mc":[{"id":"1.168135751","rc":[{"batb":[[0,2.48,14.31],[1,2.46,3.46],[2,2.44,78.51]],"ltp":2.48,"tv":654.96,"id":2996932},{"batb":[[0,2.74,3.1]],"ltp":2.86,"tv":71.88,"id":3064880},{"batb":[[0,3.8,86.55],[1,2.1,8.61],[2,1.01,1.02]],"ltp":3.75,"tv":125.61,"id":3064881}]}]}
{"op":"mcm","clk":"1004411559","pt":1580629227382,"mc":[{"id":"1.168135751","rc":[{"batb":[[0,2.76,2],[1,2.74,3.1],[2,2.72,82.34]],"ltp":2.86,"tv":71.88,"id":3064880},{"batb":[[0,3.85,2],[1,3.8,86.55],[2,2.1,8.61]],"ltp":3.75,"tv":125.61,"id":3064881}]}]}
{"op":"mcm","clk":"1004412269","pt":1580629246820,"mc":[{"id":"1.168135751","rc":[{"batl":[[0,2.56,211.1],[1,2.58,88.93]],"ltp":2.48,"tv":654.96,"id":2996932}]}]}
{"op":"mcm","clk":"1004412616","pt":1580629260729,"mc":[{"id":"1.168135751","rc":[{"batl":[[1,2.58,85.7]],"ltp":2.48,"tv":654.96,"id":2996932}]}]}
{"op":"mcm","clk":"1004412618","pt":1580629260831,"mc":[{"id":"1.168135751","rc":[{"batl":[[0,2.54,3.23],[1,2.56,211.1],[2,2.58,85.7]],"ltp":2.48,"tv":654.96,"id":2996932}]}]}
{"op":"mcm","clk":"1004413366","pt":1580629279755,"mc":[{"id":"1.168135751","rc":[{"batl":[[0,2.54,61.2]],"ltp":2.48,"tv":654.96,"id":2996932}]}]}
{"op":"mcm","clk":"1004413542","pt":1580629281767,"mc":[{"id":"1.168135751","rc":[{"batl":[[0,2.54,61.3]],"ltp":2.48,"tv":654.96,"id":2996932}]}]}
{"op":"mcm","clk":"1004415898","pt":1580629330137,"mc":[{"id":"1.168135751","rc":[{"batl":[[2,2.58,0]],"ltp":2.48,"tv":654.96,"id":2996932},{"batb":[[2,2.7,107.03]],"ltp":2.86,"tv":71.88,"id":3064880},{"batb":[[0,3.9,57.97],[1,3.85,2],[2,3.8,2.53]],"ltp":3.75,"tv":125.61,"id":3064881}]}]}
{"op":"mcm","clk":"1004416140","pt":1580629337019,"mc":[{"id":"1.168135751","rc":[{"batb":[[1,2.72,3.1]],"ltp":2.86,"tv":71.88,"id":3064880}]}]}
{"op":"mcm","clk":"1004416367","pt":1580629343161,"mc":[{"id":"1.168135751","rc":[{"batl":[[1,2.56,0]],"ltp":2.48,"tv":654.96,"id":2996932},{"batb":[[0,3.95,2.53],[1,3.9,57.97],[2,3.85,2]],"ltp":3.75,"tv":125.61,"id":3064881}]}]}
{"op":"mcm","clk":"1004418169","pt":1580629389892,"mc":[{"id":"1.168135751","rc":[{"batl":[[1,2.64,120.15]],"ltp":2.48,"tv":654.96,"id":2996932},{"batb":[[1,2.72,88.8]],"ltp":2.86,"tv":71.88,"id":3064880}]}]}
{"op":"mcm","clk":"1004419874","pt":1580629430073,"mc":[{"id":"1.168135751","rc":[{"batl":[[0,2.54,272.4]],"ltp":2.48,"tv":654.96,"id":2996932}]}]}
{"op":"mcm","clk":"1004421019","pt":1580629460699,"mc":[{"id":"1.168135751","rc":[{"batl":[[1,2.64,0]],"ltp":2.48,"tv":654.96,"id":2996932}]}]}
{"op":"mcm","clk":"1004428396","pt":1580629630698,"mc":[{"id":"1.168135751","rc":[{"batb":[[1,3.9,50.41]],"ltp":3.75,"tv":125.61,"id":3064881}]}]}
{"op":"mcm","clk":"1004428428","pt":1580629631732,"mc":[{"id":"1.168135751","rc":[{"batl":[[2,2.9,336.08]],"ltp":2.86,"tv":71.88,"id":3064880}]}]}
{"op":"mcm","clk":"1004429766","pt":1580629661752,"mc":[{"id":"1.168135751","rc":[{"batl":[[0,2.54,279.96]],"ltp":2.48,"tv":654.96,"id":2996932},{"batb":[[1,3.9,59.65]],"ltp":3.75,"tv":125.61,"id":3064881}]}]}
{"op":"mcm","clk":"1004437424","pt":1580629826763,"mc":[{"id":"1.168135751","rc":[{"batb":[[0,2.72,88.8],[1,2.7,107.03],[2,2.68,1.46]],"ltp":2.86,"tv":71.88,"id":3064880},{"batb":[[2,2.1,8.61]],"ltp":3.75,"tv":125.61,"id":3064881}]}]}
{"op":"mcm","clk":"1004439711","pt":1580629875039,"mc":[{"id":"1.168135751","rc":[{"batl":[[0,4.2,10],[1,4.3,2.53],[2,4.4,352.68]],"ltp":3.75,"tv":125.61,"id":3064881}]}]}
{"op":"mcm","clk":"1004445746","pt":1580630025414,"mc":[{"id":"1.168135751","rc":[{"trd":[[2.54,101.22]],"batl":[[0,2.54,266.69]],"ltp":2.54,"tv":681.49,"id":2996932}],"tv":878.99}]}
{"op":"mcm","clk":"1004445811","pt":1580630026802,"mc":[{"id":"1.168135751","rc":[{"batl":[[0,2.54,266.59]],"ltp":2.54,"tv":681.49,"id":2996932}]}]}
{"op":"mcm","clk":"1004445894","pt":1580630028605,"mc":[{"id":"1.168135751","rc":[{"trd":[[2.54,127.76]],"batl":[[0,2.54,253.32]],"ltp":2.54,"tv":708.02,"id":2996932}],"tv":905.52}]}
{"op":"mcm","clk":"1004445998","pt":1580630030719,"mc":[{"id":"1.168135751","rc":[{"batb":[[2,2.44,112.96]],"batl":[[0,2.54,270.12]],"ltp":2.54,"tv":708.02,"id":2996932},{"batl":[[2,2.9,368.01]],"ltp":2.86,"tv":71.88,"id":3064880}]}]}
{"op":"mcm","clk":"1004446460","pt":1580630041610,"mc":[{"id":"1.168135751","rc":[{"batl":[[0,2.54,270.23],[1,1000,2.53]],"ltp":2.54,"tv":708.02,"id":2996932}]}]}
{"op":"mcm","clk":"1004447282","pt":1580630060654,"mc":[{"id":"1.168135751","rc":[{"batb":[[1,3.9,50.41]],"ltp":3.75,"tv":125.61,"id":3064881}]}]}
{"op":"mcm","clk":"1004450221","pt":1580630127932,"mc":[{"id":"1.168135751","rc":[{"trd":[[4.2,10.14]],"batl":[[0,4.2,4.93]],"ltp":4.2,"tv":135.74,"id":3064881}],"tv":915.66}]}
{"op":"mcm","clk":"1004466098","pt":1580630449719,"mc":[{"id":"1.168135751","rc":[{"batb":[[1,2.44,112.96],[2,2.3,38]],"batl":[[0,2.54,270.12],[1,1000,0]],"ltp":2.54,"tv":708.02,"id":2996932},{"batb":[[0,2.72,85.7]],"batl":[[1,2.9,368.01],[2,2.9,0]],"ltp":2.86,"tv":71.88,"id":3064880},{"batb":[[0,3.9,50.41],[1,2.1,8.61],[2,1.12,11.15]],"batl":[[1,4.4,352.68],[2,4.4,0]],"ltp":4.2,"tv":135.74,"id":3064881}]}]}
{"op":"mcm","clk":"1004466207","pt":1580630451721,"mc":[{"id":"1.168135751","rc":[{"batb":[[1,2.44,78.51]],"ltp":2.54,"tv":708.02,"id":2996932},{"batb":[[0,2.1,8.61],[1,1.12,11.15],[2,1.08,16.71]],"batl":[[1,4.4,345.11]],"ltp":4.2,"tv":135.74,"id":3064881}]}]}
{"op":"mcm","clk":"1004466581","pt":1580630459214,"mc":[{"id":"1.168135751","rc":[{"trd":[[4.2,17.02]],"batl":[[0,4.2,1.49]],"ltp":4.2,"tv":142.62,"id":3064881}],"tv":922.54}]}
{"op":"mcm","clk":"1004466640","pt":1580630460657,"mc":[{"id":"1.168135751","rc":[{"batb":[[0,2.74,2],[1,2.72,85.7],[2,2.7,107.03]],"ltp":2.86,"tv":71.88,"id":3064880},{"batb":[[0,3.9,2],[1,2.1,8.61],[2,1.12,11.15]],"ltp":4.2,"tv":142.62,"id":3064881}]}]}
{"op":"mcm","clk":"1004467514","pt":1580630481673,"mc":[{"id":"1.168135751","rc":[{"batb":[[2,2.42,42.85]],"batl":[[0,2.54,276.84]],"ltp":2.54,"tv":708.02,"id":2996932},{"batb":[[1,3.85,75.62],[2,2.1,8.61]],"ltp":4.2,"tv":142.62,"id":3064881}]}]}
{"op":"mcm","clk":"1004467766","pt":1580630487690,"mc":[{"id":"1.168135751","rc":[{"batb":[[1,2.46,3.46],[2,2.44,78.51]],"batl":[[1,1000,2.64]],"ltp":2.54,"tv":708.02,"id":2996932},{"batb":[[0,2.74,5.1]],"batl":[[1,2.88,8.47],[2,2.9,368.01]],"ltp":2.86,"tv":71.88,"id":3064880},{"batb":[[0,3.9,4.53]],"batl":[[1,4.3,2.53],[2,4.4,345.11]],"ltp":4.2,"tv":142.62,"id":3064881}]}]}
{"op":"mcm","clk":"1004467793","pt":1580630488359,"mc":[{"id":"1.168135751","rc":[{"batl":[[0,2.54,276.95],[1,1000,2.53]],"ltp":2.54,"tv":708.02,"id":2996932}]}]}
{"op":"mcm","clk":"1004472214","pt":1580630580197,"mc":[{"id":"1.168135751","rc":[{"batl":[[0,2.52,211.21],[1,2.54,65.75],[2,1000,2.53]],"ltp":2.54,"tv":708.02,"id":2996932}]}]}
{"op":"mcm","clk":"1004473171","pt":1580630604748,"mc":[{"id":"1.168135751","rc":[{"batl":[[0,2.5,33.61],[1,2.52,211.21],[2,2.54,65.75]],"ltp":2.54,"tv":708.02,"id":2996932},{"batl":[[1,2.88,6.01]],"ltp":2.86,"tv":71.88,"id":3064880},{"batb":[[0,3.95,42.01],[1,3.9,4.53],[2,3.85,75.62]],"ltp":4.2,"tv":142.62,"id":3064881}]}]}
{"op":"mcm","clk":"1004473356","pt":1580630609743,"mc":[{"id":"1.168135751","rc":[{"batl":[[1,2.52,211.1]],"ltp":2.54,"tv":708.02,"id":2996932},{"batb":[[1,3.9,2]],"ltp":4.2,"tv":142.62,"id":3064881}]}]}
{"op":"mcm","clk":"1004473361","pt":1580630609845,"mc":[{"id":"1.168135751","rc":[{"batl":[[0,2.5,33.71]],"ltp":2.54,"tv":708.02,"id":2996932},{"batb":[[0,4,2.53],[1,3.95,42.01],[2,3.9,2]],"ltp":4.2,"tv":142.62,"id":3064881}]}]}
{"op":"mcm","clk":"1004475309","pt":1580630650816,"mc":[{"id":"1.168135751","rc":[{"batl":[[2,1000,2.53]],"ltp":2.54,"tv":708.02,"id":2996932},{"batb":[[1,2.7,107.03],[2,2.68,1.46]],"ltp":2.86,"tv":71.88,"id":3064880}]}]}
{"op":"mcm","clk":"1004475637","pt":1580630658732,"mc":[{"id":"1.168135751","rc":[{"batb":[[0,2.74,2],[1,2.72,3.1],[2,2.7,107.03]],"ltp":2.86,"tv":71.88,"id":3064880}]}]}
{"op":"mcm","clk":"1004477719","pt":1580630702229,"mc":[{"id":"1.168135751","rc":[{"batb":[[1,2.44,78.51],[2,2.42,42.85]],"ltp":2.54,"tv":708.02,"id":2996932},{"batb":[[1,2.7,107.03],[2,2.68,1.46]],"batl":[[1,2.9,368.01],[2,1000,6.01]],"ltp":2.86,"tv":71.88,"id":3064880},{"batb":[[0,3.95,42.01],[1,3.9,2],[2,2.1,8.61]],"batl":[[1,4.3,2.21]],"ltp":4.2,"tv":142.62,"id":3064881}]}]}
{"op":"mcm","clk":"1004477905","pt":1580630706637,"mc":[{"id":"1.168135751","rc":[{"batb":[[0,2.82,49.45],[1,2.74,2],[2,2.7,107.03]],"ltp":2.86,"tv":71.88,"id":3064880},{"batb":[[0,4.1,29.03],[1,3.95,42.01],[2,3.9,2]],"ltp":4.2,"tv":142.62,"id":3064881}]}]}
{"op":"mcm","clk":"1004477985","pt":1580630708600,"mc":[{"id":"1.168135751","rc":[{"batl":[[1,2.9,362.12]],"ltp":2.86,"tv":71.88,"id":3064880},{"batb":[[1,3.9,2],[2,2.1,8.61]],"batl":[[2,4.4,277.06]],"ltp":4.2,"tv":142.62,"id":3064881}]}]}
{"op":"mcm","clk":"1004478799","pt":1580630728078,"mc":[{"id":"1.168135751","rc":[{"batl":[[0,4.2,3.7],[1,4.4,277.06],[2,1000,2.53]],"ltp":4.2,"tv":142.62,"id":3064881}]}]}
{"op":"mcm","clk":"1004479221","pt":1580630737819,"mc":[{"id":"1.168135751","rc":[{"batb":[[1,2.8,35.29],[2,2.74,2]],"ltp":2.86,"tv":71.88,"id":3064880},{"batb":[[1,4,26.05],[2,3.9,2]],"batl":[[0,4.2,29.74]],"ltp":4.2,"tv":142.62,"id":3064881}]}]}
{"op":"mcm","clk":"1004493249","pt":1580631060427,"mc":[{"id":"1.168135751","rc":[{"batb":[[2,2.68,1.46]],"ltp":2.86,"tv":71.88,"id":3064880},{"batb":[[2,2.1,8.61]],"ltp":4.2,"tv":142.62,"id":3064881}]}]}
{"op":"mcm","clk":"1004493502","pt":1580631064751,"mc":[{"id":"1.168135751","rc":[{"batl":[[0,2.9,362.12],[1,1000,6.01],[2,1000,0]],"ltp":2.86,"tv":71.88,"id":3064880},{"batl":[[0,4.2,28.25]],"ltp":4.2,"tv":142.62,"id":3064881}]}]}
{"op":"mcm","clk":"1004497596","pt":1580631157676,"mc":[{"id":"1.168135751","rc":[{"trd":[[4.1,58.06]],"batb":[[0,4,26.05],[1,2.1,8.61],[2,1.5,2.53]],"batl":[[0,4.1,54.99],[1,4.2,28.25],[2,4.4,277.06]],"ltp":4.1,"tv":200.68,"id":3064881}],"tv":980.59}]}
{"op":"mcm","clk":"1004498054","pt":1580631168298,"mc":[{"id":"1.168135751","rc":[{"trd":[[2.82,98.9]],"batb":[[0,2.8,35.29],[1,2.68,1.46],[2,2.54,4]],"batl":[[0,2.82,34.57],[1,2.9,362.12],[2,1000,6.01]],"ltp":2.82,"tv":170.78,"id":3064880}],"tv":1079.5}]}
{"op":"mcm","clk":"1004498473","pt":1580631177762,"mc":[{"id":"1.168135751","rc":[{"batl":[[0,4.1,57.2],[1,4.2,26.05]],"ltp":4.1,"tv":200.68,"id":3064881}]}]}
{"op":"mcm","clk":"1004498979","pt":1580631188975,"mc":[{"id":"1.168135751","rc":[{"batl":[[0,4.1,57.31]],"ltp":4.1,"tv":200.68,"id":3064881}]}]}
{"op":"mcm","clk":"1004499540","pt":1580631199428,"mc":[{"id":"1.168135751","rc":[{"batl":[[0,2.5,244.81],[1,1000,2.53],[2,1000,0]],"ltp":2.54,"tv":708.02,"id":2996932}]}]}
{"op":"mcm","clk":"1004500534","pt":1580631222618,"mc":[{"id":"1.168135751","rc":[{"trd":[[2.5,20.11]],"batl":[[0,2.5,238.14]],"ltp":2.5,"tv":721.36,"id":2996932}],"tv":1092.84}]}
{"op":"mcm","clk":"1004500754","pt":1580631227765,"mc":[{"id":"1.168135751","rc":[{"batl":[[1,2.52,48.73],[2,1000,2.53]],"ltp":2.5,"tv":721.36,"id":2996932},{"batl":[[1,2.9,369.69]],"ltp":2.82,"tv":170.78,"id":3064880}]}]}
{"op":"mcm","clk":"1004500800","pt":1580631228740,"mc":[{"id":"1.168135751","rc":[{"trd":[[2.5,74.69]],"batl":[[0,2.5,183.56]],"ltp":2.5,"tv":775.94,"id":2996932},{"trd":[[2.8,119.31]],"batb":[[0,2.68,1.46],[1,2.54,4],[2,1.12,11.15]],"ltp":2.8,"tv":290.09,"id":3064880},{"trd":[[4.1,91.34]],"batl":[[0,4.1,24.03]],"ltp":4.1,"tv":233.96,"id":3064881}],"tv":1300.01}]}
{"op":"mcm","clk":"1004500863","pt":1580631230744,"mc":[{"id":"1.168135751","rc":[{"batb":[[2,2.3,38]],"batl":[[1,2.52,31.93]],"ltp":2.5,"tv":775.94,"id":2996932},{"batl":[[1,2.9,336.08]],"ltp":2.8,"tv":290.09,"id":3064880}]}]}
{"op":"mcm","clk":"1004501171","pt":1580631238670,"mc":[{"id":"1.168135751","rc":[{"trd":[[2.5,113.68]],"batb":[[1,2.44,121.36]],"batl":[[0,2.5,144.57]],"ltp":2.5,"tv":814.94,"id":2996932},{"trd":[[2.82,133.47]],"batb":[[0,2.78,31.93],[1,2.68,1.46],[2,2.54,4]],"batl":[[0,2.88,26.05]],"ltp":2.82,"tv":324.66,"id":3064880},{"trd":[[4,84.57]],"batb":[[0,2.1,8.61],[1,1.5,2.53],[2,1.12,11.15]],"batl":[[0,4,33.61],[1,4.1,24.03],[2,4.2,26.05]],"ltp":4.0,"tv":310.42,"id":3064881}],"tv":1450.02}]}
{"op":"mcm","clk":"1004501267","pt":1580631240791,"mc":[{"id":"1.168135751","rc":[{"batl":[[1,4.1,21.71]],"ltp":4.0,"tv":310.42,"id":3064881}]}]}
{"op":"mcm","clk":"1004501322","pt":1580631241566,"mc":[{"id":"1.168135751","rc":[{"batl":[[0,4,35.92]],"ltp":4.0,"tv":310.42,"id":3064881}]}]}
{"op":"mcm","clk":"1004501582","pt":1580631249779,"mc":[{"id":"1.168135751","rc":[{"batl":[[2,2.54,49.57]],"ltp":2.5,"tv":814.94,"id":2996932},{"batb":[[0,2.8,35.29],[1,2.78,31.93],[2,2.68,1.46]],"batl":[[2,2.92,42.01]],"ltp":2.82,"tv":324.66,"id":3064880},{"batb":[[0,3.95,26.89],[1,2.1,8.61],[2,1.5,2.53]],"batl":[[0,4,35.98],[2,4.2,40.33]],"ltp":4.0,"tv":310.42,"id":3064881}]}]}
{"op":"mcm","clk":"1004501772","pt":1580631253208,"mc":[{"id":"1.168135751","rc":[{"trd":[[2.5,119.44]],"batl":[[0,2.5,138.81]],"ltp":2.5,"tv":820.7,"id":2996932},{"trd":[[2.84,5.07]],"ltp":2.84,"tv":329.72,"id":3064880},{"trd":[[4,88.16]],"batl":[[0,4,32.39]],"ltp":4.0,"tv":314.02,"id":3064881}],"tv":1464.44}]}
{"op":"mcm","clk":"1004501895","pt":1580631256719,"mc":[{"id":"1.168135751","rc":[{"batl":[[1,2.54,49.57],[2,1000,2.53]],"ltp":2.5,"tv":820.7,"id":2996932},{"batb":[[1,2.68,1.46],[2,2.54,4]],"batl":[[0,2.9,336.08],[1,2.92,42.01],[2,1000,6.01]],"ltp":2.84,"tv":329.72,"id":3064880}]}]}
{"op":"mcm","clk":"1004502371","pt":1580631268696,"mc":[{"id":"1.168135751","rc":[{"batl":[[1,2.52,42.01],[2,2.54,49.57]],"ltp":2.5,"tv":820.7,"id":2996932},{"batb":[[0,2.82,40.33],[1,2.8,35.29],[2,2.68,1.46]],"batl":[[2,2.94,31.93]],"ltp":2.84,"tv":329.72,"id":3064880},{"batb":[[1,3.9,32.77],[2,2.1,8.61]],"batl":[[1,4.1,45.24]],"ltp":4.0,"tv":314.02,"id":3064881}]}]}
{"op":"mcm","clk":"1004502696","pt":1580631276539,"mc":[{"id":"1.168135751","rc":[{"batb":[[1,2.44,110.44]],"batl":[[2,1000,2.53]],"ltp":2.5,"tv":820.7,"id":2996932},{"batb":[[1,2.68,1.46],[2,2.54,4]],"batl":[[1,2.94,31.93],[2,1000,6.01]],"ltp":2.84,"tv":329.72,"id":3064880},{"batb":[[0,3.9,32.77],[1,2.1,8.61],[2,1.5,2.53]],"batl":[[2,4.4,277.06]],"ltp":4.0,"tv":314.02,"id":3064881}]}]}
{"op":"mcm","clk":"1004502882","pt":1580631281715,"mc":[{"id":"1.168135751","rc":[{"trd":[[2.5,371.5]],"batl":[[0,2.5,12.78]],"ltp":2.5,"tv":1072.76,"id":2996932}],"tv":1716.51}]}
{"op":"mcm","clk":"1004503155","pt":1580631288621,"mc":[{"id":"1.168135751","rc":[{"batl":[[2,2.56,77.3]],"ltp":2.5,"tv":1072.76,"id":2996932}]}]}
{"op":"mcm","clk":"1004504147","pt":1580631314380,"mc":[{"id":"1.168135751","rc":[{"trd":[[2.5,384.28]],"batl":[[0,2.52,42.01],[1,2.56,77.3],[2,2.66,172.24]],"ltp":2.5,"tv":1085.54,"id":2996932},{"trd":[[2.84,16.3]],"batl":[[0,2.84,14.09],[1,2.9,336.08],[2,2.94,31.93]],"ltp":2.84,"tv":340.95,"id":3064880},{"trd":[[4,96.15]],"batl":[[0,4,24.41]],"ltp":4.0,"tv":322.0,"id":3064881}],"tv":1748.5}]}
{"op":"mcm","clk":"1004504648","pt":1580631326582,"mc":[{"id":"1.168135751","rc":[{"batl":[[0,2.56,77.3],[1,2.56,0],[2,2.66,0]],"ltp":2.5,"tv":1085.54,"id":2996932},{"batb":[[2,1.12,11.15]],"batl":[[0,4,22.03]],"ltp":4.0,"tv":322.0,"id":3064881}]}]}
{"op":"mcm","clk":"1004504828","pt":1580631330363,"mc":[{"id":"1.168135751","rc":[{"batl":[[0,4,24.41]],"ltp":4.0,"tv":322.0,"id":3064881}]}]}
{"op":"mcm","clk":"1004505212","pt":1580631339682,"mc":[{"id":"1.168135751","rc":[{"batl":[[0,2.9,336.08],[1,2.94,31.93],[2,2.94,0]],"ltp":2.84,"tv":340.95,"id":3064880}]}]}
{"op":"mcm","clk":"1004505799","pt":1580631353805,"mc":[{"id":"1.168135751","rc":[{"batb":[[1,2.8,50.41],[2,2.68,1.46]],"ltp":2.84,"tv":340.95,"id":3064880},{"batb":[[1,3.8,60.49],[2,2.1,8.61]],"ltp":4.0,"tv":322.0,"id":3064881}]}]}
{"op":"mcm","clk":"1004507252","pt":1580631385512,"mc":[{"id":"1.168135751","rc":[{"trd":[[2.82,153.74]],"batb":[[0,2.82,30.19]],"ltp":2.82,"tv":361.23,"id":3064880}],"tv":1768.77}]}
{"op":"mcm","clk":"1004507522","pt":1580631391345,"mc":[{"id":"1.168135751","rc":[{"batl":[[0,2.56,66.38]],"ltp":2.5,"tv":1085.54,"id":2996932},{"batb":[[0,2.8,50.41],[1,2.68,1.46],[2,2.54,4]],"ltp":2.82,"tv":361.23,"id":3064880},{"batb":[[0,3.8,60.49],[1,2.1,8.61],[2,1.12,11.15]],"batl":[[1,4.1,21.71]],"ltp":4.0,"tv":322.0,"id":3064881}]}]}
{"op":"mcm","clk":"1004507923","pt":1580631400782,"mc":[{"id":"1.168135751","rc":[{"batl":[[0,3.95,2.38],[1,4,22.03],[2,4.1,21.71]],"ltp":4.0,"tv":322.0,"id":3064881}]}]}
{"op":"mcm","clk":"1004508342","pt":1580631410585,"mc":[{"id":"1.168135751","rc":[{"trd":[[3.8,31.3]],"batb":[[0,3.8,49.91]],"ltp":3.8,"tv":343.16,"id":3064881}],"tv":1789.93}]}
{"op":"mcm","clk":"1004508481","pt":1580631413593,"mc":[{"id":"1.168135751","rc":[{"batl":[[0,2.54,211.1],[1,2.56,66.38]],"ltp":2.5,"tv":1085.54,"id":2996932},{"trd":[[3.95,4.75],[4,105.05]],"batl":[[0,4,17.58],[1,4.1,21.71],[2,4.4,277.06]],"ltp":4.0,"tv":356.82,"id":3064881}],"tv":1803.59}]}
{"op":"mcm","clk":"1004508529","pt":1580631414989,"mc":[{"id":"1.168135751","rc":[{"trd":[[4,118.72]],"batl":[[0,4,10.75]],"ltp":4.0,"tv":370.49,"id":3064881}],"tv":1817.26}]}
{"op":"mcm","clk":"1004508796","pt":1580631420695,"mc":[{"id":"1.168135751","rc":[{"batb":[[1,2.44,121.36]],"batl":[[0,2.52,31.93],[1,2.54,211.1],[2,2.56,66.38]],"ltp":2.5,"tv":1085.54,"id":2996932},{"batb":[[1,2.76,84.86],[2,2.68,1.46]],"ltp":2.82,"tv":361.23,"id":3064880},{"batb":[[0,3.8,57.47]],"batl":[[1,4.1,46.08]],"ltp":4.0,"tv":370.49,"id":3064881}]}]}
{"op":"mcm","clk":"1004509121","pt":1580631427805,"mc":[{"id":"1.168135751","rc":[{"batl":[[2,2.56,0]],"ltp":2.5,"tv":1085.54,"id":2996932},{"batb":[[1,2.68,1.46],[2,2.54,4]],"ltp":2.82,"tv":361.23,"id":3064880},{"batb":[[0,2.1,8.61],[1,1.12,11.15],[2,1.08,16.71]],"ltp":4.0,"tv":370.49,"id":3064881}]}]}
{"op":"mcm","clk":"1004509128","pt":1580631428011,"mc":[{"id":"1.168135751","rc":[{"batb":[[0,3.9,26.05],[1,2.1,8.61],[2,1.12,11.15]],"ltp":4.0,"tv":370.49,"id":3064881}]}]}
{"op":"mcm","clk":"1004510250","pt":1580631455643,"mc":[{"id":"1.168135751","rc":[{"batl":[[0,2.52,243.03],[1,2.54,0]],"ltp":2.5,"tv":1085.54,"id":2996932}]}]}
{"op":"mcm","clk":"1004512984","pt":1580631523238,"mc":[{"id":"1.168135751","rc":[{"batl":[[0,2.5,211.1],[1,2.52,31.93]],"ltp":2.5,"tv":1085.54,"id":2996932}]}]}
{"op":"mcm","clk":"1004513373","pt":1580631532446,"mc":[{"id":"1.168135751","rc":[{"trd":[[2.5,434.96]],"batl":[[0,2.5,185.75]],"ltp":2.5,"tv":1136.21,"id":2996932}],"tv":1867.94}]}
{"op":"mcm","clk":"1004513736","pt":1580631540746,"mc":[{"id":"1.168135751","rc":[{"trd":[[2.5,485.63]],"batl":[[0,2.5,160.39]],"ltp":2.5,"tv":1186.89,"id":2996932}],"tv":1918.61}]}
{"op":"mcm","clk":"1004520107","pt":1580631675726,"mc":[{"id":"1.168135751","rc":[{"batl":[[1,2.52,43.69]],"ltp":2.5,"tv":1186.89,"id":2996932},{"batl":[[1,2.92,31.93],[2,2.94,31.93]],"ltp":2.82,"tv":361.23,"id":3064880},{"batb":[[0,3.9,43.69]],"batl":[[2,4.2,40.33]],"ltp":4.0,"tv":370.49,"id":3064881}]}]}
{"op":"mcm","clk":"1004521431","pt":1580631705743,"mc":[{"id":"1.168135751","rc":[{"batb":[[2,2.42,48.73]],"ltp":2.5,"tv":1186.89,"id":2996932}]}]}
{"op":"mcm","clk":"1004521698","pt":1580631711667,"mc":[{"id":"1.168135751","rc":[{"trd":[[2.5,685.64]],"batl":[[0,2.5,60.39]],"ltp":2.5,"tv":1386.89,"id":2996932}],"tv":2118.62}]}
{"op":"mcm","clk":"1004521716","pt":1580631712131,"mc":[{"id":"1.168135751","rc":[{"batb":[[1,2.44,78.51]],"ltp":2.5,"tv":1386.89,"id":2996932},{"batl":[[2,2.94,0]],"ltp":2.82,"tv":361.23,"id":3064880},{"batl":[[1,4.1,21.71]],"ltp":4.0,"tv":370.49,"id":3064881}]}]}
{"op":"mcm","clk":"1004523972","pt":1580631765722,"mc":[{"id":"1.168135751","rc":[{"trd":[[2.5,751.64]],"batl":[[0,2.5,27.39]],"ltp":2.5,"tv":1452.9,"id":2996932}],"tv":2184.62}]}
{"op":"mcm","clk":"1004527235","pt":1580631847404,"mc":[{"id":"1.168135751","rc":[{"trd":[[2.5,806.42]],"batb":[[0,2.5,2.61],[1,2.48,14.31],[2,2.44,78.51]],"batl":[[0,2.52,43.69],[1,2.52,0]],"ltp":2.5,"tv":1507.67,"id":2996932}],"tv":2239.4}]}
{"op":"mcm","clk":"1004527539","pt":1580631853785,"mc":[{"id":"1.168135751","rc":[{"batb":[[0,2.48,14.31],[1,2.44,78.51],[2,2.42,48.73]],"ltp":2.5,"tv":1507.67,"id":2996932}]}]}
{"op":"mcm","clk":"1004528548","pt":1580631874018,"mc":[{"id":"1.168135751","rc":[{"batl":[[1,2.58,135.27]],"ltp":2.5,"tv":1507.67,"id":2996932},{"batb":[[0,2.8,57.97]],"batl":[[2,2.96,41.17]],"ltp":2.82,"tv":361.23,"id":3064880}]}]}
{"op":"mcm","clk":"1004528778","pt":1580631878248,"mc":[{"id":"1.168135751","rc":[{"trd":[[4,135.42]],"batl":[[0,4,2.39]],"ltp":4.0,"tv":387.19,"id":3064881}],"tv":2256.1}]}
{"op":"mcm","clk":"1004530103","pt":1580631903768,"mc":[{"id":"1.168135751","rc":[{"batl":[[2,2.94,32.77]],"ltp":2.82,"tv":361.23,"id":3064880},{"batb":[[0,3.9,52.09]],"ltp":4.0,"tv":387.19,"id":3064881}]}]}
{"op":"mcm","clk":"1004530484","pt":1580631910663,"mc":[{"id":"1.168135751","rc":[{"batb":[[2,2.42,31.93]],"batl":[[0,2.58,135.27],[1,2.58,0]],"ltp":2.5,"tv":1507.67,"id":2996932},{"batl":[[1,2.94,32.77],[2,2.94,0]],"ltp":2.82,"tv":361.23,"id":3064880},{"batl":[[2,4.2,35.29]],"ltp":4.0,"tv":387.19,"id":3064881}]}]}
{"op":"mcm","clk":"1004531099","pt":1580631923801,"mc":[{"id":"1.168135751","rc":[{"batb":[[1,2.72,120.99],[2,2.68,1.46]],"ltp":2.82,"tv":361.23,"id":3064880},{"batb":[[1,3.75,84.86],[2,2.1,8.61]],"ltp":4.0,"tv":387.19,"id":3064881}]}]}
{"op":"mcm","clk":"1004531968","pt":1580631939811,"mc":[{"id":"1.168135751","rc":[{"batb":[[2,2.68,133.37]],"ltp":2.82,"tv":361.23,"id":3064880}]}]}
{"op":"mcm","clk":"1004532980","pt":1580631962220,"mc":[{"id":"1.168135751","rc":[{"batb":[[0,2.68,133.37],[1,2.54,4],[2,1.12,11.15]],"ltp":2.82,"tv":361.23,"id":3064880},{"batb":[[0,3.75,84.86],[1,2.1,8.61],[2,1.12,11.15]],"ltp":4.0,"tv":387.19,"id":3064881}]}]}
{"op":"mcm","clk":"1004533110","pt":1580631963819,"mc":[{"id":"1.168135751","rc":[{"batb":[[0,2.5,1.01],[1,2.48,14.31],[2,2.44,78.51]],"ltp":2.5,"tv":1507.67,"id":2996932},{"batb":[[0,2.68,134.29]],"ltp":2.82,"tv":361.23,"id":3064880}]}]}
{"op":"mcm","clk":"1004533134","pt":1580631964228,"mc":[{"id":"1.168135751","rc":[{"batb":[[0,3.75,85.52]],"ltp":4.0,"tv":387.19,"id":3064881}]}]}
{"op":"mcm","clk":"1004534418","pt":1580631985648,"mc":[{"id":"1.168135751","rc":[{"batb":[[0,2.76,2.92],[1,2.68,133.37],[2,2.54,4]],"ltp":2.82,"tv":361.23,"id":3064880}]}]}
{"op":"mcm","clk":"1004534563","pt":1580631988757,"mc":[{"id":"1.168135751","rc":[{"trd":[[2.5,808.43]],"batb":[[0,2.48,14.31],[1,2.44,78.51],[2,2.42,31.93]],"batl":[[0,2.5,41.84],[1,2.58,135.27]],"ltp":2.5,"tv":1509.69,"id":2996932},{"batb":[[1,2.72,131.91],[2,2.68,133.37]],"ltp":2.82,"tv":361.23,"id":3064880}],"tv":2258.12}]}
{"op":"mcm","clk":"1004536357","pt":1580632026784,"mc":[{"id":"1.168135751","rc":[{"batl":[[2,2.62,129.39]],"ltp":2.5,"tv":1509.69,"id":2996932},{"batb":[[0,2.82,41.17],[1,2.76,2.92],[2,2.72,131.91]],"ltp":2.82,"tv":361.23,"id":3064880},{"batb":[[0,3.95,34.45],[1,3.75,85.52],[2,2.1,8.61]],"ltp":4.0,"tv":387.19,"id":3064881}]}]}
{"op":"mcm","clk":"1004536683","pt":1580632035912,"mc":[{"id":"1.168135751","rc":[{"trd":[[2.5,813.75]],"batl":[[0,2.5,39.19]],"ltp":2.5,"tv":1515.0,"id":2996932}],"tv":2263.43}]}
{"op":"mcm","clk":"1004537470","pt":1580632056646,"mc":[{"id":"1.168135751","rc":[{"trd":[[2.5,817.58]],"batl":[[0,2.5,35.36],[1,2.54,73.94],[2,2.58,135.27]],"ltp":2.5,"tv":1518.83,"id":2996932},{"trd":[[2.82,197.68],[2.84,19.67]],"batb":[[0,2.82,19.19]],"ltp":2.82,"tv":408.53,"id":3064880},{"trd":[[4,137.82]],"batl":[[0,4.1,21.71],[1,4.2,35.29],[2,4.4,277.06]],"ltp":4.0,"tv":389.58,"id":3064881}],"tv":2316.96}]}
{"op":"mcm","clk":"1004537665","pt":1580632062754,"mc":[{"id":"1.168135751","rc":[{"batl":[[0,2.54,67.22],[1,2.54,0],[2,2.58,0]],"ltp":2.5,"tv":1518.83,"id":2996932},{"batb":[[2,2.68,1.46]],"batl":[[1,2.94,0]],"ltp":2.82,"tv":408.53,"id":3064880},{"batb":[[1,2.1,9.27],[2,1.12,11.15]],"ltp":4.0,"tv":389.58,"id":3064881}]}]}
{"op":"mcm","clk":"1004537974","pt":1580632070255,"mc":[{"id":"1.168135751","rc":[{"batb":[[2,2.42,42.01]],"ltp":2.5,"tv":1518.83,"id":2996932},{"batb":[[1,2.76,76.85]],"batl":[[1,2.92,35.29]],"ltp":2.82,"tv":408.53,"id":3064880},{"batb":[[1,3.85,68.06],[2,2.1,9.27]],"ltp":4.0,"tv":389.58,"id":3064881}]}]}
{"op":"mcm","clk":"1004538361","pt":1580632081789,"mc":[{"id":"1.168135751","rc":[{"batb":[[0,2.76,76.85],[1,2.68,1.46],[2,2.54,4]],"ltp":2.82,"tv":408.53,"id":3064880},{"batb":[[0,3.85,68.06],[1,2.1,9.27],[2,1.12,11.15]],"ltp":4.0,"tv":389.58,"id":3064881}]}]}
{"op":"mcm","clk":"1004539052","pt":1580632098795,"mc":[{"id":"1.168135751","rc":[{"batl":[[1,2.64,173.08]],"ltp":2.5,"tv":1518.83,"id":2996932}]}]}
{"op":"mcm","clk":"1004539138","pt":1580632100393,"mc":[{"id":"1.168135751","rc":[{"trd":[[2.54,257.76]],"batl":[[0,2.54,2.22]],"ltp":2.54,"tv":1648.83,"id":2996932}],"tv":2446.96}]}
{"op":"mcm","clk":"1004539320","pt":1580632104787,"mc":[{"id":"1.168135751","rc":[{"batb":[[1,2.46,32.77],[2,2.44,78.51]],"ltp":2.54,"tv":1648.83,"id":2996932},{"batb":[[2,2.64,133.59]],"batl":[[0,2.9,368.85]],"ltp":2.82,"tv":408.53,"id":3064880},{"batb":[[1,3.65,135.94],[2,2.1,8.61]],"batl":[[1,4.2,42.85]],"ltp":4.0,"tv":389.58,"id":3064881}]}]}
{"op":"mcm","clk":"1004539556","pt":1580632110714,"mc":[{"id":"1.168135751","rc":[{"batb":[[1,2.44,78.51],[2,2.3,38]],"batl":[[0,2.64,136.11],[1,2.64,0]],"ltp":2.54,"tv":1648.83,"id":2996932},{"batb":[[0,2.76,2.92],[2,2.54,4]],"batl":[[0,2.9,336.08]],"ltp":2.82,"tv":408.53,"id":3064880},{"batb":[[0,3.65,135.94],[1,2.1,8.61],[2,1.12,11.15]],"ltp":4.0,"tv":389.58,"id":3064881}]}]}
{"op":"mcm","clk":"1004539849","pt":1580632117788,"mc":[{"id":"1.168135751","rc":[{"batb":[[1,2.44,119.68]],"batl":[[1,2.66,118.47]],"ltp":2.54,"tv":1648.83,"id":2996932},{"batb":[[2,2.66,126.87]],"ltp":2.82,"tv":408.53,"id":3064880}]}]}
{"op":"mcm","clk":"1004540232","pt":1580632129815,"mc":[{"id":"1.168135751","rc":[{"batl":[[0,2.66,118.47],[1,2.66,0]],"ltp":2.54,"tv":1648.83,"id":2996932}]}]}
{"op":"mcm","clk":"1004540804","pt":1580632144552,"mc":[{"id":"1.168135751","rc":[{"batb":[[2,2.38,108.7]],"ltp":2.54,"tv":1648.83,"id":2996932},{"batb":[[1,3.4,62.5],[2,2.1,8.61]],"ltp":4.0,"tv":389.58,"id":3064881}]}]}
{"op":"mcm","clk":"1004541590","pt":1580632164697,"mc":[{"id":"1.168135751","rc":[{"batb":[[0,2.68,2.38],[1,2.66,126.87],[2,2.62,92.59]],"ltp":2.82,"tv":408.53,"id":3064880}]}]}
{"op":"mcm","clk":"1004541863","pt":1580632174672,"mc":[{"id":"1.168135751","rc":[{"batb":[[0,4,1.83],[1,3.65,135.94],[2,3.4,62.5]],"ltp":4.0,"tv":389.58,"id":3064881}]}]}
{"op":"mcm","clk":"1004541998","pt":1580632179396,"mc":[{"id":"1.168135751","rc":[{"trd":[[4.1,95]],"batb":[[0,3.65,135.94],[1,3.4,62.5],[2,2.1,8.61]],"batl":[[0,4.1,19.88]],"ltp":4.1,"tv":393.24,"id":3064881}],"tv":2450.62}]}
{"op":"mcm","clk":"1004542484","pt":1580632190814,"mc":[{"id":"1.168135751","rc":[{"batb":[[0,2.5,2],[1,2.48,14.31],[2,2.44,119.68]],"ltp":2.54,"tv":1648.83,"id":2996932},{"batb":[[0,2.7,2.92],[1,2.68,1.46],[2,2.66,126.87]],"ltp":2.82,"tv":408.53,"id":3064880}]}]}
{"op":"mcm","clk":"1004542523","pt":1580632191585,"mc":[{"id":"1.168135751","rc":[{"batb":[[0,3.7,2.66],[1,3.65,135.27],[2,3.4,62.5]],"ltp":4.1,"tv":393.24,"id":3064881}]}]}
{"op":"mcm","clk":"1004543010","pt":1580632202504,"mc":[{"id":"1.168135751","rc":[{"batb":[[2,2.44,78.51]],"ltp":2.54,"tv":1648.83,"id":2996932},{"batb":[[2,2.62,92.59]],"batl":[[1,2.92,0]],"ltp":2.82,"tv":408.53,"id":3064880},{"batb":[[1,3.4,62.5],[2,2.1,8.61]],"batl":[[1,4.4,277.06],[2,1000,2.53]],"ltp":4.1,"tv":393.24,"id":3064881}]}]}
{"op":"mcm","clk":"1004543484","pt":1580632212638,"mc":[{"id":"1.168135751","rc":[{"trd":[[2.7,8],[2.76,1.83]],"batb":[[0,2.68,1.46],[1,2.62,92.59],[2,2.54,4]],"batl":[[0,2.7,36.6],[1,2.9,336.08]],"ltp":2.7,"tv":414.36,"id":3064880}],"tv":2456.44}]}
{"op":"mcm","clk":"1004543545","pt":1580632213624,"mc":[{"id":"1.168135751","rc":[{"trd":[[2.58,13.19]],"ltp":2.58,"tv":1662.02,"id":2996932},{"trd":[[2.7,20.6]],"batl":[[0,2.7,23.99]],"ltp":2.7,"tv":426.96,"id":3064880},{"trd":[[4.1,103.31]],"batl":[[0,4.1,11.57]],"ltp":4.1,"tv":401.55,"id":3064881}],"tv":2490.54}]}
{"op":"mcm","clk":"1004543693","pt":1580632216523,"mc":[{"id":"1.168135751","rc":[{"trd":[[2.58,26.38]],"ltp":2.58,"tv":1675.21,"id":2996932},{"trd":[[2.7,33.2]],"batl":[[0,2.7,11.39]],"ltp":2.7,"tv":439.56,"id":3064880},{"trd":[[4.1,111.62]],"batl":[[0,4.1,3.26]],"ltp":4.1,"tv":409.86,"id":3064881}],"tv":2524.65}]}
{"op":"mcm","clk":"1004543827","pt":1580632219764,"mc":[{"id":"1.168135751","rc":[{"trd":[[2.58,31.35]],"ltp":2.58,"tv":1680.18,"id":2996932},{"trd":[[2.7,37.95]],"batl":[[0,2.7,6.65]],"ltp":2.7,"tv":444.31,"id":3064880},{"trd":[[4.1,114.75]],"batl":[[0,4.4,277.18],[1,1000,2.53],[2,1000,0]],"ltp":4.1,"tv":413.0,"id":3064881}],"tv":2537.49}]}
{"op":"mcm","clk":"1004545189","pt":1580632250803,"mc":[{"id":"1.168135751","rc":[{"batb":[[0,2.48,14.31],[1,2.44,78.51],[2,2.38,108.7]],"ltp":2.58,"tv":1680.18,"id":2996932},{"batb":[[0,3.4,63.16],[1,2.1,8.61],[2,1.12,11.15]],"ltp":4.1,"tv":413.0,"id":3064881}]}]}
{"op":"mcm","clk":"1004545578","pt":1580632259782,"mc":[{"id":"1.168135751","rc":[{"batb":[[0,2.5,2],[1,2.48,14.31],[2,2.44,78.51]],"ltp":2.58,"tv":1680.18,"id":2996932},{"batb":[[0,3.45,2.66],[1,3.4,62.5],[2,2.1,8.61]],"ltp":4.1,"tv":413.0,"id":3064881}]}]}
{"op":"mcm","clk":"1004547799","pt":1580632305569,"mc":[{"id":"1.168135751","rc":[{"trd":[[4.1,115]],"batb":[[0,4.1,1.7],[1,3.45,2.66],[2,3.4,62.5]],"batl":[[0,4.4,277.06]],"ltp":4.1,"tv":413.25,"id":3064881}],"tv":2537.75}]}
{"op":"mcm","clk":"1004548214","pt":1580632314770,"mc":[{"id":"1.168135751","rc":[{"trd":[[2.62,47.76],[2.68,7.99]],"batb":[[0,2.62,68.7],[1,2.54,4],[2,1.12,11.15]],"ltp":2.62,"tv":494.98,"id":3064880}],"tv":2588.42}]}
{"op":"mcm","clk":"1004548393","pt":1580632318786,"mc":[{"id":"1.168135751","rc":[{"batb":[[0,2.48,14.31],[1,2.44,78.51],[2,2.38,108.7]],"ltp":2.58,"tv":1680.18,"id":2996932},{"batb":[[1,3.4,63.16],[2,2.1,8.61]],"ltp":4.1,"tv":413.25,"id":3064881}]}]}
{"op":"mcm","clk":"1004548850","pt":1580632328566,"mc":[{"id":"1.168135751","rc":[{"batb":[[0,2.5,2],[1,2.48,14.31],[2,2.44,78.51]],"ltp":2.58,"tv":1680.18,"id":2996932},{"batb":[[1,3.85,2],[2,3.4,63.16]],"ltp":4.1,"tv":413.25,"id":3064881}]}]}
{"op":"mcm","clk":"1004549737","pt":1580632346700,"mc":[{"id":"1.168135751","rc":[{"batb":[[0,2.64,50.66],[1,2.62,68.7],[2,2.54,4]],"ltp":2.62,"tv":494.98,"id":3064880}]}]}
{"op":"mcm","clk":"1004550114","pt":1580632355520,"mc":[{"id":"1.168135751","rc":[{"trd":[[4.4,20.15]],"batl":[[0,4.4,269.37]],"ltp":4.4,"tv":428.62,"id":3064881}],"tv":2603.79}]}
{"op":"mcm","clk":"1004550698","pt":1580632367332,"mc":[{"id":"1.168135751","rc":[{"batb":[[0,3.85,2],[1,3.4,63.16],[2,2.1,8.61]],"ltp":4.4,"tv":428.62,"id":3064881}]}]}
{"op":"mcm","clk":"1004551102","pt":1580632376152,"mc":[{"id":"1.168135751","rc":[{"trd":[[4.4,23.32]],"batl":[[0,4.4,267.78]],"ltp":4.4,"tv":431.79,"id":3064881}],"tv":2606.97}]}
{"op":"mcm","clk":"1004551526","pt":1580632384669,"mc":[{"id":"1.168135751","rc":[{"batb":[[1,3.4,62.5]],"ltp":4.4,"tv":431.79,"id":3064881}]}]}
{"op":"mcm","clk":"1004551569","pt":1580632385662,"mc":[{"id":"1.168135751","rc":[{"batb":[[0,3.85,2.65]],"ltp":4.4,"tv":431.79,"id":3064881}]}]}
{"op":"mcm","clk":"1004551665","pt":1580632387767,"mc":[{"id":"1.168135751","rc":[{"batb":[[0,2.48,14.31],[1,2.44,78.51],[2,2.38,108.7]],"ltp":2.58,"tv":1680.18,"id":2996932},{"batb":[[0,3.4,63.15],[1,2.1,8.61],[2,1.12,11.15]],"ltp":4.4,"tv":431.79,"id":3064881}]}]}
{"op":"mcm","clk":"1004552095","pt":1580632396551,"mc":[{"id":"1.168135751","rc":[{"batb":[[0,2.5,2],[1,2.48,14.31],[2,2.44,78.51]],"ltp":2.58,"tv":1680.18,"id":2996932},{"batb":[[0,3.45,2.65],[1,3.4,62.5],[2,2.1,8.61]],"ltp":4.4,"tv":431.79,"id":3064881}]}]}
{"op":"mcm","clk":"1004553904","pt":1580632436623,"mc":[{"id":"1.168135751","rc":[{"batb":[[0,2.62,68.7],[1,2.54,4],[2,1.12,11.15]],"ltp":2.62,"tv":494.98,"id":3064880}]}]}
{"op":"mcm","clk":"1004554567","pt":1580632455448,"mc":[{"id":"1.168135751","rc":[{"batb":[[0,2.48,14.31],[1,2.44,78.51],[2,2.38,108.7]],"ltp":2.58,"tv":1680.18,"id":2996932},{"batb":[[0,3.4,63.15],[1,2.1,8.61],[2,1.12,11.15]],"ltp":4.4,"tv":431.79,"id":3064881}]}]}
{"op":"mcm","clk":"1004554896","pt":1580632463672,"mc":[{"id":"1.168135751","rc":[{"batb":[[0,2.5,2],[1,2.48,14.31],[2,2.44,78.51]],"ltp":2.58,"tv":1680.18,"id":2996932},{"batb":[[0,3.45,2.65],[1,3.4,62.5],[2,2.1,8.61]],"ltp":4.4,"tv":431.79,"id":3064881}]}]}
{"op":"mcm","clk":"1004555053","pt":1580632468449,"mc":[{"id":"1.168135751","rc":[{"trd":[[4.4,96.47]],"batl":[[0,4.4,231.21]],"ltp":4.4,"tv":504.94,"id":3064881}],"tv":2680.11}]}
{"op":"mcm","clk":"1004557375","pt":1580632523750,"mc":[{"id":"1.168135751","rc":[{"batb":[[0,2.48,14.31],[1,2.44,78.51],[2,2.38,108.7]],"ltp":2.58,"tv":1680.18,"id":2996932},{"batb":[[0,3.4,63.15],[1,2.1,8.61],[2,1.12,11.15]],"ltp":4.4,"tv":504.94,"id":3064881}]}]}
{"op":"mcm","clk":"1004558266","pt":1580632543760,"mc":[{"id":"1.168135751","rc":[{"trd":[[2.78,0.91]],"batb":[[0,2.96,2.12],[1,2.48,14.31],[2,2.44,78.51]],"ltp":2.78,"tv":1681.09,"id":2996932},{"trd":[[2.62,48.72]],"batb":[[0,2.62,67.74]],"ltp":2.62,"tv":495.94,"id":3064880},{"trd":[[3.9,0.65]],"batb":[[0,3.4,62.5]],"ltp":3.9,"tv":505.59,"id":3064881}],"tv":2682.63}]}
{"op":"mcm","clk":"1004558312","pt":1580632544683,"mc":[{"id":"1.168135751","rc":[{"batl":[[0,1000,2.04]],"ltp":2.78,"tv":1681.09,"id":2996932}]}]}
{"op":"mcm","clk":"1004558357","pt":1580632545670,"mc":[{"id":"1.168135751","rc":[{"trd":[[2.96,4.07]],"batb":[[0,2.48,14.39],[1,2.44,78.51],[2,2.38,108.7]],"ltp":2.96,"tv":1685.16,"id":2996932}],"tv":2686.7}]}
{"op":"mcm","clk":"1004567160","pt":1580632761150,"mc":[{"id":"1.168135751","rc":[{"batl":[[0,4.4,25]],"ltp":3.9,"tv":505.59,"id":3064881}]}]}
{"op":"mcm","clk":"1004567815","pt":1580632776752,"mc":[{"id":"1.168135751","rc":[{"trd":[[2.7,50.57]],"batl":[[0,2.7,0.33],[1,2.9,0]],"ltp":2.7,"tv":508.57,"id":3064880}],"tv":2699.32}]}
{"op":"mcm","clk":"1004586173","pt":1580633147615,"mc":[{"id":"1.168135751","rc":[{"trd":[[2.48,213.34],[2.96,4.24]],"batb":[[0,2.44,79.2],[1,2.38,108.7],[2,2.3,38]],"ltp":2.48,"tv":1712.56,"id":2996932}],"tv":2726.73}]}
{"op":"mcm","clk":"1004586332","pt":1580633150804,"mc":[{"id":"1.168135751","rc":[{"trd":[[2.48,215.03]],"batb":[[0,2.44,78.51]],"ltp":2.48,"tv":1714.26,"id":2996932},{"trd":[[2.7,50.86]],"batl":[[0,2.7,0.05]],"ltp":2.7,"tv":508.86,"id":3064880},{"trd":[[4.4,96.65]],"batl":[[0,4.4,24.82]],"ltp":4.4,"tv":505.77,"id":3064881}],"tv":2728.89}]}
{"op":"mcm","clk":"1004586386","pt":1580633151547,"mc":[{"id":"1.168135751","marketDefinition":{"bspMarket":false,"turnInPlayEnabled":true,"persistenceEnabled":true,"marketBaseRate":5.0,"eventId":"29678823","eventTypeId":"2","numberOfWinners":1,"bettingType":"ODDS","marketType":"NUMBER_OF_SETS","marketTime":"2020-02-02T08:30:00.000Z","suspendTime":"2020-02-02T08:30:00.000Z","bspReconciled":false,"complete":true,"inPlay":true,"crossMatching":true,"runnersVoidable":false,"numberOfActiveRunners":3,"betDelay":3,"status":"OPEN","runners":[{"status":"ACTIVE","sortPriority":1,"id":2996932,"name":"Three Sets"},{"status":"ACTIVE","sortPriority":2,"id":3064880,"name":"Four Sets"},{"status":"ACTIVE","sortPriority":3,"id":3064881,"name":"Five Sets"}],"regulators":["MR_INT"],"countryCode":"AU","discountAllowed":true,"timezone":"GMT","openDate":"2020-02-02T08:30:00.000Z","version":3148327243,"name":"Number of Sets?","eventName":"Thiem v Djokovic"},"rc":[{"batb":[[0,2.3,38],[1,2.2,20],[2,1.12,11.15]],"ltp":2.48,"tv":1714.26,"id":2996932},{"batb":[[0,1.12,11.15],[1,1.08,16.71],[2,1.05,27.86]],"ltp":2.7,"tv":508.86,"id":3064880},{"batb":[[0,2.1,8.61],[1,1.12,11.15],[2,1.08,16.71]],"ltp":4.4,"tv":505.77,"id":3064881}]}]}
{"op":"mcm","clk":"1004613605","pt":1580633766706,"mc":[{"id":"1.168135751","rc":[{"trd":[[2.3,10]],"batb":[[0,2.3,33]],"ltp":2.3,"tv":1724.26,"id":2996932}],"tv":2738.89}]}
{"op":"mcm","clk":"1004614647","pt":1580633785728,"mc":[{"id":"1.168135751","rc":[{"trd":[[2.3,76]],"batb":[[0,2.2,20],[1,1.12,11.15],[2,1.08,16.71]],"batl":[[0,2.3,7]],"ltp":2.3,"tv":1790.26,"id":2996932}],"tv":2804.89}]}
{"op":"mcm","clk":"1004617697","pt":1580633842726,"mc":[{"id":"1.168135751","rc":[{"trd":[[2.2,40]],"batb":[[0,1.12,11.15],[1,1.08,16.71],[2,1.05,27.86]],"ltp":2.2,"tv":1830.26,"id":2996932}],"tv":2844.89}]}
{"op":"mcm","clk":"1004861881","pt":1580638458736,"mc":[{"id":"1.168135751","rc":[{"batb":[[0,2,22.72],[1,1.12,11.15],[2,1.08,16.71]],"ltp":2.2,"tv":1830.26,"id":2996932}]}]}
{"op":"mcm","clk":"1004863563","pt":1580638478671,"mc":[{"id":"1.168135751","rc":[{"batl":[[0,13,8.33]],"ltp":2.7,"tv":508.86,"id":3064880}]}]}
{"op":"mcm","clk":"1004875385","pt":1580638626754,"mc":[{"id":"1.168135751","rc":[{"batb":[[0,1.12,11.15],[1,1.08,16.71],[2,1.05,27.86]],"ltp":2.2,"tv":1830.26,"id":2996932}]}]}
{"op":"mcm","clk":"1004875638","pt":1580638629523,"mc":[{"id":"1.168135751","rc":[{"batb":[[0,1.7,22.72],[1,1.12,11.15],[2,1.08,16.71]],"ltp":2.2,"tv":1830.26,"id":2996932}]}]}
{"op":"mcm","clk":"1004880015","pt":1580638688752,"mc":[{"id":"1.168135751","rc":[{"batb":[[0,1.12,11.15],[1,1.08,16.71],[2,1.05,27.86]],"ltp":2.2,"tv":1830.26,"id":2996932}]}]}
{"op":"mcm","clk":"1004880301","pt":1580638691730,"mc":[{"id":"1.168135751","rc":[{"batb":[[0,1.4,22.73],[1,1.12,11.14],[2,1.08,16.71]],"ltp":2.2,"tv":1830.26,"id":2996932}]}]}
{"op":"mcm","clk":"1004914262","pt":1580639070529,"mc":[{"id":"1.168135751","rc":[{"batb":[[0,2.2,16.66],[1,1.4,22.73],[2,1.12,11.14]],"ltp":2.2,"tv":1830.26,"id":2996932}]}]}
{"op":"mcm","clk":"1004938918","pt":1580639304726,"mc":[{"id":"1.168135751","rc":[{"batb":[[0,4,18.93],[1,2.2,16.66],[2,1.4,22.73]],"ltp":2.2,"tv":1830.26,"id":2996932}]}]}
{"op":"mcm","clk":"1004966421","pt":1580639572635,"mc":[{"id":"1.168135751","rc":[{"batb":[[0,2.2,16.66],[1,1.4,22.73],[2,1.12,11.14]],"ltp":2.2,"tv":1830.26,"id":2996932}]}]}
{"op":"mcm","clk":"1004966677","pt":1580639575528,"mc":[{"id":"1.168135751","rc":[{"batb":[[0,12,18.93],[1,2.2,16.66],[2,1.4,22.73]],"ltp":2.2,"tv":1830.26,"id":2996932}]}]}
{"op":"mcm","clk":"1005007537","pt":1580640010801,"mc":[{"id":"1.168135751","rc":[{"batb":[[1,1.4,22.73],[2,1.12,11.14]],"ltp":2.2,"tv":1830.26,"id":2996932}]}]}
{"op":"mcm","clk":"1005055868","pt":1580640400664,"mc":[{"id":"1.168135751","rc":[{"trd":[[2.1,17.23]],"batb":[[0,1.12,11.15],[1,1.08,16.71],[2,1.05,27.86]],"batl":[[0,2.1,16.38]],"ltp":2.1,"tv":523.0,"id":3064881}],"tv":2862.12}]}
{"op":"mcm","clk":"1005581340","pt":1580643438814,"mc":[{"id":"1.168135751","rc":[{"batb":[[1,1.12,11.15],[2,1.08,16.71]],"ltp":2.2,"tv":1830.26,"id":2996932}]}]}
{"op":"mcm","clk":"1005757622","pt":1580644473758,"mc":[{"id":"1.168135751","rc":[{"trd":[[1.12,3.98],[1.49,0.02]],"batb":[[0,1.12,9.16]],"ltp":1.12,"tv":526.99,"id":3064881}],"tv":2866.11}]}
{"op":"mcm","clk":"1005760162","pt":1580644493767,"mc":[{"id":"1.168135751","rc":[{"batb":[[1,1.01,0.52],[2,1.08,0]],"ltp":2.2,"tv":1830.26,"id":2996932}]}]}
{"op":"mcm","clk":"1005763652","pt":1580644520748,"mc":[{"id":"1.168135751","rc":[{"batb":[[0,1.08,16.71],[1,1.05,27.86],[2,1.01,0.51]],"ltp":1.12,"tv":526.99,"id":3064881}]}]}
{"op":"mcm","clk":"1005766807","pt":1580644546762,"mc":[{"id":"1.168135751","rc":[{"batb":[[0,1.08,16.72],[1,1.05,27.86],[2,1.01,0.51]],"ltp":2.7,"tv":508.86,"id":3064880}]}]}
{"op":"mcm","clk":"1005771835","pt":1580644583812,"mc":[{"id":"1.168135751","rc":[{"batb":[[0,1.05,27.86],[1,1.01,0.51],[2,1.01,0]],"ltp":1.12,"tv":526.99,"id":3064881}]}]}
{"op":"mcm","clk":"1005773792","pt":1580644597706,"mc":[{"id":"1.168135751","rc":[{"batb":[[0,1.01,0.52],[1,1.05,0],[2,1.01,0]],"ltp":2.7,"tv":508.86,"id":3064880},{"batb":[[0,1.01,0.51],[1,1.01,0]],"ltp":1.12,"tv":526.99,"id":3064881}]}]}
{"op":"mcm","clk":"1005774427","pt":1580644602718,"mc":[{"id":"1.168135751","marketDefinition":{"bspMarket":false,"turnInPlayEnabled":true,"persistenceEnabled":true,"marketBaseRate":5.0,"eventId":"29678823","eventTypeId":"2","numberOfWinners":1,"bettingType":"ODDS","marketType":"NUMBER_OF_SETS","marketTime":"2020-02-02T08:30:00.000Z","suspendTime":"2020-02-02T08:30:00.000Z","bspReconciled":false,"complete":true,"inPlay":true,"crossMatching":true,"runnersVoidable":false,"numberOfActiveRunners":3,"betDelay":3,"status":"SUSPENDED","runners":[{"status":"ACTIVE","sortPriority":1,"id":2996932,"name":"Three Sets"},{"status":"ACTIVE","sortPriority":2,"id":3064880,"name":"Four Sets"},{"status":"ACTIVE","sortPriority":3,"id":3064881,"name":"Five Sets"}],"regulators":["MR_INT"],"countryCode":"AU","discountAllowed":true,"timezone":"GMT","openDate":"2020-02-02T08:30:00.000Z","version":3148627410,"name":"Number of Sets?","eventName":"Thiem v Djokovic"}}]}
{"op":"mcm","clk":"1005775628","pt":1580644611743,"mc":[{"id":"1.168135751","rc":[{"batb":[[0,1.01,0.52],[1,1.01,0]],"ltp":2.2,"tv":1830.26,"id":2996932}]}]}
{"op":"mcm","clk":"1005814925","pt":1580644904669,"mc":[{"id":"1.168135751","tv":0.0}]}
{"op":"mcm","clk":"1005815060","pt":1580644905672,"mc":[{"id":"1.168135751","marketDefinition":{"bspMarket":false,"turnInPlayEnabled":true,"persistenceEnabled":true,"marketBaseRate":5.0,"eventId":"29678823","eventTypeId":"2","numberOfWinners":1,"bettingType":"ODDS","marketType":"NUMBER_OF_SETS","marketTime":"2020-02-02T08:30:00.000Z","suspendTime":"2020-02-02T08:30:00.000Z","bspReconciled":false,"complete":true,"inPlay":true,"crossMatching":false,"runnersVoidable":false,"numberOfActiveRunners":0,"betDelay":3,"status":"CLOSED","settledTime":"2020-02-02T12:01:41.000Z","runners":[{"status":"LOSER","sortPriority":1,"id":2996932,"name":"Three Sets"},{"status":"LOSER","sortPriority":2,"id":3064880,"name":"Four Sets"},{"status":"WINNER","sortPriority":3,"id":3064881,"name":"Five Sets"}],"regulators":["MR_INT"],"countryCode":"AU","discountAllowed":true,"timezone":"GMT","openDate":"2020-02-02T08:30:00.000Z","version":3148639809,"name":"Number of Sets?","eventName":"Thiem v Djokovic"}}]}
