{"op":"mcm","clk":"988026418","pt":1580473742115,"mc":[{"id":"1.168135803","marketDefinition":{"bspMarket":false,"turnInPlayEnabled":true,"persistenceEnabled":true,"marketBaseRate":5.0,"eventId":"29678823","eventTypeId":"2","numberOfWinners":1,"bettingType":"ODDS","marketType":"SET_WINNER","marketTime":"2020-02-02T08:30:00.000Z","suspendTime":"2020-02-02T08:30:00.000Z","bspReconciled":false,"complete":true,"inPlay":false,"crossMatching":false,"runnersVoidable":false,"numberOfActiveRunners":2,"betDelay":0,"status":"OPEN","runners":[{"status":"ACTIVE","sortPriority":1,"id":5720747,"name":"Dominic Thiem"},{"status":"ACTIVE","sortPriority":2,"id":2249229,"name":"Novak Djokovic"}],"regulators":["MR_INT"],"countryCode":"AU","discountAllowed":false,"timezone":"GMT","openDate":"2020-02-02T08:30:00.000Z","version":3143005275,"name":"Set 4 Winner","eventName":"Thiem v Djokovic"},"rc":[{"batb":[[0,1.01,20]],"ltp":0.0,"tv":0.0,"id":2249229},{"batb":[[0,1.01,20]],"ltp":0.0,"tv":0.0,"id":5720747}]}]}
{"op":"mcm","clk":"988026715","pt":1580473744836,"mc":[{"id":"1.168135803","marketDefinition":{"bspMarket":false,"turnInPlayEnabled":true,"persistenceEnabled":true,"marketBaseRate":5.0,"eventId":"29678823","eventTypeId":"2","numberOfWinners":1,"bettingType":"ODDS","marketType":"SET_WINNER","marketTime":"2020-02-02T08:30:00.000Z","suspendTime":"2020-02-02T08:30:00.000Z","bspReconciled":false,"complete":true,"inPlay":false,"crossMatching":false,"runnersVoidable":false,"numberOfActiveRunners":2,"betDelay":0,"status":"OPEN","runners":[{"status":"ACTIVE","sortPriority":1,"id":5720747,"name":"Dominic Thiem"},{"status":"ACTIVE","sortPriority":2,"id":2249229,"name":"Novak Djokovic"}],"regulators":["MR_INT"],"countryCode":"AU","discountAllowed":true,"timezone":"GMT","openDate":"2020-02-02T08:30:00.000Z","version":3143005275,"name":"Set 4 Winner","eventName":"Thiem v Djokovic"}}]}
{"op":"mcm","clk":"988033919","pt":1580473818253,"mc":[{"id":"1.168135803","rc":[{"batb":[[0,1.01,10]],"ltp":0.0,"tv":0.0,"id":2249229},{"batb":[[0,1.01,10]],"ltp":0.0,"tv":0.0,"id":5720747}]}]}
{"op":"mcm","clk":"989799972","pt":1580491427729,"mc":[{"id":"1.168135803","rc":[{"batb":[[0,1.01,10.2]],"ltp":0.0,"tv":0.0,"id":2249229},{"batb":[[0,1.01,10.2]],"ltp":0.0,"tv":0.0,"id":5720747}]}]}
{"op":"mcm","clk":"991991594","pt":1580511707738,"mc":[{"id":"1.168135803","rc":[{"batb":[[0,1.01,12.73]],"ltp":0.0,"tv":0.0,"id":2249229},{"batb":[[0,1.01,12.73]],"ltp":0.0,"tv":0.0,"id":5720747}]}]}
{"op":"mcm","clk":"991991655","pt":1580511708815,"mc":[{"id":"1.168135803","rc":[{"batb":[[0,1.01,10.71]],"ltp":0.0,"tv":0.0,"id":2249229},{"batb":[[0,1.01,10.71]],"ltp":0.0,"tv":0.0,"id":5720747}]}]}
{"op":"mcm","clk":"992004218","pt":1580511983757,"mc":[{"id":"1.168135803","rc":[{"batb":[[0,1.01,13.24]],"ltp":0.0,"tv":0.0,"id":2249229},{"batb":[[0,1.01,13.24]],"ltp":0.0,"tv":0.0,"id":5720747}]}]}
{"op":"mcm","clk":"992004256","pt":1580511984580,"mc":[{"id":"1.168135803","rc":[{"batb":[[0,1.01,11.21]],"ltp":0.0,"tv":0.0,"id":2249229},{"batb":[[0,1.01,11.21]],"ltp":0.0,"tv":0.0,"id":5720747}]}]}
{"op":"mcm","clk":"992859043","pt":1580531894609,"mc":[{"id":"1.168135803","rc":[{"batb":[[0,1.02,2780.76],[1,1.01,2791.57]],"ltp":0.0,"tv":0.0,"id":2249229},{"batb":[[0,1.02,2780.76],[1,1.01,2791.57]],"ltp":0.0,"tv":0.0,"id":5720747}]}]}
{"op":"mcm","clk":"992859544","pt":1580531911833,"mc":[{"id":"1.168135803","marketDefinition":{"bspMarket":false,"turnInPlayEnabled":true,"persistenceEnabled":true,"marketBaseRate":5.0,"eventId":"29678823","eventTypeId":"2","numberOfWinners":1,"bettingType":"ODDS","marketType":"SET_WINNER","marketTime":"2020-02-02T08:30:00.000Z","suspendTime":"2020-02-02T08:30:00.000Z","bspReconciled":false,"complete":true,"inPlay":false,"crossMatching":true,"runnersVoidable":false,"numberOfActiveRunners":2,"betDelay":0,"status":"OPEN","runners":[{"status":"ACTIVE","sortPriority":1,"id":5720747,"name":"Dominic Thiem"},{"status":"ACTIVE","sortPriority":2,"id":2249229,"name":"Novak Djokovic"}],"regulators":["MR_INT"],"countryCode":"AU","discountAllowed":true,"timezone":"GMT","openDate":"2020-02-02T08:30:00.000Z","version":3143005275,"name":"Set 4 Winner","eventName":"Thiem v Djokovic"}}]}
{"op":"mcm","clk":"1000969909","pt":1580584197683,"mc":[{"id":"1.168135803","rc":[{"batb":[[0,1.43,14],[1,1.02,2780.76],[2,1.01,2791.57]],"ltp":0.0,"tv":0.0,"id":2249229}]}]}
{"op":"mcm","clk":"1003387830","pt":1580607068727,"mc":[{"id":"1.168135803","rc":[{"batb":[[2,1.01,2791.58]],"ltp":0.0,"tv":0.0,"id":2249229}]}]}
{"op":"mcm","clk":"1003387847","pt":1580607068883,"mc":[{"id":"1.168135803","rc":[{"batb":[[0,1.43,14.01],[2,1.01,2791.57]],"ltp":0.0,"tv":0.0,"id":2249229},{"batb":[[0,1.02,2780.77]],"ltp":0.0,"tv":0.0,"id":5720747}]}]}
{"op":"mcm","clk":"1003703671","pt":1580611537304,"mc":[{"id":"1.168135803","rc":[{"batb":[[2,1.01,2793.57]],"ltp":0.0,"tv":0.0,"id":2249229},{"batb":[[1,1.01,2793.57]],"ltp":0.0,"tv":0.0,"id":5720747}]}]}
{"op":"mcm","clk":"1003704419","pt":1580611549199,"mc":[{"id":"1.168135803","rc":[{"batb":[[2,1.01,2793.58]],"ltp":0.0,"tv":0.0,"id":2249229},{"batb":[[1,1.01,2793.58]],"ltp":0.0,"tv":0.0,"id":5720747}]}]}
{"op":"mcm","clk":"1003705163","pt":1580611560314,"mc":[{"id":"1.168135803","rc":[{"batb":[[0,1.43,14.02],[2,1.01,2791.57]],"ltp":0.0,"tv":0.0,"id":2249229},{"batb":[[0,1.02,2780.78],[1,1.01,2791.57]],"ltp":0.0,"tv":0.0,"id":5720747}]}]}
{"op":"mcm","clk":"1004387494","pt":1580628621299,"mc":[{"id":"1.168135803","rc":[{"batb":[[0,1.44,2.02],[1,1.43,14],[2,1.02,2780.76]],"ltp":0.0,"tv":0.0,"id":2249229},{"batb":[[0,1.03,2.02],[1,1.02,2780.76],[2,1.01,2791.57]],"ltp":0.0,"tv":0.0,"id":5720747}]}]}
{"op":"mcm","clk":"1004411255","pt":1580629220799,"mc":[{"id":"1.168135803","rc":[{"batb":[[0,1.43,14.02],[1,1.02,2780.76],[2,1.01,2791.57]],"ltp":0.0,"tv":0.0,"id":2249229},{"batb":[[0,1.02,2780.78],[1,1.01,2791.57],[2,1.01,0]],"ltp":0.0,"tv":0.0,"id":5720747}]}]}
{"op":"mcm","clk":"1004411662","pt":1580629229425,"mc":[{"id":"1.168135803","rc":[{"batb":[[0,1.44,2.02],[1,1.43,14],[2,1.02,2780.76]],"ltp":0.0,"tv":0.0,"id":2249229},{"batb":[[0,1.03,2.02],[1,1.02,2780.76],[2,1.01,2791.57]],"ltp":0.0,"tv":0.0,"id":5720747}]}]}
{"op":"mcm","clk":"1004437518","pt":1580629828662,"mc":[{"id":"1.168135803","rc":[{"batb":[[0,1.02,2780.78],[1,1.01,2791.57],[2,1.01,0]],"ltp":0.0,"tv":0.0,"id":5720747}]}]}
{"op":"mcm","clk":"1004437580","pt":1580629829791,"mc":[{"id":"1.168135803","rc":[{"batb":[[0,1.43,14.02],[1,1.02,2780.76],[2,1.01,2791.57]],"ltp":0.0,"tv":0.0,"id":2249229}]}]}
{"op":"mcm","clk":"1004438576","pt":1580629850691,"mc":[{"id":"1.168135803","rc":[{"batb":[[0,1.44,2.02],[1,1.43,14],[2,1.02,2780.76]],"ltp":0.0,"tv":0.0,"id":2249229},{"batb":[[0,1.03,2.02],[1,1.02,2780.76],[2,1.01,2791.57]],"ltp":0.0,"tv":0.0,"id":5720747}]}]}
{"op":"mcm","clk":"1004466098","pt":1580630449719,"mc":[{"id":"1.168135803","rc":[{"batb":[[0,1.43,14.02],[1,1.02,2780.76],[2,1.01,2791.57]],"ltp":0.0,"tv":0.0,"id":2249229},{"batb":[[0,1.02,2780.78],[1,1.01,2791.57],[2,1.01,0]],"ltp":0.0,"tv":0.0,"id":5720747}]}]}
{"op":"mcm","clk":"1004466751","pt":1580630463226,"mc":[{"id":"1.168135803","rc":[{"batb":[[0,1.44,2.02],[1,1.43,14],[2,1.02,2780.76]],"ltp":0.0,"tv":0.0,"id":2249229},{"batb":[[0,1.03,2.02],[1,1.02,2780.76],[2,1.01,2791.57]],"ltp":0.0,"tv":0.0,"id":5720747}]}]}
{"op":"mcm","clk":"1004493398","pt":1580631062746,"mc":[{"id":"1.168135803","rc":[{"batb":[[0,1.43,14.02],[1,1.02,2780.76],[2,1.01,2791.57]],"ltp":0.0,"tv":0.0,"id":2249229},{"batb":[[0,1.02,2780.78],[1,1.01,2791.57],[2,1.01,0]],"ltp":0.0,"tv":0.0,"id":5720747}]}]}
{"op":"mcm","clk":"1004494528","pt":1580631085784,"mc":[{"id":"1.168135803","rc":[{"batb":[[0,1.44,2.02],[1,1.43,14],[2,1.02,2780.76]],"ltp":0.0,"tv":0.0,"id":2249229},{"batb":[[0,1.03,2.02],[1,1.02,2780.76],[2,1.01,2791.57]],"ltp":0.0,"tv":0.0,"id":5720747}]}]}
{"op":"mcm","clk":"1004520523","pt":1580631684642,"mc":[{"id":"1.168135803","rc":[{"batb":[[0,1.43,14.02],[1,1.02,2780.76],[2,1.01,2791.57]],"ltp":0.0,"tv":0.0,"id":2249229},{"batb":[[0,1.02,2780.78],[1,1.01,2791.57],[2,1.01,0]],"ltp":0.0,"tv":0.0,"id":5720747}]}]}
{"op":"mcm","clk":"1004521919","pt":1580631716374,"mc":[{"id":"1.168135803","rc":[{"batb":[[0,1.44,2.02],[1,1.43,14],[2,1.02,2780.76]],"ltp":0.0,"tv":0.0,"id":2249229},{"batb":[[0,1.03,2.02],[1,1.02,2780.76],[2,1.01,2791.57]],"ltp":0.0,"tv":0.0,"id":5720747}]}]}
{"op":"mcm","clk":"1004529678","pt":1580631895744,"mc":[{"id":"1.168135803","rc":[{"batb":[[0,1.43,14.02],[1,1.02,2780.76],[2,1.01,2791.57]],"ltp":0.0,"tv":0.0,"id":2249229},{"batb":[[0,1.02,2780.78],[1,1.01,2791.57],[2,1.01,0]],"ltp":0.0,"tv":0.0,"id":5720747}]}]}
{"op":"mcm","clk":"1004530882","pt":1580631919395,"mc":[{"id":"1.168135803","rc":[{"batb":[[0,1.44,2.02],[1,1.43,14],[2,1.02,2780.76]],"ltp":0.0,"tv":0.0,"id":2249229},{"batb":[[0,1.03,2.02],[1,1.02,2780.76],[2,1.01,2791.57]],"ltp":0.0,"tv":0.0,"id":5720747}]}]}
{"op":"mcm","clk":"1004539052","pt":1580632098795,"mc":[{"id":"1.168135803","rc":[{"batb":[[0,1.02,2780.78],[1,1.01,2791.57],[2,1.01,0]],"ltp":0.0,"tv":0.0,"id":5720747}]}]}
{"op":"mcm","clk":"1004539108","pt":1580632099784,"mc":[{"id":"1.168135803","rc":[{"batb":[[0,1.43,14.02],[1,1.02,2780.76],[2,1.01,2791.57]],"ltp":0.0,"tv":0.0,"id":2249229}]}]}
{"op":"mcm","clk":"1004540084","pt":1580632125491,"mc":[{"id":"1.168135803","rc":[{"batb":[[0,1.44,2.02],[1,1.43,14],[2,1.02,2780.76]],"ltp":0.0,"tv":0.0,"id":2249229},{"batb":[[0,1.03,2.02],[1,1.02,2780.76],[2,1.01,2791.57]],"ltp":0.0,"tv":0.0,"id":5720747}]}]}
{"op":"mcm","clk":"1004542271","pt":1580632185773,"mc":[{"id":"1.168135803","rc":[{"batb":[[0,1.43,14.02],[1,1.02,2780.76],[2,1.01,2791.57]],"ltp":0.0,"tv":0.0,"id":2249229},{"batb":[[0,1.02,2780.78],[1,1.01,2791.57],[2,1.01,0]],"ltp":0.0,"tv":0.0,"id":5720747}]}]}
{"op":"mcm","clk":"1004542600","pt":1580632193793,"mc":[{"id":"1.168135803","rc":[{"batb":[[0,1.44,2.02],[1,1.43,14],[2,1.02,2780.76]],"ltp":0.0,"tv":0.0,"id":2249229},{"batb":[[0,1.03,2.02],[1,1.02,2780.76],[2,1.01,2791.57]],"ltp":0.0,"tv":0.0,"id":5720747}]}]}
{"op":"mcm","clk":"1004545279","pt":1580632252812,"mc":[{"id":"1.168135803","rc":[{"batb":[[0,1.43,14.02],[1,1.02,2780.76],[2,1.01,2791.57]],"ltp":0.0,"tv":0.0,"id":2249229},{"batb":[[0,1.02,2780.78],[1,1.01,2791.57],[2,1.01,0]],"ltp":0.0,"tv":0.0,"id":5720747}]}]}
{"op":"mcm","clk":"1004545696","pt":1580632261894,"mc":[{"id":"1.168135803","rc":[{"batb":[[0,1.44,2.02],[1,1.43,14],[2,1.02,2780.76]],"ltp":0.0,"tv":0.0,"id":2249229},{"batb":[[0,1.03,2.02],[1,1.02,2780.76],[2,1.01,2791.57]],"ltp":0.0,"tv":0.0,"id":5720747}]}]}
{"op":"mcm","clk":"1004548504","pt":1580632321278,"mc":[{"id":"1.168135803","rc":[{"batb":[[0,1.43,14.02],[1,1.02,2780.76],[2,1.01,2791.57]],"ltp":0.0,"tv":0.0,"id":2249229},{"batb":[[0,1.02,2780.78],[1,1.01,2791.57],[2,1.01,0]],"ltp":0.0,"tv":0.0,"id":5720747}]}]}
{"op":"mcm","clk":"1004549004","pt":1580632331804,"mc":[{"id":"1.168135803","rc":[{"batb":[[0,1.44,2.02],[1,1.43,14],[2,1.02,2780.76]],"ltp":0.0,"tv":0.0,"id":2249229},{"batb":[[0,1.03,2.02],[1,1.02,2780.76],[2,1.01,2791.57]],"ltp":0.0,"tv":0.0,"id":5720747}]}]}
{"op":"mcm","clk":"1004551813","pt":1580632390749,"mc":[{"id":"1.168135803","rc":[{"batb":[[0,1.43,14.02],[1,1.02,2780.76],[2,1.01,2791.57]],"ltp":0.0,"tv":0.0,"id":2249229},{"batb":[[0,1.02,2780.78],[1,1.01,2791.57],[2,1.01,0]],"ltp":0.0,"tv":0.0,"id":5720747}]}]}
{"op":"mcm","clk":"1004552240","pt":1580632399787,"mc":[{"id":"1.168135803","rc":[{"batb":[[0,1.44,2.02],[1,1.43,14],[2,1.02,2780.76]],"ltp":0.0,"tv":0.0,"id":2249229},{"batb":[[0,1.03,2.02],[1,1.02,2780.76],[2,1.01,2791.57]],"ltp":0.0,"tv":0.0,"id":5720747}]}]}
{"op":"mcm","clk":"1004554722","pt":1580632458734,"mc":[{"id":"1.168135803","rc":[{"batb":[[0,1.43,14.02],[1,1.02,2780.76],[2,1.01,2791.57]],"ltp":0.0,"tv":0.0,"id":2249229},{"batb":[[0,1.02,2780.78],[1,1.01,2791.57],[2,1.01,0]],"ltp":0.0,"tv":0.0,"id":5720747}]}]}
{"op":"mcm","clk":"1004554986","pt":1580632466346,"mc":[{"id":"1.168135803","rc":[{"batb":[[0,1.44,2.02],[1,1.43,14],[2,1.02,2780.76]],"ltp":0.0,"tv":0.0,"id":2249229},{"batb":[[0,1.03,2.02],[1,1.02,2780.76],[2,1.01,2791.57]],"ltp":0.0,"tv":0.0,"id":5720747}]}]}
{"op":"mcm","clk":"1004557449","pt":1580632525656,"mc":[{"id":"1.168135803","rc":[{"batb":[[0,1.43,14.02],[1,1.02,2780.76],[2,1.01,2791.57]],"ltp":0.0,"tv":0.0,"id":2249229},{"batb":[[0,1.02,2780.78],[1,1.01,2791.57],[2,1.01,0]],"ltp":0.0,"tv":0.0,"id":5720747}]}]}
{"op":"mcm","clk":"1004586386","pt":1580633151547,"mc":[{"id":"1.168135803","marketDefinition":{"bspMarket":false,"turnInPlayEnabled":true,"persistenceEnabled":true,"marketBaseRate":5.0,"eventId":"29678823","eventTypeId":"2","numberOfWinners":1,"bettingType":"ODDS","marketType":"SET_WINNER","marketTime":"2020-02-02T08:30:00.000Z","suspendTime":"2020-02-02T08:30:00.000Z","bspReconciled":false,"complete":true,"inPlay":true,"crossMatching":true,"runnersVoidable":false,"numberOfActiveRunners":2,"betDelay":3,"status":"OPEN","runners":[{"status":"ACTIVE","sortPriority":1,"id":5720747,"name":"Dominic Thiem"},{"status":"ACTIVE","sortPriority":2,"id":2249229,"name":"Novak Djokovic"}],"regulators":["MR_INT"],"countryCode":"AU","discountAllowed":true,"timezone":"GMT","openDate":"2020-02-02T08:30:00.000Z","version":3148327167,"name":"Set 4 Winner","eventName":"Thiem v Djokovic"},"rc":[{"batb":[[0,1.02,2780.78],[1,1.01,2791.06],[2,1.01,0]],"ltp":0.0,"tv":0.0,"id":2249229},{"batb":[[1,1.01,2791.06]],"ltp":0.0,"tv":0.0,"id":5720747}]}]}
{"op":"mcm","clk":"1004806859","pt":1580637682758,"mc":[{"id":"1.168135803","rc":[{"batb":[[0,1.25,45.45],[1,1.02,2780.76],[2,1.01,2791.06]],"ltp":0.0,"tv":0.0,"id":2249229}]}]}
{"op":"mcm","clk":"1004807235","pt":1580637687647,"mc":[{"id":"1.168135803","rc":[{"batb":[[0,1.25,45.45],[1,1.02,2780.76],[2,1.01,2791.06]],"ltp":0.0,"tv":0.0,"id":5720747}]}]}
{"op":"mcm","clk":"1004935766","pt":1580639273471,"mc":[{"id":"1.168135803","rc":[{"batb":[[0,2.04,376.26],[1,1.25,45.45],[2,1.02,2780.76]],"ltp":0.0,"tv":0.0,"id":5720747}]}]}
{"op":"mcm","clk":"1004941529","pt":1580639330790,"mc":[{"id":"1.168135803","rc":[{"batb":[[0,2.12,24.23],[1,2.04,376.26],[2,1.25,45.45]],"ltp":0.0,"tv":0.0,"id":5720747}]}]}
{"op":"mcm","clk":"1004947932","pt":1580639394773,"mc":[{"id":"1.168135803","rc":[{"batb":[[0,1.34,123.37],[1,1.25,45.43],[2,1.02,2780.76]],"ltp":0.0,"tv":0.0,"id":2249229}]}]}
{"op":"mcm","clk":"1004949414","pt":1580639407771,"mc":[{"id":"1.168135803","rc":[{"batl":[[0,1000,6.09]],"ltp":0.0,"tv":0.0,"id":2249229}]}]}
{"op":"mcm","clk":"1004949822","pt":1580639411786,"mc":[{"id":"1.168135803","rc":[{"trd":[[1.34,0.03],[1.48,0.02],[1.49,0.02]],"batb":[[0,1.34,123.33]],"ltp":1.34,"tv":0.06,"id":2249229}],"tv":0.06}]}
{"op":"mcm","clk":"1004951276","pt":1580639425800,"mc":[{"id":"1.168135803","rc":[{"batb":[[2,1.02,2822.76]],"ltp":1.34,"tv":0.06,"id":2249229}]}]}
{"op":"mcm","clk":"1004951359","pt":1580639426796,"mc":[{"id":"1.168135803","rc":[{"batb":[[2,1.03,28]],"ltp":1.34,"tv":0.06,"id":2249229}]}]}
{"op":"mcm","clk":"1004951446","pt":1580639427780,"mc":[{"id":"1.168135803","rc":[{"batb":[[2,1.04,21]],"ltp":1.34,"tv":0.06,"id":2249229}]}]}
{"op":"mcm","clk":"1004951543","pt":1580639428776,"mc":[{"id":"1.168135803","rc":[{"batb":[[2,1.05,16.8]],"ltp":1.34,"tv":0.06,"id":2249229}]}]}
{"op":"mcm","clk":"1004951642","pt":1580639429709,"mc":[{"id":"1.168135803","rc":[{"batb":[[0,1.34,123.35]],"ltp":1.34,"tv":0.06,"id":2249229}]}]}
{"op":"mcm","clk":"1004953449","pt":1580639448409,"mc":[{"id":"1.168135803","rc":[{"batb":[[0,1.34,123.36]],"ltp":1.34,"tv":0.06,"id":2249229}]}]}
{"op":"mcm","clk":"1004964654","pt":1580639556777,"mc":[{"id":"1.168135803","rc":[{"batb":[[0,1.36,27.28],[1,1.34,123.35],[2,1.25,45.43]],"ltp":1.34,"tv":0.06,"id":2249229}]}]}
{"op":"mcm","clk":"1004968450","pt":1580639593765,"mc":[{"id":"1.168135803","rc":[{"batb":[[1,1.25,45.45],[2,1.05,16.8]],"ltp":1.34,"tv":0.06,"id":2249229}]}]}
{"op":"mcm","clk":"1004968878","pt":1580639597764,"mc":[{"id":"1.168135803","rc":[{"batb":[[1,1.34,55.81],[2,1.25,45.43]],"ltp":1.34,"tv":0.06,"id":2249229}]}]}
{"op":"mcm","clk":"1004983626","pt":1580639759715,"mc":[{"id":"1.168135803","rc":[{"batb":[[1,1.25,45.45],[2,1.05,16.8]],"ltp":1.34,"tv":0.06,"id":2249229}]}]}
{"op":"mcm","clk":"1004983999","pt":1580639763604,"mc":[{"id":"1.168135803","rc":[{"batb":[[0,1.38,61.15],[1,1.36,27.26],[2,1.25,45.45]],"ltp":1.34,"tv":0.06,"id":2249229}]}]}
{"op":"mcm","clk":"1004987328","pt":1580639799729,"mc":[{"id":"1.168135803","rc":[{"batb":[[0,1.39,18.95],[1,1.38,61.13],[2,1.36,27.26]],"ltp":1.34,"tv":0.06,"id":2249229}]}]}
{"op":"mcm","clk":"1005009609","pt":1580640031713,"mc":[{"id":"1.168135803","rc":[{"batb":[[1,1.36,27.26],[2,1.25,45.45]],"ltp":1.34,"tv":0.06,"id":2249229},{"batb":[[1,1.25,45.45],[2,1.05,16.8]],"ltp":0.0,"tv":0.0,"id":5720747}]}]}
{"op":"mcm","clk":"1005010891","pt":1580640045732,"mc":[{"id":"1.168135803","rc":[{"batb":[[1,1.38,110.07],[2,1.36,27.26]],"ltp":1.34,"tv":0.06,"id":2249229},{"batb":[[1,1.97,635.03],[2,1.25,45.45]],"ltp":0.0,"tv":0.0,"id":5720747}]}]}
{"op":"mcm","clk":"1005020275","pt":1580640139770,"mc":[{"id":"1.168135803","rc":[{"batb":[[1,1.36,27.26],[2,1.25,45.45]],"ltp":1.34,"tv":0.06,"id":2249229}]}]}
{"op":"mcm","clk":"1005020502","pt":1580640141658,"mc":[{"id":"1.168135803","rc":[{"batb":[[1,1.25,45.45],[2,1.05,16.8]],"ltp":0.0,"tv":0.0,"id":5720747}]}]}
{"op":"mcm","clk":"1005021285","pt":1580640147752,"mc":[{"id":"1.168135803","rc":[{"batb":[[1,1.38,109.9],[2,1.36,27.26]],"ltp":1.34,"tv":0.06,"id":2249229},{"batb":[[1,1.97,635.15],[2,1.25,45.45]],"ltp":0.0,"tv":0.0,"id":5720747}]}]}
{"op":"mcm","clk":"1005021429","pt":1580640148793,"mc":[{"id":"1.168135803","rc":[{"batb":[[1,1.36,27.26],[2,1.25,45.45]],"ltp":1.34,"tv":0.06,"id":2249229},{"batb":[[1,1.25,45.45],[2,1.05,16.8]],"ltp":0.0,"tv":0.0,"id":5720747}]}]}
{"op":"mcm","clk":"1005022096","pt":1580640153788,"mc":[{"id":"1.168135803","rc":[{"batb":[[1,1.38,234.23],[2,1.36,27.26]],"ltp":1.34,"tv":0.06,"id":2249229},{"batb":[[1,1.97,548.24],[2,1.25,45.45]],"ltp":0.0,"tv":0.0,"id":5720747}]}]}
{"op":"mcm","clk":"1005024714","pt":1580640172785,"mc":[{"id":"1.168135803","rc":[{"batb":[[1,1.36,27.26],[2,1.25,45.45]],"ltp":1.34,"tv":0.06,"id":2249229}]}]}
{"op":"mcm","clk":"1005027144","pt":1580640189713,"mc":[{"id":"1.168135803","rc":[{"batb":[[1,1.38,215.54],[2,1.36,27.26]],"ltp":1.34,"tv":0.06,"id":2249229}]}]}
{"op":"mcm","clk":"1005030510","pt":1580640211809,"mc":[{"id":"1.168135803","rc":[{"batb":[[1,1.36,27.26],[2,1.25,45.45]],"ltp":1.34,"tv":0.06,"id":2249229}]}]}
{"op":"mcm","clk":"1005031411","pt":1580640218769,"mc":[{"id":"1.168135803","rc":[{"batb":[[1,1.38,214.79],[2,1.36,27.26]],"ltp":1.34,"tv":0.06,"id":2249229}]}]}
{"op":"mcm","clk":"1005032119","pt":1580640223650,"mc":[{"id":"1.168135803","rc":[{"batb":[[1,1.36,27.26],[2,1.25,45.45]],"ltp":1.34,"tv":0.06,"id":2249229}]}]}
{"op":"mcm","clk":"1005033616","pt":1580640234775,"mc":[{"id":"1.168135803","rc":[{"batb":[[1,1.38,198.3],[2,1.36,27.26]],"ltp":1.34,"tv":0.06,"id":2249229}]}]}
{"op":"mcm","clk":"1005035419","pt":1580640247813,"mc":[{"id":"1.168135803","rc":[{"batb":[[1,1.36,27.26],[2,1.25,45.45]],"ltp":1.34,"tv":0.06,"id":2249229}]}]}
{"op":"mcm","clk":"1005035537","pt":1580640248792,"mc":[{"id":"1.168135803","rc":[{"batb":[[1,1.98,21.2],[2,1.97,548.24]],"ltp":0.0,"tv":0.0,"id":5720747}]}]}
{"op":"mcm","clk":"1005035893","pt":1580640251774,"mc":[{"id":"1.168135803","rc":[{"batb":[[1,1.38,3.1],[2,1.36,27.26]],"ltp":1.34,"tv":0.06,"id":2249229}]}]}
{"op":"mcm","clk":"1005036391","pt":1580640255795,"mc":[{"id":"1.168135803","rc":[{"batb":[[0,1.39,16.67]],"ltp":1.34,"tv":0.06,"id":2249229}]}]}
{"op":"mcm","clk":"1005036772","pt":1580640258785,"mc":[{"id":"1.168135803","rc":[{"batb":[[2,1.25,45.45]],"ltp":1.34,"tv":0.06,"id":2249229}]}]}
{"op":"mcm","clk":"1005037098","pt":1580640261722,"mc":[{"id":"1.168135803","rc":[{"batb":[[2,1.34,27.28]],"ltp":1.34,"tv":0.06,"id":2249229}]}]}
{"op":"mcm","clk":"1005037446","pt":1580640264809,"mc":[{"id":"1.168135803","rc":[{"batb":[[1,1.34,27.28],[2,1.25,45.43]],"ltp":1.34,"tv":0.06,"id":2249229}]}]}
{"op":"mcm","clk":"1005037911","pt":1580640268513,"mc":[{"id":"1.168135803","rc":[{"batb":[[0,1.4,7.8],[1,1.39,16.66],[2,1.34,27.28]],"ltp":1.34,"tv":0.06,"id":2249229}]}]}
{"op":"mcm","clk":"1005044597","pt":1580640316801,"mc":[{"id":"1.168135803","rc":[{"batb":[[0,1.39,16.67],[1,1.34,27.28],[2,1.25,45.43]],"ltp":1.34,"tv":0.06,"id":2249229}]}]}
{"op":"mcm","clk":"1005045325","pt":1580640321814,"mc":[{"id":"1.168135803","rc":[{"batb":[[0,1.44,13.94],[1,1.39,16.66],[2,1.34,27.28]],"ltp":1.34,"tv":0.06,"id":2249229}]}]}
{"op":"mcm","clk":"1005051436","pt":1580640367747,"mc":[{"id":"1.168135803","rc":[{"batb":[[0,2.12,15.14]],"ltp":0.0,"tv":0.0,"id":5720747}]}]}
{"op":"mcm","clk":"1005059713","pt":1580640429624,"mc":[{"id":"1.168135803","rc":[{"batb":[[0,1.39,16.67],[1,1.34,27.28],[2,1.25,45.43]],"ltp":1.34,"tv":0.06,"id":2249229},{"batb":[[2,1.25,45.45]],"ltp":0.0,"tv":0.0,"id":5720747}]}]}
{"op":"mcm","clk":"1005060227","pt":1580640433810,"mc":[{"id":"1.168135803","rc":[{"batb":[[2,1.86,155.97]],"ltp":0.0,"tv":0.0,"id":5720747}]}]}
{"op":"mcm","clk":"1005065288","pt":1580640476691,"mc":[{"id":"1.168135803","rc":[{"batb":[[0,1.4,580.75],[1,1.39,16.66],[2,1.34,27.28]],"ltp":1.34,"tv":0.06,"id":2249229}]}]}
{"op":"mcm","clk":"1005067536","pt":1580640494799,"mc":[{"id":"1.168135803","rc":[{"batb":[[0,1.39,16.67],[1,1.34,27.28],[2,1.25,45.43]],"ltp":1.34,"tv":0.06,"id":2249229}]}]}
{"op":"mcm","clk":"1005068129","pt":1580640499717,"mc":[{"id":"1.168135803","rc":[{"batb":[[0,1.4,576.92],[1,1.39,16.66],[2,1.34,27.28]],"ltp":1.34,"tv":0.06,"id":2249229}]}]}
{"op":"mcm","clk":"1005069049","pt":1580640507812,"mc":[{"id":"1.168135803","rc":[{"batb":[[0,1.39,16.67],[1,1.34,27.28],[2,1.25,45.43]],"ltp":1.34,"tv":0.06,"id":2249229}]}]}
{"op":"mcm","clk":"1005070385","pt":1580640518762,"mc":[{"id":"1.168135803","rc":[{"batb":[[0,1.44,523.31],[1,1.39,16.66],[2,1.34,27.28]],"ltp":1.34,"tv":0.06,"id":2249229}]}]}
{"op":"mcm","clk":"1005086667","pt":1580640641536,"mc":[{"id":"1.168135803","rc":[{"trd":[[2.12,30.28]],"batb":[[0,1.98,21.2],[1,1.86,155.97],[2,1.25,45.45]],"batl":[[0,2.12,2.54]],"ltp":2.12,"tv":30.28,"id":5720747}],"tv":30.34}]}
{"op":"mcm","clk":"1005087408","pt":1580640647721,"mc":[{"id":"1.168135803","rc":[{"trd":[[1.89,2.27]],"ltp":1.89,"tv":2.33,"id":2249229},{"trd":[[2.12,32.3]],"batl":[[0,2.12,0.52]],"ltp":2.12,"tv":32.3,"id":5720747}],"tv":34.64}]}
{"op":"mcm","clk":"1005087962","pt":1580640652757,"mc":[{"id":"1.168135803","rc":[{"batb":[[0,1.86,155.97],[1,1.25,45.45],[2,1.05,16.8]],"ltp":2.12,"tv":32.3,"id":5720747}]}]}
{"op":"mcm","clk":"1005088313","pt":1580640655724,"mc":[{"id":"1.168135803","rc":[{"batb":[[0,1.88,21.2],[1,1.86,155.97],[2,1.25,45.45]],"ltp":2.12,"tv":32.3,"id":5720747}]}]}
{"op":"mcm","clk":"1005088660","pt":1580640658737,"mc":[{"id":"1.168135803","rc":[{"batl":[[0,2.5,20.52]],"ltp":2.12,"tv":32.3,"id":5720747}]}]}
{"op":"mcm","clk":"1005089723","pt":1580640667758,"mc":[{"id":"1.168135803","rc":[{"batb":[[0,1.68,18.93],[1,1.44,523.31],[2,1.39,16.66]],"ltp":1.89,"tv":2.33,"id":2249229}]}]}
{"op":"mcm","clk":"1005094677","pt":1580640709818,"mc":[{"id":"1.168135803","rc":[{"batb":[[0,1.91,29.41],[1,1.88,21.2],[2,1.86,155.97]],"ltp":2.12,"tv":32.3,"id":5720747}]}]}
{"op":"mcm","clk":"1005098368","pt":1580640741748,"mc":[{"id":"1.168135803","rc":[{"batl":[[0,2.12,0.52]],"ltp":2.12,"tv":32.3,"id":5720747}]}]}
{"op":"mcm","clk":"1005099396","pt":1580640750573,"mc":[{"id":"1.168135803","rc":[{"batb":[[1,1.39,16.67],[2,1.34,27.28]],"ltp":1.89,"tv":2.33,"id":2249229},{"batb":[[2,1.25,45.45]],"ltp":2.12,"tv":32.3,"id":5720747}]}]}
{"op":"mcm","clk":"1005101512","pt":1580640767692,"mc":[{"id":"1.168135803","rc":[{"batb":[[1,1.44,516.37],[2,1.39,16.66]],"ltp":1.89,"tv":2.33,"id":2249229},{"batb":[[2,1.86,423.69]],"ltp":2.12,"tv":32.3,"id":5720747}]}]}
{"op":"mcm","clk":"1005102647","pt":1580640777680,"mc":[{"id":"1.168135803","rc":[{"batb":[[1,1.46,16.67],[2,1.44,516.35]],"ltp":1.89,"tv":2.33,"id":2249229}]}]}
{"op":"mcm","clk":"1005103115","pt":1580640781688,"mc":[{"id":"1.168135803","rc":[{"batb":[[1,1.88,12.12]],"ltp":2.12,"tv":32.3,"id":5720747}]}]}
{"op":"mcm","clk":"1005103359","pt":1580640783725,"mc":[{"id":"1.168135803","rc":[{"batb":[[1,1.86,423.69],[2,1.25,45.45]],"ltp":2.12,"tv":32.3,"id":5720747}]}]}
{"op":"mcm","clk":"1005103741","pt":1580640786813,"mc":[{"id":"1.168135803","rc":[{"batb":[[0,1.92,12.12],[1,1.91,29.41],[2,1.86,423.69]],"ltp":2.12,"tv":32.3,"id":5720747}]}]}
{"op":"mcm","clk":"1005104176","pt":1580640790702,"mc":[{"id":"1.168135803","rc":[{"batb":[[0,1.46,16.67],[1,1.44,516.35],[2,1.39,16.66]],"ltp":1.89,"tv":2.33,"id":2249229}]}]}
{"op":"mcm","clk":"1005104518","pt":1580640793820,"mc":[{"id":"1.168135803","rc":[{"batb":[[0,1.64,18.93],[1,1.46,16.67],[2,1.44,516.35]],"ltp":1.89,"tv":2.33,"id":2249229}]}]}
{"op":"mcm","clk":"1005106113","pt":1580640807738,"mc":[{"id":"1.168135803","rc":[{"batb":[[1,1.86,423.69],[2,1.25,45.45]],"ltp":2.12,"tv":32.3,"id":5720747}]}]}
{"op":"mcm","clk":"1005106430","pt":1580640810730,"mc":[{"id":"1.168135803","rc":[{"batb":[[0,2,29.41],[1,1.92,12.12],[2,1.86,423.69]],"ltp":2.12,"tv":32.3,"id":5720747}]}]}
{"op":"mcm","clk":"1005110313","pt":1580640842782,"mc":[{"id":"1.168135803","rc":[{"batb":[[2,1.39,16.66]],"ltp":1.89,"tv":2.33,"id":2249229}]}]}
{"op":"mcm","clk":"1005110865","pt":1580640847796,"mc":[{"id":"1.168135803","rc":[{"batb":[[1,1.46,543.17]],"ltp":1.89,"tv":2.33,"id":2249229}]}]}
{"op":"mcm","clk":"1005112313","pt":1580640859816,"mc":[{"id":"1.168135803","rc":[{"trd":[[1.64,36.7],[1.89,2.85]],"batb":[[0,1.46,543.76],[1,1.39,16.66],[2,1.34,27.28]],"ltp":1.64,"tv":39.61,"id":2249229},{"trd":[[2.12,32.82]],"ltp":2.12,"tv":32.82,"id":5720747}],"tv":72.44}]}
{"op":"mcm","clk":"1005113995","pt":1580640873727,"mc":[{"id":"1.168135803","rc":[{"batb":[[0,2.02,19.69],[1,2,29.41],[2,1.92,12.12]],"ltp":2.12,"tv":32.82,"id":5720747}]}]}
{"op":"mcm","clk":"1005114606","pt":1580640878738,"mc":[{"id":"1.168135803","rc":[{"batb":[[2,1.86,423.69]],"ltp":2.12,"tv":32.82,"id":5720747}]}]}
{"op":"mcm","clk":"1005114935","pt":1580640881804,"mc":[{"id":"1.168135803","rc":[{"batb":[[2,1.9,12.12]],"ltp":2.12,"tv":32.82,"id":5720747}]}]}
{"op":"mcm","clk":"1005120552","pt":1580640926267,"mc":[{"id":"1.168135803","rc":[{"batl":[[0,1.8,839.35]],"ltp":1.64,"tv":39.61,"id":2249229}]}]}
{"op":"mcm","clk":"1005121169","pt":1580640931784,"mc":[{"id":"1.168135803","rc":[{"batb":[[0,1.46,17.26]],"ltp":1.64,"tv":39.61,"id":2249229}]}]}
{"op":"mcm","clk":"1005122243","pt":1580640940719,"mc":[{"id":"1.168135803","rc":[{"batb":[[0,1.39,17.26],[1,1.34,27.28],[2,1.25,45.43]],"ltp":1.64,"tv":39.61,"id":2249229}]}]}
{"op":"mcm","clk":"1005122371","pt":1580640941814,"mc":[{"id":"1.168135803","rc":[{"batb":[[0,1.46,499.31],[1,1.39,16.66],[2,1.34,27.28]],"ltp":1.64,"tv":39.61,"id":2249229}]}]}
{"op":"mcm","clk":"1005122587","pt":1580640943733,"mc":[{"id":"1.168135803","rc":[{"batb":[[1,1.42,16.66],[2,1.39,16.66]],"ltp":1.64,"tv":39.61,"id":2249229}]}]}
{"op":"mcm","clk":"1005123195","pt":1580640948618,"mc":[{"id":"1.168135803","rc":[{"batb":[[1,1.39,16.66],[2,1.34,27.28]],"ltp":1.64,"tv":39.61,"id":2249229}]}]}
{"op":"mcm","clk":"1005123570","pt":1580640951728,"mc":[{"id":"1.168135803","rc":[{"batb":[[0,1.47,17.26],[1,1.46,498.71],[2,1.39,16.66]],"ltp":1.64,"tv":39.61,"id":2249229}]}]}
{"op":"mcm","clk":"1005126824","pt":1580640977743,"mc":[{"id":"1.168135803","rc":[{"batb":[[1,1.9,12.12],[2,1.82,451.14]],"ltp":2.12,"tv":32.82,"id":5720747}]}]}
{"op":"mcm","clk":"1005129068","pt":1580640995768,"mc":[{"id":"1.168135803","rc":[{"batb":[[0,1.9,12.12],[1,1.82,451.14],[2,1.25,45.45]],"ltp":2.12,"tv":32.82,"id":5720747}]}]}
{"op":"mcm","clk":"1005130092","pt":1580641003776,"mc":[{"id":"1.168135803","rc":[{"batb":[[1,1.84,22.72],[2,1.82,451.14]],"ltp":2.12,"tv":32.82,"id":5720747}]}]}
{"op":"mcm","clk":"1005133005","pt":1580641026816,"mc":[{"id":"1.168135803","rc":[{"batb":[[0,2.3,25.21],[1,1.9,12.12],[2,1.84,22.72]],"ltp":2.12,"tv":32.82,"id":5720747}]}]}
{"op":"mcm","clk":"1005144230","pt":1580641114657,"mc":[{"id":"1.168135803","rc":[{"batb":[[1,1.39,16.66],[2,1.34,27.28]],"ltp":1.64,"tv":39.61,"id":2249229}]}]}
{"op":"mcm","clk":"1005145348","pt":1580641122740,"mc":[{"id":"1.168135803","rc":[{"batl":[[0,2.8,48.69]],"ltp":2.12,"tv":32.82,"id":5720747}]}]}
{"op":"mcm","clk":"1005145705","pt":1580641125757,"mc":[{"id":"1.168135803","rc":[{"batb":[[0,1.39,17.26],[1,1.34,27.28],[2,1.25,45.43]],"ltp":1.64,"tv":39.61,"id":2249229}]}]}
{"op":"mcm","clk":"1005146111","pt":1580641128732,"mc":[{"id":"1.168135803","rc":[{"batb":[[0,1.42,17.26],[1,1.39,16.66],[2,1.34,27.28]],"ltp":1.64,"tv":39.61,"id":2249229}]}]}
{"op":"mcm","clk":"1005158581","pt":1580641212754,"mc":[{"id":"1.168135803","rc":[{"trd":[[2.3,50.42]],"batb":[[0,1.9,12.12],[1,1.84,22.72],[2,1.25,45.45]],"batl":[[0,2.3,4.79],[1,2.8,48.69]],"ltp":2.3,"tv":83.24,"id":5720747}],"tv":122.85}]}
{"op":"mcm","clk":"1005160466","pt":1580641223704,"mc":[{"id":"1.168135803","rc":[{"batl":[[0,2.8,48.69],[1,2.8,0]],"ltp":2.3,"tv":83.24,"id":5720747}]}]}
{"op":"mcm","clk":"1005160831","pt":1580641225714,"mc":[{"id":"1.168135803","rc":[{"batb":[[0,1.44,497.68],[1,1.42,16.66],[2,1.39,16.66]],"ltp":1.64,"tv":39.61,"id":2249229},{"batb":[[0,1.86,448.56]],"ltp":2.3,"tv":83.24,"id":5720747}]}]}
{"op":"mcm","clk":"1005160999","pt":1580641226809,"mc":[{"id":"1.168135803","rc":[{"batb":[[2,1.5,34.83]],"ltp":2.3,"tv":83.24,"id":5720747}]}]}
{"op":"mcm","clk":"1005161976","pt":1580641232802,"mc":[{"id":"1.168135803","rc":[{"batb":[[0,1.88,16.66],[1,1.86,448.56],[2,1.84,22.72]],"ltp":2.3,"tv":83.24,"id":5720747}]}]}
{"op":"mcm","clk":"1005165120","pt":1580641250727,"mc":[{"id":"1.168135803","rc":[{"batb":[[0,1.65,1.51],[1,1.44,497.68],[2,1.42,16.66]],"ltp":1.64,"tv":39.61,"id":2249229}]}]}
{"op":"mcm","clk":"1005169148","pt":1580641272686,"mc":[{"id":"1.168135803","rc":[{"batb":[[1,1.84,22.72],[2,1.5,34.83]],"ltp":2.3,"tv":83.24,"id":5720747}]}]}
{"op":"mcm","clk":"1005169327","pt":1580641273684,"mc":[{"id":"1.168135803","rc":[{"batb":[[0,2,174.83],[1,1.88,16.66],[2,1.84,22.72]],"ltp":2.3,"tv":83.24,"id":5720747}]}]}
{"op":"mcm","clk":"1005169685","pt":1580641275699,"mc":[{"id":"1.168135803","rc":[{"batb":[[2,1.86,213.09]],"ltp":2.3,"tv":83.24,"id":5720747}]}]}
{"op":"mcm","clk":"1005170174","pt":1580641278774,"mc":[{"id":"1.168135803","rc":[{"batl":[[0,2,839.35]],"ltp":1.64,"tv":39.61,"id":2249229}]}]}
{"op":"mcm","clk":"1005170898","pt":1580641282777,"mc":[{"id":"1.168135803","rc":[{"batb":[[0,2.04,84.02],[1,2,174.83],[2,1.88,16.66]],"ltp":2.3,"tv":83.24,"id":5720747}]}]}
{"op":"mcm","clk":"1005171070","pt":1580641283783,"mc":[{"id":"1.168135803","rc":[{"batb":[[0,1.66,264.9],[1,1.65,1.51],[2,1.44,497.68]],"ltp":1.64,"tv":39.61,"id":2249229}]}]}
{"op":"mcm","clk":"1005171391","pt":1580641285790,"mc":[{"id":"1.168135803","rc":[{"batl":[[0,1.98,839.35]],"ltp":1.64,"tv":39.61,"id":2249229}]}]}
{"op":"mcm","clk":"1005172243","pt":1580641290794,"mc":[{"id":"1.168135803","rc":[{"batb":[[0,1.65,1.51],[1,1.44,497.68],[2,1.42,16.66]],"ltp":1.64,"tv":39.61,"id":2249229},{"batb":[[0,2.1,158.94],[1,2.04,84.02],[2,2,174.83]],"ltp":2.3,"tv":83.24,"id":5720747}]}]}
{"op":"mcm","clk":"1005172778","pt":1580641293804,"mc":[{"id":"1.168135803","rc":[{"batb":[[1,1.42,17.26],[2,1.39,16.66]],"ltp":1.64,"tv":39.61,"id":2249229}]}]}
{"op":"mcm","clk":"1005172954","pt":1580641294807,"mc":[{"id":"1.168135803","rc":[{"batb":[[1,1.6,291.97],[2,1.42,16.67]],"ltp":1.64,"tv":39.61,"id":2249229}]}]}
{"op":"mcm","clk":"1005173096","pt":1580641295706,"mc":[{"id":"1.168135803","rc":[{"batb":[[1,2,174.83],[2,1.88,16.66]],"ltp":2.3,"tv":83.24,"id":5720747}]}]}
{"op":"mcm","clk":"1005173587","pt":1580641298727,"mc":[{"id":"1.168135803","rc":[{"batb":[[0,2.14,84.02],[1,2.1,158.94],[2,2,174.83]],"ltp":2.3,"tv":83.24,"id":5720747}]}]}
{"op":"mcm","clk":"1005175228","pt":1580641306727,"mc":[{"id":"1.168135803","rc":[{"batb":[[0,2.16,150.72],[1,2.14,84.02],[2,2.1,158.94]],"ltp":2.3,"tv":83.24,"id":5720747}]}]}
{"op":"mcm","clk":"1005175973","pt":1580641310811,"mc":[{"id":"1.168135803","rc":[{"batb":[[2,1.46,815.79]],"ltp":1.64,"tv":39.61,"id":2249229}]}]}
{"op":"mcm","clk":"1005178547","pt":1580641324745,"mc":[{"id":"1.168135803","rc":[{"batb":[[1,2.1,158.94],[2,1.88,16.66]],"ltp":2.3,"tv":83.24,"id":5720747}]}]}
{"op":"mcm","clk":"1005179034","pt":1580641327366,"mc":[{"id":"1.168135803","rc":[{"batb":[[0,2.18,84.02],[1,2.16,150.72],[2,2.1,158.94]],"ltp":2.3,"tv":83.24,"id":5720747}]}]}
{"op":"mcm","clk":"1005180363","pt":1580641334727,"mc":[{"id":"1.168135803","rc":[{"batb":[[0,2.2,145.69],[1,2.18,84.02],[2,2.16,150.72]],"ltp":2.3,"tv":83.24,"id":5720747}]}]}
{"op":"mcm","clk":"1005181620","pt":1580641341769,"mc":[{"id":"1.168135803","rc":[{"batb":[[1,2.16,150.72],[2,2.1,158.94]],"ltp":2.3,"tv":83.24,"id":5720747}]}]}
{"op":"mcm","clk":"1005183427","pt":1580641351767,"mc":[{"id":"1.168135803","rc":[{"batb":[[0,2.16,150.72],[1,2.1,158.94],[2,1.88,16.66]],"ltp":2.3,"tv":83.24,"id":5720747}]}]}
{"op":"mcm","clk":"1005186558","pt":1580641368787,"mc":[{"id":"1.168135803","rc":[{"batb":[[0,2.1,158.94],[1,1.88,16.66],[2,1.84,22.72]],"ltp":2.3,"tv":83.24,"id":5720747}]}]}
{"op":"mcm","clk":"1005187608","pt":1580641373802,"mc":[{"id":"1.168135803","rc":[{"batl":[[0,2.48,8.44],[1,2.8,48.69]],"ltp":2.3,"tv":83.24,"id":5720747}]}]}
{"op":"mcm","clk":"1005188755","pt":1580641379812,"mc":[{"id":"1.168135803","rc":[{"batb":[[0,1.88,16.66],[1,1.84,22.72],[2,1.82,198.4]],"ltp":2.3,"tv":83.24,"id":5720747}]}]}
{"op":"mcm","clk":"1005189150","pt":1580641381785,"mc":[{"id":"1.168135803","rc":[{"batb":[[0,2.04,168.11],[1,1.88,16.66],[2,1.84,22.72]],"ltp":2.3,"tv":83.24,"id":5720747}]}]}
{"op":"mcm","clk":"1005189526","pt":1580641383806,"mc":[{"id":"1.168135803","rc":[{"batl":[[0,2.18,9.75],[1,2.48,8.44],[2,2.8,48.69]],"ltp":2.3,"tv":83.24,"id":5720747}]}]}
{"op":"mcm","clk":"1005190244","pt":1580641387728,"mc":[{"id":"1.168135803","rc":[{"batb":[[0,1.68,257.1],[1,1.65,1.51],[2,1.6,291.97]],"ltp":1.64,"tv":39.61,"id":2249229}]}]}
{"op":"mcm","clk":"1005190596","pt":1580641389438,"mc":[{"id":"1.168135803","rc":[{"batl":[[0,1.92,839.35]],"ltp":1.64,"tv":39.61,"id":2249229}]}]}
{"op":"mcm","clk":"1005191072","pt":1580641391799,"mc":[{"id":"1.168135803","rc":[{"batb":[[2,1.46,816.38]],"ltp":1.64,"tv":39.61,"id":2249229}]}]}
{"op":"mcm","clk":"1005191658","pt":1580641394731,"mc":[{"id":"1.168135803","rc":[{"batb":[[0,1.88,16.66],[1,1.84,22.72],[2,1.82,198.4]],"ltp":2.3,"tv":83.24,"id":5720747}]}]}
{"op":"mcm","clk":"1005191955","pt":1580641395812,"mc":[{"id":"1.168135803","rc":[{"batb":[[0,2.1,158.94],[1,1.88,16.66],[2,1.84,22.72]],"ltp":2.3,"tv":83.24,"id":5720747}]}]}
{"op":"mcm","clk":"1005192573","pt":1580641398742,"mc":[{"id":"1.168135803","rc":[{"batl":[[0,2.48,8.44],[1,2.8,48.69],[2,2.8,0]],"ltp":2.3,"tv":83.24,"id":5720747}]}]}
{"op":"mcm","clk":"1005192786","pt":1580641399810,"mc":[{"id":"1.168135803","rc":[{"batb":[[1,2,174.83],[2,1.88,16.66]],"ltp":2.3,"tv":83.24,"id":5720747}]}]}
{"op":"mcm","clk":"1005193119","pt":1580641401720,"mc":[{"id":"1.168135803","rc":[{"trd":[[2.1,19.51]],"batb":[[0,2.1,149.18]],"ltp":2.1,"tv":102.74,"id":5720747}],"tv":142.36}]}
{"op":"mcm","clk":"1005194530","pt":1580641408744,"mc":[{"id":"1.168135803","rc":[{"batb":[[0,1.8,11.38],[1,1.68,257.1],[2,1.65,1.51]],"ltp":1.64,"tv":39.61,"id":2249229}]}]}
{"op":"mcm","clk":"1005196502","pt":1580641417764,"mc":[{"id":"1.168135803","rc":[{"batl":[[0,1.9,839.35]],"ltp":1.64,"tv":39.61,"id":2249229}]}]}
{"op":"mcm","clk":"1005207389","pt":1580641470817,"mc":[{"id":"1.168135803","rc":[{"trd":[[2.1,25.36]],"batb":[[0,2.1,146.26]],"ltp":2.1,"tv":108.59,"id":5720747}],"tv":148.21}]}
{"op":"mcm","clk":"1005210346","pt":1580641485736,"mc":[{"id":"1.168135803","rc":[{"batb":[[0,1.68,257.1],[1,1.65,1.51],[2,1.5,820.89]],"ltp":1.64,"tv":39.61,"id":2249229}]}]}
{"op":"mcm","clk":"1005211243","pt":1580641490664,"mc":[{"id":"1.168135803","rc":[{"batb":[[0,1.8,14.79],[1,1.68,257.1],[2,1.65,1.51]],"ltp":1.64,"tv":39.61,"id":2249229}]}]}
{"op":"mcm","clk":"1005221222","pt":1580641539632,"mc":[{"id":"1.168135803","rc":[{"trd":[[1.8,8]],"batb":[[0,1.8,10.79]],"ltp":1.8,"tv":47.61,"id":2249229}],"tv":156.21}]}
{"op":"mcm","clk":"1005223476","pt":1580641549815,"mc":[{"id":"1.168135803","rc":[{"trd":[[2.1,65.36]],"batb":[[0,2.1,126.26]],"ltp":2.1,"tv":148.59,"id":5720747}],"tv":196.21}]}
{"op":"mcm","clk":"1005224276","pt":1580641553756,"mc":[{"id":"1.168135803","rc":[{"batb":[[0,1.68,257.1],[1,1.65,1.51],[2,1.5,820.89]],"ltp":1.8,"tv":47.61,"id":2249229}]}]}
{"op":"mcm","clk":"1005224907","pt":1580641556730,"mc":[{"id":"1.168135803","rc":[{"batb":[[0,2.12,378.62],[1,2.1,126.26],[2,2,174.83]],"ltp":2.1,"tv":148.59,"id":5720747}]}]}
{"op":"mcm","clk":"1005225107","pt":1580641557648,"mc":[{"id":"1.168135803","rc":[{"batb":[[0,1.8,34.13],[1,1.68,257.1],[2,1.65,1.51]],"ltp":1.8,"tv":47.61,"id":2249229}]}]}
{"op":"mcm","clk":"1005225327","pt":1580641558633,"mc":[{"id":"1.168135803","rc":[{"batl":[[0,1.89,500],[1,1.9,839.35]],"ltp":1.8,"tv":47.61,"id":2249229}]}]}
{"op":"mcm","clk":"1005225600","pt":1580641559758,"mc":[{"id":"1.168135803","rc":[{"trd":[[1.89,61.19]],"batl":[[0,1.89,441.66]],"ltp":1.89,"tv":105.95,"id":2249229},{"trd":[[2.12,842.08]],"batb":[[0,2.1,126.26],[1,2,174.83],[2,1.88,16.66]],"ltp":2.12,"tv":957.85,"id":5720747}],"tv":1063.81}]}
{"op":"mcm","clk":"1005229983","pt":1580641579789,"mc":[{"id":"1.168135803","rc":[{"batb":[[0,2.2,50],[1,2.1,126.26],[2,2,174.83]],"ltp":2.12,"tv":957.85,"id":5720747}]}]}
{"op":"mcm","clk":"1005235247","pt":1580641605712,"mc":[{"id":"1.168135803","rc":[{"batb":[[1,2.14,153.36],[2,2.1,126.26]],"ltp":2.12,"tv":957.85,"id":5720747}]}]}
{"op":"mcm","clk":"1005237065","pt":1580641614816,"mc":[{"id":"1.168135803","rc":[{"trd":[[2.2,0.32]],"batb":[[0,2.2,49.84]],"ltp":2.2,"tv":958.17,"id":5720747}],"tv":1064.13}]}
{"op":"mcm","clk":"1005237470","pt":1580641616638,"mc":[{"id":"1.168135803","rc":[{"trd":[[1.8,76.25]],"batb":[[0,1.68,257.1],[1,1.65,1.51],[2,1.46,839.99]],"batl":[[0,1.8,8.29],[1,1.89,441.66],[2,1.9,839.35]],"ltp":1.8,"tv":174.2,"id":2249229}],"tv":1132.37}]}
{"op":"mcm","clk":"1005238935","pt":1580641623631,"mc":[{"id":"1.168135803","rc":[{"batl":[[0,1.89,441.66],[1,1.9,839.35],[2,1.9,0]],"ltp":1.8,"tv":174.2,"id":2249229}]}]}
{"op":"mcm","clk":"1005239157","pt":1580641624748,"mc":[{"id":"1.168135803","rc":[{"trd":[[2.48,0.79]],"batl":[[0,2.48,8.05]],"ltp":2.48,"tv":958.95,"id":5720747}],"tv":1133.16}]}
{"op":"mcm","clk":"1005243660","pt":1580641646754,"mc":[{"id":"1.168135803","rc":[{"batb":[[0,1.8,30.29],[1,1.68,257.1],[2,1.65,1.51]],"ltp":1.8,"tv":174.2,"id":2249229}]}]}
{"op":"mcm","clk":"1005244005","pt":1580641648765,"mc":[{"id":"1.168135803","rc":[{"batl":[[2,1000,2.36]],"ltp":2.48,"tv":958.95,"id":5720747}]}]}
{"op":"mcm","clk":"1005244588","pt":1580641651670,"mc":[{"id":"1.168135803","rc":[{"batl":[[2,1000,0]],"ltp":2.48,"tv":958.95,"id":5720747}]}]}
{"op":"mcm","clk":"1005245018","pt":1580641653749,"mc":[{"id":"1.168135803","rc":[{"batb":[[0,2.14,153.36],[1,2.1,126.26],[2,2,174.83]],"ltp":2.48,"tv":958.95,"id":5720747}]}]}
{"op":"mcm","clk":"1005245226","pt":1580641654762,"mc":[{"id":"1.168135803","rc":[{"batl":[[2,3.2,0.31]],"ltp":2.48,"tv":958.95,"id":5720747}]}]}
{"op":"mcm","clk":"1005245617","pt":1580641656791,"mc":[{"id":"1.168135803","rc":[{"batb":[[0,2.24,49.84],[1,2.14,153.36],[2,2.1,126.26]],"ltp":2.48,"tv":958.95,"id":5720747}]}]}
{"op":"mcm","clk":"1005246477","pt":1580641660794,"mc":[{"id":"1.168135803","rc":[{"batb":[[0,1.8,46.19]],"ltp":1.8,"tv":174.2,"id":2249229}]}]}
{"op":"mcm","clk":"1005247685","pt":1580641666586,"mc":[{"id":"1.168135803","rc":[{"trd":[[1.8,168.63]],"batb":[[0,1.68,257.1],[1,1.65,1.51],[2,1.5,804.74]],"batl":[[0,1.8,420.11],[1,1.89,441.66],[2,1.9,839.35]],"ltp":1.8,"tv":266.58,"id":2249229}],"tv":1225.54}]}
{"op":"mcm","clk":"1005249902","pt":1580641677813,"mc":[{"id":"1.168135803","rc":[{"batb":[[2,1.42,17.26]],"ltp":1.8,"tv":266.58,"id":2249229}]}]}
{"op":"mcm","clk":"1005251276","pt":1580641684809,"mc":[{"id":"1.168135803","rc":[{"batb":[[2,1.5,810.89]],"ltp":1.8,"tv":266.58,"id":2249229}]}]}
{"op":"mcm","clk":"1005251958","pt":1580641688507,"mc":[{"id":"1.168135803","rc":[{"batl":[[1,3.2,0.31],[2,3.2,0]],"ltp":2.48,"tv":958.95,"id":5720747}]}]}
{"op":"mcm","clk":"1005252761","pt":1580641692714,"mc":[{"id":"1.168135803","rc":[{"batb":[[2,1.42,17.26]],"ltp":1.8,"tv":266.58,"id":2249229}]}]}
{"op":"mcm","clk":"1005253729","pt":1580641697742,"mc":[{"id":"1.168135803","rc":[{"batl":[[0,2.38,10],[1,2.48,8.05],[2,3.2,0.31]],"ltp":2.48,"tv":958.95,"id":5720747}]}]}
{"op":"mcm","clk":"1005255111","pt":1580641704747,"mc":[{"id":"1.168135803","rc":[{"batb":[[2,1.46,822.44]],"ltp":1.8,"tv":266.58,"id":2249229}]}]}
{"op":"mcm","clk":"1005256742","pt":1580641712664,"mc":[{"id":"1.168135803","rc":[{"trd":[[1.72,13.84]],"batl":[[0,1.72,172.69],[1,1.8,420.11],[2,1.89,441.66]],"ltp":1.72,"tv":280.42,"id":2249229},{"trd":[[2.38,10]],"batl":[[0,2.48,8.05],[1,3.2,0.31],[2,3.2,0]],"ltp":2.38,"tv":968.95,"id":5720747}],"tv":1249.38}]}
{"op":"mcm","clk":"1005257846","pt":1580641717757,"mc":[{"id":"1.168135803","rc":[{"trd":[[1.68,373.06]],"batb":[[0,1.68,70.57]],"ltp":1.68,"tv":653.48,"id":2249229}],"tv":1622.44}]}
{"op":"mcm","clk":"1005258973","pt":1580641723794,"mc":[{"id":"1.168135803","rc":[{"batb":[[2,1.42,17.26]],"ltp":1.68,"tv":653.48,"id":2249229}]}]}
{"op":"mcm","clk":"1005259154","pt":1580641724699,"mc":[{"id":"1.168135803","rc":[{"batb":[[1,1.65,1.14]],"ltp":1.68,"tv":653.48,"id":2249229}]}]}
{"op":"mcm","clk":"1005259363","pt":1580641725779,"mc":[{"id":"1.168135803","rc":[{"batl":[[0,1.8,420.11],[1,1.89,441.66],[2,1.9,839.35]],"ltp":1.68,"tv":653.48,"id":2249229}]}]}
{"op":"mcm","clk":"1005259727","pt":1580641727799,"mc":[{"id":"1.168135803","rc":[{"batb":[[1,1.42,17.26],[2,1.39,16.66]],"ltp":1.68,"tv":653.48,"id":2249229}]}]}
{"op":"mcm","clk":"1005260444","pt":1580641731681,"mc":[{"id":"1.168135803","rc":[{"batb":[[0,1.69,1.14],[1,1.68,70.57],[2,1.42,17.26]],"ltp":1.68,"tv":653.48,"id":2249229}]}]}
{"op":"mcm","clk":"1005262005","pt":1580641739785,"mc":[{"id":"1.168135803","rc":[{"batb":[[0,2.3,136.25],[1,2.24,49.84],[2,2.14,153.36]],"ltp":2.38,"tv":968.95,"id":5720747}]}]}
{"op":"mcm","clk":"1005262353","pt":1580641741603,"mc":[{"id":"1.168135803","rc":[{"batb":[[0,1.72,242.82],[1,1.69,1.14],[2,1.68,70.57]],"ltp":1.68,"tv":653.48,"id":2249229}]}]}
{"op":"mcm","clk":"1005262882","pt":1580641744322,"mc":[{"id":"1.168135803","rc":[{"batb":[[0,1.69,1.14],[1,1.68,70.57],[2,1.5,804.74]],"ltp":1.68,"tv":653.48,"id":2249229}]}]}
{"op":"mcm","clk":"1005263757","pt":1580641748801,"mc":[{"id":"1.168135803","rc":[{"batb":[[0,1.7,249.76],[1,1.69,1.14],[2,1.68,70.57]],"ltp":1.68,"tv":653.48,"id":2249229}]}]}
{"op":"mcm","clk":"1005264668","pt":1580641753430,"mc":[{"id":"1.168135803","rc":[{"batb":[[1,1.68,70.57],[2,1.5,804.74]],"ltp":1.68,"tv":653.48,"id":2249229}]}]}
{"op":"mcm","clk":"1005265345","pt":1580641756813,"mc":[{"id":"1.168135803","rc":[{"batb":[[0,1.71,1.14],[1,1.7,249.76],[2,1.68,70.57]],"ltp":1.68,"tv":653.48,"id":2249229}]}]}
{"op":"mcm","clk":"1005266883","pt":1580641764813,"mc":[{"id":"1.168135803","rc":[{"trd":[[1.7,499.5],[1.71,2.27]],"batb":[[0,1.68,70.57],[1,1.42,17.26],[2,1.39,16.66]],"batl":[[0,1.7,28.91],[1,1.8,420.11],[2,1.89,441.66]],"ltp":1.7,"tv":1155.25,"id":2249229}],"tv":2124.21}]}
{"op":"mcm","clk":"1005267068","pt":1580641765721,"mc":[{"id":"1.168135803","rc":[{"batl":[[0,1.8,420.11],[1,1.89,441.66],[2,1.9,839.35]],"ltp":1.7,"tv":1155.25,"id":2249229}]}]}
{"op":"mcm","clk":"1005267914","pt":1580641769652,"mc":[{"id":"1.168135803","rc":[{"batb":[[0,2.24,49.84],[1,2.14,153.36],[2,2.1,126.26]],"ltp":2.38,"tv":968.95,"id":5720747}]}]}
{"op":"mcm","clk":"1005268710","pt":1580641773737,"mc":[{"id":"1.168135803","rc":[{"batb":[[0,2.4,307.49],[1,2.24,49.84],[2,2.14,153.36]],"ltp":2.38,"tv":968.95,"id":5720747}]}]}
{"op":"mcm","clk":"1005268878","pt":1580641774699,"mc":[{"id":"1.168135803","rc":[{"batb":[[1,1.46,822.44],[2,1.42,16.66]],"ltp":1.7,"tv":1155.25,"id":2249229}]}]}
{"op":"mcm","clk":"1005270689","pt":1580641783799,"mc":[{"id":"1.168135803","rc":[{"batb":[[0,1.46,822.44],[1,1.42,16.66],[2,1.39,16.66]],"ltp":1.7,"tv":1155.25,"id":2249229}]}]}
{"op":"mcm","clk":"1005271241","pt":1580641786666,"mc":[{"id":"1.168135803","rc":[{"batb":[[0,1.6,291.97],[1,1.46,821.86],[2,1.42,16.66]],"ltp":1.7,"tv":1155.25,"id":2249229}]}]}
{"op":"mcm","clk":"1005272564","pt":1580641793753,"mc":[{"id":"1.168135803","rc":[{"batb":[[1,1.42,16.67],[2,1.39,16.66]],"ltp":1.7,"tv":1155.25,"id":2249229}]}]}
{"op":"mcm","clk":"1005275912","pt":1580641811803,"mc":[{"id":"1.168135803","rc":[{"batb":[[1,1.46,802.83],[2,1.42,16.66]],"ltp":1.7,"tv":1155.25,"id":2249229}]}]}
{"op":"mcm","clk":"1005277530","pt":1580641820426,"mc":[{"id":"1.168135803","rc":[{"batb":[[2,1.39,16.66]],"ltp":1.7,"tv":1155.25,"id":2249229}]}]}
{"op":"mcm","clk":"1005278082","pt":1580641823508,"mc":[{"id":"1.168135803","rc":[{"batb":[[1,1.47,16.67],[2,1.46,802.81]],"ltp":1.7,"tv":1155.25,"id":2249229}]}]}
{"op":"mcm","clk":"1005280305","pt":1580641835745,"mc":[{"id":"1.168135803","rc":[{"batb":[[2,1.39,16.66]],"ltp":1.7,"tv":1155.25,"id":2249229},{"batb":[[2,2.14,573.46]],"ltp":2.38,"tv":968.95,"id":5720747}]}]}
{"op":"mcm","clk":"1005281472","pt":1580641841751,"mc":[{"id":"1.168135803","rc":[{"batb":[[2,1.46,809.17]],"ltp":1.7,"tv":1155.25,"id":2249229}]}]}
{"op":"mcm","clk":"1005282018","pt":1580641844768,"mc":[{"id":"1.168135803","rc":[{"batb":[[2,1.39,16.66]],"ltp":1.7,"tv":1155.25,"id":2249229}]}]}
{"op":"mcm","clk":"1005283592","pt":1580641852755,"mc":[{"id":"1.168135803","rc":[{"trd":[[1.72,19.3]],"batb":[[2,1.46,821.85]],"ltp":1.72,"tv":1160.71,"id":2249229},{"trd":[[2.4,3.91]],"batb":[[0,2.4,303.57]],"ltp":2.4,"tv":972.87,"id":5720747}],"tv":2133.58}]}
{"op":"mcm","clk":"1005284678","pt":1580641858802,"mc":[{"id":"1.168135803","rc":[{"batb":[[2,2.14,153.36]],"ltp":2.4,"tv":972.87,"id":5720747}]}]}
{"op":"mcm","clk":"1005286745","pt":1580641869776,"mc":[{"id":"1.168135803","rc":[{"batb":[[2,1.39,16.66]],"ltp":1.72,"tv":1160.71,"id":2249229}]}]}
{"op":"mcm","clk":"1005287116","pt":1580641871803,"mc":[{"id":"1.168135803","rc":[{"trd":[[2.4,8.96]],"batb":[[0,2.4,301.05]],"ltp":2.4,"tv":977.91,"id":5720747}],"tv":2138.62}]}
{"op":"mcm","clk":"1005288261","pt":1580641877713,"mc":[{"id":"1.168135803","rc":[{"batb":[[2,1.44,779.16]],"ltp":1.72,"tv":1160.71,"id":2249229}]}]}
{"op":"mcm","clk":"1005291724","pt":1580641895818,"mc":[{"id":"1.168135803","rc":[{"batb":[[2,1.39,16.66]],"ltp":1.72,"tv":1160.71,"id":2249229}]}]}
{"op":"mcm","clk":"1005292737","pt":1580641901553,"mc":[{"id":"1.168135803","rc":[{"batb":[[2,1.44,785.57]],"ltp":1.72,"tv":1160.71,"id":2249229}]}]}
{"op":"mcm","clk":"1005293762","pt":1580641906638,"mc":[{"id":"1.168135803","rc":[{"batb":[[2,1.39,16.66]],"ltp":1.72,"tv":1160.71,"id":2249229}]}]}
{"op":"mcm","clk":"1005294105","pt":1580641908343,"mc":[{"id":"1.168135803","rc":[{"batb":[[0,1.68,257.1],[1,1.6,291.97],[2,1.47,16.67]],"ltp":1.72,"tv":1160.71,"id":2249229}]}]}
{"op":"mcm","clk":"1005294443","pt":1580641909819,"mc":[{"id":"1.168135803","rc":[{"batb":[[0,1.6,291.97],[1,1.47,16.67],[2,1.39,16.66]],"ltp":1.72,"tv":1160.71,"id":2249229}]}]}
{"op":"mcm","clk":"1005295017","pt":1580641912745,"mc":[{"id":"1.168135803","rc":[{"batb":[[2,1.44,807.09]],"ltp":1.72,"tv":1160.71,"id":2249229}]}]}
{"op":"mcm","clk":"1005297949","pt":1580641928677,"mc":[{"id":"1.168135803","rc":[{"batb":[[2,1.39,16.66]],"ltp":1.72,"tv":1160.71,"id":2249229}]}]}
{"op":"mcm","clk":"1005299386","pt":1580641936754,"mc":[{"id":"1.168135803","rc":[{"batb":[[2,1.44,816.43]],"ltp":1.72,"tv":1160.71,"id":2249229}]}]}
{"op":"mcm","clk":"1005300125","pt":1580641940781,"mc":[{"id":"1.168135803","rc":[{"batb":[[2,1.39,16.66]],"ltp":1.72,"tv":1160.71,"id":2249229}]}]}
{"op":"mcm","clk":"1005301012","pt":1580641946784,"mc":[{"id":"1.168135803","rc":[{"batb":[[0,2.24,49.84],[1,1.88,16.66],[2,1.5,35.02]],"ltp":2.4,"tv":977.91,"id":5720747}]}]}
{"op":"mcm","clk":"1005301641","pt":1580641950795,"mc":[{"id":"1.168135803","rc":[{"trd":[[2.48,16.89]],"batb":[[0,2.48,283.29],[1,2.24,49.84],[2,1.88,16.66]],"batl":[[0,3.2,0.31],[1,3.2,0]],"ltp":2.48,"tv":994.01,"id":5720747}],"tv":2154.73}]}
{"op":"mcm","clk":"1005301781","pt":1580641951802,"mc":[{"id":"1.168135803","rc":[{"batb":[[2,1.44,841.28]],"ltp":1.72,"tv":1160.71,"id":2249229},{"batb":[[1,2.26,138.75],[2,2.24,49.84]],"ltp":2.48,"tv":994.01,"id":5720747}]}]}
{"op":"mcm","clk":"1005302235","pt":1580641954300,"mc":[{"id":"1.168135803","rc":[{"batb":[[1,2.3,134.49],[2,2.26,138.75]],"ltp":2.48,"tv":994.01,"id":5720747}]}]}
{"op":"mcm","clk":"1005303525","pt":1580641961815,"mc":[{"id":"1.168135803","rc":[{"batb":[[0,1.47,17.26],[1,1.44,841.28],[2,1.39,16.66]],"ltp":1.72,"tv":1160.71,"id":2249229}]}]}
{"op":"mcm","clk":"1005304405","pt":1580641966734,"mc":[{"id":"1.168135803","rc":[{"batb":[[0,1.52,336.8],[1,1.47,16.67],[2,1.44,841.28]],"ltp":1.72,"tv":1160.71,"id":2249229}]}]}
{"op":"mcm","clk":"1005305408","pt":1580641972707,"mc":[{"id":"1.168135803","rc":[{"trd":[[1.68,519.98]],"batb":[[2,1.39,16.66]],"ltp":1.68,"tv":1307.63,"id":2249229},{"trd":[[2.48,116.42]],"batb":[[0,2.48,183.76]],"ltp":2.48,"tv":1093.54,"id":5720747}],"tv":2401.18}]}
{"op":"mcm","clk":"1005306262","pt":1580641977724,"mc":[{"id":"1.168135803","rc":[{"batb":[[2,1.44,857.07]],"ltp":1.68,"tv":1307.63,"id":2249229}]}]}
{"op":"mcm","clk":"1005307103","pt":1580641982813,"mc":[{"id":"1.168135803","rc":[{"batb":[[0,1.59,787.32],[1,1.52,336.21],[2,1.47,16.67]],"ltp":1.68,"tv":1307.63,"id":2249229}]}]}
{"op":"mcm","clk":"1005307591","pt":1580641985728,"mc":[{"id":"1.168135803","rc":[{"batb":[[0,2.3,134.49],[1,2.26,138.75],[2,2.24,49.84]],"ltp":2.48,"tv":1093.54,"id":5720747}]}]}
{"op":"mcm","clk":"1005308515","pt":1580641990636,"mc":[{"id":"1.168135803","rc":[{"batb":[[0,2.4,189.88]],"ltp":2.48,"tv":1093.54,"id":5720747}]}]}
{"op":"mcm","clk":"1005309081","pt":1580641993660,"mc":[{"id":"1.168135803","rc":[{"batb":[[0,1.68,4.44],[1,1.59,787.32],[2,1.52,336.21]],"ltp":1.68,"tv":1307.63,"id":2249229}]}]}
{"op":"mcm","clk":"1005312638","pt":1580642014370,"mc":[{"id":"1.168135803","rc":[{"batb":[[0,1.59,787.32],[1,1.52,336.21],[2,1.47,16.67]],"ltp":1.68,"tv":1307.63,"id":2249229}]}]}
{"op":"mcm","clk":"1005313682","pt":1580642020808,"mc":[{"id":"1.168135803","rc":[{"batb":[[2,1.88,16.66]],"ltp":2.48,"tv":1093.54,"id":5720747}]}]}
{"op":"mcm","clk":"1005313867","pt":1580642021809,"mc":[{"id":"1.168135803","rc":[{"trd":[[1.72,23.64]],"ltp":1.72,"tv":1311.97,"id":2249229},{"trd":[[2.4,12.07]],"batb":[[0,2.4,186.77]],"ltp":2.4,"tv":1096.65,"id":5720747}],"tv":2408.63}]}
{"op":"mcm","clk":"1005315066","pt":1580642028709,"mc":[{"id":"1.168135803","rc":[{"batb":[[2,2.14,420.1]],"ltp":2.4,"tv":1096.65,"id":5720747}]}]}
{"op":"mcm","clk":"1005315443","pt":1580642030789,"mc":[{"id":"1.168135803","rc":[{"batl":[[0,1.68,87.88],[1,1.8,420.11],[2,1.89,441.66]],"ltp":1.72,"tv":1311.97,"id":2249229}]}]}
{"op":"mcm","clk":"1005316271","pt":1580642035806,"mc":[{"id":"1.168135803","rc":[{"batl":[[0,1.8,420.11],[1,1.89,441.66],[2,1.9,839.35]],"ltp":1.72,"tv":1311.97,"id":2249229}]}]}
{"op":"mcm","clk":"1005317839","pt":1580642043814,"mc":[{"id":"1.168135803","rc":[{"batb":[[0,1.62,282.57],[1,1.59,786.74],[2,1.52,336.21]],"ltp":1.72,"tv":1311.97,"id":2249229}]}]}
{"op":"mcm","clk":"1005319951","pt":1580642054701,"mc":[{"id":"1.168135803","rc":[{"batb":[[1,2.14,420.1],[2,1.88,16.66]],"ltp":2.4,"tv":1096.65,"id":5720747}]}]}
{"op":"mcm","clk":"1005322603","pt":1580642069638,"mc":[{"id":"1.168135803","rc":[{"trd":[[2.4,163.52]],"batb":[[0,2.4,111.04]],"ltp":2.4,"tv":1248.11,"id":5720747}],"tv":2560.08}]}
{"op":"mcm","clk":"1005323314","pt":1580642073774,"mc":[{"id":"1.168135803","rc":[{"batb":[[1,1.52,336.21],[2,1.47,16.67]],"ltp":1.72,"tv":1311.97,"id":2249229}]}]}
{"op":"mcm","clk":"1005323880","pt":1580642076766,"mc":[{"id":"1.168135803","rc":[{"batb":[[0,1.63,787.32],[1,1.62,281.99],[2,1.52,336.21]],"ltp":1.72,"tv":1311.97,"id":2249229}]}]}
{"op":"mcm","clk":"1005324060","pt":1580642077760,"mc":[{"id":"1.168135803","rc":[{"batb":[[0,1.68,345.75],[1,1.67,263.99],[2,1.63,787.32]],"batl":[[0,1.74,265.69],[1,1.76,443.1],[2,1.8,420.11]],"ltp":1.72,"tv":1311.97,"id":2249229},{"batb":[[0,2.14,420.1],[1,1.88,16.66],[2,1.5,35.02]],"ltp":2.4,"tv":1248.11,"id":5720747}]}]}
{"op":"mcm","clk":"1005325103","pt":1580642083671,"mc":[{"id":"1.168135803","rc":[{"batb":[[0,2.4,111.04],[1,2.14,420.1],[2,1.88,16.66]],"ltp":2.4,"tv":1248.11,"id":5720747}]}]}
{"op":"mcm","clk":"1005325625","pt":1580642086753,"mc":[{"id":"1.168135803","rc":[{"batl":[[0,1.8,420.11],[1,1.89,441.66],[2,1.9,839.35]],"ltp":1.72,"tv":1311.97,"id":2249229}]}]}
{"op":"mcm","clk":"1005326159","pt":1580642089774,"mc":[{"id":"1.168135803","rc":[{"batl":[[0,1.75,449.9],[1,1.77,434.08],[2,1.8,420.11]],"ltp":1.72,"tv":1311.97,"id":2249229}]}]}
{"op":"mcm","clk":"1005326512","pt":1580642091747,"mc":[{"id":"1.168135803","rc":[{"trd":[[1.72,27.43]],"ltp":1.72,"tv":1315.76,"id":2249229},{"trd":[[2.4,166.23]],"batb":[[0,2.4,108.33]],"ltp":2.4,"tv":1250.82,"id":5720747}],"tv":2566.58}]}
{"op":"mcm","clk":"1005326865","pt":1580642093766,"mc":[{"id":"1.168135803","rc":[{"batb":[[0,1.68,413.21]],"ltp":1.72,"tv":1315.76,"id":2249229}]}]}
{"op":"mcm","clk":"1005327275","pt":1580642095751,"mc":[{"id":"1.168135803","rc":[{"batb":[[1,1.88,16.66],[2,1.5,35.02]],"ltp":2.4,"tv":1250.82,"id":5720747}]}]}
{"op":"mcm","clk":"1005327954","pt":1580642099788,"mc":[{"id":"1.168135803","rc":[{"trd":[[2.4,241.96]],"batb":[[0,2.4,70.47]],"ltp":2.4,"tv":1326.55,"id":5720747}],"tv":2642.31}]}
{"op":"mcm","clk":"1005328551","pt":1580642102806,"mc":[{"id":"1.168135803","rc":[{"batl":[[0,2.46,39.92],[1,3.2,0.31]],"ltp":2.4,"tv":1326.55,"id":5720747}]}]}
{"op":"mcm","clk":"1005328738","pt":1580642103787,"mc":[{"id":"1.168135803","rc":[{"batb":[[0,1.63,787.32],[1,1.52,336.21],[2,1.47,16.67]],"batl":[[0,1.8,420.11],[1,1.89,441.66],[2,1.9,839.35]],"ltp":1.72,"tv":1315.76,"id":2249229}]}]}
{"op":"mcm","clk":"1005330006","pt":1580642110780,"mc":[{"id":"1.168135803","rc":[{"batl":[[2,1.9,0]],"ltp":1.72,"tv":1315.76,"id":2249229}]}]}
{"op":"mcm","clk":"1005330898","pt":1580642115800,"mc":[{"id":"1.168135803","rc":[{"trd":[[1.68,578.43]],"batl":[[0,1.68,109.6],[1,1.8,420.11],[2,1.89,441.66]],"ltp":1.68,"tv":1374.2,"id":2249229},{"trd":[[2.46,39.92]],"batl":[[0,3.2,0.31],[1,3.2,0]],"ltp":2.46,"tv":1366.46,"id":5720747}],"tv":2740.67}]}
{"op":"mcm","clk":"1005331465","pt":1580642118794,"mc":[{"id":"1.168135803","rc":[{"trd":[[1.68,797.62]],"batb":[[0,1.68,225.96],[1,1.67,264.04],[2,1.63,787.32]],"batl":[[0,1.74,275.79],[1,1.76,443.18],[2,1.8,420.11]],"ltp":1.68,"tv":1593.4,"id":2249229},{"batb":[[1,2.26,279.78],[2,1.88,16.66]],"ltp":2.46,"tv":1366.46,"id":5720747}],"tv":2959.87}]}
{"op":"mcm","clk":"1005331643","pt":1580642119820,"mc":[{"id":"1.168135803","rc":[{"batb":[[0,1.63,787.32],[1,1.52,336.21],[2,1.47,16.67]],"batl":[[0,1.8,420.11],[1,1.89,441.66],[2,1.8,0]],"ltp":1.68,"tv":1593.4,"id":2249229}]}]}
{"op":"mcm","clk":"1005332168","pt":1580642122717,"mc":[{"id":"1.168135803","rc":[{"batb":[[0,1.64,273.76],[1,1.63,786.74],[2,1.52,336.21]],"ltp":1.68,"tv":1593.4,"id":2249229}]}]}
{"op":"mcm","clk":"1005333753","pt":1580642131734,"mc":[{"id":"1.168135803","rc":[{"batb":[[0,2.42,40],[1,2.4,70.47],[2,2.26,279.78]],"ltp":2.46,"tv":1366.46,"id":5720747}]}]}
{"op":"mcm","clk":"1005334474","pt":1580642135737,"mc":[{"id":"1.168135803","rc":[{"batl":[[0,1.67,87.88],[1,1.8,420.11],[2,1.89,441.66]],"ltp":1.68,"tv":1593.4,"id":2249229}]}]}
{"op":"mcm","clk":"1005334835","pt":1580642137714,"mc":[{"id":"1.168135803","rc":[{"batl":[[1,1.68,25.21],[2,1.8,420.11]],"ltp":1.68,"tv":1593.4,"id":2249229}]}]}
{"op":"mcm","clk":"1005336907","pt":1580642149730,"mc":[{"id":"1.168135803","rc":[{"batb":[[0,1.63,787.32],[1,1.47,16.67],[2,1.39,16.66]],"ltp":1.68,"tv":1593.4,"id":2249229}]}]}
{"op":"mcm","clk":"1005337089","pt":1580642150752,"mc":[{"id":"1.168135803","rc":[{"batb":[[0,1.47,17.26],[1,1.39,16.66],[2,1.34,27.28]],"ltp":1.68,"tv":1593.4,"id":2249229}]}]}
{"op":"mcm","clk":"1005337458","pt":1580642152731,"mc":[{"id":"1.168135803","rc":[{"trd":[[1.67,75.26]],"batl":[[0,1.67,12.61]],"ltp":1.67,"tv":1668.66,"id":2249229},{"trd":[[2.48,167.07]],"ltp":2.48,"tv":1417.11,"id":5720747}],"tv":3085.78}]}
{"op":"mcm","clk":"1005337821","pt":1580642154752,"mc":[{"id":"1.168135803","rc":[{"trd":[[1.67,87.88]],"batl":[[0,1.68,25.21],[1,1.8,420.11],[2,1.89,441.66]],"ltp":1.67,"tv":1681.28,"id":2249229},{"trd":[[2.48,175.57]],"batl":[[0,2.48,11.5],[1,3.2,0.31]],"ltp":2.48,"tv":1425.61,"id":5720747}],"tv":3106.89}]}
{"op":"mcm","clk":"1005337983","pt":1580642155660,"mc":[{"id":"1.168135803","rc":[{"batl":[[0,1.8,420.11],[1,1.89,441.66],[2,1.89,0]],"ltp":1.67,"tv":1681.28,"id":2249229}]}]}
{"op":"mcm","clk":"1005339253","pt":1580642162763,"mc":[{"id":"1.168135803","rc":[{"trd":[[1.67,102.88]],"ltp":1.67,"tv":1696.28,"id":2249229},{"trd":[[2.48,185.67]],"batl":[[0,2.48,1.4]],"ltp":2.48,"tv":1435.71,"id":5720747}],"tv":3131.99}]}
{"op":"mcm","clk":"1005340299","pt":1580642168781,"mc":[{"id":"1.168135803","rc":[{"batb":[[2,1.88,16.66]],"ltp":2.48,"tv":1435.71,"id":5720747}]}]}
{"op":"mcm","clk":"1005340812","pt":1580642171810,"mc":[{"id":"1.168135803","rc":[{"batl":[[0,1.7,157.36],[1,1.8,420.11],[2,1.89,441.66]],"ltp":1.67,"tv":1696.28,"id":2249229},{"batb":[[0,2.44,279.78],[1,2.42,40],[2,2.4,70.47]],"ltp":2.48,"tv":1435.71,"id":5720747}]}]}
{"op":"mcm","clk":"1005341014","pt":1580642172771,"mc":[{"id":"1.168135803","rc":[{"trd":[[1.67,104.95]],"batl":[[0,1.67,14.73],[1,1.7,157.36],[2,1.8,420.11]],"ltp":1.67,"tv":1698.35,"id":2249229},{"trd":[[2.48,187.07]],"batl":[[0,3.2,0.31],[1,3.2,0]],"ltp":2.48,"tv":1437.11,"id":5720747}],"tv":3135.47}]}
{"op":"mcm","clk":"1005342774","pt":1580642181692,"mc":[{"id":"1.168135803","rc":[{"batb":[[0,1.5,284.23],[1,1.47,16.67],[2,1.39,16.66]],"ltp":1.67,"tv":1698.35,"id":2249229}]}]}
{"op":"mcm","clk":"1005343378","pt":1580642184706,"mc":[{"id":"1.168135803","rc":[{"batb":[[0,1.55,318.46],[1,1.5,283.64],[2,1.47,16.67]],"ltp":1.67,"tv":1698.35,"id":2249229}]}]}
{"op":"mcm","clk":"1005343585","pt":1580642185810,"mc":[{"id":"1.168135803","rc":[{"trd":[[1.55,18.84],[1.64,37.86]],"batb":[[0,1.55,308.45]],"ltp":1.55,"tv":1718.35,"id":2249229}],"tv":3155.47}]}
{"op":"mcm","clk":"1005344145","pt":1580642188786,"mc":[{"id":"1.168135803","rc":[{"batl":[[1,1.8,420.11],[2,1.89,441.66]],"ltp":1.55,"tv":1718.35,"id":2249229}]}]}
{"op":"mcm","clk":"1005345060","pt":1580642193802,"mc":[{"id":"1.168135803","rc":[{"trd":[[1.55,38.84]],"batb":[[0,1.55,298.45]],"ltp":1.55,"tv":1738.35,"id":2249229}],"tv":3175.47}]}
{"op":"mcm","clk":"1005346838","pt":1580642203799,"mc":[{"id":"1.168135803","rc":[{"trd":[[1.55,78.84]],"batb":[[0,1.55,278.45]],"ltp":1.55,"tv":1778.36,"id":2249229}],"tv":3215.47}]}
{"op":"mcm","clk":"1005347437","pt":1580642206818,"mc":[{"id":"1.168135803","rc":[{"batb":[[2,1.39,16.67]],"ltp":1.55,"tv":1778.36,"id":2249229},{"batb":[[2,1.88,16.66]],"ltp":2.48,"tv":1437.11,"id":5720747}]}]}
{"op":"mcm","clk":"1005347792","pt":1580642208706,"mc":[{"id":"1.168135803","rc":[{"batb":[[1,1.39,16.67],[2,1.34,27.28]],"ltp":1.55,"tv":1778.36,"id":2249229}]}]}
{"op":"mcm","clk":"1005348148","pt":1580642210782,"mc":[{"id":"1.168135803","rc":[{"batl":[[0,1.67,14.96]],"ltp":1.55,"tv":1778.36,"id":2249229}]}]}
{"op":"mcm","clk":"1005348320","pt":1580642211723,"mc":[{"id":"1.168135803","rc":[{"batb":[[0,1.56,283.64],[1,1.55,278.45],[2,1.39,16.67]],"ltp":1.55,"tv":1778.36,"id":2249229},{"batb":[[0,2.46,93.59],[1,2.44,279.78],[2,2.42,40]],"ltp":2.48,"tv":1437.11,"id":5720747}]}]}
{"op":"mcm","clk":"1005348800","pt":1580642214731,"mc":[{"id":"1.168135803","rc":[{"trd":[[1.56,39.98]],"batb":[[0,1.56,263.66]],"ltp":1.56,"tv":1818.34,"id":2249229}],"tv":3255.45}]}
{"op":"mcm","clk":"1005349489","pt":1580642218732,"mc":[{"id":"1.168135803","rc":[{"trd":[[1.65,0.45],[1.67,134.41]],"batb":[[0,1.67,48.06],[1,1.56,263.66],[2,1.55,278.45]],"batl":[[0,1.8,420.11],[1,1.89,441.66],[2,1.89,0]],"ltp":1.67,"tv":1848.25,"id":2249229}],"tv":3285.37}]}
{"op":"mcm","clk":"1005350384","pt":1580642223756,"mc":[{"id":"1.168135803","rc":[{"batb":[[0,1.56,263.66],[1,1.55,278.45],[2,1.39,16.67]],"ltp":1.67,"tv":1848.25,"id":2249229}]}]}
{"op":"mcm","clk":"1005350543","pt":1580642224656,"mc":[{"id":"1.168135803","rc":[{"trd":[[2.44,316.96],[2.46,227.08]],"batb":[[0,2.44,121.31],[1,2.42,40],[2,1.88,16.66]],"ltp":2.44,"tv":1941.24,"id":5720747}],"tv":3789.49}]}
{"op":"mcm","clk":"1005350964","pt":1580642226731,"mc":[{"id":"1.168135803","rc":[{"trd":[[1.7,547.56]],"ltp":1.7,"tv":1896.31,"id":2249229},{"trd":[[2.44,350.44]],"batb":[[0,2.44,87.83]],"ltp":2.44,"tv":1974.72,"id":5720747}],"tv":3871.03}]}
{"op":"mcm","clk":"1005351124","pt":1580642227758,"mc":[{"id":"1.168135803","rc":[{"batl":[[0,1.67,20],[1,1.8,420.11],[2,1.89,441.66]],"ltp":1.7,"tv":1896.31,"id":2249229},{"batb":[[2,1.5,35.02]],"ltp":2.44,"tv":1974.72,"id":5720747}]}]}
{"op":"mcm","clk":"1005351662","pt":1580642230769,"mc":[{"id":"1.168135803","rc":[{"batb":[[2,1.5,27.45]],"ltp":2.44,"tv":1974.72,"id":5720747}]}]}
{"op":"mcm","clk":"1005352823","pt":1580642236778,"mc":[{"id":"1.168135803","rc":[{"trd":[[1.67,174.41]],"batb":[[0,1.67,26.21],[1,1.56,263.66],[2,1.55,278.45]],"batl":[[0,1.69,17.73]],"ltp":1.67,"tv":1936.3,"id":2249229}],"tv":3911.03}]}
{"op":"mcm","clk":"1005353341","pt":1580642239740,"mc":[{"id":"1.168135803","rc":[{"batb":[[1,1.5,27.45],[2,1.25,45.45]],"ltp":2.44,"tv":1974.72,"id":5720747}]}]}
{"op":"mcm","clk":"1005353489","pt":1580642240757,"mc":[{"id":"1.168135803","rc":[{"batb":[[2,1.39,16.67]],"ltp":1.67,"tv":1936.3,"id":2249229}]}]}
{"op":"mcm","clk":"1005353854","pt":1580642242781,"mc":[{"id":"1.168135803","rc":[{"trd":[[1.67,200.62]],"batb":[[0,1.58,301.43]],"ltp":1.67,"tv":1962.52,"id":2249229},{"trd":[[2.5,17.51]],"batb":[[0,2.5,22.49],[1,2.44,87.83],[2,1.5,27.45]],"ltp":2.5,"tv":1992.23,"id":5720747}],"tv":3954.75}]}
{"op":"mcm","clk":"1005354659","pt":1580642246766,"mc":[{"id":"1.168135803","rc":[{"batl":[[0,1.8,420.11],[1,1.89,441.66],[2,1.89,0]],"ltp":1.67,"tv":1962.52,"id":2249229},{"batb":[[2,2.3,134.49]],"ltp":2.5,"tv":1992.23,"id":5720747}]}]}
{"op":"mcm","clk":"1005355186","pt":1580642249646,"mc":[{"id":"1.168135803","rc":[{"batl":[[0,1.67,17.73],[1,1.8,420.11],[2,1.89,441.66]],"ltp":1.67,"tv":1962.52,"id":2249229}]}]}
{"op":"mcm","clk":"1005356312","pt":1580642255762,"mc":[{"id":"1.168135803","rc":[{"trd":[[1.67,205.66]],"batl":[[0,1.67,15.21]],"ltp":1.67,"tv":1967.56,"id":2249229}],"tv":3959.79}]}
{"op":"mcm","clk":"1005356804","pt":1580642258586,"mc":[{"id":"1.168135803","rc":[{"trd":[[2.5,19.85]],"batb":[[0,2.5,21.32]],"ltp":2.5,"tv":1994.57,"id":5720747}],"tv":3962.13}]}
{"op":"mcm","clk":"1005357449","pt":1580642261773,"mc":[{"id":"1.168135803","rc":[{"trd":[[2.5,62.49]],"batb":[[0,2.44,87.83],[1,2.3,134.49],[2,1.5,27.45]],"batl":[[0,2.5,765.42],[1,3.2,0.31]],"ltp":2.5,"tv":2037.21,"id":5720747}],"tv":4004.77}]}
{"op":"mcm","clk":"1005357625","pt":1580642262783,"mc":[{"id":"1.168135803","rc":[{"trd":[[1.67,279.56]],"batl":[[0,1.67,50.2]],"ltp":1.67,"tv":2041.46,"id":2249229},{"batl":[[1,2.6,25.33],[2,3.2,0.31]],"ltp":2.5,"tv":2037.21,"id":5720747}],"tv":4078.68}]}
{"op":"mcm","clk":"1005357963","pt":1580642264600,"mc":[{"id":"1.168135803","rc":[{"trd":[[1.67,292.03]],"batl":[[0,1.67,37.73]],"ltp":1.67,"tv":2053.92,"id":2249229},{"trd":[[2.48,195.47]],"ltp":2.48,"tv":2045.61,"id":5720747}],"tv":4099.54}]}
{"op":"mcm","clk":"1005359365","pt":1580642271798,"mc":[{"id":"1.168135803","rc":[{"batl":[[2,1.89,0]],"ltp":1.67,"tv":2053.92,"id":2249229}]}]}
{"op":"mcm","clk":"1005359536","pt":1580642272713,"mc":[{"id":"1.168135803","rc":[{"trd":[[1.66,450]],"ltp":1.66,"tv":2503.92,"id":2249229},{"trd":[[2.5,361.31]],"batl":[[0,2.5,466.6]],"ltp":2.5,"tv":2344.43,"id":5720747}],"tv":4848.36}]}
{"op":"mcm","clk":"1005359731","pt":1580642273755,"mc":[{"id":"1.168135803","rc":[{"batl":[[0,1.8,420.11],[1,1.8,0]],"ltp":1.66,"tv":2503.92,"id":2249229}]}]}
{"op":"mcm","clk":"1005360305","pt":1580642276705,"mc":[{"id":"1.168135803","rc":[{"trd":[[1.66,487.73]],"ltp":1.66,"tv":2541.66,"id":2249229},{"trd":[[2.5,386.4]],"batl":[[0,2.5,441.52]],"ltp":2.5,"tv":2369.51,"id":5720747}],"tv":4911.18}]}
{"op":"mcm","clk":"1005360484","pt":1580642277603,"mc":[{"id":"1.168135803","rc":[{"batl":[[0,2.5,446.52]],"ltp":2.5,"tv":2369.51,"id":5720747}]}]}
{"op":"mcm","clk":"1005360889","pt":1580642279713,"mc":[{"id":"1.168135803","rc":[{"batb":[[0,1.67,36.97],[1,1.58,301.43],[2,1.56,263.66]],"ltp":1.66,"tv":2541.66,"id":2249229},{"batl":[[0,2.48,10],[1,2.5,446.52],[2,2.6,25.33]],"ltp":2.5,"tv":2369.51,"id":5720747}]}]}
{"op":"mcm","clk":"1005362187","pt":1580642286545,"mc":[{"id":"1.168135803","rc":[{"batl":[[0,2.5,446.52],[1,2.6,25.33],[2,3.2,0.31]],"ltp":2.5,"tv":2369.51,"id":5720747}]}]}
{"op":"mcm","clk":"1005362619","pt":1580642288806,"mc":[{"id":"1.168135803","rc":[{"batb":[[0,1.58,301.43],[1,1.56,263.66],[2,1.39,16.67]],"ltp":1.66,"tv":2541.66,"id":2249229},{"batl":[[1,3.2,0.31],[2,3.2,0]],"ltp":2.5,"tv":2369.51,"id":5720747}]}]}
{"op":"mcm","clk":"1005363234","pt":1580642291657,"mc":[{"id":"1.168135803","rc":[{"batl":[[0,2.48,25.33],[1,2.5,446.52],[2,3.2,0.31]],"ltp":2.5,"tv":2369.51,"id":5720747}]}]}
{"op":"mcm","clk":"1005363649","pt":1580642293609,"mc":[{"id":"1.168135803","rc":[{"batl":[[1,2.5,441.52]],"ltp":2.5,"tv":2369.51,"id":5720747}]}]}
{"op":"mcm","clk":"1005363847","pt":1580642294724,"mc":[{"id":"1.168135803","rc":[{"trd":[[2.44,370.44]],"batb":[[0,2.44,77.83]],"batl":[[1,3.2,0.31],[2,3.2,0]],"ltp":2.44,"tv":2389.51,"id":5720747}],"tv":4931.18}]}
{"op":"mcm","clk":"1005364207","pt":1580642296743,"mc":[{"id":"1.168135803","rc":[{"trd":[[1.7,593.77]],"ltp":1.7,"tv":2587.87,"id":2249229},{"trd":[[2.44,402.63]],"batb":[[0,2.44,45.63]],"ltp":2.44,"tv":2421.71,"id":5720747}],"tv":5009.58}]}
{"op":"mcm","clk":"1005365332","pt":1580642302354,"mc":[{"id":"1.168135803","rc":[{"trd":[[2.44,412.63]],"batb":[[0,2.44,40.63]],"ltp":2.44,"tv":2431.71,"id":5720747}],"tv":5019.58}]}
{"op":"mcm","clk":"1005365772","pt":1580642304636,"mc":[{"id":"1.168135803","rc":[{"batl":[[0,3.2,0.31],[1,3.2,0]],"ltp":2.44,"tv":2431.71,"id":5720747}]}]}
{"op":"mcm","clk":"1005366351","pt":1580642307766,"mc":[{"id":"1.168135803","rc":[{"trd":[[2.44,463.3]],"batb":[[0,2.44,15.28]],"ltp":2.44,"tv":2482.38,"id":5720747}],"tv":5070.26}]}
{"op":"mcm","clk":"1005367038","pt":1580642311761,"mc":[{"id":"1.168135803","rc":[{"batl":[[0,1.67,150],[1,1.8,420.11],[2,1000,0.16]],"ltp":1.7,"tv":2587.87,"id":2249229}]}]}
{"op":"mcm","clk":"1005367366","pt":1580642313563,"mc":[{"id":"1.168135803","rc":[{"trd":[[1.67,300.76]],"batl":[[0,1.67,141.27],[2,1000,0]],"ltp":1.67,"tv":2596.6,"id":2249229},{"trd":[[2.48,201.35]],"ltp":2.48,"tv":2488.26,"id":5720747}],"tv":5084.87}]}
{"op":"mcm","clk":"1005368022","pt":1580642316653,"mc":[{"id":"1.168135803","rc":[{"trd":[[1.58,0.31]],"batb":[[0,1.58,301.28]],"ltp":1.58,"tv":2596.92,"id":2249229}],"tv":5085.18}]}
{"op":"mcm","clk":"1005368804","pt":1580642320759,"mc":[{"id":"1.168135803","rc":[{"batb":[[1,1.39,16.67],[2,1.34,27.28]],"ltp":1.58,"tv":2596.92,"id":2249229}]}]}
{"op":"mcm","clk":"1005369326","pt":1580642323763,"mc":[{"id":"1.168135803","rc":[{"batb":[[0,1.6,263.66],[1,1.58,301.28],[2,1.39,16.67]],"ltp":1.58,"tv":2596.92,"id":2249229}]}]}
{"op":"mcm","clk":"1005371524","pt":1580642334698,"mc":[{"id":"1.168135803","rc":[{"trd":[[1.6,9.99]],"batb":[[0,1.6,258.67]],"ltp":1.6,"tv":2606.91,"id":2249229}],"tv":5095.18}]}
{"op":"mcm","clk":"1005371738","pt":1580642335787,"mc":[{"id":"1.168135803","rc":[{"trd":[[1.67,303.26]],"batl":[[0,1.67,138.77]],"ltp":1.67,"tv":2609.41,"id":2249229},{"trd":[[2.48,203.03]],"ltp":2.48,"tv":2489.94,"id":5720747}],"tv":5099.36}]}
{"op":"mcm","clk":"1005371941","pt":1580642336803,"mc":[{"id":"1.168135803","rc":[{"trd":[[1.67,580.8],[1.7,615.71],[1.77,174.74],[1.8,333.75]],"batl":[[0,1.8,337.56],[1,1.8,0]],"ltp":1.8,"tv":3248.75,"id":2249229},{"trd":[[2.3,184.9],[2.44,478.59]],"batb":[[0,1.5,27.45],[1,1.25,45.45],[2,1.05,16.8]],"ltp":2.3,"tv":2639.71,"id":5720747}],"tv":5888.46}]}
{"op":"mcm","clk":"1005373289","pt":1580642343632,"mc":[{"id":"1.168135803","rc":[{"batb":[[0,1.7,181.8],[1,1.6,258.67],[2,1.58,301.28]],"ltp":1.8,"tv":3248.75,"id":2249229},{"batl":[[0,2.48,13.17],[1,3.2,0.31]],"ltp":2.3,"tv":2639.71,"id":5720747}]}]}
{"op":"mcm","clk":"1005373500","pt":1580642344678,"mc":[{"id":"1.168135803","rc":[{"batb":[[2,1.39,16.67]],"ltp":1.8,"tv":3248.75,"id":2249229},{"batl":[[0,2.48,18.21]],"ltp":2.3,"tv":2639.71,"id":5720747}]}]}
{"op":"mcm","clk":"1005373896","pt":1580642346508,"mc":[{"id":"1.168135803","rc":[{"batb":[[1,1.61,286.61],[2,1.6,258.67]],"ltp":1.8,"tv":3248.75,"id":2249229}]}]}
{"op":"mcm","clk":"1005374733","pt":1580642350617,"mc":[{"id":"1.168135803","rc":[{"batb":[[0,2.26,138.75],[1,1.5,27.45],[2,1.25,45.45]],"ltp":2.3,"tv":2639.71,"id":5720747}]}]}
{"op":"mcm","clk":"1005375310","pt":1580642353786,"mc":[{"id":"1.168135803","rc":[{"batl":[[0,2.48,13.17]],"ltp":2.3,"tv":2639.71,"id":5720747}]}]}
{"op":"mcm","clk":"1005375469","pt":1580642354820,"mc":[{"id":"1.168135803","rc":[{"batl":[[0,1.72,3.55],[1,1.8,337.56]],"ltp":1.8,"tv":3248.75,"id":2249229}]}]}
{"op":"mcm","clk":"1005377565","pt":1580642365811,"mc":[{"id":"1.168135803","rc":[{"batl":[[0,1.8,337.56],[1,1.8,0]],"ltp":1.8,"tv":3248.75,"id":2249229}]}]}
{"op":"mcm","clk":"1005377714","pt":1580642366606,"mc":[{"id":"1.168135803","rc":[{"batl":[[0,2.38,17.68],[1,2.48,13.17],[2,3.2,0.31]],"ltp":2.3,"tv":2639.71,"id":5720747}]}]}
{"op":"mcm","clk":"1005377902","pt":1580642367716,"mc":[{"id":"1.168135803","rc":[{"batb":[[1,1.89,705.9],[2,1.5,27.45]],"ltp":2.3,"tv":2639.71,"id":5720747}]}]}
{"op":"mcm","clk":"1005378071","pt":1580642368730,"mc":[{"id":"1.168135803","rc":[{"trd":[[1.72,30.97]],"ltp":1.72,"tv":3252.29,"id":2249229},{"trd":[[2.38,12.56]],"batl":[[0,2.38,15.12]],"ltp":2.38,"tv":2642.28,"id":5720747}],"tv":5894.57}]}
{"op":"mcm","clk":"1005378454","pt":1580642370744,"mc":[{"id":"1.168135803","rc":[{"batl":[[1,3.2,0.31],[2,3.2,0]],"ltp":2.38,"tv":2642.28,"id":5720747}]}]}
{"op":"mcm","clk":"1005378988","pt":1580642373551,"mc":[{"id":"1.168135803","rc":[{"batb":[[1,1.67,15],[2,1.61,286.61]],"ltp":1.72,"tv":3252.29,"id":2249229},{"trd":[[2.26,26.34]],"batb":[[0,2.26,125.58]],"ltp":2.26,"tv":2668.62,"id":5720747}],"tv":5920.92}]}
{"op":"mcm","clk":"1005379491","pt":1580642376353,"mc":[{"id":"1.168135803","rc":[{"trd":[[1.72,51.9]],"batl":[[0,1.72,16.93],[1,1.8,337.56]],"ltp":1.72,"tv":3273.22,"id":2249229},{"trd":[[2.38,27.68]],"batl":[[0,3.2,0.31],[1,3.2,0]],"ltp":2.38,"tv":2683.74,"id":5720747}],"tv":5956.96}]}
{"op":"mcm","clk":"1005381928","pt":1580642389584,"mc":[{"id":"1.168135803","rc":[{"batl":[[0,1.8,337.56],[1,1.8,0]],"ltp":1.72,"tv":3273.22,"id":2249229}]}]}
{"op":"mcm","clk":"1005382155","pt":1580642390759,"mc":[{"id":"1.168135803","rc":[{"trd":[[1.7,671.94]],"batb":[[0,1.7,153.69]],"ltp":1.7,"tv":3329.46,"id":2249229}],"tv":6013.2}]}
{"op":"mcm","clk":"1005382512","pt":1580642392772,"mc":[{"id":"1.168135803","rc":[{"trd":[[1.7,705.81]],"batb":[[0,1.72,25],[1,1.7,136.75],[2,1.67,15]],"ltp":1.7,"tv":3363.32,"id":2249229}],"tv":6047.07}]}
{"op":"mcm","clk":"1005383231","pt":1580642396796,"mc":[{"id":"1.168135803","rc":[{"trd":[[1.72,82.19]],"batb":[[0,1.72,9.86]],"ltp":1.72,"tv":3393.61,"id":2249229}],"tv":6077.35}]}
{"op":"mcm","clk":"1005383422","pt":1580642397808,"mc":[{"id":"1.168135803","rc":[{"batl":[[1,1.91,287.01],[2,1.93,331.11]],"ltp":1.72,"tv":3393.61,"id":2249229}]}]}
{"op":"mcm","clk":"1005383978","pt":1580642400812,"mc":[{"id":"1.168135803","rc":[{"trd":[[1.72,100.19]],"batb":[[0,1.7,137.61],[1,1.67,15],[2,1.61,286.61]],"ltp":1.72,"tv":3411.61,"id":2249229}],"tv":6095.35}]}
{"op":"mcm","clk":"1005384392","pt":1580642402787,"mc":[{"id":"1.168135803","rc":[{"batb":[[0,1.89,705.9],[1,1.5,27.45],[2,1.25,45.45]],"ltp":2.38,"tv":2683.74,"id":5720747}]}]}
{"op":"mcm","clk":"1005385232","pt":1580642406788,"mc":[{"id":"1.168135803","rc":[{"trd":[[1.72,104.16]],"batb":[[0,1.7,136.75]],"ltp":1.72,"tv":3415.58,"id":2249229},{"trd":[[2.38,29.31]],"batb":[[0,2.1,158.94],[1,1.89,705.9],[2,1.5,27.45]],"batl":[[0,2.26,3.37],[1,3.2,0.31]],"ltp":2.38,"tv":2685.37,"id":5720747}],"tv":6100.95}]}
{"op":"mcm","clk":"1005385778","pt":1580642409812,"mc":[{"id":"1.168135803","rc":[{"batl":[[1,1.91,0],[2,1.93,0]],"ltp":1.72,"tv":3415.58,"id":2249229}]}]}
{"op":"mcm","clk":"1005386321","pt":1580642412692,"mc":[{"id":"1.168135803","rc":[{"trd":[[1.79,4.25]],"ltp":1.79,"tv":3419.83,"id":2249229},{"trd":[[2.26,29.71]],"batl":[[0,3.2,0.31],[1,3.2,0]],"ltp":2.26,"tv":2688.74,"id":5720747}],"tv":6108.57}]}
{"op":"mcm","clk":"1005386703","pt":1580642414705,"mc":[{"id":"1.168135803","rc":[{"trd":[[1.7,905.82]],"batb":[[0,1.7,36.75]],"ltp":1.7,"tv":3619.83,"id":2249229}],"tv":6308.58}]}
{"op":"mcm","clk":"1005387086","pt":1580642416790,"mc":[{"id":"1.168135803","rc":[{"batl":[[0,1.9,186.52],[1,1.91,380.73],[2,1.93,331.25]],"ltp":1.7,"tv":3619.83,"id":2249229}]}]}
{"op":"mcm","clk":"1005387758","pt":1580642420803,"mc":[{"id":"1.168135803","rc":[{"batb":[[0,2.12,100],[1,2.1,158.94],[2,1.89,705.9]],"ltp":2.26,"tv":2688.74,"id":5720747}]}]}
{"op":"mcm","clk":"1005388523","pt":1580642424732,"mc":[{"id":"1.168135803","rc":[{"batb":[[2,1.62,281.99]],"ltp":1.7,"tv":3619.83,"id":2249229},{"batl":[[0,2.42,2],[1,3.2,0.31]],"ltp":2.26,"tv":2688.74,"id":5720747}]}]}
{"op":"mcm","clk":"1005388708","pt":1580642425709,"mc":[{"id":"1.168135803","rc":[{"batb":[[0,2.14,153.36],[1,2.12,100],[2,2.1,158.94]],"ltp":2.26,"tv":2688.74,"id":5720747}]}]}
{"op":"mcm","clk":"1005389375","pt":1580642429635,"mc":[{"id":"1.168135803","rc":[{"batb":[[0,2.12,100],[1,1.89,705.9],[2,1.5,27.45]],"ltp":2.26,"tv":2688.74,"id":5720747}]}]}
{"op":"mcm","clk":"1005389583","pt":1580642430806,"mc":[{"id":"1.168135803","rc":[{"batb":[[0,1.78,317.76],[1,1.7,36.75],[2,1.67,15]],"ltp":1.7,"tv":3619.83,"id":2249229},{"batb":[[1,1.5,27.45],[2,1.25,45.45]],"ltp":2.26,"tv":2688.74,"id":5720747}]}]}
{"op":"mcm","clk":"1005389907","pt":1580642432719,"mc":[{"id":"1.168135803","rc":[{"batb":[[0,1.83,280.44],[1,1.81,399.4],[2,1.78,317.76]],"ltp":1.7,"tv":3619.83,"id":2249229}]}]}
{"op":"mcm","clk":"1005390086","pt":1580642433621,"mc":[{"id":"1.168135803","rc":[{"batl":[[0,1.9,186.75]],"ltp":1.7,"tv":3619.83,"id":2249229},{"batl":[[1,1000,3.33]],"ltp":2.26,"tv":2688.74,"id":5720747}]}]}
{"op":"mcm","clk":"1005390293","pt":1580642434734,"mc":[{"id":"1.168135803","rc":[{"batb":[[0,1.5,27.45],[1,1.25,45.45],[2,1.05,16.8]],"ltp":2.26,"tv":2688.74,"id":5720747}]}]}
{"op":"mcm","clk":"1005390467","pt":1580642435738,"mc":[{"id":"1.168135803","rc":[{"batb":[[2,1.71,5.9]],"ltp":1.7,"tv":3619.83,"id":2249229},{"batb":[[0,1.74,733.85],[1,1.5,27.26],[2,1.25,45.45]],"ltp":2.26,"tv":2688.74,"id":5720747}]}]}
{"op":"mcm","clk":"1005390641","pt":1580642436646,"mc":[{"id":"1.168135803","rc":[{"trd":[[1.86,0.45],[1.9,96.64]],"batb":[[0,1.71,5.9],[1,1.67,15],[2,1.52,170.95]],"batl":[[0,1.9,138.2],[1,1.91,0],[2,1.93,0]],"ltp":1.9,"tv":3716.93,"id":2249229}],"tv":6405.67}]}
{"op":"mcm","clk":"1005390838","pt":1580642437764,"mc":[{"id":"1.168135803","rc":[{"batb":[[0,1.73,239.49],[1,1.71,5.9],[2,1.67,15]],"ltp":1.9,"tv":3716.93,"id":2249229}]}]}
{"op":"mcm","clk":"1005391024","pt":1580642438750,"mc":[{"id":"1.168135803","rc":[{"trd":[[1.73,6.06],[1.9,107.69]],"batb":[[0,1.73,236.47]],"batl":[[0,1.9,127.16]],"ltp":1.9,"tv":3734.04,"id":2249229},{"trd":[[2.1,75.36]],"ltp":2.1,"tv":2698.74,"id":5720747}],"tv":6432.78}]}
{"op":"mcm","clk":"1005391194","pt":1580642439757,"mc":[{"id":"1.168135803","rc":[{"batb":[[0,1.82,376.14],[1,1.8,407.1],[2,1.73,236.47]],"batl":[[0,1.9,449.77],[1,1.92,336.83]],"ltp":1.9,"tv":3734.04,"id":2249229}]}]}
{"op":"mcm","clk":"1005391375","pt":1580642440773,"mc":[{"id":"1.168135803","rc":[{"trd":[[1.82,376.14]],"batb":[[0,1.8,407.1],[1,1.73,236.47],[2,1.71,5.9]],"ltp":1.82,"tv":4110.18,"id":2249229},{"trd":[[2.22,308.37]],"batb":[[0,2.24,44.51],[1,1.74,733.85],[2,1.5,27.26]],"ltp":2.22,"tv":3007.11,"id":5720747}],"tv":7117.29}]}
{"op":"mcm","clk":"1005391542","pt":1580642441680,"mc":[{"id":"1.168135803","rc":[{"batl":[[0,1.9,127.16],[1,1.92,0]],"ltp":1.82,"tv":4110.18,"id":2249229}]}]}
{"op":"mcm","clk":"1005391752","pt":1580642442740,"mc":[{"id":"1.168135803","rc":[{"batl":[[0,1000,3.33],[1,1000,0]],"ltp":2.22,"tv":3007.11,"id":5720747}]}]}
{"op":"mcm","clk":"1005391946","pt":1580642443751,"mc":[{"id":"1.168135803","rc":[{"batb":[[0,1.73,236.47],[1,1.71,5.9],[2,1.67,15]],"ltp":1.82,"tv":4110.18,"id":2249229},{"batb":[[1,1.94,185.99],[2,1.74,733.85]],"ltp":2.22,"tv":3007.11,"id":5720747}]}]}
{"op":"mcm","clk":"1005392124","pt":1580642444758,"mc":[{"id":"1.168135803","rc":[{"trd":[[1.81,55.09]],"batb":[[0,1.82,207.68],[1,1.73,236.47],[2,1.71,5.9]],"batl":[[0,1.89,259.47],[1,1.9,127.16],[2,1.91,342.55]],"ltp":1.81,"tv":4165.27,"id":2249229},{"trd":[[2.24,44.51]],"batb":[[0,1.94,185.99],[1,1.74,733.85],[2,1.5,27.26]],"batl":[[0,1000,4.09]],"ltp":2.24,"tv":3051.62,"id":5720747}],"tv":7216.89}]}
{"op":"mcm","clk":"1005392307","pt":1580642445735,"mc":[{"id":"1.168135803","rc":[{"batb":[[0,1.73,236.47],[1,1.71,5.9],[2,1.67,15]],"batl":[[0,1.9,127.16],[1,1.9,0],[2,1.91,0]],"ltp":1.81,"tv":4165.27,"id":2249229},{"batl":[[0,2.4,2],[1,1000,4.09]],"ltp":2.24,"tv":3051.62,"id":5720747}]}]}
{"op":"mcm","clk":"1005392506","pt":1580642446752,"mc":[{"id":"1.168135803","rc":[{"batb":[[2,1.68,259.62]],"batl":[[1,2.2,299.56],[2,2.22,220.33]],"ltp":1.81,"tv":4165.27,"id":2249229}]}]}
{"op":"mcm","clk":"1005392888","pt":1580642448773,"mc":[{"id":"1.168135803","rc":[{"batb":[[0,1.74,733.85],[1,1.5,27.26],[2,1.25,45.45]],"ltp":2.24,"tv":3051.62,"id":5720747}]}]}
{"op":"mcm","clk":"1005393078","pt":1580642449765,"mc":[{"id":"1.168135803","rc":[{"batl":[[1,2.2,0],[2,2.22,0]],"ltp":1.81,"tv":4165.27,"id":2249229},{"batl":[[0,1000,4.09],[1,1000,0]],"ltp":2.24,"tv":3051.62,"id":5720747}]}]}
{"op":"mcm","clk":"1005393256","pt":1580642450767,"mc":[{"id":"1.168135803","rc":[{"batb":[[2,1.7,264.5]],"ltp":1.81,"tv":4165.27,"id":2249229},{"trd":[[2.26,33.71]],"batb":[[0,1.74,734.17]],"ltp":2.26,"tv":3055.62,"id":5720747}],"tv":7220.89}]}
{"op":"mcm","clk":"1005393422","pt":1580642451773,"mc":[{"id":"1.168135803","rc":[{"batb":[[0,1.71,5.9],[1,1.7,264.5],[2,1.68,515.01]],"ltp":1.81,"tv":4165.27,"id":2249229},{"batb":[[0,1.85,206.19],[1,1.84,208.13],[2,1.74,733.67]],"batl":[[0,1000,3.33]],"ltp":2.26,"tv":3055.62,"id":5720747}]}]}
{"op":"mcm","clk":"1005393608","pt":1580642452784,"mc":[{"id":"1.168135803","rc":[{"batl":[[0,1.76,301.82],[1,1.78,428.28],[2,1.81,247.86]],"ltp":1.81,"tv":4165.27,"id":2249229},{"batb":[[2,1.5,27.26]],"batl":[[0,2.36,2],[1,1000,3.33]],"ltp":2.26,"tv":3055.62,"id":5720747}]}]}
{"op":"mcm","clk":"1005393790","pt":1580642453748,"mc":[{"id":"1.168135803","rc":[{"batb":[[2,1.69,253.38]],"ltp":1.81,"tv":4165.27,"id":2249229}]}]}
{"op":"mcm","clk":"1005393990","pt":1580642454778,"mc":[{"id":"1.168135803","rc":[{"trd":[[1.76,0.99]],"batb":[[2,1.68,515.01]],"batl":[[0,1.76,300.83]],"ltp":1.76,"tv":4166.26,"id":2249229},{"trd":[[2.3,185.66]],"ltp":2.3,"tv":3056.38,"id":5720747}],"tv":7222.64}]}
{"op":"mcm","clk":"1005394159","pt":1580642455766,"mc":[{"id":"1.168135803","rc":[{"batb":[[0,1.5,27.45],[1,1.25,45.45],[2,1.05,16.8]],"ltp":2.3,"tv":3056.38,"id":5720747}]}]}
{"op":"mcm","clk":"1005394520","pt":1580642457773,"mc":[{"id":"1.168135803","rc":[{"batl":[[2,1.81,0]],"ltp":1.76,"tv":4166.26,"id":2249229},{"batb":[[0,1.85,712.56],[1,1.5,27.26],[2,1.25,45.45]],"ltp":2.3,"tv":3056.38,"id":5720747}]}]}
{"op":"mcm","clk":"1005395076","pt":1580642460773,"mc":[{"id":"1.168135803","rc":[{"batl":[[2,2.1,186.52]],"ltp":1.76,"tv":4166.26,"id":2249229},{"batb":[[0,2,174.83],[1,1.85,712.56],[2,1.5,27.26]],"ltp":2.3,"tv":3056.38,"id":5720747}]}]}
{"op":"mcm","clk":"1005395951","pt":1580642465783,"mc":[{"id":"1.168135803","rc":[{"batb":[[1,1.67,15],[2,1.58,301.43]],"batl":[[0,2.1,186.52],[1,1.78,0],[2,2.1,0]],"ltp":1.76,"tv":4166.26,"id":2249229}]}]}
{"op":"mcm","clk":"1005396114","pt":1580642466800,"mc":[{"id":"1.168135803","rc":[{"batl":[[1,3.2,0.31]],"ltp":2.3,"tv":3056.38,"id":5720747}]}]}
{"op":"mcm","clk":"1005396293","pt":1580642467813,"mc":[{"id":"1.168135803","rc":[{"batb":[[2,1.6,478.95]],"batl":[[0,1.99,316.13],[1,2.02,435.9],[2,2.1,186.52]],"ltp":1.76,"tv":4166.26,"id":2249229},{"batl":[[0,2.3,41.86]],"ltp":2.3,"tv":3056.38,"id":5720747}]}]}
{"op":"mcm","clk":"1005396468","pt":1580642468782,"mc":[{"id":"1.168135803","rc":[{"batb":[[0,2.2,100],[1,2,174.83],[2,1.85,712.56]],"ltp":2.3,"tv":3056.38,"id":5720747}]}]}
{"op":"mcm","clk":"1005396833","pt":1580642470691,"mc":[{"id":"1.168135803","rc":[{"batb":[[0,2,174.83],[1,1.85,712.56],[2,1.5,27.26]],"ltp":2.3,"tv":3056.38,"id":5720747}]}]}
{"op":"mcm","clk":"1005397562","pt":1580642474778,"mc":[{"id":"1.168135803","rc":[{"batb":[[2,1.61,286.61]],"ltp":1.76,"tv":4166.26,"id":2249229}]}]}
{"op":"mcm","clk":"1005397745","pt":1580642475686,"mc":[{"id":"1.168135803","rc":[{"batl":[[0,2.1,186.52],[1,2.02,0],[2,2.1,0]],"ltp":1.76,"tv":4166.26,"id":2249229}]}]}
{"op":"mcm","clk":"1005397950","pt":1580642476801,"mc":[{"id":"1.168135803","rc":[{"trd":[[1.76,55.7]],"batl":[[0,1.76,38.56],[1,2.1,186.52]],"ltp":1.76,"tv":4220.96,"id":2249229},{"trd":[[2.3,227.52]],"batb":[[0,2.02,171.4],[1,2,174.83],[2,1.85,712.56]],"batl":[[0,3.2,0.31],[1,3.2,0]],"ltp":2.3,"tv":3098.24,"id":5720747}],"tv":7319.2}]}
{"op":"mcm","clk":"1005398121","pt":1580642477812,"mc":[{"id":"1.168135803","rc":[{"batb":[[2,1.6,478.95]],"batl":[[0,2.1,186.52],[1,2.1,0]],"ltp":1.76,"tv":4220.96,"id":2249229},{"batb":[[0,2.1,100],[1,2.02,171.4],[2,2,174.83]],"ltp":2.3,"tv":3098.24,"id":5720747}]}]}
{"op":"mcm","clk":"1005398280","pt":1580642478709,"mc":[{"id":"1.168135803","rc":[{"trd":[[1.67,610.79],[1.71,14.07]],"batb":[[0,1.6,478.95],[1,1.59,317.33],[2,1.44,179.67]],"batl":[[0,1.66,365.46],[1,1.67,490.63],[2,2.1,186.52]],"ltp":1.67,"tv":4262.76,"id":2249229}],"tv":7361.0}]}
{"op":"mcm","clk":"1005398455","pt":1580642479812,"mc":[{"id":"1.168135803","rc":[{"batl":[[2,1.7,37.1]],"ltp":1.67,"tv":4262.76,"id":2249229}]}]}
{"op":"mcm","clk":"1005398596","pt":1580642480722,"mc":[{"id":"1.168135803","rc":[{"batl":[[1,1.67,263.67],[2,2.1,186.52]],"ltp":1.67,"tv":4262.76,"id":2249229}]}]}
{"op":"mcm","clk":"1005398780","pt":1580642481727,"mc":[{"id":"1.168135803","rc":[{"batb":[[1,1.5,27.45],[2,1.4,337.78]],"ltp":2.3,"tv":3098.24,"id":5720747}]}]}
{"op":"mcm","clk":"1005399125","pt":1580642483738,"mc":[{"id":"1.168135803","rc":[{"trd":[[1.66,530.06]],"batl":[[0,1.66,344.3]],"ltp":1.66,"tv":4305.08,"id":2249229},{"batb":[[1,1.95,690.02],[2,1.5,27.45]],"ltp":2.3,"tv":3098.24,"id":5720747}],"tv":7403.32}]}
{"op":"mcm","clk":"1005399281","pt":1580642484685,"mc":[{"id":"1.168135803","rc":[{"batl":[[2,1.9,186.52]],"ltp":1.66,"tv":4305.08,"id":2249229}]}]}
{"op":"mcm","clk":"1005400035","pt":1580642488819,"mc":[{"id":"1.168135803","rc":[{"batb":[[2,1.5,349.66]],"ltp":1.66,"tv":4305.08,"id":2249229}]}]}
{"op":"mcm","clk":"1005400359","pt":1580642490725,"mc":[{"id":"1.168135803","rc":[{"batb":[[0,1.5,349.66],[1,1.44,179.67],[2,1.34,27.28]],"batl":[[0,1.9,186.52],[1,2.1,186.52],[2,1.9,0]],"ltp":1.66,"tv":4305.08,"id":2249229}]}]}
{"op":"mcm","clk":"1005401013","pt":1580642494752,"mc":[{"id":"1.168135803","rc":[{"batb":[[0,1.54,503.79],[1,1.53,368.22],[2,1.5,349.66]],"batl":[[0,1.8,330.63],[1,1.82,398.47],[2,1.9,186.52]],"ltp":1.66,"tv":4305.08,"id":2249229}]}]}
{"op":"mcm","clk":"1005401567","pt":1580642497757,"mc":[{"id":"1.168135803","rc":[{"batb":[[0,1.44,179.67],[1,1.34,27.28],[2,1.25,45.43]],"batl":[[0,1.9,186.52],[1,2.1,186.52],[2,1.9,0]],"ltp":1.66,"tv":4305.08,"id":2249229}]}]}
{"op":"mcm","clk":"1005401928","pt":1580642499774,"mc":[{"id":"1.168135803","rc":[{"batb":[[0,1.56,312.2],[1,1.44,179.67],[2,1.34,27.28]],"ltp":1.66,"tv":4305.08,"id":2249229}]}]}
{"op":"mcm","clk":"1005402128","pt":1580642500739,"mc":[{"id":"1.168135803","rc":[{"batb":[[0,1.63,292.54],[1,1.62,295.41],[2,1.56,312.2]],"batl":[[0,1.69,451.13],[1,1.71,488.67],[2,1.9,186.52]],"ltp":1.66,"tv":4305.08,"id":2249229}]}]}
{"op":"mcm","clk":"1005402289","pt":1580642501744,"mc":[{"id":"1.168135803","rc":[{"batb":[[0,1.56,312.2],[1,1.55,317.87],[2,1.44,179.67]],"batl":[[0,1.9,186.52],[1,2.1,186.52],[2,1.9,0]],"ltp":1.66,"tv":4305.08,"id":2249229},{"batb":[[0,2.28,136.59],[1,2.26,138.75],[2,2.1,100]],"ltp":2.3,"tv":3098.24,"id":5720747}]}]}
{"op":"mcm","clk":"1005402636","pt":1580642503755,"mc":[{"id":"1.168135803","rc":[{"batb":[[2,1.54,503.79]],"batl":[[0,1.8,330.63],[1,1.82,398.47],[2,1.9,186.52]],"ltp":1.66,"tv":4305.08,"id":2249229}]}]}
{"op":"mcm","clk":"1005403940","pt":1580642511637,"mc":[{"id":"1.168135803","rc":[{"batb":[[2,1.95,690.02]],"ltp":2.3,"tv":3098.24,"id":5720747}]}]}
{"op":"mcm","clk":"1005404488","pt":1580642514547,"mc":[{"id":"1.168135803","rc":[{"batb":[[0,1.57,87.71],[1,1.56,312.2],[2,1.55,317.87]],"ltp":1.66,"tv":4305.08,"id":2249229},{"batb":[[0,2.3,100],[1,2.28,136.59],[2,2.26,138.75]],"ltp":2.3,"tv":3098.24,"id":5720747}]}]}
{"op":"mcm","clk":"1005404710","pt":1580642515766,"mc":[{"id":"1.168135803","rc":[{"batl":[[0,1.78,50],[1,1.8,330.63],[2,1.82,398.47]],"ltp":1.66,"tv":4305.08,"id":2249229}]}]}
{"op":"mcm","clk":"1005404891","pt":1580642516751,"mc":[{"id":"1.168135803","rc":[{"batb":[[1,1.54,503.79],[2,1.53,368.22]],"ltp":1.66,"tv":4305.08,"id":2249229}]}]}
{"op":"mcm","clk":"1005405877","pt":1580642521778,"mc":[{"id":"1.168135803","rc":[{"batl":[[0,1.8,330.63],[1,1.82,398.47],[2,1.9,186.52]],"ltp":1.66,"tv":4305.08,"id":2249229}]}]}
{"op":"mcm","clk":"1005406211","pt":1580642523667,"mc":[{"id":"1.168135803","rc":[{"batl":[[0,1.76,50],[1,1.8,330.63],[2,1.82,398.47]],"ltp":1.66,"tv":4305.08,"id":2249229}]}]}
{"op":"mcm","clk":"1005406993","pt":1580642527685,"mc":[{"id":"1.168135803","rc":[{"batl":[[1,1.9,186.52],[2,2.1,186.52]],"ltp":1.66,"tv":4305.08,"id":2249229}]}]}
{"op":"mcm","clk":"1005407381","pt":1580642529795,"mc":[{"id":"1.168135803","rc":[{"batb":[[0,1.54,503.79],[1,1.53,368.22],[2,1.5,227.17]],"ltp":1.66,"tv":4305.08,"id":2249229}]}]}
{"op":"mcm","clk":"1005407584","pt":1580642530762,"mc":[{"id":"1.168135803","rc":[{"batl":[[0,1.59,277.2],[1,1.6,307.46],[2,1.61,247.86]],"ltp":1.66,"tv":4305.08,"id":2249229}]}]}
{"op":"mcm","clk":"1005407975","pt":1580642532781,"mc":[{"id":"1.168135803","rc":[{"batb":[[1,1.95,690.02],[2,1.5,27.45]],"ltp":2.3,"tv":3098.24,"id":5720747}]}]}
{"op":"mcm","clk":"1005408150","pt":1580642533795,"mc":[{"id":"1.168135803","rc":[{"trd":[[1.59,5.11]],"batl":[[0,1.59,272.09]],"ltp":1.59,"tv":4310.19,"id":2249229},{"trd":[[2.68,3.03]],"ltp":2.68,"tv":3101.26,"id":5720747}],"tv":7411.46}]}
{"op":"mcm","clk":"1005408308","pt":1580642534785,"mc":[{"id":"1.168135803","rc":[{"batb":[[0,1.95,690.02],[1,1.5,27.45],[2,1.4,337.78]],"ltp":2.68,"tv":3101.26,"id":5720747}]}]}
{"op":"mcm","clk":"1005408508","pt":1580642535794,"mc":[{"id":"1.168135803","rc":[{"batl":[[2,1.9,186.52]],"ltp":1.59,"tv":4310.19,"id":2249229}]}]}
{"op":"mcm","clk":"1005408678","pt":1580642536808,"mc":[{"id":"1.168135803","rc":[{"batb":[[0,2.5,116.55],[1,1.95,690.02],[2,1.5,27.45]],"ltp":2.68,"tv":3101.26,"id":5720747}]}]}
{"op":"mcm","clk":"1005408891","pt":1580642537777,"mc":[{"id":"1.168135803","rc":[{"batb":[[2,1.36,185.93]],"ltp":1.59,"tv":4310.19,"id":2249229}]}]}
{"op":"mcm","clk":"1005409264","pt":1580642539803,"mc":[{"id":"1.168135803","rc":[{"batb":[[2,1.44,397.36]],"ltp":1.59,"tv":4310.19,"id":2249229}]}]}
{"op":"mcm","clk":"1005409798","pt":1580642542803,"mc":[{"id":"1.168135803","rc":[{"batb":[[0,1.44,397.36],[1,1.36,185.92],[2,1.34,27.28]],"batl":[[0,1.9,186.52],[1,2.1,186.52],[2,1.9,0]],"ltp":1.59,"tv":4310.19,"id":2249229}]}]}
{"op":"mcm","clk":"1005410365","pt":1580642545799,"mc":[{"id":"1.168135803","rc":[{"batb":[[0,1.51,616.26],[1,1.5,399.49],[2,1.44,397.36]],"batl":[[0,1.65,292.76],[1,1.66,269.54],[2,1.9,186.52]],"ltp":1.59,"tv":4310.19,"id":2249229}]}]}
{"op":"mcm","clk":"1005410982","pt":1580642548632,"mc":[{"id":"1.168135803","rc":[{"batb":[[0,1.95,690.02],[1,1.5,27.45],[2,1.4,337.78]],"ltp":2.68,"tv":3101.26,"id":5720747}]}]}
{"op":"mcm","clk":"1005411167","pt":1580642549739,"mc":[{"id":"1.168135803","rc":[{"batb":[[2,1.36,185.93]],"ltp":1.59,"tv":4310.19,"id":2249229}]}]}
{"op":"mcm","clk":"1005411560","pt":1580642551730,"mc":[{"id":"1.168135803","rc":[{"batb":[[0,2.54,227.05],[1,1.95,690.02],[2,1.5,27.45]],"ltp":2.68,"tv":3101.26,"id":5720747}]}]}
{"op":"mcm","clk":"1005411761","pt":1580642552738,"mc":[{"id":"1.168135803","rc":[{"batb":[[0,1.52,336.21],[1,1.36,185.93],[2,1.34,27.28]],"batl":[[0,1.9,186.52],[1,2.1,186.52],[2,1.9,0]],"ltp":1.59,"tv":4310.19,"id":2249229}]}]}
{"op":"mcm","clk":"1005411957","pt":1580642553647,"mc":[{"id":"1.168135803","rc":[{"batb":[[0,1.52,672.43]],"ltp":1.59,"tv":4310.19,"id":2249229}]}]}
{"op":"mcm","clk":"1005412351","pt":1580642555764,"mc":[{"id":"1.168135803","rc":[{"batb":[[0,1.55,485.39],[1,1.54,358.96],[2,1.52,672.43]],"batl":[[0,1.61,536.93],[1,1.62,292.97],[2,1.9,186.52]],"ltp":1.59,"tv":4310.19,"id":2249229}]}]}
{"op":"mcm","clk":"1005412556","pt":1580642556728,"mc":[{"id":"1.168135803","rc":[{"batb":[[0,1.52,672.43],[1,1.36,185.93],[2,1.34,27.28]],"ltp":1.59,"tv":4310.19,"id":2249229}]}]}
{"op":"mcm","clk":"1005412745","pt":1580642557736,"mc":[{"id":"1.168135803","rc":[{"batb":[[0,1.53,94.33],[1,1.52,672.43],[2,1.36,185.93]],"ltp":1.59,"tv":4310.19,"id":2249229}]}]}
{"op":"mcm","clk":"1005413124","pt":1580642559756,"mc":[{"id":"1.168135803","rc":[{"batb":[[2,1.44,5.02]],"ltp":1.59,"tv":4310.19,"id":2249229}]}]}
{"op":"mcm","clk":"1005413289","pt":1580642560625,"mc":[{"id":"1.168135803","rc":[{"batb":[[2,1.51,608.93]],"batl":[[0,1.65,299.37],[1,1.66,269.55]],"ltp":1.59,"tv":4310.19,"id":2249229}]}]}
{"op":"mcm","clk":"1005414670","pt":1580642567738,"mc":[{"id":"1.168135803","rc":[{"trd":[[1.53,106.11]],"batb":[[0,1.53,41.26]],"ltp":1.53,"tv":4416.3,"id":2249229}],"tv":7517.57}]}
{"op":"mcm","clk":"1005415035","pt":1580642569754,"mc":[{"id":"1.168135803","rc":[{"trd":[[2.54,4]],"batb":[[0,2.54,225.05]],"ltp":2.54,"tv":3105.27,"id":5720747}],"tv":7521.57}]}
{"op":"mcm","clk":"1005415451","pt":1580642571753,"mc":[{"id":"1.168135803","rc":[{"batb":[[2,1.44,7.02]],"ltp":1.53,"tv":4416.3,"id":2249229}]}]}
{"op":"mcm","clk":"1005415857","pt":1580642573782,"mc":[{"id":"1.168135803","rc":[{"trd":[[1.53,108.39]],"batb":[[0,1.53,40.12],[1,1.44,7.02],[2,1.36,185.92]],"ltp":1.53,"tv":4418.58,"id":2249229}],"tv":7523.85}]}
{"op":"mcm","clk":"1005416059","pt":1580642574801,"mc":[{"id":"1.168135803","rc":[{"batb":[[0,1.59,576.69],[1,1.58,752.86],[2,1.53,40.12]],"ltp":1.53,"tv":4418.58,"id":2249229},{"batb":[[0,1.95,690.02],[1,1.5,27.45],[2,1.4,337.78]],"ltp":2.54,"tv":3105.27,"id":5720747}]}]}
{"op":"mcm","clk":"1005416869","pt":1580642578766,"mc":[{"id":"1.168135803","rc":[{"batb":[[2,1.44,9.02]],"ltp":1.53,"tv":4418.58,"id":2249229}]}]}
{"op":"mcm","clk":"1005417072","pt":1580642579778,"mc":[{"id":"1.168135803","rc":[{"batb":[[1,1.58,325.52]],"ltp":1.53,"tv":4418.58,"id":2249229}]}]}
{"op":"mcm","clk":"1005417238","pt":1580642580693,"mc":[{"id":"1.168135803","rc":[{"batb":[[0,1.62,2.7],[1,1.59,576.69],[2,1.58,325.52]],"ltp":1.53,"tv":4418.58,"id":2249229}]}]}
{"op":"mcm","clk":"1005417433","pt":1580642581769,"mc":[{"id":"1.168135803","rc":[{"trd":[[1.59,104.03],[1.62,5.4]],"batb":[[0,1.59,527.23],[1,1.58,325.52],[2,1.44,9.02]],"ltp":1.59,"tv":4522.9,"id":2249229}],"tv":7628.17}]}
{"op":"mcm","clk":"1005417629","pt":1580642582780,"mc":[{"id":"1.168135803","rc":[{"batb":[[2,1.54,323.76]],"ltp":1.59,"tv":4522.9,"id":2249229}]}]}
{"op":"mcm","clk":"1005418198","pt":1580642585783,"mc":[{"id":"1.168135803","rc":[{"batb":[[0,2.3,134.49],[1,1.95,690.02],[2,1.5,27.45]],"ltp":2.54,"tv":3105.27,"id":5720747}]}]}
{"op":"mcm","clk":"1005418367","pt":1580642586688,"mc":[{"id":"1.168135803","rc":[{"batb":[[0,1.54,323.76],[1,1.44,9.02],[2,1.39,183.36]],"ltp":1.59,"tv":4522.9,"id":2249229}]}]}
{"op":"mcm","clk":"1005418945","pt":1580642589710,"mc":[{"id":"1.168135803","rc":[{"batb":[[1,1.53,350.23],[2,1.52,377.43]],"batl":[[0,1.7,4.73],[1,1.81,365.6],[2,1.83,391.67]],"ltp":1.59,"tv":4522.9,"id":2249229}]}]}
{"op":"mcm","clk":"1005419170","pt":1580642590785,"mc":[{"id":"1.168135803","rc":[{"batb":[[0,1.54,323.81]],"ltp":1.59,"tv":4522.9,"id":2249229}]}]}
{"op":"mcm","clk":"1005419545","pt":1580642592803,"mc":[{"id":"1.168135803","rc":[{"batb":[[0,1.95,690.02],[1,1.5,27.45],[2,1.4,337.78]],"ltp":2.54,"tv":3105.27,"id":5720747}]}]}
{"op":"mcm","clk":"1005419922","pt":1580642594780,"mc":[{"id":"1.168135803","rc":[{"batb":[[0,1.55,90.95],[1,1.54,323.76],[2,1.53,350.23]],"ltp":1.59,"tv":4522.9,"id":2249229},{"batb":[[0,2.24,140.99],[1,1.95,690.02],[2,1.5,27.45]],"ltp":2.54,"tv":3105.27,"id":5720747}]}]}
{"op":"mcm","clk":"1005420133","pt":1580642595799,"mc":[{"id":"1.168135803","rc":[{"batb":[[0,1.55,90.9]],"ltp":1.59,"tv":4522.9,"id":2249229},{"batb":[[0,2.26,138.75],[1,2.24,140.99],[2,1.95,690.02]],"ltp":2.54,"tv":3105.27,"id":5720747}]}]}
{"op":"mcm","clk":"1005420703","pt":1580642598809,"mc":[{"id":"1.168135803","rc":[{"trd":[[1.7,905.92]],"batb":[[1,1.54,647.52]],"batl":[[0,1.7,4.68]],"ltp":1.7,"tv":4523.0,"id":2249229}],"tv":7628.27}]}
{"op":"mcm","clk":"1005421524","pt":1580642602789,"mc":[{"id":"1.168135803","rc":[{"batb":[[0,1.58,104.18],[1,1.55,90.9],[2,1.54,647.52]],"ltp":1.7,"tv":4523.0,"id":2249229}]}]}
{"op":"mcm","clk":"1005421878","pt":1580642604500,"mc":[{"id":"1.168135803","rc":[{"trd":[[1.7,909.51]],"batl":[[0,1.7,1.09]],"ltp":1.7,"tv":4526.59,"id":2249229},{"trd":[[2.42,2.52]],"ltp":2.42,"tv":3107.79,"id":5720747}],"tv":7634.38}]}
{"op":"mcm","clk":"1005424550","pt":1580642617641,"mc":[{"id":"1.168135803","rc":[{"batb":[[1,1.54,647.52],[2,1.53,350.23]],"batl":[[1,1.88,186.52],[2,1.83,0]],"ltp":1.7,"tv":4526.59,"id":2249229}]}]}
{"op":"mcm","clk":"1005424946","pt":1580642619721,"mc":[{"id":"1.168135803","rc":[{"batb":[[0,1.53,350.23],[1,1.52,377.43],[2,1.44,9.02]],"ltp":1.7,"tv":4526.59,"id":2249229},{"batb":[[0,1.95,690.02],[1,1.5,27.45],[2,1.4,337.78]],"ltp":2.42,"tv":3107.79,"id":5720747}]}]}
{"op":"mcm","clk":"1005425130","pt":1580642620749,"mc":[{"id":"1.168135803","rc":[{"batl":[[0,1.58,557.45],[1,1.59,314.03],[2,1.7,1.09]],"ltp":1.7,"tv":4526.59,"id":2249229}]}]}
{"op":"mcm","clk":"1005426096","pt":1580642625751,"mc":[{"id":"1.168135803","rc":[{"batl":[[0,1.58,433.94]],"ltp":1.7,"tv":4526.59,"id":2249229}]}]}
{"op":"mcm","clk":"1005427444","pt":1580642632759,"mc":[{"id":"1.168135803","rc":[{"batb":[[0,1.44,9.02],[1,1.39,183.36],[2,1.34,27.28]],"batl":[[0,1.7,1.09],[1,1.88,186.52],[2,1.7,0]],"ltp":1.7,"tv":4526.59,"id":2249229}]}]}
{"op":"mcm","clk":"1005428000","pt":1580642635802,"mc":[{"id":"1.168135803","rc":[{"batb":[[1,1.43,349.05],[2,1.42,501.84]],"batl":[[0,1.65,336.37],[1,1.66,269.58],[2,1.7,1.09]],"ltp":1.7,"tv":4526.59,"id":2249229}]}]}
{"op":"mcm","clk":"1005428331","pt":1580642637771,"mc":[{"id":"1.168135803","rc":[{"trd":[[1.65,20.85]],"batl":[[0,1.65,315.97]],"ltp":1.65,"tv":4546.99,"id":2249229},{"trd":[[2.52,13.36]],"ltp":2.52,"tv":3121.14,"id":5720747}],"tv":7668.14}]}
{"op":"mcm","clk":"1005428923","pt":1580642640813,"mc":[{"id":"1.168135803","rc":[{"batb":[[0,2.54,113.53],[1,1.95,690.02],[2,1.5,27.45]],"ltp":2.52,"tv":3121.14,"id":5720747}]}]}
{"op":"mcm","clk":"1005429111","pt":1580642641777,"mc":[{"id":"1.168135803","rc":[{"batb":[[0,1.44,406.36]],"ltp":1.65,"tv":4546.99,"id":2249229},{"batb":[[0,2.54,227.05]],"ltp":2.52,"tv":3121.14,"id":5720747}]}]}
{"op":"mcm","clk":"1005429335","pt":1580642642750,"mc":[{"id":"1.168135803","rc":[{"batb":[[0,1.45,388.53],[1,1.44,406.34],[2,1.43,349.05]],"ltp":1.65,"tv":4546.99,"id":2249229}]}]}
{"op":"mcm","clk":"1005430476","pt":1580642648752,"mc":[{"id":"1.168135803","rc":[{"batb":[[0,1.46,4.25],[1,1.45,388.51],[2,1.44,406.34]],"ltp":1.65,"tv":4546.99,"id":2249229}]}]}
{"op":"mcm","clk":"1005431263","pt":1580642652756,"mc":[{"id":"1.168135803","rc":[{"batb":[[0,1.47,1260.31],[1,1.46,4.23],[2,1.45,388.51]],"ltp":1.65,"tv":4546.99,"id":2249229}]}]}
{"op":"mcm","clk":"1005432328","pt":1580642657798,"mc":[{"id":"1.168135803","rc":[{"batl":[[0,3.1,2],[1,3.2,0.31]],"ltp":2.52,"tv":3121.14,"id":5720747}]}]}
{"op":"mcm","clk":"1005432738","pt":1580642659792,"mc":[{"id":"1.168135803","rc":[{"batb":[[0,1.46,4.25],[1,1.45,388.51],[2,1.44,406.34]],"ltp":1.65,"tv":4546.99,"id":2249229}]}]}
{"op":"mcm","clk":"1005433149","pt":1580642661792,"mc":[{"id":"1.168135803","rc":[{"trd":[[2.54,24]],"batb":[[0,2.54,217.05]],"ltp":2.54,"tv":3141.14,"id":5720747}],"tv":7688.14}]}
{"op":"mcm","clk":"1005433586","pt":1580642663778,"mc":[{"id":"1.168135803","rc":[{"batl":[[0,3.2,0.31],[1,3.2,0]],"ltp":2.54,"tv":3141.14,"id":5720747}]}]}
{"op":"mcm","clk":"1005434396","pt":1580642667804,"mc":[{"id":"1.168135803","rc":[{"batb":[[0,1.56,16.28],[1,1.46,4.25],[2,1.45,388.51]],"ltp":1.65,"tv":4546.99,"id":2249229},{"batl":[[0,3,2],[1,3.2,0.31]],"ltp":2.54,"tv":3141.14,"id":5720747}]}]}
{"op":"mcm","clk":"1005434592","pt":1580642668680,"mc":[{"id":"1.168135803","rc":[{"batl":[[1,3.05,3],[2,3.2,0.31]],"ltp":2.54,"tv":3141.14,"id":5720747}]}]}
{"op":"mcm","clk":"1005434969","pt":1580642670806,"mc":[{"id":"1.168135803","rc":[{"trd":[[1.56,50.4]],"batb":[[0,1.56,11.07]],"ltp":1.56,"tv":4557.41,"id":2249229}],"tv":7698.56}]}
{"op":"mcm","clk":"1005436240","pt":1580642677722,"mc":[{"id":"1.168135803","rc":[{"batl":[[0,1.7,1.09],[1,1.88,186.52],[2,1.7,0]],"ltp":1.56,"tv":4557.41,"id":2249229},{"batl":[[1,3.2,0.31],[2,3.2,0]],"ltp":2.54,"tv":3141.14,"id":5720747}]}]}
{"op":"mcm","clk":"1005436871","pt":1580642680727,"mc":[{"id":"1.168135803","rc":[{"trd":[[1.56,72.54]],"batb":[[0,1.46,4.25],[1,1.45,388.51],[2,1.44,406.34]],"ltp":1.56,"tv":4579.56,"id":2249229},{"batl":[[0,2.92,3],[1,3,2],[2,3.2,0.31]],"ltp":2.54,"tv":3141.14,"id":5720747}],"tv":7720.7}]}
{"op":"mcm","clk":"1005437067","pt":1580642681818,"mc":[{"id":"1.168135803","rc":[{"batb":[[1,1.5,27.45],[2,1.25,45.45]],"ltp":2.54,"tv":3141.14,"id":5720747}]}]}
{"op":"mcm","clk":"1005437391","pt":1580642683521,"mc":[{"id":"1.168135803","rc":[{"batl":[[0,1.65,330.68],[1,1.66,269.59],[2,1.7,1.09]],"ltp":1.56,"tv":4579.56,"id":2249229}]}]}
{"op":"mcm","clk":"1005437594","pt":1580642684734,"mc":[{"id":"1.168135803","rc":[{"trd":[[1.65,21.4]],"batl":[[0,1.65,330.41]],"ltp":1.65,"tv":4580.1,"id":2249229},{"batb":[[1,2.08,672.17],[2,1.5,27.45]],"ltp":2.54,"tv":3141.14,"id":5720747}],"tv":7721.25}]}
{"op":"mcm","clk":"1005438106","pt":1580642687711,"mc":[{"id":"1.168135803","rc":[{"batl":[[0,3,2],[1,3.2,0.31],[2,3.2,0]],"ltp":2.54,"tv":3141.14,"id":5720747}]}]}
{"op":"mcm","clk":"1005438258","pt":1580642688650,"mc":[{"id":"1.168135803","rc":[{"batl":[[0,1.7,1.09],[1,1.88,186.52],[2,1.7,0]],"ltp":1.65,"tv":4580.1,"id":2249229}]}]}
{"op":"mcm","clk":"1005438418","pt":1580642689558,"mc":[{"id":"1.168135803","rc":[{"batb":[[1,1.5,27.45],[2,1.25,45.45]],"ltp":2.54,"tv":3141.14,"id":5720747}]}]}
{"op":"mcm","clk":"1005438636","pt":1580642690652,"mc":[{"id":"1.168135803","rc":[{"batl":[[0,2.9,3],[1,3,2],[2,3.2,0.31]],"ltp":2.54,"tv":3141.14,"id":5720747}]}]}
{"op":"mcm","clk":"1005438827","pt":1580642691764,"mc":[{"id":"1.168135803","rc":[{"trd":[[2.54,24.06]],"batb":[[0,2.54,217.02]],"ltp":2.54,"tv":3141.2,"id":5720747}],"tv":7721.31}]}
{"op":"mcm","clk":"1005439728","pt":1580642696753,"mc":[{"id":"1.168135803","rc":[{"batl":[[0,1.56,7.07],[1,1.7,1.09],[2,1.88,186.52]],"ltp":1.65,"tv":4580.1,"id":2249229}]}]}
{"op":"mcm","clk":"1005440309","pt":1580642699744,"mc":[{"id":"1.168135803","rc":[{"trd":[[1.52,5.74]],"batl":[[0,1.52,166.09],[1,1.56,7.07],[2,1.65,318.25]],"ltp":1.52,"tv":4585.83,"id":2249229},{"trd":[[2.9,3]],"batl":[[0,3,2],[1,3.2,0.31],[2,3.2,0]],"ltp":2.9,"tv":3144.2,"id":5720747}],"tv":7730.04}]}
{"op":"mcm","clk":"1005441237","pt":1580642704768,"mc":[{"id":"1.168135803","rc":[{"batl":[[1,1.65,318.25],[2,1.66,269.58]],"ltp":1.52,"tv":4585.83,"id":2249229},{"batb":[[1,2,683.9],[2,1.5,27.45]],"ltp":2.9,"tv":3144.2,"id":5720747}]}]}
{"op":"mcm","clk":"1005441797","pt":1580642707655,"mc":[{"id":"1.168135803","rc":[{"batl":[[0,3.2,0.31],[1,3.2,0]],"ltp":2.9,"tv":3144.2,"id":5720747}]}]}
{"op":"mcm","clk":"1005442400","pt":1580642710686,"mc":[{"id":"1.168135803","rc":[{"trd":[[1.52,9.58]],"batl":[[0,1.52,162.25]],"ltp":1.52,"tv":4589.67,"id":2249229},{"trd":[[2.92,2]],"ltp":2.92,"tv":3146.2,"id":5720747}],"tv":7735.88}]}
{"op":"mcm","clk":"1005442609","pt":1580642711812,"mc":[{"id":"1.168135803","rc":[{"trd":[[1.52,14.41]],"batl":[[0,1.52,157.41]],"ltp":1.52,"tv":4594.51,"id":2249229},{"trd":[[2.92,4.52]],"ltp":2.92,"tv":3148.72,"id":5720747}],"tv":7743.24}]}
{"op":"mcm","clk":"1005443006","pt":1580642713765,"mc":[{"id":"1.168135803","rc":[{"batb":[[0,2,683.9],[1,1.5,27.45],[2,1.25,45.45]],"ltp":2.92,"tv":3148.72,"id":5720747}]}]}
{"op":"mcm","clk":"1005443334","pt":1580642715771,"mc":[{"id":"1.168135803","rc":[{"trd":[[1.52,329.24]],"batb":[[0,1.59,565.01],[1,1.58,325.55],[2,1.56,63.14]],"batl":[[0,1.65,318.25],[1,1.66,269.58],[2,1.7,1.09]],"ltp":1.52,"tv":4909.33,"id":2249229}],"tv":8058.06}]}
{"op":"mcm","clk":"1005443485","pt":1580642716772,"mc":[{"id":"1.168135803","rc":[{"batb":[[2,1.53,94.33]],"ltp":1.52,"tv":4909.33,"id":2249229},{"batl":[[0,2.86,37.86],[1,3.2,0.31]],"ltp":2.92,"tv":3148.72,"id":5720747}]}]}
{"op":"mcm","clk":"1005443654","pt":1580642717779,"mc":[{"id":"1.168135803","rc":[{"batl":[[0,3.2,0.31],[1,3.2,0]],"ltp":2.92,"tv":3148.72,"id":5720747}]}]}
{"op":"mcm","clk":"1005443988","pt":1580642719795,"mc":[{"id":"1.168135803","rc":[{"trd":[[1.59,405.01]],"batb":[[0,1.59,414.52],[2,1.46,4.25]],"ltp":1.59,"tv":5210.31,"id":2249229}],"tv":8359.04}]}
{"op":"mcm","clk":"1005444359","pt":1580642721786,"mc":[{"id":"1.168135803","rc":[{"batb":[[2,1.54,323.76]],"ltp":1.59,"tv":5210.31,"id":2249229}]}]}
{"op":"mcm","clk":"1005444850","pt":1580642724695,"mc":[{"id":"1.168135803","rc":[{"batb":[[0,1.59,522.23]],"ltp":1.59,"tv":5210.31,"id":2249229}]}]}
{"op":"mcm","clk":"1005445060","pt":1580642725809,"mc":[{"id":"1.168135803","rc":[{"batb":[[0,2.3,134.49],[1,2,683.9],[2,1.5,27.45]],"ltp":2.92,"tv":3148.72,"id":5720747}]}]}
{"op":"mcm","clk":"1005445419","pt":1580642727705,"mc":[{"id":"1.168135803","rc":[{"batb":[[0,1.54,323.76],[1,1.5,349.66],[2,1.46,4.25]],"batl":[[0,1.7,1.09],[1,1.88,186.52],[2,1.7,0]],"ltp":1.59,"tv":5210.31,"id":2249229}]}]}
{"op":"mcm","clk":"1005445606","pt":1580642728710,"mc":[{"id":"1.168135803","rc":[{"batb":[[0,1.65,7],[1,1.54,323.76],[2,1.5,349.66]],"ltp":1.59,"tv":5210.31,"id":2249229}]}]}
{"op":"mcm","clk":"1005446154","pt":1580642731815,"mc":[{"id":"1.168135803","rc":[{"batb":[[2,1.5,991.86]],"batl":[[1,1.71,323.27],[2,1.73,471.29]],"ltp":1.59,"tv":5210.31,"id":2249229}]}]}
{"op":"mcm","clk":"1005446536","pt":1580642733805,"mc":[{"id":"1.168135803","rc":[{"batb":[[1,1.5,991.86],[2,1.49,410.87]],"ltp":1.59,"tv":5210.31,"id":2249229}]}]}
{"op":"mcm","clk":"1005446861","pt":1580642735785,"mc":[{"id":"1.168135803","rc":[{"batb":[[0,2,683.9],[1,1.5,27.45],[2,1.25,45.45]],"ltp":2.92,"tv":3148.72,"id":5720747}]}]}
{"op":"mcm","clk":"1005447233","pt":1580642737814,"mc":[{"id":"1.168135803","rc":[{"batb":[[1,1.51,342.81],[2,1.5,991.86]],"ltp":1.59,"tv":5210.31,"id":2249229}]}]}
{"op":"mcm","clk":"1005447408","pt":1580642738787,"mc":[{"id":"1.168135803","rc":[{"batb":[[1,1.51,440.84]],"ltp":1.59,"tv":5210.31,"id":2249229},{"batb":[[0,2.42,246.24],[1,2,683.9],[2,1.5,27.45]],"ltp":2.92,"tv":3148.72,"id":5720747}]}]}
{"op":"mcm","clk":"1005447934","pt":1580642741720,"mc":[{"id":"1.168135803","rc":[{"batb":[[1,1.51,342.81]],"ltp":1.59,"tv":5210.31,"id":2249229}]}]}
{"op":"mcm","clk":"1005448339","pt":1580642743795,"mc":[{"id":"1.168135803","rc":[{"batb":[[1,1.52,96.15],[2,1.51,342.81]],"ltp":1.59,"tv":5210.31,"id":2249229}]}]}
{"op":"mcm","clk":"1005448515","pt":1580642744784,"mc":[{"id":"1.168135803","rc":[{"trd":[[1.65,24.48]],"batb":[[0,1.65,3.92]],"ltp":1.65,"tv":5213.39,"id":2249229},{"trd":[[2.54,26.06]],"ltp":2.54,"tv":3150.72,"id":5720747}],"tv":8364.12}]}
{"op":"mcm","clk":"1005449097","pt":1580642747733,"mc":[{"id":"1.168135803","rc":[{"batb":[[0,2,683.9],[1,1.5,27.45],[2,1.25,45.45]],"ltp":2.54,"tv":3150.72,"id":5720747}]}]}
{"op":"mcm","clk":"1005449287","pt":1580642748742,"mc":[{"id":"1.168135803","rc":[{"batb":[[0,1.65,566.63],[1,1.64,283.16],[2,1.52,96.15]],"ltp":1.65,"tv":5213.39,"id":2249229},{"batl":[[0,2.5,2],[1,3.2,0.31]],"ltp":2.54,"tv":3150.72,"id":5720747}]}]}
{"op":"mcm","clk":"1005450197","pt":1580642753727,"mc":[{"id":"1.168135803","rc":[{"batb":[[0,1.65,376.62],[2,1.46,4.25]],"ltp":1.65,"tv":5213.39,"id":2249229}]}]}
{"op":"mcm","clk":"1005450570","pt":1580642755712,"mc":[{"id":"1.168135803","rc":[{"batl":[[0,3.2,0.31],[1,3.2,0]],"ltp":2.54,"tv":3150.72,"id":5720747}]}]}
{"op":"mcm","clk":"1005450783","pt":1580642756741,"mc":[{"id":"1.168135803","rc":[{"batb":[[2,1.57,306.72]],"ltp":1.65,"tv":5213.39,"id":2249229}]}]}
{"op":"mcm","clk":"1005451203","pt":1580642758727,"mc":[{"id":"1.168135803","rc":[{"trd":[[1.7,910.6],[1.71,15.8]],"batl":[[0,1.71,321.54],[1,1.73,471.29],[2,1.88,186.52]],"ltp":1.71,"tv":5216.21,"id":2249229},{"trd":[[2.4,243.19],[2.42,3.29]],"batb":[[0,2.24,140.99],[1,2,683.9],[2,1.5,27.45]],"ltp":2.4,"tv":3152.72,"id":5720747}],"tv":8368.94}]}
{"op":"mcm","clk":"1005451586","pt":1580642760780,"mc":[{"id":"1.168135803","rc":[{"batb":[[0,1.65,3.92],[1,1.57,306.72],[2,1.46,4.25]],"batl":[[0,1.88,186.52],[1,1.73,0],[2,1.88,0]],"ltp":1.71,"tv":5216.21,"id":2249229}]}]}
{"op":"mcm","clk":"1005452179","pt":1580642763737,"mc":[{"id":"1.168135803","rc":[{"batb":[[1,1.58,583.67],[2,1.57,640.49]],"batl":[[0,1.75,260.34],[1,1.77,437.2],[2,1.88,186.52]],"ltp":1.71,"tv":5216.21,"id":2249229}]}]}
{"op":"mcm","clk":"1005453276","pt":1580642769737,"mc":[{"id":"1.168135803","rc":[{"batb":[[0,2,683.9],[1,1.5,27.45],[2,1.25,45.45]],"ltp":2.4,"tv":3152.72,"id":5720747}]}]}
{"op":"mcm","clk":"1005453638","pt":1580642771744,"mc":[{"id":"1.168135803","rc":[{"batb":[[0,2.34,260.94],[1,2,683.9],[2,1.5,27.45]],"ltp":2.4,"tv":3152.72,"id":5720747}]}]}
{"op":"mcm","clk":"1005453873","pt":1580642772746,"mc":[{"id":"1.168135803","rc":[{"batb":[[2,1.57,333.77]],"batl":[[0,1.74,50],[1,1.75,260.34],[2,1.77,437.2]],"ltp":1.71,"tv":5216.21,"id":2249229}]}]}
{"op":"mcm","clk":"1005454226","pt":1580642774630,"mc":[{"id":"1.168135803","rc":[{"batb":[[1,1.6,291.39],[2,1.59,296.32]],"ltp":1.71,"tv":5216.21,"id":2249229}]}]}
{"op":"mcm","clk":"1005454397","pt":1580642775750,"mc":[{"id":"1.168135803","rc":[{"batl":[[1,1.88,186.52],[2,1.77,0]],"ltp":1.71,"tv":5216.21,"id":2249229}]}]}
{"op":"mcm","clk":"1005455219","pt":1580642780244,"mc":[{"id":"1.168135803","rc":[{"batb":[[1,1.61,81.96],[2,1.6,291.39]],"ltp":1.71,"tv":5216.21,"id":2249229}]}]}
{"op":"mcm","clk":"1005455769","pt":1580642783337,"mc":[{"id":"1.168135803","rc":[{"batl":[[1,1.75,257.03],[2,1.77,437.21]],"ltp":1.71,"tv":5216.21,"id":2249229}]}]}
{"op":"mcm","clk":"1005455961","pt":1580642784347,"mc":[{"id":"1.168135803","rc":[{"trd":[[1.65,28.4]],"batb":[[0,1.61,81.96],[1,1.6,291.39],[2,1.59,296.32]],"ltp":1.65,"tv":5220.13,"id":2249229},{"trd":[[2.54,28.61]],"batb":[[0,2.34,261.69]],"ltp":2.54,"tv":3155.27,"id":5720747}],"tv":8375.41}]}
{"op":"mcm","clk":"1005457327","pt":1580642790747,"mc":[{"id":"1.168135803","rc":[{"batb":[[0,2.34,260.94]],"ltp":2.54,"tv":3155.27,"id":5720747}]}]}
{"op":"mcm","clk":"1005458296","pt":1580642795647,"mc":[{"id":"1.168135803","rc":[{"batb":[[0,1.6,291.39],[1,1.59,296.32],[2,1.58,587.34]],"batl":[[1,1.88,186.52],[2,1.77,0]],"ltp":1.65,"tv":5220.13,"id":2249229}]}]}
{"op":"mcm","clk":"1005458672","pt":1580642797654,"mc":[{"id":"1.168135803","rc":[{"batb":[[0,1.58,587.34],[1,1.57,333.78],[2,1.46,4.25]],"batl":[[0,1.66,123.51],[1,1.74,50],[2,1.88,186.52]],"ltp":1.65,"tv":5220.13,"id":2249229}]}]}
{"op":"mcm","clk":"1005458895","pt":1580642798772,"mc":[{"id":"1.168135803","rc":[{"batl":[[0,1.61,10],[1,1.64,331.66],[2,1.65,275.45]],"ltp":1.65,"tv":5220.13,"id":2249229}]}]}
{"op":"mcm","clk":"1005459088","pt":1580642799779,"mc":[{"id":"1.168135803","rc":[{"batb":[[0,2,683.9],[1,1.5,27.45],[2,1.25,45.45]],"ltp":2.54,"tv":3155.27,"id":5720747}]}]}
{"op":"mcm","clk":"1005461340","pt":1580642810806,"mc":[{"id":"1.168135803","rc":[{"trd":[[1.58,14.47]],"batb":[[0,1.46,4.25],[1,1.44,182.47],[2,1.25,27.28]],"batl":[[1,1.88,186.52],[2,1.65,0]],"ltp":1.58,"tv":5234.28,"id":2249229}],"tv":8389.56}]}
{"op":"mcm","clk":"1005462164","pt":1580642814788,"mc":[{"id":"1.168135803","rc":[{"batb":[[0,1.48,526.3],[1,1.47,433.79],[2,1.46,4.23]],"batl":[[1,1.72,474.58],[2,1.74,461.68]],"ltp":1.58,"tv":5234.28,"id":2249229}]}]}
{"op":"mcm","clk":"1005463334","pt":1580642820609,"mc":[{"id":"1.168135803","rc":[{"batb":[[0,1.49,458.84],[1,1.48,526.3],[2,1.47,433.79]],"ltp":1.58,"tv":5234.28,"id":2249229}]}]}
{"op":"mcm","clk":"1005463596","pt":1580642821808,"mc":[{"id":"1.168135803","rc":[{"batb":[[0,1.49,815.64]],"ltp":1.58,"tv":5234.28,"id":2249229}]}]}
{"op":"mcm","clk":"1005463794","pt":1580642822706,"mc":[{"id":"1.168135803","rc":[{"batl":[[1,1.71,50],[2,1.72,474.58]],"ltp":1.58,"tv":5234.28,"id":2249229},{"batb":[[0,2.42,123.12],[1,2.4,124.88],[2,2,683.9]],"ltp":2.54,"tv":3155.27,"id":5720747}]}]}
{"op":"mcm","clk":"1005464170","pt":1580642824719,"mc":[{"id":"1.168135803","rc":[{"batb":[[1,1.46,4.25],[2,1.44,182.47]],"batl":[[1,1.72,474.58],[2,1.74,461.68]],"ltp":1.58,"tv":5234.28,"id":2249229}]}]}
{"op":"mcm","clk":"1005464354","pt":1580642825801,"mc":[{"id":"1.168135803","rc":[{"batb":[[0,2,683.9],[1,1.5,27.45],[2,1.25,45.45]],"ltp":2.54,"tv":3155.27,"id":5720747}]}]}
{"op":"mcm","clk":"1005464512","pt":1580642826723,"mc":[{"id":"1.168135803","rc":[{"trd":[[1.61,15.9]],"batb":[[0,1.61,196.57],[1,1.49,815.64],[2,1.46,4.25]],"batl":[[0,1.72,474.58],[1,1.74,461.68],[2,1.88,186.52]],"ltp":1.61,"tv":5250.18,"id":2249229},{"trd":[[2.62,2.52]],"ltp":2.62,"tv":3157.8,"id":5720747}],"tv":8407.98}]}
{"op":"mcm","clk":"1005464709","pt":1580642827810,"mc":[{"id":"1.168135803","rc":[{"batb":[[0,1.65,463.3],[1,1.64,283.44],[2,1.61,196.57]],"batl":[[0,1.88,186.52],[1,1.74,0],[2,1.88,0]],"ltp":1.61,"tv":5250.18,"id":2249229}]}]}
{"op":"mcm","clk":"1005465252","pt":1580642830793,"mc":[{"id":"1.168135803","rc":[{"batl":[[0,1.71,263.57],[1,1.73,471.75],[2,1.88,186.52]],"ltp":1.61,"tv":5250.18,"id":2249229}]}]}
{"op":"mcm","clk":"1005465425","pt":1580642831808,"mc":[{"id":"1.168135803","rc":[{"batb":[[2,1.46,4.25]],"ltp":1.61,"tv":5250.18,"id":2249229}]}]}
{"op":"mcm","clk":"1005465912","pt":1580642834514,"mc":[{"id":"1.168135803","rc":[{"trd":[[1.65,39.91]],"batb":[[0,1.65,457.54]],"ltp":1.65,"tv":5261.7,"id":2249229}],"tv":8419.5}]}
{"op":"mcm","clk":"1005466713","pt":1580642838804,"mc":[{"id":"1.168135803","rc":[{"batb":[[2,1.57,306.72]],"ltp":1.65,"tv":5261.7,"id":2249229}]}]}
{"op":"mcm","clk":"1005466877","pt":1580642839804,"mc":[{"id":"1.168135803","rc":[{"batb":[[0,1.57,306.72],[1,1.46,4.25],[2,1.44,182.47]],"batl":[[0,1.88,186.52],[1,1.73,0],[2,1.88,0]],"ltp":1.65,"tv":5261.7,"id":2249229}]}]}
{"op":"mcm","clk":"1005467021","pt":1580642840816,"mc":[{"id":"1.168135803","rc":[{"batb":[[0,2.2,145.69],[1,2,683.9],[2,1.5,27.45]],"ltp":2.62,"tv":3157.8,"id":5720747}]}]}
{"op":"mcm","clk":"1005467358","pt":1580642842744,"mc":[{"id":"1.168135803","rc":[{"batb":[[0,1.59,432.63],[1,1.58,325.36],[2,1.57,306.72]],"batl":[[0,1.75,258.61],[1,1.77,436.3],[2,1.88,186.52]],"ltp":1.65,"tv":5261.7,"id":2249229}]}]}
{"op":"mcm","clk":"1005467552","pt":1580642843729,"mc":[{"id":"1.168135803","rc":[{"batb":[[1,1.58,411.56]],"ltp":1.65,"tv":5261.7,"id":2249229}]}]}
{"op":"mcm","clk":"1005467959","pt":1580642845816,"mc":[{"id":"1.168135803","rc":[{"batb":[[0,1.58,86.2],[1,1.46,4.25],[2,1.44,182.47]],"batl":[[2,1.83,50]],"ltp":1.65,"tv":5261.7,"id":2249229}]}]}
{"op":"mcm","clk":"1005468355","pt":1580642847756,"mc":[{"id":"1.168135803","rc":[{"batb":[[0,1.6,291.39],[1,1.58,86.2],[2,1.46,4.25]],"ltp":1.65,"tv":5261.7,"id":2249229}]}]}
{"op":"mcm","clk":"1005468532","pt":1580642848626,"mc":[{"id":"1.168135803","rc":[{"batb":[[0,1.69,334.02],[1,1.68,259.83],[2,1.6,582.77]],"ltp":1.65,"tv":5261.7,"id":2249229},{"batb":[[0,2,683.9],[1,1.5,27.45],[2,1.25,45.45]],"ltp":2.62,"tv":3157.8,"id":5720747}]}]}
{"op":"mcm","clk":"1005468744","pt":1580642849735,"mc":[{"id":"1.168135803","rc":[{"batl":[[2,1.88,186.52]],"ltp":1.65,"tv":5261.7,"id":2249229}]}]}
{"op":"mcm","clk":"1005469493","pt":1580642853623,"mc":[{"id":"1.168135803","rc":[{"batb":[[2,1.46,4.25]],"ltp":1.65,"tv":5261.7,"id":2249229}]}]}
{"op":"mcm","clk":"1005470821","pt":1580642860764,"mc":[{"id":"1.168135803","rc":[{"batl":[[0,1.88,186.52],[1,1.77,0],[2,1.88,0]],"ltp":1.65,"tv":5261.7,"id":2249229}]}]}
{"op":"mcm","clk":"1005471000","pt":1580642861721,"mc":[{"id":"1.168135803","rc":[{"batb":[[0,1.46,4.25],[1,1.44,182.47],[2,1.25,27.28]],"ltp":1.65,"tv":5261.7,"id":2249229}]}]}
{"op":"mcm","clk":"1005471534","pt":1580642864747,"mc":[{"id":"1.168135803","rc":[{"batb":[[0,1.61,420.62],[1,1.6,310.57],[2,1.46,4.25]],"batl":[[1,1.94,273.06],[2,1.96,316.96]],"ltp":1.65,"tv":5261.7,"id":2249229}]}]}
{"op":"mcm","clk":"1005472947","pt":1580642871807,"mc":[{"id":"1.168135803","rc":[{"batb":[[0,1.7,3.79],[1,1.61,420.62],[2,1.6,310.57]],"ltp":1.65,"tv":5261.7,"id":2249229}]}]}
{"op":"mcm","clk":"1005473692","pt":1580642875791,"mc":[{"id":"1.168135803","rc":[{"batb":[[1,1.62,80.64],[2,1.61,420.62]],"ltp":1.65,"tv":5261.7,"id":2249229}]}]}
{"op":"mcm","clk":"1005474232","pt":1580642878787,"mc":[{"id":"1.168135803","rc":[{"batl":[[1,1.93,50],[2,1.94,273.06]],"ltp":1.65,"tv":5261.7,"id":2249229}]}]}
{"op":"mcm","clk":"1005474923","pt":1580642882719,"mc":[{"id":"1.168135803","rc":[{"batl":[[2,1.94,0]],"ltp":1.65,"tv":5261.7,"id":2249229}]}]}
{"op":"mcm","clk":"1005475425","pt":1580642885774,"mc":[{"id":"1.168135803","rc":[{"trd":[[1.7,918.17]],"batb":[[0,1.62,80.64],[1,1.61,420.62],[2,1.6,310.57]],"batl":[[0,1.67,395.87],[1,1.69,510.36],[2,1.7,119.72]],"ltp":1.7,"tv":5269.27,"id":2249229}],"tv":8427.07}]}
{"op":"mcm","clk":"1005475572","pt":1580642886820,"mc":[{"id":"1.168135803","rc":[{"batb":[[0,1.61,420.62],[1,1.6,310.57],[2,1.46,4.25]],"ltp":1.7,"tv":5269.27,"id":2249229}]}]}
{"op":"mcm","clk":"1005476114","pt":1580642889810,"mc":[{"id":"1.168135803","rc":[{"trd":[[1.67,615.29]],"batl":[[0,1.67,391.37]],"ltp":1.67,"tv":5273.77,"id":2249229},{"trd":[[2.48,206.06]],"ltp":2.48,"tv":3160.82,"id":5720747}],"tv":8434.6}]}
{"op":"mcm","clk":"1005476271","pt":1580642890792,"mc":[{"id":"1.168135803","rc":[{"batl":[[2,1.88,186.52]],"ltp":1.67,"tv":5273.77,"id":2249229},{"batb":[[1,1.25,45.64],[2,1.05,16.8]],"ltp":2.48,"tv":3160.82,"id":5720747}]}]}
{"op":"mcm","clk":"1005476791","pt":1580642893777,"mc":[{"id":"1.168135803","rc":[{"trd":[[1.67,623.01]],"batb":[[2,1.5,349.66]],"batl":[[0,1.67,387.51]],"ltp":1.67,"tv":5281.49,"id":2249229}],"tv":8442.32}]}
{"op":"mcm","clk":"1005476972","pt":1580642894792,"mc":[{"id":"1.168135803","rc":[{"batl":[[0,1.62,8.4],[1,1.67,387.51],[2,1.69,510.36]],"ltp":1.67,"tv":5281.49,"id":2249229}]}]}
{"op":"mcm","clk":"1005477147","pt":1580642895809,"mc":[{"id":"1.168135803","rc":[{"batb":[[0,2.2,145.69],[1,2,683.9],[2,1.25,45.64]],"ltp":2.48,"tv":3160.82,"id":5720747}]}]}
{"op":"mcm","clk":"1005477321","pt":1580642896811,"mc":[{"id":"1.168135803","rc":[{"batb":[[2,1.25,29.74]],"ltp":2.48,"tv":3160.82,"id":5720747}]}]}
{"op":"mcm","clk":"1005477480","pt":1580642897820,"mc":[{"id":"1.168135803","rc":[{"trd":[[1.62,22.2],[1.67,653.49]],"batb":[[0,1.5,349.66],[1,1.46,4.25],[2,1.44,182.47]],"batl":[[0,1.88,186.52],[1,1.67,0],[2,1.69,0]],"ltp":1.67,"tv":5328.77,"id":2249229}],"tv":8489.6}]}
{"op":"mcm","clk":"1005478185","pt":1580642901814,"mc":[{"id":"1.168135803","rc":[{"batb":[[0,1.56,330.98],[1,1.55,350.2],[2,1.5,349.66]],"batl":[[0,1.79,275.81],[1,1.81,406.57],[2,1.88,186.52]],"ltp":1.67,"tv":5328.77,"id":2249229}]}]}
{"op":"mcm","clk":"1005478402","pt":1580642902820,"mc":[{"id":"1.168135803","rc":[{"batb":[[0,1.5,349.66],[1,1.46,4.25],[2,1.44,182.47]],"ltp":1.67,"tv":5328.77,"id":2249229}]}]}
{"op":"mcm","clk":"1005478787","pt":1580642904723,"mc":[{"id":"1.168135803","rc":[{"trd":[[1.61,80.41]],"batb":[[0,1.72,402.21],[1,1.7,495.83],[2,1.51,98.03]],"ltp":1.61,"tv":5393.28,"id":2249229},{"trd":[[2.64,39.34]],"ltp":2.64,"tv":3200.16,"id":5720747}],"tv":8593.45}]}
{"op":"mcm","clk":"1005478962","pt":1580642905813,"mc":[{"id":"1.168135803","rc":[{"batb":[[2,1.66,5.06]],"ltp":1.61,"tv":5393.28,"id":2249229},{"batb":[[1,1.25,29.74],[2,1.05,16.8]],"ltp":2.64,"tv":3200.16,"id":5720747}]}]}
{"op":"mcm","clk":"1005479108","pt":1580642906728,"mc":[{"id":"1.168135803","rc":[{"batb":[[2,1.51,98.03]],"ltp":1.61,"tv":5393.28,"id":2249229},{"batb":[[0,1.25,29.74],[1,1.05,16.8],[2,1.04,21]],"ltp":2.64,"tv":3200.16,"id":5720747}]}]}
{"op":"mcm","clk":"1005479450","pt":1580642908802,"mc":[{"id":"1.168135803","rc":[{"batb":[[0,1.72,332.49],[2,1.62,80.64]],"ltp":1.61,"tv":5393.28,"id":2249229},{"batb":[[0,1.8,721.3],[1,1.25,29.55],[2,1.05,16.8]],"ltp":2.64,"tv":3200.16,"id":5720747}]}]}
{"op":"mcm","clk":"1005479786","pt":1580642910818,"mc":[{"id":"1.168135803","rc":[{"batb":[[2,1.51,98.03]],"batl":[[0,1.79,339]],"ltp":1.61,"tv":5393.28,"id":2249229}]}]}
{"op":"mcm","clk":"1005479948","pt":1580642911820,"mc":[{"id":"1.168135803","rc":[{"batb":[[2,1.6,291.39]],"ltp":1.61,"tv":5393.28,"id":2249229}]}]}
{"op":"mcm","clk":"1005480089","pt":1580642912726,"mc":[{"id":"1.168135803","rc":[{"batl":[[0,1.79,421.13]],"ltp":1.61,"tv":5393.28,"id":2249229}]}]}
{"op":"mcm","clk":"1005480897","pt":1580642917613,"mc":[{"id":"1.168135803","rc":[{"batb":[[0,1.6,291.39],[1,1.48,176.83],[2,1.46,4.23]],"batl":[[0,1.88,186.52],[1,1.81,0],[2,1.88,0]],"ltp":1.61,"tv":5393.28,"id":2249229},{"batl":[[0,2.26,2],[1,3.2,0.31]],"ltp":2.64,"tv":3200.16,"id":5720747}]}]}
{"op":"mcm","clk":"1005481383","pt":1580642920746,"mc":[{"id":"1.168135803","rc":[{"batb":[[0,1.61,534.15],[1,1.6,602.85],[2,1.48,176.83]],"batl":[[1,2.04,266.97],[2,2.06,273.42]],"ltp":1.61,"tv":5393.28,"id":2249229}]}]}
{"op":"mcm","clk":"1005481754","pt":1580642922638,"mc":[{"id":"1.168135803","rc":[{"batb":[[2,1.55,2.27]],"ltp":1.61,"tv":5393.28,"id":2249229}]}]}
{"op":"mcm","clk":"1005481935","pt":1580642923738,"mc":[{"id":"1.168135803","rc":[{"batb":[[1,1.6,311.46]],"ltp":1.61,"tv":5393.28,"id":2249229},{"batl":[[0,2.26,8.58]],"ltp":2.64,"tv":3200.16,"id":5720747}]}]}
{"op":"mcm","clk":"1005482096","pt":1580642924745,"mc":[{"id":"1.168135803","rc":[{"trd":[[1.79,15.1]],"batb":[[0,1.62,281.99],[1,1.61,534.15],[2,1.6,311.46]],"batl":[[0,1.72,67.83],[1,1.88,186.52],[2,2.04,266.97]],"ltp":1.79,"tv":5404.13,"id":2249229},{"trd":[[2.26,42.3]],"batl":[[0,3.2,0.31],[1,3.2,0]],"ltp":2.26,"tv":3208.75,"id":5720747}],"tv":8612.89}]}
{"op":"mcm","clk":"1005482453","pt":1580642926775,"mc":[{"id":"1.168135803","rc":[{"batb":[[0,1.62,563.97]],"ltp":1.79,"tv":5404.13,"id":2249229}]}]}
{"op":"mcm","clk":"1005482620","pt":1580642927737,"mc":[{"id":"1.168135803","rc":[{"batb":[[0,1.97,180.24],[1,1.8,721.3],[2,1.25,29.55]],"ltp":2.26,"tv":3208.75,"id":5720747}]}]}
{"op":"mcm","clk":"1005482816","pt":1580642928738,"mc":[{"id":"1.168135803","rc":[{"batb":[[0,1.97,360.48]],"ltp":2.26,"tv":3208.75,"id":5720747}]}]}
{"op":"mcm","clk":"1005483005","pt":1580642929752,"mc":[{"id":"1.168135803","rc":[{"trd":[[1.72,106.92]],"batl":[[0,1.72,65.07]],"ltp":1.72,"tv":5406.9,"id":2249229},{"trd":[[2.38,31.31]],"ltp":2.38,"tv":3210.75,"id":5720747}],"tv":8617.65}]}
{"op":"mcm","clk":"1005483179","pt":1580642930739,"mc":[{"id":"1.168135803","rc":[{"trd":[[1.72,120.76]],"batl":[[0,1.72,51.23],[2,2.04,0]],"ltp":1.72,"tv":5420.74,"id":2249229},{"trd":[[2.38,41.31]],"ltp":2.38,"tv":3220.75,"id":5720747}],"tv":8641.49}]}
{"op":"mcm","clk":"1005483341","pt":1580642931667,"mc":[{"id":"1.168135803","rc":[{"batb":[[0,1.61,534.15],[1,1.6,311.46],[2,1.55,2.27]],"ltp":1.72,"tv":5420.74,"id":2249229}]}]}
{"op":"mcm","clk":"1005483507","pt":1580642932629,"mc":[{"id":"1.168135803","rc":[{"batl":[[0,1.69,123.51],[1,1.72,51.23],[2,1.88,186.52]],"ltp":1.72,"tv":5420.74,"id":2249229}]}]}
{"op":"mcm","clk":"1005483690","pt":1580642933760,"mc":[{"id":"1.168135803","rc":[{"trd":[[1.67,656.85]],"batl":[[0,1.67,284.73],[1,1.68,259.65],[2,1.69,123.51]],"ltp":1.67,"tv":5424.1,"id":2249229}],"tv":8644.85}]}
{"op":"mcm","clk":"1005483840","pt":1580642934736,"mc":[{"id":"1.168135803","rc":[{"batb":[[1,1.25,29.74],[2,1.05,16.8]],"ltp":2.38,"tv":3220.75,"id":5720747}]}]}
{"op":"mcm","clk":"1005484011","pt":1580642935766,"mc":[{"id":"1.168135803","rc":[{"batb":[[0,1.25,29.74],[1,1.05,16.8],[2,1.04,21]],"ltp":2.38,"tv":3220.75,"id":5720747}]}]}
{"op":"mcm","clk":"1005484375","pt":1580642937802,"mc":[{"id":"1.168135803","rc":[{"batl":[[2,1.72,51.23]],"ltp":1.67,"tv":5424.1,"id":2249229}]}]}
{"op":"mcm","clk":"1005484749","pt":1580642939672,"mc":[{"id":"1.168135803","rc":[{"batb":[[0,1.95,692.09],[1,1.25,29.74],[2,1.05,16.8]],"ltp":2.38,"tv":3220.75,"id":5720747}]}]}
{"op":"mcm","clk":"1005485157","pt":1580642941768,"mc":[{"id":"1.168135803","rc":[{"batb":[[0,2.18,148.16],[1,1.95,692.09],[2,1.25,29.74]],"ltp":2.38,"tv":3220.75,"id":5720747}]}]}
{"op":"mcm","clk":"1005485343","pt":1580642942784,"mc":[{"id":"1.168135803","rc":[{"batb":[[2,1.55,320.15]],"ltp":1.67,"tv":5424.1,"id":2249229}]}]}
{"op":"mcm","clk":"1005485867","pt":1580642945573,"mc":[{"id":"1.168135803","rc":[{"batb":[[0,1.55,320.15],[1,1.46,4.25],[2,1.44,9]],"batl":[[0,1.72,51.23],[1,1.79,12.39],[2,1.88,186.52]],"ltp":1.67,"tv":5424.1,"id":2249229}]}]}
{"op":"mcm","clk":"1005486407","pt":1580642948657,"mc":[{"id":"1.168135803","rc":[{"batb":[[0,1.55,709.09],[1,1.54,360.13],[2,1.46,4.25]],"batl":[[2,1.83,377.24]],"ltp":1.67,"tv":5424.1,"id":2249229}]}]}
{"op":"mcm","clk":"1005487322","pt":1580642953805,"mc":[{"id":"1.168135803","rc":[{"batb":[[0,1.56,312.2],[1,1.55,709.09],[2,1.54,360.13]],"batl":[[1,1.83,377.24],[2,1.85,379.39]],"ltp":1.67,"tv":5424.1,"id":2249229}]}]}
{"op":"mcm","clk":"1005487460","pt":1580642954660,"mc":[{"id":"1.168135803","rc":[{"batb":[[1,1.55,320.15],[2,1.46,4.25]],"batl":[[1,1.88,186.52],[2,1.85,0]],"ltp":1.67,"tv":5424.1,"id":2249229}]}]}
{"op":"mcm","clk":"1005487668","pt":1580642955812,"mc":[{"id":"1.168135803","rc":[{"batb":[[0,1.95,692.09],[1,1.25,29.74],[2,1.05,16.8]],"ltp":2.38,"tv":3220.75,"id":5720747}]}]}
{"op":"mcm","clk":"1005487833","pt":1580642956786,"mc":[{"id":"1.168135803","rc":[{"trd":[[1.56,97.33]],"batb":[[0,1.64,411.98],[1,1.63,290.34],[2,1.56,299.8]],"batl":[[0,1.7,314.19],[1,1.72,533.04],[2,1.88,186.52]],"ltp":1.56,"tv":5448.88,"id":2249229},{"batb":[[0,2.22,286.61],[1,1.95,692.09],[2,1.25,29.74]],"ltp":2.38,"tv":3220.75,"id":5720747}],"tv":8669.64}]}
{"op":"mcm","clk":"1005488015","pt":1580642957799,"mc":[{"id":"1.168135803","rc":[{"batb":[[0,1.56,299.8],[1,1.55,320.15],[2,1.46,4.25]],"batl":[[0,1.72,51.23],[1,1.88,186.52],[2,1.88,0]],"ltp":1.56,"tv":5448.88,"id":2249229}]}]}
{"op":"mcm","clk":"1005488711","pt":1580642961799,"mc":[{"id":"1.168135803","rc":[{"batb":[[0,1.57,87.71],[1,1.56,299.8],[2,1.55,709.09]],"batl":[[1,1.83,377.24],[2,1.85,379.39]],"ltp":1.56,"tv":5448.88,"id":2249229}]}]}
{"op":"mcm","clk":"1005489071","pt":1580642963806,"mc":[{"id":"1.168135803","rc":[{"batb":[[0,2.5,7.7],[1,2.22,286.61],[2,1.95,692.09]],"ltp":2.38,"tv":3220.75,"id":5720747}]}]}
{"op":"mcm","clk":"1005490500","pt":1580642971726,"mc":[{"id":"1.168135803","rc":[{"batb":[[0,1.56,299.8],[1,1.55,320.15],[2,1.46,4.25]],"ltp":1.56,"tv":5448.88,"id":2249229}]}]}
{"op":"mcm","clk":"1005490707","pt":1580642972754,"mc":[{"id":"1.168135803","rc":[{"batb":[[0,1.95,692.09],[1,1.25,29.74],[2,1.05,16.8]],"ltp":2.38,"tv":3220.75,"id":5720747}]}]}
{"op":"mcm","clk":"1005490915","pt":1580642973731,"mc":[{"id":"1.168135803","rc":[{"trd":[[1.72,223.22]],"batb":[[0,1.76,213.67],[1,1.74,457.48],[2,1.56,299.8]],"batl":[[0,1.83,377.24],[1,1.85,379.39],[2,1.88,186.52]],"ltp":1.72,"tv":5551.34,"id":2249229}],"tv":8772.1}]}
{"op":"mcm","clk":"1005491053","pt":1580642974522,"mc":[{"id":"1.168135803","rc":[{"batb":[[0,1.56,299.8],[1,1.55,320.15],[2,1.46,4.25]],"batl":[[0,1.88,186.52],[1,1.85,0],[2,1.88,0]],"ltp":1.72,"tv":5551.34,"id":2249229}]}]}
{"op":"mcm","clk":"1005491620","pt":1580642977749,"mc":[{"id":"1.168135803","rc":[{"batb":[[0,1.75,397.58],[1,1.73,467.22],[2,1.56,299.8]],"batl":[[0,1.82,273.69],[1,1.84,386.43],[2,1.88,186.52]],"ltp":1.72,"tv":5551.34,"id":2249229}]}]}
{"op":"mcm","clk":"1005491782","pt":1580642978579,"mc":[{"id":"1.168135803","rc":[{"batb":[[0,1.75,322.36],[2,1.55,2.27]],"ltp":1.72,"tv":5551.34,"id":2249229}]}]}
{"op":"mcm","clk":"1005491993","pt":1580642979765,"mc":[{"id":"1.168135803","rc":[{"batl":[[0,1.76,10.94],[1,1.82,273.69],[2,1.84,386.43]],"ltp":1.72,"tv":5551.34,"id":2249229}]}]}
{"op":"mcm","clk":"1005492309","pt":1580642981776,"mc":[{"id":"1.168135803","rc":[{"batb":[[2,1.65,268.97]],"batl":[[1,1.82,387.9]],"ltp":1.72,"tv":5551.34,"id":2249229}]}]}
{"op":"mcm","clk":"1005492687","pt":1580642983769,"mc":[{"id":"1.168135803","rc":[{"batb":[[0,1.65,268.97],[1,1.55,2.27],[2,1.48,176.83]],"batl":[[1,1.88,186.52],[2,1.84,0]],"ltp":1.72,"tv":5551.34,"id":2249229}]}]}
{"op":"mcm","clk":"1005493233","pt":1580642986769,"mc":[{"id":"1.168135803","rc":[{"batb":[[0,1.97,180.24],[1,1.95,692.09],[2,1.25,29.74]],"ltp":2.38,"tv":3220.75,"id":5720747}]}]}
{"op":"mcm","clk":"1005493405","pt":1580642987786,"mc":[{"id":"1.168135803","rc":[{"batb":[[0,1.95,692.09],[1,1.25,29.74],[2,1.05,16.8]],"ltp":2.38,"tv":3220.75,"id":5720747}]}]}
{"op":"mcm","clk":"1005493786","pt":1580642989774,"mc":[{"id":"1.168135803","rc":[{"batb":[[1,1.6,294.98],[2,1.59,318.91]],"batl":[[2,2.22,335.03]],"ltp":1.72,"tv":5551.34,"id":2249229}]}]}
{"op":"mcm","clk":"1005493970","pt":1580642990779,"mc":[{"id":"1.168135803","rc":[{"batl":[[0,2.5,7.6],[1,3.2,0.31]],"ltp":2.38,"tv":3220.75,"id":5720747}]}]}
{"op":"mcm","clk":"1005494347","pt":1580642992747,"mc":[{"id":"1.168135803","rc":[{"batb":[[0,1.66,420.1],[1,1.65,268.97],[2,1.6,294.98]],"ltp":1.72,"tv":5551.34,"id":2249229}]}]}
{"op":"mcm","clk":"1005494518","pt":1580642993660,"mc":[{"id":"1.168135803","rc":[{"batb":[[1,1.62,840.19]],"ltp":1.72,"tv":5551.34,"id":2249229}]}]}
{"op":"mcm","clk":"1005494745","pt":1580642994770,"mc":[{"id":"1.168135803","rc":[{"batb":[[2,1.61,286.61]],"ltp":1.72,"tv":5551.34,"id":2249229}]}]}
{"op":"mcm","clk":"1005494928","pt":1580642995793,"mc":[{"id":"1.168135803","rc":[{"batb":[[1,1.62,1122.18]],"batl":[[1,2.22,335.03],[2,2.24,215.2]],"ltp":1.72,"tv":5551.34,"id":2249229}]}]}
{"op":"mcm","clk":"1005495132","pt":1580642996755,"mc":[{"id":"1.168135803","rc":[{"batb":[[0,1.67,840.19],[1,1.66,420.1],[2,1.62,1122.18]],"ltp":1.72,"tv":5551.34,"id":2249229}]}]}
{"op":"mcm","clk":"1005495507","pt":1580642998809,"mc":[{"id":"1.168135803","rc":[{"batl":[[1,2.22,0],[2,2.24,0]],"ltp":1.72,"tv":5551.34,"id":2249229}]}]}
{"op":"mcm","clk":"1005495668","pt":1580642999665,"mc":[{"id":"1.168135803","rc":[{"trd":[[1.76,77.58]],"batb":[[0,1.76,829.26],[1,1.67,840.19],[2,1.66,420.1]],"ltp":1.76,"tv":5573.22,"id":2249229}],"tv":8793.98}]}
{"op":"mcm","clk":"1005495860","pt":1580643000757,"mc":[{"id":"1.168135803","rc":[{"batb":[[0,1.67,840.19],[1,1.66,420.1],[2,1.63,277.51]],"ltp":1.76,"tv":5573.22,"id":2249229},{"batb":[[0,1.25,29.74],[1,1.05,16.8],[2,1.04,21]],"ltp":2.38,"tv":3220.75,"id":5720747}]}]}
{"op":"mcm","clk":"1005496058","pt":1580643001684,"mc":[{"id":"1.168135803","rc":[{"batl":[[0,2.2,130.23]],"ltp":1.76,"tv":5573.22,"id":2249229}]}]}
{"op":"mcm","clk":"1005496526","pt":1580643003808,"mc":[{"id":"1.168135803","rc":[{"batb":[[0,1.68,840.19],[1,1.67,840.19],[2,1.66,420.1]],"ltp":1.76,"tv":5573.22,"id":2249229}]}]}
{"op":"mcm","clk":"1005496720","pt":1580643004775,"mc":[{"id":"1.168135803","rc":[{"batl":[[1,2.22,220.48]],"ltp":1.76,"tv":5573.22,"id":2249229},{"batb":[[0,1.74,733.85],[1,1.25,29.55],[2,1.05,16.8]],"batl":[[0,2.3,8],[1,2.5,7.6],[2,3.2,0.31]],"ltp":2.38,"tv":3220.75,"id":5720747}]}]}
{"op":"mcm","clk":"1005497123","pt":1580643006806,"mc":[{"id":"1.168135803","rc":[{"batl":[[0,2.2,360.05]],"ltp":1.76,"tv":5573.22,"id":2249229},{"batl":[[1,2.36,10],[2,2.5,7.6]],"ltp":2.38,"tv":3220.75,"id":5720747}]}]}
{"op":"mcm","clk":"1005497336","pt":1580643007816,"mc":[{"id":"1.168135803","rc":[{"batl":[[0,2.18,840.19],[1,2.2,360.05],[2,2.22,220.48]],"ltp":1.76,"tv":5573.22,"id":2249229}]}]}
{"op":"mcm","clk":"1005497709","pt":1580643009818,"mc":[{"id":"1.168135803","rc":[{"batl":[[0,2.2,360.05],[1,2.22,220.48],[2,2.22,0]],"ltp":1.76,"tv":5573.22,"id":2249229},{"batb":[[0,1.84,208.32],[1,1.74,733.67],[2,1.25,29.55]],"batl":[[0,2.36,10],[1,2.5,7.6],[2,3.2,0.31]],"ltp":2.38,"tv":3220.75,"id":5720747}]}]}
{"op":"mcm","clk":"1005498099","pt":1580643011702,"mc":[{"id":"1.168135803","rc":[{"batl":[[0,2.2,130.23],[1,2.22,0]],"ltp":1.76,"tv":5573.22,"id":2249229}]}]}
{"op":"mcm","clk":"1005498270","pt":1580643012575,"mc":[{"id":"1.168135803","rc":[{"batb":[[0,1.91,840.19],[1,1.68,840.19],[2,1.67,840.19]],"ltp":1.76,"tv":5573.22,"id":2249229},{"batb":[[0,1.86,203.29],[1,1.84,208.32],[2,1.74,733.67]],"ltp":2.38,"tv":3220.75,"id":5720747}]}]}
{"op":"mcm","clk":"1005498509","pt":1580643013818,"mc":[{"id":"1.168135803","rc":[{"batb":[[1,1.84,840.19],[2,1.83,840.19]],"ltp":1.76,"tv":5573.22,"id":2249229},{"batb":[[0,1.74,733.85],[1,1.25,29.55],[2,1.05,16.8]],"ltp":2.38,"tv":3220.75,"id":5720747}]}]}
{"op":"mcm","clk":"1005498609","pt":1580643014453,"mc":[{"id":"1.168135803","rc":[{"batb":[[0,1.98,134.6],[1,1.91,840.19],[2,1.84,840.19]],"ltp":1.76,"tv":5573.22,"id":2249229}]}]}
{"op":"mcm","clk":"1005498816","pt":1580643015425,"mc":[{"id":"1.168135803","rc":[{"batb":[[0,1.83,341.29],[1,1.81,399.44],[2,1.25,29.55]],"batl":[[0,1.91,332.17],[1,1.93,330.91],[2,2.36,10]],"ltp":2.38,"tv":3220.75,"id":5720747}]}]}
{"op":"mcm","clk":"1005499228","pt":1580643017724,"mc":[{"id":"1.168135803","rc":[{"batb":[[0,1.25,29.74],[1,1.05,16.8],[2,1.04,21]],"batl":[[0,2.36,10],[1,2.5,7.6],[2,3.2,0.31]],"ltp":2.38,"tv":3220.75,"id":5720747}]}]}
{"op":"mcm","clk":"1005499426","pt":1580643018818,"mc":[{"id":"1.168135803","rc":[{"batb":[[0,1.56,788.04],[1,1.25,29.55],[2,1.05,16.8]],"ltp":2.38,"tv":3220.75,"id":5720747}]}]}
{"op":"mcm","clk":"1005499593","pt":1580643019727,"mc":[{"id":"1.168135803","rc":[{"batb":[[0,1.91,840.19],[1,1.84,840.19],[2,1.83,840.19]],"ltp":1.76,"tv":5573.22,"id":2249229},{"batl":[[1,3.2,0.31],[2,3.2,0]],"ltp":2.38,"tv":3220.75,"id":5720747}]}]}
{"op":"mcm","clk":"1005499782","pt":1580643020815,"mc":[{"id":"1.168135803","rc":[{"batb":[[0,1.84,311.06],[1,1.82,392.04],[2,1.56,787.85]],"batl":[[0,1.92,340.61],[1,1.94,325.54],[2,2.36,10]],"ltp":2.38,"tv":3220.75,"id":5720747}]}]}
{"op":"mcm","clk":"1005501109","pt":1580643027716,"mc":[{"id":"1.168135803","rc":[{"batb":[[0,1.56,788.04],[1,1.25,29.55],[2,1.05,16.8]],"batl":[[0,2.36,10],[1,3.2,0.31],[2,2.36,0]],"ltp":2.38,"tv":3220.75,"id":5720747}]}]}
{"op":"mcm","clk":"1005501712","pt":1580643030731,"mc":[{"id":"1.168135803","rc":[{"batb":[[1,1.38,713.9],[2,1.37,586.5]],"batl":[[0,2.36,317.93],[1,2.38,183.79],[2,3.2,0.31]],"ltp":2.38,"tv":3220.75,"id":5720747}]}]}
{"op":"mcm","clk":"1005501895","pt":1580643031734,"mc":[{"id":"1.168135803","rc":[{"batb":[[0,1.7,249.95],[1,1.56,787.85],[2,1.38,713.9]],"ltp":2.38,"tv":3220.75,"id":5720747}]}]}
{"op":"mcm","clk":"1005502086","pt":1580643032744,"mc":[{"id":"1.168135803","rc":[{"batl":[[0,2.08,46.21],[1,2.2,130.23]],"ltp":1.76,"tv":5573.22,"id":2249229}]}]}
{"op":"mcm","clk":"1005502280","pt":1580643033790,"mc":[{"id":"1.168135803","rc":[{"batb":[[0,1.56,788.04],[1,1.38,713.9],[2,1.37,586.5]],"ltp":2.38,"tv":3220.75,"id":5720747}]}]}
{"op":"mcm","clk":"1005503080","pt":1580643038780,"mc":[{"id":"1.168135803","rc":[{"batb":[[0,1.38,714.09],[1,1.37,586.5],[2,1.25,29.53]],"ltp":2.38,"tv":3220.75,"id":5720747}]}]}
{"op":"mcm","clk":"1005503406","pt":1580643040729,"mc":[{"id":"1.168135803","rc":[{"trd":[[1.85,0.38]],"batb":[[0,1.38,713.9]],"batl":[[0,1.84,49.81],[1,2.36,317.93],[2,2.38,183.79]],"ltp":1.85,"tv":3221.13,"id":5720747}],"tv":8794.36}]}
{"op":"mcm","clk":"1005503578","pt":1580643041759,"mc":[{"id":"1.168135803","rc":[{"batl":[[1,2.36,307.93]],"ltp":1.85,"tv":3221.13,"id":5720747}]}]}
{"op":"mcm","clk":"1005503741","pt":1580643042737,"mc":[{"id":"1.168135803","rc":[{"batl":[[0,2.36,307.93],[1,2.38,183.79],[2,3.2,0.31]],"ltp":1.85,"tv":3221.13,"id":5720747}]}]}
{"op":"mcm","clk":"1005504096","pt":1580643044755,"mc":[{"id":"1.168135803","rc":[{"batb":[[0,1.55,2.27],[1,1.46,4.25],[2,1.44,9]],"ltp":1.76,"tv":5573.22,"id":2249229}]}]}
{"op":"mcm","clk":"1005504253","pt":1580643045730,"mc":[{"id":"1.168135803","rc":[{"batl":[[0,1.92,7.57],[1,2.36,307.93],[2,2.38,183.79]],"ltp":1.85,"tv":3221.13,"id":5720747}]}]}
{"op":"mcm","clk":"1005506702","pt":1580643058726,"mc":[{"id":"1.168135803","rc":[{"batb":[[0,1.25,29.55],[1,1.05,16.8],[2,1.04,21]],"batl":[[1,3.2,0.31],[2,2.38,0]],"ltp":1.85,"tv":3221.13,"id":5720747}]}]}
{"op":"mcm","clk":"1005507327","pt":1580643061815,"mc":[{"id":"1.168135803","rc":[{"trd":[[2.08,6.99]],"batb":[[0,1.74,303.54],[1,1.72,477.4],[2,1.55,2.27]],"batl":[[0,1.81,389.31],[1,1.83,393.92],[2,1.87,124.92]],"ltp":2.08,"tv":5580.21,"id":2249229},{"trd":[[1.92,7.57]],"batl":[[0,3.2,0.31],[1,3.2,0]],"ltp":1.92,"tv":3228.7,"id":5720747}],"tv":8808.92}]}
{"op":"mcm","clk":"1005507509","pt":1580643062723,"mc":[{"id":"1.168135803","rc":[{"batl":[[2,1.87,0]],"ltp":2.08,"tv":5580.21,"id":2249229}]}]}
{"op":"mcm","clk":"1005507883","pt":1580643064802,"mc":[{"id":"1.168135803","rc":[{"batl":[[2,2.08,6.98]],"ltp":2.08,"tv":5580.21,"id":2249229},{"batb":[[0,1.8,721.11],[1,1.25,29.55],[2,1.05,16.8]],"ltp":1.92,"tv":3228.7,"id":5720747}]}]}
{"op":"mcm","clk":"1005508077","pt":1580643065813,"mc":[{"id":"1.168135803","rc":[{"trd":[[1.81,71.15]],"batl":[[0,1.81,381.28],[2,2.08,0]],"ltp":1.81,"tv":5596.28,"id":2249229}],"tv":8824.98}]}
{"op":"mcm","clk":"1005509527","pt":1580643073820,"mc":[{"id":"1.168135803","rc":[{"batb":[[0,1.55,2.27],[1,1.48,176.83],[2,1.46,4.23]],"ltp":1.81,"tv":5596.28,"id":2249229}]}]}
{"op":"mcm","clk":"1005510055","pt":1580643076803,"mc":[{"id":"1.168135803","rc":[{"batb":[[0,1.59,484.95],[1,1.58,327.92],[2,1.55,2.27]],"batl":[[0,2.2,201.72],[1,2.22,220.3]],"ltp":1.81,"tv":5596.28,"id":2249229}]}]}
{"op":"mcm","clk":"1005510606","pt":1580643079736,"mc":[{"id":"1.168135803","rc":[{"batl":[[0,2,186.52],[1,2.2,201.72],[2,2.22,220.3]],"ltp":1.81,"tv":5596.28,"id":2249229}]}]}
{"op":"mcm","clk":"1005511225","pt":1580643082807,"mc":[{"id":"1.168135803","rc":[{"batl":[[0,2.22,1.77],[1,3.2,0.31]],"ltp":1.92,"tv":3228.7,"id":5720747}]}]}
{"op":"mcm","clk":"1005512042","pt":1580643086729,"mc":[{"id":"1.168135803","rc":[{"batb":[[0,1.84,208.13],[1,1.8,721.11],[2,1.25,29.55]],"ltp":1.92,"tv":3228.7,"id":5720747}]}]}
{"op":"mcm","clk":"1005512950","pt":1580643091738,"mc":[{"id":"1.168135803","rc":[{"batb":[[0,1.55,2.27],[1,1.48,176.83],[2,1.46,4.23]],"ltp":1.81,"tv":5596.28,"id":2249229},{"batl":[[0,2,3],[1,2.22,1.77],[2,3.2,0.31]],"ltp":1.92,"tv":3228.7,"id":5720747}]}]}
{"op":"mcm","clk":"1005513289","pt":1580643093641,"mc":[{"id":"1.168135803","rc":[{"batb":[[1,1.46,4.25],[2,1.44,9]],"ltp":1.81,"tv":5596.28,"id":2249229},{"batb":[[1,1.25,29.55],[2,1.05,16.8]],"ltp":1.92,"tv":3228.7,"id":5720747}]}]}
{"op":"mcm","clk":"1005513504","pt":1580643094729,"mc":[{"id":"1.168135803","rc":[{"trd":[[1.81,73.32],[2,3]],"batl":[[0,1.71,126.74]],"ltp":1.81,"tv":5601.44,"id":2249229},{"trd":[[2,3],[2.22,310.14]],"batl":[[0,3.2,0.31],[1,2.22,0],[2,3.2,0]],"ltp":2.22,"tv":3233.47,"id":5720747}],"tv":8834.92}]}
{"op":"mcm","clk":"1005513694","pt":1580643095735,"mc":[{"id":"1.168135803","rc":[{"batb":[[0,1.59,479.03],[1,1.58,327.92],[2,1.55,2.27]],"batl":[[0,1.65,412.06],[1,1.66,271.71],[2,1.71,126.74]],"ltp":1.81,"tv":5601.44,"id":2249229},{"batb":[[0,1.25,29.55],[1,1.05,16.8],[2,1.04,21]],"ltp":2.22,"tv":3233.47,"id":5720747}]}]}
{"op":"mcm","clk":"1005514325","pt":1580643098727,"mc":[{"id":"1.168135803","rc":[{"batb":[[0,1.95,695.9],[1,1.25,29.55],[2,1.05,16.8]],"ltp":2.22,"tv":3233.47,"id":5720747}]}]}
{"op":"mcm","clk":"1005514502","pt":1580643099741,"mc":[{"id":"1.168135803","rc":[{"batl":[[2,2.18,130.23]],"ltp":1.81,"tv":5601.44,"id":2249229}]}]}
{"op":"mcm","clk":"1005514656","pt":1580643100623,"mc":[{"id":"1.168135803","rc":[{"batl":[[2,1.81,42.01]],"ltp":1.81,"tv":5601.44,"id":2249229}]}]}
{"op":"mcm","clk":"1005515771","pt":1580643106734,"mc":[{"id":"1.168135803","rc":[{"batb":[[0,1.55,2.27],[1,1.46,4.25],[2,1.44,9]],"batl":[[0,1.81,42.01],[1,2.18,130.23],[2,1.81,0]],"ltp":1.81,"tv":5601.44,"id":2249229}]}]}
{"op":"mcm","clk":"1005515977","pt":1580643107759,"mc":[{"id":"1.168135803","rc":[{"batb":[[0,1.65,3],[1,1.55,2.27],[2,1.46,4.25]],"ltp":1.81,"tv":5601.44,"id":2249229}]}]}
{"op":"mcm","clk":"1005516130","pt":1580643108775,"mc":[{"id":"1.168135803","rc":[{"batb":[[0,1.65,9.02]],"ltp":1.81,"tv":5601.44,"id":2249229}]}]}
{"op":"mcm","clk":"1005516500","pt":1580643110762,"mc":[{"id":"1.168135803","rc":[{"batb":[[2,1.52,480.06]],"batl":[[1,1.82,373.61],[2,1.84,387.15]],"ltp":1.81,"tv":5601.44,"id":2249229}]}]}
{"op":"mcm","clk":"1005517779","pt":1580643117760,"mc":[{"id":"1.168135803","rc":[{"batb":[[2,1.46,4.25]],"batl":[[1,2.18,130.23],[2,1.84,0]],"ltp":1.81,"tv":5601.44,"id":2249229},{"batb":[[0,2.22,143.3],[1,1.95,695.9],[2,1.25,29.55]],"ltp":2.22,"tv":3233.47,"id":5720747}]}]}
{"op":"mcm","clk":"1005518157","pt":1580643119740,"mc":[{"id":"1.168135803","rc":[{"batb":[[0,1.65,6.02],[2,1.54,323.76]],"ltp":1.81,"tv":5601.44,"id":2249229}]}]}
{"op":"mcm","clk":"1005518492","pt":1580643121666,"mc":[{"id":"1.168135803","rc":[{"batb":[[0,2.4,5.25],[1,2.22,143.3],[2,1.95,695.9]],"ltp":2.22,"tv":3233.47,"id":5720747}]}]}
{"op":"mcm","clk":"1005518693","pt":1580643122755,"mc":[{"id":"1.168135803","rc":[{"batb":[[1,1.58,3],[2,1.55,2.27]],"ltp":1.81,"tv":5601.44,"id":2249229}]}]}
{"op":"mcm","clk":"1005518884","pt":1580643123770,"mc":[{"id":"1.168135803","rc":[{"batl":[[1,1.82,373.61],[2,1.84,387.15]],"ltp":1.81,"tv":5601.44,"id":2249229}]}]}
{"op":"mcm","clk":"1005520122","pt":1580643130776,"mc":[{"id":"1.168135803","rc":[{"batl":[[0,2.52,298.07],[1,3.2,0.31]],"ltp":2.22,"tv":3233.47,"id":5720747}]}]}
{"op":"mcm","clk":"1005520633","pt":1580643133694,"mc":[{"id":"1.168135803","rc":[{"trd":[[2.4,249.19]],"batb":[[0,2.4,2.25]],"ltp":2.4,"tv":3239.47,"id":5720747}],"tv":8840.92}]}
{"op":"mcm","clk":"1005521056","pt":1580643136406,"mc":[{"id":"1.168135803","rc":[{"batb":[[1,1.55,2.27],[2,1.54,323.76]],"ltp":1.81,"tv":5601.44,"id":2249229}]}]}
{"op":"mcm","clk":"1005522578","pt":1580643144727,"mc":[{"id":"1.168135803","rc":[{"trd":[[1.65,96.58]],"batb":[[0,1.55,2.27],[1,1.54,323.76],[2,1.53,329.87]],"ltp":1.65,"tv":5658.11,"id":2249229},{"trd":[[2.52,42.62]],"batl":[[0,2.52,268.81]],"ltp":2.52,"tv":3268.73,"id":5720747}],"tv":8926.84}]}
{"op":"mcm","clk":"1005523838","pt":1580643151613,"mc":[{"id":"1.168135803","rc":[{"batl":[[1,2.18,130.23],[2,1.84,0]],"ltp":1.65,"tv":5658.11,"id":2249229}]}]}
{"op":"mcm","clk":"1005524383","pt":1580643154734,"mc":[{"id":"1.168135803","rc":[{"trd":[[1.65,507.11]],"batb":[[1,1.52,480.06],[2,1.51,391.16]],"batl":[[0,1.57,213.1],[1,1.58,325.24],[2,1.81,42.01]],"ltp":1.65,"tv":6068.64,"id":2249229},{"trd":[[2.52,311.43]],"batb":[[0,2.56,420.1],[1,2.4,2.25],[2,2.22,143.3]],"batl":[[0,3.2,0.31],[1,3.2,0]],"ltp":2.52,"tv":3537.54,"id":5720747}],"tv":9606.19}]}
{"op":"mcm","clk":"1005524919","pt":1580643157732,"mc":[{"id":"1.168135803","rc":[{"batb":[[2,1.95,695.9]],"ltp":2.52,"tv":3537.54,"id":5720747}]}]}
{"op":"mcm","clk":"1005525136","pt":1580643158725,"mc":[{"id":"1.168135803","rc":[{"batl":[[0,1.57,317.2]],"ltp":1.65,"tv":6068.64,"id":2249229}]}]}
{"op":"mcm","clk":"1005525380","pt":1580643159712,"mc":[{"id":"1.168135803","rc":[{"trd":[[1.57,554.54]],"batl":[[0,1.58,325.24],[1,1.81,42.01],[2,2.18,130.23]],"ltp":1.57,"tv":6623.19,"id":2249229}],"tv":10160.73}]}
{"op":"mcm","clk":"1005525987","pt":1580643162724,"mc":[{"id":"1.168135803","rc":[{"batb":[[1,1.52,604.56]],"batl":[[0,1.58,564.24],[1,1.59,316.38],[2,1.81,42.01]],"ltp":1.57,"tv":6623.19,"id":2249229}]}]}
{"op":"mcm","clk":"1005526373","pt":1580643164735,"mc":[{"id":"1.168135803","rc":[{"batb":[[0,2.4,2.25],[1,1.95,695.9],[2,1.25,29.55]],"ltp":2.52,"tv":3537.54,"id":5720747}]}]}
{"op":"mcm","clk":"1005527808","pt":1580643171752,"mc":[{"id":"1.168135803","rc":[{"batl":[[0,2.8,130.23],[1,3.2,0.31]],"ltp":2.52,"tv":3537.54,"id":5720747}]}]}
{"op":"mcm","clk":"1005527996","pt":1580643172740,"mc":[{"id":"1.168135803","rc":[{"batb":[[0,1.52,604.56],[1,1.51,391.16],[2,1.46,4.25]],"ltp":1.57,"tv":6623.19,"id":2249229}]}]}
{"op":"mcm","clk":"1005529493","pt":1580643179795,"mc":[{"id":"1.168135803","rc":[{"trd":[[1.58,17.91]],"batl":[[0,1.58,560.8]],"ltp":1.58,"tv":6626.63,"id":2249229},{"trd":[[2.72,2]],"ltp":2.72,"tv":3539.54,"id":5720747}],"tv":10166.17}]}
{"op":"mcm","clk":"1005530869","pt":1580643186795,"mc":[{"id":"1.168135803","rc":[{"trd":[[1.58,36.71]],"batl":[[0,1.58,542]],"ltp":1.58,"tv":6645.43,"id":2249229},{"trd":[[2.72,12.92]],"ltp":2.72,"tv":3550.46,"id":5720747}],"tv":10195.89}]}
{"op":"mcm","clk":"1005531433","pt":1580643189796,"mc":[{"id":"1.168135803","rc":[{"trd":[[1.58,43.23]],"batb":[[0,1.56,2.27],[1,1.52,604.56],[2,1.51,391.16]],"batl":[[0,1.58,535.48]],"ltp":1.58,"tv":6651.95,"id":2249229},{"trd":[[2.72,16.71]],"ltp":2.72,"tv":3554.25,"id":5720747}],"tv":10206.2}]}
{"op":"mcm","clk":"1005532543","pt":1580643195791,"mc":[{"id":"1.168135803","rc":[{"trd":[[1.58,54.15]],"batl":[[0,1.58,530.02]],"ltp":1.58,"tv":6662.87,"id":2249229},{"batb":[[0,2.6,5.25],[1,2.4,2.25],[2,1.95,695.9]],"ltp":2.72,"tv":3554.25,"id":5720747}],"tv":10217.12}]}
{"op":"mcm","clk":"1005533360","pt":1580643199810,"mc":[{"id":"1.168135803","rc":[{"trd":[[1.58,140.23]],"batl":[[0,1.58,443.94]],"ltp":1.58,"tv":6748.95,"id":2249229},{"trd":[[2.72,66.71]],"ltp":2.72,"tv":3604.25,"id":5720747}],"tv":10353.2}]}
{"op":"mcm","clk":"1005533590","pt":1580643200799,"mc":[{"id":"1.168135803","rc":[{"trd":[[1.55,220.57],[1.56,101.87]],"batb":[[0,1.52,604.56],[1,1.51,391.16],[2,1.46,4.25]],"ltp":1.55,"tv":6895.22,"id":2249229},{"trd":[[2.8,78.46]],"batl":[[0,2.8,51.77]],"ltp":2.8,"tv":3682.7,"id":5720747}],"tv":10577.93}]}
{"op":"mcm","clk":"1005533773","pt":1580643201815,"mc":[{"id":"1.168135803","rc":[{"trd":[[1.58,144.59]],"batl":[[0,1.58,439.58]],"ltp":1.58,"tv":6899.58,"id":2249229},{"trd":[[2.72,69.24]],"ltp":2.72,"tv":3685.24,"id":5720747}],"tv":10584.82}]}
{"op":"mcm","clk":"1005534005","pt":1580643202812,"mc":[{"id":"1.168135803","rc":[{"batl":[[0,1.58,506.94]],"ltp":1.58,"tv":6899.58,"id":2249229}]}]}
{"op":"mcm","clk":"1005534231","pt":1580643203804,"mc":[{"id":"1.168135803","rc":[{"trd":[[1.58,157.63]],"batl":[[0,1.58,493.9]],"ltp":1.58,"tv":6912.62,"id":2249229},{"trd":[[2.72,76.81]],"batb":[[1,2.5,116.55],[2,2.4,2.25]],"ltp":2.72,"tv":3692.81,"id":5720747}],"tv":10605.43}]}
{"op":"mcm","clk":"1005535316","pt":1580643208804,"mc":[{"id":"1.168135803","rc":[{"batb":[[0,1.52,380.11],[1,1.46,4.25],[2,1.44,9]],"ltp":1.58,"tv":6912.62,"id":2249229}]}]}
{"op":"mcm","clk":"1005535544","pt":1580643209819,"mc":[{"id":"1.168135803","rc":[{"trd":[[1.55,222.25]],"ltp":1.55,"tv":6914.3,"id":2249229},{"trd":[[2.8,79.39]],"batl":[[0,2.8,50.84]],"ltp":2.8,"tv":3693.74,"id":5720747}],"tv":10608.05}]}
{"op":"mcm","clk":"1005535944","pt":1580643211819,"mc":[{"id":"1.168135803","rc":[{"batb":[[0,1.53,300.47],[1,1.52,380.11],[2,1.46,4.25]],"ltp":1.55,"tv":6914.3,"id":2249229}]}]}
{"op":"mcm","clk":"1005536804","pt":1580643215817,"mc":[{"id":"1.168135803","rc":[{"trd":[[1.58,239.11]],"batl":[[0,1.58,453.16]],"ltp":1.58,"tv":6995.78,"id":2249229}],"tv":10689.52}]}
{"op":"mcm","clk":"1005538591","pt":1580643224659,"mc":[{"id":"1.168135803","rc":[{"trd":[[1.58,260.93]],"batl":[[0,1.58,431.34]],"ltp":1.58,"tv":7017.6,"id":2249229},{"trd":[[2.72,89.48]],"ltp":2.72,"tv":3706.41,"id":5720747}],"tv":10724.01}]}
{"op":"mcm","clk":"1005539918","pt":1580643231770,"mc":[{"id":"1.168135803","rc":[{"batb":[[0,1.46,4.25],[1,1.44,9],[2,1.36,180.31]],"batl":[[0,1.81,42.01],[1,1.59,0],[2,1.81,0]],"ltp":1.58,"tv":7017.6,"id":2249229}]}]}
{"op":"mcm","clk":"1005541108","pt":1580643237642,"mc":[{"id":"1.168135803","rc":[{"batl":[[0,2.72,3.13],[1,2.8,50.84],[2,3.2,0.31]],"ltp":2.72,"tv":3706.41,"id":5720747}]}]}
{"op":"mcm","clk":"1005541302","pt":1580643238662,"mc":[{"id":"1.168135803","rc":[{"batb":[[0,1.58,10],[1,1.46,4.25],[2,1.44,9]],"ltp":1.58,"tv":7017.6,"id":2249229}]}]}
{"op":"mcm","clk":"1005541515","pt":1580643239742,"mc":[{"id":"1.168135803","rc":[{"trd":[[1.58,286.33]],"batb":[[0,1.53,318.13],[1,1.52,380.11],[2,1.46,4.25]],"batl":[[0,1.58,456.87],[1,1.59,316.38]],"ltp":1.58,"tv":7043.0,"id":2249229},{"trd":[[2.72,92.61]],"batl":[[0,2.8,50.84],[1,3.2,0.31],[2,3.2,0]],"ltp":2.72,"tv":3709.54,"id":5720747}],"tv":10752.54}]}
{"op":"mcm","clk":"1005544628","pt":1580643255718,"mc":[{"id":"1.168135803","rc":[{"trd":[[1.58,305.13]],"batl":[[0,1.58,438.07]],"ltp":1.58,"tv":7061.8,"id":2249229},{"trd":[[2.72,103.53]],"batl":[[0,2.76,50],[1,2.8,50.84],[2,3.2,0.31]],"ltp":2.72,"tv":3720.46,"id":5720747}],"tv":10782.26}]}
{"op":"mcm","clk":"1005546154","pt":1580643263769,"mc":[{"id":"1.168135803","rc":[{"batb":[[0,1.46,4.25],[1,1.44,9],[2,1.36,180.31]],"ltp":1.58,"tv":7061.8,"id":2249229}]}]}
{"op":"mcm","clk":"1005546512","pt":1580643265784,"mc":[{"id":"1.168135803","rc":[{"batl":[[0,2.72,17.84],[1,2.76,50],[2,2.8,50.84]],"ltp":2.72,"tv":3720.46,"id":5720747}]}]}
{"op":"mcm","clk":"1005547095","pt":1580643268774,"mc":[{"id":"1.168135803","rc":[{"batb":[[2,1.42,447.08]],"batl":[[0,1.65,290.71],[1,1.66,271.66]],"ltp":1.58,"tv":7061.8,"id":2249229},{"batl":[[0,2.76,50],[1,2.8,50.84],[2,3.2,0.31]],"ltp":2.72,"tv":3720.46,"id":5720747}]}]}
{"op":"mcm","clk":"1005547554","pt":1580643271284,"mc":[{"id":"1.168135803","rc":[{"batb":[[1,2.4,2.25],[2,1.95,695.9]],"batl":[[1,3.2,0.31],[2,3.2,0]],"ltp":2.72,"tv":3720.46,"id":5720747}]}]}
{"op":"mcm","clk":"1005548034","pt":1580643273788,"mc":[{"id":"1.168135803","rc":[{"batb":[[1,2.54,113.53],[2,2.4,2.25]],"ltp":2.72,"tv":3720.46,"id":5720747}]}]}
{"op":"mcm","clk":"1005548220","pt":1580643274700,"mc":[{"id":"1.168135803","rc":[{"trd":[[1.63,4]],"ltp":1.63,"tv":7065.8,"id":2249229},{"trd":[[2.6,2.5]],"batb":[[0,2.6,2.75]],"ltp":2.6,"tv":3722.97,"id":5720747}],"tv":10788.77}]}
{"op":"mcm","clk":"1005548740","pt":1580643277507,"mc":[{"id":"1.168135803","rc":[{"batb":[[2,1.43,406.58]],"ltp":1.63,"tv":7065.8,"id":2249229}]}]}
{"op":"mcm","clk":"1005548976","pt":1580643278789,"mc":[{"id":"1.168135803","rc":[{"batb":[[1,1.44,406.34]],"ltp":1.63,"tv":7065.8,"id":2249229}]}]}
{"op":"mcm","clk":"1005549159","pt":1580643279687,"mc":[{"id":"1.168135803","rc":[{"batb":[[1,2.56,112.07],[2,2.54,113.53]],"ltp":2.6,"tv":3722.97,"id":5720747}]}]}
{"op":"mcm","clk":"1005549755","pt":1580643282798,"mc":[{"id":"1.168135803","rc":[{"trd":[[1.56,111.87]],"ltp":1.56,"tv":7075.8,"id":2249229},{"trd":[[2.76,5.65]],"batl":[[0,2.76,44.35]],"ltp":2.76,"tv":3728.62,"id":5720747}],"tv":10804.42}]}
{"op":"mcm","clk":"1005549928","pt":1580643283693,"mc":[{"id":"1.168135803","rc":[{"batb":[[1,2.4,2.25],[2,1.95,695.9]],"ltp":2.76,"tv":3728.62,"id":5720747}]}]}
{"op":"mcm","clk":"1005550156","pt":1580643284811,"mc":[{"id":"1.168135803","rc":[{"batb":[[0,1.6,281.63],[1,1.59,542.64],[2,1.46,4.25]],"ltp":1.56,"tv":7075.8,"id":2249229}]}]}
{"op":"mcm","clk":"1005551113","pt":1580643289817,"mc":[{"id":"1.168135803","rc":[{"batb":[[1,1.59,319.06]],"ltp":1.56,"tv":7075.8,"id":2249229}]}]}
{"op":"mcm","clk":"1005552253","pt":1580643295817,"mc":[{"id":"1.168135803","rc":[{"trd":[[1.63,8.38]],"batb":[[0,1.63,5.62],[1,1.6,281.63],[2,1.59,319.06]],"ltp":1.63,"tv":7080.18,"id":2249229},{"trd":[[2.6,5.25]],"batb":[[0,2.4,2.25],[1,1.95,695.9],[2,1.25,29.55]],"ltp":2.6,"tv":3731.36,"id":5720747}],"tv":10811.55}]}
{"op":"mcm","clk":"1005552445","pt":1580643296726,"mc":[{"id":"1.168135803","rc":[{"batb":[[1,1.46,4.25],[2,1.44,9]],"ltp":1.63,"tv":7080.18,"id":2249229}]}]}
{"op":"mcm","clk":"1005552653","pt":1580643297808,"mc":[{"id":"1.168135803","rc":[{"batb":[[1,2.34,130.47],[2,1.95,695.9]],"batl":[[0,3.2,0.31],[1,3.2,0]],"ltp":2.6,"tv":3731.36,"id":5720747}]}]}
{"op":"mcm","clk":"1005552974","pt":1580643299622,"mc":[{"id":"1.168135803","rc":[{"batb":[[1,1.5,525.24],[2,1.49,413.49]],"batl":[[0,1.72,424.28],[1,1.74,464.6]],"ltp":1.63,"tv":7080.18,"id":2249229}]}]}
{"op":"mcm","clk":"1005553167","pt":1580643300735,"mc":[{"id":"1.168135803","rc":[{"batl":[[0,2.6,2],[1,3.2,0.31]],"ltp":2.6,"tv":3731.36,"id":5720747}]}]}
{"op":"mcm","clk":"1005553598","pt":1580643302713,"mc":[{"id":"1.168135803","rc":[{"batl":[[0,3.2,0.31],[1,3.2,0]],"ltp":2.6,"tv":3731.36,"id":5720747}]}]}
{"op":"mcm","clk":"1005554128","pt":1580643305762,"mc":[{"id":"1.168135803","rc":[{"batb":[[1,1.95,695.9],[2,1.25,29.55]],"ltp":2.6,"tv":3731.36,"id":5720747}]}]}
{"op":"mcm","clk":"1005554326","pt":1580643306736,"mc":[{"id":"1.168135803","rc":[{"batb":[[0,1.5,525.24],[1,1.49,413.49],[2,1.46,4.25]],"ltp":1.63,"tv":7080.18,"id":2249229}]}]}
{"op":"mcm","clk":"1005554530","pt":1580643307749,"mc":[{"id":"1.168135803","rc":[{"batb":[[0,2.4,127.13]],"ltp":2.6,"tv":3731.36,"id":5720747}]}]}
{"op":"mcm","clk":"1005554763","pt":1580643308762,"mc":[{"id":"1.168135803","rc":[{"batb":[[0,2.4,252.01]],"ltp":2.6,"tv":3731.36,"id":5720747}]}]}
{"op":"mcm","clk":"1005555117","pt":1580643310534,"mc":[{"id":"1.168135803","rc":[{"batb":[[0,1.52,336.21],[1,1.51,342.81],[2,1.5,525.24]],"ltp":1.63,"tv":7080.18,"id":2249229}]}]}
{"op":"mcm","clk":"1005555533","pt":1580643312727,"mc":[{"id":"1.168135803","rc":[{"trd":[[2.4,284.87]],"batb":[[0,2.4,234.17]],"ltp":2.4,"tv":3767.05,"id":5720747}],"tv":10847.23}]}
{"op":"mcm","clk":"1005555716","pt":1580643313733,"mc":[{"id":"1.168135803","rc":[{"batb":[[2,1.46,4.25]],"ltp":1.63,"tv":7080.18,"id":2249229}]}]}
{"op":"mcm","clk":"1005556157","pt":1580643315756,"mc":[{"id":"1.168135803","rc":[{"batb":[[0,1.66,199.86],[1,1.52,336.21],[2,1.51,342.81]],"ltp":1.63,"tv":7080.18,"id":2249229},{"batb":[[0,1.95,695.9],[1,1.25,29.55],[2,1.05,16.8]],"ltp":2.4,"tv":3767.05,"id":5720747}]}]}
{"op":"mcm","clk":"1005556360","pt":1580643316770,"mc":[{"id":"1.168135803","rc":[{"batb":[[1,1.65,522.52],[2,1.64,285.12]],"ltp":1.63,"tv":7080.18,"id":2249229}]}]}
{"op":"mcm","clk":"1005556967","pt":1580643319775,"mc":[{"id":"1.168135803","rc":[{"trd":[[1.72,244.97]],"batl":[[0,1.72,402.53]],"ltp":1.72,"tv":7101.93,"id":2249229},{"trd":[[2.38,57.03]],"ltp":2.38,"tv":3782.77,"id":5720747}],"tv":10884.7}]}
{"op":"mcm","clk":"1005557146","pt":1580643320748,"mc":[{"id":"1.168135803","rc":[{"batb":[[0,1.65,522.52],[1,1.64,285.12],[2,1.46,4.25]],"ltp":1.72,"tv":7101.93,"id":2249229}]}]}
{"op":"mcm","clk":"1005558895","pt":1580643328745,"mc":[{"id":"1.168135803","rc":[{"batb":[[0,1.46,4.25],[1,1.44,188.65],[2,1.25,27.28]],"ltp":1.72,"tv":7101.93,"id":2249229},{"batb":[[0,2.22,143.3],[1,1.95,695.9],[2,1.25,29.55]],"ltp":2.38,"tv":3782.77,"id":5720747}]}]}
{"op":"mcm","clk":"1005559511","pt":1580643331752,"mc":[{"id":"1.168135803","rc":[{"batb":[[0,1.59,322.62],[1,1.58,326.91],[2,1.46,4.25]],"batl":[[0,1.76,309.41],[1,1.78,431.3]],"ltp":1.72,"tv":7101.93,"id":2249229}]}]}
{"op":"mcm","clk":"1005560110","pt":1580643334697,"mc":[{"id":"1.168135803","rc":[{"batb":[[0,1.95,695.9],[1,1.25,29.55],[2,1.05,16.8]],"ltp":2.38,"tv":3782.77,"id":5720747}]}]}
{"op":"mcm","clk":"1005560843","pt":1580643337759,"mc":[{"id":"1.168135803","rc":[{"batb":[[0,2.32,132.45],[1,1.95,695.9],[2,1.25,29.55]],"batl":[[0,2.38,50],[1,3.2,0.31]],"ltp":2.38,"tv":3782.77,"id":5720747}]}]}
{"op":"mcm","clk":"1005561027","pt":1580643338768,"mc":[{"id":"1.168135803","rc":[{"batb":[[0,2.32,264.9]],"ltp":2.38,"tv":3782.77,"id":5720747}]}]}
{"op":"mcm","clk":"1005561196","pt":1580643339790,"mc":[{"id":"1.168135803","rc":[{"batb":[[0,1.6,291.39],[1,1.59,322.62],[2,1.58,326.91]],"ltp":1.72,"tv":7101.93,"id":2249229}]}]}
{"op":"mcm","clk":"1005561384","pt":1580643340697,"mc":[{"id":"1.168135803","rc":[{"batb":[[0,1.6,582.77]],"ltp":1.72,"tv":7101.93,"id":2249229}]}]}
{"op":"mcm","clk":"1005561614","pt":1580643341781,"mc":[{"id":"1.168135803","rc":[{"batb":[[1,1.46,4.25],[2,1.44,188.65]],"ltp":1.72,"tv":7101.93,"id":2249229}]}]}
{"op":"mcm","clk":"1005562214","pt":1580643344806,"mc":[{"id":"1.168135803","rc":[{"trd":[[1.72,314.16]],"ltp":1.72,"tv":7171.12,"id":2249229},{"trd":[[2.38,107.03]],"batl":[[0,3.2,0.31],[1,3.2,0]],"ltp":2.38,"tv":3832.77,"id":5720747}],"tv":11003.89}]}
{"op":"mcm","clk":"1005562844","pt":1580643347688,"mc":[{"id":"1.168135803","rc":[{"batb":[[1,1.59,322.62],[2,1.58,326.91]],"batl":[[0,1.76,309.41],[1,1.78,431.3]],"ltp":1.72,"tv":7171.12,"id":2249229}]}]}
{"op":"mcm","clk":"1005563458","pt":1580643350782,"mc":[{"id":"1.168135803","rc":[{"batl":[[0,1.75,50],[1,1.76,309.41],[2,1.78,431.3]],"ltp":1.72,"tv":7171.12,"id":2249229}]}]}
{"op":"mcm","clk":"1005564072","pt":1580643353785,"mc":[{"id":"1.168135803","rc":[{"batl":[[1,1.76,0],[2,1.78,0]],"ltp":1.72,"tv":7171.12,"id":2249229}]}]}
{"op":"mcm","clk":"1005564437","pt":1580643355792,"mc":[{"id":"1.168135803","rc":[{"batb":[[0,1.59,322.62],[1,1.58,326.91],[2,1.46,4.25]],"batl":[[0,1.65,528.13],[1,1.66,402.78],[2,1.75,50]],"ltp":1.72,"tv":7171.12,"id":2249229}]}]}
{"op":"mcm","clk":"1005564833","pt":1580643357802,"mc":[{"id":"1.168135803","rc":[{"batl":[[2,1.75,0]],"ltp":1.72,"tv":7171.12,"id":2249229}]}]}
{"op":"mcm","clk":"1005565379","pt":1580643360635,"mc":[{"id":"1.168135803","rc":[{"batl":[[1,1.66,270.87]],"ltp":1.72,"tv":7171.12,"id":2249229}]}]}
{"op":"mcm","clk":"1005565801","pt":1580643362726,"mc":[{"id":"1.168135803","rc":[{"batb":[[0,1.95,695.9],[1,1.25,29.55],[2,1.05,16.8]],"ltp":2.38,"tv":3832.77,"id":5720747}]}]}
{"op":"mcm","clk":"1005566219","pt":1580643364801,"mc":[{"id":"1.168135803","rc":[{"batb":[[2,1.5,349.66]],"ltp":1.72,"tv":7171.12,"id":2249229}]}]}
{"op":"mcm","clk":"1005566837","pt":1580643367756,"mc":[{"id":"1.168135803","rc":[{"batb":[[0,1.5,349.66],[1,1.46,4.25],[2,1.44,188.65]],"ltp":1.72,"tv":7171.12,"id":2249229}]}]}
{"op":"mcm","clk":"1005567681","pt":1580643371616,"mc":[{"id":"1.168135803","rc":[{"batb":[[1,1.48,355.18],[2,1.47,436.23]],"batl":[[0,1.72,300.61],[1,1.74,464.97]],"ltp":1.72,"tv":7171.12,"id":2249229}]}]}
{"op":"mcm","clk":"1005568883","pt":1580643377592,"mc":[{"id":"1.168135803","rc":[{"batl":[[0,1.71,50],[1,1.72,300.61],[2,1.74,464.97]],"ltp":1.72,"tv":7171.12,"id":2249229}]}]}
{"op":"mcm","clk":"1005569116","pt":1580643378815,"mc":[{"id":"1.168135803","rc":[{"batb":[[0,2.42,123.12],[1,2.4,124.88],[2,1.95,695.9]],"batl":[[0,2.52,2],[1,3.2,0.31]],"ltp":2.38,"tv":3832.77,"id":5720747}]}]}
{"op":"mcm","clk":"1005569693","pt":1580643381708,"mc":[{"id":"1.168135803","rc":[{"batb":[[0,1.5,699.32],[1,1.46,4.25],[2,1.44,188.65]],"ltp":1.72,"tv":7171.12,"id":2249229}]}]}
{"op":"mcm","clk":"1005569903","pt":1580643382817,"mc":[{"id":"1.168135803","rc":[{"batl":[[0,1.72,300.61],[1,1.74,464.97],[2,1.74,0]],"ltp":1.72,"tv":7171.12,"id":2249229},{"batb":[[0,1.95,695.9],[1,1.25,29.55],[2,1.05,16.8]],"ltp":2.38,"tv":3832.77,"id":5720747}]}]}
{"op":"mcm","clk":"1005570067","pt":1580643383720,"mc":[{"id":"1.168135803","rc":[{"batb":[[0,1.65,202.93],[1,1.5,699.32],[2,1.46,4.25]],"ltp":1.72,"tv":7171.12,"id":2249229}]}]}
{"op":"mcm","clk":"1005570211","pt":1580643384517,"mc":[{"id":"1.168135803","rc":[{"batb":[[0,1.66,372.37],[1,1.65,481.39],[2,1.5,699.32]],"ltp":1.72,"tv":7171.12,"id":2249229}]}]}
{"op":"mcm","clk":"1005570850","pt":1580643387713,"mc":[{"id":"1.168135803","rc":[{"batl":[[0,2.52,4]],"ltp":2.38,"tv":3832.77,"id":5720747}]}]}
{"op":"mcm","clk":"1005571045","pt":1580643388726,"mc":[{"id":"1.168135803","rc":[{"trd":[[1.66,530.4]],"batb":[[0,1.66,372.2],[1,1.65,278.46],[2,1.46,4.25]],"ltp":1.66,"tv":7171.46,"id":2249229}],"tv":11004.23}]}
{"op":"mcm","clk":"1005571386","pt":1580643390639,"mc":[{"id":"1.168135803","rc":[{"batl":[[0,2.52,2]],"ltp":2.38,"tv":3832.77,"id":5720747}]}]}
{"op":"mcm","clk":"1005572010","pt":1580643393759,"mc":[{"id":"1.168135803","rc":[{"batb":[[2,1.58,301.43]],"ltp":1.66,"tv":7171.46,"id":2249229},{"batl":[[0,3.2,0.31],[1,3.2,0]],"ltp":2.38,"tv":3832.77,"id":5720747}]}]}
{"op":"mcm","clk":"1005572700","pt":1580643396743,"mc":[{"id":"1.168135803","rc":[{"batb":[[0,1.58,301.43],[1,1.46,4.25],[2,1.44,188.65]],"batl":[[0,1.66,4.8],[1,1.74,0]],"ltp":1.66,"tv":7171.46,"id":2249229}]}]}
{"op":"mcm","clk":"1005573297","pt":1580643399554,"mc":[{"id":"1.168135803","rc":[{"trd":[[1.66,535.2]],"batb":[[0,1.59,574.82],[1,1.58,629.18],[2,1.46,4.25]],"batl":[[0,1.76,264.6],[1,1.78,432.65]],"ltp":1.66,"tv":7176.26,"id":2249229},{"trd":[[2.5,389.59]],"batl":[[0,2.38,6.81],[1,3.2,0.31]],"ltp":2.5,"tv":3835.96,"id":5720747}],"tv":11012.22}]}
{"op":"mcm","clk":"1005573697","pt":1580643401750,"mc":[{"id":"1.168135803","rc":[{"batb":[[1,1.58,327.75]],"ltp":1.66,"tv":7176.26,"id":2249229}]}]}
{"op":"mcm","clk":"1005574275","pt":1580643404631,"mc":[{"id":"1.168135803","rc":[{"batb":[[0,1.6,291.39],[1,1.59,574.82],[2,1.58,327.75]],"ltp":1.66,"tv":7176.26,"id":2249229}]}]}
{"op":"mcm","clk":"1005574465","pt":1580643405636,"mc":[{"id":"1.168135803","rc":[{"batb":[[0,1.6,582.77]],"ltp":1.66,"tv":7176.26,"id":2249229},{"batl":[[0,3.2,0.31],[1,3.2,0]],"ltp":2.5,"tv":3835.96,"id":5720747}]}]}
{"op":"mcm","clk":"1005574696","pt":1580643406750,"mc":[{"id":"1.168135803","rc":[{"batb":[[0,2.32,132.45],[1,1.95,695.9],[2,1.25,29.55]],"ltp":2.5,"tv":3835.96,"id":5720747}]}]}
{"op":"mcm","clk":"1005574918","pt":1580643407750,"mc":[{"id":"1.168135803","rc":[{"batb":[[0,2.32,264.9]],"batl":[[0,2.38,2],[1,3.2,0.31]],"ltp":2.5,"tv":3835.96,"id":5720747}]}]}
{"op":"mcm","clk":"1005575367","pt":1580643409782,"mc":[{"id":"1.168135803","rc":[{"batl":[[0,2.38,22]],"ltp":2.5,"tv":3835.96,"id":5720747}]}]}
{"op":"mcm","clk":"1005575573","pt":1580643410654,"mc":[{"id":"1.168135803","rc":[{"batb":[[1,1.46,4.25],[2,1.44,188.65]],"ltp":1.66,"tv":7176.26,"id":2249229}]}]}
{"op":"mcm","clk":"1005575766","pt":1580643411663,"mc":[{"id":"1.168135803","rc":[{"batl":[[0,1.75,50],[1,1.76,264.6],[2,1.78,432.65]],"ltp":1.66,"tv":7176.26,"id":2249229},{"batl":[[0,2.38,20]],"ltp":2.5,"tv":3835.96,"id":5720747}]}]}
{"op":"mcm","clk":"1005575995","pt":1580643412770,"mc":[{"id":"1.168135803","rc":[{"batb":[[0,1.61,81.96],[1,1.6,582.77],[2,1.46,4.25]],"batl":[[0,1.76,264.6],[1,1.78,432.65],[2,1.78,0]],"ltp":1.66,"tv":7176.26,"id":2249229},{"batb":[[0,1.95,695.9],[1,1.25,29.55],[2,1.05,16.8]],"ltp":2.5,"tv":3835.96,"id":5720747}]}]}
{"op":"mcm","clk":"1005576180","pt":1580643413773,"mc":[{"id":"1.168135803","rc":[{"batb":[[0,1.7,311.94],[1,1.69,191.17],[2,1.68,518.6]],"ltp":1.66,"tv":7176.26,"id":2249229}]}]}
{"op":"mcm","clk":"1005577138","pt":1580643418779,"mc":[{"id":"1.168135803","rc":[{"batb":[[1,1.68,518.6],[2,1.48,171.41]],"ltp":1.66,"tv":7176.26,"id":2249229}]}]}
{"op":"mcm","clk":"1005577711","pt":1580643421779,"mc":[{"id":"1.168135803","rc":[{"trd":[[1.76,86.73]],"batl":[[0,1.76,255.45]],"ltp":1.76,"tv":7185.41,"id":2249229},{"trd":[[2.3,234.52]],"ltp":2.3,"tv":3842.96,"id":5720747}],"tv":11028.37}]}
{"op":"mcm","clk":"1005578348","pt":1580643424765,"mc":[{"id":"1.168135803","rc":[{"trd":[[1.72,320.22]],"ltp":1.72,"tv":7191.47,"id":2249229},{"trd":[[2.38,111.41]],"batl":[[0,2.38,15.62]],"ltp":2.38,"tv":3847.34,"id":5720747}],"tv":11038.81}]}
{"op":"mcm","clk":"1005578566","pt":1580643425761,"mc":[{"id":"1.168135803","rc":[{"batb":[[0,1.48,171.41],[1,1.46,4.23],[2,1.44,9]],"ltp":1.72,"tv":7191.47,"id":2249229}]}]}
{"op":"mcm","clk":"1005579188","pt":1580643428757,"mc":[{"id":"1.168135803","rc":[{"batb":[[0,1.61,476.17],[1,1.6,312.22],[2,1.48,171.41]],"batl":[[0,1.97,258.34],[1,1.99,303.94]],"ltp":1.72,"tv":7191.47,"id":2249229}]}]}
{"op":"mcm","clk":"1005579587","pt":1580643430777,"mc":[{"id":"1.168135803","rc":[{"trd":[[1.72,341.83]],"batl":[[0,1.72,16.25],[1,1.97,258.34],[2,1.99,303.94]],"ltp":1.72,"tv":7213.08,"id":2249229},{"trd":[[2.38,127.03]],"batl":[[0,3.2,0.31],[1,3.2,0]],"ltp":2.38,"tv":3862.96,"id":5720747}],"tv":11076.04}]}
{"op":"mcm","clk":"1005580184","pt":1580643433785,"mc":[{"id":"1.168135803","rc":[{"batb":[[0,2.04,168.11],[1,1.95,695.9],[2,1.25,29.55]],"ltp":2.38,"tv":3862.96,"id":5720747}]}]}
{"op":"mcm","clk":"1005580369","pt":1580643434792,"mc":[{"id":"1.168135803","rc":[{"batb":[[0,2.04,336.21]],"ltp":2.38,"tv":3862.96,"id":5720747}]}]}
{"op":"mcm","clk":"1005580632","pt":1580643435721,"mc":[{"id":"1.168135803","rc":[{"batb":[[0,1.63,277.51],[1,1.62,281.99],[2,1.61,476.17]],"ltp":1.72,"tv":7213.08,"id":2249229}]}]}
{"op":"mcm","clk":"1005581975","pt":1580643441813,"mc":[{"id":"1.168135803","rc":[{"trd":[[1.72,358.08]],"batl":[[0,1.97,258.34],[1,1.99,303.94],[2,1.99,0]],"ltp":1.72,"tv":7229.33,"id":2249229},{"trd":[[2.38,138.78]],"batb":[[0,2.36,176.44],[1,2.04,336.21],[2,1.95,695.9]],"batl":[[0,2.38,30.26],[1,3.2,0.31]],"ltp":2.38,"tv":3874.71,"id":5720747}],"tv":11104.04}]}
{"op":"mcm","clk":"1005582742","pt":1580643445753,"mc":[{"id":"1.168135803","rc":[{"batl":[[0,3.2,0.31],[1,3.2,0]],"ltp":2.38,"tv":3874.71,"id":5720747}]}]}
{"op":"mcm","clk":"1005583327","pt":1580643448755,"mc":[{"id":"1.168135803","rc":[{"trd":[[2.36,60.53]],"batb":[[0,2.36,146.18]],"ltp":2.36,"tv":3935.23,"id":5720747}],"tv":11164.57}]}
{"op":"mcm","clk":"1005584879","pt":1580643456747,"mc":[{"id":"1.168135803","rc":[{"batl":[[0,1.72,43.69],[1,1.97,258.34],[2,1.99,303.94]],"ltp":1.72,"tv":7229.33,"id":2249229}]}]}
{"op":"mcm","clk":"1005585530","pt":1580643459788,"mc":[{"id":"1.168135803","rc":[{"batl":[[0,1.97,258.34],[1,1.99,303.94],[2,1.99,0]],"ltp":1.72,"tv":7229.33,"id":2249229}]}]}
{"op":"mcm","clk":"1005586564","pt":1580643464790,"mc":[{"id":"1.168135803","rc":[{"batb":[[0,1.61,476.17],[1,1.6,312.22],[2,1.48,171.41]],"ltp":1.72,"tv":7229.33,"id":2249229},{"trd":[[2.36,65.07]],"batb":[[0,2.36,143.91]],"ltp":2.36,"tv":3939.77,"id":5720747}],"tv":11169.11}]}
{"op":"mcm","clk":"1005586769","pt":1580643465675,"mc":[{"id":"1.168135803","rc":[{"batl":[[0,1.67,350.68],[1,1.68,260.36],[2,1.69,131.91]],"ltp":1.72,"tv":7229.33,"id":2249229}]}]}
{"op":"mcm","clk":"1005587184","pt":1580643467793,"mc":[{"id":"1.168135803","rc":[{"batb":[[0,2.38,168.04],[1,2.36,143.91],[2,2.04,336.21]],"ltp":2.36,"tv":3939.77,"id":5720747}]}]}
{"op":"mcm","clk":"1005587580","pt":1580643469763,"mc":[{"id":"1.168135803","rc":[{"batb":[[2,1.95,695.9]],"ltp":2.36,"tv":3939.77,"id":5720747}]}]}
{"op":"mcm","clk":"1005587747","pt":1580643470768,"mc":[{"id":"1.168135803","rc":[{"batl":[[2,1.69,0]],"ltp":1.72,"tv":7229.33,"id":2249229}]}]}
{"op":"mcm","clk":"1005587889","pt":1580643471666,"mc":[{"id":"1.168135803","rc":[{"batb":[[0,2.36,143.91],[1,1.95,695.9],[2,1.25,29.55]],"ltp":2.36,"tv":3939.77,"id":5720747}]}]}
{"op":"mcm","clk":"1005588292","pt":1580643473796,"mc":[{"id":"1.168135803","rc":[{"batb":[[2,1.5,349.66]],"ltp":1.72,"tv":7229.33,"id":2249229}]}]}
{"op":"mcm","clk":"1005588723","pt":1580643475674,"mc":[{"id":"1.168135803","rc":[{"batb":[[0,2.4,124.88],[1,2.36,143.91],[2,1.95,695.9]],"ltp":2.36,"tv":3939.77,"id":5720747}]}]}
{"op":"mcm","clk":"1005589163","pt":1580643477819,"mc":[{"id":"1.168135803","rc":[{"batb":[[0,1.5,349.66],[1,1.48,171.41],[2,1.46,4.23]],"ltp":1.72,"tv":7229.33,"id":2249229}]}]}
{"op":"mcm","clk":"1005589782","pt":1580643480786,"mc":[{"id":"1.168135803","rc":[{"batb":[[0,1.55,607.26],[1,1.54,362.24],[2,1.5,349.66]],"batl":[[0,1.81,427.12],[1,1.83,393.93]],"ltp":1.72,"tv":7229.33,"id":2249229}]}]}
{"op":"mcm","clk":"1005590590","pt":1580643484711,"mc":[{"id":"1.168135803","rc":[{"batl":[[0,2.48,2],[1,3.2,0.31]],"ltp":2.36,"tv":3939.77,"id":5720747}]}]}
{"op":"mcm","clk":"1005590818","pt":1580643485697,"mc":[{"id":"1.168135803","rc":[{"batb":[[2,1.48,171.41]],"ltp":1.72,"tv":7229.33,"id":2249229}]}]}
{"op":"mcm","clk":"1005591020","pt":1580643486719,"mc":[{"id":"1.168135803","rc":[{"batb":[[0,1.56,312.2],[1,1.55,607.26],[2,1.54,362.24]],"ltp":1.72,"tv":7229.33,"id":2249229},{"batb":[[0,2.36,143.91],[1,1.95,695.9],[2,1.25,29.55]],"ltp":2.36,"tv":3939.77,"id":5720747}]}]}
{"op":"mcm","clk":"1005591256","pt":1580643487808,"mc":[{"id":"1.168135803","rc":[{"batb":[[0,1.56,624.4]],"ltp":1.72,"tv":7229.33,"id":2249229}]}]}
{"op":"mcm","clk":"1005591703","pt":1580643489804,"mc":[{"id":"1.168135803","rc":[{"batb":[[1,2.26,138.75],[2,2.24,140.99]],"batl":[[0,3.2,0.31],[1,3.2,0]],"ltp":2.36,"tv":3939.77,"id":5720747}]}]}
{"op":"mcm","clk":"1005593202","pt":1580643496718,"mc":[{"id":"1.168135803","rc":[{"batb":[[0,1.55,607.26],[1,1.54,362.24],[2,1.48,171.41]],"ltp":1.72,"tv":7229.33,"id":2249229}]}]}
{"op":"mcm","clk":"1005593436","pt":1580643497745,"mc":[{"id":"1.168135803","rc":[{"batb":[[2,1.46,4.25]],"batl":[[0,1.61,435.54],[1,1.62,295.73],[2,1.65,131.91]],"ltp":1.72,"tv":7229.33,"id":2249229}]}]}
{"op":"mcm","clk":"1005593897","pt":1580643499793,"mc":[{"id":"1.168135803","rc":[{"trd":[[1.61,137.99]],"batl":[[0,1.61,377.96]],"ltp":1.61,"tv":7286.91,"id":2249229},{"trd":[[2.62,37.88]],"ltp":2.62,"tv":3975.13,"id":5720747}],"tv":11262.05}]}
{"op":"mcm","clk":"1005594360","pt":1580643501803,"mc":[{"id":"1.168135803","rc":[{"batb":[[1,1.95,695.9],[2,1.25,29.55]],"ltp":2.62,"tv":3975.13,"id":5720747}]}]}
{"op":"mcm","clk":"1005594578","pt":1580643502817,"mc":[{"id":"1.168135803","rc":[{"batb":[[2,1.48,364.25]],"batl":[[2,1.65,0]],"ltp":1.61,"tv":7286.91,"id":2249229}]}]}
{"op":"mcm","clk":"1005595745","pt":1580643507804,"mc":[{"id":"1.168135803","rc":[{"batb":[[0,2.44,121.41],[1,2.36,143.91],[2,1.95,695.9]],"ltp":2.62,"tv":3975.13,"id":5720747}]}]}
{"op":"mcm","clk":"1005596120","pt":1580643509729,"mc":[{"id":"1.168135803","rc":[{"batb":[[0,1.48,364.25],[1,1.46,4.23],[2,1.44,9]],"ltp":1.61,"tv":7286.91,"id":2249229}]}]}
{"op":"mcm","clk":"1005596743","pt":1580643512637,"mc":[{"id":"1.168135803","rc":[{"batb":[[0,1.52,563.01],[1,1.51,391.58],[2,1.48,364.25]],"batl":[[0,1.68,305.86],[1,1.7,503.07]],"ltp":1.61,"tv":7286.91,"id":2249229}]}]}
{"op":"mcm","clk":"1005597413","pt":1580643515726,"mc":[{"id":"1.168135803","rc":[{"batb":[[0,2.36,143.91],[1,1.95,695.9],[2,1.25,29.55]],"ltp":2.62,"tv":3975.13,"id":5720747}]}]}
{"op":"mcm","clk":"1005597858","pt":1580643517757,"mc":[{"id":"1.168135803","rc":[{"batb":[[0,1.53,659.74],[1,1.52,563.01],[2,1.51,391.58]],"ltp":1.61,"tv":7286.91,"id":2249229},{"batl":[[0,2.62,5],[1,3.2,0.31]],"ltp":2.62,"tv":3975.13,"id":5720747}]}]}
{"op":"mcm","clk":"1005598088","pt":1580643518730,"mc":[{"id":"1.168135803","rc":[{"batb":[[1,1.48,364.25],[2,1.46,4.23]],"ltp":1.61,"tv":7286.91,"id":2249229}]}]}
{"op":"mcm","clk":"1005598308","pt":1580643519746,"mc":[{"id":"1.168135803","rc":[{"batb":[[1,1.46,4.25],[2,1.36,187.24]],"ltp":1.61,"tv":7286.91,"id":2249229},{"batb":[[0,2.48,236.26],[1,2.36,143.91],[2,1.95,695.9]],"batl":[[1,2.7,93.26],[2,3.2,0.31]],"ltp":2.62,"tv":3975.13,"id":5720747}]}]}
{"op":"mcm","clk":"1005598729","pt":1580643521793,"mc":[{"id":"1.168135803","rc":[{"batb":[[2,1.25,27.28]],"ltp":1.61,"tv":7286.91,"id":2249229}]}]}
{"op":"mcm","clk":"1005599396","pt":1580643524777,"mc":[{"id":"1.168135803","rc":[{"batb":[[1,1.52,563.01],[2,1.51,391.58]],"batl":[[0,1.68,305.86],[1,1.7,503.07]],"ltp":1.61,"tv":7286.91,"id":2249229}]}]}
{"op":"mcm","clk":"1005600774","pt":1580643530788,"mc":[{"id":"1.168135803","rc":[{"trd":[[2.48,212.06]],"batb":[[0,2.48,233.26]],"ltp":2.48,"tv":3981.13,"id":5720747}],"tv":11268.05}]}
{"op":"mcm","clk":"1005601649","pt":1580643534765,"mc":[{"id":"1.168135803","rc":[{"batb":[[0,1.52,563.01],[1,1.51,391.58],[2,1.46,4.25]],"ltp":1.61,"tv":7286.91,"id":2249229},{"batl":[[0,2.62,3]],"ltp":2.48,"tv":3981.13,"id":5720747}]}]}
{"op":"mcm","clk":"1005601883","pt":1580643535786,"mc":[{"id":"1.168135803","rc":[{"trd":[[1.61,142.87]],"batl":[[0,1.57,275.25],[1,1.58,324.65]],"ltp":1.61,"tv":7291.79,"id":2249229},{"trd":[[2.62,40.88]],"batl":[[0,3.2,0.31],[1,2.7,0],[2,3.2,0]],"ltp":2.62,"tv":3984.13,"id":5720747}],"tv":11275.93}]}
{"op":"mcm","clk":"1005602063","pt":1580643536701,"mc":[{"id":"1.168135803","rc":[{"batl":[[0,1.58,324.65],[1,1.58,0]],"ltp":1.61,"tv":7291.79,"id":2249229}]}]}
{"op":"mcm","clk":"1005602216","pt":1580643537453,"mc":[{"id":"1.168135803","rc":[{"trd":[[1.58,308.57]],"batl":[[0,1.58,321.21]],"ltp":1.58,"tv":7295.23,"id":2249229},{"trd":[[2.72,105.53]],"ltp":2.72,"tv":3986.13,"id":5720747}],"tv":11281.37}]}
{"op":"mcm","clk":"1005602874","pt":1580643540667,"mc":[{"id":"1.168135803","rc":[{"batb":[[0,1.57,4.74],[1,1.52,563.01],[2,1.51,391.58]],"batl":[[0,1.58,595.4],[1,1.59,315.76]],"ltp":1.58,"tv":7295.23,"id":2249229},{"batb":[[0,2.36,143.91],[1,1.95,695.9],[2,1.25,29.55]],"ltp":2.72,"tv":3986.13,"id":5720747}]}]}
{"op":"mcm","clk":"1005604104","pt":1580643546602,"mc":[{"id":"1.168135803","rc":[{"batl":[[0,1.58,324.65],[1,1.59,0]],"ltp":1.58,"tv":7295.23,"id":2249229}]}]}
{"op":"mcm","clk":"1005604557","pt":1580643548710,"mc":[{"id":"1.168135803","rc":[{"batb":[[1,1.51,391.58],[2,1.46,4.25]],"ltp":1.58,"tv":7295.23,"id":2249229}]}]}
{"op":"mcm","clk":"1005604784","pt":1580643549811,"mc":[{"id":"1.168135803","rc":[{"trd":[[1.57,564.02]],"batb":[[0,1.51,391.58],[1,1.46,4.25],[2,1.44,397.34]],"ltp":1.57,"tv":7304.71,"id":2249229}],"tv":11290.85}]}
{"op":"mcm","clk":"1005604989","pt":1580643550723,"mc":[{"id":"1.168135803","rc":[{"batb":[[0,2.5,116.55],[1,2.36,143.91],[2,1.95,695.9]],"ltp":2.72,"tv":3986.13,"id":5720747}]}]}
{"op":"mcm","clk":"1005605208","pt":1580643551685,"mc":[{"id":"1.168135803","rc":[{"batb":[[1,1.5,402.56],[2,1.46,4.25]],"batl":[[0,1.61,534.92],[1,1.62,295.31]],"ltp":1.57,"tv":7304.71,"id":2249229}]}]}
{"op":"mcm","clk":"1005606130","pt":1580643555800,"mc":[{"id":"1.168135803","rc":[{"batb":[[0,2.36,143.91],[1,1.95,695.9],[2,1.25,29.55]],"ltp":2.72,"tv":3986.13,"id":5720747}]}]}
{"op":"mcm","clk":"1005606317","pt":1580643556708,"mc":[{"id":"1.168135803","rc":[{"batb":[[0,1.52,336.21],[1,1.51,391.58],[2,1.5,402.56]],"ltp":1.57,"tv":7304.71,"id":2249229}]}]}
{"op":"mcm","clk":"1005606559","pt":1580643557816,"mc":[{"id":"1.168135803","rc":[{"batb":[[0,2.64,106.6],[1,2.36,143.91],[2,1.95,695.9]],"ltp":2.72,"tv":3986.13,"id":5720747}]}]}
{"op":"mcm","clk":"1005606773","pt":1580643558781,"mc":[{"id":"1.168135803","rc":[{"batb":[[0,2.64,213.21]],"batl":[[0,2.86,93.26],[1,3.2,0.31]],"ltp":2.72,"tv":3986.13,"id":5720747}]}]}
{"op":"mcm","clk":"1005609770","pt":1580643573820,"mc":[{"id":"1.168135803","rc":[{"batb":[[0,1.51,391.58],[1,1.5,402.56],[2,1.46,4.25]],"ltp":1.57,"tv":7304.71,"id":2249229}]}]}
{"op":"mcm","clk":"1005609962","pt":1580643574726,"mc":[{"id":"1.168135803","rc":[{"batl":[[0,1.56,441.3],[1,1.57,331.69]],"ltp":1.57,"tv":7304.71,"id":2249229}]}]}
{"op":"mcm","clk":"1005610163","pt":1580643575806,"mc":[{"id":"1.168135803","rc":[{"batb":[[2,1.25,29.55]],"ltp":2.72,"tv":3986.13,"id":5720747}]}]}
{"op":"mcm","clk":"1005610730","pt":1580643578724,"mc":[{"id":"1.168135803","rc":[{"batb":[[0,2.36,143.91],[1,2.08,672.17]],"ltp":2.72,"tv":3986.13,"id":5720747}]}]}
{"op":"mcm","clk":"1005613930","pt":1580643593745,"mc":[{"id":"1.168135803","rc":[{"batb":[[0,1.51,463.16]],"ltp":1.57,"tv":7304.71,"id":2249229}]}]}
{"op":"mcm","clk":"1005614508","pt":1580643596668,"mc":[{"id":"1.168135803","rc":[{"trd":[[1.53,110.39]],"ltp":1.53,"tv":7306.71,"id":2249229},{"trd":[[2.86,1.07]],"batl":[[0,2.86,92.19]],"ltp":2.86,"tv":3987.2,"id":5720747}],"tv":11293.91}]}
{"op":"mcm","clk":"1005614757","pt":1580643597731,"mc":[{"id":"1.168135803","rc":[{"trd":[[1.56,116.86]],"batl":[[0,1.56,436.31]],"ltp":1.56,"tv":7311.7,"id":2249229},{"trd":[[2.78,2.8]],"ltp":2.78,"tv":3990.0,"id":5720747}],"tv":11301.7}]}
{"op":"mcm","clk":"1005615367","pt":1580643600743,"mc":[{"id":"1.168135803","rc":[{"batl":[[0,1.55,65.03],[1,1.56,436.31],[2,1.57,331.69]],"ltp":1.56,"tv":7311.7,"id":2249229}]}]}
{"op":"mcm","clk":"1005615575","pt":1580643601753,"mc":[{"id":"1.168135803","rc":[{"trd":[[2.82,25.34],[2.86,2.99]],"batl":[[0,2.86,91.24]],"ltp":2.86,"tv":4017.26,"id":5720747}],"tv":11328.96}]}
{"op":"mcm","clk":"1005616425","pt":1580643605789,"mc":[{"id":"1.168135803","rc":[{"trd":[[1.55,258.37]],"batl":[[0,1.55,28.91]],"ltp":1.55,"tv":7347.81,"id":2249229},{"trd":[[2.8,99.39]],"ltp":2.8,"tv":4037.26,"id":5720747}],"tv":11385.08}]}
{"op":"mcm","clk":"1005618553","pt":1580643616781,"mc":[{"id":"1.168135803","rc":[{"batb":[[0,1.51,391.58]],"ltp":1.55,"tv":7347.81,"id":2249229}]}]}
{"op":"mcm","clk":"1005619966","pt":1580643623778,"mc":[{"id":"1.168135803","rc":[{"batb":[[0,2.6,109.27],[1,2.36,143.91],[2,2.08,672.17]],"ltp":2.8,"tv":4037.26,"id":5720747}]}]}
{"op":"mcm","clk":"1005620164","pt":1580643624793,"mc":[{"id":"1.168135803","rc":[{"batb":[[0,1.51,321.52]],"batl":[[1,1.56,529.7]],"ltp":1.55,"tv":7347.81,"id":2249229}]}]}
{"op":"mcm","clk":"1005623167","pt":1580643640808,"mc":[{"id":"1.168135803","rc":[{"trd":[[1.55,284.06]],"batl":[[0,1.55,16.07]],"ltp":1.55,"tv":7373.5,"id":2249229}],"tv":11410.77}]}
{"op":"mcm","clk":"1005625004","pt":1580643649820,"mc":[{"id":"1.168135803","rc":[{"batb":[[0,1.5,402.56],[1,1.46,4.25],[2,1.33,189.82]],"ltp":1.55,"tv":7373.5,"id":2249229}]}]}
{"op":"mcm","clk":"1005625356","pt":1580643651728,"mc":[{"id":"1.168135803","rc":[{"batb":[[0,1.46,4.25],[1,1.33,189.82],[2,1.3,10]],"batl":[[1,1.77,11.36],[2,100,1.77]],"ltp":1.55,"tv":7373.5,"id":2249229}]}]}
{"op":"mcm","clk":"1005625531","pt":1580643652740,"mc":[{"id":"1.168135803","rc":[{"batb":[[0,1.5,288.17],[1,1.49,415.27],[2,1.46,4.25]],"ltp":1.55,"tv":7373.5,"id":2249229}]}]}
{"op":"mcm","clk":"1005625734","pt":1580643653812,"mc":[{"id":"1.168135803","rc":[{"batb":[[0,1.46,4.25],[1,1.33,189.82],[2,1.3,10]],"ltp":1.55,"tv":7373.5,"id":2249229}]}]}
{"op":"mcm","clk":"1005625921","pt":1580643654725,"mc":[{"id":"1.168135803","rc":[{"trd":[[1.55,304.06]],"batl":[[0,1.55,6.07]],"ltp":1.55,"tv":7393.5,"id":2249229}],"tv":11430.77}]}
{"op":"mcm","clk":"1005626122","pt":1580643655735,"mc":[{"id":"1.168135803","rc":[{"trd":[[1.53,110.57]],"batb":[[1,1.39,643.77],[2,1.38,580.58]],"batl":[[1,1.64,514.83],[2,1.65,277.97]],"ltp":1.53,"tv":7393.68,"id":2249229},{"trd":[[2.86,3.08]],"batl":[[0,2.86,91.14]],"ltp":2.86,"tv":4037.35,"id":5720747}],"tv":11431.04}]}
{"op":"mcm","clk":"1005626909","pt":1580643659754,"mc":[{"id":"1.168135803","rc":[{"batb":[[1,2.08,672.17],[2,1.25,29.55]],"ltp":2.86,"tv":4037.35,"id":5720747}]}]}
{"op":"mcm","clk":"1005627299","pt":1580643661751,"mc":[{"id":"1.168135803","rc":[{"batb":[[1,1.4,437.08],[2,1.39,643.77]],"ltp":1.53,"tv":7393.68,"id":2249229}]}]}
{"op":"mcm","clk":"1005627465","pt":1580643662617,"mc":[{"id":"1.168135803","rc":[{"batb":[[1,1.41,426.42],[2,1.4,437.08]],"ltp":1.53,"tv":7393.68,"id":2249229}]}]}
{"op":"mcm","clk":"1005627930","pt":1580643664728,"mc":[{"id":"1.168135803","rc":[{"batb":[[0,2.6,218.54]],"ltp":2.86,"tv":4037.35,"id":5720747}]}]}
{"op":"mcm","clk":"1005629367","pt":1580643671758,"mc":[{"id":"1.168135803","rc":[{"batl":[[0,3.2,0.31],[1,3.2,0]],"ltp":2.86,"tv":4037.35,"id":5720747}]}]}
{"op":"mcm","clk":"1005630316","pt":1580643676749,"mc":[{"id":"1.168135803","rc":[{"batl":[[1,1.77,11.36],[2,100,1.77]],"ltp":1.53,"tv":7393.68,"id":2249229}]}]}
{"op":"mcm","clk":"1005631490","pt":1580643682752,"mc":[{"id":"1.168135803","rc":[{"batl":[[1,1.64,514.83],[2,1.65,277.97]],"ltp":1.53,"tv":7393.68,"id":2249229}]}]}
{"op":"mcm","clk":"1005633125","pt":1580643690779,"mc":[{"id":"1.168135803","rc":[{"batl":[[0,3.25,2.31]],"ltp":2.86,"tv":4037.35,"id":5720747}]}]}
{"op":"mcm","clk":"1005634467","pt":1580643697717,"mc":[{"id":"1.168135803","rc":[{"batl":[[1,1.77,11.36],[2,100,1.77]],"ltp":1.53,"tv":7393.68,"id":2249229}]}]}
{"op":"mcm","clk":"1005634833","pt":1580643699595,"mc":[{"id":"1.168135803","rc":[{"batb":[[1,1.39,643.77],[2,1.38,580.58]],"ltp":1.53,"tv":7393.68,"id":2249229}]}]}
{"op":"mcm","clk":"1005635051","pt":1580643700721,"mc":[{"id":"1.168135803","rc":[{"trd":[[1.44,4.51],[1.45,0.67],[1.46,8.46],[1.48,0.05]],"batb":[[0,1.39,643.77],[1,1.38,580.58],[2,1.33,189.82]],"batl":[[0,1.43,386.44],[1,1.44,468.26],[2,1.55,6.07]],"ltp":1.44,"tv":7407.36,"id":2249229},{"trd":[[3.2,0.31],[3.25,2]],"ltp":3.25,"tv":4039.66,"id":5720747}],"tv":11447.02}]}
{"op":"mcm","clk":"1005635270","pt":1580643701692,"mc":[{"id":"1.168135803","rc":[{"batb":[[2,1.3,10.02]],"batl":[[0,1.44,468.26],[1,1.55,6.07],[2,1.77,11.36]],"ltp":1.44,"tv":7407.36,"id":2249229},{"batb":[[1,1.25,29.55],[2,1.05,16.8]],"ltp":3.25,"tv":4039.66,"id":5720747}]}]}
{"op":"mcm","clk":"1005635633","pt":1580643703718,"mc":[{"id":"1.168135803","rc":[{"batb":[[0,1.25,29.55],[1,1.05,16.8],[2,1.04,21]],"ltp":3.25,"tv":4039.66,"id":5720747}]}]}
{"op":"mcm","clk":"1005635851","pt":1580643704727,"mc":[{"id":"1.168135803","rc":[{"batb":[[0,1.39,785.01]],"batl":[[0,1.44,741.32],[1,1.45,450.81],[2,1.55,6.07]],"ltp":1.44,"tv":7407.36,"id":2249229},{"batb":[[0,2.26,644.1],[1,1.25,29.55],[2,1.05,16.8]],"ltp":3.25,"tv":4039.66,"id":5720747}]}]}
{"op":"mcm","clk":"1005636061","pt":1580643705781,"mc":[{"id":"1.168135803","rc":[{"batb":[[0,1.39,555.86],[1,1.3,10.02],[2,1.27,198.96]],"batl":[[0,1.44,618.18]],"ltp":1.44,"tv":7407.36,"id":2249229},{"batb":[[0,2.86,93.99],[1,2.26,644.1],[2,1.25,29.55]],"ltp":3.25,"tv":4039.66,"id":5720747}]}]}
{"op":"mcm","clk":"1005636703","pt":1580643708812,"mc":[{"id":"1.168135803","rc":[{"batb":[[0,1.4,354.36],[1,1.39,555.86],[2,1.31,563.99]],"ltp":1.44,"tv":7407.36,"id":2249229}]}]}
{"op":"mcm","clk":"1005637729","pt":1580643713745,"mc":[{"id":"1.168135803","rc":[{"batb":[[0,1.31,563.99],[1,1.3,10],[2,1.27,198.96]],"batl":[[0,1.55,6.07],[1,1.77,11.36],[2,100,1.77]],"ltp":1.44,"tv":7407.36,"id":2249229}]}]}
{"op":"mcm","clk":"1005638106","pt":1580643715613,"mc":[{"id":"1.168135803","rc":[{"batl":[[0,1.39,100],[1,1.55,6.07],[2,1.77,11.36]],"ltp":1.44,"tv":7407.36,"id":2249229}]}]}
{"op":"mcm","clk":"1005640287","pt":1580643725716,"mc":[{"id":"1.168135803","rc":[{"batb":[[0,1.3,10.02],[1,1.27,198.96],[2,1.2,5]],"ltp":1.44,"tv":7407.36,"id":2249229}]}]}
{"op":"mcm","clk":"1005640688","pt":1580643727765,"mc":[{"id":"1.168135803","rc":[{"trd":[[1.39,7.58]],"batb":[[1,1.27,893.74],[2,1.26,926.45]],"batl":[[0,1.39,96.21],[1,1.54,461.28],[2,1.55,352.35]],"ltp":1.39,"tv":7414.93,"id":2249229}],"tv":11454.6}]}
{"op":"mcm","clk":"1005640881","pt":1580643728742,"mc":[{"id":"1.168135803","rc":[{"trd":[[1.39,84.2]],"batl":[[0,1.39,19.59]],"ltp":1.39,"tv":7491.55,"id":2249229},{"trd":[[3.55,30]],"ltp":3.55,"tv":4069.66,"id":5720747}],"tv":11561.22}]}
{"op":"mcm","clk":"1005641654","pt":1580643732759,"mc":[{"id":"1.168135803","rc":[{"batb":[[0,2.88,92.99],[1,2.86,93.99],[2,2.26,644.1]],"ltp":3.55,"tv":4069.66,"id":5720747}]}]}
{"op":"mcm","clk":"1005642019","pt":1580643734757,"mc":[{"id":"1.168135803","rc":[{"batb":[[1,1.28,624.4],[2,1.27,198.96]],"ltp":1.39,"tv":7491.55,"id":2249229}]}]}
{"op":"mcm","clk":"1005642177","pt":1580643735657,"mc":[{"id":"1.168135803","rc":[{"batb":[[0,2.26,644.1],[1,1.25,29.55],[2,1.05,16.8]],"ltp":3.55,"tv":4069.66,"id":5720747}]}]}
{"op":"mcm","clk":"1005642400","pt":1580643736761,"mc":[{"id":"1.168135803","rc":[{"batb":[[2,1.2,5]],"ltp":1.39,"tv":7491.55,"id":2249229}]}]}
{"op":"mcm","clk":"1005642596","pt":1580643737718,"mc":[{"id":"1.168135803","rc":[{"trd":[[1.39,123.38]],"batb":[[0,1.49,548.58],[1,1.48,422.85],[2,1.46,285.43]],"batl":[[0,1.54,461.28],[1,1.55,352.35],[2,1.77,11.36]],"ltp":1.39,"tv":7530.74,"id":2249229}],"tv":11600.4}]}
{"op":"mcm","clk":"1005642796","pt":1580643738742,"mc":[{"id":"1.168135803","rc":[{"batl":[[0,3.2,17.42]],"ltp":3.55,"tv":4069.66,"id":5720747}]}]}
{"op":"mcm","clk":"1005643203","pt":1580643740778,"mc":[{"id":"1.168135803","rc":[{"batb":[[2,1.33,146.55]],"ltp":1.39,"tv":7530.74,"id":2249229}]}]}
{"op":"mcm","clk":"1005643739","pt":1580643743743,"mc":[{"id":"1.168135803","rc":[{"trd":[[1.49,36.58]],"batb":[[0,1.49,530.3],[2,1.38,460.08]],"ltp":1.49,"tv":7567.3,"id":2249229},{"batl":[[0,3.55,39]],"ltp":3.55,"tv":4069.66,"id":5720747}],"tv":11636.96}]}
{"op":"mcm","clk":"1005644564","pt":1580643747759,"mc":[{"id":"1.168135803","rc":[{"batb":[[0,2.6,109.27],[1,2.26,644.1],[2,1.25,29.55]],"ltp":3.55,"tv":4069.66,"id":5720747}]}]}
{"op":"mcm","clk":"1005644731","pt":1580643748685,"mc":[{"id":"1.168135803","rc":[{"batb":[[2,1.33,146.55]],"ltp":1.49,"tv":7567.3,"id":2249229}]}]}
{"op":"mcm","clk":"1005644945","pt":1580643749768,"mc":[{"id":"1.168135803","rc":[{"batb":[[0,1.33,146.55],[1,1.3,10],[2,1.22,8.86]],"batl":[[0,1.55,6.07],[1,1.77,11.36],[2,1.77,0]],"ltp":1.49,"tv":7567.3,"id":2249229}]}]}
{"op":"mcm","clk":"1005645135","pt":1580643750792,"mc":[{"id":"1.168135803","rc":[{"batb":[[0,1.4,437.08],[1,1.33,146.55],[2,1.3,10]],"ltp":1.49,"tv":7567.3,"id":2249229}]}]}
{"op":"mcm","clk":"1005645957","pt":1580643754755,"mc":[{"id":"1.168135803","rc":[{"trd":[[1.55,310.13]],"batb":[[1,1.35,854.6],[2,1.34,665.68]],"batl":[[0,1.64,302.15],[1,1.65,276.76],[2,1.77,11.36]],"ltp":1.55,"tv":7573.37,"id":2249229},{"trd":[[2.8,102.75]],"batl":[[0,3.55,39.64]],"ltp":2.8,"tv":4073.02,"id":5720747}],"tv":11646.39}]}
{"op":"mcm","clk":"1005646405","pt":1580643756789,"mc":[{"id":"1.168135803","rc":[{"batl":[[0,2.84,4],[1,3.55,39]],"ltp":2.8,"tv":4073.02,"id":5720747}]}]}
{"op":"mcm","clk":"1005646613","pt":1580643757770,"mc":[{"id":"1.168135803","rc":[{"trd":[[1.54,6.2],[1.56,117.99]],"batl":[[0,1.49,9.92],[1,1.64,302.15],[2,1.65,276.76]],"ltp":1.54,"tv":7580.7,"id":2249229},{"trd":[[2.76,6.29],[2.84,3.36]],"batl":[[0,3.55,39],[1,3.55,0]],"ltp":2.84,"tv":4077.02,"id":5720747}],"tv":11657.72}]}
{"op":"mcm","clk":"1005646824","pt":1580643758769,"mc":[{"id":"1.168135803","rc":[{"batb":[[0,1.35,854.6],[1,1.34,665.68],[2,1.33,146.53]],"ltp":1.54,"tv":7580.7,"id":2249229}]}]}
{"op":"mcm","clk":"1005647228","pt":1580643760795,"mc":[{"id":"1.168135803","rc":[{"trd":[[1.49,46.5]],"batl":[[0,1.64,302.15],[1,1.65,276.76],[2,1.77,11.36]],"ltp":1.49,"tv":7590.62,"id":2249229},{"trd":[[3,4.92]],"batb":[[1,2.58,110.65],[2,2.26,644.1]],"batl":[[0,2.84,32.89],[1,3.55,39]],"ltp":3.0,"tv":4081.94,"id":5720747}],"tv":11672.57}]}
{"op":"mcm","clk":"1005647400","pt":1580643761669,"mc":[{"id":"1.168135803","rc":[{"batb":[[0,1.36,485.64],[1,1.35,854.6],[2,1.34,665.68]],"ltp":1.49,"tv":7590.62,"id":2249229}]}]}
{"op":"mcm","clk":"1005647612","pt":1580643762806,"mc":[{"id":"1.168135803","rc":[{"batb":[[0,1.36,971.28]],"ltp":1.49,"tv":7590.62,"id":2249229}]}]}
{"op":"mcm","clk":"1005648562","pt":1580643767782,"mc":[{"id":"1.168135803","rc":[{"batb":[[1,1.33,146.55],[2,1.3,10]],"ltp":1.49,"tv":7590.62,"id":2249229}]}]}
{"op":"mcm","clk":"1005648890","pt":1580643769603,"mc":[{"id":"1.168135803","rc":[{"batb":[[0,2.26,644.1],[1,1.49,14.01],[2,1.25,29.54]],"ltp":3.0,"tv":4081.94,"id":5720747}]}]}
{"op":"mcm","clk":"1005649093","pt":1580643770727,"mc":[{"id":"1.168135803","rc":[{"batb":[[0,1.59,301.59],[1,1.58,326.07],[2,1.36,971.28]],"ltp":1.49,"tv":7590.62,"id":2249229},{"batb":[[0,1.49,14.01],[1,1.25,29.54],[2,1.05,16.8]],"ltp":3.0,"tv":4081.94,"id":5720747}]}]}
{"op":"mcm","clk":"1005649888","pt":1580643774684,"mc":[{"id":"1.168135803","rc":[{"batb":[[2,1.39,142.61]],"ltp":1.49,"tv":7590.62,"id":2249229},{"batb":[[0,1.95,769.78],[1,1.49,14.01],[2,1.25,29.54]],"ltp":3.0,"tv":4081.94,"id":5720747}]}]}
{"op":"mcm","clk":"1005650611","pt":1580643778619,"mc":[{"id":"1.168135803","rc":[{"batb":[[2,1.5,349.66]],"ltp":1.49,"tv":7590.62,"id":2249229}]}]}
{"op":"mcm","clk":"1005650830","pt":1580643779705,"mc":[{"id":"1.168135803","rc":[{"batb":[[0,2.3,134.49],[1,1.95,769.78],[2,1.49,14.01]],"ltp":3.0,"tv":4081.94,"id":5720747}]}]}
{"op":"mcm","clk":"1005651602","pt":1580643783723,"mc":[{"id":"1.168135803","rc":[{"batb":[[0,1.5,349.66],[1,1.39,142.61],[2,1.3,10.02]],"batl":[[0,1.77,11.36],[1,1.65,0],[2,1.77,0]],"ltp":1.49,"tv":7590.62,"id":2249229}]}]}
{"op":"mcm","clk":"1005652188","pt":1580643786696,"mc":[{"id":"1.168135803","rc":[{"batb":[[1,1.46,733.58],[2,1.45,462.09]],"batl":[[0,1.73,397.22],[1,1.75,456.11],[2,1.77,11.36]],"ltp":1.49,"tv":7590.62,"id":2249229}]}]}
{"op":"mcm","clk":"1005652727","pt":1580643789537,"mc":[{"id":"1.168135803","rc":[{"batb":[[0,1.95,769.78],[1,1.49,14.01],[2,1.25,29.54]],"ltp":3.0,"tv":4081.94,"id":5720747}]}]}
{"op":"mcm","clk":"1005652937","pt":1580643790623,"mc":[{"id":"1.168135803","rc":[{"batb":[[1,1.47,371.98],[2,1.46,733.58]],"ltp":1.49,"tv":7590.62,"id":2249229}]}]}
{"op":"mcm","clk":"1005653542","pt":1580643793718,"mc":[{"id":"1.168135803","rc":[{"batb":[[0,1.47,371.98],[1,1.46,733.58],[2,1.45,462.09]],"ltp":1.49,"tv":7590.62,"id":2249229},{"batb":[[0,2.38,126.69],[1,1.95,769.78],[2,1.49,14.01]],"ltp":3.0,"tv":4081.94,"id":5720747}]}]}
{"op":"mcm","clk":"1005653687","pt":1580643794420,"mc":[{"id":"1.168135803","rc":[{"batb":[[0,2.38,253.38]],"batl":[[1,3.55,0]],"ltp":3.0,"tv":4081.94,"id":5720747}]}]}
{"op":"mcm","clk":"1005653941","pt":1580643795660,"mc":[{"id":"1.168135803","rc":[{"batb":[[0,1.48,364.23],[1,1.47,371.98],[2,1.46,733.58]],"ltp":1.49,"tv":7590.62,"id":2249229}]}]}
{"op":"mcm","clk":"1005654757","pt":1580643799628,"mc":[{"id":"1.168135803","rc":[{"batb":[[2,1.46,445.7]],"batl":[[0,1.73,291.6]],"ltp":1.49,"tv":7590.62,"id":2249229}]}]}
{"op":"mcm","clk":"1005655186","pt":1580643801719,"mc":[{"id":"1.168135803","rc":[{"batb":[[1,1.47,784.16]],"ltp":1.49,"tv":7590.62,"id":2249229}]}]}
{"op":"mcm","clk":"1005655539","pt":1580643803624,"mc":[{"id":"1.168135803","rc":[{"batl":[[0,1.77,11.36],[1,1.75,0],[2,1.77,0]],"ltp":1.49,"tv":7590.62,"id":2249229}]}]}
{"op":"mcm","clk":"1005656100","pt":1580643806616,"mc":[{"id":"1.168135803","rc":[{"batb":[[1,1.47,877.3]],"batl":[[0,1.74,443.61],[1,1.76,446.84],[2,1.77,11.36]],"ltp":1.49,"tv":7590.62,"id":2249229}]}]}
{"op":"mcm","clk":"1005657948","pt":1580643816636,"mc":[{"id":"1.168135803","rc":[{"batb":[[1,1.49,14.01],[2,1.25,29.54]],"ltp":3.0,"tv":4081.94,"id":5720747}]}]}
{"op":"mcm","clk":"1005658350","pt":1580643818769,"mc":[{"id":"1.168135803","rc":[{"batb":[[1,1.47,371.98],[2,1.3,10.02]],"batl":[[0,1.77,11.36],[1,1.76,0],[2,1.77,0]],"ltp":1.49,"tv":7590.62,"id":2249229}]}]}
{"op":"mcm","clk":"1005658704","pt":1580643820783,"mc":[{"id":"1.168135803","rc":[{"trd":[[1.54,66.85]],"batb":[[0,1.3,10.02],[1,1.22,8.86],[2,1.2,5]],"batl":[[0,1.54,79.67],[1,1.77,11.36]],"ltp":1.54,"tv":7651.27,"id":2249229},{"trd":[[2.84,36.25]],"ltp":2.84,"tv":4114.83,"id":5720747}],"tv":11766.1}]}
{"op":"mcm","clk":"1005658890","pt":1580643821757,"mc":[{"id":"1.168135803","rc":[{"batb":[[0,1.47,559],[1,1.46,445.89],[2,1.3,10.02]],"batl":[[0,1.52,476.2],[1,1.53,361.86],[2,1.54,79.67]],"ltp":1.54,"tv":7651.27,"id":2249229}]}]}
{"op":"mcm","clk":"1005659072","pt":1580643822740,"mc":[{"id":"1.168135803","rc":[{"batl":[[2,1.77,11.36]],"ltp":1.54,"tv":7651.27,"id":2249229}]}]}
{"op":"mcm","clk":"1005659454","pt":1580643824728,"mc":[{"id":"1.168135803","rc":[{"batb":[[0,1.49,14.01],[1,1.25,29.54],[2,1.05,16.8]],"ltp":2.84,"tv":4114.83,"id":5720747}]}]}
{"op":"mcm","clk":"1005659642","pt":1580643825748,"mc":[{"id":"1.168135803","rc":[{"trd":[[1.52,451.32]],"batl":[[0,1.52,415.16]],"ltp":1.52,"tv":7773.35,"id":2249229}],"tv":11888.18}]}
{"op":"mcm","clk":"1005659847","pt":1580643826743,"mc":[{"id":"1.168135803","rc":[{"batb":[[2,1.33,136.52]],"ltp":1.52,"tv":7773.35,"id":2249229},{"batb":[[0,2.08,734.78],[1,1.49,14.01],[2,1.25,29.54]],"ltp":2.84,"tv":4114.83,"id":5720747}]}]}
{"op":"mcm","clk":"1005660062","pt":1580643827763,"mc":[{"id":"1.168135803","rc":[{"batb":[[0,1.33,136.52],[1,1.3,10],[2,1.22,8.86]],"batl":[[0,1.77,11.36],[1,1.53,0],[2,1.77,0]],"ltp":1.52,"tv":7773.35,"id":2249229}]}]}
{"op":"mcm","clk":"1005660396","pt":1580643829787,"mc":[{"id":"1.168135803","rc":[{"batb":[[0,2.6,109.27],[1,2.08,734.78],[2,1.49,14.01]],"ltp":2.84,"tv":4114.83,"id":5720747}]}]}
{"op":"mcm","clk":"1005660577","pt":1580643830799,"mc":[{"id":"1.168135803","rc":[{"batb":[[2,1.29,875.09]],"batl":[[0,1.66,305.96],[1,1.67,264.81],[2,1.77,11.36]],"ltp":1.52,"tv":7773.35,"id":2249229}]}]}
{"op":"mcm","clk":"1005660771","pt":1580643831772,"mc":[{"id":"1.168135803","rc":[{"batb":[[2,1.22,8.86]],"ltp":1.52,"tv":7773.35,"id":2249229}]}]}
{"op":"mcm","clk":"1005661142","pt":1580643833791,"mc":[{"id":"1.168135803","rc":[{"batb":[[0,2.08,734.78],[1,1.49,14.01],[2,1.25,29.54]],"ltp":2.84,"tv":4114.83,"id":5720747}]}]}
{"op":"mcm","clk":"1005661312","pt":1580643834814,"mc":[{"id":"1.168135803","rc":[{"batb":[[0,1.64,219.23],[1,1.6,548.73],[2,1.59,318.74]],"ltp":1.52,"tv":7773.35,"id":2249229}]}]}
{"op":"mcm","clk":"1005661520","pt":1580643835785,"mc":[{"id":"1.168135803","rc":[{"batb":[[0,1.6,548.73],[1,1.59,318.74],[2,1.52,20]],"ltp":1.52,"tv":7773.35,"id":2249229}]}]}
{"op":"mcm","clk":"1005662058","pt":1580643838712,"mc":[{"id":"1.168135803","rc":[{"batb":[[0,2.32,132.45],[1,2.08,734.78],[2,1.49,14.01]],"ltp":2.84,"tv":4114.83,"id":5720747}]}]}
{"op":"mcm","clk":"1005662471","pt":1580643840785,"mc":[{"id":"1.168135803","rc":[{"batb":[[1,2.3,134.49],[2,2.08,734.78]],"ltp":2.84,"tv":4114.83,"id":5720747}]}]}
{"op":"mcm","clk":"1005662836","pt":1580643842780,"mc":[{"id":"1.168135803","rc":[{"batb":[[2,1.53,329.87]],"ltp":1.52,"tv":7773.35,"id":2249229}]}]}
{"op":"mcm","clk":"1005663166","pt":1580643844763,"mc":[{"id":"1.168135803","rc":[{"trd":[[1.6,432.19]],"batb":[[0,1.6,126.53]],"ltp":1.6,"tv":8195.55,"id":2249229},{"trd":[[2.68,255.09]],"ltp":2.68,"tv":4366.89,"id":5720747}],"tv":12562.44}]}
{"op":"mcm","clk":"1005663684","pt":1580643847769,"mc":[{"id":"1.168135803","rc":[{"batb":[[0,1.6,304.46],[1,1.53,329.87],[2,1.52,20]],"batl":[[0,1.66,113.5],[1,1.77,11.36],[2,1.77,0]],"ltp":1.6,"tv":8195.55,"id":2249229}]}]}
{"op":"mcm","clk":"1005663832","pt":1580643848696,"mc":[{"id":"1.168135803","rc":[{"batb":[[0,1.53,329.87],[1,1.52,20],[2,1.48,364.23]],"batl":[[0,1.77,11.36],[1,1.77,0]],"ltp":1.6,"tv":8195.55,"id":2249229}]}]}
{"op":"mcm","clk":"1005664758","pt":1580643853771,"mc":[{"id":"1.168135803","rc":[{"batl":[[0,1.76,341.24],[1,1.77,11.36],[2,1.78,433.81]],"ltp":1.6,"tv":8195.55,"id":2249229}]}]}
{"op":"mcm","clk":"1005665105","pt":1580643855685,"mc":[{"id":"1.168135803","rc":[{"batb":[[0,1.52,20],[1,1.48,364.23],[2,1.46,617.11]],"ltp":1.6,"tv":8195.55,"id":2249229}]}]}
{"op":"mcm","clk":"1005665289","pt":1580643856792,"mc":[{"id":"1.168135803","rc":[{"trd":[[1.76,126.73]],"batl":[[0,1.76,321.24]],"ltp":1.76,"tv":8235.55,"id":2249229}],"tv":12602.44}]}
{"op":"mcm","clk":"1005665659","pt":1580643858779,"mc":[{"id":"1.168135803","rc":[{"batl":[[0,3,93.26]],"ltp":2.68,"tv":4366.89,"id":5720747}]}]}
{"op":"mcm","clk":"1005665809","pt":1580643859675,"mc":[{"id":"1.168135803","rc":[{"batb":[[2,1.47,371.98]],"ltp":1.76,"tv":8235.55,"id":2249229}]}]}
{"op":"mcm","clk":"1005666008","pt":1580643860793,"mc":[{"id":"1.168135803","rc":[{"batl":[[0,1.77,11.36],[1,1.77,0],[2,1.78,0]],"ltp":1.76,"tv":8235.55,"id":2249229}]}]}
{"op":"mcm","clk":"1005667386","pt":1580643868804,"mc":[{"id":"1.168135803","rc":[{"batl":[[0,1.76,305.36],[1,1.77,11.36],[2,1.78,433.82]],"ltp":1.76,"tv":8235.55,"id":2249229}]}]}
{"op":"mcm","clk":"1005671705","pt":1580643892734,"mc":[{"id":"1.168135803","rc":[{"batl":[[0,1.77,11.36],[1,1.77,0],[2,1.78,0]],"ltp":1.76,"tv":8235.55,"id":2249229}]}]}
{"op":"mcm","clk":"1005672219","pt":1580643895519,"mc":[{"id":"1.168135803","rc":[{"batl":[[0,1.6,140.31],[1,1.77,11.36]],"ltp":1.76,"tv":8235.55,"id":2249229},{"batb":[[2,1.49,14.01]],"ltp":2.68,"tv":4366.89,"id":5720747}]}]}
{"op":"mcm","clk":"1005672406","pt":1580643896644,"mc":[{"id":"1.168135803","rc":[{"trd":[[1.52,491.32]],"batb":[[0,1.46,660.56],[1,1.45,459.93],[2,1.3,10.02]],"batl":[[0,1.51,408.65],[1,1.52,371.45],[2,1.6,140.31]],"ltp":1.52,"tv":8275.55,"id":2249229},{"batb":[[0,1.49,14.01],[1,1.25,29.54],[2,1.05,16.8]],"ltp":2.68,"tv":4366.89,"id":5720747}],"tv":12642.44}]}
{"op":"mcm","clk":"1005672955","pt":1580643899732,"mc":[{"id":"1.168135803","rc":[{"batb":[[0,2.18,721.58],[1,1.49,14.01],[2,1.25,29.54]],"ltp":2.68,"tv":4366.89,"id":5720747}]}]}
{"op":"mcm","clk":"1005673155","pt":1580643900759,"mc":[{"id":"1.168135803","rc":[{"batl":[[2,1.77,11.36]],"ltp":1.52,"tv":8275.55,"id":2249229}]}]}
{"op":"mcm","clk":"1005674637","pt":1580643907754,"mc":[{"id":"1.168135803","rc":[{"batb":[[0,1.3,10.02],[1,1.29,153.83],[2,1.22,8.86]],"batl":[[0,1.77,11.36],[1,1.52,0],[2,1.77,0]],"ltp":1.52,"tv":8275.55,"id":2249229}]}]}
{"op":"mcm","clk":"1005674831","pt":1580643908730,"mc":[{"id":"1.168135803","rc":[{"batb":[[0,1.3,10.42]],"ltp":1.52,"tv":8275.55,"id":2249229}]}]}
{"op":"mcm","clk":"1005675677","pt":1580643912758,"mc":[{"id":"1.168135803","rc":[{"batb":[[1,1.29,620.34],[2,1.28,834.4]],"batl":[[0,1.65,309.57],[1,1.66,270.49],[2,1.77,11.36]],"ltp":1.52,"tv":8275.55,"id":2249229}]}]}
{"op":"mcm","clk":"1005676648","pt":1580643917732,"mc":[{"id":"1.168135803","rc":[{"trd":[[1.5,41.61],[1.52,492.12]],"batb":[[0,1.3,10.02]],"ltp":1.5,"tv":8317.96,"id":2249229},{"trd":[[3,25.73]],"batl":[[0,3,72.46]],"ltp":3.0,"tv":4387.69,"id":5720747}],"tv":12705.65}]}
{"op":"mcm","clk":"1005677049","pt":1580643919756,"mc":[{"id":"1.168135803","rc":[{"batl":[[0,2.98,2],[1,3,72.46]],"ltp":3.0,"tv":4387.69,"id":5720747}]}]}
{"op":"mcm","clk":"1005677774","pt":1580643923562,"mc":[{"id":"1.168135803","rc":[{"batb":[[0,1.5,4.22],[1,1.3,10.02],[2,1.29,620.34]],"ltp":1.5,"tv":8317.96,"id":2249229}]}]}
{"op":"mcm","clk":"1005677978","pt":1580643924781,"mc":[{"id":"1.168135803","rc":[{"batl":[[0,3,72.46],[1,3,0]],"ltp":3.0,"tv":4387.69,"id":5720747}]}]}
{"op":"mcm","clk":"1005679734","pt":1580643934190,"mc":[{"id":"1.168135803","rc":[{"batl":[[0,4.4,55.45]],"ltp":3.0,"tv":4387.69,"id":5720747}]}]}
{"op":"mcm","clk":"1005679998","pt":1580643935681,"mc":[{"id":"1.168135803","rc":[{"trd":[[1.5,50.05]],"batb":[[0,1.3,10.02],[1,1.29,620.34],[2,1.28,834.4]],"ltp":1.5,"tv":8326.4,"id":2249229}],"tv":12714.09}]}
{"op":"mcm","clk":"1005680571","pt":1580643938507,"mc":[{"id":"1.168135803","rc":[{"batb":[[1,1.29,153.83],[2,1.22,8.86]],"ltp":1.5,"tv":8326.4,"id":2249229}]}]}
{"op":"mcm","clk":"1005681005","pt":1580643940804,"mc":[{"id":"1.168135803","rc":[{"batb":[[0,1.57,246.16],[1,1.3,10.02],[2,1.29,153.83]],"ltp":1.5,"tv":8326.4,"id":2249229}]}]}
{"op":"mcm","clk":"1005681166","pt":1580643941669,"mc":[{"id":"1.168135803","rc":[{"batb":[[0,1.59,561.86],[1,1.58,326.68],[2,1.57,246.16]],"ltp":1.5,"tv":8326.4,"id":2249229}]}]}
{"op":"mcm","clk":"1005681368","pt":1580643942785,"mc":[{"id":"1.168135803","rc":[{"batb":[[0,1.49,14.01],[1,1.25,29.54],[2,1.05,16.8]],"ltp":3.0,"tv":4387.69,"id":5720747}]}]}
{"op":"mcm","clk":"1005681649","pt":1580643944612,"mc":[{"id":"1.168135803","rc":[{"trd":[[1.59,438.58]],"batb":[[0,1.59,545.07]],"ltp":1.59,"tv":8359.98,"id":2249229}],"tv":12747.67}]}
{"op":"mcm","clk":"1005682083","pt":1580643946803,"mc":[{"id":"1.168135803","rc":[{"batb":[[2,1.39,143.77]],"ltp":1.59,"tv":8359.98,"id":2249229},{"batb":[[0,1.95,770.6],[1,1.49,14.01],[2,1.25,29.54]],"ltp":3.0,"tv":4387.69,"id":5720747}]}]}
{"op":"mcm","clk":"1005683021","pt":1580643951716,"mc":[{"id":"1.168135803","rc":[{"trd":[[1.65,537.29]],"batl":[[0,1.65,294.48]],"ltp":1.65,"tv":8390.16,"id":2249229}],"tv":12777.85}]}
{"op":"mcm","clk":"1005683398","pt":1580643953694,"mc":[{"id":"1.168135803","rc":[{"batb":[[0,1.39,143.77],[1,1.3,10.02],[2,1.22,8.86]],"batl":[[0,1.77,11.36],[1,1.66,0],[2,1.77,0]],"ltp":1.65,"tv":8390.16,"id":2249229}]}]}
{"op":"mcm","clk":"1005683940","pt":1580643956811,"mc":[{"id":"1.168135803","rc":[{"batb":[[0,1.46,317.38],[1,1.45,457.45],[2,1.39,143.77]],"batl":[[0,1.75,305.61],[1,1.77,453.3]],"ltp":1.65,"tv":8390.16,"id":2249229}]}]}
{"op":"mcm","clk":"1005684266","pt":1580643958723,"mc":[{"id":"1.168135803","rc":[{"trd":[[1.75,0.14]],"batl":[[0,1.75,305.54]],"ltp":1.75,"tv":8390.3,"id":2249229}],"tv":12777.99}]}
{"op":"mcm","clk":"1005685035","pt":1580643962703,"mc":[{"id":"1.168135803","rc":[{"batl":[[0,2.58,55.45]],"ltp":3.0,"tv":4387.69,"id":5720747}]}]}
{"op":"mcm","clk":"1005686465","pt":1580643970405,"mc":[{"id":"1.168135803","rc":[{"batl":[[0,1.74,50],[1,1.75,305.54],[2,1.77,453.3]],"ltp":1.75,"tv":8390.3,"id":2249229}]}]}
{"op":"mcm","clk":"1005686901","pt":1580643972802,"mc":[{"id":"1.168135803","rc":[{"batb":[[0,2.58,50],[1,1.95,770.6],[2,1.49,14.01]],"ltp":3.0,"tv":4387.69,"id":5720747}]}]}
{"op":"mcm","clk":"1005687737","pt":1580643977812,"mc":[{"id":"1.168135803","rc":[{"batb":[[0,1.47,106.38],[1,1.46,317.38],[2,1.45,457.45]],"ltp":1.75,"tv":8390.3,"id":2249229},{"batl":[[0,3,93.26]],"ltp":3.0,"tv":4387.69,"id":5720747}]}]}
{"op":"mcm","clk":"1005688059","pt":1580643979717,"mc":[{"id":"1.168135803","rc":[{"batb":[[1,1.39,143.77],[2,1.3,10.02]],"ltp":1.75,"tv":8390.3,"id":2249229}]}]}
{"op":"mcm","clk":"1005688272","pt":1580643980730,"mc":[{"id":"1.168135803","rc":[{"batl":[[0,1.75,305.54],[1,1.77,453.3],[2,1.77,0]],"ltp":1.75,"tv":8390.3,"id":2249229}]}]}
{"op":"mcm","clk":"1005688463","pt":1580643981741,"mc":[{"id":"1.168135803","rc":[{"trd":[[1.64,116.52]],"batb":[[0,1.64,140.57],[1,1.47,106.38],[2,1.39,143.77]],"ltp":1.64,"tv":8468.95,"id":2249229},{"trd":[[2.58,50]],"batb":[[0,1.95,770.6],[1,1.49,14.01],[2,1.25,29.54]],"ltp":2.58,"tv":4437.69,"id":5720747}],"tv":12906.65}]}
{"op":"mcm","clk":"1005688626","pt":1580643982756,"mc":[{"id":"1.168135803","rc":[{"batb":[[0,1.69,303.55],[1,1.68,261.28],[2,1.64,140.57]],"ltp":1.64,"tv":8468.95,"id":2249229}]}]}
{"op":"mcm","clk":"1005688809","pt":1580643983811,"mc":[{"id":"1.168135803","rc":[{"batb":[[2,1.47,106.38]],"ltp":1.64,"tv":8468.95,"id":2249229}]}]}
{"op":"mcm","clk":"1005688970","pt":1580643984816,"mc":[{"id":"1.168135803","rc":[{"batb":[[2,1.3,10.02]],"ltp":1.64,"tv":8468.95,"id":2249229}]}]}
{"op":"mcm","clk":"1005689289","pt":1580643986726,"mc":[{"id":"1.168135803","rc":[{"trd":[[1.69,152.66]],"batb":[[0,1.69,227.22],[2,1.44,102.86]],"ltp":1.69,"tv":8621.62,"id":2249229}],"tv":13059.31}]}
{"op":"mcm","clk":"1005690054","pt":1580643991759,"mc":[{"id":"1.168135803","rc":[{"trd":[[1.69,360.57]],"batb":[[0,1.68,261.28],[1,1.44,102.86],[2,1.3,10.02]],"ltp":1.69,"tv":8829.53,"id":2249229},{"trd":[[2.46,369.92]],"ltp":2.46,"tv":4580.52,"id":5720747}],"tv":13410.05}]}
{"op":"mcm","clk":"1005690234","pt":1580643992762,"mc":[{"id":"1.168135803","rc":[{"batl":[[0,1.7,10],[1,1.75,305.54],[2,1.77,453.3]],"ltp":1.69,"tv":8829.53,"id":2249229}]}]}
{"op":"mcm","clk":"1005690578","pt":1580643994747,"mc":[{"id":"1.168135803","rc":[{"batb":[[0,1.44,102.86],[1,1.3,10.02],[2,1.22,8.86]],"batl":[[1,1.77,11.36],[2,1.77,0]],"ltp":1.69,"tv":8829.53,"id":2249229}]}]}
{"op":"mcm","clk":"1005691265","pt":1580643998769,"mc":[{"id":"1.168135803","rc":[{"batb":[[0,1.59,363.34],[1,1.58,329.92],[2,1.44,102.86]],"batl":[[2,1.99,252.88]],"ltp":1.69,"tv":8829.53,"id":2249229}]}]}
{"op":"mcm","clk":"1005691459","pt":1580643999734,"mc":[{"id":"1.168135803","rc":[{"trd":[[1.7,928.17]],"batl":[[0,1.77,11.36],[1,1.99,252.88],[2,2.02,434.62]],"ltp":1.7,"tv":8839.53,"id":2249229},{"trd":[[2.42,10.31]],"batl":[[0,2.42,86.24],[1,3,93.26]],"ltp":2.42,"tv":4587.55,"id":5720747}],"tv":13427.08}]}
