{"op":"mcm","clk":"996134465","pt":1580560628823,"mc":[{"id":"1.168209733","marketDefinition":{"bspMarket":false,"turnInPlayEnabled":true,"persistenceEnabled":true,"marketBaseRate":5.0,"eventId":"29681142","eventTypeId":"2","numberOfWinners":1,"bettingType":"ODDS","marketType":"SET_WINNER","marketTime":"2020-02-02T04:00:00.000Z","suspendTime":"2020-02-02T04:00:00.000Z","bspReconciled":false,"complete":true,"inPlay":false,"crossMatching":false,"runnersVoidable":false,"numberOfActiveRunners":2,"betDelay":0,"status":"OPEN","runners":[{"status":"ACTIVE","sortPriority":1,"id":8174357,"name":"Blaz Rola"},{"status":"ACTIVE","sortPriority":2,"id":7412952,"name":"Roberto Marcora"}],"regulators":["MR_INT"],"countryCode":"IN","discountAllowed":false,"timezone":"UTC","openDate":"2020-02-02T04:00:00.000Z","version":3145101554,"name":"Set 1 Winner","eventName":"Rola v Marcora"},"rc":[{"batb":[[0,1.01,20]],"ltp":0.0,"tv":0.0,"id":8174357},{"batb":[[0,1.01,20]],"ltp":0.0,"tv":0.0,"id":7412952}]}]}
{"op":"mcm","clk":"996134636","pt":1580560629891,"mc":[{"id":"1.168209733","marketDefinition":{"bspMarket":false,"turnInPlayEnabled":true,"persistenceEnabled":true,"marketBaseRate":5.0,"eventId":"29681142","eventTypeId":"2","numberOfWinners":1,"bettingType":"ODDS","marketType":"SET_WINNER","marketTime":"2020-02-02T04:00:00.000Z","suspendTime":"2020-02-02T04:00:00.000Z","bspReconciled":false,"complete":true,"inPlay":false,"crossMatching":false,"runnersVoidable":false,"numberOfActiveRunners":2,"betDelay":0,"status":"OPEN","runners":[{"status":"ACTIVE","sortPriority":1,"id":8174357,"name":"Blaz Rola"},{"status":"ACTIVE","sortPriority":2,"id":7412952,"name":"Roberto Marcora"}],"regulators":["MR_INT"],"countryCode":"IN","discountAllowed":false,"timezone":"UTC","openDate":"2020-02-02T04:00:00.000Z","version":3145101554,"name":"Set 1 Winner","eventName":"Rola v Marcora"}}]}
{"op":"mcm","clk":"996134845","pt":1580560630893,"mc":[{"id":"1.168209733","marketDefinition":{"bspMarket":false,"turnInPlayEnabled":true,"persistenceEnabled":true,"marketBaseRate":5.0,"eventId":"29681142","eventTypeId":"2","numberOfWinners":1,"bettingType":"ODDS","marketType":"SET_WINNER","marketTime":"2020-02-02T04:00:00.000Z","suspendTime":"2020-02-02T04:00:00.000Z","bspReconciled":false,"complete":true,"inPlay":false,"crossMatching":false,"runnersVoidable":false,"numberOfActiveRunners":2,"betDelay":0,"status":"OPEN","runners":[{"status":"ACTIVE","sortPriority":1,"id":8174357,"name":"Blaz Rola"},{"status":"ACTIVE","sortPriority":2,"id":7412952,"name":"Roberto Marcora"}],"regulators":["MR_INT"],"countryCode":"IN","discountAllowed":true,"timezone":"UTC","openDate":"2020-02-02T04:00:00.000Z","version":3145101554,"name":"Set 1 Winner","eventName":"Rola v Marcora"}}]}
{"op":"mcm","clk":"996235645","pt":1580561114627,"mc":[{"id":"1.168209733","rc":[{"batb":[[0,1.01,10]],"ltp":0.0,"tv":0.0,"id":8174357},{"batb":[[0,1.01,10]],"ltp":0.0,"tv":0.0,"id":7412952}]}]}
{"op":"mcm","clk":"997589873","pt":1580567441341,"mc":[{"id":"1.168209733","marketDefinition":{"bspMarket":false,"turnInPlayEnabled":true,"persistenceEnabled":true,"marketBaseRate":5.0,"eventId":"29681142","eventTypeId":"2","numberOfWinners":1,"bettingType":"ODDS","marketType":"SET_WINNER","marketTime":"2020-02-02T09:30:00.000Z","suspendTime":"2020-02-02T09:30:00.000Z","bspReconciled":false,"complete":true,"inPlay":false,"crossMatching":false,"runnersVoidable":false,"numberOfActiveRunners":2,"betDelay":0,"status":"OPEN","runners":[{"status":"ACTIVE","sortPriority":1,"id":8174357,"name":"Blaz Rola"},{"status":"ACTIVE","sortPriority":2,"id":7412952,"name":"Roberto Marcora"}],"regulators":["MR_INT"],"countryCode":"IN","discountAllowed":true,"timezone":"UTC","openDate":"2020-02-02T04:00:00.000Z","version":3145478789,"name":"Set 1 Winner","eventName":"Rola v Marcora"}}]}
{"op":"mcm","clk":"997590546","pt":1580567444348,"mc":[{"id":"1.168209733","marketDefinition":{"bspMarket":false,"turnInPlayEnabled":true,"persistenceEnabled":true,"marketBaseRate":5.0,"eventId":"29681142","eventTypeId":"2","numberOfWinners":1,"bettingType":"ODDS","marketType":"SET_WINNER","marketTime":"2020-02-02T09:30:00.000Z","suspendTime":"2020-02-02T09:30:00.000Z","bspReconciled":false,"complete":true,"inPlay":false,"crossMatching":false,"runnersVoidable":false,"numberOfActiveRunners":2,"betDelay":0,"status":"OPEN","runners":[{"status":"ACTIVE","sortPriority":1,"id":8174357,"name":"Blaz Rola"},{"status":"ACTIVE","sortPriority":2,"id":7412952,"name":"Roberto Marcora"}],"regulators":["MR_INT"],"countryCode":"IN","discountAllowed":true,"timezone":"UTC","openDate":"2020-02-02T09:30:00.000Z","version":3145478789,"name":"Set 1 Winner","eventName":"Rola v Marcora"}}]}
{"op":"mcm","clk":"1003058274","pt":1580602464758,"mc":[{"id":"1.168209733","rc":[{"batb":[[0,1.01,12.53]],"ltp":0.0,"tv":0.0,"id":8174357},{"batb":[[0,1.01,12.53]],"ltp":0.0,"tv":0.0,"id":7412952}]}]}
{"op":"mcm","clk":"1003058324","pt":1580602465172,"mc":[{"id":"1.168209733","rc":[{"batb":[[0,1.01,10.51]],"ltp":0.0,"tv":0.0,"id":8174357},{"batb":[[0,1.01,10.51]],"ltp":0.0,"tv":0.0,"id":7412952}]}]}
{"op":"mcm","clk":"1003179968","pt":1580603998856,"mc":[{"id":"1.168209733","rc":[{"batb":[[0,1.01,11.01]],"ltp":0.0,"tv":0.0,"id":8174357},{"batb":[[0,1.01,11.01]],"ltp":0.0,"tv":0.0,"id":7412952}]}]}
{"op":"mcm","clk":"1003387917","pt":1580607069919,"mc":[{"id":"1.168209733","rc":[{"batb":[[0,1.01,11.02]],"ltp":0.0,"tv":0.0,"id":8174357},{"batb":[[0,1.01,11.02]],"ltp":0.0,"tv":0.0,"id":7412952}]}]}
{"op":"mcm","clk":"1004326307","pt":1580627057017,"mc":[{"id":"1.168209733","rc":[{"batl":[[0,2.96,4.54]],"ltp":0.0,"tv":0.0,"id":8174357},{"batl":[[0,2.98,4.54]],"ltp":0.0,"tv":0.0,"id":7412952}]}]}
{"op":"mcm","clk":"1004326740","pt":1580627074674,"mc":[{"id":"1.168209733","marketDefinition":{"bspMarket":false,"turnInPlayEnabled":true,"persistenceEnabled":true,"marketBaseRate":5.0,"eventId":"29681142","eventTypeId":"2","numberOfWinners":1,"bettingType":"ODDS","marketType":"SET_WINNER","marketTime":"2020-02-02T09:30:00.000Z","suspendTime":"2020-02-02T09:30:00.000Z","bspReconciled":false,"complete":true,"inPlay":false,"crossMatching":true,"runnersVoidable":false,"numberOfActiveRunners":2,"betDelay":0,"status":"OPEN","runners":[{"status":"ACTIVE","sortPriority":1,"id":8174357,"name":"Blaz Rola"},{"status":"ACTIVE","sortPriority":2,"id":7412952,"name":"Roberto Marcora"}],"regulators":["MR_INT"],"countryCode":"IN","discountAllowed":true,"timezone":"UTC","openDate":"2020-02-02T09:30:00.000Z","version":3146887561,"name":"Set 1 Winner","eventName":"Rola v Marcora"}}]}
{"op":"mcm","clk":"1004694408","pt":1580635384846,"mc":[{"id":"1.168209733","rc":[{"batb":[[0,1.88,17.07],[1,1.01,11.02]],"ltp":0.0,"tv":0.0,"id":8174357},{"batb":[[0,1.99,28.48],[1,1.01,11.02]],"ltp":0.0,"tv":0.0,"id":7412952}]}]}
{"op":"mcm","clk":"1004704147","pt":1580635608357,"mc":[{"id":"1.168209733","marketDefinition":{"bspMarket":false,"turnInPlayEnabled":true,"persistenceEnabled":true,"marketBaseRate":5.0,"eventId":"29681142","eventTypeId":"2","numberOfWinners":1,"bettingType":"ODDS","marketType":"SET_WINNER","marketTime":"2020-02-02T09:21:00.000Z","suspendTime":"2020-02-02T09:21:00.000Z","bspReconciled":false,"complete":true,"inPlay":false,"crossMatching":true,"runnersVoidable":false,"numberOfActiveRunners":2,"betDelay":0,"status":"OPEN","runners":[{"status":"ACTIVE","sortPriority":1,"id":8174357,"name":"Blaz Rola"},{"status":"ACTIVE","sortPriority":2,"id":7412952,"name":"Roberto Marcora"}],"regulators":["MR_INT"],"countryCode":"IN","discountAllowed":true,"timezone":"UTC","openDate":"2020-02-02T09:30:00.000Z","version":3148345365,"name":"Set 1 Winner","eventName":"Rola v Marcora"}}]}
{"op":"mcm","clk":"1004704582","pt":1580635614514,"mc":[{"id":"1.168209733","marketDefinition":{"bspMarket":false,"turnInPlayEnabled":true,"persistenceEnabled":true,"marketBaseRate":5.0,"eventId":"29681142","eventTypeId":"2","numberOfWinners":1,"bettingType":"ODDS","marketType":"SET_WINNER","marketTime":"2020-02-02T09:21:00.000Z","suspendTime":"2020-02-02T09:21:00.000Z","bspReconciled":false,"complete":true,"inPlay":false,"crossMatching":true,"runnersVoidable":false,"numberOfActiveRunners":2,"betDelay":0,"status":"OPEN","runners":[{"status":"ACTIVE","sortPriority":1,"id":8174357,"name":"Blaz Rola"},{"status":"ACTIVE","sortPriority":2,"id":7412952,"name":"Roberto Marcora"}],"regulators":["MR_INT"],"countryCode":"IN","discountAllowed":true,"timezone":"UTC","openDate":"2020-02-02T09:21:00.000Z","version":3148345365,"name":"Set 1 Winner","eventName":"Rola v Marcora"}}]}
{"op":"mcm","clk":"1004705268","pt":1580635629258,"mc":[{"id":"1.168209733","rc":[{"batb":[[1,1.87,17.39],[2,1.01,11.02]],"ltp":0.0,"tv":0.0,"id":8174357},{"batb":[[0,2,27.85]],"ltp":0.0,"tv":0.0,"id":7412952}]}]}
{"op":"mcm","clk":"1004705625","pt":1580635639443,"mc":[{"id":"1.168209733","rc":[{"batb":[[0,1.86,17.78],[1,1.01,11.02],[2,1.01,0]],"ltp":0.0,"tv":0.0,"id":8174357},{"batb":[[0,2.02,27.22],[1,2,27.85],[2,1.01,11.02]],"ltp":0.0,"tv":0.0,"id":7412952}]}]}
{"op":"mcm","clk":"1004706361","pt":1580635659872,"mc":[{"id":"1.168209733","rc":[{"batb":[[1,1.01,12.37]],"ltp":0.0,"tv":0.0,"id":8174357},{"batb":[[2,1.01,12.26]],"ltp":0.0,"tv":0.0,"id":7412952}]}]}
{"op":"mcm","clk":"1004706373","pt":1580635660181,"mc":[{"id":"1.168209733","rc":[{"batb":[[0,1.87,1.34],[1,1.86,17.78],[2,1.01,11.02]],"ltp":0.0,"tv":0.0,"id":8174357},{"batb":[[0,2.04,1.24],[1,2.02,27.22],[2,2,27.85]],"ltp":0.0,"tv":0.0,"id":7412952}]}]}
{"op":"mcm","clk":"1004717287","pt":1580635929478,"mc":[{"id":"1.168209733","rc":[{"batb":[[2,1.01,11.02]],"ltp":0.0,"tv":0.0,"id":7412952}]}]}
{"op":"mcm","clk":"1004724695","pt":1580636099868,"mc":[{"id":"1.168209733","rc":[{"batb":[[1,1.85,18.1]],"ltp":0.0,"tv":0.0,"id":8174357},{"batb":[[0,2.04,27.99]],"ltp":0.0,"tv":0.0,"id":7412952}]}]}
{"op":"mcm","clk":"1004725085","pt":1580636109890,"mc":[{"id":"1.168209733","rc":[{"batb":[[1,2.02,26.91]],"ltp":0.0,"tv":0.0,"id":7412952}]}]}
{"op":"mcm","clk":"1004725524","pt":1580636119890,"mc":[{"id":"1.168209733","rc":[{"batb":[[0,2.04,1.24]],"ltp":0.0,"tv":0.0,"id":7412952}]}]}
{"op":"mcm","clk":"1004725960","pt":1580636130520,"mc":[{"id":"1.168209733","rc":[{"batb":[[1,1.86,48.73],[2,1.85,18.1]],"batl":[[0,2.06,39.49],[1,2.96,4.54]],"ltp":0.0,"tv":0.0,"id":8174357},{"batb":[[2,1.96,43.69]],"batl":[[0,2.18,35.29],[1,2.98,4.54]],"ltp":0.0,"tv":0.0,"id":7412952}]}]}
{"op":"mcm","clk":"1004726509","pt":1580636142841,"mc":[{"id":"1.168209733","marketDefinition":{"bspMarket":false,"turnInPlayEnabled":true,"persistenceEnabled":true,"marketBaseRate":5.0,"eventId":"29681142","eventTypeId":"2","numberOfWinners":1,"bettingType":"ODDS","marketType":"SET_WINNER","marketTime":"2020-02-02T09:21:00.000Z","suspendTime":"2020-02-02T09:21:00.000Z","bspReconciled":false,"complete":true,"inPlay":true,"crossMatching":true,"runnersVoidable":false,"numberOfActiveRunners":2,"betDelay":3,"status":"OPEN","runners":[{"status":"ACTIVE","sortPriority":1,"id":8174357,"name":"Blaz Rola"},{"status":"ACTIVE","sortPriority":2,"id":7412952,"name":"Roberto Marcora"}],"regulators":["MR_INT"],"countryCode":"IN","discountAllowed":true,"timezone":"UTC","openDate":"2020-02-02T09:21:00.000Z","version":3148351349,"name":"Set 1 Winner","eventName":"Rola v Marcora"},"rc":[{"batb":[[0,1.01,10.52],[1,1.86,0],[2,1.85,0]],"ltp":0.0,"tv":0.0,"id":8174357},{"batb":[[0,1.01,10.52],[1,2.02,0],[2,1.96,0]],"ltp":0.0,"tv":0.0,"id":7412952}]}]}
{"op":"mcm","clk":"1004726765","pt":1580636149452,"mc":[{"id":"1.168209733","rc":[{"batb":[[0,1.81,161.43],[1,1.79,180.15],[2,1.01,10.52]],"batl":[[0,2.22,90.03],[1,2.24,93.49]],"ltp":0.0,"tv":0.0,"id":8174357}]}]}
{"op":"mcm","clk":"1004727246","pt":1580636160632,"mc":[{"id":"1.168209733","rc":[{"batb":[[0,1.01,10.52],[1,1.79,0],[2,1.01,0]],"ltp":0.0,"tv":0.0,"id":8174357}]}]}
{"op":"mcm","clk":"1004727409","pt":1580636163839,"mc":[{"id":"1.168209733","rc":[{"batb":[[0,1.95,108.96],[1,1.93,141.5],[2,1.01,10.52]],"batl":[[0,2.04,150.57],[1,2.06,118.63]],"ltp":0.0,"tv":0.0,"id":8174357}]}]}
{"op":"mcm","clk":"1004727601","pt":1580636167888,"mc":[{"id":"1.168209733","rc":[{"batb":[[0,1.01,10.52],[1,1.93,0],[2,1.01,0]],"ltp":0.0,"tv":0.0,"id":8174357}]}]}
{"op":"mcm","clk":"1004727713","pt":1580636170774,"mc":[{"id":"1.168209733","rc":[{"batb":[[0,1.81,161.28],[1,1.79,180.15],[2,1.01,10.52]],"batl":[[0,2.22,90.16],[1,2.24,93.48]],"ltp":0.0,"tv":0.0,"id":8174357}]}]}
{"op":"mcm","clk":"1004727985","pt":1580636176954,"mc":[{"id":"1.168209733","rc":[{"batl":[[0,1.89,145.46],[1,1.91,148.62]],"ltp":0.0,"tv":0.0,"id":8174357}]}]}
{"op":"mcm","clk":"1004728024","pt":1580636177774,"mc":[{"id":"1.168209733","rc":[{"batb":[[0,1.76,54.61],[1,1.74,21.79],[2,1.67,25.41]],"batl":[[0,1.89,111.67],[2,1.95,42.01]],"ltp":0.0,"tv":0.0,"id":8174357},{"batb":[[0,2.18,21.95],[1,2.06,39.49],[2,1.98,29.19]],"batl":[[0,2.32,31.09]],"ltp":0.0,"tv":0.0,"id":7412952}]}]}
{"op":"mcm","clk":"1004728150","pt":1580636180671,"mc":[{"id":"1.168209733","rc":[{"batl":[[0,1.95,42.01],[1,1.91,0],[2,1.95,0]],"ltp":0.0,"tv":0.0,"id":8174357}]}]}
{"op":"mcm","clk":"1004728273","pt":1580636183666,"mc":[{"id":"1.168209733","rc":[{"batb":[[0,1.82,145.14],[1,1.8,176.73],[2,1.76,54.61]],"batl":[[0,1.9,151.42],[1,1.92,146.16],[2,1.95,42.01]],"ltp":0.0,"tv":0.0,"id":8174357}]}]}
{"op":"mcm","clk":"1004728634","pt":1580636193215,"mc":[{"id":"1.168209733","rc":[{"batb":[[0,1.76,54.61],[1,1.67,25.41],[2,1.01,10.52]],"batl":[[0,1.95,42.01],[1,1.92,0],[2,1.95,0]],"ltp":0.0,"tv":0.0,"id":8174357},{"batb":[[0,2.06,39.49],[1,1.98,29.19],[2,1.01,10.52]],"ltp":0.0,"tv":0.0,"id":7412952}]}]}
{"op":"mcm","clk":"1004728668","pt":1580636194325,"mc":[{"id":"1.168209733","rc":[{"batb":[[0,1.67,25.41],[1,1.01,10.52],[2,1.01,0]],"ltp":0.0,"tv":0.0,"id":8174357},{"batb":[[0,1.98,29.19],[1,1.01,10.52],[2,1.01,0]],"ltp":0.0,"tv":0.0,"id":7412952}]}]}
{"op":"mcm","clk":"1004728759","pt":1580636196894,"mc":[{"id":"1.168209733","rc":[{"batb":[[0,1.75,202.79],[1,1.73,201.98],[2,1.68,24.78]],"batl":[[0,2.06,139.65],[1,2.08,115.32]],"ltp":0.0,"tv":0.0,"id":8174357},{"batb":[[0,1.96,29.98]],"ltp":0.0,"tv":0.0,"id":7412952}]}]}
{"op":"mcm","clk":"1004728882","pt":1580636199784,"mc":[{"id":"1.168209733","rc":[{"batb":[[0,1.68,24.78],[1,1.01,10.52],[2,1.68,0]],"ltp":0.0,"tv":0.0,"id":8174357}]}]}
{"op":"mcm","clk":"1004728986","pt":1580636202681,"mc":[{"id":"1.168209733","rc":[{"batb":[[0,1.85,120.84],[1,1.83,167.42],[2,1.68,24.78]],"batl":[[0,1.93,149.23],[1,1.95,139.46]],"ltp":0.0,"tv":0.0,"id":8174357}]}]}
{"op":"mcm","clk":"1004729126","pt":1580636206244,"mc":[{"id":"1.168209733","rc":[{"batb":[[0,1.68,24.78],[1,1.01,10.52],[2,1.68,0]],"ltp":0.0,"tv":0.0,"id":8174357}]}]}
{"op":"mcm","clk":"1004729366","pt":1580636212937,"mc":[{"id":"1.168209733","rc":[{"batb":[[1,1.95,101.64],[2,1.93,141.45]],"batl":[[0,2.04,157.42],[1,2.06,118.61]],"ltp":0.0,"tv":0.0,"id":7412952}]}]}
{"op":"mcm","clk":"1004729394","pt":1580636213713,"mc":[{"id":"1.168209733","rc":[{"batb":[[0,1.91,16.13],[1,1.88,47.05],[2,1.78,20.3]],"batl":[[0,2.1,37.81]],"ltp":0.0,"tv":0.0,"id":8174357},{"batl":[[2,2.12,36.97]],"ltp":0.0,"tv":0.0,"id":7412952}]}]}
{"op":"mcm","clk":"1004730026","pt":1580636227667,"mc":[{"id":"1.168209733","rc":[{"batb":[[0,1.88,47.05],[1,1.78,20.3],[2,1.01,10.52]],"ltp":0.0,"tv":0.0,"id":8174357},{"batb":[[0,1.92,45.37],[1,1.74,22.11],[2,1.01,10.52]],"batl":[[0,2.12,36.97],[1,2.06,0],[2,2.12,0]],"ltp":0.0,"tv":0.0,"id":7412952}]}]}
{"op":"mcm","clk":"1004730044","pt":1580636228332,"mc":[{"id":"1.168209733","rc":[{"batb":[[0,1.78,20.3],[1,1.01,10.52],[2,1.01,0]],"ltp":0.0,"tv":0.0,"id":8174357},{"batb":[[0,1.74,22.11],[1,1.01,10.52],[2,1.01,0]],"ltp":0.0,"tv":0.0,"id":7412952}]}]}
{"op":"mcm","clk":"1004730118","pt":1580636230753,"mc":[{"id":"1.168209733","rc":[{"batb":[[0,1.79,19.91]],"ltp":0.0,"tv":0.0,"id":8174357},{"batb":[[0,1.73,22.5],[1,1.72,181.51],[2,1.7,214.66]],"batl":[[0,2.2,165.51],[1,2.22,95.89]],"ltp":0.0,"tv":0.0,"id":7412952}]}]}
{"op":"mcm","clk":"1004730134","pt":1580636231162,"mc":[{"id":"1.168209733","rc":[{"batb":[[1,1.01,10.52],[2,1.7,0]],"ltp":0.0,"tv":0.0,"id":7412952}]}]}
{"op":"mcm","clk":"1004730259","pt":1580636234781,"mc":[{"id":"1.168209733","rc":[{"batb":[[0,1.84,142.17],[1,1.82,170.47],[2,1.79,19.91]],"batl":[[0,1.92,137.13],[1,1.94,141.67]],"ltp":0.0,"tv":0.0,"id":8174357},{"batb":[[0,2.1,24.23],[1,1.9,16.52],[2,1.73,22.5]],"ltp":0.0,"tv":0.0,"id":7412952}]}]}
{"op":"mcm","clk":"1004730279","pt":1580636235257,"mc":[{"id":"1.168209733","rc":[{"batb":[[2,1.79,72.84]],"batl":[[2,1.97,42.01]],"ltp":0.0,"tv":0.0,"id":8174357},{"batb":[[1,2.04,40.33],[2,1.9,16.52]],"batl":[[0,2.28,32.77]],"ltp":0.0,"tv":0.0,"id":7412952}]}]}
{"op":"mcm","clk":"1004730805","pt":1580636247886,"mc":[{"id":"1.168209733","rc":[{"batb":[[0,1.79,72.84],[1,1.69,24.16],[2,1.01,10.52]],"batl":[[0,1.97,42.01],[1,1.94,0],[2,1.97,0]],"ltp":0.0,"tv":0.0,"id":8174357}]}]}
{"op":"mcm","clk":"1004730826","pt":1580636248303,"mc":[{"id":"1.168209733","rc":[{"batb":[[0,1.69,24.16],[1,1.01,10.52],[2,1.01,0]],"ltp":0.0,"tv":0.0,"id":8174357},{"batb":[[0,1.9,16.52],[1,1.01,10.52],[2,1.9,0]],"ltp":0.0,"tv":0.0,"id":7412952}]}]}
{"op":"mcm","clk":"1004730907","pt":1580636250774,"mc":[{"id":"1.168209733","rc":[{"batb":[[0,1.76,145.57],[1,1.74,197.88],[2,1.69,24.16]],"batl":[[0,2.12,124.03],[1,2.14,106.3]],"ltp":0.0,"tv":0.0,"id":8174357}]}]}
{"op":"mcm","clk":"1004731018","pt":1580636254523,"mc":[{"id":"1.168209733","rc":[{"batb":[[0,1.69,24.16],[1,1.01,10.52],[2,1.69,0]],"ltp":0.0,"tv":0.0,"id":8174357}]}]}
{"op":"mcm","clk":"1004731126","pt":1580636257929,"mc":[{"id":"1.168209733","rc":[{"batb":[[1,1.89,160.92],[2,1.87,156.29]],"batl":[[0,1.98,146.48],[1,2,129.37]],"ltp":0.0,"tv":0.0,"id":7412952}]}]}
{"op":"mcm","clk":"1004731149","pt":1580636258394,"mc":[{"id":"1.168209733","rc":[{"batb":[[0,1.97,29.43],[1,1.79,19.99],[2,1.01,10.52]],"ltp":0.0,"tv":0.0,"id":8174357}]}]}
{"op":"mcm","clk":"1004731181","pt":1580636259321,"mc":[{"id":"1.168209733","rc":[{"batb":[[1,1.93,44.53],[2,1.79,19.99]],"batl":[[0,2.16,36.13]],"ltp":0.0,"tv":0.0,"id":8174357},{"batb":[[2,1.87,204.18]],"batl":[[2,2.08,38.65]],"ltp":0.0,"tv":0.0,"id":7412952}]}]}
{"op":"mcm","clk":"1004731613","pt":1580636269842,"mc":[{"id":"1.168209733","rc":[{"batb":[[0,1.93,44.53],[1,1.79,19.99],[2,1.01,10.52]],"ltp":0.0,"tv":0.0,"id":8174357},{"batb":[[0,1.87,47.89],[1,1.64,26.99],[2,1.01,10.52]],"batl":[[0,2.08,38.65],[1,2,0],[2,2.08,0]],"ltp":0.0,"tv":0.0,"id":7412952}]}]}
{"op":"mcm","clk":"1004731647","pt":1580636270523,"mc":[{"id":"1.168209733","rc":[{"batb":[[0,1.79,19.99],[1,1.01,10.52],[2,1.01,0]],"ltp":0.0,"tv":0.0,"id":8174357},{"batb":[[0,1.64,26.99],[1,1.01,10.52],[2,1.01,0]],"ltp":0.0,"tv":0.0,"id":7412952}]}]}
{"op":"mcm","clk":"1004731752","pt":1580636272842,"mc":[{"id":"1.168209733","rc":[{"batb":[[1,1.61,172.91],[2,1.6,134.26]],"batl":[[0,2.2,171.52],[1,2.22,95.9]],"ltp":0.0,"tv":0.0,"id":7412952}]}]}
{"op":"mcm","clk":"1004731795","pt":1580636273726,"mc":[{"id":"1.168209733","rc":[{"batb":[[1,1.01,10.52],[2,1.6,0]],"ltp":0.0,"tv":0.0,"id":7412952}]}]}
{"op":"mcm","clk":"1004731937","pt":1580636276858,"mc":[{"id":"1.168209733","rc":[{"batb":[[0,1.83,131.22],[1,1.81,173.63],[2,1.64,26.99]],"batl":[[0,1.91,156.38],[1,1.93,143.98]],"ltp":0.0,"tv":0.0,"id":7412952}]}]}
{"op":"mcm","clk":"1004732192","pt":1580636282526,"mc":[{"id":"1.168209733","rc":[{"batb":[[0,1.64,26.99],[1,1.01,10.52],[2,1.64,0]],"ltp":0.0,"tv":0.0,"id":7412952}]}]}
{"op":"mcm","clk":"1004732372","pt":1580636285732,"mc":[{"id":"1.168209733","rc":[{"batb":[[1,1.61,172.91],[2,1.6,134.26]],"batl":[[0,2.2,171.52],[1,2.22,95.9]],"ltp":0.0,"tv":0.0,"id":7412952}]}]}
{"op":"mcm","clk":"1004732585","pt":1580636290850,"mc":[{"id":"1.168209733","rc":[{"batl":[[0,1.67,170.32],[1,1.69,220.55]],"ltp":0.0,"tv":0.0,"id":7412952}]}]}
{"op":"mcm","clk":"1004732628","pt":1580636291736,"mc":[{"id":"1.168209733","rc":[{"batb":[[0,2.36,17.31],[1,2.3,31.93],[2,1.99,28.48]],"batl":[[0,2.62,25.21]],"ltp":0.0,"tv":0.0,"id":8174357},{"batb":[[1,1.63,66.38],[2,1.61,172.91]],"batl":[[2,1.77,42.01]],"ltp":0.0,"tv":0.0,"id":7412952}]}]}
{"op":"mcm","clk":"1004733213","pt":1580636304771,"mc":[{"id":"1.168209733","rc":[{"batb":[[0,2.3,31.93],[1,1.99,28.48],[2,1.01,10.52]],"ltp":0.0,"tv":0.0,"id":8174357},{"batb":[[0,1.63,66.38],[1,1.37,55.87],[2,1.01,10.51]],"batl":[[0,1.77,42.01],[1,1.69,0],[2,1.77,0]],"ltp":0.0,"tv":0.0,"id":7412952}]}]}
{"op":"mcm","clk":"1004733280","pt":1580636306366,"mc":[{"id":"1.168209733","rc":[{"batb":[[0,1.99,28.48],[1,1.01,10.52],[2,1.01,0]],"ltp":0.0,"tv":0.0,"id":8174357},{"batb":[[0,1.37,55.87],[1,1.01,10.51],[2,1.01,0]],"ltp":0.0,"tv":0.0,"id":7412952}]}]}
{"op":"mcm","clk":"1004733326","pt":1580636307593,"mc":[{"id":"1.168209733","rc":[{"batb":[[1,1.28,274.43],[2,1.27,382.61]],"batl":[[0,1.96,153.2],[1,1.98,133.29]],"ltp":0.0,"tv":0.0,"id":7412952}]}]}
{"op":"mcm","clk":"1004733518","pt":1580636312272,"mc":[{"id":"1.168209733","rc":[{"batb":[[1,1.01,10.51],[2,1.27,0]],"ltp":0.0,"tv":0.0,"id":7412952}]}]}
{"op":"mcm","clk":"1004733662","pt":1580636315876,"mc":[{"id":"1.168209733","rc":[{"batb":[[1,1.97,42.85],[2,1.81,19.28]],"ltp":0.0,"tv":0.0,"id":8174357},{"batb":[[0,1.88,17],[1,1.87,171.65],[2,1.85,161.78]],"batl":[[2,2.02,41.17]],"ltp":0.0,"tv":0.0,"id":7412952}]}]}
{"op":"mcm","clk":"1004733670","pt":1580636316083,"mc":[{"id":"1.168209733","rc":[{"batl":[[0,2.18,35.29]],"ltp":0.0,"tv":0.0,"id":8174357},{"batl":[[2,2.04,40.33]],"ltp":0.0,"tv":0.0,"id":7412952}]}]}
{"op":"mcm","clk":"1004734533","pt":1580636334732,"mc":[{"id":"1.168209733","rc":[{"batb":[[0,1.81,19.28],[1,1.01,10.52],[2,1.81,0]],"ltp":0.0,"tv":0.0,"id":8174357},{"batb":[[0,1.63,27.54],[1,1.01,10.52],[2,1.85,0]],"ltp":0.0,"tv":0.0,"id":7412952}]}]}
{"op":"mcm","clk":"1004734686","pt":1580636337838,"mc":[{"id":"1.168209733","rc":[{"batb":[[1,1.6,136.09],[2,1.59,137.29]],"batl":[[0,2.18,188.8],[1,2.2,98.37]],"ltp":0.0,"tv":0.0,"id":7412952}]}]}
{"op":"mcm","clk":"1004735585","pt":1580636356783,"mc":[{"id":"1.168209733","rc":[{"batb":[[1,1.01,10.52],[2,1.59,0]],"ltp":0.0,"tv":0.0,"id":7412952}]}]}
{"op":"mcm","clk":"1004735709","pt":1580636359672,"mc":[{"id":"1.168209733","rc":[{"batb":[[0,1.86,119.7],[1,1.84,164.5],[2,1.81,19.28]],"batl":[[0,1.94,142.34],[1,1.96,137.34]],"ltp":0.0,"tv":0.0,"id":8174357}]}]}
{"op":"mcm","clk":"1004735754","pt":1580636360597,"mc":[{"id":"1.168209733","rc":[{"batb":[[0,2.08,25.02],[1,1.86,17.62],[2,1.01,10.52]],"ltp":0.0,"tv":0.0,"id":7412952}]}]}
{"op":"mcm","clk":"1004735806","pt":1580636361885,"mc":[{"id":"1.168209733","rc":[{"batb":[[2,1.81,70.53]],"batl":[[2,1.99,42.01]],"ltp":0.0,"tv":0.0,"id":8174357},{"batb":[[1,2.02,41.17],[2,1.86,17.62]],"batl":[[0,2.26,32.77]],"ltp":0.0,"tv":0.0,"id":7412952}]}]}
{"op":"mcm","clk":"1004736616","pt":1580636379695,"mc":[{"id":"1.168209733","rc":[{"batb":[[0,1.81,51.25],[1,1.69,24.23],[2,1.01,10.52]],"batl":[[0,1.99,42.01],[1,1.96,0],[2,1.99,0]],"ltp":0.0,"tv":0.0,"id":8174357},{"batb":[[0,2.02,41.17],[1,1.86,17.62],[2,1.01,10.52]],"ltp":0.0,"tv":0.0,"id":7412952}]}]}
{"op":"mcm","clk":"1004736659","pt":1580636380528,"mc":[{"id":"1.168209733","rc":[{"batb":[[0,1.69,24.23],[1,1.01,10.52],[2,1.01,0]],"ltp":0.0,"tv":0.0,"id":8174357},{"batb":[[0,1.86,17.62],[1,1.01,10.52],[2,1.01,0]],"ltp":0.0,"tv":0.0,"id":7412952}]}]}
{"op":"mcm","clk":"1004736791","pt":1580636382896,"mc":[{"id":"1.168209733","rc":[{"batb":[[0,1.76,186.54],[1,1.74,198],[2,1.69,24.23]],"batl":[[0,2.18,172.19],[1,2.2,98.38]],"ltp":0.0,"tv":0.0,"id":8174357}]}]}
{"op":"mcm","clk":"1004737644","pt":1580636398841,"mc":[{"id":"1.168209733","rc":[{"batb":[[0,1.69,24.23],[1,1.01,10.52],[2,1.69,0]],"ltp":0.0,"tv":0.0,"id":8174357}]}]}
{"op":"mcm","clk":"1004737799","pt":1580636401940,"mc":[{"id":"1.168209733","rc":[{"batb":[[0,1.9,107.11],[1,1.88,153.57],[2,1.69,24.23]],"batl":[[0,1.98,124.67],[1,2,129.33]],"ltp":0.0,"tv":0.0,"id":8174357}]}]}
{"op":"mcm","clk":"1004738093","pt":1580636408739,"mc":[{"id":"1.168209733","rc":[{"batb":[[0,1.69,24.23],[1,1.01,10.52],[2,1.69,0]],"ltp":0.0,"tv":0.0,"id":8174357}]}]}
{"op":"mcm","clk":"1004738230","pt":1580636411473,"mc":[{"id":"1.168209733","rc":[{"batb":[[0,1.76,186.54],[1,1.74,198],[2,1.69,24.23]],"batl":[[0,2.18,172.19],[1,2.2,98.38]],"ltp":0.0,"tv":0.0,"id":8174357}]}]}
{"op":"mcm","clk":"1004738883","pt":1580636424923,"mc":[{"id":"1.168209733","rc":[{"batl":[[0,1.84,170.2],[1,1.86,161.13]],"ltp":0.0,"tv":0.0,"id":8174357},{"batb":[[0,2.26,19.51],[1,2.1,24.31],[2,1.86,17.62]],"ltp":0.0,"tv":0.0,"id":7412952}]}]}
{"op":"mcm","clk":"1004738929","pt":1580636425494,"mc":[{"id":"1.168209733","rc":[{"batb":[[2,1.7,59.65]],"batl":[[2,1.87,42.01]],"ltp":0.0,"tv":0.0,"id":8174357},{"batb":[[1,2.16,36.13],[2,2.1,24.31]],"batl":[[0,2.44,28.57]],"ltp":0.0,"tv":0.0,"id":7412952}]}]}
{"op":"mcm","clk":"1004739336","pt":1580636433714,"mc":[{"id":"1.168209733","rc":[{"batb":[[2,1.7,83.34]],"ltp":0.0,"tv":0.0,"id":8174357},{"batb":[[0,2.24,20.06],[2,2.08,24.94]],"ltp":0.0,"tv":0.0,"id":7412952}]}]}
{"op":"mcm","clk":"1004739657","pt":1580636441325,"mc":[{"id":"1.168209733","rc":[{"batb":[[2,1.71,23.13]],"ltp":0.0,"tv":0.0,"id":8174357},{"batb":[[0,2.22,20.54],[2,2.06,25.57]],"ltp":0.0,"tv":0.0,"id":7412952}]}]}
{"op":"mcm","clk":"1004740690","pt":1580636461738,"mc":[{"id":"1.168209733","rc":[{"batb":[[0,1.71,23.13],[1,1.7,59.65],[2,1.57,31.63]],"batl":[[0,1.87,42.01],[1,1.86,0],[2,1.87,0]],"ltp":0.0,"tv":0.0,"id":8174357}]}]}
{"op":"mcm","clk":"1004740847","pt":1580636464579,"mc":[{"id":"1.168209733","rc":[{"batb":[[2,1.61,190.96]],"batl":[[1,1.94,168.27],[2,1.96,137.33]],"ltp":0.0,"tv":0.0,"id":8174357}]}]}
{"op":"mcm","clk":"1004741464","pt":1580636476585,"mc":[{"id":"1.168209733","rc":[{"batb":[[0,1.61,190.96],[1,1.6,134.09],[2,1.57,31.63]],"batl":[[0,1.94,168.27],[1,1.96,137.33],[2,1.96,0]],"ltp":0.0,"tv":0.0,"id":8174357},{"batb":[[0,2.06,25.57],[1,1.82,401.24],[2,1.01,10.52]],"ltp":0.0,"tv":0.0,"id":7412952}]}]}
{"op":"mcm","clk":"1004742270","pt":1580636489428,"mc":[{"id":"1.168209733","rc":[{"batb":[[0,1.57,31.63],[1,1.46,435.71],[2,1.01,10.51]],"ltp":0.0,"tv":0.0,"id":8174357}]}]}
{"op":"mcm","clk":"1004742359","pt":1580636491327,"mc":[{"id":"1.168209733","rc":[{"batb":[[1,1.01,10.52],[2,1.01,0]],"ltp":0.0,"tv":0.0,"id":8174357}]}]}
{"op":"mcm","clk":"1004742433","pt":1580636492926,"mc":[{"id":"1.168209733","rc":[{"batb":[[0,1.85,174.38],[1,1.83,167.53],[2,1.57,31.63]],"ltp":0.0,"tv":0.0,"id":8174357}]}]}
{"op":"mcm","clk":"1004742458","pt":1580636493490,"mc":[{"id":"1.168209733","rc":[{"batb":[[2,1.82,18.88]],"batl":[[1,1.95,42.01],[2,1.96,137.33]],"ltp":0.0,"tv":0.0,"id":8174357},{"batb":[[1,2.04,40.33],[2,1.95,30.37]],"batl":[[0,2.3,31.93]],"ltp":0.0,"tv":0.0,"id":7412952}]}]}
{"op":"mcm","clk":"1004743491","pt":1580636509555,"mc":[{"id":"1.168209733","rc":[{"batb":[[0,1.77,53.77],[1,1.68,24.78],[2,1.55,420.5]],"batl":[[0,1.95,42.01],[1,1.95,0],[2,1.96,0]],"ltp":0.0,"tv":0.0,"id":8174357},{"batb":[[0,2.04,40.33],[1,1.95,30.37],[2,1.82,401.24]],"ltp":0.0,"tv":0.0,"id":7412952}]}]}
{"op":"mcm","clk":"1004743570","pt":1580636510742,"mc":[{"id":"1.168209733","rc":[{"batb":[[0,1.68,24.78],[1,1.55,420.5],[2,1.01,10.52]],"batl":[[0,1.85,5.3]],"ltp":0.0,"tv":0.0,"id":8174357},{"batb":[[0,1.95,30.37],[1,1.82,401.24],[2,1.01,10.52]],"ltp":0.0,"tv":0.0,"id":7412952}]}]}
{"op":"mcm","clk":"1004743724","pt":1580636512955,"mc":[{"id":"1.168209733","rc":[{"batb":[[0,1.72,171.39],[1,1.7,214.4],[2,1.68,24.78]],"batl":[[1,2.02,138.56],[2,2.04,122.01]],"ltp":0.0,"tv":0.0,"id":8174357},{"batb":[[0,1.96,30.21],[1,1.95,30.37],[2,1.82,401.24]],"ltp":0.0,"tv":0.0,"id":7412952}]}]}
{"op":"mcm","clk":"1004743789","pt":1580636513937,"mc":[{"id":"1.168209733","rc":[{"batb":[[1,1.82,401.24],[2,1.01,10.52]],"ltp":0.0,"tv":0.0,"id":7412952}]}]}
{"op":"mcm","clk":"1004744759","pt":1580636530186,"mc":[{"id":"1.168209733","rc":[{"batb":[[0,1.68,24.78],[1,1.55,420.5],[2,1.01,10.52]],"batl":[[1,2.02,0],[2,2.04,0]],"ltp":0.0,"tv":0.0,"id":8174357}]}]}
{"op":"mcm","clk":"1004744838","pt":1580636531488,"mc":[{"id":"1.168209733","rc":[{"batb":[[1,1.01,10.52],[2,1.01,0]],"ltp":0.0,"tv":0.0,"id":7412952}]}]}
{"op":"mcm","clk":"1004745011","pt":1580636533898,"mc":[{"id":"1.168209733","rc":[{"trd":[[1.85,10.6]],"batb":[[0,1.93,131.1],[1,1.92,16.05],[2,1.91,146.14]],"batl":[[0,2.02,138.56],[1,2.04,162.34]],"ltp":1.85,"tv":10.6,"id":8174357},{"batb":[[1,1.95,43.69],[2,1.88,17.07]],"batl":[[0,2.18,35.29]],"ltp":0.0,"tv":0.0,"id":7412952}],"tv":10.6}]}
{"op":"mcm","clk":"1004745058","pt":1580636534474,"mc":[{"id":"1.168209733","rc":[{"batl":[[0,2.16,4.54],[1,2.18,35.29]],"ltp":0.0,"tv":0.0,"id":7412952}]}]}
{"op":"mcm","clk":"1004745125","pt":1580636535607,"mc":[{"id":"1.168209733","rc":[{"batl":[[0,2.18,35.29],[1,2.18,0]],"ltp":0.0,"tv":0.0,"id":7412952}]}]}
{"op":"mcm","clk":"1004745549","pt":1580636540680,"mc":[{"id":"1.168209733","rc":[{"batb":[[0,1.8,19.67],[1,1.55,420.5],[2,1.01,10.52]],"ltp":1.85,"tv":10.6,"id":8174357},{"batb":[[0,1.88,17.07],[1,1.67,409.76],[2,1.01,10.52]],"ltp":0.0,"tv":0.0,"id":7412952}]}]}
{"op":"mcm","clk":"1004745734","pt":1580636543891,"mc":[{"id":"1.168209733","rc":[{"batb":[[0,1.83,160.27],[1,1.81,173.61],[2,1.8,19.67]],"batl":[[0,2.08,143.38],[1,2.1,112.2]],"ltp":1.85,"tv":10.6,"id":8174357}]}]}
{"op":"mcm","clk":"1004745747","pt":1580636544093,"mc":[{"id":"1.168209733","rc":[{"batb":[[0,1.8,19.67],[1,1.55,420.5],[2,1.01,10.52]],"ltp":1.85,"tv":10.6,"id":8174357}]}]}
{"op":"mcm","clk":"1004745836","pt":1580636545694,"mc":[{"id":"1.168209733","rc":[{"batb":[[1,1.01,10.52],[2,1.01,0]],"ltp":1.85,"tv":10.6,"id":8174357}]}]}
{"op":"mcm","clk":"1004745953","pt":1580636547910,"mc":[{"id":"1.168209733","rc":[{"batb":[[0,2,28.4],[1,1.91,16.21],[2,1.89,47.05]],"batl":[[0,2.1,37.81]],"ltp":1.85,"tv":10.6,"id":8174357},{"batb":[[0,1.93,125.32],[1,1.91,146.14],[2,1.89,47.05]],"batl":[[0,2.02,149.19],[1,2.04,122.04],[2,2.1,37.81]],"ltp":0.0,"tv":0.0,"id":7412952}]}]}
{"op":"mcm","clk":"1004746555","pt":1580636560842,"mc":[{"id":"1.168209733","rc":[{"batb":[[0,1.91,16.21],[1,1.62,415.43],[2,1.01,10.52]],"ltp":1.85,"tv":10.6,"id":8174357},{"batb":[[0,1.83,18.49],[1,1.67,409.76],[2,1.01,10.52]],"ltp":0.0,"tv":0.0,"id":7412952}]}]}
{"op":"mcm","clk":"1004746691","pt":1580636563836,"mc":[{"id":"1.168209733","rc":[{"batb":[[0,1.9,137.05],[1,1.88,153.63],[2,1.83,18.49]],"batl":[[0,2.08,100.72],[1,2.1,112.18]],"ltp":0.0,"tv":0.0,"id":7412952}]}]}
{"op":"mcm","clk":"1004747399","pt":1580636577550,"mc":[{"id":"1.168209733","rc":[{"batb":[[0,1.96,43.69],[1,1.91,16.21]],"batl":[[0,2.16,36.13]],"ltp":1.85,"tv":10.6,"id":8174357},{"batb":[[2,1.84,49.57]],"batl":[[0,1.99,161.06],[1,2.02,189.34],[2,2.04,40.33]],"ltp":0.0,"tv":0.0,"id":7412952}]}]}
{"op":"mcm","clk":"1004747437","pt":1580636578268,"mc":[{"id":"1.168209733","rc":[{"batb":[[0,2.04,26.2],[1,1.96,43.69],[2,1.93,209.36]],"ltp":1.85,"tv":10.6,"id":8174357}]}]}
{"op":"mcm","clk":"1004749109","pt":1580636609830,"mc":[{"id":"1.168209733","rc":[{"batb":[[0,1.96,43.69],[1,1.92,16.05],[2,1.67,409.76]],"ltp":1.85,"tv":10.6,"id":8174357},{"batb":[[0,1.84,49.57],[1,1.67,409.76],[2,1.65,26.28]],"batl":[[0,2.04,40.33],[1,2.02,0],[2,2.04,0]],"ltp":0.0,"tv":0.0,"id":7412952}]}]}
{"op":"mcm","clk":"1004749160","pt":1580636610812,"mc":[{"id":"1.168209733","rc":[{"batb":[[0,1.92,16.05],[1,1.67,409.76],[2,1.01,10.52]],"ltp":1.85,"tv":10.6,"id":8174357},{"batb":[[0,1.67,409.76],[1,1.65,26.28],[2,1.01,10.52]],"ltp":0.0,"tv":0.0,"id":7412952}]}]}
{"op":"mcm","clk":"1004749257","pt":1580636612914,"mc":[{"id":"1.168209733","rc":[{"batb":[[1,1.91,16.13],[2,1.67,409.76]],"ltp":1.85,"tv":10.6,"id":8174357},{"batb":[[0,1.72,118.74],[1,1.7,214.37],[2,1.67,409.76]],"batl":[[0,2.12,193.15],[1,2.14,106.33]],"ltp":0.0,"tv":0.0,"id":7412952}]}]}
{"op":"mcm","clk":"1004749301","pt":1580636613899,"mc":[{"id":"1.168209733","rc":[{"batb":[[0,1.91,16.13],[1,1.67,409.76],[2,1.01,10.52]],"ltp":1.85,"tv":10.6,"id":8174357}]}]}
{"op":"mcm","clk":"1004749485","pt":1580636617606,"mc":[{"id":"1.168209733","rc":[{"batl":[[0,2.04,37.86]],"ltp":1.85,"tv":10.6,"id":8174357}]}]}
{"op":"mcm","clk":"1004749529","pt":1580636618431,"mc":[{"id":"1.168209733","rc":[{"batl":[[0,2.04,41.65]],"ltp":1.85,"tv":10.6,"id":8174357}]}]}
{"op":"mcm","clk":"1004750172","pt":1580636634728,"mc":[{"id":"1.168209733","rc":[{"batb":[[0,1.67,409.76],[1,1.65,26.12],[2,1.01,10.52]],"ltp":0.0,"tv":0.0,"id":7412952}]}]}
{"op":"mcm","clk":"1004750219","pt":1580636636060,"mc":[{"id":"1.168209733","rc":[{"batl":[[0,2.04,37.86]],"ltp":1.85,"tv":10.6,"id":8174357}]}]}
{"op":"mcm","clk":"1004750289","pt":1580636637756,"mc":[{"id":"1.168209733","rc":[{"batb":[[1,1.9,161.63],[2,1.88,153.63]],"batl":[[0,1.99,137.53],[1,2.02,189.3],[2,2.04,37.86]],"ltp":1.85,"tv":10.6,"id":8174357}]}]}
{"op":"mcm","clk":"1004750322","pt":1580636638576,"mc":[{"id":"1.168209733","rc":[{"batl":[[2,2.04,0]],"ltp":1.85,"tv":10.6,"id":8174357},{"batb":[[0,1.96,30.14],[1,1.79,19.83],[2,1.67,409.76]],"ltp":0.0,"tv":0.0,"id":7412952}]}]}
{"op":"mcm","clk":"1004750365","pt":1580636639651,"mc":[{"id":"1.168209733","rc":[{"batl":[[2,2.04,40.33]],"ltp":1.85,"tv":10.6,"id":8174357},{"batb":[[1,1.95,43.69],[2,1.79,19.83]],"batl":[[0,2.18,35.29]],"ltp":0.0,"tv":0.0,"id":7412952}]}]}
{"op":"mcm","clk":"1004751037","pt":1580636657572,"mc":[{"id":"1.168209733","rc":[{"batb":[[1,1.86,48.73],[2,1.81,19.12]],"batl":[[0,2.04,40.33],[1,2.02,0],[2,2.04,0]],"ltp":1.85,"tv":10.6,"id":8174357}]}]}
{"op":"mcm","clk":"1004751084","pt":1580636658607,"mc":[{"id":"1.168209733","rc":[{"batb":[[1,1.81,19.12],[2,1.67,409.76]],"ltp":1.85,"tv":10.6,"id":8174357},{"batb":[[1,1.79,19.83],[2,1.67,409.76]],"ltp":0.0,"tv":0.0,"id":7412952}]}]}
{"op":"mcm","clk":"1004751112","pt":1580636659171,"mc":[{"id":"1.168209733","rc":[{"batb":[[0,1.01,10.52],[1,1.81,0],[2,1.67,0]],"ltp":1.85,"tv":10.6,"id":8174357},{"batb":[[0,1.01,10.52],[1,1.79,0],[2,1.67,0]],"ltp":0.0,"tv":0.0,"id":7412952}]}]}
{"op":"mcm","clk":"1004761451","pt":1580636882795,"mc":[{"id":"1.168209733","rc":[{"batb":[[0,1.62,217.39],[1,1.61,131.13],[2,1.01,10.52]],"batl":[[0,1.69,223.02],[1,1.71,211.22]],"ltp":1.85,"tv":10.6,"id":8174357}]}]}
{"op":"mcm","clk":"1004761512","pt":1580636883928,"mc":[{"id":"1.168209733","rc":[{"batb":[[0,1.62,127.84],[1,1.56,74.78]],"batl":[[0,1.69,118.41],[1,1.7,42.01],[2,1.71,211.22]],"ltp":1.85,"tv":10.6,"id":8174357},{"batb":[[0,2.42,29.41],[1,1.01,10.52]],"batl":[[0,2.8,22.69]],"ltp":0.0,"tv":0.0,"id":7412952}]}]}
{"op":"mcm","clk":"1004761534","pt":1580636884286,"mc":[{"id":"1.168209733","rc":[{"batb":[[0,1.01,10.52],[1,1.01,0]],"ltp":0.0,"tv":0.0,"id":7412952}]}]}
{"op":"mcm","clk":"1004761627","pt":1580636886604,"mc":[{"id":"1.168209733","rc":[{"batb":[[0,1.63,197.95],[1,1.62,127.84],[2,1.56,74.78]],"ltp":1.85,"tv":10.6,"id":8174357},{"batb":[[0,2.44,28.57],[1,1.01,10.52]],"ltp":0.0,"tv":0.0,"id":7412952}]}]}
{"op":"mcm","clk":"1004761780","pt":1580636889829,"mc":[{"id":"1.168209733","rc":[{"batl":[[0,1.69,42.01],[1,1.7,218.7],[2,1.72,206.63]],"ltp":1.85,"tv":10.6,"id":8174357}]}]}
{"op":"mcm","clk":"1004762131","pt":1580636897344,"mc":[{"id":"1.168209733","rc":[{"batb":[[0,1.56,74.78],[1,1.01,10.52],[2,1.56,0]],"batl":[[1,1.7,0],[2,1.72,0]],"ltp":1.85,"tv":10.6,"id":8174357}]}]}
{"op":"mcm","clk":"1004762451","pt":1580636902946,"mc":[{"id":"1.168209733","rc":[{"batb":[[0,1.01,10.52],[1,1.01,0]],"ltp":1.85,"tv":10.6,"id":8174357},{"batb":[[0,1.01,10.52],[1,1.01,0]],"ltp":0.0,"tv":0.0,"id":7412952}]}]}
{"op":"mcm","clk":"1004763454","pt":1580636922892,"mc":[{"id":"1.168209733","rc":[{"batb":[[0,1.71,130.96],[1,1.69,218.23],[2,1.46,435.71]],"batl":[[0,1.77,42.01],[1,1.78,189.13],[2,1.8,178.32]],"ltp":1.85,"tv":10.6,"id":8174357},{"batb":[[0,2.28,32.77],[1,1.82,401.24],[2,1.01,10.52]],"batl":[[0,2.6,26.05]],"ltp":0.0,"tv":0.0,"id":7412952}]}]}
{"op":"mcm","clk":"1004763543","pt":1580636924280,"mc":[{"id":"1.168209733","rc":[{"batb":[[2,1.63,66.38]],"ltp":1.85,"tv":10.6,"id":8174357}]}]}
{"op":"mcm","clk":"1004764100","pt":1580636934904,"mc":[{"id":"1.168209733","rc":[{"batb":[[2,1.46,435.71]],"batl":[[0,1.78,189.13],[1,1.8,178.32],[2,1.8,0]],"ltp":1.85,"tv":10.6,"id":8174357},{"batb":[[0,1.82,401.24],[1,1.01,10.52],[2,1.01,0]],"ltp":0.0,"tv":0.0,"id":7412952}]}]}
{"op":"mcm","clk":"1004764104","pt":1580636935007,"mc":[{"id":"1.168209733","rc":[{"batb":[[0,1.46,435.71],[1,1.01,10.51],[2,1.46,0]],"ltp":1.85,"tv":10.6,"id":8174357}]}]}
{"op":"mcm","clk":"1004764328","pt":1580636938918,"mc":[{"id":"1.168209733","rc":[{"batb":[[1,1.45,321.42],[2,1.44,204.56]],"batl":[[0,1.96,151.82],[1,1.98,133.09]],"ltp":1.85,"tv":10.6,"id":8174357}]}]}
{"op":"mcm","clk":"1004764351","pt":1580636939489,"mc":[{"id":"1.168209733","rc":[{"batb":[[1,1.01,10.51],[2,1.44,0]],"ltp":1.85,"tv":10.6,"id":8174357}]}]}
{"op":"mcm","clk":"1004764431","pt":1580636940927,"mc":[{"id":"1.168209733","rc":[{"batb":[[0,1.01,10.52],[1,1.01,0]],"ltp":1.85,"tv":10.6,"id":8174357}]}]}
{"op":"mcm","clk":"1004764528","pt":1580636942692,"mc":[{"id":"1.168209733","rc":[{"batb":[[0,1.87,172.19],[1,1.85,161.59],[2,1.01,10.52]],"ltp":1.85,"tv":10.6,"id":8174357}]}]}
{"op":"mcm","clk":"1004764598","pt":1580636943890,"mc":[{"id":"1.168209733","rc":[{"batb":[[2,1.76,54.61]],"batl":[[0,1.96,193.83]],"ltp":1.85,"tv":10.6,"id":8174357},{"batb":[[0,2.06,39.49],[1,1.82,401.24],[2,1.01,10.52]],"batl":[[0,2.3,31.93]],"ltp":0.0,"tv":0.0,"id":7412952}]}]}
{"op":"mcm","clk":"1004765273","pt":1580636954938,"mc":[{"id":"1.168209733","rc":[{"batb":[[0,1.76,54.61],[1,1.55,420.5],[2,1.01,10.52]],"batl":[[0,1.96,42.01],[1,1.98,0]],"ltp":1.85,"tv":10.6,"id":8174357}]}]}
{"op":"mcm","clk":"1004765290","pt":1580636955247,"mc":[{"id":"1.168209733","rc":[{"batb":[[0,1.55,420.5],[1,1.01,10.52],[2,1.01,0]],"ltp":1.85,"tv":10.6,"id":8174357},{"batb":[[0,1.82,401.24],[1,1.01,10.52],[2,1.01,0]],"ltp":0.0,"tv":0.0,"id":7412952}]}]}
{"op":"mcm","clk":"1004765423","pt":1580636957839,"mc":[{"id":"1.168209733","rc":[{"batb":[[0,1.69,160.24],[1,1.67,227.7],[2,1.55,420.5]],"batl":[[0,2.08,143.2],[1,2.1,112.11]],"ltp":1.85,"tv":10.6,"id":8174357}]}]}
{"op":"mcm","clk":"1004765459","pt":1580636958410,"mc":[{"id":"1.168209733","rc":[{"batb":[[0,1.55,420.5],[1,1.01,10.52],[2,1.55,0]],"ltp":1.85,"tv":10.6,"id":8174357}]}]}
{"op":"mcm","clk":"1004765579","pt":1580636960939,"mc":[{"id":"1.168209733","rc":[{"batb":[[0,1.01,10.52],[1,1.01,0]],"ltp":1.85,"tv":10.6,"id":8174357},{"batb":[[0,1.01,10.52],[1,1.01,0]],"ltp":0.0,"tv":0.0,"id":7412952}]}]}
{"op":"mcm","clk":"1004765636","pt":1580636961919,"mc":[{"id":"1.168209733","rc":[{"batb":[[0,1.87,47.89],[1,1.01,10.52]],"batl":[[0,2.1,37.81]],"ltp":1.85,"tv":10.6,"id":8174357},{"batb":[[0,1.93,126.33],[1,1.91,191.4],[2,1.01,10.52]],"batl":[[0,2.02,147.83],[1,2.04,121.96],[2,2.14,36.13]],"ltp":0.0,"tv":0.0,"id":7412952}]}]}
{"op":"mcm","clk":"1004765790","pt":1580636964151,"mc":[{"id":"1.168209733","rc":[{"batb":[[1,1.62,415.43],[2,1.01,10.52]],"ltp":1.85,"tv":10.6,"id":8174357},{"batb":[[2,1.62,415.43]],"ltp":0.0,"tv":0.0,"id":7412952}]}]}
{"op":"mcm","clk":"1004767017","pt":1580636985768,"mc":[{"id":"1.168209733","rc":[{"batb":[[0,1.93,104.9]],"ltp":0.0,"tv":0.0,"id":7412952}]}]}
{"op":"mcm","clk":"1004767187","pt":1580636988670,"mc":[{"id":"1.168209733","rc":[{"batl":[[0,2.02,168.33]],"ltp":0.0,"tv":0.0,"id":7412952}]}]}
{"op":"mcm","clk":"1004767291","pt":1580636990473,"mc":[{"id":"1.168209733","rc":[{"batb":[[0,1.91,45.37],[1,1.62,415.43],[2,1.01,10.52]],"batl":[[0,2.14,36.13],[1,2.04,0],[2,2.14,0]],"ltp":0.0,"tv":0.0,"id":7412952}]}]}
{"op":"mcm","clk":"1004767318","pt":1580636990998,"mc":[{"id":"1.168209733","rc":[{"batb":[[0,1.62,415.43],[1,1.01,10.52],[2,1.01,0]],"ltp":1.85,"tv":10.6,"id":8174357},{"batb":[[0,1.62,415.43],[1,1.01,10.52],[2,1.01,0]],"ltp":0.0,"tv":0.0,"id":7412952}]}]}
{"op":"mcm","clk":"1004767447","pt":1580636993481,"mc":[{"id":"1.168209733","rc":[{"batb":[[0,1.72,202.59],[1,1.7,214.78],[2,1.62,415.43]],"batl":[[0,2.16,191],[1,2.18,100.83]],"ltp":0.0,"tv":0.0,"id":7412952}]}]}
{"op":"mcm","clk":"1004767476","pt":1580636994104,"mc":[{"id":"1.168209733","rc":[{"batb":[[0,1.62,415.43],[1,1.01,10.52],[2,1.62,0]],"ltp":0.0,"tv":0.0,"id":7412952}]}]}
{"op":"mcm","clk":"1004767640","pt":1580636996876,"mc":[{"id":"1.168209733","rc":[{"batb":[[0,1.01,10.52],[1,1.01,0]],"ltp":0.0,"tv":0.0,"id":7412952}]}]}
{"op":"mcm","clk":"1004767708","pt":1580636997919,"mc":[{"id":"1.168209733","rc":[{"batb":[[0,1.87,157.71],[1,1.85,161.57],[2,1.77,53.77]],"batl":[[0,1.96,165.52],[1,1.98,133.06]],"ltp":1.85,"tv":10.6,"id":8174357},{"batl":[[0,2.28,32.77]],"ltp":0.0,"tv":0.0,"id":7412952}]}]}
{"op":"mcm","clk":"1004767876","pt":1580637000710,"mc":[{"id":"1.168209733","rc":[{"batb":[[0,1.7,409.32],[1,1.01,10.52]],"ltp":0.0,"tv":0.0,"id":7412952}]}]}
{"op":"mcm","clk":"1004768441","pt":1580637009524,"mc":[{"id":"1.168209733","rc":[{"batb":[[0,1.77,53.77],[1,1.62,415.43],[2,1.01,10.52]],"batl":[[0,1.96,42.01],[1,1.98,0]],"ltp":1.85,"tv":10.6,"id":8174357},{"batb":[[0,2.04,40.33],[1,1.7,409.32],[2,1.01,10.52]],"ltp":0.0,"tv":0.0,"id":7412952}]}]}
{"op":"mcm","clk":"1004768566","pt":1580637011488,"mc":[{"id":"1.168209733","rc":[{"batb":[[0,1.62,415.43],[1,1.01,10.52],[2,1.01,0]],"ltp":1.85,"tv":10.6,"id":8174357},{"batb":[[0,1.7,409.32],[1,1.01,10.52],[2,1.01,0]],"ltp":0.0,"tv":0.0,"id":7412952}]}]}
{"op":"mcm","clk":"1004768709","pt":1580637013715,"mc":[{"id":"1.168209733","rc":[{"batb":[[0,1.01,10.52],[1,1.01,0]],"ltp":1.85,"tv":10.6,"id":8174357},{"batb":[[0,1.01,10.52],[1,1.01,0]],"ltp":0.0,"tv":0.0,"id":7412952}]}]}
{"op":"mcm","clk":"1004768849","pt":1580637015941,"mc":[{"id":"1.168209733","rc":[{"batb":[[0,1.7,59.65],[1,1.01,10.52]],"batl":[[0,1.88,42.01]],"ltp":1.85,"tv":10.6,"id":8174357},{"batb":[[0,2.14,36.13],[1,1.01,10.52]],"batl":[[0,2.42,29.41]],"ltp":0.0,"tv":0.0,"id":7412952}]}]}
{"op":"mcm","clk":"1004768860","pt":1580637016002,"mc":[{"id":"1.168209733","rc":[{"batb":[[0,1.8,108.98],[1,1.78,183.04],[2,1.7,59.65]],"batl":[[0,1.87,126.22],[1,1.88,42.01],[2,1.89,153.22]],"ltp":1.85,"tv":10.6,"id":8174357}]}]}
{"op":"mcm","clk":"1004768942","pt":1580637017805,"mc":[{"id":"1.168209733","rc":[{"batb":[[1,1.77,402.27],[2,1.01,10.52]],"ltp":0.0,"tv":0.0,"id":7412952}]}]}
{"op":"mcm","clk":"1004769469","pt":1580637027672,"mc":[{"id":"1.168209733","rc":[{"batb":[[0,1.7,59.65],[1,1.5,426.9],[2,1.01,10.52]],"batl":[[0,1.88,42.01],[1,1.88,0],[2,1.89,0]],"ltp":1.85,"tv":10.6,"id":8174357}]}]}
{"op":"mcm","clk":"1004769548","pt":1580637029232,"mc":[{"id":"1.168209733","rc":[{"batb":[[0,1.5,426.9],[1,1.01,10.52],[2,1.01,0]],"ltp":1.85,"tv":10.6,"id":8174357},{"batb":[[0,1.77,402.27],[1,1.01,10.52],[2,1.01,0]],"ltp":0.0,"tv":0.0,"id":7412952}]}]}
{"op":"mcm","clk":"1004769638","pt":1580637030938,"mc":[{"id":"1.168209733","rc":[{"batb":[[0,1.75,162.43],[1,1.73,201.55],[2,1.5,426.9]],"batl":[[0,1.98,131.28],[1,2,129.18]],"ltp":1.85,"tv":10.6,"id":8174357}]}]}
{"op":"mcm","clk":"1004769688","pt":1580637031766,"mc":[{"id":"1.168209733","rc":[{"batb":[[0,1.5,426.9],[1,1.01,10.52],[2,1.5,0]],"ltp":1.85,"tv":10.6,"id":8174357}]}]}
{"op":"mcm","clk":"1004769858","pt":1580637034763,"mc":[{"id":"1.168209733","rc":[{"batb":[[0,1.81,187.2],[1,1.79,179.89],[2,1.5,426.9]],"batl":[[0,1.89,119.59],[1,1.91,148.36]],"ltp":1.85,"tv":10.6,"id":8174357}]}]}
{"op":"mcm","clk":"1004770152","pt":1580637039158,"mc":[{"id":"1.168209733","rc":[{"batb":[[0,1.5,426.9],[1,1.01,10.52],[2,1.5,0]],"ltp":1.85,"tv":10.6,"id":8174357}]}]}
{"op":"mcm","clk":"1004770371","pt":1580637042158,"mc":[{"id":"1.168209733","rc":[{"batb":[[0,1.75,160.09],[1,1.73,201.55],[2,1.5,426.9]],"batl":[[0,1.98,133.35],[1,2,129.19]],"ltp":1.85,"tv":10.6,"id":8174357}]}]}
{"op":"mcm","clk":"1004770820","pt":1580637048983,"mc":[{"id":"1.168209733","rc":[{"batl":[[0,1.81,139.47],[1,1.98,133.35],[2,2,129.19]],"ltp":1.85,"tv":10.6,"id":8174357}]}]}
{"op":"mcm","clk":"1004770892","pt":1580637050376,"mc":[{"id":"1.168209733","rc":[{"batb":[[0,1.5,426.9],[1,1.01,10.52],[2,1.5,0]],"ltp":1.85,"tv":10.6,"id":8174357}]}]}
{"op":"mcm","clk":"1004771021","pt":1580637052804,"mc":[{"id":"1.168209733","rc":[{"batb":[[0,1.01,10.52],[1,1.01,0]],"ltp":1.85,"tv":10.6,"id":8174357}]}]}
{"op":"mcm","clk":"1004771073","pt":1580637053890,"mc":[{"id":"1.168209733","rc":[{"trd":[[1.81,278.94]],"batb":[[0,1.89,34.37],[1,1.87,156.12],[2,1.01,10.52]],"ltp":1.81,"tv":289.54,"id":8174357}],"tv":289.54}]}
{"op":"mcm","clk":"1004771140","pt":1580637055703,"mc":[{"id":"1.168209733","rc":[{"batl":[[0,2.22,37.86]],"ltp":0.0,"tv":0.0,"id":7412952}]}]}
{"op":"mcm","clk":"1004771167","pt":1580637056416,"mc":[{"id":"1.168209733","rc":[{"batb":[[0,1.89,124.95],[2,1.79,52.93]],"batl":[[0,1.97,156.5],[1,1.99,131.21]],"ltp":1.81,"tv":289.54,"id":8174357},{"batb":[[0,2.02,41.17],[1,1.77,402.27],[2,1.01,10.52]],"batl":[[0,2.26,32.77]],"ltp":0.0,"tv":0.0,"id":7412952}]}]}
{"op":"mcm","clk":"1004771744","pt":1580637068511,"mc":[{"id":"1.168209733","rc":[{"batb":[[0,1.79,52.93],[1,1.58,416.47],[2,1.01,10.52]],"batl":[[0,1.97,42.01],[1,1.99,0]],"ltp":1.81,"tv":289.54,"id":8174357}]}]}
{"op":"mcm","clk":"1004771771","pt":1580637069123,"mc":[{"id":"1.168209733","rc":[{"batb":[[0,1.58,416.47],[1,1.01,10.52],[2,1.01,0]],"ltp":1.81,"tv":289.54,"id":8174357},{"batb":[[0,1.77,402.27],[1,1.01,10.52],[2,1.01,0]],"ltp":0.0,"tv":0.0,"id":7412952}]}]}
{"op":"mcm","clk":"1004771951","pt":1580637071803,"mc":[{"id":"1.168209733","rc":[{"batb":[[0,1.79,172.94],[1,1.77,186.8],[2,1.58,416.47]],"batl":[[0,2.22,132.65],[1,2.24,93.54]],"ltp":1.81,"tv":289.54,"id":8174357}]}]}
{"op":"mcm","clk":"1004772085","pt":1580637074936,"mc":[{"id":"1.168209733","rc":[{"batb":[[0,1.58,416.47],[1,1.01,10.52],[2,1.58,0]],"ltp":1.81,"tv":289.54,"id":8174357}]}]}
{"op":"mcm","clk":"1004772226","pt":1580637077922,"mc":[{"id":"1.168209733","rc":[{"batb":[[0,1.78,170.64],[1,1.76,190.63],[2,1.58,416.47]],"batl":[[0,1.86,165.31],[1,1.88,156.02]],"ltp":1.81,"tv":289.54,"id":8174357}]}]}
{"op":"mcm","clk":"1004772256","pt":1580637078638,"mc":[{"id":"1.168209733","rc":[{"batb":[[2,1.01,10.52]],"ltp":1.81,"tv":289.54,"id":8174357},{"batb":[[0,2.16,36.13],[1,1.77,402.27],[2,1.01,10.52]],"ltp":0.0,"tv":0.0,"id":7412952}]}]}
{"op":"mcm","clk":"1004772313","pt":1580637079722,"mc":[{"id":"1.168209733","rc":[{"batb":[[2,1.7,59.65]],"batl":[[1,1.88,198.03]],"ltp":1.81,"tv":289.54,"id":8174357},{"batl":[[0,2.42,29.41]],"ltp":0.0,"tv":0.0,"id":7412952}]}]}
{"op":"mcm","clk":"1004772329","pt":1580637080061,"mc":[{"id":"1.168209733","rc":[{"batb":[[0,1.78,142.38]],"batl":[[0,1.88,42.01],[1,1.88,0]],"ltp":1.81,"tv":289.54,"id":8174357}]}]}
{"op":"mcm","clk":"1004772449","pt":1580637082939,"mc":[{"id":"1.168209733","rc":[{"batl":[[0,1.85,112.64],[1,1.87,158.82],[2,1.88,42.01]],"ltp":1.81,"tv":289.54,"id":8174357}]}]}
{"op":"mcm","clk":"1004772933","pt":1580637093939,"mc":[{"id":"1.168209733","rc":[{"batb":[[0,1.7,59.65],[1,1.01,10.52],[2,1.7,0]],"batl":[[0,1.88,42.01],[1,1.87,0],[2,1.88,0]],"ltp":1.81,"tv":289.54,"id":8174357}]}]}
{"op":"mcm","clk":"1004772971","pt":1580637095059,"mc":[{"id":"1.168209733","rc":[{"batb":[[0,1.01,10.52],[1,1.01,0]],"ltp":1.81,"tv":289.54,"id":8174357},{"batb":[[0,1.77,402.27],[1,1.01,10.52],[2,1.01,0]],"ltp":0.0,"tv":0.0,"id":7412952}]}]}
{"op":"mcm","clk":"1004773049","pt":1580637096857,"mc":[{"id":"1.168209733","rc":[{"batb":[[0,1.74,142.2],[1,1.72,206.08],[2,1.01,10.52]],"batl":[[0,1.95,113.03],[1,1.97,135.44]],"ltp":1.81,"tv":289.54,"id":8174357}]}]}
{"op":"mcm","clk":"1004773276","pt":1580637101852,"mc":[{"id":"1.168209733","rc":[{"batb":[[0,1.01,10.52],[1,1.72,0],[2,1.01,0]],"ltp":1.81,"tv":289.54,"id":8174357}]}]}
{"op":"mcm","clk":"1004773557","pt":1580637107666,"mc":[{"id":"1.168209733","rc":[{"batb":[[0,1.74,142.2],[1,1.72,206.08],[2,1.01,10.52]],"batl":[[0,1.95,113.03],[1,1.97,135.44]],"ltp":1.81,"tv":289.54,"id":8174357}]}]}
{"op":"mcm","clk":"1004774174","pt":1580637119184,"mc":[{"id":"1.168209733","rc":[{"batb":[[0,1.01,10.52],[1,1.72,0],[2,1.01,0]],"ltp":1.81,"tv":289.54,"id":8174357}]}]}
{"op":"mcm","clk":"1004774445","pt":1580637124126,"mc":[{"id":"1.168209733","rc":[{"batb":[[0,1.58,12.25],[1,1.01,10.52]],"ltp":1.81,"tv":289.54,"id":8174357}]}]}
{"op":"mcm","clk":"1004774583","pt":1580637126699,"mc":[{"id":"1.168209733","rc":[{"batb":[[0,1.77,117.87],[1,1.75,194.24],[2,1.58,12.25]],"batl":[[0,1.84,144.77],[1,1.86,161.42]],"ltp":1.81,"tv":289.54,"id":8174357}]}]}
{"op":"mcm","clk":"1004774608","pt":1580637127110,"mc":[{"id":"1.168209733","rc":[{"batb":[[0,1.75,194.24],[1,1.58,12.25],[2,1.01,10.52]],"ltp":1.81,"tv":289.54,"id":8174357}]}]}
{"op":"mcm","clk":"1004774686","pt":1580637128295,"mc":[{"id":"1.168209733","rc":[{"batb":[[1,1.66,63.01],[2,1.58,12.25]],"ltp":1.81,"tv":289.54,"id":8174357},{"batb":[[0,2.22,33.61],[1,1.77,402.27],[2,1.01,10.52]],"batl":[[0,2.52,26.89]],"ltp":0.0,"tv":0.0,"id":7412952}]}]}
{"op":"mcm","clk":"1004774755","pt":1580637129731,"mc":[{"id":"1.168209733","rc":[{"batl":[[0,1.82,42.01]],"ltp":1.81,"tv":289.54,"id":8174357}]}]}
{"op":"mcm","clk":"1004774815","pt":1580637130318,"mc":[{"id":"1.168209733","rc":[{"batb":[[1,1.73,202.64],[2,1.66,63.01]],"batl":[[1,1.83,172.84],[2,1.85,164.48]],"ltp":1.81,"tv":289.54,"id":8174357}]}]}
{"op":"mcm","clk":"1004775994","pt":1580637148131,"mc":[{"id":"1.168209733","rc":[{"batb":[[0,1.66,63.01],[1,1.58,12.25],[2,1.01,10.52]],"batl":[[2,1.85,0]],"ltp":1.81,"tv":289.54,"id":8174357}]}]}
{"op":"mcm","clk":"1004776181","pt":1580637151451,"mc":[{"id":"1.168209733","rc":[{"batb":[[0,1.74,138.1],[1,1.72,207.05],[2,1.66,63.01]],"batl":[[0,1.81,109],[1,1.82,42.01],[2,1.83,172.84]],"ltp":1.81,"tv":289.54,"id":8174357}]}]}
{"op":"mcm","clk":"1004776363","pt":1580637154346,"mc":[{"id":"1.168209733","rc":[{"batl":[[0,1.81,156.85]],"ltp":1.81,"tv":289.54,"id":8174357}]}]}
{"op":"mcm","clk":"1004779226","pt":1580637209945,"mc":[{"id":"1.168209733","rc":[{"batb":[[0,1.66,63.01],[1,1.58,12.25],[2,1.01,10.52]],"batl":[[0,1.82,42.01],[1,1.82,0],[2,1.83,0]],"ltp":1.81,"tv":289.54,"id":8174357}]}]}
{"op":"mcm","clk":"1004779285","pt":1580637211236,"mc":[{"id":"1.168209733","rc":[{"batb":[[0,1.58,12.25],[1,1.01,10.52],[2,1.01,0]],"ltp":1.81,"tv":289.54,"id":8174357},{"batb":[[0,1.77,402.27],[1,1.01,10.52],[2,1.01,0]],"ltp":0.0,"tv":0.0,"id":7412952}]}]}
{"op":"mcm","clk":"1004779355","pt":1580637212935,"mc":[{"id":"1.168209733","rc":[{"batb":[[1,1.57,202.76],[2,1.56,148.89]],"batl":[[0,1.91,101.95],[1,1.93,144.72]],"ltp":1.81,"tv":289.54,"id":8174357}]}]}
{"op":"mcm","clk":"1004779920","pt":1580637224783,"mc":[{"id":"1.168209733","rc":[{"batb":[[1,1.01,10.52],[2,1.56,0]],"ltp":1.81,"tv":289.54,"id":8174357}]}]}
{"op":"mcm","clk":"1004780057","pt":1580637227868,"mc":[{"id":"1.168209733","rc":[{"batb":[[0,1.84,106.13],[1,1.82,171.24],[2,1.58,12.25]],"ltp":1.81,"tv":289.54,"id":8174357}]}]}
{"op":"mcm","clk":"1004780096","pt":1580637228688,"mc":[{"id":"1.168209733","rc":[{"batb":[[0,2.08,38.65],[1,1.77,402.27],[2,1.01,10.52]],"batl":[[0,2.34,31.09]],"ltp":0.0,"tv":0.0,"id":7412952}]}]}
{"op":"mcm","clk":"1004780205","pt":1580637230696,"mc":[{"id":"1.168209733","rc":[{"batb":[[2,1.75,55.45]],"batl":[[1,1.92,42.01],[2,1.93,144.72]],"ltp":1.81,"tv":289.54,"id":8174357}]}]}
{"op":"mcm","clk":"1004780828","pt":1580637242737,"mc":[{"id":"1.168209733","rc":[{"batb":[[0,1.75,55.45],[1,1.58,12.25],[2,1.01,10.52]],"batl":[[0,1.92,42.01],[1,1.92,0],[2,1.93,0]],"ltp":1.81,"tv":289.54,"id":8174357}]}]}
{"op":"mcm","clk":"1004780851","pt":1580637243309,"mc":[{"id":"1.168209733","rc":[{"batb":[[0,1.58,12.25],[1,1.01,10.52],[2,1.01,0]],"ltp":1.81,"tv":289.54,"id":8174357},{"batb":[[0,1.77,402.27],[1,1.01,10.52],[2,1.01,0]],"ltp":0.0,"tv":0.0,"id":7412952}]}]}
{"op":"mcm","clk":"1004781004","pt":1580637246706,"mc":[{"id":"1.168209733","rc":[{"batb":[[0,1.69,178.81],[1,1.67,229.75],[2,1.58,12.25]],"batl":[[0,2,111.34],[1,2.02,126.14]],"ltp":1.81,"tv":289.54,"id":8174357}]}]}
{"op":"mcm","clk":"1004781319","pt":1580637252950,"mc":[{"id":"1.168209733","rc":[{"batb":[[2,1.01,10.52]],"ltp":1.81,"tv":289.54,"id":8174357}]}]}
{"op":"mcm","clk":"1004781322","pt":1580637253002,"mc":[{"id":"1.168209733","rc":[{"batl":[[0,1.76,172.51],[1,1.78,186.68]],"ltp":1.81,"tv":289.54,"id":8174357}]}]}
{"op":"mcm","clk":"1004781383","pt":1580637254235,"mc":[{"id":"1.168209733","rc":[{"batb":[[2,1.64,65.54]],"batl":[[2,1.79,42.01]],"ltp":1.81,"tv":289.54,"id":8174357},{"batb":[[0,2.28,32.77],[1,1.77,402.27],[2,1.01,10.52]],"batl":[[0,2.6,26.05]],"ltp":0.0,"tv":0.0,"id":7412952}]}]}
{"op":"mcm","clk":"1004781920","pt":1580637265186,"mc":[{"id":"1.168209733","rc":[{"batb":[[0,1.67,115.86],[1,1.01,10.52],[2,1.64,0]],"ltp":1.81,"tv":289.54,"id":8174357}]}]}
{"op":"mcm","clk":"1004782097","pt":1580637268547,"mc":[{"id":"1.168209733","rc":[{"batb":[[0,1.68,162.09],[1,1.67,115.86],[2,1.63,66.38]],"batl":[[0,1.75,202.27],[1,1.77,232.59]],"ltp":1.81,"tv":289.54,"id":8174357}]}]}
{"op":"mcm","clk":"1004782194","pt":1580637270665,"mc":[{"id":"1.168209733","rc":[{"batb":[[0,1.63,66.38],[1,1.01,10.52],[2,1.63,0]],"batl":[[0,1.77,42.01],[1,1.77,0]],"ltp":1.81,"tv":289.54,"id":8174357}]}]}
{"op":"mcm","clk":"1004782231","pt":1580637271536,"mc":[{"id":"1.168209733","rc":[{"batb":[[0,1.01,10.52],[1,1.01,0]],"ltp":1.81,"tv":289.54,"id":8174357},{"batb":[[0,1.77,402.27],[1,1.01,10.52],[2,1.01,0]],"ltp":0.0,"tv":0.0,"id":7412952}]}]}
{"op":"mcm","clk":"1004782342","pt":1580637273848,"mc":[{"id":"1.168209733","rc":[{"batb":[[0,1.49,161.98],[1,1.48,184.28],[2,1.01,10.51]],"batl":[[0,1.88,173.64],[1,1.9,152.09]],"ltp":1.81,"tv":289.54,"id":8174357}]}]}
{"op":"mcm","clk":"1004782951","pt":1580637285755,"mc":[{"id":"1.168209733","rc":[{"batb":[[0,1.01,10.52],[1,1.48,0],[2,1.01,0]],"ltp":1.81,"tv":289.54,"id":8174357}]}]}
{"op":"mcm","clk":"1004783105","pt":1580637288689,"mc":[{"id":"1.168209733","rc":[{"batb":[[0,1.8,146.09],[1,1.78,184.7],[2,1.73,57.13]],"batl":[[1,1.9,194.1]],"ltp":1.81,"tv":289.54,"id":8174357},{"batb":[[0,2.1,37.81],[1,1.77,402.27],[2,1.01,10.52]],"batl":[[0,2.36,30.25]],"ltp":0.0,"tv":0.0,"id":7412952}]}]}
{"op":"mcm","clk":"1004783710","pt":1580637301595,"mc":[{"id":"1.168209733","rc":[{"batb":[[0,1.73,57.13],[1,1.55,4.82],[2,1.01,10.52]],"batl":[[0,1.9,42.01],[1,1.9,0]],"ltp":1.81,"tv":289.54,"id":8174357}]}]}
{"op":"mcm","clk":"1004783796","pt":1580637303307,"mc":[{"id":"1.168209733","rc":[{"batb":[[0,1.55,4.82],[1,1.01,10.52],[2,1.01,0]],"ltp":1.81,"tv":289.54,"id":8174357},{"batb":[[0,1.77,402.27],[1,1.01,10.52],[2,1.01,0]],"ltp":0.0,"tv":0.0,"id":7412952}]}]}
{"op":"mcm","clk":"1004783847","pt":1580637304537,"mc":[{"id":"1.168209733","rc":[{"batb":[[0,1.63,240.02],[1,1.62,129.58],[2,1.55,4.82]],"batl":[[0,1.98,115.4],[1,2,130.13]],"ltp":1.81,"tv":289.54,"id":8174357}]}]}
{"op":"mcm","clk":"1004783893","pt":1580637305838,"mc":[{"id":"1.168209733","rc":[{"batb":[[0,1.55,4.82],[1,1.01,10.52],[2,1.55,0]],"ltp":1.81,"tv":289.54,"id":8174357}]}]}
{"op":"mcm","clk":"1004783958","pt":1580637307017,"mc":[{"id":"1.168209733","rc":[{"batb":[[0,1.01,10.52],[1,1.01,0]],"ltp":1.81,"tv":289.54,"id":8174357},{"batb":[[0,1.01,10.52],[1,1.01,0]],"ltp":0.0,"tv":0.0,"id":7412952}]}]}
{"op":"mcm","clk":"1004784061","pt":1580637308837,"mc":[{"id":"1.168209733","rc":[{"batb":[[0,1.9,120.16],[1,1.88,154.43],[2,1.01,10.52]],"ltp":1.81,"tv":289.54,"id":8174357}]}]}
{"op":"mcm","clk":"1004784122","pt":1580637310211,"mc":[{"id":"1.168209733","rc":[{"batb":[[2,1.82,50.41]],"batl":[[2,2.02,41.17]],"ltp":1.81,"tv":289.54,"id":8174357},{"batb":[[0,1.97,42.85],[1,1.01,10.52]],"batl":[[0,2.22,33.61]],"ltp":0.0,"tv":0.0,"id":7412952}]}]}
{"op":"mcm","clk":"1004784213","pt":1580637311718,"mc":[{"id":"1.168209733","rc":[{"batb":[[1,1.62,828.82],[2,1.01,10.52]],"ltp":0.0,"tv":0.0,"id":7412952}]}]}
{"op":"mcm","clk":"1004784555","pt":1580637318953,"mc":[{"id":"1.168209733","rc":[{"batb":[[0,1.82,50.41],[1,1.62,19.43],[2,1.01,10.52]],"batl":[[0,2.02,41.17],[1,2,0],[2,2.02,0]],"ltp":1.81,"tv":289.54,"id":8174357}]}]}
{"op":"mcm","clk":"1004784573","pt":1580637319359,"mc":[{"id":"1.168209733","rc":[{"batb":[[0,1.62,19.43],[1,1.01,10.52],[2,1.01,0]],"ltp":1.81,"tv":289.54,"id":8174357},{"batb":[[0,1.62,828.82],[1,1.01,10.52],[2,1.01,0]],"ltp":0.0,"tv":0.0,"id":7412952}]}]}
{"op":"mcm","clk":"1004784680","pt":1580637321867,"mc":[{"id":"1.168209733","rc":[{"batb":[[0,1.8,161.17],[1,1.78,184.67],[2,1.62,19.43]],"batl":[[0,2.04,149.61],[1,2.06,119.25]],"ltp":1.81,"tv":289.54,"id":8174357}]}]}
{"op":"mcm","clk":"1004784734","pt":1580637322857,"mc":[{"id":"1.168209733","rc":[{"batb":[[0,1.01,10.52],[1,1.78,0],[2,1.62,0]],"ltp":1.81,"tv":289.54,"id":8174357}]}]}
{"op":"mcm","clk":"1004784844","pt":1580637324780,"mc":[{"id":"1.168209733","rc":[{"batb":[[0,1.95,112.84],[1,1.93,142.14],[2,1.89,47.05]],"batl":[[2,2.1,37.81]],"ltp":1.81,"tv":289.54,"id":8174357},{"batb":[[0,1.91,45.37],[1,1.62,828.82],[2,1.01,10.52]],"batl":[[0,2.12,36.97]],"ltp":0.0,"tv":0.0,"id":7412952}]}]}
{"op":"mcm","clk":"1004786403","pt":1580637359744,"mc":[{"id":"1.168209733","rc":[{"batb":[[0,1.67,18.36],[1,1.01,10.52],[2,1.89,0]],"ltp":1.81,"tv":289.54,"id":8174357},{"batb":[[0,1.62,828.82],[1,1.01,10.52],[2,1.01,0]],"ltp":0.0,"tv":0.0,"id":7412952}]}]}
{"op":"mcm","clk":"1004786574","pt":1580637362803,"mc":[{"id":"1.168209733","rc":[{"batb":[[0,1.83,124.26],[1,1.81,174.71],[2,1.67,18.36]],"batl":[[0,2.36,130.78],[1,2.4,156.56]],"ltp":1.81,"tv":289.54,"id":8174357}]}]}
{"op":"mcm","clk":"1004786597","pt":1580637363214,"mc":[{"id":"1.168209733","rc":[{"batb":[[0,1.67,18.36],[1,1.01,10.52],[2,1.67,0]],"ltp":1.81,"tv":289.54,"id":8174357}]}]}
{"op":"mcm","clk":"1004786819","pt":1580637366212,"mc":[{"id":"1.168209733","rc":[{"batb":[[0,1.91,172.84],[1,1.89,151.79],[2,1.62,828.82]],"batl":[[0,2,121.66],[1,2.02,126.13]],"ltp":0.0,"tv":0.0,"id":7412952}]}]}
{"op":"mcm","clk":"1004786900","pt":1580637367923,"mc":[{"id":"1.168209733","rc":[{"batb":[[0,1.62,828.82],[1,1.01,10.52],[2,1.62,0]],"batl":[[0,2,97.36]],"ltp":0.0,"tv":0.0,"id":7412952}]}]}
{"op":"mcm","clk":"1004787279","pt":1580637374851,"mc":[{"id":"1.168209733","rc":[{"batb":[[0,1.74,157.93],[1,1.72,206.29],[2,1.62,828.82]],"batl":[[0,2.22,153.55],[1,2.24,94.16]],"ltp":0.0,"tv":0.0,"id":7412952}]}]}
{"op":"mcm","clk":"1004787329","pt":1580637375732,"mc":[{"id":"1.168209733","rc":[{"batb":[[0,1.01,10.52],[1,1.01,0]],"ltp":1.81,"tv":289.54,"id":8174357},{"batb":[[2,1.01,10.52]],"ltp":0.0,"tv":0.0,"id":7412952}]}]}
{"op":"mcm","clk":"1004787380","pt":1580637376661,"mc":[{"id":"1.168209733","rc":[{"batl":[[0,1.81,135.12],[1,1.83,169.96]],"ltp":0.0,"tv":0.0,"id":7412952}]}]}
{"op":"mcm","clk":"1004787486","pt":1580637378472,"mc":[{"id":"1.168209733","rc":[{"batb":[[0,2.14,36.13],[1,1.01,10.52]],"batl":[[0,2.42,29.41]],"ltp":1.81,"tv":289.54,"id":8174357},{"batb":[[1,1.72,264.26]],"batl":[[2,1.88,42.01]],"ltp":0.0,"tv":0.0,"id":7412952}]}]}
{"op":"mcm","clk":"1004787562","pt":1580637379657,"mc":[{"id":"1.168209733","rc":[{"batb":[[1,1.82,49.37],[2,1.01,10.52]],"ltp":1.81,"tv":289.54,"id":8174357},{"batb":[[2,1.46,877.11]],"ltp":0.0,"tv":0.0,"id":7412952}]}]}
{"op":"mcm","clk":"1004788178","pt":1580637388873,"mc":[{"id":"1.168209733","rc":[{"batb":[[0,1.72,57.97],[1,1.46,877.11],[2,1.01,10.51]],"batl":[[0,1.88,42.01],[1,1.83,0],[2,1.88,0]],"ltp":0.0,"tv":0.0,"id":7412952}]}]}
{"op":"mcm","clk":"1004788204","pt":1580637389287,"mc":[{"id":"1.168209733","rc":[{"batb":[[0,1.82,49.37],[1,1.01,10.52],[2,1.01,0]],"ltp":1.81,"tv":289.54,"id":8174357},{"batb":[[0,1.46,877.11],[1,1.01,10.51],[2,1.01,0]],"ltp":0.0,"tv":0.0,"id":7412952}]}]}
{"op":"mcm","clk":"1004788362","pt":1580637391879,"mc":[{"id":"1.168209733","rc":[{"batb":[[0,1.49,152.03],[1,1.48,181.03],[2,1.46,877.1]],"batl":[[0,1.99,96.74],[1,2.02,190.12]],"ltp":0.0,"tv":0.0,"id":7412952}]}]}
{"op":"mcm","clk":"1004788930","pt":1580637397666,"mc":[{"id":"1.168209733","rc":[{"batb":[[0,1.01,10.52],[1,1.01,0]],"ltp":1.81,"tv":289.54,"id":8174357},{"batb":[[2,1.01,10.51]],"ltp":0.0,"tv":0.0,"id":7412952}]}]}
{"op":"mcm","clk":"1004789014","pt":1580637398903,"mc":[{"id":"1.168209733","rc":[{"batl":[[0,1.54,240.44],[1,1.55,148.08]],"ltp":0.0,"tv":0.0,"id":7412952}]}]}
{"op":"mcm","clk":"1004789100","pt":1580637400297,"mc":[{"id":"1.168209733","rc":[{"batb":[[0,2.66,25.21],[1,1.01,10.52]],"batl":[[0,3.05,20.16]],"ltp":1.81,"tv":289.54,"id":8174357},{"batb":[[1,1.48,268.41]],"batl":[[2,1.6,42.01]],"ltp":0.0,"tv":0.0,"id":7412952}]}]}
{"op":"mcm","clk":"1004789201","pt":1580637401591,"mc":[{"id":"1.168209733","rc":[{"batb":[[1,2.12,99.99],[2,1.01,10.52]],"ltp":1.81,"tv":289.54,"id":8174357},{"batb":[[2,1.31,955.75]],"ltp":0.0,"tv":0.0,"id":7412952}]}]}
{"op":"mcm","clk":"1004789972","pt":1580637414912,"mc":[{"id":"1.168209733","rc":[{"batb":[[0,1.48,87.39],[1,1.31,955.75],[2,1.01,10.51]],"batl":[[0,1.6,42.01],[1,1.55,0],[2,1.6,0]],"ltp":0.0,"tv":0.0,"id":7412952}]}]}
{"op":"mcm","clk":"1004790041","pt":1580637415792,"mc":[{"id":"1.168209733","rc":[{"batb":[[0,2.12,99.99],[1,1.01,10.52],[2,1.01,0]],"ltp":1.81,"tv":289.54,"id":8174357},{"batb":[[0,1.31,955.76],[1,1.01,10.51],[2,1.01,0]],"ltp":0.0,"tv":0.0,"id":7412952}]}]}
{"op":"mcm","clk":"1004790172","pt":1580637417800,"mc":[{"id":"1.168209733","rc":[{"batb":[[1,1.26,507.84],[2,1.25,420.03]],"batl":[[0,1.71,213.73],[1,1.73,203.18]],"ltp":0.0,"tv":0.0,"id":7412952}]}]}
{"op":"mcm","clk":"1004790298","pt":1580637419707,"mc":[{"id":"1.168209733","rc":[{"batb":[[1,1.01,10.51],[2,1.25,0]],"ltp":0.0,"tv":0.0,"id":7412952}]}]}
{"op":"mcm","clk":"1004790630","pt":1580637422930,"mc":[{"id":"1.168209733","rc":[{"trd":[[1.48,0.02]],"batb":[[0,1.44,152.24],[1,1.43,209.16],[2,1.31,955.75]],"batl":[[0,1.48,167.65],[1,1.49,172.85]],"ltp":1.48,"tv":0.02,"id":7412952}],"tv":289.56}]}
{"op":"mcm","clk":"1004790969","pt":1580637427414,"mc":[{"id":"1.168209733","rc":[{"batb":[[0,1.31,955.75],[1,1.01,10.51],[2,1.31,0]],"ltp":1.48,"tv":0.02,"id":7412952}]}]}
{"op":"mcm","clk":"1004791152","pt":1580637430308,"mc":[{"id":"1.168209733","rc":[{"batb":[[1,1.26,507.85],[2,1.25,420.03]],"batl":[[0,1.71,213.72],[1,1.73,203.18]],"ltp":1.48,"tv":0.02,"id":7412952}]}]}
{"op":"mcm","clk":"1004791894","pt":1580637442922,"mc":[{"id":"1.168209733","rc":[{"batb":[[0,3.8,14.28]],"batl":[[0,4.6,10.92]],"ltp":1.81,"tv":289.54,"id":8174357},{"trd":[[1.31,1430.08]],"batb":[[0,1.28,149.55],[1,1.26,392.05],[2,1.01,10.51]],"batl":[[0,1.35,42.01]],"ltp":1.31,"tv":1430.09,"id":7412952}],"tv":1719.64}]}
{"op":"mcm","clk":"1004791986","pt":1580637444930,"mc":[{"id":"1.168209733","rc":[{"batl":[[0,1.31,37.86],[1,1.35,42.01]],"ltp":1.31,"tv":1430.09,"id":7412952}]}]}
{"op":"mcm","clk":"1004792014","pt":1580637445448,"mc":[{"id":"1.168209733","rc":[{"batb":[[1,1.27,385.23],[2,1.26,392.05]],"batl":[[0,1.3,148.59],[1,1.31,302.66],[2,1.35,42.01]],"ltp":1.31,"tv":1430.09,"id":7412952}]}]}
{"op":"mcm","clk":"1004792074","pt":1580637446533,"mc":[{"id":"1.168209733","rc":[{"batb":[[1,2.62,158.38],[2,1.01,10.52]],"ltp":1.81,"tv":289.54,"id":8174357}]}]}
{"op":"mcm","clk":"1004792487","pt":1580637453653,"mc":[{"id":"1.168209733","rc":[{"batb":[[1,1.27,281.68]],"ltp":1.31,"tv":1430.09,"id":7412952}]}]}
{"op":"mcm","clk":"1004792693","pt":1580637456942,"mc":[{"id":"1.168209733","rc":[{"batl":[[0,1.3,249.98]],"ltp":1.31,"tv":1430.09,"id":7412952}]}]}
{"op":"mcm","clk":"1004792882","pt":1580637460953,"mc":[{"id":"1.168209733","rc":[{"batb":[[1,1.01,10.51],[2,1.26,0]],"batl":[[0,1.35,42.01],[1,1.31,0],[2,1.35,0]],"ltp":1.31,"tv":1430.09,"id":7412952}]}]}
{"op":"mcm","clk":"1004792917","pt":1580637461576,"mc":[{"id":"1.168209733","rc":[{"batb":[[0,2.62,158.38],[1,1.01,10.52],[2,1.01,0]],"ltp":1.81,"tv":289.54,"id":8174357},{"batb":[[0,1.01,10.51],[1,1.01,0]],"ltp":1.31,"tv":1430.09,"id":7412952}]}]}
{"op":"mcm","clk":"1004792972","pt":1580637462451,"mc":[{"id":"1.168209733","rc":[{"batb":[[0,1.01,10.52],[1,1.01,0]],"ltp":1.81,"tv":289.54,"id":8174357}]}]}
{"op":"mcm","clk":"1004793054","pt":1580637463899,"mc":[{"id":"1.168209733","rc":[{"batb":[[0,1.13,820.93],[1,1.12,316.05],[2,1.01,10.51]],"batl":[[0,1.4,268.33],[1,1.41,214.21]],"ltp":1.31,"tv":1430.09,"id":7412952}]}]}
{"op":"mcm","clk":"1004793745","pt":1580637476683,"mc":[{"id":"1.168209733","rc":[{"batb":[[0,1.01,10.51],[1,1.12,0],[2,1.01,0]],"ltp":1.31,"tv":1430.09,"id":7412952}]}]}
{"op":"mcm","clk":"1004793892","pt":1580637479795,"mc":[{"id":"1.168209733","rc":[{"batb":[[0,1.36,194.53],[1,1.35,271.05],[2,1.01,10.51]],"ltp":1.31,"tv":1430.09,"id":7412952}]}]}
{"op":"mcm","clk":"1004793935","pt":1580637480619,"mc":[{"id":"1.168209733","rc":[{"batb":[[0,3.2,18.48],[1,1.01,10.52]],"batl":[[0,3.8,14.28]],"ltp":1.81,"tv":289.54,"id":8174357},{"batb":[[0,1.36,310.48]],"batl":[[2,1.45,42.01]],"ltp":1.31,"tv":1430.09,"id":7412952}]}]}
{"op":"mcm","clk":"1004793999","pt":1580637481600,"mc":[{"id":"1.168209733","rc":[{"batb":[[1,2.42,522.59],[2,1.01,10.52]],"ltp":1.81,"tv":289.54,"id":8174357},{"batb":[[2,1.22,232.88]],"batl":[[0,1.4,300.93]],"ltp":1.31,"tv":1430.09,"id":7412952}]}]}
{"op":"mcm","clk":"1004795003","pt":1580637499620,"mc":[{"id":"1.168209733","rc":[{"batb":[[0,1.36,115.95],[1,1.22,232.88],[2,1.01,10.51]],"batl":[[0,1.45,42.01],[1,1.41,0],[2,1.45,0]],"ltp":1.31,"tv":1430.09,"id":7412952}]}]}
{"op":"mcm","clk":"1004795117","pt":1580637501625,"mc":[{"id":"1.168209733","rc":[{"batb":[[0,1.01,10.52],[1,2.42,0],[2,1.01,0]],"ltp":1.81,"tv":289.54,"id":8174357},{"batb":[[0,1.01,10.51],[1,1.22,0],[2,1.01,0]],"ltp":1.31,"tv":1430.09,"id":7412952}]}]}
{"op":"mcm","clk":"1004795324","pt":1580637505748,"mc":[{"id":"1.168209733","rc":[{"batb":[[0,1.31,176.29],[1,1.3,328.1],[2,1.01,10.51]],"batl":[[0,1.34,217.11],[1,1.35,262.16]],"ltp":1.31,"tv":1430.09,"id":7412952}]}]}
{"op":"mcm","clk":"1004795417","pt":1580637507857,"mc":[{"id":"1.168209733","rc":[{"batb":[[0,2.52,522.29],[1,1.01,10.52]],"ltp":1.81,"tv":289.54,"id":8174357},{"batb":[[2,1.2,228.55]],"ltp":1.31,"tv":1430.09,"id":7412952}]}]}
{"op":"mcm","clk":"1004795552","pt":1580637510849,"mc":[{"id":"1.168209733","rc":[{"batb":[[0,1.2,228.55],[1,1.01,10.51],[2,1.2,0]],"ltp":1.31,"tv":1430.09,"id":7412952}]}]}
{"op":"mcm","clk":"1004795635","pt":1580637512651,"mc":[{"id":"1.168209733","rc":[{"batb":[[0,1.01,10.52],[1,1.01,0]],"ltp":1.81,"tv":289.54,"id":8174357},{"batb":[[0,1.01,10.51],[1,1.01,0]],"ltp":1.31,"tv":1430.09,"id":7412952}]}]}
{"op":"mcm","clk":"1004795726","pt":1580637514459,"mc":[{"id":"1.168209733","rc":[{"batb":[[0,1.13,929.07],[1,1.12,206.95],[2,1.01,10.51]],"batl":[[0,1.57,154.4],[1,1.58,137.63]],"ltp":1.31,"tv":1430.09,"id":7412952}]}]}
{"op":"mcm","clk":"1004796245","pt":1580637523884,"mc":[{"id":"1.168209733","rc":[{"batl":[[0,1.16,790.08],[1,1.17,312.08]],"ltp":1.31,"tv":1430.09,"id":7412952}]}]}
{"op":"mcm","clk":"1004796324","pt":1580637524864,"mc":[{"id":"1.168209733","rc":[{"batb":[[0,6.2,7.56],[1,1.01,10.52]],"batl":[[0,7.8,5.88]],"ltp":1.81,"tv":289.54,"id":8174357},{"batl":[[2,1.19,42.01]],"ltp":1.31,"tv":1430.09,"id":7412952}]}]}
{"op":"mcm","clk":"1004796379","pt":1580637525946,"mc":[{"id":"1.168209733","rc":[{"batb":[[1,3.25,490.46],[2,1.01,10.52]],"ltp":1.81,"tv":289.54,"id":8174357},{"batb":[[2,1.08,422.91]],"ltp":1.31,"tv":1430.09,"id":7412952}]}]}
{"op":"mcm","clk":"1004796577","pt":1580637529192,"mc":[{"id":"1.168209733","rc":[{"batl":[[0,1.16,2205.3]],"ltp":1.31,"tv":1430.09,"id":7412952}]}]}
{"op":"mcm","clk":"1004797464","pt":1580637544825,"mc":[{"id":"1.168209733","rc":[{"trd":[[7.8,0.45]],"batl":[[0,7.8,5.44]],"ltp":7.8,"tv":289.98,"id":8174357},{"trd":[[1.14,3.03]],"ltp":1.14,"tv":1433.12,"id":7412952}],"tv":1723.11}]}
{"op":"mcm","clk":"1004798387","pt":1580637561748,"mc":[{"id":"1.168209733","rc":[{"batb":[[1,1.12,175.62]],"ltp":1.14,"tv":1433.12,"id":7412952}]}]}
{"op":"mcm","clk":"1004798558","pt":1580637564645,"mc":[{"id":"1.168209733","rc":[{"batb":[[0,1.13,960.12]],"ltp":1.14,"tv":1433.12,"id":7412952}]}]}
{"op":"mcm","clk":"1004798674","pt":1580637566351,"mc":[{"id":"1.168209733","rc":[{"batb":[[1,1.08,422.91],[2,1.01,10.51]],"batl":[[0,1.16,2169.78]],"ltp":1.14,"tv":1433.12,"id":7412952}]}]}
{"op":"mcm","clk":"1004798858","pt":1580637569119,"mc":[{"id":"1.168209733","rc":[{"batl":[[1,1.17,347.3]],"ltp":1.14,"tv":1433.12,"id":7412952}]}]}
{"op":"mcm","clk":"1004801728","pt":1580637610302,"mc":[{"id":"1.168209733","rc":[{"batb":[[0,1.08,422.91],[1,1.01,10.51],[2,1.01,0]],"batl":[[0,1.19,42.01],[1,1.17,0],[2,1.19,0]],"ltp":1.14,"tv":1433.12,"id":7412952}]}]}
{"op":"mcm","clk":"1004801807","pt":1580637611401,"mc":[{"id":"1.168209733","rc":[{"batb":[[0,3.25,490.46],[1,1.01,10.52],[2,1.01,0]],"ltp":7.8,"tv":289.98,"id":8174357}]}]}
{"op":"mcm","clk":"1004801953","pt":1580637613514,"mc":[{"id":"1.168209733","rc":[{"batb":[[0,1.1,366.27],[1,1.09,806.18],[2,1.08,422.91]],"batl":[[0,1.25,317.94],[1,1.26,373.4]],"ltp":1.14,"tv":1433.12,"id":7412952}]}]}
{"op":"mcm","clk":"1004802466","pt":1580637620948,"mc":[{"id":"1.168209733","rc":[{"batb":[[0,1.08,422.91],[1,1.01,10.51],[2,1.08,0]],"ltp":1.14,"tv":1433.12,"id":7412952}]}]}
{"op":"mcm","clk":"1004802620","pt":1580637622816,"mc":[{"id":"1.168209733","rc":[{"batb":[[0,1.01,10.51],[1,1.01,0]],"ltp":1.14,"tv":1433.12,"id":7412952}]}]}
{"op":"mcm","clk":"1004802674","pt":1580637623915,"mc":[{"id":"1.168209733","rc":[{"batb":[[0,1.15,586.33],[1,1.14,532.76],[2,1.01,10.51]],"batl":[[0,1.17,229.31],[1,1.18,574.04]],"ltp":1.14,"tv":1433.12,"id":7412952}]}]}
{"op":"mcm","clk":"1004802899","pt":1580637626923,"mc":[{"id":"1.168209733","rc":[{"batb":[[0,1.09,388.34],[1,1.01,10.51],[2,1.01,0]],"ltp":1.14,"tv":1433.12,"id":7412952}]}]}
{"op":"mcm","clk":"1004803090","pt":1580637629558,"mc":[{"id":"1.168209733","rc":[{"batb":[[0,1.1,366.27],[1,1.09,1194.52],[2,1.01,10.51]],"batl":[[0,1.25,317.94],[1,1.26,373.4]],"ltp":1.14,"tv":1433.12,"id":7412952}]}]}
{"op":"mcm","clk":"1004803567","pt":1580637636956,"mc":[{"id":"1.168209733","rc":[{"batb":[[1,1.09,806.18]],"ltp":1.14,"tv":1433.12,"id":7412952}]}]}
{"op":"mcm","clk":"1004803629","pt":1580637637837,"mc":[{"id":"1.168209733","rc":[{"batl":[[0,1.12,1040.6]],"ltp":1.14,"tv":1433.12,"id":7412952}]}]}
{"op":"mcm","clk":"1004803690","pt":1580637638769,"mc":[{"id":"1.168209733","rc":[{"batb":[[0,8,5.88],[1,3.25,490.46],[2,1.01,10.52]],"batl":[[0,10.5,4.2]],"ltp":7.8,"tv":289.98,"id":8174357},{"batl":[[1,1.14,42.01]],"ltp":1.14,"tv":1433.12,"id":7412952}]}]}
{"op":"mcm","clk":"1004803826","pt":1580637640838,"mc":[{"id":"1.168209733","rc":[{"batb":[[2,1.06,554.28]],"batl":[[0,1.12,2007.31]],"ltp":1.14,"tv":1433.12,"id":7412952}]}]}
{"op":"mcm","clk":"1004804917","pt":1580637655581,"mc":[{"id":"1.168209733","rc":[{"batb":[[0,3.25,490.46],[1,1.01,10.52],[2,1.01,0]],"ltp":7.8,"tv":289.98,"id":8174357},{"batb":[[0,1.06,554.28],[1,1.01,10.51],[2,1.06,0]],"ltp":1.14,"tv":1433.12,"id":7412952}]}]}
{"op":"mcm","clk":"1004805171","pt":1580637659320,"mc":[{"id":"1.168209733","rc":[{"batb":[[0,1.07,1197.79],[1,1.06,554.28],[2,1.01,10.51]],"batl":[[0,1.18,598.18],[1,1.19,483.85]],"ltp":1.14,"tv":1433.12,"id":7412952}]}]}
{"op":"mcm","clk":"1004805228","pt":1580637660205,"mc":[{"id":"1.168209733","rc":[{"batb":[[0,1.06,554.28],[1,1.01,10.51],[2,1.01,0]],"ltp":1.14,"tv":1433.12,"id":7412952}]}]}
{"op":"mcm","clk":"1004805308","pt":1580637661301,"mc":[{"id":"1.168209733","rc":[{"batb":[[0,1.01,10.52],[1,1.01,0]],"ltp":7.8,"tv":289.98,"id":8174357},{"batb":[[0,1.01,10.51],[1,1.01,0]],"ltp":1.14,"tv":1433.12,"id":7412952}]}]}
{"op":"mcm","clk":"1004805463","pt":1580637663221,"mc":[{"id":"1.168209733","rc":[{"batb":[[0,1.07,1197.79],[1,1.01,10.51]],"batl":[[0,1.09,996.4],[1,1.1,177.78]],"ltp":1.14,"tv":1433.12,"id":7412952}]}]}
{"op":"mcm","clk":"1004805553","pt":1580637664514,"mc":[{"id":"1.168209733","rc":[{"batb":[[0,10,4.2],[1,1.01,10.52]],"batl":[[0,13.5,3.36]],"ltp":7.8,"tv":289.98,"id":8174357},{"batb":[[0,1.08,168.04],[1,1.07,1197.79],[2,1.01,10.51]],"batl":[[2,1.11,42.01]],"ltp":1.14,"tv":1433.12,"id":7412952}]}]}
{"op":"mcm","clk":"1004805616","pt":1580637665459,"mc":[{"id":"1.168209733","rc":[{"batb":[[1,3.7,477.66],[2,1.01,10.52]],"ltp":7.8,"tv":289.98,"id":8174357},{"batb":[[2,1.04,827.94]],"ltp":1.14,"tv":1433.12,"id":7412952}]}]}
{"op":"mcm","clk":"1004806262","pt":1580637674641,"mc":[{"id":"1.168209733","rc":[{"batb":[[1,1.04,827.94],[2,1.01,10.51]],"batl":[[0,1.11,42.01],[1,1.1,0],[2,1.11,0]],"ltp":1.14,"tv":1433.12,"id":7412952}]}]}
{"op":"mcm","clk":"1004806343","pt":1580637675628,"mc":[{"id":"1.168209733","rc":[{"batb":[[0,3.7,477.66],[1,1.01,10.52],[2,1.01,0]],"ltp":7.8,"tv":289.98,"id":8174357},{"batb":[[0,1.04,827.94],[1,1.01,10.51],[2,1.01,0]],"ltp":1.14,"tv":1433.12,"id":7412952}]}]}
{"op":"mcm","clk":"1004806489","pt":1580637677501,"mc":[{"id":"1.168209733","rc":[{"batb":[[0,1.06,796.6],[1,1.05,416.42],[2,1.04,827.94]],"batl":[[0,1.12,473.37],[1,1.13,665]],"ltp":1.14,"tv":1433.12,"id":7412952}]}]}
{"op":"mcm","clk":"1004806824","pt":1580637682241,"mc":[{"id":"1.168209733","rc":[{"batb":[[0,1.04,827.94],[1,1.01,10.51],[2,1.04,0]],"ltp":1.14,"tv":1433.12,"id":7412952}]}]}
{"op":"mcm","clk":"1004806933","pt":1580637683747,"mc":[{"id":"1.168209733","rc":[{"batb":[[0,1.01,10.51],[1,1.01,0]],"ltp":1.14,"tv":1433.12,"id":7412952}]}]}
{"op":"mcm","clk":"1004807033","pt":1580637685147,"mc":[{"id":"1.168209733","rc":[{"batb":[[0,1.1,1035.49],[1,1.01,10.51]],"ltp":1.14,"tv":1433.12,"id":7412952}]}]}
{"op":"mcm","clk":"1004807144","pt":1580637686564,"mc":[{"id":"1.168209733","rc":[{"batb":[[0,7.8,5.88],[1,3.7,477.66],[2,1.01,10.52]],"batl":[[0,10,4.2]],"ltp":7.8,"tv":289.98,"id":8174357},{"batb":[[0,1.11,168.04],[1,1.1,1035.49],[2,1.01,10.51]],"ltp":1.14,"tv":1433.12,"id":7412952}]}]}
{"op":"mcm","clk":"1004807243","pt":1580637687750,"mc":[{"id":"1.168209733","rc":[{"batb":[[2,1.06,548.71]],"ltp":1.14,"tv":1433.12,"id":7412952}]}]}
{"op":"mcm","clk":"1004808150","pt":1580637700698,"mc":[{"id":"1.168209733","rc":[{"batb":[[1,1.06,548.71],[2,1.01,10.51]],"ltp":1.14,"tv":1433.12,"id":7412952}]}]}
{"op":"mcm","clk":"1004808224","pt":1580637701590,"mc":[{"id":"1.168209733","rc":[{"batb":[[0,3.7,477.66],[1,1.01,10.52],[2,1.01,0]],"ltp":7.8,"tv":289.98,"id":8174357},{"batb":[[0,1.06,548.71],[1,1.01,10.51],[2,1.01,0]],"ltp":1.14,"tv":1433.12,"id":7412952}]}]}
{"op":"mcm","clk":"1004808541","pt":1580637705070,"mc":[{"id":"1.168209733","rc":[{"batb":[[0,1.01,10.51],[1,1.01,0]],"ltp":1.14,"tv":1433.12,"id":7412952}]}]}
{"op":"mcm","clk":"1004808660","pt":1580637706363,"mc":[{"id":"1.168209733","rc":[{"batb":[[0,1.12,315.74],[1,1.11,836.04],[2,1.01,10.51]],"batl":[[0,1.14,783.54],[1,1.15,337.74]],"ltp":1.14,"tv":1433.12,"id":7412952}]}]}
{"op":"mcm","clk":"1004808878","pt":1580637709619,"mc":[{"id":"1.168209733","rc":[{"batb":[[0,1.07,484.06],[1,1.01,10.51],[2,1.01,0]],"ltp":1.14,"tv":1433.12,"id":7412952}]}]}
{"op":"mcm","clk":"1004809111","pt":1580637712587,"mc":[{"id":"1.168209733","rc":[{"batb":[[0,1.07,1499.86],[1,1.06,183.7],[2,1.01,10.51]],"batl":[[0,1.2,312.31],[1,1.21,479.02]],"ltp":1.14,"tv":1433.12,"id":7412952}]}]}
{"op":"mcm","clk":"1004809352","pt":1580637715712,"mc":[{"id":"1.168209733","rc":[{"batb":[[0,1.07,1015.8]],"ltp":1.14,"tv":1433.12,"id":7412952}]}]}
{"op":"mcm","clk":"1004809429","pt":1580637716537,"mc":[{"id":"1.168209733","rc":[{"batl":[[0,1.09,1175.82]],"ltp":1.14,"tv":1433.12,"id":7412952}]}]}
{"op":"mcm","clk":"1004809589","pt":1580637718712,"mc":[{"id":"1.168209733","rc":[{"batb":[[0,10.5,4.2],[1,3.7,477.66],[2,1.01,10.52]],"ltp":7.8,"tv":289.98,"id":8174357}]}]}
{"op":"mcm","clk":"1004809654","pt":1580637719596,"mc":[{"id":"1.168209733","rc":[{"batb":[[2,1.04,827.94]],"ltp":1.14,"tv":1433.12,"id":7412952}]}]}
{"op":"mcm","clk":"1004810293","pt":1580637726649,"mc":[{"id":"1.168209733","rc":[{"batb":[[1,1.04,827.94],[2,1.01,10.51]],"ltp":1.14,"tv":1433.12,"id":7412952}]}]}
{"op":"mcm","clk":"1004810659","pt":1580637729927,"mc":[{"id":"1.168209733","rc":[{"batl":[[0,1.09,2491.32]],"ltp":1.14,"tv":1433.12,"id":7412952}]}]}
{"op":"mcm","clk":"1004811600","pt":1580637740378,"mc":[{"id":"1.168209733","rc":[{"batb":[[0,1.04,827.94],[1,1.01,10.51],[2,1.01,0]],"ltp":1.14,"tv":1433.12,"id":7412952}]}]}
{"op":"mcm","clk":"1004811716","pt":1580637741586,"mc":[{"id":"1.168209733","rc":[{"batb":[[0,3.7,477.66],[1,1.01,10.52],[2,1.01,0]],"ltp":7.8,"tv":289.98,"id":8174357}]}]}
{"op":"mcm","clk":"1004811880","pt":1580637743570,"mc":[{"id":"1.168209733","rc":[{"batb":[[0,1.06,593.42],[1,1.05,621.53],[2,1.04,827.94]],"batl":[[0,1.12,806.75],[1,1.13,334.57]],"ltp":1.14,"tv":1433.12,"id":7412952}]}]}
{"op":"mcm","clk":"1004812056","pt":1580637745866,"mc":[{"id":"1.168209733","rc":[{"batb":[[0,1.04,827.94],[1,1.01,10.51],[2,1.04,0]],"ltp":1.14,"tv":1433.12,"id":7412952}]}]}
{"op":"mcm","clk":"1004812284","pt":1580637748858,"mc":[{"id":"1.168209733","rc":[{"batb":[[0,1.08,282.75],[1,1.07,912.39],[2,1.04,827.94]],"batl":[[0,1.09,459.78],[1,1.1,709.52]],"ltp":1.14,"tv":1433.12,"id":7412952}]}]}
{"op":"mcm","clk":"1004812333","pt":1580637749481,"mc":[{"id":"1.168209733","rc":[{"batb":[[0,1.04,827.94],[1,1.01,10.51],[2,1.04,0]],"ltp":1.14,"tv":1433.12,"id":7412952}]}]}
{"op":"mcm","clk":"1004812618","pt":1580637753173,"mc":[{"id":"1.168209733","rc":[{"batb":[[0,1.06,593.42],[1,1.05,621.53],[2,1.04,827.94]],"batl":[[0,1.12,806.75],[1,1.13,334.57]],"ltp":1.14,"tv":1433.12,"id":7412952}]}]}
{"op":"mcm","clk":"1004813168","pt":1580637760772,"mc":[{"id":"1.168209733","rc":[{"batb":[[2,1.01,10.51]],"ltp":1.14,"tv":1433.12,"id":7412952}]}]}
{"op":"mcm","clk":"1004813270","pt":1580637761919,"mc":[{"id":"1.168209733","rc":[{"batl":[[0,1.07,589.67],[1,1.08,600.5]],"ltp":1.14,"tv":1433.12,"id":7412952}]}]}
{"op":"mcm","clk":"1004813350","pt":1580637762914,"mc":[{"id":"1.168209733","rc":[{"batb":[[0,12.5,3.36],[1,3.7,477.66],[2,1.01,10.52]],"ltp":7.8,"tv":289.98,"id":8174357},{"batb":[[0,1.06,761.46]],"ltp":1.14,"tv":1433.12,"id":7412952}]}]}
{"op":"mcm","clk":"1004813492","pt":1580637764789,"mc":[{"id":"1.168209733","rc":[{"batb":[[2,1.03,1097.33]],"ltp":1.14,"tv":1433.12,"id":7412952}]}]}
{"op":"mcm","clk":"1004815348","pt":1580637791751,"mc":[{"id":"1.168209733","rc":[{"batb":[[0,1.06,168.04],[1,1.03,1097.33],[2,1.01,10.51]],"batl":[[0,1.08,600.5],[1,1.08,0]],"ltp":1.14,"tv":1433.12,"id":7412952}]}]}
{"op":"mcm","clk":"1004815489","pt":1580637793637,"mc":[{"id":"1.168209733","rc":[{"batb":[[0,3.7,477.66],[1,1.01,10.52],[2,1.01,0]],"ltp":7.8,"tv":289.98,"id":8174357},{"batb":[[0,1.03,1097.33],[1,1.01,10.51],[2,1.01,0]],"ltp":1.14,"tv":1433.12,"id":7412952}]}]}
{"op":"mcm","clk":"1004815562","pt":1580637794940,"mc":[{"id":"1.168209733","rc":[{"batb":[[0,1.04,1230.29],[1,1.03,1097.33],[2,1.01,10.51]],"batl":[[0,1.08,816.6],[1,1.09,364.74]],"ltp":1.14,"tv":1433.12,"id":7412952}]}]}
{"op":"mcm","clk":"1004816022","pt":1580637801885,"mc":[{"id":"1.168209733","rc":[{"batb":[[1,1.01,10.51],[2,1.01,0]],"ltp":1.14,"tv":1433.12,"id":7412952}]}]}
{"op":"mcm","clk":"1004816083","pt":1580637802869,"mc":[{"id":"1.168209733","rc":[{"batl":[[0,1.06,1207.07],[1,1.07,42.01]],"ltp":1.14,"tv":1433.12,"id":7412952}]}]}
{"op":"mcm","clk":"1004816269","pt":1580637805946,"mc":[{"id":"1.168209733","rc":[{"batb":[[1,1.01,3338.58]],"ltp":1.14,"tv":1433.12,"id":7412952}]}]}
{"op":"mcm","clk":"1004817079","pt":1580637816581,"mc":[{"id":"1.168209733","rc":[{"batb":[[0,1.01,3338.58],[1,1.01,0]],"batl":[[0,1.07,42.01],[1,1.07,0]],"ltp":1.14,"tv":1433.12,"id":7412952}]}]}
{"op":"mcm","clk":"1004817257","pt":1580637819023,"mc":[{"id":"1.168209733","rc":[{"batb":[[0,1.03,997.09],[1,1.02,247.54],[2,1.01,3338.58]],"batl":[[0,1.07,1059.97]],"ltp":1.14,"tv":1433.12,"id":7412952}]}]}
{"op":"mcm","clk":"1004817868","pt":1580637827740,"mc":[{"id":"1.168209733","rc":[{"batb":[[0,1.01,10.52],[1,1.01,0]],"ltp":7.8,"tv":289.98,"id":8174357},{"batb":[[2,1.01,10.51]],"ltp":1.14,"tv":1433.12,"id":7412952}]}]}
{"op":"mcm","clk":"1004817958","pt":1580637828943,"mc":[{"id":"1.168209733","rc":[{"batl":[[0,1.04,1230.29]],"ltp":1.14,"tv":1433.12,"id":7412952}]}]}
{"op":"mcm","clk":"1004818104","pt":1580637830917,"mc":[{"id":"1.168209733","rc":[{"batb":[[0,1.03,1165.13]],"ltp":1.14,"tv":1433.12,"id":7412952}]}]}
{"op":"mcm","clk":"1004818165","pt":1580637831700,"mc":[{"id":"1.168209733","rc":[{"batb":[[0,4.3,459.7],[1,1.01,10.52]],"batl":[[0,160,33.71]],"ltp":7.8,"tv":289.98,"id":8174357}]}]}
{"op":"mcm","clk":"1004818414","pt":1580637835528,"mc":[{"id":"1.168209733","rc":[{"trd":[[1.03,2330.26]],"batb":[[0,1.02,247.54],[1,1.01,10.51],[2,1.01,0]],"batl":[[0,1.03,431.24],[1,1.04,1230.29]],"ltp":1.03,"tv":3763.38,"id":7412952}],"tv":4053.37}]}
{"op":"mcm","clk":"1004818637","pt":1580637838851,"mc":[{"id":"1.168209733","rc":[{"trd":[[1.03,3192.74]],"batb":[[0,1.03,410.59],[1,1.02,616.43],[2,1.01,10.51]],"batl":[[0,1.04,1230.29],[1,1.04,0]],"ltp":1.03,"tv":4625.86,"id":7412952}],"tv":4915.85}]}
{"op":"mcm","clk":"1004818804","pt":1580637841857,"mc":[{"id":"1.168209733","rc":[{"batb":[[0,1.03,718.79],[1,1.02,698.25]],"ltp":1.03,"tv":4625.86,"id":7412952}]}]}
{"op":"mcm","clk":"1004819164","pt":1580637847775,"mc":[{"id":"1.168209733","rc":[{"batb":[[0,1.01,10.51],[1,1.02,0],[2,1.01,0]],"ltp":1.03,"tv":4625.86,"id":7412952}]}]}
{"op":"mcm","clk":"1004819223","pt":1580637848657,"mc":[{"id":"1.168209733","rc":[{"batb":[[0,1.01,10.52],[1,1.01,0]],"ltp":7.8,"tv":289.98,"id":8174357}]}]}
{"op":"mcm","clk":"1004819326","pt":1580637850361,"mc":[{"id":"1.168209733","rc":[{"batb":[[0,1.01,1277.34]],"batl":[[0,1.05,1218.57]],"ltp":1.03,"tv":4625.86,"id":7412952}]}]}
{"op":"mcm","clk":"1004819473","pt":1580637852630,"mc":[{"id":"1.168209733","rc":[{"batb":[[0,1.01,10.51]],"ltp":1.03,"tv":4625.86,"id":7412952}]}]}
{"op":"mcm","clk":"1004819622","pt":1580637855660,"mc":[{"id":"1.168209733","rc":[{"batb":[[0,1.04,780.59],[1,1.03,454.06],[2,1.01,10.51]],"ltp":1.03,"tv":4625.86,"id":7412952}]}]}
{"op":"mcm","clk":"1004819710","pt":1580637856955,"mc":[{"id":"1.168209733","rc":[{"batb":[[0,4.1,466.99],[1,1.01,10.52]],"ltp":7.8,"tv":289.98,"id":8174357},{"batb":[[0,1.04,948.63],[2,1.01,3356.76]],"ltp":1.03,"tv":4625.86,"id":7412952}]}]}
{"op":"mcm","clk":"1004820550","pt":1580637870825,"mc":[{"id":"1.168209733","rc":[{"batb":[[0,1.04,168.04],[1,1.01,3356.76],[2,1.01,0]],"ltp":1.03,"tv":4625.86,"id":7412952}]}]}
{"op":"mcm","clk":"1004820594","pt":1580637871806,"mc":[{"id":"1.168209733","rc":[{"batb":[[0,1.01,10.52],[1,1.01,0]],"ltp":7.8,"tv":289.98,"id":8174357},{"batb":[[1,1.01,10.51]],"ltp":1.03,"tv":4625.86,"id":7412952}]}]}
{"op":"mcm","clk":"1004820660","pt":1580637872905,"mc":[{"id":"1.168209733","rc":[{"batb":[[0,1.01,10.51],[1,1.01,0]],"ltp":1.03,"tv":4625.86,"id":7412952}]}]}
{"op":"mcm","clk":"1004820901","pt":1580637877122,"mc":[{"id":"1.168209733","rc":[{"batb":[[0,1.05,1218.57],[1,1.01,10.51]],"batl":[[0,1.06,335.92],[1,1.07,863.01]],"ltp":1.03,"tv":4625.86,"id":7412952}]}]}
{"op":"mcm","clk":"1004820987","pt":1580637878627,"mc":[{"id":"1.168209733","rc":[{"batb":[[0,1.05,1386.61]],"batl":[[1,1.07,905.02]],"ltp":1.03,"tv":4625.86,"id":7412952}]}]}
{"op":"mcm","clk":"1004821057","pt":1580637879617,"mc":[{"id":"1.168209733","rc":[{"batb":[[0,4,465.99],[1,1.01,10.52]],"ltp":7.8,"tv":289.98,"id":8174357},{"batb":[[1,1.02,1660.05],[2,1.01,10.51]],"ltp":1.03,"tv":4625.86,"id":7412952}]}]}
{"op":"mcm","clk":"1004821616","pt":1580637889719,"mc":[{"id":"1.168209733","rc":[{"batb":[[0,1.02,1660.05],[1,1.01,10.51],[2,1.01,0]],"ltp":1.03,"tv":4625.86,"id":7412952}]}]}
{"op":"mcm","clk":"1004821791","pt":1580637892829,"mc":[{"id":"1.168209733","rc":[{"batb":[[0,1.03,1242.23],[1,1.02,1660.05],[2,1.01,10.51]],"batl":[[0,1.08,1184.72]],"ltp":1.03,"tv":4625.86,"id":7412952}]}]}
{"op":"mcm","clk":"1004821966","pt":1580637895512,"mc":[{"id":"1.168209733","rc":[{"batb":[[0,1.02,1660.05],[1,1.01,10.51],[2,1.01,0]],"ltp":1.03,"tv":4625.86,"id":7412952}]}]}
{"op":"mcm","clk":"1004822084","pt":1580637897541,"mc":[{"id":"1.168209733","rc":[{"batb":[[0,1.01,10.51],[1,1.01,0]],"ltp":1.03,"tv":4625.86,"id":7412952}]}]}
{"op":"mcm","clk":"1004822182","pt":1580637898948,"mc":[{"id":"1.168209733","rc":[{"batb":[[0,12.5,3.36],[1,4,465.99],[2,1.01,10.52]],"ltp":7.8,"tv":289.98,"id":8174357},{"batb":[[0,1.06,1207.07],[1,1.01,10.51]],"ltp":1.03,"tv":4625.86,"id":7412952}]}]}
{"op":"mcm","clk":"1004822391","pt":1580637901662,"mc":[{"id":"1.168209733","rc":[{"batb":[[1,1.03,1097.33],[2,1.01,10.51]],"ltp":1.03,"tv":4625.86,"id":7412952}]}]}
{"op":"mcm","clk":"1004823353","pt":1580637914787,"mc":[{"id":"1.168209733","rc":[{"batb":[[0,1.03,1097.33],[1,1.01,10.51],[2,1.01,0]],"ltp":1.03,"tv":4625.86,"id":7412952}]}]}
{"op":"mcm","clk":"1004823424","pt":1580637915878,"mc":[{"id":"1.168209733","rc":[{"batb":[[0,4,465.99],[1,1.01,10.52],[2,1.01,0]],"ltp":7.8,"tv":289.98,"id":8174357}]}]}
{"op":"mcm","clk":"1004823546","pt":1580637917704,"mc":[{"id":"1.168209733","rc":[{"batb":[[0,1.05,1187.35],[1,1.03,1097.33],[2,1.01,10.51]],"batl":[[0,1.09,1173.85]],"ltp":1.03,"tv":4625.86,"id":7412952}]}]}
{"op":"mcm","clk":"1004823637","pt":1580637918900,"mc":[{"id":"1.168209733","rc":[{"batb":[[0,1.03,1097.33],[1,1.01,10.51],[2,1.01,0]],"ltp":1.03,"tv":4625.86,"id":7412952}]}]}
{"op":"mcm","clk":"1004823839","pt":1580637921910,"mc":[{"id":"1.168209733","rc":[{"batb":[[0,1.07,962.71],[1,1.06,235.36],[2,1.01,10.51]],"ltp":1.03,"tv":4625.86,"id":7412952}]}]}
{"op":"mcm","clk":"1004823893","pt":1580637922701,"mc":[{"id":"1.168209733","rc":[{"batb":[[0,11.5,3.36],[1,4,465.99],[2,1.01,10.52]],"ltp":7.8,"tv":289.98,"id":8174357},{"batb":[[0,1.07,1130.75]],"ltp":1.03,"tv":4625.86,"id":7412952}]}]}
{"op":"mcm","clk":"1004824107","pt":1580637925580,"mc":[{"id":"1.168209733","rc":[{"batb":[[2,1.04,827.94]],"ltp":1.03,"tv":4625.86,"id":7412952}]}]}
{"op":"mcm","clk":"1004824382","pt":1580637929801,"mc":[{"id":"1.168209733","rc":[{"batb":[[1,1.04,827.94],[2,1.01,10.51]],"ltp":1.03,"tv":4625.86,"id":7412952}]}]}
{"op":"mcm","clk":"1004824574","pt":1580637932721,"mc":[{"id":"1.168209733","rc":[{"batb":[[0,1.07,1316.09]],"ltp":1.03,"tv":4625.86,"id":7412952}]}]}
{"op":"mcm","clk":"1004824647","pt":1580637933802,"mc":[{"id":"1.168209733","rc":[{"batl":[[0,1.09,2492.24]],"ltp":1.03,"tv":4625.86,"id":7412952}]}]}
{"op":"mcm","clk":"1004824702","pt":1580637934688,"mc":[{"id":"1.168209733","rc":[{"batb":[[0,1.07,1161.61]],"ltp":1.03,"tv":4625.86,"id":7412952}]}]}
{"op":"mcm","clk":"1004824876","pt":1580637937614,"mc":[{"id":"1.168209733","rc":[{"batb":[[1,1.06,204.2],[2,1.04,827.94]],"ltp":1.03,"tv":4625.86,"id":7412952}]}]}
{"op":"mcm","clk":"1004829303","pt":1580638009821,"mc":[{"id":"1.168209733","rc":[{"batb":[[0,4,465.99],[1,1.01,10.52],[2,1.01,0]],"ltp":7.8,"tv":289.98,"id":8174357},{"batb":[[0,1.04,827.94],[1,1.01,10.51],[2,1.04,0]],"ltp":1.03,"tv":4625.86,"id":7412952}]}]}
{"op":"mcm","clk":"1004829426","pt":1580638011597,"mc":[{"id":"1.168209733","rc":[{"batb":[[0,1.01,10.52],[1,1.01,0]],"ltp":7.8,"tv":289.98,"id":8174357},{"batb":[[0,1.01,10.51],[1,1.01,0]],"ltp":1.03,"tv":4625.86,"id":7412952}]}]}
{"op":"mcm","clk":"1004829508","pt":1580638012900,"mc":[{"id":"1.168209733","rc":[{"batb":[[0,1.03,1242.31],[1,1.01,10.51]],"batl":[[0,1.18,599.43],[1,1.19,480.87]],"ltp":1.03,"tv":4625.86,"id":7412952}]}]}
{"op":"mcm","clk":"1004829973","pt":1580638020649,"mc":[{"id":"1.168209733","rc":[{"batl":[[0,1.05,1218.64]],"ltp":1.03,"tv":4625.86,"id":7412952}]}]}
{"op":"mcm","clk":"1004830051","pt":1580638021742,"mc":[{"id":"1.168209733","rc":[{"batb":[[0,4.2,467.18],[1,1.01,10.52]],"ltp":7.8,"tv":289.98,"id":8174357},{"batb":[[1,1.01,3352.11]],"ltp":1.03,"tv":4625.86,"id":7412952}]}]}
{"op":"mcm","clk":"1004830203","pt":1580638023929,"mc":[{"id":"1.168209733","rc":[{"batl":[[0,1.05,2468.74]],"ltp":1.03,"tv":4625.86,"id":7412952}]}]}
{"op":"mcm","clk":"1004830882","pt":1580638034760,"mc":[{"id":"1.168209733","rc":[{"batb":[[0,1.01,3352.11],[1,1.01,0]],"ltp":1.03,"tv":4625.86,"id":7412952}]}]}
{"op":"mcm","clk":"1004830974","pt":1580638035953,"mc":[{"id":"1.168209733","rc":[{"batb":[[0,1.01,10.52],[1,1.01,0]],"ltp":7.8,"tv":289.98,"id":8174357},{"batb":[[0,1.01,10.51]],"ltp":1.03,"tv":4625.86,"id":7412952}]}]}
{"op":"mcm","clk":"1004831210","pt":1580638039395,"mc":[{"id":"1.168209733","rc":[{"trd":[[1.03,3209.54]],"batb":[[0,1.04,1221.96],[1,1.01,10.51]],"batl":[[0,1.06,1207.15]],"ltp":1.03,"tv":4642.66,"id":7412952}],"tv":4932.65}]}
{"op":"mcm","clk":"1004831391","pt":1580638041591,"mc":[{"id":"1.168209733","rc":[{"batb":[[0,4.1,469.71],[1,1.01,10.52]],"ltp":7.8,"tv":289.98,"id":8174357},{"batb":[[1,1.01,3338.58]],"ltp":1.03,"tv":4642.66,"id":7412952}]}]}
{"op":"mcm","clk":"1004831514","pt":1580638043202,"mc":[{"id":"1.168209733","rc":[{"batb":[[0,1.01,3338.58],[1,1.01,0]],"ltp":1.03,"tv":4642.66,"id":7412952}]}]}
{"op":"mcm","clk":"1004831625","pt":1580638044656,"mc":[{"id":"1.168209733","rc":[{"batb":[[0,1.01,10.52],[1,1.01,0]],"ltp":7.8,"tv":289.98,"id":8174357},{"batb":[[0,1.01,10.51]],"ltp":1.03,"tv":4642.66,"id":7412952}]}]}
{"op":"mcm","clk":"1004831714","pt":1580638045900,"mc":[{"id":"1.168209733","rc":[{"batb":[[0,1.01,1277.42]],"batl":[[0,1.1,192.49],[1,1.11,962.01]],"ltp":1.03,"tv":4642.66,"id":7412952}]}]}
{"op":"mcm","clk":"1004832159","pt":1580638052675,"mc":[{"id":"1.168209733","rc":[{"batb":[[0,1.01,10.51]],"ltp":1.03,"tv":4642.66,"id":7412952}]}]}
{"op":"mcm","clk":"1004832359","pt":1580638055909,"mc":[{"id":"1.168209733","rc":[{"batb":[[0,1.09,462.14],[1,1.08,718.37],[2,1.01,10.51]],"ltp":1.03,"tv":4642.66,"id":7412952}]}]}
{"op":"mcm","clk":"1004832410","pt":1580638056686,"mc":[{"id":"1.168209733","rc":[{"batb":[[0,9.8,4.2],[1,1.01,10.52]],"batl":[[0,13,3.36]],"ltp":7.8,"tv":289.98,"id":8174357},{"batl":[[1,1.11,1004.02]],"ltp":1.03,"tv":4642.66,"id":7412952}]}]}
{"op":"mcm","clk":"1004832464","pt":1580638057420,"mc":[{"id":"1.168209733","rc":[{"batb":[[1,3.6,482.49],[2,1.01,10.52]],"ltp":7.8,"tv":289.98,"id":8174357},{"batb":[[2,1.05,655.17]],"ltp":1.03,"tv":4642.66,"id":7412952}]}]}
{"op":"mcm","clk":"1004833162","pt":1580638069734,"mc":[{"id":"1.168209733","rc":[{"batb":[[0,3.6,482.49],[1,1.01,10.52],[2,1.01,0]],"ltp":7.8,"tv":289.98,"id":8174357},{"batb":[[0,1.05,655.17],[1,1.01,10.51],[2,1.05,0]],"ltp":1.03,"tv":4642.66,"id":7412952}]}]}
{"op":"mcm","clk":"1004833304","pt":1580638071842,"mc":[{"id":"1.168209733","rc":[{"batb":[[0,1.01,10.52],[1,1.01,0]],"ltp":7.8,"tv":289.98,"id":8174357},{"batb":[[0,1.01,10.51],[1,1.01,0]],"ltp":1.03,"tv":4642.66,"id":7412952}]}]}
{"op":"mcm","clk":"1004833343","pt":1580638072214,"mc":[{"id":"1.168209733","rc":[{"batb":[[0,1.04,753.74],[1,1.03,481.24],[2,1.01,10.51]],"batl":[[0,1.24,547.26],[1,1.25,393.1]],"ltp":1.03,"tv":4642.66,"id":7412952}]}]}
{"op":"mcm","clk":"1004833896","pt":1580638079733,"mc":[{"id":"1.168209733","rc":[{"batl":[[0,1.05,1218.64]],"ltp":1.03,"tv":4642.66,"id":7412952}]}]}
{"op":"mcm","clk":"1004834037","pt":1580638081666,"mc":[{"id":"1.168209733","rc":[{"batb":[[0,4.1,472.53],[1,1.01,10.52]],"ltp":7.8,"tv":289.98,"id":8174357},{"batb":[[1,1.03,428.61],[2,1.01,3319.82]],"ltp":1.03,"tv":4642.66,"id":7412952}]}]}
{"op":"mcm","clk":"1004834246","pt":1580638084940,"mc":[{"id":"1.168209733","rc":[{"batb":[[0,1.04,805.87]],"ltp":1.03,"tv":4642.66,"id":7412952}]}]}
{"op":"mcm","clk":"1004834847","pt":1580638094469,"mc":[{"id":"1.168209733","rc":[{"batb":[[0,1.01,3319.82],[1,1.03,0],[2,1.01,0]],"ltp":1.03,"tv":4642.66,"id":7412952}]}]}
{"op":"mcm","clk":"1004834936","pt":1580638095774,"mc":[{"id":"1.168209733","rc":[{"batb":[[0,1.01,10.52],[1,1.01,0]],"ltp":7.8,"tv":289.98,"id":8174357},{"batb":[[0,1.01,10.51]],"ltp":1.03,"tv":4642.66,"id":7412952}]}]}
{"op":"mcm","clk":"1004835074","pt":1580638097849,"mc":[{"id":"1.168209733","rc":[{"batb":[[0,1.01,1277.42]],"ltp":1.03,"tv":4642.66,"id":7412952}]}]}
{"op":"mcm","clk":"1004835297","pt":1580638100869,"mc":[{"id":"1.168209733","rc":[{"batl":[[0,1.02,1254.49]],"ltp":1.03,"tv":4642.66,"id":7412952}]}]}
{"op":"mcm","clk":"1004835489","pt":1580638103891,"mc":[{"id":"1.168209733","rc":[{"batb":[[0,4.6,461.11],[1,1.01,10.52]],"ltp":7.8,"tv":289.98,"id":8174357}]}]}
{"op":"mcm","clk":"1004836125","pt":1580638113775,"mc":[{"id":"1.168209733","rc":[{"trd":[[1.01,218]],"batb":[[0,1.01,1168.42]],"ltp":1.01,"tv":4860.66,"id":7412952}],"tv":5150.65}]}
{"op":"mcm","clk":"1004836314","pt":1580638116895,"mc":[{"id":"1.168209733","rc":[{"batb":[[0,1.01,10.52],[1,1.01,0]],"ltp":7.8,"tv":289.98,"id":8174357}]}]}
{"op":"mcm","clk":"1004836354","pt":1580638117516,"mc":[{"id":"1.168209733","rc":[{"batl":[[0,1.04,557.49],[1,1.05,666.46]],"ltp":1.01,"tv":4860.66,"id":7412952}]}]}
{"op":"mcm","clk":"1004838132","pt":1580638143903,"mc":[{"id":"1.168209733","marketDefinition":{"bspMarket":false,"turnInPlayEnabled":true,"persistenceEnabled":true,"marketBaseRate":5.0,"eventId":"29681142","eventTypeId":"2","numberOfWinners":1,"bettingType":"ODDS","marketType":"SET_WINNER","marketTime":"2020-02-02T09:21:00.000Z","suspendTime":"2020-02-02T09:21:00.000Z","bspReconciled":false,"complete":true,"inPlay":true,"crossMatching":true,"runnersVoidable":false,"numberOfActiveRunners":2,"betDelay":3,"status":"SUSPENDED","runners":[{"status":"ACTIVE","sortPriority":1,"id":8174357,"name":"Blaz Rola"},{"status":"ACTIVE","sortPriority":2,"id":7412952,"name":"Roberto Marcora"}],"regulators":["MR_INT"],"countryCode":"IN","discountAllowed":true,"timezone":"UTC","openDate":"2020-02-02T09:21:00.000Z","version":3148388818,"name":"Set 1 Winner","eventName":"Rola v Marcora"}}]}
{"op":"mcm","clk":"1004840505","pt":1580638176888,"mc":[{"id":"1.168209733","tv":0.0}]}
{"op":"mcm","clk":"1004840606","pt":1580638178388,"mc":[{"id":"1.168209733","marketDefinition":{"bspMarket":false,"turnInPlayEnabled":true,"persistenceEnabled":true,"marketBaseRate":5.0,"eventId":"29681142","eventTypeId":"2","numberOfWinners":1,"bettingType":"ODDS","marketType":"SET_WINNER","marketTime":"2020-02-02T09:21:00.000Z","suspendTime":"2020-02-02T09:21:00.000Z","bspReconciled":false,"complete":true,"inPlay":true,"crossMatching":false,"runnersVoidable":false,"numberOfActiveRunners":0,"betDelay":3,"status":"CLOSED","settledTime":"2020-02-02T10:09:35.000Z","runners":[{"status":"LOSER","sortPriority":1,"id":8174357,"name":"Blaz Rola"},{"status":"WINNER","sortPriority":2,"id":7412952,"name":"Roberto Marcora"}],"regulators":["MR_INT"],"countryCode":"IN","discountAllowed":true,"timezone":"UTC","openDate":"2020-02-02T09:21:00.000Z","version":3148388874,"name":"Set 1 Winner","eventName":"Rola v Marcora"}}]}
