{"op":"mcm","clk":"1005167519","pt":1580641263376,"mc":[{"id":"1.168209734","rc":[{"batl":[[0,1.34,1680.39],[1,1.87,223.2],[2,1.89,196.44]],"ltp":1.37,"tv":894.15,"id":7412952}]}]}
{"op":"mcm","clk":"1005168153","pt":1580641266882,"mc":[{"id":"1.168209734","rc":[{"batl":[[1,3,2.27],[2,1.89,0]],"ltp":1.37,"tv":894.15,"id":7412952}]}]}
{"op":"mcm","clk":"1005168673","pt":1580641269949,"mc":[{"id":"1.168209734","rc":[{"batl":[[0,1.23,730.55],[1,1.24,530.93],[2,1.34,1680.39]],"ltp":1.37,"tv":894.15,"id":7412952}]}]}
{"op":"mcm","clk":"1005168836","pt":1580641270957,"mc":[{"id":"1.168209734","rc":[{"batl":[[0,6,8.4]],"ltp":3.7,"tv":783.98,"id":8174357},{"batb":[[0,1.2,688.28]],"ltp":1.37,"tv":894.15,"id":7412952}]}]}
{"op":"mcm","clk":"1005168941","pt":1580641271577,"mc":[{"id":"1.168209734","rc":[{"batb":[[0,5,10.08],[1,1.01,10.51]],"batl":[[1,8.6,166.38]],"ltp":3.7,"tv":783.98,"id":8174357},{"batl":[[2,1.25,42.01]],"ltp":1.37,"tv":894.15,"id":7412952}]}]}
{"op":"mcm","clk":"1005169602","pt":1580641275285,"mc":[{"id":"1.168209734","rc":[{"trd":[[5.3,1.77]],"ltp":5.3,"tv":785.75,"id":8174357},{"trd":[[1.23,7.62]],"batl":[[0,1.23,722.93]],"ltp":1.23,"tv":901.77,"id":7412952}],"tv":1687.53}]}
{"op":"mcm","clk":"1005170253","pt":1580641279192,"mc":[{"id":"1.168209734","rc":[{"batb":[[0,1.2,509.98]],"batl":[[0,1.23,579.83],[1,1.25,42.01],[2,1.34,1680.39]],"ltp":1.23,"tv":901.77,"id":7412952}]}]}
{"op":"mcm","clk":"1005170844","pt":1580641282507,"mc":[{"id":"1.168209734","rc":[{"batl":[[0,1.22,336.18],[1,1.23,579.83],[2,1.25,42.01]],"ltp":1.23,"tv":901.77,"id":7412952}]}]}
{"op":"mcm","clk":"1005172362","pt":1580641291380,"mc":[{"id":"1.168209734","rc":[{"batl":[[0,1.22,2016.57]],"ltp":1.23,"tv":901.77,"id":7412952}]}]}
{"op":"mcm","clk":"1005175219","pt":1580641306633,"mc":[{"id":"1.168209734","rc":[{"batb":[[0,1.2,168.04],[1,1.01,10.51],[2,1.01,0]],"batl":[[0,1.22,1680.39],[1,1.25,42.01],[2,1.53,332.86]],"ltp":1.23,"tv":901.77,"id":7412952}]}]}
{"op":"mcm","clk":"1005175754","pt":1580641309644,"mc":[{"id":"1.168209734","rc":[{"batb":[[1,1.1,858.99],[2,1.09,561.51]],"ltp":1.23,"tv":901.77,"id":7412952}]}]}
{"op":"mcm","clk":"1005176342","pt":1580641312921,"mc":[{"id":"1.168209734","rc":[{"batl":[[0,1.25,42.01],[1,1.53,332.86],[2,1.55,294.45]],"ltp":1.23,"tv":901.77,"id":7412952}]}]}
{"op":"mcm","clk":"1005176947","pt":1580641316371,"mc":[{"id":"1.168209734","rc":[{"batb":[[0,5.1,226.44],[1,5,10.08],[2,1.01,10.51]],"ltp":5.3,"tv":785.75,"id":8174357}]}]}
{"op":"mcm","clk":"1005177450","pt":1580641318837,"mc":[{"id":"1.168209734","rc":[{"batb":[[0,5,10.08],[1,1.01,10.51],[2,1.01,0]],"ltp":5.3,"tv":785.75,"id":8174357}]}]}
{"op":"mcm","clk":"1005177624","pt":1580641319735,"mc":[{"id":"1.168209734","rc":[{"batb":[[0,1.01,10.51],[1,1.01,0]],"batl":[[0,8.6,166.38],[1,8.6,0]],"ltp":5.3,"tv":785.75,"id":8174357},{"batb":[[0,1.1,858.99],[1,1.09,561.51],[2,1.01,10.51]],"batl":[[0,1.53,332.86],[1,1.55,294.45],[2,1.56,188.4]],"ltp":1.23,"tv":901.77,"id":7412952}]}]}
{"op":"mcm","clk":"1005177717","pt":1580641320220,"mc":[{"id":"1.168209734","rc":[{"batl":[[0,1.55,294.45],[1,1.56,188.4],[2,3,2.27]],"ltp":1.23,"tv":901.77,"id":7412952}]}]}
{"op":"mcm","clk":"1005178193","pt":1580641322841,"mc":[{"id":"1.168209734","rc":[{"batb":[[0,1.01,10.51],[1,1.09,0],[2,1.01,0]],"batl":[[0,3,2.27],[1,1.56,0],[2,3,0]],"ltp":1.23,"tv":901.77,"id":7412952}]}]}
{"op":"mcm","clk":"1005178767","pt":1580641325867,"mc":[{"id":"1.168209734","rc":[{"batb":[[0,1.25,271.38],[1,1.24,572.5],[2,1.01,10.51]],"batl":[[0,1.28,598.08],[1,1.29,433.55],[2,3,2.27]],"ltp":1.23,"tv":901.77,"id":7412952}]}]}
{"op":"mcm","clk":"1005179043","pt":1580641327366,"mc":[{"id":"1.168209734","rc":[{"batl":[[0,6.6,212.64]],"ltp":5.3,"tv":785.75,"id":8174357},{"batl":[[2,1.62,267.64]],"ltp":1.23,"tv":901.77,"id":7412952}]}]}
{"op":"mcm","clk":"1005179273","pt":1580641328661,"mc":[{"id":"1.168209734","rc":[{"batb":[[0,1.01,10.51],[1,1.24,0],[2,1.01,0]],"batl":[[0,1.62,267.64],[1,3,2.27],[2,1.62,0]],"ltp":1.23,"tv":901.77,"id":7412952}]}]}
{"op":"mcm","clk":"1005179593","pt":1580641330375,"mc":[{"id":"1.168209734","rc":[{"batl":[[0,3,2.27],[1,3,0]],"ltp":1.23,"tv":901.77,"id":7412952}]}]}
{"op":"mcm","clk":"1005179811","pt":1580641331635,"mc":[{"id":"1.168209734","rc":[{"batb":[[0,1.1,858.99],[1,1.09,561.51],[2,1.01,10.51]],"batl":[[0,1.55,294.45],[1,1.56,188.4],[2,3,2.27]],"ltp":1.23,"tv":901.77,"id":7412952}]}]}
{"op":"mcm","clk":"1005180955","pt":1580641337969,"mc":[{"id":"1.168209734","rc":[{"batb":[[0,1.01,10.51],[1,1.09,0],[2,1.01,0]],"ltp":1.23,"tv":901.77,"id":7412952}]}]}
{"op":"mcm","clk":"1005181476","pt":1580641340944,"mc":[{"id":"1.168209734","rc":[{"batb":[[0,1.5,230.44],[1,1.49,229.04],[2,1.01,10.51]],"ltp":1.23,"tv":901.77,"id":7412952}]}]}
{"op":"mcm","clk":"1005181654","pt":1580641341951,"mc":[{"id":"1.168209734","rc":[{"batb":[[1,1.49,234.68]],"ltp":1.23,"tv":901.77,"id":7412952}]}]}
{"op":"mcm","clk":"1005181820","pt":1580641342762,"mc":[{"id":"1.168209734","rc":[{"batb":[[0,2.72,24.37],[1,1.01,10.51]],"batl":[[0,3.05,20.16]],"ltp":5.3,"tv":785.75,"id":8174357},{"batb":[[1,1.49,229.04],[2,1.48,87.38]],"batl":[[2,1.57,42.01]],"ltp":1.23,"tv":901.77,"id":7412952}]}]}
{"op":"mcm","clk":"1005181942","pt":1580641343456,"mc":[{"id":"1.168209734","rc":[{"batl":[[1,3.9,361.34]],"ltp":5.3,"tv":785.75,"id":8174357}]}]}
{"op":"mcm","clk":"1005183263","pt":1580641350867,"mc":[{"id":"1.168209734","rc":[{"trd":[[1.5,12.65]],"batb":[[0,1.5,224.15]],"ltp":1.5,"tv":914.35,"id":7412952}],"tv":1700.1}]}
{"op":"mcm","clk":"1005183426","pt":1580641351767,"mc":[{"id":"1.168209734","rc":[{"batl":[[0,1.55,243.95]],"ltp":1.5,"tv":914.35,"id":7412952}]}]}
{"op":"mcm","clk":"1005183997","pt":1580641354688,"mc":[{"id":"1.168209734","rc":[{"batb":[[0,1.5,282.79]],"ltp":1.5,"tv":914.35,"id":7412952}]}]}
{"op":"mcm","clk":"1005186235","pt":1580641367067,"mc":[{"id":"1.168209734","rc":[{"batb":[[2,1.01,10.51]],"ltp":1.5,"tv":914.35,"id":7412952}]}]}
{"op":"mcm","clk":"1005186691","pt":1580641369385,"mc":[{"id":"1.168209734","rc":[{"batl":[[0,3.05,22.92]],"ltp":5.3,"tv":785.75,"id":8174357}]}]}
{"op":"mcm","clk":"1005186965","pt":1580641370816,"mc":[{"id":"1.168209734","rc":[{"batl":[[0,3.05,20.16]],"ltp":5.3,"tv":785.75,"id":8174357},{"batb":[[0,1.49,85.7],[1,1.01,10.51],[2,1.01,0]],"batl":[[0,1.57,42.01],[1,1.95,145.34],[2,3,2.27]],"ltp":1.5,"tv":914.35,"id":7412952}]}]}
{"op":"mcm","clk":"1005187170","pt":1580641371777,"mc":[{"id":"1.168209734","rc":[{"batb":[[0,1.01,10.51],[1,1.01,0]],"batl":[[0,3.9,361.34],[1,3.9,0]],"ltp":5.3,"tv":785.75,"id":8174357},{"batb":[[0,1.01,10.51],[1,1.01,0]],"batl":[[0,1.95,145.34],[1,3,2.27],[2,3,0]],"ltp":1.5,"tv":914.35,"id":7412952}]}]}
{"op":"mcm","clk":"1005187606","pt":1580641373802,"mc":[{"id":"1.168209734","rc":[{"batb":[[0,1.16,321.13],[1,1.15,995.19],[2,1.01,10.51]],"batl":[[0,1.87,144.66],[1,1.89,197.33],[2,1.95,145.34]],"ltp":1.5,"tv":914.35,"id":7412952}]}]}
{"op":"mcm","clk":"1005187638","pt":1580641374013,"mc":[{"id":"1.168209734","rc":[{"batl":[[2,3,2.27]],"ltp":1.5,"tv":914.35,"id":7412952}]}]}
{"op":"mcm","clk":"1005189313","pt":1580641382582,"mc":[{"id":"1.168209734","rc":[{"batb":[[0,1.01,10.51],[1,1.15,0],[2,1.01,0]],"ltp":1.5,"tv":914.35,"id":7412952}]}]}
{"op":"mcm","clk":"1005189892","pt":1580641385808,"mc":[{"id":"1.168209734","rc":[{"batb":[[0,1.8,184.8],[1,1.78,235.59],[2,1.01,10.51]],"ltp":1.5,"tv":914.35,"id":7412952}]}]}
{"op":"mcm","clk":"1005190049","pt":1580641386707,"mc":[{"id":"1.168209734","rc":[{"batb":[[0,2.08,38.65],[1,1.01,10.51]],"batl":[[0,2.3,31.93]],"ltp":5.3,"tv":785.75,"id":8174357},{"batb":[[2,1.77,53.77]],"batl":[[2,1.91,42.01]],"ltp":1.5,"tv":914.35,"id":7412952}]}]}
{"op":"mcm","clk":"1005190158","pt":1580641387302,"mc":[{"id":"1.168209734","rc":[{"batl":[[1,2.82,527.84]],"ltp":5.3,"tv":785.75,"id":8174357}]}]}
{"op":"mcm","clk":"1005191934","pt":1580641395714,"mc":[{"id":"1.168209734","rc":[{"batl":[[0,1.91,42.01],[1,2.42,91.83],[2,3,2.27]],"ltp":1.5,"tv":914.35,"id":7412952}]}]}
{"op":"mcm","clk":"1005192571","pt":1580641398742,"mc":[{"id":"1.168209734","rc":[{"batb":[[0,1.8,208.18]],"batl":[[0,1.88,221.36],[1,1.9,194],[2,1.91,42.01]],"ltp":1.5,"tv":914.35,"id":7412952}]}]}
{"op":"mcm","clk":"1005194104","pt":1580641406632,"mc":[{"id":"1.168209734","rc":[{"batb":[[0,1.77,53.77],[1,1.01,10.51],[2,1.77,0]],"batl":[[0,1.91,42.01],[1,2.42,91.83],[2,3,2.27]],"ltp":1.5,"tv":914.35,"id":7412952}]}]}
{"op":"mcm","clk":"1005194347","pt":1580641407844,"mc":[{"id":"1.168209734","rc":[{"batb":[[0,1.01,10.51],[1,1.01,0]],"batl":[[0,2.82,527.84],[1,2.82,0]],"ltp":5.3,"tv":785.75,"id":8174357},{"batb":[[0,1.01,10.51],[1,1.01,0]],"batl":[[0,2.42,91.83],[1,3,2.27],[2,3,0]],"ltp":1.5,"tv":914.35,"id":7412952}]}]}
{"op":"mcm","clk":"1005194509","pt":1580641408637,"mc":[{"id":"1.168209734","rc":[{"batl":[[0,3,2.27],[1,3,0]],"ltp":1.5,"tv":914.35,"id":7412952}]}]}
{"op":"mcm","clk":"1005194665","pt":1580641409330,"mc":[{"id":"1.168209734","rc":[{"batb":[[0,1.25,347.92],[1,1.24,572.64],[2,1.01,10.51]],"batl":[[0,2.5,96.35],[1,2.54,171.11],[2,3,2.27]],"ltp":1.5,"tv":914.35,"id":7412952}]}]}
{"op":"mcm","clk":"1005195664","pt":1580641413634,"mc":[{"id":"1.168209734","rc":[{"batl":[[0,3,2.27],[1,2.54,0],[2,3,0]],"ltp":1.5,"tv":914.35,"id":7412952}]}]}
{"op":"mcm","clk":"1005196321","pt":1580641416845,"mc":[{"id":"1.168209734","rc":[{"batl":[[0,1.28,523.64],[1,1.29,433.59],[2,3,2.27]],"ltp":1.5,"tv":914.35,"id":7412952}]}]}
{"op":"mcm","clk":"1005196499","pt":1580641417764,"mc":[{"id":"1.168209734","rc":[{"batb":[[0,4.4,11.76],[1,1.01,10.51]],"batl":[[0,5.1,10.08]],"ltp":5.3,"tv":785.75,"id":8174357},{"batb":[[1,1.24,740.68]],"batl":[[2,1.3,42.01]],"ltp":1.5,"tv":914.35,"id":7412952}]}]}
{"op":"mcm","clk":"1005196692","pt":1580641418749,"mc":[{"id":"1.168209734","rc":[{"batl":[[1,7.2,194.01]],"ltp":5.3,"tv":785.75,"id":8174357}]}]}
{"op":"mcm","clk":"1005197520","pt":1580641422877,"mc":[{"id":"1.168209734","rc":[{"batb":[[0,1.25,305.83]],"ltp":1.5,"tv":914.35,"id":7412952}]}]}
{"op":"mcm","clk":"1005198018","pt":1580641425193,"mc":[{"id":"1.168209734","rc":[{"batl":[[0,1.28,564.77]],"ltp":1.5,"tv":914.35,"id":7412952}]}]}
{"op":"mcm","clk":"1005199948","pt":1580641434466,"mc":[{"id":"1.168209734","rc":[{"trd":[[1.25,611.66]],"batb":[[0,1.24,740.68],[1,1.01,10.51],[2,1.01,0]],"batl":[[0,1.25,1374.56],[1,1.28,461.93]],"ltp":1.25,"tv":1526.01,"id":7412952}],"tv":2311.77}]}
{"op":"mcm","clk":"1005200611","pt":1580641437590,"mc":[{"id":"1.168209734","rc":[{"trd":[[1.25,705.76]],"batb":[[0,1.24,907.29],[1,1.23,520.54],[2,1.01,10.51]],"batl":[[0,1.25,1327.51],[1,1.27,242.16],[2,1.28,461.93]],"ltp":1.25,"tv":1620.11,"id":7412952}],"tv":2405.87}]}
{"op":"mcm","clk":"1005200899","pt":1580641438871,"mc":[{"id":"1.168209734","rc":[{"batb":[[0,1.24,168.04],[1,1.01,10.51],[2,1.01,0]],"batl":[[1,1.3,42.01],[2,1.58,288.94]],"ltp":1.25,"tv":1620.11,"id":7412952}]}]}
{"op":"mcm","clk":"1005201062","pt":1580641439770,"mc":[{"id":"1.168209734","rc":[{"batb":[[0,1.01,10.51],[1,1.01,0]],"batl":[[0,7.2,194.01],[1,7.2,0]],"ltp":5.3,"tv":785.75,"id":8174357},{"batb":[[0,1.01,10.51],[1,1.01,0]],"batl":[[1,1.58,288.94],[2,3,2.27]],"ltp":1.25,"tv":1620.11,"id":7412952}]}]}
{"op":"mcm","clk":"1005201393","pt":1580641441670,"mc":[{"id":"1.168209734","rc":[{"batb":[[0,1.09,1399.59],[1,1.01,10.51]],"batl":[[2,1.88,217.96]],"ltp":1.25,"tv":1620.11,"id":7412952}]}]}
{"op":"mcm","clk":"1005201552","pt":1580641442516,"mc":[{"id":"1.168209734","rc":[{"batl":[[1,1.88,217.96],[2,1.9,194.89]],"ltp":1.25,"tv":1620.11,"id":7412952}]}]}
{"op":"mcm","clk":"1005202900","pt":1580641449500,"mc":[{"id":"1.168209734","rc":[{"batl":[[1,3,2.27],[2,1.9,0]],"ltp":1.25,"tv":1620.11,"id":7412952}]}]}
{"op":"mcm","clk":"1005203571","pt":1580641452783,"mc":[{"id":"1.168209734","rc":[{"batb":[[0,9.2,5.04],[1,1.01,10.51]],"batl":[[0,12,3.36]],"ltp":5.3,"tv":785.75,"id":8174357},{"batb":[[0,1.09,1567.63]],"batl":[[0,1.11,1015.68],[1,1.12,425.52],[2,1.25,1327.51]],"ltp":1.25,"tv":1620.11,"id":7412952}]}]}
{"op":"mcm","clk":"1005204002","pt":1580641454693,"mc":[{"id":"1.168209734","rc":[{"batl":[[1,21,87.92]],"ltp":5.3,"tv":785.75,"id":8174357}]}]}
{"op":"mcm","clk":"1005206306","pt":1580641465816,"mc":[{"id":"1.168209734","rc":[{"batb":[[0,1.01,10.51],[1,1.01,0]],"batl":[[0,21,87.92],[1,21,0]],"ltp":5.3,"tv":785.75,"id":8174357},{"batb":[[0,1.01,10.51],[1,1.01,0]],"batl":[[0,1.25,1327.51],[1,1.38,529.21],[2,3,2.27]],"ltp":1.25,"tv":1620.11,"id":7412952}]}]}
{"op":"mcm","clk":"1005206778","pt":1580641467953,"mc":[{"id":"1.168209734","rc":[{"batl":[[0,1.09,44],[1,1.25,1327.51]],"ltp":1.25,"tv":1620.11,"id":7412952}]}]}
{"op":"mcm","clk":"1005207121","pt":1580641469602,"mc":[{"id":"1.168209734","rc":[{"batl":[[0,1.25,1327.51],[1,3,2.27],[2,3,0]],"ltp":1.25,"tv":1620.11,"id":7412952}]}]}
{"op":"mcm","clk":"1005207393","pt":1580641470817,"mc":[{"id":"1.168209734","rc":[{"batb":[[0,1.14,755.15],[1,1.13,615.98],[2,1.01,10.51]],"batl":[[0,1.16,544.69],[1,1.17,790.68],[2,1.25,1327.51]],"ltp":1.25,"tv":1620.11,"id":7412952}]}]}
{"op":"mcm","clk":"1005207649","pt":1580641471939,"mc":[{"id":"1.168209734","rc":[{"batb":[[1,1.13,578.65]],"batl":[[0,1.16,508.43]],"ltp":1.25,"tv":1620.11,"id":7412952}]}]}
{"op":"mcm","clk":"1005207789","pt":1580641472622,"mc":[{"id":"1.168209734","rc":[{"batl":[[0,12.5,122.44]],"ltp":5.3,"tv":785.75,"id":8174357}]}]}
{"op":"mcm","clk":"1005207931","pt":1580641473315,"mc":[{"id":"1.168209734","rc":[{"batb":[[0,1.01,10.51],[1,1.13,0],[2,1.01,0]],"batl":[[0,1.25,1327.51],[1,1.45,422.19],[2,3,2.27]],"ltp":1.25,"tv":1620.11,"id":7412952}]}]}
{"op":"mcm","clk":"1005208449","pt":1580641475803,"mc":[{"id":"1.168209734","rc":[{"batl":[[1,3,2.27],[2,3,0]],"ltp":1.25,"tv":1620.11,"id":7412952}]}]}
{"op":"mcm","clk":"1005208534","pt":1580641476226,"mc":[{"id":"1.168209734","rc":[{"batl":[[1,1.43,183.26],[2,1.44,261.58]],"ltp":1.25,"tv":1620.11,"id":7412952}]}]}
{"op":"mcm","clk":"1005209214","pt":1580641479550,"mc":[{"id":"1.168209734","rc":[{"batl":[[1,3,2.27],[2,1.44,0]],"ltp":1.25,"tv":1620.11,"id":7412952}]}]}
{"op":"mcm","clk":"1005209354","pt":1580641480326,"mc":[{"id":"1.168209734","marketDefinition":{"bspMarket":false,"turnInPlayEnabled":true,"persistenceEnabled":true,"marketBaseRate":5.0,"eventId":"29681142","eventTypeId":"2","numberOfWinners":1,"bettingType":"ODDS","marketType":"SET_WINNER","marketTime":"2020-02-02T09:21:00.000Z","suspendTime":"2020-02-02T09:21:00.000Z","bspReconciled":false,"complete":true,"inPlay":true,"crossMatching":true,"runnersVoidable":false,"numberOfActiveRunners":2,"betDelay":3,"status":"SUSPENDED","runners":[{"status":"ACTIVE","sortPriority":1,"id":8174357,"name":"Blaz Rola"},{"status":"ACTIVE","sortPriority":2,"id":7412952,"name":"Roberto Marcora"}],"regulators":["MR_INT"],"countryCode":"IN","discountAllowed":true,"timezone":"UTC","openDate":"2020-02-02T09:21:00.000Z","version":3148495620,"name":"Set 2 Winner","eventName":"Rola v Marcora"}}]}
{"op":"mcm","clk":"1005210620","pt":1580641487328,"mc":[{"id":"1.168209734","rc":[{"batl":[[0,3,2.27],[1,3,0]],"ltp":1.25,"tv":1620.11,"id":7412952}]}]}
{"op":"mcm","clk":"1005216060","pt":1580641515182,"mc":[{"id":"1.168209734","tv":0.0}]}
{"op":"mcm","clk":"1005216382","pt":1580641516498,"mc":[{"id":"1.168209734","marketDefinition":{"bspMarket":false,"turnInPlayEnabled":true,"persistenceEnabled":true,"marketBaseRate":5.0,"eventId":"29681142","eventTypeId":"2","numberOfWinners":1,"bettingType":"ODDS","marketType":"SET_WINNER","marketTime":"2020-02-02T09:21:00.000Z","suspendTime":"2020-02-02T09:21:00.000Z","bspReconciled":false,"complete":true,"inPlay":true,"crossMatching":false,"runnersVoidable":false,"numberOfActiveRunners":0,"betDelay":3,"status":"CLOSED","settledTime":"2020-02-02T11:05:13.000Z","runners":[{"status":"LOSER","sortPriority":1,"id":8174357,"name":"Blaz Rola"},{"status":"WINNER","sortPriority":2,"id":7412952,"name":"Roberto Marcora"}],"regulators":["MR_INT"],"countryCode":"IN","discountAllowed":true,"timezone":"UTC","openDate":"2020-02-02T09:21:00.000Z","version":3148495915,"name":"Set 2 Winner","eventName":"Rola v Marcora"}}]}
