{"op":"mcm","clk":"1004130614","pt":1580620978791,"mc":[{"id":"1.168209731","rc":[{"batl":[[0,1.96,7.82]],"ltp":1.94,"tv":1925.94,"id":8174357},{"batb":[[0,2.04,6.32]],"ltp":2.04,"tv":1185.0,"id":7412952}]}]}
{"op":"mcm","clk":"1004130738","pt":1580620980762,"mc":[{"id":"1.168209731","rc":[{"batl":[[0,1.96,2.5]],"ltp":1.94,"tv":1925.94,"id":8174357},{"batb":[[0,2.02,39.86],[1,2,10],[2,1.81,330.47]],"batl":[[0,2.06,48.78]],"ltp":2.04,"tv":1185.0,"id":7412952}]}]}
{"op":"mcm","clk":"1004130800","pt":1580620981785,"mc":[{"id":"1.168209731","rc":[{"batl":[[0,1.96,7.5]],"ltp":1.94,"tv":1925.94,"id":8174357},{"batb":[[0,2.04,6],[1,2.02,39.86],[2,2,10]],"batl":[[0,2.06,42.78]],"ltp":2.04,"tv":1185.0,"id":7412952}]}]}
{"op":"mcm","clk":"1004130854","pt":1580620982865,"mc":[{"id":"1.168209731","rc":[{"batl":[[0,1.96,7.51]],"ltp":1.94,"tv":1925.94,"id":8174357},{"batb":[[0,2.04,6.01]],"batl":[[0,2.06,48.78]],"ltp":2.04,"tv":1185.0,"id":7412952}]}]}
{"op":"mcm","clk":"1004130909","pt":1580620983953,"mc":[{"id":"1.168209731","rc":[{"batl":[[0,1.96,7.52]],"ltp":1.94,"tv":1925.94,"id":8174357},{"batb":[[0,2.04,6.02]],"batl":[[0,2.06,42.78]],"ltp":2.04,"tv":1185.0,"id":7412952}]}]}
{"op":"mcm","clk":"1004130943","pt":1580620984777,"mc":[{"id":"1.168209731","rc":[{"batl":[[0,1.96,12.54],[1,2,68.06],[2,2.3,10.13]],"ltp":1.94,"tv":1925.94,"id":8174357},{"batb":[[0,2.04,12.04]],"ltp":2.04,"tv":1185.0,"id":7412952}]}]}
{"op":"mcm","clk":"1004131016","pt":1580620985861,"mc":[{"id":"1.168209731","rc":[{"batl":[[0,1.96,2.5],[1,1.97,5],[2,2,68.06]],"ltp":1.94,"tv":1925.94,"id":8174357},{"batb":[[0,2.02,39.86],[1,2,10],[2,1.81,330.47]],"batl":[[0,2.06,48.78]],"ltp":2.04,"tv":1185.0,"id":7412952}]}]}
{"op":"mcm","clk":"1004131058","pt":1580620986887,"mc":[{"id":"1.168209731","rc":[{"batl":[[0,2.06,54.78]],"ltp":2.04,"tv":1185.0,"id":7412952}]}]}
{"op":"mcm","clk":"1004131122","pt":1580620987867,"mc":[{"id":"1.168209731","rc":[{"batl":[[0,1.96,7.54]],"ltp":1.94,"tv":1925.94,"id":8174357},{"batb":[[0,2.04,6.04],[1,2.02,39.86],[2,2,10]],"batl":[[0,2.06,48.78]],"ltp":2.04,"tv":1185.0,"id":7412952}]}]}
{"op":"mcm","clk":"1004131166","pt":1580620988894,"mc":[{"id":"1.168209731","rc":[{"batl":[[0,2.06,42.78]],"ltp":2.04,"tv":1185.0,"id":7412952}]}]}
{"op":"mcm","clk":"1004131212","pt":1580620989771,"mc":[{"id":"1.168209731","rc":[{"batl":[[0,1.96,7.55]],"ltp":1.94,"tv":1925.94,"id":8174357},{"batb":[[0,2.04,6.05]],"ltp":2.04,"tv":1185.0,"id":7412952}]}]}
{"op":"mcm","clk":"1004131282","pt":1580620990901,"mc":[{"id":"1.168209731","rc":[{"batl":[[0,1.96,2.5]],"ltp":1.94,"tv":1925.94,"id":8174357},{"batb":[[0,2.02,39.86],[1,2,10],[2,1.81,330.47]],"batl":[[0,2.06,48.78]],"ltp":2.04,"tv":1185.0,"id":7412952}]}]}
{"op":"mcm","clk":"1004131384","pt":1580620992767,"mc":[{"id":"1.168209731","rc":[{"batl":[[0,1.96,7.56]],"ltp":1.94,"tv":1925.94,"id":8174357},{"batb":[[0,2.04,6.06],[1,2.02,39.86],[2,2,10]],"batl":[[0,2.06,42.78]],"ltp":2.04,"tv":1185.0,"id":7412952}]}]}
{"op":"mcm","clk":"1004131427","pt":1580620993795,"mc":[{"id":"1.168209731","rc":[{"batl":[[0,1.96,2.5]],"ltp":1.94,"tv":1925.94,"id":8174357},{"batb":[[0,2.02,39.86],[1,2,10],[2,1.81,330.47]],"batl":[[0,2.06,48.78]],"ltp":2.04,"tv":1185.0,"id":7412952}]}]}
{"op":"mcm","clk":"1004131495","pt":1580620994875,"mc":[{"id":"1.168209731","rc":[{"batl":[[0,1.96,7.58]],"ltp":1.94,"tv":1925.94,"id":8174357},{"batb":[[0,2.04,6.08],[1,2.02,39.86],[2,2,10]],"batl":[[0,2.06,42.78]],"ltp":2.04,"tv":1185.0,"id":7412952}]}]}
{"op":"mcm","clk":"1004131588","pt":1580620996878,"mc":[{"id":"1.168209731","rc":[{"batl":[[0,1.96,2.5]],"ltp":1.94,"tv":1925.94,"id":8174357},{"batb":[[0,2.02,39.86],[1,2,10],[2,1.81,330.47]],"batl":[[0,2.06,48.78]],"ltp":2.04,"tv":1185.0,"id":7412952}]}]}
{"op":"mcm","clk":"1004131634","pt":1580620997914,"mc":[{"id":"1.168209731","rc":[{"batl":[[0,1.96,7.59]],"ltp":1.94,"tv":1925.94,"id":8174357},{"batb":[[0,2.04,6.09],[1,2.02,39.86],[2,2,10]],"batl":[[0,2.06,42.78]],"ltp":2.04,"tv":1185.0,"id":7412952}]}]}
{"op":"mcm","clk":"1004131682","pt":1580620998896,"mc":[{"id":"1.168209731","rc":[{"batl":[[0,1.96,2.5]],"ltp":1.94,"tv":1925.94,"id":8174357},{"batb":[[0,2.02,39.86],[1,2,10],[2,1.81,330.47]],"batl":[[0,2.06,48.78]],"ltp":2.04,"tv":1185.0,"id":7412952}]}]}
{"op":"mcm","clk":"1004131734","pt":1580620999919,"mc":[{"id":"1.168209731","rc":[{"batl":[[0,1.96,7.6]],"ltp":1.94,"tv":1925.94,"id":8174357},{"batb":[[0,2.04,6.1],[1,2.02,39.86],[2,2,10]],"batl":[[0,2.06,42.78]],"ltp":2.04,"tv":1185.0,"id":7412952}]}]}
{"op":"mcm","clk":"1004131782","pt":1580621000907,"mc":[{"id":"1.168209731","rc":[{"batl":[[0,1.96,2.5]],"ltp":1.94,"tv":1925.94,"id":8174357},{"batb":[[0,2.02,39.86],[1,2,10],[2,1.81,330.47]],"batl":[[0,2.06,48.78]],"ltp":2.04,"tv":1185.0,"id":7412952}]}]}
{"op":"mcm","clk":"1004131826","pt":1580621001885,"mc":[{"id":"1.168209731","rc":[{"batl":[[0,1.96,7.61]],"ltp":1.94,"tv":1925.94,"id":8174357},{"batb":[[0,2.04,6.11],[1,2.02,39.86],[2,2,10]],"ltp":2.04,"tv":1185.0,"id":7412952}]}]}
{"op":"mcm","clk":"1004131870","pt":1580621002809,"mc":[{"id":"1.168209731","rc":[{"batl":[[0,1.96,2.5]],"ltp":1.94,"tv":1925.94,"id":8174357},{"batb":[[0,2.02,39.86],[1,2,10],[2,1.81,330.47]],"ltp":2.04,"tv":1185.0,"id":7412952}]}]}
{"op":"mcm","clk":"1004131912","pt":1580621003787,"mc":[{"id":"1.168209731","rc":[{"batl":[[0,1.96,7.63]],"ltp":1.94,"tv":1925.94,"id":8174357},{"batb":[[0,2.04,6.13],[1,2.02,39.86],[2,2,10]],"batl":[[0,2.06,42.78]],"ltp":2.04,"tv":1185.0,"id":7412952}]}]}
{"op":"mcm","clk":"1004131952","pt":1580621004817,"mc":[{"id":"1.168209731","rc":[{"batl":[[0,1.96,2.5]],"ltp":1.94,"tv":1925.94,"id":8174357},{"batb":[[0,2.02,39.86],[1,2,10],[2,1.81,330.47]],"batl":[[0,2.06,48.78]],"ltp":2.04,"tv":1185.0,"id":7412952}]}]}
{"op":"mcm","clk":"1004131995","pt":1580621005817,"mc":[{"id":"1.168209731","rc":[{"batl":[[0,1.96,7.64]],"ltp":1.94,"tv":1925.94,"id":8174357},{"batb":[[0,2.04,6.14],[1,2.02,39.86],[2,2,10]],"batl":[[0,2.06,42.78]],"ltp":2.04,"tv":1185.0,"id":7412952}]}]}
{"op":"mcm","clk":"1004132055","pt":1580621006794,"mc":[{"id":"1.168209731","rc":[{"batl":[[0,1.96,2.5]],"ltp":1.94,"tv":1925.94,"id":8174357},{"batb":[[0,2.02,39.86],[1,2,10],[2,1.81,330.47]],"batl":[[0,2.06,48.78]],"ltp":2.04,"tv":1185.0,"id":7412952}]}]}
{"op":"mcm","clk":"1004132101","pt":1580621007920,"mc":[{"id":"1.168209731","rc":[{"batl":[[0,1.96,7.65]],"ltp":1.94,"tv":1925.94,"id":8174357},{"batb":[[0,2.04,6.15],[1,2.02,39.86],[2,2,10]],"batl":[[0,2.06,42.78]],"ltp":2.04,"tv":1185.0,"id":7412952}]}]}
{"op":"mcm","clk":"1004132182","pt":1580621009826,"mc":[{"id":"1.168209731","rc":[{"batl":[[0,1.96,7.66]],"ltp":1.94,"tv":1925.94,"id":8174357},{"batb":[[0,2.04,6.16]],"ltp":2.04,"tv":1185.0,"id":7412952}]}]}
{"op":"mcm","clk":"1004132224","pt":1580621010808,"mc":[{"id":"1.168209731","rc":[{"batl":[[0,1.96,2.5]],"ltp":1.94,"tv":1925.94,"id":8174357},{"batb":[[0,2.02,39.86],[1,2,10],[2,1.81,330.47]],"batl":[[0,2.06,48.78]],"ltp":2.04,"tv":1185.0,"id":7412952}]}]}
{"op":"mcm","clk":"1004132270","pt":1580621011897,"mc":[{"id":"1.168209731","rc":[{"batl":[[0,1.96,7.67]],"ltp":1.94,"tv":1925.94,"id":8174357},{"batb":[[0,2.04,6.17],[1,2.02,39.86],[2,2,10]],"batl":[[0,2.06,42.78]],"ltp":2.04,"tv":1185.0,"id":7412952}]}]}
{"op":"mcm","clk":"1004132357","pt":1580621013801,"mc":[{"id":"1.168209731","rc":[{"batl":[[0,1.96,7.68]],"ltp":1.94,"tv":1925.94,"id":8174357},{"batb":[[0,2.04,6.18]],"ltp":2.04,"tv":1185.0,"id":7412952}]}]}
{"op":"mcm","clk":"1004132402","pt":1580621014825,"mc":[{"id":"1.168209731","rc":[{"batl":[[0,1.96,7.69]],"ltp":1.94,"tv":1925.94,"id":8174357},{"batb":[[0,2.04,6.19]],"ltp":2.04,"tv":1185.0,"id":7412952}]}]}
{"op":"mcm","clk":"1004132454","pt":1580621015917,"mc":[{"id":"1.168209731","rc":[{"batl":[[0,1.96,2.5]],"ltp":1.94,"tv":1925.94,"id":8174357},{"batb":[[0,2.02,39.86],[1,2,10],[2,1.81,330.47]],"batl":[[0,2.06,48.78]],"ltp":2.04,"tv":1185.0,"id":7412952}]}]}
{"op":"mcm","clk":"1004132499","pt":1580621016948,"mc":[{"id":"1.168209731","rc":[{"batl":[[0,1.96,7.7]],"ltp":1.94,"tv":1925.94,"id":8174357},{"batb":[[0,2.04,6.2],[1,2.02,39.86],[2,2,10]],"batl":[[0,2.06,42.78]],"ltp":2.04,"tv":1185.0,"id":7412952}]}]}
{"op":"mcm","clk":"1004132561","pt":1580621017938,"mc":[{"id":"1.168209731","rc":[{"batl":[[0,1.96,2.5]],"ltp":1.94,"tv":1925.94,"id":8174357},{"batb":[[0,2.02,39.86],[1,2,10],[2,1.81,330.47]],"ltp":2.04,"tv":1185.0,"id":7412952}]}]}
{"op":"mcm","clk":"1004132611","pt":1580621018909,"mc":[{"id":"1.168209731","rc":[{"batl":[[0,1.96,7.71]],"ltp":1.94,"tv":1925.94,"id":8174357},{"batb":[[0,2.04,6.21],[1,2.02,39.86],[2,2,10]],"batl":[[0,2.06,48.78]],"ltp":2.04,"tv":1185.0,"id":7412952}]}]}
{"op":"mcm","clk":"1004132664","pt":1580621019801,"mc":[{"id":"1.168209731","rc":[{"batl":[[0,2.06,42.78]],"ltp":2.04,"tv":1185.0,"id":7412952}]}]}
{"op":"mcm","clk":"1004132719","pt":1580621020832,"mc":[{"id":"1.168209731","rc":[{"batl":[[0,1.96,2.5]],"ltp":1.94,"tv":1925.94,"id":8174357},{"batb":[[0,2.02,39.86],[1,2,10],[2,1.81,330.47]],"batl":[[0,2.06,48.78]],"ltp":2.04,"tv":1185.0,"id":7412952}]}]}
{"op":"mcm","clk":"1004132770","pt":1580621021914,"mc":[{"id":"1.168209731","rc":[{"batl":[[0,1.96,7.72]],"ltp":1.94,"tv":1925.94,"id":8174357},{"batb":[[0,2.04,6.22],[1,2.02,39.86],[2,2,10]],"ltp":2.04,"tv":1185.0,"id":7412952}]}]}
{"op":"mcm","clk":"1004132817","pt":1580621022945,"mc":[{"id":"1.168209731","rc":[{"batl":[[0,1.96,7.73]],"ltp":1.94,"tv":1925.94,"id":8174357},{"batb":[[0,2.04,6.23]],"batl":[[0,2.06,42.78]],"ltp":2.04,"tv":1185.0,"id":7412952}]}]}
{"op":"mcm","clk":"1004132863","pt":1580621023925,"mc":[{"id":"1.168209731","rc":[{"batl":[[0,1.96,2.5]],"ltp":1.94,"tv":1925.94,"id":8174357},{"batb":[[0,2.02,39.86],[1,2,10],[2,1.81,330.47]],"batl":[[0,2.06,48.78]],"ltp":2.04,"tv":1185.0,"id":7412952}]}]}
{"op":"mcm","clk":"1004133009","pt":1580621026928,"mc":[{"id":"1.168209731","rc":[{"batl":[[0,1.96,7.75]],"ltp":1.94,"tv":1925.94,"id":8174357},{"batb":[[0,2.04,6.25],[1,2.02,39.86],[2,2,10]],"batl":[[0,2.06,42.78]],"ltp":2.04,"tv":1185.0,"id":7412952}]}]}
{"op":"mcm","clk":"1004133051","pt":1580621027753,"mc":[{"id":"1.168209731","rc":[{"batl":[[0,1.96,7.76]],"ltp":1.94,"tv":1925.94,"id":8174357},{"batb":[[0,2.04,6.26]],"ltp":2.04,"tv":1185.0,"id":7412952}]}]}
{"op":"mcm","clk":"1004133155","pt":1580621029941,"mc":[{"id":"1.168209731","rc":[{"batl":[[0,1.96,2.5]],"ltp":1.94,"tv":1925.94,"id":8174357},{"batb":[[0,2.02,39.86],[1,2,10],[2,1.81,330.47]],"batl":[[0,2.06,48.78]],"ltp":2.04,"tv":1185.0,"id":7412952}]}]}
{"op":"mcm","clk":"1004133210","pt":1580621030921,"mc":[{"id":"1.168209731","rc":[{"batl":[[0,1.96,7.77]],"ltp":1.94,"tv":1925.94,"id":8174357},{"batb":[[0,2.04,6.27],[1,2.02,39.86],[2,2,10]],"batl":[[0,2.06,42.78]],"ltp":2.04,"tv":1185.0,"id":7412952}]}]}
{"op":"mcm","clk":"1004133261","pt":1580621031753,"mc":[{"id":"1.168209731","rc":[{"batl":[[0,1.96,7.78]],"ltp":1.94,"tv":1925.94,"id":8174357},{"batb":[[0,2.04,6.28]],"ltp":2.04,"tv":1185.0,"id":7412952}]}]}
{"op":"mcm","clk":"1004133333","pt":1580621032942,"mc":[{"id":"1.168209731","rc":[{"batl":[[0,1.96,7.79]],"ltp":1.94,"tv":1925.94,"id":8174357},{"batb":[[0,2.04,6.29]],"ltp":2.04,"tv":1185.0,"id":7412952}]}]}
{"op":"mcm","clk":"1004133394","pt":1580621033932,"mc":[{"id":"1.168209731","rc":[{"batl":[[0,1.96,2.5]],"ltp":1.94,"tv":1925.94,"id":8174357},{"batb":[[0,2.02,39.86],[1,2,10],[2,1.81,330.47]],"batl":[[0,2.06,48.78]],"ltp":2.04,"tv":1185.0,"id":7412952}]}]}
{"op":"mcm","clk":"1004133454","pt":1580621034922,"mc":[{"id":"1.168209731","rc":[{"batl":[[0,1.96,7.8]],"ltp":1.94,"tv":1925.94,"id":8174357},{"batb":[[0,2.04,6.3],[1,2.02,39.86],[2,2,10]],"batl":[[0,2.06,42.78]],"ltp":2.04,"tv":1185.0,"id":7412952}]}]}
{"op":"mcm","clk":"1004133501","pt":1580621035950,"mc":[{"id":"1.168209731","rc":[{"batl":[[0,1.96,2.5]],"ltp":1.94,"tv":1925.94,"id":8174357},{"batb":[[0,2.02,39.86],[1,2,10],[2,1.81,330.47]],"batl":[[0,2.06,48.78]],"ltp":2.04,"tv":1185.0,"id":7412952}]}]}
{"op":"mcm","clk":"1004133558","pt":1580621036933,"mc":[{"id":"1.168209731","rc":[{"batl":[[0,1.96,7.81]],"ltp":1.94,"tv":1925.94,"id":8174357},{"batb":[[0,2.04,6.31],[1,2.02,39.86],[2,2,10]],"batl":[[0,2.06,42.78]],"ltp":2.04,"tv":1185.0,"id":7412952}]}]}
{"op":"mcm","clk":"1004133656","pt":1580621038956,"mc":[{"id":"1.168209731","rc":[{"batl":[[0,1.96,7.82]],"ltp":1.94,"tv":1925.94,"id":8174357},{"batb":[[0,2.04,6.32]],"ltp":2.04,"tv":1185.0,"id":7412952}]}]}
{"op":"mcm","clk":"1004133707","pt":1580621039940,"mc":[{"id":"1.168209731","rc":[{"batl":[[0,1.96,2.5]],"ltp":1.94,"tv":1925.94,"id":8174357},{"batb":[[0,2.02,39.86],[1,2,10],[2,1.81,330.47]],"batl":[[0,2.06,48.78]],"ltp":2.04,"tv":1185.0,"id":7412952}]}]}
{"op":"mcm","clk":"1004133761","pt":1580621040924,"mc":[{"id":"1.168209731","rc":[{"batl":[[0,1.96,7.5]],"ltp":1.94,"tv":1925.94,"id":8174357},{"batb":[[0,2.04,6],[1,2.02,39.86],[2,2,10]],"batl":[[0,2.06,42.78]],"ltp":2.04,"tv":1185.0,"id":7412952}]}]}
{"op":"mcm","clk":"1004133812","pt":1580621041759,"mc":[{"id":"1.168209731","rc":[{"batl":[[0,1.96,2.5],[1,2,68.06],[2,2.3,10.13]],"ltp":1.94,"tv":1925.94,"id":8174357},{"batb":[[0,2.02,39.86],[1,2,10],[2,1.81,330.47]],"batl":[[0,2.06,48.78]],"ltp":2.04,"tv":1185.0,"id":7412952}]}]}
{"op":"mcm","clk":"1004133939","pt":1580621043955,"mc":[{"id":"1.168209731","rc":[{"batl":[[0,1.96,7.52],[1,1.97,5],[2,2,68.06]],"ltp":1.94,"tv":1925.94,"id":8174357},{"batb":[[0,2.04,6.02],[1,2.02,39.86],[2,2,10]],"batl":[[0,2.06,54.78]],"ltp":2.04,"tv":1185.0,"id":7412952}]}]}
{"op":"mcm","clk":"1004133990","pt":1580621044859,"mc":[{"id":"1.168209731","rc":[{"batb":[[0,2.04,6]],"batl":[[0,2.06,42.78]],"ltp":2.04,"tv":1185.0,"id":7412952}]}]}
{"op":"mcm","clk":"1004134051","pt":1580621045948,"mc":[{"id":"1.168209731","rc":[{"batl":[[0,1.96,7.53]],"ltp":1.94,"tv":1925.94,"id":8174357},{"batb":[[0,2.04,6.03]],"ltp":2.04,"tv":1185.0,"id":7412952}]}]}
{"op":"mcm","clk":"1004134160","pt":1580621047862,"mc":[{"id":"1.168209731","rc":[{"batl":[[0,1.96,2.5]],"ltp":1.94,"tv":1925.94,"id":8174357},{"batb":[[0,2.02,39.86],[1,2,10],[2,1.81,330.47]],"batl":[[0,2.06,48.78]],"ltp":2.04,"tv":1185.0,"id":7412952}]}]}
{"op":"mcm","clk":"1004134222","pt":1580621048849,"mc":[{"id":"1.168209731","rc":[{"batl":[[0,1.96,7.54]],"ltp":1.94,"tv":1925.94,"id":8174357},{"batb":[[0,2.04,6.04],[1,2.02,39.86],[2,2,10]],"batl":[[0,2.06,42.78]],"ltp":2.04,"tv":1185.0,"id":7412952}]}]}
{"op":"mcm","clk":"1004134293","pt":1580621049934,"mc":[{"id":"1.168209731","rc":[{"batl":[[0,1.96,2.5]],"ltp":1.94,"tv":1925.94,"id":8174357},{"batb":[[0,2.02,39.86],[1,2,10],[2,1.81,330.47]],"batl":[[0,2.06,54.78]],"ltp":2.04,"tv":1185.0,"id":7412952}]}]}
{"op":"mcm","clk":"1004134358","pt":1580621050864,"mc":[{"id":"1.168209731","rc":[{"batl":[[0,1.96,7.55]],"ltp":1.94,"tv":1925.94,"id":8174357},{"batb":[[0,2.04,6.05],[1,2.02,39.86],[2,2,10]],"batl":[[0,2.06,48.78]],"ltp":2.04,"tv":1185.0,"id":7412952}]}]}
{"op":"mcm","clk":"1004134419","pt":1580621051844,"mc":[{"id":"1.168209731","rc":[{"batl":[[0,1.96,2.5]],"ltp":1.94,"tv":1925.94,"id":8174357},{"batb":[[0,2.02,39.86],[1,2,10],[2,1.81,330.47]],"ltp":2.04,"tv":1185.0,"id":7412952}]}]}
{"op":"mcm","clk":"1004134477","pt":1580621052879,"mc":[{"id":"1.168209731","rc":[{"batl":[[0,1.96,7.57]],"ltp":1.94,"tv":1925.94,"id":8174357},{"batb":[[0,2.04,6.07],[1,2.02,39.86],[2,2,10]],"batl":[[0,2.06,42.78]],"ltp":2.04,"tv":1185.0,"id":7412952}]}]}
{"op":"mcm","clk":"1004134540","pt":1580621053860,"mc":[{"id":"1.168209731","rc":[{"batl":[[0,1.96,2.5]],"ltp":1.94,"tv":1925.94,"id":8174357},{"batb":[[0,2.02,39.86],[1,2,10],[2,1.81,330.47]],"batl":[[0,2.06,48.78]],"ltp":2.04,"tv":1185.0,"id":7412952}]}]}
{"op":"mcm","clk":"1004134600","pt":1580621054946,"mc":[{"id":"1.168209731","rc":[{"batl":[[0,1.96,7.58]],"ltp":1.94,"tv":1925.94,"id":8174357},{"batb":[[0,2.04,6.08],[1,2.02,39.86],[2,2,10]],"batl":[[0,2.06,42.78]],"ltp":2.04,"tv":1185.0,"id":7412952}]}]}
{"op":"mcm","clk":"1004134718","pt":1580621056955,"mc":[{"id":"1.168209731","rc":[{"batl":[[0,1.96,7.59]],"ltp":1.94,"tv":1925.94,"id":8174357},{"batb":[[0,2.04,6.09]],"batl":[[0,2.06,48.78]],"ltp":2.04,"tv":1185.0,"id":7412952}]}]}
{"op":"mcm","clk":"1004134758","pt":1580621057881,"mc":[{"id":"1.168209731","rc":[{"batl":[[0,1.96,2.5]],"ltp":1.94,"tv":1925.94,"id":8174357},{"batb":[[0,2.02,39.86],[1,2,10],[2,1.81,330.47]],"ltp":2.04,"tv":1185.0,"id":7412952}]}]}
{"op":"mcm","clk":"1004134816","pt":1580621058860,"mc":[{"id":"1.168209731","rc":[{"batl":[[0,1.96,7.6]],"ltp":1.94,"tv":1925.94,"id":8174357},{"batb":[[0,2.04,6.1],[1,2.02,39.86],[2,2,10]],"batl":[[0,2.06,42.78]],"ltp":2.04,"tv":1185.0,"id":7412952}]}]}
{"op":"mcm","clk":"1004134883","pt":1580621059890,"mc":[{"id":"1.168209731","rc":[{"batl":[[0,1.96,2.5]],"ltp":1.94,"tv":1925.94,"id":8174357},{"batb":[[0,2.02,39.86],[1,2,10],[2,1.81,330.47]],"batl":[[0,2.06,48.78]],"ltp":2.04,"tv":1185.0,"id":7412952}]}]}
{"op":"mcm","clk":"1004134937","pt":1580621060870,"mc":[{"id":"1.168209731","rc":[{"batl":[[0,1.96,7.61]],"ltp":1.94,"tv":1925.94,"id":8174357},{"batb":[[0,2.04,6.11],[1,2.02,39.86],[2,2,10]],"batl":[[0,2.06,42.78]],"ltp":2.04,"tv":1185.0,"id":7412952}]}]}
{"op":"mcm","clk":"1004134997","pt":1580621061953,"mc":[{"id":"1.168209731","rc":[{"batl":[[0,1.96,2.5]],"ltp":1.94,"tv":1925.94,"id":8174357},{"batb":[[0,2.02,39.86],[1,2,10],[2,1.81,330.47]],"batl":[[0,2.06,48.78]],"ltp":2.04,"tv":1185.0,"id":7412952}]}]}
{"op":"mcm","clk":"1004135099","pt":1580621063756,"mc":[{"id":"1.168209731","rc":[{"batl":[[0,1.96,7.62]],"ltp":1.94,"tv":1925.94,"id":8174357},{"batb":[[0,2.04,6.12],[1,2.02,39.86],[2,2,10]],"batl":[[0,2.06,42.78]],"ltp":2.04,"tv":1185.0,"id":7412952}]}]}
{"op":"mcm","clk":"1004135159","pt":1580621064782,"mc":[{"id":"1.168209731","rc":[{"batl":[[0,1.96,2.5]],"ltp":1.94,"tv":1925.94,"id":8174357},{"batb":[[0,2.02,39.86],[1,2,10],[2,1.81,330.47]],"batl":[[0,2.06,48.78]],"ltp":2.04,"tv":1185.0,"id":7412952}]}]}
{"op":"mcm","clk":"1004135225","pt":1580621065763,"mc":[{"id":"1.168209731","rc":[{"batl":[[0,1.96,7.64]],"ltp":1.94,"tv":1925.94,"id":8174357},{"batb":[[0,2.04,6.14],[1,2.02,39.86],[2,2,10]],"batl":[[0,2.06,42.78]],"ltp":2.04,"tv":1185.0,"id":7412952}]}]}
{"op":"mcm","clk":"1004135355","pt":1580621067796,"mc":[{"id":"1.168209731","rc":[{"batl":[[0,1.96,7.65]],"ltp":1.94,"tv":1925.94,"id":8174357},{"batb":[[0,2.04,6.15]],"ltp":2.04,"tv":1185.0,"id":7412952}]}]}
{"op":"mcm","clk":"1004135421","pt":1580621068778,"mc":[{"id":"1.168209731","rc":[{"batl":[[0,1.96,2.5]],"ltp":1.94,"tv":1925.94,"id":8174357},{"batb":[[0,2.02,39.86],[1,2,10],[2,1.81,330.47]],"batl":[[0,2.06,48.78]],"ltp":2.04,"tv":1185.0,"id":7412952}]}]}
{"op":"mcm","clk":"1004135475","pt":1580621069761,"mc":[{"id":"1.168209731","rc":[{"batl":[[0,1.96,7.66]],"ltp":1.94,"tv":1925.94,"id":8174357},{"batb":[[0,2.04,6.16],[1,2.02,39.86],[2,2,10]],"batl":[[0,2.06,42.78]],"ltp":2.04,"tv":1185.0,"id":7412952}]}]}
{"op":"mcm","clk":"1004135531","pt":1580621070788,"mc":[{"id":"1.168209731","rc":[{"batl":[[0,1.96,2.5]],"ltp":1.94,"tv":1925.94,"id":8174357},{"batb":[[0,2.02,39.86],[1,2,10],[2,1.81,330.47]],"batl":[[0,2.06,48.78]],"ltp":2.04,"tv":1185.0,"id":7412952}]}]}
{"op":"mcm","clk":"1004135580","pt":1580621071773,"mc":[{"id":"1.168209731","rc":[{"batl":[[0,1.96,7.67]],"ltp":1.94,"tv":1925.94,"id":8174357},{"batb":[[0,2.04,6.17],[1,2.02,39.86],[2,2,10]],"batl":[[0,2.06,42.78]],"ltp":2.04,"tv":1185.0,"id":7412952}]}]}
{"op":"mcm","clk":"1004135627","pt":1580621072863,"mc":[{"id":"1.168209731","rc":[{"batl":[[0,1.96,2.5]],"ltp":1.94,"tv":1925.94,"id":8174357},{"batb":[[0,2.02,39.86],[1,2,10],[2,1.81,330.47]],"batl":[[0,2.06,48.78]],"ltp":2.04,"tv":1185.0,"id":7412952}]}]}
{"op":"mcm","clk":"1004135668","pt":1580621073889,"mc":[{"id":"1.168209731","rc":[{"batl":[[0,1.96,7.68]],"ltp":1.94,"tv":1925.94,"id":8174357},{"batb":[[0,2.04,6.18],[1,2.02,39.86],[2,2,10]],"batl":[[0,2.06,42.78]],"ltp":2.04,"tv":1185.0,"id":7412952}]}]}
{"op":"mcm","clk":"1004135715","pt":1580621074870,"mc":[{"id":"1.168209731","rc":[{"batl":[[0,1.96,2.5]],"ltp":1.94,"tv":1925.94,"id":8174357},{"batb":[[0,2.02,39.86],[1,2,10],[2,1.81,330.47]],"batl":[[0,2.06,48.78]],"ltp":2.04,"tv":1185.0,"id":7412952}]}]}
{"op":"mcm","clk":"1004135771","pt":1580621075901,"mc":[{"id":"1.168209731","rc":[{"batl":[[0,1.96,7.69]],"ltp":1.94,"tv":1925.94,"id":8174357},{"batb":[[0,2.04,6.19],[1,2.02,39.86],[2,2,10]],"batl":[[0,2.06,42.78]],"ltp":2.04,"tv":1185.0,"id":7412952}]}]}
{"op":"mcm","clk":"1004135814","pt":1580621076880,"mc":[{"id":"1.168209731","rc":[{"batl":[[0,1.96,2.5]],"ltp":1.94,"tv":1925.94,"id":8174357},{"batb":[[0,2.02,39.86],[1,2,10],[2,1.81,330.47]],"batl":[[0,2.06,48.78]],"ltp":2.04,"tv":1185.0,"id":7412952}]}]}
{"op":"mcm","clk":"1004135871","pt":1580621077911,"mc":[{"id":"1.168209731","rc":[{"batl":[[0,1.96,7.7]],"ltp":1.94,"tv":1925.94,"id":8174357},{"batb":[[0,2.04,6.2],[1,2.02,39.86],[2,2,10]],"batl":[[0,2.06,42.78]],"ltp":2.04,"tv":1185.0,"id":7412952}]}]}
{"op":"mcm","clk":"1004135923","pt":1580621078893,"mc":[{"id":"1.168209731","rc":[{"batl":[[0,1.96,7.71]],"ltp":1.94,"tv":1925.94,"id":8174357},{"batb":[[0,2.04,6.21]],"ltp":2.04,"tv":1185.0,"id":7412952}]}]}
{"op":"mcm","clk":"1004135966","pt":1580621079873,"mc":[{"id":"1.168209731","rc":[{"batl":[[0,1.96,2.5]],"ltp":1.94,"tv":1925.94,"id":8174357},{"batb":[[0,2.02,39.86],[1,2,10],[2,1.81,330.47]],"batl":[[0,2.06,48.78]],"ltp":2.04,"tv":1185.0,"id":7412952}]}]}
{"op":"mcm","clk":"1004136017","pt":1580621081012,"mc":[{"id":"1.168209731","rc":[{"batl":[[0,1.95,2.53],[1,1.96,7.72],[2,1.97,5]],"ltp":1.94,"tv":1925.94,"id":8174357},{"batb":[[0,2.04,6.22],[1,2.02,39.86],[2,2,10]],"batl":[[0,2.06,42.78]],"ltp":2.04,"tv":1185.0,"id":7412952}]}]}
{"op":"mcm","clk":"1004136215","pt":1580621085721,"mc":[{"id":"1.168209731","rc":[{"batl":[[1,1.96,5.22]],"ltp":1.94,"tv":1925.94,"id":8174357}]}]}
{"op":"mcm","clk":"1004137603","pt":1580621117071,"mc":[{"id":"1.168209731","rc":[{"batb":[[0,1.94,11.99]],"ltp":1.94,"tv":1925.94,"id":8174357}]}]}
{"op":"mcm","clk":"1004137900","pt":1580621123782,"mc":[{"id":"1.168209731","rc":[{"batb":[[2,2,6]],"batl":[[1,2.08,5],[2,2.1,5]],"ltp":2.04,"tv":1185.0,"id":7412952}]}]}
{"op":"mcm","clk":"1004137944","pt":1580621124964,"mc":[{"id":"1.168209731","rc":[{"batb":[[1,1.93,7]],"ltp":1.94,"tv":1925.94,"id":8174357}]}]}
{"op":"mcm","clk":"1004155077","pt":1580621586425,"mc":[{"id":"1.168209731","rc":[{"trd":[[1.95,0.21]],"batl":[[0,1.95,2.43]],"ltp":1.95,"tv":1926.15,"id":8174357}],"tv":3111.15}]}
{"op":"mcm","clk":"1004156918","pt":1580621643681,"mc":[{"id":"1.168209731","rc":[{"trd":[[1.94,55.81]],"batb":[[0,1.94,6],[2,1.92,8.63]],"ltp":1.94,"tv":1955.82,"id":8174357},{"trd":[[2.06,61.65]],"batl":[[0,2.06,37.42]],"ltp":2.06,"tv":1190.36,"id":7412952}],"tv":3146.19}]}
{"op":"mcm","clk":"1004157239","pt":1580621652589,"mc":[{"id":"1.168209731","rc":[{"batl":[[1,1.96,8.38]],"ltp":1.94,"tv":1955.82,"id":8174357}]}]}
{"op":"mcm","clk":"1004166315","pt":1580621885965,"mc":[{"id":"1.168209731","rc":[{"trd":[[2.06,61.87]],"batl":[[0,2.06,37.31]],"ltp":2.06,"tv":1190.59,"id":7412952}],"tv":3146.41}]}
{"op":"mcm","clk":"1004219994","pt":1580623557386,"mc":[{"id":"1.168209731","rc":[{"trd":[[1.95,2.64],[1.96,18.78]],"batl":[[0,1.97,5.89],[1,1.98,5.09],[2,2,68.06]],"ltp":1.96,"tv":1965.74,"id":8174357},{"trd":[[2.04,54.8]],"batb":[[0,2.04,4.31],[1,2.02,35.86]],"ltp":2.04,"tv":1212.54,"id":7412952}],"tv":3178.28}]}
{"op":"mcm","clk":"1004220398","pt":1580623573701,"mc":[{"id":"1.168209731","rc":[{"batb":[[0,1.94,14.94]],"batl":[[0,1.97,14.29]],"ltp":1.96,"tv":1965.74,"id":8174357}]}]}
{"op":"mcm","clk":"1004245761","pt":1580624415212,"mc":[{"id":"1.168209731","rc":[{"trd":[[1.94,70.96]],"batb":[[0,1.94,7.37]],"ltp":1.94,"tv":1980.88,"id":8174357}],"tv":3193.43}]}
{"op":"mcm","clk":"1004284862","pt":1580625662167,"mc":[{"id":"1.168209731","rc":[{"batb":[[2,1.92,10.63]],"batl":[[2,1.99,2.37]],"ltp":1.94,"tv":1980.88,"id":8174357},{"batb":[[2,2,8]],"batl":[[2,2.1,7.05]],"ltp":2.04,"tv":1212.54,"id":7412952}]}]}
{"op":"mcm","clk":"1004350238","pt":1580627706915,"mc":[{"id":"1.168209731","rc":[{"trd":[[1.94,106.08]],"batb":[[0,1.93,7],[1,1.92,10.63],[2,1.91,2.06]],"ltp":1.94,"tv":2016.0,"id":8174357},{"trd":[[2.06,81.04]],"batl":[[0,2.06,18.14]],"ltp":2.06,"tv":1231.71,"id":7412952}],"tv":3247.72}]}
{"op":"mcm","clk":"1004423053","pt":1580629511754,"mc":[{"id":"1.168209731","rc":[{"batb":[[2,1.91,2]],"ltp":1.94,"tv":2016.0,"id":8174357}]}]}
{"op":"mcm","clk":"1004423486","pt":1580629521743,"mc":[{"id":"1.168209731","rc":[{"batb":[[2,1.91,2.06]],"ltp":1.94,"tv":2016.0,"id":8174357}]}]}
{"op":"mcm","clk":"1004445072","pt":1580630008894,"mc":[{"id":"1.168209731","rc":[{"trd":[[1.96,19.67]],"batb":[[0,1.95,7.15],[1,1.94,9.09],[2,1.93,9.08]],"batl":[[0,1.97,8.4],[2,1.99,7.37]],"ltp":1.96,"tv":2016.89,"id":8174357},{"trd":[[2.04,73.52]],"batb":[[0,2.04,1.38],[2,2,6]],"batl":[[0,2.06,23.14],[1,2.08,7]],"ltp":2.04,"tv":1250.43,"id":7412952}],"tv":3267.33}]}
{"op":"mcm","clk":"1004445122","pt":1580630009874,"mc":[{"id":"1.168209731","rc":[{"batb":[[0,1.93,7],[1,1.92,10.82],[2,1.91,2.06]],"batl":[[0,1.96,5.15],[1,1.97,8.4],[2,1.98,7.15]],"ltp":1.96,"tv":2016.89,"id":8174357},{"batb":[[0,2.04,5],[2,2,8]],"batl":[[0,2.06,18.14],[1,2.08,5],[2,2.1,7]],"ltp":2.04,"tv":1250.43,"id":7412952}]}]}
{"op":"mcm","clk":"1004446294","pt":1580630037738,"mc":[{"id":"1.168209731","rc":[{"batl":[[0,1.96,16.5],[1,1.97,4]],"ltp":1.96,"tv":2016.89,"id":8174357}]}]}
{"op":"mcm","clk":"1004455716","pt":1580630239815,"mc":[{"id":"1.168209731","rc":[{"trd":[[1.96,39.17]],"batb":[[0,1.94,9],[1,1.93,7],[2,1.92,13.82]],"batl":[[0,1.97,4],[1,1.98,5.11],[2,1.99,3]],"ltp":1.96,"tv":2036.39,"id":8174357},{"trd":[[2.04,110.25]],"batb":[[0,2.02,35.86],[1,2,8],[2,1.98,2.26]],"batl":[[0,2.06,26.14],[1,2.08,8],[2,2.1,10]],"ltp":2.04,"tv":1287.17,"id":7412952}],"tv":3323.56}]}
{"op":"mcm","clk":"1004455780","pt":1580630240899,"mc":[{"id":"1.168209731","rc":[{"batb":[[0,1.93,7],[1,1.92,13.82],[2,1.91,2.06]],"batl":[[0,1.98,3],[1,1.99,5.41],[2,2,73.06]],"ltp":1.96,"tv":2036.39,"id":8174357},{"trd":[[2.04,118.45]],"batb":[[0,2.04,3.11],[1,2.02,35.86],[2,2,3]],"batl":[[0,2.06,18.14]],"ltp":2.04,"tv":1295.37,"id":7412952}],"tv":3331.76}]}
{"op":"mcm","clk":"1004455837","pt":1580630241882,"mc":[{"id":"1.168209731","rc":[{"batl":[[0,1.96,3.11],[1,1.98,3],[2,1.99,5.41]],"ltp":1.96,"tv":2036.39,"id":8174357},{"trd":[[2.04,124.67]],"batb":[[0,2.04,3]],"ltp":2.04,"tv":1301.59,"id":7412952}],"tv":3337.98}]}
{"op":"mcm","clk":"1004455906","pt":1580630242812,"mc":[{"id":"1.168209731","rc":[{"batl":[[0,1.98,3],[1,1.99,5.41],[2,2,73.06]],"ltp":1.96,"tv":2036.39,"id":8174357},{"batb":[[2,2,5]],"ltp":2.04,"tv":1301.59,"id":7412952}]}]}
{"op":"mcm","clk":"1004455971","pt":1580630243895,"mc":[{"id":"1.168209731","rc":[{"batl":[[0,1.96,3.12],[1,1.98,3],[2,1.99,5.41]],"ltp":1.96,"tv":2036.39,"id":8174357},{"trd":[[2.04,130.67]],"batb":[[2,2,3]],"ltp":2.04,"tv":1307.58,"id":7412952}],"tv":3343.98}]}
{"op":"mcm","clk":"1004456025","pt":1580630244922,"mc":[{"id":"1.168209731","rc":[{"batl":[[0,1.98,3],[1,1.99,5.41],[2,2,73.06]],"ltp":1.96,"tv":2036.39,"id":8174357},{"batb":[[0,2.04,3.13],[2,2,5]],"ltp":2.04,"tv":1307.58,"id":7412952}]}]}
{"op":"mcm","clk":"1004456069","pt":1580630245904,"mc":[{"id":"1.168209731","rc":[{"batb":[[2,1.9,2]],"batl":[[0,1.96,2.13],[1,1.98,3],[2,1.99,5.41]],"ltp":1.96,"tv":2036.39,"id":8174357},{"trd":[[2.04,136.94]],"batb":[[0,2.04,3],[2,2,3]],"ltp":2.04,"tv":1313.85,"id":7412952}],"tv":3350.24}]}
{"op":"mcm","clk":"1004456129","pt":1580630246728,"mc":[{"id":"1.168209731","rc":[{"batb":[[2,1.91,2.06]],"batl":[[0,1.97,2]],"ltp":1.96,"tv":2036.39,"id":8174357},{"batb":[[2,2,5]],"ltp":2.04,"tv":1313.85,"id":7412952}]}]}
{"op":"mcm","clk":"1004456516","pt":1580630253724,"mc":[{"id":"1.168209731","rc":[{"batb":[[0,1.94,8.94],[1,1.93,7],[2,1.92,13.82]],"batl":[[0,1.97,10.4]],"ltp":1.96,"tv":2036.39,"id":8174357}]}]}
{"op":"mcm","clk":"1004466786","pt":1580630463945,"mc":[{"id":"1.168209731","rc":[{"batb":[[1,1.93,12]],"batl":[[0,1.96,3.02],[1,1.97,10.4],[2,1.98,3]],"ltp":1.96,"tv":2036.39,"id":8174357}]}]}
{"op":"mcm","clk":"1004466844","pt":1580630464825,"mc":[{"id":"1.168209731","rc":[{"batb":[[0,2.04,4.02],[2,2,3]],"ltp":2.04,"tv":1313.85,"id":7412952}]}]}
{"op":"mcm","clk":"1004466888","pt":1580630465952,"mc":[{"id":"1.168209731","rc":[{"batb":[[2,1.92,17.82]],"batl":[[0,1.97,12.4],[1,1.98,3],[2,1.99,7.44]],"ltp":1.96,"tv":2036.39,"id":8174357},{"batb":[[0,2.04,5],[2,2,7]],"ltp":2.04,"tv":1313.85,"id":7412952}]}]}
{"op":"mcm","clk":"1004467329","pt":1580630476950,"mc":[{"id":"1.168209731","rc":[{"batl":[[1,1.98,7.15],[2,1.99,3]],"ltp":1.96,"tv":2036.39,"id":8174357}]}]}
{"op":"mcm","clk":"1004467342","pt":1580630477256,"mc":[{"id":"1.168209731","rc":[{"batl":[[1,1.98,3],[2,1.99,5.04]],"ltp":1.96,"tv":2036.39,"id":8174357}]}]}
{"op":"mcm","clk":"1004468219","pt":1580630497873,"mc":[{"id":"1.168209731","rc":[{"batl":[[2,1.99,5.05]],"ltp":1.96,"tv":2036.39,"id":8174357},{"batb":[[2,2,5]],"ltp":2.04,"tv":1313.85,"id":7412952}]}]}
{"op":"mcm","clk":"1004468224","pt":1580630498079,"mc":[{"id":"1.168209731","rc":[{"batb":[[2,2,7]],"ltp":2.04,"tv":1313.85,"id":7412952}]}]}
{"op":"mcm","clk":"1004469129","pt":1580630518894,"mc":[{"id":"1.168209731","rc":[{"batb":[[0,1.94,22.94]],"batl":[[1,1.98,5.25],[2,1.99,3]],"ltp":1.96,"tv":2036.39,"id":8174357},{"batb":[[0,2.02,35.86],[1,2,7],[2,1.99,2]],"ltp":2.04,"tv":1313.85,"id":7412952}]}]}
{"op":"mcm","clk":"1004469167","pt":1580630519414,"mc":[{"id":"1.168209731","rc":[{"batb":[[0,1.94,8.94]],"batl":[[1,1.98,3],[2,1.99,5.18]],"ltp":1.96,"tv":2036.39,"id":8174357},{"batb":[[0,2.04,5],[1,2.02,35.86],[2,2,7]],"ltp":2.04,"tv":1313.85,"id":7412952}]}]}
{"op":"mcm","clk":"1004470277","pt":1580630539947,"mc":[{"id":"1.168209731","rc":[{"batl":[[1,1.98,5.12]],"ltp":1.96,"tv":2036.39,"id":8174357}]}]}
{"op":"mcm","clk":"1004470297","pt":1580630540361,"mc":[{"id":"1.168209731","rc":[{"batl":[[1,1.98,3],[2,1.99,5]],"ltp":1.96,"tv":2036.39,"id":8174357}]}]}
{"op":"mcm","clk":"1004471365","pt":1580630560886,"mc":[{"id":"1.168209731","rc":[{"batl":[[0,1.96,4.11],[1,1.97,12.4],[2,1.98,3]],"ltp":1.96,"tv":2036.39,"id":8174357}]}]}
{"op":"mcm","clk":"1004471437","pt":1580630561861,"mc":[{"id":"1.168209731","rc":[{"batl":[[0,1.97,12.4],[1,1.98,3],[2,1.99,5.28]],"ltp":1.96,"tv":2036.39,"id":8174357},{"batb":[[0,2.04,5.22],[2,2,5]],"ltp":2.04,"tv":1313.85,"id":7412952}]}]}
{"op":"mcm","clk":"1004471448","pt":1580630562062,"mc":[{"id":"1.168209731","rc":[{"batb":[[2,2,7]],"ltp":2.04,"tv":1313.85,"id":7412952}]}]}
{"op":"mcm","clk":"1004472294","pt":1580630581927,"mc":[{"id":"1.168209731","rc":[{"batl":[[2,1.99,7.07]],"ltp":1.96,"tv":2036.39,"id":8174357},{"batb":[[0,2.04,5],[2,2,5]],"ltp":2.04,"tv":1313.85,"id":7412952}]}]}
{"op":"mcm","clk":"1004472303","pt":1580630582110,"mc":[{"id":"1.168209731","rc":[{"batb":[[2,2,7]],"ltp":2.04,"tv":1313.85,"id":7412952}]}]}
{"op":"mcm","clk":"1004473095","pt":1580630602845,"mc":[{"id":"1.168209731","rc":[{"batl":[[1,1.98,5],[2,1.99,5.04]],"ltp":1.96,"tv":2036.39,"id":8174357}]}]}
{"op":"mcm","clk":"1004473120","pt":1580630603460,"mc":[{"id":"1.168209731","rc":[{"batl":[[1,1.98,3]],"ltp":1.96,"tv":2036.39,"id":8174357},{"batb":[[0,2.04,5.12]],"ltp":2.04,"tv":1313.85,"id":7412952}]}]}
{"op":"mcm","clk":"1004473948","pt":1580630622875,"mc":[{"id":"1.168209731","rc":[{"batl":[[2,1.99,5.28]],"ltp":1.96,"tv":2036.39,"id":8174357},{"batb":[[0,2.04,5],[2,2,5]],"ltp":2.04,"tv":1313.85,"id":7412952}]}]}
{"op":"mcm","clk":"1004473958","pt":1580630623080,"mc":[{"id":"1.168209731","rc":[{"batb":[[2,2,7]],"ltp":2.04,"tv":1313.85,"id":7412952}]}]}
{"op":"mcm","clk":"1004474860","pt":1580630643894,"mc":[{"id":"1.168209731","rc":[{"batl":[[2,1.99,5.2]],"ltp":1.96,"tv":2036.39,"id":8174357}]}]}
{"op":"mcm","clk":"1004475970","pt":1580630664863,"mc":[{"id":"1.168209731","rc":[{"batl":[[2,1.99,5.36]],"ltp":1.96,"tv":2036.39,"id":8174357}]}]}
{"op":"mcm","clk":"1004476967","pt":1580630685887,"mc":[{"id":"1.168209731","rc":[{"batl":[[0,1.96,4.13],[1,1.97,12.4],[2,1.98,5.05]],"ltp":1.96,"tv":2036.39,"id":8174357}]}]}
{"op":"mcm","clk":"1004476995","pt":1580630686656,"mc":[{"id":"1.168209731","rc":[{"batl":[[0,1.97,12.4],[1,1.98,3],[2,1.99,5.34]],"ltp":1.96,"tv":2036.39,"id":8174357}]}]}
{"op":"mcm","clk":"1004477915","pt":1580630706898,"mc":[{"id":"1.168209731","rc":[{"batl":[[0,1.96,4.25],[1,1.97,12.4],[2,1.98,3]],"ltp":1.96,"tv":2036.39,"id":8174357}]}]}
{"op":"mcm","clk":"1004477959","pt":1580630707922,"mc":[{"id":"1.168209731","rc":[{"batl":[[0,1.96,4.04],[2,1.98,5.03]],"ltp":1.96,"tv":2036.39,"id":8174357},{"batb":[[0,2.04,10]],"ltp":2.04,"tv":1313.85,"id":7412952}]}]}
{"op":"mcm","clk":"1004477983","pt":1580630708493,"mc":[{"id":"1.168209731","rc":[{"batl":[[0,1.97,12.4],[1,1.98,3],[2,1.99,5.32]],"ltp":1.96,"tv":2036.39,"id":8174357},{"batb":[[0,2.04,5]],"ltp":2.04,"tv":1313.85,"id":7412952}]}]}
{"op":"mcm","clk":"1004478888","pt":1580630729938,"mc":[{"id":"1.168209731","rc":[{"batb":[[0,1.94,22.94]],"batl":[[1,1.98,5.19],[2,1.99,5.02]],"ltp":1.96,"tv":2036.39,"id":8174357},{"batb":[[0,2.02,35.86],[1,2,7],[2,1.99,2]],"ltp":2.04,"tv":1313.85,"id":7412952}]}]}
{"op":"mcm","clk":"1004478917","pt":1580630730456,"mc":[{"id":"1.168209731","rc":[{"batb":[[0,1.94,8.94]],"batl":[[1,1.98,3]],"ltp":1.96,"tv":2036.39,"id":8174357},{"batb":[[0,2.04,5],[1,2.02,35.86],[2,2,7]],"ltp":2.04,"tv":1313.85,"id":7412952}]}]}
{"op":"mcm","clk":"1004479746","pt":1580630750813,"mc":[{"id":"1.168209731","rc":[{"batl":[[1,1.98,5.02]],"ltp":1.96,"tv":2036.39,"id":8174357}]}]}
{"op":"mcm","clk":"1004479798","pt":1580630751895,"mc":[{"id":"1.168209731","rc":[{"batl":[[1,1.98,5.25],[2,1.99,3]],"ltp":1.96,"tv":2036.39,"id":8174357},{"batb":[[0,2.04,5.28]],"ltp":2.04,"tv":1313.85,"id":7412952}]}]}
{"op":"mcm","clk":"1004479838","pt":1580630752567,"mc":[{"id":"1.168209731","rc":[{"batl":[[1,1.98,3],[2,1.99,5.16]],"ltp":1.96,"tv":2036.39,"id":8174357}]}]}
{"op":"mcm","clk":"1004480780","pt":1580630772947,"mc":[{"id":"1.168209731","rc":[{"batl":[[0,1.96,4.28],[1,1.97,12.4],[2,1.98,5.25]],"ltp":1.96,"tv":2036.39,"id":8174357}]}]}
{"op":"mcm","clk":"1004480826","pt":1580630773928,"mc":[{"id":"1.168209731","rc":[{"batl":[[0,1.96,4.07],[2,1.98,3]],"ltp":1.96,"tv":2036.39,"id":8174357},{"batb":[[0,2.04,5.07]],"ltp":2.04,"tv":1313.85,"id":7412952}]}]}
{"op":"mcm","clk":"1004480856","pt":1580630774754,"mc":[{"id":"1.168209731","rc":[{"batl":[[0,1.97,12.4],[1,1.98,3],[2,1.99,5.32]],"ltp":1.96,"tv":2036.39,"id":8174357},{"batb":[[0,2.04,5.08],[2,2,5]],"ltp":2.04,"tv":1313.85,"id":7412952}]}]}
{"op":"mcm","clk":"1004480864","pt":1580630774960,"mc":[{"id":"1.168209731","rc":[{"batb":[[2,2,7]],"ltp":2.04,"tv":1313.85,"id":7412952}]}]}
{"op":"mcm","clk":"1004481719","pt":1580630795884,"mc":[{"id":"1.168209731","rc":[{"batl":[[2,1.99,5.26]],"ltp":1.96,"tv":2036.39,"id":8174357}]}]}
{"op":"mcm","clk":"1004482554","pt":1580630816895,"mc":[{"id":"1.168209731","rc":[{"batl":[[1,1.98,5.1],[2,1.99,5.35]],"ltp":1.96,"tv":2036.39,"id":8174357}]}]}
{"op":"mcm","clk":"1004482576","pt":1580630817407,"mc":[{"id":"1.168209731","rc":[{"batl":[[1,1.98,3]],"ltp":1.96,"tv":2036.39,"id":8174357},{"batb":[[0,2.04,5]],"ltp":2.04,"tv":1313.85,"id":7412952}]}]}
{"op":"mcm","clk":"1004483418","pt":1580630837940,"mc":[{"id":"1.168209731","rc":[{"batl":[[0,1.96,4.31],[1,1.97,12.4],[2,1.98,5.25]],"ltp":1.96,"tv":2036.39,"id":8174357}]}]}
{"op":"mcm","clk":"1004483457","pt":1580630838868,"mc":[{"id":"1.168209731","rc":[{"batl":[[0,1.97,12.4],[1,1.98,3],[2,1.99,5.16]],"ltp":1.96,"tv":2036.39,"id":8174357},{"batb":[[0,2.04,5.1]],"ltp":2.04,"tv":1313.85,"id":7412952}]}]}
{"op":"mcm","clk":"1004483461","pt":1580630839025,"mc":[{"id":"1.168209731","rc":[{"batb":[[2,2,9]],"ltp":2.04,"tv":1313.85,"id":7412952}]}]}
{"op":"mcm","clk":"1004484286","pt":1580630859892,"mc":[{"id":"1.168209731","rc":[{"batl":[[2,1.99,5.34]],"ltp":1.96,"tv":2036.39,"id":8174357},{"batb":[[0,2.02,35.86],[1,2,7],[2,1.99,2]],"ltp":2.04,"tv":1313.85,"id":7412952}]}]}
{"op":"mcm","clk":"1004484309","pt":1580630860359,"mc":[{"id":"1.168209731","rc":[{"batb":[[0,2.04,5.21],[1,2.02,35.86],[2,2,7]],"ltp":2.04,"tv":1313.85,"id":7412952}]}]}
{"op":"mcm","clk":"1004485174","pt":1580630881908,"mc":[{"id":"1.168209731","rc":[{"batl":[[1,1.98,5.11],[2,1.99,3]],"ltp":1.96,"tv":2036.39,"id":8174357}]}]}
{"op":"mcm","clk":"1004485194","pt":1580630882217,"mc":[{"id":"1.168209731","rc":[{"batl":[[1,1.98,3],[2,1.99,5.33]],"ltp":1.96,"tv":2036.39,"id":8174357}]}]}
{"op":"mcm","clk":"1004486001","pt":1580630902845,"mc":[{"id":"1.168209731","rc":[{"batl":[[0,1.96,4.01],[1,1.97,12.4],[2,1.98,5.09]],"ltp":1.96,"tv":2036.39,"id":8174357}]}]}
{"op":"mcm","clk":"1004486055","pt":1580630903925,"mc":[{"id":"1.168209731","rc":[{"batl":[[0,1.97,12.4],[1,1.98,3],[2,1.99,5]],"ltp":1.96,"tv":2036.39,"id":8174357},{"batb":[[0,2.04,5.12]],"ltp":2.04,"tv":1313.85,"id":7412952}]}]}
{"op":"mcm","clk":"1004486844","pt":1580630923957,"mc":[{"id":"1.168209731","rc":[{"batl":[[0,1.96,4.13],[1,1.97,12.4],[2,1.98,5.25]],"ltp":1.96,"tv":2036.39,"id":8174357}]}]}
{"op":"mcm","clk":"1004486887","pt":1580630924784,"mc":[{"id":"1.168209731","rc":[{"batl":[[0,1.97,12.4],[1,1.98,3],[2,1.99,5.29]],"ltp":1.96,"tv":2036.39,"id":8174357},{"batb":[[0,2.04,5.24],[2,2,5]],"ltp":2.04,"tv":1313.85,"id":7412952}]}]}
{"op":"mcm","clk":"1004486896","pt":1580630924989,"mc":[{"id":"1.168209731","rc":[{"batb":[[2,2,7]],"ltp":2.04,"tv":1313.85,"id":7412952}]}]}
{"op":"mcm","clk":"1004487716","pt":1580630945826,"mc":[{"id":"1.168209731","rc":[{"batb":[[0,1.94,22.94]],"batl":[[2,1.99,5.07]],"ltp":1.96,"tv":2036.39,"id":8174357},{"batb":[[0,2.02,35.86],[1,2,7],[2,1.99,2]],"ltp":2.04,"tv":1313.85,"id":7412952}]}]}
{"op":"mcm","clk":"1004487736","pt":1580630946236,"mc":[{"id":"1.168209731","rc":[{"batb":[[0,1.94,8.94]],"ltp":1.96,"tv":2036.39,"id":8174357},{"batb":[[0,2.04,5],[1,2.02,35.86],[2,2,7]],"ltp":2.04,"tv":1313.85,"id":7412952}]}]}
{"op":"mcm","clk":"1004488659","pt":1580630966863,"mc":[{"id":"1.168209731","rc":[{"batb":[[0,1.94,22.94]],"ltp":1.96,"tv":2036.39,"id":8174357},{"batb":[[0,2.02,35.86],[1,2,7],[2,1.99,2]],"ltp":2.04,"tv":1313.85,"id":7412952}]}]}
{"op":"mcm","clk":"1004488682","pt":1580630967273,"mc":[{"id":"1.168209731","rc":[{"batb":[[0,1.94,8.94]],"ltp":1.96,"tv":2036.39,"id":8174357},{"batb":[[0,2.04,5.14],[1,2.02,35.86],[2,2,7]],"ltp":2.04,"tv":1313.85,"id":7412952}]}]}
{"op":"mcm","clk":"1004489706","pt":1580630987878,"mc":[{"id":"1.168209731","rc":[{"batl":[[0,1.96,4.15],[1,1.97,12.4],[2,1.98,5.25]],"ltp":1.96,"tv":2036.39,"id":8174357}]}]}
{"op":"mcm","clk":"1004489748","pt":1580630988701,"mc":[{"id":"1.168209731","rc":[{"batl":[[0,1.97,12.4],[1,1.98,3],[2,1.99,5.01]],"ltp":1.96,"tv":2036.39,"id":8174357},{"batb":[[0,2.04,5]],"ltp":2.04,"tv":1313.85,"id":7412952}]}]}
{"op":"mcm","clk":"1004490835","pt":1580631009939,"mc":[{"id":"1.168209731","rc":[{"batl":[[2,1.99,5.15]],"ltp":1.96,"tv":2036.39,"id":8174357},{"batb":[[0,2.04,5.05],[2,2,5]],"ltp":2.04,"tv":1313.85,"id":7412952}]}]}
{"op":"mcm","clk":"1004490844","pt":1580631010141,"mc":[{"id":"1.168209731","rc":[{"batb":[[2,2,7]],"ltp":2.04,"tv":1313.85,"id":7412952}]}]}
{"op":"mcm","clk":"1004491428","pt":1580631021948,"mc":[{"id":"1.168209731","rc":[{"batb":[[0,1.95,14.11],[1,1.94,22.94],[2,1.93,12]],"batl":[[0,1.97,8.4]],"ltp":1.96,"tv":2036.39,"id":8174357},{"trd":[[2.04,147.03]],"batb":[[0,2.02,35.86],[1,2,7],[2,1.99,7.11]],"batl":[[0,2.04,20.28],[1,2.06,29.14],[2,2.08,10.07]],"ltp":2.04,"tv":1323.94,"id":7412952}],"tv":3360.34}]}
{"op":"mcm","clk":"1004491451","pt":1580631022369,"mc":[{"id":"1.168209731","rc":[{"batb":[[1,1.94,25.03],[2,1.93,14]],"ltp":1.96,"tv":2036.39,"id":8174357},{"batb":[[1,2,5]],"ltp":2.04,"tv":1323.94,"id":7412952}]}]}
{"op":"mcm","clk":"1004491500","pt":1580631023349,"mc":[{"id":"1.168209731","rc":[{"batb":[[0,1.95,21.55]],"ltp":1.96,"tv":2036.39,"id":8174357}]}]}
{"op":"mcm","clk":"1004491742","pt":1580631028771,"mc":[{"id":"1.168209731","rc":[{"batb":[[2,1.93,14.08]],"ltp":1.96,"tv":2036.39,"id":8174357},{"trd":[[2.04,178.34]],"batl":[[0,2.04,4.63]],"ltp":2.04,"tv":1355.25,"id":7412952}],"tv":3391.65}]}
{"op":"mcm","clk":"1004491793","pt":1580631029780,"mc":[{"id":"1.168209731","rc":[{"trd":[[1.95,11.26]],"batb":[[0,1.94,14],[1,1.93,14.08],[2,1.92,17.82]],"batl":[[0,1.98,3],[1,1.99,3],[2,2,73.06]],"ltp":1.95,"tv":2045.01,"id":8174357},{"trd":[[2.04,187.61]],"batl":[[0,2.06,18.14],[1,2.08,8],[2,2.1,10.05]],"ltp":2.04,"tv":1364.52,"id":7412952}],"tv":3409.54}]}
{"op":"mcm","clk":"1004491839","pt":1580631030569,"mc":[{"id":"1.168209731","rc":[{"batb":[[0,1.93,19.51],[1,1.92,17.82],[2,1.91,2.06]],"batl":[[1,1.99,5.04]],"ltp":1.95,"tv":2045.01,"id":8174357},{"batb":[[0,2.04,5.16],[1,2.02,34.73],[2,2,7]],"ltp":2.04,"tv":1364.52,"id":7412952}]}]}
{"op":"mcm","clk":"1004491909","pt":1580631031803,"mc":[{"id":"1.168209731","rc":[{"batb":[[0,1.93,12]],"batl":[[0,1.96,4.17],[1,1.98,3],[2,1.99,5.04]],"ltp":1.95,"tv":2045.01,"id":8174357}]}]}
{"op":"mcm","clk":"1004491969","pt":1580631032888,"mc":[{"id":"1.168209731","rc":[{"batl":[[0,1.98,3],[1,1.99,5.04],[2,2,73.06]],"ltp":1.95,"tv":2045.01,"id":8174357},{"batb":[[0,2.04,5]],"ltp":2.04,"tv":1364.52,"id":7412952}]}]}
{"op":"mcm","clk":"1004492945","pt":1580631053939,"mc":[{"id":"1.168209731","rc":[{"batb":[[2,1.87,72.07]],"batl":[[0,1.97,4],[1,1.98,5],[2,1.99,5.04]],"ltp":1.95,"tv":2045.01,"id":8174357}]}]}
{"op":"mcm","clk":"1004492983","pt":1580631054712,"mc":[{"id":"1.168209731","rc":[{"batb":[[2,1.91,2.06]],"batl":[[1,1.98,3],[2,1.99,5.09]],"ltp":1.95,"tv":2045.01,"id":8174357}]}]}
{"op":"mcm","clk":"1004493283","pt":1580631060944,"mc":[{"id":"1.168209731","rc":[{"batb":[[0,1.94,8.94],[1,1.93,12],[2,1.92,17.82]],"batl":[[0,1.96,4],[1,1.97,12.4],[2,1.98,3]],"ltp":1.95,"tv":2045.01,"id":8174357}]}]}
{"op":"mcm","clk":"1004493343","pt":1580631061827,"mc":[{"id":"1.168209731","rc":[{"batl":[[0,1.97,12.4],[1,1.98,3],[2,1.99,5.24]],"ltp":1.95,"tv":2045.01,"id":8174357},{"batb":[[2,2,5]],"ltp":2.04,"tv":1364.52,"id":7412952}]}]}
{"op":"mcm","clk":"1004493356","pt":1580631062028,"mc":[{"id":"1.168209731","rc":[{"batb":[[2,2,7]],"ltp":2.04,"tv":1364.52,"id":7412952}]}]}
{"op":"mcm","clk":"1004494389","pt":1580631082875,"mc":[{"id":"1.168209731","rc":[{"batl":[[2,1.99,3]],"ltp":1.95,"tv":2045.01,"id":8174357}]}]}
{"op":"mcm","clk":"1004494398","pt":1580631083033,"mc":[{"id":"1.168209731","rc":[{"batl":[[2,1.99,5.35]],"ltp":1.95,"tv":2045.01,"id":8174357}]}]}
{"op":"mcm","clk":"1004512776","pt":1580631518922,"mc":[{"id":"1.168209731","rc":[{"trd":[[1.97,23.54]],"batb":[[0,1.97,9.84],[1,1.96,20.4],[2,1.95,16.21]],"batl":[[0,2,71.06],[1,2.02,2],[2,2.04,2]],"ltp":1.97,"tv":2068.55,"id":8174357},{"trd":[[2.04,207.61]],"batb":[[0,2.02,30.73],[1,2,5],[2,1.99,7.11]],"batl":[[0,2.04,295.07],[1,2.06,29.14],[2,2.08,10.19]],"ltp":2.04,"tv":1384.52,"id":7412952}],"tv":3453.08}]}
{"op":"mcm","clk":"1004512795","pt":1580631519332,"mc":[{"id":"1.168209731","rc":[{"trd":[[1.97,43.22]],"batb":[[0,1.96,20.4],[1,1.95,14.21],[2,1.94,24.94]],"ltp":1.97,"tv":2088.23,"id":8174357}],"tv":3472.76}]}
{"op":"mcm","clk":"1004513081","pt":1580631525906,"mc":[{"id":"1.168209731","rc":[{"batb":[[2,1.94,16]],"ltp":1.97,"tv":2088.23,"id":8174357}]}]}
{"op":"mcm","clk":"1004513128","pt":1580631526936,"mc":[{"id":"1.168209731","rc":[{"trd":[[1.97,69.72]],"batb":[[1,1.95,10],[2,1.94,14.18]],"batl":[[0,1.97,13.25],[1,1.99,2.17],[2,2,73.06]],"ltp":1.97,"tv":2114.73,"id":8174357},{"batl":[[0,2.04,284.07]],"ltp":2.04,"tv":1384.52,"id":7412952}],"tv":3499.26}]}
{"op":"mcm","clk":"1004513153","pt":1580631527448,"mc":[{"id":"1.168209731","rc":[{"batl":[[0,2,71.06],[1,2.02,2.25],[2,2.04,2]],"ltp":1.97,"tv":2114.73,"id":8174357},{"batl":[[0,2.04,293.07]],"ltp":2.04,"tv":1384.52,"id":7412952}]}]}
{"op":"mcm","clk":"1004513265","pt":1580631529918,"mc":[{"id":"1.168209731","rc":[{"trd":[[1.98,4.27]],"batb":[[0,1.98,14],[1,1.97,14.27],[2,1.96,9.53]],"batl":[[0,2,68.06],[1,2.02,6]],"ltp":1.98,"tv":2119.0,"id":8174357},{"trd":[[2.02,468.17]],"batb":[[0,1.99,5.11],[1,1.98,9.27],[2,1.97,2.17]],"batl":[[0,2.02,118.91],[1,2.04,12.27],[2,2.06,31.39]],"ltp":2.02,"tv":1734.65,"id":7412952}],"tv":3853.66}]}
{"op":"mcm","clk":"1004513304","pt":1580631530952,"mc":[{"id":"1.168209731","rc":[{"batb":[[2,1.96,2.13]],"ltp":1.98,"tv":2119.0,"id":8174357}]}]}
{"op":"mcm","clk":"1004513313","pt":1580631531152,"mc":[{"id":"1.168209731","rc":[{"batb":[[0,1.99,7.28],[1,1.98,14],[2,1.97,16.44]],"ltp":1.98,"tv":2119.0,"id":8174357},{"batb":[[2,1.97,9.45]],"ltp":2.02,"tv":1734.65,"id":7412952}]}]}
{"op":"mcm","clk":"1004513796","pt":1580631541873,"mc":[{"id":"1.168209731","rc":[{"trd":[[1.99,6.06]],"batb":[[0,1.99,4.25]],"batl":[[2,2.04,8]],"ltp":1.99,"tv":2125.06,"id":8174357},{"batb":[[1,1.98,43.21]],"ltp":2.02,"tv":1734.65,"id":7412952}],"tv":3859.72}]}
{"op":"mcm","clk":"1004513812","pt":1580631542134,"mc":[{"id":"1.168209731","rc":[{"batb":[[2,1.97,9.28]],"ltp":2.02,"tv":1734.65,"id":7412952}]}]}
{"op":"mcm","clk":"1004515143","pt":1580631570894,"mc":[{"id":"1.168209731","rc":[{"batb":[[2,1.97,7.28]],"batl":[[0,2.04,12.27],[1,2.06,31.39],[2,2.08,12]],"ltp":2.02,"tv":1734.65,"id":7412952}]}]}
{"op":"mcm","clk":"1004515201","pt":1580631571921,"mc":[{"id":"1.168209731","rc":[{"trd":[[1.99,14.13]],"batb":[[0,1.99,3.03]],"ltp":1.99,"tv":2133.13,"id":8174357},{"batb":[[2,1.97,9.45]],"batl":[[2,2.08,14]],"ltp":2.02,"tv":1734.65,"id":7412952}],"tv":3867.79}]}
{"op":"mcm","clk":"1004515573","pt":1580631579895,"mc":[{"id":"1.168209731","rc":[{"trd":[[2,68.06]],"batl":[[0,2.02,6],[1,2.04,8],[2,2.06,2.25]],"ltp":2.0,"tv":2201.19,"id":8174357},{"trd":[[2,68.06]],"batl":[[0,2,38.86],[1,2.04,12.27],[2,2.06,31.39]],"ltp":2.0,"tv":1802.71,"id":7412952}],"tv":4003.9}]}
{"op":"mcm","clk":"1004515623","pt":1580631580925,"mc":[{"id":"1.168209731","rc":[{"batb":[[0,2,14],[1,1.99,17.24],[2,1.98,16]],"batl":[[0,2.04,6],[1,2.06,6.21],[2,2.08,2]],"ltp":2.0,"tv":2201.19,"id":8174357},{"batb":[[0,1.98,33.94],[1,1.97,7.28],[2,1.96,10]],"batl":[[0,2,51.86],[1,2.02,12.21],[2,2.04,14.4]],"ltp":2.0,"tv":1802.71,"id":7412952}]}]}
{"op":"mcm","clk":"1004516601","pt":1580631602733,"mc":[{"id":"1.168209731","rc":[{"batb":[[1,1.99,14.21]],"ltp":2.0,"tv":2201.19,"id":8174357},{"batl":[[2,2.04,25]],"ltp":2.0,"tv":1802.71,"id":7412952}]}]}
{"op":"mcm","clk":"1004517729","pt":1580631625836,"mc":[{"id":"1.168209731","rc":[{"batl":[[2,2.04,14.4]],"ltp":2.0,"tv":1802.71,"id":7412952}]}]}
{"op":"mcm","clk":"1004518034","pt":1580631632888,"mc":[{"id":"1.168209731","rc":[{"batb":[[0,2,17]],"ltp":2.0,"tv":2201.19,"id":8174357}]}]}
{"op":"mcm","clk":"1004519137","pt":1580631655913,"mc":[{"id":"1.168209731","rc":[{"trd":[[1.98,22.72]],"batb":[[0,1.96,10],[1,1.95,8.41],[2,1.83,45.62]],"ltp":1.98,"tv":1825.42,"id":7412952}],"tv":4026.61}]}
{"op":"mcm","clk":"1004519182","pt":1580631656786,"mc":[{"id":"1.168209731","rc":[{"batl":[[0,2.06,6.21],[1,2.1,2.05],[2,2.12,2.21]],"ltp":2.0,"tv":2201.19,"id":8174357},{"batb":[[0,1.96,40.42],[1,1.95,6.3],[2,1.94,2.09]],"batl":[[0,1.99,12.3],[1,2,51.86],[2,2.02,14.21]],"ltp":1.98,"tv":1825.42,"id":7412952}]}]}
{"op":"mcm","clk":"1004519286","pt":1580631658894,"mc":[{"id":"1.168209731","rc":[{"batb":[[0,2.02,13.31],[1,2,17],[2,1.99,16.21]],"ltp":2.0,"tv":2201.19,"id":8174357}]}]}
{"op":"mcm","clk":"1004519318","pt":1580631659716,"mc":[{"id":"1.168209731","rc":[{"batb":[[0,2,17],[1,1.99,14.21],[2,1.98,16]],"ltp":2.0,"tv":2201.19,"id":8174357}]}]}
{"op":"mcm","clk":"1004519634","pt":1580631665894,"mc":[{"id":"1.168209731","rc":[{"batb":[[0,2.02,13],[1,2,17],[2,1.99,16.21]],"batl":[[1,2.08,5.02],[2,2.1,2.05]],"ltp":2.0,"tv":2201.19,"id":8174357},{"batb":[[2,1.94,8.09]],"batl":[[0,1.98,50.86],[1,1.99,12],[2,2,15]],"ltp":1.98,"tv":1825.42,"id":7412952}]}]}
{"op":"mcm","clk":"1004519804","pt":1580631668877,"mc":[{"id":"1.168209731","rc":[{"batb":[[2,1.99,41.58]],"ltp":2.0,"tv":2201.19,"id":8174357},{"trd":[[1.98,68.05]],"batb":[[0,1.95,6.3],[1,1.94,6],[2,1.93,53.51]],"batl":[[0,1.98,28.19]],"ltp":1.98,"tv":1870.76,"id":7412952}],"tv":4071.95}]}
{"op":"mcm","clk":"1004519826","pt":1580631669391,"mc":[{"id":"1.168209731","rc":[{"batl":[[0,2.06,5]],"ltp":2.0,"tv":2201.19,"id":8174357},{"batb":[[0,1.95,6],[1,1.93,53.51],[2,1.92,2.19]],"ltp":1.98,"tv":1870.76,"id":7412952}]}]}
{"op":"mcm","clk":"1004520949","pt":1580631695644,"mc":[{"id":"1.168209731","rc":[{"batb":[[1,2,14]],"ltp":2.0,"tv":2201.19,"id":8174357}]}]}
{"op":"mcm","clk":"1004522423","pt":1580631727580,"mc":[{"id":"1.168209731","rc":[{"batb":[[2,1.92,2]],"batl":[[0,1.98,12]],"ltp":1.98,"tv":1870.76,"id":7412952}]}]}
{"op":"mcm","clk":"1004524702","pt":1580631784838,"mc":[{"id":"1.168209731","rc":[{"batb":[[2,1.92,2.19]],"ltp":1.98,"tv":1870.76,"id":7412952}]}]}
{"op":"mcm","clk":"1004525072","pt":1580631796923,"mc":[{"id":"1.168209731","rc":[{"batb":[[0,2,14],[1,1.99,14.21],[2,1.98,50.3]],"batl":[[0,2.06,3],[1,2.08,3]],"ltp":2.0,"tv":2201.19,"id":8174357},{"batl":[[0,1.99,12],[1,2,13],[2,2.02,2.25]],"ltp":1.98,"tv":1870.76,"id":7412952}]}]}
{"op":"mcm","clk":"1004525177","pt":1580631799844,"mc":[{"id":"1.168209731","rc":[{"batb":[[0,1.96,12.4],[1,1.95,6],[2,1.94,2.09]],"ltp":1.98,"tv":1870.76,"id":7412952}]}]}
{"op":"mcm","clk":"1004525330","pt":1580631803840,"mc":[{"id":"1.168209731","rc":[{"batb":[[0,1.97,8.4],[1,1.96,12.4],[2,1.95,8.11]],"ltp":1.98,"tv":1870.76,"id":7412952}]}]}
{"op":"mcm","clk":"1004525357","pt":1580631804764,"mc":[{"id":"1.168209731","rc":[{"batl":[[1,2.08,5.07]],"ltp":2.0,"tv":2201.19,"id":8174357}]}]}
{"op":"mcm","clk":"1004525441","pt":1580631806868,"mc":[{"id":"1.168209731","rc":[{"batl":[[0,2.04,3],[1,2.06,3],[2,2.08,5.07]],"ltp":2.0,"tv":2201.19,"id":8174357},{"batb":[[0,1.98,8.4],[1,1.97,8.4],[2,1.96,14.53]],"batl":[[0,2,13],[1,2.02,12.25],[2,2.04,2]],"ltp":1.98,"tv":1870.76,"id":7412952}]}]}
{"op":"mcm","clk":"1004525453","pt":1580631807123,"mc":[{"id":"1.168209731","rc":[{"batl":[[1,2.02,10]],"ltp":1.98,"tv":1870.76,"id":7412952}]}]}
{"op":"mcm","clk":"1004525565","pt":1580631809837,"mc":[{"id":"1.168209731","rc":[{"batb":[[0,1.97,8.4],[1,1.96,12.4],[2,1.95,8.11]],"ltp":1.98,"tv":1870.76,"id":7412952}]}]}
{"op":"mcm","clk":"1004525607","pt":1580631810762,"mc":[{"id":"1.168209731","rc":[{"batb":[[0,1.96,12.4],[1,1.95,8.11],[2,1.94,2.09]],"ltp":1.98,"tv":1870.76,"id":7412952}]}]}
{"op":"mcm","clk":"1004525645","pt":1580631811528,"mc":[{"id":"1.168209731","rc":[{"batl":[[0,2.06,3],[1,2.08,3],[2,2.1,2.05]],"ltp":2.0,"tv":2201.19,"id":8174357},{"batb":[[1,1.95,6]],"ltp":1.98,"tv":1870.76,"id":7412952}]}]}
{"op":"mcm","clk":"1004525777","pt":1580631814868,"mc":[{"id":"1.168209731","rc":[{"trd":[[2,109.03]],"batb":[[0,1.98,34.04],[1,1.97,8],[2,1.96,8.13]],"batl":[[0,2,23.68],[1,2.02,4.18],[2,2.04,6.31]],"ltp":2.0,"tv":2242.16,"id":8174357},{"trd":[[2,81.06]],"batb":[[0,1.99,5.18],[1,1.98,7.44],[2,1.97,7.35]],"batl":[[0,2.04,5],[1,2.06,7.27],[2,2.08,2.19]],"ltp":2.0,"tv":1883.76,"id":7412952}],"tv":4125.92}]}
{"op":"mcm","clk":"1004525782","pt":1580631814970,"mc":[{"id":"1.168209731","rc":[{"batb":[[1,1.97,6]],"ltp":2.0,"tv":2242.16,"id":8174357},{"batl":[[1,2.06,5.18]],"ltp":2.0,"tv":1883.76,"id":7412952}]}]}
{"op":"mcm","clk":"1004526050","pt":1580631821946,"mc":[{"id":"1.168209731","rc":[{"trd":[[1.99,22.23]],"batl":[[0,2,4],[1,2.02,6.18]],"ltp":1.99,"tv":2250.26,"id":8174357},{"trd":[[2.02,476.15]],"batb":[[0,2,5.42],[1,1.99,7.18],[2,1.98,7.44]],"batl":[[2,2.08,7.41]],"ltp":2.02,"tv":1891.74,"id":7412952}],"tv":4142.0}]}
{"op":"mcm","clk":"1004526099","pt":1580631822767,"mc":[{"id":"1.168209731","rc":[{"batb":[[0,1.99,6.23],[1,1.98,40.04],[2,1.97,8]],"batl":[[0,2.04,4.18],[1,2.06,5.25],[2,2.08,5.07]],"ltp":1.99,"tv":2250.26,"id":8174357},{"trd":[[2.02,476.99]],"batb":[[0,1.97,5.18],[1,1.96,10.53],[2,1.95,2.11]],"batl":[[0,2.02,4.81],[1,2.04,5],[2,2.06,7.43]],"ltp":2.02,"tv":1892.58,"id":7412952}],"tv":4142.84}]}
{"op":"mcm","clk":"1004526122","pt":1580631823281,"mc":[{"id":"1.168209731","rc":[{"batl":[[1,2.06,3]],"ltp":1.99,"tv":2250.26,"id":8174357},{"batb":[[1,1.96,8.4]],"ltp":2.02,"tv":1892.58,"id":7412952}]}]}
{"op":"mcm","clk":"1004526216","pt":1580631825744,"mc":[{"id":"1.168209731","rc":[{"batb":[[0,1.96,5],[1,1.94,2.09],[2,1.93,47.47]],"ltp":2.02,"tv":1892.58,"id":7412952}]}]}
{"op":"mcm","clk":"1004526335","pt":1580631828890,"mc":[{"id":"1.168209731","rc":[{"trd":[[1.98,42.49],[1.99,34.68]],"batb":[[0,1.98,14.92],[1,1.97,6],[2,1.96,8]],"ltp":1.98,"tv":2300.93,"id":8174357},{"batl":[[0,2.04,5],[1,2.06,5.18],[2,2.08,2]],"ltp":2.02,"tv":1892.58,"id":7412952}],"tv":4193.52}]}
{"op":"mcm","clk":"1004526382","pt":1580631829866,"mc":[{"id":"1.168209731","rc":[{"batb":[[0,1.97,6],[1,1.96,8],[2,1.95,50.2]],"ltp":1.98,"tv":2300.93,"id":8174357},{"batb":[[1,1.95,45.98],[2,1.94,2.09]],"ltp":2.02,"tv":1892.58,"id":7412952}]}]}
{"op":"mcm","clk":"1004526391","pt":1580631830071,"mc":[{"id":"1.168209731","rc":[{"batb":[[1,1.96,6]],"ltp":1.98,"tv":2300.93,"id":8174357}]}]}
{"op":"mcm","clk":"1004528081","pt":1580631864634,"mc":[{"id":"1.168209731","rc":[{"batb":[[0,1.96,6],[1,1.95,48.09],[2,1.94,2.09]],"ltp":1.98,"tv":2300.93,"id":8174357},{"batl":[[0,2.04,13.4]],"ltp":2.02,"tv":1892.58,"id":7412952}]}]}
{"op":"mcm","clk":"1004528131","pt":1580631865603,"mc":[{"id":"1.168209731","rc":[{"batb":[[0,1.98,5.13],[1,1.97,4.2],[2,1.96,7.13]],"ltp":2.02,"tv":1892.58,"id":7412952}]}]}
{"op":"mcm","clk":"1004531254","pt":1580631926776,"mc":[{"id":"1.168209731","rc":[{"batb":[[0,1.97,5.14],[1,1.96,14.75],[2,1.95,50.09]],"ltp":1.98,"tv":2300.93,"id":8174357}]}]}
{"op":"mcm","clk":"1004531362","pt":1580631928780,"mc":[{"id":"1.168209731","rc":[{"trd":[[1.96,74.12],[1.97,80]],"batb":[[0,1.97,4.15],[1,1.95,50.09],[2,1.94,2]],"batl":[[0,2.04,7],[1,2.06,6],[2,2.08,8.07]],"ltp":1.96,"tv":2346.15,"id":8174357},{"trd":[[2.04,212.85]],"batb":[[0,1.98,8],[2,1.96,10.13]],"batl":[[0,2.04,11.16],[1,2.06,3]],"ltp":2.04,"tv":1897.83,"id":7412952}],"tv":4243.99}]}
{"op":"mcm","clk":"1004532778","pt":1580631957900,"mc":[{"id":"1.168209731","rc":[{"batb":[[2,1.92,2.63]],"batl":[[0,2.02,7.31],[1,2.04,7],[2,2.06,6]],"ltp":1.96,"tv":2346.15,"id":8174357},{"batb":[[0,1.98,16.57]],"ltp":2.04,"tv":1897.83,"id":7412952}]}]}
{"op":"mcm","clk":"1004532814","pt":1580631958618,"mc":[{"id":"1.168209731","rc":[{"batb":[[0,1.96,4],[1,1.95,48.09],[2,1.94,2.09]],"batl":[[2,2.06,8.25]],"ltp":1.96,"tv":2346.15,"id":8174357},{"batl":[[0,2.04,8.16]],"ltp":2.04,"tv":1897.83,"id":7412952}]}]}
{"op":"mcm","clk":"1004533329","pt":1580631967941,"mc":[{"id":"1.168209731","rc":[{"batb":[[0,1.95,48.09],[1,1.94,2.09],[2,1.93,2]],"ltp":1.96,"tv":2346.15,"id":8174357},{"batb":[[1,1.96,10.13],[2,1.95,48.09]],"ltp":2.04,"tv":1897.83,"id":7412952}]}]}
{"op":"mcm","clk":"1004533345","pt":1580631968199,"mc":[{"id":"1.168209731","rc":[{"batb":[[1,1.94,2]],"ltp":1.96,"tv":2346.15,"id":8174357}]}]}
{"op":"mcm","clk":"1004533727","pt":1580631974946,"mc":[{"id":"1.168209731","rc":[{"batb":[[0,1.96,3.12],[1,1.95,48.09],[2,1.94,2]],"ltp":1.96,"tv":2346.15,"id":8174357}]}]}
{"op":"mcm","clk":"1004534652","pt":1580631989632,"mc":[{"id":"1.168209731","rc":[{"batb":[[0,1.96,15.87]],"batl":[[0,2.02,15.71]],"ltp":1.96,"tv":2346.15,"id":8174357},{"batb":[[0,1.99,8.15],[1,1.98,16.57],[2,1.97,2]],"batl":[[0,2.04,11.16]],"ltp":2.04,"tv":1897.83,"id":7412952}]}]}
{"op":"mcm","clk":"1004535714","pt":1580632009760,"mc":[{"id":"1.168209731","rc":[{"batb":[[0,1.97,4.16],[1,1.96,15.87],[2,1.95,50.2]],"ltp":1.96,"tv":2346.15,"id":8174357}]}]}
{"op":"mcm","clk":"1004536103","pt":1580632020774,"mc":[{"id":"1.168209731","rc":[{"batb":[[1,1.96,7.12]],"ltp":1.96,"tv":2346.15,"id":8174357}]}]}
{"op":"mcm","clk":"1004536143","pt":1580632021800,"mc":[{"id":"1.168209731","rc":[{"batb":[[0,1.97,12.82]],"ltp":1.96,"tv":2346.15,"id":8174357},{"batb":[[0,1.99,16.64],[1,1.98,8]],"ltp":2.04,"tv":1897.83,"id":7412952}]}]}
{"op":"mcm","clk":"1004536704","pt":1580632036832,"mc":[{"id":"1.168209731","rc":[{"batb":[[1,1.96,4]],"ltp":1.96,"tv":2346.15,"id":8174357}]}]}
{"op":"mcm","clk":"1004538445","pt":1580632083894,"mc":[{"id":"1.168209731","rc":[{"trd":[[1.99,30.29]],"batb":[[0,1.99,7.49],[2,1.96,2.13]],"ltp":1.99,"tv":1928.12,"id":7412952}],"tv":4274.28}]}
{"op":"mcm","clk":"1004538468","pt":1580632084568,"mc":[{"id":"1.168209731","rc":[{"batb":[[2,1.97,2]],"ltp":1.99,"tv":1928.12,"id":7412952}]}]}
{"op":"mcm","clk":"1004540759","pt":1580632143524,"mc":[{"id":"1.168209731","rc":[{"trd":[[1.97,100.27]],"batb":[[0,1.97,6.68]],"ltp":1.97,"tv":2366.43,"id":8174357}],"tv":4294.55}]}
{"op":"mcm","clk":"1004540924","pt":1580632147946,"mc":[{"id":"1.168209731","rc":[{"batb":[[0,1.97,4]],"ltp":1.97,"tv":2366.43,"id":8174357},{"batb":[[0,1.99,14.49]],"ltp":1.99,"tv":1928.12,"id":7412952}]}]}
{"op":"mcm","clk":"1004540938","pt":1580632148155,"mc":[{"id":"1.168209731","rc":[{"batb":[[0,1.97,12.66]],"ltp":1.97,"tv":2366.43,"id":8174357}]}]}
{"op":"mcm","clk":"1004541451","pt":1580632161389,"mc":[{"id":"1.168209731","rc":[{"batb":[[0,1.97,15.75]],"ltp":1.97,"tv":2366.43,"id":8174357}]}]}
{"op":"mcm","clk":"1004542164","pt":1580632183615,"mc":[{"id":"1.168209731","rc":[{"batb":[[2,1.95,92.06]],"ltp":1.97,"tv":2366.43,"id":8174357}]}]}
{"op":"mcm","clk":"1004542432","pt":1580632189784,"mc":[{"id":"1.168209731","rc":[{"batb":[[0,1.98,4.27],[1,1.97,15.75],[2,1.96,6]],"batl":[[0,2.02,12.4],[1,2.04,4]],"ltp":1.97,"tv":2366.43,"id":8174357},{"trd":[[1.99,42.05]],"batb":[[0,1.99,8.49],[1,1.98,5]],"ltp":1.99,"tv":1939.88,"id":7412952}],"tv":4306.31}]}
{"op":"mcm","clk":"1004542570","pt":1580632192822,"mc":[{"id":"1.168209731","rc":[{"batb":[[1,1.97,12.66]],"ltp":1.97,"tv":2366.43,"id":8174357}]}]}
{"op":"mcm","clk":"1004543412","pt":1580632210941,"mc":[{"id":"1.168209731","rc":[{"batl":[[0,2.02,4]],"ltp":1.97,"tv":2366.43,"id":8174357},{"batl":[[0,2.02,3.05],[1,2.04,11.16],[2,2.06,3]],"ltp":1.99,"tv":1939.88,"id":7412952}]}]}
{"op":"mcm","clk":"1004543443","pt":1580632211816,"mc":[{"id":"1.168209731","rc":[{"batb":[[1,1.97,4]],"ltp":1.97,"tv":2366.43,"id":8174357},{"batl":[[0,2.04,3],[1,2.06,3],[2,2.08,2]],"ltp":1.99,"tv":1939.88,"id":7412952}]}]}
{"op":"mcm","clk":"1004543495","pt":1580632212845,"mc":[{"id":"1.168209731","rc":[{"batb":[[0,1.97,6],[1,1.96,6],[2,1.95,91.95]],"batl":[[0,2.04,4],[1,2.06,6],[2,2.08,8.07]],"ltp":1.97,"tv":2366.43,"id":8174357},{"batb":[[0,1.97,5.06],[1,1.95,93.97],[2,1.94,2.09]],"batl":[[1,2.06,5.25]],"ltp":1.99,"tv":1939.88,"id":7412952}]}]}
{"op":"mcm","clk":"1004543504","pt":1580632213050,"mc":[{"id":"1.168209731","rc":[{"batb":[[0,1.97,4],[1,1.96,4]],"ltp":1.97,"tv":2366.43,"id":8174357},{"batl":[[1,2.06,3]],"ltp":1.99,"tv":1939.88,"id":7412952}]}]}
{"op":"mcm","clk":"1004543946","pt":1580632222753,"mc":[{"id":"1.168209731","rc":[{"batb":[[0,1.97,7.09]],"ltp":1.97,"tv":2366.43,"id":8174357}]}]}
{"op":"mcm","clk":"1004544412","pt":1580632234147,"mc":[{"id":"1.168209731","rc":[{"batb":[[2,1.94,2]],"ltp":1.99,"tv":1939.88,"id":7412952}]}]}
{"op":"mcm","clk":"1004545051","pt":1580632247877,"mc":[{"id":"1.168209731","rc":[{"batb":[[0,1.97,3.09],[1,1.95,91.95],[2,1.94,2.09]],"batl":[[0,2.02,5.26],[1,2.04,559.37],[2,2.06,8.09]],"ltp":1.97,"tv":2366.43,"id":8174357},{"batb":[[0,1.99,6.26],[1,1.97,7.23],[2,1.96,2.13]],"batl":[[0,2.06,3],[1,2.08,2],[2,2.1,2.05]],"ltp":1.99,"tv":1939.88,"id":7412952}]}]}
{"op":"mcm","clk":"1004545501","pt":1580632257874,"mc":[{"id":"1.168209731","rc":[{"batb":[[1,1.96,5.31],[2,1.95,91.95]],"batl":[[0,2,7],[1,2.02,5.26],[2,2.04,559.37]],"ltp":1.97,"tv":2366.43,"id":8174357},{"trd":[[2,87.11]],"batb":[[0,2,8.31],[1,1.99,8.31],[2,1.98,7.31]],"batl":[[0,2.04,5],[1,2.06,5],[2,2.08,2]],"ltp":2.0,"tv":1945.94,"id":7412952}],"tv":4312.37}]}
{"op":"mcm","clk":"1004545584","pt":1580632259884,"mc":[{"id":"1.168209731","rc":[{"batb":[[1,1.95,91.95],[2,1.94,2.09]],"batl":[[2,2.04,561.37]],"ltp":1.97,"tv":2366.43,"id":8174357},{"batb":[[2,1.98,9.57]],"batl":[[0,2.06,5],[1,2.08,2],[2,2.1,2]],"ltp":2.0,"tv":1945.94,"id":7412952}]}]}
{"op":"mcm","clk":"1004545647","pt":1580632260913,"mc":[{"id":"1.168209731","rc":[{"batb":[[0,1.98,7],[1,1.97,8.24],[2,1.96,599.9]],"batl":[[0,2.02,5.26],[1,2.04,561.37],[2,2.06,8]],"ltp":1.97,"tv":2366.43,"id":8174357},{"batb":[[0,1.98,9.57],[1,1.97,10],[2,1.95,91.97]],"batl":[[0,2.04,5],[1,2.06,5],[2,2.08,2.19]],"ltp":2.0,"tv":1945.94,"id":7412952}]}]}
{"op":"mcm","clk":"1004545684","pt":1580632261688,"mc":[{"id":"1.168209731","rc":[{"batb":[[0,1.97,16.24],[1,1.96,599.9],[2,1.95,91.95]],"batl":[[0,2.02,8],[1,2.04,562.37]],"ltp":1.97,"tv":2366.43,"id":8174357},{"batb":[[0,1.98,7.31],[1,1.97,8],[2,1.96,2]],"ltp":2.0,"tv":1945.94,"id":7412952}]}]}
{"op":"mcm","clk":"1004545834","pt":1580632264783,"mc":[{"id":"1.168209731","rc":[{"batb":[[0,1.98,10.28],[1,1.97,18.41],[2,1.96,599.9]],"ltp":1.97,"tv":2366.43,"id":8174357},{"batl":[[0,2,10.08],[1,2.02,6.02],[2,2.04,7.13]],"ltp":2.0,"tv":1945.94,"id":7412952}]}]}
{"op":"mcm","clk":"1004546188","pt":1580632271899,"mc":[{"id":"1.168209731","rc":[{"trd":[[1.98,42.61],[2,119.1]],"batb":[[0,1.97,23.24],[1,1.96,602.03],[2,1.95,100.84]],"batl":[[0,2.02,13],[1,2.04,568.37],[2,2.06,14]],"ltp":1.98,"tv":2376.62,"id":8174357},{"trd":[[2,97.2]],"batb":[[0,1.98,16],[1,1.97,16]],"batl":[[0,2.04,11],[1,2.06,13.25],[2,2.08,2.19]],"ltp":2.0,"tv":1956.02,"id":7412952}],"tv":4332.65}]}
{"op":"mcm","clk":"1004546226","pt":1580632272723,"mc":[{"id":"1.168209731","rc":[{"batb":[[1,1.96,599.9]],"ltp":1.98,"tv":2376.62,"id":8174357},{"batl":[[1,2.06,11]],"ltp":2.0,"tv":1956.02,"id":7412952}]}]}
{"op":"mcm","clk":"1004546616","pt":1580632279850,"mc":[{"id":"1.168209731","rc":[{"trd":[[1.97,140.81]],"batb":[[0,1.97,2.96]],"ltp":1.97,"tv":2417.16,"id":8174357}],"tv":4373.19}]}
{"op":"mcm","clk":"1004546852","pt":1580632284948,"mc":[{"id":"1.168209731","rc":[{"batb":[[1,1.96,614.9]],"batl":[[0,1.99,3.06],[1,2.02,15],[2,2.04,570.5]],"ltp":1.97,"tv":2417.16,"id":8174357},{"batb":[[0,2,18.13],[1,1.99,18.13],[2,1.98,16]],"ltp":2.0,"tv":1956.02,"id":7412952}]}]}
{"op":"mcm","clk":"1004546912","pt":1580632285929,"mc":[{"id":"1.168209731","rc":[{"batb":[[0,1.97,15.13],[1,1.96,617.17]],"ltp":1.97,"tv":2417.16,"id":8174357},{"batb":[[0,1.99,18.13],[1,1.98,18.26],[2,1.97,18]],"ltp":2.0,"tv":1956.02,"id":7412952}]}]}
{"op":"mcm","clk":"1004547708","pt":1580632303761,"mc":[{"id":"1.168209731","rc":[{"batb":[[1,1.96,614.9]],"batl":[[2,2.04,568.37]],"ltp":1.97,"tv":2417.16,"id":8174357},{"batb":[[2,1.97,16]],"ltp":2.0,"tv":1956.02,"id":7412952}]}]}
{"op":"mcm","clk":"1004547725","pt":1580632303967,"mc":[{"id":"1.168209731","rc":[{"batl":[[2,2.04,570.37]],"ltp":1.97,"tv":2417.16,"id":8174357},{"batb":[[2,1.97,18.17]],"ltp":2.0,"tv":1956.02,"id":7412952}]}]}
{"op":"mcm","clk":"1004547890","pt":1580632307944,"mc":[{"id":"1.168209731","rc":[{"batb":[[0,1.97,15.26],[2,1.95,98.73]],"ltp":1.97,"tv":2417.16,"id":8174357},{"trd":[[2.02,500.93]],"batl":[[2,2.08,14.45]],"ltp":2.02,"tv":1979.97,"id":7412952}],"tv":4397.13}]}
{"op":"mcm","clk":"1004547898","pt":1580632308148,"mc":[{"id":"1.168209731","rc":[{"batb":[[2,1.95,100.73]],"ltp":1.97,"tv":2417.16,"id":8174357}]}]}
{"op":"mcm","clk":"1004548032","pt":1580632310946,"mc":[{"id":"1.168209731","rc":[{"batb":[[0,1.97,62.93],[2,1.95,17]],"batl":[[2,2.04,570.5]],"ltp":1.97,"tv":2417.16,"id":8174357},{"batb":[[2,1.97,74.03]],"ltp":2.02,"tv":1979.97,"id":7412952}]}]}
{"op":"mcm","clk":"1004558188","pt":1580632541957,"mc":[{"id":"1.168209731","rc":[{"trd":[[1.97,262.43]],"batb":[[0,1.97,2.09]],"batl":[[2,2.04,568.37]],"ltp":1.97,"tv":2538.78,"id":8174357},{"batb":[[2,1.97,71.86]],"ltp":2.02,"tv":1979.97,"id":7412952}],"tv":4518.75}]}
{"op":"mcm","clk":"1004558223","pt":1580632542879,"mc":[{"id":"1.168209731","rc":[{"batb":[[0,1.96,614.9],[1,1.95,15],[2,1.94,18]],"batl":[[2,2.04,570.5]],"ltp":1.97,"tv":2538.78,"id":8174357},{"batb":[[0,1.99,83.98],[2,1.97,18]],"ltp":2.02,"tv":1979.97,"id":7412952}]}]}
{"op":"mcm","clk":"1004558237","pt":1580632543186,"mc":[{"id":"1.168209731","rc":[{"batb":[[0,1.97,15.23],[1,1.96,614.9],[2,1.95,17.11]],"batl":[[1,2.02,20],[2,2.04,575.5]],"ltp":1.97,"tv":2538.78,"id":8174357},{"batb":[[1,1.98,24.26],[2,1.97,24]],"ltp":2.02,"tv":1979.97,"id":7412952}]}]}
{"op":"mcm","clk":"1004558947","pt":1580632559778,"mc":[{"id":"1.168209731","rc":[{"trd":[[1.97,287.66]],"batb":[[0,1.97,2.61]],"ltp":1.97,"tv":2564.01,"id":8174357}],"tv":4543.98}]}
{"op":"mcm","clk":"1004559188","pt":1580632564666,"mc":[{"id":"1.168209731","rc":[{"batb":[[2,1.95,55.2]],"ltp":1.97,"tv":2564.01,"id":8174357}]}]}
{"op":"mcm","clk":"1004571979","pt":1580632867875,"mc":[{"id":"1.168209731","rc":[{"batl":[[2,2.04,573.37]],"ltp":1.97,"tv":2564.01,"id":8174357}]}]}
{"op":"mcm","clk":"1004572002","pt":1580632868177,"mc":[{"id":"1.168209731","rc":[{"batl":[[2,2.04,575.5]],"ltp":1.97,"tv":2564.01,"id":8174357}]}]}
{"op":"mcm","clk":"1004572982","pt":1580632887918,"mc":[{"id":"1.168209731","rc":[{"trd":[[1.97,292.73]],"batb":[[0,1.96,614.97],[1,1.95,55.2],[2,1.94,18]],"ltp":1.97,"tv":2569.08,"id":8174357}],"tv":4549.05}]}
{"op":"mcm","clk":"1004573029","pt":1580632888422,"mc":[{"id":"1.168209731","rc":[{"batb":[[1,1.95,53.09]],"ltp":1.97,"tv":2569.08,"id":8174357},{"batb":[[2,1.97,24.17]],"ltp":2.02,"tv":1979.97,"id":7412952}]}]}
{"op":"mcm","clk":"1004574770","pt":1580632920935,"mc":[{"id":"1.168209731","rc":[{"trd":[[1.99,37.23]],"batb":[[0,1.97,17],[1,1.96,614.9],[2,1.95,53.09]],"batl":[[0,2.02,18.51],[1,2.04,573.37],[2,2.06,20]],"ltp":1.99,"tv":2571.63,"id":8174357},{"trd":[[2,99.73]],"batb":[[0,1.99,91.85],[1,1.98,22],[2,1.97,24]],"ltp":2.0,"tv":1982.5,"id":7412952}],"tv":4554.13}]}
{"op":"mcm","clk":"1004574807","pt":1580632921454,"mc":[{"id":"1.168209731","rc":[{"batb":[[2,1.95,55.09]],"ltp":1.99,"tv":2571.63,"id":8174357}]}]}
{"op":"mcm","clk":"1004592058","pt":1580633280490,"mc":[{"id":"1.168209731","rc":[{"batb":[[0,1.99,65.85]],"ltp":2.0,"tv":1982.5,"id":7412952}]}]}
{"op":"mcm","clk":"1004594407","pt":1580633335840,"mc":[{"id":"1.168209731","rc":[{"trd":[[1.97,326.39]],"batb":[[0,1.96,615.07],[1,1.95,53.09],[2,1.94,18.09]],"ltp":1.97,"tv":2605.29,"id":8174357}],"tv":4587.79}]}
{"op":"mcm","clk":"1004595013","pt":1580633347886,"mc":[{"id":"1.168209731","rc":[{"trd":[[1.96,166.02],[1.97,326.73]],"batb":[[0,1.97,16.03],[1,1.96,568.95],[2,1.95,55.09]],"batl":[[0,2.02,25.51],[1,2.04,580.37],[2,2.06,27]],"ltp":1.96,"tv":2697.53,"id":8174357},{"batb":[[1,1.98,30],[2,1.97,32]],"ltp":2.0,"tv":1982.5,"id":7412952}],"tv":4680.03}]}
{"op":"mcm","clk":"1004595050","pt":1580633348466,"mc":[{"id":"1.168209731","rc":[{"trd":[[1.97,358.39]],"batb":[[0,1.96,569.15],[1,1.95,53.09],[2,1.94,18.09]],"ltp":1.97,"tv":2729.19,"id":8174357}],"tv":4711.69}]}
{"op":"mcm","clk":"1004597742","pt":1580633401925,"mc":[{"id":"1.168209731","rc":[{"trd":[[1.96,669.42],[1.97,358.79]],"batb":[[0,1.97,15.8],[1,1.96,317.25],[2,1.95,55.2]],"ltp":1.96,"tv":3232.99,"id":8174357},{"batb":[[0,1.99,97.85]],"ltp":2.0,"tv":1982.5,"id":7412952}],"tv":5215.49}]}
{"op":"mcm","clk":"1004597769","pt":1580633402432,"mc":[{"id":"1.168209731","rc":[{"batb":[[2,1.95,57.31]],"ltp":1.96,"tv":3232.99,"id":8174357}]}]}
{"op":"mcm","clk":"1004599900","pt":1580633451800,"mc":[{"id":"1.168209731","rc":[{"trd":[[1.97,390.4]],"batb":[[0,1.97,16.28],[2,1.95,55.2]],"ltp":1.97,"tv":3264.59,"id":8174357}],"tv":5247.09}]}
{"op":"mcm","clk":"1004599937","pt":1580633452671,"mc":[{"id":"1.168209731","rc":[{"trd":[[1.97,422.96]],"batb":[[2,1.95,55.09]],"ltp":1.97,"tv":3297.15,"id":8174357}],"tv":5279.66}]}
{"op":"mcm","clk":"1004599978","pt":1580633453490,"mc":[{"id":"1.168209731","rc":[{"trd":[[1.97,455.52]],"batb":[[0,1.96,317.25],[1,1.95,53.09],[2,1.94,18.09]],"ltp":1.97,"tv":3329.72,"id":8174357}],"tv":5312.22}]}
{"op":"mcm","clk":"1004602836","pt":1580633521878,"mc":[{"id":"1.168209731","rc":[{"trd":[[1.96,703.02]],"batb":[[0,1.96,300.45]],"ltp":1.96,"tv":3363.32,"id":8174357}],"tv":5345.83}]}
{"op":"mcm","clk":"1004606488","pt":1580633611904,"mc":[{"id":"1.168209731","rc":[{"trd":[[1.96,1307.38]],"batb":[[0,1.95,53.09],[1,1.94,18.09],[2,1.93,2.08]],"ltp":1.96,"tv":3967.68,"id":8174357},{"trd":[[2.04,216.47]],"batl":[[0,2.04,7.38]],"ltp":2.04,"tv":1986.12,"id":7412952}],"tv":5953.8}]}
{"op":"mcm","clk":"1004606526","pt":1580633612777,"mc":[{"id":"1.168209731","rc":[{"batb":[[0,1.95,38.09],[1,1.94,16]],"batl":[[0,2,33.68],[1,2.02,25],[2,2.04,582.5]],"ltp":1.96,"tv":3967.68,"id":8174357},{"batb":[[1,1.98,42],[2,1.97,43.17]],"batl":[[0,2.08,12.26],[1,2.1,2.05],[2,2.12,2.21]],"ltp":2.04,"tv":1986.12,"id":7412952}]}]}
{"op":"mcm","clk":"1004607335","pt":1580633633792,"mc":[{"id":"1.168209731","rc":[{"batb":[[1,1.93,18.26],[2,1.92,4.82]],"batl":[[1,2.02,27],[2,2.04,580.37]],"ltp":1.96,"tv":3967.68,"id":8174357},{"batb":[[0,2.02,40.18],[1,1.99,99.85],[2,1.98,40]],"ltp":2.04,"tv":1986.12,"id":7412952}]}]}
{"op":"mcm","clk":"1004607366","pt":1580633634405,"mc":[{"id":"1.168209731","rc":[{"batl":[[0,1.98,33.29],[1,2,35.68],[2,2.02,27]],"ltp":1.96,"tv":3967.68,"id":8174357},{"batb":[[2,1.98,42.26]],"ltp":2.04,"tv":1986.12,"id":7412952}]}]}
{"op":"mcm","clk":"1004608281","pt":1580633654848,"mc":[{"id":"1.168209731","rc":[{"batb":[[2,1.92,2.63]],"batl":[[2,2.02,25]],"ltp":1.96,"tv":3967.68,"id":8174357},{"batb":[[1,2,40],[2,1.99,99.85]],"batl":[[1,2.1,13.34],[2,2.42,22.4]],"ltp":2.04,"tv":1986.12,"id":7412952}]}]}
{"op":"mcm","clk":"1004608296","pt":1580633655158,"mc":[{"id":"1.168209731","rc":[{"batb":[[2,1.92,4.82]],"batl":[[2,2.02,27]],"ltp":1.96,"tv":3967.68,"id":8174357},{"batl":[[2,2.12,2.21]],"ltp":2.04,"tv":1986.12,"id":7412952}]}]}
{"op":"mcm","clk":"1004608687","pt":1580633662938,"mc":[{"id":"1.168209731","rc":[{"batl":[[1,2,624.66],[2,2.02,27.25]],"ltp":1.96,"tv":3967.68,"id":8174357},{"batl":[[2,2.12,2.05]],"ltp":2.04,"tv":1986.12,"id":7412952}]}]}
{"op":"mcm","clk":"1004609043","pt":1580633670845,"mc":[{"id":"1.168209731","rc":[{"batb":[[2,1.92,644.09]],"batl":[[2,2.02,27]],"ltp":1.96,"tv":3967.68,"id":8174357}]}]}
{"op":"mcm","clk":"1004609610","pt":1580633681389,"mc":[{"id":"1.168209731","rc":[{"batb":[[2,1.92,644.21]],"batl":[[2,2.02,27.25]],"ltp":1.96,"tv":3967.68,"id":8174357},{"batl":[[2,2.12,2.21]],"ltp":2.04,"tv":1986.12,"id":7412952}]}]}
{"op":"mcm","clk":"1004612488","pt":1580633743882,"mc":[{"id":"1.168209731","rc":[{"batb":[[0,1.93,91.42],[1,1.92,642.02],[2,1.91,2.06]],"batl":[[2,2.02,25]],"ltp":1.96,"tv":3967.68,"id":8174357},{"batl":[[1,2.1,11.29]],"ltp":2.04,"tv":1986.12,"id":7412952}]}]}
{"op":"mcm","clk":"1004612507","pt":1580633744190,"mc":[{"id":"1.168209731","rc":[{"batl":[[2,2.02,27.25]],"ltp":1.96,"tv":3967.68,"id":8174357}]}]}
{"op":"mcm","clk":"1004618867","pt":1580633866214,"mc":[{"id":"1.168209731","rc":[{"batl":[[2,2.02,27]],"ltp":1.96,"tv":3967.68,"id":8174357},{"batl":[[0,2.08,13.02]],"ltp":2.04,"tv":1986.12,"id":7412952}]}]}
{"op":"mcm","clk":"1004619368","pt":1580633874746,"mc":[{"id":"1.168209731","rc":[{"trd":[[2.02,502.45]],"batb":[[0,2.02,39.42]],"batl":[[0,2.08,12.26]],"ltp":2.02,"tv":1987.64,"id":7412952}],"tv":5955.32}]}
{"op":"mcm","clk":"1004626664","pt":1580634004645,"mc":[{"id":"1.168209731","rc":[{"trd":[[1.98,52.89]],"batl":[[0,1.98,33]],"ltp":1.98,"tv":3977.96,"id":8174357},{"trd":[[2.02,591.37]],"batb":[[0,2.02,37]],"ltp":2.02,"tv":2076.56,"id":7412952}],"tv":6054.52}]}
{"op":"mcm","clk":"1004630772","pt":1580634068639,"mc":[{"id":"1.168209731","rc":[{"batl":[[2,2.02,27.25]],"ltp":1.98,"tv":3977.96,"id":8174357}]}]}
{"op":"mcm","clk":"1004634093","pt":1580634128803,"mc":[{"id":"1.168209731","rc":[{"batb":[[0,1.94,10.58],[1,1.93,91.42],[2,1.92,642.02]],"batl":[[0,1.98,43.37]],"ltp":1.98,"tv":3977.96,"id":8174357},{"batb":[[0,2.02,47.16]],"batl":[[0,2.06,9.97],[1,2.08,12.26],[2,2.1,11.29]],"ltp":2.02,"tv":2076.56,"id":7412952}]}]}
{"op":"mcm","clk":"1004634136","pt":1580634129419,"mc":[{"id":"1.168209731","rc":[{"batb":[[2,1.92,644.21]],"ltp":1.98,"tv":3977.96,"id":8174357},{"batl":[[2,2.1,13.34]],"ltp":2.02,"tv":2076.56,"id":7412952}]}]}
{"op":"mcm","clk":"1004635487","pt":1580634157839,"mc":[{"id":"1.168209731","rc":[{"batb":[[0,1.94,29.58]],"ltp":1.98,"tv":3977.96,"id":8174357}]}]}
{"op":"mcm","clk":"1004639328","pt":1580634242768,"mc":[{"id":"1.168209731","rc":[{"batb":[[0,1.95,38.09],[1,1.94,29.58],[2,1.93,18.26]],"batl":[[2,2.02,27]],"ltp":1.98,"tv":3977.96,"id":8174357}]}]}
{"op":"mcm","clk":"1004639366","pt":1580634243382,"mc":[{"id":"1.168209731","rc":[{"batb":[[1,1.94,10.58]],"ltp":1.98,"tv":3977.96,"id":8174357}]}]}
{"op":"mcm","clk":"1004645624","pt":1580634374728,"mc":[{"id":"1.168209731","rc":[{"batb":[[0,1.94,29.58],[1,1.93,91.42],[2,1.92,644.21]],"batl":[[2,2.02,27.25]],"ltp":1.98,"tv":3977.96,"id":8174357}]}]}
{"op":"mcm","clk":"1004645806","pt":1580634379024,"mc":[{"id":"1.168209731","rc":[{"batl":[[1,2.08,22.83]],"ltp":2.02,"tv":2076.56,"id":7412952}]}]}
{"op":"mcm","clk":"1004646527","pt":1580634393754,"mc":[{"id":"1.168209731","rc":[{"batb":[[0,1.95,9.81],[1,1.94,122],[2,1.93,93.5]],"batl":[[2,2.02,27]],"ltp":1.98,"tv":3977.96,"id":8174357}]}]}
{"op":"mcm","clk":"1004647303","pt":1580634410875,"mc":[{"id":"1.168209731","rc":[{"trd":[[1.95,30.88]],"batb":[[0,1.94,122],[1,1.93,93.5],[2,1.92,644.02]],"batl":[[0,1.95,408.93],[1,1.98,43.37],[2,2,624.66]],"ltp":1.95,"tv":3997.58,"id":8174357},{"batb":[[0,2.04,9.36],[1,2.02,47.16],[2,2,40]],"batl":[[1,2.08,32.01]],"ltp":2.02,"tv":2076.56,"id":7412952}],"tv":6074.14}]}
{"op":"mcm","clk":"1004647345","pt":1580634411451,"mc":[{"id":"1.168209731","rc":[{"batb":[[0,1.94,92.42],[1,1.93,91.42],[2,1.92,663.02]],"batl":[[1,1.96,34.27],[2,1.97,36.43]],"ltp":1.95,"tv":3997.58,"id":8174357},{"batb":[[0,2.04,46.36],[2,2,42]],"batl":[[0,2.08,22.83],[1,2.1,11.29],[2,2.12,15.32]],"ltp":2.02,"tv":2076.56,"id":7412952}]}]}
{"op":"mcm","clk":"1004647819","pt":1580634420783,"mc":[{"id":"1.168209731","rc":[{"trd":[[1.94,290.81]],"batb":[[0,1.93,75.3],[1,1.92,661.02],[2,1.91,21.33]],"ltp":1.94,"tv":4182.31,"id":8174357},{"batl":[[0,2.08,10.57]],"ltp":2.02,"tv":2076.56,"id":7412952}],"tv":6258.87}]}
{"op":"mcm","clk":"1004648960","pt":1580634440831,"mc":[{"id":"1.168209731","rc":[{"trd":[[2.04,237.61]],"batb":[[0,2.04,45.38]],"batl":[[0,2.08,9.37]],"ltp":2.04,"tv":2097.7,"id":7412952}],"tv":6280.01}]}
{"op":"mcm","clk":"1004649376","pt":1580634450934,"mc":[{"id":"1.168209731","rc":[{"batl":[[1,1.96,36.54]],"ltp":1.94,"tv":4182.31,"id":8174357}]}]}
{"op":"mcm","clk":"1004650549","pt":1580634476559,"mc":[{"id":"1.168209731","rc":[{"batb":[[0,2.04,45.31]],"batl":[[0,2.08,9.31]],"ltp":2.04,"tv":2097.7,"id":7412952}]}]}
{"op":"mcm","clk":"1004650809","pt":1580634481965,"mc":[{"id":"1.168209731","rc":[{"trd":[[1.93,100.92],[1.94,290.93]],"batb":[[0,1.93,43.5]],"ltp":1.93,"tv":4245.92,"id":8174357}],"tv":6343.62}]}
{"op":"mcm","clk":"1004650911","pt":1580634483867,"mc":[{"id":"1.168209731","rc":[{"batb":[[1,2.02,92.86]],"ltp":2.04,"tv":2097.7,"id":7412952}]}]}
{"op":"mcm","clk":"1004651054","pt":1580634486792,"mc":[{"id":"1.168209731","rc":[{"trd":[[1.93,116.06]],"batb":[[0,1.93,35.93]],"batl":[[0,1.95,442.93]],"ltp":1.93,"tv":4261.06,"id":8174357}],"tv":6358.76}]}
{"op":"mcm","clk":"1004651065","pt":1580634486996,"mc":[{"id":"1.168209731","rc":[{"batb":[[1,2.02,100.03]],"ltp":2.04,"tv":2097.7,"id":7412952}]}]}
{"op":"mcm","clk":"1004652327","pt":1580634516950,"mc":[{"id":"1.168209731","rc":[{"batl":[[0,1.94,42.01],[1,1.95,442.93],[2,1.96,38.66]],"ltp":1.93,"tv":4261.06,"id":8174357}]}]}
{"op":"mcm","clk":"1004652361","pt":1580634517622,"mc":[{"id":"1.168209731","rc":[{"batb":[[1,2.02,102.27]],"ltp":2.04,"tv":2097.7,"id":7412952}]}]}
{"op":"mcm","clk":"1004656058","pt":1580634602956,"mc":[{"id":"1.168209731","rc":[{"trd":[[1.93,141.4]],"batb":[[0,1.93,23.25]],"ltp":1.93,"tv":4286.4,"id":8174357},{"batb":[[0,2.04,35.79]],"batl":[[0,2.1,11.29],[1,2.12,15.32],[2,2.14,15.24]],"ltp":2.04,"tv":2097.7,"id":7412952}],"tv":6384.1}]}
{"op":"mcm","clk":"1004656075","pt":1580634603366,"mc":[{"id":"1.168209731","rc":[{"batb":[[0,2.04,45.13],[1,2.02,114.28]],"batl":[[0,2.08,9.13],[1,2.1,11.29],[2,2.12,15.32]],"ltp":2.04,"tv":2097.7,"id":7412952}]}]}
{"op":"mcm","clk":"1004656248","pt":1580634607277,"mc":[{"id":"1.168209731","rc":[{"batb":[[0,2.06,36],[1,2.04,35.79],[2,2.02,190]],"batl":[[0,2.1,20.32],[1,2.12,15.32],[2,2.14,15.31]],"ltp":2.04,"tv":2097.7,"id":7412952}]}]}
{"op":"mcm","clk":"1004658037","pt":1580634650617,"mc":[{"id":"1.168209731","rc":[{"trd":[[1.93,146.27]],"batb":[[0,1.93,20.81]],"ltp":1.93,"tv":4291.28,"id":8174357},{"batb":[[1,2.04,38.1]],"batl":[[0,2.1,20.22]],"ltp":2.04,"tv":2097.7,"id":7412952}],"tv":6388.98}]}
{"op":"mcm","clk":"1004659578","pt":1580634684945,"mc":[{"id":"1.168209731","rc":[{"trd":[[1.94,293.1]],"batl":[[0,1.94,40.93]],"ltp":1.94,"tv":4293.44,"id":8174357},{"batl":[[0,2.1,11.29],[2,2.14,13.2]],"ltp":2.04,"tv":2097.7,"id":7412952}],"tv":6391.15}]}
{"op":"mcm","clk":"1004659588","pt":1580634685152,"mc":[{"id":"1.168209731","rc":[{"batl":[[0,2.1,20.13],[2,2.14,15.24]],"ltp":2.04,"tv":2097.7,"id":7412952}]}]}
{"op":"mcm","clk":"1004665826","pt":1580634807470,"mc":[{"id":"1.168209731","rc":[{"batl":[[0,2.1,19.82],[2,2.14,15.38]],"ltp":2.04,"tv":2097.7,"id":7412952}]}]}
{"op":"mcm","clk":"1004671273","pt":1580634907848,"mc":[{"id":"1.168209731","rc":[{"batl":[[0,2.1,19.57],[2,2.14,15.45]],"ltp":2.04,"tv":2097.7,"id":7412952}]}]}
{"op":"mcm","clk":"1004675400","pt":1580634987846,"mc":[{"id":"1.168209731","rc":[{"batb":[[0,1.92,661.02],[1,1.91,70.83],[2,1.9,23.59]],"ltp":1.94,"tv":4293.44,"id":8174357},{"batb":[[1,2.04,45.52]],"batl":[[0,2.1,11.29],[1,2.12,13.27]],"ltp":2.04,"tv":2097.7,"id":7412952}]}]}
{"op":"mcm","clk":"1004675414","pt":1580634988053,"mc":[{"id":"1.168209731","rc":[{"batl":[[0,2.1,19.37]],"ltp":2.04,"tv":2097.7,"id":7412952}]}]}
{"op":"mcm","clk":"1004679460","pt":1580635062868,"mc":[{"id":"1.168209731","rc":[{"trd":[[2.06,109.04]],"batb":[[0,2.06,22]],"ltp":2.06,"tv":2125.7,"id":7412952}],"tv":6419.15}]}
{"op":"mcm","clk":"1004679490","pt":1580635063338,"mc":[{"id":"1.168209731","rc":[{"batl":[[0,2.1,19.22]],"ltp":2.06,"tv":2125.7,"id":7412952}]}]}
{"op":"mcm","clk":"1004682943","pt":1580635127740,"mc":[{"id":"1.168209731","rc":[{"batl":[[0,1.94,80.78]],"ltp":1.94,"tv":4293.44,"id":8174357},{"batl":[[0,2.1,19.07]],"ltp":2.06,"tv":2125.7,"id":7412952}]}]}
{"op":"mcm","clk":"1004686629","pt":1580635201610,"mc":[{"id":"1.168209731","rc":[{"batl":[[0,2.1,18.89]],"ltp":2.06,"tv":2125.7,"id":7412952}]}]}
{"op":"mcm","clk":"1004689674","pt":1580635268570,"mc":[{"id":"1.168209731","rc":[{"batl":[[0,2.1,18.73]],"ltp":2.06,"tv":2125.7,"id":7412952}]}]}
{"op":"mcm","clk":"1004694408","pt":1580635384846,"mc":[{"id":"1.168209731","rc":[{"batb":[[2,2.02,300.08]],"batl":[[0,2.1,18.45]],"ltp":2.06,"tv":2125.7,"id":7412952}]}]}
{"op":"mcm","clk":"1004695455","pt":1580635412856,"mc":[{"id":"1.168209731","rc":[{"batb":[[0,1.92,642.02],[1,1.91,60.29]],"batl":[[0,1.93,23.1],[1,1.94,80.78],[2,1.95,445.03]],"ltp":1.94,"tv":4293.44,"id":8174357},{"batb":[[0,2.06,29.27]],"batl":[[0,2.1,18.38]],"ltp":2.06,"tv":2125.7,"id":7412952}]}]}
{"op":"mcm","clk":"1004697390","pt":1580635458790,"mc":[{"id":"1.168209731","rc":[{"trd":[[1.92,134.43]],"batb":[[0,1.92,574.81],[1,1.91,65.56]],"batl":[[1,1.94,107.78]],"ltp":1.92,"tv":4427.87,"id":8174357}],"tv":6553.57}]}
{"op":"mcm","clk":"1004698907","pt":1580635494563,"mc":[{"id":"1.168209731","rc":[{"batb":[[0,2.06,29.22]],"batl":[[0,2.1,18.34]],"ltp":2.06,"tv":2125.7,"id":7412952}]}]}
{"op":"mcm","clk":"1004698985","pt":1580635495851,"mc":[{"id":"1.168209731","rc":[{"trd":[[1.92,134.96]],"batb":[[0,1.92,574.54]],"ltp":1.92,"tv":4428.41,"id":8174357}],"tv":6554.11}]}
{"op":"mcm","clk":"1004698996","pt":1580635496066,"mc":[{"id":"1.168209731","rc":[{"batl":[[0,2.1,18.33]],"ltp":2.06,"tv":2125.7,"id":7412952}]}]}
{"op":"mcm","clk":"1004699206","pt":1580635500899,"mc":[{"id":"1.168209731","rc":[{"trd":[[1.92,172.86]],"batb":[[0,1.92,555.6]],"ltp":1.92,"tv":4466.31,"id":8174357}],"tv":6592.01}]}
{"op":"mcm","clk":"1004701097","pt":1580635545833,"mc":[{"id":"1.168209731","rc":[{"trd":[[1.92,177.06],[1.93,151.52]],"batb":[[0,1.92,553.5]],"batl":[[0,1.93,20.48]],"ltp":1.93,"tv":4475.75,"id":8174357},{"batb":[[0,2.06,29.15]],"batl":[[0,2.1,18.27]],"ltp":2.06,"tv":2125.7,"id":7412952}],"tv":6601.45}]}
{"op":"mcm","clk":"1004702957","pt":1580635586868,"mc":[{"id":"1.168209731","rc":[{"batb":[[0,2.06,29.05],[2,2.02,224.36]],"batl":[[0,2.1,18.17]],"ltp":2.06,"tv":2125.7,"id":7412952}]}]}
{"op":"mcm","clk":"1004704147","pt":1580635608357,"mc":[{"id":"1.168209731","marketDefinition":{"bspMarket":false,"turnInPlayEnabled":true,"persistenceEnabled":true,"marketBaseRate":5.0,"eventId":"29681142","eventTypeId":"2","numberOfWinners":1,"bettingType":"ODDS","marketType":"MATCH_ODDS","marketTime":"2020-02-02T09:21:00.000Z","suspendTime":"2020-02-02T09:21:00.000Z","bspReconciled":false,"complete":true,"inPlay":false,"crossMatching":true,"runnersVoidable":false,"numberOfActiveRunners":2,"betDelay":0,"status":"OPEN","runners":[{"status":"ACTIVE","sortPriority":1,"id":8174357,"name":"Blaz Rola"},{"status":"ACTIVE","sortPriority":2,"id":7412952,"name":"Roberto Marcora"}],"regulators":["MR_INT"],"countryCode":"IN","discountAllowed":true,"timezone":"UTC","openDate":"2020-02-02T09:30:00.000Z","version":3148345361,"name":"Match Odds","eventName":"Rola v Marcora"}}]}
{"op":"mcm","clk":"1004704226","pt":1580635609915,"mc":[{"id":"1.168209731","rc":[{"batb":[[2,1.9,21.53]],"batl":[[2,1.95,442.93]],"ltp":1.93,"tv":4475.75,"id":8174357},{"batb":[[0,2.06,28.99],[2,2.02,222.12]],"batl":[[0,2.1,11.29],[2,2.14,13.2]],"ltp":2.06,"tv":2125.7,"id":7412952}]}]}
{"op":"mcm","clk":"1004704235","pt":1580635610019,"mc":[{"id":"1.168209731","rc":[{"batl":[[0,2.1,18.11]],"ltp":2.06,"tv":2125.7,"id":7412952}]}]}
{"op":"mcm","clk":"1004704582","pt":1580635614514,"mc":[{"id":"1.168209731","marketDefinition":{"bspMarket":false,"turnInPlayEnabled":true,"persistenceEnabled":true,"marketBaseRate":5.0,"eventId":"29681142","eventTypeId":"2","numberOfWinners":1,"bettingType":"ODDS","marketType":"MATCH_ODDS","marketTime":"2020-02-02T09:21:00.000Z","suspendTime":"2020-02-02T09:21:00.000Z","bspReconciled":false,"complete":true,"inPlay":false,"crossMatching":true,"runnersVoidable":false,"numberOfActiveRunners":2,"betDelay":0,"status":"OPEN","runners":[{"status":"ACTIVE","sortPriority":1,"id":8174357,"name":"Blaz Rola"},{"status":"ACTIVE","sortPriority":2,"id":7412952,"name":"Roberto Marcora"}],"regulators":["MR_INT"],"countryCode":"IN","discountAllowed":true,"timezone":"UTC","openDate":"2020-02-02T09:21:00.000Z","version":3148345361,"name":"Match Odds","eventName":"Rola v Marcora"},"rc":[{"batb":[[0,2.06,28.98]],"batl":[[0,2.1,18.1]],"ltp":2.06,"tv":2125.7,"id":7412952}]}]}
{"op":"mcm","clk":"1004704907","pt":1580635619931,"mc":[{"id":"1.168209731","rc":[{"batb":[[0,2.06,28.97]],"batl":[[0,2.1,18.09]],"ltp":2.06,"tv":2125.7,"id":7412952}]}]}
{"op":"mcm","clk":"1004705268","pt":1580635629258,"mc":[{"id":"1.168209731","rc":[{"batb":[[0,2.06,28.94],[1,2.04,153.31],[2,2.02,112.04]],"batl":[[0,2.1,18.07]],"ltp":2.06,"tv":2125.7,"id":7412952}]}]}
{"op":"mcm","clk":"1004705625","pt":1580635639443,"mc":[{"id":"1.168209731","rc":[{"batb":[[0,2.06,134.35],[1,2.04,45.52]],"batl":[[0,2.1,18.04]],"ltp":2.06,"tv":2125.7,"id":7412952}]}]}
{"op":"mcm","clk":"1004705950","pt":1580635647879,"mc":[{"id":"1.168209731","rc":[{"batb":[[0,2.06,134.33]],"batl":[[0,2.1,18.02]],"ltp":2.06,"tv":2125.7,"id":7412952}]}]}
{"op":"mcm","clk":"1004706140","pt":1580635653770,"mc":[{"id":"1.168209731","rc":[{"trd":[[1.93,192.48]],"batb":[[0,1.93,587.48],[1,1.92,565.5],[2,1.91,65.56]],"batl":[[0,1.94,80.78],[1,1.95,432.93],[2,1.96,26.27]],"ltp":1.93,"tv":4516.71,"id":8174357},{"batb":[[0,2.06,105.43]],"batl":[[0,2.08,6.83],[1,2.1,18.02],[2,2.12,8]],"ltp":2.06,"tv":2125.7,"id":7412952}],"tv":6642.41}]}
{"op":"mcm","clk":"1004706558","pt":1580635664867,"mc":[{"id":"1.168209731","rc":[{"batl":[[0,2.08,6.8]],"ltp":2.06,"tv":2125.7,"id":7412952}]}]}
{"op":"mcm","clk":"1004707901","pt":1580635698932,"mc":[{"id":"1.168209731","rc":[{"batl":[[0,2.08,6.72],[1,2.1,11.29]],"ltp":2.06,"tv":2125.7,"id":7412952}]}]}
{"op":"mcm","clk":"1004708085","pt":1580635703623,"mc":[{"id":"1.168209731","rc":[{"batl":[[0,2.08,6.71]],"ltp":2.06,"tv":2125.7,"id":7412952}]}]}
{"op":"mcm","clk":"1004708317","pt":1580635709942,"mc":[{"id":"1.168209731","rc":[{"trd":[[1.94,294.61]],"batl":[[0,1.94,80.03]],"ltp":1.94,"tv":4518.22,"id":8174357}],"tv":6643.92}]}
{"op":"mcm","clk":"1004708326","pt":1580635710244,"mc":[{"id":"1.168209731","rc":[{"batl":[[0,2.08,6.69]],"ltp":2.06,"tv":2125.7,"id":7412952}]}]}
{"op":"mcm","clk":"1004709295","pt":1580635730947,"mc":[{"id":"1.168209731","rc":[{"batb":[[2,2.02,101.88]],"batl":[[0,2.1,11.29],[1,2.12,8],[2,2.14,8]],"ltp":2.06,"tv":2125.7,"id":7412952}]}]}
{"op":"mcm","clk":"1004709891","pt":1580635745571,"mc":[{"id":"1.168209731","rc":[{"batl":[[2,1.96,111.13]],"ltp":1.94,"tv":4518.22,"id":8174357}]}]}
{"op":"mcm","clk":"1004711532","pt":1580635787749,"mc":[{"id":"1.168209731","rc":[{"trd":[[1.93,202.97]],"batb":[[0,1.93,582.24]],"ltp":1.93,"tv":4528.71,"id":8174357}],"tv":6654.41}]}
{"op":"mcm","clk":"1004712013","pt":1580635800825,"mc":[{"id":"1.168209731","rc":[{"trd":[[1.93,203.31]],"batb":[[0,1.93,582.07]],"ltp":1.93,"tv":4529.05,"id":8174357}],"tv":6654.75}]}
{"op":"mcm","clk":"1004716503","pt":1580635914174,"mc":[{"id":"1.168209731","rc":[{"batb":[[0,1.93,542.21]],"batl":[[0,1.94,40.17]],"ltp":1.93,"tv":4529.05,"id":8174357}]}]}
{"op":"mcm","clk":"1004717155","pt":1580635926687,"mc":[{"id":"1.168209731","rc":[{"trd":[[1.93,271.36]],"batb":[[0,1.93,508.18]],"ltp":1.93,"tv":4597.11,"id":8174357}],"tv":6722.81}]}
{"op":"mcm","clk":"1004717287","pt":1580635929478,"mc":[{"id":"1.168209731","rc":[{"batb":[[0,2.04,151.43],[1,2.02,101.88],[2,2,30]],"ltp":2.06,"tv":2125.7,"id":7412952}]}]}
{"op":"mcm","clk":"1004718326","pt":1580635951812,"mc":[{"id":"1.168209731","rc":[{"trd":[[1.93,309]],"batb":[[0,1.93,489.36]],"ltp":1.93,"tv":4634.74,"id":8174357}],"tv":6760.44}]}
{"op":"mcm","clk":"1004719389","pt":1580635974860,"mc":[{"id":"1.168209731","rc":[{"trd":[[1.94,374.95]],"batb":[[0,1.93,500.36]],"batl":[[0,1.95,432.93],[1,1.96,111.13],[2,1.97,24]],"ltp":1.94,"tv":4715.08,"id":8174357},{"batb":[[0,2.04,141.64],[1,2.02,90.88]],"batl":[[0,2.08,8],[1,2.1,11.29],[2,2.12,8]],"ltp":2.06,"tv":2125.7,"id":7412952}],"tv":6840.78}]}
{"op":"mcm","clk":"1004719412","pt":1580635975372,"mc":[{"id":"1.168209731","rc":[{"batb":[[0,1.93,528.99],[2,1.91,14]],"ltp":1.94,"tv":4715.08,"id":8174357},{"batb":[[0,2.04,131.91],[1,2.02,86.12]],"ltp":2.06,"tv":2125.7,"id":7412952}]}]}
{"op":"mcm","clk":"1004720008","pt":1580635988561,"mc":[{"id":"1.168209731","rc":[{"trd":[[1.93,477.04]],"batb":[[0,1.93,444.97]],"ltp":1.93,"tv":4883.13,"id":8174357}],"tv":7008.83}]}
{"op":"mcm","clk":"1004724125","pt":1580636084527,"mc":[{"id":"1.168209731","rc":[{"trd":[[1.95,841.56]],"batb":[[0,1.93,28.63]],"batl":[[0,1.95,3.59]],"ltp":1.95,"tv":5693.81,"id":8174357}],"tv":7819.51}]}
{"op":"mcm","clk":"1004724608","pt":1580636097854,"mc":[{"id":"1.168209731","rc":[{"batb":[[1,1.92,607.93]],"ltp":1.95,"tv":5693.81,"id":8174357}]}]}
{"op":"mcm","clk":"1004724619","pt":1580636098061,"mc":[{"id":"1.168209731","rc":[{"batb":[[0,1.93,39.63]],"ltp":1.95,"tv":5693.81,"id":8174357}]}]}
{"op":"mcm","clk":"1004724695","pt":1580636099868,"mc":[{"id":"1.168209731","rc":[{"batb":[[0,1.93,28.63]],"ltp":1.95,"tv":5693.81,"id":8174357},{"batb":[[0,2.06,103.78],[1,2.04,26],[2,2.02,86.12]],"ltp":2.06,"tv":2125.7,"id":7412952}]}]}
{"op":"mcm","clk":"1004725085","pt":1580636109890,"mc":[{"id":"1.168209731","rc":[{"trd":[[2.06,110.81]],"batb":[[0,2.06,102.9]],"ltp":2.06,"tv":2127.46,"id":7412952}],"tv":7821.28}]}
{"op":"mcm","clk":"1004726509","pt":1580636142841,"mc":[{"id":"1.168209731","marketDefinition":{"bspMarket":false,"turnInPlayEnabled":true,"persistenceEnabled":true,"marketBaseRate":5.0,"eventId":"29681142","eventTypeId":"2","numberOfWinners":1,"bettingType":"ODDS","marketType":"MATCH_ODDS","marketTime":"2020-02-02T09:21:00.000Z","suspendTime":"2020-02-02T09:21:00.000Z","bspReconciled":false,"complete":true,"inPlay":true,"crossMatching":true,"runnersVoidable":false,"numberOfActiveRunners":2,"betDelay":3,"status":"OPEN","runners":[{"status":"ACTIVE","sortPriority":1,"id":8174357,"name":"Blaz Rola"},{"status":"ACTIVE","sortPriority":2,"id":7412952,"name":"Roberto Marcora"}],"regulators":["MR_INT"],"countryCode":"IN","discountAllowed":true,"timezone":"UTC","openDate":"2020-02-02T09:21:00.000Z","version":3148351356,"name":"Match Odds","eventName":"Rola v Marcora"},"rc":[{"batb":[[0,1.92,595.93],[1,1.88,420.1],[2,1.79,39.86]],"batl":[[0,1.96,2.27],[1,2,3.3],[2,2.3,10.13]],"ltp":1.95,"tv":5693.81,"id":8174357},{"batb":[[0,1.11,37.97],[1,1.05,152.3],[2,1.04,169.36]],"batl":[[0,2.2,2.53],[1,2.42,22.4],[2,2.5,10.13]],"ltp":2.06,"tv":2127.46,"id":7412952}]}]}
{"op":"mcm","clk":"1004726765","pt":1580636149452,"mc":[{"id":"1.168209731","rc":[{"batb":[[2,1.85,198.79]],"batl":[[2,2.12,293.79]],"ltp":1.95,"tv":5693.81,"id":8174357}]}]}
{"op":"mcm","clk":"1004727175","pt":1580636158971,"mc":[{"id":"1.168209731","rc":[{"batb":[[1,1.05,530.92]],"ltp":2.06,"tv":2127.46,"id":7412952}]}]}
{"op":"mcm","clk":"1004727246","pt":1580636160632,"mc":[{"id":"1.168209731","rc":[{"batb":[[2,1.79,39.86]],"batl":[[2,2.3,10.13]],"ltp":1.95,"tv":5693.81,"id":8174357}]}]}
{"op":"mcm","clk":"1004727409","pt":1580636163839,"mc":[{"id":"1.168209731","rc":[{"batb":[[0,1.93,200.78],[1,1.92,595.93],[2,1.91,220.52]],"batl":[[1,2,182.7],[2,2.02,189.6]],"ltp":1.95,"tv":5693.81,"id":8174357},{"batb":[[1,1.1,378.72],[2,1.05,530.82]],"ltp":2.06,"tv":2127.46,"id":7412952}]}]}
{"op":"mcm","clk":"1004727601","pt":1580636167888,"mc":[{"id":"1.168209731","rc":[{"batb":[[0,1.92,595.93],[1,1.88,420.1],[2,1.79,39.86]],"batl":[[1,2,3.3],[2,2.3,10.13]],"ltp":1.95,"tv":5693.81,"id":8174357},{"batb":[[0,1.2,189.42],[1,1.11,37.86],[2,1.1,378.72]],"ltp":2.06,"tv":2127.46,"id":7412952}]}]}
{"op":"mcm","clk":"1004727713","pt":1580636170774,"mc":[{"id":"1.168209731","rc":[{"batb":[[2,1.85,198.57]],"batl":[[1,2,2.79],[2,2.12,293.98]],"ltp":1.95,"tv":5693.81,"id":8174357},{"batb":[[0,1.4,75.73],[1,1.3,75.72],[2,1.2,189.41]],"ltp":2.06,"tv":2127.46,"id":7412952}]}]}
{"op":"mcm","clk":"1004727852","pt":1580636174489,"mc":[{"id":"1.168209731","rc":[{"batl":[[2,2.3,10.13]],"ltp":1.95,"tv":5693.81,"id":8174357},{"batb":[[0,1.5,75.72],[1,1.4,75.73],[2,1.3,75.72]],"ltp":2.06,"tv":2127.46,"id":7412952}]}]}
{"op":"mcm","clk":"1004727985","pt":1580636176954,"mc":[{"id":"1.168209731","rc":[{"trd":[[1.92,485.6]],"batb":[[0,1.92,441.66]],"batl":[[0,1.93,217.43],[1,1.96,2.27],[2,2,2.79]],"ltp":1.92,"tv":6002.35,"id":8174357}],"tv":8129.82}]}
{"op":"mcm","clk":"1004728024","pt":1580636177774,"mc":[{"id":"1.168209731","rc":[{"trd":[[1.92,710.39]],"batb":[[0,1.92,279.18],[2,1.79,92.79]],"batl":[[0,1.96,44.28],[1,2,2.79],[2,2.3,10.13]],"ltp":1.92,"tv":6227.13,"id":8174357},{"trd":[[2.1,91.59]],"batb":[[0,2.02,151.88],[1,1.5,75.72],[2,1.4,75.73]],"batl":[[1,2.26,32.92],[2,2.42,22.25]],"ltp":2.1,"tv":2219.05,"id":7412952}],"tv":8446.19}]}
{"op":"mcm","clk":"1004728150","pt":1580636180671,"mc":[{"id":"1.168209731","rc":[{"trd":[[1.92,1066.65]],"batb":[[0,1.92,101.05],[2,1.86,163.63]],"ltp":1.92,"tv":6583.39,"id":8174357}],"tv":8802.45}]}
{"op":"mcm","clk":"1004728273","pt":1580636183666,"mc":[{"id":"1.168209731","rc":[{"batb":[[2,1.86,259]],"batl":[[0,1.93,193.45],[1,1.95,210.47],[2,1.96,44.28]],"ltp":1.92,"tv":6583.39,"id":8174357}]}]}
{"op":"mcm","clk":"1004728634","pt":1580636193215,"mc":[{"id":"1.168209731","rc":[{"batb":[[2,1.79,92.79]],"batl":[[0,1.96,44.28],[1,2,2.79],[2,2.3,10.13]],"ltp":1.92,"tv":6583.39,"id":8174357}]}]}
{"op":"mcm","clk":"1004728668","pt":1580636194325,"mc":[{"id":"1.168209731","rc":[{"batb":[[2,1.79,39.86]],"batl":[[0,1.96,2.27]],"ltp":1.92,"tv":6583.39,"id":8174357},{"batb":[[0,2.02,110.71]],"batl":[[1,2.42,22.4],[2,2.5,10.13]],"ltp":2.1,"tv":2219.05,"id":7412952}]}]}
{"op":"mcm","clk":"1004728759","pt":1580636196894,"mc":[{"id":"1.168209731","rc":[{"batb":[[2,1.82,231.71]],"batl":[[2,2.04,280.52]],"ltp":1.92,"tv":6583.39,"id":8174357},{"batb":[[1,1.99,115.35],[2,1.5,75.72]],"ltp":2.1,"tv":2219.05,"id":7412952}]}]}
{"op":"mcm","clk":"1004728882","pt":1580636199784,"mc":[{"id":"1.168209731","rc":[{"batb":[[2,1.79,39.86]],"batl":[[2,2.3,10.13]],"ltp":1.92,"tv":6583.39,"id":8174357}]}]}
{"op":"mcm","clk":"1004728986","pt":1580636202681,"mc":[{"id":"1.168209731","rc":[{"batb":[[1,1.88,648.51],[2,1.86,239.64]],"batl":[[0,1.95,201.31],[1,1.96,2.27],[2,1.97,204.11]],"ltp":1.92,"tv":6583.39,"id":8174357}]}]}
{"op":"mcm","clk":"1004729126","pt":1580636206244,"mc":[{"id":"1.168209731","rc":[{"batb":[[1,1.88,420.1],[2,1.79,39.86]],"batl":[[0,1.96,2.27],[1,2,2.79],[2,2.3,10.13]],"ltp":1.92,"tv":6583.39,"id":8174357}]}]}
{"op":"mcm","clk":"1004729242","pt":1580636209642,"mc":[{"id":"1.168209731","rc":[{"batb":[[0,1.92,42.43],[1,1.79,39.86],[2,1.77,88.36]],"ltp":1.92,"tv":6583.39,"id":8174357}]}]}
{"op":"mcm","clk":"1004729271","pt":1580636210518,"mc":[{"id":"1.168209731","rc":[{"batb":[[0,1.99,115.35],[1,1.5,75.72],[2,1.4,75.73]],"ltp":2.1,"tv":2219.05,"id":7412952}]}]}
{"op":"mcm","clk":"1004729366","pt":1580636212937,"mc":[{"id":"1.168209731","rc":[{"trd":[[1.96,1309.65]],"batb":[[0,1.96,162.21],[1,1.94,210.01],[2,1.92,42.43]],"batl":[[0,2,2.79],[1,2.04,280.52],[2,2.06,178.9]],"ltp":1.96,"tv":6585.67,"id":8174357},{"trd":[[2.04,239.79]],"batb":[[1,1.4,75.73],[2,1.3,75.72]],"ltp":2.04,"tv":2221.23,"id":7412952}],"tv":8806.9}]}
{"op":"mcm","clk":"1004729394","pt":1580636213713,"mc":[{"id":"1.168209731","rc":[{"batb":[[2,1.93,67.51]],"batl":[[2,2.06,218.39]],"ltp":1.96,"tv":6585.67,"id":8174357},{"batb":[[0,2,114.95],[1,1.94,44.53],[2,1.86,72.07]],"batl":[[0,2.14,36.13],[1,2.2,2.53],[2,2.42,22.4]],"ltp":2.04,"tv":2221.23,"id":7412952}]}]}
{"op":"mcm","clk":"1004730026","pt":1580636227667,"mc":[{"id":"1.168209731","rc":[{"batb":[[0,1.92,42.43],[1,1.88,235.41],[2,1.85,77.58]],"batl":[[1,2.06,39.49],[2,2.3,10.13]],"ltp":1.96,"tv":6585.67,"id":8174357},{"batb":[[0,1.94,44.53],[1,1.86,72.07],[2,1.5,75.72]],"ltp":2.04,"tv":2221.23,"id":7412952}]}]}
{"op":"mcm","clk":"1004730044","pt":1580636228332,"mc":[{"id":"1.168209731","rc":[{"batb":[[1,1.88,188.36]],"batl":[[1,2.3,10.13],[2,2.5,10.13]],"ltp":1.96,"tv":6585.67,"id":8174357},{"batb":[[0,1.86,72.07],[1,1.5,75.72],[2,1.4,75.73]],"batl":[[0,2.2,2.53],[1,2.42,22.4],[2,2.5,10.13]],"ltp":2.04,"tv":2221.23,"id":7412952}]}]}
{"op":"mcm","clk":"1004730118","pt":1580636230753,"mc":[{"id":"1.168209731","rc":[{"batb":[[1,1.88,417.12],[2,1.86,315.59]],"batl":[[1,2.2,166.2],[2,2.22,144.6]],"ltp":1.96,"tv":6585.67,"id":8174357},{"batb":[[0,1.84,73.49]],"ltp":2.04,"tv":2221.23,"id":7412952}]}]}
{"op":"mcm","clk":"1004730134","pt":1580636231162,"mc":[{"id":"1.168209731","rc":[{"batl":[[1,2.3,10.13],[2,2.5,10.13]],"ltp":1.96,"tv":6585.67,"id":8174357}]}]}
{"op":"mcm","clk":"1004730225","pt":1580636233854,"mc":[{"id":"1.168209731","rc":[{"trd":[[1.92,1098.29]],"batb":[[0,1.92,26.61]],"batl":[[0,1.93,3127],[1,2,2.79],[2,2.3,10.13]],"ltp":1.92,"tv":6617.31,"id":8174357},{"batl":[[0,2.2,13.86]],"ltp":2.04,"tv":2221.23,"id":7412952}],"tv":8838.54}]}
{"op":"mcm","clk":"1004730259","pt":1580636234781,"mc":[{"id":"1.168209731","rc":[{"trd":[[1.92,1151.51]],"batb":[[0,1.88,417.12],[1,1.86,315.59],[2,1.8,378.93]],"batl":[[0,1.92,561.63],[1,1.95,201.01],[2,1.97,204.12]],"ltp":1.92,"tv":6670.53,"id":8174357},{"batb":[[0,2.08,101.74],[1,1.96,122.51],[2,1.84,73.49]],"batl":[[1,2.24,434.19],[2,2.42,22.25]],"ltp":2.04,"tv":2221.23,"id":7412952}],"tv":8891.76}]}
{"op":"mcm","clk":"1004730279","pt":1580636235257,"mc":[{"id":"1.168209731","rc":[{"batb":[[2,1.82,50.41]],"ltp":1.92,"tv":6670.53,"id":8174357},{"batb":[[1,2.02,41.17],[2,1.96,122.51]],"batl":[[1,2.24,467.8]],"ltp":2.04,"tv":2221.23,"id":7412952}]}]}
{"op":"mcm","clk":"1004730652","pt":1580636244080,"mc":[{"id":"1.168209731","rc":[{"batl":[[0,2.2,2.53]],"ltp":2.04,"tv":2221.23,"id":7412952}]}]}
{"op":"mcm","clk":"1004730805","pt":1580636247886,"mc":[{"id":"1.168209731","rc":[{"batb":[[0,1.88,188.36],[1,1.86,75.93]],"batl":[[0,1.98,42.01],[1,2,2.79],[2,2.3,10.13]],"ltp":1.92,"tv":6670.53,"id":8174357},{"batl":[[1,2.24,33.76]],"ltp":2.04,"tv":2221.23,"id":7412952}]}]}
{"op":"mcm","clk":"1004730826","pt":1580636248303,"mc":[{"id":"1.168209731","rc":[{"batb":[[1,1.8,378.93],[2,1.79,125.3]],"batl":[[0,2,2.79],[1,2.3,10.13],[2,2.5,10.13]],"ltp":1.92,"tv":6670.53,"id":8174357},{"batb":[[0,1.96,122.51],[1,1.5,75.72],[2,1.4,75.73]],"batl":[[1,2.42,22.4],[2,2.5,10.13]],"ltp":2.04,"tv":2221.23,"id":7412952}]}]}
{"op":"mcm","clk":"1004730907","pt":1580636250774,"mc":[{"id":"1.168209731","rc":[{"batb":[[1,1.83,216.68],[2,1.81,261.6]],"batl":[[1,2.08,279.79],[2,2.1,169.26]],"ltp":1.92,"tv":6670.53,"id":8174357}]}]}
{"op":"mcm","clk":"1004731018","pt":1580636254523,"mc":[{"id":"1.168209731","rc":[{"batb":[[1,1.8,378.93],[2,1.79,125.3]],"batl":[[1,2.3,10.13],[2,2.5,10.13]],"ltp":1.92,"tv":6670.53,"id":8174357}]}]}
{"op":"mcm","clk":"1004731049","pt":1580636255502,"mc":[{"id":"1.168209731","rc":[{"trd":[[1.88,157.72]],"batb":[[0,1.88,175.76]],"ltp":1.88,"tv":6695.73,"id":8174357}],"tv":8916.97}]}
{"op":"mcm","clk":"1004731126","pt":1580636257929,"mc":[{"id":"1.168209731","rc":[{"trd":[[2,121.89]],"batb":[[0,2,4.77],[1,1.88,175.76],[2,1.8,378.93]],"batl":[[0,2.04,6.66],[1,2.06,518.5],[2,2.3,10.13]],"ltp":2.0,"tv":6698.52,"id":8174357},{"trd":[[2,102.52]],"batb":[[1,1.93,257.48],[2,1.91,220.47]],"batl":[[0,2,1.98],[1,2.02,312.95],[2,2.04,184.13]],"ltp":2.0,"tv":2224.02,"id":7412952}],"tv":8922.54}]}
{"op":"mcm","clk":"1004731149","pt":1580636258394,"mc":[{"id":"1.168209731","rc":[{"batb":[[1,1.97,63.42],[2,1.88,175.76]],"ltp":2.0,"tv":6698.52,"id":8174357}]}]}
{"op":"mcm","clk":"1004731181","pt":1580636259321,"mc":[{"id":"1.168209731","rc":[{"batb":[[2,1.9,46.21]],"batl":[[2,2.12,36.97]],"ltp":2.0,"tv":6698.52,"id":8174357}]}]}
{"op":"mcm","clk":"1004731540","pt":1580636267937,"mc":[{"id":"1.168209731","rc":[{"batb":[[0,1.97,63.42],[1,1.9,46.21],[2,1.88,175.76]],"batl":[[0,2,4.77]],"ltp":2.0,"tv":6698.52,"id":8174357},{"batl":[[0,2.02,312.95],[1,2.04,184.13],[2,2.08,552.93]],"ltp":2.0,"tv":2224.02,"id":7412952}]}]}
{"op":"mcm","clk":"1004731574","pt":1580636268708,"mc":[{"id":"1.168209731","rc":[{"batl":[[0,2.06,518.5],[1,2.12,36.97],[2,2.3,10.13]],"ltp":2.0,"tv":6698.52,"id":8174357}]}]}
{"op":"mcm","clk":"1004731613","pt":1580636269842,"mc":[{"id":"1.168209731","rc":[{"batb":[[0,1.9,46.21],[1,1.88,195.97],[2,1.87,74.83]],"batl":[[0,2.12,36.97],[1,2.3,14.68],[2,2.5,10.13]],"ltp":2.0,"tv":6698.52,"id":8174357},{"batb":[[0,1.9,46.21],[1,1.79,80.41],[2,1.77,20.37]],"batl":[[0,2.1,37.81],[1,2.14,5.25],[2,2.2,7.41]],"ltp":2.0,"tv":2224.02,"id":7412952}]}]}
{"op":"mcm","clk":"1004731647","pt":1580636270523,"mc":[{"id":"1.168209731","rc":[{"batb":[[0,1.88,175.76],[1,1.87,74.83],[2,1.84,23.22]],"batl":[[0,2.3,14.68],[1,2.5,10.13],[2,3,42.01]],"ltp":2.0,"tv":6698.52,"id":8174357},{"batb":[[0,1.79,80.41],[1,1.77,20.37],[2,1.4,75.73]],"batl":[[0,2.2,7.41],[1,2.42,22.4],[2,2.5,10.13]],"ltp":2.0,"tv":2224.02,"id":7412952}]}]}
{"op":"mcm","clk":"1004731709","pt":1580636271952,"mc":[{"id":"1.168209731","rc":[{"batb":[[2,1.85,20.57]],"batl":[[0,2.26,4.52],[1,2.3,14.68],[2,2.5,10.13]],"ltp":2.0,"tv":6698.52,"id":8174357},{"batb":[[0,1.8,22.93],[1,1.79,80.41],[2,1.77,20.37]],"batl":[[0,2.18,5.25],[1,2.2,7.41],[2,2.42,22.4]],"ltp":2.0,"tv":2224.02,"id":7412952}]}]}
{"op":"mcm","clk":"1004731752","pt":1580636272842,"mc":[{"id":"1.168209731","rc":[{"batl":[[0,2.12,153.36],[1,2.14,160.25],[2,2.18,5.25]],"ltp":2.0,"tv":2224.02,"id":7412952}]}]}
{"op":"mcm","clk":"1004731795","pt":1580636273726,"mc":[{"id":"1.168209731","rc":[{"batl":[[0,2.18,5.25],[1,2.2,7.41],[2,2.42,22.4]],"ltp":2.0,"tv":2224.02,"id":7412952}]}]}
{"op":"mcm","clk":"1004731937","pt":1580636276858,"mc":[{"id":"1.168209731","rc":[{"batb":[[0,1.88,196.22]],"ltp":2.0,"tv":6698.52,"id":8174357},{"batb":[[0,1.9,170.52],[1,1.88,231.72],[2,1.8,22.93]],"batl":[[0,1.97,237.12],[1,1.99,198.19],[2,2.14,5.25]],"ltp":2.0,"tv":2224.02,"id":7412952}]}]}
{"op":"mcm","clk":"1004732192","pt":1580636282526,"mc":[{"id":"1.168209731","rc":[{"batb":[[0,1.88,175.76]],"ltp":2.0,"tv":6698.52,"id":8174357},{"batb":[[0,1.8,22.93],[1,1.79,80.41],[2,1.77,20.37]],"batl":[[0,2.18,5.25],[1,2.2,7.41],[2,2.42,22.4]],"ltp":2.0,"tv":2224.02,"id":7412952}]}]}
{"op":"mcm","clk":"1004732335","pt":1580636284956,"mc":[{"id":"1.168209731","rc":[{"batl":[[0,2.02,4],[1,2.26,4.52],[2,2.3,14.68]],"ltp":2.0,"tv":6698.52,"id":8174357}]}]}
{"op":"mcm","clk":"1004732372","pt":1580636285732,"mc":[{"id":"1.168209731","rc":[{"batb":[[0,1.88,196.72]],"batl":[[0,2.02,2]],"ltp":2.0,"tv":6698.52,"id":8174357},{"batl":[[0,2.12,153.36],[1,2.14,165.5],[2,2.18,5.25]],"ltp":2.0,"tv":2224.02,"id":7412952}]}]}
{"op":"mcm","clk":"1004732390","pt":1580636286245,"mc":[{"id":"1.168209731","rc":[{"batb":[[0,1.88,175.76]],"batl":[[0,2.26,4.52],[1,2.3,14.68],[2,2.5,10.13]],"ltp":2.0,"tv":6698.52,"id":8174357},{"batl":[[1,2.14,160.25]],"ltp":2.0,"tv":2224.02,"id":7412952}]}]}
{"op":"mcm","clk":"1004732440","pt":1580636287648,"mc":[{"id":"1.168209731","rc":[{"batl":[[0,2.18,5.25],[1,2.2,7.41],[2,2.42,22.4]],"ltp":2.0,"tv":2224.02,"id":7412952}]}]}
{"op":"mcm","clk":"1004732585","pt":1580636290850,"mc":[{"id":"1.168209731","rc":[{"batb":[[0,2.08,101],[1,1.88,175.76],[2,1.87,74.83]],"batl":[[1,2.28,8.57],[2,2.3,14.68]],"ltp":2.0,"tv":6698.52,"id":8174357},{"batl":[[0,1.82,254],[1,1.83,137.1],[2,1.84,252.17]],"ltp":2.0,"tv":2224.02,"id":7412952}]}]}
{"op":"mcm","clk":"1004732628","pt":1580636291736,"mc":[{"id":"1.168209731","rc":[{"batb":[[0,2.16,95.76],[1,2.1,2.59],[2,2.08,139.65]],"ltp":2.0,"tv":6698.52,"id":8174357},{"batb":[[0,1.81,2.56],[1,1.8,22.93],[2,1.79,80.41]],"ltp":2.0,"tv":2224.02,"id":7412952}]}]}
{"op":"mcm","clk":"1004733213","pt":1580636304771,"mc":[{"id":"1.168209731","rc":[{"batb":[[0,2.1,2.59],[1,2.08,38.65],[2,1.99,78.43]],"batl":[[0,2.3,10.13],[1,2.32,31.09],[2,2.5,10.13]],"ltp":2.0,"tv":6698.52,"id":8174357},{"batb":[[1,1.75,55.45],[2,1.74,494.03]],"batl":[[0,1.85,480.59],[1,1.87,497.4],[2,1.93,42.01]],"ltp":2.0,"tv":2224.02,"id":7412952}]}]}
{"op":"mcm","clk":"1004733224","pt":1580636305081,"mc":[{"id":"1.168209731","rc":[{"trd":[[2.24,2.07]],"batb":[[0,2.24,286.71],[1,2.1,2.59],[2,2.08,38.65]],"ltp":2.24,"tv":6700.59,"id":8174357},{"trd":[[1.81,2.56]],"batb":[[0,1.75,55.45],[1,1.74,494.03],[2,1.72,510.84]],"ltp":1.81,"tv":2226.58,"id":7412952}],"tv":8927.17}]}
{"op":"mcm","clk":"1004733280","pt":1580636306366,"mc":[{"id":"1.168209731","rc":[{"trd":[[2.24,66.93]],"batb":[[0,2.24,221.85],[2,1.99,78.43]],"batl":[[1,2.5,10.13],[2,2.94,2.75]],"ltp":2.24,"tv":6765.45,"id":8174357},{"trd":[[1.81,82.82]],"batb":[[0,1.74,494.03],[1,1.72,510.84],[2,1.6,119.36]],"batl":[[2,2.02,5.25]],"ltp":1.81,"tv":2306.84,"id":7412952}],"tv":9072.3}]}
{"op":"mcm","clk":"1004733326","pt":1580636307593,"mc":[{"id":"1.168209731","rc":[{"batl":[[2,1.99,210.32]],"ltp":1.81,"tv":2306.84,"id":7412952}]}]}
{"op":"mcm","clk":"1004733455","pt":1580636311087,"mc":[{"id":"1.168209731","rc":[{"batb":[[0,2.1,2.59],[1,1.99,78.43],[2,1.91,20.39]],"ltp":2.24,"tv":6765.45,"id":8174357}]}]}
{"op":"mcm","clk":"1004733518","pt":1580636312272,"mc":[{"id":"1.168209731","rc":[{"batl":[[0,1.99,210.32],[1,2.02,291.01],[2,2.1,4.85]],"ltp":1.81,"tv":2306.84,"id":7412952}]}]}
{"op":"mcm","clk":"1004733563","pt":1580636313296,"mc":[{"id":"1.168209731","rc":[{"batb":[[0,1.99,78.43],[1,1.91,20.39],[2,1.88,175.76]],"ltp":2.24,"tv":6765.45,"id":8174357}]}]}
{"op":"mcm","clk":"1004733624","pt":1580636314792,"mc":[{"id":"1.168209731","rc":[{"trd":[[2.3,443.68]],"batl":[[0,2.04,4634.77],[1,2.12,800.76],[2,2.5,10.13]],"ltp":2.3,"tv":7209.13,"id":8174357},{"batb":[[0,1.94,8.18],[1,1.87,1717.01],[2,1.74,494.03]],"batl":[[0,1.98,9.52],[1,1.99,210.32],[2,2.02,291.01]],"ltp":1.81,"tv":2306.84,"id":7412952}],"tv":9515.98}]}
{"op":"mcm","clk":"1004733662","pt":1580636315876,"mc":[{"id":"1.168209731","rc":[{"batb":[[1,1.94,44.53],[2,1.91,20.39]],"batl":[[0,2.04,190.13],[2,2.16,36.13]],"ltp":2.3,"tv":7209.13,"id":8174357},{"batb":[[0,1.94,70.89],[1,1.92,178.21],[2,1.9,224.11]],"batl":[[2,2,42.01]],"ltp":1.81,"tv":2306.84,"id":7412952}]}]}
{"op":"mcm","clk":"1004733670","pt":1580636316083,"mc":[{"id":"1.168209731","rc":[{"batb":[[1,1.91,20.39],[2,1.88,248.86]],"batl":[[2,2.5,10.13]],"ltp":2.3,"tv":7209.13,"id":8174357},{"batl":[[2,2.02,291.01]],"ltp":1.81,"tv":2306.84,"id":7412952}]}]}
{"op":"mcm","clk":"1004733774","pt":1580636318713,"mc":[{"id":"1.168209731","rc":[{"batb":[[0,1.99,61.92]],"batl":[[2,2.3,68.76]],"ltp":2.3,"tv":7209.13,"id":8174357}]}]}
{"op":"mcm","clk":"1004733815","pt":1580636319904,"mc":[{"id":"1.168209731","rc":[{"batb":[[1,1.94,44.53],[2,1.91,20.39]],"batl":[[2,2.16,40.02]],"ltp":2.3,"tv":7209.13,"id":8174357}]}]}
{"op":"mcm","clk":"1004733850","pt":1580636320684,"mc":[{"id":"1.168209731","rc":[{"batl":[[2,2.16,36.13]],"ltp":2.3,"tv":7209.13,"id":8174357}]}]}
{"op":"mcm","clk":"1004733948","pt":1580636322806,"mc":[{"id":"1.168209731","rc":[{"trd":[[2.04,1.92]],"batl":[[0,2.04,188.21]],"ltp":2.04,"tv":7211.05,"id":8174357},{"trd":[[1.96,2]],"ltp":1.96,"tv":2308.84,"id":7412952}],"tv":9519.9}]}
{"op":"mcm","clk":"1004733973","pt":1580636323730,"mc":[{"id":"1.168209731","rc":[{"trd":[[2.04,6.72]],"batl":[[0,2.04,183.41]],"ltp":2.04,"tv":7215.85,"id":8174357},{"trd":[[1.96,7]],"ltp":1.96,"tv":2313.84,"id":7412952}],"tv":9529.7}]}
{"op":"mcm","clk":"1004734003","pt":1580636324410,"mc":[{"id":"1.168209731","rc":[{"trd":[[2.04,16.33]],"batl":[[0,2.04,173.8]],"ltp":2.04,"tv":7225.46,"id":8174357},{"trd":[[1.96,17]],"ltp":1.96,"tv":2323.84,"id":7412952}],"tv":9549.31}]}
{"op":"mcm","clk":"1004734132","pt":1580636327411,"mc":[{"id":"1.168209731","rc":[{"trd":[[2.02,2]],"ltp":2.02,"tv":7227.46,"id":8174357},{"trd":[[1.98,70.09]],"batl":[[0,1.98,7.48]],"ltp":1.98,"tv":2325.88,"id":7412952}],"tv":9553.35}]}
{"op":"mcm","clk":"1004734488","pt":1580636333952,"mc":[{"id":"1.168209731","rc":[{"batl":[[1,2.16,36.13],[2,2.3,4.35]],"ltp":2.02,"tv":7227.46,"id":8174357},{"batb":[[0,1.94,62.71]],"batl":[[0,1.99,210.32],[1,2.02,291.01],[2,2.06,39.49]],"ltp":1.98,"tv":2325.88,"id":7412952}]}]}
{"op":"mcm","clk":"1004734533","pt":1580636334732,"mc":[{"id":"1.168209731","rc":[{"batb":[[0,1.88,266.82],[1,1.85,20.57],[2,1.84,23.22]],"batl":[[0,2.44,4.58],[1,2.5,10.13],[2,3,42.01]],"ltp":2.02,"tv":7227.46,"id":8174357},{"batb":[[0,1.78,82.54],[1,1.7,23.82],[2,1.4,75.73]],"batl":[[0,2.14,4.75],[1,2.18,5.25],[2,2.2,7.41]],"ltp":1.98,"tv":2325.88,"id":7412952}]}]}
{"op":"mcm","clk":"1004734686","pt":1580636337838,"mc":[{"id":"1.168209731","rc":[{"batl":[[0,2.3,4.55],[1,2.44,4.58],[2,2.5,10.13]],"ltp":2.02,"tv":7227.46,"id":8174357},{"batb":[[1,1.77,22.37],[2,1.74,293.42]],"batl":[[0,2.1,151.64],[1,2.12,164.62],[2,2.14,4.75]],"ltp":1.98,"tv":2325.88,"id":7412952}]}]}
{"op":"mcm","clk":"1004734698","pt":1580636338047,"mc":[{"id":"1.168209731","rc":[{"batl":[[0,2.44,4.58],[1,2.5,10.13],[2,3,42.01]],"ltp":2.02,"tv":7227.46,"id":8174357},{"batb":[[1,1.74,293.42],[2,1.72,310.92]],"ltp":1.98,"tv":2325.88,"id":7412952}]}]}
{"op":"mcm","clk":"1004735164","pt":1580636347954,"mc":[{"id":"1.168209731","rc":[{"batb":[[0,1.91,19.39],[1,1.88,266.82],[2,1.85,20.57]],"batl":[[0,2.3,4.45],[1,2.44,4.58],[2,2.5,10.13]],"ltp":2.02,"tv":7227.46,"id":8174357},{"batb":[[1,1.77,24.37],[2,1.74,293.42]],"ltp":1.98,"tv":2325.88,"id":7412952}]}]}
{"op":"mcm","clk":"1004735173","pt":1580636348157,"mc":[{"id":"1.168209731","rc":[{"batb":[[0,1.88,266.82],[1,1.85,20.57],[2,1.84,23.22]],"batl":[[0,2.44,4.58],[1,2.5,10.13],[2,3,42.01]],"ltp":2.02,"tv":7227.46,"id":8174357},{"batb":[[1,1.74,293.42],[2,1.72,310.92]],"ltp":1.98,"tv":2325.88,"id":7412952}]}]}
{"op":"mcm","clk":"1004735502","pt":1580636354867,"mc":[{"id":"1.168209731","rc":[{"batl":[[0,2.3,5.05],[1,2.44,4.58],[2,2.5,10.13]],"ltp":2.02,"tv":7227.46,"id":8174357},{"batb":[[1,1.77,23.37],[2,1.74,293.42]],"ltp":1.98,"tv":2325.88,"id":7412952}]}]}
{"op":"mcm","clk":"1004735511","pt":1580636355069,"mc":[{"id":"1.168209731","rc":[{"batl":[[0,2.44,4.58],[1,2.5,10.13],[2,3,42.01]],"ltp":2.02,"tv":7227.46,"id":8174357},{"batb":[[1,1.74,293.42],[2,1.72,310.92]],"ltp":1.98,"tv":2325.88,"id":7412952}]}]}
{"op":"mcm","clk":"1004735585","pt":1580636356783,"mc":[{"id":"1.168209731","rc":[{"batb":[[1,1.7,23.82],[2,1.4,75.73]],"batl":[[0,2.14,4.75],[1,2.18,5.25],[2,2.2,7.41]],"ltp":1.98,"tv":2325.88,"id":7412952}]}]}
{"op":"mcm","clk":"1004735709","pt":1580636359672,"mc":[{"id":"1.168209731","rc":[{"batb":[[0,1.91,156.59],[1,1.89,227.75],[2,1.88,266.82]],"batl":[[0,1.94,9.44],[1,1.98,240.31],[2,2,195.1]],"ltp":2.02,"tv":7227.46,"id":8174357},{"batb":[[0,2.04,105.49],[1,1.78,82.54],[2,1.7,23.82]],"batl":[[0,2.12,11.57],[1,2.14,4.75],[2,2.18,5.25]],"ltp":1.98,"tv":2325.88,"id":7412952}]}]}
{"op":"mcm","clk":"1004735754","pt":1580636360597,"mc":[{"id":"1.168209731","rc":[{"trd":[[1.94,380.14]],"batl":[[0,1.94,6.84]],"ltp":1.94,"tv":7232.65,"id":8174357},{"batb":[[0,2.04,211.32],[1,1.92,64.83]],"ltp":1.98,"tv":2325.88,"id":7412952}],"tv":9558.54}]}
{"op":"mcm","clk":"1004735806","pt":1580636361885,"mc":[{"id":"1.168209731","rc":[{"batb":[[1,1.95,43.69],[2,1.92,64.83]],"batl":[[2,2.18,40.54]],"ltp":1.98,"tv":2325.88,"id":7412952}]}]}
{"op":"mcm","clk":"1004736024","pt":1580636366372,"mc":[{"id":"1.168209731","rc":[{"batb":[[1,1.99,17.51],[2,1.95,64.4]],"batl":[[2,2.16,5.72]],"ltp":1.98,"tv":2325.88,"id":7412952}]}]}
{"op":"mcm","clk":"1004736194","pt":1580636370500,"mc":[{"id":"1.168209731","rc":[{"batl":[[0,1.98,240.31],[1,2,195.1],[2,2.02,6.75]],"ltp":1.94,"tv":7232.65,"id":8174357},{"batl":[[0,2.14,4.75],[1,2.16,5.72],[2,2.18,40.54]],"ltp":1.98,"tv":2325.88,"id":7412952}]}]}
{"op":"mcm","clk":"1004736318","pt":1580636373399,"mc":[{"id":"1.168209731","rc":[{"batb":[[0,2.06,7.89],[1,2.04,211.32],[2,1.99,17.51]],"batl":[[0,2.12,13.95],[1,2.14,4.75],[2,2.16,5.72]],"ltp":1.98,"tv":2325.88,"id":7412952}]}]}
{"op":"mcm","clk":"1004736616","pt":1580636379695,"mc":[{"id":"1.168209731","rc":[{"batb":[[0,1.88,175.76],[1,1.87,20.27],[2,1.85,20.57]],"batl":[[0,2.04,40.33],[1,2.06,5.75],[2,2.44,4.58]],"ltp":1.94,"tv":7232.65,"id":8174357},{"batb":[[0,1.95,64.4],[1,1.92,64.83],[2,1.7,23.82]],"batl":[[0,2.16,5.72],[1,2.18,40.54],[2,2.2,7.41]],"ltp":1.98,"tv":2325.88,"id":7412952}]}]}
{"op":"mcm","clk":"1004736659","pt":1580636380528,"mc":[{"id":"1.168209731","rc":[{"batl":[[0,2.06,5.75],[1,2.44,4.58],[2,2.5,10.13]],"ltp":1.94,"tv":7232.65,"id":8174357},{"batb":[[0,1.95,20.71]],"batl":[[1,2.18,5.25]],"ltp":1.98,"tv":2325.88,"id":7412952}]}]}
{"op":"mcm","clk":"1004736791","pt":1580636382896,"mc":[{"id":"1.168209731","rc":[{"batb":[[2,1.85,184.43]],"batl":[[0,2.02,5.75],[1,2.06,5.75],[2,2.12,258.53]],"ltp":1.94,"tv":7232.65,"id":8174357},{"batb":[[0,1.99,16.51],[1,1.95,20.71],[2,1.92,64.83]],"ltp":1.98,"tv":2325.88,"id":7412952}]}]}
{"op":"mcm","clk":"1004736801","pt":1580636383103,"mc":[{"id":"1.168209731","rc":[{"batl":[[0,2.06,5.75],[1,2.12,258.53],[2,2.14,160.39]],"ltp":1.94,"tv":7232.65,"id":8174357},{"batb":[[0,1.95,20.71],[1,1.92,64.83],[2,1.7,23.82]],"ltp":1.98,"tv":2325.88,"id":7412952}]}]}
{"op":"mcm","clk":"1004737047","pt":1580636386313,"mc":[{"id":"1.168209731","rc":[{"batl":[[0,2.02,5.25],[1,2.06,5.75],[2,2.12,258.53]],"ltp":1.94,"tv":7232.65,"id":8174357},{"batb":[[0,1.99,17.51],[1,1.95,20.71],[2,1.92,64.83]],"ltp":1.98,"tv":2325.88,"id":7412952}]}]}
{"op":"mcm","clk":"1004737590","pt":1580636397760,"mc":[{"id":"1.168209731","rc":[{"batl":[[0,2.06,5.75],[1,2.12,258.53],[2,2.14,160.39]],"ltp":1.94,"tv":7232.65,"id":8174357},{"batb":[[0,1.95,20.71],[1,1.92,64.83],[2,1.7,23.82]],"ltp":1.98,"tv":2325.88,"id":7412952}]}]}
{"op":"mcm","clk":"1004737644","pt":1580636398841,"mc":[{"id":"1.168209731","rc":[{"batb":[[2,1.85,20.57]],"batl":[[1,2.44,4.58],[2,2.5,10.13]],"ltp":1.94,"tv":7232.65,"id":8174357}]}]}
{"op":"mcm","clk":"1004737799","pt":1580636401940,"mc":[{"id":"1.168209731","rc":[{"batb":[[0,1.93,207.23],[1,1.91,220.41],[2,1.88,175.76]],"batl":[[0,1.96,10.37],[1,2,182.37],[2,2.02,189.48]],"ltp":1.94,"tv":7232.65,"id":8174357},{"batb":[[0,2.04,10.87],[1,1.95,20.71],[2,1.92,64.83]],"batl":[[0,2.08,9.94],[1,2.16,5.72],[2,2.18,5.25]],"ltp":1.98,"tv":2325.88,"id":7412952}]}]}
{"op":"mcm","clk":"1004737826","pt":1580636402457,"mc":[{"id":"1.168209731","rc":[{"batb":[[0,1.93,197.3]],"batl":[[0,2,182.37],[1,2.02,189.48],[2,2.06,5.75]],"ltp":1.94,"tv":7232.65,"id":8174357},{"batb":[[0,1.95,20.71],[1,1.92,64.83],[2,1.7,23.82]],"batl":[[0,2.16,5.72],[1,2.18,5.25],[2,2.2,7.41]],"ltp":1.98,"tv":2325.88,"id":7412952}]}]}
{"op":"mcm","clk":"1004737917","pt":1580636404363,"mc":[{"id":"1.168209731","rc":[{"batl":[[1,2.02,195.23]],"ltp":1.94,"tv":7232.65,"id":8174357},{"batb":[[0,1.99,16.51],[1,1.95,20.71],[2,1.92,64.83]],"ltp":1.98,"tv":2325.88,"id":7412952}]}]}
{"op":"mcm","clk":"1004738093","pt":1580636408739,"mc":[{"id":"1.168209731","rc":[{"batb":[[0,1.88,175.76],[1,1.87,20.27],[2,1.85,20.57]],"batl":[[0,2.06,5.75],[1,2.44,4.58],[2,2.5,10.13]],"ltp":1.94,"tv":7232.65,"id":8174357},{"batb":[[0,1.95,20.71],[1,1.92,64.83],[2,1.7,23.82]],"ltp":1.98,"tv":2325.88,"id":7412952}]}]}
{"op":"mcm","clk":"1004738230","pt":1580636411473,"mc":[{"id":"1.168209731","rc":[{"batb":[[2,1.85,184.43]],"batl":[[1,2.12,258.53],[2,2.14,160.39]],"ltp":1.94,"tv":7232.65,"id":8174357}]}]}
{"op":"mcm","clk":"1004738584","pt":1580636418787,"mc":[{"id":"1.168209731","rc":[{"batl":[[0,2.02,6.75],[1,2.06,5.75],[2,2.12,258.53]],"ltp":1.94,"tv":7232.65,"id":8174357},{"batb":[[0,1.99,17.51],[1,1.95,20.71],[2,1.92,64.83]],"ltp":1.98,"tv":2325.88,"id":7412952}]}]}
{"op":"mcm","clk":"1004738599","pt":1580636419097,"mc":[{"id":"1.168209731","rc":[{"batl":[[0,2.06,5.75],[1,2.12,258.53],[2,2.14,160.39]],"ltp":1.94,"tv":7232.65,"id":8174357},{"batb":[[0,1.95,20.71],[1,1.92,64.83],[2,1.7,23.82]],"ltp":1.98,"tv":2325.88,"id":7412952}]}]}
{"op":"mcm","clk":"1004738718","pt":1580636421781,"mc":[{"id":"1.168209731","rc":[{"batl":[[1,2.5,10.13],[2,3,42.01]],"ltp":1.94,"tv":7232.65,"id":8174357},{"batb":[[2,1.5,75.72]],"batl":[[2,2.2,2.53]],"ltp":1.98,"tv":2325.88,"id":7412952}]}]}
{"op":"mcm","clk":"1004738883","pt":1580636424923,"mc":[{"id":"1.168209731","rc":[{"trd":[[1.88,261.79]],"batb":[[0,1.88,71.69]],"batl":[[0,1.89,462.04],[1,1.91,187.09],[2,1.93,217.16]],"ltp":1.88,"tv":7336.72,"id":8174357},{"trd":[[2.14,91.43]],"batb":[[0,2.1,91.15],[1,2.06,204.68],[2,1.95,20.71]],"batl":[[2,2.2,9.3]],"ltp":2.14,"tv":2417.31,"id":7412952}],"tv":9754.04}]}
{"op":"mcm","clk":"1004738929","pt":1580636425494,"mc":[{"id":"1.168209731","rc":[{"trd":[[1.88,369.49]],"batb":[[0,1.88,17.85],[1,1.85,184.43],[2,1.83,252.35]],"ltp":1.88,"tv":7444.42,"id":8174357},{"batb":[[2,2.04,40.33]],"batl":[[0,2.18,5.25],[1,2.2,9.3],[2,2.28,445.92]],"ltp":2.14,"tv":2417.31,"id":7412952}],"tv":9861.74}]}
{"op":"mcm","clk":"1004739078","pt":1580636428495,"mc":[{"id":"1.168209731","rc":[{"trd":[[1.88,396.27]],"batb":[[0,1.88,4.45]],"ltp":1.88,"tv":7471.2,"id":8174357}],"tv":9888.52}]}
{"op":"mcm","clk":"1004739336","pt":1580636433714,"mc":[{"id":"1.168209731","rc":[{"batb":[[1,1.85,20.57],[2,1.82,81.2]],"ltp":1.88,"tv":7471.2,"id":8174357},{"batb":[[0,2.12,94.81],[1,2.1,91.15],[2,2.06,100.98]],"ltp":2.14,"tv":2417.31,"id":7412952}]}]}
{"op":"mcm","clk":"1004739355","pt":1580636434128,"mc":[{"id":"1.168209731","rc":[{"trd":[[1.89,123.68]],"batl":[[0,1.89,338.36]],"ltp":1.89,"tv":7594.88,"id":8174357},{"trd":[[2.12,464.37]],"batb":[[0,2.1,91.15],[1,2.06,100.98],[2,2.04,147.81]],"ltp":2.12,"tv":2717.19,"id":7412952}],"tv":10312.08}]}
{"op":"mcm","clk":"1004739460","pt":1580636436592,"mc":[{"id":"1.168209731","rc":[{"batb":[[2,1.84,276.93]],"ltp":1.89,"tv":7594.88,"id":8174357}]}]}
{"op":"mcm","clk":"1004739526","pt":1580636438033,"mc":[{"id":"1.168209731","rc":[{"trd":[[1.89,237.42]],"batl":[[0,1.89,224.62]],"ltp":1.89,"tv":7708.62,"id":8174357},{"trd":[[2.12,565.67]],"ltp":2.12,"tv":2818.49,"id":7412952}],"tv":10527.12}]}
{"op":"mcm","clk":"1004739657","pt":1580636441325,"mc":[{"id":"1.168209731","rc":[{"batb":[[2,1.84,355.38]],"ltp":1.89,"tv":7708.62,"id":8174357},{"batb":[[0,2.1,189.5],[2,2.04,40.33]],"ltp":2.12,"tv":2818.49,"id":7412952}]}]}
{"op":"mcm","clk":"1004739740","pt":1580636442913,"mc":[{"id":"1.168209731","rc":[{"trd":[[1.89,243.03]],"batl":[[0,1.89,219.01]],"ltp":1.89,"tv":7714.23,"id":8174357},{"trd":[[2.12,570.67]],"ltp":2.12,"tv":2823.49,"id":7412952}],"tv":10537.73}]}
{"op":"mcm","clk":"1004739837","pt":1580636444622,"mc":[{"id":"1.168209731","rc":[{"trd":[[1.88,405.18]],"batb":[[0,1.85,20.57],[1,1.84,355.38],[2,1.82,338.3]],"batl":[[0,1.88,4.79],[1,1.89,219.01],[2,1.91,187.09]],"ltp":1.88,"tv":7723.14,"id":8174357}],"tv":10546.63}]}
{"op":"mcm","clk":"1004740024","pt":1580636448646,"mc":[{"id":"1.168209731","rc":[{"trd":[[1.88,407.43]],"batl":[[0,1.88,16.05]],"ltp":1.88,"tv":7725.39,"id":8174357},{"trd":[[2.12,572.67]],"ltp":2.12,"tv":2825.49,"id":7412952}],"tv":10550.89}]}
{"op":"mcm","clk":"1004740245","pt":1580636453130,"mc":[{"id":"1.168209731","rc":[{"trd":[[1.85,18.48]],"batb":[[0,1.85,11.33]],"ltp":1.85,"tv":7743.87,"id":8174357}],"tv":10569.37}]}
{"op":"mcm","clk":"1004740540","pt":1580636459165,"mc":[{"id":"1.168209731","rc":[{"trd":[[1.88,411.43]],"batl":[[0,1.88,14.05]],"ltp":1.88,"tv":7747.87,"id":8174357}],"tv":10573.37}]}
{"op":"mcm","clk":"1004740690","pt":1580636461738,"mc":[{"id":"1.168209731","rc":[{"batb":[[1,1.84,78.45],[2,1.82,81.2]],"batl":[[2,1.95,42.01]],"ltp":1.88,"tv":7747.87,"id":8174357}]}]}
{"op":"mcm","clk":"1004741428","pt":1580636475862,"mc":[{"id":"1.168209731","rc":[{"batl":[[1,1.89,21.04]],"ltp":1.88,"tv":7747.87,"id":8174357},{"batl":[[2,2.28,32.92]],"ltp":2.12,"tv":2825.49,"id":7412952}]}]}
{"op":"mcm","clk":"1004741464","pt":1580636476585,"mc":[{"id":"1.168209731","rc":[{"batb":[[0,1.8,378.93],[1,1.79,39.86],[2,1.74,356.64]],"batl":[[1,1.97,160.93],[2,1.99,198.1]],"ltp":1.88,"tv":7747.87,"id":8174357},{"batb":[[0,2.02,111.41],[1,1.95,20.71],[2,1.5,75.72]],"batl":[[0,2.2,2.53],[1,2.42,22.4],[2,2.5,10.13]],"ltp":2.12,"tv":2825.49,"id":7412952}]}]}
{"op":"mcm","clk":"1004741601","pt":1580636479380,"mc":[{"id":"1.168209731","rc":[{"batb":[[2,1.77,20.37]],"batl":[[1,1.93,19.07],[2,1.95,18.9]],"ltp":1.88,"tv":7747.87,"id":8174357},{"batb":[[0,2.04,5.37],[1,2.02,111.41]],"batl":[[1,2.3,4.8],[2,2.36,4.82]],"ltp":2.12,"tv":2825.49,"id":7412952}]}]}
{"op":"mcm","clk":"1004741637","pt":1580636480098,"mc":[{"id":"1.168209731","rc":[{"batl":[[0,1.85,2.52],[1,1.88,14.05],[2,1.93,19.07]],"ltp":1.88,"tv":7747.87,"id":8174357}]}]}
{"op":"mcm","clk":"1004741853","pt":1580636483492,"mc":[{"id":"1.168209731","rc":[{"batb":[[2,1.6,75.72]],"ltp":2.12,"tv":2825.49,"id":7412952}]}]}
{"op":"mcm","clk":"1004742081","pt":1580636485821,"mc":[{"id":"1.168209731","rc":[{"batb":[[0,2.06,5.58],[1,2.04,5.37],[2,2.02,111.41]],"ltp":2.12,"tv":2825.49,"id":7412952}]}]}
{"op":"mcm","clk":"1004742090","pt":1580636485980,"mc":[{"id":"1.168209731","rc":[{"batb":[[0,2.04,5.37],[1,2.02,111.41],[2,1.6,75.72]],"ltp":2.12,"tv":2825.49,"id":7412952}]}]}
{"op":"mcm","clk":"1004742236","pt":1580636488912,"mc":[{"id":"1.168209731","rc":[{"trd":[[1.85,21],[1.88,425.48]],"batl":[[0,1.93,19.07],[1,1.95,18.9],[2,1.97,160.93]],"ltp":1.88,"tv":7764.44,"id":8174357},{"trd":[[2.12,585.13],[2.16,2.16]],"batl":[[0,2.12,637.11],[1,2.2,2.53],[2,2.3,4.8]],"ltp":2.12,"tv":2840.11,"id":7412952}],"tv":10604.56}]}
{"op":"mcm","clk":"1004742270","pt":1580636489428,"mc":[{"id":"1.168209731","rc":[{"batl":[[0,1.95,18.9],[1,1.97,160.93],[2,1.99,198.1]],"ltp":1.88,"tv":7764.44,"id":8174357},{"batb":[[2,1.5,75.72]],"ltp":2.12,"tv":2840.11,"id":7412952}]}]}
{"op":"mcm","clk":"1004742433","pt":1580636492926,"mc":[{"id":"1.168209731","rc":[{"batb":[[0,1.9,249.34],[1,1.88,231.7],[2,1.8,378.93]],"batl":[[1,1.96,538.99],[2,1.97,160.93]],"ltp":1.88,"tv":7764.44,"id":8174357},{"batb":[[0,2.06,7.62],[1,2.04,5.37],[2,2.02,111.41]],"batl":[[0,2.12,651.32],[1,2.16,567.68],[2,2.18,83.99]],"ltp":2.12,"tv":2840.11,"id":7412952}]}]}
{"op":"mcm","clk":"1004742458","pt":1580636493490,"mc":[{"id":"1.168209731","rc":[{"batb":[[0,1.91,69.55],[1,1.9,249.34],[2,1.88,231.7]],"ltp":1.88,"tv":7764.44,"id":8174357}]}]}
{"op":"mcm","clk":"1004742846","pt":1580636499648,"mc":[{"id":"1.168209731","rc":[{"trd":[[1.91,3.36]],"batb":[[0,1.91,67.87]],"batl":[[2,1.97,179.43]],"ltp":1.91,"tv":7767.8,"id":8174357},{"batb":[[2,2.02,116.65]],"batl":[[2,2.18,89.74]],"ltp":2.12,"tv":2840.11,"id":7412952}],"tv":10607.92}]}
{"op":"mcm","clk":"1004743438","pt":1580636508940,"mc":[{"id":"1.168209731","rc":[{"batl":[[1,2.16,83.68]],"ltp":2.12,"tv":2840.11,"id":7412952}]}]}
{"op":"mcm","clk":"1004743491","pt":1580636509555,"mc":[{"id":"1.168209731","rc":[{"batb":[[0,1.86,18.18],[1,1.83,70.97],[2,1.82,81.36]],"batl":[[0,1.99,16.5],[1,2,42.01],[2,2.3,309.75]],"ltp":1.91,"tv":7767.8,"id":8174357},{"batb":[[0,2,57.93],[1,1.94,62.32],[2,1.5,75.72]],"batl":[[0,2.12,637.11],[1,2.2,36.98],[2,2.22,4.9]],"ltp":2.12,"tv":2840.11,"id":7412952}]}]}
{"op":"mcm","clk":"1004743570","pt":1580636510742,"mc":[{"id":"1.168209731","rc":[{"batb":[[1,1.83,20.56]],"batl":[[1,2.3,309.75],[2,2.5,10.13]],"ltp":1.91,"tv":7767.8,"id":8174357},{"batb":[[0,2,15.92],[2,1.05,152.41]],"batl":[[1,2.2,2.53]],"ltp":2.12,"tv":2840.11,"id":7412952}]}]}
{"op":"mcm","clk":"1004743724","pt":1580636512955,"mc":[{"id":"1.168209731","rc":[{"batl":[[1,2.04,311.22],[2,2.06,178.91]],"ltp":1.91,"tv":7767.8,"id":8174357},{"batb":[[1,1.95,61.84],[2,1.94,62.32]],"ltp":2.12,"tv":2840.11,"id":7412952}]}]}
{"op":"mcm","clk":"1004743789","pt":1580636513937,"mc":[{"id":"1.168209731","rc":[{"batb":[[2,1.81,353.85]],"ltp":1.91,"tv":7767.8,"id":8174357},{"batb":[[2,1.05,152.41]],"batl":[[0,2.06,2.27],[1,2.12,637.11],[2,2.2,2.53]],"ltp":2.12,"tv":2840.11,"id":7412952}]}]}
{"op":"mcm","clk":"1004743892","pt":1580636515949,"mc":[{"id":"1.168209731","rc":[{"batl":[[0,1.97,19.5],[1,1.99,16.5],[2,2.04,311.22]],"ltp":1.91,"tv":7767.8,"id":8174357}]}]}
{"op":"mcm","clk":"1004743925","pt":1580636516566,"mc":[{"id":"1.168209731","rc":[{"batl":[[0,1.99,16.5],[1,2.04,311.22],[2,2.06,178.91]],"ltp":1.91,"tv":7767.8,"id":8174357}]}]}
{"op":"mcm","clk":"1004744108","pt":1580636519675,"mc":[{"id":"1.168209731","rc":[{"batb":[[2,1.82,378.93]],"ltp":1.91,"tv":7767.8,"id":8174357}]}]}
{"op":"mcm","clk":"1004744127","pt":1580636519982,"mc":[{"id":"1.168209731","rc":[{"batl":[[0,2.12,637.11],[1,2.2,2.53],[2,2.22,4.9]],"ltp":2.12,"tv":2840.11,"id":7412952}]}]}
{"op":"mcm","clk":"1004744506","pt":1580636525882,"mc":[{"id":"1.168209731","rc":[{"batl":[[0,1.97,16.5],[1,1.99,16.5],[2,2.04,311.22]],"ltp":1.91,"tv":7767.8,"id":8174357},{"batb":[[0,2.02,6.24],[1,2,15.92],[2,1.95,61.84]],"batl":[[1,2.18,5.75],[2,2.2,2.53]],"ltp":2.12,"tv":2840.11,"id":7412952}]}]}
{"op":"mcm","clk":"1004744518","pt":1580636526084,"mc":[{"id":"1.168209731","rc":[{"batl":[[0,1.99,16.5],[1,2.04,311.22],[2,2.06,178.91]],"ltp":1.91,"tv":7767.8,"id":8174357},{"batb":[[0,2,15.92],[1,1.95,61.84],[2,1.05,152.41]],"batl":[[1,2.2,2.53],[2,2.22,4.9]],"ltp":2.12,"tv":2840.11,"id":7412952}]}]}
{"op":"mcm","clk":"1004744759","pt":1580636530186,"mc":[{"id":"1.168209731","rc":[{"batl":[[1,2.3,309.75],[2,2.5,10.13]],"ltp":1.91,"tv":7767.8,"id":8174357}]}]}
{"op":"mcm","clk":"1004744922","pt":1580636532906,"mc":[{"id":"1.168209731","rc":[{"trd":[[1.98,53.47]],"batb":[[0,1.93,96.21],[1,1.86,18.18],[2,1.83,20.56]],"batl":[[0,1.97,15.92],[1,1.99,16.5],[2,2.02,382.3]],"ltp":1.98,"tv":7768.38,"id":8174357},{"trd":[[2.02,604.42]],"batl":[[0,2.08,489],[1,2.1,101.7],[2,2.12,1336.17]],"ltp":2.02,"tv":2853.16,"id":7412952}],"tv":10621.55}]}
{"op":"mcm","clk":"1004745011","pt":1580636533898,"mc":[{"id":"1.168209731","rc":[{"batb":[[0,1.98,62.79],[1,1.95,234.94],[2,1.93,309.64]],"batl":[[0,1.99,16.5],[1,2.02,382.3],[2,2.04,311.22]],"ltp":1.98,"tv":7768.38,"id":8174357},{"batb":[[2,1.94,44.53]],"ltp":2.02,"tv":2853.16,"id":7412952}]}]}
{"op":"mcm","clk":"1004745474","pt":1580636539899,"mc":[{"id":"1.168209731","rc":[{"batl":[[0,2.1,101.7],[1,2.12,1336.17],[2,2.14,36.13]],"ltp":2.02,"tv":2853.16,"id":7412952}]}]}
{"op":"mcm","clk":"1004745549","pt":1580636540680,"mc":[{"id":"1.168209731","rc":[{"batb":[[0,1.89,71.92],[1,1.88,20.21],[2,1.82,378.93]],"batl":[[0,2.04,5.63],[1,2.3,309.75],[2,2.5,10.13]],"ltp":1.98,"tv":7768.38,"id":8174357},{"batb":[[0,1.97,20.17],[1,1.9,66.88],[2,1.05,152.41]],"batl":[[0,2.12,637.11],[1,2.14,5.25],[2,2.2,2.53]],"ltp":2.02,"tv":2853.16,"id":7412952}]}]}
{"op":"mcm","clk":"1004745734","pt":1580636543891,"mc":[{"id":"1.168209731","rc":[{"batb":[[0,1.91,22.39],[1,1.89,71.92],[2,1.88,269.18]],"batl":[[1,2.08,301.87],[2,2.1,169.29]],"ltp":1.98,"tv":7768.38,"id":8174357},{"batl":[[0,2.1,4.85],[1,2.12,637.11],[2,2.14,5.25]],"ltp":2.02,"tv":2853.16,"id":7412952}]}]}
{"op":"mcm","clk":"1004745747","pt":1580636544093,"mc":[{"id":"1.168209731","rc":[{"batb":[[0,1.89,71.92],[1,1.88,20.21],[2,1.82,378.93]],"batl":[[1,2.3,309.75],[2,2.5,10.13]],"ltp":1.98,"tv":7768.38,"id":8174357},{"batl":[[0,2.12,637.11],[1,2.14,5.25],[2,2.2,2.53]],"ltp":2.02,"tv":2853.16,"id":7412952}]}]}
{"op":"mcm","clk":"1004745836","pt":1580636545694,"mc":[{"id":"1.168209731","rc":[{"batl":[[1,2.5,10.13],[2,3,42.01]],"ltp":1.98,"tv":7768.38,"id":8174357}]}]}
{"op":"mcm","clk":"1004745904","pt":1580636546928,"mc":[{"id":"1.168209731","rc":[{"trd":[[2.02,7.75]],"batl":[[1,2.06,8.23],[2,2.08,370.77]],"ltp":2.02,"tv":7774.13,"id":8174357},{"trd":[[1.98,79.14]],"batb":[[0,1.99,16.92],[1,1.97,20.17],[2,1.9,66.88]],"batl":[[0,2.02,1467.37],[1,2.04,540.8],[2,2.06,975.86]],"ltp":1.98,"tv":2862.21,"id":7412952}],"tv":10636.35}]}
{"op":"mcm","clk":"1004745953","pt":1580636547910,"mc":[{"id":"1.168209731","rc":[{"batb":[[0,2.02,115.98],[1,1.96,64.36],[2,1.93,44.53]],"ltp":2.02,"tv":7774.13,"id":8174357},{"batb":[[0,1.97,20.17],[1,1.94,173.07],[2,1.92,216.9]],"batl":[[0,2.02,862.76],[1,2.04,724.95],[2,2.06,97.59]],"ltp":1.98,"tv":2862.21,"id":7412952}]}]}
{"op":"mcm","clk":"1004746200","pt":1580636553616,"mc":[{"id":"1.168209731","rc":[{"batb":[[2,1.95,18.71]],"batl":[[1,2.06,14.48]],"ltp":2.02,"tv":7774.13,"id":8174357},{"batb":[[1,1.96,16.63],[2,1.95,18.71]],"batl":[[2,2.06,104.01]],"ltp":1.98,"tv":2862.21,"id":7412952}]}]}
{"op":"mcm","clk":"1004746371","pt":1580636557022,"mc":[{"id":"1.168209731","rc":[{"batl":[[1,2.06,6.25]],"ltp":2.02,"tv":7774.13,"id":8174357}]}]}
{"op":"mcm","clk":"1004746555","pt":1580636560842,"mc":[{"id":"1.168209731","rc":[{"batb":[[0,1.96,64.36],[1,1.91,21.39],[2,1.88,20.21]],"batl":[[0,2.5,10.13],[1,2.72,241.55],[2,3,42.01]],"ltp":2.02,"tv":7774.13,"id":8174357},{"batb":[[0,1.95,18.71],[1,1.86,70.97],[2,1.05,152.41]],"batl":[[0,2.1,6.35],[1,2.12,637.11],[2,2.14,5.25]],"ltp":1.98,"tv":2862.21,"id":7412952}]}]}
{"op":"mcm","clk":"1004746691","pt":1580636563836,"mc":[{"id":"1.168209731","rc":[{"batb":[[1,1.95,15.91],[2,1.91,21.39]],"ltp":2.02,"tv":7774.13,"id":8174357},{"batb":[[1,1.91,245.09],[2,1.89,227.93]],"batl":[[0,2.06,161.29],[1,2.08,173.97],[2,2.1,6.35]],"ltp":1.98,"tv":2862.21,"id":7412952}]}]}
{"op":"mcm","clk":"1004746728","pt":1580636564511,"mc":[{"id":"1.168209731","rc":[{"batl":[[0,1.97,2.27],[1,2.06,161.29],[2,2.08,173.97]],"ltp":1.98,"tv":2862.21,"id":7412952}]}]}
{"op":"mcm","clk":"1004746817","pt":1580636566630,"mc":[{"id":"1.168209731","rc":[{"batb":[[0,1.96,81.74]],"batl":[[0,2.06,5.25],[1,2.08,6.19],[2,2.5,10.13]],"ltp":2.02,"tv":7774.13,"id":8174357},{"batb":[[0,1.96,16.13],[1,1.95,18.71],[2,1.91,245.09]],"batl":[[0,2.06,161.29],[1,2.08,173.97],[2,2.1,6.35]],"ltp":1.98,"tv":2862.21,"id":7412952}]}]}
{"op":"mcm","clk":"1004746976","pt":1580636569628,"mc":[{"id":"1.168209731","rc":[{"batb":[[2,1.94,20.42]],"ltp":1.98,"tv":2862.21,"id":7412952}]}]}
{"op":"mcm","clk":"1004747267","pt":1580636574860,"mc":[{"id":"1.168209731","rc":[{"batb":[[0,1.96,64.36],[1,1.91,21.39],[2,1.88,20.21]],"batl":[[0,2.08,6.19],[1,2.5,10.13],[2,2.72,241.55]],"ltp":2.02,"tv":7774.13,"id":8174357},{"batb":[[0,1.95,18.71],[1,1.91,245.09],[2,1.89,227.93]],"batl":[[0,2.1,6.35],[1,2.12,637.11],[2,2.14,5.25]],"ltp":1.98,"tv":2862.21,"id":7412952}]}]}
{"op":"mcm","clk":"1004747399","pt":1580636577550,"mc":[{"id":"1.168209731","rc":[{"batb":[[0,2.02,2],[1,2,297.35],[2,1.99,132.58]],"batl":[[1,2.16,370],[2,2.2,34.45]],"ltp":2.02,"tv":7774.13,"id":8174357},{"batb":[[1,1.92,9.46],[2,1.91,245.09]],"batl":[[0,1.96,8.82],[1,1.98,630.31],[2,2,492.64]],"ltp":1.98,"tv":2862.21,"id":7412952}]}]}
{"op":"mcm","clk":"1004747437","pt":1580636578268,"mc":[{"id":"1.168209731","rc":[{"trd":[[2.06,17.71]],"batb":[[0,2.06,91.58],[1,2.02,2],[2,2,297.35]],"ltp":2.06,"tv":7791.84,"id":8174357},{"trd":[[1.95,18.71]],"batb":[[0,1.92,9.46],[1,1.91,245.09],[2,1.89,629.26]],"ltp":1.95,"tv":2880.92,"id":7412952}],"tv":10672.77}]}
{"op":"mcm","clk":"1004747773","pt":1580636584881,"mc":[{"id":"1.168209731","rc":[{"batl":[[2,2.2,38.58]],"ltp":2.06,"tv":7791.84,"id":8174357}]}]}
{"op":"mcm","clk":"1004747958","pt":1580636588189,"mc":[{"id":"1.168209731","rc":[{"trd":[[2.06,21.37]],"batb":[[0,2.06,89.75]],"ltp":2.06,"tv":7795.5,"id":8174357}],"tv":10676.43}]}
{"op":"mcm","clk":"1004748209","pt":1580636592280,"mc":[{"id":"1.168209731","rc":[{"trd":[[2.06,26.11]],"batb":[[0,2.06,85.01]],"ltp":2.06,"tv":7800.24,"id":8174357},{"trd":[[1.95,23.71]],"ltp":1.95,"tv":2885.92,"id":7412952}],"tv":10686.16}]}
{"op":"mcm","clk":"1004748406","pt":1580636595907,"mc":[{"id":"1.168209731","rc":[{"trd":[[1.92,10.14]],"batb":[[0,1.92,4.39]],"ltp":1.92,"tv":2896.06,"id":7412952}],"tv":10696.3}]}
{"op":"mcm","clk":"1004748419","pt":1580636596072,"mc":[{"id":"1.168209731","rc":[{"batl":[[0,1.94,27.02],[1,1.96,8.82],[2,1.98,630.31]],"ltp":1.92,"tv":2896.06,"id":7412952}]}]}
{"op":"mcm","clk":"1004748954","pt":1580636606892,"mc":[{"id":"1.168209731","rc":[{"trd":[[2.06,32.83]],"batb":[[0,2.06,81.65]],"ltp":2.06,"tv":7806.96,"id":8174357},{"batb":[[0,1.91,245.09],[1,1.89,629.26],[2,1.87,70.89]],"batl":[[1,1.98,630.31],[2,2,492.64]],"ltp":1.92,"tv":2896.06,"id":7412952}],"tv":10703.02}]}
{"op":"mcm","clk":"1004748960","pt":1580636606997,"mc":[{"id":"1.168209731","rc":[{"batl":[[0,1.98,630.31],[1,2,492.64],[2,2.02,41.17]],"ltp":1.92,"tv":2896.06,"id":7412952}]}]}
{"op":"mcm","clk":"1004749109","pt":1580636609830,"mc":[{"id":"1.168209731","rc":[{"batb":[[0,1.99,103.7],[1,1.93,17.93],[2,1.91,21.39]],"batl":[[0,2.2,34.45],[1,2.5,10.13],[2,2.72,241.55]],"ltp":2.06,"tv":7806.96,"id":8174357},{"batb":[[0,1.84,49.57],[1,1.78,23.16],[2,1.74,88.12]],"batl":[[0,2.02,41.17],[1,2.08,6.19],[2,2.1,6.35]],"ltp":1.92,"tv":2896.06,"id":7412952}]}]}
{"op":"mcm","clk":"1004749160","pt":1580636610812,"mc":[{"id":"1.168209731","rc":[{"batb":[[0,1.99,61.69],[1,1.9,21.66],[2,1.88,20.21]],"batl":[[0,2.5,10.13],[1,2.72,241.55],[2,3,42.01]],"ltp":2.06,"tv":7806.96,"id":8174357},{"batb":[[0,1.78,23.16],[1,1.74,88.12],[2,1.1,378.83]],"batl":[[0,1.92,27.02],[1,2.12,642.32],[2,2.14,5.25]],"ltp":1.92,"tv":2896.06,"id":7412952}]}]}
{"op":"mcm","clk":"1004749257","pt":1580636612914,"mc":[{"id":"1.168209731","rc":[{"batb":[[1,1.98,62.39],[2,1.9,21.66]],"batl":[[0,2.22,4.75],[1,2.3,4.15],[2,2.5,10.13]],"ltp":2.06,"tv":7806.96,"id":8174357},{"batb":[[0,1.82,21.14],[1,1.8,195.39],[2,1.78,299.87]],"batl":[[1,2.06,235.13],[2,2.08,174]],"ltp":1.92,"tv":2896.06,"id":7412952}]}]}
{"op":"mcm","clk":"1004749301","pt":1580636613899,"mc":[{"id":"1.168209731","rc":[{"batb":[[0,1.98,62.39],[1,1.93,20.93]],"batl":[[0,2.3,4.15],[1,2.5,10.13],[2,2.72,241.55]],"ltp":2.06,"tv":7806.96,"id":8174357},{"batb":[[0,1.8,195.39],[1,1.78,299.87],[2,1.75,87.18]],"batl":[[2,2.08,179.19]],"ltp":1.92,"tv":2896.06,"id":7412952}]}]}
{"op":"mcm","clk":"1004749429","pt":1580636616418,"mc":[{"id":"1.168209731","rc":[{"batl":[[0,2.22,5.25],[1,2.3,4.15],[2,2.5,10.13]],"ltp":2.06,"tv":7806.96,"id":8174357},{"batb":[[0,1.82,22.14],[1,1.8,195.39],[2,1.78,299.87]],"ltp":1.92,"tv":2896.06,"id":7412952}]}]}
{"op":"mcm","clk":"1004749837","pt":1580636625642,"mc":[{"id":"1.168209731","rc":[{"batl":[[0,2.5,10.13],[1,2.72,241.55],[2,3,42.01]],"ltp":2.06,"tv":7806.96,"id":8174357},{"batb":[[0,1.8,195.39],[1,1.78,299.87],[2,1.75,87.18]],"ltp":1.92,"tv":2896.06,"id":7412952}]}]}
{"op":"mcm","clk":"1004749952","pt":1580636628937,"mc":[{"id":"1.168209731","rc":[{"batl":[[0,2.3,4.45],[1,2.5,10.13],[2,2.72,241.55]],"ltp":2.06,"tv":7806.96,"id":8174357},{"batb":[[0,1.82,19.14],[1,1.8,195.39],[2,1.78,299.87]],"ltp":1.92,"tv":2896.06,"id":7412952}]}]}
{"op":"mcm","clk":"1004749957","pt":1580636629030,"mc":[{"id":"1.168209731","rc":[{"batb":[[0,1.8,195.39],[1,1.78,299.87],[2,1.75,87.18]],"ltp":1.92,"tv":2896.06,"id":7412952}]}]}
{"op":"mcm","clk":"1004750172","pt":1580636634728,"mc":[{"id":"1.168209731","rc":[{"batb":[[1,1.9,21.66],[2,1.88,20.21]],"ltp":2.06,"tv":7806.96,"id":8174357},{"batb":[[0,1.78,23.16],[1,1.75,87.18],[2,1.63,5.07]],"batl":[[1,2.12,642.32],[2,2.14,5.25]],"ltp":1.92,"tv":2896.06,"id":7412952}]}]}
{"op":"mcm","clk":"1004750289","pt":1580636637756,"mc":[{"id":"1.168209731","rc":[{"batb":[[1,1.95,179.16],[2,1.93,213.42]],"batl":[[0,2.02,195.82],[1,2.04,184.1],[2,2.08,635.99]],"ltp":2.06,"tv":7806.96,"id":8174357},{"trd":[[1.92,64.18]],"batb":[[0,1.93,111.2],[1,1.78,23.16],[2,1.75,87.18]],"batl":[[0,2.04,10.54],[1,2.06,384],[2,2.08,411.86]],"ltp":1.92,"tv":2950.1,"id":7412952}],"tv":10757.06}]}
{"op":"mcm","clk":"1004750322","pt":1580636638576,"mc":[{"id":"1.168209731","rc":[{"batb":[[0,1.94,62.24],[1,1.93,111.2],[2,1.84,74.12]],"ltp":1.92,"tv":2950.1,"id":7412952}]}]}
{"op":"mcm","clk":"1004750365","pt":1580636639651,"mc":[{"id":"1.168209731","rc":[{"batb":[[1,1.93,204.24],[2,1.9,46.21]],"batl":[[2,2.08,450.51]],"ltp":1.92,"tv":2950.1,"id":7412952}]}]}
{"op":"mcm","clk":"1004750422","pt":1580636641556,"mc":[{"id":"1.168209731","rc":[{"batb":[[1,1.93,169.13]],"ltp":1.92,"tv":2950.1,"id":7412952}]}]}
{"op":"mcm","clk":"1004750453","pt":1580636642171,"mc":[{"id":"1.168209731","rc":[{"batb":[[1,1.93,111.2]],"ltp":1.92,"tv":2950.1,"id":7412952}]}]}
{"op":"mcm","clk":"1004750553","pt":1580636644752,"mc":[{"id":"1.168209731","rc":[{"batl":[[2,2.08,641.93]],"ltp":2.06,"tv":7806.96,"id":8174357},{"batb":[[1,1.93,128.13],[2,1.9,64.87]],"ltp":1.92,"tv":2950.1,"id":7412952}]}]}
{"op":"mcm","clk":"1004750587","pt":1580636645884,"mc":[{"id":"1.168209731","rc":[{"trd":[[1.98,77.24]],"batb":[[0,1.98,38.62]],"ltp":1.98,"tv":7830.73,"id":8174357},{"trd":[[2.04,283.94]],"batl":[[0,2.06,384],[1,2.08,450.51],[2,2.1,5.65]],"ltp":2.04,"tv":2994.25,"id":7412952}],"tv":10824.98}]}
{"op":"mcm","clk":"1004750977","pt":1580636655977,"mc":[{"id":"1.168209731","rc":[{"batl":[[0,2.02,182.12]],"ltp":1.98,"tv":7830.73,"id":8174357}]}]}
{"op":"mcm","clk":"1004751037","pt":1580636657572,"mc":[{"id":"1.168209731","rc":[{"batb":[[1,1.92,45.37],[2,1.91,87.02]],"batl":[[0,2.08,106.93],[1,2.12,5.71],[2,2.14,36.13]],"ltp":1.98,"tv":7830.73,"id":8174357},{"batl":[[0,2.08,38.65],[1,2.1,5.65],[2,2.12,637.11]],"ltp":2.04,"tv":2994.25,"id":7412952}]}]}
{"op":"mcm","clk":"1004751084","pt":1580636658607,"mc":[{"id":"1.168209731","rc":[{"batb":[[1,1.91,87.02],[2,1.88,20.21]],"batl":[[2,2.5,10.13]],"ltp":1.98,"tv":7830.73,"id":8174357},{"batb":[[2,1.9,18.66]],"batl":[[0,2.1,5.65],[1,2.12,637.11],[2,2.14,5.25]],"ltp":2.04,"tv":2994.25,"id":7412952}]}]}
{"op":"mcm","clk":"1004751112","pt":1580636659171,"mc":[{"id":"1.168209731","rc":[{"trd":[[1.98,93.24]],"batb":[[0,1.91,17.39],[1,1.88,20.21],[2,1.82,378.93]],"ltp":1.98,"tv":7846.73,"id":8174357},{"batb":[[0,1.93,128.13],[1,1.9,18.66],[2,1.78,23.16]],"ltp":2.04,"tv":2994.25,"id":7412952}],"tv":10840.98}]}
{"op":"mcm","clk":"1004751254","pt":1580636662671,"mc":[{"id":"1.168209731","rc":[{"batl":[[0,1.98,47.06],[1,2.08,106.93],[2,2.12,5.71]],"ltp":1.98,"tv":7846.73,"id":8174357}]}]}
{"op":"mcm","clk":"1004751356","pt":1580636664864,"mc":[{"id":"1.168209731","rc":[{"batl":[[0,1.98,7.57]],"ltp":1.98,"tv":7846.73,"id":8174357}]}]}
{"op":"mcm","clk":"1004751677","pt":1580636672123,"mc":[{"id":"1.168209731","rc":[{"batl":[[1,2,4.21],[2,2.08,106.93]],"ltp":1.98,"tv":7846.73,"id":8174357},{"batb":[[0,2,4.21],[1,1.93,128.13],[2,1.9,18.66]],"batl":[[0,2.04,7.77],[1,2.1,5.65],[2,2.12,637.11]],"ltp":2.04,"tv":2994.25,"id":7412952}]}]}
{"op":"mcm","clk":"1004751724","pt":1580636673416,"mc":[{"id":"1.168209731","rc":[{"batl":[[1,2.06,3.36],[2,2.1,5.65]],"ltp":2.04,"tv":2994.25,"id":7412952}]}]}
{"op":"mcm","clk":"1004751815","pt":1580636675423,"mc":[{"id":"1.168209731","rc":[{"trd":[[1.91,38.14],[1.94,383.71],[1.96,1317.74]],"batb":[[0,1.88,20.21],[1,1.82,378.93],[2,1.79,39.86]],"batl":[[0,1.91,10.44],[1,1.98,7.57],[2,2,4.21]],"ltp":1.91,"tv":7893.17,"id":8174357},{"trd":[[2.04,291.71],[2.06,114.17]],"batl":[[0,2.12,637.11],[1,2.14,5.25],[2,2.2,2.53]],"ltp":2.06,"tv":3005.38,"id":7412952}],"tv":10898.56}]}
{"op":"mcm","clk":"1004751920","pt":1580636677744,"mc":[{"id":"1.168209731","rc":[{"batl":[[0,1.98,7.57],[1,2,4.21],[2,2.08,106.93]],"ltp":1.91,"tv":7893.17,"id":8174357}]}]}
{"op":"mcm","clk":"1004752258","pt":1580636685416,"mc":[{"id":"1.168209731","rc":[{"batl":[[1,2.08,106.93],[2,2.12,5.71]],"ltp":1.91,"tv":7893.17,"id":8174357},{"batb":[[0,1.93,128.13],[1,1.9,18.66],[2,1.78,23.16]],"ltp":2.06,"tv":3005.38,"id":7412952}]}]}
{"op":"mcm","clk":"1004752352","pt":1580636687732,"mc":[{"id":"1.168209731","rc":[{"trd":[[1.89,253.11]],"ltp":1.89,"tv":7903.26,"id":8174357},{"trd":[[2.12,594.12]],"batl":[[0,2.12,628.12]],"ltp":2.12,"tv":3014.37,"id":7412952}],"tv":10917.63}]}
{"op":"mcm","clk":"1004752384","pt":1580636688350,"mc":[{"id":"1.168209731","rc":[{"batl":[[0,1.98,15.58]],"ltp":1.89,"tv":7903.26,"id":8174357},{"batl":[[0,2.06,7.7],[1,2.12,628.12],[2,2.14,5.25]],"ltp":2.12,"tv":3014.37,"id":7412952}]}]}
{"op":"mcm","clk":"1004752423","pt":1580636689326,"mc":[{"id":"1.168209731","rc":[{"trd":[[1.94,385.71]],"ltp":1.94,"tv":7905.26,"id":8174357},{"trd":[[2.06,116.05]],"batl":[[0,2.06,5.82]],"ltp":2.06,"tv":3016.25,"id":7412952}],"tv":10921.51}]}
{"op":"mcm","clk":"1004752843","pt":1580636699584,"mc":[{"id":"1.168209731","rc":[{"batl":[[0,1.98,7.57]],"ltp":1.94,"tv":7905.26,"id":8174357},{"batl":[[0,2.12,628.12],[1,2.14,5.25],[2,2.2,2.53]],"ltp":2.06,"tv":3016.25,"id":7412952}]}]}
{"op":"mcm","clk":"1004753055","pt":1580636702546,"mc":[{"id":"1.168209731","rc":[{"batb":[[0,1.94,7.73],[1,1.88,20.21],[2,1.82,378.93]],"batl":[[0,1.98,17.54]],"ltp":1.94,"tv":7905.26,"id":8174357}]}]}
{"op":"mcm","clk":"1004753351","pt":1580636706687,"mc":[{"id":"1.168209731","rc":[{"batl":[[0,1.98,9.97]],"ltp":1.94,"tv":7905.26,"id":8174357}]}]}
{"op":"mcm","clk":"1004753499","pt":1580636709790,"mc":[{"id":"1.168209731","rc":[{"trd":[[1.94,400.86]],"batb":[[0,1.88,20.37],[1,1.82,378.93],[2,1.79,39.86]],"ltp":1.94,"tv":7920.4,"id":8174357}],"tv":10936.65}]}
{"op":"mcm","clk":"1004753516","pt":1580636710199,"mc":[{"id":"1.168209731","rc":[{"trd":[[1.94,401.18]],"batb":[[0,1.88,20.21]],"batl":[[0,1.98,10.43]],"ltp":1.94,"tv":7920.72,"id":8174357}],"tv":10936.97}]}
{"op":"mcm","clk":"1004753670","pt":1580636713702,"mc":[{"id":"1.168209731","rc":[{"batl":[[0,1.98,9.97]],"ltp":1.94,"tv":7920.72,"id":8174357}]}]}
{"op":"mcm","clk":"1004753932","pt":1580636719908,"mc":[{"id":"1.168209731","rc":[{"batl":[[0,2.08,106.93],[1,2.12,5.71],[2,2.5,10.13]],"ltp":1.94,"tv":7920.72,"id":8174357}]}]}
{"op":"mcm","clk":"1004754090","pt":1580636722908,"mc":[{"id":"1.168209731","rc":[{"batb":[[0,1.92,9.34],[1,1.88,20.21],[2,1.82,378.93]],"batl":[[0,1.96,8.95],[1,2.08,106.93],[2,2.12,5.71]],"ltp":1.94,"tv":7920.72,"id":8174357}]}]}
{"op":"mcm","clk":"1004754098","pt":1580636723112,"mc":[{"id":"1.168209731","rc":[{"batb":[[0,1.88,20.21],[1,1.82,378.93],[2,1.79,39.86]],"batl":[[0,2.08,106.93],[1,2.12,5.71],[2,2.5,10.13]],"ltp":1.94,"tv":7920.72,"id":8174357}]}]}
{"op":"mcm","clk":"1004754241","pt":1580636726004,"mc":[{"id":"1.168209731","rc":[{"batb":[[0,1.92,9.34],[1,1.88,20.21],[2,1.82,378.93]],"batl":[[0,1.96,8.95],[1,2.08,106.93],[2,2.12,5.71]],"ltp":1.94,"tv":7920.72,"id":8174357}]}]}
{"op":"mcm","clk":"1004754567","pt":1580636733847,"mc":[{"id":"1.168209731","rc":[{"trd":[[1.92,1152.49]],"batb":[[0,1.92,8.85]],"ltp":1.92,"tv":7921.7,"id":8174357}],"tv":10937.95}]}
{"op":"mcm","clk":"1004754892","pt":1580636740658,"mc":[{"id":"1.168209731","rc":[{"trd":[[1.92,1170.09]],"batb":[[0,1.88,20.26],[1,1.82,378.93],[2,1.79,39.86]],"ltp":1.92,"tv":7939.3,"id":8174357}],"tv":10955.55}]}
{"op":"mcm","clk":"1004755037","pt":1580636743956,"mc":[{"id":"1.168209731","rc":[{"batb":[[0,1.88,20.21]],"batl":[[0,2.08,106.93],[1,2.12,5.71],[2,2.5,10.13]],"ltp":1.92,"tv":7939.3,"id":8174357}]}]}
{"op":"mcm","clk":"1004755097","pt":1580636745649,"mc":[{"id":"1.168209731","rc":[{"batl":[[0,1.92,238.57],[1,2.08,106.93],[2,2.12,5.71]],"ltp":1.92,"tv":7939.3,"id":8174357}]}]}
{"op":"mcm","clk":"1004755161","pt":1580636746943,"mc":[{"id":"1.168209731","rc":[{"batl":[[1,1.94,9.19],[2,2.08,106.93]],"ltp":1.92,"tv":7939.3,"id":8174357},{"batl":[[0,2.12,639.96]],"ltp":2.06,"tv":3016.25,"id":7412952}]}]}
{"op":"mcm","clk":"1004755320","pt":1580636750855,"mc":[{"id":"1.168209731","rc":[{"batl":[[1,2.08,106.93],[2,2.12,5.71]],"ltp":1.92,"tv":7939.3,"id":8174357},{"batl":[[0,2.12,628.12]],"ltp":2.06,"tv":3016.25,"id":7412952}]}]}
{"op":"mcm","clk":"1004755440","pt":1580636753741,"mc":[{"id":"1.168209731","rc":[{"batl":[[1,1.94,9.19],[2,2.08,106.93]],"ltp":1.92,"tv":7939.3,"id":8174357},{"batl":[[0,2.12,639.96]],"ltp":2.06,"tv":3016.25,"id":7412952}]}]}
{"op":"mcm","clk":"1004756030","pt":1580636767205,"mc":[{"id":"1.168209731","rc":[{"trd":[[1.92,1224.2]],"batl":[[0,1.92,184.46]],"ltp":1.92,"tv":7993.41,"id":8174357},{"trd":[[2.08,137.27]],"ltp":2.08,"tv":3066.25,"id":7412952}],"tv":11059.66}]}
{"op":"mcm","clk":"1004757095","pt":1580636792133,"mc":[{"id":"1.168209731","rc":[{"trd":[[1.92,1226.66]],"batl":[[0,1.92,182]],"ltp":1.92,"tv":7995.87,"id":8174357},{"trd":[[2.08,139.54]],"ltp":2.08,"tv":3068.52,"id":7412952}],"tv":11064.39}]}
{"op":"mcm","clk":"1004757427","pt":1580636800645,"mc":[{"id":"1.168209731","rc":[{"trd":[[1.92,1231.2]],"batl":[[0,1.92,179.73]],"ltp":1.92,"tv":8000.41,"id":8174357}],"tv":11068.93}]}
{"op":"mcm","clk":"1004758257","pt":1580636820371,"mc":[{"id":"1.168209731","rc":[{"trd":[[2.12,598.12]],"batl":[[0,2.12,637.96]],"ltp":2.12,"tv":3072.52,"id":7412952}],"tv":11072.93}]}
{"op":"mcm","clk":"1004759101","pt":1580636838297,"mc":[{"id":"1.168209731","rc":[{"batl":[[0,1.94,9.19],[1,2.08,106.93],[2,2.12,5.71]],"ltp":1.92,"tv":8000.41,"id":8174357}]}]}
{"op":"mcm","clk":"1004760487","pt":1580636863561,"mc":[{"id":"1.168209731","rc":[{"trd":[[1.89,432.84]],"ltp":1.89,"tv":8180.14,"id":8174357},{"trd":[[2.12,758.51]],"batl":[[0,2.12,477.57]],"ltp":2.12,"tv":3232.91,"id":7412952}],"tv":11413.06}]}
{"op":"mcm","clk":"1004760691","pt":1580636867674,"mc":[{"id":"1.168209731","rc":[{"trd":[[1.89,434.84]],"ltp":1.89,"tv":8182.14,"id":8174357},{"trd":[[2.12,760.3]],"batl":[[0,2.12,475.79]],"ltp":2.12,"tv":3234.69,"id":7412952}],"tv":11416.84}]}
{"op":"mcm","clk":"1004761287","pt":1580636879502,"mc":[{"id":"1.168209731","rc":[{"batl":[[0,2.08,100.99],[1,2.5,10.13],[2,3,42.01]],"ltp":1.89,"tv":8182.14,"id":8174357},{"batb":[[0,1.93,111.2],[1,1.78,23.16],[2,1.63,5.07]],"batl":[[0,2.12,463.95]],"ltp":2.12,"tv":3234.69,"id":7412952}]}]}
{"op":"mcm","clk":"1004761451","pt":1580636882795,"mc":[{"id":"1.168209731","rc":[{"trd":[[1.89,897.61]],"ltp":1.89,"tv":8644.91,"id":8174357},{"trd":[[2.12,1275.62]],"batl":[[0,2.14,5.25],[1,2.2,2.53],[2,2.42,22.4]],"ltp":2.12,"tv":3750.02,"id":7412952}],"tv":12394.94}]}
{"op":"mcm","clk":"1004761512","pt":1580636883928,"mc":[{"id":"1.168209731","rc":[{"batb":[[0,2.12,36.97],[1,1.93,111.2],[2,1.78,23.16]],"batl":[[2,2.4,29.56]],"ltp":2.12,"tv":3750.02,"id":7412952}]}]}
{"op":"mcm","clk":"1004761534","pt":1580636884286,"mc":[{"id":"1.168209731","rc":[{"batb":[[0,1.93,111.2],[1,1.78,23.16],[2,1.63,5.07]],"batl":[[2,2.42,22.4]],"ltp":2.12,"tv":3750.02,"id":7412952}]}]}
{"op":"mcm","clk":"1004761627","pt":1580636886604,"mc":[{"id":"1.168209731","rc":[{"trd":[[1.87,6.01],[1.88,465.9]],"batb":[[0,1.82,378.93],[1,1.79,39.86],[2,1.78,240.13]],"batl":[[0,1.84,160.75],[1,1.86,242.83],[2,2.08,100.99]],"ltp":1.87,"tv":8691.34,"id":8174357},{"trd":[[2.14,96.68]],"batl":[[0,2.2,2.53],[1,2.42,22.4],[2,2.5,10.13]],"ltp":2.14,"tv":3755.27,"id":7412952}],"tv":12446.62}]}
{"op":"mcm","clk":"1004761715","pt":1580636888390,"mc":[{"id":"1.168209731","rc":[{"batb":[[0,2.14,3.92],[1,1.93,111.2],[2,1.78,23.16]],"ltp":2.14,"tv":3755.27,"id":7412952}]}]}
{"op":"mcm","clk":"1004761780","pt":1580636889829,"mc":[{"id":"1.168209731","rc":[{"batl":[[0,1.84,202.76]],"ltp":1.87,"tv":8691.34,"id":8174357},{"batb":[[0,1.93,111.2],[1,1.78,23.16],[2,1.63,5.07]],"ltp":2.14,"tv":3755.27,"id":7412952}]}]}
{"op":"mcm","clk":"1004761811","pt":1580636890396,"mc":[{"id":"1.168209731","rc":[{"trd":[[1.82,77.92],[1.83,78.77]],"batb":[[0,1.82,339.97]],"ltp":1.82,"tv":8772.31,"id":8174357},{"trd":[[2.2,65.52]],"batb":[[0,2.18,35.29],[1,1.93,111.2],[2,1.78,23.16]],"batl":[[0,2.4,29.56],[1,2.42,22.25]],"ltp":2.2,"tv":3757.8,"id":7412952}],"tv":12530.12}]}
{"op":"mcm","clk":"1004761993","pt":1580636893941,"mc":[{"id":"1.168209731","rc":[{"trd":[[1.82,84.64]],"batb":[[0,1.82,336.61]],"ltp":1.82,"tv":8779.03,"id":8174357}],"tv":12536.84}]}
{"op":"mcm","clk":"1004762131","pt":1580636897344,"mc":[{"id":"1.168209731","rc":[{"batb":[[2,1.71,58.81]],"batl":[[0,1.84,42.01],[1,2.08,100.99],[2,2.5,10.13]],"ltp":1.82,"tv":8779.03,"id":8174357}]}]}
{"op":"mcm","clk":"1004762173","pt":1580636898121,"mc":[{"id":"1.168209731","rc":[{"trd":[[1.82,284.64]],"batb":[[0,1.82,236.61]],"ltp":1.82,"tv":8979.03,"id":8174357}],"tv":12736.84}]}
{"op":"mcm","clk":"1004762451","pt":1580636902946,"mc":[{"id":"1.168209731","rc":[{"batb":[[2,1.39,2.08]],"batl":[[0,2.08,100.99],[1,2.5,10.13],[2,3,42.01]],"ltp":1.82,"tv":8979.03,"id":8174357},{"batb":[[0,1.93,111.2],[1,1.78,23.16],[2,1.63,5.07]],"batl":[[0,2.42,22.4],[1,2.5,10.13],[2,1000,0.02]],"ltp":2.2,"tv":3757.8,"id":7412952}]}]}
{"op":"mcm","clk":"1004763041","pt":1580636914866,"mc":[{"id":"1.168209731","rc":[{"batb":[[0,1.78,23.16],[1,1.63,5.07],[2,1.05,152.41]],"ltp":2.2,"tv":3757.8,"id":7412952}]}]}
{"op":"mcm","clk":"1004763048","pt":1580636915073,"mc":[{"id":"1.168209731","rc":[{"batb":[[0,1.63,5.07],[1,1.05,152.41],[2,1.04,169.36]],"ltp":2.2,"tv":3757.8,"id":7412952}]}]}
{"op":"mcm","clk":"1004763336","pt":1580636920789,"mc":[{"id":"1.168209731","rc":[{"trd":[[1.89,1727.03]],"batb":[[0,1.82,339.76],[2,1.74,877.85]],"ltp":1.89,"tv":9808.45,"id":8174357},{"trd":[[2.12,2015.05]],"ltp":2.12,"tv":4497.23,"id":7412952}],"tv":14305.69}]}
{"op":"mcm","clk":"1004763396","pt":1580636921867,"mc":[{"id":"1.168209731","rc":[{"batb":[[1,1.05,531.03]],"ltp":2.12,"tv":4497.23,"id":7412952}]}]}
{"op":"mcm","clk":"1004763454","pt":1580636922892,"mc":[{"id":"1.168209731","rc":[{"batb":[[2,1.75,55.45]],"batl":[[1,2.3,309.75],[2,2.5,10.13]],"ltp":1.89,"tv":9808.45,"id":8174357},{"batl":[[0,2.32,31.24],[1,2.42,22.25],[2,2.5,10.13]],"ltp":2.12,"tv":4497.23,"id":7412952}]}]}
{"op":"mcm","clk":"1004763459","pt":1580636922994,"mc":[{"id":"1.168209731","rc":[{"batb":[[0,1.83,182.27],[1,1.82,339.76],[2,1.81,261.05]],"batl":[[0,1.89,187.81],[1,1.91,223.72],[2,2.08,100.99]],"ltp":1.89,"tv":9808.45,"id":8174357}]}]}
{"op":"mcm","clk":"1004763543","pt":1580636924280,"mc":[{"id":"1.168209731","rc":[{"batb":[[0,2.12,36.97],[1,1.63,5.07],[2,1.05,531.03]],"ltp":2.12,"tv":4497.23,"id":7412952}]}]}
{"op":"mcm","clk":"1004763620","pt":1580636925773,"mc":[{"id":"1.168209731","rc":[{"batl":[[0,1.89,229.82]],"ltp":1.89,"tv":9808.45,"id":8174357},{"batb":[[2,1.1,378.83]],"ltp":2.12,"tv":4497.23,"id":7412952}]}]}
{"op":"mcm","clk":"1004763771","pt":1580636928663,"mc":[{"id":"1.168209731","rc":[{"batb":[[2,1.2,189.42]],"ltp":2.12,"tv":4497.23,"id":7412952}]}]}
{"op":"mcm","clk":"1004763828","pt":1580636929901,"mc":[{"id":"1.168209731","rc":[{"batb":[[0,2.12,84.76]],"ltp":2.12,"tv":4497.23,"id":7412952}]}]}
{"op":"mcm","clk":"1004763878","pt":1580636930781,"mc":[{"id":"1.168209731","rc":[{"batb":[[0,2.12,36.97]],"ltp":2.12,"tv":4497.23,"id":7412952}]}]}
{"op":"mcm","clk":"1004763924","pt":1580636931503,"mc":[{"id":"1.168209731","rc":[{"trd":[[1.83,120.99]],"batb":[[0,1.83,161.16]],"ltp":1.83,"tv":9850.67,"id":8174357}],"tv":14347.91}]}
{"op":"mcm","clk":"1004763961","pt":1580636932172,"mc":[{"id":"1.168209731","rc":[{"batb":[[2,1.4,75.73]],"ltp":2.12,"tv":4497.23,"id":7412952}]}]}
{"op":"mcm","clk":"1004764042","pt":1580636933671,"mc":[{"id":"1.168209731","rc":[{"trd":[[1.83,142.97]],"batb":[[0,1.83,150.17]],"ltp":1.83,"tv":9872.65,"id":8174357}],"tv":14369.89}]}
{"op":"mcm","clk":"1004764100","pt":1580636934904,"mc":[{"id":"1.168209731","rc":[{"batb":[[1,1.82,236.61]],"batl":[[0,1.89,187.81]],"ltp":1.83,"tv":9872.65,"id":8174357},{"batb":[[0,1.63,5.07],[1,1.4,75.73],[2,1.3,75.72]],"batl":[[0,2.42,22.4],[1,2.5,10.13],[2,1000,0.02]],"ltp":2.12,"tv":4497.23,"id":7412952}]}]}
{"op":"mcm","clk":"1004764104","pt":1580636935007,"mc":[{"id":"1.168209731","rc":[{"batb":[[0,1.82,236.61],[1,1.79,39.86],[2,1.5,426.9]],"batl":[[0,2.08,100.99],[1,2.3,309.75],[2,2.5,10.13]],"ltp":1.83,"tv":9872.65,"id":8174357}]}]}
{"op":"mcm","clk":"1004764180","pt":1580636936294,"mc":[{"id":"1.168209731","rc":[{"batb":[[1,1.5,75.72],[2,1.4,75.73]],"ltp":2.12,"tv":4497.23,"id":7412952}]}]}
{"op":"mcm","clk":"1004764328","pt":1580636938918,"mc":[{"id":"1.168209731","rc":[{"batb":[[2,1.65,324.04]],"batl":[[0,2,182.65],[1,2.02,189.26],[2,2.08,100.99]],"ltp":1.83,"tv":9872.65,"id":8174357}]}]}
{"op":"mcm","clk":"1004764351","pt":1580636939489,"mc":[{"id":"1.168209731","rc":[{"batb":[[2,1.5,426.9]],"ltp":1.83,"tv":9872.65,"id":8174357}]}]}
{"op":"mcm","clk":"1004764431","pt":1580636940927,"mc":[{"id":"1.168209731","rc":[{"batb":[[2,1.39,2.08]],"ltp":1.83,"tv":9872.65,"id":8174357}]}]}
{"op":"mcm","clk":"1004764481","pt":1580636941917,"mc":[{"id":"1.168209731","rc":[{"trd":[[1.96,1330.7]],"batb":[[0,1.92,515.97],[1,1.88,1016.95],[2,1.82,236.61]],"batl":[[2,2.06,593.71]],"ltp":1.96,"tv":9885.61,"id":8174357},{"trd":[[2.04,304.16]],"batl":[[0,2.04,2936.95],[1,2.12,8.35],[2,2.42,22.4]],"ltp":2.04,"tv":4509.68,"id":7412952}],"tv":14395.3}]}
{"op":"mcm","clk":"1004764528","pt":1580636942692,"mc":[{"id":"1.168209731","rc":[{"trd":[[2,171.99]],"batb":[[0,1.93,196.23],[1,1.92,515.97],[2,1.91,220.2]],"batl":[[0,2,157.6]],"ltp":2.0,"tv":9935.71,"id":8174357},{"batl":[[0,2.12,8.35],[1,2.42,22.4],[2,2.5,10.13]],"ltp":2.04,"tv":4509.68,"id":7412952}],"tv":14445.4}]}
{"op":"mcm","clk":"1004764598","pt":1580636943890,"mc":[{"id":"1.168209731","rc":[{"batl":[[0,1.99,42.01],[1,2,157.6],[2,2.02,189.26]],"ltp":2.0,"tv":9935.71,"id":8174357},{"batb":[[0,2.02,41.17],[1,1.63,5.07],[2,1.5,75.72]],"batl":[[0,2.22,33.76],[1,2.42,22.25]],"ltp":2.04,"tv":4509.68,"id":7412952}]}]}
{"op":"mcm","clk":"1004764643","pt":1580636944915,"mc":[{"id":"1.168209731","rc":[{"batl":[[0,2.42,22.4],[1,2.5,10.13],[2,1000,0.02]],"ltp":2.04,"tv":4509.68,"id":7412952}]}]}
{"op":"mcm","clk":"1004764692","pt":1580636945746,"mc":[{"id":"1.168209731","rc":[{"batl":[[0,2.2,34.45],[1,2.42,22.4],[2,2.5,10.13]],"ltp":2.04,"tv":4509.68,"id":7412952}]}]}
{"op":"mcm","clk":"1004764762","pt":1580636946838,"mc":[{"id":"1.168209731","rc":[{"batb":[[1,1.92,525.43]],"batl":[[0,1.96,8.8],[1,1.99,42.01],[2,2,157.6]],"ltp":2.0,"tv":9935.71,"id":8174357}]}]}
{"op":"mcm","clk":"1004765094","pt":1580636951433,"mc":[{"id":"1.168209731","rc":[{"batb":[[1,1.5,75.72],[2,1.4,75.73]],"ltp":2.04,"tv":4509.68,"id":7412952}]}]}
{"op":"mcm","clk":"1004765126","pt":1580636952001,"mc":[{"id":"1.168209731","rc":[{"batb":[[1,1.92,515.97]],"batl":[[0,1.99,42.01],[1,2,157.6],[2,2.02,189.26]],"ltp":2.0,"tv":9935.71,"id":8174357}]}]}
{"op":"mcm","clk":"1004765181","pt":1580636953030,"mc":[{"id":"1.168209731","rc":[{"batl":[[0,1.94,13.51],[1,1.99,42.01],[2,2,157.6]],"ltp":2.0,"tv":9935.71,"id":8174357}]}]}
{"op":"mcm","clk":"1004765273","pt":1580636954938,"mc":[{"id":"1.168209731","rc":[{"trd":[[1.93,482.5]],"batb":[[0,1.83,50.41],[1,1.82,236.61],[2,1.79,39.86]],"batl":[[2,2.08,100.99]],"ltp":1.93,"tv":9941.17,"id":8174357},{"trd":[[2.08,144.61]],"ltp":2.08,"tv":4514.75,"id":7412952}],"tv":14455.93}]}
{"op":"mcm","clk":"1004765290","pt":1580636955247,"mc":[{"id":"1.168209731","rc":[{"batb":[[0,1.82,236.61],[1,1.79,39.86],[2,1.55,420.5]],"batl":[[1,2.08,100.99],[2,2.3,309.75]],"ltp":1.93,"tv":9941.17,"id":8174357},{"batb":[[0,1.5,75.72],[1,1.4,75.73],[2,1.3,75.72]],"batl":[[0,2.42,22.4],[1,2.5,10.13],[2,1000,0.02]],"ltp":2.08,"tv":4514.75,"id":7412952}]}]}
{"op":"mcm","clk":"1004765423","pt":1580636957839,"mc":[{"id":"1.168209731","rc":[{"batb":[[1,1.81,196.25],[2,1.79,310.58]],"batl":[[1,2.08,326.77],[2,2.1,169.11]],"ltp":1.93,"tv":9941.17,"id":8174357}]}]}
{"op":"mcm","clk":"1004765459","pt":1580636958410,"mc":[{"id":"1.168209731","rc":[{"batb":[[1,1.79,39.86],[2,1.55,420.5]],"batl":[[1,2.08,100.99],[2,2.3,309.75]],"ltp":1.93,"tv":9941.17,"id":8174357}]}]}
{"op":"mcm","clk":"1004765579","pt":1580636960939,"mc":[{"id":"1.168209731","rc":[{"trd":[[1.94,428.2]],"batb":[[0,2,317.97],[1,1.97,942.94],[2,1.82,236.61]],"batl":[[0,2.06,11.87],[2,2.16,601.28]],"ltp":1.94,"tv":9968.19,"id":8174357},{"batl":[[0,2,3331.77],[1,2.42,22.4],[2,2.5,10.13]],"ltp":2.08,"tv":4514.75,"id":7412952}],"tv":14482.95}]}
{"op":"mcm","clk":"1004765636","pt":1580636961919,"mc":[{"id":"1.168209731","rc":[{"batb":[[1,1.97,95.64],[2,1.92,45.37]],"batl":[[2,2.1,37.81]],"ltp":1.94,"tv":9968.19,"id":8174357},{"batb":[[0,1.93,202.34],[1,1.91,265.65],[2,1.4,75.73]],"batl":[[0,2,495.24],[1,2.02,189.46],[2,2.1,37.81]],"ltp":2.08,"tv":4514.75,"id":7412952}]}]}
{"op":"mcm","clk":"1004765859","pt":1580636965239,"mc":[{"id":"1.168209731","rc":[{"trd":[[2,236.84]],"batl":[[0,2,428.08]],"ltp":2.0,"tv":4649.07,"id":7412952}],"tv":14617.27}]}
{"op":"mcm","clk":"1004766344","pt":1580636973763,"mc":[{"id":"1.168209731","rc":[{"trd":[[2,175.99]],"batb":[[0,2,315.97]],"ltp":2.0,"tv":9972.19,"id":8174357}],"tv":14621.27}]}
{"op":"mcm","clk":"1004766450","pt":1580636975432,"mc":[{"id":"1.168209731","rc":[{"batb":[[0,2,311.96]],"batl":[[0,2.08,100.99],[1,2.1,37.81],[2,2.16,601.28]],"ltp":2.0,"tv":9972.19,"id":8174357}]}]}
{"op":"mcm","clk":"1004766615","pt":1580636978371,"mc":[{"id":"1.168209731","rc":[{"batl":[[0,2.04,12.07],[1,2.08,100.99],[2,2.1,37.81]],"ltp":2.0,"tv":9972.19,"id":8174357},{"batl":[[1,2.02,201.59]],"ltp":2.0,"tv":4649.07,"id":7412952}]}]}
{"op":"mcm","clk":"1004766911","pt":1580636983989,"mc":[{"id":"1.168209731","rc":[{"batl":[[0,2.08,100.99],[1,2.1,37.81],[2,2.16,601.28]],"ltp":2.0,"tv":9972.19,"id":8174357},{"batl":[[1,2.02,189.46]],"ltp":2.0,"tv":4649.07,"id":7412952}]}]}
{"op":"mcm","clk":"1004767017","pt":1580636985768,"mc":[{"id":"1.168209731","rc":[{"trd":[[1.93,200]],"batb":[[0,1.91,45.37],[1,1.4,75.73],[2,1.3,75.72]],"ltp":1.93,"tv":4849.07,"id":7412952}],"tv":14821.27}]}
{"op":"mcm","clk":"1004767087","pt":1580636986851,"mc":[{"id":"1.168209731","rc":[{"trd":[[2,195.99]],"batb":[[0,2,301.96]],"batl":[[0,2.04,12.07],[1,2.08,100.99],[2,2.1,37.81]],"ltp":2.0,"tv":9992.19,"id":8174357},{"batl":[[1,2.02,201.59]],"ltp":1.93,"tv":4849.07,"id":7412952}],"tv":14841.27}]}
{"op":"mcm","clk":"1004767187","pt":1580636988670,"mc":[{"id":"1.168209731","rc":[{"batb":[[0,1.92,256.82],[1,1.91,45.37],[2,1.9,223.97]],"batl":[[0,2,481.4]],"ltp":1.93,"tv":4849.07,"id":7412952}]}]}
{"op":"mcm","clk":"1004767291","pt":1580636990473,"mc":[{"id":"1.168209731","rc":[{"batb":[[0,1.92,45.37],[1,1.82,236.61],[2,1.79,39.86]],"batl":[[0,2.1,37.81],[1,2.3,309.75],[2,2.5,10.13]],"ltp":2.0,"tv":9992.19,"id":8174357},{"batb":[[0,1.91,45.37],[1,1.4,75.73],[2,1.3,75.72]],"batl":[[0,2.1,37.81],[1,2.42,22.4],[2,2.5,10.13]],"ltp":1.93,"tv":4849.07,"id":7412952}]}]}
{"op":"mcm","clk":"1004767318","pt":1580636990998,"mc":[{"id":"1.168209731","rc":[{"batb":[[0,1.82,236.61],[1,1.79,39.86],[2,1.55,420.5]],"batl":[[0,2.3,309.75],[1,2.5,10.13],[2,3,42.01]],"ltp":2.0,"tv":9992.19,"id":8174357},{"batb":[[0,1.4,75.73],[1,1.3,75.72],[2,1.2,189.41]],"batl":[[0,2.42,22.4],[1,2.5,10.13],[2,1000,0.02]],"ltp":1.93,"tv":4849.07,"id":7412952}]}]}
{"op":"mcm","clk":"1004767447","pt":1580636993481,"mc":[{"id":"1.168209731","rc":[{"batb":[[0,1.8,216.78],[1,1.78,276.82],[2,1.4,75.73]],"batl":[[0,2.08,256.84],[1,2.1,169.09],[2,2.42,22.4]],"ltp":1.93,"tv":4849.07,"id":7412952}]}]}
{"op":"mcm","clk":"1004767476","pt":1580636994104,"mc":[{"id":"1.168209731","rc":[{"batb":[[0,1.4,75.73],[1,1.3,75.72],[2,1.2,189.41]],"batl":[[0,2.42,22.4],[1,2.5,10.13],[2,1000,0.02]],"ltp":1.93,"tv":4849.07,"id":7412952}]}]}
{"op":"mcm","clk":"1004767640","pt":1580636996876,"mc":[{"id":"1.168209731","rc":[{"batb":[[0,1.92,480.06],[1,1.82,236.61],[2,1.79,39.86]],"batl":[[0,1.94,8.22],[1,1.97,11.5],[2,2.04,477.96]],"ltp":2.0,"tv":9992.19,"id":8174357},{"batb":[[0,2.02,3.74],[1,1.97,98.81],[2,1.96,96.42]],"batl":[[0,2.12,12.68],[1,2.42,22.4],[2,2.5,10.13]],"ltp":1.93,"tv":4849.07,"id":7412952}]}]}
{"op":"mcm","clk":"1004767708","pt":1580636997919,"mc":[{"id":"1.168209731","rc":[{"batb":[[0,1.93,232.8],[1,1.92,480.06],[2,1.91,220.23]],"batl":[[2,2,147.36]],"ltp":2.0,"tv":9992.19,"id":8174357},{"batb":[[1,1.98,42.85],[2,1.97,98.81]],"batl":[[1,2.16,36.13],[2,2.42,22.4]],"ltp":1.93,"tv":4849.07,"id":7412952}]}]}
{"op":"mcm","clk":"1004768088","pt":1580637003823,"mc":[{"id":"1.168209731","rc":[{"batl":[[0,2.12,17.39],[1,2.14,5.75],[2,2.16,36.13]],"ltp":1.93,"tv":4849.07,"id":7412952}]}]}
{"op":"mcm","clk":"1004768441","pt":1580637009524,"mc":[{"id":"1.168209731","rc":[{"batb":[[0,1.88,17.46],[1,1.86,48.73],[2,1.82,236.61]],"batl":[[0,1.97,11.5],[1,2.02,41.17],[2,2.1,5.85]],"ltp":2.0,"tv":9992.19,"id":8174357},{"batb":[[2,1.91,19.39]],"batl":[[0,2.14,5.75],[1,2.16,36.13],[2,2.42,22.4]],"ltp":1.93,"tv":4849.07,"id":7412952}]}]}
{"op":"mcm","clk":"1004768474","pt":1580637010092,"mc":[{"id":"1.168209731","rc":[{"batl":[[0,2.02,41.17],[1,2.1,5.85],[2,2.3,309.75]],"ltp":2.0,"tv":9992.19,"id":8174357},{"batb":[[0,1.98,42.85],[1,1.91,19.39],[2,1.5,75.72]],"ltp":1.93,"tv":4849.07,"id":7412952}]}]}
{"op":"mcm","clk":"1004768566","pt":1580637011488,"mc":[{"id":"1.168209731","rc":[{"batb":[[1,1.82,236.61],[2,1.79,39.86]],"batl":[[0,2.1,5.85],[1,2.3,309.75],[2,2.5,10.13]],"ltp":2.0,"tv":9992.19,"id":8174357},{"batb":[[0,1.91,19.39],[1,1.5,75.72],[2,1.4,75.73]],"batl":[[0,2.06,1.09],[1,2.14,5.75]],"ltp":1.93,"tv":4849.07,"id":7412952}]}]}
{"op":"mcm","clk":"1004768849","pt":1580637015941,"mc":[{"id":"1.168209731","rc":[{"trd":[[1.94,429.36]],"batb":[[1,1.86,406.87],[2,1.82,236.61]],"batl":[[0,1.89,17.48],[1,1.92,114.46],[2,1.94,11.25]],"ltp":1.94,"tv":9993.35,"id":8174357},{"trd":[[2.06,117.14]],"batb":[[0,2.06,3.41],[1,2.04,40.33],[2,2.02,104.09]],"batl":[[0,2.14,5.75],[1,2.2,9.86],[2,2.24,33.76]],"ltp":2.06,"tv":4850.16,"id":7412952}],"tv":14843.52}]}
{"op":"mcm","clk":"1004768860","pt":1580637016002,"mc":[{"id":"1.168209731","rc":[{"batb":[[0,1.88,239.55],[1,1.86,646.18]],"ltp":1.94,"tv":9993.35,"id":8174357}]}]}
{"op":"mcm","clk":"1004769194","pt":1580637022314,"mc":[{"id":"1.168209731","rc":[{"batb":[[1,1.86,667.86],[2,1.85,19.37]],"batl":[[1,1.92,595.05],[2,1.94,508.65]],"ltp":1.94,"tv":9993.35,"id":8174357},{"batb":[[2,2.02,110.33]],"batl":[[1,2.18,5.25],[2,2.2,9.86]],"ltp":2.06,"tv":4850.16,"id":7412952}]}]}
{"op":"mcm","clk":"1004769469","pt":1580637027672,"mc":[{"id":"1.168209731","rc":[{"batb":[[0,1.85,19.37],[1,1.84,494.03],[2,1.82,747.45]],"batl":[[0,1.92,480.59],[1,1.94,508.65],[2,1.96,42.01]],"ltp":1.94,"tv":9993.35,"id":8174357},{"batb":[[2,2,17.46]],"batl":[[0,2.18,5.25],[1,2.24,33.76],[2,2.42,22.25]],"ltp":2.06,"tv":4850.16,"id":7412952}]}]}
{"op":"mcm","clk":"1004769548","pt":1580637029232,"mc":[{"id":"1.168209731","rc":[{"batl":[[1,1.94,497.4],[2,1.97,16.5]],"ltp":1.94,"tv":9993.35,"id":8174357},{"batb":[[0,2,17.46],[1,1.91,19.39],[2,1.5,75.72]],"batl":[[1,2.42,22.4],[2,2.5,10.13]],"ltp":2.06,"tv":4850.16,"id":7412952}]}]}
{"op":"mcm","clk":"1004769638","pt":1580637030938,"mc":[{"id":"1.168209731","rc":[{"batb":[[0,1.85,193.3],[2,1.83,251.93]],"ltp":1.94,"tv":9993.35,"id":8174357}]}]}
{"op":"mcm","clk":"1004769688","pt":1580637031766,"mc":[{"id":"1.168209731","rc":[{"batb":[[0,1.85,19.37],[2,1.82,747.45]],"ltp":1.94,"tv":9993.35,"id":8174357}]}]}
{"op":"mcm","clk":"1004769815","pt":1580637033935,"mc":[{"id":"1.168209731","rc":[{"batl":[[0,1.88,4.2],[1,1.92,480.59],[2,1.94,497.4]],"ltp":1.94,"tv":9993.35,"id":8174357},{"batb":[[0,2.02,5.24],[1,2,17.46],[2,1.91,19.39]],"ltp":2.06,"tv":4850.16,"id":7412952}]}]}
{"op":"mcm","clk":"1004769858","pt":1580637034763,"mc":[{"id":"1.168209731","rc":[{"trd":[[1.88,474.3],[1.9,20.1]],"batb":[[0,1.9,145.9],[1,1.88,231.28],[2,1.85,19.37]],"batl":[[0,1.92,480.59],[1,1.94,497.4],[2,1.96,148.91]],"ltp":1.9,"tv":10021.85,"id":8174357},{"batb":[[0,2,17.46],[1,1.91,19.39],[2,1.5,75.72]],"ltp":2.06,"tv":4850.16,"id":7412952}],"tv":14872.02}]}
{"op":"mcm","clk":"1004769899","pt":1580637035377,"mc":[{"id":"1.168209731","rc":[{"batb":[[0,1.85,19.37],[1,1.84,494.03],[2,1.82,747.45]],"ltp":1.9,"tv":10021.85,"id":8174357}]}]}
{"op":"mcm","clk":"1004770084","pt":1580637038276,"mc":[{"id":"1.168209731","rc":[{"batb":[[0,1.89,265.53],[1,1.87,235.37],[2,1.85,19.37]],"ltp":1.9,"tv":10021.85,"id":8174357}]}]}
{"op":"mcm","clk":"1004770152","pt":1580637039158,"mc":[{"id":"1.168209731","rc":[{"batb":[[0,1.85,19.37],[1,1.84,494.03],[2,1.82,747.45]],"batl":[[2,1.97,16.5]],"ltp":1.9,"tv":10021.85,"id":8174357}]}]}
{"op":"mcm","clk":"1004770278","pt":1580637040861,"mc":[{"id":"1.168209731","rc":[{"batb":[[0,2.02,5.24],[1,2,17.46],[2,1.91,19.39]],"ltp":2.06,"tv":4850.16,"id":7412952}]}]}
{"op":"mcm","clk":"1004770303","pt":1580637041173,"mc":[{"id":"1.168209731","rc":[{"batb":[[0,2,17.46],[1,1.91,19.39],[2,1.5,75.72]],"ltp":2.06,"tv":4850.16,"id":7412952}]}]}
{"op":"mcm","clk":"1004770371","pt":1580637042158,"mc":[{"id":"1.168209731","rc":[{"batb":[[0,1.85,187.6],[2,1.83,251.93]],"ltp":1.9,"tv":10021.85,"id":8174357}]}]}
{"op":"mcm","clk":"1004770775","pt":1580637048204,"mc":[{"id":"1.168209731","rc":[{"trd":[[1.85,25.54]],"batb":[[0,1.85,185.33]],"ltp":1.85,"tv":10026.4,"id":8174357}],"tv":14876.56}]}
{"op":"mcm","clk":"1004770892","pt":1580637050376,"mc":[{"id":"1.168209731","rc":[{"batb":[[0,1.85,17.1],[2,1.82,747.45]],"batl":[[0,2,18.73],[1,2.04,293.53],[2,2.06,178.69]],"ltp":1.85,"tv":10026.4,"id":8174357}]}]}
{"op":"mcm","clk":"1004771021","pt":1580637052804,"mc":[{"id":"1.168209731","rc":[{"batl":[[0,1.98,14.53],[1,2,18.73],[2,2.04,293.53]],"ltp":1.85,"tv":10026.4,"id":8174357},{"batb":[[1,1.94,445.64],[2,1.91,19.39]],"batl":[[0,2.04,186.39],[1,2.06,451.2],[2,2.08,8.87]],"ltp":2.06,"tv":4850.16,"id":7412952}]}]}
{"op":"mcm","clk":"1004771073","pt":1580637053890,"mc":[{"id":"1.168209731","rc":[{"batb":[[0,1.95,210.74],[1,1.93,213.26],[2,1.85,17.1]],"batl":[[2,2.04,183.96]],"ltp":1.85,"tv":10026.4,"id":8174357}]}]}
{"op":"mcm","clk":"1004771088","pt":1580637054301,"mc":[{"id":"1.168209731","rc":[{"batb":[[2,1.87,47.89]],"ltp":1.85,"tv":10026.4,"id":8174357},{"batb":[[1,1.96,43.69],[2,1.94,445.64]],"ltp":2.06,"tv":4850.16,"id":7412952}]}]}
{"op":"mcm","clk":"1004771167","pt":1580637056416,"mc":[{"id":"1.168209731","rc":[{"batl":[[2,2.02,151.18]],"ltp":1.85,"tv":10026.4,"id":8174357}]}]}
{"op":"mcm","clk":"1004771349","pt":1580637060082,"mc":[{"id":"1.168209731","rc":[{"batb":[[2,1.91,20.39]],"ltp":1.85,"tv":10026.4,"id":8174357}]}]}
{"op":"mcm","clk":"1004771744","pt":1580637068511,"mc":[{"id":"1.168209731","rc":[{"batb":[[0,1.89,19.41],[1,1.87,47.89],[2,1.82,236.61]],"batl":[[0,2.04,40.33],[1,2.12,5.96],[2,2.3,309.75]],"ltp":1.85,"tv":10026.4,"id":8174357},{"batb":[[0,1.96,43.69],[1,1.9,21.46],[2,1.5,75.72]],"batl":[[0,2.14,40.88],[1,2.42,22.4],[2,2.5,10.13]],"ltp":2.06,"tv":4850.16,"id":7412952}]}]}
{"op":"mcm","clk":"1004771771","pt":1580637069123,"mc":[{"id":"1.168209731","rc":[{"batb":[[1,1.82,236.61],[2,1.79,39.86]],"batl":[[0,2.12,5.96],[1,2.3,309.75],[2,2.5,10.13]],"ltp":1.85,"tv":10026.4,"id":8174357},{"batb":[[0,1.9,21.46],[1,1.5,75.72],[2,1.4,75.73]],"batl":[[0,2.14,4.75]],"ltp":2.06,"tv":4850.16,"id":7412952}]}]}
{"op":"mcm","clk":"1004771951","pt":1580637071803,"mc":[{"id":"1.168209731","rc":[{"batb":[[0,1.89,206.85],[1,1.87,235.31],[2,1.82,236.61]],"batl":[[1,2.18,235.06],[2,2.2,148.43]],"ltp":1.85,"tv":10026.4,"id":8174357}]}]}
{"op":"mcm","clk":"1004772032","pt":1580637073704,"mc":[{"id":"1.168209731","rc":[{"trd":[[1.2,378.81],[1.29,0.24],[1.3,151.45],[1.39,4.13],[1.4,151.45],[1.48,0.02],[1.55,841],[1.66,15.27],[1.7,40.07],[1.79,101.7],[1.81,0.19],[1.82,757.85],[1.87,482.07],[1.89,2140.73]],"batb":[[0,1.1,378.72],[1,1.05,530.82],[2,1.04,169.36]],"batl":[[0,1.11,3765.89],[1,2.12,5.96],[2,2.3,309.75]],"ltp":1.2,"tv":13043.3,"id":8174357},{"trd":[[2.14,101.43],[2.22,0.15],[2.42,28.15],[2.5,10.13]],"batl":[[0,1000,0.02],[1,2.42,0],[2,2.5,0]],"ltp":2.5,"tv":4887.44,"id":7412952}],"tv":17930.75}]}
{"op":"mcm","clk":"1004772085","pt":1580637074936,"mc":[{"id":"1.168209731","rc":[{"trd":[[1.11,122.4]],"batb":[[0,1.05,152.3],[1,1.04,169.36],[2,1.03,246.17]],"batl":[[0,1.11,3682.84],[1,2.08,5.69],[2,2.12,5.96]],"ltp":1.11,"tv":13165.7,"id":8174357},{"trd":[[10,4.85]],"batb":[[0,1.93,18.36],[1,1.9,21.46]],"ltp":10.0,"tv":4892.29,"id":7412952}],"tv":18057.99}]}
{"op":"mcm","clk":"1004772168","pt":1580637076635,"mc":[{"id":"1.168209731","rc":[{"trd":[[1.11,3805.24]],"batl":[[0,1.89,10.39],[1,1.93,12.5],[2,1.96,207.27]],"ltp":1.11,"tv":16848.54,"id":8174357},{"trd":[[10,413.65]],"batb":[[0,2.06,4.08],[1,2.02,97.24],[2,1.99,109.86]],"batl":[[0,2.16,91.06],[1,2.2,15.98],[2,1000,0.02]],"ltp":10.0,"tv":5301.09,"id":7412952}],"tv":22149.64}]}
{"op":"mcm","clk":"1004772226","pt":1580637077922,"mc":[{"id":"1.168209731","rc":[{"batb":[[0,1.87,190.05],[1,1.85,243.84],[2,1.05,152.3]],"batl":[[2,1.94,249.04]],"ltp":1.11,"tv":16848.54,"id":8174357}]}]}
{"op":"mcm","clk":"1004772256","pt":1580637078638,"mc":[{"id":"1.168209731","rc":[{"batl":[[2,2.26,37.86]],"ltp":10.0,"tv":5301.09,"id":7412952}]}]}
{"op":"mcm","clk":"1004772313","pt":1580637079722,"mc":[{"id":"1.168209731","rc":[{"trd":[[1.87,607.71]],"batb":[[0,1.87,64.41],[2,1.8,52.09]],"ltp":1.87,"tv":16974.18,"id":8174357},{"trd":[[2.16,293.05]],"batb":[[1,2.02,138.41]],"batl":[[0,2.2,15.98],[1,2.22,33.61],[2,1000,0.02]],"ltp":2.16,"tv":5591.98,"id":7412952}],"tv":22566.16}]}
{"op":"mcm","clk":"1004772329","pt":1580637080061,"mc":[{"id":"1.168209731","rc":[{"batb":[[0,1.8,52.09],[1,1.05,152.3],[2,1.04,169.36]],"batl":[[2,1.96,42.01]],"ltp":1.87,"tv":16974.18,"id":8174357}]}]}
{"op":"mcm","clk":"1004772449","pt":1580637082939,"mc":[{"id":"1.168209731","rc":[{"batb":[[0,1.86,241.78],[1,1.84,248.3],[2,1.8,52.09]],"batl":[[1,1.93,223.16],[2,1.95,210.64]],"ltp":1.87,"tv":16974.18,"id":8174357}]}]}
{"op":"mcm","clk":"1004772523","pt":1580637084542,"mc":[{"id":"1.168209731","rc":[{"batb":[[0,1.86,261.46],[1,1.85,23.57],[2,1.84,248.3]],"batl":[[2,1.95,263.94]],"ltp":1.87,"tv":16974.18,"id":8174357},{"batb":[[1,2.04,16.87],[2,2.02,155.65]],"batl":[[0,2.18,5.25],[1,2.2,15.98],[2,2.22,33.61]],"ltp":2.16,"tv":5591.98,"id":7412952}]}]}
{"op":"mcm","clk":"1004772689","pt":1580637087831,"mc":[{"id":"1.168209731","rc":[{"batb":[[2,1.84,267.52]],"ltp":1.87,"tv":16974.18,"id":8174357},{"batl":[[1,2.2,21.01]],"ltp":2.16,"tv":5591.98,"id":7412952}]}]}
{"op":"mcm","clk":"1004772933","pt":1580637093939,"mc":[{"id":"1.168209731","rc":[{"batb":[[0,1.84,19.22],[1,1.8,52.09],[2,1.2,189.31]],"batl":[[0,1.96,42.01],[1,1.98,51.87],[2,2.08,5.69]],"ltp":1.87,"tv":16974.18,"id":8174357},{"batb":[[0,2.02,58.41],[1,1.93,18.36],[2,1.9,21.46]],"batl":[[0,2.2,5.03],[1,2.22,33.61],[2,1000,0.02]],"ltp":2.16,"tv":5591.98,"id":7412952}]}]}
{"op":"mcm","clk":"1004772947","pt":1580637094347,"mc":[{"id":"1.168209731","rc":[{"batb":[[2,1.3,75.72]],"ltp":1.87,"tv":16974.18,"id":8174357}]}]}
{"op":"mcm","clk":"1004772971","pt":1580637095059,"mc":[{"id":"1.168209731","rc":[{"batb":[[1,1.3,75.72],[2,1.2,189.31]],"batl":[[0,1.98,51.87],[1,2.08,5.69],[2,2.12,5.96]],"ltp":1.87,"tv":16974.18,"id":8174357},{"batb":[[0,2.02,17.24]],"batl":[[1,1000,0.02],[2,1000,0]],"ltp":2.16,"tv":5591.98,"id":7412952}]}]}
{"op":"mcm","clk":"1004773049","pt":1580637096857,"mc":[{"id":"1.168209731","rc":[{"batb":[[1,1.83,225.61],[2,1.81,261.83]],"batl":[[1,2,157.69],[2,2.02,189.66]],"ltp":1.87,"tv":16974.18,"id":8174357},{"batb":[[0,2.04,16.87],[1,2.02,17.24],[2,1.93,18.36]],"ltp":2.16,"tv":5591.98,"id":7412952}]}]}
{"op":"mcm","clk":"1004773085","pt":1580637097574,"mc":[{"id":"1.168209731","rc":[{"batb":[[0,2.02,17.24],[1,1.93,18.36],[2,1.9,21.46]],"ltp":2.16,"tv":5591.98,"id":7412952}]}]}
{"op":"mcm","clk":"1004773276","pt":1580637101852,"mc":[{"id":"1.168209731","rc":[{"batb":[[1,1.3,75.72],[2,1.2,189.31]],"batl":[[1,2.08,5.69],[2,2.12,5.96]],"ltp":1.87,"tv":16974.18,"id":8174357}]}]}
{"op":"mcm","clk":"1004773293","pt":1580637102164,"mc":[{"id":"1.168209731","rc":[{"batl":[[1,2.3,309.75],[2,2.5,10.13]],"ltp":1.87,"tv":16974.18,"id":8174357},{"batb":[[1,1.5,75.72],[2,1.4,75.73]],"ltp":2.16,"tv":5591.98,"id":7412952}]}]}
{"op":"mcm","clk":"1004773422","pt":1580637104782,"mc":[{"id":"1.168209731","rc":[{"batb":[[0,1.88,161.65],[1,1.86,239.76],[2,1.84,19.22]],"batl":[[0,1.94,162.07],[1,1.96,207.48],[2,1.98,51.87]],"ltp":1.87,"tv":16974.18,"id":8174357}]}]}
{"op":"mcm","clk":"1004773443","pt":1580637105251,"mc":[{"id":"1.168209731","rc":[{"batb":[[0,1.84,19.22],[1,1.3,75.72],[2,1.2,189.31]],"batl":[[0,1.98,51.87],[1,2.3,309.75],[2,2.5,10.13]],"ltp":1.87,"tv":16974.18,"id":8174357}]}]}
{"op":"mcm","clk":"1004773557","pt":1580637107666,"mc":[{"id":"1.168209731","rc":[{"batb":[[1,1.83,225.61],[2,1.81,261.83]],"batl":[[1,2,157.69],[2,2.02,189.66]],"ltp":1.87,"tv":16974.18,"id":8174357}]}]}
{"op":"mcm","clk":"1004774174","pt":1580637119184,"mc":[{"id":"1.168209731","rc":[{"batb":[[1,1.4,75.72],[2,1.3,75.72]],"batl":[[1,2.3,309.75],[2,2.5,10.13]],"ltp":1.87,"tv":16974.18,"id":8174357}]}]}
{"op":"mcm","clk":"1004774265","pt":1580637120775,"mc":[{"id":"1.168209731","rc":[{"batb":[[0,1.85,18.97],[1,1.84,19.22],[2,1.4,75.72]],"batl":[[0,1.95,53.1],[1,1.98,51.87],[2,2.3,309.75]],"ltp":1.87,"tv":16974.18,"id":8174357},{"batb":[[0,2.04,16.87],[1,2.02,17.24],[2,1.5,75.72]],"batl":[[0,2.18,5.75],[1,2.2,5.03],[2,1000,0.02]],"ltp":2.16,"tv":5591.98,"id":7412952}]}]}
{"op":"mcm","clk":"1004774316","pt":1580637121802,"mc":[{"id":"1.168209731","rc":[{"batb":[[0,1.89,1034.97]],"batl":[[0,1.98,51.87],[1,2.5,10.13],[2,3,42.01]],"ltp":1.87,"tv":16974.18,"id":8174357},{"batb":[[0,2.02,17.24],[1,1.5,75.72],[2,1.4,75.73]],"batl":[[0,2.08,2889.6],[1,2.14,888.11],[2,2.2,11.58]],"ltp":2.16,"tv":5591.98,"id":7412952}]}]}
{"op":"mcm","clk":"1004774327","pt":1580637122010,"mc":[{"id":"1.168209731","rc":[{"batb":[[0,1.89,103.5]],"ltp":1.87,"tv":16974.18,"id":8174357},{"batl":[[0,2.14,88.81],[1,2.2,5.03],[2,1000,0.02]],"ltp":2.16,"tv":5591.98,"id":7412952}]}]}
{"op":"mcm","clk":"1004774445","pt":1580637124126,"mc":[{"id":"1.168209731","rc":[{"batb":[[2,1.62,11.7]],"ltp":1.87,"tv":16974.18,"id":8174357}]}]}
{"op":"mcm","clk":"1004774505","pt":1580637125105,"mc":[{"id":"1.168209731","rc":[{"batl":[[2,2.6,508.48]],"ltp":1.87,"tv":16974.18,"id":8174357}]}]}
{"op":"mcm","clk":"1004774583","pt":1580637126699,"mc":[{"id":"1.168209731","rc":[{"trd":[[1.83,1204.99],[1.84,70],[1.87,709.34],[1.89,2347.73]],"batb":[[0,1.74,630.09],[1,1.62,11.7],[2,1.4,75.72]],"batl":[[0,1.83,36.88],[1,1.89,8.99],[2,1.9,107.08]],"ltp":1.83,"tv":18383.27,"id":8174357},{"trd":[[2.14,190.24],[2.2,87.73]],"batb":[[0,2.08,94.96],[1,2.02,17.24],[2,1.5,75.72]],"batl":[[0,1000,0.02],[1,2.2,0],[2,1000,0]],"ltp":2.2,"tv":5703.0,"id":7412952}],"tv":24086.27}]}
{"op":"mcm","clk":"1004774686","pt":1580637128295,"mc":[{"id":"1.168209731","rc":[{"batl":[[2,1.9,149.09]],"ltp":1.83,"tv":18383.27,"id":8174357},{"batb":[[0,2.1,37.81],[1,2.08,94.96],[2,2.02,17.24]],"batl":[[0,2.3,31.93],[1,1000,0.02]],"ltp":2.2,"tv":5703.0,"id":7412952}]}]}
{"op":"mcm","clk":"1004774755","pt":1580637129731,"mc":[{"id":"1.168209731","rc":[{"batb":[[0,1.76,54.61],[1,1.74,630.09],[2,1.62,11.7]],"ltp":1.83,"tv":18383.27,"id":8174357}]}]}
{"op":"mcm","clk":"1004774815","pt":1580637130318,"mc":[{"id":"1.168209731","rc":[{"trd":[[1.83,1278.75]],"batb":[[0,1.84,199.34],[1,1.82,257.71],[2,1.76,54.61]],"batl":[[0,1.89,8.99],[1,1.9,149.09],[2,1.91,240.46]],"ltp":1.83,"tv":18457.03,"id":8174357}],"tv":24160.03}]}
{"op":"mcm","clk":"1004775036","pt":1580637133320,"mc":[{"id":"1.168209731","rc":[{"batl":[[2,1.91,259.99]],"ltp":1.83,"tv":18457.03,"id":8174357}]}]}
{"op":"mcm","clk":"1004775226","pt":1580637136720,"mc":[{"id":"1.168209731","rc":[{"trd":[[1.89,2351.97]],"batb":[[1,1.83,9.15],[2,1.82,257.71]],"batl":[[0,1.9,149.09],[1,1.91,259.99],[2,1.93,217.77]],"ltp":1.89,"tv":18461.27,"id":8174357}],"tv":24164.27}]}
{"op":"mcm","clk":"1004775415","pt":1580637139716,"mc":[{"id":"1.168209731","rc":[{"trd":[[1.84,80.13]],"batb":[[0,1.84,194.27]],"batl":[[0,1.86,11.97],[1,1.9,149.09],[2,1.91,259.99]],"ltp":1.84,"tv":18471.4,"id":8174357},{"batl":[[0,2.24,14.03],[1,2.3,31.93],[2,1000,0.02]],"ltp":2.2,"tv":5703.0,"id":7412952}],"tv":24174.41}]}
{"op":"mcm","clk":"1004775438","pt":1580637140023,"mc":[{"id":"1.168209731","rc":[{"batl":[[1,1.89,3.39],[2,1.9,149.09]],"ltp":1.84,"tv":18471.4,"id":8174357}]}]}
{"op":"mcm","clk":"1004775702","pt":1580637143927,"mc":[{"id":"1.168209731","rc":[{"batb":[[1,1.82,257.71],[2,1.76,54.61]],"ltp":1.84,"tv":18471.4,"id":8174357}]}]}
{"op":"mcm","clk":"1004775746","pt":1580637144552,"mc":[{"id":"1.168209731","rc":[{"batl":[[1,1.9,149.09],[2,1.91,259.99]],"ltp":1.84,"tv":18471.4,"id":8174357}]}]}
{"op":"mcm","clk":"1004775870","pt":1580637146163,"mc":[{"id":"1.168209731","rc":[{"batl":[[0,1.9,149.09],[1,1.91,259.99],[2,1.93,217.77]],"ltp":1.84,"tv":18471.4,"id":8174357},{"batl":[[0,2.3,31.93],[1,1000,0.02],[2,1000,0]],"ltp":2.2,"tv":5703.0,"id":7412952}]}]}
{"op":"mcm","clk":"1004775975","pt":1580637147827,"mc":[{"id":"1.168209731","rc":[{"trd":[[1.82,1273.29],[1.84,468.69],[1.87,727.61]],"batb":[[0,1.76,54.61],[1,1.74,630.09],[2,1.62,11.7]],"batl":[[0,1.82,590.79],[1,1.9,149.09],[2,1.91,259.99]],"ltp":1.82,"tv":19393.66,"id":8174357},{"trd":[[2.16,293.08]],"ltp":2.16,"tv":5703.03,"id":7412952}],"tv":25096.7}]}
{"op":"mcm","clk":"1004775994","pt":1580637148131,"mc":[{"id":"1.168209731","rc":[{"batl":[[2,1.98,51.87]],"ltp":1.82,"tv":19393.66,"id":8174357}]}]}
{"op":"mcm","clk":"1004776044","pt":1580637149164,"mc":[{"id":"1.168209731","rc":[{"batl":[[1,1.86,11.97],[2,1.9,149.09]],"ltp":1.82,"tv":19393.66,"id":8174357},{"batl":[[0,2.24,14.03],[1,2.3,31.93],[2,1000,0.02]],"ltp":2.16,"tv":5703.03,"id":7412952}]}]}
{"op":"mcm","clk":"1004776148","pt":1580637150931,"mc":[{"id":"1.168209731","rc":[{"trd":[[1.82,1557.58]],"batl":[[0,1.82,448.64]],"ltp":1.82,"tv":19677.95,"id":8174357}],"tv":25380.99}]}
{"op":"mcm","clk":"1004776181","pt":1580637151451,"mc":[{"id":"1.168209731","rc":[{"trd":[[1.82,2002.21]],"batl":[[0,1.82,226.31]],"ltp":1.82,"tv":20122.59,"id":8174357}],"tv":25825.62}]}
{"op":"mcm","clk":"1004776363","pt":1580637154346,"mc":[{"id":"1.168209731","rc":[{"trd":[[1.82,2006.95]],"batb":[[0,1.81,232.21],[1,1.79,272.84],[2,1.76,54.61]],"batl":[[0,1.82,221.58],[2,1.87,166.61]],"ltp":1.82,"tv":20127.32,"id":8174357},{"trd":[[2.2,91.65]],"ltp":2.2,"tv":5706.94,"id":7412952}],"tv":25834.27}]}
{"op":"mcm","clk":"1004776458","pt":1580637155942,"mc":[{"id":"1.168209731","rc":[{"batl":[[1,1.84,3.39],[2,1.86,11.97]],"ltp":1.82,"tv":20127.32,"id":8174357}]}]}
{"op":"mcm","clk":"1004776554","pt":1580637157746,"mc":[{"id":"1.168209731","rc":[{"trd":[[1.82,2274.23]],"batl":[[0,1.82,87.93]],"ltp":1.82,"tv":20394.61,"id":8174357}],"tv":26101.56}]}
{"op":"mcm","clk":"1004776616","pt":1580637158875,"mc":[{"id":"1.168209731","rc":[{"batl":[[1,1.86,11.97],[2,1.87,166.61]],"ltp":1.82,"tv":20394.61,"id":8174357}]}]}
{"op":"mcm","clk":"1004776991","pt":1580637165784,"mc":[{"id":"1.168209731","rc":[{"trd":[[1.82,2282.64]],"batl":[[0,1.82,83.73]],"ltp":1.82,"tv":20403.01,"id":8174357}],"tv":26109.96}]}
{"op":"mcm","clk":"1004777023","pt":1580637166301,"mc":[{"id":"1.168209731","rc":[{"trd":[[1.81,76.19]],"batb":[[0,1.81,194.21]],"ltp":1.81,"tv":20479.01,"id":8174357}],"tv":26185.96}]}
{"op":"mcm","clk":"1004777205","pt":1580637169612,"mc":[{"id":"1.168209731","rc":[{"trd":[[1.81,82.96]],"batb":[[0,1.81,190.82]],"batl":[[2,1.87,186.43]],"ltp":1.81,"tv":20485.78,"id":8174357}],"tv":26192.73}]}
{"op":"mcm","clk":"1004777267","pt":1580637170495,"mc":[{"id":"1.168209731","rc":[{"trd":[[1.82,2285.1]],"batl":[[0,1.82,81.27]],"ltp":1.82,"tv":20488.25,"id":8174357},{"trd":[[2.2,93.69]],"ltp":2.2,"tv":5708.98,"id":7412952}],"tv":26197.24}]}
{"op":"mcm","clk":"1004777434","pt":1580637173490,"mc":[{"id":"1.168209731","rc":[{"trd":[[1.82,2285.37]],"batl":[[0,1.82,81.13]],"ltp":1.82,"tv":20488.52,"id":8174357}],"tv":26197.51}]}
{"op":"mcm","clk":"1004778440","pt":1580637192849,"mc":[{"id":"1.168209731","rc":[{"batl":[[2,1000,1.53]],"ltp":2.2,"tv":5708.98,"id":7412952}]}]}
{"op":"mcm","clk":"1004778462","pt":1580637193214,"mc":[{"id":"1.168209731","rc":[{"batl":[[2,1000,0.02]],"ltp":2.2,"tv":5708.98,"id":7412952}]}]}
{"op":"mcm","clk":"1004778610","pt":1580637196314,"mc":[{"id":"1.168209731","rc":[{"trd":[[1.82,2287.2]],"batl":[[0,1.82,79.3]],"ltp":1.82,"tv":20490.35,"id":8174357},{"trd":[[2.2,95.2]],"ltp":2.2,"tv":5710.5,"id":7412952}],"tv":26200.85}]}
{"op":"mcm","clk":"1004778973","pt":1580637204841,"mc":[{"id":"1.168209731","rc":[{"trd":[[1.82,2291.2]],"batl":[[0,1.82,77.3]],"ltp":1.82,"tv":20494.35,"id":8174357}],"tv":26204.85}]}
{"op":"mcm","clk":"1004779226","pt":1580637209945,"mc":[{"id":"1.168209731","rc":[{"batb":[[0,1.76,54.61],[1,1.62,11.7],[2,1.3,75.72]],"batl":[[1,1.9,42.01],[2,1.98,51.87]],"ltp":1.82,"tv":20494.35,"id":8174357},{"batb":[[1,2.02,17.24],[2,1.6,75.72]],"batl":[[0,2.3,31.93],[1,1000,0.02],[2,1000,0]],"ltp":2.2,"tv":5710.5,"id":7412952}]}]}
{"op":"mcm","clk":"1004779254","pt":1580637210565,"mc":[{"id":"1.168209731","rc":[{"batl":[[0,1.82,78.11]],"ltp":1.82,"tv":20494.35,"id":8174357}]}]}
{"op":"mcm","clk":"1004779285","pt":1580637211236,"mc":[{"id":"1.168209731","rc":[{"batb":[[0,1.62,11.7],[1,1.3,75.72],[2,1.2,189.31]],"batl":[[1,1.98,51.87],[2,2.42,556.38]],"ltp":1.82,"tv":20494.35,"id":8174357},{"batb":[[0,2.02,17.24],[1,1.6,75.72],[2,1.5,75.72]],"batl":[[0,1000,0.02],[1,1000,0]],"ltp":2.2,"tv":5710.5,"id":7412952}]}]}
{"op":"mcm","clk":"1004779355","pt":1580637212935,"mc":[{"id":"1.168209731","rc":[{"batb":[[0,1.7,191.24],[1,1.68,338.8],[2,1.62,11.7]],"batl":[[1,1.93,66.5],[2,1.94,213.06]],"ltp":1.82,"tv":20494.35,"id":8174357},{"batb":[[0,2.06,20.58],[1,2.02,17.24],[2,1.6,75.72]],"ltp":2.2,"tv":5710.5,"id":7412952}]}]}
{"op":"mcm","clk":"1004779372","pt":1580637213145,"mc":[{"id":"1.168209731","rc":[{"batl":[[1,1.94,213.06],[2,1.96,208.36]],"ltp":1.82,"tv":20494.35,"id":8174357},{"batb":[[0,2.02,17.24],[1,1.6,75.72],[2,1.5,75.72]],"ltp":2.2,"tv":5710.5,"id":7412952}]}]}
{"op":"mcm","clk":"1004779688","pt":1580637219849,"mc":[{"id":"1.168209731","rc":[{"batl":[[0,1.81,9.42],[1,1.82,77.3],[2,1.93,66.5]],"ltp":1.82,"tv":20494.35,"id":8174357},{"batb":[[0,2.06,20.58],[1,2.02,17.24],[2,1.6,75.72]],"ltp":2.2,"tv":5710.5,"id":7412952}]}]}
{"op":"mcm","clk":"1004779700","pt":1580637220156,"mc":[{"id":"1.168209731","rc":[{"batl":[[2,1.94,213.06]],"ltp":1.82,"tv":20494.35,"id":8174357},{"batb":[[0,2.02,17.24],[1,1.6,75.72],[2,1.5,75.72]],"ltp":2.2,"tv":5710.5,"id":7412952}]}]}
{"op":"mcm","clk":"1004779849","pt":1580637223292,"mc":[{"id":"1.168209731","rc":[{"batl":[[2,1.93,66.5]],"ltp":1.82,"tv":20494.35,"id":8174357},{"batb":[[0,2.06,20.58],[1,2.02,17.24],[2,1.6,75.72]],"ltp":2.2,"tv":5710.5,"id":7412952}]}]}
{"op":"mcm","clk":"1004779920","pt":1580637224783,"mc":[{"id":"1.168209731","rc":[{"batb":[[0,1.62,11.7],[1,1.3,75.72],[2,1.2,189.31]],"batl":[[2,1.94,213.06]],"ltp":1.82,"tv":20494.35,"id":8174357},{"batb":[[0,2.02,17.24],[1,1.6,75.72],[2,1.5,75.72]],"ltp":2.2,"tv":5710.5,"id":7412952}]}]}
{"op":"mcm","clk":"1004780057","pt":1580637227868,"mc":[{"id":"1.168209731","rc":[{"trd":[[1.81,92.38],[1.82,2368.5]],"batb":[[0,1.87,231.26],[1,1.85,244.94],[2,1.62,11.7]],"batl":[[0,1.94,222.77],[1,1.96,821.7],[2,1.97,63.5]],"ltp":1.82,"tv":20581.07,"id":8174357},{"trd":[[2.2,159.14],[2.22,7.84]],"batb":[[1,1.5,75.72],[2,1.4,75.73]],"batl":[[0,2.12,11.36],[1,2.18,86.72],[2,2.2,687.22]],"ltp":2.2,"tv":5782.13,"id":7412952}],"tv":26363.2}]}
{"op":"mcm","clk":"1004780096","pt":1580637228688,"mc":[{"id":"1.168209731","rc":[{"batb":[[1,1.85,712.49]],"ltp":1.82,"tv":20581.07,"id":8174357}]}]}
{"op":"mcm","clk":"1004780145","pt":1580637229666,"mc":[{"id":"1.168209731","rc":[{"batb":[[1,1.85,871.65]],"ltp":1.82,"tv":20581.07,"id":8174357},{"batl":[[2,2.2,695.55]],"ltp":2.2,"tv":5782.13,"id":7412952}]}]}
{"op":"mcm","clk":"1004780205","pt":1580637230696,"mc":[{"id":"1.168209731","rc":[{"batb":[[2,1.81,51.25]],"batl":[[2,1.97,105.51]],"ltp":1.82,"tv":20581.07,"id":8174357},{"batb":[[0,2.02,58.41]],"batl":[[2,2.2,687.22]],"ltp":2.2,"tv":5782.13,"id":7412952}]}]}
{"op":"mcm","clk":"1004780252","pt":1580637231675,"mc":[{"id":"1.168209731","rc":[{"batb":[[1,1.85,274.2],[2,1.84,48.76]],"ltp":1.82,"tv":20581.07,"id":8174357}]}]}
{"op":"mcm","clk":"1004780268","pt":1580637232088,"mc":[{"id":"1.168209731","rc":[{"batb":[[1,1.85,244.94]],"ltp":1.82,"tv":20581.07,"id":8174357}]}]}
{"op":"mcm","clk":"1004780370","pt":1580637233890,"mc":[{"id":"1.168209731","rc":[{"batb":[[2,1.81,51.25]],"batl":[[1,1.96,887.32]],"ltp":1.82,"tv":20581.07,"id":8174357},{"batb":[[0,2.04,21.12],[1,2.02,58.41],[2,2,62.91]],"ltp":2.2,"tv":5782.13,"id":7412952}]}]}
{"op":"mcm","clk":"1004780828","pt":1580637242737,"mc":[{"id":"1.168209731","rc":[{"batb":[[0,1.81,51.25],[1,1.62,11.7],[2,1.4,75.72]],"batl":[[0,1.97,42.01],[1,2,63.03],[2,2.42,556.38]],"ltp":1.82,"tv":20581.07,"id":8174357},{"batb":[[0,2.02,41.17],[1,2,62.91],[2,1.5,75.72]],"batl":[[0,2.22,33.61],[1,1000,0.02],[2,2.2,0]],"ltp":2.2,"tv":5782.13,"id":7412952}]}]}
{"op":"mcm","clk":"1004780851","pt":1580637243309,"mc":[{"id":"1.168209731","rc":[{"batb":[[0,1.62,11.7],[1,1.4,75.72],[2,1.3,75.72]],"batl":[[0,2,63.03],[1,2.42,556.38],[2,2.5,10.13]],"ltp":1.82,"tv":20581.07,"id":8174357},{"batb":[[0,2,62.91],[1,1.5,75.72],[2,1.4,75.73]],"batl":[[0,1000,0.02],[1,1000,0]],"ltp":2.2,"tv":5782.13,"id":7412952}]}]}
{"op":"mcm","clk":"1004781004","pt":1580637246706,"mc":[{"id":"1.168209731","rc":[{"batb":[[0,1.77,290.54],[1,1.75,294.51],[2,1.62,11.7]],"batl":[[0,1.99,148.08],[1,2,62.91],[2,2.02,286.87]],"ltp":1.82,"tv":20581.07,"id":8174357}]}]}
{"op":"mcm","clk":"1004781156","pt":1580637249948,"mc":[{"id":"1.168209731","rc":[{"batl":[[0,1.96,65.62],[1,1.99,148.08],[2,2,62.91]],"ltp":1.82,"tv":20581.07,"id":8174357},{"batb":[[0,2.04,21.12],[1,2,62.91],[2,1.5,75.72]],"ltp":2.2,"tv":5782.13,"id":7412952}]}]}
{"op":"mcm","clk":"1004781171","pt":1580637250223,"mc":[{"id":"1.168209731","rc":[{"batl":[[0,2,63.03],[1,2.42,556.38],[2,2.5,10.13]],"ltp":1.82,"tv":20581.07,"id":8174357},{"batb":[[0,2,62.91],[1,1.5,75.72],[2,1.4,75.73]],"ltp":2.2,"tv":5782.13,"id":7412952}]}]}
{"op":"mcm","clk":"1004781319","pt":1580637252950,"mc":[{"id":"1.168209731","rc":[{"batb":[[2,1.4,75.72]],"batl":[[0,1.83,15.28],[1,1.86,177.86],[2,2,63.03]],"ltp":1.82,"tv":20581.07,"id":8174357},{"batb":[[0,2.2,431.52],[1,2.16,114.57],[2,2,62.91]],"batl":[[0,2.28,9.9],[1,2.36,402.73],[2,1000,0.02]],"ltp":2.2,"tv":5782.13,"id":7412952}]}]}
{"op":"mcm","clk":"1004781322","pt":1580637253002,"mc":[{"id":"1.168209731","rc":[{"batl":[[1,1.84,283.09],[2,1.86,422.79]],"ltp":1.82,"tv":20581.07,"id":8174357}]}]}
{"op":"mcm","clk":"1004781383","pt":1580637254235,"mc":[{"id":"1.168209731","rc":[{"batb":[[2,1.74,56.29]],"ltp":1.82,"tv":20581.07,"id":8174357},{"batb":[[2,2.14,36.13]],"batl":[[1,2.36,432.98]],"ltp":2.2,"tv":5782.13,"id":7412952}]}]}
{"op":"mcm","clk":"1004781660","pt":1580637259760,"mc":[{"id":"1.168209731","rc":[{"batb":[[1,1.75,788.54]],"ltp":1.82,"tv":20581.07,"id":8174357}]}]}
{"op":"mcm","clk":"1004781902","pt":1580637264819,"mc":[{"id":"1.168209731","rc":[{"trd":[[1.74,16.48],[1.75,2358.03],[1.77,581.08],[1.78,25.28]],"batb":[[0,1.74,48.05],[1,1.73,510.84],[2,1.4,75.72]],"ltp":1.74,"tv":22768.4,"id":8174357},{"trd":[[2.28,39.43]],"batl":[[0,2.36,432.98],[1,1000,0.02],[2,1000,0]],"ltp":2.28,"tv":5792.03,"id":7412952}],"tv":28560.43}]}
{"op":"mcm","clk":"1004781920","pt":1580637265186,"mc":[{"id":"1.168209731","rc":[{"batb":[[0,1.73,510.84],[1,1.4,75.72],[2,1.3,75.72]],"batl":[[1,1.86,177.86],[2,1.87,480.59]],"ltp":1.74,"tv":22768.4,"id":8174357}]}]}
{"op":"mcm","clk":"1004782097","pt":1580637268547,"mc":[{"id":"1.168209731","rc":[{"batb":[[0,1.75,263.35],[1,1.73,875]],"batl":[[0,1.81,212.06],[1,1.83,274.12],[2,1.86,177.86]],"ltp":1.74,"tv":22768.4,"id":8174357}]}]}
{"op":"mcm","clk":"1004782194","pt":1580637270665,"mc":[{"id":"1.168209731","rc":[{"batb":[[0,1.73,567.97],[1,1.3,75.72],[2,1.2,189.31]],"batl":[[0,1.87,480.59],[1,1.88,42.01],[2,1.89,497.4]],"ltp":1.74,"tv":22768.4,"id":8174357},{"batb":[[0,2.14,36.13],[1,2.04,20.37],[2,2,62.91]],"batl":[[0,2.36,30.25]],"ltp":2.28,"tv":5792.03,"id":7412952}]}]}
{"op":"mcm","clk":"1004782231","pt":1580637271536,"mc":[{"id":"1.168209731","rc":[{"batb":[[0,1.73,510.84]],"batl":[[1,1.89,497.4],[2,1.91,66.5]],"ltp":1.74,"tv":22768.4,"id":8174357},{"batb":[[0,2.04,20.37],[1,2,62.91],[2,1.6,75.72]],"batl":[[0,1000,0.02],[1,1000,0]],"ltp":2.28,"tv":5792.03,"id":7412952}]}]}
{"op":"mcm","clk":"1004782342","pt":1580637273848,"mc":[{"id":"1.168209731","rc":[{"batb":[[1,1.62,356.93],[2,1.61,200.1]],"batl":[[1,1.89,710.91],[2,1.91,292.56]],"ltp":1.74,"tv":22768.4,"id":8174357},{"batb":[[0,2.08,20.31],[1,2.04,20.37],[2,2,62.91]],"ltp":2.28,"tv":5792.03,"id":7412952}]}]}
{"op":"mcm","clk":"1004782352","pt":1580637274156,"mc":[{"id":"1.168209731","rc":[{"batb":[[0,2.04,20.37],[1,2,62.91],[2,1.6,75.72]],"ltp":2.28,"tv":5792.03,"id":7412952}]}]}
{"op":"mcm","clk":"1004782429","pt":1580637275649,"mc":[{"id":"1.168209731","rc":[{"batb":[[0,1.74,195.77],[1,1.73,510.84],[2,1.62,356.93]],"ltp":1.74,"tv":22768.4,"id":8174357}]}]}
{"op":"mcm","clk":"1004782485","pt":1580637276472,"mc":[{"id":"1.168209731","rc":[{"batb":[[0,1.73,510.84],[1,1.62,356.93],[2,1.61,200.1]],"ltp":1.74,"tv":22768.4,"id":8174357}]}]}
{"op":"mcm","clk":"1004782766","pt":1580637282762,"mc":[{"id":"1.168209731","rc":[{"batb":[[1,1.63,195.77],[2,1.62,356.93]],"ltp":1.74,"tv":22768.4,"id":8174357}]}]}
{"op":"mcm","clk":"1004782951","pt":1580637285755,"mc":[{"id":"1.168209731","rc":[{"batb":[[2,1.3,75.72]],"batl":[[0,1.89,213.51],[1,1.91,292.56],[2,1.95,63.7]],"ltp":1.74,"tv":22768.4,"id":8174357},{"batb":[[0,2.08,20.31],[1,2.04,20.37],[2,2,62.91]],"ltp":2.28,"tv":5792.03,"id":7412952}]}]}
{"op":"mcm","clk":"1004782961","pt":1580637285963,"mc":[{"id":"1.168209731","rc":[{"batb":[[0,2.04,20.37],[1,2,62.91],[2,1.6,75.72]],"ltp":2.28,"tv":5792.03,"id":7412952}]}]}
{"op":"mcm","clk":"1004783054","pt":1580637287866,"mc":[{"id":"1.168209731","rc":[{"batb":[[0,1.79,1148.26],[1,1.76,1742.87],[2,1.73,510.84]],"batl":[[0,1.89,222.54]],"ltp":1.74,"tv":22768.4,"id":8174357},{"batb":[[0,2.08,425],[1,2.04,20.37],[2,2,62.91]],"batl":[[0,2.18,998.48],[1,2.2,17.27],[2,1000,0.02]],"ltp":2.28,"tv":5792.03,"id":7412952}]}]}
{"op":"mcm","clk":"1004783105","pt":1580637288689,"mc":[{"id":"1.168209731","rc":[{"batb":[[0,1.83,162.98],[1,1.81,263.49],[2,1.8,52.09]],"batl":[[2,1.94,42.01]],"ltp":1.74,"tv":22768.4,"id":8174357},{"batb":[[1,2.04,60.7]],"batl":[[0,2.18,99.85],[2,2.26,32.77]],"ltp":2.28,"tv":5792.03,"id":7412952}]}]}
{"op":"mcm","clk":"1004783339","pt":1580637293886,"mc":[{"id":"1.168209731","rc":[{"trd":[[1.89,2424.75]],"batl":[[0,1.89,186.15]],"ltp":1.89,"tv":22841.17,"id":8174357}],"tv":28633.2}]}
{"op":"mcm","clk":"1004783374","pt":1580637294712,"mc":[{"id":"1.168209731","rc":[{"batb":[[1,1.81,757.52]],"batl":[[2,1.93,480.59]],"ltp":1.89,"tv":22841.17,"id":8174357},{"batb":[[1,2.06,21.08],[2,2.04,60.7]],"ltp":2.28,"tv":5792.03,"id":7412952}]}]}
{"op":"mcm","clk":"1004783456","pt":1580637296776,"mc":[{"id":"1.168209731","rc":[{"trd":[[1.84,586.99]],"batb":[[0,1.83,183.79]],"batl":[[0,1.84,351.57],[1,1.89,186.15],[2,1.91,292.56]],"ltp":1.84,"tv":22959.47,"id":8174357},{"trd":[[2.18,99.85]],"batl":[[0,2.2,17.27],[1,2.26,32.77],[2,1000,0.02]],"ltp":2.18,"tv":5891.88,"id":7412952}],"tv":28851.35}]}
{"op":"mcm","clk":"1004783638","pt":1580637300606,"mc":[{"id":"1.168209731","rc":[{"trd":[[1.84,805.64]],"batl":[[0,1.84,242.25]],"ltp":1.84,"tv":23178.13,"id":8174357}],"tv":29070.01}]}
{"op":"mcm","clk":"1004783710","pt":1580637301595,"mc":[{"id":"1.168209731","rc":[{"batb":[[0,1.81,494.03],[1,1.8,52.09],[2,1.79,510.84]],"batl":[[1,1.93,480.59],[2,1.94,109.26]],"ltp":1.84,"tv":23178.13,"id":8174357},{"batb":[[0,2.06,21.08],[1,2.04,40.33],[2,2.02,21.24]],"batl":[[0,2.26,32.77],[1,1000,0.02],[2,1000,0]],"ltp":2.18,"tv":5891.88,"id":7412952}]}]}
{"op":"mcm","clk":"1004783796","pt":1580637303307,"mc":[{"id":"1.168209731","rc":[{"batb":[[1,1.79,510.84],[2,1.74,204.17]],"batl":[[2,1.94,67.25]],"ltp":1.84,"tv":23178.13,"id":8174357},{"batb":[[1,2.02,21.24],[2,2,62.91]],"batl":[[0,1000,0.02],[1,1000,0]],"ltp":2.18,"tv":5891.88,"id":7412952}]}]}
{"op":"mcm","clk":"1004783893","pt":1580637305838,"mc":[{"id":"1.168209731","rc":[{"batl":[[0,1.94,67.25],[1,1.95,63.7],[2,1.96,249.87]],"ltp":1.84,"tv":23178.13,"id":8174357}]}]}
{"op":"mcm","clk":"1004783932","pt":1580637306502,"mc":[{"id":"1.168209731","rc":[{"batl":[[0,1.92,215.09],[1,1.96,249.87],[2,1.97,65.5]],"ltp":1.84,"tv":23178.13,"id":8174357},{"batb":[[0,2.02,21.24],[1,2,62.91],[2,1.6,75.72]],"ltp":2.18,"tv":5891.88,"id":7412952}]}]}
{"op":"mcm","clk":"1004783958","pt":1580637307017,"mc":[{"id":"1.168209731","rc":[{"batb":[[2,1.3,75.72]],"batl":[[0,1.96,249.87],[1,1.97,65.5],[2,1.98,265.78]],"ltp":1.84,"tv":23178.13,"id":8174357}]}]}
{"op":"mcm","clk":"1004784061","pt":1580637308837,"mc":[{"id":"1.168209731","rc":[{"batb":[[0,1.89,172.14],[1,1.88,114.14],[2,1.87,236.95]],"batl":[[2,1.98,278.18]],"ltp":1.84,"tv":23178.13,"id":8174357},{"batb":[[2,1.5,75.72]],"batl":[[0,2.08,10.98],[1,2.12,633.79],[2,1000,0.02]],"ltp":2.18,"tv":5891.88,"id":7412952}]}]}
{"op":"mcm","clk":"1004784122","pt":1580637310211,"mc":[{"id":"1.168209731","rc":[{"batb":[[2,1.97,42.85]],"batl":[[2,2.18,35.29]],"ltp":2.18,"tv":5891.88,"id":7412952}]}]}
{"op":"mcm","clk":"1004784213","pt":1580637311718,"mc":[{"id":"1.168209731","rc":[{"batb":[[1,1.88,143.4]],"ltp":1.84,"tv":23178.13,"id":8174357}]}]}
{"op":"mcm","clk":"1004784408","pt":1580637315645,"mc":[{"id":"1.168209731","rc":[{"batb":[[1,1.88,114.14]],"ltp":1.84,"tv":23178.13,"id":8174357}]}]}
{"op":"mcm","clk":"1004784448","pt":1580637316724,"mc":[{"id":"1.168209731","rc":[{"batl":[[0,1.96,318.74]],"ltp":1.84,"tv":23178.13,"id":8174357},{"batb":[[0,2.04,22.12],[1,2.02,21.24],[2,2,62.91]],"ltp":2.18,"tv":5891.88,"id":7412952}]}]}
{"op":"mcm","clk":"1004784459","pt":1580637317036,"mc":[{"id":"1.168209731","rc":[{"trd":[[1.92,1243.09]],"batl":[[0,1.92,220.26],[1,1.96,318.74],[2,1.97,65.5]],"ltp":1.92,"tv":23190.02,"id":8174357},{"trd":[[2.08,155.59]],"batl":[[0,2.12,633.79],[1,2.18,35.29],[2,1000,0.02]],"ltp":2.08,"tv":5902.86,"id":7412952}],"tv":29092.89}]}
{"op":"mcm","clk":"1004784555","pt":1580637318953,"mc":[{"id":"1.168209731","rc":[{"batb":[[0,1.86,48.73],[1,1.82,194.93],[2,1.67,19.87]],"batl":[[1,1.96,68.87]],"ltp":1.92,"tv":23190.02,"id":8174357},{"batl":[[0,2.18,35.29],[1,1000,0.02],[2,1000,0]],"ltp":2.08,"tv":5902.86,"id":7412952}]}]}
{"op":"mcm","clk":"1004784573","pt":1580637319359,"mc":[{"id":"1.168209731","rc":[{"batb":[[0,1.82,194.93],[1,1.67,19.87],[2,1.4,75.72]],"batl":[[0,1.92,222.38]],"ltp":1.92,"tv":23190.02,"id":8174357},{"batl":[[0,1000,0.02],[1,1000,0]],"ltp":2.08,"tv":5902.86,"id":7412952}]}]}
{"op":"mcm","clk":"1004784632","pt":1580637320856,"mc":[{"id":"1.168209731","rc":[{"batl":[[1,1.94,69.25],[2,1.96,68.87]],"ltp":1.92,"tv":23190.02,"id":8174357},{"batb":[[0,2.06,21.58],[1,2.04,22.12],[2,2.02,21.24]],"ltp":2.08,"tv":5902.86,"id":7412952}]}]}
{"op":"mcm","clk":"1004784680","pt":1580637321867,"mc":[{"id":"1.168209731","rc":[{"batb":[[0,1.82,388.22],[1,1.8,268.39],[2,1.67,19.87]],"batl":[[0,1.92,2.12],[1,1.96,68.87],[2,1.97,65.5]],"ltp":1.92,"tv":23190.02,"id":8174357},{"batb":[[0,2.04,22.12],[1,2.02,21.24],[2,1.5,75.72]],"ltp":2.08,"tv":5902.86,"id":7412952}]}]}
{"op":"mcm","clk":"1004784734","pt":1580637322857,"mc":[{"id":"1.168209731","rc":[{"batb":[[0,1.82,194.93],[1,1.67,19.87],[2,1.4,75.72]],"batl":[[0,1.92,3.1]],"ltp":1.92,"tv":23190.02,"id":8174357}]}]}
{"op":"mcm","clk":"1004784793","pt":1580637323852,"mc":[{"id":"1.168209731","rc":[{"trd":[[1.92,1249.3]],"batb":[[0,1.93,109.3],[1,1.92,222.19],[2,1.82,428.5]],"batl":[[0,1.96,68.87],[1,1.97,65.5],[2,1.99,170.75]],"ltp":1.92,"tv":23196.23,"id":8174357},{"trd":[[2.04,318.68]],"batb":[[0,2.04,14.86],[2,2,4.48]],"batl":[[0,2.12,1261.99],[1,2.2,94.07],[2,1000,0.02]],"ltp":2.04,"tv":5917.38,"id":7412952}],"tv":29113.61}]}
{"op":"mcm","clk":"1004784844","pt":1580637324780,"mc":[{"id":"1.168209731","rc":[{"batb":[[1,1.92,223.2],[2,1.91,45.37]],"ltp":1.92,"tv":23196.23,"id":8174357},{"batl":[[0,2.1,37.81],[1,2.12,1261.99],[2,2.2,94.07]],"ltp":2.04,"tv":5917.38,"id":7412952}]}]}
{"op":"mcm","clk":"1004784965","pt":1580637327566,"mc":[{"id":"1.168209731","rc":[{"trd":[[1.96,1467.96]],"batl":[[0,1.97,65.74],[1,1.99,170.75],[2,2.02,287.32]],"ltp":1.96,"tv":23333.49,"id":8174357},{"batb":[[2,1.92,45.37]],"ltp":2.04,"tv":5917.38,"id":7412952}],"tv":29250.87}]}
{"op":"mcm","clk":"1004785097","pt":1580637330762,"mc":[{"id":"1.168209731","rc":[{"batl":[[1,1.98,8.13],[2,1.99,170.63]],"ltp":1.96,"tv":23333.49,"id":8174357},{"batl":[[0,2.06,7.71],[1,2.1,37.81],[2,2.12,1261.99]],"ltp":2.04,"tv":5917.38,"id":7412952}]}]}
{"op":"mcm","clk":"1004785242","pt":1580637333866,"mc":[{"id":"1.168209731","rc":[{"trd":[[1.94,437.54]],"batl":[[0,1.94,209.8],[1,1.97,65.74],[2,1.99,170.75]],"ltp":1.94,"tv":23341.67,"id":8174357},{"trd":[[2.06,124.85]],"batl":[[0,2.1,37.81],[1,2.12,1261.99],[2,2.14,5.75]],"ltp":2.06,"tv":5925.09,"id":7412952}],"tv":29266.76}]}
{"op":"mcm","clk":"1004785265","pt":1580637334380,"mc":[{"id":"1.168209731","rc":[{"batb":[[2,1.9,225.19]],"ltp":1.94,"tv":23341.67,"id":8174357},{"batl":[[0,2.12,1261.99],[1,2.14,5.75],[2,2.18,4.75]],"ltp":2.06,"tv":5925.09,"id":7412952}]}]}
{"op":"mcm","clk":"1004785377","pt":1580637336806,"mc":[{"id":"1.168209731","rc":[{"trd":[[1.94,445.72]],"batl":[[0,1.94,201.61],[2,1.98,8.13]],"ltp":1.94,"tv":23349.85,"id":8174357},{"trd":[[2.06,132.56]],"ltp":2.06,"tv":5932.8,"id":7412952}],"tv":29282.66}]}
{"op":"mcm","clk":"1004785408","pt":1580637337484,"mc":[{"id":"1.168209731","rc":[{"trd":[[1.93,487.4],[1.94,517.98]],"batb":[[0,1.93,106.85]],"batl":[[0,1.94,167.35]],"ltp":1.93,"tv":23427.01,"id":8174357},{"batl":[[1,2.14,41.88]],"ltp":2.06,"tv":5932.8,"id":7412952}],"tv":29359.81}]}
{"op":"mcm","clk":"1004785673","pt":1580637344105,"mc":[{"id":"1.168209731","rc":[{"batl":[[2,1.99,170.75]],"ltp":1.93,"tv":23427.01,"id":8174357}]}]}
{"op":"mcm","clk":"1004785842","pt":1580637347915,"mc":[{"id":"1.168209731","rc":[{"trd":[[1.93,508.4]],"batb":[[0,1.93,96.35]],"ltp":1.93,"tv":23448.01,"id":8174357}],"tv":29380.82}]}
{"op":"mcm","clk":"1004785868","pt":1580637348490,"mc":[{"id":"1.168209731","rc":[{"batl":[[0,1.94,165.48]],"ltp":1.93,"tv":23448.01,"id":8174357}]}]}
{"op":"mcm","clk":"1004785948","pt":1580637350091,"mc":[{"id":"1.168209731","rc":[{"batb":[[0,2.06,7.71],[1,2.04,14.86],[2,2.02,21.24]],"batl":[[0,2.12,1276.16]],"ltp":2.06,"tv":5932.8,"id":7412952}]}]}
{"op":"mcm","clk":"1004786032","pt":1580637351637,"mc":[{"id":"1.168209731","rc":[{"trd":[[1.93,512.18]],"batb":[[0,1.93,94.46]],"ltp":1.93,"tv":23451.79,"id":8174357}],"tv":29384.6}]}
{"op":"mcm","clk":"1004786152","pt":1580637354220,"mc":[{"id":"1.168209731","rc":[{"trd":[[1.93,513.47]],"batb":[[0,1.93,93.17]],"ltp":1.93,"tv":23453.08,"id":8174357},{"trd":[[2.08,156.79]],"ltp":2.08,"tv":5934.0,"id":7412952}],"tv":29387.09}]}
{"op":"mcm","clk":"1004786403","pt":1580637359744,"mc":[{"id":"1.168209731","rc":[{"batb":[[0,1.86,20.18],[1,1.85,252.14],[2,1.67,19.87]],"batl":[[1,2.5,10.25],[2,2.68,4.39]],"ltp":1.93,"tv":23453.08,"id":8174357},{"batb":[[0,1.6,30.14],[1,1.59,27.11],[2,1.53,33.33]],"batl":[[0,2.18,4.75],[1,1000,0.02],[2,2.18,0]],"ltp":2.08,"tv":5934.0,"id":7412952}]}]}
{"op":"mcm","clk":"1004786574","pt":1580637362803,"mc":[{"id":"1.168209731","rc":[{"batb":[[0,1.88,20.71],[1,1.86,20.18],[2,1.85,475.95]],"batl":[[1,2.16,157.03],[2,2.18,152.51]],"ltp":1.93,"tv":23453.08,"id":8174357},{"batl":[[0,2.14,4.75],[1,2.18,4.75],[2,1000,0.02]],"ltp":2.08,"tv":5934.0,"id":7412952}]}]}
{"op":"mcm","clk":"1004786597","pt":1580637363214,"mc":[{"id":"1.168209731","rc":[{"batb":[[0,1.86,20.18],[1,1.85,252.14],[2,1.67,19.87]],"batl":[[0,1.93,1.01],[1,1.94,165.48],[2,2.5,10.25]],"ltp":1.93,"tv":23453.08,"id":8174357},{"batl":[[0,2.18,4.75],[1,1000,0.02],[2,1000,0]],"ltp":2.08,"tv":5934.0,"id":7412952}]}]}
{"op":"mcm","clk":"1004786795","pt":1580637365951,"mc":[{"id":"1.168209731","rc":[{"trd":[[1.93,514.48],[1.94,545.12]],"batl":[[0,1.94,138.35],[1,2.5,10.25],[2,2.68,4.39]],"ltp":1.94,"tv":23481.23,"id":8174357},{"trd":[[2.06,159.07]],"ltp":2.06,"tv":5960.5,"id":7412952}],"tv":29441.74}]}
{"op":"mcm","clk":"1004786819","pt":1580637366212,"mc":[{"id":"1.168209731","rc":[{"trd":[[1.94,821.82]],"batb":[[0,1.95,96.89],[1,1.93,214.31],[2,1.88,22.21]],"batl":[[0,2.02,151.53],[1,2.04,185.04],[2,2.5,10.13]],"ltp":1.94,"tv":23757.93,"id":8174357},{"batl":[[0,2.14,5.25],[1,2.18,4.75],[2,1000,0.02]],"ltp":2.06,"tv":5960.5,"id":7412952}],"tv":29718.43}]}
{"op":"mcm","clk":"1004786900","pt":1580637367923,"mc":[{"id":"1.168209731","rc":[{"batb":[[0,1.96,29.26],[1,1.95,361.97],[2,1.93,214.31]],"ltp":1.94,"tv":23757.93,"id":8174357}]}]}
{"op":"mcm","clk":"1004786948","pt":1580637368756,"mc":[{"id":"1.168209731","rc":[{"batb":[[0,1.96,154.09]],"ltp":1.94,"tv":23757.93,"id":8174357}]}]}
{"op":"mcm","clk":"1004787006","pt":1580637369943,"mc":[{"id":"1.168209731","rc":[{"batb":[[0,1.96,262.25],[1,1.95,145.65]],"ltp":1.94,"tv":23757.93,"id":8174357}]}]}
{"op":"mcm","clk":"1004787048","pt":1580637370924,"mc":[{"id":"1.168209731","rc":[{"batb":[[0,1.96,232.99],[1,1.88,22.21],[2,1.86,20.18]],"batl":[[0,2.5,10.25],[1,2.68,4.39],[2,2.7,4.35]],"ltp":1.94,"tv":23757.93,"id":8174357}]}]}
{"op":"mcm","clk":"1004787074","pt":1580637371441,"mc":[{"id":"1.168209731","rc":[{"batb":[[0,1.96,108.16]],"ltp":1.94,"tv":23757.93,"id":8174357}]}]}
{"op":"mcm","clk":"1004787118","pt":1580637372227,"mc":[{"id":"1.168209731","rc":[{"batb":[[0,1.86,20.18],[1,1.85,252.14],[2,1.67,19.87]],"ltp":1.94,"tv":23757.93,"id":8174357},{"batl":[[0,2.18,4.75],[1,1000,0.02],[2,1000,0]],"ltp":2.06,"tv":5960.5,"id":7412952}]}]}
{"op":"mcm","clk":"1004787279","pt":1580637374851,"mc":[{"id":"1.168209731","rc":[{"batb":[[2,1.84,282.01]],"batl":[[0,2.16,215.17],[1,2.18,152.56],[2,2.5,10.13]],"ltp":1.94,"tv":23757.93,"id":8174357},{"batb":[[0,1.82,241.98],[1,1.6,30.14],[2,1.59,27.11]],"ltp":2.06,"tv":5960.5,"id":7412952}]}]}
