{"op":"mcm","clk":"996134465","pt":1580560628823,"mc":[{"id":"1.168209734","marketDefinition":{"bspMarket":false,"turnInPlayEnabled":true,"persistenceEnabled":true,"marketBaseRate":5.0,"eventId":"29681142","eventTypeId":"2","numberOfWinners":1,"bettingType":"ODDS","marketType":"SET_WINNER","marketTime":"2020-02-02T04:00:00.000Z","suspendTime":"2020-02-02T04:00:00.000Z","bspReconciled":false,"complete":true,"inPlay":false,"crossMatching":false,"runnersVoidable":false,"numberOfActiveRunners":2,"betDelay":0,"status":"OPEN","runners":[{"status":"ACTIVE","sortPriority":1,"id":8174357,"name":"Blaz Rola"},{"status":"ACTIVE","sortPriority":2,"id":7412952,"name":"Roberto Marcora"}],"regulators":["MR_INT"],"countryCode":"IN","discountAllowed":false,"timezone":"UTC","openDate":"2020-02-02T04:00:00.000Z","version":3145101552,"name":"Set 2 Winner","eventName":"Rola v Marcora"},"rc":[{"batb":[[0,1.01,20]],"ltp":0.0,"tv":0.0,"id":8174357},{"batb":[[0,1.01,20]],"ltp":0.0,"tv":0.0,"id":7412952}]}]}
{"op":"mcm","clk":"996134636","pt":1580560629891,"mc":[{"id":"1.168209734","marketDefinition":{"bspMarket":false,"turnInPlayEnabled":true,"persistenceEnabled":true,"marketBaseRate":5.0,"eventId":"29681142","eventTypeId":"2","numberOfWinners":1,"bettingType":"ODDS","marketType":"SET_WINNER","marketTime":"2020-02-02T04:00:00.000Z","suspendTime":"2020-02-02T04:00:00.000Z","bspReconciled":false,"complete":true,"inPlay":false,"crossMatching":false,"runnersVoidable":false,"numberOfActiveRunners":2,"betDelay":0,"status":"OPEN","runners":[{"status":"ACTIVE","sortPriority":1,"id":8174357,"name":"Blaz Rola"},{"status":"ACTIVE","sortPriority":2,"id":7412952,"name":"Roberto Marcora"}],"regulators":["MR_INT"],"countryCode":"IN","discountAllowed":false,"timezone":"UTC","openDate":"2020-02-02T04:00:00.000Z","version":3145101552,"name":"Set 2 Winner","eventName":"Rola v Marcora"}}]}
{"op":"mcm","clk":"996134845","pt":1580560630893,"mc":[{"id":"1.168209734","marketDefinition":{"bspMarket":false,"turnInPlayEnabled":true,"persistenceEnabled":true,"marketBaseRate":5.0,"eventId":"29681142","eventTypeId":"2","numberOfWinners":1,"bettingType":"ODDS","marketType":"SET_WINNER","marketTime":"2020-02-02T04:00:00.000Z","suspendTime":"2020-02-02T04:00:00.000Z","bspReconciled":false,"complete":true,"inPlay":false,"crossMatching":false,"runnersVoidable":false,"numberOfActiveRunners":2,"betDelay":0,"status":"OPEN","runners":[{"status":"ACTIVE","sortPriority":1,"id":8174357,"name":"Blaz Rola"},{"status":"ACTIVE","sortPriority":2,"id":7412952,"name":"Roberto Marcora"}],"regulators":["MR_INT"],"countryCode":"IN","discountAllowed":true,"timezone":"UTC","openDate":"2020-02-02T04:00:00.000Z","version":3145101552,"name":"Set 2 Winner","eventName":"Rola v Marcora"}}]}
{"op":"mcm","clk":"996235645","pt":1580561114627,"mc":[{"id":"1.168209734","rc":[{"batb":[[0,1.01,10]],"ltp":0.0,"tv":0.0,"id":8174357},{"batb":[[0,1.01,10]],"ltp":0.0,"tv":0.0,"id":7412952}]}]}
{"op":"mcm","clk":"997589873","pt":1580567441341,"mc":[{"id":"1.168209734","marketDefinition":{"bspMarket":false,"turnInPlayEnabled":true,"persistenceEnabled":true,"marketBaseRate":5.0,"eventId":"29681142","eventTypeId":"2","numberOfWinners":1,"bettingType":"ODDS","marketType":"SET_WINNER","marketTime":"2020-02-02T09:30:00.000Z","suspendTime":"2020-02-02T09:30:00.000Z","bspReconciled":false,"complete":true,"inPlay":false,"crossMatching":false,"runnersVoidable":false,"numberOfActiveRunners":2,"betDelay":0,"status":"OPEN","runners":[{"status":"ACTIVE","sortPriority":1,"id":8174357,"name":"Blaz Rola"},{"status":"ACTIVE","sortPriority":2,"id":7412952,"name":"Roberto Marcora"}],"regulators":["MR_INT"],"countryCode":"IN","discountAllowed":true,"timezone":"UTC","openDate":"2020-02-02T04:00:00.000Z","version":3145478791,"name":"Set 2 Winner","eventName":"Rola v Marcora"}}]}
{"op":"mcm","clk":"997590546","pt":1580567444348,"mc":[{"id":"1.168209734","marketDefinition":{"bspMarket":false,"turnInPlayEnabled":true,"persistenceEnabled":true,"marketBaseRate":5.0,"eventId":"29681142","eventTypeId":"2","numberOfWinners":1,"bettingType":"ODDS","marketType":"SET_WINNER","marketTime":"2020-02-02T09:30:00.000Z","suspendTime":"2020-02-02T09:30:00.000Z","bspReconciled":false,"complete":true,"inPlay":false,"crossMatching":false,"runnersVoidable":false,"numberOfActiveRunners":2,"betDelay":0,"status":"OPEN","runners":[{"status":"ACTIVE","sortPriority":1,"id":8174357,"name":"Blaz Rola"},{"status":"ACTIVE","sortPriority":2,"id":7412952,"name":"Roberto Marcora"}],"regulators":["MR_INT"],"countryCode":"IN","discountAllowed":true,"timezone":"UTC","openDate":"2020-02-02T09:30:00.000Z","version":3145478791,"name":"Set 2 Winner","eventName":"Rola v Marcora"}}]}
{"op":"mcm","clk":"1003058399","pt":1580602466055,"mc":[{"id":"1.168209734","rc":[{"batb":[[0,1.01,10.51]],"ltp":0.0,"tv":0.0,"id":8174357},{"batb":[[0,1.01,10.51]],"ltp":0.0,"tv":0.0,"id":7412952}]}]}
{"op":"mcm","clk":"1003179968","pt":1580603998856,"mc":[{"id":"1.168209734","rc":[{"batb":[[0,1.01,13.04]],"ltp":0.0,"tv":0.0,"id":8174357},{"batb":[[0,1.01,13.04]],"ltp":0.0,"tv":0.0,"id":7412952}]}]}
{"op":"mcm","clk":"1003180038","pt":1580603999879,"mc":[{"id":"1.168209734","rc":[{"batb":[[0,1.01,10.51]],"ltp":0.0,"tv":0.0,"id":8174357},{"batb":[[0,1.01,10.51]],"ltp":0.0,"tv":0.0,"id":7412952}]}]}
{"op":"mcm","clk":"1003180050","pt":1580603999985,"mc":[{"id":"1.168209734","rc":[{"batb":[[0,1.01,11.01]],"ltp":0.0,"tv":0.0,"id":8174357},{"batb":[[0,1.01,11.01]],"ltp":0.0,"tv":0.0,"id":7412952}]}]}
{"op":"mcm","clk":"1003387917","pt":1580607069919,"mc":[{"id":"1.168209734","rc":[{"batb":[[0,1.01,11.02]],"ltp":0.0,"tv":0.0,"id":8174357}]}]}
{"op":"mcm","clk":"1003387928","pt":1580607070023,"mc":[{"id":"1.168209734","rc":[{"batb":[[0,1.01,11.02]],"ltp":0.0,"tv":0.0,"id":7412952}]}]}
{"op":"mcm","clk":"1004694408","pt":1580635384846,"mc":[{"id":"1.168209734","rc":[{"batb":[[0,1.88,17.07],[1,1.01,11.02]],"ltp":0.0,"tv":0.0,"id":8174357},{"batb":[[0,2,28.4],[1,1.01,11.02]],"ltp":0.0,"tv":0.0,"id":7412952}]}]}
{"op":"mcm","clk":"1004695586","pt":1580635416039,"mc":[{"id":"1.168209734","marketDefinition":{"bspMarket":false,"turnInPlayEnabled":true,"persistenceEnabled":true,"marketBaseRate":5.0,"eventId":"29681142","eventTypeId":"2","numberOfWinners":1,"bettingType":"ODDS","marketType":"SET_WINNER","marketTime":"2020-02-02T09:30:00.000Z","suspendTime":"2020-02-02T09:30:00.000Z","bspReconciled":false,"complete":true,"inPlay":false,"crossMatching":true,"runnersVoidable":false,"numberOfActiveRunners":2,"betDelay":0,"status":"OPEN","runners":[{"status":"ACTIVE","sortPriority":1,"id":8174357,"name":"Blaz Rola"},{"status":"ACTIVE","sortPriority":2,"id":7412952,"name":"Roberto Marcora"}],"regulators":["MR_INT"],"countryCode":"IN","discountAllowed":true,"timezone":"UTC","openDate":"2020-02-02T09:30:00.000Z","version":3146887563,"name":"Set 2 Winner","eventName":"Rola v Marcora"}}]}
{"op":"mcm","clk":"1004704147","pt":1580635608357,"mc":[{"id":"1.168209734","marketDefinition":{"bspMarket":false,"turnInPlayEnabled":true,"persistenceEnabled":true,"marketBaseRate":5.0,"eventId":"29681142","eventTypeId":"2","numberOfWinners":1,"bettingType":"ODDS","marketType":"SET_WINNER","marketTime":"2020-02-02T09:21:00.000Z","suspendTime":"2020-02-02T09:21:00.000Z","bspReconciled":false,"complete":true,"inPlay":false,"crossMatching":true,"runnersVoidable":false,"numberOfActiveRunners":2,"betDelay":0,"status":"OPEN","runners":[{"status":"ACTIVE","sortPriority":1,"id":8174357,"name":"Blaz Rola"},{"status":"ACTIVE","sortPriority":2,"id":7412952,"name":"Roberto Marcora"}],"regulators":["MR_INT"],"countryCode":"IN","discountAllowed":true,"timezone":"UTC","openDate":"2020-02-02T09:30:00.000Z","version":3148345367,"name":"Set 2 Winner","eventName":"Rola v Marcora"}}]}
{"op":"mcm","clk":"1004704582","pt":1580635614514,"mc":[{"id":"1.168209734","marketDefinition":{"bspMarket":false,"turnInPlayEnabled":true,"persistenceEnabled":true,"marketBaseRate":5.0,"eventId":"29681142","eventTypeId":"2","numberOfWinners":1,"bettingType":"ODDS","marketType":"SET_WINNER","marketTime":"2020-02-02T09:21:00.000Z","suspendTime":"2020-02-02T09:21:00.000Z","bspReconciled":false,"complete":true,"inPlay":false,"crossMatching":true,"runnersVoidable":false,"numberOfActiveRunners":2,"betDelay":0,"status":"OPEN","runners":[{"status":"ACTIVE","sortPriority":1,"id":8174357,"name":"Blaz Rola"},{"status":"ACTIVE","sortPriority":2,"id":7412952,"name":"Roberto Marcora"}],"regulators":["MR_INT"],"countryCode":"IN","discountAllowed":true,"timezone":"UTC","openDate":"2020-02-02T09:21:00.000Z","version":3148345367,"name":"Set 2 Winner","eventName":"Rola v Marcora"}}]}
{"op":"mcm","clk":"1004705268","pt":1580635629258,"mc":[{"id":"1.168209734","rc":[{"batb":[[0,1.87,17.47]],"ltp":0.0,"tv":0.0,"id":8174357},{"batb":[[0,2,27.77]],"ltp":0.0,"tv":0.0,"id":7412952}]}]}
{"op":"mcm","clk":"1004705625","pt":1580635639443,"mc":[{"id":"1.168209734","rc":[{"batb":[[1,1.85,17.86],[2,1.01,11.02]],"ltp":0.0,"tv":0.0,"id":8174357},{"batb":[[0,2.02,27.15]],"ltp":0.0,"tv":0.0,"id":7412952}]}]}
{"op":"mcm","clk":"1004717287","pt":1580635929478,"mc":[{"id":"1.168209734","rc":[{"batb":[[0,1.86,17.78],[1,1.01,11.02],[2,1.01,0]],"ltp":0.0,"tv":0.0,"id":8174357}]}]}
{"op":"mcm","clk":"1004718606","pt":1580635957959,"mc":[{"id":"1.168209734","rc":[{"batb":[[0,1.87,1.34],[1,1.86,17.78],[2,1.01,11.02]],"ltp":0.0,"tv":0.0,"id":8174357},{"batb":[[0,2.04,1.24],[1,2.02,27.15],[2,1.01,11.02]],"ltp":0.0,"tv":0.0,"id":7412952}]}]}
{"op":"mcm","clk":"1004724695","pt":1580636099868,"mc":[{"id":"1.168209734","rc":[{"batb":[[2,1.84,18.18]],"ltp":0.0,"tv":0.0,"id":8174357},{"batb":[[0,2.04,27.91],[1,1.01,11.02],[2,1.01,0]],"ltp":0.0,"tv":0.0,"id":7412952}]}]}
{"op":"mcm","clk":"1004725085","pt":1580636109890,"mc":[{"id":"1.168209734","rc":[{"batb":[[2,1.85,18.02]],"ltp":0.0,"tv":0.0,"id":8174357},{"batb":[[1,2.02,26.83],[2,1.01,11.02]],"ltp":0.0,"tv":0.0,"id":7412952}]}]}
{"op":"mcm","clk":"1004725089","pt":1580636109993,"mc":[{"id":"1.168209734","rc":[{"batb":[[1,1.85,18.02],[2,1.01,11.02]],"ltp":0.0,"tv":0.0,"id":8174357},{"batb":[[0,2.04,1.24]],"ltp":0.0,"tv":0.0,"id":7412952}]}]}
{"op":"mcm","clk":"1004725960","pt":1580636130520,"mc":[{"id":"1.168209734","rc":[{"batb":[[1,1.86,48.73],[2,1.85,18.02]],"batl":[[0,2.06,39.49]],"ltp":0.0,"tv":0.0,"id":8174357},{"batb":[[2,1.96,43.69]],"batl":[[0,2.18,35.29]],"ltp":0.0,"tv":0.0,"id":7412952}]}]}
{"op":"mcm","clk":"1004726509","pt":1580636142841,"mc":[{"id":"1.168209734","marketDefinition":{"bspMarket":false,"turnInPlayEnabled":true,"persistenceEnabled":true,"marketBaseRate":5.0,"eventId":"29681142","eventTypeId":"2","numberOfWinners":1,"bettingType":"ODDS","marketType":"SET_WINNER","marketTime":"2020-02-02T09:21:00.000Z","suspendTime":"2020-02-02T09:21:00.000Z","bspReconciled":false,"complete":true,"inPlay":true,"crossMatching":true,"runnersVoidable":false,"numberOfActiveRunners":2,"betDelay":3,"status":"OPEN","runners":[{"status":"ACTIVE","sortPriority":1,"id":8174357,"name":"Blaz Rola"},{"status":"ACTIVE","sortPriority":2,"id":7412952,"name":"Roberto Marcora"}],"regulators":["MR_INT"],"countryCode":"IN","discountAllowed":true,"timezone":"UTC","openDate":"2020-02-02T09:21:00.000Z","version":3148351362,"name":"Set 2 Winner","eventName":"Rola v Marcora"},"rc":[{"batb":[[0,1.01,10.52],[1,1.86,0],[2,1.85,0]],"ltp":0.0,"tv":0.0,"id":8174357},{"batb":[[0,1.01,10.52],[1,2.02,0],[2,1.96,0]],"ltp":0.0,"tv":0.0,"id":7412952}]}]}
{"op":"mcm","clk":"1004728024","pt":1580636177774,"mc":[{"id":"1.168209734","rc":[{"batb":[[0,1.82,50.41],[1,1.81,19.28],[2,1.79,20.14]],"batl":[[0,2.02,41.17]],"ltp":0.0,"tv":0.0,"id":8174357},{"batb":[[0,2.08,25.02],[1,2.02,27.3],[2,1.97,42.85]],"batl":[[0,2.22,33.61]],"ltp":0.0,"tv":0.0,"id":7412952}]}]}
{"op":"mcm","clk":"1004728634","pt":1580636193215,"mc":[{"id":"1.168209734","rc":[{"batb":[[1,1.79,20.14],[2,1.01,10.52]],"ltp":0.0,"tv":0.0,"id":8174357},{"batb":[[0,2.02,27.3],[1,1.97,42.85],[2,1.01,10.52]],"ltp":0.0,"tv":0.0,"id":7412952}]}]}
{"op":"mcm","clk":"1004728668","pt":1580636194325,"mc":[{"id":"1.168209734","rc":[{"batb":[[0,1.79,20.14],[1,1.01,10.52],[2,1.01,0]],"ltp":0.0,"tv":0.0,"id":8174357},{"batb":[[1,1.01,10.52],[2,1.01,0]],"ltp":0.0,"tv":0.0,"id":7412952}]}]}
{"op":"mcm","clk":"1004728759","pt":1580636196894,"mc":[{"id":"1.168209734","rc":[{"batb":[[0,1.8,19.59]],"ltp":0.0,"tv":0.0,"id":8174357},{"batb":[[0,2,28.17]],"ltp":0.0,"tv":0.0,"id":7412952}]}]}
{"op":"mcm","clk":"1004729394","pt":1580636213713,"mc":[{"id":"1.168209734","rc":[{"batb":[[0,1.88,17.23],[1,1.86,48.73],[2,1.84,18.1]],"batl":[[0,2.08,38.65]],"ltp":0.0,"tv":0.0,"id":8174357},{"batb":[[1,1.94,15.5],[2,1.92,45.37]],"batl":[[0,2.16,36.13]],"ltp":0.0,"tv":0.0,"id":7412952}]}]}
{"op":"mcm","clk":"1004730026","pt":1580636227667,"mc":[{"id":"1.168209734","rc":[{"batb":[[0,1.86,48.73],[1,1.84,18.1],[2,1.01,10.52]],"ltp":0.0,"tv":0.0,"id":8174357},{"batb":[[0,1.94,15.5],[1,1.92,45.37],[2,1.01,10.52]],"ltp":0.0,"tv":0.0,"id":7412952}]}]}
{"op":"mcm","clk":"1004730044","pt":1580636228332,"mc":[{"id":"1.168209734","rc":[{"batb":[[0,1.84,18.1],[1,1.01,10.52],[2,1.01,0]],"ltp":0.0,"tv":0.0,"id":8174357},{"batb":[[1,1.01,10.52],[2,1.01,0]],"ltp":0.0,"tv":0.0,"id":7412952}]}]}
{"op":"mcm","clk":"1004730118","pt":1580636230753,"mc":[{"id":"1.168209734","rc":[{"batb":[[0,1.86,17.7]],"ltp":0.0,"tv":0.0,"id":8174357},{"batb":[[0,1.93,15.74]],"ltp":0.0,"tv":0.0,"id":7412952}]}]}
{"op":"mcm","clk":"1004730259","pt":1580636234781,"mc":[{"id":"1.168209734","rc":[{"batb":[[1,1.83,18.65],[2,1.01,10.52]],"ltp":0.0,"tv":0.0,"id":8174357},{"batb":[[0,2.02,27.3],[1,1.97,29.43],[2,1.93,15.74]],"ltp":0.0,"tv":0.0,"id":7412952}]}]}
{"op":"mcm","clk":"1004730279","pt":1580636235257,"mc":[{"id":"1.168209734","rc":[{"batb":[[1,1.84,49.57],[2,1.83,18.65]],"batl":[[0,2.04,40.33]],"ltp":0.0,"tv":0.0,"id":8174357},{"batb":[[1,1.97,72.28],[2,1.01,10.52]],"batl":[[0,2.18,35.29]],"ltp":0.0,"tv":0.0,"id":7412952}]}]}
{"op":"mcm","clk":"1004730826","pt":1580636248303,"mc":[{"id":"1.168209734","rc":[{"batb":[[0,1.83,18.65],[1,1.01,10.52],[2,1.83,0]],"ltp":0.0,"tv":0.0,"id":8174357},{"batb":[[0,1.97,29.43],[1,1.01,10.52],[2,1.01,0]],"ltp":0.0,"tv":0.0,"id":7412952}]}]}
{"op":"mcm","clk":"1004731149","pt":1580636258394,"mc":[{"id":"1.168209734","rc":[{"batb":[[0,1.9,16.52],[1,1.87,17.39],[2,1.01,10.52]],"ltp":0.0,"tv":0.0,"id":8174357},{"batb":[[1,1.92,16.05],[2,1.01,10.52]],"ltp":0.0,"tv":0.0,"id":7412952}]}]}
{"op":"mcm","clk":"1004731181","pt":1580636259321,"mc":[{"id":"1.168209734","rc":[{"batb":[[1,1.89,47.05],[2,1.87,17.39]],"batl":[[0,2.1,37.81]],"ltp":0.0,"tv":0.0,"id":8174357},{"batb":[[1,1.92,61.42]],"batl":[[0,2.14,36.13]],"ltp":0.0,"tv":0.0,"id":7412952}]}]}
{"op":"mcm","clk":"1004731613","pt":1580636269842,"mc":[{"id":"1.168209734","rc":[{"batb":[[0,1.89,47.05],[1,1.87,17.39],[2,1.01,10.52]],"ltp":0.0,"tv":0.0,"id":8174357},{"batb":[[0,1.92,61.42],[1,1.01,10.52],[2,1.01,0]],"ltp":0.0,"tv":0.0,"id":7412952}]}]}
{"op":"mcm","clk":"1004731647","pt":1580636270523,"mc":[{"id":"1.168209734","rc":[{"batb":[[0,1.87,17.39],[1,1.01,10.52],[2,1.01,0]],"ltp":0.0,"tv":0.0,"id":8174357},{"batb":[[0,1.92,16.05]],"ltp":0.0,"tv":0.0,"id":7412952}]}]}
{"op":"mcm","clk":"1004732628","pt":1580636291736,"mc":[{"id":"1.168209734","rc":[{"batb":[[0,1.96,30.21],[1,1.93,44.53],[2,1.91,16.21]],"batl":[[0,2.16,36.13]],"ltp":0.0,"tv":0.0,"id":8174357},{"batb":[[1,1.88,47.05],[2,1.84,18.25]],"batl":[[0,2.08,38.65]],"ltp":0.0,"tv":0.0,"id":7412952}]}]}
{"op":"mcm","clk":"1004733213","pt":1580636304771,"mc":[{"id":"1.168209734","rc":[{"batb":[[0,1.93,44.53],[1,1.91,16.21],[2,1.01,10.52]],"ltp":0.0,"tv":0.0,"id":8174357},{"batb":[[0,1.88,47.05],[1,1.84,18.25],[2,1.01,10.52]],"ltp":0.0,"tv":0.0,"id":7412952}]}]}
{"op":"mcm","clk":"1004733280","pt":1580636306366,"mc":[{"id":"1.168209734","rc":[{"batb":[[0,1.91,16.21],[1,1.01,10.52],[2,1.01,0]],"ltp":0.0,"tv":0.0,"id":8174357},{"batb":[[0,1.84,18.25],[1,1.01,10.52],[2,1.01,0]],"ltp":0.0,"tv":0.0,"id":7412952}]}]}
{"op":"mcm","clk":"1004733662","pt":1580636315876,"mc":[{"id":"1.168209734","rc":[{"batb":[[0,1.91,61.58],[1,1.88,17.15],[2,1.01,10.52]],"batl":[[0,2.12,36.97]],"ltp":0.0,"tv":0.0,"id":8174357},{"batb":[[0,1.96,29.98],[1,1.9,62.66],[2,1.01,10.52]],"ltp":0.0,"tv":0.0,"id":7412952}]}]}
{"op":"mcm","clk":"1004733670","pt":1580636316083,"mc":[{"id":"1.168209734","rc":[{"batb":[[1,1.9,16.44]],"ltp":0.0,"tv":0.0,"id":7412952}]}]}
{"op":"mcm","clk":"1004733774","pt":1580636318713,"mc":[{"id":"1.168209734","rc":[{"batb":[[2,1.89,47.05]],"ltp":0.0,"tv":0.0,"id":7412952}]}]}
{"op":"mcm","clk":"1004733815","pt":1580636319904,"mc":[{"id":"1.168209734","rc":[{"batl":[[0,2.1,37.81]],"ltp":0.0,"tv":0.0,"id":7412952}]}]}
{"op":"mcm","clk":"1004734533","pt":1580636334732,"mc":[{"id":"1.168209734","rc":[{"batb":[[0,1.88,17.15],[1,1.01,10.52],[2,1.01,0]],"ltp":0.0,"tv":0.0,"id":8174357},{"batb":[[0,1.9,16.44],[1,1.01,10.52],[2,1.89,0]],"ltp":0.0,"tv":0.0,"id":7412952}]}]}
{"op":"mcm","clk":"1004735754","pt":1580636360597,"mc":[{"id":"1.168209734","rc":[{"batb":[[1,1.84,18.18],[2,1.01,10.52]],"ltp":0.0,"tv":0.0,"id":8174357},{"batb":[[0,2,28.25],[1,1.94,15.42],[2,1.01,10.52]],"ltp":0.0,"tv":0.0,"id":7412952}]}]}
{"op":"mcm","clk":"1004735806","pt":1580636361885,"mc":[{"id":"1.168209734","rc":[{"batb":[[0,1.88,64.2]],"batl":[[0,2.1,37.81]],"ltp":0.0,"tv":0.0,"id":8174357},{"batb":[[2,1.93,44.53]],"batl":[[0,2.14,36.13]],"ltp":0.0,"tv":0.0,"id":7412952}]}]}
{"op":"mcm","clk":"1004736616","pt":1580636379695,"mc":[{"id":"1.168209734","rc":[{"batb":[[0,1.88,47.05]],"ltp":0.0,"tv":0.0,"id":8174357},{"batb":[[0,1.94,15.42],[1,1.93,44.53],[2,1.01,10.52]],"ltp":0.0,"tv":0.0,"id":7412952}]}]}
{"op":"mcm","clk":"1004736659","pt":1580636380528,"mc":[{"id":"1.168209734","rc":[{"batb":[[0,1.84,18.18],[1,1.01,10.52],[2,1.01,0]],"ltp":0.0,"tv":0.0,"id":8174357},{"batb":[[1,1.01,10.52],[2,1.01,0]],"ltp":0.0,"tv":0.0,"id":7412952}]}]}
{"op":"mcm","clk":"1004737954","pt":1580636405136,"mc":[{"id":"1.168209734","rc":[{"batl":[[0,2.52,270.1]],"ltp":0.0,"tv":0.0,"id":8174357},{"batl":[[0,2.7,245.56]],"ltp":0.0,"tv":0.0,"id":7412952}]}]}
{"op":"mcm","clk":"1004738883","pt":1580636424923,"mc":[{"id":"1.168209734","rc":[{"batb":[[1,1.8,19.59],[2,1.01,10.52]],"ltp":0.0,"tv":0.0,"id":8174357},{"batb":[[0,2.04,26.59],[1,2,28.17],[2,1.94,15.42]],"ltp":0.0,"tv":0.0,"id":7412952}]}]}
{"op":"mcm","clk":"1004738929","pt":1580636425494,"mc":[{"id":"1.168209734","rc":[{"batb":[[0,1.84,67.75]],"batl":[[0,2.04,40.33],[1,2.52,270.1]],"ltp":0.0,"tv":0.0,"id":8174357},{"batb":[[2,1.97,42.85]],"batl":[[0,2.18,35.29],[1,2.7,245.56]],"ltp":0.0,"tv":0.0,"id":7412952}]}]}
{"op":"mcm","clk":"1004739336","pt":1580636433714,"mc":[{"id":"1.168209734","rc":[{"batb":[[0,1.86,17.7],[1,1.84,49.57],[2,1.82,19.04]],"ltp":0.0,"tv":0.0,"id":8174357},{"batb":[[0,2.02,27.3],[1,1.98,28.95]],"ltp":0.0,"tv":0.0,"id":7412952}]}]}
{"op":"mcm","clk":"1004739657","pt":1580636441325,"mc":[{"id":"1.168209734","rc":[{"batb":[[0,1.87,17.23],[2,1.83,18.57]],"ltp":0.0,"tv":0.0,"id":8174357},{"batb":[[0,2,28.09],[1,1.97,72.51],[2,1.01,10.52]],"ltp":0.0,"tv":0.0,"id":7412952}]}]}
{"op":"mcm","clk":"1004741464","pt":1580636476585,"mc":[{"id":"1.168209734","rc":[{"batb":[[0,1.83,18.57],[1,1.01,10.52],[2,1.83,0]],"batl":[[0,2.52,270.1],[1,2.52,0]],"ltp":0.0,"tv":0.0,"id":8174357},{"batb":[[0,1.97,29.66],[1,1.01,10.52],[2,1.01,0]],"batl":[[0,2.7,245.56],[1,2.7,0]],"ltp":0.0,"tv":0.0,"id":7412952}]}]}
{"op":"mcm","clk":"1004742458","pt":1580636493490,"mc":[{"id":"1.168209734","rc":[{"batb":[[0,1.91,16.37],[1,1.88,47.05],[2,1.87,17.47]],"batl":[[0,2.08,38.65],[1,2.52,270.1]],"ltp":0.0,"tv":0.0,"id":8174357},{"batb":[[1,1.94,60.11],[2,1.01,10.52]],"batl":[[0,2.16,36.13],[1,2.7,245.56]],"ltp":0.0,"tv":0.0,"id":7412952}]}]}
{"op":"mcm","clk":"1004743491","pt":1580636509555,"mc":[{"id":"1.168209734","rc":[{"batb":[[0,1.88,47.05],[1,1.87,17.47],[2,1.01,10.52]],"ltp":0.0,"tv":0.0,"id":8174357},{"batb":[[0,1.94,60.11],[1,1.01,10.52],[2,1.01,0]],"ltp":0.0,"tv":0.0,"id":7412952}]}]}
{"op":"mcm","clk":"1004743570","pt":1580636510742,"mc":[{"id":"1.168209734","rc":[{"batb":[[0,1.87,17.47],[1,1.01,10.52],[2,1.01,0]],"batl":[[0,2.52,270.1],[1,2.52,0]],"ltp":0.0,"tv":0.0,"id":8174357},{"batb":[[0,1.94,15.58]],"batl":[[0,2.7,245.56],[1,2.7,0]],"ltp":0.0,"tv":0.0,"id":7412952}]}]}
{"op":"mcm","clk":"1004745011","pt":1580636533898,"mc":[{"id":"1.168209734","rc":[{"batb":[[0,1.94,15.58],[1,1.9,62.81],[2,1.87,476.81]],"batl":[[0,2.1,37.81],[1,2.52,270.1]],"ltp":0.0,"tv":0.0,"id":8174357},{"batb":[[1,1.92,45.37],[2,1.9,16.44]],"batl":[[0,2.12,36.97],[1,2.7,245.56]],"ltp":0.0,"tv":0.0,"id":7412952}]}]}
{"op":"mcm","clk":"1004745058","pt":1580636534474,"mc":[{"id":"1.168209734","rc":[{"batb":[[2,1.01,10.52]],"ltp":0.0,"tv":0.0,"id":8174357}]}]}
{"op":"mcm","clk":"1004745549","pt":1580636540680,"mc":[{"id":"1.168209734","rc":[{"batb":[[0,1.9,16.6],[1,1.01,10.52],[2,1.01,0]],"batl":[[0,2.52,270.1],[1,2.52,0]],"ltp":0.0,"tv":0.0,"id":8174357},{"batb":[[0,1.9,16.44],[1,1.01,10.52],[2,1.9,0]],"batl":[[0,2.7,245.56],[1,2.7,0]],"ltp":0.0,"tv":0.0,"id":7412952}]}]}
{"op":"mcm","clk":"1004745953","pt":1580636547910,"mc":[{"id":"1.168209734","rc":[{"batb":[[0,1.97,29.58],[1,1.93,15.82],[2,1.92,45.37]],"batl":[[0,2.14,36.13],[1,2.52,270.1]],"ltp":0.0,"tv":0.0,"id":8174357},{"batb":[[0,1.9,62.66],[1,1.88,17],[2,1.01,10.52]],"batl":[[0,2.1,37.81],[1,2.7,245.56]],"ltp":0.0,"tv":0.0,"id":7412952}]}]}
{"op":"mcm","clk":"1004746555","pt":1580636560842,"mc":[{"id":"1.168209734","rc":[{"batb":[[0,1.93,15.82],[1,1.01,10.52],[2,1.92,0]],"batl":[[0,2.52,270.1],[1,2.52,0]],"ltp":0.0,"tv":0.0,"id":8174357},{"batb":[[0,1.88,17],[1,1.01,10.52],[2,1.01,0]],"batl":[[0,2.7,245.56],[1,2.7,0]],"ltp":0.0,"tv":0.0,"id":7412952}]}]}
{"op":"mcm","clk":"1004747399","pt":1580636577550,"mc":[{"id":"1.168209734","rc":[{"batb":[[0,1.97,42.85],[1,1.93,15.82],[2,1.01,10.52]],"batl":[[0,2.18,35.29],[1,2.52,270.1]],"ltp":0.0,"tv":0.0,"id":8174357},{"batb":[[1,1.85,48.73],[2,1.01,10.52]],"batl":[[0,2.04,40.33]],"ltp":0.0,"tv":0.0,"id":7412952}]}]}
{"op":"mcm","clk":"1004747437","pt":1580636578268,"mc":[{"id":"1.168209734","rc":[{"batb":[[0,1.99,28.56],[1,1.97,42.85],[2,1.96,30.06]],"ltp":0.0,"tv":0.0,"id":8174357},{"batb":[[2,1.83,18.57]],"ltp":0.0,"tv":0.0,"id":7412952}]}]}
{"op":"mcm","clk":"1004747584","pt":1580636581265,"mc":[{"id":"1.168209734","rc":[{"batl":[[1,2.52,270.1]],"ltp":0.0,"tv":0.0,"id":7412952}]}]}
{"op":"mcm","clk":"1004749109","pt":1580636609830,"mc":[{"id":"1.168209734","rc":[{"batb":[[0,1.97,42.85],[1,1.96,30.06],[2,1.01,10.52]],"ltp":0.0,"tv":0.0,"id":8174357},{"batb":[[0,1.85,48.73],[1,1.83,18.57],[2,1.01,10.52]],"ltp":0.0,"tv":0.0,"id":7412952}]}]}
{"op":"mcm","clk":"1004749160","pt":1580636610812,"mc":[{"id":"1.168209734","rc":[{"batb":[[0,1.96,30.06],[1,1.01,10.52],[2,1.01,0]],"batl":[[0,2.52,270.1],[1,2.52,0]],"ltp":0.0,"tv":0.0,"id":8174357},{"batb":[[0,1.83,18.57],[1,1.01,10.52],[2,1.01,0]],"batl":[[0,2.52,270.1],[1,2.52,0]],"ltp":0.0,"tv":0.0,"id":7412952}]}]}
{"op":"mcm","clk":"1004749257","pt":1580636612914,"mc":[{"id":"1.168209734","rc":[{"batb":[[0,1.95,30.29]],"ltp":0.0,"tv":0.0,"id":8174357},{"batb":[[0,1.84,18.41]],"ltp":0.0,"tv":0.0,"id":7412952}]}]}
{"op":"mcm","clk":"1004750322","pt":1580636638576,"mc":[{"id":"1.168209734","rc":[{"batb":[[1,1.92,15.97],[2,1.01,10.52]],"ltp":0.0,"tv":0.0,"id":8174357},{"batb":[[0,1.92,16.05],[1,1.87,17.31],[2,1.01,10.52]],"ltp":0.0,"tv":0.0,"id":7412952}]}]}
{"op":"mcm","clk":"1004750365","pt":1580636639651,"mc":[{"id":"1.168209734","rc":[{"batb":[[1,1.94,44.53],[2,1.92,15.97]],"batl":[[0,2.16,36.13],[1,2.52,270.1]],"ltp":0.0,"tv":0.0,"id":8174357},{"batb":[[1,1.88,47.05],[2,1.87,17.31]],"batl":[[0,2.08,38.65],[1,2.52,270.1]],"ltp":0.0,"tv":0.0,"id":7412952}]}]}
{"op":"mcm","clk":"1004751084","pt":1580636658607,"mc":[{"id":"1.168209734","rc":[{"batb":[[1,1.92,15.97],[2,1.01,10.52]],"batl":[[0,2.52,270.1],[1,2.52,0]],"ltp":0.0,"tv":0.0,"id":8174357},{"batb":[[1,1.87,17.31],[2,1.01,10.52]],"batl":[[0,2.52,270.1],[1,2.52,0]],"ltp":0.0,"tv":0.0,"id":7412952}]}]}
{"op":"mcm","clk":"1004751112","pt":1580636659171,"mc":[{"id":"1.168209734","rc":[{"batb":[[0,1.01,10.52],[1,1.92,0],[2,1.01,0]],"ltp":0.0,"tv":0.0,"id":8174357},{"batb":[[0,1.01,10.52],[1,1.87,0],[2,1.01,0]],"ltp":0.0,"tv":0.0,"id":7412952}]}]}
{"op":"mcm","clk":"1004761512","pt":1580636883928,"mc":[{"id":"1.168209734","rc":[{"batb":[[0,1.81,51.25],[1,1.01,10.52]],"batl":[[0,2,42.01]],"ltp":0.0,"tv":0.0,"id":8174357},{"batb":[[0,1.99,42.01],[1,1.01,10.52]],"batl":[[0,2.24,33.61]],"ltp":0.0,"tv":0.0,"id":7412952}]}]}
{"op":"mcm","clk":"1004761627","pt":1580636886604,"mc":[{"id":"1.168209734","rc":[{"batb":[[0,1.01,10.52],[1,1.01,0]],"ltp":0.0,"tv":0.0,"id":7412952}]}]}
{"op":"mcm","clk":"1004761780","pt":1580636889829,"mc":[{"id":"1.168209734","rc":[{"batb":[[0,2,42.01],[1,1.01,10.52]],"ltp":0.0,"tv":0.0,"id":7412952}]}]}
{"op":"mcm","clk":"1004762451","pt":1580636902946,"mc":[{"id":"1.168209734","rc":[{"batb":[[0,1.01,10.52],[1,1.01,0]],"ltp":0.0,"tv":0.0,"id":8174357},{"batb":[[0,1.01,10.52],[1,1.01,0]],"ltp":0.0,"tv":0.0,"id":7412952}]}]}
{"op":"mcm","clk":"1004763454","pt":1580636922892,"mc":[{"id":"1.168209734","rc":[{"batl":[[0,2.02,41.17],[1,2.52,270.1]],"ltp":0.0,"tv":0.0,"id":8174357},{"batb":[[0,1.98,42.85],[1,1.01,10.52]],"batl":[[0,2.22,33.61],[1,2.7,245.56]],"ltp":0.0,"tv":0.0,"id":7412952}]}]}
{"op":"mcm","clk":"1004763543","pt":1580636924280,"mc":[{"id":"1.168209734","rc":[{"batb":[[0,1.82,50.41],[1,1.01,10.52]],"ltp":0.0,"tv":0.0,"id":8174357}]}]}
{"op":"mcm","clk":"1004763701","pt":1580636927375,"mc":[{"id":"1.168209734","rc":[{"batl":[[0,2.2,416.88],[1,2.22,33.61],[2,2.7,245.56]],"ltp":0.0,"tv":0.0,"id":7412952}]}]}
{"op":"mcm","clk":"1004764100","pt":1580636934904,"mc":[{"id":"1.168209734","rc":[{"batb":[[0,1.01,10.52],[1,1.01,0]],"batl":[[0,2.52,270.1],[1,2.52,0]],"ltp":0.0,"tv":0.0,"id":8174357},{"batb":[[0,1.01,10.52],[1,1.01,0]],"batl":[[0,2.7,245.56],[1,2.22,0],[2,2.7,0]],"ltp":0.0,"tv":0.0,"id":7412952}]}]}
{"op":"mcm","clk":"1004764598","pt":1580636943890,"mc":[{"id":"1.168209734","rc":[{"batb":[[0,1.83,50.41],[1,1.01,10.52]],"batl":[[0,2.04,40.33],[1,2.52,270.1]],"ltp":0.0,"tv":0.0,"id":8174357},{"batb":[[0,1.96,43.69],[1,1.01,10.52]],"batl":[[0,2.2,34.45],[1,2.7,245.56]],"ltp":0.0,"tv":0.0,"id":7412952}]}]}
{"op":"mcm","clk":"1004765290","pt":1580636955247,"mc":[{"id":"1.168209734","rc":[{"batb":[[0,1.01,10.52],[1,1.01,0]],"batl":[[0,2.52,270.1],[1,2.52,0]],"ltp":0.0,"tv":0.0,"id":8174357},{"batb":[[0,1.01,10.52],[1,1.01,0]],"batl":[[0,2.7,245.56],[1,2.7,0]],"ltp":0.0,"tv":0.0,"id":7412952}]}]}
{"op":"mcm","clk":"1004765636","pt":1580636961919,"mc":[{"id":"1.168209734","rc":[{"batb":[[0,1.87,47.89],[1,1.01,10.52]],"batl":[[0,2.08,38.65],[1,2.52,270.1]],"ltp":0.0,"tv":0.0,"id":8174357},{"batb":[[0,1.91,45.37],[1,1.01,10.52]],"batl":[[0,2.14,36.13],[1,2.7,245.56]],"ltp":0.0,"tv":0.0,"id":7412952}]}]}
{"op":"mcm","clk":"1004767318","pt":1580636990998,"mc":[{"id":"1.168209734","rc":[{"batb":[[0,1.01,10.52],[1,1.01,0]],"batl":[[0,2.52,270.1],[1,2.52,0]],"ltp":0.0,"tv":0.0,"id":8174357},{"batb":[[0,1.01,10.52],[1,1.01,0]],"batl":[[0,2.7,245.56],[1,2.7,0]],"ltp":0.0,"tv":0.0,"id":7412952}]}]}
{"op":"mcm","clk":"1004767708","pt":1580636997919,"mc":[{"id":"1.168209734","rc":[{"batb":[[0,1.85,48.73],[1,1.01,10.52]],"batl":[[0,2.06,39.49],[1,2.52,270.1]],"ltp":0.0,"tv":0.0,"id":8174357},{"batb":[[0,1.94,44.53],[1,1.01,10.52]],"batl":[[0,2.18,35.29],[1,2.7,245.56]],"ltp":0.0,"tv":0.0,"id":7412952}]}]}
{"op":"mcm","clk":"1004768566","pt":1580637011488,"mc":[{"id":"1.168209734","rc":[{"batb":[[0,1.01,10.52],[1,1.01,0]],"batl":[[0,2.52,270.1],[1,2.52,0]],"ltp":0.0,"tv":0.0,"id":8174357},{"batb":[[0,1.01,10.52],[1,1.01,0]],"batl":[[0,2.7,245.56],[1,2.7,0]],"ltp":0.0,"tv":0.0,"id":7412952}]}]}
{"op":"mcm","clk":"1004768849","pt":1580637015941,"mc":[{"id":"1.168209734","rc":[{"batb":[[0,1.83,50.41],[1,1.01,10.52]],"batl":[[0,2.04,40.33],[1,2.52,270.1]],"ltp":0.0,"tv":0.0,"id":8174357},{"batb":[[0,1.96,43.69],[1,1.01,10.52]],"batl":[[0,2.2,34.45],[1,2.7,245.56]],"ltp":0.0,"tv":0.0,"id":7412952}]}]}
{"op":"mcm","clk":"1004769548","pt":1580637029232,"mc":[{"id":"1.168209734","rc":[{"batb":[[0,1.01,10.52],[1,1.01,0]],"batl":[[0,2.52,270.1],[1,2.52,0]],"ltp":0.0,"tv":0.0,"id":8174357},{"batb":[[0,1.01,10.52],[1,1.01,0]],"batl":[[0,2.7,245.56],[1,2.7,0]],"ltp":0.0,"tv":0.0,"id":7412952}]}]}
{"op":"mcm","clk":"1004771073","pt":1580637053890,"mc":[{"id":"1.168209734","rc":[{"batl":[[0,2.48,162.99],[1,2.7,245.56]],"ltp":0.0,"tv":0.0,"id":7412952}]}]}
{"op":"mcm","clk":"1004771088","pt":1580637054301,"mc":[{"id":"1.168209734","rc":[{"batb":[[0,1.87,47.89],[1,1.01,10.52]],"batl":[[0,2.08,38.65],[1,2.52,270.1]],"ltp":0.0,"tv":0.0,"id":8174357},{"batb":[[0,1.92,45.37],[1,1.01,10.52]],"batl":[[0,2.14,36.13]],"ltp":0.0,"tv":0.0,"id":7412952}]}]}
{"op":"mcm","clk":"1004771218","pt":1580637057407,"mc":[{"id":"1.168209734","rc":[{"batl":[[0,2.14,224.88]],"ltp":0.0,"tv":0.0,"id":7412952}]}]}
{"op":"mcm","clk":"1004771744","pt":1580637068511,"mc":[{"id":"1.168209734","rc":[{"batl":[[0,2.14,36.13]],"ltp":0.0,"tv":0.0,"id":7412952}]}]}
{"op":"mcm","clk":"1004771771","pt":1580637069123,"mc":[{"id":"1.168209734","rc":[{"batb":[[0,1.01,10.52],[1,1.01,0]],"batl":[[0,2.52,270.1],[1,2.52,0]],"ltp":0.0,"tv":0.0,"id":8174357},{"batb":[[0,1.01,10.52],[1,1.01,0]],"batl":[[0,2.7,245.56],[1,2.7,0]],"ltp":0.0,"tv":0.0,"id":7412952}]}]}
{"op":"mcm","clk":"1004772256","pt":1580637078638,"mc":[{"id":"1.168209734","rc":[{"batl":[[0,2.04,40.33],[1,2.52,270.1]],"ltp":0.0,"tv":0.0,"id":8174357},{"batb":[[0,1.96,43.69],[1,1.01,10.52]],"ltp":0.0,"tv":0.0,"id":7412952}]}]}
{"op":"mcm","clk":"1004772313","pt":1580637079722,"mc":[{"id":"1.168209734","rc":[{"batb":[[0,1.85,48.73],[1,1.01,10.52]],"ltp":0.0,"tv":0.0,"id":8174357},{"batl":[[0,2.18,35.29]],"ltp":0.0,"tv":0.0,"id":7412952}]}]}
{"op":"mcm","clk":"1004772449","pt":1580637082939,"mc":[{"id":"1.168209734","rc":[{"batl":[[1,2.6,15.66]],"ltp":0.0,"tv":0.0,"id":7412952}]}]}
{"op":"mcm","clk":"1004772971","pt":1580637095059,"mc":[{"id":"1.168209734","rc":[{"batb":[[0,1.01,10.52],[1,1.01,0]],"batl":[[0,2.52,270.1],[1,2.52,0]],"ltp":0.0,"tv":0.0,"id":8174357},{"batb":[[0,1.01,10.52],[1,1.01,0]],"batl":[[0,2.6,15.66],[1,2.6,0]],"ltp":0.0,"tv":0.0,"id":7412952}]}]}
{"op":"mcm","clk":"1004774505","pt":1580637125105,"mc":[{"id":"1.168209734","rc":[{"batl":[[0,2.6,6.65]],"ltp":0.0,"tv":0.0,"id":7412952}]}]}
{"op":"mcm","clk":"1004774686","pt":1580637128295,"mc":[{"id":"1.168209734","rc":[{"batb":[[0,1.82,50.41],[1,1.01,10.52]],"batl":[[0,2.02,41.17],[1,2.52,270.1]],"ltp":0.0,"tv":0.0,"id":8174357},{"batb":[[0,1.98,42.85],[1,1.01,10.52]],"batl":[[0,2.22,33.61],[1,2.6,6.65]],"ltp":0.0,"tv":0.0,"id":7412952}]}]}
{"op":"mcm","clk":"1004779285","pt":1580637211236,"mc":[{"id":"1.168209734","rc":[{"batb":[[0,1.01,10.52],[1,1.01,0]],"batl":[[0,2.52,270.1],[1,2.52,0]],"ltp":0.0,"tv":0.0,"id":8174357},{"batb":[[0,1.01,10.52],[1,1.01,0]],"batl":[[0,2.6,6.65],[1,2.6,0]],"ltp":0.0,"tv":0.0,"id":7412952}]}]}
{"op":"mcm","clk":"1004780096","pt":1580637228688,"mc":[{"id":"1.168209734","rc":[{"batl":[[0,2.04,40.33],[1,2.52,270.1]],"ltp":0.0,"tv":0.0,"id":8174357},{"batb":[[0,1.96,43.69],[1,1.01,10.52]],"ltp":0.0,"tv":0.0,"id":7412952}]}]}
{"op":"mcm","clk":"1004780205","pt":1580637230696,"mc":[{"id":"1.168209734","rc":[{"batb":[[0,1.84,49.57],[1,1.01,10.52]],"ltp":0.0,"tv":0.0,"id":8174357},{"batl":[[0,2.18,35.29],[1,2.6,6.65]],"ltp":0.0,"tv":0.0,"id":7412952}]}]}
{"op":"mcm","clk":"1004780252","pt":1580637231675,"mc":[{"id":"1.168209734","rc":[{"batl":[[0,2.18,220.54]],"ltp":0.0,"tv":0.0,"id":7412952}]}]}
{"op":"mcm","clk":"1004780828","pt":1580637242737,"mc":[{"id":"1.168209734","rc":[{"batl":[[0,2.18,35.29]],"ltp":0.0,"tv":0.0,"id":7412952}]}]}
{"op":"mcm","clk":"1004780851","pt":1580637243309,"mc":[{"id":"1.168209734","rc":[{"batb":[[0,1.01,10.52],[1,1.01,0]],"batl":[[0,2.52,270.1],[1,2.52,0]],"ltp":0.0,"tv":0.0,"id":8174357},{"batb":[[0,1.01,10.52],[1,1.01,0]],"batl":[[0,2.6,6.65],[1,2.6,0]],"ltp":0.0,"tv":0.0,"id":7412952}]}]}
{"op":"mcm","clk":"1004781383","pt":1580637254235,"mc":[{"id":"1.168209734","rc":[{"batb":[[0,1.8,52.09],[1,1.01,10.52]],"batl":[[0,2,42.01],[1,2.52,270.1]],"ltp":0.0,"tv":0.0,"id":8174357},{"batb":[[0,1.99,42.01],[1,1.01,10.52]],"batl":[[0,2.24,33.61],[1,2.6,6.65]],"ltp":0.0,"tv":0.0,"id":7412952}]}]}
{"op":"mcm","clk":"1004782231","pt":1580637271536,"mc":[{"id":"1.168209734","rc":[{"batb":[[0,1.01,10.52],[1,1.01,0]],"batl":[[0,2.52,270.1],[1,2.52,0]],"ltp":0.0,"tv":0.0,"id":8174357},{"batb":[[0,1.01,10.52],[1,1.01,0]],"batl":[[0,2.6,6.65],[1,2.6,0]],"ltp":0.0,"tv":0.0,"id":7412952}]}]}
{"op":"mcm","clk":"1004783105","pt":1580637288689,"mc":[{"id":"1.168209734","rc":[{"batb":[[0,1.82,50.41],[1,1.01,10.52]],"batl":[[0,2.02,41.17],[1,2.52,270.1]],"ltp":0.0,"tv":0.0,"id":8174357},{"batb":[[0,1.97,42.85],[1,1.01,10.52]],"batl":[[0,2.22,33.61],[1,2.6,6.65]],"ltp":0.0,"tv":0.0,"id":7412952}]}]}
{"op":"mcm","clk":"1004783256","pt":1580637291775,"mc":[{"id":"1.168209734","rc":[{"batb":[[0,1.83,492.03],[1,1.82,50.41],[2,1.01,10.52]],"ltp":0.0,"tv":0.0,"id":8174357}]}]}
{"op":"mcm","clk":"1004783710","pt":1580637301595,"mc":[{"id":"1.168209734","rc":[{"batb":[[0,1.82,50.41],[1,1.01,10.52],[2,1.01,0]],"ltp":0.0,"tv":0.0,"id":8174357}]}]}
{"op":"mcm","clk":"1004783796","pt":1580637303307,"mc":[{"id":"1.168209734","rc":[{"batb":[[0,1.01,10.52],[1,1.01,0]],"batl":[[0,2.52,270.1],[1,2.52,0]],"ltp":0.0,"tv":0.0,"id":8174357},{"batb":[[0,1.01,10.52],[1,1.01,0]],"batl":[[0,2.6,6.65],[1,2.6,0]],"ltp":0.0,"tv":0.0,"id":7412952}]}]}
{"op":"mcm","clk":"1004784122","pt":1580637310211,"mc":[{"id":"1.168209734","rc":[{"batb":[[0,1.84,49.57],[1,1.01,10.52]],"batl":[[0,2.06,39.49],[1,2.52,270.1]],"ltp":0.0,"tv":0.0,"id":8174357},{"batb":[[0,1.94,44.53],[1,1.01,10.52]],"batl":[[0,2.18,35.29],[1,2.6,6.65]],"ltp":0.0,"tv":0.0,"id":7412952}]}]}
{"op":"mcm","clk":"1004784573","pt":1580637319359,"mc":[{"id":"1.168209734","rc":[{"batb":[[0,1.01,10.52],[1,1.01,0]],"batl":[[0,2.52,270.1],[1,2.52,0]],"ltp":0.0,"tv":0.0,"id":8174357},{"batb":[[0,1.01,10.52],[1,1.01,0]],"batl":[[0,2.6,6.65],[1,2.6,0]],"ltp":0.0,"tv":0.0,"id":7412952}]}]}
{"op":"mcm","clk":"1004784844","pt":1580637324780,"mc":[{"id":"1.168209734","rc":[{"batb":[[0,1.88,47.05],[1,1.01,10.52]],"batl":[[0,2.1,37.81],[1,2.52,270.1]],"ltp":0.0,"tv":0.0,"id":8174357},{"batb":[[0,1.91,45.37],[1,1.01,10.52]],"batl":[[0,2.12,36.97],[1,2.6,6.65]],"ltp":0.0,"tv":0.0,"id":7412952}]}]}
{"op":"mcm","clk":"1004786403","pt":1580637359744,"mc":[{"id":"1.168209734","rc":[{"batb":[[0,1.01,10.52],[1,1.01,0]],"batl":[[0,2.52,270.1],[1,2.52,0]],"ltp":0.0,"tv":0.0,"id":8174357},{"batb":[[0,1.01,10.52],[1,1.01,0]],"batl":[[0,2.6,6.65],[1,2.6,0]],"ltp":0.0,"tv":0.0,"id":7412952}]}]}
{"op":"mcm","clk":"1004787409","pt":1580637377131,"mc":[{"id":"1.168209734","rc":[{"batl":[[0,2.2,191.25]],"ltp":0.0,"tv":0.0,"id":7412952}]}]}
{"op":"mcm","clk":"1004787486","pt":1580637378472,"mc":[{"id":"1.168209734","rc":[{"batb":[[0,1.92,45.37],[1,1.01,10.52]],"batl":[[0,2.14,36.13]],"ltp":0.0,"tv":0.0,"id":8174357},{"batb":[[0,1.87,47.89],[1,1.01,10.52]],"batl":[[0,2.08,38.65]],"ltp":0.0,"tv":0.0,"id":7412952}]}]}
{"op":"mcm","clk":"1004787562","pt":1580637379657,"mc":[{"id":"1.168209734","rc":[{"batl":[[1,2.84,463.76]],"ltp":0.0,"tv":0.0,"id":8174357},{"batl":[[1,2.4,24.05]],"ltp":0.0,"tv":0.0,"id":7412952}]}]}
{"op":"mcm","clk":"1004787775","pt":1580637381528,"mc":[{"id":"1.168209734","rc":[{"batl":[[0,2.08,240.59]],"ltp":0.0,"tv":0.0,"id":7412952}]}]}
{"op":"mcm","clk":"1004788178","pt":1580637388873,"mc":[{"id":"1.168209734","rc":[{"batl":[[0,2.08,38.65]],"ltp":0.0,"tv":0.0,"id":7412952}]}]}
{"op":"mcm","clk":"1004788204","pt":1580637389287,"mc":[{"id":"1.168209734","rc":[{"batb":[[0,1.01,10.52],[1,1.01,0]],"batl":[[0,2.84,463.76],[1,2.84,0]],"ltp":0.0,"tv":0.0,"id":8174357},{"batb":[[0,1.01,10.52],[1,1.01,0]],"batl":[[0,2.4,24.05],[1,2.4,0]],"ltp":0.0,"tv":0.0,"id":7412952}]}]}
{"op":"mcm","clk":"1004789100","pt":1580637400297,"mc":[{"id":"1.168209734","rc":[{"batb":[[0,1.96,43.69],[1,1.01,10.52]],"batl":[[0,2.2,34.45],[1,2.84,463.76]],"ltp":0.0,"tv":0.0,"id":8174357},{"batb":[[0,1.83,50.41],[1,1.01,10.52]],"batl":[[0,2.04,40.33],[1,2.4,24.05]],"ltp":0.0,"tv":0.0,"id":7412952}]}]}
{"op":"mcm","clk":"1004789371","pt":1580637403608,"mc":[{"id":"1.168209734","rc":[{"batl":[[0,2.02,440.96],[1,2.04,40.33],[2,2.4,24.05]],"ltp":0.0,"tv":0.0,"id":7412952}]}]}
{"op":"mcm","clk":"1004789972","pt":1580637414912,"mc":[{"id":"1.168209734","rc":[{"batl":[[0,2.04,40.33],[1,2.4,24.05],[2,2.4,0]],"ltp":0.0,"tv":0.0,"id":7412952}]}]}
{"op":"mcm","clk":"1004790041","pt":1580637415792,"mc":[{"id":"1.168209734","rc":[{"batb":[[0,1.01,10.52],[1,1.01,0]],"batl":[[0,2.84,463.76],[1,2.84,0]],"ltp":0.0,"tv":0.0,"id":8174357},{"batb":[[0,1.01,10.52],[1,1.01,0]],"batl":[[0,2.4,24.05],[1,2.4,0]],"ltp":0.0,"tv":0.0,"id":7412952}]}]}
{"op":"mcm","clk":"1004791894","pt":1580637442922,"mc":[{"id":"1.168209734","rc":[{"batb":[[0,2,42.01],[1,1.01,10.52]],"batl":[[0,2.24,33.61],[1,2.84,463.76]],"ltp":0.0,"tv":0.0,"id":8174357},{"batb":[[0,1.8,52.09],[1,1.01,10.52]],"batl":[[0,2,42.01],[1,2.3,132.95]],"ltp":0.0,"tv":0.0,"id":7412952}]}]}
{"op":"mcm","clk":"1004791938","pt":1580637443942,"mc":[{"id":"1.168209734","rc":[{"batl":[[1,2.3,0]],"ltp":0.0,"tv":0.0,"id":7412952}]}]}
{"op":"mcm","clk":"1004792014","pt":1580637445448,"mc":[{"id":"1.168209734","rc":[{"batl":[[1,2.84,0]],"ltp":0.0,"tv":0.0,"id":8174357}]}]}
{"op":"mcm","clk":"1004792074","pt":1580637446533,"mc":[{"id":"1.168209734","rc":[{"batl":[[0,1.98,154.25],[1,2,42.01],[2,2.3,58.4]],"ltp":0.0,"tv":0.0,"id":7412952}]}]}
{"op":"mcm","clk":"1004792232","pt":1580637449226,"mc":[{"id":"1.168209734","rc":[{"batl":[[1,3,213.76]],"ltp":0.0,"tv":0.0,"id":8174357}]}]}
{"op":"mcm","clk":"1004792693","pt":1580637456942,"mc":[{"id":"1.168209734","rc":[{"batb":[[0,1.01,10.52],[1,1.01,0]],"ltp":0.0,"tv":0.0,"id":8174357},{"batl":[[1,2.3,58.4],[2,2.3,0]],"ltp":0.0,"tv":0.0,"id":7412952}]}]}
{"op":"mcm","clk":"1004792822","pt":1580637459766,"mc":[{"id":"1.168209734","rc":[{"batb":[[0,2.02,41.17],[1,1.01,10.52]],"ltp":0.0,"tv":0.0,"id":8174357},{"batl":[[1,1.99,42.01],[2,2.3,58.4]],"ltp":0.0,"tv":0.0,"id":7412952}]}]}
{"op":"mcm","clk":"1004792882","pt":1580637460953,"mc":[{"id":"1.168209734","rc":[{"batl":[[0,1.99,42.01],[1,2.3,58.4],[2,2.3,0]],"ltp":0.0,"tv":0.0,"id":7412952}]}]}
{"op":"mcm","clk":"1004792917","pt":1580637461576,"mc":[{"id":"1.168209734","rc":[{"batb":[[0,1.01,10.52],[1,1.01,0]],"batl":[[0,3,213.76],[1,3,0]],"ltp":0.0,"tv":0.0,"id":8174357},{"batb":[[0,1.01,10.52],[1,1.01,0]],"batl":[[0,2.3,58.4],[1,2.3,0]],"ltp":0.0,"tv":0.0,"id":7412952}]}]}
{"op":"mcm","clk":"1004793935","pt":1580637480619,"mc":[{"id":"1.168209734","rc":[{"batb":[[0,1.98,42.85],[1,1.01,10.52]],"batl":[[0,2.24,33.61],[1,3,213.76]],"ltp":0.0,"tv":0.0,"id":8174357},{"batb":[[0,1.81,51.25],[1,1.01,10.52]],"batl":[[0,2.02,41.17]],"ltp":0.0,"tv":0.0,"id":7412952}]}]}
{"op":"mcm","clk":"1004793999","pt":1580637481600,"mc":[{"id":"1.168209734","rc":[{"batl":[[1,2.3,384.29]],"ltp":0.0,"tv":0.0,"id":7412952}]}]}
{"op":"mcm","clk":"1004795117","pt":1580637501625,"mc":[{"id":"1.168209734","rc":[{"batb":[[0,1.01,10.52],[1,1.01,0]],"batl":[[0,3,213.76],[1,3,0]],"ltp":0.0,"tv":0.0,"id":8174357},{"batb":[[0,1.01,10.52],[1,1.01,0]],"ltp":0.0,"tv":0.0,"id":7412952}]}]}
{"op":"mcm","clk":"1004795417","pt":1580637507857,"mc":[{"id":"1.168209734","rc":[{"batl":[[0,2.3,375.75]],"ltp":0.0,"tv":0.0,"id":7412952}]}]}
{"op":"mcm","clk":"1004796324","pt":1580637524864,"mc":[{"id":"1.168209734","rc":[{"batl":[[0,2.4,29.41],[1,3,213.76]],"ltp":0.0,"tv":0.0,"id":8174357},{"batb":[[0,1.71,58.81],[1,1.01,10.52]],"batl":[[0,1.89,42.01]],"ltp":0.0,"tv":0.0,"id":7412952}]}]}
{"op":"mcm","clk":"1004796379","pt":1580637525946,"mc":[{"id":"1.168209734","rc":[{"batl":[[1,2.3,350.71]],"ltp":0.0,"tv":0.0,"id":7412952}]}]}
{"op":"mcm","clk":"1004796425","pt":1580637526874,"mc":[{"id":"1.168209734","rc":[{"batb":[[0,2.14,36.13],[1,1.01,10.52]],"ltp":0.0,"tv":0.0,"id":8174357}]}]}
{"op":"mcm","clk":"1004796475","pt":1580637527851,"mc":[{"id":"1.168209734","rc":[{"batl":[[0,1.88,512.29],[1,1.89,42.01],[2,2.3,350.71]],"ltp":0.0,"tv":0.0,"id":7412952}]}]}
{"op":"mcm","clk":"1004801728","pt":1580637610302,"mc":[{"id":"1.168209734","rc":[{"batl":[[0,1.89,42.01],[1,2.3,350.71],[2,2.3,0]],"ltp":0.0,"tv":0.0,"id":7412952}]}]}
{"op":"mcm","clk":"1004801807","pt":1580637611401,"mc":[{"id":"1.168209734","rc":[{"batb":[[0,1.01,10.52],[1,1.01,0]],"batl":[[0,3,213.76],[1,3,0]],"ltp":0.0,"tv":0.0,"id":8174357},{"batb":[[0,1.01,10.52],[1,1.01,0]],"batl":[[0,2.3,350.71],[1,2.3,0]],"ltp":0.0,"tv":0.0,"id":7412952}]}]}
{"op":"mcm","clk":"1004803629","pt":1580637637837,"mc":[{"id":"1.168209734","rc":[{"batl":[[0,2.14,188.75],[1,2.3,350.71]],"ltp":0.0,"tv":0.0,"id":7412952}]}]}
{"op":"mcm","clk":"1004803690","pt":1580637638769,"mc":[{"id":"1.168209734","rc":[{"batb":[[0,2.16,36.13],[1,1.01,10.52]],"batl":[[0,2.44,28.57],[1,3,213.76]],"ltp":0.0,"tv":0.0,"id":8174357},{"batb":[[0,1.69,60.49],[1,1.01,10.52]],"batl":[[0,1.87,42.01]],"ltp":0.0,"tv":0.0,"id":7412952}]}]}
{"op":"mcm","clk":"1004803891","pt":1580637641867,"mc":[{"id":"1.168209734","rc":[{"batb":[[0,2.18,184.97],[1,2.16,36.13],[2,1.01,10.52]],"ltp":0.0,"tv":0.0,"id":8174357}]}]}
{"op":"mcm","clk":"1004804917","pt":1580637655581,"mc":[{"id":"1.168209734","rc":[{"batb":[[0,1.01,10.52],[1,2.16,0],[2,1.01,0]],"batl":[[0,3,213.76],[1,3,0]],"ltp":0.0,"tv":0.0,"id":8174357},{"batb":[[0,1.01,10.52],[1,1.01,0]],"batl":[[0,2.3,350.71],[1,2.3,0]],"ltp":0.0,"tv":0.0,"id":7412952}]}]}
{"op":"mcm","clk":"1004805553","pt":1580637664514,"mc":[{"id":"1.168209734","rc":[{"batb":[[0,2.18,35.29],[1,1.01,10.52]],"batl":[[0,2.48,27.73],[1,3,213.76]],"ltp":0.0,"tv":0.0,"id":8174357},{"batb":[[0,1.68,61.33],[1,1.01,10.52]],"batl":[[0,1.85,42.01],[1,2.3,350.71]],"ltp":0.0,"tv":0.0,"id":7412952}]}]}
{"op":"mcm","clk":"1004806343","pt":1580637675628,"mc":[{"id":"1.168209734","rc":[{"batb":[[0,1.01,10.52],[1,1.01,0]],"batl":[[0,3,213.76],[1,3,0]],"ltp":0.0,"tv":0.0,"id":8174357},{"batb":[[0,1.01,10.52],[1,1.01,0]],"batl":[[0,2.3,350.71],[1,2.3,0]],"ltp":0.0,"tv":0.0,"id":7412952}]}]}
{"op":"mcm","clk":"1004807144","pt":1580637686564,"mc":[{"id":"1.168209734","rc":[{"batb":[[0,2.14,36.13],[1,1.01,10.52]],"batl":[[0,2.42,29.41],[1,3,213.76]],"ltp":0.0,"tv":0.0,"id":8174357},{"batb":[[0,1.7,59.65],[1,1.01,10.52]],"batl":[[0,1.88,42.01],[1,2.3,350.71]],"ltp":0.0,"tv":0.0,"id":7412952}]}]}
{"op":"mcm","clk":"1004808224","pt":1580637701590,"mc":[{"id":"1.168209734","rc":[{"batb":[[0,1.01,10.52],[1,1.01,0]],"batl":[[0,3,213.76],[1,3,0]],"ltp":0.0,"tv":0.0,"id":8174357},{"batb":[[0,1.01,10.52],[1,1.01,0]],"batl":[[0,2.3,350.71],[1,2.3,0]],"ltp":0.0,"tv":0.0,"id":7412952}]}]}
{"op":"mcm","clk":"1004809471","pt":1580637717004,"mc":[{"id":"1.168209734","rc":[{"batl":[[0,1.91,131.72],[1,2.3,350.71]],"ltp":0.0,"tv":0.0,"id":7412952}]}]}
{"op":"mcm","clk":"1004809589","pt":1580637718712,"mc":[{"id":"1.168209734","rc":[{"batb":[[0,2.16,36.13],[1,1.01,10.52]],"batl":[[0,2.44,28.57],[1,3,213.76]],"ltp":0.0,"tv":0.0,"id":8174357},{"batb":[[0,1.69,60.49],[1,1.01,10.52]],"batl":[[0,1.86,42.01]],"ltp":0.0,"tv":0.0,"id":7412952}]}]}
{"op":"mcm","clk":"1004809894","pt":1580637721921,"mc":[{"id":"1.168209734","rc":[{"batl":[[0,1.85,136.1],[1,1.86,42.01],[2,2.3,350.71]],"ltp":0.0,"tv":0.0,"id":7412952}]}]}
{"op":"mcm","clk":"1004811600","pt":1580637740378,"mc":[{"id":"1.168209734","rc":[{"batl":[[0,1.86,42.01],[1,2.3,350.71],[2,2.3,0]],"ltp":0.0,"tv":0.0,"id":7412952}]}]}
{"op":"mcm","clk":"1004811716","pt":1580637741586,"mc":[{"id":"1.168209734","rc":[{"batb":[[0,1.01,10.52],[1,1.01,0]],"batl":[[0,3,213.76],[1,3,0]],"ltp":0.0,"tv":0.0,"id":8174357},{"batb":[[0,1.01,10.52],[1,1.01,0]],"batl":[[0,2.3,350.71],[1,2.3,0]],"ltp":0.0,"tv":0.0,"id":7412952}]}]}
{"op":"mcm","clk":"1004813350","pt":1580637762914,"mc":[{"id":"1.168209734","rc":[{"batb":[[0,2.2,34.45],[1,1.01,10.52]],"batl":[[0,2.5,27.73],[1,3,213.76]],"ltp":0.0,"tv":0.0,"id":8174357},{"batb":[[0,1.66,63.01],[1,1.01,10.52]],"batl":[[0,1.83,42.01],[1,2.3,350.71]],"ltp":0.0,"tv":0.0,"id":7412952}]}]}
{"op":"mcm","clk":"1004813878","pt":1580637770411,"mc":[{"id":"1.168209734","rc":[{"batl":[[0,1.82,547.75],[1,1.83,42.01],[2,2.3,350.71]],"ltp":0.0,"tv":0.0,"id":7412952}]}]}
{"op":"mcm","clk":"1004815348","pt":1580637791751,"mc":[{"id":"1.168209734","rc":[{"batl":[[0,1.83,42.01],[1,2.3,350.71],[2,2.3,0]],"ltp":0.0,"tv":0.0,"id":7412952}]}]}
{"op":"mcm","clk":"1004815489","pt":1580637793637,"mc":[{"id":"1.168209734","rc":[{"batb":[[0,1.01,10.52],[1,1.01,0]],"batl":[[0,3,213.76],[1,3,0]],"ltp":0.0,"tv":0.0,"id":8174357},{"batb":[[0,1.01,10.52],[1,1.01,0]],"batl":[[0,2.3,350.71],[1,2.3,0]],"ltp":0.0,"tv":0.0,"id":7412952}]}]}
{"op":"mcm","clk":"1004816083","pt":1580637802869,"mc":[{"id":"1.168209734","rc":[{"batb":[[0,2.26,32.77],[1,1.01,10.52]],"batl":[[0,2.58,26.05],[1,3,213.76]],"ltp":0.0,"tv":0.0,"id":8174357},{"batb":[[0,1.64,65.54],[1,1.01,10.52]],"batl":[[0,1.8,42.01]],"ltp":0.0,"tv":0.0,"id":7412952}]}]}
{"op":"mcm","clk":"1004816269","pt":1580637805946,"mc":[{"id":"1.168209734","rc":[{"batb":[[0,2.3,446.28],[1,2.26,32.77],[2,1.01,10.52]],"ltp":0.0,"tv":0.0,"id":8174357},{"batl":[[1,2.16,375.58]],"ltp":0.0,"tv":0.0,"id":7412952}]}]}
{"op":"mcm","clk":"1004817020","pt":1580637815905,"mc":[{"id":"1.168209734","rc":[{"batb":[[0,2.26,32.77],[1,1.01,10.52],[2,1.01,0]],"ltp":0.0,"tv":0.0,"id":8174357}]}]}
{"op":"mcm","clk":"1004817163","pt":1580637817620,"mc":[{"id":"1.168209734","rc":[{"batb":[[0,1.01,10.52],[1,1.01,0]],"batl":[[0,3,213.76],[1,3,0]],"ltp":0.0,"tv":0.0,"id":8174357},{"batb":[[0,1.01,10.52],[1,1.01,0]],"batl":[[0,2.16,375.58],[1,2.16,0]],"ltp":0.0,"tv":0.0,"id":7412952}]}]}
{"op":"mcm","clk":"1004818104","pt":1580637830917,"mc":[{"id":"1.168209734","rc":[{"batb":[[0,2.3,31.93],[1,1.01,10.52]],"batl":[[0,2.62,25.21]],"ltp":0.0,"tv":0.0,"id":8174357},{"batb":[[0,1.61,68.06],[1,1.01,10.52]],"batl":[[0,1.77,42.01],[1,2.16,375.58]],"ltp":0.0,"tv":0.0,"id":7412952}]}]}
{"op":"mcm","clk":"1004818165","pt":1580637831700,"mc":[{"id":"1.168209734","rc":[{"batl":[[1,3.45,231.3]],"ltp":0.0,"tv":0.0,"id":8174357}]}]}
{"op":"mcm","clk":"1004818351","pt":1580637834440,"mc":[{"id":"1.168209734","rc":[{"batb":[[0,2.32,457.14],[1,2.3,31.93],[2,1.01,10.52]],"ltp":0.0,"tv":0.0,"id":8174357}]}]}
{"op":"mcm","clk":"1004819164","pt":1580637847775,"mc":[{"id":"1.168209734","rc":[{"batb":[[0,1.01,10.52],[1,2.3,0],[2,1.01,0]],"batl":[[0,3.45,231.3],[1,3.45,0]],"ltp":0.0,"tv":0.0,"id":8174357},{"batb":[[0,1.01,10.52],[1,1.01,0]],"batl":[[0,2.16,375.58],[1,2.16,0]],"ltp":0.0,"tv":0.0,"id":7412952}]}]}
{"op":"mcm","clk":"1004819710","pt":1580637856955,"mc":[{"id":"1.168209734","rc":[{"batb":[[0,2.28,32.77],[1,1.01,10.52]],"batl":[[0,2.6,26.05],[1,3.45,231.3]],"ltp":0.0,"tv":0.0,"id":8174357},{"batb":[[0,1.62,67.22],[1,1.01,10.52]],"batl":[[0,1.78,42.01],[1,2.1,405.23]],"ltp":0.0,"tv":0.0,"id":7412952}]}]}
{"op":"mcm","clk":"1004820594","pt":1580637871806,"mc":[{"id":"1.168209734","rc":[{"batl":[[1,2.1,0]],"ltp":0.0,"tv":0.0,"id":7412952}]}]}
{"op":"mcm","clk":"1004820660","pt":1580637872905,"mc":[{"id":"1.168209734","rc":[{"batb":[[0,1.01,10.52],[1,1.01,0]],"batl":[[0,3.45,231.3],[1,3.45,0]],"ltp":0.0,"tv":0.0,"id":8174357},{"batb":[[0,1.01,10.52],[1,1.01,0]],"ltp":0.0,"tv":0.0,"id":7412952}]}]}
{"op":"mcm","clk":"1004820987","pt":1580637878627,"mc":[{"id":"1.168209734","rc":[{"batb":[[0,2.26,32.77],[1,1.01,10.52]],"batl":[[0,2.56,26.89]],"ltp":0.0,"tv":0.0,"id":8174357},{"batb":[[0,1.64,65.54],[1,1.01,10.52]],"batl":[[0,1.8,42.01]],"ltp":0.0,"tv":0.0,"id":7412952}]}]}
{"op":"mcm","clk":"1004821057","pt":1580637879617,"mc":[{"id":"1.168209734","rc":[{"batl":[[1,2.16,379.97]],"ltp":0.0,"tv":0.0,"id":7412952}]}]}
{"op":"mcm","clk":"1004821121","pt":1580637880810,"mc":[{"id":"1.168209734","rc":[{"batl":[[1,3.3,243.07]],"ltp":0.0,"tv":0.0,"id":8174357}]}]}
{"op":"mcm","clk":"1004821616","pt":1580637889719,"mc":[{"id":"1.168209734","rc":[{"batb":[[0,1.01,10.52],[1,1.01,0]],"batl":[[0,3.3,243.07],[1,3.3,0]],"ltp":0.0,"tv":0.0,"id":8174357},{"batb":[[0,1.01,10.52],[1,1.01,0]],"batl":[[0,2.16,379.97],[1,2.16,0]],"ltp":0.0,"tv":0.0,"id":7412952}]}]}
{"op":"mcm","clk":"1004822182","pt":1580637898948,"mc":[{"id":"1.168209734","rc":[{"batb":[[0,2.24,33.61],[1,1.01,10.52]],"batl":[[0,2.54,26.89],[1,3.3,243.07]],"ltp":0.0,"tv":0.0,"id":8174357},{"batb":[[0,1.65,63.85],[1,1.01,10.52]],"batl":[[0,1.81,42.01],[1,2.16,379.97]],"ltp":0.0,"tv":0.0,"id":7412952}]}]}
{"op":"mcm","clk":"1004823424","pt":1580637915878,"mc":[{"id":"1.168209734","rc":[{"batb":[[0,1.01,10.52],[1,1.01,0]],"batl":[[0,3.3,243.07],[1,3.3,0]],"ltp":0.0,"tv":0.0,"id":8174357},{"batb":[[0,1.01,10.52],[1,1.01,0]],"batl":[[0,2.16,379.97],[1,2.16,0]],"ltp":0.0,"tv":0.0,"id":7412952}]}]}
{"op":"mcm","clk":"1004823893","pt":1580637922701,"mc":[{"id":"1.168209734","rc":[{"batb":[[0,2.18,35.29],[1,1.01,10.52]],"batl":[[0,2.48,27.73],[1,3.3,243.07]],"ltp":0.0,"tv":0.0,"id":8174357},{"batb":[[0,1.68,61.33],[1,1.01,10.52]],"batl":[[0,1.85,42.01],[1,2.16,379.97]],"ltp":0.0,"tv":0.0,"id":7412952}]}]}
{"op":"mcm","clk":"1004829303","pt":1580638009821,"mc":[{"id":"1.168209734","rc":[{"batb":[[0,1.01,10.52],[1,1.01,0]],"batl":[[0,3.3,243.07],[1,3.3,0]],"ltp":0.0,"tv":0.0,"id":8174357},{"batb":[[0,1.01,10.52],[1,1.01,0]],"batl":[[0,2.16,379.97],[1,2.16,0]],"ltp":0.0,"tv":0.0,"id":7412952}]}]}
{"op":"mcm","clk":"1004829973","pt":1580638020649,"mc":[{"id":"1.168209734","rc":[{"batb":[[0,2.2,34.45],[1,1.01,10.52]],"batl":[[0,2.5,27.73],[1,3.3,243.07]],"ltp":0.0,"tv":0.0,"id":8174357},{"batb":[[0,1.66,63.01],[1,1.01,10.52]],"batl":[[0,1.83,42.01]],"ltp":0.0,"tv":0.0,"id":7412952}]}]}
{"op":"mcm","clk":"1004830051","pt":1580638021742,"mc":[{"id":"1.168209734","rc":[{"batl":[[1,2.16,372.8]],"ltp":0.0,"tv":0.0,"id":7412952}]}]}
{"op":"mcm","clk":"1004830203","pt":1580638023929,"mc":[{"id":"1.168209734","rc":[{"batl":[[0,1.82,547.75],[1,1.83,42.01],[2,2.16,372.8]],"ltp":0.0,"tv":0.0,"id":7412952}]}]}
{"op":"mcm","clk":"1004830882","pt":1580638034760,"mc":[{"id":"1.168209734","rc":[{"batl":[[0,1.83,42.01],[1,2.16,372.8],[2,2.16,0]],"ltp":0.0,"tv":0.0,"id":7412952}]}]}
{"op":"mcm","clk":"1004830974","pt":1580638035953,"mc":[{"id":"1.168209734","rc":[{"batb":[[0,1.01,10.52],[1,1.01,0]],"batl":[[0,3.3,243.07],[1,3.3,0]],"ltp":0.0,"tv":0.0,"id":8174357},{"batb":[[0,1.01,10.52],[1,1.01,0]],"ltp":0.0,"tv":0.0,"id":7412952}]}]}
{"op":"mcm","clk":"1004831391","pt":1580638041591,"mc":[{"id":"1.168209734","rc":[{"batl":[[0,2.16,375.58]],"ltp":0.0,"tv":0.0,"id":7412952}]}]}
{"op":"mcm","clk":"1004832410","pt":1580638056686,"mc":[{"id":"1.168209734","rc":[{"batb":[[0,2.16,36.13],[1,1.01,10.52]],"batl":[[0,2.44,28.57],[1,3.15,128.5],[2,3.3,243.07]],"ltp":0.0,"tv":0.0,"id":8174357},{"batb":[[0,1.69,60.49],[1,1.01,10.52]],"batl":[[0,1.86,42.01]],"ltp":0.0,"tv":0.0,"id":7412952}]}]}
{"op":"mcm","clk":"1004832464","pt":1580638057420,"mc":[{"id":"1.168209734","rc":[{"batl":[[1,3.3,243.07],[2,3.3,0]],"ltp":0.0,"tv":0.0,"id":8174357},{"batl":[[1,2.22,365.49]],"ltp":0.0,"tv":0.0,"id":7412952}]}]}
{"op":"mcm","clk":"1004833162","pt":1580638069734,"mc":[{"id":"1.168209734","rc":[{"batb":[[0,1.01,10.52],[1,1.01,0]],"batl":[[0,3.3,243.07],[1,3.3,0]],"ltp":0.0,"tv":0.0,"id":8174357},{"batb":[[0,1.01,10.52],[1,1.01,0]],"batl":[[0,2.22,365.49],[1,2.22,0]],"ltp":0.0,"tv":0.0,"id":7412952}]}]}
{"op":"mcm","clk":"1004833955","pt":1580638080628,"mc":[{"id":"1.168209734","rc":[{"batb":[[0,2.18,35.29],[1,1.01,10.52]],"batl":[[0,2.48,27.73],[1,3.3,243.07]],"ltp":0.0,"tv":0.0,"id":8174357},{"batb":[[0,1.68,61.33],[1,1.01,10.52]],"batl":[[0,1.85,42.01]],"ltp":0.0,"tv":0.0,"id":7412952}]}]}
{"op":"mcm","clk":"1004834037","pt":1580638081666,"mc":[{"id":"1.168209734","rc":[{"batl":[[1,2.22,353.99]],"ltp":0.0,"tv":0.0,"id":7412952}]}]}
{"op":"mcm","clk":"1004834246","pt":1580638084940,"mc":[{"id":"1.168209734","rc":[{"batb":[[0,2.22,441.34],[1,2.18,35.29],[2,1.01,10.52]],"ltp":0.0,"tv":0.0,"id":8174357}]}]}
{"op":"mcm","clk":"1004834847","pt":1580638094469,"mc":[{"id":"1.168209734","rc":[{"batb":[[0,2.18,35.29],[1,1.01,10.52],[2,1.01,0]],"ltp":0.0,"tv":0.0,"id":8174357}]}]}
{"op":"mcm","clk":"1004834936","pt":1580638095774,"mc":[{"id":"1.168209734","rc":[{"batb":[[0,1.01,10.52],[1,1.01,0]],"batl":[[0,3.3,243.07],[1,3.3,0]],"ltp":0.0,"tv":0.0,"id":8174357},{"batb":[[0,1.01,10.52],[1,1.01,0]],"ltp":0.0,"tv":0.0,"id":7412952}]}]}
{"op":"mcm","clk":"1004835422","pt":1580638102690,"mc":[{"id":"1.168209734","rc":[{"batb":[[0,2.2,34.45],[1,1.01,10.52]],"batl":[[0,2.5,27.73],[1,3.3,243.07]],"ltp":0.0,"tv":0.0,"id":8174357},{"batb":[[0,1.66,63.01],[1,1.01,10.52]],"batl":[[0,1.83,42.01]],"ltp":0.0,"tv":0.0,"id":7412952}]}]}
{"op":"mcm","clk":"1004835489","pt":1580638103891,"mc":[{"id":"1.168209734","rc":[{"batl":[[1,2.16,366.79]],"ltp":0.0,"tv":0.0,"id":7412952}]}]}
{"op":"mcm","clk":"1004836242","pt":1580638115811,"mc":[{"id":"1.168209734","rc":[{"batb":[[0,1.01,10.52],[1,1.01,0]],"batl":[[0,3.3,243.07],[1,3.3,0]],"ltp":0.0,"tv":0.0,"id":8174357},{"batb":[[0,1.01,10.52],[1,1.01,0]],"batl":[[0,2.16,366.79],[1,2.16,0]],"ltp":0.0,"tv":0.0,"id":7412952}]}]}
{"op":"mcm","clk":"1004838344","pt":1580638146830,"mc":[{"id":"1.168209734","rc":[{"batb":[[0,2.22,33.61],[1,1.01,10.52]],"batl":[[0,2.54,26.89],[1,3.3,243.07]],"ltp":0.0,"tv":0.0,"id":8174357},{"batb":[[0,1.67,164.24],[1,1.66,120.34],[2,1.65,63.85]],"batl":[[0,1.73,120.96],[1,1.75,201.29],[2,1.82,42.01]],"ltp":0.0,"tv":0.0,"id":7412952}]}]}
{"op":"mcm","clk":"1004840413","pt":1580638175785,"mc":[{"id":"1.168209734","rc":[{"batb":[[0,1.01,10.52],[1,1.01,0]],"batl":[[0,3.3,243.07],[1,3.3,0]],"ltp":0.0,"tv":0.0,"id":8174357},{"batb":[[2,1.01,10.52]],"batl":[[2,1.82,0]],"ltp":0.0,"tv":0.0,"id":7412952}]}]}
{"op":"mcm","clk":"1004841822","pt":1580638194508,"mc":[{"id":"1.168209734","rc":[{"batb":[[0,1.67,195.99]],"batl":[[0,1.74,191.85],[1,1.76,197.07]],"ltp":0.0,"tv":0.0,"id":7412952}]}]}
{"op":"mcm","clk":"1004853208","pt":1580638346119,"mc":[{"id":"1.168209734","rc":[{"trd":[[2.34,7.57]],"ltp":2.34,"tv":7.57,"id":8174357},{"trd":[[1.74,10.18]],"batl":[[0,1.74,181.67]],"ltp":1.74,"tv":10.18,"id":7412952}],"tv":17.75}]}
{"op":"mcm","clk":"1004857380","pt":1580638401797,"mc":[{"id":"1.168209734","rc":[{"batb":[[0,1.66,120.34],[1,1.01,10.52],[2,1.01,0]],"ltp":1.74,"tv":10.18,"id":7412952}]}]}
{"op":"mcm","clk":"1004857577","pt":1580638404763,"mc":[{"id":"1.168209734","rc":[{"batb":[[0,1.66,210.67],[1,1.65,123.35],[2,1.01,10.52]],"batl":[[0,1.73,193.08],[1,1.75,201.36]],"ltp":1.74,"tv":10.18,"id":7412952}]}]}
{"op":"mcm","clk":"1004859612","pt":1580638431722,"mc":[{"id":"1.168209734","rc":[{"batb":[[0,1.01,10.52],[1,1.65,0],[2,1.01,0]],"ltp":1.74,"tv":10.18,"id":7412952}]}]}
{"op":"mcm","clk":"1004859859","pt":1580638434739,"mc":[{"id":"1.168209734","rc":[{"batb":[[0,1.53,231.86],[1,1.52,167.81],[2,1.01,10.52]],"batl":[[0,1.82,165.72],[1,1.84,171.65]],"ltp":1.74,"tv":10.18,"id":7412952}]}]}
{"op":"mcm","clk":"1004859962","pt":1580638436102,"mc":[{"id":"1.168209734","rc":[{"batb":[[0,1.01,10.52],[1,1.52,0],[2,1.01,0]],"ltp":1.74,"tv":10.18,"id":7412952}]}]}
{"op":"mcm","clk":"1004860225","pt":1580638439609,"mc":[{"id":"1.168209734","rc":[{"batb":[[0,1.64,118.62],[1,1.63,128.52],[2,1.01,10.52]],"batl":[[0,1.7,199.75],[1,1.72,213.1]],"ltp":1.74,"tv":10.18,"id":7412952}]}]}
{"op":"mcm","clk":"1004860640","pt":1580638444430,"mc":[{"id":"1.168209734","rc":[{"batb":[[0,1.01,10.52],[1,1.63,0],[2,1.01,0]],"ltp":1.74,"tv":10.18,"id":7412952}]}]}
{"op":"mcm","clk":"1004860914","pt":1580638447421,"mc":[{"id":"1.168209734","rc":[{"batb":[[0,1.53,234.65],[1,1.52,167.81],[2,1.01,10.52]],"batl":[[0,1.82,163.37],[1,1.84,171.65]],"ltp":1.74,"tv":10.18,"id":7412952}]}]}
{"op":"mcm","clk":"1004861159","pt":1580638450618,"mc":[{"id":"1.168209734","rc":[{"batb":[[0,1.01,10.52],[1,1.52,0],[2,1.01,0]],"ltp":1.74,"tv":10.18,"id":7412952}]}]}
{"op":"mcm","clk":"1004861438","pt":1580638453751,"mc":[{"id":"1.168209734","rc":[{"batb":[[0,1.75,134.15],[1,1.73,207.73],[2,1.01,10.52]],"ltp":1.74,"tv":10.18,"id":7412952}]}]}
{"op":"mcm","clk":"1004861541","pt":1580638454821,"mc":[{"id":"1.168209734","rc":[{"batb":[[0,2.1,37.81],[1,1.01,10.52]],"batl":[[0,2.38,30.25]],"ltp":2.34,"tv":7.57,"id":8174357},{"batb":[[2,1.72,57.97]],"batl":[[2,1.89,42.01]],"ltp":1.74,"tv":10.18,"id":7412952}]}]}
{"op":"mcm","clk":"1004861763","pt":1580638457125,"mc":[{"id":"1.168209734","rc":[{"batl":[[1,3,484.06]],"ltp":2.34,"tv":7.57,"id":8174357}]}]}
{"op":"mcm","clk":"1004862484","pt":1580638465845,"mc":[{"id":"1.168209734","rc":[{"batb":[[0,1.72,57.97],[1,1.01,10.52],[2,1.72,0]],"batl":[[0,1.89,42.01],[1,2.3,94.35],[2,1.89,0]],"ltp":1.74,"tv":10.18,"id":7412952}]}]}
{"op":"mcm","clk":"1004862724","pt":1580638468756,"mc":[{"id":"1.168209734","rc":[{"batb":[[0,1.01,10.52],[1,1.01,0]],"batl":[[0,3,484.06],[1,3,0]],"ltp":2.34,"tv":7.57,"id":8174357},{"batb":[[0,1.63,194.46],[1,1.62,131.7],[2,1.01,10.52]],"batl":[[0,1.9,173.57],[1,1.92,150.56],[2,2.3,94.35]],"ltp":1.74,"tv":10.18,"id":7412952}]}]}
{"op":"mcm","clk":"1004862808","pt":1580638469847,"mc":[{"id":"1.168209734","rc":[{"batb":[[0,1.01,10.52],[1,1.62,0],[2,1.01,0]],"batl":[[0,2.3,94.35],[1,1.92,0],[2,2.3,0]],"ltp":1.74,"tv":10.18,"id":7412952}]}]}
{"op":"mcm","clk":"1004862915","pt":1580638471250,"mc":[{"id":"1.168209734","rc":[{"batb":[[0,1.72,195.48],[1,1.7,220.78],[2,1.01,10.52]],"batl":[[0,1.79,135.9],[1,1.81,180.88],[2,2.3,94.35]],"ltp":1.74,"tv":10.18,"id":7412952}]}]}
{"op":"mcm","clk":"1004863337","pt":1580638475955,"mc":[{"id":"1.168209734","rc":[{"batb":[[0,1.01,10.52],[1,1.7,0],[2,1.01,0]],"batl":[[0,2.3,94.35],[1,1.81,0],[2,2.3,0]],"ltp":1.74,"tv":10.18,"id":7412952}]}]}
{"op":"mcm","clk":"1004863514","pt":1580638478055,"mc":[{"id":"1.168209734","rc":[{"batb":[[0,1.63,194.46],[1,1.62,131.7],[2,1.01,10.52]],"batl":[[0,1.9,173.57],[1,1.92,150.56],[2,2.3,94.35]],"ltp":1.74,"tv":10.18,"id":7412952}]}]}
{"op":"mcm","clk":"1004864024","pt":1580638483783,"mc":[{"id":"1.168209734","rc":[{"batl":[[0,2.3,94.35],[1,1.92,0],[2,2.3,0]],"ltp":1.74,"tv":10.18,"id":7412952}]}]}
{"op":"mcm","clk":"1004864319","pt":1580638486871,"mc":[{"id":"1.168209734","rc":[{"batb":[[0,2.28,32.77],[1,1.01,10.52]],"batl":[[0,2.6,26.05]],"ltp":2.34,"tv":7.57,"id":8174357},{"batb":[[0,1.63,260.84]],"batl":[[0,1.69,140.3],[1,1.71,217.67],[2,1.78,42.01]],"ltp":1.74,"tv":10.18,"id":7412952}]}]}
{"op":"mcm","clk":"1004864530","pt":1580638489396,"mc":[{"id":"1.168209734","rc":[{"batl":[[1,3.45,410.62]],"ltp":2.34,"tv":7.57,"id":8174357}]}]}
{"op":"mcm","clk":"1004865936","pt":1580638503882,"mc":[{"id":"1.168209734","rc":[{"batb":[[0,1.01,10.52],[1,1.01,0]],"batl":[[0,3.45,410.62],[1,3.45,0]],"ltp":2.34,"tv":7.57,"id":8174357},{"batb":[[0,1.01,10.52],[1,1.62,0],[2,1.01,0]],"batl":[[0,2.1,117.98],[1,1.71,0],[2,1.78,0]],"ltp":1.74,"tv":10.18,"id":7412952}]}]}
{"op":"mcm","clk":"1004866323","pt":1580638508730,"mc":[{"id":"1.168209734","rc":[{"batb":[[0,1.6,159.54],[1,1.59,140.91],[2,1.01,10.52]],"batl":[[0,1.66,212.91],[1,1.67,116.99],[2,2.1,117.98]],"ltp":1.74,"tv":10.18,"id":7412952}]}]}
{"op":"mcm","clk":"1004866703","pt":1580638513416,"mc":[{"id":"1.168209734","rc":[{"batb":[[0,1.01,10.52],[1,1.59,0],[2,1.01,0]],"batl":[[0,2.1,117.98],[1,1.67,0],[2,2.1,0]],"ltp":1.74,"tv":10.18,"id":7412952}]}]}
{"op":"mcm","clk":"1004866918","pt":1580638516308,"mc":[{"id":"1.168209734","rc":[{"batb":[[0,1.48,179.55],[1,1.47,191.71],[2,1.01,10.51]],"batl":[[0,1.8,124.45],[1,1.82,177.8],[2,2.1,117.98]],"ltp":1.74,"tv":10.18,"id":7412952}]}]}
{"op":"mcm","clk":"1004867157","pt":1580638519943,"mc":[{"id":"1.168209734","rc":[{"batb":[[0,1.01,10.52],[1,1.47,0],[2,1.01,0]],"ltp":1.74,"tv":10.18,"id":7412952}]}]}
{"op":"mcm","clk":"1004867386","pt":1580638522939,"mc":[{"id":"1.168209734","rc":[{"batb":[[0,2.12,36.97],[1,1.01,10.52]],"ltp":2.34,"tv":7.57,"id":8174357},{"batb":[[0,1.73,196.43],[1,1.71,216.4],[2,1.01,10.52]],"batl":[[2,1.87,42.01]],"ltp":1.74,"tv":10.18,"id":7412952}]}]}
{"op":"mcm","clk":"1004867406","pt":1580638523315,"mc":[{"id":"1.168209734","rc":[{"batl":[[0,2.4,29.41]],"ltp":2.34,"tv":7.57,"id":8174357},{"batb":[[1,1.71,275.21]],"ltp":1.74,"tv":10.18,"id":7412952}]}]}
{"op":"mcm","clk":"1004867584","pt":1580638525866,"mc":[{"id":"1.168209734","rc":[{"batl":[[1,3.15,453.41]],"ltp":2.34,"tv":7.57,"id":8174357}]}]}
{"op":"mcm","clk":"1004868684","pt":1580638538945,"mc":[{"id":"1.168209734","rc":[{"batb":[[0,1.71,58.81],[1,1.01,10.52],[2,1.01,0]],"batl":[[0,1.87,42.01],[1,2.1,117.98],[2,1.87,0]],"ltp":1.74,"tv":10.18,"id":7412952}]}]}
{"op":"mcm","clk":"1004868783","pt":1580638540047,"mc":[{"id":"1.168209734","rc":[{"batb":[[0,1.01,10.52],[1,1.01,0]],"batl":[[0,3.15,453.41],[1,3.15,0]],"ltp":2.34,"tv":7.57,"id":8174357},{"batb":[[0,1.01,10.52],[1,1.01,0]],"batl":[[0,2.1,117.98],[1,2.1,0]],"ltp":1.74,"tv":10.18,"id":7412952}]}]}
{"op":"mcm","clk":"1004868913","pt":1580638541823,"mc":[{"id":"1.168209734","rc":[{"batb":[[0,1.6,177.57],[1,1.59,141],[2,1.01,10.52]],"batl":[[0,1.89,103.76],[1,1.91,153.12],[2,2.1,117.98]],"ltp":1.74,"tv":10.18,"id":7412952}]}]}
{"op":"mcm","clk":"1004869131","pt":1580638544328,"mc":[{"id":"1.168209734","rc":[{"batb":[[0,1.01,10.52],[1,1.59,0],[2,1.01,0]],"ltp":1.74,"tv":10.18,"id":7412952}]}]}
{"op":"mcm","clk":"1004869257","pt":1580638545936,"mc":[{"id":"1.168209734","rc":[{"batl":[[2,2.1,0]],"ltp":1.74,"tv":10.18,"id":7412952}]}]}
{"op":"mcm","clk":"1004869330","pt":1580638546935,"mc":[{"id":"1.168209734","rc":[{"batb":[[0,1.82,132.47],[1,1.8,182.12],[2,1.01,10.52]],"ltp":1.74,"tv":10.18,"id":7412952}]}]}
{"op":"mcm","clk":"1004869516","pt":1580638549951,"mc":[{"id":"1.168209734","rc":[{"batb":[[0,2.02,41.17],[1,1.01,10.52]],"batl":[[0,2.26,32.77]],"ltp":2.34,"tv":7.57,"id":8174357},{"batb":[[2,1.79,52.93]],"batl":[[2,1.97,42.01]],"ltp":1.74,"tv":10.18,"id":7412952}]}]}
{"op":"mcm","clk":"1004869586","pt":1580638550737,"mc":[{"id":"1.168209734","rc":[{"batl":[[1,2.92,498.35]],"ltp":2.34,"tv":7.57,"id":8174357}]}]}
{"op":"mcm","clk":"1004870152","pt":1580638558950,"mc":[{"id":"1.168209734","rc":[{"batb":[[0,1.79,52.93],[1,1.01,10.52],[2,1.79,0]],"batl":[[0,1.97,42.01],[1,2.36,86.99],[2,1.97,0]],"ltp":1.74,"tv":10.18,"id":7412952}]}]}
{"op":"mcm","clk":"1004870218","pt":1580638559986,"mc":[{"id":"1.168209734","rc":[{"batb":[[0,1.01,10.52],[1,1.01,0]],"batl":[[0,2.92,498.35],[1,2.92,0]],"ltp":2.34,"tv":7.57,"id":8174357},{"batb":[[0,1.01,10.52],[1,1.01,0]],"batl":[[0,2.36,86.99],[1,2.36,0]],"ltp":1.74,"tv":10.18,"id":7412952}]}]}
{"op":"mcm","clk":"1004870374","pt":1580638561877,"mc":[{"id":"1.168209734","rc":[{"batb":[[0,1.74,124.67],[1,1.72,211.86],[2,1.01,10.52]],"batl":[[0,1.95,158.15],[1,1.97,139.42],[2,2.36,86.99]],"ltp":1.74,"tv":10.18,"id":7412952}]}]}
{"op":"mcm","clk":"1004870448","pt":1580638562880,"mc":[{"id":"1.168209734","rc":[{"batb":[[0,1.01,10.52],[1,1.72,0],[2,1.01,0]],"ltp":1.74,"tv":10.18,"id":7412952}]}]}
{"op":"mcm","clk":"1004870693","pt":1580638565857,"mc":[{"id":"1.168209734","rc":[{"batb":[[0,1.87,112.18],[1,1.85,166.68],[2,1.01,10.52]],"ltp":1.74,"tv":10.18,"id":7412952}]}]}
{"op":"mcm","clk":"1004870777","pt":1580638566903,"mc":[{"id":"1.168209734","rc":[{"batb":[[0,1.94,44.53],[1,1.01,10.52]],"batl":[[0,2.18,35.29],[1,2.92,498.35]],"ltp":2.34,"tv":7.57,"id":8174357},{"batb":[[2,1.84,49.57]],"batl":[[2,2.04,40.33]],"ltp":1.74,"tv":10.18,"id":7412952}]}]}
{"op":"mcm","clk":"1004870975","pt":1580638569757,"mc":[{"id":"1.168209734","rc":[{"batl":[[0,2.12,70.2],[1,2.18,35.29],[2,2.92,498.35]],"ltp":2.34,"tv":7.57,"id":8174357},{"batb":[[0,1.84,49.57],[1,1.01,10.52],[2,1.84,0]],"batl":[[0,2.04,40.33],[1,2.36,86.99],[2,2.04,0]],"ltp":1.74,"tv":10.18,"id":7412952}]}]}
{"op":"mcm","clk":"1004871203","pt":1580638572878,"mc":[{"id":"1.168209734","rc":[{"batb":[[0,1.86,175.97],[1,1.84,219.33],[2,1.01,10.52]],"batl":[[0,1.94,105.09],[1,1.96,141.68],[2,2.04,40.33]],"ltp":1.74,"tv":10.18,"id":7412952}]}]}
{"op":"mcm","clk":"1004872019","pt":1580638583877,"mc":[{"id":"1.168209734","rc":[{"batb":[[0,1.01,10.52],[1,1.84,0],[2,1.01,0]],"batl":[[0,2.04,40.33],[1,2.36,86.99],[2,2.04,0]],"ltp":1.74,"tv":10.18,"id":7412952}]}]}
{"op":"mcm","clk":"1004872079","pt":1580638584874,"mc":[{"id":"1.168209734","rc":[{"batb":[[0,1.01,10.52],[1,1.01,0]],"ltp":2.34,"tv":7.57,"id":8174357}]}]}
{"op":"mcm","clk":"1004872213","pt":1580638586877,"mc":[{"id":"1.168209734","rc":[{"batb":[[0,1.85,48.73],[1,1.01,10.52]],"ltp":1.74,"tv":10.18,"id":7412952}]}]}
{"op":"mcm","clk":"1004872276","pt":1580638587773,"mc":[{"id":"1.168209734","rc":[{"batb":[[0,1.95,43.69],[1,1.01,10.52]],"ltp":2.34,"tv":7.57,"id":8174357}]}]}
{"op":"mcm","clk":"1004872522","pt":1580638590936,"mc":[{"id":"1.168209734","rc":[{"batb":[[0,1.86,165.44],[1,1.85,48.73],[2,1.84,169.83]],"batl":[[0,1.94,115.43],[1,1.96,141.74],[2,2.02,434.75]],"ltp":1.74,"tv":10.18,"id":7412952}]}]}
{"op":"mcm","clk":"1004872529","pt":1580638591007,"mc":[{"id":"1.168209734","rc":[{"batl":[[2,2.04,40.33]],"ltp":1.74,"tv":10.18,"id":7412952}]}]}
{"op":"mcm","clk":"1004873509","pt":1580638602834,"mc":[{"id":"1.168209734","rc":[{"batb":[[0,1.85,48.73],[1,1.01,10.52],[2,1.84,0]],"batl":[[0,2.04,40.33],[1,2.36,86.99],[2,2.04,0]],"ltp":1.74,"tv":10.18,"id":7412952}]}]}
{"op":"mcm","clk":"1004873727","pt":1580638605833,"mc":[{"id":"1.168209734","rc":[{"batb":[[1,1.78,157.22],[2,1.76,196.16]],"batl":[[1,2.18,176.51],[2,2.2,101.84]],"ltp":1.74,"tv":10.18,"id":7412952}]}]}
{"op":"mcm","clk":"1004873767","pt":1580638606198,"mc":[{"id":"1.168209734","rc":[{"batl":[[0,2.02,434.75],[1,2.04,40.33],[2,2.18,176.51]],"ltp":1.74,"tv":10.18,"id":7412952}]}]}
{"op":"mcm","clk":"1004874908","pt":1580638620721,"mc":[{"id":"1.168209734","rc":[{"batl":[[0,2.04,40.33],[1,2.18,176.51],[2,2.2,101.84]],"ltp":1.74,"tv":10.18,"id":7412952}]}]}
{"op":"mcm","clk":"1004875017","pt":1580638622043,"mc":[{"id":"1.168209734","rc":[{"batb":[[0,1.01,10.52],[1,1.01,0]],"batl":[[1,2.92,498.35],[2,2.92,0]],"ltp":2.34,"tv":7.57,"id":8174357},{"batb":[[0,1.78,157.22],[1,1.76,196.16],[2,1.01,10.52]],"batl":[[0,2.18,176.51],[1,2.2,101.84],[2,2.36,86.99]],"ltp":1.74,"tv":10.18,"id":7412952}]}]}
{"op":"mcm","clk":"1004875858","pt":1580638632133,"mc":[{"id":"1.168209734","rc":[{"batb":[[0,1.01,10.52],[1,1.76,0],[2,1.01,0]],"batl":[[0,2.36,86.99],[1,2.2,0],[2,2.36,0]],"ltp":1.74,"tv":10.18,"id":7412952}]}]}
{"op":"mcm","clk":"1004876068","pt":1580638634830,"mc":[{"id":"1.168209734","rc":[{"batl":[[1,2.92,0]],"ltp":2.34,"tv":7.57,"id":8174357}]}]}
{"op":"mcm","clk":"1004876138","pt":1580638635558,"mc":[{"id":"1.168209734","rc":[{"batb":[[0,1.9,145.91],[1,1.88,158.64],[2,1.01,10.52]],"batl":[[0,1.98,103.59],[1,2,133.55],[2,2.36,86.99]],"ltp":1.74,"tv":10.18,"id":7412952}]}]}
{"op":"mcm","clk":"1004876413","pt":1580638638953,"mc":[{"id":"1.168209734","rc":[{"batl":[[1,2.72,540.28]],"ltp":2.34,"tv":7.57,"id":8174357},{"batb":[[0,1.01,10.52],[1,1.88,0],[2,1.01,0]],"batl":[[0,2.36,86.99],[1,2,0],[2,2.36,0]],"ltp":1.74,"tv":10.18,"id":7412952}]}]}
{"op":"mcm","clk":"1004876597","pt":1580638641667,"mc":[{"id":"1.168209734","rc":[{"batb":[[0,1.78,157.22],[1,1.76,196.16],[2,1.01,10.52]],"batl":[[0,2.18,176.51],[1,2.2,101.84],[2,2.36,86.99]],"ltp":1.74,"tv":10.18,"id":7412952}]}]}
{"op":"mcm","clk":"1004876805","pt":1580638644266,"mc":[{"id":"1.168209734","rc":[{"batb":[[0,1.01,10.52],[1,1.76,0],[2,1.01,0]],"batl":[[0,2.36,86.99],[1,2.2,0],[2,2.36,0]],"ltp":1.74,"tv":10.18,"id":7412952}]}]}
{"op":"mcm","clk":"1004877013","pt":1580638646877,"mc":[{"id":"1.168209734","rc":[{"batl":[[1,2.72,0]],"ltp":2.34,"tv":7.57,"id":8174357}]}]}
{"op":"mcm","clk":"1004877071","pt":1580638647656,"mc":[{"id":"1.168209734","rc":[{"batb":[[0,1.85,186.42],[1,1.83,173.47],[2,1.01,10.52]],"batl":[[0,1.93,106.15],[1,1.95,144.56],[2,2.12,70.2]],"ltp":2.34,"tv":7.57,"id":8174357}]}]}
{"op":"mcm","clk":"1004877153","pt":1580638649003,"mc":[{"id":"1.168209734","rc":[{"batb":[[2,1.78,53.77]],"batl":[[2,1.98,42.01]],"ltp":2.34,"tv":7.57,"id":8174357},{"batb":[[0,2.02,41.17],[1,1.01,10.52]],"batl":[[0,2.28,32.77]],"ltp":1.74,"tv":10.18,"id":7412952}]}]}
{"op":"mcm","clk":"1004877294","pt":1580638651068,"mc":[{"id":"1.168209734","rc":[{"batl":[[1,2.72,66.37]],"ltp":1.74,"tv":10.18,"id":7412952}]}]}
{"op":"mcm","clk":"1004877574","pt":1580638654674,"mc":[{"id":"1.168209734","rc":[{"batb":[[0,1.78,53.77],[1,1.01,10.52],[2,1.78,0]],"batl":[[0,1.98,42.01],[1,2.12,70.2],[2,2.5,607.28]],"ltp":2.34,"tv":7.57,"id":8174357}]}]}
{"op":"mcm","clk":"1004877797","pt":1580638657792,"mc":[{"id":"1.168209734","rc":[{"batb":[[0,1.86,109.34],[1,1.84,170.34],[2,1.78,53.77]],"batl":[[0,1.94,171.32],[1,1.96,142.29],[2,1.98,42.01]],"ltp":2.34,"tv":7.57,"id":8174357}]}]}
{"op":"mcm","clk":"1004878716","pt":1580638671501,"mc":[{"id":"1.168209734","rc":[{"batb":[[0,1.78,53.77],[1,1.01,10.52],[2,1.78,0]],"batl":[[0,1.98,42.01],[1,2.5,607.28],[2,1.98,0]],"ltp":2.34,"tv":7.57,"id":8174357}]}]}
{"op":"mcm","clk":"1004878763","pt":1580638672119,"mc":[{"id":"1.168209734","rc":[{"batb":[[0,1.01,10.52],[1,1.01,0]],"batl":[[0,2.5,607.28],[1,2.5,0]],"ltp":2.34,"tv":7.57,"id":8174357},{"batb":[[0,1.01,10.52],[1,1.01,0]],"batl":[[0,2.72,66.37],[1,2.72,0]],"ltp":1.74,"tv":10.18,"id":7412952}]}]}
{"op":"mcm","clk":"1004878927","pt":1580638674418,"mc":[{"id":"1.168209734","rc":[{"batb":[[0,1.61,235.86],[1,1.6,139.85],[2,1.01,10.52]],"batl":[[0,2.1,178.36],[1,2.12,112.79],[2,2.5,607.28]],"ltp":2.34,"tv":7.57,"id":8174357}]}]}
{"op":"mcm","clk":"1004879193","pt":1580638678512,"mc":[{"id":"1.168209734","rc":[{"batb":[[0,1.01,10.52],[1,1.6,0],[2,1.01,0]],"batl":[[0,2.5,607.28],[1,2.12,0],[2,2.5,0]],"ltp":2.34,"tv":7.57,"id":8174357}]}]}
{"op":"mcm","clk":"1004879488","pt":1580638681911,"mc":[{"id":"1.168209734","rc":[{"batb":[[0,1.92,112.71],[1,1.9,153.41],[2,1.01,10.52]],"batl":[[0,2,121.22],[1,2.02,129.68]],"ltp":1.74,"tv":10.18,"id":7412952}]}]}
{"op":"mcm","clk":"1004879586","pt":1580638682908,"mc":[{"id":"1.168209734","rc":[{"batb":[[0,1.9,46.21],[1,1.01,10.52]],"batl":[[0,2.12,36.97],[1,2.5,607.28]],"ltp":2.34,"tv":7.57,"id":8174357},{"batb":[[2,1.89,47.05]],"batl":[[2,2.12,36.97]],"ltp":1.74,"tv":10.18,"id":7412952}]}]}
{"op":"mcm","clk":"1004880319","pt":1580638691939,"mc":[{"id":"1.168209734","rc":[{"batb":[[0,1.01,10.52],[1,1.01,0]],"batl":[[0,2.5,607.28],[1,2.5,0]],"ltp":2.34,"tv":7.57,"id":8174357},{"batb":[[0,1.01,10.52],[1,1.9,0],[2,1.89,0]],"batl":[[0,2.5,77.04],[1,2.02,0],[2,2.12,0]],"ltp":1.74,"tv":10.18,"id":7412952}]}]}
{"op":"mcm","clk":"1004880588","pt":1580638694925,"mc":[{"id":"1.168209734","rc":[{"batb":[[0,1.8,185.94],[1,1.78,189.03],[2,1.01,10.52]],"ltp":1.74,"tv":10.18,"id":7412952}]}]}
{"op":"mcm","clk":"1004880818","pt":1580638697742,"mc":[{"id":"1.168209734","rc":[{"batl":[[0,1.88,148.45],[1,1.9,155.48]],"ltp":1.74,"tv":10.18,"id":7412952}]}]}
{"op":"mcm","clk":"1004880911","pt":1580638698952,"mc":[{"id":"1.168209734","rc":[{"batb":[[0,2.02,41.17],[1,1.01,10.52]],"batl":[[0,2.26,32.77]],"ltp":2.34,"tv":7.57,"id":8174357},{"batb":[[0,1.8,238.03]],"batl":[[2,1.99,42.01]],"ltp":1.74,"tv":10.18,"id":7412952}]}]}
{"op":"mcm","clk":"1004881059","pt":1580638700423,"mc":[{"id":"1.168209734","rc":[{"batl":[[1,2.92,498.35]],"ltp":2.34,"tv":7.57,"id":8174357}]}]}
{"op":"mcm","clk":"1004881239","pt":1580638702562,"mc":[{"id":"1.168209734","rc":[{"trd":[[2.12,70]],"ltp":2.12,"tv":77.57,"id":8174357},{"trd":[[1.88,78.94]],"batb":[[0,1.8,52.09],[1,1.01,10.52],[2,1.01,0]],"batl":[[0,1.88,69.51]],"ltp":1.88,"tv":89.12,"id":7412952}],"tv":166.69}]}
{"op":"mcm","clk":"1004881497","pt":1580638705536,"mc":[{"id":"1.168209734","rc":[{"batb":[[0,1.81,123.96],[1,1.8,52.09],[2,1.79,185.34]],"batl":[[0,1.88,119.52]],"ltp":1.88,"tv":89.12,"id":7412952}]}]}
{"op":"mcm","clk":"1004881807","pt":1580638708931,"mc":[{"id":"1.168209734","rc":[{"batb":[[0,1.8,52.09],[1,1.01,10.52],[2,1.79,0]],"batl":[[0,1.99,42.01],[1,2.36,86.99],[2,1.99,0]],"ltp":1.88,"tv":89.12,"id":7412952}]}]}
{"op":"mcm","clk":"1004881933","pt":1580638710371,"mc":[{"id":"1.168209734","rc":[{"batb":[[0,1.01,10.52],[1,1.01,0]],"batl":[[0,2.92,498.35],[1,2.92,0]],"ltp":2.12,"tv":77.57,"id":8174357},{"batb":[[0,1.01,10.52],[1,1.01,0]],"batl":[[0,2.36,86.99],[1,2.36,0]],"ltp":1.88,"tv":89.12,"id":7412952}]}]}
{"op":"mcm","clk":"1004882056","pt":1580638711642,"mc":[{"id":"1.168209734","rc":[{"batb":[[0,1.74,113.06],[1,1.72,211.46],[2,1.01,10.52]],"batl":[[0,2.08,151.09],[1,2.1,115.92],[2,2.36,86.99]],"ltp":1.88,"tv":89.12,"id":7412952}]}]}
{"op":"mcm","clk":"1004882142","pt":1580638712673,"mc":[{"id":"1.168209734","rc":[{"batb":[[0,1.01,10.52],[1,1.72,0],[2,1.01,0]],"batl":[[0,2.36,86.99],[1,2.1,0],[2,2.36,0]],"ltp":1.88,"tv":89.12,"id":7412952}]}]}
{"op":"mcm","clk":"1004882381","pt":1580638715955,"mc":[{"id":"1.168209734","rc":[{"batb":[[0,1.84,146.49],[1,1.82,175.71],[2,1.01,10.52]],"batl":[[0,1.92,149.58],[1,1.94,145.96],[2,2.36,86.99]],"ltp":1.88,"tv":89.12,"id":7412952}]}]}
{"op":"mcm","clk":"1004882626","pt":1580638718951,"mc":[{"id":"1.168209734","rc":[{"batb":[[0,1.01,10.52],[1,1.82,0],[2,1.01,0]],"batl":[[0,2.36,86.99],[1,1.94,0],[2,2.36,0]],"ltp":1.88,"tv":89.12,"id":7412952}]}]}
{"op":"mcm","clk":"1004882833","pt":1580638721582,"mc":[{"id":"1.168209734","rc":[{"batb":[[0,1.74,111.48],[1,1.72,211.46],[2,1.01,10.52]],"batl":[[0,2.08,152.43],[1,2.1,115.92],[2,2.36,86.99]],"ltp":1.88,"tv":89.12,"id":7412952}]}]}
{"op":"mcm","clk":"1004883075","pt":1580638724776,"mc":[{"id":"1.168209734","rc":[{"batl":[[0,2.36,86.99],[1,2.1,0],[2,2.36,0]],"ltp":1.88,"tv":89.12,"id":7412952}]}]}
{"op":"mcm","clk":"1004883296","pt":1580638727457,"mc":[{"id":"1.168209734","rc":[{"batl":[[0,1.81,193.86],[1,1.83,174.26]],"ltp":1.88,"tv":89.12,"id":7412952}]}]}
{"op":"mcm","clk":"1004883460","pt":1580638729887,"mc":[{"id":"1.168209734","rc":[{"batb":[[0,2.12,36.97],[1,1.01,10.52]],"batl":[[0,2.38,30.25],[1,2.92,498.35]],"ltp":2.12,"tv":77.57,"id":8174357},{"batb":[[1,1.72,269.43]],"batl":[[2,1.9,42.01]],"ltp":1.88,"tv":89.12,"id":7412952}]}]}
{"op":"mcm","clk":"1004884484","pt":1580638742810,"mc":[{"id":"1.168209734","rc":[{"batb":[[0,1.72,57.97],[1,1.01,10.52],[2,1.01,0]],"batl":[[0,1.9,42.01],[1,2.22,99.42],[2,1.9,0]],"ltp":1.88,"tv":89.12,"id":7412952}]}]}
{"op":"mcm","clk":"1004884584","pt":1580638744093,"mc":[{"id":"1.168209734","rc":[{"batb":[[0,1.01,10.52],[1,1.01,0]],"batl":[[0,2.92,498.35],[1,2.92,0]],"ltp":2.12,"tv":77.57,"id":8174357},{"batb":[[0,1.01,10.52],[1,1.01,0]],"batl":[[0,2.22,99.42],[1,2.22,0]],"ltp":1.88,"tv":89.12,"id":7412952}]}]}
{"op":"mcm","clk":"1004884710","pt":1580638745919,"mc":[{"id":"1.168209734","rc":[{"batb":[[0,1.7,188.05],[1,1.68,230.06],[2,1.01,10.52]],"batl":[[0,1.89,132.24],[1,1.91,152.92],[2,2.22,99.42]],"ltp":1.88,"tv":89.12,"id":7412952}]}]}
{"op":"mcm","clk":"1004884793","pt":1580638746914,"mc":[{"id":"1.168209734","rc":[{"batl":[[0,2.22,99.42],[1,1.91,0],[2,2.22,0]],"ltp":1.88,"tv":89.12,"id":7412952}]}]}
{"op":"mcm","clk":"1004885015","pt":1580638749793,"mc":[{"id":"1.168209734","rc":[{"batl":[[0,1.77,165.06],[1,1.79,186.97],[2,2.22,99.42]],"ltp":1.88,"tv":89.12,"id":7412952}]}]}
{"op":"mcm","clk":"1004885157","pt":1580638751611,"mc":[{"id":"1.168209734","rc":[{"batb":[[0,2.18,35.29],[1,1.01,10.52]],"batl":[[0,2.48,27.73],[1,2.92,498.35]],"ltp":2.12,"tv":77.57,"id":8174357},{"batb":[[1,1.68,291.39]],"batl":[[2,1.85,42.01]],"ltp":1.88,"tv":89.12,"id":7412952}]}]}
{"op":"mcm","clk":"1004886241","pt":1580638764532,"mc":[{"id":"1.168209734","rc":[{"batl":[[0,2.92,498.35],[1,2.92,0]],"ltp":2.12,"tv":77.57,"id":8174357}]}]}
{"op":"mcm","clk":"1004886476","pt":1580638767408,"mc":[{"id":"1.168209734","rc":[{"batl":[[0,2.46,28.57],[1,2.92,498.35]],"ltp":2.12,"tv":77.57,"id":8174357}]}]}
{"op":"mcm","clk":"1004887379","pt":1580638777823,"mc":[{"id":"1.168209734","rc":[{"batb":[[0,1.68,61.33],[1,1.01,10.52],[2,1.01,0]],"batl":[[0,1.85,42.01],[1,2.22,99.42],[2,1.85,0]],"ltp":1.88,"tv":89.12,"id":7412952}]}]}
{"op":"mcm","clk":"1004887419","pt":1580638778344,"mc":[{"id":"1.168209734","rc":[{"batb":[[0,1.01,10.52],[1,1.01,0]],"batl":[[0,2.92,498.35],[1,2.92,0]],"ltp":2.12,"tv":77.57,"id":8174357},{"batb":[[0,1.01,10.52],[1,1.01,0]],"batl":[[0,2.22,99.42],[1,2.22,0]],"ltp":1.88,"tv":89.12,"id":7412952}]}]}
{"op":"mcm","clk":"1004887638","pt":1580638780230,"mc":[{"id":"1.168209734","rc":[{"batb":[[0,1.56,132.59],[1,1.55,154.74],[2,1.01,10.52]],"batl":[[0,1.87,158.88],[1,1.89,157.73],[2,2.22,99.42]],"ltp":1.88,"tv":89.12,"id":7412952}]}]}
{"op":"mcm","clk":"1004888056","pt":1580638785772,"mc":[{"id":"1.168209734","rc":[{"batb":[[0,1.01,10.52],[1,1.55,0],[2,1.01,0]],"ltp":1.88,"tv":89.12,"id":7412952}]}]}
{"op":"mcm","clk":"1004888315","pt":1580638788756,"mc":[{"id":"1.168209734","rc":[{"batb":[[0,1.79,184.89],[1,1.77,192.3],[2,1.01,10.52]],"ltp":1.88,"tv":89.12,"id":7412952}]}]}
{"op":"mcm","clk":"1004888386","pt":1580638789538,"mc":[{"id":"1.168209734","rc":[{"batb":[[0,2.06,39.49],[1,1.01,10.52]],"batl":[[0,2.32,31.09],[1,2.92,498.35]],"ltp":2.12,"tv":77.57,"id":8174357},{"batb":[[2,1.76,54.61]],"batl":[[2,1.93,42.01]],"ltp":1.88,"tv":89.12,"id":7412952}]}]}
{"op":"mcm","clk":"1004889881","pt":1580638808861,"mc":[{"id":"1.168209734","rc":[{"batb":[[0,1.76,54.61],[1,1.01,10.52],[2,1.76,0]],"batl":[[0,1.93,42.01],[1,2.22,99.42],[2,1.93,0]],"ltp":1.88,"tv":89.12,"id":7412952}]}]}
{"op":"mcm","clk":"1004889979","pt":1580638810167,"mc":[{"id":"1.168209734","rc":[{"batb":[[0,1.01,10.52],[1,1.01,0]],"batl":[[0,2.92,498.35],[1,2.92,0]],"ltp":2.12,"tv":77.57,"id":8174357},{"batb":[[0,1.01,10.52],[1,1.01,0]],"batl":[[0,2.22,99.42],[1,2.22,0]],"ltp":1.88,"tv":89.12,"id":7412952}]}]}
{"op":"mcm","clk":"1004890093","pt":1580638811569,"mc":[{"id":"1.168209734","rc":[{"batb":[[0,1.66,234.94],[1,1.65,123.23],[2,1.01,10.52]],"batl":[[0,1.95,124.3],[1,1.97,139.24],[2,2.22,99.42]],"ltp":1.88,"tv":89.12,"id":7412952}]}]}
{"op":"mcm","clk":"1004890256","pt":1580638813497,"mc":[{"id":"1.168209734","rc":[{"batb":[[0,1.01,10.52],[1,1.65,0],[2,1.01,0]],"batl":[[0,2.22,99.42],[1,1.97,0],[2,2.22,0]],"ltp":1.88,"tv":89.12,"id":7412952}]}]}
{"op":"mcm","clk":"1004890504","pt":1580638816487,"mc":[{"id":"1.168209734","rc":[{"batb":[[0,1.77,119.6],[1,1.75,199.49],[2,1.01,10.52]],"batl":[[0,1.84,158.05],[1,1.86,165.71],[2,2.22,99.42]],"ltp":1.88,"tv":89.12,"id":7412952}]}]}
{"op":"mcm","clk":"1004890820","pt":1580638820814,"mc":[{"id":"1.168209734","rc":[{"batb":[[0,1.01,10.52],[1,1.75,0],[2,1.01,0]],"batl":[[0,2.22,99.42],[1,1.86,0],[2,2.22,0]],"ltp":1.88,"tv":89.12,"id":7412952}]}]}
{"op":"mcm","clk":"1004891007","pt":1580638823415,"mc":[{"id":"1.168209734","rc":[{"batb":[[0,1.66,234.94],[1,1.65,123.23],[2,1.01,10.52]],"batl":[[0,1.95,124.3],[1,1.97,139.24],[2,2.22,99.42]],"ltp":1.88,"tv":89.12,"id":7412952}]}]}
{"op":"mcm","clk":"1004891265","pt":1580638826913,"mc":[{"id":"1.168209734","rc":[{"batl":[[0,2.22,99.42],[1,1.97,0],[2,2.22,0]],"ltp":1.88,"tv":89.12,"id":7412952}]}]}
{"op":"mcm","clk":"1004891520","pt":1580638829887,"mc":[{"id":"1.168209734","rc":[{"batl":[[0,1.73,169.76],[1,1.75,201.16],[2,2.22,99.42]],"ltp":1.88,"tv":89.12,"id":7412952}]}]}
{"op":"mcm","clk":"1004891694","pt":1580638831721,"mc":[{"id":"1.168209734","rc":[{"batb":[[0,2.24,33.61],[1,1.01,10.52]],"batl":[[0,2.54,26.89]],"ltp":2.12,"tv":77.57,"id":8174357},{"batb":[[1,1.65,187.08]],"batl":[[2,1.81,42.01]],"ltp":1.88,"tv":89.12,"id":7412952}]}]}
{"op":"mcm","clk":"1004891832","pt":1580638833026,"mc":[{"id":"1.168209734","rc":[{"batl":[[1,3.3,435.41]],"ltp":2.12,"tv":77.57,"id":8174357}]}]}
{"op":"mcm","clk":"1004892669","pt":1580638842841,"mc":[{"id":"1.168209734","rc":[{"batb":[[0,1.65,63.85],[1,1.01,10.52],[2,1.01,0]],"batl":[[0,1.81,42.01],[1,2.22,99.42],[2,1.81,0]],"ltp":1.88,"tv":89.12,"id":7412952}]}]}
{"op":"mcm","clk":"1004892772","pt":1580638844221,"mc":[{"id":"1.168209734","rc":[{"batb":[[0,1.01,10.52],[1,1.01,0]],"batl":[[0,3.3,435.41],[1,3.3,0]],"ltp":2.12,"tv":77.57,"id":8174357},{"batb":[[0,1.01,10.52],[1,1.01,0]],"batl":[[0,2.22,99.42],[1,2.22,0]],"ltp":1.88,"tv":89.12,"id":7412952}]}]}
{"op":"mcm","clk":"1004892872","pt":1580638845423,"mc":[{"id":"1.168209734","rc":[{"batb":[[0,1.49,294.65],[1,1.48,186.98],[2,1.01,10.51]],"batl":[[0,1.85,141.36],[1,1.87,163.05],[2,2.22,99.42]],"ltp":1.88,"tv":89.12,"id":7412952}]}]}
{"op":"mcm","clk":"1004893078","pt":1580638847919,"mc":[{"id":"1.168209734","rc":[{"batl":[[0,2.22,99.42],[1,1.87,0],[2,2.22,0]],"ltp":1.88,"tv":89.12,"id":7412952}]}]}
{"op":"mcm","clk":"1004893347","pt":1580638850634,"mc":[{"id":"1.168209734","rc":[{"batl":[[0,1.54,127.05],[1,1.55,152.94]],"ltp":1.88,"tv":89.12,"id":7412952}]}]}
{"op":"mcm","clk":"1004893434","pt":1580638851624,"mc":[{"id":"1.168209734","rc":[{"batb":[[0,2.6,26.05],[1,1.01,10.52]],"batl":[[0,3,21]],"ltp":2.12,"tv":77.57,"id":8174357},{"batb":[[0,1.5,84.02],[1,1.49,294.65],[2,1.48,186.98]],"batl":[[2,1.62,42.01]],"ltp":1.88,"tv":89.12,"id":7412952}]}]}
{"op":"mcm","clk":"1004893617","pt":1580638853750,"mc":[{"id":"1.168209734","rc":[{"batl":[[1,4.2,332.97]],"ltp":2.12,"tv":77.57,"id":8174357}]}]}
{"op":"mcm","clk":"1004893737","pt":1580638855158,"mc":[{"id":"1.168209734","rc":[{"batb":[[1,1.49,210.94]],"ltp":1.88,"tv":89.12,"id":7412952}]}]}
{"op":"mcm","clk":"1004894061","pt":1580638858930,"mc":[{"id":"1.168209734","rc":[{"batl":[[0,1.54,208.14]],"ltp":1.88,"tv":89.12,"id":7412952}]}]}
{"op":"mcm","clk":"1004894631","pt":1580638865149,"mc":[{"id":"1.168209734","rc":[{"trd":[[1.5,0.03]],"batb":[[0,1.5,84]],"ltp":1.5,"tv":89.15,"id":7412952}],"tv":166.72}]}
{"op":"mcm","clk":"1004894763","pt":1580638866860,"mc":[{"id":"1.168209734","rc":[{"batb":[[1,1.01,10.52],[2,1.48,0]],"batl":[[0,1.62,42.01],[1,1.89,150.49],[2,1.62,0]],"ltp":1.5,"tv":89.15,"id":7412952}]}]}
{"op":"mcm","clk":"1004894923","pt":1580638868735,"mc":[{"id":"1.168209734","rc":[{"batb":[[0,1.01,10.52],[1,1.01,0]],"batl":[[0,4.2,332.97],[1,4.2,0]],"ltp":2.12,"tv":77.57,"id":8174357},{"batb":[[0,1.01,10.52],[1,1.01,0]],"batl":[[0,1.89,150.49],[1,1.89,0]],"ltp":1.5,"tv":89.15,"id":7412952}]}]}
{"op":"mcm","clk":"1004894988","pt":1580638869772,"mc":[{"id":"1.168209734","rc":[{"batb":[[0,1.3,345.45],[1,1.29,358.64],[2,1.01,10.51]],"batl":[[0,1.68,120.68],[1,1.7,222.41],[2,1.89,150.49]],"ltp":1.5,"tv":89.15,"id":7412952}]}]}
{"op":"mcm","clk":"1004895074","pt":1580638870868,"mc":[{"id":"1.168209734","rc":[{"batb":[[0,1.01,10.52],[1,1.29,0],[2,1.01,0]],"ltp":1.5,"tv":89.15,"id":7412952}]}]}
{"op":"mcm","clk":"1004895226","pt":1580638872545,"mc":[{"id":"1.168209734","rc":[{"batl":[[2,1.89,0]],"ltp":1.5,"tv":89.15,"id":7412952}]}]}
{"op":"mcm","clk":"1004895334","pt":1580638873866,"mc":[{"id":"1.168209734","rc":[{"batb":[[0,1.62,230.45],[1,1.61,135.01],[2,1.01,10.52]],"ltp":1.5,"tv":89.15,"id":7412952}]}]}
{"op":"mcm","clk":"1004895492","pt":1580638875585,"mc":[{"id":"1.168209734","rc":[{"batb":[[0,2.3,31.93],[1,1.01,10.52]],"batl":[[0,2.62,25.21]],"ltp":2.12,"tv":77.57,"id":8174357},{"batb":[[1,1.61,203.07]],"batl":[[2,1.76,42.01]],"ltp":1.5,"tv":89.15,"id":7412952}]}]}
{"op":"mcm","clk":"1004895579","pt":1580638876681,"mc":[{"id":"1.168209734","rc":[{"batl":[[1,3.45,410.62]],"ltp":2.12,"tv":77.57,"id":8174357}]}]}
{"op":"mcm","clk":"1004895951","pt":1580638880766,"mc":[{"id":"1.168209734","rc":[{"batb":[[2,1.01,10.53]],"ltp":1.5,"tv":89.15,"id":7412952}]}]}
{"op":"mcm","clk":"1004895973","pt":1580638881081,"mc":[{"id":"1.168209734","rc":[{"batb":[[2,1.01,10.52]],"ltp":1.5,"tv":89.15,"id":7412952}]}]}
{"op":"mcm","clk":"1004896228","pt":1580638884190,"mc":[{"id":"1.168209734","rc":[{"batb":[[2,1.01,10.53]],"ltp":1.5,"tv":89.15,"id":7412952}]}]}
{"op":"mcm","clk":"1004896815","pt":1580638891400,"mc":[{"id":"1.168209734","rc":[{"batb":[[0,1.61,68.06],[1,1.01,10.53],[2,1.01,0]],"batl":[[0,1.76,42.01],[1,2.1,117.98],[2,1.76,0]],"ltp":1.5,"tv":89.15,"id":7412952}]}]}
{"op":"mcm","clk":"1004896899","pt":1580638892488,"mc":[{"id":"1.168209734","rc":[{"batb":[[0,1.01,10.52],[1,1.01,0]],"batl":[[0,3.45,410.62],[1,3.45,0]],"ltp":2.12,"tv":77.57,"id":8174357},{"batb":[[0,1.01,10.53],[1,1.01,0]],"batl":[[0,2.1,117.98],[1,2.1,0]],"ltp":1.5,"tv":89.15,"id":7412952}]}]}
{"op":"mcm","clk":"1004897292","pt":1580638897376,"mc":[{"id":"1.168209734","rc":[{"batb":[[0,1.58,126.57],[1,1.57,147.79],[2,1.01,10.53]],"batl":[[0,1.63,150.62],[1,1.64,124.98],[2,2.1,117.98]],"ltp":1.5,"tv":89.15,"id":7412952}]}]}
{"op":"mcm","clk":"1004897608","pt":1580638901799,"mc":[{"id":"1.168209734","rc":[{"batb":[[0,1.01,10.53],[1,1.57,0],[2,1.01,0]],"batl":[[0,2.1,117.98],[1,1.64,0],[2,2.1,0]],"ltp":1.5,"tv":89.15,"id":7412952}]}]}
{"op":"mcm","clk":"1004897840","pt":1580638904698,"mc":[{"id":"1.168209734","rc":[{"batb":[[0,1.41,211.4],[1,1.4,237.5],[2,1.01,10.51]],"batl":[[0,1.85,159.88],[1,1.87,163.4],[2,2.1,117.98]],"ltp":1.5,"tv":89.15,"id":7412952}]}]}
{"op":"mcm","clk":"1004898052","pt":1580638907705,"mc":[{"id":"1.168209734","rc":[{"batb":[[0,1.01,10.53],[1,1.4,0],[2,1.01,0]],"ltp":1.5,"tv":89.15,"id":7412952}]}]}
{"op":"mcm","clk":"1004898122","pt":1580638908718,"mc":[{"id":"1.168209734","rc":[{"batl":[[2,2.1,0]],"ltp":1.5,"tv":89.15,"id":7412952}]}]}
{"op":"mcm","clk":"1004898245","pt":1580638910498,"mc":[{"id":"1.168209734","rc":[{"batb":[[0,1.78,109.85],[1,1.76,196.18],[2,1.01,10.53]],"ltp":1.5,"tv":89.15,"id":7412952}]}]}
{"op":"mcm","clk":"1004898290","pt":1580638911115,"mc":[{"id":"1.168209734","rc":[{"batb":[[0,2.08,38.65],[1,1.01,10.52]],"ltp":2.12,"tv":77.57,"id":8174357},{"batl":[[2,1.92,42.01]],"ltp":1.5,"tv":89.15,"id":7412952}]}]}
{"op":"mcm","clk":"1004898432","pt":1580638912925,"mc":[{"id":"1.168209734","rc":[{"batl":[[0,3,484.06]],"ltp":2.12,"tv":77.57,"id":8174357}]}]}
{"op":"mcm","clk":"1004899213","pt":1580638921915,"mc":[{"id":"1.168209734","rc":[{"batb":[[0,1.01,10.53],[1,1.76,0],[2,1.01,0]],"batl":[[0,1.92,42.01],[1,2.3,94.35],[2,1.92,0]],"ltp":1.5,"tv":89.15,"id":7412952}]}]}
{"op":"mcm","clk":"1004899269","pt":1580638922540,"mc":[{"id":"1.168209734","rc":[{"batb":[[0,1.01,10.52],[1,1.01,0]],"ltp":2.12,"tv":77.57,"id":8174357},{"batl":[[0,2.3,94.35],[1,2.3,0]],"ltp":1.5,"tv":89.15,"id":7412952}]}]}
{"op":"mcm","clk":"1004899509","pt":1580638924904,"mc":[{"id":"1.168209734","rc":[{"batb":[[0,1.61,218.72],[1,1.6,138.11],[2,1.01,10.53]],"batl":[[0,1.96,134.93],[1,1.98,137.47],[2,2.3,94.35]],"ltp":1.5,"tv":89.15,"id":7412952}]}]}
{"op":"mcm","clk":"1004899716","pt":1580638927516,"mc":[{"id":"1.168209734","rc":[{"batb":[[0,1.01,10.53],[1,1.6,0],[2,1.01,0]],"ltp":1.5,"tv":89.15,"id":7412952}]}]}
{"op":"mcm","clk":"1004899928","pt":1580638929911,"mc":[{"id":"1.168209734","rc":[{"batb":[[0,1.88,129.05],[1,1.86,163.97],[2,1.01,10.53]],"ltp":1.5,"tv":89.15,"id":7412952}]}]}
{"op":"mcm","clk":"1004900015","pt":1580638930853,"mc":[{"id":"1.168209734","rc":[{"batb":[[2,1.79,225.93]],"ltp":1.5,"tv":89.15,"id":7412952}]}]}
{"op":"mcm","clk":"1004900088","pt":1580638931623,"mc":[{"id":"1.168209734","rc":[{"batb":[[0,1.93,44.53],[1,1.01,10.52]],"batl":[[0,2.16,36.13]],"ltp":2.12,"tv":77.57,"id":8174357},{"batb":[[1,1.86,212.7]],"batl":[[2,2.06,39.49]],"ltp":1.5,"tv":89.15,"id":7412952}]}]}
{"op":"mcm","clk":"1004900222","pt":1580638933207,"mc":[{"id":"1.168209734","rc":[{"batl":[[1,2.82,521.28]],"ltp":2.12,"tv":77.57,"id":8174357}]}]}
{"op":"mcm","clk":"1004905270","pt":1580638991867,"mc":[{"id":"1.168209734","rc":[{"batb":[[0,1.86,48.73],[1,1.79,225.93],[2,1.01,10.53]],"batl":[[0,2.06,39.49],[1,2.3,94.35],[2,2.06,0]],"ltp":1.5,"tv":89.15,"id":7412952}]}]}
{"op":"mcm","clk":"1004905379","pt":1580638992859,"mc":[{"id":"1.168209734","rc":[{"batl":[[0,2.04,7.57],[1,2.16,36.13],[2,2.82,521.28]],"ltp":2.12,"tv":77.57,"id":8174357}]}]}
{"op":"mcm","clk":"1004905579","pt":1580638994662,"mc":[{"id":"1.168209734","rc":[{"trd":[[2.04,7.57]],"batl":[[0,2.16,36.13],[1,2.82,521.28],[2,2.82,0]],"ltp":2.04,"tv":85.14,"id":8174357},{"trd":[[1.96,7.88]],"batb":[[0,1.87,155.85],[1,1.86,48.73],[2,1.85,166.94]],"batl":[[0,1.95,109.59],[1,1.97,139.66],[2,2.06,39.49]],"ltp":1.96,"tv":97.03,"id":7412952}],"tv":182.17}]}
{"op":"mcm","clk":"1004909093","pt":1580639022697,"mc":[{"id":"1.168209734","rc":[{"batb":[[0,1.86,48.73],[1,1.78,227.16],[2,1.01,10.53]],"batl":[[0,2.06,39.49],[1,2.3,94.35],[2,2.06,0]],"ltp":1.96,"tv":97.03,"id":7412952}]}]}
{"op":"mcm","clk":"1004909378","pt":1580639024867,"mc":[{"id":"1.168209734","rc":[{"batb":[[0,1.01,10.52],[1,1.01,0]],"batl":[[0,2.82,521.28],[1,2.82,0]],"ltp":2.04,"tv":85.14,"id":8174357},{"batb":[[0,1.01,10.53],[1,1.78,0],[2,1.01,0]],"batl":[[0,2.3,94.35],[1,2.3,0]],"ltp":1.96,"tv":97.03,"id":7412952}]}]}
{"op":"mcm","clk":"1004909690","pt":1580639027700,"mc":[{"id":"1.168209734","rc":[{"batb":[[0,1.91,166.07],[1,1.89,156],[2,1.01,10.53]],"batl":[[0,2,143.77],[1,2.02,129.65],[2,2.3,94.35]],"ltp":1.96,"tv":97.03,"id":7412952}]}]}
{"op":"mcm","clk":"1004910066","pt":1580639030417,"mc":[{"id":"1.168209734","rc":[{"batb":[[0,1.01,10.53],[1,1.89,0],[2,1.01,0]],"batl":[[0,2.3,94.35],[1,2.02,0],[2,2.3,0]],"ltp":1.96,"tv":97.03,"id":7412952}]}]}
{"op":"mcm","clk":"1004910468","pt":1580639033778,"mc":[{"id":"1.168209734","rc":[{"batb":[[0,1.78,188.23],[1,1.76,196.59],[2,1.01,10.53]],"batl":[[0,2.2,111.54],[1,2.22,99.05],[2,2.3,94.35]],"ltp":1.96,"tv":97.03,"id":7412952}]}]}
{"op":"mcm","clk":"1004910561","pt":1580639034829,"mc":[{"id":"1.168209734","rc":[{"batl":[[0,2.3,94.35],[1,2.22,0],[2,2.3,0]],"ltp":1.96,"tv":97.03,"id":7412952}]}]}
{"op":"mcm","clk":"1004910899","pt":1580639037883,"mc":[{"id":"1.168209734","rc":[{"batl":[[0,1.86,168.04],[1,1.88,160.85],[2,2.3,94.35]],"ltp":1.96,"tv":97.03,"id":7412952}]}]}
{"op":"mcm","clk":"1004911119","pt":1580639039405,"mc":[{"id":"1.168209734","rc":[{"batb":[[0,2.04,40.33],[1,1.01,10.52]],"batl":[[0,2.28,32.77],[1,2.82,521.28]],"ltp":2.04,"tv":85.14,"id":8174357},{"batb":[[1,1.77,53.77],[2,1.76,196.59]],"batl":[[2,1.97,42.01]],"ltp":1.96,"tv":97.03,"id":7412952}]}]}
{"op":"mcm","clk":"1004912281","pt":1580639049843,"mc":[{"id":"1.168209734","rc":[{"batb":[[0,1.77,53.77],[1,1.01,10.53],[2,1.76,0]],"batl":[[0,1.97,42.01],[1,2.3,94.35],[2,1.97,0]],"ltp":1.96,"tv":97.03,"id":7412952}]}]}
{"op":"mcm","clk":"1004912387","pt":1580639050718,"mc":[{"id":"1.168209734","rc":[{"batb":[[0,1.01,10.52],[1,1.01,0]],"batl":[[0,2.82,521.28],[1,2.82,0]],"ltp":2.04,"tv":85.14,"id":8174357},{"batb":[[0,1.01,10.53],[1,1.01,0]],"batl":[[0,2.3,94.35],[1,2.3,0]],"ltp":1.96,"tv":97.03,"id":7412952}]}]}
{"op":"mcm","clk":"1004912590","pt":1580639052836,"mc":[{"id":"1.168209734","rc":[{"batb":[[0,1.72,207.42],[1,1.7,221.27],[2,1.01,10.53]],"batl":[[0,2.02,137.87],[1,2.04,125.97],[2,2.3,94.35]],"ltp":1.96,"tv":97.03,"id":7412952}]}]}
{"op":"mcm","clk":"1004912690","pt":1580639053825,"mc":[{"id":"1.168209734","rc":[{"batb":[[0,1.01,10.53],[1,1.7,0],[2,1.01,0]],"batl":[[0,2.3,94.35],[1,2.04,0],[2,2.3,0]],"ltp":1.96,"tv":97.03,"id":7412952}]}]}
{"op":"mcm","clk":"1004912771","pt":1580639054615,"mc":[{"id":"1.168209734","rc":[{"batb":[[0,1.81,163.29],[1,1.79,185.8],[2,1.01,10.53]],"batl":[[0,1.89,162.16],[1,1.91,153.24],[2,2.3,94.35]],"ltp":1.96,"tv":97.03,"id":7412952}]}]}
{"op":"mcm","clk":"1004913142","pt":1580639057833,"mc":[{"id":"1.168209734","rc":[{"batb":[[0,1.01,10.53],[1,1.79,0],[2,1.01,0]],"batl":[[0,2.3,94.35],[1,1.91,0],[2,2.3,0]],"ltp":1.96,"tv":97.03,"id":7412952}]}]}
{"op":"mcm","clk":"1004913381","pt":1580639060699,"mc":[{"id":"1.168209734","rc":[{"batb":[[0,1.72,207.42],[1,1.7,221.27],[2,1.01,10.53]],"batl":[[0,2.02,137.87],[1,2.04,125.97],[2,2.3,94.35]],"ltp":1.96,"tv":97.03,"id":7412952}]}]}
{"op":"mcm","clk":"1004914308","pt":1580639070950,"mc":[{"id":"1.168209734","rc":[{"batl":[[0,2.3,94.35],[1,2.04,0],[2,2.3,0]],"ltp":1.96,"tv":97.03,"id":7412952}]}]}
{"op":"mcm","clk":"1004914612","pt":1580639073925,"mc":[{"id":"1.168209734","rc":[{"batl":[[0,1.79,126.68],[1,1.81,181.31],[2,2.3,94.35]],"ltp":1.96,"tv":97.03,"id":7412952}]}]}
{"op":"mcm","clk":"1004914739","pt":1580639075228,"mc":[{"id":"1.168209734","rc":[{"batb":[[0,2.12,36.97],[1,1.01,10.52]],"batl":[[0,2.38,30.25]],"ltp":2.04,"tv":85.14,"id":8174357},{"batb":[[0,1.72,265.39]],"batl":[[2,1.9,42.01]],"ltp":1.96,"tv":97.03,"id":7412952}]}]}
{"op":"mcm","clk":"1004914951","pt":1580639077260,"mc":[{"id":"1.168209734","rc":[{"batl":[[1,3.15,455.72]],"ltp":2.04,"tv":85.14,"id":8174357}]}]}
{"op":"mcm","clk":"1004916418","pt":1580639092940,"mc":[{"id":"1.168209734","rc":[{"batb":[[0,1.72,57.97],[1,1.01,10.53],[2,1.01,0]],"batl":[[0,1.9,42.01],[1,2.3,94.35],[2,1.9,0]],"ltp":1.96,"tv":97.03,"id":7412952}]}]}
{"op":"mcm","clk":"1004916573","pt":1580639094553,"mc":[{"id":"1.168209734","rc":[{"batb":[[0,1.01,10.52],[1,1.01,0]],"batl":[[0,3.15,455.72],[1,3.15,0]],"ltp":2.04,"tv":85.14,"id":8174357},{"batb":[[0,1.01,10.53],[1,1.01,0]],"batl":[[0,2.3,94.35],[1,2.3,0]],"ltp":1.96,"tv":97.03,"id":7412952}]}]}
{"op":"mcm","clk":"1004916708","pt":1580639095745,"mc":[{"id":"1.168209734","rc":[{"batb":[[0,1.69,152.15],[1,1.68,115.85],[2,1.01,10.53]],"batl":[[0,1.89,169.85],[1,1.91,153.2],[2,2.3,94.35]],"ltp":1.96,"tv":97.03,"id":7412952}]}]}
{"op":"mcm","clk":"1004916790","pt":1580639096736,"mc":[{"id":"1.168209734","rc":[{"batl":[[0,2.3,94.35],[1,1.91,0],[2,2.3,0]],"ltp":1.96,"tv":97.03,"id":7412952}]}]}
{"op":"mcm","clk":"1004917082","pt":1580639099754,"mc":[{"id":"1.168209734","rc":[{"batl":[[0,1.75,115.08],[1,1.77,194.89]],"ltp":1.96,"tv":97.03,"id":7412952}]}]}
{"op":"mcm","clk":"1004917282","pt":1580639101949,"mc":[{"id":"1.168209734","rc":[{"batb":[[0,2.16,36.13],[1,1.01,10.52]],"batl":[[0,2.46,28.57],[1,3.15,455.72]],"ltp":2.04,"tv":85.14,"id":8174357},{"batb":[[0,1.69,212.64]],"batl":[[2,1.86,42.01]],"ltp":1.96,"tv":97.03,"id":7412952}]}]}
{"op":"mcm","clk":"1004918411","pt":1580639113877,"mc":[{"id":"1.168209734","rc":[{"batb":[[0,1.69,60.49],[1,1.01,10.53],[2,1.01,0]],"batl":[[0,1.86,42.01],[1,2.16,111.53],[2,1.86,0]],"ltp":1.96,"tv":97.03,"id":7412952}]}]}
{"op":"mcm","clk":"1004918481","pt":1580639114669,"mc":[{"id":"1.168209734","rc":[{"batb":[[0,1.01,10.52],[1,1.01,0]],"batl":[[0,3.15,455.72],[1,3.15,0]],"ltp":2.04,"tv":85.14,"id":8174357},{"batb":[[0,1.01,10.53],[1,1.01,0]],"batl":[[0,2.16,111.53],[1,2.16,0]],"ltp":1.96,"tv":97.03,"id":7412952}]}]}
{"op":"mcm","clk":"1004918812","pt":1580639118498,"mc":[{"id":"1.168209734","rc":[{"batb":[[0,1.7,139.58],[1,1.68,230.24],[2,1.01,10.53]],"batl":[[0,1.76,117.02],[1,1.78,191.34],[2,2.16,111.53]],"ltp":1.96,"tv":97.03,"id":7412952}]}]}
{"op":"mcm","clk":"1004919103","pt":1580639121585,"mc":[{"id":"1.168209734","rc":[{"batb":[[0,1.01,10.53],[1,1.68,0],[2,1.01,0]],"batl":[[0,2.16,111.53],[1,1.78,0],[2,2.16,0]],"ltp":1.96,"tv":97.03,"id":7412952}]}]}
{"op":"mcm","clk":"1004919409","pt":1580639124819,"mc":[{"id":"1.168209734","rc":[{"batb":[[0,1.67,177.14],[1,1.66,120.92],[2,1.01,10.53]],"batl":[[0,1.8,112.68],[1,1.82,178.17],[2,2.16,111.53]],"ltp":1.96,"tv":97.03,"id":7412952}]}]}
{"op":"mcm","clk":"1004919829","pt":1580639128899,"mc":[{"id":"1.168209734","rc":[{"batl":[[0,2.16,111.53],[1,1.82,0],[2,2.16,0]],"ltp":1.96,"tv":97.03,"id":7412952}]}]}
{"op":"mcm","clk":"1004920175","pt":1580639131811,"mc":[{"id":"1.168209734","rc":[{"batl":[[0,1.73,112.47],[1,1.75,202.31],[2,2.16,111.53]],"ltp":1.96,"tv":97.03,"id":7412952}]}]}
{"op":"mcm","clk":"1004920338","pt":1580639133323,"mc":[{"id":"1.168209734","rc":[{"batb":[[0,2.2,34.45],[1,1.01,10.52]],"batl":[[0,2.5,27.73],[1,3.15,455.72]],"ltp":2.04,"tv":85.14,"id":8174357},{"batb":[[1,1.66,183.93]],"batl":[[2,1.83,42.01]],"ltp":1.96,"tv":97.03,"id":7412952}]}]}
{"op":"mcm","clk":"1004923099","pt":1580639159946,"mc":[{"id":"1.168209734","rc":[{"batb":[[0,1.66,63.01],[1,1.01,10.53],[2,1.01,0]],"batl":[[0,1.83,42.01],[1,2.16,111.53],[2,1.83,0]],"ltp":1.96,"tv":97.03,"id":7412952}]}]}
{"op":"mcm","clk":"1004923138","pt":1580639160354,"mc":[{"id":"1.168209734","rc":[{"batb":[[0,1.01,10.52],[1,1.01,0]],"batl":[[0,3.15,455.72],[1,3.15,0]],"ltp":2.04,"tv":85.14,"id":8174357},{"batb":[[0,1.01,10.53],[1,1.01,0]],"batl":[[0,2.16,111.53],[1,2.16,0]],"ltp":1.96,"tv":97.03,"id":7412952}]}]}
{"op":"mcm","clk":"1004923368","pt":1580639162364,"mc":[{"id":"1.168209734","rc":[{"batb":[[0,1.52,246.35],[1,1.51,172.93],[2,1.01,10.53]],"batl":[[0,1.84,185.72],[1,1.86,166.27],[2,2.16,111.53]],"ltp":1.96,"tv":97.03,"id":7412952}]}]}
{"op":"mcm","clk":"1004924116","pt":1580639168949,"mc":[{"id":"1.168209734","rc":[{"batl":[[0,2.16,111.53],[1,1.86,0],[2,2.16,0]],"ltp":1.96,"tv":97.03,"id":7412952}]}]}
{"op":"mcm","clk":"1004924439","pt":1580639171950,"mc":[{"id":"1.168209734","rc":[{"batl":[[0,1.57,124.55],[1,1.58,143.24]],"ltp":1.96,"tv":97.03,"id":7412952}]}]}
{"op":"mcm","clk":"1004924637","pt":1580639173641,"mc":[{"id":"1.168209734","rc":[{"batb":[[0,2.5,27.73],[1,1.01,10.52]],"batl":[[0,2.9,21.85]],"ltp":2.04,"tv":85.14,"id":8174357},{"batb":[[0,1.53,78.98],[1,1.52,246.35],[2,1.51,172.93]],"batl":[[2,1.66,42.01]],"ltp":1.96,"tv":97.03,"id":7412952}]}]}
{"op":"mcm","clk":"1004924850","pt":1580639175634,"mc":[{"id":"1.168209734","rc":[{"batl":[[1,3.9,361.35]],"ltp":2.04,"tv":85.14,"id":8174357}]}]}
{"op":"mcm","clk":"1004928207","pt":1580639206615,"mc":[{"id":"1.168209734","rc":[{"batb":[[1,1.01,10.53],[2,1.51,0]],"batl":[[0,1.66,42.01],[1,1.95,145.32],[2,1.66,0]],"ltp":1.96,"tv":97.03,"id":7412952}]}]}
{"op":"mcm","clk":"1004928398","pt":1580639208408,"mc":[{"id":"1.168209734","rc":[{"batb":[[0,1.01,10.52],[1,1.01,0]],"batl":[[0,3.9,361.35],[1,3.9,0]],"ltp":2.04,"tv":85.14,"id":8174357},{"batb":[[0,1.01,10.53],[1,1.01,0]],"batl":[[0,1.95,145.32],[1,1.95,0]],"ltp":1.96,"tv":97.03,"id":7412952}]}]}
{"op":"mcm","clk":"1004928523","pt":1580639209579,"mc":[{"id":"1.168209734","rc":[{"batb":[[0,1.36,155.49],[1,1.35,281.71],[2,1.01,10.51]],"batl":[[0,1.7,210.38],[1,1.72,213.71],[2,1.95,145.32]],"ltp":1.96,"tv":97.03,"id":7412952}]}]}
{"op":"mcm","clk":"1004932187","pt":1580639240559,"mc":[{"id":"1.168209734","rc":[{"batb":[[0,1.01,10.53],[1,1.35,0],[2,1.01,0]],"ltp":1.96,"tv":97.03,"id":7412952}]}]}
{"op":"mcm","clk":"1004932659","pt":1580639243818,"mc":[{"id":"1.168209734","rc":[{"batb":[[0,2.28,32.77],[1,1.01,10.52]],"batl":[[0,2.58,26.05]],"ltp":2.04,"tv":85.14,"id":8174357},{"batb":[[0,1.63,306.26],[1,1.62,132.24],[2,1.01,10.53]],"ltp":1.96,"tv":97.03,"id":7412952}]}]}
{"op":"mcm","clk":"1004933030","pt":1580639246831,"mc":[{"id":"1.168209734","rc":[{"batl":[[1,3.45,410.62]],"ltp":2.04,"tv":85.14,"id":8174357},{"batl":[[2,1.78,42.01]],"ltp":1.96,"tv":97.03,"id":7412952}]}]}
{"op":"mcm","clk":"1004934750","pt":1580639263352,"mc":[{"id":"1.168209734","rc":[{"batb":[[0,1.63,66.38],[1,1.01,10.53],[2,1.01,0]],"batl":[[0,1.78,42.01],[1,1.95,145.32],[2,1.78,0]],"ltp":1.96,"tv":97.03,"id":7412952}]}]}
{"op":"mcm","clk":"1004934875","pt":1580639264655,"mc":[{"id":"1.168209734","rc":[{"batb":[[0,1.01,10.52],[1,1.01,0]],"batl":[[0,3.45,410.62],[1,3.45,0]],"ltp":2.04,"tv":85.14,"id":8174357},{"batb":[[0,1.01,10.53],[1,1.01,0]],"batl":[[0,1.95,145.32],[1,1.95,0]],"ltp":1.96,"tv":97.03,"id":7412952}]}]}
{"op":"mcm","clk":"1004934991","pt":1580639265954,"mc":[{"id":"1.168209734","rc":[{"batb":[[0,1.46,240.03],[1,1.45,204.35],[2,1.01,10.51]],"batl":[[0,1.82,149.37],[1,1.84,172.11],[2,1.95,145.32]],"ltp":1.96,"tv":97.03,"id":7412952}]}]}
{"op":"mcm","clk":"1004935491","pt":1580639270760,"mc":[{"id":"1.168209734","rc":[{"batb":[[0,1.01,10.53],[1,1.45,0],[2,1.01,0]],"ltp":1.96,"tv":97.03,"id":7412952}]}]}
{"op":"mcm","clk":"1004935605","pt":1580639271963,"mc":[{"id":"1.168209734","rc":[{"batl":[[2,1.95,0]],"ltp":1.96,"tv":97.03,"id":7412952}]}]}
{"op":"mcm","clk":"1004935802","pt":1580639273862,"mc":[{"id":"1.168209734","rc":[{"batl":[[0,2.42,5]],"ltp":2.04,"tv":85.14,"id":8174357},{"batb":[[0,1.75,151.16],[1,1.73,208.26],[2,1.01,10.53]],"ltp":1.96,"tv":97.03,"id":7412952}]}]}
{"op":"mcm","clk":"1004936003","pt":1580639275897,"mc":[{"id":"1.168209734","rc":[{"batb":[[0,2.08,38.65],[1,1.01,10.52]],"ltp":2.04,"tv":85.14,"id":8174357},{"batl":[[2,1.91,42.01]],"ltp":1.96,"tv":97.03,"id":7412952}]}]}
{"op":"mcm","clk":"1004936023","pt":1580639276062,"mc":[{"id":"1.168209734","rc":[{"batl":[[1,3.15,455.72]],"ltp":2.04,"tv":85.14,"id":8174357}]}]}
{"op":"mcm","clk":"1004936297","pt":1580639278890,"mc":[{"id":"1.168209734","rc":[{"batl":[[0,3.15,455.72],[1,3.15,0]],"ltp":2.04,"tv":85.14,"id":8174357}]}]}
{"op":"mcm","clk":"1004936648","pt":1580639281881,"mc":[{"id":"1.168209734","rc":[{"batb":[[0,1.01,10.53],[1,1.73,0],[2,1.01,0]],"batl":[[0,1.91,42.01],[1,2.22,102.71],[2,1.91,0]],"ltp":1.96,"tv":97.03,"id":7412952}]}]}
{"op":"mcm","clk":"1004936704","pt":1580639282399,"mc":[{"id":"1.168209734","rc":[{"batb":[[0,1.01,10.52],[1,1.01,0]],"ltp":2.04,"tv":85.14,"id":8174357},{"batl":[[0,2.22,102.71],[1,2.22,0]],"ltp":1.96,"tv":97.03,"id":7412952}]}]}
{"op":"mcm","clk":"1004936938","pt":1580639284814,"mc":[{"id":"1.168209734","rc":[{"batb":[[0,1.6,162.56],[1,1.59,141.37],[2,1.01,10.53]],"batl":[[0,1.92,125.65],[1,1.94,146.3],[2,2.22,102.71]],"ltp":1.96,"tv":97.03,"id":7412952}]}]}
{"op":"mcm","clk":"1004937087","pt":1580639286523,"mc":[{"id":"1.168209734","rc":[{"batl":[[0,2.2,5],[1,3.15,455.72]],"ltp":2.04,"tv":85.14,"id":8174357}]}]}
{"op":"mcm","clk":"1004937231","pt":1580639287797,"mc":[{"id":"1.168209734","rc":[{"batl":[[0,3.15,455.72],[1,3.15,0]],"ltp":2.04,"tv":85.14,"id":8174357}]}]}
{"op":"mcm","clk":"1004937347","pt":1580639288829,"mc":[{"id":"1.168209734","rc":[{"batb":[[0,1.01,10.53],[1,1.59,0],[2,1.01,0]],"ltp":1.96,"tv":97.03,"id":7412952}]}]}
{"op":"mcm","clk":"1004937641","pt":1580639291636,"mc":[{"id":"1.168209734","rc":[{"batb":[[0,1.84,173.58],[1,1.82,176.09],[2,1.01,10.53]],"ltp":1.96,"tv":97.03,"id":7412952}]}]}
{"op":"mcm","clk":"1004937833","pt":1580639293729,"mc":[{"id":"1.168209734","rc":[{"batb":[[0,1.97,42.85],[1,1.01,10.52]],"ltp":2.04,"tv":85.14,"id":8174357},{"batl":[[2,2.02,41.17]],"ltp":1.96,"tv":97.03,"id":7412952}]}]}
{"op":"mcm","clk":"1004937926","pt":1580639294727,"mc":[{"id":"1.168209734","rc":[{"batl":[[0,2.2,34.45],[1,2.92,502.2]],"ltp":2.04,"tv":85.14,"id":8174357},{"batb":[[1,1.83,50.41],[2,1.82,176.09]],"ltp":1.96,"tv":97.03,"id":7412952}]}]}
{"op":"mcm","clk":"1004938662","pt":1580639302015,"mc":[{"id":"1.168209734","rc":[{"trd":[[2.08,5]],"ltp":2.08,"tv":90.14,"id":8174357},{"trd":[[1.92,5.42]],"batl":[[0,1.92,120.23]],"ltp":1.92,"tv":102.45,"id":7412952}],"tv":192.59}]}
{"op":"mcm","clk":"1004939031","pt":1580639305933,"mc":[{"id":"1.168209734","rc":[{"batb":[[0,1.83,50.41],[1,1.01,10.53],[2,1.82,0]],"batl":[[0,2.02,41.17],[1,2.22,102.71],[2,2.02,0]],"ltp":1.92,"tv":102.45,"id":7412952}]}]}
{"op":"mcm","clk":"1004939082","pt":1580639306434,"mc":[{"id":"1.168209734","rc":[{"batb":[[0,1.01,10.52],[1,1.01,0]],"batl":[[0,2.92,502.2],[1,2.92,0]],"ltp":2.08,"tv":90.14,"id":8174357},{"batb":[[0,1.01,10.53],[1,1.01,0]],"batl":[[0,2.22,102.71],[1,2.22,0]],"ltp":1.92,"tv":102.45,"id":7412952}]}]}
{"op":"mcm","clk":"1004939327","pt":1580639308849,"mc":[{"id":"1.168209734","rc":[{"batb":[[0,1.75,210.97],[1,1.73,208.52],[2,1.01,10.53]],"batl":[[0,1.97,101.02],[1,1.99,135.58],[2,2.22,102.71]],"ltp":1.92,"tv":102.45,"id":7412952}]}]}
{"op":"mcm","clk":"1004939416","pt":1580639309637,"mc":[{"id":"1.168209734","rc":[{"batb":[[0,1.01,10.53],[1,1.73,0],[2,1.01,0]],"batl":[[0,2.22,102.71],[1,1.99,0],[2,2.22,0]],"ltp":1.92,"tv":102.45,"id":7412952}]}]}
{"op":"mcm","clk":"1004939660","pt":1580639311861,"mc":[{"id":"1.168209734","rc":[{"batb":[[0,1.82,193.83],[1,1.8,182.59],[2,1.01,10.53]],"batl":[[0,1.9,124.18],[1,1.92,150.97],[2,2.22,102.71]],"ltp":1.92,"tv":102.45,"id":7412952}]}]}
{"op":"mcm","clk":"1004940281","pt":1580639317850,"mc":[{"id":"1.168209734","rc":[{"batb":[[0,1.01,10.53],[1,1.8,0],[2,1.01,0]],"batl":[[0,2.22,102.71],[1,1.92,0],[2,2.22,0]],"ltp":1.92,"tv":102.45,"id":7412952}]}]}
{"op":"mcm","clk":"1004940586","pt":1580639320777,"mc":[{"id":"1.168209734","rc":[{"batb":[[0,1.75,210.97],[1,1.73,208.52],[2,1.01,10.53]],"batl":[[0,1.97,101.02],[1,1.99,135.58],[2,2.22,102.71]],"ltp":1.92,"tv":102.45,"id":7412952}]}]}
{"op":"mcm","clk":"1004941148","pt":1580639326888,"mc":[{"id":"1.168209734","rc":[{"batb":[[0,1.01,10.53],[1,1.73,0],[2,1.01,0]],"ltp":1.92,"tv":102.45,"id":7412952}]}]}
{"op":"mcm","clk":"1004941447","pt":1580639329885,"mc":[{"id":"1.168209734","rc":[{"batb":[[0,1.89,157.13],[1,1.87,161.39],[2,1.79,225.93]],"ltp":1.92,"tv":102.45,"id":7412952}]}]}
{"op":"mcm","clk":"1004941619","pt":1580639331708,"mc":[{"id":"1.168209734","rc":[{"batb":[[0,1.9,46.21],[1,1.01,10.52]],"batl":[[0,2.12,36.97],[1,2.92,502.2]],"ltp":2.08,"tv":90.14,"id":8174357},{"batb":[[0,1.89,204.18],[2,1.01,10.53]],"batl":[[2,2.1,37.81]],"ltp":1.92,"tv":102.45,"id":7412952}]}]}
{"op":"mcm","clk":"1004942891","pt":1580639343872,"mc":[{"id":"1.168209734","rc":[{"trd":[[1.89,33.6]],"batb":[[0,1.89,187.38]],"ltp":1.89,"tv":136.05,"id":7412952}],"tv":226.2}]}
{"op":"mcm","clk":"1004950318","pt":1580639415795,"mc":[{"id":"1.168209734","rc":[{"batb":[[0,1.89,47.05],[1,1.01,10.53],[2,1.01,0]],"batl":[[0,2.1,37.81],[1,2.22,102.71],[2,2.1,0]],"ltp":1.89,"tv":136.05,"id":7412952}]}]}
{"op":"mcm","clk":"1004950402","pt":1580639416482,"mc":[{"id":"1.168209734","rc":[{"batb":[[0,1.01,10.52],[1,1.01,0]],"batl":[[0,2.92,502.2],[1,2.92,0]],"ltp":2.08,"tv":90.14,"id":8174357},{"batb":[[0,1.01,10.53],[1,1.01,0]],"batl":[[0,2.22,102.71],[1,2.22,0]],"ltp":1.89,"tv":136.05,"id":7412952}]}]}
{"op":"mcm","clk":"1004950625","pt":1580639418865,"mc":[{"id":"1.168209734","rc":[{"batb":[[0,1.8,119.36],[1,1.78,189.26],[2,1.01,10.53]],"batl":[[1,2.26,179.08],[2,2.28,92.15]],"ltp":1.89,"tv":136.05,"id":7412952}]}]}
{"op":"mcm","clk":"1004951542","pt":1580639428776,"mc":[{"id":"1.168209734","rc":[{"batl":[[1,2.26,0],[2,2.28,0]],"ltp":1.89,"tv":136.05,"id":7412952}]}]}
{"op":"mcm","clk":"1004951847","pt":1580639431910,"mc":[{"id":"1.168209734","rc":[{"batl":[[0,1.87,134.38],[1,1.89,158.43],[2,2.22,102.71]],"ltp":1.89,"tv":136.05,"id":7412952}]}]}
{"op":"mcm","clk":"1004952015","pt":1580639433587,"mc":[{"id":"1.168209734","rc":[{"batb":[[0,2,42.01],[1,1.01,10.52]],"batl":[[0,2.24,33.61],[1,2.92,502.2]],"ltp":2.08,"tv":90.14,"id":8174357},{"batb":[[0,1.8,171.45]],"batl":[[2,2,42.01]],"ltp":1.89,"tv":136.05,"id":7412952}]}]}
{"op":"mcm","clk":"1004953576","pt":1580639449928,"mc":[{"id":"1.168209734","rc":[{"batb":[[0,1.8,52.09],[1,1.01,10.53],[2,1.01,0]],"batl":[[0,2,42.01],[1,2.22,102.71],[2,2,0]],"ltp":1.89,"tv":136.05,"id":7412952}]}]}
{"op":"mcm","clk":"1004953635","pt":1580639450553,"mc":[{"id":"1.168209734","rc":[{"batb":[[0,1.01,10.52],[1,1.01,0]],"batl":[[0,2.92,502.2],[1,2.92,0]],"ltp":2.08,"tv":90.14,"id":8174357},{"batb":[[0,1.01,10.53],[1,1.01,0]],"batl":[[0,2.22,102.71],[1,2.22,0]],"ltp":1.89,"tv":136.05,"id":7412952}]}]}
{"op":"mcm","clk":"1004953851","pt":1580639452435,"mc":[{"id":"1.168209734","rc":[{"batb":[[0,1.73,212.8],[1,1.71,217.02],[2,1.01,10.53]],"batl":[[0,2.04,97.91],[1,2.06,122.51],[2,2.22,102.71]],"ltp":1.89,"tv":136.05,"id":7412952}]}]}
{"op":"mcm","clk":"1004953956","pt":1580639453537,"mc":[{"id":"1.168209734","rc":[{"batb":[[0,1.01,10.53],[1,1.71,0],[2,1.01,0]],"batl":[[0,2.22,102.71],[1,2.06,0],[2,2.22,0]],"ltp":1.89,"tv":136.05,"id":7412952}]}]}
{"op":"mcm","clk":"1004954288","pt":1580639456731,"mc":[{"id":"1.168209734","rc":[{"batb":[[0,1.83,115.83],[1,1.81,179.16],[2,1.01,10.53]],"batl":[[0,1.9,113.66],[1,1.92,151.01],[2,2.22,102.71]],"ltp":1.89,"tv":136.05,"id":7412952}]}]}
{"op":"mcm","clk":"1004954605","pt":1580639459764,"mc":[{"id":"1.168209734","rc":[{"batb":[[0,1.01,10.53],[1,1.81,0],[2,1.01,0]],"batl":[[0,2.22,102.71],[1,1.92,0],[2,2.22,0]],"ltp":1.89,"tv":136.05,"id":7412952}]}]}
{"op":"mcm","clk":"1004954927","pt":1580639462557,"mc":[{"id":"1.168209734","rc":[{"batb":[[0,1.73,212.8],[1,1.71,217.02],[2,1.01,10.53]],"batl":[[0,2.04,97.91],[1,2.06,122.51],[2,2.22,102.71]],"ltp":1.89,"tv":136.05,"id":7412952}]}]}
{"op":"mcm","clk":"1004955075","pt":1580639463864,"mc":[{"id":"1.168209734","rc":[{"batb":[[0,1.01,10.53],[1,1.71,0],[2,1.01,0]],"ltp":1.89,"tv":136.05,"id":7412952}]}]}
{"op":"mcm","clk":"1004955389","pt":1580639466953,"mc":[{"id":"1.168209734","rc":[{"batb":[[0,1.96,110.57],[1,1.94,143.83],[2,1.01,10.53]],"batl":[[2,2.22,0]],"ltp":1.89,"tv":136.05,"id":7412952}]}]}
{"op":"mcm","clk":"1004955501","pt":1580639467945,"mc":[{"id":"1.168209734","rc":[{"batb":[[0,1.86,48.73],[1,1.01,10.52]],"batl":[[0,2.06,39.49]],"ltp":2.08,"tv":90.14,"id":8174357},{"batb":[[2,1.93,44.53]],"batl":[[2,2.16,36.13]],"ltp":1.89,"tv":136.05,"id":7412952}]}]}
{"op":"mcm","clk":"1004955663","pt":1580639469784,"mc":[{"id":"1.168209734","rc":[{"batl":[[1,2.72,544.53]],"ltp":2.08,"tv":90.14,"id":8174357}]}]}
{"op":"mcm","clk":"1004956729","pt":1580639480624,"mc":[{"id":"1.168209734","rc":[{"batb":[[0,1.93,44.53],[1,1.01,10.53],[2,1.93,0]],"batl":[[0,2.16,36.13],[1,2.5,81.68],[2,2.16,0]],"ltp":1.89,"tv":136.05,"id":7412952}]}]}
{"op":"mcm","clk":"1004956933","pt":1580639482616,"mc":[{"id":"1.168209734","rc":[{"batb":[[0,1.01,10.52],[1,1.01,0]],"batl":[[0,2.72,544.53],[1,2.72,0]],"ltp":2.08,"tv":90.14,"id":8174357},{"batb":[[0,1.01,10.53],[1,1.01,0]],"batl":[[0,2.5,81.68],[1,2.5,0]],"ltp":1.89,"tv":136.05,"id":7412952}]}]}
{"op":"mcm","clk":"1004957008","pt":1580639483506,"mc":[{"id":"1.168209734","rc":[{"batb":[[0,1.82,186.58],[1,1.8,182.58],[2,1.01,10.53]],"batl":[[0,2.46,133.12],[1,2.5,226.74]],"ltp":1.89,"tv":136.05,"id":7412952}]}]}
{"op":"mcm","clk":"1004958260","pt":1580639496514,"mc":[{"id":"1.168209734","rc":[{"batl":[[0,2.5,81.68],[1,2.5,0]],"ltp":1.89,"tv":136.05,"id":7412952}]}]}
{"op":"mcm","clk":"1004958563","pt":1580639499814,"mc":[{"id":"1.168209734","rc":[{"batl":[[0,1.9,131.06],[1,1.92,150.96]],"ltp":1.89,"tv":136.05,"id":7412952}]}]}
{"op":"mcm","clk":"1004958767","pt":1580639501947,"mc":[{"id":"1.168209734","rc":[{"batb":[[0,1.98,42.85],[1,1.01,10.52]],"batl":[[0,2.24,33.61],[1,2.72,544.53]],"ltp":2.08,"tv":90.14,"id":8174357},{"batb":[[0,1.82,236.99]],"batl":[[2,2.02,41.17]],"ltp":1.89,"tv":136.05,"id":7412952}]}]}
{"op":"mcm","clk":"1004960721","pt":1580639519953,"mc":[{"id":"1.168209734","rc":[{"batb":[[0,1.82,50.41],[1,1.01,10.53],[2,1.01,0]],"batl":[[0,2.02,41.17],[1,2.36,91.76],[2,2.02,0]],"ltp":1.89,"tv":136.05,"id":7412952}]}]}
{"op":"mcm","clk":"1004960822","pt":1580639520882,"mc":[{"id":"1.168209734","rc":[{"batb":[[0,1.01,10.52],[1,1.01,0]],"batl":[[0,2.72,544.53],[1,2.72,0]],"ltp":2.08,"tv":90.14,"id":8174357},{"batb":[[0,1.01,10.53],[1,1.01,0]],"batl":[[0,2.36,91.76],[1,2.36,0]],"ltp":1.89,"tv":136.05,"id":7412952}]}]}
{"op":"mcm","clk":"1004960977","pt":1580639522379,"mc":[{"id":"1.168209734","rc":[{"batb":[[0,1.74,200.3],[1,1.72,212.64],[2,1.01,10.53]],"batl":[[0,2.14,175.18],[1,2.16,107.02],[2,2.36,91.76]],"ltp":1.89,"tv":136.05,"id":7412952}]}]}
{"op":"mcm","clk":"1004961237","pt":1580639524946,"mc":[{"id":"1.168209734","rc":[{"batl":[[0,2.36,91.76],[1,2.16,0],[2,2.36,0]],"ltp":1.89,"tv":136.05,"id":7412952}]}]}
{"op":"mcm","clk":"1004961504","pt":1580639527880,"mc":[{"id":"1.168209734","rc":[{"batl":[[0,1.81,112.76],[1,1.83,175.24]],"ltp":1.89,"tv":136.05,"id":7412952}]}]}
{"op":"mcm","clk":"1004961744","pt":1580639529589,"mc":[{"id":"1.168209734","rc":[{"batb":[[0,2.1,37.81],[1,1.01,10.52]],"batl":[[0,2.36,30.25]],"ltp":2.08,"tv":90.14,"id":8174357},{"batb":[[1,1.73,57.13],[2,1.72,212.64]],"batl":[[2,1.92,42.01]],"ltp":1.89,"tv":136.05,"id":7412952}]}]}
{"op":"mcm","clk":"1004961894","pt":1580639530382,"mc":[{"id":"1.168209734","rc":[{"batl":[[1,3.15,455.72]],"ltp":2.08,"tv":90.14,"id":8174357}]}]}
{"op":"mcm","clk":"1004962844","pt":1580639539379,"mc":[{"id":"1.168209734","rc":[{"batb":[[0,1.73,57.13],[1,1.01,10.53],[2,1.72,0]],"batl":[[0,1.92,42.01],[1,2.22,102.71],[2,1.92,0]],"ltp":1.89,"tv":136.05,"id":7412952}]}]}
{"op":"mcm","clk":"1004962984","pt":1580639540871,"mc":[{"id":"1.168209734","rc":[{"batb":[[0,1.01,10.52],[1,1.01,0]],"batl":[[0,3.15,455.72],[1,3.15,0]],"ltp":2.08,"tv":90.14,"id":8174357},{"batb":[[0,1.01,10.53],[1,1.01,0]],"batl":[[0,2.22,102.71],[1,2.22,0]],"ltp":1.89,"tv":136.05,"id":7412952}]}]}
{"op":"mcm","clk":"1004963170","pt":1580639542800,"mc":[{"id":"1.168209734","rc":[{"batb":[[0,1.71,168.03],[1,1.69,225.79],[2,1.01,10.53]],"batl":[[0,1.91,155.33],[1,1.93,148.53],[2,2.22,102.71]],"ltp":1.89,"tv":136.05,"id":7412952}]}]}
{"op":"mcm","clk":"1004963200","pt":1580639543068,"mc":[{"id":"1.168209734","rc":[{"batb":[[0,1.01,10.53],[1,1.69,0],[2,1.01,0]],"batl":[[0,2.22,102.71],[1,1.93,0],[2,2.22,0]],"ltp":1.89,"tv":136.05,"id":7412952}]}]}
{"op":"mcm","clk":"1004963519","pt":1580639546277,"mc":[{"id":"1.168209734","rc":[{"batb":[[0,1.76,162.51],[1,1.74,204.3],[2,1.01,10.53]],"batl":[[0,1.83,128.95],[1,1.85,169.29],[2,2.22,102.71]],"ltp":1.89,"tv":136.05,"id":7412952}]}]}
{"op":"mcm","clk":"1004963855","pt":1580639549985,"mc":[{"id":"1.168209734","rc":[{"batb":[[0,1.01,10.53],[1,1.74,0],[2,1.01,0]],"batl":[[0,2.22,102.71],[1,1.85,0],[2,2.22,0]],"ltp":1.89,"tv":136.05,"id":7412952}]}]}
{"op":"mcm","clk":"1004964158","pt":1580639553000,"mc":[{"id":"1.168209734","rc":[{"batb":[[0,1.71,168.03],[1,1.69,225.79],[2,1.01,10.53]],"batl":[[0,1.91,155.33],[1,1.93,148.53],[2,2.22,102.71]],"ltp":1.89,"tv":136.05,"id":7412952}]}]}
{"op":"mcm","clk":"1004964667","pt":1580639556880,"mc":[{"id":"1.168209734","rc":[{"batl":[[0,2.22,102.71],[1,1.93,0],[2,2.22,0]],"ltp":1.89,"tv":136.05,"id":7412952}]}]}
{"op":"mcm","clk":"1004965008","pt":1580639559682,"mc":[{"id":"1.168209734","rc":[{"batl":[[0,1.78,175.43],[1,1.8,184.49],[2,2.22,102.71]],"ltp":1.89,"tv":136.05,"id":7412952}]}]}
{"op":"mcm","clk":"1004965321","pt":1580639561581,"mc":[{"id":"1.168209734","rc":[{"batb":[[0,2.16,36.13],[1,1.01,10.52]],"batl":[[0,2.44,28.57],[1,3.15,455.72]],"ltp":2.08,"tv":90.14,"id":8174357},{"batb":[[1,1.69,286.28]],"batl":[[2,1.87,42.01]],"ltp":1.89,"tv":136.05,"id":7412952}]}]}
{"op":"mcm","clk":"1004968756","pt":1580639596663,"mc":[{"id":"1.168209734","rc":[{"batb":[[0,1.69,60.49],[1,1.01,10.53],[2,1.01,0]],"batl":[[0,1.87,42.01],[1,2.22,102.71],[2,1.87,0]],"ltp":1.89,"tv":136.05,"id":7412952}]}]}
{"op":"mcm","clk":"1004969081","pt":1580639599957,"mc":[{"id":"1.168209734","rc":[{"batb":[[0,2.18,447.47],[1,2.16,36.13],[2,1.01,10.52]],"ltp":2.08,"tv":90.14,"id":8174357},{"batb":[[1,1.54,236.32],[2,1.53,164.24]],"batl":[[1,1.89,144.75],[2,1.91,153.42]],"ltp":1.89,"tv":136.05,"id":7412952}]}]}
{"op":"mcm","clk":"1004969632","pt":1580639605595,"mc":[{"id":"1.168209734","rc":[{"batb":[[0,2.16,36.13],[1,1.01,10.52],[2,1.01,0]],"ltp":2.08,"tv":90.14,"id":8174357}]}]}
{"op":"mcm","clk":"1004969730","pt":1580639606696,"mc":[{"id":"1.168209734","rc":[{"batb":[[0,1.01,10.52],[1,1.01,0]],"batl":[[0,3.15,455.72],[1,3.15,0]],"ltp":2.08,"tv":90.14,"id":8174357},{"batb":[[0,1.54,236.32],[1,1.53,164.24],[2,1.01,10.53]],"batl":[[0,1.89,144.75],[1,1.91,153.42],[2,2.22,102.71]],"ltp":1.89,"tv":136.05,"id":7412952}]}]}
{"op":"mcm","clk":"1004970182","pt":1580639611794,"mc":[{"id":"1.168209734","rc":[{"batl":[[0,2.22,102.71],[1,1.91,0],[2,2.22,0]],"ltp":1.89,"tv":136.05,"id":7412952}]}]}
{"op":"mcm","clk":"1004970460","pt":1580639614870,"mc":[{"id":"1.168209734","rc":[{"batl":[[0,1.6,239.84],[1,1.61,133.4]],"ltp":1.89,"tv":136.05,"id":7412952}]}]}
{"op":"mcm","clk":"1004970534","pt":1580639615907,"mc":[{"id":"1.168209734","rc":[{"batl":[[0,2.84,22.69]],"ltp":2.08,"tv":90.14,"id":8174357},{"batb":[[0,1.54,313.62]],"batl":[[2,1.68,42.01]],"ltp":1.89,"tv":136.05,"id":7412952}]}]}
{"op":"mcm","clk":"1004970642","pt":1580639617073,"mc":[{"id":"1.168209734","rc":[{"batl":[[1,3.9,358.88]],"ltp":2.08,"tv":90.14,"id":8174357}]}]}
{"op":"mcm","clk":"1004970796","pt":1580639618692,"mc":[{"id":"1.168209734","rc":[{"batb":[[0,2.48,27.73],[1,1.01,10.52]],"ltp":2.08,"tv":90.14,"id":8174357}]}]}
{"op":"mcm","clk":"1004971635","pt":1580639627915,"mc":[{"id":"1.168209734","rc":[{"batb":[[0,1.54,77.3],[1,1.01,10.53],[2,1.01,0]],"batl":[[0,1.68,42.01],[1,1.95,140.42],[2,1.68,0]],"ltp":1.89,"tv":136.05,"id":7412952}]}]}
{"op":"mcm","clk":"1004971693","pt":1580639628701,"mc":[{"id":"1.168209734","rc":[{"batb":[[0,1.01,10.52],[1,1.01,0]],"batl":[[0,3.9,358.88],[1,3.9,0]],"ltp":2.08,"tv":90.14,"id":8174357},{"batb":[[0,1.01,10.53],[1,1.01,0]],"batl":[[0,1.95,140.42],[1,1.95,0]],"ltp":1.89,"tv":136.05,"id":7412952}]}]}
{"op":"mcm","clk":"1004971842","pt":1580639630637,"mc":[{"id":"1.168209734","rc":[{"batb":[[0,1.35,406.08],[1,1.34,296.07],[2,1.01,10.51]],"batl":[[0,1.73,135.54],[1,1.75,202.38],[2,1.95,140.42]],"ltp":1.89,"tv":136.05,"id":7412952}]}]}
{"op":"mcm","clk":"1004972856","pt":1580639643855,"mc":[{"id":"1.168209734","rc":[{"batl":[[0,1.95,140.42],[1,1.75,0],[2,1.95,0]],"ltp":1.89,"tv":136.05,"id":7412952}]}]}
{"op":"mcm","clk":"1004973105","pt":1580639646840,"mc":[{"id":"1.168209734","rc":[{"trd":[[1.48,0.02],[1.5,0.07]],"batb":[[0,1.35,406.05]],"batl":[[0,1.39,173.93],[1,1.4,232.46]],"ltp":1.48,"tv":136.11,"id":7412952}],"tv":226.25}]}
{"op":"mcm","clk":"1004973198","pt":1580639647927,"mc":[{"id":"1.168209734","rc":[{"batl":[[0,3.7,15.12]],"ltp":2.08,"tv":90.14,"id":8174357},{"batb":[[0,1.37,113.43],[1,1.35,406.05],[2,1.34,296.07]],"ltp":1.48,"tv":136.11,"id":7412952}]}]}
{"op":"mcm","clk":"1004973334","pt":1580639649450,"mc":[{"id":"1.168209734","rc":[{"batl":[[1,5.5,254.06]],"ltp":2.08,"tv":90.14,"id":8174357},{"batl":[[2,1.71,219.49]],"ltp":1.48,"tv":136.11,"id":7412952}]}]}
{"op":"mcm","clk":"1004975086","pt":1580639669875,"mc":[{"id":"1.168209734","rc":[{"batb":[[1,1.01,10.51],[2,1.34,0]],"batl":[[0,1.71,219.49],[1,1.4,0],[2,1.71,0]],"ltp":1.48,"tv":136.11,"id":7412952}]}]}
{"op":"mcm","clk":"1004975173","pt":1580639670767,"mc":[{"id":"1.168209734","rc":[{"batl":[[0,5.5,254.06],[1,5.5,0]],"ltp":2.08,"tv":90.14,"id":8174357},{"batb":[[0,1.01,10.51],[1,1.01,0]],"ltp":1.48,"tv":136.11,"id":7412952}]}]}
{"op":"mcm","clk":"1004975361","pt":1580639672761,"mc":[{"id":"1.168209734","rc":[{"batb":[[0,1.19,239.92],[1,1.18,632.73],[2,1.01,10.51]],"batl":[[0,1.52,199.26],[1,1.53,161.27]],"ltp":1.48,"tv":136.11,"id":7412952}]}]}
{"op":"mcm","clk":"1004975456","pt":1580639673865,"mc":[{"id":"1.168209734","rc":[{"batb":[[0,1.01,10.51],[1,1.18,0],[2,1.01,0]],"ltp":1.48,"tv":136.11,"id":7412952}]}]}
{"op":"mcm","clk":"1004975699","pt":1580639676907,"mc":[{"id":"1.168209734","rc":[{"batb":[[0,1.32,209.22],[1,1.31,329.31],[2,1.01,10.51]],"batl":[[0,1.35,193.1],[1,1.36,265.12]],"ltp":1.48,"tv":136.11,"id":7412952}]}]}
{"op":"mcm","clk":"1004975864","pt":1580639678695,"mc":[{"id":"1.168209734","rc":[{"batl":[[0,6,230.1]],"ltp":2.08,"tv":90.14,"id":8174357},{"batl":[[2,1.66,239.65]],"ltp":1.48,"tv":136.11,"id":7412952}]}]}
{"op":"mcm","clk":"1004976169","pt":1580639682388,"mc":[{"id":"1.168209734","rc":[{"batb":[[0,1.01,10.51],[1,1.31,0],[2,1.01,0]],"batl":[[0,1.66,239.65],[1,1.36,0],[2,1.66,0]],"ltp":1.48,"tv":136.11,"id":7412952}]}]}
{"op":"mcm","clk":"1004976453","pt":1580639685605,"mc":[{"id":"1.168209734","rc":[{"batb":[[0,1.19,245.69],[1,1.18,632.77],[2,1.01,10.51]],"batl":[[0,1.52,194.74],[1,1.53,161.26]],"ltp":1.48,"tv":136.11,"id":7412952}]}]}
{"op":"mcm","clk":"1004977705","pt":1580639699932,"mc":[{"id":"1.168209734","rc":[{"batb":[[0,1.01,10.51],[1,1.18,0],[2,1.01,0]],"ltp":1.48,"tv":136.11,"id":7412952}]}]}
{"op":"mcm","clk":"1004977948","pt":1580639702935,"mc":[{"id":"1.168209734","rc":[{"batb":[[0,1.47,269.43],[1,1.46,198.87],[2,1.01,10.51]],"ltp":1.48,"tv":136.11,"id":7412952}]}]}
{"op":"mcm","clk":"1004978015","pt":1580639703628,"mc":[{"id":"1.168209734","rc":[{"batb":[[0,2.66,25.21],[1,1.01,10.52]],"batl":[[0,3.1,19.32]],"ltp":2.08,"tv":90.14,"id":8174357},{"batb":[[0,1.48,87.38],[1,1.47,269.43],[2,1.46,198.87]],"batl":[[2,1.59,42.01]],"ltp":1.48,"tv":136.11,"id":7412952}]}]}
{"op":"mcm","clk":"1004978245","pt":1580639705636,"mc":[{"id":"1.168209734","rc":[{"batl":[[1,4.6,304.41]],"ltp":2.08,"tv":90.14,"id":8174357}]}]}
{"op":"mcm","clk":"1004980114","pt":1580639723831,"mc":[{"id":"1.168209734","rc":[{"batb":[[1,1.01,10.51],[2,1.46,0]],"batl":[[0,1.59,42.01],[1,1.82,170.1],[2,1.59,0]],"ltp":1.48,"tv":136.11,"id":7412952}]}]}
{"op":"mcm","clk":"1004980192","pt":1580639724765,"mc":[{"id":"1.168209734","rc":[{"batb":[[0,1.01,10.52],[1,1.01,0]],"batl":[[0,4.6,304.41],[1,4.6,0]],"ltp":2.08,"tv":90.14,"id":8174357},{"batb":[[0,1.01,10.51],[1,1.01,0]],"batl":[[0,1.82,170.1],[1,1.82,0]],"ltp":1.48,"tv":136.11,"id":7412952}]}]}
{"op":"mcm","clk":"1004980322","pt":1580639726247,"mc":[{"id":"1.168209734","rc":[{"batb":[[0,1.25,570.8],[1,1.24,458.93],[2,1.01,10.51]],"batl":[[0,1.69,174.75],[1,1.71,218.28],[2,1.82,170.1]],"ltp":1.48,"tv":136.11,"id":7412952}]}]}
{"op":"mcm","clk":"1004981193","pt":1580639734770,"mc":[{"id":"1.168209734","rc":[{"batl":[[0,1.82,170.1],[1,1.71,0],[2,1.82,0]],"ltp":1.48,"tv":136.11,"id":7412952}]}]}
{"op":"mcm","clk":"1004981485","pt":1580639737760,"mc":[{"id":"1.168209734","rc":[{"batl":[[0,4.6,10.92]],"ltp":2.08,"tv":90.14,"id":8174357},{"batb":[[0,1.27,155.44],[1,1.25,570.8],[2,1.24,458.93]],"batl":[[0,1.29,464.9],[1,1.3,326.5]],"ltp":1.48,"tv":136.11,"id":7412952}]}]}
{"op":"mcm","clk":"1004981515","pt":1580639738074,"mc":[{"id":"1.168209734","rc":[{"batb":[[0,3.85,14.28],[1,1.01,10.52]],"ltp":2.08,"tv":90.14,"id":8174357},{"batl":[[2,1.35,42.01]],"ltp":1.48,"tv":136.11,"id":7412952}]}]}
{"op":"mcm","clk":"1004981784","pt":1580639741055,"mc":[{"id":"1.168209734","rc":[{"batl":[[1,7.2,194.01]],"ltp":2.08,"tv":90.14,"id":8174357}]}]}
{"op":"mcm","clk":"1004983162","pt":1580639754901,"mc":[{"id":"1.168209734","rc":[{"batb":[[0,1.01,10.52],[1,1.01,0]],"batl":[[0,7.2,194.01],[1,7.2,0]],"ltp":2.08,"tv":90.14,"id":8174357},{"trd":[[1.27,95.5]],"batb":[[0,1.27,107.67]],"batl":[[2,1.58,288.93]],"ltp":1.27,"tv":231.61,"id":7412952}],"tv":321.75}]}
{"op":"mcm","clk":"1004983452","pt":1580639757885,"mc":[{"id":"1.168209734","rc":[{"batb":[[0,4,13.44],[1,1.01,10.52]],"batl":[[0,4.7,10.92],[1,7.2,194.01]],"ltp":2.08,"tv":90.14,"id":8174357},{"batb":[[0,1.27,154.72],[1,1.01,10.51],[2,1.24,0]],"batl":[[0,1.33,42.01],[1,1.58,288.93],[2,1.58,0]],"ltp":1.27,"tv":231.61,"id":7412952}]}]}
{"op":"mcm","clk":"1004983527","pt":1580639758785,"mc":[{"id":"1.168209734","rc":[{"batb":[[0,1.01,10.52],[1,1.01,0]],"batl":[[0,7.2,194.01],[1,7.2,0]],"ltp":2.08,"tv":90.14,"id":8174357},{"batb":[[0,1.01,10.51],[1,1.01,0]],"batl":[[0,1.58,288.93],[1,1.58,0]],"ltp":1.27,"tv":231.61,"id":7412952}]}]}
{"op":"mcm","clk":"1004983751","pt":1580639760886,"mc":[{"id":"1.168209734","rc":[{"batb":[[0,4.1,13.44],[1,1.01,10.52]],"ltp":2.08,"tv":90.14,"id":8174357},{"batl":[[0,1.42,285.76],[1,1.43,210.82]],"ltp":1.27,"tv":231.61,"id":7412952}]}]}
{"op":"mcm","clk":"1004983777","pt":1580639761194,"mc":[{"id":"1.168209734","rc":[{"batb":[[0,1.01,10.52],[1,1.01,0]],"ltp":2.08,"tv":90.14,"id":8174357}]}]}
{"op":"mcm","clk":"1004984029","pt":1580639763912,"mc":[{"id":"1.168209734","rc":[{"batb":[[0,1.38,193.2],[1,1.37,263.22],[2,1.01,10.51]],"ltp":1.27,"tv":231.61,"id":7412952}]}]}
{"op":"mcm","clk":"1004984218","pt":1580639765685,"mc":[{"id":"1.168209734","rc":[{"batb":[[0,3.2,18.48],[1,1.01,10.52]],"batl":[[0,3.65,15.12]],"ltp":2.08,"tv":90.14,"id":8174357},{"batb":[[0,1.38,303.27]],"batl":[[2,1.45,42.01]],"ltp":1.27,"tv":231.61,"id":7412952}]}]}
{"op":"mcm","clk":"1004984285","pt":1580639766410,"mc":[{"id":"1.168209734","rc":[{"batl":[[1,5.3,262.07]],"ltp":2.08,"tv":90.14,"id":8174357}]}]}
{"op":"mcm","clk":"1004985721","pt":1580639781927,"mc":[{"id":"1.168209734","rc":[{"batb":[[0,1.38,110.07],[1,1.01,10.51],[2,1.01,0]],"batl":[[0,1.45,42.01],[1,1.73,206.02],[2,1.45,0]],"ltp":1.27,"tv":231.61,"id":7412952}]}]}
{"op":"mcm","clk":"1004985806","pt":1580639782818,"mc":[{"id":"1.168209734","rc":[{"batb":[[0,1.01,10.52],[1,1.01,0]],"batl":[[0,5.3,262.07],[1,5.3,0]],"ltp":2.08,"tv":90.14,"id":8174357},{"batb":[[0,1.01,10.51],[1,1.01,0]],"batl":[[0,1.73,206.02],[1,1.73,0]],"ltp":1.27,"tv":231.61,"id":7412952}]}]}
{"op":"mcm","clk":"1004985983","pt":1580639784940,"mc":[{"id":"1.168209734","rc":[{"batb":[[0,1.09,447.97],[1,1.08,739.49],[2,1.01,10.51]],"batl":[[0,1.68,179.71],[1,1.7,222.64]],"ltp":1.27,"tv":231.61,"id":7412952}]}]}
{"op":"mcm","clk":"1004986166","pt":1580639786922,"mc":[{"id":"1.168209734","rc":[{"batb":[[0,1.01,10.51],[1,1.08,0],[2,1.01,0]],"ltp":1.27,"tv":231.61,"id":7412952}]}]}
{"op":"mcm","clk":"1004986454","pt":1580639789856,"mc":[{"id":"1.168209734","rc":[{"batb":[[0,2.38,30.25],[1,1.01,10.52]],"batl":[[0,2.68,24.37]],"ltp":2.08,"tv":90.14,"id":8174357},{"batb":[[0,1.62,169.9],[1,1.61,135.12],[2,1.59,70.58]],"batl":[[2,1.71,42.01]],"ltp":1.27,"tv":231.61,"id":7412952}]}]}
{"op":"mcm","clk":"1004986503","pt":1580639790327,"mc":[{"id":"1.168209734","rc":[{"batb":[[2,1.6,69.74]],"ltp":1.27,"tv":231.61,"id":7412952}]}]}
{"op":"mcm","clk":"1004986653","pt":1580639791842,"mc":[{"id":"1.168209734","rc":[{"batl":[[1,3.65,389.35]],"ltp":2.08,"tv":90.14,"id":8174357}]}]}
{"op":"mcm","clk":"1004987939","pt":1580639805749,"mc":[{"id":"1.168209734","rc":[{"batb":[[0,1.6,69.74],[1,1.01,10.51],[2,1.6,0]],"batl":[[0,1.71,42.01],[1,2.04,130.5],[2,1.71,0]],"ltp":1.27,"tv":231.61,"id":7412952}]}]}
{"op":"mcm","clk":"1004988076","pt":1580639806851,"mc":[{"id":"1.168209734","rc":[{"batb":[[0,1.01,10.52],[1,1.01,0]],"batl":[[0,3.65,389.35],[1,3.65,0]],"ltp":2.08,"tv":90.14,"id":8174357},{"batb":[[0,1.01,10.51],[1,1.01,0]],"batl":[[0,2.04,130.5],[1,2.04,0]],"ltp":1.27,"tv":231.61,"id":7412952}]}]}
{"op":"mcm","clk":"1004988537","pt":1580639811774,"mc":[{"id":"1.168209734","rc":[{"batb":[[0,1.56,233.28],[1,1.55,156.15],[2,1.01,10.51]],"batl":[[0,1.62,208.34],[1,1.63,127.83],[2,2.04,130.5]],"ltp":1.27,"tv":231.61,"id":7412952}]}]}
{"op":"mcm","clk":"1004989101","pt":1580639817902,"mc":[{"id":"1.168209734","rc":[{"batb":[[0,1.01,10.51],[1,1.55,0],[2,1.01,0]],"batl":[[0,2.04,130.5],[1,1.63,0],[2,2.04,0]],"ltp":1.27,"tv":231.61,"id":7412952}]}]}
{"op":"mcm","clk":"1004989419","pt":1580639820858,"mc":[{"id":"1.168209734","rc":[{"batb":[[0,1.37,289.82],[1,1.36,273.85],[2,1.01,10.51]],"batl":[[0,1.87,121.17],[1,1.89,158.54],[2,2.04,130.5]],"ltp":1.27,"tv":231.61,"id":7412952}]}]}
{"op":"mcm","clk":"1004990125","pt":1580639827779,"mc":[{"id":"1.168209734","rc":[{"batb":[[0,1.01,10.51],[1,1.36,0],[2,1.01,0]],"ltp":1.27,"tv":231.61,"id":7412952}]}]}
{"op":"mcm","clk":"1004990442","pt":1580639830901,"mc":[{"id":"1.168209734","rc":[{"batb":[[0,1.8,133.49],[1,1.78,189.4],[2,1.01,10.51]],"batl":[[2,2.04,0]],"ltp":1.27,"tv":231.61,"id":7412952}]}]}
{"op":"mcm","clk":"1004990564","pt":1580639831695,"mc":[{"id":"1.168209734","rc":[{"batb":[[0,2.08,38.65],[1,1.01,10.52]],"batl":[[0,2.3,31.93]],"ltp":2.08,"tv":90.14,"id":8174357},{"batb":[[2,1.76,54.61]],"batl":[[2,1.91,42.01]],"ltp":1.27,"tv":231.61,"id":7412952}]}]}
{"op":"mcm","clk":"1004990780","pt":1580639834003,"mc":[{"id":"1.168209734","rc":[{"batl":[[1,3,486.49]],"ltp":2.08,"tv":90.14,"id":8174357}]}]}
{"op":"mcm","clk":"1004992578","pt":1580639853814,"mc":[{"id":"1.168209734","rc":[{"batb":[[0,1.76,54.61],[1,1.01,10.51],[2,1.76,0]],"batl":[[0,1.91,42.01],[1,2.3,97.52],[2,1.91,0]],"ltp":1.27,"tv":231.61,"id":7412952}]}]}
{"op":"mcm","clk":"1004992685","pt":1580639854903,"mc":[{"id":"1.168209734","rc":[{"batb":[[0,1.01,10.52],[1,1.01,0]],"batl":[[0,3,486.49],[1,3,0]],"ltp":2.08,"tv":90.14,"id":8174357},{"batb":[[0,1.01,10.51],[1,1.01,0]],"batl":[[0,2.3,97.52],[1,2.3,0]],"ltp":1.27,"tv":231.61,"id":7412952}]}]}
{"op":"mcm","clk":"1004992824","pt":1580639856207,"mc":[{"id":"1.168209734","rc":[{"batb":[[0,1.61,165.92],[1,1.6,138.26],[2,1.01,10.51]],"batl":[[0,2,117.17],[1,2.02,129.8],[2,2.3,97.52]],"ltp":1.27,"tv":231.61,"id":7412952}]}]}
{"op":"mcm","clk":"1004993238","pt":1580639860230,"mc":[{"id":"1.168209734","rc":[{"batb":[[0,1.01,10.51],[1,1.6,0],[2,1.01,0]],"ltp":1.27,"tv":231.61,"id":7412952}]}]}
{"op":"mcm","clk":"1004993659","pt":1580639863736,"mc":[{"id":"1.168209734","rc":[{"batb":[[0,1.92,45.37],[1,1.01,10.52]],"batl":[[0,2.12,36.97]],"ltp":2.08,"tv":90.14,"id":8174357},{"batb":[[0,1.92,118.06],[1,1.9,153.56],[2,1.89,47.05]],"batl":[[2,2.08,38.65]],"ltp":1.27,"tv":231.61,"id":7412952}]}]}
{"op":"mcm","clk":"1004993876","pt":1580639866151,"mc":[{"id":"1.168209734","rc":[{"batl":[[1,2.82,525.27]],"ltp":2.08,"tv":90.14,"id":8174357}]}]}
{"op":"mcm","clk":"1004997475","pt":1580639904293,"mc":[{"id":"1.168209734","rc":[{"trd":[[1.92,36.09]],"batb":[[0,1.92,102.72]],"ltp":1.92,"tv":262.28,"id":7412952}],"tv":352.43}]}
{"op":"mcm","clk":"1005002825","pt":1580639960841,"mc":[{"id":"1.168209734","rc":[{"batb":[[0,1.01,10.52],[1,1.01,0]],"batl":[[0,2.82,525.27],[1,2.82,0]],"ltp":2.08,"tv":90.14,"id":8174357},{"batb":[[2,1.01,10.51]],"batl":[[2,2.3,97.52]],"ltp":1.92,"tv":262.28,"id":7412952}]}]}
{"op":"mcm","clk":"1005004686","pt":1580639980956,"mc":[{"id":"1.168209734","rc":[{"batb":[[0,1.01,10.51],[1,1.9,0],[2,1.01,0]],"batl":[[0,2.3,97.52],[1,2.02,0],[2,2.3,0]],"ltp":1.92,"tv":262.28,"id":7412952}]}]}
{"op":"mcm","clk":"1005004897","pt":1580639983464,"mc":[{"id":"1.168209734","rc":[{"batb":[[0,1.81,165.87],[1,1.79,186.04],[2,1.01,10.51]],"batl":[[1,2.32,123.94],[2,2.34,85.84]],"ltp":1.92,"tv":262.28,"id":7412952}]}]}
{"op":"mcm","clk":"1005006380","pt":1580639998352,"mc":[{"id":"1.168209734","rc":[{"batl":[[1,2.32,0],[2,2.34,0]],"ltp":1.92,"tv":262.28,"id":7412952}]}]}
{"op":"mcm","clk":"1005006755","pt":1580640001895,"mc":[{"id":"1.168209734","rc":[{"batb":[[0,2.04,40.33],[1,1.01,10.52]],"batl":[[0,2.26,32.77],[1,2.82,525.27]],"ltp":2.08,"tv":90.14,"id":8174357},{"batb":[[0,1.81,217.12]],"batl":[[0,1.89,160.47],[1,1.91,153.45],[2,1.97,42.01]],"ltp":1.92,"tv":262.28,"id":7412952}]}]}
{"op":"mcm","clk":"1005007908","pt":1580640014885,"mc":[{"id":"1.168209734","rc":[{"batb":[[0,1.81,51.25],[1,1.01,10.51],[2,1.01,0]],"batl":[[0,1.97,42.01],[1,2.3,97.52],[2,1.97,0]],"ltp":1.92,"tv":262.28,"id":7412952}]}]}
{"op":"mcm","clk":"1005008127","pt":1580640016883,"mc":[{"id":"1.168209734","rc":[{"batb":[[0,1.01,10.52],[1,1.01,0]],"batl":[[0,2.82,525.27],[1,2.82,0]],"ltp":2.08,"tv":90.14,"id":8174357},{"batb":[[0,1.01,10.51],[1,1.01,0]],"batl":[[0,2.3,97.52],[1,2.3,0]],"ltp":1.92,"tv":262.28,"id":7412952}]}]}
{"op":"mcm","clk":"1005008209","pt":1580640017808,"mc":[{"id":"1.168209734","rc":[{"batb":[[0,1.74,199.18],[1,1.72,212.8],[2,1.01,10.51]],"batl":[[0,2.08,112.5],[1,2.1,115.97],[2,2.3,97.52]],"ltp":1.92,"tv":262.28,"id":7412952}]}]}
{"op":"mcm","clk":"1005008661","pt":1580640022584,"mc":[{"id":"1.168209734","rc":[{"batl":[[0,2.3,97.52],[1,2.1,0],[2,2.3,0]],"ltp":1.92,"tv":262.28,"id":7412952}]}]}
{"op":"mcm","clk":"1005008998","pt":1580640025891,"mc":[{"id":"1.168209734","rc":[{"batb":[[0,2.12,36.97],[1,1.01,10.52]],"batl":[[0,2.38,30.25]],"ltp":2.08,"tv":90.14,"id":8174357},{"batb":[[1,1.73,57.13],[2,1.72,212.8]],"batl":[[0,1.81,114.3],[1,1.83,175.38],[2,1.89,42.01]],"ltp":1.92,"tv":262.28,"id":7412952}]}]}
{"op":"mcm","clk":"1005009314","pt":1580640028721,"mc":[{"id":"1.168209734","rc":[{"batl":[[1,3.15,459.06]],"ltp":2.08,"tv":90.14,"id":8174357}]}]}
{"op":"mcm","clk":"1005010472","pt":1580640040840,"mc":[{"id":"1.168209734","rc":[{"batb":[[0,1.73,57.13],[1,1.01,10.51],[2,1.72,0]],"batl":[[0,1.89,42.01],[1,2.3,97.52],[2,1.89,0]],"ltp":1.92,"tv":262.28,"id":7412952}]}]}
{"op":"mcm","clk":"1005010625","pt":1580640042829,"mc":[{"id":"1.168209734","rc":[{"batb":[[0,1.01,10.52],[1,1.01,0]],"batl":[[0,3.15,459.06],[1,3.15,0]],"ltp":2.08,"tv":90.14,"id":8174357},{"batb":[[0,1.01,10.51],[1,1.01,0]],"batl":[[0,2.3,97.52],[1,2.3,0]],"ltp":1.92,"tv":262.28,"id":7412952}]}]}
{"op":"mcm","clk":"1005010718","pt":1580640043719,"mc":[{"id":"1.168209734","rc":[{"trd":[[2,2.27]],"ltp":2.0,"tv":92.41,"id":8174357},{"trd":[[2,2.27]],"batb":[[0,1.7,220.52],[1,1.68,230.99],[2,1.01,10.51]],"batl":[[0,1.92,138.54],[1,1.94,146.37],[2,2.3,97.52]],"ltp":2.0,"tv":264.55,"id":7412952}],"tv":356.97}]}
{"op":"mcm","clk":"1005011948","pt":1580640057863,"mc":[{"id":"1.168209734","rc":[{"batb":[[0,1.01,10.51],[1,1.68,0],[2,1.01,0]],"ltp":2.0,"tv":264.55,"id":7412952}]}]}
{"op":"mcm","clk":"1005012239","pt":1580640060871,"mc":[{"id":"1.168209734","rc":[{"batb":[[0,1.84,158.91],[1,1.82,176.17],[2,1.01,10.51]],"ltp":2.0,"tv":264.55,"id":7412952}]}]}
{"op":"mcm","clk":"1005012310","pt":1580640061863,"mc":[{"id":"1.168209734","rc":[{"batb":[[0,2.02,41.17],[1,1.01,10.52]],"batl":[[0,2.24,33.61]],"ltp":2.0,"tv":92.41,"id":8174357},{"batb":[[2,1.8,52.09]],"batl":[[2,1.98,42.01]],"ltp":2.0,"tv":264.55,"id":7412952}]}]}
{"op":"mcm","clk":"1005012544","pt":1580640064259,"mc":[{"id":"1.168209734","rc":[{"batl":[[1,2.92,502.2]],"ltp":2.0,"tv":92.41,"id":8174357}]}]}
{"op":"mcm","clk":"1005013096","pt":1580640070574,"mc":[{"id":"1.168209734","rc":[{"batb":[[0,1.8,52.09],[1,1.01,10.51],[2,1.8,0]],"batl":[[0,1.98,42.01],[1,2.3,97.52],[2,7,2.27]],"ltp":2.0,"tv":264.55,"id":7412952}]}]}
{"op":"mcm","clk":"1005013331","pt":1580640073592,"mc":[{"id":"1.168209734","rc":[{"batb":[[0,1.83,187.65],[1,1.81,179.53],[2,1.8,52.09]],"batl":[[0,1.91,121.81],[1,1.93,148.82],[2,1.98,42.01]],"ltp":2.0,"tv":264.55,"id":7412952}]}]}
{"op":"mcm","clk":"1005014247","pt":1580640083401,"mc":[{"id":"1.168209734","rc":[{"batb":[[0,1.8,52.09],[1,1.01,10.51],[2,1.8,0]],"batl":[[0,1.98,42.01],[1,2.3,97.52],[2,7,2.27]],"ltp":2.0,"tv":264.55,"id":7412952}]}]}
{"op":"mcm","clk":"1005014384","pt":1580640084875,"mc":[{"id":"1.168209734","rc":[{"batb":[[0,1.01,10.52],[1,1.01,0]],"batl":[[0,2.92,502.2],[1,2.92,0]],"ltp":2.0,"tv":92.41,"id":8174357},{"batb":[[0,1.01,10.51],[1,1.01,0]],"batl":[[0,2.3,97.52],[1,7,2.27],[2,7,0]],"ltp":2.0,"tv":264.55,"id":7412952}]}]}
{"op":"mcm","clk":"1005014491","pt":1580640086008,"mc":[{"id":"1.168209734","rc":[{"batb":[[0,1.75,117.35],[1,1.73,208.48],[2,1.01,10.51]],"batl":[[0,2.18,170.24],[1,2.2,101.75],[2,2.3,97.52]],"ltp":2.0,"tv":264.55,"id":7412952}]}]}
{"op":"mcm","clk":"1005014665","pt":1580640087898,"mc":[{"id":"1.168209734","rc":[{"batb":[[0,1.01,10.51],[1,1.73,0],[2,1.01,0]],"batl":[[0,2.3,97.52],[1,7,2.27],[2,2.3,0]],"ltp":2.0,"tv":264.55,"id":7412952}]}]}
{"op":"mcm","clk":"1005014932","pt":1580640090790,"mc":[{"id":"1.168209734","rc":[{"batb":[[0,1.88,122.38],[1,1.86,164.31],[2,1.01,10.51]],"batl":[[0,1.96,142.52],[1,1.98,137.78],[2,2.3,97.52]],"ltp":2.0,"tv":264.55,"id":7412952}]}]}
{"op":"mcm","clk":"1005015168","pt":1580640093401,"mc":[{"id":"1.168209734","rc":[{"batb":[[0,1.01,10.51],[1,1.86,0],[2,1.01,0]],"batl":[[0,2.3,97.52],[1,7,2.27],[2,2.3,0]],"ltp":2.0,"tv":264.55,"id":7412952}]}]}
{"op":"mcm","clk":"1005015440","pt":1580640096307,"mc":[{"id":"1.168209734","rc":[{"batb":[[0,1.75,117.35],[1,1.73,208.48],[2,1.01,10.51]],"batl":[[0,2.18,170.24],[1,2.2,101.75],[2,2.3,97.52]],"ltp":2.0,"tv":264.55,"id":7412952}]}]}
{"op":"mcm","clk":"1005016840","pt":1580640110846,"mc":[{"id":"1.168209734","rc":[{"batl":[[0,2.3,97.52],[1,7,2.27],[2,2.3,0]],"ltp":2.0,"tv":264.55,"id":7412952}]}]}
{"op":"mcm","clk":"1005017167","pt":1580640113930,"mc":[{"id":"1.168209734","rc":[{"batl":[[0,1.82,182.56],[1,1.84,172.32],[2,2.3,97.52]],"ltp":2.0,"tv":264.55,"id":7412952}]}]}
{"op":"mcm","clk":"1005017369","pt":1580640115918,"mc":[{"id":"1.168209734","rc":[{"batb":[[0,2.14,36.13],[1,1.01,10.52]],"batl":[[0,2.38,30.25],[1,2.92,502.2]],"ltp":2.0,"tv":92.41,"id":8174357},{"batb":[[2,1.72,57.97]],"batl":[[2,1.88,42.01]],"ltp":2.0,"tv":264.55,"id":7412952}]}]}
{"op":"mcm","clk":"1005020098","pt":1580640138175,"mc":[{"id":"1.168209734","rc":[{"batb":[[0,1.72,57.97],[1,1.01,10.51],[2,1.72,0]],"batl":[[0,1.88,42.01],[1,2.3,97.52],[2,7,2.27]],"ltp":2.0,"tv":264.55,"id":7412952}]}]}
{"op":"mcm","clk":"1005020195","pt":1580640139073,"mc":[{"id":"1.168209734","rc":[{"batb":[[0,1.01,10.52],[1,1.01,0]],"batl":[[0,2.92,502.2],[1,2.92,0]],"ltp":2.0,"tv":92.41,"id":8174357},{"batb":[[0,1.01,10.51],[1,1.01,0]],"batl":[[0,2.3,97.52],[1,7,2.27],[2,7,0]],"ltp":2.0,"tv":264.55,"id":7412952}]}]}
{"op":"mcm","clk":"1005020411","pt":1580640140868,"mc":[{"id":"1.168209734","rc":[{"batb":[[0,1.71,170.39],[1,1.69,226.18],[2,1.01,10.51]],"batl":[[0,1.92,165.18],[1,1.94,146.43],[2,2.3,97.52]],"ltp":2.0,"tv":264.55,"id":7412952}]}]}
{"op":"mcm","clk":"1005020890","pt":1580640144752,"mc":[{"id":"1.168209734","rc":[{"batl":[[0,2.3,97.52],[1,7,2.27],[2,2.3,0]],"ltp":2.0,"tv":264.55,"id":7412952}]}]}
{"op":"mcm","clk":"1005021065","pt":1580640146072,"mc":[{"id":"1.168209734","rc":[{"batl":[[0,7,2.27],[1,7,0]],"ltp":2.0,"tv":264.55,"id":7412952}]}]}
{"op":"mcm","clk":"1005021283","pt":1580640147752,"mc":[{"id":"1.168209734","rc":[{"batl":[[0,1.78,174.32],[1,1.8,184.81],[2,7,2.27]],"ltp":2.0,"tv":264.55,"id":7412952}]}]}
{"op":"mcm","clk":"1005021360","pt":1580640148377,"mc":[{"id":"1.168209734","rc":[{"batb":[[0,2.2,34.45],[1,1.01,10.52]],"batl":[[0,2.46,28.57]],"ltp":2.0,"tv":92.41,"id":8174357},{"batb":[[2,1.68,61.33]],"batl":[[2,1.83,42.01]],"ltp":2.0,"tv":264.55,"id":7412952}]}]}
{"op":"mcm","clk":"1005021613","pt":1580640150155,"mc":[{"id":"1.168209734","rc":[{"batl":[[1,3.3,438.62]],"ltp":2.0,"tv":92.41,"id":8174357}]}]}
{"op":"mcm","clk":"1005023073","pt":1580640161794,"mc":[{"id":"1.168209734","rc":[{"batb":[[0,1.71,149.48]],"ltp":2.0,"tv":264.55,"id":7412952}]}]}
{"op":"mcm","clk":"1005023504","pt":1580640164670,"mc":[{"id":"1.168209734","rc":[{"batl":[[0,1.78,194.42]],"ltp":2.0,"tv":264.55,"id":7412952}]}]}
{"op":"mcm","clk":"1005024639","pt":1580640172302,"mc":[{"id":"1.168209734","rc":[{"trd":[[1.71,35.37]],"batb":[[0,1.71,131.79]],"ltp":1.71,"tv":299.92,"id":7412952}],"tv":392.34}]}
{"op":"mcm","clk":"1005025561","pt":1580640178825,"mc":[{"id":"1.168209734","rc":[{"batb":[[0,1.68,61.33],[1,1.01,10.51],[2,1.68,0]],"batl":[[0,1.83,42.01],[1,2.16,111.53],[2,7,2.27]],"ltp":1.71,"tv":299.92,"id":7412952}]}]}
{"op":"mcm","clk":"1005025658","pt":1580640179505,"mc":[{"id":"1.168209734","rc":[{"batb":[[0,1.01,10.52],[1,1.01,0]],"batl":[[0,3.3,438.62],[1,3.3,0]],"ltp":2.0,"tv":92.41,"id":8174357},{"batb":[[0,1.01,10.51],[1,1.01,0]],"batl":[[0,2.16,111.53],[1,7,2.27],[2,7,0]],"ltp":1.71,"tv":299.92,"id":7412952}]}]}
{"op":"mcm","clk":"1005026429","pt":1580640184914,"mc":[{"id":"1.168209734","rc":[{"batb":[[0,1.67,149.99],[1,1.66,121.18],[2,1.01,10.51]],"batl":[[0,1.73,140.08],[1,1.75,202.79],[2,2.16,111.53]],"ltp":1.71,"tv":299.92,"id":7412952}]}]}
{"op":"mcm","clk":"1005027289","pt":1580640190617,"mc":[{"id":"1.168209734","rc":[{"batb":[[0,1.01,10.51],[1,1.66,0],[2,1.01,0]],"batl":[[0,2.16,111.53],[1,7,2.27],[2,2.16,0]],"ltp":1.71,"tv":299.92,"id":7412952}]}]}
{"op":"mcm","clk":"1005027798","pt":1580640193833,"mc":[{"id":"1.168209734","rc":[{"batb":[[0,1.53,137.21],[1,1.52,168.44],[2,1.01,10.51]],"batl":[[0,1.9,132.03],[1,1.92,151.26],[2,2.16,111.53]],"ltp":1.71,"tv":299.92,"id":7412952}]}]}
{"op":"mcm","clk":"1005029069","pt":1580640201510,"mc":[{"id":"1.168209734","rc":[{"batb":[[0,1.01,10.51],[1,1.52,0],[2,1.01,0]],"ltp":1.71,"tv":299.92,"id":7412952}]}]}
{"op":"mcm","clk":"1005029518","pt":1580640204719,"mc":[{"id":"1.168209734","rc":[{"batb":[[0,1.82,186.8],[1,1.8,182.91],[2,1.01,10.51]],"ltp":1.71,"tv":299.92,"id":7412952}]}]}
{"op":"mcm","clk":"1005029739","pt":1580640206120,"mc":[{"id":"1.168209734","rc":[{"batb":[[0,2.04,40.33],[1,1.01,10.52]],"batl":[[0,2.26,32.77]],"ltp":2.0,"tv":92.41,"id":8174357},{"batb":[[2,1.79,52.93]],"batl":[[2,1.95,42.01]],"ltp":1.71,"tv":299.92,"id":7412952}]}]}
{"op":"mcm","clk":"1005030003","pt":1580640207814,"mc":[{"id":"1.168209734","rc":[{"batl":[[1,3,486.49]],"ltp":2.0,"tv":92.41,"id":8174357}]}]}
{"op":"mcm","clk":"1005031447","pt":1580640218930,"mc":[{"id":"1.168209734","rc":[{"batb":[[0,1.79,52.93],[1,1.01,10.51],[2,1.79,0]],"batl":[[0,1.95,42.01],[1,2.16,111.53],[2,7,2.27]],"ltp":1.71,"tv":299.92,"id":7412952}]}]}
{"op":"mcm","clk":"1005031522","pt":1580640219594,"mc":[{"id":"1.168209734","rc":[{"batb":[[0,1.01,10.52],[1,1.01,0]],"batl":[[0,3,486.49],[1,3,0]],"ltp":2.0,"tv":92.41,"id":8174357},{"batb":[[0,1.01,10.51],[1,1.01,0]],"batl":[[0,2.16,111.53],[1,7,2.27],[2,7,0]],"ltp":1.71,"tv":299.92,"id":7412952}]}]}
{"op":"mcm","clk":"1005032011","pt":1580640222852,"mc":[{"id":"1.168209734","rc":[{"batb":[[0,1.66,221.33],[1,1.65,124.04],[2,1.01,10.51]],"batl":[[0,2.02,219.16],[1,2.04,126.2],[2,2.16,111.53]],"ltp":1.71,"tv":299.92,"id":7412952}]}]}
{"op":"mcm","clk":"1005032228","pt":1580640224450,"mc":[{"id":"1.168209734","rc":[{"batb":[[0,1.01,10.51],[1,1.65,0],[2,1.01,0]],"ltp":1.71,"tv":299.92,"id":7412952}]}]}
{"op":"mcm","clk":"1005032443","pt":1580640225950,"mc":[{"id":"1.168209734","rc":[{"batl":[[2,7,2.27]],"ltp":1.71,"tv":299.92,"id":7412952}]}]}
{"op":"mcm","clk":"1005032677","pt":1580640227642,"mc":[{"id":"1.168209734","rc":[{"batb":[[0,1.92,146.87],[1,1.9,153.7],[2,1.01,10.51]],"ltp":1.71,"tv":299.92,"id":7412952}]}]}
{"op":"mcm","clk":"1005032761","pt":1580640228165,"mc":[{"id":"1.168209734","rc":[{"batb":[[0,1.92,45.37],[1,1.01,10.52]],"batl":[[0,2.12,36.97]],"ltp":2.0,"tv":92.41,"id":8174357},{"batb":[[2,1.89,47.05]],"batl":[[2,2.06,39.49]],"ltp":1.71,"tv":299.92,"id":7412952}]}]}
{"op":"mcm","clk":"1005032993","pt":1580640229933,"mc":[{"id":"1.168209734","rc":[{"batl":[[1,2.82,525.27]],"ltp":2.0,"tv":92.41,"id":8174357}]}]}
{"op":"mcm","clk":"1005034148","pt":1580640238770,"mc":[{"id":"1.168209734","rc":[{"batb":[[0,1.89,47.05],[1,1.01,10.51],[2,1.89,0]],"batl":[[0,2.06,39.49],[1,2.42,88.82],[2,7,2.27]],"ltp":1.71,"tv":299.92,"id":7412952}]}]}
{"op":"mcm","clk":"1005034253","pt":1580640239447,"mc":[{"id":"1.168209734","rc":[{"batb":[[0,1.01,10.52],[1,1.01,0]],"batl":[[0,2.82,525.27],[1,2.82,0]],"ltp":2.0,"tv":92.41,"id":8174357},{"batb":[[0,1.01,10.51],[1,1.01,0]],"batl":[[0,2.42,88.82],[1,7,2.27],[2,7,0]],"ltp":1.71,"tv":299.92,"id":7412952}]}]}
{"op":"mcm","clk":"1005034623","pt":1580640241956,"mc":[{"id":"1.168209734","rc":[{"batb":[[0,1.81,130.51],[1,1.79,186.19],[2,1.01,10.51]],"batl":[[0,2.08,149.29],[1,2.1,116.07],[2,2.42,88.82]],"ltp":1.71,"tv":299.92,"id":7412952}]}]}
{"op":"mcm","clk":"1005035149","pt":1580640245558,"mc":[{"id":"1.168209734","rc":[{"batl":[[0,2.42,88.82],[1,7,2.27],[2,2.42,0]],"ltp":1.71,"tv":299.92,"id":7412952}]}]}
{"op":"mcm","clk":"1005035420","pt":1580640247860,"mc":[{"id":"1.168209734","rc":[{"batl":[[0,7,2.27],[1,7,0]],"ltp":1.71,"tv":299.92,"id":7412952}]}]}
{"op":"mcm","clk":"1005035458","pt":1580640248169,"mc":[{"id":"1.168209734","rc":[{"batl":[[0,1.88,116.53],[1,1.9,156.23],[2,7,2.27]],"ltp":1.71,"tv":299.92,"id":7412952}]}]}
{"op":"mcm","clk":"1005035700","pt":1580640250193,"mc":[{"id":"1.168209734","rc":[{"batb":[[0,2.06,39.49],[1,1.01,10.52]],"batl":[[0,2.28,32.77],[1,2.82,525.27]],"ltp":2.0,"tv":92.41,"id":8174357},{"batb":[[1,1.8,52.09],[2,1.79,186.19]],"batl":[[2,1.95,42.01]],"ltp":1.71,"tv":299.92,"id":7412952}]}]}
{"op":"mcm","clk":"1005037224","pt":1580640262931,"mc":[{"id":"1.168209734","rc":[{"batb":[[0,1.8,52.09],[1,1.01,10.51],[2,1.79,0]],"batl":[[0,1.95,42.01],[1,2.3,97.52],[2,7,2.27]],"ltp":1.71,"tv":299.92,"id":7412952}]}]}
{"op":"mcm","clk":"1005037281","pt":1580640263402,"mc":[{"id":"1.168209734","rc":[{"batb":[[0,1.01,10.52],[1,1.01,0]],"batl":[[0,2.82,525.27],[1,2.82,0]],"ltp":2.0,"tv":92.41,"id":8174357},{"batb":[[0,1.01,10.51],[1,1.01,0]],"batl":[[0,2.3,97.52],[1,7,2.27],[2,7,0]],"ltp":1.71,"tv":299.92,"id":7412952}]}]}
{"op":"mcm","clk":"1005037501","pt":1580640265223,"mc":[{"id":"1.168209734","rc":[{"batb":[[0,1.62,171.89],[1,1.61,135.44],[2,1.01,10.51]],"batl":[[0,2.02,176.79],[1,2.04,126.23],[2,2.3,97.52]],"ltp":1.71,"tv":299.92,"id":7412952}]}]}
{"op":"mcm","clk":"1005037908","pt":1580640268513,"mc":[{"id":"1.168209734","rc":[{"batb":[[0,1.01,10.51],[1,1.61,0],[2,1.01,0]],"batl":[[0,2.3,97.52],[1,7,2.27],[2,2.3,0]],"ltp":1.71,"tv":299.92,"id":7412952}]}]}
{"op":"mcm","clk":"1005038339","pt":1580640271952,"mc":[{"id":"1.168209734","rc":[{"batb":[[0,1.77,123.15],[1,1.75,200.7],[2,1.01,10.51]],"batl":[[0,1.84,158.41],[1,1.86,166.78],[2,2.3,97.52]],"ltp":1.71,"tv":299.92,"id":7412952}]}]}
{"op":"mcm","clk":"1005038694","pt":1580640274834,"mc":[{"id":"1.168209734","rc":[{"batl":[[0,3.15,459.06]],"ltp":2.0,"tv":92.41,"id":8174357},{"batb":[[0,1.01,10.51],[1,1.75,0],[2,1.01,0]],"batl":[[0,2.3,97.52],[1,7,2.27],[2,2.3,0]],"ltp":1.71,"tv":299.92,"id":7412952}]}]}
{"op":"mcm","clk":"1005039045","pt":1580640277760,"mc":[{"id":"1.168209734","rc":[{"batb":[[0,1.62,171.89],[1,1.61,135.44],[2,1.01,10.51]],"batl":[[0,2.02,176.79],[1,2.04,126.23],[2,2.3,97.52]],"ltp":1.71,"tv":299.92,"id":7412952}]}]}
{"op":"mcm","clk":"1005039817","pt":1580640283868,"mc":[{"id":"1.168209734","rc":[{"batb":[[0,1.01,10.51],[1,1.61,0],[2,1.01,0]],"ltp":1.71,"tv":299.92,"id":7412952}]}]}
{"op":"mcm","clk":"1005040220","pt":1580640286940,"mc":[{"id":"1.168209734","rc":[{"batb":[[0,1.93,116.22],[1,1.91,151.19],[2,1.01,10.51]],"ltp":1.71,"tv":299.92,"id":7412952}]}]}
{"op":"mcm","clk":"1005040406","pt":1580640288452,"mc":[{"id":"1.168209734","rc":[{"batb":[[0,1.91,45.37],[1,1.01,10.52]],"batl":[[0,2.1,37.81]],"ltp":2.0,"tv":92.41,"id":8174357},{"batb":[[2,1.9,46.21]],"batl":[[2,2.08,38.65]],"ltp":1.71,"tv":299.92,"id":7412952}]}]}
{"op":"mcm","clk":"1005040544","pt":1580640289556,"mc":[{"id":"1.168209734","rc":[{"batl":[[1,2.82,525.27]],"ltp":2.0,"tv":92.41,"id":8174357}]}]}
{"op":"mcm","clk":"1005042705","pt":1580640304561,"mc":[{"id":"1.168209734","rc":[{"batb":[[0,1.9,46.21],[1,1.01,10.51],[2,1.9,0]],"batl":[[0,2.08,38.65],[1,2.3,97.52],[2,7,2.27]],"ltp":1.71,"tv":299.92,"id":7412952}]}]}
{"op":"mcm","clk":"1005042818","pt":1580640305401,"mc":[{"id":"1.168209734","rc":[{"batb":[[0,1.01,10.52],[1,1.01,0]],"batl":[[0,2.82,525.27],[1,2.82,0]],"ltp":2.0,"tv":92.41,"id":8174357},{"batb":[[0,1.01,10.51],[1,1.01,0]],"batl":[[0,2.3,97.52],[1,7,2.27],[2,7,0]],"ltp":1.71,"tv":299.92,"id":7412952}]}]}
{"op":"mcm","clk":"1005043550","pt":1580640309705,"mc":[{"id":"1.168209734","rc":[{"batb":[[0,1.93,134.03],[1,1.91,151.2],[2,1.01,10.52]],"batl":[[0,2.02,159.85],[1,2.04,126.27],[2,2.82,525.27]],"ltp":2.0,"tv":92.41,"id":8174357}]}]}
{"op":"mcm","clk":"1005043617","pt":1580640310178,"mc":[{"id":"1.168209734","rc":[{"batb":[[2,1.84,49.57]],"batl":[[0,2.02,201.02]],"ltp":2.0,"tv":92.41,"id":8174357},{"batb":[[0,1.98,42.85],[1,1.01,10.51]],"batl":[[0,2.18,35.29],[1,2.3,97.52],[2,7,2.27]],"ltp":1.71,"tv":299.92,"id":7412952}]}]}
{"op":"mcm","clk":"1005050811","pt":1580640363548,"mc":[{"id":"1.168209734","rc":[{"batb":[[2,1.01,10.52]],"ltp":2.0,"tv":92.41,"id":8174357},{"trd":[[1.98,35.37]],"batb":[[0,1.98,25.16]],"ltp":1.98,"tv":335.29,"id":7412952}],"tv":427.7}]}
{"op":"mcm","clk":"1005051280","pt":1580640366553,"mc":[{"id":"1.168209734","rc":[{"batb":[[2,1.87,47.89]],"ltp":2.0,"tv":92.41,"id":8174357},{"batb":[[0,1.98,42.81]],"ltp":1.98,"tv":335.29,"id":7412952}]}]}
{"op":"mcm","clk":"1005055632","pt":1580640398508,"mc":[{"id":"1.168209734","rc":[{"batb":[[0,1.87,47.89],[1,1.01,10.52],[2,1.87,0]],"batl":[[0,2.02,41.17],[1,2.82,525.27],[2,2.82,0]],"ltp":2.0,"tv":92.41,"id":8174357}]}]}
{"op":"mcm","clk":"1005055721","pt":1580640399301,"mc":[{"id":"1.168209734","rc":[{"batb":[[0,1.01,10.52],[1,1.01,0]],"batl":[[0,2.82,525.27],[1,2.82,0]],"ltp":2.0,"tv":92.41,"id":8174357},{"batb":[[0,1.01,10.51],[1,1.01,0]],"batl":[[0,2.3,97.52],[1,7,2.27],[2,7,0]],"ltp":1.98,"tv":335.29,"id":7412952}]}]}
{"op":"mcm","clk":"1005055956","pt":1580640401422,"mc":[{"id":"1.168209734","rc":[{"batb":[[0,1.68,188.07],[1,1.67,118.92],[2,1.01,10.52]],"batl":[[0,2.16,104.01],[1,2.18,104.32],[2,2.82,525.27]],"ltp":2.0,"tv":92.41,"id":8174357}]}]}
{"op":"mcm","clk":"1005056260","pt":1580640403762,"mc":[{"id":"1.168209734","rc":[{"batb":[[0,1.01,10.52],[1,1.67,0],[2,1.01,0]],"batl":[[0,2.82,525.27],[1,2.18,0],[2,2.82,0]],"ltp":2.0,"tv":92.41,"id":8174357}]}]}
{"op":"mcm","clk":"1005056486","pt":1580640405703,"mc":[{"id":"1.168209734","rc":[{"batl":[[0,7,2.27],[1,7,0]],"ltp":1.98,"tv":335.29,"id":7412952}]}]}
{"op":"mcm","clk":"1005056644","pt":1580640406817,"mc":[{"id":"1.168209734","rc":[{"batb":[[0,1.87,180.17],[1,1.85,167.38],[2,1.01,10.52]],"batl":[[0,1.96,166.03],[1,1.98,137.92]],"ltp":2.0,"tv":92.41,"id":8174357}]}]}
{"op":"mcm","clk":"1005057088","pt":1580640409818,"mc":[{"id":"1.168209734","rc":[{"batb":[[0,1.01,10.52],[1,1.85,0],[2,1.01,0]],"batl":[[0,2.6,580.26],[1,1.98,0]],"ltp":2.0,"tv":92.41,"id":8174357},{"batl":[[0,2.6,78.43],[1,7,2.27]],"ltp":1.98,"tv":335.29,"id":7412952}]}]}
{"op":"mcm","clk":"1005057773","pt":1580640414809,"mc":[{"id":"1.168209734","rc":[{"batl":[[0,7,2.27],[1,7,0]],"ltp":1.98,"tv":335.29,"id":7412952}]}]}
{"op":"mcm","clk":"1005057929","pt":1580640415917,"mc":[{"id":"1.168209734","rc":[{"batb":[[0,1.86,137.97],[1,1.84,170.22],[2,1.01,10.51]],"batl":[[0,1.94,143.88],[1,1.96,142.11],[2,7,2.27]],"ltp":1.98,"tv":335.29,"id":7412952}]}]}
{"op":"mcm","clk":"1005057972","pt":1580640416290,"mc":[{"id":"1.168209734","rc":[{"batb":[[0,1.98,42.85],[1,1.01,10.52]],"batl":[[0,2.18,35.29]],"ltp":2.0,"tv":92.41,"id":8174357},{"batb":[[1,1.85,48.73],[2,1.84,170.22]],"batl":[[2,1.98,445.7]],"ltp":1.98,"tv":335.29,"id":7412952}]}]}
{"op":"mcm","clk":"1005058307","pt":1580640418920,"mc":[{"id":"1.168209734","rc":[{"batl":[[1,2.92,504.71]],"ltp":2.0,"tv":92.41,"id":8174357}]}]}
{"op":"mcm","clk":"1005059863","pt":1580640430821,"mc":[{"id":"1.168209734","rc":[{"batb":[[0,1.85,48.73],[1,1.01,10.51],[2,1.84,0]],"batl":[[0,2.02,41.17],[1,2.36,94.85],[2,7,2.27]],"ltp":1.98,"tv":335.29,"id":7412952}]}]}
{"op":"mcm","clk":"1005059931","pt":1580640431346,"mc":[{"id":"1.168209734","rc":[{"batb":[[0,1.01,10.52],[1,1.01,0]],"batl":[[0,2.92,504.71],[1,2.92,0]],"ltp":2.0,"tv":92.41,"id":8174357},{"batb":[[0,1.01,10.51],[1,1.01,0]],"batl":[[0,2.36,94.85],[1,7,2.27],[2,7,0]],"ltp":1.98,"tv":335.29,"id":7412952}]}]}
{"op":"mcm","clk":"1005060173","pt":1580640433351,"mc":[{"id":"1.168209734","rc":[{"batb":[[0,1.78,154.94],[1,1.76,197.01],[2,1.01,10.51]],"batl":[[0,2.18,172.08],[1,2.2,101.78],[2,2.36,94.85]],"ltp":1.98,"tv":335.29,"id":7412952}]}]}
{"op":"mcm","clk":"1005060583","pt":1580640436540,"mc":[{"id":"1.168209734","rc":[{"batb":[[0,1.01,10.51],[1,1.76,0],[2,1.01,0]],"batl":[[0,2.36,94.85],[1,7,2.27],[2,2.36,0]],"ltp":1.98,"tv":335.29,"id":7412952}]}]}
{"op":"mcm","clk":"1005060859","pt":1580640438905,"mc":[{"id":"1.168209734","rc":[{"batl":[[0,7,2.27],[1,7,0]],"ltp":1.98,"tv":335.29,"id":7412952}]}]}
{"op":"mcm","clk":"1005060973","pt":1580640439639,"mc":[{"id":"1.168209734","rc":[{"batb":[[0,1.85,181.22],[1,1.83,173.36],[2,1.01,10.52]],"batl":[[0,1.93,111.22],[1,1.95,144.43]],"ltp":2.0,"tv":92.41,"id":8174357}]}]}
{"op":"mcm","clk":"1005061116","pt":1580640440838,"mc":[{"id":"1.168209734","rc":[{"batb":[[0,1.81,51.25],[1,1.01,10.52],[2,1.01,0]],"ltp":2.0,"tv":92.41,"id":8174357}]}]}
{"op":"mcm","clk":"1005061332","pt":1580640442824,"mc":[{"id":"1.168209734","rc":[{"batb":[[0,2.04,40.33],[1,1.01,10.51]],"batl":[[0,2.24,33.61],[1,7,2.27]],"ltp":1.98,"tv":335.29,"id":7412952}]}]}
{"op":"mcm","clk":"1005061455","pt":1580640443927,"mc":[{"id":"1.168209734","rc":[{"batb":[[0,1.86,113.2],[1,1.84,170.23],[2,1.81,51.25]],"batl":[[0,1.94,167.71],[1,1.96,142.15],[2,2.6,580.26]],"ltp":2.0,"tv":92.41,"id":8174357},{"batl":[[1,2.6,78.43],[2,7,2.27]],"ltp":1.98,"tv":335.29,"id":7412952}]}]}
{"op":"mcm","clk":"1005061489","pt":1580640444134,"mc":[{"id":"1.168209734","rc":[{"batl":[[1,1.96,184.16]],"ltp":2.0,"tv":92.41,"id":8174357}]}]}
{"op":"mcm","clk":"1005062358","pt":1580640450931,"mc":[{"id":"1.168209734","rc":[{"batb":[[0,1.81,51.25],[1,1.01,10.52],[2,1.81,0]],"batl":[[0,1.96,42.01],[1,2.6,580.26],[2,2.6,0]],"ltp":2.0,"tv":92.41,"id":8174357}]}]}
{"op":"mcm","clk":"1005062443","pt":1580640451661,"mc":[{"id":"1.168209734","rc":[{"batb":[[0,1.01,10.52],[1,1.01,0]],"batl":[[0,2.6,580.26],[1,2.6,0]],"ltp":2.0,"tv":92.41,"id":8174357},{"batb":[[0,1.01,10.51],[1,1.01,0]],"batl":[[0,2.6,78.43],[1,7,2.27],[2,7,0]],"ltp":1.98,"tv":335.29,"id":7412952}]}]}
{"op":"mcm","clk":"1005062649","pt":1580640453543,"mc":[{"id":"1.168209734","rc":[{"batb":[[0,1.56,225.16],[1,1.55,156.79],[2,1.01,10.52]],"batl":[[0,2.14,189.76],[1,2.16,107.14],[2,2.6,580.26]],"ltp":2.0,"tv":92.41,"id":8174357}]}]}
{"op":"mcm","clk":"1005062758","pt":1580640454644,"mc":[{"id":"1.168209734","rc":[{"batb":[[0,1.01,10.52],[1,1.55,0],[2,1.01,0]],"batl":[[0,2.6,580.26],[1,2.16,0],[2,2.6,0]],"ltp":2.0,"tv":92.41,"id":8174357}]}]}
{"op":"mcm","clk":"1005063024","pt":1580640456947,"mc":[{"id":"1.168209734","rc":[{"batb":[[0,1.89,112.91],[1,1.87,161.59],[2,1.01,10.51]],"batl":[[0,1.97,144.25],[1,1.99,135.8],[2,7,2.27]],"ltp":1.98,"tv":335.29,"id":7412952}]}]}
{"op":"mcm","clk":"1005063136","pt":1580640457826,"mc":[{"id":"1.168209734","rc":[{"batl":[[2,2.02,430.35]],"ltp":1.98,"tv":335.29,"id":7412952}]}]}
{"op":"mcm","clk":"1005063190","pt":1580640458345,"mc":[{"id":"1.168209734","rc":[{"batb":[[0,1.96,43.69],[1,1.01,10.52]],"batl":[[0,2.16,36.13],[1,2.6,580.26]],"ltp":2.0,"tv":92.41,"id":8174357},{"batb":[[2,1.86,48.73]],"ltp":1.98,"tv":335.29,"id":7412952}]}]}
{"op":"mcm","clk":"1005065181","pt":1580640475592,"mc":[{"id":"1.168209734","rc":[{"batb":[[0,1.01,10.52],[1,1.01,0]],"batl":[[0,2.6,580.26],[1,2.6,0]],"ltp":2.0,"tv":92.41,"id":8174357},{"batb":[[0,1.01,10.51],[1,1.87,0],[2,1.86,0]],"batl":[[0,2.42,88.82],[1,7,2.27],[2,2.02,0]],"ltp":1.98,"tv":335.29,"id":7412952}]}]}
{"op":"mcm","clk":"1005065560","pt":1580640478801,"mc":[{"id":"1.168209734","rc":[{"batb":[[0,1.78,176.75],[1,1.76,197.08],[2,1.01,10.51]],"batl":[[0,2.28,117.07],[1,2.3,89.94],[2,2.42,88.82]],"ltp":1.98,"tv":335.29,"id":7412952}]}]}
{"op":"mcm","clk":"1005065605","pt":1580640479189,"mc":[{"id":"1.168209734","rc":[{"batb":[[0,1.01,10.51],[1,1.76,0],[2,1.01,0]],"batl":[[0,2.42,88.82],[1,7,2.27],[2,2.42,0]],"ltp":1.98,"tv":335.29,"id":7412952}]}]}
{"op":"mcm","clk":"1005066005","pt":1580640482386,"mc":[{"id":"1.168209734","rc":[{"batb":[[0,1.94,116.47],[1,1.92,148.72],[2,1.01,10.51]],"batl":[[0,2.02,105.69],[1,2.04,126.23],[2,2.42,88.82]],"ltp":1.98,"tv":335.29,"id":7412952}]}]}
{"op":"mcm","clk":"1005066461","pt":1580640485875,"mc":[{"id":"1.168209734","rc":[{"batb":[[0,1.01,10.51],[1,1.92,0],[2,1.01,0]],"batl":[[0,2.42,88.82],[1,7,2.27],[2,2.42,0]],"ltp":1.98,"tv":335.29,"id":7412952}]}]}
{"op":"mcm","clk":"1005066843","pt":1580640488921,"mc":[{"id":"1.168209734","rc":[{"batb":[[0,1.78,176.75],[1,1.76,197.08],[2,1.01,10.51]],"batl":[[0,2.28,117.07],[1,2.3,89.94],[2,2.42,88.82]],"ltp":1.98,"tv":335.29,"id":7412952}]}]}
{"op":"mcm","clk":"1005067345","pt":1580640493195,"mc":[{"id":"1.168209734","rc":[{"batb":[[0,1.01,10.51],[1,1.76,0],[2,1.01,0]],"batl":[[0,2.42,88.82],[1,7,2.27],[2,2.42,0]],"ltp":1.98,"tv":335.29,"id":7412952}]}]}
{"op":"mcm","clk":"1005067658","pt":1580640495790,"mc":[{"id":"1.168209734","rc":[{"batl":[[0,7,2.27],[1,7,0]],"ltp":1.98,"tv":335.29,"id":7412952}]}]}
{"op":"mcm","clk":"1005067728","pt":1580640496412,"mc":[{"id":"1.168209734","rc":[{"batb":[[0,1.78,161.95],[1,1.76,197.12],[2,1.01,10.52]],"batl":[[0,1.85,112.65],[1,1.87,164.23]],"ltp":2.0,"tv":92.41,"id":8174357}]}]}
{"op":"mcm","clk":"1005067994","pt":1580640498729,"mc":[{"id":"1.168209734","rc":[{"batb":[[2,1.74,56.29]],"batl":[[2,1.9,42.01]],"ltp":2.0,"tv":92.41,"id":8174357},{"batb":[[0,2.12,36.97],[1,1.01,10.51]],"batl":[[0,2.34,31.09],[1,2.72,71.39],[2,7,2.27]],"ltp":1.98,"tv":335.29,"id":7412952}]}]}
{"op":"mcm","clk":"1005068585","pt":1580640503899,"mc":[{"id":"1.168209734","rc":[{"batl":[[2,2.5,612.78]],"ltp":2.0,"tv":92.41,"id":8174357}]}]}
{"op":"mcm","clk":"1005068866","pt":1580640506243,"mc":[{"id":"1.168209734","rc":[{"batl":[[2,1.89,42.01]],"ltp":2.0,"tv":92.41,"id":8174357}]}]}
{"op":"mcm","clk":"1005069912","pt":1580640514740,"mc":[{"id":"1.168209734","rc":[{"batb":[[0,1.74,56.29],[1,1.01,10.52],[2,1.74,0]],"batl":[[0,1.89,42.01],[1,2.5,612.78],[2,1.89,0]],"ltp":2.0,"tv":92.41,"id":8174357}]}]}
{"op":"mcm","clk":"1005069972","pt":1580640515357,"mc":[{"id":"1.168209734","rc":[{"batb":[[0,1.01,10.52],[1,1.01,0]],"batl":[[0,2.5,612.78],[1,2.5,0]],"ltp":2.0,"tv":92.41,"id":8174357},{"batb":[[0,1.01,10.51],[1,1.01,0]],"batl":[[0,2.72,71.39],[1,7,2.27],[2,7,0]],"ltp":1.98,"tv":335.29,"id":7412952}]}]}
{"op":"mcm","clk":"1005070242","pt":1580640517558,"mc":[{"id":"1.168209734","rc":[{"batb":[[0,1.41,143.96],[1,1.4,239.22],[2,1.01,10.51]],"batl":[[0,2.14,186.26],[1,2.16,107.13],[2,2.5,612.78]],"ltp":2.0,"tv":92.41,"id":8174357}]}]}
{"op":"mcm","clk":"1005070352","pt":1580640518448,"mc":[{"id":"1.168209734","rc":[{"batb":[[0,1.01,10.52],[1,1.4,0],[2,1.01,0]],"batl":[[0,2.5,612.78],[1,2.16,0],[2,2.5,0]],"ltp":2.0,"tv":92.41,"id":8174357}]}]}
{"op":"mcm","clk":"1005070748","pt":1580640521872,"mc":[{"id":"1.168209734","rc":[{"batb":[[0,1.69,170.07],[1,1.68,116.35],[2,1.01,10.52]],"batl":[[0,1.76,199.13],[1,1.78,191.84]],"ltp":2.0,"tv":92.41,"id":8174357}]}]}
{"op":"mcm","clk":"1005071031","pt":1580640523956,"mc":[{"id":"1.168209734","rc":[{"batb":[[0,1.01,10.52],[1,1.68,0],[2,1.01,0]],"batl":[[0,2.36,665.22],[1,1.78,0]],"ltp":2.0,"tv":92.41,"id":8174357}]}]}
{"op":"mcm","clk":"1005071228","pt":1580640525553,"mc":[{"id":"1.168209734","rc":[{"batl":[[0,7,2.27],[1,7,0]],"ltp":1.98,"tv":335.29,"id":7412952}]}]}
{"op":"mcm","clk":"1005071427","pt":1580640526651,"mc":[{"id":"1.168209734","rc":[{"batb":[[0,1.41,143.96],[1,1.4,239.22],[2,1.01,10.51]],"batl":[[0,2.14,186.26],[1,2.16,107.13]],"ltp":2.0,"tv":92.41,"id":8174357}]}]}
{"op":"mcm","clk":"1005072938","pt":1580640538859,"mc":[{"id":"1.168209734","rc":[{"trd":[[1.48,0.02]],"batb":[[0,1.41,143.95],[2,1.39,107.54]],"batl":[[0,1.45,266.13],[1,1.46,194.93]],"ltp":1.48,"tv":92.43,"id":8174357}],"tv":427.72}]}
{"op":"mcm","clk":"1005073213","pt":1580640540882,"mc":[{"id":"1.168209734","rc":[{"batl":[[2,1.89,909.26]],"ltp":1.48,"tv":92.43,"id":8174357},{"batl":[[0,4.2,49.83],[1,7,2.27]],"ltp":1.98,"tv":335.29,"id":7412952}]}]}
{"op":"mcm","clk":"1005073334","pt":1580640541778,"mc":[{"id":"1.168209734","rc":[{"batl":[[0,3.55,15.96],[1,4.2,49.83],[2,7,2.27]],"ltp":1.98,"tv":335.29,"id":7412952}]}]}
{"op":"mcm","clk":"1005074001","pt":1580640546882,"mc":[{"id":"1.168209734","rc":[{"batl":[[0,1.45,238.29]],"ltp":1.48,"tv":92.43,"id":8174357}]}]}
{"op":"mcm","clk":"1005074402","pt":1580640549794,"mc":[{"id":"1.168209734","rc":[{"batb":[[0,1.41,172.65]],"ltp":1.48,"tv":92.43,"id":8174357}]}]}
{"op":"mcm","clk":"1005074934","pt":1580640553510,"mc":[{"id":"1.168209734","rc":[{"trd":[[1.41,345.3]],"batb":[[0,1.4,239.22],[1,1.39,107.54],[2,1.01,10.51]],"batl":[[0,1.41,163.43],[1,1.45,238.29],[2,1.46,194.93]],"ltp":1.41,"tv":437.73,"id":8174357}],"tv":773.03}]}
{"op":"mcm","clk":"1005075525","pt":1580640557825,"mc":[{"id":"1.168209734","rc":[{"batb":[[0,1.39,107.54],[1,1.01,10.51],[2,1.01,0]],"batl":[[1,1.89,909.26],[2,1.46,0]],"ltp":1.41,"tv":437.73,"id":8174357}]}]}
{"op":"mcm","clk":"1005075770","pt":1580640559606,"mc":[{"id":"1.168209734","rc":[{"batb":[[0,1.01,10.51],[1,1.01,0]],"batl":[[1,1.89,0]],"ltp":1.41,"tv":437.73,"id":8174357},{"batl":[[0,7,2.27],[1,4.2,0],[2,7,0]],"ltp":1.98,"tv":335.29,"id":7412952}]}]}
{"op":"mcm","clk":"1005075920","pt":1580640560915,"mc":[{"id":"1.168209734","rc":[{"batl":[[1,1.83,169.91],[2,1.85,169.83]],"ltp":1.41,"tv":437.73,"id":8174357}]}]}
{"op":"mcm","clk":"1005076244","pt":1580640563832,"mc":[{"id":"1.168209734","rc":[{"trd":[[1.41,672.16]],"batb":[[0,1.74,163.27],[1,1.01,10.51]],"batl":[[0,1.83,169.91],[1,1.85,169.83],[2,1.85,0]],"ltp":1.41,"tv":764.59,"id":8174357}],"tv":1099.88}]}
{"op":"mcm","clk":"1005076348","pt":1580640564712,"mc":[{"id":"1.168209734","rc":[{"batb":[[0,1.01,10.51],[1,1.01,0]],"ltp":1.41,"tv":764.59,"id":8174357}]}]}
{"op":"mcm","clk":"1005076484","pt":1580640565702,"mc":[{"id":"1.168209734","rc":[{"batl":[[0,2.42,638.47]],"ltp":1.41,"tv":764.59,"id":8174357},{"batl":[[0,2.34,37.86],[1,2.82,69.88],[2,7,2.27]],"ltp":1.98,"tv":335.29,"id":7412952}]}]}
{"op":"mcm","clk":"1005076559","pt":1580640566426,"mc":[{"id":"1.168209734","rc":[{"batl":[[0,2.82,69.88],[1,7,2.27],[2,7,0]],"ltp":1.98,"tv":335.29,"id":7412952}]}]}
{"op":"mcm","clk":"1005076750","pt":1580640567938,"mc":[{"id":"1.168209734","rc":[{"batb":[[0,1.75,175.82],[1,1.73,209.44],[2,1.01,10.51]],"batl":[[0,1.85,42.01],[1,2.42,638.47]],"ltp":1.41,"tv":764.59,"id":8174357},{"batb":[[0,2.16,36.13],[1,1.01,10.51]],"ltp":1.98,"tv":335.29,"id":7412952}]}]}
{"op":"mcm","clk":"1005076772","pt":1580640568045,"mc":[{"id":"1.168209734","rc":[{"batb":[[2,1.72,57.97]],"ltp":1.41,"tv":764.59,"id":8174357},{"batl":[[0,2.38,30.25],[1,2.82,69.88],[2,7,2.27]],"ltp":1.98,"tv":335.29,"id":7412952}]}]}
{"op":"mcm","clk":"1005077128","pt":1580640570823,"mc":[{"id":"1.168209734","rc":[{"batb":[[0,1.75,204.88]],"batl":[[0,1.83,188.54],[1,1.85,212.01],[2,2.42,638.47]],"ltp":1.41,"tv":764.59,"id":8174357}]}]}
{"op":"mcm","clk":"1005078245","pt":1580640579931,"mc":[{"id":"1.168209734","rc":[{"batb":[[0,1.72,57.97],[1,1.01,10.51],[2,1.72,0]],"batl":[[0,1.85,42.01],[1,2.42,638.47],[2,2.42,0]],"ltp":1.41,"tv":764.59,"id":8174357}]}]}
{"op":"mcm","clk":"1005078417","pt":1580640581354,"mc":[{"id":"1.168209734","rc":[{"batb":[[0,1.01,10.51],[1,1.01,0]],"batl":[[0,2.42,638.47],[1,2.42,0]],"ltp":1.41,"tv":764.59,"id":8174357},{"batb":[[0,1.01,10.51],[1,1.01,0]],"batl":[[0,2.82,69.88],[1,7,2.27],[2,7,0]],"ltp":1.98,"tv":335.29,"id":7412952}]}]}
{"op":"mcm","clk":"1005078617","pt":1580640582763,"mc":[{"id":"1.168209734","rc":[{"batb":[[0,1.39,283.13],[1,1.38,257.83],[2,1.01,10.51]],"batl":[[0,2.1,151.23],[1,2.12,113.12],[2,2.42,638.47]],"ltp":1.41,"tv":764.59,"id":8174357}]}]}
{"op":"mcm","clk":"1005078726","pt":1580640583652,"mc":[{"id":"1.168209734","rc":[{"batb":[[0,1.01,10.51],[1,1.38,0],[2,1.01,0]],"batl":[[0,2.42,638.47],[1,2.12,0],[2,2.42,0]],"ltp":1.41,"tv":764.59,"id":8174357}]}]}
{"op":"mcm","clk":"1005078998","pt":1580640585861,"mc":[{"id":"1.168209734","rc":[{"batl":[[0,7,2.27],[1,7,0]],"ltp":1.98,"tv":335.29,"id":7412952}]}]}
{"op":"mcm","clk":"1005079123","pt":1580640586855,"mc":[{"id":"1.168209734","rc":[{"batb":[[0,1.91,159.31],[1,1.89,156.51],[2,1.01,10.51]],"batl":[[0,2,152.27],[1,2.02,130.11],[2,7,2.27]],"ltp":1.98,"tv":335.29,"id":7412952}]}]}
{"op":"mcm","clk":"1005079134","pt":1580640586958,"mc":[{"id":"1.168209734","rc":[{"batl":[[1,2.02,558.59]],"ltp":1.98,"tv":335.29,"id":7412952}]}]}
{"op":"mcm","clk":"1005079335","pt":1580640588373,"mc":[{"id":"1.168209734","rc":[{"batb":[[0,1.95,43.69],[1,1.01,10.51]],"batl":[[0,2.14,36.13]],"ltp":1.41,"tv":764.59,"id":8174357},{"batb":[[2,1.87,47.89]],"batl":[[2,2.04,40.33]],"ltp":1.98,"tv":335.29,"id":7412952}]}]}
{"op":"mcm","clk":"1005079498","pt":1580640589578,"mc":[{"id":"1.168209734","rc":[{"batl":[[1,2.82,525.27]],"ltp":1.41,"tv":764.59,"id":8174357}]}]}
{"op":"mcm","clk":"1005080828","pt":1580640599352,"mc":[{"id":"1.168209734","rc":[{"batb":[[0,1.01,10.51],[1,1.01,0]],"batl":[[0,2.82,525.27],[1,2.82,0]],"ltp":1.41,"tv":764.59,"id":8174357},{"batb":[[0,1.01,10.51],[1,1.89,0],[2,1.87,0]],"batl":[[0,2.42,88.82],[1,7,2.27],[2,2.04,0]],"ltp":1.98,"tv":335.29,"id":7412952}]}]}
{"op":"mcm","clk":"1005081186","pt":1580640601942,"mc":[{"id":"1.168209734","rc":[{"batb":[[0,1.79,166.03],[1,1.77,193.59],[2,1.01,10.51]],"batl":[[0,2.36,95.99],[1,2.38,82.09],[2,2.42,88.82]],"ltp":1.98,"tv":335.29,"id":7412952}]}]}
{"op":"mcm","clk":"1005081659","pt":1580640605356,"mc":[{"id":"1.168209734","rc":[{"batl":[[0,2.42,88.82],[1,7,2.27],[2,2.42,0]],"ltp":1.98,"tv":335.29,"id":7412952}]}]}
{"op":"mcm","clk":"1005082000","pt":1580640607884,"mc":[{"id":"1.168209734","rc":[{"batl":[[0,7,2.27],[1,7,0]],"ltp":1.98,"tv":335.29,"id":7412952}]}]}
{"op":"mcm","clk":"1005082087","pt":1580640608404,"mc":[{"id":"1.168209734","rc":[{"batl":[[0,1.87,181.56],[1,1.89,158.87],[2,7,2.27]],"ltp":1.98,"tv":335.29,"id":7412952}]}]}
{"op":"mcm","clk":"1005082359","pt":1580640610387,"mc":[{"id":"1.168209734","rc":[{"batb":[[0,2.12,36.97],[1,1.01,10.51]],"batl":[[0,2.34,31.09],[1,2.82,525.27]],"ltp":1.41,"tv":764.59,"id":8174357},{"batb":[[2,1.76,54.61]],"batl":[[2,1.9,42.01]],"ltp":1.98,"tv":335.29,"id":7412952}]}]}
{"op":"mcm","clk":"1005085980","pt":1580640636825,"mc":[{"id":"1.168209734","rc":[{"batb":[[0,1.76,54.61],[1,1.01,10.51],[2,1.76,0]],"batl":[[0,1.9,42.01],[1,2.3,97.52],[2,7,2.27]],"ltp":1.98,"tv":335.29,"id":7412952}]}]}
{"op":"mcm","clk":"1005086147","pt":1580640637908,"mc":[{"id":"1.168209734","rc":[{"batb":[[0,1.01,10.51],[1,1.01,0]],"batl":[[0,2.82,525.27],[1,2.82,0]],"ltp":1.41,"tv":764.59,"id":8174357},{"batb":[[0,1.01,10.51],[1,1.01,0]],"batl":[[0,2.3,97.52],[1,7,2.27],[2,7,0]],"ltp":1.98,"tv":335.29,"id":7412952}]}]}
{"op":"mcm","clk":"1005086385","pt":1580640639633,"mc":[{"id":"1.168209734","rc":[{"batb":[[0,1.59,153.56],[1,1.58,145.35],[2,1.01,10.51]],"batl":[[0,2,98.48],[1,2.02,130.13],[2,2.3,97.52]],"ltp":1.98,"tv":335.29,"id":7412952}]}]}
{"op":"mcm","clk":"1005087213","pt":1580640645951,"mc":[{"id":"1.168209734","rc":[{"batb":[[0,1.01,10.51],[1,1.58,0],[2,1.01,0]],"ltp":1.98,"tv":335.29,"id":7412952}]}]}
{"op":"mcm","clk":"1005087544","pt":1580640648924,"mc":[{"id":"1.168209734","rc":[{"batb":[[0,1.92,138.93],[1,1.9,153.92],[2,1.01,10.51]],"ltp":1.98,"tv":335.29,"id":7412952}]}]}
{"op":"mcm","clk":"1005087689","pt":1580640650337,"mc":[{"id":"1.168209734","rc":[{"batb":[[0,1.95,43.69],[1,1.01,10.51]],"batl":[[0,2.16,36.13],[1,2.82,525.27]],"ltp":1.41,"tv":764.59,"id":8174357},{"batb":[[2,1.87,47.89]],"batl":[[2,2.04,40.33]],"ltp":1.98,"tv":335.29,"id":7412952}]}]}
{"op":"mcm","clk":"1005089108","pt":1580640662761,"mc":[{"id":"1.168209734","rc":[{"batb":[[0,1.87,47.89],[1,1.01,10.51],[2,1.87,0]],"batl":[[0,2.04,40.33],[1,2.3,97.52],[2,7,2.27]],"ltp":1.98,"tv":335.29,"id":7412952}]}]}
{"op":"mcm","clk":"1005089233","pt":1580640663645,"mc":[{"id":"1.168209734","rc":[{"batb":[[0,1.01,10.51],[1,1.01,0]],"batl":[[0,2.82,525.27],[1,2.82,0]],"ltp":1.41,"tv":764.59,"id":8174357},{"batb":[[0,1.01,10.51],[1,1.01,0]],"batl":[[0,2.3,97.52],[1,7,2.27],[2,7,0]],"ltp":1.98,"tv":335.29,"id":7412952}]}]}
{"op":"mcm","clk":"1005089849","pt":1580640668758,"mc":[{"id":"1.168209734","rc":[{"batb":[[0,1.88,153.85],[1,1.86,164.67],[2,1.01,10.51]],"batl":[[0,1.96,113.59],[1,1.98,138.08],[2,2.3,97.52]],"ltp":1.98,"tv":335.29,"id":7412952}]}]}
{"op":"mcm","clk":"1005090355","pt":1580640672658,"mc":[{"id":"1.168209734","rc":[{"batb":[[0,1.01,10.51],[1,1.86,0],[2,1.01,0]],"batl":[[0,2.3,97.52],[1,7,2.27],[2,2.3,0]],"ltp":1.98,"tv":335.29,"id":7412952}]}]}
{"op":"mcm","clk":"1005090592","pt":1580640674639,"mc":[{"id":"1.168209734","rc":[{"trd":[[2.82,0.01]],"batl":[[0,2.82,525.26]],"ltp":2.82,"tv":764.6,"id":8174357},{"trd":[[1.54,0.02]],"ltp":1.54,"tv":335.3,"id":7412952}],"tv":1099.91}]}
{"op":"mcm","clk":"1005090748","pt":1580640675879,"mc":[{"id":"1.168209734","rc":[{"batb":[[0,1.74,171.7],[1,1.72,213.27],[2,1.01,10.51]],"batl":[[0,2.12,117.65],[1,2.14,110.14],[2,2.3,97.52]],"ltp":1.54,"tv":335.3,"id":7412952}]}]}
{"op":"mcm","clk":"1005090996","pt":1580640677959,"mc":[{"id":"1.168209734","rc":[{"batl":[[0,2.3,97.52],[1,7,2.27],[2,2.3,0]],"ltp":1.54,"tv":335.3,"id":7412952}]}]}
{"op":"mcm","clk":"1005091359","pt":1580640680957,"mc":[{"id":"1.168209734","rc":[{"batl":[[0,1.81,142.25],[1,1.83,175.8],[2,2.3,97.52]],"ltp":1.54,"tv":335.3,"id":7412952}]}]}
{"op":"mcm","clk":"1005091563","pt":1580640682690,"mc":[{"id":"1.168209734","rc":[{"batb":[[0,2.18,35.29],[1,1.01,10.51]],"batl":[[0,2.42,29.41]],"ltp":2.82,"tv":764.6,"id":8174357},{"batl":[[2,1.85,42.01]],"ltp":1.54,"tv":335.3,"id":7412952}]}]}
{"op":"mcm","clk":"1005091693","pt":1580640683791,"mc":[{"id":"1.168209734","rc":[{"batl":[[1,3.15,459.05]],"ltp":2.82,"tv":764.6,"id":8174357}]}]}
{"op":"mcm","clk":"1005091779","pt":1580640684370,"mc":[{"id":"1.168209734","rc":[{"batb":[[2,1.71,58.81]],"ltp":1.54,"tv":335.3,"id":7412952}]}]}
{"op":"mcm","clk":"1005092739","pt":1580640692914,"mc":[{"id":"1.168209734","rc":[{"batb":[[0,1.71,58.81],[1,1.01,10.51],[2,1.71,0]],"batl":[[0,1.85,42.01],[1,2.3,97.52],[2,7,2.27]],"ltp":1.54,"tv":335.3,"id":7412952}]}]}
{"op":"mcm","clk":"1005092794","pt":1580640693493,"mc":[{"id":"1.168209734","rc":[{"batb":[[0,1.01,10.51],[1,1.01,0]],"batl":[[0,3.15,459.05],[1,3.15,0]],"ltp":2.82,"tv":764.6,"id":8174357},{"batb":[[0,1.01,10.51],[1,1.01,0]],"batl":[[0,2.3,97.52],[1,7,2.27],[2,7,0]],"ltp":1.54,"tv":335.3,"id":7412952}]}]}
{"op":"mcm","clk":"1005093251","pt":1580640697794,"mc":[{"id":"1.168209734","rc":[{"batl":[[0,7,2.27],[1,7,0]],"ltp":1.54,"tv":335.3,"id":7412952}]}]}
{"op":"mcm","clk":"1005093375","pt":1580640698896,"mc":[{"id":"1.168209734","rc":[{"batb":[[0,1.69,135.44],[1,1.68,116.3],[2,1.01,10.51]],"batl":[[0,1.75,133.62],[1,1.77,195.68],[2,7,2.27]],"ltp":1.54,"tv":335.3,"id":7412952}]}]}
{"op":"mcm","clk":"1005093660","pt":1580640701510,"mc":[{"id":"1.168209734","rc":[{"batb":[[0,1.01,10.51],[1,1.68,0],[2,1.01,0]],"batl":[[0,2.16,111.54],[1,7,2.27],[2,7,0]],"ltp":1.54,"tv":335.3,"id":7412952}]}]}
{"op":"mcm","clk":"1005093987","pt":1580640704083,"mc":[{"id":"1.168209734","rc":[{"batb":[[0,1.5,234.11],[1,1.49,183.35],[2,1.01,10.51]],"batl":[[0,1.99,161.48],[1,2.02,196.11],[2,2.16,111.54]],"ltp":1.54,"tv":335.3,"id":7412952}]}]}
{"op":"mcm","clk":"1005094170","pt":1580640705492,"mc":[{"id":"1.168209734","rc":[{"batb":[[0,1.01,10.51],[1,1.49,0],[2,1.01,0]],"ltp":1.54,"tv":335.3,"id":7412952}]}]}
{"op":"mcm","clk":"1005094410","pt":1580640707628,"mc":[{"id":"1.168209734","rc":[{"batl":[[2,7,2.27]],"ltp":1.54,"tv":335.3,"id":7412952}]}]}
{"op":"mcm","clk":"1005094538","pt":1580640708721,"mc":[{"id":"1.168209734","rc":[{"batb":[[0,1.9,158.3],[1,1.88,159.17],[2,1.01,10.51]],"ltp":1.54,"tv":335.3,"id":7412952}]}]}
{"op":"mcm","clk":"1005094736","pt":1580640710397,"mc":[{"id":"1.168209734","rc":[{"batb":[[0,1.97,42.85],[1,1.01,10.51]],"batl":[[0,2.16,36.13]],"ltp":2.82,"tv":764.6,"id":8174357},{"batb":[[2,1.86,48.73]],"batl":[[1,2.02,237.28]],"ltp":1.54,"tv":335.3,"id":7412952}]}]}
{"op":"mcm","clk":"1005094840","pt":1580640711384,"mc":[{"id":"1.168209734","rc":[{"batl":[[1,2.82,525.26]],"ltp":2.82,"tv":764.6,"id":8174357},{"batl":[[2,2.42,88.83]],"ltp":1.54,"tv":335.3,"id":7412952}]}]}
{"op":"mcm","clk":"1005096266","pt":1580640722741,"mc":[{"id":"1.168209734","rc":[{"batb":[[0,1.86,48.73],[1,1.01,10.51],[2,1.86,0]],"batl":[[0,2.02,41.17],[1,2.42,88.83],[2,7,2.27]],"ltp":1.54,"tv":335.3,"id":7412952}]}]}
{"op":"mcm","clk":"1005096409","pt":1580640723808,"mc":[{"id":"1.168209734","rc":[{"batb":[[0,1.01,10.51],[1,1.01,0]],"batl":[[0,2.82,525.26],[1,2.82,0]],"ltp":2.82,"tv":764.6,"id":8174357},{"batb":[[0,1.01,10.51],[1,1.01,0]],"batl":[[0,2.42,88.83],[1,7,2.27],[2,7,0]],"ltp":1.54,"tv":335.3,"id":7412952}]}]}
{"op":"mcm","clk":"1005096551","pt":1580640725109,"mc":[{"id":"1.168209734","rc":[{"batb":[[0,1.69,177.41],[1,1.68,116.41],[2,1.01,10.51]],"batl":[[0,2.14,178.5],[1,2.16,107.32],[2,2.42,88.83]],"ltp":1.54,"tv":335.3,"id":7412952}]}]}
{"op":"mcm","clk":"1005096960","pt":1580640728920,"mc":[{"id":"1.168209734","rc":[{"batl":[[0,2.42,88.83],[1,7,2.27],[2,2.42,0]],"ltp":1.54,"tv":335.3,"id":7412952}]}]}
{"op":"mcm","clk":"1005097155","pt":1580640730730,"mc":[{"id":"1.168209734","rc":[{"batl":[[0,7,2.27],[1,7,0]],"ltp":1.54,"tv":335.3,"id":7412952}]}]}
{"op":"mcm","clk":"1005097289","pt":1580640731935,"mc":[{"id":"1.168209734","rc":[{"batb":[[2,1.01,10.52]],"batl":[[0,1.76,192.37],[1,1.78,191.9],[2,7,2.27]],"ltp":1.54,"tv":335.3,"id":7412952}]}]}
{"op":"mcm","clk":"1005097384","pt":1580640732950,"mc":[{"id":"1.168209734","rc":[{"batb":[[0,2.26,32.77],[1,1.01,10.51]],"batl":[[0,2.52,26.89]],"ltp":2.82,"tv":764.6,"id":8174357},{"batb":[[2,1.67,62.17]],"batl":[[2,1.8,42.01]],"ltp":1.54,"tv":335.3,"id":7412952}]}]}
{"op":"mcm","clk":"1005097604","pt":1580640734825,"mc":[{"id":"1.168209734","rc":[{"batl":[[1,3.3,438.62]],"ltp":2.82,"tv":764.6,"id":8174357}]}]}
{"op":"mcm","clk":"1005098825","pt":1580640745868,"mc":[{"id":"1.168209734","rc":[{"batb":[[0,1.67,62.17],[1,1.01,10.52],[2,1.67,0]],"batl":[[0,1.8,42.01],[1,2.16,111.54],[2,7,2.27]],"ltp":1.54,"tv":335.3,"id":7412952}]}]}
{"op":"mcm","clk":"1005099074","pt":1580640747957,"mc":[{"id":"1.168209734","rc":[{"batb":[[0,1.01,10.51],[1,1.01,0]],"batl":[[0,3.3,438.62],[1,3.3,0]],"ltp":2.82,"tv":764.6,"id":8174357},{"batb":[[0,1.01,10.52],[1,1.01,0]],"batl":[[0,2.16,111.54],[1,7,2.27],[2,7,0]],"ltp":1.54,"tv":335.3,"id":7412952}]}]}
{"op":"mcm","clk":"1005099167","pt":1580640748749,"mc":[{"id":"1.168209734","rc":[{"batb":[[0,1.39,162.25],[1,1.38,255.32],[2,1.01,10.51]],"batl":[[0,2,115.67],[1,2.02,130.14],[2,2.16,111.54]],"ltp":1.54,"tv":335.3,"id":7412952}]}]}
{"op":"mcm","clk":"1005099757","pt":1580640753757,"mc":[{"id":"1.168209734","rc":[{"batb":[[0,1.01,10.52],[1,1.38,0],[2,1.01,0]],"ltp":1.54,"tv":335.3,"id":7412952}]}]}
{"op":"mcm","clk":"1005100021","pt":1580640755846,"mc":[{"id":"1.168209734","rc":[{"batl":[[2,7,2.27]],"ltp":1.54,"tv":335.3,"id":7412952}]}]}
{"op":"mcm","clk":"1005100116","pt":1580640756776,"mc":[{"id":"1.168209734","rc":[{"batb":[[0,1.96,43.69],[1,1.01,10.51]],"batl":[[0,2.16,36.13]],"ltp":2.82,"tv":764.6,"id":8174357},{"batb":[[0,1.92,121.04],[1,1.9,153.92],[2,1.86,48.73]],"ltp":1.54,"tv":335.3,"id":7412952}]}]}
{"op":"mcm","clk":"1005100230","pt":1580640757765,"mc":[{"id":"1.168209734","rc":[{"batl":[[0,2.14,36.13]],"ltp":2.82,"tv":764.6,"id":8174357},{"batb":[[2,1.88,47.05]],"batl":[[2,2.04,40.33]],"ltp":1.54,"tv":335.3,"id":7412952}]}]}
{"op":"mcm","clk":"1005100533","pt":1580640760164,"mc":[{"id":"1.168209734","rc":[{"batl":[[1,2.82,525.26]],"ltp":2.82,"tv":764.6,"id":8174357}]}]}
{"op":"mcm","clk":"1005102328","pt":1580640774900,"mc":[{"id":"1.168209734","rc":[{"batb":[[0,1.88,47.05],[1,1.01,10.52],[2,1.88,0]],"batl":[[0,2.04,40.33],[1,2.42,88.83],[2,7,2.27]],"ltp":1.54,"tv":335.3,"id":7412952}]}]}
{"op":"mcm","clk":"1005102438","pt":1580640775893,"mc":[{"id":"1.168209734","rc":[{"batb":[[0,1.01,10.51],[1,1.01,0]],"batl":[[0,2.82,525.26],[1,2.82,0]],"ltp":2.82,"tv":764.6,"id":8174357},{"batb":[[0,1.01,10.52],[1,1.01,0]],"batl":[[0,2.42,88.83],[1,7,2.27],[2,7,0]],"ltp":1.54,"tv":335.3,"id":7412952}]}]}
{"op":"mcm","clk":"1005102656","pt":1580640777788,"mc":[{"id":"1.168209734","rc":[{"batb":[[0,1.68,160.4],[1,1.67,118.84],[2,1.01,10.52]],"batl":[[0,2.18,184.44],[1,2.2,101.95],[2,2.42,88.83]],"ltp":1.54,"tv":335.3,"id":7412952}]}]}
{"op":"mcm","clk":"1005103632","pt":1580640785917,"mc":[{"id":"1.168209734","rc":[{"batb":[[0,1.01,10.52],[1,1.67,0],[2,1.01,0]],"batl":[[0,2.42,88.83],[1,2.2,0],[2,2.42,0]],"ltp":1.54,"tv":335.3,"id":7412952}]}]}
{"op":"mcm","clk":"1005103867","pt":1580640787898,"mc":[{"id":"1.168209734","rc":[{"batl":[[1,3,2.27]],"ltp":1.54,"tv":335.3,"id":7412952}]}]}
{"op":"mcm","clk":"1005103980","pt":1580640788894,"mc":[{"id":"1.168209734","rc":[{"batb":[[0,1.86,110.88],[1,1.84,170.51],[2,1.01,10.51]],"batl":[[0,1.94,170.97],[1,1.96,142.39]],"ltp":2.82,"tv":764.6,"id":8174357},{"batl":[[0,3,2.27],[1,3,0]],"ltp":1.54,"tv":335.3,"id":7412952}]}]}
{"op":"mcm","clk":"1005104161","pt":1580640790495,"mc":[{"id":"1.168209734","rc":[{"batb":[[2,1.79,52.93]],"batl":[[1,1.96,184.4]],"ltp":2.82,"tv":764.6,"id":8174357},{"batb":[[0,2.04,40.33],[1,1.01,10.52]],"batl":[[0,2.26,32.77],[1,3,2.27]],"ltp":1.54,"tv":335.3,"id":7412952}]}]}
{"op":"mcm","clk":"1005104382","pt":1580640792419,"mc":[{"id":"1.168209734","rc":[{"batl":[[2,2.5,617.42]],"ltp":2.82,"tv":764.6,"id":8174357},{"batl":[[1,2.72,75.65],[2,3,2.27]],"ltp":1.54,"tv":335.3,"id":7412952}]}]}
{"op":"mcm","clk":"1005115397","pt":1580640885946,"mc":[{"id":"1.168209734","rc":[{"batb":[[0,1.79,52.93],[1,1.01,10.51],[2,1.79,0]],"batl":[[0,1.96,42.01],[1,2.5,617.42],[2,2.5,0]],"ltp":2.82,"tv":764.6,"id":8174357}]}]}
{"op":"mcm","clk":"1005115627","pt":1580640887736,"mc":[{"id":"1.168209734","rc":[{"batb":[[0,1.01,10.51],[1,1.01,0]],"batl":[[0,2.5,617.42],[1,2.5,0]],"ltp":2.82,"tv":764.6,"id":8174357},{"batb":[[0,1.01,10.52],[1,1.01,0]],"batl":[[0,2.72,75.65],[1,3,2.27],[2,3,0]],"ltp":1.54,"tv":335.3,"id":7412952}]}]}
{"op":"mcm","clk":"1005115766","pt":1580640888922,"mc":[{"id":"1.168209734","rc":[{"batb":[[0,1.63,138.68],[1,1.62,132.74],[2,1.01,10.51]],"batl":[[0,2.08,157.09],[1,2.1,116.26],[2,2.5,617.42]],"ltp":2.82,"tv":764.6,"id":8174357}]}]}
{"op":"mcm","clk":"1005115865","pt":1580640889756,"mc":[{"id":"1.168209734","rc":[{"batb":[[0,1.01,10.51],[1,1.62,0],[2,1.01,0]],"batl":[[0,2.5,617.42],[1,2.1,0],[2,2.5,0]],"ltp":2.82,"tv":764.6,"id":8174357}]}]}
{"op":"mcm","clk":"1005116067","pt":1580640891528,"mc":[{"id":"1.168209734","rc":[{"batl":[[0,3,2.27],[1,3,0]],"ltp":1.54,"tv":335.3,"id":7412952}]}]}
{"op":"mcm","clk":"1005116256","pt":1580640892837,"mc":[{"id":"1.168209734","rc":[{"batb":[[0,1.93,139.05],[1,1.91,151.42],[2,1.01,10.52]],"batl":[[0,2.02,155.9],[1,2.04,126.43],[2,3,2.27]],"ltp":1.54,"tv":335.3,"id":7412952}]}]}
{"op":"mcm","clk":"1005116478","pt":1580640894551,"mc":[{"id":"1.168209734","rc":[{"batb":[[0,1.91,45.37],[1,1.01,10.51]],"batl":[[0,2.1,37.81],[1,2.5,617.42]],"ltp":2.82,"tv":764.6,"id":8174357},{"batb":[[1,1.91,196.79]],"batl":[[2,2.1,37.81]],"ltp":1.54,"tv":335.3,"id":7412952}]}]}
{"op":"mcm","clk":"1005118056","pt":1580640906867,"mc":[{"id":"1.168209734","rc":[{"batb":[[0,1.91,45.37],[1,1.01,10.52],[2,1.01,0]],"batl":[[0,2.1,37.81],[1,2.5,86.2],[2,3,2.27]],"ltp":1.54,"tv":335.3,"id":7412952}]}]}
{"op":"mcm","clk":"1005118185","pt":1580640907864,"mc":[{"id":"1.168209734","rc":[{"batb":[[0,1.01,10.51],[1,1.01,0]],"batl":[[0,2.5,617.42],[1,2.5,0]],"ltp":2.82,"tv":764.6,"id":8174357},{"batb":[[0,1.01,10.52],[1,1.01,0]],"batl":[[0,2.5,86.2],[1,3,2.27],[2,3,0]],"ltp":1.54,"tv":335.3,"id":7412952}]}]}
{"op":"mcm","clk":"1005118455","pt":1580640909953,"mc":[{"id":"1.168209734","rc":[{"batb":[[0,1.84,166.16],[1,1.82,176.66],[2,1.01,10.52]],"batl":[[0,2.26,87.31],[1,2.28,92.25],[2,2.5,86.2]],"ltp":1.54,"tv":335.3,"id":7412952}]}]}
{"op":"mcm","clk":"1005118964","pt":1580640913850,"mc":[{"id":"1.168209734","rc":[{"batb":[[0,1.01,10.52],[1,1.82,0],[2,1.01,0]],"batl":[[0,2.5,86.2],[1,3,2.27],[2,2.5,0]],"ltp":1.54,"tv":335.3,"id":7412952}]}]}
{"op":"mcm","clk":"1005119347","pt":1580640916806,"mc":[{"id":"1.168209734","rc":[{"batb":[[0,1.79,144.62],[1,1.77,193.73],[2,1.75,55.45]],"batl":[[0,1.86,121.43],[1,1.88,161.81],[2,2.5,617.42]],"ltp":2.82,"tv":764.6,"id":8174357},{"batl":[[0,2.3,31.93],[1,2.5,86.2],[2,3,2.27]],"ltp":1.54,"tv":335.3,"id":7412952}]}]}
{"op":"mcm","clk":"1005121141","pt":1580640931577,"mc":[{"id":"1.168209734","rc":[{"batb":[[0,1.01,10.51],[1,1.77,0],[2,1.75,0]],"batl":[[0,2.5,617.42],[1,1.88,0],[2,2.5,0]],"ltp":2.82,"tv":764.6,"id":8174357},{"batl":[[0,2.5,86.2],[1,3,2.27],[2,3,0]],"ltp":1.54,"tv":335.3,"id":7412952}]}]}
{"op":"mcm","clk":"1005121452","pt":1580640934178,"mc":[{"id":"1.168209734","rc":[{"batb":[[0,1.52,159.35],[1,1.51,173.83],[2,1.01,10.51]],"batl":[[0,2.04,120.13],[1,2.06,122.9],[2,2.5,617.42]],"ltp":2.82,"tv":764.6,"id":8174357}]}]}
{"op":"mcm","clk":"1005121692","pt":1580640936198,"mc":[{"id":"1.168209734","rc":[{"batb":[[0,1.01,10.51],[1,1.51,0],[2,1.01,0]],"ltp":2.82,"tv":764.6,"id":8174357}]}]}
{"op":"mcm","clk":"1005122009","pt":1580640938893,"mc":[{"id":"1.168209734","rc":[{"batb":[[0,1.95,160.82],[1,1.93,146.58],[2,1.01,10.51]],"ltp":2.82,"tv":764.6,"id":8174357}]}]}
{"op":"mcm","clk":"1005122218","pt":1580640940513,"mc":[{"id":"1.168209734","rc":[{"batb":[[2,1.9,46.21]],"batl":[[2,2.08,38.65]],"ltp":2.82,"tv":764.6,"id":8174357},{"batb":[[0,1.92,45.37],[1,1.01,10.52]],"batl":[[0,2.1,37.81],[1,2.5,86.2],[2,3,2.27]],"ltp":1.54,"tv":335.3,"id":7412952}]}]}
{"op":"mcm","clk":"1005123346","pt":1580640949917,"mc":[{"id":"1.168209734","rc":[{"batb":[[0,1.9,46.21],[1,1.01,10.51],[2,1.9,0]],"batl":[[0,2.08,38.65],[1,2.5,617.42],[2,2.08,0]],"ltp":2.82,"tv":764.6,"id":8174357}]}]}
{"op":"mcm","clk":"1005123548","pt":1580640951524,"mc":[{"id":"1.168209734","rc":[{"batb":[[0,1.01,10.51],[1,1.01,0]],"batl":[[0,2.5,617.42],[1,2.5,0]],"ltp":2.82,"tv":764.6,"id":8174357},{"batb":[[0,1.01,10.52],[1,1.01,0]],"batl":[[0,2.5,86.2],[1,3,2.27],[2,3,0]],"ltp":1.54,"tv":335.3,"id":7412952}]}]}
{"op":"mcm","clk":"1005124070","pt":1580640955732,"mc":[{"id":"1.168209734","rc":[{"batb":[[0,1.9,157.2],[1,1.88,159.2],[2,1.01,10.51]],"batl":[[0,1.99,162.75],[1,2.02,196.2],[2,2.5,617.42]],"ltp":2.82,"tv":764.6,"id":8174357}]}]}
{"op":"mcm","clk":"1005124540","pt":1580640959533,"mc":[{"id":"1.168209734","rc":[{"batb":[[0,1.01,10.51],[1,1.88,0],[2,1.01,0]],"batl":[[0,2.5,617.42],[1,2.02,0],[2,2.5,0]],"ltp":2.82,"tv":764.6,"id":8174357}]}]}
{"op":"mcm","clk":"1005124845","pt":1580640961942,"mc":[{"id":"1.168209734","rc":[{"batb":[[0,1.72,178.55],[1,1.7,222.38],[2,1.01,10.51]],"batl":[[0,2.18,107.17],[1,2.2,101.82],[2,2.5,617.42]],"ltp":2.82,"tv":764.6,"id":8174357}]}]}
{"op":"mcm","clk":"1005125393","pt":1580640965934,"mc":[{"id":"1.168209734","rc":[{"batb":[[0,1.01,10.51],[1,1.7,0],[2,1.01,0]],"batl":[[0,2.5,617.42],[1,2.2,0],[2,2.5,0]],"ltp":2.82,"tv":764.6,"id":8174357}]}]}
{"op":"mcm","clk":"1005125629","pt":1580640967951,"mc":[{"id":"1.168209734","rc":[{"batl":[[0,3,2.27],[1,3,0]],"ltp":1.54,"tv":335.3,"id":7412952}]}]}
{"op":"mcm","clk":"1005125702","pt":1580640968636,"mc":[{"id":"1.168209734","rc":[{"batb":[[0,2.02,41.17],[1,1.01,10.51]],"batl":[[0,2.22,33.61]],"ltp":2.82,"tv":764.6,"id":8174357},{"batb":[[0,1.85,104.72],[1,1.83,173.43],[2,1.81,51.25]],"batl":[[0,1.92,111.11],[1,1.94,146.83],[2,1.98,42.01]],"ltp":1.54,"tv":335.3,"id":7412952}]}]}
{"op":"mcm","clk":"1005126044","pt":1580640971845,"mc":[{"id":"1.168209734","rc":[{"batl":[[1,2.92,502.19]],"ltp":2.82,"tv":764.6,"id":8174357}]}]}
{"op":"mcm","clk":"1005128115","pt":1580640988779,"mc":[{"id":"1.168209734","rc":[{"batb":[[0,1.81,51.25],[1,1.01,10.52],[2,1.81,0]],"batl":[[0,1.98,42.01],[1,2.36,91.77],[2,3,2.27]],"ltp":1.54,"tv":335.3,"id":7412952}]}]}
{"op":"mcm","clk":"1005128223","pt":1580640989566,"mc":[{"id":"1.168209734","rc":[{"batb":[[0,1.01,10.51],[1,1.01,0]],"batl":[[0,2.92,502.19],[1,2.92,0]],"ltp":2.82,"tv":764.6,"id":8174357},{"batb":[[0,1.01,10.52],[1,1.01,0]],"batl":[[0,2.36,91.77],[1,3,2.27],[2,3,0]],"ltp":1.54,"tv":335.3,"id":7412952}]}]}
{"op":"mcm","clk":"1005128525","pt":1580640991601,"mc":[{"id":"1.168209734","rc":[{"batb":[[0,1.8,164.43],[1,1.78,190.02],[2,1.01,10.52]],"batl":[[0,2.04,98.03],[1,2.06,122.88],[2,2.36,91.77]],"ltp":1.54,"tv":335.3,"id":7412952}]}]}
{"op":"mcm","clk":"1005128958","pt":1580640994884,"mc":[{"id":"1.168209734","rc":[{"batl":[[0,2.36,91.77],[1,3,2.27],[2,2.36,0]],"ltp":1.54,"tv":335.3,"id":7412952}]}]}
{"op":"mcm","clk":"1005129315","pt":1580640997897,"mc":[{"id":"1.168209734","rc":[{"batl":[[0,1.88,173.27],[1,1.9,156.35],[2,2.36,91.77]],"ltp":1.54,"tv":335.3,"id":7412952}]}]}
{"op":"mcm","clk":"1005129390","pt":1580640998578,"mc":[{"id":"1.168209734","rc":[{"batb":[[0,2.08,38.65],[1,1.01,10.51]],"batl":[[0,2.3,31.93],[1,2.92,502.19]],"ltp":2.82,"tv":764.6,"id":8174357},{"batb":[[2,1.77,53.77]],"batl":[[2,1.93,42.01]],"ltp":1.54,"tv":335.3,"id":7412952}]}]}
{"op":"mcm","clk":"1005129661","pt":1580641001112,"mc":[{"id":"1.168209734","rc":[{"batb":[[0,1.8,132.42]],"batl":[[0,1.93,42.01],[1,2.36,91.77],[2,3,2.27]],"ltp":1.54,"tv":335.3,"id":7412952}]}]}
{"op":"mcm","clk":"1005130185","pt":1580641004498,"mc":[{"id":"1.168209734","rc":[{"batl":[[0,1.87,124.17],[1,1.89,159.08],[2,1.93,42.01]],"ltp":1.54,"tv":335.3,"id":7412952}]}]}
{"op":"mcm","clk":"1005131886","pt":1580641019329,"mc":[{"id":"1.168209734","rc":[{"trd":[[1.8,264.84]],"batb":[[0,1.77,53.77],[1,1.01,10.52],[2,1.77,0]],"batl":[[0,1.8,67.58],[1,1.87,124.17],[2,1.89,159.08]],"ltp":1.8,"tv":600.14,"id":7412952}],"tv":1364.75}]}
{"op":"mcm","clk":"1005132011","pt":1580641020009,"mc":[{"id":"1.168209734","rc":[{"trd":[[2.24,3.48]],"ltp":2.24,"tv":768.08,"id":8174357},{"trd":[[1.8,269.17]],"batl":[[0,1.8,63.25]],"ltp":1.8,"tv":604.47,"id":7412952}],"tv":1372.56}]}
{"op":"mcm","clk":"1005132321","pt":1580641022302,"mc":[{"id":"1.168209734","rc":[{"batb":[[0,1.79,177.54],[1,1.77,247.63],[2,1.01,10.52]],"batl":[[1,1.87,171.54]],"ltp":1.8,"tv":604.47,"id":7412952}]}]}
{"op":"mcm","clk":"1005133137","pt":1580641027597,"mc":[{"id":"1.168209734","rc":[{"batb":[[0,1.01,10.51],[1,1.01,0]],"batl":[[0,2.92,502.19],[1,2.92,0]],"ltp":2.24,"tv":768.08,"id":8174357},{"batb":[[0,1.01,10.52],[1,1.77,0],[2,1.01,0]],"batl":[[1,2.36,91.77],[2,3,2.27]],"ltp":1.8,"tv":604.47,"id":7412952}]}]}
{"op":"mcm","clk":"1005133406","pt":1580641029944,"mc":[{"id":"1.168209734","rc":[{"batl":[[0,2.36,91.77],[1,3,2.27],[2,3,0]],"ltp":1.8,"tv":604.47,"id":7412952}]}]}
{"op":"mcm","clk":"1005133481","pt":1580641030520,"mc":[{"id":"1.168209734","rc":[{"batb":[[0,1.4,315.12],[1,1.39,300.83],[2,1.01,10.51]],"batl":[[0,2.22,163.27],[1,2.24,117.29],[2,3,2.27]],"ltp":1.8,"tv":604.47,"id":7412952}]}]}
{"op":"mcm","clk":"1005134193","pt":1580641035922,"mc":[{"id":"1.168209734","rc":[{"batl":[[0,3,2.27],[1,2.24,0],[2,3,0]],"ltp":1.8,"tv":604.47,"id":7412952}]}]}
{"op":"mcm","clk":"1005134624","pt":1580641038838,"mc":[{"id":"1.168209734","rc":[{"trd":[[1.54,0.05]],"batb":[[0,1.4,315.1]],"batl":[[0,1.44,218.69],[1,1.45,243.78],[2,3,2.27]],"ltp":1.54,"tv":604.51,"id":7412952}],"tv":1372.59}]}
{"op":"mcm","clk":"1005134922","pt":1580641040936,"mc":[{"id":"1.168209734","rc":[{"batl":[[0,3.5,16.8],[1,4.9,281.9]],"ltp":2.24,"tv":768.08,"id":8174357},{"batb":[[0,1.4,420.12]],"batl":[[2,1.77,192.77]],"ltp":1.54,"tv":604.51,"id":7412952}]}]}
{"op":"mcm","clk":"1005135215","pt":1580641042815,"mc":[{"id":"1.168209734","rc":[{"batl":[[2,1.48,42.01]],"ltp":1.54,"tv":604.51,"id":7412952}]}]}
{"op":"mcm","clk":"1005135330","pt":1580641043751,"mc":[{"id":"1.168209734","rc":[{"batb":[[0,3.1,19.32],[1,1.01,10.51]],"ltp":2.24,"tv":768.08,"id":8174357}]}]}
{"op":"mcm","clk":"1005136759","pt":1580641054956,"mc":[{"id":"1.168209734","rc":[{"trd":[[1.4,213.52]],"batb":[[0,1.4,313.36]],"ltp":1.4,"tv":818.03,"id":7412952}],"tv":1586.11}]}
{"op":"mcm","clk":"1005137194","pt":1580641057942,"mc":[{"id":"1.168209734","rc":[{"batb":[[0,1.4,372.84]],"batl":[[0,1.44,264.72]],"ltp":1.4,"tv":818.03,"id":7412952}]}]}
{"op":"mcm","clk":"1005137571","pt":1580641060861,"mc":[{"id":"1.168209734","rc":[{"batb":[[0,1.4,105.02],[1,1.01,10.51],[2,1.01,0]],"batl":[[0,1.48,42.01],[1,1.77,192.77],[2,3,2.27]],"ltp":1.4,"tv":818.03,"id":7412952}]}]}
{"op":"mcm","clk":"1005137664","pt":1580641061634,"mc":[{"id":"1.168209734","rc":[{"batb":[[0,1.01,10.51],[1,1.01,0]],"batl":[[0,4.9,281.9],[1,4.9,0]],"ltp":2.24,"tv":768.08,"id":8174357},{"batb":[[0,1.01,10.51],[1,1.01,0]],"batl":[[0,1.77,192.77],[1,3,2.27],[2,3,0]],"ltp":1.4,"tv":818.03,"id":7412952}]}]}
{"op":"mcm","clk":"1005137787","pt":1580641062774,"mc":[{"id":"1.168209734","rc":[{"batl":[[0,3,2.27],[1,3,0]],"ltp":1.4,"tv":818.03,"id":7412952}]}]}
{"op":"mcm","clk":"1005137889","pt":1580641063664,"mc":[{"id":"1.168209734","rc":[{"batb":[[0,1.27,294.48],[1,1.26,500.97],[2,1.01,10.51]],"batl":[[0,1.88,203.31],[1,1.9,189.58],[2,3,2.27]],"ltp":1.4,"tv":818.03,"id":7412952}]}]}
{"op":"mcm","clk":"1005138013","pt":1580641064858,"mc":[{"id":"1.168209734","rc":[{"batl":[[0,3,2.27],[1,1.9,0],[2,3,0]],"ltp":1.4,"tv":818.03,"id":7412952}]}]}
{"op":"mcm","clk":"1005138389","pt":1580641067872,"mc":[{"id":"1.168209734","rc":[{"batl":[[0,1.3,414.99],[1,1.31,387.12],[2,3,2.27]],"ltp":1.4,"tv":818.03,"id":7412952}]}]}
{"op":"mcm","clk":"1005138484","pt":1580641068656,"mc":[{"id":"1.168209734","rc":[{"batb":[[0,4,13.44],[1,1.01,10.51]],"batl":[[0,4.7,10.92]],"ltp":2.24,"tv":768.08,"id":8174357},{"batb":[[0,1.27,449.92]],"batl":[[2,1.33,42.01]],"ltp":1.4,"tv":818.03,"id":7412952}]}]}
{"op":"mcm","clk":"1005138652","pt":1580641070271,"mc":[{"id":"1.168209734","rc":[{"batl":[[1,6.6,212.64]],"ltp":2.24,"tv":768.08,"id":8174357}]}]}
{"op":"mcm","clk":"1005139777","pt":1580641079592,"mc":[{"id":"1.168209734","rc":[{"batb":[[0,1.01,10.51],[1,1.01,0]],"batl":[[0,6.6,212.64],[1,6.6,0]],"ltp":2.24,"tv":768.08,"id":8174357},{"batb":[[0,1.01,10.51],[1,1.26,0],[2,1.01,0]],"batl":[[0,1.62,267.64],[1,3,2.27],[2,1.33,0]],"ltp":1.4,"tv":818.03,"id":7412952}]}]}
{"op":"mcm","clk":"1005140301","pt":1580641083866,"mc":[{"id":"1.168209734","rc":[{"batb":[[0,1.31,314.2],[1,1.01,10.51]],"batl":[[0,1.35,268.85],[1,1.62,267.64],[2,3,2.27]],"ltp":1.4,"tv":818.03,"id":7412952}]}]}
{"op":"mcm","clk":"1005140680","pt":1580641086890,"mc":[{"id":"1.168209734","rc":[{"batl":[[0,6,231.41]],"ltp":2.24,"tv":768.08,"id":8174357},{"batb":[[1,1.3,426.33],[2,1.01,10.51]],"batl":[[0,1.34,239.72],[1,1.35,340.89],[2,1.62,267.64]],"ltp":1.4,"tv":818.03,"id":7412952}]}]}
{"op":"mcm","clk":"1005140917","pt":1580641088715,"mc":[{"id":"1.168209734","rc":[{"batb":[[0,1.01,10.51],[1,1.3,0],[2,1.01,0]],"batl":[[0,1.62,267.64],[1,3,2.27],[2,1.62,0]],"ltp":1.4,"tv":818.03,"id":7412952}]}]}
{"op":"mcm","clk":"1005141074","pt":1580641089871,"mc":[{"id":"1.168209734","rc":[{"batl":[[0,3,2.27],[1,3,0]],"ltp":1.4,"tv":818.03,"id":7412952}]}]}
{"op":"mcm","clk":"1005141350","pt":1580641091901,"mc":[{"id":"1.168209734","rc":[{"batb":[[0,1.16,967.6],[1,1.15,377.84],[2,1.01,10.51]],"batl":[[0,1.6,260.89],[1,1.61,164.73],[2,3,2.27]],"ltp":1.4,"tv":818.03,"id":7412952}]}]}
{"op":"mcm","clk":"1005142049","pt":1580641097593,"mc":[{"id":"1.168209734","rc":[{"batl":[[0,3,2.27],[1,1.61,0],[2,3,0]],"ltp":1.4,"tv":818.03,"id":7412952}]}]}
{"op":"mcm","clk":"1005142434","pt":1580641100711,"mc":[{"id":"1.168209734","rc":[{"batl":[[0,1.19,777.12],[1,1.2,526.8],[2,3,2.27]],"ltp":1.4,"tv":818.03,"id":7412952}]}]}
{"op":"mcm","clk":"1005142719","pt":1580641102896,"mc":[{"id":"1.168209734","rc":[{"batb":[[0,5.6,8.4],[1,1.01,10.51]],"batl":[[0,6.8,6.72]],"ltp":2.24,"tv":768.08,"id":8174357},{"batb":[[0,1.17,168.04],[1,1.16,967.6],[2,1.15,377.84]],"batl":[[2,1.22,42.01]],"ltp":1.4,"tv":818.03,"id":7412952}]}]}
{"op":"mcm","clk":"1005142854","pt":1580641103889,"mc":[{"id":"1.168209734","rc":[{"batl":[[1,11.5,134.12]],"ltp":2.24,"tv":768.08,"id":8174357}]}]}
{"op":"mcm","clk":"1005143430","pt":1580641108523,"mc":[{"id":"1.168209734","rc":[{"batb":[[0,1.17,184.62]],"ltp":1.4,"tv":818.03,"id":7412952}]}]}
{"op":"mcm","clk":"1005143851","pt":1580641111532,"mc":[{"id":"1.168209734","rc":[{"batb":[[0,1.01,10.51],[1,1.01,0]],"batl":[[0,11.5,134.12],[1,11.5,0]],"ltp":2.24,"tv":768.08,"id":8174357},{"batb":[[0,1.17,168.04],[1,1.16,554.53]],"batl":[[0,1.19,716.84],[1,1.47,396.84],[2,3,2.27]],"ltp":1.4,"tv":818.03,"id":7412952}]}]}
{"op":"mcm","clk":"1005144271","pt":1580641114935,"mc":[{"id":"1.168209734","rc":[{"batb":[[0,5.8,8.4],[1,1.01,10.51]],"batl":[[0,7,6.72],[1,11.5,134.12]],"ltp":2.24,"tv":768.08,"id":8174357},{"trd":[[1.19,33.18]],"batb":[[0,1.16,314.79],[1,1.15,794.51],[2,1.01,10.51]],"batl":[[0,1.18,467.06],[1,1.19,595.07],[2,1.21,42.01]],"ltp":1.19,"tv":851.2,"id":7412952}],"tv":1619.29}]}
{"op":"mcm","clk":"1005144394","pt":1580641115854,"mc":[{"id":"1.168209734","rc":[{"batb":[[0,1.01,10.51],[1,1.15,0],[2,1.01,0]],"batl":[[0,1.21,42.01],[1,1.47,396.84],[2,3,2.27]],"ltp":1.19,"tv":851.2,"id":7412952}]}]}
{"op":"mcm","clk":"1005145149","pt":1580641121234,"mc":[{"id":"1.168209734","rc":[{"batb":[[0,1.01,10.51],[1,1.01,0]],"ltp":2.24,"tv":768.08,"id":8174357},{"batl":[[0,1.47,396.84],[1,3,2.27],[2,3,0]],"ltp":1.19,"tv":851.2,"id":7412952}]}]}
{"op":"mcm","clk":"1005145607","pt":1580641124932,"mc":[{"id":"1.168209734","rc":[{"batb":[[0,5.9,8.4],[1,1.01,10.51]],"ltp":2.24,"tv":768.08,"id":8174357},{"batb":[[0,1.16,168.04],[1,1.01,10.51]],"batl":[[0,1.2,42.01],[1,1.47,396.84],[2,3,2.27]],"ltp":1.19,"tv":851.2,"id":7412952}]}]}
{"op":"mcm","clk":"1005145712","pt":1580641125859,"mc":[{"id":"1.168209734","rc":[{"batb":[[0,1.01,10.51],[1,1.01,0]],"batl":[[0,11.5,134.12],[1,11.5,0]],"ltp":2.24,"tv":768.08,"id":8174357},{"batb":[[0,1.01,10.51],[1,1.01,0]],"batl":[[0,1.47,396.84],[1,3,2.27],[2,3,0]],"ltp":1.19,"tv":851.2,"id":7412952}]}]}
{"op":"mcm","clk":"1005145841","pt":1580641126747,"mc":[{"id":"1.168209734","rc":[{"batl":[[0,3,2.27],[1,3,0]],"ltp":1.19,"tv":851.2,"id":7412952}]}]}
{"op":"mcm","clk":"1005145977","pt":1580641127643,"mc":[{"id":"1.168209734","rc":[{"batb":[[0,1.05,1482.8],[1,1.01,10.51]],"batl":[[0,1.25,327.89],[1,1.26,505.6],[2,3,2.27]],"ltp":1.19,"tv":851.2,"id":7412952}]}]}
{"op":"mcm","clk":"1005148353","pt":1580641144984,"mc":[{"id":"1.168209734","rc":[{"batb":[[0,1.01,10.51],[1,1.01,0]],"batl":[[0,3,2.27],[1,1.26,0],[2,3,0]],"ltp":1.19,"tv":851.2,"id":7412952}]}]}
{"op":"mcm","clk":"1005148874","pt":1580641148390,"mc":[{"id":"1.168209734","rc":[{"batb":[[0,1.13,1133.76],[1,1.01,10.51]],"batl":[[0,1.16,891.75],[1,3,2.27]],"ltp":1.19,"tv":851.2,"id":7412952}]}]}
{"op":"mcm","clk":"1005149101","pt":1580641149885,"mc":[{"id":"1.168209734","rc":[{"batl":[[0,12.5,122.98]],"ltp":2.24,"tv":768.08,"id":8174357},{"batl":[[1,1.45,426.74],[2,3,2.27]],"ltp":1.19,"tv":851.2,"id":7412952}]}]}
{"op":"mcm","clk":"1005149281","pt":1580641151288,"mc":[{"id":"1.168209734","rc":[{"batb":[[0,1.13,1305.26]],"batl":[[0,1.16,1086.28],[1,1.17,253.72],[2,1.45,426.74]],"ltp":1.19,"tv":851.2,"id":7412952}]}]}
{"op":"mcm","clk":"1005149444","pt":1580641152597,"mc":[{"id":"1.168209734","rc":[{"batb":[[0,1.01,10.51],[1,1.01,0]],"batl":[[0,1.45,426.74],[1,3,2.27],[2,1.45,0]],"ltp":1.19,"tv":851.2,"id":7412952}]}]}
{"op":"mcm","clk":"1005149841","pt":1580641155562,"mc":[{"id":"1.168209734","rc":[{"batb":[[0,1.05,1482.8],[1,1.01,10.51]],"batl":[[0,1.26,668.61],[1,1.27,471.84],[2,3,2.27]],"ltp":1.19,"tv":851.2,"id":7412952}]}]}
{"op":"mcm","clk":"1005152347","pt":1580641174805,"mc":[{"id":"1.168209734","rc":[{"batb":[[0,1.01,10.51],[1,1.01,0]],"ltp":1.19,"tv":851.2,"id":7412952}]}]}
{"op":"mcm","clk":"1005152805","pt":1580641177911,"mc":[{"id":"1.168209734","rc":[{"batb":[[0,1.23,341.25],[1,1.22,638.41],[2,1.01,10.51]],"batl":[[0,1.26,589.85]],"ltp":1.19,"tv":851.2,"id":7412952}]}]}
{"op":"mcm","clk":"1005152908","pt":1580641178693,"mc":[{"id":"1.168209734","rc":[{"batb":[[0,4.5,11.76],[1,1.01,10.51]],"batl":[[0,5.3,9.24]],"ltp":2.24,"tv":768.08,"id":8174357},{"batb":[[0,1.23,509.29]],"batl":[[2,1.28,42.01]],"ltp":1.19,"tv":851.2,"id":7412952}]}]}
{"op":"mcm","clk":"1005153174","pt":1580641180721,"mc":[{"id":"1.168209734","rc":[{"batl":[[1,7.2,194.01]],"ltp":2.24,"tv":768.08,"id":8174357},{"batb":[[0,1.23,590.17]],"ltp":1.19,"tv":851.2,"id":7412952}]}]}
{"op":"mcm","clk":"1005153281","pt":1580641181616,"mc":[{"id":"1.168209734","rc":[{"batl":[[2,1.58,288.94]],"ltp":1.19,"tv":851.2,"id":7412952}]}]}
{"op":"mcm","clk":"1005153794","pt":1580641184819,"mc":[{"id":"1.168209734","rc":[{"batl":[[2,1.29,42.01]],"ltp":1.19,"tv":851.2,"id":7412952}]}]}
{"op":"mcm","clk":"1005156199","pt":1580641200795,"mc":[{"id":"1.168209734","rc":[{"batl":[[0,1.26,536.09]],"ltp":1.19,"tv":851.2,"id":7412952}]}]}
{"op":"mcm","clk":"1005156756","pt":1580641203482,"mc":[{"id":"1.168209734","rc":[{"batb":[[0,1.23,645.43]],"ltp":1.19,"tv":851.2,"id":7412952}]}]}
{"op":"mcm","clk":"1005157408","pt":1580641206662,"mc":[{"id":"1.168209734","rc":[{"batb":[[0,1.23,168.04],[1,1.01,10.51],[2,1.01,0]],"batl":[[0,1.29,42.01],[1,1.58,288.94],[2,3,2.27]],"ltp":1.19,"tv":851.2,"id":7412952}]}]}
{"op":"mcm","clk":"1005157574","pt":1580641207661,"mc":[{"id":"1.168209734","rc":[{"batb":[[0,1.01,10.51],[1,1.01,0]],"batl":[[0,7.2,194.01],[1,7.2,0]],"ltp":2.24,"tv":768.08,"id":8174357},{"batb":[[0,1.01,10.51],[1,1.01,0]],"batl":[[0,1.58,288.94],[1,3,2.27],[2,3,0]],"ltp":1.19,"tv":851.2,"id":7412952}]}]}
{"op":"mcm","clk":"1005157765","pt":1580641208666,"mc":[{"id":"1.168209734","rc":[{"batl":[[0,3,2.27],[1,3,0]],"ltp":1.19,"tv":851.2,"id":7412952}]}]}
{"op":"mcm","clk":"1005157889","pt":1580641209377,"mc":[{"id":"1.168209734","rc":[{"batb":[[0,1.08,1130.17],[1,1.07,314.35],[2,1.01,10.51]],"batl":[[0,1.37,315.41],[1,1.38,311.92],[2,3,2.27]],"ltp":1.19,"tv":851.2,"id":7412952}]}]}
{"op":"mcm","clk":"1005158548","pt":1580641212585,"mc":[{"id":"1.168209734","rc":[{"batb":[[0,1.01,10.51],[1,1.07,0],[2,1.01,0]],"batl":[[0,3,2.27],[1,1.38,0],[2,3,0]],"ltp":1.19,"tv":851.2,"id":7412952}]}]}
{"op":"mcm","clk":"1005159101","pt":1580641215792,"mc":[{"id":"1.168209734","rc":[{"batb":[[0,1.2,282.32],[1,1.19,753.61],[2,1.01,10.51]],"batl":[[0,1.22,385.3],[1,1.23,575.64],[2,3,2.27]],"ltp":1.19,"tv":851.2,"id":7412952}]}]}
{"op":"mcm","clk":"1005159456","pt":1580641218021,"mc":[{"id":"1.168209734","rc":[{"batl":[[0,8.6,166.38]],"ltp":2.24,"tv":768.08,"id":8174357},{"batl":[[2,1.53,332.86]],"ltp":1.19,"tv":851.2,"id":7412952}]}]}
{"op":"mcm","clk":"1005159936","pt":1580641220538,"mc":[{"id":"1.168209734","rc":[{"batb":[[0,1.01,10.51],[1,1.19,0],[2,1.01,0]],"batl":[[0,1.53,332.86],[1,3,2.27],[2,1.53,0]],"ltp":1.19,"tv":851.2,"id":7412952}]}]}
{"op":"mcm","clk":"1005160306","pt":1580641222703,"mc":[{"id":"1.168209734","rc":[{"batl":[[0,3,2.27],[1,3,0]],"ltp":1.19,"tv":851.2,"id":7412952}]}]}
{"op":"mcm","clk":"1005160436","pt":1580641223496,"mc":[{"id":"1.168209734","rc":[{"batb":[[0,1.08,1130.17],[1,1.07,314.35],[2,1.01,10.51]],"batl":[[0,1.37,315.41],[1,1.38,311.92],[2,3,2.27]],"ltp":1.19,"tv":851.2,"id":7412952}]}]}
{"op":"mcm","clk":"1005161006","pt":1580641226809,"mc":[{"id":"1.168209734","rc":[{"batb":[[0,1.01,10.51],[1,1.07,0],[2,1.01,0]],"ltp":1.19,"tv":851.2,"id":7412952}]}]}
{"op":"mcm","clk":"1005161472","pt":1580641229918,"mc":[{"id":"1.168209734","rc":[{"batb":[[0,1.33,524.68],[1,1.32,402.89],[2,1.01,10.51]],"ltp":1.19,"tv":851.2,"id":7412952}]}]}
{"op":"mcm","clk":"1005161614","pt":1580641230716,"mc":[{"id":"1.168209734","rc":[{"batb":[[0,3.5,16.8],[1,1.01,10.51]],"batl":[[0,4,13.44]],"ltp":2.24,"tv":768.08,"id":8174357},{"batb":[[0,1.33,651.55]],"batl":[[2,1.4,42.01]],"ltp":1.19,"tv":851.2,"id":7412952}]}]}
{"op":"mcm","clk":"1005162034","pt":1580641233213,"mc":[{"id":"1.168209734","rc":[{"batl":[[1,5.5,254.05]],"ltp":2.24,"tv":768.08,"id":8174357},{"batb":[[0,1.33,524.68]],"ltp":1.19,"tv":851.2,"id":7412952}]}]}
{"op":"mcm","clk":"1005162515","pt":1580641236304,"mc":[{"id":"1.168209734","rc":[{"batb":[[0,1.34,123.51],[1,1.33,524.68],[2,1.32,402.89]],"ltp":1.19,"tv":851.2,"id":7412952}]}]}
{"op":"mcm","clk":"1005163748","pt":1580641243957,"mc":[{"id":"1.168209734","rc":[{"batb":[[1,1.33,382.17],[2,1.01,10.51]],"batl":[[0,1.37,258.45]],"ltp":1.19,"tv":851.2,"id":7412952}]}]}
{"op":"mcm","clk":"1005164176","pt":1580641246343,"mc":[{"id":"1.168209734","rc":[{"batb":[[0,1.34,323.28]],"ltp":1.19,"tv":851.2,"id":7412952}]}]}
{"op":"mcm","clk":"1005164499","pt":1580641247934,"mc":[{"id":"1.168209734","rc":[{"trd":[[3.7,15.9]],"ltp":3.7,"tv":783.98,"id":8174357},{"trd":[[1.37,42.95]],"batl":[[0,1.37,215.5]],"ltp":1.37,"tv":894.15,"id":7412952}],"tv":1678.14}]}
{"op":"mcm","clk":"1005165645","pt":1580641252735,"mc":[{"id":"1.168209734","rc":[{"batb":[[0,1.34,355.22]],"ltp":1.37,"tv":894.15,"id":7412952}]}]}
{"op":"mcm","clk":"1005166846","pt":1580641259753,"mc":[{"id":"1.168209734","rc":[{"batb":[[0,1.01,10.51],[1,1.01,0]],"batl":[[0,5.5,254.05],[1,5.5,0]],"ltp":3.7,"tv":783.98,"id":8174357},{"batb":[[0,1.01,10.51],[1,1.33,0],[2,1.01,0]],"batl":[[0,1.71,219.51],[1,3,2.27],[2,1.4,0]],"ltp":1.37,"tv":894.15,"id":7412952}]}]}
{"op":"mcm","clk":"1005167224","pt":1580641261939,"mc":[{"id":"1.168209734","rc":[{"batl":[[0,3,2.27],[1,3,0]],"ltp":1.37,"tv":894.15,"id":7412952}]}]}
{"op":"mcm","clk":"1005167380","pt":1580641262753,"mc":[{"id":"1.168209734","rc":[{"batb":[[0,1.2,520.24],[1,1.19,758.87],[2,1.01,10.51]],"batl":[[0,1.87,223.2],[1,1.89,196.44],[2,3,2.27]],"ltp":1.37,"tv":894.15,"id":7412952}]}]}
