{"op":"mcm","clk":"996134465","pt":1580560628823,"mc":[{"id":"1.168209731","marketDefinition":{"bspMarket":false,"turnInPlayEnabled":true,"persistenceEnabled":true,"marketBaseRate":5.0,"eventId":"29681142","eventTypeId":"2","numberOfWinners":1,"bettingType":"ODDS","marketType":"MATCH_ODDS","marketTime":"2020-02-02T04:00:00.000Z","suspendTime":"2020-02-02T04:00:00.000Z","bspReconciled":false,"complete":true,"inPlay":false,"crossMatching":false,"runnersVoidable":false,"numberOfActiveRunners":2,"betDelay":0,"status":"OPEN","runners":[{"status":"ACTIVE","sortPriority":1,"id":8174357,"name":"Blaz Rola"},{"status":"ACTIVE","sortPriority":2,"id":7412952,"name":"Roberto Marcora"}],"regulators":["MR_INT"],"countryCode":"IN","discountAllowed":false,"timezone":"UTC","openDate":"2020-02-02T04:00:00.000Z","version":3145101551,"name":"Match Odds","eventName":"Rola v Marcora"},"rc":[{"batb":[[0,1.05,152.2],[1,1.04,168.86],[2,1.03,190.07]],"ltp":0.0,"tv":0.0,"id":8174357},{"batb":[[0,1.05,152.2],[1,1.04,168.86],[2,1.03,190.07]],"ltp":0.0,"tv":0.0,"id":7412952}]}]}
{"op":"mcm","clk":"996134636","pt":1580560629891,"mc":[{"id":"1.168209731","marketDefinition":{"bspMarket":false,"turnInPlayEnabled":true,"persistenceEnabled":true,"marketBaseRate":5.0,"eventId":"29681142","eventTypeId":"2","numberOfWinners":1,"bettingType":"ODDS","marketType":"MATCH_ODDS","marketTime":"2020-02-02T04:00:00.000Z","suspendTime":"2020-02-02T04:00:00.000Z","bspReconciled":false,"complete":true,"inPlay":false,"crossMatching":false,"runnersVoidable":false,"numberOfActiveRunners":2,"betDelay":0,"status":"OPEN","runners":[{"status":"ACTIVE","sortPriority":1,"id":8174357,"name":"Blaz Rola"},{"status":"ACTIVE","sortPriority":2,"id":7412952,"name":"Roberto Marcora"}],"regulators":["MR_INT"],"countryCode":"IN","discountAllowed":false,"timezone":"UTC","openDate":"2020-02-02T04:00:00.000Z","version":3145101551,"name":"Match Odds","eventName":"Rola v Marcora"}}]}
{"op":"mcm","clk":"996134845","pt":1580560630893,"mc":[{"id":"1.168209731","marketDefinition":{"bspMarket":false,"turnInPlayEnabled":true,"persistenceEnabled":true,"marketBaseRate":5.0,"eventId":"29681142","eventTypeId":"2","numberOfWinners":1,"bettingType":"ODDS","marketType":"MATCH_ODDS","marketTime":"2020-02-02T04:00:00.000Z","suspendTime":"2020-02-02T04:00:00.000Z","bspReconciled":false,"complete":true,"inPlay":false,"crossMatching":false,"runnersVoidable":false,"numberOfActiveRunners":2,"betDelay":0,"status":"OPEN","runners":[{"status":"ACTIVE","sortPriority":1,"id":8174357,"name":"Blaz Rola"},{"status":"ACTIVE","sortPriority":2,"id":7412952,"name":"Roberto Marcora"}],"regulators":["MR_INT"],"countryCode":"IN","discountAllowed":true,"timezone":"UTC","openDate":"2020-02-02T04:00:00.000Z","version":3145101551,"name":"Match Odds","eventName":"Rola v Marcora"}}]}
{"op":"mcm","clk":"996193464","pt":1580560896090,"mc":[{"id":"1.168209731","rc":[{"batb":[[2,1.03,237.77]],"ltp":0.0,"tv":0.0,"id":8174357},{"batb":[[2,1.03,237.77]],"ltp":0.0,"tv":0.0,"id":7412952}]}]}
{"op":"mcm","clk":"996194756","pt":1580560903252,"mc":[{"id":"1.168209731","rc":[{"batb":[[0,1.13,75.72],[1,1.05,152.2],[2,1.04,168.86]],"ltp":0.0,"tv":0.0,"id":7412952}]}]}
{"op":"mcm","clk":"996195051","pt":1580560904672,"mc":[{"id":"1.168209731","marketDefinition":{"bspMarket":false,"turnInPlayEnabled":true,"persistenceEnabled":true,"marketBaseRate":5.0,"eventId":"29681142","eventTypeId":"2","numberOfWinners":1,"bettingType":"ODDS","marketType":"MATCH_ODDS","marketTime":"2020-02-02T04:00:00.000Z","suspendTime":"2020-02-02T04:00:00.000Z","bspReconciled":false,"complete":true,"inPlay":false,"crossMatching":true,"runnersVoidable":false,"numberOfActiveRunners":2,"betDelay":0,"status":"OPEN","runners":[{"status":"ACTIVE","sortPriority":1,"id":8174357,"name":"Blaz Rola"},{"status":"ACTIVE","sortPriority":2,"id":7412952,"name":"Roberto Marcora"}],"regulators":["MR_INT"],"countryCode":"IN","discountAllowed":true,"timezone":"UTC","openDate":"2020-02-02T04:00:00.000Z","version":3145101551,"name":"Match Odds","eventName":"Rola v Marcora"}}]}
{"op":"mcm","clk":"996258688","pt":1580561233237,"mc":[{"id":"1.168209731","rc":[{"batb":[[0,1.06,50.48],[1,1.05,152.2],[2,1.04,168.86]],"ltp":0.0,"tv":0.0,"id":8174357}]}]}
{"op":"mcm","clk":"996440683","pt":1580562190378,"mc":[{"id":"1.168209731","rc":[{"batl":[[0,95,15.9]],"ltp":0.0,"tv":0.0,"id":8174357},{"batl":[[0,95,15.9]],"ltp":0.0,"tv":0.0,"id":7412952}]}]}
{"op":"mcm","clk":"996580964","pt":1580562799858,"mc":[{"id":"1.168209731","rc":[{"batl":[[1,990,2.2]],"ltp":0.0,"tv":0.0,"id":8174357},{"batl":[[1,990,2.2]],"ltp":0.0,"tv":0.0,"id":7412952}]}]}
{"op":"mcm","clk":"997110182","pt":1580565364562,"mc":[{"id":"1.168209731","rc":[{"batb":[[0,1.13,75.72],[1,1.06,50.48],[2,1.05,152.2]],"ltp":0.0,"tv":0.0,"id":8174357}]}]}
{"op":"mcm","clk":"997589873","pt":1580567441341,"mc":[{"id":"1.168209731","marketDefinition":{"bspMarket":false,"turnInPlayEnabled":true,"persistenceEnabled":true,"marketBaseRate":5.0,"eventId":"29681142","eventTypeId":"2","numberOfWinners":1,"bettingType":"ODDS","marketType":"MATCH_ODDS","marketTime":"2020-02-02T09:30:00.000Z","suspendTime":"2020-02-02T09:30:00.000Z","bspReconciled":false,"complete":true,"inPlay":false,"crossMatching":true,"runnersVoidable":false,"numberOfActiveRunners":2,"betDelay":0,"status":"OPEN","runners":[{"status":"ACTIVE","sortPriority":1,"id":8174357,"name":"Blaz Rola"},{"status":"ACTIVE","sortPriority":2,"id":7412952,"name":"Roberto Marcora"}],"regulators":["MR_INT"],"countryCode":"IN","discountAllowed":true,"timezone":"UTC","openDate":"2020-02-02T04:00:00.000Z","version":3145478785,"name":"Match Odds","eventName":"Rola v Marcora"}}]}
{"op":"mcm","clk":"997590546","pt":1580567444348,"mc":[{"id":"1.168209731","marketDefinition":{"bspMarket":false,"turnInPlayEnabled":true,"persistenceEnabled":true,"marketBaseRate":5.0,"eventId":"29681142","eventTypeId":"2","numberOfWinners":1,"bettingType":"ODDS","marketType":"MATCH_ODDS","marketTime":"2020-02-02T09:30:00.000Z","suspendTime":"2020-02-02T09:30:00.000Z","bspReconciled":false,"complete":true,"inPlay":false,"crossMatching":true,"runnersVoidable":false,"numberOfActiveRunners":2,"betDelay":0,"status":"OPEN","runners":[{"status":"ACTIVE","sortPriority":1,"id":8174357,"name":"Blaz Rola"},{"status":"ACTIVE","sortPriority":2,"id":7412952,"name":"Roberto Marcora"}],"regulators":["MR_INT"],"countryCode":"IN","discountAllowed":true,"timezone":"UTC","openDate":"2020-02-02T09:30:00.000Z","version":3145478785,"name":"Match Odds","eventName":"Rola v Marcora"}}]}
{"op":"mcm","clk":"999517293","pt":1580575121654,"mc":[{"id":"1.168209731","rc":[{"batl":[[0,3.2,2.64],[1,95,15.9],[2,990,2.2]],"ltp":0.0,"tv":0.0,"id":8174357}]}]}
{"op":"mcm","clk":"999739034","pt":1580576333827,"mc":[{"id":"1.168209731","rc":[{"batb":[[0,1.14,15.12],[1,1.13,75.72],[2,1.06,50.48]],"ltp":0.0,"tv":0.0,"id":8174357}]}]}
{"op":"mcm","clk":"999739098","pt":1580576334390,"mc":[{"id":"1.168209731","rc":[{"batl":[[0,3.15,3.36],[1,3.2,2.64],[2,95,15.9]],"ltp":0.0,"tv":0.0,"id":8174357},{"batb":[[0,1.14,15.12],[1,1.13,75.72],[2,1.05,152.2]],"batl":[[0,16,3.36],[1,95,15.9],[2,990,2.2]],"ltp":0.0,"tv":0.0,"id":7412952}]}]}
{"op":"mcm","clk":"999783191","pt":1580576651911,"mc":[{"id":"1.168209731","rc":[{"batb":[[0,1.4,66.61],[1,1.14,15.12],[2,1.13,75.72]],"batl":[[0,1.76,45.52],[1,3.15,3.36],[2,3.2,2.64]],"ltp":0.0,"tv":0.0,"id":8174357}]}]}
{"op":"mcm","clk":"999783922","pt":1580576656454,"mc":[{"id":"1.168209731","rc":[{"batl":[[0,2.02,34.3]],"ltp":0.0,"tv":0.0,"id":8174357}]}]}
{"op":"mcm","clk":"999784375","pt":1580576659333,"mc":[{"id":"1.168209731","rc":[{"batb":[[0,1.14,15.12],[1,1.13,75.72],[2,1.06,50.48]],"batl":[[0,3.15,3.36],[1,3.2,2.64],[2,95,15.9]],"ltp":0.0,"tv":0.0,"id":8174357}]}]}
{"op":"mcm","clk":"999785101","pt":1580576663841,"mc":[{"id":"1.168209731","rc":[{"batb":[[0,1.53,33.16],[1,1.52,37.86],[2,1.14,15.12]],"ltp":0.0,"tv":0.0,"id":8174357},{"batb":[[0,2.18,20.36],[1,2.16,42.4],[2,1.14,15.12]],"ltp":0.0,"tv":0.0,"id":7412952}]}]}
{"op":"mcm","clk":"999790910","pt":1580576700251,"mc":[{"id":"1.168209731","rc":[{"batb":[[2,1.13,75.72]],"ltp":0.0,"tv":0.0,"id":8174357},{"batb":[[2,1.13,75.72]],"ltp":0.0,"tv":0.0,"id":7412952}]}]}
{"op":"mcm","clk":"999792166","pt":1580576708391,"mc":[{"id":"1.168209731","rc":[{"batb":[[1,1.52,59.82]],"ltp":0.0,"tv":0.0,"id":8174357}]}]}
{"op":"mcm","clk":"999802358","pt":1580576774526,"mc":[{"id":"1.168209731","rc":[{"batb":[[0,1.53,92.98],[1,1.13,75.72],[2,1.06,50.48]],"ltp":0.0,"tv":0.0,"id":8174357}]}]}
{"op":"mcm","clk":"999832285","pt":1580576975939,"mc":[{"id":"1.168209731","rc":[{"batb":[[0,1.53,33.16]],"ltp":0.0,"tv":0.0,"id":8174357}]}]}
{"op":"mcm","clk":"999832362","pt":1580576976438,"mc":[{"id":"1.168209731","rc":[{"batb":[[0,1.58,32.06],[1,1.54,59.82],[2,1.13,75.72]],"ltp":0.0,"tv":0.0,"id":8174357}]}]}
{"op":"mcm","clk":"999852585","pt":1580577107326,"mc":[{"id":"1.168209731","rc":[{"batb":[[0,1.54,59.82],[1,1.13,75.72],[2,1.06,50.48]],"ltp":0.0,"tv":0.0,"id":8174357},{"batl":[[0,2.4,302.89],[1,16,3.36],[2,95,15.9]],"ltp":0.0,"tv":0.0,"id":7412952}]}]}
{"op":"mcm","clk":"999853335","pt":1580577112714,"mc":[{"id":"1.168209731","rc":[{"batb":[[0,2.16,42.4],[1,1.13,75.72],[2,1.05,152.2]],"ltp":0.0,"tv":0.0,"id":7412952}]}]}
{"op":"mcm","clk":"999853638","pt":1580577114778,"mc":[{"id":"1.168209731","rc":[{"batl":[[0,2.14,19.75],[1,3.15,3.36],[2,3.2,2.64]],"ltp":0.0,"tv":0.0,"id":8174357},{"batb":[[0,1.13,75.72],[1,1.05,152.2],[2,1.04,168.86]],"ltp":0.0,"tv":0.0,"id":7412952}]}]}
{"op":"mcm","clk":"999853691","pt":1580577115113,"mc":[{"id":"1.168209731","rc":[{"batb":[[0,1.55,59.82]],"ltp":0.0,"tv":0.0,"id":8174357}]}]}
{"op":"mcm","clk":"999854521","pt":1580577120927,"mc":[{"id":"1.168209731","rc":[{"batb":[[0,1.13,75.72],[1,1.06,50.48],[2,1.05,152.2]],"batl":[[1,3.2,2.64],[2,95,15.9]],"ltp":0.0,"tv":0.0,"id":8174357}]}]}
{"op":"mcm","clk":"999854623","pt":1580577121529,"mc":[{"id":"1.168209731","rc":[{"batb":[[0,1.54,59.82],[1,1.13,75.72],[2,1.06,50.48]],"batl":[[0,3.2,2.64],[1,95,15.9],[2,990,2.2]],"ltp":0.0,"tv":0.0,"id":8174357},{"batb":[[0,2.08,20.31],[1,2.06,43.92],[2,1.14,15.12]],"batl":[[1,95,15.9],[2,990,2.2]],"ltp":0.0,"tv":0.0,"id":7412952}]}]}
{"op":"mcm","clk":"999863112","pt":1580577177763,"mc":[{"id":"1.168209731","rc":[{"batb":[[0,1.58,59.82]],"ltp":0.0,"tv":0.0,"id":8174357}]}]}
{"op":"mcm","clk":"999863329","pt":1580577179161,"mc":[{"id":"1.168209731","rc":[{"batb":[[2,1.13,75.72]],"ltp":0.0,"tv":0.0,"id":7412952}]}]}
{"op":"mcm","clk":"999869046","pt":1580577216138,"mc":[{"id":"1.168209731","rc":[{"batb":[[0,1.6,59.82]],"ltp":0.0,"tv":0.0,"id":8174357}]}]}
{"op":"mcm","clk":"999877021","pt":1580577269604,"mc":[{"id":"1.168209731","rc":[{"batb":[[0,2.06,43.92],[1,1.13,75.72],[2,1.05,152.2]],"ltp":0.0,"tv":0.0,"id":7412952}]}]}
{"op":"mcm","clk":"999877168","pt":1580577270794,"mc":[{"id":"1.168209731","rc":[{"batb":[[0,2.1,31.74],[1,2.06,43.92],[2,1.13,75.72]],"ltp":0.0,"tv":0.0,"id":7412952}]}]}
{"op":"mcm","clk":"999893669","pt":1580577376032,"mc":[{"id":"1.168209731","rc":[{"batb":[[1,2.08,21.11],[2,2.06,43.92]],"ltp":0.0,"tv":0.0,"id":7412952}]}]}
{"op":"mcm","clk":"999894365","pt":1580577380639,"mc":[{"id":"1.168209731","rc":[{"batb":[[0,1.62,59.82]],"ltp":0.0,"tv":0.0,"id":8174357}]}]}
{"op":"mcm","clk":"999965268","pt":1580577846310,"mc":[{"id":"1.168209731","rc":[{"trd":[[2.4,17.63]],"batl":[[0,2.4,294.08]],"ltp":2.4,"tv":17.62,"id":7412952}],"tv":17.62}]}
{"op":"mcm","clk":"999974212","pt":1580577901092,"mc":[{"id":"1.168209731","rc":[{"batb":[[0,1.13,75.72],[1,1.06,50.48],[2,1.05,152.2]],"ltp":0.0,"tv":0.0,"id":8174357}]}]}
{"op":"mcm","clk":"999974677","pt":1580577903685,"mc":[{"id":"1.168209731","rc":[{"batb":[[0,2.14,43.92],[1,2.1,31.74],[2,2.08,21.11]],"ltp":2.4,"tv":17.62,"id":7412952}]}]}
{"op":"mcm","clk":"999974817","pt":1580577904480,"mc":[{"id":"1.168209731","rc":[{"batb":[[0,1.58,57.55],[1,1.13,75.72],[2,1.06,50.48]],"ltp":0.0,"tv":0.0,"id":8174357},{"batb":[[0,2.12,43.92]],"ltp":2.4,"tv":17.62,"id":7412952}]}]}
{"op":"mcm","clk":"999975006","pt":1580577905622,"mc":[{"id":"1.168209731","rc":[{"batb":[[0,1.13,75.72],[1,1.06,50.48],[2,1.05,152.2]],"ltp":0.0,"tv":0.0,"id":8174357}]}]}
{"op":"mcm","clk":"999976690","pt":1580577915645,"mc":[{"id":"1.168209731","rc":[{"batb":[[0,2.2,43.92]],"ltp":2.4,"tv":17.62,"id":7412952}]}]}
{"op":"mcm","clk":"999977101","pt":1580577918328,"mc":[{"id":"1.168209731","rc":[{"batb":[[0,1.14,15.12],[1,1.13,75.72],[2,1.06,50.48]],"ltp":0.0,"tv":0.0,"id":8174357}]}]}
{"op":"mcm","clk":"999977667","pt":1580577921545,"mc":[{"id":"1.168209731","rc":[{"batb":[[0,1.56,58.31],[1,1.14,15.12],[2,1.13,75.72]],"ltp":0.0,"tv":0.0,"id":8174357},{"batb":[[0,2.18,43.92]],"ltp":2.4,"tv":17.62,"id":7412952}]}]}
{"op":"mcm","clk":"999986398","pt":1580577978278,"mc":[{"id":"1.168209731","rc":[{"batb":[[1,1.13,75.72],[2,1.06,50.48]],"ltp":0.0,"tv":0.0,"id":8174357}]}]}
{"op":"mcm","clk":"1000068503","pt":1580578486207,"mc":[{"id":"1.168209731","rc":[{"batb":[[0,2.2,31.47],[1,2.18,43.92]],"ltp":2.4,"tv":17.62,"id":7412952}]}]}
{"op":"mcm","clk":"1000069084","pt":1580578489812,"mc":[{"id":"1.168209731","rc":[{"batb":[[0,1.58,58.31]],"ltp":0.0,"tv":0.0,"id":8174357}]}]}
{"op":"mcm","clk":"1000069623","pt":1580578492937,"mc":[{"id":"1.168209731","rc":[{"batb":[[0,1.57,58.31]],"ltp":0.0,"tv":0.0,"id":8174357},{"batb":[[1,2.16,43.92]],"ltp":2.4,"tv":17.62,"id":7412952}]}]}
{"op":"mcm","clk":"1000345926","pt":1580580358107,"mc":[{"id":"1.168209731","rc":[{"batb":[[0,1.56,58.31]],"ltp":0.0,"tv":0.0,"id":8174357}]}]}
{"op":"mcm","clk":"1000352792","pt":1580580404839,"mc":[{"id":"1.168209731","rc":[{"batb":[[0,1.57,58.31]],"ltp":0.0,"tv":0.0,"id":8174357}]}]}
{"op":"mcm","clk":"1000355838","pt":1580580425270,"mc":[{"id":"1.168209731","rc":[{"batb":[[0,2.2,47.32]],"ltp":2.4,"tv":17.62,"id":7412952}]}]}
{"op":"mcm","clk":"1000425648","pt":1580580871554,"mc":[{"id":"1.168209731","rc":[{"batb":[[0,2.24,46.77]],"ltp":2.4,"tv":17.62,"id":7412952}]}]}
{"op":"mcm","clk":"1000528563","pt":1580581626661,"mc":[{"id":"1.168209731","rc":[{"trd":[[1.71,352.88]],"ltp":1.71,"tv":352.88,"id":8174357},{"trd":[[2.4,269.06]],"batl":[[0,2.4,42.65]],"ltp":2.4,"tv":269.06,"id":7412952}],"tv":621.94}]}
{"op":"mcm","clk":"1000533276","pt":1580581659752,"mc":[{"id":"1.168209731","rc":[{"trd":[[1.71,412.74]],"ltp":1.71,"tv":412.73,"id":8174357},{"trd":[[2.4,311.71]],"batl":[[0,95,15.9],[1,990,2.2],[2,990,0]],"ltp":2.4,"tv":311.7,"id":7412952}],"tv":724.44}]}
{"op":"mcm","clk":"1000533779","pt":1580581663720,"mc":[{"id":"1.168209731","rc":[{"batb":[[0,1.13,75.72],[1,1.06,50.48],[2,1.05,152.2]],"ltp":1.71,"tv":412.73,"id":8174357}]}]}
{"op":"mcm","clk":"1000547959","pt":1580581766742,"mc":[{"id":"1.168209731","rc":[{"batb":[[0,1.14,15.12],[1,1.13,75.72],[2,1.06,50.48]],"batl":[[0,3.15,3.36],[1,3.2,2.64],[2,95,15.9]],"ltp":1.71,"tv":412.73,"id":8174357},{"batl":[[0,14.5,3.36],[1,95,15.9],[2,990,2.2]],"ltp":2.4,"tv":311.7,"id":7412952}]}]}
{"op":"mcm","clk":"1000627429","pt":1580582262928,"mc":[{"id":"1.168209731","rc":[{"batb":[[1,1.06,50.48],[2,1.05,152.2]],"ltp":1.71,"tv":412.73,"id":8174357}]}]}
{"op":"mcm","clk":"1000627443","pt":1580582263034,"mc":[{"id":"1.168209731","rc":[{"batb":[[0,1.15,75.72],[1,1.14,15.12],[2,1.06,50.48]],"ltp":1.71,"tv":412.73,"id":8174357}]}]}
{"op":"mcm","clk":"1000635387","pt":1580582310316,"mc":[{"id":"1.168209731","rc":[{"batb":[[1,1.06,50.48],[2,1.05,152.2]],"ltp":1.71,"tv":412.73,"id":8174357}]}]}
{"op":"mcm","clk":"1000646456","pt":1580582368056,"mc":[{"id":"1.168209731","rc":[{"batb":[[0,1.16,15.12],[1,1.15,75.72],[2,1.06,50.48]],"ltp":1.71,"tv":412.73,"id":8174357}]}]}
{"op":"mcm","clk":"1000651590","pt":1580582396703,"mc":[{"id":"1.168209731","rc":[{"trd":[[1.57,33.84]],"batb":[[0,1.42,92.13],[1,1.16,15.12],[2,1.15,75.72]],"batl":[[0,1.57,58.7],[1,3.15,3.36],[2,3.2,2.64]],"ltp":1.57,"tv":446.57,"id":8174357},{"batb":[[0,2.16,43.92],[1,2.08,21.11],[2,1.13,75.72]],"ltp":2.4,"tv":311.7,"id":7412952}],"tv":758.28}]}
{"op":"mcm","clk":"1000651766","pt":1580582397603,"mc":[{"id":"1.168209731","rc":[{"batb":[[0,1.49,167.65],[1,1.42,92.13],[2,1.16,15.12]],"ltp":1.57,"tv":446.57,"id":8174357}]}]}
{"op":"mcm","clk":"1000655188","pt":1580582416697,"mc":[{"id":"1.168209731","rc":[{"batb":[[0,1.5,87.3],[1,1.49,167.65]],"batl":[[0,3.15,3.36],[1,3.2,2.64],[2,95,15.9]],"ltp":1.57,"tv":446.57,"id":8174357}]}]}
{"op":"mcm","clk":"1000655302","pt":1580582417431,"mc":[{"id":"1.168209731","rc":[{"batb":[[0,2.2,51.52],[1,2.16,43.92],[2,2.08,21.11]],"ltp":2.4,"tv":311.7,"id":7412952}]}]}
{"op":"mcm","clk":"1000656587","pt":1580582425111,"mc":[{"id":"1.168209731","rc":[{"batb":[[2,1.15,75.72]],"ltp":1.57,"tv":446.57,"id":8174357}]}]}
{"op":"mcm","clk":"1000665585","pt":1580582480465,"mc":[{"id":"1.168209731","rc":[{"batb":[[0,1.49,259.23],[1,1.15,75.72],[2,1.06,50.48]],"ltp":1.57,"tv":446.57,"id":8174357}]}]}
{"op":"mcm","clk":"1000684686","pt":1580582595085,"mc":[{"id":"1.168209731","rc":[{"batb":[[1,1.42,68.51],[2,1.15,75.72]],"ltp":1.57,"tv":446.57,"id":8174357},{"batb":[[0,2.24,23.21],[1,2.2,51.52],[2,2.16,43.92]],"ltp":2.4,"tv":311.7,"id":7412952}]}]}
{"op":"mcm","clk":"1000707625","pt":1580582726863,"mc":[{"id":"1.168209731","rc":[{"batb":[[0,1.5,16.8],[1,1.49,167.65],[2,1.42,68.51]],"batl":[[0,1.77,66.63],[1,1.81,8.4],[2,3.15,3.36]],"ltp":1.57,"tv":446.57,"id":8174357},{"batb":[[0,2.24,29.98],[1,2.16,43.92],[2,2.08,21.11]],"batl":[[0,3,8.4],[1,14.5,3.36],[2,95,15.9]],"ltp":2.4,"tv":311.7,"id":7412952}]}]}
{"op":"mcm","clk":"1000713120","pt":1580582757899,"mc":[{"id":"1.168209731","rc":[{"batl":[[1,3.15,3.36],[2,3.2,2.64]],"ltp":1.57,"tv":446.57,"id":8174357}]}]}
{"op":"mcm","clk":"1000713295","pt":1580582758880,"mc":[{"id":"1.168209731","rc":[{"batl":[[0,1.77,75.03]],"ltp":1.57,"tv":446.57,"id":8174357},{"batb":[[0,2.24,23.21]],"ltp":2.4,"tv":311.7,"id":7412952}]}]}
{"op":"mcm","clk":"1000713343","pt":1580582759179,"mc":[{"id":"1.168209731","rc":[{"batb":[[0,2.28,6.56],[1,2.24,23.21],[2,2.16,43.92]],"ltp":2.4,"tv":311.7,"id":7412952}]}]}
{"op":"mcm","clk":"1000715137","pt":1580582769689,"mc":[{"id":"1.168209731","rc":[{"batl":[[1,3.2,2.64],[2,95,15.9]],"ltp":1.57,"tv":446.57,"id":8174357},{"batl":[[1,95,15.9],[2,990,2.2]],"ltp":2.4,"tv":311.7,"id":7412952}]}]}
{"op":"mcm","clk":"1000864351","pt":1580583663943,"mc":[{"id":"1.168209731","rc":[{"batb":[[2,1.46,62.09]],"batl":[[0,1.77,8.4]],"ltp":1.57,"tv":446.57,"id":8174357},{"batb":[[0,2.44,48.42],[1,2.4,43.92],[2,2.28,6.56]],"ltp":2.4,"tv":311.7,"id":7412952}]}]}
{"op":"mcm","clk":"1000864873","pt":1580583666744,"mc":[{"id":"1.168209731","rc":[{"batl":[[0,3.2,2.64],[1,95,15.9],[2,990,2.2]],"ltp":1.57,"tv":446.57,"id":8174357},{"batb":[[2,2.24,23.21]],"ltp":2.4,"tv":311.7,"id":7412952}]}]}
{"op":"mcm","clk":"1000864978","pt":1580583667245,"mc":[{"id":"1.168209731","rc":[{"batl":[[0,1.7,8.4],[1,3.2,2.64],[2,95,15.9]],"ltp":1.57,"tv":446.57,"id":8174357},{"batb":[[0,2.44,54.25]],"ltp":2.4,"tv":311.7,"id":7412952}]}]}
{"op":"mcm","clk":"1000912928","pt":1580583921210,"mc":[{"id":"1.168209731","rc":[{"batb":[[0,2.44,70]],"ltp":2.4,"tv":311.7,"id":7412952}]}]}
{"op":"mcm","clk":"1000913207","pt":1580583922608,"mc":[{"id":"1.168209731","rc":[{"batb":[[2,2.08,21.11]],"ltp":2.4,"tv":311.7,"id":7412952}]}]}
{"op":"mcm","clk":"1000913327","pt":1580583923205,"mc":[{"id":"1.168209731","rc":[{"batb":[[2,2.24,30.53]],"ltp":2.4,"tv":311.7,"id":7412952}]}]}
{"op":"mcm","clk":"1001183496","pt":1580585302841,"mc":[{"id":"1.168209731","rc":[{"batb":[[1,1.46,62.09],[2,1.42,90.15]],"ltp":1.57,"tv":446.57,"id":8174357}]}]}
{"op":"mcm","clk":"1001252646","pt":1580585667735,"mc":[{"id":"1.168209731","rc":[{"batb":[[0,1.54,102.12],[1,1.5,16.8],[2,1.46,62.09]],"ltp":1.57,"tv":446.57,"id":8174357},{"batb":[[0,2.44,5.83]],"ltp":2.4,"tv":311.7,"id":7412952}]}]}
{"op":"mcm","clk":"1001252999","pt":1580585669753,"mc":[{"id":"1.168209731","rc":[{"batb":[[0,1.54,70.11],[1,1.51,114.48],[2,1.5,16.8]],"ltp":1.57,"tv":446.57,"id":8174357},{"batb":[[1,2.08,21.11],[2,2,37.86]],"ltp":2.4,"tv":311.7,"id":7412952}]}]}
{"op":"mcm","clk":"1001253101","pt":1580585670283,"mc":[{"id":"1.168209731","rc":[{"batb":[[0,1.57,62.09],[1,1.54,70.11]],"ltp":1.57,"tv":446.57,"id":8174357}]}]}
{"op":"mcm","clk":"1001253421","pt":1580585671887,"mc":[{"id":"1.168209731","rc":[{"batb":[[0,1.51,114.99],[1,1.5,16.8],[2,1.15,75.72]],"ltp":1.57,"tv":446.57,"id":8174357},{"batb":[[2,1.13,75.72]],"ltp":2.4,"tv":311.7,"id":7412952}]}]}
{"op":"mcm","clk":"1001253480","pt":1580585672221,"mc":[{"id":"1.168209731","rc":[{"batb":[[2,1.46,82.31]],"ltp":1.57,"tv":446.57,"id":8174357},{"batb":[[1,2.16,32.64],[2,2.08,21.11]],"ltp":2.4,"tv":311.7,"id":7412952}]}]}
{"op":"mcm","clk":"1001254478","pt":1580585677605,"mc":[{"id":"1.168209731","rc":[{"batb":[[1,1.5,77.38]],"ltp":1.57,"tv":446.57,"id":8174357},{"batb":[[1,2.3,39.38],[2,2.16,32.64]],"ltp":2.4,"tv":311.7,"id":7412952}]}]}
{"op":"mcm","clk":"1001257564","pt":1580585693924,"mc":[{"id":"1.168209731","rc":[{"batl":[[0,95,15.9],[1,990,2.2],[2,990,0]],"ltp":2.4,"tv":311.7,"id":7412952}]}]}
{"op":"mcm","clk":"1001257765","pt":1580585694825,"mc":[{"id":"1.168209731","rc":[{"batb":[[1,1.5,60.58]],"ltp":1.57,"tv":446.57,"id":8174357},{"batl":[[0,2.98,8.4],[1,95,15.9],[2,990,2.2]],"ltp":2.4,"tv":311.7,"id":7412952}]}]}
{"op":"mcm","clk":"1001257900","pt":1580585695534,"mc":[{"id":"1.168209731","rc":[{"batb":[[0,1.53,113.65],[1,1.52,16.16],[2,1.5,60.58]],"ltp":1.57,"tv":446.57,"id":8174357}]}]}
{"op":"mcm","clk":"1001263871","pt":1580585726880,"mc":[{"id":"1.168209731","rc":[{"batb":[[1,1.5,60.58],[2,1.46,82.31]],"ltp":1.57,"tv":446.57,"id":8174357},{"batl":[[0,95,15.9],[1,990,2.2],[2,990,0]],"ltp":2.4,"tv":311.7,"id":7412952}]}]}
{"op":"mcm","clk":"1001264042","pt":1580585727708,"mc":[{"id":"1.168209731","rc":[{"batb":[[0,1.54,15.56],[1,1.53,113.65],[2,1.5,60.58]],"ltp":1.57,"tv":446.57,"id":8174357},{"batl":[[0,2.9,8.4],[1,95,15.9],[2,990,2.2]],"ltp":2.4,"tv":311.7,"id":7412952}]}]}
{"op":"mcm","clk":"1001264120","pt":1580585728119,"mc":[{"id":"1.168209731","rc":[{"batb":[[1,1.5,60.58],[2,1.46,82.31]],"ltp":1.57,"tv":446.57,"id":8174357}]}]}
{"op":"mcm","clk":"1001270364","pt":1580585758943,"mc":[{"id":"1.168209731","rc":[{"batl":[[0,95,15.9],[1,990,2.2],[2,990,0]],"ltp":2.4,"tv":311.7,"id":7412952}]}]}
{"op":"mcm","clk":"1001270489","pt":1580585759537,"mc":[{"id":"1.168209731","rc":[{"batl":[[0,2.86,8.4],[1,95,15.9],[2,990,2.2]],"ltp":2.4,"tv":311.7,"id":7412952}]}]}
{"op":"mcm","clk":"1001617668","pt":1580587714928,"mc":[{"id":"1.168209731","rc":[{"batb":[[2,1.15,75.72]],"ltp":1.57,"tv":446.57,"id":8174357},{"batb":[[2,2.08,21.11]],"ltp":2.4,"tv":311.7,"id":7412952}]}]}
{"op":"mcm","clk":"1001617784","pt":1580587715515,"mc":[{"id":"1.168209731","rc":[{"batb":[[2,1.46,103.71]],"ltp":1.57,"tv":446.57,"id":8174357},{"batb":[[2,2.16,41.13]],"ltp":2.4,"tv":311.7,"id":7412952}]}]}
{"op":"mcm","clk":"1001996519","pt":1580589796024,"mc":[{"id":"1.168209731","rc":[{"batl":[[0,2.78,73.75],[1,2.86,8.4],[2,95,15.9]],"ltp":2.4,"tv":311.7,"id":7412952}]}]}
{"op":"mcm","clk":"1001996777","pt":1580589797406,"mc":[{"id":"1.168209731","rc":[{"batb":[[2,1.15,75.72]],"ltp":1.57,"tv":446.57,"id":8174357},{"batb":[[2,2.08,21.11]],"ltp":2.4,"tv":311.7,"id":7412952}]}]}
{"op":"mcm","clk":"1001996977","pt":1580589798619,"mc":[{"id":"1.168209731","rc":[{"batb":[[0,1.55,60.58],[1,1.54,15.56],[2,1.5,95.41]],"ltp":1.57,"tv":446.57,"id":8174357},{"batb":[[1,2.08,21.11],[2,2.06,45]],"ltp":2.4,"tv":311.7,"id":7412952}]}]}
{"op":"mcm","clk":"1001997970","pt":1580589804861,"mc":[{"id":"1.168209731","rc":[{"batb":[[0,1.54,76.14],[1,1.5,95.41],[2,1.15,75.72]],"ltp":1.57,"tv":446.57,"id":8174357}]}]}
{"op":"mcm","clk":"1001998025","pt":1580589805137,"mc":[{"id":"1.168209731","rc":[{"batb":[[1,2.22,40.89],[2,2.08,21.11]],"ltp":2.4,"tv":311.7,"id":7412952}]}]}
{"op":"mcm","clk":"1001999730","pt":1580589815656,"mc":[{"id":"1.168209731","rc":[{"batl":[[1,95,15.9],[2,990,2.2]],"ltp":2.4,"tv":311.7,"id":7412952}]}]}
{"op":"mcm","clk":"1001999899","pt":1580589816869,"mc":[{"id":"1.168209731","rc":[{"batb":[[0,1.57,14.74],[1,1.54,60.58],[2,1.5,95.41]],"ltp":1.57,"tv":446.57,"id":8174357},{"batl":[[0,2.78,82.15]],"ltp":2.4,"tv":311.7,"id":7412952}]}]}
{"op":"mcm","clk":"1002004868","pt":1580589848692,"mc":[{"id":"1.168209731","rc":[{"batl":[[0,2.76,8.4],[1,2.78,73.75],[2,95,15.9]],"ltp":2.4,"tv":311.7,"id":7412952}]}]}
{"op":"mcm","clk":"1002026003","pt":1580589973730,"mc":[{"id":"1.168209731","rc":[{"batb":[[0,1.58,129.56],[1,1.57,14.74],[2,1.54,60.58]],"ltp":1.57,"tv":446.57,"id":8174357},{"batl":[[0,95,15.9],[1,990,2.2],[2,95,0]],"ltp":2.4,"tv":311.7,"id":7412952}]}]}
{"op":"mcm","clk":"1002026173","pt":1580589974847,"mc":[{"id":"1.168209731","rc":[{"batb":[[0,1.59,14.24],[1,1.58,129.56]],"ltp":1.57,"tv":446.57,"id":8174357},{"batl":[[0,2.74,8.4],[1,95,15.9],[2,990,2.2]],"ltp":2.4,"tv":311.7,"id":7412952}]}]}
{"op":"mcm","clk":"1002031664","pt":1580590006848,"mc":[{"id":"1.168209731","rc":[{"batb":[[1,1.54,60.58],[2,1.5,95.41]],"ltp":1.57,"tv":446.57,"id":8174357},{"batl":[[0,2.7,8.4]],"ltp":2.4,"tv":311.7,"id":7412952}]}]}
{"op":"mcm","clk":"1002106498","pt":1580590543922,"mc":[{"id":"1.168209731","rc":[{"batb":[[2,1.15,75.72]],"ltp":1.57,"tv":446.57,"id":8174357}]}]}
{"op":"mcm","clk":"1002106561","pt":1580590544551,"mc":[{"id":"1.168209731","rc":[{"batb":[[2,1.52,164.55]],"ltp":1.57,"tv":446.57,"id":8174357},{"batb":[[2,2.12,76.4]],"ltp":2.4,"tv":311.7,"id":7412952}]}]}
{"op":"mcm","clk":"1002145070","pt":1580590897879,"mc":[{"id":"1.168209731","rc":[{"batb":[[1,2.2,40.89]],"ltp":2.4,"tv":311.7,"id":7412952}]}]}
{"op":"mcm","clk":"1002153986","pt":1580590976723,"mc":[{"id":"1.168209731","rc":[{"trd":[[1.7,8.39]],"batl":[[0,3.2,2.65],[1,95,15.9],[2,990,2.2]],"ltp":1.7,"tv":454.97,"id":8174357},{"trd":[[2.42,5.9],[2.44,11.66]],"batb":[[0,2.2,40.89],[1,2.12,76.4],[2,2.08,21.11]],"ltp":2.42,"tv":329.26,"id":7412952}],"tv":784.24}]}
{"op":"mcm","clk":"1002157647","pt":1580591007939,"mc":[{"id":"1.168209731","rc":[{"batl":[[0,3.2,2.64]],"ltp":1.7,"tv":454.97,"id":8174357}]}]}
{"op":"mcm","clk":"1002184200","pt":1580591235611,"mc":[{"id":"1.168209731","rc":[{"batb":[[0,1.6,226.89],[1,1.59,14.24],[2,1.54,60.58]],"ltp":1.7,"tv":454.97,"id":8174357}]}]}
{"op":"mcm","clk":"1002184332","pt":1580591236820,"mc":[{"id":"1.168209731","rc":[{"batb":[[1,2.08,21.11],[2,1.13,75.72]],"ltp":2.42,"tv":329.26,"id":7412952}]}]}
{"op":"mcm","clk":"1002184450","pt":1580591237819,"mc":[{"id":"1.168209731","rc":[{"batb":[[0,2.1,77.79]],"ltp":2.42,"tv":329.26,"id":7412952}]}]}
{"op":"mcm","clk":"1002184521","pt":1580591238415,"mc":[{"id":"1.168209731","rc":[{"batb":[[2,1.57,60.58]],"ltp":1.7,"tv":454.97,"id":8174357}]}]}
{"op":"mcm","clk":"1002184788","pt":1580591240820,"mc":[{"id":"1.168209731","rc":[{"batb":[[2,1.56,60.58]],"ltp":1.7,"tv":454.97,"id":8174357},{"batb":[[0,2.18,41.65],[1,2.1,77.79],[2,2.08,21.11]],"ltp":2.42,"tv":329.26,"id":7412952}]}]}
{"op":"mcm","clk":"1002186906","pt":1580591257760,"mc":[{"id":"1.168209731","rc":[{"batb":[[1,1.56,60.58],[2,1.53,161.45]],"ltp":1.7,"tv":454.97,"id":8174357},{"batl":[[0,2.66,12.6]],"ltp":2.42,"tv":329.26,"id":7412952}]}]}
{"op":"mcm","clk":"1002186940","pt":1580591258034,"mc":[{"id":"1.168209731","rc":[{"batb":[[0,1.61,20.66],[1,1.6,226.89],[2,1.56,60.58]],"ltp":1.7,"tv":454.97,"id":8174357}]}]}
{"op":"mcm","clk":"1002190868","pt":1580591289673,"mc":[{"id":"1.168209731","rc":[{"batl":[[0,2.64,12.6]],"ltp":2.42,"tv":329.26,"id":7412952}]}]}
{"op":"mcm","clk":"1002251066","pt":1580591850595,"mc":[{"id":"1.168209731","rc":[{"batb":[[0,1.66,51.25],[1,1.61,20.66]],"ltp":1.7,"tv":454.97,"id":8174357}]}]}
{"op":"mcm","clk":"1002254533","pt":1580591876843,"mc":[{"id":"1.168209731","rc":[{"batl":[[0,95,15.9],[1,990,2.2],[2,990,0]],"ltp":2.42,"tv":329.26,"id":7412952}]}]}
{"op":"mcm","clk":"1002254659","pt":1580591877651,"mc":[{"id":"1.168209731","rc":[{"batb":[[1,1.56,60.58],[2,1.53,161.45]],"ltp":1.7,"tv":454.97,"id":8174357},{"batl":[[0,2.52,12.6],[1,95,15.9],[2,990,2.2]],"ltp":2.42,"tv":329.26,"id":7412952}]}]}
{"op":"mcm","clk":"1002254697","pt":1580591877961,"mc":[{"id":"1.168209731","rc":[{"batb":[[0,1.66,70.35]],"ltp":1.7,"tv":454.97,"id":8174357}]}]}
{"op":"mcm","clk":"1002289380","pt":1580592173047,"mc":[{"id":"1.168209731","rc":[{"batb":[[1,1.62,93.93],[2,1.56,60.58]],"ltp":1.7,"tv":454.97,"id":8174357},{"batb":[[0,2.34,66.6],[1,2.18,41.65],[2,2.1,77.79]],"ltp":2.42,"tv":329.26,"id":7412952}]}]}
{"op":"mcm","clk":"1002347480","pt":1580592738951,"mc":[{"id":"1.168209731","rc":[{"batb":[[2,2.14,103.62]],"ltp":2.42,"tv":329.26,"id":7412952}]}]}
{"op":"mcm","clk":"1002434495","pt":1580593637868,"mc":[{"id":"1.168209731","rc":[{"batb":[[0,2.34,64.97]],"ltp":2.42,"tv":329.26,"id":7412952}]}]}
{"op":"mcm","clk":"1002434505","pt":1580593637974,"mc":[{"id":"1.168209731","rc":[{"batb":[[1,1.62,96.3]],"ltp":1.7,"tv":454.97,"id":8174357}]}]}
{"op":"mcm","clk":"1002448499","pt":1580593824780,"mc":[{"id":"1.168209731","rc":[{"batl":[[0,2.46,18.99],[1,2.52,12.6],[2,95,15.9]],"ltp":2.42,"tv":329.26,"id":7412952}]}]}
{"op":"mcm","clk":"1002448789","pt":1580593827955,"mc":[{"id":"1.168209731","rc":[{"batb":[[0,1.66,51.25]],"ltp":1.7,"tv":454.97,"id":8174357},{"batl":[[0,2.46,31.6],[1,95,15.9],[2,990,2.2]],"ltp":2.42,"tv":329.26,"id":7412952}]}]}
{"op":"mcm","clk":"1002448803","pt":1580593828161,"mc":[{"id":"1.168209731","rc":[{"batb":[[0,1.68,18.53],[1,1.66,51.25],[2,1.62,96.3]],"ltp":1.7,"tv":454.97,"id":8174357}]}]}
{"op":"mcm","clk":"1002449114","pt":1580593832663,"mc":[{"id":"1.168209731","rc":[{"batl":[[0,1.8,227.17],[1,3.2,2.64],[2,95,15.9]],"ltp":1.7,"tv":454.97,"id":8174357},{"batl":[[0,2.42,18.99],[1,2.46,12.6],[2,95,15.9]],"ltp":2.42,"tv":329.26,"id":7412952}]}]}
{"op":"mcm","clk":"1002449797","pt":1580593841867,"mc":[{"id":"1.168209731","rc":[{"batl":[[0,2.4,18.99]],"ltp":2.42,"tv":329.26,"id":7412952}]}]}
{"op":"mcm","clk":"1002450420","pt":1580593849913,"mc":[{"id":"1.168209731","rc":[{"batl":[[0,2.46,12.6],[1,95,15.9],[2,990,2.2]],"ltp":2.42,"tv":329.26,"id":7412952}]}]}
{"op":"mcm","clk":"1002479941","pt":1580594226866,"mc":[{"id":"1.168209731","rc":[{"trd":[[2.34,33.61]],"batb":[[0,2.34,48.17]],"ltp":2.34,"tv":362.87,"id":7412952}],"tv":817.84}]}
{"op":"mcm","clk":"1002480028","pt":1580594227900,"mc":[{"id":"1.168209731","rc":[{"batb":[[1,1.67,39.62],[2,1.66,51.25]],"ltp":1.7,"tv":454.97,"id":8174357},{"batb":[[0,2.3,71.02]],"ltp":2.34,"tv":362.87,"id":7412952}]}]}
{"op":"mcm","clk":"1002534444","pt":1580595029823,"mc":[{"id":"1.168209731","rc":[{"batb":[[2,2,37.86]],"ltp":2.34,"tv":362.87,"id":7412952}]}]}
{"op":"mcm","clk":"1002534500","pt":1580595030751,"mc":[{"id":"1.168209731","rc":[{"batb":[[1,2.06,111.44]],"ltp":2.34,"tv":362.87,"id":7412952}]}]}
{"op":"mcm","clk":"1002535151","pt":1580595039774,"mc":[{"id":"1.168209731","rc":[{"batb":[[1,2.1,43.16],[2,2.06,111.44]],"ltp":2.34,"tv":362.87,"id":7412952}]}]}
{"op":"mcm","clk":"1002541951","pt":1580595124574,"mc":[{"id":"1.168209731","rc":[{"batl":[[0,2.44,189.33],[1,2.46,12.6],[2,95,15.9]],"ltp":2.34,"tv":362.87,"id":7412952}]}]}
{"op":"mcm","clk":"1002542160","pt":1580595126816,"mc":[{"id":"1.168209731","rc":[{"batb":[[0,1.67,39.62],[1,1.66,51.25],[2,1.59,60.58]],"ltp":1.7,"tv":454.97,"id":8174357},{"batb":[[1,2,37.86],[2,1.81,37.86]],"batl":[[1,95,15.9],[2,990,2.2]],"ltp":2.34,"tv":362.87,"id":7412952}]}]}
{"op":"mcm","clk":"1002542199","pt":1580595127393,"mc":[{"id":"1.168209731","rc":[{"batb":[[0,1.7,18.01],[1,1.67,39.62],[2,1.66,51.25]],"ltp":1.7,"tv":454.97,"id":8174357},{"batb":[[2,1.99,119.32]],"batl":[[0,2.42,12.6],[1,2.44,189.33],[2,95,15.9]],"ltp":2.34,"tv":362.87,"id":7412952}]}]}
{"op":"mcm","clk":"1002542447","pt":1580595130803,"mc":[{"id":"1.168209731","rc":[{"batl":[[1,2.44,182.83]],"ltp":2.34,"tv":362.87,"id":7412952}]}]}
{"op":"mcm","clk":"1002542537","pt":1580595131898,"mc":[{"id":"1.168209731","rc":[{"batb":[[2,1.81,37.86]],"ltp":2.34,"tv":362.87,"id":7412952}]}]}
{"op":"mcm","clk":"1002542594","pt":1580595132722,"mc":[{"id":"1.168209731","rc":[{"batb":[[1,1.67,215.94]],"ltp":1.7,"tv":454.97,"id":8174357},{"batb":[[1,2.02,45.43],[2,2,37.86]],"ltp":2.34,"tv":362.87,"id":7412952}]}]}
{"op":"mcm","clk":"1002542740","pt":1580595134605,"mc":[{"id":"1.168209731","rc":[{"batb":[[1,2,37.86],[2,1.95,124.34]],"ltp":2.34,"tv":362.87,"id":7412952}]}]}
{"op":"mcm","clk":"1002543344","pt":1580595141632,"mc":[{"id":"1.168209731","rc":[{"batb":[[2,1.98,46.19]],"ltp":2.34,"tv":362.87,"id":7412952}]}]}
{"op":"mcm","clk":"1002553244","pt":1580595256818,"mc":[{"id":"1.168209731","rc":[{"batb":[[0,1.71,54.07],[1,1.7,18.01],[2,1.67,176.31]],"ltp":1.7,"tv":454.97,"id":8174357},{"batb":[[0,2.26,41.34]],"ltp":2.34,"tv":362.87,"id":7412952}]}]}
{"op":"mcm","clk":"1002553340","pt":1580595257547,"mc":[{"id":"1.168209731","rc":[{"batb":[[0,1.72,262.84],[1,1.71,54.07],[2,1.7,18.01]],"ltp":1.7,"tv":454.97,"id":8174357},{"batl":[[1,95,15.9],[2,990,2.2]],"ltp":2.34,"tv":362.87,"id":7412952}]}]}
{"op":"mcm","clk":"1002553491","pt":1580595258914,"mc":[{"id":"1.168209731","rc":[{"batb":[[1,2,84.05],[2,1.96,123.05]],"ltp":2.34,"tv":362.87,"id":7412952}]}]}
{"op":"mcm","clk":"1002553799","pt":1580595262753,"mc":[{"id":"1.168209731","rc":[{"batb":[[1,2,37.86],[2,1.98,46.19]],"ltp":2.34,"tv":362.87,"id":7412952}]}]}
{"op":"mcm","clk":"1002554499","pt":1580595271858,"mc":[{"id":"1.168209731","rc":[{"trd":[[1.8,84.02]],"batl":[[0,1.8,185.16]],"ltp":1.8,"tv":538.99,"id":8174357}],"tv":901.86}]}
{"op":"mcm","clk":"1002555419","pt":1580595282677,"mc":[{"id":"1.168209731","rc":[{"batb":[[0,1.73,17.27],[1,1.72,262.84],[2,1.71,54.07]],"ltp":1.8,"tv":538.99,"id":8174357},{"batl":[[0,2.38,12.6]],"ltp":2.34,"tv":362.87,"id":7412952}]}]}
{"op":"mcm","clk":"1002564181","pt":1580595390320,"mc":[{"id":"1.168209731","rc":[{"batb":[[0,1.73,43.97],[2,1.67,60.58]],"ltp":1.8,"tv":538.99,"id":8174357}]}]}
{"op":"mcm","clk":"1002574484","pt":1580595522432,"mc":[{"id":"1.168209731","rc":[{"batb":[[1,1.67,60.58],[2,1.66,178.98]],"ltp":1.8,"tv":538.99,"id":8174357}]}]}
{"op":"mcm","clk":"1002574518","pt":1580595523119,"mc":[{"id":"1.168209731","rc":[{"batb":[[0,1.73,17.27],[1,1.68,97.56],[2,1.67,60.58]],"ltp":1.8,"tv":538.99,"id":8174357}]}]}
{"op":"mcm","clk":"1002574647","pt":1580595524749,"mc":[{"id":"1.168209731","rc":[{"batb":[[2,1.99,119.32]],"ltp":2.34,"tv":362.87,"id":7412952}]}]}
{"op":"mcm","clk":"1002574752","pt":1580595525929,"mc":[{"id":"1.168209731","rc":[{"batb":[[2,1.64,184.58]],"ltp":1.8,"tv":538.99,"id":8174357}]}]}
{"op":"mcm","clk":"1002574797","pt":1580595526394,"mc":[{"id":"1.168209731","rc":[{"batb":[[1,2.02,46.19],[2,2,37.86]],"ltp":2.34,"tv":362.87,"id":7412952}]}]}
{"op":"mcm","clk":"1002575159","pt":1580595531306,"mc":[{"id":"1.168209731","rc":[{"batb":[[2,1.65,55.28]],"ltp":1.8,"tv":538.99,"id":8174357},{"batb":[[1,2,84.05],[2,1.99,119.32]],"ltp":2.34,"tv":362.87,"id":7412952}]}]}
{"op":"mcm","clk":"1002594291","pt":1580595808525,"mc":[{"id":"1.168209731","rc":[{"batl":[[0,1.79,8.4],[1,1.8,185.16],[2,3.2,2.64]],"ltp":1.8,"tv":538.99,"id":8174357}]}]}
{"op":"mcm","clk":"1002594488","pt":1580595811106,"mc":[{"id":"1.168209731","rc":[{"trd":[[2.38,4.64]],"batl":[[0,2.38,10.28]],"ltp":2.38,"tv":367.51,"id":7412952}],"tv":906.5}]}
{"op":"mcm","clk":"1002599294","pt":1580595882413,"mc":[{"id":"1.168209731","rc":[{"trd":[[1.79,6.16]],"batl":[[0,1.79,5.32]],"ltp":1.79,"tv":545.15,"id":8174357}],"tv":912.67}]}
{"op":"mcm","clk":"1002605891","pt":1580595977787,"mc":[{"id":"1.168209731","rc":[{"trd":[[2.38,12.76]],"batl":[[0,2.38,6.23]],"ltp":2.38,"tv":375.63,"id":7412952}],"tv":920.78}]}
{"op":"mcm","clk":"1002621026","pt":1580596191474,"mc":[{"id":"1.168209731","rc":[{"batb":[[2,1.66,55.28]],"ltp":1.79,"tv":545.15,"id":8174357}]}]}
{"op":"mcm","clk":"1002646963","pt":1580596569893,"mc":[{"id":"1.168209731","rc":[{"batb":[[0,1.74,420.1],[1,1.73,17.27],[2,1.68,97.56]],"ltp":1.79,"tv":545.15,"id":8174357}]}]}
{"op":"mcm","clk":"1002647029","pt":1580596571184,"mc":[{"id":"1.168209731","rc":[{"batb":[[0,1.75,11.06],[1,1.74,420.1],[2,1.73,17.27]],"ltp":1.79,"tv":545.15,"id":8174357},{"batl":[[0,2.34,8.4],[1,2.38,6.23],[2,95,15.9]],"ltp":2.38,"tv":375.63,"id":7412952}]}]}
{"op":"mcm","clk":"1002647127","pt":1580596572595,"mc":[{"id":"1.168209731","rc":[{"batb":[[2,1.73,437.36]],"ltp":1.79,"tv":545.15,"id":8174357}]}]}
{"op":"mcm","clk":"1002647456","pt":1580596577810,"mc":[{"id":"1.168209731","rc":[{"batb":[[0,1.75,431.15]],"ltp":1.79,"tv":545.15,"id":8174357}]}]}
{"op":"mcm","clk":"1002647805","pt":1580596583809,"mc":[{"id":"1.168209731","rc":[{"batb":[[2,1.73,420.1]],"ltp":1.79,"tv":545.15,"id":8174357},{"batl":[[1,95,15.9],[2,990,2.2]],"ltp":2.38,"tv":375.63,"id":7412952}]}]}
{"op":"mcm","clk":"1002647838","pt":1580596584377,"mc":[{"id":"1.168209731","rc":[{"batb":[[0,1.76,11.06],[1,1.75,431.15],[2,1.74,420.1]],"ltp":1.79,"tv":545.15,"id":8174357},{"batl":[[0,2.32,8.4],[1,2.34,8.4],[2,95,15.9]],"ltp":2.38,"tv":375.63,"id":7412952}]}]}
{"op":"mcm","clk":"1002648847","pt":1580596602915,"mc":[{"id":"1.168209731","rc":[{"trd":[[1.76,22.11]],"batb":[[0,1.75,431.15],[1,1.74,420.1],[2,1.73,420.1]],"ltp":1.76,"tv":567.27,"id":8174357},{"batb":[[1,2.08,46.19],[2,2,37.86]],"ltp":2.38,"tv":375.63,"id":7412952}],"tv":942.9}]}
{"op":"mcm","clk":"1002648876","pt":1580596603537,"mc":[{"id":"1.168209731","rc":[{"batb":[[1,1.74,444.7]],"ltp":1.76,"tv":567.27,"id":8174357},{"batb":[[0,2.26,32.84],[2,2.04,113.58]],"ltp":2.38,"tv":375.63,"id":7412952}]}]}
{"op":"mcm","clk":"1002649120","pt":1580596608346,"mc":[{"id":"1.168209731","rc":[{"batb":[[1,2.06,46.19]],"ltp":2.38,"tv":375.63,"id":7412952}]}]}
{"op":"mcm","clk":"1002649514","pt":1580596615538,"mc":[{"id":"1.168209731","rc":[{"batl":[[0,2.34,8.4],[1,95,15.9],[2,990,2.2]],"ltp":2.38,"tv":375.63,"id":7412952}]}]}
{"op":"mcm","clk":"1002650026","pt":1580596624442,"mc":[{"id":"1.168209731","rc":[{"batb":[[2,2,37.86]],"ltp":2.38,"tv":375.63,"id":7412952}]}]}
{"op":"mcm","clk":"1002650100","pt":1580596625744,"mc":[{"id":"1.168209731","rc":[{"batb":[[1,2.1,46.19],[2,2.08,109.37]],"ltp":2.38,"tv":375.63,"id":7412952}]}]}
{"op":"mcm","clk":"1002650222","pt":1580596627858,"mc":[{"id":"1.168209731","rc":[{"batb":[[1,2.08,109.37],[2,2,37.86]],"ltp":2.38,"tv":375.63,"id":7412952}]}]}
{"op":"mcm","clk":"1002650243","pt":1580596628168,"mc":[{"id":"1.168209731","rc":[{"batb":[[1,2.08,155.57]],"ltp":2.38,"tv":375.63,"id":7412952}]}]}
{"op":"mcm","clk":"1002651305","pt":1580596646772,"mc":[{"id":"1.168209731","rc":[{"batl":[[0,1.79,13.72]],"ltp":1.76,"tv":567.27,"id":8174357}]}]}
{"op":"mcm","clk":"1002651346","pt":1580596647599,"mc":[{"id":"1.168209731","rc":[{"batb":[[0,1.76,11.06],[1,1.75,431.15],[2,1.74,444.7]],"ltp":1.76,"tv":567.27,"id":8174357},{"batb":[[0,2.26,39.51]],"batl":[[0,2.32,8.4],[1,2.34,8.4],[2,95,15.9]],"ltp":2.38,"tv":375.63,"id":7412952}]}]}
{"op":"mcm","clk":"1002653093","pt":1580596678827,"mc":[{"id":"1.168209731","rc":[{"batl":[[0,1.79,5.32]],"ltp":1.76,"tv":567.27,"id":8174357}]}]}
{"op":"mcm","clk":"1002653147","pt":1580596679755,"mc":[{"id":"1.168209731","rc":[{"batb":[[0,1.75,431.15],[1,1.74,444.7],[2,1.73,420.1]],"ltp":1.76,"tv":567.27,"id":8174357},{"batl":[[0,2.34,8.4],[1,95,15.9],[2,990,2.2]],"ltp":2.38,"tv":375.63,"id":7412952}]}]}
{"op":"mcm","clk":"1002653210","pt":1580596680739,"mc":[{"id":"1.168209731","rc":[{"batl":[[0,1.79,251.82]],"ltp":1.76,"tv":567.27,"id":8174357},{"batb":[[0,2.26,32.84]],"ltp":2.38,"tv":375.63,"id":7412952}]}]}
{"op":"mcm","clk":"1002653357","pt":1580596682864,"mc":[{"id":"1.168209731","rc":[{"batb":[[1,2.14,103.62],[2,2.08,46.19]],"ltp":2.38,"tv":375.63,"id":7412952}]}]}
{"op":"mcm","clk":"1002653486","pt":1580596684845,"mc":[{"id":"1.168209731","rc":[{"batb":[[2,2.1,46.19]],"ltp":2.38,"tv":375.63,"id":7412952}]}]}
{"op":"mcm","clk":"1002654043","pt":1580596693762,"mc":[{"id":"1.168209731","rc":[{"batb":[[2,2.08,46.19]],"ltp":2.38,"tv":375.63,"id":7412952}]}]}
{"op":"mcm","clk":"1002655023","pt":1580596711893,"mc":[{"id":"1.168209731","rc":[{"batl":[[0,1.78,8.4],[1,1.79,251.82],[2,1.8,185.16]],"ltp":1.76,"tv":567.27,"id":8174357},{"batb":[[0,2.28,6.56],[1,2.26,32.84],[2,2.14,103.62]],"batl":[[0,2.32,8.4],[1,2.34,8.4],[2,95,15.9]],"ltp":2.38,"tv":375.63,"id":7412952}]}]}
{"op":"mcm","clk":"1002655053","pt":1580596712204,"mc":[{"id":"1.168209731","rc":[{"batb":[[0,1.76,11.06],[1,1.75,431.15],[2,1.74,444.7]],"ltp":1.76,"tv":567.27,"id":8174357}]}]}
{"op":"mcm","clk":"1002655761","pt":1580596724797,"mc":[{"id":"1.168209731","rc":[{"trd":[[1.76,50.48]],"batb":[[0,1.75,431.15],[1,1.74,444.7],[2,1.73,420.1]],"batl":[[1,1.79,5.32]],"ltp":1.76,"tv":595.63,"id":8174357},{"trd":[[2.32,21.55]],"batl":[[0,2.34,8.4],[1,95,15.9],[2,990,2.2]],"ltp":2.32,"tv":397.18,"id":7412952}],"tv":992.81}]}
{"op":"mcm","clk":"1002655831","pt":1580596725924,"mc":[{"id":"1.168209731","rc":[{"trd":[[1.75,780.95]],"batb":[[0,1.75,40.68]],"ltp":1.75,"tv":1376.58,"id":8174357},{"trd":[[2.34,42.97]],"batb":[[2,2.08,46.19]],"batl":[[0,2.34,3.72]],"ltp":2.34,"tv":406.54,"id":7412952}],"tv":1783.12}]}
{"op":"mcm","clk":"1002655875","pt":1580596726908,"mc":[{"id":"1.168209731","rc":[{"batl":[[1,1.79,15.83]],"ltp":1.75,"tv":1376.58,"id":8174357},{"batb":[[2,2.2,98.44]],"ltp":2.34,"tv":406.54,"id":7412952}]}]}
{"op":"mcm","clk":"1002656013","pt":1580596728827,"mc":[{"id":"1.168209731","rc":[{"batb":[[2,2.1,46.19]],"ltp":2.34,"tv":406.54,"id":7412952}]}]}
{"op":"mcm","clk":"1002656066","pt":1580596729801,"mc":[{"id":"1.168209731","rc":[{"batb":[[2,2.06,111.44]],"ltp":2.34,"tv":406.54,"id":7412952}]}]}
{"op":"mcm","clk":"1002656386","pt":1580596736111,"mc":[{"id":"1.168209731","rc":[{"batb":[[2,2.08,43.92]],"ltp":2.34,"tv":406.54,"id":7412952}]}]}
{"op":"mcm","clk":"1002656796","pt":1580596743307,"mc":[{"id":"1.168209731","rc":[{"batl":[[0,1.79,15.83],[1,1.8,185.16],[2,3.2,2.64]],"ltp":1.75,"tv":1376.58,"id":8174357}]}]}
{"op":"mcm","clk":"1002656869","pt":1580596744701,"mc":[{"id":"1.168209731","rc":[{"batl":[[0,1.78,12.6],[1,1.79,15.83],[2,1.8,185.16]],"ltp":1.75,"tv":1376.58,"id":8174357},{"batb":[[0,2.26,32.84],[1,2.08,43.92],[2,2.06,111.44]],"ltp":2.34,"tv":406.54,"id":7412952}]}]}
{"op":"mcm","clk":"1002656930","pt":1580596745627,"mc":[{"id":"1.168209731","rc":[{"batb":[[0,2.28,9.85],[1,2.26,32.84],[2,2.08,43.92]],"ltp":2.34,"tv":406.54,"id":7412952}]}]}
{"op":"mcm","clk":"1002657018","pt":1580596746926,"mc":[{"id":"1.168209731","rc":[{"batb":[[2,2.1,151.31]],"ltp":2.34,"tv":406.54,"id":7412952}]}]}
{"op":"mcm","clk":"1002657530","pt":1580596755863,"mc":[{"id":"1.168209731","rc":[{"batb":[[2,2.1,107.39]],"ltp":2.34,"tv":406.54,"id":7412952}]}]}
{"op":"mcm","clk":"1002659158","pt":1580596788554,"mc":[{"id":"1.168209731","rc":[{"batb":[[0,1.75,460.78]],"ltp":1.75,"tv":1376.58,"id":8174357}]}]}
{"op":"mcm","clk":"1002669471","pt":1580596950278,"mc":[{"id":"1.168209731","rc":[{"batb":[[2,2.1,151.31]],"ltp":2.34,"tv":406.54,"id":7412952}]}]}
{"op":"mcm","clk":"1002672386","pt":1580596997330,"mc":[{"id":"1.168209731","rc":[{"batb":[[2,2.1,107.39]],"ltp":2.34,"tv":406.54,"id":7412952}]}]}
{"op":"mcm","clk":"1002674584","pt":1580597036783,"mc":[{"id":"1.168209731","rc":[{"batb":[[2,2.1,151.31]],"ltp":2.34,"tv":406.54,"id":7412952}]}]}
{"op":"mcm","clk":"1002681739","pt":1580597156455,"mc":[{"id":"1.168209731","rc":[{"batb":[[2,2.1,43.92]],"ltp":2.34,"tv":406.54,"id":7412952}]}]}
{"op":"mcm","clk":"1002681869","pt":1580597158952,"mc":[{"id":"1.168209731","rc":[{"batb":[[2,2.08,109.37]],"ltp":2.34,"tv":406.54,"id":7412952}]}]}
{"op":"mcm","clk":"1002681878","pt":1580597159056,"mc":[{"id":"1.168209731","rc":[{"batb":[[2,2.14,43.92]],"ltp":2.34,"tv":406.54,"id":7412952}]}]}
{"op":"mcm","clk":"1002682004","pt":1580597160957,"mc":[{"id":"1.168209731","rc":[{"batb":[[2,2.12,43.92]],"ltp":2.34,"tv":406.54,"id":7412952}]}]}
{"op":"mcm","clk":"1002698405","pt":1580597446925,"mc":[{"id":"1.168209731","rc":[{"batb":[[2,2,37.86]],"ltp":2.34,"tv":406.54,"id":7412952}]}]}
{"op":"mcm","clk":"1002705462","pt":1580597559854,"mc":[{"id":"1.168209731","rc":[{"trd":[[1.78,12.6],[1.79,21.99],[1.8,269.18]],"batb":[[0,1.76,29.44],[1,1.75,460.78],[2,1.74,444.7]],"batl":[[0,3.2,2.64],[1,95,15.9],[2,990,2.2]],"ltp":1.8,"tv":1590.17,"id":8174357},{"trd":[[2.24,148.79],[2.26,78.22],[2.28,29.53]],"batb":[[0,2,37.86],[1,1.97,8.75],[2,1.96,123.05]],"ltp":2.24,"tv":663.08,"id":7412952}],"tv":2253.25}]}
{"op":"mcm","clk":"1002705697","pt":1580597563180,"mc":[{"id":"1.168209731","rc":[{"batb":[[0,1.77,50.69],[1,1.76,29.44],[2,1.75,460.78]],"ltp":1.8,"tv":1590.17,"id":8174357},{"batb":[[0,2.12,73.84],[1,2,37.86],[2,1.97,8.75]],"ltp":2.24,"tv":663.08,"id":7412952}]}]}
{"op":"mcm","clk":"1002705766","pt":1580597564678,"mc":[{"id":"1.168209731","rc":[{"batb":[[2,1.96,123.05]],"ltp":2.24,"tv":663.08,"id":7412952}]}]}
{"op":"mcm","clk":"1002706760","pt":1580597581807,"mc":[{"id":"1.168209731","rc":[{"batl":[[0,1.9,8.4],[1,3.2,2.64],[2,95,15.9]],"ltp":1.8,"tv":1590.17,"id":8174357},{"batb":[[0,2.12,81.35]],"batl":[[0,2.3,8.4],[1,2.34,3.72],[2,95,15.9]],"ltp":2.24,"tv":663.08,"id":7412952}]}]}
{"op":"mcm","clk":"1002706780","pt":1580597582118,"mc":[{"id":"1.168209731","rc":[{"batb":[[0,1.77,61.6]],"ltp":1.8,"tv":1590.17,"id":8174357}]}]}
{"op":"mcm","clk":"1002708418","pt":1580597608405,"mc":[{"id":"1.168209731","rc":[{"batl":[[0,1.83,75.72],[1,1.9,8.4],[2,3.2,2.64]],"ltp":1.8,"tv":1590.17,"id":8174357}]}]}
{"op":"mcm","clk":"1002708810","pt":1580597613732,"mc":[{"id":"1.168209731","rc":[{"batl":[[1,3.2,2.64],[2,95,15.9]],"ltp":1.8,"tv":1590.17,"id":8174357},{"batl":[[0,2.34,3.72],[1,95,15.9],[2,990,2.2]],"ltp":2.24,"tv":663.08,"id":7412952}]}]}
{"op":"mcm","clk":"1002708883","pt":1580597614715,"mc":[{"id":"1.168209731","rc":[{"batb":[[0,1.77,50.69]],"ltp":1.8,"tv":1590.17,"id":8174357},{"batb":[[0,2.12,73.84]],"ltp":2.24,"tv":663.08,"id":7412952}]}]}
{"op":"mcm","clk":"1002712403","pt":1580597672898,"mc":[{"id":"1.168209731","rc":[{"trd":[[1.83,75.72]],"batl":[[0,3.2,2.64],[1,95,15.9],[2,990,2.2]],"ltp":1.83,"tv":1665.89,"id":8174357},{"trd":[[2.12,147.69],[2.2,62.99]],"batb":[[0,2,37.86],[1,1.96,123.05],[2,1.81,37.86]],"ltp":2.12,"tv":873.76,"id":7412952}],"tv":2539.66}]}
{"op":"mcm","clk":"1002712432","pt":1580597673422,"mc":[{"id":"1.168209731","rc":[{"batb":[[0,2.06,52.58],[1,2,37.86],[2,1.96,123.05]],"ltp":2.12,"tv":873.76,"id":7412952}]}]}
{"op":"mcm","clk":"1002712521","pt":1580597674818,"mc":[{"id":"1.168209731","rc":[{"batb":[[0,1.82,86.91],[1,1.78,178.66],[2,1.76,29.44]],"ltp":1.83,"tv":1665.89,"id":8174357},{"batb":[[0,2.08,21.21],[1,2.06,194.74],[2,2,37.86]],"ltp":2.12,"tv":873.76,"id":7412952}]}]}
{"op":"mcm","clk":"1002712565","pt":1580597675489,"mc":[{"id":"1.168209731","rc":[{"batb":[[0,1.83,7.92],[1,1.82,86.91],[2,1.75,460.78]],"ltp":1.83,"tv":1665.89,"id":8174357},{"batb":[[1,2,37.86],[2,1.96,123.05]],"batl":[[0,95,15.9],[1,990,2.2],[2,990,0]],"ltp":2.12,"tv":873.76,"id":7412952}]}]}
{"op":"mcm","clk":"1002714994","pt":1580597714937,"mc":[{"id":"1.168209731","rc":[{"batl":[[0,13.5,3.36],[1,95,15.9],[2,990,2.2]],"ltp":2.12,"tv":873.76,"id":7412952}]}]}
{"op":"mcm","clk":"1002715001","pt":1580597715138,"mc":[{"id":"1.168209731","rc":[{"batl":[[0,3.15,3.36],[1,3.2,2.64],[2,95,15.9]],"ltp":1.83,"tv":1665.89,"id":8174357}]}]}
{"op":"mcm","clk":"1002720963","pt":1580597799368,"mc":[{"id":"1.168209731","rc":[{"batb":[[2,1.98,46.19]],"ltp":2.12,"tv":873.76,"id":7412952}]}]}
{"op":"mcm","clk":"1002721853","pt":1580597812881,"mc":[{"id":"1.168209731","rc":[{"batb":[[0,1.84,64.37],[1,1.75,460.78],[2,1.74,420.1]],"ltp":1.83,"tv":1665.89,"id":8174357},{"batb":[[0,2.02,68.73]],"ltp":2.12,"tv":873.76,"id":7412952}]}]}
{"op":"mcm","clk":"1002721861","pt":1580597812984,"mc":[{"id":"1.168209731","rc":[{"batb":[[0,2.02,74.15]],"ltp":2.12,"tv":873.76,"id":7412952}]}]}
{"op":"mcm","clk":"1002725193","pt":1580597870667,"mc":[{"id":"1.168209731","rc":[{"trd":[[1.88,45.98]],"batl":[[0,1.88,43.27],[1,3.15,3.36],[2,3.2,2.64]],"ltp":1.88,"tv":1711.87,"id":8174357}],"tv":2585.64}]}
{"op":"mcm","clk":"1002725282","pt":1580597871750,"mc":[{"id":"1.168209731","rc":[{"trd":[[1.84,31.56]],"batb":[[0,1.81,82.84]],"ltp":1.84,"tv":1743.43,"id":8174357},{"batb":[[0,2.04,66.32],[1,2.02,5.42],[2,2,37.86]],"ltp":2.12,"tv":873.76,"id":7412952}],"tv":2617.19}]}
{"op":"mcm","clk":"1002725348","pt":1580597872731,"mc":[{"id":"1.168209731","rc":[{"batb":[[1,2,37.86],[2,1.98,46.19]],"ltp":2.12,"tv":873.76,"id":7412952}]}]}
{"op":"mcm","clk":"1002725876","pt":1580597881140,"mc":[{"id":"1.168209731","rc":[{"batl":[[1,3.2,2.64],[2,95,15.9]],"ltp":1.84,"tv":1743.43,"id":8174357}]}]}
{"op":"mcm","clk":"1002728084","pt":1580597913594,"mc":[{"id":"1.168209731","rc":[{"batb":[[2,1.74,579.73]],"ltp":1.84,"tv":1743.43,"id":8174357}]}]}
{"op":"mcm","clk":"1002728161","pt":1580597914881,"mc":[{"id":"1.168209731","rc":[{"batb":[[2,1.88,134.23]],"ltp":2.12,"tv":873.76,"id":7412952}]}]}
{"op":"mcm","clk":"1002728193","pt":1580597915495,"mc":[{"id":"1.168209731","rc":[{"batb":[[1,1.76,57.55],[2,1.75,460.78]],"ltp":1.84,"tv":1743.43,"id":8174357}]}]}
{"op":"mcm","clk":"1002728658","pt":1580597923286,"mc":[{"id":"1.168209731","rc":[{"batb":[[1,1.75,460.78],[2,1.74,637.28]],"ltp":1.84,"tv":1743.43,"id":8174357},{"batb":[[2,1.89,48.46]],"ltp":2.12,"tv":873.76,"id":7412952}]}]}
{"op":"mcm","clk":"1002728694","pt":1580597924005,"mc":[{"id":"1.168209731","rc":[{"trd":[[1.88,132.42]],"batl":[[0,3.2,2.69],[1,95,15.9],[2,990,2.2]],"ltp":1.88,"tv":1829.87,"id":8174357}],"tv":2703.64}]}
{"op":"mcm","clk":"1002728749","pt":1580597925090,"mc":[{"id":"1.168209731","rc":[{"batb":[[1,2.02,5.42],[2,2,37.86]],"ltp":2.12,"tv":873.76,"id":7412952}]}]}
{"op":"mcm","clk":"1002729255","pt":1580597932902,"mc":[{"id":"1.168209731","rc":[{"batb":[[0,2.04,49.87]],"ltp":2.12,"tv":873.76,"id":7412952}]}]}
{"op":"mcm","clk":"1002729327","pt":1580597933891,"mc":[{"id":"1.168209731","rc":[{"batb":[[0,1.83,7.92],[1,1.82,89.68],[2,1.75,460.78]],"ltp":1.88,"tv":1829.87,"id":8174357}]}]}
{"op":"mcm","clk":"1002729337","pt":1580597934086,"mc":[{"id":"1.168209731","rc":[{"batb":[[0,1.84,224.47],[1,1.83,7.92],[2,1.82,89.68]],"ltp":1.88,"tv":1829.87,"id":8174357}]}]}
{"op":"mcm","clk":"1002729396","pt":1580597935587,"mc":[{"id":"1.168209731","rc":[{"batb":[[0,1.85,9.16],[1,1.84,224.47]],"ltp":1.88,"tv":1829.87,"id":8174357}]}]}
{"op":"mcm","clk":"1002730038","pt":1580597945633,"mc":[{"id":"1.168209731","rc":[{"batb":[[0,1.86,45.44],[1,1.85,9.16],[2,1.84,224.47]],"ltp":1.88,"tv":1829.87,"id":8174357}]}]}
{"op":"mcm","clk":"1002730530","pt":1580597952721,"mc":[{"id":"1.168209731","rc":[{"trd":[[1.86,9]],"batb":[[0,1.86,40.93]],"ltp":1.86,"tv":1838.88,"id":8174357},{"batb":[[0,2.04,53.91]],"ltp":2.12,"tv":873.76,"id":7412952}],"tv":2712.64}]}
{"op":"mcm","clk":"1002731951","pt":1580597974849,"mc":[{"id":"1.168209731","rc":[{"batl":[[0,3.15,3.41],[1,3.2,2.64],[2,95,15.9]],"ltp":1.86,"tv":1838.88,"id":8174357}]}]}
{"op":"mcm","clk":"1002732036","pt":1580597976039,"mc":[{"id":"1.168209731","rc":[{"batb":[[1,1.85,18.64]],"ltp":1.86,"tv":1838.88,"id":8174357}]}]}
{"op":"mcm","clk":"1002732272","pt":1580597978847,"mc":[{"id":"1.168209731","rc":[{"trd":[[1.86,21.1]],"batb":[[0,1.85,18.64],[1,1.84,224.47],[2,1.81,145.84]],"ltp":1.86,"tv":1850.98,"id":8174357}],"tv":2724.74}]}
{"op":"mcm","clk":"1002732284","pt":1580597979053,"mc":[{"id":"1.168209731","rc":[{"batb":[[0,1.85,64.33]],"ltp":1.86,"tv":1850.98,"id":8174357},{"batb":[[0,2.04,59.33]],"ltp":2.12,"tv":873.76,"id":7412952}]}]}
{"op":"mcm","clk":"1002755277","pt":1580598317890,"mc":[{"id":"1.168209731","rc":[{"batb":[[1,1.81,145.84],[2,1.76,57.55]],"ltp":1.86,"tv":1850.98,"id":8174357}]}]}
{"op":"mcm","clk":"1002755287","pt":1580598317995,"mc":[{"id":"1.168209731","rc":[{"batb":[[0,1.86,218.11],[1,1.85,64.33],[2,1.81,145.84]],"ltp":1.86,"tv":1850.98,"id":8174357}]}]}
{"op":"mcm","clk":"1002755378","pt":1580598319710,"mc":[{"id":"1.168209731","rc":[{"batb":[[0,1.87,21.54],[1,1.86,218.11],[2,1.85,45.7]],"ltp":1.86,"tv":1850.98,"id":8174357}]}]}
{"op":"mcm","clk":"1002757128","pt":1580598347121,"mc":[{"id":"1.168209731","rc":[{"batb":[[0,1.87,46.04],[2,1.81,145.84]],"ltp":1.86,"tv":1850.98,"id":8174357}]}]}
{"op":"mcm","clk":"1002787030","pt":1580598758412,"mc":[{"id":"1.168209731","rc":[{"trd":[[1.88,132.52]],"batb":[[0,1.88,215.66],[1,1.87,46.04]],"batl":[[0,3.15,3.36]],"ltp":1.88,"tv":1851.07,"id":8174357}],"tv":2724.84}]}
{"op":"mcm","clk":"1002787108","pt":1580598759505,"mc":[{"id":"1.168209731","rc":[{"batb":[[0,1.89,20.95],[1,1.88,215.66],[2,1.87,24.5]],"ltp":1.88,"tv":1851.07,"id":8174357}]}]}
{"op":"mcm","clk":"1002787143","pt":1580598760021,"mc":[{"id":"1.168209731","rc":[{"batb":[[2,1.81,233.67]],"ltp":2.12,"tv":873.76,"id":7412952}]}]}
{"op":"mcm","clk":"1002787225","pt":1580598761225,"mc":[{"id":"1.168209731","rc":[{"batb":[[1,1.81,233.67],[2,1.71,37.86]],"ltp":2.12,"tv":873.76,"id":7412952}]}]}
{"op":"mcm","clk":"1002793330","pt":1580598839614,"mc":[{"id":"1.168209731","rc":[{"batb":[[1,1.87,24.5],[2,1.81,145.84]],"ltp":1.88,"tv":1851.07,"id":8174357}]}]}
{"op":"mcm","clk":"1002793546","pt":1580598841710,"mc":[{"id":"1.168209731","rc":[{"batb":[[0,1.87,24.5],[1,1.81,145.84],[2,1.78,57.55]],"ltp":1.88,"tv":1851.07,"id":8174357}]}]}
{"op":"mcm","clk":"1002795548","pt":1580598865545,"mc":[{"id":"1.168209731","rc":[{"batb":[[0,1.88,215.71],[1,1.82,79.12],[2,1.81,145.84]],"ltp":1.88,"tv":1851.07,"id":8174357},{"batb":[[0,2.02,75.74]],"ltp":2.12,"tv":873.76,"id":7412952}]}]}
{"op":"mcm","clk":"1002795626","pt":1580598866236,"mc":[{"id":"1.168209731","rc":[{"batb":[[0,1.89,16.33],[1,1.88,215.71],[2,1.82,79.12]],"ltp":1.88,"tv":1851.07,"id":8174357}]}]}
{"op":"mcm","clk":"1002817772","pt":1580599178680,"mc":[{"id":"1.168209731","rc":[{"batb":[[0,1.89,25.78]],"batl":[[0,1.99,8.4],[1,3.15,3.36],[2,3.2,2.64]],"ltp":1.88,"tv":1851.07,"id":8174357},{"trd":[[2.12,164.49]],"batb":[[0,2.02,83.97]],"ltp":2.12,"tv":890.56,"id":7412952}],"tv":2741.64}]}
{"op":"mcm","clk":"1002818026","pt":1580599181880,"mc":[{"id":"1.168209731","rc":[{"batl":[[1,3.2,2.64],[2,95,15.9]],"ltp":1.88,"tv":1851.07,"id":8174357}]}]}
{"op":"mcm","clk":"1002820338","pt":1580599210297,"mc":[{"id":"1.168209731","rc":[{"batb":[[0,1.89,16.33]],"ltp":1.88,"tv":1851.07,"id":8174357}]}]}
{"op":"mcm","clk":"1002838748","pt":1580599467075,"mc":[{"id":"1.168209731","rc":[{"batb":[[1,1.82,79.12],[2,1.81,145.84]],"ltp":1.88,"tv":1851.07,"id":8174357}]}]}
{"op":"mcm","clk":"1002838891","pt":1580599468807,"mc":[{"id":"1.168209731","rc":[{"batb":[[0,1.84,223.47],[1,1.82,97.05]],"ltp":1.88,"tv":1851.07,"id":8174357}]}]}
{"op":"mcm","clk":"1002838976","pt":1580599469810,"mc":[{"id":"1.168209731","rc":[{"batb":[[2,1.78,209]],"ltp":1.88,"tv":1851.07,"id":8174357},{"batb":[[1,1.82,144.06],[2,1.81,87.84]],"ltp":2.12,"tv":890.56,"id":7412952}]}]}
{"op":"mcm","clk":"1002839045","pt":1580599470723,"mc":[{"id":"1.168209731","rc":[{"batb":[[0,1.85,232.53],[1,1.82,79.12]],"ltp":1.88,"tv":1851.07,"id":8174357}]}]}
{"op":"mcm","clk":"1002839128","pt":1580599471834,"mc":[{"id":"1.168209731","rc":[{"batb":[[2,1.78,151.45]],"ltp":1.88,"tv":1851.07,"id":8174357},{"batb":[[1,1.85,49.98],[2,1.82,144.06]],"ltp":2.12,"tv":890.56,"id":7412952}]}]}
{"op":"mcm","clk":"1002839262","pt":1580599473829,"mc":[{"id":"1.168209731","rc":[{"batb":[[2,1.79,50.73]],"ltp":1.88,"tv":1851.07,"id":8174357},{"batb":[[1,1.83,49.98]],"ltp":2.12,"tv":890.56,"id":7412952}]}]}
{"op":"mcm","clk":"1002839776","pt":1580599480918,"mc":[{"id":"1.168209731","rc":[{"batb":[[0,1.86,9.28],[1,1.85,232.53],[2,1.82,79.12]],"ltp":1.88,"tv":1851.07,"id":8174357}]}]}
{"op":"mcm","clk":"1002839791","pt":1580599481128,"mc":[{"id":"1.168209731","rc":[{"batb":[[1,1.85,10.16]],"ltp":1.88,"tv":1851.07,"id":8174357}]}]}
{"op":"mcm","clk":"1002839881","pt":1580599482526,"mc":[{"id":"1.168209731","rc":[{"batb":[[0,1.83,224.68],[1,1.82,79.12],[2,1.8,8.06]],"ltp":1.88,"tv":1851.07,"id":8174357}]}]}
{"op":"mcm","clk":"1002840010","pt":1580599484147,"mc":[{"id":"1.168209731","rc":[{"batb":[[2,1.79,50.73]],"ltp":1.88,"tv":1851.07,"id":8174357}]}]}
{"op":"mcm","clk":"1002840572","pt":1580599491931,"mc":[{"id":"1.168209731","rc":[{"batb":[[0,1.84,14.69],[1,1.83,224.68],[2,1.82,79.12]],"ltp":1.88,"tv":1851.07,"id":8174357}]}]}
{"op":"mcm","clk":"1002840608","pt":1580599492343,"mc":[{"id":"1.168209731","rc":[{"batb":[[0,1.85,222.37],[1,1.84,14.69]],"ltp":1.88,"tv":1851.07,"id":8174357}]}]}
{"op":"mcm","clk":"1002840715","pt":1580599493956,"mc":[{"id":"1.168209731","rc":[{"batb":[[0,1.86,7.8],[1,1.85,222.37]],"ltp":1.88,"tv":1851.07,"id":8174357}]}]}
{"op":"mcm","clk":"1002840742","pt":1580599494221,"mc":[{"id":"1.168209731","rc":[{"batb":[[1,1.82,79.12],[2,1.79,50.73]],"ltp":1.88,"tv":1851.07,"id":8174357}]}]}
{"op":"mcm","clk":"1002840859","pt":1580599495941,"mc":[{"id":"1.168209731","rc":[{"batb":[[0,1.83,232.6]],"ltp":1.88,"tv":1851.07,"id":8174357}]}]}
{"op":"mcm","clk":"1002841267","pt":1580599501532,"mc":[{"id":"1.168209731","rc":[{"batb":[[0,1.85,222.37],[1,1.84,56.62],[2,1.83,7.92]],"ltp":1.88,"tv":1851.07,"id":8174357}]}]}
{"op":"mcm","clk":"1002841347","pt":1580599502840,"mc":[{"id":"1.168209731","rc":[{"batb":[[2,1.79,50.73]],"ltp":1.88,"tv":1851.07,"id":8174357}]}]}
{"op":"mcm","clk":"1002843646","pt":1580599535801,"mc":[{"id":"1.168209731","rc":[{"batb":[[0,1.86,12.89],[1,1.85,222.37],[2,1.84,56.62]],"ltp":1.88,"tv":1851.07,"id":8174357}]}]}
{"op":"mcm","clk":"1002843661","pt":1580599536008,"mc":[{"id":"1.168209731","rc":[{"batb":[[1,1.84,56.62],[2,1.79,50.73]],"ltp":1.88,"tv":1851.07,"id":8174357}]}]}
{"op":"mcm","clk":"1002843763","pt":1580599537521,"mc":[{"id":"1.168209731","rc":[{"batb":[[0,1.85,222.37]],"ltp":1.88,"tv":1851.07,"id":8174357}]}]}
{"op":"mcm","clk":"1002844651","pt":1580599550430,"mc":[{"id":"1.168209731","rc":[{"batb":[[0,1.86,7.8]],"ltp":1.88,"tv":1851.07,"id":8174357}]}]}
{"op":"mcm","clk":"1002844751","pt":1580599551804,"mc":[{"id":"1.168209731","rc":[{"batb":[[0,1.84,56.62],[1,1.79,50.73],[2,1.78,151.45]],"ltp":1.88,"tv":1851.07,"id":8174357}]}]}
{"op":"mcm","clk":"1002844769","pt":1580599552013,"mc":[{"id":"1.168209731","rc":[{"batb":[[0,1.85,222.37],[1,1.84,56.62],[2,1.79,50.73]],"ltp":1.88,"tv":1851.07,"id":8174357}]}]}
{"op":"mcm","clk":"1002847959","pt":1580599595271,"mc":[{"id":"1.168209731","rc":[{"batb":[[0,1.86,13.32]],"ltp":1.88,"tv":1851.07,"id":8174357}]}]}
{"op":"mcm","clk":"1002848074","pt":1580599596756,"mc":[{"id":"1.168209731","rc":[{"batb":[[0,1.84,56.62],[1,1.79,50.73],[2,1.78,151.45]],"ltp":1.88,"tv":1851.07,"id":8174357}]}]}
{"op":"mcm","clk":"1002848095","pt":1580599597077,"mc":[{"id":"1.168209731","rc":[{"batb":[[0,1.85,222.37],[1,1.84,56.62],[2,1.79,50.73]],"ltp":1.88,"tv":1851.07,"id":8174357}]}]}
{"op":"mcm","clk":"1002849061","pt":1580599609313,"mc":[{"id":"1.168209731","rc":[{"batb":[[0,1.86,7.8]],"ltp":1.88,"tv":1851.07,"id":8174357}]}]}
{"op":"mcm","clk":"1002849229","pt":1580599610680,"mc":[{"id":"1.168209731","rc":[{"batb":[[0,1.84,56.62],[1,1.79,50.73],[2,1.78,151.45]],"ltp":1.88,"tv":1851.07,"id":8174357}]}]}
{"op":"mcm","clk":"1002849401","pt":1580599612602,"mc":[{"id":"1.168209731","rc":[{"batb":[[0,1.85,222.37],[1,1.84,56.62],[2,1.79,50.73]],"ltp":1.88,"tv":1851.07,"id":8174357}]}]}
{"op":"mcm","clk":"1002850854","pt":1580599630913,"mc":[{"id":"1.168209731","rc":[{"batb":[[0,1.86,34.99],[1,1.79,50.73],[2,1.78,151.45]],"ltp":1.88,"tv":1851.07,"id":8174357}]}]}
{"op":"mcm","clk":"1002860813","pt":1580599758484,"mc":[{"id":"1.168209731","rc":[{"batb":[[0,1.84,223.47],[1,1.81,90.72],[2,1.79,50.73]],"ltp":1.88,"tv":1851.07,"id":8174357}]}]}
{"op":"mcm","clk":"1002860923","pt":1580599759742,"mc":[{"id":"1.168209731","rc":[{"batb":[[0,1.85,16.86],[1,1.84,223.47],[2,1.81,90.72]],"ltp":1.88,"tv":1851.07,"id":8174357}]}]}
{"op":"mcm","clk":"1002860960","pt":1580599760158,"mc":[{"id":"1.168209731","rc":[{"batb":[[0,1.85,239.23],[1,1.81,90.72],[2,1.79,50.73]],"ltp":1.88,"tv":1851.07,"id":8174357}]}]}
{"op":"mcm","clk":"1002871641","pt":1580599885855,"mc":[{"id":"1.168209731","rc":[{"batb":[[0,1.86,34.99],[1,1.85,239.23]],"ltp":1.88,"tv":1851.07,"id":8174357}]}]}
{"op":"mcm","clk":"1002871657","pt":1580599886011,"mc":[{"id":"1.168209731","rc":[{"batb":[[1,1.85,16.86]],"ltp":1.88,"tv":1851.07,"id":8174357}]}]}
{"op":"mcm","clk":"1002871801","pt":1580599887729,"mc":[{"id":"1.168209731","rc":[{"batb":[[1,1.79,50.73],[2,1.78,151.45]],"ltp":1.88,"tv":1851.07,"id":8174357}]}]}
{"op":"mcm","clk":"1002880823","pt":1580600012710,"mc":[{"id":"1.168209731","rc":[{"batb":[[0,1.83,224.68],[1,1.81,90.72],[2,1.79,50.73]],"ltp":1.88,"tv":1851.07,"id":8174357}]}]}
{"op":"mcm","clk":"1002880911","pt":1580600013917,"mc":[{"id":"1.168209731","rc":[{"batb":[[0,1.84,16.89]],"ltp":1.88,"tv":1851.07,"id":8174357}]}]}
{"op":"mcm","clk":"1002881044","pt":1580600014914,"mc":[{"id":"1.168209731","rc":[{"batb":[[0,1.85,222.37]],"ltp":1.88,"tv":1851.07,"id":8174357}]}]}
{"op":"mcm","clk":"1002881079","pt":1580600015328,"mc":[{"id":"1.168209731","rc":[{"batb":[[0,1.86,18.69]],"ltp":1.88,"tv":1851.07,"id":8174357}]}]}
{"op":"mcm","clk":"1002881223","pt":1580600016733,"mc":[{"id":"1.168209731","rc":[{"batb":[[0,1.84,223.47],[1,1.82,7.97],[2,1.81,90.72]],"ltp":1.88,"tv":1851.07,"id":8174357}]}]}
{"op":"mcm","clk":"1002881358","pt":1580600018823,"mc":[{"id":"1.168209731","rc":[{"batb":[[0,1.85,239.21],[1,1.81,90.72],[2,1.79,50.73]],"ltp":1.88,"tv":1851.07,"id":8174357}]}]}
{"op":"mcm","clk":"1002889402","pt":1580600139904,"mc":[{"id":"1.168209731","rc":[{"batb":[[0,1.86,34.99],[1,1.85,16.84]],"ltp":1.88,"tv":1851.07,"id":8174357}]}]}
{"op":"mcm","clk":"1002889487","pt":1580600141060,"mc":[{"id":"1.168209731","rc":[{"batb":[[1,1.79,50.73],[2,1.78,151.45]],"ltp":1.88,"tv":1851.07,"id":8174357}]}]}
{"op":"mcm","clk":"1002897934","pt":1580600267919,"mc":[{"id":"1.168209731","rc":[{"batb":[[0,1.81,90.72]],"ltp":1.88,"tv":1851.07,"id":8174357}]}]}
{"op":"mcm","clk":"1002897943","pt":1580600268023,"mc":[{"id":"1.168209731","rc":[{"batb":[[0,1.81,318.01]],"ltp":1.88,"tv":1851.07,"id":8174357}]}]}
{"op":"mcm","clk":"1002898040","pt":1580600269632,"mc":[{"id":"1.168209731","rc":[{"batb":[[0,1.83,224.68],[1,1.82,17.62],[2,1.81,90.72]],"ltp":1.88,"tv":1851.07,"id":8174357}]}]}
{"op":"mcm","clk":"1002898153","pt":1580600271406,"mc":[{"id":"1.168209731","rc":[{"batb":[[0,1.85,222.37],[1,1.84,17.48]],"ltp":1.88,"tv":1851.07,"id":8174357}]}]}
{"op":"mcm","clk":"1002898245","pt":1580600272907,"mc":[{"id":"1.168209731","rc":[{"batb":[[0,1.86,17.49],[1,1.85,222.37]],"ltp":1.88,"tv":1851.07,"id":8174357}]}]}
{"op":"mcm","clk":"1002898259","pt":1580600273216,"mc":[{"id":"1.168209731","rc":[{"batb":[[1,1.81,90.72],[2,1.79,50.73]],"ltp":1.88,"tv":1851.07,"id":8174357}]}]}
{"op":"mcm","clk":"1002898317","pt":1580600274509,"mc":[{"id":"1.168209731","rc":[{"batb":[[0,1.82,226.14]],"ltp":1.88,"tv":1851.07,"id":8174357}]}]}
{"op":"mcm","clk":"1002898385","pt":1580600275699,"mc":[{"id":"1.168209731","rc":[{"batb":[[0,1.83,7.92],[1,1.82,226.14],[2,1.81,90.72]],"ltp":1.88,"tv":1851.07,"id":8174357}]}]}
{"op":"mcm","clk":"1002898404","pt":1580600276116,"mc":[{"id":"1.168209731","rc":[{"batb":[[0,1.84,223.47],[1,1.83,7.92]],"ltp":1.88,"tv":1851.07,"id":8174357}]}]}
{"op":"mcm","clk":"1002898477","pt":1580600277428,"mc":[{"id":"1.168209731","rc":[{"batb":[[0,1.85,240.02],[1,1.81,90.72],[2,1.79,50.73]],"ltp":1.88,"tv":1851.07,"id":8174357}]}]}
{"op":"mcm","clk":"1002905055","pt":1580600385511,"mc":[{"id":"1.168209731","rc":[{"batb":[[0,1.86,420.1],[1,1.85,17.65],[2,1.84,420.1]],"ltp":1.88,"tv":1851.07,"id":8174357}]}]}
{"op":"mcm","clk":"1002905099","pt":1580600386133,"mc":[{"id":"1.168209731","rc":[{"batb":[[0,1.87,29.28],[1,1.86,420.1]],"ltp":1.88,"tv":1851.07,"id":8174357}]}]}
{"op":"mcm","clk":"1002905823","pt":1580600397056,"mc":[{"id":"1.168209731","rc":[{"batb":[[0,1.87,53.78]],"ltp":1.88,"tv":1851.07,"id":8174357}]}]}
{"op":"mcm","clk":"1002916015","pt":1580600547124,"mc":[{"id":"1.168209731","rc":[{"batl":[[1,2,68.06],[2,3.2,2.64]],"ltp":1.88,"tv":1851.07,"id":8174357}]}]}
{"op":"mcm","clk":"1002916142","pt":1580600548837,"mc":[{"id":"1.168209731","rc":[{"batb":[[0,2.02,89.39]],"ltp":2.12,"tv":890.56,"id":7412952}]}]}
{"op":"mcm","clk":"1002996376","pt":1580601724825,"mc":[{"id":"1.168209731","rc":[{"batb":[[0,1.88,36.25],[1,1.87,53.78],[2,1.86,420.1]],"ltp":1.88,"tv":1851.07,"id":8174357},{"batb":[[0,2.02,56.06]],"ltp":2.12,"tv":890.56,"id":7412952}]}]}
{"op":"mcm","clk":"1003149214","pt":1580603597467,"mc":[{"id":"1.168209731","rc":[{"trd":[[2.02,4]],"batb":[[0,2.02,54.06]],"ltp":2.02,"tv":894.56,"id":7412952}],"tv":2745.64}]}
{"op":"mcm","clk":"1003149267","pt":1580603598140,"mc":[{"id":"1.168209731","rc":[{"batb":[[0,1.88,38.38]],"ltp":1.88,"tv":1851.07,"id":8174357}]}]}
{"op":"mcm","clk":"1003155462","pt":1580603668776,"mc":[{"id":"1.168209731","rc":[{"batb":[[2,1.81,37.86]],"ltp":2.02,"tv":894.56,"id":7412952}]}]}
{"op":"mcm","clk":"1003155525","pt":1580603669452,"mc":[{"id":"1.168209731","rc":[{"batb":[[2,1.82,219.78]],"ltp":2.02,"tv":894.56,"id":7412952}]}]}
{"op":"mcm","clk":"1003189247","pt":1580604149655,"mc":[{"id":"1.168209731","rc":[{"trd":[[2.02,54.41]],"batb":[[0,2.02,28.85]],"ltp":2.02,"tv":944.97,"id":7412952}],"tv":2796.05}]}
{"op":"mcm","clk":"1003189342","pt":1580604151248,"mc":[{"id":"1.168209731","rc":[{"batb":[[0,1.88,79.1],[1,1.87,29.28]],"ltp":1.88,"tv":1851.07,"id":8174357},{"batb":[[0,2.02,13.65],[1,1.95,76.45],[2,1.83,49.98]],"ltp":2.02,"tv":944.97,"id":7412952}]}]}
{"op":"mcm","clk":"1003326321","pt":1580606256044,"mc":[{"id":"1.168209731","rc":[{"trd":[[2.02,69.61]],"batb":[[0,2.02,6.05]],"ltp":2.02,"tv":960.17,"id":7412952}],"tv":2811.25}]}
{"op":"mcm","clk":"1003326460","pt":1580606257647,"mc":[{"id":"1.168209731","rc":[{"batb":[[0,1.95,77.08],[1,1.83,49.98],[2,1.82,219.78]],"ltp":2.02,"tv":960.17,"id":7412952}]}]}
{"op":"mcm","clk":"1003328209","pt":1580606279785,"mc":[{"id":"1.168209731","rc":[{"batb":[[0,2,8.4],[1,1.95,76.45],[2,1.83,49.98]],"batl":[[0,2.14,8.4],[1,13.5,3.36],[2,95,15.9]],"ltp":2.02,"tv":960.17,"id":7412952}]}]}
{"op":"mcm","clk":"1003328227","pt":1580606279990,"mc":[{"id":"1.168209731","rc":[{"batb":[[0,1.88,88.64]],"ltp":1.88,"tv":1851.07,"id":8174357}]}]}
{"op":"mcm","clk":"1003328325","pt":1580606281077,"mc":[{"id":"1.168209731","rc":[{"batb":[[0,2.02,5.42],[1,2,8.4],[2,1.95,76.45]],"ltp":2.02,"tv":960.17,"id":7412952}]}]}
{"op":"mcm","clk":"1003328755","pt":1580606285698,"mc":[{"id":"1.168209731","rc":[{"batl":[[1,95,15.9],[2,990,2.2]],"ltp":2.02,"tv":960.17,"id":7412952}]}]}
{"op":"mcm","clk":"1003330964","pt":1580606311717,"mc":[{"id":"1.168209731","rc":[{"batb":[[0,2.02,13.65],[1,1.95,76.45],[2,1.83,49.98]],"ltp":2.02,"tv":960.17,"id":7412952}]}]}
{"op":"mcm","clk":"1003434722","pt":1580607696710,"mc":[{"id":"1.168209731","rc":[{"batb":[[0,1.89,323.14],[1,1.88,88.64],[2,1.87,29.28]],"ltp":1.88,"tv":1851.07,"id":8174357}]}]}
{"op":"mcm","clk":"1003434787","pt":1580607697535,"mc":[{"id":"1.168209731","rc":[{"batb":[[0,1.9,23.11],[1,1.89,323.14],[2,1.88,88.64]],"ltp":1.88,"tv":1851.07,"id":8174357}]}]}
{"op":"mcm","clk":"1003435024","pt":1580607700621,"mc":[{"id":"1.168209731","rc":[{"batb":[[2,1.81,37.86]],"ltp":2.02,"tv":960.17,"id":7412952}]}]}
{"op":"mcm","clk":"1003435192","pt":1580607703140,"mc":[{"id":"1.168209731","rc":[{"batb":[[1,1.88,88.64],[2,1.86,420.1]],"ltp":1.88,"tv":1851.07,"id":8174357}]}]}
{"op":"mcm","clk":"1003435326","pt":1580607704939,"mc":[{"id":"1.168209731","rc":[{"batb":[[0,1.88,88.64],[1,1.86,420.1],[2,1.84,420.1]],"ltp":1.88,"tv":1851.07,"id":8174357}]}]}
{"op":"mcm","clk":"1003435333","pt":1580607705042,"mc":[{"id":"1.168209731","rc":[{"batb":[[0,1.89,7.67],[1,1.88,88.64],[2,1.86,420.1]],"ltp":1.88,"tv":1851.07,"id":8174357}]}]}
{"op":"mcm","clk":"1003436246","pt":1580607716725,"mc":[{"id":"1.168209731","rc":[{"batb":[[1,1.88,79.1]],"ltp":1.88,"tv":1851.07,"id":8174357}]}]}
{"op":"mcm","clk":"1003436271","pt":1580607717034,"mc":[{"id":"1.168209731","rc":[{"batb":[[0,1.89,340.25]],"ltp":1.88,"tv":1851.07,"id":8174357}]}]}
{"op":"mcm","clk":"1003437686","pt":1580607734854,"mc":[{"id":"1.168209731","rc":[{"batb":[[0,1.9,14.62],[1,1.89,340.25],[2,1.88,79.1]],"ltp":1.88,"tv":1851.07,"id":8174357}]}]}
{"op":"mcm","clk":"1003438836","pt":1580607748699,"mc":[{"id":"1.168209731","rc":[{"batb":[[1,1.89,7.67]],"ltp":1.88,"tv":1851.07,"id":8174357},{"batl":[[0,95,15.9],[1,990,2.2],[2,1000,0.02]],"ltp":2.02,"tv":960.17,"id":7412952}]}]}
{"op":"mcm","clk":"1003438894","pt":1580607749421,"mc":[{"id":"1.168209731","rc":[{"batb":[[0,1.9,9.33]],"ltp":1.88,"tv":1851.07,"id":8174357},{"batl":[[0,2.12,8.4],[1,95,15.9],[2,990,2.2]],"ltp":2.02,"tv":960.17,"id":7412952}]}]}
{"op":"mcm","clk":"1003441110","pt":1580607777945,"mc":[{"id":"1.168209731","rc":[{"batb":[[2,1.86,420.1]],"ltp":1.88,"tv":1851.07,"id":8174357}]}]}
{"op":"mcm","clk":"1003441120","pt":1580607778049,"mc":[{"id":"1.168209731","rc":[{"batb":[[0,1.91,48.86],[1,1.9,9.33],[2,1.89,7.67]],"ltp":1.88,"tv":1851.07,"id":8174357}]}]}
{"op":"mcm","clk":"1003441216","pt":1580607779444,"mc":[{"id":"1.168209731","rc":[{"batb":[[2,1.86,420.1]],"ltp":1.88,"tv":1851.07,"id":8174357}]}]}
{"op":"mcm","clk":"1003441313","pt":1580607780729,"mc":[{"id":"1.168209731","rc":[{"batl":[[0,95,15.9],[1,990,2.2],[2,1000,0.02]],"ltp":2.02,"tv":960.17,"id":7412952}]}]}
{"op":"mcm","clk":"1003441401","pt":1580607781863,"mc":[{"id":"1.168209731","rc":[{"batb":[[0,1.91,58.09],[1,1.86,420.1],[2,1.84,420.1]],"ltp":1.88,"tv":1851.07,"id":8174357},{"batl":[[0,2.1,8.4],[1,95,15.9],[2,990,2.2]],"ltp":2.02,"tv":960.17,"id":7412952}]}]}
{"op":"mcm","clk":"1003521994","pt":1580608945232,"mc":[{"id":"1.168209731","rc":[{"batb":[[2,1.81,88.6]],"ltp":2.02,"tv":960.17,"id":7412952}]}]}
{"op":"mcm","clk":"1003535101","pt":1580609158950,"mc":[{"id":"1.168209731","rc":[{"batb":[[0,1.92,10.29],[1,1.91,58.09],[2,1.86,420.1]],"batl":[[0,1.99,16.4]],"ltp":1.88,"tv":1851.07,"id":8174357},{"batb":[[1,2,10],[2,1.95,76.45]],"batl":[[0,2.08,8.29],[1,2.1,8.4],[2,95,15.9]],"ltp":2.02,"tv":960.17,"id":7412952}]}]}
{"op":"mcm","clk":"1003535130","pt":1580609159414,"mc":[{"id":"1.168209731","rc":[{"batb":[[1,1.91,65.69]],"ltp":1.88,"tv":1851.07,"id":8174357}]}]}
{"op":"mcm","clk":"1003536260","pt":1580609179237,"mc":[{"id":"1.168209731","rc":[{"batl":[[0,1.98,10.1],[1,1.99,16.4],[2,2,68.06]],"ltp":1.88,"tv":1851.07,"id":8174357},{"batb":[[0,2.02,25.65]],"ltp":2.02,"tv":960.17,"id":7412952}]}]}
{"op":"mcm","clk":"1003536708","pt":1580609186682,"mc":[{"id":"1.168209731","rc":[{"batl":[[1,1.99,8]],"ltp":1.88,"tv":1851.07,"id":8174357}]}]}
{"op":"mcm","clk":"1003536775","pt":1580609187873,"mc":[{"id":"1.168209731","rc":[{"batb":[[1,1.91,56.45]],"batl":[[0,1.99,8],[1,2,68.06],[2,3.2,2.64]],"ltp":1.88,"tv":1851.07,"id":8174357},{"batb":[[0,2.02,13.65]],"batl":[[1,95,15.9],[2,990,2.2]],"ltp":2.02,"tv":960.17,"id":7412952}]}]}
{"op":"mcm","clk":"1003536825","pt":1580609188685,"mc":[{"id":"1.168209731","rc":[{"batb":[[0,1.92,19.42],[1,1.91,48.86]],"batl":[[0,1.98,8.4],[1,1.99,8],[2,2,68.06]],"ltp":1.88,"tv":1851.07,"id":8174357},{"batl":[[0,2.08,16.69]],"ltp":2.02,"tv":960.17,"id":7412952}]}]}
{"op":"mcm","clk":"1003536919","pt":1580609190067,"mc":[{"id":"1.168209731","rc":[{"batb":[[0,1.92,26.98]],"ltp":1.88,"tv":1851.07,"id":8174357}]}]}
{"op":"mcm","clk":"1003540612","pt":1580609245333,"mc":[{"id":"1.168209731","rc":[{"batb":[[0,1.94,13.13],[1,1.93,29.63],[2,1.92,26.98]],"ltp":1.88,"tv":1851.07,"id":8174357}]}]}
{"op":"mcm","clk":"1003540705","pt":1580609246550,"mc":[{"id":"1.168209731","rc":[{"batb":[[2,1.92,19.42]],"ltp":1.88,"tv":1851.07,"id":8174357}]}]}
{"op":"mcm","clk":"1003541083","pt":1580609251814,"mc":[{"id":"1.168209731","rc":[{"batb":[[0,1.94,8.94],[1,1.93,42.63],[2,1.92,10.29]],"batl":[[0,1.98,18.4]],"ltp":1.88,"tv":1851.07,"id":8174357},{"batb":[[0,2.02,25.65]],"ltp":2.02,"tv":960.17,"id":7412952}]}]}
{"op":"mcm","clk":"1003541095","pt":1580609252021,"mc":[{"id":"1.168209731","rc":[{"batl":[[2,2,78.06]],"ltp":1.88,"tv":1851.07,"id":8174357}]}]}
{"op":"mcm","clk":"1003741633","pt":1580612185042,"mc":[{"id":"1.168209731","rc":[{"trd":[[1.94,5.22]],"batb":[[0,1.94,6.33],[2,1.92,12.92]],"ltp":1.94,"tv":1856.29,"id":8174357}],"tv":2816.47}]}
{"op":"mcm","clk":"1003799264","pt":1580613291778,"mc":[{"id":"1.168209731","rc":[{"batb":[[0,1.94,17.61]],"ltp":1.94,"tv":1856.29,"id":8174357},{"trd":[[2.02,97.48]],"batb":[[0,2.02,11.72]],"ltp":2.02,"tv":988.04,"id":7412952}],"tv":2844.33}]}
{"op":"mcm","clk":"1003799280","pt":1580613292093,"mc":[{"id":"1.168209731","rc":[{"batb":[[0,1.94,6.33],[1,1.93,29.63],[2,1.92,2.63]],"ltp":1.94,"tv":1856.29,"id":8174357}]}]}
{"op":"mcm","clk":"1003799678","pt":1580613301815,"mc":[{"id":"1.168209731","rc":[{"batb":[[0,1.94,17.33],[1,1.93,37.55]],"ltp":1.94,"tv":1856.29,"id":8174357},{"batb":[[2,1.94,78.03]],"ltp":2.02,"tv":988.04,"id":7412952}]}]}
{"op":"mcm","clk":"1003799690","pt":1580613302024,"mc":[{"id":"1.168209731","rc":[{"batb":[[0,1.94,6.33]],"ltp":1.94,"tv":1856.29,"id":8174357}]}]}
{"op":"mcm","clk":"1003800551","pt":1580613322259,"mc":[{"id":"1.168209731","rc":[{"batb":[[0,1.94,17.34]],"ltp":1.94,"tv":1856.29,"id":8174357}]}]}
{"op":"mcm","clk":"1003807428","pt":1580613501987,"mc":[{"id":"1.168209731","rc":[{"trd":[[2.02,117.74]],"batb":[[0,2.02,1.59]],"ltp":2.02,"tv":1008.3,"id":7412952}],"tv":2864.6}]}
{"op":"mcm","clk":"1003883372","pt":1580615167204,"mc":[{"id":"1.168209731","rc":[{"batl":[[1,990,2.2],[2,1000,0.02]],"ltp":2.02,"tv":1008.3,"id":7412952}]}]}
{"op":"mcm","clk":"1003889200","pt":1580615351756,"mc":[{"id":"1.168209731","rc":[{"batl":[[1,4,3.03],[2,990,2.2]],"ltp":2.02,"tv":1008.3,"id":7412952}]}]}
{"op":"mcm","clk":"1003889477","pt":1580615360164,"mc":[{"id":"1.168209731","rc":[{"batl":[[1,4,3.18]],"ltp":2.02,"tv":1008.3,"id":7412952}]}]}
{"op":"mcm","clk":"1003889886","pt":1580615372392,"mc":[{"id":"1.168209731","rc":[{"trd":[[2.02,118.04]],"batb":[[0,2.02,1.44]],"batl":[[1,990,2.2],[2,1000,0.02]],"ltp":2.02,"tv":1008.6,"id":7412952}],"tv":2864.9}]}
{"op":"mcm","clk":"1003890050","pt":1580615377363,"mc":[{"id":"1.168209731","rc":[{"batl":[[1,4,3.03],[2,990,2.2]],"ltp":2.02,"tv":1008.6,"id":7412952}]}]}
{"op":"mcm","clk":"1003890466","pt":1580615389719,"mc":[{"id":"1.168209731","rc":[{"batl":[[1,4,3.18]],"ltp":2.02,"tv":1008.6,"id":7412952}]}]}
{"op":"mcm","clk":"1003890827","pt":1580615401516,"mc":[{"id":"1.168209731","rc":[{"batl":[[1,990,2.35],[2,1000,0.02]],"ltp":2.02,"tv":1008.6,"id":7412952}]}]}
{"op":"mcm","clk":"1003922126","pt":1580616242513,"mc":[{"id":"1.168209731","rc":[{"batl":[[1,95,2.42],[2,990,2.2]],"ltp":2.02,"tv":1008.6,"id":7412952}]}]}
{"op":"mcm","clk":"1003923315","pt":1580616272748,"mc":[{"id":"1.168209731","rc":[{"batl":[[1,4.2,153.87],[2,95,2.27]],"ltp":2.02,"tv":1008.6,"id":7412952}]}]}
{"op":"mcm","clk":"1004004344","pt":1580618010703,"mc":[{"id":"1.168209731","rc":[{"batb":[[0,1.94,20.53]],"ltp":1.94,"tv":1856.29,"id":8174357}]}]}
{"op":"mcm","clk":"1004082130","pt":1580619854860,"mc":[{"id":"1.168209731","rc":[{"trd":[[1.93,37.43],[1.94,25.75]],"batb":[[0,1.93,10.08],[1,1.92,2.63],[2,1.87,89.8]],"batl":[[0,1.98,8.4]],"ltp":1.93,"tv":1914.25,"id":8174357},{"trd":[[2.08,87.27]],"batb":[[0,2.02,43.3],[2,1.81,330.47]],"batl":[[0,2.08,8.07],[1,2.16,10.96],[2,4.2,153.87]],"ltp":2.08,"tv":1095.87,"id":7412952}],"tv":3010.13}]}
{"op":"mcm","clk":"1004082147","pt":1580619855224,"mc":[{"id":"1.168209731","rc":[{"batl":[[1,2,68.06],[2,2.3,10.13]],"ltp":1.93,"tv":1914.25,"id":8174357},{"batb":[[0,2.02,55.3]],"ltp":2.08,"tv":1095.87,"id":7412952}]}]}
{"op":"mcm","clk":"1004082190","pt":1580619856354,"mc":[{"id":"1.168209731","rc":[{"batb":[[2,1.87,82.05]],"batl":[[0,1.97,10.08],[1,1.98,8.4],[2,2,68.06]],"ltp":1.93,"tv":1914.25,"id":8174357},{"batl":[[1,4.2,153.87],[2,95,2.27]],"ltp":2.08,"tv":1095.87,"id":7412952}]}]}
{"op":"mcm","clk":"1004082877","pt":1580619875781,"mc":[{"id":"1.168209731","rc":[{"batl":[[1,2,68.06],[2,2.3,10.13]],"ltp":1.93,"tv":1914.25,"id":8174357}]}]}
{"op":"mcm","clk":"1004082923","pt":1580619876760,"mc":[{"id":"1.168209731","rc":[{"batl":[[0,1.97,12.6],[1,1.98,10.19],[2,2,68.06]],"ltp":1.93,"tv":1914.25,"id":8174357},{"batb":[[0,2.04,12.19],[1,2.02,55.3],[2,2,10]],"ltp":2.08,"tv":1095.87,"id":7412952}]}]}
{"op":"mcm","clk":"1004082978","pt":1580619877850,"mc":[{"id":"1.168209731","rc":[{"batb":[[0,1.92,12.63],[1,1.87,82.05],[2,1.86,420.1]],"batl":[[0,1.96,3.16],[1,1.97,22.6],[2,1.98,10.19]],"ltp":1.93,"tv":1914.25,"id":8174357},{"batb":[[0,2.02,67.66],[1,2,10],[2,1.81,330.47]],"batl":[[0,2.08,8],[1,2.1,8.2],[2,4.2,153.87]],"ltp":2.08,"tv":1095.87,"id":7412952}]}]}
{"op":"mcm","clk":"1004082998","pt":1580619878363,"mc":[{"id":"1.168209731","rc":[{"batl":[[0,2.06,70.91],[1,2.08,8],[2,2.1,8.2]],"ltp":2.08,"tv":1095.87,"id":7412952}]}]}
{"op":"mcm","clk":"1004083062","pt":1580619879660,"mc":[{"id":"1.168209731","rc":[{"batb":[[0,1.93,17.72],[1,1.92,12.63],[2,1.87,59.79]],"ltp":1.93,"tv":1914.25,"id":8174357},{"batb":[[2,1.99,12.21]],"ltp":2.08,"tv":1095.87,"id":7412952}]}]}
{"op":"mcm","clk":"1004083083","pt":1580619880070,"mc":[{"id":"1.168209731","rc":[{"trd":[[2.06,33.59]],"batl":[[0,2.06,54.13]],"ltp":2.06,"tv":1129.46,"id":7412952}],"tv":3043.71}]}
{"op":"mcm","clk":"1004084194","pt":1580619908928,"mc":[{"id":"1.168209731","rc":[{"batl":[[0,1.96,13.8],[1,1.97,10]],"ltp":1.93,"tv":1914.25,"id":8174357},{"batb":[[0,2.02,55.3]],"ltp":2.06,"tv":1129.46,"id":7412952}]}]}
{"op":"mcm","clk":"1004084208","pt":1580619909294,"mc":[{"id":"1.168209731","rc":[{"batb":[[0,2.04,11],[1,2.02,55.3],[2,2,10]],"ltp":2.06,"tv":1129.46,"id":7412952}]}]}
{"op":"mcm","clk":"1004085938","pt":1580619955770,"mc":[{"id":"1.168209731","rc":[{"trd":[[2.06,56.28]],"batb":[[1,2.02,43.86]],"batl":[[0,2.06,42.78]],"ltp":2.06,"tv":1152.15,"id":7412952}],"tv":3066.41}]}
{"op":"mcm","clk":"1004085981","pt":1580619956754,"mc":[{"id":"1.168209731","rc":[{"batb":[[0,1.93,10.21],[2,1.9,41.4]],"batl":[[0,1.96,22.8]],"ltp":1.93,"tv":1914.25,"id":8174357}]}]}
{"op":"mcm","clk":"1004085989","pt":1580619956958,"mc":[{"id":"1.168209731","rc":[{"batl":[[0,1.96,13.8]],"ltp":1.93,"tv":1914.25,"id":8174357}]}]}
{"op":"mcm","clk":"1004086797","pt":1580619976779,"mc":[{"id":"1.168209731","rc":[{"trd":[[1.96,11.29]],"batl":[[0,1.96,2.5]],"ltp":1.96,"tv":1925.54,"id":8174357},{"trd":[[2.04,32.85]],"batb":[[0,2.02,43.86],[1,2,10],[2,1.99,12.21]],"ltp":2.04,"tv":1185.0,"id":7412952}],"tv":3110.54}]}
{"op":"mcm","clk":"1004086817","pt":1580619977187,"mc":[{"id":"1.168209731","rc":[{"batb":[[0,1.94,9],[1,1.93,10.21],[2,1.92,12.63]],"batl":[[2,1.98,7]],"ltp":1.96,"tv":1925.54,"id":8174357},{"batb":[[0,2.02,39.86],[2,1.99,8]],"ltp":2.04,"tv":1185.0,"id":7412952}]}]}
{"op":"mcm","clk":"1004086883","pt":1580619978894,"mc":[{"id":"1.168209731","rc":[{"batb":[[0,1.93,17.72],[1,1.92,12.63],[2,1.9,41.4]],"batl":[[0,1.96,9.6]],"ltp":1.96,"tv":1925.54,"id":8174357},{"batb":[[0,2.04,8.1],[1,2.02,39.86],[2,2,10]],"ltp":2.04,"tv":1185.0,"id":7412952}]}]}
{"op":"mcm","clk":"1004086926","pt":1580619979878,"mc":[{"id":"1.168209731","rc":[{"batb":[[0,1.94,9],[1,1.93,10.21],[2,1.92,12.63]],"batl":[[0,1.96,2.5]],"ltp":1.96,"tv":1925.54,"id":8174357},{"batb":[[0,2.02,39.86],[1,2,10],[2,1.99,8]],"batl":[[0,2.06,49.78]],"ltp":2.04,"tv":1185.0,"id":7412952}]}]}
{"op":"mcm","clk":"1004086944","pt":1580619980285,"mc":[{"id":"1.168209731","rc":[{"batl":[[0,2.06,42.78]],"ltp":2.04,"tv":1185.0,"id":7412952}]}]}
{"op":"mcm","clk":"1004087635","pt":1580619994824,"mc":[{"id":"1.168209731","rc":[{"batb":[[1,1.93,17.72]],"ltp":1.96,"tv":1925.54,"id":8174357}]}]}
{"op":"mcm","clk":"1004087653","pt":1580619995239,"mc":[{"id":"1.168209731","rc":[{"batb":[[0,2.04,8.19],[1,2.02,39.86],[2,2,10]],"ltp":2.04,"tv":1185.0,"id":7412952}]}]}
{"op":"mcm","clk":"1004087957","pt":1580620001813,"mc":[{"id":"1.168209731","rc":[{"batb":[[0,1.94,17.94]],"ltp":1.96,"tv":1925.54,"id":8174357},{"batb":[[0,2.02,39.86],[1,2,10],[2,1.99,8]],"ltp":2.04,"tv":1185.0,"id":7412952}]}]}
{"op":"mcm","clk":"1004088887","pt":1580620022761,"mc":[{"id":"1.168209731","rc":[{"batl":[[1,1.97,6]],"ltp":1.96,"tv":1925.54,"id":8174357}]}]}
{"op":"mcm","clk":"1004089749","pt":1580620043875,"mc":[{"id":"1.168209731","rc":[{"batb":[[0,2.04,8.01],[1,2.02,39.86],[2,2,10]],"ltp":2.04,"tv":1185.0,"id":7412952}]}]}
{"op":"mcm","clk":"1004089795","pt":1580620044907,"mc":[{"id":"1.168209731","rc":[{"batb":[[0,2.02,39.86],[1,2,10],[2,1.99,8]],"batl":[[0,2.06,49.78]],"ltp":2.04,"tv":1185.0,"id":7412952}]}]}
{"op":"mcm","clk":"1004089837","pt":1580620045890,"mc":[{"id":"1.168209731","rc":[{"batb":[[0,2.04,7.14],[1,2.02,39.86],[2,2,10]],"batl":[[0,2.06,42.78]],"ltp":2.04,"tv":1185.0,"id":7412952}]}]}
{"op":"mcm","clk":"1004089881","pt":1580620046873,"mc":[{"id":"1.168209731","rc":[{"batb":[[0,2.02,39.86],[1,2,10],[2,1.99,8]],"batl":[[0,2.06,49.78]],"ltp":2.04,"tv":1185.0,"id":7412952}]}]}
{"op":"mcm","clk":"1004089921","pt":1580620047909,"mc":[{"id":"1.168209731","rc":[{"batb":[[0,2.04,7.15],[1,2.02,39.86],[2,2,10]],"batl":[[0,2.06,42.78]],"ltp":2.04,"tv":1185.0,"id":7412952}]}]}
{"op":"mcm","clk":"1004089938","pt":1580620048275,"mc":[{"id":"1.168209731","rc":[{"batb":[[0,2.02,39.86],[1,2,10],[2,1.99,8]],"ltp":2.04,"tv":1185.0,"id":7412952}]}]}
{"op":"mcm","clk":"1004090806","pt":1580620069910,"mc":[{"id":"1.168209731","rc":[{"batl":[[0,2.06,48.78]],"ltp":2.04,"tv":1185.0,"id":7412952}]}]}
{"op":"mcm","clk":"1004090930","pt":1580620072905,"mc":[{"id":"1.168209731","rc":[{"batb":[[0,2.04,7.29],[1,2.02,39.86],[2,2,10]],"batl":[[0,2.06,42.78]],"ltp":2.04,"tv":1185.0,"id":7412952}]}]}
{"op":"mcm","clk":"1004090973","pt":1580620073834,"mc":[{"id":"1.168209731","rc":[{"batb":[[0,2.02,39.86],[1,2,10],[2,1.99,8]],"ltp":2.04,"tv":1185.0,"id":7412952}]}]}
{"op":"mcm","clk":"1004091708","pt":1580620094858,"mc":[{"id":"1.168209731","rc":[{"batl":[[0,1.96,8.79]],"ltp":1.96,"tv":1925.54,"id":8174357},{"batl":[[0,2.06,48.78]],"ltp":2.04,"tv":1185.0,"id":7412952}]}]}
{"op":"mcm","clk":"1004091758","pt":1580620095940,"mc":[{"id":"1.168209731","rc":[{"batl":[[0,1.96,2.5],[1,1.97,6.08],[2,1.98,6.08]],"ltp":1.96,"tv":1925.54,"id":8174357},{"batb":[[0,2.04,7.08],[1,2.02,39.86],[2,2,10]],"batl":[[0,2.06,42.78]],"ltp":2.04,"tv":1185.0,"id":7412952}]}]}
{"op":"mcm","clk":"1004091798","pt":1580620096862,"mc":[{"id":"1.168209731","rc":[{"batb":[[0,2.04,7.09]],"ltp":2.04,"tv":1185.0,"id":7412952}]}]}
{"op":"mcm","clk":"1004091839","pt":1580620097947,"mc":[{"id":"1.168209731","rc":[{"batl":[[0,2.06,48.78]],"ltp":2.04,"tv":1185.0,"id":7412952}]}]}
{"op":"mcm","clk":"1004091869","pt":1580620098769,"mc":[{"id":"1.168209731","rc":[{"batb":[[0,2.04,7.1]],"batl":[[0,2.06,42.78]],"ltp":2.04,"tv":1185.0,"id":7412952}]}]}
{"op":"mcm","clk":"1004091921","pt":1580620099853,"mc":[{"id":"1.168209731","rc":[{"batb":[[0,2.02,39.86],[1,2,10],[2,1.99,8]],"batl":[[0,2.06,48.78]],"ltp":2.04,"tv":1185.0,"id":7412952}]}]}
{"op":"mcm","clk":"1004091984","pt":1580620100944,"mc":[{"id":"1.168209731","rc":[{"batb":[[0,2.04,7.11],[1,2.02,39.86],[2,2,10]],"batl":[[0,2.06,42.78]],"ltp":2.04,"tv":1185.0,"id":7412952}]}]}
{"op":"mcm","clk":"1004092023","pt":1580620101767,"mc":[{"id":"1.168209731","rc":[{"batb":[[0,2.02,39.86],[1,2,10],[2,1.99,8]],"batl":[[0,2.06,48.78]],"ltp":2.04,"tv":1185.0,"id":7412952}]}]}
{"op":"mcm","clk":"1004092066","pt":1580620102952,"mc":[{"id":"1.168209731","rc":[{"batb":[[0,2.04,7.12],[1,2.02,39.86],[2,2,10]],"batl":[[0,2.06,42.78]],"ltp":2.04,"tv":1185.0,"id":7412952}]}]}
{"op":"mcm","clk":"1004092093","pt":1580620103779,"mc":[{"id":"1.168209731","rc":[{"batb":[[0,2.02,39.86],[1,2,10],[2,1.99,8]],"batl":[[0,2.06,48.78]],"ltp":2.04,"tv":1185.0,"id":7412952}]}]}
{"op":"mcm","clk":"1004092240","pt":1580620107950,"mc":[{"id":"1.168209731","rc":[{"batb":[[0,2.04,7.15],[1,2.02,39.86],[2,2,10]],"ltp":2.04,"tv":1185.0,"id":7412952}]}]}
{"op":"mcm","clk":"1004092262","pt":1580620108776,"mc":[{"id":"1.168209731","rc":[{"batb":[[0,2.02,39.86],[1,2,10],[2,1.99,8]],"ltp":2.04,"tv":1185.0,"id":7412952}]}]}
{"op":"mcm","clk":"1004092554","pt":1580620116879,"mc":[{"id":"1.168209731","rc":[{"batb":[[0,2.04,7.2],[1,2.02,39.86],[2,2,10]],"batl":[[0,2.06,42.78]],"ltp":2.04,"tv":1185.0,"id":7412952}]}]}
{"op":"mcm","clk":"1004092633","pt":1580620118885,"mc":[{"id":"1.168209731","rc":[{"batb":[[0,2.02,39.86],[1,2,10],[2,1.99,8]],"batl":[[0,2.06,48.78]],"ltp":2.04,"tv":1185.0,"id":7412952}]}]}
{"op":"mcm","clk":"1004092773","pt":1580620122801,"mc":[{"id":"1.168209731","rc":[{"batb":[[0,2.04,7.23],[1,2.02,39.86],[2,2,10]],"batl":[[0,2.06,42.78]],"ltp":2.04,"tv":1185.0,"id":7412952}]}]}
{"op":"mcm","clk":"1004092803","pt":1580620123886,"mc":[{"id":"1.168209731","rc":[{"batb":[[0,2.04,7.24]],"ltp":2.04,"tv":1185.0,"id":7412952}]}]}
{"op":"mcm","clk":"1004092842","pt":1580620124878,"mc":[{"id":"1.168209731","rc":[{"batb":[[0,2.02,39.86],[1,2,10],[2,1.99,8]],"batl":[[0,2.06,48.78]],"ltp":2.04,"tv":1185.0,"id":7412952}]}]}
{"op":"mcm","clk":"1004092871","pt":1580620125903,"mc":[{"id":"1.168209731","rc":[{"batb":[[1,1.93,14.51]],"ltp":1.96,"tv":1925.54,"id":8174357}]}]}
{"op":"mcm","clk":"1004092902","pt":1580620126879,"mc":[{"id":"1.168209731","rc":[{"batb":[[0,2.04,7.25],[1,2.02,39.86],[2,2,10]],"ltp":2.04,"tv":1185.0,"id":7412952}]}]}
{"op":"mcm","clk":"1004092932","pt":1580620127907,"mc":[{"id":"1.168209731","rc":[{"batl":[[0,1.96,15.02]],"ltp":1.96,"tv":1925.54,"id":8174357},{"batb":[[0,2.04,14.52]],"batl":[[0,2.06,42.78]],"ltp":2.04,"tv":1185.0,"id":7412952}]}]}
{"op":"mcm","clk":"1004092960","pt":1580620128780,"mc":[{"id":"1.168209731","rc":[{"batl":[[0,1.96,7.76],[1,1.97,5.26],[2,1.98,5.26]],"ltp":1.96,"tv":1925.54,"id":8174357},{"batb":[[0,2.04,6.26]],"ltp":2.04,"tv":1185.0,"id":7412952}]}]}
{"op":"mcm","clk":"1004092988","pt":1580620129909,"mc":[{"id":"1.168209731","rc":[{"batl":[[0,1.96,2.5]],"ltp":1.96,"tv":1925.54,"id":8174357},{"batb":[[0,2.02,39.86],[1,2,10],[2,1.99,8]],"batl":[[0,2.06,48.78]],"ltp":2.04,"tv":1185.0,"id":7412952}]}]}
{"op":"mcm","clk":"1004093042","pt":1580620131915,"mc":[{"id":"1.168209731","rc":[{"batl":[[0,1.96,7.78]],"ltp":1.96,"tv":1925.54,"id":8174357},{"batb":[[0,2.04,6.28],[1,2.02,39.86],[2,2,10]],"batl":[[0,2.06,42.78]],"ltp":2.04,"tv":1185.0,"id":7412952}]}]}
{"op":"mcm","clk":"1004093122","pt":1580620133924,"mc":[{"id":"1.168209731","rc":[{"batl":[[0,1.96,7.79]],"ltp":1.96,"tv":1925.54,"id":8174357},{"batb":[[0,2.04,6.29]],"batl":[[0,2.06,48.78]],"ltp":2.04,"tv":1185.0,"id":7412952}]}]}
{"op":"mcm","clk":"1004093151","pt":1580620134914,"mc":[{"id":"1.168209731","rc":[{"batl":[[0,1.96,7.8]],"ltp":1.96,"tv":1925.54,"id":8174357},{"batb":[[0,2.04,6.3]],"ltp":2.04,"tv":1185.0,"id":7412952}]}]}
{"op":"mcm","clk":"1004093166","pt":1580620135794,"mc":[{"id":"1.168209731","rc":[{"batl":[[0,1.96,13.1]],"ltp":1.96,"tv":1925.54,"id":8174357},{"batb":[[0,2.04,12.6]],"batl":[[0,2.06,42.78]],"ltp":2.04,"tv":1185.0,"id":7412952}]}]}
{"op":"mcm","clk":"1004093189","pt":1580620136821,"mc":[{"id":"1.168209731","rc":[{"batl":[[0,1.96,2.5]],"ltp":1.96,"tv":1925.54,"id":8174357},{"batb":[[0,2.02,39.86],[1,2,10],[2,1.99,8]],"batl":[[0,2.06,48.78]],"ltp":2.04,"tv":1185.0,"id":7412952}]}]}
{"op":"mcm","clk":"1004093227","pt":1580620137913,"mc":[{"id":"1.168209731","rc":[{"batl":[[0,1.96,7.81]],"ltp":1.96,"tv":1925.54,"id":8174357},{"batb":[[0,2.04,6.31],[1,2.02,39.86],[2,2,10]],"batl":[[0,2.06,42.78]],"ltp":2.04,"tv":1185.0,"id":7412952}]}]}
{"op":"mcm","clk":"1004093255","pt":1580620138836,"mc":[{"id":"1.168209731","rc":[{"batl":[[0,1.96,7.82]],"ltp":1.96,"tv":1925.54,"id":8174357},{"batb":[[0,2.04,6.32]],"ltp":2.04,"tv":1185.0,"id":7412952}]}]}
{"op":"mcm","clk":"1004093281","pt":1580620139917,"mc":[{"id":"1.168209731","rc":[{"batl":[[0,1.96,2.5]],"ltp":1.96,"tv":1925.54,"id":8174357},{"batb":[[0,2.02,39.86],[1,2,10],[2,1.99,8]],"batl":[[0,2.06,48.78]],"ltp":2.04,"tv":1185.0,"id":7412952}]}]}
{"op":"mcm","clk":"1004093335","pt":1580620141932,"mc":[{"id":"1.168209731","rc":[{"batb":[[0,2.04,6],[1,2.02,39.86],[2,2,10]],"ltp":2.04,"tv":1185.0,"id":7412952}]}]}
{"op":"mcm","clk":"1004093376","pt":1580620142913,"mc":[{"id":"1.168209731","rc":[{"batb":[[0,2.02,39.86],[1,2,10],[2,1.99,8]],"ltp":2.04,"tv":1185.0,"id":7412952}]}]}
{"op":"mcm","clk":"1004093451","pt":1580620144925,"mc":[{"id":"1.168209731","rc":[{"batl":[[0,1.96,7.52]],"ltp":1.96,"tv":1925.54,"id":8174357},{"batb":[[0,2.04,6.02],[1,2.02,39.86],[2,2,10]],"batl":[[0,2.06,42.78]],"ltp":2.04,"tv":1185.0,"id":7412952}]}]}
{"op":"mcm","clk":"1004093485","pt":1580620145805,"mc":[{"id":"1.168209731","rc":[{"batl":[[0,1.96,7.53]],"ltp":1.96,"tv":1925.54,"id":8174357},{"batb":[[0,2.04,6.03]],"ltp":2.04,"tv":1185.0,"id":7412952}]}]}
{"op":"mcm","clk":"1004093514","pt":1580620146938,"mc":[{"id":"1.168209731","rc":[{"batl":[[0,1.96,2.5]],"ltp":1.96,"tv":1925.54,"id":8174357},{"batb":[[0,2.02,39.86],[1,2,10],[2,1.99,8]],"batl":[[0,2.06,48.78]],"ltp":2.04,"tv":1185.0,"id":7412952}]}]}
{"op":"mcm","clk":"1004093634","pt":1580620150850,"mc":[{"id":"1.168209731","rc":[{"batl":[[0,1.96,7.55]],"ltp":1.96,"tv":1925.54,"id":8174357},{"batb":[[0,2.04,6.05],[1,2.02,39.86],[2,2,10]],"batl":[[0,2.06,42.78]],"ltp":2.04,"tv":1185.0,"id":7412952}]}]}
{"op":"mcm","clk":"1004093666","pt":1580620151831,"mc":[{"id":"1.168209731","rc":[{"batl":[[0,1.96,7.56]],"ltp":1.96,"tv":1925.54,"id":8174357},{"batb":[[0,2.04,6.06]],"ltp":2.04,"tv":1185.0,"id":7412952}]}]}
{"op":"mcm","clk":"1004093745","pt":1580620153909,"mc":[{"id":"1.168209731","rc":[{"batl":[[0,1.96,2.5]],"ltp":1.96,"tv":1925.54,"id":8174357},{"batb":[[0,2.02,39.86],[1,2,10],[2,1.99,8]],"batl":[[0,2.06,48.78]],"ltp":2.04,"tv":1185.0,"id":7412952}]}]}
{"op":"mcm","clk":"1004093854","pt":1580620156944,"mc":[{"id":"1.168209731","rc":[{"batl":[[0,1.96,7.59]],"ltp":1.96,"tv":1925.54,"id":8174357},{"batb":[[0,2.04,6.09],[1,2.02,39.86],[2,2,10]],"ltp":2.04,"tv":1185.0,"id":7412952}]}]}
{"op":"mcm","clk":"1004093899","pt":1580620157922,"mc":[{"id":"1.168209731","rc":[{"batl":[[0,1.96,2.5]],"ltp":1.96,"tv":1925.54,"id":8174357},{"batb":[[0,2.02,39.86],[1,2,10],[2,1.99,8]],"ltp":2.04,"tv":1185.0,"id":7412952}]}]}
{"op":"mcm","clk":"1004093966","pt":1580620159828,"mc":[{"id":"1.168209731","rc":[{"batb":[[2,1.81,330.47]],"ltp":2.04,"tv":1185.0,"id":7412952}]}]}
{"op":"mcm","clk":"1004094039","pt":1580620161829,"mc":[{"id":"1.168209731","rc":[{"batl":[[1,2,68.06],[2,2.3,10.13]],"ltp":1.96,"tv":1925.54,"id":8174357}]}]}
{"op":"mcm","clk":"1004094075","pt":1580620162916,"mc":[{"id":"1.168209731","rc":[{"batl":[[1,1.97,10.24],[2,2,68.06]],"ltp":1.96,"tv":1925.54,"id":8174357},{"batb":[[0,2.04,12.24],[1,2.02,39.86],[2,2,10]],"ltp":2.04,"tv":1185.0,"id":7412952}]}]}
{"op":"mcm","clk":"1004100515","pt":1580620347265,"mc":[{"id":"1.168209731","rc":[{"trd":[[1.94,26.14]],"batb":[[0,1.94,17.74]],"ltp":1.94,"tv":1925.94,"id":8174357}],"tv":3110.94}]}
{"op":"mcm","clk":"1004101280","pt":1580620374899,"mc":[{"id":"1.168209731","rc":[{"batb":[[0,1.94,20.93]],"batl":[[1,1.97,5]],"ltp":1.94,"tv":1925.94,"id":8174357},{"batb":[[0,2.02,39.86],[1,2,10],[2,1.81,330.47]],"ltp":2.04,"tv":1185.0,"id":7412952}]}]}
{"op":"mcm","clk":"1004101365","pt":1580620376956,"mc":[{"id":"1.168209731","rc":[{"batl":[[0,1.96,7.81]],"ltp":1.94,"tv":1925.94,"id":8174357},{"batb":[[0,2.04,6.31],[1,2.02,39.86],[2,2,10]],"batl":[[0,2.06,42.78]],"ltp":2.04,"tv":1185.0,"id":7412952}]}]}
{"op":"mcm","clk":"1004101433","pt":1580620378858,"mc":[{"id":"1.168209731","rc":[{"batl":[[0,1.96,7.82]],"ltp":1.94,"tv":1925.94,"id":8174357},{"batb":[[0,2.04,6.32]],"ltp":2.04,"tv":1185.0,"id":7412952}]}]}
{"op":"mcm","clk":"1004101516","pt":1580620380870,"mc":[{"id":"1.168209731","rc":[{"batl":[[0,1.96,7.5]],"ltp":1.94,"tv":1925.94,"id":8174357},{"batb":[[0,2.04,6]],"ltp":2.04,"tv":1185.0,"id":7412952}]}]}
{"op":"mcm","clk":"1004101557","pt":1580620381897,"mc":[{"id":"1.168209731","rc":[{"batl":[[0,2.06,48.78]],"ltp":2.04,"tv":1185.0,"id":7412952}]}]}
{"op":"mcm","clk":"1004101584","pt":1580620382878,"mc":[{"id":"1.168209731","rc":[{"batl":[[0,1.96,12.52]],"ltp":1.94,"tv":1925.94,"id":8174357},{"batb":[[0,2.04,6.01]],"batl":[[0,2.06,42.78]],"ltp":2.04,"tv":1185.0,"id":7412952}]}]}
{"op":"mcm","clk":"1004101623","pt":1580620383906,"mc":[{"id":"1.168209731","rc":[{"batb":[[0,2.04,12.02]],"ltp":2.04,"tv":1185.0,"id":7412952}]}]}
{"op":"mcm","clk":"1004101668","pt":1580620384888,"mc":[{"id":"1.168209731","rc":[{"batl":[[0,1.96,12.54],[1,1.97,5.02]],"ltp":1.94,"tv":1925.94,"id":8174357},{"batb":[[0,2.04,12.04]],"ltp":2.04,"tv":1185.0,"id":7412952}]}]}
{"op":"mcm","clk":"1004101699","pt":1580620385866,"mc":[{"id":"1.168209731","rc":[{"batl":[[0,1.96,7.53],[1,1.97,5]],"ltp":1.94,"tv":1925.94,"id":8174357},{"batb":[[0,2.04,6.03]],"batl":[[0,2.06,48.78]],"ltp":2.04,"tv":1185.0,"id":7412952}]}]}
{"op":"mcm","clk":"1004101733","pt":1580620386896,"mc":[{"id":"1.168209731","rc":[{"batl":[[0,2.06,42.78]],"ltp":2.04,"tv":1185.0,"id":7412952}]}]}
{"op":"mcm","clk":"1004101768","pt":1580620387770,"mc":[{"id":"1.168209731","rc":[{"batl":[[0,1.96,7.54]],"ltp":1.94,"tv":1925.94,"id":8174357},{"batb":[[0,2.04,6.04]],"ltp":2.04,"tv":1185.0,"id":7412952}]}]}
{"op":"mcm","clk":"1004101806","pt":1580620388800,"mc":[{"id":"1.168209731","rc":[{"batl":[[0,1.96,2.5]],"ltp":1.94,"tv":1925.94,"id":8174357},{"batb":[[0,2.02,39.86],[1,2,10],[2,1.81,330.47]],"batl":[[0,2.06,48.78]],"ltp":2.04,"tv":1185.0,"id":7412952}]}]}
{"op":"mcm","clk":"1004101931","pt":1580620391901,"mc":[{"id":"1.168209731","rc":[{"batl":[[0,1.96,7.56]],"ltp":1.94,"tv":1925.94,"id":8174357},{"batb":[[0,2.04,6.06],[1,2.02,39.86],[2,2,10]],"batl":[[0,2.06,42.78]],"ltp":2.04,"tv":1185.0,"id":7412952}]}]}
{"op":"mcm","clk":"1004102011","pt":1580620393804,"mc":[{"id":"1.168209731","rc":[{"batl":[[0,1.96,7.57]],"ltp":1.94,"tv":1925.94,"id":8174357},{"batb":[[0,2.04,6.07]],"ltp":2.04,"tv":1185.0,"id":7412952}]}]}
{"op":"mcm","clk":"1004102046","pt":1580620394881,"mc":[{"id":"1.168209731","rc":[{"batl":[[0,1.96,2.5]],"ltp":1.94,"tv":1925.94,"id":8174357},{"batb":[[0,2.02,39.86],[1,2,10],[2,1.81,330.47]],"batl":[[0,2.06,48.78]],"ltp":2.04,"tv":1185.0,"id":7412952}]}]}
{"op":"mcm","clk":"1004102175","pt":1580620397919,"mc":[{"id":"1.168209731","rc":[{"batl":[[0,1.96,7.59]],"ltp":1.94,"tv":1925.94,"id":8174357},{"batb":[[0,2.04,6.09],[1,2.02,39.86],[2,2,10]],"batl":[[0,2.06,42.78]],"ltp":2.04,"tv":1185.0,"id":7412952}]}]}
{"op":"mcm","clk":"1004102212","pt":1580620398793,"mc":[{"id":"1.168209731","rc":[{"batl":[[0,1.96,7.6]],"ltp":1.94,"tv":1925.94,"id":8174357},{"batb":[[0,2.04,6.1]],"ltp":2.04,"tv":1185.0,"id":7412952}]}]}
{"op":"mcm","clk":"1004102270","pt":1580620400904,"mc":[{"id":"1.168209731","rc":[{"batl":[[0,1.96,2.5]],"ltp":1.94,"tv":1925.94,"id":8174357},{"batb":[[0,2.02,39.86],[1,2,10],[2,1.81,330.47]],"batl":[[0,2.06,48.78]],"ltp":2.04,"tv":1185.0,"id":7412952}]}]}
{"op":"mcm","clk":"1004102341","pt":1580620402910,"mc":[{"id":"1.168209731","rc":[{"batl":[[0,1.96,7.62]],"ltp":1.94,"tv":1925.94,"id":8174357},{"batb":[[0,2.04,6.12],[1,2.02,39.86],[2,2,10]],"batl":[[0,2.06,42.78]],"ltp":2.04,"tv":1185.0,"id":7412952}]}]}
{"op":"mcm","clk":"1004102380","pt":1580620403902,"mc":[{"id":"1.168209731","rc":[{"batl":[[0,1.96,7.63]],"ltp":1.94,"tv":1925.94,"id":8174357},{"batb":[[0,2.04,6.13]],"batl":[[0,2.06,48.78]],"ltp":2.04,"tv":1185.0,"id":7412952}]}]}
{"op":"mcm","clk":"1004102445","pt":1580620405809,"mc":[{"id":"1.168209731","rc":[{"batl":[[0,1.96,2.5]],"ltp":1.94,"tv":1925.94,"id":8174357},{"batb":[[0,2.02,39.86],[1,2,10],[2,1.81,330.47]],"ltp":2.04,"tv":1185.0,"id":7412952}]}]}
{"op":"mcm","clk":"1004102480","pt":1580620406899,"mc":[{"id":"1.168209731","rc":[{"batl":[[0,1.96,7.64]],"ltp":1.94,"tv":1925.94,"id":8174357},{"batb":[[0,2.04,6.14],[1,2.02,39.86],[2,2,10]],"ltp":2.04,"tv":1185.0,"id":7412952}]}]}
{"op":"mcm","clk":"1004102515","pt":1580620407931,"mc":[{"id":"1.168209731","rc":[{"batl":[[0,1.96,7.65]],"ltp":1.94,"tv":1925.94,"id":8174357},{"batb":[[0,2.04,6.15]],"batl":[[0,2.06,42.78]],"ltp":2.04,"tv":1185.0,"id":7412952}]}]}
{"op":"mcm","clk":"1004102555","pt":1580620408910,"mc":[{"id":"1.168209731","rc":[{"batl":[[0,1.96,2.5]],"ltp":1.94,"tv":1925.94,"id":8174357},{"batb":[[0,2.02,39.86],[1,2,10],[2,1.81,330.47]],"batl":[[0,2.06,48.78]],"ltp":2.04,"tv":1185.0,"id":7412952}]}]}
{"op":"mcm","clk":"1004102616","pt":1580620410921,"mc":[{"id":"1.168209731","rc":[{"batl":[[0,1.96,7.66]],"ltp":1.94,"tv":1925.94,"id":8174357},{"batb":[[0,2.04,6.16],[1,2.02,39.86],[2,2,10]],"batl":[[0,2.06,42.78]],"ltp":2.04,"tv":1185.0,"id":7412952}]}]}
{"op":"mcm","clk":"1004102651","pt":1580620411800,"mc":[{"id":"1.168209731","rc":[{"batl":[[0,1.96,7.67]],"ltp":1.94,"tv":1925.94,"id":8174357},{"batb":[[0,2.04,6.17]],"ltp":2.04,"tv":1185.0,"id":7412952}]}]}
{"op":"mcm","clk":"1004102694","pt":1580620412830,"mc":[{"id":"1.168209731","rc":[{"batl":[[0,1.96,2.5]],"ltp":1.94,"tv":1925.94,"id":8174357},{"batb":[[0,2.02,39.86],[1,2,10],[2,1.81,330.47]],"batl":[[0,2.06,48.78]],"ltp":2.04,"tv":1185.0,"id":7412952}]}]}
{"op":"mcm","clk":"1004102730","pt":1580620413909,"mc":[{"id":"1.168209731","rc":[{"batl":[[0,1.96,7.68]],"ltp":1.94,"tv":1925.94,"id":8174357},{"batb":[[0,2.04,6.18],[1,2.02,39.86],[2,2,10]],"batl":[[0,2.06,42.78]],"ltp":2.04,"tv":1185.0,"id":7412952}]}]}
{"op":"mcm","clk":"1004102767","pt":1580620414938,"mc":[{"id":"1.168209731","rc":[{"batl":[[0,1.96,7.69]],"ltp":1.94,"tv":1925.94,"id":8174357},{"batb":[[0,2.04,6.19]],"batl":[[0,2.06,48.78]],"ltp":2.04,"tv":1185.0,"id":7412952}]}]}
{"op":"mcm","clk":"1004102803","pt":1580620415918,"mc":[{"id":"1.168209731","rc":[{"batl":[[0,1.96,2.5]],"ltp":1.94,"tv":1925.94,"id":8174357},{"batb":[[0,2.02,39.86],[1,2,10],[2,1.81,330.47]],"ltp":2.04,"tv":1185.0,"id":7412952}]}]}
{"op":"mcm","clk":"1004102870","pt":1580620417938,"mc":[{"id":"1.168209731","rc":[{"batl":[[0,1.96,7.7]],"ltp":1.94,"tv":1925.94,"id":8174357},{"batb":[[0,2.04,6.2],[1,2.02,39.86],[2,2,10]],"batl":[[0,2.06,42.78]],"ltp":2.04,"tv":1185.0,"id":7412952}]}]}
{"op":"mcm","clk":"1004102904","pt":1580620418816,"mc":[{"id":"1.168209731","rc":[{"batl":[[0,1.96,7.71]],"ltp":1.94,"tv":1925.94,"id":8174357},{"batb":[[0,2.04,6.21]],"ltp":2.04,"tv":1185.0,"id":7412952}]}]}
{"op":"mcm","clk":"1004102942","pt":1580620419951,"mc":[{"id":"1.168209731","rc":[{"batl":[[0,1.96,2.5]],"ltp":1.94,"tv":1925.94,"id":8174357},{"batb":[[0,2.02,39.86],[1,2,10],[2,1.81,330.47]],"batl":[[0,2.06,48.78]],"ltp":2.04,"tv":1185.0,"id":7412952}]}]}
{"op":"mcm","clk":"1004103097","pt":1580620424830,"mc":[{"id":"1.168209731","rc":[{"batl":[[0,1.96,7.74]],"ltp":1.94,"tv":1925.94,"id":8174357},{"batb":[[0,2.04,6.24],[1,2.02,39.86],[2,2,10]],"batl":[[0,2.06,42.78]],"ltp":2.04,"tv":1185.0,"id":7412952}]}]}
{"op":"mcm","clk":"1004103135","pt":1580620425756,"mc":[{"id":"1.168209731","rc":[{"batl":[[0,1.96,7.75]],"ltp":1.94,"tv":1925.94,"id":8174357},{"batb":[[0,2.04,6.25]],"ltp":2.04,"tv":1185.0,"id":7412952}]}]}
{"op":"mcm","clk":"1004103165","pt":1580620426836,"mc":[{"id":"1.168209731","rc":[{"batl":[[0,1.96,2.5]],"ltp":1.94,"tv":1925.94,"id":8174357},{"batb":[[0,2.02,39.86],[1,2,10],[2,1.81,330.47]],"batl":[[0,2.06,48.78]],"ltp":2.04,"tv":1185.0,"id":7412952}]}]}
{"op":"mcm","clk":"1004103311","pt":1580620429924,"mc":[{"id":"1.168209731","rc":[{"batl":[[0,1.96,7.77]],"ltp":1.94,"tv":1925.94,"id":8174357},{"batb":[[0,2.04,6.27],[1,2.02,39.86],[2,2,10]],"ltp":2.04,"tv":1185.0,"id":7412952}]}]}
{"op":"mcm","clk":"1004103375","pt":1580620431872,"mc":[{"id":"1.168209731","rc":[{"batl":[[0,1.96,2.5]],"ltp":1.94,"tv":1925.94,"id":8174357},{"batb":[[0,2.02,39.86],[1,2,10],[2,1.81,330.47]],"ltp":2.04,"tv":1185.0,"id":7412952}]}]}
{"op":"mcm","clk":"1004103471","pt":1580620434757,"mc":[{"id":"1.168209731","rc":[{"batl":[[0,1.96,7.79]],"ltp":1.94,"tv":1925.94,"id":8174357},{"batb":[[0,2.04,6.29],[1,2.02,39.86],[2,2,10]],"batl":[[0,2.06,42.78]],"ltp":2.04,"tv":1185.0,"id":7412952}]}]}
{"op":"mcm","clk":"1004103516","pt":1580620435939,"mc":[{"id":"1.168209731","rc":[{"batl":[[0,1.96,2.5]],"ltp":1.94,"tv":1925.94,"id":8174357},{"batb":[[0,2.02,39.86],[1,2,10],[2,1.81,330.47]],"batl":[[0,2.06,48.78]],"ltp":2.04,"tv":1185.0,"id":7412952}]}]}
{"op":"mcm","clk":"1004103801","pt":1580620443951,"mc":[{"id":"1.168209731","rc":[{"batl":[[0,1.96,7.52]],"ltp":1.94,"tv":1925.94,"id":8174357},{"batb":[[0,2.04,6.02],[1,2.02,39.86],[2,2,10]],"batl":[[0,2.06,42.78]],"ltp":2.04,"tv":1185.0,"id":7412952}]}]}
{"op":"mcm","clk":"1004103848","pt":1580620445755,"mc":[{"id":"1.168209731","rc":[{"batl":[[0,1.96,2.5]],"ltp":1.94,"tv":1925.94,"id":8174357},{"batb":[[0,2.02,39.86],[1,2,10],[2,1.81,330.47]],"batl":[[0,2.06,48.78]],"ltp":2.04,"tv":1185.0,"id":7412952}]}]}
{"op":"mcm","clk":"1004103883","pt":1580620446888,"mc":[{"id":"1.168209731","rc":[{"batl":[[0,1.96,7.53]],"ltp":1.94,"tv":1925.94,"id":8174357},{"batb":[[0,2.04,6.03],[1,2.02,39.86],[2,2,10]],"batl":[[0,2.06,42.78]],"ltp":2.04,"tv":1185.0,"id":7412952}]}]}
{"op":"mcm","clk":"1004103914","pt":1580620447866,"mc":[{"id":"1.168209731","rc":[{"batl":[[0,1.96,7.54]],"ltp":1.94,"tv":1925.94,"id":8174357},{"batb":[[0,2.04,6.04]],"batl":[[0,2.06,48.78]],"ltp":2.04,"tv":1185.0,"id":7412952}]}]}
{"op":"mcm","clk":"1004103947","pt":1580620448788,"mc":[{"id":"1.168209731","rc":[{"batl":[[0,2.06,42.78]],"ltp":2.04,"tv":1185.0,"id":7412952}]}]}
{"op":"mcm","clk":"1004103979","pt":1580620449775,"mc":[{"id":"1.168209731","rc":[{"batl":[[0,1.96,7.55]],"ltp":1.94,"tv":1925.94,"id":8174357},{"batb":[[0,2.04,6.05]],"ltp":2.04,"tv":1185.0,"id":7412952}]}]}
{"op":"mcm","clk":"1004104027","pt":1580620450868,"mc":[{"id":"1.168209731","rc":[{"batl":[[0,1.96,2.5]],"ltp":1.94,"tv":1925.94,"id":8174357},{"batb":[[0,2.02,39.86],[1,2,10],[2,1.81,330.47]],"batl":[[0,2.06,48.78]],"ltp":2.04,"tv":1185.0,"id":7412952}]}]}
{"op":"mcm","clk":"1004104164","pt":1580620453954,"mc":[{"id":"1.168209731","rc":[{"batl":[[0,1.96,7.57]],"ltp":1.94,"tv":1925.94,"id":8174357},{"batb":[[0,2.04,6.07],[1,2.02,39.86],[2,2,10]],"batl":[[0,2.06,42.78]],"ltp":2.04,"tv":1185.0,"id":7412952}]}]}
{"op":"mcm","clk":"1004104200","pt":1580620454883,"mc":[{"id":"1.168209731","rc":[{"batl":[[0,1.96,7.58]],"ltp":1.94,"tv":1925.94,"id":8174357},{"batb":[[0,2.04,6.08]],"ltp":2.04,"tv":1185.0,"id":7412952}]}]}
{"op":"mcm","clk":"1004104267","pt":1580620456905,"mc":[{"id":"1.168209731","rc":[{"batl":[[0,1.96,7.59]],"ltp":1.94,"tv":1925.94,"id":8174357},{"batb":[[0,2.04,6.09]],"ltp":2.04,"tv":1185.0,"id":7412952}]}]}
{"op":"mcm","clk":"1004104294","pt":1580620457882,"mc":[{"id":"1.168209731","rc":[{"batl":[[0,2.06,48.78]],"ltp":2.04,"tv":1185.0,"id":7412952}]}]}
{"op":"mcm","clk":"1004104335","pt":1580620458803,"mc":[{"id":"1.168209731","rc":[{"batl":[[0,1.96,7.6]],"ltp":1.94,"tv":1925.94,"id":8174357},{"batb":[[0,2.04,6.1]],"batl":[[0,2.06,42.78]],"ltp":2.04,"tv":1185.0,"id":7412952}]}]}
{"op":"mcm","clk":"1004104414","pt":1580620460867,"mc":[{"id":"1.168209731","rc":[{"batl":[[0,1.96,7.61]],"ltp":1.94,"tv":1925.94,"id":8174357},{"batb":[[0,2.04,6.11]],"ltp":2.04,"tv":1185.0,"id":7412952}]}]}
{"op":"mcm","clk":"1004104440","pt":1580620461792,"mc":[{"id":"1.168209731","rc":[{"batl":[[0,2.06,48.78]],"ltp":2.04,"tv":1185.0,"id":7412952}]}]}
{"op":"mcm","clk":"1004104470","pt":1580620462872,"mc":[{"id":"1.168209731","rc":[{"batl":[[0,1.96,7.62]],"ltp":1.94,"tv":1925.94,"id":8174357},{"batb":[[0,2.04,6.12]],"batl":[[0,2.06,42.78]],"ltp":2.04,"tv":1185.0,"id":7412952}]}]}
{"op":"mcm","clk":"1004104504","pt":1580620463900,"mc":[{"id":"1.168209731","rc":[{"batl":[[0,1.96,7.63]],"ltp":1.94,"tv":1925.94,"id":8174357},{"batb":[[0,2.04,6.13]],"batl":[[0,2.06,48.78]],"ltp":2.04,"tv":1185.0,"id":7412952}]}]}
{"op":"mcm","clk":"1004104581","pt":1580620465803,"mc":[{"id":"1.168209731","rc":[{"batl":[[0,1.96,2.5]],"ltp":1.94,"tv":1925.94,"id":8174357},{"batb":[[0,2.02,39.86],[1,2,10],[2,1.81,330.47]],"ltp":2.04,"tv":1185.0,"id":7412952}]}]}
{"op":"mcm","clk":"1004104648","pt":1580620467908,"mc":[{"id":"1.168209731","rc":[{"batl":[[0,1.96,7.65]],"ltp":1.94,"tv":1925.94,"id":8174357},{"batb":[[0,2.04,6.15],[1,2.02,39.86],[2,2,10]],"ltp":2.04,"tv":1185.0,"id":7412952}]}]}
{"op":"mcm","clk":"1004104687","pt":1580620468886,"mc":[{"id":"1.168209731","rc":[{"batl":[[0,2.06,42.78]],"ltp":2.04,"tv":1185.0,"id":7412952}]}]}
{"op":"mcm","clk":"1004104714","pt":1580620469813,"mc":[{"id":"1.168209731","rc":[{"batl":[[0,1.96,7.66]],"ltp":1.94,"tv":1925.94,"id":8174357},{"batb":[[0,2.04,6.16]],"ltp":2.04,"tv":1185.0,"id":7412952}]}]}
{"op":"mcm","clk":"1004104780","pt":1580620471824,"mc":[{"id":"1.168209731","rc":[{"batl":[[0,1.96,2.5]],"ltp":1.94,"tv":1925.94,"id":8174357},{"batb":[[0,2.02,39.86],[1,2,10],[2,1.81,330.47]],"batl":[[0,2.06,48.78]],"ltp":2.04,"tv":1185.0,"id":7412952}]}]}
{"op":"mcm","clk":"1004104955","pt":1580620476923,"mc":[{"id":"1.168209731","rc":[{"batl":[[0,1.96,7.7]],"ltp":1.94,"tv":1925.94,"id":8174357},{"batb":[[0,2.04,6.2],[1,2.02,39.86],[2,2,10]],"batl":[[0,2.06,42.78]],"ltp":2.04,"tv":1185.0,"id":7412952}]}]}
{"op":"mcm","clk":"1004104998","pt":1580620477902,"mc":[{"id":"1.168209731","rc":[{"batl":[[0,1.96,2.5]],"ltp":1.94,"tv":1925.94,"id":8174357},{"batb":[[0,2.02,39.86],[1,2,10],[2,1.81,330.47]],"batl":[[0,2.06,48.78]],"ltp":2.04,"tv":1185.0,"id":7412952}]}]}
{"op":"mcm","clk":"1004105076","pt":1580620479910,"mc":[{"id":"1.168209731","rc":[{"batl":[[0,1.96,7.71]],"ltp":1.94,"tv":1925.94,"id":8174357},{"batb":[[0,2.04,6.21],[1,2.02,39.86],[2,2,10]],"ltp":2.04,"tv":1185.0,"id":7412952}]}]}
{"op":"mcm","clk":"1004105113","pt":1580620480894,"mc":[{"id":"1.168209731","rc":[{"batl":[[0,1.96,7.72]],"ltp":1.94,"tv":1925.94,"id":8174357},{"batb":[[0,2.04,6.22]],"ltp":2.04,"tv":1185.0,"id":7412952}]}]}
{"op":"mcm","clk":"1004105157","pt":1580620481820,"mc":[{"id":"1.168209731","rc":[{"batl":[[0,2.06,42.78]],"ltp":2.04,"tv":1185.0,"id":7412952}]}]}
{"op":"mcm","clk":"1004105202","pt":1580620482798,"mc":[{"id":"1.168209731","rc":[{"batl":[[0,1.96,7.73]],"ltp":1.94,"tv":1925.94,"id":8174357},{"batb":[[0,2.04,6.23]],"ltp":2.04,"tv":1185.0,"id":7412952}]}]}
{"op":"mcm","clk":"1004105245","pt":1580620483931,"mc":[{"id":"1.168209731","rc":[{"batl":[[0,1.96,2.5]],"ltp":1.94,"tv":1925.94,"id":8174357},{"batb":[[0,2.02,39.86],[1,2,10],[2,1.81,330.47]],"batl":[[0,2.06,48.78]],"ltp":2.04,"tv":1185.0,"id":7412952}]}]}
{"op":"mcm","clk":"1004105308","pt":1580620485836,"mc":[{"id":"1.168209731","rc":[{"batl":[[0,1.96,7.75]],"ltp":1.94,"tv":1925.94,"id":8174357},{"batb":[[0,2.04,6.25],[1,2.02,39.86],[2,2,10]],"batl":[[0,2.06,42.78]],"ltp":2.04,"tv":1185.0,"id":7412952}]}]}
{"op":"mcm","clk":"1004105350","pt":1580620486923,"mc":[{"id":"1.168209731","rc":[{"batl":[[0,1.96,2.5]],"ltp":1.94,"tv":1925.94,"id":8174357},{"batb":[[0,2.02,39.86],[1,2,10],[2,1.81,330.47]],"batl":[[0,2.06,48.78]],"ltp":2.04,"tv":1185.0,"id":7412952}]}]}
{"op":"mcm","clk":"1004105415","pt":1580620488936,"mc":[{"id":"1.168209731","rc":[{"batl":[[0,1.96,7.76]],"ltp":1.94,"tv":1925.94,"id":8174357},{"batb":[[0,2.04,6.26],[1,2.02,39.86],[2,2,10]],"batl":[[0,2.06,42.78]],"ltp":2.04,"tv":1185.0,"id":7412952}]}]}
{"op":"mcm","clk":"1004105451","pt":1580620489808,"mc":[{"id":"1.168209731","rc":[{"batl":[[0,1.96,7.77]],"ltp":1.94,"tv":1925.94,"id":8174357},{"batb":[[0,2.04,6.27]],"ltp":2.04,"tv":1185.0,"id":7412952}]}]}
{"op":"mcm","clk":"1004105536","pt":1580620491941,"mc":[{"id":"1.168209731","rc":[{"batl":[[0,1.96,2.5]],"ltp":1.94,"tv":1925.94,"id":8174357},{"batb":[[0,2.02,39.86],[1,2,10],[2,1.81,330.47]],"batl":[[0,2.06,48.78]],"ltp":2.04,"tv":1185.0,"id":7412952}]}]}
{"op":"mcm","clk":"1004105699","pt":1580620495957,"mc":[{"id":"1.168209731","rc":[{"batl":[[0,1.96,7.8]],"ltp":1.94,"tv":1925.94,"id":8174357},{"batb":[[0,2.04,6.3],[1,2.02,39.86],[2,2,10]],"batl":[[0,2.06,42.78]],"ltp":2.04,"tv":1185.0,"id":7412952}]}]}
{"op":"mcm","clk":"1004105757","pt":1580620496937,"mc":[{"id":"1.168209731","rc":[{"batl":[[0,1.96,2.5]],"ltp":1.94,"tv":1925.94,"id":8174357},{"batb":[[0,2.02,39.86],[1,2,10],[2,1.81,330.47]],"batl":[[0,2.06,48.78]],"ltp":2.04,"tv":1185.0,"id":7412952}]}]}
{"op":"mcm","clk":"1004105847","pt":1580620498943,"mc":[{"id":"1.168209731","rc":[{"batl":[[0,1.96,7.82]],"ltp":1.94,"tv":1925.94,"id":8174357},{"batb":[[0,2.04,6.32],[1,2.02,39.86],[2,2,10]],"batl":[[0,2.06,42.78]],"ltp":2.04,"tv":1185.0,"id":7412952}]}]}
{"op":"mcm","clk":"1004105921","pt":1580620500851,"mc":[{"id":"1.168209731","rc":[{"batl":[[0,1.96,2.5]],"ltp":1.94,"tv":1925.94,"id":8174357},{"batb":[[0,2.02,39.86],[1,2,10],[2,1.81,330.47]],"batl":[[0,2.06,48.78]],"ltp":2.04,"tv":1185.0,"id":7412952}]}]}
{"op":"mcm","clk":"1004105966","pt":1580620501939,"mc":[{"id":"1.168209731","rc":[{"batl":[[0,1.96,7.5]],"ltp":1.94,"tv":1925.94,"id":8174357},{"batb":[[0,2.04,6],[1,2.02,39.86],[2,2,10]],"batl":[[0,2.06,42.78]],"ltp":2.04,"tv":1185.0,"id":7412952}]}]}
{"op":"mcm","clk":"1004106016","pt":1580620502761,"mc":[{"id":"1.168209731","rc":[{"batl":[[0,1.96,7.51]],"ltp":1.94,"tv":1925.94,"id":8174357},{"batb":[[0,2.04,6.01]],"ltp":2.04,"tv":1185.0,"id":7412952}]}]}
{"op":"mcm","clk":"1004106070","pt":1580620503951,"mc":[{"id":"1.168209731","rc":[{"batl":[[0,1.96,2.5]],"ltp":1.94,"tv":1925.94,"id":8174357},{"batb":[[0,2.02,39.86],[1,2,10],[2,1.81,330.47]],"batl":[[0,2.06,48.78]],"ltp":2.04,"tv":1185.0,"id":7412952}]}]}
{"op":"mcm","clk":"1004106165","pt":1580620505857,"mc":[{"id":"1.168209731","rc":[{"batl":[[0,1.96,7.53]],"ltp":1.94,"tv":1925.94,"id":8174357},{"batb":[[0,2.04,6.03],[1,2.02,39.86],[2,2,10]],"batl":[[0,2.06,42.78]],"ltp":2.04,"tv":1185.0,"id":7412952}]}]}
{"op":"mcm","clk":"1004106220","pt":1580620506945,"mc":[{"id":"1.168209731","rc":[{"batl":[[0,1.96,2.5]],"ltp":1.94,"tv":1925.94,"id":8174357},{"batb":[[0,2.02,39.86],[1,2,10],[2,1.81,330.47]],"ltp":2.04,"tv":1185.0,"id":7412952}]}]}
{"op":"mcm","clk":"1004106269","pt":1580620507767,"mc":[{"id":"1.168209731","rc":[{"batl":[[0,2.06,48.78]],"ltp":2.04,"tv":1185.0,"id":7412952}]}]}
{"op":"mcm","clk":"1004106335","pt":1580620508853,"mc":[{"id":"1.168209731","rc":[{"batl":[[0,1.96,7.54]],"ltp":1.94,"tv":1925.94,"id":8174357},{"batb":[[0,2.04,6.04],[1,2.02,39.86],[2,2,10]],"batl":[[0,2.06,42.78]],"ltp":2.04,"tv":1185.0,"id":7412952}]}]}
{"op":"mcm","clk":"1004106388","pt":1580620509876,"mc":[{"id":"1.168209731","rc":[{"batl":[[0,1.96,2.5]],"ltp":1.94,"tv":1925.94,"id":8174357},{"batb":[[0,2.02,39.86],[1,2,10],[2,1.81,330.47]],"batl":[[0,2.06,48.78]],"ltp":2.04,"tv":1185.0,"id":7412952}]}]}
{"op":"mcm","clk":"1004106501","pt":1580620511939,"mc":[{"id":"1.168209731","rc":[{"batl":[[0,1.96,7.56]],"ltp":1.94,"tv":1925.94,"id":8174357},{"batb":[[0,2.04,6.06],[1,2.02,39.86],[2,2,10]],"batl":[[0,2.06,42.78]],"ltp":2.04,"tv":1185.0,"id":7412952}]}]}
{"op":"mcm","clk":"1004106602","pt":1580620513941,"mc":[{"id":"1.168209731","rc":[{"batl":[[0,1.96,2.5]],"ltp":1.94,"tv":1925.94,"id":8174357},{"batb":[[0,2.02,39.86],[1,2,10],[2,1.81,330.47]],"batl":[[0,2.06,48.78]],"ltp":2.04,"tv":1185.0,"id":7412952}]}]}
{"op":"mcm","clk":"1004106717","pt":1580620515947,"mc":[{"id":"1.168209731","rc":[{"batl":[[0,1.96,7.58]],"ltp":1.94,"tv":1925.94,"id":8174357},{"batb":[[0,2.04,6.08],[1,2.02,39.86],[2,2,10]],"batl":[[0,2.06,42.78]],"ltp":2.04,"tv":1185.0,"id":7412952}]}]}
{"op":"mcm","clk":"1004106759","pt":1580620516766,"mc":[{"id":"1.168209731","rc":[{"batl":[[0,1.96,7.59]],"ltp":1.94,"tv":1925.94,"id":8174357},{"batb":[[0,2.04,6.09]],"ltp":2.04,"tv":1185.0,"id":7412952}]}]}
{"op":"mcm","clk":"1004106814","pt":1580620517843,"mc":[{"id":"1.168209731","rc":[{"batl":[[0,1.96,2.5]],"ltp":1.94,"tv":1925.94,"id":8174357},{"batb":[[0,2.02,39.86],[1,2,10],[2,1.81,330.47]],"batl":[[0,2.06,48.78]],"ltp":2.04,"tv":1185.0,"id":7412952}]}]}
{"op":"mcm","clk":"1004106858","pt":1580620518766,"mc":[{"id":"1.168209731","rc":[{"batl":[[0,1.96,7.5],[1,2,68.06],[2,2.3,10.13]],"ltp":1.94,"tv":1925.94,"id":8174357},{"batb":[[0,2.04,6],[1,2.02,39.86],[2,2,10]],"batl":[[0,2.06,42.78]],"ltp":2.04,"tv":1185.0,"id":7412952}]}]}
{"op":"mcm","clk":"1004106918","pt":1580620519949,"mc":[{"id":"1.168209731","rc":[{"batl":[[0,1.96,7.6],[1,1.97,5],[2,2,68.06]],"ltp":1.94,"tv":1925.94,"id":8174357},{"batb":[[0,2.04,6.1]],"batl":[[0,2.06,54.78]],"ltp":2.04,"tv":1185.0,"id":7412952}]}]}
{"op":"mcm","clk":"1004106956","pt":1580620520775,"mc":[{"id":"1.168209731","rc":[{"batl":[[0,1.96,2.5]],"ltp":1.94,"tv":1925.94,"id":8174357},{"batb":[[0,2.02,39.86],[1,2,10],[2,1.81,330.47]],"batl":[[0,2.06,48.78]],"ltp":2.04,"tv":1185.0,"id":7412952}]}]}
{"op":"mcm","clk":"1004107113","pt":1580620523880,"mc":[{"id":"1.168209731","rc":[{"batl":[[0,1.96,7.62]],"ltp":1.94,"tv":1925.94,"id":8174357},{"batb":[[0,2.04,6.12],[1,2.02,39.86],[2,2,10]],"ltp":2.04,"tv":1185.0,"id":7412952}]}]}
{"op":"mcm","clk":"1004107161","pt":1580620524764,"mc":[{"id":"1.168209731","rc":[{"batl":[[0,1.96,7.63]],"ltp":1.94,"tv":1925.94,"id":8174357},{"batb":[[0,2.04,6.13]],"batl":[[0,2.06,42.78]],"ltp":2.04,"tv":1185.0,"id":7412952}]}]}
{"op":"mcm","clk":"1004107202","pt":1580620525588,"mc":[{"id":"1.168209731","rc":[{"batl":[[0,1.96,2.5]],"ltp":1.94,"tv":1925.94,"id":8174357},{"batb":[[0,2.02,39.86],[1,2,10],[2,1.81,330.47]],"batl":[[0,2.06,48.78]],"ltp":2.04,"tv":1185.0,"id":7412952}]}]}
{"op":"mcm","clk":"1004107286","pt":1580620526785,"mc":[{"id":"1.168209731","rc":[{"batl":[[0,1.96,7.64]],"ltp":1.94,"tv":1925.94,"id":8174357},{"batb":[[0,2.04,6.14],[1,2.02,39.86],[2,2,10]],"batl":[[0,2.06,42.78]],"ltp":2.04,"tv":1185.0,"id":7412952}]}]}
{"op":"mcm","clk":"1004107341","pt":1580620527768,"mc":[{"id":"1.168209731","rc":[{"batl":[[0,1.96,7.65]],"ltp":1.94,"tv":1925.94,"id":8174357},{"batb":[[0,2.04,6.15]],"ltp":2.04,"tv":1185.0,"id":7412952}]}]}
{"op":"mcm","clk":"1004107387","pt":1580620528900,"mc":[{"id":"1.168209731","rc":[{"batl":[[0,2.06,48.78]],"ltp":2.04,"tv":1185.0,"id":7412952}]}]}
{"op":"mcm","clk":"1004107437","pt":1580620529778,"mc":[{"id":"1.168209731","rc":[{"batl":[[0,1.96,2.5]],"ltp":1.94,"tv":1925.94,"id":8174357},{"batb":[[0,2.02,39.86],[1,2,10],[2,1.81,330.47]],"batl":[[0,2.06,42.78]],"ltp":2.04,"tv":1185.0,"id":7412952}]}]}
{"op":"mcm","clk":"1004107483","pt":1580620530857,"mc":[{"id":"1.168209731","rc":[{"batl":[[0,1.96,7.66]],"ltp":1.94,"tv":1925.94,"id":8174357},{"batb":[[0,2.04,6.16],[1,2.02,39.86],[2,2,10]],"batl":[[0,2.06,48.78]],"ltp":2.04,"tv":1185.0,"id":7412952}]}]}
{"op":"mcm","clk":"1004107521","pt":1580620531784,"mc":[{"id":"1.168209731","rc":[{"batl":[[0,1.96,7.67]],"ltp":1.94,"tv":1925.94,"id":8174357},{"batb":[[0,2.04,6.17]],"batl":[[0,2.06,42.78]],"ltp":2.04,"tv":1185.0,"id":7412952}]}]}
{"op":"mcm","clk":"1004107579","pt":1580620532912,"mc":[{"id":"1.168209731","rc":[{"batl":[[0,1.96,2.5]],"ltp":1.94,"tv":1925.94,"id":8174357},{"batb":[[0,2.02,39.86],[1,2,10],[2,1.81,330.47]],"batl":[[0,2.06,48.78]],"ltp":2.04,"tv":1185.0,"id":7412952}]}]}
{"op":"mcm","clk":"1004107635","pt":1580620533890,"mc":[{"id":"1.168209731","rc":[{"batl":[[0,1.96,7.68]],"ltp":1.94,"tv":1925.94,"id":8174357},{"batb":[[0,2.04,6.18],[1,2.02,39.86],[2,2,10]],"batl":[[0,2.06,42.78]],"ltp":2.04,"tv":1185.0,"id":7412952}]}]}
{"op":"mcm","clk":"1004107675","pt":1580620534814,"mc":[{"id":"1.168209731","rc":[{"batl":[[0,1.96,7.69]],"ltp":1.94,"tv":1925.94,"id":8174357},{"batb":[[0,2.04,6.19]],"ltp":2.04,"tv":1185.0,"id":7412952}]}]}
{"op":"mcm","clk":"1004107717","pt":1580620535786,"mc":[{"id":"1.168209731","rc":[{"batl":[[0,1.96,2.5]],"ltp":1.94,"tv":1925.94,"id":8174357},{"batb":[[0,2.02,39.86],[1,2,10],[2,1.81,330.47]],"batl":[[0,2.06,48.78]],"ltp":2.04,"tv":1185.0,"id":7412952}]}]}
{"op":"mcm","clk":"1004107782","pt":1580620536918,"mc":[{"id":"1.168209731","rc":[{"batl":[[0,1.96,7.7]],"ltp":1.94,"tv":1925.94,"id":8174357},{"batb":[[0,2.04,6.2],[1,2.02,39.86],[2,2,10]],"batl":[[0,2.06,42.78]],"ltp":2.04,"tv":1185.0,"id":7412952}]}]}
{"op":"mcm","clk":"1004107885","pt":1580620538928,"mc":[{"id":"1.168209731","rc":[{"batl":[[0,1.96,2.5]],"ltp":1.94,"tv":1925.94,"id":8174357},{"batb":[[0,2.02,39.86],[1,2,10],[2,1.81,330.47]],"batl":[[0,2.06,48.78]],"ltp":2.04,"tv":1185.0,"id":7412952}]}]}
{"op":"mcm","clk":"1004108044","pt":1580620541915,"mc":[{"id":"1.168209731","rc":[{"batl":[[0,1.96,7.72]],"ltp":1.94,"tv":1925.94,"id":8174357},{"batb":[[0,2.04,6.22],[1,2.02,39.86],[2,2,10]],"ltp":2.04,"tv":1185.0,"id":7412952}]}]}
{"op":"mcm","clk":"1004108098","pt":1580620542894,"mc":[{"id":"1.168209731","rc":[{"batl":[[0,1.96,7.73]],"ltp":1.94,"tv":1925.94,"id":8174357},{"batb":[[0,2.04,6.23]],"batl":[[0,2.06,42.78]],"ltp":2.04,"tv":1185.0,"id":7412952}]}]}
{"op":"mcm","clk":"1004108156","pt":1580620543922,"mc":[{"id":"1.168209731","rc":[{"batl":[[0,1.96,7.74]],"ltp":1.94,"tv":1925.94,"id":8174357},{"batb":[[0,2.04,6.24]],"ltp":2.04,"tv":1185.0,"id":7412952}]}]}
{"op":"mcm","clk":"1004108242","pt":1580620545822,"mc":[{"id":"1.168209731","rc":[{"batl":[[0,1.96,2.5]],"ltp":1.94,"tv":1925.94,"id":8174357},{"batb":[[0,2.02,39.86],[1,2,10],[2,1.81,330.47]],"batl":[[0,2.06,48.78]],"ltp":2.04,"tv":1185.0,"id":7412952}]}]}
{"op":"mcm","clk":"1004108292","pt":1580620546898,"mc":[{"id":"1.168209731","rc":[{"batl":[[0,1.96,7.75]],"ltp":1.94,"tv":1925.94,"id":8174357},{"batb":[[0,2.04,6.25],[1,2.02,39.86],[2,2,10]],"batl":[[0,2.06,42.78]],"ltp":2.04,"tv":1185.0,"id":7412952}]}]}
{"op":"mcm","clk":"1004108348","pt":1580620547926,"mc":[{"id":"1.168209731","rc":[{"batl":[[0,1.96,2.5]],"ltp":1.94,"tv":1925.94,"id":8174357},{"batb":[[0,2.02,39.86],[1,2,10],[2,1.81,330.47]],"batl":[[0,2.06,48.78]],"ltp":2.04,"tv":1185.0,"id":7412952}]}]}
{"op":"mcm","clk":"1004108449","pt":1580620549825,"mc":[{"id":"1.168209731","rc":[{"batl":[[0,1.96,7.77]],"ltp":1.94,"tv":1925.94,"id":8174357},{"batb":[[0,2.04,6.27],[1,2.02,39.86],[2,2,10]],"batl":[[0,2.06,42.78]],"ltp":2.04,"tv":1185.0,"id":7412952}]}]}
{"op":"mcm","clk":"1004108507","pt":1580620550906,"mc":[{"id":"1.168209731","rc":[{"batl":[[0,2.06,48.78]],"ltp":2.04,"tv":1185.0,"id":7412952}]}]}
{"op":"mcm","clk":"1004108562","pt":1580620551846,"mc":[{"id":"1.168209731","rc":[{"batl":[[0,1.96,7.78]],"ltp":1.94,"tv":1925.94,"id":8174357},{"batb":[[0,2.04,6.28]],"batl":[[0,2.06,42.78]],"ltp":2.04,"tv":1185.0,"id":7412952}]}]}
{"op":"mcm","clk":"1004108632","pt":1580620552929,"mc":[{"id":"1.168209731","rc":[{"batl":[[0,1.96,2.5]],"ltp":1.94,"tv":1925.94,"id":8174357},{"batb":[[0,2.02,39.86],[1,2,10],[2,1.81,330.47]],"batl":[[0,2.06,48.78]],"ltp":2.04,"tv":1185.0,"id":7412952}]}]}
{"op":"mcm","clk":"1004108860","pt":1580620557911,"mc":[{"id":"1.168209731","rc":[{"batl":[[0,1.96,7.81]],"ltp":1.94,"tv":1925.94,"id":8174357},{"batb":[[0,2.04,6.31],[1,2.02,39.86],[2,2,10]],"batl":[[0,2.06,42.78]],"ltp":2.04,"tv":1185.0,"id":7412952}]}]}
{"op":"mcm","clk":"1004108911","pt":1580620558829,"mc":[{"id":"1.168209731","rc":[{"batl":[[0,1.96,7.82]],"ltp":1.94,"tv":1925.94,"id":8174357},{"batb":[[0,2.04,6.32]],"ltp":2.04,"tv":1185.0,"id":7412952}]}]}
{"op":"mcm","clk":"1004108967","pt":1580620559954,"mc":[{"id":"1.168209731","rc":[{"batl":[[0,2.06,48.78]],"ltp":2.04,"tv":1185.0,"id":7412952}]}]}
{"op":"mcm","clk":"1004109005","pt":1580620560935,"mc":[{"id":"1.168209731","rc":[{"batl":[[0,1.96,2.5]],"ltp":1.94,"tv":1925.94,"id":8174357},{"batb":[[0,2.02,39.86],[1,2,10],[2,1.81,330.47]],"ltp":2.04,"tv":1185.0,"id":7412952}]}]}
{"op":"mcm","clk":"1004109095","pt":1580620562945,"mc":[{"id":"1.168209731","rc":[{"batl":[[0,1.96,7.51]],"ltp":1.94,"tv":1925.94,"id":8174357},{"batb":[[0,2.04,6.01],[1,2.02,39.86],[2,2,10]],"batl":[[0,2.06,42.78]],"ltp":2.04,"tv":1185.0,"id":7412952}]}]}
{"op":"mcm","clk":"1004109135","pt":1580620563922,"mc":[{"id":"1.168209731","rc":[{"batl":[[0,1.96,7.52]],"ltp":1.94,"tv":1925.94,"id":8174357},{"batb":[[0,2.04,6.02]],"ltp":2.04,"tv":1185.0,"id":7412952}]}]}
{"op":"mcm","clk":"1004109243","pt":1580620565831,"mc":[{"id":"1.168209731","rc":[{"batl":[[0,1.96,2.5]],"ltp":1.94,"tv":1925.94,"id":8174357},{"batb":[[0,2.02,39.86],[1,2,10],[2,1.81,330.47]],"batl":[[0,2.06,48.78]],"ltp":2.04,"tv":1185.0,"id":7412952}]}]}
{"op":"mcm","clk":"1004109341","pt":1580620567860,"mc":[{"id":"1.168209731","rc":[{"batl":[[0,1.96,7.54]],"ltp":1.94,"tv":1925.94,"id":8174357},{"batb":[[0,2.04,6.04],[1,2.02,39.86],[2,2,10]],"batl":[[0,2.06,42.78]],"ltp":2.04,"tv":1185.0,"id":7412952}]}]}
{"op":"mcm","clk":"1004109442","pt":1580620569838,"mc":[{"id":"1.168209731","rc":[{"batl":[[0,1.96,7.55]],"ltp":1.94,"tv":1925.94,"id":8174357},{"batb":[[0,2.04,6.05]],"ltp":2.04,"tv":1185.0,"id":7412952}]}]}
{"op":"mcm","clk":"1004109545","pt":1580620571946,"mc":[{"id":"1.168209731","rc":[{"batl":[[0,1.96,2.5]],"ltp":1.94,"tv":1925.94,"id":8174357},{"batb":[[0,2.02,39.86],[1,2,10],[2,1.81,330.47]],"batl":[[0,2.06,48.78]],"ltp":2.04,"tv":1185.0,"id":7412952}]}]}
{"op":"mcm","clk":"1004109789","pt":1580620576768,"mc":[{"id":"1.168209731","rc":[{"batl":[[0,2.06,54.78]],"ltp":2.04,"tv":1185.0,"id":7412952}]}]}
{"op":"mcm","clk":"1004109844","pt":1580620577951,"mc":[{"id":"1.168209731","rc":[{"batl":[[0,1.96,12.68]],"ltp":1.94,"tv":1925.94,"id":8174357},{"batb":[[0,2.04,12.18],[1,2.02,39.86],[2,2,10]],"batl":[[0,2.06,42.78]],"ltp":2.04,"tv":1185.0,"id":7412952}]}]}
{"op":"mcm","clk":"1004109879","pt":1580620578869,"mc":[{"id":"1.168209731","rc":[{"batl":[[0,1.96,7.6]],"ltp":1.94,"tv":1925.94,"id":8174357},{"batb":[[0,2.04,6.1]],"batl":[[0,2.06,48.78]],"ltp":2.04,"tv":1185.0,"id":7412952}]}]}
{"op":"mcm","clk":"1004109921","pt":1580620579945,"mc":[{"id":"1.168209731","rc":[{"batl":[[0,1.96,2.5]],"ltp":1.94,"tv":1925.94,"id":8174357},{"batb":[[0,2.02,39.86],[1,2,10],[2,1.81,330.47]],"ltp":2.04,"tv":1185.0,"id":7412952}]}]}
{"op":"mcm","clk":"1004109998","pt":1580620581947,"mc":[{"id":"1.168209731","rc":[{"batl":[[0,1.96,7.61]],"ltp":1.94,"tv":1925.94,"id":8174357},{"batb":[[0,2.04,6.11],[1,2.02,39.86],[2,2,10]],"batl":[[0,2.06,42.78]],"ltp":2.04,"tv":1185.0,"id":7412952}]}]}
{"op":"mcm","clk":"1004110039","pt":1580620582767,"mc":[{"id":"1.168209731","rc":[{"batl":[[0,1.96,2.5]],"ltp":1.94,"tv":1925.94,"id":8174357},{"batb":[[0,2.02,39.86],[1,2,10],[2,1.81,330.47]],"batl":[[0,2.06,48.78]],"ltp":2.04,"tv":1185.0,"id":7412952}]}]}
{"op":"mcm","clk":"1004110086","pt":1580620583845,"mc":[{"id":"1.168209731","rc":[{"batl":[[0,1.96,7.63]],"ltp":1.94,"tv":1925.94,"id":8174357},{"batb":[[0,2.04,6.13],[1,2.02,39.86],[2,2,10]],"batl":[[0,2.06,42.78]],"ltp":2.04,"tv":1185.0,"id":7412952}]}]}
{"op":"mcm","clk":"1004110187","pt":1580620585853,"mc":[{"id":"1.168209731","rc":[{"batl":[[0,1.96,2.5]],"ltp":1.94,"tv":1925.94,"id":8174357},{"batb":[[0,2.02,39.86],[1,2,10],[2,1.81,330.47]],"batl":[[0,2.06,48.78]],"ltp":2.04,"tv":1185.0,"id":7412952}]}]}
{"op":"mcm","clk":"1004110250","pt":1580620586937,"mc":[{"id":"1.168209731","rc":[{"batl":[[0,1.96,7.64]],"ltp":1.94,"tv":1925.94,"id":8174357},{"batb":[[0,2.04,6.14],[1,2.02,39.86],[2,2,10]],"batl":[[0,2.06,42.78]],"ltp":2.04,"tv":1185.0,"id":7412952}]}]}
{"op":"mcm","clk":"1004110292","pt":1580620587758,"mc":[{"id":"1.168209731","rc":[{"batl":[[0,1.96,2.5]],"ltp":1.94,"tv":1925.94,"id":8174357},{"batb":[[0,2.02,39.86],[1,2,10],[2,1.81,330.47]],"batl":[[0,2.06,48.78]],"ltp":2.04,"tv":1185.0,"id":7412952}]}]}
{"op":"mcm","clk":"1004110354","pt":1580620588836,"mc":[{"id":"1.168209731","rc":[{"batl":[[0,1.96,7.65]],"ltp":1.94,"tv":1925.94,"id":8174357},{"batb":[[0,2.04,6.15],[1,2.02,39.86],[2,2,10]],"batl":[[0,2.06,42.78]],"ltp":2.04,"tv":1185.0,"id":7412952}]}]}
{"op":"mcm","clk":"1004110404","pt":1580620589862,"mc":[{"id":"1.168209731","rc":[{"batl":[[0,1.96,7.66]],"ltp":1.94,"tv":1925.94,"id":8174357},{"batb":[[0,2.04,6.16]],"ltp":2.04,"tv":1185.0,"id":7412952}]}]}
{"op":"mcm","clk":"1004110496","pt":1580620591877,"mc":[{"id":"1.168209731","rc":[{"batl":[[0,1.96,7.67]],"ltp":1.94,"tv":1925.94,"id":8174357},{"batb":[[0,2.04,6.17]],"batl":[[0,2.06,48.78]],"ltp":2.04,"tv":1185.0,"id":7412952}]}]}
{"op":"mcm","clk":"1004110536","pt":1580620592855,"mc":[{"id":"1.168209731","rc":[{"batl":[[0,1.96,2.5]],"ltp":1.94,"tv":1925.94,"id":8174357},{"batb":[[0,2.02,39.86],[1,2,10],[2,1.81,330.47]],"ltp":2.04,"tv":1185.0,"id":7412952}]}]}
{"op":"mcm","clk":"1004110577","pt":1580620593884,"mc":[{"id":"1.168209731","rc":[{"batl":[[0,1.96,7.68]],"ltp":1.94,"tv":1925.94,"id":8174357},{"batb":[[0,2.04,6.18],[1,2.02,39.86],[2,2,10]],"batl":[[0,2.06,42.78]],"ltp":2.04,"tv":1185.0,"id":7412952}]}]}
{"op":"mcm","clk":"1004110618","pt":1580620594857,"mc":[{"id":"1.168209731","rc":[{"batl":[[0,1.96,7.69]],"ltp":1.94,"tv":1925.94,"id":8174357},{"batb":[[0,2.04,6.19]],"batl":[[0,2.06,48.78]],"ltp":2.04,"tv":1185.0,"id":7412952}]}]}
{"op":"mcm","clk":"1004110653","pt":1580620595782,"mc":[{"id":"1.168209731","rc":[{"batl":[[0,1.96,2.5]],"ltp":1.94,"tv":1925.94,"id":8174357},{"batb":[[0,2.02,39.86],[1,2,10],[2,1.81,330.47]],"ltp":2.04,"tv":1185.0,"id":7412952}]}]}
{"op":"mcm","clk":"1004110705","pt":1580620596758,"mc":[{"id":"1.168209731","rc":[{"batl":[[0,1.96,7.7]],"ltp":1.94,"tv":1925.94,"id":8174357},{"batb":[[0,2.04,6.2],[1,2.02,39.86],[2,2,10]],"batl":[[0,2.06,42.78]],"ltp":2.04,"tv":1185.0,"id":7412952}]}]}
{"op":"mcm","clk":"1004110795","pt":1580620598758,"mc":[{"id":"1.168209731","rc":[{"batl":[[0,1.96,2.5]],"ltp":1.94,"tv":1925.94,"id":8174357},{"batb":[[0,2.02,39.86],[1,2,10],[2,1.81,330.47]],"batl":[[0,2.06,48.78]],"ltp":2.04,"tv":1185.0,"id":7412952}]}]}
{"op":"mcm","clk":"1004110903","pt":1580620600861,"mc":[{"id":"1.168209731","rc":[{"batl":[[0,1.96,7.72]],"ltp":1.94,"tv":1925.94,"id":8174357},{"batb":[[0,2.04,6.22],[1,2.02,39.86],[2,2,10]],"batl":[[0,2.06,42.78]],"ltp":2.04,"tv":1185.0,"id":7412952}]}]}
{"op":"mcm","clk":"1004110959","pt":1580620601887,"mc":[{"id":"1.168209731","rc":[{"batl":[[0,1.96,2.5]],"ltp":1.94,"tv":1925.94,"id":8174357},{"batb":[[0,2.02,39.86],[1,2,10],[2,1.81,330.47]],"batl":[[0,2.06,48.78]],"ltp":2.04,"tv":1185.0,"id":7412952}]}]}
{"op":"mcm","clk":"1004111005","pt":1580620602757,"mc":[{"id":"1.168209731","rc":[{"batl":[[0,1.96,7.73]],"ltp":1.94,"tv":1925.94,"id":8174357},{"batb":[[0,2.04,6.23],[1,2.02,39.86],[2,2,10]],"batl":[[0,2.06,42.78]],"ltp":2.04,"tv":1185.0,"id":7412952}]}]}
{"op":"mcm","clk":"1004111107","pt":1580620604867,"mc":[{"id":"1.168209731","rc":[{"batl":[[0,1.96,2.5]],"ltp":1.94,"tv":1925.94,"id":8174357},{"batb":[[0,2.02,39.86],[1,2,10],[2,1.81,330.47]],"batl":[[0,2.06,48.78]],"ltp":2.04,"tv":1185.0,"id":7412952}]}]}
{"op":"mcm","clk":"1004111244","pt":1580620607891,"mc":[{"id":"1.168209731","rc":[{"batl":[[0,1.96,7.76]],"ltp":1.94,"tv":1925.94,"id":8174357},{"batb":[[0,2.04,6.26],[1,2.02,39.86],[2,2,10]],"batl":[[0,2.06,42.78]],"ltp":2.04,"tv":1185.0,"id":7412952}]}]}
{"op":"mcm","clk":"1004111316","pt":1580620609900,"mc":[{"id":"1.168209731","rc":[{"batl":[[0,1.96,2.5]],"ltp":1.94,"tv":1925.94,"id":8174357},{"batb":[[0,2.02,39.86],[1,2,10],[2,1.81,330.47]],"batl":[[0,2.06,48.78]],"ltp":2.04,"tv":1185.0,"id":7412952}]}]}
{"op":"mcm","clk":"1004111409","pt":1580620611908,"mc":[{"id":"1.168209731","rc":[{"batl":[[0,1.96,7.78]],"ltp":1.94,"tv":1925.94,"id":8174357},{"batb":[[0,2.04,6.28],[1,2.02,39.86],[2,2,10]],"batl":[[0,2.06,42.78]],"ltp":2.04,"tv":1185.0,"id":7412952}]}]}
{"op":"mcm","clk":"1004111480","pt":1580620612893,"mc":[{"id":"1.168209731","rc":[{"batl":[[0,1.96,2.5]],"ltp":1.94,"tv":1925.94,"id":8174357},{"batb":[[0,2.02,39.86],[1,2,10],[2,1.81,330.47]],"batl":[[0,2.06,48.78]],"ltp":2.04,"tv":1185.0,"id":7412952}]}]}
{"op":"mcm","clk":"1004111553","pt":1580620613873,"mc":[{"id":"1.168209731","rc":[{"batl":[[0,1.96,7.79]],"ltp":1.94,"tv":1925.94,"id":8174357},{"batb":[[0,2.04,6.29],[1,2.02,39.86],[2,2,10]],"ltp":2.04,"tv":1185.0,"id":7412952}]}]}
{"op":"mcm","clk":"1004111602","pt":1580620614901,"mc":[{"id":"1.168209731","rc":[{"batl":[[0,1.96,7.8]],"ltp":1.94,"tv":1925.94,"id":8174357},{"batb":[[0,2.04,6.3]],"ltp":2.04,"tv":1185.0,"id":7412952}]}]}
{"op":"mcm","clk":"1004111649","pt":1580620615775,"mc":[{"id":"1.168209731","rc":[{"batl":[[0,2.06,42.78]],"ltp":2.04,"tv":1185.0,"id":7412952}]}]}
{"op":"mcm","clk":"1004111725","pt":1580620616799,"mc":[{"id":"1.168209731","rc":[{"batl":[[0,1.96,2.5]],"ltp":1.94,"tv":1925.94,"id":8174357},{"batb":[[0,2.02,39.86],[1,2,10],[2,1.81,330.47]],"batl":[[0,2.06,48.78]],"ltp":2.04,"tv":1185.0,"id":7412952}]}]}
{"op":"mcm","clk":"1004111789","pt":1580620617884,"mc":[{"id":"1.168209731","rc":[{"batl":[[0,1.96,7.81]],"ltp":1.94,"tv":1925.94,"id":8174357},{"batb":[[0,2.04,6.31],[1,2.02,39.86],[2,2,10]],"batl":[[0,2.06,42.78]],"ltp":2.04,"tv":1185.0,"id":7412952}]}]}
{"op":"mcm","clk":"1004111842","pt":1580620618912,"mc":[{"id":"1.168209731","rc":[{"batl":[[0,1.96,7.82]],"ltp":1.94,"tv":1925.94,"id":8174357},{"batb":[[0,2.04,6.32]],"batl":[[0,2.06,48.78]],"ltp":2.04,"tv":1185.0,"id":7412952}]}]}
{"op":"mcm","clk":"1004111879","pt":1580620619791,"mc":[{"id":"1.168209731","rc":[{"batl":[[0,2.06,42.78]],"ltp":2.04,"tv":1185.0,"id":7412952}]}]}
{"op":"mcm","clk":"1004111933","pt":1580620620773,"mc":[{"id":"1.168209731","rc":[{"batl":[[0,1.96,2.5]],"ltp":1.94,"tv":1925.94,"id":8174357},{"batb":[[0,2.02,39.86],[1,2,10],[2,1.81,330.47]],"batl":[[0,2.06,48.78]],"ltp":2.04,"tv":1185.0,"id":7412952}]}]}
{"op":"mcm","clk":"1004111980","pt":1580620621803,"mc":[{"id":"1.168209731","rc":[{"batl":[[0,1.96,7.5]],"ltp":1.94,"tv":1925.94,"id":8174357},{"batb":[[0,2.04,6],[1,2.02,39.86],[2,2,10]],"batl":[[0,2.06,42.78]],"ltp":2.04,"tv":1185.0,"id":7412952}]}]}
{"op":"mcm","clk":"1004112037","pt":1580620622892,"mc":[{"id":"1.168209731","rc":[{"batl":[[0,1.96,2.5]],"ltp":1.94,"tv":1925.94,"id":8174357},{"batb":[[0,2.02,39.86],[1,2,10],[2,1.81,330.47]],"batl":[[0,2.06,48.78]],"ltp":2.04,"tv":1185.0,"id":7412952}]}]}
{"op":"mcm","clk":"1004112091","pt":1580620623920,"mc":[{"id":"1.168209731","rc":[{"batl":[[0,1.96,7.52]],"ltp":1.94,"tv":1925.94,"id":8174357},{"batb":[[0,2.04,6.02],[1,2.02,39.86],[2,2,10]],"batl":[[0,2.06,42.78]],"ltp":2.04,"tv":1185.0,"id":7412952}]}]}
{"op":"mcm","clk":"1004112192","pt":1580620625925,"mc":[{"id":"1.168209731","rc":[{"batl":[[0,1.96,7.53]],"ltp":1.94,"tv":1925.94,"id":8174357},{"batb":[[0,2.04,6.03]],"ltp":2.04,"tv":1185.0,"id":7412952}]}]}
{"op":"mcm","clk":"1004112315","pt":1580620627935,"mc":[{"id":"1.168209731","rc":[{"batl":[[0,1.96,2.5]],"ltp":1.94,"tv":1925.94,"id":8174357},{"batb":[[0,2.02,39.86],[1,2,10],[2,1.81,330.47]],"batl":[[0,2.06,48.78]],"ltp":2.04,"tv":1185.0,"id":7412952}]}]}
{"op":"mcm","clk":"1004112486","pt":1580620630924,"mc":[{"id":"1.168209731","rc":[{"batl":[[0,1.96,7.55]],"ltp":1.94,"tv":1925.94,"id":8174357},{"batb":[[0,2.04,6.05],[1,2.02,39.86],[2,2,10]],"batl":[[0,2.06,42.78]],"ltp":2.04,"tv":1185.0,"id":7412952}]}]}
{"op":"mcm","clk":"1004112542","pt":1580620631897,"mc":[{"id":"1.168209731","rc":[{"batl":[[0,1.96,7.56]],"ltp":1.94,"tv":1925.94,"id":8174357},{"batb":[[0,2.04,6.06]],"batl":[[0,2.06,48.78]],"ltp":2.04,"tv":1185.0,"id":7412952}]}]}
{"op":"mcm","clk":"1004112590","pt":1580620632823,"mc":[{"id":"1.168209731","rc":[{"batl":[[0,1.96,2.5]],"ltp":1.94,"tv":1925.94,"id":8174357},{"batb":[[0,2.02,39.86],[1,2,10],[2,1.81,330.47]],"ltp":2.04,"tv":1185.0,"id":7412952}]}]}
{"op":"mcm","clk":"1004112696","pt":1580620634922,"mc":[{"id":"1.168209731","rc":[{"batl":[[0,1.96,7.58]],"ltp":1.94,"tv":1925.94,"id":8174357},{"batb":[[0,2.04,6.08],[1,2.02,39.86],[2,2,10]],"batl":[[0,2.06,42.78]],"ltp":2.04,"tv":1185.0,"id":7412952}]}]}
{"op":"mcm","clk":"1004112799","pt":1580620636929,"mc":[{"id":"1.168209731","rc":[{"batl":[[0,1.96,2.5]],"ltp":1.94,"tv":1925.94,"id":8174357},{"batb":[[0,2.02,39.86],[1,2,10],[2,1.81,330.47]],"batl":[[0,2.06,48.78]],"ltp":2.04,"tv":1185.0,"id":7412952}]}]}
{"op":"mcm","clk":"1004112897","pt":1580620638930,"mc":[{"id":"1.168209731","rc":[{"batl":[[0,1.96,7.6]],"ltp":1.94,"tv":1925.94,"id":8174357},{"batb":[[0,2.04,6.1],[1,2.02,39.86],[2,2,10]],"batl":[[0,2.06,42.78]],"ltp":2.04,"tv":1185.0,"id":7412952}]}]}
{"op":"mcm","clk":"1004112990","pt":1580620640931,"mc":[{"id":"1.168209731","rc":[{"batl":[[0,1.96,2.5]],"ltp":1.94,"tv":1925.94,"id":8174357},{"batb":[[0,2.02,39.86],[1,2,10],[2,1.81,330.47]],"batl":[[0,2.06,48.78]],"ltp":2.04,"tv":1185.0,"id":7412952}]}]}
{"op":"mcm","clk":"1004113034","pt":1580620641906,"mc":[{"id":"1.168209731","rc":[{"batl":[[0,1.96,7.61]],"ltp":1.94,"tv":1925.94,"id":8174357},{"batb":[[0,2.04,6.11],[1,2.02,39.86],[2,2,10]],"batl":[[0,2.06,42.78]],"ltp":2.04,"tv":1185.0,"id":7412952}]}]}
{"op":"mcm","clk":"1004113081","pt":1580620642937,"mc":[{"id":"1.168209731","rc":[{"batl":[[0,1.96,2.5]],"ltp":1.94,"tv":1925.94,"id":8174357},{"batb":[[0,2.02,39.86],[1,2,10],[2,1.81,330.47]],"batl":[[0,2.06,48.78]],"ltp":2.04,"tv":1185.0,"id":7412952}]}]}
{"op":"mcm","clk":"1004113129","pt":1580620643910,"mc":[{"id":"1.168209731","rc":[{"batl":[[0,1.96,7.63]],"ltp":1.94,"tv":1925.94,"id":8174357},{"batb":[[0,2.04,6.13],[1,2.02,39.86],[2,2,10]],"batl":[[0,2.06,42.78]],"ltp":2.04,"tv":1185.0,"id":7412952}]}]}
{"op":"mcm","clk":"1004113242","pt":1580620645912,"mc":[{"id":"1.168209731","rc":[{"batl":[[0,1.96,2.5]],"ltp":1.94,"tv":1925.94,"id":8174357},{"batb":[[0,2.02,39.86],[1,2,10],[2,1.81,330.47]],"batl":[[0,2.06,48.78]],"ltp":2.04,"tv":1185.0,"id":7412952}]}]}
{"op":"mcm","clk":"1004113293","pt":1580620646938,"mc":[{"id":"1.168209731","rc":[{"batl":[[0,1.96,7.64]],"ltp":1.94,"tv":1925.94,"id":8174357},{"batb":[[0,2.04,6.14],[1,2.02,39.86],[2,2,10]],"batl":[[0,2.06,42.78]],"ltp":2.04,"tv":1185.0,"id":7412952}]}]}
{"op":"mcm","clk":"1004113347","pt":1580620647911,"mc":[{"id":"1.168209731","rc":[{"batl":[[0,1.96,2.5]],"ltp":1.94,"tv":1925.94,"id":8174357},{"batb":[[0,2.02,39.86],[1,2,10],[2,1.81,330.47]],"batl":[[0,2.06,48.78]],"ltp":2.04,"tv":1185.0,"id":7412952}]}]}
{"op":"mcm","clk":"1004113406","pt":1580620648943,"mc":[{"id":"1.168209731","rc":[{"batl":[[0,1.96,7.65]],"ltp":1.94,"tv":1925.94,"id":8174357},{"batb":[[0,2.04,6.15],[1,2.02,39.86],[2,2,10]],"batl":[[0,2.06,42.78]],"ltp":2.04,"tv":1185.0,"id":7412952}]}]}
{"op":"mcm","clk":"1004113453","pt":1580620649918,"mc":[{"id":"1.168209731","rc":[{"batl":[[0,1.96,2.5]],"ltp":1.94,"tv":1925.94,"id":8174357},{"batb":[[0,2.02,39.86],[1,2,10],[2,1.81,330.47]],"batl":[[0,2.06,48.78]],"ltp":2.04,"tv":1185.0,"id":7412952}]}]}
{"op":"mcm","clk":"1004113503","pt":1580620650947,"mc":[{"id":"1.168209731","rc":[{"batl":[[0,1.96,7.66]],"ltp":1.94,"tv":1925.94,"id":8174357},{"batb":[[0,2.04,6.16],[1,2.02,39.86],[2,2,10]],"batl":[[0,2.06,42.78]],"ltp":2.04,"tv":1185.0,"id":7412952}]}]}
{"op":"mcm","clk":"1004113553","pt":1580620651925,"mc":[{"id":"1.168209731","rc":[{"batl":[[0,1.96,2.5]],"ltp":1.94,"tv":1925.94,"id":8174357},{"batb":[[0,2.02,39.86],[1,2,10],[2,1.81,330.47]],"batl":[[0,2.06,48.78]],"ltp":2.04,"tv":1185.0,"id":7412952}]}]}
{"op":"mcm","clk":"1004113592","pt":1580620652954,"mc":[{"id":"1.168209731","rc":[{"batl":[[0,1.96,7.68]],"ltp":1.94,"tv":1925.94,"id":8174357},{"batb":[[0,2.04,6.18],[1,2.02,39.86],[2,2,10]],"batl":[[0,2.06,42.78]],"ltp":2.04,"tv":1185.0,"id":7412952}]}]}
{"op":"mcm","clk":"1004113630","pt":1580620653929,"mc":[{"id":"1.168209731","rc":[{"batl":[[0,1.96,2.5]],"ltp":1.94,"tv":1925.94,"id":8174357},{"batb":[[0,2.02,39.86],[1,2,10],[2,1.81,330.47]],"batl":[[0,2.06,48.78]],"ltp":2.04,"tv":1185.0,"id":7412952}]}]}
{"op":"mcm","clk":"1004113741","pt":1580620656815,"mc":[{"id":"1.168209731","rc":[{"batl":[[0,1.96,7.7]],"ltp":1.94,"tv":1925.94,"id":8174357},{"batb":[[0,2.04,6.2],[1,2.02,39.86],[2,2,10]],"ltp":2.04,"tv":1185.0,"id":7412952}]}]}
{"op":"mcm","clk":"1004113784","pt":1580620657941,"mc":[{"id":"1.168209731","rc":[{"batl":[[0,2.06,42.78]],"ltp":2.04,"tv":1185.0,"id":7412952}]}]}
{"op":"mcm","clk":"1004113821","pt":1580620658760,"mc":[{"id":"1.168209731","rc":[{"batl":[[0,1.96,7.71]],"ltp":1.94,"tv":1925.94,"id":8174357},{"batb":[[0,2.04,6.21]],"ltp":2.04,"tv":1185.0,"id":7412952}]}]}
{"op":"mcm","clk":"1004113909","pt":1580620660763,"mc":[{"id":"1.168209731","rc":[{"batl":[[0,1.96,7.72]],"ltp":1.94,"tv":1925.94,"id":8174357},{"batb":[[0,2.04,6.22]],"ltp":2.04,"tv":1185.0,"id":7412952}]}]}
{"op":"mcm","clk":"1004113960","pt":1580620661840,"mc":[{"id":"1.168209731","rc":[{"batl":[[0,1.96,2.5]],"ltp":1.94,"tv":1925.94,"id":8174357},{"batb":[[0,2.02,39.86],[1,2,10],[2,1.81,330.47]],"batl":[[0,2.06,48.78]],"ltp":2.04,"tv":1185.0,"id":7412952}]}]}
{"op":"mcm","clk":"1004114013","pt":1580620662864,"mc":[{"id":"1.168209731","rc":[{"batl":[[0,1.96,7.73]],"ltp":1.94,"tv":1925.94,"id":8174357},{"batb":[[0,2.04,6.23],[1,2.02,39.86],[2,2,10]],"batl":[[0,2.06,42.78]],"ltp":2.04,"tv":1185.0,"id":7412952}]}]}
{"op":"mcm","clk":"1004114071","pt":1580620663942,"mc":[{"id":"1.168209731","rc":[{"batl":[[0,2.06,48.78]],"ltp":2.04,"tv":1185.0,"id":7412952}]}]}
{"op":"mcm","clk":"1004114113","pt":1580620664863,"mc":[{"id":"1.168209731","rc":[{"batl":[[0,1.96,2.5]],"ltp":1.94,"tv":1925.94,"id":8174357},{"batb":[[0,2.02,39.86],[1,2,10],[2,1.81,330.47]],"ltp":2.04,"tv":1185.0,"id":7412952}]}]}
{"op":"mcm","clk":"1004114161","pt":1580620665838,"mc":[{"id":"1.168209731","rc":[{"batl":[[0,1.96,7.75]],"ltp":1.94,"tv":1925.94,"id":8174357},{"batb":[[0,2.04,6.25],[1,2.02,39.86],[2,2,10]],"batl":[[0,2.06,42.78]],"ltp":2.04,"tv":1185.0,"id":7412952}]}]}
{"op":"mcm","clk":"1004114261","pt":1580620667944,"mc":[{"id":"1.168209731","rc":[{"batl":[[0,1.96,2.5]],"ltp":1.94,"tv":1925.94,"id":8174357},{"batb":[[0,2.02,39.86],[1,2,10],[2,1.81,330.47]],"batl":[[0,2.06,48.78]],"ltp":2.04,"tv":1185.0,"id":7412952}]}]}
{"op":"mcm","clk":"1004114306","pt":1580620668871,"mc":[{"id":"1.168209731","rc":[{"batl":[[0,1.96,7.76]],"ltp":1.94,"tv":1925.94,"id":8174357},{"batb":[[0,2.04,6.26],[1,2.02,39.86],[2,2,10]],"ltp":2.04,"tv":1185.0,"id":7412952}]}]}
{"op":"mcm","clk":"1004114356","pt":1580620669950,"mc":[{"id":"1.168209731","rc":[{"batl":[[0,1.96,7.77]],"ltp":1.94,"tv":1925.94,"id":8174357},{"batb":[[0,2.04,6.27]],"ltp":2.04,"tv":1185.0,"id":7412952}]}]}
{"op":"mcm","clk":"1004114404","pt":1580620670934,"mc":[{"id":"1.168209731","rc":[{"batl":[[0,2.06,42.78]],"ltp":2.04,"tv":1185.0,"id":7412952}]}]}
{"op":"mcm","clk":"1004114439","pt":1580620671855,"mc":[{"id":"1.168209731","rc":[{"batl":[[0,1.96,7.78]],"ltp":1.94,"tv":1925.94,"id":8174357},{"batb":[[0,2.04,6.28]],"ltp":2.04,"tv":1185.0,"id":7412952}]}]}
{"op":"mcm","clk":"1004114541","pt":1580620673856,"mc":[{"id":"1.168209731","rc":[{"batl":[[0,1.96,2.5]],"ltp":1.94,"tv":1925.94,"id":8174357},{"batb":[[0,2.02,39.86],[1,2,10],[2,1.81,330.47]],"ltp":2.04,"tv":1185.0,"id":7412952}]}]}
{"op":"mcm","clk":"1004114583","pt":1580620674881,"mc":[{"id":"1.168209731","rc":[{"batl":[[0,2.06,48.78]],"ltp":2.04,"tv":1185.0,"id":7412952}]}]}
{"op":"mcm","clk":"1004114820","pt":1580620680944,"mc":[{"id":"1.168209731","rc":[{"batl":[[0,1.96,7.5]],"ltp":1.94,"tv":1925.94,"id":8174357},{"batb":[[0,2.04,6],[1,2.02,39.86],[2,2,10]],"ltp":2.04,"tv":1185.0,"id":7412952}]}]}
{"op":"mcm","clk":"1004114861","pt":1580620681873,"mc":[{"id":"1.168209731","rc":[{"batl":[[0,1.96,2.5]],"ltp":1.94,"tv":1925.94,"id":8174357},{"batb":[[0,2.02,39.86],[1,2,10],[2,1.81,330.47]],"ltp":2.04,"tv":1185.0,"id":7412952}]}]}
{"op":"mcm","clk":"1004114974","pt":1580620683787,"mc":[{"id":"1.168209731","rc":[{"batl":[[0,2.06,54.78]],"ltp":2.04,"tv":1185.0,"id":7412952}]}]}
{"op":"mcm","clk":"1004115033","pt":1580620684764,"mc":[{"id":"1.168209731","rc":[{"batl":[[0,1.96,7.52]],"ltp":1.94,"tv":1925.94,"id":8174357},{"batb":[[0,2.04,6.02],[1,2.02,39.86],[2,2,10]],"batl":[[0,2.06,42.78]],"ltp":2.04,"tv":1185.0,"id":7412952}]}]}
{"op":"mcm","clk":"1004115097","pt":1580620685796,"mc":[{"id":"1.168209731","rc":[{"batl":[[0,1.96,2.5]],"ltp":1.94,"tv":1925.94,"id":8174357},{"batb":[[0,2.02,39.86],[1,2,10],[2,1.81,330.47]],"batl":[[0,2.06,48.78]],"ltp":2.04,"tv":1185.0,"id":7412952}]}]}
{"op":"mcm","clk":"1004115205","pt":1580620687858,"mc":[{"id":"1.168209731","rc":[{"batl":[[0,1.96,7.54]],"ltp":1.94,"tv":1925.94,"id":8174357},{"batb":[[0,2.04,6.04],[1,2.02,39.86],[2,2,10]],"batl":[[0,2.06,42.78]],"ltp":2.04,"tv":1185.0,"id":7412952}]}]}
{"op":"mcm","clk":"1004115308","pt":1580620689867,"mc":[{"id":"1.168209731","rc":[{"batl":[[0,1.96,7.55]],"ltp":1.94,"tv":1925.94,"id":8174357},{"batb":[[0,2.04,6.05]],"batl":[[0,2.06,48.78]],"ltp":2.04,"tv":1185.0,"id":7412952}]}]}
{"op":"mcm","clk":"1004115355","pt":1580620690765,"mc":[{"id":"1.168209731","rc":[{"batl":[[0,2.06,42.78]],"ltp":2.04,"tv":1185.0,"id":7412952}]}]}
{"op":"mcm","clk":"1004115416","pt":1580620691894,"mc":[{"id":"1.168209731","rc":[{"batl":[[0,1.96,7.56]],"ltp":1.94,"tv":1925.94,"id":8174357},{"batb":[[0,2.04,6.06]],"batl":[[0,2.06,48.78]],"ltp":2.04,"tv":1185.0,"id":7412952}]}]}
{"op":"mcm","clk":"1004115462","pt":1580620692771,"mc":[{"id":"1.168209731","rc":[{"batl":[[0,1.96,2.5]],"ltp":1.94,"tv":1925.94,"id":8174357},{"batb":[[0,2.02,39.86],[1,2,10],[2,1.81,330.47]],"ltp":2.04,"tv":1185.0,"id":7412952}]}]}
{"op":"mcm","clk":"1004115559","pt":1580620694868,"mc":[{"id":"1.168209731","rc":[{"batl":[[0,1.96,7.58]],"ltp":1.94,"tv":1925.94,"id":8174357},{"batb":[[0,2.04,6.08],[1,2.02,39.86],[2,2,10]],"batl":[[0,2.06,42.78]],"ltp":2.04,"tv":1185.0,"id":7412952}]}]}
{"op":"mcm","clk":"1004115646","pt":1580620696786,"mc":[{"id":"1.168209731","rc":[{"batl":[[0,1.96,7.59]],"ltp":1.94,"tv":1925.94,"id":8174357},{"batb":[[0,2.04,6.09]],"ltp":2.04,"tv":1185.0,"id":7412952}]}]}
{"op":"mcm","clk":"1004115744","pt":1580620698791,"mc":[{"id":"1.168209731","rc":[{"batl":[[0,1.96,7.6]],"ltp":1.94,"tv":1925.94,"id":8174357},{"batb":[[0,2.04,6.1]],"ltp":2.04,"tv":1185.0,"id":7412952}]}]}
{"op":"mcm","clk":"1004115787","pt":1580620699771,"mc":[{"id":"1.168209731","rc":[{"batl":[[0,1.96,2.5]],"ltp":1.94,"tv":1925.94,"id":8174357},{"batb":[[0,2.02,39.86],[1,2,10],[2,1.81,330.47]],"batl":[[0,2.06,48.78]],"ltp":2.04,"tv":1185.0,"id":7412952}]}]}
{"op":"mcm","clk":"1004115834","pt":1580620700796,"mc":[{"id":"1.168209731","rc":[{"batl":[[0,1.96,7.61]],"ltp":1.94,"tv":1925.94,"id":8174357},{"batb":[[0,2.04,6.11],[1,2.02,39.86],[2,2,10]],"batl":[[0,2.06,42.78]],"ltp":2.04,"tv":1185.0,"id":7412952}]}]}
{"op":"mcm","clk":"1004115931","pt":1580620702906,"mc":[{"id":"1.168209731","rc":[{"batl":[[0,1.96,2.5]],"ltp":1.94,"tv":1925.94,"id":8174357},{"batb":[[0,2.02,39.86],[1,2,10],[2,1.81,330.47]],"batl":[[0,2.06,48.78]],"ltp":2.04,"tv":1185.0,"id":7412952}]}]}
{"op":"mcm","clk":"1004116091","pt":1580620705910,"mc":[{"id":"1.168209731","rc":[{"batl":[[0,1.96,7.64]],"ltp":1.94,"tv":1925.94,"id":8174357},{"batb":[[0,2.04,6.14],[1,2.02,39.86],[2,2,10]],"batl":[[0,2.06,42.78]],"ltp":2.04,"tv":1185.0,"id":7412952}]}]}
{"op":"mcm","clk":"1004116155","pt":1580620706886,"mc":[{"id":"1.168209731","rc":[{"batl":[[0,1.96,2.5]],"ltp":1.94,"tv":1925.94,"id":8174357},{"batb":[[0,2.02,39.86],[1,2,10],[2,1.81,330.47]],"batl":[[0,2.06,48.78]],"ltp":2.04,"tv":1185.0,"id":7412952}]}]}
{"op":"mcm","clk":"1004116279","pt":1580620708890,"mc":[{"id":"1.168209731","rc":[{"batl":[[0,1.96,7.65]],"ltp":1.94,"tv":1925.94,"id":8174357},{"batb":[[0,2.04,6.15],[1,2.02,39.86],[2,2,10]],"batl":[[0,2.06,42.78]],"ltp":2.04,"tv":1185.0,"id":7412952}]}]}
{"op":"mcm","clk":"1004116335","pt":1580620709919,"mc":[{"id":"1.168209731","rc":[{"batl":[[0,1.96,2.5]],"ltp":1.94,"tv":1925.94,"id":8174357},{"batb":[[0,2.02,39.86],[1,2,10],[2,1.81,330.47]],"batl":[[0,2.06,48.78]],"ltp":2.04,"tv":1185.0,"id":7412952}]}]}
{"op":"mcm","clk":"1004116385","pt":1580620710896,"mc":[{"id":"1.168209731","rc":[{"batl":[[0,1.96,7.66]],"ltp":1.94,"tv":1925.94,"id":8174357},{"batb":[[0,2.04,6.16],[1,2.02,39.86],[2,2,10]],"batl":[[0,2.06,42.78]],"ltp":2.04,"tv":1185.0,"id":7412952}]}]}
{"op":"mcm","clk":"1004116437","pt":1580620711875,"mc":[{"id":"1.168209731","rc":[{"batl":[[0,1.96,2.5]],"ltp":1.94,"tv":1925.94,"id":8174357},{"batb":[[0,2.02,39.86],[1,2,10],[2,1.81,330.47]],"batl":[[0,2.06,48.78]],"ltp":2.04,"tv":1185.0,"id":7412952}]}]}
{"op":"mcm","clk":"1004116482","pt":1580620712903,"mc":[{"id":"1.168209731","rc":[{"batl":[[0,1.96,7.67]],"ltp":1.94,"tv":1925.94,"id":8174357},{"batb":[[0,2.04,6.17],[1,2.02,39.86],[2,2,10]],"batl":[[0,2.06,42.78]],"ltp":2.04,"tv":1185.0,"id":7412952}]}]}
{"op":"mcm","clk":"1004116524","pt":1580620713727,"mc":[{"id":"1.168209731","rc":[{"batl":[[0,1.96,7.68]],"ltp":1.94,"tv":1925.94,"id":8174357},{"batb":[[0,2.04,6.18]],"ltp":2.04,"tv":1185.0,"id":7412952}]}]}
{"op":"mcm","clk":"1004116570","pt":1580620714807,"mc":[{"id":"1.168209731","rc":[{"batl":[[0,1.96,2.5]],"ltp":1.94,"tv":1925.94,"id":8174357},{"batb":[[0,2.02,39.86],[1,2,10],[2,1.81,330.47]],"batl":[[0,2.06,48.78]],"ltp":2.04,"tv":1185.0,"id":7412952}]}]}
{"op":"mcm","clk":"1004116610","pt":1580620715787,"mc":[{"id":"1.168209731","rc":[{"batl":[[0,1.96,7.69]],"ltp":1.94,"tv":1925.94,"id":8174357},{"batb":[[0,2.04,6.19],[1,2.02,39.86],[2,2,10]],"batl":[[0,2.06,42.78]],"ltp":2.04,"tv":1185.0,"id":7412952}]}]}
{"op":"mcm","clk":"1004116666","pt":1580620716816,"mc":[{"id":"1.168209731","rc":[{"batl":[[0,1.96,7.7]],"ltp":1.94,"tv":1925.94,"id":8174357},{"batb":[[0,2.04,6.2]],"ltp":2.04,"tv":1185.0,"id":7412952}]}]}
{"op":"mcm","clk":"1004116714","pt":1580620717799,"mc":[{"id":"1.168209731","rc":[{"batl":[[0,1.96,2.5]],"ltp":1.94,"tv":1925.94,"id":8174357},{"batb":[[0,2.02,39.86],[1,2,10],[2,1.81,330.47]],"batl":[[0,2.06,48.78]],"ltp":2.04,"tv":1185.0,"id":7412952}]}]}
{"op":"mcm","clk":"1004116832","pt":1580620719904,"mc":[{"id":"1.168209731","rc":[{"batl":[[0,1.96,7.71]],"ltp":1.94,"tv":1925.94,"id":8174357},{"batb":[[0,2.04,6.21],[1,2.02,39.86],[2,2,10]],"batl":[[0,2.06,42.78]],"ltp":2.04,"tv":1185.0,"id":7412952}]}]}
{"op":"mcm","clk":"1004116889","pt":1580620720932,"mc":[{"id":"1.168209731","rc":[{"batl":[[0,1.96,7.72]],"ltp":1.94,"tv":1925.94,"id":8174357},{"batb":[[0,2.04,6.22]],"batl":[[0,2.06,48.78]],"ltp":2.04,"tv":1185.0,"id":7412952}]}]}
{"op":"mcm","clk":"1004116936","pt":1580620721811,"mc":[{"id":"1.168209731","rc":[{"batl":[[0,2.06,42.78]],"ltp":2.04,"tv":1185.0,"id":7412952}]}]}
{"op":"mcm","clk":"1004116996","pt":1580620722837,"mc":[{"id":"1.168209731","rc":[{"batl":[[0,1.96,2.5]],"ltp":1.94,"tv":1925.94,"id":8174357},{"batb":[[0,2.02,39.86],[1,2,10],[2,1.81,330.47]],"batl":[[0,2.06,48.78]],"ltp":2.04,"tv":1185.0,"id":7412952}]}]}
{"op":"mcm","clk":"1004117059","pt":1580620723918,"mc":[{"id":"1.168209731","rc":[{"batl":[[0,1.96,7.74]],"ltp":1.94,"tv":1925.94,"id":8174357},{"batb":[[0,2.04,6.24],[1,2.02,39.86],[2,2,10]],"ltp":2.04,"tv":1185.0,"id":7412952}]}]}
{"op":"mcm","clk":"1004117113","pt":1580620724841,"mc":[{"id":"1.168209731","rc":[{"batl":[[0,2.06,42.78]],"ltp":2.04,"tv":1185.0,"id":7412952}]}]}
{"op":"mcm","clk":"1004117169","pt":1580620725924,"mc":[{"id":"1.168209731","rc":[{"batl":[[0,1.96,2.5]],"ltp":1.94,"tv":1925.94,"id":8174357},{"batb":[[0,2.02,39.86],[1,2,10],[2,1.81,330.47]],"batl":[[0,2.06,48.78]],"ltp":2.04,"tv":1185.0,"id":7412952}]}]}
{"op":"mcm","clk":"1004117239","pt":1580620726953,"mc":[{"id":"1.168209731","rc":[{"batl":[[0,1.96,7.75]],"ltp":1.94,"tv":1925.94,"id":8174357},{"batb":[[0,2.04,6.25],[1,2.02,39.86],[2,2,10]],"batl":[[0,2.06,42.78]],"ltp":2.04,"tv":1185.0,"id":7412952}]}]}
{"op":"mcm","clk":"1004117323","pt":1580620727936,"mc":[{"id":"1.168209731","rc":[{"batl":[[0,1.96,2.5]],"ltp":1.94,"tv":1925.94,"id":8174357},{"batb":[[0,2.02,39.86],[1,2,10],[2,1.81,330.47]],"batl":[[0,2.06,48.78]],"ltp":2.04,"tv":1185.0,"id":7412952}]}]}
{"op":"mcm","clk":"1004117386","pt":1580620728918,"mc":[{"id":"1.168209731","rc":[{"batl":[[0,1.96,7.76]],"ltp":1.94,"tv":1925.94,"id":8174357},{"batb":[[0,2.04,6.26],[1,2.02,39.86],[2,2,10]],"batl":[[0,2.06,42.78]],"ltp":2.04,"tv":1185.0,"id":7412952}]}]}
{"op":"mcm","clk":"1004117438","pt":1580620729946,"mc":[{"id":"1.168209731","rc":[{"batl":[[0,1.96,2.5]],"ltp":1.94,"tv":1925.94,"id":8174357},{"batb":[[0,2.02,39.86],[1,2,10],[2,1.81,330.47]],"batl":[[0,2.06,48.78]],"ltp":2.04,"tv":1185.0,"id":7412952}]}]}
{"op":"mcm","clk":"1004117559","pt":1580620731922,"mc":[{"id":"1.168209731","rc":[{"batl":[[0,1.96,7.78]],"ltp":1.94,"tv":1925.94,"id":8174357},{"batb":[[0,2.04,6.28],[1,2.02,39.86],[2,2,10]],"batl":[[0,2.06,42.78]],"ltp":2.04,"tv":1185.0,"id":7412952}]}]}
{"op":"mcm","clk":"1004117610","pt":1580620732949,"mc":[{"id":"1.168209731","rc":[{"batl":[[0,1.96,2.5]],"ltp":1.94,"tv":1925.94,"id":8174357},{"batb":[[0,2.02,39.86],[1,2,10],[2,1.81,330.47]],"batl":[[0,2.06,48.78]],"ltp":2.04,"tv":1185.0,"id":7412952}]}]}
{"op":"mcm","clk":"1004117657","pt":1580620733929,"mc":[{"id":"1.168209731","rc":[{"batl":[[0,1.96,7.79]],"ltp":1.94,"tv":1925.94,"id":8174357},{"batb":[[0,2.04,6.29],[1,2.02,39.86],[2,2,10]],"batl":[[0,2.06,42.78]],"ltp":2.04,"tv":1185.0,"id":7412952}]}]}
{"op":"mcm","clk":"1004117693","pt":1580620734753,"mc":[{"id":"1.168209731","rc":[{"batl":[[0,1.96,2.5]],"ltp":1.94,"tv":1925.94,"id":8174357},{"batb":[[0,2.02,39.86],[1,2,10],[2,1.81,330.47]],"batl":[[0,2.06,48.78]],"ltp":2.04,"tv":1185.0,"id":7412952}]}]}
{"op":"mcm","clk":"1004117809","pt":1580620736859,"mc":[{"id":"1.168209731","rc":[{"batl":[[0,1.96,7.81]],"ltp":1.94,"tv":1925.94,"id":8174357},{"batb":[[0,2.04,6.31],[1,2.02,39.86],[2,2,10]],"ltp":2.04,"tv":1185.0,"id":7412952}]}]}
{"op":"mcm","clk":"1004117884","pt":1580620737945,"mc":[{"id":"1.168209731","rc":[{"batl":[[0,1.96,2.5]],"ltp":1.94,"tv":1925.94,"id":8174357},{"batb":[[0,2.02,39.86],[1,2,10],[2,1.81,330.47]],"ltp":2.04,"tv":1185.0,"id":7412952}]}]}
{"op":"mcm","clk":"1004117944","pt":1580620738932,"mc":[{"id":"1.168209731","rc":[{"batl":[[0,1.96,7.82]],"ltp":1.94,"tv":1925.94,"id":8174357},{"batb":[[0,2.04,6.32],[1,2.02,39.86],[2,2,10]],"batl":[[0,2.06,42.78]],"ltp":2.04,"tv":1185.0,"id":7412952}]}]}
{"op":"mcm","clk":"1004118041","pt":1580620740941,"mc":[{"id":"1.168209731","rc":[{"batl":[[0,1.96,7.5]],"ltp":1.94,"tv":1925.94,"id":8174357},{"batb":[[0,2.04,6]],"ltp":2.04,"tv":1185.0,"id":7412952}]}]}
{"op":"mcm","clk":"1004118094","pt":1580620741869,"mc":[{"id":"1.168209731","rc":[{"batl":[[0,2.06,48.78]],"ltp":2.04,"tv":1185.0,"id":7412952}]}]}
{"op":"mcm","clk":"1004118152","pt":1580620742954,"mc":[{"id":"1.168209731","rc":[{"batl":[[0,1.96,7.51]],"ltp":1.94,"tv":1925.94,"id":8174357},{"batb":[[0,2.04,6.01]],"batl":[[0,2.06,42.78]],"ltp":2.04,"tv":1185.0,"id":7412952}]}]}
{"op":"mcm","clk":"1004118209","pt":1580620743952,"mc":[{"id":"1.168209731","rc":[{"batl":[[0,1.96,2.5]],"ltp":1.94,"tv":1925.94,"id":8174357},{"batb":[[0,2.02,39.86],[1,2,10],[2,1.81,330.47]],"batl":[[0,2.06,48.78]],"ltp":2.04,"tv":1185.0,"id":7412952}]}]}
{"op":"mcm","clk":"1004118291","pt":1580620745757,"mc":[{"id":"1.168209731","rc":[{"batl":[[0,1.96,7.53]],"ltp":1.94,"tv":1925.94,"id":8174357},{"batb":[[0,2.04,6.03],[1,2.02,39.86],[2,2,10]],"batl":[[0,2.06,42.78]],"ltp":2.04,"tv":1185.0,"id":7412952}]}]}
{"op":"mcm","clk":"1004118395","pt":1580620747776,"mc":[{"id":"1.168209731","rc":[{"batl":[[0,1.96,7.54]],"ltp":1.94,"tv":1925.94,"id":8174357},{"batb":[[0,2.04,6.04]],"ltp":2.04,"tv":1185.0,"id":7412952}]}]}
{"op":"mcm","clk":"1004118442","pt":1580620748764,"mc":[{"id":"1.168209731","rc":[{"batl":[[0,1.96,2.5]],"ltp":1.94,"tv":1925.94,"id":8174357},{"batb":[[0,2.02,39.86],[1,2,10],[2,1.81,330.47]],"batl":[[0,2.06,48.78]],"ltp":2.04,"tv":1185.0,"id":7412952}]}]}
{"op":"mcm","clk":"1004118597","pt":1580620751759,"mc":[{"id":"1.168209731","rc":[{"batl":[[0,1.96,7.56]],"ltp":1.94,"tv":1925.94,"id":8174357},{"batb":[[0,2.04,6.06],[1,2.02,39.86],[2,2,10]],"batl":[[0,2.06,42.78]],"ltp":2.04,"tv":1185.0,"id":7412952}]}]}
{"op":"mcm","clk":"1004118662","pt":1580620752954,"mc":[{"id":"1.168209731","rc":[{"batl":[[0,1.96,7.57]],"ltp":1.94,"tv":1925.94,"id":8174357},{"batb":[[0,2.04,6.07]],"ltp":2.04,"tv":1185.0,"id":7412952}]}]}
{"op":"mcm","clk":"1004118751","pt":1580620754858,"mc":[{"id":"1.168209731","rc":[{"batl":[[0,1.96,2.5]],"ltp":1.94,"tv":1925.94,"id":8174357},{"batb":[[0,2.02,39.86],[1,2,10],[2,1.81,330.47]],"batl":[[0,2.06,48.78]],"ltp":2.04,"tv":1185.0,"id":7412952}]}]}
{"op":"mcm","clk":"1004118797","pt":1580620755890,"mc":[{"id":"1.168209731","rc":[{"batl":[[0,1.96,7.58]],"ltp":1.94,"tv":1925.94,"id":8174357},{"batb":[[0,2.04,6.08],[1,2.02,39.86],[2,2,10]],"batl":[[0,2.06,42.78]],"ltp":2.04,"tv":1185.0,"id":7412952}]}]}
{"op":"mcm","clk":"1004118857","pt":1580620756872,"mc":[{"id":"1.168209731","rc":[{"batl":[[0,1.96,2.5]],"ltp":1.94,"tv":1925.94,"id":8174357},{"batb":[[0,2.02,39.86],[1,2,10],[2,1.81,330.47]],"batl":[[0,2.06,48.78]],"ltp":2.04,"tv":1185.0,"id":7412952}]}]}
{"op":"mcm","clk":"1004118919","pt":1580620757951,"mc":[{"id":"1.168209731","rc":[{"batl":[[0,1.96,7.59]],"ltp":1.94,"tv":1925.94,"id":8174357},{"batb":[[0,2.04,6.09],[1,2.02,39.86],[2,2,10]],"batl":[[0,2.06,42.78]],"ltp":2.04,"tv":1185.0,"id":7412952}]}]}
{"op":"mcm","clk":"1004118951","pt":1580620758773,"mc":[{"id":"1.168209731","rc":[{"batl":[[0,1.96,7.6]],"ltp":1.94,"tv":1925.94,"id":8174357},{"batb":[[0,2.04,6.1]],"ltp":2.04,"tv":1185.0,"id":7412952}]}]}
{"op":"mcm","clk":"1004119021","pt":1580620759957,"mc":[{"id":"1.168209731","rc":[{"batl":[[0,1.96,2.5]],"ltp":1.94,"tv":1925.94,"id":8174357},{"batb":[[0,2.02,39.86],[1,2,10],[2,1.81,330.47]],"batl":[[0,2.06,54.78]],"ltp":2.04,"tv":1185.0,"id":7412952}]}]}
{"op":"mcm","clk":"1004119067","pt":1580620760783,"mc":[{"id":"1.168209731","rc":[{"batl":[[0,2.06,42.78]],"ltp":2.04,"tv":1185.0,"id":7412952}]}]}
{"op":"mcm","clk":"1004119142","pt":1580620761876,"mc":[{"id":"1.168209731","rc":[{"batl":[[0,1.96,7.61],[1,2,68.06],[2,2.3,10.13]],"ltp":1.94,"tv":1925.94,"id":8174357},{"batb":[[0,2.04,6],[1,2.02,39.86],[2,2,10]],"ltp":2.04,"tv":1185.0,"id":7412952}]}]}
{"op":"mcm","clk":"1004119200","pt":1580620762804,"mc":[{"id":"1.168209731","rc":[{"batl":[[0,1.96,2.5],[1,1.97,5],[2,2,68.06]],"ltp":1.94,"tv":1925.94,"id":8174357},{"batb":[[0,2.02,39.86],[1,2,10],[2,1.81,330.47]],"batl":[[0,2.06,48.78]],"ltp":2.04,"tv":1185.0,"id":7412952}]}]}
{"op":"mcm","clk":"1004119301","pt":1580620764765,"mc":[{"id":"1.168209731","rc":[{"batl":[[0,1.96,7.63]],"ltp":1.94,"tv":1925.94,"id":8174357},{"batb":[[0,2.04,6.13],[1,2.02,39.86],[2,2,10]],"batl":[[0,2.06,42.78]],"ltp":2.04,"tv":1185.0,"id":7412952}]}]}
{"op":"mcm","clk":"1004119357","pt":1580620765801,"mc":[{"id":"1.168209731","rc":[{"batl":[[0,1.96,2.5]],"ltp":1.94,"tv":1925.94,"id":8174357},{"batb":[[0,2.02,39.86],[1,2,10],[2,1.81,330.47]],"batl":[[0,2.06,48.78]],"ltp":2.04,"tv":1185.0,"id":7412952}]}]}
{"op":"mcm","clk":"1004119423","pt":1580620766787,"mc":[{"id":"1.168209731","rc":[{"batl":[[0,1.96,7.64]],"ltp":1.94,"tv":1925.94,"id":8174357},{"batb":[[0,2.04,6.14],[1,2.02,39.86],[2,2,10]],"batl":[[0,2.06,42.78]],"ltp":2.04,"tv":1185.0,"id":7412952}]}]}
{"op":"mcm","clk":"1004119485","pt":1580620767814,"mc":[{"id":"1.168209731","rc":[{"batl":[[0,1.96,2.5]],"ltp":1.94,"tv":1925.94,"id":8174357},{"batb":[[0,2.02,39.86],[1,2,10],[2,1.81,330.47]],"batl":[[0,2.06,48.78]],"ltp":2.04,"tv":1185.0,"id":7412952}]}]}
{"op":"mcm","clk":"1004119549","pt":1580620768795,"mc":[{"id":"1.168209731","rc":[{"batl":[[0,1.96,7.65]],"ltp":1.94,"tv":1925.94,"id":8174357},{"batb":[[0,2.04,6.15],[1,2.02,39.86],[2,2,10]],"batl":[[0,2.06,42.78]],"ltp":2.04,"tv":1185.0,"id":7412952}]}]}
{"op":"mcm","clk":"1004119600","pt":1580620769820,"mc":[{"id":"1.168209731","rc":[{"batl":[[0,1.96,2.5]],"ltp":1.94,"tv":1925.94,"id":8174357},{"batb":[[0,2.02,39.86],[1,2,10],[2,1.81,330.47]],"batl":[[0,2.06,48.78]],"ltp":2.04,"tv":1185.0,"id":7412952}]}]}
{"op":"mcm","clk":"1004119653","pt":1580620770809,"mc":[{"id":"1.168209731","rc":[{"batl":[[0,1.96,7.66]],"ltp":1.94,"tv":1925.94,"id":8174357},{"batb":[[0,2.04,6.16],[1,2.02,39.86],[2,2,10]],"batl":[[0,2.06,42.78]],"ltp":2.04,"tv":1185.0,"id":7412952}]}]}
{"op":"mcm","clk":"1004119709","pt":1580620771799,"mc":[{"id":"1.168209731","rc":[{"batl":[[0,1.96,2.5]],"ltp":1.94,"tv":1925.94,"id":8174357},{"batb":[[0,2.02,39.86],[1,2,10],[2,1.81,330.47]],"batl":[[0,2.06,48.78]],"ltp":2.04,"tv":1185.0,"id":7412952}]}]}
{"op":"mcm","clk":"1004119767","pt":1580620772780,"mc":[{"id":"1.168209731","rc":[{"batl":[[0,1.96,7.67]],"ltp":1.94,"tv":1925.94,"id":8174357},{"batb":[[0,2.04,6.17],[1,2.02,39.86],[2,2,10]],"batl":[[0,2.06,42.78]],"ltp":2.04,"tv":1185.0,"id":7412952}]}]}
{"op":"mcm","clk":"1004119822","pt":1580620773809,"mc":[{"id":"1.168209731","rc":[{"batl":[[0,1.96,2.5]],"ltp":1.94,"tv":1925.94,"id":8174357},{"batb":[[0,2.02,39.86],[1,2,10],[2,1.81,330.47]],"batl":[[0,2.06,48.78]],"ltp":2.04,"tv":1185.0,"id":7412952}]}]}
{"op":"mcm","clk":"1004119877","pt":1580620774793,"mc":[{"id":"1.168209731","rc":[{"batl":[[0,1.96,7.69]],"ltp":1.94,"tv":1925.94,"id":8174357},{"batb":[[0,2.04,6.19],[1,2.02,39.86],[2,2,10]],"batl":[[0,2.06,42.78]],"ltp":2.04,"tv":1185.0,"id":7412952}]}]}
{"op":"mcm","clk":"1004119935","pt":1580620775826,"mc":[{"id":"1.168209731","rc":[{"batl":[[0,1.96,2.5]],"ltp":1.94,"tv":1925.94,"id":8174357},{"batb":[[0,2.02,39.86],[1,2,10],[2,1.81,330.47]],"batl":[[0,2.06,48.78]],"ltp":2.04,"tv":1185.0,"id":7412952}]}]}
{"op":"mcm","clk":"1004119987","pt":1580620776813,"mc":[{"id":"1.168209731","rc":[{"batl":[[0,1.96,7.7]],"ltp":1.94,"tv":1925.94,"id":8174357},{"batb":[[0,2.04,6.2],[1,2.02,39.86],[2,2,10]],"batl":[[0,2.06,42.78]],"ltp":2.04,"tv":1185.0,"id":7412952}]}]}
{"op":"mcm","clk":"1004120049","pt":1580620777889,"mc":[{"id":"1.168209731","rc":[{"batl":[[0,1.96,2.5]],"ltp":1.94,"tv":1925.94,"id":8174357},{"batb":[[0,2.02,39.86],[1,2,10],[2,1.81,330.47]],"batl":[[0,2.06,48.78]],"ltp":2.04,"tv":1185.0,"id":7412952}]}]}
{"op":"mcm","clk":"1004120111","pt":1580620778911,"mc":[{"id":"1.168209731","rc":[{"batl":[[0,1.96,7.71]],"ltp":1.94,"tv":1925.94,"id":8174357},{"batb":[[0,2.04,6.21],[1,2.02,39.86],[2,2,10]],"batl":[[0,2.06,42.78]],"ltp":2.04,"tv":1185.0,"id":7412952}]}]}
{"op":"mcm","clk":"1004120176","pt":1580620779892,"mc":[{"id":"1.168209731","rc":[{"batl":[[0,1.96,2.5]],"ltp":1.94,"tv":1925.94,"id":8174357},{"batb":[[0,2.02,39.86],[1,2,10],[2,1.81,330.47]],"batl":[[0,2.06,48.78]],"ltp":2.04,"tv":1185.0,"id":7412952}]}]}
{"op":"mcm","clk":"1004120247","pt":1580620780923,"mc":[{"id":"1.168209731","rc":[{"batl":[[0,1.96,7.72]],"ltp":1.94,"tv":1925.94,"id":8174357},{"batb":[[0,2.04,6.22],[1,2.02,39.86],[2,2,10]],"batl":[[0,2.06,42.78]],"ltp":2.04,"tv":1185.0,"id":7412952}]}]}
{"op":"mcm","clk":"1004120318","pt":1580620781907,"mc":[{"id":"1.168209731","rc":[{"batl":[[0,1.96,2.5]],"ltp":1.94,"tv":1925.94,"id":8174357},{"batb":[[0,2.02,39.86],[1,2,10],[2,1.81,330.47]],"batl":[[0,2.06,48.78]],"ltp":2.04,"tv":1185.0,"id":7412952}]}]}
{"op":"mcm","clk":"1004120370","pt":1580620782932,"mc":[{"id":"1.168209731","rc":[{"batl":[[0,1.96,7.73]],"ltp":1.94,"tv":1925.94,"id":8174357},{"batb":[[0,2.04,6.23],[1,2.02,39.86],[2,2,10]],"batl":[[0,2.06,42.78]],"ltp":2.04,"tv":1185.0,"id":7412952}]}]}
{"op":"mcm","clk":"1004120434","pt":1580620783913,"mc":[{"id":"1.168209731","rc":[{"batl":[[0,1.96,2.5]],"ltp":1.94,"tv":1925.94,"id":8174357},{"batb":[[0,2.02,39.86],[1,2,10],[2,1.81,330.47]],"batl":[[0,2.06,48.78]],"ltp":2.04,"tv":1185.0,"id":7412952}]}]}
{"op":"mcm","clk":"1004120483","pt":1580620784896,"mc":[{"id":"1.168209731","rc":[{"batl":[[0,1.96,7.74]],"ltp":1.94,"tv":1925.94,"id":8174357},{"batb":[[0,2.04,6.24],[1,2.02,39.86],[2,2,10]],"batl":[[0,2.06,42.78]],"ltp":2.04,"tv":1185.0,"id":7412952}]}]}
{"op":"mcm","clk":"1004120530","pt":1580620785922,"mc":[{"id":"1.168209731","rc":[{"batl":[[0,1.96,2.5]],"ltp":1.94,"tv":1925.94,"id":8174357},{"batb":[[0,2.02,39.86],[1,2,10],[2,1.81,330.47]],"batl":[[0,2.06,48.78]],"ltp":2.04,"tv":1185.0,"id":7412952}]}]}
{"op":"mcm","clk":"1004120583","pt":1580620786905,"mc":[{"id":"1.168209731","rc":[{"batl":[[0,1.96,7.75]],"ltp":1.94,"tv":1925.94,"id":8174357},{"batb":[[0,2.04,6.25],[1,2.02,39.86],[2,2,10]],"batl":[[0,2.06,42.78]],"ltp":2.04,"tv":1185.0,"id":7412952}]}]}
{"op":"mcm","clk":"1004120627","pt":1580620787931,"mc":[{"id":"1.168209731","rc":[{"batl":[[0,1.96,2.5]],"ltp":1.94,"tv":1925.94,"id":8174357},{"batb":[[0,2.02,39.86],[1,2,10],[2,1.81,330.47]],"batl":[[0,2.06,48.78]],"ltp":2.04,"tv":1185.0,"id":7412952}]}]}
{"op":"mcm","clk":"1004120675","pt":1580620788912,"mc":[{"id":"1.168209731","rc":[{"batl":[[0,1.96,7.76]],"ltp":1.94,"tv":1925.94,"id":8174357},{"batb":[[0,2.04,6.26],[1,2.02,39.86],[2,2,10]],"batl":[[0,2.06,42.78]],"ltp":2.04,"tv":1185.0,"id":7412952}]}]}
{"op":"mcm","clk":"1004120730","pt":1580620789939,"mc":[{"id":"1.168209731","rc":[{"batl":[[0,1.96,2.5]],"ltp":1.94,"tv":1925.94,"id":8174357},{"batb":[[0,2.02,39.86],[1,2,10],[2,1.81,330.47]],"batl":[[0,2.06,48.78]],"ltp":2.04,"tv":1185.0,"id":7412952}]}]}
{"op":"mcm","clk":"1004120779","pt":1580620790931,"mc":[{"id":"1.168209731","rc":[{"batl":[[0,1.96,7.77]],"ltp":1.94,"tv":1925.94,"id":8174357},{"batb":[[0,2.04,6.27],[1,2.02,39.86],[2,2,10]],"batl":[[0,2.06,42.78]],"ltp":2.04,"tv":1185.0,"id":7412952}]}]}
{"op":"mcm","clk":"1004120839","pt":1580620791911,"mc":[{"id":"1.168209731","rc":[{"batl":[[0,1.96,2.5],[1,2,68.06],[2,2.3,10.13]],"ltp":1.94,"tv":1925.94,"id":8174357},{"batb":[[0,2.02,39.86],[1,2,10],[2,1.81,330.47]],"batl":[[0,2.06,48.78]],"ltp":2.04,"tv":1185.0,"id":7412952}]}]}
{"op":"mcm","clk":"1004120887","pt":1580620792833,"mc":[{"id":"1.168209731","rc":[{"batl":[[1,1.97,5],[2,2,68.06]],"ltp":1.94,"tv":1925.94,"id":8174357}]}]}
{"op":"mcm","clk":"1004120955","pt":1580620793921,"mc":[{"id":"1.168209731","rc":[{"batl":[[0,1.96,7.79]],"ltp":1.94,"tv":1925.94,"id":8174357},{"batb":[[0,2.04,6.29],[1,2.02,39.86],[2,2,10]],"batl":[[0,2.06,42.78]],"ltp":2.04,"tv":1185.0,"id":7412952}]}]}
{"op":"mcm","clk":"1004120999","pt":1580620794948,"mc":[{"id":"1.168209731","rc":[{"batl":[[0,1.96,2.5]],"ltp":1.94,"tv":1925.94,"id":8174357},{"batb":[[0,2.02,39.86],[1,2,10],[2,1.81,330.47]],"batl":[[0,2.06,48.78]],"ltp":2.04,"tv":1185.0,"id":7412952}]}]}
{"op":"mcm","clk":"1004121052","pt":1580620795941,"mc":[{"id":"1.168209731","rc":[{"batl":[[0,1.96,7.8]],"ltp":1.94,"tv":1925.94,"id":8174357},{"batb":[[0,2.04,6.3],[1,2.02,39.86],[2,2,10]],"batl":[[0,2.06,42.78]],"ltp":2.04,"tv":1185.0,"id":7412952}]}]}
{"op":"mcm","clk":"1004121109","pt":1580620796922,"mc":[{"id":"1.168209731","rc":[{"batl":[[0,1.96,2.5]],"ltp":1.94,"tv":1925.94,"id":8174357},{"batb":[[0,2.02,39.86],[1,2,10],[2,1.81,330.47]],"batl":[[0,2.06,48.78]],"ltp":2.04,"tv":1185.0,"id":7412952}]}]}
{"op":"mcm","clk":"1004121168","pt":1580620797921,"mc":[{"id":"1.168209731","rc":[{"batl":[[0,1.96,7.81]],"ltp":1.94,"tv":1925.94,"id":8174357},{"batb":[[0,2.04,6.31],[1,2.02,39.86],[2,2,10]],"batl":[[0,2.06,42.78]],"ltp":2.04,"tv":1185.0,"id":7412952}]}]}
{"op":"mcm","clk":"1004121218","pt":1580620798948,"mc":[{"id":"1.168209731","rc":[{"batl":[[0,1.96,2.5]],"ltp":1.94,"tv":1925.94,"id":8174357},{"batb":[[0,2.02,39.86],[1,2,10],[2,1.81,330.47]],"batl":[[0,2.06,48.78]],"ltp":2.04,"tv":1185.0,"id":7412952}]}]}
{"op":"mcm","clk":"1004121263","pt":1580620799928,"mc":[{"id":"1.168209731","rc":[{"batl":[[0,1.96,7.82]],"ltp":1.94,"tv":1925.94,"id":8174357},{"batb":[[0,2.04,6.32],[1,2.02,39.86],[2,2,10]],"batl":[[0,2.06,42.78]],"ltp":2.04,"tv":1185.0,"id":7412952}]}]}
{"op":"mcm","clk":"1004121314","pt":1580620800907,"mc":[{"id":"1.168209731","rc":[{"batl":[[0,1.96,2.5]],"ltp":1.94,"tv":1925.94,"id":8174357},{"batb":[[0,2.02,39.86],[1,2,10],[2,1.81,330.47]],"batl":[[0,2.06,48.78]],"ltp":2.04,"tv":1185.0,"id":7412952}]}]}
{"op":"mcm","clk":"1004121414","pt":1580620802836,"mc":[{"id":"1.168209731","rc":[{"batl":[[0,1.96,7.51]],"ltp":1.94,"tv":1925.94,"id":8174357},{"batb":[[0,2.04,6.01],[1,2.02,39.86],[2,2,10]],"batl":[[0,2.06,42.78]],"ltp":2.04,"tv":1185.0,"id":7412952}]}]}
{"op":"mcm","clk":"1004121467","pt":1580620803916,"mc":[{"id":"1.168209731","rc":[{"batl":[[0,1.96,2.5]],"ltp":1.94,"tv":1925.94,"id":8174357},{"batb":[[0,2.02,39.86],[1,2,10],[2,1.81,330.47]],"batl":[[0,2.06,48.78]],"ltp":2.04,"tv":1185.0,"id":7412952}]}]}
{"op":"mcm","clk":"1004121520","pt":1580620804944,"mc":[{"id":"1.168209731","rc":[{"batl":[[0,1.96,7.52]],"ltp":1.94,"tv":1925.94,"id":8174357},{"batb":[[0,2.04,6.02],[1,2.02,39.86],[2,2,10]],"batl":[[0,2.06,42.78]],"ltp":2.04,"tv":1185.0,"id":7412952}]}]}
{"op":"mcm","clk":"1004121564","pt":1580620805825,"mc":[{"id":"1.168209731","rc":[{"batl":[[0,1.96,7.53]],"ltp":1.94,"tv":1925.94,"id":8174357},{"batb":[[0,2.04,6.03]],"ltp":2.04,"tv":1185.0,"id":7412952}]}]}
{"op":"mcm","clk":"1004121614","pt":1580620806852,"mc":[{"id":"1.168209731","rc":[{"batl":[[0,1.96,2.5]],"ltp":1.94,"tv":1925.94,"id":8174357},{"batb":[[0,2.02,39.86],[1,2,10],[2,1.81,330.47]],"batl":[[0,2.06,48.78]],"ltp":2.04,"tv":1185.0,"id":7412952}]}]}
{"op":"mcm","clk":"1004121675","pt":1580620807834,"mc":[{"id":"1.168209731","rc":[{"batl":[[0,1.96,7.54]],"ltp":1.94,"tv":1925.94,"id":8174357},{"batb":[[0,2.04,6.04],[1,2.02,39.86],[2,2,10]],"batl":[[0,2.06,42.78]],"ltp":2.04,"tv":1185.0,"id":7412952}]}]}
{"op":"mcm","clk":"1004121732","pt":1580620808861,"mc":[{"id":"1.168209731","rc":[{"batl":[[0,1.96,2.5]],"ltp":1.94,"tv":1925.94,"id":8174357},{"batb":[[0,2.02,39.86],[1,2,10],[2,1.81,330.47]],"batl":[[0,2.06,48.78]],"ltp":2.04,"tv":1185.0,"id":7412952}]}]}
{"op":"mcm","clk":"1004121783","pt":1580620809842,"mc":[{"id":"1.168209731","rc":[{"batl":[[0,1.96,7.55]],"ltp":1.94,"tv":1925.94,"id":8174357},{"batb":[[0,2.04,6.05],[1,2.02,39.86],[2,2,10]],"batl":[[0,2.06,42.78]],"ltp":2.04,"tv":1185.0,"id":7412952}]}]}
{"op":"mcm","clk":"1004121848","pt":1580620810865,"mc":[{"id":"1.168209731","rc":[{"batl":[[0,1.96,2.5]],"ltp":1.94,"tv":1925.94,"id":8174357},{"batb":[[0,2.02,39.86],[1,2,10],[2,1.81,330.47]],"batl":[[0,2.06,48.78]],"ltp":2.04,"tv":1185.0,"id":7412952}]}]}
{"op":"mcm","clk":"1004121903","pt":1580620811947,"mc":[{"id":"1.168209731","rc":[{"batl":[[0,1.96,7.56]],"ltp":1.94,"tv":1925.94,"id":8174357},{"batb":[[0,2.04,6.06],[1,2.02,39.86],[2,2,10]],"batl":[[0,2.06,42.78]],"ltp":2.04,"tv":1185.0,"id":7412952}]}]}
{"op":"mcm","clk":"1004121945","pt":1580620812819,"mc":[{"id":"1.168209731","rc":[{"batl":[[0,1.96,2.5]],"ltp":1.94,"tv":1925.94,"id":8174357},{"batb":[[0,2.02,39.86],[1,2,10],[2,1.81,330.47]],"batl":[[0,2.06,48.78]],"ltp":2.04,"tv":1185.0,"id":7412952}]}]}
{"op":"mcm","clk":"1004121985","pt":1580620813844,"mc":[{"id":"1.168209731","rc":[{"batl":[[0,1.96,7.57]],"ltp":1.94,"tv":1925.94,"id":8174357},{"batb":[[0,2.04,6.07],[1,2.02,39.86],[2,2,10]],"batl":[[0,2.06,42.78]],"ltp":2.04,"tv":1185.0,"id":7412952}]}]}
{"op":"mcm","clk":"1004122034","pt":1580620814828,"mc":[{"id":"1.168209731","rc":[{"batl":[[0,1.96,2.5]],"ltp":1.94,"tv":1925.94,"id":8174357},{"batb":[[0,2.02,39.86],[1,2,10],[2,1.81,330.47]],"batl":[[0,2.06,48.78]],"ltp":2.04,"tv":1185.0,"id":7412952}]}]}
{"op":"mcm","clk":"1004122083","pt":1580620815856,"mc":[{"id":"1.168209731","rc":[{"batl":[[0,1.96,7.58]],"ltp":1.94,"tv":1925.94,"id":8174357},{"batb":[[0,2.04,6.08],[1,2.02,39.86],[2,2,10]],"batl":[[0,2.06,42.78]],"ltp":2.04,"tv":1185.0,"id":7412952}]}]}
{"op":"mcm","clk":"1004122129","pt":1580620816831,"mc":[{"id":"1.168209731","rc":[{"batl":[[0,1.96,2.5]],"ltp":1.94,"tv":1925.94,"id":8174357},{"batb":[[0,2.02,39.86],[1,2,10],[2,1.81,330.47]],"batl":[[0,2.06,48.78]],"ltp":2.04,"tv":1185.0,"id":7412952}]}]}
{"op":"mcm","clk":"1004122182","pt":1580620817860,"mc":[{"id":"1.168209731","rc":[{"batl":[[0,1.96,7.59]],"ltp":1.94,"tv":1925.94,"id":8174357},{"batb":[[0,2.04,6.09],[1,2.02,39.86],[2,2,10]],"batl":[[0,2.06,42.78]],"ltp":2.04,"tv":1185.0,"id":7412952}]}]}
{"op":"mcm","clk":"1004122237","pt":1580620818838,"mc":[{"id":"1.168209731","rc":[{"batl":[[0,1.96,2.5]],"ltp":1.94,"tv":1925.94,"id":8174357},{"batb":[[0,2.02,39.86],[1,2,10],[2,1.81,330.47]],"batl":[[0,2.06,48.78]],"ltp":2.04,"tv":1185.0,"id":7412952}]}]}
{"op":"mcm","clk":"1004122290","pt":1580620819868,"mc":[{"id":"1.168209731","rc":[{"batl":[[0,1.96,7.6]],"ltp":1.94,"tv":1925.94,"id":8174357},{"batb":[[0,2.04,6.1],[1,2.02,39.86],[2,2,10]],"batl":[[0,2.06,42.78]],"ltp":2.04,"tv":1185.0,"id":7412952}]}]}
{"op":"mcm","clk":"1004122348","pt":1580620820847,"mc":[{"id":"1.168209731","rc":[{"batl":[[0,1.96,2.5]],"ltp":1.94,"tv":1925.94,"id":8174357},{"batb":[[0,2.02,39.86],[1,2,10],[2,1.81,330.47]],"batl":[[0,2.06,48.78]],"ltp":2.04,"tv":1185.0,"id":7412952}]}]}
{"op":"mcm","clk":"1004122402","pt":1580620821873,"mc":[{"id":"1.168209731","rc":[{"batl":[[0,1.96,7.61]],"ltp":1.94,"tv":1925.94,"id":8174357},{"batb":[[0,2.04,6.11],[1,2.02,39.86],[2,2,10]],"batl":[[0,2.06,42.78]],"ltp":2.04,"tv":1185.0,"id":7412952}]}]}
{"op":"mcm","clk":"1004122465","pt":1580620822854,"mc":[{"id":"1.168209731","rc":[{"batl":[[0,1.96,2.5]],"ltp":1.94,"tv":1925.94,"id":8174357},{"batb":[[0,2.02,39.86],[1,2,10],[2,1.81,330.47]],"batl":[[0,2.06,48.78]],"ltp":2.04,"tv":1185.0,"id":7412952}]}]}
{"op":"mcm","clk":"1004122512","pt":1580620823891,"mc":[{"id":"1.168209731","rc":[{"batl":[[0,1.96,7.63]],"ltp":1.94,"tv":1925.94,"id":8174357},{"batb":[[0,2.04,6.13],[1,2.02,39.86],[2,2,10]],"batl":[[0,2.06,42.78]],"ltp":2.04,"tv":1185.0,"id":7412952}]}]}
{"op":"mcm","clk":"1004122555","pt":1580620824854,"mc":[{"id":"1.168209731","rc":[{"batl":[[0,1.96,2.5]],"ltp":1.94,"tv":1925.94,"id":8174357},{"batb":[[0,2.02,39.86],[1,2,10],[2,1.81,330.47]],"batl":[[0,2.06,48.78]],"ltp":2.04,"tv":1185.0,"id":7412952}]}]}
{"op":"mcm","clk":"1004122600","pt":1580620825882,"mc":[{"id":"1.168209731","rc":[{"batl":[[0,1.96,7.64]],"ltp":1.94,"tv":1925.94,"id":8174357},{"batb":[[0,2.04,6.14],[1,2.02,39.86],[2,2,10]],"batl":[[0,2.06,42.78]],"ltp":2.04,"tv":1185.0,"id":7412952}]}]}
{"op":"mcm","clk":"1004122662","pt":1580620826859,"mc":[{"id":"1.168209731","rc":[{"batl":[[0,1.96,2.5]],"ltp":1.94,"tv":1925.94,"id":8174357},{"batb":[[0,2.02,39.86],[1,2,10],[2,1.81,330.47]],"batl":[[0,2.06,48.78]],"ltp":2.04,"tv":1185.0,"id":7412952}]}]}
{"op":"mcm","clk":"1004122710","pt":1580620827883,"mc":[{"id":"1.168209731","rc":[{"batl":[[0,1.96,7.65]],"ltp":1.94,"tv":1925.94,"id":8174357},{"batb":[[0,2.04,6.15],[1,2.02,39.86],[2,2,10]],"batl":[[0,2.06,42.78]],"ltp":2.04,"tv":1185.0,"id":7412952}]}]}
{"op":"mcm","clk":"1004122765","pt":1580620828859,"mc":[{"id":"1.168209731","rc":[{"batl":[[0,1.96,2.5]],"ltp":1.94,"tv":1925.94,"id":8174357},{"batb":[[0,2.02,39.86],[1,2,10],[2,1.81,330.47]],"batl":[[0,2.06,48.78]],"ltp":2.04,"tv":1185.0,"id":7412952}]}]}
{"op":"mcm","clk":"1004122820","pt":1580620829888,"mc":[{"id":"1.168209731","rc":[{"batl":[[0,1.96,7.66]],"ltp":1.94,"tv":1925.94,"id":8174357},{"batb":[[0,2.04,6.16],[1,2.02,39.86],[2,2,10]],"batl":[[0,2.06,42.78]],"ltp":2.04,"tv":1185.0,"id":7412952}]}]}
{"op":"mcm","clk":"1004122872","pt":1580620830866,"mc":[{"id":"1.168209731","rc":[{"batl":[[0,1.96,2.5]],"ltp":1.94,"tv":1925.94,"id":8174357},{"batb":[[0,2.02,39.86],[1,2,10],[2,1.81,330.47]],"batl":[[0,2.06,48.78]],"ltp":2.04,"tv":1185.0,"id":7412952}]}]}
{"op":"mcm","clk":"1004122926","pt":1580620831892,"mc":[{"id":"1.168209731","rc":[{"batl":[[0,1.96,7.67]],"ltp":1.94,"tv":1925.94,"id":8174357},{"batb":[[0,2.04,6.17],[1,2.02,39.86],[2,2,10]],"batl":[[0,2.06,42.78]],"ltp":2.04,"tv":1185.0,"id":7412952}]}]}
{"op":"mcm","clk":"1004122981","pt":1580620832872,"mc":[{"id":"1.168209731","rc":[{"batl":[[0,1.96,2.5]],"ltp":1.94,"tv":1925.94,"id":8174357},{"batb":[[0,2.02,39.86],[1,2,10],[2,1.81,330.47]],"batl":[[0,2.06,48.78]],"ltp":2.04,"tv":1185.0,"id":7412952}]}]}
{"op":"mcm","clk":"1004123046","pt":1580620833849,"mc":[{"id":"1.168209731","rc":[{"batl":[[0,1.96,7.68]],"ltp":1.94,"tv":1925.94,"id":8174357},{"batb":[[0,2.04,6.18],[1,2.02,39.86],[2,2,10]],"batl":[[0,2.06,42.78]],"ltp":2.04,"tv":1185.0,"id":7412952}]}]}
{"op":"mcm","clk":"1004123105","pt":1580620834878,"mc":[{"id":"1.168209731","rc":[{"batl":[[0,1.96,2.5]],"ltp":1.94,"tv":1925.94,"id":8174357},{"batb":[[0,2.02,39.86],[1,2,10],[2,1.81,330.47]],"batl":[[0,2.06,48.78]],"ltp":2.04,"tv":1185.0,"id":7412952}]}]}
{"op":"mcm","clk":"1004123170","pt":1580620835875,"mc":[{"id":"1.168209731","rc":[{"batl":[[0,1.96,7.69]],"ltp":1.94,"tv":1925.94,"id":8174357},{"batb":[[0,2.04,6.19],[1,2.02,39.86],[2,2,10]],"batl":[[0,2.06,42.78]],"ltp":2.04,"tv":1185.0,"id":7412952}]}]}
{"op":"mcm","clk":"1004123223","pt":1580620836900,"mc":[{"id":"1.168209731","rc":[{"batl":[[0,1.96,2.5]],"ltp":1.94,"tv":1925.94,"id":8174357},{"batb":[[0,2.02,39.86],[1,2,10],[2,1.81,330.47]],"batl":[[0,2.06,48.78]],"ltp":2.04,"tv":1185.0,"id":7412952}]}]}
{"op":"mcm","clk":"1004123288","pt":1580620837878,"mc":[{"id":"1.168209731","rc":[{"batl":[[0,1.96,7.7]],"ltp":1.94,"tv":1925.94,"id":8174357},{"batb":[[0,2.04,6.2],[1,2.02,39.86],[2,2,10]],"batl":[[0,2.06,42.78]],"ltp":2.04,"tv":1185.0,"id":7412952}]}]}
{"op":"mcm","clk":"1004123350","pt":1580620838856,"mc":[{"id":"1.168209731","rc":[{"batl":[[0,1.96,2.5]],"ltp":1.94,"tv":1925.94,"id":8174357},{"batb":[[0,2.02,39.86],[1,2,10],[2,1.81,330.47]],"batl":[[0,2.06,48.78]],"ltp":2.04,"tv":1185.0,"id":7412952}]}]}
{"op":"mcm","clk":"1004123412","pt":1580620839879,"mc":[{"id":"1.168209731","rc":[{"batl":[[0,1.96,7.71]],"ltp":1.94,"tv":1925.94,"id":8174357},{"batb":[[0,2.04,6.21],[1,2.02,39.86],[2,2,10]],"batl":[[0,2.06,42.78]],"ltp":2.04,"tv":1185.0,"id":7412952}]}]}
{"op":"mcm","clk":"1004123453","pt":1580620840909,"mc":[{"id":"1.168209731","rc":[{"batl":[[0,1.96,2.5]],"ltp":1.94,"tv":1925.94,"id":8174357},{"batb":[[0,2.02,39.86],[1,2,10],[2,1.81,330.47]],"batl":[[0,2.06,48.78]],"ltp":2.04,"tv":1185.0,"id":7412952}]}]}
{"op":"mcm","clk":"1004123497","pt":1580620841887,"mc":[{"id":"1.168209731","rc":[{"batl":[[0,1.96,7.72]],"ltp":1.94,"tv":1925.94,"id":8174357},{"batb":[[0,2.04,6.22],[1,2.02,39.86],[2,2,10]],"batl":[[0,2.06,42.78]],"ltp":2.04,"tv":1185.0,"id":7412952}]}]}
{"op":"mcm","clk":"1004123539","pt":1580620842863,"mc":[{"id":"1.168209731","rc":[{"batl":[[0,1.96,2.5]],"ltp":1.94,"tv":1925.94,"id":8174357},{"batb":[[0,2.02,39.86],[1,2,10],[2,1.81,330.47]],"batl":[[0,2.06,48.78]],"ltp":2.04,"tv":1185.0,"id":7412952}]}]}
{"op":"mcm","clk":"1004123593","pt":1580620843892,"mc":[{"id":"1.168209731","rc":[{"batl":[[0,1.96,7.74]],"ltp":1.94,"tv":1925.94,"id":8174357},{"batb":[[0,2.04,6.24],[1,2.02,39.86],[2,2,10]],"batl":[[0,2.06,42.78]],"ltp":2.04,"tv":1185.0,"id":7412952}]}]}
{"op":"mcm","clk":"1004123649","pt":1580620844867,"mc":[{"id":"1.168209731","rc":[{"batl":[[0,1.96,2.5]],"ltp":1.94,"tv":1925.94,"id":8174357},{"batb":[[0,2.02,39.86],[1,2,10],[2,1.81,330.47]],"batl":[[0,2.06,48.78]],"ltp":2.04,"tv":1185.0,"id":7412952}]}]}
{"op":"mcm","clk":"1004123691","pt":1580620845895,"mc":[{"id":"1.168209731","rc":[{"batl":[[0,1.96,7.75]],"ltp":1.94,"tv":1925.94,"id":8174357},{"batb":[[0,2.04,6.25],[1,2.02,39.86],[2,2,10]],"batl":[[0,2.06,42.78]],"ltp":2.04,"tv":1185.0,"id":7412952}]}]}
{"op":"mcm","clk":"1004123702","pt":1580620846100,"mc":[{"id":"1.168209731","rc":[{"batl":[[0,1.96,2.5]],"ltp":1.94,"tv":1925.94,"id":8174357},{"batb":[[0,2.04,12.5]],"ltp":2.04,"tv":1185.0,"id":7412952}]}]}
{"op":"mcm","clk":"1004124632","pt":1580620866906,"mc":[{"id":"1.168209731","rc":[{"batb":[[0,2.02,39.86],[1,2,10],[2,1.81,330.47]],"batl":[[0,2.06,48.78]],"ltp":2.04,"tv":1185.0,"id":7412952}]}]}
{"op":"mcm","clk":"1004124688","pt":1580620867938,"mc":[{"id":"1.168209731","rc":[{"batl":[[0,1.96,7.54],[1,2,68.06],[2,2.3,10.13]],"ltp":1.94,"tv":1925.94,"id":8174357},{"batb":[[0,2.04,6],[1,2.02,39.86],[2,2,10]],"batl":[[0,2.06,42.78]],"ltp":2.04,"tv":1185.0,"id":7412952}]}]}
{"op":"mcm","clk":"1004124744","pt":1580620868917,"mc":[{"id":"1.168209731","rc":[{"batl":[[0,1.96,2.5]],"ltp":1.94,"tv":1925.94,"id":8174357},{"batb":[[0,2.02,39.86],[1,2,10],[2,1.81,330.47]],"batl":[[0,2.06,48.78]],"ltp":2.04,"tv":1185.0,"id":7412952}]}]}
{"op":"mcm","clk":"1004124785","pt":1580620869794,"mc":[{"id":"1.168209731","rc":[{"batl":[[0,1.96,7.55],[1,1.97,5.05],[2,2,68.06]],"ltp":1.94,"tv":1925.94,"id":8174357},{"batb":[[0,2.04,6.05],[1,2.02,39.86],[2,2,10]],"batl":[[0,2.06,42.78]],"ltp":2.04,"tv":1185.0,"id":7412952}]}]}
{"op":"mcm","clk":"1004124827","pt":1580620870827,"mc":[{"id":"1.168209731","rc":[{"batl":[[0,1.96,2.5]],"ltp":1.94,"tv":1925.94,"id":8174357},{"batb":[[0,2.02,39.86],[1,2,10],[2,1.81,330.47]],"batl":[[0,2.06,48.78]],"ltp":2.04,"tv":1185.0,"id":7412952}]}]}
{"op":"mcm","clk":"1004124878","pt":1580620871809,"mc":[{"id":"1.168209731","rc":[{"batl":[[0,1.96,7.56]],"ltp":1.94,"tv":1925.94,"id":8174357},{"batb":[[0,2.04,6.06],[1,2.02,39.86],[2,2,10]],"batl":[[0,2.06,42.78]],"ltp":2.04,"tv":1185.0,"id":7412952}]}]}
{"op":"mcm","clk":"1004124941","pt":1580620872840,"mc":[{"id":"1.168209731","rc":[{"batl":[[0,1.96,2.5]],"ltp":1.94,"tv":1925.94,"id":8174357},{"batb":[[0,2.02,39.86],[1,2,10],[2,1.81,330.47]],"batl":[[0,2.06,48.78]],"ltp":2.04,"tv":1185.0,"id":7412952}]}]}
{"op":"mcm","clk":"1004124985","pt":1580620873818,"mc":[{"id":"1.168209731","rc":[{"batl":[[0,1.96,7.57]],"ltp":1.94,"tv":1925.94,"id":8174357},{"batb":[[0,2.04,6.07],[1,2.02,39.86],[2,2,10]],"batl":[[0,2.06,42.78]],"ltp":2.04,"tv":1185.0,"id":7412952}]}]}
{"op":"mcm","clk":"1004125028","pt":1580620874846,"mc":[{"id":"1.168209731","rc":[{"batl":[[0,1.96,2.5]],"ltp":1.94,"tv":1925.94,"id":8174357},{"batb":[[0,2.02,39.86],[1,2,10],[2,1.81,330.47]],"batl":[[0,2.06,48.78]],"ltp":2.04,"tv":1185.0,"id":7412952}]}]}
{"op":"mcm","clk":"1004125087","pt":1580620875827,"mc":[{"id":"1.168209731","rc":[{"batl":[[0,1.96,7.58]],"ltp":1.94,"tv":1925.94,"id":8174357},{"batb":[[0,2.04,6.08],[1,2.02,39.86],[2,2,10]],"batl":[[0,2.06,42.78]],"ltp":2.04,"tv":1185.0,"id":7412952}]}]}
{"op":"mcm","clk":"1004125140","pt":1580620876810,"mc":[{"id":"1.168209731","rc":[{"batl":[[0,1.96,2.5]],"ltp":1.94,"tv":1925.94,"id":8174357},{"batb":[[0,2.02,39.86],[1,2,10],[2,1.81,330.47]],"batl":[[0,2.06,48.78]],"ltp":2.04,"tv":1185.0,"id":7412952}]}]}
{"op":"mcm","clk":"1004125189","pt":1580620877841,"mc":[{"id":"1.168209731","rc":[{"batl":[[0,1.96,7.59]],"ltp":1.94,"tv":1925.94,"id":8174357},{"batb":[[0,2.04,6.09],[1,2.02,39.86],[2,2,10]],"batl":[[0,2.06,42.78]],"ltp":2.04,"tv":1185.0,"id":7412952}]}]}
{"op":"mcm","clk":"1004125246","pt":1580620878823,"mc":[{"id":"1.168209731","rc":[{"batl":[[0,1.96,2.5]],"ltp":1.94,"tv":1925.94,"id":8174357},{"batb":[[0,2.02,39.86],[1,2,10],[2,1.81,330.47]],"batl":[[0,2.06,48.78]],"ltp":2.04,"tv":1185.0,"id":7412952}]}]}
{"op":"mcm","clk":"1004125293","pt":1580620879799,"mc":[{"id":"1.168209731","rc":[{"batl":[[0,1.96,7.6]],"ltp":1.94,"tv":1925.94,"id":8174357},{"batb":[[0,2.04,6.1],[1,2.02,39.86],[2,2,10]],"batl":[[0,2.06,42.78]],"ltp":2.04,"tv":1185.0,"id":7412952}]}]}
{"op":"mcm","clk":"1004125335","pt":1580620880830,"mc":[{"id":"1.168209731","rc":[{"batl":[[0,1.96,2.5]],"ltp":1.94,"tv":1925.94,"id":8174357},{"batb":[[0,2.02,39.86],[1,2,10],[2,1.81,330.47]],"batl":[[0,2.06,48.78]],"ltp":2.04,"tv":1185.0,"id":7412952}]}]}
{"op":"mcm","clk":"1004125381","pt":1580620881810,"mc":[{"id":"1.168209731","rc":[{"batl":[[0,1.96,7.61]],"ltp":1.94,"tv":1925.94,"id":8174357},{"batb":[[0,2.04,6.11],[1,2.02,39.86],[2,2,10]],"batl":[[0,2.06,42.78]],"ltp":2.04,"tv":1185.0,"id":7412952}]}]}
{"op":"mcm","clk":"1004125434","pt":1580620882941,"mc":[{"id":"1.168209731","rc":[{"batl":[[0,1.96,7.62]],"ltp":1.94,"tv":1925.94,"id":8174357},{"batb":[[0,2.04,6.12]],"ltp":2.04,"tv":1185.0,"id":7412952}]}]}
{"op":"mcm","clk":"1004125478","pt":1580620883921,"mc":[{"id":"1.168209731","rc":[{"batl":[[0,1.96,2.5]],"ltp":1.94,"tv":1925.94,"id":8174357},{"batb":[[0,2.02,39.86],[1,2,10],[2,1.81,330.47]],"batl":[[0,2.06,48.78]],"ltp":2.04,"tv":1185.0,"id":7412952}]}]}
{"op":"mcm","clk":"1004125521","pt":1580620884946,"mc":[{"id":"1.168209731","rc":[{"batl":[[0,1.96,7.63]],"ltp":1.94,"tv":1925.94,"id":8174357},{"batb":[[0,2.04,6.13],[1,2.02,39.86],[2,2,10]],"batl":[[0,2.06,42.78]],"ltp":2.04,"tv":1185.0,"id":7412952}]}]}
{"op":"mcm","clk":"1004125566","pt":1580620885926,"mc":[{"id":"1.168209731","rc":[{"batl":[[0,1.96,2.5]],"ltp":1.94,"tv":1925.94,"id":8174357},{"batb":[[0,2.02,39.86],[1,2,10],[2,1.81,330.47]],"batl":[[0,2.06,48.78]],"ltp":2.04,"tv":1185.0,"id":7412952}]}]}
{"op":"mcm","clk":"1004125612","pt":1580620886912,"mc":[{"id":"1.168209731","rc":[{"batl":[[0,1.96,7.64]],"ltp":1.94,"tv":1925.94,"id":8174357},{"batb":[[0,2.04,6.14],[1,2.02,39.86],[2,2,10]],"batl":[[0,2.06,42.78]],"ltp":2.04,"tv":1185.0,"id":7412952}]}]}
{"op":"mcm","clk":"1004125659","pt":1580620887946,"mc":[{"id":"1.168209731","rc":[{"batl":[[0,1.96,7.65]],"ltp":1.94,"tv":1925.94,"id":8174357},{"batb":[[0,2.04,6.15]],"ltp":2.04,"tv":1185.0,"id":7412952}]}]}
{"op":"mcm","clk":"1004125713","pt":1580620888927,"mc":[{"id":"1.168209731","rc":[{"batl":[[0,1.96,2.5]],"ltp":1.94,"tv":1925.94,"id":8174357},{"batb":[[0,2.02,39.86],[1,2,10],[2,1.81,330.47]],"batl":[[0,2.06,48.78]],"ltp":2.04,"tv":1185.0,"id":7412952}]}]}
{"op":"mcm","clk":"1004125764","pt":1580620889955,"mc":[{"id":"1.168209731","rc":[{"batl":[[0,1.96,7.66]],"ltp":1.94,"tv":1925.94,"id":8174357},{"batb":[[0,2.04,6.16],[1,2.02,39.86],[2,2,10]],"batl":[[0,2.06,42.78]],"ltp":2.04,"tv":1185.0,"id":7412952}]}]}
{"op":"mcm","clk":"1004125802","pt":1580620890835,"mc":[{"id":"1.168209731","rc":[{"batl":[[0,1.96,2.5]],"ltp":1.94,"tv":1925.94,"id":8174357},{"batb":[[0,2.02,39.86],[1,2,10],[2,1.81,330.47]],"batl":[[0,2.06,48.78]],"ltp":2.04,"tv":1185.0,"id":7412952}]}]}
{"op":"mcm","clk":"1004125847","pt":1580620891865,"mc":[{"id":"1.168209731","rc":[{"batl":[[0,1.96,7.67]],"ltp":1.94,"tv":1925.94,"id":8174357},{"batl":[[0,2.06,54.78]],"ltp":2.04,"tv":1185.0,"id":7412952}]}]}
{"op":"mcm","clk":"1004125896","pt":1580620892950,"mc":[{"id":"1.168209731","rc":[{"batl":[[0,1.96,7.68],[1,1.97,5]],"ltp":1.94,"tv":1925.94,"id":8174357},{"batb":[[0,2.04,6.18],[1,2.02,39.86],[2,2,10]],"batl":[[0,2.06,42.78]],"ltp":2.04,"tv":1185.0,"id":7412952}]}]}
{"op":"mcm","clk":"1004125938","pt":1580620893934,"mc":[{"id":"1.168209731","rc":[{"batl":[[0,1.96,2.5]],"ltp":1.94,"tv":1925.94,"id":8174357},{"batb":[[0,2.02,39.86],[1,2,10],[2,1.81,330.47]],"batl":[[0,2.06,48.78]],"ltp":2.04,"tv":1185.0,"id":7412952}]}]}
{"op":"mcm","clk":"1004126041","pt":1580620895941,"mc":[{"id":"1.168209731","rc":[{"batl":[[0,1.96,12.88]],"ltp":1.94,"tv":1925.94,"id":8174357},{"batb":[[0,2.04,12.38],[1,2.02,39.86],[2,2,10]],"batl":[[0,2.06,42.78]],"ltp":2.04,"tv":1185.0,"id":7412952}]}]}
{"op":"mcm","clk":"1004126082","pt":1580620896761,"mc":[{"id":"1.168209731","rc":[{"batl":[[0,1.96,7.7]],"ltp":1.94,"tv":1925.94,"id":8174357},{"batb":[[0,2.04,6.2]],"ltp":2.04,"tv":1185.0,"id":7412952}]}]}
{"op":"mcm","clk":"1004126126","pt":1580620897738,"mc":[{"id":"1.168209731","rc":[{"batl":[[0,1.96,2.5]],"ltp":1.94,"tv":1925.94,"id":8174357},{"batb":[[0,2.02,39.86],[1,2,10],[2,1.81,330.47]],"batl":[[0,2.06,48.78]],"ltp":2.04,"tv":1185.0,"id":7412952}]}]}
{"op":"mcm","clk":"1004126179","pt":1580620898763,"mc":[{"id":"1.168209731","rc":[{"batl":[[0,1.96,7.71]],"ltp":1.94,"tv":1925.94,"id":8174357},{"batb":[[0,2.04,6.21],[1,2.02,39.86],[2,2,10]],"batl":[[0,2.06,42.78]],"ltp":2.04,"tv":1185.0,"id":7412952}]}]}
{"op":"mcm","clk":"1004126280","pt":1580620900769,"mc":[{"id":"1.168209731","rc":[{"batl":[[0,1.96,7.72]],"ltp":1.94,"tv":1925.94,"id":8174357},{"batb":[[0,2.04,6.22]],"ltp":2.04,"tv":1185.0,"id":7412952}]}]}
{"op":"mcm","clk":"1004126354","pt":1580620901955,"mc":[{"id":"1.168209731","rc":[{"batl":[[0,1.96,7.73]],"ltp":1.94,"tv":1925.94,"id":8174357},{"batb":[[0,2.04,6.23]],"ltp":2.04,"tv":1185.0,"id":7412952}]}]}
{"op":"mcm","clk":"1004126441","pt":1580620903759,"mc":[{"id":"1.168209731","rc":[{"batl":[[0,1.96,2.5]],"ltp":1.94,"tv":1925.94,"id":8174357},{"batb":[[0,2.02,39.86],[1,2,10],[2,1.81,330.47]],"batl":[[0,2.06,48.78]],"ltp":2.04,"tv":1185.0,"id":7412952}]}]}
{"op":"mcm","clk":"1004126613","pt":1580620906855,"mc":[{"id":"1.168209731","rc":[{"batl":[[0,1.96,7.75]],"ltp":1.94,"tv":1925.94,"id":8174357},{"batb":[[0,2.04,6.25],[1,2.02,39.86],[2,2,10]],"batl":[[0,2.06,42.78]],"ltp":2.04,"tv":1185.0,"id":7412952}]}]}
{"op":"mcm","clk":"1004126669","pt":1580620907883,"mc":[{"id":"1.168209731","rc":[{"batl":[[0,1.96,2.5]],"ltp":1.94,"tv":1925.94,"id":8174357},{"batb":[[0,2.02,39.86],[1,2,10],[2,1.81,330.47]],"batl":[[0,2.06,48.78]],"ltp":2.04,"tv":1185.0,"id":7412952}]}]}
{"op":"mcm","clk":"1004126722","pt":1580620908868,"mc":[{"id":"1.168209731","rc":[{"batl":[[0,1.96,7.76]],"ltp":1.94,"tv":1925.94,"id":8174357},{"batb":[[0,2.04,6.26],[1,2.02,39.86],[2,2,10]],"batl":[[0,2.06,42.78]],"ltp":2.04,"tv":1185.0,"id":7412952}]}]}
{"op":"mcm","clk":"1004126790","pt":1580620909894,"mc":[{"id":"1.168209731","rc":[{"batl":[[0,1.96,2.5]],"ltp":1.94,"tv":1925.94,"id":8174357},{"batb":[[0,2.02,39.86],[1,2,10],[2,1.81,330.47]],"batl":[[0,2.06,48.78]],"ltp":2.04,"tv":1185.0,"id":7412952}]}]}
{"op":"mcm","clk":"1004126838","pt":1580620910883,"mc":[{"id":"1.168209731","rc":[{"batl":[[0,1.96,7.77]],"ltp":1.94,"tv":1925.94,"id":8174357},{"batb":[[0,2.04,6.27],[1,2.02,39.86],[2,2,10]],"batl":[[0,2.06,42.78]],"ltp":2.04,"tv":1185.0,"id":7412952}]}]}
{"op":"mcm","clk":"1004126900","pt":1580620911867,"mc":[{"id":"1.168209731","rc":[{"batl":[[0,1.96,2.5]],"ltp":1.94,"tv":1925.94,"id":8174357},{"batb":[[0,2.02,39.86],[1,2,10],[2,1.81,330.47]],"batl":[[0,2.06,48.78]],"ltp":2.04,"tv":1185.0,"id":7412952}]}]}
{"op":"mcm","clk":"1004126944","pt":1580620912895,"mc":[{"id":"1.168209731","rc":[{"batl":[[0,1.96,7.79]],"ltp":1.94,"tv":1925.94,"id":8174357},{"batb":[[0,2.04,6.29],[1,2.02,39.86],[2,2,10]],"ltp":2.04,"tv":1185.0,"id":7412952}]}]}
{"op":"mcm","clk":"1004127005","pt":1580620913874,"mc":[{"id":"1.168209731","rc":[{"batl":[[0,2.06,42.78]],"ltp":2.04,"tv":1185.0,"id":7412952}]}]}
{"op":"mcm","clk":"1004127046","pt":1580620914795,"mc":[{"id":"1.168209731","rc":[{"batl":[[0,1.96,2.5]],"ltp":1.94,"tv":1925.94,"id":8174357},{"batb":[[0,2.02,39.86],[1,2,10],[2,1.81,330.47]],"batl":[[0,2.06,48.78]],"ltp":2.04,"tv":1185.0,"id":7412952}]}]}
{"op":"mcm","clk":"1004127114","pt":1580620915779,"mc":[{"id":"1.168209731","rc":[{"batl":[[0,1.96,7.8]],"ltp":1.94,"tv":1925.94,"id":8174357},{"batb":[[0,2.04,6.3],[1,2.02,39.86],[2,2,10]],"batl":[[0,2.06,42.78]],"ltp":2.04,"tv":1185.0,"id":7412952}]}]}
{"op":"mcm","clk":"1004127165","pt":1580620916805,"mc":[{"id":"1.168209731","rc":[{"batl":[[0,1.96,2.5]],"ltp":1.94,"tv":1925.94,"id":8174357},{"batb":[[0,2.02,39.86],[1,2,10],[2,1.81,330.47]],"batl":[[0,2.06,48.78]],"ltp":2.04,"tv":1185.0,"id":7412952}]}]}
{"op":"mcm","clk":"1004127222","pt":1580620917783,"mc":[{"id":"1.168209731","rc":[{"batl":[[0,1.96,7.81]],"ltp":1.94,"tv":1925.94,"id":8174357},{"batb":[[0,2.04,6.31],[1,2.02,39.86],[2,2,10]],"batl":[[0,2.06,42.78]],"ltp":2.04,"tv":1185.0,"id":7412952}]}]}
{"op":"mcm","clk":"1004127269","pt":1580620918763,"mc":[{"id":"1.168209731","rc":[{"batl":[[0,1.96,2.5]],"ltp":1.94,"tv":1925.94,"id":8174357},{"batb":[[0,2.02,39.86],[1,2,10],[2,1.81,330.47]],"batl":[[0,2.06,48.78]],"ltp":2.04,"tv":1185.0,"id":7412952}]}]}
{"op":"mcm","clk":"1004127331","pt":1580620919790,"mc":[{"id":"1.168209731","rc":[{"batl":[[0,1.96,7.82]],"ltp":1.94,"tv":1925.94,"id":8174357},{"batb":[[0,2.04,6.32],[1,2.02,39.86],[2,2,10]],"batl":[[0,2.06,42.78]],"ltp":2.04,"tv":1185.0,"id":7412952}]}]}
{"op":"mcm","clk":"1004127387","pt":1580620920780,"mc":[{"id":"1.168209731","rc":[{"batl":[[0,1.96,2.5]],"ltp":1.94,"tv":1925.94,"id":8174357},{"batb":[[0,2.02,39.86],[1,2,10],[2,1.81,330.47]],"batl":[[0,2.06,48.78]],"ltp":2.04,"tv":1185.0,"id":7412952}]}]}
{"op":"mcm","clk":"1004127511","pt":1580620922888,"mc":[{"id":"1.168209731","rc":[{"batl":[[0,1.96,7.51]],"ltp":1.94,"tv":1925.94,"id":8174357},{"batb":[[0,2.04,6.01],[1,2.02,39.86],[2,2,10]],"batl":[[0,2.06,42.78]],"ltp":2.04,"tv":1185.0,"id":7412952}]}]}
{"op":"mcm","clk":"1004127569","pt":1580620923865,"mc":[{"id":"1.168209731","rc":[{"batl":[[0,1.96,2.5]],"ltp":1.94,"tv":1925.94,"id":8174357},{"batb":[[0,2.02,39.86],[1,2,10],[2,1.81,330.47]],"batl":[[0,2.06,48.78]],"ltp":2.04,"tv":1185.0,"id":7412952}]}]}
{"op":"mcm","clk":"1004127617","pt":1580620924894,"mc":[{"id":"1.168209731","rc":[{"batl":[[0,1.96,7.52]],"ltp":1.94,"tv":1925.94,"id":8174357},{"batb":[[0,2.04,6.02],[1,2.02,39.86],[2,2,10]],"batl":[[0,2.06,42.78]],"ltp":2.04,"tv":1185.0,"id":7412952}]}]}
{"op":"mcm","clk":"1004127668","pt":1580620925878,"mc":[{"id":"1.168209731","rc":[{"batl":[[0,1.96,2.5]],"ltp":1.94,"tv":1925.94,"id":8174357},{"batb":[[0,2.02,39.86],[1,2,10],[2,1.81,330.47]],"batl":[[0,2.06,48.78]],"ltp":2.04,"tv":1185.0,"id":7412952}]}]}
{"op":"mcm","clk":"1004127717","pt":1580620926909,"mc":[{"id":"1.168209731","rc":[{"batl":[[0,1.96,7.53]],"ltp":1.94,"tv":1925.94,"id":8174357},{"batb":[[0,2.04,6.03],[1,2.02,39.86],[2,2,10]],"batl":[[0,2.06,42.78]],"ltp":2.04,"tv":1185.0,"id":7412952}]}]}
{"op":"mcm","clk":"1004127763","pt":1580620927890,"mc":[{"id":"1.168209731","rc":[{"batl":[[0,1.96,2.5]],"ltp":1.94,"tv":1925.94,"id":8174357},{"batb":[[0,2.02,39.86],[1,2,10],[2,1.81,330.47]],"batl":[[0,2.06,48.78]],"ltp":2.04,"tv":1185.0,"id":7412952}]}]}
{"op":"mcm","clk":"1004127824","pt":1580620928871,"mc":[{"id":"1.168209731","rc":[{"batl":[[0,1.96,7.54]],"ltp":1.94,"tv":1925.94,"id":8174357},{"batb":[[0,2.04,6.04],[1,2.02,39.86],[2,2,10]],"batl":[[0,2.06,42.78]],"ltp":2.04,"tv":1185.0,"id":7412952}]}]}
{"op":"mcm","clk":"1004127867","pt":1580620929908,"mc":[{"id":"1.168209731","rc":[{"batl":[[0,1.96,2.5]],"ltp":1.94,"tv":1925.94,"id":8174357},{"batb":[[0,2.02,39.86],[1,2,10],[2,1.81,330.47]],"batl":[[0,2.06,48.78]],"ltp":2.04,"tv":1185.0,"id":7412952}]}]}
{"op":"mcm","clk":"1004128011","pt":1580620932804,"mc":[{"id":"1.168209731","rc":[{"batl":[[0,2.06,54.78]],"ltp":2.04,"tv":1185.0,"id":7412952}]}]}
{"op":"mcm","clk":"1004128086","pt":1580620933783,"mc":[{"id":"1.168209731","rc":[{"batl":[[0,1.96,7.57]],"ltp":1.94,"tv":1925.94,"id":8174357},{"batb":[[0,2.04,6.07],[1,2.02,39.86],[2,2,10]],"batl":[[0,2.06,42.78]],"ltp":2.04,"tv":1185.0,"id":7412952}]}]}
{"op":"mcm","clk":"1004128137","pt":1580620934808,"mc":[{"id":"1.168209731","rc":[{"batl":[[0,1.96,2.5]],"ltp":1.94,"tv":1925.94,"id":8174357},{"batb":[[0,2.02,39.86],[1,2,10],[2,1.81,330.47]],"batl":[[0,2.06,48.78]],"ltp":2.04,"tv":1185.0,"id":7412952}]}]}
{"op":"mcm","clk":"1004128182","pt":1580620935786,"mc":[{"id":"1.168209731","rc":[{"batl":[[0,1.96,7.58]],"ltp":1.94,"tv":1925.94,"id":8174357},{"batb":[[0,2.04,6.08],[1,2.02,39.86],[2,2,10]],"batl":[[0,2.06,42.78]],"ltp":2.04,"tv":1185.0,"id":7412952}]}]}
{"op":"mcm","clk":"1004128239","pt":1580620936917,"mc":[{"id":"1.168209731","rc":[{"batl":[[0,1.96,2.5]],"ltp":1.94,"tv":1925.94,"id":8174357},{"batb":[[0,2.02,39.86],[1,2,10],[2,1.81,330.47]],"batl":[[0,2.06,48.78]],"ltp":2.04,"tv":1185.0,"id":7412952}]}]}
{"op":"mcm","clk":"1004128289","pt":1580620937896,"mc":[{"id":"1.168209731","rc":[{"batl":[[0,1.96,7.59]],"ltp":1.94,"tv":1925.94,"id":8174357},{"batb":[[0,2.04,6.09],[1,2.02,39.86],[2,2,10]],"batl":[[0,2.06,42.78]],"ltp":2.04,"tv":1185.0,"id":7412952}]}]}
{"op":"mcm","clk":"1004128349","pt":1580620938925,"mc":[{"id":"1.168209731","rc":[{"batl":[[0,1.96,2.5]],"ltp":1.94,"tv":1925.94,"id":8174357},{"batb":[[0,2.02,39.86],[1,2,10],[2,1.81,330.47]],"batl":[[0,2.06,48.78]],"ltp":2.04,"tv":1185.0,"id":7412952}]}]}
{"op":"mcm","clk":"1004128410","pt":1580620939912,"mc":[{"id":"1.168209731","rc":[{"batl":[[0,1.96,7.6]],"ltp":1.94,"tv":1925.94,"id":8174357},{"batb":[[0,2.04,6.1],[1,2.02,39.86],[2,2,10]],"batl":[[0,2.06,42.78]],"ltp":2.04,"tv":1185.0,"id":7412952}]}]}
{"op":"mcm","clk":"1004128469","pt":1580620940897,"mc":[{"id":"1.168209731","rc":[{"batl":[[0,1.96,2.5]],"ltp":1.94,"tv":1925.94,"id":8174357},{"batb":[[0,2.02,39.86],[1,2,10],[2,1.81,330.47]],"batl":[[0,2.06,48.78]],"ltp":2.04,"tv":1185.0,"id":7412952}]}]}
{"op":"mcm","clk":"1004128518","pt":1580620941823,"mc":[{"id":"1.168209731","rc":[{"batl":[[0,1.96,7.61]],"ltp":1.94,"tv":1925.94,"id":8174357},{"batb":[[0,2.04,6.11],[1,2.02,39.86],[2,2,10]],"batl":[[0,2.06,42.78]],"ltp":2.04,"tv":1185.0,"id":7412952}]}]}
{"op":"mcm","clk":"1004128577","pt":1580620942806,"mc":[{"id":"1.168209731","rc":[{"batl":[[0,1.96,2.5]],"ltp":1.94,"tv":1925.94,"id":8174357},{"batb":[[0,2.02,39.86],[1,2,10],[2,1.81,330.47]],"batl":[[0,2.06,48.78]],"ltp":2.04,"tv":1185.0,"id":7412952}]}]}
{"op":"mcm","clk":"1004128640","pt":1580620943834,"mc":[{"id":"1.168209731","rc":[{"batl":[[0,1.96,7.63]],"ltp":1.94,"tv":1925.94,"id":8174357},{"batb":[[0,2.04,6.13],[1,2.02,39.86],[2,2,10]],"batl":[[0,2.06,42.78]],"ltp":2.04,"tv":1185.0,"id":7412952}]}]}
{"op":"mcm","clk":"1004128707","pt":1580620944816,"mc":[{"id":"1.168209731","rc":[{"batl":[[0,1.96,2.5]],"ltp":1.94,"tv":1925.94,"id":8174357},{"batb":[[0,2.02,39.86],[1,2,10],[2,1.81,330.47]],"batl":[[0,2.06,48.78]],"ltp":2.04,"tv":1185.0,"id":7412952}]}]}
{"op":"mcm","clk":"1004128757","pt":1580620945822,"mc":[{"id":"1.168209731","rc":[{"batl":[[0,1.96,7.64]],"ltp":1.94,"tv":1925.94,"id":8174357},{"batb":[[0,2.04,6.14],[1,2.02,39.86],[2,2,10]],"batl":[[0,2.06,42.78]],"ltp":2.04,"tv":1185.0,"id":7412952}]}]}
{"op":"mcm","clk":"1004128810","pt":1580620946804,"mc":[{"id":"1.168209731","rc":[{"batl":[[0,1.96,2.5]],"ltp":1.94,"tv":1925.94,"id":8174357},{"batb":[[0,2.02,39.86],[1,2,10],[2,1.81,330.47]],"batl":[[0,2.06,48.78]],"ltp":2.04,"tv":1185.0,"id":7412952}]}]}
{"op":"mcm","clk":"1004128876","pt":1580620947833,"mc":[{"id":"1.168209731","rc":[{"batl":[[0,1.96,7.65]],"ltp":1.94,"tv":1925.94,"id":8174357},{"batb":[[0,2.04,6.15],[1,2.02,39.86],[2,2,10]],"batl":[[0,2.06,42.78]],"ltp":2.04,"tv":1185.0,"id":7412952}]}]}
{"op":"mcm","clk":"1004128926","pt":1580620948814,"mc":[{"id":"1.168209731","rc":[{"batl":[[0,1.96,2.5]],"ltp":1.94,"tv":1925.94,"id":8174357},{"batb":[[0,2.02,39.86],[1,2,10],[2,1.81,330.47]],"batl":[[0,2.06,48.78]],"ltp":2.04,"tv":1185.0,"id":7412952}]}]}
{"op":"mcm","clk":"1004128979","pt":1580620949842,"mc":[{"id":"1.168209731","rc":[{"batl":[[0,1.96,7.66]],"ltp":1.94,"tv":1925.94,"id":8174357},{"batb":[[0,2.04,6.16],[1,2.02,39.86],[2,2,10]],"batl":[[0,2.06,42.78]],"ltp":2.04,"tv":1185.0,"id":7412952}]}]}
{"op":"mcm","clk":"1004129052","pt":1580620950828,"mc":[{"id":"1.168209731","rc":[{"batl":[[0,1.96,2.5]],"ltp":1.94,"tv":1925.94,"id":8174357},{"batb":[[0,2.02,39.86],[1,2,10],[2,1.81,330.47]],"batl":[[0,2.06,48.78]],"ltp":2.04,"tv":1185.0,"id":7412952}]}]}
{"op":"mcm","clk":"1004129115","pt":1580620951912,"mc":[{"id":"1.168209731","rc":[{"batl":[[0,1.96,7.67]],"ltp":1.94,"tv":1925.94,"id":8174357},{"batb":[[0,2.04,6.17],[1,2.02,39.86],[2,2,10]],"batl":[[0,2.06,42.78]],"ltp":2.04,"tv":1185.0,"id":7412952}]}]}
{"op":"mcm","clk":"1004129158","pt":1580620952940,"mc":[{"id":"1.168209731","rc":[{"batl":[[0,1.96,2.5]],"ltp":1.94,"tv":1925.94,"id":8174357},{"batb":[[0,2.02,39.86],[1,2,10],[2,1.81,330.47]],"batl":[[0,2.06,48.78]],"ltp":2.04,"tv":1185.0,"id":7412952}]}]}
{"op":"mcm","clk":"1004129212","pt":1580620953918,"mc":[{"id":"1.168209731","rc":[{"batl":[[0,1.96,7.68]],"ltp":1.94,"tv":1925.94,"id":8174357},{"batb":[[0,2.04,6.18],[1,2.02,39.86],[2,2,10]],"batl":[[0,2.06,42.78]],"ltp":2.04,"tv":1185.0,"id":7412952}]}]}
{"op":"mcm","clk":"1004129284","pt":1580620954899,"mc":[{"id":"1.168209731","rc":[{"batl":[[0,1.96,2.5]],"ltp":1.94,"tv":1925.94,"id":8174357},{"batb":[[0,2.02,39.86],[1,2,10],[2,1.81,330.47]],"batl":[[0,2.06,48.78]],"ltp":2.04,"tv":1185.0,"id":7412952}]}]}
{"op":"mcm","clk":"1004129334","pt":1580620955933,"mc":[{"id":"1.168209731","rc":[{"batl":[[0,1.96,7.69]],"ltp":1.94,"tv":1925.94,"id":8174357},{"batb":[[0,2.04,6.19],[1,2.02,39.86],[2,2,10]],"batl":[[0,2.06,42.78]],"ltp":2.04,"tv":1185.0,"id":7412952}]}]}
{"op":"mcm","clk":"1004129389","pt":1580620956912,"mc":[{"id":"1.168209731","rc":[{"batl":[[0,1.96,2.5]],"ltp":1.94,"tv":1925.94,"id":8174357},{"batb":[[0,2.02,39.86],[1,2,10],[2,1.81,330.47]],"batl":[[0,2.06,48.78]],"ltp":2.04,"tv":1185.0,"id":7412952}]}]}
{"op":"mcm","clk":"1004129464","pt":1580620957944,"mc":[{"id":"1.168209731","rc":[{"batl":[[0,1.96,7.7]],"ltp":1.94,"tv":1925.94,"id":8174357},{"batb":[[0,2.04,6.2],[1,2.02,39.86],[2,2,10]],"batl":[[0,2.06,42.78]],"ltp":2.04,"tv":1185.0,"id":7412952}]}]}
{"op":"mcm","clk":"1004129522","pt":1580620958931,"mc":[{"id":"1.168209731","rc":[{"batl":[[0,1.96,2.5]],"ltp":1.94,"tv":1925.94,"id":8174357},{"batb":[[0,2.02,39.86],[1,2,10],[2,1.81,330.47]],"batl":[[0,2.06,48.78]],"ltp":2.04,"tv":1185.0,"id":7412952}]}]}
{"op":"mcm","clk":"1004129588","pt":1580620959955,"mc":[{"id":"1.168209731","rc":[{"batl":[[1,2,68.06],[2,2.3,10.13]],"ltp":1.94,"tv":1925.94,"id":8174357}]}]}
{"op":"mcm","clk":"1004129641","pt":1580620960938,"mc":[{"id":"1.168209731","rc":[{"batl":[[0,1.96,7.72],[1,1.97,5],[2,2,68.06]],"ltp":1.94,"tv":1925.94,"id":8174357},{"batb":[[0,2.04,6.22],[1,2.02,39.86],[2,2,10]],"batl":[[0,2.06,42.78]],"ltp":2.04,"tv":1185.0,"id":7412952}]}]}
{"op":"mcm","clk":"1004129751","pt":1580620962954,"mc":[{"id":"1.168209731","rc":[{"batl":[[0,1.96,2.5]],"ltp":1.94,"tv":1925.94,"id":8174357},{"batb":[[0,2.02,39.86],[1,2,10],[2,1.81,330.47]],"batl":[[0,2.06,48.78]],"ltp":2.04,"tv":1185.0,"id":7412952}]}]}
{"op":"mcm","clk":"1004129845","pt":1580620964818,"mc":[{"id":"1.168209731","rc":[{"batl":[[0,1.96,7.74]],"ltp":1.94,"tv":1925.94,"id":8174357},{"batb":[[0,2.04,6.24],[1,2.02,39.86],[2,2,10]],"batl":[[0,2.06,42.78]],"ltp":2.04,"tv":1185.0,"id":7412952}]}]}
{"op":"mcm","clk":"1004129904","pt":1580620965851,"mc":[{"id":"1.168209731","rc":[{"batl":[[0,1.96,2.5]],"ltp":1.94,"tv":1925.94,"id":8174357},{"batb":[[0,2.02,39.86],[1,2,10],[2,1.81,330.47]],"batl":[[0,2.06,48.78]],"ltp":2.04,"tv":1185.0,"id":7412952}]}]}
{"op":"mcm","clk":"1004129968","pt":1580620966839,"mc":[{"id":"1.168209731","rc":[{"batl":[[0,1.96,7.75]],"ltp":1.94,"tv":1925.94,"id":8174357},{"batb":[[0,2.04,6.25],[1,2.02,39.86],[2,2,10]],"batl":[[0,2.06,42.78]],"ltp":2.04,"tv":1185.0,"id":7412952}]}]}
{"op":"mcm","clk":"1004130021","pt":1580620967871,"mc":[{"id":"1.168209731","rc":[{"batl":[[0,1.96,2.5]],"ltp":1.94,"tv":1925.94,"id":8174357},{"batb":[[0,2.02,39.86],[1,2,10],[2,1.81,330.47]],"batl":[[0,2.06,48.78]],"ltp":2.04,"tv":1185.0,"id":7412952}]}]}
{"op":"mcm","clk":"1004130085","pt":1580620968851,"mc":[{"id":"1.168209731","rc":[{"batl":[[0,1.96,7.76]],"ltp":1.94,"tv":1925.94,"id":8174357},{"batb":[[0,2.04,6.26],[1,2.02,39.86],[2,2,10]],"batl":[[0,2.06,42.78]],"ltp":2.04,"tv":1185.0,"id":7412952}]}]}
{"op":"mcm","clk":"1004130136","pt":1580620969832,"mc":[{"id":"1.168209731","rc":[{"batl":[[0,1.96,2.5]],"ltp":1.94,"tv":1925.94,"id":8174357},{"batb":[[0,2.02,39.86],[1,2,10],[2,1.81,330.47]],"batl":[[0,2.06,48.78]],"ltp":2.04,"tv":1185.0,"id":7412952}]}]}
{"op":"mcm","clk":"1004130198","pt":1580620970867,"mc":[{"id":"1.168209731","rc":[{"batl":[[0,1.96,7.77]],"ltp":1.94,"tv":1925.94,"id":8174357},{"batb":[[0,2.04,6.27],[1,2.02,39.86],[2,2,10]],"batl":[[0,2.06,42.78]],"ltp":2.04,"tv":1185.0,"id":7412952}]}]}
{"op":"mcm","clk":"1004130248","pt":1580620971843,"mc":[{"id":"1.168209731","rc":[{"batl":[[0,1.96,2.5]],"ltp":1.94,"tv":1925.94,"id":8174357},{"batb":[[0,2.02,39.86],[1,2,10],[2,1.81,330.47]],"batl":[[0,2.06,48.78]],"ltp":2.04,"tv":1185.0,"id":7412952}]}]}
{"op":"mcm","clk":"1004130352","pt":1580620973862,"mc":[{"id":"1.168209731","rc":[{"batl":[[0,1.96,7.79]],"ltp":1.94,"tv":1925.94,"id":8174357},{"batb":[[0,2.04,6.29],[1,2.02,39.86],[2,2,10]],"batl":[[0,2.06,42.78]],"ltp":2.04,"tv":1185.0,"id":7412952}]}]}
{"op":"mcm","clk":"1004130403","pt":1580620974886,"mc":[{"id":"1.168209731","rc":[{"batl":[[0,1.96,2.5]],"ltp":1.94,"tv":1925.94,"id":8174357},{"batb":[[0,2.02,39.86],[1,2,10],[2,1.81,330.47]],"batl":[[0,2.06,48.78]],"ltp":2.04,"tv":1185.0,"id":7412952}]}]}
{"op":"mcm","clk":"1004130456","pt":1580620975868,"mc":[{"id":"1.168209731","rc":[{"batl":[[0,1.96,7.8]],"ltp":1.94,"tv":1925.94,"id":8174357},{"batb":[[0,2.04,6.3],[1,2.02,39.86],[2,2,10]],"ltp":2.04,"tv":1185.0,"id":7412952}]}]}
{"op":"mcm","clk":"1004130515","pt":1580620976891,"mc":[{"id":"1.168209731","rc":[{"batl":[[0,1.96,7.81]],"ltp":1.94,"tv":1925.94,"id":8174357},{"batb":[[0,2.04,6.31]],"batl":[[0,2.06,42.78]],"ltp":2.04,"tv":1185.0,"id":7412952}]}]}
