{"op":"mcm","clk":"996134465","pt":1580560628823,"mc":[{"id":"1.168209732","marketDefinition":{"bspMarket":false,"turnInPlayEnabled":true,"persistenceEnabled":true,"marketBaseRate":5.0,"eventId":"29681142","eventTypeId":"2","numberOfWinners":1,"bettingType":"ODDS","marketType":"SET_BETTING","marketTime":"2020-02-02T04:00:00.000Z","suspendTime":"2020-02-02T04:00:00.000Z","bspReconciled":false,"complete":true,"inPlay":false,"crossMatching":false,"runnersVoidable":false,"numberOfActiveRunners":4,"betDelay":0,"status":"OPEN","runners":[{"status":"ACTIVE","sortPriority":1,"id":12986368,"name":"Rola 2-0"},{"status":"ACTIVE","sortPriority":2,"id":12986367,"name":"Rola 2-1"},{"status":"ACTIVE","sortPriority":3,"id":18318122,"name":"Marcora 2-0"},{"status":"ACTIVE","sortPriority":4,"id":18318124,"name":"Marcora 2-1"}],"regulators":["MR_INT"],"countryCode":"IN","discountAllowed":false,"timezone":"UTC","openDate":"2020-02-02T04:00:00.000Z","version":3145101547,"name":"Set Betting","eventName":"Rola v Marcora"}}]}
{"op":"mcm","clk":"996134636","pt":1580560629891,"mc":[{"id":"1.168209732","marketDefinition":{"bspMarket":false,"turnInPlayEnabled":true,"persistenceEnabled":true,"marketBaseRate":5.0,"eventId":"29681142","eventTypeId":"2","numberOfWinners":1,"bettingType":"ODDS","marketType":"SET_BETTING","marketTime":"2020-02-02T04:00:00.000Z","suspendTime":"2020-02-02T04:00:00.000Z","bspReconciled":false,"complete":true,"inPlay":false,"crossMatching":false,"runnersVoidable":false,"numberOfActiveRunners":4,"betDelay":0,"status":"OPEN","runners":[{"status":"ACTIVE","sortPriority":1,"id":12986368,"name":"Rola 2-0"},{"status":"ACTIVE","sortPriority":2,"id":12986367,"name":"Rola 2-1"},{"status":"ACTIVE","sortPriority":3,"id":18318122,"name":"Marcora 2-0"},{"status":"ACTIVE","sortPriority":4,"id":18318124,"name":"Marcora 2-1"}],"regulators":["MR_INT"],"countryCode":"IN","discountAllowed":false,"timezone":"UTC","openDate":"2020-02-02T04:00:00.000Z","version":3145101547,"name":"Set Betting","eventName":"Rola v Marcora"}}]}
{"op":"mcm","clk":"996134845","pt":1580560630893,"mc":[{"id":"1.168209732","marketDefinition":{"bspMarket":false,"turnInPlayEnabled":true,"persistenceEnabled":true,"marketBaseRate":5.0,"eventId":"29681142","eventTypeId":"2","numberOfWinners":1,"bettingType":"ODDS","marketType":"SET_BETTING","marketTime":"2020-02-02T04:00:00.000Z","suspendTime":"2020-02-02T04:00:00.000Z","bspReconciled":false,"complete":true,"inPlay":false,"crossMatching":false,"runnersVoidable":false,"numberOfActiveRunners":4,"betDelay":0,"status":"OPEN","runners":[{"status":"ACTIVE","sortPriority":1,"id":12986368,"name":"Rola 2-0"},{"status":"ACTIVE","sortPriority":2,"id":12986367,"name":"Rola 2-1"},{"status":"ACTIVE","sortPriority":3,"id":18318122,"name":"Marcora 2-0"},{"status":"ACTIVE","sortPriority":4,"id":18318124,"name":"Marcora 2-1"}],"regulators":["MR_INT"],"countryCode":"IN","discountAllowed":true,"timezone":"UTC","openDate":"2020-02-02T04:00:00.000Z","version":3145101547,"name":"Set Betting","eventName":"Rola v Marcora"}}]}
{"op":"mcm","clk":"996580964","pt":1580562799858,"mc":[{"id":"1.168209732","rc":[{"batb":[[0,1.02,2]],"ltp":0.0,"tv":0.0,"id":12986367},{"batb":[[0,1.02,2]],"ltp":0.0,"tv":0.0,"id":18318124},{"batb":[[0,1.02,2]],"ltp":0.0,"tv":0.0,"id":12986368},{"batb":[[0,1.02,2]],"ltp":0.0,"tv":0.0,"id":18318122}]}]}
{"op":"mcm","clk":"997589873","pt":1580567441341,"mc":[{"id":"1.168209732","marketDefinition":{"bspMarket":false,"turnInPlayEnabled":true,"persistenceEnabled":true,"marketBaseRate":5.0,"eventId":"29681142","eventTypeId":"2","numberOfWinners":1,"bettingType":"ODDS","marketType":"SET_BETTING","marketTime":"2020-02-02T09:30:00.000Z","suspendTime":"2020-02-02T09:30:00.000Z","bspReconciled":false,"complete":true,"inPlay":false,"crossMatching":false,"runnersVoidable":false,"numberOfActiveRunners":4,"betDelay":0,"status":"OPEN","runners":[{"status":"ACTIVE","sortPriority":1,"id":12986368,"name":"Rola 2-0"},{"status":"ACTIVE","sortPriority":2,"id":12986367,"name":"Rola 2-1"},{"status":"ACTIVE","sortPriority":3,"id":18318122,"name":"Marcora 2-0"},{"status":"ACTIVE","sortPriority":4,"id":18318124,"name":"Marcora 2-1"}],"regulators":["MR_INT"],"countryCode":"IN","discountAllowed":true,"timezone":"UTC","openDate":"2020-02-02T04:00:00.000Z","version":3145478787,"name":"Set Betting","eventName":"Rola v Marcora"}}]}
{"op":"mcm","clk":"997590546","pt":1580567444348,"mc":[{"id":"1.168209732","marketDefinition":{"bspMarket":false,"turnInPlayEnabled":true,"persistenceEnabled":true,"marketBaseRate":5.0,"eventId":"29681142","eventTypeId":"2","numberOfWinners":1,"bettingType":"ODDS","marketType":"SET_BETTING","marketTime":"2020-02-02T09:30:00.000Z","suspendTime":"2020-02-02T09:30:00.000Z","bspReconciled":false,"complete":true,"inPlay":false,"crossMatching":false,"runnersVoidable":false,"numberOfActiveRunners":4,"betDelay":0,"status":"OPEN","runners":[{"status":"ACTIVE","sortPriority":1,"id":12986368,"name":"Rola 2-0"},{"status":"ACTIVE","sortPriority":2,"id":12986367,"name":"Rola 2-1"},{"status":"ACTIVE","sortPriority":3,"id":18318122,"name":"Marcora 2-0"},{"status":"ACTIVE","sortPriority":4,"id":18318124,"name":"Marcora 2-1"}],"regulators":["MR_INT"],"countryCode":"IN","discountAllowed":true,"timezone":"UTC","openDate":"2020-02-02T09:30:00.000Z","version":3145478787,"name":"Set Betting","eventName":"Rola v Marcora"}}]}
{"op":"mcm","clk":"1000453348","pt":1580581062175,"mc":[{"id":"1.168209732","rc":[{"batb":[[0,2.12,30.29],[1,1.02,2]],"ltp":0.0,"tv":0.0,"id":12986368}]}]}
{"op":"mcm","clk":"1002635902","pt":1580596405651,"mc":[{"id":"1.168209732","rc":[{"batb":[[0,1.02,2],[1,1.02,0]],"ltp":0.0,"tv":0.0,"id":12986368}]}]}
{"op":"mcm","clk":"1002649033","pt":1580596605918,"mc":[{"id":"1.168209732","rc":[{"batb":[[0,2.12,30.29],[1,1.02,2]],"ltp":0.0,"tv":0.0,"id":12986368}]}]}
{"op":"mcm","clk":"1002738591","pt":1580598066241,"mc":[{"id":"1.168209732","rc":[{"batb":[[0,2.34,30.29]],"ltp":0.0,"tv":0.0,"id":12986368}]}]}
{"op":"mcm","clk":"1003058399","pt":1580602466055,"mc":[{"id":"1.168209732","rc":[{"batb":[[1,1.01,0.51]],"ltp":0.0,"tv":0.0,"id":12986367},{"batb":[[1,1.01,0.51]],"ltp":0.0,"tv":0.0,"id":18318124},{"batb":[[2,1.01,0.51]],"ltp":0.0,"tv":0.0,"id":12986368},{"batb":[[1,1.01,0.51]],"ltp":0.0,"tv":0.0,"id":18318122}]}]}
{"op":"mcm","clk":"1003078676","pt":1580602689778,"mc":[{"id":"1.168209732","rc":[{"batb":[[0,2.5,30.29]],"ltp":0.0,"tv":0.0,"id":12986368}]}]}
{"op":"mcm","clk":"1003180038","pt":1580603999879,"mc":[{"id":"1.168209732","rc":[{"batb":[[1,1.01,1.01]],"ltp":0.0,"tv":0.0,"id":12986367},{"batb":[[1,1.01,1.01]],"ltp":0.0,"tv":0.0,"id":18318124},{"batb":[[2,1.01,1.01]],"ltp":0.0,"tv":0.0,"id":12986368},{"batb":[[1,1.01,1.01]],"ltp":0.0,"tv":0.0,"id":18318122}]}]}
{"op":"mcm","clk":"1004673432","pt":1580634945569,"mc":[{"id":"1.168209732","rc":[{"batb":[[0,1.02,2],[1,1.01,1.01],[2,1.01,0]],"ltp":0.0,"tv":0.0,"id":12986368}]}]}
{"op":"mcm","clk":"1004694408","pt":1580635384846,"mc":[{"id":"1.168209732","rc":[{"batb":[[0,4.5,16.92],[1,1.02,2],[2,1.01,1.01]],"batl":[[0,5.2,16.13]],"ltp":0.0,"tv":0.0,"id":12986367},{"batb":[[0,4.7,15.03],[1,1.02,2],[2,1.01,1.01]],"batl":[[0,5.5,14.4]],"ltp":0.0,"tv":0.0,"id":18318124},{"batb":[[0,3,22.74],[1,1.02,2],[2,1.01,1.01]],"batl":[[0,3.35,21.87]],"ltp":0.0,"tv":0.0,"id":12986368},{"batb":[[0,3.35,17.55],[1,1.02,2],[2,1.01,1.01]],"batl":[[0,3.75,16.92]],"ltp":0.0,"tv":0.0,"id":18318122}]}]}
{"op":"mcm","clk":"1004704147","pt":1580635608357,"mc":[{"id":"1.168209732","marketDefinition":{"bspMarket":false,"turnInPlayEnabled":true,"persistenceEnabled":true,"marketBaseRate":5.0,"eventId":"29681142","eventTypeId":"2","numberOfWinners":1,"bettingType":"ODDS","marketType":"SET_BETTING","marketTime":"2020-02-02T09:21:00.000Z","suspendTime":"2020-02-02T09:21:00.000Z","bspReconciled":false,"complete":true,"inPlay":false,"crossMatching":false,"runnersVoidable":false,"numberOfActiveRunners":4,"betDelay":0,"status":"OPEN","runners":[{"status":"ACTIVE","sortPriority":1,"id":12986368,"name":"Rola 2-0"},{"status":"ACTIVE","sortPriority":2,"id":12986367,"name":"Rola 2-1"},{"status":"ACTIVE","sortPriority":3,"id":18318122,"name":"Marcora 2-0"},{"status":"ACTIVE","sortPriority":4,"id":18318124,"name":"Marcora 2-1"}],"regulators":["MR_INT"],"countryCode":"IN","discountAllowed":true,"timezone":"UTC","openDate":"2020-02-02T09:30:00.000Z","version":3148345363,"name":"Set Betting","eventName":"Rola v Marcora"}}]}
{"op":"mcm","clk":"1004704582","pt":1580635614514,"mc":[{"id":"1.168209732","marketDefinition":{"bspMarket":false,"turnInPlayEnabled":true,"persistenceEnabled":true,"marketBaseRate":5.0,"eventId":"29681142","eventTypeId":"2","numberOfWinners":1,"bettingType":"ODDS","marketType":"SET_BETTING","marketTime":"2020-02-02T09:21:00.000Z","suspendTime":"2020-02-02T09:21:00.000Z","bspReconciled":false,"complete":true,"inPlay":false,"crossMatching":false,"runnersVoidable":false,"numberOfActiveRunners":4,"betDelay":0,"status":"OPEN","runners":[{"status":"ACTIVE","sortPriority":1,"id":12986368,"name":"Rola 2-0"},{"status":"ACTIVE","sortPriority":2,"id":12986367,"name":"Rola 2-1"},{"status":"ACTIVE","sortPriority":3,"id":18318122,"name":"Marcora 2-0"},{"status":"ACTIVE","sortPriority":4,"id":18318124,"name":"Marcora 2-1"}],"regulators":["MR_INT"],"countryCode":"IN","discountAllowed":true,"timezone":"UTC","openDate":"2020-02-02T09:21:00.000Z","version":3148345363,"name":"Set Betting","eventName":"Rola v Marcora"}}]}
{"op":"mcm","clk":"1004705227","pt":1580635628332,"mc":[{"id":"1.168209732","rc":[{"trd":[[2.98,48.92],[3,45.48]],"batb":[[0,1.02,2],[1,1.01,1.01],[2,1.01,0]],"batl":[[0,2.98,94.66],[1,3.35,21.87]],"ltp":2.98,"tv":94.39,"id":12986368}],"tv":94.39}]}
{"op":"mcm","clk":"1004705268","pt":1580635629258,"mc":[{"id":"1.168209732","rc":[{"batb":[[0,4.6,16.68]],"batl":[[0,5.2,15.89]],"ltp":0.0,"tv":0.0,"id":12986367},{"batb":[[0,4.8,14.79]],"batl":[[0,5.5,14.16]],"ltp":0.0,"tv":0.0,"id":18318124},{"trd":[[2.98,96.13]],"batl":[[0,2.98,71.06],[1,3.2,22.66]],"ltp":2.98,"tv":141.6,"id":12986368},{"batb":[[0,3.4,17.23]],"batl":[[0,3.75,16.68]],"ltp":0.0,"tv":0.0,"id":18318122}],"tv":141.6}]}
{"op":"mcm","clk":"1004705625","pt":1580635639443,"mc":[{"id":"1.168209732","rc":[{"batb":[[0,4.6,16.37]],"batl":[[0,5.3,15.66]],"ltp":0.0,"tv":0.0,"id":12986367},{"batb":[[0,4.9,14.56]],"batl":[[0,5.6,13.93]],"ltp":0.0,"tv":0.0,"id":18318124},{"batb":[[0,2.94,24.55],[1,1.02,2],[2,1.01,1.01]],"batl":[[1,3.15,23.6]],"ltp":2.98,"tv":141.6,"id":12986368},{"batb":[[0,3.45,16.92]],"batl":[[0,3.75,16.37]],"ltp":0.0,"tv":0.0,"id":18318122}]}]}
{"op":"mcm","clk":"1004706160","pt":1580635654406,"mc":[{"id":"1.168209732","marketDefinition":{"bspMarket":false,"turnInPlayEnabled":true,"persistenceEnabled":true,"marketBaseRate":5.0,"eventId":"29681142","eventTypeId":"2","numberOfWinners":1,"bettingType":"ODDS","marketType":"SET_BETTING","marketTime":"2020-02-02T09:21:00.000Z","suspendTime":"2020-02-02T09:21:00.000Z","bspReconciled":false,"complete":true,"inPlay":false,"crossMatching":true,"runnersVoidable":false,"numberOfActiveRunners":4,"betDelay":0,"status":"OPEN","runners":[{"status":"ACTIVE","sortPriority":1,"id":12986368,"name":"Rola 2-0"},{"status":"ACTIVE","sortPriority":2,"id":12986367,"name":"Rola 2-1"},{"status":"ACTIVE","sortPriority":3,"id":18318122,"name":"Marcora 2-0"},{"status":"ACTIVE","sortPriority":4,"id":18318124,"name":"Marcora 2-1"}],"regulators":["MR_INT"],"countryCode":"IN","discountAllowed":true,"timezone":"UTC","openDate":"2020-02-02T09:21:00.000Z","version":3148345363,"name":"Set Betting","eventName":"Rola v Marcora"}}]}
{"op":"mcm","clk":"1004706297","pt":1580635658384,"mc":[{"id":"1.168209732","rc":[{"batl":[[0,2.98,71.06]],"ltp":2.98,"tv":141.6,"id":12986368}]}]}
{"op":"mcm","clk":"1004717287","pt":1580635929478,"mc":[{"id":"1.168209732","rc":[{"batb":[[0,4.7,16.29]],"ltp":0.0,"tv":0.0,"id":12986367},{"batl":[[0,5.5,13.93]],"ltp":0.0,"tv":0.0,"id":18318124}]}]}
{"op":"mcm","clk":"1004717743","pt":1580635939105,"mc":[{"id":"1.168209732","rc":[{"batb":[[0,2.94,24.39]],"batl":[[1,3.15,23.45]],"ltp":2.98,"tv":141.6,"id":12986368}]}]}
{"op":"mcm","clk":"1004718326","pt":1580635951812,"mc":[{"id":"1.168209732","rc":[{"trd":[[4.8,12.78]],"batb":[[2,1.01,2.19]],"batl":[[0,4.8,1.18],[1,5.3,15.66]],"ltp":4.8,"tv":12.78,"id":12986367},{"trd":[[2.98,116.73]],"batb":[[2,1.01,2.91]],"batl":[[0,2.98,60.76]],"ltp":2.98,"tv":162.2,"id":12986368}],"tv":174.98}]}
{"op":"mcm","clk":"1004718349","pt":1580635952229,"mc":[{"id":"1.168209732","rc":[{"trd":[[4.8,15.14]],"batb":[[2,1.01,1.01]],"batl":[[0,5.3,15.66],[1,5.3,0]],"ltp":4.8,"tv":15.14,"id":12986367},{"trd":[[2.98,120.53]],"batb":[[2,1.01,1.01]],"batl":[[0,2.98,58.86]],"ltp":2.98,"tv":166.0,"id":12986368}],"tv":181.15}]}
{"op":"mcm","clk":"1004719938","pt":1580635987173,"mc":[{"id":"1.168209732","rc":[{"batl":[[0,4.8,3.79],[1,5.3,15.66]],"ltp":4.8,"tv":15.14,"id":12986367}]}]}
{"op":"mcm","clk":"1004724695","pt":1580636099868,"mc":[{"id":"1.168209732","rc":[{"batb":[[0,4.7,15.97]],"batl":[[1,5.3,15.26]],"ltp":4.8,"tv":15.14,"id":12986367},{"batb":[[0,4.9,14.32]],"batl":[[0,5.6,13.77]],"ltp":0.0,"tv":0.0,"id":18318124},{"trd":[[2.94,52.78]],"batb":[[0,2.9,25.41]],"batl":[[0,2.94,32.47],[1,3.1,24.39]],"ltp":2.94,"tv":218.78,"id":12986368},{"batb":[[0,3.5,16.68]],"batl":[[0,3.8,16.13]],"ltp":0.0,"tv":0.0,"id":18318122}],"tv":233.93}]}
{"op":"mcm","clk":"1004724968","pt":1580636107302,"mc":[{"id":"1.168209732","rc":[{"trd":[[2.94,64.78]],"batl":[[0,2.94,26.47]],"ltp":2.94,"tv":230.78,"id":12986368}],"tv":245.93}]}
{"op":"mcm","clk":"1004725085","pt":1580636109890,"mc":[{"id":"1.168209732","rc":[{"batl":[[2,3.15,24.23]],"ltp":2.94,"tv":230.78,"id":12986368},{"batb":[[1,3.45,16.84],[2,1.02,2]],"ltp":0.0,"tv":0.0,"id":18318122}]}]}
{"op":"mcm","clk":"1004725089","pt":1580636109993,"mc":[{"id":"1.168209732","rc":[{"batb":[[0,2.9,25.26]],"batl":[[1,3.15,24.23],[2,3.15,0]],"ltp":2.94,"tv":230.78,"id":12986368},{"batb":[[0,3.45,16.84],[1,1.02,2],[2,1.01,1.01]],"ltp":0.0,"tv":0.0,"id":18318122}]}]}
{"op":"mcm","clk":"1004725848","pt":1580636127532,"mc":[{"id":"1.168209732","rc":[{"batl":[[0,2.92,26.47]],"ltp":2.94,"tv":230.78,"id":12986368}]}]}
{"op":"mcm","clk":"1004725960","pt":1580636130520,"mc":[{"id":"1.168209732","rc":[{"batb":[[1,4.6,10.92],[2,1.02,2]],"batl":[[1,5.3,24.51]],"ltp":4.8,"tv":15.14,"id":12986367},{"batb":[[1,4.7,10.92],[2,1.02,2]],"batl":[[0,5.6,22.17]],"ltp":0.0,"tv":0.0,"id":18318124},{"trd":[[2.92,52.09]],"batl":[[0,3.15,24.65],[1,3.35,17.64]],"ltp":2.92,"tv":282.88,"id":12986368},{"batb":[[1,3.3,17.64],[2,1.02,2]],"batl":[[0,3.8,30.41]],"ltp":0.0,"tv":0.0,"id":18318122}],"tv":298.02}]}
{"op":"mcm","clk":"1004726509","pt":1580636142841,"mc":[{"id":"1.168209732","marketDefinition":{"bspMarket":false,"turnInPlayEnabled":true,"persistenceEnabled":true,"marketBaseRate":5.0,"eventId":"29681142","eventTypeId":"2","numberOfWinners":1,"bettingType":"ODDS","marketType":"SET_BETTING","marketTime":"2020-02-02T09:21:00.000Z","suspendTime":"2020-02-02T09:21:00.000Z","bspReconciled":false,"complete":true,"inPlay":true,"crossMatching":true,"runnersVoidable":false,"numberOfActiveRunners":4,"betDelay":3,"status":"OPEN","runners":[{"status":"ACTIVE","sortPriority":1,"id":12986368,"name":"Rola 2-0"},{"status":"ACTIVE","sortPriority":2,"id":12986367,"name":"Rola 2-1"},{"status":"ACTIVE","sortPriority":3,"id":18318122,"name":"Marcora 2-0"},{"status":"ACTIVE","sortPriority":4,"id":18318124,"name":"Marcora 2-1"}],"regulators":["MR_INT"],"countryCode":"IN","discountAllowed":true,"timezone":"UTC","openDate":"2020-02-02T09:21:00.000Z","version":3148351350,"name":"Set Betting","eventName":"Rola v Marcora"},"rc":[{"batb":[[0,1.01,0.51],[1,4.6,0],[2,1.02,0]],"batl":[[1,5.3,0]],"ltp":4.8,"tv":15.14,"id":12986367},{"batb":[[0,1.01,0.51],[1,4.7,0],[2,1.02,0]],"ltp":0.0,"tv":0.0,"id":18318124},{"batb":[[0,1.01,0.51],[1,1.02,0],[2,1.01,0]],"batl":[[0,2.92,0.42],[1,3.35,0]],"ltp":2.92,"tv":282.88,"id":12986368},{"batb":[[0,1.01,0.51],[1,3.3,0],[2,1.02,0]],"ltp":0.0,"tv":0.0,"id":18318122}]}]}
{"op":"mcm","clk":"1004726765","pt":1580636149452,"mc":[{"id":"1.168209732","rc":[{"batb":[[0,4.6,34.36],[1,4.5,40.76],[2,1.01,0.51]],"ltp":4.8,"tv":15.14,"id":12986367},{"batb":[[0,4.8,23.37],[1,4.7,37.07],[2,1.01,0.51]],"ltp":0.0,"tv":0.0,"id":18318124},{"trd":[[2.92,52.93]],"batb":[[0,3,35.3],[1,2.96,45.28],[2,1.01,0.51]],"ltp":2.92,"tv":283.72,"id":12986368},{"batb":[[0,3.05,71.89],[1,3,54.2],[2,1.01,0.51]],"ltp":0.0,"tv":0.0,"id":18318122}],"tv":298.86}]}
{"op":"mcm","clk":"1004727246","pt":1580636160632,"mc":[{"id":"1.168209732","rc":[{"batb":[[0,1.01,0.51],[1,2.96,0],[2,1.01,0]],"ltp":2.92,"tv":283.72,"id":12986368},{"batb":[[0,1.01,0.51],[1,3,0],[2,1.01,0]],"ltp":0.0,"tv":0.0,"id":18318122}]}]}
{"op":"mcm","clk":"1004727409","pt":1580636163839,"mc":[{"id":"1.168209732","rc":[{"batb":[[0,3.2,64.85],[1,3.15,48.01],[2,1.01,0.51]],"ltp":2.92,"tv":283.72,"id":12986368},{"batb":[[0,3.35,35.22],[1,3.3,43.04],[2,1.01,0.51]],"ltp":0.0,"tv":0.0,"id":18318122}]}]}
{"op":"mcm","clk":"1004727601","pt":1580636167888,"mc":[{"id":"1.168209732","rc":[{"batb":[[0,1.01,0.51],[1,3.15,0],[2,1.01,0]],"ltp":2.92,"tv":283.72,"id":12986368},{"batb":[[0,1.01,0.51],[1,3.3,0],[2,1.01,0]],"ltp":0.0,"tv":0.0,"id":18318122}]}]}
{"op":"mcm","clk":"1004727713","pt":1580636170774,"mc":[{"id":"1.168209732","rc":[{"batb":[[0,3,35.64],[1,2.96,45.28],[2,1.01,0.51]],"ltp":2.92,"tv":283.72,"id":12986368},{"batb":[[0,3.05,71.92],[1,3,54.2],[2,1.01,0.51]],"ltp":0.0,"tv":0.0,"id":18318122}]}]}
{"op":"mcm","clk":"1004727852","pt":1580636174489,"mc":[{"id":"1.168209732","rc":[{"batb":[[0,1.01,0.51],[1,3,0],[2,1.01,0]],"ltp":0.0,"tv":0.0,"id":18318122}]}]}
{"op":"mcm","clk":"1004727985","pt":1580636176954,"mc":[{"id":"1.168209732","rc":[{"batb":[[0,4.6,44.47]],"ltp":4.8,"tv":15.14,"id":12986367},{"batb":[[0,3.6,60.41],[1,3.55,35.81],[2,1.01,0.51]],"ltp":0.0,"tv":0.0,"id":18318122}]}]}
{"op":"mcm","clk":"1004728024","pt":1580636177774,"mc":[{"id":"1.168209732","rc":[{"batb":[[0,4.7,15.82],[1,4.6,44.47],[2,4.5,52.52]],"batl":[[1,5.3,9.24],[2,5.4,14.79]],"ltp":4.8,"tv":15.14,"id":12986367},{"batb":[[0,4.9,14.63],[1,4.7,47.99]],"batl":[[0,5.6,21.94]],"ltp":0.0,"tv":0.0,"id":18318124},{"trd":[[3,68.61]],"batb":[[0,3,24.07],[2,2.84,22.69]],"batl":[[0,3.15,19.32],[1,3.2,22.74]],"ltp":3.0,"tv":306.85,"id":12986368},{"batb":[[0,3.75,13.93],[1,3.6,48.93],[2,3.55,35.81]],"batl":[[0,4,13.44],[1,4.1,13.53],[2,4.4,22.82]],"ltp":0.0,"tv":0.0,"id":18318122}],"tv":322.0}]}
{"op":"mcm","clk":"1004728150","pt":1580636180671,"mc":[{"id":"1.168209732","rc":[{"batb":[[1,4.7,55.12],[2,4.6,38.32]],"ltp":0.0,"tv":0.0,"id":18318124},{"batb":[[0,3,37.3]],"ltp":3.0,"tv":306.85,"id":12986368},{"batb":[[1,3.6,36.55]],"ltp":0.0,"tv":0.0,"id":18318122}]}]}
{"op":"mcm","clk":"1004728160","pt":1580636180982,"mc":[{"id":"1.168209732","rc":[{"batb":[[1,4.6,52.43]],"ltp":4.8,"tv":15.14,"id":12986367}]}]}
{"op":"mcm","clk":"1004728273","pt":1580636183666,"mc":[{"id":"1.168209732","rc":[{"batb":[[1,4.6,60.99]],"ltp":4.8,"tv":15.14,"id":12986367},{"batb":[[0,3,61.99]],"ltp":3.0,"tv":306.85,"id":12986368}]}]}
{"op":"mcm","clk":"1004728634","pt":1580636193215,"mc":[{"id":"1.168209732","rc":[{"batb":[[0,2.84,22.69],[1,2.6,13.3],[2,1.01,0.51]],"ltp":3.0,"tv":306.85,"id":12986368},{"batb":[[0,3.45,16.8],[1,3.35,18.02],[2,1.01,0.51]],"batl":[[1,4.4,22.82],[2,4.4,0]],"ltp":0.0,"tv":0.0,"id":18318122}]}]}
{"op":"mcm","clk":"1004728668","pt":1580636194325,"mc":[{"id":"1.168209732","rc":[{"batb":[[2,4.5,40.76]],"batl":[[1,5.4,14.79],[2,5.4,0]],"ltp":4.8,"tv":15.14,"id":12986367},{"batb":[[1,4.7,44.2]],"batl":[[0,5.6,13.53]],"ltp":0.0,"tv":0.0,"id":18318124},{"batb":[[0,2.6,13.3],[1,1.01,0.51],[2,1.01,0]],"batl":[[0,3.2,22.74],[1,3.2,0]],"ltp":3.0,"tv":306.85,"id":12986368},{"batb":[[0,3.35,18.02],[1,1.01,0.51],[2,1.01,0]],"batl":[[0,4.4,22.82],[1,4.4,0]],"ltp":0.0,"tv":0.0,"id":18318122}]}]}
{"op":"mcm","clk":"1004728759","pt":1580636196894,"mc":[{"id":"1.168209732","rc":[{"trd":[[4.8,22.72]],"batb":[[0,4.8,11.79],[1,4.7,15.82],[2,4.6,60.99]],"batl":[[0,5.4,14.79],[1,5.4,0]],"ltp":4.8,"tv":22.71,"id":12986367},{"batb":[[1,4.8,15.11],[2,4.7,44.2]],"batl":[[0,5.5,14.01],[1,5.6,13.53]],"ltp":0.0,"tv":0.0,"id":18318124},{"batb":[[0,2.9,46.18],[1,2.86,49.55],[2,2.64,12.75]],"batl":[[1,3.25,21.79]],"ltp":3.0,"tv":306.85,"id":12986368},{"batb":[[1,3.3,50.21],[2,3.25,44.47]],"ltp":0.0,"tv":0.0,"id":18318122}],"tv":329.57}]}
{"op":"mcm","clk":"1004728763","pt":1580636196996,"mc":[{"id":"1.168209732","rc":[{"batb":[[1,4.6,60.99],[2,4.5,40.76]],"batl":[[0,5.4,14.63]],"ltp":4.8,"tv":22.71,"id":12986367},{"batb":[[0,4.8,15.11],[1,4.7,44.2],[2,4.6,38.32]],"batl":[[1,5.6,0]],"ltp":0.0,"tv":0.0,"id":18318124},{"batl":[[0,3.25,21.79],[1,3.25,0]],"ltp":3.0,"tv":306.85,"id":12986368},{"batb":[[0,3.3,50.21],[1,3.25,44.47],[2,1.01,0.51]],"ltp":0.0,"tv":0.0,"id":18318122}]}]}
{"op":"mcm","clk":"1004728882","pt":1580636199784,"mc":[{"id":"1.168209732","rc":[{"batb":[[0,2.64,12.75],[1,1.01,0.51],[2,2.64,0]],"ltp":3.0,"tv":306.85,"id":12986368},{"batb":[[0,3.3,18.65],[1,1.01,0.51],[2,1.01,0]],"ltp":0.0,"tv":0.0,"id":18318122}]}]}
{"op":"mcm","clk":"1004728986","pt":1580636202681,"mc":[{"id":"1.168209732","rc":[{"batb":[[0,3.05,59.51],[1,3,54.56],[2,2.64,12.75]],"ltp":3.0,"tv":306.85,"id":12986368},{"batb":[[0,3.5,62.65],[1,3.45,38.14],[2,3.3,18.65]],"ltp":0.0,"tv":0.0,"id":18318122}]}]}
{"op":"mcm","clk":"1004729126","pt":1580636206244,"mc":[{"id":"1.168209732","rc":[{"batb":[[0,2.64,12.75],[1,1.01,0.51],[2,2.64,0]],"ltp":3.0,"tv":306.85,"id":12986368},{"batb":[[0,3.3,18.65],[1,1.01,0.51],[2,3.3,0]],"ltp":0.0,"tv":0.0,"id":18318122}]}]}
{"op":"mcm","clk":"1004729366","pt":1580636212937,"mc":[{"id":"1.168209732","rc":[{"trd":[[3.25,43.58]],"batb":[[0,3.25,45.14],[1,3.2,46.35],[2,2.64,12.75]],"ltp":3.25,"tv":350.44,"id":12986368},{"batb":[[0,3.3,50.21],[1,3.25,44.47],[2,1.01,0.51]],"ltp":0.0,"tv":0.0,"id":18318122}],"tv":373.15}]}
{"op":"mcm","clk":"1004729394","pt":1580636213713,"mc":[{"id":"1.168209732","rc":[{"batb":[[0,4.6,88.28],[1,4.5,40.76],[2,1.01,0.51]],"batl":[[0,5.3,9.24],[1,5.4,14.63]],"ltp":4.8,"tv":22.71,"id":12986367},{"batb":[[1,4.7,55.12]],"batl":[[0,5.5,23.25]],"ltp":0.0,"tv":0.0,"id":18318124},{"batb":[[2,3.05,20.16]],"batl":[[0,3.45,16.8],[1,3.8,15.34]],"ltp":3.25,"tv":350.44,"id":12986368},{"batb":[[0,3.35,18.57],[1,3.3,31.56],[2,3.25,44.47]],"batl":[[0,3.6,17.94],[1,3.65,15.12],[2,3.95,14.71]],"ltp":0.0,"tv":0.0,"id":18318122}]}]}
{"op":"mcm","clk":"1004729472","pt":1580636216337,"mc":[{"id":"1.168209732","rc":[{"batb":[[0,3.25,62.73]],"ltp":3.25,"tv":350.44,"id":12986368}]}]}
{"op":"mcm","clk":"1004730026","pt":1580636227667,"mc":[{"id":"1.168209732","rc":[{"batb":[[0,4.6,79.72]],"ltp":4.8,"tv":22.71,"id":12986367},{"batb":[[0,3.05,20.16],[1,2.84,10.7],[2,1.01,0.51]],"ltp":3.25,"tv":350.44,"id":12986368},{"batb":[[0,3.2,18.48],[1,2.94,25.57],[2,1.01,0.51]],"batl":[[0,3.65,15.12],[1,3.95,14.71],[2,3.95,0]],"ltp":0.0,"tv":0.0,"id":18318122}]}]}
{"op":"mcm","clk":"1004730044","pt":1580636228332,"mc":[{"id":"1.168209732","rc":[{"batb":[[0,4.6,68.8]],"batl":[[0,5.4,14.63],[1,5.4,0]],"ltp":4.8,"tv":22.71,"id":12986367},{"batb":[[1,4.7,44.2]],"batl":[[0,5.5,14.01]],"ltp":0.0,"tv":0.0,"id":18318124},{"batb":[[0,2.84,10.7],[1,1.01,0.51],[2,1.01,0]],"batl":[[0,3.8,15.34],[1,3.8,0]],"ltp":3.25,"tv":350.44,"id":12986368},{"batb":[[0,2.94,25.57],[1,1.01,0.51],[2,1.01,0]],"batl":[[0,3.95,14.71],[1,3.95,0]],"ltp":0.0,"tv":0.0,"id":18318122}]}]}
{"op":"mcm","clk":"1004730118","pt":1580636230753,"mc":[{"id":"1.168209732","rc":[{"batl":[[0,5.3,15.26]],"ltp":4.8,"tv":22.71,"id":12986367},{"batl":[[0,5.4,14.48]],"ltp":0.0,"tv":0.0,"id":18318124},{"batb":[[0,3.05,54.59],[1,3,54.56],[2,2.86,10.46]],"batl":[[0,3.85,14.79]],"ltp":3.25,"tv":350.44,"id":12986368},{"batb":[[0,2.92,10.39],[1,2.9,46.95],[2,2.86,49.1]],"batl":[[0,3.9,14.95]],"ltp":0.0,"tv":0.0,"id":18318122}]}]}
{"op":"mcm","clk":"1004730134","pt":1580636231162,"mc":[{"id":"1.168209732","rc":[{"batb":[[0,4.6,60.84],[1,1.01,0.51],[2,1.01,0]],"ltp":4.8,"tv":22.71,"id":12986367},{"batb":[[1,1.01,0.51],[2,2.86,0]],"ltp":0.0,"tv":0.0,"id":18318122}]}]}
{"op":"mcm","clk":"1004730259","pt":1580636234781,"mc":[{"id":"1.168209732","rc":[{"batb":[[0,4.7,25.06],[1,4.6,60.84],[2,1.01,0.51]],"batl":[[1,5.4,14.79]],"ltp":4.8,"tv":22.71,"id":12986367},{"batl":[[1,5.5,14.48]],"ltp":0.0,"tv":0.0,"id":18318124},{"batl":[[0,3.1,25.02],[1,3.45,19.51],[2,3.85,14.79]],"ltp":3.25,"tv":350.44,"id":12986368},{"batb":[[0,3.6,15.5],[1,3.55,29.53],[2,3.5,37.14]],"batl":[[1,4.3,24.86]],"ltp":0.0,"tv":0.0,"id":18318122}]}]}
{"op":"mcm","clk":"1004730279","pt":1580636235257,"mc":[{"id":"1.168209732","rc":[{"batb":[[1,4.6,71.76]],"batl":[[0,5.3,9.24]],"ltp":4.8,"tv":22.71,"id":12986367},{"batb":[[1,4.7,55.12]],"batl":[[0,5.5,23.72],[1,5.5,0]],"ltp":0.0,"tv":0.0,"id":18318124},{"batb":[[2,2.9,21.85]],"batl":[[1,3.25,18.48],[2,3.45,19.51]],"ltp":3.25,"tv":350.44,"id":12986368},{"batl":[[0,3.9,29.23]],"ltp":0.0,"tv":0.0,"id":18318122}]}]}
{"op":"mcm","clk":"1004730805","pt":1580636247886,"mc":[{"id":"1.168209732","rc":[{"batb":[[0,4.6,71.76],[1,1.01,0.51],[2,1.01,0]],"ltp":4.8,"tv":22.71,"id":12986367},{"batb":[[0,2.9,21.85],[1,2.86,10.46],[2,2.7,12.2]],"ltp":3.25,"tv":350.44,"id":12986368},{"batb":[[1,3.4,16.8],[2,3.2,20.22]],"ltp":0.0,"tv":0.0,"id":18318122}]}]}
{"op":"mcm","clk":"1004730826","pt":1580636248303,"mc":[{"id":"1.168209732","rc":[{"batb":[[0,4.6,60.84]],"batl":[[0,5.4,14.79],[1,5.4,0]],"ltp":4.8,"tv":22.71,"id":12986367},{"batb":[[1,4.7,44.2]],"batl":[[0,5.5,14.48]],"ltp":0.0,"tv":0.0,"id":18318124},{"batb":[[0,2.7,12.2],[1,1.01,0.51],[2,2.7,0]],"batl":[[0,3.45,19.51],[1,3.25,0],[2,3.45,0]],"ltp":3.25,"tv":350.44,"id":12986368},{"batb":[[0,3.2,20.22],[1,1.01,0.51],[2,3.2,0]],"batl":[[0,4.3,24.86],[1,4.3,0]],"ltp":0.0,"tv":0.0,"id":18318122}]}]}
{"op":"mcm","clk":"1004730907","pt":1580636250774,"mc":[{"id":"1.168209732","rc":[{"batb":[[0,4.6,76.46],[1,4.5,40.64],[2,1.01,0.51]],"ltp":4.8,"tv":22.71,"id":12986367},{"batb":[[0,2.92,44.28],[1,2.88,48.65],[2,2.7,12.2]],"ltp":3.25,"tv":350.44,"id":12986368},{"batb":[[0,3.2,52.86],[1,3.15,48.05],[2,1.01,0.51]],"ltp":0.0,"tv":0.0,"id":18318122}]}]}
{"op":"mcm","clk":"1004731018","pt":1580636254523,"mc":[{"id":"1.168209732","rc":[{"batb":[[0,2.7,12.2],[1,1.01,0.51],[2,2.7,0]],"ltp":3.25,"tv":350.44,"id":12986368}]}]}
{"op":"mcm","clk":"1004731126","pt":1580636257929,"mc":[{"id":"1.168209732","rc":[{"batb":[[0,3.35,68.37],[1,3.3,42.91],[2,2.7,12.2]],"ltp":3.25,"tv":350.44,"id":12986368}]}]}
{"op":"mcm","clk":"1004731149","pt":1580636258394,"mc":[{"id":"1.168209732","rc":[{"batb":[[1,4.5,57.64]],"batl":[[0,5.3,15.66],[1,5.4,14.79]],"ltp":4.8,"tv":22.71,"id":12986367},{"batb":[[1,4.7,59.78]],"batl":[[0,5.5,14.16]],"ltp":0.0,"tv":0.0,"id":18318124},{"batb":[[2,3.15,20.22]],"batl":[[1,4.2,24.86]],"ltp":3.25,"tv":350.44,"id":12986368},{"batb":[[2,2.8,11.64]],"batl":[[0,3.5,19.51],[1,3.9,15.11]],"ltp":0.0,"tv":0.0,"id":18318122}]}]}
{"op":"mcm","clk":"1004731181","pt":1580636259321,"mc":[{"id":"1.168209732","rc":[{"batb":[[0,4.6,87.38]],"batl":[[1,5.4,24.03]],"ltp":4.8,"tv":22.71,"id":12986367},{"batb":[[2,4.6,49.24]],"batl":[[0,5.5,23.4]],"ltp":0.0,"tv":0.0,"id":18318124},{"batb":[[2,3.15,39.55]],"batl":[[1,3.55,15.96],[2,4.2,24.86]],"ltp":3.25,"tv":350.44,"id":12986368},{"batb":[[1,3.15,67.37]],"batl":[[1,3.55,15.96],[2,3.9,15.11]],"ltp":0.0,"tv":0.0,"id":18318122}]}]}
{"op":"mcm","clk":"1004731613","pt":1580636269842,"mc":[{"id":"1.168209732","rc":[{"batb":[[0,4.6,55.39]],"batl":[[0,5.4,24.03],[1,5.4,0]],"ltp":4.8,"tv":22.71,"id":12986367},{"batb":[[0,4.7,52.65],[1,4.6,49.24],[2,1.01,0.51]],"ltp":0.0,"tv":0.0,"id":18318124},{"batb":[[0,3.15,19.32],[1,2.88,10.31],[2,1.01,0.51]],"batl":[[0,3.55,15.96],[1,4.2,24.86],[2,4.2,0]],"ltp":3.25,"tv":350.44,"id":12986368},{"batb":[[0,3.15,19.32],[1,2.8,11.64],[2,1.01,0.51]],"batl":[[0,3.55,15.96],[1,3.9,15.11],[2,3.9,0]],"ltp":0.0,"tv":0.0,"id":18318122}]}]}
{"op":"mcm","clk":"1004731647","pt":1580636270523,"mc":[{"id":"1.168209732","rc":[{"batb":[[0,4.6,44.47]],"batl":[[0,5.4,14.79]],"ltp":4.8,"tv":22.71,"id":12986367},{"batb":[[1,4.6,38.32]],"batl":[[0,5.5,14.16]],"ltp":0.0,"tv":0.0,"id":18318124},{"batb":[[0,2.88,10.31],[1,1.01,0.51],[2,1.01,0]],"batl":[[0,4.2,24.86],[1,4.2,0]],"ltp":3.25,"tv":350.44,"id":12986368},{"batb":[[0,2.8,11.64],[1,1.01,0.51],[2,1.01,0]],"batl":[[0,3.9,15.11],[1,3.9,0]],"ltp":0.0,"tv":0.0,"id":18318122}]}]}
{"op":"mcm","clk":"1004731752","pt":1580636272842,"mc":[{"id":"1.168209732","rc":[{"batb":[[0,3.05,72.15],[1,3,54.4],[2,2.88,10.31]],"ltp":3.25,"tv":350.44,"id":12986368},{"batb":[[1,2.7,62.59],[2,2.66,59.16]],"ltp":0.0,"tv":0.0,"id":18318122}]}]}
{"op":"mcm","clk":"1004731795","pt":1580636273726,"mc":[{"id":"1.168209732","rc":[{"batb":[[0,2.88,10.31],[1,1.01,0.51],[2,2.88,0]],"ltp":3.25,"tv":350.44,"id":12986368},{"batb":[[1,1.01,0.51],[2,2.66,0]],"ltp":0.0,"tv":0.0,"id":18318122}]}]}
{"op":"mcm","clk":"1004731937","pt":1580636276858,"mc":[{"id":"1.168209732","rc":[{"batb":[[0,4.6,56.4]],"ltp":4.8,"tv":22.71,"id":12986367},{"batb":[[0,3.5,51.98],[1,3.45,38.62],[2,2.88,10.31]],"ltp":3.25,"tv":350.44,"id":12986368},{"batb":[[0,3.05,75.8],[1,3,53.89],[2,2.8,11.64]],"ltp":0.0,"tv":0.0,"id":18318122}]}]}
{"op":"mcm","clk":"1004732192","pt":1580636282526,"mc":[{"id":"1.168209732","rc":[{"batb":[[0,4.6,44.47]],"ltp":4.8,"tv":22.71,"id":12986367},{"batb":[[0,2.88,10.31],[1,1.01,0.51],[2,2.88,0]],"ltp":3.25,"tv":350.44,"id":12986368},{"batb":[[0,2.8,11.64],[1,1.01,0.51],[2,2.8,0]],"ltp":0.0,"tv":0.0,"id":18318122}]}]}
{"op":"mcm","clk":"1004732372","pt":1580636285732,"mc":[{"id":"1.168209732","rc":[{"batb":[[0,3.05,72.15],[1,3,54.4],[2,2.88,10.31]],"ltp":3.25,"tv":350.44,"id":12986368},{"batb":[[1,2.7,62.59],[2,2.66,59.16]],"ltp":0.0,"tv":0.0,"id":18318122}]}]}
{"op":"mcm","clk":"1004732440","pt":1580636287648,"mc":[{"id":"1.168209732","rc":[{"batb":[[0,2.88,10.31],[1,1.01,0.51],[2,2.88,0]],"ltp":3.25,"tv":350.44,"id":12986368}]}]}
{"op":"mcm","clk":"1004732585","pt":1580636290850,"mc":[{"id":"1.168209732","rc":[{"batb":[[0,4.7,71.06]],"ltp":0.0,"tv":0.0,"id":18318124},{"batb":[[0,4.1,74.86],[1,4,53.1],[2,2.88,10.31]],"ltp":3.25,"tv":350.44,"id":12986368}]}]}
{"op":"mcm","clk":"1004732628","pt":1580636291736,"mc":[{"id":"1.168209732","rc":[{"batb":[[1,4.5,69.4],[2,4.4,17.86]],"batl":[[0,5.2,16.21],[1,5.3,24.59]],"ltp":4.8,"tv":22.71,"id":12986367},{"batb":[[0,4.8,15.19],[1,4.7,55.48],[2,4.6,49.24]],"batl":[[0,5.5,23.4],[1,5.6,13.69]],"ltp":0.0,"tv":0.0,"id":18318124},{"batb":[[2,3.75,13.22]],"batl":[[1,4.3,12.6],[2,5.9,11.64]],"ltp":3.25,"tv":350.44,"id":12986368},{"batb":[[1,2.74,23.53],[2,2.7,62.59]],"batl":[[0,2.96,11.41],[1,3.1,19.32],[2,3.45,20.22]],"ltp":0.0,"tv":0.0,"id":18318122}]}]}
{"op":"mcm","clk":"1004733213","pt":1580636304771,"mc":[{"id":"1.168209732","rc":[{"batb":[[0,4.5,52.4],[1,4.4,17.86],[2,1.01,0.51]],"batl":[[0,5.3,24.59],[1,5.3,0]],"ltp":4.8,"tv":22.71,"id":12986367},{"batb":[[1,4.7,37.72]],"batl":[[0,5.5,9.24]],"ltp":0.0,"tv":0.0,"id":18318124},{"batb":[[0,3.7,15.12],[1,3.2,19.59],[2,1.01,0.51]],"batl":[[0,4.3,12.6],[1,5.9,11.64],[2,5.9,0]],"ltp":3.25,"tv":350.44,"id":12986368},{"batb":[[0,2.74,23.53],[1,2.32,18.88],[2,1.01,0.51]],"batl":[[0,3.1,19.32],[1,3.45,20.22],[2,3.45,0]],"ltp":0.0,"tv":0.0,"id":18318122}]}]}
{"op":"mcm","clk":"1004733280","pt":1580636306366,"mc":[{"id":"1.168209732","rc":[{"batb":[[0,4.5,40.64]],"batl":[[0,5.3,15.34]],"ltp":4.8,"tv":22.71,"id":12986367},{"batb":[[2,4.6,38.32]],"batl":[[0,5.6,13.69],[1,5.6,0]],"ltp":0.0,"tv":0.0,"id":18318124},{"batb":[[0,3.2,19.59],[1,1.01,0.51],[2,1.01,0]],"batl":[[0,5.9,11.64],[1,5.9,0]],"ltp":3.25,"tv":350.44,"id":12986368},{"batb":[[0,2.32,18.88],[1,1.01,0.51],[2,1.01,0]],"batl":[[0,3.45,20.22],[1,3.45,0]],"ltp":0.0,"tv":0.0,"id":18318122}]}]}
{"op":"mcm","clk":"1004733326","pt":1580636307593,"mc":[{"id":"1.168209732","rc":[{"batb":[[1,4.4,60.94]],"ltp":4.8,"tv":22.71,"id":12986367},{"batb":[[0,3.4,67.09],[1,3.35,41.36],[2,3.2,19.59]],"ltp":3.25,"tv":350.44,"id":12986368},{"batb":[[1,2.16,60.09],[2,2.14,54.42]],"ltp":0.0,"tv":0.0,"id":18318122}]}]}
{"op":"mcm","clk":"1004733518","pt":1580636312272,"mc":[{"id":"1.168209732","rc":[{"batb":[[0,4.4,17.86],[1,1.01,0.51],[2,1.01,0]],"ltp":4.8,"tv":22.71,"id":12986367},{"batb":[[1,1.01,0.51],[2,2.14,0]],"ltp":0.0,"tv":0.0,"id":18318122}]}]}
{"op":"mcm","clk":"1004733662","pt":1580636315876,"mc":[{"id":"1.168209732","rc":[{"batb":[[0,4.7,25.02],[1,4.6,66.95],[2,1.01,0.51]],"batl":[[0,5.3,15.11]],"ltp":4.8,"tv":22.71,"id":12986367},{"batl":[[0,5.5,14.32]],"ltp":0.0,"tv":0.0,"id":18318124},{"batb":[[2,3.2,38.08]],"batl":[[0,3.45,18.96],[1,3.65,15.12],[2,4.3,24.08]],"ltp":3.25,"tv":350.44,"id":12986368},{"batb":[[0,3.15,58.41],[1,3.1,49.96],[2,3.05,20.16]],"batl":[[0,3.45,37.03],[1,3.85,15.66]],"ltp":0.0,"tv":0.0,"id":18318122}]}]}
{"op":"mcm","clk":"1004733670","pt":1580636316083,"mc":[{"id":"1.168209732","rc":[{"batb":[[2,3.2,19.59]],"ltp":3.25,"tv":350.44,"id":12986368}]}]}
{"op":"mcm","clk":"1004733774","pt":1580636318713,"mc":[{"id":"1.168209732","rc":[{"batl":[[1,5.5,9.24]],"ltp":4.8,"tv":22.71,"id":12986367}]}]}
{"op":"mcm","clk":"1004733815","pt":1580636319904,"mc":[{"id":"1.168209732","rc":[{"batb":[[2,4.6,49.24]],"batl":[[0,5.4,9.24],[1,5.5,14.32]],"ltp":0.0,"tv":0.0,"id":18318124},{"batb":[[2,3.2,38.08]],"ltp":3.25,"tv":350.44,"id":12986368}]}]}
{"op":"mcm","clk":"1004734533","pt":1580636334732,"mc":[{"id":"1.168209732","rc":[{"batb":[[0,4.6,56.03],[1,1.01,0.51],[2,1.01,0]],"batl":[[1,5.5,0]],"ltp":4.8,"tv":22.71,"id":12986367},{"batb":[[1,4.7,28.67],[2,4.6,38.32]],"batl":[[0,5.5,14.32],[1,5.5,0]],"ltp":0.0,"tv":0.0,"id":18318124},{"batb":[[0,2.9,25.02],[1,1.01,0.51],[2,3.2,0]],"batl":[[0,4.3,24.08],[1,3.65,0],[2,4.3,0]],"ltp":3.25,"tv":350.44,"id":12986368},{"batb":[[0,2.76,11.96],[1,1.01,0.51],[2,3.05,0]],"batl":[[0,3.85,15.66],[1,3.85,0]],"ltp":0.0,"tv":0.0,"id":18318122}]}]}
{"op":"mcm","clk":"1004734686","pt":1580636337838,"mc":[{"id":"1.168209732","rc":[{"batb":[[0,4.6,65.69],[1,4.5,40.81],[2,1.01,0.51]],"ltp":4.8,"tv":22.71,"id":12986367},{"batb":[[0,3.1,60.14],[1,3.05,52.29],[2,2.9,25.02]],"ltp":3.25,"tv":350.44,"id":12986368},{"batb":[[1,2.68,43.41],[2,2.64,60.48]],"ltp":0.0,"tv":0.0,"id":18318122}]}]}
{"op":"mcm","clk":"1004735585","pt":1580636356783,"mc":[{"id":"1.168209732","rc":[{"batb":[[0,4.6,56.03],[1,1.01,0.51],[2,1.01,0]],"ltp":4.8,"tv":22.71,"id":12986367},{"batb":[[1,1.01,0.51],[2,2.64,0]],"ltp":0.0,"tv":0.0,"id":18318122}]}]}
{"op":"mcm","clk":"1004735709","pt":1580636359672,"mc":[{"id":"1.168209732","rc":[{"batb":[[0,4.7,33.49],[1,4.6,56.03],[2,1.01,0.51]],"ltp":4.8,"tv":22.71,"id":12986367},{"batb":[[0,3.45,54.04],[1,3.4,39.62],[2,2.76,11.96]],"ltp":0.0,"tv":0.0,"id":18318122}]}]}
{"op":"mcm","clk":"1004735754","pt":1580636360597,"mc":[{"id":"1.168209732","rc":[{"batb":[[1,4.6,55.48]],"batl":[[0,5.4,14.95]],"ltp":4.8,"tv":22.71,"id":12986367},{"batb":[[0,4.7,44.33],[1,4.6,38.32],[2,1.01,0.51]],"batl":[[0,5.4,14.71]],"ltp":0.0,"tv":0.0,"id":18318124},{"batl":[[0,3.15,24],[1,3.55,17.94]],"ltp":3.25,"tv":350.44,"id":12986368},{"batb":[[0,3.5,16.21],[1,3.45,54.04],[2,3.4,39.62]],"batl":[[1,4.3,24.86]],"ltp":0.0,"tv":0.0,"id":18318122}]}]}
{"op":"mcm","clk":"1004735806","pt":1580636361885,"mc":[{"id":"1.168209732","rc":[{"batb":[[1,4.6,66.4]],"batl":[[0,5.4,24.19]],"ltp":4.8,"tv":22.71,"id":12986367},{"batb":[[1,4.6,49.24]],"batl":[[0,5.4,23.96]],"ltp":0.0,"tv":0.0,"id":18318124},{"batb":[[2,2.98,21]],"batl":[[1,3.35,17.64],[2,3.55,17.94]],"ltp":3.25,"tv":350.44,"id":12986368},{"batl":[[0,3.85,29.94]],"ltp":0.0,"tv":0.0,"id":18318122}]}]}
{"op":"mcm","clk":"1004736616","pt":1580636379695,"mc":[{"id":"1.168209732","rc":[{"batb":[[0,2.98,21],[1,2.72,11.88],[2,1.01,0.51]],"batl":[[0,3.35,17.64],[1,3.55,17.94],[2,3.55,0]],"ltp":3.25,"tv":350.44,"id":12986368},{"batb":[[0,3.35,17.64],[1,3.1,21.72],[2,1.01,0.51]],"batl":[[0,3.85,14.28]],"ltp":0.0,"tv":0.0,"id":18318122}]}]}
{"op":"mcm","clk":"1004736659","pt":1580636380528,"mc":[{"id":"1.168209732","rc":[{"batb":[[1,4.6,55.48]],"batl":[[0,5.4,14.95]],"ltp":4.8,"tv":22.71,"id":12986367},{"batb":[[1,4.6,38.32]],"batl":[[0,5.4,14.71]],"ltp":0.0,"tv":0.0,"id":18318124},{"batb":[[0,2.72,11.88],[1,1.01,0.51],[2,1.01,0]],"batl":[[0,3.55,17.94],[1,3.55,0]],"ltp":3.25,"tv":350.44,"id":12986368},{"batb":[[0,3.1,21.72],[1,1.01,0.51],[2,1.01,0]],"batl":[[0,4.3,24.86],[1,4.3,0]],"ltp":0.0,"tv":0.0,"id":18318122}]}]}
{"op":"mcm","clk":"1004736791","pt":1580636382896,"mc":[{"id":"1.168209732","rc":[{"batb":[[0,2.96,37.32],[1,2.92,47.02],[2,2.72,11.88]],"ltp":3.25,"tv":350.44,"id":12986368},{"batb":[[0,3.1,64.06],[1,3.05,51.99],[2,1.01,0.51]],"ltp":0.0,"tv":0.0,"id":18318122}]}]}
{"op":"mcm","clk":"1004737644","pt":1580636398841,"mc":[{"id":"1.168209732","rc":[{"batb":[[0,2.72,11.88],[1,1.01,0.51],[2,2.72,0]],"ltp":3.25,"tv":350.44,"id":12986368},{"batb":[[0,3.1,21.72],[1,1.01,0.51],[2,1.01,0]],"ltp":0.0,"tv":0.0,"id":18318122}]}]}
{"op":"mcm","clk":"1004737799","pt":1580636401940,"mc":[{"id":"1.168209732","rc":[{"batb":[[0,3.15,75.82],[1,3.1,50.05],[2,2.72,11.88]],"ltp":3.25,"tv":350.44,"id":12986368},{"batb":[[0,3.4,30.15],[1,3.35,41.31],[2,3.1,21.72]],"ltp":0.0,"tv":0.0,"id":18318122}]}]}
{"op":"mcm","clk":"1004738093","pt":1580636408739,"mc":[{"id":"1.168209732","rc":[{"batb":[[0,2.72,11.88],[1,1.01,0.51],[2,2.72,0]],"ltp":3.25,"tv":350.44,"id":12986368},{"batb":[[0,3.1,21.72],[1,1.01,0.51],[2,3.1,0]],"ltp":0.0,"tv":0.0,"id":18318122}]}]}
{"op":"mcm","clk":"1004738230","pt":1580636411473,"mc":[{"id":"1.168209732","rc":[{"batb":[[0,2.96,37.32],[1,2.92,47.02],[2,2.72,11.88]],"ltp":3.25,"tv":350.44,"id":12986368},{"batb":[[0,3.1,64.06],[1,3.05,51.99],[2,1.01,0.51]],"ltp":0.0,"tv":0.0,"id":18318122}]}]}
{"op":"mcm","clk":"1004738718","pt":1580636421781,"mc":[{"id":"1.168209732","rc":[{"batb":[[0,3.1,21.72],[1,1.01,0.51],[2,1.01,0]],"ltp":0.0,"tv":0.0,"id":18318122}]}]}
{"op":"mcm","clk":"1004738883","pt":1580636424923,"mc":[{"id":"1.168209732","rc":[{"batb":[[0,4.7,49.46]],"ltp":4.8,"tv":22.71,"id":12986367},{"trd":[[2.96,23.28]],"batb":[[0,2.96,25.68]],"batl":[[0,3.1,24.39],[1,3.55,17.94]],"ltp":2.96,"tv":373.72,"id":12986368},{"batb":[[0,3.85,13.14],[1,3.7,36.85],[2,3.65,33.5]],"batl":[[1,4.9,18.33]],"ltp":0.0,"tv":0.0,"id":18318122}],"tv":396.44}]}
{"op":"mcm","clk":"1004738929","pt":1580636425494,"mc":[{"id":"1.168209732","rc":[{"batb":[[1,4.6,50.11]],"batl":[[0,5.4,23.88]],"ltp":4.8,"tv":22.71,"id":12986367},{"batb":[[1,4.6,49.24]],"batl":[[0,5.4,23.96]],"ltp":0.0,"tv":0.0,"id":18318124},{"batb":[[2,2.78,23.53]],"batl":[[0,3.1,43.72],[1,3.55,0]],"ltp":2.96,"tv":373.72,"id":12986368},{"batl":[[0,4.2,12.6],[1,4.3,24.86],[2,4.9,18.33]],"ltp":0.0,"tv":0.0,"id":18318122}]}]}
{"op":"mcm","clk":"1004739336","pt":1580636433714,"mc":[{"id":"1.168209732","rc":[{"batb":[[0,4.7,49.31]],"ltp":4.8,"tv":22.71,"id":12986367},{"batb":[[0,4.7,28.67],[1,4.6,65.53]],"batl":[[0,5.3,15.19],[1,5.4,9.24]],"ltp":0.0,"tv":0.0,"id":18318124},{"trd":[[2.96,45.63]],"batb":[[0,2.78,23.53],[1,2.76,11.41],[2,2.52,14.56]],"batl":[[0,3.1,19.32],[1,3.2,23.53]],"ltp":2.96,"tv":396.07,"id":12986368},{"batb":[[0,3.8,13.38]],"batl":[[0,4.2,25.59],[1,4.8,18.88],[2,4.9,0]],"ltp":0.0,"tv":0.0,"id":18318122}],"tv":418.78}]}
{"op":"mcm","clk":"1004739460","pt":1580636436592,"mc":[{"id":"1.168209732","rc":[{"batb":[[0,2.94,56.42],[1,2.9,47.69],[2,2.78,23.53]],"ltp":2.96,"tv":396.07,"id":12986368}]}]}
{"op":"mcm","clk":"1004739657","pt":1580636441325,"mc":[{"id":"1.168209732","rc":[{"batb":[[0,4.7,49.15]],"batl":[[0,5.4,9.24],[1,5.5,14.48]],"ltp":4.8,"tv":22.71,"id":12986367},{"batl":[[0,5.2,15.89],[1,5.3,15.19],[2,5.4,9.24]],"ltp":0.0,"tv":0.0,"id":18318124},{"batb":[[2,2.8,11.02]],"batl":[[0,3,10.78],[1,3.1,19.32],[2,3.25,22.66]],"ltp":2.96,"tv":396.07,"id":12986368},{"batb":[[0,3.75,13.77]],"ltp":0.0,"tv":0.0,"id":18318122}]}]}
{"op":"mcm","clk":"1004740690","pt":1580636461738,"mc":[{"id":"1.168209732","rc":[{"batb":[[0,2.8,11.02],[1,2.78,23.53],[2,2.56,14.01]],"ltp":2.96,"tv":396.07,"id":12986368},{"batb":[[1,3.6,15.96],[2,3.45,16.76]],"ltp":0.0,"tv":0.0,"id":18318122}]}]}
{"op":"mcm","clk":"1004740847","pt":1580636464579,"mc":[{"id":"1.168209732","rc":[{"batb":[[2,2.68,47.84]],"ltp":2.96,"tv":396.07,"id":12986368},{"batb":[[2,3.45,78.96]],"ltp":0.0,"tv":0.0,"id":18318122}]}]}
{"op":"mcm","clk":"1004741464","pt":1580636476585,"mc":[{"id":"1.168209732","rc":[{"batb":[[1,4.6,39.19]],"batl":[[0,5.5,14.48],[1,5.5,0]],"ltp":4.8,"tv":22.71,"id":12986367},{"batb":[[1,4.6,54.61]],"batl":[[0,5.3,15.19],[1,5.3,0],[2,5.4,0]],"ltp":0.0,"tv":0.0,"id":18318124},{"batb":[[0,2.68,47.84],[1,2.64,60.89],[2,2.56,14.01]],"batl":[[0,3.25,22.66],[1,3.1,0],[2,3.25,0]],"ltp":2.96,"tv":396.07,"id":12986368},{"batb":[[0,3.45,78.96],[1,3.4,39.56],[2,1.01,0.51]],"batl":[[0,4.8,18.88],[1,4.8,0]],"ltp":0.0,"tv":0.0,"id":18318122}]}]}
{"op":"mcm","clk":"1004742270","pt":1580636489428,"mc":[{"id":"1.168209732","rc":[{"batb":[[0,2.56,14.01],[1,1.01,0.51],[2,2.56,0]],"ltp":2.96,"tv":396.07,"id":12986368}]}]}
{"op":"mcm","clk":"1004742433","pt":1580636492926,"mc":[{"id":"1.168209732","rc":[{"batb":[[0,3.1,57.47],[1,3.05,52.27],[2,2.56,14.01]],"ltp":2.96,"tv":396.07,"id":12986368}]}]}
{"op":"mcm","clk":"1004742458","pt":1580636493490,"mc":[{"id":"1.168209732","rc":[{"batb":[[1,4.6,50.11]],"batl":[[0,5.4,23.8]],"ltp":4.8,"tv":22.71,"id":12986367},{"batb":[[1,4.6,65.53]],"batl":[[0,5.3,24.43]],"ltp":0.0,"tv":0.0,"id":18318124},{"batb":[[2,2.98,23.53]],"batl":[[0,3.25,41.14],[1,3.45,19.59]],"ltp":2.96,"tv":396.07,"id":12986368},{"batb":[[0,3.45,95.76],[2,3.25,19.43]],"batl":[[0,3.8,16.21],[1,3.95,13.44],[2,4.3,25.34]],"ltp":0.0,"tv":0.0,"id":18318122}]}]}
{"op":"mcm","clk":"1004743491","pt":1580636509555,"mc":[{"id":"1.168209732","rc":[{"batb":[[0,2.88,21.85],[1,2.74,11.57],[2,1.01,0.51]],"batl":[[0,3.25,18.48]],"ltp":2.96,"tv":396.07,"id":12986368},{"batb":[[0,3.45,16.8],[1,3.25,19.43],[2,1.01,0.51]],"batl":[[0,3.95,13.44],[1,4.3,25.34],[2,4.3,0]],"ltp":0.0,"tv":0.0,"id":18318122}]}]}
{"op":"mcm","clk":"1004743570","pt":1580636510742,"mc":[{"id":"1.168209732","rc":[{"batb":[[1,4.6,39.19]],"batl":[[0,5.4,14.56]],"ltp":4.8,"tv":22.71,"id":12986367},{"batb":[[1,4.6,54.61]],"batl":[[0,5.3,15.19]],"ltp":0.0,"tv":0.0,"id":18318124},{"batb":[[0,2.74,11.57],[1,1.01,0.51],[2,1.01,0]],"batl":[[0,3.45,19.59],[1,3.45,0]],"ltp":2.96,"tv":396.07,"id":12986368},{"batb":[[0,3.25,19.43],[1,1.01,0.51],[2,1.01,0]],"batl":[[0,4.3,25.34],[1,4.3,0]],"ltp":0.0,"tv":0.0,"id":18318122}]}]}
{"op":"mcm","clk":"1004743724","pt":1580636512955,"mc":[{"id":"1.168209732","rc":[{"batb":[[1,4.6,55.16]],"ltp":4.8,"tv":22.71,"id":12986367},{"batb":[[0,2.86,57.66],[1,2.82,51.23],[2,2.76,11.57]],"ltp":2.96,"tv":396.07,"id":12986368},{"batb":[[0,3.3,60.65],[1,3.25,63.66],[2,1.01,0.51]],"ltp":0.0,"tv":0.0,"id":18318122}]}]}
{"op":"mcm","clk":"1004743789","pt":1580636513937,"mc":[{"id":"1.168209732","rc":[{"batb":[[0,4.7,33.49]],"ltp":4.8,"tv":22.71,"id":12986367},{"batl":[[0,4.3,24.78]],"ltp":0.0,"tv":0.0,"id":18318122}]}]}
{"op":"mcm","clk":"1004744759","pt":1580636530186,"mc":[{"id":"1.168209732","rc":[{"batb":[[0,2.76,11.57],[1,1.01,0.51],[2,2.76,0]],"ltp":2.96,"tv":396.07,"id":12986368},{"batb":[[0,3.25,19.43],[1,1.01,0.51],[2,1.01,0]],"ltp":0.0,"tv":0.0,"id":18318122}]}]}
{"op":"mcm","clk":"1004745011","pt":1580636533898,"mc":[{"id":"1.168209732","rc":[{"batb":[[1,4.6,66.08]],"batl":[[1,5.5,9.24]],"ltp":4.8,"tv":22.71,"id":12986367},{"batb":[[1,4.6,65.37]],"batl":[[0,5.3,24.43]],"ltp":0.0,"tv":0.0,"id":18318124},{"batb":[[0,3.25,47.17],[1,3.2,46.46],[2,3.15,20.3]],"batl":[[0,3.45,36.4],[1,3.65,17.23]],"ltp":2.96,"tv":396.07,"id":12986368},{"batb":[[0,3.3,60.65],[1,3.25,82.15],[2,3.1,21.95]],"batl":[[0,3.55,18.88],[1,3.75,15.12],[2,3.85,15.66]],"ltp":0.0,"tv":0.0,"id":18318122}]}]}
{"op":"mcm","clk":"1004745549","pt":1580636540680,"mc":[{"id":"1.168209732","rc":[{"batb":[[1,4.6,55.16]],"batl":[[1,5.5,0]],"ltp":4.8,"tv":22.71,"id":12986367},{"batb":[[0,4.6,54.45],[1,1.01,0.51],[2,1.01,0]],"batl":[[0,5.3,15.19]],"ltp":0.0,"tv":0.0,"id":18318124},{"batb":[[0,2.94,24.55],[1,1.01,0.51],[2,3.15,0]],"batl":[[0,3.65,17.23],[1,3.65,0]],"ltp":2.96,"tv":396.07,"id":12986368},{"batb":[[0,3.1,21.95],[1,1.01,0.51],[2,3.1,0]],"batl":[[0,3.85,15.66],[1,3.75,0],[2,3.85,0]],"ltp":0.0,"tv":0.0,"id":18318122}]}]}
{"op":"mcm","clk":"1004745734","pt":1580636543891,"mc":[{"id":"1.168209732","rc":[{"batb":[[0,4.6,75.23],[1,4.5,40.1],[2,1.01,0.51]],"ltp":0.0,"tv":0.0,"id":18318124},{"batb":[[0,3.05,56.37],[1,3,54.5],[2,2.94,24.55]],"ltp":2.96,"tv":396.07,"id":12986368},{"batb":[[0,3.2,62.36],[1,3.15,47.8],[2,3.1,21.95]],"ltp":0.0,"tv":0.0,"id":18318122}]}]}
{"op":"mcm","clk":"1004745747","pt":1580636544093,"mc":[{"id":"1.168209732","rc":[{"batb":[[0,2.94,24.55],[1,1.01,0.51],[2,2.94,0]],"ltp":2.96,"tv":396.07,"id":12986368}]}]}
{"op":"mcm","clk":"1004745953","pt":1580636547910,"mc":[{"id":"1.168209732","rc":[{"batb":[[1,4.6,66.08]],"batl":[[0,5.3,15.26],[1,5.5,9.24]],"ltp":4.8,"tv":22.71,"id":12986367},{"batb":[[1,4.5,51.86]],"batl":[[0,5.3,24.43]],"ltp":0.0,"tv":0.0,"id":18318124},{"batb":[[0,3.35,51.58],[1,3.3,60.8],[2,3.15,19.32]],"batl":[[0,3.55,15.96],[1,3.65,17.23],[2,3.75,16.05]],"ltp":2.96,"tv":396.07,"id":12986368},{"batb":[[1,3.15,67.12]],"batl":[[0,3.4,21.17],[1,3.6,34.3]],"ltp":0.0,"tv":0.0,"id":18318122}]}]}
{"op":"mcm","clk":"1004746555","pt":1580636560842,"mc":[{"id":"1.168209732","rc":[{"batb":[[0,4.7,23.74],[1,4.6,55.16]],"batl":[[1,5.5,0]],"ltp":4.8,"tv":22.71,"id":12986367},{"batb":[[1,4.5,40.1]],"batl":[[0,5.3,15.19]],"ltp":0.0,"tv":0.0,"id":18318124},{"batb":[[0,3.1,20.69],[1,1.01,0.51],[2,3.15,0]],"batl":[[0,3.75,16.05],[1,3.65,0],[2,3.75,0]],"ltp":2.96,"tv":396.07,"id":12986368},{"batb":[[0,3.15,47.8],[1,3,23.76],[2,1.01,0.51]],"batl":[[0,3.6,18.33],[1,3.6,0]],"ltp":0.0,"tv":0.0,"id":18318122}]}]}
{"op":"mcm","clk":"1004746691","pt":1580636563836,"mc":[{"id":"1.168209732","rc":[{"batb":[[0,3.2,65.28],[1,3.15,48.15],[2,3.1,20.69]],"ltp":2.96,"tv":396.07,"id":12986368},{"batb":[[1,3.1,49.84],[2,3,23.76]],"ltp":0.0,"tv":0.0,"id":18318122}]}]}
{"op":"mcm","clk":"1004747267","pt":1580636574860,"mc":[{"id":"1.168209732","rc":[{"batb":[[0,3.1,20.69],[1,1.01,0.51],[2,3.1,0]],"ltp":2.96,"tv":396.07,"id":12986368}]}]}
{"op":"mcm","clk":"1004747399","pt":1580636577550,"mc":[{"id":"1.168209732","rc":[{"batb":[[0,4.7,44.63]],"batl":[[1,5.5,9.24]],"ltp":4.8,"tv":22.71,"id":12986367},{"batb":[[2,4.4,11.76]],"batl":[[0,5.2,9.24],[1,5.3,15.19]],"ltp":0.0,"tv":0.0,"id":18318124},{"batb":[[0,3.4,68.17],[1,3.35,41.31],[2,3.3,17.64]],"batl":[[0,3.75,31.17]],"ltp":2.96,"tv":396.07,"id":12986368},{"batb":[[2,3,44.77]],"batl":[[0,3.45,16.8],[1,3.6,18.33]],"ltp":0.0,"tv":0.0,"id":18318122}]}]}
{"op":"mcm","clk":"1004747437","pt":1580636578268,"mc":[{"id":"1.168209732","rc":[{"batl":[[1,5.4,15.11]],"ltp":0.0,"tv":0.0,"id":18318124},{"batb":[[0,3.4,84.77]],"batl":[[1,4.4,22.74]],"ltp":2.96,"tv":396.07,"id":12986368},{"batl":[[0,3.3,22.82],[1,3.45,16.8],[2,3.55,19.2]],"ltp":0.0,"tv":0.0,"id":18318122}]}]}
{"op":"mcm","clk":"1004749109","pt":1580636609830,"mc":[{"id":"1.168209732","rc":[{"batb":[[0,4.6,64.76]],"ltp":0.0,"tv":0.0,"id":18318124},{"batb":[[0,3.3,17.64],[1,3.2,19.67],[2,1.01,0.51]],"batl":[[0,3.75,15.12]],"ltp":2.96,"tv":396.07,"id":12986368},{"batb":[[0,3,21],[1,2.72,12.51],[2,1.01,0.51]],"batl":[[0,3.45,16.8],[1,3.55,19.2],[2,3.55,0]],"ltp":0.0,"tv":0.0,"id":18318122}]}]}
{"op":"mcm","clk":"1004749160","pt":1580636610812,"mc":[{"id":"1.168209732","rc":[{"batb":[[0,4.7,33.71]],"batl":[[1,5.5,0]],"ltp":4.8,"tv":22.71,"id":12986367},{"batb":[[2,1.01,0.51]],"batl":[[0,5.4,15.11],[1,5.4,0]],"ltp":0.0,"tv":0.0,"id":18318124},{"batb":[[0,3.2,19.67],[1,1.01,0.51],[2,1.01,0]],"batl":[[0,4.4,22.74],[1,4.4,0]],"ltp":2.96,"tv":396.07,"id":12986368},{"batb":[[0,2.72,12.51],[1,1.01,0.51],[2,1.01,0]],"batl":[[0,3.55,19.2],[1,3.55,0]],"ltp":0.0,"tv":0.0,"id":18318122}]}]}
{"op":"mcm","clk":"1004749257","pt":1580636612914,"mc":[{"id":"1.168209732","rc":[{"batl":[[0,5.4,14.95]],"ltp":0.0,"tv":0.0,"id":18318124},{"batb":[[0,3.2,76.66],[1,3.15,67.95],[2,1.01,0.51]],"ltp":2.96,"tv":396.07,"id":12986368},{"batb":[[0,2.84,43.45],[1,2.8,51.9],[2,2.72,12.51]],"batl":[[0,3.55,19.04]],"ltp":0.0,"tv":0.0,"id":18318122}]}]}
{"op":"mcm","clk":"1004750172","pt":1580636634728,"mc":[{"id":"1.168209732","rc":[{"batb":[[0,2.72,12.51],[1,1.01,0.51],[2,2.72,0]],"ltp":0.0,"tv":0.0,"id":18318122}]}]}
{"op":"mcm","clk":"1004750289","pt":1580636637756,"mc":[{"id":"1.168209732","rc":[{"batb":[[0,3.35,46.85],[1,3.3,42.73],[2,2.72,12.51]],"ltp":0.0,"tv":0.0,"id":18318122}]}]}
{"op":"mcm","clk":"1004750322","pt":1580636638576,"mc":[{"id":"1.168209732","rc":[{"batl":[[0,5.3,15.26]],"ltp":0.0,"tv":0.0,"id":18318124},{"batb":[[2,3,23.13]],"batl":[[0,3.5,19.2],[1,3.9,15.03]],"ltp":2.96,"tv":396.07,"id":12986368},{"batb":[[2,3.2,19.75]],"batl":[[1,3.8,16.13]],"ltp":0.0,"tv":0.0,"id":18318122}]}]}
{"op":"mcm","clk":"1004750365","pt":1580636639651,"mc":[{"id":"1.168209732","rc":[{"batb":[[0,4.7,44.63]],"batl":[[1,5.5,9.24]],"ltp":4.8,"tv":22.71,"id":12986367},{"batb":[[2,4.4,11.76]],"batl":[[0,5.2,9.24],[1,5.3,15.26]],"ltp":0.0,"tv":0.0,"id":18318124},{"batb":[[2,3.1,19.32]],"batl":[[1,3.55,15.96],[2,3.9,15.03]],"ltp":2.96,"tv":396.07,"id":12986368},{"batb":[[2,3.2,38.23]],"batl":[[1,3.65,15.12],[2,3.8,16.13]],"ltp":0.0,"tv":0.0,"id":18318122}]}]}
{"op":"mcm","clk":"1004751037","pt":1580636657572,"mc":[{"id":"1.168209732","rc":[{"batb":[[0,4.7,10.92],[1,4.6,15.97]],"ltp":4.8,"tv":22.71,"id":12986367},{"batb":[[0,4.6,16.13],[1,4.4,11.76],[2,1.01,0.51]],"ltp":0.0,"tv":0.0,"id":18318124},{"batb":[[0,3.15,19.91],[1,3.1,19.32],[2,3,23.13]],"ltp":2.96,"tv":396.07,"id":12986368},{"batb":[[0,3.2,38.23],[1,2.92,25.26],[2,1.01,0.51]],"ltp":0.0,"tv":0.0,"id":18318122}]}]}
{"op":"mcm","clk":"1004751084","pt":1580636658607,"mc":[{"id":"1.168209732","rc":[{"batb":[[0,4.6,15.97],[1,1.01,0.51],[2,1.01,0]],"batl":[[1,5.5,0]],"ltp":4.8,"tv":22.71,"id":12986367},{"batb":[[1,1.01,0.51],[2,1.01,0]],"batl":[[0,5.3,15.26],[1,5.3,0]],"ltp":0.0,"tv":0.0,"id":18318124},{"batb":[[1,3,23.13],[2,1.01,0.51]],"batl":[[1,3.9,15.03],[2,3.9,0]],"ltp":2.96,"tv":396.07,"id":12986368},{"batb":[[0,3.2,19.75]],"batl":[[1,3.8,16.13],[2,3.8,0]],"ltp":0.0,"tv":0.0,"id":18318122}]}]}
{"op":"mcm","clk":"1004751112","pt":1580636659171,"mc":[{"id":"1.168209732","rc":[{"batb":[[0,1.01,0.51],[1,1.01,0]],"ltp":4.8,"tv":22.71,"id":12986367},{"batb":[[0,1.01,0.51],[1,1.01,0]],"ltp":0.0,"tv":0.0,"id":18318124},{"batb":[[0,1.01,0.51],[1,3,0],[2,1.01,0]],"ltp":2.96,"tv":396.07,"id":12986368},{"batb":[[0,1.01,0.51],[1,2.92,0],[2,1.01,0]],"ltp":0.0,"tv":0.0,"id":18318122}]}]}
{"op":"mcm","clk":"1004761451","pt":1580636882795,"mc":[{"id":"1.168209732","rc":[{"batb":[[0,4.7,38.49],[1,4.6,39],[2,1.01,0.51]],"ltp":4.8,"tv":22.71,"id":12986367},{"batb":[[0,4.6,39.46],[1,4.5,40.44],[2,1.01,0.51]],"ltp":0.0,"tv":0.0,"id":18318124},{"batb":[[0,2.74,45.27],[1,2.7,57.42],[2,1.01,0.51]],"ltp":2.96,"tv":396.07,"id":12986368},{"batb":[[0,4.1,60.99],[1,4,52.81],[2,1.01,0.51]],"ltp":0.0,"tv":0.0,"id":18318122}]}]}
{"op":"mcm","clk":"1004761512","pt":1580636883928,"mc":[{"id":"1.168209732","rc":[{"batb":[[1,4.6,49.92]],"batl":[[0,5.4,9.24]],"ltp":4.8,"tv":22.71,"id":12986367},{"batb":[[0,4.5,52.2],[1,1.01,0.51],[2,1.01,0]],"batl":[[0,5.3,9.24]],"ltp":0.0,"tv":0.0,"id":18318124},{"batb":[[0,2.54,26.89],[1,1.01,0.51],[2,1.01,0]],"batl":[[0,2.86,21.85]],"ltp":2.96,"tv":396.07,"id":12986368},{"batb":[[0,4.1,46.53]],"batl":[[0,4.8,10.92]],"ltp":0.0,"tv":0.0,"id":18318122}]}]}
{"op":"mcm","clk":"1004761627","pt":1580636886604,"mc":[{"id":"1.168209732","rc":[{"batb":[[0,4.7,57.56]],"ltp":4.8,"tv":22.71,"id":12986367},{"batb":[[0,4.5,67.92],[1,4.4,41.9],[2,1.01,0.51]],"ltp":0.0,"tv":0.0,"id":18318124},{"batb":[[0,2.76,57.13],[1,2.72,56.55],[2,2.54,26.89]],"ltp":2.96,"tv":396.07,"id":12986368}]}]}
{"op":"mcm","clk":"1004761780","pt":1580636889829,"mc":[{"id":"1.168209732","rc":[{"batl":[[0,2.84,22.69]],"ltp":2.96,"tv":396.07,"id":12986368}]}]}
{"op":"mcm","clk":"1004762131","pt":1580636897344,"mc":[{"id":"1.168209732","rc":[{"batb":[[0,4.6,10.92],[1,1.01,0.51],[2,1.01,0]],"ltp":4.8,"tv":22.71,"id":12986367},{"batb":[[0,4.5,11.76],[1,1.01,0.51],[2,1.01,0]],"ltp":0.0,"tv":0.0,"id":18318124},{"batb":[[0,2.54,26.89],[1,1.01,0.51],[2,2.54,0]],"ltp":2.96,"tv":396.07,"id":12986368},{"batb":[[0,4.1,13.44],[1,1.01,0.51],[2,1.01,0]],"ltp":0.0,"tv":0.0,"id":18318122}]}]}
{"op":"mcm","clk":"1004762451","pt":1580636902946,"mc":[{"id":"1.168209732","rc":[{"batb":[[0,1.01,0.51],[1,1.01,0]],"ltp":4.8,"tv":22.71,"id":12986367},{"batb":[[0,1.01,0.51],[1,1.01,0]],"ltp":0.0,"tv":0.0,"id":18318124},{"batb":[[0,1.01,0.51],[1,1.01,0]],"ltp":2.96,"tv":396.07,"id":12986368},{"batb":[[0,1.01,0.51],[1,1.01,0]],"ltp":0.0,"tv":0.0,"id":18318122}]}]}
{"op":"mcm","clk":"1004763396","pt":1580636921867,"mc":[{"id":"1.168209732","rc":[{"batb":[[0,4.5,11.76],[1,1.01,0.51]],"batl":[[0,5.4,9.24]],"ltp":4.8,"tv":22.71,"id":12986367},{"batb":[[0,4.5,11.76],[1,1.01,0.51]],"batl":[[0,5.3,9.24]],"ltp":0.0,"tv":0.0,"id":18318124},{"batb":[[0,2.64,25.21],[1,1.01,0.51]],"batl":[[0,2.98,21]],"ltp":2.96,"tv":396.07,"id":12986368},{"batb":[[0,3.9,14.28],[1,1.01,0.51]],"batl":[[0,4.5,11.76]],"ltp":0.0,"tv":0.0,"id":18318122}]}]}
{"op":"mcm","clk":"1004763454","pt":1580636922892,"mc":[{"id":"1.168209732","rc":[{"batb":[[0,1.01,0.51],[1,1.01,0]],"ltp":2.96,"tv":396.07,"id":12986368}]}]}
{"op":"mcm","clk":"1004763459","pt":1580636922994,"mc":[{"id":"1.168209732","rc":[{"batb":[[0,4.7,49.83],[1,4.6,39.17],[2,4.5,11.76]],"ltp":4.8,"tv":22.71,"id":12986367},{"batb":[[0,4.5,74],[1,4.4,41.77],[2,1.01,0.51]],"ltp":0.0,"tv":0.0,"id":18318124},{"batb":[[0,2.88,59.62],[1,2.84,50.58],[2,1.01,0.51]],"ltp":2.96,"tv":396.07,"id":12986368},{"batb":[[1,3.85,37.94],[2,3.8,30.15]],"ltp":0.0,"tv":0.0,"id":18318122}]}]}
{"op":"mcm","clk":"1004763543","pt":1580636924280,"mc":[{"id":"1.168209732","rc":[{"batb":[[2,2.66,25.21]],"ltp":2.96,"tv":396.07,"id":12986368}]}]}
{"op":"mcm","clk":"1004763924","pt":1580636931503,"mc":[{"id":"1.168209732","rc":[{"batb":[[0,4.5,52.08],[1,1.01,0.51],[2,1.01,0]],"ltp":0.0,"tv":0.0,"id":18318124}]}]}
{"op":"mcm","clk":"1004764100","pt":1580636934904,"mc":[{"id":"1.168209732","rc":[{"batb":[[2,1.01,0.51]],"ltp":4.8,"tv":22.71,"id":12986367},{"batb":[[0,4.6,22.52],[1,4.5,40.32],[2,1.01,0.51]],"ltp":0.0,"tv":0.0,"id":18318124},{"batb":[[2,1.01,0.51]],"ltp":2.96,"tv":396.07,"id":12986368},{"batb":[[0,3.85,37.94],[1,3.8,30.15],[2,1.01,0.51]],"ltp":0.0,"tv":0.0,"id":18318122}]}]}
{"op":"mcm","clk":"1004764104","pt":1580636935007,"mc":[{"id":"1.168209732","rc":[{"batb":[[0,4.7,39.26]],"ltp":4.8,"tv":22.71,"id":12986367},{"batb":[[0,4.5,40.32],[1,1.01,0.51],[2,1.01,0]],"ltp":0.0,"tv":0.0,"id":18318124},{"batb":[[0,1.01,0.51],[1,2.84,0],[2,1.01,0]],"ltp":2.96,"tv":396.07,"id":12986368},{"batb":[[0,1.01,0.51],[1,3.8,0],[2,1.01,0]],"ltp":0.0,"tv":0.0,"id":18318122}]}]}
{"op":"mcm","clk":"1004764328","pt":1580636938918,"mc":[{"id":"1.168209732","rc":[{"batb":[[1,4.4,42.11],[2,1.01,0.51]],"ltp":0.0,"tv":0.0,"id":18318124},{"batb":[[0,2.46,49.12],[1,2.42,77.2],[2,1.01,0.51]],"ltp":2.96,"tv":396.07,"id":12986368},{"batb":[[0,3.45,30.05],[1,3.4,39.54],[2,1.01,0.51]],"ltp":0.0,"tv":0.0,"id":18318122}]}]}
{"op":"mcm","clk":"1004764351","pt":1580636939489,"mc":[{"id":"1.168209732","rc":[{"batb":[[1,1.01,0.51],[2,1.01,0]],"ltp":0.0,"tv":0.0,"id":18318124},{"batb":[[0,1.01,0.51],[1,2.42,0],[2,1.01,0]],"ltp":2.96,"tv":396.07,"id":12986368}]}]}
{"op":"mcm","clk":"1004764528","pt":1580636942692,"mc":[{"id":"1.168209732","rc":[{"batb":[[0,4.6,32.6],[1,4.5,40.32],[2,1.01,0.51]],"ltp":0.0,"tv":0.0,"id":18318124},{"batb":[[0,3.15,68.77],[1,3.1,50.38],[2,1.01,0.51]],"ltp":2.96,"tv":396.07,"id":12986368},{"batb":[[0,3.4,39.54],[1,1.01,0.51],[2,1.01,0]],"ltp":0.0,"tv":0.0,"id":18318122}]}]}
{"op":"mcm","clk":"1004764598","pt":1580636943890,"mc":[{"id":"1.168209732","rc":[{"batb":[[2,4.5,11.76]],"batl":[[0,5.3,9.24]],"ltp":4.8,"tv":22.71,"id":12986367},{"batb":[[1,4.5,52.08]],"batl":[[0,5.4,9.24]],"ltp":0.0,"tv":0.0,"id":18318124},{"batb":[[2,2.86,21.85]],"batl":[[0,3.25,18.48]],"ltp":2.96,"tv":396.07,"id":12986368},{"batb":[[0,3.5,16.8],[1,3.4,39.54],[2,1.01,0.51]],"batl":[[0,4.1,13.44]],"ltp":0.0,"tv":0.0,"id":18318122}]}]}
{"op":"mcm","clk":"1004764692","pt":1580636945746,"mc":[{"id":"1.168209732","rc":[{"batb":[[1,3.4,68.05],[2,3.35,40.63]],"batl":[[0,4,13.44]],"ltp":0.0,"tv":0.0,"id":18318122}]}]}
{"op":"mcm","clk":"1004765273","pt":1580636954938,"mc":[{"id":"1.168209732","rc":[{"batb":[[0,2.86,21.85],[1,1.01,0.51],[2,2.86,0]],"ltp":2.96,"tv":396.07,"id":12986368},{"batb":[[1,1.01,0.51],[2,3.35,0]],"ltp":0.0,"tv":0.0,"id":18318122}]}]}
{"op":"mcm","clk":"1004765290","pt":1580636955247,"mc":[{"id":"1.168209732","rc":[{"batb":[[2,1.01,0.51]],"ltp":4.8,"tv":22.71,"id":12986367},{"batb":[[1,4.5,40.32]],"ltp":0.0,"tv":0.0,"id":18318124},{"batb":[[0,1.01,0.51],[1,1.01,0]],"ltp":2.96,"tv":396.07,"id":12986368},{"batb":[[0,1.01,0.51],[1,1.01,0]],"ltp":0.0,"tv":0.0,"id":18318122}]}]}
{"op":"mcm","clk":"1004765423","pt":1580636957839,"mc":[{"id":"1.168209732","rc":[{"batb":[[0,2.84,51.73],[1,2.8,52.51],[2,1.01,0.51]],"ltp":2.96,"tv":396.07,"id":12986368},{"batb":[[0,3.2,72.63],[1,3.15,47.3],[2,1.01,0.51]],"ltp":0.0,"tv":0.0,"id":18318122}]}]}
{"op":"mcm","clk":"1004765459","pt":1580636958410,"mc":[{"id":"1.168209732","rc":[{"batb":[[0,1.01,0.51],[1,2.8,0],[2,1.01,0]],"ltp":2.96,"tv":396.07,"id":12986368}]}]}
{"op":"mcm","clk":"1004765636","pt":1580636961919,"mc":[{"id":"1.168209732","rc":[{"batb":[[2,4.5,11.76]],"batl":[[0,5.3,9.24]],"ltp":4.8,"tv":22.71,"id":12986367},{"batb":[[1,4.5,52.08]],"batl":[[0,5.3,9.24]],"ltp":0.0,"tv":0.0,"id":18318124},{"batb":[[0,3.35,63.74],[1,3.3,43.2],[2,3.1,19.32]],"batl":[[0,3.55,15.96]],"ltp":2.96,"tv":396.07,"id":12986368},{"batb":[[0,3.25,18.48],[1,3.2,72.63],[2,3.15,47.3]],"batl":[[0,3.75,15.12]],"ltp":0.0,"tv":0.0,"id":18318122}]}]}
{"op":"mcm","clk":"1004767291","pt":1580636990473,"mc":[{"id":"1.168209732","rc":[{"batb":[[0,4.6,22.26]],"ltp":0.0,"tv":0.0,"id":18318124},{"batb":[[0,3.1,19.32],[1,1.01,0.51],[2,3.1,0]],"ltp":2.96,"tv":396.07,"id":12986368},{"batb":[[1,1.01,0.51],[2,3.15,0]],"ltp":0.0,"tv":0.0,"id":18318122}]}]}
{"op":"mcm","clk":"1004767318","pt":1580636990998,"mc":[{"id":"1.168209732","rc":[{"batb":[[2,1.01,0.51]],"ltp":4.8,"tv":22.71,"id":12986367},{"batb":[[1,4.5,40.32]],"ltp":0.0,"tv":0.0,"id":18318124},{"batb":[[0,1.01,0.51],[1,1.01,0]],"ltp":2.96,"tv":396.07,"id":12986368},{"batb":[[0,1.01,0.51],[1,1.01,0]],"ltp":0.0,"tv":0.0,"id":18318122}]}]}
{"op":"mcm","clk":"1004767447","pt":1580636993481,"mc":[{"id":"1.168209732","rc":[{"batb":[[0,3.15,75.47],[1,3.1,50.42],[2,1.01,0.51]],"ltp":2.96,"tv":396.07,"id":12986368},{"batb":[[0,2.86,57.53],[1,2.82,50.39],[2,1.01,0.51]],"ltp":0.0,"tv":0.0,"id":18318122}]}]}
{"op":"mcm","clk":"1004767476","pt":1580636994104,"mc":[{"id":"1.168209732","rc":[{"batb":[[0,1.01,0.51],[1,3.1,0],[2,1.01,0]],"ltp":2.96,"tv":396.07,"id":12986368},{"batb":[[0,1.01,0.51],[1,2.82,0],[2,1.01,0]],"ltp":0.0,"tv":0.0,"id":18318122}]}]}
{"op":"mcm","clk":"1004767708","pt":1580636997919,"mc":[{"id":"1.168209732","rc":[{"batb":[[2,4.5,11.76]],"batl":[[0,5.3,9.24]],"ltp":4.8,"tv":22.71,"id":12986367},{"batb":[[1,4.5,52.08]],"batl":[[0,5.3,9.24]],"ltp":0.0,"tv":0.0,"id":18318124},{"batb":[[0,3.15,75.47],[1,3.1,50.42],[2,2.92,21.85]],"batl":[[0,3.3,17.64]],"ltp":2.96,"tv":396.07,"id":12986368},{"batb":[[0,3.45,49.4],[1,3.4,39.43],[2,1.01,0.51]],"batl":[[0,4,13.44]],"ltp":0.0,"tv":0.0,"id":18318122}]}]}
{"op":"mcm","clk":"1004768441","pt":1580637009524,"mc":[{"id":"1.168209732","rc":[{"batb":[[0,2.92,21.85],[1,1.01,0.51],[2,2.92,0]],"ltp":2.96,"tv":396.07,"id":12986368},{"batb":[[0,3.45,16.8],[1,1.01,0.51],[2,1.01,0]],"ltp":0.0,"tv":0.0,"id":18318122}]}]}
{"op":"mcm","clk":"1004768566","pt":1580637011488,"mc":[{"id":"1.168209732","rc":[{"batb":[[2,1.01,0.51]],"ltp":4.8,"tv":22.71,"id":12986367},{"batb":[[1,4.5,40.32]],"ltp":0.0,"tv":0.0,"id":18318124},{"batb":[[0,1.01,0.51],[1,1.01,0]],"ltp":2.96,"tv":396.07,"id":12986368},{"batb":[[0,1.01,0.51],[1,1.01,0]],"ltp":0.0,"tv":0.0,"id":18318122}]}]}
{"op":"mcm","clk":"1004768709","pt":1580637013715,"mc":[{"id":"1.168209732","rc":[{"batb":[[0,4.5,40.32],[1,1.01,0.51],[2,1.01,0]],"ltp":0.0,"tv":0.0,"id":18318124}]}]}
{"op":"mcm","clk":"1004768849","pt":1580637015941,"mc":[{"id":"1.168209732","rc":[{"batb":[[2,4.5,11.76]],"batl":[[0,5.3,9.24]],"ltp":4.8,"tv":22.71,"id":12986367},{"batb":[[0,4.5,52.08]],"batl":[[0,5.3,9.24]],"ltp":0.0,"tv":0.0,"id":18318124},{"batb":[[0,2.8,22.69],[1,1.01,0.51]],"batl":[[0,3.15,19.32]],"ltp":2.96,"tv":396.07,"id":12986368},{"batb":[[0,3.65,15.12],[1,1.01,0.51]],"batl":[[0,4.3,12.6]],"ltp":0.0,"tv":0.0,"id":18318122}]}]}
{"op":"mcm","clk":"1004768860","pt":1580637016002,"mc":[{"id":"1.168209732","rc":[{"batb":[[0,4.5,73.78],[1,4.4,41.69],[2,1.01,0.51]],"ltp":0.0,"tv":0.0,"id":18318124},{"batb":[[0,3.05,36.01],[1,3,55.1],[2,2.8,22.69]],"ltp":2.96,"tv":396.07,"id":12986368},{"batb":[[1,3.6,56.27],[2,3.55,35.29]],"ltp":0.0,"tv":0.0,"id":18318122}]}]}
{"op":"mcm","clk":"1004769469","pt":1580637027672,"mc":[{"id":"1.168209732","rc":[{"batb":[[0,2.8,22.69],[1,1.01,0.51],[2,2.8,0]],"ltp":2.96,"tv":396.07,"id":12986368},{"batb":[[1,1.01,0.51],[2,3.55,0]],"ltp":0.0,"tv":0.0,"id":18318122}]}]}
{"op":"mcm","clk":"1004769548","pt":1580637029232,"mc":[{"id":"1.168209732","rc":[{"batb":[[2,1.01,0.51]],"ltp":4.8,"tv":22.71,"id":12986367},{"batb":[[0,4.5,62.02]],"ltp":0.0,"tv":0.0,"id":18318124},{"batb":[[0,1.01,0.51],[1,1.01,0]],"ltp":2.96,"tv":396.07,"id":12986368},{"batb":[[0,1.01,0.51],[1,1.01,0]],"ltp":0.0,"tv":0.0,"id":18318122}]}]}
{"op":"mcm","clk":"1004769638","pt":1580637030938,"mc":[{"id":"1.168209732","rc":[{"batb":[[0,2.96,38.01],[1,2.92,47.33],[2,1.01,0.51]],"ltp":2.96,"tv":396.07,"id":12986368},{"batb":[[0,3.35,63.73],[1,3.3,42.14],[2,1.01,0.51]],"ltp":0.0,"tv":0.0,"id":18318122}]}]}
{"op":"mcm","clk":"1004769688","pt":1580637031766,"mc":[{"id":"1.168209732","rc":[{"batb":[[0,1.01,0.51],[1,2.92,0],[2,1.01,0]],"ltp":2.96,"tv":396.07,"id":12986368},{"batb":[[0,1.01,0.51],[1,3.3,0],[2,1.01,0]],"ltp":0.0,"tv":0.0,"id":18318122}]}]}
{"op":"mcm","clk":"1004769858","pt":1580637034763,"mc":[{"id":"1.168209732","rc":[{"batb":[[0,3.05,76.43],[1,3,54.74],[2,1.01,0.51]],"ltp":2.96,"tv":396.07,"id":12986368},{"batb":[[0,3.55,55.61],[1,3.5,36.53],[2,1.01,0.51]],"ltp":0.0,"tv":0.0,"id":18318122}]}]}
{"op":"mcm","clk":"1004770152","pt":1580637039158,"mc":[{"id":"1.168209732","rc":[{"batb":[[0,1.01,0.51],[1,3,0],[2,1.01,0]],"ltp":2.96,"tv":396.07,"id":12986368},{"batb":[[0,1.01,0.51],[1,3.5,0],[2,1.01,0]],"ltp":0.0,"tv":0.0,"id":18318122}]}]}
{"op":"mcm","clk":"1004770371","pt":1580637042158,"mc":[{"id":"1.168209732","rc":[{"batb":[[0,2.96,37.13],[1,2.92,47.33],[2,1.01,0.51]],"ltp":2.96,"tv":396.07,"id":12986368},{"batb":[[0,3.35,64.5],[1,3.3,42.14],[2,1.01,0.51]],"ltp":0.0,"tv":0.0,"id":18318122}]}]}
{"op":"mcm","clk":"1004770892","pt":1580637050376,"mc":[{"id":"1.168209732","rc":[{"batb":[[0,1.01,0.51],[1,2.92,0],[2,1.01,0]],"ltp":2.96,"tv":396.07,"id":12986368}]}]}
{"op":"mcm","clk":"1004771073","pt":1580637053890,"mc":[{"id":"1.168209732","rc":[{"batb":[[2,4.5,11.76]],"batl":[[0,5.3,9.24]],"ltp":4.8,"tv":22.71,"id":12986367},{"batb":[[1,4.4,53.45]],"batl":[[0,5.2,9.24]],"ltp":0.0,"tv":0.0,"id":18318124},{"batb":[[0,3.2,46.95],[1,2.94,21],[2,1.01,0.51]],"batl":[[0,3.35,17.64]],"ltp":2.96,"tv":396.07,"id":12986368},{"batb":[[0,3.45,16.8],[1,3.35,41]],"batl":[[0,4,13.44]],"ltp":0.0,"tv":0.0,"id":18318122}]}]}
{"op":"mcm","clk":"1004771088","pt":1580637054301,"mc":[{"id":"1.168209732","rc":[{"batb":[[1,1.01,0.51],[2,1.01,0]],"ltp":2.96,"tv":396.07,"id":12986368}]}]}
{"op":"mcm","clk":"1004771167","pt":1580637056416,"mc":[{"id":"1.168209732","rc":[{"batb":[[0,3.2,70.18],[1,3.15,48.4],[2,2.96,21]],"ltp":2.96,"tv":396.07,"id":12986368},{"batb":[[1,3.4,33.54],[2,3.35,41]],"batl":[[0,3.95,13.44]],"ltp":0.0,"tv":0.0,"id":18318122}]}]}
{"op":"mcm","clk":"1004771744","pt":1580637068511,"mc":[{"id":"1.168209732","rc":[{"batb":[[0,4.5,53.09]],"ltp":0.0,"tv":0.0,"id":18318124},{"batb":[[0,2.96,21],[1,1.01,0.51],[2,2.96,0]],"ltp":2.96,"tv":396.07,"id":12986368},{"batb":[[1,1.01,0.51],[2,3.35,0]],"ltp":0.0,"tv":0.0,"id":18318122}]}]}
{"op":"mcm","clk":"1004771771","pt":1580637069123,"mc":[{"id":"1.168209732","rc":[{"batb":[[2,1.01,0.51]],"ltp":4.8,"tv":22.71,"id":12986367},{"batb":[[1,4.4,41.69]],"ltp":0.0,"tv":0.0,"id":18318124},{"batb":[[0,1.01,0.51],[1,1.01,0]],"ltp":2.96,"tv":396.07,"id":12986368},{"batb":[[0,1.01,0.51],[1,1.01,0]],"ltp":0.0,"tv":0.0,"id":18318122}]}]}
{"op":"mcm","clk":"1004771951","pt":1580637071803,"mc":[{"id":"1.168209732","rc":[{"batb":[[0,4.7,46.91]],"ltp":4.8,"tv":22.71,"id":12986367},{"batb":[[0,3.05,50.98],[1,3,54.87],[2,1.01,0.51]],"ltp":2.96,"tv":396.07,"id":12986368},{"batb":[[0,3,72.41],[1,2.96,44.51],[2,1.01,0.51]],"ltp":0.0,"tv":0.0,"id":18318122}]}]}
{"op":"mcm","clk":"1004772032","pt":1580637073704,"mc":[{"id":"1.168209732","rc":[{"batb":[[0,1.01,0.51],[1,2.96,0],[2,1.01,0]],"ltp":0.0,"tv":0.0,"id":18318122}]}]}
{"op":"mcm","clk":"1004772085","pt":1580637074936,"mc":[{"id":"1.168209732","rc":[{"batb":[[0,4.7,25.69]],"ltp":4.8,"tv":22.71,"id":12986367},{"batb":[[0,4.5,40.43],[1,1.01,0.51],[2,1.01,0]],"ltp":0.0,"tv":0.0,"id":18318124},{"batb":[[0,3,54.87],[1,1.01,0.51],[2,1.01,0]],"ltp":2.96,"tv":396.07,"id":12986368}]}]}
{"op":"mcm","clk":"1004772168","pt":1580637076635,"mc":[{"id":"1.168209732","rc":[{"batb":[[0,3.6,34.63],[1,1.01,0.51]],"ltp":0.0,"tv":0.0,"id":18318122}]}]}
{"op":"mcm","clk":"1004772226","pt":1580637077922,"mc":[{"id":"1.168209732","rc":[{"batb":[[2,4.4,11.76]],"batl":[[0,5.2,9.24]],"ltp":4.8,"tv":22.71,"id":12986367},{"batb":[[0,4.6,34.31],[1,4.5,52.19],[2,1.01,0.51]],"batl":[[0,5.3,9.24]],"ltp":0.0,"tv":0.0,"id":18318124},{"batb":[[0,3,70.66],[1,2.96,45.18],[2,2.82,22.69]],"batl":[[0,3.15,19.32]],"ltp":2.96,"tv":396.07,"id":12986368},{"batb":[[0,3.7,15.12],[1,3.65,42.21],[2,3.6,34.63]],"batl":[[0,4.3,12.6]],"ltp":0.0,"tv":0.0,"id":18318122}]}]}
{"op":"mcm","clk":"1004772256","pt":1580637078638,"mc":[{"id":"1.168209732","rc":[{"batb":[[2,1.01,0.51]],"ltp":4.8,"tv":22.71,"id":12986367},{"batb":[[1,4.5,40.43]],"ltp":0.0,"tv":0.0,"id":18318124},{"batb":[[0,3.65,42.21],[1,3.6,34.63],[2,1.01,0.51]],"ltp":0.0,"tv":0.0,"id":18318122}]}]}
{"op":"mcm","clk":"1004772313","pt":1580637079722,"mc":[{"id":"1.168209732","rc":[{"batb":[[2,4.5,11.76]],"batl":[[0,5.3,9.24]],"ltp":4.8,"tv":22.71,"id":12986367},{"batb":[[2,4.4,11.76]],"batl":[[0,5.2,9.24]],"ltp":0.0,"tv":0.0,"id":18318124},{"batl":[[0,3.2,18.48]],"ltp":2.96,"tv":396.07,"id":12986368},{"batb":[[0,3.65,57.33]],"batl":[[0,4.2,12.6]],"ltp":0.0,"tv":0.0,"id":18318122}]}]}
{"op":"mcm","clk":"1004772329","pt":1580637080061,"mc":[{"id":"1.168209732","rc":[{"batb":[[0,4.6,39.17],[1,4.5,11.76],[2,1.01,0.51]],"ltp":4.8,"tv":22.71,"id":12986367}]}]}
{"op":"mcm","clk":"1004772449","pt":1580637082939,"mc":[{"id":"1.168209732","rc":[{"batb":[[0,4.6,59.69],[1,4.5,52.45]],"ltp":4.8,"tv":22.71,"id":12986367}]}]}
{"op":"mcm","clk":"1004772933","pt":1580637093939,"mc":[{"id":"1.168209732","rc":[{"batb":[[0,2.82,22.69],[1,1.01,0.51],[2,2.82,0]],"ltp":2.96,"tv":396.07,"id":12986368},{"batb":[[0,3.65,15.12],[1,1.01,0.51],[2,1.01,0]],"ltp":0.0,"tv":0.0,"id":18318122}]}]}
{"op":"mcm","clk":"1004772971","pt":1580637095059,"mc":[{"id":"1.168209732","rc":[{"batb":[[1,4.5,40.69]],"ltp":4.8,"tv":22.71,"id":12986367},{"batb":[[2,1.01,0.51]],"ltp":0.0,"tv":0.0,"id":18318124},{"batb":[[0,1.01,0.51],[1,1.01,0]],"ltp":2.96,"tv":396.07,"id":12986368},{"batb":[[0,1.01,0.51],[1,1.01,0]],"ltp":0.0,"tv":0.0,"id":18318122}]}]}
{"op":"mcm","clk":"1004773049","pt":1580637096857,"mc":[{"id":"1.168209732","rc":[{"batb":[[0,2.94,36.49],[1,2.9,47.76],[2,1.01,0.51]],"ltp":2.96,"tv":396.07,"id":12986368},{"batb":[[0,3.4,62.5],[1,3.35,41.16],[2,1.01,0.51]],"ltp":0.0,"tv":0.0,"id":18318122}]}]}
{"op":"mcm","clk":"1004773276","pt":1580637101852,"mc":[{"id":"1.168209732","rc":[{"batb":[[0,1.01,0.51],[1,2.9,0],[2,1.01,0]],"ltp":2.96,"tv":396.07,"id":12986368},{"batb":[[0,1.01,0.51],[1,3.35,0],[2,1.01,0]],"ltp":0.0,"tv":0.0,"id":18318122}]}]}
{"op":"mcm","clk":"1004773557","pt":1580637107666,"mc":[{"id":"1.168209732","rc":[{"batb":[[0,2.94,36.49],[1,2.9,47.76],[2,1.01,0.51]],"ltp":2.96,"tv":396.07,"id":12986368},{"batb":[[0,3.4,62.5],[1,3.35,41.16],[2,1.01,0.51]],"ltp":0.0,"tv":0.0,"id":18318122}]}]}
{"op":"mcm","clk":"1004774174","pt":1580637119184,"mc":[{"id":"1.168209732","rc":[{"batb":[[0,4.6,39.23],[1,1.01,0.51],[2,1.01,0]],"ltp":4.8,"tv":22.71,"id":12986367},{"batb":[[0,1.01,0.51],[1,2.9,0],[2,1.01,0]],"ltp":2.96,"tv":396.07,"id":12986368},{"batb":[[0,1.01,0.51],[1,3.35,0],[2,1.01,0]],"ltp":0.0,"tv":0.0,"id":18318122}]}]}
{"op":"mcm","clk":"1004774416","pt":1580637123615,"mc":[{"id":"1.168209732","rc":[{"batb":[[0,4.7,26.22],[1,4.6,39.23],[2,1.01,0.51]],"ltp":4.8,"tv":22.71,"id":12986367}]}]}
{"op":"mcm","clk":"1004774583","pt":1580637126699,"mc":[{"id":"1.168209732","rc":[{"batb":[[0,3,59.83],[1,2.96,45.18],[2,1.01,0.51]],"ltp":2.96,"tv":396.07,"id":12986368},{"batb":[[0,3.65,57.61],[1,3.6,34.57],[2,1.01,0.51]],"ltp":0.0,"tv":0.0,"id":18318122}]}]}
{"op":"mcm","clk":"1004774608","pt":1580637127110,"mc":[{"id":"1.168209732","rc":[{"batb":[[0,4.6,39.23],[1,1.01,0.51],[2,1.01,0]],"ltp":4.8,"tv":22.71,"id":12986367},{"batb":[[0,1.01,0.51],[1,2.96,0],[2,1.01,0]],"ltp":2.96,"tv":396.07,"id":12986368},{"batb":[[0,3.65,33.76],[1,1.01,0.51],[2,1.01,0]],"ltp":0.0,"tv":0.0,"id":18318122}]}]}
{"op":"mcm","clk":"1004774686","pt":1580637128295,"mc":[{"id":"1.168209732","rc":[{"batb":[[1,4.5,52.19]],"batl":[[0,5.3,9.24]],"ltp":0.0,"tv":0.0,"id":18318124},{"batb":[[0,2.72,24.37],[1,1.01,0.51]],"batl":[[0,3.05,20.16]],"ltp":2.96,"tv":396.07,"id":12986368},{"batl":[[0,4.5,11.76]],"ltp":0.0,"tv":0.0,"id":18318122}]}]}
{"op":"mcm","clk":"1004774755","pt":1580637129731,"mc":[{"id":"1.168209732","rc":[{"batl":[[0,5.2,9.24]],"ltp":4.8,"tv":22.71,"id":12986367},{"batb":[[0,3.85,14.28],[1,3.65,33.76],[2,1.01,0.51]],"ltp":0.0,"tv":0.0,"id":18318122}]}]}
{"op":"mcm","clk":"1004774815","pt":1580637130318,"mc":[{"id":"1.168209732","rc":[{"batb":[[1,4.5,40.59],[2,4.4,11.76]],"ltp":4.8,"tv":22.71,"id":12986367},{"batb":[[0,4.6,55.6]],"ltp":0.0,"tv":0.0,"id":18318124},{"batb":[[0,2.98,40.06],[1,2.94,45.81],[2,2.72,24.37]],"ltp":2.96,"tv":396.07,"id":12986368},{"batb":[[1,3.7,32.97]],"ltp":0.0,"tv":0.0,"id":18318122}]}]}
{"op":"mcm","clk":"1004775036","pt":1580637133320,"mc":[{"id":"1.168209732","rc":[{"batb":[[1,3.75,28.23],[2,3.7,32.97]],"ltp":0.0,"tv":0.0,"id":18318122}]}]}
{"op":"mcm","clk":"1004775226","pt":1580637136720,"mc":[{"id":"1.168209732","rc":[{"batl":[[0,4.4,732.49],[1,4.5,11.76]],"ltp":0.0,"tv":0.0,"id":18318122}]}]}
{"op":"mcm","clk":"1004775362","pt":1580637138939,"mc":[{"id":"1.168209732","rc":[{"batl":[[0,4.5,11.76],[1,4.5,0]],"ltp":0.0,"tv":0.0,"id":18318122}]}]}
{"op":"mcm","clk":"1004775808","pt":1580637145334,"mc":[{"id":"1.168209732","rc":[{"batl":[[0,4.4,726.94],[1,4.5,11.76]],"ltp":0.0,"tv":0.0,"id":18318122}]}]}
{"op":"mcm","clk":"1004775994","pt":1580637148131,"mc":[{"id":"1.168209732","rc":[{"batb":[[0,4.5,40.59],[1,4.4,11.76],[2,1.01,0.51]],"ltp":4.8,"tv":22.71,"id":12986367},{"batb":[[0,4.6,39.29],[1,4.5,11.76]],"ltp":0.0,"tv":0.0,"id":18318124},{"batb":[[0,2.94,45.81],[1,2.72,24.37],[2,1.01,0.51]],"ltp":2.96,"tv":396.07,"id":12986368},{"batb":[[2,1.01,0.51]],"ltp":0.0,"tv":0.0,"id":18318122}]}]}
{"op":"mcm","clk":"1004776181","pt":1580637151451,"mc":[{"id":"1.168209732","rc":[{"batb":[[0,4.5,51.82],[1,4.4,53.8]],"ltp":4.8,"tv":22.71,"id":12986367},{"batb":[[0,4.7,41.28],[1,4.6,39.29],[2,4.5,11.76]],"ltp":0.0,"tv":0.0,"id":18318124},{"batb":[[0,2.72,24.37],[1,1.01,0.51],[2,1.01,0]],"ltp":2.96,"tv":396.07,"id":12986368},{"batb":[[1,3.8,26.99],[2,3.75,28.23]],"ltp":0.0,"tv":0.0,"id":18318122}]}]}
{"op":"mcm","clk":"1004776270","pt":1580637152848,"mc":[{"id":"1.168209732","rc":[{"batb":[[2,1.01,0.51]],"ltp":0.0,"tv":0.0,"id":18318124},{"trd":[[3.05,40.33]],"batb":[[0,3.05,16.94]],"ltp":3.05,"tv":436.4,"id":12986368},{"batb":[[0,3.8,26.99],[1,3.75,28.23],[2,1.01,0.51]],"ltp":0.0,"tv":0.0,"id":18318122}],"tv":459.11}]}
{"op":"mcm","clk":"1004776363","pt":1580637154346,"mc":[{"id":"1.168209732","rc":[{"batb":[[0,4.7,52.74]],"ltp":0.0,"tv":0.0,"id":18318124},{"batb":[[1,2.92,51.51],[2,2.88,47.76]],"ltp":3.05,"tv":436.4,"id":12986368},{"batb":[[0,3.8,42.1]],"ltp":0.0,"tv":0.0,"id":18318122}]}]}
{"op":"mcm","clk":"1004776458","pt":1580637155942,"mc":[{"id":"1.168209732","rc":[{"batb":[[2,4.4,11.76]],"ltp":0.0,"tv":0.0,"id":18318124},{"trd":[[3.05,53.78]],"batb":[[0,3.05,10.22]],"batl":[[0,3.15,19.32]],"ltp":3.05,"tv":449.84,"id":12986368},{"batb":[[1,3.75,43.35]],"ltp":0.0,"tv":0.0,"id":18318122}],"tv":472.56}]}
{"op":"mcm","clk":"1004779226","pt":1580637209945,"mc":[{"id":"1.168209732","rc":[{"batb":[[1,2.74,23.53],[2,1.01,0.51]],"ltp":3.05,"tv":449.84,"id":12986368},{"batb":[[0,3.75,15.12],[1,1.01,0.51],[2,1.01,0]],"ltp":0.0,"tv":0.0,"id":18318122}]}]}
{"op":"mcm","clk":"1004779254","pt":1580637210565,"mc":[{"id":"1.168209732","rc":[{"batl":[[0,4.5,11.76],[1,4.5,0]],"ltp":0.0,"tv":0.0,"id":18318122}]}]}
{"op":"mcm","clk":"1004779285","pt":1580637211236,"mc":[{"id":"1.168209732","rc":[{"batb":[[1,4.4,42.04]],"ltp":4.8,"tv":22.71,"id":12986367},{"batb":[[2,1.01,0.51]],"ltp":0.0,"tv":0.0,"id":18318124},{"batb":[[1,1.01,0.51],[2,1.01,0]],"ltp":3.05,"tv":449.84,"id":12986368},{"batb":[[0,1.01,0.51],[1,1.01,0]],"ltp":0.0,"tv":0.0,"id":18318122}]}]}
{"op":"mcm","clk":"1004779355","pt":1580637212935,"mc":[{"id":"1.168209732","rc":[{"batb":[[1,2.62,55.04],[2,2.58,63.64]],"ltp":3.05,"tv":449.84,"id":12986368},{"batb":[[0,3.55,42.77],[1,3.5,38.03],[2,1.01,0.51]],"ltp":0.0,"tv":0.0,"id":18318122}]}]}
{"op":"mcm","clk":"1004779920","pt":1580637224783,"mc":[{"id":"1.168209732","rc":[{"batb":[[1,1.01,0.51],[2,2.58,0]],"ltp":3.05,"tv":449.84,"id":12986368}]}]}
{"op":"mcm","clk":"1004780057","pt":1580637227868,"mc":[{"id":"1.168209732","rc":[{"batb":[[0,3.1,44.22],[1,3.05,61.67],[2,1.01,0.51]],"ltp":3.05,"tv":449.84,"id":12986368}]}]}
{"op":"mcm","clk":"1004780096","pt":1580637228688,"mc":[{"id":"1.168209732","rc":[{"batb":[[2,4.3,12.6]],"batl":[[0,5.2,9.24]],"ltp":4.8,"tv":22.71,"id":12986367},{"batb":[[2,4.4,11.76]],"batl":[[0,5.3,9.24]],"ltp":0.0,"tv":0.0,"id":18318124},{"batb":[[2,2.92,21.85]],"batl":[[0,3.35,17.64]],"ltp":3.05,"tv":449.84,"id":12986368},{"batb":[[0,3.55,58.73]],"batl":[[0,4.2,12.6]],"ltp":0.0,"tv":0.0,"id":18318122}]}]}
{"op":"mcm","clk":"1004780828","pt":1580637242737,"mc":[{"id":"1.168209732","rc":[{"batb":[[0,4.5,42.14]],"ltp":4.8,"tv":22.71,"id":12986367},{"batb":[[0,3.05,10.22],[1,2.92,21.85],[2,1.01,0.51]],"ltp":3.05,"tv":449.84,"id":12986368},{"batb":[[0,3.55,15.96],[1,1.01,0.51],[2,1.01,0]],"ltp":0.0,"tv":0.0,"id":18318122}]}]}
{"op":"mcm","clk":"1004780851","pt":1580637243309,"mc":[{"id":"1.168209732","rc":[{"batb":[[2,1.01,0.51]],"ltp":4.8,"tv":22.71,"id":12986367},{"batb":[[2,1.01,0.51]],"ltp":0.0,"tv":0.0,"id":18318124},{"batb":[[1,1.01,0.51],[2,1.01,0]],"ltp":3.05,"tv":449.84,"id":12986368},{"batb":[[0,1.01,0.51],[1,1.01,0]],"ltp":0.0,"tv":0.0,"id":18318122}]}]}
{"op":"mcm","clk":"1004781004","pt":1580637246706,"mc":[{"id":"1.168209732","rc":[{"batb":[[1,2.82,61.05],[2,2.78,52.23]],"ltp":3.05,"tv":449.84,"id":12986368},{"batb":[[0,3.35,65.7],[1,3.3,43.67],[2,1.01,0.51]],"ltp":0.0,"tv":0.0,"id":18318122}]}]}
{"op":"mcm","clk":"1004781171","pt":1580637250223,"mc":[{"id":"1.168209732","rc":[{"batb":[[0,4.7,41.28],[1,1.01,0.51],[2,1.01,0]],"ltp":0.0,"tv":0.0,"id":18318124},{"batb":[[0,1.01,0.51],[1,3.3,0],[2,1.01,0]],"ltp":0.0,"tv":0.0,"id":18318122}]}]}
{"op":"mcm","clk":"1004781322","pt":1580637253002,"mc":[{"id":"1.168209732","rc":[{"batb":[[0,4.8,21.19],[1,4.7,41.28],[2,1.01,0.51]],"ltp":0.0,"tv":0.0,"id":18318124},{"batb":[[0,3.95,49.91],[1,3.9,29.31],[2,1.01,0.51]],"ltp":0.0,"tv":0.0,"id":18318122}]}]}
{"op":"mcm","clk":"1004781383","pt":1580637254235,"mc":[{"id":"1.168209732","rc":[{"batb":[[1,4.4,53.8]],"batl":[[0,5.2,9.24]],"ltp":4.8,"tv":22.71,"id":12986367},{"batb":[[2,4.5,11.76]],"batl":[[0,5.3,9.24]],"ltp":0.0,"tv":0.0,"id":18318124},{"trd":[[3.05,73.94]],"batb":[[0,2.82,61.19],[1,2.78,52.23],[2,2.74,23.53]],"batl":[[0,3.1,19.32]],"ltp":3.05,"tv":470.0,"id":12986368},{"batb":[[1,3.9,43.59]],"batl":[[0,4.6,10.92]],"ltp":0.0,"tv":0.0,"id":18318122}],"tv":492.72}]}
{"op":"mcm","clk":"1004781920","pt":1580637265186,"mc":[{"id":"1.168209732","rc":[{"batb":[[0,4.5,24.93]],"ltp":4.8,"tv":22.71,"id":12986367},{"batb":[[0,2.74,23.66],[1,1.01,0.51],[2,2.74,0]],"ltp":3.05,"tv":470.0,"id":12986368},{"batb":[[0,3.95,28.69],[1,3.9,14.28]],"ltp":0.0,"tv":0.0,"id":18318122}]}]}
{"op":"mcm","clk":"1004782097","pt":1580637268547,"mc":[{"id":"1.168209732","rc":[{"batb":[[0,4.8,50.69]],"ltp":0.0,"tv":0.0,"id":18318124},{"batb":[[0,2.8,40.61],[1,2.76,53],[2,2.74,23.53]],"ltp":3.05,"tv":470.0,"id":12986368},{"batb":[[0,4,58.11],[1,3.95,28.69],[2,3.9,14.28]],"batl":[[0,4.6,696.63]],"ltp":0.0,"tv":0.0,"id":18318122}]}]}
{"op":"mcm","clk":"1004782194","pt":1580637270665,"mc":[{"id":"1.168209732","rc":[{"batb":[[0,4.4,53.8],[1,1.01,0.51],[2,1.01,0]],"ltp":4.8,"tv":22.71,"id":12986367},{"batb":[[0,2.74,23.66],[1,1.01,0.51],[2,2.74,0]],"ltp":3.05,"tv":470.0,"id":12986368},{"batb":[[0,3.9,14.28],[1,1.01,0.51],[2,3.9,0]],"batl":[[0,4.6,10.92]],"ltp":0.0,"tv":0.0,"id":18318122}]}]}
{"op":"mcm","clk":"1004782231","pt":1580637271536,"mc":[{"id":"1.168209732","rc":[{"batb":[[0,4.4,42.04]],"ltp":4.8,"tv":22.71,"id":12986367},{"batb":[[2,1.01,0.51]],"ltp":0.0,"tv":0.0,"id":18318124},{"batb":[[0,1.01,0.64],[1,1.01,0]],"ltp":3.05,"tv":470.0,"id":12986368},{"batb":[[0,1.01,0.51],[1,1.01,0]],"ltp":0.0,"tv":0.0,"id":18318122}]}]}
{"op":"mcm","clk":"1004782342","pt":1580637273848,"mc":[{"id":"1.168209732","rc":[{"batb":[[0,4.4,56.83],[1,4.3,43.8],[2,1.01,0.51]],"ltp":4.8,"tv":22.71,"id":12986367},{"batb":[[0,2.46,55.48],[1,2.42,75.2],[2,1.01,0.51]],"ltp":3.05,"tv":470.0,"id":12986368},{"batb":[[0,3.65,62.58],[1,3.6,35.74],[2,1.01,0.51]],"ltp":0.0,"tv":0.0,"id":18318122}]}]}
{"op":"mcm","clk":"1004782650","pt":1580637280180,"mc":[{"id":"1.168209732","rc":[{"batb":[[0,2.46,55.34]],"ltp":3.05,"tv":470.0,"id":12986368}]}]}
{"op":"mcm","clk":"1004782951","pt":1580637285755,"mc":[{"id":"1.168209732","rc":[{"batb":[[0,1.01,0.51],[1,2.42,0],[2,1.01,0]],"ltp":3.05,"tv":470.0,"id":12986368}]}]}
{"op":"mcm","clk":"1004783105","pt":1580637288689,"mc":[{"id":"1.168209732","rc":[{"batb":[[1,4.3,56.4]],"batl":[[0,5.1,10.08]],"ltp":4.8,"tv":22.71,"id":12986367},{"batb":[[2,4.5,11.76]],"batl":[[0,5.3,9.24]],"ltp":0.0,"tv":0.0,"id":18318124},{"batb":[[0,3,49.61],[1,2.96,44.19],[2,2.9,21.85]],"batl":[[0,3.35,17.64]],"ltp":3.05,"tv":470.0,"id":12986368},{"batb":[[0,3.65,77.7]],"batl":[[0,4.2,12.6]],"ltp":0.0,"tv":0.0,"id":18318122}]}]}
{"op":"mcm","clk":"1004783710","pt":1580637301595,"mc":[{"id":"1.168209732","rc":[{"batb":[[0,2.9,21.85],[1,1.01,0.51],[2,2.9,0]],"ltp":3.05,"tv":470.0,"id":12986368},{"batb":[[0,3.65,15.12],[1,1.01,0.51],[2,1.01,0]],"ltp":0.0,"tv":0.0,"id":18318122}]}]}
{"op":"mcm","clk":"1004783796","pt":1580637303307,"mc":[{"id":"1.168209732","rc":[{"batb":[[1,4.3,43.8]],"ltp":4.8,"tv":22.71,"id":12986367},{"batb":[[2,1.01,0.51]],"ltp":0.0,"tv":0.0,"id":18318124},{"batb":[[0,1.01,0.51],[1,1.01,0]],"ltp":3.05,"tv":470.0,"id":12986368},{"batb":[[0,1.01,0.51],[1,1.01,0]],"ltp":0.0,"tv":0.0,"id":18318122}]}]}
{"op":"mcm","clk":"1004783847","pt":1580637304537,"mc":[{"id":"1.168209732","rc":[{"batb":[[0,2.7,62.35],[1,2.66,58.26],[2,1.01,0.51]],"ltp":3.05,"tv":470.0,"id":12986368},{"batb":[[0,3.45,45.86],[1,3.4,41.15],[2,1.01,0.51]],"ltp":0.0,"tv":0.0,"id":18318122}]}]}
{"op":"mcm","clk":"1004783893","pt":1580637305838,"mc":[{"id":"1.168209732","rc":[{"batb":[[0,1.01,0.51],[1,2.66,0],[2,1.01,0]],"ltp":3.05,"tv":470.0,"id":12986368}]}]}
{"op":"mcm","clk":"1004784061","pt":1580637308837,"mc":[{"id":"1.168209732","rc":[{"batb":[[0,3.15,75.04],[1,3.1,48.74],[2,1.01,0.51]],"ltp":3.05,"tv":470.0,"id":12986368}]}]}
{"op":"mcm","clk":"1004784122","pt":1580637310211,"mc":[{"id":"1.168209732","rc":[{"batb":[[1,4.3,56.4]],"batl":[[0,5.1,10.08]],"ltp":4.8,"tv":22.71,"id":12986367},{"batb":[[2,4.4,11.76]],"batl":[[0,5.3,9.24]],"ltp":0.0,"tv":0.0,"id":18318124},{"batb":[[2,3.05,20.16]],"batl":[[0,3.55,15.96]],"ltp":3.05,"tv":470.0,"id":12986368},{"batb":[[0,3.45,62.66]],"batl":[[0,4,13.44]],"ltp":0.0,"tv":0.0,"id":18318122}]}]}
{"op":"mcm","clk":"1004784555","pt":1580637318953,"mc":[{"id":"1.168209732","rc":[{"batb":[[0,4.8,40.26]],"ltp":0.0,"tv":0.0,"id":18318124},{"batb":[[0,3.05,20.16],[1,1.01,0.51],[2,3.05,0]],"ltp":3.05,"tv":470.0,"id":12986368},{"batb":[[0,3.45,16.8],[1,1.01,0.51],[2,1.01,0]],"ltp":0.0,"tv":0.0,"id":18318122}]}]}
{"op":"mcm","clk":"1004784573","pt":1580637319359,"mc":[{"id":"1.168209732","rc":[{"batb":[[1,4.3,43.8]],"ltp":4.8,"tv":22.71,"id":12986367},{"batb":[[2,1.01,0.51]],"ltp":0.0,"tv":0.0,"id":18318124},{"batb":[[0,1.01,0.51],[1,1.01,0]],"ltp":3.05,"tv":470.0,"id":12986368},{"batb":[[0,1.01,0.51],[1,1.01,0]],"ltp":0.0,"tv":0.0,"id":18318122}]}]}
{"op":"mcm","clk":"1004784680","pt":1580637321867,"mc":[{"id":"1.168209732","rc":[{"batb":[[0,2.98,54.11],[1,2.94,44.95],[2,1.01,0.51]],"ltp":3.05,"tv":470.0,"id":12986368},{"batb":[[0,3.35,41.18],[1,3.3,44.3],[2,1.01,0.51]],"ltp":0.0,"tv":0.0,"id":18318122}]}]}
{"op":"mcm","clk":"1004784734","pt":1580637322857,"mc":[{"id":"1.168209732","rc":[{"batb":[[0,1.01,0.51],[1,2.94,0],[2,1.01,0]],"ltp":3.05,"tv":470.0,"id":12986368}]}]}
{"op":"mcm","clk":"1004784844","pt":1580637324780,"mc":[{"id":"1.168209732","rc":[{"batb":[[1,4.3,56.4]],"batl":[[0,5.1,10.08]],"ltp":4.8,"tv":22.71,"id":12986367},{"batb":[[2,4.4,11.76]],"batl":[[0,5.2,9.24]],"ltp":0.0,"tv":0.0,"id":18318124},{"batb":[[0,3.25,92.16],[1,3.2,45.01],[2,1.01,0.51]],"batl":[[0,3.7,15.12]],"ltp":3.05,"tv":470.0,"id":12986368},{"batb":[[2,3.25,18.48]],"batl":[[0,3.8,14.28]],"ltp":0.0,"tv":0.0,"id":18318122}]}]}
{"op":"mcm","clk":"1004786403","pt":1580637359744,"mc":[{"id":"1.168209732","rc":[{"batb":[[1,4.3,43.8]],"ltp":4.8,"tv":22.71,"id":12986367},{"batb":[[2,1.01,0.51]],"ltp":0.0,"tv":0.0,"id":18318124},{"batb":[[0,1.01,0.51],[1,3.2,0],[2,1.01,0]],"ltp":3.05,"tv":470.0,"id":12986368},{"batb":[[0,1.01,0.51],[1,3.3,0],[2,3.25,0]],"ltp":0.0,"tv":0.0,"id":18318122}]}]}
{"op":"mcm","clk":"1004786574","pt":1580637362803,"mc":[{"id":"1.168209732","rc":[{"batb":[[0,3.05,70.71],[1,3,53.02],[2,1.01,0.51]],"ltp":3.05,"tv":470.0,"id":12986368},{"batb":[[0,2.94,46.74],[1,2.9,48.97],[2,1.01,0.51]],"ltp":0.0,"tv":0.0,"id":18318122}]}]}
{"op":"mcm","clk":"1004786597","pt":1580637363214,"mc":[{"id":"1.168209732","rc":[{"batb":[[0,1.01,0.51],[1,3,0],[2,1.01,0]],"ltp":3.05,"tv":470.0,"id":12986368},{"batb":[[0,1.01,0.51],[1,2.9,0],[2,1.01,0]],"ltp":0.0,"tv":0.0,"id":18318122}]}]}
{"op":"mcm","clk":"1004786819","pt":1580637366212,"mc":[{"id":"1.168209732","rc":[{"batb":[[0,3.35,63.52],[1,3.3,41.78],[2,1.01,0.51]],"ltp":3.05,"tv":470.0,"id":12986368},{"batb":[[0,3.25,51.03],[1,3.2,47.68],[2,1.01,0.51]],"ltp":0.0,"tv":0.0,"id":18318122}]}]}
{"op":"mcm","clk":"1004786900","pt":1580637367923,"mc":[{"id":"1.168209732","rc":[{"batb":[[0,4.4,47.28]],"ltp":4.8,"tv":22.71,"id":12986367}]}]}
{"op":"mcm","clk":"1004787048","pt":1580637370924,"mc":[{"id":"1.168209732","rc":[{"batb":[[0,1.01,0.51],[1,3.3,0],[2,1.01,0]],"ltp":3.05,"tv":470.0,"id":12986368},{"batb":[[0,1.01,0.51],[1,3.2,0],[2,1.01,0]],"ltp":0.0,"tv":0.0,"id":18318122}]}]}
{"op":"mcm","clk":"1004787279","pt":1580637374851,"mc":[{"id":"1.168209732","rc":[{"batb":[[0,3.05,61.05],[1,3,53],[2,1.01,0.51]],"ltp":3.05,"tv":470.0,"id":12986368},{"batb":[[0,2.94,57.49],[1,2.9,48.98],[2,1.01,0.51]],"ltp":0.0,"tv":0.0,"id":18318122}]}]}
{"op":"mcm","clk":"1004787329","pt":1580637375732,"mc":[{"id":"1.168209732","rc":[{"batb":[[0,1.01,0.51],[1,3,0],[2,1.01,0]],"ltp":3.05,"tv":470.0,"id":12986368}]}]}
{"op":"mcm","clk":"1004787380","pt":1580637376661,"mc":[{"id":"1.168209732","rc":[{"batb":[[0,4.8,52.4]],"ltp":0.0,"tv":0.0,"id":18318124},{"batb":[[0,3.8,31.27],[1,3.75,30.77],[2,1.01,0.51]],"ltp":3.05,"tv":470.0,"id":12986368}]}]}
{"op":"mcm","clk":"1004787486","pt":1580637378472,"mc":[{"id":"1.168209732","rc":[{"batb":[[1,4.3,56.4]],"batl":[[0,5.1,10.08]],"ltp":4.8,"tv":22.71,"id":12986367},{"batb":[[2,4.4,11.76]],"batl":[[0,5.2,9.24]],"ltp":0.0,"tv":0.0,"id":18318124},{"batb":[[2,3.65,15.12]],"batl":[[0,4.3,12.6]],"ltp":3.05,"tv":470.0,"id":12986368},{"batb":[[0,2.94,78.49]],"batl":[[0,3.35,17.64]],"ltp":0.0,"tv":0.0,"id":18318122}]}]}
{"op":"mcm","clk":"1004788178","pt":1580637388873,"mc":[{"id":"1.168209732","rc":[{"batb":[[0,4.4,33]],"ltp":4.8,"tv":22.71,"id":12986367},{"batb":[[0,4.8,42.13]],"ltp":0.0,"tv":0.0,"id":18318124},{"batb":[[0,3.65,15.12],[1,1.01,0.51],[2,3.65,0]],"ltp":3.05,"tv":470.0,"id":12986368},{"batb":[[0,2.94,21],[1,1.01,0.51],[2,1.01,0]],"ltp":0.0,"tv":0.0,"id":18318122}]}]}
{"op":"mcm","clk":"1004788204","pt":1580637389287,"mc":[{"id":"1.168209732","rc":[{"batb":[[1,4.3,43.8]],"ltp":4.8,"tv":22.71,"id":12986367},{"batb":[[2,1.01,0.51]],"ltp":0.0,"tv":0.0,"id":18318124},{"batb":[[0,1.01,0.51],[1,1.01,0]],"ltp":3.05,"tv":470.0,"id":12986368},{"batb":[[0,1.01,0.51],[1,1.01,0]],"ltp":0.0,"tv":0.0,"id":18318122}]}]}
{"op":"mcm","clk":"1004788362","pt":1580637391879,"mc":[{"id":"1.168209732","rc":[{"batb":[[0,3.4,38.26],[1,3.35,40.4],[2,1.01,0.51]],"ltp":3.05,"tv":470.0,"id":12986368},{"batb":[[0,2.5,68.83],[1,2.46,75.2],[2,1.01,0.51]],"ltp":0.0,"tv":0.0,"id":18318122}]}]}
{"op":"mcm","clk":"1004788760","pt":1580637395804,"mc":[{"id":"1.168209732","rc":[{"batb":[[0,4.8,40.26],[1,1.01,0.51],[2,1.01,0]],"ltp":0.0,"tv":0.0,"id":18318124},{"batb":[[0,1.01,0.51],[1,3.35,0],[2,1.01,0]],"ltp":3.05,"tv":470.0,"id":12986368}]}]}
{"op":"mcm","clk":"1004789014","pt":1580637398903,"mc":[{"id":"1.168209732","rc":[{"batb":[[0,4.9,34.89],[1,4.8,40.26],[2,1.01,0.51]],"ltp":0.0,"tv":0.0,"id":18318124},{"batb":[[0,4.9,26.7],[1,4.8,34.2],[2,1.01,0.51]],"ltp":3.05,"tv":470.0,"id":12986368}]}]}
{"op":"mcm","clk":"1004789100","pt":1580637400297,"mc":[{"id":"1.168209732","rc":[{"batb":[[2,4.2,12.6]],"batl":[[0,5,10.08]],"ltp":4.8,"tv":22.71,"id":12986367},{"batb":[[2,4.5,11.76]],"batl":[[0,5.3,9.24]],"ltp":0.0,"tv":0.0,"id":18318124},{"batb":[[2,4.6,10.92]],"batl":[[0,5.4,9.24]],"ltp":3.05,"tv":470.0,"id":12986368},{"batb":[[0,2.52,26.89],[1,2.5,68.83],[2,2.46,75.2]],"batl":[[0,2.88,21.85]],"ltp":0.0,"tv":0.0,"id":18318122}]}]}
{"op":"mcm","clk":"1004789972","pt":1580637414912,"mc":[{"id":"1.168209732","rc":[{"batb":[[0,4.3,43.8],[1,4.2,12.6],[2,1.01,0.51]],"ltp":4.8,"tv":22.71,"id":12986367},{"batb":[[0,4.8,40.26],[1,4.5,11.76],[2,1.01,0.51]],"ltp":0.0,"tv":0.0,"id":18318124},{"batb":[[0,4.6,10.92],[1,1.01,0.51],[2,4.6,0]],"ltp":3.05,"tv":470.0,"id":12986368},{"batb":[[1,1.01,0.51],[2,2.46,0]],"ltp":0.0,"tv":0.0,"id":18318122}]}]}
{"op":"mcm","clk":"1004790041","pt":1580637415792,"mc":[{"id":"1.168209732","rc":[{"batb":[[1,1.01,0.51],[2,1.01,0]],"ltp":4.8,"tv":22.71,"id":12986367},{"batb":[[1,1.01,0.51],[2,1.01,0]],"ltp":0.0,"tv":0.0,"id":18318124},{"batb":[[0,1.01,0.51],[1,1.01,0]],"ltp":3.05,"tv":470.0,"id":12986368},{"batb":[[0,1.01,0.51],[1,1.01,0]],"ltp":0.0,"tv":0.0,"id":18318122}]}]}
{"op":"mcm","clk":"1004790172","pt":1580637417800,"mc":[{"id":"1.168209732","rc":[{"batb":[[0,4.3,66.62],[1,4.2,46.35],[2,1.01,0.51]],"ltp":4.8,"tv":22.71,"id":12986367},{"batb":[[0,4.8,55.37],[1,4.7,38.04],[2,1.01,0.51]],"ltp":0.0,"tv":0.0,"id":18318124},{"batb":[[0,4.1,47.27],[1,4,51.81],[2,1.01,0.51]],"ltp":3.05,"tv":470.0,"id":12986368},{"batb":[[0,2.12,76.94],[1,2.1,59.13],[2,1.01,0.51]],"ltp":0.0,"tv":0.0,"id":18318122}]}]}
{"op":"mcm","clk":"1004790298","pt":1580637419707,"mc":[{"id":"1.168209732","rc":[{"batb":[[0,4.3,44.39],[1,1.01,0.51],[2,1.01,0]],"ltp":4.8,"tv":22.71,"id":12986367},{"batb":[[0,4.8,40.26],[1,1.01,0.51],[2,1.01,0]],"ltp":0.0,"tv":0.0,"id":18318124},{"batb":[[0,1.01,0.51],[1,4,0],[2,1.01,0]],"ltp":3.05,"tv":470.0,"id":12986368},{"batb":[[0,1.01,0.51],[1,2.1,0],[2,1.01,0]],"ltp":0.0,"tv":0.0,"id":18318122}]}]}
{"op":"mcm","clk":"1004790630","pt":1580637422930,"mc":[{"id":"1.168209732","rc":[{"batb":[[0,4.4,30.69],[1,4.3,44.39],[2,1.01,0.51]],"ltp":4.8,"tv":22.71,"id":12986367},{"batb":[[0,4.9,41.17],[1,4.8,40.26],[2,1.01,0.51]],"ltp":0.0,"tv":0.0,"id":18318124},{"batb":[[0,5.2,44.1],[1,5.1,29.51],[2,1.01,0.51]],"ltp":3.05,"tv":470.0,"id":12986368},{"batb":[[0,2.42,57.74],[1,2.38,82.32],[2,1.01,0.51]],"ltp":0.0,"tv":0.0,"id":18318122}]}]}
{"op":"mcm","clk":"1004790969","pt":1580637427414,"mc":[{"id":"1.168209732","rc":[{"batb":[[0,4.3,44.39],[1,1.01,0.51],[2,1.01,0]],"ltp":4.8,"tv":22.71,"id":12986367},{"batb":[[0,4.8,40.26],[1,1.01,0.51],[2,1.01,0]],"ltp":0.0,"tv":0.0,"id":18318124},{"batb":[[0,1.01,0.51],[1,5.1,0],[2,1.01,0]],"ltp":3.05,"tv":470.0,"id":12986368},{"batb":[[0,1.01,0.51],[1,2.38,0],[2,1.01,0]],"ltp":0.0,"tv":0.0,"id":18318122}]}]}
{"op":"mcm","clk":"1004791152","pt":1580637430308,"mc":[{"id":"1.168209732","rc":[{"batb":[[0,4.3,66.62],[1,4.2,46.35],[2,1.01,0.51]],"ltp":4.8,"tv":22.71,"id":12986367},{"batb":[[0,4.8,55.37],[1,4.7,38.04],[2,1.01,0.51]],"ltp":0.0,"tv":0.0,"id":18318124},{"batb":[[0,4.1,47.27],[1,4,51.82],[2,1.01,0.51]],"ltp":3.05,"tv":470.0,"id":12986368},{"batb":[[0,2.12,76.94],[1,2.1,59.13],[2,1.01,0.51]],"ltp":0.0,"tv":0.0,"id":18318122}]}]}
{"op":"mcm","clk":"1004791690","pt":1580637439553,"mc":[{"id":"1.168209732","rc":[{"batb":[[0,1.01,0.51],[1,4.7,0],[2,1.01,0]],"ltp":0.0,"tv":0.0,"id":18318124},{"batb":[[0,1.01,0.51],[1,4,0],[2,1.01,0]],"ltp":3.05,"tv":470.0,"id":12986368}]}]}
{"op":"mcm","clk":"1004791894","pt":1580637442922,"mc":[{"id":"1.168209732","rc":[{"batb":[[2,4.1,13.44]],"batl":[[0,4.8,10.92]],"ltp":4.8,"tv":22.71,"id":12986367},{"batb":[[0,5,30.79],[1,4.9,35.1],[2,4.6,10.92]],"batl":[[0,5.4,9.24]],"ltp":0.0,"tv":0.0,"id":18318124},{"batb":[[0,7.4,14.52],[1,7.2,27],[2,6.4,7.56]],"batl":[[0,8,5.88]],"ltp":3.05,"tv":470.0,"id":12986368},{"batb":[[0,2.2,34.45],[1,2.12,57.58]],"batl":[[0,2.46,28.57]],"ltp":0.0,"tv":0.0,"id":18318122}]}]}
{"op":"mcm","clk":"1004792014","pt":1580637445448,"mc":[{"id":"1.168209732","rc":[{"batb":[[1,2.14,54.3],[2,2.12,57.58]],"ltp":0.0,"tv":0.0,"id":18318122}]}]}
{"op":"mcm","clk":"1004792487","pt":1580637453653,"mc":[{"id":"1.168209732","rc":[{"batb":[[0,4.3,44.67],[1,4.1,13.44],[2,1.01,0.51]],"ltp":4.8,"tv":22.71,"id":12986367},{"batb":[[0,5,20.43],[2,1.01,0.51]],"ltp":0.0,"tv":0.0,"id":18318124},{"batb":[[1,2.12,57.58],[2,1.01,0.51]],"ltp":0.0,"tv":0.0,"id":18318122}]}]}
{"op":"mcm","clk":"1004792693","pt":1580637456942,"mc":[{"id":"1.168209732","rc":[{"batb":[[0,4.4,43.96],[1,4.3,44.67],[2,4.1,13.44]],"ltp":4.8,"tv":22.71,"id":12986367},{"batb":[[2,4.5,11.76]],"ltp":0.0,"tv":0.0,"id":18318124},{"batb":[[0,7.4,26.28]],"ltp":3.05,"tv":470.0,"id":12986368},{"trd":[[2.2,20.72]],"batb":[[0,2.2,24.09],[1,2.12,75.53],[2,2.1,59.17]],"batl":[[0,2.42,265.37]],"ltp":2.2,"tv":20.71,"id":18318122}],"tv":513.44}]}
{"op":"mcm","clk":"1004792822","pt":1580637459766,"mc":[{"id":"1.168209732","rc":[{"batl":[[0,4.9,10.08]],"ltp":4.8,"tv":22.71,"id":12986367},{"batb":[[0,2.2,34.17]],"batl":[[1,2.44,28.57]],"ltp":2.2,"tv":20.71,"id":18318122}]}]}
{"op":"mcm","clk":"1004792882","pt":1580637460953,"mc":[{"id":"1.168209732","rc":[{"batb":[[0,4.9,35.1],[1,4.5,11.76],[2,1.01,0.51]],"ltp":0.0,"tv":0.0,"id":18318124},{"batb":[[0,6.4,7.56],[1,1.01,0.51],[2,6.4,0]],"ltp":3.05,"tv":470.0,"id":12986368},{"batb":[[1,1.01,0.51],[2,2.1,0]],"batl":[[0,2.44,28.57],[1,2.44,0]],"ltp":2.2,"tv":20.71,"id":18318122}]}]}
{"op":"mcm","clk":"1004792917","pt":1580637461576,"mc":[{"id":"1.168209732","rc":[{"batb":[[2,1.01,0.51]],"ltp":4.8,"tv":22.71,"id":12986367},{"batb":[[1,1.01,0.51],[2,1.01,0]],"ltp":0.0,"tv":0.0,"id":18318124},{"batb":[[0,1.01,0.51],[1,1.01,0]],"ltp":3.05,"tv":470.0,"id":12986368},{"batb":[[0,1.01,0.51],[1,1.01,0]],"ltp":2.2,"tv":20.71,"id":18318122}]}]}
{"op":"mcm","clk":"1004793054","pt":1580637463899,"mc":[{"id":"1.168209732","rc":[{"batb":[[1,4.8,36.44],[2,1.01,0.51]],"ltp":0.0,"tv":0.0,"id":18318124},{"batb":[[0,6,31.25],[1,5.9,21.23],[2,1.01,0.51]],"ltp":3.05,"tv":470.0,"id":12986368},{"batb":[[0,1.88,82.83],[1,1.86,85.9],[2,1.01,0.51]],"ltp":2.2,"tv":20.71,"id":18318122}]}]}
{"op":"mcm","clk":"1004793745","pt":1580637476683,"mc":[{"id":"1.168209732","rc":[{"batb":[[0,1.01,0.51],[1,1.86,0],[2,1.01,0]],"ltp":2.2,"tv":20.71,"id":18318122}]}]}
{"op":"mcm","clk":"1004793892","pt":1580637479795,"mc":[{"id":"1.168209732","rc":[{"batb":[[0,2.28,71.66],[1,2.26,47.89],[2,1.01,0.51]],"ltp":2.2,"tv":20.71,"id":18318122}]}]}
{"op":"mcm","clk":"1004793935","pt":1580637480619,"mc":[{"id":"1.168209732","rc":[{"batb":[[2,4.2,12.6]],"batl":[[0,4.9,10.08]],"ltp":4.8,"tv":22.71,"id":12986367},{"batb":[[2,4.5,11.76]],"batl":[[0,5.4,9.24]],"ltp":0.0,"tv":0.0,"id":18318124},{"batb":[[2,5.5,9.24]],"batl":[[0,6.6,6.72]],"ltp":3.05,"tv":470.0,"id":12986368},{"batb":[[0,2.32,31.09],[1,2.28,71.66],[2,2.26,47.89]],"batl":[[0,2.62,25.21]],"ltp":2.2,"tv":20.71,"id":18318122}]}]}
{"op":"mcm","clk":"1004795003","pt":1580637499620,"mc":[{"id":"1.168209732","rc":[{"batb":[[0,4.4,24.84]],"ltp":4.8,"tv":22.71,"id":12986367},{"batb":[[0,4.8,36.44],[1,4.5,11.76],[2,1.01,0.51]],"ltp":0.0,"tv":0.0,"id":18318124},{"batb":[[0,5.5,9.24],[1,1.01,0.51],[2,5.5,0]],"ltp":3.05,"tv":470.0,"id":12986368},{"batb":[[1,1.01,0.51],[2,2.26,0]],"ltp":2.2,"tv":20.71,"id":18318122}]}]}
{"op":"mcm","clk":"1004795117","pt":1580637501625,"mc":[{"id":"1.168209732","rc":[{"batb":[[2,1.01,0.51]],"ltp":4.8,"tv":22.71,"id":12986367},{"batb":[[1,1.01,0.51],[2,1.01,0]],"ltp":0.0,"tv":0.0,"id":18318124},{"batb":[[0,1.01,0.51],[1,1.01,0]],"ltp":3.05,"tv":470.0,"id":12986368},{"batb":[[0,1.01,0.51],[1,1.01,0]],"ltp":2.2,"tv":20.71,"id":18318122}]}]}
{"op":"mcm","clk":"1004795324","pt":1580637505748,"mc":[{"id":"1.168209732","rc":[{"batb":[[0,4.4,36.25]],"ltp":4.8,"tv":22.71,"id":12986367},{"batb":[[0,4.9,46.13],[1,4.8,36.44],[2,1.01,0.51]],"ltp":0.0,"tv":0.0,"id":18318124},{"batb":[[0,6.6,48.22],[1,6.4,34.49],[2,1.01,0.51]],"ltp":3.05,"tv":470.0,"id":12986368},{"batb":[[0,2.2,49.97],[1,2.18,53.11],[2,1.01,0.51]],"ltp":2.2,"tv":20.71,"id":18318122}]}]}
{"op":"mcm","clk":"1004795552","pt":1580637510849,"mc":[{"id":"1.168209732","rc":[{"batb":[[0,4.4,24.84]],"ltp":4.8,"tv":22.71,"id":12986367},{"batb":[[0,4.8,36.44],[1,1.01,0.51],[2,1.01,0]],"ltp":0.0,"tv":0.0,"id":18318124},{"batb":[[0,1.01,0.51],[1,6.4,0],[2,1.01,0]],"ltp":3.05,"tv":470.0,"id":12986368},{"batb":[[0,1.01,0.51],[1,2.18,0],[2,1.01,0]],"ltp":2.2,"tv":20.71,"id":18318122}]}]}
{"op":"mcm","clk":"1004795726","pt":1580637514459,"mc":[{"id":"1.168209732","rc":[{"batb":[[0,4.8,51.23],[1,4.7,37.88],[2,1.01,0.51]],"ltp":0.0,"tv":0.0,"id":18318124},{"batb":[[0,4.7,36.68],[1,4.6,37.32],[2,1.01,0.51]],"ltp":3.05,"tv":470.0,"id":12986368},{"batb":[[0,1.9,76.26],[1,1.88,83.05],[2,1.01,0.51]],"ltp":2.2,"tv":20.71,"id":18318122}]}]}
{"op":"mcm","clk":"1004796086","pt":1580637520839,"mc":[{"id":"1.168209732","rc":[{"batb":[[0,1.01,0.51],[1,4.7,0],[2,1.01,0]],"ltp":0.0,"tv":0.0,"id":18318124},{"batb":[[0,1.01,0.51],[1,4.6,0],[2,1.01,0]],"ltp":3.05,"tv":470.0,"id":12986368}]}]}
{"op":"mcm","clk":"1004796245","pt":1580637523884,"mc":[{"id":"1.168209732","rc":[{"batb":[[0,5,45.56],[1,4.9,34.88],[2,1.01,0.51]],"ltp":0.0,"tv":0.0,"id":18318124},{"batb":[[0,12.5,28.86],[1,12,21.91],[2,1.01,0.51]],"ltp":3.05,"tv":470.0,"id":12986368}]}]}
{"op":"mcm","clk":"1004796324","pt":1580637524864,"mc":[{"id":"1.168209732","rc":[{"batb":[[1,4.3,57.27]],"batl":[[0,5.1,10.08]],"ltp":4.8,"tv":22.71,"id":12986367},{"batb":[[2,4.6,10.92]],"batl":[[0,5.5,9.24]],"ltp":0.0,"tv":0.0,"id":18318124},{"batb":[[2,10.5,4.2]],"ltp":3.05,"tv":470.0,"id":12986368},{"batb":[[0,1.9,122.47]],"ltp":2.2,"tv":20.71,"id":18318122}]}]}
{"op":"mcm","clk":"1004796425","pt":1580637526874,"mc":[{"id":"1.168209732","rc":[{"batl":[[0,2.1,37.81]],"ltp":2.2,"tv":20.71,"id":18318122}]}]}
{"op":"mcm","clk":"1004797156","pt":1580637539809,"mc":[{"id":"1.168209732","rc":[{"batb":[[0,4.3,57.27],[1,1.01,0.51],[2,1.01,0]],"ltp":4.8,"tv":22.71,"id":12986367}]}]}
{"op":"mcm","clk":"1004797337","pt":1580637542608,"mc":[{"id":"1.168209732","rc":[{"batb":[[0,4.3,77.52],[1,4.2,46.94],[2,1.01,0.51]],"ltp":4.8,"tv":22.71,"id":12986367}]}]}
{"op":"mcm","clk":"1004801728","pt":1580637610302,"mc":[{"id":"1.168209732","rc":[{"batb":[[0,4.3,56.4]],"ltp":4.8,"tv":22.71,"id":12986367},{"batb":[[0,5,27.26]],"ltp":0.0,"tv":0.0,"id":18318124},{"batb":[[0,10.5,4.2],[1,1.01,0.51],[2,10.5,0]],"ltp":3.05,"tv":470.0,"id":12986368},{"batb":[[0,1.9,46.21],[1,1.01,0.51],[2,1.01,0]],"ltp":2.2,"tv":20.71,"id":18318122}]}]}
{"op":"mcm","clk":"1004801807","pt":1580637611401,"mc":[{"id":"1.168209732","rc":[{"batb":[[0,4.3,43.8]],"ltp":4.8,"tv":22.71,"id":12986367},{"batb":[[2,1.01,0.51]],"ltp":0.0,"tv":0.0,"id":18318124},{"batb":[[0,1.01,0.51],[1,1.01,0]],"ltp":3.05,"tv":470.0,"id":12986368},{"batb":[[0,1.01,0.51],[1,1.01,0]],"ltp":2.2,"tv":20.71,"id":18318122}]}]}
{"op":"mcm","clk":"1004801953","pt":1580637613514,"mc":[{"id":"1.168209732","rc":[{"batb":[[0,8.4,30],[1,8.2,20.36],[2,1.01,0.51]],"ltp":3.05,"tv":470.0,"id":12986368},{"batb":[[0,1.83,88.35],[1,1.81,93.83],[2,1.01,0.51]],"ltp":2.2,"tv":20.71,"id":18318122}]}]}
{"op":"mcm","clk":"1004802466","pt":1580637620948,"mc":[{"id":"1.168209732","rc":[{"batb":[[0,1.01,0.51],[1,8.2,0],[2,1.01,0]],"ltp":3.05,"tv":470.0,"id":12986368},{"batb":[[0,1.01,0.51],[1,1.81,0],[2,1.01,0]],"ltp":2.2,"tv":20.71,"id":18318122}]}]}
{"op":"mcm","clk":"1004802674","pt":1580637623915,"mc":[{"id":"1.168209732","rc":[{"batb":[[0,4.3,59.1]],"ltp":4.8,"tv":22.71,"id":12986367},{"batb":[[0,5,44.09]],"ltp":0.0,"tv":0.0,"id":18318124},{"batb":[[0,11.5,21.16],[1,11,26.59],[2,1.01,0.51]],"ltp":3.05,"tv":470.0,"id":12986368},{"batb":[[0,1.94,53.22],[1,1.92,77.7],[2,1.01,0.51]],"ltp":2.2,"tv":20.71,"id":18318122}]}]}
{"op":"mcm","clk":"1004802899","pt":1580637626923,"mc":[{"id":"1.168209732","rc":[{"batb":[[0,4.3,43.8]],"ltp":4.8,"tv":22.71,"id":12986367},{"batb":[[0,5,27.26]],"ltp":0.0,"tv":0.0,"id":18318124},{"batb":[[0,1.01,0.51],[1,11,0],[2,1.01,0]],"ltp":3.05,"tv":470.0,"id":12986368},{"batb":[[0,1.01,0.51],[1,1.92,0],[2,1.01,0]],"ltp":2.2,"tv":20.71,"id":18318122}]}]}
{"op":"mcm","clk":"1004803090","pt":1580637629558,"mc":[{"id":"1.168209732","rc":[{"batb":[[0,8.4,30],[1,8.2,20.36],[2,1.01,0.51]],"ltp":3.05,"tv":470.0,"id":12986368},{"batb":[[0,1.83,88.35],[1,1.81,93.83],[2,1.01,0.51]],"ltp":2.2,"tv":20.71,"id":18318122}]}]}
{"op":"mcm","clk":"1004803385","pt":1580637634163,"mc":[{"id":"1.168209732","rc":[{"batb":[[1,1.01,0.51],[2,1.01,0]],"ltp":4.8,"tv":22.71,"id":12986367},{"batb":[[1,1.01,0.51],[2,1.01,0]],"ltp":0.0,"tv":0.0,"id":18318124},{"batb":[[0,1.01,0.51],[1,8.2,0],[2,1.01,0]],"ltp":3.05,"tv":470.0,"id":12986368}]}]}
{"op":"mcm","clk":"1004803629","pt":1580637637837,"mc":[{"id":"1.168209732","rc":[{"batb":[[0,4.4,26.64],[1,4.3,43.8],[2,1.01,0.51]],"ltp":4.8,"tv":22.71,"id":12986367},{"batb":[[0,5.1,24.44],[1,5,27.26],[2,1.01,0.51]],"ltp":0.0,"tv":0.0,"id":18318124},{"batb":[[0,17,8.82],[1,16.5,11.66],[2,1.01,0.51]],"ltp":3.05,"tv":470.0,"id":12986368}]}]}
{"op":"mcm","clk":"1004803690","pt":1580637638769,"mc":[{"id":"1.168209732","rc":[{"batb":[[1,4.3,56.4]],"batl":[[0,5.1,10.08]],"ltp":4.8,"tv":22.71,"id":12986367},{"batb":[[2,4.6,10.92]],"batl":[[0,5.5,9.24]],"ltp":0.0,"tv":0.0,"id":18318124},{"batb":[[2,13.5,3.36]],"ltp":3.05,"tv":470.0,"id":12986368},{"batb":[[0,1.83,138.76]],"batl":[[0,2.02,41.17]],"ltp":2.2,"tv":20.71,"id":18318122}]}]}
{"op":"mcm","clk":"1004804917","pt":1580637655581,"mc":[{"id":"1.168209732","rc":[{"batb":[[0,4.3,43.8],[1,1.01,0.51],[2,1.01,0]],"ltp":4.8,"tv":22.71,"id":12986367},{"batb":[[0,5,27.26],[1,1.01,0.51],[2,4.6,0]],"ltp":0.0,"tv":0.0,"id":18318124},{"batb":[[0,1.01,0.51],[1,16.5,0],[2,13.5,0]],"ltp":3.05,"tv":470.0,"id":12986368},{"batb":[[0,1.01,0.51],[1,1.81,0],[2,1.01,0]],"ltp":2.2,"tv":20.71,"id":18318122}]}]}
{"op":"mcm","clk":"1004805171","pt":1580637659320,"mc":[{"id":"1.168209732","rc":[{"batb":[[1,4.2,47.33],[2,1.01,0.51]],"ltp":4.8,"tv":22.71,"id":12986367},{"batb":[[0,5,38.46],[1,4.9,35.02],[2,1.01,0.51]],"ltp":0.0,"tv":0.0,"id":18318124},{"batb":[[0,11.5,9.75],[1,11,27.07],[2,1.01,0.51]],"ltp":3.05,"tv":470.0,"id":12986368},{"batb":[[0,1.78,86.65],[1,1.76,102.95],[2,1.01,0.51]],"ltp":2.2,"tv":20.71,"id":18318122}]}]}
{"op":"mcm","clk":"1004805228","pt":1580637660205,"mc":[{"id":"1.168209732","rc":[{"batb":[[1,1.01,0.51],[2,1.01,0]],"ltp":4.8,"tv":22.71,"id":12986367},{"batb":[[1,1.01,0.51],[2,1.01,0]],"ltp":0.0,"tv":0.0,"id":18318124},{"batb":[[0,1.01,0.51],[1,11,0],[2,1.01,0]],"ltp":3.05,"tv":470.0,"id":12986368},{"batb":[[0,1.01,0.51],[1,1.76,0],[2,1.01,0]],"ltp":2.2,"tv":20.71,"id":18318122}]}]}
{"op":"mcm","clk":"1004805463","pt":1580637663221,"mc":[{"id":"1.168209732","rc":[{"batb":[[0,4.4,41.51],[1,4.3,43.8],[2,1.01,0.51]],"ltp":4.8,"tv":22.71,"id":12986367},{"batb":[[0,5.1,34.06],[1,5,38.46],[2,1.01,0.51]],"ltp":0.0,"tv":0.0,"id":18318124},{"batb":[[0,22,7.53],[1,21,13.86],[2,1.01,0.51]],"ltp":3.05,"tv":470.0,"id":12986368},{"batb":[[0,1.78,86.65],[1,1.76,102.95],[2,1.01,0.51]],"ltp":2.2,"tv":20.71,"id":18318122}]}]}
{"op":"mcm","clk":"1004805553","pt":1580637664514,"mc":[{"id":"1.168209732","rc":[{"batb":[[1,4.3,56.4]],"batl":[[0,5.1,10.08]],"ltp":4.8,"tv":22.71,"id":12986367},{"batb":[[2,4.6,10.92]],"batl":[[0,5.5,9.24]],"ltp":0.0,"tv":0.0,"id":18318124},{"batb":[[0,1.78,140.42]],"batl":[[0,1.97,42.01]],"ltp":2.2,"tv":20.71,"id":18318122}]}]}
{"op":"mcm","clk":"1004806262","pt":1580637674641,"mc":[{"id":"1.168209732","rc":[{"batb":[[0,4.3,56.4],[1,1.01,0.51],[2,1.01,0]],"ltp":4.8,"tv":22.71,"id":12986367},{"batb":[[0,5,38.46],[1,4.6,10.92],[2,1.01,0.51]],"ltp":0.0,"tv":0.0,"id":18318124},{"batb":[[0,1.01,0.51],[1,21,0],[2,1.01,0]],"ltp":3.05,"tv":470.0,"id":12986368},{"batb":[[0,1.78,53.77],[1,1.01,0.51],[2,1.01,0]],"ltp":2.2,"tv":20.71,"id":18318122}]}]}
{"op":"mcm","clk":"1004806343","pt":1580637675628,"mc":[{"id":"1.168209732","rc":[{"batb":[[0,4.3,43.8]],"ltp":4.8,"tv":22.71,"id":12986367},{"batb":[[1,1.01,0.51],[2,1.01,0]],"ltp":0.0,"tv":0.0,"id":18318124},{"batb":[[0,1.01,0.51],[1,1.01,0]],"ltp":2.2,"tv":20.71,"id":18318122}]}]}
{"op":"mcm","clk":"1004806489","pt":1580637677501,"mc":[{"id":"1.168209732","rc":[{"batb":[[1,4.2,47.33],[2,1.01,0.51]],"ltp":4.8,"tv":22.71,"id":12986367},{"batb":[[0,5,49.57],[1,4.9,34.88],[2,1.01,0.51]],"ltp":0.0,"tv":0.0,"id":18318124},{"batb":[[0,16,11.91],[1,15.5,13.17],[2,1.01,0.51]],"ltp":3.05,"tv":470.0,"id":12986368},{"batb":[[0,1.75,70.16],[1,1.73,109.05],[2,1.01,0.51]],"ltp":2.2,"tv":20.71,"id":18318122}]}]}
{"op":"mcm","clk":"1004806824","pt":1580637682241,"mc":[{"id":"1.168209732","rc":[{"batb":[[0,1.01,0.51],[1,1.73,0],[2,1.01,0]],"ltp":2.2,"tv":20.71,"id":18318122}]}]}
{"op":"mcm","clk":"1004807033","pt":1580637685147,"mc":[{"id":"1.168209732","rc":[{"batb":[[0,1.86,68.46],[1,1.84,88.92],[2,1.01,0.51]],"ltp":2.2,"tv":20.71,"id":18318122}]}]}
{"op":"mcm","clk":"1004807144","pt":1580637686564,"mc":[{"id":"1.168209732","rc":[{"batb":[[1,4.2,59.93]],"batl":[[0,5,10.08]],"ltp":4.8,"tv":22.71,"id":12986367},{"batb":[[2,4.6,10.92]],"batl":[[0,5.5,9.24]],"ltp":0.0,"tv":0.0,"id":18318124},{"batb":[[2,13.5,3.36]],"ltp":3.05,"tv":470.0,"id":12986368},{"batb":[[1,1.85,48.73],[2,1.84,88.92]],"batl":[[0,2.04,40.33]],"ltp":2.2,"tv":20.71,"id":18318122}]}]}
{"op":"mcm","clk":"1004808150","pt":1580637700698,"mc":[{"id":"1.168209732","rc":[{"batb":[[0,4.2,59.93],[1,1.01,0.51],[2,1.01,0]],"ltp":4.8,"tv":22.71,"id":12986367},{"batb":[[0,5,28.76]],"ltp":0.0,"tv":0.0,"id":18318124},{"batb":[[0,13.5,3.36],[1,1.01,0.51],[2,13.5,0]],"ltp":3.05,"tv":470.0,"id":12986368},{"batb":[[0,1.85,48.73],[1,1.01,0.51],[2,1.84,0]],"ltp":2.2,"tv":20.71,"id":18318122}]}]}
{"op":"mcm","clk":"1004808224","pt":1580637701590,"mc":[{"id":"1.168209732","rc":[{"batb":[[0,4.2,47.33]],"ltp":4.8,"tv":22.71,"id":12986367},{"batb":[[2,1.01,0.51]],"ltp":0.0,"tv":0.0,"id":18318124},{"batb":[[0,1.01,0.51],[1,1.01,0]],"ltp":3.05,"tv":470.0,"id":12986368},{"batb":[[0,1.01,0.51],[1,1.01,0]],"ltp":2.2,"tv":20.71,"id":18318122}]}]}
{"op":"mcm","clk":"1004808426","pt":1580637703773,"mc":[{"id":"1.168209732","rc":[{"batb":[[0,4.2,47.41]],"ltp":4.8,"tv":22.71,"id":12986367}]}]}
{"op":"mcm","clk":"1004808660","pt":1580637706363,"mc":[{"id":"1.168209732","rc":[{"batb":[[0,4.3,37.36],[1,4.2,47.41],[2,1.01,0.51]],"ltp":4.8,"tv":22.71,"id":12986367},{"batb":[[0,5,45.36]],"ltp":0.0,"tv":0.0,"id":18318124},{"batb":[[0,14.5,7.82],[1,14,16.43],[2,1.01,0.51]],"ltp":3.05,"tv":470.0,"id":12986368},{"batb":[[0,1.89,58.7],[1,1.87,84.43],[2,1.01,0.51]],"ltp":2.2,"tv":20.71,"id":18318122}]}]}
{"op":"mcm","clk":"1004808878","pt":1580637709619,"mc":[{"id":"1.168209732","rc":[{"batb":[[0,4.2,47.41],[1,1.01,0.51],[2,1.01,0]],"ltp":4.8,"tv":22.71,"id":12986367},{"batb":[[0,5,28.76]],"ltp":0.0,"tv":0.0,"id":18318124},{"batb":[[0,1.01,0.51],[1,14,0],[2,1.01,0]],"ltp":3.05,"tv":470.0,"id":12986368},{"batb":[[0,1.01,0.51],[1,1.87,0],[2,1.01,0]],"ltp":2.2,"tv":20.71,"id":18318122}]}]}
{"op":"mcm","clk":"1004809111","pt":1580637712587,"mc":[{"id":"1.168209732","rc":[{"batb":[[0,4.2,67.83],[1,4.1,49.61],[2,1.01,0.51]],"ltp":4.8,"tv":22.71,"id":12986367},{"batb":[[0,10,28.32],[1,9.8,13.88],[2,1.01,0.51]],"ltp":3.05,"tv":470.0,"id":12986368},{"batb":[[0,1.79,98.05],[1,1.77,101.07],[2,1.01,0.51]],"ltp":2.2,"tv":20.71,"id":18318122}]}]}
{"op":"mcm","clk":"1004809180","pt":1580637713517,"mc":[{"id":"1.168209732","rc":[{"batb":[[0,4.2,47.33],[1,1.01,0.51],[2,1.01,0]],"ltp":4.8,"tv":22.71,"id":12986367},{"batb":[[1,1.01,0.51],[2,1.01,0]],"ltp":0.0,"tv":0.0,"id":18318124},{"batb":[[0,1.01,0.51],[1,9.8,0],[2,1.01,0]],"ltp":3.05,"tv":470.0,"id":12986368}]}]}
{"op":"mcm","clk":"1004809429","pt":1580637716537,"mc":[{"id":"1.168209732","rc":[{"batb":[[0,4.3,56.66],[1,4.2,47.33],[2,1.01,0.51]],"ltp":4.8,"tv":22.71,"id":12986367},{"batb":[[0,5.1,24.79],[1,5,28.76],[2,1.01,0.51]],"ltp":0.0,"tv":0.0,"id":18318124},{"batb":[[0,22,12.02],[1,21,13.66],[2,1.01,0.51]],"ltp":3.05,"tv":470.0,"id":12986368}]}]}
{"op":"mcm","clk":"1004809589","pt":1580637718712,"mc":[{"id":"1.168209732","rc":[{"batb":[[1,4.2,59.93]],"batl":[[0,5,10.08]],"ltp":4.8,"tv":22.71,"id":12986367},{"batb":[[2,4.6,10.92]],"batl":[[0,5.5,9.24]],"ltp":0.0,"tv":0.0,"id":18318124},{"batb":[[0,1.79,150.98]],"batl":[[0,1.98,42.01]],"ltp":2.2,"tv":20.71,"id":18318122}]}]}
{"op":"mcm","clk":"1004810293","pt":1580637726649,"mc":[{"id":"1.168209732","rc":[{"trd":[[22,10.74]],"batb":[[0,22,6.65]],"ltp":22.0,"tv":480.74,"id":12986368}],"tv":524.18}]}
{"op":"mcm","clk":"1004810659","pt":1580637729927,"mc":[{"id":"1.168209732","rc":[{"batb":[[0,22,10.98]],"batl":[[0,690,3.69]],"ltp":22.0,"tv":480.74,"id":12986368}]}]}
{"op":"mcm","clk":"1004811600","pt":1580637740378,"mc":[{"id":"1.168209732","rc":[{"batb":[[0,4.2,59.93],[1,1.01,0.51],[2,1.01,0]],"ltp":4.8,"tv":22.71,"id":12986367},{"batb":[[0,5,28.76],[1,4.6,10.92],[2,1.01,0.51]],"ltp":0.0,"tv":0.0,"id":18318124},{"batb":[[0,1.01,0.51],[1,21,0],[2,1.01,0]],"ltp":22.0,"tv":480.74,"id":12986368},{"batb":[[0,1.79,52.93],[1,1.01,0.51],[2,1.01,0]],"ltp":2.2,"tv":20.71,"id":18318122}]}]}
{"op":"mcm","clk":"1004811716","pt":1580637741586,"mc":[{"id":"1.168209732","rc":[{"batb":[[0,4.2,47.33]],"ltp":4.8,"tv":22.71,"id":12986367},{"batb":[[1,1.01,0.51],[2,1.01,0]],"ltp":0.0,"tv":0.0,"id":18318124},{"batb":[[0,1.01,0.51],[1,1.01,0]],"ltp":2.2,"tv":20.71,"id":18318122}]}]}
{"op":"mcm","clk":"1004811880","pt":1580637743570,"mc":[{"id":"1.168209732","rc":[{"batb":[[0,4.2,59.71],[1,4.1,49.82],[2,1.01,0.51]],"ltp":4.8,"tv":22.71,"id":12986367},{"batb":[[0,5,41.89],[1,4.9,34.99],[2,1.01,0.51]],"ltp":0.0,"tv":0.0,"id":18318124},{"batb":[[0,16.5,7.44],[1,16,12.43],[2,1.01,0.51]],"ltp":22.0,"tv":480.74,"id":12986368},{"batb":[[0,1.76,85.53],[1,1.74,107.19],[2,1.01,0.51]],"ltp":2.2,"tv":20.71,"id":18318122}]}]}
{"op":"mcm","clk":"1004812056","pt":1580637745866,"mc":[{"id":"1.168209732","rc":[{"batb":[[0,4.2,47.33],[1,1.01,0.51],[2,1.01,0]],"ltp":4.8,"tv":22.71,"id":12986367},{"batb":[[0,5,33.75],[1,1.01,0.51],[2,1.01,0]],"ltp":0.0,"tv":0.0,"id":18318124},{"batb":[[0,1.01,0.51],[1,16,0],[2,1.01,0]],"ltp":22.0,"tv":480.74,"id":12986368},{"batb":[[0,1.01,0.51],[1,1.74,0],[2,1.01,0]],"ltp":2.2,"tv":20.71,"id":18318122}]}]}
{"op":"mcm","clk":"1004812284","pt":1580637748858,"mc":[{"id":"1.168209732","rc":[{"batb":[[0,4.3,47.9],[1,4.2,47.33],[2,1.01,0.51]],"ltp":4.8,"tv":22.71,"id":12986367},{"batb":[[0,5.1,21.53],[1,5,33.75],[2,1.01,0.51]],"ltp":0.0,"tv":0.0,"id":18318124},{"batb":[[0,20,20.29],[1,19.5,7.93],[2,1.01,0.51]],"ltp":22.0,"tv":480.74,"id":12986368},{"batb":[[0,1.81,71.82],[1,1.79,97.29],[2,1.01,0.51]],"ltp":2.2,"tv":20.71,"id":18318122}]}]}
{"op":"mcm","clk":"1004812333","pt":1580637749481,"mc":[{"id":"1.168209732","rc":[{"batb":[[0,4.2,47.33],[1,1.01,0.51],[2,1.01,0]],"ltp":4.8,"tv":22.71,"id":12986367},{"batb":[[0,5,33.75],[1,1.01,0.51],[2,1.01,0]],"ltp":0.0,"tv":0.0,"id":18318124},{"batb":[[0,1.01,0.51],[1,19.5,0],[2,1.01,0]],"ltp":22.0,"tv":480.74,"id":12986368},{"batb":[[0,1.01,0.51],[1,1.79,0],[2,1.01,0]],"ltp":2.2,"tv":20.71,"id":18318122}]}]}
{"op":"mcm","clk":"1004812618","pt":1580637753173,"mc":[{"id":"1.168209732","rc":[{"batb":[[0,4.2,59.71],[1,4.1,49.82],[2,1.01,0.51]],"ltp":4.8,"tv":22.71,"id":12986367},{"batb":[[0,5,41.89],[1,4.9,34.99],[2,1.01,0.51]],"ltp":0.0,"tv":0.0,"id":18318124},{"batb":[[0,16.5,7.44],[1,16,12.43],[2,1.01,0.51]],"ltp":22.0,"tv":480.74,"id":12986368},{"batb":[[0,1.76,85.53],[1,1.74,107.19],[2,1.01,0.51]],"ltp":2.2,"tv":20.71,"id":18318122}]}]}
{"op":"mcm","clk":"1004813001","pt":1580637758684,"mc":[{"id":"1.168209732","rc":[{"batb":[[0,1.01,0.51],[1,4.1,0],[2,1.01,0]],"ltp":4.8,"tv":22.71,"id":12986367},{"batb":[[0,5,33.75],[1,1.01,0.51],[2,1.01,0]],"ltp":0.0,"tv":0.0,"id":18318124},{"batb":[[0,1.01,0.51],[1,16,0],[2,1.01,0]],"ltp":22.0,"tv":480.74,"id":12986368}]}]}
{"op":"mcm","clk":"1004813270","pt":1580637761919,"mc":[{"id":"1.168209732","rc":[{"batb":[[0,4.4,32.56],[1,4.3,45.05],[2,1.01,0.51]],"ltp":4.8,"tv":22.71,"id":12986367},{"batb":[[0,5.1,33.51],[1,5,33.75],[2,1.01,0.51]],"ltp":0.0,"tv":0.0,"id":18318124},{"batb":[[0,27,3.96],[1,26,9.05],[2,1.01,0.51]],"ltp":22.0,"tv":480.74,"id":12986368}]}]}
{"op":"mcm","clk":"1004813350","pt":1580637762914,"mc":[{"id":"1.168209732","rc":[{"batb":[[1,4.3,57.65]],"batl":[[0,5.1,10.08]],"ltp":4.8,"tv":22.71,"id":12986367},{"batb":[[2,4.6,10.92]],"batl":[[0,5.5,9.24]],"ltp":0.0,"tv":0.0,"id":18318124},{"batb":[[1,1.74,163.48]],"batl":[[0,1.92,42.01]],"ltp":2.2,"tv":20.71,"id":18318122}]}]}
{"op":"mcm","clk":"1004815348","pt":1580637791751,"mc":[{"id":"1.168209732","rc":[{"batb":[[0,4.3,57.65],[1,1.01,0.51],[2,1.01,0]],"ltp":4.8,"tv":22.71,"id":12986367},{"batb":[[0,5,33.75],[1,4.6,10.92],[2,1.01,0.51]],"ltp":0.0,"tv":0.0,"id":18318124},{"batb":[[0,1.01,0.51],[1,26,0],[2,1.01,0]],"ltp":22.0,"tv":480.74,"id":12986368},{"batb":[[0,1.74,56.29],[1,1.01,0.51],[2,1.01,0]],"ltp":2.2,"tv":20.71,"id":18318122}]}]}
{"op":"mcm","clk":"1004815489","pt":1580637793637,"mc":[{"id":"1.168209732","rc":[{"batb":[[0,4.3,45.05]],"ltp":4.8,"tv":22.71,"id":12986367},{"batb":[[1,1.01,0.51],[2,1.01,0]],"ltp":0.0,"tv":0.0,"id":18318124},{"batb":[[0,1.01,0.51],[1,1.01,0]],"ltp":2.2,"tv":20.71,"id":18318122}]}]}
{"op":"mcm","clk":"1004815562","pt":1580637794940,"mc":[{"id":"1.168209732","rc":[{"batb":[[1,4.2,47.37],[2,1.01,0.51]],"ltp":4.8,"tv":22.71,"id":12986367},{"batb":[[0,5,50.94],[1,4.9,34.86],[2,1.01,0.51]],"ltp":0.0,"tv":0.0,"id":18318124},{"batb":[[0,24,7.38],[1,23,11.46],[2,1.01,0.51]],"ltp":22.0,"tv":480.74,"id":12986368},{"batb":[[0,1.71,73.89],[1,1.69,118.24],[2,1.01,0.51]],"ltp":2.2,"tv":20.71,"id":18318122}]}]}
{"op":"mcm","clk":"1004815845","pt":1580637799185,"mc":[{"id":"1.168209732","rc":[{"batb":[[0,1.01,0.51],[1,4.2,0],[2,1.01,0]],"ltp":4.8,"tv":22.71,"id":12986367},{"batb":[[0,1.01,0.51],[1,4.9,0],[2,1.01,0]],"ltp":0.0,"tv":0.0,"id":18318124},{"batb":[[0,1.01,0.51],[1,23,0],[2,1.01,0]],"ltp":22.0,"tv":480.74,"id":12986368}]}]}
{"op":"mcm","clk":"1004816083","pt":1580637802869,"mc":[{"id":"1.168209732","rc":[{"batb":[[0,4.5,49.52],[1,4.4,54.2],[2,1.01,0.51]],"batl":[[0,5.3,9.24]],"ltp":4.8,"tv":22.71,"id":12986367},{"batb":[[0,5.2,30.88],[1,5.1,32.17],[2,4.6,10.92]],"batl":[[0,5.6,8.4]],"ltp":0.0,"tv":0.0,"id":18318124},{"batb":[[0,32,13.98],[1,30,7.54],[2,1.01,0.51]],"ltp":22.0,"tv":480.74,"id":12986368},{"batb":[[1,1.7,59.65],[2,1.69,118.24]],"batl":[[0,1.86,42.01]],"ltp":2.2,"tv":20.71,"id":18318122}]}]}
{"op":"mcm","clk":"1004817079","pt":1580637816581,"mc":[{"id":"1.168209732","rc":[{"batb":[[0,4.4,54.2],[1,1.01,0.51],[2,1.01,0]],"ltp":4.8,"tv":22.71,"id":12986367},{"batb":[[0,5.1,32.17],[1,4.6,10.92],[2,1.01,0.51]],"ltp":0.0,"tv":0.0,"id":18318124},{"batb":[[0,1.01,0.51],[1,30,0],[2,1.01,0]],"ltp":22.0,"tv":480.74,"id":12986368},{"batb":[[0,1.7,59.65],[1,1.01,0.51],[2,1.69,0]],"ltp":2.2,"tv":20.71,"id":18318122}]}]}
{"op":"mcm","clk":"1004817163","pt":1580637817620,"mc":[{"id":"1.168209732","rc":[{"batb":[[0,4.4,42.44]],"ltp":4.8,"tv":22.71,"id":12986367},{"batb":[[1,1.01,0.51],[2,1.01,0]],"ltp":0.0,"tv":0.0,"id":18318124},{"batb":[[0,1.01,0.51],[1,1.01,0]],"ltp":2.2,"tv":20.71,"id":18318122}]}]}
{"op":"mcm","clk":"1004817257","pt":1580637819023,"mc":[{"id":"1.168209732","rc":[{"batb":[[0,4.4,56.01],[1,4.3,44.65],[2,1.01,0.51]],"ltp":4.8,"tv":22.71,"id":12986367},{"batb":[[0,5.1,42.95],[1,5,33.44],[2,1.01,0.51]],"ltp":0.0,"tv":0.0,"id":18318124},{"batb":[[0,28,6.15],[1,27,8.31],[2,1.01,0.51]],"ltp":22.0,"tv":480.74,"id":12986368},{"batb":[[0,1.65,79.03],[1,1.64,66.2],[2,1.01,0.51]],"ltp":2.2,"tv":20.71,"id":18318122}]}]}
{"op":"mcm","clk":"1004817756","pt":1580637826025,"mc":[{"id":"1.168209732","rc":[{"batb":[[0,1.01,0.51],[1,4.3,0],[2,1.01,0]],"ltp":4.8,"tv":22.71,"id":12986367},{"batb":[[0,1.01,0.51],[1,5,0],[2,1.01,0]],"ltp":0.0,"tv":0.0,"id":18318124},{"batb":[[0,1.01,0.51],[1,27,0],[2,1.01,0]],"ltp":22.0,"tv":480.74,"id":12986368}]}]}
{"op":"mcm","clk":"1004817958","pt":1580637828943,"mc":[{"id":"1.168209732","rc":[{"batb":[[0,4.7,33.34],[1,4.6,38.57],[2,1.01,0.51]],"ltp":4.8,"tv":22.71,"id":12986367},{"batb":[[0,5.3,35.66],[1,5.2,30.74],[2,1.01,0.51]],"ltp":0.0,"tv":0.0,"id":18318124},{"batb":[[0,50,5.41],[1,48,5.05],[2,1.01,0.51]],"ltp":22.0,"tv":480.74,"id":12986368}]}]}
{"op":"mcm","clk":"1004818104","pt":1580637830917,"mc":[{"id":"1.168209732","rc":[{"batb":[[2,4.5,11.76]],"batl":[[0,5.4,9.24]],"ltp":4.8,"tv":22.71,"id":12986367},{"batb":[[2,4.6,10.92]],"batl":[[0,5.6,8.4]],"ltp":0.0,"tv":0.0,"id":18318124},{"batb":[[0,1.65,142.88]],"batl":[[0,1.81,42.01]],"ltp":2.2,"tv":20.71,"id":18318122}]}]}
{"op":"mcm","clk":"1004818414","pt":1580637835528,"mc":[{"id":"1.168209732","rc":[{"batb":[[1,48,4.31]],"ltp":22.0,"tv":480.74,"id":12986368}]}]}
{"op":"mcm","clk":"1004818637","pt":1580637838851,"mc":[{"id":"1.168209732","rc":[{"batb":[[0,50,9.32],[1,48,3.41]],"ltp":22.0,"tv":480.74,"id":12986368},{"batl":[[0,1.8,42.01]],"ltp":2.2,"tv":20.71,"id":18318122}]}]}
{"op":"mcm","clk":"1004818961","pt":1580637844555,"mc":[{"id":"1.168209732","rc":[{"batl":[[0,640,3.89]],"ltp":22.0,"tv":480.74,"id":12986368}]}]}
{"op":"mcm","clk":"1004819164","pt":1580637847775,"mc":[{"id":"1.168209732","rc":[{"batb":[[0,4.6,38.57],[1,1.01,0.51],[2,4.5,0]],"ltp":4.8,"tv":22.71,"id":12986367},{"batb":[[0,5.2,30.74],[1,1.01,0.51],[2,4.6,0]],"ltp":0.0,"tv":0.0,"id":18318124},{"batb":[[0,1.01,0.51],[1,48,0],[2,1.01,0]],"ltp":22.0,"tv":480.74,"id":12986368},{"batb":[[0,1.01,0.51],[1,1.64,0],[2,1.01,0]],"ltp":2.2,"tv":20.71,"id":18318122}]}]}
{"op":"mcm","clk":"1004819326","pt":1580637850361,"mc":[{"id":"1.168209732","rc":[{"batb":[[1,4.5,40.61],[2,1.01,0.51]],"ltp":4.8,"tv":22.71,"id":12986367},{"batb":[[0,5.2,43.06],[1,5.1,32.01],[2,1.01,0.51]],"ltp":0.0,"tv":0.0,"id":18318124},{"batb":[[0,38,10.23],[1,36,7.91],[2,1.01,0.51]],"ltp":22.0,"tv":480.74,"id":12986368},{"batb":[[0,1.59,69.2],[1,1.58,75.94],[2,1.01,0.51]],"ltp":2.2,"tv":20.71,"id":18318122}]}]}
{"op":"mcm","clk":"1004819473","pt":1580637852630,"mc":[{"id":"1.168209732","rc":[{"batb":[[0,1.01,0.51],[1,1.58,0],[2,1.01,0]],"ltp":2.2,"tv":20.71,"id":18318122}]}]}
{"op":"mcm","clk":"1004819622","pt":1580637855660,"mc":[{"id":"1.168209732","rc":[{"batb":[[0,1.68,113.53],[1,1.67,62.2],[2,1.01,0.51]],"ltp":2.2,"tv":20.71,"id":18318122}]}]}
{"op":"mcm","clk":"1004819710","pt":1580637856955,"mc":[{"id":"1.168209732","rc":[{"batb":[[1,4.5,52.37]],"batl":[[0,5.4,9.24]],"ltp":4.8,"tv":22.71,"id":12986367},{"batb":[[2,4.6,10.92]],"batl":[[0,5.6,8.4]],"ltp":0.0,"tv":0.0,"id":18318124},{"batb":[[0,1.68,174.86]],"batl":[[0,1.83,42.01]],"ltp":2.2,"tv":20.71,"id":18318122}]}]}
{"op":"mcm","clk":"1004820085","pt":1580637861886,"mc":[{"id":"1.168209732","rc":[{"trd":[[4.6,4.93]],"batb":[[0,4.6,33.64]],"ltp":4.6,"tv":27.64,"id":12986367},{"trd":[[5.2,4.36]],"batb":[[0,5.2,38.7]],"ltp":5.2,"tv":4.36,"id":18318124},{"trd":[[38,0.6]],"batb":[[0,38,9.63]],"ltp":38.0,"tv":481.34,"id":12986368},{"trd":[[1.78,12.73]],"ltp":1.78,"tv":33.44,"id":18318122}],"tv":546.8}]}
{"op":"mcm","clk":"1004820296","pt":1580637865267,"mc":[{"id":"1.168209732","rc":[{"batl":[[0,750,3.33]],"ltp":38.0,"tv":481.34,"id":12986368}]}]}
{"op":"mcm","clk":"1004820550","pt":1580637870825,"mc":[{"id":"1.168209732","rc":[{"batb":[[0,4.5,52.37],[1,1.01,0.51],[2,1.01,0]],"ltp":4.6,"tv":27.64,"id":12986367},{"batb":[[0,5.1,32.01],[1,4.6,10.92],[2,1.01,0.51]],"ltp":5.2,"tv":4.36,"id":18318124},{"batb":[[0,1.01,0.51],[1,36,0],[2,1.01,0]],"ltp":38.0,"tv":481.34,"id":12986368},{"batb":[[0,1.68,61.33],[1,1.01,0.51],[2,1.01,0]],"ltp":1.78,"tv":33.44,"id":18318122}]}]}
{"op":"mcm","clk":"1004820660","pt":1580637872905,"mc":[{"id":"1.168209732","rc":[{"batb":[[0,4.5,40.61]],"ltp":4.6,"tv":27.64,"id":12986367},{"batb":[[1,1.01,0.51],[2,1.01,0]],"ltp":5.2,"tv":4.36,"id":18318124},{"batb":[[0,1.01,0.51],[1,1.01,0]],"ltp":1.78,"tv":33.44,"id":18318122}]}]}
{"op":"mcm","clk":"1004820901","pt":1580637877122,"mc":[{"id":"1.168209732","rc":[{"batb":[[1,4.4,42.75],[2,1.01,0.51]],"ltp":4.6,"tv":27.64,"id":12986367},{"batb":[[0,5.1,51.11],[1,5,33.34],[2,1.01,0.51]],"ltp":5.2,"tv":4.36,"id":18318124},{"batb":[[0,30,9.43],[1,29,7.34],[2,1.01,0.51]],"ltp":38.0,"tv":481.34,"id":12986368},{"batb":[[0,1.73,62.76],[1,1.71,113.64],[2,1.01,0.51]],"ltp":1.78,"tv":33.44,"id":18318122}]}]}
{"op":"mcm","clk":"1004820987","pt":1580637878627,"mc":[{"id":"1.168209732","rc":[{"batb":[[1,4.4,54.51]],"batl":[[0,5.3,9.24]],"ltp":4.6,"tv":27.64,"id":12986367},{"batb":[[2,4.6,10.92]],"batl":[[0,5.5,9.24]],"ltp":5.2,"tv":4.36,"id":18318124},{"batb":[[1,1.71,172.45]],"batl":[[0,1.87,42.01]],"ltp":1.78,"tv":33.44,"id":18318122}]}]}
{"op":"mcm","clk":"1004821616","pt":1580637889719,"mc":[{"id":"1.168209732","rc":[{"batb":[[0,4.4,42.75],[1,1.01,0.51],[2,1.01,0]],"ltp":4.6,"tv":27.64,"id":12986367},{"batb":[[0,5.1,32.01],[2,1.01,0.51]],"ltp":5.2,"tv":4.36,"id":18318124},{"batb":[[0,1.01,0.51],[1,29,0],[2,1.01,0]],"ltp":38.0,"tv":481.34,"id":12986368},{"batb":[[0,1.01,0.51],[1,1.71,0],[2,1.01,0]],"ltp":1.78,"tv":33.44,"id":18318122}]}]}
{"op":"mcm","clk":"1004821791","pt":1580637892829,"mc":[{"id":"1.168209732","rc":[{"batb":[[1,4.3,44.98],[2,1.01,0.51]],"ltp":4.6,"tv":27.64,"id":12986367},{"batb":[[0,25,8.19],[1,24,10.87],[2,1.01,0.51]],"ltp":38.0,"tv":481.34,"id":12986368},{"batb":[[0,1.66,78.95],[1,1.65,64.82],[2,1.01,0.51]],"ltp":1.78,"tv":33.44,"id":18318122}]}]}
{"op":"mcm","clk":"1004821966","pt":1580637895512,"mc":[{"id":"1.168209732","rc":[{"batb":[[0,1.01,0.51],[1,1.65,0],[2,1.01,0]],"ltp":1.78,"tv":33.44,"id":18318122}]}]}
{"op":"mcm","clk":"1004822182","pt":1580637898948,"mc":[{"id":"1.168209732","rc":[{"batb":[[0,4.4,54.51]],"batl":[[0,5.2,9.24]],"ltp":4.6,"tv":27.64,"id":12986367},{"batb":[[2,4.6,10.92]],"batl":[[0,5.5,9.24]],"ltp":5.2,"tv":4.36,"id":18318124},{"batb":[[0,1.77,67.9],[1,1.75,105.09],[2,1.01,0.51]],"batl":[[0,1.91,42.01]],"ltp":1.78,"tv":33.44,"id":18318122}]}]}
{"op":"mcm","clk":"1004822391","pt":1580637901662,"mc":[{"id":"1.168209732","rc":[{"batb":[[2,1.74,56.29]],"ltp":1.78,"tv":33.44,"id":18318122}]}]}
{"op":"mcm","clk":"1004822651","pt":1580637904936,"mc":[{"id":"1.168209732","rc":[{"batl":[[0,1.9,156.95],[1,1.91,42.01]],"ltp":1.78,"tv":33.44,"id":18318122}]}]}
{"op":"mcm","clk":"1004823353","pt":1580637914787,"mc":[{"id":"1.168209732","rc":[{"batb":[[0,4.4,11.76]],"ltp":4.6,"tv":27.64,"id":12986367},{"batb":[[0,5,33.34],[1,4.6,10.92],[2,1.01,0.51]],"ltp":5.2,"tv":4.36,"id":18318124},{"batb":[[0,1.01,0.51],[1,24,0],[2,1.01,0]],"ltp":38.0,"tv":481.34,"id":12986368},{"batb":[[0,1.74,56.29],[1,1.01,0.51],[2,1.74,0]],"batl":[[0,1.91,42.01],[1,1.91,0]],"ltp":1.78,"tv":33.44,"id":18318122}]}]}
{"op":"mcm","clk":"1004823424","pt":1580637915878,"mc":[{"id":"1.168209732","rc":[{"batb":[[0,4.3,44.98],[1,1.01,0.51],[2,1.01,0]],"ltp":4.6,"tv":27.64,"id":12986367},{"batb":[[1,1.01,0.51],[2,1.01,0]],"ltp":5.2,"tv":4.36,"id":18318124},{"batb":[[0,1.01,0.51],[1,1.01,0]],"ltp":1.78,"tv":33.44,"id":18318122}]}]}
{"op":"mcm","clk":"1004823546","pt":1580637917704,"mc":[{"id":"1.168209732","rc":[{"batb":[[1,4.2,47.28],[2,1.01,0.51]],"ltp":4.6,"tv":27.64,"id":12986367},{"batb":[[0,5,46.62],[1,4.9,34.97],[2,1.01,0.51]],"ltp":5.2,"tv":4.36,"id":18318124},{"batb":[[0,23,4.65],[1,22,13.13],[2,1.01,0.51]],"ltp":38.0,"tv":481.34,"id":12986368},{"batb":[[0,1.72,60.66],[1,1.7,115.95],[2,1.01,0.51]],"ltp":1.78,"tv":33.44,"id":18318122}]}]}
{"op":"mcm","clk":"1004823637","pt":1580637918900,"mc":[{"id":"1.168209732","rc":[{"batb":[[0,1.01,0.51],[1,1.7,0],[2,1.01,0]],"ltp":1.78,"tv":33.44,"id":18318122}]}]}
{"op":"mcm","clk":"1004823839","pt":1580637921910,"mc":[{"id":"1.168209732","rc":[{"batb":[[0,1.8,67.02],[1,1.78,99.3],[2,1.01,0.51]],"ltp":1.78,"tv":33.44,"id":18318122}]}]}
{"op":"mcm","clk":"1004823893","pt":1580637922701,"mc":[{"id":"1.168209732","rc":[{"batb":[[1,4.2,59.88]],"batl":[[0,5,10.08]],"ltp":4.6,"tv":27.64,"id":12986367},{"batb":[[2,4.6,10.92]],"batl":[[0,5.5,9.24]],"ltp":5.2,"tv":4.36,"id":18318124},{"batb":[[1,1.78,153.07]],"batl":[[0,1.94,42.01]],"ltp":1.78,"tv":33.44,"id":18318122}]}]}
{"op":"mcm","clk":"1004824382","pt":1580637929801,"mc":[{"id":"1.168209732","rc":[{"batb":[[0,4.2,59.88],[1,1.01,0.51],[2,1.01,0]],"ltp":4.6,"tv":27.64,"id":12986367},{"batb":[[0,5,33.92],[1,4.6,10.92],[2,1.01,0.51]],"ltp":5.2,"tv":4.36,"id":18318124},{"batb":[[0,22,13.13],[1,1.01,0.51],[2,1.01,0]],"ltp":38.0,"tv":481.34,"id":12986368},{"batb":[[0,1.78,53.77],[1,1.01,0.51],[2,1.01,0]],"ltp":1.78,"tv":33.44,"id":18318122}]}]}
{"op":"mcm","clk":"1004824574","pt":1580637932721,"mc":[{"id":"1.168209732","rc":[{"batb":[[0,4.2,73.86],[1,4.1,49.15],[2,1.01,0.51]],"ltp":4.6,"tv":27.64,"id":12986367},{"batb":[[0,5.1,24.53],[1,5,33.92],[2,4.6,10.92]],"ltp":5.2,"tv":4.36,"id":18318124},{"batb":[[1,21,13.82],[2,1.01,0.51]],"ltp":38.0,"tv":481.34,"id":12986368},{"batb":[[0,1.81,77.97],[1,1.79,97.32],[2,1.78,53.77]],"ltp":1.78,"tv":33.44,"id":18318122}]}]}
{"op":"mcm","clk":"1004824647","pt":1580637933802,"mc":[{"id":"1.168209732","rc":[{"batl":[[0,550,4.62]],"ltp":38.0,"tv":481.34,"id":12986368},{"batl":[[0,1.93,165.64],[1,1.94,42.01]],"ltp":1.78,"tv":33.44,"id":18318122}]}]}
{"op":"mcm","clk":"1004824702","pt":1580637934688,"mc":[{"id":"1.168209732","rc":[{"batl":[[0,1.94,42.01],[1,1.94,0]],"ltp":1.78,"tv":33.44,"id":18318122}]}]}
{"op":"mcm","clk":"1004824876","pt":1580637937614,"mc":[{"id":"1.168209732","rc":[{"batb":[[0,22,15.76]],"ltp":38.0,"tv":481.34,"id":12986368}]}]}
{"op":"mcm","clk":"1004825082","pt":1580637940788,"mc":[{"id":"1.168209732","rc":[{"batl":[[0,1.94,210.59]],"ltp":1.78,"tv":33.44,"id":18318122}]}]}
{"op":"mcm","clk":"1004829303","pt":1580638009821,"mc":[{"id":"1.168209732","rc":[{"batb":[[0,4.2,36.81]],"ltp":4.6,"tv":27.64,"id":12986367},{"batb":[[0,5,33.92],[1,1.01,0.51],[2,4.6,0]],"ltp":5.2,"tv":4.36,"id":18318124},{"batb":[[0,1.01,0.51],[1,21,0],[2,1.01,0]],"ltp":38.0,"tv":481.34,"id":12986368},{"batb":[[0,1.01,0.51],[1,1.79,0],[2,1.78,0]],"ltp":1.78,"tv":33.44,"id":18318122}]}]}
{"op":"mcm","clk":"1004829508","pt":1580638012900,"mc":[{"id":"1.168209732","rc":[{"batb":[[1,4.9,35.39],[2,1.01,0.51]],"ltp":5.2,"tv":4.36,"id":18318124},{"batb":[[0,11.5,14.41],[1,11,27.36],[2,1.01,0.51]],"ltp":38.0,"tv":481.34,"id":12986368},{"batb":[[0,1.74,75.18],[1,1.72,111.2],[2,1.01,0.51]],"ltp":1.78,"tv":33.44,"id":18318122}]}]}
{"op":"mcm","clk":"1004829771","pt":1580638017317,"mc":[{"id":"1.168209732","rc":[{"batb":[[1,1.01,0.51],[2,1.01,0]],"ltp":4.6,"tv":27.64,"id":12986367},{"batb":[[1,1.01,0.51],[2,1.01,0]],"ltp":5.2,"tv":4.36,"id":18318124},{"batb":[[0,1.01,0.51],[1,11,0],[2,1.01,0]],"ltp":38.0,"tv":481.34,"id":12986368}]}]}
{"op":"mcm","clk":"1004829973","pt":1580638020649,"mc":[{"id":"1.168209732","rc":[{"batb":[[0,4.3,25.22],[1,4.2,59.66],[2,1.01,0.51]],"batl":[[0,5,10.08]],"ltp":4.6,"tv":27.64,"id":12986367},{"batb":[[0,5.1,36.29],[1,5,33.92],[2,4.6,10.92]],"batl":[[0,5.5,9.24]],"ltp":5.2,"tv":4.36,"id":18318124},{"batb":[[0,42,4.53],[1,40,7.57],[2,1.01,0.51]],"ltp":38.0,"tv":481.34,"id":12986368},{"batb":[[1,1.72,169.17]],"batl":[[0,1.87,42.01]],"ltp":1.78,"tv":33.44,"id":18318122}]}]}
{"op":"mcm","clk":"1004830882","pt":1580638034760,"mc":[{"id":"1.168209732","rc":[{"batb":[[0,4.2,49.41],[1,1.01,0.51],[2,1.01,0]],"ltp":4.6,"tv":27.64,"id":12986367},{"batb":[[0,5,33.92],[1,4.6,10.92],[2,1.01,0.51]],"ltp":5.2,"tv":4.36,"id":18318124},{"batb":[[0,1.01,0.51],[1,40,0],[2,1.01,0]],"ltp":38.0,"tv":481.34,"id":12986368},{"batb":[[0,1.72,57.97],[1,1.01,0.51],[2,1.01,0]],"ltp":1.78,"tv":33.44,"id":18318122}]}]}
{"op":"mcm","clk":"1004830974","pt":1580638035953,"mc":[{"id":"1.168209732","rc":[{"batb":[[0,4.2,36.81]],"ltp":4.6,"tv":27.64,"id":12986367},{"batb":[[1,1.01,0.51],[2,1.01,0]],"ltp":5.2,"tv":4.36,"id":18318124},{"batb":[[0,1.01,0.51],[1,1.01,0]],"ltp":1.78,"tv":33.44,"id":18318122}]}]}
{"op":"mcm","clk":"1004831068","pt":1580638037468,"mc":[{"id":"1.168209732","rc":[{"batb":[[1,4.1,49.7],[2,1.01,0.51]],"ltp":4.6,"tv":27.64,"id":12986367}]}]}
{"op":"mcm","clk":"1004831210","pt":1580638039395,"mc":[{"id":"1.168209732","rc":[{"batb":[[0,4.2,64.86]],"ltp":4.6,"tv":27.64,"id":12986367},{"batb":[[0,5.1,31.4],[1,5,33.92],[2,1.01,0.51]],"ltp":5.2,"tv":4.36,"id":18318124},{"batb":[[0,34,2.98],[1,32,11.94],[2,1.01,0.51]],"ltp":38.0,"tv":481.34,"id":12986368},{"batb":[[0,1.76,84.17],[1,1.74,106.97],[2,1.01,0.51]],"ltp":1.78,"tv":33.44,"id":18318122}]}]}
{"op":"mcm","clk":"1004831514","pt":1580638043202,"mc":[{"id":"1.168209732","rc":[{"batb":[[0,4.2,36.81]],"ltp":4.6,"tv":27.64,"id":12986367},{"batb":[[0,5,33.92],[1,1.01,0.51],[2,1.01,0]],"ltp":5.2,"tv":4.36,"id":18318124},{"batb":[[0,1.01,0.51],[1,32,0],[2,1.01,0]],"ltp":38.0,"tv":481.34,"id":12986368},{"batb":[[0,1.01,0.51],[1,1.74,0],[2,1.01,0]],"ltp":1.78,"tv":33.44,"id":18318122}]}]}
{"op":"mcm","clk":"1004831714","pt":1580638045900,"mc":[{"id":"1.168209732","rc":[{"batb":[[0,5,46.32],[1,4.9,35.17],[2,1.01,0.51]],"ltp":5.2,"tv":4.36,"id":18318124},{"batb":[[0,18.5,11.93],[1,18,9.87],[2,1.01,0.51]],"ltp":38.0,"tv":481.34,"id":12986368},{"batb":[[0,1.69,82.6],[1,1.68,60.66],[2,1.01,0.51]],"ltp":1.78,"tv":33.44,"id":18318122}]}]}
{"op":"mcm","clk":"1004832159","pt":1580638052675,"mc":[{"id":"1.168209732","rc":[{"batb":[[0,1.01,0.51],[1,1.68,0],[2,1.01,0]],"ltp":1.78,"tv":33.44,"id":18318122}]}]}
{"op":"mcm","clk":"1004832359","pt":1580638055909,"mc":[{"id":"1.168209732","rc":[{"batb":[[0,1.85,95.27],[1,1.83,90.66],[2,1.01,0.51]],"ltp":1.78,"tv":33.44,"id":18318122}]}]}
{"op":"mcm","clk":"1004832410","pt":1580638056686,"mc":[{"id":"1.168209732","rc":[{"batb":[[0,4.2,49.41]],"batl":[[0,5,10.08]],"ltp":4.6,"tv":27.64,"id":12986367},{"batb":[[2,4.6,10.92]],"batl":[[0,5.5,9.24]],"ltp":5.2,"tv":4.36,"id":18318124},{"batb":[[2,1.81,51.25]],"batl":[[0,2,42.01]],"ltp":1.78,"tv":33.44,"id":18318122}]}]}
{"op":"mcm","clk":"1004833162","pt":1580638069734,"mc":[{"id":"1.168209732","rc":[{"batb":[[0,4.1,49.7],[1,1.01,0.51],[2,1.01,0]],"ltp":4.6,"tv":27.64,"id":12986367},{"batb":[[0,4.9,35.17],[1,1.01,0.51],[2,4.6,0]],"ltp":5.2,"tv":4.36,"id":18318124},{"batb":[[0,1.01,0.51],[1,18,0],[2,1.01,0]],"ltp":38.0,"tv":481.34,"id":12986368},{"batb":[[0,1.01,0.51],[1,1.83,0],[2,1.81,0]],"ltp":1.78,"tv":33.44,"id":18318122}]}]}
{"op":"mcm","clk":"1004833343","pt":1580638072214,"mc":[{"id":"1.168209732","rc":[{"batb":[[0,4.1,73.44],[1,4,51.98],[2,1.01,0.51]],"ltp":4.6,"tv":27.64,"id":12986367},{"batb":[[0,4.9,56.04],[1,4.8,36.75],[2,1.01,0.51]],"ltp":5.2,"tv":4.36,"id":18318124},{"batb":[[0,9,21.07],[1,8.8,17.95],[2,1.01,0.51]],"ltp":38.0,"tv":481.34,"id":12986368},{"batb":[[0,1.76,86.47],[1,1.74,106.97],[2,1.01,0.51]],"ltp":1.78,"tv":33.44,"id":18318122}]}]}
{"op":"mcm","clk":"1004833653","pt":1580638076457,"mc":[{"id":"1.168209732","rc":[{"batb":[[0,4.1,49.7],[1,1.01,0.51],[2,1.01,0]],"ltp":4.6,"tv":27.64,"id":12986367},{"batb":[[0,1.01,0.51],[1,4.8,0],[2,1.01,0]],"ltp":5.2,"tv":4.36,"id":18318124},{"batb":[[0,1.01,0.51],[1,8.8,0],[2,1.01,0]],"ltp":38.0,"tv":481.34,"id":12986368}]}]}
{"op":"mcm","clk":"1004833896","pt":1580638079733,"mc":[{"id":"1.168209732","rc":[{"batb":[[0,4.2,36.33],[1,4.1,49.7],[2,1.01,0.51]],"ltp":4.6,"tv":27.64,"id":12986367},{"batb":[[0,5.1,24.79],[1,5,33.9],[2,1.01,0.51]],"ltp":5.2,"tv":4.36,"id":18318124},{"batb":[[0,38,8.79],[1,36,9.12],[2,1.01,0.51]],"ltp":38.0,"tv":481.34,"id":12986368}]}]}
{"op":"mcm","clk":"1004833955","pt":1580638080628,"mc":[{"id":"1.168209732","rc":[{"batb":[[1,4.1,63.14]],"batl":[[0,4.9,10.08]],"ltp":4.6,"tv":27.64,"id":12986367},{"batb":[[2,4.6,10.92]],"batl":[[0,5.5,9.24]],"ltp":5.2,"tv":4.36,"id":18318124},{"batb":[[2,1.73,57.13]],"batl":[[0,1.9,42.01]],"ltp":1.78,"tv":33.44,"id":18318122}]}]}
{"op":"mcm","clk":"1004834037","pt":1580638081666,"mc":[{"id":"1.168209732","rc":[{"batb":[[0,4.2,25.13]],"ltp":4.6,"tv":27.64,"id":12986367},{"batb":[[0,38,7.83]],"ltp":38.0,"tv":481.34,"id":12986368}]}]}
{"op":"mcm","clk":"1004834246","pt":1580638084940,"mc":[{"id":"1.168209732","rc":[{"batl":[[0,670,3.73]],"ltp":38.0,"tv":481.34,"id":12986368}]}]}
{"op":"mcm","clk":"1004834847","pt":1580638094469,"mc":[{"id":"1.168209732","rc":[{"batb":[[0,4.1,63.14],[1,1.01,0.51],[2,1.01,0]],"ltp":4.6,"tv":27.64,"id":12986367},{"batb":[[0,5,33.9],[1,4.6,10.92],[2,1.01,0.51]],"ltp":5.2,"tv":4.36,"id":18318124},{"batb":[[0,1.01,0.51],[1,36,0],[2,1.01,0]],"ltp":38.0,"tv":481.34,"id":12986368},{"batb":[[0,1.73,57.13],[1,1.01,0.51],[2,1.73,0]],"ltp":1.78,"tv":33.44,"id":18318122}]}]}
{"op":"mcm","clk":"1004834936","pt":1580638095774,"mc":[{"id":"1.168209732","rc":[{"batb":[[0,4.1,49.7]],"ltp":4.6,"tv":27.64,"id":12986367},{"batb":[[1,1.01,0.51],[2,1.01,0]],"ltp":5.2,"tv":4.36,"id":18318124},{"batb":[[0,1.01,0.51],[1,1.01,0]],"ltp":1.78,"tv":33.44,"id":18318122}]}]}
{"op":"mcm","clk":"1004835074","pt":1580638097849,"mc":[{"id":"1.168209732","rc":[{"batb":[[0,1.7,97.84],[1,1.68,120.59],[2,1.01,0.51]],"ltp":1.78,"tv":33.44,"id":18318122}]}]}
{"op":"mcm","clk":"1004835297","pt":1580638100869,"mc":[{"id":"1.168209732","rc":[{"batb":[[0,4.2,39.8],[1,4.1,49.7],[2,1.01,0.51]],"ltp":4.6,"tv":27.64,"id":12986367},{"batb":[[0,5.1,39.73],[1,5,33.9],[2,1.01,0.51]],"ltp":5.2,"tv":4.36,"id":18318124}]}]}
{"op":"mcm","clk":"1004835422","pt":1580638102690,"mc":[{"id":"1.168209732","rc":[{"batb":[[1,4.1,63.14]],"batl":[[0,4.9,10.08]],"ltp":4.6,"tv":27.64,"id":12986367},{"batb":[[2,4.6,10.92]],"batl":[[0,5.6,8.4]],"ltp":5.2,"tv":4.36,"id":18318124},{"batb":[[1,1.68,181.92]],"batl":[[0,1.84,42.01]],"ltp":1.78,"tv":33.44,"id":18318122}]}]}
{"op":"mcm","clk":"1004836186","pt":1580638114819,"mc":[{"id":"1.168209732","rc":[{"batb":[[0,4.1,45.16],[1,1.01,0.51],[2,1.01,0]],"ltp":4.6,"tv":27.64,"id":12986367},{"batb":[[0,5,33.9],[1,4.6,10.92],[2,1.01,0.51]],"ltp":5.2,"tv":4.36,"id":18318124},{"batb":[[0,1.68,61.33],[1,1.01,0.51],[2,1.01,0]],"ltp":1.78,"tv":33.44,"id":18318122}]}]}
{"op":"mcm","clk":"1004836242","pt":1580638115811,"mc":[{"id":"1.168209732","rc":[{"batb":[[0,4.1,31.72]],"ltp":4.6,"tv":27.64,"id":12986367},{"batb":[[1,1.01,0.51],[2,1.01,0]],"ltp":5.2,"tv":4.36,"id":18318124},{"batb":[[0,1.01,0.51],[1,1.01,0]],"ltp":1.78,"tv":33.44,"id":18318122}]}]}
{"op":"mcm","clk":"1004836354","pt":1580638117516,"mc":[{"id":"1.168209732","rc":[{"batb":[[1,4,52.44],[2,1.01,0.51]],"ltp":4.6,"tv":27.64,"id":12986367},{"batb":[[0,5,52.24],[1,4.9,35.1],[2,1.01,0.51]],"ltp":5.2,"tv":4.36,"id":18318124},{"batb":[[0,44,6.93],[1,42,6.73],[2,1.01,0.51]],"ltp":38.0,"tv":481.34,"id":12986368},{"batb":[[0,1.67,90.72],[1,1.66,62.77],[2,1.01,0.51]],"ltp":1.78,"tv":33.44,"id":18318122}]}]}
{"op":"mcm","clk":"1004838132","pt":1580638143903,"mc":[{"id":"1.168209732","rc":[{"batb":[[1,1.01,0.51],[2,1.01,0]],"ltp":4.6,"tv":27.64,"id":12986367},{"batb":[[0,5,33.9],[1,1.01,0.51],[2,1.01,0]],"ltp":5.2,"tv":4.36,"id":18318124},{"batb":[[0,1.01,0.51],[1,42,0],[2,1.01,0]],"ltp":38.0,"tv":481.34,"id":12986368}]}]}
{"op":"mcm","clk":"1004838344","pt":1580638146830,"mc":[{"id":"1.168209732","rc":[{"batb":[[0,4.2,66.39],[1,4.1,62.24],[2,1.01,0.51]],"batl":[[0,4.9,10.08]],"ltp":4.6,"tv":27.64,"id":12986367},{"batb":[[0,5.1,49.99],[1,5,33.9],[2,4.6,10.92]],"batl":[[0,5.6,8.4]],"ltp":5.2,"tv":4.36,"id":18318124},{"batb":[[2,1.65,63.85]],"batl":[[0,1.81,42.01]],"ltp":1.78,"tv":33.44,"id":18318122}]}]}
{"op":"mcm","clk":"1004838399","pt":1580638147558,"mc":[{"id":"1.168209732","rc":[{"batb":[[1,4.1,48.8]],"ltp":4.6,"tv":27.64,"id":12986367}]}]}
{"op":"mcm","clk":"1004838514","pt":1580638149228,"mc":[{"id":"1.168209732","rc":[{"batb":[[0,4.2,78.99]],"ltp":4.6,"tv":27.64,"id":12986367},{"batl":[[0,1.8,42.01]],"ltp":1.78,"tv":33.44,"id":18318122}]}]}
{"op":"mcm","clk":"1004838974","pt":1580638155460,"mc":[{"id":"1.168209732","rc":[{"batb":[[0,17,15.96],[1,1.01,0.51]],"ltp":38.0,"tv":481.34,"id":12986368}]}]}
{"op":"mcm","clk":"1004840413","pt":1580638175785,"mc":[{"id":"1.168209732","rc":[{"batb":[[0,4.2,66.39]],"ltp":4.6,"tv":27.64,"id":12986367},{"batb":[[2,1.01,0.51]],"ltp":5.2,"tv":4.36,"id":18318124},{"batb":[[2,1.01,0.51]],"ltp":1.78,"tv":33.44,"id":18318122}]}]}
{"op":"mcm","clk":"1004840671","pt":1580638179185,"mc":[{"id":"1.168209732","rc":[{"batl":[[0,14.5,210.57]],"ltp":4.6,"tv":27.64,"id":12986367},{"batl":[[0,22,134.88]],"ltp":5.2,"tv":4.36,"id":18318124},{"batl":[[0,2.02,112.27]],"ltp":1.78,"tv":33.44,"id":18318122}]}]}
{"op":"mcm","clk":"1004841573","pt":1580638191094,"mc":[{"id":"1.168209732","rc":[{"batb":[[0,4.2,54.27]],"ltp":4.6,"tv":27.64,"id":12986367},{"batb":[[0,5.1,32.56],[1,1.01,0.51],[2,1.01,0]],"ltp":5.2,"tv":4.36,"id":18318124}]}]}
{"op":"mcm","clk":"1004841822","pt":1580638194508,"mc":[{"id":"1.168209732","rc":[{"batb":[[0,5.2,20.02],[1,5.1,32.56],[2,1.01,0.51]],"ltp":5.2,"tv":4.36,"id":18318124}]}]}
{"op":"mcm","clk":"1004849008","pt":1580638294849,"mc":[{"id":"1.168209732","rc":[{"batb":[[0,1.67,112.56]],"ltp":1.78,"tv":33.44,"id":18318122}]}]}
{"op":"mcm","clk":"1004857380","pt":1580638401797,"mc":[{"id":"1.168209732","rc":[{"batb":[[1,1.01,0.51],[2,1.01,0]],"ltp":4.6,"tv":27.64,"id":12986367},{"batb":[[0,5.1,32.56],[1,1.01,0.51],[2,1.01,0]],"ltp":5.2,"tv":4.36,"id":18318124},{"batb":[[0,1.66,62.77],[1,1.01,0.51],[2,1.01,0]],"ltp":1.78,"tv":33.44,"id":18318122}]}]}
{"op":"mcm","clk":"1004857577","pt":1580638404763,"mc":[{"id":"1.168209732","rc":[{"batb":[[0,4.3,47.71],[1,4.2,54.27],[2,1.01,0.51]],"ltp":4.6,"tv":27.64,"id":12986367},{"batb":[[0,5.1,42.36],[1,5,33.56],[2,1.01,0.51]],"ltp":5.2,"tv":4.36,"id":18318124},{"batb":[[0,1.66,114.19],[1,1.65,64.86],[2,1.01,0.51]],"ltp":1.78,"tv":33.44,"id":18318122}]}]}
{"op":"mcm","clk":"1004859612","pt":1580638431722,"mc":[{"id":"1.168209732","rc":[{"batb":[[0,1.01,0.51],[1,4.2,0],[2,1.01,0]],"ltp":4.6,"tv":27.64,"id":12986367},{"batb":[[0,1.01,0.51],[1,5,0],[2,1.01,0]],"ltp":5.2,"tv":4.36,"id":18318124},{"batb":[[0,1.01,0.51],[1,1.65,0],[2,1.01,0]],"ltp":1.78,"tv":33.44,"id":18318122}]}]}
{"op":"mcm","clk":"1004859859","pt":1580638434739,"mc":[{"id":"1.168209732","rc":[{"batb":[[0,4,58.41],[1,3.95,27.4],[2,1.01,0.51]],"ltp":4.6,"tv":27.64,"id":12986367},{"batb":[[0,4.8,35.77],[1,4.7,38.73],[2,1.01,0.51]],"ltp":5.2,"tv":4.36,"id":18318124},{"batb":[[0,1.53,125.63],[1,1.52,88.24],[2,1.01,0.51]],"ltp":1.78,"tv":33.44,"id":18318122}]}]}
{"op":"mcm","clk":"1004859962","pt":1580638436102,"mc":[{"id":"1.168209732","rc":[{"batb":[[0,1.01,0.51],[1,3.95,0],[2,1.01,0]],"ltp":4.6,"tv":27.64,"id":12986367},{"batb":[[0,1.01,0.51],[1,4.7,0],[2,1.01,0]],"ltp":5.2,"tv":4.36,"id":18318124},{"batb":[[0,1.01,0.51],[1,1.52,0],[2,1.01,0]],"ltp":1.78,"tv":33.44,"id":18318122}]}]}
{"op":"mcm","clk":"1004860225","pt":1580638439609,"mc":[{"id":"1.168209732","rc":[{"batb":[[0,4.4,50.54],[1,4.3,44.37],[2,1.01,0.51]],"ltp":4.6,"tv":27.64,"id":12986367},{"batb":[[0,5.2,50.24],[1,5.1,31.98],[2,1.01,0.51]],"ltp":5.2,"tv":4.36,"id":18318124},{"batb":[[0,1.64,65.89],[1,1.63,67.58],[2,1.01,0.51]],"ltp":1.78,"tv":33.44,"id":18318122}]}]}
{"op":"mcm","clk":"1004860640","pt":1580638444430,"mc":[{"id":"1.168209732","rc":[{"batb":[[0,1.01,0.51],[1,4.3,0],[2,1.01,0]],"ltp":4.6,"tv":27.64,"id":12986367},{"batb":[[0,1.01,0.51],[1,5.1,0],[2,1.01,0]],"ltp":5.2,"tv":4.36,"id":18318124},{"batb":[[0,1.01,0.51],[1,1.63,0],[2,1.01,0]],"ltp":1.78,"tv":33.44,"id":18318122}]}]}
{"op":"mcm","clk":"1004860914","pt":1580638447421,"mc":[{"id":"1.168209732","rc":[{"batb":[[0,4,57.37],[1,3.95,27.4],[2,1.01,0.51]],"ltp":4.6,"tv":27.64,"id":12986367},{"batb":[[0,4.8,36.04],[1,4.7,38.73],[2,1.01,0.51]],"ltp":5.2,"tv":4.36,"id":18318124},{"batb":[[0,1.53,127.14],[1,1.52,88.24],[2,1.01,0.51]],"ltp":1.78,"tv":33.44,"id":18318122}]}]}
{"op":"mcm","clk":"1004861159","pt":1580638450618,"mc":[{"id":"1.168209732","rc":[{"batb":[[0,1.01,0.51],[1,1.52,0],[2,1.01,0]],"ltp":1.78,"tv":33.44,"id":18318122}]}]}
{"op":"mcm","clk":"1004861438","pt":1580638453751,"mc":[{"id":"1.168209732","rc":[{"batb":[[0,1.75,73.85],[1,1.73,109.24],[2,1.01,0.51]],"ltp":1.78,"tv":33.44,"id":18318122}]}]}
{"op":"mcm","clk":"1004861541","pt":1580638454821,"mc":[{"id":"1.168209732","rc":[{"batb":[[1,3.95,40.84]],"batl":[[0,4.6,10.92]],"ltp":4.6,"tv":27.64,"id":12986367},{"batb":[[2,4.4,11.76]],"batl":[[0,5.2,9.24]],"ltp":5.2,"tv":4.36,"id":18318124},{"batb":[[2,1.72,57.97]],"batl":[[0,1.9,42.01]],"ltp":1.78,"tv":33.44,"id":18318122}]}]}
{"op":"mcm","clk":"1004862484","pt":1580638465845,"mc":[{"id":"1.168209732","rc":[{"batb":[[0,3.95,13.44],[1,1.01,0.51],[2,1.01,0]],"ltp":4.6,"tv":27.64,"id":12986367},{"batb":[[0,4.4,11.76],[1,1.01,0.51],[2,4.4,0]],"ltp":5.2,"tv":4.36,"id":18318124},{"batb":[[0,1.72,57.97],[1,1.01,0.51],[2,1.72,0]],"ltp":1.78,"tv":33.44,"id":18318122}]}]}
{"op":"mcm","clk":"1004862724","pt":1580638468756,"mc":[{"id":"1.168209732","rc":[{"batb":[[0,3.85,29.43],[1,3.8,30.34],[2,1.01,0.51]],"ltp":4.6,"tv":27.64,"id":12986367},{"batb":[[0,4.6,30.01],[1,4.5,42.86],[2,1.01,0.51]],"ltp":5.2,"tv":4.36,"id":18318124},{"batb":[[0,1.63,105.79],[1,1.62,69.26],[2,1.01,0.51]],"ltp":1.78,"tv":33.44,"id":18318122}]}]}
{"op":"mcm","clk":"1004862808","pt":1580638469847,"mc":[{"id":"1.168209732","rc":[{"batb":[[0,1.01,0.51],[1,3.8,0],[2,1.01,0]],"ltp":4.6,"tv":27.64,"id":12986367},{"batb":[[0,1.01,0.51],[1,4.5,0],[2,1.01,0]],"ltp":5.2,"tv":4.36,"id":18318124},{"batb":[[0,1.01,0.51],[1,1.62,0],[2,1.01,0]],"ltp":1.78,"tv":33.44,"id":18318122}]}]}
{"op":"mcm","clk":"1004862915","pt":1580638471250,"mc":[{"id":"1.168209732","rc":[{"batb":[[0,4.1,44.82],[1,4,52.73],[2,1.01,0.51]],"ltp":4.6,"tv":27.64,"id":12986367},{"batb":[[0,4.9,29.74],[1,4.8,37.02],[2,1.01,0.51]],"ltp":5.2,"tv":4.36,"id":18318124},{"batb":[[0,1.72,106.15],[1,1.7,116.11],[2,1.01,0.51]],"ltp":1.78,"tv":33.44,"id":18318122}]}]}
{"op":"mcm","clk":"1004863337","pt":1580638475955,"mc":[{"id":"1.168209732","rc":[{"batb":[[0,1.01,0.51],[1,4,0],[2,1.01,0]],"ltp":4.6,"tv":27.64,"id":12986367},{"batb":[[0,1.01,0.51],[1,4.8,0],[2,1.01,0]],"ltp":5.2,"tv":4.36,"id":18318124},{"batb":[[0,1.01,0.51],[1,1.7,0],[2,1.01,0]],"ltp":1.78,"tv":33.44,"id":18318122}]}]}
{"op":"mcm","clk":"1004863514","pt":1580638478055,"mc":[{"id":"1.168209732","rc":[{"batb":[[0,3.85,29.43],[1,3.8,30.34],[2,1.01,0.51]],"ltp":4.6,"tv":27.64,"id":12986367},{"batb":[[0,4.6,30.01],[1,4.5,42.86],[2,1.01,0.51]],"ltp":5.2,"tv":4.36,"id":18318124},{"batb":[[0,1.63,105.79],[1,1.62,69.26],[2,1.01,0.51]],"ltp":1.78,"tv":33.44,"id":18318122}]}]}
{"op":"mcm","clk":"1004864024","pt":1580638483783,"mc":[{"id":"1.168209732","rc":[{"batb":[[0,1.01,0.51],[1,3.8,0],[2,1.01,0]],"ltp":4.6,"tv":27.64,"id":12986367},{"batb":[[0,1.01,0.51],[1,4.5,0],[2,1.01,0]],"ltp":5.2,"tv":4.36,"id":18318124}]}]}
{"op":"mcm","clk":"1004864319","pt":1580638486871,"mc":[{"id":"1.168209732","rc":[{"batb":[[0,4.4,63.32],[1,4.3,56.74],[2,1.01,0.51]],"batl":[[0,5.1,10.08]],"ltp":4.6,"tv":27.64,"id":12986367},{"batb":[[0,5.3,19.54],[1,5.2,31.06],[2,4.7,10.92]],"batl":[[0,5.7,8.4]],"ltp":5.2,"tv":4.36,"id":18318124},{"batb":[[0,1.63,172.17]],"batl":[[0,1.77,42.01]],"ltp":1.78,"tv":33.44,"id":18318122}]}]}
{"op":"mcm","clk":"1004865936","pt":1580638503882,"mc":[{"id":"1.168209732","rc":[{"batb":[[0,1.01,0.51],[1,4.3,0],[2,1.01,0]],"ltp":4.6,"tv":27.64,"id":12986367},{"batb":[[0,1.01,0.51],[1,5.2,0],[2,4.7,0]],"ltp":5.2,"tv":4.36,"id":18318124},{"batb":[[0,1.01,0.51],[1,1.62,0],[2,1.01,0]],"ltp":1.78,"tv":33.44,"id":18318122}]}]}
{"op":"mcm","clk":"1004866323","pt":1580638508730,"mc":[{"id":"1.168209732","rc":[{"batb":[[0,4.6,38.58],[1,4.5,40.1],[2,1.01,0.51]],"ltp":4.6,"tv":27.64,"id":12986367},{"batb":[[0,5.4,39.95],[1,5.3,29.47],[2,1.01,0.51]],"ltp":5.2,"tv":4.36,"id":18318124},{"batb":[[0,1.6,87.51],[1,1.59,74.1],[2,1.01,0.51]],"ltp":1.78,"tv":33.44,"id":18318122}]}]}
{"op":"mcm","clk":"1004866703","pt":1580638513416,"mc":[{"id":"1.168209732","rc":[{"batb":[[0,1.01,0.51],[1,4.5,0],[2,1.01,0]],"ltp":4.6,"tv":27.64,"id":12986367},{"batb":[[0,1.01,0.51],[1,5.3,0],[2,1.01,0]],"ltp":5.2,"tv":4.36,"id":18318124},{"batb":[[0,1.01,0.51],[1,1.59,0],[2,1.01,0]],"ltp":1.78,"tv":33.44,"id":18318122}]}]}
{"op":"mcm","clk":"1004866918","pt":1580638516308,"mc":[{"id":"1.168209732","rc":[{"batb":[[0,4.1,35.01],[1,4,52.91],[2,1.01,0.51]],"ltp":4.6,"tv":27.64,"id":12986367},{"batb":[[0,4.8,46.44],[1,4.7,38.56],[2,1.01,0.51]],"ltp":5.2,"tv":4.36,"id":18318124},{"batb":[[0,1.48,98.3],[1,1.47,100.8],[2,1.01,0.51]],"ltp":1.78,"tv":33.44,"id":18318122}]}]}
{"op":"mcm","clk":"1004867157","pt":1580638519943,"mc":[{"id":"1.168209732","rc":[{"batb":[[0,1.01,0.51],[1,1.47,0],[2,1.01,0]],"ltp":1.78,"tv":33.44,"id":18318122}]}]}
{"op":"mcm","clk":"1004867386","pt":1580638522939,"mc":[{"id":"1.168209732","rc":[{"batb":[[1,4,66.35]],"batl":[[0,4.7,10.92]],"ltp":4.6,"tv":27.64,"id":12986367},{"batb":[[2,4.4,11.76]],"batl":[[0,5.2,9.24]],"ltp":5.2,"tv":4.36,"id":18318124},{"batb":[[0,1.73,106.65],[1,1.71,172.61],[2,1.01,0.51]],"batl":[[0,1.88,42.01]],"ltp":1.78,"tv":33.44,"id":18318122}]}]}
{"op":"mcm","clk":"1004868684","pt":1580638538945,"mc":[{"id":"1.168209732","rc":[{"batb":[[0,4,13.44],[1,1.01,0.51],[2,1.01,0]],"ltp":4.6,"tv":27.64,"id":12986367},{"batb":[[0,4.4,11.76],[1,1.01,0.51],[2,4.4,0]],"ltp":5.2,"tv":4.36,"id":18318124},{"batb":[[0,1.71,58.81],[1,1.01,0.51],[2,1.01,0]],"ltp":1.78,"tv":33.44,"id":18318122}]}]}
{"op":"mcm","clk":"1004868783","pt":1580638540047,"mc":[{"id":"1.168209732","rc":[{"batb":[[0,1.01,0.51],[1,1.01,0]],"ltp":4.6,"tv":27.64,"id":12986367},{"batb":[[0,1.01,0.51],[1,1.01,0]],"ltp":5.2,"tv":4.36,"id":18318124},{"batb":[[0,1.01,0.51],[1,1.01,0]],"ltp":1.78,"tv":33.44,"id":18318122}]}]}
{"op":"mcm","clk":"1004868913","pt":1580638541823,"mc":[{"id":"1.168209732","rc":[{"batb":[[0,3.85,41.1],[1,3.8,30.23],[2,1.01,0.51]],"ltp":4.6,"tv":27.64,"id":12986367},{"batb":[[0,4.5,64.06],[1,4.4,44.56],[2,1.01,0.51]],"ltp":5.2,"tv":4.36,"id":18318124},{"batb":[[0,1.6,96.99],[1,1.59,74.14],[2,1.01,0.51]],"ltp":1.78,"tv":33.44,"id":18318122}]}]}
{"op":"mcm","clk":"1004869131","pt":1580638544328,"mc":[{"id":"1.168209732","rc":[{"batb":[[0,1.01,0.51],[1,1.59,0],[2,1.01,0]],"ltp":1.78,"tv":33.44,"id":18318122}]}]}
{"op":"mcm","clk":"1004869330","pt":1580638546935,"mc":[{"id":"1.168209732","rc":[{"batb":[[0,1.82,72.85],[1,1.8,95.77],[2,1.01,0.51]],"ltp":1.78,"tv":33.44,"id":18318122}]}]}
{"op":"mcm","clk":"1004869516","pt":1580638549951,"mc":[{"id":"1.168209732","rc":[{"batb":[[0,3.85,55.38]],"batl":[[0,4.5,11.76]],"ltp":4.6,"tv":27.64,"id":12986367},{"batb":[[2,4.1,13.44]],"batl":[[0,4.9,10.08]],"ltp":5.2,"tv":4.36,"id":18318124},{"batb":[[2,1.79,52.93]],"batl":[[0,1.97,42.01]],"ltp":1.78,"tv":33.44,"id":18318122}]}]}
{"op":"mcm","clk":"1004870152","pt":1580638558950,"mc":[{"id":"1.168209732","rc":[{"batb":[[0,3.85,14.28],[1,1.01,0.51],[2,1.01,0]],"ltp":4.6,"tv":27.64,"id":12986367},{"batb":[[0,4.4,44.56],[1,4.1,13.44],[2,1.01,0.51]],"ltp":5.2,"tv":4.36,"id":18318124},{"batb":[[0,1.79,52.93],[1,1.01,0.51],[2,1.79,0]],"ltp":1.78,"tv":33.44,"id":18318122}]}]}
{"op":"mcm","clk":"1004870218","pt":1580638559986,"mc":[{"id":"1.168209732","rc":[{"batb":[[0,1.01,0.51],[1,1.01,0]],"ltp":4.6,"tv":27.64,"id":12986367},{"batb":[[1,1.01,0.51],[2,1.01,0]],"ltp":5.2,"tv":4.36,"id":18318124},{"batb":[[0,1.01,0.51],[1,1.01,0]],"ltp":1.78,"tv":33.44,"id":18318122}]}]}
{"op":"mcm","clk":"1004870374","pt":1580638561877,"mc":[{"id":"1.168209732","rc":[{"batb":[[0,3.7,58.32],[1,3.65,33.15],[2,1.01,0.51]],"ltp":4.6,"tv":27.64,"id":12986367},{"batb":[[0,4.4,59.35],[1,4.3,47.07],[2,1.01,0.51]],"ltp":5.2,"tv":4.36,"id":18318124},{"batb":[[0,1.74,68.9],[1,1.72,111.4],[2,1.01,0.51]],"ltp":1.78,"tv":33.44,"id":18318122}]}]}
{"op":"mcm","clk":"1004870448","pt":1580638562880,"mc":[{"id":"1.168209732","rc":[{"batb":[[0,1.01,0.51],[1,1.72,0],[2,1.01,0]],"ltp":1.78,"tv":33.44,"id":18318122}]}]}
{"op":"mcm","clk":"1004870693","pt":1580638565857,"mc":[{"id":"1.168209732","rc":[{"batb":[[0,1.87,62.1],[1,1.85,87.65],[2,1.01,0.51]],"ltp":1.78,"tv":33.44,"id":18318122}]}]}
{"op":"mcm","clk":"1004870851","pt":1580638567955,"mc":[{"id":"1.168209732","rc":[{"batb":[[2,3.6,15.96]],"batl":[[0,4.2,12.6]],"ltp":4.6,"tv":27.64,"id":12986367},{"batb":[[2,4.1,13.44]],"batl":[[0,4.8,10.92]],"ltp":5.2,"tv":4.36,"id":18318124},{"batb":[[2,1.84,49.57]],"batl":[[0,2.04,40.33]],"ltp":1.78,"tv":33.44,"id":18318122}]}]}
{"op":"mcm","clk":"1004870975","pt":1580638569757,"mc":[{"id":"1.168209732","rc":[{"batb":[[0,3.7,32.39],[1,3.6,15.96],[2,1.01,0.51]],"ltp":4.6,"tv":27.64,"id":12986367},{"batb":[[0,1.84,49.57],[1,1.01,0.51],[2,1.84,0]],"ltp":1.78,"tv":33.44,"id":18318122}]}]}
{"op":"mcm","clk":"1004871203","pt":1580638572878,"mc":[{"id":"1.168209732","rc":[{"batb":[[0,3.75,29.05],[1,3.7,32.39],[2,3.6,15.96]],"ltp":4.6,"tv":27.64,"id":12986367},{"batb":[[0,1.86,95.66],[1,1.84,138.85],[2,1.01,0.51]],"ltp":1.78,"tv":33.44,"id":18318122}]}]}
{"op":"mcm","clk":"1004871524","pt":1580638576787,"mc":[{"id":"1.168209732","rc":[{"batl":[[0,2.02,187.97],[1,2.04,40.33]],"ltp":1.78,"tv":33.44,"id":18318122}]}]}
{"op":"mcm","clk":"1004872019","pt":1580638583877,"mc":[{"id":"1.168209732","rc":[{"batb":[[0,3.7,32.39],[1,3.6,15.96],[2,1.01,0.51]],"ltp":4.6,"tv":27.64,"id":12986367},{"batb":[[0,4.4,45.38],[1,4.1,13.44],[2,1.01,0.51]],"ltp":5.2,"tv":4.36,"id":18318124},{"batb":[[0,1.01,0.51],[1,1.84,0],[2,1.01,0]],"ltp":1.78,"tv":33.44,"id":18318122}]}]}
{"op":"mcm","clk":"1004872079","pt":1580638584874,"mc":[{"id":"1.168209732","rc":[{"batb":[[1,1.01,0.51],[2,1.01,0]],"ltp":4.6,"tv":27.64,"id":12986367},{"batl":[[0,1.84,150],[1,2.04,0]],"ltp":1.78,"tv":33.44,"id":18318122}]}]}
{"op":"mcm","clk":"1004872213","pt":1580638586877,"mc":[{"id":"1.168209732","rc":[{"batb":[[1,3.65,33.15],[2,1.01,0.51]],"ltp":4.6,"tv":27.64,"id":12986367},{"trd":[[1.84,300]],"batb":[[0,1.85,48.73],[1,1.01,0.51]],"ltp":1.84,"tv":333.44,"id":18318122}],"tv":846.8}]}
{"op":"mcm","clk":"1004872276","pt":1580638587773,"mc":[{"id":"1.168209732","rc":[{"batb":[[1,3.65,48.27]],"ltp":4.6,"tv":27.64,"id":12986367},{"batb":[[0,1.01,0.51],[1,1.01,0]],"batl":[[0,2,42.01]],"ltp":1.84,"tv":333.44,"id":18318122}]}]}
{"op":"mcm","clk":"1004872302","pt":1580638588190,"mc":[{"id":"1.168209732","rc":[{"batb":[[1,3.65,33.15]],"ltp":4.6,"tv":27.64,"id":12986367}]}]}
{"op":"mcm","clk":"1004872385","pt":1580638589386,"mc":[{"id":"1.168209732","rc":[{"batb":[[0,4.4,45.41]],"ltp":5.2,"tv":4.36,"id":18318124}]}]}
{"op":"mcm","clk":"1004872522","pt":1580638590936,"mc":[{"id":"1.168209732","rc":[{"batb":[[0,3.7,50.91],[2,3.6,15.96]],"ltp":4.6,"tv":27.64,"id":12986367},{"batb":[[0,4.5,30.13],[1,4.4,45.41],[2,4.1,13.44]],"ltp":5.2,"tv":4.36,"id":18318124},{"batb":[[0,1.86,90.99],[1,1.85,48.73],[2,1.84,89.28]],"batl":[[0,2.04,40.33]],"ltp":1.84,"tv":333.44,"id":18318122}]}]}
{"op":"mcm","clk":"1004872738","pt":1580638593595,"mc":[{"id":"1.168209732","rc":[{"batl":[[0,2.02,187.97],[1,2.04,40.33]],"ltp":1.84,"tv":333.44,"id":18318122}]}]}
{"op":"mcm","clk":"1004873509","pt":1580638602834,"mc":[{"id":"1.168209732","rc":[{"batb":[[0,3.6,15.96],[1,1.01,0.51],[2,3.6,0]],"ltp":4.6,"tv":27.64,"id":12986367},{"batb":[[0,4.1,13.44],[1,1.01,0.51],[2,4.1,0]],"ltp":5.2,"tv":4.36,"id":18318124},{"batb":[[0,1.85,48.73],[1,1.01,0.51],[2,1.84,0]],"ltp":1.84,"tv":333.44,"id":18318122}]}]}
{"op":"mcm","clk":"1004873533","pt":1580638602990,"mc":[{"id":"1.168209732","rc":[{"batl":[[0,2.04,40.33],[1,2.04,0]],"ltp":1.84,"tv":333.44,"id":18318122}]}]}
{"op":"mcm","clk":"1004873727","pt":1580638605833,"mc":[{"id":"1.168209732","rc":[{"batb":[[1,3.3,66.29],[2,3.25,44.11]],"ltp":4.6,"tv":27.64,"id":12986367},{"batb":[[1,4,75.96],[2,3.95,29.16]],"ltp":5.2,"tv":4.36,"id":18318124},{"batb":[[1,1.78,86.85],[2,1.76,103.12]],"ltp":1.84,"tv":333.44,"id":18318122}]}]}
{"op":"mcm","clk":"1004875017","pt":1580638622043,"mc":[{"id":"1.168209732","rc":[{"batb":[[0,3.3,66.29],[1,3.25,44.11],[2,1.01,0.51]],"ltp":4.6,"tv":27.64,"id":12986367},{"batb":[[0,4,75.96],[1,3.95,29.16],[2,1.01,0.51]],"ltp":5.2,"tv":4.36,"id":18318124},{"batb":[[0,1.78,86.85],[1,1.76,103.12],[2,1.01,0.51]],"ltp":1.84,"tv":333.44,"id":18318122}]}]}
{"op":"mcm","clk":"1004875858","pt":1580638632133,"mc":[{"id":"1.168209732","rc":[{"batb":[[0,1.01,0.51],[1,3.25,0],[2,1.01,0]],"ltp":4.6,"tv":27.64,"id":12986367},{"batb":[[0,1.01,0.51],[1,3.95,0],[2,1.01,0]],"ltp":5.2,"tv":4.36,"id":18318124},{"batb":[[0,1.01,0.51],[1,1.76,0],[2,1.01,0]],"ltp":1.84,"tv":333.44,"id":18318122}]}]}
{"op":"mcm","clk":"1004876138","pt":1580638635558,"mc":[{"id":"1.168209732","rc":[{"batb":[[0,3.6,62.65],[1,3.55,35.4],[2,1.01,0.51]],"ltp":4.6,"tv":27.64,"id":12986367},{"batb":[[0,4.4,34.37],[1,4.3,47.82],[2,1.01,0.51]],"ltp":5.2,"tv":4.36,"id":18318124},{"batb":[[0,1.9,80.64],[1,1.88,83.39],[2,1.01,0.51]],"ltp":1.84,"tv":333.44,"id":18318122}]}]}
{"op":"mcm","clk":"1004876413","pt":1580638638953,"mc":[{"id":"1.168209732","rc":[{"batb":[[0,1.01,0.51],[1,3.55,0],[2,1.01,0]],"ltp":4.6,"tv":27.64,"id":12986367},{"batb":[[0,1.01,0.51],[1,4.3,0],[2,1.01,0]],"ltp":5.2,"tv":4.36,"id":18318124},{"batb":[[0,1.01,0.51],[1,1.88,0],[2,1.01,0]],"ltp":1.84,"tv":333.44,"id":18318122}]}]}
{"op":"mcm","clk":"1004876597","pt":1580638641667,"mc":[{"id":"1.168209732","rc":[{"batb":[[0,3.3,66.29],[1,3.25,44.11],[2,1.01,0.51]],"ltp":4.6,"tv":27.64,"id":12986367},{"batb":[[0,4,75.96],[1,3.95,29.16],[2,1.01,0.51]],"ltp":5.2,"tv":4.36,"id":18318124},{"batb":[[0,1.78,86.85],[1,1.76,103.12],[2,1.01,0.51]],"ltp":1.84,"tv":333.44,"id":18318122}]}]}
{"op":"mcm","clk":"1004876805","pt":1580638644266,"mc":[{"id":"1.168209732","rc":[{"batb":[[0,1.01,0.51],[1,1.76,0],[2,1.01,0]],"ltp":1.84,"tv":333.44,"id":18318122}]}]}
{"op":"mcm","clk":"1004877071","pt":1580638647656,"mc":[{"id":"1.168209732","rc":[{"batb":[[0,2.06,104.27],[1,2.04,65.02],[2,1.01,0.51]],"ltp":1.84,"tv":333.44,"id":18318122}]}]}
{"op":"mcm","clk":"1004877153","pt":1580638649003,"mc":[{"id":"1.168209732","rc":[{"batb":[[0,3.3,83.93]],"batl":[[0,3.8,14.28]],"ltp":4.6,"tv":27.64,"id":12986367},{"batb":[[2,3.75,15.12]],"batl":[[0,4.4,11.76]],"ltp":5.2,"tv":4.36,"id":18318124},{"batb":[[2,2.02,41.17]],"batl":[[0,2.26,32.77]],"ltp":1.84,"tv":333.44,"id":18318122}]}]}
{"op":"mcm","clk":"1004878716","pt":1580638671501,"mc":[{"id":"1.168209732","rc":[{"batb":[[0,3.3,17.64],[1,1.01,0.51],[2,1.01,0]],"ltp":4.6,"tv":27.64,"id":12986367},{"batb":[[0,3.75,15.12],[1,1.01,0.51],[2,3.75,0]],"ltp":5.2,"tv":4.36,"id":18318124},{"batb":[[0,2.02,41.17],[1,1.01,0.51],[2,2.02,0]],"ltp":1.84,"tv":333.44,"id":18318122}]}]}
{"op":"mcm","clk":"1004878763","pt":1580638672119,"mc":[{"id":"1.168209732","rc":[{"batb":[[0,1.01,0.51],[1,1.01,0]],"ltp":4.6,"tv":27.64,"id":12986367},{"batb":[[0,1.01,0.51],[1,1.01,0]],"ltp":5.2,"tv":4.36,"id":18318124},{"batb":[[0,1.01,0.51],[1,1.01,0]],"ltp":1.84,"tv":333.44,"id":18318122}]}]}
{"op":"mcm","clk":"1004878927","pt":1580638674418,"mc":[{"id":"1.168209732","rc":[{"batb":[[0,2.9,36.87],[1,2.86,49.52],[2,1.01,0.51]],"ltp":4.6,"tv":27.64,"id":12986367},{"batb":[[0,3.55,34.33],[1,3.5,39.38],[2,1.01,0.51]],"ltp":5.2,"tv":4.36,"id":18318124},{"batb":[[0,1.92,62.98],[1,1.9,80.65],[2,1.01,0.51]],"ltp":1.84,"tv":333.44,"id":18318122}]}]}
{"op":"mcm","clk":"1004879193","pt":1580638678512,"mc":[{"id":"1.168209732","rc":[{"batb":[[0,1.01,0.51],[1,2.86,0],[2,1.01,0]],"ltp":4.6,"tv":27.64,"id":12986367},{"batb":[[0,1.01,0.51],[1,3.5,0],[2,1.01,0]],"ltp":5.2,"tv":4.36,"id":18318124}]}]}
{"op":"mcm","clk":"1004879488","pt":1580638681911,"mc":[{"id":"1.168209732","rc":[{"batb":[[0,3.6,34.77],[1,3.55,35.7],[2,1.01,0.51]],"ltp":4.6,"tv":27.64,"id":12986367},{"batb":[[0,4.3,70.81],[1,4.2,49.85],[2,1.01,0.51]],"ltp":5.2,"tv":4.36,"id":18318124}]}]}
{"op":"mcm","clk":"1004879586","pt":1580638682908,"mc":[{"id":"1.168209732","rc":[{"batb":[[2,3.5,16.8]],"batl":[[0,4.1,13.44]],"ltp":4.6,"tv":27.64,"id":12986367},{"batb":[[2,3.95,13.44]],"batl":[[0,4.7,10.92]],"ltp":5.2,"tv":4.36,"id":18318124},{"batb":[[1,1.91,45.37],[2,1.9,80.65]],"batl":[[0,2.1,37.81]],"ltp":1.84,"tv":333.44,"id":18318122}]}]}
{"op":"mcm","clk":"1004880319","pt":1580638691939,"mc":[{"id":"1.168209732","rc":[{"batb":[[0,3.5,16.8],[1,1.01,0.51],[2,3.5,0]],"ltp":4.6,"tv":27.64,"id":12986367},{"batb":[[0,3.95,13.44],[1,1.01,0.51],[2,3.95,0]],"ltp":5.2,"tv":4.36,"id":18318124},{"batb":[[0,1.91,45.37],[1,1.01,0.51],[2,1.9,0]],"ltp":1.84,"tv":333.44,"id":18318122}]}]}
{"op":"mcm","clk":"1004880323","pt":1580638692042,"mc":[{"id":"1.168209732","rc":[{"batb":[[0,1.01,0.51],[1,1.01,0]],"ltp":4.6,"tv":27.64,"id":12986367},{"batb":[[0,1.01,0.51],[1,1.01,0]],"ltp":5.2,"tv":4.36,"id":18318124},{"batb":[[0,1.01,0.51],[1,1.01,0]],"ltp":1.84,"tv":333.44,"id":18318122}]}]}
{"op":"mcm","clk":"1004880588","pt":1580638694925,"mc":[{"id":"1.168209732","rc":[{"batb":[[0,1.8,101.73],[1,1.78,99.38],[2,1.01,0.51]],"ltp":1.84,"tv":333.44,"id":18318122}]}]}
{"op":"mcm","clk":"1004880818","pt":1580638697742,"mc":[{"id":"1.168209732","rc":[{"batb":[[0,3.85,38.67],[1,3.8,30.19],[2,1.01,0.51]],"ltp":4.6,"tv":27.64,"id":12986367},{"batb":[[0,4.6,62.46],[1,4.5,42.55],[2,1.01,0.51]],"ltp":5.2,"tv":4.36,"id":18318124}]}]}
{"op":"mcm","clk":"1004880911","pt":1580638698952,"mc":[{"id":"1.168209732","rc":[{"batb":[[2,3.7,15.12]],"batl":[[0,4.4,11.76]],"ltp":4.6,"tv":27.64,"id":12986367},{"batb":[[2,4.2,12.6]],"batl":[[0,5,10.08]],"ltp":5.2,"tv":4.36,"id":18318124},{"batb":[[0,1.8,153.82]],"batl":[[0,1.97,42.01]],"ltp":1.84,"tv":333.44,"id":18318122}]}]}
{"op":"mcm","clk":"1004881239","pt":1580638702562,"mc":[{"id":"1.168209732","rc":[{"batb":[[0,1.8,52.09],[1,1.01,0.51],[2,1.01,0]],"ltp":1.84,"tv":333.44,"id":18318122}]}]}
{"op":"mcm","clk":"1004881497","pt":1580638705536,"mc":[{"id":"1.168209732","rc":[{"batb":[[0,1.81,69.14],[1,1.8,52.09],[2,1.79,97.44]],"ltp":1.84,"tv":333.44,"id":18318122}]}]}
{"op":"mcm","clk":"1004881807","pt":1580638708931,"mc":[{"id":"1.168209732","rc":[{"batb":[[0,3.7,15.12],[1,1.01,0.51],[2,3.7,0]],"ltp":4.6,"tv":27.64,"id":12986367},{"batb":[[0,4.2,12.6],[1,1.01,0.51],[2,4.2,0]],"ltp":5.2,"tv":4.36,"id":18318124},{"batb":[[0,1.8,52.09],[1,1.01,0.51],[2,1.79,0]],"ltp":1.84,"tv":333.44,"id":18318122}]}]}
{"op":"mcm","clk":"1004881933","pt":1580638710371,"mc":[{"id":"1.168209732","rc":[{"batb":[[0,1.01,0.51],[1,1.01,0]],"ltp":4.6,"tv":27.64,"id":12986367},{"batb":[[0,1.01,0.51],[1,1.01,0]],"ltp":5.2,"tv":4.36,"id":18318124},{"batb":[[0,1.01,0.51],[1,1.01,0]],"ltp":1.84,"tv":333.44,"id":18318122}]}]}
{"op":"mcm","clk":"1004882056","pt":1580638711642,"mc":[{"id":"1.168209732","rc":[{"batb":[[0,3.45,43.19],[1,3.4,39.56],[2,1.01,0.51]],"ltp":4.6,"tv":27.64,"id":12986367},{"batb":[[0,4.2,58.83],[1,4.1,52.88],[2,1.01,0.51]],"ltp":5.2,"tv":4.36,"id":18318124},{"batb":[[0,1.74,63.57],[1,1.72,111.17],[2,1.01,0.51]],"ltp":1.84,"tv":333.44,"id":18318122}]}]}
{"op":"mcm","clk":"1004882142","pt":1580638712673,"mc":[{"id":"1.168209732","rc":[{"batb":[[0,1.01,0.51],[1,3.4,0],[2,1.01,0]],"ltp":4.6,"tv":27.64,"id":12986367},{"batb":[[0,1.01,0.51],[1,4.1,0],[2,1.01,0]],"ltp":5.2,"tv":4.36,"id":18318124},{"batb":[[0,1.01,0.51],[1,1.72,0],[2,1.01,0]],"ltp":1.84,"tv":333.44,"id":18318122}]}]}
{"op":"mcm","clk":"1004882381","pt":1580638715955,"mc":[{"id":"1.168209732","rc":[{"batb":[[0,3.75,43.41],[1,3.7,32.12],[2,1.01,0.51]],"ltp":4.6,"tv":27.64,"id":12986367},{"batb":[[0,4.5,64.66],[1,4.4,44.72],[2,1.01,0.51]],"ltp":5.2,"tv":4.36,"id":18318124},{"batb":[[0,1.84,80.92],[1,1.82,92.37],[2,1.01,0.51]],"ltp":1.84,"tv":333.44,"id":18318122}]}]}
{"op":"mcm","clk":"1004882626","pt":1580638718951,"mc":[{"id":"1.168209732","rc":[{"batb":[[0,1.01,0.51],[1,3.7,0],[2,1.01,0]],"ltp":4.6,"tv":27.64,"id":12986367},{"batb":[[0,1.01,0.51],[1,4.4,0],[2,1.01,0]],"ltp":5.2,"tv":4.36,"id":18318124},{"batb":[[0,1.01,0.51],[1,1.82,0],[2,1.01,0]],"ltp":1.84,"tv":333.44,"id":18318122}]}]}
{"op":"mcm","clk":"1004882833","pt":1580638721582,"mc":[{"id":"1.168209732","rc":[{"batb":[[0,3.45,43.96],[1,3.4,39.57],[2,1.01,0.51]],"ltp":4.6,"tv":27.64,"id":12986367},{"batb":[[0,4.2,58.6],[1,4.1,52.88],[2,1.01,0.51]],"ltp":5.2,"tv":4.36,"id":18318124},{"batb":[[0,1.74,62.71],[1,1.72,111.17],[2,1.01,0.51]],"ltp":1.84,"tv":333.44,"id":18318122}]}]}
{"op":"mcm","clk":"1004883075","pt":1580638724776,"mc":[{"id":"1.168209732","rc":[{"batb":[[0,1.01,0.51],[1,3.4,0],[2,1.01,0]],"ltp":4.6,"tv":27.64,"id":12986367},{"batb":[[0,1.01,0.51],[1,4.1,0],[2,1.01,0]],"ltp":5.2,"tv":4.36,"id":18318124}]}]}
{"op":"mcm","clk":"1004883296","pt":1580638727457,"mc":[{"id":"1.168209732","rc":[{"batb":[[0,4,66.15],[1,3.95,27.18],[2,1.01,0.51]],"ltp":4.6,"tv":27.64,"id":12986367},{"batb":[[0,4.9,24.91],[1,4.8,37.17],[2,1.01,0.51]],"ltp":5.2,"tv":4.36,"id":18318124}]}]}
{"op":"mcm","clk":"1004883460","pt":1580638729887,"mc":[{"id":"1.168209732","rc":[{"batb":[[2,3.9,14.28]],"batl":[[0,4.6,10.92]],"ltp":4.6,"tv":27.64,"id":12986367},{"batb":[[2,4.4,11.76]],"batl":[[0,5.3,9.24]],"ltp":5.2,"tv":4.36,"id":18318124},{"batb":[[1,1.72,169.14]],"batl":[[0,1.88,42.01]],"ltp":1.84,"tv":333.44,"id":18318122}]}]}
{"op":"mcm","clk":"1004884484","pt":1580638742810,"mc":[{"id":"1.168209732","rc":[{"batb":[[0,3.9,14.28],[1,1.01,0.51],[2,3.9,0]],"ltp":4.6,"tv":27.64,"id":12986367},{"batb":[[0,4.4,11.76],[1,1.01,0.51],[2,4.4,0]],"ltp":5.2,"tv":4.36,"id":18318124},{"batb":[[0,1.72,57.97],[1,1.01,0.51],[2,1.01,0]],"ltp":1.84,"tv":333.44,"id":18318122}]}]}
{"op":"mcm","clk":"1004884584","pt":1580638744093,"mc":[{"id":"1.168209732","rc":[{"batb":[[0,1.01,0.51],[1,1.01,0]],"ltp":4.6,"tv":27.64,"id":12986367},{"batb":[[0,1.01,0.51],[1,1.01,0]],"ltp":5.2,"tv":4.36,"id":18318124},{"batb":[[0,1.01,0.51],[1,1.01,0]],"ltp":1.84,"tv":333.44,"id":18318122}]}]}
{"op":"mcm","clk":"1004884710","pt":1580638745919,"mc":[{"id":"1.168209732","rc":[{"batb":[[0,3.8,36.51],[1,3.75,31.13],[2,1.01,0.51]],"ltp":4.6,"tv":27.64,"id":12986367},{"batb":[[0,4.7,23.24],[1,4.6,40.99],[2,1.01,0.51]],"ltp":5.2,"tv":4.36,"id":18318124},{"batb":[[0,1.7,103.07],[1,1.68,120.95],[2,1.01,0.51]],"ltp":1.84,"tv":333.44,"id":18318122}]}]}
{"op":"mcm","clk":"1004884793","pt":1580638746914,"mc":[{"id":"1.168209732","rc":[{"batb":[[0,1.01,0.51],[1,3.75,0],[2,1.01,0]],"ltp":4.6,"tv":27.64,"id":12986367},{"batb":[[0,1.01,0.51],[1,4.6,0],[2,1.01,0]],"ltp":5.2,"tv":4.36,"id":18318124}]}]}
{"op":"mcm","clk":"1004885015","pt":1580638749793,"mc":[{"id":"1.168209732","rc":[{"batb":[[0,4.2,26.83],[1,4.1,49.79],[2,1.01,0.51]],"ltp":4.6,"tv":27.64,"id":12986367},{"batb":[[0,5,24.24],[1,4.9,35.47],[2,1.01,0.51]],"ltp":5.2,"tv":4.36,"id":18318124}]}]}
{"op":"mcm","clk":"1004885157","pt":1580638751611,"mc":[{"id":"1.168209732","rc":[{"batb":[[1,4.1,63.23]],"batl":[[0,4.9,10.08]],"ltp":4.6,"tv":27.64,"id":12986367},{"batb":[[2,4.5,11.76]],"batl":[[0,5.4,9.24]],"ltp":5.2,"tv":4.36,"id":18318124},{"batb":[[1,1.68,182.28]],"batl":[[0,1.83,42.01]],"ltp":1.84,"tv":333.44,"id":18318122}]}]}
{"op":"mcm","clk":"1004886476","pt":1580638767408,"mc":[{"id":"1.168209732","rc":[{"batl":[[0,4.8,10.92]],"ltp":4.6,"tv":27.64,"id":12986367}]}]}
{"op":"mcm","clk":"1004887379","pt":1580638777823,"mc":[{"id":"1.168209732","rc":[{"batb":[[0,4.1,13.44],[1,1.01,0.51],[2,1.01,0]],"ltp":4.6,"tv":27.64,"id":12986367},{"batb":[[0,4.5,11.76],[1,1.01,0.51],[2,4.5,0]],"ltp":5.2,"tv":4.36,"id":18318124},{"batb":[[0,1.68,61.33],[1,1.01,0.51],[2,1.01,0]],"ltp":1.84,"tv":333.44,"id":18318122}]}]}
{"op":"mcm","clk":"1004887419","pt":1580638778344,"mc":[{"id":"1.168209732","rc":[{"batb":[[0,1.01,0.51],[1,1.01,0]],"ltp":4.6,"tv":27.64,"id":12986367},{"batb":[[0,1.01,0.51],[1,1.01,0]],"ltp":5.2,"tv":4.36,"id":18318124},{"batb":[[0,1.01,0.51],[1,1.01,0]],"ltp":1.84,"tv":333.44,"id":18318122}]}]}
{"op":"mcm","clk":"1004887638","pt":1580638780230,"mc":[{"id":"1.168209732","rc":[{"batb":[[0,3.9,39.7],[1,3.85,29.16],[2,1.01,0.51]],"ltp":4.6,"tv":27.64,"id":12986367},{"batb":[[0,4.6,59.85],[1,4.5,42.44],[2,1.01,0.51]],"ltp":5.2,"tv":4.36,"id":18318124},{"batb":[[0,1.56,74.22],[1,1.55,81.34],[2,1.01,0.51]],"ltp":1.84,"tv":333.44,"id":18318122}]}]}
{"op":"mcm","clk":"1004888056","pt":1580638785772,"mc":[{"id":"1.168209732","rc":[{"batb":[[0,1.01,0.51],[1,1.55,0],[2,1.01,0]],"ltp":1.84,"tv":333.44,"id":18318122}]}]}
{"op":"mcm","clk":"1004888315","pt":1580638788756,"mc":[{"id":"1.168209732","rc":[{"batb":[[0,1.79,101.16],[1,1.77,101.1],[2,1.01,0.51]],"ltp":1.84,"tv":333.44,"id":18318122}]}]}
{"op":"mcm","clk":"1004888386","pt":1580638789538,"mc":[{"id":"1.168209732","rc":[{"batb":[[0,3.9,53.98]],"batl":[[0,4.6,10.92]],"ltp":4.6,"tv":27.64,"id":12986367},{"batb":[[2,4.2,12.6]],"batl":[[0,5,10.08]],"ltp":5.2,"tv":4.36,"id":18318124},{"batb":[[2,1.76,54.61]],"batl":[[0,1.94,42.01]],"ltp":1.84,"tv":333.44,"id":18318122}]}]}
{"op":"mcm","clk":"1004889881","pt":1580638808861,"mc":[{"id":"1.168209732","rc":[{"batb":[[0,3.9,14.28],[1,1.01,0.51],[2,1.01,0]],"ltp":4.6,"tv":27.64,"id":12986367},{"batb":[[0,4.2,12.6],[1,1.01,0.51],[2,4.2,0]],"ltp":5.2,"tv":4.36,"id":18318124},{"batb":[[0,1.76,54.61],[1,1.01,0.51],[2,1.76,0]],"ltp":1.84,"tv":333.44,"id":18318122}]}]}
{"op":"mcm","clk":"1004889979","pt":1580638810167,"mc":[{"id":"1.168209732","rc":[{"batb":[[0,1.01,0.51],[1,1.01,0]],"ltp":4.6,"tv":27.64,"id":12986367},{"batb":[[0,1.01,0.51],[1,1.01,0]],"ltp":5.2,"tv":4.36,"id":18318124},{"batb":[[0,1.01,0.51],[1,1.01,0]],"ltp":1.84,"tv":333.44,"id":18318122}]}]}
{"op":"mcm","clk":"1004890093","pt":1580638811569,"mc":[{"id":"1.168209732","rc":[{"batb":[[0,3.7,44.78],[1,3.65,33.11],[2,1.01,0.51]],"batl":[[0,4.5,11.76]],"ltp":4.6,"tv":27.64,"id":12986367},{"batb":[[0,4.4,60.91],[1,4.3,47.11],[2,1.01,0.51]],"ltp":5.2,"tv":4.36,"id":18318124},{"batb":[[0,1.67,64.17],[1,1.66,63.21],[2,1.01,0.51]],"ltp":1.84,"tv":333.44,"id":18318122}]}]}
{"op":"mcm","clk":"1004890256","pt":1580638813497,"mc":[{"id":"1.168209732","rc":[{"batb":[[0,1.01,0.51],[1,3.65,0],[2,1.01,0]],"ltp":4.6,"tv":27.64,"id":12986367},{"batb":[[0,1.01,0.51],[1,4.3,0],[2,1.01,0]],"ltp":5.2,"tv":4.36,"id":18318124},{"batb":[[0,1.01,0.51],[1,1.66,0],[2,1.01,0]],"ltp":1.84,"tv":333.44,"id":18318122}]}]}
{"op":"mcm","clk":"1004890504","pt":1580638816487,"mc":[{"id":"1.168209732","rc":[{"batb":[[0,4,27.05],[1,3.95,27.54],[2,1.01,0.51]],"ltp":4.6,"tv":27.64,"id":12986367},{"batb":[[0,4.7,51.13],[1,4.6,40.49],[2,1.01,0.51]],"ltp":5.2,"tv":4.36,"id":18318124},{"batb":[[0,1.77,66.88],[1,1.75,104.88],[2,1.01,0.51]],"ltp":1.84,"tv":333.44,"id":18318122}]}]}
{"op":"mcm","clk":"1004890820","pt":1580638820814,"mc":[{"id":"1.168209732","rc":[{"batb":[[0,1.01,0.51],[1,3.95,0],[2,1.01,0]],"ltp":4.6,"tv":27.64,"id":12986367},{"batb":[[0,1.01,0.51],[1,4.6,0],[2,1.01,0]],"ltp":5.2,"tv":4.36,"id":18318124},{"batb":[[0,1.01,0.51],[1,1.75,0],[2,1.01,0]],"ltp":1.84,"tv":333.44,"id":18318122}]}]}
{"op":"mcm","clk":"1004891007","pt":1580638823415,"mc":[{"id":"1.168209732","rc":[{"batb":[[0,3.7,44.78],[1,3.65,33.11],[2,1.01,0.51]],"ltp":4.6,"tv":27.64,"id":12986367},{"batb":[[0,4.4,60.91],[1,4.3,47.11],[2,1.01,0.51]],"ltp":5.2,"tv":4.36,"id":18318124},{"batb":[[0,1.67,64.17],[1,1.66,63.21],[2,1.01,0.51]],"ltp":1.84,"tv":333.44,"id":18318122}]}]}
{"op":"mcm","clk":"1004891265","pt":1580638826913,"mc":[{"id":"1.168209732","rc":[{"batb":[[0,1.01,0.51],[1,3.65,0],[2,1.01,0]],"ltp":4.6,"tv":27.64,"id":12986367},{"batb":[[0,1.01,0.51],[1,4.3,0],[2,1.01,0]],"ltp":5.2,"tv":4.36,"id":18318124}]}]}
{"op":"mcm","clk":"1004891520","pt":1580638829887,"mc":[{"id":"1.168209732","rc":[{"batb":[[0,4.3,49.12],[1,4.2,46.66],[2,1.01,0.51]],"ltp":4.6,"tv":27.64,"id":12986367},{"batb":[[0,5.1,33.67],[1,5,33.75],[2,1.01,0.51]],"ltp":5.2,"tv":4.36,"id":18318124}]}]}
{"op":"mcm","clk":"1004891694","pt":1580638831721,"mc":[{"id":"1.168209732","rc":[{"batb":[[1,4.2,59.26]],"batl":[[0,5,10.08]],"ltp":4.6,"tv":27.64,"id":12986367},{"batb":[[2,4.6,10.92]],"batl":[[0,5.5,9.24]],"ltp":5.2,"tv":4.36,"id":18318124},{"batb":[[2,1.65,63.85]],"batl":[[0,1.8,42.01]],"ltp":1.84,"tv":333.44,"id":18318122}]}]}
{"op":"mcm","clk":"1004892669","pt":1580638842841,"mc":[{"id":"1.168209732","rc":[{"batb":[[0,4.2,12.6],[1,1.01,0.51],[2,1.01,0]],"ltp":4.6,"tv":27.64,"id":12986367},{"batb":[[0,4.6,10.92],[1,1.01,0.51],[2,4.6,0]],"ltp":5.2,"tv":4.36,"id":18318124},{"batb":[[0,1.65,63.85],[1,1.01,0.51],[2,1.65,0]],"ltp":1.84,"tv":333.44,"id":18318122}]}]}
{"op":"mcm","clk":"1004892772","pt":1580638844221,"mc":[{"id":"1.168209732","rc":[{"batb":[[0,1.01,0.51],[1,1.01,0]],"ltp":4.6,"tv":27.64,"id":12986367},{"batb":[[0,1.01,0.51],[1,1.01,0]],"ltp":5.2,"tv":4.36,"id":18318124},{"batb":[[0,1.01,0.51],[1,1.01,0]],"ltp":1.84,"tv":333.44,"id":18318122}]}]}
{"op":"mcm","clk":"1004892872","pt":1580638845423,"mc":[{"id":"1.168209732","rc":[{"batb":[[0,3.95,46.48],[1,3.9,28.21],[2,1.01,0.51]],"ltp":4.6,"tv":27.64,"id":12986367},{"batb":[[0,4.7,28.35],[1,4.6,40.85],[2,1.01,0.51]],"ltp":5.2,"tv":4.36,"id":18318124},{"batb":[[0,1.49,159.62],[1,1.48,98.28],[2,1.01,0.51]],"ltp":1.84,"tv":333.44,"id":18318122}]}]}
{"op":"mcm","clk":"1004893078","pt":1580638847919,"mc":[{"id":"1.168209732","rc":[{"batb":[[0,1.01,0.51],[1,3.9,0],[2,1.01,0]],"ltp":4.6,"tv":27.64,"id":12986367},{"batb":[[0,1.01,0.51],[1,4.6,0],[2,1.01,0]],"ltp":5.2,"tv":4.36,"id":18318124}]}]}
{"op":"mcm","clk":"1004893347","pt":1580638850634,"mc":[{"id":"1.168209732","rc":[{"batb":[[0,5.2,31.22],[1,5.1,30.02],[2,1.01,0.51]],"ltp":4.6,"tv":27.64,"id":12986367},{"batb":[[0,6,50.82],[1,5.9,23.08],[2,1.01,0.51]],"ltp":5.2,"tv":4.36,"id":18318124}]}]}
{"op":"mcm","clk":"1004893434","pt":1580638851624,"mc":[{"id":"1.168209732","rc":[{"batb":[[2,4.9,10.08]],"batl":[[0,5.9,8.4]],"ltp":4.6,"tv":27.64,"id":12986367},{"batb":[[2,5.3,9.24]],"batl":[[0,6.6,6.72]],"ltp":5.2,"tv":4.36,"id":18318124},{"batb":[[0,1.5,84.02],[1,1.49,159.62],[2,1.48,98.28]],"batl":[[0,1.61,42.01]],"ltp":1.84,"tv":333.44,"id":18318122}]}]}
{"op":"mcm","clk":"1004893737","pt":1580638855158,"mc":[{"id":"1.168209732","rc":[{"batb":[[1,4.9,10.08],[2,1.01,0.51]],"ltp":4.6,"tv":27.64,"id":12986367},{"batb":[[1,1.49,114]],"ltp":1.84,"tv":333.44,"id":18318122}]}]}
{"op":"mcm","clk":"1004894061","pt":1580638858930,"mc":[{"id":"1.168209732","rc":[{"batb":[[0,5.3,25.06],[1,5.2,31.22],[2,4.9,10.08]],"ltp":4.6,"tv":27.64,"id":12986367},{"batl":[[0,1.6,78.76],[1,1.61,42.01]],"ltp":1.84,"tv":333.44,"id":18318122}]}]}
{"op":"mcm","clk":"1004894763","pt":1580638866860,"mc":[{"id":"1.168209732","rc":[{"batb":[[0,4.9,10.08],[1,1.01,0.51],[2,4.9,0]],"ltp":4.6,"tv":27.64,"id":12986367},{"batb":[[0,5.3,9.24],[1,1.01,0.51],[2,5.3,0]],"ltp":5.2,"tv":4.36,"id":18318124},{"batb":[[1,1.01,0.51],[2,1.48,0]],"batl":[[0,1.61,42.01],[1,1.61,0]],"ltp":1.84,"tv":333.44,"id":18318122}]}]}
{"op":"mcm","clk":"1004894923","pt":1580638868735,"mc":[{"id":"1.168209732","rc":[{"batb":[[0,1.01,0.51],[1,1.01,0]],"ltp":4.6,"tv":27.64,"id":12986367},{"batb":[[0,1.01,0.51],[1,1.01,0]],"ltp":5.2,"tv":4.36,"id":18318124},{"batb":[[0,1.01,0.51],[1,1.01,0]],"ltp":1.84,"tv":333.44,"id":18318122}]}]}
{"op":"mcm","clk":"1004894988","pt":1580638869772,"mc":[{"id":"1.168209732","rc":[{"batb":[[0,4.5,56.41],[1,4.4,42.22],[2,1.01,0.51]],"ltp":4.6,"tv":27.64,"id":12986367},{"batb":[[0,5.2,39.96],[1,5.1,32.12],[2,1.01,0.51]],"ltp":5.2,"tv":4.36,"id":18318124},{"batb":[[0,1.3,185.16],[1,1.29,188.64],[2,1.01,0.51]],"ltp":1.84,"tv":333.44,"id":18318122}]}]}
{"op":"mcm","clk":"1004895074","pt":1580638870868,"mc":[{"id":"1.168209732","rc":[{"batb":[[0,1.01,0.51],[1,1.29,0],[2,1.01,0]],"ltp":1.84,"tv":333.44,"id":18318122}]}]}
{"op":"mcm","clk":"1004895334","pt":1580638873866,"mc":[{"id":"1.168209732","rc":[{"batb":[[0,1.62,124.03],[1,1.61,71.02],[2,1.01,0.51]],"ltp":1.84,"tv":333.44,"id":18318122}]}]}
{"op":"mcm","clk":"1004895492","pt":1580638875585,"mc":[{"id":"1.168209732","rc":[{"batb":[[1,4.4,53.98]],"batl":[[0,5.2,9.24]],"ltp":4.6,"tv":27.64,"id":12986367},{"batb":[[2,4.7,10.92]],"batl":[[0,5.6,8.4]],"ltp":5.2,"tv":4.36,"id":18318124},{"batb":[[1,1.61,139.08]],"batl":[[0,1.76,42.01]],"ltp":1.84,"tv":333.44,"id":18318122}]}]}
{"op":"mcm","clk":"1004896815","pt":1580638891400,"mc":[{"id":"1.168209732","rc":[{"batb":[[0,4.4,11.76],[1,1.01,0.51],[2,1.01,0]],"ltp":4.6,"tv":27.64,"id":12986367},{"batb":[[0,4.7,10.92],[1,1.01,0.51],[2,4.7,0]],"ltp":5.2,"tv":4.36,"id":18318124},{"batb":[[0,1.61,68.06],[1,1.01,0.51],[2,1.01,0]],"ltp":1.84,"tv":333.44,"id":18318122}]}]}
{"op":"mcm","clk":"1004896899","pt":1580638892488,"mc":[{"id":"1.168209732","rc":[{"batb":[[0,1.01,0.51],[1,1.01,0]],"ltp":4.6,"tv":27.64,"id":12986367},{"batb":[[0,1.01,0.51],[1,1.01,0]],"ltp":5.2,"tv":4.36,"id":18318124},{"batb":[[0,1.01,0.51],[1,1.01,0]],"ltp":1.84,"tv":333.44,"id":18318122}]}]}
{"op":"mcm","clk":"1004897292","pt":1580638897376,"mc":[{"id":"1.168209732","rc":[{"batb":[[0,4.8,24.75],[1,4.7,36.74],[2,1.01,0.51]],"ltp":4.6,"tv":27.64,"id":12986367},{"batb":[[0,5.5,26.34],[1,5.4,28.44],[2,1.01,0.51]],"ltp":5.2,"tv":4.36,"id":18318124},{"batb":[[0,1.58,69.46],[1,1.57,77.74],[2,1.01,0.51]],"ltp":1.84,"tv":333.44,"id":18318122}]}]}
{"op":"mcm","clk":"1004897608","pt":1580638901799,"mc":[{"id":"1.168209732","rc":[{"batb":[[0,1.01,0.51],[1,4.7,0],[2,1.01,0]],"ltp":4.6,"tv":27.64,"id":12986367},{"batb":[[0,1.01,0.51],[1,5.4,0],[2,1.01,0]],"ltp":5.2,"tv":4.36,"id":18318124},{"batb":[[0,1.01,0.51],[1,1.57,0],[2,1.01,0]],"ltp":1.84,"tv":333.44,"id":18318122}]}]}
{"op":"mcm","clk":"1004897840","pt":1580638904698,"mc":[{"id":"1.168209732","rc":[{"batb":[[0,4,52.58],[1,3.95,27.62],[2,1.01,0.51]],"ltp":4.6,"tv":27.64,"id":12986367},{"batb":[[0,4.6,42.45],[1,4.5,42.65],[2,1.01,0.51]],"ltp":5.2,"tv":4.36,"id":18318124},{"batb":[[0,1.41,114.39],[1,1.4,124.92],[2,1.01,0.51]],"ltp":1.84,"tv":333.44,"id":18318122}]}]}
{"op":"mcm","clk":"1004898052","pt":1580638907705,"mc":[{"id":"1.168209732","rc":[{"batb":[[0,1.01,0.51],[1,1.4,0],[2,1.01,0]],"ltp":1.84,"tv":333.44,"id":18318122}]}]}
{"op":"mcm","clk":"1004898245","pt":1580638910498,"mc":[{"id":"1.168209732","rc":[{"batb":[[0,1.78,60.35],[1,1.76,103.2],[2,1.01,0.51]],"ltp":1.84,"tv":333.44,"id":18318122}]}]}
{"op":"mcm","clk":"1004898290","pt":1580638911115,"mc":[{"id":"1.168209732","rc":[{"batb":[[0,4,66.02]],"batl":[[0,4.7,10.92]],"ltp":4.6,"tv":27.64,"id":12986367},{"batb":[[2,4.2,12.6]],"batl":[[0,5,10.08]],"ltp":5.2,"tv":4.36,"id":18318124},{"batb":[[2,1.75,55.45]],"batl":[[0,1.93,42.01]],"ltp":1.84,"tv":333.44,"id":18318122}]}]}
{"op":"mcm","clk":"1004899213","pt":1580638921915,"mc":[{"id":"1.168209732","rc":[{"batb":[[0,4,13.44],[1,1.01,0.51],[2,1.01,0]],"ltp":4.6,"tv":27.64,"id":12986367},{"batb":[[0,4.2,12.6],[1,1.01,0.51],[2,4.2,0]],"ltp":5.2,"tv":4.36,"id":18318124},{"batb":[[0,1.75,55.45],[1,1.01,0.51],[2,1.75,0]],"ltp":1.84,"tv":333.44,"id":18318122}]}]}
{"op":"mcm","clk":"1004899269","pt":1580638922540,"mc":[{"id":"1.168209732","rc":[{"batb":[[0,1.01,0.51],[1,1.01,0]],"ltp":4.6,"tv":27.64,"id":12986367},{"batb":[[0,1.01,0.51],[1,1.01,0]],"ltp":5.2,"tv":4.36,"id":18318124},{"batb":[[0,1.01,0.51],[1,1.01,0]],"ltp":1.84,"tv":333.44,"id":18318122}]}]}
{"op":"mcm","clk":"1004899509","pt":1580638924904,"mc":[{"id":"1.168209732","rc":[{"batb":[[0,3.75,49.89],[1,3.7,32.35],[2,1.01,0.51]],"ltp":4.6,"tv":27.64,"id":12986367},{"batb":[[0,4.3,52.4],[1,4.2,49.82],[2,1.01,0.51]],"ltp":5.2,"tv":4.36,"id":18318124},{"batb":[[0,1.61,117.88],[1,1.6,72.64],[2,1.01,0.51]],"ltp":1.84,"tv":333.44,"id":18318122}]}]}
{"op":"mcm","clk":"1004899716","pt":1580638927516,"mc":[{"id":"1.168209732","rc":[{"batb":[[0,1.01,0.51],[1,1.6,0],[2,1.01,0]],"ltp":1.84,"tv":333.44,"id":18318122}]}]}
{"op":"mcm","clk":"1004899928","pt":1580638929911,"mc":[{"id":"1.168209732","rc":[{"batb":[[0,1.88,70.32],[1,1.86,86.25],[2,1.01,0.51]],"ltp":1.84,"tv":333.44,"id":18318122}]}]}
{"op":"mcm","clk":"1004900088","pt":1580638931623,"mc":[{"id":"1.168209732","rc":[{"batb":[[1,3.7,47.47]],"batl":[[0,4.3,12.6]],"ltp":4.6,"tv":27.64,"id":12986367},{"batb":[[2,3.95,13.44]],"batl":[[0,4.6,10.92]],"ltp":5.2,"tv":4.36,"id":18318124},{"batb":[[1,1.86,134.98]],"batl":[[0,2.06,39.49]],"ltp":1.84,"tv":333.44,"id":18318122}]}]}
{"op":"mcm","clk":"1004905270","pt":1580638991867,"mc":[{"id":"1.168209732","rc":[{"batb":[[0,3.75,31.62],[1,3.7,15.12]],"ltp":4.6,"tv":27.64,"id":12986367},{"trd":[[1.86,159.36],[1.88,140.64]],"batb":[[0,1.86,48.73],[1,1.01,0.51],[2,1.01,0]],"ltp":1.86,"tv":633.44,"id":18318122}],"tv":1146.8}]}
{"op":"mcm","clk":"1004905579","pt":1580638994662,"mc":[{"id":"1.168209732","rc":[{"batb":[[0,3.8,28.05],[1,3.75,31.62],[2,3.7,15.12]],"ltp":4.6,"tv":27.64,"id":12986367},{"batb":[[0,4.3,60.67]],"ltp":5.2,"tv":4.36,"id":18318124},{"batb":[[0,1.87,84.41],[1,1.86,48.73],[2,1.85,87.82]],"ltp":1.86,"tv":633.44,"id":18318122}]}]}
{"op":"mcm","clk":"1004909093","pt":1580639022697,"mc":[{"id":"1.168209732","rc":[{"batb":[[0,3.7,15.12],[1,1.01,0.51],[2,3.7,0]],"ltp":4.6,"tv":27.64,"id":12986367},{"batb":[[0,3.95,13.44],[1,1.01,0.51],[2,3.95,0]],"ltp":5.2,"tv":4.36,"id":18318124},{"batb":[[0,1.86,48.73],[1,1.01,0.51],[2,1.85,0]],"ltp":1.86,"tv":633.44,"id":18318122}]}]}
{"op":"mcm","clk":"1004909378","pt":1580639024867,"mc":[{"id":"1.168209732","rc":[{"batb":[[0,1.01,0.51],[1,1.01,0]],"ltp":4.6,"tv":27.64,"id":12986367},{"batb":[[0,1.01,0.51],[1,1.01,0]],"ltp":5.2,"tv":4.36,"id":18318124},{"batb":[[0,1.01,0.51],[1,1.01,0]],"ltp":1.86,"tv":633.44,"id":18318122}]}]}
{"op":"mcm","clk":"1004909690","pt":1580639027700,"mc":[{"id":"1.168209732","rc":[{"batb":[[0,3.7,31.96],[1,3.65,33.7],[2,1.01,0.51]],"ltp":4.6,"tv":27.64,"id":12986367},{"batb":[[0,4.2,64.72],[1,4.1,52.63],[2,1.01,0.51]],"ltp":5.2,"tv":4.36,"id":18318124},{"batb":[[0,1.91,89.74],[1,1.89,82.06],[2,1.01,0.51]],"ltp":1.86,"tv":633.44,"id":18318122}]}]}
{"op":"mcm","clk":"1004910066","pt":1580639030417,"mc":[{"id":"1.168209732","rc":[{"batb":[[0,1.01,0.51],[1,3.65,0],[2,1.01,0]],"ltp":4.6,"tv":27.64,"id":12986367},{"batb":[[0,1.01,0.51],[1,4.1,0],[2,1.01,0]],"ltp":5.2,"tv":4.36,"id":18318124},{"batb":[[0,1.01,0.51],[1,1.89,0],[2,1.01,0]],"ltp":1.86,"tv":633.44,"id":18318122}]}]}
{"op":"mcm","clk":"1004910468","pt":1580639033778,"mc":[{"id":"1.168209732","rc":[{"batb":[[0,3.35,49.16],[1,3.3,42.95],[2,1.01,0.51]],"ltp":4.6,"tv":27.64,"id":12986367},{"batb":[[0,3.9,47.49],[1,3.85,31.05],[2,1.01,0.51]],"ltp":5.2,"tv":4.36,"id":18318124},{"batb":[[0,1.78,101.56],[1,1.76,103.41],[2,1.01,0.51]],"ltp":1.86,"tv":633.44,"id":18318122}]}]}
{"op":"mcm","clk":"1004910561","pt":1580639034829,"mc":[{"id":"1.168209732","rc":[{"batb":[[0,1.01,0.51],[1,3.3,0],[2,1.01,0]],"ltp":4.6,"tv":27.64,"id":12986367},{"batb":[[0,1.01,0.51],[1,3.85,0],[2,1.01,0]],"ltp":5.2,"tv":4.36,"id":18318124}]}]}
{"op":"mcm","clk":"1004910899","pt":1580639037883,"mc":[{"id":"1.168209732","rc":[{"batb":[[0,4,44.81],[1,3.95,27.78],[2,1.01,0.51]],"ltp":4.6,"tv":27.64,"id":12986367},{"batb":[[0,4.6,27.33],[1,4.5,43.01],[2,1.01,0.51]],"ltp":5.2,"tv":4.36,"id":18318124}]}]}
{"op":"mcm","clk":"1004911119","pt":1580639039405,"mc":[{"id":"1.168209732","rc":[{"batb":[[2,3.85,14.28]],"batl":[[0,4.6,10.92]],"ltp":4.6,"tv":27.64,"id":12986367},{"batb":[[2,4.1,13.44]],"batl":[[0,4.9,10.08]],"ltp":5.2,"tv":4.36,"id":18318124},{"batb":[[1,1.77,53.77],[2,1.76,103.41]],"batl":[[0,1.96,42.01]],"ltp":1.86,"tv":633.44,"id":18318122}]}]}
{"op":"mcm","clk":"1004912281","pt":1580639049843,"mc":[{"id":"1.168209732","rc":[{"batb":[[0,3.85,14.28],[1,1.01,0.51],[2,3.85,0]],"ltp":4.6,"tv":27.64,"id":12986367},{"batb":[[0,4.1,13.44],[1,1.01,0.51],[2,4.1,0]],"ltp":5.2,"tv":4.36,"id":18318124},{"batb":[[0,1.77,53.77],[1,1.01,0.51],[2,1.76,0]],"ltp":1.86,"tv":633.44,"id":18318122}]}]}
{"op":"mcm","clk":"1004912387","pt":1580639050718,"mc":[{"id":"1.168209732","rc":[{"batb":[[0,1.01,0.51],[1,1.01,0]],"ltp":4.6,"tv":27.64,"id":12986367},{"batb":[[0,1.01,0.51],[1,1.01,0]],"ltp":5.2,"tv":4.36,"id":18318124},{"batb":[[0,1.01,0.51],[1,1.01,0]],"ltp":1.86,"tv":633.44,"id":18318122}]}]}
{"op":"mcm","clk":"1004912590","pt":1580639052836,"mc":[{"id":"1.168209732","rc":[{"batb":[[0,3.65,30.41],[1,3.6,34.86],[2,1.01,0.51]],"ltp":4.6,"tv":27.64,"id":12986367},{"batb":[[0,4.2,52.83],[1,4.1,52.83],[2,1.01,0.51]],"ltp":5.2,"tv":4.36,"id":18318124},{"batb":[[0,1.72,111.75],[1,1.7,116.39],[2,1.01,0.51]],"ltp":1.86,"tv":633.44,"id":18318122}]}]}
{"op":"mcm","clk":"1004912690","pt":1580639053825,"mc":[{"id":"1.168209732","rc":[{"batb":[[0,1.01,0.51],[1,3.6,0],[2,1.01,0]],"ltp":4.6,"tv":27.64,"id":12986367},{"batb":[[0,1.01,0.51],[1,4.1,0],[2,1.01,0]],"ltp":5.2,"tv":4.36,"id":18318124},{"batb":[[0,1.01,0.51],[1,1.7,0],[2,1.01,0]],"ltp":1.86,"tv":633.44,"id":18318122}]}]}
{"op":"mcm","clk":"1004912771","pt":1580639054615,"mc":[{"id":"1.168209732","rc":[{"batb":[[0,3.95,27.52],[1,3.9,28.79],[2,1.01,0.51]],"ltp":4.6,"tv":27.64,"id":12986367},{"batb":[[0,4.5,38.51],[1,4.4,45.1],[2,1.01,0.51]],"ltp":5.2,"tv":4.36,"id":18318124},{"batb":[[0,1.81,88.41],[1,1.79,97.74],[2,1.01,0.51]],"ltp":1.86,"tv":633.44,"id":18318122}]}]}
{"op":"mcm","clk":"1004913142","pt":1580639057833,"mc":[{"id":"1.168209732","rc":[{"batb":[[0,1.01,0.51],[1,3.9,0],[2,1.01,0]],"ltp":4.6,"tv":27.64,"id":12986367},{"batb":[[0,1.01,0.51],[1,4.4,0],[2,1.01,0]],"ltp":5.2,"tv":4.36,"id":18318124},{"batb":[[0,1.01,0.51],[1,1.79,0],[2,1.01,0]],"ltp":1.86,"tv":633.44,"id":18318122}]}]}
{"op":"mcm","clk":"1004913381","pt":1580639060699,"mc":[{"id":"1.168209732","rc":[{"batb":[[0,3.65,30.41],[1,3.6,34.86],[2,1.01,0.51]],"ltp":4.6,"tv":27.64,"id":12986367},{"batb":[[0,4.2,52.83],[1,4.1,52.83],[2,1.01,0.51]],"ltp":5.2,"tv":4.36,"id":18318124},{"batb":[[0,1.72,111.75],[1,1.7,116.39],[2,1.01,0.51]],"ltp":1.86,"tv":633.44,"id":18318122}]}]}
{"op":"mcm","clk":"1004914308","pt":1580639070950,"mc":[{"id":"1.168209732","rc":[{"batb":[[0,1.01,0.51],[1,3.6,0],[2,1.01,0]],"ltp":4.6,"tv":27.64,"id":12986367},{"batb":[[0,1.01,0.51],[1,4.1,0],[2,1.01,0]],"ltp":5.2,"tv":4.36,"id":18318124}]}]}
{"op":"mcm","clk":"1004914612","pt":1580639073925,"mc":[{"id":"1.168209732","rc":[{"batb":[[0,4.2,40.43],[1,4.1,50.29],[2,1.01,0.51]],"ltp":4.6,"tv":27.64,"id":12986367},{"batb":[[0,4.7,58.1],[1,4.6,40.43],[2,1.01,0.51]],"ltp":5.2,"tv":4.36,"id":18318124}]}]}
{"op":"mcm","clk":"1004914739","pt":1580639075228,"mc":[{"id":"1.168209732","rc":[{"batb":[[2,4,13.44]],"batl":[[0,4.8,10.92]],"ltp":4.6,"tv":27.64,"id":12986367},{"batb":[[2,4.3,12.6]],"batl":[[0,5.1,10.08]],"ltp":5.2,"tv":4.36,"id":18318124},{"batb":[[0,1.72,169.72]],"batl":[[0,1.89,42.01]],"ltp":1.86,"tv":633.44,"id":18318122}]}]}
{"op":"mcm","clk":"1004916418","pt":1580639092940,"mc":[{"id":"1.168209732","rc":[{"batb":[[0,4,13.44],[1,1.01,0.51],[2,4,0]],"ltp":4.6,"tv":27.64,"id":12986367},{"batb":[[0,4.3,12.6],[1,1.01,0.51],[2,4.3,0]],"ltp":5.2,"tv":4.36,"id":18318124},{"batb":[[0,1.72,57.97],[1,1.01,0.51],[2,1.01,0]],"ltp":1.86,"tv":633.44,"id":18318122}]}]}
{"op":"mcm","clk":"1004916573","pt":1580639094553,"mc":[{"id":"1.168209732","rc":[{"batb":[[0,1.01,0.51],[1,1.01,0]],"ltp":4.6,"tv":27.64,"id":12986367},{"batb":[[0,1.01,0.51],[1,1.01,0]],"ltp":5.2,"tv":4.36,"id":18318124},{"batb":[[0,1.01,0.51],[1,1.01,0]],"ltp":1.86,"tv":633.44,"id":18318122}]}]}
{"op":"mcm","clk":"1004916708","pt":1580639095745,"mc":[{"id":"1.168209732","rc":[{"batb":[[0,3.9,46.25],[1,3.85,29.52],[2,1.01,0.51]],"ltp":4.6,"tv":27.64,"id":12986367},{"batb":[[0,4.5,51.52],[1,4.4,44.89],[2,1.01,0.51]],"ltp":5.2,"tv":4.36,"id":18318124},{"batb":[[0,1.69,82.72],[1,1.68,60.94],[2,1.01,0.51]],"ltp":1.86,"tv":633.44,"id":18318122}]}]}
{"op":"mcm","clk":"1004916790","pt":1580639096736,"mc":[{"id":"1.168209732","rc":[{"batb":[[0,1.01,0.51],[1,3.85,0],[2,1.01,0]],"ltp":4.6,"tv":27.64,"id":12986367},{"batb":[[0,1.01,0.51],[1,4.4,0],[2,1.01,0]],"ltp":5.2,"tv":4.36,"id":18318124}]}]}
{"op":"mcm","clk":"1004917082","pt":1580639099754,"mc":[{"id":"1.168209732","rc":[{"batb":[[0,4.3,59.92],[1,4.2,47.18],[2,1.01,0.51]],"ltp":4.6,"tv":27.64,"id":12986367},{"batb":[[0,4.9,21.33],[1,4.8,37.25],[2,1.01,0.51]],"ltp":5.2,"tv":4.36,"id":18318124}]}]}
{"op":"mcm","clk":"1004917282","pt":1580639101949,"mc":[{"id":"1.168209732","rc":[{"batb":[[1,4.2,59.78]],"batl":[[0,4.9,10.08]],"ltp":4.6,"tv":27.64,"id":12986367},{"batb":[[2,4.3,12.6]],"batl":[[0,5.2,9.24]],"ltp":5.2,"tv":4.36,"id":18318124},{"batb":[[0,1.69,143.21]],"batl":[[0,1.85,42.01]],"ltp":1.86,"tv":633.44,"id":18318122}]}]}
{"op":"mcm","clk":"1004918411","pt":1580639113877,"mc":[{"id":"1.168209732","rc":[{"batb":[[0,4.2,12.6],[1,1.01,0.51],[2,1.01,0]],"ltp":4.6,"tv":27.64,"id":12986367},{"batb":[[0,4.3,12.6],[1,1.01,0.51],[2,4.3,0]],"ltp":5.2,"tv":4.36,"id":18318124},{"batb":[[0,1.69,60.49],[1,1.01,0.51],[2,1.01,0]],"ltp":1.86,"tv":633.44,"id":18318122}]}]}
{"op":"mcm","clk":"1004918481","pt":1580639114669,"mc":[{"id":"1.168209732","rc":[{"batb":[[0,1.01,0.51],[1,1.01,0]],"ltp":4.6,"tv":27.64,"id":12986367},{"batb":[[0,1.01,0.51],[1,1.01,0]],"ltp":5.2,"tv":4.36,"id":18318124},{"batb":[[0,1.01,0.51],[1,1.01,0]],"ltp":1.86,"tv":633.44,"id":18318122}]}]}
{"op":"mcm","clk":"1004918674","pt":1580639116889,"mc":[{"id":"1.168209732","rc":[{"batb":[[0,4.7,38.59],[1,1.01,0.51]],"ltp":5.2,"tv":4.36,"id":18318124}]}]}
{"op":"mcm","clk":"1004918812","pt":1580639118498,"mc":[{"id":"1.168209732","rc":[{"batb":[[0,4.3,39.94],[1,4.2,47.53],[2,1.01,0.51]],"ltp":4.6,"tv":27.64,"id":12986367},{"batb":[[0,4.8,51.29],[1,4.7,38.59],[2,1.01,0.51]],"ltp":5.2,"tv":4.36,"id":18318124},{"batb":[[0,1.7,76.09],[1,1.68,121.1],[2,1.01,0.51]],"ltp":1.86,"tv":633.44,"id":18318122}]}]}
{"op":"mcm","clk":"1004919103","pt":1580639121585,"mc":[{"id":"1.168209732","rc":[{"batb":[[0,1.01,0.51],[1,4.2,0],[2,1.01,0]],"ltp":4.6,"tv":27.64,"id":12986367},{"batb":[[0,4.7,38.59],[1,1.01,0.51],[2,1.01,0]],"ltp":5.2,"tv":4.36,"id":18318124},{"batb":[[0,1.01,0.51],[1,1.68,0],[2,1.01,0]],"ltp":1.86,"tv":633.44,"id":18318122}]}]}
{"op":"mcm","clk":"1004919409","pt":1580639124819,"mc":[{"id":"1.168209732","rc":[{"batb":[[0,4.1,58.18],[1,4,52.98],[2,1.01,0.51]],"ltp":4.6,"tv":27.64,"id":12986367},{"batb":[[0,4.7,60.25],[1,4.6,40.39],[2,1.01,0.51]],"ltp":5.2,"tv":4.36,"id":18318124},{"batb":[[0,1.67,95.89],[1,1.66,63.61],[2,1.01,0.51]],"ltp":1.86,"tv":633.44,"id":18318122}]}]}
{"op":"mcm","clk":"1004919829","pt":1580639128899,"mc":[{"id":"1.168209732","rc":[{"batb":[[0,1.01,0.51],[1,4,0],[2,1.01,0]],"ltp":4.6,"tv":27.64,"id":12986367},{"batb":[[0,1.01,0.51],[1,4.6,0],[2,1.01,0]],"ltp":5.2,"tv":4.36,"id":18318124}]}]}
{"op":"mcm","clk":"1004920175","pt":1580639131811,"mc":[{"id":"1.168209732","rc":[{"batb":[[0,4.4,55.28],[1,4.3,44.72],[2,1.01,0.51]],"ltp":4.6,"tv":27.64,"id":12986367},{"batb":[[0,4.9,36.6],[1,4.8,37.01],[2,1.01,0.51]],"ltp":5.2,"tv":4.36,"id":18318124}]}]}
{"op":"mcm","clk":"1004920338","pt":1580639133323,"mc":[{"id":"1.168209732","rc":[{"batb":[[1,4.3,57.32]],"batl":[[0,5.1,10.08]],"ltp":4.6,"tv":27.64,"id":12986367},{"batb":[[2,4.4,11.76]],"batl":[[0,5.2,9.24]],"ltp":5.2,"tv":4.36,"id":18318124},{"batb":[[1,1.66,126.62]],"batl":[[0,1.82,42.01]],"ltp":1.86,"tv":633.44,"id":18318122}]}]}
{"op":"mcm","clk":"1004923099","pt":1580639159946,"mc":[{"id":"1.168209732","rc":[{"batb":[[0,4.3,12.6],[1,1.01,0.51],[2,1.01,0]],"ltp":4.6,"tv":27.64,"id":12986367},{"batb":[[0,4.4,11.76],[1,1.01,0.51],[2,4.4,0]],"ltp":5.2,"tv":4.36,"id":18318124},{"batb":[[0,1.66,63.01],[1,1.01,0.51],[2,1.01,0]],"ltp":1.86,"tv":633.44,"id":18318122}]}]}
{"op":"mcm","clk":"1004923138","pt":1580639160354,"mc":[{"id":"1.168209732","rc":[{"batb":[[0,1.01,0.51],[1,1.01,0]],"ltp":4.6,"tv":27.64,"id":12986367},{"batb":[[0,1.01,0.51],[1,1.01,0]],"ltp":5.2,"tv":4.36,"id":18318124},{"batb":[[0,1.01,0.51],[1,1.01,0]],"ltp":1.86,"tv":633.44,"id":18318122}]}]}
{"op":"mcm","clk":"1004923368","pt":1580639162364,"mc":[{"id":"1.168209732","rc":[{"batb":[[0,4.1,50.18],[1,4,53.13],[2,1.01,0.51]],"ltp":4.6,"tv":27.64,"id":12986367},{"batb":[[0,4.6,24.62],[1,4.5,43.07],[2,1.01,0.51]],"ltp":5.2,"tv":4.36,"id":18318124},{"batb":[[0,1.52,132.56],[1,1.51,90.96],[2,1.01,0.51]],"ltp":1.86,"tv":633.44,"id":18318122}]}]}
{"op":"mcm","clk":"1004924116","pt":1580639168949,"mc":[{"id":"1.168209732","rc":[{"batb":[[0,1.01,0.51],[1,4,0],[2,1.01,0]],"ltp":4.6,"tv":27.64,"id":12986367},{"batb":[[0,1.01,0.51],[1,4.5,0],[2,1.01,0]],"ltp":5.2,"tv":4.36,"id":18318124}]}]}
{"op":"mcm","clk":"1004924439","pt":1580639171950,"mc":[{"id":"1.168209732","rc":[{"batb":[[0,5.2,29.31],[1,5.1,30.53],[2,1.01,0.51]],"ltp":4.6,"tv":27.64,"id":12986367},{"batb":[[0,5.7,23.32],[1,5.6,26.36],[2,1.01,0.51]],"ltp":5.2,"tv":4.36,"id":18318124}]}]}
{"op":"mcm","clk":"1004924637","pt":1580639173641,"mc":[{"id":"1.168209732","rc":[{"batb":[[2,4.9,10.08]],"batl":[[0,5.9,8.4]],"ltp":4.6,"tv":27.64,"id":12986367},{"batb":[[2,5,10.08]],"batl":[[0,6,8.4]],"ltp":5.2,"tv":4.36,"id":18318124},{"batb":[[0,1.53,78.98],[1,1.52,132.56],[2,1.51,90.96]],"batl":[[0,1.65,42.01]],"ltp":1.86,"tv":633.44,"id":18318122}]}]}
{"op":"mcm","clk":"1004928207","pt":1580639206615,"mc":[{"id":"1.168209732","rc":[{"batb":[[0,4.9,10.08],[1,1.01,0.51],[2,4.9,0]],"ltp":4.6,"tv":27.64,"id":12986367},{"batb":[[0,5,10.08],[1,1.01,0.51],[2,5,0]],"ltp":5.2,"tv":4.36,"id":18318124},{"batb":[[1,1.01,0.51],[2,1.51,0]],"ltp":1.86,"tv":633.44,"id":18318122}]}]}
{"op":"mcm","clk":"1004928398","pt":1580639208408,"mc":[{"id":"1.168209732","rc":[{"batb":[[0,1.01,0.51],[1,1.01,0]],"ltp":4.6,"tv":27.64,"id":12986367},{"batb":[[0,1.01,0.51],[1,1.01,0]],"ltp":5.2,"tv":4.36,"id":18318124},{"batb":[[0,1.01,0.51],[1,1.01,0]],"ltp":1.86,"tv":633.44,"id":18318122}]}]}
{"op":"mcm","clk":"1004928523","pt":1580639209579,"mc":[{"id":"1.168209732","rc":[{"batb":[[0,4.6,38.41],[1,4.5,40.5],[2,1.01,0.51]],"ltp":4.6,"tv":27.64,"id":12986367},{"batb":[[0,5,47.45],[1,4.9,35.16],[2,1.01,0.51]],"ltp":5.2,"tv":4.36,"id":18318124},{"batb":[[0,1.36,85.08],[1,1.35,148.17],[2,1.01,0.51]],"ltp":1.86,"tv":633.44,"id":18318122}]}]}
{"op":"mcm","clk":"1004932187","pt":1580639240559,"mc":[{"id":"1.168209732","rc":[{"batb":[[0,1.01,0.51],[1,1.35,0],[2,1.01,0]],"ltp":1.86,"tv":633.44,"id":18318122}]}]}
{"op":"mcm","clk":"1004932659","pt":1580639243818,"mc":[{"id":"1.168209732","rc":[{"batb":[[1,4.5,52.26]],"batl":[[0,5.3,9.24]],"ltp":4.6,"tv":27.64,"id":12986367},{"batb":[[2,4.5,11.76]],"batl":[[0,5.3,9.24]],"ltp":5.2,"tv":4.36,"id":18318124},{"batb":[[0,1.63,195.35],[1,1.62,69.56],[2,1.01,0.51]],"batl":[[0,1.77,42.01]],"ltp":1.86,"tv":633.44,"id":18318122}]}]}
{"op":"mcm","clk":"1004934750","pt":1580639263352,"mc":[{"id":"1.168209732","rc":[{"batb":[[0,4.5,11.76],[1,1.01,0.51],[2,1.01,0]],"ltp":4.6,"tv":27.64,"id":12986367},{"batb":[[0,4.5,11.76],[1,1.01,0.51],[2,4.5,0]],"ltp":5.2,"tv":4.36,"id":18318124},{"batb":[[0,1.63,66.38],[1,1.01,0.51],[2,1.01,0]],"ltp":1.86,"tv":633.44,"id":18318122}]}]}
{"op":"mcm","clk":"1004934875","pt":1580639264655,"mc":[{"id":"1.168209732","rc":[{"batb":[[0,1.01,0.51],[1,1.01,0]],"ltp":4.6,"tv":27.64,"id":12986367},{"batb":[[0,1.01,0.51],[1,1.01,0]],"ltp":5.2,"tv":4.36,"id":18318124},{"batb":[[0,1.01,0.51],[1,1.01,0]],"ltp":1.86,"tv":633.44,"id":18318122}]}]}
{"op":"mcm","clk":"1004934991","pt":1580639265954,"mc":[{"id":"1.168209732","rc":[{"batb":[[0,4.2,31.8],[1,4.1,50.45],[2,1.01,0.51]],"ltp":4.6,"tv":27.64,"id":12986367},{"batb":[[0,4.6,33.15],[1,4.5,42.93],[2,1.01,0.51]],"ltp":5.2,"tv":4.36,"id":18318124},{"batb":[[0,1.46,129.33],[1,1.45,107.49],[2,1.01,0.51]],"ltp":1.86,"tv":633.44,"id":18318122}]}]}
{"op":"mcm","clk":"1004935491","pt":1580639270760,"mc":[{"id":"1.168209732","rc":[{"batb":[[0,1.01,0.51],[1,1.45,0],[2,1.01,0]],"ltp":1.86,"tv":633.44,"id":18318122}]}]}
{"op":"mcm","clk":"1004935802","pt":1580639273862,"mc":[{"id":"1.168209732","rc":[{"batb":[[0,1.75,82.11],[1,1.73,109.55],[2,1.01,0.51]],"ltp":1.86,"tv":633.44,"id":18318122}]}]}
{"op":"mcm","clk":"1004936003","pt":1580639275897,"mc":[{"id":"1.168209732","rc":[{"batb":[[1,4.1,63.89]],"batl":[[0,4.9,10.08]],"ltp":4.6,"tv":27.64,"id":12986367},{"batb":[[2,4.1,13.44]],"batl":[[0,4.8,10.92]],"ltp":5.2,"tv":4.36,"id":18318124},{"batb":[[1,1.74,56.29],[2,1.73,109.55]],"batl":[[0,1.91,42.01]],"ltp":1.86,"tv":633.44,"id":18318122}]}]}
{"op":"mcm","clk":"1004936648","pt":1580639281881,"mc":[{"id":"1.168209732","rc":[{"batb":[[0,4.1,13.44],[1,1.01,0.51],[2,1.01,0]],"ltp":4.6,"tv":27.64,"id":12986367},{"batb":[[0,4.1,13.44],[1,1.01,0.51],[2,4.1,0]],"ltp":5.2,"tv":4.36,"id":18318124},{"batb":[[0,1.74,56.29],[1,1.01,0.51],[2,1.73,0]],"ltp":1.86,"tv":633.44,"id":18318122}]}]}
{"op":"mcm","clk":"1004936704","pt":1580639282399,"mc":[{"id":"1.168209732","rc":[{"batb":[[0,1.01,0.51],[1,1.01,0]],"ltp":4.6,"tv":27.64,"id":12986367},{"batb":[[0,1.01,0.51],[1,1.01,0]],"ltp":5.2,"tv":4.36,"id":18318124},{"batb":[[0,1.01,0.51],[1,1.01,0]],"ltp":1.86,"tv":633.44,"id":18318122}]}]}
{"op":"mcm","clk":"1004936938","pt":1580639284814,"mc":[{"id":"1.168209732","rc":[{"batb":[[0,3.9,52.29],[1,3.85,29.47],[2,1.01,0.51]],"ltp":4.6,"tv":27.64,"id":12986367},{"batb":[[0,4.3,50.09],[1,4.2,50.02],[2,1.01,0.51]],"ltp":5.2,"tv":4.36,"id":18318124},{"batb":[[0,1.6,88.34],[1,1.59,74.36],[2,1.01,0.51]],"ltp":1.86,"tv":633.44,"id":18318122}]}]}
{"op":"mcm","clk":"1004937347","pt":1580639288829,"mc":[{"id":"1.168209732","rc":[{"batb":[[0,1.01,0.51],[1,1.59,0],[2,1.01,0]],"ltp":1.86,"tv":633.44,"id":18318122}]}]}
{"op":"mcm","clk":"1004937641","pt":1580639291636,"mc":[{"id":"1.168209732","rc":[{"batb":[[0,1.84,93.78],[1,1.82,92.63],[2,1.01,0.51]],"ltp":1.86,"tv":633.44,"id":18318122}]}]}
{"op":"mcm","clk":"1004937833","pt":1580639293729,"mc":[{"id":"1.168209732","rc":[{"batb":[[0,3.9,66.57]],"batl":[[0,4.6,10.92]],"ltp":4.6,"tv":27.64,"id":12986367},{"batb":[[2,3.85,14.28]],"batl":[[0,4.5,11.76]],"ltp":5.2,"tv":4.36,"id":18318124},{"batl":[[0,2.02,41.17]],"ltp":1.86,"tv":633.44,"id":18318122}]}]}
{"op":"mcm","clk":"1004937926","pt":1580639294727,"mc":[{"id":"1.168209732","rc":[{"batb":[[1,1.83,50.41],[2,1.82,92.63]],"ltp":1.86,"tv":633.44,"id":18318122}]}]}
{"op":"mcm","clk":"1004939031","pt":1580639305933,"mc":[{"id":"1.168209732","rc":[{"batb":[[0,3.9,14.28],[1,1.01,0.51],[2,1.01,0]],"ltp":4.6,"tv":27.64,"id":12986367},{"batb":[[0,4.2,50.02],[1,3.85,14.28],[2,1.01,0.51]],"ltp":5.2,"tv":4.36,"id":18318124},{"batb":[[0,1.83,50.41],[1,1.01,0.51],[2,1.82,0]],"ltp":1.86,"tv":633.44,"id":18318122}]}]}
{"op":"mcm","clk":"1004939082","pt":1580639306434,"mc":[{"id":"1.168209732","rc":[{"batb":[[0,1.01,0.51],[1,1.01,0]],"ltp":4.6,"tv":27.64,"id":12986367},{"batb":[[1,1.01,0.51],[2,1.01,0]],"ltp":5.2,"tv":4.36,"id":18318124},{"batb":[[0,1.01,0.51],[1,1.01,0]],"ltp":1.86,"tv":633.44,"id":18318122}]}]}
{"op":"mcm","clk":"1004939327","pt":1580639308849,"mc":[{"id":"1.168209732","rc":[{"batb":[[0,3.8,35.82],[1,3.75,31.54],[2,1.01,0.51]],"ltp":4.6,"tv":27.64,"id":12986367},{"batb":[[1,4.1,52.88],[2,1.01,0.51]],"ltp":5.2,"tv":4.36,"id":18318124},{"batb":[[0,1.76,60.26],[1,1.74,107.37],[2,1.01,0.51]],"ltp":1.86,"tv":633.44,"id":18318122}]}]}
{"op":"mcm","clk":"1004939416","pt":1580639309637,"mc":[{"id":"1.168209732","rc":[{"batb":[[0,1.01,0.51],[1,3.75,0],[2,1.01,0]],"ltp":4.6,"tv":27.64,"id":12986367},{"batb":[[1,1.01,0.51],[2,1.01,0]],"ltp":5.2,"tv":4.36,"id":18318124},{"batb":[[0,1.01,0.51],[1,1.74,0],[2,1.01,0]],"ltp":1.86,"tv":633.44,"id":18318122}]}]}
{"op":"mcm","clk":"1004939660","pt":1580639311861,"mc":[{"id":"1.168209732","rc":[{"batb":[[0,3.95,52.52],[1,3.9,28.56],[2,1.01,0.51]],"ltp":4.6,"tv":27.64,"id":12986367},{"batb":[[0,4.3,69.61],[1,4.2,50.02],[2,1.01,0.51]],"ltp":5.2,"tv":4.36,"id":18318124},{"batb":[[0,1.83,57.61],[1,1.81,94.22],[2,1.01,0.51]],"ltp":1.86,"tv":633.44,"id":18318122}]}]}
{"op":"mcm","clk":"1004940281","pt":1580639317850,"mc":[{"id":"1.168209732","rc":[{"batb":[[0,1.01,0.51],[1,3.9,0],[2,1.01,0]],"ltp":4.6,"tv":27.64,"id":12986367},{"batb":[[0,4.2,50.02],[1,1.01,0.51],[2,1.01,0]],"ltp":5.2,"tv":4.36,"id":18318124},{"batb":[[0,1.01,0.51],[1,1.81,0],[2,1.01,0]],"ltp":1.86,"tv":633.44,"id":18318122}]}]}
{"op":"mcm","clk":"1004940586","pt":1580639320777,"mc":[{"id":"1.168209732","rc":[{"batb":[[0,3.8,35.82],[1,3.75,31.54],[2,1.01,0.51]],"ltp":4.6,"tv":27.64,"id":12986367},{"batb":[[1,4.1,52.88],[2,1.01,0.51]],"ltp":5.2,"tv":4.36,"id":18318124},{"batb":[[0,1.76,60.26],[1,1.74,107.37],[2,1.01,0.51]],"ltp":1.86,"tv":633.44,"id":18318122}]}]}
{"op":"mcm","clk":"1004941148","pt":1580639326888,"mc":[{"id":"1.168209732","rc":[{"batb":[[0,1.01,0.51],[1,1.74,0],[2,1.01,0]],"ltp":1.86,"tv":633.44,"id":18318122}]}]}
{"op":"mcm","clk":"1004941447","pt":1580639329885,"mc":[{"id":"1.168209732","rc":[{"batb":[[0,1.89,85.07],[1,1.87,84.89],[2,1.01,0.51]],"ltp":1.86,"tv":633.44,"id":18318122}]}]}
{"op":"mcm","clk":"1004941619","pt":1580639331708,"mc":[{"id":"1.168209732","rc":[{"batb":[[2,3.7,15.12]],"batl":[[0,4.3,12.6]],"ltp":4.6,"tv":27.64,"id":12986367},{"batb":[[2,3.8,14.28]],"batl":[[0,4.4,11.76]],"ltp":5.2,"tv":4.36,"id":18318124},{"batb":[[0,1.89,132.12]],"batl":[[0,2.1,37.81]],"ltp":1.86,"tv":633.44,"id":18318122}]}]}
{"op":"mcm","clk":"1004950318","pt":1580639415795,"mc":[{"id":"1.168209732","rc":[{"batb":[[0,3.7,15.12],[1,1.01,0.51],[2,3.7,0]],"ltp":4.6,"tv":27.64,"id":12986367},{"batb":[[0,3.8,14.28],[1,1.01,0.51],[2,3.8,0]],"ltp":5.2,"tv":4.36,"id":18318124},{"batb":[[0,1.89,47.05],[1,1.01,0.51],[2,1.01,0]],"ltp":1.86,"tv":633.44,"id":18318122}]}]}
{"op":"mcm","clk":"1004950402","pt":1580639416482,"mc":[{"id":"1.168209732","rc":[{"batb":[[0,1.01,0.51],[1,1.01,0]],"ltp":4.6,"tv":27.64,"id":12986367},{"batb":[[0,1.01,0.51],[1,1.01,0]],"ltp":5.2,"tv":4.36,"id":18318124},{"batb":[[0,1.01,0.51],[1,1.01,0]],"ltp":1.86,"tv":633.44,"id":18318122}]}]}
{"op":"mcm","clk":"1004950625","pt":1580639418865,"mc":[{"id":"1.168209732","rc":[{"batb":[[0,3.35,47.56],[1,3.3,43.04],[2,1.01,0.51]],"ltp":4.6,"tv":27.64,"id":12986367},{"batb":[[0,3.75,59.45],[1,3.7,34.01],[2,1.01,0.51]],"ltp":5.2,"tv":4.36,"id":18318124},{"batb":[[0,1.8,65.1],[1,1.78,99.57],[2,1.01,0.51]],"ltp":1.86,"tv":633.44,"id":18318122}]}]}
{"op":"mcm","clk":"1004951542","pt":1580639428776,"mc":[{"id":"1.168209732","rc":[{"batb":[[0,1.01,0.51],[1,3.3,0],[2,1.01,0]],"ltp":4.6,"tv":27.64,"id":12986367},{"batb":[[0,1.01,0.51],[1,3.7,0],[2,1.01,0]],"ltp":5.2,"tv":4.36,"id":18318124}]}]}
{"op":"mcm","clk":"1004951847","pt":1580639431910,"mc":[{"id":"1.168209732","rc":[{"batb":[[0,4,63.04],[1,3.95,27.67],[2,1.01,0.51]],"ltp":4.6,"tv":27.64,"id":12986367},{"batb":[[0,4.4,61.89],[1,4.3,47.15],[2,1.01,0.51]],"ltp":5.2,"tv":4.36,"id":18318124}]}]}
{"op":"mcm","clk":"1004952015","pt":1580639433587,"mc":[{"id":"1.168209732","rc":[{"batb":[[2,3.85,14.28]],"batl":[[0,4.6,10.92]],"ltp":4.6,"tv":27.64,"id":12986367},{"batb":[[2,3.95,13.44]],"batl":[[0,4.7,10.92]],"ltp":5.2,"tv":4.36,"id":18318124},{"batb":[[0,1.8,117.19]],"batl":[[0,1.99,42.01]],"ltp":1.86,"tv":633.44,"id":18318122}]}]}
{"op":"mcm","clk":"1004953576","pt":1580639449928,"mc":[{"id":"1.168209732","rc":[{"batb":[[0,3.85,14.28],[1,1.01,0.51],[2,3.85,0]],"ltp":4.6,"tv":27.64,"id":12986367},{"batb":[[0,3.95,13.44],[1,1.01,0.51],[2,3.95,0]],"ltp":5.2,"tv":4.36,"id":18318124},{"batb":[[0,1.8,52.09],[1,1.01,0.51],[2,1.01,0]],"ltp":1.86,"tv":633.44,"id":18318122}]}]}
{"op":"mcm","clk":"1004953635","pt":1580639450553,"mc":[{"id":"1.168209732","rc":[{"batb":[[0,1.01,0.51],[1,1.01,0]],"ltp":4.6,"tv":27.64,"id":12986367},{"batb":[[0,1.01,0.51],[1,1.01,0]],"ltp":5.2,"tv":4.36,"id":18318124},{"batb":[[0,1.01,0.51],[1,1.01,0]],"ltp":1.86,"tv":633.44,"id":18318122}]}]}
{"op":"mcm","clk":"1004953851","pt":1580639452435,"mc":[{"id":"1.168209732","rc":[{"batb":[[0,3.65,39.01],[1,3.6,34.85],[2,1.01,0.51]],"ltp":4.6,"tv":27.64,"id":12986367},{"batb":[[0,4.1,39.06],[1,4,56.19],[2,1.01,0.51]],"ltp":5.2,"tv":4.36,"id":18318124},{"batb":[[0,1.74,58.92],[1,1.72,111.68],[2,1.01,0.51]],"ltp":1.86,"tv":633.44,"id":18318122}]}]}
{"op":"mcm","clk":"1004953956","pt":1580639453537,"mc":[{"id":"1.168209732","rc":[{"batb":[[0,1.01,0.51],[1,3.6,0],[2,1.01,0]],"ltp":4.6,"tv":27.64,"id":12986367},{"batb":[[0,1.01,0.51],[1,4,0],[2,1.01,0]],"ltp":5.2,"tv":4.36,"id":18318124},{"batb":[[0,1.01,0.51],[1,1.72,0],[2,1.01,0]],"ltp":1.86,"tv":633.44,"id":18318122}]}]}
{"op":"mcm","clk":"1004954288","pt":1580639456731,"mc":[{"id":"1.168209732","rc":[{"batb":[[0,3.95,43.82],[1,3.9,28.7],[2,1.01,0.51]],"ltp":4.6,"tv":27.64,"id":12986367},{"batb":[[0,4.4,26.97],[1,4.3,47.73],[2,1.01,0.51]],"ltp":5.2,"tv":4.36,"id":18318124},{"batb":[[0,1.83,63.2],[1,1.81,94.25],[2,1.01,0.51]],"ltp":1.86,"tv":633.44,"id":18318122}]}]}
{"op":"mcm","clk":"1004954605","pt":1580639459764,"mc":[{"id":"1.168209732","rc":[{"batb":[[0,1.01,0.51],[1,3.9,0],[2,1.01,0]],"ltp":4.6,"tv":27.64,"id":12986367},{"batb":[[0,1.01,0.51],[1,4.3,0],[2,1.01,0]],"ltp":5.2,"tv":4.36,"id":18318124},{"batb":[[0,1.01,0.51],[1,1.81,0],[2,1.01,0]],"ltp":1.86,"tv":633.44,"id":18318122}]}]}
{"op":"mcm","clk":"1004954927","pt":1580639462557,"mc":[{"id":"1.168209732","rc":[{"batb":[[0,3.65,39.01],[1,3.6,34.85],[2,1.01,0.51]],"ltp":4.6,"tv":27.64,"id":12986367},{"batb":[[0,4.1,39.06],[1,4,56.19],[2,1.01,0.51]],"ltp":5.2,"tv":4.36,"id":18318124},{"batb":[[0,1.74,58.92],[1,1.72,111.68],[2,1.01,0.51]],"ltp":1.86,"tv":633.44,"id":18318122}]}]}
{"op":"mcm","clk":"1004955075","pt":1580639463864,"mc":[{"id":"1.168209732","rc":[{"batb":[[0,1.01,0.51],[1,1.72,0],[2,1.01,0]],"ltp":1.86,"tv":633.44,"id":18318122}]}]}
