{"op":"mcm","clk":"998153799","pt":1580585268961,"mc":[{"id":"1.168224344","marketDefinition":{"bspMarket":false,"turnInPlayEnabled":true,"persistenceEnabled":true,"marketBaseRate":5.0,"eventId":"29681717","eventTypeId":"2","numberOfWinners":1,"bettingType":"ODDS","marketType":"SET_WINNER","marketTime":"2020-02-02T09:30:00.000Z","suspendTime":"2020-02-02T09:30:00.000Z","bspReconciled":false,"complete":true,"inPlay":false,"crossMatching":false,"runnersVoidable":false,"numberOfActiveRunners":2,"betDelay":0,"status":"OPEN","runners":[{"status":"ACTIVE","sortPriority":1,"id":6498878,"name":"Marco Trungelliti"},{"status":"ACTIVE","sortPriority":2,"id":8174333,"name":"Enzo Couacaud"}],"regulators":["MR_INT"],"countryCode":"FR","discountAllowed":false,"timezone":"UTC","openDate":"2020-02-02T09:30:00.000Z","version":3147098151,"name":"Set 2 Winner","eventName":"Trungelliti v Couacaud"},"rc":[{"batb":[[0,1.01,20]],"ltp":0.0,"tv":0.0,"id":6498878},{"batb":[[0,1.01,20]],"ltp":0.0,"tv":0.0,"id":8174333}]}]}
{"op":"mcm","clk":"998154037","pt":1580585270458,"mc":[{"id":"1.168224344","marketDefinition":{"bspMarket":false,"turnInPlayEnabled":true,"persistenceEnabled":true,"marketBaseRate":5.0,"eventId":"29681717","eventTypeId":"2","numberOfWinners":1,"bettingType":"ODDS","marketType":"SET_WINNER","marketTime":"2020-02-02T09:30:00.000Z","suspendTime":"2020-02-02T09:30:00.000Z","bspReconciled":false,"complete":true,"inPlay":false,"crossMatching":false,"runnersVoidable":false,"numberOfActiveRunners":2,"betDelay":0,"status":"OPEN","runners":[{"status":"ACTIVE","sortPriority":1,"id":6498878,"name":"Marco Trungelliti"},{"status":"ACTIVE","sortPriority":2,"id":8174333,"name":"Enzo Couacaud"}],"regulators":["MR_INT"],"countryCode":"FR","discountAllowed":false,"timezone":"UTC","openDate":"2020-02-02T09:30:00.000Z","version":3147098151,"name":"Set 2 Winner","eventName":"Trungelliti v Couacaud"}}]}
{"op":"mcm","clk":"998154461","pt":1580585272452,"mc":[{"id":"1.168224344","marketDefinition":{"bspMarket":false,"turnInPlayEnabled":true,"persistenceEnabled":true,"marketBaseRate":5.0,"eventId":"29681717","eventTypeId":"2","numberOfWinners":1,"bettingType":"ODDS","marketType":"SET_WINNER","marketTime":"2020-02-02T09:30:00.000Z","suspendTime":"2020-02-02T09:30:00.000Z","bspReconciled":false,"complete":true,"inPlay":false,"crossMatching":false,"runnersVoidable":false,"numberOfActiveRunners":2,"betDelay":0,"status":"OPEN","runners":[{"status":"ACTIVE","sortPriority":1,"id":6498878,"name":"Marco Trungelliti"},{"status":"ACTIVE","sortPriority":2,"id":8174333,"name":"Enzo Couacaud"}],"regulators":["MR_INT"],"countryCode":"FR","discountAllowed":true,"timezone":"UTC","openDate":"2020-02-02T09:30:00.000Z","version":3147098151,"name":"Set 2 Winner","eventName":"Trungelliti v Couacaud"}}]}
{"op":"mcm","clk":"998178647","pt":1580585417045,"mc":[{"id":"1.168224344","rc":[{"batb":[[0,1.01,15]],"ltp":0.0,"tv":0.0,"id":6498878},{"batb":[[0,1.01,15]],"ltp":0.0,"tv":0.0,"id":8174333}]}]}
{"op":"mcm","clk":"999887118","pt":1580602184316,"mc":[{"id":"1.168224344","rc":[{"batb":[[0,1.01,17.53]],"ltp":0.0,"tv":0.0,"id":6498878},{"batb":[[0,1.01,17.53]],"ltp":0.0,"tv":0.0,"id":8174333}]}]}
{"op":"mcm","clk":"999887184","pt":1580602185410,"mc":[{"id":"1.168224344","rc":[{"batb":[[0,1.01,15.51]],"ltp":0.0,"tv":0.0,"id":6498878},{"batb":[[0,1.01,15.51]],"ltp":0.0,"tv":0.0,"id":8174333}]}]}
{"op":"mcm","clk":"999983197","pt":1580603724270,"mc":[{"id":"1.168224344","rc":[{"batb":[[0,1.01,16.01]],"ltp":0.0,"tv":0.0,"id":6498878},{"batb":[[0,1.01,16.01]],"ltp":0.0,"tv":0.0,"id":8174333}]}]}
{"op":"mcm","clk":"1000104055","pt":1580607069353,"mc":[{"id":"1.168224344","rc":[{"batb":[[0,1.01,16.02]],"ltp":0.0,"tv":0.0,"id":6498878},{"batb":[[0,1.01,16.02]],"ltp":0.0,"tv":0.0,"id":8174333}]}]}
{"op":"mcm","clk":"1001405682","pt":1580635220301,"mc":[{"id":"1.168224344","rc":[{"batb":[[0,2.36,17.23],[1,1.01,16.02]],"ltp":0.0,"tv":0.0,"id":6498878},{"batb":[[0,1.64,27.07],[1,1.01,16.02]],"ltp":0.0,"tv":0.0,"id":8174333}]}]}
{"op":"mcm","clk":"1001406525","pt":1580635235757,"mc":[{"id":"1.168224344","marketDefinition":{"bspMarket":false,"turnInPlayEnabled":true,"persistenceEnabled":true,"marketBaseRate":5.0,"eventId":"29681717","eventTypeId":"2","numberOfWinners":1,"bettingType":"ODDS","marketType":"SET_WINNER","marketTime":"2020-02-02T09:30:00.000Z","suspendTime":"2020-02-02T09:30:00.000Z","bspReconciled":false,"complete":true,"inPlay":false,"crossMatching":true,"runnersVoidable":false,"numberOfActiveRunners":2,"betDelay":0,"status":"OPEN","runners":[{"status":"ACTIVE","sortPriority":1,"id":6498878,"name":"Marco Trungelliti"},{"status":"ACTIVE","sortPriority":2,"id":8174333,"name":"Enzo Couacaud"}],"regulators":["MR_INT"],"countryCode":"FR","discountAllowed":true,"timezone":"UTC","openDate":"2020-02-02T09:30:00.000Z","version":3147124815,"name":"Set 2 Winner","eventName":"Trungelliti v Couacaud"}}]}
{"op":"mcm","clk":"1001410030","pt":1580635314173,"mc":[{"id":"1.168224344","marketDefinition":{"bspMarket":false,"turnInPlayEnabled":true,"persistenceEnabled":true,"marketBaseRate":5.0,"eventId":"29681717","eventTypeId":"2","numberOfWinners":1,"bettingType":"ODDS","marketType":"SET_WINNER","marketTime":"2020-02-02T09:19:00.000Z","suspendTime":"2020-02-02T09:19:00.000Z","bspReconciled":false,"complete":true,"inPlay":false,"crossMatching":true,"runnersVoidable":false,"numberOfActiveRunners":2,"betDelay":0,"status":"OPEN","runners":[{"status":"ACTIVE","sortPriority":1,"id":6498878,"name":"Marco Trungelliti"},{"status":"ACTIVE","sortPriority":2,"id":8174333,"name":"Enzo Couacaud"}],"regulators":["MR_INT"],"countryCode":"FR","discountAllowed":true,"timezone":"UTC","openDate":"2020-02-02T09:30:00.000Z","version":3148342590,"name":"Set 2 Winner","eventName":"Trungelliti v Couacaud"}}]}
{"op":"mcm","clk":"1001410228","pt":1580635317874,"mc":[{"id":"1.168224344","marketDefinition":{"bspMarket":false,"turnInPlayEnabled":true,"persistenceEnabled":true,"marketBaseRate":5.0,"eventId":"29681717","eventTypeId":"2","numberOfWinners":1,"bettingType":"ODDS","marketType":"SET_WINNER","marketTime":"2020-02-02T09:19:00.000Z","suspendTime":"2020-02-02T09:19:00.000Z","bspReconciled":false,"complete":true,"inPlay":false,"crossMatching":true,"runnersVoidable":false,"numberOfActiveRunners":2,"betDelay":0,"status":"OPEN","runners":[{"status":"ACTIVE","sortPriority":1,"id":6498878,"name":"Marco Trungelliti"},{"status":"ACTIVE","sortPriority":2,"id":8174333,"name":"Enzo Couacaud"}],"regulators":["MR_INT"],"countryCode":"FR","discountAllowed":true,"timezone":"UTC","openDate":"2020-02-02T09:19:00.000Z","version":3148342590,"name":"Set 2 Winner","eventName":"Trungelliti v Couacaud"}}]}
{"op":"mcm","clk":"1001420874","pt":1580635535308,"mc":[{"id":"1.168224344","rc":[{"batb":[[0,1.01,16.02],[1,1.01,0]],"ltp":0.0,"tv":0.0,"id":6498878},{"batb":[[0,1.01,16.02],[1,1.01,0]],"ltp":0.0,"tv":0.0,"id":8174333}]}]}
{"op":"mcm","clk":"1001420967","pt":1580635537142,"mc":[{"id":"1.168224344","marketDefinition":{"bspMarket":false,"turnInPlayEnabled":true,"persistenceEnabled":true,"marketBaseRate":5.0,"eventId":"29681717","eventTypeId":"2","numberOfWinners":1,"bettingType":"ODDS","marketType":"SET_WINNER","marketTime":"2020-02-02T09:19:00.000Z","suspendTime":"2020-02-02T09:19:00.000Z","bspReconciled":false,"complete":true,"inPlay":true,"crossMatching":true,"runnersVoidable":false,"numberOfActiveRunners":2,"betDelay":3,"status":"OPEN","runners":[{"status":"ACTIVE","sortPriority":1,"id":6498878,"name":"Marco Trungelliti"},{"status":"ACTIVE","sortPriority":2,"id":8174333,"name":"Enzo Couacaud"}],"regulators":["MR_INT"],"countryCode":"FR","discountAllowed":true,"timezone":"UTC","openDate":"2020-02-02T09:19:00.000Z","version":3148343960,"name":"Set 2 Winner","eventName":"Trungelliti v Couacaud"},"rc":[{"batb":[[0,1.01,15.52]],"ltp":0.0,"tv":0.0,"id":6498878},{"batb":[[0,1.01,15.52]],"ltp":0.0,"tv":0.0,"id":8174333}]}]}
{"op":"mcm","clk":"1001455365","pt":1580636221436,"mc":[{"id":"1.168224344","rc":[{"batb":[[0,1.61,1205.68],[1,1.01,15.52]],"ltp":0.0,"tv":0.0,"id":6498878}]}]}
{"op":"mcm","clk":"1001455502","pt":1580636224057,"mc":[{"id":"1.168224344","rc":[{"batb":[[0,2.26,19.51],[1,2.2,34.45],[2,1.01,15.52]],"batl":[[0,2.5,27.73]],"ltp":0.0,"tv":0.0,"id":6498878},{"batb":[[0,1.67,62.17],[1,1.62,28.01],[2,1.01,15.52]],"batl":[[0,1.83,42.01]],"ltp":0.0,"tv":0.0,"id":8174333}]}]}
{"op":"mcm","clk":"1001455859","pt":1580636232251,"mc":[{"id":"1.168224344","rc":[{"batb":[[1,1.01,15.52],[2,1.01,0]],"ltp":0.0,"tv":0.0,"id":6498878},{"batb":[[0,1.62,28.01],[1,1.01,15.52],[2,1.01,0]],"ltp":0.0,"tv":0.0,"id":8174333}]}]}
{"op":"mcm","clk":"1001456179","pt":1580636239276,"mc":[{"id":"1.168224344","rc":[{"batb":[[0,2.4,16.6],[1,2.32,18.41],[2,2.24,33.61]],"batl":[[0,2.54,26.89]],"ltp":0.0,"tv":0.0,"id":6498878},{"batb":[[0,1.65,63.85],[1,1.62,28.01],[2,1.6,29.43]],"batl":[[0,1.81,42.01]],"ltp":0.0,"tv":0.0,"id":8174333}]}]}
{"op":"mcm","clk":"1001456591","pt":1580636248662,"mc":[{"id":"1.168224344","rc":[{"batb":[[0,2.32,18.41],[1,2.24,33.61],[2,1.01,15.52]],"ltp":0.0,"tv":0.0,"id":6498878},{"batb":[[1,1.6,29.43],[2,1.01,15.52]],"ltp":0.0,"tv":0.0,"id":8174333}]}]}
{"op":"mcm","clk":"1001456652","pt":1580636250365,"mc":[{"id":"1.168224344","rc":[{"batb":[[1,1.01,15.52],[2,1.01,0]],"ltp":0.0,"tv":0.0,"id":6498878},{"batb":[[0,1.6,29.43],[1,1.01,15.52],[2,1.01,0]],"ltp":0.0,"tv":0.0,"id":8174333}]}]}
{"op":"mcm","clk":"1001456711","pt":1580636251800,"mc":[{"id":"1.168224344","rc":[{"batb":[[0,2.3,18.73]],"ltp":0.0,"tv":0.0,"id":6498878},{"batb":[[0,1.61,28.95]],"ltp":0.0,"tv":0.0,"id":8174333}]}]}
{"op":"mcm","clk":"1001457406","pt":1580636267322,"mc":[{"id":"1.168224344","rc":[{"batb":[[0,2.44,15.97],[1,2.36,17.23],[2,2.26,32.77]],"batl":[[0,2.58,26.05]],"ltp":0.0,"tv":0.0,"id":6498878},{"batb":[[0,1.63,66.38],[1,1.61,28.95],[2,1.59,30.06]],"batl":[[0,1.79,42.01]],"ltp":0.0,"tv":0.0,"id":8174333}]}]}
{"op":"mcm","clk":"1001457835","pt":1580636276346,"mc":[{"id":"1.168224344","rc":[{"batb":[[0,2.36,17.23],[1,1.01,15.52],[2,2.26,0]],"ltp":0.0,"tv":0.0,"id":6498878},{"batb":[[0,1.59,30.06],[1,1.01,15.52],[2,1.59,0]],"ltp":0.0,"tv":0.0,"id":8174333}]}]}
{"op":"mcm","clk":"1001457978","pt":1580636279336,"mc":[{"id":"1.168224344","rc":[{"batb":[[0,2.34,17.62]],"ltp":0.0,"tv":0.0,"id":6498878},{"batb":[[0,1.6,29.43]],"ltp":0.0,"tv":0.0,"id":8174333}]}]}
{"op":"mcm","clk":"1001458885","pt":1580636302243,"mc":[{"id":"1.168224344","rc":[{"batb":[[0,2.44,15.74],[1,2.38,16.84],[2,2.34,17.62]],"ltp":0.0,"tv":0.0,"id":6498878},{"batb":[[1,1.57,31.71],[2,1.01,15.52]],"ltp":0.0,"tv":0.0,"id":8174333}]}]}
{"op":"mcm","clk":"1001458934","pt":1580636303272,"mc":[{"id":"1.168224344","rc":[{"batb":[[2,2.34,31.09]],"batl":[[0,2.66,25.21]],"ltp":0.0,"tv":0.0,"id":6498878},{"batb":[[0,1.6,99.16]],"batl":[[0,1.75,42.01]],"ltp":0.0,"tv":0.0,"id":8174333}]}]}
{"op":"mcm","clk":"1001460641","pt":1580636342692,"mc":[{"id":"1.168224344","rc":[{"batb":[[0,2.38,16.84],[1,2.34,31.09],[2,1.01,15.52]],"ltp":0.0,"tv":0.0,"id":6498878},{"batb":[[0,1.6,69.74]],"ltp":0.0,"tv":0.0,"id":8174333}]}]}
{"op":"mcm","clk":"1001460712","pt":1580636344390,"mc":[{"id":"1.168224344","rc":[{"batb":[[1,1.01,15.52],[2,1.01,0]],"ltp":0.0,"tv":0.0,"id":6498878},{"batb":[[0,1.57,31.71],[1,1.01,15.52],[2,1.01,0]],"ltp":0.0,"tv":0.0,"id":8174333}]}]}
{"op":"mcm","clk":"1001460789","pt":1580636346201,"mc":[{"id":"1.168224344","rc":[{"batb":[[0,2.36,17.23]],"ltp":0.0,"tv":0.0,"id":6498878},{"batb":[[0,1.58,31.08]],"ltp":0.0,"tv":0.0,"id":8174333}]}]}
{"op":"mcm","clk":"1001461801","pt":1580636367353,"mc":[{"id":"1.168224344","rc":[{"batb":[[1,2.32,18.18],[2,1.01,15.52]],"ltp":0.0,"tv":0.0,"id":6498878},{"batb":[[0,1.64,27.15],[1,1.6,29.51],[2,1.01,15.52]],"ltp":0.0,"tv":0.0,"id":8174333}]}]}
{"op":"mcm","clk":"1001461808","pt":1580636367417,"mc":[{"id":"1.168224344","rc":[{"batb":[[1,2.32,49.26]],"batl":[[0,2.62,25.21]],"ltp":0.0,"tv":0.0,"id":6498878},{"batb":[[1,1.62,67.22],[2,1.6,29.51]],"batl":[[0,1.78,42.01]],"ltp":0.0,"tv":0.0,"id":8174333}]}]}
{"op":"mcm","clk":"1001462392","pt":1580636383159,"mc":[{"id":"1.168224344","rc":[{"batb":[[0,2.32,49.26],[1,1.01,15.52],[2,1.01,0]],"ltp":0.0,"tv":0.0,"id":6498878},{"batb":[[0,1.62,67.22],[1,1.6,29.51],[2,1.01,15.52]],"ltp":0.0,"tv":0.0,"id":8174333}]}]}
{"op":"mcm","clk":"1001462520","pt":1580636384562,"mc":[{"id":"1.168224344","rc":[{"batb":[[0,2.32,18.18]],"ltp":0.0,"tv":0.0,"id":6498878},{"batb":[[0,1.6,29.51],[1,1.01,15.52],[2,1.01,0]],"ltp":0.0,"tv":0.0,"id":8174333}]}]}
{"op":"mcm","clk":"1001462601","pt":1580636386372,"mc":[{"id":"1.168224344","rc":[{"batb":[[0,1.61,29.03],[1,1.6,29.51],[2,1.01,15.52]],"ltp":0.0,"tv":0.0,"id":8174333}]}]}
{"op":"mcm","clk":"1001462620","pt":1580636386982,"mc":[{"id":"1.168224344","rc":[{"batb":[[1,1.01,15.52],[2,1.01,0]],"ltp":0.0,"tv":0.0,"id":8174333}]}]}
{"op":"mcm","clk":"1001463147","pt":1580636401376,"mc":[{"id":"1.168224344","rc":[{"batb":[[0,2.44,15.97],[1,2.38,17.07],[2,1.01,15.52]],"ltp":0.0,"tv":0.0,"id":6498878},{"batb":[[1,1.57,31.63],[2,1.01,15.52]],"ltp":0.0,"tv":0.0,"id":8174333}]}]}
{"op":"mcm","clk":"1001463150","pt":1580636401476,"mc":[{"id":"1.168224344","rc":[{"batb":[[1,2.38,47.32]],"batl":[[0,2.7,24.37]],"ltp":0.0,"tv":0.0,"id":6498878},{"batb":[[1,1.59,70.58],[2,1.57,31.63]],"batl":[[0,1.74,42.01]],"ltp":0.0,"tv":0.0,"id":8174333}]}]}
{"op":"mcm","clk":"1001463305","pt":1580636404983,"mc":[{"id":"1.168224344","rc":[{"batl":[[1,3.3,191.92]],"ltp":0.0,"tv":0.0,"id":6498878},{"batl":[[1,2.16,342.82]],"ltp":0.0,"tv":0.0,"id":8174333}]}]}
{"op":"mcm","clk":"1001463678","pt":1580636414115,"mc":[{"id":"1.168224344","rc":[{"batb":[[0,2.38,47.32],[1,1.01,15.52],[2,1.01,0]],"ltp":0.0,"tv":0.0,"id":6498878},{"batb":[[0,1.59,70.58],[1,1.57,31.63],[2,1.01,15.52]],"ltp":0.0,"tv":0.0,"id":8174333}]}]}
{"op":"mcm","clk":"1001463704","pt":1580636414521,"mc":[{"id":"1.168224344","rc":[{"batb":[[0,2.38,17.07]],"batl":[[0,3.3,191.92],[1,3.3,0]],"ltp":0.0,"tv":0.0,"id":6498878},{"batb":[[0,1.57,31.63],[1,1.01,15.52],[2,1.01,0]],"batl":[[0,2.16,342.82],[1,2.16,0]],"ltp":0.0,"tv":0.0,"id":8174333}]}]}
{"op":"mcm","clk":"1001464756","pt":1580636437313,"mc":[{"id":"1.168224344","rc":[{"batb":[[1,2.34,17.94],[2,1.01,15.52]],"ltp":0.0,"tv":0.0,"id":6498878},{"batb":[[0,1.63,27.3],[1,1.6,29.58],[2,1.58,1386.56]],"ltp":0.0,"tv":0.0,"id":8174333}]}]}
{"op":"mcm","clk":"1001464782","pt":1580636437930,"mc":[{"id":"1.168224344","rc":[{"batb":[[1,2.34,49.03]],"batl":[[0,2.64,25.21],[1,3.3,191.92]],"ltp":0.0,"tv":0.0,"id":6498878},{"batb":[[1,1.61,68.06],[2,1.6,29.58]],"batl":[[0,1.76,42.01],[1,2.16,342.82]],"ltp":0.0,"tv":0.0,"id":8174333}]}]}
{"op":"mcm","clk":"1001465568","pt":1580636456233,"mc":[{"id":"1.168224344","rc":[{"batb":[[0,2.34,49.03],[1,1.01,15.52],[2,1.01,0]],"ltp":0.0,"tv":0.0,"id":6498878},{"batb":[[0,1.61,68.06],[1,1.6,29.58],[2,1.01,15.52]],"ltp":0.0,"tv":0.0,"id":8174333}]}]}
{"op":"mcm","clk":"1001465585","pt":1580636456545,"mc":[{"id":"1.168224344","rc":[{"batb":[[0,2.34,17.94]],"batl":[[0,3.3,191.92],[1,3.3,0]],"ltp":0.0,"tv":0.0,"id":6498878},{"batb":[[0,1.6,29.58],[1,1.01,15.52],[2,1.01,0]],"batl":[[0,2.16,342.82],[1,2.16,0]],"ltp":0.0,"tv":0.0,"id":8174333}]}]}
{"op":"mcm","clk":"1001465919","pt":1580636464168,"mc":[{"id":"1.168224344","rc":[{"batb":[[0,2.46,15.58],[1,2.4,46.17],[2,1.01,15.52]],"batl":[[0,2.72,24.37],[1,3.3,191.92]],"ltp":0.0,"tv":0.0,"id":6498878},{"batb":[[1,1.59,70.58],[2,1.56,32.5]],"batl":[[0,1.73,42.01],[1,2.16,342.82]],"ltp":0.0,"tv":0.0,"id":8174333}]}]}
{"op":"mcm","clk":"1001466518","pt":1580636477263,"mc":[{"id":"1.168224344","rc":[{"batb":[[0,2.4,46.17],[1,1.01,15.52],[2,1.01,0]],"ltp":0.0,"tv":0.0,"id":6498878},{"batb":[[0,1.59,70.58],[1,1.56,32.5],[2,1.01,15.52]],"ltp":0.0,"tv":0.0,"id":8174333}]}]}
{"op":"mcm","clk":"1001466631","pt":1580636479378,"mc":[{"id":"1.168224344","rc":[{"batb":[[0,2.4,16.76]],"batl":[[0,3.3,191.92],[1,3.3,0]],"ltp":0.0,"tv":0.0,"id":6498878},{"batb":[[0,1.56,32.5],[1,1.01,15.52],[2,1.01,0]],"batl":[[0,2.16,342.82],[1,2.16,0]],"ltp":0.0,"tv":0.0,"id":8174333}]}]}
{"op":"mcm","clk":"1001468105","pt":1580636505023,"mc":[{"id":"1.168224344","rc":[{"batb":[[0,2.56,14.01],[1,2.48,15.34],[2,1.01,15.52]],"ltp":0.0,"tv":0.0,"id":6498878},{"batb":[[1,1.52,35.96],[2,1.01,15.52]],"ltp":0.0,"tv":0.0,"id":8174333}]}]}
{"op":"mcm","clk":"1001468184","pt":1580636506208,"mc":[{"id":"1.168224344","rc":[{"batb":[[2,2.46,28.57]],"batl":[[0,2.8,22.69],[1,3.3,191.92]],"ltp":0.0,"tv":0.0,"id":6498878},{"batb":[[0,1.56,107.27]],"batl":[[0,1.7,42.01],[1,2.16,342.82]],"ltp":0.0,"tv":0.0,"id":8174333}]}]}
{"op":"mcm","clk":"1001468630","pt":1580636514143,"mc":[{"id":"1.168224344","rc":[{"batb":[[0,2.48,15.34],[1,2.46,28.57],[2,1.01,15.52]],"ltp":0.0,"tv":0.0,"id":6498878},{"batb":[[0,1.56,74.78]],"ltp":0.0,"tv":0.0,"id":8174333}]}]}
{"op":"mcm","clk":"1001468657","pt":1580636514610,"mc":[{"id":"1.168224344","rc":[{"batb":[[1,1.01,15.52],[2,1.01,0]],"batl":[[0,3.3,191.92],[1,3.3,0]],"ltp":0.0,"tv":0.0,"id":6498878},{"batb":[[0,1.52,35.96],[1,1.01,15.52],[2,1.01,0]],"batl":[[0,2.16,342.82],[1,2.16,0]],"ltp":0.0,"tv":0.0,"id":8174333}]}]}
{"op":"mcm","clk":"1001469131","pt":1580636523348,"mc":[{"id":"1.168224344","rc":[{"batl":[[0,3.65,170.41]],"ltp":0.0,"tv":0.0,"id":6498878},{"batl":[[0,2.04,383.01]],"ltp":0.0,"tv":0.0,"id":8174333}]}]}
{"op":"mcm","clk":"1001471284","pt":1580636555994,"mc":[{"id":"1.168224344","rc":[{"batb":[[1,2.42,29.41],[2,2.4,16.52]],"batl":[[0,2.74,23.53]],"ltp":0.0,"tv":0.0,"id":6498878},{"batb":[[0,1.59,30.06],[1,1.57,73.1],[2,1.55,33.05]],"batl":[[0,1.72,42.01],[1,2.04,383.01]],"ltp":0.0,"tv":0.0,"id":8174333}]}]}
{"op":"mcm","clk":"1001471380","pt":1580636557898,"mc":[{"id":"1.168224344","rc":[{"batl":[[1,3.45,180.4]],"ltp":0.0,"tv":0.0,"id":6498878}]}]}
{"op":"mcm","clk":"1001472488","pt":1580636579918,"mc":[{"id":"1.168224344","rc":[{"batb":[[0,2.42,29.41],[1,2.4,16.52],[2,1.01,15.52]],"ltp":0.0,"tv":0.0,"id":6498878},{"batb":[[0,1.57,73.1],[1,1.55,33.05],[2,1.01,15.52]],"ltp":0.0,"tv":0.0,"id":8174333}]}]}
{"op":"mcm","clk":"1001472549","pt":1580636580910,"mc":[{"id":"1.168224344","rc":[{"batb":[[0,2.4,16.52],[1,1.01,15.52],[2,1.01,0]],"batl":[[0,3.45,180.4],[1,3.45,0]],"ltp":0.0,"tv":0.0,"id":6498878},{"batb":[[0,1.55,33.05],[1,1.01,15.52],[2,1.01,0]],"batl":[[0,2.04,383.01],[1,2.04,0]],"ltp":0.0,"tv":0.0,"id":8174333}]}]}
{"op":"mcm","clk":"1001473182","pt":1580636591403,"mc":[{"id":"1.168224344","rc":[{"batb":[[0,2.58,13.69],[1,2.5,15.03],[2,1.01,15.52]],"ltp":0.0,"tv":0.0,"id":6498878},{"batb":[[1,1.51,36.74],[2,1.01,15.52]],"ltp":0.0,"tv":0.0,"id":8174333}]}]}
{"op":"mcm","clk":"1001473188","pt":1580636591506,"mc":[{"id":"1.168224344","rc":[{"batb":[[2,2.48,27.73]],"batl":[[0,2.82,22.69],[1,3.45,180.4]],"ltp":0.0,"tv":0.0,"id":6498878},{"batb":[[0,1.55,108.66]],"batl":[[0,1.69,42.01],[1,2.04,383.01]],"ltp":0.0,"tv":0.0,"id":8174333}]}]}
{"op":"mcm","clk":"1001474086","pt":1580636610345,"mc":[{"id":"1.168224344","rc":[{"batb":[[0,2.5,15.03],[1,2.48,27.73],[2,1.01,15.52]],"ltp":0.0,"tv":0.0,"id":6498878},{"batb":[[0,1.55,75.62]],"ltp":0.0,"tv":0.0,"id":8174333}]}]}
{"op":"mcm","clk":"1001474104","pt":1580636610758,"mc":[{"id":"1.168224344","rc":[{"batb":[[1,1.01,15.52],[2,1.01,0]],"batl":[[0,3.45,180.4],[1,3.45,0]],"ltp":0.0,"tv":0.0,"id":6498878},{"batb":[[0,1.51,36.74],[1,1.01,15.52],[2,1.01,0]],"batl":[[0,2.04,383.01],[1,2.04,0]],"ltp":0.0,"tv":0.0,"id":8174333}]}]}
{"op":"mcm","clk":"1001475662","pt":1580636645317,"mc":[{"id":"1.168224344","rc":[{"batb":[[0,2.7,12.04],[1,2.6,13.45],[2,2.5,444.68]],"ltp":0.0,"tv":0.0,"id":6498878},{"batb":[[1,1.49,38.16],[2,1.01,15.52]],"ltp":0.0,"tv":0.0,"id":8174333}]}]}
{"op":"mcm","clk":"1001475673","pt":1580636645623,"mc":[{"id":"1.168224344","rc":[{"batb":[[1,2.64,25.21],[2,2.6,13.45]],"batl":[[0,3.05,20.16]],"ltp":0.0,"tv":0.0,"id":6498878},{"batb":[[2,1.48,87.39]],"batl":[[0,1.61,42.01],[1,2.04,383.01]],"ltp":0.0,"tv":0.0,"id":8174333}]}]}
{"op":"mcm","clk":"1001475769","pt":1580636648193,"mc":[{"id":"1.168224344","rc":[{"batl":[[1,3.9,158.24]],"ltp":0.0,"tv":0.0,"id":6498878}]}]}
{"op":"mcm","clk":"1001477328","pt":1580636675368,"mc":[{"id":"1.168224344","rc":[{"batb":[[0,2.64,25.21],[1,2.6,13.45],[2,1.01,15.52]],"ltp":0.0,"tv":0.0,"id":6498878},{"batb":[[0,1.49,38.16],[1,1.48,87.39],[2,1.01,15.51]],"ltp":0.0,"tv":0.0,"id":8174333}]}]}
{"op":"mcm","clk":"1001477372","pt":1580636676656,"mc":[{"id":"1.168224344","rc":[{"batb":[[0,2.6,13.45],[1,1.01,15.52],[2,1.01,0]],"batl":[[0,3.9,158.24],[1,3.9,0]],"ltp":0.0,"tv":0.0,"id":6498878},{"batb":[[1,1.01,15.52],[2,1.01,0]],"batl":[[0,2.04,383.01],[1,2.04,0]],"ltp":0.0,"tv":0.0,"id":8174333}]}]}
{"op":"mcm","clk":"1001477817","pt":1580636683363,"mc":[{"id":"1.168224344","rc":[{"batb":[[0,2.76,11.57],[1,2.66,12.67],[2,1.01,15.52]],"ltp":0.0,"tv":0.0,"id":6498878},{"batb":[[1,1.47,40.37],[2,1.01,15.51]],"ltp":0.0,"tv":0.0,"id":8174333}]}]}
{"op":"mcm","clk":"1001477828","pt":1580636683669,"mc":[{"id":"1.168224344","rc":[{"batb":[[1,2.7,24.37],[2,2.66,12.67]],"batl":[[0,3.1,19.32],[1,3.9,158.24]],"ltp":0.0,"tv":0.0,"id":6498878},{"batb":[[1,1.48,87.39],[2,1.47,40.36]],"batl":[[0,1.59,42.01],[1,2.04,383.01]],"ltp":0.0,"tv":0.0,"id":8174333}]}]}
{"op":"mcm","clk":"1001478313","pt":1580636693357,"mc":[{"id":"1.168224344","rc":[{"batb":[[0,2.7,24.37],[1,2.66,12.67],[2,1.01,15.52]],"ltp":0.0,"tv":0.0,"id":6498878},{"batb":[[0,1.48,87.39],[1,1.47,40.36],[2,1.01,15.51]],"ltp":0.0,"tv":0.0,"id":8174333}]}]}
{"op":"mcm","clk":"1001478392","pt":1580636695362,"mc":[{"id":"1.168224344","rc":[{"batb":[[0,2.66,12.67],[1,1.01,15.52],[2,1.01,0]],"batl":[[0,3.9,158.24],[1,3.9,0]],"ltp":0.0,"tv":0.0,"id":6498878},{"batb":[[0,1.47,40.37],[1,1.01,15.51],[2,1.01,0]],"batl":[[0,2.04,383.01],[1,2.04,0]],"ltp":0.0,"tv":0.0,"id":8174333}]}]}
{"op":"mcm","clk":"1001479177","pt":1580636707311,"mc":[{"id":"1.168224344","rc":[{"batb":[[1,2.56,14.08],[2,1.01,15.52]],"ltp":0.0,"tv":0.0,"id":6498878},{"batb":[[0,1.52,35.33],[1,1.5,37.14],[2,1.01,15.52]],"ltp":0.0,"tv":0.0,"id":8174333}]}]}
{"op":"mcm","clk":"1001479247","pt":1580636708393,"mc":[{"id":"1.168224344","rc":[{"batb":[[1,2.6,26.05],[2,2.56,14.08]],"batl":[[0,3,21]],"ltp":0.0,"tv":0.0,"id":6498878},{"batb":[[1,1.5,121.16]],"batl":[[0,1.62,42.01],[1,2.04,383.01]],"ltp":0.0,"tv":0.0,"id":8174333}]}]}
{"op":"mcm","clk":"1001479266","pt":1580636708805,"mc":[{"id":"1.168224344","rc":[{"batl":[[1,3.65,170.41]],"ltp":0.0,"tv":0.0,"id":6498878}]}]}
{"op":"mcm","clk":"1001479776","pt":1580636717320,"mc":[{"id":"1.168224344","rc":[{"batb":[[0,2.6,26.05],[1,2.56,14.08],[2,1.01,15.52]],"ltp":0.0,"tv":0.0,"id":6498878},{"batb":[[0,1.5,121.16],[1,1.01,15.52],[2,1.01,0]],"ltp":0.0,"tv":0.0,"id":8174333}]}]}
{"op":"mcm","clk":"1001479885","pt":1580636719187,"mc":[{"id":"1.168224344","rc":[{"batb":[[0,2.56,14.08],[1,1.01,15.52],[2,1.01,0]],"batl":[[0,3.65,170.41],[1,3.65,0]],"ltp":0.0,"tv":0.0,"id":6498878},{"batb":[[0,1.5,37.14]],"batl":[[0,2.04,383.01],[1,2.04,0]],"ltp":0.0,"tv":0.0,"id":8174333}]}]}
{"op":"mcm","clk":"1001480193","pt":1580636725332,"mc":[{"id":"1.168224344","rc":[{"batb":[[0,2.72,11.88],[1,2.62,13.14],[2,1.01,15.52]],"ltp":0.0,"tv":0.0,"id":6498878},{"batb":[[1,1.48,39.11],[2,1.01,15.51]],"ltp":0.0,"tv":0.0,"id":8174333}]}]}
{"op":"mcm","clk":"1001480232","pt":1580636726003,"mc":[{"id":"1.168224344","rc":[{"batb":[[1,2.66,25.21],[2,2.62,13.14]],"batl":[[0,3.05,20.16],[1,3.65,170.41]],"ltp":0.0,"tv":0.0,"id":6498878},{"batb":[[1,1.49,85.7],[2,1.48,39.11]],"batl":[[0,1.61,42.01],[1,2.04,383.01]],"ltp":0.0,"tv":0.0,"id":8174333}]}]}
{"op":"mcm","clk":"1001480593","pt":1580636733328,"mc":[{"id":"1.168224344","rc":[{"batb":[[0,2.66,25.21],[1,2.62,13.14],[2,1.01,15.52]],"ltp":0.0,"tv":0.0,"id":6498878},{"batb":[[0,1.49,85.7],[1,1.48,39.11],[2,1.01,15.51]],"ltp":0.0,"tv":0.0,"id":8174333}]}]}
{"op":"mcm","clk":"1001480663","pt":1580636734719,"mc":[{"id":"1.168224344","rc":[{"batb":[[0,2.62,13.14],[1,1.01,15.52],[2,1.01,0]],"batl":[[0,3.65,170.41],[1,3.65,0]],"ltp":0.0,"tv":0.0,"id":6498878},{"batb":[[0,1.48,39.11],[1,1.01,15.51],[2,1.01,0]],"batl":[[0,2.04,383.01],[1,2.04,0]],"ltp":0.0,"tv":0.0,"id":8174333}]}]}
{"op":"mcm","clk":"1001482756","pt":1580636773186,"mc":[{"id":"1.168224344","rc":[{"batb":[[0,2.78,11.17],[1,2.7,12.27],[2,1.01,15.52]],"ltp":0.0,"tv":0.0,"id":6498878},{"batb":[[1,1.47,40.76],[2,1.01,15.51]],"ltp":0.0,"tv":0.0,"id":8174333}]}]}
{"op":"mcm","clk":"1001482809","pt":1580636774371,"mc":[{"id":"1.168224344","rc":[{"batb":[[2,2.68,24.37]],"batl":[[0,3.1,19.32],[1,3.65,170.41]],"ltp":0.0,"tv":0.0,"id":6498878},{"batb":[[1,1.47,129.82]],"batl":[[0,1.59,42.01],[1,2.04,383.01]],"ltp":0.0,"tv":0.0,"id":8174333}]}]}
{"op":"mcm","clk":"1001483486","pt":1580636789692,"mc":[{"id":"1.168224344","rc":[{"batb":[[0,2.7,12.27],[1,2.68,24.37],[2,1.01,15.52]],"ltp":0.0,"tv":0.0,"id":6498878},{"batb":[[0,1.47,129.83],[1,1.01,15.51],[2,1.01,0]],"ltp":0.0,"tv":0.0,"id":8174333}]}]}
{"op":"mcm","clk":"1001483542","pt":1580636790838,"mc":[{"id":"1.168224344","rc":[{"batb":[[1,1.01,15.52],[2,1.01,0]],"batl":[[0,3.65,170.41],[1,3.65,0]],"ltp":0.0,"tv":0.0,"id":6498878},{"batb":[[0,1.47,40.77]],"batl":[[0,2.04,383.01],[1,2.04,0]],"ltp":0.0,"tv":0.0,"id":8174333}]}]}
{"op":"mcm","clk":"1001484332","pt":1580636806936,"mc":[{"id":"1.168224344","rc":[{"batb":[[0,2.84,10.62],[1,2.76,11.41],[2,1.01,15.52]],"ltp":0.0,"tv":0.0,"id":6498878},{"batb":[[1,1.44,43.83],[2,1.01,15.51]],"ltp":0.0,"tv":0.0,"id":8174333}]}]}
{"op":"mcm","clk":"1001484374","pt":1580636807706,"mc":[{"id":"1.168224344","rc":[{"batb":[[1,2.8,22.69],[2,2.76,11.41]],"batl":[[0,3.2,18.48]],"ltp":0.0,"tv":0.0,"id":6498878},{"batb":[[1,1.45,93.26],[2,1.44,43.83]],"batl":[[0,1.57,42.01]],"ltp":0.0,"tv":0.0,"id":8174333}]}]}
{"op":"mcm","clk":"1001484462","pt":1580636809203,"mc":[{"id":"1.168224344","rc":[{"batl":[[1,4.2,148.03]],"ltp":0.0,"tv":0.0,"id":6498878},{"batl":[[1,1.89,435.28]],"ltp":0.0,"tv":0.0,"id":8174333}]}]}
{"op":"mcm","clk":"1001484987","pt":1580636817937,"mc":[{"id":"1.168224344","rc":[{"batb":[[0,1.47,915.29]],"ltp":0.0,"tv":0.0,"id":8174333}]}]}
{"op":"mcm","clk":"1001489115","pt":1580636895026,"mc":[{"id":"1.168224344","rc":[{"batb":[[0,2.76,11.41],[1,1.01,15.52],[2,2.76,0]],"batl":[[0,4.2,148.03],[1,4.2,0]],"ltp":0.0,"tv":0.0,"id":6498878},{"batb":[[0,1.44,43.84],[1,1.01,15.51],[2,1.44,0]],"batl":[[0,1.89,435.28],[1,1.89,0]],"ltp":0.0,"tv":0.0,"id":8174333}]}]}
{"op":"mcm","clk":"1001490199","pt":1580636916100,"mc":[{"id":"1.168224344","rc":[{"batb":[[0,2.92,24.63],[1,2.86,32.23],[2,1.01,15.52]],"batl":[[0,3.3,17.64],[1,4.2,148.03]],"ltp":0.0,"tv":0.0,"id":6498878},{"batb":[[0,1.44,138.78],[1,1.42,47.37],[2,1.01,15.51]],"batl":[[0,1.55,42.01],[1,1.89,435.28]],"ltp":0.0,"tv":0.0,"id":8174333}]}]}
{"op":"mcm","clk":"1001491069","pt":1580636932223,"mc":[{"id":"1.168224344","rc":[{"batb":[[0,2.86,32.23],[1,1.01,15.52],[2,1.01,0]],"ltp":0.0,"tv":0.0,"id":6498878},{"batb":[[0,1.44,94.95]],"ltp":0.0,"tv":0.0,"id":8174333}]}]}
{"op":"mcm","clk":"1001491118","pt":1580636933002,"mc":[{"id":"1.168224344","rc":[{"batb":[[0,2.86,10.39]],"batl":[[0,4.2,148.03],[1,4.2,0]],"ltp":0.0,"tv":0.0,"id":6498878},{"batb":[[0,1.42,47.38],[1,1.01,15.51],[2,1.01,0]],"batl":[[0,1.89,435.28],[1,1.89,0]],"ltp":0.0,"tv":0.0,"id":8174333}]}]}
{"op":"mcm","clk":"1001492226","pt":1580636950408,"mc":[{"id":"1.168224344","rc":[{"batb":[[0,3.05,22.27],[1,2.94,24.23],[2,2.92,21.85]],"batl":[[0,3.35,17.64],[1,4.2,148.03]],"ltp":0.0,"tv":0.0,"id":6498878},{"batb":[[0,1.42,147.36],[1,1.39,52.17],[2,1.01,15.51]],"batl":[[0,1.53,42.01],[1,1.89,435.28]],"ltp":0.0,"tv":0.0,"id":8174333}]}]}
{"op":"mcm","clk":"1001493172","pt":1580636963324,"mc":[{"id":"1.168224344","rc":[{"batb":[[0,2.94,24.23],[1,2.92,21.85],[2,1.01,15.52]],"ltp":0.0,"tv":0.0,"id":6498878},{"batb":[[0,1.42,99.99]],"ltp":0.0,"tv":0.0,"id":8174333}]}]}
{"op":"mcm","clk":"1001493273","pt":1580636964933,"mc":[{"id":"1.168224344","rc":[{"batb":[[1,1.01,15.52],[2,1.01,0]],"batl":[[0,4.2,148.03],[1,4.2,0]],"ltp":0.0,"tv":0.0,"id":6498878},{"batb":[[0,1.39,52.18],[1,1.01,15.51],[2,1.01,0]],"batl":[[0,1.89,435.28],[1,1.89,0]],"ltp":0.0,"tv":0.0,"id":8174333}]}]}
{"op":"mcm","clk":"1001494462","pt":1580636984364,"mc":[{"id":"1.168224344","rc":[{"trd":[[3.1,0]],"batb":[[0,3.2,19.67],[1,3.05,21.79],[2,2.94,24.23]],"ltp":3.1,"tv":0.0,"id":6498878},{"trd":[[1.48,0.01]],"batb":[[0,1.39,52.17],[1,1.36,56.57],[2,1.01,15.51]],"ltp":1.48,"tv":0.01,"id":8174333}],"tv":0.01}]}
{"op":"mcm","clk":"1001494475","pt":1580636984568,"mc":[{"id":"1.168224344","rc":[{"batb":[[2,1.01,15.52]],"ltp":3.1,"tv":0.0,"id":6498878}]}]}
{"op":"mcm","clk":"1001494554","pt":1580636985881,"mc":[{"id":"1.168224344","rc":[{"batb":[[2,2.98,21]],"batl":[[0,3.45,16.8]],"ltp":3.1,"tv":0.0,"id":6498878},{"batb":[[0,1.41,101.66],[1,1.39,52.17],[2,1.36,56.57]],"batl":[[0,1.52,42.01]],"ltp":1.48,"tv":0.01,"id":8174333}]}]}
{"op":"mcm","clk":"1001494651","pt":1580636987371,"mc":[{"id":"1.168224344","rc":[{"batl":[[1,4.9,126.27]],"ltp":3.1,"tv":0.0,"id":6498878}]}]}
{"op":"mcm","clk":"1001494660","pt":1580636987481,"mc":[{"id":"1.168224344","rc":[{"batl":[[1,1.77,500.61]],"ltp":1.48,"tv":0.01,"id":8174333}]}]}
{"op":"mcm","clk":"1001495558","pt":1580637001027,"mc":[{"id":"1.168224344","rc":[{"batb":[[0,3.05,21.79],[1,1.01,15.52],[2,2.98,0]],"batl":[[0,4.9,126.27],[1,4.9,0]],"ltp":3.1,"tv":0.0,"id":6498878},{"batb":[[0,1.36,56.57],[1,1.01,15.51],[2,1.36,0]],"batl":[[0,1.77,500.61],[1,1.77,0]],"ltp":1.48,"tv":0.01,"id":8174333}]}]}
{"op":"mcm","clk":"1001495961","pt":1580637007048,"mc":[{"id":"1.168224344","rc":[{"batb":[[1,2.96,23.84],[2,1.01,15.52]],"ltp":3.1,"tv":0.0,"id":6498878},{"batb":[[0,1.41,48.23],[1,1.38,53.03],[2,1.01,15.51]],"ltp":1.48,"tv":0.01,"id":8174333}]}]}
{"op":"mcm","clk":"1001496030","pt":1580637008336,"mc":[{"id":"1.168224344","rc":[{"batb":[[2,2.94,21]],"batl":[[0,3.4,16.8],[1,4.9,126.27]],"ltp":3.1,"tv":0.0,"id":6498878},{"batb":[[0,1.42,99.98],[1,1.41,48.23],[2,1.38,53.03]],"batl":[[0,1.52,42.01],[1,1.77,500.61]],"ltp":1.48,"tv":0.01,"id":8174333}]}]}
{"op":"mcm","clk":"1001496752","pt":1580637019835,"mc":[{"id":"1.168224344","rc":[{"batb":[[0,2.96,23.84],[1,2.94,21],[2,1.01,15.52]],"ltp":3.1,"tv":0.0,"id":6498878},{"batb":[[1,1.38,53.03],[2,1.01,15.51]],"ltp":1.48,"tv":0.01,"id":8174333}]}]}
{"op":"mcm","clk":"1001496840","pt":1580637021024,"mc":[{"id":"1.168224344","rc":[{"batb":[[1,1.01,15.52],[2,1.01,0]],"batl":[[0,4.9,126.27],[1,4.9,0]],"ltp":3.1,"tv":0.0,"id":6498878},{"batb":[[0,1.38,53.03],[1,1.01,15.51],[2,1.01,0]],"batl":[[0,1.77,500.61],[1,1.77,0]],"ltp":1.48,"tv":0.01,"id":8174333}]}]}
{"op":"mcm","clk":"1001497459","pt":1580637031972,"mc":[{"id":"1.168224344","rc":[{"batb":[[1,2.9,21.85],[2,2.86,10.46]],"batl":[[0,3.35,17.64]],"ltp":3.1,"tv":0.0,"id":6498878},{"batb":[[0,1.44,44.93],[1,1.42,99.98],[2,1.4,49.96]],"batl":[[0,1.53,42.01],[1,1.77,500.61]],"ltp":1.48,"tv":0.01,"id":8174333}]}]}
{"op":"mcm","clk":"1001497572","pt":1580637033937,"mc":[{"id":"1.168224344","rc":[{"batl":[[1,4.6,136.05]],"ltp":3.1,"tv":0.0,"id":6498878}]}]}
{"op":"mcm","clk":"1001498844","pt":1580637055075,"mc":[{"id":"1.168224344","rc":[{"batb":[[0,2.86,10.46],[1,1.01,15.52],[2,2.86,0]],"batl":[[0,4.6,136.05],[1,4.6,0]],"ltp":3.1,"tv":0.0,"id":6498878},{"batb":[[0,1.4,49.96],[1,1.01,15.51],[2,1.4,0]],"batl":[[0,1.77,500.61],[1,1.77,0]],"ltp":1.48,"tv":0.01,"id":8174333}]}]}
{"op":"mcm","clk":"1001500717","pt":1580637093321,"mc":[{"id":"1.168224344","rc":[{"batb":[[1,2.76,11.41],[2,1.01,15.52]],"ltp":3.1,"tv":0.0,"id":6498878},{"batb":[[0,1.47,41.23],[1,1.43,45.24],[2,1.01,15.51]],"ltp":1.48,"tv":0.01,"id":8174333}]}]}
{"op":"mcm","clk":"1001500756","pt":1580637094144,"mc":[{"id":"1.168224344","rc":[{"batb":[[1,2.84,22.69],[2,2.76,11.41]],"batl":[[0,3.3,17.64]],"ltp":3.1,"tv":0.0,"id":6498878},{"batb":[[1,1.43,142.7]],"batl":[[0,1.54,42.01],[1,1.77,500.61]],"ltp":1.48,"tv":0.01,"id":8174333}]}]}
{"op":"mcm","clk":"1001500853","pt":1580637095833,"mc":[{"id":"1.168224344","rc":[{"batl":[[1,4.2,148.03]],"ltp":3.1,"tv":0.0,"id":6498878}]}]}
{"op":"mcm","clk":"1001501804","pt":1580637115068,"mc":[{"id":"1.168224344","rc":[{"batb":[[0,2.76,11.41],[1,1.01,15.52],[2,2.76,0]],"batl":[[0,4.2,148.03],[1,4.2,0]],"ltp":3.1,"tv":0.0,"id":6498878},{"batb":[[0,1.43,45.24],[1,1.01,15.51],[2,1.01,0]],"batl":[[0,1.77,500.61],[1,1.77,0]],"ltp":1.48,"tv":0.01,"id":8174333}]}]}
{"op":"mcm","clk":"1001501963","pt":1580637117998,"mc":[{"id":"1.168224344","rc":[{"batb":[[0,2.78,11.33]],"ltp":3.1,"tv":0.0,"id":6498878}]}]}
{"op":"mcm","clk":"1001502363","pt":1580637125413,"mc":[{"id":"1.168224344","rc":[{"batb":[[1,2.7,12.04],[2,1.01,15.52]],"ltp":3.1,"tv":0.0,"id":6498878},{"batb":[[0,1.49,38.79],[1,1.46,42.17],[2,1.01,15.51]],"ltp":1.48,"tv":0.01,"id":8174333}]}]}
{"op":"mcm","clk":"1001502406","pt":1580637126393,"mc":[{"id":"1.168224344","rc":[{"batb":[[0,2.8,22.69],[1,2.78,11.33],[2,2.7,12.04]],"batl":[[0,3.25,18.48],[1,4.2,148.03]],"ltp":3.1,"tv":0.0,"id":6498878},{"batb":[[2,1.44,94.94]],"batl":[[0,1.55,42.01],[1,1.77,500.61]],"ltp":1.48,"tv":0.01,"id":8174333}]}]}
{"op":"mcm","clk":"1001503398","pt":1580637143311,"mc":[{"id":"1.168224344","rc":[{"batb":[[1,2.7,12.04],[2,1.01,15.52]],"ltp":3.1,"tv":0.0,"id":6498878},{"batb":[[0,1.46,42.17],[1,1.44,94.94],[2,1.01,15.51]],"ltp":1.48,"tv":0.01,"id":8174333}]}]}
{"op":"mcm","clk":"1001503512","pt":1580637145126,"mc":[{"id":"1.168224344","rc":[{"batb":[[0,2.7,12.04],[1,1.01,15.52],[2,1.01,0]],"batl":[[0,4.2,148.03],[1,4.2,0]],"ltp":3.1,"tv":0.0,"id":6498878},{"batb":[[1,1.01,15.51],[2,1.01,0]],"batl":[[0,1.77,500.61],[1,1.77,0]],"ltp":1.48,"tv":0.01,"id":8174333}]}]}
{"op":"mcm","clk":"1001503868","pt":1580637150931,"mc":[{"id":"1.168224344","rc":[{"batb":[[1,2.6,13.3],[2,1.01,15.52]],"ltp":3.1,"tv":0.0,"id":6498878},{"batb":[[0,1.51,36.82],[1,1.49,38.63],[2,1.01,15.51]],"ltp":1.48,"tv":0.01,"id":8174333}]}]}
{"op":"mcm","clk":"1001503925","pt":1580637152128,"mc":[{"id":"1.168224344","rc":[{"batb":[[0,2.72,24.37],[1,2.7,12.04],[2,2.6,13.3]],"batl":[[0,3.15,19.32]],"ltp":3.1,"tv":0.0,"id":6498878},{"batb":[[2,1.47,89.06]],"batl":[[0,1.58,42.01]],"ltp":1.48,"tv":0.01,"id":8174333}]}]}
{"op":"mcm","clk":"1001503981","pt":1580637153362,"mc":[{"id":"1.168224344","rc":[{"batl":[[1,3.9,158.24]],"ltp":3.1,"tv":0.0,"id":6498878},{"batl":[[1,1.95,409.86]],"ltp":1.48,"tv":0.01,"id":8174333}]}]}
{"op":"mcm","clk":"1001505231","pt":1580637175153,"mc":[{"id":"1.168224344","rc":[{"batb":[[0,2.6,13.3],[1,1.01,15.52],[2,2.6,0]],"batl":[[0,3.9,158.24],[1,3.9,0]],"ltp":3.1,"tv":0.0,"id":6498878},{"batb":[[0,1.49,38.63],[1,1.01,15.51],[2,1.47,0]],"batl":[[0,1.95,409.86],[1,1.95,0]],"ltp":1.48,"tv":0.01,"id":8174333}]}]}
{"op":"mcm","clk":"1001506748","pt":1580637201326,"mc":[{"id":"1.168224344","rc":[{"batb":[[0,2.76,11.33],[1,2.66,12.67],[2,1.01,15.52]],"ltp":3.1,"tv":0.0,"id":6498878},{"batb":[[1,1.47,40.84],[2,1.01,15.51]],"ltp":1.48,"tv":0.01,"id":8174333}]}]}
{"op":"mcm","clk":"1001506799","pt":1580637202254,"mc":[{"id":"1.168224344","rc":[{"batb":[[0,2.76,34.86]],"batl":[[0,3.2,18.48],[1,3.9,158.24]],"ltp":3.1,"tv":0.0,"id":6498878},{"batb":[[2,1.45,93.26]],"batl":[[0,1.57,42.01],[1,1.95,409.86]],"ltp":1.48,"tv":0.01,"id":8174333}]}]}
{"op":"mcm","clk":"1001507461","pt":1580637215769,"mc":[{"id":"1.168224344","rc":[{"batb":[[0,2.76,23.53]],"ltp":3.1,"tv":0.0,"id":6498878},{"batb":[[0,1.47,40.84],[1,1.45,93.26],[2,1.01,15.51]],"ltp":1.48,"tv":0.01,"id":8174333}]}]}
{"op":"mcm","clk":"1001507547","pt":1580637217160,"mc":[{"id":"1.168224344","rc":[{"batb":[[0,2.66,12.67],[1,1.01,15.52],[2,1.01,0]],"batl":[[0,3.9,158.24],[1,3.9,0]],"ltp":3.1,"tv":0.0,"id":6498878},{"batb":[[1,1.01,15.51],[2,1.01,0]],"batl":[[0,1.95,409.86],[1,1.95,0]],"ltp":1.48,"tv":0.01,"id":8174333}]}]}
{"op":"mcm","clk":"1001508266","pt":1580637231367,"mc":[{"id":"1.168224344","rc":[{"batb":[[1,2.54,14.16],[2,1.01,15.52]],"ltp":3.1,"tv":0.0,"id":6498878},{"batb":[[0,1.52,35.33],[1,1.5,37.77],[2,1.47,40.84]],"ltp":1.48,"tv":0.01,"id":8174333}]}]}
{"op":"mcm","clk":"1001508298","pt":1580637232189,"mc":[{"id":"1.168224344","rc":[{"batb":[[0,2.68,24.37],[1,2.66,12.67],[2,2.54,14.16]],"batl":[[0,3.1,19.32],[1,3.9,158.24]],"ltp":3.1,"tv":0.0,"id":6498878},{"batb":[[2,1.48,87.38]],"batl":[[0,1.59,42.01],[1,1.95,409.86]],"ltp":1.48,"tv":0.01,"id":8174333}]}]}
{"op":"mcm","clk":"1001509017","pt":1580637245989,"mc":[{"id":"1.168224344","rc":[{"batb":[[1,2.54,14.16],[2,1.01,15.52]],"ltp":3.1,"tv":0.0,"id":6498878},{"batb":[[0,1.5,37.77],[1,1.48,87.38],[2,1.01,15.51]],"ltp":1.48,"tv":0.01,"id":8174333}]}]}
{"op":"mcm","clk":"1001509092","pt":1580637247216,"mc":[{"id":"1.168224344","rc":[{"batb":[[0,2.54,14.16],[1,1.01,15.52],[2,1.01,0]],"batl":[[0,3.9,158.24],[1,3.9,0]],"ltp":3.1,"tv":0.0,"id":6498878},{"batb":[[1,1.01,15.51],[2,1.01,0]],"batl":[[0,1.95,409.86],[1,1.95,0]],"ltp":1.48,"tv":0.01,"id":8174333}]}]}
{"op":"mcm","clk":"1001509170","pt":1580637248914,"mc":[{"id":"1.168224344","rc":[{"batb":[[0,2.58,13.69]],"ltp":3.1,"tv":0.0,"id":6498878},{"batb":[[0,1.49,38.63]],"ltp":1.48,"tv":0.01,"id":8174333}]}]}
{"op":"mcm","clk":"1001510666","pt":1580637278330,"mc":[{"id":"1.168224344","rc":[{"batb":[[0,2.62,25.21],[1,2.58,13.69],[2,1.01,15.52]],"batl":[[0,3,21]],"ltp":3.1,"tv":0.0,"id":6498878},{"batb":[[0,1.5,84.02],[1,1.49,38.63],[2,1.01,15.51]],"batl":[[0,1.62,42.01],[1,1.95,409.86]],"ltp":1.48,"tv":0.01,"id":8174333}]}]}
{"op":"mcm","clk":"1001510718","pt":1580637279358,"mc":[{"id":"1.168224344","rc":[{"batb":[[2,2.46,15.42]],"ltp":3.1,"tv":0.0,"id":6498878},{"batb":[[0,1.55,33.05],[1,1.53,35.17],[2,1.5,84.02]],"ltp":1.48,"tv":0.01,"id":8174333}]}]}
{"op":"mcm","clk":"1001510809","pt":1580637281258,"mc":[{"id":"1.168224344","rc":[{"batl":[[1,3.65,170.41]],"ltp":3.1,"tv":0.0,"id":6498878}]}]}
{"op":"mcm","clk":"1001511649","pt":1580637298008,"mc":[{"id":"1.168224344","rc":[{"batb":[[1,2.46,15.42],[2,1.01,15.52]],"ltp":3.1,"tv":0.0,"id":6498878},{"batb":[[0,1.53,35.17],[1,1.5,84.02],[2,1.01,15.51]],"ltp":1.48,"tv":0.01,"id":8174333}]}]}
{"op":"mcm","clk":"1001511705","pt":1580637299299,"mc":[{"id":"1.168224344","rc":[{"batb":[[0,2.46,15.42],[1,1.01,15.52],[2,1.01,0]],"batl":[[0,3.65,170.41],[1,3.65,0]],"ltp":3.1,"tv":0.0,"id":6498878},{"batb":[[1,1.01,15.51],[2,1.01,0]],"batl":[[0,1.95,409.86],[1,1.95,0]],"ltp":1.48,"tv":0.01,"id":8174333}]}]}
{"op":"mcm","clk":"1001512360","pt":1580637310415,"mc":[{"id":"1.168224344","rc":[{"batb":[[0,2.52,26.89],[1,2.46,15.42],[2,2.36,17.31]],"batl":[[0,2.92,21.85]],"ltp":3.1,"tv":0.0,"id":6498878},{"batb":[[0,1.59,29.82],[1,1.57,31.87],[2,1.53,114.15]],"batl":[[0,1.66,42.01],[1,1.95,409.86]],"ltp":1.48,"tv":0.01,"id":8174333}]}]}
{"op":"mcm","clk":"1001512376","pt":1580637310628,"mc":[{"id":"1.168224344","rc":[{"batb":[[2,1.53,78.98]],"ltp":1.48,"tv":0.01,"id":8174333}]}]}
{"op":"mcm","clk":"1001512497","pt":1580637312226,"mc":[{"id":"1.168224344","rc":[{"batl":[[0,3.45,180.4]],"ltp":3.1,"tv":0.0,"id":6498878}]}]}
{"op":"mcm","clk":"1001512545","pt":1580637312804,"mc":[{"id":"1.168224344","rc":[{"batl":[[0,2.9,21.85],[1,3.45,180.4]],"ltp":3.1,"tv":0.0,"id":6498878}]}]}
{"op":"mcm","clk":"1001513333","pt":1580637329320,"mc":[{"id":"1.168224344","rc":[{"batb":[[0,2.36,17.31],[1,1.01,15.52],[2,2.36,0]],"batl":[[0,3.45,180.4],[1,3.45,0]],"ltp":3.1,"tv":0.0,"id":6498878},{"batb":[[0,1.57,31.87],[1,1.01,15.51],[2,1.53,0]],"batl":[[0,1.95,409.86],[1,1.95,0]],"ltp":1.48,"tv":0.01,"id":8174333}]}]}
{"op":"mcm","clk":"1001514545","pt":1580637354271,"mc":[{"id":"1.168224344","rc":[{"batb":[[0,2.36,47.56]],"batl":[[0,2.68,24.37]],"ltp":3.1,"tv":0.0,"id":6498878},{"batb":[[0,1.59,70.58],[1,1.57,31.87],[2,1.01,15.51]],"batl":[[0,1.74,42.01]],"ltp":1.48,"tv":0.01,"id":8174333}]}]}
{"op":"mcm","clk":"1001514574","pt":1580637354790,"mc":[{"id":"1.168224344","rc":[{"batb":[[0,2.36,17.31],[1,2.34,31.09],[2,2.3,18.65]],"batl":[[0,2.66,25.21]],"ltp":3.1,"tv":0.0,"id":6498878},{"batb":[[0,1.64,26.99],[1,1.6,99.08]],"ltp":1.48,"tv":0.01,"id":8174333}]}]}
{"op":"mcm","clk":"1001514701","pt":1580637357071,"mc":[{"id":"1.168224344","rc":[{"batl":[[1,3.3,191.92]],"ltp":3.1,"tv":0.0,"id":6498878},{"batl":[[1,2.16,342.82]],"ltp":1.48,"tv":0.01,"id":8174333}]}]}
{"op":"mcm","clk":"1001520759","pt":1580637447317,"mc":[{"id":"1.168224344","rc":[{"batb":[[0,2.3,18.65],[1,1.01,15.52],[2,2.3,0]],"batl":[[0,3.3,191.92],[1,3.3,0]],"ltp":3.1,"tv":0.0,"id":6498878},{"batb":[[0,1.6,29.35],[1,1.01,15.51],[2,1.01,0]],"batl":[[0,2.16,342.82],[1,2.16,0]],"ltp":1.48,"tv":0.01,"id":8174333}]}]}
{"op":"mcm","clk":"1001522173","pt":1580637466326,"mc":[{"id":"1.168224344","rc":[{"batb":[[0,2.3,50.58]],"batl":[[0,2.62,25.21],[1,3.3,191.92]],"ltp":3.1,"tv":0.0,"id":6498878},{"batb":[[0,1.62,67.22],[1,1.6,29.35],[2,1.01,15.51]],"batl":[[0,1.77,42.01],[1,2.16,342.82]],"ltp":1.48,"tv":0.01,"id":8174333}]}]}
{"op":"mcm","clk":"1001522196","pt":1580637466840,"mc":[{"id":"1.168224344","rc":[{"batb":[[1,2.26,19.83],[2,1.01,15.52]],"ltp":3.1,"tv":0.0,"id":6498878},{"batb":[[0,1.67,25.34],[1,1.63,27.54],[2,1.62,67.22]],"ltp":1.48,"tv":0.01,"id":8174333}]}]}
{"op":"mcm","clk":"1001522780","pt":1580637476328,"mc":[{"id":"1.168224344","rc":[{"batb":[[0,2.3,31.93]],"ltp":3.1,"tv":0.0,"id":6498878},{"batb":[[0,1.63,27.54],[1,1.62,67.22],[2,1.01,15.51]],"ltp":1.48,"tv":0.01,"id":8174333}]}]}
{"op":"mcm","clk":"1001522838","pt":1580637477353,"mc":[{"id":"1.168224344","rc":[{"batb":[[0,2.26,19.83],[1,1.01,15.52],[2,1.01,0]],"batl":[[0,3.3,191.92],[1,3.3,0]],"ltp":3.1,"tv":0.0,"id":6498878},{"batb":[[1,1.01,15.51],[2,1.01,0]],"batl":[[0,2.16,342.82],[1,2.16,0]],"ltp":1.48,"tv":0.01,"id":8174333}]}]}
{"op":"mcm","clk":"1001523827","pt":1580637494377,"mc":[{"id":"1.168224344","rc":[{"batb":[[0,2.26,52.6],[1,2.2,20.93],[2,1.01,15.52]],"batl":[[0,2.58,26.05],[1,3.3,191.92]],"ltp":3.1,"tv":0.0,"id":6498878},{"batb":[[0,1.7,23.92],[1,1.66,25.81],[2,1.64,65.54]],"batl":[[0,1.79,42.01],[1,2.16,342.82]],"ltp":1.48,"tv":0.01,"id":8174333}]}]}
{"op":"mcm","clk":"1001524718","pt":1580637511266,"mc":[{"id":"1.168224344","rc":[{"batb":[[0,2.2,20.93],[1,1.01,15.52],[2,1.01,0]],"batl":[[0,3.3,191.92],[1,3.3,0]],"ltp":3.1,"tv":0.0,"id":6498878},{"batb":[[0,1.66,25.81],[1,1.01,15.51],[2,1.64,0]],"batl":[[0,2.16,342.82],[1,2.16,0]],"ltp":1.48,"tv":0.01,"id":8174333}]}]}
{"op":"mcm","clk":"1001525745","pt":1580637528322,"mc":[{"id":"1.168224344","rc":[{"batb":[[0,2.32,31.09],[1,2.2,20.93],[2,1.01,15.52]],"batl":[[0,2.64,25.21],[1,3.3,191.92]],"ltp":3.1,"tv":0.0,"id":6498878},{"batb":[[1,1.62,67.22],[2,1.01,15.51]],"batl":[[0,1.76,42.01],[1,2.16,342.82]],"ltp":1.48,"tv":0.01,"id":8174333}]}]}
{"op":"mcm","clk":"1001525763","pt":1580637528685,"mc":[{"id":"1.168224344","rc":[{"batb":[[0,2.32,49.34],[1,2.26,19.43]],"ltp":3.1,"tv":0.0,"id":6498878},{"batb":[[1,1.62,95.46]],"ltp":1.48,"tv":0.01,"id":8174333}]}]}
{"op":"mcm","clk":"1001526826","pt":1580637546216,"mc":[{"id":"1.168224344","rc":[{"batb":[[0,2.32,31.09]],"ltp":3.1,"tv":0.0,"id":6498878},{"batb":[[0,1.62,95.46],[1,1.01,15.51],[2,1.01,0]],"ltp":1.48,"tv":0.01,"id":8174333}]}]}
{"op":"mcm","clk":"1001526895","pt":1580637547714,"mc":[{"id":"1.168224344","rc":[{"batb":[[0,2.26,19.43],[1,1.01,15.52],[2,1.01,0]],"batl":[[0,3.3,191.92],[1,3.3,0]],"ltp":3.1,"tv":0.0,"id":6498878},{"batb":[[0,1.62,28.25]],"batl":[[0,2.16,342.82],[1,2.16,0]],"ltp":1.48,"tv":0.01,"id":8174333}]}]}
{"op":"mcm","clk":"1001527745","pt":1580637562369,"mc":[{"id":"1.168224344","rc":[{"batb":[[0,2.28,32.77],[1,2.26,19.43],[2,2.22,20.69]],"batl":[[0,2.6,26.05],[1,3.3,191.92]],"ltp":3.1,"tv":0.0,"id":6498878},{"batb":[[0,1.69,24.39],[1,1.65,26.44],[2,1.63,66.38]],"batl":[[0,1.78,42.01],[1,2.16,342.82]],"ltp":1.48,"tv":0.01,"id":8174333}]}]}
{"op":"mcm","clk":"1001529346","pt":1580637583359,"mc":[{"id":"1.168224344","rc":[{"batb":[[0,2.22,20.69],[1,1.01,15.52],[2,2.22,0]],"batl":[[0,3.3,191.92],[1,3.3,0]],"ltp":3.1,"tv":0.0,"id":6498878},{"batb":[[0,1.65,26.44],[1,1.01,15.51],[2,1.63,0]],"batl":[[0,2.16,342.82],[1,2.16,0]],"ltp":1.48,"tv":0.01,"id":8174333}]}]}
{"op":"mcm","clk":"1001529837","pt":1580637590374,"mc":[{"id":"1.168224344","rc":[{"batb":[[0,2.22,54.3]],"batl":[[0,2.54,26.89],[1,3.3,191.92]],"ltp":3.1,"tv":0.0,"id":6498878},{"batb":[[0,1.66,63.01],[1,1.65,26.44],[2,1.01,15.51]],"batl":[[0,1.82,42.01],[1,2.16,342.82]],"ltp":1.48,"tv":0.01,"id":8174333}]}]}
{"op":"mcm","clk":"1001529894","pt":1580637591301,"mc":[{"id":"1.168224344","rc":[{"batb":[[0,2.22,20.69],[1,2.14,23.05],[2,1.01,15.52]],"ltp":3.1,"tv":0.0,"id":6498878},{"batb":[[0,1.71,23.05],[1,1.68,24.63],[2,1.66,63.01]],"batl":[[0,2.16,342.82],[1,2.16,0]],"ltp":1.48,"tv":0.01,"id":8174333}]}]}
{"op":"mcm","clk":"1001529952","pt":1580637592385,"mc":[{"id":"1.168224344","rc":[{"batb":[[0,2.24,33.61],[1,2.22,20.69],[2,2.14,23.05]],"ltp":3.1,"tv":0.0,"id":6498878},{"batl":[[0,1.81,42.01],[1,2.16,342.82]],"ltp":1.48,"tv":0.01,"id":8174333}]}]}
{"op":"mcm","clk":"1001531583","pt":1580637612216,"mc":[{"id":"1.168224344","rc":[{"batb":[[1,2.14,23.05],[2,1.01,15.52]],"ltp":3.1,"tv":0.0,"id":6498878},{"batb":[[0,1.68,24.63],[1,1.66,63.01],[2,1.01,15.51]],"ltp":1.48,"tv":0.01,"id":8174333}]}]}
{"op":"mcm","clk":"1001531677","pt":1580637613411,"mc":[{"id":"1.168224344","rc":[{"batb":[[0,2.14,23.05],[1,1.01,15.52],[2,1.01,0]],"batl":[[0,3.3,191.92],[1,3.3,0]],"ltp":3.1,"tv":0.0,"id":6498878},{"batb":[[1,1.01,15.51],[2,1.01,0]],"batl":[[0,2.16,342.82],[1,2.16,0]],"ltp":1.48,"tv":0.01,"id":8174333}]}]}
{"op":"mcm","clk":"1001532625","pt":1580637626412,"mc":[{"id":"1.168224344","rc":[{"batb":[[0,2.26,32.77],[1,2.14,23.05],[2,1.01,15.52]],"batl":[[0,2.56,26.89],[1,3.3,191.92]],"ltp":3.1,"tv":0.0,"id":6498878},{"batb":[[1,1.65,63.85],[2,1.01,15.51]],"batl":[[0,1.8,42.01],[1,2.16,342.82]],"ltp":1.48,"tv":0.01,"id":8174333}]}]}
{"op":"mcm","clk":"1001532667","pt":1580637626821,"mc":[{"id":"1.168224344","rc":[{"batb":[[0,2.28,19.28],[1,2.26,32.77],[2,2.2,21.48]],"ltp":3.1,"tv":0.0,"id":6498878},{"batb":[[1,1.66,25.89],[2,1.65,63.85]],"ltp":1.48,"tv":0.01,"id":8174333}]}]}
{"op":"mcm","clk":"1001533536","pt":1580637638043,"mc":[{"id":"1.168224344","rc":[{"batb":[[0,2.26,32.77],[1,2.2,21.48],[2,1.01,15.52]],"ltp":3.1,"tv":0.0,"id":6498878},{"batb":[[0,1.66,25.89],[1,1.65,63.85],[2,1.01,15.51]],"ltp":1.48,"tv":0.01,"id":8174333}]}]}
{"op":"mcm","clk":"1001533671","pt":1580637639546,"mc":[{"id":"1.168224344","rc":[{"batb":[[0,2.2,21.48],[1,1.01,15.52],[2,1.01,0]],"batl":[[0,3.3,191.92],[1,3.3,0]],"ltp":3.1,"tv":0.0,"id":6498878},{"batb":[[1,1.01,15.51],[2,1.01,0]],"batl":[[0,2.16,342.82],[1,2.16,0]],"ltp":1.48,"tv":0.01,"id":8174333}]}]}
{"op":"mcm","clk":"1001534323","pt":1580637648220,"mc":[{"id":"1.168224344","rc":[{"batb":[[0,2.32,18.18],[1,2.24,20.06],[2,2.2,21.48]],"ltp":3.1,"tv":0.0,"id":6498878},{"batb":[[1,1.63,27.38],[2,1.01,15.51]],"ltp":1.48,"tv":0.01,"id":8174333}]}]}
{"op":"mcm","clk":"1001534340","pt":1580637648533,"mc":[{"id":"1.168224344","rc":[{"batb":[[1,2.28,32.77],[2,2.24,20.06]],"batl":[[0,2.6,26.05],[1,3.3,191.92]],"ltp":3.1,"tv":0.0,"id":6498878},{"batb":[[1,1.63,93.76]],"batl":[[0,1.78,42.01],[1,2.16,342.82]],"ltp":1.48,"tv":0.01,"id":8174333}]}]}
{"op":"mcm","clk":"1001534974","pt":1580637657141,"mc":[{"id":"1.168224344","rc":[{"batb":[[0,2.28,32.77],[1,2.24,20.06],[2,1.01,15.52]],"ltp":3.1,"tv":0.0,"id":6498878},{"batb":[[0,1.63,93.76],[1,1.01,15.51],[2,1.01,0]],"ltp":1.48,"tv":0.01,"id":8174333}]}]}
{"op":"mcm","clk":"1001535009","pt":1580637657512,"mc":[{"id":"1.168224344","rc":[{"batb":[[0,2.24,20.06],[1,1.01,15.52],[2,1.01,0]],"batl":[[0,3.3,191.92],[1,3.3,0]],"ltp":3.1,"tv":0.0,"id":6498878},{"batb":[[0,1.63,27.38]],"batl":[[0,2.16,342.82],[1,2.16,0]],"ltp":1.48,"tv":0.01,"id":8174333}]}]}
{"op":"mcm","clk":"1001535579","pt":1580637663332,"mc":[{"id":"1.168224344","rc":[{"batb":[[0,2.38,17.07],[1,2.3,18.73],[2,2.24,20.06]],"ltp":3.1,"tv":0.0,"id":6498878},{"batb":[[1,1.61,29.03],[2,1.01,15.51]],"ltp":1.48,"tv":0.01,"id":8174333}]}]}
{"op":"mcm","clk":"1001535670","pt":1580637664414,"mc":[{"id":"1.168224344","rc":[{"batb":[[2,1.01,15.52]],"ltp":3.1,"tv":0.0,"id":6498878}]}]}
{"op":"mcm","clk":"1001535772","pt":1580637665353,"mc":[{"id":"1.168224344","rc":[{"batb":[[1,2.32,31.09],[2,2.3,18.73]],"batl":[[0,2.64,25.21],[1,3.3,191.92]],"ltp":3.1,"tv":0.0,"id":6498878},{"batb":[[1,1.61,97.09]],"batl":[[0,1.76,42.01],[1,2.16,342.82]],"ltp":1.48,"tv":0.01,"id":8174333}]}]}
{"op":"mcm","clk":"1001536224","pt":1580637671325,"mc":[{"id":"1.168224344","rc":[{"batb":[[0,2.32,31.09],[1,2.3,18.73],[2,1.01,15.52]],"ltp":3.1,"tv":0.0,"id":6498878},{"batb":[[0,1.61,97.09],[1,1.01,15.51],[2,1.01,0]],"ltp":1.48,"tv":0.01,"id":8174333}]}]}
{"op":"mcm","clk":"1001536247","pt":1580637671536,"mc":[{"id":"1.168224344","rc":[{"batb":[[0,2.3,18.73],[1,1.01,15.52],[2,1.01,0]],"batl":[[0,3.3,191.92],[1,3.3,0]],"ltp":3.1,"tv":0.0,"id":6498878},{"batb":[[0,1.61,29.03]],"batl":[[0,2.16,342.82],[1,2.16,0]],"ltp":1.48,"tv":0.01,"id":8174333}]}]}
{"op":"mcm","clk":"1001536829","pt":1580637679265,"mc":[{"id":"1.168224344","rc":[{"batb":[[0,2.44,15.97],[1,2.38,30.25],[2,2.36,17.31]],"batl":[[0,2.72,24.37],[1,3.3,191.92]],"ltp":3.1,"tv":0.0,"id":6498878},{"batb":[[1,1.59,70.58],[2,1.57,31.79]],"batl":[[0,1.73,42.01],[1,2.16,342.82]],"ltp":1.48,"tv":0.01,"id":8174333}]}]}
{"op":"mcm","clk":"1001543901","pt":1580637762158,"mc":[{"id":"1.168224344","rc":[{"batb":[[0,2.38,30.25],[1,2.36,17.31],[2,1.01,15.52]],"ltp":3.1,"tv":0.0,"id":6498878},{"batb":[[0,1.59,70.58],[1,1.57,31.79],[2,1.01,15.51]],"ltp":1.48,"tv":0.01,"id":8174333}]}]}
{"op":"mcm","clk":"1001544042","pt":1580637763599,"mc":[{"id":"1.168224344","rc":[{"batb":[[0,2.36,17.31],[1,1.01,15.52],[2,1.01,0]],"batl":[[0,3.3,191.92],[1,3.3,0]],"ltp":3.1,"tv":0.0,"id":6498878},{"batb":[[0,1.57,31.79],[1,1.01,15.51],[2,1.01,0]],"batl":[[0,2.16,342.82],[1,2.16,0]],"ltp":1.48,"tv":0.01,"id":8174333}]}]}
{"op":"mcm","clk":"1001545582","pt":1580637782372,"mc":[{"id":"1.168224344","rc":[{"batb":[[0,2.54,14.4],[1,2.46,15.58],[2,1.01,15.52]],"ltp":3.1,"tv":0.0,"id":6498878},{"batb":[[1,1.52,35.33],[2,1.01,15.51]],"ltp":1.48,"tv":0.01,"id":8174333}]}]}
{"op":"mcm","clk":"1001545602","pt":1580637782580,"mc":[{"id":"1.168224344","rc":[{"batb":[[1,2.46,44.15]],"batl":[[0,2.78,23.53]],"ltp":3.1,"tv":0.0,"id":6498878},{"batb":[[0,1.57,104.88]],"batl":[[0,1.7,42.01]],"ltp":1.48,"tv":0.01,"id":8174333}]}]}
{"op":"mcm","clk":"1001545845","pt":1580637785288,"mc":[{"id":"1.168224344","rc":[{"batl":[[1,3.65,170.41]],"ltp":3.1,"tv":0.0,"id":6498878},{"batl":[[1,2.04,383.01]],"ltp":1.48,"tv":0.01,"id":8174333}]}]}
{"op":"mcm","clk":"1001546950","pt":1580637797586,"mc":[{"id":"1.168224344","rc":[{"batb":[[0,2.46,15.58],[1,1.01,15.52],[2,1.01,0]],"batl":[[0,3.65,170.41],[1,3.65,0]],"ltp":3.1,"tv":0.0,"id":6498878},{"batb":[[0,1.52,35.33],[1,1.01,15.51],[2,1.01,0]],"batl":[[0,2.04,383.01],[1,2.04,0]],"ltp":1.48,"tv":0.01,"id":8174333}]}]}
{"op":"mcm","clk":"1001547648","pt":1580637807330,"mc":[{"id":"1.168224344","rc":[{"batb":[[0,2.66,12.67],[1,2.58,13.77],[2,2.5,27.73]],"batl":[[0,2.86,21.85],[1,3.65,170.41]],"ltp":3.1,"tv":0.0,"id":6498878},{"batb":[[0,1.54,77.3],[1,1.52,35.33],[2,1.48,39.42]],"batl":[[0,1.68,42.01],[1,2.04,383.01]],"ltp":1.48,"tv":0.01,"id":8174333}]}]}
{"op":"mcm","clk":"1001549090","pt":1580637824549,"mc":[{"id":"1.168224344","rc":[{"batb":[[0,2.58,13.77],[1,2.5,27.73],[2,1.01,15.52]],"ltp":3.1,"tv":0.0,"id":6498878},{"batb":[[1,1.48,39.42],[2,1.01,15.51]],"ltp":1.48,"tv":0.01,"id":8174333}]}]}
{"op":"mcm","clk":"1001549185","pt":1580637825662,"mc":[{"id":"1.168224344","rc":[{"batb":[[1,1.01,15.52],[2,1.01,0]],"batl":[[0,3.65,170.41],[1,3.65,0]],"ltp":3.1,"tv":0.0,"id":6498878},{"batb":[[0,1.48,39.42],[1,1.01,15.51],[2,1.01,0]],"batl":[[0,2.04,383.01],[1,2.04,0]],"ltp":1.48,"tv":0.01,"id":8174333}]}]}
{"op":"mcm","clk":"1001549848","pt":1580637833360,"mc":[{"id":"1.168224344","rc":[{"batb":[[0,2.8,11.09],[1,2.7,12.2],[2,2.6,445.29]],"ltp":3.1,"tv":0.0,"id":6498878},{"batb":[[1,1.45,43.59],[2,1.01,15.51]],"ltp":1.48,"tv":0.01,"id":8174333}]}]}
{"op":"mcm","clk":"1001549866","pt":1580637833571,"mc":[{"id":"1.168224344","rc":[{"batb":[[2,1.01,15.52]],"ltp":3.1,"tv":0.0,"id":6498878}]}]}
{"op":"mcm","clk":"1001549972","pt":1580637834865,"mc":[{"id":"1.168224344","rc":[{"batb":[[2,2.56,26.89]],"batl":[[0,2.92,21.85],[1,3.65,170.41]],"ltp":3.1,"tv":0.0,"id":6498878},{"batb":[[0,1.52,80.66],[1,1.48,39.42],[2,1.45,43.59]],"batl":[[0,1.66,42.01],[1,2.04,383.01]],"ltp":1.48,"tv":0.01,"id":8174333}]}]}
{"op":"mcm","clk":"1001550826","pt":1580637844359,"mc":[{"id":"1.168224344","rc":[{"batb":[[0,2.7,12.2],[1,2.56,26.89],[2,1.01,15.52]],"ltp":3.1,"tv":0.0,"id":6498878},{"batb":[[1,1.45,43.59],[2,1.01,15.51]],"ltp":1.48,"tv":0.01,"id":8174333}]}]}
{"op":"mcm","clk":"1001550971","pt":1580637846066,"mc":[{"id":"1.168224344","rc":[{"batb":[[1,1.01,15.52],[2,1.01,0]],"batl":[[0,3.65,170.41],[1,3.65,0]],"ltp":3.1,"tv":0.0,"id":6498878},{"batb":[[0,1.45,43.59],[1,1.01,15.51],[2,1.01,0]],"batl":[[0,2.04,383.01],[1,2.04,0]],"ltp":1.48,"tv":0.01,"id":8174333}]}]}
{"op":"mcm","clk":"1001552599","pt":1580637864285,"mc":[{"id":"1.168224344","rc":[{"batb":[[1,2.6,13.38],[2,1.01,15.52]],"ltp":3.1,"tv":0.0,"id":6498878},{"batb":[[0,1.51,36.51],[1,1.47,40.76],[2,1.01,15.51]],"ltp":1.48,"tv":0.01,"id":8174333}]}]}
{"op":"mcm","clk":"1001552664","pt":1580637864904,"mc":[{"id":"1.168224344","rc":[{"batb":[[2,2.52,26.89]],"batl":[[0,2.88,21.85],[1,3.65,170.41]],"ltp":3.1,"tv":0.0,"id":6498878},{"batb":[[0,1.53,78.98],[1,1.51,36.51],[2,1.47,40.76]],"batl":[[0,1.67,42.01],[1,2.04,383.01]],"ltp":1.48,"tv":0.01,"id":8174333}]}]}
{"op":"mcm","clk":"1001555068","pt":1580637892106,"mc":[{"id":"1.168224344","rc":[{"batb":[[0,2.6,13.38],[1,1.01,15.52],[2,2.52,0]],"batl":[[0,3.65,170.41],[1,3.65,0]],"ltp":3.1,"tv":0.0,"id":6498878},{"batb":[[0,1.47,40.76],[1,1.01,15.51],[2,1.47,0]],"batl":[[0,2.04,383.01],[1,2.04,0]],"ltp":1.48,"tv":0.01,"id":8174333}]}]}
{"op":"mcm","clk":"1001556475","pt":1580637907278,"mc":[{"id":"1.168224344","rc":[{"batb":[[1,2.5,27.73],[2,2.48,15.19]],"batl":[[0,2.84,22.69],[1,3.65,170.41]],"ltp":3.1,"tv":0.0,"id":6498878},{"batb":[[0,1.54,110.97],[1,1.49,38.24],[2,1.01,15.51]],"batl":[[0,1.67,42.01],[1,2.04,383.01]],"ltp":1.48,"tv":0.01,"id":8174333}]}]}
{"op":"mcm","clk":"1001558075","pt":1580637926831,"mc":[{"id":"1.168224344","rc":[{"batb":[[0,2.5,27.73],[1,2.48,15.19],[2,1.01,15.52]],"ltp":3.1,"tv":0.0,"id":6498878},{"batb":[[0,1.54,77.3]],"ltp":1.48,"tv":0.01,"id":8174333}]}]}
{"op":"mcm","clk":"1001558209","pt":1580637928333,"mc":[{"id":"1.168224344","rc":[{"batb":[[0,2.48,15.19],[1,1.01,15.52],[2,1.01,0]],"batl":[[0,3.65,170.41],[1,3.65,0]],"ltp":3.1,"tv":0.0,"id":6498878},{"batb":[[0,1.49,38.24],[1,1.01,15.51],[2,1.01,0]],"batl":[[0,2.04,383.01],[1,2.04,0]],"ltp":1.48,"tv":0.01,"id":8174333}]}]}
{"op":"mcm","clk":"1001561353","pt":1580637963827,"mc":[{"id":"1.168224344","rc":[{"batb":[[1,2.4,16.6],[2,1.01,15.52]],"ltp":3.1,"tv":0.0,"id":6498878},{"batb":[[0,1.59,30.21],[1,1.53,34.46],[2,1.01,15.51]],"ltp":1.48,"tv":0.01,"id":8174333}]}]}
{"op":"mcm","clk":"1001561473","pt":1580637965017,"mc":[{"id":"1.168224344","rc":[{"batb":[[1,2.46,28.57],[2,2.4,16.6]],"batl":[[0,2.8,22.69],[1,3.65,170.41]],"ltp":3.1,"tv":0.0,"id":6498878},{"batl":[[0,1.7,42.01],[1,2.04,383.01]],"ltp":1.48,"tv":0.01,"id":8174333}]}]}
{"op":"mcm","clk":"1001561603","pt":1580637966316,"mc":[{"id":"1.168224344","rc":[{"batb":[[1,1.56,74.78],[2,1.53,34.46]],"ltp":1.48,"tv":0.01,"id":8174333}]}]}
{"op":"mcm","clk":"1001563522","pt":1580637989149,"mc":[{"id":"1.168224344","rc":[{"batb":[[0,2.46,28.57],[1,2.4,16.6],[2,1.01,15.52]],"ltp":3.1,"tv":0.0,"id":6498878},{"batb":[[0,1.56,74.78],[1,1.53,34.46],[2,1.01,15.51]],"ltp":1.48,"tv":0.01,"id":8174333}]}]}
{"op":"mcm","clk":"1001563566","pt":1580637989723,"mc":[{"id":"1.168224344","rc":[{"batb":[[0,2.4,16.6],[1,1.01,15.52],[2,1.01,0]],"batl":[[0,3.65,170.41],[1,3.65,0]],"ltp":3.1,"tv":0.0,"id":6498878},{"batb":[[0,1.53,34.46],[1,1.01,15.51],[2,1.01,0]],"batl":[[0,2.04,383.01],[1,2.04,0]],"ltp":1.48,"tv":0.01,"id":8174333}]}]}
{"op":"mcm","clk":"1001563766","pt":1580637992232,"mc":[{"id":"1.168224344","rc":[{"batb":[[0,2.38,16.84]],"ltp":3.1,"tv":0.0,"id":6498878},{"batb":[[0,1.54,34.15]],"ltp":1.48,"tv":0.01,"id":8174333}]}]}
{"op":"mcm","clk":"1001564186","pt":1580637997140,"mc":[{"id":"1.168224344","rc":[{"batb":[[0,2.42,29.41],[1,2.38,16.84],[2,2.32,18.33]],"batl":[[0,2.76,23.53]],"ltp":3.1,"tv":0.0,"id":6498878},{"batb":[[0,1.63,27.7],[1,1.58,30.92],[2,1.57,73.1]],"batl":[[0,1.71,42.01],[1,2.04,383.01]],"ltp":1.48,"tv":0.01,"id":8174333}]}]}
{"op":"mcm","clk":"1001564374","pt":1580637999368,"mc":[{"id":"1.168224344","rc":[{"batl":[[1,3.45,180.4]],"ltp":3.1,"tv":0.0,"id":6498878}]}]}
{"op":"mcm","clk":"1001565439","pt":1580638011341,"mc":[{"id":"1.168224344","rc":[{"batb":[[1,2.32,18.33],[2,1.01,15.52]],"ltp":3.1,"tv":0.0,"id":6498878},{"batb":[[0,1.58,30.92],[1,1.57,73.1],[2,1.01,15.51]],"ltp":1.48,"tv":0.01,"id":8174333}]}]}
{"op":"mcm","clk":"1001565488","pt":1580638011860,"mc":[{"id":"1.168224344","rc":[{"batb":[[0,2.32,18.33],[1,1.01,15.52],[2,1.01,0]],"batl":[[0,3.45,180.4],[1,3.45,0]],"ltp":3.1,"tv":0.0,"id":6498878},{"batb":[[1,1.01,15.51],[2,1.01,0]],"batl":[[0,2.04,383.01],[1,2.04,0]],"ltp":1.48,"tv":0.01,"id":8174333}]}]}
{"op":"mcm","clk":"1001567415","pt":1580638033307,"mc":[{"id":"1.168224344","rc":[{"batb":[[0,2.5,14.79],[1,2.46,28.57],[2,2.42,16.44]],"batl":[[0,2.82,22.69],[1,3.45,180.4]],"ltp":3.1,"tv":0.0,"id":6498878},{"batb":[[1,1.56,74.78],[2,1.53,34.93]],"batl":[[0,1.69,42.01],[1,2.04,383.01]],"ltp":1.48,"tv":0.01,"id":8174333}]}]}
{"op":"mcm","clk":"1001568980","pt":1580638051851,"mc":[{"id":"1.168224344","rc":[{"batb":[[0,2.42,16.44],[1,1.01,15.52],[2,2.42,0]],"batl":[[0,3.45,180.4],[1,3.45,0]],"ltp":3.1,"tv":0.0,"id":6498878},{"batb":[[0,1.53,34.93],[1,1.01,15.51],[2,1.53,0]],"batl":[[0,2.04,383.01],[1,2.04,0]],"ltp":1.48,"tv":0.01,"id":8174333}]}]}
{"op":"mcm","clk":"1001570521","pt":1580638069260,"mc":[{"id":"1.168224344","rc":[{"batb":[[0,2.64,12.83],[1,2.52,14.71],[2,2.5,27.73]],"batl":[[0,2.88,21.85]],"ltp":3.1,"tv":0.0,"id":6498878},{"batb":[[0,1.54,77.3],[1,1.53,34.93],[2,1.47,40.21]],"batl":[[0,1.67,42.01],[1,2.04,383.01]],"ltp":1.48,"tv":0.01,"id":8174333}]}]}
{"op":"mcm","clk":"1001570730","pt":1580638071428,"mc":[{"id":"1.168224344","rc":[{"batl":[[1,3.9,158.24]],"ltp":3.1,"tv":0.0,"id":6498878}]}]}
{"op":"mcm","clk":"1001572190","pt":1580638089962,"mc":[{"id":"1.168224344","rc":[{"batb":[[0,2.52,14.71],[1,1.01,15.52],[2,2.5,0]],"batl":[[0,3.9,158.24],[1,3.9,0]],"ltp":3.1,"tv":0.0,"id":6498878},{"batb":[[0,1.47,40.21],[1,1.01,15.51],[2,1.47,0]],"batl":[[0,2.04,383.01],[1,2.04,0]],"ltp":1.48,"tv":0.01,"id":8174333}]}]}
{"op":"mcm","clk":"1001573430","pt":1580638104360,"mc":[{"id":"1.168224344","rc":[{"batb":[[0,2.82,10.78],[1,2.66,12.51],[2,1.01,15.52]],"ltp":3.1,"tv":0.0,"id":6498878},{"batb":[[1,1.46,42.41],[2,1.01,15.51]],"ltp":1.48,"tv":0.01,"id":8174333}]}]}
{"op":"mcm","clk":"1001573458","pt":1580638104671,"mc":[{"id":"1.168224344","rc":[{"batb":[[1,2.66,37.72]],"batl":[[0,3.1,19.32],[1,3.9,158.24]],"ltp":3.1,"tv":0.0,"id":6498878},{"batb":[[0,1.48,87.38],[1,1.47,40.21],[2,1.46,42.41]],"batl":[[0,1.6,42.01]],"ltp":1.48,"tv":0.01,"id":8174333}]}]}
{"op":"mcm","clk":"1001573559","pt":1580638105867,"mc":[{"id":"1.168224344","rc":[{"batl":[[1,1.89,435.28]],"ltp":1.48,"tv":0.01,"id":8174333}]}]}
{"op":"mcm","clk":"1001575530","pt":1580638129327,"mc":[{"id":"1.168224344","rc":[{"batb":[[0,2.66,37.72],[1,1.01,15.52],[2,1.01,0]],"ltp":3.1,"tv":0.0,"id":6498878},{"batb":[[1,1.46,42.41],[2,1.01,15.51]],"ltp":1.48,"tv":0.01,"id":8174333}]}]}
{"op":"mcm","clk":"1001575569","pt":1580638129743,"mc":[{"id":"1.168224344","rc":[{"batb":[[0,2.66,12.51]],"batl":[[0,3.9,158.24],[1,3.9,0]],"ltp":3.1,"tv":0.0,"id":6498878},{"batb":[[0,1.46,42.41],[1,1.01,15.51],[2,1.01,0]],"batl":[[0,1.89,435.28],[1,1.89,0]],"ltp":1.48,"tv":0.01,"id":8174333}]}]}
{"op":"mcm","clk":"1001577737","pt":1580638154364,"mc":[{"id":"1.168224344","rc":[{"batb":[[0,2.88,25.65],[1,2.76,11.57],[2,1.01,15.52]],"ltp":3.1,"tv":0.0,"id":6498878},{"batb":[[1,1.43,45.48],[2,1.01,15.51]],"ltp":1.48,"tv":0.01,"id":8174333}]}]}
{"op":"mcm","clk":"1001577797","pt":1580638155041,"mc":[{"id":"1.168224344","rc":[{"batb":[[2,2.74,23.53]],"batl":[[0,3.1,19.32],[1,3.9,158.24]],"ltp":3.1,"tv":0.0,"id":6498878},{"batb":[[0,1.47,89.06],[1,1.46,42.41],[2,1.43,45.48]],"batl":[[0,1.59,42.01],[1,1.89,435.28]],"ltp":1.48,"tv":0.01,"id":8174333}]}]}
{"op":"mcm","clk":"1001579404","pt":1580638172554,"mc":[{"id":"1.168224344","rc":[{"batb":[[0,2.76,11.57],[1,2.74,23.53],[2,1.01,15.52]],"ltp":3.1,"tv":0.0,"id":6498878},{"batb":[[1,1.43,45.48],[2,1.01,15.51]],"ltp":1.48,"tv":0.01,"id":8174333}]}]}
{"op":"mcm","clk":"1001579499","pt":1580638173765,"mc":[{"id":"1.168224344","rc":[{"batb":[[1,1.01,15.52],[2,1.01,0]],"batl":[[0,3.9,158.24],[1,3.9,0]],"ltp":3.1,"tv":0.0,"id":6498878},{"batb":[[0,1.43,45.48],[1,1.01,15.51],[2,1.01,0]],"batl":[[0,1.89,435.28],[1,1.89,0]],"ltp":1.48,"tv":0.01,"id":8174333}]}]}
{"op":"mcm","clk":"1001581117","pt":1580638192332,"mc":[{"id":"1.168224344","rc":[{"batb":[[1,2.62,13.22],[2,1.01,15.52]],"ltp":3.1,"tv":0.0,"id":6498878},{"batb":[[0,1.49,38.16],[1,1.47,41.23],[2,1.01,15.51]],"ltp":1.48,"tv":0.01,"id":8174333}]}]}
{"op":"mcm","clk":"1001581213","pt":1580638193324,"mc":[{"id":"1.168224344","rc":[{"batb":[[1,2.66,25.21],[2,2.62,13.22]],"batl":[[0,3.05,20.16],[1,3.9,158.24]],"ltp":3.1,"tv":0.0,"id":6498878},{"batb":[[0,1.49,123.86]],"batl":[[0,1.61,42.01],[1,1.89,435.28]],"ltp":1.48,"tv":0.01,"id":8174333}]}]}
{"op":"mcm","clk":"1001582933","pt":1580638211207,"mc":[{"id":"1.168224344","rc":[{"batb":[[0,2.66,25.21],[1,2.62,13.22],[2,1.01,15.52]],"ltp":3.1,"tv":0.0,"id":6498878},{"batb":[[0,1.49,85.7]],"ltp":1.48,"tv":0.01,"id":8174333}]}]}
{"op":"mcm","clk":"1001582980","pt":1580638211733,"mc":[{"id":"1.168224344","rc":[{"batb":[[0,2.62,13.22],[1,1.01,15.52],[2,1.01,0]],"batl":[[0,3.9,158.24],[1,3.9,0]],"ltp":3.1,"tv":0.0,"id":6498878},{"batb":[[0,1.47,41.23],[1,1.01,15.51],[2,1.01,0]],"batl":[[0,1.89,435.28],[1,1.89,0]],"ltp":1.48,"tv":0.01,"id":8174333}]}]}
{"op":"mcm","clk":"1001585041","pt":1580638234903,"mc":[{"id":"1.168224344","rc":[{"batb":[[0,2.86,10.46],[1,2.7,36.48],[2,1.01,15.52]],"batl":[[0,3.1,19.32],[1,3.9,158.24]],"ltp":3.1,"tv":0.0,"id":6498878},{"batb":[[0,1.48,87.38],[1,1.47,41.23],[2,1.44,44.38]],"batl":[[0,1.6,42.01],[1,1.89,435.28]],"ltp":1.48,"tv":0.01,"id":8174333}]}]}
{"op":"mcm","clk":"1001586236","pt":1580638248326,"mc":[{"id":"1.168224344","rc":[{"batl":[[2,1000,0.02]],"ltp":1.48,"tv":0.01,"id":8174333}]}]}
{"op":"mcm","clk":"1001586272","pt":1580638248634,"mc":[{"id":"1.168224344","rc":[{"batl":[[2,1000,0]],"ltp":1.48,"tv":0.01,"id":8174333}]}]}
{"op":"mcm","clk":"1001586498","pt":1580638251252,"mc":[{"id":"1.168224344","rc":[{"batb":[[0,2.7,36.48],[1,1.01,15.52],[2,1.01,0]],"ltp":3.1,"tv":0.0,"id":6498878},{"batb":[[1,1.44,44.38],[2,1.01,15.51]],"ltp":1.48,"tv":0.01,"id":8174333}]}]}
{"op":"mcm","clk":"1001586545","pt":1580638251827,"mc":[{"id":"1.168224344","rc":[{"batb":[[0,2.7,12.12]],"batl":[[0,3.9,158.24],[1,3.9,0]],"ltp":3.1,"tv":0.0,"id":6498878},{"trd":[[1.48,0.04]],"batb":[[0,1.44,44.38],[1,1.01,15.51],[2,1.01,0]],"batl":[[0,1.89,435.28],[1,1.89,0]],"ltp":1.48,"tv":0.04,"id":8174333}],"tv":0.04}]}
{"op":"mcm","clk":"1001587668","pt":1580638263025,"mc":[{"id":"1.168224344","rc":[{"batb":[[1,1.01,18.55]],"ltp":1.48,"tv":0.04,"id":8174333}]}]}
{"op":"mcm","clk":"1001587738","pt":1580638263767,"mc":[{"id":"1.168224344","rc":[{"batb":[[1,1.01,15.51]],"ltp":1.48,"tv":0.04,"id":8174333}]}]}
{"op":"mcm","clk":"1001588021","pt":1580638266878,"mc":[{"id":"1.168224344","rc":[{"batb":[[0,1.44,44.39]],"ltp":1.48,"tv":0.04,"id":8174333}]}]}
{"op":"mcm","clk":"1001589543","pt":1580638283384,"mc":[{"id":"1.168224344","rc":[{"batb":[[0,2.94,24.23],[1,2.8,11.02],[2,2.74,23.53]],"batl":[[0,3.15,19.32],[1,3.9,158.24]],"ltp":3.1,"tv":0.0,"id":6498878},{"batb":[[0,1.47,89.08],[1,1.44,44.38],[2,1.42,46.82]],"batl":[[0,1.59,42.01],[1,1.89,435.28]],"ltp":1.48,"tv":0.04,"id":8174333}]}]}
{"op":"mcm","clk":"1001590851","pt":1580638295415,"mc":[{"id":"1.168224344","rc":[{"batb":[[0,2.8,11.02],[1,2.74,23.53],[2,1.01,15.52]],"ltp":3.1,"tv":0.0,"id":6498878},{"batb":[[1,1.42,46.82],[2,1.01,15.51]],"ltp":1.48,"tv":0.04,"id":8174333}]}]}
{"op":"mcm","clk":"1001590935","pt":1580638296401,"mc":[{"id":"1.168224344","rc":[{"batb":[[1,1.01,15.52],[2,1.01,0]],"batl":[[0,3.9,158.24],[1,3.9,0]],"ltp":3.1,"tv":0.0,"id":6498878},{"batb":[[0,1.42,46.83],[1,1.01,15.51],[2,1.01,0]],"batl":[[0,1.89,435.28],[1,1.89,0]],"ltp":1.48,"tv":0.04,"id":8174333}]}]}
{"op":"mcm","clk":"1001591412","pt":1580638301793,"mc":[{"id":"1.168224344","rc":[{"batb":[[0,1.47,239.11],[1,1.46,196.26],[2,1.42,46.82]],"batl":[[0,1.52,211.42],[1,1.53,159.24],[2,1.89,435.28]],"ltp":1.48,"tv":0.04,"id":8174333}]}]}
{"op":"mcm","clk":"1001591504","pt":1580638302842,"mc":[{"id":"1.168224344","rc":[{"batb":[[0,3,22.58],[1,2.78,23.53],[2,2.74,11.64]],"batl":[[0,3.2,18.48],[1,3.9,158.24]],"ltp":3.1,"tv":0.0,"id":6498878},{"batb":[[1,1.46,287]],"batl":[[2,1.57,42.01]],"ltp":1.48,"tv":0.04,"id":8174333}]}]}
{"op":"mcm","clk":"1001594164","pt":1580638323162,"mc":[{"id":"1.168224344","rc":[{"trd":[[1.47,168],[1.48,0.07]],"batb":[[0,1.47,155.09]],"ltp":1.47,"tv":168.07,"id":8174333}],"tv":168.08}]}
{"op":"mcm","clk":"1001594601","pt":1580638326493,"mc":[{"id":"1.168224344","rc":[{"batb":[[0,1.47,215.9]],"ltp":1.47,"tv":168.07,"id":8174333}]}]}
{"op":"mcm","clk":"1001602686","pt":1580638401905,"mc":[{"id":"1.168224344","rc":[{"batb":[[0,2.74,11.64],[1,1.01,15.52],[2,2.74,0]],"batl":[[0,3.9,158.24],[1,3.9,0]],"ltp":3.1,"tv":0.0,"id":6498878},{"batb":[[0,1.34,62.47],[1,1.01,15.51],[2,1.42,0]],"batl":[[0,1.89,435.28],[1,1.53,0],[2,1.57,0]],"ltp":1.47,"tv":168.07,"id":8174333}]}]}
{"op":"mcm","clk":"1001603251","pt":1580638407813,"mc":[{"id":"1.168224344","rc":[{"batb":[[0,1.45,233.36],[1,1.44,208.4],[2,1.34,62.47]],"batl":[[0,1.5,260.22],[1,1.51,167.45],[2,1.89,435.28]],"ltp":1.47,"tv":168.07,"id":8174333}]}]}
{"op":"mcm","clk":"1001603510","pt":1580638410412,"mc":[{"id":"1.168224344","rc":[{"batb":[[0,1.34,62.47],[1,1.01,15.51],[2,1.34,0]],"batl":[[0,1.89,435.28],[1,1.51,0],[2,1.89,0]],"ltp":1.47,"tv":168.07,"id":8174333}]}]}
{"op":"mcm","clk":"1001603540","pt":1580638410725,"mc":[{"id":"1.168224344","rc":[{"batl":[[0,4.6,136.05]],"ltp":3.1,"tv":0.0,"id":6498878}]}]}
{"op":"mcm","clk":"1001603813","pt":1580638413344,"mc":[{"id":"1.168224344","rc":[{"batb":[[0,1.38,194.62],[1,1.37,261.05],[2,1.34,62.47]],"batl":[[0,1.6,211.23],[1,1.61,131.8],[2,1.89,435.28]],"ltp":1.47,"tv":168.07,"id":8174333}]}]}
{"op":"mcm","clk":"1001604054","pt":1580638415640,"mc":[{"id":"1.168224344","rc":[{"batl":[[0,1.89,435.28],[1,1.61,0],[2,1.89,0]],"ltp":1.47,"tv":168.07,"id":8174333}]}]}
{"op":"mcm","clk":"1001604467","pt":1580638419329,"mc":[{"id":"1.168224344","rc":[{"batb":[[0,3.5,15.42],[1,3.1,19.32],[2,3.05,21.72]],"batl":[[0,3.65,15.12]],"ltp":3.1,"tv":0.0,"id":6498878},{"batb":[[0,1.38,304.69]],"batl":[[0,1.42,275.42],[1,1.43,209.19],[2,1.45,5.8]],"ltp":1.47,"tv":168.07,"id":8174333}]}]}
{"op":"mcm","clk":"1001604542","pt":1580638419910,"mc":[{"id":"1.168224344","rc":[{"batl":[[2,1.48,42.01]],"ltp":1.47,"tv":168.07,"id":8174333}]}]}
{"op":"mcm","clk":"1001604805","pt":1580638422227,"mc":[{"id":"1.168224344","rc":[{"batl":[[1,5.3,118.79]],"ltp":3.1,"tv":0.0,"id":6498878}]}]}
{"op":"mcm","clk":"1001605310","pt":1580638427326,"mc":[{"id":"1.168224344","rc":[{"trd":[[3.5,14.12]],"batb":[[0,3.5,1.31]],"ltp":3.5,"tv":14.12,"id":6498878},{"trd":[[1.4,35.29]],"ltp":1.4,"tv":203.36,"id":8174333}],"tv":217.48}]}
{"op":"mcm","clk":"1001605422","pt":1580638428330,"mc":[{"id":"1.168224344","rc":[{"batb":[[0,3.05,21.72],[1,1.01,15.52],[2,3.05,0]],"batl":[[0,5.3,118.79],[1,5.3,0]],"ltp":3.5,"tv":14.12,"id":6498878},{"batb":[[0,1.25,88.12],[1,1.01,15.51],[2,1.34,0]],"batl":[[0,1.73,527.57],[1,1.43,0],[2,1.48,0]],"ltp":1.4,"tv":203.36,"id":8174333}]}]}
{"op":"mcm","clk":"1001605731","pt":1580638431356,"mc":[{"id":"1.168224344","rc":[{"batb":[[0,1.28,435.77],[1,1.27,392.95],[2,1.26,86.31]],"batl":[[0,1.5,160.44],[1,1.51,168.11],[2,1.73,527.57]],"ltp":1.4,"tv":203.36,"id":8174333}]}]}
{"op":"mcm","clk":"1001605854","pt":1580638432359,"mc":[{"id":"1.168224344","rc":[{"batb":[[0,1.26,86.31],[1,1.01,15.51],[2,1.26,0]],"ltp":1.4,"tv":203.36,"id":8174333}]}]}
{"op":"mcm","clk":"1001606181","pt":1580638435326,"mc":[{"id":"1.168224344","rc":[{"batb":[[0,1.46,137.87],[1,1.45,201.52],[2,1.26,86.31]],"ltp":1.4,"tv":203.36,"id":8174333}]}]}
{"op":"mcm","clk":"1001606275","pt":1580638436255,"mc":[{"id":"1.168224344","rc":[{"batb":[[1,2.7,12.04],[2,1.01,15.52]],"ltp":3.5,"tv":14.12,"id":6498878},{"batb":[[2,1.43,47.29]],"ltp":1.4,"tv":203.36,"id":8174333}]}]}
{"op":"mcm","clk":"1001606326","pt":1580638436848,"mc":[{"id":"1.168224344","rc":[{"batb":[[1,2.84,22.69],[2,2.7,12.04]],"batl":[[0,3.25,18.48]],"ltp":3.5,"tv":14.12,"id":6498878},{"batb":[[2,1.44,94.94]],"batl":[[2,1.55,42.01]],"ltp":1.4,"tv":203.36,"id":8174333}]}]}
{"op":"mcm","clk":"1001606526","pt":1580638438934,"mc":[{"id":"1.168224344","rc":[{"batl":[[1,4.6,136.05]],"ltp":3.5,"tv":14.12,"id":6498878}]}]}
{"op":"mcm","clk":"1001607778","pt":1580638450368,"mc":[{"id":"1.168224344","rc":[{"batb":[[0,1.44,94.94],[1,1.43,47.29],[2,1.33,65.86]],"batl":[[0,1.55,42.01],[1,1.73,527.57],[2,1.55,0]],"ltp":1.4,"tv":203.36,"id":8174333}]}]}
{"op":"mcm","clk":"1001607832","pt":1580638450780,"mc":[{"id":"1.168224344","rc":[{"batb":[[0,2.84,22.69],[1,2.7,12.04],[2,1.01,15.52]],"ltp":3.5,"tv":14.12,"id":6498878},{"batb":[[1,1.33,65.86],[2,1.01,15.51]],"ltp":1.4,"tv":203.36,"id":8174333}]}]}
{"op":"mcm","clk":"1001607976","pt":1580638451886,"mc":[{"id":"1.168224344","rc":[{"batb":[[0,2.7,12.04],[1,1.01,15.52],[2,1.01,0]],"batl":[[0,4.6,136.05],[1,4.6,0]],"ltp":3.5,"tv":14.12,"id":6498878},{"batb":[[0,1.33,65.86],[1,1.01,15.51],[2,1.01,0]],"batl":[[0,1.73,527.57],[1,1.73,0]],"ltp":1.4,"tv":203.36,"id":8174333}]}]}
{"op":"mcm","clk":"1001608129","pt":1580638453286,"mc":[{"id":"1.168224344","rc":[{"batb":[[0,1.35,254.76],[1,1.34,291.73],[2,1.33,65.86]],"batl":[[0,1.6,221.61],[1,1.61,131.76],[2,1.73,527.57]],"ltp":1.4,"tv":203.36,"id":8174333}]}]}
{"op":"mcm","clk":"1001608729","pt":1580638458269,"mc":[{"id":"1.168224344","rc":[{"batb":[[0,1.33,65.86],[1,1.01,15.51],[2,1.33,0]],"ltp":1.4,"tv":203.36,"id":8174333}]}]}
{"op":"mcm","clk":"1001609083","pt":1580638461187,"mc":[{"id":"1.168224344","rc":[{"batb":[[0,1.54,242.47],[1,1.53,162.12],[2,1.33,65.86]],"batl":[[2,1.73,0]],"ltp":1.4,"tv":203.36,"id":8174333}]}]}
{"op":"mcm","clk":"1001609184","pt":1580638461918,"mc":[{"id":"1.168224344","rc":[{"batb":[[1,2.48,15.34],[2,1.01,15.52]],"ltp":3.5,"tv":14.12,"id":6498878},{"batb":[[1,1.53,198.94],[2,1.42,48.94]],"ltp":1.4,"tv":203.36,"id":8174333}]}]}
{"op":"mcm","clk":"1001609293","pt":1580638462903,"mc":[{"id":"1.168224344","rc":[{"batb":[[1,2.6,26.05],[2,2.48,15.34]],"batl":[[0,2.96,21]],"ltp":3.5,"tv":14.12,"id":6498878},{"batb":[[2,1.51,82.34]],"batl":[[2,1.63,42.01]],"ltp":1.4,"tv":203.36,"id":8174333}]}]}
{"op":"mcm","clk":"1001609537","pt":1580638465219,"mc":[{"id":"1.168224344","rc":[{"batl":[[1,3.9,158.24]],"ltp":3.5,"tv":14.12,"id":6498878}]}]}
{"op":"mcm","clk":"1001610857","pt":1580638477329,"mc":[{"id":"1.168224344","rc":[{"batb":[[0,2.6,26.05],[1,2.48,15.34],[2,1.01,15.52]],"ltp":3.5,"tv":14.12,"id":6498878},{"batb":[[0,1.51,82.34],[1,1.42,48.94],[2,1.01,15.51]],"batl":[[0,1.63,42.01],[1,1.95,409.86],[2,1.63,0]],"ltp":1.4,"tv":203.36,"id":8174333}]}]}
{"op":"mcm","clk":"1001610956","pt":1580638478257,"mc":[{"id":"1.168224344","rc":[{"batb":[[0,2.48,15.34],[1,1.01,15.52],[2,1.01,0]],"batl":[[0,3.9,158.24],[1,3.9,0]],"ltp":3.5,"tv":14.12,"id":6498878},{"batb":[[0,1.42,48.94],[1,1.01,15.51],[2,1.01,0]],"batl":[[0,1.95,409.86],[1,1.95,0]],"ltp":1.4,"tv":203.36,"id":8174333}]}]}
{"op":"mcm","clk":"1001611574","pt":1580638483259,"mc":[{"id":"1.168224344","rc":[{"batb":[[0,1.52,226.16],[1,1.51,170.79],[2,1.42,48.94]],"batl":[[0,1.57,133.36],[1,1.58,141.54],[2,1.95,409.86]],"ltp":1.4,"tv":203.36,"id":8174333}]}]}
{"op":"mcm","clk":"1001611874","pt":1580638485972,"mc":[{"id":"1.168224344","rc":[{"batb":[[0,1.42,48.94],[1,1.01,15.51],[2,1.42,0]],"batl":[[0,1.95,409.86],[1,1.58,0],[2,1.95,0]],"ltp":1.4,"tv":203.36,"id":8174333}]}]}
{"op":"mcm","clk":"1001612243","pt":1580638489245,"mc":[{"id":"1.168224344","rc":[{"batb":[[0,1.44,258.29],[1,1.43,215.03],[2,1.42,48.94]],"batl":[[0,1.68,117.88],[1,1.7,219.68],[2,1.95,409.86]],"ltp":1.4,"tv":203.36,"id":8174333}]}]}
{"op":"mcm","clk":"1001612357","pt":1580638490126,"mc":[{"id":"1.168224344","rc":[{"batb":[[0,1.42,48.94],[1,1.01,15.51],[2,1.42,0]],"ltp":1.4,"tv":203.36,"id":8174333}]}]}
{"op":"mcm","clk":"1001612732","pt":1580638493289,"mc":[{"id":"1.168224344","rc":[{"batb":[[0,1.62,222.56],[1,1.61,133.26],[2,1.42,48.94]],"ltp":1.4,"tv":203.36,"id":8174333}]}]}
{"op":"mcm","clk":"1001612799","pt":1580638493866,"mc":[{"id":"1.168224344","rc":[{"batb":[[1,2.34,17.86],[2,1.01,15.52]],"ltp":3.5,"tv":14.12,"id":6498878},{"batb":[[1,1.61,163.24],[2,1.54,35.96]],"ltp":1.4,"tv":203.36,"id":8174333}]}]}
{"op":"mcm","clk":"1001612887","pt":1580638494871,"mc":[{"id":"1.168224344","rc":[{"batb":[[1,2.42,29.41],[2,2.34,17.86]],"batl":[[0,2.76,23.53]],"ltp":3.5,"tv":14.12,"id":6498878},{"batb":[[2,1.57,73.1]],"batl":[[2,1.72,42.01]],"ltp":1.4,"tv":203.36,"id":8174333}]}]}
{"op":"mcm","clk":"1001613043","pt":1580638496276,"mc":[{"id":"1.168224344","rc":[{"batl":[[1,3.45,180.4]],"ltp":3.5,"tv":14.12,"id":6498878}]}]}
{"op":"mcm","clk":"1001613965","pt":1580638504307,"mc":[{"id":"1.168224344","rc":[{"batb":[[0,2.42,29.41],[1,2.34,17.86],[2,1.01,15.52]],"ltp":3.5,"tv":14.12,"id":6498878},{"batb":[[0,1.57,73.1],[1,1.54,35.96],[2,1.01,15.51]],"batl":[[0,1.72,42.01],[1,1.95,409.86],[2,1.72,0]],"ltp":1.4,"tv":203.36,"id":8174333}]}]}
{"op":"mcm","clk":"1001614134","pt":1580638505884,"mc":[{"id":"1.168224344","rc":[{"batb":[[0,2.34,17.86],[1,1.01,15.52],[2,1.01,0]],"batl":[[0,3.45,180.4],[1,3.45,0]],"ltp":3.5,"tv":14.12,"id":6498878},{"batb":[[0,1.54,35.96],[1,1.01,15.51],[2,1.01,0]],"batl":[[0,1.95,409.86],[1,1.95,0]],"ltp":1.4,"tv":203.36,"id":8174333}]}]}
{"op":"mcm","clk":"1001614232","pt":1580638506877,"mc":[{"id":"1.168224344","rc":[{"batb":[[0,1.56,124.3],[1,1.55,153.49],[2,1.54,35.96]],"batl":[[0,1.74,167.64],[1,1.76,195.53],[2,1.95,409.86]],"ltp":1.4,"tv":203.36,"id":8174333}]}]}
{"op":"mcm","clk":"1001614352","pt":1580638507982,"mc":[{"id":"1.168224344","rc":[{"batb":[[0,1.54,35.96],[1,1.01,15.51],[2,1.54,0]],"batl":[[0,1.95,409.86],[1,1.76,0],[2,1.95,0]],"ltp":1.4,"tv":203.36,"id":8174333}]}]}
{"op":"mcm","clk":"1001614665","pt":1580638511105,"mc":[{"id":"1.168224344","rc":[{"batb":[[0,1.61,171.68],[1,1.6,136.22],[2,1.54,35.96]],"batl":[[0,1.67,179.26],[1,1.69,223.81],[2,1.95,409.86]],"ltp":1.4,"tv":203.36,"id":8174333}]}]}
{"op":"mcm","clk":"1001614879","pt":1580638513101,"mc":[{"id":"1.168224344","rc":[{"batb":[[0,1.54,35.96],[1,1.01,15.51],[2,1.54,0]],"batl":[[0,1.95,409.86],[1,1.69,0],[2,1.95,0]],"ltp":1.4,"tv":203.36,"id":8174333}]}]}
{"op":"mcm","clk":"1001615239","pt":1580638516301,"mc":[{"id":"1.168224344","rc":[{"batb":[[0,1.56,124.3],[1,1.55,153.49],[2,1.54,35.96]],"batl":[[0,1.74,167.64],[1,1.76,195.53],[2,1.95,409.86]],"ltp":1.4,"tv":203.36,"id":8174333}]}]}
{"op":"mcm","clk":"1001615667","pt":1580638520412,"mc":[{"id":"1.168224344","rc":[{"batb":[[0,1.54,35.96],[1,1.01,15.51],[2,1.54,0]],"ltp":1.4,"tv":203.36,"id":8174333}]}]}
{"op":"mcm","clk":"1001615874","pt":1580638522314,"mc":[{"id":"1.168224344","rc":[{"batl":[[2,1.95,0]],"ltp":1.4,"tv":203.36,"id":8174333}]}]}
{"op":"mcm","clk":"1001615927","pt":1580638522787,"mc":[{"id":"1.168224344","rc":[{"batb":[[0,1.67,213.89],[1,1.66,119.17],[2,1.54,35.96]],"ltp":1.4,"tv":203.36,"id":8174333}]}]}
{"op":"mcm","clk":"1001616058","pt":1580638524298,"mc":[{"id":"1.168224344","rc":[{"batb":[[1,2.06,25.57],[2,1.01,15.52]],"ltp":3.5,"tv":14.12,"id":6498878},{"batb":[[0,1.68,26.28],[1,1.67,213.89],[2,1.66,119.17]],"ltp":1.4,"tv":203.36,"id":8174333}]}]}
{"op":"mcm","clk":"1001616105","pt":1580638524920,"mc":[{"id":"1.168224344","rc":[{"batb":[[1,2.28,32.77],[2,2.06,25.57]],"batl":[[0,2.62,25.21]],"ltp":3.5,"tv":14.12,"id":6498878},{"batl":[[2,1.78,42.01]],"ltp":1.4,"tv":203.36,"id":8174333}]}]}
{"op":"mcm","clk":"1001616203","pt":1580638525917,"mc":[{"id":"1.168224344","rc":[{"batl":[[1,3.3,191.92]],"ltp":3.5,"tv":14.12,"id":6498878}]}]}
{"op":"mcm","clk":"1001619856","pt":1580638559833,"mc":[{"id":"1.168224344","rc":[{"batb":[[1,1.62,67.22],[2,1.59,31.32]],"batl":[[0,1.78,42.01],[1,2.16,342.82],[2,1.78,0]],"ltp":1.4,"tv":203.36,"id":8174333}]}]}
{"op":"mcm","clk":"1001620164","pt":1580638562879,"mc":[{"id":"1.168224344","rc":[{"batb":[[0,2.28,32.77],[1,2.06,25.57],[2,1.01,15.52]],"ltp":3.5,"tv":14.12,"id":6498878},{"batb":[[0,1.62,67.22],[1,1.59,289.87],[2,1.58,143.13]],"batl":[[1,1.92,140.83],[2,1.94,143.68]],"ltp":1.4,"tv":203.36,"id":8174333}]}]}
{"op":"mcm","clk":"1001620265","pt":1580638563972,"mc":[{"id":"1.168224344","rc":[{"batb":[[0,2.06,25.57],[1,1.01,15.52],[2,1.01,0]],"batl":[[0,3.3,191.92],[1,3.3,0]],"ltp":3.5,"tv":14.12,"id":6498878},{"batb":[[0,1.59,289.87],[1,1.58,143.13],[2,1.01,15.51]],"batl":[[0,1.92,140.83],[1,1.94,143.68],[2,2.16,342.82]],"ltp":1.4,"tv":203.36,"id":8174333}]}]}
{"op":"mcm","clk":"1001620979","pt":1580638570957,"mc":[{"id":"1.168224344","rc":[{"batl":[[0,2.16,342.82],[1,1.94,0],[2,2.16,0]],"ltp":1.4,"tv":203.36,"id":8174333}]}]}
{"op":"mcm","clk":"1001621384","pt":1580638574391,"mc":[{"id":"1.168224344","rc":[{"batb":[[0,2.52,14.63],[1,2.24,20.06],[2,2.06,25.57]],"ltp":3.5,"tv":14.12,"id":6498878},{"batb":[[2,1.53,36.19]],"batl":[[0,1.65,125.7],[1,1.66,118.51]],"ltp":1.4,"tv":203.36,"id":8174333}]}]}
{"op":"mcm","clk":"1001621455","pt":1580638574970,"mc":[{"id":"1.168224344","rc":[{"batb":[[1,2.44,28.57],[2,2.24,20.06]],"batl":[[0,2.8,22.69]],"ltp":3.5,"tv":14.12,"id":6498878},{"batb":[[2,1.56,74.78]],"batl":[[2,1.7,42.01]],"ltp":1.4,"tv":203.36,"id":8174333}]}]}
{"op":"mcm","clk":"1001621581","pt":1580638576168,"mc":[{"id":"1.168224344","rc":[{"batl":[[1,3.65,170.41]],"ltp":3.5,"tv":14.12,"id":6498878}]}]}
{"op":"mcm","clk":"1001622437","pt":1580638584982,"mc":[{"id":"1.168224344","rc":[{"batb":[[0,2.44,28.57],[1,2.24,20.06],[2,1.01,15.52]],"ltp":3.5,"tv":14.12,"id":6498878},{"batb":[[0,1.56,74.78],[1,1.53,36.19],[2,1.01,15.51]],"batl":[[0,1.7,42.01],[1,2.04,383.01],[2,1.7,0]],"ltp":1.4,"tv":203.36,"id":8174333}]}]}
{"op":"mcm","clk":"1001622515","pt":1580638585933,"mc":[{"id":"1.168224344","rc":[{"batb":[[0,2.24,20.06],[1,1.01,15.52],[2,1.01,0]],"batl":[[0,3.65,170.41],[1,3.65,0]],"ltp":3.5,"tv":14.12,"id":6498878},{"batb":[[0,1.53,36.19],[1,1.01,15.51],[2,1.01,0]],"batl":[[0,2.04,383.01],[1,2.04,0]],"ltp":1.4,"tv":203.36,"id":8174333}]}]}
{"op":"mcm","clk":"1001622717","pt":1580638587718,"mc":[{"id":"1.168224344","rc":[{"batb":[[0,1.54,200.98],[1,1.53,198.03],[2,1.01,15.51]],"batl":[[0,1.78,170.01],[1,1.8,181.56],[2,2.04,383.01]],"ltp":1.4,"tv":203.36,"id":8174333}]}]}
{"op":"mcm","clk":"1001623762","pt":1580638597629,"mc":[{"id":"1.168224344","rc":[{"batb":[[0,1.53,36.19],[1,1.01,15.51],[2,1.01,0]],"batl":[[0,2.04,383.01],[1,1.8,0],[2,2.04,0]],"ltp":1.4,"tv":203.36,"id":8174333}]}]}
{"op":"mcm","clk":"1001624085","pt":1580638601001,"mc":[{"id":"1.168224344","rc":[{"batb":[[0,1.62,137.86],[1,1.61,132.98],[2,1.53,36.19]],"batl":[[0,1.68,198.34],[1,1.7,219.22],[2,2.04,383.01]],"ltp":1.4,"tv":203.36,"id":8174333}]}]}
{"op":"mcm","clk":"1001624187","pt":1580638601947,"mc":[{"id":"1.168224344","rc":[{"batb":[[0,1.53,36.19],[1,1.01,15.51],[2,1.53,0]],"batl":[[0,2.04,383.01],[1,1.7,0],[2,2.04,0]],"ltp":1.4,"tv":203.36,"id":8174333}]}]}
{"op":"mcm","clk":"1001624537","pt":1580638605375,"mc":[{"id":"1.168224344","rc":[{"batb":[[0,1.54,200.98],[1,1.53,198.03],[2,1.01,15.51]],"ltp":1.4,"tv":203.36,"id":8174333}]}]}
{"op":"mcm","clk":"1001624793","pt":1580638608078,"mc":[{"id":"1.168224344","rc":[{"batl":[[0,1.59,126.12],[1,1.6,135.12],[2,2.04,383.01]],"ltp":1.4,"tv":203.36,"id":8174333}]}]}
{"op":"mcm","clk":"1001624867","pt":1580638608946,"mc":[{"id":"1.168224344","rc":[{"batb":[[0,2.68,12.27],[1,2.56,26.89],[2,2.46,15.5]],"batl":[[0,2.98,21],[1,3.65,170.41]],"ltp":3.5,"tv":14.12,"id":6498878},{"batb":[[2,1.51,82.34]],"batl":[[2,1.64,42.01]],"ltp":1.4,"tv":203.36,"id":8174333}]}]}
{"op":"mcm","clk":"1001625775","pt":1580638619166,"mc":[{"id":"1.168224344","rc":[{"batb":[[0,1.53,36.19],[1,1.51,82.34],[2,1.49,40.36]],"batl":[[0,1.64,42.01],[1,2.04,383.01],[2,1.64,0]],"ltp":1.4,"tv":203.36,"id":8174333}]}]}
{"op":"mcm","clk":"1001625855","pt":1580638620004,"mc":[{"id":"1.168224344","rc":[{"batb":[[0,2.46,15.5],[1,1.01,15.52],[2,2.46,0]],"batl":[[0,3.65,170.41],[1,3.65,0]],"ltp":3.5,"tv":14.12,"id":6498878},{"batb":[[0,1.49,40.36],[1,1.01,15.51],[2,1.49,0]],"batl":[[0,2.04,383.01],[1,2.04,0]],"ltp":1.4,"tv":203.36,"id":8174333}]}]}
{"op":"mcm","clk":"1001626088","pt":1580638622213,"mc":[{"id":"1.168224344","rc":[{"batb":[[0,1.51,146.34],[1,1.5,174.88],[2,1.49,40.36]],"batl":[[0,1.67,190.32],[1,1.69,223.74],[2,2.04,383.01]],"ltp":1.4,"tv":203.36,"id":8174333}]}]}
{"op":"mcm","clk":"1001626176","pt":1580638623204,"mc":[{"id":"1.168224344","rc":[{"batb":[[0,1.49,40.36],[1,1.01,15.51],[2,1.49,0]],"batl":[[0,2.04,383.01],[1,1.69,0],[2,2.04,0]],"ltp":1.4,"tv":203.36,"id":8174333}]}]}
{"op":"mcm","clk":"1001626767","pt":1580638629273,"mc":[{"id":"1.168224344","rc":[{"batb":[[0,1.51,154.65],[1,1.5,174.88],[2,1.49,40.36]],"batl":[[0,1.67,182.96],[1,1.69,223.75],[2,2.04,383.01]],"ltp":1.4,"tv":203.36,"id":8174333}]}]}
{"op":"mcm","clk":"1001627422","pt":1580638636305,"mc":[{"id":"1.168224344","rc":[{"batl":[[0,2.04,383.01],[1,1.69,0],[2,2.04,0]],"ltp":1.4,"tv":203.36,"id":8174333}]}]}
{"op":"mcm","clk":"1001627687","pt":1580638639322,"mc":[{"id":"1.168224344","rc":[{"batl":[[0,1.56,217.03],[1,1.57,144.38]],"ltp":1.4,"tv":203.36,"id":8174333}]}]}
{"op":"mcm","clk":"1001627752","pt":1580638640111,"mc":[{"id":"1.168224344","rc":[{"batb":[[0,2.82,10.78],[1,2.64,12.75],[2,1.01,15.52]],"ltp":3.5,"tv":14.12,"id":6498878}]}]}
{"op":"mcm","clk":"1001627816","pt":1580638641001,"mc":[{"id":"1.168224344","rc":[{"batb":[[1,2.66,25.21],[2,2.64,12.75]],"batl":[[0,3.1,19.32]],"ltp":3.5,"tv":14.12,"id":6498878},{"batl":[[2,1.6,42.01]],"ltp":1.4,"tv":203.36,"id":8174333}]}]}
{"op":"mcm","clk":"1001627954","pt":1580638642817,"mc":[{"id":"1.168224344","rc":[{"batl":[[1,4.2,148.03]],"ltp":3.5,"tv":14.12,"id":6498878}]}]}
{"op":"mcm","clk":"1001628715","pt":1580638653048,"mc":[{"id":"1.168224344","rc":[{"batb":[[0,2.66,25.21],[1,2.64,12.75],[2,1.01,15.52]],"ltp":3.5,"tv":14.12,"id":6498878},{"batb":[[0,1.48,87.38],[1,1.47,42.72],[2,1.01,15.51]],"batl":[[0,1.6,42.01],[1,1.89,435.28],[2,1.6,0]],"ltp":1.4,"tv":203.36,"id":8174333}]}]}
{"op":"mcm","clk":"1001628791","pt":1580638653939,"mc":[{"id":"1.168224344","rc":[{"batb":[[0,2.64,12.75],[1,1.01,15.52],[2,1.01,0]],"batl":[[0,4.2,148.03],[1,4.2,0]],"ltp":3.5,"tv":14.12,"id":6498878},{"batb":[[0,1.47,42.72],[1,1.01,15.51],[2,1.01,0]],"batl":[[0,1.89,435.28],[1,1.89,0]],"ltp":1.4,"tv":203.36,"id":8174333}]}]}
{"op":"mcm","clk":"1001629303","pt":1580638658316,"mc":[{"id":"1.168224344","rc":[{"batb":[[0,1.51,270.49],[1,1.5,175.58],[2,1.47,42.72]],"batl":[[0,1.57,252.27],[1,1.58,140.86],[2,1.89,435.28]],"ltp":1.4,"tv":203.36,"id":8174333}]}]}
{"op":"mcm","clk":"1001629410","pt":1580638659565,"mc":[{"id":"1.168224344","rc":[{"batb":[[0,1.47,42.72],[1,1.01,15.51],[2,1.47,0]],"batl":[[0,1.89,435.28],[1,1.58,0],[2,1.89,0]],"ltp":1.4,"tv":203.36,"id":8174333}]}]}
{"op":"mcm","clk":"1001629718","pt":1580638663019,"mc":[{"id":"1.168224344","rc":[{"batb":[[0,1.49,208.71],[1,1.48,185.13],[2,1.47,42.72]],"ltp":1.4,"tv":203.36,"id":8174333}]}]}
{"op":"mcm","clk":"1001629972","pt":1580638666047,"mc":[{"id":"1.168224344","rc":[{"batl":[[0,1.54,201.44],[1,1.55,151.57],[2,1.89,435.28]],"ltp":1.4,"tv":203.36,"id":8174333}]}]}
{"op":"mcm","clk":"1001630060","pt":1580638667031,"mc":[{"id":"1.168224344","rc":[{"batb":[[0,2.9,25.41],[1,2.76,23.53],[2,2.64,12.75]],"batl":[[0,3.2,18.48],[1,4.2,148.03]],"ltp":3.5,"tv":14.12,"id":6498878},{"batl":[[2,1.57,42.01]],"ltp":1.4,"tv":203.36,"id":8174333}]}]}
{"op":"mcm","clk":"1001632724","pt":1580638691163,"mc":[{"id":"1.168224344","rc":[{"batb":[[0,2.76,23.53],[1,2.64,12.75],[2,1.01,15.52]],"ltp":3.5,"tv":14.12,"id":6498878},{"batb":[[0,1.46,90.74],[1,1.36,59.17],[2,1.01,15.51]],"batl":[[0,1.57,42.01],[1,1.89,435.28],[2,1.57,0]],"ltp":1.4,"tv":203.36,"id":8174333}]}]}
{"op":"mcm","clk":"1001632843","pt":1580638691995,"mc":[{"id":"1.168224344","rc":[{"batb":[[0,2.64,12.75],[1,1.01,15.52],[2,1.01,0]],"batl":[[0,4.2,148.03],[1,4.2,0]],"ltp":3.5,"tv":14.12,"id":6498878},{"batb":[[0,1.36,59.17],[1,1.01,15.51],[2,1.01,0]],"batl":[[0,1.89,435.28],[1,1.89,0]],"ltp":1.4,"tv":203.36,"id":8174333}]}]}
{"op":"mcm","clk":"1001633547","pt":1580638697172,"mc":[{"id":"1.168224344","rc":[{"batb":[[0,1.47,182.28],[1,1.46,195.83],[2,1.36,59.17]],"batl":[[0,1.52,264.88],[1,1.53,158.91],[2,1.89,435.28]],"ltp":1.4,"tv":203.36,"id":8174333}]}]}
{"op":"mcm","clk":"1001634110","pt":1580638703196,"mc":[{"id":"1.168224344","rc":[{"batb":[[0,1.36,59.17],[1,1.01,15.51],[2,1.36,0]],"batl":[[0,1.89,435.28],[1,1.53,0],[2,1.89,0]],"ltp":1.4,"tv":203.36,"id":8174333}]}]}
{"op":"mcm","clk":"1001634454","pt":1580638706111,"mc":[{"id":"1.168224344","rc":[{"batb":[[0,1.39,186.64],[1,1.38,251.85],[2,1.36,59.17]],"batl":[[0,1.63,221.93],[1,1.64,123.23],[2,1.89,435.28]],"ltp":1.4,"tv":203.36,"id":8174333}]}]}
{"op":"mcm","clk":"1001635238","pt":1580638714530,"mc":[{"id":"1.168224344","rc":[{"batb":[[0,1.36,59.17],[1,1.01,15.51],[2,1.36,0]],"ltp":1.4,"tv":203.36,"id":8174333}]}]}
{"op":"mcm","clk":"1001635540","pt":1580638718217,"mc":[{"id":"1.168224344","rc":[{"batb":[[1,2.44,16.05],[2,1.01,15.52]],"ltp":3.5,"tv":14.12,"id":6498878},{"batb":[[0,1.57,188.03],[1,1.56,149.88],[2,1.55,34.93]],"ltp":1.4,"tv":203.36,"id":8174333}]}]}
{"op":"mcm","clk":"1001635605","pt":1580638719009,"mc":[{"id":"1.168224344","rc":[{"batb":[[1,2.56,26.89],[2,2.44,16.05]],"batl":[[0,2.94,21]],"ltp":3.5,"tv":14.12,"id":6498878},{"batl":[[2,1.65,42.01]],"ltp":1.4,"tv":203.36,"id":8174333}]}]}
{"op":"mcm","clk":"1001635758","pt":1580638720852,"mc":[{"id":"1.168224344","rc":[{"batl":[[1,3.9,158.24]],"ltp":3.5,"tv":14.12,"id":6498878}]}]}
{"op":"mcm","clk":"1001636738","pt":1580638733260,"mc":[{"id":"1.168224344","rc":[{"batb":[[0,2.56,26.89],[1,2.44,16.05],[2,1.01,15.52]],"ltp":3.5,"tv":14.12,"id":6498878},{"batb":[[0,1.52,80.66],[1,1.45,45.24],[2,1.01,15.51]],"batl":[[0,1.65,42.01],[1,1.89,435.28],[2,1.65,0]],"ltp":1.4,"tv":203.36,"id":8174333}]}]}
{"op":"mcm","clk":"1001636816","pt":1580638734362,"mc":[{"id":"1.168224344","rc":[{"batb":[[0,2.44,16.05],[1,1.01,15.52],[2,1.01,0]],"batl":[[0,3.9,158.24],[1,3.9,0]],"ltp":3.5,"tv":14.12,"id":6498878},{"batb":[[0,1.45,45.24],[1,1.01,15.51],[2,1.01,0]],"batl":[[0,1.89,435.28],[1,1.89,0]],"ltp":1.4,"tv":203.36,"id":8174333}]}]}
{"op":"mcm","clk":"1001636932","pt":1580638736023,"mc":[{"id":"1.168224344","rc":[{"batb":[[0,1.47,266.19],[1,1.46,196.42],[2,1.45,45.24]],"batl":[[0,1.71,203.52],[1,1.73,206.46],[2,1.89,435.28]],"ltp":1.4,"tv":203.36,"id":8174333}]}]}
{"op":"mcm","clk":"1001636993","pt":1580638736857,"mc":[{"id":"1.168224344","rc":[{"batb":[[0,1.45,45.24],[1,1.01,15.51],[2,1.45,0]],"batl":[[0,1.89,435.28],[1,1.73,0],[2,1.89,0]],"ltp":1.4,"tv":203.36,"id":8174333}]}]}
{"op":"mcm","clk":"1001637250","pt":1580638740260,"mc":[{"id":"1.168224344","rc":[{"batb":[[0,1.55,185.23],[1,1.54,157.58],[2,1.45,45.24]],"batl":[[0,1.6,126.09],[1,1.61,132.02],[2,1.89,435.28]],"ltp":1.4,"tv":203.36,"id":8174333}]}]}
{"op":"mcm","clk":"1001637606","pt":1580638744252,"mc":[{"id":"1.168224344","rc":[{"batb":[[0,1.45,45.24],[1,1.01,15.51],[2,1.45,0]],"batl":[[0,1.89,435.28],[1,1.61,0],[2,1.89,0]],"ltp":1.4,"tv":203.36,"id":8174333}]}]}
{"op":"mcm","clk":"1001637844","pt":1580638747281,"mc":[{"id":"1.168224344","rc":[{"batb":[[0,1.47,266.19],[1,1.46,196.42],[2,1.45,45.24]],"ltp":1.4,"tv":203.36,"id":8174333}]}]}
{"op":"mcm","clk":"1001638102","pt":1580638750264,"mc":[{"id":"1.168224344","rc":[{"batl":[[0,1.52,186.36],[1,1.53,159.37],[2,1.89,435.28]],"ltp":1.4,"tv":203.36,"id":8174333}]}]}
{"op":"mcm","clk":"1001638163","pt":1580638751046,"mc":[{"id":"1.168224344","rc":[{"batb":[[0,2.98,23.6],[1,2.8,22.69],[2,2.66,12.59]],"batl":[[0,3.25,18.48]],"ltp":3.5,"tv":14.12,"id":6498878},{"batl":[[2,1.55,42.01]],"ltp":1.4,"tv":203.36,"id":8174333}]}]}
{"op":"mcm","clk":"1001638322","pt":1580638753069,"mc":[{"id":"1.168224344","rc":[{"batl":[[1,4.6,136.05]],"ltp":3.5,"tv":14.12,"id":6498878}]}]}
{"op":"mcm","clk":"1001639264","pt":1580638764386,"mc":[{"id":"1.168224344","rc":[{"batb":[[0,1.45,45.24],[1,1.44,94.94],[2,1.33,66.72]],"batl":[[0,1.55,42.01],[1,1.89,435.28],[2,1.55,0]],"ltp":1.4,"tv":203.36,"id":8174333}]}]}
{"op":"mcm","clk":"1001639290","pt":1580638764691,"mc":[{"id":"1.168224344","rc":[{"batb":[[0,2.8,22.69],[1,2.66,12.59],[2,1.01,15.52]],"ltp":3.5,"tv":14.12,"id":6498878},{"batb":[[0,1.44,94.94],[1,1.33,66.72],[2,1.01,15.51]],"ltp":1.4,"tv":203.36,"id":8174333}]}]}
{"op":"mcm","clk":"1001639409","pt":1580638766314,"mc":[{"id":"1.168224344","rc":[{"batb":[[0,2.66,12.59],[1,1.01,15.52],[2,1.01,0]],"batl":[[0,4.6,136.05],[1,4.6,0]],"ltp":3.5,"tv":14.12,"id":6498878},{"batb":[[0,1.33,66.72],[1,1.01,15.51],[2,1.01,0]],"batl":[[0,1.89,435.28],[1,1.89,0]],"ltp":1.4,"tv":203.36,"id":8174333}]}]}
{"op":"mcm","clk":"1001639513","pt":1580638767406,"mc":[{"id":"1.168224344","rc":[{"batb":[[0,1.35,391.48],[1,1.34,293.23],[2,1.33,66.72]],"batl":[[0,1.62,126.27],[1,1.63,126.28],[2,1.89,435.28]],"ltp":1.4,"tv":203.36,"id":8174333}]}]}
{"op":"mcm","clk":"1001639541","pt":1580638767671,"mc":[{"id":"1.168224344","rc":[{"batb":[[0,1.33,66.72],[1,1.01,15.51],[2,1.33,0]],"batl":[[0,1.89,435.28],[1,1.63,0],[2,1.89,0]],"ltp":1.4,"tv":203.36,"id":8174333}]}]}
{"op":"mcm","clk":"1001639879","pt":1580638771015,"mc":[{"id":"1.168224344","rc":[{"batb":[[0,1.45,168.89],[1,1.44,207.66],[2,1.33,66.72]],"batl":[[0,1.49,148.18],[1,1.5,172.49],[2,1.89,435.28]],"ltp":1.4,"tv":203.36,"id":8174333}]}]}
{"op":"mcm","clk":"1001640063","pt":1580638773214,"mc":[{"id":"1.168224344","rc":[{"batb":[[0,1.33,66.72],[1,1.01,15.51],[2,1.33,0]],"batl":[[0,1.89,435.28],[1,1.5,0],[2,1.89,0]],"ltp":1.4,"tv":203.36,"id":8174333}]}]}
{"op":"mcm","clk":"1001640350","pt":1580638776413,"mc":[{"id":"1.168224344","rc":[{"batb":[[0,1.35,391.48],[1,1.34,293.23],[2,1.33,66.72]],"batl":[[0,1.62,126.27],[1,1.63,126.28],[2,1.89,435.28]],"ltp":1.4,"tv":203.36,"id":8174333}]}]}
{"op":"mcm","clk":"1001641767","pt":1580638792137,"mc":[{"id":"1.168224344","rc":[{"batl":[[0,1.89,435.28],[1,1.63,0],[2,1.89,0]],"ltp":1.4,"tv":203.36,"id":8174333}]}]}
{"op":"mcm","clk":"1001642025","pt":1580638795120,"mc":[{"id":"1.168224344","rc":[{"batl":[[0,1.39,177.52],[1,1.4,230.36]],"ltp":1.4,"tv":203.36,"id":8174333}]}]}
{"op":"mcm","clk":"1001642089","pt":1580638796054,"mc":[{"id":"1.168224344","rc":[{"batb":[[0,3.65,14.08],[1,3.05,22.03],[2,1.01,15.52]],"ltp":3.5,"tv":14.12,"id":6498878}]}]}
{"op":"mcm","clk":"1001642182","pt":1580638797146,"mc":[{"id":"1.168224344","rc":[{"batb":[[1,3.3,17.64],[2,3.05,22.03]],"batl":[[0,3.9,14.28]],"ltp":3.5,"tv":14.12,"id":6498878},{"batb":[[1,1.34,416.74]],"batl":[[2,1.43,42.01]],"ltp":1.4,"tv":203.36,"id":8174333}]}]}
{"op":"mcm","clk":"1001642308","pt":1580638798756,"mc":[{"id":"1.168224344","rc":[{"batl":[[1,5.5,115.06]],"ltp":3.5,"tv":14.12,"id":6498878}]}]}
{"op":"mcm","clk":"1001643783","pt":1580638816279,"mc":[{"id":"1.168224344","rc":[{"batb":[[0,3.05,22.03],[1,1.01,15.52],[2,3.05,0]],"batl":[[0,5.5,115.06],[1,5.5,0]],"ltp":3.5,"tv":14.12,"id":6498878},{"batb":[[0,1.21,109.76],[1,1.01,15.51],[2,1.33,0]],"batl":[[0,1.71,542.06],[1,1.4,0],[2,1.43,0]],"ltp":1.4,"tv":203.36,"id":8174333}]}]}
{"op":"mcm","clk":"1001644000","pt":1580638818738,"mc":[{"id":"1.168224344","rc":[{"batb":[[0,1.23,521.23],[1,1.22,505.92],[2,1.21,109.76]],"batl":[[0,1.5,151.38],[1,1.51,167.98],[2,1.71,542.06]],"ltp":1.4,"tv":203.36,"id":8174333}]}]}
{"op":"mcm","clk":"1001644085","pt":1580638819772,"mc":[{"id":"1.168224344","rc":[{"batb":[[0,1.21,109.76],[1,1.01,15.51],[2,1.21,0]],"ltp":1.4,"tv":203.36,"id":8174333}]}]}
{"op":"mcm","clk":"1001644314","pt":1580638823104,"mc":[{"id":"1.168224344","rc":[{"batb":[[1,2.9,21.85],[2,1.01,15.52]],"ltp":3.5,"tv":14.12,"id":6498878},{"batb":[[0,1.46,147.05],[1,1.45,201.38],[2,1.21,109.76]],"batl":[[2,1.53,42.01]],"ltp":1.4,"tv":203.36,"id":8174333}]}]}
{"op":"mcm","clk":"1001644375","pt":1580638823886,"mc":[{"id":"1.168224344","rc":[{"batb":[[2,2.62,13.06]],"batl":[[0,3.35,17.64]],"ltp":3.5,"tv":14.12,"id":6498878},{"batb":[[2,1.43,145.22]],"ltp":1.4,"tv":203.36,"id":8174333}]}]}
{"op":"mcm","clk":"1001644529","pt":1580638825875,"mc":[{"id":"1.168224344","rc":[{"batl":[[1,4.6,136.05]],"ltp":3.5,"tv":14.12,"id":6498878}]}]}
{"op":"mcm","clk":"1001645504","pt":1580638837299,"mc":[{"id":"1.168224344","rc":[{"batb":[[0,2.9,21.85],[1,2.62,13.06],[2,1.01,15.52]],"ltp":3.5,"tv":14.12,"id":6498878},{"batb":[[0,1.43,97.46],[1,1.28,78.68],[2,1.01,15.51]],"batl":[[0,1.53,42.01],[1,1.71,542.06],[2,1.53,0]],"ltp":1.4,"tv":203.36,"id":8174333}]}]}
{"op":"mcm","clk":"1001645560","pt":1580638838117,"mc":[{"id":"1.168224344","rc":[{"batb":[[0,2.62,13.06],[1,1.01,15.52],[2,1.01,0]],"batl":[[0,4.6,136.05],[1,4.6,0]],"ltp":3.5,"tv":14.12,"id":6498878},{"batb":[[0,1.28,78.68],[1,1.01,15.51],[2,1.01,0]],"batl":[[0,1.71,542.06],[1,1.71,0]],"ltp":1.4,"tv":203.36,"id":8174333}]}]}
{"op":"mcm","clk":"1001645728","pt":1580638840321,"mc":[{"id":"1.168224344","rc":[{"batb":[[0,1.31,204.64],[1,1.3,340.46],[2,1.28,78.68]],"batl":[[0,1.64,172.82],[1,1.65,120.77],[2,1.71,542.06]],"ltp":1.4,"tv":203.36,"id":8174333}]}]}
{"op":"mcm","clk":"1001645918","pt":1580638842635,"mc":[{"id":"1.168224344","rc":[{"batb":[[0,1.28,78.68],[1,1.01,15.51],[2,1.28,0]],"ltp":1.4,"tv":203.36,"id":8174333}]}]}
{"op":"mcm","clk":"1001646161","pt":1580638845319,"mc":[{"id":"1.168224344","rc":[{"batb":[[0,1.58,223.64],[1,1.57,146.37],[2,1.28,78.68]],"batl":[[2,1.71,0]],"ltp":1.4,"tv":203.36,"id":8174333}]}]}
{"op":"mcm","clk":"1001646254","pt":1580638846317,"mc":[{"id":"1.168224344","rc":[{"batb":[[1,2.36,17.39],[2,1.01,15.52]],"ltp":3.5,"tv":14.12,"id":6498878},{"batb":[[2,1.55,34.38]],"ltp":1.4,"tv":203.36,"id":8174333}]}]}
{"op":"mcm","clk":"1001646336","pt":1580638847128,"mc":[{"id":"1.168224344","rc":[{"batb":[[1,2.54,26.89],[2,2.36,17.39]],"batl":[[0,2.9,21.85]],"ltp":3.5,"tv":14.12,"id":6498878},{"batl":[[1,1.65,162.78]],"ltp":1.4,"tv":203.36,"id":8174333}]}]}
{"op":"mcm","clk":"1001646577","pt":1580638849814,"mc":[{"id":"1.168224344","rc":[{"trd":[[2.62,25.92]],"batb":[[0,2.54,26.99],[1,2.36,17.39],[2,1.01,15.52]],"batl":[[1,3.65,170.41]],"ltp":2.62,"tv":40.04,"id":6498878},{"batl":[[2,2.04,383.01]],"ltp":1.4,"tv":203.36,"id":8174333}],"tv":243.4}]}
{"op":"mcm","clk":"1001647542","pt":1580638861325,"mc":[{"id":"1.168224344","rc":[{"batb":[[0,1.55,34.38],[1,1.53,78.98],[2,1.42,48.86]],"batl":[[0,1.65,42.01],[1,2.04,383.01],[2,2.04,0]],"ltp":1.4,"tv":203.36,"id":8174333}]}]}
{"op":"mcm","clk":"1001647656","pt":1580638862328,"mc":[{"id":"1.168224344","rc":[{"batb":[[0,2.36,17.39],[1,1.01,15.52],[2,1.01,0]],"batl":[[0,3.65,170.41],[1,3.65,0]],"ltp":2.62,"tv":40.04,"id":6498878},{"batb":[[0,1.42,48.86],[1,1.01,15.51],[2,1.42,0]],"batl":[[0,2.04,383.01],[1,2.04,0]],"ltp":1.4,"tv":203.36,"id":8174333}]}]}
{"op":"mcm","clk":"1001647831","pt":1580638864204,"mc":[{"id":"1.168224344","rc":[{"batb":[[0,1.45,263.01],[1,1.44,208.39],[2,1.42,48.86]],"batl":[[0,1.75,134.18],[1,1.77,191.82],[2,2.04,383.01]],"ltp":1.4,"tv":203.36,"id":8174333}]}]}
{"op":"mcm","clk":"1001647900","pt":1580638865031,"mc":[{"id":"1.168224344","rc":[{"batb":[[0,2.34,17.7]],"ltp":2.62,"tv":40.04,"id":6498878},{"batb":[[2,1.43,48.15]],"ltp":1.4,"tv":203.36,"id":8174333}]}]}
{"op":"mcm","clk":"1001648214","pt":1580638868842,"mc":[{"id":"1.168224344","rc":[{"batb":[[0,1.43,48.15],[1,1.01,15.51],[2,1.43,0]],"ltp":1.4,"tv":203.36,"id":8174333}]}]}
{"op":"mcm","clk":"1001648506","pt":1580638871957,"mc":[{"id":"1.168224344","rc":[{"batb":[[0,1.69,120.87],[1,1.67,231.13],[2,1.43,48.15]],"ltp":1.4,"tv":203.36,"id":8174333}]}]}
{"op":"mcm","clk":"1001648616","pt":1580638873128,"mc":[{"id":"1.168224344","rc":[{"batb":[[1,2.32,31.09],[2,2.04,26.12]],"batl":[[0,2.62,25.21]],"ltp":2.62,"tv":40.04,"id":6498878},{"batb":[[1,1.67,257.65],[2,1.62,67.22]],"batl":[[1,1.76,42.01],[2,1.77,191.82]],"ltp":1.4,"tv":203.36,"id":8174333}]}]}
{"op":"mcm","clk":"1001648773","pt":1580638874652,"mc":[{"id":"1.168224344","rc":[{"batl":[[1,3.3,191.92]],"ltp":2.62,"tv":40.04,"id":6498878}]}]}
{"op":"mcm","clk":"1001650577","pt":1580638895971,"mc":[{"id":"1.168224344","rc":[{"trd":[[1.75,100.82]],"batl":[[0,1.75,83.77]],"ltp":1.75,"tv":304.18,"id":8174333}],"tv":344.22}]}
{"op":"mcm","clk":"1001650811","pt":1580638899390,"mc":[{"id":"1.168224344","rc":[{"batl":[[0,1.75,115.59]],"ltp":1.75,"tv":304.18,"id":8174333}]}]}
{"op":"mcm","clk":"1001654726","pt":1580638950169,"mc":[{"id":"1.168224344","rc":[{"batb":[[0,2.04,26.12],[1,1.01,15.52],[2,2.04,0]],"batl":[[0,3.3,191.92],[1,3.3,0]],"ltp":2.62,"tv":40.04,"id":6498878},{"batb":[[0,1.59,31.63],[1,1.01,15.51],[2,1.62,0]],"batl":[[0,2.04,383.01],[1,1.76,0],[2,1.77,0]],"ltp":1.75,"tv":304.18,"id":8174333}]}]}
{"op":"mcm","clk":"1001654922","pt":1580638952885,"mc":[{"id":"1.168224344","rc":[{"batb":[[0,1.6,240.89],[1,1.59,171.09],[2,1.01,15.51]],"batl":[[0,1.96,160.05],[1,1.98,134.87],[2,2.04,383.01]],"ltp":1.75,"tv":304.18,"id":8174333}]}]}
{"op":"mcm","clk":"1001655603","pt":1580638960215,"mc":[{"id":"1.168224344","rc":[{"batb":[[0,1.59,31.63],[1,1.01,15.51],[2,1.01,0]],"ltp":1.75,"tv":304.18,"id":8174333}]}]}
{"op":"mcm","clk":"1001655744","pt":1580638962091,"mc":[{"id":"1.168224344","rc":[{"batl":[[2,2.04,0]],"ltp":1.75,"tv":304.18,"id":8174333}]}]}
{"op":"mcm","clk":"1001655850","pt":1580638963412,"mc":[{"id":"1.168224344","rc":[{"batb":[[0,1.87,170.56],[1,1.85,163.67],[2,1.59,31.63]],"ltp":1.75,"tv":304.18,"id":8174333}]}]}
{"op":"mcm","clk":"1001655900","pt":1580638964021,"mc":[{"id":"1.168224344","rc":[{"batb":[[1,1.75,21.32],[2,1.01,15.52]],"ltp":2.62,"tv":40.04,"id":6498878},{"batb":[[0,1.87,189.05],[2,1.72,24]],"ltp":1.75,"tv":304.18,"id":8174333}]}]}
{"op":"mcm","clk":"1001655997","pt":1580638965110,"mc":[{"id":"1.168224344","rc":[{"batb":[[0,2.04,66.45]],"batl":[[0,2.3,31.93]],"ltp":2.62,"tv":40.04,"id":6498878},{"batb":[[2,1.77,53.77]],"batl":[[0,1.96,202.06]],"ltp":1.75,"tv":304.18,"id":8174333}]}]}
{"op":"mcm","clk":"1001656101","pt":1580638966302,"mc":[{"id":"1.168224344","rc":[{"batl":[[1,2.82,231.28]],"ltp":2.62,"tv":40.04,"id":6498878},{"batl":[[2,2.42,286.52]],"ltp":1.75,"tv":304.18,"id":8174333}]}]}
{"op":"mcm","clk":"1001656664","pt":1580638973232,"mc":[{"id":"1.168224344","rc":[{"batb":[[0,2.04,40.33]],"ltp":2.62,"tv":40.04,"id":6498878},{"batb":[[0,1.77,53.77],[1,1.72,24],[2,1.01,15.51]],"batl":[[0,1.96,42.01],[1,2.42,286.52],[2,2.42,0]],"ltp":1.75,"tv":304.18,"id":8174333}]}]}
{"op":"mcm","clk":"1001656733","pt":1580638974175,"mc":[{"id":"1.168224344","rc":[{"batb":[[0,1.75,21.32],[1,1.01,15.52],[2,1.01,0]],"batl":[[0,2.82,231.28],[1,2.82,0]],"ltp":2.62,"tv":40.04,"id":6498878},{"batb":[[0,1.72,24],[1,1.01,15.51],[2,1.01,0]],"batl":[[0,2.42,286.52],[1,2.42,0]],"ltp":1.75,"tv":304.18,"id":8174333}]}]}
{"op":"mcm","clk":"1001657149","pt":1580638979188,"mc":[{"id":"1.168224344","rc":[{"batb":[[0,1.93,164.12],[1,1.91,147.81],[2,1.72,24]],"batl":[[0,2.02,117.17],[1,2.04,123.45],[2,2.42,286.52]],"ltp":1.75,"tv":304.18,"id":8174333}]}]}
{"op":"mcm","clk":"1001657170","pt":1580638979498,"mc":[{"id":"1.168224344","rc":[{"batb":[[0,1.72,24],[1,1.01,15.51],[2,1.72,0]],"batl":[[0,2.42,286.52],[1,2.04,0],[2,2.42,0]],"ltp":1.75,"tv":304.18,"id":8174333}]}]}
{"op":"mcm","clk":"1001657452","pt":1580638982125,"mc":[{"id":"1.168224344","rc":[{"batb":[[0,1.73,139.74],[1,1.72,24],[2,1.71,212.77]],"batl":[[0,2.34,127.41],[1,2.38,161.41],[2,2.42,286.52]],"ltp":1.75,"tv":304.18,"id":8174333}]}]}
{"op":"mcm","clk":"1001657733","pt":1580638985191,"mc":[{"id":"1.168224344","rc":[{"batl":[[0,2.42,286.52],[1,2.38,0],[2,2.42,0]],"ltp":1.75,"tv":304.18,"id":8174333}]}]}
{"op":"mcm","clk":"1001658030","pt":1580638988011,"mc":[{"id":"1.168224344","rc":[{"batl":[[0,1.8,168.1],[1,1.82,174.95]],"ltp":1.75,"tv":304.18,"id":8174333}]}]}
{"op":"mcm","clk":"1001658129","pt":1580638989201,"mc":[{"id":"1.168224344","rc":[{"batb":[[0,2.26,19.83],[1,2.22,33.61],[2,1.93,15.74]],"batl":[[0,2.54,26.89]],"ltp":2.62,"tv":40.04,"id":6498878},{"batl":[[1,1.82,216.96]],"ltp":1.75,"tv":304.18,"id":8174333}]}]}
{"op":"mcm","clk":"1001658315","pt":1580638991398,"mc":[{"id":"1.168224344","rc":[{"batl":[[1,3.15,200.42]],"ltp":2.62,"tv":40.04,"id":6498878},{"batl":[[2,2.22,329.01]],"ltp":1.75,"tv":304.18,"id":8174333}]}]}
{"op":"mcm","clk":"1001659135","pt":1580638999369,"mc":[{"id":"1.168224344","rc":[{"batb":[[0,2.22,33.61],[1,1.93,15.74],[2,1.01,15.52]],"ltp":2.62,"tv":40.04,"id":6498878},{"batb":[[0,1.66,63.01],[1,1.61,30.14],[2,1.01,15.51]],"batl":[[0,1.82,42.01],[1,2.22,329.01],[2,2.22,0]],"ltp":1.75,"tv":304.18,"id":8174333}]}]}
{"op":"mcm","clk":"1001659223","pt":1580639000230,"mc":[{"id":"1.168224344","rc":[{"batb":[[0,1.93,15.74],[1,1.01,15.52],[2,1.01,0]],"batl":[[0,3.15,200.42],[1,3.15,0]],"ltp":2.62,"tv":40.04,"id":6498878},{"batb":[[0,1.61,30.14],[1,1.01,15.51],[2,1.01,0]],"batl":[[0,2.22,329.01],[1,2.22,0]],"ltp":1.75,"tv":304.18,"id":8174333}]}]}
{"op":"mcm","clk":"1001659448","pt":1580639002821,"mc":[{"id":"1.168224344","rc":[{"batb":[[0,1.62,147.8],[1,1.61,162.93],[2,1.01,15.51]],"batl":[[0,2.08,153.42],[1,2.1,113.47],[2,2.22,329.01]],"ltp":1.75,"tv":304.18,"id":8174333}]}]}
{"op":"mcm","clk":"1001660457","pt":1580639008243,"mc":[{"id":"1.168224344","rc":[{"batl":[[0,2.22,329.01],[1,2.1,0],[2,2.22,0]],"ltp":1.75,"tv":304.18,"id":8174333}]}]}
{"op":"mcm","clk":"1001660947","pt":1580639011366,"mc":[{"id":"1.168224344","rc":[{"batl":[[0,1.68,188.16],[1,1.7,218.92]],"ltp":1.75,"tv":304.18,"id":8174333}]}]}
{"op":"mcm","clk":"1001661074","pt":1580639012157,"mc":[{"id":"1.168224344","rc":[{"batb":[[0,2.48,15.26],[1,2.16,22.42],[2,1.01,15.52]],"ltp":2.62,"tv":40.04,"id":6498878},{"batb":[[2,1.54,36.04]],"ltp":1.75,"tv":304.18,"id":8174333}]}]}
{"op":"mcm","clk":"1001661208","pt":1580639013247,"mc":[{"id":"1.168224344","rc":[{"batl":[[0,2.78,23.53]],"ltp":2.62,"tv":40.04,"id":6498878},{"batb":[[2,1.57,73.1]],"ltp":1.75,"tv":304.18,"id":8174333}]}]}
{"op":"mcm","clk":"1001661278","pt":1580639013765,"mc":[{"id":"1.168224344","rc":[{"batl":[[1,3.65,170.41]],"ltp":2.62,"tv":40.04,"id":6498878},{"batl":[[2,2.04,383.01]],"ltp":1.75,"tv":304.18,"id":8174333}]}]}
{"op":"mcm","clk":"1001661695","pt":1580639017839,"mc":[{"id":"1.168224344","rc":[{"batb":[[1,2.42,29.41],[2,2.16,22.42]],"ltp":2.62,"tv":40.04,"id":6498878},{"batl":[[1,1.69,42.01],[2,1.7,218.92]],"ltp":1.75,"tv":304.18,"id":8174333}]}]}
{"op":"mcm","clk":"1001662658","pt":1580639027381,"mc":[{"id":"1.168224344","rc":[{"batb":[[0,2.42,29.41],[1,2.16,22.42],[2,1.01,15.52]],"ltp":2.62,"tv":40.04,"id":6498878},{"batb":[[0,1.57,73.1],[1,1.54,36.04],[2,1.01,15.51]],"batl":[[0,1.69,42.01],[1,2.04,383.01],[2,1.7,0]],"ltp":1.75,"tv":304.18,"id":8174333}]}]}
{"op":"mcm","clk":"1001662754","pt":1580639028274,"mc":[{"id":"1.168224344","rc":[{"batb":[[0,2.16,22.42],[1,1.01,15.52],[2,1.01,0]],"batl":[[0,3.65,170.41],[1,3.65,0]],"ltp":2.62,"tv":40.04,"id":6498878},{"batb":[[0,1.54,36.04],[1,1.01,15.51],[2,1.01,0]],"batl":[[0,2.04,383.01],[1,2.04,0]],"ltp":1.75,"tv":304.18,"id":8174333}]}]}
{"op":"mcm","clk":"1001662989","pt":1580639030212,"mc":[{"id":"1.168224344","rc":[{"batb":[[0,1.55,137.25],[1,1.54,193.22],[2,1.01,15.51]],"ltp":1.75,"tv":304.18,"id":8174333}]}]}
{"op":"mcm","clk":"1001663350","pt":1580639033297,"mc":[{"id":"1.168224344","rc":[{"batl":[[0,1.6,171.15],[1,1.61,131.69],[2,2.04,383.01]],"ltp":1.75,"tv":304.18,"id":8174333}]}]}
{"op":"mcm","clk":"1001663471","pt":1580639034410,"mc":[{"id":"1.168224344","rc":[{"batb":[[0,2.68,12.35],[1,2.44,15.82],[2,1.01,15.52]],"ltp":2.62,"tv":40.04,"id":6498878},{"batb":[[2,1.5,39.73]],"ltp":1.75,"tv":304.18,"id":8174333}]}]}
{"op":"mcm","clk":"1001663584","pt":1580639035204,"mc":[{"id":"1.168224344","rc":[{"batb":[[1,2.58,26.05],[2,2.44,15.82]],"batl":[[0,2.98,21],[1,3.65,170.41]],"ltp":2.62,"tv":40.04,"id":6498878},{"batb":[[2,1.51,82.34]],"batl":[[2,1.63,42.01]],"ltp":1.75,"tv":304.18,"id":8174333}]}]}
{"op":"mcm","clk":"1001664306","pt":1580639040978,"mc":[{"id":"1.168224344","rc":[{"trd":[[1.6,5.04]],"batl":[[0,1.6,168.63]],"ltp":1.6,"tv":309.22,"id":8174333}],"tv":349.26}]}
{"op":"mcm","clk":"1001664491","pt":1580639042293,"mc":[{"id":"1.168224344","rc":[{"batb":[[0,1.54,36.04],[1,1.51,82.34],[2,1.5,39.73]],"batl":[[0,1.63,42.01],[1,2.04,383.01],[2,1.63,0]],"ltp":1.6,"tv":309.22,"id":8174333}]}]}
{"op":"mcm","clk":"1001664581","pt":1580639042919,"mc":[{"id":"1.168224344","rc":[{"batb":[[0,2.58,26.05],[1,2.44,15.82],[2,1.01,15.52]],"ltp":2.62,"tv":40.04,"id":6498878},{"batb":[[0,1.51,82.34],[1,1.5,39.73],[2,1.01,15.51]],"ltp":1.6,"tv":309.22,"id":8174333}]}]}
{"op":"mcm","clk":"1001664739","pt":1580639044321,"mc":[{"id":"1.168224344","rc":[{"batb":[[0,2.44,15.82],[1,1.01,15.52],[2,1.01,0]],"batl":[[0,3.65,170.41],[1,3.65,0]],"ltp":2.62,"tv":40.04,"id":6498878},{"batb":[[0,1.5,39.73],[1,1.01,15.51],[2,1.01,0]],"batl":[[0,2.04,383.01],[1,2.04,0]],"ltp":1.6,"tv":309.22,"id":8174333}]}]}
{"op":"mcm","clk":"1001664845","pt":1580639045258,"mc":[{"id":"1.168224344","rc":[{"batb":[[0,1.51,276.07],[1,1.5,215.07],[2,1.01,15.51]],"batl":[[0,1.68,227.15],[1,1.7,218.72],[2,2.04,383.01]],"ltp":1.6,"tv":309.22,"id":8174333}]}]}
{"op":"mcm","clk":"1001665043","pt":1580639046792,"mc":[{"id":"1.168224344","rc":[{"batl":[[0,2.04,383.01],[1,1.7,0],[2,2.04,0]],"ltp":1.6,"tv":309.22,"id":8174333}]}]}
{"op":"mcm","clk":"1001665474","pt":1580639050405,"mc":[{"id":"1.168224344","rc":[{"batb":[[0,2.8,10.94],[1,2.54,14.4],[2,2.44,15.82]],"ltp":2.62,"tv":40.04,"id":6498878},{"batb":[[2,1.38,56.65]],"batl":[[0,1.57,246.06],[1,1.58,140.67],[2,1.63,710.5]],"ltp":1.6,"tv":309.22,"id":8174333}]}]}
{"op":"mcm","clk":"1001665563","pt":1580639051235,"mc":[{"id":"1.168224344","rc":[{"batb":[[1,2.7,24.37],[2,2.54,14.4]],"batl":[[0,3.15,19.32]],"ltp":2.62,"tv":40.04,"id":6498878},{"batb":[[2,1.47,89.06]],"batl":[[2,1.59,42.01]],"ltp":1.6,"tv":309.22,"id":8174333}]}]}
{"op":"mcm","clk":"1001665746","pt":1580639053103,"mc":[{"id":"1.168224344","rc":[{"batl":[[1,4.2,148.03]],"ltp":2.62,"tv":40.04,"id":6498878}]}]}
{"op":"mcm","clk":"1001667730","pt":1580639071371,"mc":[{"id":"1.168224344","rc":[{"batb":[[0,2.7,24.37],[1,2.54,14.4],[2,1.01,15.52]],"ltp":2.62,"tv":40.04,"id":6498878},{"batb":[[0,1.47,89.06],[1,1.38,56.65],[2,1.01,15.51]],"batl":[[0,1.59,42.01],[1,1.89,435.28],[2,1.59,0]],"ltp":1.6,"tv":309.22,"id":8174333}]}]}
{"op":"mcm","clk":"1001667837","pt":1580639072252,"mc":[{"id":"1.168224344","rc":[{"batb":[[0,2.54,14.4],[1,1.01,15.52],[2,1.01,0]],"batl":[[0,4.2,148.03],[1,4.2,0]],"ltp":2.62,"tv":40.04,"id":6498878},{"batb":[[0,1.38,56.65],[1,1.01,15.51],[2,1.01,0]],"batl":[[0,1.89,435.28],[1,1.89,0]],"ltp":1.6,"tv":309.22,"id":8174333}]}]}
{"op":"mcm","clk":"1001668034","pt":1580639073978,"mc":[{"id":"1.168224344","rc":[{"batb":[[0,1.4,197.99],[1,1.39,243.17],[2,1.38,56.65]],"batl":[[0,1.66,119.36],[1,1.67,115.88],[2,1.89,435.28]],"ltp":1.6,"tv":309.22,"id":8174333}]}]}
{"op":"mcm","clk":"1001668262","pt":1580639076384,"mc":[{"id":"1.168224344","rc":[{"batb":[[0,1.38,56.65],[1,1.01,15.51],[2,1.38,0]],"batl":[[0,1.89,435.28],[1,1.67,0],[2,1.89,0]],"ltp":1.6,"tv":309.22,"id":8174333}]}]}
{"op":"mcm","clk":"1001668559","pt":1580639079403,"mc":[{"id":"1.168224344","rc":[{"batb":[[0,1.4,197.99],[1,1.39,243.17],[2,1.38,56.65]],"batl":[[0,1.44,221.56],[1,1.45,197.11]],"ltp":1.6,"tv":309.22,"id":8174333}]}]}
{"op":"mcm","clk":"1001668644","pt":1580639080201,"mc":[{"id":"1.168224344","rc":[{"batb":[[0,3.35,17.62],[1,2.88,10.31],[2,1.01,15.52]],"ltp":2.62,"tv":40.04,"id":6498878}]}]}
{"op":"mcm","clk":"1001668740","pt":1580639081261,"mc":[{"id":"1.168224344","rc":[{"batb":[[1,3.1,19.32],[2,2.88,10.31]],"batl":[[0,3.65,15.12]],"ltp":2.62,"tv":40.04,"id":6498878},{"batb":[[2,1.38,166.72]],"batl":[[2,1.47,42.01]],"ltp":1.6,"tv":309.22,"id":8174333}]}]}
{"op":"mcm","clk":"1001668837","pt":1580639082356,"mc":[{"id":"1.168224344","rc":[{"batl":[[1,5.3,118.79]],"ltp":2.62,"tv":40.04,"id":6498878}]}]}
{"op":"mcm","clk":"1001669942","pt":1580639093258,"mc":[{"id":"1.168224344","rc":[{"batb":[[0,3.1,19.32],[1,2.88,10.31],[2,1.01,15.52]],"ltp":2.62,"tv":40.04,"id":6498878},{"batb":[[0,1.38,110.07],[1,1.26,88.05],[2,1.01,15.51]],"batl":[[0,1.47,42.01],[1,1.73,527.57],[2,1.47,0]],"ltp":1.6,"tv":309.22,"id":8174333}]}]}
{"op":"mcm","clk":"1001670059","pt":1580639094294,"mc":[{"id":"1.168224344","rc":[{"batb":[[0,2.88,10.31],[1,1.01,15.52],[2,1.01,0]],"batl":[[0,5.3,118.79],[1,5.3,0]],"ltp":2.62,"tv":40.04,"id":6498878},{"batb":[[0,1.26,88.05],[1,1.01,15.51],[2,1.01,0]],"batl":[[0,1.73,527.57],[1,1.73,0]],"ltp":1.6,"tv":309.22,"id":8174333}]}]}
{"op":"mcm","clk":"1001670235","pt":1580639096111,"mc":[{"id":"1.168224344","rc":[{"batb":[[0,1.28,291.39],[1,1.27,388.64],[2,1.26,88.05]],"batl":[[0,1.55,267.78],[1,1.56,147.38],[2,1.73,527.57]],"ltp":1.6,"tv":309.22,"id":8174333}]}]}
{"op":"mcm","clk":"1001671272","pt":1580639106178,"mc":[{"id":"1.168224344","rc":[{"batb":[[0,1.26,88.05],[1,1.01,15.51],[2,1.26,0]],"batl":[[0,1.73,527.57],[1,1.56,0],[2,1.73,0]],"ltp":1.6,"tv":309.22,"id":8174333}]}]}
{"op":"mcm","clk":"1001671602","pt":1580639109291,"mc":[{"id":"1.168224344","rc":[{"batb":[[0,1.37,323.12],[1,1.36,271.14],[2,1.26,88.05]],"batl":[[0,1.41,180.64],[1,1.42,215.9],[2,1.73,527.57]],"ltp":1.6,"tv":309.22,"id":8174333}]}]}
{"op":"mcm","clk":"1001671633","pt":1580639109600,"mc":[{"id":"1.168224344","rc":[{"batb":[[0,1.37,259.02],[1,1.26,88.05],[2,1.01,15.51]],"batl":[[0,1.42,177.14],[1,1.73,527.57],[2,1.73,0]],"ltp":1.6,"tv":309.22,"id":8174333}]}]}
{"op":"mcm","clk":"1001671967","pt":1580639112889,"mc":[{"id":"1.168224344","rc":[{"batb":[[0,1.26,88.05],[1,1.01,15.51],[2,1.01,0]],"batl":[[0,1.73,527.57],[1,1.73,0]],"ltp":1.6,"tv":309.22,"id":8174333}]}]}
{"op":"mcm","clk":"1001672330","pt":1580639116218,"mc":[{"id":"1.168224344","rc":[{"batb":[[0,1.29,304.59],[1,1.28,365.91],[2,1.26,88.05]],"ltp":1.6,"tv":309.22,"id":8174333}]}]}
{"op":"mcm","clk":"1001672635","pt":1580639119348,"mc":[{"id":"1.168224344","rc":[{"batb":[[0,4.2,19.28],[1,3.85,14.28],[2,3.55,14.87]],"batl":[[0,4.6,10.92]],"ltp":2.62,"tv":40.04,"id":6498878},{"batb":[[2,1.27,155.44]],"batl":[[0,1.32,173.84],[1,1.33,287.87],[2,1.35,42.01]],"ltp":1.6,"tv":309.22,"id":8174333}]}]}
{"op":"mcm","clk":"1001672944","pt":1580639122213,"mc":[{"id":"1.168224344","rc":[{"batl":[[1,6.6,98.95]],"ltp":2.62,"tv":40.04,"id":6498878}]}]}
{"op":"mcm","clk":"1001673819","pt":1580639131134,"mc":[{"id":"1.168224344","rc":[{"batb":[[0,1.27,155.44],[1,1.26,88.05],[2,1.16,147.76]],"batl":[[0,1.35,42.01],[1,1.62,614.4],[2,1.35,0]],"ltp":1.6,"tv":309.22,"id":8174333}]}]}
{"op":"mcm","clk":"1001673959","pt":1580639132388,"mc":[{"id":"1.168224344","rc":[{"batb":[[0,3.55,14.87],[1,1.01,15.52],[2,3.55,0]],"batl":[[0,6.6,98.95],[1,6.6,0]],"ltp":2.62,"tv":40.04,"id":6498878},{"batb":[[0,1.16,147.76],[1,1.01,15.51],[2,1.16,0]],"batl":[[0,1.62,614.4],[1,1.62,0]],"ltp":1.6,"tv":309.22,"id":8174333}]}]}
{"op":"mcm","clk":"1001674423","pt":1580639137178,"mc":[{"id":"1.168224344","rc":[{"batb":[[0,1.27,233.35],[1,1.26,399.3],[2,1.16,147.76]],"batl":[[0,1.3,313.64],[1,1.31,308.51],[2,1.62,614.4]],"ltp":1.6,"tv":309.22,"id":8174333}]}]}
{"op":"mcm","clk":"1001674638","pt":1580639139271,"mc":[{"id":"1.168224344","rc":[{"batb":[[0,1.27,198.45]],"ltp":1.6,"tv":309.22,"id":8174333}]}]}
{"op":"mcm","clk":"1001674780","pt":1580639140370,"mc":[{"id":"1.168224344","rc":[{"batb":[[0,1.16,147.76],[1,1.01,15.51],[2,1.16,0]],"batl":[[0,1.62,614.4],[1,1.31,0],[2,1.62,0]],"ltp":1.6,"tv":309.22,"id":8174333}]}]}
{"op":"mcm","clk":"1001675150","pt":1580639143669,"mc":[{"id":"1.168224344","rc":[{"batb":[[0,1.19,197.11],[1,1.18,617.54],[2,1.16,147.76]],"batl":[[0,1.41,153.18],[1,1.42,213.37],[2,1.62,614.4]],"ltp":1.6,"tv":309.22,"id":8174333}]}]}
{"op":"mcm","clk":"1001677566","pt":1580639164273,"mc":[{"id":"1.168224344","rc":[{"batl":[[0,1.62,614.4],[1,1.42,0],[2,1.62,0]],"ltp":1.6,"tv":309.22,"id":8174333}]}]}
{"op":"mcm","clk":"1001677913","pt":1580639167361,"mc":[{"id":"1.168224344","rc":[{"batl":[[0,6.4,7.56]],"ltp":2.62,"tv":40.04,"id":6498878},{"batb":[[1,1.18,785.58]],"batl":[[0,1.21,331.52],[1,1.22,464.82]],"ltp":1.6,"tv":309.22,"id":8174333}]}]}
{"op":"mcm","clk":"1001677997","pt":1580639168060,"mc":[{"id":"1.168224344","rc":[{"batb":[[0,5.9,17.86],[1,5.2,9.24],[2,5,13.3]],"ltp":2.62,"tv":40.04,"id":6498878},{"batl":[[2,1.24,42.01]],"ltp":1.6,"tv":309.22,"id":8174333}]}]}
{"op":"mcm","clk":"1001678215","pt":1580639169949,"mc":[{"id":"1.168224344","rc":[{"batl":[[1,11.5,70.11]],"ltp":2.62,"tv":40.04,"id":6498878}]}]}
{"op":"mcm","clk":"1001680005","pt":1580639185365,"mc":[{"id":"1.168224344","rc":[{"batb":[[0,1.18,168.04],[1,1.16,147.76],[2,1.11,223.77]],"batl":[[0,1.24,42.01],[1,1.47,803.22],[2,1.24,0]],"ltp":1.6,"tv":309.22,"id":8174333}]}]}
{"op":"mcm","clk":"1001680104","pt":1580639186414,"mc":[{"id":"1.168224344","rc":[{"batb":[[0,5,13.3],[1,1.01,15.52],[2,5,0]],"batl":[[0,11.5,70.11],[1,11.5,0]],"ltp":2.62,"tv":40.04,"id":6498878},{"batb":[[0,1.11,223.77],[1,1.01,15.51],[2,1.11,0]],"batl":[[0,1.47,803.22],[1,1.47,0]],"ltp":1.6,"tv":309.22,"id":8174333}]}]}
{"op":"mcm","clk":"1001680339","pt":1580639188260,"mc":[{"id":"1.168224344","rc":[{"batb":[[0,1.13,296.28],[1,1.12,851.72],[2,1.11,223.77]],"batl":[[0,1.26,271.84],[1,1.27,366.47],[2,1.47,803.22]],"ltp":1.6,"tv":309.22,"id":8174333}]}]}
{"op":"mcm","clk":"1001681014","pt":1580639192284,"mc":[{"id":"1.168224344","rc":[{"batl":[[0,1.47,803.22],[1,1.27,0],[2,1.47,0]],"ltp":1.6,"tv":309.22,"id":8174333}]}]}
{"op":"mcm","clk":"1001681455","pt":1580639195370,"mc":[{"id":"1.168224344","rc":[{"batl":[[0,9.4,4.2]],"ltp":2.62,"tv":40.04,"id":6498878},{"batb":[[1,1.12,1019.76]],"batl":[[0,1.15,723.35],[1,1.16,393.86]],"ltp":1.6,"tv":309.22,"id":8174333}]}]}
{"op":"mcm","clk":"1001681568","pt":1580639196165,"mc":[{"id":"1.168224344","rc":[{"batb":[[0,8,9.13],[1,7.2,6.72],[2,5.8,18.96]],"ltp":2.62,"tv":40.04,"id":6498878},{"batl":[[1,1.16,435.87]],"ltp":1.6,"tv":309.22,"id":8174333}]}]}
{"op":"mcm","clk":"1001681779","pt":1580639198269,"mc":[{"id":"1.168224344","rc":[{"batl":[[1,17,57.33]],"ltp":2.62,"tv":40.04,"id":6498878},{"batl":[[2,1.4,927.7]],"ltp":1.6,"tv":309.22,"id":8174333}]}]}
{"op":"mcm","clk":"1001682077","pt":1580639200988,"mc":[{"id":"1.168224344","rc":[{"batb":[[2,1.11,223.54]],"ltp":1.6,"tv":309.22,"id":8174333}]}]}
{"op":"mcm","clk":"1001688957","pt":1580639254032,"mc":[{"id":"1.168224344","rc":[{"batb":[[0,1.13,263.73]],"batl":[[1,1.16,404.08]],"ltp":1.6,"tv":309.22,"id":8174333}]}]}
{"op":"mcm","clk":"1001689267","pt":1580639256925,"mc":[{"id":"1.168224344","rc":[{"batb":[[1,1.12,1052.61]],"batl":[[0,1.15,755.42]],"ltp":1.6,"tv":309.22,"id":8174333}]}]}
{"op":"mcm","clk":"1001690607","pt":1580639269250,"mc":[{"id":"1.168224344","rc":[{"batb":[[0,1.12,168.04],[1,1.11,223.54],[2,1.08,293.72]],"batl":[[0,1.16,42.01],[1,1.4,927.7],[2,1.4,0]],"ltp":1.6,"tv":309.22,"id":8174333}]}]}
{"op":"mcm","clk":"1001690707","pt":1580639270235,"mc":[{"id":"1.168224344","rc":[{"batb":[[0,7.2,6.72],[1,5.8,18.96],[2,1.01,15.52]],"ltp":2.62,"tv":40.04,"id":6498878},{"batb":[[1,1.08,293.72],[2,1.01,15.51]],"ltp":1.6,"tv":309.22,"id":8174333}]}]}
{"op":"mcm","clk":"1001690754","pt":1580639270649,"mc":[{"id":"1.168224344","rc":[{"batb":[[0,5.8,18.96],[1,1.01,15.52],[2,1.01,0]],"batl":[[0,17,57.33],[1,17,0]],"ltp":2.62,"tv":40.04,"id":6498878},{"batb":[[0,1.08,293.72],[1,1.01,15.51],[2,1.01,0]],"batl":[[0,1.4,927.7],[1,1.4,0]],"ltp":1.6,"tv":309.22,"id":8174333}]}]}
{"op":"mcm","clk":"1001690923","pt":1580639272271,"mc":[{"id":"1.168224344","rc":[{"batb":[[0,1.1,621.67],[1,1.09,554.95],[2,1.08,293.72]],"batl":[[0,1.21,427.84],[1,1.22,463.69],[2,1.4,927.7]],"ltp":1.6,"tv":309.22,"id":8174333}]}]}
{"op":"mcm","clk":"1001691021","pt":1580639273052,"mc":[{"id":"1.168224344","rc":[{"batb":[[0,1.08,293.72],[1,1.01,15.51],[2,1.08,0]],"batl":[[0,1.4,927.7],[1,1.22,0],[2,1.4,0]],"ltp":1.6,"tv":309.22,"id":8174333}]}]}
{"op":"mcm","clk":"1001691378","pt":1580639276270,"mc":[{"id":"1.168224344","rc":[{"batb":[[0,1.14,334.49],[1,1.13,803.01],[2,1.08,293.72]],"batl":[[0,1.16,586.5],[1,1.17,519.99],[2,1.4,927.7]],"ltp":1.6,"tv":309.22,"id":8174333}]}]}
{"op":"mcm","clk":"1001691689","pt":1580639279289,"mc":[{"id":"1.168224344","rc":[{"batl":[[0,14,62.58]],"ltp":2.62,"tv":40.04,"id":6498878},{"batb":[[0,1.08,293.72],[1,1.01,15.51],[2,1.08,0]],"batl":[[0,1.4,927.7],[1,1.17,0],[2,1.4,0]],"ltp":1.6,"tv":309.22,"id":8174333}]}]}
{"op":"mcm","clk":"1001691999","pt":1580639282187,"mc":[{"id":"1.168224344","rc":[{"batb":[[0,1.1,621.19],[1,1.09,555.43],[2,1.08,293.72]],"batl":[[0,1.21,428.28],[1,1.22,463.69],[2,1.4,927.7]],"ltp":1.6,"tv":309.22,"id":8174333}]}]}
{"op":"mcm","clk":"1001692829","pt":1580639290588,"mc":[{"id":"1.168224344","rc":[{"batb":[[0,1.08,293.72],[1,1.01,15.51],[2,1.08,0]],"ltp":1.6,"tv":309.22,"id":8174333}]}]}
{"op":"mcm","clk":"1001693234","pt":1580639294411,"mc":[{"id":"1.168224344","rc":[{"batb":[[1,4.2,20.22],[2,1.01,15.52]],"ltp":2.62,"tv":40.04,"id":6498878},{"batb":[[0,1.18,712.93],[1,1.17,524.63],[2,1.12,195.29]],"ltp":1.6,"tv":309.22,"id":8174333}]}]}
{"op":"mcm","clk":"1001693352","pt":1580639295406,"mc":[{"id":"1.168224344","rc":[{"batb":[[1,5.6,8.4],[2,4.2,20.22]],"batl":[[0,7,6.72]],"ltp":2.62,"tv":40.04,"id":6498878},{"batb":[[1,1.17,692.67]],"batl":[[1,1.22,505.7]],"ltp":1.6,"tv":309.22,"id":8174333}]}]}
{"op":"mcm","clk":"1001693580","pt":1580639297405,"mc":[{"id":"1.168224344","rc":[{"batl":[[1,11.5,70.11]],"ltp":2.62,"tv":40.04,"id":6498878}]}]}
{"op":"mcm","clk":"1001694369","pt":1580639304310,"mc":[{"id":"1.168224344","rc":[{"batb":[[0,5.6,8.4],[1,4.2,20.22],[2,1.01,15.52]],"ltp":2.62,"tv":40.04,"id":6498878},{"batb":[[0,1.17,168.04],[1,1.12,195.29],[2,1.01,15.51]],"batl":[[0,1.22,42.01],[1,1.4,927.7],[2,1.4,0]],"ltp":1.6,"tv":309.22,"id":8174333}]}]}
{"op":"mcm","clk":"1001694390","pt":1580639304527,"mc":[{"id":"1.168224344","rc":[{"batb":[[0,4.2,20.22],[1,1.01,15.52],[2,1.01,0]],"batl":[[0,11.5,70.11],[1,11.5,0]],"ltp":2.62,"tv":40.04,"id":6498878},{"batb":[[0,1.12,195.29],[1,1.01,15.51],[2,1.01,0]],"batl":[[0,1.4,927.7],[1,1.4,0]],"ltp":1.6,"tv":309.22,"id":8174333}]}]}
{"op":"mcm","clk":"1001694684","pt":1580639307221,"mc":[{"id":"1.168224344","rc":[{"batb":[[0,1.14,479.66],[1,1.13,656.56],[2,1.12,195.29]],"batl":[[0,1.32,426.19],[1,1.33,285.52],[2,1.4,927.7]],"ltp":1.6,"tv":309.22,"id":8174333}]}]}
{"op":"mcm","clk":"1001695040","pt":1580639310362,"mc":[{"id":"1.168224344","rc":[{"batl":[[0,1.4,927.7],[1,1.33,0],[2,1.4,0]],"ltp":1.6,"tv":309.22,"id":8174333}]}]}
{"op":"mcm","clk":"1001695370","pt":1580639313330,"mc":[{"id":"1.168224344","rc":[{"batl":[[0,1.16,457.27],[1,1.17,622.4],[2,1.4,927.7]],"ltp":1.6,"tv":309.22,"id":8174333}]}]}
{"op":"mcm","clk":"1001695475","pt":1580639314267,"mc":[{"id":"1.168224344","rc":[{"batb":[[0,7.2,11.41],[1,5.1,12.67],[2,1.01,15.52]],"ltp":2.62,"tv":40.04,"id":6498878},{"batb":[[0,1.14,317.57]],"batl":[[1,1.17,490.13]],"ltp":1.6,"tv":309.22,"id":8174333}]}]}
{"op":"mcm","clk":"1001695683","pt":1580639316372,"mc":[{"id":"1.168224344","rc":[{"batb":[[1,6.8,6.72],[2,5.1,12.67]],"batl":[[0,8.8,5.04],[1,14,62.58]],"ltp":2.62,"tv":40.04,"id":6498878},{"batb":[[1,1.13,824.6]],"batl":[[1,1.17,532.14]],"ltp":1.6,"tv":309.22,"id":8174333}]}]}
{"op":"mcm","clk":"1001695741","pt":1580639316890,"mc":[{"id":"1.168224344","rc":[{"batb":[[0,1.14,245.98],[1,1.13,988.13]],"batl":[[0,1.16,616.62],[1,1.17,462.38]],"ltp":1.6,"tv":309.22,"id":8174333}]}]}
{"op":"mcm","clk":"1001695976","pt":1580639319059,"mc":[{"id":"1.168224344","rc":[{"trd":[[1.14,491.96]],"batb":[[0,1.13,988.13],[1,1.12,195.29],[2,1.09,278.85]],"batl":[[1,1.17,374.51]],"ltp":1.14,"tv":801.18,"id":8174333}],"tv":841.22}]}
{"op":"mcm","clk":"1001696078","pt":1580639320052,"mc":[{"id":"1.168224344","rc":[{"batb":[[0,1.13,1060.35]],"batl":[[0,1.16,686.98]],"ltp":1.14,"tv":801.18,"id":8174333}]}]}
{"op":"mcm","clk":"1001696274","pt":1580639321874,"mc":[{"id":"1.168224344","rc":[{"batb":[[0,1.13,1239.51]],"batl":[[0,1.16,775.61]],"ltp":1.14,"tv":801.18,"id":8174333}]}]}
{"op":"mcm","clk":"1001696432","pt":1580639323270,"mc":[{"id":"1.168224344","rc":[{"batb":[[0,6.8,6.72],[1,5.1,12.67],[2,1.01,15.52]],"ltp":2.62,"tv":40.04,"id":6498878},{"batb":[[0,1.13,168.04],[1,1.09,278.85],[2,1.01,15.51]],"batl":[[0,1.17,42.01],[1,1.4,927.7],[2,1.4,0]],"ltp":1.14,"tv":801.18,"id":8174333}]}]}
{"op":"mcm","clk":"1001696605","pt":1580639324893,"mc":[{"id":"1.168224344","rc":[{"batb":[[0,5.1,12.67],[1,1.01,15.52],[2,1.01,0]],"batl":[[0,14,62.58],[1,14,0]],"ltp":2.62,"tv":40.04,"id":6498878},{"batb":[[0,1.09,278.85],[1,1.01,15.51],[2,1.01,0]],"batl":[[0,1.4,927.7],[1,1.4,0]],"ltp":1.14,"tv":801.18,"id":8174333}]}]}
{"op":"mcm","clk":"1001696722","pt":1580639325845,"mc":[{"id":"1.168224344","rc":[{"batb":[[0,1.1,744.75],[1,1.09,709.58],[2,1.01,15.51]],"batl":[[0,1.24,452.46],[1,1.25,406.64],[2,1.4,927.7]],"ltp":1.14,"tv":801.18,"id":8174333}]}]}
{"op":"mcm","clk":"1001696948","pt":1580639327987,"mc":[{"id":"1.168224344","rc":[{"batb":[[0,1.09,278.85],[1,1.01,15.51],[2,1.01,0]],"ltp":1.14,"tv":801.18,"id":8174333}]}]}
{"op":"mcm","clk":"1001697341","pt":1580639331173,"mc":[{"id":"1.168224344","rc":[{"batb":[[0,1.21,456.88],[1,1.2,566.67],[2,1.09,278.85]],"ltp":1.14,"tv":801.18,"id":8174333}]}]}
{"op":"mcm","clk":"1001697423","pt":1580639331762,"mc":[{"id":"1.168224344","rc":[{"batb":[[1,5,10.08],[2,3.55,15.19]],"batl":[[0,6.2,7.56]],"ltp":2.62,"tv":40.04,"id":6498878},{"batb":[[1,1.2,683.59],[2,1.19,168.04]],"batl":[[1,1.25,448.65]],"ltp":1.14,"tv":801.18,"id":8174333}]}]}
{"op":"mcm","clk":"1001697732","pt":1580639334403,"mc":[{"id":"1.168224344","rc":[{"batl":[[1,8.6,81.89]],"ltp":2.62,"tv":40.04,"id":6498878}]}]}
{"op":"mcm","clk":"1001698837","pt":1580639343102,"mc":[{"id":"1.168224344","rc":[{"batb":[[0,5,10.08],[1,3.55,15.19],[2,1.01,15.52]],"ltp":2.62,"tv":40.04,"id":6498878},{"batb":[[0,1.19,168.04],[1,1.14,172.94],[2,1.01,15.51]],"batl":[[0,1.25,42.01],[1,1.4,927.7],[2,1.4,0]],"ltp":1.14,"tv":801.18,"id":8174333}]}]}
{"op":"mcm","clk":"1001699020","pt":1580639344502,"mc":[{"id":"1.168224344","rc":[{"batb":[[0,3.55,15.19],[1,1.01,15.52],[2,1.01,0]],"batl":[[0,8.6,81.89],[1,8.6,0]],"ltp":2.62,"tv":40.04,"id":6498878},{"batb":[[0,1.14,172.94],[1,1.01,15.51],[2,1.01,0]],"batl":[[0,1.4,927.7],[1,1.4,0]],"ltp":1.14,"tv":801.18,"id":8174333}]}]}
{"op":"mcm","clk":"1001699156","pt":1580639345613,"mc":[{"id":"1.168224344","rc":[{"batb":[[0,1.15,463.3],[1,1.14,836.04],[2,1.01,15.51]],"batl":[[0,1.39,314.39],[1,1.4,1157.64]],"ltp":1.14,"tv":801.18,"id":8174333}]}]}
{"op":"mcm","clk":"1001699462","pt":1580639348136,"mc":[{"id":"1.168224344","rc":[{"batb":[[0,1.14,172.94],[1,1.01,15.51],[2,1.01,0]],"batl":[[0,1.4,927.7],[1,1.4,0]],"ltp":1.14,"tv":801.18,"id":8174333}]}]}
{"op":"mcm","clk":"1001699853","pt":1580639351305,"mc":[{"id":"1.168224344","rc":[{"batb":[[0,1.24,158.15],[1,1.23,472.85],[2,1.14,172.94]],"batl":[[0,1.27,377.9]],"ltp":1.14,"tv":801.18,"id":8174333}]}]}
{"op":"mcm","clk":"1001700199","pt":1580639354300,"mc":[{"id":"1.168224344","rc":[{"batb":[[0,1.14,172.94],[1,1.01,15.51],[2,1.14,0]],"batl":[[0,1.26,169.18]],"ltp":1.14,"tv":801.18,"id":8174333}]}]}
{"op":"mcm","clk":"1001700230","pt":1580639354500,"mc":[{"id":"1.168224344","rc":[{"batl":[[0,7.8,87.91]],"ltp":2.62,"tv":40.04,"id":6498878},{"batl":[[0,1.56,675.59]],"ltp":1.14,"tv":801.18,"id":8174333}]}]}
{"op":"mcm","clk":"1001700517","pt":1580639357122,"mc":[{"id":"1.168224344","rc":[{"batb":[[0,1.15,424.76],[1,1.14,874.91],[2,1.01,15.51]],"batl":[[0,1.39,346.01],[1,1.4,230.03],[2,1.56,675.59]],"ltp":1.14,"tv":801.18,"id":8174333}]}]}
{"op":"mcm","clk":"1001700898","pt":1580639360139,"mc":[{"id":"1.168224344","rc":[{"batb":[[0,1.14,172.94],[1,1.01,15.51],[2,1.01,0]],"ltp":1.14,"tv":801.18,"id":8174333}]}]}
{"op":"mcm","clk":"1001701301","pt":1580639363413,"mc":[{"id":"1.168224344","rc":[{"batb":[[0,3.55,31.15]],"ltp":2.62,"tv":40.04,"id":6498878},{"batb":[[0,1.35,216.73],[1,1.34,292.76],[2,1.14,172.94]],"batl":[[0,1.39,388.02]],"ltp":1.14,"tv":801.18,"id":8174333}]}]}
{"op":"mcm","clk":"1001701396","pt":1580639364243,"mc":[{"id":"1.168224344","rc":[{"batb":[[1,2.68,12.35],[2,1.01,15.52]],"batl":[[0,4.2,12.6]],"ltp":2.62,"tv":40.04,"id":6498878},{"batb":[[1,1.34,356.1],[2,1.31,135.27]],"ltp":1.14,"tv":801.18,"id":8174333}]}]}
{"op":"mcm","clk":"1001701549","pt":1580639365856,"mc":[{"id":"1.168224344","rc":[{"batl":[[1,5.5,115.06]],"ltp":2.62,"tv":40.04,"id":6498878}]}]}
{"op":"mcm","clk":"1001702753","pt":1580639376335,"mc":[{"id":"1.168224344","rc":[{"batb":[[0,3.55,15.96]],"ltp":2.62,"tv":40.04,"id":6498878},{"batb":[[0,1.31,135.27],[1,1.26,89.85],[2,1.01,15.51]],"batl":[[0,1.39,42.01],[1,1.56,675.59],[2,1.56,0]],"ltp":1.14,"tv":801.18,"id":8174333}]}]}
{"op":"mcm","clk":"1001702770","pt":1580639376436,"mc":[{"id":"1.168224344","rc":[{"batb":[[0,2.68,12.35],[1,1.01,15.52],[2,1.01,0]],"batl":[[0,5.5,115.06],[1,5.5,0]],"ltp":2.62,"tv":40.04,"id":6498878},{"batb":[[0,1.26,89.85],[1,1.01,15.51],[2,1.01,0]],"batl":[[0,1.56,675.59],[1,1.56,0]],"ltp":1.14,"tv":801.18,"id":8174333}]}]}
{"op":"mcm","clk":"1001703130","pt":1580639379227,"mc":[{"id":"1.168224344","rc":[{"batb":[[0,1.26,512.5],[1,1.25,433.6],[2,1.01,15.51]],"batl":[[1,1.6,226.98],[2,1.61,132.56]],"ltp":1.14,"tv":801.18,"id":8174333}]}]}
{"op":"mcm","clk":"1001705060","pt":1580639396345,"mc":[{"id":"1.168224344","rc":[{"batb":[[0,1.26,89.85],[1,1.01,15.51],[2,1.01,0]],"ltp":1.14,"tv":801.18,"id":8174333}]}]}
{"op":"mcm","clk":"1001705349","pt":1580639399134,"mc":[{"id":"1.168224344","rc":[{"batb":[[0,1.54,243.12],[1,1.53,163.1],[2,1.26,89.85]],"batl":[[0,1.6,226.98],[1,1.61,132.56],[2,1.61,0]],"ltp":1.14,"tv":801.18,"id":8174333}]}]}
{"op":"mcm","clk":"1001705455","pt":1580639400145,"mc":[{"id":"1.168224344","rc":[{"batb":[[1,2.58,26.05],[2,2.34,17.7]],"batl":[[0,2.94,21]],"ltp":2.62,"tv":40.04,"id":6498878},{"batb":[[0,1.54,279.16],[2,1.39,54.05]],"batl":[[2,1.64,42.01]],"ltp":1.14,"tv":801.18,"id":8174333}]}]}
{"op":"mcm","clk":"1001705762","pt":1580639402346,"mc":[{"id":"1.168224344","rc":[{"batl":[[1,3.9,158.24]],"ltp":2.62,"tv":40.04,"id":6498878},{"batb":[[2,1.52,80.66]],"ltp":1.14,"tv":801.18,"id":8174333}]}]}
{"op":"mcm","clk":"1001709123","pt":1580639433322,"mc":[{"id":"1.168224344","rc":[{"batb":[[0,1.54,36.04],[1,1.52,80.66],[2,1.39,54.05]],"batl":[[0,1.64,42.01],[1,1.95,409.86],[2,1.64,0]],"ltp":1.14,"tv":801.18,"id":8174333}]}]}
{"op":"mcm","clk":"1001709161","pt":1580639433641,"mc":[{"id":"1.168224344","rc":[{"batb":[[0,2.58,26.05],[1,2.34,17.7],[2,1.01,15.52]],"ltp":2.62,"tv":40.04,"id":6498878},{"batb":[[0,1.52,80.66],[1,1.39,54.05],[2,1.01,15.51]],"ltp":1.14,"tv":801.18,"id":8174333}]}]}
{"op":"mcm","clk":"1001709258","pt":1580639434627,"mc":[{"id":"1.168224344","rc":[{"batb":[[0,2.34,17.7],[1,1.01,15.52],[2,1.01,0]],"batl":[[0,3.9,158.24],[1,3.9,0]],"ltp":2.62,"tv":40.04,"id":6498878},{"batb":[[0,1.39,54.05],[1,1.01,15.51],[2,1.01,0]],"batl":[[0,1.95,409.86],[1,1.95,0]],"ltp":1.14,"tv":801.18,"id":8174333}]}]}
{"op":"mcm","clk":"1001709404","pt":1580639436137,"mc":[{"id":"1.168224344","rc":[{"batb":[[0,1.41,196.2],[1,1.4,237.07],[2,1.39,54.05]],"batl":[[0,1.72,116.94],[1,1.74,204.32],[2,1.95,409.86]],"ltp":1.14,"tv":801.18,"id":8174333}]}]}
{"op":"mcm","clk":"1001710520","pt":1580639443337,"mc":[{"id":"1.168224344","rc":[{"batb":[[0,1.39,54.05],[1,1.01,15.51],[2,1.39,0]],"ltp":1.14,"tv":801.18,"id":8174333}]}]}
{"op":"mcm","clk":"1001710888","pt":1580639446328,"mc":[{"id":"1.168224344","rc":[{"batb":[[0,1.66,177.25],[1,1.65,122.41],[2,1.39,54.05]],"ltp":1.14,"tv":801.18,"id":8174333}]}]}
{"op":"mcm","clk":"1001711040","pt":1580639447368,"mc":[{"id":"1.168224344","rc":[{"batb":[[1,2.14,22.98],[2,1.01,15.52]],"ltp":2.62,"tv":40.04,"id":6498878},{"batb":[[0,1.67,26.52],[1,1.66,177.25],[2,1.65,122.41]],"ltp":1.14,"tv":801.18,"id":8174333}]}]}
{"op":"mcm","clk":"1001711066","pt":1580639447578,"mc":[{"id":"1.168224344","rc":[{"batb":[[0,2.34,48.79]],"batl":[[0,2.64,25.21]],"ltp":2.62,"tv":40.04,"id":6498878},{"batl":[[2,1.75,42.01]],"ltp":1.14,"tv":801.18,"id":8174333}]}]}
{"op":"mcm","clk":"1001711298","pt":1580639449571,"mc":[{"id":"1.168224344","rc":[{"batl":[[1,3.45,180.4]],"ltp":2.62,"tv":40.04,"id":6498878}]}]}
{"op":"mcm","clk":"1001713648","pt":1580639467373,"mc":[{"id":"1.168224344","rc":[{"batb":[[0,2.34,31.09]],"ltp":2.62,"tv":40.04,"id":6498878},{"batb":[[0,1.61,68.06],[1,1.52,37.61],[2,1.01,15.51]],"batl":[[0,1.75,42.01],[1,1.95,409.86],[2,1.75,0]],"ltp":1.14,"tv":801.18,"id":8174333}]}]}
{"op":"mcm","clk":"1001713764","pt":1580639468579,"mc":[{"id":"1.168224344","rc":[{"batb":[[0,2.14,22.98],[1,1.01,15.52],[2,1.01,0]],"batl":[[0,3.45,180.4],[1,3.45,0]],"ltp":2.62,"tv":40.04,"id":6498878},{"batb":[[0,1.52,37.61],[1,1.01,15.51],[2,1.01,0]],"batl":[[0,1.95,409.86],[1,1.95,0]],"ltp":1.14,"tv":801.18,"id":8174333}]}]}
{"op":"mcm","clk":"1001714262","pt":1580639473412,"mc":[{"id":"1.168224344","rc":[{"batb":[[0,1.63,193.96],[1,1.62,130.92],[2,1.52,37.61]],"batl":[[0,1.69,136.96],[1,1.71,216.51],[2,1.95,409.86]],"ltp":1.14,"tv":801.18,"id":8174333}]}]}
{"op":"mcm","clk":"1001714469","pt":1580639475407,"mc":[{"id":"1.168224344","rc":[{"batb":[[0,1.52,37.61],[1,1.01,15.51],[2,1.52,0]],"batl":[[0,1.95,409.86],[1,1.71,0],[2,1.95,0]],"ltp":1.14,"tv":801.18,"id":8174333}]}]}
{"op":"mcm","clk":"1001714742","pt":1580639478144,"mc":[{"id":"1.168224344","rc":[{"batb":[[0,1.52,314.02],[1,1.51,171.98],[2,1.01,15.51]],"batl":[[0,1.85,178.29],[1,1.87,161.79],[2,1.95,409.86]],"ltp":1.14,"tv":801.18,"id":8174333}]}]}
{"op":"mcm","clk":"1001715729","pt":1580639487319,"mc":[{"id":"1.168224344","rc":[{"batb":[[0,1.52,37.61],[1,1.01,15.51],[2,1.01,0]],"ltp":1.14,"tv":801.18,"id":8174333}]}]}
{"op":"mcm","clk":"1001715947","pt":1580639489216,"mc":[{"id":"1.168224344","rc":[{"batl":[[2,1.95,0]],"ltp":1.14,"tv":801.18,"id":8174333}]}]}
{"op":"mcm","clk":"1001716025","pt":1580639490251,"mc":[{"id":"1.168224344","rc":[{"batb":[[0,1.77,179.96],[1,1.75,198.16],[2,1.52,37.61]],"ltp":1.14,"tv":801.18,"id":8174333}]}]}
{"op":"mcm","clk":"1001716122","pt":1580639491250,"mc":[{"id":"1.168224344","rc":[{"batb":[[1,2,28.01],[2,1.01,15.52]],"ltp":2.62,"tv":40.04,"id":6498878},{"batb":[[0,1.8,20.93],[1,1.77,179.96],[2,1.75,198.16]],"ltp":1.14,"tv":801.18,"id":8174333}]}]}
{"op":"mcm","clk":"1001716164","pt":1580639491721,"mc":[{"id":"1.168224344","rc":[{"batb":[[0,2.16,36.13],[1,2.14,22.98],[2,2,28.01]],"batl":[[0,2.44,28.57]],"ltp":2.62,"tv":40.04,"id":6498878},{"batl":[[0,1.85,220.3]],"ltp":1.14,"tv":801.18,"id":8174333}]}]}
{"op":"mcm","clk":"1001716288","pt":1580639493131,"mc":[{"id":"1.168224344","rc":[{"batl":[[1,3.15,200.42]],"ltp":2.62,"tv":40.04,"id":6498878},{"batl":[[2,2.22,329.01]],"ltp":1.14,"tv":801.18,"id":8174333}]}]}
{"op":"mcm","clk":"1001717997","pt":1580639512109,"mc":[{"id":"1.168224344","rc":[{"batb":[[1,1.69,60.49],[2,1.67,26.91]],"batl":[[0,1.85,42.01],[1,2.22,329.01],[2,2.22,0]],"ltp":1.14,"tv":801.18,"id":8174333}]}]}
{"op":"mcm","clk":"1001718042","pt":1580639512586,"mc":[{"id":"1.168224344","rc":[{"batb":[[0,2,28.01],[1,1.01,15.52],[2,2,0]],"batl":[[0,3.15,200.42],[1,3.15,0]],"ltp":2.62,"tv":40.04,"id":6498878},{"batb":[[0,1.67,26.91],[1,1.01,15.51],[2,1.67,0]],"batl":[[0,2.22,329.01],[1,2.22,0]],"ltp":1.14,"tv":801.18,"id":8174333}]}]}
{"op":"mcm","clk":"1001718247","pt":1580639515092,"mc":[{"id":"1.168224344","rc":[{"batb":[[1,1.66,199.33],[2,1.65,122.47]],"batl":[[0,1.94,140.44],[1,1.96,140.11],[2,2.22,329.01]],"ltp":1.14,"tv":801.18,"id":8174333}]}]}
{"op":"mcm","clk":"1001718372","pt":1580639516000,"mc":[{"id":"1.168224344","rc":[{"batb":[[1,1.01,15.51],[2,1.65,0]],"batl":[[0,2.22,329.01],[1,1.96,0],[2,2.22,0]],"ltp":1.14,"tv":801.18,"id":8174333}]}]}
{"op":"mcm","clk":"1001718915","pt":1580639519133,"mc":[{"id":"1.168224344","rc":[{"batb":[[0,1.75,151.27],[1,1.73,205.99],[2,1.67,26.91]],"batl":[[0,1.82,141.82],[1,1.84,170.32],[2,2.22,329.01]],"ltp":1.14,"tv":801.18,"id":8174333}]}]}
{"op":"mcm","clk":"1001719400","pt":1580639523016,"mc":[{"id":"1.168224344","rc":[{"batb":[[0,1.67,26.91],[1,1.01,15.51],[2,1.67,0]],"batl":[[0,2.22,329.01],[1,1.84,0],[2,2.22,0]],"ltp":1.14,"tv":801.18,"id":8174333}]}]}
{"op":"mcm","clk":"1001719700","pt":1580639526210,"mc":[{"id":"1.168224344","rc":[{"batb":[[1,1.66,199.33],[2,1.65,122.47]],"batl":[[0,1.94,140.44],[1,1.96,140.11],[2,2.22,329.01]],"ltp":1.14,"tv":801.18,"id":8174333}]}]}
{"op":"mcm","clk":"1001719892","pt":1580639528143,"mc":[{"id":"1.168224344","rc":[{"batb":[[1,1.01,15.51],[2,1.65,0]],"ltp":1.14,"tv":801.18,"id":8174333}]}]}
{"op":"mcm","clk":"1001720160","pt":1580639530917,"mc":[{"id":"1.168224344","rc":[{"batb":[[0,1.86,132.05],[1,1.84,167.76],[2,1.67,26.91]],"ltp":1.14,"tv":801.18,"id":8174333}]}]}
{"op":"mcm","clk":"1001720279","pt":1580639532129,"mc":[{"id":"1.168224344","rc":[{"batb":[[0,2.06,39.49],[1,2,28.01],[2,1.93,15.66]],"batl":[[0,2.3,31.93]],"ltp":2.62,"tv":40.04,"id":6498878},{"batb":[[0,1.91,17.31],[1,1.86,132.05],[2,1.84,167.76]],"batl":[[1,1.95,42.01],[2,1.96,140.11]],"ltp":1.14,"tv":801.18,"id":8174333}]}]}
{"op":"mcm","clk":"1001720380","pt":1580639533241,"mc":[{"id":"1.168224344","rc":[{"batl":[[1,2.92,221.26]],"ltp":2.62,"tv":40.04,"id":6498878}]}]}
{"op":"mcm","clk":"1001721577","pt":1580639543169,"mc":[{"id":"1.168224344","rc":[{"batb":[[1,1.93,15.66],[2,1.01,15.52]],"ltp":2.62,"tv":40.04,"id":6498878},{"batb":[[0,1.82,20.06],[1,1.77,53.77],[2,1.01,15.51]],"batl":[[0,1.95,42.01],[1,2.22,329.01],[2,1.96,0]],"ltp":1.14,"tv":801.18,"id":8174333}]}]}
{"op":"mcm","clk":"1001721712","pt":1580639544655,"mc":[{"id":"1.168224344","rc":[{"batb":[[0,1.93,15.66],[1,1.01,15.52],[2,1.01,0]],"batl":[[0,2.92,221.26],[1,2.92,0]],"ltp":2.62,"tv":40.04,"id":6498878},{"batb":[[1,1.01,15.51],[2,1.01,0]],"batl":[[0,2.22,329.01],[1,2.22,0]],"ltp":1.14,"tv":801.18,"id":8174333}]}]}
{"op":"mcm","clk":"1001721853","pt":1580639546331,"mc":[{"id":"1.168224344","rc":[{"batb":[[0,1.96,30.21]],"ltp":2.62,"tv":40.04,"id":6498878},{"batb":[[0,1.8,137.72],[1,1.78,187.01],[2,1.01,15.51]],"batl":[[0,1.99,143.12],[1,2.02,193.07],[2,2.22,329.01]],"ltp":1.14,"tv":801.18,"id":8174333}]}]}
{"op":"mcm","clk":"1001722788","pt":1580639553318,"mc":[{"id":"1.168224344","rc":[{"batl":[[0,2.22,329.01],[1,2.02,0],[2,2.22,0]],"ltp":1.14,"tv":801.18,"id":8174333}]}]}
{"op":"mcm","clk":"1001723063","pt":1580639556211,"mc":[{"id":"1.168224344","rc":[{"batb":[[0,2.14,23.05],[1,2,28.17],[2,1.01,15.52]],"ltp":2.62,"tv":40.04,"id":6498878},{"batb":[[2,1.67,26.52]],"batl":[[0,1.87,129.32],[1,1.89,156.61],[2,2.22,329.01]],"ltp":1.14,"tv":801.18,"id":8174333}]}]}
{"op":"mcm","clk":"1001723264","pt":1580639558408,"mc":[{"id":"1.168224344","rc":[{"batb":[[1,2.1,37.81],[2,2,28.17]],"batl":[[0,2.38,30.25],[1,2.92,221.26]],"ltp":2.62,"tv":40.04,"id":6498878},{"batb":[[2,1.73,57.13]],"batl":[[2,1.91,42.01]],"ltp":1.14,"tv":801.18,"id":8174333}]}]}
{"op":"mcm","clk":"1001724716","pt":1580639570229,"mc":[{"id":"1.168224344","rc":[{"trd":[[2.14,49.42]],"batb":[[0,2.1,37.81],[1,2,28.17],[2,1.01,15.52]],"ltp":2.14,"tv":89.45,"id":6498878},{"trd":[[1.87,3.8]],"batl":[[0,1.87,125.52]],"ltp":1.87,"tv":804.98,"id":8174333}],"tv":894.44}]}
{"op":"mcm","clk":"1001725492","pt":1580639578373,"mc":[{"id":"1.168224344","rc":[{"batb":[[0,1.8,20.85],[1,1.73,57.13],[2,1.67,26.52]],"batl":[[0,1.91,42.01],[1,2.22,329.01],[2,1.91,0]],"ltp":1.87,"tv":804.98,"id":8174333}]}]}
{"op":"mcm","clk":"1001725586","pt":1580639579266,"mc":[{"id":"1.168224344","rc":[{"batb":[[0,2,28.17],[1,1.01,15.52],[2,1.01,0]],"batl":[[0,2.92,221.26],[1,2.92,0]],"ltp":2.14,"tv":89.45,"id":6498878},{"batb":[[0,1.67,26.52],[1,1.01,15.51],[2,1.67,0]],"batl":[[0,2.22,329.01],[1,2.22,0]],"ltp":1.87,"tv":804.98,"id":8174333}]}]}
{"op":"mcm","clk":"1001725808","pt":1580639581387,"mc":[{"id":"1.168224344","rc":[{"batb":[[0,1.69,153.12],[1,1.67,259.43],[2,1.01,15.51]],"batl":[[0,1.96,115.49],[1,1.98,135.93],[2,2.22,329.01]],"ltp":1.87,"tv":804.98,"id":8174333}]}]}
{"op":"mcm","clk":"1001725879","pt":1580639581869,"mc":[{"id":"1.168224344","rc":[{"batb":[[0,1.98,29.03]],"ltp":2.14,"tv":89.45,"id":6498878},{"batb":[[0,1.69,178.85],[1,1.67,232.91]],"ltp":1.87,"tv":804.98,"id":8174333}]}]}
{"op":"mcm","clk":"1001726042","pt":1580639583279,"mc":[{"id":"1.168224344","rc":[{"batl":[[0,2.22,329.01],[1,1.98,0],[2,2.22,0]],"ltp":1.87,"tv":804.98,"id":8174333}]}]}
{"op":"mcm","clk":"1001726324","pt":1580639586370,"mc":[{"id":"1.168224344","rc":[{"batl":[[0,1.76,204.87],[1,1.78,189.22],[2,2.22,329.01]],"ltp":1.87,"tv":804.98,"id":8174333}]}]}
{"op":"mcm","clk":"1001726382","pt":1580639586947,"mc":[{"id":"1.168224344","rc":[{"batb":[[0,2.32,18.25],[1,2.02,26.91],[2,1.01,15.52]],"ltp":2.14,"tv":89.45,"id":6498878},{"batb":[[2,1.49,40.68]],"batl":[[2,1.85,139.5]],"ltp":1.87,"tv":804.98,"id":8174333}]}]}
{"op":"mcm","clk":"1001726435","pt":1580639587580,"mc":[{"id":"1.168224344","rc":[{"batl":[[0,2.56,26.89]],"ltp":2.14,"tv":89.45,"id":6498878},{"batb":[[2,1.65,63.85]],"ltp":1.87,"tv":804.98,"id":8174333}]}]}
{"op":"mcm","clk":"1001726644","pt":1580639589815,"mc":[{"id":"1.168224344","rc":[{"batl":[[1,3.3,191.92]],"ltp":2.14,"tv":89.45,"id":6498878}]}]}
{"op":"mcm","clk":"1001727808","pt":1580639601399,"mc":[{"id":"1.168224344","rc":[{"batb":[[0,2.02,26.91],[1,1.01,15.52],[2,1.01,0]],"ltp":2.14,"tv":89.45,"id":6498878},{"batb":[[0,1.65,63.85],[1,1.49,40.68],[2,1.01,15.51]],"batl":[[0,2.22,329.01],[1,1.78,0],[2,1.85,0]],"ltp":1.87,"tv":804.98,"id":8174333}]}]}
{"op":"mcm","clk":"1001727915","pt":1580639602613,"mc":[{"id":"1.168224344","rc":[{"batl":[[0,3.3,191.92],[1,3.3,0]],"ltp":2.14,"tv":89.45,"id":6498878},{"batb":[[0,1.49,40.68],[1,1.01,15.51],[2,1.01,0]],"ltp":1.87,"tv":804.98,"id":8174333}]}]}
{"op":"mcm","clk":"1001728052","pt":1580639604132,"mc":[{"id":"1.168224344","rc":[{"batb":[[0,1.5,200.34],[1,1.49,221.79],[2,1.01,15.51]],"batl":[[0,1.94,149.33],[1,1.96,140.12],[2,2.22,329.01]],"ltp":1.87,"tv":804.98,"id":8174333}]}]}
{"op":"mcm","clk":"1001728391","pt":1580639608013,"mc":[{"id":"1.168224344","rc":[{"batb":[[0,1.49,40.68],[1,1.01,15.51],[2,1.01,0]],"ltp":1.87,"tv":804.98,"id":8174333}]}]}
{"op":"mcm","clk":"1001728677","pt":1580639611377,"mc":[{"id":"1.168224344","rc":[{"batb":[[1,1.74,22.03],[2,1.01,15.52]],"batl":[[0,2.34,172.75]],"ltp":2.14,"tv":89.45,"id":6498878},{"batb":[[0,1.88,18.02],[1,1.86,122.76],[2,1.84,167.72]],"ltp":1.87,"tv":804.98,"id":8174333}]}]}
{"op":"mcm","clk":"1001728702","pt":1580639611638,"mc":[{"id":"1.168224344","rc":[{"batb":[[0,2.02,68.08]],"batl":[[0,2.28,32.77]],"ltp":2.14,"tv":89.45,"id":6498878},{"batl":[[1,1.96,182.13]],"ltp":1.87,"tv":804.98,"id":8174333}]}]}
{"op":"mcm","clk":"1001728944","pt":1580639614034,"mc":[{"id":"1.168224344","rc":[{"batl":[[1,2.92,221.26]],"ltp":2.14,"tv":89.45,"id":6498878}]}]}
{"op":"mcm","clk":"1001732637","pt":1580639654307,"mc":[{"id":"1.168224344","rc":[{"trd":[[1.88,36.04]],"batb":[[0,1.86,122.76],[1,1.84,167.72],[2,1.78,53.77]],"batl":[[0,1.88,7.31],[1,1.94,149.33],[2,1.96,182.13]],"ltp":1.88,"tv":841.02,"id":8174333}],"tv":930.48}]}
{"op":"mcm","clk":"1001732963","pt":1580639657867,"mc":[{"id":"1.168224344","rc":[{"batb":[[0,2.04,26.44],[1,2.02,41.17],[2,1.75,21.72]],"ltp":2.14,"tv":89.45,"id":6498878},{"batb":[[0,1.87,18.33],[1,1.86,122.76],[2,1.84,167.72]],"ltp":1.88,"tv":841.02,"id":8174333}]}]}
{"op":"mcm","clk":"1001737029","pt":1580639697379,"mc":[{"id":"1.168224344","rc":[{"trd":[[1.87,40.46]],"batb":[[0,1.86,122.76],[1,1.84,167.72],[2,1.78,53.77]],"batl":[[0,1.87,1.67],[1,1.88,7.31],[2,1.94,149.33]],"ltp":1.87,"tv":877.68,"id":8174333}],"tv":967.14}]}
{"op":"mcm","clk":"1001737241","pt":1580639699266,"mc":[{"id":"1.168224344","rc":[{"batb":[[0,1.78,53.77],[1,1.72,24.16],[2,1.01,15.51]],"batl":[[2,1.96,42.01]],"ltp":1.87,"tv":877.68,"id":8174333}]}]}
{"op":"mcm","clk":"1001737337","pt":1580639699988,"mc":[{"id":"1.168224344","rc":[{"batb":[[0,2.02,41.17],[1,1.75,21.72],[2,1.01,15.52]],"ltp":2.14,"tv":89.45,"id":6498878}]}]}
{"op":"mcm","clk":"1001737488","pt":1580639701263,"mc":[{"id":"1.168224344","rc":[{"batb":[[0,1.75,21.72],[1,1.01,15.52],[2,1.01,0]],"batl":[[0,2.92,221.26],[1,2.92,0]],"ltp":2.14,"tv":89.45,"id":6498878},{"batb":[[0,1.72,24.16],[1,1.01,15.51],[2,1.01,0]],"batl":[[2,2.22,329.01]],"ltp":1.87,"tv":877.68,"id":8174333}]}]}
{"op":"mcm","clk":"1001737600","pt":1580639702261,"mc":[{"id":"1.168224344","rc":[{"batb":[[0,1.72,186.46],[1,1.7,218.79],[2,1.01,15.51]],"ltp":1.87,"tv":877.68,"id":8174333}]}]}
{"op":"mcm","clk":"1001737716","pt":1580639703367,"mc":[{"id":"1.168224344","rc":[{"batb":[[0,1.76,21.32]],"ltp":2.14,"tv":89.45,"id":6498878},{"batb":[[0,1.72,162.3],[1,1.71,24.55],[2,1.7,218.79]],"ltp":1.87,"tv":877.68,"id":8174333}]}]}
{"op":"mcm","clk":"1001738552","pt":1580639710407,"mc":[{"id":"1.168224344","rc":[{"batl":[[0,1.79,162.11],[1,1.81,179.38],[2,1.87,1.67]],"ltp":1.87,"tv":877.68,"id":8174333}]}]}
{"op":"mcm","clk":"1001738636","pt":1580639711094,"mc":[{"id":"1.168224344","rc":[{"batb":[[0,2.28,19.28],[1,1.98,29.19],[2,1.01,15.52]],"ltp":2.14,"tv":89.45,"id":6498878}]}]}
{"op":"mcm","clk":"1001738702","pt":1580639711671,"mc":[{"id":"1.168224344","rc":[{"batb":[[1,2.2,34.45],[2,1.98,29.19]],"batl":[[0,2.5,27.73]],"ltp":2.14,"tv":89.45,"id":6498878},{"batl":[[2,1.84,42.01]],"ltp":1.87,"tv":877.68,"id":8174333}]}]}
{"op":"mcm","clk":"1001738901","pt":1580639713713,"mc":[{"id":"1.168224344","rc":[{"batl":[[1,3.3,191.92]],"ltp":2.14,"tv":89.45,"id":6498878}]}]}
{"op":"mcm","clk":"1001739484","pt":1580639719104,"mc":[{"id":"1.168224344","rc":[{"batb":[[0,1.98,29.19],[1,1.01,15.52],[2,1.98,0]],"batl":[[0,3.3,191.92],[1,3.3,0]],"ltp":2.14,"tv":89.45,"id":6498878},{"batb":[[0,1.61,30.45],[1,1.01,15.51],[2,1.7,0]],"batl":[[0,1.88,7.31],[1,2.22,329.01],[2,1.84,0]],"ltp":1.87,"tv":877.68,"id":8174333}]}]}
{"op":"mcm","clk":"1001739735","pt":1580639721340,"mc":[{"id":"1.168224344","rc":[{"batb":[[0,1.63,164.85],[1,1.62,130.77],[2,1.61,30.45]],"batl":[[1,2,120.58],[2,2.02,128.03]],"ltp":1.87,"tv":877.68,"id":8174333}]}]}
{"op":"mcm","clk":"1001739773","pt":1580639721656,"mc":[{"id":"1.168224344","rc":[{"batb":[[0,1.61,30.45],[1,1.01,15.51],[2,1.61,0]],"batl":[[1,2.22,329.01],[2,2.02,0]],"ltp":1.87,"tv":877.68,"id":8174333}]}]}
{"op":"mcm","clk":"1001740479","pt":1580639727927,"mc":[{"id":"1.168224344","rc":[{"batb":[[0,1.63,164.85],[1,1.62,130.77],[2,1.61,30.45]],"batl":[[1,2,120.58],[2,2.02,128.03]],"ltp":1.87,"tv":877.68,"id":8174333}]}]}
{"op":"mcm","clk":"1001740848","pt":1580639731168,"mc":[{"id":"1.168224344","rc":[{"batb":[[0,1.61,30.45],[1,1.01,15.51],[2,1.61,0]],"ltp":1.87,"tv":877.68,"id":8174333}]}]}
{"op":"mcm","clk":"1001740955","pt":1580639732215,"mc":[{"id":"1.168224344","rc":[{"trd":[[1.61,4]],"batb":[[0,1.61,28.45]],"ltp":1.61,"tv":881.68,"id":8174333}],"tv":971.14}]}
{"op":"mcm","clk":"1001741141","pt":1580639734356,"mc":[{"id":"1.168224344","rc":[{"batb":[[0,1.98,72.04],[1,1.66,26.04],[2,1.01,15.52]],"batl":[[0,2.2,34.45]],"ltp":2.14,"tv":89.45,"id":6498878},{"trd":[[1.88,50.66]],"batb":[[0,1.93,16.68],[1,1.92,98.81],[2,1.9,151.37]],"batl":[[0,2,120.58],[1,2.02,169.2],[2,2.22,329.01]],"ltp":1.88,"tv":896.31,"id":8174333}],"tv":985.76}]}
{"op":"mcm","clk":"1001741419","pt":1580639737029,"mc":[{"id":"1.168224344","rc":[{"batl":[[1,2.82,231.28]],"ltp":2.14,"tv":89.45,"id":6498878}]}]}
{"op":"mcm","clk":"1001742156","pt":1580639744356,"mc":[{"id":"1.168224344","rc":[{"batb":[[0,1.98,42.85]],"ltp":2.14,"tv":89.45,"id":6498878},{"batb":[[0,1.83,50.41],[1,1.74,23.45],[2,1.01,15.51]],"batl":[[0,2.02,41.17],[1,2.22,329.01],[2,2.22,0]],"ltp":1.88,"tv":896.31,"id":8174333}]}]}
{"op":"mcm","clk":"1001742189","pt":1580639744662,"mc":[{"id":"1.168224344","rc":[{"batb":[[0,1.66,26.04],[1,1.01,15.52],[2,1.01,0]],"batl":[[0,2.82,231.28],[1,2.82,0]],"ltp":2.14,"tv":89.45,"id":6498878},{"batb":[[0,1.74,23.45],[1,1.01,15.51],[2,1.01,0]],"batl":[[0,2.22,329.01],[1,2.22,0]],"ltp":1.88,"tv":896.31,"id":8174333}]}]}
{"op":"mcm","clk":"1001742448","pt":1580639747386,"mc":[{"id":"1.168224344","rc":[{"batb":[[1,1.73,195.15],[2,1.71,214.52]],"batl":[[1,2.48,99],[2,2.52,139.42]],"ltp":1.88,"tv":896.31,"id":8174333}]}]}
{"op":"mcm","clk":"1001742638","pt":1580639749257,"mc":[{"id":"1.168224344","rc":[{"batb":[[1,1.01,15.51],[2,1.71,0]],"batl":[[1,2.48,0],[2,2.52,0]],"ltp":1.88,"tv":896.31,"id":8174333}]}]}
{"op":"mcm","clk":"1001743244","pt":1580639755275,"mc":[{"id":"1.168224344","rc":[{"batb":[[0,1.67,213.44],[1,1.66,145.44],[2,1.01,15.52]],"batl":[[0,2.36,102.73],[1,2.4,159.32],[2,2.82,231.28]],"ltp":2.14,"tv":89.45,"id":6498878}]}]}
{"op":"mcm","clk":"1001743349","pt":1580639756259,"mc":[{"id":"1.168224344","rc":[{"batl":[[0,2.5,274.54]],"ltp":1.88,"tv":896.31,"id":8174333}]}]}
{"op":"mcm","clk":"1001744328","pt":1580639765284,"mc":[{"id":"1.168224344","rc":[{"batb":[[0,1.66,26.04],[1,1.01,15.52],[2,1.01,0]],"batl":[[0,2.82,231.28],[1,2.4,0],[2,2.82,0]],"ltp":2.14,"tv":89.45,"id":6498878}]}]}
{"op":"mcm","clk":"1001744612","pt":1580639768385,"mc":[{"id":"1.168224344","rc":[{"batb":[[0,2.24,20.3],[1,1.91,16.13],[2,1.66,26.04]],"ltp":2.14,"tv":89.45,"id":6498878},{"batb":[[1,1.73,195.15],[2,1.71,214.52]],"batl":[[0,1.8,120.34],[1,1.82,176.38]],"ltp":1.88,"tv":896.31,"id":8174333}]}]}
{"op":"mcm","clk":"1001744633","pt":1580639768542,"mc":[{"id":"1.168224344","rc":[{"batb":[[2,1.01,15.52]],"ltp":2.14,"tv":89.45,"id":6498878}]}]}
{"op":"mcm","clk":"1001744719","pt":1580639769655,"mc":[{"id":"1.168224344","rc":[{"batb":[[1,2.18,35.29],[2,1.91,16.13]],"batl":[[0,2.48,27.73]],"ltp":2.14,"tv":89.45,"id":6498878},{"batl":[[2,1.85,42.01]],"ltp":1.88,"tv":896.31,"id":8174333}]}]}
{"op":"mcm","clk":"1001744878","pt":1580639771365,"mc":[{"id":"1.168224344","rc":[{"batl":[[1,3.15,200.42]],"ltp":2.14,"tv":89.45,"id":6498878}]}]}
{"op":"mcm","clk":"1001745857","pt":1580639781201,"mc":[{"id":"1.168224344","rc":[{"batb":[[0,2.18,35.29],[1,1.91,16.13],[2,1.01,15.52]],"ltp":2.14,"tv":89.45,"id":6498878},{"batb":[[0,1.69,60.49],[1,1.61,30.53],[2,1.01,15.51]],"batl":[[0,1.85,42.01],[1,2.22,329.01],[2,1.85,0]],"ltp":1.88,"tv":896.31,"id":8174333}]}]}
{"op":"mcm","clk":"1001746011","pt":1580639782770,"mc":[{"id":"1.168224344","rc":[{"batb":[[0,1.91,16.13],[1,1.01,15.52],[2,1.01,0]],"batl":[[0,3.15,200.42],[1,3.15,0]],"ltp":2.14,"tv":89.45,"id":6498878},{"batb":[[0,1.61,30.53],[1,1.01,15.51],[2,1.01,0]],"batl":[[0,2.22,329.01],[1,2.22,0]],"ltp":1.88,"tv":896.31,"id":8174333}]}]}
{"op":"mcm","clk":"1001746145","pt":1580639784373,"mc":[{"id":"1.168224344","rc":[{"batb":[[0,1.62,180.89],[1,1.61,164.42],[2,1.01,15.51]],"batl":[[0,2.08,181.58],[1,2.1,114.34],[2,2.22,329.01]],"ltp":1.88,"tv":896.31,"id":8174333}]}]}
{"op":"mcm","clk":"1001747384","pt":1580639797275,"mc":[{"id":"1.168224344","rc":[{"batl":[[0,2.22,329.01],[1,2.1,0],[2,2.22,0]],"ltp":1.88,"tv":896.31,"id":8174333}]}]}
{"op":"mcm","clk":"1001747666","pt":1580639800406,"mc":[{"id":"1.168224344","rc":[{"batl":[[0,1.68,162.28],[1,1.7,220.73]],"ltp":1.88,"tv":896.31,"id":8174333}]}]}
{"op":"mcm","clk":"1001747715","pt":1580639800929,"mc":[{"id":"1.168224344","rc":[{"batb":[[0,2.5,15.03],[1,2.26,19.83],[2,1.01,15.52]],"ltp":2.14,"tv":89.45,"id":6498878},{"batb":[[2,1.55,35.17]],"ltp":1.88,"tv":896.31,"id":8174333}]}]}
{"op":"mcm","clk":"1001747805","pt":1580639801727,"mc":[{"id":"1.168224344","rc":[{"batb":[[1,2.36,30.25],[2,2.26,19.83]],"batl":[[0,2.72,24.37],[1,3.45,180.4]],"ltp":2.14,"tv":89.45,"id":6498878},{"batb":[[2,1.59,70.58]],"batl":[[2,1.73,42.01]],"ltp":1.88,"tv":896.31,"id":8174333}]}]}
{"op":"mcm","clk":"1001747974","pt":1580639803311,"mc":[{"id":"1.168224344","rc":[{"batl":[[1,3.45,0]],"ltp":2.14,"tv":89.45,"id":6498878}]}]}
{"op":"mcm","clk":"1001748955","pt":1580639813336,"mc":[{"id":"1.168224344","rc":[{"batb":[[0,1.61,30.53],[1,1.59,70.58],[2,1.55,35.17]],"batl":[[0,1.73,42.01],[1,2.16,342.82],[2,1.73,0]],"ltp":1.88,"tv":896.31,"id":8174333}]}]}
{"op":"mcm","clk":"1001749050","pt":1580639814268,"mc":[{"id":"1.168224344","rc":[{"batb":[[0,2.36,30.25],[1,2.26,19.83],[2,1.01,15.52]],"ltp":2.14,"tv":89.45,"id":6498878},{"batb":[[0,1.59,70.58],[1,1.55,35.17],[2,1.01,15.51]],"ltp":1.88,"tv":896.31,"id":8174333}]}]}
{"op":"mcm","clk":"1001749093","pt":1580639814855,"mc":[{"id":"1.168224344","rc":[{"batb":[[0,2.26,19.83],[1,1.01,15.52],[2,1.01,0]],"ltp":2.14,"tv":89.45,"id":6498878},{"batb":[[0,1.55,35.17],[1,1.01,15.51],[2,1.01,0]],"batl":[[0,2.16,342.82],[1,2.16,0]],"ltp":1.88,"tv":896.31,"id":8174333}]}]}
{"op":"mcm","clk":"1001749225","pt":1580639816412,"mc":[{"id":"1.168224344","rc":[{"batb":[[0,1.57,215.66],[1,1.56,150.99],[2,1.55,35.17]],"batl":[[0,1.79,188.81],[1,1.81,179.37],[2,2.16,342.82]],"ltp":1.88,"tv":896.31,"id":8174333}]}]}
{"op":"mcm","clk":"1001749234","pt":1580639816522,"mc":[{"id":"1.168224344","rc":[{"batb":[[0,1.55,35.17],[1,1.01,15.51],[2,1.55,0]],"batl":[[0,2.16,342.82],[1,1.81,0],[2,2.16,0]],"ltp":1.88,"tv":896.31,"id":8174333}]}]}
{"op":"mcm","clk":"1001749563","pt":1580639819955,"mc":[{"id":"1.168224344","rc":[{"batb":[[0,1.64,158.47],[1,1.63,127.89],[2,1.55,35.17]],"batl":[[0,1.7,158.32],[1,1.72,212.19],[2,2.16,342.82]],"ltp":1.88,"tv":896.31,"id":8174333}]}]}
{"op":"mcm","clk":"1001749695","pt":1580639821171,"mc":[{"id":"1.168224344","rc":[{"batb":[[0,1.55,35.17],[1,1.01,15.51],[2,1.55,0]],"batl":[[0,2.16,342.82],[1,1.72,0],[2,2.16,0]],"ltp":1.88,"tv":896.31,"id":8174333}]}]}
{"op":"mcm","clk":"1001750015","pt":1580639824061,"mc":[{"id":"1.168224344","rc":[{"batb":[[0,1.57,215.66],[1,1.56,150.99],[2,1.55,35.17]],"batl":[[0,1.79,188.81],[1,1.81,179.37],[2,2.16,342.82]],"ltp":1.88,"tv":896.31,"id":8174333}]}]}
{"op":"mcm","clk":"1001751362","pt":1580639837405,"mc":[{"id":"1.168224344","rc":[{"batb":[[0,1.55,35.17],[1,1.01,15.51],[2,1.55,0]],"ltp":1.88,"tv":896.31,"id":8174333}]}]}
{"op":"mcm","clk":"1001751681","pt":1580639840181,"mc":[{"id":"1.168224344","rc":[{"batb":[[0,1.72,134.45],[1,1.7,218.77],[2,1.55,35.17]],"ltp":1.88,"tv":896.31,"id":8174333}]}]}
{"op":"mcm","clk":"1001751751","pt":1580639840868,"mc":[{"id":"1.168224344","rc":[{"batb":[[1,1.89,16.92],[2,1.01,15.52]],"ltp":2.14,"tv":89.45,"id":6498878},{"batb":[[0,1.73,23.92],[1,1.72,134.45],[2,1.7,218.77]],"ltp":1.88,"tv":896.31,"id":8174333}]}]}
{"op":"mcm","clk":"1001751840","pt":1580639841800,"mc":[{"id":"1.168224344","rc":[{"batb":[[1,2.22,33.61],[2,1.89,16.92]],"batl":[[0,2.5,27.73]],"ltp":2.14,"tv":89.45,"id":6498878},{"batl":[[2,1.82,42.01]],"ltp":1.88,"tv":896.31,"id":8174333}]}]}
{"op":"mcm","clk":"1001751955","pt":1580639842996,"mc":[{"id":"1.168224344","rc":[{"batl":[[1,3,213.45]],"ltp":2.14,"tv":89.45,"id":6498878}]}]}
{"op":"mcm","clk":"1001752785","pt":1580639851503,"mc":[{"id":"1.168224344","rc":[{"batb":[[0,2.22,33.61],[1,1.89,16.92],[2,1.01,15.52]],"ltp":2.14,"tv":89.45,"id":6498878},{"batb":[[0,1.72,134.45],[1,1.7,218.77],[2,1.66,63.01]],"ltp":1.88,"tv":896.31,"id":8174333}]}]}
{"op":"mcm","clk":"1001753235","pt":1580639856314,"mc":[{"id":"1.168224344","rc":[{"batb":[[0,1.66,63.01],[1,1.58,32.26],[2,1.01,15.51]],"batl":[[0,1.82,42.01],[1,2.16,342.82],[2,1.82,0]],"ltp":1.88,"tv":896.31,"id":8174333}]}]}
{"op":"mcm","clk":"1001753286","pt":1580639856784,"mc":[{"id":"1.168224344","rc":[{"batb":[[0,1.89,16.92],[1,1.01,15.52],[2,1.01,0]],"batl":[[0,3,213.45],[1,3,0]],"ltp":2.14,"tv":89.45,"id":6498878},{"batb":[[0,1.58,32.26],[1,1.01,15.51],[2,1.01,0]],"batl":[[0,2.16,342.82],[1,2.16,0]],"ltp":1.88,"tv":896.31,"id":8174333}]}]}
{"op":"mcm","clk":"1001753994","pt":1580639862319,"mc":[{"id":"1.168224344","rc":[{"batb":[[0,1.77,127.4],[1,1.75,198.05],[2,1.58,32.26]],"batl":[[0,1.84,145.76],[1,1.86,164.63],[2,2.16,342.82]],"ltp":1.88,"tv":896.31,"id":8174333}]}]}
{"op":"mcm","clk":"1001754183","pt":1580639863997,"mc":[{"id":"1.168224344","rc":[{"batb":[[0,1.58,32.26],[1,1.01,15.51],[2,1.58,0]],"batl":[[0,2.16,342.82],[1,1.86,0],[2,2.16,0]],"ltp":1.88,"tv":896.31,"id":8174333}]}]}
{"op":"mcm","clk":"1001754561","pt":1580639866898,"mc":[{"id":"1.168224344","rc":[{"batb":[[0,1.59,207.76],[1,1.58,176.06],[2,1.01,15.51]],"batl":[[0,2.1,160.42],[1,2.12,111.26],[2,2.16,342.82]],"ltp":1.88,"tv":896.31,"id":8174333}]}]}
{"op":"mcm","clk":"1001755475","pt":1580639875218,"mc":[{"id":"1.168224344","rc":[{"batl":[[0,2.16,342.82],[1,2.12,0],[2,2.16,0]],"ltp":1.88,"tv":896.31,"id":8174333}]}]}
{"op":"mcm","clk":"1001755738","pt":1580639877943,"mc":[{"id":"1.168224344","rc":[{"batl":[[0,1.65,178.64],[1,1.66,119.05],[2,2.16,342.82]],"ltp":1.88,"tv":896.31,"id":8174333}]}]}
{"op":"mcm","clk":"1001755851","pt":1580639879034,"mc":[{"id":"1.168224344","rc":[{"batb":[[0,2.54,14.16],[1,2.22,20.77],[2,1.01,15.52]],"ltp":2.14,"tv":89.45,"id":6498878},{"batb":[[2,1.41,51.46]],"ltp":1.88,"tv":896.31,"id":8174333}]}]}
{"op":"mcm","clk":"1001755916","pt":1580639879711,"mc":[{"id":"1.168224344","rc":[{"batb":[[1,2.44,28.57],[2,2.22,20.77]],"batl":[[0,2.8,22.69]],"ltp":2.14,"tv":89.45,"id":6498878},{"batb":[[2,1.56,74.78]],"batl":[[2,1.69,42.01]],"ltp":1.88,"tv":896.31,"id":8174333}]}]}
{"op":"mcm","clk":"1001756093","pt":1580639881394,"mc":[{"id":"1.168224344","rc":[{"batl":[[1,3.45,180.4]],"ltp":2.14,"tv":89.45,"id":6498878}]}]}
{"op":"mcm","clk":"1001758300","pt":1580639905882,"mc":[{"id":"1.168224344","rc":[{"batb":[[0,2.44,28.57],[1,2.22,20.77],[2,1.01,15.52]],"ltp":2.14,"tv":89.45,"id":6498878},{"batb":[[0,1.56,74.78],[1,1.41,51.46],[2,1.01,15.51]],"batl":[[0,1.69,42.01],[1,2.16,342.82],[2,1.69,0]],"ltp":1.88,"tv":896.31,"id":8174333}]}]}
{"op":"mcm","clk":"1001758403","pt":1580639906789,"mc":[{"id":"1.168224344","rc":[{"batb":[[0,2.22,20.77],[1,1.01,15.52],[2,1.01,0]],"batl":[[0,3.45,180.4],[1,3.45,0]],"ltp":2.14,"tv":89.45,"id":6498878},{"batb":[[0,1.41,51.46],[1,1.01,15.51],[2,1.01,0]],"batl":[[0,2.16,342.82],[1,2.16,0]],"ltp":1.88,"tv":896.31,"id":8174333}]}]}
{"op":"mcm","clk":"1001758633","pt":1580639908906,"mc":[{"id":"1.168224344","rc":[{"batb":[[0,1.4,51.69]],"batl":[[0,1.81,152.03],[1,1.83,173.28],[2,2.16,342.82]],"ltp":1.88,"tv":896.31,"id":8174333}]}]}
{"op":"mcm","clk":"1001758943","pt":1580639912351,"mc":[{"id":"1.168224344","rc":[{"batb":[[1,1.99,28.48],[2,1.01,15.52]],"ltp":2.14,"tv":89.45,"id":6498878},{"batb":[[0,1.74,174.23],[1,1.72,210.13],[2,1.56,34.46]],"ltp":1.88,"tv":896.31,"id":8174333}]}]}
{"op":"mcm","clk":"1001759094","pt":1580639913868,"mc":[{"id":"1.168224344","rc":[{"batb":[[1,2.2,34.45],[2,1.99,28.48]],"batl":[[0,2.48,27.73]],"ltp":2.14,"tv":89.45,"id":6498878},{"batb":[[2,1.67,62.17]],"batl":[[1,1.83,215.29]],"ltp":1.88,"tv":896.31,"id":8174333}]}]}
{"op":"mcm","clk":"1001759178","pt":1580639914755,"mc":[{"id":"1.168224344","rc":[{"batl":[[1,3,213.45]],"ltp":2.14,"tv":89.45,"id":6498878}]}]}
{"op":"mcm","clk":"1001760145","pt":1580639925061,"mc":[{"id":"1.168224344","rc":[{"batb":[[0,2.2,34.45],[1,1.99,28.48],[2,1.01,15.52]],"ltp":2.14,"tv":89.45,"id":6498878},{"batb":[[0,1.67,62.17],[1,1.56,34.46],[2,1.01,15.51]],"batl":[[0,1.83,42.01],[1,2.16,342.82],[2,2.16,0]],"ltp":1.88,"tv":896.31,"id":8174333}]}]}
{"op":"mcm","clk":"1001760313","pt":1580639926792,"mc":[{"id":"1.168224344","rc":[{"batb":[[0,1.99,28.48],[1,1.01,15.52],[2,1.01,0]],"batl":[[0,3,213.45],[1,3,0]],"ltp":2.14,"tv":89.45,"id":6498878},{"batb":[[0,1.56,34.46],[1,1.01,15.51],[2,1.01,0]],"batl":[[0,2.16,342.82],[1,2.16,0]],"ltp":1.88,"tv":896.31,"id":8174333}]}]}
{"op":"mcm","clk":"1001760678","pt":1580639932728,"mc":[{"id":"1.168224344","rc":[{"batb":[[0,1.7,182.79],[1,1.68,228.21],[2,1.56,34.46]],"batl":[[0,1.77,165.29],[1,1.79,185.98],[2,2.16,342.82]],"ltp":1.88,"tv":896.31,"id":8174333}]}]}
{"op":"mcm","clk":"1001760996","pt":1580639934158,"mc":[{"id":"1.168224344","rc":[{"batb":[[0,1.56,34.46],[1,1.01,15.51],[2,1.56,0]],"batl":[[0,2.16,342.82],[1,1.79,0],[2,2.16,0]],"ltp":1.88,"tv":896.31,"id":8174333}]}]}
{"op":"mcm","clk":"1001761258","pt":1580639937190,"mc":[{"id":"1.168224344","rc":[{"batb":[[0,1.57,137.62],[1,1.56,185.1],[2,1.01,15.51]],"batl":[[0,1.97,149.24],[1,1.99,133.86],[2,2.16,342.82]],"ltp":1.88,"tv":896.31,"id":8174333}]}]}
{"op":"mcm","clk":"1001762017","pt":1580639944796,"mc":[{"id":"1.168224344","rc":[{"batl":[[0,2.16,342.82],[1,1.99,0],[2,2.16,0]],"ltp":1.88,"tv":896.31,"id":8174333}]}]}
{"op":"mcm","clk":"1001762334","pt":1580639948384,"mc":[{"id":"1.168224344","rc":[{"batb":[[0,2.62,13.06],[1,2.2,21.01],[2,1.99,28.48]],"ltp":2.14,"tv":89.45,"id":6498878},{"batb":[[2,1.36,60.51]],"batl":[[0,1.62,148.9],[1,1.63,127.05]],"ltp":1.88,"tv":896.31,"id":8174333}]}]}
{"op":"mcm","clk":"1001762358","pt":1580639948593,"mc":[{"id":"1.168224344","rc":[{"batb":[[2,1.01,15.52]],"ltp":2.14,"tv":89.45,"id":6498878}]}]}
{"op":"mcm","clk":"1001762456","pt":1580639949785,"mc":[{"id":"1.168224344","rc":[{"batb":[[1,2.5,27.73],[2,2.2,21.01]],"batl":[[0,2.88,21.85]],"ltp":2.14,"tv":89.45,"id":6498878},{"batb":[[2,1.54,77.3]],"batl":[[2,1.67,42.01]],"ltp":1.88,"tv":896.31,"id":8174333}]}]}
{"op":"mcm","clk":"1001762575","pt":1580639950991,"mc":[{"id":"1.168224344","rc":[{"batl":[[1,3.65,170.41]],"ltp":2.14,"tv":89.45,"id":6498878}]}]}
{"op":"mcm","clk":"1001764230","pt":1580639969159,"mc":[{"id":"1.168224344","rc":[{"batb":[[0,2.5,27.73],[1,2.2,21.01],[2,1.01,15.52]],"ltp":2.14,"tv":89.45,"id":6498878},{"batb":[[0,1.54,77.3],[1,1.36,60.51],[2,1.01,15.51]],"batl":[[0,1.67,42.01],[1,2.04,383.01],[2,1.67,0]],"ltp":1.88,"tv":896.31,"id":8174333}]}]}
{"op":"mcm","clk":"1001764391","pt":1580639970841,"mc":[{"id":"1.168224344","rc":[{"batb":[[0,2.2,21.01],[1,1.01,15.52],[2,1.01,0]],"batl":[[0,3.65,170.41],[1,3.65,0]],"ltp":2.14,"tv":89.45,"id":6498878},{"batb":[[0,1.36,60.51],[1,1.01,15.51],[2,1.01,0]],"batl":[[0,2.04,383.01],[1,2.04,0]],"ltp":1.88,"tv":896.31,"id":8174333}]}]}
{"op":"mcm","clk":"1001764500","pt":1580639972029,"mc":[{"id":"1.168224344","rc":[{"batl":[[0,1.81,110.49],[1,1.83,173.38],[2,2.04,383.01]],"ltp":1.88,"tv":896.31,"id":8174333}]}]}
{"op":"mcm","clk":"1001764588","pt":1580639973074,"mc":[{"id":"1.168224344","rc":[{"batl":[[2,2.04,0]],"ltp":1.88,"tv":896.31,"id":8174333}]}]}
{"op":"mcm","clk":"1001764696","pt":1580639974327,"mc":[{"id":"1.168224344","rc":[{"batb":[[0,1.74,194.82],[1,1.72,210.27],[2,1.36,60.51]],"ltp":1.88,"tv":896.31,"id":8174333}]}]}
{"op":"mcm","clk":"1001764762","pt":1580639974949,"mc":[{"id":"1.168224344","rc":[{"batb":[[1,1.96,30.21],[2,1.01,15.52]],"ltp":2.14,"tv":89.45,"id":6498878},{"batb":[[0,1.75,22.66],[1,1.74,194.82],[2,1.72,210.27]],"ltp":1.88,"tv":896.31,"id":8174333}]}]}
{"op":"mcm","clk":"1001764836","pt":1580639975732,"mc":[{"id":"1.168224344","rc":[{"batb":[[0,2.2,55.46]],"batl":[[0,2.48,27.73]],"ltp":2.14,"tv":89.45,"id":6498878},{"batl":[[1,1.83,215.39]],"ltp":1.88,"tv":896.31,"id":8174333}]}]}
{"op":"mcm","clk":"1001764945","pt":1580639977138,"mc":[{"id":"1.168224344","rc":[{"batl":[[1,3,213.45]],"ltp":2.14,"tv":89.45,"id":6498878},{"batl":[[2,2.3,309.75]],"ltp":1.88,"tv":896.31,"id":8174333}]}]}
{"op":"mcm","clk":"1001766104","pt":1580639990057,"mc":[{"id":"1.168224344","rc":[{"batb":[[0,2.2,34.45]],"ltp":2.14,"tv":89.45,"id":6498878},{"batb":[[0,1.68,61.33],[1,1.54,36.12],[2,1.01,15.51]],"batl":[[0,1.83,42.01],[1,2.3,309.75],[2,2.3,0]],"ltp":1.88,"tv":896.31,"id":8174333}]}]}
{"op":"mcm","clk":"1001766170","pt":1580639990780,"mc":[{"id":"1.168224344","rc":[{"trd":[[2.2,4.54]],"batb":[[0,1.96,30.21],[1,1.01,15.52],[2,1.01,0]],"batl":[[0,3,213.45],[1,3,0]],"ltp":2.2,"tv":93.99,"id":6498878},{"batb":[[0,1.54,36.12],[1,1.01,15.51],[2,1.01,0]],"batl":[[0,2.3,309.75],[1,2.3,0]],"ltp":1.88,"tv":896.31,"id":8174333}],"tv":990.3}]}
{"op":"mcm","clk":"1001766447","pt":1580639993284,"mc":[{"id":"1.168224344","rc":[{"batl":[[0,2.02,214.74],[1,2.04,124.37],[2,2.3,309.75]],"ltp":1.88,"tv":896.31,"id":8174333}]}]}
{"op":"mcm","clk":"1001766730","pt":1580639996385,"mc":[{"id":"1.168224344","rc":[{"batb":[[0,1.98,42.85],[1,1.96,30.21],[2,1.84,18.33]],"ltp":2.2,"tv":93.99,"id":6498878},{"batb":[[0,1.96,16.05],[1,1.92,140.63],[2,1.9,151.39]],"batl":[[0,2.02,255.91]],"ltp":1.88,"tv":896.31,"id":8174333}]}]}
{"op":"mcm","clk":"1001767025","pt":1580639999493,"mc":[{"id":"1.168224344","rc":[{"batl":[[0,2.72,241.55]],"ltp":2.2,"tv":93.99,"id":6498878}]}]}
{"op":"mcm","clk":"1001767905","pt":1580640008343,"mc":[{"id":"1.168224344","rc":[{"batb":[[1,1.84,18.33],[2,1.01,15.52]],"ltp":2.2,"tv":93.99,"id":6498878},{"batb":[[0,1.79,21.17],[1,1.01,15.51],[2,1.9,0]],"batl":[[0,2.02,41.17],[1,2.3,309.75],[2,7,2.27]],"ltp":1.88,"tv":896.31,"id":8174333}]}]}
{"op":"mcm","clk":"1001767950","pt":1580640008857,"mc":[{"id":"1.168224344","rc":[{"batb":[[0,1.84,18.33],[1,1.01,15.52],[2,1.01,0]],"ltp":2.2,"tv":93.99,"id":6498878},{"batl":[[0,2.3,309.75],[1,7,2.27],[2,7,0]],"ltp":1.88,"tv":896.31,"id":8174333}]}]}
{"op":"mcm","clk":"1001768165","pt":1580640010860,"mc":[{"id":"1.168224344","rc":[{"batb":[[1,1.78,165.53],[2,1.76,194.33]],"batl":[[0,2.12,96.3],[1,2.14,108.24],[2,2.3,309.75]],"ltp":1.88,"tv":896.31,"id":8174333}]}]}
{"op":"mcm","clk":"1001768513","pt":1580640014044,"mc":[{"id":"1.168224344","rc":[{"batb":[[1,1.01,15.51],[2,1.76,0]],"batl":[[0,2.3,309.75],[1,7,2.27],[2,2.3,0]],"ltp":1.88,"tv":896.31,"id":8174333}]}]}
{"op":"mcm","clk":"1001768844","pt":1580640017249,"mc":[{"id":"1.168224344","rc":[{"batb":[[0,1.89,145.32],[1,1.87,159.25],[2,1.79,21.17]],"batl":[[0,1.97,104.52],[1,1.99,133.87],[2,2.3,309.75]],"ltp":1.88,"tv":896.31,"id":8174333}]}]}
{"op":"mcm","clk":"1001769515","pt":1580640023954,"mc":[{"id":"1.168224344","rc":[{"batb":[[0,1.79,21.17],[1,1.01,15.51],[2,1.79,0]],"batl":[[0,2.3,309.75],[1,7,2.27],[2,2.3,0]],"ltp":1.88,"tv":896.31,"id":8174333}]}]}
{"op":"mcm","clk":"1001769756","pt":1580640026933,"mc":[{"id":"1.168224344","rc":[{"batb":[[1,1.78,163.81],[2,1.76,194.33]],"batl":[[0,2.12,97.8],[1,2.14,108.24],[2,2.3,309.75]],"ltp":1.88,"tv":896.31,"id":8174333}]}]}
{"op":"mcm","clk":"1001770747","pt":1580640038489,"mc":[{"id":"1.168224344","rc":[{"batl":[[0,2.3,309.75],[1,7,2.27],[2,2.3,0]],"ltp":1.88,"tv":896.31,"id":8174333}]}]}
{"op":"mcm","clk":"1001771074","pt":1580640042254,"mc":[{"id":"1.168224344","rc":[{"batb":[[0,2.16,22.66],[1,2.12,36.97],[2,1.88,17.23]],"batl":[[0,2.4,29.41],[1,2.72,241.55]],"ltp":2.2,"tv":93.99,"id":6498878},{"batl":[[0,1.86,183.26],[1,1.88,159.11],[2,1.89,42.01]],"ltp":1.88,"tv":896.31,"id":8174333}]}]}
{"op":"mcm","clk":"1001772237","pt":1580640055628,"mc":[{"id":"1.168224344","rc":[{"trd":[[1.79,0.03]],"batb":[[0,1.79,21.15]],"ltp":1.79,"tv":896.34,"id":8174333}],"tv":990.33}]}
{"op":"mcm","clk":"1001772787","pt":1580640061753,"mc":[{"id":"1.168224344","rc":[{"batb":[[0,2.12,36.97],[1,1.88,17.23],[2,1.01,15.52]],"ltp":2.2,"tv":93.99,"id":6498878},{"batb":[[0,1.72,57.97],[1,1.53,36.82],[2,1.01,15.51]],"batl":[[0,1.89,42.01],[1,2.3,309.75],[2,7,2.27]],"ltp":1.79,"tv":896.34,"id":8174333}]}]}
{"op":"mcm","clk":"1001772930","pt":1580640062869,"mc":[{"id":"1.168224344","rc":[{"batb":[[0,1.88,17.23],[1,1.01,15.52],[2,1.01,0]],"batl":[[0,2.72,241.55],[1,2.72,0]],"ltp":2.2,"tv":93.99,"id":6498878},{"batb":[[0,1.53,36.82],[1,1.01,15.51],[2,1.01,0]],"batl":[[0,2.3,309.75],[1,7,2.27],[2,7,0]],"ltp":1.79,"tv":896.34,"id":8174333}]}]}
{"op":"mcm","clk":"1001773055","pt":1580640064359,"mc":[{"id":"1.168224344","rc":[{"batb":[[0,1.54,146.11],[1,1.53,199.33],[2,1.01,15.51]],"batl":[[0,2.1,119.86],[1,2.12,111.2],[2,2.3,309.75]],"ltp":1.79,"tv":896.34,"id":8174333}]}]}
{"op":"mcm","clk":"1001773381","pt":1580640068151,"mc":[{"id":"1.168224344","rc":[{"batb":[[0,1.53,36.82],[1,1.01,15.51],[2,1.01,0]],"batl":[[0,2.3,309.75],[1,7,2.27],[2,2.3,0]],"ltp":1.79,"tv":896.34,"id":8174333}]}]}
{"op":"mcm","clk":"1001773556","pt":1580640070354,"mc":[{"id":"1.168224344","rc":[{"batb":[[1,1.01,15.52]],"batl":[[0,7,2.27],[1,7,0]],"ltp":1.79,"tv":896.34,"id":8174333}]}]}
{"op":"mcm","clk":"1001773614","pt":1580640070937,"mc":[{"id":"1.168224344","rc":[{"batb":[[0,1.91,124.94],[1,1.89,153.85],[2,1.88,17.23]],"batl":[[0,1.99,109.12],[1,2.02,192.81]],"ltp":2.2,"tv":93.99,"id":6498878},{"batb":[[1,1.01,15.51]],"ltp":1.79,"tv":896.34,"id":8174333}]}]}
{"op":"mcm","clk":"1001773712","pt":1580640072043,"mc":[{"id":"1.168224344","rc":[{"batb":[[1,1.89,200.9]],"batl":[[2,2.12,36.97]],"ltp":2.2,"tv":93.99,"id":6498878},{"batb":[[0,2.02,28.17],[1,1.9,46.21],[2,1.83,19.67]],"batl":[[0,2.12,36.97],[1,7,2.27]],"ltp":1.79,"tv":896.34,"id":8174333}]}]}
{"op":"mcm","clk":"1001773898","pt":1580640074272,"mc":[{"id":"1.168224344","rc":[{"batl":[[1,2.72,241.55],[2,7,2.27]],"ltp":1.79,"tv":896.34,"id":8174333}]}]}
{"op":"mcm","clk":"1001774904","pt":1580640083976,"mc":[{"id":"1.168224344","rc":[{"batl":[[2,2.5,274.54]],"ltp":2.2,"tv":93.99,"id":6498878}]}]}
{"op":"mcm","clk":"1001775204","pt":1580640087372,"mc":[{"id":"1.168224344","rc":[{"batl":[[2,2.1,37.81]],"ltp":2.2,"tv":93.99,"id":6498878}]}]}
{"op":"mcm","clk":"1001781720","pt":1580640143381,"mc":[{"id":"1.168224344","rc":[{"batb":[[0,1.89,47.05],[1,1.57,31.71],[2,1.01,15.52]],"batl":[[0,2.1,37.81],[1,2.5,274.54],[2,2.1,0]],"ltp":2.2,"tv":93.99,"id":6498878},{"batb":[[0,1.9,46.21],[1,1.83,19.67],[2,1.01,15.52]],"ltp":1.79,"tv":896.34,"id":8174333}]}]}
{"op":"mcm","clk":"1001781933","pt":1580640145078,"mc":[{"id":"1.168224344","rc":[{"batb":[[0,1.57,31.71],[1,1.01,15.52],[2,1.01,0]],"batl":[[0,2.5,274.54],[1,2.5,0]],"ltp":2.2,"tv":93.99,"id":6498878},{"batb":[[0,1.83,19.67],[1,1.01,15.52],[2,1.01,0]],"batl":[[0,2.72,241.55],[1,7,2.27],[2,7,0]],"ltp":1.79,"tv":896.34,"id":8174333}]}]}
{"op":"mcm","clk":"1001782117","pt":1580640146383,"mc":[{"id":"1.168224344","rc":[{"batb":[[0,1.62,122.74],[1,1.61,132.97],[2,1.57,31.71]],"batl":[[0,2.24,169.8],[1,2.26,93.08],[2,2.5,274.54]],"ltp":2.2,"tv":93.99,"id":6498878}]}]}
{"op":"mcm","clk":"1001782171","pt":1580640146858,"mc":[{"id":"1.168224344","rc":[{"batb":[[0,1.57,31.71],[1,1.01,15.52],[2,1.57,0]],"batl":[[0,2.5,274.54],[1,2.26,0],[2,2.5,0]],"ltp":2.2,"tv":93.99,"id":6498878}]}]}
{"op":"mcm","clk":"1001783185","pt":1580640153363,"mc":[{"id":"1.168224344","rc":[{"batb":[[0,1.62,122.74],[1,1.61,132.97],[2,1.57,31.71]],"batl":[[0,2.24,169.8],[1,2.26,93.08],[2,2.5,274.54]],"ltp":2.2,"tv":93.99,"id":6498878}]}]}
{"op":"mcm","clk":"1001784517","pt":1580640163203,"mc":[{"id":"1.168224344","rc":[{"batl":[[0,2.5,274.54],[1,2.26,0],[2,2.5,0]],"ltp":2.2,"tv":93.99,"id":6498878}]}]}
{"op":"mcm","clk":"1001784824","pt":1580640165202,"mc":[{"id":"1.168224344","rc":[{"batl":[[0,7,2.27],[1,7,0]],"ltp":1.79,"tv":896.34,"id":8174333}]}]}
{"op":"mcm","clk":"1001785012","pt":1580640166306,"mc":[{"id":"1.168224344","rc":[{"batl":[[0,1.68,213.29],[1,1.7,219.1]],"ltp":2.2,"tv":93.99,"id":6498878}]}]}
{"op":"mcm","clk":"1001785113","pt":1580640167027,"mc":[{"id":"1.168224344","rc":[{"batb":[[0,2.58,14.4],[1,2.14,24.23],[2,1.01,15.52]],"ltp":1.79,"tv":896.34,"id":8174333}]}]}
{"op":"mcm","clk":"1001785308","pt":1580640168309,"mc":[{"id":"1.168224344","rc":[{"batb":[[0,1.62,189.96]],"ltp":2.2,"tv":93.99,"id":6498878},{"batl":[[0,2.6,26.05],[1,7,2.27]],"ltp":1.79,"tv":896.34,"id":8174333}]}]}
{"op":"mcm","clk":"1001785473","pt":1580640169412,"mc":[{"id":"1.168224344","rc":[{"batl":[[2,2.1,363.31]],"ltp":2.2,"tv":93.99,"id":6498878},{"batl":[[1,3.45,180.4],[2,7,2.27]],"ltp":1.79,"tv":896.34,"id":8174333}]}]}
{"op":"mcm","clk":"1001785568","pt":1580640170099,"mc":[{"id":"1.168224344","rc":[{"batl":[[2,1.76,42.01]],"ltp":2.2,"tv":93.99,"id":6498878},{"trd":[[2.58,23.53]],"batb":[[0,2.58,2.64],[1,2.32,31.09],[2,2.14,24.23]],"ltp":2.58,"tv":919.86,"id":8174333}],"tv":1013.86}]}
{"op":"mcm","clk":"1001787392","pt":1580640182407,"mc":[{"id":"1.168224344","rc":[{"batb":[[0,1.62,67.22],[1,1.57,31.71],[2,1.29,73.34]],"batl":[[0,1.76,42.01],[1,2.1,363.31],[2,1.76,0]],"ltp":2.2,"tv":93.99,"id":6498878}]}]}
{"op":"mcm","clk":"1001787544","pt":1580640183199,"mc":[{"id":"1.168224344","rc":[{"batb":[[0,1.29,73.34],[1,1.01,15.51],[2,1.29,0]],"batl":[[0,2.1,363.31],[1,2.1,0]],"ltp":2.2,"tv":93.99,"id":6498878},{"batb":[[0,2.14,24.23],[1,1.01,15.52],[2,2.14,0]],"batl":[[0,3.45,180.4],[1,7,2.27],[2,7,0]],"ltp":2.58,"tv":919.86,"id":8174333}]}]}
{"op":"mcm","clk":"1001787873","pt":1580640185235,"mc":[{"id":"1.168224344","rc":[{"batb":[[0,1.33,369.27],[1,1.32,314.39],[2,1.29,73.33]],"batl":[[0,1.92,134.14],[1,1.94,144.24],[2,2.1,363.31]],"ltp":2.2,"tv":93.99,"id":6498878}]}]}
{"op":"mcm","clk":"1001788015","pt":1580640186028,"mc":[{"id":"1.168224344","rc":[{"batb":[[0,1.3,71.3],[1,1.01,15.51],[2,1.29,0]],"batl":[[0,2.1,363.31],[1,1.94,0],[2,2.1,0]],"ltp":2.2,"tv":93.99,"id":6498878},{"batb":[[0,2.1,25.1]],"ltp":2.58,"tv":919.86,"id":8174333}]}]}
{"op":"mcm","clk":"1001788382","pt":1580640188292,"mc":[{"id":"1.168224344","rc":[{"batb":[[0,1.55,193.79],[1,1.54,157.58],[2,1.3,71.3]],"batl":[[0,1.61,249.38],[1,1.62,128.5],[2,2.1,363.31]],"ltp":2.2,"tv":93.99,"id":6498878}]}]}
{"op":"mcm","clk":"1001788646","pt":1580640189768,"mc":[{"id":"1.168224344","rc":[{"batb":[[0,1.3,71.3],[1,1.01,15.51],[2,1.3,0]],"batl":[[0,2.1,363.31],[1,1.62,0],[2,2.1,0]],"ltp":2.2,"tv":93.99,"id":6498878}]}]}
{"op":"mcm","clk":"1001788960","pt":1580640191618,"mc":[{"id":"1.168224344","rc":[{"batl":[[0,7,2.27],[1,7,0]],"ltp":2.58,"tv":919.86,"id":8174333}]}]}
{"op":"mcm","clk":"1001789171","pt":1580640192937,"mc":[{"id":"1.168224344","rc":[{"batb":[[0,1.33,369.27],[1,1.32,314.39],[2,1.3,71.29]],"batl":[[0,1.92,134.14],[1,1.94,144.24]],"ltp":2.2,"tv":93.99,"id":6498878}]}]}
{"op":"mcm","clk":"1001789822","pt":1580640197219,"mc":[{"id":"1.168224344","rc":[{"trd":[[1.48,0.02]],"batb":[[0,1.33,369.26]],"batl":[[0,1.37,257.63],[1,1.38,243.14]],"ltp":1.48,"tv":94.01,"id":6498878}],"tv":1013.88}]}
{"op":"mcm","clk":"1001789979","pt":1580640198331,"mc":[{"id":"1.168224344","rc":[{"batb":[[0,1.34,123.51],[1,1.33,369.26],[2,1.32,314.39]],"ltp":1.48,"tv":94.01,"id":6498878},{"batb":[[0,3.8,13.06],[1,2.86,10.86],[2,1.01,15.52]],"batl":[[0,3.9,14.28],[1,7,2.27]],"ltp":2.58,"tv":919.86,"id":8174333}]}]}
{"op":"mcm","clk":"1001790285","pt":1580640199844,"mc":[{"id":"1.168224344","rc":[{"batl":[[2,1.71,542.06]],"ltp":1.48,"tv":94.01,"id":6498878},{"batl":[[1,5.5,115.06],[2,7,2.27]],"ltp":2.58,"tv":919.86,"id":8174333}]}]}
{"op":"mcm","clk":"1001790497","pt":1580640201246,"mc":[{"id":"1.168224344","rc":[{"batl":[[2,1.42,42.01]],"ltp":1.48,"tv":94.01,"id":6498878}]}]}
{"op":"mcm","clk":"1001790875","pt":1580640204252,"mc":[{"id":"1.168224344","rc":[{"batb":[[1,3.4,16.8],[2,2.86,10.86]],"ltp":2.58,"tv":919.86,"id":8174333}]}]}
{"op":"mcm","clk":"1001791452","pt":1580640208122,"mc":[{"id":"1.168224344","rc":[{"trd":[[1.34,186.52]],"batb":[[0,1.34,30.25]],"ltp":1.34,"tv":280.54,"id":6498878}],"tv":1200.4}]}
{"op":"mcm","clk":"1001791560","pt":1580640209065,"mc":[{"id":"1.168224344","rc":[{"batb":[[0,1.33,369.26],[1,1.32,314.39],[2,1.3,71.29]],"batl":[[2,1.71,542.06]],"ltp":1.34,"tv":280.54,"id":6498878},{"batb":[[1,2.86,10.86],[2,1.01,15.52]],"batl":[[0,5.5,115.06],[1,7,2.27],[2,7,0]],"ltp":2.58,"tv":919.86,"id":8174333}]}]}
{"op":"mcm","clk":"1001791865","pt":1580640211232,"mc":[{"id":"1.168224344","rc":[{"batb":[[0,1.3,71.29],[1,1.09,252.65],[2,1.01,15.51]],"batl":[[0,1.71,542.06],[1,1.38,0],[2,1.71,0]],"ltp":1.34,"tv":280.54,"id":6498878}]}]}
{"op":"mcm","clk":"1001792025","pt":1580640212355,"mc":[{"id":"1.168224344","rc":[{"batb":[[0,1.33,126.87]],"batl":[[0,1.4,42.01],[1,1.71,542.06]],"ltp":1.34,"tv":280.54,"id":6498878},{"batb":[[0,3.5,16.8]],"batl":[[0,4,13.44],[1,5.5,115.06],[2,7,2.27]],"ltp":2.58,"tv":919.86,"id":8174333}]}]}
{"op":"mcm","clk":"1001792130","pt":1580640213088,"mc":[{"id":"1.168224344","rc":[{"batb":[[0,1.09,252.65],[1,1.01,15.51],[2,1.01,0]],"batl":[[0,1.71,542.06],[1,1.71,0]],"ltp":1.34,"tv":280.54,"id":6498878},{"batb":[[0,2.86,10.86],[1,1.01,15.52],[2,1.01,0]],"batl":[[0,5.5,115.06],[1,7,2.27],[2,7,0]],"ltp":2.58,"tv":919.86,"id":8174333}]}]}
{"op":"mcm","clk":"1001792294","pt":1580640214092,"mc":[{"id":"1.168224344","rc":[{"batb":[[0,1.11,1084.43],[1,1.09,252.65],[2,1.01,15.51]],"batl":[[0,1.56,178.04],[1,1.57,144.28]],"ltp":1.34,"tv":280.54,"id":6498878},{"batl":[[0,7,2.27],[1,7,0]],"ltp":2.58,"tv":919.86,"id":8174333}]}]}
{"op":"mcm","clk":"1001792470","pt":1580640215344,"mc":[{"id":"1.168224344","rc":[{"batb":[[1,1.09,249.26]],"ltp":1.34,"tv":280.54,"id":6498878},{"batb":[[0,2.84,11.09]],"ltp":2.58,"tv":919.86,"id":8174333}]}]}
{"op":"mcm","clk":"1001793496","pt":1580640223759,"mc":[{"id":"1.168224344","rc":[{"batb":[[0,1.09,249.26],[1,1.01,15.51],[2,1.01,0]],"ltp":1.34,"tv":280.54,"id":6498878}]}]}
{"op":"mcm","clk":"1001793941","pt":1580640227331,"mc":[{"id":"1.168224344","rc":[{"batb":[[0,1.51,195.22],[1,1.5,174.87],[2,1.48,39.5]],"ltp":1.34,"tv":280.54,"id":6498878},{"batb":[[1,2.18,22.66],[2,1.01,15.52]],"ltp":2.58,"tv":919.86,"id":8174333}]}]}
{"op":"mcm","clk":"1001794046","pt":1580640228261,"mc":[{"id":"1.168224344","rc":[{"batb":[[2,1.49,85.7]],"batl":[[2,1.58,42.01]],"ltp":1.34,"tv":280.54,"id":6498878},{"batb":[[1,2.72,24.37],[2,2.18,22.66]],"batl":[[0,3.05,20.16],[1,7,2.27]],"ltp":2.58,"tv":919.86,"id":8174333}]}]}
{"op":"mcm","clk":"1001794150","pt":1580640229150,"mc":[{"id":"1.168224344","rc":[{"batl":[[1,3.9,158.24],[2,7,2.27]],"ltp":2.58,"tv":919.86,"id":8174333}]}]}
{"op":"mcm","clk":"1001795732","pt":1580640243167,"mc":[{"id":"1.168224344","rc":[{"batb":[[0,1.18,129.83],[1,1.01,15.51],[2,1.49,0]],"batl":[[0,1.95,409.86],[1,1.57,0],[2,1.58,0]],"ltp":1.34,"tv":280.54,"id":6498878},{"batb":[[0,2.18,22.66],[1,1.01,15.52],[2,2.18,0]],"batl":[[0,3.9,158.24],[1,7,2.27],[2,7,0]],"ltp":2.58,"tv":919.86,"id":8174333}]}]}
{"op":"mcm","clk":"1001795874","pt":1580640244362,"mc":[{"id":"1.168224344","rc":[{"batl":[[0,7,2.27],[1,7,0]],"ltp":2.58,"tv":919.86,"id":8174333}]}]}
{"op":"mcm","clk":"1001796015","pt":1580640245556,"mc":[{"id":"1.168224344","rc":[{"batb":[[0,1.2,439.4],[1,1.19,592.55],[2,1.18,129.83]],"batl":[[0,1.85,143.17],[1,1.87,161.38]],"ltp":1.34,"tv":280.54,"id":6498878}]}]}
{"op":"mcm","clk":"1001798885","pt":1580640271121,"mc":[{"id":"1.168224344","rc":[{"batb":[[0,1.18,129.83],[1,1.01,15.51],[2,1.18,0]],"ltp":1.34,"tv":280.54,"id":6498878}]}]}
{"op":"mcm","clk":"1001799281","pt":1580640274311,"mc":[{"id":"1.168224344","rc":[{"batb":[[0,1.78,118.87],[1,1.76,193.74],[2,1.18,129.83]],"ltp":1.34,"tv":280.54,"id":6498878}]}]}
{"op":"mcm","clk":"1001799371","pt":1580640275032,"mc":[{"id":"1.168224344","rc":[{"batb":[[1,1.76,214.91],[2,1.34,60.66]],"ltp":1.34,"tv":280.54,"id":6498878},{"batb":[[1,1.78,20.87],[2,1.01,15.51]],"ltp":2.58,"tv":919.86,"id":8174333}]}]}
{"op":"mcm","clk":"1001799505","pt":1580640276185,"mc":[{"id":"1.168224344","rc":[{"batb":[[2,1.73,57.13]],"batl":[[1,1.86,42.01],[2,1.87,161.38]],"ltp":1.34,"tv":280.54,"id":6498878},{"batb":[[1,2.16,36.13],[2,1.78,20.87]],"batl":[[0,2.38,30.25],[1,7,2.27]],"ltp":2.58,"tv":919.86,"id":8174333}]}]}
{"op":"mcm","clk":"1001799542","pt":1580640276505,"mc":[{"id":"1.168224344","rc":[{"batl":[[1,2.92,221.26],[2,7,2.27]],"ltp":2.58,"tv":919.86,"id":8174333}]}]}
{"op":"mcm","clk":"1001799889","pt":1580640279795,"mc":[{"id":"1.168224344","rc":[{"trd":[[1.85,186.52]],"batl":[[0,1.85,49.91]],"ltp":1.85,"tv":467.06,"id":6498878}],"tv":1386.93}]}
{"op":"mcm","clk":"1001800311","pt":1580640283090,"mc":[{"id":"1.168224344","rc":[{"batb":[[0,1.78,154.37]],"batl":[[0,1.85,109.02]],"ltp":1.85,"tv":467.06,"id":6498878}]}]}
{"op":"mcm","clk":"1001801663","pt":1580640295255,"mc":[{"id":"1.168224344","rc":[{"batb":[[0,1.34,60.66],[1,1.01,15.51],[2,1.73,0]],"batl":[[0,2.36,299.17],[1,1.86,0],[2,1.87,0]],"ltp":1.85,"tv":467.06,"id":6498878},{"batb":[[0,1.78,20.87],[1,1.01,15.51],[2,1.78,0]],"batl":[[0,2.92,221.26],[1,7,2.27],[2,7,0]],"ltp":2.58,"tv":919.86,"id":8174333}]}]}
{"op":"mcm","clk":"1001801821","pt":1580640296525,"mc":[{"id":"1.168224344","rc":[{"batl":[[0,7,2.27],[1,7,0]],"ltp":2.58,"tv":919.86,"id":8174333}]}]}
{"op":"mcm","clk":"1001801942","pt":1580640297454,"mc":[{"id":"1.168224344","rc":[{"batb":[[0,1.37,293.96],[1,1.36,269.59],[2,1.34,60.66]],"batl":[[0,2.26,138.69],[1,2.28,90.83]],"ltp":1.85,"tv":467.06,"id":6498878}]}]}
{"op":"mcm","clk":"1001802179","pt":1580640299029,"mc":[{"id":"1.168224344","rc":[{"batb":[[0,1.34,60.66],[1,1.01,15.51],[2,1.34,0]],"ltp":1.85,"tv":467.06,"id":6498878}]}]}
{"op":"mcm","clk":"1001802626","pt":1580640302349,"mc":[{"id":"1.168224344","rc":[{"batb":[[0,1.68,168.36],[1,1.67,116.67],[2,1.34,60.66]],"batl":[[0,1.75,199.11],[1,1.77,191.72]],"ltp":1.85,"tv":467.06,"id":6498878}]}]}
{"op":"mcm","clk":"1001802751","pt":1580640303073,"mc":[{"id":"1.168224344","rc":[{"batb":[[0,1.34,60.66],[1,1.01,15.51],[2,1.34,0]],"ltp":1.85,"tv":467.06,"id":6498878}]}]}
{"op":"mcm","clk":"1001802998","pt":1580640304869,"mc":[{"id":"1.168224344","rc":[{"batl":[[0,2.22,329.01]],"ltp":1.85,"tv":467.06,"id":6498878},{"batl":[[0,3.15,200.42],[1,7,2.27]],"ltp":2.58,"tv":919.86,"id":8174333}]}]}
{"op":"mcm","clk":"1001803165","pt":1580640306036,"mc":[{"id":"1.168224344","rc":[{"batb":[[0,1.37,293.96],[1,1.36,269.59],[2,1.34,60.66]],"batl":[[0,2.26,138.69],[1,2.28,90.83]],"ltp":1.85,"tv":467.06,"id":6498878},{"batl":[[0,7,2.27],[1,7,0]],"ltp":2.58,"tv":919.86,"id":8174333}]}]}
{"op":"mcm","clk":"1001804551","pt":1580640316971,"mc":[{"id":"1.168224344","rc":[{"batl":[[0,1.41,203.35],[1,1.42,214.54]],"ltp":1.85,"tv":467.06,"id":6498878}]}]}
{"op":"mcm","clk":"1001804705","pt":1580640318177,"mc":[{"id":"1.168224344","rc":[{"batb":[[1,1.36,385.54]],"batl":[[2,1.43,42.01]],"ltp":1.85,"tv":467.06,"id":6498878},{"batb":[[0,3.5,16.05],[1,3.3,17.64],[2,2.2,21.72]],"batl":[[0,3.8,14.28],[1,7,2.27]],"ltp":2.58,"tv":919.86,"id":8174333}]}]}
{"op":"mcm","clk":"1001804808","pt":1580640318903,"mc":[{"id":"1.168224344","rc":[{"batl":[[1,4.9,126.27],[2,7,2.27]],"ltp":2.58,"tv":919.86,"id":8174333}]}]}
{"op":"mcm","clk":"1001806695","pt":1580640334016,"mc":[{"id":"1.168224344","rc":[{"batb":[[0,1.36,115.95],[1,1.01,15.51],[2,1.34,0]],"batl":[[0,1.43,42.01],[1,1.77,500.61],[2,1.43,0]],"ltp":1.85,"tv":467.06,"id":6498878},{"batb":[[0,3.3,17.64],[1,2.2,21.72],[2,1.01,15.52]],"ltp":2.58,"tv":919.86,"id":8174333}]}]}
{"op":"mcm","clk":"1001806874","pt":1580640335307,"mc":[{"id":"1.168224344","rc":[{"batb":[[0,1.01,15.51],[1,1.01,0]],"ltp":1.85,"tv":467.06,"id":6498878},{"batb":[[0,2.2,21.72],[1,1.01,15.52],[2,1.01,0]],"batl":[[0,7,2.27],[1,4.9,0],[2,7,0]],"ltp":2.58,"tv":919.86,"id":8174333}]}]}
{"op":"mcm","clk":"1001807098","pt":1580640337296,"mc":[{"id":"1.168224344","rc":[{"batb":[[0,2.22,21.64],[1,2.2,21.72],[2,1.01,15.52]],"ltp":2.58,"tv":919.86,"id":8174333}]}]}
{"op":"mcm","clk":"1001807173","pt":1580640338027,"mc":[{"id":"1.168224344","rc":[{"batb":[[1,1.01,15.52],[2,1.01,0]],"ltp":2.58,"tv":919.86,"id":8174333}]}]}
{"op":"mcm","clk":"1001807420","pt":1580640340117,"mc":[{"id":"1.168224344","rc":[{"batb":[[0,1.27,517.73],[1,1.26,408.86],[2,1.01,15.51]],"batl":[[0,1.31,375.95],[1,1.32,298.3]],"ltp":1.85,"tv":467.06,"id":6498878}]}]}
{"op":"mcm","clk":"1001807535","pt":1580640341113,"mc":[{"id":"1.168224344","rc":[{"batb":[[0,1.01,15.51],[1,1.26,0],[2,1.01,0]],"batl":[[0,1.66,579.81],[1,1.32,0]],"ltp":1.85,"tv":467.06,"id":6498878},{"batl":[[0,6,106.18],[1,7,2.27]],"ltp":2.58,"tv":919.86,"id":8174333}]}]}
{"op":"mcm","clk":"1001807676","pt":1580640342107,"mc":[{"id":"1.168224344","rc":[{"batl":[[0,7,2.27],[1,7,0]],"ltp":2.58,"tv":919.86,"id":8174333}]}]}
{"op":"mcm","clk":"1001807874","pt":1580640343736,"mc":[{"id":"1.168224344","rc":[{"batl":[[0,1.84,159.97],[1,1.86,163.96]],"ltp":1.85,"tv":467.06,"id":6498878}]}]}
{"op":"mcm","clk":"1001808806","pt":1580640351406,"mc":[{"id":"1.168224344","rc":[{"batb":[[0,1.77,110.26],[1,1.75,197.35],[2,1.74,22.11]],"ltp":1.85,"tv":467.06,"id":6498878},{"batb":[[1,1.8,20.14],[2,1.01,15.52]],"ltp":2.58,"tv":919.86,"id":8174333}]}]}
{"op":"mcm","clk":"1001808913","pt":1580640352351,"mc":[{"id":"1.168224344","rc":[{"batb":[[1,2.18,35.29],[2,1.8,20.14]],"batl":[[0,2.4,29.41],[1,7,2.27]],"ltp":2.58,"tv":919.86,"id":8174333}]}]}
{"op":"mcm","clk":"1001809021","pt":1580640353145,"mc":[{"id":"1.168224344","rc":[{"batl":[[2,2.36,299.17]],"ltp":1.85,"tv":467.06,"id":6498878},{"batl":[[1,2.92,221.26],[2,7,2.27]],"ltp":2.58,"tv":919.86,"id":8174333}]}]}
{"op":"mcm","clk":"1001811137","pt":1580640369941,"mc":[{"id":"1.168224344","rc":[{"batb":[[0,1.71,58.81],[1,1.33,63.02],[2,1.01,15.51]],"batl":[[0,2.36,299.17],[1,1.86,0],[2,2.36,0]],"ltp":1.85,"tv":467.06,"id":6498878},{"batb":[[0,2.18,35.29],[1,1.8,20.14],[2,1.01,15.52]],"ltp":2.58,"tv":919.86,"id":8174333}]}]}
{"op":"mcm","clk":"1001811305","pt":1580640371356,"mc":[{"id":"1.168224344","rc":[{"batb":[[0,1.33,63.02],[1,1.01,15.51],[2,1.01,0]],"ltp":1.85,"tv":467.06,"id":6498878},{"batb":[[0,1.8,20.14],[1,1.01,15.52],[2,1.01,0]],"batl":[[0,7,2.27],[1,2.92,0],[2,7,0]],"ltp":2.58,"tv":919.86,"id":8174333}]}]}
{"op":"mcm","clk":"1001811519","pt":1580640373137,"mc":[{"id":"1.168224344","rc":[{"batb":[[0,1.36,371.06],[1,1.35,280.45],[2,1.33,63.02]],"batl":[[0,1.85,42.01],[1,2.24,142.1],[2,2.26,93.06]],"ltp":1.85,"tv":467.06,"id":6498878}]}]}
{"op":"mcm","clk":"1001811612","pt":1580640373966,"mc":[{"id":"1.168224344","rc":[{"batl":[[0,2.24,142.1],[1,2.26,93.06],[2,2.26,0]],"ltp":1.85,"tv":467.06,"id":6498878}]}]}
{"op":"mcm","clk":"1001812044","pt":1580640377339,"mc":[{"id":"1.168224344","rc":[{"batb":[[0,1.33,63.02],[1,1.01,15.51],[2,1.33,0]],"ltp":1.85,"tv":467.06,"id":6498878}]}]}
{"op":"mcm","clk":"1001812355","pt":1580640380356,"mc":[{"id":"1.168224344","rc":[{"batl":[[0,2.22,33.61]],"ltp":1.85,"tv":467.06,"id":6498878},{"batb":[[0,1.82,50.41],[1,1.81,144.01],[2,1.8,20.14]],"batl":[[0,1.89,172.68],[1,1.91,151.54],[2,7,2.27]],"ltp":2.58,"tv":919.86,"id":8174333}]}]}
{"op":"mcm","clk":"1001812461","pt":1580640381341,"mc":[{"id":"1.168224344","rc":[{"batb":[[0,2.12,23.92],[1,2.02,41.17],[2,1.72,23.05]],"ltp":1.85,"tv":467.06,"id":6498878},{"batl":[[2,1.98,42.01]],"ltp":2.58,"tv":919.86,"id":8174333}]}]}
{"op":"mcm","clk":"1001812599","pt":1580640382591,"mc":[{"id":"1.168224344","rc":[{"batl":[[1,2.82,231.28]],"ltp":1.85,"tv":467.06,"id":6498878}]}]}
{"op":"mcm","clk":"1001814104","pt":1580640395410,"mc":[{"id":"1.168224344","rc":[{"batb":[[0,1.72,23.05],[1,1.01,15.51],[2,1.72,0]],"batl":[[0,2.82,231.28],[1,2.82,0]],"ltp":1.85,"tv":467.06,"id":6498878},{"batb":[[0,1.62,29.21],[1,1.01,15.51],[2,1.8,0]],"batl":[[0,2.42,286.52],[1,7,2.27],[2,1.98,0]],"ltp":2.58,"tv":919.86,"id":8174333}]}]}
{"op":"mcm","clk":"1001814414","pt":1580640398089,"mc":[{"id":"1.168224344","rc":[{"batb":[[0,1.64,167.08],[1,1.63,127.94],[2,1.62,29.19]],"batl":[[0,2.34,148.51],[1,2.36,82.49],[2,2.42,286.52]],"ltp":2.58,"tv":919.86,"id":8174333}]}]}
{"op":"mcm","clk":"1001814878","pt":1580640402298,"mc":[{"id":"1.168224344","rc":[{"batl":[[0,2.42,286.52],[1,7,2.27],[2,2.42,0]],"ltp":2.58,"tv":919.86,"id":8174333}]}]}
{"op":"mcm","clk":"1001815243","pt":1580640405288,"mc":[{"id":"1.168224344","rc":[{"trd":[[1.79,0.07]],"batb":[[0,1.64,167.06]],"batl":[[0,1.7,150.34],[1,1.72,212.27],[2,7,2.27]],"ltp":1.79,"tv":919.9,"id":8174333}],"tv":1386.96}]}
{"op":"mcm","clk":"1001815360","pt":1580640406297,"mc":[{"id":"1.168224344","rc":[{"batb":[[0,2.44,15.82],[1,2.14,22.9],[2,1.01,15.51]],"batl":[[0,2.54,26.89]],"ltp":1.85,"tv":467.06,"id":6498878},{"batb":[[0,1.66,63.01],[1,1.64,167.06],[2,1.63,127.94]],"ltp":1.79,"tv":919.9,"id":8174333}]}]}
{"op":"mcm","clk":"1001815684","pt":1580640408869,"mc":[{"id":"1.168224344","rc":[{"batb":[[1,2.28,32.77],[2,2.14,22.9]],"batl":[[1,3.3,191.92]],"ltp":1.85,"tv":467.06,"id":6498878},{"batl":[[2,1.79,42.01]],"ltp":1.79,"tv":919.9,"id":8174333}]}]}
{"op":"mcm","clk":"1001816770","pt":1580640418232,"mc":[{"id":"1.168224344","rc":[{"batb":[[1,1.63,127.94],[2,1.62,29.19]],"ltp":1.79,"tv":919.9,"id":8174333}]}]}
{"op":"mcm","clk":"1001817104","pt":1580640420700,"mc":[{"id":"1.168224344","rc":[{"batb":[[1,1.63,238.37],[2,1.62,160.44]],"batl":[[0,1.7,205.69]],"ltp":1.79,"tv":919.9,"id":8174333}]}]}
{"op":"mcm","clk":"1001819081","pt":1580640438121,"mc":[{"id":"1.168224344","rc":[{"batb":[[1,1.62,29.19],[2,1.43,47.05]],"batl":[[0,1.79,42.01],[1,2.16,342.82],[2,7,2.27]],"ltp":1.79,"tv":919.9,"id":8174333}]}]}
{"op":"mcm","clk":"1001819236","pt":1580640439329,"mc":[{"id":"1.168224344","rc":[{"batb":[[0,2.14,22.9],[1,1.01,15.51],[2,2.14,0]],"batl":[[0,3.3,191.92],[1,3.3,0]],"ltp":1.85,"tv":467.06,"id":6498878},{"batb":[[0,1.43,47.05],[1,1.01,15.51],[2,1.43,0]],"batl":[[0,2.16,342.82],[1,7,2.27],[2,7,0]],"ltp":1.79,"tv":919.9,"id":8174333}]}]}
{"op":"mcm","clk":"1001819468","pt":1580640441258,"mc":[{"id":"1.168224344","rc":[{"batb":[[0,1.45,289.26],[1,1.44,210.37],[2,1.43,47.05]],"batl":[[0,1.87,163.8],[1,1.89,156.69],[2,2.16,342.82]],"ltp":1.79,"tv":919.9,"id":8174333}]}]}
{"op":"mcm","clk":"1001820430","pt":1580640449000,"mc":[{"id":"1.168224344","rc":[{"batl":[[0,2.16,342.82],[1,7,2.27],[2,2.16,0]],"ltp":1.79,"tv":919.9,"id":8174333}]}]}
{"op":"mcm","clk":"1001820697","pt":1580640451085,"mc":[{"id":"1.168224344","rc":[{"batl":[[0,7,2.27],[1,7,0]],"ltp":1.79,"tv":919.9,"id":8174333}]}]}
{"op":"mcm","clk":"1001820859","pt":1580640452400,"mc":[{"id":"1.168224344","rc":[{"batl":[[0,1.5,215.91],[1,1.51,169.05],[2,2.02,521.75]],"ltp":1.79,"tv":919.9,"id":8174333}]}]}
{"op":"mcm","clk":"1001820914","pt":1580640452813,"mc":[{"id":"1.168224344","rc":[{"batb":[[0,3,22.5],[1,2.52,14.71],[2,1.01,15.51]],"ltp":1.85,"tv":467.06,"id":6498878}]}]}
{"op":"mcm","clk":"1001821111","pt":1580640454277,"mc":[{"id":"1.168224344","rc":[{"batb":[[1,2.72,24.37],[2,2.52,14.71]],"batl":[[0,3.05,20.16]],"ltp":1.85,"tv":467.06,"id":6498878},{"batb":[[0,1.48,87.38],[1,1.45,289.26],[2,1.44,210.37]],"batl":[[2,1.58,42.01]],"ltp":1.79,"tv":919.9,"id":8174333}]}]}
{"op":"mcm","clk":"1001821233","pt":1580640455276,"mc":[{"id":"1.168224344","rc":[{"batl":[[1,4.2,148.03]],"ltp":1.85,"tv":467.06,"id":6498878}]}]}
{"op":"mcm","clk":"1001822842","pt":1580640468142,"mc":[{"id":"1.168224344","rc":[{"batb":[[0,2.72,24.37],[1,2.52,14.71],[2,1.01,15.51]],"ltp":1.85,"tv":467.06,"id":6498878},{"batb":[[1,1.26,85.92],[2,1.01,15.51]],"batl":[[0,1.58,42.01],[1,1.89,435.28],[2,7,2.27]],"ltp":1.79,"tv":919.9,"id":8174333}]}]}
{"op":"mcm","clk":"1001822980","pt":1580640469333,"mc":[{"id":"1.168224344","rc":[{"batb":[[0,2.52,14.71],[1,1.01,15.51],[2,1.01,0]],"batl":[[0,4.2,148.03],[1,4.2,0]],"ltp":1.85,"tv":467.06,"id":6498878},{"batb":[[0,1.26,85.92],[1,1.01,15.51],[2,1.01,0]],"batl":[[0,1.89,435.28],[1,7,2.27],[2,7,0]],"ltp":1.79,"tv":919.9,"id":8174333}]}]}
{"op":"mcm","clk":"1001823155","pt":1580640470692,"mc":[{"id":"1.168224344","rc":[{"batb":[[0,1.28,373.08],[1,1.27,394.61],[2,1.26,85.92]],"batl":[[0,1.67,204.4],[1,1.69,225.35],[2,1.89,435.28]],"ltp":1.79,"tv":919.9,"id":8174333}]}]}
{"op":"mcm","clk":"1001823364","pt":1580640472304,"mc":[{"id":"1.168224344","rc":[{"batl":[[0,1.89,435.28],[1,7,2.27],[2,1.89,0]],"ltp":1.79,"tv":919.9,"id":8174333}]}]}
{"op":"mcm","clk":"1001823618","pt":1580640474252,"mc":[{"id":"1.168224344","rc":[{"batl":[[0,7,2.27],[1,7,0]],"ltp":1.79,"tv":919.9,"id":8174333}]}]}
{"op":"mcm","clk":"1001823763","pt":1580640475349,"mc":[{"id":"1.168224344","rc":[{"batl":[[0,1.31,174.26],[1,1.32,307.87],[2,7,2.27]],"ltp":1.79,"tv":919.9,"id":8174333}]}]}
{"op":"mcm","clk":"1001823915","pt":1580640476337,"mc":[{"id":"1.168224344","rc":[{"batb":[[0,4.2,19.99],[1,3.7,15.12],[2,3.25,18.49]],"batl":[[0,4.3,12.6]],"ltp":1.85,"tv":467.06,"id":6498878},{"batb":[[0,1.3,139.47],[1,1.28,373.08],[2,1.27,394.61]],"batl":[[2,1.37,42.01]],"ltp":1.79,"tv":919.9,"id":8174333}]}]}
{"op":"mcm","clk":"1001824334","pt":1580640479410,"mc":[{"id":"1.168224344","rc":[{"batl":[[1,6,106.18]],"ltp":1.85,"tv":467.06,"id":6498878}]}]}
{"op":"mcm","clk":"1001825841","pt":1580640491363,"mc":[{"id":"1.168224344","rc":[{"batb":[[0,3.25,18.49],[1,1.01,15.51],[2,3.25,0]],"batl":[[0,6,106.18],[1,6,0]],"ltp":1.85,"tv":467.06,"id":6498878},{"batb":[[0,1.13,174.6],[1,1.01,15.51],[2,1.27,0]],"batl":[[0,1.66,579.81],[1,7,2.27],[2,1.37,0]],"ltp":1.79,"tv":919.9,"id":8174333}]}]}
{"op":"mcm","clk":"1001825971","pt":1580640492389,"mc":[{"id":"1.168224344","rc":[{"batl":[[0,7,2.27],[1,7,0]],"ltp":1.79,"tv":919.9,"id":8174333}]}]}
{"op":"mcm","clk":"1001826183","pt":1580640494129,"mc":[{"id":"1.168224344","rc":[{"batb":[[0,1.15,481.53],[1,1.14,644.21],[2,1.13,174.6]],"batl":[[0,1.44,197.68],[1,1.45,199.46],[2,7,2.27]],"ltp":1.79,"tv":919.9,"id":8174333}]}]}
{"op":"mcm","clk":"1001826279","pt":1580640494958,"mc":[{"id":"1.168224344","rc":[{"batb":[[0,1.13,174.6],[1,1.01,15.51],[2,1.13,0]],"ltp":1.79,"tv":919.9,"id":8174333}]}]}
{"op":"mcm","clk":"1001826689","pt":1580640498365,"mc":[{"id":"1.168224344","rc":[{"batb":[[1,3,21],[2,2.56,14.01]],"ltp":1.85,"tv":467.06,"id":6498878},{"batb":[[0,1.4,233.28],[1,1.39,246.04],[2,1.38,54.68]],"batl":[[2,1.5,42.01]],"ltp":1.79,"tv":919.9,"id":8174333}]}]}
{"op":"mcm","clk":"1001826747","pt":1580640498740,"mc":[{"id":"1.168224344","rc":[{"batl":[[0,3.4,16.8]],"ltp":1.85,"tv":467.06,"id":6498878},{"batb":[[0,1.41,101.66],[1,1.4,233.28],[2,1.39,246.04]],"ltp":1.79,"tv":919.9,"id":8174333}]}]}
{"op":"mcm","clk":"1001826874","pt":1580640499768,"mc":[{"id":"1.168224344","rc":[{"batl":[[1,4.6,136.05]],"ltp":1.85,"tv":467.06,"id":6498878}]}]}
{"op":"mcm","clk":"1001827753","pt":1580640507288,"mc":[{"id":"1.168224344","rc":[{"batb":[[1,1.4,192.94]],"ltp":1.79,"tv":919.9,"id":8174333}]}]}
{"op":"mcm","clk":"1001828028","pt":1580640509787,"mc":[{"id":"1.168224344","rc":[{"batl":[[0,1.44,236.89]],"ltp":1.79,"tv":919.9,"id":8174333}]}]}
{"op":"mcm","clk":"1001828197","pt":1580640511395,"mc":[{"id":"1.168224344","rc":[{"batb":[[0,2.56,14.01],[1,1.01,15.51],[2,2.56,0]],"batl":[[0,4.6,136.05],[1,4.6,0]],"ltp":1.85,"tv":467.06,"id":6498878},{"batb":[[0,1.19,119.28],[1,1.01,15.51],[2,1.39,0]],"batl":[[0,1.82,469.11],[1,7,2.27],[2,1.5,0]],"ltp":1.79,"tv":919.9,"id":8174333}]}]}
{"op":"mcm","clk":"1001828309","pt":1580640512387,"mc":[{"id":"1.168224344","rc":[{"batl":[[0,7,2.27],[1,7,0]],"ltp":1.79,"tv":919.9,"id":8174333}]}]}
{"op":"mcm","clk":"1001828857","pt":1580640517091,"mc":[{"id":"1.168224344","rc":[{"batb":[[0,1.35,399.25],[1,1.34,296.32],[2,1.19,119.28]],"batl":[[0,1.39,181.52],[1,1.4,232.83],[2,7,2.27]],"ltp":1.79,"tv":919.9,"id":8174333}]}]}
{"op":"mcm","clk":"1001829089","pt":1580640518994,"mc":[{"id":"1.168224344","rc":[{"batl":[[0,5.3,118.79]],"ltp":1.85,"tv":467.06,"id":6498878},{"batb":[[0,1.19,119.28],[1,1.01,15.51],[2,1.19,0]],"batl":[[0,1.73,527.57],[1,7,2.27],[2,7,0]],"ltp":1.79,"tv":919.9,"id":8174333}]}]}
{"op":"mcm","clk":"1001829293","pt":1580640520508,"mc":[{"id":"1.168224344","rc":[{"batl":[[0,7,2.27],[1,7,0]],"ltp":1.79,"tv":919.9,"id":8174333}]}]}
{"op":"mcm","clk":"1001829461","pt":1580640521933,"mc":[{"id":"1.168224344","rc":[{"batb":[[0,1.21,214.49],[1,1.2,563.12],[2,1.19,119.28]],"batl":[[0,1.64,227.12],[1,1.65,121.8],[2,7,2.27]],"ltp":1.79,"tv":919.9,"id":8174333}]}]}
{"op":"mcm","clk":"1001831761","pt":1580640542927,"mc":[{"id":"1.168224344","rc":[{"batb":[[0,1.19,119.28],[1,1.01,15.51],[2,1.19,0]],"ltp":1.79,"tv":919.9,"id":8174333}]}]}
{"op":"mcm","clk":"1001832171","pt":1580640546361,"mc":[{"id":"1.168224344","rc":[{"batb":[[1,2.44,28.57],[2,1.01,15.51]],"batl":[[0,2.7,24.37]],"ltp":1.85,"tv":467.06,"id":6498878},{"batb":[[0,1.58,246.81],[1,1.57,147.57],[2,1.19,119.28]],"batl":[[2,1.7,42.01]],"ltp":1.79,"tv":919.9,"id":8174333}]}]}
{"op":"mcm","clk":"1001832210","pt":1580640546836,"mc":[{"id":"1.168224344","rc":[{"batb":[[2,2.06,25.65]],"ltp":1.85,"tv":467.06,"id":6498878},{"batb":[[1,1.57,180.07],[2,1.3,71.13]],"ltp":1.79,"tv":919.9,"id":8174333}]}]}
{"op":"mcm","clk":"1001832453","pt":1580640549123,"mc":[{"id":"1.168224344","rc":[{"batl":[[1,3.45,180.4]],"ltp":1.85,"tv":467.06,"id":6498878}]}]}
{"op":"mcm","clk":"1001834788","pt":1580640570356,"mc":[{"id":"1.168224344","rc":[{"batb":[[0,1.58,72.26],[1,1.57,32.5]],"batl":[[0,1.7,42.01],[1,2.1,363.31],[2,7,2.27]],"ltp":1.79,"tv":919.9,"id":8174333}]}]}
{"op":"mcm","clk":"1001834905","pt":1580640571398,"mc":[{"id":"1.168224344","rc":[{"batb":[[0,2.06,25.65],[1,1.01,15.51],[2,2.06,0]],"batl":[[0,3.45,180.4],[1,3.45,0]],"ltp":1.85,"tv":467.06,"id":6498878},{"batb":[[0,1.3,71.13],[1,1.01,15.51],[2,1.3,0]],"batl":[[0,2.1,363.31],[1,7,2.27],[2,7,0]],"ltp":1.79,"tv":919.9,"id":8174333}]}]}
{"op":"mcm","clk":"1001835136","pt":1580640573386,"mc":[{"id":"1.168224344","rc":[{"batb":[[0,1.32,292.97],[1,1.31,331.5],[2,1.3,71.13]],"batl":[[0,1.91,102.78],[1,1.93,147.07],[2,2.1,363.31]],"ltp":1.79,"tv":919.9,"id":8174333}]}]}
{"op":"mcm","clk":"1001835346","pt":1580640575176,"mc":[{"id":"1.168224344","rc":[{"batb":[[0,1.3,71.13],[1,1.01,15.51],[2,1.3,0]],"ltp":1.79,"tv":919.9,"id":8174333}]}]}
{"op":"mcm","clk":"1001835739","pt":1580640578366,"mc":[{"id":"1.168224344","rc":[{"batb":[[1,2.02,41.17],[2,1.01,15.51]],"ltp":1.85,"tv":467.06,"id":6498878},{"batb":[[0,1.84,112.63],[1,1.82,174.02],[2,1.3,71.13]],"batl":[[2,1.97,42.01]],"ltp":1.79,"tv":919.9,"id":8174333}]}]}
{"op":"mcm","clk":"1001835826","pt":1580640578990,"mc":[{"id":"1.168224344","rc":[{"batb":[[2,1.82,19.12]],"batl":[[0,2.2,34.45]],"ltp":1.85,"tv":467.06,"id":6498878},{"batb":[[0,1.84,131.51],[1,1.82,224.43],[2,1.56,33.05]],"ltp":1.79,"tv":919.9,"id":8174333}]}]}
{"op":"mcm","clk":"1001836182","pt":1580640581684,"mc":[{"id":"1.168224344","rc":[{"batl":[[1,2.72,241.55]],"ltp":1.85,"tv":467.06,"id":6498878}]}]}
{"op":"mcm","clk":"1001837000","pt":1580640587904,"mc":[{"id":"1.168224344","rc":[{"batl":[[0,1.97,42.01],[1,2.5,274.54],[2,7,2.27]],"ltp":1.79,"tv":919.9,"id":8174333}]}]}
{"op":"mcm","clk":"1001837396","pt":1580640590791,"mc":[{"id":"1.168224344","rc":[{"batl":[[0,1.92,173.3],[1,1.94,144.7],[2,1.97,42.01]],"ltp":1.79,"tv":919.9,"id":8174333}]}]}
{"op":"mcm","clk":"1001838058","pt":1580640596167,"mc":[{"id":"1.168224344","rc":[{"batb":[[0,1.84,18.88],[1,1.82,50.41]],"batl":[[0,1.97,42.01],[1,2.5,274.54],[2,7,2.27]],"ltp":1.79,"tv":919.9,"id":8174333}]}]}
{"op":"mcm","clk":"1001838242","pt":1580640597376,"mc":[{"id":"1.168224344","rc":[{"batb":[[0,1.82,19.12],[1,1.01,15.51],[2,1.82,0]],"batl":[[0,2.72,241.55],[1,2.72,0]],"ltp":1.85,"tv":467.06,"id":6498878},{"batb":[[0,1.56,33.05],[1,1.01,15.51],[2,1.56,0]],"batl":[[0,2.5,274.54],[1,7,2.27],[2,7,0]],"ltp":1.79,"tv":919.9,"id":8174333}]}]}
{"op":"mcm","clk":"1001838445","pt":1580640598985,"mc":[{"id":"1.168224344","rc":[{"batb":[[0,1.57,265.74],[1,1.56,184.63],[2,1.01,15.51]],"batl":[[0,2.18,133.53],[1,2.2,100.19],[2,2.5,274.54]],"ltp":1.79,"tv":919.9,"id":8174333}]}]}
{"op":"mcm","clk":"1001838592","pt":1580640600270,"mc":[{"id":"1.168224344","rc":[{"batb":[[0,1.56,33.05],[1,1.01,15.51],[2,1.01,0]],"batl":[[0,2.5,274.54],[1,7,2.27],[2,2.5,0]],"ltp":1.79,"tv":919.9,"id":8174333}]}]}
{"op":"mcm","clk":"1001838970","pt":1580640603302,"mc":[{"id":"1.168224344","rc":[{"batb":[[0,1.85,136.11],[1,1.83,170.61],[2,1.82,19.12]],"batl":[[0,1.93,144.26],[1,1.95,142.07]],"ltp":1.85,"tv":467.06,"id":6498878},{"batl":[[0,7,2.27],[1,7,0]],"ltp":1.79,"tv":919.9,"id":8174333}]}]}
{"op":"mcm","clk":"1001839123","pt":1580640604373,"mc":[{"id":"1.168224344","rc":[{"batl":[[2,1.96,42.01]],"ltp":1.85,"tv":467.06,"id":6498878},{"batb":[[0,2.1,25.26],[1,2.06,39.49],[2,1.89,17.39]],"batl":[[0,2.26,32.77],[1,7,2.27]],"ltp":1.79,"tv":919.9,"id":8174333}]}]}
{"op":"mcm","clk":"1001839469","pt":1580640606686,"mc":[{"id":"1.168224344","rc":[{"batl":[[1,2.82,231.28],[2,7,2.27]],"ltp":1.79,"tv":919.9,"id":8174333}]}]}
{"op":"mcm","clk":"1001843268","pt":1580640636343,"mc":[{"id":"1.168224344","rc":[{"batb":[[0,1.85,111.01]],"ltp":1.85,"tv":467.06,"id":6498878}]}]}
{"op":"mcm","clk":"1001843672","pt":1580640639325,"mc":[{"id":"1.168224344","rc":[{"batl":[[0,1.93,168.37]],"ltp":1.85,"tv":467.06,"id":6498878}]}]}
{"op":"mcm","clk":"1001844266","pt":1580640643924,"mc":[{"id":"1.168224344","rc":[{"trd":[[1.85,194.52]],"batb":[[0,1.85,107.01]],"ltp":1.85,"tv":475.06,"id":6498878}],"tv":1394.96}]}
{"op":"mcm","clk":"1001845281","pt":1580640652344,"mc":[{"id":"1.168224344","rc":[{"trd":[[2.1,20]],"batb":[[0,2.1,15.26]],"ltp":2.1,"tv":939.9,"id":8174333}],"tv":1414.96}]}
{"op":"mcm","clk":"1001845777","pt":1580640656252,"mc":[{"id":"1.168224344","rc":[{"batb":[[2,1.82,18.88]],"ltp":1.85,"tv":475.06,"id":6498878},{"batb":[[0,2.08,25.57],[2,1.88,17.55]],"ltp":2.1,"tv":939.9,"id":8174333}]}]}
{"op":"mcm","clk":"1001849115","pt":1580640682847,"mc":[{"id":"1.168224344","rc":[{"batb":[[0,1.81,51.25],[1,1.54,33.75],[2,1.01,15.51]],"batl":[[0,1.96,42.01],[1,2.42,286.52],[2,1.96,0]],"ltp":1.85,"tv":475.06,"id":6498878},{"batb":[[0,2.06,39.49],[1,1.88,17.55],[2,1.01,15.51]],"ltp":2.1,"tv":939.9,"id":8174333}]}]}
{"op":"mcm","clk":"1001849178","pt":1580640683426,"mc":[{"id":"1.168224344","rc":[{"batb":[[0,1.54,33.75],[1,1.01,15.51],[2,1.01,0]],"batl":[[0,2.42,286.52],[1,2.42,0]],"ltp":1.85,"tv":475.06,"id":6498878},{"batb":[[0,1.88,17.55],[1,1.01,15.51],[2,1.01,0]],"batl":[[0,2.82,231.28],[1,7,2.27],[2,7,0]],"ltp":2.1,"tv":939.9,"id":8174333}]}]}
{"op":"mcm","clk":"1001849436","pt":1580640686044,"mc":[{"id":"1.168224344","rc":[{"batb":[[0,1.58,183.54],[1,1.57,146.3],[2,1.55,33.75]],"batl":[[0,2.14,140.66],[1,2.16,105.65],[2,2.42,286.52]],"ltp":1.85,"tv":475.06,"id":6498878}]}]}
{"op":"mcm","clk":"1001850387","pt":1580640693546,"mc":[{"id":"1.168224344","rc":[{"batb":[[0,1.55,33.75],[1,1.01,15.51],[2,1.55,0]],"batl":[[0,2.42,286.52],[1,2.16,0],[2,2.42,0]],"ltp":1.85,"tv":475.06,"id":6498878}]}]}
{"op":"mcm","clk":"1001850715","pt":1580640696336,"mc":[{"id":"1.168224344","rc":[{"batb":[[0,1.01,15.51],[1,1.01,0]],"batl":[[0,7,2.27],[1,7,0]],"ltp":2.1,"tv":939.9,"id":8174333}]}]}
{"op":"mcm","clk":"1001850827","pt":1580640697274,"mc":[{"id":"1.168224344","rc":[{"batb":[[0,2.02,27.62],[1,1.76,21.56],[2,1.55,33.75]],"ltp":1.85,"tv":475.06,"id":6498878},{"batb":[[0,1.88,137.82],[1,1.86,162.19],[2,1.74,22.66]],"batl":[[0,1.96,120.02],[1,1.98,136.06],[2,7,2.27]],"ltp":2.1,"tv":939.9,"id":8174333}]}]}
{"op":"mcm","clk":"1001850960","pt":1580640698370,"mc":[{"id":"1.168224344","rc":[{"batb":[[0,1.96,43.69],[2,1.01,15.51]],"batl":[[0,2.14,36.13]],"ltp":1.85,"tv":475.06,"id":6498878},{"batb":[[0,1.88,184.87]],"batl":[[2,2.04,40.33]],"ltp":2.1,"tv":939.9,"id":8174333}]}]}
{"op":"mcm","clk":"1001851134","pt":1580640699575,"mc":[{"id":"1.168224344","rc":[{"batl":[[1,2.72,241.55]],"ltp":1.85,"tv":475.06,"id":6498878}]}]}
