{"op":"mcm","clk":"998153799","pt":1580585268961,"mc":[{"id":"1.168224334","marketDefinition":{"bspMarket":false,"turnInPlayEnabled":true,"persistenceEnabled":true,"marketBaseRate":5.0,"eventId":"29681717","eventTypeId":"2","numberOfWinners":1,"bettingType":"ODDS","marketType":"SET_BETTING","marketTime":"2020-02-02T09:30:00.000Z","suspendTime":"2020-02-02T09:30:00.000Z","bspReconciled":false,"complete":true,"inPlay":false,"crossMatching":false,"runnersVoidable":false,"numberOfActiveRunners":4,"betDelay":0,"status":"OPEN","runners":[{"status":"ACTIVE","sortPriority":1,"id":13117428,"name":"Trungelliti 2-0"},{"status":"ACTIVE","sortPriority":2,"id":13117429,"name":"Trungelliti 2-1"},{"status":"ACTIVE","sortPriority":3,"id":17151079,"name":"Couacaud 2-0"},{"status":"ACTIVE","sortPriority":4,"id":17151080,"name":"Couacaud 2-1"}],"regulators":["MR_INT"],"countryCode":"FR","discountAllowed":false,"timezone":"UTC","openDate":"2020-02-02T09:30:00.000Z","version":3147098131,"name":"Set Betting","eventName":"Trungelliti v Couacaud"}}]}
{"op":"mcm","clk":"998154037","pt":1580585270458,"mc":[{"id":"1.168224334","marketDefinition":{"bspMarket":false,"turnInPlayEnabled":true,"persistenceEnabled":true,"marketBaseRate":5.0,"eventId":"29681717","eventTypeId":"2","numberOfWinners":1,"bettingType":"ODDS","marketType":"SET_BETTING","marketTime":"2020-02-02T09:30:00.000Z","suspendTime":"2020-02-02T09:30:00.000Z","bspReconciled":false,"complete":true,"inPlay":false,"crossMatching":false,"runnersVoidable":false,"numberOfActiveRunners":4,"betDelay":0,"status":"OPEN","runners":[{"status":"ACTIVE","sortPriority":1,"id":13117428,"name":"Trungelliti 2-0"},{"status":"ACTIVE","sortPriority":2,"id":13117429,"name":"Trungelliti 2-1"},{"status":"ACTIVE","sortPriority":3,"id":17151079,"name":"Couacaud 2-0"},{"status":"ACTIVE","sortPriority":4,"id":17151080,"name":"Couacaud 2-1"}],"regulators":["MR_INT"],"countryCode":"FR","discountAllowed":false,"timezone":"UTC","openDate":"2020-02-02T09:30:00.000Z","version":3147098131,"name":"Set Betting","eventName":"Trungelliti v Couacaud"}}]}
{"op":"mcm","clk":"998154461","pt":1580585272452,"mc":[{"id":"1.168224334","marketDefinition":{"bspMarket":false,"turnInPlayEnabled":true,"persistenceEnabled":true,"marketBaseRate":5.0,"eventId":"29681717","eventTypeId":"2","numberOfWinners":1,"bettingType":"ODDS","marketType":"SET_BETTING","marketTime":"2020-02-02T09:30:00.000Z","suspendTime":"2020-02-02T09:30:00.000Z","bspReconciled":false,"complete":true,"inPlay":false,"crossMatching":false,"runnersVoidable":false,"numberOfActiveRunners":4,"betDelay":0,"status":"OPEN","runners":[{"status":"ACTIVE","sortPriority":1,"id":13117428,"name":"Trungelliti 2-0"},{"status":"ACTIVE","sortPriority":2,"id":13117429,"name":"Trungelliti 2-1"},{"status":"ACTIVE","sortPriority":3,"id":17151079,"name":"Couacaud 2-0"},{"status":"ACTIVE","sortPriority":4,"id":17151080,"name":"Couacaud 2-1"}],"regulators":["MR_INT"],"countryCode":"FR","discountAllowed":true,"timezone":"UTC","openDate":"2020-02-02T09:30:00.000Z","version":3147098131,"name":"Set Betting","eventName":"Trungelliti v Couacaud"}}]}
{"op":"mcm","clk":"998565808","pt":1580587945216,"mc":[{"id":"1.168224334","rc":[{"batb":[[0,1.02,2]],"ltp":0.0,"tv":0.0,"id":13117429},{"batb":[[0,1.02,2]],"ltp":0.0,"tv":0.0,"id":13117428},{"batb":[[0,1.02,2]],"ltp":0.0,"tv":0.0,"id":17151080},{"batb":[[0,1.02,2]],"ltp":0.0,"tv":0.0,"id":17151079}]}]}
{"op":"mcm","clk":"999887184","pt":1580602185410,"mc":[{"id":"1.168224334","rc":[{"batb":[[1,1.01,0.51]],"ltp":0.0,"tv":0.0,"id":13117429},{"batb":[[1,1.01,0.51]],"ltp":0.0,"tv":0.0,"id":13117428},{"batb":[[1,1.01,0.51]],"ltp":0.0,"tv":0.0,"id":17151080},{"batb":[[1,1.01,0.51]],"ltp":0.0,"tv":0.0,"id":17151079}]}]}
{"op":"mcm","clk":"999983197","pt":1580603724270,"mc":[{"id":"1.168224334","rc":[{"batb":[[1,1.01,3.04]],"ltp":0.0,"tv":0.0,"id":13117429},{"batb":[[1,1.01,3.04]],"ltp":0.0,"tv":0.0,"id":13117428},{"batb":[[1,1.01,3.04]],"ltp":0.0,"tv":0.0,"id":17151080},{"batb":[[1,1.01,3.04]],"ltp":0.0,"tv":0.0,"id":17151079}]}]}
{"op":"mcm","clk":"999983261","pt":1580603725361,"mc":[{"id":"1.168224334","rc":[{"batb":[[1,1.01,1.01]],"ltp":0.0,"tv":0.0,"id":13117429},{"batb":[[1,1.01,1.01]],"ltp":0.0,"tv":0.0,"id":13117428},{"batb":[[1,1.01,1.01]],"ltp":0.0,"tv":0.0,"id":17151080},{"batb":[[1,1.01,1.01]],"ltp":0.0,"tv":0.0,"id":17151079}]}]}
{"op":"mcm","clk":"1000894045","pt":1580623394634,"mc":[{"id":"1.168224334","rc":[{"batb":[[0,2.36,30.29],[1,1.02,2],[2,1.01,1.01]],"ltp":0.0,"tv":0.0,"id":17151079}]}]}
{"op":"mcm","clk":"1001079465","pt":1580628020403,"mc":[{"id":"1.168224334","rc":[{"batb":[[0,1.02,2],[1,1.01,1.01],[2,1.01,0]],"ltp":0.0,"tv":0.0,"id":17151079}]}]}
{"op":"mcm","clk":"1001079473","pt":1580628020506,"mc":[{"id":"1.168224334","rc":[{"batb":[[0,2.22,30.29],[1,1.02,2],[2,1.01,1.01]],"ltp":0.0,"tv":0.0,"id":17151079}]}]}
{"op":"mcm","clk":"1001392896","pt":1580634959850,"mc":[{"id":"1.168224334","rc":[{"batb":[[0,1.02,2],[1,1.01,1.01],[2,1.01,0]],"ltp":0.0,"tv":0.0,"id":17151079}]}]}
{"op":"mcm","clk":"1001405682","pt":1580635220301,"mc":[{"id":"1.168224334","rc":[{"batb":[[0,5.6,20.14],[1,1.02,2],[2,1.01,1.01]],"batl":[[0,6.8,18.73]],"ltp":0.0,"tv":0.0,"id":13117429},{"batb":[[0,4.3,18.73],[1,1.02,2],[2,1.01,1.01]],"batl":[[0,5,17.86]],"ltp":0.0,"tv":0.0,"id":13117428},{"batb":[[0,4.3,18.8],[1,1.02,2],[2,1.01,1.01]],"batl":[[0,5,17.86]],"ltp":0.0,"tv":0.0,"id":17151080},{"batb":[[0,2.36,17.31],[1,1.02,2],[2,1.01,1.01]],"batl":[[0,2.56,16.92]],"ltp":0.0,"tv":0.0,"id":17151079}]}]}
{"op":"mcm","clk":"1001410030","pt":1580635314173,"mc":[{"id":"1.168224334","marketDefinition":{"bspMarket":false,"turnInPlayEnabled":true,"persistenceEnabled":true,"marketBaseRate":5.0,"eventId":"29681717","eventTypeId":"2","numberOfWinners":1,"bettingType":"ODDS","marketType":"SET_BETTING","marketTime":"2020-02-02T09:19:00.000Z","suspendTime":"2020-02-02T09:19:00.000Z","bspReconciled":false,"complete":true,"inPlay":false,"crossMatching":false,"runnersVoidable":false,"numberOfActiveRunners":4,"betDelay":0,"status":"OPEN","runners":[{"status":"ACTIVE","sortPriority":1,"id":13117428,"name":"Trungelliti 2-0"},{"status":"ACTIVE","sortPriority":2,"id":13117429,"name":"Trungelliti 2-1"},{"status":"ACTIVE","sortPriority":3,"id":17151079,"name":"Couacaud 2-0"},{"status":"ACTIVE","sortPriority":4,"id":17151080,"name":"Couacaud 2-1"}],"regulators":["MR_INT"],"countryCode":"FR","discountAllowed":true,"timezone":"UTC","openDate":"2020-02-02T09:30:00.000Z","version":3148342586,"name":"Set Betting","eventName":"Trungelliti v Couacaud"}}]}
{"op":"mcm","clk":"1001410228","pt":1580635317874,"mc":[{"id":"1.168224334","marketDefinition":{"bspMarket":false,"turnInPlayEnabled":true,"persistenceEnabled":true,"marketBaseRate":5.0,"eventId":"29681717","eventTypeId":"2","numberOfWinners":1,"bettingType":"ODDS","marketType":"SET_BETTING","marketTime":"2020-02-02T09:19:00.000Z","suspendTime":"2020-02-02T09:19:00.000Z","bspReconciled":false,"complete":true,"inPlay":false,"crossMatching":false,"runnersVoidable":false,"numberOfActiveRunners":4,"betDelay":0,"status":"OPEN","runners":[{"status":"ACTIVE","sortPriority":1,"id":13117428,"name":"Trungelliti 2-0"},{"status":"ACTIVE","sortPriority":2,"id":13117429,"name":"Trungelliti 2-1"},{"status":"ACTIVE","sortPriority":3,"id":17151079,"name":"Couacaud 2-0"},{"status":"ACTIVE","sortPriority":4,"id":17151080,"name":"Couacaud 2-1"}],"regulators":["MR_INT"],"countryCode":"FR","discountAllowed":true,"timezone":"UTC","openDate":"2020-02-02T09:19:00.000Z","version":3148342586,"name":"Set Betting","eventName":"Trungelliti v Couacaud"}}]}
{"op":"mcm","clk":"1001420874","pt":1580635535308,"mc":[{"id":"1.168224334","rc":[{"batb":[[0,1.02,2],[1,1.01,1.01],[2,1.01,0]],"ltp":0.0,"tv":0.0,"id":13117429},{"batb":[[0,1.02,2],[1,1.01,1.01],[2,1.01,0]],"ltp":0.0,"tv":0.0,"id":13117428},{"batb":[[0,1.02,2],[1,1.01,1.01],[2,1.01,0]],"ltp":0.0,"tv":0.0,"id":17151080},{"batb":[[0,1.02,2],[1,1.01,1.01],[2,1.01,0]],"ltp":0.0,"tv":0.0,"id":17151079}]}]}
{"op":"mcm","clk":"1001420967","pt":1580635537142,"mc":[{"id":"1.168224334","marketDefinition":{"bspMarket":false,"turnInPlayEnabled":true,"persistenceEnabled":true,"marketBaseRate":5.0,"eventId":"29681717","eventTypeId":"2","numberOfWinners":1,"bettingType":"ODDS","marketType":"SET_BETTING","marketTime":"2020-02-02T09:19:00.000Z","suspendTime":"2020-02-02T09:19:00.000Z","bspReconciled":false,"complete":true,"inPlay":true,"crossMatching":false,"runnersVoidable":false,"numberOfActiveRunners":4,"betDelay":3,"status":"OPEN","runners":[{"status":"ACTIVE","sortPriority":1,"id":13117428,"name":"Trungelliti 2-0"},{"status":"ACTIVE","sortPriority":2,"id":13117429,"name":"Trungelliti 2-1"},{"status":"ACTIVE","sortPriority":3,"id":17151079,"name":"Couacaud 2-0"},{"status":"ACTIVE","sortPriority":4,"id":17151080,"name":"Couacaud 2-1"}],"regulators":["MR_INT"],"countryCode":"FR","discountAllowed":true,"timezone":"UTC","openDate":"2020-02-02T09:19:00.000Z","version":3148343916,"name":"Set Betting","eventName":"Trungelliti v Couacaud"},"rc":[{"batb":[[0,1.01,0.51],[1,1.01,0]],"ltp":0.0,"tv":0.0,"id":13117429},{"batb":[[0,1.01,0.51],[1,1.01,0]],"ltp":0.0,"tv":0.0,"id":13117428},{"batb":[[0,1.01,0.51],[1,1.01,0]],"ltp":0.0,"tv":0.0,"id":17151080},{"batb":[[0,1.01,0.51],[1,1.01,0]],"ltp":0.0,"tv":0.0,"id":17151079}]}]}
{"op":"mcm","clk":"1001455502","pt":1580636224057,"mc":[{"id":"1.168224334","rc":[{"batb":[[0,5.5,10.39],[1,5.1,10.08],[2,1.01,0.51]],"batl":[[0,6.2,7.56],[1,6.8,18.8]],"ltp":0.0,"tv":0.0,"id":13117429},{"batb":[[0,3.9,14.28],[1,3.65,13.93],[2,1.01,0.51]],"batl":[[0,4.7,10.92],[1,5.3,15.42]],"ltp":0.0,"tv":0.0,"id":13117428},{"batb":[[0,4.2,12.6],[1,4.1,20.69],[2,1.01,0.51]],"batl":[[0,5.1,27.16]],"ltp":0.0,"tv":0.0,"id":17151080},{"batb":[[0,2.5,27.73],[1,2.28,19.43],[2,1.01,0.51]],"batl":[[0,2.88,21.85],[1,2.96,11.72]],"ltp":0.0,"tv":0.0,"id":17151079}]}]}
{"op":"mcm","clk":"1001455549","pt":1580636225142,"mc":[{"id":"1.168224334","rc":[{"batb":[[0,5.5,54.06],[1,5.4,54.25],[2,5.1,10.08]],"ltp":0.0,"tv":0.0,"id":13117429},{"batb":[[0,4.3,64.55],[1,4.2,95.7],[2,3.9,14.28]],"ltp":0.0,"tv":0.0,"id":13117428},{"batb":[[0,4.2,92.09],[1,4.1,121.65]],"ltp":0.0,"tv":0.0,"id":17151080},{"batb":[[0,2.62,103.24],[1,2.58,129.02],[2,2.5,27.73]],"ltp":0.0,"tv":0.0,"id":17151079}]}]}
{"op":"mcm","clk":"1001455812","pt":1580636231266,"mc":[{"id":"1.168224334","rc":[{"batb":[[0,5.5,10.39]],"ltp":0.0,"tv":0.0,"id":13117429},{"batb":[[0,3.9,14.28],[1,3.65,13.93],[2,1.01,0.51]],"ltp":0.0,"tv":0.0,"id":13117428},{"batb":[[0,4.2,12.6],[1,4.1,97.43]],"ltp":0.0,"tv":0.0,"id":17151080},{"batb":[[0,2.5,27.73],[1,2.28,19.43],[2,1.01,0.51]],"ltp":0.0,"tv":0.0,"id":17151079}]}]}
{"op":"mcm","clk":"1001455859","pt":1580636232251,"mc":[{"id":"1.168224334","rc":[{"batb":[[2,1.01,0.51]],"batl":[[0,6.8,18.8],[1,6.8,0]],"ltp":0.0,"tv":0.0,"id":13117429},{"batb":[[0,3.65,13.93],[1,1.01,0.51],[2,1.01,0]],"batl":[[0,5.3,15.42],[1,5.3,0]],"ltp":0.0,"tv":0.0,"id":13117428},{"batb":[[0,4.1,97.43],[1,1.01,0.51],[2,1.01,0]],"batl":[[0,5.1,17.07]],"ltp":0.0,"tv":0.0,"id":17151080},{"batb":[[0,2.28,19.43],[1,1.01,0.51],[2,1.01,0]],"batl":[[0,2.96,11.72],[1,2.96,0]],"ltp":0.0,"tv":0.0,"id":17151079}]}]}
{"op":"mcm","clk":"1001455959","pt":1580636234165,"mc":[{"id":"1.168224334","rc":[{"batb":[[2,5.3,56.38]],"ltp":0.0,"tv":0.0,"id":13117429},{"batb":[[0,3.75,61.96],[1,3.7,65.33],[2,3.65,13.93]],"ltp":0.0,"tv":0.0,"id":13117428},{"batb":[[1,4,107.01],[2,1.01,0.51]],"ltp":0.0,"tv":0.0,"id":17151080},{"batb":[[0,2.46,100.55],[1,2.42,153.3],[2,2.28,19.43]],"ltp":0.0,"tv":0.0,"id":17151079}]}]}
{"op":"mcm","clk":"1001456015","pt":1580636235259,"mc":[{"id":"1.168224334","rc":[{"batb":[[2,1.01,0.51]],"ltp":0.0,"tv":0.0,"id":13117429},{"batb":[[0,3.65,13.93],[1,1.01,0.51],[2,3.65,0]],"ltp":0.0,"tv":0.0,"id":13117428},{"batb":[[1,1.01,0.51],[2,1.01,0]],"ltp":0.0,"tv":0.0,"id":17151080}]}]}
{"op":"mcm","clk":"1001456138","pt":1580636238348,"mc":[{"id":"1.168224334","rc":[{"batb":[[0,5.5,79.03]],"ltp":0.0,"tv":0.0,"id":13117429},{"batb":[[0,4.7,71.19],[1,4.6,77.48],[2,3.65,13.93]],"ltp":0.0,"tv":0.0,"id":13117428},{"batb":[[0,4.2,141.29],[1,4.1,120.57],[2,1.01,0.51]],"ltp":0.0,"tv":0.0,"id":17151080}]}]}
{"op":"mcm","clk":"1001456179","pt":1580636239276,"mc":[{"id":"1.168224334","rc":[{"batb":[[0,5.6,10.31],[1,5.5,68.64],[2,5.4,54.25]],"batl":[[0,6.4,7.56],[1,6.8,18.49]],"ltp":0.0,"tv":0.0,"id":13117429},{"batb":[[1,4.6,93.61],[2,4.2,12.6]],"batl":[[0,5.1,10.08],[1,5.3,15.42],[2,5.9,12.51]],"ltp":0.0,"tv":0.0,"id":13117428},{"batb":[[0,4.4,17.94],[1,4.3,31.8],[2,4.2,141.29]],"batl":[[1,5.2,25.77]],"ltp":0.0,"tv":0.0,"id":17151080},{"trd":[[2.46,37.92]],"batb":[[0,2.46,81.59],[2,2.4,29.41]],"batl":[[0,2.7,14.95],[1,2.72,24.37]],"ltp":2.46,"tv":37.92,"id":17151079}],"tv":37.92}]}
{"op":"mcm","clk":"1001456591","pt":1580636248662,"mc":[{"id":"1.168224334","rc":[{"batb":[[1,5.4,54.25],[2,5.1,10.08]],"ltp":0.0,"tv":0.0,"id":13117429},{"batb":[[0,4.2,12.6],[1,4,21.95],[2,1.01,0.51]],"batl":[[1,5.9,12.51],[2,5.9,0]],"ltp":0.0,"tv":0.0,"id":13117428},{"batb":[[0,4.3,31.8],[1,4.2,62.9],[2,4.1,99.88]],"batl":[[0,5.2,25.77],[1,5.2,0]],"ltp":0.0,"tv":0.0,"id":17151080},{"batb":[[0,2.4,29.41],[1,2.16,22.42],[2,1.01,0.51]],"ltp":2.46,"tv":37.92,"id":17151079}]}]}
{"op":"mcm","clk":"1001456652","pt":1580636250365,"mc":[{"id":"1.168224334","rc":[{"batb":[[2,1.01,0.51]],"batl":[[0,6.8,18.49],[1,6.8,0]],"ltp":0.0,"tv":0.0,"id":13117429},{"batb":[[0,4,21.95],[1,1.01,0.51],[2,1.01,0]],"batl":[[0,5.9,12.51],[1,5.9,0]],"ltp":0.0,"tv":0.0,"id":13117428},{"batb":[[0,4.3,19.2]],"batl":[[0,5.2,16.52]],"ltp":0.0,"tv":0.0,"id":17151080},{"batb":[[0,2.16,22.42],[1,1.01,0.51],[2,1.01,0]],"batl":[[1,2.72,0]],"ltp":2.46,"tv":37.92,"id":17151079}]}]}
{"op":"mcm","clk":"1001456711","pt":1580636251800,"mc":[{"id":"1.168224334","rc":[{"batb":[[1,5.4,84.51],[2,5.3,55.97]],"ltp":0.0,"tv":0.0,"id":13117429},{"batb":[[0,4.1,149.81],[1,4,127.69],[2,1.01,0.51]],"batl":[[0,5.8,12.75]],"ltp":0.0,"tv":0.0,"id":13117428},{"batb":[[0,2.34,133.9],[1,2.3,176.2],[2,2.22,21.87]],"batl":[[0,2.72,14.56]],"ltp":2.46,"tv":37.92,"id":17151079}]}]}
{"op":"mcm","clk":"1001456741","pt":1580636252570,"mc":[{"id":"1.168224334","rc":[{"batb":[[1,5.4,54.25],[2,1.01,0.51]],"ltp":0.0,"tv":0.0,"id":13117429},{"batb":[[0,4,21.95],[1,1.01,0.51],[2,1.01,0]],"ltp":0.0,"tv":0.0,"id":13117428},{"batb":[[0,2.22,21.87],[1,1.01,0.51],[2,2.22,0]],"ltp":2.46,"tv":37.92,"id":17151079}]}]}
{"op":"mcm","clk":"1001456818","pt":1580636254470,"mc":[{"id":"1.168224334","marketDefinition":{"bspMarket":false,"turnInPlayEnabled":true,"persistenceEnabled":true,"marketBaseRate":5.0,"eventId":"29681717","eventTypeId":"2","numberOfWinners":1,"bettingType":"ODDS","marketType":"SET_BETTING","marketTime":"2020-02-02T09:19:00.000Z","suspendTime":"2020-02-02T09:19:00.000Z","bspReconciled":false,"complete":true,"inPlay":true,"crossMatching":true,"runnersVoidable":false,"numberOfActiveRunners":4,"betDelay":3,"status":"OPEN","runners":[{"status":"ACTIVE","sortPriority":1,"id":13117428,"name":"Trungelliti 2-0"},{"status":"ACTIVE","sortPriority":2,"id":13117429,"name":"Trungelliti 2-1"},{"status":"ACTIVE","sortPriority":3,"id":17151079,"name":"Couacaud 2-0"},{"status":"ACTIVE","sortPriority":4,"id":17151080,"name":"Couacaud 2-1"}],"regulators":["MR_INT"],"countryCode":"FR","discountAllowed":true,"timezone":"UTC","openDate":"2020-02-02T09:19:00.000Z","version":3148343916,"name":"Set Betting","eventName":"Trungelliti v Couacaud"}}]}
{"op":"mcm","clk":"1001456876","pt":1580636255965,"mc":[{"id":"1.168224334","rc":[{"batb":[[1,5.5,61.44],[2,5.4,54.25]],"ltp":0.0,"tv":0.0,"id":13117429},{"batb":[[0,4.6,59.84],[1,4.5,81.7],[2,4,21.95]],"ltp":0.0,"tv":0.0,"id":13117428},{"batb":[[1,4.2,126.47]],"ltp":0.0,"tv":0.0,"id":17151080},{"batb":[[0,2.5,100.5],[1,2.46,146.6],[2,2.22,21.87]],"ltp":2.46,"tv":37.92,"id":17151079}]}]}
{"op":"mcm","clk":"1001456907","pt":1580636256687,"mc":[{"id":"1.168224334","rc":[{"batb":[[1,5.4,54.25],[2,1.01,0.51]],"ltp":0.0,"tv":0.0,"id":13117429},{"batb":[[0,4,21.95],[1,1.01,0.51],[2,4,0]],"ltp":0.0,"tv":0.0,"id":13117428},{"batb":[[1,4.2,62.9]],"ltp":0.0,"tv":0.0,"id":17151080},{"batb":[[0,2.22,21.87],[1,1.01,0.51],[2,2.22,0]],"ltp":2.46,"tv":37.92,"id":17151079}]}]}
{"op":"mcm","clk":"1001457017","pt":1580636259581,"mc":[{"id":"1.168224334","rc":[{"batb":[[1,5.4,84.51],[2,5.3,55.97]],"ltp":0.0,"tv":0.0,"id":13117429},{"batb":[[0,4.1,149.81],[1,4,127.69],[2,1.01,0.51]],"ltp":0.0,"tv":0.0,"id":13117428},{"batb":[[0,2.34,133.9],[1,2.3,176.2],[2,2.22,21.87]],"ltp":2.46,"tv":37.92,"id":17151079}]}]}
{"op":"mcm","clk":"1001457204","pt":1580636263405,"mc":[{"id":"1.168224334","rc":[{"batb":[[1,1.01,0.51],[2,5.3,0]],"ltp":0.0,"tv":0.0,"id":13117429},{"batb":[[0,4,21.95],[1,1.01,0.51],[2,1.01,0]],"ltp":0.0,"tv":0.0,"id":13117428},{"batb":[[2,1.01,0.51]],"ltp":0.0,"tv":0.0,"id":17151080}]}]}
{"op":"mcm","clk":"1001457345","pt":1580636265985,"mc":[{"id":"1.168224334","rc":[{"batb":[[0,5.6,49.98],[1,5.5,52.14],[2,1.01,0.51]],"ltp":0.0,"tv":0.0,"id":13117429},{"batb":[[0,5.1,52.05],[1,5,64.38],[2,4,21.95]],"ltp":0.0,"tv":0.0,"id":13117428},{"batb":[[0,4.3,110.26],[1,4.2,95.26]],"ltp":0.0,"tv":0.0,"id":17151080}]}]}
{"op":"mcm","clk":"1001457406","pt":1580636267322,"mc":[{"id":"1.168224334","rc":[{"batb":[[2,5.2,9.24]],"batl":[[0,6.4,7.56],[1,6.8,18.25]],"ltp":0.0,"tv":0.0,"id":13117429},{"batb":[[1,5,77.68],[2,4.6,16.44]],"batl":[[0,5.5,9.24],[1,5.8,12.75],[2,6.2,11.17]],"ltp":0.0,"tv":0.0,"id":13117428},{"batb":[[0,4.4,18.1],[1,4.3,103.66],[2,4.2,95.26]],"batl":[[0,5.1,16.37],[1,5.2,9.24]],"ltp":0.0,"tv":0.0,"id":17151080},{"trd":[[2.34,42.64]],"batb":[[0,2.34,112.58],[2,2.28,32.77]],"batl":[[0,2.48,18.33],[1,2.58,26.05]],"ltp":2.34,"tv":80.56,"id":17151079}],"tv":80.56}]}
{"op":"mcm","clk":"1001457835","pt":1580636276346,"mc":[{"id":"1.168224334","rc":[{"batb":[[0,5.6,10.31],[2,1.01,0.51]],"batl":[[0,6.8,18.25],[1,6.8,0]],"ltp":0.0,"tv":0.0,"id":13117429},{"batb":[[0,4.6,16.44],[1,1.01,0.51],[2,4.6,0]],"batl":[[0,6.2,11.17],[1,5.8,0],[2,6.2,0]],"ltp":0.0,"tv":0.0,"id":13117428},{"batb":[[1,4.3,54.53]],"batl":[[1,5.2,0]],"ltp":0.0,"tv":0.0,"id":17151080},{"batb":[[0,2.14,24],[1,1.01,0.51],[2,2.28,0]],"batl":[[1,2.58,0]],"ltp":2.34,"tv":80.56,"id":17151079}]}]}
{"op":"mcm","clk":"1001457978","pt":1580636279336,"mc":[{"id":"1.168224334","rc":[{"batb":[[2,5.4,54.06]],"ltp":0.0,"tv":0.0,"id":13117429},{"batb":[[0,4.7,77.25],[1,4.6,77.42],[2,4.5,16.84]],"batl":[[0,6,11.49]],"ltp":0.0,"tv":0.0,"id":13117428},{"batb":[[0,2.28,136.58],[1,2.26,93.37],[2,2.18,23.29]],"batl":[[0,2.52,17.78]],"ltp":2.34,"tv":80.56,"id":17151079}]}]}
{"op":"mcm","clk":"1001458736","pt":1580636298637,"mc":[{"id":"1.168224334","rc":[{"batb":[[2,1.01,0.51]],"ltp":0.0,"tv":0.0,"id":13117429},{"batb":[[0,4.5,16.84],[1,1.01,0.51],[2,4.5,0]],"ltp":0.0,"tv":0.0,"id":13117428}]}]}
{"op":"mcm","clk":"1001458885","pt":1580636302243,"mc":[{"id":"1.168224334","rc":[{"batb":[[0,5.6,70.8]],"ltp":0.0,"tv":0.0,"id":13117429},{"batb":[[0,5.3,86.01],[1,5.2,58.61],[2,4.7,15.11]],"batl":[[1,7.2,15.89]],"ltp":0.0,"tv":0.0,"id":13117428},{"batb":[[0,4.5,17.31],[1,4.4,18.1],[2,4.3,114.12]],"batl":[[1,5.2,15.42]],"ltp":0.0,"tv":0.0,"id":17151080},{"batl":[[0,2.3,22.66],[1,2.44,19.28],[2,2.52,17.78]],"ltp":2.34,"tv":80.56,"id":17151079}]}]}
{"op":"mcm","clk":"1001458934","pt":1580636303272,"mc":[{"id":"1.168224334","rc":[{"batb":[[2,5.4,9.24]],"batl":[[0,6.6,6.72],[1,6.8,18.25]],"ltp":0.0,"tv":0.0,"id":13117429},{"batb":[[2,4.8,10.92]],"batl":[[0,5.9,8.4],[1,6,11.49],[2,7.2,15.89]],"ltp":0.0,"tv":0.0,"id":13117428},{"batb":[[2,4.3,126.72]],"batl":[[0,5.1,26.45]],"ltp":0.0,"tv":0.0,"id":17151080},{"batb":[[2,2.18,58.58]],"batl":[[2,2.46,28.57]],"ltp":2.34,"tv":80.56,"id":17151079}]}]}
{"op":"mcm","clk":"1001459473","pt":1580636315567,"mc":[{"id":"1.168224334","rc":[{"trd":[[2.3,45.32]],"batb":[[0,2.3,11.34],[1,2.28,136.58],[2,2.26,93.37]],"batl":[[0,2.44,19.28],[1,2.46,28.57],[2,2.46,0]],"ltp":2.3,"tv":125.88,"id":17151079}],"tv":125.88}]}
{"op":"mcm","clk":"1001460484","pt":1580636339123,"mc":[{"id":"1.168224334","rc":[{"batb":[[0,5.6,10.31]],"ltp":0.0,"tv":0.0,"id":13117429},{"batb":[[0,5.3,11.96],[1,4.8,10.92],[2,4.7,15.11]],"ltp":0.0,"tv":0.0,"id":13117428},{"batb":[[2,4.3,67.13]],"ltp":0.0,"tv":0.0,"id":17151080},{"batb":[[1,2.18,58.58],[2,2.02,28.88]],"ltp":2.3,"tv":125.88,"id":17151079}]}]}
{"op":"mcm","clk":"1001460627","pt":1580636342327,"mc":[{"id":"1.168224334","rc":[{"batb":[[1,5.5,80.95],[2,5.4,62.97]],"ltp":0.0,"tv":0.0,"id":13117429},{"batb":[[1,4.9,51.18],[2,4.8,81.57]],"ltp":0.0,"tv":0.0,"id":13117428},{"batb":[[2,2.12,130.26]],"ltp":2.3,"tv":125.88,"id":17151079}]}]}
{"op":"mcm","clk":"1001460641","pt":1580636342692,"mc":[{"id":"1.168224334","rc":[{"batb":[[0,4.9,51.18],[1,4.8,81.57],[2,4.7,15.11]],"batl":[[1,7.2,15.89],[2,7.2,0]],"ltp":0.0,"tv":0.0,"id":13117428},{"batb":[[0,4.4,18.1],[1,4.3,67.13],[2,4.2,95.26]],"batl":[[0,5.1,10.08]],"ltp":0.0,"tv":0.0,"id":17151080},{"batb":[[1,2.18,35.29]],"ltp":2.3,"tv":125.88,"id":17151079}]}]}
{"op":"mcm","clk":"1001460712","pt":1580636344390,"mc":[{"id":"1.168224334","rc":[{"batb":[[2,5.4,53.73]],"batl":[[0,6.8,18.25],[1,6.8,0]],"ltp":0.0,"tv":0.0,"id":13117429},{"batb":[[1,4.8,70.65]],"batl":[[0,7.2,15.89],[1,7.2,0]],"ltp":0.0,"tv":0.0,"id":13117428},{"batb":[[1,4.3,54.53]],"batl":[[0,5.2,15.42],[1,5.2,0]],"ltp":0.0,"tv":0.0,"id":17151080},{"batb":[[1,2.12,130.26],[2,2.1,115.43]],"batl":[[1,2.46,0]],"ltp":2.3,"tv":125.88,"id":17151079}]}]}
{"op":"mcm","clk":"1001460789","pt":1580636346201,"mc":[{"id":"1.168224334","rc":[{"batb":[[1,5.5,52.14],[2,1.01,0.51]],"batl":[[0,6.6,18.65]],"ltp":0.0,"tv":0.0,"id":13117429},{"batb":[[0,4.7,15.11],[1,1.01,0.51],[2,4.7,0]],"ltp":0.0,"tv":0.0,"id":13117428},{"batb":[[1,2.04,28.09],[2,1.01,0.51]],"batl":[[0,2.46,18.73]],"ltp":2.3,"tv":125.88,"id":17151079}]}]}
{"op":"mcm","clk":"1001460920","pt":1580636349190,"mc":[{"id":"1.168224334","rc":[{"batb":[[0,5.6,80.68]],"ltp":0.0,"tv":0.0,"id":13117429},{"batb":[[0,5.5,45.6],[1,5.4,54.25],[2,4.7,15.11]],"ltp":0.0,"tv":0.0,"id":13117428},{"batb":[[1,4.3,132.67]],"ltp":0.0,"tv":0.0,"id":17151080},{"batb":[[1,2.24,165.03],[2,2.22,98.18]],"ltp":2.3,"tv":125.88,"id":17151079}]}]}
{"op":"mcm","clk":"1001461129","pt":1580636352293,"mc":[{"id":"1.168224334","rc":[{"batb":[[0,5.6,10.31]],"ltp":0.0,"tv":0.0,"id":13117429},{"batb":[[0,4.7,15.11],[1,1.01,0.51],[2,4.7,0]],"ltp":0.0,"tv":0.0,"id":13117428},{"batb":[[1,4.3,54.53]],"ltp":0.0,"tv":0.0,"id":17151080},{"batb":[[1,2.04,28.09],[2,1.01,0.51]],"ltp":2.3,"tv":125.88,"id":17151079}]}]}
{"op":"mcm","clk":"1001461228","pt":1580636354404,"mc":[{"id":"1.168224334","rc":[{"batb":[[1,5.5,80.95],[2,5.4,53.73]],"ltp":0.0,"tv":0.0,"id":13117429},{"batb":[[0,4.9,51.18],[1,4.8,70.65],[2,4.7,15.11]],"ltp":0.0,"tv":0.0,"id":13117428},{"batb":[[1,2.12,130.26],[2,2.1,115.43]],"ltp":2.3,"tv":125.88,"id":17151079}]}]}
{"op":"mcm","clk":"1001461253","pt":1580636354915,"mc":[{"id":"1.168224334","rc":[{"batb":[[0,2.12,130.26],[1,2.1,115.43],[2,2.04,28.09]],"ltp":2.3,"tv":125.88,"id":17151079}]}]}
{"op":"mcm","clk":"1001461409","pt":1580636358018,"mc":[{"id":"1.168224334","rc":[{"batb":[[0,2.44,11.34],[1,2.12,130.26],[2,2.1,115.43]],"ltp":2.3,"tv":125.88,"id":17151079}]}]}
{"op":"mcm","clk":"1001461640","pt":1580636363222,"mc":[{"id":"1.168224334","rc":[{"batb":[[1,2.04,28.09],[2,1.01,0.51]],"ltp":2.3,"tv":125.88,"id":17151079}]}]}
{"op":"mcm","clk":"1001461747","pt":1580636366119,"mc":[{"id":"1.168224334","rc":[{"batb":[[1,2.4,135.41],[2,2.36,164]],"ltp":2.3,"tv":125.88,"id":17151079}]}]}
{"op":"mcm","clk":"1001461801","pt":1580636367353,"mc":[{"id":"1.168224334","rc":[{"batb":[[0,5.5,91.73],[1,5.4,53.73],[2,5.3,9.24]],"batl":[[0,6.6,25.37]],"ltp":0.0,"tv":0.0,"id":13117429},{"batl":[[0,5.3,14.79],[1,5.5,9.24],[2,6.2,10.94]],"ltp":0.0,"tv":0.0,"id":13117428},{"batb":[[1,4.3,73.73],[2,4.2,107.86]],"batl":[[0,4.9,17.55],[1,5,16.68],[2,5.1,10.08]],"ltp":0.0,"tv":0.0,"id":17151080},{"batl":[[1,2.58,26.05],[2,2.6,16.21]],"ltp":2.3,"tv":125.88,"id":17151079}]}]}
{"op":"mcm","clk":"1001461866","pt":1580636369059,"mc":[{"id":"1.168224334","rc":[{"batb":[[0,2.4,135.41],[1,2.36,164],[2,2.34,19.2]],"ltp":2.3,"tv":125.88,"id":17151079}]}]}
{"op":"mcm","clk":"1001461998","pt":1580636372154,"mc":[{"id":"1.168224334","rc":[{"trd":[[2.46,60.6]],"batl":[[0,2.46,7.39]],"ltp":2.46,"tv":148.56,"id":17151079}],"tv":148.56}]}
{"op":"mcm","clk":"1001462392","pt":1580636383159,"mc":[{"id":"1.168224334","rc":[{"batb":[[0,5.5,62.92]],"ltp":0.0,"tv":0.0,"id":13117429},{"batb":[[0,4.5,11.76],[1,4.4,18.25],[2,1.01,0.51]],"batl":[[0,5.5,9.24],[1,6.2,10.94],[2,6.2,0]],"ltp":0.0,"tv":0.0,"id":13117428},{"batb":[[0,4.3,19.2],[1,4.2,107.86],[2,1.01,0.51]],"batl":[[0,5,16.68],[1,5.1,10.08],[2,5.1,0]],"ltp":0.0,"tv":0.0,"id":17151080},{"batb":[[0,2.3,31.93],[1,2.16,23.6],[2,1.01,0.51]],"batl":[[0,2.58,26.05],[1,2.6,16.21],[2,2.6,0]],"ltp":2.46,"tv":148.56,"id":17151079}]}]}
{"op":"mcm","clk":"1001462520","pt":1580636384562,"mc":[{"id":"1.168224334","rc":[{"batb":[[2,1.01,0.51]],"batl":[[0,6.6,18.65]],"ltp":0.0,"tv":0.0,"id":13117429},{"batb":[[0,4.4,18.25],[1,1.01,0.51],[2,1.01,0]],"batl":[[0,6.2,10.94],[1,6.2,0]],"ltp":0.0,"tv":0.0,"id":13117428},{"batb":[[1,4.2,95.26]],"batl":[[1,5.1,0]],"ltp":0.0,"tv":0.0,"id":17151080},{"batb":[[0,2.16,23.6],[1,1.01,0.51],[2,1.01,0]],"batl":[[0,2.6,16.21],[1,2.6,0]],"ltp":2.46,"tv":148.56,"id":17151079}]}]}
{"op":"mcm","clk":"1001462601","pt":1580636386372,"mc":[{"id":"1.168224334","rc":[{"batb":[[0,4.5,120.99],[1,4.4,103.27],[2,1.01,0.51]],"ltp":0.0,"tv":0.0,"id":13117428},{"batb":[[2,4.1,100.6]],"ltp":0.0,"tv":0.0,"id":17151080},{"batb":[[0,2.24,168.08],[1,2.22,98.17],[2,2.16,23.6]],"ltp":2.46,"tv":148.56,"id":17151079}]}]}
{"op":"mcm","clk":"1001462620","pt":1580636386982,"mc":[{"id":"1.168224334","rc":[{"batb":[[1,1.01,0.51],[2,1.01,0]],"ltp":0.0,"tv":0.0,"id":13117429},{"batb":[[0,4.4,18.25],[1,1.01,0.51],[2,1.01,0]],"batl":[[0,6,11.25]],"ltp":0.0,"tv":0.0,"id":13117428},{"batb":[[2,1.01,0.51]],"batl":[[0,5.1,16.44]],"ltp":0.0,"tv":0.0,"id":17151080},{"batb":[[0,2.18,23.21],[1,1.01,0.51],[2,2.16,0]],"batl":[[0,2.62,16.13]],"ltp":2.46,"tv":148.56,"id":17151079}]}]}
{"op":"mcm","clk":"1001462741","pt":1580636390241,"mc":[{"id":"1.168224334","rc":[{"batb":[[0,5.6,37.06],[1,5.5,62.92],[2,1.01,0.51]],"ltp":0.0,"tv":0.0,"id":13117429},{"batb":[[0,5,56.06],[1,4.9,67.34],[2,4.4,18.25]],"ltp":0.0,"tv":0.0,"id":13117428},{"batb":[[0,4.3,87.41]],"ltp":0.0,"tv":0.0,"id":17151080},{"batb":[[0,2.36,168.02],[1,2.32,171.79],[2,2.18,23.21]],"ltp":2.46,"tv":148.56,"id":17151079}]}]}
{"op":"mcm","clk":"1001462866","pt":1580636394152,"mc":[{"id":"1.168224334","rc":[{"batb":[[0,5.5,62.92],[1,1.01,0.51],[2,1.01,0]],"ltp":0.0,"tv":0.0,"id":13117429},{"batb":[[0,4.4,18.25],[1,1.01,0.51],[2,4.4,0]],"ltp":0.0,"tv":0.0,"id":13117428},{"batb":[[0,4.3,19.2]],"ltp":0.0,"tv":0.0,"id":17151080},{"batb":[[0,2.18,23.21],[1,1.01,0.51],[2,2.18,0]],"ltp":2.46,"tv":148.56,"id":17151079}]}]}
{"op":"mcm","clk":"1001462973","pt":1580636397191,"mc":[{"id":"1.168224334","rc":[{"batb":[[1,5.4,54.15],[2,1.01,0.51]],"ltp":0.0,"tv":0.0,"id":13117429},{"batb":[[0,4.5,120.99],[1,4.4,103.27],[2,1.01,0.51]],"ltp":0.0,"tv":0.0,"id":13117428},{"batb":[[2,4.1,100.6]],"ltp":0.0,"tv":0.0,"id":17151080},{"batb":[[0,2.24,168.08],[1,2.22,98.17],[2,2.18,23.21]],"ltp":2.46,"tv":148.56,"id":17151079}]}]}
{"op":"mcm","clk":"1001463000","pt":1580636397870,"mc":[{"id":"1.168224334","rc":[{"batb":[[1,1.01,0.51],[2,1.01,0]],"ltp":0.0,"tv":0.0,"id":13117429},{"batb":[[0,4.4,18.25],[1,1.01,0.51],[2,1.01,0]],"ltp":0.0,"tv":0.0,"id":13117428},{"batb":[[2,1.01,0.51]],"ltp":0.0,"tv":0.0,"id":17151080}]}]}
{"op":"mcm","clk":"1001463147","pt":1580636401376,"mc":[{"id":"1.168224334","rc":[{"batb":[[0,5.6,83.55],[1,5.5,62.76],[2,5.4,9.24]],"batl":[[0,6.6,25.21]],"ltp":0.0,"tv":0.0,"id":13117429},{"batb":[[0,5.5,45.41],[1,5.4,54.25],[2,5.3,11.72]],"batl":[[0,6,19.65],[1,7.6,14.48]],"ltp":0.0,"tv":0.0,"id":13117428},{"batb":[[0,4.5,17.23],[1,4.4,18.41],[2,4.3,140.35]],"batl":[[0,5.1,26.53],[1,5.2,15.42]],"ltp":0.0,"tv":0.0,"id":17151080},{"batl":[[0,2.3,22.66],[1,2.44,28.57],[2,2.46,18.88]],"ltp":2.46,"tv":148.56,"id":17151079}]}]}
{"op":"mcm","clk":"1001463631","pt":1580636413286,"mc":[{"id":"1.168224334","rc":[{"batb":[[0,5.6,48.02]],"ltp":0.0,"tv":0.0,"id":13117429},{"batb":[[0,5.3,11.72],[1,5,10.08],[2,4.8,15.11]],"ltp":0.0,"tv":0.0,"id":13117428},{"batb":[[2,4.3,65.79]],"ltp":0.0,"tv":0.0,"id":17151080},{"batb":[[0,2.18,23.21],[1,2.16,36.13],[2,2,29.9]],"ltp":2.46,"tv":148.56,"id":17151079}]}]}
{"op":"mcm","clk":"1001463678","pt":1580636414115,"mc":[{"id":"1.168224334","rc":[{"batb":[[0,5.6,37.56]],"ltp":0.0,"tv":0.0,"id":13117429},{"batb":[[0,5,10.08],[1,4.8,15.11],[2,1.01,0.51]],"batl":[[0,6,8.4]],"ltp":0.0,"tv":0.0,"id":13117428},{"batb":[[0,4.4,18.41],[1,4.3,65.79],[2,4.2,95.26]],"batl":[[0,5.1,10.08]],"ltp":0.0,"tv":0.0,"id":17151080},{"batb":[[0,2.16,36.13],[1,2,29.9],[2,1.01,0.51]],"batl":[[0,2.44,28.57],[1,2.46,18.88],[2,2.46,0]],"ltp":2.46,"tv":148.56,"id":17151079}]}]}
{"op":"mcm","clk":"1001463704","pt":1580636414521,"mc":[{"id":"1.168224334","rc":[{"batb":[[2,1.01,0.51]],"batl":[[0,6.6,18.49]],"ltp":0.0,"tv":0.0,"id":13117429},{"batb":[[0,4.8,15.11],[1,1.01,0.51],[2,1.01,0]],"batl":[[0,7.6,14.48],[1,7.6,0]],"ltp":0.0,"tv":0.0,"id":13117428},{"batb":[[1,4.3,53.19]],"batl":[[0,5.2,15.42],[1,5.2,0]],"ltp":0.0,"tv":0.0,"id":17151080},{"batb":[[0,2,29.9],[1,1.01,0.51],[2,1.01,0]],"batl":[[0,2.46,18.88],[1,2.46,0]],"ltp":2.46,"tv":148.56,"id":17151079}]}]}
{"op":"mcm","clk":"1001463788","pt":1580636416275,"mc":[{"id":"1.168224334","rc":[{"batb":[[0,4.9,81.99],[1,4.8,85.27],[2,1.01,0.51]],"ltp":0.0,"tv":0.0,"id":13117428},{"batb":[[0,2.06,160.7],[1,2.04,125.78],[2,2,29.9]],"ltp":2.46,"tv":148.56,"id":17151079}]}]}
{"op":"mcm","clk":"1001463837","pt":1580636417324,"mc":[{"id":"1.168224334","rc":[{"batb":[[0,4.8,15.11],[1,1.01,0.51],[2,1.01,0]],"ltp":0.0,"tv":0.0,"id":13117428},{"batb":[[2,1.01,0.51]],"ltp":0.0,"tv":0.0,"id":17151080},{"batb":[[0,2,29.9],[1,1.01,0.51],[2,2,0]],"ltp":2.46,"tv":148.56,"id":17151079}]}]}
{"op":"mcm","clk":"1001463963","pt":1580636420486,"mc":[{"id":"1.168224334","rc":[{"batb":[[0,5.6,83.84]],"ltp":0.0,"tv":0.0,"id":13117429},{"batb":[[0,5.7,40.6],[1,5.6,50.09],[2,4.8,15.11]],"ltp":0.0,"tv":0.0,"id":13117428},{"batb":[[0,4.4,76.6],[1,4.3,90.76]],"ltp":0.0,"tv":0.0,"id":17151080},{"batb":[[0,2.2,174.4],[1,2.18,103.43],[2,2,29.9]],"ltp":2.46,"tv":148.56,"id":17151079}]}]}
{"op":"mcm","clk":"1001464058","pt":1580636422501,"mc":[{"id":"1.168224334","rc":[{"batb":[[0,5.6,37.56]],"ltp":0.0,"tv":0.0,"id":13117429},{"batb":[[0,4.8,15.11],[1,1.01,0.51],[2,4.8,0]],"ltp":0.0,"tv":0.0,"id":13117428},{"batb":[[0,4.4,18.41],[1,4.3,53.91]],"ltp":0.0,"tv":0.0,"id":17151080},{"batb":[[0,2,29.9],[1,1.01,0.51],[2,2,0]],"ltp":2.46,"tv":148.56,"id":17151079}]}]}
{"op":"mcm","clk":"1001464206","pt":1580636425504,"mc":[{"id":"1.168224334","rc":[{"batb":[[0,4.9,80.94],[1,4.8,85.27],[2,1.01,0.51]],"ltp":0.0,"tv":0.0,"id":13117428},{"batb":[[2,4.2,95.93]],"ltp":0.0,"tv":0.0,"id":17151080},{"batb":[[0,2.06,162.61],[1,2.04,125.78],[2,2,29.9]],"ltp":2.46,"tv":148.56,"id":17151079}]}]}
{"op":"mcm","clk":"1001464629","pt":1580636433819,"mc":[{"id":"1.168224334","rc":[{"batb":[[0,2,29.9],[1,1.01,0.51],[2,2,0]],"ltp":2.46,"tv":148.56,"id":17151079}]}]}
{"op":"mcm","clk":"1001464756","pt":1580636437313,"mc":[{"id":"1.168224334","rc":[{"batb":[[2,5.4,9.24]],"batl":[[0,6.6,25.21]],"ltp":0.0,"tv":0.0,"id":13117429},{"batb":[[2,4.6,10.92]],"batl":[[0,5.4,14.48],[1,5.6,8.4],[2,6.2,10.54]],"ltp":0.0,"tv":0.0,"id":13117428},{"batb":[[1,4.3,73.03],[2,4.2,108.53]],"batl":[[0,4.9,17.55],[1,5.1,26.53]],"ltp":0.0,"tv":0.0,"id":17151080},{"batb":[[0,2.38,163.73],[1,2.34,167.76],[2,2.32,19.36]],"batl":[[1,2.56,26.89],[2,2.62,16.05]],"ltp":2.46,"tv":148.56,"id":17151079}]}]}
{"op":"mcm","clk":"1001465568","pt":1580636456233,"mc":[{"id":"1.168224334","rc":[{"batb":[[0,5.5,62.76],[1,5.4,9.24],[2,1.01,0.51]],"ltp":0.0,"tv":0.0,"id":13117429},{"batb":[[0,4.6,10.92],[1,4.4,18.49],[2,1.01,0.51]],"batl":[[0,5.6,8.4],[1,6.2,10.54],[2,6.2,0]],"ltp":0.0,"tv":0.0,"id":13117428},{"batb":[[0,4.3,19.12],[1,4.2,108.53],[2,1.01,0.51]],"batl":[[0,5.1,26.53],[1,5.1,0]],"ltp":0.0,"tv":0.0,"id":17151080},{"batb":[[0,2.26,32.77],[1,2.14,24.16],[2,1.01,0.51]],"batl":[[0,2.56,26.89],[1,2.62,16.05],[2,2.62,0]],"ltp":2.46,"tv":148.56,"id":17151079}]}]}
{"op":"mcm","clk":"1001465585","pt":1580636456545,"mc":[{"id":"1.168224334","rc":[{"batb":[[1,1.01,0.51],[2,1.01,0]],"batl":[[0,6.6,18.49]],"ltp":0.0,"tv":0.0,"id":13117429},{"batb":[[0,4.4,18.49],[1,1.01,0.51],[2,1.01,0]],"batl":[[0,6.2,10.54],[1,6.2,0]],"ltp":0.0,"tv":0.0,"id":13117428},{"batb":[[1,4.2,95.93]],"batl":[[0,5.1,16.44]],"ltp":0.0,"tv":0.0,"id":17151080},{"batb":[[0,2.14,24.16],[1,1.01,0.51],[2,1.01,0]],"batl":[[0,2.62,16.05],[1,2.62,0]],"ltp":2.46,"tv":148.56,"id":17151079}]}]}
{"op":"mcm","clk":"1001465678","pt":1580636459268,"mc":[{"id":"1.168224334","rc":[{"batb":[[1,5.4,54.05],[2,1.01,0.51]],"ltp":0.0,"tv":0.0,"id":13117429},{"batb":[[0,4.5,112.54],[1,4.4,103.64],[2,1.01,0.51]],"ltp":0.0,"tv":0.0,"id":13117428},{"batb":[[2,4.1,100.77]],"ltp":0.0,"tv":0.0,"id":17151080},{"batb":[[0,2.22,107.15],[1,2.2,100.88],[2,2.14,24.16]],"ltp":2.46,"tv":148.56,"id":17151079}]}]}
{"op":"mcm","clk":"1001465723","pt":1580636460144,"mc":[{"id":"1.168224334","rc":[{"batb":[[1,1.01,0.51],[2,1.01,0]],"ltp":0.0,"tv":0.0,"id":13117429},{"batb":[[0,4.4,18.49],[1,1.01,0.51],[2,1.01,0]],"ltp":0.0,"tv":0.0,"id":13117428},{"batb":[[1,1.01,0.51],[2,4.1,0]],"ltp":0.0,"tv":0.0,"id":17151080}]}]}
{"op":"mcm","clk":"1001465879","pt":1580636463184,"mc":[{"id":"1.168224334","rc":[{"batb":[[0,5.6,84.61],[1,5.5,62.76],[2,1.01,0.51]],"ltp":0.0,"tv":0.0,"id":13117429},{"batb":[[0,5.6,74.94],[1,5.5,51.63],[2,4.4,18.49]],"ltp":0.0,"tv":0.0,"id":13117428},{"batb":[[0,4.4,50.39],[1,4.3,110.03],[2,1.01,0.51]],"ltp":0.0,"tv":0.0,"id":17151080}]}]}
{"op":"mcm","clk":"1001465919","pt":1580636464168,"mc":[{"id":"1.168224334","rc":[{"batb":[[0,5.6,95.07],[1,5.5,61.38]],"batl":[[0,6.8,25.21]],"ltp":0.0,"tv":0.0,"id":13117429},{"batb":[[1,5.5,62.57],[2,5.1,10.08]],"batl":[[1,6.4,7.56],[2,8.2,11.88]],"ltp":0.0,"tv":0.0,"id":13117428},{"batb":[[0,4.5,17.23],[1,4.4,68.8],[2,4.3,103.51]],"batl":[[0,5.1,26.53],[1,5.3,14.79]],"ltp":0.0,"tv":0.0,"id":17151080},{"batb":[[2,2.14,60.28]],"batl":[[0,2.26,23.53],[1,2.4,29.41],[2,2.46,18.96]],"ltp":2.46,"tv":148.56,"id":17151079}]}]}
{"op":"mcm","clk":"1001466518","pt":1580636477263,"mc":[{"id":"1.168224334","rc":[{"batb":[[0,5.6,54.31]],"ltp":0.0,"tv":0.0,"id":13117429},{"batb":[[0,5.1,10.08],[1,4.7,15.26],[2,1.01,0.51]],"batl":[[0,6.4,7.56],[1,8.2,11.88],[2,8.2,0]],"ltp":0.0,"tv":0.0,"id":13117428},{"batb":[[0,4.4,18.41],[1,4.3,12.6],[2,1.01,0.51]],"batl":[[0,5.1,10.08]],"ltp":0.0,"tv":0.0,"id":17151080},{"batb":[[0,2.14,36.13],[1,1.94,16.44],[2,1.01,0.51]],"batl":[[0,2.4,29.41],[1,2.46,18.96],[2,2.46,0]],"ltp":2.46,"tv":148.56,"id":17151079}]}]}
{"op":"mcm","clk":"1001466631","pt":1580636479378,"mc":[{"id":"1.168224334","rc":[{"batb":[[1,5.5,52.14]],"batl":[[0,6.8,18.49]],"ltp":0.0,"tv":0.0,"id":13117429},{"batb":[[0,4.7,15.26],[1,1.01,0.51],[2,1.01,0]],"batl":[[0,8.2,11.88],[1,8.2,0]],"ltp":0.0,"tv":0.0,"id":13117428},{"batb":[[1,1.01,0.51],[2,1.01,0]],"batl":[[0,5.3,14.79],[1,5.3,0]],"ltp":0.0,"tv":0.0,"id":17151080},{"batb":[[0,1.94,16.44],[1,1.01,0.51],[2,1.01,0]],"batl":[[0,2.46,18.96],[1,2.46,0]],"ltp":2.46,"tv":148.56,"id":17151079}]}]}
{"op":"mcm","clk":"1001466672","pt":1580636480303,"mc":[{"id":"1.168224334","rc":[{"batb":[[1,1.01,0.51],[2,1.01,0]],"ltp":0.0,"tv":0.0,"id":13117429}]}]}
{"op":"mcm","clk":"1001466800","pt":1580636484060,"mc":[{"id":"1.168224334","rc":[{"batb":[[0,5.7,46.02],[1,5.6,54.31],[2,1.01,0.51]],"ltp":0.0,"tv":0.0,"id":13117429},{"batb":[[0,5.9,56.32],[1,5.8,46.1],[2,4.7,15.26]],"ltp":0.0,"tv":0.0,"id":13117428},{"batb":[[0,4.4,98.76],[1,4.3,90.4],[2,1.01,0.51]],"ltp":0.0,"tv":0.0,"id":17151080},{"batb":[[0,2.16,164.68],[1,2.14,109.17],[2,1.94,16.44]],"ltp":2.46,"tv":148.56,"id":17151079}]}]}
{"op":"mcm","clk":"1001466900","pt":1580636485976,"mc":[{"id":"1.168224334","rc":[{"batb":[[0,5.6,54.31],[1,1.01,0.51],[2,1.01,0]],"ltp":0.0,"tv":0.0,"id":13117429},{"batb":[[0,4.7,15.26],[1,1.01,0.51],[2,4.7,0]],"ltp":0.0,"tv":0.0,"id":13117428},{"batb":[[0,4.4,18.41],[1,1.01,0.51],[2,1.01,0]],"ltp":0.0,"tv":0.0,"id":17151080},{"batb":[[0,1.94,16.44],[1,1.01,0.51],[2,1.94,0]],"ltp":2.46,"tv":148.56,"id":17151079}]}]}
{"op":"mcm","clk":"1001467069","pt":1580636488961,"mc":[{"id":"1.168224334","rc":[{"batb":[[1,5.5,52.08],[2,1.01,0.51]],"ltp":0.0,"tv":0.0,"id":13117429},{"batb":[[0,4.9,60.64],[1,4.8,70.48],[2,4.7,15.26]],"ltp":0.0,"tv":0.0,"id":13117428},{"batb":[[1,4.2,139.24],[2,4.1,99.97]],"ltp":0.0,"tv":0.0,"id":17151080},{"batb":[[0,1.99,132.66],[1,1.97,139.85],[2,1.94,16.44]],"ltp":2.46,"tv":148.56,"id":17151079}]}]}
{"op":"mcm","clk":"1001467918","pt":1580636500886,"mc":[{"id":"1.168224334","rc":[{"batb":[[0,5.6,10.46],[1,1.01,0.51],[2,1.01,0]],"ltp":0.0,"tv":0.0,"id":13117429},{"batb":[[0,4.7,15.26],[1,1.01,0.51],[2,4.7,0]],"ltp":0.0,"tv":0.0,"id":13117428},{"batb":[[1,1.01,0.51],[2,4.1,0]],"ltp":0.0,"tv":0.0,"id":17151080}]}]}
{"op":"mcm","clk":"1001468072","pt":1580636504307,"mc":[{"id":"1.168224334","rc":[{"batb":[[0,5.8,45.9],[1,5.7,48.07],[2,5.6,10.46]],"ltp":0.0,"tv":0.0,"id":13117429},{"batb":[[0,7.2,74.14],[1,7,59.57],[2,4.7,15.26]],"ltp":0.0,"tv":0.0,"id":13117428},{"batb":[[0,4.5,112.49],[1,4.4,103.59],[2,1.01,0.51]],"ltp":0.0,"tv":0.0,"id":17151080}]}]}
{"op":"mcm","clk":"1001468105","pt":1580636505023,"mc":[{"id":"1.168224334","rc":[{"batb":[[1,5.7,68.37],[2,1.01,0.51]],"batl":[[0,6.8,17.78]],"ltp":0.0,"tv":0.0,"id":13117429},{"batb":[[1,7,72.08],[2,5.6,10.54]],"batl":[[1,14,11.17]],"ltp":0.0,"tv":0.0,"id":13117428},{"batb":[[0,4.7,15.42],[1,4.5,129.64],[2,4.4,85.18]],"batl":[[1,5.7,12.75]],"ltp":0.0,"tv":0.0,"id":17151080},{"batl":[[0,2.02,16.21],[1,2.24,24.16]],"ltp":2.46,"tv":148.56,"id":17151079}]}]}
{"op":"mcm","clk":"1001468184","pt":1580636506208,"mc":[{"id":"1.168224334","rc":[{"batb":[[2,5.6,8.4]],"batl":[[0,6.8,24.5]],"ltp":0.0,"tv":0.0,"id":13117429},{"batb":[[2,6.4,7.56]],"batl":[[0,8,5.88],[1,8.2,11.88],[2,14,11.17]],"ltp":0.0,"tv":0.0,"id":13117428},{"batb":[[2,4.4,96.94]],"batl":[[1,5.4,9.24],[2,5.7,12.75]],"ltp":0.0,"tv":0.0,"id":17151080},{"batb":[[2,1.94,60.97]],"batl":[[1,2.16,36.13],[2,2.24,24.16]],"ltp":2.46,"tv":148.56,"id":17151079}]}]}
{"op":"mcm","clk":"1001468630","pt":1580636514143,"mc":[{"id":"1.168224334","rc":[{"batb":[[0,5.7,68.37],[1,5.6,8.4],[2,1.01,0.51]],"ltp":0.0,"tv":0.0,"id":13117429},{"batb":[[0,6.4,7.56],[1,5.6,10.54],[2,1.01,0.51]],"batl":[[1,14,11.17],[2,14,0]],"ltp":0.0,"tv":0.0,"id":13117428},{"batb":[[0,4.5,17.15],[1,4.4,67.48],[2,1.01,0.51]],"batl":[[0,5.4,9.24],[1,5.7,12.75],[2,5.7,0]],"ltp":0.0,"tv":0.0,"id":17151080},{"batb":[[0,1.94,44.53],[1,1.73,23.84],[2,1.01,0.51]],"batl":[[0,2.16,36.13],[1,2.24,24.16],[2,2.24,0]],"ltp":2.46,"tv":148.56,"id":17151079}]}]}
{"op":"mcm","clk":"1001468657","pt":1580636514610,"mc":[{"id":"1.168224334","rc":[{"batb":[[1,1.01,0.51],[2,1.01,0]],"batl":[[0,6.8,17.78]],"ltp":0.0,"tv":0.0,"id":13117429},{"batb":[[0,5.6,10.54],[1,1.01,0.51],[2,1.01,0]],"batl":[[0,14,11.17],[1,14,0]],"ltp":0.0,"tv":0.0,"id":13117428},{"batb":[[1,4.4,55.72]],"batl":[[0,5.7,12.75],[1,5.7,0]],"ltp":0.0,"tv":0.0,"id":17151080},{"batb":[[0,1.73,23.84],[1,1.01,0.51],[2,1.01,0]],"batl":[[0,2.24,24.16],[1,2.24,0]],"ltp":2.46,"tv":148.56,"id":17151079}]}]}
{"op":"mcm","clk":"1001468820","pt":1580636517137,"mc":[{"id":"1.168224334","rc":[{"batb":[[1,5.6,50.02],[2,1.01,0.51]],"ltp":0.0,"tv":0.0,"id":13117429},{"batb":[[0,5.7,53.97],[1,5.6,60.43],[2,1.01,0.51]],"ltp":0.0,"tv":0.0,"id":13117428},{"batb":[[2,4.3,90.81]],"ltp":0.0,"tv":0.0,"id":17151080},{"batb":[[0,1.74,180.98],[1,1.73,23.84],[2,1.72,217.01]],"ltp":2.46,"tv":148.56,"id":17151079}]}]}
{"op":"mcm","clk":"1001468852","pt":1580636517915,"mc":[{"id":"1.168224334","rc":[{"batb":[[1,1.01,0.51],[2,1.01,0]],"ltp":0.0,"tv":0.0,"id":13117429},{"batb":[[0,5.6,10.54],[1,1.01,0.51],[2,1.01,0]],"ltp":0.0,"tv":0.0,"id":13117428},{"batb":[[1,1.01,0.51],[2,4.3,0]],"ltp":0.0,"tv":0.0,"id":17151080},{"batb":[[0,1.73,23.84],[1,1.01,0.51],[2,1.72,0]],"ltp":2.46,"tv":148.56,"id":17151079}]}]}
{"op":"mcm","clk":"1001468992","pt":1580636520921,"mc":[{"id":"1.168224334","rc":[{"batb":[[0,5.8,60.76],[1,5.7,68.37],[2,1.01,0.51]],"ltp":0.0,"tv":0.0,"id":13117429},{"batb":[[0,8,31.69],[1,7.8,48],[2,5.6,10.54]],"ltp":0.0,"tv":0.0,"id":13117428},{"batb":[[0,4.6,71.49],[1,4.5,98.68],[2,1.01,0.51]],"ltp":0.0,"tv":0.0,"id":17151080},{"batb":[[0,1.93,174.32],[1,1.91,153.94],[2,1.73,23.84]],"ltp":2.46,"tv":148.56,"id":17151079}]}]}
{"op":"mcm","clk":"1001469131","pt":1580636523348,"mc":[{"id":"1.168224334","rc":[{"batb":[[0,5.7,68.37],[1,1.01,0.51],[2,1.01,0]],"ltp":0.0,"tv":0.0,"id":13117429},{"batb":[[0,5.6,10.54],[1,1.01,0.51],[2,5.6,0]],"ltp":0.0,"tv":0.0,"id":13117428},{"batb":[[0,4.5,17.15],[1,1.01,0.51],[2,1.01,0]],"ltp":0.0,"tv":0.0,"id":17151080},{"batb":[[0,1.73,23.84],[1,1.01,0.51],[2,1.73,0]],"ltp":2.46,"tv":148.56,"id":17151079}]}]}
{"op":"mcm","clk":"1001469301","pt":1580636525729,"mc":[{"id":"1.168224334","rc":[{"batb":[[1,5.6,50.02],[2,1.01,0.51]],"ltp":0.0,"tv":0.0,"id":13117429},{"batb":[[0,5.7,53.97],[1,5.6,60.43],[2,1.01,0.51]],"ltp":0.0,"tv":0.0,"id":13117428},{"batb":[[1,4.4,55.72],[2,4.3,90.81]],"ltp":0.0,"tv":0.0,"id":17151080},{"batb":[[0,1.74,180.98],[1,1.73,23.84],[2,1.72,217.01]],"ltp":2.46,"tv":148.56,"id":17151079}]}]}
{"op":"mcm","clk":"1001471136","pt":1580636552259,"mc":[{"id":"1.168224334","rc":[{"batb":[[0,1.73,23.84],[1,1.01,0.51],[2,1.72,0]],"ltp":2.46,"tv":148.56,"id":17151079}]}]}
{"op":"mcm","clk":"1001471232","pt":1580636554956,"mc":[{"id":"1.168224334","rc":[{"batb":[[0,2.2,140.39],[1,2.18,103.5],[2,1.73,23.84]],"ltp":2.46,"tv":148.56,"id":17151079}]}]}
{"op":"mcm","clk":"1001471284","pt":1580636555994,"mc":[{"id":"1.168224334","rc":[{"batb":[[1,5.6,60.48],[2,5.5,9.24]],"batl":[[0,6.8,24.5]],"ltp":0.0,"tv":0.0,"id":13117429},{"batb":[[2,5.3,9.24]],"batl":[[0,6.4,27.86],[1,8.4,11.57]],"ltp":0.0,"tv":0.0,"id":13117428},{"batb":[[2,4.3,122.14]],"batl":[[0,5.1,16.37],[1,5.2,9.24],[2,5.3,14.71]],"ltp":0.0,"tv":0.0,"id":17151080},{"batb":[[2,2.14,24.78]],"batl":[[1,2.34,31.09],[2,2.44,19.12]],"ltp":2.46,"tv":148.56,"id":17151079}]}]}
{"op":"mcm","clk":"1001472470","pt":1580636579403,"mc":[{"id":"1.168224334","rc":[{"batb":[[0,5.7,20.3]],"ltp":0.0,"tv":0.0,"id":13117429},{"batb":[[0,5.6,10.54],[1,5.3,9.24],[2,4.8,14.63]],"ltp":0.0,"tv":0.0,"id":13117428},{"batb":[[1,4.3,31.33],[2,1.01,0.51]],"ltp":0.0,"tv":0.0,"id":17151080},{"batb":[[0,2.14,24.78],[1,2.1,37.81],[2,1.93,16.84]],"ltp":2.46,"tv":148.56,"id":17151079}]}]}
{"op":"mcm","clk":"1001472488","pt":1580636579918,"mc":[{"id":"1.168224334","rc":[{"batb":[[0,5.6,60.48],[1,5.5,9.24],[2,1.01,0.51]],"ltp":0.0,"tv":0.0,"id":13117429},{"batb":[[0,5.3,9.24],[1,4.8,14.63],[2,1.01,0.51]],"batl":[[0,6.4,7.56]],"ltp":0.0,"tv":0.0,"id":13117428},{"batb":[[0,4.3,31.33],[1,1.01,0.51],[2,1.01,0]],"batl":[[0,5.2,9.24],[1,5.3,14.71],[2,5.3,0]],"ltp":0.0,"tv":0.0,"id":17151080},{"batb":[[0,2.1,37.81],[1,1.93,16.84],[2,1.01,0.51]],"batl":[[0,2.34,31.09],[1,2.44,19.12],[2,2.44,0]],"ltp":2.46,"tv":148.56,"id":17151079}]}]}
{"op":"mcm","clk":"1001472549","pt":1580636580910,"mc":[{"id":"1.168224334","rc":[{"batb":[[1,1.01,0.51],[2,1.01,0]],"batl":[[0,6.8,17.78]],"ltp":0.0,"tv":0.0,"id":13117429},{"batb":[[0,4.8,14.63],[1,1.01,0.51],[2,1.01,0]],"batl":[[0,8.4,11.57],[1,8.4,0]],"ltp":0.0,"tv":0.0,"id":13117428},{"batb":[[0,4.3,18.73]],"batl":[[0,5.3,14.71],[1,5.3,0]],"ltp":0.0,"tv":0.0,"id":17151080},{"batb":[[0,1.93,16.84],[1,1.01,0.51],[2,1.01,0]],"batl":[[0,2.44,19.12],[1,2.44,0]],"ltp":2.46,"tv":148.56,"id":17151079}]}]}
{"op":"mcm","clk":"1001472661","pt":1580636582352,"mc":[{"id":"1.168224334","rc":[{"batb":[[1,5.5,51.94],[2,1.01,0.51]],"ltp":0.0,"tv":0.0,"id":13117429},{"batb":[[0,4.9,91.96],[1,4.8,84.61],[2,1.01,0.51]],"ltp":0.0,"tv":0.0,"id":13117428},{"batb":[[1,4.2,142.66],[2,4.1,99.91]],"ltp":0.0,"tv":0.0,"id":17151080},{"batb":[[0,1.98,129.78],[1,1.96,142.06],[2,1.93,16.84]],"ltp":2.46,"tv":148.56,"id":17151079}]}]}
{"op":"mcm","clk":"1001473003","pt":1580636587729,"mc":[{"id":"1.168224334","rc":[{"batb":[[0,5.6,10.46],[1,1.01,0.51],[2,1.01,0]],"ltp":0.0,"tv":0.0,"id":13117429},{"batb":[[0,4.8,14.63],[1,1.01,0.51],[2,1.01,0]],"ltp":0.0,"tv":0.0,"id":13117428},{"batb":[[1,1.01,0.51],[2,4.1,0]],"ltp":0.0,"tv":0.0,"id":17151080},{"batb":[[0,1.93,16.84],[1,1.01,0.51],[2,1.93,0]],"ltp":2.46,"tv":148.56,"id":17151079}]}]}
{"op":"mcm","clk":"1001473182","pt":1580636591403,"mc":[{"id":"1.168224334","rc":[{"batb":[[0,5.8,58.01],[1,5.7,67.96],[2,5.6,8.4]],"batl":[[0,6.8,17.55],[1,7,6.72]],"ltp":0.0,"tv":0.0,"id":13117429},{"batb":[[0,7.4,39.89],[1,7.2,56.83],[2,7,12.2]],"batl":[[0,8.2,5.04],[1,8.4,11.57],[2,14,10.62]],"ltp":0.0,"tv":0.0,"id":13117428},{"batb":[[0,4.7,15.34],[1,4.5,136.7],[2,4.4,96.81]],"batl":[[1,5.4,9.24],[2,5.7,12.67]],"ltp":0.0,"tv":0.0,"id":17151080},{"batb":[[0,1.98,129.78],[1,1.96,142.06],[2,1.93,61.37]],"batl":[[0,2.02,16.52],[1,2.14,36.13],[2,2.22,24.78]],"ltp":2.46,"tv":148.56,"id":17151079}]}]}
{"op":"mcm","clk":"1001473754","pt":1580636603348,"mc":[{"id":"1.168224334","rc":[{"batb":[[0,5.7,20.06],[1,5.6,8.4],[2,1.01,0.51]],"ltp":0.0,"tv":0.0,"id":13117429},{"batb":[[0,7,12.2],[1,6.4,7.56],[2,5.6,10.39]],"ltp":0.0,"tv":0.0,"id":13117428},{"batb":[[1,4.5,17],[2,4.4,11.76]],"ltp":0.0,"tv":0.0,"id":17151080},{"batb":[[0,1.93,61.37],[1,1.71,24.47],[2,1.01,0.51]],"ltp":2.46,"tv":148.56,"id":17151079}]}]}
{"op":"mcm","clk":"1001474004","pt":1580636608541,"mc":[{"id":"1.168224334","rc":[{"batl":[[1,7,0]],"ltp":0.0,"tv":0.0,"id":13117429}]}]}
{"op":"mcm","clk":"1001474104","pt":1580636610758,"mc":[{"id":"1.168224334","rc":[{"batb":[[1,1.01,0.51],[2,1.01,0]],"ltp":0.0,"tv":0.0,"id":13117429},{"batb":[[0,5.6,10.39],[1,1.01,0.51],[2,5.6,0]],"batl":[[0,14,10.62],[1,8.4,0],[2,14,0]],"ltp":0.0,"tv":0.0,"id":13117428},{"batb":[[0,4.5,17],[1,1.01,0.51],[2,4.4,0]],"batl":[[0,5.7,12.67],[1,5.4,0],[2,5.7,0]],"ltp":0.0,"tv":0.0,"id":17151080},{"batb":[[0,1.71,24.47],[1,1.01,0.51],[2,1.01,0]],"batl":[[0,2.22,24.78],[1,2.14,0],[2,2.22,0]],"ltp":2.46,"tv":148.56,"id":17151079}]}]}
{"op":"mcm","clk":"1001475299","pt":1580636638115,"mc":[{"id":"1.168224334","rc":[{"batb":[[0,5.7,47.44],[1,5.6,24.94],[2,1.01,0.51]],"ltp":0.0,"tv":0.0,"id":13117429},{"batb":[[0,5.7,41.24],[1,5.6,35.12],[2,1.01,0.51]],"ltp":0.0,"tv":0.0,"id":13117428},{"batb":[[1,4.4,30.53],[2,4.3,45.36]],"ltp":0.0,"tv":0.0,"id":17151080},{"batb":[[0,1.73,109.81],[1,1.71,135.24],[2,1.01,0.51]],"ltp":2.46,"tv":148.56,"id":17151079}]}]}
{"op":"mcm","clk":"1001475472","pt":1580636641814,"mc":[{"id":"1.168224334","rc":[{"batb":[[0,5.7,20.06],[1,1.01,0.51],[2,1.01,0]],"ltp":0.0,"tv":0.0,"id":13117429},{"batb":[[0,5.6,10.39],[1,1.01,0.51],[2,1.01,0]],"ltp":0.0,"tv":0.0,"id":13117428},{"batb":[[1,1.01,0.51],[2,4.3,0]],"ltp":0.0,"tv":0.0,"id":17151080},{"batb":[[0,1.71,24.47],[1,1.01,0.51],[2,1.01,0]],"ltp":2.46,"tv":148.56,"id":17151079}]}]}
{"op":"mcm","clk":"1001475662","pt":1580636645317,"mc":[{"id":"1.168224334","rc":[{"batb":[[0,6,20.96],[1,5.9,22.29],[2,5.8,18.73]],"batl":[[1,7,17.07]],"ltp":0.0,"tv":0.0,"id":13117429},{"batb":[[0,12.5,18.9],[1,12,23.3],[2,10.5,11.57]],"batl":[[1,17,7.55]],"ltp":0.0,"tv":0.0,"id":13117428},{"batb":[[0,5,13.14],[1,4.8,61.16],[2,4.7,36.72]],"batl":[[1,5.8,12.12]],"ltp":0.0,"tv":0.0,"id":17151080},{"batb":[[0,1.73,109.81],[1,1.71,135.24],[2,1.66,27.15]],"batl":[[0,1.78,24],[1,1.9,19.67]],"ltp":2.46,"tv":148.56,"id":17151079}]}]}
{"op":"mcm","clk":"1001475673","pt":1580636645623,"mc":[{"id":"1.168224334","rc":[{"batb":[[1,5.9,30.69]],"batl":[[2,7.4,5.88]],"ltp":0.0,"tv":0.0,"id":13117429},{"batb":[[2,11,4.2]],"ltp":0.0,"tv":0.0,"id":13117428},{"batb":[[2,4.7,47.64]],"batl":[[0,5.7,21.07]],"ltp":0.0,"tv":0.0,"id":17151080},{"batb":[[2,1.66,90.16]],"batl":[[1,1.81,42.01],[2,1.9,19.67]],"ltp":2.46,"tv":148.56,"id":17151079}]}]}
{"op":"mcm","clk":"1001477328","pt":1580636675368,"mc":[{"id":"1.168224334","rc":[{"batb":[[0,5.9,8.4],[1,5.7,19.75],[2,1.01,0.51]],"batl":[[0,7,17.07],[1,7.4,5.88],[2,7.4,0]],"ltp":0.0,"tv":0.0,"id":13117429},{"batb":[[0,11,4.2],[1,8.6,7.55],[2,1.01,0.51]],"batl":[[0,17,7.55],[1,17,0]],"ltp":0.0,"tv":0.0,"id":13117428},{"batb":[[0,4.8,14.48],[1,4.7,47.64],[2,1.01,0.51]],"batl":[[0,5.7,8.4]],"ltp":0.0,"tv":0.0,"id":17151080},{"batb":[[0,1.66,90.16],[1,1.01,0.51],[2,1.66,0]],"batl":[[0,1.81,42.01],[1,1.9,19.67],[2,1.9,0]],"ltp":2.46,"tv":148.56,"id":17151079}]}]}
{"op":"mcm","clk":"1001477372","pt":1580636676656,"mc":[{"id":"1.168224334","rc":[{"batb":[[0,5.7,19.75],[1,1.01,0.51],[2,1.01,0]],"batl":[[1,7.4,0]],"ltp":0.0,"tv":0.0,"id":13117429},{"batb":[[0,8.6,7.55],[1,1.01,0.51],[2,1.01,0]],"ltp":0.0,"tv":0.0,"id":13117428},{"batb":[[1,4.7,36.72]],"batl":[[0,5.8,12.12],[1,5.8,0]],"ltp":0.0,"tv":0.0,"id":17151080},{"batb":[[0,1.66,27.15]],"batl":[[0,1.9,19.67],[1,1.9,0]],"ltp":2.46,"tv":148.56,"id":17151079}]}]}
{"op":"mcm","clk":"1001477488","pt":1580636678157,"mc":[{"id":"1.168224334","rc":[{"batb":[[0,5.8,37.96],[1,5.7,43.58],[2,1.01,0.51]],"ltp":0.0,"tv":0.0,"id":13117429},{"batb":[[0,9.8,23.51],[1,9.6,15.26],[2,8.6,7.55]],"ltp":0.0,"tv":0.0,"id":13117428},{"batb":[[2,4.6,38.68]],"ltp":0.0,"tv":0.0,"id":17151080},{"batb":[[0,1.69,68.39],[1,1.67,120.13],[2,1.66,27.15]],"ltp":2.46,"tv":148.56,"id":17151079}]}]}
{"op":"mcm","clk":"1001477584","pt":1580636679346,"mc":[{"id":"1.168224334","rc":[{"batb":[[0,5.7,19.75],[1,1.01,0.51],[2,1.01,0]],"ltp":0.0,"tv":0.0,"id":13117429},{"batb":[[0,8.6,7.55],[1,1.01,0.51],[2,8.6,0]],"ltp":0.0,"tv":0.0,"id":13117428},{"batb":[[1,1.01,0.51],[2,4.6,0]],"ltp":0.0,"tv":0.0,"id":17151080}]}]}
{"op":"mcm","clk":"1001477773","pt":1580636682381,"mc":[{"id":"1.168224334","rc":[{"batb":[[0,6,37.91],[1,5.9,22.06],[2,5.7,19.75]],"ltp":0.0,"tv":0.0,"id":13117429},{"batb":[[0,15,8.19],[1,14.5,16.05],[2,8.6,7.55]],"ltp":0.0,"tv":0.0,"id":13117428},{"batb":[[0,4.9,34.42],[1,4.8,49.66],[2,1.01,0.51]],"ltp":0.0,"tv":0.0,"id":17151080}]}]}
{"op":"mcm","clk":"1001477817","pt":1580636683363,"mc":[{"id":"1.168224334","rc":[{"batb":[[1,5.9,40.39],[2,5.8,19.12]],"batl":[[0,7,16.37]],"ltp":0.0,"tv":0.0,"id":13117429},{"batb":[[2,12.5,8.1]],"batl":[[1,21,5.27]],"ltp":0.0,"tv":0.0,"id":13117428},{"batb":[[0,5.1,12.59],[1,5,13.53],[2,4.9,34.42]],"batl":[[1,5.9,11.57]],"ltp":0.0,"tv":0.0,"id":17151080},{"batb":[[0,1.66,27.15],[1,1.62,30.06],[2,1.01,0.51]],"batl":[[0,1.73,26.59],[1,1.82,22.58]],"ltp":2.46,"tv":148.56,"id":17151079}]}]}
{"op":"mcm","clk":"1001477828","pt":1580636683669,"mc":[{"id":"1.168224334","rc":[{"batb":[[0,6,46.31]],"batl":[[1,7.6,5.88]],"ltp":0.0,"tv":0.0,"id":13117429},{"batb":[[2,13,3.36]],"ltp":0.0,"tv":0.0,"id":13117428},{"batl":[[0,5.8,20.52]],"ltp":0.0,"tv":0.0,"id":17151080},{"batb":[[1,1.62,97.27]],"batl":[[1,1.76,42.01],[2,1.82,22.58]],"ltp":2.46,"tv":148.56,"id":17151079}]}]}
{"op":"mcm","clk":"1001477936","pt":1580636686188,"mc":[{"id":"1.168224334","rc":[{"batb":[[0,6,65.99]],"ltp":0.0,"tv":0.0,"id":13117429},{"batb":[[0,15,15.27]],"ltp":0.0,"tv":0.0,"id":13117428},{"batb":[[0,1.68,87.97],[1,1.66,150.16],[2,1.62,97.27]],"ltp":2.46,"tv":148.56,"id":17151079}]}]}
{"op":"mcm","clk":"1001478083","pt":1580636689380,"mc":[{"id":"1.168224334","rc":[{"batb":[[0,15,19.21]],"ltp":0.0,"tv":0.0,"id":13117428}]}]}
{"op":"mcm","clk":"1001478313","pt":1580636693357,"mc":[{"id":"1.168224334","rc":[{"batb":[[0,6,35.9],[1,5.9,22.06]],"ltp":0.0,"tv":0.0,"id":13117429},{"batb":[[0,13,3.36],[1,10,13.61],[2,1.01,0.51]],"batl":[[0,21,5.27],[1,21,0]],"ltp":0.0,"tv":0.0,"id":13117428},{"batb":[[0,5,13.53],[1,4.8,37.09],[2,1.01,0.51]],"batl":[[0,5.8,8.4]],"ltp":0.0,"tv":0.0,"id":17151080},{"batb":[[0,1.62,97.27],[1,1.01,0.51],[2,1.62,0]],"batl":[[0,1.76,42.01],[1,1.82,22.58],[2,1.82,0]],"ltp":2.46,"tv":148.56,"id":17151079}]}]}
{"op":"mcm","clk":"1001478392","pt":1580636695362,"mc":[{"id":"1.168224334","rc":[{"batb":[[0,6,27.5]],"batl":[[1,7.6,0]],"ltp":0.0,"tv":0.0,"id":13117429},{"batb":[[0,10,13.61],[1,1.01,0.51],[2,1.01,0]],"ltp":0.0,"tv":0.0,"id":13117428},{"batb":[[1,4.8,26.17]],"batl":[[0,5.9,11.57],[1,5.9,0]],"ltp":0.0,"tv":0.0,"id":17151080},{"batb":[[0,1.62,30.06]],"batl":[[0,1.82,22.58],[1,1.82,0]],"ltp":2.46,"tv":148.56,"id":17151079}]}]}
{"op":"mcm","clk":"1001478609","pt":1580636699182,"mc":[{"id":"1.168224334","rc":[{"batb":[[0,6,52.09]],"ltp":0.0,"tv":0.0,"id":13117429},{"batb":[[0,14.5,12.31],[1,14,17.5],[2,10,13.61]],"ltp":0.0,"tv":0.0,"id":13117428},{"batb":[[1,4.8,56.32]],"ltp":0.0,"tv":0.0,"id":17151080},{"batb":[[0,1.69,97.57],[1,1.67,120.52],[2,1.62,30.06]],"ltp":2.46,"tv":148.56,"id":17151079}]}]}
{"op":"mcm","clk":"1001478653","pt":1580636699998,"mc":[{"id":"1.168224334","rc":[{"batb":[[2,4.7,36.45]],"ltp":0.0,"tv":0.0,"id":17151080}]}]}
{"op":"mcm","clk":"1001478749","pt":1580636701194,"mc":[{"id":"1.168224334","rc":[{"batb":[[0,6,27.5]],"ltp":0.0,"tv":0.0,"id":13117429},{"batb":[[0,10,13.61],[1,1.01,0.51],[2,10,0]],"ltp":0.0,"tv":0.0,"id":13117428},{"batb":[[1,4.8,26.17]],"ltp":0.0,"tv":0.0,"id":17151080},{"batb":[[0,1.62,30.06],[1,1.01,0.51],[2,1.62,0]],"ltp":2.46,"tv":148.56,"id":17151079}]}]}
{"op":"mcm","clk":"1001479009","pt":1580636704208,"mc":[{"id":"1.168224334","rc":[{"batb":[[0,12,22],[1,11.5,25.93],[2,10,13.61]],"ltp":0.0,"tv":0.0,"id":13117428}]}]}
{"op":"mcm","clk":"1001479122","pt":1580636706220,"mc":[{"id":"1.168224334","rc":[{"batb":[[0,1.75,76.9],[1,1.73,106.56],[2,1.62,30.06]],"ltp":2.46,"tv":148.56,"id":17151079}]}]}
{"op":"mcm","clk":"1001479177","pt":1580636707311,"mc":[{"id":"1.168224334","rc":[{"batb":[[2,5.6,20.46]],"batl":[[0,6.8,17.62]],"ltp":0.0,"tv":0.0,"id":13117429},{"batl":[[0,13,12.43],[1,16.5,8.03]],"ltp":0.0,"tv":0.0,"id":13117428},{"batb":[[1,4.8,40.96]],"batl":[[0,5.6,12.98],[1,5.8,12.35]],"ltp":0.0,"tv":0.0,"id":17151080},{"batb":[[0,1.75,99.95],[2,1.68,26.2]],"batl":[[1,1.95,17.94]],"ltp":2.46,"tv":148.56,"id":17151079}]}]}
{"op":"mcm","clk":"1001479247","pt":1580636708393,"mc":[{"id":"1.168224334","rc":[{"batb":[[2,5.8,8.4]],"batl":[[1,7.2,6.72]],"ltp":0.0,"tv":0.0,"id":13117429},{"batb":[[2,11,4.2]],"ltp":0.0,"tv":0.0,"id":13117428},{"batb":[[2,4.7,47.37]],"batl":[[1,5.7,8.4],[2,5.8,12.35]],"ltp":0.0,"tv":0.0,"id":17151080},{"batb":[[2,1.68,87.54]],"batl":[[1,1.84,42.01],[2,1.95,17.94]],"ltp":2.46,"tv":148.56,"id":17151079}]}]}
{"op":"mcm","clk":"1001479776","pt":1580636717320,"mc":[{"id":"1.168224334","rc":[{"batl":[[0,16.5,8.03],[1,16.5,0]],"ltp":0.0,"tv":0.0,"id":13117428},{"batb":[[0,4.8,40.96],[1,4.7,47.37],[2,1.01,0.51]],"batl":[[0,5.7,8.4],[1,5.8,12.35],[2,5.8,0]],"ltp":0.0,"tv":0.0,"id":17151080},{"batb":[[0,1.75,76.9]],"batl":[[0,1.84,42.01],[1,1.95,17.94],[2,1.95,0]],"ltp":2.46,"tv":148.56,"id":17151079}]}]}
{"op":"mcm","clk":"1001479781","pt":1580636717425,"mc":[{"id":"1.168224334","rc":[{"batb":[[0,5.9,22.06],[1,5.8,8.4],[2,5.6,20.46]],"ltp":0.0,"tv":0.0,"id":13117429},{"batb":[[0,11,4.2],[1,7.8,9.36],[2,1.01,0.51]],"ltp":0.0,"tv":0.0,"id":13117428},{"batb":[[0,4.8,14.79],[1,4.7,10.92]],"ltp":0.0,"tv":0.0,"id":17151080},{"batb":[[0,1.68,87.54],[1,1.01,0.51],[2,1.68,0]],"ltp":2.46,"tv":148.56,"id":17151079}]}]}
{"op":"mcm","clk":"1001479885","pt":1580636719187,"mc":[{"id":"1.168224334","rc":[{"batb":[[1,5.6,20.46],[2,1.01,0.51]],"batl":[[1,7.2,0]],"ltp":0.0,"tv":0.0,"id":13117429},{"batb":[[0,7.8,9.36],[1,1.01,0.51],[2,1.01,0]],"ltp":0.0,"tv":0.0,"id":13117428},{"batb":[[1,1.01,0.51],[2,1.01,0]],"batl":[[0,5.8,12.35],[1,5.8,0]],"ltp":0.0,"tv":0.0,"id":17151080},{"batb":[[0,1.68,26.2]],"batl":[[0,1.95,17.94],[1,1.95,0]],"ltp":2.46,"tv":148.56,"id":17151079}]}]}
{"op":"mcm","clk":"1001479958","pt":1580636720321,"mc":[{"id":"1.168224334","rc":[{"batb":[[1,5.8,23.49],[2,5.6,20.46]],"ltp":0.0,"tv":0.0,"id":13117429},{"batb":[[0,9.2,15.01],[1,9,18.07],[2,7.8,9.36]],"ltp":0.0,"tv":0.0,"id":13117428},{"batb":[[1,4.6,50.44],[2,4.5,40.45]],"ltp":0.0,"tv":0.0,"id":17151080},{"batb":[[0,1.69,88.81],[1,1.68,26.2],[2,1.67,120.47]],"ltp":2.46,"tv":148.56,"id":17151079}]}]}
{"op":"mcm","clk":"1001480013","pt":1580636721615,"mc":[{"id":"1.168224334","rc":[{"batb":[[1,5.6,20.46],[2,1.01,0.51]],"ltp":0.0,"tv":0.0,"id":13117429},{"batb":[[0,7.8,9.36],[1,1.01,0.51],[2,7.8,0]],"ltp":0.0,"tv":0.0,"id":13117428},{"batb":[[1,1.01,0.51],[2,4.5,0]],"ltp":0.0,"tv":0.0,"id":17151080}]}]}
{"op":"mcm","clk":"1001480148","pt":1580636724402,"mc":[{"id":"1.168224334","rc":[{"batb":[[0,6,44.58],[1,5.9,22.06],[2,5.6,20.46]],"ltp":0.0,"tv":0.0,"id":13117429},{"batb":[[0,15,7.22],[1,14.5,16.44],[2,7.8,9.36]],"ltp":0.0,"tv":0.0,"id":13117428},{"batb":[[0,4.8,70.06],[1,4.7,36.47],[2,1.01,0.51]],"ltp":0.0,"tv":0.0,"id":17151080}]}]}
{"op":"mcm","clk":"1001480193","pt":1580636725332,"mc":[{"id":"1.168224334","rc":[{"batb":[[2,5.8,18.96]],"batl":[[1,7,17]],"ltp":0.0,"tv":0.0,"id":13117429},{"batb":[[2,12,8.66]],"batl":[[1,21,5.35]],"ltp":0.0,"tv":0.0,"id":13117428},{"batb":[[0,5.1,12.9],[1,4.9,13.93],[2,4.8,55.27]],"batl":[[1,5.9,11.88]],"ltp":0.0,"tv":0.0,"id":17151080},{"batl":[[0,1.75,25.65],[1,1.85,21.32]],"ltp":2.46,"tv":148.56,"id":17151079}]}]}
{"op":"mcm","clk":"1001480232","pt":1580636726003,"mc":[{"id":"1.168224334","rc":[{"batb":[[1,5.9,30.46]],"batl":[[2,7.2,6.72]],"ltp":0.0,"tv":0.0,"id":13117429},{"batb":[[2,12.5,3.36]],"ltp":0.0,"tv":0.0,"id":13117428},{"batl":[[0,5.8,20.76]],"ltp":0.0,"tv":0.0,"id":17151080},{"batl":[[1,1.79,42.01],[2,1.85,21.32]],"ltp":2.46,"tv":148.56,"id":17151079}]}]}
{"op":"mcm","clk":"1001480307","pt":1580636727913,"mc":[{"id":"1.168224334","rc":[{"batl":[[2,7.2,0]],"ltp":0.0,"tv":0.0,"id":13117429},{"batl":[[1,1.85,21.32],[2,1.85,0]],"ltp":2.46,"tv":148.56,"id":17151079}]}]}
{"op":"mcm","clk":"1001480457","pt":1580636730941,"mc":[{"id":"1.168224334","rc":[{"batl":[[2,7.4,5.88]],"ltp":0.0,"tv":0.0,"id":13117429},{"batl":[[1,1.78,42.01],[2,1.85,21.32]],"ltp":2.46,"tv":148.56,"id":17151079}]}]}
{"op":"mcm","clk":"1001480593","pt":1580636733328,"mc":[{"id":"1.168224334","rc":[{"batb":[[0,5.9,30.46],[1,5.7,19.83],[2,1.01,0.51]],"batl":[[0,7,17],[1,7.4,5.88],[2,7.4,0]],"ltp":0.0,"tv":0.0,"id":13117429},{"batb":[[0,12.5,3.36],[1,9.4,15.42],[2,1.01,0.51]],"batl":[[0,21,5.35],[1,21,0]],"ltp":0.0,"tv":0.0,"id":13117428},{"batb":[[0,4.9,13.93],[1,4.7,47.39],[2,1.01,0.51]],"batl":[[0,5.8,8.4]],"ltp":0.0,"tv":0.0,"id":17151080},{"batb":[[0,1.63,95.65],[1,1.01,0.51],[2,1.67,0]],"batl":[[0,1.78,42.01],[1,1.85,21.32],[2,1.85,0]],"ltp":2.46,"tv":148.56,"id":17151079}]}]}
{"op":"mcm","clk":"1001480663","pt":1580636734719,"mc":[{"id":"1.168224334","rc":[{"batb":[[0,5.9,22.06]],"batl":[[1,7.4,0]],"ltp":0.0,"tv":0.0,"id":13117429},{"batb":[[0,9.4,15.42],[1,1.01,0.51],[2,1.01,0]],"ltp":0.0,"tv":0.0,"id":13117428},{"batb":[[1,4.7,36.47]],"batl":[[0,5.9,11.88],[1,5.9,0]],"ltp":0.0,"tv":0.0,"id":17151080},{"batb":[[0,1.63,29.27]],"batl":[[0,1.85,21.32],[1,1.85,0]],"ltp":2.46,"tv":148.56,"id":17151079}]}]}
{"op":"mcm","clk":"1001480741","pt":1580636736223,"mc":[{"id":"1.168224334","rc":[{"batb":[[0,5.9,36.44],[1,5.8,23.25],[2,5.7,19.83]],"ltp":0.0,"tv":0.0,"id":13117429},{"batb":[[0,11.5,11.94],[1,11,28.88],[2,9.4,15.42]],"ltp":0.0,"tv":0.0,"id":13117428},{"batb":[[1,4.7,50.1],[2,4.6,38.43]],"ltp":0.0,"tv":0.0,"id":17151080},{"batb":[[0,1.65,76.29],[1,1.64,64.62],[2,1.63,29.27]],"ltp":2.46,"tv":148.56,"id":17151079}]}]}
{"op":"mcm","clk":"1001480802","pt":1580636737354,"mc":[{"id":"1.168224334","rc":[{"batb":[[0,5.9,22.34],[1,5.7,19.83],[2,1.01,0.51]],"ltp":0.0,"tv":0.0,"id":13117429},{"batb":[[0,9.4,15.42],[1,1.01,0.51],[2,9.4,0]],"ltp":0.0,"tv":0.0,"id":13117428},{"batb":[[1,4.7,36.61],[2,1.01,0.51]],"ltp":0.0,"tv":0.0,"id":17151080},{"batb":[[0,1.63,29.27],[1,1.01,0.51],[2,1.63,0]],"ltp":2.46,"tv":148.56,"id":17151079}]}]}
{"op":"mcm","clk":"1001480873","pt":1580636738749,"mc":[{"id":"1.168224334","rc":[{"batb":[[0,6,38.4],[1,5.9,22.34],[2,5.7,19.83]],"ltp":0.0,"tv":0.0,"id":13117429},{"batb":[[0,14,13.33],[1,13.5,18.83],[2,9.4,15.42]],"ltp":0.0,"tv":0.0,"id":13117428},{"batb":[[1,4.8,46.76],[2,4.7,36.61]],"ltp":0.0,"tv":0.0,"id":17151080},{"batb":[[0,1.71,65.31],[1,1.69,115.44],[2,1.63,29.27]],"ltp":2.46,"tv":148.56,"id":17151079}]}]}
{"op":"mcm","clk":"1001480993","pt":1580636740959,"mc":[{"id":"1.168224334","rc":[{"batb":[[0,5.9,22.34],[1,5.7,19.83],[2,1.01,0.51]],"ltp":0.0,"tv":0.0,"id":13117429},{"batb":[[0,9.4,15.42],[1,1.01,0.51],[2,9.4,0]],"ltp":0.0,"tv":0.0,"id":13117428},{"batb":[[1,4.7,36.61],[2,1.01,0.51]],"ltp":0.0,"tv":0.0,"id":17151080},{"batb":[[0,1.63,29.27],[1,1.01,0.51],[2,1.63,0]],"ltp":2.46,"tv":148.56,"id":17151079}]}]}
{"op":"mcm","clk":"1001481184","pt":1580636744364,"mc":[{"id":"1.168224334","rc":[{"batb":[[0,5.9,36.44],[1,5.8,23.25],[2,5.7,19.83]],"ltp":0.0,"tv":0.0,"id":13117429},{"batb":[[0,11.5,11.94],[1,11,28.88],[2,9.4,15.42]],"ltp":0.0,"tv":0.0,"id":13117428},{"batb":[[1,4.7,50.1],[2,4.6,38.43]],"ltp":0.0,"tv":0.0,"id":17151080},{"batb":[[0,1.65,76.29],[1,1.64,64.62],[2,1.63,29.27]],"ltp":2.46,"tv":148.56,"id":17151079}]}]}
{"op":"mcm","clk":"1001482554","pt":1580636769778,"mc":[{"id":"1.168224334","rc":[{"batb":[[0,5.7,19.83],[1,1.01,0.51],[2,5.7,0]],"ltp":0.0,"tv":0.0,"id":13117429},{"batb":[[0,9.4,15.42],[1,1.01,0.51],[2,9.4,0]],"ltp":0.0,"tv":0.0,"id":13117428},{"batb":[[1,1.01,0.51],[2,4.6,0]],"ltp":0.0,"tv":0.0,"id":17151080}]}]}
{"op":"mcm","clk":"1001482704","pt":1580636772405,"mc":[{"id":"1.168224334","rc":[{"batb":[[0,6.2,17.96],[1,6,42.87],[2,5.7,19.83]],"ltp":0.0,"tv":0.0,"id":13117429},{"batb":[[0,17.5,15.98],[1,17,11.61],[2,9.4,15.42]],"ltp":0.0,"tv":0.0,"id":13117428},{"batb":[[0,4.9,56.7],[1,4.8,34.94],[2,1.01,0.51]],"ltp":0.0,"tv":0.0,"id":17151080}]}]}
{"op":"mcm","clk":"1001482756","pt":1580636773186,"mc":[{"id":"1.168224334","rc":[{"batb":[[2,5.9,18.18]],"batl":[[0,7,16.29]],"ltp":0.0,"tv":0.0,"id":13117429},{"batb":[[2,14.5,5.67]],"batl":[[1,24,4.25]],"ltp":0.0,"tv":0.0,"id":13117428},{"batb":[[0,5.2,12.35],[1,5,13.14],[2,4.9,42.77]],"batl":[[1,6,11.41]],"ltp":0.0,"tv":0.0,"id":17151080},{"batl":[[0,1.69,28.64],[1,1.76,25.26]],"ltp":2.46,"tv":148.56,"id":17151079}]}]}
{"op":"mcm","clk":"1001482809","pt":1580636774371,"mc":[{"id":"1.168224334","rc":[{"batb":[[1,6,51.27]],"batl":[[1,7.4,5.88]],"ltp":0.0,"tv":0.0,"id":13117429},{"batl":[[0,5.9,20.28]],"ltp":0.0,"tv":0.0,"id":17151080},{"batl":[[1,1.73,42.01],[2,1.76,25.26]],"ltp":2.46,"tv":148.56,"id":17151079}]}]}
{"op":"mcm","clk":"1001483486","pt":1580636789692,"mc":[{"id":"1.168224334","rc":[{"batb":[[0,6,39.27],[1,5.8,19.28],[2,1.01,0.51]],"ltp":0.0,"tv":0.0,"id":13117429},{"batb":[[0,12,8.58],[1,1.01,0.51],[2,14.5,0]],"batl":[[0,24,4.25],[1,24,0]],"ltp":0.0,"tv":0.0,"id":13117428},{"batb":[[0,5,13.14],[1,4.8,45.86],[2,1.01,0.51]],"batl":[[0,5.9,8.4]],"ltp":0.0,"tv":0.0,"id":17151080},{"batb":[[0,1.6,31.47],[1,1.59,70.58],[2,1.01,0.51]],"batl":[[0,1.73,42.01],[1,1.76,25.26],[2,1.76,0]],"ltp":2.46,"tv":148.56,"id":17151079}]}]}
{"op":"mcm","clk":"1001483542","pt":1580636790838,"mc":[{"id":"1.168224334","rc":[{"batb":[[0,6,30.87]],"batl":[[1,7.4,0]],"ltp":0.0,"tv":0.0,"id":13117429},{"batb":[[1,4.8,34.94]],"batl":[[0,6,11.41],[1,6,0]],"ltp":0.0,"tv":0.0,"id":17151080},{"batb":[[1,1.01,0.51],[2,1.01,0]],"batl":[[0,1.76,25.26],[1,1.76,0]],"ltp":2.46,"tv":148.56,"id":17151079}]}]}
{"op":"mcm","clk":"1001483637","pt":1580636792393,"mc":[{"id":"1.168224334","rc":[{"batb":[[1,5.9,22.44],[2,5.8,19.28]],"ltp":0.0,"tv":0.0,"id":13117429},{"batb":[[0,15,11.87],[1,14.5,16.29],[2,12,8.58]],"ltp":0.0,"tv":0.0,"id":13117428},{"batb":[[1,4.8,50.6],[2,4.7,36.54]],"ltp":0.0,"tv":0.0,"id":17151080},{"batb":[[0,1.62,116.25],[1,1.61,69.25],[2,1.6,31.47]],"ltp":2.46,"tv":148.56,"id":17151079}]}]}
{"op":"mcm","clk":"1001483681","pt":1580636793425,"mc":[{"id":"1.168224334","rc":[{"batb":[[0,12,8.58],[1,1.01,0.51],[2,12,0]],"ltp":0.0,"tv":0.0,"id":13117428},{"batb":[[1,4.8,35.03],[2,1.01,0.51]],"ltp":0.0,"tv":0.0,"id":17151080},{"batb":[[0,1.6,31.47],[1,1.01,0.51],[2,1.6,0]],"ltp":2.46,"tv":148.56,"id":17151079}]}]}
{"op":"mcm","clk":"1001483848","pt":1580636797337,"mc":[{"id":"1.168224334","rc":[{"batb":[[0,6,31.72]],"ltp":0.0,"tv":0.0,"id":13117429}]}]}
{"op":"mcm","clk":"1001483984","pt":1580636800226,"mc":[{"id":"1.168224334","rc":[{"batb":[[0,15,12.17],[1,14.5,16.29],[2,12,8.58]],"ltp":0.0,"tv":0.0,"id":13117428},{"batb":[[1,4.8,50.29],[2,4.7,36.55]],"ltp":0.0,"tv":0.0,"id":17151080},{"batb":[[0,1.62,114.53],[1,1.61,69.25],[2,1.6,31.47]],"ltp":2.46,"tv":148.56,"id":17151079}]}]}
{"op":"mcm","clk":"1001484156","pt":1580636803229,"mc":[{"id":"1.168224334","rc":[{"batb":[[1,5.8,19.28],[2,1.01,0.51]],"ltp":0.0,"tv":0.0,"id":13117429},{"batb":[[0,12,8.58],[1,1.01,0.51],[2,12,0]],"ltp":0.0,"tv":0.0,"id":13117428},{"batb":[[1,1.01,0.51],[2,4.7,0]],"ltp":0.0,"tv":0.0,"id":17151080}]}]}
{"op":"mcm","clk":"1001484306","pt":1580636806316,"mc":[{"id":"1.168224334","rc":[{"batb":[[0,6.2,35.19],[1,6,42.42],[2,5.8,19.28]],"ltp":0.0,"tv":0.0,"id":13117429},{"batb":[[0,19.5,13.23],[1,19,9.29],[2,12,8.58]],"ltp":0.0,"tv":0.0,"id":13117428},{"batb":[[0,5,36.74],[1,4.9,33.62],[2,1.01,0.51]],"ltp":0.0,"tv":0.0,"id":17151080}]}]}
{"op":"mcm","clk":"1001484332","pt":1580636806936,"mc":[{"id":"1.168224334","rc":[{"batb":[[1,6,59.81],[2,5.9,18.41]],"batl":[[0,7.4,15.11]],"ltp":0.0,"tv":0.0,"id":13117429},{"batb":[[2,16,4.48]],"ltp":0.0,"tv":0.0,"id":13117428},{"batb":[[0,5.3,11.88],[1,5.1,12.59],[2,5,23.6]],"batl":[[1,6.2,10.7]],"ltp":0.0,"tv":0.0,"id":17151080},{"batl":[[0,1.66,30.76],[1,1.7,28.01]],"ltp":2.46,"tv":148.56,"id":17151079}]}]}
{"op":"mcm","clk":"1001484374","pt":1580636807706,"mc":[{"id":"1.168224334","rc":[{"batb":[[0,6.2,42.75]],"batl":[[1,7.8,5.88]],"ltp":0.0,"tv":0.0,"id":13117429},{"batl":[[0,6,19.81]],"ltp":0.0,"tv":0.0,"id":17151080},{"batl":[[1,1.69,42.01],[2,1.7,28.01]],"ltp":2.46,"tv":148.56,"id":17151079}]}]}
{"op":"mcm","clk":"1001485735","pt":1580636832045,"mc":[{"id":"1.168224334","rc":[{"batb":[[0,19.5,9.02],[1,16,4.48],[2,14,5.98]],"ltp":0.0,"tv":0.0,"id":13117428}]}]}
{"op":"mcm","clk":"1001485900","pt":1580636834942,"mc":[{"id":"1.168224334","rc":[{"batb":[[0,20,5.07],[1,19.5,9.02],[2,16,4.48]],"ltp":0.0,"tv":0.0,"id":13117428}]}]}
{"op":"mcm","clk":"1001489115","pt":1580636895026,"mc":[{"id":"1.168224334","rc":[{"batb":[[0,6,42.42],[1,5.9,18.41],[2,1.01,0.51]],"batl":[[1,7.8,0]],"ltp":0.0,"tv":0.0,"id":13117429},{"batb":[[0,14,5.98],[1,1.01,0.51],[2,16,0]],"ltp":0.0,"tv":0.0,"id":13117428},{"batb":[[0,5.1,12.59],[1,4.9,33.62],[2,1.01,0.51]],"batl":[[0,6.2,10.7],[1,6.2,0]],"ltp":0.0,"tv":0.0,"id":17151080},{"batb":[[0,1.54,35.8],[1,1.01,0.51],[2,1.6,0]],"batl":[[0,1.7,28.01],[1,1.69,0],[2,1.7,0]],"ltp":2.46,"tv":148.56,"id":17151079}]}]}
{"op":"mcm","clk":"1001489437","pt":1580636901051,"mc":[{"id":"1.168224334","rc":[{"batb":[[0,6.2,45.28],[1,6,42.42],[2,5.9,18.41]],"ltp":0.0,"tv":0.0,"id":13117429},{"batb":[[0,20,19.28],[1,19.5,8.68],[2,14,5.98]],"ltp":0.0,"tv":0.0,"id":13117428},{"batb":[[1,5,29.27],[2,4.9,33.62]],"ltp":0.0,"tv":0.0,"id":17151080},{"batb":[[0,1.61,113.66],[1,1.6,70.88],[2,1.54,35.8]],"ltp":2.46,"tv":148.56,"id":17151079}]}]}
{"op":"mcm","clk":"1001489587","pt":1580636904283,"mc":[{"id":"1.168224334","rc":[{"batb":[[0,6,42.42],[1,5.9,18.41],[2,1.01,0.51]],"ltp":0.0,"tv":0.0,"id":13117429},{"batb":[[0,14,5.98],[1,1.01,0.51],[2,14,0]],"ltp":0.0,"tv":0.0,"id":13117428},{"batb":[[1,4.9,33.62],[2,1.01,0.51]],"ltp":0.0,"tv":0.0,"id":17151080},{"batb":[[0,1.54,35.8],[1,1.01,0.51],[2,1.54,0]],"ltp":2.46,"tv":148.56,"id":17151079}]}]}
{"op":"mcm","clk":"1001489735","pt":1580636907159,"mc":[{"id":"1.168224334","rc":[{"batb":[[0,6,59.24],[1,5.9,40.52]],"ltp":0.0,"tv":0.0,"id":13117429},{"batb":[[0,17.5,6.32],[1,17,11.92],[2,14,5.98]],"ltp":0.0,"tv":0.0,"id":13117428},{"batb":[[2,4.8,35.07]],"ltp":0.0,"tv":0.0,"id":17151080},{"batb":[[0,1.58,73.73],[1,1.57,75.93],[2,1.54,35.8]],"ltp":2.46,"tv":148.56,"id":17151079}]}]}
{"op":"mcm","clk":"1001489995","pt":1580636912291,"mc":[{"id":"1.168224334","rc":[{"batb":[[0,5.9,18.41],[1,1.01,0.51],[2,1.01,0]],"ltp":0.0,"tv":0.0,"id":13117429},{"batb":[[0,14,5.98],[1,1.01,0.51],[2,14,0]],"ltp":0.0,"tv":0.0,"id":13117428},{"batb":[[1,1.01,0.51],[2,4.8,0]],"ltp":0.0,"tv":0.0,"id":17151080}]}]}
{"op":"mcm","clk":"1001490147","pt":1580636915282,"mc":[{"id":"1.168224334","rc":[{"batb":[[0,6.4,30.7],[1,6.2,39.66],[2,5.9,18.41]],"ltp":0.0,"tv":0.0,"id":13117429},{"batb":[[0,25,4.75],[1,24,11.58],[2,14,5.98]],"ltp":0.0,"tv":0.0,"id":13117428},{"batb":[[0,5.1,36.54],[1,5,32.09],[2,1.01,0.51]],"ltp":0.0,"tv":0.0,"id":17151080}]}]}
{"op":"mcm","clk":"1001490199","pt":1580636916100,"mc":[{"id":"1.168224334","rc":[{"batb":[[0,6.4,38.26],[1,6.2,55.79],[2,6,17.07]],"batl":[[1,7.6,14.24],[2,8,5.88]],"ltp":0.0,"tv":0.0,"id":13117429},{"batb":[[2,19.5,5.51]],"ltp":0.0,"tv":0.0,"id":13117428},{"batb":[[0,5.4,11.09],[1,5.3,11.8],[2,5.1,23.95]],"batl":[[0,6,8.4],[1,6.2,10.7],[2,6.6,19.43]],"ltp":0.0,"tv":0.0,"id":17151080},{"batb":[[0,1.57,75.93],[1,1.54,35.8],[2,1.52,80.66]],"batl":[[0,1.6,34.93],[1,1.64,42.01],[2,1.65,31.55]],"ltp":2.46,"tv":148.56,"id":17151079}]}]}
{"op":"mcm","clk":"1001490385","pt":1580636918784,"mc":[{"id":"1.168224334","rc":[{"batb":[[0,6.4,50.15]],"ltp":0.0,"tv":0.0,"id":13117429},{"batb":[[0,25,7.46]],"ltp":0.0,"tv":0.0,"id":13117428},{"batb":[[0,1.57,125.36],[1,1.56,78.13],[2,1.54,35.8]],"ltp":2.46,"tv":148.56,"id":17151079}]}]}
{"op":"mcm","clk":"1001491069","pt":1580636932223,"mc":[{"id":"1.168224334","rc":[{"batb":[[0,6.4,25.38],[1,6.2,39.66]],"batl":[[0,7.6,14.24],[1,8,5.88],[2,8,0]],"ltp":0.0,"tv":0.0,"id":13117429},{"batb":[[0,16.5,4.09],[1,1.01,0.51],[2,19.5,0]],"ltp":0.0,"tv":0.0,"id":13117428},{"batb":[[0,5.3,11.8],[1,5,32.09],[2,4.9,10.08]],"batl":[[1,6.6,19.43],[2,6.6,0]],"ltp":0.0,"tv":0.0,"id":17151080},{"batb":[[0,1.52,80.66],[1,1.49,40.76],[2,1.01,0.51]],"batl":[[0,1.64,42.01],[1,1.65,31.55],[2,1.65,0]],"ltp":2.46,"tv":148.56,"id":17151079}]}]}
{"op":"mcm","clk":"1001491118","pt":1580636933002,"mc":[{"id":"1.168224334","rc":[{"batb":[[0,6.4,17.82]],"batl":[[1,8,0]],"ltp":0.0,"tv":0.0,"id":13117429},{"batb":[[2,1.01,0.51]],"batl":[[0,6.6,19.43],[1,6.6,0]],"ltp":0.0,"tv":0.0,"id":17151080},{"batb":[[0,1.49,40.76],[1,1.01,0.51],[2,1.01,0]],"batl":[[0,1.65,31.55],[1,1.65,0]],"ltp":2.46,"tv":148.56,"id":17151079}]}]}
{"op":"mcm","clk":"1001491389","pt":1580636938200,"mc":[{"id":"1.168224334","rc":[{"batb":[[0,6.4,49.92]],"ltp":0.0,"tv":0.0,"id":13117429},{"batb":[[0,27,4.61],[1,26,10.01],[2,16.5,4.09]],"ltp":0.0,"tv":0.0,"id":13117428},{"batb":[[1,5.1,28.69],[2,5,32.09]],"ltp":0.0,"tv":0.0,"id":17151080},{"batb":[[0,1.56,121.82],[1,1.55,80.11],[2,1.49,40.76]],"ltp":2.46,"tv":148.56,"id":17151079}]}]}
{"op":"mcm","clk":"1001491626","pt":1580636941921,"mc":[{"id":"1.168224334","rc":[{"batb":[[0,6.4,17.82]],"ltp":0.0,"tv":0.0,"id":13117429},{"batb":[[0,16.5,4.09],[1,1.01,0.51],[2,16.5,0]],"ltp":0.0,"tv":0.0,"id":13117428},{"batb":[[1,5,32.09],[2,1.01,0.51]],"ltp":0.0,"tv":0.0,"id":17151080},{"batb":[[0,1.49,40.76],[1,1.01,0.51],[2,1.49,0]],"ltp":2.46,"tv":148.56,"id":17151079}]}]}
{"op":"mcm","clk":"1001491828","pt":1580636944816,"mc":[{"id":"1.168224334","rc":[{"batb":[[0,21,5.39],[1,20,16.98],[2,16.5,4.09]],"ltp":0.0,"tv":0.0,"id":13117428},{"batb":[[2,4.9,33.53]],"ltp":0.0,"tv":0.0,"id":17151080},{"batb":[[0,1.52,144.93],[1,1.51,88.9],[2,1.49,40.76]],"ltp":2.46,"tv":148.56,"id":17151079}]}]}
{"op":"mcm","clk":"1001491991","pt":1580636947201,"mc":[{"id":"1.168224334","rc":[{"batb":[[1,6,17.07],[2,1.01,0.51]],"ltp":0.0,"tv":0.0,"id":13117429},{"batb":[[0,16.5,4.09],[1,1.01,0.51],[2,16.5,0]],"ltp":0.0,"tv":0.0,"id":13117428},{"batb":[[1,1.01,0.51],[2,4.9,0]],"ltp":0.0,"tv":0.0,"id":17151080}]}]}
{"op":"mcm","clk":"1001492226","pt":1580636950408,"mc":[{"id":"1.168224334","rc":[{"batb":[[0,6.6,46.23],[1,6.4,52.17],[2,6.2,15.97]],"batl":[[1,8,12.9],[2,8.2,5.04]],"ltp":0.0,"tv":0.0,"id":13117429},{"batb":[[0,36,3.87],[1,34,11.35],[2,26,3.91]],"ltp":0.0,"tv":0.0,"id":13117428},{"batb":[[0,5.6,10.46],[1,5.4,11.09],[2,5.3,11.8]],"batl":[[0,6.2,7.56],[1,6.6,19.43],[2,6.8,17.55]],"ltp":0.0,"tv":0.0,"id":17151080},{"batl":[[0,1.55,39.73],[1,1.59,77.73],[2,1.65,31.55]],"ltp":2.46,"tv":148.56,"id":17151079}]}]}
{"op":"mcm","clk":"1001492260","pt":1580636951025,"mc":[{"id":"1.168224334","rc":[{"batb":[[2,5.2,28.89]],"ltp":0.0,"tv":0.0,"id":17151080},{"batl":[[2,1.65,0]],"ltp":2.46,"tv":148.56,"id":17151079}]}]}
{"op":"mcm","clk":"1001493172","pt":1580636963324,"mc":[{"id":"1.168224334","rc":[{"batb":[[0,6.6,6.72],[1,6.4,37.06]],"batl":[[0,8,12.9],[1,8.2,5.04],[2,8.2,0]],"ltp":0.0,"tv":0.0,"id":13117429},{"batb":[[0,21,4.34],[1,1.01,0.51],[2,26,0]],"ltp":0.0,"tv":0.0,"id":13117428},{"batb":[[0,5.4,11.09],[1,5.1,30.54],[2,5,10.08]],"batl":[[1,6.8,17.55],[2,6.8,0]],"ltp":0.0,"tv":0.0,"id":17151080},{"batb":[[0,1.48,87.38],[1,1.43,47.52],[2,1.01,0.51]],"batl":[[0,1.59,77.73],[1,1.59,0]],"ltp":2.46,"tv":148.56,"id":17151079}]}]}
{"op":"mcm","clk":"1001493273","pt":1580636964933,"mc":[{"id":"1.168224334","rc":[{"batb":[[0,6.4,37.06],[1,6.2,15.97],[2,1.01,0.51]],"batl":[[1,8.2,0]],"ltp":0.0,"tv":0.0,"id":13117429},{"batb":[[2,1.01,0.51]],"batl":[[0,6.8,17.55],[1,6.8,0]],"ltp":0.0,"tv":0.0,"id":17151080},{"batb":[[0,1.43,47.52],[1,1.01,0.51],[2,1.01,0]],"batl":[[0,1.59,35.72]],"ltp":2.46,"tv":148.56,"id":17151079}]}]}
{"op":"mcm","clk":"1001493339","pt":1580636966066,"mc":[{"id":"1.168224334","rc":[{"batb":[[0,6.4,50.78],[1,6.2,55.42]],"ltp":0.0,"tv":0.0,"id":13117429},{"batb":[[0,27,12.25],[1,26,9.73],[2,21,4.34]],"ltp":0.0,"tv":0.0,"id":13117428},{"batb":[[2,5,31.93]],"ltp":0.0,"tv":0.0,"id":17151080},{"batb":[[0,1.48,106.58],[1,1.47,98.93],[2,1.43,47.52]],"ltp":2.46,"tv":148.56,"id":17151079}]}]}
{"op":"mcm","clk":"1001493416","pt":1580636967256,"mc":[{"id":"1.168224334","rc":[{"batb":[[0,6.4,37.06],[1,6.2,15.97]],"ltp":0.0,"tv":0.0,"id":13117429},{"batb":[[0,21,4.34],[1,1.01,0.51],[2,21,0]],"ltp":0.0,"tv":0.0,"id":13117428},{"batb":[[2,1.01,0.51]],"ltp":0.0,"tv":0.0,"id":17151080},{"batb":[[0,1.43,47.52],[1,1.01,0.51],[2,1.43,0]],"ltp":2.46,"tv":148.56,"id":17151079}]}]}
{"op":"mcm","clk":"1001493625","pt":1580636970357,"mc":[{"id":"1.168224334","rc":[{"batb":[[0,6.6,46.82],[1,6.4,37.06],[2,6.2,15.97]],"ltp":0.0,"tv":0.0,"id":13117429},{"batb":[[0,38,9.16],[1,36,9.07],[2,21,4.34]],"ltp":0.0,"tv":0.0,"id":13117428},{"batb":[[1,5.2,36.98],[2,5.1,30.54]],"ltp":0.0,"tv":0.0,"id":17151080},{"batb":[[0,1.51,153.96],[1,1.5,91.37],[2,1.43,47.52]],"ltp":2.46,"tv":148.56,"id":17151079}]}]}
{"op":"mcm","clk":"1001493727","pt":1580636972065,"mc":[{"id":"1.168224334","rc":[{"batb":[[0,6.4,37.06],[1,6.2,15.97],[2,1.01,0.51]],"ltp":0.0,"tv":0.0,"id":13117429},{"batb":[[0,21,4.34],[1,1.01,0.51],[2,21,0]],"ltp":0.0,"tv":0.0,"id":13117428},{"batb":[[1,5.1,30.54],[2,1.01,0.51]],"ltp":0.0,"tv":0.0,"id":17151080},{"batb":[[0,1.43,47.52],[1,1.01,0.51],[2,1.43,0]],"ltp":2.46,"tv":148.56,"id":17151079}]}]}
{"op":"mcm","clk":"1001493908","pt":1580636975072,"mc":[{"id":"1.168224334","rc":[{"batb":[[0,6.4,50.78],[1,6.2,55.42]],"ltp":0.0,"tv":0.0,"id":13117429},{"batb":[[0,27,12.26],[1,26,9.73],[2,21,4.34]],"ltp":0.0,"tv":0.0,"id":13117428},{"batb":[[2,5,31.93]],"ltp":0.0,"tv":0.0,"id":17151080},{"batb":[[0,1.48,106.57],[1,1.47,98.93],[2,1.43,47.52]],"ltp":2.46,"tv":148.56,"id":17151079}]}]}
{"op":"mcm","clk":"1001494245","pt":1580636981254,"mc":[{"id":"1.168224334","rc":[{"batb":[[0,6.2,15.97],[1,1.01,0.51],[2,1.01,0]],"ltp":0.0,"tv":0.0,"id":13117429},{"batb":[[0,21,4.34],[1,1.01,0.51],[2,21,0]],"ltp":0.0,"tv":0.0,"id":13117428},{"batb":[[1,1.01,0.51],[2,5,0]],"ltp":0.0,"tv":0.0,"id":17151080}]}]}
{"op":"mcm","clk":"1001494462","pt":1580636984364,"mc":[{"id":"1.168224334","rc":[{"batb":[[0,6.8,33.24],[1,6.6,13.69],[2,6.4,14.79]],"batl":[[1,8.4,11.57]],"ltp":0.0,"tv":0.0,"id":13117429},{"batb":[[0,60,3.41],[1,55,5.88],[2,30,2.64]],"ltp":0.0,"tv":0.0,"id":13117428},{"batb":[[0,5.8,18.8],[1,5.6,10.31],[2,5.4,11.09]],"batl":[[1,7,16.29]],"ltp":0.0,"tv":0.0,"id":17151080},{"batb":[[0,1.47,98.93],[1,1.43,47.52],[2,1.4,53.35]],"batl":[[0,1.49,46.19],[1,1.53,41.62],[2,1.59,35.72]],"ltp":2.46,"tv":148.56,"id":17151079}]}]}
{"op":"mcm","clk":"1001494475","pt":1580636984568,"mc":[{"id":"1.168224334","rc":[{"batb":[[2,5.3,39.47]],"ltp":0.0,"tv":0.0,"id":17151080},{"batl":[[2,1.59,0]],"ltp":2.46,"tv":148.56,"id":17151079}]}]}
{"op":"mcm","clk":"1001494554","pt":1580636985881,"mc":[{"id":"1.168224334","rc":[{"batb":[[1,6.6,20.41]],"batl":[[1,8.4,16.61]],"ltp":0.0,"tv":0.0,"id":13117429},{"batl":[[0,6.2,7.56],[1,6.8,17.55],[2,7,16.29]],"ltp":0.0,"tv":0.0,"id":17151080},{"batb":[[1,1.45,93.26],[2,1.43,47.52]],"batl":[[2,1.55,42.01]],"ltp":2.46,"tv":148.56,"id":17151079}]}]}
{"op":"mcm","clk":"1001494651","pt":1580636987371,"mc":[{"id":"1.168224334","rc":[{"batb":[[0,7,30.31],[1,6.8,33.24],[2,6.6,20.41]],"ltp":0.0,"tv":0.0,"id":13117429},{"batb":[[0,60,5.85]],"ltp":0.0,"tv":0.0,"id":13117428},{"batb":[[0,1.47,154.65],[1,1.46,102.47],[2,1.45,93.26]],"ltp":2.46,"tv":148.56,"id":17151079}]}]}
{"op":"mcm","clk":"1001495558","pt":1580637001027,"mc":[{"id":"1.168224334","rc":[{"batb":[[0,6.8,33.24],[1,6.4,14.79],[2,1.01,0.51]],"batl":[[0,8.4,11.57],[1,8.4,0]],"ltp":0.0,"tv":0.0,"id":13117429},{"batb":[[0,1.01,0.51],[1,55,0],[2,30,0]],"ltp":0.0,"tv":0.0,"id":13117428},{"batb":[[0,5.6,10.31],[1,5.2,29.05],[2,1.01,0.51]],"batl":[[0,7,16.29],[1,6.8,0],[2,7,0]],"ltp":0.0,"tv":0.0,"id":17151080},{"batb":[[0,1.4,53.35],[1,1.01,0.51],[2,1.45,0]],"batl":[[0,1.53,41.62],[1,1.53,0],[2,1.55,0]],"ltp":2.46,"tv":148.56,"id":17151079}]}]}
{"op":"mcm","clk":"1001495772","pt":1580637004028,"mc":[{"id":"1.168224334","rc":[{"batb":[[1,6.6,35.32],[2,6.4,14.79]],"ltp":0.0,"tv":0.0,"id":13117429},{"batb":[[0,46,5.23],[1,44,6.86],[2,1.01,0.51]],"ltp":0.0,"tv":0.0,"id":13117428},{"batb":[[1,5.2,36.82],[2,5.1,30.31]],"ltp":0.0,"tv":0.0,"id":17151080}]}]}
{"op":"mcm","clk":"1001495909","pt":1580637006330,"mc":[{"id":"1.168224334","rc":[{"batb":[[0,1.5,105.06],[1,1.49,93.86],[2,1.4,53.35]],"ltp":2.46,"tv":148.56,"id":17151079}]}]}
{"op":"mcm","clk":"1001495961","pt":1580637007048,"mc":[{"id":"1.168224334","rc":[{"batl":[[0,7.6,13.85],[1,8,12.59]],"ltp":0.0,"tv":0.0,"id":13117429},{"batb":[[2,23,3.15]],"ltp":0.0,"tv":0.0,"id":13117428},{"batb":[[1,5.5,10.86],[2,5.2,36.82]],"batl":[[0,6.6,19.2],[1,6.8,17.47]],"ltp":0.0,"tv":0.0,"id":17151080},{"batb":[[2,1.47,42.72]],"batl":[[1,1.58,36.98]],"ltp":2.46,"tv":148.56,"id":17151079}]}]}
{"op":"mcm","clk":"1001496030","pt":1580637008336,"mc":[{"id":"1.168224334","rc":[{"batb":[[1,6.6,42.04]],"batl":[[2,8.2,5.04]],"ltp":0.0,"tv":0.0,"id":13117429},{"batl":[[0,6.2,7.56],[1,6.6,19.2],[2,6.8,17.47]],"ltp":0.0,"tv":0.0,"id":17151080},{"batl":[[1,1.57,42.01],[2,1.58,36.98]],"ltp":2.46,"tv":148.56,"id":17151079}]}]}
{"op":"mcm","clk":"1001496223","pt":1580637011747,"mc":[{"id":"1.168224334","rc":[{"batb":[[0,6.8,46.14]],"ltp":0.0,"tv":0.0,"id":13117429}]}]}
{"op":"mcm","clk":"1001496752","pt":1580637019835,"mc":[{"id":"1.168224334","rc":[{"batb":[[0,6.8,18.01],[2,6.2,16.05]],"batl":[[0,8,12.59],[1,8.2,5.04],[2,8.2,0]],"ltp":0.0,"tv":0.0,"id":13117429},{"batb":[[0,23,3.15],[1,1.01,0.51],[2,23,0]],"ltp":0.0,"tv":0.0,"id":13117428},{"batb":[[0,5.5,10.86],[1,5.1,40.39],[2,1.01,0.51]],"batl":[[1,6.8,17.47],[2,6.8,0]],"ltp":0.0,"tv":0.0,"id":17151080},{"batb":[[0,1.46,90.74],[1,1.42,49.88],[2,1.01,0.51]],"batl":[[0,1.57,42.01],[1,1.58,36.98],[2,1.58,0]],"ltp":2.46,"tv":148.56,"id":17151079}]}]}
{"op":"mcm","clk":"1001496840","pt":1580637021024,"mc":[{"id":"1.168224334","rc":[{"batb":[[1,6.6,35.32]],"batl":[[1,8.2,0]],"ltp":0.0,"tv":0.0,"id":13117429},{"batb":[[1,5.1,30.31]],"batl":[[0,6.8,17.47],[1,6.8,0]],"ltp":0.0,"tv":0.0,"id":17151080},{"batb":[[0,1.42,49.88],[1,1.01,0.51],[2,1.01,0]],"batl":[[0,1.58,36.98],[1,1.58,0]],"ltp":2.46,"tv":148.56,"id":17151079}]}]}
{"op":"mcm","clk":"1001496990","pt":1580637023447,"mc":[{"id":"1.168224334","rc":[{"batb":[[0,32,14.56],[1,30,6.96],[2,23,3.15]],"ltp":0.0,"tv":0.0,"id":13117428},{"batb":[[2,5,31.75]],"ltp":0.0,"tv":0.0,"id":17151080},{"batb":[[0,1.45,127.68],[1,1.44,108.58],[2,1.42,49.88]],"ltp":2.46,"tv":148.56,"id":17151079}]}]}
{"op":"mcm","clk":"1001497231","pt":1580637027833,"mc":[{"id":"1.168224334","rc":[{"batb":[[0,1.42,49.88],[1,1.01,0.51],[2,1.42,0]],"ltp":2.46,"tv":148.56,"id":17151079}]}]}
{"op":"mcm","clk":"1001497395","pt":1580637030836,"mc":[{"id":"1.168224334","rc":[{"batb":[[0,1.53,129.03],[1,1.52,86.9],[2,1.42,49.88]],"ltp":2.46,"tv":148.56,"id":17151079}]}]}
{"op":"mcm","clk":"1001497459","pt":1580637031972,"mc":[{"id":"1.168224334","rc":[{"batb":[[1,6.6,42.04]],"batl":[[0,7.4,15.03],[1,7.8,13.53],[2,8.2,5.04]],"ltp":0.0,"tv":0.0,"id":13117429},{"batb":[[1,5.3,11.88],[2,5.1,30.31]],"batl":[[0,6,8.4],[1,6.2,10.46],[2,6.6,18.49]],"ltp":0.0,"tv":0.0,"id":17151080},{"batb":[[1,1.52,124.82],[2,1.49,85.7]],"batl":[[1,1.6,42.01],[2,1.65,31.47]],"ltp":2.46,"tv":148.56,"id":17151079}]}]}
{"op":"mcm","clk":"1001498844","pt":1580637055075,"mc":[{"id":"1.168224334","rc":[{"batb":[[0,6.6,25.34],[1,6,17.23],[2,1.01,0.51]],"batl":[[0,7.8,13.53],[1,7.8,0],[2,8.2,0]],"ltp":0.0,"tv":0.0,"id":13117429},{"batb":[[0,17,7.87],[1,1.01,0.51],[2,23,0]],"ltp":0.0,"tv":0.0,"id":13117428},{"batb":[[0,5.3,11.88],[1,5,22.62],[2,1.01,0.51]],"batl":[[0,6.6,18.49],[1,6.2,0],[2,6.6,0]],"ltp":0.0,"tv":0.0,"id":17151080},{"batb":[[0,1.44,46.89],[1,1.01,0.51],[2,1.49,0]],"batl":[[0,1.65,31.47],[1,1.6,0],[2,1.65,0]],"ltp":2.46,"tv":148.56,"id":17151079}]}]}
{"op":"mcm","clk":"1001499139","pt":1580637061004,"mc":[{"id":"1.168224334","rc":[{"batb":[[0,6.8,28.04],[1,6.6,35.84],[2,6,17.23]],"ltp":0.0,"tv":0.0,"id":13117429},{"batb":[[0,38,7.71],[1,36,10.28],[2,17,7.87]],"ltp":0.0,"tv":0.0,"id":13117428},{"batb":[[1,5.1,44.55],[2,5,31.55]],"ltp":0.0,"tv":0.0,"id":17151080},{"batb":[[0,1.52,88.06],[1,1.51,88.98],[2,1.44,46.89]],"ltp":2.46,"tv":148.56,"id":17151079}]}]}
{"op":"mcm","clk":"1001499361","pt":1580637064708,"mc":[{"id":"1.168224334","rc":[{"batb":[[0,6.6,25.34],[1,6,17.23],[2,1.01,0.51]],"ltp":0.0,"tv":0.0,"id":13117429},{"batb":[[0,17,7.87],[1,1.01,0.51],[2,17,0]],"ltp":0.0,"tv":0.0,"id":13117428},{"batb":[[1,5,22.62],[2,1.01,0.51]],"ltp":0.0,"tv":0.0,"id":17151080},{"batb":[[0,1.44,46.89],[1,1.01,0.51],[2,1.44,0]],"ltp":2.46,"tv":148.56,"id":17151079}]}]}
{"op":"mcm","clk":"1001499504","pt":1580637067633,"mc":[{"id":"1.168224334","rc":[{"batb":[[1,6.4,38.43],[2,6,17.23]],"ltp":0.0,"tv":0.0,"id":13117429},{"batb":[[0,22,14.12],[1,21,15.51],[2,17,7.87]],"ltp":0.0,"tv":0.0,"id":13117428},{"batb":[[2,4.9,33.43]],"ltp":0.0,"tv":0.0,"id":17151080},{"batb":[[0,1.46,138.83],[1,1.45,105.49],[2,1.44,46.89]],"ltp":2.46,"tv":148.56,"id":17151079}]}]}
{"op":"mcm","clk":"1001500536","pt":1580637089322,"mc":[{"id":"1.168224334","rc":[{"batb":[[0,1.44,46.89],[1,1.01,0.51],[2,1.44,0]],"ltp":2.46,"tv":148.56,"id":17151079}]}]}
{"op":"mcm","clk":"1001500658","pt":1580637092346,"mc":[{"id":"1.168224334","rc":[{"batb":[[0,1.59,80.99],[1,1.58,74.65],[2,1.44,46.89]],"ltp":2.46,"tv":148.56,"id":17151079}]}]}
{"op":"mcm","clk":"1001500717","pt":1580637093321,"mc":[{"id":"1.168224334","rc":[{"batl":[[0,7.2,16.13],[1,7.4,14.87]],"ltp":0.0,"tv":0.0,"id":13117429},{"batl":[[0,26,7.16]],"ltp":0.0,"tv":0.0,"id":13117428},{"batb":[[1,5.1,12.59],[2,5,22.62]],"batl":[[0,6,11.41],[1,6.4,10.31]],"ltp":0.0,"tv":0.0,"id":17151080},{"batb":[[1,1.58,106.91],[2,1.51,38.32]],"batl":[[1,1.71,27.85]],"ltp":2.46,"tv":148.56,"id":17151079}]}]}
{"op":"mcm","clk":"1001500756","pt":1580637094144,"mc":[{"id":"1.168224334","rc":[{"batb":[[1,6.4,45.99]],"batl":[[2,8,5.88]],"ltp":0.0,"tv":0.0,"id":13117429},{"batl":[[0,6,19.81]],"ltp":0.0,"tv":0.0,"id":17151080},{"batb":[[2,1.52,80.66]],"batl":[[1,1.66,42.01],[2,1.71,27.85]],"ltp":2.46,"tv":148.56,"id":17151079}]}]}
{"op":"mcm","clk":"1001501765","pt":1580637114395,"mc":[{"id":"1.168224334","rc":[{"batb":[[0,6.4,45.99],[1,6,17.23],[2,5.9,18.18]],"ltp":0.0,"tv":0.0,"id":13117429},{"batb":[[0,17,7.87],[1,14,6.29],[2,1.01,0.51]],"ltp":0.0,"tv":0.0,"id":13117428},{"batb":[[2,4.9,33.52]],"ltp":0.0,"tv":0.0,"id":17151080},{"batb":[[0,1.58,32.26],[1,1.52,80.66],[2,1.51,38.32]],"ltp":2.46,"tv":148.56,"id":17151079}]}]}
{"op":"mcm","clk":"1001501804","pt":1580637115068,"mc":[{"id":"1.168224334","rc":[{"batb":[[0,6.4,38.43],[1,5.9,18.18],[2,1.01,0.51]],"batl":[[0,7.4,14.87],[1,7.4,0],[2,8,0]],"ltp":0.0,"tv":0.0,"id":13117429},{"batb":[[0,14,6.29],[1,1.01,0.51],[2,1.01,0]],"ltp":0.0,"tv":0.0,"id":13117428},{"batb":[[0,5.1,12.59],[1,4.9,23.44],[2,1.01,0.51]],"batl":[[0,6.4,10.31],[1,6.4,0]],"ltp":0.0,"tv":0.0,"id":17151080},{"batb":[[0,1.51,38.32],[1,1.01,0.51],[2,1.51,0]],"batl":[[0,1.71,27.85],[1,1.66,0],[2,1.71,0]],"ltp":2.46,"tv":148.56,"id":17151079}]}]}
{"op":"mcm","clk":"1001501923","pt":1580637117276,"mc":[{"id":"1.168224334","rc":[{"batb":[[1,6.2,40.87],[2,5.9,18.18]],"ltp":0.0,"tv":0.0,"id":13117429},{"batb":[[0,18,12.3],[1,17.5,11.62],[2,14,6.29]],"ltp":0.0,"tv":0.0,"id":13117428},{"batb":[[2,4.8,35.05]],"ltp":0.0,"tv":0.0,"id":17151080},{"batb":[[0,1.53,98.53],[1,1.52,86.75],[2,1.51,38.32]],"ltp":2.46,"tv":148.56,"id":17151079}]}]}
{"op":"mcm","clk":"1001501963","pt":1580637117998,"mc":[{"id":"1.168224334","rc":[{"batb":[[2,5.9,17.94]],"batl":[[0,7.4,14.71]],"ltp":0.0,"tv":0.0,"id":13117429},{"batl":[[0,1.7,28.01]],"ltp":2.46,"tv":148.56,"id":17151079}]}]}
{"op":"mcm","clk":"1001502179","pt":1580637122009,"mc":[{"id":"1.168224334","rc":[{"batb":[[0,1.51,38.32],[1,1.01,0.51],[2,1.51,0]],"ltp":2.46,"tv":148.56,"id":17151079}]}]}
{"op":"mcm","clk":"1001502363","pt":1580637125413,"mc":[{"id":"1.168224334","rc":[{"batl":[[0,7,16.76],[1,7.2,15.89]],"ltp":0.0,"tv":0.0,"id":13117429},{"batl":[[0,19.5,5.9],[1,26,7.08]],"ltp":0.0,"tv":0.0,"id":13117428},{"batb":[[1,5,13.3],[2,4.9,23.44]],"batl":[[0,5.8,12.12],[1,6.2,11.09]],"ltp":0.0,"tv":0.0,"id":17151080},{"batb":[[0,1.64,28.64],[1,1.63,107.96],[2,1.62,68.14]],"batl":[[1,1.75,25.34]],"ltp":2.46,"tv":148.56,"id":17151079}]}]}
{"op":"mcm","clk":"1001502406","pt":1580637126393,"mc":[{"id":"1.168224334","rc":[{"batb":[[0,6.4,45.99]],"batl":[[2,8,5.88]],"ltp":0.0,"tv":0.0,"id":13117429},{"batl":[[1,5.9,8.4],[2,6.2,11.09]],"ltp":0.0,"tv":0.0,"id":17151080},{"batl":[[0,1.69,42.01],[1,1.7,28.01],[2,1.75,25.34]],"ltp":2.46,"tv":148.56,"id":17151079}]}]}
{"op":"mcm","clk":"1001503398","pt":1580637143311,"mc":[{"id":"1.168224334","rc":[{"batb":[[0,6.4,7.56],[2,5.8,19.04]],"batl":[[0,7.2,15.89],[1,8,5.88],[2,8,0]],"ltp":0.0,"tv":0.0,"id":13117429},{"batb":[[0,12.5,8.26],[1,1.01,0.51],[2,14,0]],"batl":[[0,26,7.08],[1,26,0]],"ltp":0.0,"tv":0.0,"id":13117428},{"batb":[[0,5,13.3],[1,4.8,45.97],[2,1.01,0.51]],"batl":[[0,5.9,8.4],[1,6.2,11.09],[2,6.2,0]],"ltp":0.0,"tv":0.0,"id":17151080},{"batb":[[0,1.57,32.97],[1,1.56,74.78],[2,1.01,0.51]],"batl":[[1,1.75,25.34],[2,1.75,0]],"ltp":2.46,"tv":148.56,"id":17151079}]}]}
{"op":"mcm","clk":"1001503512","pt":1580637145126,"mc":[{"id":"1.168224334","rc":[{"batb":[[0,6.2,40.87],[1,5.8,19.04],[2,1.01,0.51]],"batl":[[1,8,0]],"ltp":0.0,"tv":0.0,"id":13117429},{"batb":[[1,4.8,35.05]],"batl":[[0,6.2,11.09],[1,6.2,0]],"ltp":0.0,"tv":0.0,"id":17151080},{"batb":[[1,1.01,0.51],[2,1.01,0]],"batl":[[0,1.75,25.34],[1,1.75,0]],"ltp":2.46,"tv":148.56,"id":17151079}]}]}
{"op":"mcm","clk":"1001503587","pt":1580637146221,"mc":[{"id":"1.168224334","rc":[{"batb":[[0,6.2,57.43],[1,6,43.42],[2,5.8,19.04]],"ltp":0.0,"tv":0.0,"id":13117429},{"batb":[[0,16,8.21],[1,15.5,15.05],[2,12.5,8.26]],"ltp":0.0,"tv":0.0,"id":13117428},{"batb":[[2,4.7,36.64]],"ltp":0.0,"tv":0.0,"id":17151080},{"batb":[[0,1.58,125.78],[1,1.57,109.63],[2,1.01,0.51]],"ltp":2.46,"tv":148.56,"id":17151079}]}]}
{"op":"mcm","clk":"1001503655","pt":1580637147310,"mc":[{"id":"1.168224334","rc":[{"batb":[[0,1.57,32.97],[1,1.01,0.51],[2,1.01,0]],"ltp":2.46,"tv":148.56,"id":17151079}]}]}
{"op":"mcm","clk":"1001503839","pt":1580637150361,"mc":[{"id":"1.168224334","rc":[{"batb":[[0,1.67,76.1],[1,1.66,62.31],[2,1.57,32.97]],"ltp":2.46,"tv":148.56,"id":17151079}]}]}
{"op":"mcm","clk":"1001503868","pt":1580637150931,"mc":[{"id":"1.168224334","rc":[{"batl":[[0,6.8,17.78],[1,7,17.15]],"ltp":0.0,"tv":0.0,"id":13117429},{"batl":[[0,17,7.71],[1,21,5.04]],"ltp":0.0,"tv":0.0,"id":13117428},{"batb":[[1,4.8,49.53]],"batl":[[0,5.7,12.75],[1,5.8,12.2]],"ltp":0.0,"tv":0.0,"id":17151080},{"batb":[[0,1.69,25.89],[1,1.67,76.1],[2,1.66,62.31]],"batl":[[1,1.87,20.77]],"ltp":2.46,"tv":148.56,"id":17151079}]}]}
{"op":"mcm","clk":"1001503925","pt":1580637152128,"mc":[{"id":"1.168224334","rc":[{"batb":[[0,6.2,64.99]],"batl":[[2,7.6,5.88]],"ltp":0.0,"tv":0.0,"id":13117429},{"batb":[[1,4.8,60.45]],"batl":[[1,5.8,20.6]],"ltp":0.0,"tv":0.0,"id":17151080},{"batl":[[0,1.75,67.35]],"ltp":2.46,"tv":148.56,"id":17151079}]}]}
{"op":"mcm","clk":"1001505231","pt":1580637175153,"mc":[{"id":"1.168224334","rc":[{"batb":[[0,6.2,22.24],[2,5.7,20.06]],"batl":[[0,7,17.15],[1,7,0],[2,7.6,0]],"ltp":0.0,"tv":0.0,"id":13117429},{"batb":[[0,9.4,15.58],[1,1.01,0.51],[2,12.5,0]],"batl":[[0,21,5.04],[1,21,0]],"ltp":0.0,"tv":0.0,"id":13117428},{"batb":[[0,4.8,14.48],[1,1.01,0.51],[2,4.7,0]],"batl":[[0,5.8,12.2],[1,5.8,0]],"ltp":0.0,"tv":0.0,"id":17151080},{"batb":[[0,1.63,29.03],[1,1.01,0.51],[2,1.66,0]],"batl":[[0,1.87,20.77],[1,1.87,0]],"ltp":2.46,"tv":148.56,"id":17151079}]}]}
{"op":"mcm","clk":"1001505866","pt":1580637185259,"mc":[{"id":"1.168224334","rc":[{"batb":[[0,11.5,33.18],[1,11,26.65],[2,9.4,15.58]],"ltp":0.0,"tv":0.0,"id":13117428},{"batb":[[1,4.6,58.44],[2,4.5,40.2]],"ltp":0.0,"tv":0.0,"id":17151080},{"batb":[[1,1.62,113.62],[2,1.61,69.64]],"ltp":2.46,"tv":148.56,"id":17151079}]}]}
{"op":"mcm","clk":"1001506534","pt":1580637197346,"mc":[{"id":"1.168224334","rc":[{"batb":[[1,5.7,20.06],[2,1.01,0.51]],"ltp":0.0,"tv":0.0,"id":13117429},{"batb":[[0,9.4,15.58],[1,1.01,0.51],[2,9.4,0]],"ltp":0.0,"tv":0.0,"id":13117428},{"batb":[[1,1.01,0.51],[2,4.5,0]],"ltp":0.0,"tv":0.0,"id":17151080}]}]}
{"op":"mcm","clk":"1001506691","pt":1580637200346,"mc":[{"id":"1.168224334","rc":[{"batb":[[0,6.4,34.12],[1,6.2,40.92],[2,5.7,20.06]],"ltp":0.0,"tv":0.0,"id":13117429},{"batb":[[0,19.5,9.58],[1,19,9.86],[2,9.4,15.58]],"ltp":0.0,"tv":0.0,"id":13117428},{"batb":[[0,4.9,24.71],[1,4.8,49.46],[2,1.01,0.51]],"ltp":0.0,"tv":0.0,"id":17151080}]}]}
{"op":"mcm","clk":"1001506748","pt":1580637201326,"mc":[{"id":"1.168224334","rc":[{"batb":[[0,6.4,22.97],[2,5.9,18.33]],"batl":[[0,7,16.52]],"ltp":0.0,"tv":0.0,"id":13117429},{"batb":[[0,19.5,6.29],[2,15,5.35]],"batl":[[1,28,6.45]],"ltp":0.0,"tv":0.0,"id":13117428},{"batb":[[0,5.1,12.67],[1,4.9,38.4],[2,4.8,34.98]],"batl":[[1,5.9,11.49]],"ltp":0.0,"tv":0.0,"id":17151080},{"batb":[[1,1.62,67.88],[2,1.58,32.26]],"batl":[[0,1.7,28.4],[1,1.79,23.68]],"ltp":2.46,"tv":148.56,"id":17151079}]}]}
{"op":"mcm","clk":"1001506799","pt":1580637202254,"mc":[{"id":"1.168224334","rc":[{"batb":[[1,6.2,48.48]],"batl":[[1,7.8,5.88]],"ltp":0.0,"tv":0.0,"id":13117429},{"batb":[[2,4.8,45.9]],"batl":[[1,5.9,19.89]],"ltp":0.0,"tv":0.0,"id":17151080},{"batl":[[0,1.7,70.41]],"ltp":2.46,"tv":148.56,"id":17151079}]}]}
{"op":"mcm","clk":"1001506871","pt":1580637203757,"mc":[{"id":"1.168224334","rc":[{"batb":[[0,1.63,97.06]],"ltp":2.46,"tv":148.56,"id":17151079}]}]}
{"op":"mcm","clk":"1001507434","pt":1580637215357,"mc":[{"id":"1.168224334","rc":[{"batb":[[0,6.2,36.99],[1,5.9,18.33],[2,5.7,20.06]],"ltp":0.0,"tv":0.0,"id":13117429},{"batb":[[0,15,5.35],[1,11.5,9.91],[2,1.01,0.51]],"ltp":0.0,"tv":0.0,"id":13117428},{"batb":[[1,4.9,13.69],[2,4.8,32.15]],"ltp":0.0,"tv":0.0,"id":17151080},{"batb":[[0,1.63,29.03],[1,1.58,32.26],[2,1.56,74.78]],"ltp":2.46,"tv":148.56,"id":17151079}]}]}
{"op":"mcm","clk":"1001507461","pt":1580637215769,"mc":[{"id":"1.168224334","rc":[{"batb":[[1,5.7,20.06],[2,1.01,0.51]],"ltp":0.0,"tv":0.0,"id":13117429},{"batb":[[0,11.5,9.91],[1,1.01,0.51],[2,1.01,0]],"batl":[[0,28,6.45],[1,28,0]],"ltp":0.0,"tv":0.0,"id":13117428},{"batb":[[0,4.9,13.69],[1,4.8,32.15],[2,1.01,0.51]],"batl":[[0,5.9,19.89],[1,5.9,0]],"ltp":0.0,"tv":0.0,"id":17151080},{"batb":[[0,1.58,32.26],[1,1.56,74.78],[2,1.01,0.51]],"batl":[[0,1.7,42.01]],"ltp":2.46,"tv":148.56,"id":17151079}]}]}
{"op":"mcm","clk":"1001507547","pt":1580637217160,"mc":[{"id":"1.168224334","rc":[{"batb":[[0,6.2,29.43]],"batl":[[1,7.8,0]],"ltp":0.0,"tv":0.0,"id":13117429},{"batb":[[1,4.8,21.23]],"batl":[[0,5.9,11.49]],"ltp":0.0,"tv":0.0,"id":17151080},{"batb":[[1,1.01,0.51],[2,1.01,0]],"batl":[[0,1.79,23.68],[1,1.79,0]],"ltp":2.46,"tv":148.56,"id":17151079}]}]}
{"op":"mcm","clk":"1001507618","pt":1580637218340,"mc":[{"id":"1.168224334","rc":[{"batb":[[1,6,43.89],[2,5.7,20.06]],"ltp":0.0,"tv":0.0,"id":13117429},{"batb":[[0,14.5,17.37],[1,14,18.12],[2,11.5,9.91]],"ltp":0.0,"tv":0.0,"id":13117428},{"batb":[[2,4.7,36.92]],"ltp":0.0,"tv":0.0,"id":17151080},{"batb":[[0,1.59,111.86],[1,1.58,106.83],[2,1.01,0.51]],"ltp":2.46,"tv":148.56,"id":17151079}]}]}
{"op":"mcm","clk":"1001508116","pt":1580637228278,"mc":[{"id":"1.168224334","rc":[{"batb":[[0,1.58,32.26],[1,1.01,0.51],[2,1.01,0]],"ltp":2.46,"tv":148.56,"id":17151079}]}]}
{"op":"mcm","clk":"1001508266","pt":1580637231367,"mc":[{"id":"1.168224334","rc":[{"batl":[[0,6.8,17.86],[1,7,16.52]],"ltp":0.0,"tv":0.0,"id":13117429},{"batl":[[0,15.5,9.13],[1,20,5.43],[2,28,6.45]],"ltp":0.0,"tv":0.0,"id":13117428},{"batb":[[2,4.7,52.11]],"batl":[[0,5.6,13.14],[1,5.7,12.43],[2,5.9,11.49]],"ltp":0.0,"tv":0.0,"id":17151080},{"batb":[[0,1.72,24.16],[1,1.7,60.8],[2,1.68,118.65]],"batl":[[1,1.93,18.65]],"ltp":2.46,"tv":148.56,"id":17151079}]}]}
{"op":"mcm","clk":"1001508298","pt":1580637232189,"mc":[{"id":"1.168224334","rc":[{"batb":[[1,6,52.29]],"batl":[[1,7.4,5.88]],"ltp":0.0,"tv":0.0,"id":13117429},{"batb":[[2,13,3.36]],"batl":[[2,28,0]],"ltp":0.0,"tv":0.0,"id":13117428},{"batb":[[2,4.7,63.03]],"batl":[[1,5.7,20.83],[2,5.9,0]],"ltp":0.0,"tv":0.0,"id":17151080},{"batl":[[0,1.77,42.01],[1,1.79,23.68],[2,1.93,18.65]],"ltp":2.46,"tv":148.56,"id":17151079}]}]}
{"op":"mcm","clk":"1001509017","pt":1580637245989,"mc":[{"id":"1.168224334","rc":[{"batb":[[0,6,52.29],[1,5.6,10.39],[2,1.01,0.51]],"ltp":0.0,"tv":0.0,"id":13117429},{"batb":[[0,13,3.36],[1,8.6,7.79],[2,1.01,0.51]],"batl":[[0,20,5.43],[1,20,0]],"ltp":0.0,"tv":0.0,"id":13117428},{"batb":[[0,4.7,26.11],[1,1.01,0.51],[2,4.7,0]],"batl":[[0,5.7,20.83],[1,5.7,0]],"ltp":0.0,"tv":0.0,"id":17151080},{"batb":[[0,1.65,27.93],[1,1.63,66.38],[2,1.01,0.51]],"batl":[[1,1.93,18.65],[2,1.93,0]],"ltp":2.46,"tv":148.56,"id":17151079}]}]}
{"op":"mcm","clk":"1001509092","pt":1580637247216,"mc":[{"id":"1.168224334","rc":[{"batb":[[0,6,43.89]],"batl":[[1,7.4,0]],"ltp":0.0,"tv":0.0,"id":13117429},{"batb":[[0,8.6,7.79],[1,1.01,0.51],[2,1.01,0]],"ltp":0.0,"tv":0.0,"id":13117428},{"batb":[[0,4.7,15.19]],"batl":[[0,5.7,12.43]],"ltp":0.0,"tv":0.0,"id":17151080},{"batb":[[1,1.01,0.51],[2,1.01,0]],"batl":[[0,1.93,18.65],[1,1.93,0]],"ltp":2.46,"tv":148.56,"id":17151079}]}]}
{"op":"mcm","clk":"1001509170","pt":1580637248914,"mc":[{"id":"1.168224334","rc":[{"batb":[[1,5.9,23.13]],"batl":[[0,7,16.84]],"ltp":0.0,"tv":0.0,"id":13117429},{"batb":[[0,10.5,11.29],[1,10,36.88],[2,8.8,7.4]],"batl":[[0,21,5.19]],"ltp":0.0,"tv":0.0,"id":13117428},{"batb":[[1,4.6,37.68],[2,4.5,40.69]],"ltp":0.0,"tv":0.0,"id":17151080},{"batb":[[0,1.64,109.95],[1,1.63,66.42],[2,1.01,0.51]],"batl":[[0,1.91,19.2]],"ltp":2.46,"tv":148.56,"id":17151079}]}]}
{"op":"mcm","clk":"1001509220","pt":1580637249791,"mc":[{"id":"1.168224334","rc":[{"batb":[[1,1.01,0.51],[2,1.01,0]],"ltp":0.0,"tv":0.0,"id":13117429},{"batb":[[0,8.8,7.4],[1,1.01,0.51],[2,8.8,0]],"ltp":0.0,"tv":0.0,"id":13117428},{"batb":[[2,1.01,0.51]],"ltp":0.0,"tv":0.0,"id":17151080},{"batb":[[0,1.64,28.64],[1,1.01,0.51],[2,1.01,0]],"ltp":2.46,"tv":148.56,"id":17151079}]}]}
{"op":"mcm","clk":"1001509463","pt":1580637253411,"mc":[{"id":"1.168224334","rc":[{"batb":[[0,6.2,22.32],[1,6,43.89],[2,1.01,0.51]],"ltp":0.0,"tv":0.0,"id":13117429},{"batb":[[0,13.5,15.24],[1,13,21.23],[2,8.8,7.4]],"ltp":0.0,"tv":0.0,"id":13117428},{"batb":[[0,4.7,61.84]],"ltp":0.0,"tv":0.0,"id":17151080},{"batb":[[0,1.72,71.09],[1,1.7,113.97],[2,1.64,28.64]],"ltp":2.46,"tv":148.56,"id":17151079}]}]}
{"op":"mcm","clk":"1001509522","pt":1580637254392,"mc":[{"id":"1.168224334","rc":[{"batb":[[0,6,43.89],[1,1.01,0.51],[2,1.01,0]],"ltp":0.0,"tv":0.0,"id":13117429},{"batb":[[0,8.8,7.4],[1,1.01,0.51],[2,8.8,0]],"ltp":0.0,"tv":0.0,"id":13117428},{"batb":[[0,4.7,15.19]],"ltp":0.0,"tv":0.0,"id":17151080},{"batb":[[0,1.64,28.64],[1,1.01,0.51],[2,1.64,0]],"ltp":2.46,"tv":148.56,"id":17151079}]}]}
{"op":"mcm","clk":"1001509660","pt":1580637257390,"mc":[{"id":"1.168224334","rc":[{"batb":[[1,5.9,23.13],[2,1.01,0.51]],"ltp":0.0,"tv":0.0,"id":13117429},{"batb":[[0,10.5,11.29],[1,10,36.88],[2,8.8,7.4]],"ltp":0.0,"tv":0.0,"id":13117428},{"batb":[[2,4.5,40.69]],"ltp":0.0,"tv":0.0,"id":17151080},{"batb":[[0,1.64,109.95],[1,1.63,66.42],[2,1.01,0.51]],"ltp":2.46,"tv":148.56,"id":17151079}]}]}
{"op":"mcm","clk":"1001510466","pt":1580637274930,"mc":[{"id":"1.168224334","rc":[{"batb":[[0,1.64,28.64],[1,1.01,0.51],[2,1.01,0]],"ltp":2.46,"tv":148.56,"id":17151079}]}]}
{"op":"mcm","clk":"1001510666","pt":1580637278330,"mc":[{"id":"1.168224334","rc":[{"batb":[[2,5.8,8.4]],"batl":[[1,7.4,5.88]],"ltp":0.0,"tv":0.0,"id":13117429},{"batb":[[1,10,41.08]],"batl":[[0,13.5,3.36],[1,21,5.19]],"ltp":0.0,"tv":0.0,"id":13117428},{"batb":[[2,4.5,52.45]],"batl":[[0,5.5,9.24],[1,5.7,12.43]],"ltp":0.0,"tv":0.0,"id":17151080},{"batb":[[0,1.81,88.02],[1,1.79,95.96],[2,1.71,58.81]],"batl":[[0,1.89,42.01],[1,1.91,19.2]],"ltp":2.46,"tv":148.56,"id":17151079}]}]}
{"op":"mcm","clk":"1001510718","pt":1580637279358,"mc":[{"id":"1.168224334","rc":[{"batl":[[0,6.8,18.02],[1,7.4,0]],"ltp":0.0,"tv":0.0,"id":13117429},{"batb":[[1,10,36.88]],"batl":[[0,11,7.08],[1,14.5,10.07]],"ltp":0.0,"tv":0.0,"id":13117428},{"batb":[[2,4.5,69.53]],"batl":[[0,5.3,14.79],[1,5.5,22.93]],"ltp":0.0,"tv":0.0,"id":17151080},{"batb":[[0,1.84,19.51],[1,1.81,88.02],[2,1.79,95.96]],"batl":[[2,2.14,27.77]],"ltp":2.46,"tv":148.56,"id":17151079}]}]}
{"op":"mcm","clk":"1001510809","pt":1580637281258,"mc":[{"id":"1.168224334","rc":[{"batl":[[1,7.2,6.72]],"ltp":0.0,"tv":0.0,"id":13117429},{"batb":[[2,9.8,4.2]],"batl":[[1,13,3.36],[2,14.5,10.07]],"ltp":0.0,"tv":0.0,"id":13117428}]}]}
{"op":"mcm","clk":"1001511649","pt":1580637298008,"mc":[{"id":"1.168224334","rc":[{"batb":[[0,5.9,23.13],[1,5.8,8.4],[2,5.6,10.39]],"ltp":0.0,"tv":0.0,"id":13117429},{"batb":[[0,9.8,4.2],[1,6.4,15.19],[2,1.01,0.51]],"batl":[[0,13,3.36],[1,14.5,10.07],[2,14.5,0]],"ltp":0.0,"tv":0.0,"id":13117428},{"batb":[[0,4.5,28.84],[1,1.01,0.51],[2,4.5,0]],"batl":[[0,5.5,22.93],[1,5.5,0]],"ltp":0.0,"tv":0.0,"id":17151080},{"batb":[[0,1.74,23.53],[1,1.72,57.97],[2,1.01,0.51]],"batl":[[1,2.14,27.77],[2,2.14,0]],"ltp":2.46,"tv":148.56,"id":17151079}]}]}
{"op":"mcm","clk":"1001511705","pt":1580637299299,"mc":[{"id":"1.168224334","rc":[{"batb":[[1,5.6,10.39],[2,1.01,0.51]],"batl":[[1,7.2,0]],"ltp":0.0,"tv":0.0,"id":13117429},{"batb":[[0,6.4,15.19],[1,1.01,0.51],[2,1.01,0]],"batl":[[0,14.5,10.07],[1,14.5,0]],"ltp":0.0,"tv":0.0,"id":13117428},{"batb":[[0,4.5,17.07]],"batl":[[0,5.5,13.69]],"ltp":0.0,"tv":0.0,"id":17151080},{"batb":[[1,1.01,0.51],[2,1.01,0]],"batl":[[0,2.14,27.77],[1,2.14,0]],"ltp":2.46,"tv":148.56,"id":17151079}]}]}
{"op":"mcm","clk":"1001511756","pt":1580637300380,"mc":[{"id":"1.168224334","rc":[{"batb":[[1,5.8,24.35],[2,5.6,10.39]],"ltp":0.0,"tv":0.0,"id":13117429},{"batb":[[0,7.2,42.76],[1,7,31.74],[2,6.4,15.19]],"ltp":0.0,"tv":0.0,"id":13117428},{"batb":[[1,4.4,41.36],[2,4.3,45.43]],"ltp":0.0,"tv":0.0,"id":17151080},{"batb":[[1,1.72,86.46],[2,1.7,114]],"ltp":2.46,"tv":148.56,"id":17151079}]}]}
{"op":"mcm","clk":"1001512165","pt":1580637307115,"mc":[{"id":"1.168224334","rc":[{"batb":[[1,1.01,0.51],[2,1.7,0]],"ltp":2.46,"tv":148.56,"id":17151079}]}]}
{"op":"mcm","clk":"1001512360","pt":1580637310415,"mc":[{"id":"1.168224334","rc":[{"batb":[[2,5.7,8.4]],"batl":[[0,6.6,19.04],[1,6.8,18.02],[2,7,6.72]],"ltp":0.0,"tv":0.0,"id":13117429},{"batb":[[0,7.2,49.48]],"batl":[[0,7.6,14.32],[1,9.2,14.4],[2,14.5,10.07]],"ltp":0.0,"tv":0.0,"id":13117428},{"batb":[[2,4.3,77.07]],"batl":[[0,5.1,16.29],[1,5.2,24.66],[2,5.5,13.69]],"ltp":0.0,"tv":0.0,"id":17151080},{"batb":[[0,2.02,28.56],[1,2,85.36],[2,1.98,69.89]],"batl":[[0,2.1,37.81],[1,2.14,27.77],[2,2.42,19.91]],"ltp":2.46,"tv":148.56,"id":17151079}]}]}
{"op":"mcm","clk":"1001512376","pt":1580637310628,"mc":[{"id":"1.168224334","rc":[{"batb":[[2,5.5,10.7]],"batl":[[1,7,6.72],[2,7,0]],"ltp":0.0,"tv":0.0,"id":13117429},{"batl":[[2,14.5,0]],"ltp":0.0,"tv":0.0,"id":13117428},{"batl":[[2,5.5,0]],"ltp":0.0,"tv":0.0,"id":17151080}]}]}
{"op":"mcm","clk":"1001512545","pt":1580637312804,"mc":[{"id":"1.168224334","rc":[{"batb":[[2,5.6,8.4]],"ltp":0.0,"tv":0.0,"id":13117429}]}]}
{"op":"mcm","clk":"1001513333","pt":1580637329320,"mc":[{"id":"1.168224334","rc":[{"batb":[[0,5.5,10.7],[1,1.01,0.51],[2,5.6,0]],"batl":[[1,7,0]],"ltp":0.0,"tv":0.0,"id":13117429},{"batb":[[0,5.1,12.9],[1,1.01,0.51],[2,6.4,0]],"batl":[[0,9.2,9.36],[1,9.2,0]],"ltp":0.0,"tv":0.0,"id":13117428},{"batb":[[0,4.3,19.04],[1,1.01,0.51],[2,4.3,0]],"batl":[[0,5.2,15.42],[1,5.2,0]],"ltp":0.0,"tv":0.0,"id":17151080},{"batb":[[0,1.91,17.23],[1,1.01,0.51],[2,1.98,0]],"batl":[[0,2.42,19.91],[1,2.14,0],[2,2.42,0]],"ltp":2.46,"tv":148.56,"id":17151079}]}]}
{"op":"mcm","clk":"1001513419","pt":1580637331332,"mc":[{"id":"1.168224334","rc":[{"batb":[[0,5.7,39.49],[1,5.6,25.96],[2,5.5,10.7]],"ltp":0.0,"tv":0.0,"id":13117429},{"batb":[[0,5.5,45.19],[1,5.4,28.29],[2,5.1,12.9]],"ltp":0.0,"tv":0.0,"id":13117428},{"batb":[[1,4.2,51.19],[2,4.1,50.32]],"ltp":0.0,"tv":0.0,"id":17151080},{"batb":[[1,1.88,91.71],[2,1.86,84.83]],"ltp":2.46,"tv":148.56,"id":17151079}]}]}
{"op":"mcm","clk":"1001513457","pt":1580637332110,"mc":[{"id":"1.168224334","rc":[{"batb":[[0,5.5,10.7],[1,1.01,0.51],[2,5.5,0]],"ltp":0.0,"tv":0.0,"id":13117429},{"batb":[[0,5.1,12.9],[1,1.01,0.51],[2,5.1,0]],"ltp":0.0,"tv":0.0,"id":13117428},{"batb":[[1,1.01,0.51],[2,4.1,0]],"ltp":0.0,"tv":0.0,"id":17151080},{"batb":[[1,1.01,0.51],[2,1.86,0]],"ltp":2.46,"tv":148.56,"id":17151079}]}]}
{"op":"mcm","clk":"1001513639","pt":1580637335824,"mc":[{"id":"1.168224334","rc":[{"batb":[[0,5.9,18.16],[1,5.8,24.48],[2,5.5,10.7]],"ltp":0.0,"tv":0.0,"id":13117429},{"batb":[[0,6.8,40.47],[1,6.6,36.17],[2,5.1,12.9]],"ltp":0.0,"tv":0.0,"id":13117428},{"batb":[[0,4.4,24.73],[1,4.3,64.82],[2,1.01,0.51]],"ltp":0.0,"tv":0.0,"id":17151080},{"batb":[[0,2.04,100.97],[1,2.02,65.79],[2,1.91,17.23]],"ltp":2.46,"tv":148.56,"id":17151079}]}]}
{"op":"mcm","clk":"1001513680","pt":1580637336548,"mc":[{"id":"1.168224334","rc":[{"batb":[[0,5.5,10.7],[1,1.01,0.51],[2,5.5,0]],"ltp":0.0,"tv":0.0,"id":13117429},{"batb":[[0,5.1,12.9],[1,1.01,0.51],[2,5.1,0]],"ltp":0.0,"tv":0.0,"id":13117428},{"batb":[[0,4.3,19.04],[1,1.01,0.51],[2,1.01,0]],"ltp":0.0,"tv":0.0,"id":17151080},{"batb":[[0,1.91,17.23],[1,1.01,0.51],[2,1.91,0]],"ltp":2.46,"tv":148.56,"id":17151079}]}]}
{"op":"mcm","clk":"1001513853","pt":1580637340351,"mc":[{"id":"1.168224334","rc":[{"batb":[[0,5.7,39.49],[1,5.6,25.96],[2,5.5,10.7]],"ltp":0.0,"tv":0.0,"id":13117429},{"batb":[[0,5.5,45.19],[1,5.4,28.29],[2,5.1,12.9]],"ltp":0.0,"tv":0.0,"id":13117428},{"batb":[[1,4.2,51.19],[2,4.1,50.32]],"ltp":0.0,"tv":0.0,"id":17151080},{"batb":[[1,1.88,91.71],[2,1.86,84.83]],"ltp":2.46,"tv":148.56,"id":17151079}]}]}
{"op":"mcm","clk":"1001514383","pt":1580637351169,"mc":[{"id":"1.168224334","rc":[{"batb":[[1,1.01,0.51],[2,1.86,0]],"ltp":2.46,"tv":148.56,"id":17151079}]}]}
{"op":"mcm","clk":"1001514545","pt":1580637354271,"mc":[{"id":"1.168224334","rc":[{"batl":[[0,6.4,7.56],[1,6.6,19.04]],"ltp":0.0,"tv":0.0,"id":13117429},{"batb":[[2,5.3,9.24]],"batl":[[0,6.4,7.56],[1,9.2,9.36]],"ltp":0.0,"tv":0.0,"id":13117428},{"batl":[[0,4.8,10.92],[1,5.2,15.42]],"ltp":0.0,"tv":0.0,"id":17151080},{"batb":[[0,2.26,56.76],[1,2.24,48.8],[2,2.2,34.45]],"batl":[[1,2.48,27.73]],"ltp":2.46,"tv":148.56,"id":17151079}]}]}
{"op":"mcm","clk":"1001514574","pt":1580637354790,"mc":[{"id":"1.168224334","rc":[{"batl":[[0,6.4,17.87]],"ltp":0.0,"tv":0.0,"id":13117429},{"batb":[[2,5.2,9.24]],"batl":[[0,5.8,12.43],[1,6.4,7.56],[2,7.2,15.97]],"ltp":0.0,"tv":0.0,"id":13117428},{"batb":[[1,4.2,71.02],[2,4.1,63.76]],"batl":[[1,5,16.68]],"ltp":0.0,"tv":0.0,"id":17151080},{"batb":[[0,2.28,20.38],[1,2.26,56.76],[2,2.24,48.8]],"batl":[[1,2.5,27.73],[2,2.6,16.44]],"ltp":2.46,"tv":148.56,"id":17151079}]}]}
{"op":"mcm","clk":"1001520759","pt":1580637447317,"mc":[{"id":"1.168224334","rc":[{"batb":[[0,5.6,25.96],[1,5.5,10.7],[2,1.01,0.51]],"batl":[[0,6.6,19.04],[1,6.6,0]],"ltp":0.0,"tv":0.0,"id":13117429},{"batb":[[0,4.5,17.15],[1,1.01,0.51],[2,5.2,0]],"batl":[[0,7.2,15.97],[1,6.4,0],[2,7.2,0]],"ltp":0.0,"tv":0.0,"id":13117428},{"batb":[[0,4.2,19.83],[1,4.1,50.32],[2,1.01,0.51]],"batl":[[0,5,16.68],[1,5,0]],"ltp":0.0,"tv":0.0,"id":17151080},{"batb":[[0,2.08,26.75],[1,1.01,0.51],[2,2.24,0]],"batl":[[0,2.6,16.44],[1,2.5,0],[2,2.6,0]],"ltp":2.46,"tv":148.56,"id":17151079}]}]}
{"op":"mcm","clk":"1001521001","pt":1580637450311,"mc":[{"id":"1.168224334","rc":[{"batb":[[0,5.6,42.83],[1,5.5,37.98]],"ltp":0.0,"tv":0.0,"id":13117429},{"batb":[[0,5,24.23],[1,4.9,35.9],[2,4.5,17.15]],"ltp":0.0,"tv":0.0,"id":13117428},{"batb":[[1,4.1,66.23],[2,4,53.82]],"ltp":0.0,"tv":0.0,"id":17151080},{"batb":[[1,2.06,111.76],[2,2.04,64.1]],"ltp":2.46,"tv":148.56,"id":17151079}]}]}
{"op":"mcm","clk":"1001521022","pt":1580637450516,"mc":[{"id":"1.168224334","rc":[{"batb":[[0,5.6,26.18],[1,5.5,10.7]],"ltp":0.0,"tv":0.0,"id":13117429},{"batb":[[0,4.5,17.15],[1,1.01,0.51],[2,4.5,0]],"ltp":0.0,"tv":0.0,"id":13117428},{"batb":[[1,4.1,50.69],[2,1.01,0.51]],"ltp":0.0,"tv":0.0,"id":17151080},{"batb":[[1,1.01,0.51],[2,2.04,0]],"ltp":2.46,"tv":148.56,"id":17151079}]}]}
{"op":"mcm","clk":"1001521239","pt":1580637452886,"mc":[{"id":"1.168224334","rc":[{"batb":[[0,5.7,42.12],[1,5.6,26.18],[2,5.5,10.7]],"ltp":0.0,"tv":0.0,"id":13117429},{"batb":[[0,5.7,38.35],[1,5.6,26.44],[2,4.5,17.15]],"ltp":0.0,"tv":0.0,"id":13117428},{"batb":[[0,4.2,86.37]],"ltp":0.0,"tv":0.0,"id":17151080},{"batb":[[0,2.22,64.67],[1,2.2,51.39],[2,2.08,26.75]],"ltp":2.46,"tv":148.56,"id":17151079}]}]}
{"op":"mcm","clk":"1001521521","pt":1580637457206,"mc":[{"id":"1.168224334","rc":[{"batb":[[0,5.6,26.18],[1,5.5,10.7],[2,1.01,0.51]],"ltp":0.0,"tv":0.0,"id":13117429},{"batb":[[0,4.5,17.15],[1,1.01,0.51],[2,4.5,0]],"ltp":0.0,"tv":0.0,"id":13117428},{"batb":[[0,4.2,19.83]],"ltp":0.0,"tv":0.0,"id":17151080},{"batb":[[0,2.08,26.75],[1,1.01,0.51],[2,2.08,0]],"ltp":2.46,"tv":148.56,"id":17151079}]}]}
{"op":"mcm","clk":"1001521734","pt":1580637460336,"mc":[{"id":"1.168224334","rc":[{"batb":[[0,5.6,42.83],[1,5.5,37.98]],"ltp":0.0,"tv":0.0,"id":13117429},{"batb":[[0,5,24.23],[1,4.9,35.9],[2,4.5,17.15]],"ltp":0.0,"tv":0.0,"id":13117428},{"batb":[[1,4.1,66.23],[2,4,53.82]],"ltp":0.0,"tv":0.0,"id":17151080},{"batb":[[1,2.06,111.76],[2,2.04,64.1]],"ltp":2.46,"tv":148.56,"id":17151079}]}]}
{"op":"mcm","clk":"1001521943","pt":1580637462815,"mc":[{"id":"1.168224334","rc":[{"batb":[[0,5.6,26.18],[1,5.5,10.7]],"ltp":0.0,"tv":0.0,"id":13117429},{"batb":[[0,4.5,17.15],[1,1.01,0.51],[2,4.5,0]],"ltp":0.0,"tv":0.0,"id":13117428},{"batb":[[1,4.1,50.69],[2,1.01,0.51]],"ltp":0.0,"tv":0.0,"id":17151080},{"batb":[[1,1.01,0.51],[2,2.04,0]],"ltp":2.46,"tv":148.56,"id":17151079}]}]}
{"op":"mcm","clk":"1001522173","pt":1580637466326,"mc":[{"id":"1.168224334","rc":[{"batb":[[0,5.6,42.83],[1,5.5,37.98],[2,5.1,10.08]],"batl":[[0,6.2,7.56],[1,6.6,19.04]],"ltp":0.0,"tv":0.0,"id":13117429},{"batb":[[0,5,24.23],[1,4.9,35.9],[2,4.7,10.92]],"batl":[[0,5.8,8.4],[1,7.2,15.97]],"ltp":0.0,"tv":0.0,"id":13117428},{"batb":[[1,4.1,66.23],[2,4,67.26]],"batl":[[0,4.8,10.92],[1,5,16.68]],"ltp":0.0,"tv":0.0,"id":17151080},{"batb":[[0,2.4,73.65],[1,2.36,83.49],[2,2.34,31.09]],"batl":[[1,2.64,25.21]],"ltp":2.46,"tv":148.56,"id":17151079}]}]}
{"op":"mcm","clk":"1001522196","pt":1580637466840,"mc":[{"id":"1.168224334","rc":[{"batb":[[2,5.4,11.09]],"batl":[[1,6.4,20.3]],"ltp":0.0,"tv":0.0,"id":13117429},{"batl":[[0,5.1,16.37],[1,5.8,8.4],[2,5.9,11.64]],"ltp":0.0,"tv":0.0,"id":13117428},{"batb":[[1,4.1,87]],"batl":[[0,4.8,29.81],[1,4.9,17.94]],"ltp":0.0,"tv":0.0,"id":17151080},{"batb":[[0,2.44,16.84],[1,2.4,73.65],[2,2.36,83.49]],"batl":[[2,2.78,13.85]],"ltp":2.46,"tv":148.56,"id":17151079}]}]}
{"op":"mcm","clk":"1001522780","pt":1580637476328,"mc":[{"id":"1.168224334","rc":[{"batb":[[0,5.6,25.96],[1,5.5,27.28]],"ltp":0.0,"tv":0.0,"id":13117429},{"batb":[[0,4.7,10.92],[1,4.1,21.17],[2,1.01,0.51]],"batl":[[0,5.8,8.4],[1,5.9,11.64],[2,5.9,0]],"ltp":0.0,"tv":0.0,"id":13117428},{"batb":[[0,4.1,55.22],[1,4,67.26],[2,1.01,0.51]],"batl":[[0,4.8,10.92]],"ltp":0.0,"tv":0.0,"id":17151080},{"batb":[[0,2.34,31.09],[1,2.24,21.4],[2,1.01,0.51]],"batl":[[0,2.64,25.21],[1,2.78,13.85],[2,2.78,0]],"ltp":2.46,"tv":148.56,"id":17151079}]}]}
{"op":"mcm","clk":"1001522838","pt":1580637477353,"mc":[{"id":"1.168224334","rc":[{"batl":[[0,6.4,20.3],[1,6.4,0]],"ltp":0.0,"tv":0.0,"id":13117429},{"batb":[[0,4.1,21.17],[1,1.01,0.51],[2,1.01,0]],"batl":[[0,5.9,11.64],[1,5.9,0]],"ltp":0.0,"tv":0.0,"id":13117428},{"batb":[[1,4,53.82]],"batl":[[0,4.9,17.94],[1,4.9,0]],"ltp":0.0,"tv":0.0,"id":17151080},{"batb":[[0,2.24,21.4],[1,1.01,0.51],[2,1.01,0]],"batl":[[0,2.78,13.85],[1,2.78,0]],"ltp":2.46,"tv":148.56,"id":17151079}]}]}
{"op":"mcm","clk":"1001522962","pt":1580637479336,"mc":[{"id":"1.168224334","rc":[{"batb":[[0,4.6,27.53],[1,4.5,43.49],[2,4.1,21.17]],"ltp":0.0,"tv":0.0,"id":13117428},{"batb":[[1,2.22,75.27],[2,2.2,51.37]],"ltp":2.46,"tv":148.56,"id":17151079}]}]}
{"op":"mcm","clk":"1001523056","pt":1580637480933,"mc":[{"id":"1.168224334","rc":[{"batb":[[1,5.4,11.09],[2,1.01,0.51]],"ltp":0.0,"tv":0.0,"id":13117429},{"batb":[[0,4.1,21.17],[1,1.01,0.51],[2,4.1,0]],"ltp":0.0,"tv":0.0,"id":13117428},{"batb":[[1,1.01,0.51],[2,2.2,0]],"ltp":2.46,"tv":148.56,"id":17151079}]}]}
{"op":"mcm","clk":"1001523260","pt":1580637484142,"mc":[{"id":"1.168224334","rc":[{"batb":[[0,5.7,21.39],[1,5.6,25.96],[2,5.4,11.09]],"ltp":0.0,"tv":0.0,"id":13117429},{"batb":[[0,5.1,35.07],[1,5,34.14],[2,4.1,21.17]],"ltp":0.0,"tv":0.0,"id":13117428},{"batb":[[0,4.1,96.62]],"ltp":0.0,"tv":0.0,"id":17151080},{"batb":[[0,2.36,77.57],[1,2.32,87.54],[2,2.24,21.4]],"ltp":2.46,"tv":148.56,"id":17151079}]}]}
{"op":"mcm","clk":"1001523432","pt":1580637487378,"mc":[{"id":"1.168224334","rc":[{"batb":[[0,5.6,25.96],[1,5.4,11.09],[2,1.01,0.51]],"ltp":0.0,"tv":0.0,"id":13117429},{"batb":[[0,4.1,21.17],[1,1.01,0.51],[2,4.1,0]],"ltp":0.0,"tv":0.0,"id":13117428},{"batb":[[0,4.1,55.22]],"ltp":0.0,"tv":0.0,"id":17151080},{"batb":[[0,2.24,21.4],[1,1.01,0.51],[2,2.24,0]],"ltp":2.46,"tv":148.56,"id":17151079}]}]}
{"op":"mcm","clk":"1001523587","pt":1580637490169,"mc":[{"id":"1.168224334","rc":[{"batb":[[1,5.5,27.55],[2,5.4,11.09]],"ltp":0.0,"tv":0.0,"id":13117429},{"batb":[[0,4.6,27.53],[1,4.5,43.49],[2,4.1,21.17]],"ltp":0.0,"tv":0.0,"id":13117428},{"batb":[[1,2.22,75.27],[2,2.2,51.37]],"ltp":2.46,"tv":148.56,"id":17151079}]}]}
{"op":"mcm","clk":"1001523643","pt":1580637490982,"mc":[{"id":"1.168224334","rc":[{"batb":[[1,1.01,0.51],[2,2.2,0]],"ltp":2.46,"tv":148.56,"id":17151079}]}]}
{"op":"mcm","clk":"1001523827","pt":1580637494377,"mc":[{"id":"1.168224334","rc":[{"batb":[[0,5.5,27.55],[1,5.4,11.09],[2,5,10.08]],"batl":[[0,6.2,7.56],[1,6.4,20.3]],"ltp":0.0,"tv":0.0,"id":13117429},{"batb":[[0,4.5,43.49],[1,4.4,11.76]],"batl":[[0,4.6,20.06],[1,5.2,15.82],[2,5.4,9.24]],"ltp":0.0,"tv":0.0,"id":13117428},{"batb":[[1,4,67.26]],"batl":[[0,4.7,29.96],[1,4.9,17.94]],"ltp":0.0,"tv":0.0,"id":17151080},{"batb":[[0,2.62,14.08],[1,2.44,45.72],[2,2.24,21.4]],"batl":[[0,2.78,37.37],[1,2.94,11.88]],"ltp":2.46,"tv":148.56,"id":17151079}]}]}
{"op":"mcm","clk":"1001523828","pt":1580637494478,"mc":[{"id":"1.168224334","rc":[{"batl":[[1,6.4,10.31]],"ltp":0.0,"tv":0.0,"id":13117429},{"batl":[[1,4.9,0]],"ltp":0.0,"tv":0.0,"id":17151080},{"batb":[[2,1.01,0.51]],"ltp":2.46,"tv":148.56,"id":17151079}]}]}
{"op":"mcm","clk":"1001523927","pt":1580637496792,"mc":[{"id":"1.168224334","rc":[{"batb":[[1,5.4,39.4]],"ltp":0.0,"tv":0.0,"id":13117429},{"batb":[[1,4.4,56.84]],"ltp":0.0,"tv":0.0,"id":13117428},{"batb":[[0,4.1,73.57]],"ltp":0.0,"tv":0.0,"id":17151080},{"batb":[[1,2.56,67.8],[2,2.52,70.09]],"ltp":2.46,"tv":148.56,"id":17151079}]}]}
{"op":"mcm","clk":"1001524650","pt":1580637510385,"mc":[{"id":"1.168224334","rc":[{"batb":[[0,5.4,39.4],[1,5,10.08],[2,1.01,0.51]],"ltp":0.0,"tv":0.0,"id":13117429},{"batb":[[0,4.4,11.76],[1,4.1,21.17],[2,3.85,24.86]],"ltp":0.0,"tv":0.0,"id":13117428},{"batb":[[0,4.1,55.22]],"ltp":0.0,"tv":0.0,"id":17151080},{"batb":[[1,2.44,45.72],[2,1.01,0.51]],"ltp":2.46,"tv":148.56,"id":17151079}]}]}
{"op":"mcm","clk":"1001524718","pt":1580637511266,"mc":[{"id":"1.168224334","rc":[{"batb":[[1,1.01,0.51],[2,1.01,0]],"batl":[[0,6.4,10.31],[1,6.4,0]],"ltp":0.0,"tv":0.0,"id":13117429},{"batb":[[0,3.85,24.86],[1,1.01,0.51],[2,3.85,0]],"batl":[[0,5.2,15.82],[1,5.2,0],[2,5.4,0]],"ltp":0.0,"tv":0.0,"id":13117428},{"batb":[[1,4,53.82]],"batl":[[0,4.7,19.04]],"ltp":0.0,"tv":0.0,"id":17151080},{"batb":[[0,2.44,17.15],[1,1.01,0.51],[2,1.01,0]],"batl":[[0,2.94,11.88],[1,2.94,0]],"ltp":2.46,"tv":148.56,"id":17151079}]}]}
{"op":"mcm","clk":"1001524843","pt":1580637513376,"mc":[{"id":"1.168224334","rc":[{"batb":[[0,5.4,56.79],[1,5.3,29.33],[2,1.01,0.51]],"ltp":0.0,"tv":0.0,"id":13117429},{"batb":[[0,4.3,26.61],[1,4.2,50.5],[2,3.85,24.86]],"ltp":0.0,"tv":0.0,"id":13117428},{"batb":[[1,2.42,45.53],[2,2.38,82.04]],"ltp":2.46,"tv":148.56,"id":17151079}]}]}
{"op":"mcm","clk":"1001524874","pt":1580637514099,"mc":[{"id":"1.168224334","rc":[{"batb":[[0,5.4,39.4],[1,1.01,0.51],[2,1.01,0]],"ltp":0.0,"tv":0.0,"id":13117429},{"batb":[[0,3.85,24.86],[1,1.01,0.51],[2,3.85,0]],"ltp":0.0,"tv":0.0,"id":13117428},{"batb":[[1,1.01,0.51],[2,2.38,0]],"ltp":2.46,"tv":148.56,"id":17151079}]}]}
{"op":"mcm","clk":"1001525081","pt":1580637517500,"mc":[{"id":"1.168224334","rc":[{"batb":[[0,5.5,36.46],[1,5.4,39.4],[2,1.01,0.51]],"ltp":0.0,"tv":0.0,"id":13117429},{"batb":[[0,4.6,35.35],[1,4.5,42.96],[2,3.85,24.86]],"ltp":0.0,"tv":0.0,"id":13117428},{"batb":[[0,4.1,79.34]],"ltp":0.0,"tv":0.0,"id":17151080},{"batb":[[0,2.54,46.95],[1,2.5,71.74],[2,2.44,17.15]],"ltp":2.46,"tv":148.56,"id":17151079}]}]}
{"op":"mcm","clk":"1001525215","pt":1580637520075,"mc":[{"id":"1.168224334","rc":[{"batb":[[0,5.4,39.4],[1,1.01,0.51],[2,1.01,0]],"ltp":0.0,"tv":0.0,"id":13117429},{"batb":[[0,3.85,24.86],[1,1.01,0.51],[2,3.85,0]],"ltp":0.0,"tv":0.0,"id":13117428},{"batb":[[0,4.1,55.22]],"ltp":0.0,"tv":0.0,"id":17151080},{"batb":[[0,2.44,17.15],[1,1.01,0.51],[2,2.44,0]],"ltp":2.46,"tv":148.56,"id":17151079}]}]}
{"op":"mcm","clk":"1001525388","pt":1580637523002,"mc":[{"id":"1.168224334","rc":[{"batb":[[0,5.4,56.79],[1,5.3,29.33],[2,1.01,0.51]],"ltp":0.0,"tv":0.0,"id":13117429},{"batb":[[0,4.3,26.61],[1,4.2,50.5],[2,3.85,24.86]],"ltp":0.0,"tv":0.0,"id":13117428},{"batb":[[1,2.42,45.53],[2,2.38,82.04]],"ltp":2.46,"tv":148.56,"id":17151079}]}]}
{"op":"mcm","clk":"1001525543","pt":1580637525125,"mc":[{"id":"1.168224334","rc":[{"batb":[[0,5.4,11.09],[1,1.01,0.51],[2,1.01,0]],"ltp":0.0,"tv":0.0,"id":13117429},{"batb":[[0,3.85,24.86],[1,1.01,0.51],[2,3.85,0]],"ltp":0.0,"tv":0.0,"id":13117428},{"batb":[[1,1.01,0.51],[2,1.01,0]],"ltp":0.0,"tv":0.0,"id":17151080}]}]}
{"op":"mcm","clk":"1001525745","pt":1580637528322,"mc":[{"id":"1.168224334","rc":[{"batb":[[0,5.6,27.26],[1,5.5,38.24],[2,5.4,11.09]],"batl":[[0,6.2,7.56],[1,6.4,10.31]],"ltp":0.0,"tv":0.0,"id":13117429},{"batb":[[0,4.9,51.41],[1,4.8,47.75],[2,4.6,16.6]],"batl":[[1,5.8,8.4],[2,6.2,10.78]],"ltp":0.0,"tv":0.0,"id":13117428},{"batb":[[0,4.2,49.35],[1,4.1,72.54],[2,4,13.44]],"batl":[[1,4.8,10.92],[2,4.9,17.78]],"ltp":0.0,"tv":0.0,"id":17151080},{"batl":[[0,2.58,16.76],[1,2.66,25.21],[2,2.78,13.61]],"ltp":2.46,"tv":148.56,"id":17151079}]}]}
{"op":"mcm","clk":"1001525763","pt":1580637528685,"mc":[{"id":"1.168224334","rc":[{"batb":[[2,5.1,10.08]],"ltp":0.0,"tv":0.0,"id":13117429}]}]}
{"op":"mcm","clk":"1001526826","pt":1580637546216,"mc":[{"id":"1.168224334","rc":[{"batb":[[0,5.5,38.24],[1,5.1,10.08],[2,1.01,0.51]],"ltp":0.0,"tv":0.0,"id":13117429},{"batb":[[0,4.8,10.92],[1,4.1,21.09],[2,1.01,0.51]],"batl":[[0,5.8,8.4],[1,6.2,10.78],[2,6.2,0]],"ltp":0.0,"tv":0.0,"id":13117428},{"batb":[[0,4.1,72.54],[1,4,13.44],[2,1.01,0.51]],"batl":[[0,4.8,10.92],[1,4.9,17.78],[2,4.9,0]],"ltp":0.0,"tv":0.0,"id":17151080},{"batb":[[0,2.34,31.09],[1,2.2,22.42],[2,1.01,0.51]],"batl":[[0,2.66,25.21],[1,2.78,13.61],[2,2.78,0]],"ltp":2.46,"tv":148.56,"id":17151079}]}]}
{"op":"mcm","clk":"1001526895","pt":1580637547714,"mc":[{"id":"1.168224334","rc":[{"batb":[[1,1.01,0.51],[2,1.01,0]],"batl":[[0,6.4,10.31],[1,6.4,0]],"ltp":0.0,"tv":0.0,"id":13117429},{"batb":[[0,4.1,21.09],[1,1.01,0.51],[2,1.01,0]],"batl":[[0,6.2,10.78],[1,6.2,0]],"ltp":0.0,"tv":0.0,"id":13117428},{"batb":[[1,1.01,0.51],[2,1.01,0]],"batl":[[0,4.9,17.78],[1,4.9,0]],"ltp":0.0,"tv":0.0,"id":17151080},{"batb":[[0,2.2,22.42],[1,1.01,0.51],[2,1.01,0]],"batl":[[0,2.78,13.61],[1,2.78,0]],"ltp":2.46,"tv":148.56,"id":17151079}]}]}
{"op":"mcm","clk":"1001526973","pt":1580637549102,"mc":[{"id":"1.168224334","rc":[{"batb":[[0,5.5,47.09],[1,5.4,28.25],[2,1.01,0.51]],"ltp":0.0,"tv":0.0,"id":13117429},{"batb":[[0,4.5,35.05],[1,4.4,45.24],[2,4.1,21.09]],"ltp":0.0,"tv":0.0,"id":13117428},{"batb":[[1,4,54.63],[2,1.01,0.51]],"ltp":0.0,"tv":0.0,"id":17151080},{"batb":[[0,2.2,97.21],[1,2.18,52.93],[2,1.01,0.51]],"ltp":2.46,"tv":148.56,"id":17151079}]}]}
{"op":"mcm","clk":"1001527492","pt":1580637558129,"mc":[{"id":"1.168224334","rc":[{"batb":[[0,2.2,22.42],[1,1.01,0.51],[2,1.01,0]],"ltp":2.46,"tv":148.56,"id":17151079}]}]}
{"op":"mcm","clk":"1001527648","pt":1580637561130,"mc":[{"id":"1.168224334","rc":[{"batb":[[0,2.58,50.75],[1,2.54,68.72],[2,2.2,22.42]],"ltp":2.46,"tv":148.56,"id":17151079}]}]}
{"op":"mcm","clk":"1001527745","pt":1580637562369,"mc":[{"id":"1.168224334","rc":[{"batb":[[0,5.5,36.07],[1,5.4,39.66],[2,5.1,10.08]],"batl":[[0,6.2,7.56],[1,6.4,10.31]],"ltp":0.0,"tv":0.0,"id":13117429},{"batb":[[0,4.5,46.81]],"batl":[[0,4.6,19.99],[1,5.2,15.74],[2,5.4,9.24]],"ltp":0.0,"tv":0.0,"id":13117428},{"batb":[[2,3.95,13.44]],"batl":[[0,4.7,30.28]],"ltp":0.0,"tv":0.0,"id":17151080},{"batb":[[0,2.64,13.93],[1,2.58,50.75],[2,2.54,68.72]],"batl":[[0,2.78,37.14],[1,2.96,11.8]],"ltp":2.46,"tv":148.56,"id":17151079}]}]}
{"op":"mcm","clk":"1001529265","pt":1580637582381,"mc":[{"id":"1.168224334","rc":[{"batb":[[0,5.4,11.41],[1,5.1,10.08],[2,1.01,0.51]],"ltp":0.0,"tv":0.0,"id":13117429},{"batb":[[0,4.5,11.76],[1,4.1,21.09],[2,3.9,24.78]],"ltp":0.0,"tv":0.0,"id":13117428},{"batb":[[0,4.1,20.77],[1,3.95,13.44],[2,1.01,0.51]],"ltp":0.0,"tv":0.0,"id":17151080},{"batb":[[1,2.46,28.57],[2,2.44,17]],"ltp":2.46,"tv":148.56,"id":17151079}]}]}
{"op":"mcm","clk":"1001529346","pt":1580637583359,"mc":[{"id":"1.168224334","rc":[{"batb":[[1,3.9,24.78],[2,1.01,0.51]],"batl":[[0,5.2,15.74],[1,5.4,9.24],[2,5.4,0]],"ltp":0.0,"tv":0.0,"id":13117428},{"batb":[[0,2.46,28.57],[1,2.44,17],[2,1.01,0.51]],"batl":[[0,2.78,23.53]],"ltp":2.46,"tv":148.56,"id":17151079}]}]}
{"op":"mcm","clk":"1001529353","pt":1580637583464,"mc":[{"id":"1.168224334","rc":[{"batb":[[1,1.01,0.51],[2,1.01,0]],"batl":[[0,6.4,10.31],[1,6.4,0]],"ltp":0.0,"tv":0.0,"id":13117429},{"batb":[[0,3.9,24.78],[1,1.01,0.51],[2,1.01,0]],"batl":[[1,5.4,0]],"ltp":0.0,"tv":0.0,"id":13117428},{"batb":[[1,1.01,0.51],[2,1.01,0]],"batl":[[0,4.7,19.36]],"ltp":0.0,"tv":0.0,"id":17151080},{"batb":[[0,2.44,17],[1,1.01,0.51],[2,1.01,0]],"batl":[[0,2.96,11.8],[1,2.96,0]],"ltp":2.46,"tv":148.56,"id":17151079}]}]}
{"op":"mcm","clk":"1001529546","pt":1580637585984,"mc":[{"id":"1.168224334","rc":[{"batb":[[0,5.5,20.85],[1,5.4,39.89],[2,1.01,0.51]],"ltp":0.0,"tv":0.0,"id":13117429},{"batb":[[0,4.2,72.38],[1,4.1,52.62],[2,3.9,24.63]],"ltp":0.0,"tv":0.0,"id":13117428},{"batb":[[0,4.1,46.86],[1,4,54.98],[2,1.01,0.51]],"ltp":0.0,"tv":0.0,"id":17151080},{"batb":[[1,2.42,75.86],[2,2.38,81.86]],"batl":[[0,2.94,11.88]],"ltp":2.46,"tv":148.56,"id":17151079}]}]}
{"op":"mcm","clk":"1001529629","pt":1580637587070,"mc":[{"id":"1.168224334","rc":[{"batb":[[1,1.01,0.51],[2,2.38,0]],"ltp":2.46,"tv":148.56,"id":17151079}]}]}
{"op":"mcm","clk":"1001529837","pt":1580637590374,"mc":[{"id":"1.168224334","rc":[{"batb":[[2,4.9,10.08]],"batl":[[0,6,8.4],[1,6.4,10.31]],"ltp":0.0,"tv":0.0,"id":13117429},{"batb":[[0,4.2,84.98]],"batl":[[0,5,10.08],[1,5.2,15.74]],"ltp":0.0,"tv":0.0,"id":13117428},{"batb":[[2,3.95,13.44]],"batl":[[0,4.7,30.28]],"ltp":0.0,"tv":0.0,"id":17151080},{"batb":[[0,2.68,61.7],[1,2.64,61.94],[2,2.58,26.05]],"batl":[[0,2.94,32.89]],"ltp":2.46,"tv":148.56,"id":17151079}]}]}
{"op":"mcm","clk":"1001529894","pt":1580637591301,"mc":[{"id":"1.168224334","rc":[{"batl":[[1,6.2,10.7]],"ltp":0.0,"tv":0.0,"id":13117429},{"batl":[[0,4.3,23.29],[1,4.9,17.94],[2,5,10.08]],"ltp":0.0,"tv":0.0,"id":13117428},{"batb":[[0,4.1,26.09],[2,3.95,37.13]],"batl":[[0,4.6,19.91],[1,4.7,10.92]],"ltp":0.0,"tv":0.0,"id":17151080},{"batb":[[0,2.78,12.04],[1,2.68,61.7],[2,2.64,61.94]],"batl":[[1,3.45,20.3]],"ltp":2.46,"tv":148.56,"id":17151079}]}]}
{"op":"mcm","clk":"1001531583","pt":1580637612216,"mc":[{"id":"1.168224334","rc":[{"batb":[[0,5.4,39.89],[1,4.9,10.08],[2,1.01,0.51]],"ltp":0.0,"tv":0.0,"id":13117429},{"batb":[[0,4.2,12.6],[1,3.35,17.47],[2,1.01,0.51]],"batl":[[0,4.9,17.94],[1,5,10.08],[2,5,0]],"ltp":0.0,"tv":0.0,"id":13117428},{"batb":[[0,3.95,37.13],[1,1.01,0.51],[2,3.95,0]],"ltp":0.0,"tv":0.0,"id":17151080},{"batb":[[0,2.58,26.05],[1,2.56,15.11],[2,1.01,0.51]],"batl":[[0,2.94,21]],"ltp":2.46,"tv":148.56,"id":17151079}]}]}
{"op":"mcm","clk":"1001531677","pt":1580637613411,"mc":[{"id":"1.168224334","rc":[{"batb":[[1,1.01,0.51],[2,1.01,0]],"batl":[[0,6.2,10.7],[1,6.2,0]],"ltp":0.0,"tv":0.0,"id":13117429},{"batb":[[0,3.35,17.47],[1,1.01,0.51],[2,1.01,0]],"batl":[[1,5,0]],"ltp":0.0,"tv":0.0,"id":13117428},{"batb":[[0,3.95,23.68]],"batl":[[1,4.7,0]],"ltp":0.0,"tv":0.0,"id":17151080},{"batb":[[0,2.56,15.11],[1,1.01,0.51],[2,1.01,0]],"batl":[[0,3.45,20.3],[1,3.45,0]],"ltp":2.46,"tv":148.56,"id":17151079}]}]}
{"op":"mcm","clk":"1001531797","pt":1580637615320,"mc":[{"id":"1.168224334","rc":[{"batb":[[1,5.3,29.68],[2,1.01,0.51]],"ltp":0.0,"tv":0.0,"id":13117429},{"batb":[[0,3.65,53.28],[1,3.6,36.5],[2,3.35,17.47]],"ltp":0.0,"tv":0.0,"id":13117428},{"batb":[[0,3.95,73.92],[1,3.9,29.38],[2,1.01,0.51]],"ltp":0.0,"tv":0.0,"id":17151080},{"batb":[[1,2.5,47.76],[2,2.46,74.94]],"ltp":2.46,"tv":148.56,"id":17151079}]}]}
{"op":"mcm","clk":"1001531838","pt":1580637615795,"mc":[{"id":"1.168224334","rc":[{"batb":[[0,5.4,28.48],[1,5.3,41.48]],"ltp":0.0,"tv":0.0,"id":13117429},{"batb":[[0,3.35,17.47],[1,1.01,0.51],[2,3.35,0]],"batl":[[0,4.8,18.1]],"ltp":0.0,"tv":0.0,"id":13117428},{"batb":[[0,4,22.98],[1,3.95,28.3]],"batl":[[0,4.7,19.67]],"ltp":0.0,"tv":0.0,"id":17151080},{"batb":[[1,1.01,0.51],[2,2.46,0]],"ltp":2.46,"tv":148.56,"id":17151079}]}]}
{"op":"mcm","clk":"1001532257","pt":1580637622030,"mc":[{"id":"1.168224334","rc":[{"batb":[[0,3.65,53.28],[1,3.6,36.5],[2,3.35,17.47]],"ltp":0.0,"tv":0.0,"id":13117428},{"batb":[[1,3.95,50.24],[2,3.9,29.38]],"ltp":0.0,"tv":0.0,"id":17151080},{"batb":[[1,2.5,47.76],[2,2.46,74.94]],"ltp":2.46,"tv":148.56,"id":17151079}]}]}
{"op":"mcm","clk":"1001532312","pt":1580637622657,"mc":[{"id":"1.168224334","rc":[{"batb":[[1,5.3,11.8]],"ltp":0.0,"tv":0.0,"id":13117429},{"batb":[[0,3.35,17.47],[1,1.01,0.51],[2,3.35,0]],"ltp":0.0,"tv":0.0,"id":13117428},{"batb":[[1,1.01,0.51],[2,3.9,0]],"ltp":0.0,"tv":0.0,"id":17151080},{"batb":[[1,1.01,0.51],[2,2.46,0]],"ltp":2.46,"tv":148.56,"id":17151079}]}]}
{"op":"mcm","clk":"1001532625","pt":1580637626412,"mc":[{"id":"1.168224334","rc":[{"batb":[[0,5.5,35.84],[1,5.4,28.48],[2,5.3,11.8]],"batl":[[0,6,8.4],[1,6.2,10.7]],"ltp":0.0,"tv":0.0,"id":13117429},{"batb":[[0,4.7,47.64],[1,4.6,40.65],[2,4.5,11.76]],"batl":[[1,5.4,9.24]],"ltp":0.0,"tv":0.0,"id":13117428},{"batb":[[0,4.1,61.88],[1,4,90.71],[2,1.01,0.51]],"batl":[[0,4.7,30.59]],"ltp":0.0,"tv":0.0,"id":17151080},{"batb":[[1,2.5,47.76],[2,2.46,74.94]],"batl":[[0,2.78,23.53],[1,3.45,20.3]],"ltp":2.46,"tv":148.56,"id":17151079}]}]}
{"op":"mcm","clk":"1001532667","pt":1580637626821,"mc":[{"id":"1.168224334","rc":[{"batb":[[2,5.3,11.57]],"ltp":0.0,"tv":0.0,"id":13117429},{"batl":[[1,5.4,23.72]],"ltp":0.0,"tv":0.0,"id":13117428},{"batb":[[0,4.1,83.67],[1,4,67.73]],"batl":[[1,4.8,18.96]],"ltp":0.0,"tv":0.0,"id":17151080},{"batl":[[0,2.7,14.79],[1,2.78,23.53],[2,3.05,11.02]],"ltp":2.46,"tv":148.56,"id":17151079}]}]}
{"op":"mcm","clk":"1001533536","pt":1580637638043,"mc":[{"id":"1.168224334","rc":[{"batb":[[0,5.4,28.48],[1,5.3,11.57],[2,5,10.08]],"ltp":0.0,"tv":0.0,"id":13117429},{"batb":[[0,4.5,11.76],[1,3.8,13.22],[2,1.01,0.51]],"batl":[[0,5.4,23.72],[1,5.4,0]],"ltp":0.0,"tv":0.0,"id":13117428},{"batb":[[0,4.1,21.79]],"batl":[[0,4.7,10.92]],"ltp":0.0,"tv":0.0,"id":17151080},{"batb":[[0,2.44,28.57],[1,2.4,17.86],[2,1.01,0.51]],"batl":[[0,2.78,23.53],[1,3.05,11.02],[2,3.05,0]],"ltp":2.46,"tv":148.56,"id":17151079}]}]}
{"op":"mcm","clk":"1001533671","pt":1580637639546,"mc":[{"id":"1.168224334","rc":[{"batb":[[2,1.01,0.51]],"batl":[[0,6.2,10.7],[1,6.2,0]],"ltp":0.0,"tv":0.0,"id":13117429},{"batb":[[0,3.8,13.22],[1,1.01,0.51],[2,1.01,0]],"batl":[[0,5.4,14.48]],"ltp":0.0,"tv":0.0,"id":13117428},{"batb":[[1,4,54.29]],"batl":[[0,4.8,18.96],[1,4.8,0]],"ltp":0.0,"tv":0.0,"id":17151080},{"batb":[[0,2.4,17.86],[1,1.01,0.51],[2,1.01,0]],"batl":[[0,3.05,11.02],[1,3.05,0]],"ltp":2.46,"tv":148.56,"id":17151079}]}]}
{"op":"mcm","clk":"1001533764","pt":1580637640838,"mc":[{"id":"1.168224334","rc":[{"batb":[[0,5.4,39.78],[1,5.3,40.99]],"ltp":0.0,"tv":0.0,"id":13117429},{"batb":[[0,4.1,55.35],[1,4,56.06],[2,3.8,13.22]],"ltp":0.0,"tv":0.0,"id":13117428},{"batb":[[1,4,70.38],[2,3.95,28.29]],"ltp":0.0,"tv":0.0,"id":17151080},{"batb":[[1,2.36,65.01],[2,2.32,87.94]],"ltp":2.46,"tv":148.56,"id":17151079}]}]}
{"op":"mcm","clk":"1001534053","pt":1580637644761,"mc":[{"id":"1.168224334","rc":[{"batb":[[0,5.3,11.57],[1,1.01,0.51],[2,1.01,0]],"ltp":0.0,"tv":0.0,"id":13117429},{"batb":[[0,3.8,13.22],[1,1.01,0.51],[2,3.8,0]],"ltp":0.0,"tv":0.0,"id":13117428},{"batb":[[1,1.01,0.51],[2,3.95,0]],"ltp":0.0,"tv":0.0,"id":17151080}]}]}
{"op":"mcm","clk":"1001534264","pt":1580637647411,"mc":[{"id":"1.168224334","rc":[{"batb":[[0,5.6,22.72],[1,5.5,27.27],[2,5.3,11.57]],"ltp":0.0,"tv":0.0,"id":13117429},{"batb":[[0,5.2,24.03],[1,5.1,32.49],[2,3.8,13.22]],"ltp":0.0,"tv":0.0,"id":13117428},{"batb":[[0,4.2,37.02],[1,4.1,73.41],[2,1.01,0.51]],"ltp":0.0,"tv":0.0,"id":17151080}]}]}
{"op":"mcm","clk":"1001534323","pt":1580637648220,"mc":[{"id":"1.168224334","rc":[{"batb":[[2,5.4,11.09]],"ltp":0.0,"tv":0.0,"id":13117429},{"batb":[[2,4.8,15.11]],"batl":[[1,5.9,11.96]],"ltp":0.0,"tv":0.0,"id":13117428},{"batb":[[0,4.2,57.56]],"ltp":0.0,"tv":0.0,"id":17151080},{"batl":[[0,2.54,17.47],[1,2.74,14.16],[2,3.05,11.02]],"ltp":2.46,"tv":148.56,"id":17151079}]}]}
{"op":"mcm","clk":"1001534340","pt":1580637648533,"mc":[{"id":"1.168224334","rc":[{"batl":[[0,6.2,18.11]],"ltp":0.0,"tv":0.0,"id":13117429},{"batb":[[2,4.9,10.08]],"batl":[[1,5.9,20.36]],"ltp":0.0,"tv":0.0,"id":13117428},{"batb":[[1,4.1,51.62],[2,4,13.44]],"batl":[[0,4.8,29.26]],"ltp":0.0,"tv":0.0,"id":17151080},{"batb":[[2,2.34,31.09]],"batl":[[1,2.64,25.21],[2,2.74,14.16]],"ltp":2.46,"tv":148.56,"id":17151079}]}]}
{"op":"mcm","clk":"1001534974","pt":1580637657141,"mc":[{"id":"1.168224334","rc":[{"batb":[[0,5.5,27.27],[1,5.3,11.57],[2,5,10.08]],"ltp":0.0,"tv":0.0,"id":13117429},{"batb":[[0,4.9,10.08],[1,4.2,19.75],[2,1.01,0.51]],"batl":[[0,5.9,20.36],[1,5.9,0]],"ltp":0.0,"tv":0.0,"id":13117428},{"batb":[[0,4.2,20.54]],"ltp":0.0,"tv":0.0,"id":17151080},{"batb":[[0,2.34,31.09],[1,2.28,20.38],[2,1.01,0.51]],"batl":[[0,2.64,25.21],[1,2.74,14.16],[2,2.74,0]],"ltp":2.46,"tv":148.56,"id":17151079}]}]}
{"op":"mcm","clk":"1001535009","pt":1580637657512,"mc":[{"id":"1.168224334","rc":[{"batb":[[2,1.01,0.51]],"batl":[[0,6.2,10.54]],"ltp":0.0,"tv":0.0,"id":13117429},{"batb":[[0,4.2,19.75],[1,1.01,0.51],[2,1.01,0]],"batl":[[0,5.9,11.96]],"ltp":0.0,"tv":0.0,"id":13117428},{"batb":[[2,1.01,0.51]],"batl":[[0,4.8,18.33]],"ltp":0.0,"tv":0.0,"id":17151080},{"batb":[[0,2.28,20.38],[1,1.01,0.51],[2,1.01,0]],"batl":[[0,2.74,14.16],[1,2.74,0]],"ltp":2.46,"tv":148.56,"id":17151079}]}]}
{"op":"mcm","clk":"1001535281","pt":1580637660321,"mc":[{"id":"1.168224334","rc":[{"batb":[[0,2.28,84.07],[1,2.26,47.76],[2,1.01,0.51]],"ltp":2.46,"tv":148.56,"id":17151079}]}]}
{"op":"mcm","clk":"1001535579","pt":1580637663332,"mc":[{"id":"1.168224334","rc":[{"batb":[[0,5.6,36.53],[1,5.5,27.27],[2,5.4,11.33]],"batl":[[1,6.4,20.54]],"ltp":0.0,"tv":0.0,"id":13117429},{"batb":[[0,5.5,34.8],[1,5.4,28.44],[2,5.2,12.51]],"batl":[[1,6.2,10.62]],"ltp":0.0,"tv":0.0,"id":13117428},{"batb":[[0,4.2,74.29]],"ltp":0.0,"tv":0.0,"id":17151080},{"batb":[[2,2.22,22.03]],"batl":[[0,2.42,19.91],[1,2.54,17.31],[2,2.74,14.16]],"ltp":2.46,"tv":148.56,"id":17151079}]}]}
{"op":"mcm","clk":"1001535670","pt":1580637664414,"mc":[{"id":"1.168224334","rc":[{"batl":[[0,6.2,7.56]],"ltp":0.0,"tv":0.0,"id":13117429},{"batl":[[2,6.4,7.56]],"ltp":0.0,"tv":0.0,"id":13117428},{"batb":[[0,4.2,73.5],[1,4.1,65.06]],"batl":[[0,4.8,29.26]],"ltp":0.0,"tv":0.0,"id":17151080},{"batb":[[1,2.26,80.53]],"batl":[[1,2.54,44.2],[2,2.74,0]],"ltp":2.46,"tv":148.56,"id":17151079}]}]}
{"op":"mcm","clk":"1001536224","pt":1580637671325,"mc":[{"id":"1.168224334","rc":[{"batb":[[0,5.5,27.27],[1,5.4,11.33],[2,5.1,10.08]],"ltp":0.0,"tv":0.0,"id":13117429},{"batb":[[0,5.1,10.08],[1,4.7,15.26],[2,1.01,0.51]],"batl":[[0,6.2,10.62],[1,6.4,7.56],[2,6.4,0]],"ltp":0.0,"tv":0.0,"id":13117428},{"batb":[[0,4.2,61.94]],"ltp":0.0,"tv":0.0,"id":17151080},{"batb":[[0,2.26,32.77],[1,2.22,22.03],[2,1.01,0.51]],"batl":[[0,2.54,44.2],[1,2.54,0]],"ltp":2.46,"tv":148.56,"id":17151079}]}]}
{"op":"mcm","clk":"1001536247","pt":1580637671536,"mc":[{"id":"1.168224334","rc":[{"batb":[[2,1.01,0.51]],"batl":[[0,6.4,20.54],[1,6.4,0]],"ltp":0.0,"tv":0.0,"id":13117429},{"batb":[[0,4.7,15.26],[1,1.01,0.51],[2,1.01,0]],"batl":[[1,6.4,0]],"ltp":0.0,"tv":0.0,"id":13117428},{"batb":[[1,4.1,51.62]],"batl":[[0,4.8,18.33]],"ltp":0.0,"tv":0.0,"id":17151080},{"batb":[[0,2.22,22.03],[1,1.01,0.51],[2,1.01,0]],"batl":[[0,2.54,17.31]],"ltp":2.46,"tv":148.56,"id":17151079}]}]}
{"op":"mcm","clk":"1001536447","pt":1580637674026,"mc":[{"id":"1.168224334","rc":[{"batb":[[0,5.5,41.26],[1,5.4,39.47]],"ltp":0.0,"tv":0.0,"id":13117429},{"batb":[[0,5.2,31.52],[1,5.1,32.38],[2,4.7,15.26]],"ltp":0.0,"tv":0.0,"id":13117428},{"batb":[[0,2.24,58.1],[1,2.22,72.29],[2,1.01,0.51]],"ltp":2.46,"tv":148.56,"id":17151079}]}]}
{"op":"mcm","clk":"1001536545","pt":1580637675325,"mc":[{"id":"1.168224334","rc":[{"batb":[[0,5.4,11.33],[1,1.01,0.51],[2,1.01,0]],"ltp":0.0,"tv":0.0,"id":13117429},{"batb":[[0,4.7,15.26],[1,1.01,0.51],[2,4.7,0]],"ltp":0.0,"tv":0.0,"id":13117428}]}]}
{"op":"mcm","clk":"1001536765","pt":1580637678235,"mc":[{"id":"1.168224334","rc":[{"batb":[[0,5.7,23.08],[1,5.6,26.18],[2,5.4,11.33]],"ltp":0.0,"tv":0.0,"id":13117429},{"batb":[[0,5.7,32.48],[1,5.6,26.25],[2,4.7,15.26]],"ltp":0.0,"tv":0.0,"id":13117428},{"batb":[[0,4.2,80.34]],"ltp":0.0,"tv":0.0,"id":17151080}]}]}
{"op":"mcm","clk":"1001536829","pt":1580637679265,"mc":[{"id":"1.168224334","rc":[{"batb":[[2,5.5,10.94]],"batl":[[0,6.4,28.1],[1,6.6,19.12]],"ltp":0.0,"tv":0.0,"id":13117429},{"batb":[[2,5.4,20.26]],"batl":[[1,6.6,6.72],[2,8,12.75]],"ltp":0.0,"tv":0.0,"id":13117428},{"batb":[[0,4.3,19.2],[1,4.2,80.34],[2,4.1,51.62]],"batl":[[0,4.8,29.26],[1,5,16.6]],"ltp":0.0,"tv":0.0,"id":17151080},{"batb":[[2,2.18,35.29]],"batl":[[0,2.34,21.48],[1,2.46,28.57],[2,2.54,17.31]],"ltp":2.46,"tv":148.56,"id":17151079}]}]}
{"op":"mcm","clk":"1001543901","pt":1580637762158,"mc":[{"id":"1.168224334","rc":[{"batb":[[0,5.6,26.18],[1,5.5,10.94],[2,5.2,9.24]],"batl":[[0,6.4,7.56]],"ltp":0.0,"tv":0.0,"id":13117429},{"batb":[[0,5.4,9.24],[1,4.8,14.95],[2,1.01,0.51]],"batl":[[0,6.6,6.72],[1,8,12.75],[2,8,0]],"ltp":0.0,"tv":0.0,"id":13117428},{"batb":[[0,4.2,19.75],[1,4.1,51.62],[2,4,13.44]],"batl":[[0,4.8,10.92]],"ltp":0.0,"tv":0.0,"id":17151080},{"batb":[[0,2.18,35.29],[1,2,29.74],[2,1.01,0.51]],"batl":[[0,2.46,28.57],[1,2.54,17.31],[2,2.54,0]],"ltp":2.46,"tv":148.56,"id":17151079}]}]}
{"op":"mcm","clk":"1001544042","pt":1580637763599,"mc":[{"id":"1.168224334","rc":[{"batb":[[2,1.01,0.51]],"batl":[[0,6.6,19.12],[1,6.6,0]],"ltp":0.0,"tv":0.0,"id":13117429},{"batb":[[0,4.8,14.95],[1,1.01,0.51],[2,1.01,0]],"batl":[[0,8,12.75],[1,8,0]],"ltp":0.0,"tv":0.0,"id":13117428},{"batb":[[2,1.01,0.51]],"batl":[[0,5,16.6],[1,5,0]],"ltp":0.0,"tv":0.0,"id":17151080},{"batb":[[0,2,29.74],[1,1.01,0.51],[2,1.01,0]],"batl":[[0,2.54,17.31],[1,2.54,0]],"ltp":2.46,"tv":148.56,"id":17151079}]}]}
{"op":"mcm","clk":"1001544145","pt":1580637764949,"mc":[{"id":"1.168224334","rc":[{"batb":[[1,5.5,38.16]],"ltp":0.0,"tv":0.0,"id":13117429},{"batb":[[0,5.1,27.42],[1,5,34.01],[2,4.8,14.95]],"ltp":0.0,"tv":0.0,"id":13117428},{"batb":[[1,4.1,69.35],[2,4,54.17]],"ltp":0.0,"tv":0.0,"id":17151080},{"batb":[[0,2.02,113.02],[1,2,98.01],[2,1.01,0.51]],"ltp":2.46,"tv":148.56,"id":17151079}]}]}
{"op":"mcm","clk":"1001544291","pt":1580637766666,"mc":[{"id":"1.168224334","rc":[{"batb":[[1,5.5,10.94]],"ltp":0.0,"tv":0.0,"id":13117429},{"batb":[[0,4.8,14.95],[1,1.01,0.51],[2,4.8,0]],"ltp":0.0,"tv":0.0,"id":13117428},{"batb":[[1,1.01,0.51],[2,4,0]],"ltp":0.0,"tv":0.0,"id":17151080},{"batb":[[0,2,29.74],[1,1.01,0.51],[2,1.01,0]],"ltp":2.46,"tv":148.56,"id":17151079}]}]}
{"op":"mcm","clk":"1001544564","pt":1580637770053,"mc":[{"id":"1.168224334","rc":[{"batb":[[0,5.7,30.36],[1,5.6,26.18],[2,5.5,10.94]],"ltp":0.0,"tv":0.0,"id":13117429},{"batb":[[0,6,19.09],[1,5.9,23.62],[2,4.8,14.95]],"ltp":0.0,"tv":0.0,"id":13117428},{"batb":[[0,4.3,25.75],[1,4.2,68.71],[2,1.01,0.51]],"ltp":0.0,"tv":0.0,"id":17151080},{"batb":[[0,2.18,93.66],[1,2.16,54.3],[2,2,29.74]],"ltp":2.46,"tv":148.56,"id":17151079}]}]}
{"op":"mcm","clk":"1001544715","pt":1580637771762,"mc":[{"id":"1.168224334","rc":[{"batb":[[0,5.6,26.18],[1,5.5,10.94],[2,1.01,0.51]],"ltp":0.0,"tv":0.0,"id":13117429},{"batb":[[0,4.8,14.95],[1,1.01,0.51],[2,4.8,0]],"ltp":0.0,"tv":0.0,"id":13117428},{"batb":[[0,4.2,19.75],[1,1.01,0.51],[2,1.01,0]],"ltp":0.0,"tv":0.0,"id":17151080},{"batb":[[0,2,29.74],[1,1.01,0.51],[2,2,0]],"ltp":2.46,"tv":148.56,"id":17151079}]}]}
{"op":"mcm","clk":"1001544960","pt":1580637775185,"mc":[{"id":"1.168224334","rc":[{"batb":[[1,5.5,38.16]],"ltp":0.0,"tv":0.0,"id":13117429},{"batb":[[0,5.1,27.42],[1,5,34.01],[2,4.8,14.95]],"ltp":0.0,"tv":0.0,"id":13117428},{"batb":[[1,4.1,69.35],[2,4,54.17]],"ltp":0.0,"tv":0.0,"id":17151080},{"batb":[[0,2.02,113.02],[1,2,98.01],[2,1.01,0.51]],"ltp":2.46,"tv":148.56,"id":17151079}]}]}
{"op":"mcm","clk":"1001545214","pt":1580637778660,"mc":[{"id":"1.168224334","rc":[{"batb":[[0,5.5,10.94],[1,1.01,0.51],[2,1.01,0]],"ltp":0.0,"tv":0.0,"id":13117429},{"batb":[[0,4.8,14.95],[1,1.01,0.51],[2,4.8,0]],"ltp":0.0,"tv":0.0,"id":13117428},{"batb":[[1,1.01,0.51],[2,4,0]],"ltp":0.0,"tv":0.0,"id":17151080}]}]}
{"op":"mcm","clk":"1001545582","pt":1580637782372,"mc":[{"id":"1.168224334","rc":[{"batb":[[0,5.8,31.62],[1,5.7,25.02],[2,5.6,10.31]],"batl":[[1,6.8,18.02]],"ltp":0.0,"tv":0.0,"id":13117429},{"batb":[[0,7,41.61],[1,6.8,33.55],[2,6.6,13.53]],"batl":[[1,12,15.11]],"ltp":0.0,"tv":0.0,"id":13117428},{"batb":[[0,4.5,17.39],[1,4.4,32.9],[2,4.3,65.05]],"batl":[[1,5.4,14.48]],"ltp":0.0,"tv":0.0,"id":17151080},{"batb":[[2,1.81,20.61]],"batl":[[0,2.12,28.8],[1,2.3,22.74]],"ltp":2.46,"tv":148.56,"id":17151079}]}]}
{"op":"mcm","clk":"1001545602","pt":1580637782580,"mc":[{"id":"1.168224334","rc":[{"batl":[[0,6.6,25.84]],"ltp":0.0,"tv":0.0,"id":13117429},{"batl":[[1,8.2,5.04],[2,12,15.11]],"ltp":0.0,"tv":0.0,"id":13117428},{"batl":[[0,5,26.68]],"ltp":0.0,"tv":0.0,"id":17151080},{"batb":[[0,2.02,154.19]],"batl":[[1,2.24,33.61],[2,2.3,22.74]],"ltp":2.46,"tv":148.56,"id":17151079}]}]}
{"op":"mcm","clk":"1001546950","pt":1580637797586,"mc":[{"id":"1.168224334","rc":[{"batb":[[0,5.7,25.02],[1,5.5,10.62],[2,1.01,0.51]],"batl":[[0,6.8,18.02],[1,6.8,0]],"ltp":0.0,"tv":0.0,"id":13117429},{"batb":[[0,5.6,10.39],[1,1.01,0.51],[2,6.6,0]],"batl":[[0,12,15.11],[1,8.2,0],[2,12,0]],"ltp":0.0,"tv":0.0,"id":13117428},{"batb":[[0,4.3,18.88],[1,1.01,0.51],[2,4.3,0]],"batl":[[0,5.4,14.48],[1,5.4,0]],"ltp":0.0,"tv":0.0,"id":17151080},{"batb":[[0,1.81,20.61],[1,1.01,0.51],[2,1.81,0]],"batl":[[0,2.3,22.74],[1,2.24,0],[2,2.3,0]],"ltp":2.46,"tv":148.56,"id":17151079}]}]}
{"op":"mcm","clk":"1001547165","pt":1580637800490,"mc":[{"id":"1.168224334","rc":[{"batb":[[0,5.7,31.83],[1,5.6,26.07],[2,5.5,10.62]],"ltp":0.0,"tv":0.0,"id":13117429},{"batb":[[0,5.9,39.15],[1,5.8,24.26],[2,5.6,10.39]],"ltp":0.0,"tv":0.0,"id":13117428},{"batb":[[1,4.2,69.39],[2,4.1,51.01]],"ltp":0.0,"tv":0.0,"id":17151080},{"batb":[[0,1.83,82.59],[1,1.81,114.12],[2,1.01,0.51]],"ltp":2.46,"tv":148.56,"id":17151079}]}]}
{"op":"mcm","clk":"1001547373","pt":1580637803602,"mc":[{"id":"1.168224334","rc":[{"batb":[[0,5.5,10.62],[1,1.01,0.51],[2,5.5,0]],"ltp":0.0,"tv":0.0,"id":13117429},{"batb":[[0,5.6,10.39],[1,1.01,0.51],[2,5.6,0]],"ltp":0.0,"tv":0.0,"id":13117428},{"batb":[[1,1.01,0.51],[2,4.1,0]],"ltp":0.0,"tv":0.0,"id":17151080}]}]}
{"op":"mcm","clk":"1001547648","pt":1580637807330,"mc":[{"id":"1.168224334","rc":[{"batb":[[0,6,23.16],[1,5.9,23.25],[2,5.5,10.62]],"batl":[[0,6.6,6.72],[1,6.8,18.02]],"ltp":0.0,"tv":0.0,"id":13117429},{"batb":[[0,10,21.41],[1,9.8,15.56],[2,8.6,5.04]],"batl":[[0,11.5,3.36],[1,12,15.11]],"ltp":0.0,"tv":0.0,"id":13117428},{"batb":[[0,4.6,33.01],[1,4.5,41.46],[2,4.4,11.76]],"batl":[[0,5.3,9.24],[1,5.4,14.48]],"ltp":0.0,"tv":0.0,"id":17151080},{"batb":[[0,1.83,133]],"batl":[[0,2.02,41.17],[1,2.3,22.74]],"ltp":2.46,"tv":148.56,"id":17151079}]}]}
{"op":"mcm","clk":"1001547675","pt":1580637807748,"mc":[{"id":"1.168224334","rc":[{"batb":[[2,5.8,19.28]],"batl":[[2,7,16.76]],"ltp":0.0,"tv":0.0,"id":13117429},{"batb":[[2,9.2,16.76]],"batl":[[2,21,5.19]],"ltp":0.0,"tv":0.0,"id":13117428},{"batb":[[0,4.7,15.11],[1,4.6,33.01],[2,4.5,58.14]],"batl":[[2,5.7,12.67]],"ltp":0.0,"tv":0.0,"id":17151080},{"batb":[[2,1.64,28.56]],"batl":[[0,1.88,20.22],[1,2.02,41.17],[2,2.04,16.05]],"ltp":2.46,"tv":148.56,"id":17151079}]}]}
{"op":"mcm","clk":"1001549063","pt":1580637824241,"mc":[{"id":"1.168224334","rc":[{"batb":[[0,5.9,23.25],[1,5.8,19.28],[2,5.6,20.38]],"ltp":0.0,"tv":0.0,"id":13117429},{"batb":[[0,9.2,16.76],[1,8.6,5.04],[2,7.4,11.02]],"ltp":0.0,"tv":0.0,"id":13117428},{"batb":[[1,4.5,16.68],[2,4.4,11.76]],"ltp":0.0,"tv":0.0,"id":17151080},{"batb":[[0,1.83,50.41],[1,1.81,20.61]],"ltp":2.46,"tv":148.56,"id":17151079}]}]}
{"op":"mcm","clk":"1001549090","pt":1580637824549,"mc":[{"id":"1.168224334","rc":[{"batb":[[1,5.6,20.38],[2,5.4,9.24]],"batl":[[1,7,16.76],[2,7,0]],"ltp":0.0,"tv":0.0,"id":13117429},{"batb":[[0,8.6,5.04],[1,7.4,11.02],[2,1.01,0.51]],"batl":[[1,21,5.19],[2,21,0]],"ltp":0.0,"tv":0.0,"id":13117428},{"batb":[[0,4.5,16.68],[1,4.4,11.76],[2,1.01,0.51]],"batl":[[1,5.7,12.67],[2,5.7,0]],"ltp":0.0,"tv":0.0,"id":17151080},{"batb":[[1,1.64,28.56],[2,1.01,0.51]],"batl":[[0,2.02,41.17],[1,2.04,16.05],[2,2.04,0]],"ltp":2.46,"tv":148.56,"id":17151079}]}]}
{"op":"mcm","clk":"1001549185","pt":1580637825662,"mc":[{"id":"1.168224334","rc":[{"batb":[[2,1.01,0.51]],"batl":[[0,7,16.76],[1,7,0]],"ltp":0.0,"tv":0.0,"id":13117429},{"batb":[[0,7.4,11.02],[1,1.01,0.51],[2,1.01,0]],"batl":[[0,21,5.19],[1,21,0]],"ltp":0.0,"tv":0.0,"id":13117428},{"batb":[[1,1.01,0.51],[2,1.01,0]],"batl":[[0,5.7,12.67],[1,5.7,0]],"ltp":0.0,"tv":0.0,"id":17151080},{"batb":[[0,1.64,28.56],[1,1.01,0.51],[2,1.01,0]],"batl":[[0,2.04,16.05],[1,2.04,0]],"ltp":2.46,"tv":148.56,"id":17151079}]}]}
{"op":"mcm","clk":"1001549300","pt":1580637827165,"mc":[{"id":"1.168224334","rc":[{"batb":[[1,5.8,24.26],[2,5.6,20.38]],"ltp":0.0,"tv":0.0,"id":13117429},{"batb":[[0,7.8,24.43],[1,7.6,26.73],[2,7.4,11.02]],"ltp":0.0,"tv":0.0,"id":13117428},{"batb":[[1,4.4,55.4],[2,4.3,45.75]],"ltp":0.0,"tv":0.0,"id":17151080},{"batb":[[0,1.66,110.57],[1,1.65,64.57],[2,1.64,28.56]],"ltp":2.46,"tv":148.56,"id":17151079}]}]}
{"op":"mcm","clk":"1001549553","pt":1580637830140,"mc":[{"id":"1.168224334","rc":[{"batb":[[0,5.6,20.38],[1,1.01,0.51],[2,5.6,0]],"ltp":0.0,"tv":0.0,"id":13117429},{"batb":[[0,7.4,11.02],[1,1.01,0.51],[2,7.4,0]],"ltp":0.0,"tv":0.0,"id":13117428},{"batb":[[1,1.01,0.51],[2,4.3,0]],"ltp":0.0,"tv":0.0,"id":17151080}]}]}
{"op":"mcm","clk":"1001549848","pt":1580637833360,"mc":[{"id":"1.168224334","rc":[{"batb":[[0,6.2,20.47],[1,6,44.03],[2,5.9,18.1]],"batl":[[1,7.2,15.5]],"ltp":0.0,"tv":0.0,"id":13117429},{"batb":[[0,17,15.22],[1,16.5,12.88],[2,14.5,5.59]],"ltp":0.0,"tv":0.0,"id":13117428},{"batb":[[0,5,13.22],[1,4.9,14.32],[2,4.8,46.58]],"batl":[[1,6,11.17]],"ltp":0.0,"tv":0.0,"id":17151080},{"batl":[[0,1.71,27.93],[1,1.8,23.29],[2,2.04,16.05]],"ltp":2.46,"tv":148.56,"id":17151079}]}]}
{"op":"mcm","clk":"1001549866","pt":1580637833571,"mc":[{"id":"1.168224334","rc":[{"batl":[[2,2.04,0]],"ltp":2.46,"tv":148.56,"id":17151079}]}]}
{"op":"mcm","clk":"1001549972","pt":1580637834865,"mc":[{"id":"1.168224334","rc":[{"batl":[[0,6.6,6.72],[1,7,16.76],[2,7.2,15.5]],"ltp":0.0,"tv":0.0,"id":13117429},{"batl":[[0,5.6,8.4],[1,5.7,12.67],[2,6,11.17]],"ltp":0.0,"tv":0.0,"id":17151080},{"batb":[[0,1.67,62.17],[1,1.66,110.57],[2,1.65,64.57]],"ltp":2.46,"tv":148.56,"id":17151079}]}]}
{"op":"mcm","clk":"1001550045","pt":1580637835686,"mc":[{"id":"1.168224334","rc":[{"batl":[[2,1.84,42.01]],"ltp":2.46,"tv":148.56,"id":17151079}]}]}
{"op":"mcm","clk":"1001550826","pt":1580637844359,"mc":[{"id":"1.168224334","rc":[{"batb":[[0,6,35.34],[1,5.7,19.67],[2,5.4,9.24]],"batl":[[1,7.2,15.5],[2,7.2,0]],"ltp":0.0,"tv":0.0,"id":13117429},{"batb":[[0,13.5,3.36],[1,11.5,9.91],[2,1.01,0.51]],"ltp":0.0,"tv":0.0,"id":13117428},{"batb":[[0,4.9,14.32],[1,4.7,37.21],[2,4.5,11.76]],"batl":[[1,6,11.17],[2,6,0]],"ltp":0.0,"tv":0.0,"id":17151080},{"batb":[[1,1.54,36.27],[2,1.01,0.51]],"batl":[[0,1.8,23.29],[1,1.84,42.01],[2,1.84,0]],"ltp":2.46,"tv":148.56,"id":17151079}]}]}
{"op":"mcm","clk":"1001550971","pt":1580637846066,"mc":[{"id":"1.168224334","rc":[{"batb":[[2,1.01,0.51]],"batl":[[0,7.2,15.5],[1,7.2,0]],"ltp":0.0,"tv":0.0,"id":13117429},{"batb":[[0,11.5,9.91],[1,1.01,0.51],[2,1.01,0]],"ltp":0.0,"tv":0.0,"id":13117428},{"batb":[[2,1.01,0.51]],"batl":[[0,6,11.17],[1,6,0]],"ltp":0.0,"tv":0.0,"id":17151080},{"batb":[[0,1.54,36.27],[1,1.01,0.51],[2,1.01,0]],"batl":[[1,1.84,0]],"ltp":2.46,"tv":148.56,"id":17151079}]}]}
{"op":"mcm","clk":"1001551086","pt":1580637847260,"mc":[{"id":"1.168224334","rc":[{"batb":[[1,1.01,0.51],[2,1.01,0]],"ltp":0.0,"tv":0.0,"id":17151080}]}]}
{"op":"mcm","clk":"1001551359","pt":1580637850368,"mc":[{"id":"1.168224334","rc":[{"batb":[[0,6.2,28.88],[1,6,43.79],[2,5.7,19.67]],"ltp":0.0,"tv":0.0,"id":13117429},{"batb":[[0,19,8.73],[1,18.5,10.33],[2,11.5,9.91]],"ltp":0.0,"tv":0.0,"id":13117428},{"batb":[[0,4.9,38.45],[1,4.8,35.8],[2,1.01,0.51]],"ltp":0.0,"tv":0.0,"id":17151080},{"batb":[[0,1.64,104.74],[1,1.63,67.44],[2,1.54,36.27]],"ltp":2.46,"tv":148.56,"id":17151079}]}]}
{"op":"mcm","clk":"1001551490","pt":1580637852082,"mc":[{"id":"1.168224334","rc":[{"batb":[[0,6,35.34],[1,5.7,19.67],[2,1.01,0.51]],"ltp":0.0,"tv":0.0,"id":13117429},{"batb":[[0,11.5,9.91],[1,1.01,0.51],[2,11.5,0]],"ltp":0.0,"tv":0.0,"id":13117428},{"batb":[[0,4.9,14.32],[1,1.01,0.51],[2,1.01,0]],"ltp":0.0,"tv":0.0,"id":17151080},{"batb":[[0,1.54,36.27],[1,1.01,0.51],[2,1.54,0]],"ltp":2.46,"tv":148.56,"id":17151079}]}]}
{"op":"mcm","clk":"1001551798","pt":1580637855506,"mc":[{"id":"1.168224334","rc":[{"batb":[[1,5.9,23.05],[2,5.7,19.67]],"ltp":0.0,"tv":0.0,"id":13117429},{"batb":[[0,13,10.61],[1,12.5,23.08],[2,11.5,9.91]],"ltp":0.0,"tv":0.0,"id":13117428},{"batb":[[1,4.7,35.69],[2,4.6,39.32]],"ltp":0.0,"tv":0.0,"id":17151080},{"batb":[[0,1.56,117.03],[1,1.55,81.42],[2,1.54,36.27]],"ltp":2.46,"tv":148.56,"id":17151079}]}]}
{"op":"mcm","clk":"1001552255","pt":1580637860590,"mc":[{"id":"1.168224334","rc":[{"batb":[[0,1.54,36.27],[1,1.01,0.51],[2,1.54,0]],"ltp":2.46,"tv":148.56,"id":17151079}]}]}
{"op":"mcm","clk":"1001552599","pt":1580637864285,"mc":[{"id":"1.168224334","rc":[{"batl":[[0,6.8,18.33],[1,7,16.92]],"ltp":0.0,"tv":0.0,"id":13117429},{"batl":[[0,15.5,9.21]],"ltp":0.0,"tv":0.0,"id":13117428},{"batb":[[2,4.6,55.21]],"batl":[[0,5.5,13.69],[1,5.9,11.88]],"ltp":0.0,"tv":0.0,"id":17151080},{"batb":[[0,1.74,96.53],[1,1.73,23.76],[2,1.72,110.96]],"batl":[[1,1.95,18.18]],"ltp":2.46,"tv":148.56,"id":17151079}]}]}
{"op":"mcm","clk":"1001552664","pt":1580637864904,"mc":[{"id":"1.168224334","rc":[{"batl":[[0,6.6,6.72],[1,6.8,18.33],[2,7,16.92]],"ltp":0.0,"tv":0.0,"id":13117429},{"batl":[[0,5.4,9.24],[1,5.5,13.69],[2,5.9,11.88]],"ltp":0.0,"tv":0.0,"id":17151080},{"batb":[[0,1.74,152.82]],"batl":[[1,1.91,42.01],[2,1.95,18.18]],"ltp":2.46,"tv":148.56,"id":17151079}]}]}
{"op":"mcm","clk":"1001554987","pt":1580637891328,"mc":[{"id":"1.168224334","rc":[{"batb":[[0,5.9,23.05],[1,5.7,19.67],[2,5.6,20.54]],"ltp":0.0,"tv":0.0,"id":13117429},{"batb":[[0,11.5,9.91],[1,11,4.2],[2,8.4,7.95]],"ltp":0.0,"tv":0.0,"id":13117428},{"batb":[[1,4.6,15.89],[2,4.5,11.76]],"ltp":0.0,"tv":0.0,"id":17151080},{"batb":[[0,1.74,56.29],[2,1.56,33.83]],"ltp":2.46,"tv":148.56,"id":17151079}]}]}
{"op":"mcm","clk":"1001555068","pt":1580637892106,"mc":[{"id":"1.168224334","rc":[{"batb":[[1,5.6,20.54],[2,1.01,0.51]],"batl":[[0,7,16.92],[1,6.8,0],[2,7,0]],"ltp":0.0,"tv":0.0,"id":13117429},{"batb":[[0,8.4,7.95],[1,1.01,0.51],[2,8.4,0]],"ltp":0.0,"tv":0.0,"id":13117428},{"batb":[[0,4.6,15.89],[1,1.01,0.51],[2,4.5,0]],"batl":[[0,5.9,11.88],[1,5.5,0],[2,5.9,0]],"ltp":0.0,"tv":0.0,"id":17151080},{"batb":[[0,1.56,33.83],[1,1.01,0.51],[2,1.56,0]],"batl":[[0,1.95,18.18],[1,1.91,0],[2,1.95,0]],"ltp":2.46,"tv":148.56,"id":17151079}]}]}
{"op":"mcm","clk":"1001555499","pt":1580637897340,"mc":[{"id":"1.168224334","rc":[{"batb":[[0,6,44.31],[1,5.9,23.05],[2,5.6,20.54]],"ltp":0.0,"tv":0.0,"id":13117429},{"batb":[[0,14.5,18.71],[1,14,18.03],[2,8.4,7.95]],"ltp":0.0,"tv":0.0,"id":13117428},{"batb":[[0,4.7,56.25],[1,4.6,54.86],[2,1.01,0.51]],"ltp":0.0,"tv":0.0,"id":17151080},{"batb":[[0,1.71,65.86],[1,1.69,117.76],[2,1.56,33.83]],"ltp":2.46,"tv":148.56,"id":17151079}]}]}
{"op":"mcm","clk":"1001555805","pt":1580637900156,"mc":[{"id":"1.168224334","rc":[{"batb":[[0,5.9,23.05],[1,5.6,20.54],[2,1.01,0.51]],"ltp":0.0,"tv":0.0,"id":13117429},{"batb":[[0,8.4,7.95],[1,1.01,0.51],[2,8.4,0]],"ltp":0.0,"tv":0.0,"id":13117428},{"batb":[[0,4.6,15.89],[1,1.01,0.51],[2,1.01,0]],"ltp":0.0,"tv":0.0,"id":17151080},{"batb":[[0,1.56,33.83],[1,1.01,0.51],[2,1.56,0]],"ltp":2.46,"tv":148.56,"id":17151079}]}]}
{"op":"mcm","clk":"1001556475","pt":1580637907278,"mc":[{"id":"1.168224334","rc":[{"batb":[[1,5.8,24.1],[2,5.6,10.54]],"batl":[[0,6.6,25.13]],"ltp":0.0,"tv":0.0,"id":13117429},{"batb":[[0,9.2,19.13],[1,9,18.73],[2,8.4,7.95]],"batl":[[0,10.5,11.75]],"ltp":0.0,"tv":0.0,"id":13117428},{"batb":[[1,4.5,47.71],[2,4.4,61.96]],"batl":[[0,5.1,10.08],[1,5.2,15.19],[2,5.7,12.43]],"ltp":0.0,"tv":0.0,"id":17151080},{"batb":[[0,1.88,75.51],[1,1.87,18.49],[2,1.86,134.37]],"batl":[[1,2.06,39.49],[2,2.26,24]],"ltp":2.46,"tv":148.56,"id":17151079}]}]}
{"op":"mcm","clk":"1001558075","pt":1580637926831,"mc":[{"id":"1.168224334","rc":[{"batb":[[0,5.8,24.1],[1,5.6,10.54],[2,5.3,9.24]],"ltp":0.0,"tv":0.0,"id":13117429},{"batb":[[0,8.2,5.04],[1,5.9,18.73],[2,1.01,0.51]],"batl":[[0,10.5,4.2]],"ltp":0.0,"tv":0.0,"id":13117428},{"batb":[[0,4.4,18.49],[1,4.3,12.6],[2,1.01,0.51]],"batl":[[1,5.7,12.43],[2,5.7,0]],"ltp":0.0,"tv":0.0,"id":17151080},{"batb":[[0,1.86,48.73],[1,1.59,31.55],[2,1.01,0.51]],"batl":[[0,2.06,39.49],[1,2.26,24],[2,2.26,0]],"ltp":2.46,"tv":148.56,"id":17151079}]}]}
{"op":"mcm","clk":"1001558209","pt":1580637928333,"mc":[{"id":"1.168224334","rc":[{"batb":[[2,1.01,0.51]],"batl":[[0,6.6,18.41]],"ltp":0.0,"tv":0.0,"id":13117429},{"batb":[[0,5.9,18.73],[1,1.01,0.51],[2,1.01,0]],"ltp":0.0,"tv":0.0,"id":13117428},{"batb":[[1,1.01,0.51],[2,1.01,0]],"batl":[[0,5.7,12.43],[1,5.7,0]],"ltp":0.0,"tv":0.0,"id":17151080},{"batb":[[0,1.59,31.55],[1,1.01,0.51],[2,1.01,0]],"batl":[[0,2.26,24],[1,2.26,0]],"ltp":2.46,"tv":148.56,"id":17151079}]}]}
{"op":"mcm","clk":"1001558355","pt":1580637930011,"mc":[{"id":"1.168224334","rc":[{"batb":[[1,5.7,25.25],[2,5.6,10.54]],"ltp":0.0,"tv":0.0,"id":13117429},{"batb":[[0,6.2,34.26],[1,6,44.45],[2,5.9,18.73]],"ltp":0.0,"tv":0.0,"id":13117428},{"batb":[[1,4.3,31.33],[2,4.2,48.88]],"ltp":0.0,"tv":0.0,"id":17151080},{"batb":[[0,1.59,144.07],[1,1.58,75.64],[2,1.01,0.51]],"ltp":2.46,"tv":148.56,"id":17151079}]}]}
{"op":"mcm","clk":"1001558426","pt":1580637930897,"mc":[{"id":"1.168224334","rc":[{"batb":[[1,5.6,10.54],[2,1.01,0.51]],"ltp":0.0,"tv":0.0,"id":13117429},{"batb":[[0,5.9,18.73],[1,1.01,0.51],[2,5.9,0]],"ltp":0.0,"tv":0.0,"id":13117428},{"batb":[[1,1.01,0.51],[2,4.2,0]],"ltp":0.0,"tv":0.0,"id":17151080},{"batb":[[0,1.59,31.55],[1,1.01,0.51],[2,1.01,0]],"ltp":2.46,"tv":148.56,"id":17151079}]}]}
{"op":"mcm","clk":"1001558692","pt":1580637934323,"mc":[{"id":"1.168224334","rc":[{"batb":[[0,5.9,37.31],[1,5.8,24.1],[2,5.6,10.54]],"ltp":0.0,"tv":0.0,"id":13117429},{"batb":[[0,10.5,30.45],[1,10,35.83],[2,5.9,18.73]],"ltp":0.0,"tv":0.0,"id":13117428},{"batb":[[0,4.6,36.76],[1,4.5,41.4],[2,4.4,18.49]],"ltp":0.0,"tv":0.0,"id":17151080},{"batb":[[0,1.81,98.01],[1,1.79,97.04],[2,1.59,31.55]],"ltp":2.46,"tv":148.56,"id":17151079}]}]}
{"op":"mcm","clk":"1001558938","pt":1580637937140,"mc":[{"id":"1.168224334","rc":[{"batb":[[0,5.8,24.1],[1,5.6,10.54],[2,1.01,0.51]],"ltp":0.0,"tv":0.0,"id":13117429},{"batb":[[0,5.9,18.73],[1,1.01,0.51],[2,5.9,0]],"ltp":0.0,"tv":0.0,"id":13117428},{"batb":[[0,4.4,18.49],[1,1.01,0.51],[2,4.4,0]],"ltp":0.0,"tv":0.0,"id":17151080},{"batb":[[0,1.59,31.55],[1,1.01,0.51],[2,1.59,0]],"ltp":2.46,"tv":148.56,"id":17151079}]}]}
{"op":"mcm","clk":"1001559202","pt":1580637940146,"mc":[{"id":"1.168224334","rc":[{"batb":[[1,5.7,25.25],[2,5.6,10.54]],"ltp":0.0,"tv":0.0,"id":13117429},{"batb":[[0,6.2,34.26],[1,6,44.45],[2,5.9,18.73]],"ltp":0.0,"tv":0.0,"id":13117428},{"batb":[[1,4.3,31.33],[2,4.2,48.88]],"ltp":0.0,"tv":0.0,"id":17151080},{"batb":[[0,1.59,144.07],[1,1.58,75.64],[2,1.01,0.51]],"batl":[[0,1.88,10.23],[1,2.26,24]],"ltp":2.46,"tv":148.56,"id":17151079}]}]}
{"op":"mcm","clk":"1001560984","pt":1580637960075,"mc":[{"id":"1.168224334","rc":[{"batb":[[0,1.59,31.55],[1,1.01,0.51],[2,1.01,0]],"ltp":2.46,"tv":148.56,"id":17151079}]}]}
{"op":"mcm","clk":"1001561313","pt":1580637963413,"mc":[{"id":"1.168224334","rc":[{"trd":[[1.88,20.46]],"batb":[[0,2.14,75.5],[1,2.12,57.39],[2,1.59,31.55]],"batl":[[0,2.26,24],[1,2.26,0]],"ltp":1.88,"tv":169.02,"id":17151079}],"tv":169.02}]}
{"op":"mcm","clk":"1001561353","pt":1580637963827,"mc":[{"id":"1.168224334","rc":[{"batl":[[0,6.8,17.47],[1,10.5,7.32]],"ltp":0.0,"tv":0.0,"id":13117428},{"batb":[[2,4.2,69.49]],"batl":[[0,4.9,17.62],[1,5.3,14.95]],"ltp":0.0,"tv":0.0,"id":17151080},{"batb":[[0,2.14,100.21],[2,1.85,18.96]],"batl":[[1,2.52,17.55]],"ltp":1.88,"tv":169.02,"id":17151079}]}]}
{"op":"mcm","clk":"1001561473","pt":1580637965017,"mc":[{"id":"1.168224334","rc":[{"batl":[[0,6.6,25.13]],"ltp":0.0,"tv":0.0,"id":13117429},{"batb":[[1,6,52.85]],"batl":[[1,7.4,5.88],[2,10.5,7.32]],"ltp":0.0,"tv":0.0,"id":13117428},{"batl":[[0,4.8,10.92],[1,4.9,17.62],[2,5.3,14.95]],"ltp":0.0,"tv":0.0,"id":17151080}]}]}
{"op":"mcm","clk":"1001561603","pt":1580637966316,"mc":[{"id":"1.168224334","rc":[{"batb":[[2,2.08,38.65]],"batl":[[1,2.34,31.09],[2,2.52,17.55]],"ltp":1.88,"tv":169.02,"id":17151079}]}]}
{"op":"mcm","clk":"1001563522","pt":1580637989149,"mc":[{"id":"1.168224334","rc":[{"batb":[[0,5.5,10.78],[1,5.3,9.24],[2,1.01,0.51]],"ltp":0.0,"tv":0.0,"id":13117429},{"batb":[[0,6,8.4],[1,4.8,14.79],[2,1.01,0.51]],"batl":[[0,7.4,5.88],[1,10.5,7.32],[2,10.5,0]],"ltp":0.0,"tv":0.0,"id":13117428},{"batb":[[0,4.2,20.61],[1,4,13.44],[2,1.01,0.51]],"batl":[[1,5.3,14.95],[2,5.3,0]],"ltp":0.0,"tv":0.0,"id":17151080},{"batb":[[0,2.08,38.65],[1,1.85,18.96],[2,1.01,0.51]],"batl":[[0,2.34,31.09],[1,2.52,17.55],[2,2.52,0]],"ltp":1.88,"tv":169.02,"id":17151079}]}]}
{"op":"mcm","clk":"1001563566","pt":1580637989723,"mc":[{"id":"1.168224334","rc":[{"batb":[[1,1.01,0.51],[2,1.01,0]],"batl":[[0,6.6,18.41]],"ltp":0.0,"tv":0.0,"id":13117429},{"batb":[[0,4.8,14.79],[1,1.01,0.51],[2,1.01,0]],"batl":[[0,10.5,7.32],[1,10.5,0]],"ltp":0.0,"tv":0.0,"id":13117428},{"batb":[[1,1.01,0.51],[2,1.01,0]],"batl":[[0,5.3,14.95],[1,5.3,0]],"ltp":0.0,"tv":0.0,"id":17151080},{"batb":[[0,1.85,18.96],[1,1.01,0.51],[2,1.01,0]],"batl":[[0,2.52,17.55],[1,2.52,0]],"ltp":1.88,"tv":169.02,"id":17151079}]}]}
{"op":"mcm","clk":"1001563766","pt":1580637992232,"mc":[{"id":"1.168224334","rc":[{"batb":[[0,5.6,42.14],[1,5.5,37.84],[2,1.01,0.51]],"ltp":0.0,"tv":0.0,"id":13117429},{"batb":[[0,5.1,33.1],[1,5,34],[2,4.8,14.79]],"ltp":0.0,"tv":0.0,"id":13117428},{"batb":[[0,4.2,20.38],[1,4.1,56.87],[2,4,54.45]],"ltp":0.0,"tv":0.0,"id":17151080},{"batb":[[0,1.87,71.57],[1,1.86,18.73],[2,1.85,87.14]],"batl":[[0,2.54,17.31]],"ltp":1.88,"tv":169.02,"id":17151079}]}]}
{"op":"mcm","clk":"1001563828","pt":1580637993021,"mc":[{"id":"1.168224334","rc":[{"batb":[[0,1.86,18.73],[1,1.01,0.51],[2,1.85,0]],"ltp":1.88,"tv":169.02,"id":17151079}]}]}
{"op":"mcm","clk":"1001564094","pt":1580637996044,"mc":[{"id":"1.168224334","rc":[{"batb":[[0,2.38,71.26],[1,2.34,85.82],[2,1.86,18.73]],"ltp":1.88,"tv":169.02,"id":17151079}]}]}
{"op":"mcm","clk":"1001564186","pt":1580637997140,"mc":[{"id":"1.168224334","rc":[{"batb":[[1,5.5,27.06],[2,5.4,11.33]],"batl":[[0,6.4,27.31]],"ltp":0.0,"tv":0.0,"id":13117429},{"batb":[[0,5.1,43.18]],"batl":[[0,5.4,14.4],[1,6.2,7.56],[2,7,17]],"ltp":0.0,"tv":0.0,"id":13117428},{"batb":[[2,4,76.72]],"batl":[[0,4.6,10.92],[1,4.7,19.36],[2,5,17.23]],"ltp":0.0,"tv":0.0,"id":17151080},{"batb":[[0,2.4,17.7],[1,2.38,71.26],[2,2.34,85.82]],"batl":[[1,2.8,13.45]],"ltp":1.88,"tv":169.02,"id":17151079}]}]}
{"op":"mcm","clk":"1001564374","pt":1580637999368,"mc":[{"id":"1.168224334","rc":[{"batl":[[1,2.58,26.05],[2,2.8,13.45]],"ltp":1.88,"tv":169.02,"id":17151079}]}]}
{"op":"mcm","clk":"1001565439","pt":1580638011341,"mc":[{"id":"1.168224334","rc":[{"batb":[[0,5.6,26.36],[1,5.4,11.33],[2,5.3,9.24]],"ltp":0.0,"tv":0.0,"id":13117429},{"batb":[[0,5.1,10.08],[1,4.2,20.14],[2,1.01,0.51]],"batl":[[0,6.2,7.56],[1,7,17],[2,7,0]],"ltp":0.0,"tv":0.0,"id":13117428},{"batb":[[0,4,76.72],[1,3.9,14.28],[2,1.01,0.51]],"batl":[[1,5,17.23],[2,5,0]],"ltp":0.0,"tv":0.0,"id":17151080},{"batb":[[0,2.28,32.77],[1,2.12,25.41],[2,1.01,0.51]],"batl":[[0,2.58,26.05],[1,2.8,13.45],[2,2.8,0]],"ltp":1.88,"tv":169.02,"id":17151079}]}]}
{"op":"mcm","clk":"1001565488","pt":1580638011860,"mc":[{"id":"1.168224334","rc":[{"batb":[[2,1.01,0.51]],"batl":[[0,6.4,19.75]],"ltp":0.0,"tv":0.0,"id":13117429},{"batb":[[0,4.2,20.14],[1,1.01,0.51],[2,1.01,0]],"batl":[[0,7,17],[1,7,0]],"ltp":0.0,"tv":0.0,"id":13117428},{"batb":[[1,1.01,0.51],[2,1.01,0]],"batl":[[0,5,17.23],[1,5,0]],"ltp":0.0,"tv":0.0,"id":17151080},{"batb":[[0,2.12,25.41],[1,1.01,0.51],[2,1.01,0]],"batl":[[0,2.8,13.45],[1,2.8,0]],"ltp":1.88,"tv":169.02,"id":17151079}]}]}
{"op":"mcm","clk":"1001566091","pt":1580638018779,"mc":[{"id":"1.168224334","rc":[{"batb":[[0,5.7,35.61],[1,5.6,26.36],[2,5.4,11.33]],"ltp":0.0,"tv":0.0,"id":13117429},{"batb":[[0,5.3,46.93],[1,5.2,31.12],[2,4.2,20.14]],"ltp":0.0,"tv":0.0,"id":13117428},{"batb":[[0,4.1,63.27],[1,4,76.72],[2,1.01,0.51]],"ltp":0.0,"tv":0.0,"id":17151080},{"batb":[[0,2.32,59.7],[1,2.3,45.39],[2,2.12,25.41]],"ltp":1.88,"tv":169.02,"id":17151079}]}]}
{"op":"mcm","clk":"1001566237","pt":1580638020391,"mc":[{"id":"1.168224334","rc":[{"batb":[[0,5.6,26.36],[1,5.4,11.33],[2,1.01,0.51]],"ltp":0.0,"tv":0.0,"id":13117429},{"batb":[[0,4.2,20.14],[1,1.01,0.51],[2,4.2,0]],"ltp":0.0,"tv":0.0,"id":13117428},{"batb":[[0,4,76.72],[1,1.01,0.51],[2,1.01,0]],"ltp":0.0,"tv":0.0,"id":17151080},{"batb":[[0,2.12,25.41],[1,1.01,0.51],[2,2.12,0]],"ltp":1.88,"tv":169.02,"id":17151079}]}]}
{"op":"mcm","clk":"1001566483","pt":1580638023366,"mc":[{"id":"1.168224334","rc":[{"batb":[[1,5.5,27.46],[2,5.4,11.33]],"ltp":0.0,"tv":0.0,"id":13117429},{"batb":[[0,4.5,66.4],[1,4.4,45.22],[2,4.2,20.14]],"ltp":0.0,"tv":0.0,"id":13117428},{"batb":[[1,3.95,28.44],[2,1.01,0.51]],"ltp":0.0,"tv":0.0,"id":17151080},{"batb":[[0,2.12,99.92],[1,2.1,58.95],[2,1.01,0.51]],"ltp":1.88,"tv":169.02,"id":17151079}]}]}
{"op":"mcm","clk":"1001567054","pt":1580638029609,"mc":[{"id":"1.168224334","rc":[{"batb":[[0,5.4,11.33],[1,1.01,0.51],[2,5.4,0]],"ltp":0.0,"tv":0.0,"id":13117429},{"batb":[[0,4.2,20.14],[1,1.01,0.51],[2,4.2,0]],"ltp":0.0,"tv":0.0,"id":13117428},{"batb":[[0,4,22.27],[1,1.01,0.51],[2,1.01,0]],"ltp":0.0,"tv":0.0,"id":17151080}]}]}
{"op":"mcm","clk":"1001567415","pt":1580638033307,"mc":[{"id":"1.168224334","rc":[{"batb":[[0,5.8,39.79],[1,5.7,25.13],[2,5.5,10.94]],"batl":[[1,6.6,25.29]],"ltp":0.0,"tv":0.0,"id":13117429},{"batb":[[0,6.4,20.66],[1,6.2,42.02],[2,5.9,26.58]],"batl":[[1,7.4,5.88],[2,11,7.08]],"ltp":0.0,"tv":0.0,"id":13117428},{"batb":[[0,4.4,18.1],[1,4.3,26.86],[2,4.2,69.16]],"batl":[[0,4.8,10.92],[1,5,17.23],[2,5.3,14.71]],"ltp":0.0,"tv":0.0,"id":17151080},{"batb":[[2,2.08,38.65]],"batl":[[0,2.22,24.71],[1,2.34,31.09],[2,2.52,17.86]],"ltp":1.88,"tv":169.02,"id":17151079}]}]}
{"op":"mcm","clk":"1001568980","pt":1580638051851,"mc":[{"id":"1.168224334","rc":[{"batb":[[0,5.7,25.13],[1,5.5,10.94],[2,1.01,0.51]],"batl":[[0,6.6,18.57],[1,6.6,0]],"ltp":0.0,"tv":0.0,"id":13117429},{"batb":[[0,4.9,14.4],[1,1.01,0.51],[2,5.9,0]],"batl":[[0,11,7.08],[1,7.4,0],[2,11,0]],"ltp":0.0,"tv":0.0,"id":13117428},{"batb":[[0,4.2,20.38],[1,1.01,0.51],[2,4.2,0]],"batl":[[0,5.3,14.71],[1,5,0],[2,5.3,0]],"ltp":0.0,"tv":0.0,"id":17151080},{"batb":[[0,1.84,19.36],[1,1.01,0.51],[2,2.08,0]],"batl":[[0,2.52,17.86],[1,2.34,0],[2,2.52,0]],"ltp":1.88,"tv":169.02,"id":17151079}]}]}
{"op":"mcm","clk":"1001569173","pt":1580638054604,"mc":[{"id":"1.168224334","rc":[{"batb":[[0,5.7,34.67],[1,5.6,26.27],[2,5.5,10.94]],"ltp":0.0,"tv":0.0,"id":13117429},{"batb":[[0,5.2,32.22],[1,5.1,32.74],[2,4.9,14.4]],"ltp":0.0,"tv":0.0,"id":13117428},{"batb":[[1,4.1,48.27],[2,4,54.41]],"ltp":0.0,"tv":0.0,"id":17151080},{"batb":[[0,1.85,84.13],[1,1.84,19.36],[2,1.83,90.17]],"ltp":1.88,"tv":169.02,"id":17151079}]}]}
{"op":"mcm","clk":"1001570138","pt":1580638064947,"mc":[{"id":"1.168224334","rc":[{"batb":[[0,5.5,10.94],[1,1.01,0.51],[2,5.5,0]],"ltp":0.0,"tv":0.0,"id":13117429},{"batb":[[0,4.9,14.4],[1,1.01,0.51],[2,4.9,0]],"ltp":0.0,"tv":0.0,"id":13117428},{"batb":[[1,1.01,0.51],[2,4,0]],"ltp":0.0,"tv":0.0,"id":17151080}]}]}
{"op":"mcm","clk":"1001570445","pt":1580638068232,"mc":[{"id":"1.168224334","rc":[{"batb":[[0,6,36.07],[1,5.9,23.25],[2,5.5,10.94]],"ltp":0.0,"tv":0.0,"id":13117429},{"batb":[[0,9.6,14.52],[1,9.4,17.29],[2,4.9,14.4]],"ltp":0.0,"tv":0.0,"id":13117428},{"batb":[[0,4.5,52.26],[1,4.4,43.22],[2,4.2,20.38]],"ltp":0.0,"tv":0.0,"id":17151080}]}]}
{"op":"mcm","clk":"1001570521","pt":1580638069260,"mc":[{"id":"1.168224334","rc":[{"batb":[[2,5.7,19.91]],"batl":[[0,6.6,25.29],[1,6.8,17.55]],"ltp":0.0,"tv":0.0,"id":13117429},{"batb":[[2,8.8,7.4]],"batl":[[0,11,11.28]],"ltp":0.0,"tv":0.0,"id":13117428},{"batb":[[0,4.7,15.42],[1,4.5,52.26],[2,4.4,61.4]],"batl":[[0,5.2,9.24],[1,5.3,14.71],[2,5.9,11.72]],"ltp":0.0,"tv":0.0,"id":17151080},{"batb":[[0,1.85,132.86]],"batl":[[0,1.92,19.04],[1,2.04,40.33],[2,2.22,25.02]],"ltp":1.88,"tv":169.02,"id":17151079}]}]}
{"op":"mcm","clk":"1001572190","pt":1580638089962,"mc":[{"id":"1.168224334","rc":[{"batb":[[0,5.9,23.25],[1,5.5,10.62],[2,1.01,0.51]],"batl":[[0,6.8,17.55],[1,6.8,0]],"ltp":0.0,"tv":0.0,"id":13117429},{"batb":[[0,6,17.62],[1,1.01,0.51],[2,8.8,0]],"ltp":0.0,"tv":0.0,"id":13117428},{"batb":[[0,4.4,18.18],[1,1.01,0.51],[2,4.4,0]],"batl":[[0,5.9,11.72],[1,5.3,0],[2,5.9,0]],"ltp":0.0,"tv":0.0,"id":17151080},{"batb":[[0,1.57,33.28],[1,1.01,0.51],[2,1.83,0]],"batl":[[0,2.22,25.02],[1,2.04,0],[2,2.22,0]],"ltp":1.88,"tv":169.02,"id":17151079}]}]}
{"op":"mcm","clk":"1001572391","pt":1580638092347,"mc":[{"id":"1.168224334","rc":[{"batb":[[1,5.8,24.42],[2,5.5,10.62]],"ltp":0.0,"tv":0.0,"id":13117429},{"batb":[[0,6.4,35.1],[1,6.2,41.64],[2,6,17.62]],"ltp":0.0,"tv":0.0,"id":13117428},{"batb":[[1,4.3,29.99],[2,4.2,48.73]],"ltp":0.0,"tv":0.0,"id":17151080},{"batb":[[0,1.57,175.44],[1,1.56,79.47],[2,1.01,0.51]],"ltp":1.88,"tv":169.02,"id":17151079}]}]}
{"op":"mcm","clk":"1001573078","pt":1580638100143,"mc":[{"id":"1.168224334","rc":[{"batb":[[0,5.5,10.62],[1,1.01,0.51],[2,5.5,0]],"ltp":0.0,"tv":0.0,"id":13117429},{"batb":[[0,6,17.62],[1,1.01,0.51],[2,6,0]],"ltp":0.0,"tv":0.0,"id":13117428},{"batb":[[1,1.01,0.51],[2,4.2,0]],"ltp":0.0,"tv":0.0,"id":17151080}]}]}
{"op":"mcm","clk":"1001573315","pt":1580638102950,"mc":[{"id":"1.168224334","rc":[{"batb":[[0,6.2,44.5],[1,6,43.6],[2,5.5,10.62]],"ltp":0.0,"tv":0.0,"id":13117429},{"batb":[[0,32,3.85],[1,30,15.03],[2,6,17.62]],"ltp":0.0,"tv":0.0,"id":13117428},{"batb":[[0,5,20.81],[1,4.9,34.04],[2,4.4,18.18]],"ltp":0.0,"tv":0.0,"id":17151080}]}]}
{"op":"mcm","clk":"1001573430","pt":1580638104360,"mc":[{"id":"1.168224334","rc":[{"batb":[[2,5.8,18.8]],"batl":[[1,7,16.6]],"ltp":0.0,"tv":0.0,"id":13117429},{"batb":[[2,22,3.61]],"ltp":0.0,"tv":0.0,"id":13117428},{"batb":[[0,5.2,12.2],[1,5,20.81],[2,4.9,47.97]],"batl":[[1,6,11.17]],"ltp":0.0,"tv":0.0,"id":17151080},{"batb":[[2,1.52,38.08]],"batl":[[0,1.63,32.5],[1,1.76,25.26]],"ltp":1.88,"tv":169.02,"id":17151079}]}]}
{"op":"mcm","clk":"1001573458","pt":1580638104671,"mc":[{"id":"1.168224334","rc":[{"batl":[[1,7,23.32]],"ltp":0.0,"tv":0.0,"id":13117429},{"batl":[[0,5.7,8.4],[1,5.9,11.72],[2,6,11.17]],"ltp":0.0,"tv":0.0,"id":17151080},{"batb":[[2,1.55,75.62]],"batl":[[1,1.69,42.01],[2,1.76,25.26]],"ltp":1.88,"tv":169.02,"id":17151079}]}]}
{"op":"mcm","clk":"1001575530","pt":1580638129327,"mc":[{"id":"1.168224334","rc":[{"batb":[[0,6,43.6],[1,5.7,8.4],[2,5.6,10.39]],"batl":[[0,7,23.32],[1,7,0]],"ltp":0.0,"tv":0.0,"id":13117429},{"batb":[[0,14,6.22],[1,1.01,0.51],[2,22,0]],"ltp":0.0,"tv":0.0,"id":13117428},{"batb":[[0,4.9,13.93],[1,4.7,10.92],[2,1.01,0.51]],"batl":[[1,6,11.17],[2,6,0]],"ltp":0.0,"tv":0.0,"id":17151080},{"batb":[[0,1.55,75.62],[1,1.52,38.08],[2,1.01,0.51]],"batl":[[0,1.69,42.01],[1,1.76,25.26],[2,1.76,0]],"ltp":1.88,"tv":169.02,"id":17151079}]}]}
{"op":"mcm","clk":"1001575569","pt":1580638129743,"mc":[{"id":"1.168224334","rc":[{"batb":[[1,5.6,10.39],[2,1.01,0.51]],"batl":[[0,7,16.6]],"ltp":0.0,"tv":0.0,"id":13117429},{"batb":[[1,1.01,0.51],[2,1.01,0]],"batl":[[0,6,11.17],[1,6,0]],"ltp":0.0,"tv":0.0,"id":17151080},{"batb":[[0,1.52,38.08],[1,1.01,0.51],[2,1.01,0]],"batl":[[0,1.76,25.26],[1,1.76,0]],"ltp":1.88,"tv":169.02,"id":17151079}]}]}
{"op":"mcm","clk":"1001575792","pt":1580638132118,"mc":[{"id":"1.168224334","rc":[{"batb":[[1,4.8,29.48],[2,1.01,0.51]],"ltp":0.0,"tv":0.0,"id":17151080}]}]}
{"op":"mcm","clk":"1001576025","pt":1580638134911,"mc":[{"id":"1.168224334","rc":[{"batb":[[0,6.2,36],[1,6,43.6],[2,5.6,10.39]],"ltp":0.0,"tv":0.0,"id":13117429},{"batb":[[0,27,10.58],[1,26,10.1],[2,14,6.22]],"ltp":0.0,"tv":0.0,"id":13117428},{"batb":[[0,4.9,56.88]],"ltp":0.0,"tv":0.0,"id":17151080},{"batb":[[0,1.59,123.62],[1,1.58,75.65],[2,1.52,38.08]],"ltp":1.88,"tv":169.02,"id":17151079}]}]}
{"op":"mcm","clk":"1001576122","pt":1580638136055,"mc":[{"id":"1.168224334","rc":[{"batb":[[0,6,43.6],[1,5.6,10.39],[2,1.01,0.51]],"ltp":0.0,"tv":0.0,"id":13117429},{"batb":[[0,14,6.22],[1,1.01,0.51],[2,14,0]],"ltp":0.0,"tv":0.0,"id":13117428},{"batb":[[0,4.9,13.93]],"ltp":0.0,"tv":0.0,"id":17151080},{"batb":[[0,1.52,38.08],[1,1.01,0.51],[2,1.52,0]],"ltp":1.88,"tv":169.02,"id":17151079}]}]}
{"op":"mcm","clk":"1001576401","pt":1580638139012,"mc":[{"id":"1.168224334","rc":[{"batb":[[1,5.9,23.02],[2,5.6,10.39]],"ltp":0.0,"tv":0.0,"id":13117429},{"batb":[[0,17.5,15.04],[1,17,12.24],[2,14,6.22]],"ltp":0.0,"tv":0.0,"id":13117428},{"batb":[[2,4.7,37.35]],"ltp":0.0,"tv":0.0,"id":17151080},{"batb":[[0,1.53,83.97],[1,1.52,125.65],[2,1.01,0.51]],"ltp":1.88,"tv":169.02,"id":17151079}]}]}
{"op":"mcm","clk":"1001577420","pt":1580638150531,"mc":[{"id":"1.168224334","rc":[{"batb":[[0,5.6,10.39],[1,1.01,0.51],[2,5.6,0]],"ltp":0.0,"tv":0.0,"id":13117429},{"batb":[[0,14,6.22],[1,1.01,0.51],[2,14,0]],"ltp":0.0,"tv":0.0,"id":13117428},{"batb":[[1,1.01,0.51],[2,4.7,0]],"ltp":0.0,"tv":0.0,"id":17151080}]}]}
{"op":"mcm","clk":"1001577737","pt":1580638154364,"mc":[{"id":"1.168224334","rc":[{"batb":[[0,6.4,26.13],[1,6.2,41.01],[2,5.7,19.91]],"batl":[[1,7.2,15.58]],"ltp":0.0,"tv":0.0,"id":13117429},{"batb":[[0,55,7.12],[1,50,5.82],[2,20,5.27]],"ltp":0.0,"tv":0.0,"id":13117428},{"batb":[[0,5.3,11.57],[1,5.1,34.69],[2,5,32.47]],"batl":[[1,6.4,10.31]],"ltp":0.0,"tv":0.0,"id":17151080},{"batb":[[2,1.47,43.43]],"batl":[[0,1.57,37.14],[1,1.67,30.21]],"ltp":1.88,"tv":169.02,"id":17151079}]}]}
{"op":"mcm","clk":"1001577797","pt":1580638155041,"mc":[{"id":"1.168224334","rc":[{"batb":[[2,5.8,8.4]],"batl":[[1,7.2,22.3]],"ltp":0.0,"tv":0.0,"id":13117429},{"batl":[[0,5.9,8.4],[1,6,11.17],[2,6.4,10.31]],"ltp":0.0,"tv":0.0,"id":17151080},{"batb":[[2,1.51,82.34]],"ltp":1.88,"tv":169.02,"id":17151079}]}]}
{"op":"mcm","clk":"1001577929","pt":1580638156653,"mc":[{"id":"1.168224334","rc":[{"batl":[[1,1.63,42.01],[2,1.67,30.21]],"ltp":1.88,"tv":169.02,"id":17151079}]}]}
{"op":"mcm","clk":"1001579386","pt":1580638172395,"mc":[{"id":"1.168224334","rc":[{"batb":[[0,6.2,23.39],[1,5.8,8.4],[2,5.7,19.91]],"ltp":0.0,"tv":0.0,"id":13117429},{"batb":[[0,20,5.27],[1,1.01,0.51],[2,20,0]],"ltp":0.0,"tv":0.0,"id":13117428},{"batb":[[1,5.1,12.75],[2,4.8,10.92]],"ltp":0.0,"tv":0.0,"id":17151080},{"batb":[[0,1.52,38.08],[1,1.51,82.34],[2,1.47,43.43]],"ltp":1.88,"tv":169.02,"id":17151079}]}]}
{"op":"mcm","clk":"1001579404","pt":1580638172554,"mc":[{"id":"1.168224334","rc":[{"batl":[[0,7.2,22.3],[1,7.2,0]],"ltp":0.0,"tv":0.0,"id":13117429},{"batb":[[0,5.1,12.75],[1,4.8,10.92],[2,1.01,0.51]],"batl":[[1,6.4,10.31],[2,6.4,0]],"ltp":0.0,"tv":0.0,"id":17151080},{"batb":[[0,1.51,82.34],[1,1.47,43.43],[2,1.01,0.51]],"batl":[[0,1.63,42.01],[1,1.67,30.21],[2,1.67,0]],"ltp":1.88,"tv":169.02,"id":17151079}]}]}
{"op":"mcm","clk":"1001579499","pt":1580638173765,"mc":[{"id":"1.168224334","rc":[{"batb":[[1,5.7,19.91],[2,1.01,0.51]],"batl":[[0,7.2,15.58]],"ltp":0.0,"tv":0.0,"id":13117429},{"batb":[[1,1.01,0.51],[2,1.01,0]],"batl":[[0,6.4,10.31],[1,6.4,0]],"ltp":0.0,"tv":0.0,"id":17151080},{"batb":[[0,1.47,43.43],[1,1.01,0.51],[2,1.01,0]],"batl":[[0,1.67,30.21],[1,1.67,0]],"ltp":1.88,"tv":169.02,"id":17151079}]}]}
{"op":"mcm","clk":"1001579639","pt":1580638175378,"mc":[{"id":"1.168224334","rc":[{"batb":[[1,6,44.19],[2,5.7,19.91]],"ltp":0.0,"tv":0.0,"id":13117429},{"batb":[[0,28,3.76],[1,27,9.6],[2,20,5.27]],"ltp":0.0,"tv":0.0,"id":13117428},{"batb":[[1,4.9,36.12],[2,4.8,35.44]],"ltp":0.0,"tv":0.0,"id":17151080},{"batb":[[0,1.49,126.8],[1,1.48,97.76],[2,1.47,43.43]],"ltp":1.88,"tv":169.02,"id":17151079}]}]}
{"op":"mcm","clk":"1001580822","pt":1580638188701,"mc":[{"id":"1.168224334","rc":[{"batb":[[0,1.47,43.43],[1,1.01,0.51],[2,1.47,0]],"ltp":1.88,"tv":169.02,"id":17151079}]}]}
{"op":"mcm","clk":"1001581117","pt":1580638192332,"mc":[{"id":"1.168224334","rc":[{"batl":[[0,6.6,18.57],[1,6.8,17.31]],"ltp":0.0,"tv":0.0,"id":13117429},{"batb":[[2,4.8,49.92]],"batl":[[0,5.8,12.27],[1,6,11.41]],"ltp":0.0,"tv":0.0,"id":17151080},{"batb":[[0,1.6,115.54],[1,1.59,73.72],[2,1.53,36.9]],"batl":[[1,1.81,22.74]],"ltp":1.88,"tv":169.02,"id":17151079}]}]}
{"op":"mcm","clk":"1001581213","pt":1580638193324,"mc":[{"id":"1.168224334","rc":[{"batb":[[2,5.7,28.31]],"batl":[[2,7,6.72]],"ltp":0.0,"tv":0.0,"id":13117429},{"batl":[[0,5.7,8.4],[1,5.8,12.27],[2,6,11.41]],"ltp":0.0,"tv":0.0,"id":17151080},{"batb":[[2,1.57,73.1]],"batl":[[1,1.71,42.01],[2,1.81,22.74]],"ltp":1.88,"tv":169.02,"id":17151079}]}]}
{"op":"mcm","clk":"1001582933","pt":1580638211207,"mc":[{"id":"1.168224334","rc":[{"batb":[[0,6,25.27],[1,5.7,8.4],[2,5.5,10.62]],"batl":[[0,6.8,17.31],[1,7,6.72],[2,7,0]],"ltp":0.0,"tv":0.0,"id":13117429},{"batb":[[0,12,8.89],[1,1.01,0.51],[2,20,0]],"ltp":0.0,"tv":0.0,"id":13117428},{"batb":[[0,4.8,14.48],[1,4.7,10.92],[2,1.01,0.51]],"batl":[[1,6,11.41],[2,6,0]],"ltp":0.0,"tv":0.0,"id":17151080},{"batb":[[0,1.57,73.1],[1,1.53,36.9],[2,1.01,0.51]],"batl":[[0,1.71,42.01],[1,1.81,22.74],[2,1.81,0]],"ltp":1.88,"tv":169.02,"id":17151079}]}]}
{"op":"mcm","clk":"1001582980","pt":1580638211733,"mc":[{"id":"1.168224334","rc":[{"batb":[[1,5.5,10.62],[2,1.01,0.51]],"batl":[[1,7,0]],"ltp":0.0,"tv":0.0,"id":13117429},{"batb":[[1,1.01,0.51],[2,1.01,0]],"batl":[[0,6,11.41],[1,6,0]],"ltp":0.0,"tv":0.0,"id":17151080},{"batb":[[0,1.53,36.9],[1,1.01,0.51],[2,1.01,0]],"batl":[[0,1.81,22.74],[1,1.81,0]],"ltp":1.88,"tv":169.02,"id":17151079}]}]}
{"op":"mcm","clk":"1001583202","pt":1580638214061,"mc":[{"id":"1.168224334","rc":[{"batb":[[1,5.9,23.33],[2,5.5,10.62]],"ltp":0.0,"tv":0.0,"id":13117429},{"batb":[[0,14.5,18.57],[1,14,18.18],[2,12,8.89]],"ltp":0.0,"tv":0.0,"id":13117428},{"batb":[[1,4.7,37.28],[2,4.6,39.13]],"ltp":0.0,"tv":0.0,"id":17151080},{"batb":[[0,1.54,85.03],[1,1.53,122.24],[2,1.01,0.51]],"ltp":1.88,"tv":169.02,"id":17151079}]}]}
{"op":"mcm","clk":"1001584714","pt":1580638231409,"mc":[{"id":"1.168224334","rc":[{"batb":[[1,5.5,10.62],[2,1.01,0.51]],"ltp":0.0,"tv":0.0,"id":13117429},{"batb":[[0,12,8.89],[1,1.01,0.51],[2,12,0]],"ltp":0.0,"tv":0.0,"id":13117428},{"batb":[[1,1.01,0.51],[2,4.6,0]],"ltp":0.0,"tv":0.0,"id":17151080}]}]}
{"op":"mcm","clk":"1001584942","pt":1580638233810,"mc":[{"id":"1.168224334","rc":[{"batb":[[0,6.2,47.21],[1,6,43.49],[2,5.5,10.62]],"ltp":0.0,"tv":0.0,"id":13117429},{"batb":[[0,55,4.01],[1,50,9.24],[2,12,8.89]],"ltp":0.0,"tv":0.0,"id":13117428},{"batb":[[0,5,42.18],[1,4.9,33.67],[2,4.8,14.48]],"ltp":0.0,"tv":0.0,"id":17151080}]}]}
{"op":"mcm","clk":"1001585041","pt":1580638234903,"mc":[{"id":"1.168224334","rc":[{"batb":[[2,5.9,18.57]],"batl":[[1,7,23.09]],"ltp":0.0,"tv":0.0,"id":13117429},{"batb":[[2,18.5,6.45]],"ltp":0.0,"tv":0.0,"id":13117428},{"batb":[[0,5.2,11.88],[1,5,55.56],[2,4.9,33.67]],"batl":[[0,5.8,8.4],[1,6,11.41],[2,6.2,10.54]],"ltp":0.0,"tv":0.0,"id":17151080},{"batb":[[2,1.52,80.66]],"batl":[[0,1.59,35.96],[1,1.65,42.01],[2,1.7,28.33]],"ltp":1.88,"tv":169.02,"id":17151079}]}]}
{"op":"mcm","clk":"1001586498","pt":1580638251252,"mc":[{"id":"1.168224334","rc":[{"batb":[[0,6,43.49],[1,5.7,8.4],[2,5.6,10.39]],"batl":[[0,7,23.09],[1,7,0]],"ltp":0.0,"tv":0.0,"id":13117429},{"batb":[[0,18.5,6.45],[1,1.01,0.51],[2,18.5,0]],"ltp":0.0,"tv":0.0,"id":13117428},{"batb":[[0,5,13.38],[1,4.8,10.92],[2,1.01,0.51]],"batl":[[1,6.2,10.54],[2,6.2,0]],"ltp":0.0,"tv":0.0,"id":17151080},{"batb":[[0,1.52,80.66],[1,1.47,42.88],[2,1.01,0.51]],"batl":[[0,1.65,42.01],[1,1.7,28.33],[2,1.7,0]],"ltp":1.88,"tv":169.02,"id":17151079}]}]}
{"op":"mcm","clk":"1001586545","pt":1580638251827,"mc":[{"id":"1.168224334","rc":[{"batb":[[1,5.6,10.39],[2,1.01,0.51]],"batl":[[0,7,16.37]],"ltp":0.0,"tv":0.0,"id":13117429},{"batb":[[1,1.01,0.51],[2,1.01,0]],"batl":[[0,6.2,10.54],[1,6.2,0]],"ltp":0.0,"tv":0.0,"id":17151080},{"batb":[[0,1.47,42.88],[1,1.01,0.51],[2,1.01,0]],"batl":[[0,1.7,28.33],[1,1.7,0]],"ltp":1.88,"tv":169.02,"id":17151079}]}]}
{"op":"mcm","clk":"1001586758","pt":1580638254219,"mc":[{"id":"1.168224334","rc":[{"batb":[[1,5.9,22.99],[2,5.6,10.39]],"ltp":0.0,"tv":0.0,"id":13117429},{"batb":[[0,24,12.27],[1,23,12.91],[2,18.5,6.45]],"ltp":0.0,"tv":0.0,"id":13117428},{"batb":[[1,4.8,52.89],[2,4.7,36.92]],"ltp":0.0,"tv":0.0,"id":17151080},{"batb":[[0,1.49,154.85],[1,1.48,97.92],[2,1.47,42.88]],"ltp":1.88,"tv":169.02,"id":17151079}]}]}
{"op":"mcm","clk":"1001588434","pt":1580638271549,"mc":[{"id":"1.168224334","rc":[{"batb":[[1,5.6,10.39],[2,1.01,0.51]],"ltp":0.0,"tv":0.0,"id":13117429},{"batb":[[0,18.5,6.45],[1,1.01,0.51],[2,18.5,0]],"ltp":0.0,"tv":0.0,"id":13117428},{"batb":[[1,1.01,0.51],[2,4.7,0]],"ltp":0.0,"tv":0.0,"id":17151080},{"batb":[[0,1.47,42.88],[1,1.01,0.51],[2,1.47,0]],"ltp":1.88,"tv":169.02,"id":17151079}]}]}
{"op":"mcm","clk":"1001589130","pt":1580638279282,"mc":[{"id":"1.168224334","rc":[{"batb":[[1,5.9,23.03],[2,5.6,10.39]],"ltp":0.0,"tv":0.0,"id":13117429},{"batb":[[0,25,9.45],[1,24,12.35],[2,18.5,6.45]],"ltp":0.0,"tv":0.0,"id":13117428},{"batb":[[1,4.8,55.19],[2,4.7,36.98]],"ltp":0.0,"tv":0.0,"id":17151080},{"batb":[[0,1.49,149.88],[1,1.48,97.85],[2,1.47,42.88]],"ltp":1.88,"tv":169.02,"id":17151079}]}]}
{"op":"mcm","clk":"1001589184","pt":1580638279897,"mc":[{"id":"1.168224334","rc":[{"batb":[[0,5.6,10.39],[1,1.01,0.51],[2,5.6,0]],"ltp":0.0,"tv":0.0,"id":13117429},{"batb":[[0,18.5,6.45],[1,1.01,0.51],[2,18.5,0]],"ltp":0.0,"tv":0.0,"id":13117428},{"batb":[[1,1.01,0.51],[2,4.7,0]],"ltp":0.0,"tv":0.0,"id":17151080}]}]}
{"op":"mcm","clk":"1001589543","pt":1580638283384,"mc":[{"id":"1.168224334","rc":[{"batb":[[0,6.4,29.96],[1,6.2,40.85],[2,6,17.47]],"batl":[[1,7.2,22.14]],"ltp":0.0,"tv":0.0,"id":13117429},{"batb":[[0,30,2.48]],"ltp":0.0,"tv":0.0,"id":13117428},{"batb":[[0,5.4,10.94],[1,5.2,12.2],[2,5.1,42.34]],"batl":[[0,6,8.4],[1,6.2,10.54],[2,6.4,19.59]],"ltp":0.0,"tv":0.0,"id":17151080},{"batb":[[1,1.48,185.23]],"batl":[[0,1.53,41.7],[1,1.6,77.18]],"ltp":1.88,"tv":169.02,"id":17151079}]}]}
{"op":"mcm","clk":"1001590851","pt":1580638295415,"mc":[{"id":"1.168224334","rc":[{"batb":[[0,6.2,26.04],[1,5.8,8.4],[2,5.7,19.99]],"batl":[[0,7.2,22.14],[1,7.2,0]],"ltp":0.0,"tv":0.0,"id":13117429},{"batb":[[0,5.2,12.2],[1,5,32.1],[2,4.9,10.08]],"batl":[[1,6.4,19.59],[2,6.4,0]],"ltp":0.0,"tv":0.0,"id":17151080},{"batb":[[0,1.48,87.38],[1,1.44,46.82],[2,1.01,0.51]],"batl":[[0,1.6,77.18],[1,1.6,0]],"ltp":1.88,"tv":169.02,"id":17151079}]}]}
{"op":"mcm","clk":"1001590935","pt":1580638296401,"mc":[{"id":"1.168224334","rc":[{"batb":[[1,5.7,19.99],[2,1.01,0.51]],"batl":[[0,7.2,15.42]],"ltp":0.0,"tv":0.0,"id":13117429},{"batb":[[2,1.01,0.51]],"batl":[[0,6.4,19.59],[1,6.4,0]],"ltp":0.0,"tv":0.0,"id":17151080},{"batb":[[0,1.44,46.82],[1,1.01,0.51],[2,1.01,0]],"batl":[[0,1.6,35.17]],"ltp":1.88,"tv":169.02,"id":17151079}]}]}
{"op":"mcm","clk":"1001591096","pt":1580638298117,"mc":[{"id":"1.168224334","rc":[{"batb":[[1,6,44.06],[2,5.7,19.99]],"ltp":0.0,"tv":0.0,"id":13117429},{"batb":[[0,65,7.46],[1,60,3.28],[2,30,2.48]],"ltp":0.0,"tv":0.0,"id":13117428},{"batb":[[2,4.9,33.78]],"ltp":0.0,"tv":0.0,"id":17151080},{"batb":[[0,1.47,127.58],[1,1.46,103.75],[2,1.44,46.82]],"ltp":1.88,"tv":169.02,"id":17151079}]}]}
{"op":"mcm","clk":"1001591192","pt":1580638299191,"mc":[{"id":"1.168224334","rc":[{"batb":[[0,5.7,19.99],[1,1.01,0.51],[2,5.7,0]],"ltp":0.0,"tv":0.0,"id":13117429},{"batb":[[0,30,2.48],[1,1.01,0.51],[2,30,0]],"ltp":0.0,"tv":0.0,"id":13117428},{"batb":[[1,1.01,0.51],[2,4.9,0]],"ltp":0.0,"tv":0.0,"id":17151080}]}]}
{"op":"mcm","clk":"1001591412","pt":1580638301793,"mc":[{"id":"1.168224334","rc":[{"batb":[[0,6.6,15.6],[1,6.4,38.44],[2,5.7,19.99]],"ltp":0.0,"tv":0.0,"id":13117429},{"batb":[[0,5.2,44.98],[1,5.1,30.81],[2,1.01,0.51]],"ltp":0.0,"tv":0.0,"id":17151080}]}]}
{"op":"mcm","clk":"1001591504","pt":1580638302842,"mc":[{"id":"1.168224334","rc":[{"batb":[[2,6.2,16.44]],"batl":[[0,7.2,22.14],[1,8.6,10.86]],"ltp":0.0,"tv":0.0,"id":13117429},{"batb":[[0,1.01,0.51],[1,1.01,0]],"ltp":0.0,"tv":0.0,"id":13117428},{"batb":[[0,5.5,10.54],[1,5.2,32.78],[2,5.1,30.81]],"batl":[[0,6,8.4],[1,6.4,19.59],[2,7.6,14.16]],"ltp":0.0,"tv":0.0,"id":17151080},{"batb":[[2,1.45,93.26]],"batl":[[0,1.5,45.48],[1,1.57,42.01],[2,1.58,36.9]],"ltp":1.88,"tv":169.02,"id":17151079}]}]}
{"op":"mcm","clk":"1001592727","pt":1580638311465,"mc":[{"id":"1.168224334","rc":[{"batb":[[0,6.4,38.44],[1,6.2,16.44],[2,5.9,8.4]],"ltp":0.0,"tv":0.0,"id":13117429}]}]}
{"op":"mcm","clk":"1001593040","pt":1580638314422,"mc":[{"id":"1.168224334","rc":[{"batb":[[0,6.4,53.82],[1,6.2,56.6]],"ltp":0.0,"tv":0.0,"id":13117429}]}]}
{"op":"mcm","clk":"1001594203","pt":1580638323467,"mc":[{"id":"1.168224334","rc":[{"batb":[[0,6.4,38.45],[1,6.2,16.44]],"ltp":0.0,"tv":0.0,"id":13117429}]}]}
{"op":"mcm","clk":"1001594601","pt":1580638326493,"mc":[{"id":"1.168224334","rc":[{"batb":[[0,6.6,17.74],[1,6.4,38.45],[2,6.2,16.44]],"ltp":0.0,"tv":0.0,"id":13117429}]}]}
{"op":"mcm","clk":"1001602686","pt":1580638401905,"mc":[{"id":"1.168224334","rc":[{"batb":[[0,5.6,10.39],[1,1.01,0.51],[2,6.2,0]],"batl":[[0,8.6,10.86],[1,8.6,0]],"ltp":0.0,"tv":0.0,"id":13117429},{"batb":[[0,5,13.14],[1,1.01,0.51],[2,5.1,0]],"batl":[[0,7.6,14.16],[1,6.4,0],[2,7.6,0]],"ltp":0.0,"tv":0.0,"id":17151080},{"batb":[[0,1.35,62.47],[1,1.01,0.51],[2,1.45,0]],"batl":[[0,1.58,36.9],[1,1.57,0],[2,1.58,0]],"ltp":1.88,"tv":169.02,"id":17151079}]}]}
{"op":"mcm","clk":"1001603192","pt":1580638407201,"mc":[{"id":"1.168224334","rc":[{"batb":[[0,9,13.44],[1,1.01,0.51]],"ltp":0.0,"tv":0.0,"id":13117428}]}]}
{"op":"mcm","clk":"1001603251","pt":1580638407813,"mc":[{"id":"1.168224334","rc":[{"batb":[[0,6.8,15.61],[1,6.6,36.02],[2,5.6,10.39]],"ltp":0.0,"tv":0.0,"id":13117429},{"batb":[[0,5.4,19.24],[1,5.3,28.49],[2,5,13.14]],"ltp":0.0,"tv":0.0,"id":17151080},{"batb":[[0,1.45,124.02],[1,1.44,109.69],[2,1.35,62.47]],"ltp":1.88,"tv":169.02,"id":17151079}]}]}
{"op":"mcm","clk":"1001603510","pt":1580638410412,"mc":[{"id":"1.168224334","rc":[{"batb":[[0,5.6,10.39],[1,1.01,0.51],[2,5.6,0]],"ltp":0.0,"tv":0.0,"id":13117429},{"batb":[[0,5,13.14],[1,1.01,0.51],[2,5,0]],"ltp":0.0,"tv":0.0,"id":17151080},{"batb":[[0,1.35,62.47],[1,1.01,0.51],[2,1.35,0]],"ltp":1.88,"tv":169.02,"id":17151079}]}]}
{"op":"mcm","clk":"1001603813","pt":1580638413344,"mc":[{"id":"1.168224334","rc":[{"batb":[[0,6,20.13],[1,5.9,23.3],[2,5.6,10.39]],"ltp":0.0,"tv":0.0,"id":13117429},{"batb":[[1,4.7,54.6],[2,4.6,38.66]],"ltp":0.0,"tv":0.0,"id":17151080},{"batb":[[0,1.38,103.69],[1,1.37,137.4],[2,1.35,62.47]],"ltp":1.88,"tv":169.02,"id":17151079}]}]}
{"op":"mcm","clk":"1001604054","pt":1580638415640,"mc":[{"id":"1.168224334","rc":[{"batb":[[0,5.6,10.39],[1,1.01,0.51],[2,5.6,0]],"ltp":0.0,"tv":0.0,"id":13117429},{"batb":[[1,1.01,0.51],[2,4.6,0]],"ltp":0.0,"tv":0.0,"id":17151080}]}]}
{"op":"mcm","clk":"1001604467","pt":1580638419329,"mc":[{"id":"1.168224334","rc":[{"batb":[[0,7.6,25.74],[1,7.4,27.92],[2,7.2,11.49]],"batl":[[0,8.2,5.04],[1,8.6,10.86],[2,10.5,7.24]],"ltp":0.0,"tv":0.0,"id":13117429},{"batb":[[0,6.4,15.11],[1,6,35.89],[2,5.9,22.21]],"batl":[[0,6.8,6.72],[1,7.6,14.16],[2,9.4,8.97]],"ltp":0.0,"tv":0.0,"id":17151080},{"batb":[[0,1.38,213.76]],"batl":[[0,1.4,60.35],[1,1.48,88.98],[2,1.58,36.9]],"ltp":1.88,"tv":169.02,"id":17151079}]}]}
{"op":"mcm","clk":"1001604542","pt":1580638419910,"mc":[{"id":"1.168224334","rc":[{"batl":[[2,1.58,0]],"ltp":1.88,"tv":169.02,"id":17151079}]}]}
{"op":"mcm","clk":"1001605422","pt":1580638428330,"mc":[{"id":"1.168224334","rc":[{"batb":[[0,6.2,15.74],[1,1.01,0.51],[2,7.2,0]],"batl":[[0,10.5,7.24],[1,8.6,0],[2,10.5,0]],"ltp":0.0,"tv":0.0,"id":13117429},{"batb":[[0,5.6,20.46],[1,1.01,0.51],[2,5.9,0]],"batl":[[0,9.4,8.97],[1,7.6,0],[2,9.4,0]],"ltp":0.0,"tv":0.0,"id":17151080},{"batb":[[0,1.26,88.12],[1,1.01,0.51],[2,1.35,0]],"batl":[[0,1.48,46.97],[1,1.48,0]],"ltp":1.88,"tv":169.02,"id":17151079}]}]}
{"op":"mcm","clk":"1001605731","pt":1580638431356,"mc":[{"id":"1.168224334","rc":[{"batb":[[0,6.6,45.14],[1,6.4,37.74],[2,6.2,15.74]],"ltp":0.0,"tv":0.0,"id":13117429},{"batb":[[1,5.5,10.46],[2,5.3,33.8]],"ltp":0.0,"tv":0.0,"id":17151080},{"batb":[[0,1.28,230.71],[1,1.27,293.13],[2,1.26,88.12]],"batl":[[1,1.49,45.95]],"ltp":1.88,"tv":169.02,"id":17151079}]}]}
{"op":"mcm","clk":"1001605854","pt":1580638432359,"mc":[{"id":"1.168224334","rc":[{"batb":[[0,5.5,10.46],[1,5.3,33.8],[2,5.2,29.52]],"ltp":0.0,"tv":0.0,"id":17151080},{"batb":[[0,1.27,86.31],[1,1.01,0.51],[2,1.26,0]],"batl":[[0,1.49,45.95],[1,1.49,0]],"ltp":1.88,"tv":169.02,"id":17151079}]}]}
{"op":"mcm","clk":"1001606181","pt":1580638435326,"mc":[{"id":"1.168224334","rc":[{"batb":[[0,1.46,73.75],[1,1.45,106.07],[2,1.27,86.31]],"ltp":1.88,"tv":169.02,"id":17151079}]}]}
{"op":"mcm","clk":"1001606275","pt":1580638436255,"mc":[{"id":"1.168224334","rc":[{"batl":[[0,7.4,15.11],[1,8.8,10.39]],"ltp":0.0,"tv":0.0,"id":13117429},{"batl":[[0,6.6,19.51],[1,7.8,13.14]],"ltp":0.0,"tv":0.0,"id":17151080},{"batb":[[2,1.44,53.12]],"batl":[[1,1.59,35.96]],"ltp":1.88,"tv":169.02,"id":17151079}]}]}
{"op":"mcm","clk":"1001606326","pt":1580638436848,"mc":[{"id":"1.168224334","rc":[{"batl":[[1,7.6,5.88],[2,8.8,10.39]],"ltp":0.0,"tv":0.0,"id":13117429},{"batb":[[0,1.01,0.51],[1,1.01,0]],"ltp":0.0,"tv":0.0,"id":13117428},{"batl":[[0,6,8.4],[1,6.6,19.51],[2,7.8,13.14]],"ltp":0.0,"tv":0.0,"id":17151080},{"batb":[[2,1.44,142.23]],"batl":[[1,1.55,42.01],[2,1.59,35.96]],"ltp":1.88,"tv":169.02,"id":17151079}]}]}
{"op":"mcm","clk":"1001607778","pt":1580638450368,"mc":[{"id":"1.168224334","rc":[{"batb":[[0,6.2,15.74],[1,6,8.4],[2,5.5,10.54]],"ltp":0.0,"tv":0.0,"id":13117429},{"batb":[[1,5,10.08],[2,4.9,13.61]],"ltp":0.0,"tv":0.0,"id":17151080},{"batb":[[0,1.44,142.23],[1,1.33,65.86],[2,1.01,0.51]],"ltp":1.88,"tv":169.02,"id":17151079}]}]}
{"op":"mcm","clk":"1001607832","pt":1580638450780,"mc":[{"id":"1.168224334","rc":[{"batb":[[0,6,8.4],[1,5.5,10.54],[2,1.01,0.51]],"batl":[[0,7.6,5.88],[1,8.8,10.39],[2,8.8,0]],"ltp":0.0,"tv":0.0,"id":13117429},{"batb":[[0,5,10.08],[1,4.9,13.61],[2,1.01,0.51]],"batl":[[1,7.8,13.14],[2,7.8,0]],"ltp":0.0,"tv":0.0,"id":17151080},{"batb":[[0,1.44,94.94]],"batl":[[0,1.55,42.01],[1,1.59,35.96],[2,1.59,0]],"ltp":1.88,"tv":169.02,"id":17151079}]}]}
{"op":"mcm","clk":"1001607976","pt":1580638451886,"mc":[{"id":"1.168224334","rc":[{"batb":[[0,5.5,10.54],[1,1.01,0.51],[2,1.01,0]],"batl":[[0,8.8,10.39],[1,8.8,0]],"ltp":0.0,"tv":0.0,"id":13117429},{"batb":[[0,4.9,13.61],[1,1.01,0.51],[2,1.01,0]],"batl":[[0,7.8,13.14],[1,7.8,0]],"ltp":0.0,"tv":0.0,"id":17151080},{"batb":[[0,1.33,65.86],[1,1.01,0.51],[2,1.01,0]],"batl":[[0,1.59,35.96],[1,1.59,0]],"ltp":1.88,"tv":169.02,"id":17151079}]}]}
{"op":"mcm","clk":"1001608129","pt":1580638453286,"mc":[{"id":"1.168224334","rc":[{"batb":[[0,6,25.69],[1,5.9,23.22],[2,5.5,10.54]],"ltp":0.0,"tv":0.0,"id":13117429},{"batb":[[1,4.7,51.51],[2,4.6,38.71]],"ltp":0.0,"tv":0.0,"id":17151080},{"batb":[[0,1.35,135.37],[1,1.34,153.55],[2,1.33,65.86]],"ltp":1.88,"tv":169.02,"id":17151079}]}]}
{"op":"mcm","clk":"1001608729","pt":1580638458269,"mc":[{"id":"1.168224334","rc":[{"batb":[[0,1.33,65.86],[1,1.01,0.51],[2,1.33,0]],"ltp":1.88,"tv":169.02,"id":17151079}]}]}
{"op":"mcm","clk":"1001609083","pt":1580638461187,"mc":[{"id":"1.168224334","rc":[{"batb":[[0,1.54,128.75],[1,1.53,85.33],[2,1.33,65.86]],"ltp":1.88,"tv":169.02,"id":17151079}]}]}
{"op":"mcm","clk":"1001609184","pt":1580638461918,"mc":[{"id":"1.168224334","rc":[{"batl":[[0,6.4,19.67],[1,7.6,14.4]],"ltp":0.0,"tv":0.0,"id":13117429},{"batl":[[0,5.6,13.06],[1,6.6,18.96]],"ltp":0.0,"tv":0.0,"id":17151080},{"batb":[[1,1.53,122.15],[2,1.43,48.94]],"batl":[[1,1.68,29.35]],"ltp":1.88,"tv":169.02,"id":17151079}]}]}
{"op":"mcm","clk":"1001609293","pt":1580638462903,"mc":[{"id":"1.168224334","rc":[{"batb":[[2,5.6,8.4]],"batl":[[1,6.8,6.72],[2,7.6,14.4]],"ltp":0.0,"tv":0.0,"id":13117429},{"batl":[[0,5.5,9.24],[1,5.6,13.06],[2,6.6,18.96]],"ltp":0.0,"tv":0.0,"id":17151080},{"batb":[[2,1.51,82.34]],"batl":[[1,1.63,42.01],[2,1.68,29.35]],"ltp":1.88,"tv":169.02,"id":17151079}]}]}
{"op":"mcm","clk":"1001610857","pt":1580638477329,"mc":[{"id":"1.168224334","rc":[{"batb":[[0,5.6,8.4],[1,5.1,12.75],[2,1.01,0.51]],"batl":[[0,6.8,6.72],[1,7.6,14.4],[2,7.6,0]],"ltp":0.0,"tv":0.0,"id":13117429},{"batb":[[0,4.5,28.68],[1,1.01,0.51],[2,4.6,0]],"batl":[[1,6.6,18.96],[2,6.6,0]],"ltp":0.0,"tv":0.0,"id":17151080},{"batb":[[0,1.51,82.34],[1,1.43,48.94],[2,1.01,0.51]],"batl":[[0,1.63,42.01],[1,1.68,29.35],[2,1.68,0]],"ltp":1.88,"tv":169.02,"id":17151079}]}]}
{"op":"mcm","clk":"1001610956","pt":1580638478257,"mc":[{"id":"1.168224334","rc":[{"batb":[[0,5.1,12.75],[1,1.01,0.51],[2,1.01,0]],"batl":[[0,7.6,14.4],[1,7.6,0]],"ltp":0.0,"tv":0.0,"id":13117429},{"batb":[[0,4.5,16.92]],"batl":[[0,6.6,18.96],[1,6.6,0]],"ltp":0.0,"tv":0.0,"id":17151080},{"batb":[[0,1.43,48.94],[1,1.01,0.51],[2,1.01,0]],"batl":[[0,1.68,29.35],[1,1.68,0]],"ltp":1.88,"tv":169.02,"id":17151079}]}]}
{"op":"mcm","clk":"1001611574","pt":1580638483259,"mc":[{"id":"1.168224334","rc":[{"batb":[[0,6,60.72],[1,5.9,22.75],[2,5.1,12.75]],"ltp":0.0,"tv":0.0,"id":13117429},{"batb":[[0,4.9,21.11],[1,4.8,35.59],[2,4.5,16.92]],"ltp":0.0,"tv":0.0,"id":17151080},{"batb":[[0,1.52,120.17],[1,1.51,89.89],[2,1.43,48.94]],"ltp":1.88,"tv":169.02,"id":17151079}]}]}
{"op":"mcm","clk":"1001611874","pt":1580638485972,"mc":[{"id":"1.168224334","rc":[{"batb":[[0,5.1,12.75],[1,1.01,0.51],[2,5.1,0]],"ltp":0.0,"tv":0.0,"id":13117429},{"batb":[[0,4.5,16.92],[1,1.01,0.51],[2,4.5,0]],"ltp":0.0,"tv":0.0,"id":17151080},{"batb":[[0,1.43,48.94],[1,1.01,0.51],[2,1.43,0]],"ltp":1.88,"tv":169.02,"id":17151079}]}]}
{"op":"mcm","clk":"1001612243","pt":1580638489245,"mc":[{"id":"1.168224334","rc":[{"batb":[[0,5.5,29.02],[1,5.4,28.21],[2,5.1,12.75]],"ltp":0.0,"tv":0.0,"id":13117429},{"batb":[[1,4.3,68.65],[2,4.2,47.52]],"ltp":0.0,"tv":0.0,"id":17151080},{"batb":[[0,1.44,137.13],[1,1.43,162.12],[2,1.01,0.51]],"ltp":1.88,"tv":169.02,"id":17151079}]}]}
{"op":"mcm","clk":"1001612357","pt":1580638490126,"mc":[{"id":"1.168224334","rc":[{"batb":[[0,1.43,48.94],[1,1.01,0.51],[2,1.01,0]],"ltp":1.88,"tv":169.02,"id":17151079}]}]}
{"op":"mcm","clk":"1001612732","pt":1580638493289,"mc":[{"id":"1.168224334","rc":[{"batb":[[0,1.62,118.19],[1,1.61,70.14],[2,1.43,48.94]],"ltp":1.88,"tv":169.02,"id":17151079}]}]}
{"op":"mcm","clk":"1001612799","pt":1580638493866,"mc":[{"id":"1.168224334","rc":[{"batl":[[0,5.8,12.27],[1,6.4,20.3]],"ltp":0.0,"tv":0.0,"id":13117429},{"batb":[[1,4.3,87.53]],"batl":[[0,5.1,16.13],[1,5.5,13.53]],"ltp":0.0,"tv":0.0,"id":17151080},{"batb":[[0,1.62,148.17],[2,1.54,35.96]],"batl":[[1,1.75,25.73]],"ltp":1.88,"tv":169.02,"id":17151079}]}]}
{"op":"mcm","clk":"1001612887","pt":1580638494871,"mc":[{"id":"1.168224334","rc":[{"batb":[[2,5.2,9.24]],"batl":[[1,6.4,27.86]],"ltp":0.0,"tv":0.0,"id":13117429},{"batb":[[2,4.2,60.12]],"batl":[[0,5.1,26.21]],"ltp":0.0,"tv":0.0,"id":17151080},{"batb":[[2,1.57,73.1]],"batl":[[1,1.7,42.01],[2,1.75,25.73]],"ltp":1.88,"tv":169.02,"id":17151079}]}]}
{"op":"mcm","clk":"1001613965","pt":1580638504307,"mc":[{"id":"1.168224334","rc":[{"batb":[[0,5.2,9.24],[1,4.8,14.79],[2,1.01,0.51]],"batl":[[0,6.4,27.86],[1,6.4,0]],"ltp":0.0,"tv":0.0,"id":13117429},{"batb":[[0,4.3,18.88],[1,4.2,44.22],[2,1.01,0.51]],"batl":[[0,5.1,10.08]],"ltp":0.0,"tv":0.0,"id":17151080},{"batb":[[0,1.57,73.1],[1,1.54,35.96],[2,1.01,0.51]],"batl":[[0,1.7,42.01],[1,1.75,25.73],[2,1.75,0]],"ltp":1.88,"tv":169.02,"id":17151079}]}]}
{"op":"mcm","clk":"1001614134","pt":1580638505884,"mc":[{"id":"1.168224334","rc":[{"batb":[[0,4.8,14.79],[1,1.01,0.51],[2,1.01,0]],"batl":[[0,6.4,20.3]],"ltp":0.0,"tv":0.0,"id":13117429},{"batb":[[1,4.2,31.62]],"batl":[[0,5.5,13.53],[1,5.5,0]],"ltp":0.0,"tv":0.0,"id":17151080},{"batb":[[0,1.54,35.96],[1,1.01,0.51],[2,1.01,0]],"batl":[[0,1.75,25.73],[1,1.75,0]],"ltp":1.88,"tv":169.02,"id":17151079}]}]}
{"op":"mcm","clk":"1001614232","pt":1580638506877,"mc":[{"id":"1.168224334","rc":[{"batb":[[0,5.2,41.48],[1,5.1,31.9],[2,4.8,14.79]],"ltp":0.0,"tv":0.0,"id":13117429},{"batb":[[2,4.1,50.99]],"ltp":0.0,"tv":0.0,"id":17151080},{"batb":[[0,1.56,66.51],[1,1.55,80.79],[2,1.54,35.96]],"ltp":1.88,"tv":169.02,"id":17151079}]}]}
{"op":"mcm","clk":"1001614352","pt":1580638507982,"mc":[{"id":"1.168224334","rc":[{"batb":[[0,4.8,14.79],[1,1.01,0.51],[2,4.8,0]],"ltp":0.0,"tv":0.0,"id":13117429},{"batb":[[1,1.01,0.51],[2,4.1,0]],"ltp":0.0,"tv":0.0,"id":17151080},{"batb":[[0,1.54,35.96],[1,1.01,0.51],[2,1.54,0]],"ltp":1.88,"tv":169.02,"id":17151079}]}]}
{"op":"mcm","clk":"1001614665","pt":1580638511105,"mc":[{"id":"1.168224334","rc":[{"batb":[[0,5.6,23.75],[1,5.5,27.15],[2,4.8,14.79]],"ltp":0.0,"tv":0.0,"id":13117429},{"batb":[[0,4.4,47.07],[1,4.3,64.22],[2,1.01,0.51]],"ltp":0.0,"tv":0.0,"id":17151080},{"batb":[[0,1.61,91.42],[1,1.6,71.7],[2,1.54,35.96]],"ltp":1.88,"tv":169.02,"id":17151079}]}]}
{"op":"mcm","clk":"1001614879","pt":1580638513101,"mc":[{"id":"1.168224334","rc":[{"batb":[[0,4.8,14.79],[1,1.01,0.51],[2,4.8,0]],"ltp":0.0,"tv":0.0,"id":13117429},{"batb":[[0,4.3,18.88],[1,1.01,0.51],[2,1.01,0]],"ltp":0.0,"tv":0.0,"id":17151080},{"batb":[[0,1.54,35.96],[1,1.01,0.51],[2,1.54,0]],"ltp":1.88,"tv":169.02,"id":17151079}]}]}
{"op":"mcm","clk":"1001615239","pt":1580638516301,"mc":[{"id":"1.168224334","rc":[{"batb":[[0,5.2,41.48],[1,5.1,31.9],[2,4.8,14.79]],"ltp":0.0,"tv":0.0,"id":13117429},{"batb":[[1,4.2,31.62],[2,4.1,50.99]],"ltp":0.0,"tv":0.0,"id":17151080},{"batb":[[0,1.56,66.51],[1,1.55,80.79],[2,1.54,35.96]],"ltp":1.88,"tv":169.02,"id":17151079}]}]}
{"op":"mcm","clk":"1001615667","pt":1580638520412,"mc":[{"id":"1.168224334","rc":[{"batb":[[0,1.54,35.96],[1,1.01,0.51],[2,1.54,0]],"ltp":1.88,"tv":169.02,"id":17151079}]}]}
{"op":"mcm","clk":"1001615927","pt":1580638522787,"mc":[{"id":"1.168224334","rc":[{"batb":[[0,1.67,113.6],[1,1.66,62.73],[2,1.54,35.96]],"ltp":1.88,"tv":169.02,"id":17151079}]}]}
{"op":"mcm","clk":"1001616058","pt":1580638524298,"mc":[{"id":"1.168224334","rc":[{"batl":[[0,5.4,14.16],[1,5.9,11.88]],"ltp":0.0,"tv":0.0,"id":13117429},{"batl":[[0,4.8,18.02],[1,5.2,15.34]],"ltp":0.0,"tv":0.0,"id":17151080},{"batb":[[0,1.68,26.28],[1,1.67,113.6],[2,1.66,62.73]],"batl":[[1,1.93,18.57]],"ltp":1.88,"tv":169.02,"id":17151079}]}]}
{"op":"mcm","clk":"1001616105","pt":1580638524920,"mc":[{"id":"1.168224334","rc":[{"batb":[[2,4.9,10.08]],"batl":[[2,6,8.4]],"ltp":0.0,"tv":0.0,"id":13117429},{"batb":[[2,4.1,64.43]],"batl":[[1,4.9,10.08],[2,5.2,15.34]],"ltp":0.0,"tv":0.0,"id":17151080},{"batl":[[1,1.78,42.01],[2,1.93,18.57]],"ltp":1.88,"tv":169.02,"id":17151079}]}]}
{"op":"mcm","clk":"1001619856","pt":1580638559833,"mc":[{"id":"1.168224334","rc":[{"batb":[[0,4.9,10.08],[1,4.8,14.79],[2,4.2,20.06]],"ltp":0.0,"tv":0.0,"id":13117429},{"batb":[[1,4.1,13.44],[2,3.85,25.18]],"ltp":0.0,"tv":0.0,"id":17151080},{"batb":[[1,1.62,67.22],[2,1.6,31.32]],"ltp":1.88,"tv":169.02,"id":17151079}]}]}
{"op":"mcm","clk":"1001620164","pt":1580638562879,"mc":[{"id":"1.168224334","rc":[{"batb":[[1,4.6,41.3],[2,4.5,42.39]],"batl":[[0,5.9,11.88],[1,6,8.4],[2,6,0]],"ltp":0.0,"tv":0.0,"id":13117429},{"batb":[[0,4.1,13.44],[1,3.85,25.18],[2,3.7,57.56]],"batl":[[0,4.9,10.08],[1,5.2,15.34],[2,5.2,0]],"ltp":0.0,"tv":0.0,"id":17151080},{"batb":[[0,1.62,67.22],[1,1.6,31.32],[2,1.59,137.2]],"batl":[[0,1.78,42.01],[1,1.93,18.57],[2,1.93,0]],"ltp":1.88,"tv":169.02,"id":17151079}]}]}
{"op":"mcm","clk":"1001620265","pt":1580638563972,"mc":[{"id":"1.168224334","rc":[{"batb":[[0,4.6,41.3],[1,4.5,42.39],[2,4.2,20.06]],"batl":[[1,6,0]],"ltp":0.0,"tv":0.0,"id":13117429},{"batb":[[0,3.85,25.18],[1,3.7,57.56],[2,3.65,33.75]],"batl":[[0,5.2,15.34],[1,5.2,0]],"ltp":0.0,"tv":0.0,"id":17151080},{"batb":[[0,1.6,31.32],[1,1.59,137.2],[2,1.58,75.34]],"batl":[[0,1.93,18.57],[1,1.93,0]],"ltp":1.88,"tv":169.02,"id":17151079}]}]}
{"op":"mcm","clk":"1001620979","pt":1580638570957,"mc":[{"id":"1.168224334","rc":[{"batb":[[0,4.2,20.06],[1,1.01,0.51],[2,4.2,0]],"ltp":0.0,"tv":0.0,"id":13117429},{"batb":[[1,1.01,0.51],[2,3.65,0]],"ltp":0.0,"tv":0.0,"id":17151080}]}]}
{"op":"mcm","clk":"1001621384","pt":1580638574391,"mc":[{"id":"1.168224334","rc":[{"batb":[[0,5.6,42.6],[1,5.5,26.9],[2,5.2,12.35]],"batl":[[1,6.4,20.3]],"ltp":0.0,"tv":0.0,"id":13117429},{"batb":[[0,4.6,16.05],[1,4.5,32.11],[2,4.4,43.22]],"batl":[[1,5.5,13.38]],"ltp":0.0,"tv":0.0,"id":17151080},{"batl":[[0,1.66,30.61],[1,1.8,23.21],[2,1.93,18.57]],"ltp":1.88,"tv":169.02,"id":17151079}]}]}
{"op":"mcm","clk":"1001621455","pt":1580638574970,"mc":[{"id":"1.168224334","rc":[{"batb":[[2,5.2,21.6]],"batl":[[1,6.4,27.86]],"ltp":0.0,"tv":0.0,"id":13117429},{"batl":[[0,5.2,24.59]],"ltp":0.0,"tv":0.0,"id":17151080},{"batl":[[1,1.7,42.01],[2,1.8,23.21]],"ltp":1.88,"tv":169.02,"id":17151079}]}]}
{"op":"mcm","clk":"1001622437","pt":1580638584982,"mc":[{"id":"1.168224334","rc":[{"batb":[[0,5.2,9.24],[1,4.6,16.37],[2,1.01,0.51]],"batl":[[0,6.4,27.86],[1,6.4,0]],"ltp":0.0,"tv":0.0,"id":13117429},{"batb":[[0,4.3,12.6],[1,4.1,20.77],[2,1.01,0.51]],"batl":[[0,5.2,9.24]],"ltp":0.0,"tv":0.0,"id":17151080},{"batb":[[0,1.56,74.78],[1,1.54,36.19],[2,1.01,0.51]],"batl":[[0,1.7,42.01],[1,1.8,23.21],[2,1.8,0]],"ltp":1.88,"tv":169.02,"id":17151079}]}]}
{"op":"mcm","clk":"1001622515","pt":1580638585933,"mc":[{"id":"1.168224334","rc":[{"batb":[[0,4.6,16.37],[1,1.01,0.51],[2,1.01,0]],"batl":[[0,6.4,20.3]],"ltp":0.0,"tv":0.0,"id":13117429},{"batb":[[0,4.1,20.77],[1,1.01,0.51],[2,1.01,0]],"batl":[[0,5.5,13.38],[1,5.5,0]],"ltp":0.0,"tv":0.0,"id":17151080},{"batb":[[0,1.54,36.19],[1,1.01,0.51],[2,1.01,0]],"batl":[[0,1.8,23.21],[1,1.8,0]],"ltp":1.88,"tv":169.02,"id":17151079}]}]}
{"op":"mcm","clk":"1001622717","pt":1580638587718,"mc":[{"id":"1.168224334","rc":[{"batb":[[0,5,53.71],[1,4.9,34.72],[2,4.6,16.37]],"ltp":0.0,"tv":0.0,"id":13117429},{"batb":[[0,4.1,46.7],[1,4,54.07],[2,1.01,0.51]],"ltp":0.0,"tv":0.0,"id":17151080},{"batb":[[0,1.54,143.12],[1,1.53,85.18],[2,1.01,0.51]],"ltp":1.88,"tv":169.02,"id":17151079}]}]}
{"op":"mcm","clk":"1001623762","pt":1580638597629,"mc":[{"id":"1.168224334","rc":[{"batb":[[0,4.6,16.37],[1,1.01,0.51],[2,4.6,0]],"ltp":0.0,"tv":0.0,"id":13117429},{"batb":[[0,4.1,20.77],[1,1.01,0.51],[2,1.01,0]],"ltp":0.0,"tv":0.0,"id":17151080},{"batb":[[0,1.54,36.19],[1,1.01,0.51],[2,1.01,0]],"ltp":1.88,"tv":169.02,"id":17151079}]}]}
{"op":"mcm","clk":"1001623882","pt":1580638598792,"mc":[{"id":"1.168224334","rc":[{"batb":[[0,10,13.44],[1,1.01,0.51]],"ltp":0.0,"tv":0.0,"id":13117428}]}]}
{"op":"mcm","clk":"1001624085","pt":1580638601001,"mc":[{"id":"1.168224334","rc":[{"batb":[[0,5.5,36.05],[1,5.4,28.12],[2,4.6,16.37]],"ltp":0.0,"tv":0.0,"id":13117429},{"batb":[[0,4.4,37.18],[1,4.3,45.5],[2,4.1,20.77]],"ltp":0.0,"tv":0.0,"id":17151080},{"batb":[[0,1.62,73.65],[1,1.61,69.99],[2,1.54,36.19]],"ltp":1.88,"tv":169.02,"id":17151079}]}]}
{"op":"mcm","clk":"1001624187","pt":1580638601947,"mc":[{"id":"1.168224334","rc":[{"batb":[[0,4.6,16.37],[1,1.01,0.51],[2,4.6,0]],"ltp":0.0,"tv":0.0,"id":13117429},{"batb":[[0,4.1,20.77],[1,1.01,0.51],[2,4.1,0]],"ltp":0.0,"tv":0.0,"id":17151080},{"batb":[[0,1.54,36.19],[1,1.01,0.51],[2,1.54,0]],"ltp":1.88,"tv":169.02,"id":17151079}]}]}
{"op":"mcm","clk":"1001624537","pt":1580638605375,"mc":[{"id":"1.168224334","rc":[{"batb":[[0,1.54,143.12],[1,1.53,85.18],[2,1.01,0.51]],"ltp":1.88,"tv":169.02,"id":17151079}]}]}
{"op":"mcm","clk":"1001624793","pt":1580638608078,"mc":[{"id":"1.168224334","rc":[{"batb":[[0,6,32.97],[1,5.9,23.13],[2,4.6,16.37]],"ltp":0.0,"tv":0.0,"id":13117429},{"batb":[[0,4.7,53.74],[1,4.6,38.66],[2,4.1,20.77]],"ltp":0.0,"tv":0.0,"id":17151080}]}]}
{"op":"mcm","clk":"1001624867","pt":1580638608946,"mc":[{"id":"1.168224334","rc":[{"batb":[[2,5.5,19.79]],"batl":[[1,6.8,24.11]],"ltp":0.0,"tv":0.0,"id":13117429},{"batb":[[0,4.9,13.93],[1,4.7,53.74],[2,4.6,38.66]],"batl":[[0,5.5,22.62],[1,5.8,12.12]],"ltp":0.0,"tv":0.0,"id":17151080},{"batb":[[2,1.51,82.34]],"batl":[[0,1.6,35.33],[1,1.64,42.01],[2,1.68,29.19]],"ltp":1.88,"tv":169.02,"id":17151079}]}]}
{"op":"mcm","clk":"1001625775","pt":1580638619166,"mc":[{"id":"1.168224334","rc":[{"batb":[[0,5.5,19.79],[1,5,13.14],[2,1.01,0.51]],"ltp":0.0,"tv":0.0,"id":13117429},{"batb":[[1,4.5,28.44],[2,1.01,0.51]],"ltp":0.0,"tv":0.0,"id":17151080},{"batb":[[0,1.54,36.19],[1,1.51,82.34],[2,1.49,40.36]],"ltp":1.88,"tv":169.02,"id":17151079}]}]}
{"op":"mcm","clk":"1001625855","pt":1580638620004,"mc":[{"id":"1.168224334","rc":[{"batb":[[0,5,13.14],[1,1.01,0.51],[2,1.01,0]],"batl":[[0,6.8,17.39],[1,6.8,0]],"ltp":0.0,"tv":0.0,"id":13117429},{"batb":[[0,4.5,16.68],[1,1.01,0.51],[2,1.01,0]],"batl":[[0,5.8,12.12],[1,5.8,0]],"ltp":0.0,"tv":0.0,"id":17151080},{"batb":[[0,1.49,40.36],[1,1.01,0.51],[2,1.49,0]],"batl":[[0,1.68,29.19],[1,1.64,0],[2,1.68,0]],"ltp":1.88,"tv":169.02,"id":17151079}]}]}
{"op":"mcm","clk":"1001626088","pt":1580638622213,"mc":[{"id":"1.168224334","rc":[{"batb":[[0,5.5,42.53],[1,5.4,28.03],[2,5,13.14]],"ltp":0.0,"tv":0.0,"id":13117429},{"batb":[[1,4.4,59.07],[2,4.3,45.12]],"ltp":0.0,"tv":0.0,"id":17151080},{"batb":[[0,1.51,78.19],[1,1.5,92.04],[2,1.49,40.36]],"ltp":1.88,"tv":169.02,"id":17151079}]}]}
{"op":"mcm","clk":"1001626176","pt":1580638623204,"mc":[{"id":"1.168224334","rc":[{"batb":[[0,5,13.14],[1,1.01,0.51],[2,5,0]],"ltp":0.0,"tv":0.0,"id":13117429},{"batb":[[1,1.01,0.51],[2,4.3,0]],"ltp":0.0,"tv":0.0,"id":17151080},{"batb":[[0,1.49,40.36],[1,1.01,0.51],[2,1.49,0]],"ltp":1.88,"tv":169.02,"id":17151079}]}]}
{"op":"mcm","clk":"1001626672","pt":1580638628278,"mc":[{"id":"1.168224334","rc":[{"batb":[[0,1.01,0.51],[1,1.01,0]],"ltp":0.0,"tv":0.0,"id":13117428}]}]}
{"op":"mcm","clk":"1001626767","pt":1580638629273,"mc":[{"id":"1.168224334","rc":[{"batb":[[0,5.5,41.66],[1,5.4,28.03],[2,5,13.14]],"ltp":0.0,"tv":0.0,"id":13117429},{"batb":[[1,4.4,57.92],[2,4.3,45.12]],"ltp":0.0,"tv":0.0,"id":17151080},{"batb":[[0,1.51,82.57],[1,1.5,92.04],[2,1.49,40.36]],"ltp":1.88,"tv":169.02,"id":17151079}]}]}
{"op":"mcm","clk":"1001627422","pt":1580638636305,"mc":[{"id":"1.168224334","rc":[{"batb":[[0,5,13.14],[1,1.01,0.51],[2,5,0]],"ltp":0.0,"tv":0.0,"id":13117429},{"batb":[[1,1.01,0.51],[2,4.3,0]],"ltp":0.0,"tv":0.0,"id":17151080}]}]}
{"op":"mcm","clk":"1001627687","pt":1580638639322,"mc":[{"id":"1.168224334","rc":[{"batb":[[0,6.2,48.88],[1,6,43.38],[2,5,13.14]],"ltp":0.0,"tv":0.0,"id":13117429},{"batb":[[0,4.9,41.48],[1,4.8,35.23],[2,4.5,16.68]],"ltp":0.0,"tv":0.0,"id":17151080}]}]}
{"op":"mcm","clk":"1001627752","pt":1580638640111,"mc":[{"id":"1.168224334","rc":[{"batb":[[2,5.8,18.65]],"batl":[[1,7.2,16.13]],"ltp":0.0,"tv":0.0,"id":13117429},{"batb":[[0,5.1,12.67],[1,4.9,55.56],[2,4.8,35.23]],"batl":[[1,5.9,11.64]],"ltp":0.0,"tv":0.0,"id":17151080},{"batl":[[0,1.55,39.34],[1,1.61,34.31]],"ltp":1.88,"tv":169.02,"id":17151079}]}]}
{"op":"mcm","clk":"1001627816","pt":1580638641001,"mc":[{"id":"1.168224334","rc":[{"batl":[[1,7.2,22.85]],"ltp":0.0,"tv":0.0,"id":13117429},{"batl":[[0,5.8,20.52]],"ltp":0.0,"tv":0.0,"id":17151080},{"batl":[[1,1.6,42.01],[2,1.61,34.31]],"ltp":1.88,"tv":169.02,"id":17151079}]}]}
{"op":"mcm","clk":"1001628715","pt":1580638653048,"mc":[{"id":"1.168224334","rc":[{"batb":[[0,6,21.56],[1,5.7,8.4],[2,5.4,11.09]],"batl":[[0,7.2,22.85],[1,7.2,0]],"ltp":0.0,"tv":0.0,"id":13117429},{"batb":[[0,4.9,14.08],[1,4.8,21.73],[2,4.7,10.92]],"batl":[[0,5.8,8.4]],"ltp":0.0,"tv":0.0,"id":17151080},{"batb":[[0,1.48,87.38],[1,1.47,42.72],[2,1.01,0.51]],"batl":[[0,1.6,42.01],[1,1.61,34.31],[2,1.61,0]],"ltp":1.88,"tv":169.02,"id":17151079}]}]}
