{"op":"mcm","clk":"998153799","pt":1580585268961,"mc":[{"id":"1.168224340","marketDefinition":{"bspMarket":false,"turnInPlayEnabled":true,"persistenceEnabled":true,"marketBaseRate":5.0,"eventId":"29681717","eventTypeId":"2","numberOfWinners":1,"bettingType":"ODDS","marketType":"SET_WINNER","marketTime":"2020-02-02T09:30:00.000Z","suspendTime":"2020-02-02T09:30:00.000Z","bspReconciled":false,"complete":true,"inPlay":false,"crossMatching":false,"runnersVoidable":false,"numberOfActiveRunners":2,"betDelay":0,"status":"OPEN","runners":[{"status":"ACTIVE","sortPriority":1,"id":6498878,"name":"Marco Trungelliti"},{"status":"ACTIVE","sortPriority":2,"id":8174333,"name":"Enzo Couacaud"}],"regulators":["MR_INT"],"countryCode":"FR","discountAllowed":false,"timezone":"UTC","openDate":"2020-02-02T09:30:00.000Z","version":3147098132,"name":"Set 1 Winner","eventName":"Trungelliti v Couacaud"},"rc":[{"batb":[[0,1.01,20]],"ltp":0.0,"tv":0.0,"id":6498878},{"batb":[[0,1.01,20]],"ltp":0.0,"tv":0.0,"id":8174333}]}]}
{"op":"mcm","clk":"998154037","pt":1580585270458,"mc":[{"id":"1.168224340","marketDefinition":{"bspMarket":false,"turnInPlayEnabled":true,"persistenceEnabled":true,"marketBaseRate":5.0,"eventId":"29681717","eventTypeId":"2","numberOfWinners":1,"bettingType":"ODDS","marketType":"SET_WINNER","marketTime":"2020-02-02T09:30:00.000Z","suspendTime":"2020-02-02T09:30:00.000Z","bspReconciled":false,"complete":true,"inPlay":false,"crossMatching":false,"runnersVoidable":false,"numberOfActiveRunners":2,"betDelay":0,"status":"OPEN","runners":[{"status":"ACTIVE","sortPriority":1,"id":6498878,"name":"Marco Trungelliti"},{"status":"ACTIVE","sortPriority":2,"id":8174333,"name":"Enzo Couacaud"}],"regulators":["MR_INT"],"countryCode":"FR","discountAllowed":false,"timezone":"UTC","openDate":"2020-02-02T09:30:00.000Z","version":3147098132,"name":"Set 1 Winner","eventName":"Trungelliti v Couacaud"}}]}
{"op":"mcm","clk":"998154461","pt":1580585272452,"mc":[{"id":"1.168224340","marketDefinition":{"bspMarket":false,"turnInPlayEnabled":true,"persistenceEnabled":true,"marketBaseRate":5.0,"eventId":"29681717","eventTypeId":"2","numberOfWinners":1,"bettingType":"ODDS","marketType":"SET_WINNER","marketTime":"2020-02-02T09:30:00.000Z","suspendTime":"2020-02-02T09:30:00.000Z","bspReconciled":false,"complete":true,"inPlay":false,"crossMatching":false,"runnersVoidable":false,"numberOfActiveRunners":2,"betDelay":0,"status":"OPEN","runners":[{"status":"ACTIVE","sortPriority":1,"id":6498878,"name":"Marco Trungelliti"},{"status":"ACTIVE","sortPriority":2,"id":8174333,"name":"Enzo Couacaud"}],"regulators":["MR_INT"],"countryCode":"FR","discountAllowed":true,"timezone":"UTC","openDate":"2020-02-02T09:30:00.000Z","version":3147098132,"name":"Set 1 Winner","eventName":"Trungelliti v Couacaud"}}]}
{"op":"mcm","clk":"998178647","pt":1580585417045,"mc":[{"id":"1.168224340","rc":[{"batb":[[0,1.01,15]],"ltp":0.0,"tv":0.0,"id":6498878},{"batb":[[0,1.01,15]],"ltp":0.0,"tv":0.0,"id":8174333}]}]}
{"op":"mcm","clk":"999887118","pt":1580602184316,"mc":[{"id":"1.168224340","rc":[{"batb":[[0,1.01,17.53]],"ltp":0.0,"tv":0.0,"id":6498878},{"batb":[[0,1.01,17.53]],"ltp":0.0,"tv":0.0,"id":8174333}]}]}
{"op":"mcm","clk":"999887184","pt":1580602185410,"mc":[{"id":"1.168224340","rc":[{"batb":[[0,1.01,15.51]],"ltp":0.0,"tv":0.0,"id":6498878},{"batb":[[0,1.01,15.51]],"ltp":0.0,"tv":0.0,"id":8174333}]}]}
{"op":"mcm","clk":"999983197","pt":1580603724270,"mc":[{"id":"1.168224340","rc":[{"batb":[[0,1.01,18.04]],"ltp":0.0,"tv":0.0,"id":6498878},{"batb":[[0,1.01,18.04]],"ltp":0.0,"tv":0.0,"id":8174333}]}]}
{"op":"mcm","clk":"999983261","pt":1580603725361,"mc":[{"id":"1.168224340","rc":[{"batb":[[0,1.01,16.01]],"ltp":0.0,"tv":0.0,"id":6498878},{"batb":[[0,1.01,16.01]],"ltp":0.0,"tv":0.0,"id":8174333}]}]}
{"op":"mcm","clk":"1000104055","pt":1580607069353,"mc":[{"id":"1.168224340","rc":[{"batb":[[0,1.01,18.01]],"ltp":0.0,"tv":0.0,"id":6498878},{"batb":[[0,1.01,18.01]],"ltp":0.0,"tv":0.0,"id":8174333}]}]}
{"op":"mcm","clk":"1000104076","pt":1580607069815,"mc":[{"id":"1.168224340","rc":[{"batb":[[0,1.01,16.02]],"ltp":0.0,"tv":0.0,"id":6498878},{"batb":[[0,1.01,16.02]],"ltp":0.0,"tv":0.0,"id":8174333}]}]}
{"op":"mcm","clk":"1001379398","pt":1580634705406,"mc":[{"id":"1.168224340","rc":[{"batl":[[0,3.4,2.27]],"ltp":0.0,"tv":0.0,"id":6498878},{"batl":[[0,2.1,7.57]],"ltp":0.0,"tv":0.0,"id":8174333}]}]}
{"op":"mcm","clk":"1001380442","pt":1580634724975,"mc":[{"id":"1.168224340","marketDefinition":{"bspMarket":false,"turnInPlayEnabled":true,"persistenceEnabled":true,"marketBaseRate":5.0,"eventId":"29681717","eventTypeId":"2","numberOfWinners":1,"bettingType":"ODDS","marketType":"SET_WINNER","marketTime":"2020-02-02T09:30:00.000Z","suspendTime":"2020-02-02T09:30:00.000Z","bspReconciled":false,"complete":true,"inPlay":false,"crossMatching":true,"runnersVoidable":false,"numberOfActiveRunners":2,"betDelay":0,"status":"OPEN","runners":[{"status":"ACTIVE","sortPriority":1,"id":6498878,"name":"Marco Trungelliti"},{"status":"ACTIVE","sortPriority":2,"id":8174333,"name":"Enzo Couacaud"}],"regulators":["MR_INT"],"countryCode":"FR","discountAllowed":true,"timezone":"UTC","openDate":"2020-02-02T09:30:00.000Z","version":3147124813,"name":"Set 1 Winner","eventName":"Trungelliti v Couacaud"}}]}
{"op":"mcm","clk":"1001405682","pt":1580635220301,"mc":[{"id":"1.168224340","rc":[{"batb":[[0,2.38,17.07],[1,1.01,16.02]],"ltp":0.0,"tv":0.0,"id":6498878},{"batb":[[0,1.63,27.38],[1,1.01,16.02]],"ltp":0.0,"tv":0.0,"id":8174333}]}]}
{"op":"mcm","clk":"1001410030","pt":1580635314173,"mc":[{"id":"1.168224340","marketDefinition":{"bspMarket":false,"turnInPlayEnabled":true,"persistenceEnabled":true,"marketBaseRate":5.0,"eventId":"29681717","eventTypeId":"2","numberOfWinners":1,"bettingType":"ODDS","marketType":"SET_WINNER","marketTime":"2020-02-02T09:19:00.000Z","suspendTime":"2020-02-02T09:19:00.000Z","bspReconciled":false,"complete":true,"inPlay":false,"crossMatching":true,"runnersVoidable":false,"numberOfActiveRunners":2,"betDelay":0,"status":"OPEN","runners":[{"status":"ACTIVE","sortPriority":1,"id":6498878,"name":"Marco Trungelliti"},{"status":"ACTIVE","sortPriority":2,"id":8174333,"name":"Enzo Couacaud"}],"regulators":["MR_INT"],"countryCode":"FR","discountAllowed":true,"timezone":"UTC","openDate":"2020-02-02T09:30:00.000Z","version":3148342588,"name":"Set 1 Winner","eventName":"Trungelliti v Couacaud"}}]}
{"op":"mcm","clk":"1001410228","pt":1580635317874,"mc":[{"id":"1.168224340","marketDefinition":{"bspMarket":false,"turnInPlayEnabled":true,"persistenceEnabled":true,"marketBaseRate":5.0,"eventId":"29681717","eventTypeId":"2","numberOfWinners":1,"bettingType":"ODDS","marketType":"SET_WINNER","marketTime":"2020-02-02T09:19:00.000Z","suspendTime":"2020-02-02T09:19:00.000Z","bspReconciled":false,"complete":true,"inPlay":false,"crossMatching":true,"runnersVoidable":false,"numberOfActiveRunners":2,"betDelay":0,"status":"OPEN","runners":[{"status":"ACTIVE","sortPriority":1,"id":6498878,"name":"Marco Trungelliti"},{"status":"ACTIVE","sortPriority":2,"id":8174333,"name":"Enzo Couacaud"}],"regulators":["MR_INT"],"countryCode":"FR","discountAllowed":true,"timezone":"UTC","openDate":"2020-02-02T09:19:00.000Z","version":3148342588,"name":"Set 1 Winner","eventName":"Trungelliti v Couacaud"}}]}
{"op":"mcm","clk":"1001420874","pt":1580635535308,"mc":[{"id":"1.168224340","rc":[{"batb":[[0,1.01,16.02],[1,1.01,0]],"ltp":0.0,"tv":0.0,"id":6498878},{"batb":[[0,1.01,16.02],[1,1.01,0]],"ltp":0.0,"tv":0.0,"id":8174333}]}]}
{"op":"mcm","clk":"1001420967","pt":1580635537142,"mc":[{"id":"1.168224340","marketDefinition":{"bspMarket":false,"turnInPlayEnabled":true,"persistenceEnabled":true,"marketBaseRate":5.0,"eventId":"29681717","eventTypeId":"2","numberOfWinners":1,"bettingType":"ODDS","marketType":"SET_WINNER","marketTime":"2020-02-02T09:19:00.000Z","suspendTime":"2020-02-02T09:19:00.000Z","bspReconciled":false,"complete":true,"inPlay":true,"crossMatching":true,"runnersVoidable":false,"numberOfActiveRunners":2,"betDelay":3,"status":"OPEN","runners":[{"status":"ACTIVE","sortPriority":1,"id":6498878,"name":"Marco Trungelliti"},{"status":"ACTIVE","sortPriority":2,"id":8174333,"name":"Enzo Couacaud"}],"regulators":["MR_INT"],"countryCode":"FR","discountAllowed":true,"timezone":"UTC","openDate":"2020-02-02T09:19:00.000Z","version":3148344085,"name":"Set 1 Winner","eventName":"Trungelliti v Couacaud"},"rc":[{"batb":[[0,1.01,15.52]],"ltp":0.0,"tv":0.0,"id":6498878},{"batb":[[0,1.01,15.52]],"ltp":0.0,"tv":0.0,"id":8174333}]}]}
{"op":"mcm","clk":"1001455502","pt":1580636224057,"mc":[{"id":"1.168224340","rc":[{"batb":[[0,2.18,35.29],[1,2,27.62],[2,1.01,15.52]],"batl":[[0,2.46,28.57]],"ltp":0.0,"tv":0.0,"id":6498878},{"batb":[[0,1.68,61.33],[1,1.57,31.79],[2,1.01,15.52]],"batl":[[0,1.86,42.01]],"ltp":0.0,"tv":0.0,"id":8174333}]}]}
{"op":"mcm","clk":"1001455549","pt":1580636225142,"mc":[{"id":"1.168224340","rc":[{"batb":[[0,1.72,373.44],[1,1.7,429.23],[2,1.68,61.33]],"batl":[[0,1.79,254.95],[1,1.81,351.81],[2,1.86,42.01]],"ltp":0.0,"tv":0.0,"id":8174333}]}]}
{"op":"mcm","clk":"1001455812","pt":1580636231266,"mc":[{"id":"1.168224340","rc":[{"batb":[[0,1.68,61.33],[1,1.57,31.79],[2,1.01,15.52]],"batl":[[0,1.86,42.01],[1,1.81,0],[2,1.86,0]],"ltp":0.0,"tv":0.0,"id":8174333}]}]}
{"op":"mcm","clk":"1001455859","pt":1580636232251,"mc":[{"id":"1.168224340","rc":[{"batb":[[0,2,27.62],[1,1.01,15.52],[2,1.01,0]],"ltp":0.0,"tv":0.0,"id":6498878},{"batb":[[0,1.57,31.79],[1,1.01,15.52],[2,1.01,0]],"ltp":0.0,"tv":0.0,"id":8174333}]}]}
{"op":"mcm","clk":"1001455959","pt":1580636234165,"mc":[{"id":"1.168224340","rc":[{"batb":[[0,1.62,296.19],[1,1.61,262.03],[2,1.57,31.79]],"batl":[[0,2.02,192.38],[1,2.04,244.13]],"ltp":0.0,"tv":0.0,"id":8174333}]}]}
{"op":"mcm","clk":"1001456138","pt":1580636238348,"mc":[{"id":"1.168224340","rc":[{"batl":[[0,1.68,360.62],[1,1.7,431.88]],"ltp":0.0,"tv":0.0,"id":8174333}]}]}
{"op":"mcm","clk":"1001456179","pt":1580636239276,"mc":[{"id":"1.168224340","rc":[{"batb":[[0,2.54,14.32],[1,2.34,31.09],[2,2.24,20.06]],"batl":[[0,2.68,24.37]],"ltp":0.0,"tv":0.0,"id":6498878},{"batb":[[2,1.6,69.74]],"batl":[[2,1.75,42.01]],"ltp":0.0,"tv":0.0,"id":8174333}]}]}
{"op":"mcm","clk":"1001456591","pt":1580636248662,"mc":[{"id":"1.168224340","rc":[{"batb":[[0,2.34,31.09],[1,2.24,20.06],[2,1.01,15.52]],"ltp":0.0,"tv":0.0,"id":6498878},{"batb":[[0,1.6,69.74],[1,1.49,38.55],[2,1.01,15.52]],"batl":[[0,1.75,42.01],[1,1.7,0],[2,1.75,0]],"ltp":0.0,"tv":0.0,"id":8174333}]}]}
{"op":"mcm","clk":"1001456652","pt":1580636250365,"mc":[{"id":"1.168224340","rc":[{"batb":[[0,2.24,20.06],[1,1.01,15.52],[2,1.01,0]],"ltp":0.0,"tv":0.0,"id":6498878},{"batb":[[0,1.49,38.55],[1,1.01,15.52],[2,1.01,0]],"ltp":0.0,"tv":0.0,"id":8174333}]}]}
{"op":"mcm","clk":"1001456711","pt":1580636251800,"mc":[{"id":"1.168224340","rc":[{"batb":[[0,1.55,281.65],[1,1.54,310.01],[2,1.5,38]],"batl":[[0,1.83,292.69],[1,1.85,328.19]],"ltp":0.0,"tv":0.0,"id":8174333}]}]}
{"op":"mcm","clk":"1001456741","pt":1580636252570,"mc":[{"id":"1.168224340","rc":[{"batb":[[0,1.5,38],[1,1.01,15.52],[2,1.5,0]],"ltp":0.0,"tv":0.0,"id":8174333}]}]}
{"op":"mcm","clk":"1001456876","pt":1580636255965,"mc":[{"id":"1.168224340","rc":[{"batb":[[0,1.64,432.62],[1,1.63,250.93],[2,1.5,38]],"batl":[[0,1.71,392.53],[1,1.73,407.11]],"ltp":0.0,"tv":0.0,"id":8174333}]}]}
{"op":"mcm","clk":"1001456907","pt":1580636256687,"mc":[{"id":"1.168224340","rc":[{"batb":[[0,1.5,38],[1,1.01,15.52],[2,1.5,0]],"ltp":0.0,"tv":0.0,"id":8174333}]}]}
{"op":"mcm","clk":"1001457017","pt":1580636259581,"mc":[{"id":"1.168224340","rc":[{"batb":[[0,1.55,281.65],[1,1.54,310.01],[2,1.5,38]],"batl":[[0,1.83,292.69],[1,1.85,328.19]],"ltp":0.0,"tv":0.0,"id":8174333}]}]}
{"op":"mcm","clk":"1001457345","pt":1580636265985,"mc":[{"id":"1.168224340","rc":[{"batl":[[0,1.6,320.06],[1,1.61,259.69]],"ltp":0.0,"tv":0.0,"id":8174333}]}]}
{"op":"mcm","clk":"1001457406","pt":1580636267322,"mc":[{"id":"1.168224340","rc":[{"batb":[[0,2.74,11.57],[1,2.52,14.48],[2,2.5,27.73]],"batl":[[0,2.88,21.85]],"ltp":0.0,"tv":0.0,"id":6498878},{"batb":[[2,1.53,78.98]],"batl":[[2,1.66,42.01]],"ltp":0.0,"tv":0.0,"id":8174333}]}]}
{"op":"mcm","clk":"1001457835","pt":1580636276346,"mc":[{"id":"1.168224340","rc":[{"batb":[[0,2.52,14.48],[1,1.01,15.52],[2,2.5,0]],"ltp":0.0,"tv":0.0,"id":6498878},{"batb":[[0,1.45,42.66],[1,1.01,15.51],[2,1.53,0]],"ltp":0.0,"tv":0.0,"id":8174333}]}]}
{"op":"mcm","clk":"1001457978","pt":1580636279336,"mc":[{"id":"1.168224340","rc":[{"batb":[[0,2.5,14.79]],"ltp":0.0,"tv":0.0,"id":6498878},{"batb":[[0,1.51,462.47],[1,1.5,345.3],[2,1.46,41.87]],"batl":[[0,1.67,296.76],[1,1.69,441.11]],"ltp":0.0,"tv":0.0,"id":8174333}]}]}
{"op":"mcm","clk":"1001458885","pt":1580636302243,"mc":[{"id":"1.168224340","rc":[{"batb":[[0,2.86,10.46],[1,2.6,13.3],[2,2.5,14.79]],"ltp":0.0,"tv":0.0,"id":6498878},{"batl":[[0,1.56,270.88],[1,1.57,284.97]],"ltp":0.0,"tv":0.0,"id":8174333}]}]}
{"op":"mcm","clk":"1001458934","pt":1580636303272,"mc":[{"id":"1.168224340","rc":[{"batb":[[1,2.62,25.21],[2,2.6,13.3]],"batl":[[0,3.05,20.16]],"ltp":0.0,"tv":0.0,"id":6498878},{"batb":[[2,1.49,85.7]],"batl":[[2,1.61,42.01]],"ltp":0.0,"tv":0.0,"id":8174333}]}]}
{"op":"mcm","clk":"1001460484","pt":1580636339123,"mc":[{"id":"1.168224340","rc":[{"batb":[[0,1.49,85.7],[1,1.46,41.71],[2,1.36,56.34]],"batl":[[0,1.61,42.01],[1,1.57,0],[2,1.61,0]],"ltp":0.0,"tv":0.0,"id":8174333}]}]}
{"op":"mcm","clk":"1001460627","pt":1580636342327,"mc":[{"id":"1.168224340","rc":[{"batb":[[2,1.41,462.34]],"batl":[[1,1.65,450.6],[2,1.66,232.68]],"ltp":0.0,"tv":0.0,"id":8174333}]}]}
{"op":"mcm","clk":"1001460641","pt":1580636342692,"mc":[{"id":"1.168224340","rc":[{"batb":[[0,2.62,25.21],[1,2.6,13.3],[2,1.01,15.52]],"ltp":0.0,"tv":0.0,"id":6498878},{"batb":[[1,1.41,462.35],[2,1.4,464.17]],"ltp":0.0,"tv":0.0,"id":8174333}]}]}
{"op":"mcm","clk":"1001460712","pt":1580636344390,"mc":[{"id":"1.168224340","rc":[{"batb":[[0,2.6,13.3],[1,1.01,15.52],[2,1.01,0]],"ltp":0.0,"tv":0.0,"id":6498878},{"batb":[[0,1.41,462.35],[1,1.4,464.17],[2,1.36,56.34]],"batl":[[0,1.65,450.6],[1,1.66,232.68],[2,1.66,0]],"ltp":0.0,"tv":0.0,"id":8174333}]}]}
{"op":"mcm","clk":"1001460789","pt":1580636346201,"mc":[{"id":"1.168224340","rc":[{"batb":[[0,2.58,13.61]],"ltp":0.0,"tv":0.0,"id":6498878},{"batb":[[0,1.37,55.4],[1,1.01,15.51],[2,1.36,0]],"ltp":0.0,"tv":0.0,"id":8174333}]}]}
{"op":"mcm","clk":"1001460920","pt":1580636349190,"mc":[{"id":"1.168224340","rc":[{"batb":[[0,1.49,421.36],[1,1.48,364.54],[2,1.37,55.39]],"batl":[[0,1.54,378.7],[1,1.55,298.37]],"ltp":0.0,"tv":0.0,"id":8174333}]}]}
{"op":"mcm","clk":"1001461129","pt":1580636352293,"mc":[{"id":"1.168224340","rc":[{"batb":[[0,1.37,55.4],[1,1.01,15.51],[2,1.37,0]],"ltp":0.0,"tv":0.0,"id":8174333}]}]}
{"op":"mcm","clk":"1001461228","pt":1580636354404,"mc":[{"id":"1.168224340","rc":[{"batb":[[0,1.41,462.35],[1,1.4,464.17],[2,1.37,55.39]],"batl":[[0,1.65,450.6],[1,1.66,232.68]],"ltp":0.0,"tv":0.0,"id":8174333}]}]}
{"op":"mcm","clk":"1001461640","pt":1580636363222,"mc":[{"id":"1.168224340","rc":[{"batb":[[0,1.37,55.4],[1,1.01,15.51],[2,1.37,0]],"ltp":0.0,"tv":0.0,"id":8174333}]}]}
{"op":"mcm","clk":"1001461747","pt":1580636366119,"mc":[{"id":"1.168224340","rc":[{"batb":[[0,1.59,286.51],[1,1.58,281.07],[2,1.37,55.4]],"ltp":0.0,"tv":0.0,"id":8174333}]}]}
{"op":"mcm","clk":"1001461801","pt":1580636367353,"mc":[{"id":"1.168224340","rc":[{"batb":[[1,2.4,16.68],[2,1.01,15.52]],"ltp":0.0,"tv":0.0,"id":6498878},{"batb":[[2,1.55,33.2]],"ltp":0.0,"tv":0.0,"id":8174333}]}]}
{"op":"mcm","clk":"1001461808","pt":1580636367417,"mc":[{"id":"1.168224340","rc":[{"batb":[[1,2.46,28.57],[2,2.4,16.68]],"batl":[[0,2.8,22.69]],"ltp":0.0,"tv":0.0,"id":6498878},{"batb":[[2,1.56,74.78]],"batl":[[2,1.68,42.01]],"ltp":0.0,"tv":0.0,"id":8174333}]}]}
{"op":"mcm","clk":"1001462392","pt":1580636383159,"mc":[{"id":"1.168224340","rc":[{"batb":[[0,2.46,28.57],[1,2.4,16.68],[2,1.01,15.52]],"ltp":0.0,"tv":0.0,"id":6498878},{"batb":[[0,1.56,74.78],[1,1.45,43.13],[2,1.01,15.51]],"batl":[[0,1.68,42.01],[1,1.66,0],[2,1.68,0]],"ltp":0.0,"tv":0.0,"id":8174333}]}]}
{"op":"mcm","clk":"1001462520","pt":1580636384562,"mc":[{"id":"1.168224340","rc":[{"batb":[[0,2.4,16.68],[1,1.01,15.52],[2,1.01,0]],"ltp":0.0,"tv":0.0,"id":6498878},{"batb":[[0,1.45,43.13],[1,1.01,15.51],[2,1.01,0]],"ltp":0.0,"tv":0.0,"id":8174333}]}]}
{"op":"mcm","clk":"1001462601","pt":1580636386372,"mc":[{"id":"1.168224340","rc":[{"batb":[[1,2.38,16.84],[2,1.01,15.52]],"ltp":0.0,"tv":0.0,"id":6498878},{"batb":[[0,1.49,487.37],[1,1.48,364.98],[2,1.45,43.12]],"batl":[[0,1.72,335.43],[1,1.74,399.73]],"ltp":0.0,"tv":0.0,"id":8174333}]}]}
{"op":"mcm","clk":"1001462620","pt":1580636386982,"mc":[{"id":"1.168224340","rc":[{"batb":[[0,2.38,16.84],[1,1.01,15.52],[2,1.01,0]],"ltp":0.0,"tv":0.0,"id":6498878},{"batb":[[0,1.45,42.66],[1,1.01,15.51],[2,1.45,0]],"ltp":0.0,"tv":0.0,"id":8174333}]}]}
{"op":"mcm","clk":"1001462741","pt":1580636390241,"mc":[{"id":"1.168224340","rc":[{"batb":[[0,1.57,292.25],[1,1.56,295.03],[2,1.45,42.66]],"batl":[[0,1.62,256.99],[1,1.63,248.78]],"ltp":0.0,"tv":0.0,"id":8174333}]}]}
{"op":"mcm","clk":"1001462866","pt":1580636394152,"mc":[{"id":"1.168224340","rc":[{"batb":[[0,1.45,42.66],[1,1.01,15.51],[2,1.45,0]],"ltp":0.0,"tv":0.0,"id":8174333}]}]}
{"op":"mcm","clk":"1001462973","pt":1580636397191,"mc":[{"id":"1.168224340","rc":[{"batb":[[0,1.49,487.37],[1,1.48,364.98],[2,1.45,42.65]],"batl":[[0,1.72,335.43],[1,1.74,399.73]],"ltp":0.0,"tv":0.0,"id":8174333}]}]}
{"op":"mcm","clk":"1001463147","pt":1580636401376,"mc":[{"id":"1.168224340","rc":[{"batb":[[0,2.9,25.41],[1,2.6,13.45],[2,1.01,15.52]],"ltp":0.0,"tv":0.0,"id":6498878},{"batl":[[0,1.54,316.8],[1,1.55,298.72]],"ltp":0.0,"tv":0.0,"id":8174333}]}]}
{"op":"mcm","clk":"1001463150","pt":1580636401476,"mc":[{"id":"1.168224340","rc":[{"batb":[[1,2.68,24.37],[2,2.6,13.45]],"batl":[[0,3.1,19.32]],"ltp":0.0,"tv":0.0,"id":6498878},{"batb":[[1,1.48,452.36]],"batl":[[2,1.59,42.01]],"ltp":0.0,"tv":0.0,"id":8174333}]}]}
{"op":"mcm","clk":"1001463631","pt":1580636413286,"mc":[{"id":"1.168224340","rc":[{"batb":[[0,1.48,87.39],[1,1.45,42.65],[2,1.34,526.4]],"batl":[[0,1.59,42.01],[1,1.55,0],[2,1.59,0]],"ltp":0.0,"tv":0.0,"id":8174333}]}]}
{"op":"mcm","clk":"1001463678","pt":1580636414115,"mc":[{"id":"1.168224340","rc":[{"batb":[[0,2.68,24.37],[1,2.6,13.45],[2,2.04,394.09]],"ltp":0.0,"tv":0.0,"id":6498878},{"batb":[[1,1.34,526.4],[2,1.01,15.51]],"ltp":0.0,"tv":0.0,"id":8174333}]}]}
{"op":"mcm","clk":"1001463704","pt":1580636414521,"mc":[{"id":"1.168224340","rc":[{"batb":[[0,2.6,13.45],[1,2.04,394.09],[2,1.01,15.52]],"ltp":0.0,"tv":0.0,"id":6498878},{"batb":[[0,1.34,526.41],[1,1.01,15.51],[2,1.01,0]],"ltp":0.0,"tv":0.0,"id":8174333}]}]}
{"op":"mcm","clk":"1001463788","pt":1580636416275,"mc":[{"id":"1.168224340","rc":[{"batb":[[0,1.37,730.44],[1,1.36,535.03],[2,1.34,526.4]],"batl":[[0,1.64,354],[1,1.65,237.97]],"ltp":0.0,"tv":0.0,"id":8174333}]}]}
{"op":"mcm","clk":"1001463837","pt":1580636417324,"mc":[{"id":"1.168224340","rc":[{"batb":[[0,1.34,526.41],[1,1.01,15.51],[2,1.34,0]],"ltp":0.0,"tv":0.0,"id":8174333}]}]}
{"op":"mcm","clk":"1001463963","pt":1580636420486,"mc":[{"id":"1.168224340","rc":[{"batb":[[0,1.47,310.74],[1,1.46,385.03],[2,1.34,526.4]],"batl":[[0,1.52,557.75],[1,1.53,312.35]],"ltp":0.0,"tv":0.0,"id":8174333}]}]}
{"op":"mcm","clk":"1001464058","pt":1580636422501,"mc":[{"id":"1.168224340","rc":[{"batb":[[0,1.34,526.41],[1,1.01,15.51],[2,1.34,0]],"ltp":0.0,"tv":0.0,"id":8174333}]}]}
{"op":"mcm","clk":"1001464206","pt":1580636425504,"mc":[{"id":"1.168224340","rc":[{"batb":[[0,1.37,735.75],[1,1.36,535.04],[2,1.34,526.4]],"batl":[[0,1.64,349.59],[1,1.65,237.97]],"ltp":0.0,"tv":0.0,"id":8174333}]}]}
{"op":"mcm","clk":"1001464629","pt":1580636433819,"mc":[{"id":"1.168224340","rc":[{"batb":[[0,1.34,526.41],[1,1.01,15.51],[2,1.34,0]],"ltp":0.0,"tv":0.0,"id":8174333}]}]}
{"op":"mcm","clk":"1001464720","pt":1580636436339,"mc":[{"id":"1.168224340","rc":[{"batb":[[0,1.34,60.99]],"ltp":0.0,"tv":0.0,"id":8174333}]}]}
{"op":"mcm","clk":"1001464756","pt":1580636437313,"mc":[{"id":"1.168224340","rc":[{"batb":[[1,2.38,17.07],[2,2.04,394.09]],"ltp":0.0,"tv":0.0,"id":6498878},{"batb":[[0,1.58,424.54],[1,1.57,288.48],[2,1.54,33.68]],"ltp":0.0,"tv":0.0,"id":8174333}]}]}
{"op":"mcm","clk":"1001464782","pt":1580636437930,"mc":[{"id":"1.168224340","rc":[{"batb":[[1,2.48,27.73],[2,2.38,17.07]],"batl":[[0,2.84,22.69]],"ltp":0.0,"tv":0.0,"id":6498878},{"batb":[[2,1.54,110.97]],"batl":[[2,1.67,42.01]],"ltp":0.0,"tv":0.0,"id":8174333}]}]}
{"op":"mcm","clk":"1001465568","pt":1580636456233,"mc":[{"id":"1.168224340","rc":[{"batb":[[0,2.48,27.73],[1,2.38,17.07],[2,2.04,394.09]],"ltp":0.0,"tv":0.0,"id":6498878},{"batb":[[0,1.54,77.3],[1,1.44,44.78],[2,1.4,451]],"batl":[[0,1.67,42.01],[1,1.65,0],[2,1.67,0]],"ltp":0.0,"tv":0.0,"id":8174333}]}]}
{"op":"mcm","clk":"1001465585","pt":1580636456545,"mc":[{"id":"1.168224340","rc":[{"batb":[[0,2.38,17.07],[1,2.04,394.09],[2,1.01,15.52]],"ltp":0.0,"tv":0.0,"id":6498878},{"batb":[[0,1.44,44.78],[1,1.4,451],[2,1.01,15.51]],"ltp":0.0,"tv":0.0,"id":8174333}]}]}
{"op":"mcm","clk":"1001465678","pt":1580636459268,"mc":[{"id":"1.168224340","rc":[{"batb":[[0,1.47,533.22],[1,1.46,386.66],[2,1.44,44.77]],"batl":[[0,1.73,381.46],[1,1.75,392]],"ltp":0.0,"tv":0.0,"id":8174333}]}]}
{"op":"mcm","clk":"1001465879","pt":1580636463184,"mc":[{"id":"1.168224340","rc":[{"batl":[[0,1.52,349.66],[1,1.53,313.63]],"ltp":0.0,"tv":0.0,"id":8174333}]}]}
{"op":"mcm","clk":"1001465919","pt":1580636464168,"mc":[{"id":"1.168224340","rc":[{"batb":[[0,2.96,23.92],[1,2.76,23.53],[2,2.58,13.69]],"batl":[[0,3.2,18.48]],"ltp":0.0,"tv":0.0,"id":6498878},{"batb":[[1,1.46,477.4]],"batl":[[2,1.57,42.01]],"ltp":0.0,"tv":0.0,"id":8174333}]}]}
{"op":"mcm","clk":"1001466518","pt":1580636477263,"mc":[{"id":"1.168224340","rc":[{"batb":[[0,2.76,23.53],[1,2.58,13.69],[2,2.04,394.09]],"ltp":0.0,"tv":0.0,"id":6498878},{"batb":[[0,1.46,90.75],[1,1.31,477.51],[2,1.3,72.31]],"batl":[[0,1.57,42.01],[1,1.53,0],[2,1.57,0]],"ltp":0.0,"tv":0.0,"id":8174333}]}]}
{"op":"mcm","clk":"1001466631","pt":1580636479378,"mc":[{"id":"1.168224340","rc":[{"batb":[[0,2.58,13.69],[1,2.04,394.09],[2,1.01,15.52]],"ltp":0.0,"tv":0.0,"id":6498878},{"batb":[[0,1.31,477.52],[1,1.3,72.31],[2,1.01,15.51]],"ltp":0.0,"tv":0.0,"id":8174333}]}]}
{"op":"mcm","clk":"1001466703","pt":1580636481277,"mc":[{"id":"1.168224340","rc":[{"batb":[[1,1.01,15.52],[2,1.01,0]],"ltp":0.0,"tv":0.0,"id":6498878}]}]}
{"op":"mcm","clk":"1001466800","pt":1580636484060,"mc":[{"id":"1.168224340","rc":[{"batb":[[0,1.44,470.22],[1,1.43,422.27],[2,1.31,477.51]],"batl":[[0,1.49,536.33],[1,1.5,337.44]],"ltp":0.0,"tv":0.0,"id":8174333}]}]}
{"op":"mcm","clk":"1001466827","pt":1580636484894,"mc":[{"id":"1.168224340","rc":[{"batb":[[1,2.22,384.52],[2,1.01,15.52]],"ltp":0.0,"tv":0.0,"id":6498878}]}]}
{"op":"mcm","clk":"1001466900","pt":1580636485976,"mc":[{"id":"1.168224340","rc":[{"batb":[[0,1.31,477.52],[1,1.3,72.31],[2,1.01,15.51]],"ltp":0.0,"tv":0.0,"id":8174333}]}]}
{"op":"mcm","clk":"1001467069","pt":1580636488961,"mc":[{"id":"1.168224340","rc":[{"batb":[[0,1.32,852.01],[1,1.31,1126.07],[2,1.3,72.31]],"batl":[[0,1.65,327.53],[1,1.66,233.09]],"ltp":0.0,"tv":0.0,"id":8174333}]}]}
{"op":"mcm","clk":"1001467975","pt":1580636502331,"mc":[{"id":"1.168224340","rc":[{"batb":[[1,1.01,15.52],[2,1.01,0]],"ltp":0.0,"tv":0.0,"id":6498878},{"batb":[[1,1.31,648.56]],"ltp":0.0,"tv":0.0,"id":8174333}]}]}
{"op":"mcm","clk":"1001468072","pt":1580636504307,"mc":[{"id":"1.168224340","rc":[{"trd":[[1.48,0.02]],"batb":[[0,1.32,852]],"batl":[[0,1.36,462.12],[1,1.37,497.62]],"ltp":1.48,"tv":0.02,"id":8174333}],"tv":0.02}]}
{"op":"mcm","clk":"1001468105","pt":1580636505023,"mc":[{"id":"1.168224340","rc":[{"batb":[[0,3.8,25.57],[1,3,23.13],[2,1.01,15.52]],"ltp":0.0,"tv":0.0,"id":6498878}]}]}
{"op":"mcm","clk":"1001468184","pt":1580636506208,"mc":[{"id":"1.168224340","rc":[{"batb":[[2,2.52,381.46]],"batl":[[0,4.1,13.44]],"ltp":0.0,"tv":0.0,"id":6498878},{"batb":[[0,1.32,983.07]],"ltp":1.48,"tv":0.02,"id":8174333}]}]}
{"op":"mcm","clk":"1001468630","pt":1580636514143,"mc":[{"id":"1.168224340","rc":[{"batb":[[0,3,23.13],[1,2.52,381.46],[2,1.01,15.52]],"ltp":0.0,"tv":0.0,"id":6498878},{"batb":[[0,1.32,131.07],[1,1.2,530.86],[2,1.16,149.26]],"ltp":1.48,"tv":0.02,"id":8174333}]}]}
{"op":"mcm","clk":"1001468657","pt":1580636514610,"mc":[{"id":"1.168224340","rc":[{"batb":[[0,1.2,530.86],[1,1.16,149.26],[2,1.01,15.51]],"ltp":1.48,"tv":0.02,"id":8174333}]}]}
{"op":"mcm","clk":"1001468710","pt":1580636515437,"mc":[{"id":"1.168224340","rc":[{"batb":[[1,1.01,15.52],[2,1.01,0]],"ltp":0.0,"tv":0.0,"id":6498878},{"batb":[[0,1.16,149.26],[1,1.01,15.51],[2,1.01,0]],"ltp":1.48,"tv":0.02,"id":8174333}]}]}
{"op":"mcm","clk":"1001468820","pt":1580636517137,"mc":[{"id":"1.168224340","rc":[{"batb":[[0,1.16,1184.63],[1,1.15,1184.69],[2,1.01,15.51]],"batl":[[0,1.52,554.49],[1,1.53,312.34]],"ltp":1.48,"tv":0.02,"id":8174333}]}]}
{"op":"mcm","clk":"1001468852","pt":1580636517915,"mc":[{"id":"1.168224340","rc":[{"batb":[[0,1.16,149.26],[1,1.01,15.51],[2,1.01,0]],"ltp":1.48,"tv":0.02,"id":8174333}]}]}
{"op":"mcm","clk":"1001468992","pt":1580636520921,"mc":[{"id":"1.168224340","rc":[{"batb":[[0,1.29,478.76],[1,1.28,729.02],[2,1.16,149.26]],"batl":[[0,1.32,473.27],[1,1.33,573.62]],"ltp":1.48,"tv":0.02,"id":8174333}]}]}
{"op":"mcm","clk":"1001469131","pt":1580636523348,"mc":[{"id":"1.168224340","rc":[{"batb":[[0,1.16,149.26],[1,1.01,15.51],[2,1.16,0]],"ltp":1.48,"tv":0.02,"id":8174333}]}]}
{"op":"mcm","clk":"1001469301","pt":1580636525729,"mc":[{"id":"1.168224340","rc":[{"batb":[[0,1.16,1184.63],[1,1.15,1184.69],[2,1.01,15.51]],"batl":[[0,1.52,554.49],[1,1.53,312.34]],"ltp":1.48,"tv":0.02,"id":8174333}]}]}
{"op":"mcm","clk":"1001471136","pt":1580636552259,"mc":[{"id":"1.168224340","rc":[{"batb":[[0,1.16,149.26],[1,1.01,15.51],[2,1.01,0]],"ltp":1.48,"tv":0.02,"id":8174333}]}]}
{"op":"mcm","clk":"1001471232","pt":1580636554956,"mc":[{"id":"1.168224340","rc":[{"batb":[[0,1.47,314.08],[1,1.46,385.02],[2,1.16,149.26]],"ltp":1.48,"tv":0.02,"id":8174333}]}]}
{"op":"mcm","clk":"1001471284","pt":1580636555994,"mc":[{"id":"1.168224340","rc":[{"batb":[[1,2.82,22.69],[2,2.6,13.45]],"batl":[[0,3.25,18.48]],"ltp":0.0,"tv":0.0,"id":6498878},{"batb":[[2,1.44,94.94]],"batl":[[2,1.55,42.01]],"ltp":1.48,"tv":0.02,"id":8174333}]}]}
{"op":"mcm","clk":"1001472470","pt":1580636579403,"mc":[{"id":"1.168224340","rc":[{"batb":[[0,1.44,94.94],[1,1.43,45.95],[2,1.31,477.51]],"batl":[[0,1.55,42.01],[1,1.53,0],[2,1.55,0]],"ltp":1.48,"tv":0.02,"id":8174333}]}]}
{"op":"mcm","clk":"1001472488","pt":1580636579918,"mc":[{"id":"1.168224340","rc":[{"batb":[[0,2.82,22.69],[1,2.6,13.45],[2,2.12,388.65]],"ltp":0.0,"tv":0.0,"id":6498878},{"batb":[[1,1.31,477.51],[2,1.29,73.57]],"ltp":1.48,"tv":0.02,"id":8174333}]}]}
{"op":"mcm","clk":"1001472549","pt":1580636580910,"mc":[{"id":"1.168224340","rc":[{"batb":[[0,2.6,13.45],[1,2.12,388.65],[2,1.01,15.52]],"ltp":0.0,"tv":0.0,"id":6498878},{"batb":[[0,1.31,477.51],[1,1.29,73.57],[2,1.01,15.51]],"ltp":1.48,"tv":0.02,"id":8174333}]}]}
{"op":"mcm","clk":"1001472661","pt":1580636582352,"mc":[{"id":"1.168224340","rc":[{"batb":[[0,1.32,604.02],[1,1.31,1122.1],[2,1.29,73.57]],"batl":[[0,1.64,262.85],[1,1.65,238.28]],"ltp":1.48,"tv":0.02,"id":8174333}]}]}
{"op":"mcm","clk":"1001473003","pt":1580636587729,"mc":[{"id":"1.168224340","rc":[{"batb":[[0,1.31,477.51],[1,1.29,73.57],[2,1.01,15.51]],"ltp":1.48,"tv":0.02,"id":8174333}]}]}
{"op":"mcm","clk":"1001473072","pt":1580636589116,"mc":[{"id":"1.168224340","rc":[{"batb":[[1,1.01,15.52],[2,1.01,0]],"ltp":0.0,"tv":0.0,"id":6498878},{"batb":[[0,1.29,73.57],[1,1.01,15.51],[2,1.01,0]],"ltp":1.48,"tv":0.02,"id":8174333}]}]}
{"op":"mcm","clk":"1001473182","pt":1580636591403,"mc":[{"id":"1.168224340","rc":[{"batb":[[0,3.85,25.02],[1,3,22.42],[2,1.01,15.52]],"ltp":0.0,"tv":0.0,"id":6498878},{"batb":[[0,1.32,604.02],[1,1.31,644.59],[2,1.29,73.57]],"batl":[[0,1.36,689.26],[1,1.37,494.64]],"ltp":1.48,"tv":0.02,"id":8174333}]}]}
{"op":"mcm","clk":"1001473188","pt":1580636591506,"mc":[{"id":"1.168224340","rc":[{"batb":[[1,3.5,16.8],[2,3,22.42]],"batl":[[0,4.1,13.44]],"ltp":0.0,"tv":0.0,"id":6498878},{"batb":[[1,1.31,779.86]],"batl":[[2,1.4,42.01]],"ltp":1.48,"tv":0.02,"id":8174333}]}]}
{"op":"mcm","clk":"1001473754","pt":1580636603348,"mc":[{"id":"1.168224340","rc":[{"batb":[[0,1.31,135.27],[1,1.29,73.57],[2,1.2,530.86]],"batl":[[0,1.4,42.01],[1,1.37,0],[2,1.4,0]],"ltp":1.48,"tv":0.02,"id":8174333}]}]}
{"op":"mcm","clk":"1001474086","pt":1580636610345,"mc":[{"id":"1.168224340","rc":[{"batb":[[0,3.5,16.8],[1,3,22.42],[2,2.52,381.46]],"ltp":0.0,"tv":0.0,"id":6498878},{"batb":[[1,1.2,530.86],[2,1.15,152.72]],"ltp":1.48,"tv":0.02,"id":8174333}]}]}
{"op":"mcm","clk":"1001474104","pt":1580636610758,"mc":[{"id":"1.168224340","rc":[{"batb":[[0,3,22.42],[1,2.52,381.46],[2,1.01,15.52]],"ltp":0.0,"tv":0.0,"id":6498878},{"batb":[[0,1.2,530.86],[1,1.15,152.72],[2,1.01,15.51]],"ltp":1.48,"tv":0.02,"id":8174333}]}]}
{"op":"mcm","clk":"1001474143","pt":1580636611735,"mc":[{"id":"1.168224340","rc":[{"batb":[[1,1.01,15.52],[2,1.01,0]],"ltp":0.0,"tv":0.0,"id":6498878},{"batb":[[0,1.15,152.72],[1,1.01,15.51],[2,1.01,0]],"ltp":1.48,"tv":0.02,"id":8174333}]}]}
{"op":"mcm","clk":"1001474495","pt":1580636620396,"mc":[{"id":"1.168224340","rc":[{"batb":[[1,2.62,379.26],[2,1.01,15.52]],"ltp":0.0,"tv":0.0,"id":6498878},{"batb":[[0,1.18,549.72],[1,1.15,152.72],[2,1.01,15.51]],"ltp":1.48,"tv":0.02,"id":8174333}]}]}
{"op":"mcm","clk":"1001475299","pt":1580636638115,"mc":[{"id":"1.168224340","rc":[{"batb":[[1,1.16,405.54],[2,1.15,858.18]],"batl":[[0,1.51,216.46],[1,1.52,160.56]],"ltp":1.48,"tv":0.02,"id":8174333}]}]}
{"op":"mcm","clk":"1001475472","pt":1580636641814,"mc":[{"id":"1.168224340","rc":[{"batb":[[1,1.15,152.72],[2,1.01,15.51]],"ltp":1.48,"tv":0.02,"id":8174333}]}]}
{"op":"mcm","clk":"1001475613","pt":1580636644287,"mc":[{"id":"1.168224340","rc":[{"batb":[[1,1.01,15.52],[2,1.01,0]],"ltp":0.0,"tv":0.0,"id":6498878},{"batb":[[0,1.15,152.72],[1,1.01,15.51],[2,1.01,0]],"ltp":1.48,"tv":0.02,"id":8174333}]}]}
{"op":"mcm","clk":"1001475662","pt":1580636645317,"mc":[{"id":"1.168224340","rc":[{"batb":[[0,6,17],[1,4.8,14.32],[2,1.01,15.52]],"ltp":0.0,"tv":0.0,"id":6498878},{"batb":[[0,1.16,405.54],[1,1.15,858.18],[2,1.12,193.64]],"batl":[[0,1.18,340.05],[1,1.19,549.47]],"ltp":1.48,"tv":0.02,"id":8174333}]}]}
{"op":"mcm","clk":"1001475673","pt":1580636645623,"mc":[{"id":"1.168224340","rc":[{"batb":[[0,6.2,7.56],[1,6,17],[2,4.8,14.32]],"batl":[[0,7.8,5.88]],"ltp":0.0,"tv":0.0,"id":6498878},{"batb":[[1,1.15,1026.22]],"batl":[[1,1.19,591.48]],"ltp":1.48,"tv":0.02,"id":8174333}]}]}
{"op":"mcm","clk":"1001477328","pt":1580636675368,"mc":[{"id":"1.168224340","rc":[{"batb":[[1,4.8,14.32],[2,3.15,373.59]],"ltp":0.0,"tv":0.0,"id":6498878},{"batb":[[0,1.15,168.04],[1,1.12,193.64],[2,1.09,779.05]],"batl":[[0,1.19,42.01],[1,1.19,0]],"ltp":1.48,"tv":0.02,"id":8174333}]}]}
{"op":"mcm","clk":"1001477372","pt":1580636676656,"mc":[{"id":"1.168224340","rc":[{"batb":[[0,4.8,14.32],[1,3.15,373.59],[2,1.01,15.52]],"ltp":0.0,"tv":0.0,"id":6498878},{"batb":[[0,1.12,193.64],[1,1.09,779.05],[2,1.01,15.51]],"ltp":1.48,"tv":0.02,"id":8174333}]}]}
{"op":"mcm","clk":"1001477488","pt":1580636678157,"mc":[{"id":"1.168224340","rc":[{"batb":[[0,1.13,612.36],[1,1.12,720.19],[2,1.09,779.05]],"batl":[[0,1.24,271.5],[1,1.25,400.67]],"ltp":1.48,"tv":0.02,"id":8174333}]}]}
{"op":"mcm","clk":"1001477679","pt":1580636680373,"mc":[{"id":"1.168224340","rc":[{"batb":[[2,1.01,15.51]],"ltp":1.48,"tv":0.02,"id":8174333}]}]}
{"op":"mcm","clk":"1001477773","pt":1580636682381,"mc":[{"id":"1.168224340","rc":[{"batl":[[0,1.15,444.42],[1,1.16,663.53]],"ltp":1.48,"tv":0.02,"id":8174333}]}]}
{"op":"mcm","clk":"1001477817","pt":1580636683363,"mc":[{"id":"1.168224340","rc":[{"batb":[[0,7.2,11.57],[1,5.7,19.59],[2,3.15,373.59]],"ltp":0.0,"tv":0.0,"id":6498878},{"batb":[[0,1.13,487.13],[2,1.1,240.29]],"batl":[[1,1.16,542.29]],"ltp":1.48,"tv":0.02,"id":8174333}]}]}
{"op":"mcm","clk":"1001477828","pt":1580636683669,"mc":[{"id":"1.168224340","rc":[{"batb":[[1,7,6.72],[2,5.7,19.59]],"batl":[[0,9.2,5.04]],"ltp":0.0,"tv":0.0,"id":6498878},{"batb":[[1,1.12,888.23]],"batl":[[1,1.16,584.3]],"ltp":1.48,"tv":0.02,"id":8174333}]}]}
{"op":"mcm","clk":"1001477876","pt":1580636684651,"mc":[{"id":"1.168224340","rc":[{"batl":[[0,1.15,447.45]],"ltp":1.48,"tv":0.02,"id":8174333}]}]}
{"op":"mcm","clk":"1001477936","pt":1580636686188,"mc":[{"id":"1.168224340","rc":[{"trd":[[1.13,578.06]],"batb":[[0,1.13,198.1],[1,1.12,1014.58]],"batl":[[0,1.15,570.55],[1,1.16,481.09]],"ltp":1.13,"tv":578.07,"id":8174333}],"tv":578.07}]}
{"op":"mcm","clk":"1001478083","pt":1580636689380,"mc":[{"id":"1.168224340","rc":[{"batb":[[0,1.13,381.29],[1,1.12,1121.37]],"batl":[[0,1.15,674.67]],"ltp":1.13,"tv":578.07,"id":8174333}]}]}
{"op":"mcm","clk":"1001478313","pt":1580636693357,"mc":[{"id":"1.168224340","rc":[{"batb":[[0,7,6.72],[1,5.7,19.59],[2,3.15,373.59]],"ltp":0.0,"tv":0.0,"id":6498878},{"batb":[[0,1.12,168.04],[1,1.1,240.29],[2,1.07,893.98]],"batl":[[0,1.15,3.03],[1,1.16,42.01]],"ltp":1.13,"tv":578.07,"id":8174333}]}]}
{"op":"mcm","clk":"1001478392","pt":1580636695362,"mc":[{"id":"1.168224340","rc":[{"batb":[[0,5.7,19.59],[1,3.15,373.59],[2,1.01,15.52]],"ltp":0.0,"tv":0.0,"id":6498878},{"batb":[[0,1.1,240.29],[1,1.07,893.98],[2,1.01,15.51]],"batl":[[1,1.16,0]],"ltp":1.13,"tv":578.07,"id":8174333}]}]}
{"op":"mcm","clk":"1001478609","pt":1580636699182,"mc":[{"id":"1.168224340","rc":[{"batb":[[0,1.13,1070.02],[1,1.1,240.29],[2,1.07,893.98]],"batl":[[1,1.16,755.46],[2,1.17,346.48]],"ltp":1.13,"tv":578.07,"id":8174333}]}]}
{"op":"mcm","clk":"1001478749","pt":1580636701194,"mc":[{"id":"1.168224340","rc":[{"batb":[[0,1.1,240.29],[1,1.07,893.98],[2,1.01,15.51]],"batl":[[1,1.16,0],[2,1.17,0]],"ltp":1.13,"tv":578.07,"id":8174333}]}]}
{"op":"mcm","clk":"1001479009","pt":1580636704208,"mc":[{"id":"1.168224340","rc":[{"batl":[[1,1.19,401.45],[2,1.2,524]],"ltp":1.13,"tv":578.07,"id":8174333}]}]}
{"op":"mcm","clk":"1001479069","pt":1580636705196,"mc":[{"id":"1.168224340","rc":[{"batb":[[1,1.01,15.51],[2,1.01,0]],"ltp":1.13,"tv":578.07,"id":8174333}]}]}
{"op":"mcm","clk":"1001479122","pt":1580636706220,"mc":[{"id":"1.168224340","rc":[{"trd":[[1.15,6.06]],"batb":[[0,1.17,272.77],[1,1.16,719.59],[2,1.1,240.29]],"batl":[[0,1.19,401.45],[1,1.2,524],[2,1.2,0]],"ltp":1.15,"tv":584.13,"id":8174333}],"tv":584.13}]}
{"op":"mcm","clk":"1001479177","pt":1580636707311,"mc":[{"id":"1.168224340","rc":[{"batb":[[1,4.4,17.86],[2,3.15,373.59]],"ltp":0.0,"tv":0.0,"id":6498878},{"batb":[[0,1.17,412.27],[2,1.13,186]],"ltp":1.15,"tv":584.13,"id":8174333}]}]}
{"op":"mcm","clk":"1001479247","pt":1580636708393,"mc":[{"id":"1.168224340","rc":[{"batb":[[0,5.8,8.4],[1,5.7,19.59],[2,4.4,17.86]],"batl":[[0,7.2,2.27]],"ltp":0.0,"tv":0.0,"id":6498878}]}]}
{"op":"mcm","clk":"1001479303","pt":1580636709585,"mc":[{"id":"1.168224340","rc":[{"batl":[[0,7.4,5.88]],"ltp":0.0,"tv":0.0,"id":6498878}]}]}
{"op":"mcm","clk":"1001479776","pt":1580636717320,"mc":[{"id":"1.168224340","rc":[{"batb":[[1,4.4,17.86],[2,3.15,373.59]],"ltp":0.0,"tv":0.0,"id":6498878},{"batb":[[0,1.17,272.77]],"ltp":1.15,"tv":584.13,"id":8174333}]}]}
{"op":"mcm","clk":"1001479781","pt":1580636717425,"mc":[{"id":"1.168224340","rc":[{"batb":[[0,1.13,186],[1,1.11,684.32],[2,1.01,15.51]],"ltp":1.15,"tv":584.13,"id":8174333}]}]}
{"op":"mcm","clk":"1001479885","pt":1580636719187,"mc":[{"id":"1.168224340","rc":[{"batb":[[0,4.4,17.86],[1,3.15,373.59],[2,1.01,15.52]],"ltp":0.0,"tv":0.0,"id":6498878}]}]}
{"op":"mcm","clk":"1001479958","pt":1580636720321,"mc":[{"id":"1.168224340","rc":[{"batb":[[0,1.13,873.11],[1,1.12,451.14],[2,1.11,684.32]],"batl":[[0,1.27,429.44],[1,1.28,351.56]],"ltp":1.15,"tv":584.13,"id":8174333}]}]}
{"op":"mcm","clk":"1001480067","pt":1580636723011,"mc":[{"id":"1.168224340","rc":[{"batb":[[2,1.01,15.51]],"ltp":1.15,"tv":584.13,"id":8174333}]}]}
{"op":"mcm","clk":"1001480148","pt":1580636724402,"mc":[{"id":"1.168224340","rc":[{"batl":[[0,1.15,401.96],[1,1.16,676.4]],"ltp":1.15,"tv":584.13,"id":8174333}]}]}
{"op":"mcm","clk":"1001480193","pt":1580636725332,"mc":[{"id":"1.168224340","rc":[{"batb":[[0,7,12.35],[1,5.4,10.94],[2,3.15,373.59]],"ltp":0.0,"tv":0.0,"id":6498878},{"batb":[[2,1.1,240.61]],"ltp":1.15,"tv":584.13,"id":8174333}]}]}
{"op":"mcm","clk":"1001480232","pt":1580636726003,"mc":[{"id":"1.168224340","rc":[{"batb":[[0,7,19.07]],"batl":[[0,9,5.04]],"ltp":0.0,"tv":0.0,"id":6498878},{"batl":[[2,1.17,42.01]],"ltp":1.15,"tv":584.13,"id":8174333}]}]}
{"op":"mcm","clk":"1001480593","pt":1580636733328,"mc":[{"id":"1.168224340","rc":[{"batb":[[0,7,6.72]],"ltp":0.0,"tv":0.0,"id":6498878},{"batb":[[0,1.1,240.61],[1,1.07,893.98],[2,1.01,15.51]],"batl":[[0,1.17,42.01],[1,1.16,0],[2,1.17,0]],"ltp":1.15,"tv":584.13,"id":8174333}]}]}
{"op":"mcm","clk":"1001480663","pt":1580636734719,"mc":[{"id":"1.168224340","rc":[{"batb":[[0,5.4,10.94],[1,3.15,373.59],[2,1.01,15.52]],"ltp":0.0,"tv":0.0,"id":6498878}]}]}
{"op":"mcm","clk":"1001480741","pt":1580636736223,"mc":[{"id":"1.168224340","rc":[{"batb":[[0,1.11,276.71],[1,1.1,1126.57],[2,1.07,893.98]],"batl":[[0,1.2,206.63],[1,1.21,501.43]],"ltp":1.15,"tv":584.13,"id":8174333}]}]}
{"op":"mcm","clk":"1001480802","pt":1580636737354,"mc":[{"id":"1.168224340","rc":[{"batb":[[0,1.1,240.61],[1,1.07,893.98],[2,1.01,15.51]],"ltp":1.15,"tv":584.13,"id":8174333}]}]}
{"op":"mcm","clk":"1001480840","pt":1580636738135,"mc":[{"id":"1.168224340","rc":[{"batb":[[1,1.01,15.51],[2,1.01,0]],"ltp":1.15,"tv":584.13,"id":8174333}]}]}
{"op":"mcm","clk":"1001480873","pt":1580636738749,"mc":[{"id":"1.168224340","rc":[{"batb":[[0,1.14,587.66],[1,1.13,541.39],[2,1.1,240.61]],"batl":[[0,1.16,378.11],[1,1.17,632.48]],"ltp":1.15,"tv":584.13,"id":8174333}]}]}
{"op":"mcm","clk":"1001480993","pt":1580636740959,"mc":[{"id":"1.168224340","rc":[{"batb":[[0,1.1,240.61],[1,1.01,15.51],[2,1.1,0]],"ltp":1.15,"tv":584.13,"id":8174333}]}]}
{"op":"mcm","clk":"1001481064","pt":1580636742249,"mc":[{"id":"1.168224340","rc":[{"batb":[[1,1.08,824.68],[2,1.01,15.51]],"ltp":1.15,"tv":584.13,"id":8174333}]}]}
{"op":"mcm","clk":"1001481184","pt":1580636744364,"mc":[{"id":"1.168224340","rc":[{"batb":[[0,1.11,276.71],[1,1.1,1126.57],[2,1.08,824.68]],"batl":[[0,1.2,206.63],[1,1.21,501.43]],"ltp":1.15,"tv":584.13,"id":8174333}]}]}
{"op":"mcm","clk":"1001482602","pt":1580636770495,"mc":[{"id":"1.168224340","rc":[{"batb":[[1,1.01,15.52],[2,1.01,0]],"ltp":0.0,"tv":0.0,"id":6498878},{"batb":[[2,1.01,15.51]],"ltp":1.15,"tv":584.13,"id":8174333}]}]}
{"op":"mcm","clk":"1001482704","pt":1580636772405,"mc":[{"id":"1.168224340","rc":[{"batl":[[0,1.13,1035.31]],"ltp":1.15,"tv":584.13,"id":8174333}]}]}
{"op":"mcm","clk":"1001482756","pt":1580636773186,"mc":[{"id":"1.168224340","rc":[{"batb":[[0,8.4,8.1],[1,7,12.12],[2,1.01,15.52]],"ltp":0.0,"tv":0.0,"id":6498878},{"batb":[[2,1.08,279.87]],"ltp":1.15,"tv":584.13,"id":8174333}]}]}
{"op":"mcm","clk":"1001482809","pt":1580636774371,"mc":[{"id":"1.168224340","rc":[{"batb":[[1,8,5.88],[2,7,12.12]],"batl":[[0,10.5,4.2]],"ltp":0.0,"tv":0.0,"id":6498878},{"batl":[[1,1.14,42.01]],"ltp":1.15,"tv":584.13,"id":8174333}]}]}
{"op":"mcm","clk":"1001483486","pt":1580636789692,"mc":[{"id":"1.168224340","rc":[{"batb":[[0,8,5.88],[1,7,12.12],[2,3.5,371.08]],"ltp":0.0,"tv":0.0,"id":6498878},{"batb":[[0,1.08,279.87],[1,1.06,955.61],[2,1.01,15.51]],"batl":[[0,1.14,42.01],[1,1.14,0]],"ltp":1.15,"tv":584.13,"id":8174333}]}]}
{"op":"mcm","clk":"1001483542","pt":1580636790838,"mc":[{"id":"1.168224340","rc":[{"batb":[[0,7,12.12],[1,3.5,371.08],[2,1.01,15.52]],"ltp":0.0,"tv":0.0,"id":6498878}]}]}
{"op":"mcm","clk":"1001483637","pt":1580636792393,"mc":[{"id":"1.168224340","rc":[{"batb":[[0,1.09,1175.88],[1,1.08,279.87],[2,1.06,955.61]],"batl":[[0,1.15,590.41],[1,1.16,519.6]],"ltp":1.15,"tv":584.13,"id":8174333}]}]}
{"op":"mcm","clk":"1001483681","pt":1580636793425,"mc":[{"id":"1.168224340","rc":[{"batb":[[0,1.08,279.87],[1,1.06,955.61],[2,1.01,15.51]],"ltp":1.15,"tv":584.13,"id":8174333}]}]}
{"op":"mcm","clk":"1001483984","pt":1580636800226,"mc":[{"id":"1.168224340","rc":[{"batb":[[0,1.09,1175.88],[1,1.08,279.87],[2,1.06,955.61]],"batl":[[0,1.15,595.73],[1,1.16,514.33]],"ltp":1.15,"tv":584.13,"id":8174333}]}]}
{"op":"mcm","clk":"1001484246","pt":1580636805025,"mc":[{"id":"1.168224340","rc":[{"batb":[[2,1.01,15.51]],"ltp":1.15,"tv":584.13,"id":8174333}]}]}
{"op":"mcm","clk":"1001484306","pt":1580636806316,"mc":[{"id":"1.168224340","rc":[{"batl":[[0,1.11,453.93],[1,1.12,694.51]],"ltp":1.15,"tv":584.13,"id":8174333}]}]}
{"op":"mcm","clk":"1001484332","pt":1580636806936,"mc":[{"id":"1.168224340","rc":[{"batb":[[0,9.2,16.21],[1,8.2,8.58],[2,3.5,371.08]],"ltp":0.0,"tv":0.0,"id":6498878},{"batb":[[2,1.06,381.29]],"ltp":1.15,"tv":584.13,"id":8174333}]}]}
{"op":"mcm","clk":"1001484374","pt":1580636807706,"mc":[{"id":"1.168224340","rc":[{"batb":[[1,9,5.04],[2,8.2,8.58]],"batl":[[0,12,3.36]],"ltp":0.0,"tv":0.0,"id":6498878},{"batb":[[0,1.09,1343.92]],"ltp":1.15,"tv":584.13,"id":8174333}]}]}
{"op":"mcm","clk":"1001489115","pt":1580636895026,"mc":[{"id":"1.168224340","rc":[{"batb":[[0,8.2,8.58],[1,3.5,371.08],[2,1.01,15.52]],"ltp":0.0,"tv":0.0,"id":6498878},{"batb":[[0,1.06,381.29],[1,1.05,1069.56],[2,1.01,15.51]],"ltp":1.15,"tv":584.13,"id":8174333}]}]}
{"op":"mcm","clk":"1001489437","pt":1580636901051,"mc":[{"id":"1.168224340","rc":[{"batb":[[0,1.09,810.65],[1,1.08,368.61],[2,1.06,381.29]],"batl":[[0,1.11,969.27],[1,1.12,183.76]],"ltp":1.15,"tv":584.13,"id":8174333}]}]}
{"op":"mcm","clk":"1001489587","pt":1580636904283,"mc":[{"id":"1.168224340","rc":[{"batb":[[0,1.06,381.29],[1,1.05,1069.56],[2,1.01,15.51]],"ltp":1.15,"tv":584.13,"id":8174333}]}]}
{"op":"mcm","clk":"1001489735","pt":1580636907159,"mc":[{"id":"1.168224340","rc":[{"batb":[[0,1.07,1197.86],[1,1.06,381.29],[2,1.05,1069.56]],"batl":[[0,1.13,701.76],[1,1.14,428.7]],"ltp":1.15,"tv":584.13,"id":8174333}]}]}
{"op":"mcm","clk":"1001490094","pt":1580636914358,"mc":[{"id":"1.168224340","rc":[{"batb":[[2,1.01,15.51]],"ltp":1.15,"tv":584.13,"id":8174333}]}]}
{"op":"mcm","clk":"1001490147","pt":1580636915282,"mc":[{"id":"1.168224340","rc":[{"batl":[[0,1.09,963.61],[1,1.1,210.34]],"ltp":1.15,"tv":584.13,"id":8174333}]}]}
{"op":"mcm","clk":"1001490199","pt":1580636916100,"mc":[{"id":"1.168224340","rc":[{"batb":[[0,11.5,9.52],[1,11,4.2],[2,9.6,14.79]],"ltp":0.0,"tv":0.0,"id":6498878},{"batb":[[2,1.04,568.48]],"batl":[[1,1.1,42.01]],"ltp":1.15,"tv":584.13,"id":8174333}]}]}
{"op":"mcm","clk":"1001490293","pt":1580636917703,"mc":[{"id":"1.168224340","rc":[{"trd":[[1.07,500]],"batb":[[0,1.07,947.86]],"ltp":1.07,"tv":1084.13,"id":8174333}],"tv":1084.13}]}
{"op":"mcm","clk":"1001490385","pt":1580636918784,"mc":[{"id":"1.168224340","rc":[{"batl":[[0,1.09,1044.8]],"ltp":1.07,"tv":1084.13,"id":8174333}]}]}
{"op":"mcm","clk":"1001490522","pt":1580636921407,"mc":[{"id":"1.168224340","rc":[{"batb":[[0,1.07,1197.86]],"batl":[[0,1.09,1134.81]],"ltp":1.07,"tv":1084.13,"id":8174333}]}]}
{"op":"mcm","clk":"1001491069","pt":1580636932223,"mc":[{"id":"1.168224340","rc":[{"batb":[[0,11,4.2],[1,9.6,14.79],[2,3.5,371.08]],"ltp":0.0,"tv":0.0,"id":6498878},{"batb":[[0,1.04,568.48],[1,1.03,1571.88],[2,1.01,15.51]],"batl":[[0,1.1,42.01],[1,1.1,0]],"ltp":1.07,"tv":1084.13,"id":8174333}]}]}
{"op":"mcm","clk":"1001491118","pt":1580636933002,"mc":[{"id":"1.168224340","rc":[{"batb":[[0,9.6,14.79],[1,3.5,371.08],[2,1.01,15.52]],"ltp":0.0,"tv":0.0,"id":6498878}]}]}
{"op":"mcm","clk":"1001491389","pt":1580636938200,"mc":[{"id":"1.168224340","rc":[{"batb":[[0,1.07,482.28],[1,1.06,722.33],[2,1.04,568.48]],"batl":[[0,1.08,557.83],[1,1.09,623.17]],"ltp":1.07,"tv":1084.13,"id":8174333}]}]}
{"op":"mcm","clk":"1001491626","pt":1580636941921,"mc":[{"id":"1.168224340","rc":[{"batb":[[0,1.04,568.48],[1,1.03,1571.88],[2,1.01,15.51]],"ltp":1.07,"tv":1084.13,"id":8174333}]}]}
{"op":"mcm","clk":"1001491828","pt":1580636944816,"mc":[{"id":"1.168224340","rc":[{"batb":[[0,1.05,871.29],[1,1.04,921.22],[2,1.03,1571.88]],"batl":[[0,1.11,1025.23]],"ltp":1.07,"tv":1084.13,"id":8174333}]}]}
{"op":"mcm","clk":"1001492128","pt":1580636949007,"mc":[{"id":"1.168224340","rc":[{"batb":[[1,1.01,15.52],[2,1.01,0]],"ltp":0.0,"tv":0.0,"id":6498878},{"batb":[[2,1.01,15.51]],"ltp":1.07,"tv":1084.13,"id":8174333}]}]}
{"op":"mcm","clk":"1001492226","pt":1580636950408,"mc":[{"id":"1.168224340","rc":[{"batb":[[0,1.05,1039.33]],"batl":[[0,1.06,808.54],[1,1.07,396.87]],"ltp":1.07,"tv":1084.13,"id":8174333}]}]}
{"op":"mcm","clk":"1001492260","pt":1580636951025,"mc":[{"id":"1.168224340","rc":[{"batb":[[0,15.5,4.8],[1,12.5,8.1],[2,1.01,15.52]],"ltp":0.0,"tv":0.0,"id":6498878}]}]}
{"op":"mcm","clk":"1001492387","pt":1580636953135,"mc":[{"id":"1.168224340","rc":[{"batb":[[2,4.1,374.13]],"ltp":0.0,"tv":0.0,"id":6498878},{"batb":[[2,1.01,4081.97]],"ltp":1.07,"tv":1084.13,"id":8174333}]}]}
{"op":"mcm","clk":"1001493172","pt":1580636963324,"mc":[{"id":"1.168224340","rc":[{"batb":[[0,12.5,8.1],[1,4.1,374.13],[2,1.01,15.52]],"ltp":0.0,"tv":0.0,"id":6498878},{"batb":[[0,1.05,168.04],[1,1.01,4081.97],[2,1.01,0]],"ltp":1.07,"tv":1084.13,"id":8174333}]}]}
{"op":"mcm","clk":"1001493273","pt":1580636964933,"mc":[{"id":"1.168224340","rc":[{"batb":[[0,1.01,4081.97],[1,1.01,0]],"ltp":1.07,"tv":1084.13,"id":8174333}]}]}
{"op":"mcm","clk":"1001493339","pt":1580636966066,"mc":[{"id":"1.168224340","rc":[{"batb":[[0,1.03,413.08],[1,1.02,839.45],[2,1.01,4081.97]],"batl":[[0,1.08,906.75],[1,1.09,277.44]],"ltp":1.07,"tv":1084.13,"id":8174333}]}]}
{"op":"mcm","clk":"1001493416","pt":1580636967256,"mc":[{"id":"1.168224340","rc":[{"batb":[[0,1.01,4081.97],[1,1.02,0],[2,1.01,0]],"ltp":1.07,"tv":1084.13,"id":8174333}]}]}
{"op":"mcm","clk":"1001493625","pt":1580636970357,"mc":[{"id":"1.168224340","rc":[{"batb":[[0,1.04,1232.42],[1,1.01,4081.97]],"batl":[[0,1.06,1209.16]],"ltp":1.07,"tv":1084.13,"id":8174333}]}]}
{"op":"mcm","clk":"1001493727","pt":1580636972065,"mc":[{"id":"1.168224340","rc":[{"batb":[[0,1.01,4081.97],[1,1.01,0]],"ltp":1.07,"tv":1084.13,"id":8174333}]}]}
{"op":"mcm","clk":"1001493908","pt":1580636975072,"mc":[{"id":"1.168224340","rc":[{"batb":[[0,1.03,412.58],[1,1.02,839.95],[2,1.01,4081.97]],"batl":[[0,1.08,907.15],[1,1.09,277.05]],"ltp":1.07,"tv":1084.13,"id":8174333}]}]}
{"op":"mcm","clk":"1001494383","pt":1580636983273,"mc":[{"id":"1.168224340","rc":[{"batb":[[2,1.01,15.51]],"ltp":1.07,"tv":1084.13,"id":8174333}]}]}
{"op":"mcm","clk":"1001494462","pt":1580636984364,"mc":[{"id":"1.168224340","rc":[{"batb":[[0,23,3.01],[1,18.5,6.29],[2,12.5,8.1]],"ltp":0.0,"tv":0.0,"id":6498878},{"batb":[[0,1.03,228.59]],"batl":[[0,1.04,1232.42]],"ltp":1.07,"tv":1084.13,"id":8174333}]}]}
{"op":"mcm","clk":"1001494475","pt":1580636984568,"mc":[{"id":"1.168224340","rc":[{"batb":[[2,4.1,374.13]],"ltp":0.0,"tv":0.0,"id":6498878}]}]}
{"op":"mcm","clk":"1001494554","pt":1580636985881,"mc":[{"id":"1.168224340","rc":[{"batb":[[0,1.03,396.63]],"ltp":1.07,"tv":1084.13,"id":8174333}]}]}
{"op":"mcm","clk":"1001494651","pt":1580636987371,"mc":[{"id":"1.168224340","rc":[{"batl":[[0,160,37.1]],"ltp":0.0,"tv":0.0,"id":6498878},{"batb":[[1,1.02,1025.75]],"ltp":1.07,"tv":1084.13,"id":8174333}]}]}
{"op":"mcm","clk":"1001495558","pt":1580637001027,"mc":[{"id":"1.168224340","rc":[{"batb":[[0,18.5,6.29],[1,4.1,374.13],[2,1.01,15.52]],"ltp":0.0,"tv":0.0,"id":6498878},{"batb":[[0,1.01,15.51],[1,1.02,0],[2,1.01,0]],"ltp":1.07,"tv":1084.13,"id":8174333}]}]}
{"op":"mcm","clk":"1001495591","pt":1580637001538,"mc":[{"id":"1.168224340","rc":[{"batb":[[1,1.01,15.52],[2,1.01,0]],"ltp":0.0,"tv":0.0,"id":6498878}]}]}
{"op":"mcm","clk":"1001495772","pt":1580637004028,"mc":[{"id":"1.168224340","rc":[{"batl":[[0,1.05,1220.68]],"ltp":1.07,"tv":1084.13,"id":8174333}]}]}
{"op":"mcm","clk":"1001495909","pt":1580637006330,"mc":[{"id":"1.168224340","rc":[{"batb":[[0,1.04,299],[1,1.03,942.47],[2,1.01,15.51]],"ltp":1.07,"tv":1084.13,"id":8174333}]}]}
{"op":"mcm","clk":"1001495961","pt":1580637007048,"mc":[{"id":"1.168224340","rc":[{"batb":[[1,14,6.29],[2,1.01,15.52]],"ltp":0.0,"tv":0.0,"id":6498878},{"batb":[[1,1.03,1679.56]],"ltp":1.07,"tv":1084.13,"id":8174333}]}]}
{"op":"mcm","clk":"1001496030","pt":1580637008336,"mc":[{"id":"1.168224340","rc":[{"batb":[[0,1.04,467.04]],"batl":[[1,1.06,42.01]],"ltp":1.07,"tv":1084.13,"id":8174333}]}]}
{"op":"mcm","clk":"1001496081","pt":1580637009323,"mc":[{"id":"1.168224340","rc":[{"batb":[[2,4.2,372.95]],"ltp":0.0,"tv":0.0,"id":6498878},{"batb":[[0,1.04,399.28],[2,1.01,3892.94]],"ltp":1.07,"tv":1084.13,"id":8174333}]}]}
{"op":"mcm","clk":"1001496223","pt":1580637011747,"mc":[{"id":"1.168224340","rc":[{"batb":[[1,1.03,1747.98]],"ltp":1.07,"tv":1084.13,"id":8174333}]}]}
{"op":"mcm","clk":"1001496752","pt":1580637019835,"mc":[{"id":"1.168224340","rc":[{"batb":[[0,14,6.29],[1,4.2,372.95],[2,1.01,15.52]],"ltp":0.0,"tv":0.0,"id":6498878},{"batb":[[0,1.04,168.04],[1,1.01,3892.94],[2,1.01,0]],"batl":[[0,1.06,42.01],[1,1.06,0]],"ltp":1.07,"tv":1084.13,"id":8174333}]}]}
{"op":"mcm","clk":"1001496840","pt":1580637021024,"mc":[{"id":"1.168224340","rc":[{"batb":[[1,1.01,15.52],[2,1.01,0]],"ltp":0.0,"tv":0.0,"id":6498878},{"batb":[[0,1.01,15.51],[1,1.01,0]],"ltp":1.07,"tv":1084.13,"id":8174333}]}]}
{"op":"mcm","clk":"1001496990","pt":1580637023447,"mc":[{"id":"1.168224340","rc":[{"batb":[[0,1.01,1284.53]],"batl":[[0,1.07,1197.86]],"ltp":1.07,"tv":1084.13,"id":8174333}]}]}
{"op":"mcm","clk":"1001497231","pt":1580637027833,"mc":[{"id":"1.168224340","rc":[{"batb":[[0,1.01,15.51]],"ltp":1.07,"tv":1084.13,"id":8174333}]}]}
{"op":"mcm","clk":"1001497395","pt":1580637030836,"mc":[{"id":"1.168224340","rc":[{"batb":[[0,1.05,1220.68],[1,1.01,15.51]],"ltp":1.07,"tv":1084.13,"id":8174333}]}]}
{"op":"mcm","clk":"1001497459","pt":1580637031972,"mc":[{"id":"1.168224340","rc":[{"batb":[[1,13.5,3.36],[2,9.8,14.16]],"ltp":0.0,"tv":0.0,"id":6498878},{"batb":[[1,1.04,486.41],[2,1.01,15.51]],"batl":[[1,1.08,42.01]],"ltp":1.07,"tv":1084.13,"id":8174333}]}]}
{"op":"mcm","clk":"1001497526","pt":1580637032957,"mc":[{"id":"1.168224340","rc":[{"batb":[[2,1.02,2184.08]],"ltp":1.07,"tv":1084.13,"id":8174333}]}]}
{"op":"mcm","clk":"1001498844","pt":1580637055075,"mc":[{"id":"1.168224340","rc":[{"batb":[[0,9.8,14.16],[1,4,369.93],[2,1.01,15.52]],"ltp":0.0,"tv":0.0,"id":6498878},{"batb":[[0,1.02,2184.08],[1,1.01,15.51],[2,1.02,0]],"ltp":1.07,"tv":1084.13,"id":8174333}]}]}
{"op":"mcm","clk":"1001498913","pt":1580637056005,"mc":[{"id":"1.168224340","rc":[{"batb":[[1,1.01,15.52],[2,1.01,0]],"ltp":0.0,"tv":0.0,"id":6498878},{"batb":[[0,1.01,15.51],[1,1.01,0]],"ltp":1.07,"tv":1084.13,"id":8174333}]}]}
{"op":"mcm","clk":"1001499139","pt":1580637061004,"mc":[{"id":"1.168224340","rc":[{"batb":[[0,1.04,1232.42],[1,1.01,15.51]],"batl":[[0,1.06,1209.16]],"ltp":1.07,"tv":1084.13,"id":8174333}]}]}
{"op":"mcm","clk":"1001499211","pt":1580637062087,"mc":[{"id":"1.168224340","rc":[{"batb":[[1,4.1,374.13],[2,1.01,15.52]],"ltp":0.0,"tv":0.0,"id":6498878},{"batb":[[1,1.01,4081.97]],"ltp":1.07,"tv":1084.13,"id":8174333}]}]}
{"op":"mcm","clk":"1001499361","pt":1580637064708,"mc":[{"id":"1.168224340","rc":[{"batb":[[0,1.01,4081.97],[1,1.01,0]],"ltp":1.07,"tv":1084.13,"id":8174333}]}]}
{"op":"mcm","clk":"1001499452","pt":1580637066095,"mc":[{"id":"1.168224340","rc":[{"batb":[[1,1.01,15.52],[2,1.01,0]],"ltp":0.0,"tv":0.0,"id":6498878},{"batb":[[0,1.01,15.51]],"ltp":1.07,"tv":1084.13,"id":8174333}]}]}
{"op":"mcm","clk":"1001499504","pt":1580637067633,"mc":[{"id":"1.168224340","rc":[{"batb":[[0,1.01,1284.53]],"batl":[[0,1.1,725.91],[1,1.11,435.32]],"ltp":1.07,"tv":1084.13,"id":8174333}]}]}
{"op":"mcm","clk":"1001500536","pt":1580637089322,"mc":[{"id":"1.168224340","rc":[{"batb":[[0,1.01,15.51]],"ltp":1.07,"tv":1084.13,"id":8174333}]}]}
{"op":"mcm","clk":"1001500658","pt":1580637092346,"mc":[{"id":"1.168224340","rc":[{"batb":[[0,1.08,1186.77],[1,1.01,15.51]],"ltp":1.07,"tv":1084.13,"id":8174333}]}]}
{"op":"mcm","clk":"1001500717","pt":1580637093321,"mc":[{"id":"1.168224340","rc":[{"batb":[[1,8,8.97],[2,1.01,15.52]],"ltp":0.0,"tv":0.0,"id":6498878},{"batb":[[0,1.08,1489.38],[1,1.04,488.38],[2,1.01,15.51]],"ltp":1.07,"tv":1084.13,"id":8174333}]}]}
{"op":"mcm","clk":"1001500756","pt":1580637094144,"mc":[{"id":"1.168224340","rc":[{"batb":[[0,9.8,18.36]],"batl":[[0,13,3.36]],"ltp":0.0,"tv":0.0,"id":6498878},{"batb":[[0,1.08,1657.42]],"ltp":1.07,"tv":1084.13,"id":8174333}]}]}
{"op":"mcm","clk":"1001500781","pt":1580637094550,"mc":[{"id":"1.168224340","rc":[{"batb":[[2,3.7,374.33]],"ltp":0.0,"tv":0.0,"id":6498878},{"batb":[[1,1.04,1751.38]],"ltp":1.07,"tv":1084.13,"id":8174333}]}]}
{"op":"mcm","clk":"1001501765","pt":1580637114395,"mc":[{"id":"1.168224340","rc":[{"batb":[[0,1.08,470.65]],"ltp":1.07,"tv":1084.13,"id":8174333}]}]}
{"op":"mcm","clk":"1001501804","pt":1580637115068,"mc":[{"id":"1.168224340","rc":[{"batb":[[0,8,8.97],[1,3.7,374.33],[2,1.01,15.52]],"ltp":0.0,"tv":0.0,"id":6498878},{"batb":[[0,1.04,1751.38],[1,1.01,15.51],[2,1.01,0]],"ltp":1.07,"tv":1084.13,"id":8174333}]}]}
{"op":"mcm","clk":"1001501923","pt":1580637117276,"mc":[{"id":"1.168224340","rc":[{"batb":[[0,1.05,1220.68],[1,1.04,1751.38],[2,1.01,15.51]],"batl":[[0,1.13,996.62]],"ltp":1.07,"tv":1084.13,"id":8174333}]}]}
{"op":"mcm","clk":"1001502179","pt":1580637122009,"mc":[{"id":"1.168224340","rc":[{"batb":[[0,1.04,1751.38],[1,1.01,15.51],[2,1.01,0]],"ltp":1.07,"tv":1084.13,"id":8174333}]}]}
{"op":"mcm","clk":"1001502242","pt":1580637122993,"mc":[{"id":"1.168224340","rc":[{"batb":[[0,1.04,488.38]],"ltp":1.07,"tv":1084.13,"id":8174333}]}]}
{"op":"mcm","clk":"1001502363","pt":1580637125413,"mc":[{"id":"1.168224340","rc":[{"batb":[[1,7,12.12],[2,3.7,374.33]],"ltp":0.0,"tv":0.0,"id":6498878},{"batb":[[0,1.11,396.68],[1,1.1,991.9],[2,1.08,304.34]],"ltp":1.07,"tv":1084.13,"id":8174333}]}]}
{"op":"mcm","clk":"1001502406","pt":1580637126393,"mc":[{"id":"1.168224340","rc":[{"batb":[[0,8.2,5.04],[1,8,8.97],[2,7,12.12]],"batl":[[0,11,4.2]],"ltp":0.0,"tv":0.0,"id":6498878},{"batb":[[1,1.1,1159.94]],"batl":[[1,1.14,42.01]],"ltp":1.07,"tv":1084.13,"id":8174333}]}]}
{"op":"mcm","clk":"1001503398","pt":1580637143311,"mc":[{"id":"1.168224340","rc":[{"batb":[[1,7,12.12],[2,3.7,374.33]],"ltp":0.0,"tv":0.0,"id":6498878},{"batb":[[0,1.1,168.04],[1,1.08,304.34],[2,1.06,955.61]],"batl":[[0,1.14,42.01],[1,1.14,0]],"ltp":1.07,"tv":1084.13,"id":8174333}]}]}
{"op":"mcm","clk":"1001503512","pt":1580637145126,"mc":[{"id":"1.168224340","rc":[{"batb":[[0,7,12.12],[1,3.7,374.33],[2,1.01,15.52]],"ltp":0.0,"tv":0.0,"id":6498878},{"batb":[[0,1.08,304.34],[1,1.06,955.61],[2,1.01,15.51]],"ltp":1.07,"tv":1084.13,"id":8174333}]}]}
{"op":"mcm","clk":"1001503587","pt":1580637146221,"mc":[{"id":"1.168224340","rc":[{"batb":[[0,1.08,1491.11]],"batl":[[0,1.14,187.16],[1,1.15,765.12]],"ltp":1.07,"tv":1084.13,"id":8174333}]}]}
{"op":"mcm","clk":"1001503655","pt":1580637147310,"mc":[{"id":"1.168224340","rc":[{"batb":[[0,1.08,304.34]],"ltp":1.07,"tv":1084.13,"id":8174333}]}]}
{"op":"mcm","clk":"1001503757","pt":1580637149126,"mc":[{"id":"1.168224340","rc":[{"batb":[[1,1.01,15.51],[2,1.01,0]],"ltp":1.07,"tv":1084.13,"id":8174333}]}]}
{"op":"mcm","clk":"1001503839","pt":1580637150361,"mc":[{"id":"1.168224340","rc":[{"batb":[[0,1.12,1144.39],[1,1.08,304.34],[2,1.01,15.51]],"ltp":1.07,"tv":1084.13,"id":8174333}]}]}
{"op":"mcm","clk":"1001503868","pt":1580637150931,"mc":[{"id":"1.168224340","rc":[{"batb":[[1,5.3,11.49],[2,3.7,374.33]],"ltp":0.0,"tv":0.0,"id":6498878},{"batb":[[0,1.13,188.05],[1,1.12,1144.39],[2,1.09,247.61]],"ltp":1.07,"tv":1084.13,"id":8174333}]}]}
{"op":"mcm","clk":"1001503925","pt":1580637152128,"mc":[{"id":"1.168224340","rc":[{"batb":[[0,7.4,5.88],[1,7,12.12],[2,5.3,11.49]],"batl":[[0,9.6,4.2]],"ltp":0.0,"tv":0.0,"id":6498878},{"batb":[[1,1.12,1312.43]],"batl":[[2,1.16,42.01]],"ltp":1.07,"tv":1084.13,"id":8174333}]}]}
{"op":"mcm","clk":"1001505231","pt":1580637175153,"mc":[{"id":"1.168224340","rc":[{"batb":[[0,5.3,11.49],[1,3.7,374.33],[2,1.01,15.52]],"ltp":0.0,"tv":0.0,"id":6498878},{"batb":[[0,1.09,247.61],[1,1.07,893.98],[2,1.01,15.51]],"ltp":1.07,"tv":1084.13,"id":8174333}]}]}
{"op":"mcm","clk":"1001505866","pt":1580637185259,"mc":[{"id":"1.168224340","rc":[{"batb":[[0,1.1,545.27],[1,1.09,873.22],[2,1.07,893.98]],"batl":[[0,1.2,308.27],[1,1.21,516.73]],"ltp":1.07,"tv":1084.13,"id":8174333}]}]}
{"op":"mcm","clk":"1001506614","pt":1580637198745,"mc":[{"id":"1.168224340","rc":[{"batb":[[2,1.01,15.51]],"ltp":1.07,"tv":1084.13,"id":8174333}]}]}
{"op":"mcm","clk":"1001506691","pt":1580637200346,"mc":[{"id":"1.168224340","rc":[{"batl":[[0,1.12,1045.75]],"ltp":1.07,"tv":1084.13,"id":8174333}]}]}
{"op":"mcm","clk":"1001506748","pt":1580637201326,"mc":[{"id":"1.168224340","rc":[{"batb":[[0,8.6,7.71],[1,6.4,14.48],[2,3.7,374.33]],"ltp":0.0,"tv":0.0,"id":6498878},{"batb":[[1,1.09,796.94],[2,1.07,320.16]],"batl":[[0,1.12,971.87]],"ltp":1.07,"tv":1084.13,"id":8174333}]}]}
{"op":"mcm","clk":"1001506799","pt":1580637202254,"mc":[{"id":"1.168224340","rc":[{"batb":[[0,8.8,5.04],[1,8.6,7.71],[2,6.4,14.48]],"batl":[[0,11.5,3.36]],"ltp":0.0,"tv":0.0,"id":6498878},{"batl":[[1,1.13,42.01]],"ltp":1.07,"tv":1084.13,"id":8174333}]}]}
{"op":"mcm","clk":"1001506871","pt":1580637203757,"mc":[{"id":"1.168224340","rc":[{"batb":[[0,1.1,620.85]],"batl":[[1,1.13,213]],"ltp":1.07,"tv":1084.13,"id":8174333}]}]}
{"op":"mcm","clk":"1001507434","pt":1580637215357,"mc":[{"id":"1.168224340","rc":[{"batb":[[0,1.09,247.61],[1,1.07,320.16],[2,1.05,1069.56]],"batl":[[0,1.13,42.01],[1,1.13,0]],"ltp":1.07,"tv":1084.13,"id":8174333}]}]}
{"op":"mcm","clk":"1001507461","pt":1580637215769,"mc":[{"id":"1.168224340","rc":[{"batb":[[1,6.4,14.48],[2,3.7,374.33]],"ltp":0.0,"tv":0.0,"id":6498878},{"batb":[[0,1.07,320.16],[1,1.05,1069.56],[2,1.01,15.51]],"ltp":1.07,"tv":1084.13,"id":8174333}]}]}
{"op":"mcm","clk":"1001507547","pt":1580637217160,"mc":[{"id":"1.168224340","rc":[{"batb":[[0,6.4,14.48],[1,3.7,374.33],[2,1.01,15.52]],"ltp":0.0,"tv":0.0,"id":6498878}]}]}
{"op":"mcm","clk":"1001507618","pt":1580637218340,"mc":[{"id":"1.168224340","rc":[{"batb":[[0,1.08,909.34],[1,1.07,600.18],[2,1.05,1069.56]],"batl":[[0,1.16,684.3],[1,1.17,417.03]],"ltp":1.07,"tv":1084.13,"id":8174333}]}]}
{"op":"mcm","clk":"1001508116","pt":1580637228278,"mc":[{"id":"1.168224340","rc":[{"batb":[[0,1.07,320.16],[1,1.05,1069.56],[2,1.01,15.51]],"ltp":1.07,"tv":1084.13,"id":8174333}]}]}
{"op":"mcm","clk":"1001508156","pt":1580637229151,"mc":[{"id":"1.168224340","rc":[{"batb":[[1,1.01,15.51],[2,1.01,0]],"ltp":1.07,"tv":1084.13,"id":8174333}]}]}
{"op":"mcm","clk":"1001508266","pt":1580637231367,"mc":[{"id":"1.168224340","rc":[{"batb":[[1,4.7,14.95],[2,3.7,374.33]],"ltp":0.0,"tv":0.0,"id":6498878},{"batb":[[0,1.14,461.47],[1,1.13,838.65],[2,1.1,234]],"ltp":1.07,"tv":1084.13,"id":8174333}]}]}
{"op":"mcm","clk":"1001508298","pt":1580637232189,"mc":[{"id":"1.168224340","rc":[{"batb":[[0,7,6.72],[1,6.4,14.48],[2,4.7,14.95]],"batl":[[0,9,5.04]],"ltp":0.0,"tv":0.0,"id":6498878},{"batl":[[1,1.17,459.04]],"ltp":1.07,"tv":1084.13,"id":8174333}]}]}
{"op":"mcm","clk":"1001509017","pt":1580637245989,"mc":[{"id":"1.168224340","rc":[{"batb":[[1,4.7,14.95],[2,3.7,374.33]],"ltp":0.0,"tv":0.0,"id":6498878},{"batb":[[0,1.1,234],[1,1.08,824.68],[2,1.01,15.51]],"batl":[[0,1.17,42.01],[1,1.17,0]],"ltp":1.07,"tv":1084.13,"id":8174333}]}]}
{"op":"mcm","clk":"1001509092","pt":1580637247216,"mc":[{"id":"1.168224340","rc":[{"batb":[[0,4.7,14.95],[1,3.7,374.33],[2,1.01,15.52]],"ltp":0.0,"tv":0.0,"id":6498878}]}]}
{"op":"mcm","clk":"1001509170","pt":1580637248914,"mc":[{"id":"1.168224340","rc":[{"batb":[[0,4.8,14.48]],"ltp":0.0,"tv":0.0,"id":6498878},{"batb":[[0,1.1,1220.98],[1,1.09,179.85],[2,1.08,824.68]],"batl":[[0,1.23,206.6],[1,1.24,442.35]],"ltp":1.07,"tv":1084.13,"id":8174333}]}]}
{"op":"mcm","clk":"1001509220","pt":1580637249791,"mc":[{"id":"1.168224340","rc":[{"batb":[[0,1.1,234],[1,1.08,824.68],[2,1.01,15.51]],"ltp":1.07,"tv":1084.13,"id":8174333}]}]}
{"op":"mcm","clk":"1001509463","pt":1580637253411,"mc":[{"id":"1.168224340","rc":[{"batb":[[0,1.15,550.99],[1,1.14,568.48],[2,1.1,234]],"batl":[[0,1.17,354.49],[1,1.18,612.68]],"ltp":1.07,"tv":1084.13,"id":8174333}]}]}
{"op":"mcm","clk":"1001509522","pt":1580637254392,"mc":[{"id":"1.168224340","rc":[{"batb":[[0,1.1,234],[1,1.08,824.68],[2,1.01,15.51]],"ltp":1.07,"tv":1084.13,"id":8174333}]}]}
{"op":"mcm","clk":"1001509660","pt":1580637257390,"mc":[{"id":"1.168224340","rc":[{"batb":[[0,1.1,1220.98],[1,1.09,179.85],[2,1.08,824.68]],"batl":[[0,1.23,206.6],[1,1.24,442.35]],"ltp":1.07,"tv":1084.13,"id":8174333}]}]}
{"op":"mcm","clk":"1001510466","pt":1580637274930,"mc":[{"id":"1.168224340","rc":[{"batb":[[0,1.1,234],[1,1.08,824.68],[2,1.01,15.51]],"ltp":1.07,"tv":1084.13,"id":8174333}]}]}
{"op":"mcm","clk":"1001510558","pt":1580637276527,"mc":[{"id":"1.168224340","rc":[{"batb":[[1,1.01,15.52],[2,1.01,0]],"ltp":0.0,"tv":0.0,"id":6498878},{"batb":[[1,1.01,15.51],[2,1.01,0]],"ltp":1.07,"tv":1084.13,"id":8174333}]}]}
{"op":"mcm","clk":"1001510666","pt":1580637278330,"mc":[{"id":"1.168224340","rc":[{"batb":[[0,5.1,10.08],[1,4.8,14.48],[2,1.01,15.52]],"ltp":0.0,"tv":0.0,"id":6498878},{"batb":[[0,1.21,270.62],[1,1.2,571.72],[2,1.1,234]],"batl":[[1,1.24,484.36]],"ltp":1.07,"tv":1084.13,"id":8174333}]}]}
{"op":"mcm","clk":"1001510718","pt":1580637279358,"mc":[{"id":"1.168224340","rc":[{"batb":[[2,3.5,15.42]],"ltp":0.0,"tv":0.0,"id":6498878},{"batb":[[0,1.21,377.71],[2,1.15,156.66]],"batl":[[1,1.24,442.35]],"ltp":1.07,"tv":1084.13,"id":8174333}]}]}
{"op":"mcm","clk":"1001510809","pt":1580637281258,"mc":[{"id":"1.168224340","rc":[{"batl":[[0,6.2,7.56]],"ltp":0.0,"tv":0.0,"id":6498878},{"batb":[[2,1.19,168.04]],"ltp":1.07,"tv":1084.13,"id":8174333}]}]}
{"op":"mcm","clk":"1001511649","pt":1580637298008,"mc":[{"id":"1.168224340","rc":[{"batb":[[1,3.5,15.42],[2,2.9,375.84]],"ltp":0.0,"tv":0.0,"id":6498878},{"batb":[[0,1.19,168.04],[1,1.15,156.66],[2,1.13,629.97]],"ltp":1.07,"tv":1084.13,"id":8174333}]}]}
{"op":"mcm","clk":"1001511705","pt":1580637299299,"mc":[{"id":"1.168224340","rc":[{"batb":[[0,3.5,15.42],[1,2.9,375.84],[2,1.01,15.52]],"ltp":0.0,"tv":0.0,"id":6498878},{"batb":[[0,1.15,156.66],[1,1.13,629.97],[2,1.01,15.51]],"ltp":1.07,"tv":1084.13,"id":8174333}]}]}
{"op":"mcm","clk":"1001511756","pt":1580637300380,"mc":[{"id":"1.168224340","rc":[{"batb":[[0,1.15,584.94],[1,1.14,692.26],[2,1.13,629.97]],"batl":[[0,1.37,358.88],[1,1.38,250.01]],"ltp":1.07,"tv":1084.13,"id":8174333}]}]}
{"op":"mcm","clk":"1001512165","pt":1580637307115,"mc":[{"id":"1.168224340","rc":[{"batb":[[0,1.15,156.66],[1,1.13,629.97],[2,1.01,15.51]],"ltp":1.07,"tv":1084.13,"id":8174333}]}]}
{"op":"mcm","clk":"1001512228","pt":1580637308096,"mc":[{"id":"1.168224340","rc":[{"batb":[[1,1.01,15.52],[2,1.01,0]],"ltp":0.0,"tv":0.0,"id":6498878},{"batb":[[1,1.01,15.51],[2,1.01,0]],"ltp":1.07,"tv":1084.13,"id":8174333}]}]}
{"op":"mcm","clk":"1001512360","pt":1580637310415,"mc":[{"id":"1.168224340","rc":[{"batb":[[0,3.65,15.12],[1,3.5,15.42],[2,2.76,11.33]],"ltp":0.0,"tv":0.0,"id":6498878},{"batb":[[0,1.34,62.39],[1,1.33,298.39],[2,1.32,322.92]],"batl":[[0,1.37,400.89]],"ltp":1.07,"tv":1084.13,"id":8174333}]}]}
{"op":"mcm","clk":"1001512545","pt":1580637312804,"mc":[{"id":"1.168224340","rc":[{"batl":[[0,4.3,12.6]],"ltp":0.0,"tv":0.0,"id":6498878}]}]}
{"op":"mcm","clk":"1001513333","pt":1580637329320,"mc":[{"id":"1.168224340","rc":[{"batb":[[0,2.76,11.33],[1,2.42,381.73],[2,1.01,15.52]],"ltp":0.0,"tv":0.0,"id":6498878},{"batb":[[0,1.26,86.08],[1,1.22,523],[2,1.01,15.51]],"ltp":1.07,"tv":1084.13,"id":8174333}]}]}
{"op":"mcm","clk":"1001513419","pt":1580637331332,"mc":[{"id":"1.168224340","rc":[{"batb":[[1,1.25,461.78],[2,1.24,464.48]],"batl":[[0,1.54,148.54],[1,1.55,153.98]],"ltp":1.07,"tv":1084.13,"id":8174333}]}]}
{"op":"mcm","clk":"1001513457","pt":1580637332110,"mc":[{"id":"1.168224340","rc":[{"batb":[[1,1.22,523],[2,1.01,15.51]],"ltp":1.07,"tv":1084.13,"id":8174333}]}]}
{"op":"mcm","clk":"1001513639","pt":1580637335824,"mc":[{"id":"1.168224340","rc":[{"batb":[[0,1.36,263.84],[1,1.35,287.73],[2,1.26,86.08]],"batl":[[0,1.4,292.38],[1,1.41,227.71]],"ltp":1.07,"tv":1084.13,"id":8174333}]}]}
{"op":"mcm","clk":"1001513680","pt":1580637336548,"mc":[{"id":"1.168224340","rc":[{"batb":[[0,1.26,86.08],[1,1.22,523],[2,1.01,15.51]],"ltp":1.07,"tv":1084.13,"id":8174333}]}]}
{"op":"mcm","clk":"1001513853","pt":1580637340351,"mc":[{"id":"1.168224340","rc":[{"batb":[[1,1.25,461.78],[2,1.24,464.48]],"batl":[[0,1.54,148.54],[1,1.55,153.98]],"ltp":1.07,"tv":1084.13,"id":8174333}]}]}
{"op":"mcm","clk":"1001514383","pt":1580637351169,"mc":[{"id":"1.168224340","rc":[{"batb":[[1,1.22,523],[2,1.01,15.51]],"ltp":1.07,"tv":1084.13,"id":8174333}]}]}
{"op":"mcm","clk":"1001514469","pt":1580637352877,"mc":[{"id":"1.168224340","rc":[{"batb":[[1,1.01,15.52],[2,1.01,0]],"ltp":0.0,"tv":0.0,"id":6498878},{"batb":[[1,1.01,15.51],[2,1.01,0]],"ltp":1.07,"tv":1084.13,"id":8174333}]}]}
{"op":"mcm","clk":"1001514545","pt":1580637354271,"mc":[{"id":"1.168224340","rc":[{"batb":[[1,2.72,24.37],[2,1.01,15.52]],"ltp":0.0,"tv":0.0,"id":6498878},{"batb":[[0,1.49,282.95],[1,1.48,190.26],[2,1.26,86.08]],"batl":[[2,1.58,42.01]],"ltp":1.07,"tv":1084.13,"id":8174333}]}]}
{"op":"mcm","clk":"1001514574","pt":1580637354790,"mc":[{"id":"1.168224340","rc":[{"batb":[[1,2.7,24.37],[2,2.48,15.34]],"batl":[[0,3.1,19.32]],"ltp":0.0,"tv":0.0,"id":6498878},{"batb":[[0,1.49,321.58],[2,1.47,89.06]],"batl":[[2,1.59,42.01]],"ltp":1.07,"tv":1084.13,"id":8174333}]}]}
{"op":"mcm","clk":"1001520759","pt":1580637447317,"mc":[{"id":"1.168224340","rc":[{"batb":[[0,2.48,15.34],[1,2.04,394.09],[2,1.01,15.52]],"ltp":0.0,"tv":0.0,"id":6498878},{"batb":[[0,1.36,56.41],[1,1.34,465.43],[2,1.01,15.51]],"ltp":1.07,"tv":1084.13,"id":8174333}]}]}
{"op":"mcm","clk":"1001521239","pt":1580637452886,"mc":[{"id":"1.168224340","rc":[{"batb":[[0,1.47,218.46],[1,1.46,200.94],[2,1.36,56.41]],"batl":[[0,1.52,250.27],[1,1.53,163.08]],"ltp":1.07,"tv":1084.13,"id":8174333}]}]}
{"op":"mcm","clk":"1001521521","pt":1580637457206,"mc":[{"id":"1.168224340","rc":[{"batb":[[0,1.36,56.41],[1,1.34,465.43],[2,1.01,15.51]],"ltp":1.07,"tv":1084.13,"id":8174333}]}]}
{"op":"mcm","clk":"1001521734","pt":1580637460336,"mc":[{"id":"1.168224340","rc":[{"batb":[[0,1.38,214.49],[1,1.37,267.61],[2,1.36,56.41]],"batl":[[0,1.64,145.24],[1,1.65,123.88]],"ltp":1.07,"tv":1084.13,"id":8174333}]}]}
{"op":"mcm","clk":"1001521943","pt":1580637462815,"mc":[{"id":"1.168224340","rc":[{"batb":[[0,1.36,56.41],[1,1.34,465.43],[2,1.01,15.51]],"ltp":1.07,"tv":1084.13,"id":8174333}]}]}
{"op":"mcm","clk":"1001522037","pt":1580637464211,"mc":[{"id":"1.168224340","rc":[{"batb":[[1,1.01,15.51],[2,1.01,0]],"ltp":1.07,"tv":1084.13,"id":8174333}]}]}
{"op":"mcm","clk":"1001522173","pt":1580637466326,"mc":[{"id":"1.168224340","rc":[{"batb":[[0,2.48,43.07]],"ltp":0.0,"tv":0.0,"id":6498878},{"batb":[[0,1.59,124.12],[1,1.58,145.95],[2,1.36,56.41]],"batl":[[0,1.64,145.24],[1,1.65,123.88],[2,1.69,42.01]],"ltp":1.07,"tv":1084.13,"id":8174333}]}]}
{"op":"mcm","clk":"1001522196","pt":1580637466840,"mc":[{"id":"1.168224340","rc":[{"batb":[[1,2.26,19.51],[2,2.04,394.09]],"batl":[[0,2.82,22.69]],"ltp":0.0,"tv":0.0,"id":6498878},{"batb":[[0,1.59,154.18],[2,1.55,75.62]],"ltp":1.07,"tv":1084.13,"id":8174333}]}]}
{"op":"mcm","clk":"1001522780","pt":1580637476328,"mc":[{"id":"1.168224340","rc":[{"batb":[[0,2.48,27.73]],"ltp":0.0,"tv":0.0,"id":6498878},{"batb":[[0,1.55,75.62],[1,1.47,40.84],[2,1.38,448.45]],"batl":[[0,1.69,42.01],[1,1.65,0],[2,1.69,0]],"ltp":1.07,"tv":1084.13,"id":8174333}]}]}
{"op":"mcm","clk":"1001522838","pt":1580637477353,"mc":[{"id":"1.168224340","rc":[{"batb":[[0,2.26,19.51],[1,2.04,394.09],[2,1.01,15.52]],"ltp":0.0,"tv":0.0,"id":6498878},{"batb":[[0,1.47,40.84],[1,1.38,448.45],[2,1.01,15.51]],"ltp":1.07,"tv":1084.13,"id":8174333}]}]}
{"op":"mcm","clk":"1001522962","pt":1580637479336,"mc":[{"id":"1.168224340","rc":[{"batb":[[0,1.47,341.02],[1,1.46,201.49],[2,1.38,448.45]],"batl":[[0,1.73,127.03],[1,1.75,203.85]],"ltp":1.07,"tv":1084.13,"id":8174333}]}]}
{"op":"mcm","clk":"1001523056","pt":1580637480933,"mc":[{"id":"1.168224340","rc":[{"batb":[[0,1.47,40.84],[1,1.38,448.45],[2,1.01,15.51]],"ltp":1.07,"tv":1084.13,"id":8174333}]}]}
{"op":"mcm","clk":"1001523260","pt":1580637484142,"mc":[{"id":"1.168224340","rc":[{"batb":[[0,1.56,223.72],[1,1.55,157.54],[2,1.47,40.84]],"batl":[[0,1.62,222.22],[1,1.63,129.08]],"ltp":1.07,"tv":1084.13,"id":8174333}]}]}
{"op":"mcm","clk":"1001523432","pt":1580637487378,"mc":[{"id":"1.168224340","rc":[{"batb":[[0,1.47,40.84],[1,1.38,448.45],[2,1.01,15.51]],"ltp":1.07,"tv":1084.13,"id":8174333}]}]}
{"op":"mcm","clk":"1001523587","pt":1580637490169,"mc":[{"id":"1.168224340","rc":[{"batb":[[0,1.47,341.02],[1,1.46,201.49],[2,1.38,448.45]],"batl":[[0,1.73,127.03],[1,1.75,203.85]],"ltp":1.07,"tv":1084.13,"id":8174333}]}]}
{"op":"mcm","clk":"1001523643","pt":1580637490982,"mc":[{"id":"1.168224340","rc":[{"batb":[[0,1.47,40.84],[1,1.38,448.45],[2,1.01,15.51]],"ltp":1.07,"tv":1084.13,"id":8174333}]}]}
{"op":"mcm","clk":"1001523785","pt":1580637493354,"mc":[{"id":"1.168224340","rc":[{"batb":[[1,1.01,15.52],[2,1.01,0]],"ltp":0.0,"tv":0.0,"id":6498878},{"batb":[[1,1.01,15.51],[2,1.01,0]],"ltp":1.07,"tv":1084.13,"id":8174333}]}]}
{"op":"mcm","clk":"1001523827","pt":1580637494377,"mc":[{"id":"1.168224340","rc":[{"batb":[[0,2.28,32.77],[1,2.26,19.51],[2,2.12,23.53]],"batl":[[0,2.6,26.05]],"ltp":0.0,"tv":0.0,"id":6498878},{"batb":[[0,1.69,24.31],[1,1.67,118.94],[2,1.62,67.22]],"batl":[[0,1.77,42.01],[1,1.75,0]],"ltp":1.07,"tv":1084.13,"id":8174333}]}]}
{"op":"mcm","clk":"1001523927","pt":1580637496792,"mc":[{"id":"1.168224340","rc":[{"batb":[[1,1.68,143.73],[2,1.67,118.94]],"batl":[[0,1.74,134.29],[1,1.76,199.67],[2,1.77,42.01]],"ltp":1.07,"tv":1084.13,"id":8174333}]}]}
{"op":"mcm","clk":"1001524650","pt":1580637510385,"mc":[{"id":"1.168224340","rc":[{"batb":[[1,1.62,67.22],[2,1.58,30.45]],"batl":[[0,1.77,42.01],[1,1.76,0],[2,1.77,0]],"ltp":1.07,"tv":1084.13,"id":8174333}]}]}
{"op":"mcm","clk":"1001524718","pt":1580637511266,"mc":[{"id":"1.168224340","rc":[{"batb":[[0,2.12,23.53],[1,1.82,401.24],[2,1.01,15.52]],"ltp":0.0,"tv":0.0,"id":6498878},{"batb":[[0,1.58,30.45],[1,1.46,435.7],[2,1.01,15.51]],"ltp":1.07,"tv":1084.13,"id":8174333}]}]}
{"op":"mcm","clk":"1001524843","pt":1580637513376,"mc":[{"id":"1.168224340","rc":[{"batb":[[0,1.59,174.32],[1,1.58,176.29],[2,1.46,435.7]],"batl":[[0,1.81,139.31],[1,1.83,175.92]],"ltp":1.07,"tv":1084.13,"id":8174333}]}]}
{"op":"mcm","clk":"1001524874","pt":1580637514099,"mc":[{"id":"1.168224340","rc":[{"batb":[[0,1.58,30.45],[1,1.46,435.7],[2,1.01,15.51]],"ltp":1.07,"tv":1084.13,"id":8174333}]}]}
{"op":"mcm","clk":"1001525081","pt":1580637517500,"mc":[{"id":"1.168224340","rc":[{"batb":[[0,1.66,163.79],[1,1.65,124.23],[2,1.58,30.45]],"batl":[[0,1.72,137.41],[1,1.74,207.37]],"ltp":1.07,"tv":1084.13,"id":8174333}]}]}
{"op":"mcm","clk":"1001525215","pt":1580637520075,"mc":[{"id":"1.168224340","rc":[{"batb":[[0,1.58,30.45],[1,1.46,435.7],[2,1.01,15.51]],"ltp":1.07,"tv":1084.13,"id":8174333}]}]}
{"op":"mcm","clk":"1001525388","pt":1580637523002,"mc":[{"id":"1.168224340","rc":[{"batb":[[0,1.59,174.32],[1,1.58,176.29],[2,1.46,435.7]],"batl":[[0,1.81,139.31],[1,1.83,175.92]],"ltp":1.07,"tv":1084.13,"id":8174333}]}]}
{"op":"mcm","clk":"1001525684","pt":1580637527394,"mc":[{"id":"1.168224340","rc":[{"batb":[[1,1.01,15.52],[2,1.01,0]],"ltp":0.0,"tv":0.0,"id":6498878},{"batb":[[2,1.01,15.51]],"ltp":1.07,"tv":1084.13,"id":8174333}]}]}
{"op":"mcm","clk":"1001525745","pt":1580637528322,"mc":[{"id":"1.168224340","rc":[{"batb":[[0,2.46,28.57],[1,2.12,23.53],[2,1.01,15.52]],"batl":[[0,2.82,22.69]],"ltp":0.0,"tv":0.0,"id":6498878},{"batb":[[2,1.55,75.62]],"batl":[[0,1.65,219.26],[1,1.66,120.77],[2,1.68,42.01]],"ltp":1.07,"tv":1084.13,"id":8174333}]}]}
{"op":"mcm","clk":"1001525763","pt":1580637528685,"mc":[{"id":"1.168224340","rc":[{"batb":[[0,2.48,15.11],[1,2.46,28.57],[2,2.24,20.14]],"ltp":0.0,"tv":0.0,"id":6498878}]}]}
{"op":"mcm","clk":"1001526826","pt":1580637546216,"mc":[{"id":"1.168224340","rc":[{"batb":[[0,2.46,28.57],[1,2.24,20.14],[2,1.97,394.86]],"ltp":0.0,"tv":0.0,"id":6498878},{"batb":[[0,1.55,75.62],[1,1.45,43.35],[2,1.38,448.45]],"batl":[[0,1.68,42.01],[1,1.66,0],[2,1.68,0]],"ltp":1.07,"tv":1084.13,"id":8174333}]}]}
{"op":"mcm","clk":"1001526895","pt":1580637547714,"mc":[{"id":"1.168224340","rc":[{"batb":[[0,2.24,20.14],[1,1.97,394.86],[2,1.01,15.52]],"ltp":0.0,"tv":0.0,"id":6498878},{"batb":[[0,1.45,43.35],[1,1.38,448.45],[2,1.01,15.51]],"ltp":1.07,"tv":1084.13,"id":8174333}]}]}
{"op":"mcm","clk":"1001526973","pt":1580637549102,"mc":[{"id":"1.168224340","rc":[{"batb":[[0,1.46,201.92],[1,1.45,249.6],[2,1.38,448.45]],"batl":[[0,1.76,198.13],[1,1.78,192.15]],"ltp":1.07,"tv":1084.13,"id":8174333}]}]}
{"op":"mcm","clk":"1001527492","pt":1580637558129,"mc":[{"id":"1.168224340","rc":[{"batb":[[0,1.45,43.35],[1,1.38,448.45],[2,1.01,15.51]],"ltp":1.07,"tv":1084.13,"id":8174333}]}]}
{"op":"mcm","clk":"1001527600","pt":1580637560156,"mc":[{"id":"1.168224340","rc":[{"batb":[[1,1.01,15.51],[2,1.01,0]],"ltp":1.07,"tv":1084.13,"id":8174333}]}]}
{"op":"mcm","clk":"1001527648","pt":1580637561130,"mc":[{"id":"1.168224340","rc":[{"batb":[[0,1.69,169.27],[1,1.68,116.5],[2,1.45,43.35]],"ltp":1.07,"tv":1084.13,"id":8174333}]}]}
{"op":"mcm","clk":"1001527745","pt":1580637562369,"mc":[{"id":"1.168224340","rc":[{"batb":[[0,2.26,32.77],[1,2.24,20.14],[2,2.12,23.84]],"batl":[[0,2.58,26.05]],"ltp":0.0,"tv":0.0,"id":6498878},{"batb":[[0,1.7,23.6],[1,1.69,169.27],[2,1.68,116.5]],"batl":[[1,1.78,234.16]],"ltp":1.07,"tv":1084.13,"id":8174333}]}]}
{"op":"mcm","clk":"1001529265","pt":1580637582381,"mc":[{"id":"1.168224340","rc":[{"batb":[[1,1.63,66.38],[2,1.6,29.66]],"batl":[[0,1.78,42.01],[1,1.78,0]],"ltp":1.07,"tv":1084.13,"id":8174333}]}]}
{"op":"mcm","clk":"1001529346","pt":1580637583359,"mc":[{"id":"1.168224340","rc":[{"batb":[[1,2.12,23.84],[2,1.97,394.86]],"ltp":0.0,"tv":0.0,"id":6498878},{"batb":[[0,1.63,66.38],[1,1.6,29.66],[2,1.46,435.7]],"ltp":1.07,"tv":1084.13,"id":8174333}]}]}
{"op":"mcm","clk":"1001529353","pt":1580637583464,"mc":[{"id":"1.168224340","rc":[{"batb":[[0,2.12,23.84],[1,1.97,394.86],[2,1.01,15.52]],"ltp":0.0,"tv":0.0,"id":6498878},{"batb":[[0,1.6,29.66],[1,1.46,435.7],[2,1.01,15.51]],"ltp":1.07,"tv":1084.13,"id":8174333}]}]}
{"op":"mcm","clk":"1001529546","pt":1580637585984,"mc":[{"id":"1.168224340","rc":[{"batb":[[0,1.6,251.08],[1,1.59,172.41],[2,1.46,435.7]],"batl":[[0,1.82,127.36],[1,1.84,172.92]],"ltp":1.07,"tv":1084.13,"id":8174333}]}]}
{"op":"mcm","clk":"1001529629","pt":1580637587070,"mc":[{"id":"1.168224340","rc":[{"batb":[[0,1.59,29.74],[1,1.46,435.7],[2,1.01,15.51]],"ltp":1.07,"tv":1084.13,"id":8174333}]}]}
{"op":"mcm","clk":"1001529709","pt":1580637588361,"mc":[{"id":"1.168224340","rc":[{"batb":[[1,1.01,15.52],[2,1.01,0]],"ltp":0.0,"tv":0.0,"id":6498878},{"batb":[[1,1.01,15.51],[2,1.01,0]],"ltp":1.07,"tv":1084.13,"id":8174333}]}]}
{"op":"mcm","clk":"1001529837","pt":1580637590374,"mc":[{"id":"1.168224340","rc":[{"batb":[[0,2.16,36.13],[1,2.12,23.84],[2,1.01,15.52]],"batl":[[0,2.44,28.57]],"ltp":0.0,"tv":0.0,"id":6498878},{"batb":[[0,1.75,174.13],[1,1.73,209.11],[2,1.69,60.49]],"batl":[[2,1.85,42.01]],"ltp":1.07,"tv":1084.13,"id":8174333}]}]}
{"op":"mcm","clk":"1001529894","pt":1580637591301,"mc":[{"id":"1.168224340","rc":[{"batb":[[2,1.84,18.18]],"ltp":0.0,"tv":0.0,"id":6498878},{"batb":[[0,1.78,20.22],[1,1.75,174.13],[2,1.73,209.11]],"ltp":1.07,"tv":1084.13,"id":8174333}]}]}
{"op":"mcm","clk":"1001531583","pt":1580637612216,"mc":[{"id":"1.168224340","rc":[{"batb":[[1,1.84,18.18],[2,1.77,402.27]],"ltp":0.0,"tv":0.0,"id":6498878},{"batb":[[0,1.69,60.49],[1,1.64,26.67],[2,1.5,426.9]],"batl":[[0,1.85,42.01],[1,1.84,0],[2,1.85,0]],"ltp":1.07,"tv":1084.13,"id":8174333}]}]}
{"op":"mcm","clk":"1001531677","pt":1580637613411,"mc":[{"id":"1.168224340","rc":[{"batb":[[0,1.84,18.18],[1,1.77,402.27],[2,1.01,15.52]],"ltp":0.0,"tv":0.0,"id":6498878},{"batb":[[0,1.64,26.67],[1,1.5,426.9],[2,1.01,15.51]],"ltp":1.07,"tv":1084.13,"id":8174333}]}]}
{"op":"mcm","clk":"1001531797","pt":1580637615320,"mc":[{"id":"1.168224340","rc":[{"batb":[[1,1.63,191.97],[2,1.62,132.9]],"batl":[[0,2.1,165.33],[1,2.12,112.84]],"ltp":1.07,"tv":1084.13,"id":8174333}]}]}
{"op":"mcm","clk":"1001531838","pt":1580637615795,"mc":[{"id":"1.168224340","rc":[{"batb":[[0,1.65,26.59],[1,1.5,426.9],[2,1.01,15.51]],"ltp":1.07,"tv":1084.13,"id":8174333}]}]}
{"op":"mcm","clk":"1001532257","pt":1580637622030,"mc":[{"id":"1.168224340","rc":[{"batb":[[1,1.63,191.97],[2,1.62,132.9]],"batl":[[0,2.1,165.33],[1,2.12,112.84]],"ltp":1.07,"tv":1084.13,"id":8174333}]}]}
{"op":"mcm","clk":"1001532312","pt":1580637622657,"mc":[{"id":"1.168224340","rc":[{"batb":[[1,1.5,426.9],[2,1.01,15.51]],"ltp":1.07,"tv":1084.13,"id":8174333}]}]}
{"op":"mcm","clk":"1001532520","pt":1580637625312,"mc":[{"id":"1.168224340","rc":[{"batb":[[1,1.01,15.52],[2,1.01,0]],"ltp":0.0,"tv":0.0,"id":6498878},{"batb":[[1,1.01,15.51],[2,1.01,0]],"ltp":1.07,"tv":1084.13,"id":8174333}]}]}
{"op":"mcm","clk":"1001532625","pt":1580637626412,"mc":[{"id":"1.168224340","rc":[{"batb":[[0,2.34,31.09],[1,1.84,18.18],[2,1.01,15.52]],"batl":[[0,2.68,24.37]],"ltp":0.0,"tv":0.0,"id":6498878},{"batb":[[1,1.63,191.97],[2,1.62,132.9]],"batl":[[0,1.69,147.19],[1,1.71,219.82],[2,1.74,42.01]],"ltp":1.07,"tv":1084.13,"id":8174333}]}]}
{"op":"mcm","clk":"1001532667","pt":1580637626821,"mc":[{"id":"1.168224340","rc":[{"batb":[[0,2.34,48.71],[1,2.06,25.65]],"ltp":0.0,"tv":0.0,"id":6498878}]}]}
{"op":"mcm","clk":"1001532827","pt":1580637628944,"mc":[{"id":"1.168224340","rc":[{"batb":[[2,1.92,394.91]],"ltp":0.0,"tv":0.0,"id":6498878}]}]}
{"op":"mcm","clk":"1001533536","pt":1580637638043,"mc":[{"id":"1.168224340","rc":[{"batb":[[0,2.34,31.09]],"ltp":0.0,"tv":0.0,"id":6498878},{"batb":[[0,1.6,69.74],[1,1.55,33.05],[2,1.4,451]],"batl":[[0,1.74,42.01],[1,1.71,0],[2,1.74,0]],"ltp":1.07,"tv":1084.13,"id":8174333}]}]}
{"op":"mcm","clk":"1001533671","pt":1580637639546,"mc":[{"id":"1.168224340","rc":[{"batb":[[0,2.06,25.65],[1,1.92,394.91],[2,1.01,15.52]],"ltp":0.0,"tv":0.0,"id":6498878},{"batb":[[0,1.55,33.05],[1,1.4,451],[2,1.01,15.51]],"ltp":1.07,"tv":1084.13,"id":8174333}]}]}
{"op":"mcm","clk":"1001533764","pt":1580637640838,"mc":[{"id":"1.168224340","rc":[{"batb":[[0,1.55,213.09],[1,1.54,161.03],[2,1.4,451]],"batl":[[0,1.87,158.6],[1,1.89,158.9]],"ltp":1.07,"tv":1084.13,"id":8174333}]}]}
{"op":"mcm","clk":"1001534264","pt":1580637647411,"mc":[{"id":"1.168224340","rc":[{"batl":[[0,1.6,144.48],[1,1.61,134.92]],"ltp":1.07,"tv":1084.13,"id":8174333}]}]}
{"op":"mcm","clk":"1001534323","pt":1580637648220,"mc":[{"id":"1.168224340","rc":[{"batb":[[0,2.58,13.69],[1,2.32,18.1],[2,2.06,25.65]],"ltp":0.0,"tv":0.0,"id":6498878},{"batb":[[2,1.49,38.71]],"ltp":1.07,"tv":1084.13,"id":8174333}]}]}
{"op":"mcm","clk":"1001534340","pt":1580637648533,"mc":[{"id":"1.168224340","rc":[{"batb":[[1,2.52,26.89],[2,2.32,18.1]],"batl":[[0,2.92,21.85]],"ltp":0.0,"tv":0.0,"id":6498878},{"batb":[[2,1.53,78.98]],"batl":[[2,1.65,42.01]],"ltp":1.07,"tv":1084.13,"id":8174333}]}]}
{"op":"mcm","clk":"1001534974","pt":1580637657141,"mc":[{"id":"1.168224340","rc":[{"batb":[[0,2.52,26.89],[1,2.32,18.1],[2,1.92,394.91]],"ltp":0.0,"tv":0.0,"id":6498878},{"batb":[[0,1.53,78.98],[1,1.49,38.71],[2,1.4,451]],"batl":[[0,1.65,42.01],[1,1.61,0],[2,1.65,0]],"ltp":1.07,"tv":1084.13,"id":8174333}]}]}
{"op":"mcm","clk":"1001535009","pt":1580637657512,"mc":[{"id":"1.168224340","rc":[{"batb":[[0,2.32,18.1],[1,1.92,394.91],[2,1.01,15.52]],"ltp":0.0,"tv":0.0,"id":6498878},{"batb":[[0,1.49,38.71],[1,1.4,451],[2,1.01,15.51]],"ltp":1.07,"tv":1084.13,"id":8174333}]}]}
{"op":"mcm","clk":"1001535281","pt":1580637660321,"mc":[{"id":"1.168224340","rc":[{"batb":[[0,1.5,235.34],[1,1.49,222.87],[2,1.4,451]],"ltp":1.07,"tv":1084.13,"id":8174333}]}]}
{"op":"mcm","clk":"1001535381","pt":1580637661421,"mc":[{"id":"1.168224340","rc":[{"batb":[[1,1.01,15.52],[2,1.01,0]],"ltp":0.0,"tv":0.0,"id":6498878},{"batb":[[2,1.01,15.51]],"ltp":1.07,"tv":1084.13,"id":8174333}]}]}
{"op":"mcm","clk":"1001535579","pt":1580637663332,"mc":[{"id":"1.168224340","rc":[{"batb":[[0,2.78,11.33],[1,2.6,13.53],[2,2.32,18.1]],"ltp":0.0,"tv":0.0,"id":6498878},{"batb":[[2,1.46,41.7]],"batl":[[0,1.55,173.72],[1,1.56,151.42]],"ltp":1.07,"tv":1084.13,"id":8174333}]}]}
{"op":"mcm","clk":"1001535670","pt":1580637664414,"mc":[{"id":"1.168224340","rc":[{"batb":[[2,1.01,15.52]],"ltp":0.0,"tv":0.0,"id":6498878}]}]}
{"op":"mcm","clk":"1001535772","pt":1580637665353,"mc":[{"id":"1.168224340","rc":[{"batb":[[1,2.64,25.21],[2,2.6,13.53]],"batl":[[0,3.05,20.16]],"ltp":0.0,"tv":0.0,"id":6498878},{"batb":[[1,1.49,308.57]],"batl":[[2,1.6,42.01]],"ltp":1.07,"tv":1084.13,"id":8174333}]}]}
{"op":"mcm","clk":"1001536224","pt":1580637671325,"mc":[{"id":"1.168224340","rc":[{"batb":[[0,2.64,25.21],[1,2.6,13.53],[2,2.04,394.09]],"ltp":0.0,"tv":0.0,"id":6498878},{"batb":[[0,1.49,85.7],[1,1.46,41.7],[2,1.34,465.43]],"batl":[[0,1.6,42.01],[1,1.56,0],[2,1.6,0]],"ltp":1.07,"tv":1084.13,"id":8174333}]}]}
{"op":"mcm","clk":"1001536247","pt":1580637671536,"mc":[{"id":"1.168224340","rc":[{"batb":[[0,2.6,13.53],[1,2.04,394.09],[2,1.01,15.52]],"ltp":0.0,"tv":0.0,"id":6498878},{"batb":[[0,1.46,41.7],[1,1.34,465.43],[2,1.01,15.51]],"ltp":1.07,"tv":1084.13,"id":8174333}]}]}
{"op":"mcm","clk":"1001536447","pt":1580637674026,"mc":[{"id":"1.168224340","rc":[{"batb":[[0,1.48,228.24],[1,1.47,194.75],[2,1.46,41.7]],"batl":[[0,1.59,145.27],[1,1.6,138.02]],"ltp":1.07,"tv":1084.13,"id":8174333}]}]}
{"op":"mcm","clk":"1001536765","pt":1580637678235,"mc":[{"id":"1.168224340","rc":[{"batl":[[0,1.53,218.3],[1,1.54,158.76]],"ltp":1.07,"tv":1084.13,"id":8174333}]}]}
{"op":"mcm","clk":"1001536829","pt":1580637679265,"mc":[{"id":"1.168224340","rc":[{"batb":[[0,2.86,10.46],[1,2.74,23.53],[2,2.54,14.32]],"batl":[[0,3.2,18.48]],"ltp":0.0,"tv":0.0,"id":6498878},{"batb":[[2,1.46,132.44]],"batl":[[2,1.57,42.01]],"ltp":1.07,"tv":1084.13,"id":8174333}]}]}
{"op":"mcm","clk":"1001540570","pt":1580637725297,"mc":[{"id":"1.168224340","rc":[{"trd":[[1.48,242]],"batb":[[0,1.48,107.25]],"ltp":1.48,"tv":1326.11,"id":8174333}],"tv":1326.11}]}
{"op":"mcm","clk":"1001540868","pt":1580637728267,"mc":[{"id":"1.168224340","rc":[{"batb":[[0,1.48,183.93]],"batl":[[0,1.53,261.18]],"ltp":1.48,"tv":1326.11,"id":8174333}]}]}
{"op":"mcm","clk":"1001543901","pt":1580637762158,"mc":[{"id":"1.168224340","rc":[{"batb":[[0,2.74,23.53],[1,2.54,14.32],[2,2.04,394.09]],"ltp":0.0,"tv":0.0,"id":6498878},{"batb":[[0,1.46,90.74],[1,1.34,465.43],[2,1.33,63.81]],"batl":[[0,1.57,42.01],[1,1.54,0],[2,1.57,0]],"ltp":1.48,"tv":1326.11,"id":8174333}]}]}
{"op":"mcm","clk":"1001544042","pt":1580637763599,"mc":[{"id":"1.168224340","rc":[{"batb":[[0,2.54,14.32],[1,2.04,394.09],[2,1.01,15.52]],"ltp":0.0,"tv":0.0,"id":6498878},{"batb":[[0,1.34,465.43],[1,1.33,63.81],[2,1.01,15.51]],"ltp":1.48,"tv":1326.11,"id":8174333}]}]}
{"op":"mcm","clk":"1001544145","pt":1580637764949,"mc":[{"id":"1.168224340","rc":[{"batb":[[0,1.35,328.28],[1,1.34,764.74],[2,1.33,63.81]],"batl":[[0,1.63,158.33],[1,1.64,126.4]],"ltp":1.48,"tv":1326.11,"id":8174333}]}]}
{"op":"mcm","clk":"1001544291","pt":1580637766666,"mc":[{"id":"1.168224340","rc":[{"batb":[[0,1.34,465.43],[1,1.33,63.81],[2,1.01,15.51]],"ltp":1.48,"tv":1326.11,"id":8174333}]}]}
{"op":"mcm","clk":"1001544564","pt":1580637770053,"mc":[{"id":"1.168224340","rc":[{"batb":[[0,1.45,249.31],[1,1.44,213.2],[2,1.34,465.43]],"batl":[[0,1.5,264.08],[1,1.51,171.34]],"ltp":1.48,"tv":1326.11,"id":8174333}]}]}
{"op":"mcm","clk":"1001544715","pt":1580637771762,"mc":[{"id":"1.168224340","rc":[{"batb":[[0,1.34,465.43],[1,1.33,63.81],[2,1.01,15.51]],"ltp":1.48,"tv":1326.11,"id":8174333}]}]}
{"op":"mcm","clk":"1001544960","pt":1580637775185,"mc":[{"id":"1.168224340","rc":[{"batb":[[0,1.35,328.28],[1,1.34,764.74],[2,1.33,63.81]],"batl":[[0,1.63,158.33],[1,1.64,126.4]],"ltp":1.48,"tv":1326.11,"id":8174333}]}]}
{"op":"mcm","clk":"1001545476","pt":1580637781385,"mc":[{"id":"1.168224340","rc":[{"batb":[[1,1.01,15.52],[2,1.01,0]],"ltp":0.0,"tv":0.0,"id":6498878},{"batb":[[1,1.34,299.31]],"ltp":1.48,"tv":1326.11,"id":8174333}]}]}
{"op":"mcm","clk":"1001545582","pt":1580637782372,"mc":[{"id":"1.168224340","rc":[{"batb":[[0,3.55,15.03],[1,2.96,24.08],[2,1.01,15.52]],"ltp":0.0,"tv":0.0,"id":6498878},{"batl":[[0,1.39,257.67],[1,1.4,235.19]],"ltp":1.48,"tv":1326.11,"id":8174333}]}]}
{"op":"mcm","clk":"1001545602","pt":1580637782580,"mc":[{"id":"1.168224340","rc":[{"batb":[[1,3.3,17.64],[2,2.96,24.08]],"batl":[[0,3.9,14.28]],"ltp":0.0,"tv":0.0,"id":6498878},{"batb":[[0,1.35,447.59]],"batl":[[2,1.44,42.01]],"ltp":1.48,"tv":1326.11,"id":8174333}]}]}
{"op":"mcm","clk":"1001546950","pt":1580637797586,"mc":[{"id":"1.168224340","rc":[{"batb":[[0,2.96,24.08],[1,2.42,381.73],[2,1.01,15.52]],"ltp":0.0,"tv":0.0,"id":6498878},{"batb":[[0,1.22,523],[1,1.21,110.63],[2,1.01,15.51]],"ltp":1.48,"tv":1326.11,"id":8174333}]}]}
{"op":"mcm","clk":"1001547165","pt":1580637800490,"mc":[{"id":"1.168224340","rc":[{"batb":[[0,1.22,1056.62],[1,1.21,644.41]],"batl":[[0,1.5,179.22],[1,1.51,171.92]],"ltp":1.48,"tv":1326.11,"id":8174333}]}]}
{"op":"mcm","clk":"1001547573","pt":1580637806289,"mc":[{"id":"1.168224340","rc":[{"batb":[[1,1.01,15.52],[2,1.01,0]],"ltp":0.0,"tv":0.0,"id":6498878},{"batb":[[0,1.22,533.62]],"ltp":1.48,"tv":1326.11,"id":8174333}]}]}
{"op":"mcm","clk":"1001547648","pt":1580637807330,"mc":[{"id":"1.168224340","rc":[{"batb":[[0,4.5,11.76],[1,2.96,24.08],[2,1.01,15.52]],"batl":[[0,5.4,9.24]],"ltp":0.0,"tv":0.0,"id":6498878},{"batl":[[0,1.25,340.22],[1,1.26,399.23],[2,1.29,42.01]],"ltp":1.48,"tv":1326.11,"id":8174333}]}]}
{"op":"mcm","clk":"1001547675","pt":1580637807748,"mc":[{"id":"1.168224340","rc":[{"batb":[[0,4.9,13.77],[1,4.5,11.76],[2,3.85,24.71]],"ltp":0.0,"tv":0.0,"id":6498878},{"batb":[[2,1.1,228.26]],"ltp":1.48,"tv":1326.11,"id":8174333}]}]}
{"op":"mcm","clk":"1001547890","pt":1580637810512,"mc":[{"id":"1.168224340","rc":[{"batb":[[2,1.14,627.92]],"ltp":1.48,"tv":1326.11,"id":8174333}]}]}
{"op":"mcm","clk":"1001549063","pt":1580637824241,"mc":[{"id":"1.168224340","rc":[{"batb":[[0,1.21,110.63],[1,1.14,627.92],[2,1.1,228.26]],"batl":[[0,1.29,42.01],[1,1.26,0],[2,1.29,0]],"ltp":1.48,"tv":1326.11,"id":8174333}]}]}
{"op":"mcm","clk":"1001549090","pt":1580637824549,"mc":[{"id":"1.168224340","rc":[{"batb":[[0,4.5,11.76],[1,3.85,24.71],[2,2.8,375.33]],"ltp":0.0,"tv":0.0,"id":6498878},{"batb":[[0,1.14,627.92],[1,1.1,227.63],[2,1.01,15.51]],"ltp":1.48,"tv":1326.11,"id":8174333}]}]}
{"op":"mcm","clk":"1001549185","pt":1580637825662,"mc":[{"id":"1.168224340","rc":[{"batb":[[0,3.85,24.71],[1,1.01,15.52],[2,2.8,0]],"ltp":0.0,"tv":0.0,"id":6498878},{"batb":[[0,1.1,227.63],[1,1.01,15.51],[2,1.01,0]],"ltp":1.48,"tv":1326.11,"id":8174333}]}]}
{"op":"mcm","clk":"1001549300","pt":1580637827165,"mc":[{"id":"1.168224340","rc":[{"batb":[[0,1.12,226.64],[1,1.11,939.68],[2,1.1,227.63]],"batl":[[0,1.34,154.55],[1,1.35,280]],"ltp":1.48,"tv":1326.11,"id":8174333}]}]}
{"op":"mcm","clk":"1001549848","pt":1580637833360,"mc":[{"id":"1.168224340","rc":[{"batb":[[0,8,8.89],[1,6,16.44],[2,3.85,24.71]],"ltp":0.0,"tv":0.0,"id":6498878},{"batl":[[0,1.14,983.39]],"ltp":1.48,"tv":1326.11,"id":8174333}]}]}
{"op":"mcm","clk":"1001549866","pt":1580637833571,"mc":[{"id":"1.168224340","rc":[{"batb":[[2,1.01,15.52]],"ltp":0.0,"tv":0.0,"id":6498878}]}]}
{"op":"mcm","clk":"1001549972","pt":1580637834865,"mc":[{"id":"1.168224340","rc":[{"batb":[[1,7.2,6.72],[2,6,16.44]],"batl":[[0,9.4,4.2]],"ltp":0.0,"tv":0.0,"id":6498878},{"batb":[[0,1.12,394.68]],"batl":[[1,1.16,42.01]],"ltp":1.48,"tv":1326.11,"id":8174333}]}]}
{"op":"mcm","clk":"1001550826","pt":1580637844359,"mc":[{"id":"1.168224340","rc":[{"batb":[[0,7.2,6.72],[1,6,16.44],[2,3.5,371.08]],"ltp":0.0,"tv":0.0,"id":6498878},{"batb":[[0,1.12,168.04],[1,1.06,955.61],[2,1.05,457.38]],"batl":[[0,1.16,42.01],[1,1.16,0]],"ltp":1.48,"tv":1326.11,"id":8174333}]}]}
{"op":"mcm","clk":"1001550971","pt":1580637846066,"mc":[{"id":"1.168224340","rc":[{"batb":[[0,6,16.44],[1,1.01,15.52],[2,3.5,0]],"ltp":0.0,"tv":0.0,"id":6498878},{"batb":[[0,1.05,457.38],[1,1.01,15.51],[2,1.05,0]],"ltp":1.48,"tv":1326.11,"id":8174333}]}]}
{"op":"mcm","clk":"1001551359","pt":1580637850368,"mc":[{"id":"1.168224340","rc":[{"batb":[[0,1.1,1167.64],[1,1.05,457.38],[2,1.01,15.51]],"batl":[[0,1.12,511.5],[1,1.13,640.72]],"ltp":1.48,"tv":1326.11,"id":8174333}]}]}
{"op":"mcm","clk":"1001551490","pt":1580637852082,"mc":[{"id":"1.168224340","rc":[{"batb":[[0,1.05,457.38],[1,1.01,15.51],[2,1.01,0]],"ltp":1.48,"tv":1326.11,"id":8174333}]}]}
{"op":"mcm","clk":"1001551798","pt":1580637855506,"mc":[{"id":"1.168224340","rc":[{"batb":[[0,1.06,243.76],[1,1.05,1446.44],[2,1.01,15.51]],"batl":[[0,1.19,699.72],[1,1.2,386.86]],"ltp":1.48,"tv":1326.11,"id":8174333}]}]}
{"op":"mcm","clk":"1001551883","pt":1580637856494,"mc":[{"id":"1.168224340","rc":[{"trd":[[1.06,147.88]],"batb":[[0,1.06,169.82]],"ltp":1.06,"tv":1473.99,"id":8174333}],"tv":1473.99}]}
{"op":"mcm","clk":"1001552186","pt":1580637859968,"mc":[{"id":"1.168224340","rc":[{"batb":[[0,1.06,216.68]],"ltp":1.06,"tv":1473.99,"id":8174333}]}]}
{"op":"mcm","clk":"1001552255","pt":1580637860590,"mc":[{"id":"1.168224340","rc":[{"batb":[[0,1.05,457.38],[1,1.01,15.51],[2,1.01,0]],"ltp":1.06,"tv":1473.99,"id":8174333}]}]}
{"op":"mcm","clk":"1001552599","pt":1580637864285,"mc":[{"id":"1.168224340","rc":[{"batb":[[1,4.5,17.23],[2,1.01,15.52]],"ltp":0.0,"tv":0.0,"id":6498878},{"batb":[[0,1.16,689.67],[1,1.15,587.69],[2,1.05,447.46]],"ltp":1.06,"tv":1473.99,"id":8174333}]}]}
{"op":"mcm","clk":"1001552664","pt":1580637864904,"mc":[{"id":"1.168224340","rc":[{"batb":[[1,5.7,8.4],[2,4.5,17.23]],"batl":[[0,7,6.72]],"ltp":0.0,"tv":0.0,"id":6498878},{"batb":[[2,1.09,779.05]],"ltp":1.06,"tv":1473.99,"id":8174333}]}]}
{"op":"mcm","clk":"1001554987","pt":1580637891328,"mc":[{"id":"1.168224340","rc":[{"batb":[[0,1.15,155.63],[1,1.09,779.05],[2,1.05,447.46]],"ltp":1.06,"tv":1473.99,"id":8174333}]}]}
{"op":"mcm","clk":"1001555068","pt":1580637892106,"mc":[{"id":"1.168224340","rc":[{"batb":[[0,4.5,17.23],[1,3.15,373.59],[2,1.01,15.52]],"ltp":0.0,"tv":0.0,"id":6498878},{"batb":[[0,1.09,779.05],[1,1.05,447.46],[2,1.01,15.51]],"ltp":1.06,"tv":1473.99,"id":8174333}]}]}
{"op":"mcm","clk":"1001555133","pt":1580637892936,"mc":[{"id":"1.168224340","rc":[{"batb":[[1,1.01,15.52],[2,1.01,0]],"ltp":0.0,"tv":0.0,"id":6498878},{"batb":[[0,1.05,447.46],[1,1.01,15.51],[2,1.01,0]],"ltp":1.06,"tv":1473.99,"id":8174333}]}]}
{"op":"mcm","clk":"1001555499","pt":1580637897340,"mc":[{"id":"1.168224340","rc":[{"batb":[[0,1.14,530.28],[1,1.13,612.71],[2,1.05,447.46]],"batl":[[0,1.16,473.37],[1,1.17,639.13]],"ltp":1.06,"tv":1473.99,"id":8174333}]}]}
{"op":"mcm","clk":"1001555667","pt":1580637899160,"mc":[{"id":"1.168224340","rc":[{"batb":[[1,3.25,373.26],[2,1.01,15.52]],"ltp":0.0,"tv":0.0,"id":6498878},{"batb":[[2,1.08,824.68]],"ltp":1.06,"tv":1473.99,"id":8174333}]}]}
{"op":"mcm","clk":"1001555805","pt":1580637900156,"mc":[{"id":"1.168224340","rc":[{"batb":[[0,1.08,824.68],[1,1.05,447.46],[2,1.01,15.51]],"ltp":1.06,"tv":1473.99,"id":8174333}]}]}
{"op":"mcm","clk":"1001555995","pt":1580637902078,"mc":[{"id":"1.168224340","rc":[{"batb":[[1,1.01,15.52],[2,1.01,0]],"ltp":0.0,"tv":0.0,"id":6498878},{"batb":[[0,1.05,447.46],[1,1.01,15.51],[2,1.01,0]],"ltp":1.06,"tv":1473.99,"id":8174333}]}]}
{"op":"mcm","clk":"1001556475","pt":1580637907278,"mc":[{"id":"1.168224340","rc":[{"batb":[[1,4.2,12.6],[2,3.05,21.64]],"batl":[[0,5,10.08]],"ltp":0.0,"tv":0.0,"id":6498878},{"batb":[[0,1.25,346.12],[1,1.24,630.75],[2,1.23,95.13]],"batl":[[0,1.28,344.43],[1,1.29,350.29],[2,1.31,42.01]],"ltp":1.06,"tv":1473.99,"id":8174333}]}]}
{"op":"mcm","clk":"1001558075","pt":1580637926831,"mc":[{"id":"1.168224340","rc":[{"batb":[[0,4.2,12.6],[1,3.05,21.64],[2,2.72,378.25]],"ltp":0.0,"tv":0.0,"id":6498878},{"batb":[[0,1.24,168.04],[1,1.16,576.13],[2,1.05,424.41]],"batl":[[0,1.31,42.01],[1,1.29,0],[2,1.31,0]],"ltp":1.06,"tv":1473.99,"id":8174333}]}]}
{"op":"mcm","clk":"1001558209","pt":1580637928333,"mc":[{"id":"1.168224340","rc":[{"batb":[[0,3.05,21.64],[1,1.01,15.52],[2,2.72,0]],"ltp":0.0,"tv":0.0,"id":6498878},{"batb":[[0,1.05,424.41],[1,1.01,15.51],[2,1.05,0]],"ltp":1.06,"tv":1473.99,"id":8174333}]}]}
{"op":"mcm","clk":"1001558355","pt":1580637930011,"mc":[{"id":"1.168224340","rc":[{"batb":[[0,1.06,740.94],[1,1.05,911.54],[2,1.01,15.51]],"batl":[[0,1.47,164.22],[1,1.48,186.63]],"ltp":1.06,"tv":1473.99,"id":8174333}]}]}
{"op":"mcm","clk":"1001558426","pt":1580637930897,"mc":[{"id":"1.168224340","rc":[{"batb":[[0,1.05,424.41],[1,1.01,15.51],[2,1.01,0]],"ltp":1.06,"tv":1473.99,"id":8174333}]}]}
{"op":"mcm","clk":"1001558692","pt":1580637934323,"mc":[{"id":"1.168224340","rc":[{"batb":[[0,1.21,175.27],[1,1.2,570.26],[2,1.05,424.41]],"batl":[[0,1.23,291.62],[1,1.24,441.21]],"ltp":1.06,"tv":1473.99,"id":8174333}]}]}
{"op":"mcm","clk":"1001558791","pt":1580637935521,"mc":[{"id":"1.168224340","rc":[{"batb":[[1,2.9,375.84],[2,1.01,15.52]],"ltp":0.0,"tv":0.0,"id":6498878},{"batb":[[2,1.13,629.97]],"ltp":1.06,"tv":1473.99,"id":8174333}]}]}
{"op":"mcm","clk":"1001558938","pt":1580637937140,"mc":[{"id":"1.168224340","rc":[{"batb":[[0,1.13,629.97],[1,1.05,424.41],[2,1.01,15.51]],"ltp":1.06,"tv":1473.99,"id":8174333}]}]}
{"op":"mcm","clk":"1001559042","pt":1580637938441,"mc":[{"id":"1.168224340","rc":[{"batb":[[1,1.01,15.52],[2,1.01,0]],"ltp":0.0,"tv":0.0,"id":6498878},{"batb":[[0,1.05,424.41],[1,1.01,15.51],[2,1.01,0]],"ltp":1.06,"tv":1473.99,"id":8174333}]}]}
{"op":"mcm","clk":"1001559202","pt":1580637940146,"mc":[{"id":"1.168224340","rc":[{"batb":[[0,1.06,740.94],[1,1.05,911.54],[2,1.01,15.51]],"batl":[[0,1.47,164.22],[1,1.48,186.63]],"ltp":1.06,"tv":1473.99,"id":8174333}]}]}
{"op":"mcm","clk":"1001560984","pt":1580637960075,"mc":[{"id":"1.168224340","rc":[{"batb":[[0,1.05,424.41],[1,1.01,15.51],[2,1.01,0]],"ltp":1.06,"tv":1473.99,"id":8174333}]}]}
{"op":"mcm","clk":"1001561313","pt":1580637963413,"mc":[{"id":"1.168224340","rc":[{"batb":[[0,1.43,210.27],[1,1.42,226.71],[2,1.06,1241.74]],"ltp":1.06,"tv":1473.99,"id":8174333}]}]}
{"op":"mcm","clk":"1001561353","pt":1580637963827,"mc":[{"id":"1.168224340","rc":[{"batb":[[1,2.52,14.71],[2,1.01,15.52]],"ltp":0.0,"tv":0.0,"id":6498878},{"batb":[[2,1.41,48.39]],"ltp":1.06,"tv":1473.99,"id":8174333}]}]}
{"op":"mcm","clk":"1001561473","pt":1580637965017,"mc":[{"id":"1.168224340","rc":[{"batb":[[1,2.98,21],[2,2.52,14.71]],"batl":[[0,3.45,16.8]],"ltp":0.0,"tv":0.0,"id":6498878},{"batb":[[2,1.41,150.05]],"batl":[[2,1.51,42.01]],"ltp":1.06,"tv":1473.99,"id":8174333}]}]}
{"op":"mcm","clk":"1001563522","pt":1580637989149,"mc":[{"id":"1.168224340","rc":[{"batb":[[0,2.98,21],[1,2.52,14.71],[2,2.22,384.52]],"ltp":0.0,"tv":0.0,"id":6498878},{"batb":[[0,1.41,101.66],[1,1.28,485.89],[2,1.23,96.39]],"batl":[[0,1.51,42.01],[1,1.48,0],[2,1.51,0]],"ltp":1.06,"tv":1473.99,"id":8174333}]}]}
{"op":"mcm","clk":"1001563566","pt":1580637989723,"mc":[{"id":"1.168224340","rc":[{"batb":[[0,2.52,14.71],[1,2.22,384.52],[2,1.01,15.52]],"ltp":0.0,"tv":0.0,"id":6498878},{"batb":[[0,1.28,485.89],[1,1.23,96.39],[2,1.01,15.51]],"ltp":1.06,"tv":1473.99,"id":8174333}]}]}
{"op":"mcm","clk":"1001563766","pt":1580637992232,"mc":[{"id":"1.168224340","rc":[{"batb":[[0,2.5,14.87]],"ltp":0.0,"tv":0.0,"id":6498878},{"batb":[[1,1.25,203.44],[2,1.24,459.37]],"batl":[[0,1.64,148.42],[1,1.65,123.9]],"ltp":1.06,"tv":1473.99,"id":8174333}]}]}
{"op":"mcm","clk":"1001563828","pt":1580637993021,"mc":[{"id":"1.168224340","rc":[{"batb":[[1,1.23,95.52],[2,1.01,15.51]],"ltp":1.06,"tv":1473.99,"id":8174333}]}]}
{"op":"mcm","clk":"1001564021","pt":1580637995371,"mc":[{"id":"1.168224340","rc":[{"batb":[[1,1.01,15.52],[2,1.01,0]],"ltp":0.0,"tv":0.0,"id":6498878},{"batb":[[0,1.23,95.52],[1,1.01,15.51],[2,1.01,0]],"ltp":1.06,"tv":1473.99,"id":8174333}]}]}
{"op":"mcm","clk":"1001564094","pt":1580637996044,"mc":[{"id":"1.168224340","rc":[{"batb":[[0,1.58,267.8],[1,1.57,150.14],[2,1.23,95.52]],"ltp":1.06,"tv":1473.99,"id":8174333}]}]}
{"op":"mcm","clk":"1001564186","pt":1580637997140,"mc":[{"id":"1.168224340","rc":[{"batb":[[1,2.2,21.01],[2,1.01,15.52]],"batl":[[0,2.84,22.69]],"ltp":0.0,"tv":0.0,"id":6498878},{"batb":[[0,1.58,298.56],[2,1.54,77.3]],"batl":[[2,1.67,42.01]],"ltp":1.06,"tv":1473.99,"id":8174333}]}]}
{"op":"mcm","clk":"1001564374","pt":1580637999368,"mc":[{"id":"1.168224340","rc":[{"batb":[[1,2.48,27.73],[2,2.2,21.01]],"ltp":0.0,"tv":0.0,"id":6498878}]}]}
{"op":"mcm","clk":"1001565439","pt":1580638011341,"mc":[{"id":"1.168224340","rc":[{"batb":[[0,2.48,27.73],[1,2.2,21.01],[2,1.97,394.86]],"ltp":0.0,"tv":0.0,"id":6498878},{"batb":[[0,1.54,77.3],[1,1.41,49.18],[2,1.38,448.45]],"batl":[[0,1.67,42.01],[1,1.65,0],[2,1.67,0]],"ltp":1.06,"tv":1473.99,"id":8174333}]}]}
{"op":"mcm","clk":"1001565488","pt":1580638011860,"mc":[{"id":"1.168224340","rc":[{"batb":[[0,2.2,21.01],[1,1.97,394.86],[2,1.01,15.52]],"ltp":0.0,"tv":0.0,"id":6498878},{"batb":[[0,1.41,49.18],[1,1.38,448.45],[2,1.01,15.51]],"ltp":1.06,"tv":1473.99,"id":8174333}]}]}
{"op":"mcm","clk":"1001566091","pt":1580638018779,"mc":[{"id":"1.168224340","rc":[{"batb":[[0,1.55,132.11],[1,1.54,161.48],[2,1.41,49.18]],"batl":[[0,1.6,193],[1,1.61,135.33]],"ltp":1.06,"tv":1473.99,"id":8174333}]}]}
{"op":"mcm","clk":"1001566237","pt":1580638020391,"mc":[{"id":"1.168224340","rc":[{"batb":[[0,1.41,49.18],[1,1.38,448.45],[2,1.01,15.51]],"ltp":1.06,"tv":1473.99,"id":8174333}]}]}
{"op":"mcm","clk":"1001566483","pt":1580638023366,"mc":[{"id":"1.168224340","rc":[{"batb":[[0,1.42,240.69],[1,1.41,284],[2,1.38,448.45]],"batl":[[0,1.78,191.6],[1,1.8,186]],"ltp":1.06,"tv":1473.99,"id":8174333}]}]}
{"op":"mcm","clk":"1001567219","pt":1580638031381,"mc":[{"id":"1.168224340","rc":[{"batb":[[1,1.01,15.52],[2,1.01,0]],"ltp":0.0,"tv":0.0,"id":6498878},{"batb":[[2,1.01,15.51]],"ltp":1.06,"tv":1473.99,"id":8174333}]}]}
{"op":"mcm","clk":"1001567415","pt":1580638033307,"mc":[{"id":"1.168224340","rc":[{"batb":[[0,3.1,21.17],[1,2.94,21],[2,2.54,14.4]],"batl":[[0,3.45,16.8]],"ltp":0.0,"tv":0.0,"id":6498878},{"batb":[[1,1.41,385.66],[2,1.23,98.9]],"batl":[[0,1.46,158.52],[1,1.47,192.39],[2,1.51,42.01]],"ltp":1.06,"tv":1473.99,"id":8174333}]}]}
{"op":"mcm","clk":"1001567558","pt":1580638034971,"mc":[{"id":"1.168224340","rc":[{"batb":[[2,1.28,485.89]],"ltp":1.06,"tv":1473.99,"id":8174333}]}]}
{"op":"mcm","clk":"1001568980","pt":1580638051851,"mc":[{"id":"1.168224340","rc":[{"batb":[[0,2.54,14.4],[1,2.22,384.52],[2,1.01,15.52]],"ltp":0.0,"tv":0.0,"id":6498878},{"batb":[[0,1.28,485.89],[1,1.23,98.9],[2,1.01,15.51]],"ltp":1.06,"tv":1473.99,"id":8174333}]}]}
{"op":"mcm","clk":"1001569173","pt":1580638054604,"mc":[{"id":"1.168224340","rc":[{"batb":[[1,1.24,431.25],[2,1.23,589.67]],"batl":[[0,1.63,171.98],[1,1.64,126.73]],"ltp":1.06,"tv":1473.99,"id":8174333}]}]}
{"op":"mcm","clk":"1001570358","pt":1580638067237,"mc":[{"id":"1.168224340","rc":[{"batb":[[1,1.01,15.52],[2,1.01,0]],"ltp":0.0,"tv":0.0,"id":6498878},{"batb":[[0,1.24,431.25],[1,1.23,589.67],[2,1.01,15.51]],"ltp":1.06,"tv":1473.99,"id":8174333}]}]}
{"op":"mcm","clk":"1001570445","pt":1580638068232,"mc":[{"id":"1.168224340","rc":[{"batb":[[0,2.62,512.04],[1,2.54,14.4],[2,1.01,15.52]],"ltp":0.0,"tv":0.0,"id":6498878},{"batl":[[0,1.27,321.75],[1,1.28,367.22]],"ltp":1.06,"tv":1473.99,"id":8174333}]}]}
{"op":"mcm","clk":"1001570521","pt":1580638069260,"mc":[{"id":"1.168224340","rc":[{"batb":[[0,4.6,16.29],[1,4.2,12.6],[2,3.1,20.69]],"batl":[[0,5.1,10.08]],"ltp":0.0,"tv":0.0,"id":6498878},{"batb":[[0,1.24,599.29],[2,1.05,434.01]],"batl":[[2,1.31,42.01]],"ltp":1.06,"tv":1473.99,"id":8174333}]}]}
{"op":"mcm","clk":"1001570730","pt":1580638071428,"mc":[{"id":"1.168224340","rc":[{"batb":[[2,1.16,576.13]],"ltp":1.06,"tv":1473.99,"id":8174333}]}]}
{"op":"mcm","clk":"1001572190","pt":1580638089962,"mc":[{"id":"1.168224340","rc":[{"batb":[[0,3.1,20.69],[1,2.72,378.25],[2,1.01,15.52]],"ltp":0.0,"tv":0.0,"id":6498878},{"batb":[[0,1.16,576.13],[1,1.05,434.01],[2,1.01,15.51]],"ltp":1.06,"tv":1473.99,"id":8174333}]}]}
{"op":"mcm","clk":"1001572391","pt":1580638092347,"mc":[{"id":"1.168224340","rc":[{"batb":[[1,1.01,15.52],[2,1.01,0]],"ltp":0.0,"tv":0.0,"id":6498878},{"batb":[[0,1.06,425.11],[1,1.05,1239.99]],"batl":[[0,1.46,260.04],[1,1.47,191.59]],"ltp":1.06,"tv":1473.99,"id":8174333}]}]}
{"op":"mcm","clk":"1001573315","pt":1580638102950,"mc":[{"id":"1.168224340","rc":[{"batl":[[0,1.07,895.59],[1,1.08,313.53]],"ltp":1.06,"tv":1473.99,"id":8174333}]}]}
{"op":"mcm","clk":"1001573430","pt":1580638104360,"mc":[{"id":"1.168224340","rc":[{"batb":[[0,12.5,7.63],[1,7.8,9.6],[2,1.01,15.52]],"ltp":0.0,"tv":0.0,"id":6498878},{"batb":[[2,1.02,874.08]],"ltp":1.06,"tv":1473.99,"id":8174333}]}]}
{"op":"mcm","clk":"1001573458","pt":1580638104671,"mc":[{"id":"1.168224340","rc":[{"batb":[[0,13.5,3.36],[1,12.5,7.63],[2,7.8,9.6]],"ltp":0.0,"tv":0.0,"id":6498878},{"batb":[[2,1.02,3058.16]],"batl":[[1,1.08,355.54]],"ltp":1.06,"tv":1473.99,"id":8174333}]}]}
{"op":"mcm","clk":"1001575530","pt":1580638129327,"mc":[{"id":"1.168224340","rc":[{"batb":[[1,7.8,9.6],[2,4,369.93]],"ltp":0.0,"tv":0.0,"id":6498878},{"batb":[[0,1.02,3058.16],[1,1.01,15.51],[2,1.02,0]],"batl":[[0,1.08,42.01],[1,1.08,0]],"ltp":1.06,"tv":1473.99,"id":8174333}]}]}
{"op":"mcm","clk":"1001575569","pt":1580638129743,"mc":[{"id":"1.168224340","rc":[{"batb":[[0,7.8,9.6],[1,4,369.93],[2,1.01,15.52]],"ltp":0.0,"tv":0.0,"id":6498878}]}]}
{"op":"mcm","clk":"1001575731","pt":1580638131396,"mc":[{"id":"1.168224340","rc":[{"batb":[[1,1.01,15.52],[2,1.01,0]],"ltp":0.0,"tv":0.0,"id":6498878},{"batb":[[0,1.02,874.08]],"ltp":1.06,"tv":1473.99,"id":8174333}]}]}
{"op":"mcm","clk":"1001576025","pt":1580638134911,"mc":[{"id":"1.168224340","rc":[{"batb":[[0,1.07,465.85],[1,1.06,753.24],[2,1.02,874.08]],"batl":[[0,1.08,607.16],[1,1.09,588.22]],"ltp":1.06,"tv":1473.99,"id":8174333}]}]}
{"op":"mcm","clk":"1001576122","pt":1580638136055,"mc":[{"id":"1.168224340","rc":[{"batb":[[0,1.02,874.08],[1,1.01,15.51],[2,1.02,0]],"ltp":1.06,"tv":1473.99,"id":8174333}]}]}
{"op":"mcm","clk":"1001576401","pt":1580638139012,"mc":[{"id":"1.168224340","rc":[{"batb":[[0,1.03,1259.12],[1,1.02,874.08],[2,1.01,15.51]],"batl":[[0,1.13,645.9],[1,1.14,497.39]],"ltp":1.06,"tv":1473.99,"id":8174333}]}]}
{"op":"mcm","clk":"1001577737","pt":1580638154364,"mc":[{"id":"1.168224340","rc":[{"batb":[[0,21,4.48],[1,11.5,9.84],[2,1.01,15.52]],"ltp":0.0,"tv":0.0,"id":6498878},{"batl":[[0,1.04,1247.01]],"ltp":1.06,"tv":1473.99,"id":8174333}]}]}
{"op":"mcm","clk":"1001577840","pt":1580638155665,"mc":[{"id":"1.168224340","rc":[{"batb":[[2,4.3,371.17]],"batl":[[0,160,37.1]],"ltp":0.0,"tv":0.0,"id":6498878}]}]}
{"op":"mcm","clk":"1001579386","pt":1580638172395,"mc":[{"id":"1.168224340","rc":[{"batb":[[0,1.02,874.08],[1,1.01,15.51],[2,1.01,0]],"ltp":1.06,"tv":1473.99,"id":8174333}]}]}
{"op":"mcm","clk":"1001579404","pt":1580638172554,"mc":[{"id":"1.168224340","rc":[{"batb":[[0,11.5,9.84],[1,4.3,371.17],[2,1.01,15.52]],"ltp":0.0,"tv":0.0,"id":6498878},{"batb":[[0,1.01,15.51],[1,1.01,0]],"ltp":1.06,"tv":1473.99,"id":8174333}]}]}
{"op":"mcm","clk":"1001579499","pt":1580638173765,"mc":[{"id":"1.168224340","rc":[{"batb":[[1,1.01,15.52],[2,1.01,0]],"ltp":0.0,"tv":0.0,"id":6498878}]}]}
{"op":"mcm","clk":"1001579639","pt":1580638175378,"mc":[{"id":"1.168224340","rc":[{"batb":[[0,1.01,1299.57]],"batl":[[0,1.08,742.51],[1,1.09,454.11]],"ltp":1.06,"tv":1473.99,"id":8174333}]}]}
{"op":"mcm","clk":"1001580822","pt":1580638188701,"mc":[{"id":"1.168224340","rc":[{"batb":[[0,1.01,15.51]],"ltp":1.06,"tv":1473.99,"id":8174333}]}]}
{"op":"mcm","clk":"1001581117","pt":1580638192332,"mc":[{"id":"1.168224340","rc":[{"batb":[[1,6.6,13.93],[2,1.01,15.52]],"ltp":0.0,"tv":0.0,"id":6498878},{"batb":[[0,1.07,312.71],[1,1.06,1281.64],[2,1.02,841.98]],"ltp":1.06,"tv":1473.99,"id":8174333}]}]}
{"op":"mcm","clk":"1001581213","pt":1580638193324,"mc":[{"id":"1.168224340","rc":[{"batb":[[0,12,3.36],[1,11.5,9.84],[2,6.6,13.93]],"ltp":0.0,"tv":0.0,"id":6498878},{"batb":[[2,1.03,1571.88]],"batl":[[1,1.09,496.12]],"ltp":1.06,"tv":1473.99,"id":8174333}]}]}
{"op":"mcm","clk":"1001582933","pt":1580638211207,"mc":[{"id":"1.168224340","rc":[{"batb":[[1,6.6,13.93],[2,3.85,370.95]],"ltp":0.0,"tv":0.0,"id":6498878},{"batb":[[0,1.03,1571.88],[1,1.02,841.98],[2,1.01,15.51]],"batl":[[0,1.09,42.01],[1,1.09,0]],"ltp":1.06,"tv":1473.99,"id":8174333}]}]}
{"op":"mcm","clk":"1001582980","pt":1580638211733,"mc":[{"id":"1.168224340","rc":[{"batb":[[0,6.6,13.93],[1,3.85,370.95],[2,1.01,15.52]],"ltp":0.0,"tv":0.0,"id":6498878}]}]}
{"op":"mcm","clk":"1001583122","pt":1580638213373,"mc":[{"id":"1.168224340","rc":[{"batb":[[1,1.01,15.52],[2,1.01,0]],"ltp":0.0,"tv":0.0,"id":6498878},{"batb":[[0,1.02,841.98],[1,1.01,15.51],[2,1.01,0]],"ltp":1.06,"tv":1473.99,"id":8174333}]}]}
{"op":"mcm","clk":"1001583202","pt":1580638214061,"mc":[{"id":"1.168224340","rc":[{"batb":[[0,1.03,1259.12],[1,1.02,841.98],[2,1.01,15.51]],"batl":[[0,1.16,557.24],[1,1.17,555.98]],"ltp":1.06,"tv":1473.99,"id":8174333}]}]}
{"op":"mcm","clk":"1001584942","pt":1580638233810,"mc":[{"id":"1.168224340","rc":[{"batl":[[0,1.04,1199.65]],"ltp":1.06,"tv":1473.99,"id":8174333}]}]}
{"op":"mcm","clk":"1001585041","pt":1580638234903,"mc":[{"id":"1.168224340","rc":[{"batb":[[0,20,5.04],[1,10,12.35],[2,1.01,15.52]],"ltp":0.0,"tv":0.0,"id":6498878}]}]}
{"op":"mcm","clk":"1001585205","pt":1580638236899,"mc":[{"id":"1.168224340","rc":[{"batb":[[2,4.3,371.17]],"batl":[[0,160,37.1]],"ltp":0.0,"tv":0.0,"id":6498878}]}]}
{"op":"mcm","clk":"1001586236","pt":1580638248326,"mc":[{"id":"1.168224340","rc":[{"batl":[[1,1000,0.02]],"ltp":1.06,"tv":1473.99,"id":8174333}]}]}
{"op":"mcm","clk":"1001586272","pt":1580638248634,"mc":[{"id":"1.168224340","rc":[{"batl":[[1,1000,0]],"ltp":1.06,"tv":1473.99,"id":8174333}]}]}
{"op":"mcm","clk":"1001586498","pt":1580638251252,"mc":[{"id":"1.168224340","rc":[{"batb":[[0,10,12.35],[1,4.3,371.17],[2,1.01,15.52]],"ltp":0.0,"tv":0.0,"id":6498878},{"batb":[[0,1.01,15.51],[1,1.02,0],[2,1.01,0]],"ltp":1.06,"tv":1473.99,"id":8174333}]}]}
{"op":"mcm","clk":"1001586545","pt":1580638251827,"mc":[{"id":"1.168224340","rc":[{"batl":[[0,1.03,0.02]],"ltp":1.06,"tv":1473.99,"id":8174333}]}]}
{"op":"mcm","clk":"1001586618","pt":1580638252857,"mc":[{"id":"1.168224340","rc":[{"batb":[[1,1.01,15.52],[2,1.01,0]],"ltp":0.0,"tv":0.0,"id":6498878}]}]}
{"op":"mcm","clk":"1001586758","pt":1580638254219,"mc":[{"id":"1.168224340","rc":[{"batl":[[0,1.09,496.41],[1,1.1,687.11]],"ltp":1.06,"tv":1473.99,"id":8174333}]}]}
{"op":"mcm","clk":"1001587033","pt":1580638257024,"mc":[{"id":"1.168224340","rc":[{"batl":[[0,1.03,1596.39],[1,1.09,496.39],[2,1.1,687.11]],"ltp":1.06,"tv":1473.99,"id":8174333}]}]}
{"op":"mcm","clk":"1001588434","pt":1580638271549,"mc":[{"id":"1.168224340","rc":[{"batl":[[1,1.09,0],[2,1.1,0]],"ltp":1.06,"tv":1473.99,"id":8174333}]}]}
{"op":"mcm","clk":"1001588790","pt":1580638275357,"mc":[{"id":"1.168224340","rc":[{"trd":[[1.03,2494.02]],"batl":[[0,1.03,349.38]],"ltp":1.03,"tv":3968.0,"id":8174333}],"tv":3968.0}]}
{"op":"mcm","clk":"1001589048","pt":1580638278181,"mc":[{"id":"1.168224340","rc":[{"batb":[[0,1.01,18.55]],"ltp":1.03,"tv":3968.0,"id":8174333}]}]}
{"op":"mcm","clk":"1001589130","pt":1580638279282,"mc":[{"id":"1.168224340","rc":[{"batb":[[0,1.01,15.51]],"batl":[[1,1.09,928.33],[2,1.1,259.1]],"ltp":1.03,"tv":3968.0,"id":8174333}]}]}
{"op":"mcm","clk":"1001589184","pt":1580638279897,"mc":[{"id":"1.168224340","rc":[{"batl":[[1,1.09,0],[2,1.1,0]],"ltp":1.03,"tv":3968.0,"id":8174333}]}]}
{"op":"mcm","clk":"1001589403","pt":1580638282393,"mc":[{"id":"1.168224340","rc":[{"trd":[[1.03,2494.05]],"batl":[[0,1.03,349.36]],"ltp":1.03,"tv":3968.04,"id":8174333}],"tv":3968.04}]}
{"op":"mcm","clk":"1001589543","pt":1580638283384,"mc":[{"id":"1.168224340","rc":[{"batb":[[0,23,3.08]],"ltp":0.0,"tv":0.0,"id":6498878},{"batl":[[0,1.02,1271.47],[1,1.03,349.36]],"ltp":1.03,"tv":3968.04,"id":8174333}]}]}
{"op":"mcm","clk":"1001589762","pt":1580638284493,"mc":[{"id":"1.168224340","rc":[{"batb":[[1,4.7,367.67],[2,1.01,15.52]],"ltp":0.0,"tv":0.0,"id":6498878}]}]}
{"op":"mcm","clk":"1001590197","pt":1580638288367,"mc":[{"id":"1.168224340","rc":[{"trd":[[1.01,31.01]],"batl":[[0,1.01,771.31],[1,1.02,1271.47],[2,1.03,349.36]],"ltp":1.01,"tv":3999.05,"id":8174333}],"tv":3999.05}]}
{"op":"mcm","clk":"1001590346","pt":1580638289976,"mc":[{"id":"1.168224340","rc":[{"batl":[[0,1.01,881.31]],"ltp":1.01,"tv":3999.05,"id":8174333}]}]}
{"op":"mcm","clk":"1001590739","pt":1580638294274,"mc":[{"id":"1.168224340","rc":[{"batl":[[0,1.01,771.31]],"ltp":1.01,"tv":3999.05,"id":8174333}]}]}
{"op":"mcm","clk":"1001590851","pt":1580638295415,"mc":[{"id":"1.168224340","rc":[{"batl":[[1,1.03,349.36],[2,1.03,0]],"ltp":1.01,"tv":3999.05,"id":8174333}]}]}
{"op":"mcm","clk":"1001590935","pt":1580638296401,"mc":[{"id":"1.168224340","rc":[{"batb":[[1,1.01,15.52],[2,1.01,0]],"ltp":0.0,"tv":0.0,"id":6498878},{"batl":[[0,1.01,8333.07]],"ltp":1.01,"tv":3999.05,"id":8174333}]}]}
{"op":"mcm","clk":"1001591096","pt":1580638298117,"mc":[{"id":"1.168224340","rc":[{"batl":[[1,1.03,701.41],[2,1.04,898.34]],"ltp":1.01,"tv":3999.05,"id":8174333}]}]}
{"op":"mcm","clk":"1001591192","pt":1580638299191,"mc":[{"id":"1.168224340","rc":[{"batl":[[1,1.03,349.36],[2,1.04,0]],"ltp":1.01,"tv":3999.05,"id":8174333}]}]}
{"op":"mcm","clk":"1001591236","pt":1580638299606,"mc":[{"id":"1.168224340","marketDefinition":{"bspMarket":false,"turnInPlayEnabled":true,"persistenceEnabled":true,"marketBaseRate":5.0,"eventId":"29681717","eventTypeId":"2","numberOfWinners":1,"bettingType":"ODDS","marketType":"SET_WINNER","marketTime":"2020-02-02T09:19:00.000Z","suspendTime":"2020-02-02T09:19:00.000Z","bspReconciled":false,"complete":true,"inPlay":true,"crossMatching":true,"runnersVoidable":false,"numberOfActiveRunners":2,"betDelay":3,"status":"SUSPENDED","runners":[{"status":"ACTIVE","sortPriority":1,"id":6498878,"name":"Marco Trungelliti"},{"status":"ACTIVE","sortPriority":2,"id":8174333,"name":"Enzo Couacaud"}],"regulators":["MR_INT"],"countryCode":"FR","discountAllowed":true,"timezone":"UTC","openDate":"2020-02-02T09:19:00.000Z","version":3148389371,"name":"Set 1 Winner","eventName":"Trungelliti v Couacaud"},"rc":[{"batb":[[0,1.01,15.52],[1,1.01,0]],"ltp":0.0,"tv":0.0,"id":6498878}]}]}
{"op":"mcm","clk":"1001591737","pt":1580638304235,"mc":[{"id":"1.168224340","rc":[{"batl":[[0,1.01,7561.75]],"ltp":1.01,"tv":3999.05,"id":8174333}]}]}
{"op":"mcm","clk":"1001595392","pt":1580638333690,"mc":[{"id":"1.168224340","tv":0.0}]}
{"op":"mcm","clk":"1001595494","pt":1580638334679,"mc":[{"id":"1.168224340","marketDefinition":{"bspMarket":false,"turnInPlayEnabled":true,"persistenceEnabled":true,"marketBaseRate":5.0,"eventId":"29681717","eventTypeId":"2","numberOfWinners":1,"bettingType":"ODDS","marketType":"SET_WINNER","marketTime":"2020-02-02T09:19:00.000Z","suspendTime":"2020-02-02T09:19:00.000Z","bspReconciled":false,"complete":true,"inPlay":true,"crossMatching":false,"runnersVoidable":false,"numberOfActiveRunners":0,"betDelay":3,"status":"CLOSED","settledTime":"2020-02-02T10:12:12.000Z","runners":[{"status":"LOSER","sortPriority":1,"id":6498878,"name":"Marco Trungelliti"},{"status":"WINNER","sortPriority":2,"id":8174333,"name":"Enzo Couacaud"}],"regulators":["MR_INT"],"countryCode":"FR","discountAllowed":true,"timezone":"UTC","openDate":"2020-02-02T09:19:00.000Z","version":3148391037,"name":"Set 1 Winner","eventName":"Trungelliti v Couacaud"}}]}
