{"op":"mcm","clk":"998153799","pt":1580585268961,"mc":[{"id":"1.168224329","marketDefinition":{"bspMarket":false,"turnInPlayEnabled":true,"persistenceEnabled":true,"marketBaseRate":5.0,"eventId":"29681717","eventTypeId":"2","numberOfWinners":1,"bettingType":"ODDS","marketType":"MATCH_ODDS","marketTime":"2020-02-02T09:30:00.000Z","suspendTime":"2020-02-02T09:30:00.000Z","bspReconciled":false,"complete":true,"inPlay":false,"crossMatching":false,"runnersVoidable":false,"numberOfActiveRunners":2,"betDelay":0,"status":"OPEN","runners":[{"status":"ACTIVE","sortPriority":1,"id":6498878,"name":"Marco Trungelliti"},{"status":"ACTIVE","sortPriority":2,"id":8174333,"name":"Enzo Couacaud"}],"regulators":["MR_INT"],"countryCode":"FR","discountAllowed":false,"timezone":"UTC","openDate":"2020-02-02T09:30:00.000Z","version":3147098135,"name":"Match Odds","eventName":"Trungelliti v Couacaud"},"rc":[{"batb":[[0,1.05,152.2],[1,1.04,168.86],[2,1.03,190.07]],"ltp":0.0,"tv":0.0,"id":6498878},{"batb":[[0,1.05,152.2],[1,1.04,168.86],[2,1.03,190.07]],"ltp":0.0,"tv":0.0,"id":8174333}]}]}
{"op":"mcm","clk":"998154037","pt":1580585270458,"mc":[{"id":"1.168224329","marketDefinition":{"bspMarket":false,"turnInPlayEnabled":true,"persistenceEnabled":true,"marketBaseRate":5.0,"eventId":"29681717","eventTypeId":"2","numberOfWinners":1,"bettingType":"ODDS","marketType":"MATCH_ODDS","marketTime":"2020-02-02T09:30:00.000Z","suspendTime":"2020-02-02T09:30:00.000Z","bspReconciled":false,"complete":true,"inPlay":false,"crossMatching":false,"runnersVoidable":false,"numberOfActiveRunners":2,"betDelay":0,"status":"OPEN","runners":[{"status":"ACTIVE","sortPriority":1,"id":6498878,"name":"Marco Trungelliti"},{"status":"ACTIVE","sortPriority":2,"id":8174333,"name":"Enzo Couacaud"}],"regulators":["MR_INT"],"countryCode":"FR","discountAllowed":false,"timezone":"UTC","openDate":"2020-02-02T09:30:00.000Z","version":3147098135,"name":"Match Odds","eventName":"Trungelliti v Couacaud"}}]}
{"op":"mcm","clk":"998154461","pt":1580585272452,"mc":[{"id":"1.168224329","marketDefinition":{"bspMarket":false,"turnInPlayEnabled":true,"persistenceEnabled":true,"marketBaseRate":5.0,"eventId":"29681717","eventTypeId":"2","numberOfWinners":1,"bettingType":"ODDS","marketType":"MATCH_ODDS","marketTime":"2020-02-02T09:30:00.000Z","suspendTime":"2020-02-02T09:30:00.000Z","bspReconciled":false,"complete":true,"inPlay":false,"crossMatching":false,"runnersVoidable":false,"numberOfActiveRunners":2,"betDelay":0,"status":"OPEN","runners":[{"status":"ACTIVE","sortPriority":1,"id":6498878,"name":"Marco Trungelliti"},{"status":"ACTIVE","sortPriority":2,"id":8174333,"name":"Enzo Couacaud"}],"regulators":["MR_INT"],"countryCode":"FR","discountAllowed":true,"timezone":"UTC","openDate":"2020-02-02T09:30:00.000Z","version":3147098135,"name":"Match Odds","eventName":"Trungelliti v Couacaud"}}]}
{"op":"mcm","clk":"998201772","pt":1580585542978,"mc":[{"id":"1.168224329","rc":[{"batb":[[0,1.06,50.48],[1,1.05,152.2],[2,1.04,168.86]],"ltp":0.0,"tv":0.0,"id":6498878},{"batb":[[0,1.06,50.48],[1,1.05,152.2],[2,1.04,168.86]],"ltp":0.0,"tv":0.0,"id":8174333}]}]}
{"op":"mcm","clk":"998203241","pt":1580585550620,"mc":[{"id":"1.168224329","marketDefinition":{"bspMarket":false,"turnInPlayEnabled":true,"persistenceEnabled":true,"marketBaseRate":5.0,"eventId":"29681717","eventTypeId":"2","numberOfWinners":1,"bettingType":"ODDS","marketType":"MATCH_ODDS","marketTime":"2020-02-02T09:30:00.000Z","suspendTime":"2020-02-02T09:30:00.000Z","bspReconciled":false,"complete":true,"inPlay":false,"crossMatching":true,"runnersVoidable":false,"numberOfActiveRunners":2,"betDelay":0,"status":"OPEN","runners":[{"status":"ACTIVE","sortPriority":1,"id":6498878,"name":"Marco Trungelliti"},{"status":"ACTIVE","sortPriority":2,"id":8174333,"name":"Enzo Couacaud"}],"regulators":["MR_INT"],"countryCode":"FR","discountAllowed":true,"timezone":"UTC","openDate":"2020-02-02T09:30:00.000Z","version":3147124809,"name":"Match Odds","eventName":"Trungelliti v Couacaud"}}]}
{"op":"mcm","clk":"998270172","pt":1580585930734,"mc":[{"id":"1.168224329","rc":[{"batl":[[0,48,31.05]],"ltp":0.0,"tv":0.0,"id":6498878},{"batl":[[0,48,31.05]],"ltp":0.0,"tv":0.0,"id":8174333}]}]}
{"op":"mcm","clk":"998565808","pt":1580587945216,"mc":[{"id":"1.168224329","rc":[{"batl":[[1,990,2.2]],"ltp":0.0,"tv":0.0,"id":6498878},{"batl":[[1,990,2.2]],"ltp":0.0,"tv":0.0,"id":8174333}]}]}
{"op":"mcm","clk":"999858323","pt":1580601582397,"mc":[{"id":"1.168224329","rc":[{"batl":[[2,1000,2]],"ltp":0.0,"tv":0.0,"id":6498878},{"batl":[[2,1000,2]],"ltp":0.0,"tv":0.0,"id":8174333}]}]}
{"op":"mcm","clk":"999858375","pt":1580601583322,"mc":[{"id":"1.168224329","rc":[{"batl":[[2,1000,0.02]],"ltp":0.0,"tv":0.0,"id":6498878},{"batl":[[2,1000,0.02]],"ltp":0.0,"tv":0.0,"id":8174333}]}]}
{"op":"mcm","clk":"999858381","pt":1580601583426,"mc":[{"id":"1.168224329","rc":[{"batb":[[0,1.06,50.58],[2,1.04,169.36]],"ltp":0.0,"tv":0.0,"id":6498878},{"batb":[[0,1.06,50.58],[2,1.04,169.36]],"ltp":0.0,"tv":0.0,"id":8174333}]}]}
{"op":"mcm","clk":"999860251","pt":1580601626786,"mc":[{"id":"1.168224329","rc":[{"batb":[[0,1.06,50.68]],"ltp":0.0,"tv":0.0,"id":6498878},{"batb":[[0,1.06,50.68]],"ltp":0.0,"tv":0.0,"id":8174333}]}]}
{"op":"mcm","clk":"1000102221","pt":1580607020668,"mc":[{"id":"1.168224329","rc":[{"batb":[[0,1.06,50.69]],"ltp":0.0,"tv":0.0,"id":6498878},{"batb":[[0,1.06,50.69]],"ltp":0.0,"tv":0.0,"id":8174333}]}]}
{"op":"mcm","clk":"1000473022","pt":1580615093088,"mc":[{"id":"1.168224329","rc":[{"batl":[[0,990,2.2],[1,1000,0.02],[2,1000,0]],"ltp":0.0,"tv":0.0,"id":6498878},{"batl":[[0,990,2.2],[1,1000,0.02],[2,1000,0]],"ltp":0.0,"tv":0.0,"id":8174333}]}]}
{"op":"mcm","clk":"1000533925","pt":1580616337322,"mc":[{"id":"1.168224329","rc":[{"batl":[[0,95,15.9],[1,990,2.2],[2,1000,0.02]],"ltp":0.0,"tv":0.0,"id":6498878},{"batl":[[0,95,15.9],[1,990,2.2],[2,1000,0.02]],"ltp":0.0,"tv":0.0,"id":8174333}]}]}
{"op":"mcm","clk":"1000535669","pt":1580616373193,"mc":[{"id":"1.168224329","rc":[{"batb":[[0,1.13,75.83],[1,1.06,50.58],[2,1.05,152.2]],"ltp":0.0,"tv":0.0,"id":6498878},{"batb":[[0,1.13,75.83],[1,1.06,50.58],[2,1.05,152.2]],"ltp":0.0,"tv":0.0,"id":8174333}]}]}
{"op":"mcm","clk":"1000548094","pt":1580616635539,"mc":[{"id":"1.168224329","rc":[{"batl":[[0,3,84.02],[1,95,15.9],[2,990,2.2]],"ltp":0.0,"tv":0.0,"id":8174333}]}]}
{"op":"mcm","clk":"1000548630","pt":1580616645076,"mc":[{"id":"1.168224329","rc":[{"batb":[[0,1.5,84.02],[1,1.13,75.83],[2,1.06,50.58]],"ltp":0.0,"tv":0.0,"id":8174333}]}]}
{"op":"mcm","clk":"1000757917","pt":1580620189745,"mc":[{"id":"1.168224329","rc":[{"batl":[[0,4.2,153.72],[1,95,15.9],[2,990,2.2]],"ltp":0.0,"tv":0.0,"id":6498878},{"batl":[[1,4.2,153.72],[2,95,15.9]],"ltp":0.0,"tv":0.0,"id":8174333}]}]}
{"op":"mcm","clk":"1000758714","pt":1580620208048,"mc":[{"id":"1.168224329","rc":[{"batb":[[0,1.14,15.23],[1,1.13,75.72],[2,1.06,50.58]],"batl":[[0,4.1,3.36],[1,4.2,153.72],[2,95,15.9]],"ltp":0.0,"tv":0.0,"id":6498878},{"batb":[[0,1.51,10.92],[1,1.5,84.02],[2,1.13,75.83]],"batl":[[0,2.98,3.36],[1,3,84.02],[2,4.2,153.72]],"ltp":0.0,"tv":0.0,"id":8174333}]}]}
{"op":"mcm","clk":"1000785815","pt":1580620785103,"mc":[{"id":"1.168224329","rc":[{"batb":[[0,1.82,24.99],[1,1.14,15.23],[2,1.13,75.72]],"ltp":0.0,"tv":0.0,"id":6498878},{"batb":[[1,1.5,114.31]],"ltp":0.0,"tv":0.0,"id":8174333}]}]}
{"op":"mcm","clk":"1000786357","pt":1580620797557,"mc":[{"id":"1.168224329","rc":[{"batb":[[1,1.13,75.83],[2,1.06,50.58]],"ltp":0.0,"tv":0.0,"id":6498878}]}]}
{"op":"mcm","clk":"1000788795","pt":1580620846460,"mc":[{"id":"1.168224329","rc":[{"batb":[[0,1.83,11.76],[1,1.82,24.99],[2,1.13,75.83]],"ltp":0.0,"tv":0.0,"id":6498878}]}]}
{"op":"mcm","clk":"1000798129","pt":1580621027140,"mc":[{"id":"1.168224329","rc":[{"batb":[[0,1.83,36.75],[1,1.13,75.83],[2,1.06,50.58]],"ltp":0.0,"tv":0.0,"id":6498878},{"batb":[[0,1.51,41.21],[1,1.5,84.02]],"ltp":0.0,"tv":0.0,"id":8174333}]}]}
{"op":"mcm","clk":"1000828030","pt":1580621587822,"mc":[{"id":"1.168224329","rc":[{"batb":[[0,1.51,41.29]],"ltp":0.0,"tv":0.0,"id":8174333}]}]}
{"op":"mcm","clk":"1000836106","pt":1580621752360,"mc":[{"id":"1.168224329","rc":[{"batb":[[0,1.53,123.33],[1,1.51,41.29],[2,1.5,84.02]],"ltp":0.0,"tv":0.0,"id":8174333}]}]}
{"op":"mcm","clk":"1000836118","pt":1580621752565,"mc":[{"id":"1.168224329","rc":[{"batb":[[0,1.87,35.35],[1,1.83,36.75],[2,1.13,75.83]],"ltp":0.0,"tv":0.0,"id":6498878},{"batb":[[0,1.53,49.16]],"ltp":0.0,"tv":0.0,"id":8174333}]}]}
{"op":"mcm","clk":"1000836427","pt":1580621758076,"mc":[{"id":"1.168224329","rc":[{"batb":[[0,1.83,36.75],[1,1.13,75.83],[2,1.06,50.58]],"ltp":0.0,"tv":0.0,"id":6498878},{"batb":[[0,1.51,41.29],[1,1.5,84.02],[2,1.13,75.83]],"ltp":0.0,"tv":0.0,"id":8174333}]}]}
{"op":"mcm","clk":"1000836830","pt":1580621764150,"mc":[{"id":"1.168224329","rc":[{"batb":[[0,1.94,34.26],[1,1.83,36.75],[2,1.13,75.83]],"ltp":0.0,"tv":0.0,"id":6498878},{"batb":[[0,1.52,49.57],[1,1.51,41.21],[2,1.5,84.02]],"ltp":0.0,"tv":0.0,"id":8174333}]}]}
{"op":"mcm","clk":"1000837515","pt":1580621776887,"mc":[{"id":"1.168224329","rc":[{"batb":[[1,1.83,61.74]],"ltp":0.0,"tv":0.0,"id":6498878}]}]}
{"op":"mcm","clk":"1000838193","pt":1580621791330,"mc":[{"id":"1.168224329","rc":[{"batb":[[1,1.83,49.98]],"ltp":0.0,"tv":0.0,"id":6498878}]}]}
{"op":"mcm","clk":"1000838207","pt":1580621791534,"mc":[{"id":"1.168224329","rc":[{"batb":[[1,1.51,30.29]],"ltp":0.0,"tv":0.0,"id":8174333}]}]}
{"op":"mcm","clk":"1000838650","pt":1580621799248,"mc":[{"id":"1.168224329","rc":[{"trd":[[1.94,35.37]],"batb":[[0,1.93,34.36]],"ltp":1.94,"tv":35.37,"id":6498878},{"batb":[[0,1.52,31.82]],"ltp":0.0,"tv":0.0,"id":8174333}],"tv":35.37}]}
{"op":"mcm","clk":"1000838695","pt":1580621800538,"mc":[{"id":"1.168224329","rc":[{"batb":[[1,1.13,75.83],[2,1.06,50.58]],"ltp":1.94,"tv":35.37,"id":6498878}]}]}
{"op":"mcm","clk":"1000840411","pt":1580621841007,"mc":[{"id":"1.168224329","rc":[{"batb":[[0,1.57,30.64],[1,1.53,10.08],[2,1.51,30.36]],"ltp":0.0,"tv":0.0,"id":8174333}]}]}
{"op":"mcm","clk":"1000842410","pt":1580621887306,"mc":[{"id":"1.168224329","rc":[{"batb":[[0,1.93,34.44]],"ltp":1.94,"tv":35.37,"id":6498878}]}]}
{"op":"mcm","clk":"1000842529","pt":1580621891019,"mc":[{"id":"1.168224329","rc":[{"batb":[[1,1.51,30.36],[2,1.5,84.02]],"ltp":0.0,"tv":0.0,"id":8174333}]}]}
{"op":"mcm","clk":"1000850626","pt":1580622125834,"mc":[{"id":"1.168224329","rc":[{"batb":[[1,1.51,30.29]],"ltp":0.0,"tv":0.0,"id":8174333}]}]}
{"op":"mcm","clk":"1000852934","pt":1580622185755,"mc":[{"id":"1.168224329","rc":[{"batb":[[0,1.57,30.72]],"ltp":0.0,"tv":0.0,"id":8174333}]}]}
{"op":"mcm","clk":"1000866462","pt":1580622564533,"mc":[{"id":"1.168224329","rc":[{"batb":[[1,1.51,6.5],[2,1.13,75.83]],"ltp":1.94,"tv":35.37,"id":6498878}]}]}
{"op":"mcm","clk":"1000866513","pt":1580622566023,"mc":[{"id":"1.168224329","rc":[{"batb":[[1,1.51,37.57]],"ltp":0.0,"tv":0.0,"id":8174333}]}]}
{"op":"mcm","clk":"1000888859","pt":1580623254402,"mc":[{"id":"1.168224329","rc":[{"batb":[[0,2,45.43],[1,1.51,6.57]],"ltp":1.94,"tv":35.37,"id":6498878},{"batb":[[0,1.67,29.14],[1,1.66,30.29],[2,1.51,7.36]],"ltp":0.0,"tv":0.0,"id":8174333}]}]}
{"op":"mcm","clk":"1000888862","pt":1580623254455,"mc":[{"id":"1.168224329","rc":[{"batb":[[0,2.02,32.11],[1,2,45.43],[2,1.51,6.57]],"ltp":1.94,"tv":35.37,"id":6498878}]}]}
{"op":"mcm","clk":"1000891284","pt":1580623325006,"mc":[{"id":"1.168224329","rc":[{"batb":[[2,1.51,6.5]],"ltp":1.94,"tv":35.37,"id":6498878},{"batb":[[2,1.51,7.28]],"ltp":0.0,"tv":0.0,"id":8174333}]}]}
{"op":"mcm","clk":"1000906117","pt":1580623685246,"mc":[{"id":"1.168224329","rc":[{"batb":[[0,2.02,32.19]],"ltp":1.94,"tv":35.37,"id":6498878}]}]}
{"op":"mcm","clk":"1000906140","pt":1580623685757,"mc":[{"id":"1.168224329","rc":[{"batb":[[0,1.67,29.22]],"ltp":0.0,"tv":0.0,"id":8174333}]}]}
{"op":"mcm","clk":"1000966828","pt":1580625084649,"mc":[{"id":"1.168224329","rc":[{"batb":[[0,1.66,30.36],[1,1.51,7.28],[2,1.5,84.02]],"ltp":0.0,"tv":0.0,"id":8174333}]}]}
{"op":"mcm","clk":"1000967048","pt":1580625089291,"mc":[{"id":"1.168224329","rc":[{"batb":[[0,1.51,7.36],[1,1.5,84.02],[2,1.38,4.01]],"ltp":0.0,"tv":0.0,"id":8174333}]}]}
{"op":"mcm","clk":"1000967088","pt":1580625090061,"mc":[{"id":"1.168224329","rc":[{"batb":[[0,2.16,32.28],[1,2.14,45.43],[2,1.51,6.57]],"ltp":1.94,"tv":35.37,"id":6498878},{"batb":[[0,1.52,52.82],[1,1.51,7.28],[2,1.5,84.02]],"ltp":0.0,"tv":0.0,"id":8174333}]}]}
{"op":"mcm","clk":"1000967348","pt":1580625096270,"mc":[{"id":"1.168224329","rc":[{"batb":[[1,2.12,45.43]],"ltp":1.94,"tv":35.37,"id":6498878},{"batb":[[0,1.57,35.67]],"ltp":0.0,"tv":0.0,"id":8174333}]}]}
{"op":"mcm","clk":"1000967507","pt":1580625099505,"mc":[{"id":"1.168224329","rc":[{"batb":[[0,1.58,50.64],[1,1.57,35.59],[2,1.51,7.28]],"ltp":0.0,"tv":0.0,"id":8174333}]}]}
{"op":"mcm","clk":"1000968457","pt":1580625122898,"mc":[{"id":"1.168224329","rc":[{"batb":[[2,1.51,6.5]],"ltp":1.94,"tv":35.37,"id":6498878}]}]}
{"op":"mcm","clk":"1000970068","pt":1580625165151,"mc":[{"id":"1.168224329","rc":[{"batb":[[2,1.38,4.01]],"ltp":1.94,"tv":35.37,"id":6498878}]}]}
{"op":"mcm","clk":"1000970094","pt":1580625165666,"mc":[{"id":"1.168224329","rc":[{"batb":[[2,1.5,84.02]],"ltp":0.0,"tv":0.0,"id":8174333}]}]}
{"op":"mcm","clk":"1000970779","pt":1580625183682,"mc":[{"id":"1.168224329","rc":[{"batb":[[0,2.16,32.36]],"ltp":1.94,"tv":35.37,"id":6498878}]}]}
{"op":"mcm","clk":"1000973263","pt":1580625245340,"mc":[{"id":"1.168224329","rc":[{"batb":[[1,1.38,4.01],[2,1.13,75.82]],"ltp":1.94,"tv":35.37,"id":6498878}]}]}
{"op":"mcm","clk":"1000973269","pt":1580625245442,"mc":[{"id":"1.168224329","rc":[{"batb":[[0,2.16,77.79]],"ltp":1.94,"tv":35.37,"id":6498878}]}]}
{"op":"mcm","clk":"1000979420","pt":1580625400154,"mc":[{"id":"1.168224329","rc":[{"batb":[[0,2.2,31.77],[1,2.16,45.51],[2,1.38,4.01]],"ltp":1.94,"tv":35.37,"id":6498878}]}]}
{"op":"mcm","clk":"1000980259","pt":1580625422502,"mc":[{"id":"1.168224329","rc":[{"batb":[[1,2.16,45.43]],"ltp":1.94,"tv":35.37,"id":6498878}]}]}
{"op":"mcm","clk":"1000981268","pt":1580625454224,"mc":[{"id":"1.168224329","rc":[{"batl":[[0,4.1,157.08],[1,95,15.9],[2,990,2.2]],"ltp":1.94,"tv":35.37,"id":6498878}]}]}
{"op":"mcm","clk":"1000982312","pt":1580625482488,"mc":[{"id":"1.168224329","rc":[{"batb":[[0,2.2,31.85]],"ltp":1.94,"tv":35.37,"id":6498878}]}]}
{"op":"mcm","clk":"1000982823","pt":1580625497597,"mc":[{"id":"1.168224329","rc":[{"batb":[[0,2.2,47.6]],"ltp":1.94,"tv":35.37,"id":6498878},{"batb":[[0,1.58,75.64]],"ltp":0.0,"tv":0.0,"id":8174333}]}]}
{"op":"mcm","clk":"1000998540","pt":1580625908527,"mc":[{"id":"1.168224329","rc":[{"batl":[[0,2.4,3.03],[1,2.98,3.36],[2,3,84.02]],"ltp":0.0,"tv":0.0,"id":8174333}]}]}
{"op":"mcm","clk":"1000999865","pt":1580625944654,"mc":[{"id":"1.168224329","rc":[{"batl":[[1,3,84.02],[2,4.2,153.72]],"ltp":0.0,"tv":0.0,"id":8174333}]}]}
{"op":"mcm","clk":"1001010237","pt":1580626283537,"mc":[{"id":"1.168224329","rc":[{"batb":[[0,1.57,35.67],[1,1.5,84.02],[2,1.38,4.01]],"ltp":0.0,"tv":0.0,"id":8174333}]}]}
{"op":"mcm","clk":"1001010335","pt":1580626285441,"mc":[{"id":"1.168224329","rc":[{"batb":[[0,1.58,77.64],[1,1.57,35.59],[2,1.5,84.02]],"ltp":0.0,"tv":0.0,"id":8174333}]}]}
{"op":"mcm","clk":"1001010433","pt":1580626288415,"mc":[{"id":"1.168224329","rc":[{"batb":[[1,1.5,84.02],[2,1.38,4.01]],"ltp":0.0,"tv":0.0,"id":8174333}]}]}
{"op":"mcm","clk":"1001013650","pt":1580626397349,"mc":[{"id":"1.168224329","rc":[{"batb":[[1,1.38,4.01],[2,1.35,7.57]],"batl":[[1,4.2,153.72],[2,95,15.9]],"ltp":0.0,"tv":0.0,"id":8174333}]}]}
{"op":"mcm","clk":"1001013885","pt":1580626403376,"mc":[{"id":"1.168224329","rc":[{"batl":[[1,3,42.01],[2,4.2,153.72]],"ltp":0.0,"tv":0.0,"id":8174333}]}]}
{"op":"mcm","clk":"1001030284","pt":1580626862710,"mc":[{"id":"1.168224329","rc":[{"batb":[[0,2.2,93.03],[1,1.38,4.01],[2,1.33,45.43]],"ltp":1.94,"tv":35.37,"id":6498878}]}]}
{"op":"mcm","clk":"1001031455","pt":1580626894436,"mc":[{"id":"1.168224329","rc":[{"batb":[[1,1.55,59.06],[2,1.38,4.01]],"ltp":0.0,"tv":0.0,"id":8174333}]}]}
{"op":"mcm","clk":"1001038142","pt":1580627089352,"mc":[{"id":"1.168224329","rc":[{"batb":[[0,2.2,45.51]],"batl":[[0,2.72,3.79],[1,4.1,157.08],[2,95,15.9]],"ltp":1.94,"tv":35.37,"id":6498878},{"batb":[[0,1.55,59.14],[1,1.38,4.01],[2,1.35,7.57]],"batl":[[0,1.83,7.57],[1,2.4,3.03],[2,3,42.01]],"ltp":0.0,"tv":0.0,"id":8174333}]}]}
{"op":"mcm","clk":"1001038152","pt":1580627089555,"mc":[{"id":"1.168224329","rc":[{"batl":[[0,2.72,48.7]],"ltp":1.94,"tv":35.37,"id":6498878},{"batl":[[0,1.81,59.13],[1,1.83,7.57],[2,2.4,3.03]],"ltp":0.0,"tv":0.0,"id":8174333}]}]}
{"op":"mcm","clk":"1001038445","pt":1580627096842,"mc":[{"id":"1.168224329","rc":[{"batl":[[0,1.79,59.96],[1,1.8,7.57]],"ltp":0.0,"tv":0.0,"id":8174333}]}]}
{"op":"mcm","clk":"1001038668","pt":1580627102147,"mc":[{"id":"1.168224329","rc":[{"batl":[[0,1.78,67.82],[1,2.4,3.03],[2,3,42.01]],"ltp":0.0,"tv":0.0,"id":8174333}]}]}
{"op":"mcm","clk":"1001040402","pt":1580627144395,"mc":[{"id":"1.168224329","rc":[{"batl":[[1,4.1,153.72]],"ltp":1.94,"tv":35.37,"id":6498878}]}]}
{"op":"mcm","clk":"1001044062","pt":1580627220708,"mc":[{"id":"1.168224329","rc":[{"batb":[[0,2.2,45.43]],"ltp":1.94,"tv":35.37,"id":6498878}]}]}
{"op":"mcm","clk":"1001046966","pt":1580627280765,"mc":[{"id":"1.168224329","rc":[{"batb":[[0,2.2,45.51]],"ltp":1.94,"tv":35.37,"id":6498878}]}]}
{"op":"mcm","clk":"1001085207","pt":1580628161315,"mc":[{"id":"1.168224329","rc":[{"batb":[[1,1.52,45.43],[2,1.38,4.01]],"ltp":1.94,"tv":35.37,"id":6498878}]}]}
{"op":"mcm","clk":"1001085453","pt":1580628167632,"mc":[{"id":"1.168224329","rc":[{"batb":[[1,1.52,30.29]],"ltp":1.94,"tv":35.37,"id":6498878}]}]}
{"op":"mcm","clk":"1001086225","pt":1580628182527,"mc":[{"id":"1.168224329","rc":[{"batl":[[1,2.28,3.03]],"ltp":0.0,"tv":0.0,"id":8174333}]}]}
{"op":"mcm","clk":"1001092059","pt":1580628319195,"mc":[{"id":"1.168224329","rc":[{"batl":[[0,2.72,3.79]],"ltp":1.94,"tv":35.37,"id":6498878},{"batl":[[0,1.78,7.57]],"ltp":0.0,"tv":0.0,"id":8174333}]}]}
{"op":"mcm","clk":"1001093048","pt":1580628344663,"mc":[{"id":"1.168224329","rc":[{"batl":[[0,1.78,67.91]],"ltp":0.0,"tv":0.0,"id":8174333}]}]}
{"op":"mcm","clk":"1001102038","pt":1580628516118,"mc":[{"id":"1.168224329","rc":[{"batb":[[0,2.36,50.29],[1,2.2,45.51],[2,1.52,30.29]],"ltp":1.94,"tv":35.37,"id":6498878},{"batb":[[0,1.61,70.95],[1,1.55,59.06],[2,1.38,4.01]],"ltp":0.0,"tv":0.0,"id":8174333}]}]}
{"op":"mcm","clk":"1001106670","pt":1580628613322,"mc":[{"id":"1.168224329","rc":[{"batb":[[1,1.54,40.89]],"ltp":0.0,"tv":0.0,"id":8174333}]}]}
{"op":"mcm","clk":"1001107494","pt":1580628631756,"mc":[{"id":"1.168224329","rc":[{"batb":[[1,1.54,59.06]],"ltp":0.0,"tv":0.0,"id":8174333}]}]}
{"op":"mcm","clk":"1001111668","pt":1580628719002,"mc":[{"id":"1.168224329","rc":[{"batb":[[1,2.2,45.43]],"ltp":1.94,"tv":35.37,"id":6498878}]}]}
{"op":"mcm","clk":"1001116892","pt":1580628836025,"mc":[{"id":"1.168224329","rc":[{"batb":[[2,2.06,27.15]],"ltp":1.94,"tv":35.37,"id":6498878},{"batb":[[2,1.5,57.55]],"ltp":0.0,"tv":0.0,"id":8174333}]}]}
{"op":"mcm","clk":"1001127181","pt":1580629080367,"mc":[{"id":"1.168224329","rc":[{"batb":[[0,2.36,50.37]],"ltp":1.94,"tv":35.37,"id":6498878}]}]}
{"op":"mcm","clk":"1001134411","pt":1580629238200,"mc":[{"id":"1.168224329","rc":[{"batl":[[0,1.78,7.57]],"ltp":0.0,"tv":0.0,"id":8174333}]}]}
{"op":"mcm","clk":"1001134464","pt":1580629239179,"mc":[{"id":"1.168224329","rc":[{"batb":[[2,1.52,30.29]],"ltp":1.94,"tv":35.37,"id":6498878},{"batb":[[2,1.38,4.01]],"ltp":0.0,"tv":0.0,"id":8174333}]}]}
{"op":"mcm","clk":"1001134494","pt":1580629239790,"mc":[{"id":"1.168224329","rc":[{"batb":[[2,2.06,35.72]],"ltp":1.94,"tv":35.37,"id":6498878},{"batb":[[2,1.5,75.72]],"ltp":0.0,"tv":0.0,"id":8174333}]}]}
{"op":"mcm","clk":"1001178452","pt":1580630261994,"mc":[{"id":"1.168224329","rc":[{"batb":[[2,2,37.86]],"ltp":1.94,"tv":35.37,"id":6498878},{"batb":[[2,1.41,37.87]],"ltp":0.0,"tv":0.0,"id":8174333}]}]}
{"op":"mcm","clk":"1001178475","pt":1580630262560,"mc":[{"id":"1.168224329","rc":[{"batb":[[2,2.08,35.06]],"ltp":1.94,"tv":35.37,"id":6498878},{"batb":[[2,1.5,75.72]],"ltp":0.0,"tv":0.0,"id":8174333}]}]}
{"op":"mcm","clk":"1001187212","pt":1580630450075,"mc":[{"id":"1.168224329","rc":[{"batb":[[1,2.22,45.43]],"ltp":1.94,"tv":35.37,"id":6498878}]}]}
{"op":"mcm","clk":"1001196086","pt":1580630612257,"mc":[{"id":"1.168224329","rc":[{"batb":[[1,2.22,83.3]],"ltp":1.94,"tv":35.37,"id":6498878},{"trd":[[1.62,4.88],[1.68,0.15]],"batb":[[0,1.61,70.87]],"ltp":1.62,"tv":5.03,"id":8174333}],"tv":40.4}]}
{"op":"mcm","clk":"1001221965","pt":1580631087891,"mc":[{"id":"1.168224329","rc":[{"batb":[[2,2,37.86]],"ltp":1.94,"tv":35.37,"id":6498878},{"batb":[[2,1.41,37.87]],"ltp":1.62,"tv":5.03,"id":8174333}]}]}
{"op":"mcm","clk":"1001222007","pt":1580631088525,"mc":[{"id":"1.168224329","rc":[{"batb":[[2,2.08,35.06]],"ltp":1.94,"tv":35.37,"id":6498878},{"batb":[[2,1.49,77.27]],"ltp":1.62,"tv":5.03,"id":8174333}]}]}
{"op":"mcm","clk":"1001222674","pt":1580631102070,"mc":[{"id":"1.168224329","rc":[{"batb":[[1,1.53,40.89]],"ltp":1.62,"tv":5.03,"id":8174333}]}]}
{"op":"mcm","clk":"1001226388","pt":1580631187337,"mc":[{"id":"1.168224329","rc":[{"batb":[[1,1.49,77.27],[2,1.41,37.87]],"ltp":1.62,"tv":5.03,"id":8174333}]}]}
{"op":"mcm","clk":"1001226398","pt":1580631187539,"mc":[{"id":"1.168224329","rc":[{"batb":[[1,1.53,59.06],[2,1.49,77.27]],"ltp":1.62,"tv":5.03,"id":8174333}]}]}
{"op":"mcm","clk":"1001251119","pt":1580631806156,"mc":[{"id":"1.168224329","rc":[{"batl":[[1,4,153.72]],"ltp":1.94,"tv":35.37,"id":6498878},{"batl":[[2,2.92,153.72]],"ltp":1.62,"tv":5.03,"id":8174333}]}]}
{"op":"mcm","clk":"1001252098","pt":1580631833105,"mc":[{"id":"1.168224329","rc":[{"batl":[[0,1.74,2.02],[1,1.78,7.57],[2,2.28,3.03]],"ltp":1.62,"tv":5.03,"id":8174333}]}]}
{"op":"mcm","clk":"1001268672","pt":1580632188604,"mc":[{"id":"1.168224329","rc":[{"batb":[[0,2.36,100.66]],"ltp":1.94,"tv":35.37,"id":6498878},{"batb":[[0,1.61,141.74]],"ltp":1.62,"tv":5.03,"id":8174333}]}]}
{"op":"mcm","clk":"1001269346","pt":1580632205548,"mc":[{"id":"1.168224329","rc":[{"batb":[[0,2.36,119.19]],"ltp":1.94,"tv":35.37,"id":6498878},{"batb":[[0,1.61,191.26]],"ltp":1.62,"tv":5.03,"id":8174333}]}]}
{"op":"mcm","clk":"1001269529","pt":1580632209755,"mc":[{"id":"1.168224329","rc":[{"batb":[[1,2.22,37.86]],"ltp":1.94,"tv":35.37,"id":6498878},{"batb":[[1,1.49,77.27],[2,1.41,37.87]],"ltp":1.62,"tv":5.03,"id":8174333}]}]}
{"op":"mcm","clk":"1001270237","pt":1580632231157,"mc":[{"id":"1.168224329","rc":[{"batb":[[2,2,37.86]],"ltp":1.94,"tv":35.37,"id":6498878},{"batb":[[1,1.41,37.87],[2,1.38,4]],"ltp":1.62,"tv":5.03,"id":8174333}]}]}
{"op":"mcm","clk":"1001273527","pt":1580632321233,"mc":[{"id":"1.168224329","rc":[{"batb":[[0,2.42,258.44],[1,2.36,119.19],[2,2.22,37.86]],"ltp":1.94,"tv":35.37,"id":6498878}]}]}
{"op":"mcm","clk":"1001273545","pt":1580632321540,"mc":[{"id":"1.168224329","rc":[{"batb":[[1,2.4,18.01],[2,2.36,119.19]],"ltp":1.94,"tv":35.37,"id":6498878},{"batb":[[0,1.61,149.94],[1,1.6,42.01],[2,1.41,37.87]],"ltp":1.62,"tv":5.03,"id":8174333}]}]}
{"op":"mcm","clk":"1001278284","pt":1580632444313,"mc":[{"id":"1.168224329","rc":[{"batb":[[0,2.42,119.13],[2,2.36,18.61]],"ltp":1.94,"tv":35.37,"id":6498878},{"batb":[[0,1.61,46.14]],"ltp":1.62,"tv":5.03,"id":8174333}]}]}
{"op":"mcm","clk":"1001278289","pt":1580632444416,"mc":[{"id":"1.168224329","rc":[{"batb":[[0,2.46,92.56],[1,2.42,119.13],[2,2.4,18.01]],"ltp":1.94,"tv":35.37,"id":6498878}]}]}
{"op":"mcm","clk":"1001278377","pt":1580632445824,"mc":[{"id":"1.168224329","rc":[{"batb":[[0,2.48,116.26],[1,2.46,92.56],[2,2.42,17.75]],"ltp":1.94,"tv":35.37,"id":6498878},{"batb":[[1,1.59,42.72]],"ltp":1.62,"tv":5.03,"id":8174333}]}]}
{"op":"mcm","clk":"1001278418","pt":1580632446647,"mc":[{"id":"1.168224329","rc":[{"batb":[[1,1.58,43.45]],"ltp":1.62,"tv":5.03,"id":8174333}]}]}
{"op":"mcm","clk":"1001278455","pt":1580632447524,"mc":[{"id":"1.168224329","rc":[{"batb":[[2,2.44,17.5]],"ltp":1.94,"tv":35.37,"id":6498878}]}]}
{"op":"mcm","clk":"1001278794","pt":1580632454164,"mc":[{"id":"1.168224329","rc":[{"trd":[[1.61,30.4]],"batb":[[0,1.61,30.94]],"ltp":1.61,"tv":35.43,"id":8174333}],"tv":70.8}]}
{"op":"mcm","clk":"1001278820","pt":1580632454586,"mc":[{"id":"1.168224329","rc":[{"batb":[[1,2.46,102.23]],"ltp":1.94,"tv":35.37,"id":6498878},{"batb":[[0,1.61,8.2],[1,1.59,75.62],[2,1.58,43.45]],"ltp":1.61,"tv":35.43,"id":8174333}]}]}
{"op":"mcm","clk":"1001278873","pt":1580632455652,"mc":[{"id":"1.168224329","rc":[{"batb":[[1,2.46,119.49]],"ltp":1.94,"tv":35.37,"id":6498878},{"batb":[[2,1.57,44.22]],"ltp":1.61,"tv":35.43,"id":8174333}]}]}
{"op":"mcm","clk":"1001283500","pt":1580632570296,"mc":[{"id":"1.168224329","rc":[{"batb":[[0,2.5,74.04],[1,2.48,116.26],[2,2.46,17.27]],"ltp":1.94,"tv":35.37,"id":6498878}]}]}
{"op":"mcm","clk":"1001287497","pt":1580632675433,"mc":[{"id":"1.168224329","rc":[{"batb":[[0,2.5,74.11]],"ltp":1.94,"tv":35.37,"id":6498878}]}]}
{"op":"mcm","clk":"1001290871","pt":1580632766501,"mc":[{"id":"1.168224329","rc":[{"batl":[[2,90,1.68]],"ltp":1.94,"tv":35.37,"id":6498878}]}]}
{"op":"mcm","clk":"1001291241","pt":1580632775212,"mc":[{"id":"1.168224329","rc":[{"batb":[[1,2.46,17.27],[2,2.44,17.5]],"batl":[[2,90,2.55]],"ltp":1.94,"tv":35.37,"id":6498878}]}]}
{"op":"mcm","clk":"1001291266","pt":1580632775781,"mc":[{"id":"1.168224329","rc":[{"batb":[[0,2.5,189.63]],"ltp":1.94,"tv":35.37,"id":6498878}]}]}
{"op":"mcm","clk":"1001291475","pt":1580632780703,"mc":[{"id":"1.168224329","rc":[{"trd":[[2.5,1.6],[2.52,0.15]],"batb":[[0,2.5,188.76]],"batl":[[2,90,1.68]],"ltp":2.5,"tv":37.11,"id":6498878}],"tv":72.55}]}
{"op":"mcm","clk":"1001291657","pt":1580632785728,"mc":[{"id":"1.168224329","rc":[{"batl":[[2,95,15.9]],"ltp":2.5,"tv":37.11,"id":6498878}]}]}
{"op":"mcm","clk":"1001293173","pt":1580632821252,"mc":[{"id":"1.168224329","rc":[{"batb":[[0,2.52,33.49],[1,2.5,188.76],[2,2.46,17.27]],"ltp":2.5,"tv":37.11,"id":6498878}]}]}
{"op":"mcm","clk":"1001293195","pt":1580632821868,"mc":[{"id":"1.168224329","rc":[{"batb":[[1,2.5,73.24]],"ltp":2.5,"tv":37.11,"id":6498878},{"batb":[[2,1.56,45.01]],"ltp":1.61,"tv":35.43,"id":8174333}]}]}
{"op":"mcm","clk":"1001293227","pt":1580632822691,"mc":[{"id":"1.168224329","rc":[{"batb":[[2,2.48,17.03]],"ltp":2.5,"tv":37.11,"id":6498878}]}]}
{"op":"mcm","clk":"1001293471","pt":1580632828575,"mc":[{"id":"1.168224329","rc":[{"batb":[[0,2.54,46.45],[1,2.52,33.49]],"ltp":2.5,"tv":37.11,"id":6498878}]}]}
{"op":"mcm","clk":"1001305332","pt":1580633067238,"mc":[{"id":"1.168224329","rc":[{"batl":[[0,1.78,7.57],[1,2.28,3.03],[2,2.92,153.72]],"ltp":1.61,"tv":35.43,"id":8174333}]}]}
{"op":"mcm","clk":"1001306528","pt":1580633091985,"mc":[{"id":"1.168224329","rc":[{"trd":[[2.54,36.28]],"batb":[[0,2.54,10.17]],"ltp":2.54,"tv":73.39,"id":6498878},{"trd":[[1.65,55.85]],"ltp":1.65,"tv":91.28,"id":8174333}],"tv":164.68}]}
{"op":"mcm","clk":"1001306601","pt":1580633093382,"mc":[{"id":"1.168224329","rc":[{"trd":[[2.54,73.92]],"batb":[[0,2.52,33.49],[1,2.48,17.03],[2,2.46,17.27]],"ltp":2.54,"tv":111.03,"id":6498878},{"trd":[[1.65,248.22]],"batb":[[0,1.65,53.39],[1,1.61,8.2],[2,1.59,90.98]],"ltp":1.65,"tv":283.66,"id":8174333}],"tv":394.69}]}
{"op":"mcm","clk":"1001306643","pt":1580633094206,"mc":[{"id":"1.168224329","rc":[{"trd":[[2.54,103.75]],"batb":[[1,2.5,26.57],[2,2.42,17.75]],"ltp":2.54,"tv":140.86,"id":6498878},{"trd":[[1.65,294.14]],"batb":[[0,1.65,7.47],[1,1.62,71.43],[2,1.61,8.2]],"ltp":1.65,"tv":329.57,"id":8174333}],"tv":470.44}]}
{"op":"mcm","clk":"1001306684","pt":1580633094779,"mc":[{"id":"1.168224329","rc":[{"batb":[[2,2.44,17.5]],"ltp":2.54,"tv":140.86,"id":6498878}]}]}
{"op":"mcm","clk":"1001308931","pt":1580633136723,"mc":[{"id":"1.168224329","rc":[{"trd":[[2.52,16.6]],"batb":[[0,2.52,17.04]],"ltp":2.52,"tv":157.31,"id":6498878},{"trd":[[1.66,25]],"ltp":1.66,"tv":354.57,"id":8174333}],"tv":511.89}]}
{"op":"mcm","clk":"1001309261","pt":1580633142302,"mc":[{"id":"1.168224329","rc":[{"batb":[[0,1.65,32.25]],"ltp":1.66,"tv":354.57,"id":8174333}]}]}
{"op":"mcm","clk":"1001309293","pt":1580633142814,"mc":[{"id":"1.168224329","rc":[{"batb":[[2,2.42,17.75]],"ltp":2.52,"tv":157.31,"id":6498878},{"trd":[[1.65,304.27]],"batb":[[0,1.65,27.18]],"ltp":1.65,"tv":364.7,"id":8174333}],"tv":522.02}]}
{"op":"mcm","clk":"1001309344","pt":1580633143794,"mc":[{"id":"1.168224329","rc":[{"batb":[[2,2.44,17.5]],"ltp":2.52,"tv":157.31,"id":6498878}]}]}
{"op":"mcm","clk":"1001310557","pt":1580633165950,"mc":[{"id":"1.168224329","rc":[{"trd":[[2.52,50.7]],"batb":[[0,2.5,26.57],[1,2.44,17.5],[2,2.42,17.75]],"batl":[[0,2.52,82.94],[1,2.72,3.79],[2,4,153.72]],"ltp":2.52,"tv":191.41,"id":6498878}],"tv":556.12}]}
{"op":"mcm","clk":"1001310610","pt":1580633166832,"mc":[{"id":"1.168224329","rc":[{"batb":[[1,2.4,18.01],[2,2.22,37.86]],"ltp":2.52,"tv":191.41,"id":6498878}]}]}
{"op":"mcm","clk":"1001311276","pt":1580633180025,"mc":[{"id":"1.168224329","rc":[{"batl":[[0,2.72,3.79],[1,4,153.72],[2,95,15.9]],"ltp":2.52,"tv":191.41,"id":6498878}]}]}
{"op":"mcm","clk":"1001312698","pt":1580633211361,"mc":[{"id":"1.168224329","rc":[{"batb":[[0,2.4,18.01],[1,2.22,37.86],[2,2.02,37.12]],"ltp":2.52,"tv":191.41,"id":6498878}]}]}
{"op":"mcm","clk":"1001312714","pt":1580633211772,"mc":[{"id":"1.168224329","rc":[{"batb":[[0,2.42,83.64],[1,2.36,18.53],[2,2.22,37.86]],"ltp":2.52,"tv":191.41,"id":6498878},{"batb":[[1,1.62,112.09]],"ltp":1.65,"tv":364.7,"id":8174333}]}]}
{"op":"mcm","clk":"1001313039","pt":1580633219184,"mc":[{"id":"1.168224329","rc":[{"batb":[[0,1.65,2.4]],"ltp":1.65,"tv":364.7,"id":8174333}]}]}
{"op":"mcm","clk":"1001313065","pt":1580633219800,"mc":[{"id":"1.168224329","rc":[{"batb":[[1,2.38,18.27],[2,2.36,18.53]],"ltp":2.52,"tv":191.41,"id":6498878},{"batb":[[1,1.62,71.43]],"ltp":1.65,"tv":364.7,"id":8174333}]}]}
{"op":"mcm","clk":"1001318849","pt":1580633341333,"mc":[{"id":"1.168224329","rc":[{"batb":[[0,2.4,98.86]],"ltp":2.52,"tv":191.41,"id":6498878}]}]}
{"op":"mcm","clk":"1001336381","pt":1580633760340,"mc":[{"id":"1.168224329","rc":[{"batb":[[0,1.65,146.08],[1,1.62,112.09]],"batl":[[0,1.71,138.63],[1,1.78,7.57],[2,2.28,3.03]],"ltp":1.65,"tv":364.7,"id":8174333}]}]}
{"op":"mcm","clk":"1001336390","pt":1580633760545,"mc":[{"id":"1.168224329","rc":[{"batb":[[1,2.36,18.53],[2,2.22,37.86]],"ltp":2.52,"tv":191.41,"id":6498878},{"trd":[[1.65,352.27]],"batb":[[0,1.65,122.07]],"ltp":1.65,"tv":412.71,"id":8174333}],"tv":604.12}]}
{"op":"mcm","clk":"1001340163","pt":1580633854637,"mc":[{"id":"1.168224329","rc":[{"trd":[[1.65,422.28]],"batb":[[0,1.65,87.07]],"ltp":1.65,"tv":482.71,"id":8174333}],"tv":674.13}]}
{"op":"mcm","clk":"1001342215","pt":1580633915299,"mc":[{"id":"1.168224329","rc":[{"trd":[[2.4,296.5]],"batb":[[0,2.36,18.53],[1,2.02,37.12],[2,2,37.86]],"batl":[[0,2.4,483.11],[1,2.72,3.79],[2,4,153.72]],"ltp":2.4,"tv":487.91,"id":6498878},{"trd":[[1.71,138.63]],"batl":[[0,1.78,7.57],[1,2.28,3.03],[2,2.92,153.72]],"ltp":1.71,"tv":621.34,"id":8174333}],"tv":1109.26}]}
{"op":"mcm","clk":"1001342261","pt":1580633916125,"mc":[{"id":"1.168224329","rc":[{"trd":[[2.4,512.51]],"batb":[[0,2.3,81.78],[1,2.02,61.83]],"batl":[[0,2.4,375.1]],"ltp":2.4,"tv":703.92,"id":6498878},{"batb":[[0,1.66,117.1],[1,1.65,87.07],[2,1.62,40.66]],"ltp":1.71,"tv":621.34,"id":8174333}],"tv":1325.27}]}
{"op":"mcm","clk":"1001342313","pt":1580633917102,"mc":[{"id":"1.168224329","rc":[{"batb":[[1,2.24,20.32],[2,2.02,37.12]],"ltp":2.4,"tv":703.92,"id":6498878},{"batb":[[0,1.68,37.07],[1,1.66,117.1],[2,1.65,87.07]],"ltp":1.71,"tv":621.34,"id":8174333}]}]}
{"op":"mcm","clk":"1001342584","pt":1580633924932,"mc":[{"id":"1.168224329","rc":[{"batb":[[0,1.71,4.23],[1,1.68,37.07],[2,1.66,117.1]],"ltp":1.71,"tv":621.34,"id":8174333}]}]}
{"op":"mcm","clk":"1001342785","pt":1580633932112,"mc":[{"id":"1.168224329","rc":[{"trd":[[2.4,522.51]],"batl":[[0,2.4,370.1]],"ltp":2.4,"tv":713.92,"id":6498878}],"tv":1335.27}]}
{"op":"mcm","clk":"1001343696","pt":1580633957648,"mc":[{"id":"1.168224329","rc":[{"batb":[[0,1.72,2.27],[1,1.71,4.23],[2,1.68,37.07]],"ltp":1.71,"tv":621.34,"id":8174333}]}]}
{"op":"mcm","clk":"1001343728","pt":1580633958668,"mc":[{"id":"1.168224329","rc":[{"trd":[[2.4,754.52]],"batl":[[0,2.4,254.1]],"ltp":2.4,"tv":945.93,"id":6498878}],"tv":1567.27}]}
{"op":"mcm","clk":"1001344566","pt":1580633986962,"mc":[{"id":"1.168224329","rc":[{"trd":[[2.4,1052.53]],"batl":[[0,2.4,105.09]],"ltp":2.4,"tv":1243.94,"id":6498878},{"batb":[[1,1.69,49.45]],"ltp":1.71,"tv":621.34,"id":8174333}],"tv":1865.28}]}
{"op":"mcm","clk":"1001344652","pt":1580633989789,"mc":[{"id":"1.168224329","rc":[{"batb":[[0,1.72,150.15]],"batl":[[0,1.76,144.51],[1,1.78,7.57],[2,2.28,3.03]],"ltp":1.71,"tv":621.34,"id":8174333}]}]}
{"op":"mcm","clk":"1001345263","pt":1580634003268,"mc":[{"id":"1.168224329","rc":[{"batb":[[2,2.14,2]],"ltp":2.4,"tv":1243.94,"id":6498878}]}]}
{"op":"mcm","clk":"1001345346","pt":1580634004188,"mc":[{"id":"1.168224329","rc":[{"trd":[[2.3,86.96]],"batb":[[0,2.3,38.3],[2,2.02,37.34]],"ltp":2.3,"tv":1330.9,"id":6498878}],"tv":1952.24}]}
{"op":"mcm","clk":"1001345443","pt":1580634005287,"mc":[{"id":"1.168224329","rc":[{"trd":[[1.72,294.6]],"batb":[[0,1.72,2.85]],"ltp":1.72,"tv":915.94,"id":8174333}],"tv":2246.84}]}
{"op":"mcm","clk":"1001345514","pt":1580634006373,"mc":[{"id":"1.168224329","rc":[{"batb":[[1,1.68,37.07],[2,1.65,87.07]],"ltp":1.72,"tv":915.94,"id":8174333}]}]}
{"op":"mcm","clk":"1001345522","pt":1580634006478,"mc":[{"id":"1.168224329","rc":[{"batb":[[0,1.72,47.24]],"ltp":1.72,"tv":915.94,"id":8174333}]}]}
{"op":"mcm","clk":"1001346240","pt":1580634018105,"mc":[{"id":"1.168224329","rc":[{"batl":[[0,1.75,2.27],[1,1.76,144.51],[2,1.78,7.57]],"ltp":1.72,"tv":915.94,"id":8174333}]}]}
{"op":"mcm","clk":"1001348036","pt":1580634057347,"mc":[{"id":"1.168224329","rc":[{"trd":[[1.75,3.36]],"batl":[[0,1.76,145.1],[1,1.78,7.57],[2,2.28,3.03]],"ltp":1.75,"tv":919.3,"id":8174333}],"tv":2250.2}]}
{"op":"mcm","clk":"1001348070","pt":1580634058167,"mc":[{"id":"1.168224329","rc":[{"trd":[[1.72,386.95]],"batb":[[0,1.72,1.06],[1,1.67,37.62]],"ltp":1.72,"tv":1011.66,"id":8174333}],"tv":2342.56}]}
{"op":"mcm","clk":"1001348184","pt":1580634060132,"mc":[{"id":"1.168224329","rc":[{"batb":[[0,2.32,32.62],[1,2.3,38.3],[2,2.26,20.01]],"ltp":2.3,"tv":1330.9,"id":6498878},{"batb":[[0,1.69,64.41]],"ltp":1.72,"tv":1011.66,"id":8174333}]}]}
{"op":"mcm","clk":"1001350511","pt":1580634116820,"mc":[{"id":"1.168224329","rc":[{"batb":[[0,1.68,86.47]],"ltp":1.72,"tv":1011.66,"id":8174333}]}]}
{"op":"mcm","clk":"1001350582","pt":1580634118209,"mc":[{"id":"1.168224329","rc":[{"trd":[[2.4,1258.99]],"batb":[[2,2.28,19.69]],"batl":[[0,2.4,1.85]],"ltp":2.4,"tv":1537.36,"id":6498878},{"batb":[[1,1.65,125.84],[2,1.62,41.06]],"ltp":1.72,"tv":1011.66,"id":8174333}],"tv":2549.03}]}
{"op":"mcm","clk":"1001352414","pt":1580634156348,"mc":[{"id":"1.168224329","rc":[{"trd":[[2.4,1259.39]],"batb":[[0,2.34,78.66],[1,2.32,32.62],[2,2.3,38.3]],"batl":[[0,2.4,1.45]],"ltp":2.4,"tv":1537.76,"id":6498878},{"trd":[[1.71,139.19]],"batl":[[0,1.76,144.51]],"ltp":1.71,"tv":1012.22,"id":8174333}],"tv":2549.99}]}
{"op":"mcm","clk":"1001352486","pt":1580634157374,"mc":[{"id":"1.168224329","rc":[{"trd":[[2.4,1260.84]],"batb":[[1,2.32,19.1],[2,2.28,19.69]],"batl":[[0,2.72,3.79],[1,4,153.72],[2,95,15.9]],"ltp":2.4,"tv":1539.21,"id":6498878},{"trd":[[1.68,165.25],[1.71,141.23]],"batb":[[0,1.65,87.07],[1,1.63,40.41],[2,1.62,40.66]],"ltp":1.68,"tv":1179.36,"id":8174333}],"tv":2718.58}]}
{"op":"mcm","clk":"1001352496","pt":1580634157580,"mc":[{"id":"1.168224329","rc":[{"batb":[[0,2.36,79.47],[1,2.34,78.66],[2,2.32,19.1]],"ltp":2.4,"tv":1539.21,"id":6498878},{"batb":[[0,1.66,49.66],[1,1.65,87.07],[2,1.63,40.41]],"ltp":1.68,"tv":1179.36,"id":8174333}]}]}
{"op":"mcm","clk":"1001352911","pt":1580634165583,"mc":[{"id":"1.168224329","rc":[{"batb":[[0,1.67,2.27],[1,1.66,49.66],[2,1.65,87.07]],"ltp":1.68,"tv":1179.36,"id":8174333}]}]}
{"op":"mcm","clk":"1001363463","pt":1580634384334,"mc":[{"id":"1.168224329","rc":[{"batl":[[0,2.5,10.13],[1,2.72,3.79],[2,4,153.72]],"ltp":2.4,"tv":1539.21,"id":6498878}]}]}
{"op":"mcm","clk":"1001363496","pt":1580634385013,"mc":[{"id":"1.168224329","rc":[{"trd":[[2.5,21.29]],"batl":[[0,2.72,4.07],[1,4,153.72],[2,95,15.9]],"ltp":2.5,"tv":1558.91,"id":6498878}],"tv":2738.27}]}
{"op":"mcm","clk":"1001363669","pt":1580634388299,"mc":[{"id":"1.168224329","rc":[{"batl":[[0,2.5,223.27],[1,2.72,3.79],[2,4,153.72]],"ltp":2.5,"tv":1558.91,"id":6498878}]}]}
{"op":"mcm","clk":"1001367579","pt":1580634465398,"mc":[{"id":"1.168224329","rc":[{"batl":[[0,1.73,2.27],[1,1.76,144.51],[2,1.78,7.57]],"ltp":1.68,"tv":1179.36,"id":8174333}]}]}
{"op":"mcm","clk":"1001367632","pt":1580634466222,"mc":[{"id":"1.168224329","rc":[{"trd":[[2.5,197.29]],"batl":[[0,2.5,135.27]],"ltp":2.5,"tv":1734.91,"id":6498878}],"tv":2914.27}]}
{"op":"mcm","clk":"1001369863","pt":1580634515253,"mc":[{"id":"1.168224329","rc":[{"trd":[[2.5,467.82]],"batb":[[0,2.5,14.19],[1,2.36,79.47]],"batl":[[0,2.72,3.79],[1,4,153.72],[2,95,15.9]],"ltp":2.5,"tv":2005.44,"id":6498878},{"trd":[[1.66,108.96],[1.67,4.54]],"batb":[[0,1.66,7.68],[1,1.65,87.07],[2,1.64,39.39]],"ltp":1.66,"tv":1267.86,"id":8174333}],"tv":3273.3}]}
{"op":"mcm","clk":"1001369915","pt":1580634516383,"mc":[{"id":"1.168224329","rc":[{"batb":[[1,2.38,23.26],[2,2.36,84.98]],"ltp":2.5,"tv":2005.44,"id":6498878},{"batb":[[0,1.65,87.07],[1,1.64,55.04],[2,1.61,8.6]],"ltp":1.66,"tv":1267.86,"id":8174333}]}]}
{"op":"mcm","clk":"1001369963","pt":1580634517263,"mc":[{"id":"1.168224329","rc":[{"trd":[[1.65,596.42]],"batb":[[0,1.64,55.04],[1,1.61,8.6],[2,1.6,42.01]],"batl":[[0,1.65,14.16],[1,1.73,2.27],[2,1.76,144.51]],"ltp":1.65,"tv":1442.0,"id":8174333}],"tv":3447.44}]}
{"op":"mcm","clk":"1001369971","pt":1580634517467,"mc":[{"id":"1.168224329","rc":[{"batb":[[2,1.59,42.72]],"ltp":1.65,"tv":1442.0,"id":8174333}]}]}
{"op":"mcm","clk":"1001370062","pt":1580634519376,"mc":[{"id":"1.168224329","rc":[{"batb":[[0,2.5,30.99]],"ltp":2.5,"tv":2005.44,"id":6498878},{"trd":[[1.64,108.6]],"batb":[[0,1.63,1.14],[1,1.61,8.2],[2,1.51,87.28]],"ltp":1.64,"tv":1550.6,"id":8174333}],"tv":3556.04}]}
{"op":"mcm","clk":"1001370111","pt":1580634520359,"mc":[{"id":"1.168224329","rc":[{"batb":[[0,2.52,22.92],[1,2.5,14.19],[2,2.48,17.03]],"ltp":2.5,"tv":2005.44,"id":6498878},{"trd":[[1.65,611.56]],"batb":[[0,1.61,8.6],[1,1.59,135.13],[2,1.56,45.01]],"batl":[[0,1.65,6.59]],"ltp":1.65,"tv":1565.75,"id":8174333}],"tv":3571.19}]}
{"op":"mcm","clk":"1001370141","pt":1580634521182,"mc":[{"id":"1.168224329","rc":[{"batl":[[0,1.66,7.53]],"ltp":1.65,"tv":1565.75,"id":8174333}]}]}
{"op":"mcm","clk":"1001370223","pt":1580634523092,"mc":[{"id":"1.168224329","rc":[{"batb":[[0,1.63,7.97],[1,1.61,8.2],[2,1.59,135.13]],"ltp":1.65,"tv":1565.75,"id":8174333}]}]}
{"op":"mcm","clk":"1001370289","pt":1580634524380,"mc":[{"id":"1.168224329","rc":[{"batb":[[1,1.62,7.57],[2,1.61,8.2]],"ltp":1.65,"tv":1565.75,"id":8174333}]}]}
{"op":"mcm","clk":"1001370319","pt":1580634525201,"mc":[{"id":"1.168224329","rc":[{"trd":[[2.52,96.54]],"batb":[[0,2.5,14.19],[1,2.48,17.03],[2,2.32,19.1]],"batl":[[0,2.52,39.11],[1,2.72,3.79],[2,4,153.72]],"ltp":2.52,"tv":2051.28,"id":6498878}],"tv":3617.03}]}
{"op":"mcm","clk":"1001370368","pt":1580634526380,"mc":[{"id":"1.168224329","rc":[{"batb":[[1,2.4,18.01],[2,2.38,100.99]],"ltp":2.52,"tv":2051.28,"id":6498878},{"batb":[[0,1.63,74.57]],"ltp":1.65,"tv":1565.75,"id":8174333}]}]}
{"op":"mcm","clk":"1001370428","pt":1580634527771,"mc":[{"id":"1.168224329","rc":[{"batl":[[0,1.73,2.27],[1,1.76,144.51],[2,1.78,7.57]],"ltp":1.65,"tv":1565.75,"id":8174333}]}]}
{"op":"mcm","clk":"1001370470","pt":1580634529003,"mc":[{"id":"1.168224329","rc":[{"batb":[[0,1.63,66.99],[1,1.61,8.2],[2,1.6,42.01]],"ltp":1.65,"tv":1565.75,"id":8174333}]}]}
{"op":"mcm","clk":"1001370524","pt":1580634530189,"mc":[{"id":"1.168224329","rc":[{"batl":[[0,1.71,7.31],[1,1.73,2.27],[2,1.76,144.51]],"ltp":1.65,"tv":1565.75,"id":8174333}]}]}
{"op":"mcm","clk":"1001370544","pt":1580634530807,"mc":[{"id":"1.168224329","rc":[{"batb":[[0,1.64,7.57],[1,1.63,66.99],[2,1.61,8.2]],"ltp":1.65,"tv":1565.75,"id":8174333}]}]}
{"op":"mcm","clk":"1001370675","pt":1580634533905,"mc":[{"id":"1.168224329","rc":[{"batl":[[0,1.67,8.4],[1,1.71,7.31],[2,1.73,2.27]],"ltp":1.65,"tv":1565.75,"id":8174333}]}]}
{"op":"mcm","clk":"1001370855","pt":1580634537311,"mc":[{"id":"1.168224329","rc":[{"batl":[[0,2.72,3.79],[1,4,153.72],[2,95,15.9]],"ltp":2.52,"tv":2051.28,"id":6498878},{"trd":[[1.64,122.43]],"batb":[[0,1.63,67.65],[1,1.61,8.2],[2,1.59,42.72]],"ltp":1.64,"tv":1579.57,"id":8174333}],"tv":3630.85}]}
{"op":"mcm","clk":"1001370899","pt":1580634538291,"mc":[{"id":"1.168224329","rc":[{"trd":[[2.5,496.2],[2.52,101.04]],"batb":[[0,2.38,100.99],[1,2.34,18.81],[2,2.32,19.1]],"batl":[[0,2.5,20.71],[1,2.72,3.79],[2,4,153.72]],"ltp":2.5,"tv":2084.16,"id":6498878},{"trd":[[1.65,618.43]],"ltp":1.65,"tv":1586.44,"id":8174333}],"tv":3670.6}]}
{"op":"mcm","clk":"1001370956","pt":1580634539271,"mc":[{"id":"1.168224329","rc":[{"batb":[[1,1.61,49.52]],"ltp":1.65,"tv":1586.44,"id":8174333}]}]}
{"op":"mcm","clk":"1001371002","pt":1580634540196,"mc":[{"id":"1.168224329","rc":[{"batb":[[0,1.64,8.23],[1,1.63,66.99],[2,1.61,49.52]],"ltp":1.65,"tv":1586.44,"id":8174333}]}]}
{"op":"mcm","clk":"1001371454","pt":1580634550316,"mc":[{"id":"1.168224329","rc":[{"batb":[[1,2.36,18.53],[2,2.34,18.81]],"batl":[[0,2.72,3.79],[1,4,153.72],[2,95,15.9]],"ltp":2.5,"tv":2084.16,"id":6498878}]}]}
{"op":"mcm","clk":"1001371499","pt":1580634551297,"mc":[{"id":"1.168224329","rc":[{"batb":[[1,2.34,18.81],[2,2.32,19.1]],"ltp":2.5,"tv":2084.16,"id":6498878},{"trd":[[1.67,21.35]],"batb":[[0,1.67,22.71],[1,1.64,8.23],[2,1.63,66.99]],"batl":[[0,1.71,7.31],[1,1.73,2.27],[2,1.76,144.51]],"ltp":1.67,"tv":1603.24,"id":8174333}],"tv":3687.4}]}
{"op":"mcm","clk":"1001371535","pt":1580634552329,"mc":[{"id":"1.168224329","rc":[{"batb":[[2,1.63,107]],"ltp":1.67,"tv":1603.24,"id":8174333}]}]}
{"op":"mcm","clk":"1001371906","pt":1580634561116,"mc":[{"id":"1.168224329","rc":[{"batb":[[1,1.63,107],[2,1.61,49.52]],"batl":[[0,1.73,2.27],[1,1.76,144.51],[2,1.78,7.57]],"ltp":1.67,"tv":1603.24,"id":8174333}]}]}
{"op":"mcm","clk":"1001371960","pt":1580634562363,"mc":[{"id":"1.168224329","rc":[{"trd":[[1.67,64.81]],"batb":[[0,1.63,66.99],[1,1.62,40.66]],"batl":[[0,1.72,7.27],[1,1.73,2.27],[2,1.76,144.51]],"ltp":1.67,"tv":1646.7,"id":8174333}],"tv":3730.86}]}
{"op":"mcm","clk":"1001372018","pt":1580634563345,"mc":[{"id":"1.168224329","rc":[{"batb":[[1,2.36,18.53],[2,2.34,18.81]],"ltp":2.5,"tv":2084.16,"id":6498878},{"batb":[[0,1.64,7.57],[1,1.63,66.99]],"ltp":1.67,"tv":1646.7,"id":8174333}]}]}
{"op":"mcm","clk":"1001372027","pt":1580634563555,"mc":[{"id":"1.168224329","rc":[{"batl":[[1,1.73,4.54]],"ltp":1.67,"tv":1646.7,"id":8174333}]}]}
{"op":"mcm","clk":"1001372077","pt":1580634564540,"mc":[{"id":"1.168224329","rc":[{"batb":[[0,1.65,7.57],[1,1.64,7.57],[2,1.63,66.99]],"ltp":1.67,"tv":1646.7,"id":8174333}]}]}
{"op":"mcm","clk":"1001372205","pt":1580634566862,"mc":[{"id":"1.168224329","rc":[{"batb":[[0,1.63,66.99],[1,1.61,49.52],[2,1.59,42.72]],"batl":[[0,1.73,4.54],[1,1.76,144.51],[2,1.78,7.57]],"ltp":1.67,"tv":1646.7,"id":8174333}]}]}
{"op":"mcm","clk":"1001372255","pt":1580634568045,"mc":[{"id":"1.168224329","rc":[{"batl":[[0,1.69,7.4],[1,1.73,4.54],[2,1.76,144.51]],"ltp":1.67,"tv":1646.7,"id":8174333}]}]}
{"op":"mcm","clk":"1001372382","pt":1580634570059,"mc":[{"id":"1.168224329","rc":[{"batb":[[0,1.65,7.57],[1,1.63,66.99],[2,1.61,49.52]],"ltp":1.67,"tv":1646.7,"id":8174333}]}]}
{"op":"mcm","clk":"1001372420","pt":1580634570936,"mc":[{"id":"1.168224329","rc":[{"batb":[[1,1.64,7.57],[2,1.63,66.99]],"ltp":1.67,"tv":1646.7,"id":8174333}]}]}
{"op":"mcm","clk":"1001374355","pt":1580634613197,"mc":[{"id":"1.168224329","rc":[{"trd":[[1.65,632.26]],"batb":[[0,1.64,8.23],[1,1.63,66.99],[2,1.61,49.52]],"batl":[[0,1.73,4.54],[1,1.76,144.51],[2,1.78,7.57]],"ltp":1.65,"tv":1660.53,"id":8174333}],"tv":3744.69}]}
{"op":"mcm","clk":"1001374393","pt":1580634614277,"mc":[{"id":"1.168224329","rc":[{"trd":[[1.66,122.71]],"batb":[[0,1.63,66.99],[1,1.61,49.52],[2,1.59,42.72]],"ltp":1.66,"tv":1674.28,"id":8174333}],"tv":3758.44}]}
{"op":"mcm","clk":"1001374490","pt":1580634616195,"mc":[{"id":"1.168224329","rc":[{"batb":[[0,1.65,7.57],[1,1.64,7.57],[2,1.63,66.99]],"ltp":1.66,"tv":1674.28,"id":8174333}]}]}
{"op":"mcm","clk":"1001374566","pt":1580634617993,"mc":[{"id":"1.168224329","rc":[{"batb":[[0,1.64,7.57],[1,1.63,66.99],[2,1.61,49.52]],"ltp":1.66,"tv":1674.28,"id":8174333}]}]}
{"op":"mcm","clk":"1001374670","pt":1580634620204,"mc":[{"id":"1.168224329","rc":[{"batb":[[0,1.63,66.99],[1,1.61,49.52],[2,1.59,42.72]],"ltp":1.66,"tv":1674.28,"id":8174333}]}]}
{"op":"mcm","clk":"1001374730","pt":1580634621291,"mc":[{"id":"1.168224329","rc":[{"batl":[[0,1.7,7.35],[1,1.73,4.54],[2,1.76,144.51]],"ltp":1.66,"tv":1674.28,"id":8174333}]}]}
{"op":"mcm","clk":"1001374925","pt":1580634625884,"mc":[{"id":"1.168224329","rc":[{"batb":[[0,1.64,7.57],[1,1.63,66.99],[2,1.61,49.52]],"ltp":1.66,"tv":1674.28,"id":8174333}]}]}
{"op":"mcm","clk":"1001374971","pt":1580634627587,"mc":[{"id":"1.168224329","rc":[{"batb":[[0,1.65,7.57],[1,1.64,7.57],[2,1.63,66.99]],"ltp":1.66,"tv":1674.28,"id":8174333}]}]}
{"op":"mcm","clk":"1001375206","pt":1580634633320,"mc":[{"id":"1.168224329","rc":[{"batb":[[0,1.64,7.57],[1,1.63,66.99],[2,1.61,49.52]],"ltp":1.66,"tv":1674.28,"id":8174333}]}]}
{"op":"mcm","clk":"1001375241","pt":1580634634194,"mc":[{"id":"1.168224329","rc":[{"trd":[[1.64,136.25]],"batb":[[0,1.63,67.65],[1,1.61,49.52],[2,1.59,42.72]],"ltp":1.64,"tv":1688.1,"id":8174333}],"tv":3772.27}]}
{"op":"mcm","clk":"1001375272","pt":1580634634928,"mc":[{"id":"1.168224329","rc":[{"trd":[[1.65,645.99]],"ltp":1.65,"tv":1701.84,"id":8174333}],"tv":3786.0}]}
{"op":"mcm","clk":"1001375320","pt":1580634636304,"mc":[{"id":"1.168224329","rc":[{"batb":[[0,1.64,8.23],[1,1.63,66.99],[2,1.61,49.52]],"ltp":1.65,"tv":1701.84,"id":8174333}]}]}
{"op":"mcm","clk":"1001375516","pt":1580634640329,"mc":[{"id":"1.168224329","rc":[{"batb":[[0,1.64,16.73]],"batl":[[0,1.68,7.35]],"ltp":1.65,"tv":1701.84,"id":8174333}]}]}
{"op":"mcm","clk":"1001375610","pt":1580634642341,"mc":[{"id":"1.168224329","rc":[{"batb":[[0,1.64,24.3],[2,1.62,40.66]],"ltp":1.65,"tv":1701.84,"id":8174333}]}]}
{"op":"mcm","clk":"1001375652","pt":1580634643423,"mc":[{"id":"1.168224329","rc":[{"batb":[[0,1.65,7.57],[1,1.64,24.3],[2,1.63,66.99]],"ltp":1.65,"tv":1701.84,"id":8174333}]}]}
{"op":"mcm","clk":"1001375739","pt":1580634645333,"mc":[{"id":"1.168224329","rc":[{"batb":[[0,1.64,24.3],[1,1.63,66.99],[2,1.62,40.66]],"batl":[[1,1.72,2.27],[2,1.73,2.27]],"ltp":1.65,"tv":1701.84,"id":8174333}]}]}
{"op":"mcm","clk":"1001375914","pt":1580634648967,"mc":[{"id":"1.168224329","rc":[{"batl":[[0,1.71,7.35],[1,1.72,197.93]],"ltp":1.65,"tv":1701.84,"id":8174333}]}]}
{"op":"mcm","clk":"1001375967","pt":1580634650052,"mc":[{"id":"1.168224329","rc":[{"batb":[[2,1.61,49.52]],"batl":[[1,1.72,2.27]],"ltp":1.65,"tv":1701.84,"id":8174333}]}]}
{"op":"mcm","clk":"1001376022","pt":1580634651139,"mc":[{"id":"1.168224329","rc":[{"trd":[[1.64,183.69]],"batb":[[0,1.63,67.57],[1,1.62,40.66]],"ltp":1.64,"tv":1749.28,"id":8174333}],"tv":3833.45}]}
{"op":"mcm","clk":"1001376093","pt":1580634652378,"mc":[{"id":"1.168224329","rc":[{"trd":[[1.65,671.91]],"batb":[[1,1.61,8.2],[2,1.59,42.72]],"batl":[[0,1.65,1.52],[1,1.71,7.35],[2,1.72,2.27]],"ltp":1.65,"tv":1775.2,"id":8174333}],"tv":3859.36}]}
{"op":"mcm","clk":"1001376146","pt":1580634653361,"mc":[{"id":"1.168224329","rc":[{"batl":[[0,1.65,2.17]],"ltp":1.65,"tv":1775.2,"id":8174333}]}]}
{"op":"mcm","clk":"1001376221","pt":1580634654965,"mc":[{"id":"1.168224329","rc":[{"batb":[[0,1.64,8.15],[1,1.63,66.99],[2,1.61,8.2]],"ltp":1.65,"tv":1775.2,"id":8174333}]}]}
{"op":"mcm","clk":"1001376314","pt":1580634656870,"mc":[{"id":"1.168224329","rc":[{"batb":[[0,1.63,66.99],[1,1.61,8.2],[2,1.59,42.72]],"ltp":1.65,"tv":1775.2,"id":8174333}]}]}
{"op":"mcm","clk":"1001376498","pt":1580634660587,"mc":[{"id":"1.168224329","rc":[{"batl":[[0,1.65,9.75]],"ltp":1.65,"tv":1775.2,"id":8174333}]}]}
{"op":"mcm","clk":"1001376658","pt":1580634663368,"mc":[{"id":"1.168224329","rc":[{"batb":[[1,1.61,49.52]],"batl":[[0,1.71,7.35],[1,1.72,2.27],[2,1.73,2.27]],"ltp":1.65,"tv":1775.2,"id":8174333}]}]}
{"op":"mcm","clk":"1001376716","pt":1580634664656,"mc":[{"id":"1.168224329","rc":[{"batb":[[1,1.62,7.57],[2,1.61,49.52]],"ltp":1.65,"tv":1775.2,"id":8174333}]}]}
{"op":"mcm","clk":"1001376876","pt":1580634668159,"mc":[{"id":"1.168224329","rc":[{"batb":[[0,2.42,1.04],[1,2.38,100.99],[2,2.36,18.53]],"ltp":2.5,"tv":2084.16,"id":6498878},{"batb":[[0,1.64,1.54],[1,1.63,66.99],[2,1.62,7.57]],"batl":[[0,1.68,7.35]],"ltp":1.65,"tv":1775.2,"id":8174333}]}]}
{"op":"mcm","clk":"1001379806","pt":1580634712215,"mc":[{"id":"1.168224329","rc":[{"batb":[[1,2.4,5.36],[2,2.38,100.99]],"ltp":2.5,"tv":2084.16,"id":6498878},{"trd":[[1.63,16.92],[1.64,186.77]],"batb":[[0,1.62,91.21],[1,1.61,49.52],[2,1.59,42.72]],"ltp":1.63,"tv":1795.2,"id":8174333}],"tv":3879.36}]}
{"op":"mcm","clk":"1001380302","pt":1580634722430,"mc":[{"id":"1.168224329","rc":[{"batb":[[0,1.63,7.57],[1,1.62,91.21],[2,1.61,49.52]],"ltp":1.63,"tv":1795.2,"id":8174333}]}]}
{"op":"mcm","clk":"1001380408","pt":1580634724326,"mc":[{"id":"1.168224329","rc":[{"batb":[[0,1.62,91.21],[1,1.61,49.52],[2,1.59,42.72]],"ltp":1.63,"tv":1795.2,"id":8174333}]}]}
{"op":"mcm","clk":"1001380536","pt":1580634727152,"mc":[{"id":"1.168224329","rc":[{"batl":[[0,1.67,7.35]],"ltp":1.63,"tv":1795.2,"id":8174333}]}]}
{"op":"mcm","clk":"1001381050","pt":1580634737236,"mc":[{"id":"1.168224329","rc":[{"trd":[[1.62,169.13]],"batb":[[0,1.62,1.52]],"ltp":1.62,"tv":1959.44,"id":8174333}],"tv":4043.6}]}
{"op":"mcm","clk":"1001381096","pt":1580634738364,"mc":[{"id":"1.168224329","rc":[{"batb":[[0,2.5,71.13],[1,2.42,1.04],[2,2.36,18.53]],"ltp":2.5,"tv":2084.16,"id":6498878},{"batb":[[0,1.61,49.52],[1,1.6,53.47]],"ltp":1.62,"tv":1959.44,"id":8174333}]}]}
{"op":"mcm","clk":"1001381125","pt":1580634739340,"mc":[{"id":"1.168224329","rc":[{"batb":[[1,2.46,17.27],[2,2.42,1.04]],"ltp":2.5,"tv":2084.16,"id":6498878},{"batb":[[0,1.61,8.2],[2,1.57,44.22]],"ltp":1.62,"tv":1959.44,"id":8174333}]}]}
{"op":"mcm","clk":"1001381163","pt":1580634740471,"mc":[{"id":"1.168224329","rc":[{"batl":[[0,1.72,2.27],[1,1.73,2.27],[2,1.76,144.51]],"ltp":1.62,"tv":1959.44,"id":8174333}]}]}
{"op":"mcm","clk":"1001381246","pt":1580634741864,"mc":[{"id":"1.168224329","rc":[{"batl":[[0,1.64,9.81],[1,1.72,2.27],[2,1.73,2.27]],"ltp":1.62,"tv":1959.44,"id":8174333}]}]}
{"op":"mcm","clk":"1001381286","pt":1580634742580,"mc":[{"id":"1.168224329","rc":[{"batb":[[0,1.61,15.77]],"ltp":1.62,"tv":1959.44,"id":8174333}]}]}
{"op":"mcm","clk":"1001381466","pt":1580634745852,"mc":[{"id":"1.168224329","rc":[{"trd":[[1.63,20.92]],"batl":[[0,1.63,7.81]],"ltp":1.63,"tv":1963.44,"id":8174333}],"tv":4047.6}]}
{"op":"mcm","clk":"1001381598","pt":1580634748376,"mc":[{"id":"1.168224329","rc":[{"batl":[[0,1.64,7.81]],"ltp":1.63,"tv":1963.44,"id":8174333}]}]}
{"op":"mcm","clk":"1001381694","pt":1580634750394,"mc":[{"id":"1.168224329","rc":[{"batb":[[0,1.62,7.57],[1,1.61,15.77],[2,1.6,53.47]],"ltp":1.63,"tv":1963.44,"id":8174333}]}]}
{"op":"mcm","clk":"1001382079","pt":1580634759311,"mc":[{"id":"1.168224329","rc":[{"trd":[[1.61,60.08]],"batb":[[0,1.6,54.4],[1,1.58,43.45],[2,1.57,44.22]],"ltp":1.61,"tv":1993.12,"id":8174333}],"tv":4077.28}]}
{"op":"mcm","clk":"1001382134","pt":1580634760388,"mc":[{"id":"1.168224329","rc":[{"batb":[[1,1.57,44.22],[2,1.56,45.01]],"batl":[[0,1.62,6.6],[1,1.64,7.81],[2,1.72,2.27]],"ltp":1.61,"tv":1993.12,"id":8174333}]}]}
{"op":"mcm","clk":"1001382138","pt":1580634760487,"mc":[{"id":"1.168224329","rc":[{"batb":[[1,1.56,45.01],[2,1.52,72.81]],"ltp":1.61,"tv":1993.12,"id":8174333}]}]}
{"op":"mcm","clk":"1001382210","pt":1580634762186,"mc":[{"id":"1.168224329","rc":[{"batb":[[0,1.6,53.47]],"ltp":1.61,"tv":1993.12,"id":8174333}]}]}
{"op":"mcm","clk":"1001382536","pt":1580634770311,"mc":[{"id":"1.168224329","rc":[{"batl":[[0,1.64,7.81],[1,1.72,2.27],[2,1.73,2.27]],"ltp":1.61,"tv":1993.12,"id":8174333}]}]}
{"op":"mcm","clk":"1001382587","pt":1580634771398,"mc":[{"id":"1.168224329","rc":[{"batb":[[1,1.57,44.22],[2,1.56,45.01]],"batl":[[0,1.63,6.6],[1,1.64,7.81],[2,1.72,2.27]],"ltp":1.61,"tv":1993.12,"id":8174333}]}]}
{"op":"mcm","clk":"1001382651","pt":1580634772997,"mc":[{"id":"1.168224329","rc":[{"batl":[[1,1.66,7.81]],"ltp":1.61,"tv":1993.12,"id":8174333}]}]}
{"op":"mcm","clk":"1001382712","pt":1580634774490,"mc":[{"id":"1.168224329","rc":[{"batb":[[1,1.59,7.57],[2,1.57,44.22]],"ltp":1.61,"tv":1993.12,"id":8174333}]}]}
{"op":"mcm","clk":"1001385099","pt":1580634820266,"mc":[{"id":"1.168224329","rc":[{"trd":[[1.63,34.12]],"batl":[[0,1.66,7.81],[1,1.72,2.27],[2,1.73,2.27]],"ltp":1.63,"tv":2006.32,"id":8174333}],"tv":4090.49}]}
{"op":"mcm","clk":"1001385164","pt":1580634821251,"mc":[{"id":"1.168224329","rc":[{"trd":[[1.6,104.96]],"batb":[[0,1.59,8.56],[1,1.57,44.22],[2,1.56,45.01]],"ltp":1.6,"tv":2111.28,"id":8174333}],"tv":4195.44}]}
{"op":"mcm","clk":"1001385218","pt":1580634822181,"mc":[{"id":"1.168224329","rc":[{"batb":[[0,2.48,65.87]],"ltp":2.5,"tv":2084.16,"id":6498878},{"batb":[[0,1.6,83.61],[1,1.59,7.57],[2,1.57,44.22]],"ltp":1.6,"tv":2111.28,"id":8174333}]}]}
{"op":"mcm","clk":"1001385235","pt":1580634822487,"mc":[{"id":"1.168224329","rc":[{"batb":[[1,2.44,17.5]],"ltp":2.5,"tv":2084.16,"id":6498878},{"batb":[[2,1.58,43.45]],"ltp":1.6,"tv":2111.28,"id":8174333}]}]}
{"op":"mcm","clk":"1001385338","pt":1580634824393,"mc":[{"id":"1.168224329","rc":[{"batb":[[0,1.6,91.18]],"ltp":1.6,"tv":2111.28,"id":8174333}]}]}
{"op":"mcm","clk":"1001385549","pt":1580634828878,"mc":[{"id":"1.168224329","rc":[{"batb":[[0,1.6,83.61],[1,1.58,43.45],[2,1.57,44.22]],"batl":[[0,1.72,2.27],[1,1.73,2.27],[2,1.76,144.51]],"ltp":1.6,"tv":2111.28,"id":8174333}]}]}
{"op":"mcm","clk":"1001385607","pt":1580634830266,"mc":[{"id":"1.168224329","rc":[{"batb":[[0,1.61,7.57],[1,1.6,83.61],[2,1.58,43.45]],"batl":[[0,1.64,7.78],[1,1.72,2.27],[2,1.73,2.27]],"ltp":1.6,"tv":2111.28,"id":8174333}]}]}
{"op":"mcm","clk":"1001385724","pt":1580634832494,"mc":[{"id":"1.168224329","rc":[{"batb":[[0,1.61,15.14]],"ltp":1.6,"tv":2111.28,"id":8174333}]}]}
{"op":"mcm","clk":"1001385771","pt":1580634833579,"mc":[{"id":"1.168224329","rc":[{"batb":[[2,1.59,7.57]],"ltp":1.6,"tv":2111.28,"id":8174333}]}]}
{"op":"mcm","clk":"1001386502","pt":1580634846280,"mc":[{"id":"1.168224329","rc":[{"trd":[[1.6,269.38]],"batb":[[0,1.6,1.39],[1,1.59,7.57],[2,1.58,43.45]],"ltp":1.6,"tv":2275.71,"id":8174333}],"tv":4359.87}]}
{"op":"mcm","clk":"1001386564","pt":1580634847414,"mc":[{"id":"1.168224329","rc":[{"batb":[[0,2.48,82.9]],"ltp":2.5,"tv":2084.16,"id":6498878},{"batb":[[2,1.52,121.28]],"ltp":1.6,"tv":2275.71,"id":8174333}]}]}
{"op":"mcm","clk":"1001386631","pt":1580634848400,"mc":[{"id":"1.168224329","rc":[{"batb":[[0,2.58,50.64],[1,2.42,1.04],[2,2.3,19.39]],"ltp":2.5,"tv":2084.16,"id":6498878},{"batb":[[0,1.59,7.57],[1,1.54,172.69]],"ltp":1.6,"tv":2275.71,"id":8174333}]}]}
{"op":"mcm","clk":"1001386707","pt":1580634849384,"mc":[{"id":"1.168224329","rc":[{"batb":[[1,2.56,16.16],[2,2.42,1.04]],"ltp":2.5,"tv":2084.16,"id":6498878},{"batb":[[2,1.53,47.56]],"ltp":1.6,"tv":2275.71,"id":8174333}]}]}
{"op":"mcm","clk":"1001386744","pt":1580634849999,"mc":[{"id":"1.168224329","rc":[{"batl":[[0,1.63,7.78]],"ltp":1.6,"tv":2275.71,"id":8174333}]}]}
{"op":"mcm","clk":"1001386821","pt":1580634851603,"mc":[{"id":"1.168224329","rc":[{"batb":[[0,1.54,172.69],[1,1.53,47.56],[2,1.52,121.28]],"ltp":1.6,"tv":2275.71,"id":8174333}]}]}
{"op":"mcm","clk":"1001387620","pt":1580634865296,"mc":[{"id":"1.168224329","rc":[{"trd":[[1.6,283.24]],"batb":[[0,1.54,173.34]],"ltp":1.6,"tv":2289.56,"id":8174333}],"tv":4373.73}]}
{"op":"mcm","clk":"1001387683","pt":1580634866227,"mc":[{"id":"1.168224329","rc":[{"batl":[[0,2.72,137.7]],"ltp":2.5,"tv":2084.16,"id":6498878},{"batl":[[0,1.61,6.88],[1,1.63,7.78],[2,1.72,2.27]],"ltp":1.6,"tv":2289.56,"id":8174333}]}]}
{"op":"mcm","clk":"1001387756","pt":1580634867408,"mc":[{"id":"1.168224329","rc":[{"batb":[[1,2.52,16.59]],"ltp":2.5,"tv":2084.16,"id":6498878},{"batb":[[0,1.55,46.48],[1,1.54,172.69],[2,1.53,47.56]],"ltp":1.6,"tv":2289.56,"id":8174333}]}]}
{"op":"mcm","clk":"1001387772","pt":1580634867717,"mc":[{"id":"1.168224329","rc":[{"batb":[[0,1.59,8.22],[1,1.55,45.83],[2,1.54,172.69]],"ltp":1.6,"tv":2289.56,"id":8174333}]}]}
{"op":"mcm","clk":"1001388209","pt":1580634874813,"mc":[{"id":"1.168224329","rc":[{"batl":[[0,2.72,3.79]],"ltp":2.5,"tv":2084.16,"id":6498878},{"batb":[[0,1.59,7.57]],"ltp":1.6,"tv":2289.56,"id":8174333}]}]}
{"op":"mcm","clk":"1001388305","pt":1580634876405,"mc":[{"id":"1.168224329","rc":[{"batb":[[1,2.56,16.16],[2,2.52,16.59]],"ltp":2.5,"tv":2084.16,"id":6498878},{"batb":[[0,1.59,15.14],[1,1.54,219.37],[2,1.53,47.56]],"ltp":1.6,"tv":2289.56,"id":8174333}]}]}
{"op":"mcm","clk":"1001388318","pt":1580634876609,"mc":[{"id":"1.168224329","rc":[{"batb":[[1,1.58,7.57],[2,1.54,219.37]],"ltp":1.6,"tv":2289.56,"id":8174333}]}]}
{"op":"mcm","clk":"1001388366","pt":1580634877434,"mc":[{"id":"1.168224329","rc":[{"batb":[[1,2.52,16.59],[2,2.42,1.04]],"ltp":2.5,"tv":2084.16,"id":6498878},{"batb":[[2,1.55,45.83]],"ltp":1.6,"tv":2289.56,"id":8174333}]}]}
{"op":"mcm","clk":"1001388642","pt":1580634882328,"mc":[{"id":"1.168224329","rc":[{"batb":[[0,1.58,7.57],[1,1.55,45.83],[2,1.54,219.37]],"ltp":1.6,"tv":2289.56,"id":8174333}]}]}
{"op":"mcm","clk":"1001388702","pt":1580634883353,"mc":[{"id":"1.168224329","rc":[{"trd":[[1.58,13.86]],"batb":[[0,1.55,46.48],[1,1.54,219.37],[2,1.53,47.56]],"ltp":1.58,"tv":2303.42,"id":8174333}],"tv":4387.59}]}
{"op":"mcm","clk":"1001388770","pt":1580634884238,"mc":[{"id":"1.168224329","rc":[{"batb":[[1,2.56,16.16],[2,2.52,16.59]],"ltp":2.5,"tv":2084.16,"id":6498878},{"trd":[[1.59,13.76],[1.61,61.38]],"batb":[[0,1.54,173.34],[1,1.53,47.56],[2,1.52,121.28]],"batl":[[0,1.61,6.23]],"ltp":1.61,"tv":2318.49,"id":8174333}],"tv":4402.65}]}
{"op":"mcm","clk":"1001388814","pt":1580634884959,"mc":[{"id":"1.168224329","rc":[{"batb":[[0,1.59,359.58],[1,1.54,173.34],[2,1.53,47.56]],"ltp":1.61,"tv":2318.49,"id":8174333}]}]}
{"op":"mcm","clk":"1001388854","pt":1580634885536,"mc":[{"id":"1.168224329","rc":[{"batb":[[1,2.52,16.59],[2,2.42,1.04]],"ltp":2.5,"tv":2084.16,"id":6498878},{"batb":[[1,1.55,46.48],[2,1.54,172.69]],"ltp":1.61,"tv":2318.49,"id":8174333}]}]}
{"op":"mcm","clk":"1001388946","pt":1580634887035,"mc":[{"id":"1.168224329","rc":[{"trd":[[1.61,73.21]],"batb":[[0,1.6,15.14],[1,1.59,359.58],[2,1.55,46.48]],"batl":[[0,1.63,8.1],[1,1.72,2.27],[2,1.73,2.27]],"ltp":1.61,"tv":2330.32,"id":8174333}],"tv":4414.48}]}
{"op":"mcm","clk":"1001389070","pt":1580634889358,"mc":[{"id":"1.168224329","rc":[{"batb":[[1,1.55,46.48],[2,1.54,172.69]],"ltp":1.61,"tv":2330.32,"id":8174333}]}]}
{"op":"mcm","clk":"1001389137","pt":1580634890850,"mc":[{"id":"1.168224329","rc":[{"batb":[[1,2.56,16.16],[2,2.52,16.59]],"ltp":2.5,"tv":2084.16,"id":6498878},{"batb":[[0,1.54,220.02],[1,1.53,47.56],[2,1.52,121.28]],"ltp":1.61,"tv":2330.32,"id":8174333}]}]}
{"op":"mcm","clk":"1001389178","pt":1580634891680,"mc":[{"id":"1.168224329","rc":[{"batb":[[0,1.58,15.79],[1,1.54,172.69],[2,1.53,47.56]],"ltp":1.61,"tv":2330.32,"id":8174333}]}]}
{"op":"mcm","clk":"1001389252","pt":1580634892966,"mc":[{"id":"1.168224329","rc":[{"batb":[[0,1.59,7.57],[1,1.58,15.79],[2,1.54,219.37]],"ltp":1.61,"tv":2330.32,"id":8174333}]}]}
{"op":"mcm","clk":"1001389284","pt":1580634893434,"mc":[{"id":"1.168224329","rc":[{"batb":[[1,2.52,16.59],[2,2.42,1.04]],"ltp":2.5,"tv":2084.16,"id":6498878},{"batb":[[2,1.55,45.83]],"ltp":1.61,"tv":2330.32,"id":8174333}]}]}
{"op":"mcm","clk":"1001389383","pt":1580634895239,"mc":[{"id":"1.168224329","rc":[{"trd":[[1.61,73.85]],"batb":[[0,1.61,11.69],[1,1.59,7.57],[2,1.58,15.79]],"batl":[[0,1.63,7.78]],"ltp":1.61,"tv":2330.95,"id":8174333}],"tv":4415.11}]}
{"op":"mcm","clk":"1001389667","pt":1580634900381,"mc":[{"id":"1.168224329","rc":[{"trd":[[1.61,95.65]],"batb":[[0,1.55,46.62],[1,1.54,219.37],[2,1.53,47.56]],"batl":[[0,1.72,2.27],[1,1.73,2.27],[2,1.76,144.51]],"ltp":1.61,"tv":2352.75,"id":8174333}],"tv":4436.92}]}
{"op":"mcm","clk":"1001389727","pt":1580634901160,"mc":[{"id":"1.168224329","rc":[{"batl":[[0,2.72,137.7]],"ltp":2.5,"tv":2084.16,"id":6498878},{"batb":[[0,1.54,220.17],[1,1.53,47.56],[2,1.52,121.28]],"batl":[[0,1.63,7.84],[1,1.72,2.27],[2,1.73,2.27]],"ltp":1.61,"tv":2352.75,"id":8174333}]}]}
{"op":"mcm","clk":"1001389783","pt":1580634902140,"mc":[{"id":"1.168224329","rc":[{"batl":[[0,2.72,3.79]],"ltp":2.5,"tv":2084.16,"id":6498878},{"batb":[[0,1.59,23.51],[1,1.55,45.83],[2,1.54,219.37]],"ltp":1.61,"tv":2352.75,"id":8174333}]}]}
{"op":"mcm","clk":"1001389988","pt":1580634905387,"mc":[{"id":"1.168224329","rc":[{"trd":[[1.59,57.77],[1.61,97.23]],"batb":[[0,1.55,46.54],[1,1.54,219.37],[2,1.53,47.56]],"ltp":1.59,"tv":2398.34,"id":8174333}],"tv":4482.5}]}
{"op":"mcm","clk":"1001390023","pt":1580634906059,"mc":[{"id":"1.168224329","rc":[{"batl":[[0,1.6,21.87],[1,1.63,7.84],[2,1.72,2.27]],"ltp":1.59,"tv":2398.34,"id":8174333}]}]}
{"op":"mcm","clk":"1001390076","pt":1580634907286,"mc":[{"id":"1.168224329","rc":[{"trd":[[1.6,326.98]],"batb":[[0,1.6,420.81],[1,1.55,46.54],[2,1.54,219.37]],"batl":[[0,1.63,7.84],[1,1.72,2.27],[2,1.73,2.27]],"ltp":1.6,"tv":2442.08,"id":8174333}],"tv":4526.24}]}
{"op":"mcm","clk":"1001390120","pt":1580634908470,"mc":[{"id":"1.168224329","rc":[{"batb":[[1,2.5,16.8]],"ltp":2.5,"tv":2084.16,"id":6498878}]}]}
{"op":"mcm","clk":"1001390187","pt":1580634909502,"mc":[{"id":"1.168224329","rc":[{"batb":[[1,1.56,45.72],[2,1.55,45.83]],"ltp":1.6,"tv":2442.08,"id":8174333}]}]}
{"op":"mcm","clk":"1001390331","pt":1580634911367,"mc":[{"id":"1.168224329","rc":[{"batb":[[0,1.6,17.53],[1,1.59,15.86],[2,1.56,45.01]],"ltp":1.6,"tv":2442.08,"id":8174333}]}]}
{"op":"mcm","clk":"1001390361","pt":1580634911777,"mc":[{"id":"1.168224329","rc":[{"batb":[[0,2.52,89.74]],"ltp":2.5,"tv":2084.16,"id":6498878},{"batb":[[0,1.59,15.86],[1,1.57,83.8]],"ltp":1.6,"tv":2442.08,"id":8174333}]}]}
{"op":"mcm","clk":"1001390978","pt":1580634922385,"mc":[{"id":"1.168224329","rc":[{"trd":[[1.59,103.38]],"batb":[[0,1.57,84.42],[1,1.56,45.01],[2,1.55,45.83]],"ltp":1.59,"tv":2487.68,"id":8174333}],"tv":4571.85}]}
{"op":"mcm","clk":"1001391092","pt":1580634924412,"mc":[{"id":"1.168224329","rc":[{"batb":[[1,1.55,45.83],[2,1.54,46.68]],"batl":[[0,1.61,15.14],[1,1.63,7.84],[2,1.72,2.27]],"ltp":1.59,"tv":2487.68,"id":8174333}]}]}
{"op":"mcm","clk":"1001391146","pt":1580634925496,"mc":[{"id":"1.168224329","rc":[{"batb":[[0,2.54,16.37],[1,2.52,89.74],[2,2.5,16.8]],"ltp":2.5,"tv":2084.16,"id":6498878}]}]}
{"op":"mcm","clk":"1001391233","pt":1580634926895,"mc":[{"id":"1.168224329","rc":[{"batb":[[0,1.58,7.57],[1,1.57,83.8]],"ltp":1.59,"tv":2487.68,"id":8174333}]}]}
{"op":"mcm","clk":"1001391509","pt":1580634932401,"mc":[{"id":"1.168224329","rc":[{"batb":[[0,2.52,89.74],[1,2.5,16.8],[2,2.42,1.04]],"ltp":2.5,"tv":2084.16,"id":6498878},{"batb":[[2,1.55,45.83]],"batl":[[0,1.63,15.41],[1,1.72,2.27],[2,1.73,2.27]],"ltp":1.59,"tv":2487.68,"id":8174333}]}]}
{"op":"mcm","clk":"1001391989","pt":1580634941412,"mc":[{"id":"1.168224329","rc":[{"batb":[[0,2.54,16.37],[1,2.52,89.74],[2,2.5,16.8]],"ltp":2.5,"tv":2084.16,"id":6498878},{"trd":[[1.58,27.73]],"batb":[[0,1.57,84.44],[1,1.54,46.68],[2,1.53,47.56]],"batl":[[0,1.6,7.57],[1,1.63,15.41],[2,1.72,2.27]],"ltp":1.58,"tv":2501.56,"id":8174333}],"tv":4585.72}]}
{"op":"mcm","clk":"1001392104","pt":1580634944337,"mc":[{"id":"1.168224329","rc":[{"batb":[[0,1.57,83.8],[1,1.54,47.32]],"ltp":1.58,"tv":2501.56,"id":8174333}]}]}
{"op":"mcm","clk":"1001392161","pt":1580634945317,"mc":[{"id":"1.168224329","rc":[{"batb":[[0,1.59,45.6],[1,1.57,83.8],[2,1.56,7.57]],"ltp":1.58,"tv":2501.56,"id":8174333}]}]}
{"op":"mcm","clk":"1001392220","pt":1580634946398,"mc":[{"id":"1.168224329","rc":[{"batb":[[0,2.52,106.33],[1,2.5,16.8],[2,2.42,1.04]],"ltp":2.5,"tv":2084.16,"id":6498878}]}]}
{"op":"mcm","clk":"1001392346","pt":1580634948402,"mc":[{"id":"1.168224329","rc":[{"batb":[[0,2.52,89.74],[1,2.48,17.03]],"ltp":2.5,"tv":2084.16,"id":6498878},{"batb":[[2,1.56,52.58]],"batl":[[0,1.63,15.41],[1,1.72,2.27],[2,1.73,2.27]],"ltp":1.58,"tv":2501.56,"id":8174333}]}]}
{"op":"mcm","clk":"1001392453","pt":1580634950412,"mc":[{"id":"1.168224329","rc":[{"batb":[[0,2.52,106.33]],"ltp":2.5,"tv":2084.16,"id":6498878},{"batl":[[0,1.62,7.57],[1,1.63,15.41],[2,1.72,2.27]],"ltp":1.58,"tv":2501.56,"id":8174333}]}]}
{"op":"mcm","clk":"1001392818","pt":1580634958351,"mc":[{"id":"1.168224329","rc":[{"trd":[[1.59,192.62]],"batb":[[0,1.57,84.78],[1,1.56,52.58],[2,1.55,8.21]],"batl":[[1,1.65,7.57]],"ltp":1.59,"tv":2590.8,"id":8174333}],"tv":4674.96}]}
{"op":"mcm","clk":"1001392861","pt":1580634959027,"mc":[{"id":"1.168224329","rc":[{"batb":[[0,2.52,89.74]],"ltp":2.5,"tv":2084.16,"id":6498878},{"batb":[[0,1.57,83.8]],"ltp":1.59,"tv":2590.8,"id":8174333}]}]}
{"op":"mcm","clk":"1001392896","pt":1580634959850,"mc":[{"id":"1.168224329","rc":[{"batb":[[1,2.5,16.8],[2,2.48,17.03]],"ltp":2.5,"tv":2084.16,"id":6498878},{"batb":[[1,1.56,7.57],[2,1.55,54.04]],"ltp":1.59,"tv":2590.8,"id":8174333}]}]}
{"op":"mcm","clk":"1001392944","pt":1580634960942,"mc":[{"id":"1.168224329","rc":[{"batb":[[0,1.58,7.57],[1,1.57,83.8],[2,1.56,7.57]],"ltp":1.59,"tv":2590.8,"id":8174333}]}]}
{"op":"mcm","clk":"1001393125","pt":1580634964642,"mc":[{"id":"1.168224329","rc":[{"batl":[[0,1.6,7.57],[1,1.62,7.57],[2,1.65,7.57]],"ltp":1.59,"tv":2590.8,"id":8174333}]}]}
{"op":"mcm","clk":"1001393252","pt":1580634967563,"mc":[{"id":"1.168224329","rc":[{"batl":[[0,1.62,7.57],[1,1.65,7.57],[2,1.72,2.27]],"ltp":1.59,"tv":2590.8,"id":8174333}]}]}
{"op":"mcm","clk":"1001393365","pt":1580634969838,"mc":[{"id":"1.168224329","rc":[{"batl":[[1,1.64,7.57],[2,1.65,7.57]],"ltp":1.59,"tv":2590.8,"id":8174333}]}]}
{"op":"mcm","clk":"1001393464","pt":1580634971753,"mc":[{"id":"1.168224329","rc":[{"batl":[[0,1.62,15.14]],"ltp":1.59,"tv":2590.8,"id":8174333}]}]}
{"op":"mcm","clk":"1001393491","pt":1580634972469,"mc":[{"id":"1.168224329","rc":[{"batb":[[0,2.52,106.33]],"ltp":2.5,"tv":2084.16,"id":6498878}]}]}
{"op":"mcm","clk":"1001393914","pt":1580634980682,"mc":[{"id":"1.168224329","rc":[{"trd":[[1.62,199.42]],"batl":[[0,1.64,7.57],[1,1.65,7.57],[2,1.72,2.27]],"ltp":1.62,"tv":2621.1,"id":8174333}],"tv":4705.26}]}
{"op":"mcm","clk":"1001393966","pt":1580634981562,"mc":[{"id":"1.168224329","rc":[{"batb":[[0,2.52,89.74]],"ltp":2.5,"tv":2084.16,"id":6498878}]}]}
{"op":"mcm","clk":"1001394045","pt":1580634983263,"mc":[{"id":"1.168224329","rc":[{"batl":[[0,1.62,7.57],[1,1.64,7.57],[2,1.65,7.57]],"ltp":1.62,"tv":2621.1,"id":8174333}]}]}
{"op":"mcm","clk":"1001394081","pt":1580634984081,"mc":[{"id":"1.168224329","rc":[{"trd":[[1.62,214.56]],"batb":[[0,1.62,65.7],[1,1.58,7.57],[2,1.57,83.8]],"batl":[[0,1.64,7.57],[1,1.65,7.57],[2,1.72,2.27]],"ltp":1.62,"tv":2636.24,"id":8174333}],"tv":4720.4}]}
{"op":"mcm","clk":"1001394094","pt":1580634984494,"mc":[{"id":"1.168224329","rc":[{"batb":[[1,2.44,17.5],[2,2.42,1.04]],"ltp":2.5,"tv":2084.16,"id":6498878},{"batb":[[1,1.58,51.03]],"ltp":1.62,"tv":2636.24,"id":8174333}]}]}
{"op":"mcm","clk":"1001394319","pt":1580634988772,"mc":[{"id":"1.168224329","rc":[{"batb":[[0,1.58,51.03],[1,1.57,83.8],[2,1.56,7.57]],"ltp":1.62,"tv":2636.24,"id":8174333}]}]}
{"op":"mcm","clk":"1001394352","pt":1580634989489,"mc":[{"id":"1.168224329","rc":[{"batb":[[1,2.5,16.8],[2,2.44,17.5]],"ltp":2.5,"tv":2084.16,"id":6498878},{"batb":[[0,1.58,7.57]],"ltp":1.62,"tv":2636.24,"id":8174333}]}]}
{"op":"mcm","clk":"1001394590","pt":1580634993204,"mc":[{"id":"1.168224329","rc":[{"trd":[[1.62,229.64]],"batl":[[0,1.65,7.6],[1,1.72,2.27],[2,1.73,2.27]],"ltp":1.62,"tv":2651.32,"id":8174333}],"tv":4735.48}]}
{"op":"mcm","clk":"1001394614","pt":1580634993874,"mc":[{"id":"1.168224329","rc":[{"trd":[[1.62,229.7]],"batb":[[0,1.62,443.33],[1,1.58,7.57],[2,1.57,83.8]],"batl":[[0,1.65,7.57]],"ltp":1.62,"tv":2651.38,"id":8174333}],"tv":4735.54}]}
{"op":"mcm","clk":"1001394640","pt":1580634994590,"mc":[{"id":"1.168224329","rc":[{"batb":[[1,2.44,17.5],[2,2.42,1.04]],"ltp":2.5,"tv":2084.16,"id":6498878},{"batb":[[1,1.59,7.57],[2,1.58,51.03]],"ltp":1.62,"tv":2651.38,"id":8174333}]}]}
{"op":"mcm","clk":"1001394762","pt":1580634997368,"mc":[{"id":"1.168224329","rc":[{"trd":[[1.62,761.71]],"batb":[[0,1.62,177.32],[1,1.58,43.45],[2,1.57,83.8]],"batl":[[0,1.72,2.27],[1,1.73,2.27],[2,1.76,144.51]],"ltp":1.62,"tv":3183.39,"id":8174333}],"tv":5267.55}]}
{"op":"mcm","clk":"1001394814","pt":1580634998287,"mc":[{"id":"1.168224329","rc":[{"batb":[[0,1.59,15.14]],"batl":[[0,1.65,6.62],[1,1.72,2.27],[2,1.73,2.27]],"ltp":1.62,"tv":3183.39,"id":8174333}]}]}
{"op":"mcm","clk":"1001394951","pt":1580635000208,"mc":[{"id":"1.168224329","rc":[{"batb":[[1,2.5,16.8],[2,2.44,17.5]],"ltp":2.5,"tv":2084.16,"id":6498878},{"batb":[[0,1.59,22.72],[1,1.57,83.8],[2,1.56,45.01]],"ltp":1.62,"tv":3183.39,"id":8174333}]}]}
{"op":"mcm","clk":"1001395018","pt":1580635001292,"mc":[{"id":"1.168224329","rc":[{"batb":[[1,2.48,17.03]],"ltp":2.5,"tv":2084.16,"id":6498878},{"batl":[[0,1.62,40.53],[1,1.65,6.62],[2,1.72,2.27]],"ltp":1.62,"tv":3183.39,"id":8174333}]}]}
{"op":"mcm","clk":"1001395048","pt":1580635001910,"mc":[{"id":"1.168224329","rc":[{"batb":[[0,1.6,7.57],[1,1.59,22.72],[2,1.57,83.8]],"ltp":1.62,"tv":3183.39,"id":8174333}]}]}
{"op":"mcm","clk":"1001395114","pt":1580635002995,"mc":[{"id":"1.168224329","rc":[{"batb":[[0,2.52,106.33]],"ltp":2.5,"tv":2084.16,"id":6498878},{"trd":[[1.6,342.12]],"batb":[[0,1.59,22.72],[1,1.57,83.8],[2,1.55,45.83]],"batl":[[0,1.6,23.83],[1,1.62,40.53],[2,1.65,6.62]],"ltp":1.6,"tv":3198.53,"id":8174333}],"tv":5282.7}]}
{"op":"mcm","clk":"1001395158","pt":1580635003512,"mc":[{"id":"1.168224329","rc":[{"batb":[[0,2.56,16.16],[1,2.52,106.33],[2,2.48,17.03]],"ltp":2.5,"tv":2084.16,"id":6498878},{"batb":[[2,1.54,46.68]],"ltp":1.6,"tv":3198.53,"id":8174333}]}]}
{"op":"mcm","clk":"1001395267","pt":1580635005994,"mc":[{"id":"1.168224329","rc":[{"batb":[[0,1.58,7.57]],"ltp":1.6,"tv":3198.53,"id":8174333}]}]}
{"op":"mcm","clk":"1001395331","pt":1580635007269,"mc":[{"id":"1.168224329","rc":[{"batb":[[2,1.53,47.56]],"batl":[[1,1.62,48.1]],"ltp":1.6,"tv":3198.53,"id":8174333}]}]}
{"op":"mcm","clk":"1001395338","pt":1580635007476,"mc":[{"id":"1.168224329","rc":[{"batb":[[0,2.58,15.96],[1,2.56,16.16],[2,2.52,106.33]],"ltp":2.5,"tv":2084.16,"id":6498878}]}]}
{"op":"mcm","clk":"1001395743","pt":1580635015412,"mc":[{"id":"1.168224329","rc":[{"trd":[[1.58,41.61]],"batb":[[0,1.57,84.44],[1,1.53,47.56],[2,1.52,72.81]],"batl":[[0,1.62,48.1],[1,1.65,6.62],[2,1.72,2.27]],"ltp":1.58,"tv":3212.41,"id":8174333}],"tv":5296.57}]}
{"op":"mcm","clk":"1001395793","pt":1580635016291,"mc":[{"id":"1.168224329","rc":[{"trd":[[2.72,3.79]],"batb":[[0,2.54,16.37],[1,2.52,106.33],[2,2.48,17.03]],"batl":[[0,4,153.72],[1,95,15.9],[2,990,2.2]],"ltp":2.72,"tv":2087.94,"id":6498878},{"trd":[[1.58,49.4]],"batb":[[0,1.57,83.8],[1,1.54,46.68],[2,1.53,47.56]],"batl":[[0,1.58,17.03],[1,1.59,40.53],[2,1.62,7.57]],"ltp":1.58,"tv":3220.2,"id":8174333}],"tv":5308.15}]}
{"op":"mcm","clk":"1001395803","pt":1580635016502,"mc":[{"id":"1.168224329","rc":[{"batb":[[0,2.6,15.75],[1,2.54,16.37],[2,2.52,106.33]],"ltp":2.72,"tv":2087.94,"id":6498878},{"trd":[[1.58,83.14]],"batb":[[1,1.52,121.28],[2,1.51,37.86]],"batl":[[0,1.59,40.69],[1,1.62,7.57],[2,1.65,6.62]],"ltp":1.58,"tv":3253.94,"id":8174333}],"tv":5341.89}]}
{"op":"mcm","clk":"1001396022","pt":1580635022705,"mc":[{"id":"1.168224329","rc":[{"trd":[[1.58,83.47],[1.59,207.43]],"batl":[[0,1.59,33.12]],"ltp":1.59,"tv":3269.08,"id":8174333}],"tv":5357.03}]}
{"op":"mcm","clk":"1001396118","pt":1580635024522,"mc":[{"id":"1.168224329","rc":[{"batl":[[1,1.61,7.57],[2,1.62,7.57]],"ltp":1.59,"tv":3269.08,"id":8174333}]}]}
{"op":"mcm","clk":"1001396274","pt":1580635028109,"mc":[{"id":"1.168224329","rc":[{"trd":[[1.59,222.58]],"batl":[[0,1.59,25.55]],"ltp":1.59,"tv":3284.23,"id":8174333}],"tv":5372.17}]}
{"op":"mcm","clk":"1001396314","pt":1580635028886,"mc":[{"id":"1.168224329","rc":[{"trd":[[1.59,268.01]],"batb":[[1,1.53,47.56],[2,1.52,121.28]],"batl":[[0,1.59,2.83]],"ltp":1.59,"tv":3329.66,"id":8174333}],"tv":5417.61}]}
{"op":"mcm","clk":"1001396365","pt":1580635030020,"mc":[{"id":"1.168224329","rc":[{"batb":[[0,2.54,16.37],[1,2.52,106.33],[2,2.48,17.03]],"ltp":2.72,"tv":2087.94,"id":6498878},{"trd":[[1.59,273.68]],"batb":[[0,1.59,4.74],[1,1.57,83.8],[2,1.53,47.56]],"batl":[[0,1.61,7.57],[1,1.62,7.57],[2,1.65,6.62]],"ltp":1.59,"tv":3335.33,"id":8174333}],"tv":5423.28}]}
{"op":"mcm","clk":"1001396400","pt":1580635030533,"mc":[{"id":"1.168224329","rc":[{"batb":[[0,2.52,89.74],[1,2.5,16.8]],"ltp":2.72,"tv":2087.94,"id":6498878},{"batb":[[2,1.55,45.83]],"ltp":1.59,"tv":3335.33,"id":8174333}]}]}
{"op":"mcm","clk":"1001396458","pt":1580635031723,"mc":[{"id":"1.168224329","rc":[{"batl":[[1,1.62,15.14]],"ltp":1.59,"tv":3335.33,"id":8174333}]}]}
{"op":"mcm","clk":"1001396495","pt":1580635032518,"mc":[{"id":"1.168224329","rc":[{"batb":[[0,2.54,16.37],[1,2.52,89.74],[2,2.5,16.8]],"ltp":2.72,"tv":2087.94,"id":6498878},{"batb":[[2,1.54,46.68]],"ltp":1.59,"tv":3335.33,"id":8174333}]}]}
{"op":"mcm","clk":"1001396577","pt":1580635034530,"mc":[{"id":"1.168224329","rc":[{"batb":[[0,1.57,83.8],[1,1.54,46.68],[2,1.53,47.56]],"ltp":1.59,"tv":3335.33,"id":8174333}]}]}
{"op":"mcm","clk":"1001396633","pt":1580635036022,"mc":[{"id":"1.168224329","rc":[{"batl":[[0,1.62,15.14],[1,1.65,6.62],[2,1.72,2.27]],"ltp":1.59,"tv":3335.33,"id":8174333}]}]}
{"op":"mcm","clk":"1001396656","pt":1580635036541,"mc":[{"id":"1.168224329","rc":[{"batb":[[0,2.52,89.74],[1,2.5,16.8],[2,2.48,17.03]],"ltp":2.72,"tv":2087.94,"id":6498878},{"batb":[[1,1.55,45.83],[2,1.54,46.68]],"batl":[[0,1.62,22.72]],"ltp":1.59,"tv":3335.33,"id":8174333}]}]}
{"op":"mcm","clk":"1001396686","pt":1580635037518,"mc":[{"id":"1.168224329","rc":[{"batb":[[0,2.54,16.37],[1,2.52,89.74],[2,2.5,16.8]],"ltp":2.72,"tv":2087.94,"id":6498878},{"batb":[[1,1.54,46.68],[2,1.53,47.56]],"ltp":1.59,"tv":3335.33,"id":8174333}]}]}
{"op":"mcm","clk":"1001397051","pt":1580635044843,"mc":[{"id":"1.168224329","rc":[{"batb":[[0,2.56,63.36],[1,2.54,16.37]],"ltp":2.72,"tv":2087.94,"id":6498878},{"batb":[[0,1.55,142.25]],"ltp":1.59,"tv":3335.33,"id":8174333}]}]}
{"op":"mcm","clk":"1001397110","pt":1580635046029,"mc":[{"id":"1.168224329","rc":[{"batb":[[0,2.56,79.52]],"ltp":2.72,"tv":2087.94,"id":6498878},{"batb":[[1,1.53,47.56],[2,1.52,121.28]],"batl":[[0,1.65,6.62],[1,1.72,2.27],[2,1.73,2.27]],"ltp":1.59,"tv":3335.33,"id":8174333}]}]}
{"op":"mcm","clk":"1001397137","pt":1580635046543,"mc":[{"id":"1.168224329","rc":[{"batb":[[0,2.56,63.36]],"ltp":2.72,"tv":2087.94,"id":6498878},{"batb":[[1,1.54,46.68],[2,1.53,47.56]],"ltp":1.59,"tv":3335.33,"id":8174333}]}]}
{"op":"mcm","clk":"1001397202","pt":1580635048134,"mc":[{"id":"1.168224329","rc":[{"batl":[[0,1.64,15.14],[1,1.65,6.62],[2,1.72,2.27]],"ltp":1.59,"tv":3335.33,"id":8174333}]}]}
{"op":"mcm","clk":"1001397297","pt":1580635050247,"mc":[{"id":"1.168224329","rc":[{"batl":[[1,1.72,2.27],[2,1.73,2.27]],"ltp":1.59,"tv":3335.33,"id":8174333}]}]}
{"op":"mcm","clk":"1001397358","pt":1580635051422,"mc":[{"id":"1.168224329","rc":[{"batb":[[0,1.56,7.57],[1,1.55,142.25],[2,1.54,46.68]],"ltp":1.59,"tv":3335.33,"id":8174333}]}]}
{"op":"mcm","clk":"1001397426","pt":1580635053066,"mc":[{"id":"1.168224329","rc":[{"batl":[[0,1.59,4.09],[1,1.64,15.14],[2,1.72,2.27]],"ltp":1.59,"tv":3335.33,"id":8174333}]}]}
{"op":"mcm","clk":"1001397449","pt":1580635053432,"mc":[{"id":"1.168224329","rc":[{"batb":[[2,1.53,47.56]],"ltp":1.59,"tv":3335.33,"id":8174333}]}]}
{"op":"mcm","clk":"1001397676","pt":1580635057471,"mc":[{"id":"1.168224329","rc":[{"trd":[[1.59,281.85]],"batb":[[0,1.59,3.48],[1,1.56,7.57],[2,1.55,142.25]],"batl":[[0,1.64,15.14],[1,1.72,2.27],[2,1.73,2.27]],"ltp":1.59,"tv":3343.51,"id":8174333}],"tv":5431.45}]}
{"op":"mcm","clk":"1001397774","pt":1580635059072,"mc":[{"id":"1.168224329","rc":[{"batl":[[0,1.62,15.14],[1,1.64,15.14],[2,1.72,2.27]],"ltp":1.59,"tv":3343.51,"id":8174333}]}]}
{"op":"mcm","clk":"1001397862","pt":1580635060162,"mc":[{"id":"1.168224329","rc":[{"batb":[[0,1.56,7.57],[1,1.55,142.25],[2,1.53,47.56]],"ltp":1.59,"tv":3343.51,"id":8174333}]}]}
{"op":"mcm","clk":"1001398011","pt":1580635062561,"mc":[{"id":"1.168224329","rc":[{"batb":[[0,1.56,15.14]],"ltp":1.59,"tv":3343.51,"id":8174333}]}]}
{"op":"mcm","clk":"1001398327","pt":1580635068785,"mc":[{"id":"1.168224329","rc":[{"batl":[[1,1.64,22.72]],"ltp":1.59,"tv":3343.51,"id":8174333}]}]}
{"op":"mcm","clk":"1001398423","pt":1580635070384,"mc":[{"id":"1.168224329","rc":[{"batl":[[1,1.72,2.27],[2,1.73,2.27]],"ltp":1.59,"tv":3343.51,"id":8174333}]}]}
{"op":"mcm","clk":"1001398450","pt":1580635070952,"mc":[{"id":"1.168224329","rc":[{"batl":[[0,1.62,22.72]],"ltp":1.59,"tv":3343.51,"id":8174333}]}]}
{"op":"mcm","clk":"1001398473","pt":1580635071466,"mc":[{"id":"1.168224329","rc":[{"batb":[[0,2.56,79.52]],"ltp":2.72,"tv":2087.94,"id":6498878}]}]}
{"op":"mcm","clk":"1001398843","pt":1580635079845,"mc":[{"id":"1.168224329","rc":[{"batl":[[0,1.6,22.72]],"ltp":1.59,"tv":3343.51,"id":8174333}]}]}
{"op":"mcm","clk":"1001398877","pt":1580635080519,"mc":[{"id":"1.168224329","rc":[{"batb":[[2,1.52,121.28]],"ltp":1.59,"tv":3343.51,"id":8174333}]}]}
{"op":"mcm","clk":"1001398926","pt":1580635081548,"mc":[{"id":"1.168224329","rc":[{"batb":[[0,2.6,15.75],[1,2.56,79.52],[2,2.54,16.37]],"ltp":2.72,"tv":2087.94,"id":6498878}]}]}
{"op":"mcm","clk":"1001399017","pt":1580635083150,"mc":[{"id":"1.168224329","rc":[{"batb":[[0,1.55,142.25],[1,1.54,7.57]],"ltp":1.59,"tv":3343.51,"id":8174333}]}]}
{"op":"mcm","clk":"1001399056","pt":1580635083824,"mc":[{"id":"1.168224329","rc":[{"batb":[[2,1.53,7.57]],"ltp":1.59,"tv":3343.51,"id":8174333}]}]}
{"op":"mcm","clk":"1001399258","pt":1580635088053,"mc":[{"id":"1.168224329","rc":[{"batl":[[0,1.6,30.29]],"ltp":1.59,"tv":3343.51,"id":8174333}]}]}
{"op":"mcm","clk":"1001399398","pt":1580635090677,"mc":[{"id":"1.168224329","rc":[{"batl":[[0,1.72,2.27],[1,1.73,2.27],[2,1.76,144.51]],"ltp":1.59,"tv":3343.51,"id":8174333}]}]}
{"op":"mcm","clk":"1001399462","pt":1580635091761,"mc":[{"id":"1.168224329","rc":[{"batb":[[0,2.56,63.36],[1,2.54,16.37],[2,2.5,16.8]],"ltp":2.72,"tv":2087.94,"id":6498878},{"batb":[[1,1.54,54.25]],"batl":[[0,1.61,15.14],[1,1.72,2.27],[2,1.73,2.27]],"ltp":1.59,"tv":3343.51,"id":8174333}]}]}
{"op":"mcm","clk":"1001399555","pt":1580635094177,"mc":[{"id":"1.168224329","rc":[{"batl":[[0,1.61,30.29]],"ltp":1.59,"tv":3343.51,"id":8174333}]}]}
{"op":"mcm","clk":"1001399574","pt":1580635094440,"mc":[{"id":"1.168224329","rc":[{"batb":[[0,2.58,15.96],[1,2.56,63.36],[2,2.54,16.37]],"ltp":2.72,"tv":2087.94,"id":6498878},{"batb":[[1,1.54,7.57]],"ltp":1.59,"tv":3343.51,"id":8174333}]}]}
{"op":"mcm","clk":"1001400963","pt":1580635121725,"mc":[{"id":"1.168224329","rc":[{"batl":[[0,1.6,30.29]],"ltp":1.59,"tv":3343.51,"id":8174333}]}]}
{"op":"mcm","clk":"1001401009","pt":1580635122497,"mc":[{"id":"1.168224329","rc":[{"batb":[[0,2.6,15.75],[1,2.58,15.96],[2,2.56,63.36]],"ltp":2.72,"tv":2087.94,"id":6498878}]}]}
{"op":"mcm","clk":"1001401137","pt":1580635124712,"mc":[{"id":"1.168224329","rc":[{"batl":[[0,1.62,30.29]],"ltp":1.59,"tv":3343.51,"id":8174333}]}]}
{"op":"mcm","clk":"1001401191","pt":1580635125490,"mc":[{"id":"1.168224329","rc":[{"batb":[[0,2.56,79.52],[1,2.54,16.37],[2,2.5,16.8]],"ltp":2.72,"tv":2087.94,"id":6498878},{"batb":[[2,1.53,55.13]],"ltp":1.59,"tv":3343.51,"id":8174333}]}]}
{"op":"mcm","clk":"1001402902","pt":1580635159863,"mc":[{"id":"1.168224329","rc":[{"batl":[[0,1.63,30.29]],"ltp":1.59,"tv":3343.51,"id":8174333}]}]}
{"op":"mcm","clk":"1001403052","pt":1580635163230,"mc":[{"id":"1.168224329","rc":[{"batl":[[0,1.62,30.29]],"ltp":1.59,"tv":3343.51,"id":8174333}]}]}
{"op":"mcm","clk":"1001403776","pt":1580635178042,"mc":[{"id":"1.168224329","rc":[{"batb":[[0,2.62,26.1],[1,2.56,16.16],[2,2.54,16.37]],"ltp":2.72,"tv":2087.94,"id":6498878}]}]}
{"op":"mcm","clk":"1001403818","pt":1580635178663,"mc":[{"id":"1.168224329","rc":[{"batb":[[1,2.58,15.96],[2,2.56,16.16]],"ltp":2.72,"tv":2087.94,"id":6498878},{"batb":[[2,1.53,7.57]],"ltp":1.59,"tv":3343.51,"id":8174333}]}]}
{"op":"mcm","clk":"1001404737","pt":1580635199175,"mc":[{"id":"1.168224329","rc":[{"batl":[[0,1.61,30.29]],"ltp":1.59,"tv":3343.51,"id":8174333}]}]}
{"op":"mcm","clk":"1001405048","pt":1580635206103,"mc":[{"id":"1.168224329","rc":[{"batb":[[1,1.52,121.28],[2,1.51,37.86]],"batl":[[0,1.72,2.27],[1,1.73,2.27],[2,1.76,144.51]],"ltp":1.59,"tv":3343.51,"id":8174333}]}]}
{"op":"mcm","clk":"1001405090","pt":1580635207190,"mc":[{"id":"1.168224329","rc":[{"batl":[[0,1.61,65.97],[1,1.72,2.27],[2,1.73,2.27]],"ltp":1.59,"tv":3343.51,"id":8174333}]}]}
{"op":"mcm","clk":"1001405147","pt":1580635208220,"mc":[{"id":"1.168224329","rc":[{"batb":[[1,1.54,7.57],[2,1.53,7.57]],"ltp":1.59,"tv":3343.51,"id":8174333}]}]}
{"op":"mcm","clk":"1001405217","pt":1580635209975,"mc":[{"id":"1.168224329","rc":[{"batb":[[0,1.56,47.29],[1,1.55,142.25],[2,1.54,7.57]],"batl":[[0,1.72,2.27],[1,1.73,2.27],[2,1.76,144.51]],"ltp":1.59,"tv":3343.51,"id":8174333}]}]}
{"op":"mcm","clk":"1001405244","pt":1580635210489,"mc":[{"id":"1.168224329","rc":[{"batb":[[1,2.56,16.16],[2,2.54,16.37]],"ltp":2.72,"tv":2087.94,"id":6498878}]}]}
{"op":"mcm","clk":"1001405314","pt":1580635212086,"mc":[{"id":"1.168224329","rc":[{"batl":[[0,1.61,22.72],[1,1.72,2.27],[2,1.73,2.27]],"ltp":1.59,"tv":3343.51,"id":8174333}]}]}
{"op":"mcm","clk":"1001405346","pt":1580635212611,"mc":[{"id":"1.168224329","rc":[{"batl":[[0,1.61,30.29]],"ltp":1.59,"tv":3343.51,"id":8174333}]}]}
{"op":"mcm","clk":"1001405568","pt":1580635217305,"mc":[{"id":"1.168224329","rc":[{"batl":[[1,1.64,22.72],[2,1.72,2.27]],"ltp":1.59,"tv":3343.51,"id":8174333}]}]}
{"op":"mcm","clk":"1001405682","pt":1580635220301,"mc":[{"id":"1.168224329","rc":[{"batb":[[1,2.56,73.36]],"ltp":2.72,"tv":2087.94,"id":6498878},{"batb":[[0,1.57,127.54],[1,1.56,47.29],[2,1.55,142.25]],"ltp":1.59,"tv":3343.51,"id":8174333}]}]}
{"op":"mcm","clk":"1001405990","pt":1580635226708,"mc":[{"id":"1.168224329","rc":[{"trd":[[1.57,0.03]],"batb":[[0,1.57,127.53]],"ltp":1.57,"tv":3343.54,"id":8174333}],"tv":5431.48}]}
{"op":"mcm","clk":"1001406255","pt":1580635231615,"mc":[{"id":"1.168224329","rc":[{"batb":[[0,1.57,127.54]],"ltp":1.57,"tv":3343.54,"id":8174333}]}]}
{"op":"mcm","clk":"1001407403","pt":1580635254175,"mc":[{"id":"1.168224329","rc":[{"batl":[[0,1.64,22.72],[1,1.72,2.27],[2,1.73,2.27]],"ltp":1.57,"tv":3343.54,"id":8174333}]}]}
{"op":"mcm","clk":"1001407438","pt":1580635254949,"mc":[{"id":"1.168224329","rc":[{"batl":[[0,1.6,7.57],[1,1.64,22.72],[2,1.72,2.27]],"ltp":1.57,"tv":3343.54,"id":8174333}]}]}
{"op":"mcm","clk":"1001407577","pt":1580635257673,"mc":[{"id":"1.168224329","rc":[{"batl":[[1,1.61,7.57],[2,1.64,22.72]],"ltp":1.57,"tv":3343.54,"id":8174333}]}]}
{"op":"mcm","clk":"1001407666","pt":1580635259981,"mc":[{"id":"1.168224329","rc":[{"batl":[[0,1.61,7.57],[1,1.64,22.72],[2,1.72,2.27]],"ltp":1.57,"tv":3343.54,"id":8174333}]}]}
{"op":"mcm","clk":"1001407694","pt":1580635260650,"mc":[{"id":"1.168224329","rc":[{"batl":[[0,1.61,22.72]],"ltp":1.57,"tv":3343.54,"id":8174333}]}]}
{"op":"mcm","clk":"1001407739","pt":1580635262090,"mc":[{"id":"1.168224329","rc":[{"batl":[[0,1.61,30.29]],"ltp":1.57,"tv":3343.54,"id":8174333}]}]}
{"op":"mcm","clk":"1001408936","pt":1580635290596,"mc":[{"id":"1.168224329","rc":[{"batl":[[0,1.59,7.57],[1,1.61,30.29],[2,1.64,22.72]],"ltp":1.57,"tv":3343.54,"id":8174333}]}]}
{"op":"mcm","clk":"1001409081","pt":1580635294298,"mc":[{"id":"1.168224329","rc":[{"trd":[[1.58,97.84]],"batl":[[0,1.61,30.68],[1,1.64,22.72],[2,1.72,2.27]],"ltp":1.58,"tv":3357.91,"id":8174333}],"tv":5445.85}]}
{"op":"mcm","clk":"1001409176","pt":1580635297021,"mc":[{"id":"1.168224329","rc":[{"batl":[[0,1.61,30.29]],"ltp":1.58,"tv":3357.91,"id":8174333}]}]}
{"op":"mcm","clk":"1001409276","pt":1580635299433,"mc":[{"id":"1.168224329","rc":[{"batl":[[0,1.72,2.27],[1,1.73,2.27],[2,1.76,144.51]],"ltp":1.58,"tv":3357.91,"id":8174333}]}]}
{"op":"mcm","clk":"1001409364","pt":1580635301226,"mc":[{"id":"1.168224329","rc":[{"batl":[[0,1.61,58.91],[1,1.72,2.27],[2,1.73,2.27]],"ltp":1.58,"tv":3357.91,"id":8174333}]}]}
{"op":"mcm","clk":"1001409466","pt":1580635303237,"mc":[{"id":"1.168224329","rc":[{"batl":[[0,1.61,15.14]],"ltp":1.58,"tv":3357.91,"id":8174333}]}]}
{"op":"mcm","clk":"1001409478","pt":1580635303439,"mc":[{"id":"1.168224329","rc":[{"batl":[[0,1.61,22.72]],"ltp":1.58,"tv":3357.91,"id":8174333}]}]}
{"op":"mcm","clk":"1001409568","pt":1580635304825,"mc":[{"id":"1.168224329","rc":[{"batl":[[0,1.61,37.86]],"ltp":1.58,"tv":3357.91,"id":8174333}]}]}
{"op":"mcm","clk":"1001409657","pt":1580635306628,"mc":[{"id":"1.168224329","rc":[{"batl":[[1,1.64,7.57],[2,1.72,2.27]],"ltp":1.58,"tv":3357.91,"id":8174333}]}]}
{"op":"mcm","clk":"1001409948","pt":1580635312940,"mc":[{"id":"1.168224329","rc":[{"batb":[[0,2.58,50.64]],"ltp":2.72,"tv":2087.94,"id":6498878},{"batb":[[0,1.58,55.75],[1,1.57,127.54],[2,1.56,47.29]],"ltp":1.58,"tv":3357.91,"id":8174333}]}]}
{"op":"mcm","clk":"1001410030","pt":1580635314173,"mc":[{"id":"1.168224329","marketDefinition":{"bspMarket":false,"turnInPlayEnabled":true,"persistenceEnabled":true,"marketBaseRate":5.0,"eventId":"29681717","eventTypeId":"2","numberOfWinners":1,"bettingType":"ODDS","marketType":"MATCH_ODDS","marketTime":"2020-02-02T09:19:00.000Z","suspendTime":"2020-02-02T09:19:00.000Z","bspReconciled":false,"complete":true,"inPlay":false,"crossMatching":true,"runnersVoidable":false,"numberOfActiveRunners":2,"betDelay":0,"status":"OPEN","runners":[{"status":"ACTIVE","sortPriority":1,"id":6498878,"name":"Marco Trungelliti"},{"status":"ACTIVE","sortPriority":2,"id":8174333,"name":"Enzo Couacaud"}],"regulators":["MR_INT"],"countryCode":"FR","discountAllowed":true,"timezone":"UTC","openDate":"2020-02-02T09:30:00.000Z","version":3148342584,"name":"Match Odds","eventName":"Trungelliti v Couacaud"},"rc":[{"batb":[[1,2.56,57.2]],"ltp":2.72,"tv":2087.94,"id":6498878}]}]}
{"op":"mcm","clk":"1001410228","pt":1580635317874,"mc":[{"id":"1.168224329","marketDefinition":{"bspMarket":false,"turnInPlayEnabled":true,"persistenceEnabled":true,"marketBaseRate":5.0,"eventId":"29681717","eventTypeId":"2","numberOfWinners":1,"bettingType":"ODDS","marketType":"MATCH_ODDS","marketTime":"2020-02-02T09:19:00.000Z","suspendTime":"2020-02-02T09:19:00.000Z","bspReconciled":false,"complete":true,"inPlay":false,"crossMatching":true,"runnersVoidable":false,"numberOfActiveRunners":2,"betDelay":0,"status":"OPEN","runners":[{"status":"ACTIVE","sortPriority":1,"id":6498878,"name":"Marco Trungelliti"},{"status":"ACTIVE","sortPriority":2,"id":8174333,"name":"Enzo Couacaud"}],"regulators":["MR_INT"],"countryCode":"FR","discountAllowed":true,"timezone":"UTC","openDate":"2020-02-02T09:19:00.000Z","version":3148342584,"name":"Match Odds","eventName":"Trungelliti v Couacaud"}}]}
{"op":"mcm","clk":"1001410722","pt":1580635326380,"mc":[{"id":"1.168224329","rc":[{"batl":[[0,3.75,16.74],[1,4,153.72],[2,95,15.9]],"ltp":2.72,"tv":2087.94,"id":6498878}]}]}
{"op":"mcm","clk":"1001410775","pt":1580635327364,"mc":[{"id":"1.168224329","rc":[{"batb":[[0,2.56,57.2],[1,2.54,16.37],[2,2.5,16.8]],"batl":[[0,4,153.72],[1,95,15.9],[2,990,2.2]],"ltp":2.72,"tv":2087.94,"id":6498878},{"trd":[[1.58,207.32]],"batb":[[0,1.57,127.54],[1,1.56,47.29],[2,1.54,54.25]],"ltp":1.58,"tv":3467.38,"id":8174333}],"tv":5555.33}]}
{"op":"mcm","clk":"1001410786","pt":1580635327557,"mc":[{"id":"1.168224329","rc":[{"batb":[[0,2.64,46.7],[1,2.56,73.36],[2,2.54,16.37]],"ltp":2.72,"tv":2087.94,"id":6498878},{"batb":[[2,1.55,87.15]],"ltp":1.58,"tv":3467.38,"id":8174333}]}]}
{"op":"mcm","clk":"1001411047","pt":1580635333361,"mc":[{"id":"1.168224329","rc":[{"batl":[[0,1.64,7.57],[1,1.72,2.27],[2,1.73,2.27]],"ltp":1.58,"tv":3467.38,"id":8174333}]}]}
{"op":"mcm","clk":"1001411055","pt":1580635333463,"mc":[{"id":"1.168224329","rc":[{"batl":[[0,1.6,37.86],[1,1.64,7.57],[2,1.72,2.27]],"ltp":1.58,"tv":3467.38,"id":8174333}]}]}
{"op":"mcm","clk":"1001411118","pt":1580635334592,"mc":[{"id":"1.168224329","rc":[{"batb":[[1,2.58,15.96],[2,2.56,73.36]],"ltp":2.72,"tv":2087.94,"id":6498878}]}]}
{"op":"mcm","clk":"1001411251","pt":1580635337267,"mc":[{"id":"1.168224329","rc":[{"batl":[[0,1.6,7.57]],"ltp":1.58,"tv":3467.38,"id":8174333}]}]}
{"op":"mcm","clk":"1001411265","pt":1580635337574,"mc":[{"id":"1.168224329","rc":[{"batb":[[1,2.56,73.36],[2,2.54,16.37]],"ltp":2.72,"tv":2087.94,"id":6498878}]}]}
{"op":"mcm","clk":"1001411305","pt":1580635338596,"mc":[{"id":"1.168224329","rc":[{"batl":[[0,1.6,15.14]],"ltp":1.58,"tv":3467.38,"id":8174333}]}]}
{"op":"mcm","clk":"1001411379","pt":1580635340396,"mc":[{"id":"1.168224329","rc":[{"batl":[[0,1.6,22.72]],"ltp":1.58,"tv":3467.38,"id":8174333}]}]}
{"op":"mcm","clk":"1001411386","pt":1580635340704,"mc":[{"id":"1.168224329","rc":[{"batl":[[0,1.6,30.29]],"ltp":1.58,"tv":3467.38,"id":8174333}]}]}
{"op":"mcm","clk":"1001411419","pt":1580635341575,"mc":[{"id":"1.168224329","rc":[{"batb":[[1,2.58,15.96],[2,2.56,73.36]],"ltp":2.72,"tv":2087.94,"id":6498878}]}]}
{"op":"mcm","clk":"1001411681","pt":1580635347982,"mc":[{"id":"1.168224329","rc":[{"trd":[[1.6,400.37]],"batl":[[0,1.6,1.16]],"ltp":1.6,"tv":3525.64,"id":8174333}],"tv":5613.58}]}
{"op":"mcm","clk":"1001411719","pt":1580635348700,"mc":[{"id":"1.168224329","rc":[{"batb":[[1,2.56,73.36],[2,2.54,16.37]],"ltp":2.72,"tv":2087.94,"id":6498878}]}]}
{"op":"mcm","clk":"1001411790","pt":1580635350803,"mc":[{"id":"1.168224329","rc":[{"batl":[[0,1.6,8.73]],"ltp":1.6,"tv":3525.64,"id":8174333}]}]}
{"op":"mcm","clk":"1001411919","pt":1580635353419,"mc":[{"id":"1.168224329","rc":[{"trd":[[1.6,417.83]],"batb":[[0,1.6,14.89],[1,1.57,127.54],[2,1.56,47.29]],"batl":[[0,1.64,7.57],[1,1.72,2.27],[2,1.73,2.27]],"ltp":1.6,"tv":3543.1,"id":8174333}],"tv":5631.04}]}
{"op":"mcm","clk":"1001412199","pt":1580635359107,"mc":[{"id":"1.168224329","rc":[{"trd":[[1.6,432.98]],"batb":[[0,1.6,13.62]],"ltp":1.6,"tv":3558.24,"id":8174333}],"tv":5646.19}]}
{"op":"mcm","clk":"1001412235","pt":1580635359720,"mc":[{"id":"1.168224329","rc":[{"trd":[[1.6,460.22]],"batb":[[0,1.57,127.54],[1,1.56,47.29],[2,1.55,87.15]],"ltp":1.6,"tv":3585.48,"id":8174333}],"tv":5673.43}]}
{"op":"mcm","clk":"1001412556","pt":1580635365395,"mc":[{"id":"1.168224329","rc":[{"trd":[[2.64,14.88]],"batb":[[0,2.64,31.82]],"ltp":2.64,"tv":2102.82,"id":6498878},{"trd":[[1.61,121.63]],"ltp":1.61,"tv":3609.88,"id":8174333}],"tv":5712.71}]}
{"op":"mcm","clk":"1001412590","pt":1580635366011,"mc":[{"id":"1.168224329","rc":[{"batb":[[0,1.57,181.51],[2,1.54,7.57]],"ltp":1.61,"tv":3609.88,"id":8174333}]}]}
{"op":"mcm","clk":"1001412726","pt":1580635369499,"mc":[{"id":"1.168224329","rc":[{"batl":[[0,1.6,7.57],[1,1.64,7.57],[2,1.72,2.27]],"ltp":1.61,"tv":3609.88,"id":8174333}]}]}
{"op":"mcm","clk":"1001412812","pt":1580635371100,"mc":[{"id":"1.168224329","rc":[{"batb":[[1,1.54,7.57],[2,1.53,47.56]],"ltp":1.61,"tv":3609.88,"id":8174333}]}]}
{"op":"mcm","clk":"1001413021","pt":1580635374819,"mc":[{"id":"1.168224329","rc":[{"batb":[[1,1.55,7.57],[2,1.54,7.57]],"ltp":1.61,"tv":3609.88,"id":8174333}]}]}
{"op":"mcm","clk":"1001413083","pt":1580635375941,"mc":[{"id":"1.168224329","rc":[{"batb":[[1,1.56,7.57],[2,1.55,7.57]],"ltp":1.61,"tv":3609.88,"id":8174333}]}]}
{"op":"mcm","clk":"1001416247","pt":1580635446003,"mc":[{"id":"1.168224329","rc":[{"batb":[[0,2.58,68.59]],"ltp":2.64,"tv":2102.82,"id":6498878},{"batb":[[0,1.57,127.54],[1,1.56,90.26]],"ltp":1.61,"tv":3609.88,"id":8174333}]}]}
{"op":"mcm","clk":"1001416274","pt":1580635446624,"mc":[{"id":"1.168224329","rc":[{"batb":[[1,2.56,57.2]],"ltp":2.64,"tv":2102.82,"id":6498878}]}]}
{"op":"mcm","clk":"1001416349","pt":1580635448324,"mc":[{"id":"1.168224329","rc":[{"trd":[[2.66,1.68]],"ltp":2.66,"tv":2104.5,"id":6498878},{"trd":[[1.6,463.01]],"batl":[[0,1.6,4.78]],"ltp":1.6,"tv":3612.67,"id":8174333}],"tv":5717.18}]}
{"op":"mcm","clk":"1001416427","pt":1580635449822,"mc":[{"id":"1.168224329","rc":[{"batb":[[0,1.59,2.81],[1,1.57,127.54],[2,1.56,90.26]],"ltp":1.6,"tv":3612.67,"id":8174333}]}]}
{"op":"mcm","clk":"1001418664","pt":1580635495850,"mc":[{"id":"1.168224329","rc":[{"trd":[[1.59,285.5]],"batb":[[0,1.57,128.53],[1,1.56,90.26],[2,1.55,7.57]],"ltp":1.59,"tv":3616.32,"id":8174333}],"tv":5720.83}]}
{"op":"mcm","clk":"1001418719","pt":1580635496786,"mc":[{"id":"1.168224329","rc":[{"trd":[[2.66,1.95]],"ltp":2.66,"tv":2104.77,"id":6498878},{"trd":[[1.6,463.46]],"batl":[[0,1.6,4.33]],"ltp":1.6,"tv":3616.77,"id":8174333}],"tv":5721.54}]}
{"op":"mcm","clk":"1001418858","pt":1580635498950,"mc":[{"id":"1.168224329","rc":[{"batb":[[0,1.59,1.43],[1,1.57,127.54],[2,1.56,90.26]],"ltp":1.6,"tv":3616.77,"id":8174333}]}]}
{"op":"mcm","clk":"1001418959","pt":1580635500794,"mc":[{"id":"1.168224329","rc":[{"trd":[[1.57,1.23],[1.59,288.36]],"batb":[[0,1.57,126.94],[1,1.56,90.26],[2,1.55,7.57]],"ltp":1.57,"tv":3620.83,"id":8174333}],"tv":5725.61}]}
{"op":"mcm","clk":"1001420067","pt":1580635521203,"mc":[{"id":"1.168224329","rc":[{"trd":[[2.58,44.19]],"batb":[[0,2.58,24.4]],"ltp":2.58,"tv":2148.97,"id":6498878},{"trd":[[1.6,472.12],[1.64,271.44]],"batb":[[0,1.59,4.36],[1,1.57,126.94],[2,1.56,90.26]],"batl":[[0,1.72,2.27],[1,1.73,2.27],[2,1.76,144.51]],"ltp":1.64,"tv":3714.17,"id":8174333}],"tv":5863.14}]}
{"op":"mcm","clk":"1001420107","pt":1580635521875,"mc":[{"id":"1.168224329","rc":[{"batb":[[1,1.58,97.66],[2,1.57,126.94]],"ltp":1.64,"tv":3714.17,"id":8174333}]}]}
{"op":"mcm","clk":"1001420146","pt":1580635522593,"mc":[{"id":"1.168224329","rc":[{"batb":[[2,2.52,16.59]],"ltp":2.58,"tv":2148.97,"id":6498878}]}]}
{"op":"mcm","clk":"1001420874","pt":1580635535308,"mc":[{"id":"1.168224329","rc":[{"batb":[[1,2.52,16.59],[2,2.5,16.8]],"ltp":2.58,"tv":2148.97,"id":6498878},{"trd":[[1.59,293.41]],"batb":[[0,1.59,1.84],[2,1.56,7.59]],"ltp":1.59,"tv":3719.21,"id":8174333}],"tv":5868.18}]}
{"op":"mcm","clk":"1001420967","pt":1580635537142,"mc":[{"id":"1.168224329","marketDefinition":{"bspMarket":false,"turnInPlayEnabled":true,"persistenceEnabled":true,"marketBaseRate":5.0,"eventId":"29681717","eventTypeId":"2","numberOfWinners":1,"bettingType":"ODDS","marketType":"MATCH_ODDS","marketTime":"2020-02-02T09:19:00.000Z","suspendTime":"2020-02-02T09:19:00.000Z","bspReconciled":false,"complete":true,"inPlay":true,"crossMatching":true,"runnersVoidable":false,"numberOfActiveRunners":2,"betDelay":3,"status":"OPEN","runners":[{"status":"ACTIVE","sortPriority":1,"id":6498878,"name":"Marco Trungelliti"},{"status":"ACTIVE","sortPriority":2,"id":8174333,"name":"Enzo Couacaud"}],"regulators":["MR_INT"],"countryCode":"FR","discountAllowed":true,"timezone":"UTC","openDate":"2020-02-02T09:19:00.000Z","version":3148343927,"name":"Match Odds","eventName":"Trungelliti v Couacaud"},"rc":[{"batb":[[0,1.11,37.97],[1,1.05,152.3],[2,1.04,169.36]],"batl":[[0,1000,0.02],[1,95,0],[2,990,0]],"ltp":2.58,"tv":2148.97,"id":6498878},{"batb":[[0,1.11,37.99],[1,1.05,152.3],[2,1.04,2036.28]],"batl":[[0,1.73,2.27],[1,1.76,144.51],[2,3,42.01]],"ltp":1.59,"tv":3719.21,"id":8174333}]}]}
{"op":"mcm","clk":"1001421795","pt":1580635553433,"mc":[{"id":"1.168224329","rc":[{"batb":[[0,1.26,3.38],[1,1.11,37.96],[2,1.05,152.3]],"ltp":2.58,"tv":2148.97,"id":6498878}]}]}
{"op":"mcm","clk":"1001422732","pt":1580635571267,"mc":[{"id":"1.168224329","rc":[{"batb":[[0,1.51,756.18],[1,1.26,3.38],[2,1.11,37.96]],"ltp":2.58,"tv":2148.97,"id":6498878},{"batb":[[0,1.12,756.3],[1,1.11,37.86],[2,1.05,152.3]],"ltp":1.59,"tv":3719.21,"id":8174333}]}]}
{"op":"mcm","clk":"1001423124","pt":1580635577087,"mc":[{"id":"1.168224329","rc":[{"batb":[[2,1.04,1867.51]],"ltp":1.59,"tv":3719.21,"id":8174333}]}]}
{"op":"mcm","clk":"1001423258","pt":1580635578784,"mc":[{"id":"1.168224329","rc":[{"batb":[[0,1.12,7561.88]],"ltp":1.59,"tv":3719.21,"id":8174333}]}]}
{"op":"mcm","clk":"1001424333","pt":1580635595190,"mc":[{"id":"1.168224329","rc":[{"batb":[[0,1.13,755.84],[1,1.12,7561.75],[2,1.11,37.86]],"ltp":1.59,"tv":3719.21,"id":8174333}]}]}
{"op":"mcm","clk":"1001424478","pt":1580635596322,"mc":[{"id":"1.168224329","rc":[{"batb":[[1,1.3,756.19],[2,1.26,3.37]],"ltp":2.58,"tv":2148.97,"id":6498878}]}]}
{"op":"mcm","clk":"1001424993","pt":1580635603018,"mc":[{"id":"1.168224329","rc":[{"batb":[[0,1.14,7561.88],[1,1.13,755.72],[2,1.12,7561.75]],"ltp":1.59,"tv":3719.21,"id":8174333}]}]}
{"op":"mcm","clk":"1001425243","pt":1580635606108,"mc":[{"id":"1.168224329","rc":[{"trd":[[2.76,0.01],[3.1,0.01]],"batb":[[0,1.51,756.27]],"ltp":3.1,"tv":2148.98,"id":6498878},{"trd":[[1.48,0.01],[1.57,1.25]],"batb":[[0,1.14,7561.85]],"ltp":1.48,"tv":3719.23,"id":8174333}],"tv":5868.22}]}
{"op":"mcm","clk":"1001425755","pt":1580635611001,"mc":[{"id":"1.168224329","rc":[{"batl":[[1,1.75,74.21],[2,1.76,144.51]],"ltp":1.48,"tv":3719.23,"id":8174333}]}]}
{"op":"mcm","clk":"1001426077","pt":1580635613943,"mc":[{"id":"1.168224329","rc":[{"batb":[[2,1.12,6805.58]],"ltp":1.48,"tv":3719.23,"id":8174333}]}]}
{"op":"mcm","clk":"1001426303","pt":1580635615548,"mc":[{"id":"1.168224329","rc":[{"batb":[[1,1.12,6805.58],[2,1.11,37.86]],"ltp":1.48,"tv":3719.23,"id":8174333}]}]}
{"op":"mcm","clk":"1001426663","pt":1580635618647,"mc":[{"id":"1.168224329","rc":[{"batb":[[0,1.15,755.82],[1,1.14,7561.75],[2,1.12,6805.58]],"ltp":1.48,"tv":3719.23,"id":8174333}]}]}
{"op":"mcm","clk":"1001426901","pt":1580635622655,"mc":[{"id":"1.168224329","rc":[{"batb":[[0,1.16,755.44],[1,1.15,755.72],[2,1.14,7561.75]],"ltp":1.48,"tv":3719.23,"id":8174333}]}]}
{"op":"mcm","clk":"1001427062","pt":1580635625424,"mc":[{"id":"1.168224329","rc":[{"batb":[[0,1.55,151.54],[1,1.51,756.18],[2,1.3,756.19]],"ltp":3.1,"tv":2148.98,"id":6498878},{"batb":[[0,1.16,906.88]],"ltp":1.48,"tv":3719.23,"id":8174333}]}]}
{"op":"mcm","clk":"1001427278","pt":1580635629574,"mc":[{"id":"1.168224329","rc":[{"batb":[[0,1.16,755.44]],"ltp":1.48,"tv":3719.23,"id":8174333}]}]}
{"op":"mcm","clk":"1001427441","pt":1580635632655,"mc":[{"id":"1.168224329","rc":[{"batb":[[0,1.18,151.55],[1,1.16,755.34],[2,1.15,755.72]],"ltp":1.48,"tv":3719.23,"id":8174333}]}]}
{"op":"mcm","clk":"1001427835","pt":1580635639552,"mc":[{"id":"1.168224329","rc":[{"batb":[[0,1.2,755.44],[1,1.18,151.45],[2,1.16,755.34]],"ltp":1.48,"tv":3719.23,"id":8174333}]}]}
{"op":"mcm","clk":"1001427948","pt":1580635641656,"mc":[{"id":"1.168224329","rc":[{"batb":[[0,1.25,755.34],[1,1.2,755.44],[2,1.18,151.45]],"ltp":1.48,"tv":3719.23,"id":8174333}]}]}
{"op":"mcm","clk":"1001428011","pt":1580635642792,"mc":[{"id":"1.168224329","rc":[{"batb":[[0,1.3,755.34],[1,1.25,755.34],[2,1.2,755.44]],"ltp":1.48,"tv":3719.23,"id":8174333}]}]}
{"op":"mcm","clk":"1001428428","pt":1580635649656,"mc":[{"id":"1.168224329","rc":[{"batb":[[0,1.31,755.72],[1,1.3,755.34],[2,1.25,755.34]],"ltp":1.48,"tv":3719.23,"id":8174333}]}]}
{"op":"mcm","clk":"1001428559","pt":1580635651862,"mc":[{"id":"1.168224329","rc":[{"batb":[[0,1.6,755.43],[1,1.55,151.45],[2,1.51,756.18]],"ltp":3.1,"tv":2148.98,"id":6498878},{"batb":[[0,1.35,30],[1,1.31,755.72],[2,1.3,755.34]],"ltp":1.48,"tv":3719.23,"id":8174333}]}]}
{"op":"mcm","clk":"1001428822","pt":1580635656999,"mc":[{"id":"1.168224329","rc":[{"batb":[[1,1.32,755.34],[2,1.31,755.72]],"ltp":1.48,"tv":3719.23,"id":8174333}]}]}
{"op":"mcm","clk":"1001429086","pt":1580635661986,"mc":[{"id":"1.168224329","rc":[{"batb":[[1,1.51,756.18],[2,1.3,756.19]],"ltp":3.1,"tv":2148.98,"id":6498878}]}]}
{"op":"mcm","clk":"1001429263","pt":1580635665106,"mc":[{"id":"1.168224329","rc":[{"batb":[[0,1.62,151.54],[1,1.6,755.34],[2,1.51,756.18]],"ltp":3.1,"tv":2148.98,"id":6498878},{"batb":[[1,1.32,906.78]],"ltp":1.48,"tv":3719.23,"id":8174333}]}]}
{"op":"mcm","clk":"1001430795","pt":1580635695321,"mc":[{"id":"1.168224329","rc":[{"batb":[[2,1.3,755.34]],"ltp":1.48,"tv":3719.23,"id":8174333}]}]}
{"op":"mcm","clk":"1001430968","pt":1580635698422,"mc":[{"id":"1.168224329","rc":[{"batb":[[0,1.36,755.72],[1,1.35,30],[2,1.32,906.78]],"ltp":1.48,"tv":3719.23,"id":8174333}]}]}
{"op":"mcm","clk":"1001431395","pt":1580635706026,"mc":[{"id":"1.168224329","rc":[{"batb":[[0,1.37,755.34],[1,1.36,755.72],[2,1.35,30]],"ltp":1.48,"tv":3719.23,"id":8174333}]}]}
{"op":"mcm","clk":"1001431445","pt":1580635707056,"mc":[{"id":"1.168224329","rc":[{"batl":[[1,1.75,225.66]],"ltp":1.48,"tv":3719.23,"id":8174333}]}]}
{"op":"mcm","clk":"1001431704","pt":1580635711064,"mc":[{"id":"1.168224329","rc":[{"batb":[[1,1.51,756.18],[2,1.3,756.19]],"ltp":3.1,"tv":2148.98,"id":6498878}]}]}
{"op":"mcm","clk":"1001431921","pt":1580635714160,"mc":[{"id":"1.168224329","rc":[{"batb":[[0,1.63,755.43],[1,1.62,151.45],[2,1.51,756.18]],"ltp":3.1,"tv":2148.98,"id":6498878}]}]}
{"op":"mcm","clk":"1001433354","pt":1580635738992,"mc":[{"id":"1.168224329","rc":[{"batb":[[1,1.51,756.18],[2,1.3,756.19]],"ltp":3.1,"tv":2148.98,"id":6498878}]}]}
{"op":"mcm","clk":"1001433556","pt":1580635742100,"mc":[{"id":"1.168224329","rc":[{"batb":[[0,1.64,151.54],[1,1.63,755.34],[2,1.51,756.18]],"ltp":3.1,"tv":2148.98,"id":6498878},{"batb":[[0,1.38,151.45],[1,1.37,755.34],[2,1.36,755.72]],"ltp":1.48,"tv":3719.23,"id":8174333}]}]}
{"op":"mcm","clk":"1001433591","pt":1580635742468,"mc":[{"id":"1.168224329","rc":[{"batb":[[2,1.35,30]],"ltp":1.48,"tv":3719.23,"id":8174333}]}]}
{"op":"mcm","clk":"1001433689","pt":1580635744069,"mc":[{"id":"1.168224329","rc":[{"batb":[[0,1.38,211.23]],"ltp":1.48,"tv":3719.23,"id":8174333}]}]}
{"op":"mcm","clk":"1001433733","pt":1580635744686,"mc":[{"id":"1.168224329","rc":[{"batb":[[0,1.38,271.01]],"ltp":1.48,"tv":3719.23,"id":8174333}]}]}
{"op":"mcm","clk":"1001433793","pt":1580635745871,"mc":[{"id":"1.168224329","rc":[{"batb":[[0,1.38,1026.73]],"ltp":1.48,"tv":3719.23,"id":8174333}]}]}
{"op":"mcm","clk":"1001433929","pt":1580635748166,"mc":[{"id":"1.168224329","rc":[{"batb":[[0,1.39,116.49],[1,1.38,1026.73],[2,1.37,755.34]],"ltp":1.48,"tv":3719.23,"id":8174333}]}]}
{"op":"mcm","clk":"1001434038","pt":1580635750072,"mc":[{"id":"1.168224329","rc":[{"batb":[[0,1.39,174.74]],"ltp":1.48,"tv":3719.23,"id":8174333}]}]}
{"op":"mcm","clk":"1001434110","pt":1580635751103,"mc":[{"id":"1.168224329","rc":[{"batb":[[1,1.51,756.18],[2,1.3,756.19]],"ltp":3.1,"tv":2148.98,"id":6498878}]}]}
{"op":"mcm","clk":"1001434283","pt":1580635754196,"mc":[{"id":"1.168224329","rc":[{"batb":[[0,1.65,755.43],[1,1.64,151.45],[2,1.51,756.18]],"ltp":3.1,"tv":2148.98,"id":6498878}]}]}
{"op":"mcm","clk":"1001434425","pt":1580635756718,"mc":[{"id":"1.168224329","rc":[{"trd":[[3.5,0.09]],"batb":[[0,1.65,755.34]],"ltp":3.5,"tv":2149.08,"id":6498878},{"trd":[[1.4,0.24]],"batb":[[0,1.4,1680.15],[1,1.39,174.74],[2,1.38,1026.73]],"ltp":1.4,"tv":3719.47,"id":8174333}],"tv":5868.55}]}
{"op":"mcm","clk":"1001434528","pt":1580635758686,"mc":[{"id":"1.168224329","rc":[{"batl":[[0,1.67,4.08],[1,1.73,2.27],[2,1.75,225.66]],"ltp":1.4,"tv":3719.47,"id":8174333}]}]}
{"op":"mcm","clk":"1001434735","pt":1580635762289,"mc":[{"id":"1.168224329","rc":[{"batb":[[0,1.45,20],[1,1.41,7.57],[2,1.4,1680.15]],"ltp":1.4,"tv":3719.47,"id":8174333}]}]}
{"op":"mcm","clk":"1001434793","pt":1580635763115,"mc":[{"id":"1.168224329","rc":[{"batb":[[1,1.41,173.79]],"ltp":1.4,"tv":3719.47,"id":8174333}]}]}
{"op":"mcm","clk":"1001434953","pt":1580635765326,"mc":[{"id":"1.168224329","rc":[{"batl":[[0,90,1.68],[1,1000,0.02]],"ltp":3.5,"tv":2149.08,"id":6498878}]}]}
{"op":"mcm","clk":"1001435262","pt":1580635770310,"mc":[{"id":"1.168224329","rc":[{"batb":[[1,1.41,166.22]],"batl":[[0,1.73,2.27],[1,1.75,225.66],[2,1.76,144.51]],"ltp":1.4,"tv":3719.47,"id":8174333}]}]}
{"op":"mcm","clk":"1001435304","pt":1580635770927,"mc":[{"id":"1.168224329","rc":[{"batb":[[2,1.38,907.16]],"ltp":1.4,"tv":3719.47,"id":8174333}]}]}
{"op":"mcm","clk":"1001435464","pt":1580635773097,"mc":[{"id":"1.168224329","rc":[{"batl":[[0,90,1.81]],"ltp":3.5,"tv":2149.08,"id":6498878},{"batb":[[0,1.46,32.92],[1,1.45,20],[2,1.41,166.22]],"ltp":1.4,"tv":3719.47,"id":8174333}]}]}
{"op":"mcm","clk":"1001435522","pt":1580635774026,"mc":[{"id":"1.168224329","rc":[{"batb":[[2,1.42,1680.15]],"ltp":1.4,"tv":3719.47,"id":8174333}]}]}
{"op":"mcm","clk":"1001435556","pt":1580635774436,"mc":[{"id":"1.168224329","rc":[{"batl":[[0,1.62,4.2],[1,1.73,2.27],[2,1.75,225.66]],"ltp":1.4,"tv":3719.47,"id":8174333}]}]}
{"op":"mcm","clk":"1001435795","pt":1580635778230,"mc":[{"id":"1.168224329","rc":[{"batb":[[0,1.8,75.72],[1,1.65,755.34],[2,1.64,151.45]],"ltp":3.5,"tv":2149.08,"id":6498878},{"batl":[[0,1.73,2.27],[1,1.75,225.66],[2,1.76,144.51]],"ltp":1.4,"tv":3719.47,"id":8174333}]}]}
{"op":"mcm","clk":"1001435907","pt":1580635780151,"mc":[{"id":"1.168224329","rc":[{"batb":[[2,1.43,158.5]],"ltp":1.4,"tv":3719.47,"id":8174333}]}]}
{"op":"mcm","clk":"1001436055","pt":1580635782120,"mc":[{"id":"1.168224329","rc":[{"batl":[[0,90,1.68]],"ltp":3.5,"tv":2149.08,"id":6498878},{"batl":[[0,1.59,4.29],[1,1.73,2.27],[2,1.75,225.66]],"ltp":1.4,"tv":3719.47,"id":8174333}]}]}
{"op":"mcm","clk":"1001436256","pt":1580635784857,"mc":[{"id":"1.168224329","rc":[{"batl":[[0,90,1.81]],"ltp":3.5,"tv":2149.08,"id":6498878}]}]}
{"op":"mcm","clk":"1001436348","pt":1580635786252,"mc":[{"id":"1.168224329","rc":[{"batb":[[0,1.47,74.21],[1,1.46,32.92],[2,1.45,20]],"ltp":1.4,"tv":3719.47,"id":8174333}]}]}
{"op":"mcm","clk":"1001436387","pt":1580635786819,"mc":[{"id":"1.168224329","rc":[{"batl":[[0,1.73,2.27],[1,1.75,225.66],[2,1.76,144.51]],"ltp":1.4,"tv":3719.47,"id":8174333}]}]}
{"op":"mcm","clk":"1001436574","pt":1580635789920,"mc":[{"id":"1.168224329","rc":[{"batb":[[1,1.7,75.72],[2,1.65,755.34]],"ltp":3.5,"tv":2149.08,"id":6498878},{"batl":[[0,1.58,4.29],[1,1.73,2.27],[2,1.75,225.66]],"ltp":1.4,"tv":3719.47,"id":8174333}]}]}
{"op":"mcm","clk":"1001436679","pt":1580635791350,"mc":[{"id":"1.168224329","rc":[{"batl":[[0,1000,0.15],[1,1000,0]],"ltp":3.5,"tv":2149.08,"id":6498878}]}]}
{"op":"mcm","clk":"1001436731","pt":1580635792126,"mc":[{"id":"1.168224329","rc":[{"batl":[[0,1.73,2.27],[1,1.75,225.66],[2,1.76,144.51]],"ltp":1.4,"tv":3719.47,"id":8174333}]}]}
{"op":"mcm","clk":"1001436803","pt":1580635793365,"mc":[{"id":"1.168224329","rc":[{"batb":[[2,1.66,114.74]],"ltp":3.5,"tv":2149.08,"id":6498878}]}]}
{"op":"mcm","clk":"1001436817","pt":1580635793524,"mc":[{"id":"1.168224329","rc":[{"batb":[[2,1.66,172.1]],"ltp":3.5,"tv":2149.08,"id":6498878}]}]}
{"op":"mcm","clk":"1001436900","pt":1580635795265,"mc":[{"id":"1.168224329","rc":[{"batb":[[2,1.66,229.47]],"ltp":3.5,"tv":2149.08,"id":6498878},{"batb":[[2,1.43,158.5]],"batl":[[0,1.57,4.29],[1,1.73,2.27],[2,1.75,225.66]],"ltp":1.4,"tv":3719.47,"id":8174333}]}]}
{"op":"mcm","clk":"1001437034","pt":1580635798047,"mc":[{"id":"1.168224329","rc":[{"batb":[[0,1.48,47.33],[1,1.47,74.21]],"ltp":1.4,"tv":3719.47,"id":8174333}]}]}
{"op":"mcm","clk":"1001437517","pt":1580635805060,"mc":[{"id":"1.168224329","rc":[{"batb":[[0,1.49,74.21],[1,1.48,47.33],[2,1.47,74.21]],"ltp":1.4,"tv":3719.47,"id":8174333}]}]}
{"op":"mcm","clk":"1001437920","pt":1580635812481,"mc":[{"id":"1.168224329","rc":[{"batl":[[0,1.73,2.27],[1,1.75,225.66],[2,1.76,144.51]],"ltp":1.4,"tv":3719.47,"id":8174333}]}]}
{"op":"mcm","clk":"1001438126","pt":1580635816590,"mc":[{"id":"1.168224329","rc":[{"batl":[[0,1.63,4.18],[1,1.73,2.27],[2,1.75,225.66]],"ltp":1.4,"tv":3719.47,"id":8174333}]}]}
{"op":"mcm","clk":"1001438586","pt":1580635825159,"mc":[{"id":"1.168224329","rc":[{"batl":[[0,1.73,2.27],[1,1.75,225.66],[2,1.76,144.51]],"ltp":1.4,"tv":3719.47,"id":8174333}]}]}
{"op":"mcm","clk":"1001438667","pt":1580635826964,"mc":[{"id":"1.168224329","rc":[{"batb":[[1,1.47,74.21],[2,1.38,755.72]],"ltp":1.4,"tv":3719.47,"id":8174333}]}]}
{"op":"mcm","clk":"1001438732","pt":1580635828299,"mc":[{"id":"1.168224329","rc":[{"batb":[[2,1.4,158.5]],"ltp":1.4,"tv":3719.47,"id":8174333}]}]}
{"op":"mcm","clk":"1001438758","pt":1580635828764,"mc":[{"id":"1.168224329","rc":[{"batl":[[0,1.59,4.29],[1,1.73,2.27],[2,1.75,225.66]],"ltp":1.4,"tv":3719.47,"id":8174333}]}]}
{"op":"mcm","clk":"1001440305","pt":1580635859148,"mc":[{"id":"1.168224329","rc":[{"batl":[[0,1.73,2.27],[1,1.75,225.66],[2,1.76,144.51]],"ltp":1.4,"tv":3719.47,"id":8174333}]}]}
{"op":"mcm","clk":"1001440572","pt":1580635863230,"mc":[{"id":"1.168224329","rc":[{"batl":[[0,1.56,4.37],[1,1.73,2.27],[2,1.75,225.66]],"ltp":1.4,"tv":3719.47,"id":8174333}]}]}
{"op":"mcm","clk":"1001440988","pt":1580635870558,"mc":[{"id":"1.168224329","rc":[{"batb":[[0,1.81,756.18],[1,1.8,75.72],[2,1.7,75.72]],"ltp":3.5,"tv":2149.08,"id":6498878}]}]}
{"op":"mcm","clk":"1001441108","pt":1580635872970,"mc":[{"id":"1.168224329","rc":[{"batb":[[2,1.71,756.18]],"ltp":3.5,"tv":2149.08,"id":6498878}]}]}
{"op":"mcm","clk":"1001441710","pt":1580635883665,"mc":[{"id":"1.168224329","rc":[{"batl":[[0,1.73,2.27],[1,1.75,225.66],[2,1.76,144.51]],"ltp":1.4,"tv":3719.47,"id":8174333}]}]}
{"op":"mcm","clk":"1001442373","pt":1580635895176,"mc":[{"id":"1.168224329","rc":[{"batb":[[2,1.41,756.18]],"batl":[[0,1.67,4.08],[1,1.73,2.27],[2,1.75,225.66]],"ltp":1.4,"tv":3719.47,"id":8174333}]}]}
{"op":"mcm","clk":"1001442638","pt":1580635900368,"mc":[{"id":"1.168224329","rc":[{"batb":[[0,1.82,46.18],[1,1.81,756.18],[2,1.8,75.72]],"ltp":3.5,"tv":2149.08,"id":6498878}]}]}
{"op":"mcm","clk":"1001442666","pt":1580635900882,"mc":[{"id":"1.168224329","rc":[{"batb":[[0,1.82,92.35]],"ltp":3.5,"tv":2149.08,"id":6498878}]}]}
{"op":"mcm","clk":"1001442871","pt":1580635904894,"mc":[{"id":"1.168224329","rc":[{"batb":[[2,1.42,108.18]],"batl":[[0,1.73,2.27],[1,1.75,225.66],[2,1.76,144.51]],"ltp":1.4,"tv":3719.47,"id":8174333}]}]}
{"op":"mcm","clk":"1001443115","pt":1580635908807,"mc":[{"id":"1.168224329","rc":[{"batl":[[0,1.59,4.29],[1,1.73,2.27],[2,1.75,225.66]],"ltp":1.4,"tv":3719.47,"id":8174333}]}]}
{"op":"mcm","clk":"1001443398","pt":1580635913809,"mc":[{"id":"1.168224329","rc":[{"batb":[[2,1.43,151.24]],"ltp":1.4,"tv":3719.47,"id":8174333}]}]}
{"op":"mcm","clk":"1001444071","pt":1580635927116,"mc":[{"id":"1.168224329","rc":[{"trd":[[2.68,2.54]],"ltp":2.68,"tv":2151.62,"id":6498878},{"trd":[[1.59,297.69]],"batl":[[0,1.73,2.27],[1,1.75,225.66],[2,1.76,144.51]],"ltp":1.59,"tv":3723.75,"id":8174333}],"tv":5875.37}]}
{"op":"mcm","clk":"1001444130","pt":1580635928200,"mc":[{"id":"1.168224329","rc":[{"batl":[[0,2.68,4],[1,1000,0.15]],"ltp":2.68,"tv":2151.62,"id":6498878}]}]}
{"op":"mcm","clk":"1001444166","pt":1580635929020,"mc":[{"id":"1.168224329","rc":[{"batl":[[0,2.68,2]],"ltp":2.68,"tv":2151.62,"id":6498878}]}]}
{"op":"mcm","clk":"1001444211","pt":1580635929945,"mc":[{"id":"1.168224329","rc":[{"batl":[[0,1000,0.15],[1,1000,0]],"ltp":2.68,"tv":2151.62,"id":6498878}]}]}
{"op":"mcm","clk":"1001444820","pt":1580635942728,"mc":[{"id":"1.168224329","rc":[{"batl":[[0,1.68,4],[1,1.73,2.27],[2,1.75,225.66]],"ltp":1.59,"tv":3723.75,"id":8174333}]}]}
{"op":"mcm","clk":"1001446072","pt":1580635970792,"mc":[{"id":"1.168224329","rc":[{"batb":[[2,1.4,113.58]],"ltp":1.59,"tv":3723.75,"id":8174333}]}]}
{"op":"mcm","clk":"1001446200","pt":1580635973884,"mc":[{"id":"1.168224329","rc":[{"batb":[[2,1.41,151.24]],"ltp":1.59,"tv":3723.75,"id":8174333}]}]}
{"op":"mcm","clk":"1001446452","pt":1580635980273,"mc":[{"id":"1.168224329","rc":[{"batb":[[0,1.83,466.31],[1,1.82,92.35],[2,1.81,756.18]],"ltp":2.68,"tv":2151.62,"id":6498878}]}]}
{"op":"mcm","clk":"1001446627","pt":1580635985575,"mc":[{"id":"1.168224329","rc":[{"batb":[[2,1.42,113.58]],"ltp":1.59,"tv":3723.75,"id":8174333}]}]}
{"op":"mcm","clk":"1001446741","pt":1580635988817,"mc":[{"id":"1.168224329","rc":[{"batb":[[1,1.81,756.18],[2,1.8,75.72]],"ltp":2.68,"tv":2151.62,"id":6498878}]}]}
{"op":"mcm","clk":"1001446850","pt":1580635991905,"mc":[{"id":"1.168224329","rc":[{"batb":[[0,1.84,92.35],[1,1.83,466.31],[2,1.81,756.18]],"ltp":2.68,"tv":2151.62,"id":6498878}]}]}
{"op":"mcm","clk":"1001446933","pt":1580635994113,"mc":[{"id":"1.168224329","rc":[{"batb":[[1,1.83,617.75]],"ltp":2.68,"tv":2151.62,"id":6498878}]}]}
{"op":"mcm","clk":"1001447212","pt":1580636002998,"mc":[{"id":"1.168224329","rc":[{"batl":[[0,2.8,192.14],[1,1000,0.15]],"ltp":2.68,"tv":2151.62,"id":6498878}]}]}
{"op":"mcm","clk":"1001448299","pt":1580636035942,"mc":[{"id":"1.168224329","rc":[{"batb":[[2,1.43,151.24]],"ltp":1.59,"tv":3723.75,"id":8174333}]}]}
{"op":"mcm","clk":"1001448514","pt":1580636042077,"mc":[{"id":"1.168224329","rc":[{"batb":[[1,1.83,151.45]],"batl":[[0,2.76,16.8],[1,2.8,192.14],[2,1000,0.15]],"ltp":2.68,"tv":2151.62,"id":6498878}]}]}
{"op":"mcm","clk":"1001448565","pt":1580636043380,"mc":[{"id":"1.168224329","rc":[{"batl":[[0,1.73,2.27],[1,1.75,225.66],[2,1.76,144.51]],"ltp":1.59,"tv":3723.75,"id":8174333}]}]}
{"op":"mcm","clk":"1001448643","pt":1580636045184,"mc":[{"id":"1.168224329","rc":[{"batb":[[0,1.86,466.31],[1,1.84,92.35],[2,1.83,151.45]],"ltp":2.68,"tv":2151.62,"id":6498878}]}]}
{"op":"mcm","clk":"1001448662","pt":1580636045446,"mc":[{"id":"1.168224329","rc":[{"batb":[[1,1.83,151.45],[2,1.81,756.18]],"ltp":2.68,"tv":2151.62,"id":6498878}]}]}
{"op":"mcm","clk":"1001449506","pt":1580636071641,"mc":[{"id":"1.168224329","rc":[{"batl":[[2,1000,0.02]],"ltp":2.68,"tv":2151.62,"id":6498878}]}]}
{"op":"mcm","clk":"1001450156","pt":1580636087365,"mc":[{"id":"1.168224329","rc":[{"batb":[[1,1.81,756.18],[2,1.8,75.72]],"ltp":2.68,"tv":2151.62,"id":6498878}]}]}
{"op":"mcm","clk":"1001450282","pt":1580636090469,"mc":[{"id":"1.168224329","rc":[{"batb":[[0,1.87,151.45],[1,1.86,466.31],[2,1.81,756.18]],"ltp":2.68,"tv":2151.62,"id":6498878}]}]}
{"op":"mcm","clk":"1001450655","pt":1580636103161,"mc":[{"id":"1.168224329","rc":[{"batb":[[1,1.81,756.18],[2,1.8,75.72]],"ltp":2.68,"tv":2151.62,"id":6498878},{"batb":[[2,1.39,756.18]],"ltp":1.59,"tv":3723.75,"id":8174333}]}]}
{"op":"mcm","clk":"1001450777","pt":1580636106266,"mc":[{"id":"1.168224329","rc":[{"batb":[[0,1.88,466.31],[1,1.87,151.45],[2,1.81,756.18]],"ltp":2.68,"tv":2151.62,"id":6498878},{"batb":[[2,1.4,151.24]],"ltp":1.59,"tv":3723.75,"id":8174333}]}]}
{"op":"mcm","clk":"1001451323","pt":1580636123195,"mc":[{"id":"1.168224329","rc":[{"batb":[[1,1.81,756.18],[2,1.8,75.72]],"ltp":2.68,"tv":2151.62,"id":6498878}]}]}
{"op":"mcm","clk":"1001451414","pt":1580636126292,"mc":[{"id":"1.168224329","rc":[{"batb":[[0,1.89,151.45],[1,1.88,466.31],[2,1.81,756.18]],"ltp":2.68,"tv":2151.62,"id":6498878}]}]}
{"op":"mcm","clk":"1001451491","pt":1580636128922,"mc":[{"id":"1.168224329","rc":[{"batl":[[1,1000,0.02],[2,1000,0]],"ltp":2.68,"tv":2151.62,"id":6498878}]}]}
{"op":"mcm","clk":"1001451629","pt":1580636133014,"mc":[{"id":"1.168224329","rc":[{"batb":[[0,1.6,42.22],[1,1.49,74.21],[2,1.47,74.21]],"ltp":1.59,"tv":3723.75,"id":8174333}]}]}
{"op":"mcm","clk":"1001451860","pt":1580636139213,"mc":[{"id":"1.168224329","rc":[{"batl":[[0,1000,0.02],[1,1000,0]],"ltp":2.68,"tv":2151.62,"id":6498878}]}]}
{"op":"mcm","clk":"1001452470","pt":1580636155179,"mc":[{"id":"1.168224329","rc":[{"batb":[[1,1.4,151.24],[2,1.39,756.18]],"batl":[[1,1.76,144.51],[2,3,42.01]],"ltp":1.59,"tv":3723.75,"id":8174333}]}]}
{"op":"mcm","clk":"1001452617","pt":1580636158357,"mc":[{"id":"1.168224329","rc":[{"batl":[[0,1.7,25.21],[1,1.73,2.27],[2,1.76,144.51]],"ltp":1.59,"tv":3723.75,"id":8174333}]}]}
{"op":"mcm","clk":"1001452712","pt":1580636160063,"mc":[{"id":"1.168224329","rc":[{"batb":[[1,1.42,151.45],[2,1.4,151.24]],"ltp":1.59,"tv":3723.75,"id":8174333}]}]}
{"op":"mcm","clk":"1001453206","pt":1580636170367,"mc":[{"id":"1.168224329","rc":[{"batb":[[1,1.81,756.18],[2,1.8,75.72]],"ltp":2.68,"tv":2151.62,"id":6498878},{"batb":[[2,1.39,756.18]],"ltp":1.59,"tv":3723.75,"id":8174333}]}]}
{"op":"mcm","clk":"1001453348","pt":1580636173505,"mc":[{"id":"1.168224329","rc":[{"batb":[[0,1.9,466.31],[1,1.89,151.45],[2,1.81,756.18]],"ltp":2.68,"tv":2151.62,"id":6498878},{"batb":[[1,1.43,151.24],[2,1.42,151.45]],"ltp":1.59,"tv":3723.75,"id":8174333}]}]}
{"op":"mcm","clk":"1001453541","pt":1580636177884,"mc":[{"id":"1.168224329","rc":[{"batl":[[1,1.76,144.51],[2,3,42.01]],"ltp":1.59,"tv":3723.75,"id":8174333}]}]}
{"op":"mcm","clk":"1001453716","pt":1580636181195,"mc":[{"id":"1.168224329","rc":[{"batb":[[1,1.81,756.18],[2,1.8,75.72]],"ltp":2.68,"tv":2151.62,"id":6498878},{"batl":[[0,1.69,2.27],[1,1.7,25.21],[2,1.76,144.51]],"ltp":1.59,"tv":3723.75,"id":8174333}]}]}
{"op":"mcm","clk":"1001453850","pt":1580636184286,"mc":[{"id":"1.168224329","rc":[{"batb":[[0,1.91,151.45],[1,1.9,466.31],[2,1.81,756.18]],"ltp":2.68,"tv":2151.62,"id":6498878}]}]}
{"op":"mcm","clk":"1001453864","pt":1580636184700,"mc":[{"id":"1.168224329","rc":[{"batb":[[1,1.42,151.45],[2,1.26,756.18]],"ltp":1.59,"tv":3723.75,"id":8174333}]}]}
{"op":"mcm","clk":"1001454095","pt":1580636189512,"mc":[{"id":"1.168224329","rc":[{"batb":[[1,1.81,756.18],[2,1.8,75.72]],"ltp":2.68,"tv":2151.62,"id":6498878}]}]}
{"op":"mcm","clk":"1001454198","pt":1580636192136,"mc":[{"id":"1.168224329","rc":[{"batb":[[1,1.26,756.18],[2,1.25,378.62]],"ltp":1.59,"tv":3723.75,"id":8174333}]}]}
{"op":"mcm","clk":"1001454214","pt":1580636192597,"mc":[{"id":"1.168224329","rc":[{"batb":[[0,1.92,466.31],[1,1.91,151.45],[2,1.81,756.18]],"ltp":2.68,"tv":2151.62,"id":6498878}]}]}
{"op":"mcm","clk":"1001454321","pt":1580636195198,"mc":[{"id":"1.168224329","rc":[{"batb":[[1,1.27,151.45],[2,1.26,756.18]],"ltp":1.59,"tv":3723.75,"id":8174333}]}]}
{"op":"mcm","clk":"1001454409","pt":1580636198546,"mc":[{"id":"1.168224329","rc":[{"batb":[[1,1.81,756.18],[2,1.8,75.72]],"ltp":2.68,"tv":2151.62,"id":6498878}]}]}
{"op":"mcm","clk":"1001454534","pt":1580636201657,"mc":[{"id":"1.168224329","rc":[{"batb":[[0,1.94,151.45],[1,1.92,466.31],[2,1.81,756.18]],"ltp":2.68,"tv":2151.62,"id":6498878}]}]}
{"op":"mcm","clk":"1001454582","pt":1580636203411,"mc":[{"id":"1.168224329","rc":[{"trd":[[2.42,9.21],[2.44,1.57]],"ltp":2.42,"tv":2162.4,"id":6498878},{"trd":[[1.69,2.27],[1.7,37.31],[1.76,289.02]],"batb":[[0,1.76,426.76],[1,1.6,42.22],[2,1.28,151.24]],"batl":[[0,1.83,14.13],[1,1.86,677.35],[2,3,42.01]],"ltp":1.76,"tv":4052.35,"id":8174333}],"tv":6214.75}]}
{"op":"mcm","clk":"1001454657","pt":1580636205217,"mc":[{"id":"1.168224329","rc":[{"batb":[[0,1.6,42.22],[1,1.28,151.24],[2,1.27,151.45]],"batl":[[0,3,42.01],[1,1000,0.02],[2,3,0]],"ltp":1.76,"tv":4052.35,"id":8174333}]}]}
{"op":"mcm","clk":"1001454694","pt":1580636206350,"mc":[{"id":"1.168224329","rc":[{"batb":[[1,1.3,75.72],[2,1.28,151.24]],"batl":[[0,1.8,3.36],[1,3,42.01],[2,1000,0.02]],"ltp":1.76,"tv":4052.35,"id":8174333}]}]}
{"op":"mcm","clk":"1001454743","pt":1580636207531,"mc":[{"id":"1.168224329","rc":[{"batb":[[0,1.92,466.31],[1,1.81,756.18],[2,1.71,756.18]],"ltp":2.42,"tv":2162.4,"id":6498878}]}]}
{"op":"mcm","clk":"1001454837","pt":1580636210260,"mc":[{"id":"1.168224329","rc":[{"batb":[[1,1.56,494.03],[2,1.54,510.84]],"batl":[[1,1.83,480.59],[2,1.85,497.4]],"ltp":1.76,"tv":4052.35,"id":8174333}]}]}
{"op":"mcm","clk":"1001454850","pt":1580636210623,"mc":[{"id":"1.168224329","rc":[{"batb":[[0,1.96,151.45],[1,1.92,466.31],[2,1.81,756.18]],"ltp":2.42,"tv":2162.4,"id":6498878}]}]}
{"op":"mcm","clk":"1001455048","pt":1580636214742,"mc":[{"id":"1.168224329","rc":[{"batb":[[1,1.31,756.18],[2,1.3,75.72]],"ltp":1.76,"tv":4052.35,"id":8174333}]}]}
{"op":"mcm","clk":"1001455182","pt":1580636217363,"mc":[{"id":"1.168224329","rc":[{"batb":[[0,2.4,7.66],[1,2.32,382.67],[2,1.96,151.45]],"batl":[[0,2.46,6.82],[1,2.5,424.77],[2,1000,0.02]],"ltp":2.42,"tv":2162.4,"id":6498878},{"batb":[[1,1.33,151.45],[2,1.31,756.18]],"ltp":1.76,"tv":4052.35,"id":8174333}]}]}
{"op":"mcm","clk":"1001455439","pt":1580636223166,"mc":[{"id":"1.168224329","rc":[{"batl":[[1,3,42.01],[2,1000,0.02]],"ltp":1.76,"tv":4052.35,"id":8174333}]}]}
{"op":"mcm","clk":"1001455502","pt":1580636224057,"mc":[{"id":"1.168224329","rc":[{"batb":[[2,2.3,31.93]],"batl":[[2,2.58,26.05]],"ltp":2.42,"tv":2162.4,"id":6498878},{"batb":[[0,1.64,494.03],[1,1.62,578.05],[2,1.6,42.22]],"batl":[[0,1.75,480.59],[1,1.77,497.4],[2,1.78,42.01]],"ltp":1.76,"tv":4052.35,"id":8174333}]}]}
{"op":"mcm","clk":"1001455549","pt":1580636225142,"mc":[{"id":"1.168224329","rc":[{"batb":[[0,1.65,378.27],[1,1.64,862.89],[2,1.62,578.05]],"batl":[[0,1.7,544.53],[1,1.72,627.42],[2,1.75,480.59]],"ltp":1.76,"tv":4052.35,"id":8174333}]}]}
{"op":"mcm","clk":"1001455812","pt":1580636231266,"mc":[{"id":"1.168224329","rc":[{"batb":[[0,2.3,31.93],[1,2.28,76.87],[2,1.96,151.45]],"batl":[[0,2.58,26.05],[1,1000,0.02],[2,2.58,0]],"ltp":2.42,"tv":2162.4,"id":6498878},{"batb":[[0,1.64,494.03],[1,1.62,578.05],[2,1.6,42.22]],"batl":[[0,1.75,480.59],[1,1.77,497.4],[2,1.78,42.01]],"ltp":1.76,"tv":4052.35,"id":8174333}]}]}
{"op":"mcm","clk":"1001455859","pt":1580636232251,"mc":[{"id":"1.168224329","rc":[{"batb":[[0,2.28,76.87],[1,1.96,151.45],[2,1.71,756.18]],"batl":[[0,1000,0.02],[1,1000,0]],"ltp":2.42,"tv":2162.4,"id":6498878},{"batb":[[1,1.62,510.84]],"batl":[[2,1.8,3.36]],"ltp":1.76,"tv":4052.35,"id":8174333}]}]}
{"op":"mcm","clk":"1001456015","pt":1580636235259,"mc":[{"id":"1.168224329","rc":[{"batb":[[0,1.6,42.22],[1,1.59,596.79],[2,1.58,423.87]],"ltp":1.76,"tv":4052.35,"id":8174333}]}]}
{"op":"mcm","clk":"1001456138","pt":1580636238348,"mc":[{"id":"1.168224329","rc":[{"batb":[[0,2.56,5.67],[1,2.46,392.02],[2,2.28,76.87]],"batl":[[0,2.66,395.97],[1,1000,0.02]],"ltp":2.42,"tv":2162.4,"id":6498878},{"batb":[[1,1.59,2011.88]],"batl":[[0,1.64,1910.9],[1,1.65,359.64],[2,1.75,480.59]],"ltp":1.76,"tv":4052.35,"id":8174333}]}]}
{"op":"mcm","clk":"1001456179","pt":1580636239276,"mc":[{"id":"1.168224329","rc":[{"batb":[[0,2.64,52.17],[1,2.56,5.67],[2,2.46,392.02]],"batl":[[1,2.74,23.53],[2,1000,0.02]],"ltp":2.42,"tv":2162.4,"id":6498878},{"batl":[[2,1.71,42.01]],"ltp":1.76,"tv":4052.35,"id":8174333}]}]}
{"op":"mcm","clk":"1001456403","pt":1580636244592,"mc":[{"id":"1.168224329","rc":[{"batl":[[0,1.64,2391.49],[2,1.66,497.4]],"ltp":1.76,"tv":4052.35,"id":8174333}]}]}
{"op":"mcm","clk":"1001456527","pt":1580636247062,"mc":[{"id":"1.168224329","rc":[{"batl":[[2,2.76,3.02]],"ltp":2.42,"tv":2162.4,"id":6498878}]}]}
{"op":"mcm","clk":"1001456575","pt":1580636248249,"mc":[{"id":"1.168224329","rc":[{"batb":[[1,2.44,64.28],[2,2.42,29.41]],"batl":[[0,2.74,23.53],[1,2.76,3.02],[2,1000,0.02]],"ltp":2.42,"tv":2162.4,"id":6498878},{"batb":[[1,1.59,596.79]],"batl":[[0,1.64,1019.54]],"ltp":1.76,"tv":4052.35,"id":8174333}]}]}
{"op":"mcm","clk":"1001456591","pt":1580636248662,"mc":[{"id":"1.168224329","rc":[{"batb":[[0,2.44,64.28],[1,2.42,29.41],[2,1.96,151.45]],"batl":[[1,1000,0.02],[2,1000,0]],"ltp":2.42,"tv":2162.4,"id":6498878},{"batb":[[1,1.57,73.1],[2,1.56,494.03]],"batl":[[0,1.64,480.59],[1,1.66,497.4],[2,1.7,22.25]],"ltp":1.76,"tv":4052.35,"id":8174333}]}]}
{"op":"mcm","clk":"1001456652","pt":1580636250365,"mc":[{"id":"1.168224329","rc":[{"batb":[[1,2.42,3.94],[2,2.36,4.43]],"batl":[[0,1000,0.02],[1,1000,0]],"ltp":2.42,"tv":2162.4,"id":6498878},{"batb":[[1,1.57,31.57]],"ltp":1.76,"tv":4052.35,"id":8174333}]}]}
{"op":"mcm","clk":"1001456711","pt":1580636251800,"mc":[{"id":"1.168224329","rc":[{"batb":[[0,2.42,69.32],[1,2.36,4.43],[2,1.96,151.45]],"batl":[[0,2.76,3.02],[1,1000,0.02]],"ltp":2.42,"tv":2162.4,"id":6498878}]}]}
{"op":"mcm","clk":"1001456876","pt":1580636255965,"mc":[{"id":"1.168224329","rc":[{"batb":[[0,1.6,799.96],[1,1.59,414.64],[2,1.57,31.57]],"batl":[[1,1.66,1197.01],[2,1.68,678.69]],"ltp":1.76,"tv":4052.35,"id":8174333}]}]}
{"op":"mcm","clk":"1001456907","pt":1580636256687,"mc":[{"id":"1.168224329","rc":[{"batb":[[0,1.6,42.22],[1,1.57,31.57],[2,1.56,494.03]],"batl":[[1,1.66,497.4],[2,1.7,22.25]],"ltp":1.76,"tv":4052.35,"id":8174333}]}]}
{"op":"mcm","clk":"1001457204","pt":1580636263405,"mc":[{"id":"1.168224329","rc":[{"batb":[[2,1.55,602.5]],"ltp":1.76,"tv":4052.35,"id":8174333}]}]}
{"op":"mcm","clk":"1001457345","pt":1580636265985,"mc":[{"id":"1.168224329","rc":[{"batb":[[0,2.6,330.13],[1,2.42,69.32],[2,2.36,4.43]],"batl":[[1,2.78,8.64],[2,2.84,520.02]],"ltp":2.42,"tv":2162.4,"id":6498878},{"trd":[[1.6,556.56]],"batb":[[0,1.57,31.57],[1,1.55,2054.11],[2,1.54,467.64]],"batl":[[0,1.6,2080.85],[1,1.61,391.74],[2,1.64,480.59]],"ltp":1.6,"tv":4136.79,"id":8174333}],"tv":6299.19}]}
{"op":"mcm","clk":"1001457406","pt":1580636267322,"mc":[{"id":"1.168224329","rc":[{"trd":[[2.76,24.01]],"batb":[[0,2.76,25.21],[1,2.62,53.82],[2,2.6,330.13]],"batl":[[0,2.78,8.64],[1,2.84,520.02],[2,2.88,21.85]],"ltp":2.76,"tv":2186.39,"id":6498878},{"trd":[[1.57,32.82]],"batb":[[0,1.55,2054.11],[1,1.54,544.94],[2,1.5,152.41]],"ltp":1.57,"tv":4168.36,"id":8174333}],"tv":6354.76}]}
{"op":"mcm","clk":"1001457613","pt":1580636271401,"mc":[{"id":"1.168224329","rc":[{"batl":[[2,1.66,42.01]],"ltp":1.57,"tv":4168.36,"id":8174333}]}]}
{"op":"mcm","clk":"1001457692","pt":1580636273046,"mc":[{"id":"1.168224329","rc":[{"batb":[[2,2.6,334.37]],"batl":[[1,2.82,3.25],[2,2.84,520.02]],"ltp":2.76,"tv":2186.39,"id":6498878},{"batb":[[0,1.55,2082.9],[1,1.54,577.56]],"batl":[[2,1.62,25.75]],"ltp":1.57,"tv":4168.36,"id":8174333}]}]}
{"op":"mcm","clk":"1001457835","pt":1580636276346,"mc":[{"id":"1.168224329","rc":[{"trd":[[2.76,43.05]],"batb":[[0,2.62,53.82],[1,2.6,4.24],[2,2.56,4.33]],"batl":[[0,2.82,3.25],[1,2.86,3.39],[2,1000,0.02]],"ltp":2.76,"tv":2205.44,"id":6498878},{"batb":[[0,1.55,28.79],[1,1.54,32.62],[2,1.47,164.6]],"batl":[[0,1.62,25.75],[1,1.64,26.43],[2,1.7,22.25]],"ltp":1.57,"tv":4168.36,"id":8174333}],"tv":6373.8}]}
{"op":"mcm","clk":"1001457869","pt":1580636277119,"mc":[{"id":"1.168224329","rc":[{"batb":[[1,2.56,4.33],[2,2.42,3.94]],"batl":[[0,2.86,3.39],[1,1000,0.02],[2,1000,0]],"ltp":2.76,"tv":2205.44,"id":6498878},{"batb":[[0,1.54,32.62],[1,1.47,164.6],[2,1.34,756.18]],"batl":[[0,1.64,26.43],[1,1.7,22.25],[2,1.73,23.87]],"ltp":1.57,"tv":4168.36,"id":8174333}]}]}
{"op":"mcm","clk":"1001457978","pt":1580636279336,"mc":[{"id":"1.168224329","rc":[{"batb":[[0,2.58,55.23]],"ltp":2.76,"tv":2205.44,"id":6498878},{"batb":[[1,1.53,469.26],[2,1.52,491.59]],"batl":[[0,1.64,540.98],[1,1.65,359.82],[2,1.7,22.25]],"ltp":1.57,"tv":4168.36,"id":8174333}]}]}
{"op":"mcm","clk":"1001458140","pt":1580636283140,"mc":[{"id":"1.168224329","rc":[{"trd":[[2.58,48.74]],"batb":[[0,2.6,4.24],[1,2.58,52.96],[2,2.56,4.33]],"batl":[[0,2.82,3.25],[1,2.86,3.39],[2,1000,0.02]],"ltp":2.58,"tv":2209.98,"id":6498878},{"batb":[[0,1.55,30.19],[1,1.54,32.62],[2,1.53,469.26]],"batl":[[0,1.62,27.75],[1,1.64,540.98],[2,1.65,359.82]],"ltp":1.57,"tv":4168.36,"id":8174333}],"tv":6378.35}]}
{"op":"mcm","clk":"1001458184","pt":1580636284234,"mc":[{"id":"1.168224329","rc":[{"batb":[[0,2.58,52.96],[1,2.56,4.33],[2,2.42,3.94]],"batl":[[0,2.86,3.39],[1,1000,0.02],[2,1000,0]],"ltp":2.58,"tv":2209.98,"id":6498878},{"batb":[[0,1.54,32.62],[1,1.53,469.26],[2,1.52,491.59]],"batl":[[0,1.64,540.98],[1,1.65,359.82],[2,1.7,22.25]],"ltp":1.57,"tv":4168.36,"id":8174333}]}]}
{"op":"mcm","clk":"1001458301","pt":1580636287325,"mc":[{"id":"1.168224329","rc":[{"batb":[[0,2.6,4.24],[1,2.58,52.96],[2,2.56,4.33]],"batl":[[0,2.82,3.75],[1,2.86,3.39],[2,1000,0.02]],"ltp":2.58,"tv":2209.98,"id":6498878},{"batb":[[0,1.55,35.39],[1,1.54,32.62],[2,1.53,469.26]],"batl":[[0,1.62,29.25],[1,1.64,540.98],[2,1.65,359.82]],"ltp":1.57,"tv":4168.36,"id":8174333}]}]}
{"op":"mcm","clk":"1001458333","pt":1580636288371,"mc":[{"id":"1.168224329","rc":[{"batb":[[0,2.58,52.96],[1,2.56,4.33],[2,2.42,3.94]],"batl":[[0,2.86,3.39],[1,1000,0.02],[2,1000,0]],"ltp":2.58,"tv":2209.98,"id":6498878},{"batb":[[0,1.54,32.62],[1,1.53,469.26],[2,1.52,491.59]],"batl":[[0,1.64,540.98],[1,1.65,359.82],[2,1.7,22.25]],"ltp":1.57,"tv":4168.36,"id":8174333}]}]}
{"op":"mcm","clk":"1001458682","pt":1580636297352,"mc":[{"id":"1.168224329","rc":[{"batb":[[0,2.6,4.24],[1,2.58,52.96],[2,2.56,4.33]],"batl":[[0,2.82,3.25],[1,2.86,3.39],[2,1000,0.02]],"ltp":2.58,"tv":2209.98,"id":6498878},{"batb":[[0,1.55,33.19],[1,1.54,32.62],[2,1.53,469.26]],"batl":[[0,1.62,29.25],[1,1.64,540.98],[2,1.65,359.82]],"ltp":1.57,"tv":4168.36,"id":8174333}]}]}
{"op":"mcm","clk":"1001458694","pt":1580636297662,"mc":[{"id":"1.168224329","rc":[{"batb":[[0,2.58,52.96],[1,2.56,4.33],[2,2.42,3.94]],"batl":[[0,2.86,3.39],[1,1000,0.02],[2,1000,0]],"ltp":2.58,"tv":2209.98,"id":6498878},{"batb":[[0,1.54,32.62],[1,1.53,469.26],[2,1.52,491.59]],"batl":[[0,1.64,540.98],[1,1.65,359.82],[2,1.7,22.25]],"ltp":1.57,"tv":4168.36,"id":8174333}]}]}
{"op":"mcm","clk":"1001458736","pt":1580636298637,"mc":[{"id":"1.168224329","rc":[{"batb":[[2,1.8,75.72]],"ltp":2.58,"tv":2209.98,"id":6498878},{"batl":[[0,1.64,26.43],[1,1.8,3.36],[2,2,151.45]],"ltp":1.57,"tv":4168.36,"id":8174333}]}]}
{"op":"mcm","clk":"1001458850","pt":1580636301369,"mc":[{"id":"1.168224329","rc":[{"batb":[[0,2.68,4.36],[1,2.58,52.96],[2,2.56,4.33]],"batl":[[1,2.88,6.13],[2,2.92,350.52]],"ltp":2.58,"tv":2209.98,"id":6498878},{"batb":[[1,1.53,1939.85]],"batl":[[0,1.56,16.33],[1,1.58,1424.05],[2,1.59,21.89]],"ltp":1.57,"tv":4168.36,"id":8174333}]}]}
{"op":"mcm","clk":"1001458885","pt":1580636302243,"mc":[{"id":"1.168224329","rc":[{"batb":[[0,2.84,43.35],[1,2.68,55.03],[2,2.58,52.96]],"ltp":2.58,"tv":2209.98,"id":6498878},{"batl":[[1,1.57,497.97],[2,1.58,1844.58]],"ltp":1.57,"tv":4168.36,"id":8174333}]}]}
{"op":"mcm","clk":"1001458934","pt":1580636303272,"mc":[{"id":"1.168224329","rc":[{"batb":[[1,2.74,2.67],[2,2.68,55.03]],"ltp":2.58,"tv":2209.98,"id":6498878}]}]}
{"op":"mcm","clk":"1001459106","pt":1580636306459,"mc":[{"id":"1.168224329","rc":[{"batb":[[1,2.68,55.03],[2,2.62,25.21]],"ltp":2.58,"tv":2209.98,"id":6498878}]}]}
{"op":"mcm","clk":"1001459301","pt":1580636310674,"mc":[{"id":"1.168224329","rc":[{"batb":[[1,2.68,4.36],[2,2.66,50.75]],"ltp":2.58,"tv":2209.98,"id":6498878}]}]}
{"op":"mcm","clk":"1001459536","pt":1580636317059,"mc":[{"id":"1.168224329","rc":[{"trd":[[2.84,7.65]],"batb":[[0,2.84,35.7]],"ltp":2.84,"tv":2217.63,"id":6498878},{"trd":[[1.55,14.02]],"ltp":1.55,"tv":4182.38,"id":8174333}],"tv":6400.01}]}
{"op":"mcm","clk":"1001459811","pt":1580636323268,"mc":[{"id":"1.168224329","rc":[{"batl":[[0,1.55,13.51],[1,1.56,16.33],[2,1.57,497.97]],"ltp":1.55,"tv":4182.38,"id":8174333}]}]}
{"op":"mcm","clk":"1001460484","pt":1580636339123,"mc":[{"id":"1.168224329","rc":[{"batb":[[1,1.53,1470.59],[2,1.5,84.02]],"batl":[[0,1.56,16.33],[1,1.58,1424.05],[2,1.59,21.89]],"ltp":1.55,"tv":4182.38,"id":8174333}]}]}
{"op":"mcm","clk":"1001460627","pt":1580636342327,"mc":[{"id":"1.168224329","rc":[{"batl":[[1,2.98,21],[2,1000,0.02]],"ltp":2.84,"tv":2217.63,"id":6498878},{"trd":[[1.54,27.02]],"batb":[[0,1.54,19.11],[1,1.5,84.02],[2,1.49,160.28]],"batl":[[0,1.59,21.89],[1,1.61,42.01],[2,1.62,609.57]],"ltp":1.54,"tv":4209.4,"id":8174333}],"tv":6427.03}]}
{"op":"mcm","clk":"1001460641","pt":1580636342692,"mc":[{"id":"1.168224329","rc":[{"batb":[[0,2.66,50.75],[1,2.62,25.21],[2,2.56,4.33]],"batl":[[0,2.98,21],[1,1000,0.02],[2,1000,0]],"ltp":2.84,"tv":2217.63,"id":6498878},{"batb":[[0,1.5,84.02],[1,1.46,973.19],[2,1.45,600.42]],"batl":[[0,1.61,42.01],[1,1.62,609.57],[2,1.63,375.25]],"ltp":1.54,"tv":4209.4,"id":8174333}]}]}
{"op":"mcm","clk":"1001460712","pt":1580636344390,"mc":[{"id":"1.168224329","rc":[{"batb":[[1,2.56,4.33],[2,2.02,466.31]],"batl":[[0,1000,0.02],[1,1000,0]],"ltp":2.84,"tv":2217.63,"id":6498878},{"batb":[[0,1.46,973.19],[1,1.45,600.42],[2,1.43,190.96]],"batl":[[0,1.62,609.57],[1,1.63,375.25],[2,1.64,26.43]],"ltp":1.54,"tv":4209.4,"id":8174333}]}]}
{"op":"mcm","clk":"1001460789","pt":1580636346201,"mc":[{"id":"1.168224329","rc":[{"batb":[[0,2.64,51.85]],"batl":[[0,3.2,2.68],[1,1000,0.02]],"ltp":2.84,"tv":2217.63,"id":6498878},{"batb":[[0,1.46,40.88],[1,1.43,187.5],[2,1.38,756.18]],"batl":[[0,1.5,4.2],[1,1.64,26.43],[2,1.8,3.36]],"ltp":1.54,"tv":4209.4,"id":8174333}]}]}
{"op":"mcm","clk":"1001460920","pt":1580636349190,"mc":[{"id":"1.168224329","rc":[{"trd":[[3,2.1]],"ltp":3.0,"tv":2219.73,"id":6498878},{"trd":[[1.5,4.2]],"batb":[[0,1.51,841.43],[1,1.5,520.61],[2,1.46,40.88]],"batl":[[0,1.56,664.88],[1,1.57,429.67],[2,1.64,26.43]],"ltp":1.5,"tv":4213.6,"id":8174333}],"tv":6433.34}]}
{"op":"mcm","clk":"1001461129","pt":1580636352293,"mc":[{"id":"1.168224329","rc":[{"batb":[[1,2.62,6.04],[2,2.56,4.33]],"batl":[[0,3.1,3.15],[1,3.2,2.68],[2,1000,0.02]],"ltp":3.0,"tv":2219.73,"id":6498878},{"batb":[[0,1.48,35.51],[1,1.46,40.88],[2,1.43,187.5]],"batl":[[0,1.61,31.5],[1,1.64,26.43],[2,1.8,3.36]],"ltp":1.5,"tv":4213.6,"id":8174333}]}]}
{"op":"mcm","clk":"1001461141","pt":1580636352499,"mc":[{"id":"1.168224329","rc":[{"batb":[[1,2.56,4.33],[2,2.02,466.31]],"batl":[[0,3.2,2.68],[1,1000,0.02],[2,1000,0]],"ltp":3.0,"tv":2219.73,"id":6498878},{"batb":[[0,1.46,40.88],[1,1.43,187.5],[2,1.38,756.18]],"batl":[[0,1.64,26.43],[1,1.8,3.36],[2,1.98,151.45]],"ltp":1.5,"tv":4213.6,"id":8174333}]}]}
{"op":"mcm","clk":"1001461228","pt":1580636354404,"mc":[{"id":"1.168224329","rc":[{"batb":[[0,1.46,1014.07],[1,1.45,600.42],[2,1.43,187.5]],"batl":[[0,1.62,609.57],[1,1.63,375.25],[2,1.64,26.43]],"ltp":1.5,"tv":4213.6,"id":8174333}]}]}
{"op":"mcm","clk":"1001461555","pt":1580636360854,"mc":[{"id":"1.168224329","rc":[{"batb":[[2,1.8,75.72]],"ltp":3.0,"tv":2219.73,"id":6498878}]}]}
{"op":"mcm","clk":"1001461640","pt":1580636363222,"mc":[{"id":"1.168224329","rc":[{"batb":[[0,1.46,40.88],[1,1.43,187.5],[2,1.25,378.62]],"ltp":1.5,"tv":4213.6,"id":8174333}]}]}
{"op":"mcm","clk":"1001461663","pt":1580636363947,"mc":[{"id":"1.168224329","rc":[{"trd":[[3.2,0.2]],"batl":[[0,3.2,2.58]],"ltp":3.2,"tv":2219.93,"id":6498878}],"tv":6433.54}]}
{"op":"mcm","clk":"1001461747","pt":1580636366119,"mc":[{"id":"1.168224329","rc":[{"batl":[[0,2.72,9.41],[1,2.78,550.96],[2,2.86,74.74]],"ltp":3.2,"tv":2219.93,"id":6498878},{"batb":[[0,1.57,605.72],[1,1.56,445.01],[2,1.52,122.44]],"batl":[[0,1.62,627.05]],"ltp":1.5,"tv":4213.6,"id":8174333}]}]}
{"op":"mcm","clk":"1001461801","pt":1580636367353,"mc":[{"id":"1.168224329","rc":[{"batb":[[1,2.58,2.61],[2,2.56,4.33]],"ltp":3.2,"tv":2219.93,"id":6498878},{"batb":[[1,1.56,447.7],[2,1.55,138.56]],"ltp":1.5,"tv":4213.6,"id":8174333}]}]}
{"op":"mcm","clk":"1001462026","pt":1580636372621,"mc":[{"id":"1.168224329","rc":[{"batb":[[1,2.6,5.99],[2,2.58,8.67]],"batl":[[2,2.82,3.25]],"ltp":3.2,"tv":2219.93,"id":6498878},{"batb":[[2,1.55,174.35]],"batl":[[0,1.62,656.3],[1,1.63,403.75]],"ltp":1.5,"tv":4213.6,"id":8174333}]}]}
{"op":"mcm","clk":"1001462392","pt":1580636383159,"mc":[{"id":"1.168224329","rc":[{"batb":[[0,2.58,8.67],[1,2.52,85.9],[2,1.8,75.72]],"batl":[[0,2.88,21.85],[1,2.9,3.25],[2,3.2,2.58]],"ltp":3.2,"tv":2219.93,"id":6498878},{"batb":[[0,1.56,2.69],[1,1.54,77.3],[2,1.53,37.33]],"batl":[[0,1.63,28.5],[1,1.66,42.01],[2,1.8,3.36]],"ltp":1.5,"tv":4213.6,"id":8174333}]}]}
{"op":"mcm","clk":"1001462520","pt":1580636384562,"mc":[{"id":"1.168224329","rc":[{"batb":[[1,2.52,59.01]],"batl":[[0,2.9,3.25],[1,3.2,2.58],[2,1000,0.02]],"ltp":3.2,"tv":2219.93,"id":6498878},{"batb":[[1,1.53,37.33],[2,1.48,163.34]],"batl":[[1,1.8,3.36],[2,1.98,151.45]],"ltp":1.5,"tv":4213.6,"id":8174333}]}]}
{"op":"mcm","clk":"1001462601","pt":1580636386372,"mc":[{"id":"1.168224329","rc":[{"batb":[[0,2.6,5.99],[1,2.58,8.67],[2,2.52,59.01]],"batl":[[0,2.82,3.25],[1,2.9,3.25],[2,3.2,2.58]],"ltp":3.2,"tv":2219.93,"id":6498878},{"batb":[[1,1.55,29.39],[2,1.53,37.33]],"batl":[[0,1.62,29.25],[1,1.63,28.5],[2,1.66,532.14]],"ltp":1.5,"tv":4213.6,"id":8174333}]}]}
{"op":"mcm","clk":"1001462620","pt":1580636386982,"mc":[{"id":"1.168224329","rc":[{"batb":[[0,2.58,8.67],[1,2.52,59.01],[2,1.8,75.72]],"batl":[[0,2.9,3.25],[1,3.2,2.58],[2,1000,0.02]],"ltp":3.2,"tv":2219.93,"id":6498878},{"batb":[[1,1.53,37.33],[2,1.49,159.72]],"batl":[[0,1.63,28.5],[1,1.8,3.36],[2,1.98,151.45]],"ltp":1.5,"tv":4213.6,"id":8174333}]}]}
{"op":"mcm","clk":"1001462741","pt":1580636390241,"mc":[{"id":"1.168224329","rc":[{"batl":[[0,2.64,100],[1,2.9,3.25],[2,3.2,2.58]],"ltp":3.2,"tv":2219.93,"id":6498878},{"batb":[[0,1.56,542.54],[1,1.55,455.82],[2,1.53,37.33]],"batl":[[0,1.61,713.65],[1,1.62,383.13],[2,1.63,28.5]],"ltp":1.5,"tv":4213.6,"id":8174333}]}]}
{"op":"mcm","clk":"1001462806","pt":1580636392150,"mc":[{"id":"1.168224329","rc":[{"batl":[[0,2.9,3.25],[1,3.2,2.58],[2,1000,0.02]],"ltp":3.2,"tv":2219.93,"id":6498878}]}]}
{"op":"mcm","clk":"1001462834","pt":1580636393071,"mc":[{"id":"1.168224329","rc":[{"batb":[[0,2.6,5.99],[1,2.58,8.67],[2,2.52,59.01]],"batl":[[0,2.82,2.97],[1,2.9,3.25],[2,3.2,2.58]],"ltp":3.2,"tv":2219.93,"id":6498878},{"batb":[[1,1.55,489.41]],"batl":[[1,1.62,412.38]],"ltp":1.5,"tv":4213.6,"id":8174333}]}]}
{"op":"mcm","clk":"1001462866","pt":1580636394152,"mc":[{"id":"1.168224329","rc":[{"batb":[[0,1.56,2.69],[1,1.55,33.59]],"batl":[[0,1.62,29.25],[1,1.63,28.5],[2,1.8,3.36]],"ltp":1.5,"tv":4213.6,"id":8174333}]}]}
{"op":"mcm","clk":"1001462886","pt":1580636394773,"mc":[{"id":"1.168224329","rc":[{"batb":[[0,2.58,6.06],[1,2.52,59.01],[2,1.8,75.72]],"batl":[[0,2.9,3.25],[1,3.2,2.58],[2,1000,0.02]],"ltp":3.2,"tv":2219.93,"id":6498878},{"batb":[[0,1.53,37.33],[1,1.49,159.72],[2,1.46,40.88]],"batl":[[0,1.63,28.5],[1,1.8,3.36],[2,1.98,151.45]],"ltp":1.5,"tv":4213.6,"id":8174333}]}]}
{"op":"mcm","clk":"1001462973","pt":1580636397191,"mc":[{"id":"1.168224329","rc":[{"batb":[[1,1.51,824.09],[2,1.5,520.51]],"batl":[[1,1.66,532.14],[2,1.68,679.87]],"ltp":1.5,"tv":4213.6,"id":8174333}]}]}
{"op":"mcm","clk":"1001463000","pt":1580636397870,"mc":[{"id":"1.168224329","rc":[{"batl":[[1,1.8,3.36],[2,1.98,151.45]],"ltp":1.5,"tv":4213.6,"id":8174333}]}]}
{"op":"mcm","clk":"1001463096","pt":1580636400400,"mc":[{"id":"1.168224329","rc":[{"batb":[[0,2.88,7.2],[1,2.78,6.16],[2,2.58,6.06]],"batl":[[1,3,5.22],[2,3.05,443.99]],"ltp":3.2,"tv":2219.93,"id":6498878},{"batb":[[1,1.51,2314.16],[2,1.5,530.95]],"batl":[[0,1.55,1451.61],[1,1.56,32.17],[2,1.58,985.92]],"ltp":1.5,"tv":4213.6,"id":8174333}]}]}
{"op":"mcm","clk":"1001463147","pt":1580636401376,"mc":[{"id":"1.168224329","rc":[{"batb":[[1,2.82,43.67],[2,2.78,6.16]],"batl":[[2,3.05,464.15]],"ltp":3.2,"tv":2219.93,"id":6498878},{"batl":[[1,1.56,713.37],[2,1.57,429.59]],"ltp":1.5,"tv":4213.6,"id":8174333}]}]}
{"op":"mcm","clk":"1001463195","pt":1580636402463,"mc":[{"id":"1.168224329","rc":[{"batb":[[2,2.8,2.59]],"ltp":3.2,"tv":2219.93,"id":6498878}]}]}
{"op":"mcm","clk":"1001463273","pt":1580636404366,"mc":[{"id":"1.168224329","rc":[{"trd":[[2.88,14.08]],"batb":[[0,2.82,43.83],[1,2.8,2.59],[2,2.78,6.16]],"ltp":2.88,"tv":2234.01,"id":6498878}],"tv":6447.62}]}
{"op":"mcm","clk":"1001463400","pt":1580636407303,"mc":[{"id":"1.168224329","rc":[{"batb":[[1,1.51,2808.19]],"batl":[[2,1.57,910.18]],"ltp":1.5,"tv":4213.6,"id":8174333}]}]}
{"op":"mcm","clk":"1001463456","pt":1580636408898,"mc":[{"id":"1.168224329","rc":[{"trd":[[2.88,14.4]],"batb":[[0,2.82,43.67]],"batl":[[0,2.88,99.84],[1,2.9,3.25],[2,3,5.22]],"ltp":2.88,"tv":2234.33,"id":6498878}],"tv":6447.94}]}
{"op":"mcm","clk":"1001463631","pt":1580636413286,"mc":[{"id":"1.168224329","rc":[{"batl":[[1,3.05,20.16],[2,3.2,2.58]],"ltp":2.88,"tv":2234.33,"id":6498878},{"batb":[[0,1.51,494.03],[1,1.49,673.16],[2,1.48,87.38]],"batl":[[0,1.56,32.17],[1,1.57,480.59],[2,1.59,539.41]],"ltp":1.5,"tv":4213.6,"id":8174333}]}]}
{"op":"mcm","clk":"1001463678","pt":1580636414115,"mc":[{"id":"1.168224329","rc":[{"batb":[[0,2.8,2.59],[1,2.66,82.44],[2,2.6,5.64]],"batl":[[0,3.05,20.16],[1,3.2,2.58],[2,3.25,2.3]],"ltp":2.88,"tv":2234.33,"id":6498878},{"batb":[[1,1.49,513.44]],"batl":[[0,1.57,480.59],[1,1.59,539.41],[2,1.6,30.01]],"ltp":1.5,"tv":4213.6,"id":8174333}]}]}
{"op":"mcm","clk":"1001463704","pt":1580636414521,"mc":[{"id":"1.168224329","rc":[{"batb":[[1,2.66,57.24]],"batl":[[0,3.2,2.58],[1,3.25,2.3],[2,3.35,2.5]],"ltp":2.88,"tv":2234.33,"id":6498878},{"batb":[[2,1.46,40.88]],"batl":[[1,1.59,497.4]],"ltp":1.5,"tv":4213.6,"id":8174333}]}]}
{"op":"mcm","clk":"1001463956","pt":1580636420382,"mc":[{"id":"1.168224329","rc":[{"trd":[[2.82,28.95]],"batl":[[0,2.82,12.13],[1,3.2,2.58],[2,3.25,2.3]],"ltp":2.82,"tv":2263.28,"id":6498878},{"trd":[[1.54,37.27]],"ltp":1.54,"tv":4223.85,"id":8174333}],"tv":6487.14}]}
{"op":"mcm","clk":"1001463963","pt":1580636420486,"mc":[{"id":"1.168224329","rc":[{"trd":[[2.82,41.09]],"batl":[[0,3.2,2.58],[1,3.25,2.3],[2,3.35,2.5]],"ltp":2.82,"tv":2275.42,"id":6498878},{"trd":[[1.54,59.49]],"batb":[[1,1.5,592.12],[2,1.49,1046.81]],"batl":[[0,1.54,481.85],[1,1.55,451.71],[2,1.57,480.59]],"ltp":1.54,"tv":4246.07,"id":8174333}],"tv":6521.49}]}
{"op":"mcm","clk":"1001464058","pt":1580636422501,"mc":[{"id":"1.168224329","rc":[{"batb":[[1,1.49,513.44],[2,1.46,40.88]],"batl":[[0,1.57,480.59],[1,1.59,497.4],[2,1.6,30.01]],"ltp":1.54,"tv":4246.07,"id":8174333}]}]}
{"op":"mcm","clk":"1001464457","pt":1580636430304,"mc":[{"id":"1.168224329","rc":[{"batb":[[0,2.66,57.24],[1,2.6,5.64],[2,2.58,6.06]],"ltp":2.82,"tv":2275.42,"id":6498878},{"batb":[[1,1.49,510.84]],"ltp":1.54,"tv":4246.07,"id":8174333}]}]}
{"op":"mcm","clk":"1001464629","pt":1580636433819,"mc":[{"id":"1.168224329","rc":[{"batb":[[0,2.66,51.46]],"ltp":2.82,"tv":2275.42,"id":6498878},{"batl":[[0,1.61,453.54],[1,1.62,413.41],[2,1.63,28.5]],"ltp":1.54,"tv":4246.07,"id":8174333}]}]}
{"op":"mcm","clk":"1001464720","pt":1580636436339,"mc":[{"id":"1.168224329","rc":[{"batl":[[0,2.72,6.55],[1,2.84,524.23],[2,3.2,2.58]],"ltp":2.82,"tv":2275.42,"id":6498878},{"batb":[[0,1.56,1442.31],[1,1.52,119.49],[2,1.51,494.03]],"batl":[[0,1.61,1851.06],[1,1.62,435.39]],"ltp":1.54,"tv":4246.07,"id":8174333}]}]}
{"op":"mcm","clk":"1001464756","pt":1580636437313,"mc":[{"id":"1.168224329","rc":[{"batb":[[0,1.56,2256.41],[1,1.55,596.59]],"ltp":1.54,"tv":4246.07,"id":8174333}]}]}
{"op":"mcm","clk":"1001464782","pt":1580636437930,"mc":[{"id":"1.168224329","rc":[{"batb":[[1,2.64,2.58],[2,2.6,5.64]],"batl":[[2,2.92,21.85]],"ltp":2.82,"tv":2275.42,"id":6498878},{"batb":[[2,1.54,2.62]],"ltp":1.54,"tv":4246.07,"id":8174333}]}]}
{"op":"mcm","clk":"1001464990","pt":1580636442916,"mc":[{"id":"1.168224329","rc":[{"batl":[[1,2.84,525.11]],"ltp":2.82,"tv":2275.42,"id":6498878}]}]}
{"op":"mcm","clk":"1001465011","pt":1580636443442,"mc":[{"id":"1.168224329","rc":[{"batl":[[2,2.86,3.25]],"ltp":2.82,"tv":2275.42,"id":6498878},{"batb":[[2,1.54,32.74]],"ltp":1.54,"tv":4246.07,"id":8174333}]}]}
{"op":"mcm","clk":"1001465431","pt":1580636452822,"mc":[{"id":"1.168224329","rc":[{"trd":[[2.72,6.21]],"batl":[[0,2.72,4.13]],"ltp":2.72,"tv":2277.84,"id":6498878},{"trd":[[1.58,211.48]],"ltp":1.58,"tv":4250.24,"id":8174333}],"tv":6528.08}]}
{"op":"mcm","clk":"1001465568","pt":1580636456233,"mc":[{"id":"1.168224329","rc":[{"batb":[[0,2.64,2.58],[1,2.58,6.06],[2,2.56,26.89]],"batl":[[0,2.92,22.73],[1,2.94,3.08],[2,3.2,2.58]],"ltp":2.72,"tv":2277.84,"id":6498878},{"batb":[[0,1.54,2.62],[1,1.53,78.98],[2,1.52,37.24]],"batl":[[0,1.63,28.5],[1,1.64,42.01],[2,1.7,2.27]],"ltp":1.58,"tv":4250.24,"id":8174333}]}]}
{"op":"mcm","clk":"1001465585","pt":1580636456545,"mc":[{"id":"1.168224329","rc":[{"batb":[[2,2.52,59.64]],"batl":[[0,2.94,3.96],[1,3.2,2.58],[2,3.25,2.3]],"ltp":2.72,"tv":2277.84,"id":6498878},{"batb":[[1,1.52,37.24],[2,1.48,165.7]],"batl":[[1,1.7,2.27],[2,1.8,3.36]],"ltp":1.58,"tv":4250.24,"id":8174333}]}]}
{"op":"mcm","clk":"1001465678","pt":1580636459268,"mc":[{"id":"1.168224329","rc":[{"batb":[[1,2.6,5.99],[2,2.58,6.06]],"ltp":2.72,"tv":2277.84,"id":6498878},{"batb":[[2,1.5,700.62]],"batl":[[0,1.62,29.25],[1,1.63,28.5],[2,1.66,522.08]],"ltp":1.58,"tv":4250.24,"id":8174333}]}]}
{"op":"mcm","clk":"1001465723","pt":1580636460144,"mc":[{"id":"1.168224329","rc":[{"batb":[[1,2.58,6.06],[2,2.52,59.64]],"ltp":2.72,"tv":2277.84,"id":6498878},{"batl":[[0,1.63,28.5],[1,1.7,2.27],[2,1.8,3.36]],"ltp":1.58,"tv":4250.24,"id":8174333}]}]}
{"op":"mcm","clk":"1001465786","pt":1580636461480,"mc":[{"id":"1.168224329","rc":[{"batb":[[0,1.52,37.24],[1,1.5,700.62],[2,1.49,533.99]],"ltp":1.58,"tv":4250.24,"id":8174333}]}]}
{"op":"mcm","clk":"1001465879","pt":1580636463184,"mc":[{"id":"1.168224329","rc":[{"trd":[[2.8,0.88],[2.86,3.39]],"batb":[[0,2.8,5.98],[1,2.64,2.58],[2,2.58,6.06]],"batl":[[0,2.94,3.08]],"ltp":2.86,"tv":2282.11,"id":6498878},{"trd":[[1.52,21.24],[1.53,6.34],[1.54,126.73],[1.55,15.62]],"batb":[[0,1.52,26.62],[1,1.5,2200.62]],"batl":[[0,1.54,1861.69],[1,1.55,484.73],[2,1.62,2632.41]],"ltp":1.52,"tv":4346.66,"id":8174333}],"tv":6628.77}]}
{"op":"mcm","clk":"1001465919","pt":1580636464168,"mc":[{"id":"1.168224329","rc":[{"batb":[[0,2.88,41.7],[1,2.8,5.98],[2,2.72,24.37]],"batl":[[1,3.15,19.32],[2,3.2,2.58]],"ltp":2.86,"tv":2282.11,"id":6498878},{"batl":[[2,1.57,42.01]],"ltp":1.52,"tv":4346.66,"id":8174333}]}]}
{"op":"mcm","clk":"1001465995","pt":1580636466275,"mc":[{"id":"1.168224329","rc":[{"batl":[[1,3.05,9.06],[2,3.15,19.32]],"ltp":2.86,"tv":2282.11,"id":6498878},{"trd":[[1.52,55.16]],"batb":[[0,1.52,9.66]],"ltp":1.52,"tv":4380.58,"id":8174333}],"tv":6662.69}]}
{"op":"mcm","clk":"1001466253","pt":1580636473176,"mc":[{"id":"1.168224329","rc":[{"batl":[[1,3.15,19.32],[2,3.2,2.58]],"ltp":2.86,"tv":2282.11,"id":6498878}]}]}
{"op":"mcm","clk":"1001466397","pt":1580636476275,"mc":[{"id":"1.168224329","rc":[{"trd":[[2.92,26.04]],"ltp":2.92,"tv":2308.15,"id":6498878},{"trd":[[1.52,124.52]],"batb":[[0,1.5,2200.62],[1,1.49,533.99],[2,1.48,165.7]],"batl":[[0,1.52,40.3],[1,1.54,1861.69],[2,1.55,484.73]],"ltp":1.52,"tv":4449.94,"id":8174333}],"tv":6758.1}]}
{"op":"mcm","clk":"1001466518","pt":1580636477263,"mc":[{"id":"1.168224329","rc":[{"batb":[[0,2.72,24.37],[1,2.66,51.14],[2,2.58,6.06]],"batl":[[0,3.15,19.32],[1,3.65,2.1],[2,4.2,148.03]],"ltp":2.92,"tv":2308.15,"id":6498878},{"batb":[[0,1.47,89.06],[1,1.39,214.41],[2,1.38,44.96]],"batl":[[1,1.57,42.01],[2,1.63,28.5]],"ltp":1.52,"tv":4449.94,"id":8174333}]}]}
{"op":"mcm","clk":"1001466631","pt":1580636479378,"mc":[{"id":"1.168224329","rc":[{"trd":[[2.92,34.44]],"batb":[[0,2.66,51.14],[1,2.58,6.06],[2,2.04,394.09]],"batl":[[0,3.45,2.7],[2,3.75,2.02]],"ltp":2.92,"tv":2316.55,"id":6498878},{"trd":[[1.52,140.66]],"batb":[[0,1.41,46.89]],"batl":[[0,1.52,24.16],[1,1.56,22.27]],"ltp":1.52,"tv":4466.08,"id":8174333}],"tv":6782.64}]}
{"op":"mcm","clk":"1001466672","pt":1580636480303,"mc":[{"id":"1.168224329","rc":[{"batl":[[0,3.4,2.59]],"ltp":2.92,"tv":2316.55,"id":6498878},{"batb":[[0,1.42,45.44]],"batl":[[1,1.63,28.5],[2,1.71,2.27]],"ltp":1.52,"tv":4466.08,"id":8174333}]}]}
{"op":"mcm","clk":"1001466703","pt":1580636481277,"mc":[{"id":"1.168224329","rc":[{"batl":[[0,3.65,2.1],[1,3.75,2.02],[2,4.2,148.03]],"ltp":2.92,"tv":2316.55,"id":6498878},{"batb":[[0,1.39,214.41],[1,1.38,44.96],[2,1.37,52.77]],"ltp":1.52,"tv":4466.08,"id":8174333}]}]}
{"op":"mcm","clk":"1001466771","pt":1580636483282,"mc":[{"id":"1.168224329","rc":[{"batb":[[0,2.9,9.86],[1,2.66,51.14],[2,2.58,6.06]],"batl":[[0,3,11.2],[1,3.65,2.1],[2,3.75,2.02]],"ltp":2.92,"tv":2316.55,"id":6498878},{"batb":[[0,1.5,10],[1,1.39,214.41],[2,1.38,44.96]],"batl":[[1,1.53,10.84],[2,1.63,28.5]],"ltp":1.52,"tv":4466.08,"id":8174333}]}]}
{"op":"mcm","clk":"1001466800","pt":1580636484060,"mc":[{"id":"1.168224329","rc":[{"batb":[[0,2.66,51.14],[1,2.58,6.06],[2,2.04,394.09]],"batl":[[0,3.65,2.1],[1,3.75,2.02],[2,4.2,148.03]],"ltp":2.92,"tv":2316.55,"id":6498878},{"batb":[[0,1.48,796.85],[1,1.47,565.31],[2,1.39,214.41]],"batl":[[0,1.52,425.59],[1,1.53,475.23]],"ltp":1.52,"tv":4466.08,"id":8174333}]}]}
{"op":"mcm","clk":"1001466900","pt":1580636485976,"mc":[{"id":"1.168224329","rc":[{"batb":[[0,1.39,214.41],[1,1.38,44.96],[2,1.37,52.77]],"batl":[[0,1.52,24.16],[1,1.63,28.5],[2,1.71,2.27]],"ltp":1.52,"tv":4466.08,"id":8174333}]}]}
{"op":"mcm","clk":"1001467069","pt":1580636488961,"mc":[{"id":"1.168224329","rc":[{"batb":[[0,1.41,902.21],[1,1.4,700.08],[2,1.39,214.41]],"batl":[[1,1.61,377.53],[2,1.62,384.47]],"ltp":1.52,"tv":4466.08,"id":8174333}]}]}
{"op":"mcm","clk":"1001467111","pt":1580636490300,"mc":[{"id":"1.168224329","rc":[{"batb":[[0,1.42,42.94],[1,1.41,902.21],[2,1.4,700.08]],"ltp":1.52,"tv":4466.08,"id":8174333}]}]}
{"op":"mcm","clk":"1001467119","pt":1580636490505,"mc":[{"id":"1.168224329","rc":[{"batb":[[0,2.66,65.42]],"batl":[[0,3.4,2.59],[1,3.65,2.1],[2,3.75,2.02]],"ltp":2.92,"tv":2316.55,"id":6498878},{"batl":[[1,1.6,69.16],[2,1.61,377.53]],"ltp":1.52,"tv":4466.08,"id":8174333}]}]}
{"op":"mcm","clk":"1001467833","pt":1580636499494,"mc":[{"id":"1.168224329","rc":[{"batb":[[0,2.66,51.14]],"batl":[[0,3.65,2.1],[1,3.75,2.02],[2,4.2,148.03]],"ltp":2.92,"tv":2316.55,"id":6498878},{"batb":[[0,1.41,902.21],[1,1.4,700.08],[2,1.39,214.41]],"batl":[[1,1.61,377.53],[2,1.62,384.47]],"ltp":1.52,"tv":4466.08,"id":8174333}]}]}
{"op":"mcm","clk":"1001467918","pt":1580636500886,"mc":[{"id":"1.168224329","rc":[{"batl":[[1,1.63,28.5],[2,1.71,2.27]],"ltp":1.52,"tv":4466.08,"id":8174333}]}]}
{"op":"mcm","clk":"1001467975","pt":1580636502331,"mc":[{"id":"1.168224329","rc":[{"batb":[[2,1.8,75.72]],"batl":[[2,1000,0.02]],"ltp":2.92,"tv":2316.55,"id":6498878}]}]}
{"op":"mcm","clk":"1001468072","pt":1580636504307,"mc":[{"id":"1.168224329","rc":[{"batb":[[0,3.4,7.79],[1,3.25,13.85],[2,3.15,2.56]],"batl":[[0,3.55,6.79],[1,3.65,2.1],[2,3.7,342.33]],"ltp":2.92,"tv":2316.55,"id":6498878},{"batb":[[0,1.41,2500.58]],"batl":[[0,1.44,959.6],[1,1.45,2254.76],[2,1.46,570.38]],"ltp":1.52,"tv":4466.08,"id":8174333}]}]}
{"op":"mcm","clk":"1001468105","pt":1580636505023,"mc":[{"id":"1.168224329","rc":[{"batb":[[1,3.25,89.62]],"ltp":2.92,"tv":2316.55,"id":6498878}]}]}
{"op":"mcm","clk":"1001468184","pt":1580636506208,"mc":[{"id":"1.168224329","rc":[{"batl":[[0,3.55,22.75]],"ltp":2.92,"tv":2316.55,"id":6498878},{"batb":[[2,1.39,321.95]],"ltp":1.52,"tv":4466.08,"id":8174333}]}]}
{"op":"mcm","clk":"1001468439","pt":1580636510331,"mc":[{"id":"1.168224329","rc":[{"batl":[[0,1.44,1440.19],[2,1.46,1067.78]],"ltp":1.52,"tv":4466.08,"id":8174333}]}]}
{"op":"mcm","clk":"1001468557","pt":1580636512805,"mc":[{"id":"1.168224329","rc":[{"trd":[[1.41,4]],"batb":[[0,1.41,2498.58]],"ltp":1.41,"tv":4470.08,"id":8174333}],"tv":6786.64}]}
{"op":"mcm","clk":"1001468630","pt":1580636514143,"mc":[{"id":"1.168224329","rc":[{"batb":[[0,3.25,13.85],[1,3.15,2.56],[2,3.05,20.16]],"batl":[[0,3.55,15.96],[1,4.9,126.27],[2,1000,0.02]],"ltp":2.92,"tv":2316.55,"id":6498878},{"batb":[[0,1.41,2.63],[1,1.39,107.54],[2,1.36,494.03]],"batl":[[0,1.44,574.92],[1,1.46,497.4],[2,1.49,42.01]],"ltp":1.41,"tv":4470.08,"id":8174333}]}]}
{"op":"mcm","clk":"1001468657","pt":1580636514610,"mc":[{"id":"1.168224329","rc":[{"batb":[[2,2.9,102.44]],"batl":[[0,4.9,126.27],[1,1000,0.02],[2,1000,0]],"ltp":2.92,"tv":2316.55,"id":6498878},{"batb":[[1,1.36,494.03],[2,1.34,510.84]],"batl":[[2,1.52,24.16]],"ltp":1.41,"tv":4470.08,"id":8174333}]}]}
{"op":"mcm","clk":"1001468820","pt":1580636517137,"mc":[{"id":"1.168224329","rc":[{"batb":[[0,3.15,2.56],[1,2.9,102.44],[2,2.8,11.68]],"ltp":2.92,"tv":2316.55,"id":6498878},{"batl":[[0,1.44,480.59]],"ltp":1.41,"tv":4470.08,"id":8174333}]}]}
{"op":"mcm","clk":"1001468960","pt":1580636520245,"mc":[{"id":"1.168224329","rc":[{"trd":[[3.45,1.08]],"batb":[[0,3.45,9.73],[1,3.15,2.56],[2,2.9,102.44]],"batl":[[0,3.7,10.85],[1,4.9,126.27],[2,1000,0.02]],"ltp":3.45,"tv":2317.63,"id":6498878},{"trd":[[1.41,6.63]],"batb":[[0,1.37,10.04]],"batl":[[0,1.41,11.11],[1,1.44,480.59],[2,1.46,497.4]],"ltp":1.41,"tv":4472.71,"id":8174333}],"tv":6790.34}]}
{"op":"mcm","clk":"1001468992","pt":1580636520921,"mc":[{"id":"1.168224329","rc":[{"batb":[[0,3.15,2.56],[1,2.9,102.44],[2,2.8,11.68]],"batl":[[0,4.9,126.27],[1,1000,0.02],[2,1000,0]],"ltp":3.45,"tv":2317.63,"id":6498878},{"batb":[[0,1.39,746.98],[1,1.38,746.42],[2,1.36,494.03]],"batl":[[0,1.43,990.8],[1,1.44,1082.11]],"ltp":1.41,"tv":4472.71,"id":8174333}]}]}
{"op":"mcm","clk":"1001469131","pt":1580636523348,"mc":[{"id":"1.168224329","rc":[{"batb":[[0,1.36,494.03],[1,1.34,510.84],[2,1.3,298.6]],"batl":[[0,1.44,480.59],[1,1.46,497.4],[2,1.52,24.16]],"ltp":1.41,"tv":4472.71,"id":8174333}]}]}
{"op":"mcm","clk":"1001469301","pt":1580636525729,"mc":[{"id":"1.168224329","rc":[{"batb":[[2,1.31,469.77]],"ltp":1.41,"tv":4472.71,"id":8174333}]}]}
{"op":"mcm","clk":"1001469738","pt":1580636531977,"mc":[{"id":"1.168224329","rc":[{"batb":[[0,2.9,102.44],[1,2.8,11.68],[2,2.66,11.78]],"ltp":3.45,"tv":2317.63,"id":6498878}]}]}
{"op":"mcm","clk":"1001471136","pt":1580636552259,"mc":[{"id":"1.168224329","rc":[{"batb":[[2,1.3,298.6]],"batl":[[0,1.52,24.16],[1,1.54,667.91],[2,1.55,514.42]],"ltp":1.41,"tv":4472.71,"id":8174333}]}]}
{"op":"mcm","clk":"1001471181","pt":1580636553763,"mc":[{"id":"1.168224329","rc":[{"batl":[[0,1000,0.02],[1,1000,0]],"ltp":3.45,"tv":2317.63,"id":6498878}]}]}
{"op":"mcm","clk":"1001471232","pt":1580636554956,"mc":[{"id":"1.168224329","rc":[{"batb":[[1,2.88,428],[2,2.8,11.68]],"batl":[[0,3.15,300],[1,3.2,340.52],[2,1000,0.02]],"ltp":3.45,"tv":2317.63,"id":6498878},{"trd":[[1.5,15.38]],"batb":[[0,1.5,1913.92],[1,1.49,532.17],[2,1.48,11.7]],"batl":[[1,1.54,2885.95]],"ltp":1.5,"tv":4483.89,"id":8174333}],"tv":6801.52}]}
{"op":"mcm","clk":"1001471284","pt":1580636555994,"mc":[{"id":"1.168224329","rc":[{"batb":[[2,2.8,34.37]],"batl":[[1,3.2,359]],"ltp":3.45,"tv":2317.63,"id":6498878}]}]}
{"op":"mcm","clk":"1001471345","pt":1580636557072,"mc":[{"id":"1.168224329","rc":[{"batb":[[0,2.94,2.58],[1,2.9,102.44],[2,2.88,428]],"ltp":3.45,"tv":2317.63,"id":6498878}]}]}
{"op":"mcm","clk":"1001471380","pt":1580636557898,"mc":[{"id":"1.168224329","rc":[{"batl":[[2,4.2,148.03]],"ltp":3.45,"tv":2317.63,"id":6498878}]}]}
{"op":"mcm","clk":"1001471654","pt":1580636563012,"mc":[{"id":"1.168224329","rc":[{"batl":[[2,3.5,2.19]],"ltp":3.45,"tv":2317.63,"id":6498878}]}]}
{"op":"mcm","clk":"1001471729","pt":1580636564819,"mc":[{"id":"1.168224329","rc":[{"batb":[[2,1.47,169.72]],"ltp":1.5,"tv":4483.89,"id":8174333}]}]}
{"op":"mcm","clk":"1001471876","pt":1580636567816,"mc":[{"id":"1.168224329","rc":[{"batb":[[0,2.96,8.47],[1,2.94,2.58],[2,2.9,102.44]],"ltp":3.45,"tv":2317.63,"id":6498878},{"batb":[[2,1.48,17.37]],"ltp":1.5,"tv":4483.89,"id":8174333}]}]}
{"op":"mcm","clk":"1001472334","pt":1580636576720,"mc":[{"id":"1.168224329","rc":[{"batl":[[0,3.2,359],[1,3.5,2.19],[2,3.8,2.02]],"ltp":3.45,"tv":2317.63,"id":6498878},{"batl":[[1,1.54,2128.95]],"ltp":1.5,"tv":4483.89,"id":8174333}]}]}
{"op":"mcm","clk":"1001472470","pt":1580636579403,"mc":[{"id":"1.168224329","rc":[{"batb":[[0,2.94,2.58],[1,2.9,102.44],[2,2.8,22.69]],"batl":[[0,3.2,18.48]],"ltp":3.45,"tv":2317.63,"id":6498878},{"batb":[[0,1.47,169.72],[1,1.45,93.26],[2,1.4,41.86]],"batl":[[1,1.56,42.01],[2,1.59,69.5]],"ltp":1.5,"tv":4483.89,"id":8174333}]}]}
{"op":"mcm","clk":"1001472488","pt":1580636579918,"mc":[{"id":"1.168224329","rc":[{"batb":[[1,2.8,22.69],[2,2.68,63.73]],"ltp":3.45,"tv":2317.63,"id":6498878},{"batb":[[0,1.45,93.26],[1,1.4,41.86],[2,1.38,218.97]],"ltp":1.5,"tv":4483.89,"id":8174333}]}]}
{"op":"mcm","clk":"1001472549","pt":1580636580910,"mc":[{"id":"1.168224329","rc":[{"batb":[[1,2.68,63.73],[2,2.66,11.78]],"batl":[[0,3.8,2.02],[1,4.2,148.03],[2,1000,0.02]],"ltp":3.45,"tv":2317.63,"id":6498878},{"batb":[[0,1.38,218.97],[1,1.36,48.18],[2,1.04,1867.61]],"batl":[[1,1.59,69.5],[2,1.6,58.31]],"ltp":1.5,"tv":4483.89,"id":8174333}]}]}
{"op":"mcm","clk":"1001472661","pt":1580636582352,"mc":[{"id":"1.168224329","rc":[{"batb":[[0,1.41,608.01],[1,1.4,697.12],[2,1.38,218.97]],"ltp":1.5,"tv":4483.89,"id":8174333}]}]}
{"op":"mcm","clk":"1001472803","pt":1580636584111,"mc":[{"id":"1.168224329","rc":[{"batl":[[0,3.5,2.51],[1,3.8,2.02],[2,4.2,148.03]],"ltp":3.45,"tv":2317.63,"id":6498878},{"batb":[[1,1.4,737.33]],"ltp":1.5,"tv":4483.89,"id":8174333}]}]}
{"op":"mcm","clk":"1001472870","pt":1580636585039,"mc":[{"id":"1.168224329","rc":[{"batb":[[0,2.68,63.73],[1,2.66,11.78],[2,2.6,13.49]],"ltp":3.45,"tv":2317.63,"id":6498878}]}]}
{"op":"mcm","clk":"1001472895","pt":1580636585503,"mc":[{"id":"1.168224329","rc":[{"batl":[[0,1.5,25],[1,1.52,24.16],[2,1.59,69.5]],"ltp":1.5,"tv":4483.89,"id":8174333}]}]}
{"op":"mcm","clk":"1001473003","pt":1580636587729,"mc":[{"id":"1.168224329","rc":[{"batl":[[0,3.8,2.02],[1,4.2,148.03],[2,1000,0.02]],"ltp":3.45,"tv":2317.63,"id":6498878},{"batb":[[0,1.38,218.97],[1,1.36,48.18],[2,1.04,1867.61]],"ltp":1.5,"tv":4483.89,"id":8174333}]}]}
{"op":"mcm","clk":"1001473072","pt":1580636589116,"mc":[{"id":"1.168224329","rc":[{"batl":[[1,1000,0.02],[2,1000,0]],"ltp":3.45,"tv":2317.63,"id":6498878}]}]}
{"op":"mcm","clk":"1001473111","pt":1580636590208,"mc":[{"id":"1.168224329","rc":[{"batl":[[0,3.6,6.44],[1,3.7,338],[2,3.8,2.02]],"ltp":3.45,"tv":2317.63,"id":6498878},{"trd":[[1.41,49.01]],"batb":[[0,1.41,1574.55],[1,1.38,218.97],[2,1.36,940.06]],"batl":[[0,1.43,4633.6],[1,1.44,918],[2,1.45,1551.72]],"ltp":1.41,"tv":4526.27,"id":8174333}],"tv":6843.9}]}
{"op":"mcm","clk":"1001473182","pt":1580636591403,"mc":[{"id":"1.168224329","rc":[{"batb":[[0,3.3,87.2],[1,2.92,100],[2,2.68,13.61]],"ltp":3.45,"tv":2317.63,"id":6498878},{"batb":[[0,1.41,2182.56],[1,1.4,697.12],[2,1.38,218.97]],"batl":[[0,1.43,93.5],[2,1.45,2530.46]],"ltp":1.41,"tv":4526.27,"id":8174333}]}]}
{"op":"mcm","clk":"1001473188","pt":1580636591506,"mc":[{"id":"1.168224329","rc":[{"batb":[[1,3.1,19.32],[2,2.92,100]],"batl":[[1,3.65,15.12],[2,3.7,338]],"ltp":3.45,"tv":2317.63,"id":6498878},{"batb":[[2,1.38,329.04]],"ltp":1.41,"tv":4526.27,"id":8174333}]}]}
{"op":"mcm","clk":"1001473279","pt":1580636593213,"mc":[{"id":"1.168224329","rc":[{"batb":[[1,3.2,2.55],[2,3.1,19.32]],"ltp":3.45,"tv":2317.63,"id":6498878}]}]}
{"op":"mcm","clk":"1001473628","pt":1580636600455,"mc":[{"id":"1.168224329","rc":[{"batl":[[0,3.65,15.12],[1,3.7,338],[2,3.8,2.02]],"ltp":3.45,"tv":2317.63,"id":6498878}]}]}
{"op":"mcm","clk":"1001473754","pt":1580636603348,"mc":[{"id":"1.168224329","rc":[{"batl":[[0,3.5,5.81],[1,3.65,15.12],[2,3.7,338]],"ltp":3.45,"tv":2317.63,"id":6498878},{"batb":[[0,1.41,1574.55],[1,1.38,329.04],[2,1.36,940.06]],"batl":[[0,1.42,13.83],[1,1.43,93.5],[2,1.44,918]],"ltp":1.41,"tv":4526.27,"id":8174333}]}]}
{"op":"mcm","clk":"1001474004","pt":1580636608541,"mc":[{"id":"1.168224329","rc":[{"trd":[[1.41,149.01]],"batb":[[0,1.41,1524.55]],"ltp":1.41,"tv":4626.27,"id":8174333}],"tv":6943.9}]}
{"op":"mcm","clk":"1001474086","pt":1580636610345,"mc":[{"id":"1.168224329","rc":[{"batb":[[0,3.2,2.55],[1,3.1,19.32],[2,2.92,100]],"batl":[[0,3.65,15.12],[1,5.3,118.79],[2,1000,0.02]],"ltp":3.45,"tv":2317.63,"id":6498878},{"batb":[[0,1.38,110.07],[1,1.29,305.36],[2,1.05,378.82]],"batl":[[0,1.48,42.01],[1,1.52,24.16],[2,1.53,67.5]],"ltp":1.41,"tv":4626.27,"id":8174333}]}]}
{"op":"mcm","clk":"1001474104","pt":1580636610758,"mc":[{"id":"1.168224329","rc":[{"batb":[[1,2.92,100],[2,2.74,12.02]],"batl":[[0,5.3,118.79],[1,1000,0.02],[2,1000,0]],"ltp":3.45,"tv":2317.63,"id":6498878},{"batb":[[0,1.29,305.36],[1,1.05,378.82],[2,1.04,1867.41]],"batl":[[0,1.52,24.16],[1,1.57,62.5],[2,1.59,69.5]],"ltp":1.41,"tv":4626.27,"id":8174333}]}]}
{"op":"mcm","clk":"1001474143","pt":1580636611735,"mc":[{"id":"1.168224329","rc":[{"batb":[[1,1.1,378.82],[2,1.05,378.62]],"ltp":1.41,"tv":4626.27,"id":8174333}]}]}
{"op":"mcm","clk":"1001474279","pt":1580636615181,"mc":[{"id":"1.168224329","rc":[{"batb":[[1,1.15,378.72],[2,1.1,378.72]],"ltp":1.41,"tv":4626.27,"id":8174333}]}]}
{"op":"mcm","clk":"1001474495","pt":1580636620396,"mc":[{"id":"1.168224329","rc":[{"batb":[[0,2.92,100],[1,2.88,11.71]],"ltp":3.45,"tv":2317.63,"id":6498878},{"batl":[[1,1.53,66.5],[2,1.57,62.5]],"ltp":1.41,"tv":4626.27,"id":8174333}]}]}
{"op":"mcm","clk":"1001474511","pt":1580636620864,"mc":[{"id":"1.168224329","rc":[{"batb":[[1,2.74,12.02],[2,2.3,385.09]],"ltp":3.45,"tv":2317.63,"id":6498878},{"batl":[[1,1.57,62.5],[2,1.7,2.27]],"ltp":1.41,"tv":4626.27,"id":8174333}]}]}
{"op":"mcm","clk":"1001474792","pt":1580636627185,"mc":[{"id":"1.168224329","rc":[{"batb":[[1,2.88,11.71],[2,2.74,12.02]],"ltp":3.45,"tv":2317.63,"id":6498878},{"batl":[[1,1.53,66.5],[2,1.57,62.5]],"ltp":1.41,"tv":4626.27,"id":8174333}]}]}
{"op":"mcm","clk":"1001474815","pt":1580636627595,"mc":[{"id":"1.168224329","rc":[{"batb":[[1,2.74,12.02],[2,2.3,385.09]],"ltp":3.45,"tv":2317.63,"id":6498878},{"batl":[[1,1.57,62.5],[2,1.7,2.27]],"ltp":1.41,"tv":4626.27,"id":8174333}]}]}
{"op":"mcm","clk":"1001475268","pt":1580636637397,"mc":[{"id":"1.168224329","rc":[{"batb":[[1,2.88,11.71],[2,2.74,12.02]],"ltp":3.45,"tv":2317.63,"id":6498878},{"batl":[[1,1.53,66.5],[2,1.57,62.5]],"ltp":1.41,"tv":4626.27,"id":8174333}]}]}
{"op":"mcm","clk":"1001475299","pt":1580636638115,"mc":[{"id":"1.168224329","rc":[{"batb":[[1,2.74,12.02],[2,2.3,385.09]],"ltp":3.45,"tv":2317.63,"id":6498878},{"batb":[[0,1.3,599.92],[1,1.29,834.14],[2,1.15,378.72]],"batl":[[1,1.53,232.12],[2,1.54,231.56]],"ltp":1.41,"tv":4626.27,"id":8174333}]}]}
{"op":"mcm","clk":"1001475423","pt":1580636640787,"mc":[{"id":"1.168224329","rc":[{"batb":[[1,2.88,11.71],[2,2.74,12.02]],"ltp":3.45,"tv":2317.63,"id":6498878},{"batl":[[1,1.53,298.62]],"ltp":1.41,"tv":4626.27,"id":8174333}]}]}
{"op":"mcm","clk":"1001475472","pt":1580636641814,"mc":[{"id":"1.168224329","rc":[{"batb":[[1,2.74,12.02],[2,2.3,385.09]],"ltp":3.45,"tv":2317.63,"id":6498878},{"batb":[[0,1.29,305.36],[1,1.15,378.72],[2,1.1,378.72]],"batl":[[1,1.57,62.5],[2,1.7,2.27]],"ltp":1.41,"tv":4626.27,"id":8174333}]}]}
{"op":"mcm","clk":"1001475613","pt":1580636644287,"mc":[{"id":"1.168224329","rc":[{"batb":[[2,2,75.72]],"batl":[[0,4.5,4.99],[1,4.8,309],[2,5,172.49]],"ltp":3.45,"tv":2317.63,"id":6498878},{"batb":[[1,1.25,689.95],[2,1.15,378.72]],"batl":[[0,1.3,13.44],[1,1.32,1415.46],[2,1.34,279.85]],"ltp":1.41,"tv":4626.27,"id":8174333}]}]}
{"op":"mcm","clk":"1001475662","pt":1580636645317,"mc":[{"id":"1.168224329","rc":[{"batb":[[0,3.95,97.41],[1,3.6,59.64],[2,2.74,12.02]],"ltp":3.45,"tv":2317.63,"id":6498878},{"trd":[[1.3,26.88]],"batb":[[0,1.3,586.48],[1,1.29,834.14],[2,1.27,337.78]],"batl":[[0,1.32,1415.46],[1,1.33,312.29],[2,1.34,699.31]],"ltp":1.3,"tv":4653.15,"id":8174333}],"tv":6970.78}]}
{"op":"mcm","clk":"1001475673","pt":1580636645623,"mc":[{"id":"1.168224329","rc":[{"batb":[[0,4,13.44],[1,3.95,97.41],[2,3.6,59.64]],"batl":[[1,4.8,319.92]],"ltp":3.45,"tv":2317.63,"id":6498878},{"batl":[[1,1.33,354.3]],"ltp":1.3,"tv":4653.15,"id":8174333}]}]}
{"op":"mcm","clk":"1001475903","pt":1580636651332,"mc":[{"id":"1.168224329","rc":[{"batb":[[2,3.85,9.57]],"batl":[[1,4.6,2],[2,4.8,319.92]],"ltp":3.45,"tv":2317.63,"id":6498878},{"batb":[[2,1.28,53.91]],"ltp":1.3,"tv":4653.15,"id":8174333}]}]}
{"op":"mcm","clk":"1001475912","pt":1580636651488,"mc":[{"id":"1.168224329","rc":[{"batl":[[1,4.8,319.92],[2,5,172.49]],"ltp":3.45,"tv":2317.63,"id":6498878},{"batb":[[2,1.27,337.78]],"ltp":1.3,"tv":4653.15,"id":8174333}]}]}
{"op":"mcm","clk":"1001476123","pt":1580636654792,"mc":[{"id":"1.168224329","rc":[{"batl":[[0,4.8,319.92],[1,5,172.49],[2,6.6,98.95]],"ltp":3.45,"tv":2317.63,"id":6498878}]}]}
{"op":"mcm","clk":"1001476348","pt":1580636658403,"mc":[{"id":"1.168224329","rc":[{"trd":[[4.4,8.66]],"ltp":4.4,"tv":2326.29,"id":6498878},{"trd":[[1.3,31.42],[1.31,31.52]],"batb":[[0,1.3,581.94]],"batl":[[0,1.31,4.28],[1,1.32,1415.46],[2,1.33,354.3]],"ltp":1.3,"tv":4689.21,"id":8174333}],"tv":7015.5}]}
{"op":"mcm","clk":"1001476952","pt":1580636668255,"mc":[{"id":"1.168224329","rc":[{"batl":[[0,4.6,2.01],[1,4.8,319.92],[2,5,172.49]],"ltp":4.4,"tv":2326.29,"id":6498878},{"batb":[[2,1.28,63.16]],"batl":[[0,1.32,1415.46],[1,1.33,354.3],[2,1.34,699.31]],"ltp":1.3,"tv":4689.21,"id":8174333}]}]}
{"op":"mcm","clk":"1001476963","pt":1580636668462,"mc":[{"id":"1.168224329","rc":[{"batl":[[0,4.8,319.92],[1,5,172.49],[2,6.6,98.95]],"ltp":4.4,"tv":2326.29,"id":6498878},{"batb":[[2,1.27,337.78]],"ltp":1.3,"tv":4689.21,"id":8174333}]}]}
{"op":"mcm","clk":"1001477224","pt":1580636672946,"mc":[{"id":"1.168224329","rc":[{"batb":[[1,3.95,94.81]],"ltp":4.4,"tv":2326.29,"id":6498878}]}]}
{"op":"mcm","clk":"1001477278","pt":1580636674245,"mc":[{"id":"1.168224329","rc":[{"batl":[[0,4.4,4.69],[1,4.8,319.92],[2,5,172.49]],"ltp":4.4,"tv":2326.29,"id":6498878},{"batl":[[0,1.31,16.59],[1,1.32,1415.46],[2,1.33,354.3]],"ltp":1.3,"tv":4689.21,"id":8174333}]}]}
{"op":"mcm","clk":"1001477328","pt":1580636675368,"mc":[{"id":"1.168224329","rc":[{"batb":[[1,3.7,9.52],[2,3.6,59.64]],"batl":[[0,4.6,2],[1,4.8,10.92],[2,6.6,98.95]],"ltp":4.4,"tv":2326.29,"id":6498878},{"batb":[[0,1.28,62.41],[1,1.27,337.78],[2,1.26,161.32]],"batl":[[0,1.33,42.01],[1,1.37,77.5],[2,1.52,24.16]],"ltp":1.3,"tv":4689.21,"id":8174333}]}]}
{"op":"mcm","clk":"1001477372","pt":1580636676656,"mc":[{"id":"1.168224329","rc":[{"batb":[[0,3.7,9.52],[1,3.6,59.64],[2,2.74,12.02]],"batl":[[1,6.6,98.95],[2,1000,0.02]],"ltp":4.4,"tv":2326.29,"id":6498878},{"batb":[[2,1.1,378.82]],"batl":[[0,1.37,77.5],[1,1.52,24.16],[2,1.57,62.5]],"ltp":1.3,"tv":4689.21,"id":8174333}]}]}
{"op":"mcm","clk":"1001477488","pt":1580636678157,"mc":[{"id":"1.168224329","rc":[{"batb":[[0,1.28,578.88],[1,1.27,913.71]],"batl":[[1,1.38,481.11],[2,1.39,351.15]],"ltp":1.3,"tv":4689.21,"id":8174333}]}]}
{"op":"mcm","clk":"1001477584","pt":1580636679346,"mc":[{"id":"1.168224329","rc":[{"batl":[[1,1.52,24.16],[2,1.57,62.5]],"ltp":1.3,"tv":4689.21,"id":8174333}]}]}
{"op":"mcm","clk":"1001477679","pt":1580636680373,"mc":[{"id":"1.168224329","rc":[{"batl":[[0,1.3,2],[1,1.37,77.5],[2,1.52,24.16]],"ltp":1.3,"tv":4689.21,"id":8174333}]}]}
{"op":"mcm","clk":"1001477773","pt":1580636682381,"mc":[{"id":"1.168224329","rc":[{"batb":[[0,4.3,9.48],[1,3.7,9.52],[2,3.6,59.64]],"batl":[[1,4.8,5.92],[2,5.2,320]],"ltp":4.4,"tv":2326.29,"id":6498878},{"trd":[[1.28,2807.66]],"batb":[[0,1.28,932.86]],"batl":[[0,1.29,972],[1,1.3,96.45],[2,1.31,2214.72]],"ltp":1.28,"tv":7496.87,"id":8174333}],"tv":9823.16}]}
{"op":"mcm","clk":"1001477817","pt":1580636683363,"mc":[{"id":"1.168224329","rc":[{"batb":[[1,4.2,82.07],[2,4.1,2.54]],"ltp":4.4,"tv":2326.29,"id":6498878},{"batb":[[2,1.24,373.66]],"ltp":1.28,"tv":7496.87,"id":8174333}]}]}
{"op":"mcm","clk":"1001477828","pt":1580636683669,"mc":[{"id":"1.168224329","rc":[{"batb":[[0,4.3,22.08]],"batl":[[2,5.1,10.08]],"ltp":4.4,"tv":2326.29,"id":6498878},{"batb":[[2,1.24,541.7]],"batl":[[2,1.31,2256.73]],"ltp":1.28,"tv":7496.87,"id":8174333}]}]}
{"op":"mcm","clk":"1001477936","pt":1580636686188,"mc":[{"id":"1.168224329","rc":[{"batl":[[1,1.3,399.38]],"ltp":1.28,"tv":7496.87,"id":8174333}]}]}
{"op":"mcm","clk":"1001478083","pt":1580636689380,"mc":[{"id":"1.168224329","rc":[{"batb":[[2,4.1,14.98]],"batl":[[1,4.8,7.92],[2,4.9,2]],"ltp":4.4,"tv":2326.29,"id":6498878},{"batb":[[1,1.27,1161.91],[2,1.26,1187.8]],"batl":[[1,1.3,938.95],[2,1.31,2762.53]],"ltp":1.28,"tv":7496.87,"id":8174333}]}]}
{"op":"mcm","clk":"1001478126","pt":1580636690051,"mc":[{"id":"1.168224329","rc":[{"trd":[[1.28,2809.68]],"batb":[[0,1.28,931.85]],"ltp":1.28,"tv":7498.89,"id":8174333}],"tv":9825.19}]}
{"op":"mcm","clk":"1001478313","pt":1580636693357,"mc":[{"id":"1.168224329","rc":[{"batb":[[1,4.1,14.98],[2,3.9,12.46]],"batl":[[0,4.9,2],[1,5.1,10.08],[2,6.6,98.95]],"ltp":4.4,"tv":2326.29,"id":6498878},{"batb":[[0,1.26,963.45],[1,1.25,519.24],[2,1.24,541.7]],"batl":[[0,1.3,585.44],[1,1.31,547.81],[2,1.32,116.86]],"ltp":1.28,"tv":7498.89,"id":8174333}]}]}
{"op":"mcm","clk":"1001478392","pt":1580636695362,"mc":[{"id":"1.168224329","rc":[{"batb":[[0,4.5,3.53],[1,4.3,9.48],[2,4.1,14.98]],"batl":[[0,4.7,6.02],[1,4.9,2]],"ltp":4.4,"tv":2326.29,"id":6498878},{"batb":[[2,1.24,373.66]],"batl":[[1,1.31,505.8]],"ltp":1.28,"tv":7498.89,"id":8174333}]}]}
{"op":"mcm","clk":"1001478440","pt":1580636696194,"mc":[{"id":"1.168224329","rc":[{"batb":[[0,4.1,14.98],[1,3.9,12.46],[2,3.85,102.29]],"batl":[[0,4.9,2],[1,6.6,98.95],[2,1000,0.02]],"ltp":4.4,"tv":2326.29,"id":6498878},{"batb":[[0,1.26,572.42]],"batl":[[0,1.3,490.99]],"ltp":1.28,"tv":7498.89,"id":8174333}]}]}
{"op":"mcm","clk":"1001478472","pt":1580636696761,"mc":[{"id":"1.168224329","rc":[{"batl":[[0,4.9,2.88]],"ltp":4.4,"tv":2326.29,"id":6498878}]}]}
{"op":"mcm","clk":"1001478609","pt":1580636699182,"mc":[{"id":"1.168224329","rc":[{"batb":[[0,1.28,525.41],[1,1.27,582.97],[2,1.26,572.42]],"batl":[[1,1.31,1012.82],[2,1.32,571.69]],"ltp":1.28,"tv":7498.89,"id":8174333}]}]}
{"op":"mcm","clk":"1001478653","pt":1580636699998,"mc":[{"id":"1.168224329","rc":[{"batl":[[0,4.8,2.88],[1,4.9,2],[2,6.6,98.95]],"ltp":4.4,"tv":2326.29,"id":6498878},{"batb":[[1,1.27,638.84]],"ltp":1.28,"tv":7498.89,"id":8174333}]}]}
{"op":"mcm","clk":"1001478749","pt":1580636701194,"mc":[{"id":"1.168224329","rc":[{"batb":[[0,1.27,55.87],[1,1.26,572.42],[2,1.25,519.24]],"batl":[[1,1.31,505.8],[2,1.32,116.86]],"ltp":1.28,"tv":7498.89,"id":8174333}]}]}
{"op":"mcm","clk":"1001478776","pt":1580636701507,"mc":[{"id":"1.168224329","rc":[{"batl":[[0,4.9,2.88],[1,6.6,98.95],[2,1000,0.02]],"ltp":4.4,"tv":2326.29,"id":6498878},{"batb":[[0,1.26,572.42],[1,1.25,519.24],[2,1.24,373.66]],"ltp":1.28,"tv":7498.89,"id":8174333}]}]}
{"op":"mcm","clk":"1001478951","pt":1580636703381,"mc":[{"id":"1.168224329","rc":[{"batl":[[2,1.32,119.13]],"ltp":1.28,"tv":7498.89,"id":8174333}]}]}
{"op":"mcm","clk":"1001479009","pt":1580636704208,"mc":[{"id":"1.168224329","rc":[{"batb":[[0,3.9,12.46],[1,3.85,102.29],[2,3.7,9.52]],"ltp":4.4,"tv":2326.29,"id":6498878},{"batl":[[0,1.3,2],[1,1.32,2.27],[2,1.34,692.94]],"ltp":1.28,"tv":7498.89,"id":8174333}]}]}
{"op":"mcm","clk":"1001479069","pt":1580636705196,"mc":[{"id":"1.168224329","rc":[{"batl":[[1,1000,0.02],[2,1000,0]],"ltp":4.4,"tv":2326.29,"id":6498878}]}]}
{"op":"mcm","clk":"1001479122","pt":1580636706220,"mc":[{"id":"1.168224329","rc":[{"trd":[[4.3,0.6]],"batb":[[0,4,3.87],[1,3.9,320.97],[2,3.85,102.29]],"batl":[[0,4.3,174.42],[1,4.6,320.34],[2,4.7,696.52]],"ltp":4.3,"tv":2326.89,"id":6498878},{"trd":[[1.3,33.42],[1.32,4.53]],"batb":[[0,1.32,10.59],[1,1.31,275.97],[2,1.3,507.69]],"batl":[[0,1.33,843],[1,1.34,692.94],[2,1.35,405.98]],"ltp":1.32,"tv":7505.42,"id":8174333}],"tv":9832.32}]}
{"op":"mcm","clk":"1001479177","pt":1580636707311,"mc":[{"id":"1.168224329","rc":[{"batb":[[2,1.3,797.16]],"ltp":1.32,"tv":7505.42,"id":8174333}]}]}
{"op":"mcm","clk":"1001479247","pt":1580636708393,"mc":[{"id":"1.168224329","rc":[{"batb":[[1,3.9,335.25]],"batl":[[2,4.7,707.44]],"ltp":4.3,"tv":2326.89,"id":6498878},{"batl":[[1,1.34,734.95]],"ltp":1.32,"tv":7505.42,"id":8174333}]}]}
{"op":"mcm","clk":"1001479351","pt":1580636710611,"mc":[{"id":"1.168224329","rc":[{"trd":[[1.32,25.25]],"batb":[[0,1.31,276.2],[1,1.3,797.16],[2,1.27,482.44]],"ltp":1.32,"tv":7526.14,"id":8174333}],"tv":9853.04}]}
{"op":"mcm","clk":"1001479485","pt":1580636713032,"mc":[{"id":"1.168224329","rc":[{"batl":[[1,4.6,322.35]],"ltp":4.3,"tv":2326.89,"id":6498878},{"batb":[[2,1.29,494.03]],"batl":[[2,1.35,886.57]],"ltp":1.32,"tv":7526.14,"id":8174333}]}]}
{"op":"mcm","clk":"1001479692","pt":1580636716025,"mc":[{"id":"1.168224329","rc":[{"batb":[[0,3.9,335.25],[1,3.85,102.29],[2,3.7,9.52]],"ltp":4.3,"tv":2326.89,"id":6498878},{"batb":[[0,1.31,275.97]],"ltp":1.32,"tv":7526.14,"id":8174333}]}]}
{"op":"mcm","clk":"1001479776","pt":1580636717320,"mc":[{"id":"1.168224329","rc":[{"batb":[[0,3.9,14.28],[1,3.6,13.79],[2,3.5,16.12]],"batl":[[0,4.6,2.89],[1,4.7,10.92],[2,4.9,2]],"ltp":4.3,"tv":2326.89,"id":6498878},{"batb":[[1,1.3,507.69]],"batl":[[0,1.34,624.7],[1,1.35,886.57],[2,1.37,497.4]],"ltp":1.32,"tv":7526.14,"id":8174333}]}]}
{"op":"mcm","clk":"1001479781","pt":1580636717425,"mc":[{"id":"1.168224329","rc":[{"batb":[[0,1.29,494.03],[1,1.28,61.91],[2,1.27,993.28]],"batl":[[0,1.34,42.01],[1,1.35,480.59]],"ltp":1.32,"tv":7526.14,"id":8174333}]}]}
{"op":"mcm","clk":"1001479885","pt":1580636719187,"mc":[{"id":"1.168224329","rc":[{"batb":[[0,3.6,13.79],[1,3.5,16.12],[2,3.4,67.12]],"batl":[[1,4.9,2],[2,6,106.18]],"ltp":4.3,"tv":2326.89,"id":6498878},{"batb":[[2,1.27,837.84]],"batl":[[0,1.35,480.59],[1,1.37,497.4],[2,1.38,108.75]],"ltp":1.32,"tv":7526.14,"id":8174333}]}]}
{"op":"mcm","clk":"1001479958","pt":1580636720321,"mc":[{"id":"1.168224329","rc":[{"batb":[[1,1.28,530.12],[2,1.27,1419.64]],"ltp":1.32,"tv":7526.14,"id":8174333}]}]}
{"op":"mcm","clk":"1001480013","pt":1580636721615,"mc":[{"id":"1.168224329","rc":[{"batb":[[0,1.28,530.12],[1,1.27,908.8],[2,1.26,69.98]],"ltp":1.32,"tv":7526.14,"id":8174333}]}]}
{"op":"mcm","clk":"1001480148","pt":1580636724402,"mc":[{"id":"1.168224329","rc":[{"trd":[[4.4,10.42]],"batb":[[0,4.4,4.67],[1,4.3,228.77],[2,3.6,13.79]],"batl":[[0,4.6,2.01],[1,4.7,9.33],[2,4.8,224.94]],"ltp":4.4,"tv":2328.66,"id":6498878},{"batb":[[0,1.28,2287.93]],"batl":[[0,1.3,1155.95],[1,1.31,2277.41],[2,1.32,453.92]],"ltp":1.32,"tv":7526.14,"id":8174333}],"tv":9854.8}]}
{"op":"mcm","clk":"1001480193","pt":1580636725332,"mc":[{"id":"1.168224329","rc":[{"batb":[[2,4.1,85.92]],"ltp":4.4,"tv":2328.66,"id":6498878}]}]}
{"op":"mcm","clk":"1001480232","pt":1580636726003,"mc":[{"id":"1.168224329","rc":[{"batb":[[2,4.1,99.36]],"ltp":4.4,"tv":2328.66,"id":6498878},{"batl":[[2,1.32,495.93]],"ltp":1.32,"tv":7526.14,"id":8174333}]}]}
{"op":"mcm","clk":"1001480307","pt":1580636727913,"mc":[{"id":"1.168224329","rc":[{"batb":[[2,4.1,85.92]],"ltp":4.4,"tv":2328.66,"id":6498878},{"batl":[[2,1.32,453.92]],"ltp":1.32,"tv":7526.14,"id":8174333}]}]}
{"op":"mcm","clk":"1001480457","pt":1580636730941,"mc":[{"id":"1.168224329","rc":[{"batb":[[2,4.2,12.6]],"ltp":4.4,"tv":2328.66,"id":6498878},{"batb":[[2,1.26,572.42]],"batl":[[1,1.31,2808.41],[2,1.32,959.72]],"ltp":1.32,"tv":7526.14,"id":8174333}]}]}
{"op":"mcm","clk":"1001480499","pt":1580636731618,"mc":[{"id":"1.168224329","rc":[{"batl":[[2,4.8,226.94]],"ltp":4.4,"tv":2328.66,"id":6498878},{"batb":[[1,1.27,965.67]],"batl":[[2,1.32,1076.83]],"ltp":1.32,"tv":7526.14,"id":8174333}]}]}
{"op":"mcm","clk":"1001480593","pt":1580636733328,"mc":[{"id":"1.168224329","rc":[{"batb":[[0,4.3,13.68],[1,4.2,12.6],[2,4.1,12.54]],"batl":[[0,4.8,2],[1,4.9,2],[2,5,10.08]],"ltp":4.4,"tv":2328.66,"id":6498878},{"batb":[[0,1.27,56.87],[1,1.26,572.42],[2,1.25,1053.23]],"batl":[[0,1.3,135.95],[1,1.31,531],[2,1.32,622.91]],"ltp":1.32,"tv":7526.14,"id":8174333}]}]}
{"op":"mcm","clk":"1001480613","pt":1580636733639,"mc":[{"id":"1.168224329","rc":[{"batl":[[0,4.9,2],[1,5,10.08],[2,6,106.18]],"ltp":4.4,"tv":2328.66,"id":6498878},{"batb":[[0,1.26,572.42],[1,1.25,1053.23],[2,1.1,378.82]],"ltp":1.32,"tv":7526.14,"id":8174333}]}]}
{"op":"mcm","clk":"1001480663","pt":1580636734719,"mc":[{"id":"1.168224329","rc":[{"batb":[[1,4.1,12.54],[2,4,2.69]],"batl":[[1,6,106.18],[2,1000,0.02]],"ltp":4.4,"tv":2328.66,"id":6498878},{"batb":[[1,1.25,885.19]],"batl":[[1,1.31,488.99]],"ltp":1.32,"tv":7526.14,"id":8174333}]}]}
{"op":"mcm","clk":"1001480741","pt":1580636736223,"mc":[{"id":"1.168224329","rc":[{"batb":[[0,1.26,1084.17],[1,1.25,1525.04]],"ltp":1.32,"tv":7526.14,"id":8174333}]}]}
{"op":"mcm","clk":"1001480802","pt":1580636737354,"mc":[{"id":"1.168224329","rc":[{"batb":[[0,4.1,12.54],[1,4,2.69],[2,3.9,12.56]],"ltp":4.4,"tv":2328.66,"id":6498878},{"batb":[[0,1.26,572.42],[1,1.25,885.19]],"batl":[[0,1.31,488.99],[1,1.32,622.91],[2,1.34,110.25]],"ltp":1.32,"tv":7526.14,"id":8174333}]}]}
{"op":"mcm","clk":"1001480873","pt":1580636738749,"mc":[{"id":"1.168224329","rc":[{"batb":[[0,1.29,316.32],[1,1.28,553.54],[2,1.26,572.42]],"batl":[[1,1.32,1267.84],[2,1.33,435.68]],"ltp":1.32,"tv":7526.14,"id":8174333}]}]}
{"op":"mcm","clk":"1001480948","pt":1580636740135,"mc":[{"id":"1.168224329","rc":[{"batl":[[0,4.8,2],[1,4.9,2],[2,6,106.18]],"ltp":4.4,"tv":2328.66,"id":6498878},{"batb":[[2,1.27,66.87]],"ltp":1.32,"tv":7526.14,"id":8174333}]}]}
{"op":"mcm","clk":"1001480993","pt":1580636740959,"mc":[{"id":"1.168224329","rc":[{"batl":[[0,4.9,2],[1,6,106.18],[2,1000,0.02]],"ltp":4.4,"tv":2328.66,"id":6498878},{"batb":[[0,1.26,572.42],[1,1.25,885.19],[2,1.1,378.82]],"batl":[[1,1.32,622.91],[2,1.34,110.25]],"ltp":1.32,"tv":7526.14,"id":8174333}]}]}
{"op":"mcm","clk":"1001481184","pt":1580636744364,"mc":[{"id":"1.168224329","rc":[{"batb":[[0,1.26,1084.17],[1,1.25,1525.04]],"ltp":1.32,"tv":7526.14,"id":8174333}]}]}
{"op":"mcm","clk":"1001481648","pt":1580636752146,"mc":[{"id":"1.168224329","rc":[{"batb":[[1,3.9,12.56],[2,3.75,54.21]],"ltp":4.4,"tv":2328.66,"id":6498878},{"trd":[[1.26,92]],"batb":[[0,1.26,1038.17]],"ltp":1.26,"tv":7618.14,"id":8174333}],"tv":9946.8}]}
{"op":"mcm","clk":"1001481780","pt":1580636754359,"mc":[{"id":"1.168224329","rc":[{"batl":[[0,4.8,2],[1,4.9,2],[2,6,106.18]],"ltp":4.4,"tv":2328.66,"id":6498878},{"batb":[[0,1.27,53.87],[1,1.26,1038.17],[2,1.25,1525.04]],"ltp":1.26,"tv":7618.14,"id":8174333}]}]}
{"op":"mcm","clk":"1001481792","pt":1580636754562,"mc":[{"id":"1.168224329","rc":[{"batl":[[0,4.9,2],[1,6,106.18],[2,1000,0.02]],"ltp":4.4,"tv":2328.66,"id":6498878},{"batb":[[0,1.26,1038.17],[1,1.25,1525.04],[2,1.1,378.82]],"ltp":1.26,"tv":7618.14,"id":8174333}]}]}
{"op":"mcm","clk":"1001482129","pt":1580636761280,"mc":[{"id":"1.168224329","rc":[{"batl":[[0,4.8,2],[1,4.9,2],[2,6,106.18]],"ltp":4.4,"tv":2328.66,"id":6498878},{"batb":[[0,1.27,67.87],[1,1.26,1038.17],[2,1.25,1525.04]],"ltp":1.26,"tv":7618.14,"id":8174333}]}]}
{"op":"mcm","clk":"1001482148","pt":1580636761591,"mc":[{"id":"1.168224329","rc":[{"batl":[[0,4.9,2],[1,6,106.18],[2,1000,0.02]],"ltp":4.4,"tv":2328.66,"id":6498878},{"batb":[[0,1.26,1038.17],[1,1.25,1525.04],[2,1.1,378.82]],"ltp":1.26,"tv":7618.14,"id":8174333}]}]}
{"op":"mcm","clk":"1001482554","pt":1580636769778,"mc":[{"id":"1.168224329","rc":[{"batb":[[0,1.26,535.73],[1,1.25,1005.8]],"ltp":1.26,"tv":7618.14,"id":8174333}]}]}
{"op":"mcm","clk":"1001482602","pt":1580636770495,"mc":[{"id":"1.168224329","rc":[{"batl":[[1,1000,0.02],[2,1000,0]],"ltp":4.4,"tv":2328.66,"id":6498878}]}]}
{"op":"mcm","clk":"1001482704","pt":1580636772405,"mc":[{"id":"1.168224329","rc":[{"batb":[[0,4.5,16.26],[1,4.1,12.54],[2,3.9,12.56]],"batl":[[1,5,6.45],[2,5.4,260]],"ltp":4.4,"tv":2328.66,"id":6498878},{"batb":[[0,1.26,2321.44],[2,1.24,797.19]],"batl":[[0,1.27,23.05],[1,1.28,1502.59],[2,1.29,2388.33]],"ltp":1.26,"tv":7618.14,"id":8174333}]}]}
{"op":"mcm","clk":"1001482756","pt":1580636773186,"mc":[{"id":"1.168224329","rc":[{"batb":[[1,4.4,73.02],[2,4.1,99.64]],"ltp":4.4,"tv":2328.66,"id":6498878}]}]}
{"op":"mcm","clk":"1001482809","pt":1580636774371,"mc":[{"id":"1.168224329","rc":[{"batb":[[1,4.4,84.78]],"batl":[[2,5.3,9.24]],"ltp":4.4,"tv":2328.66,"id":6498878},{"batl":[[2,1.29,2430.34]],"ltp":1.26,"tv":7618.14,"id":8174333}]}]}
{"op":"mcm","clk":"1001483041","pt":1580636779175,"mc":[{"id":"1.168224329","rc":[{"batb":[[2,1.24,1299.63]],"batl":[[1,1.28,1991.58],[2,1.29,2936.14]],"ltp":1.26,"tv":7618.14,"id":8174333}]}]}
{"op":"mcm","clk":"1001483094","pt":1580636780669,"mc":[{"id":"1.168224329","rc":[{"batb":[[1,4.4,98.99],[2,4.3,14.28]],"batl":[[1,5,8.45]],"ltp":4.4,"tv":2328.66,"id":6498878},{"batb":[[1,1.25,1072.01]],"batl":[[2,1.29,3083.64]],"ltp":1.26,"tv":7618.14,"id":8174333}]}]}
{"op":"mcm","clk":"1001483137","pt":1580636781599,"mc":[{"id":"1.168224329","rc":[{"trd":[[1.27,45.74]],"batl":[[0,1.28,1991.76],[1,1.29,3083.64],[2,1.3,2892.88]],"ltp":1.27,"tv":7663.88,"id":8174333}],"tv":9992.54}]}
{"op":"mcm","clk":"1001483471","pt":1580636789415,"mc":[{"id":"1.168224329","rc":[{"batb":[[0,4.4,98.99],[1,4.3,14.28],[2,4.1,99.64]],"batl":[[1,5,2]],"ltp":4.4,"tv":2328.66,"id":6498878},{"batb":[[0,1.26,535.73],[2,1.24,502.44]],"batl":[[0,1.28,488.99],[1,1.29,1339.45],[2,1.3,631.65]],"ltp":1.27,"tv":7663.88,"id":8174333}]}]}
{"op":"mcm","clk":"1001483486","pt":1580636789692,"mc":[{"id":"1.168224329","rc":[{"batb":[[0,4.4,25.97]],"batl":[[0,5,2],[1,5.3,9.24],[2,7.8,87.91]],"ltp":4.4,"tv":2328.66,"id":6498878},{"batb":[[0,1.25,481.19],[1,1.24,502.44],[2,1.23,559.87]],"batl":[[1,1.29,695.31],[2,1.3,142.05]],"ltp":1.27,"tv":7663.88,"id":8174333}]}]}
{"op":"mcm","clk":"1001483542","pt":1580636790838,"mc":[{"id":"1.168224329","rc":[{"batb":[[0,4.4,14.21]],"batl":[[1,7.8,87.91],[2,1000,0.02]],"ltp":4.4,"tv":2328.66,"id":6498878},{"trd":[[1.25,45.64]],"batb":[[0,1.25,458.37],[2,1.23,391.84]],"batl":[[1,1.29,653.3]],"ltp":1.25,"tv":7709.52,"id":8174333}],"tv":10038.18}]}
{"op":"mcm","clk":"1001483637","pt":1580636792393,"mc":[{"id":"1.168224329","rc":[{"batb":[[1,1.24,1172.24]],"ltp":1.25,"tv":7709.52,"id":8174333}]}]}
{"op":"mcm","clk":"1001483681","pt":1580636793425,"mc":[{"id":"1.168224329","rc":[{"batb":[[1,1.24,502.44]],"ltp":1.25,"tv":7709.52,"id":8174333}]}]}
{"op":"mcm","clk":"1001483732","pt":1580636794909,"mc":[{"id":"1.168224329","rc":[{"batl":[[1,1000,0.02],[2,1000,0]],"ltp":4.4,"tv":2328.66,"id":6498878}]}]}
{"op":"mcm","clk":"1001483788","pt":1580636796203,"mc":[{"id":"1.168224329","rc":[{"batb":[[0,4.5,12.3],[1,4.4,14.21],[2,4.3,14.28]],"batl":[[0,4.8,10.17],[1,4.9,2],[2,5,2]],"ltp":4.4,"tv":2328.66,"id":6498878},{"batb":[[0,1.27,11.24],[1,1.26,66.98],[2,1.25,458.37]],"batl":[[0,1.28,500.08]],"ltp":1.25,"tv":7709.52,"id":8174333}]}]}
{"op":"mcm","clk":"1001483848","pt":1580636797337,"mc":[{"id":"1.168224329","rc":[{"batb":[[0,4.4,14.21],[1,4.3,14.28],[2,4.1,99.64]],"batl":[[0,5,2],[1,1000,0.02],[2,5,0]],"ltp":4.4,"tv":2328.66,"id":6498878},{"batb":[[0,1.25,468.58],[1,1.24,502.44],[2,1.23,391.84]],"batl":[[0,1.28,488.99]],"ltp":1.25,"tv":7709.52,"id":8174333}]}]}
{"op":"mcm","clk":"1001483923","pt":1580636798832,"mc":[{"id":"1.168224329","rc":[{"batl":[[1,7.2,92.18],[2,1000,0.02]],"ltp":4.4,"tv":2328.66,"id":6498878}]}]}
{"op":"mcm","clk":"1001483984","pt":1580636800226,"mc":[{"id":"1.168224329","rc":[{"batb":[[1,1.24,1172.24]],"ltp":1.25,"tv":7709.52,"id":8174333}]}]}
{"op":"mcm","clk":"1001484156","pt":1580636803229,"mc":[{"id":"1.168224329","rc":[{"batb":[[2,4.1,87.1]],"ltp":4.4,"tv":2328.66,"id":6498878}]}]}
{"op":"mcm","clk":"1001484171","pt":1580636803536,"mc":[{"id":"1.168224329","rc":[{"batb":[[1,1.24,669.8]],"ltp":1.25,"tv":7709.52,"id":8174333}]}]}
{"op":"mcm","clk":"1001484246","pt":1580636805025,"mc":[{"id":"1.168224329","rc":[{"batl":[[1,1000,0.02],[2,1000,0]],"ltp":4.4,"tv":2328.66,"id":6498878}]}]}
{"op":"mcm","clk":"1001484306","pt":1580636806316,"mc":[{"id":"1.168224329","rc":[{"batb":[[0,4.7,14.42],[1,4.6,40.14],[2,4.4,14.21]],"batl":[[1,5.1,5.05],[2,5.5,225.36]],"ltp":4.4,"tv":2328.66,"id":6498878},{"batl":[[0,1.26,1066.17],[1,1.27,436.99],[2,1.28,3347.81]],"ltp":1.25,"tv":7709.52,"id":8174333}]}]}
{"op":"mcm","clk":"1001484332","pt":1580636806936,"mc":[{"id":"1.168224329","rc":[{"batb":[[1,4.6,106.15]],"ltp":4.4,"tv":2328.66,"id":6498878}]}]}
{"op":"mcm","clk":"1001484374","pt":1580636807706,"mc":[{"id":"1.168224329","rc":[{"batb":[[0,4.7,25.34]],"ltp":4.4,"tv":2328.66,"id":6498878},{"batl":[[1,1.27,479]],"ltp":1.25,"tv":7709.52,"id":8174333}]}]}
{"op":"mcm","clk":"1001484667","pt":1580636813032,"mc":[{"id":"1.168224329","rc":[{"batl":[[2,1.28,2858.82]],"ltp":1.25,"tv":7709.52,"id":8174333}]}]}
{"op":"mcm","clk":"1001485735","pt":1580636832045,"mc":[{"id":"1.168224329","rc":[{"trd":[[1.25,237.64],[1.26,94.06]],"batb":[[0,1.25,372.58]],"batl":[[0,1.26,1065.14]],"ltp":1.26,"tv":7903.58,"id":8174333}],"tv":10232.24}]}
{"op":"mcm","clk":"1001485900","pt":1580636834942,"mc":[{"id":"1.168224329","rc":[{"batb":[[0,1.25,415.53]],"batl":[[1,1.27,531.22]],"ltp":1.26,"tv":7903.58,"id":8174333}]}]}
{"op":"mcm","clk":"1001486096","pt":1580636838866,"mc":[{"id":"1.168224329","rc":[{"trd":[[1.26,98.5]],"batl":[[0,1.26,1062.92]],"ltp":1.26,"tv":7908.02,"id":8174333}],"tv":10236.68}]}
{"op":"mcm","clk":"1001489001","pt":1580636892915,"mc":[{"id":"1.168224329","rc":[{"batl":[[0,1.26,19.17]],"ltp":1.26,"tv":7908.02,"id":8174333}]}]}
{"op":"mcm","clk":"1001489115","pt":1580636895026,"mc":[{"id":"1.168224329","rc":[{"batb":[[0,4.4,14.21],[1,4.3,74.83],[2,2.9,375.84]],"batl":[[0,8.6,81.89],[1,1000,0.02],[2,5.5,0]],"ltp":4.4,"tv":2328.66,"id":6498878},{"batb":[[0,1.21,445.58],[1,1.05,378.82],[2,1.04,1867.41]],"batl":[[0,1.29,147.5],[1,1.5,151.45],[2,1.52,24.16]],"ltp":1.26,"tv":7908.02,"id":8174333}]}]}
{"op":"mcm","clk":"1001489283","pt":1580636898173,"mc":[{"id":"1.168224329","rc":[{"batl":[[0,5.4,2],[1,8.6,81.89],[2,1000,0.02]],"ltp":4.4,"tv":2328.66,"id":6498878},{"batb":[[0,1.23,417.76],[1,1.21,445.58],[2,1.05,378.82]],"ltp":1.26,"tv":7908.02,"id":8174333}]}]}
{"op":"mcm","clk":"1001489437","pt":1580636901051,"mc":[{"id":"1.168224329","rc":[{"batb":[[0,4.5,16.26],[1,4.4,14.21],[2,4.3,74.83]],"batl":[[0,5.2,2],[1,5.4,2],[2,8.6,81.89]],"ltp":4.4,"tv":2328.66,"id":6498878},{"batb":[[0,1.24,819.92],[1,1.23,797.78],[2,1.21,445.58]],"batl":[[0,1.27,578.66],[1,1.28,682.59],[2,1.29,147.5]],"ltp":1.26,"tv":7908.02,"id":8174333}]}]}
{"op":"mcm","clk":"1001489480","pt":1580636902181,"mc":[{"id":"1.168224329","rc":[{"trd":[[1.24,0.72]],"batb":[[0,1.24,819.56]],"ltp":1.24,"tv":7908.74,"id":8174333}],"tv":10237.4}]}
{"op":"mcm","clk":"1001489587","pt":1580636904283,"mc":[{"id":"1.168224329","rc":[{"batb":[[0,1.24,72.27],[1,1.23,417.76]],"batl":[[0,1.28,147.59],[1,1.29,147.5],[2,1.5,151.45]],"ltp":1.24,"tv":7908.74,"id":8174333}]}]}
{"op":"mcm","clk":"1001489599","pt":1580636904488,"mc":[{"id":"1.168224329","rc":[{"batb":[[0,4.4,14.21],[1,4.3,74.83],[2,2.9,375.84]],"batl":[[0,5.4,2],[1,8.6,81.89],[2,1000,0.02]],"ltp":4.4,"tv":2328.66,"id":6498878},{"batb":[[0,1.23,417.76],[1,1.21,445.58],[2,1.05,378.82]],"batl":[[0,1.29,147.5],[1,1.5,151.45],[2,1.52,24.16]],"ltp":1.24,"tv":7908.74,"id":8174333}]}]}
{"op":"mcm","clk":"1001489735","pt":1580636907159,"mc":[{"id":"1.168224329","rc":[{"batb":[[1,1.22,742.76],[2,1.21,445.58]],"batl":[[0,1.29,686.1],[1,1.3,492.83],[2,1.5,151.45]],"ltp":1.24,"tv":7908.74,"id":8174333}]}]}
{"op":"mcm","clk":"1001489995","pt":1580636912291,"mc":[{"id":"1.168224329","rc":[{"batl":[[0,1.29,147.5],[1,1.5,151.45],[2,1.52,24.16]],"ltp":1.24,"tv":7908.74,"id":8174333}]}]}
{"op":"mcm","clk":"1001490094","pt":1580636914358,"mc":[{"id":"1.168224329","rc":[{"batb":[[0,4.5,16.26],[1,4.4,14.21],[2,4.3,74.83]],"batl":[[0,5.2,2],[1,5.4,2]],"ltp":4.4,"tv":2328.66,"id":6498878},{"batb":[[0,1.24,69.77],[1,1.23,417.76],[2,1.22,742.76]],"batl":[[0,1.28,147.59],[1,1.29,147.5],[2,1.5,151.45]],"ltp":1.24,"tv":7908.74,"id":8174333}]}]}
{"op":"mcm","clk":"1001490147","pt":1580636915282,"mc":[{"id":"1.168224329","rc":[{"batb":[[0,4.8,13.78]],"batl":[[0,5.4,2],[1,5.7,5.86],[2,6.2,453.84]],"ltp":4.4,"tv":2328.66,"id":6498878},{"trd":[[1.23,2065.24]],"batb":[[0,1.23,1214.41],[1,1.22,742.76],[2,1.21,445.58]],"batl":[[0,1.24,1594],[1,1.25,2251.09],[2,1.26,747]],"ltp":1.23,"tv":9973.98,"id":8174333}],"tv":12302.64}]}
{"op":"mcm","clk":"1001490199","pt":1580636916100,"mc":[{"id":"1.168224329","rc":[{"batb":[[0,5,64.53],[1,4.8,13.78],[2,4.7,62.87]],"batl":[[2,6.2,461.4]],"ltp":4.4,"tv":2328.66,"id":6498878},{"batl":[[1,1.25,2293.1]],"ltp":1.23,"tv":9973.98,"id":8174333}]}]}
{"op":"mcm","clk":"1001490385","pt":1580636918784,"mc":[{"id":"1.168224329","rc":[{"trd":[[5.1,5.88]],"ltp":5.1,"tv":2334.54,"id":6498878},{"trd":[[1.23,2071.28],[1.24,24.91]],"batb":[[0,1.23,1211.39],[1,1.22,861.85],[2,1.21,1142.78]],"batl":[[0,1.24,1569.81],[1,1.25,2475.38]],"ltp":1.23,"tv":10004.21,"id":8174333}],"tv":12338.76}]}
{"op":"mcm","clk":"1001490522","pt":1580636921407,"mc":[{"id":"1.168224329","rc":[{"batb":[[1,1.22,1364.29],[2,1.21,1175.04]],"batl":[[1,1.25,2506.74],[2,1.26,1235.99]],"ltp":1.23,"tv":10004.21,"id":8174333}]}]}
{"op":"mcm","clk":"1001490527","pt":1580636921461,"mc":[{"id":"1.168224329","rc":[{"batb":[[2,1.21,1694.28]],"ltp":1.23,"tv":10004.21,"id":8174333}]}]}
{"op":"mcm","clk":"1001490641","pt":1580636923978,"mc":[{"id":"1.168224329","rc":[{"batb":[[2,4.7,79.79]],"batl":[[2,5.8,2]],"ltp":5.1,"tv":2334.54,"id":6498878},{"batb":[[2,1.21,1772.97]],"ltp":1.23,"tv":10004.21,"id":8174333}]}]}
{"op":"mcm","clk":"1001490716","pt":1580636925107,"mc":[{"id":"1.168224329","rc":[{"batl":[[1,5.8,2],[2,6,2]],"ltp":5.1,"tv":2334.54,"id":6498878}]}]}
{"op":"mcm","clk":"1001490874","pt":1580636928097,"mc":[{"id":"1.168224329","rc":[{"batl":[[1,5.5,4.81],[2,5.8,2]],"ltp":5.1,"tv":2334.54,"id":6498878},{"batl":[[0,1.24,1595.59]],"ltp":1.23,"tv":10004.21,"id":8174333}]}]}
{"op":"mcm","clk":"1001491069","pt":1580636932223,"mc":[{"id":"1.168224329","rc":[{"batb":[[0,5,10.08],[1,4.7,79.79],[2,4.4,16.84]],"batl":[[0,5.8,2],[1,6,2],[2,6.2,7.56]],"ltp":5.1,"tv":2334.54,"id":6498878},{"batb":[[0,1.22,502.44],[1,1.21,597.93],[2,1.2,84.22]],"batl":[[0,1.25,42.01],[1,1.26,488.99],[2,1.27,693.3]],"ltp":1.23,"tv":10004.21,"id":8174333}]}]}
{"op":"mcm","clk":"1001491118","pt":1580636933002,"mc":[{"id":"1.168224329","rc":[{"batb":[[0,4.7,79.79],[1,4.4,16.84],[2,3,75.72]],"batl":[[2,9.8,75.27]],"ltp":5.1,"tv":2334.54,"id":6498878},{"batl":[[0,1.26,488.99],[1,1.27,693.3],[2,1.29,147.5]],"ltp":1.23,"tv":10004.21,"id":8174333}]}]}
{"op":"mcm","clk":"1001491389","pt":1580636938200,"mc":[{"id":"1.168224329","rc":[{"batb":[[0,1.22,1030.12],[1,1.21,1394.87]],"batl":[[0,1.24,344.69],[1,1.25,623.9],[2,1.26,488.99]],"ltp":1.23,"tv":10004.21,"id":8174333}]}]}
{"op":"mcm","clk":"1001491626","pt":1580636941921,"mc":[{"id":"1.168224329","rc":[{"batb":[[0,1.22,502.44],[1,1.21,597.93]],"batl":[[0,1.26,488.99],[1,1.27,693.3],[2,1.29,147.5]],"ltp":1.23,"tv":10004.21,"id":8174333}]}]}
{"op":"mcm","clk":"1001491735","pt":1580636943528,"mc":[{"id":"1.168224329","rc":[{"batb":[[1,4.4,14.21]],"ltp":5.1,"tv":2334.54,"id":6498878}]}]}
{"op":"mcm","clk":"1001491828","pt":1580636944816,"mc":[{"id":"1.168224329","rc":[{"batb":[[2,1.2,850.74]],"batl":[[1,1.27,1466.14],[2,1.28,535.71]],"ltp":1.23,"tv":10004.21,"id":8174333}]}]}
{"op":"mcm","clk":"1001491991","pt":1580636947201,"mc":[{"id":"1.168224329","rc":[{"batl":[[0,6,2],[1,9.8,75.27],[2,1000,0.02]],"ltp":5.1,"tv":2334.54,"id":6498878},{"batb":[[0,1.2,850.74],[1,1.19,1359.06],[2,1.05,378.72]],"batl":[[1,1.27,693.3],[2,1.29,147.5]],"ltp":1.23,"tv":10004.21,"id":8174333}]}]}
{"op":"mcm","clk":"1001492128","pt":1580636949007,"mc":[{"id":"1.168224329","rc":[{"batl":[[1,1000,0.02],[2,1000,0]],"ltp":5.1,"tv":2334.54,"id":6498878}]}]}
{"op":"mcm","clk":"1001492226","pt":1580636950408,"mc":[{"id":"1.168224329","rc":[{"batb":[[0,5.4,9.24],[1,5.1,16.84],[2,4.7,79.79]],"batl":[[1,6.2,4.36],[2,6.6,6.72]],"ltp":5.1,"tv":2334.54,"id":6498878},{"batb":[[0,1.2,2725.74],[2,1.04,1867.51]],"batl":[[0,1.21,2437.17],[1,1.22,2112.82],[2,1.23,732.66]],"ltp":1.23,"tv":10004.21,"id":8174333}]}]}
{"op":"mcm","clk":"1001492260","pt":1580636951025,"mc":[{"id":"1.168224329","rc":[{"batb":[[0,5.4,53.93],[1,5.1,71.37],[2,4.7,16.92]],"ltp":5.1,"tv":2334.54,"id":6498878},{"batb":[[2,1.16,592.08]],"ltp":1.23,"tv":10004.21,"id":8174333}]}]}
{"op":"mcm","clk":"1001492594","pt":1580636956035,"mc":[{"id":"1.168224329","rc":[{"batl":[[1,1.22,2120.39]],"ltp":1.23,"tv":10004.21,"id":8174333}]}]}
{"op":"mcm","clk":"1001492621","pt":1580636956448,"mc":[{"id":"1.168224329","rc":[{"batb":[[2,5,15.03]],"batl":[[2,6.6,8.72]],"ltp":5.1,"tv":2334.54,"id":6498878},{"batb":[[2,1.18,604.3]],"batl":[[2,1.23,1221.65]],"ltp":1.23,"tv":10004.21,"id":8174333}]}]}
{"op":"mcm","clk":"1001493172","pt":1580636963324,"mc":[{"id":"1.168224329","rc":[{"batb":[[0,5.4,9.24],[1,5.1,54.53]],"batl":[[0,6.6,8.72],[1,7,2],[2,11.5,70.11]],"ltp":5.1,"tv":2334.54,"id":6498878},{"batb":[[0,1.2,1875.1],[1,1.18,604.3],[2,1.17,611.21]],"batl":[[0,1.22,1851.83],[1,1.23,531],[2,1.24,505.8]],"ltp":1.23,"tv":10004.21,"id":8174333}]}]}
{"op":"mcm","clk":"1001493179","pt":1580636963427,"mc":[{"id":"1.168224329","rc":[{"batb":[[0,1.18,604.4],[1,1.17,611.21],[2,1.16,592.08]],"batl":[[0,1.22,7.57]],"ltp":1.23,"tv":10004.21,"id":8174333}]}]}
{"op":"mcm","clk":"1001493273","pt":1580636964933,"mc":[{"id":"1.168224329","rc":[{"batb":[[0,5.1,54.53],[1,5,15.03],[2,4.7,16.92]],"batl":[[0,6.6,2]],"ltp":5.1,"tv":2334.54,"id":6498878},{"batl":[[1,1.23,488.99]],"ltp":1.23,"tv":10004.21,"id":8174333}]}]}
{"op":"mcm","clk":"1001493339","pt":1580636966066,"mc":[{"id":"1.168224329","rc":[{"batb":[[0,1.18,1347.11],[1,1.17,1515.24]],"batl":[[2,1.24,966.28]],"ltp":1.23,"tv":10004.21,"id":8174333}]}]}
{"op":"mcm","clk":"1001493416","pt":1580636967256,"mc":[{"id":"1.168224329","rc":[{"batb":[[0,1.18,604.4],[1,1.17,611.21]],"batl":[[2,1.24,505.8]],"ltp":1.23,"tv":10004.21,"id":8174333}]}]}
{"op":"mcm","clk":"1001493625","pt":1580636970357,"mc":[{"id":"1.168224329","rc":[{"batb":[[0,1.2,409.31],[1,1.19,892.05],[2,1.18,604.3]],"batl":[[0,1.22,606.24],[1,1.23,1170.34]],"ltp":1.23,"tv":10004.21,"id":8174333}]}]}
{"op":"mcm","clk":"1001493639","pt":1580636970562,"mc":[{"id":"1.168224329","rc":[{"trd":[[1.22,0.1]],"batl":[[0,1.22,606.2]],"ltp":1.22,"tv":10004.31,"id":8174333}],"tv":12338.85}]}
{"op":"mcm","clk":"1001493727","pt":1580636972065,"mc":[{"id":"1.168224329","rc":[{"batb":[[0,1.18,604.4],[1,1.17,611.21],[2,1.16,592.08]],"batl":[[0,1.22,7.53],[1,1.23,488.99]],"ltp":1.22,"tv":10004.31,"id":8174333}]}]}
{"op":"mcm","clk":"1001493908","pt":1580636975072,"mc":[{"id":"1.168224329","rc":[{"batb":[[0,1.18,1347.02],[1,1.17,1515.33]],"batl":[[2,1.24,966.41]],"ltp":1.22,"tv":10004.31,"id":8174333}]}]}
{"op":"mcm","clk":"1001494100","pt":1580636978884,"mc":[{"id":"1.168224329","rc":[{"batb":[[0,5.1,51.93]],"ltp":5.1,"tv":2334.54,"id":6498878}]}]}
{"op":"mcm","clk":"1001494245","pt":1580636981254,"mc":[{"id":"1.168224329","rc":[{"trd":[[1.18,261.94],[1.2,0.2]],"batb":[[0,1.18,844.48],[1,1.17,996.09]],"batl":[[2,1.24,505.8]],"ltp":1.18,"tv":10266.45,"id":8174333}],"tv":12600.99}]}
{"op":"mcm","clk":"1001494383","pt":1580636983273,"mc":[{"id":"1.168224329","rc":[{"batl":[[2,1000,0.02]],"ltp":5.1,"tv":2334.54,"id":6498878}]}]}
{"op":"mcm","clk":"1001494462","pt":1580636984364,"mc":[{"id":"1.168224329","rc":[{"batb":[[0,6.2,2.66],[1,6,71.36],[2,5.6,41.62]],"batl":[[0,7,2],[1,7.2,6.54],[2,7.6,171.28]],"ltp":5.1,"tv":2334.54,"id":6498878},{"trd":[[1.18,4192.26]],"batb":[[0,1.18,786.1]],"batl":[[0,1.2,2343.14],[1,1.21,761.71],[2,1.22,212.78]],"ltp":1.18,"tv":14196.77,"id":8174333}],"tv":16531.31}]}
{"op":"mcm","clk":"1001494554","pt":1580636985881,"mc":[{"id":"1.168224329","rc":[{"batb":[[2,5.8,8.4]],"batl":[[1,7.2,13.26]],"ltp":5.1,"tv":2334.54,"id":6498878},{"batb":[[2,1.16,760.12]],"batl":[[1,1.21,803.72]],"ltp":1.18,"tv":14196.77,"id":8174333}]}]}
{"op":"mcm","clk":"1001494651","pt":1580636987371,"mc":[{"id":"1.168224329","rc":[{"batb":[[0,1.18,1118.34],[1,1.17,1119.66]],"batl":[[0,1.2,2746.72]],"ltp":1.18,"tv":14196.77,"id":8174333}]}]}
{"op":"mcm","clk":"1001494910","pt":1580636992392,"mc":[{"id":"1.168224329","rc":[{"trd":[[1.18,4454.2]],"batb":[[0,1.18,987.37]],"ltp":1.18,"tv":14458.71,"id":8174333}],"tv":16793.25}]}
{"op":"mcm","clk":"1001495025","pt":1580636993800,"mc":[{"id":"1.168224329","rc":[{"batl":[[1,7.2,6.72]],"ltp":5.1,"tv":2334.54,"id":6498878}]}]}
{"op":"mcm","clk":"1001495238","pt":1580636996825,"mc":[{"id":"1.168224329","rc":[{"batl":[[0,6.8,4.7],[1,7,2],[2,7.2,6.72]],"ltp":5.1,"tv":2334.54,"id":6498878}]}]}
{"op":"mcm","clk":"1001495558","pt":1580637001027,"mc":[{"id":"1.168224329","rc":[{"batb":[[1,5.6,41.62],[2,5.1,17.64]],"batl":[[0,14,62.58],[1,1000,0.02],[2,7.2,0]],"ltp":5.1,"tv":2334.54,"id":6498878},{"batb":[[0,1.14,669.5],[1,1.04,1867.51],[2,1.03,2254.79]],"batl":[[0,1.21,672.04],[1,1.22,7.53],[2,1.23,230.5]],"ltp":1.18,"tv":14458.71,"id":8174333}]}]}
{"op":"mcm","clk":"1001495716","pt":1580637003207,"mc":[{"id":"1.168224329","rc":[{"batb":[[0,5.6,41.62],[1,5.1,17.64],[2,5,15.03]],"ltp":5.1,"tv":2334.54,"id":6498878}]}]}
{"op":"mcm","clk":"1001495772","pt":1580637004028,"mc":[{"id":"1.168224329","rc":[{"batl":[[1,1.22,735.33]],"ltp":1.18,"tv":14458.71,"id":8174333}]}]}
{"op":"mcm","clk":"1001495844","pt":1580637005242,"mc":[{"id":"1.168224329","rc":[{"batb":[[2,1.03,2254.77]],"ltp":1.18,"tv":14458.71,"id":8174333}]}]}
{"op":"mcm","clk":"1001495909","pt":1580637006330,"mc":[{"id":"1.168224329","rc":[{"batl":[[0,6.8,248.86],[1,7,214],[2,1000,0.02]],"ltp":5.1,"tv":2334.54,"id":6498878},{"batb":[[0,1.19,447.88],[1,1.18,966.31],[2,1.17,171.45]],"batl":[[0,1.21,3538.4]],"ltp":1.18,"tv":14458.71,"id":8174333}]}]}
{"op":"mcm","clk":"1001495961","pt":1580637007048,"mc":[{"id":"1.168224329","rc":[{"batb":[[1,5.2,49.41],[2,5.1,17.64]],"ltp":5.1,"tv":2334.54,"id":6498878},{"batb":[[1,1.18,1503.71]],"ltp":1.18,"tv":14458.71,"id":8174333}]}]}
{"op":"mcm","clk":"1001496030","pt":1580637008336,"mc":[{"id":"1.168224329","rc":[{"trd":[[6.4,51.2]],"batb":[[0,5.6,50.02]],"batl":[[1,7,220.72]],"ltp":6.4,"tv":2385.74,"id":6498878},{"trd":[[1.19,275.36],[1.21,0.11]],"batb":[[0,1.19,172.52]],"batl":[[0,1.21,3538.34],[1,1.22,777.34]],"ltp":1.21,"tv":14734.18,"id":8174333}],"tv":17119.92}]}
{"op":"mcm","clk":"1001496081","pt":1580637009323,"mc":[{"id":"1.168224329","rc":[{"trd":[[1.19,308.96]],"batb":[[0,1.19,155.72]],"ltp":1.19,"tv":14767.78,"id":8174333}],"tv":17153.53}]}
{"op":"mcm","clk":"1001496092","pt":1580637009530,"mc":[{"id":"1.168224329","rc":[{"batl":[[2,12.5,65.97]],"ltp":6.4,"tv":2385.74,"id":6498878}]}]}
{"op":"mcm","clk":"1001496223","pt":1580637011747,"mc":[{"id":"1.168224329","rc":[{"batb":[[0,1.19,278.91]],"batl":[[0,1.21,3687.98]],"ltp":1.19,"tv":14767.78,"id":8174333}]}]}
{"op":"mcm","clk":"1001496287","pt":1580637012631,"mc":[{"id":"1.168224329","rc":[{"batb":[[1,5.3,18.18],[2,5.2,49.41]],"ltp":6.4,"tv":2385.74,"id":6498878}]}]}
{"op":"mcm","clk":"1001496708","pt":1580637019256,"mc":[{"id":"1.168224329","rc":[{"batl":[[0,6.8,26.89],[1,7,6.72]],"ltp":6.4,"tv":2385.74,"id":6498878},{"batl":[[0,1.21,821.62]],"ltp":1.19,"tv":14767.78,"id":8174333}]}]}
{"op":"mcm","clk":"1001496752","pt":1580637019835,"mc":[{"id":"1.168224329","rc":[{"batb":[[0,5.6,8.4]],"batl":[[0,7,6.72],[1,12.5,65.97],[2,1000,0.02]],"ltp":6.4,"tv":2385.74,"id":6498878},{"batb":[[0,1.15,633.23],[1,1.04,1867.51],[2,1.03,2254.77]],"batl":[[0,1.22,293.9],[1,1.23,230.5],[2,1.24,220.48]],"ltp":1.19,"tv":14767.78,"id":8174333}]}]}
{"op":"mcm","clk":"1001496840","pt":1580637021024,"mc":[{"id":"1.168224329","rc":[{"batb":[[0,5.3,18.18],[1,5.2,49.41],[2,5.1,17.64]],"batl":[[0,12.5,65.97],[1,1000,0.02],[2,1000,0]],"ltp":6.4,"tv":2385.74,"id":6498878},{"batl":[[0,1.22,251.89]],"ltp":1.19,"tv":14767.78,"id":8174333}]}]}
{"op":"mcm","clk":"1001496872","pt":1580637021543,"mc":[{"id":"1.168224329","rc":[{"batb":[[1,1.05,378.72],[2,1.04,1867.41]],"ltp":1.19,"tv":14767.78,"id":8174333}]}]}
{"op":"mcm","clk":"1001496990","pt":1580637023447,"mc":[{"id":"1.168224329","rc":[{"batb":[[0,1.16,1163.05],[1,1.15,1141.9],[2,1.05,378.72]],"batl":[[1,1.23,937.93]],"ltp":1.19,"tv":14767.78,"id":8174333}]}]}
{"op":"mcm","clk":"1001497231","pt":1580637027833,"mc":[{"id":"1.168224329","rc":[{"batb":[[0,1.15,633.23],[1,1.05,378.72],[2,1.04,1867.41]],"ltp":1.19,"tv":14767.78,"id":8174333}]}]}
{"op":"mcm","clk":"1001497333","pt":1580637029751,"mc":[{"id":"1.168224329","rc":[{"batl":[[0,1000,0.02],[1,1000,0]],"ltp":6.4,"tv":2385.74,"id":6498878}]}]}
{"op":"mcm","clk":"1001497395","pt":1580637030836,"mc":[{"id":"1.168224329","rc":[{"batl":[[0,5.7,4.08],[1,5.9,37.05],[2,6.2,242.62]],"ltp":6.4,"tv":2385.74,"id":6498878},{"batb":[[0,1.2,809.93],[1,1.19,960.98],[2,1.15,633.23]],"batl":[[1,1.23,3334.74]],"ltp":1.19,"tv":14767.78,"id":8174333}]}]}
{"op":"mcm","clk":"1001497459","pt":1580637031972,"mc":[{"id":"1.168224329","rc":[{"batb":[[0,5.3,27.42]],"ltp":6.4,"tv":2385.74,"id":6498878},{"batb":[[0,1.2,1284.62],[2,1.18,168.04]],"batl":[[1,1.23,3376.75]],"ltp":1.19,"tv":14767.78,"id":8174333}]}]}
{"op":"mcm","clk":"1001497526","pt":1580637032957,"mc":[{"id":"1.168224329","rc":[{"batb":[[0,5.4,2.67],[1,5.3,27.42],[2,5.2,49.41]],"ltp":6.4,"tv":2385.74,"id":6498878}]}]}
{"op":"mcm","clk":"1001497731","pt":1580637037351,"mc":[{"id":"1.168224329","rc":[{"trd":[[5.7,4.08]],"batl":[[0,5.9,37.05],[1,6.2,242.62],[2,6.4,211]],"ltp":5.7,"tv":2389.82,"id":6498878},{"trd":[[1.2,81.76],[1.21,19.33]],"batb":[[0,1.2,1243.84]],"ltp":1.2,"tv":14868.56,"id":8174333}],"tv":17258.39}]}
{"op":"mcm","clk":"1001497754","pt":1580637037657,"mc":[{"id":"1.168224329","rc":[{"batb":[[2,1.18,670.48]],"batl":[[1,1.23,3865.74],[2,1.24,726.28]],"ltp":1.2,"tv":14868.56,"id":8174333}]}]}
