{"op":"mcm","clk":"1001415471","pt":1580567750513,"mc":[{"id":"1.168217556","marketDefinition":{"bspMarket":false,"turnInPlayEnabled":true,"persistenceEnabled":true,"marketBaseRate":5.0,"eventId":"29681263","eventTypeId":"2","numberOfWinners":1,"bettingType":"ODDS","marketType":"SET_WINNER","marketTime":"2020-02-02T11:30:00.000Z","suspendTime":"2020-02-02T11:30:00.000Z","bspReconciled":false,"complete":true,"inPlay":false,"crossMatching":false,"runnersVoidable":false,"numberOfActiveRunners":2,"betDelay":0,"status":"OPEN","runners":[{"status":"ACTIVE","sortPriority":1,"id":7412809,"name":"Evgeny Karlovskiy"},{"status":"ACTIVE","sortPriority":2,"id":2263624,"name":"Viktor Troicki"}],"regulators":["MR_INT"],"countryCode":"IN","discountAllowed":false,"timezone":"UTC","openDate":"2020-02-02T11:30:00.000Z","version":3145496348,"name":"Set 1 Winner","eventName":"Karlovskiy v Troicki"}}]}
{"op":"mcm","clk":"1001415705","pt":1580567751514,"mc":[{"id":"1.168217556","marketDefinition":{"bspMarket":false,"turnInPlayEnabled":true,"persistenceEnabled":true,"marketBaseRate":5.0,"eventId":"29681263","eventTypeId":"2","numberOfWinners":1,"bettingType":"ODDS","marketType":"SET_WINNER","marketTime":"2020-02-02T11:30:00.000Z","suspendTime":"2020-02-02T11:30:00.000Z","bspReconciled":false,"complete":true,"inPlay":false,"crossMatching":false,"runnersVoidable":false,"numberOfActiveRunners":2,"betDelay":0,"status":"OPEN","runners":[{"status":"ACTIVE","sortPriority":1,"id":7412809,"name":"Evgeny Karlovskiy"},{"status":"ACTIVE","sortPriority":2,"id":2263624,"name":"Viktor Troicki"}],"regulators":["MR_INT"],"countryCode":"IN","discountAllowed":false,"timezone":"UTC","openDate":"2020-02-02T11:30:00.000Z","version":3145496348,"name":"Set 1 Winner","eventName":"Karlovskiy v Troicki"}}]}
{"op":"mcm","clk":"1001415945","pt":1580567752496,"mc":[{"id":"1.168217556","marketDefinition":{"bspMarket":false,"turnInPlayEnabled":true,"persistenceEnabled":true,"marketBaseRate":5.0,"eventId":"29681263","eventTypeId":"2","numberOfWinners":1,"bettingType":"ODDS","marketType":"SET_WINNER","marketTime":"2020-02-02T11:30:00.000Z","suspendTime":"2020-02-02T11:30:00.000Z","bspReconciled":false,"complete":true,"inPlay":false,"crossMatching":false,"runnersVoidable":false,"numberOfActiveRunners":2,"betDelay":0,"status":"OPEN","runners":[{"status":"ACTIVE","sortPriority":1,"id":7412809,"name":"Evgeny Karlovskiy"},{"status":"ACTIVE","sortPriority":2,"id":2263624,"name":"Viktor Troicki"}],"regulators":["MR_INT"],"countryCode":"IN","discountAllowed":true,"timezone":"UTC","openDate":"2020-02-02T11:30:00.000Z","version":3145496348,"name":"Set 1 Winner","eventName":"Karlovskiy v Troicki"}}]}
{"op":"mcm","clk":"1001422883","pt":1580567785309,"mc":[{"id":"1.168217556","rc":[{"batb":[[0,1.01,20]],"ltp":0.0,"tv":0.0,"id":2263624},{"batb":[[0,1.01,20]],"ltp":0.0,"tv":0.0,"id":7412809}]}]}
{"op":"mcm","clk":"1001538085","pt":1580568313307,"mc":[{"id":"1.168217556","rc":[{"batb":[[0,1.01,10]],"ltp":0.0,"tv":0.0,"id":2263624},{"batb":[[0,1.01,10]],"ltp":0.0,"tv":0.0,"id":7412809}]}]}
{"op":"mcm","clk":"1006948321","pt":1580602465431,"mc":[{"id":"1.168217556","rc":[{"batb":[[0,1.01,12.53]],"ltp":0.0,"tv":0.0,"id":2263624},{"batb":[[0,1.01,12.53]],"ltp":0.0,"tv":0.0,"id":7412809}]}]}
{"op":"mcm","clk":"1006948413","pt":1580602466518,"mc":[{"id":"1.168217556","rc":[{"batb":[[0,1.01,10.51]],"ltp":0.0,"tv":0.0,"id":2263624},{"batb":[[0,1.01,10.51]],"ltp":0.0,"tv":0.0,"id":7412809}]}]}
{"op":"mcm","clk":"1007059766","pt":1580604000402,"mc":[{"id":"1.168217556","rc":[{"batb":[[0,1.01,11.01]],"ltp":0.0,"tv":0.0,"id":2263624},{"batb":[[0,1.01,11.01]],"ltp":0.0,"tv":0.0,"id":7412809}]}]}
{"op":"mcm","clk":"1007202912","pt":1580607092495,"mc":[{"id":"1.168217556","rc":[{"batb":[[0,1.01,13.01]],"ltp":0.0,"tv":0.0,"id":2263624},{"batb":[[0,1.01,13.01]],"ltp":0.0,"tv":0.0,"id":7412809}]}]}
{"op":"mcm","clk":"1007202965","pt":1580607093378,"mc":[{"id":"1.168217556","rc":[{"batb":[[0,1.01,11.02]],"ltp":0.0,"tv":0.0,"id":2263624},{"batb":[[0,1.01,11.02]],"ltp":0.0,"tv":0.0,"id":7412809}]}]}
{"op":"mcm","clk":"1007985319","pt":1580627248694,"mc":[{"id":"1.168217556","rc":[{"batl":[[0,2.14,7.57]],"ltp":0.0,"tv":0.0,"id":2263624},{"batl":[[0,3.5,3.03]],"ltp":0.0,"tv":0.0,"id":7412809}]}]}
{"op":"mcm","clk":"1007985559","pt":1580627253024,"mc":[{"id":"1.168217556","marketDefinition":{"bspMarket":false,"turnInPlayEnabled":true,"persistenceEnabled":true,"marketBaseRate":5.0,"eventId":"29681263","eventTypeId":"2","numberOfWinners":1,"bettingType":"ODDS","marketType":"SET_WINNER","marketTime":"2020-02-02T11:30:00.000Z","suspendTime":"2020-02-02T11:30:00.000Z","bspReconciled":false,"complete":true,"inPlay":false,"crossMatching":true,"runnersVoidable":false,"numberOfActiveRunners":2,"betDelay":0,"status":"OPEN","runners":[{"status":"ACTIVE","sortPriority":1,"id":7412809,"name":"Evgeny Karlovskiy"},{"status":"ACTIVE","sortPriority":2,"id":2263624,"name":"Viktor Troicki"}],"regulators":["MR_INT"],"countryCode":"IN","discountAllowed":true,"timezone":"UTC","openDate":"2020-02-02T11:30:00.000Z","version":3146887733,"name":"Set 1 Winner","eventName":"Karlovskiy v Troicki"}}]}
{"op":"mcm","clk":"1008458746","pt":1580635606316,"mc":[{"id":"1.168217556","marketDefinition":{"bspMarket":false,"turnInPlayEnabled":true,"persistenceEnabled":true,"marketBaseRate":5.0,"eventId":"29681263","eventTypeId":"2","numberOfWinners":1,"bettingType":"ODDS","marketType":"SET_WINNER","marketTime":"2020-02-02T11:21:00.000Z","suspendTime":"2020-02-02T11:21:00.000Z","bspReconciled":false,"complete":true,"inPlay":false,"crossMatching":true,"runnersVoidable":false,"numberOfActiveRunners":2,"betDelay":0,"status":"OPEN","runners":[{"status":"ACTIVE","sortPriority":1,"id":7412809,"name":"Evgeny Karlovskiy"},{"status":"ACTIVE","sortPriority":2,"id":2263624,"name":"Viktor Troicki"}],"regulators":["MR_INT"],"countryCode":"IN","discountAllowed":true,"timezone":"UTC","openDate":"2020-02-02T11:30:00.000Z","version":3148345099,"name":"Set 1 Winner","eventName":"Karlovskiy v Troicki"}}]}
{"op":"mcm","clk":"1008459143","pt":1580635610325,"mc":[{"id":"1.168217556","marketDefinition":{"bspMarket":false,"turnInPlayEnabled":true,"persistenceEnabled":true,"marketBaseRate":5.0,"eventId":"29681263","eventTypeId":"2","numberOfWinners":1,"bettingType":"ODDS","marketType":"SET_WINNER","marketTime":"2020-02-02T11:21:00.000Z","suspendTime":"2020-02-02T11:21:00.000Z","bspReconciled":false,"complete":true,"inPlay":false,"crossMatching":true,"runnersVoidable":false,"numberOfActiveRunners":2,"betDelay":0,"status":"OPEN","runners":[{"status":"ACTIVE","sortPriority":1,"id":7412809,"name":"Evgeny Karlovskiy"},{"status":"ACTIVE","sortPriority":2,"id":2263624,"name":"Viktor Troicki"}],"regulators":["MR_INT"],"countryCode":"IN","discountAllowed":true,"timezone":"UTC","openDate":"2020-02-02T11:21:00.000Z","version":3148345099,"name":"Set 1 Winner","eventName":"Karlovskiy v Troicki"}}]}
{"op":"mcm","clk":"1009033963","pt":1580641605793,"mc":[{"id":"1.168217556","marketDefinition":{"bspMarket":false,"turnInPlayEnabled":true,"persistenceEnabled":true,"marketBaseRate":5.0,"eventId":"29681263","eventTypeId":"2","numberOfWinners":1,"bettingType":"ODDS","marketType":"SET_WINNER","marketTime":"2020-02-02T11:09:00.000Z","suspendTime":"2020-02-02T11:09:00.000Z","bspReconciled":false,"complete":true,"inPlay":false,"crossMatching":true,"runnersVoidable":false,"numberOfActiveRunners":2,"betDelay":0,"status":"OPEN","runners":[{"status":"ACTIVE","sortPriority":1,"id":7412809,"name":"Evgeny Karlovskiy"},{"status":"ACTIVE","sortPriority":2,"id":2263624,"name":"Viktor Troicki"}],"regulators":["MR_INT"],"countryCode":"IN","discountAllowed":true,"timezone":"UTC","openDate":"2020-02-02T11:21:00.000Z","version":3148499127,"name":"Set 1 Winner","eventName":"Karlovskiy v Troicki"}}]}
{"op":"mcm","clk":"1009034829","pt":1580641610805,"mc":[{"id":"1.168217556","marketDefinition":{"bspMarket":false,"turnInPlayEnabled":true,"persistenceEnabled":true,"marketBaseRate":5.0,"eventId":"29681263","eventTypeId":"2","numberOfWinners":1,"bettingType":"ODDS","marketType":"SET_WINNER","marketTime":"2020-02-02T11:09:00.000Z","suspendTime":"2020-02-02T11:09:00.000Z","bspReconciled":false,"complete":true,"inPlay":false,"crossMatching":true,"runnersVoidable":false,"numberOfActiveRunners":2,"betDelay":0,"status":"OPEN","runners":[{"status":"ACTIVE","sortPriority":1,"id":7412809,"name":"Evgeny Karlovskiy"},{"status":"ACTIVE","sortPriority":2,"id":2263624,"name":"Viktor Troicki"}],"regulators":["MR_INT"],"countryCode":"IN","discountAllowed":true,"timezone":"UTC","openDate":"2020-02-02T11:09:00.000Z","version":3148499127,"name":"Set 1 Winner","eventName":"Karlovskiy v Troicki"}}]}
{"op":"mcm","clk":"1009040775","pt":1580641648076,"mc":[{"id":"1.168217556","rc":[{"batb":[[0,1.41,2.01],[1,1.01,11.01]],"ltp":0.0,"tv":0.0,"id":2263624},{"batb":[[0,1.88,2],[1,1.01,11.02]],"ltp":0.0,"tv":0.0,"id":7412809}]}]}
{"op":"mcm","clk":"1009058427","pt":1580641763010,"mc":[{"id":"1.168217556","rc":[{"batb":[[0,1.64,27.07],[1,1.41,2.01],[2,1.01,11.01]],"ltp":0.0,"tv":0.0,"id":2263624},{"batb":[[0,2.36,17.31],[1,1.88,2],[2,1.01,11.02]],"ltp":0.0,"tv":0.0,"id":7412809}]}]}
{"op":"mcm","clk":"1009061288","pt":1580641781459,"mc":[{"id":"1.168217556","rc":[{"batb":[[0,2.38,17.23]],"ltp":0.0,"tv":0.0,"id":7412809}]}]}
{"op":"mcm","clk":"1009062747","pt":1580641791469,"mc":[{"id":"1.168217556","rc":[{"batb":[[0,1.63,27.3]],"ltp":0.0,"tv":0.0,"id":2263624}]}]}
{"op":"mcm","clk":"1009064113","pt":1580641801397,"mc":[{"id":"1.168217556","rc":[{"batb":[[0,2.38,17.07]],"ltp":0.0,"tv":0.0,"id":7412809}]}]}
{"op":"mcm","clk":"1009074424","pt":1580641874415,"mc":[{"id":"1.168217556","rc":[{"batb":[[2,1.01,12.7]],"ltp":0.0,"tv":0.0,"id":7412809}]}]}
{"op":"mcm","clk":"1009074559","pt":1580641875326,"mc":[{"id":"1.168217556","rc":[{"batb":[[2,1.01,12.55]],"ltp":0.0,"tv":0.0,"id":2263624},{"batb":[[0,2.4,1.05],[1,2.38,17.07],[2,1.88,2]],"ltp":0.0,"tv":0.0,"id":7412809}]}]}
{"op":"mcm","clk":"1009074622","pt":1580641875699,"mc":[{"id":"1.168217556","rc":[{"batb":[[0,1.64,1.54],[1,1.63,27.3],[2,1.41,2.01]],"ltp":0.0,"tv":0.0,"id":2263624}]}]}
{"op":"mcm","clk":"1009079667","pt":1580641907335,"mc":[{"id":"1.168217556","marketDefinition":{"bspMarket":false,"turnInPlayEnabled":true,"persistenceEnabled":true,"marketBaseRate":5.0,"eventId":"29681263","eventTypeId":"2","numberOfWinners":1,"bettingType":"ODDS","marketType":"SET_WINNER","marketTime":"2020-02-02T11:07:00.000Z","suspendTime":"2020-02-02T11:07:00.000Z","bspReconciled":false,"complete":true,"inPlay":false,"crossMatching":true,"runnersVoidable":false,"numberOfActiveRunners":2,"betDelay":0,"status":"OPEN","runners":[{"status":"ACTIVE","sortPriority":1,"id":7412809,"name":"Evgeny Karlovskiy"},{"status":"ACTIVE","sortPriority":2,"id":2263624,"name":"Viktor Troicki"}],"regulators":["MR_INT"],"countryCode":"IN","discountAllowed":true,"timezone":"UTC","openDate":"2020-02-02T11:09:00.000Z","version":3148508172,"name":"Set 1 Winner","eventName":"Karlovskiy v Troicki"}}]}
{"op":"mcm","clk":"1009080067","pt":1580641909607,"mc":[{"id":"1.168217556","marketDefinition":{"bspMarket":false,"turnInPlayEnabled":true,"persistenceEnabled":true,"marketBaseRate":5.0,"eventId":"29681263","eventTypeId":"2","numberOfWinners":1,"bettingType":"ODDS","marketType":"SET_WINNER","marketTime":"2020-02-02T11:07:00.000Z","suspendTime":"2020-02-02T11:07:00.000Z","bspReconciled":false,"complete":true,"inPlay":false,"crossMatching":true,"runnersVoidable":false,"numberOfActiveRunners":2,"betDelay":0,"status":"OPEN","runners":[{"status":"ACTIVE","sortPriority":1,"id":7412809,"name":"Evgeny Karlovskiy"},{"status":"ACTIVE","sortPriority":2,"id":2263624,"name":"Viktor Troicki"}],"regulators":["MR_INT"],"countryCode":"IN","discountAllowed":true,"timezone":"UTC","openDate":"2020-02-02T11:07:00.000Z","version":3148508172,"name":"Set 1 Winner","eventName":"Karlovskiy v Troicki"}}]}
{"op":"mcm","clk":"1009085829","pt":1580641945886,"mc":[{"id":"1.168217556","rc":[{"batb":[[2,1.54,166.67]],"ltp":0.0,"tv":0.0,"id":2263624},{"batb":[[2,2.18,76.27]],"ltp":0.0,"tv":0.0,"id":7412809}]}]}
{"op":"mcm","clk":"1009102038","pt":1580642049085,"mc":[{"id":"1.168217556","rc":[{"batb":[[2,1.61,68.06]],"batl":[[0,1.75,42.01],[1,2.14,7.57]],"ltp":0.0,"tv":0.0,"id":2263624},{"batb":[[2,2.36,30.25]],"batl":[[0,2.66,25.21],[1,3.5,3.03]],"ltp":0.0,"tv":0.0,"id":7412809}]}]}
{"op":"mcm","clk":"1009121978","pt":1580642167716,"mc":[{"id":"1.168217556","rc":[{"trd":[[2.4,2.1]],"batb":[[0,2.38,17.07],[1,2.36,30.25],[2,2.18,76.27]],"batl":[[0,2.4,3.51],[1,2.66,25.21],[2,3.5,3.03]],"ltp":2.4,"tv":2.09,"id":7412809}],"tv":2.09}]}
{"op":"mcm","clk":"1009122414","pt":1580642170368,"mc":[{"id":"1.168217556","rc":[{"batl":[[0,2.66,25.21],[1,3.5,3.03],[2,3.5,0]],"ltp":2.4,"tv":2.09,"id":7412809}]}]}
{"op":"mcm","clk":"1009124489","pt":1580642183378,"mc":[{"id":"1.168217556","rc":[{"batb":[[0,1.64,28.76]],"ltp":0.0,"tv":0.0,"id":2263624},{"trd":[[2.38,9.12]],"batb":[[0,2.38,12.51]],"ltp":2.38,"tv":11.22,"id":7412809}],"tv":11.22}]}
{"op":"mcm","clk":"1009124520","pt":1580642183555,"mc":[{"id":"1.168217556","rc":[{"batb":[[1,1.61,68.06],[2,1.54,166.67]],"ltp":0.0,"tv":0.0,"id":2263624}]}]}
{"op":"mcm","clk":"1009134679","pt":1580642249473,"mc":[{"id":"1.168217556","rc":[{"batb":[[0,1.65,2],[1,1.64,28.76],[2,1.61,68.06]],"ltp":0.0,"tv":0.0,"id":2263624},{"batb":[[0,2.4,2],[1,2.38,12.51],[2,2.36,30.25]],"ltp":2.38,"tv":11.22,"id":7412809}]}]}
{"op":"mcm","clk":"1009142257","pt":1580642298506,"mc":[{"id":"1.168217556","marketDefinition":{"bspMarket":false,"turnInPlayEnabled":true,"persistenceEnabled":true,"marketBaseRate":5.0,"eventId":"29681263","eventTypeId":"2","numberOfWinners":1,"bettingType":"ODDS","marketType":"SET_WINNER","marketTime":"2020-02-02T11:07:00.000Z","suspendTime":"2020-02-02T11:07:00.000Z","bspReconciled":false,"complete":true,"inPlay":true,"crossMatching":true,"runnersVoidable":false,"numberOfActiveRunners":2,"betDelay":3,"status":"OPEN","runners":[{"status":"ACTIVE","sortPriority":1,"id":7412809,"name":"Evgeny Karlovskiy"},{"status":"ACTIVE","sortPriority":2,"id":2263624,"name":"Viktor Troicki"}],"regulators":["MR_INT"],"countryCode":"IN","discountAllowed":true,"timezone":"UTC","openDate":"2020-02-02T11:07:00.000Z","version":3148519489,"name":"Set 1 Winner","eventName":"Karlovskiy v Troicki"},"rc":[{"batb":[[1,1.64,1.54]],"ltp":0.0,"tv":0.0,"id":2263624},{"batb":[[1,2.36,30.25],[2,2.18,76.27]],"ltp":2.38,"tv":11.22,"id":7412809}]}]}
{"op":"mcm","clk":"1009142281","pt":1580642298583,"mc":[{"id":"1.168217556","rc":[{"batb":[[0,1.01,10.52],[1,1.64,0],[2,1.61,0]],"ltp":0.0,"tv":0.0,"id":2263624},{"batb":[[0,1.01,10.52],[1,2.36,0],[2,2.18,0]],"ltp":2.38,"tv":11.22,"id":7412809}]}]}
{"op":"mcm","clk":"1009143285","pt":1580642305432,"mc":[{"id":"1.168217556","rc":[{"batb":[[0,1.74,22.42],[1,1.61,29.35],[2,1.01,10.52]],"ltp":0.0,"tv":0.0,"id":2263624},{"batb":[[0,2.2,21.32],[1,2.08,24.78],[2,1.01,10.52]],"ltp":2.38,"tv":11.22,"id":7412809}]}]}
{"op":"mcm","clk":"1009143343","pt":1580642305846,"mc":[{"id":"1.168217556","rc":[{"batb":[[1,1.67,62.17],[2,1.61,29.35]],"batl":[[0,1.84,42.01]],"ltp":0.0,"tv":0.0,"id":2263624},{"batb":[[0,2.2,55.77]],"ltp":2.38,"tv":11.22,"id":7412809}]}]}
{"op":"mcm","clk":"1009143550","pt":1580642307246,"mc":[{"id":"1.168217556","rc":[{"batl":[[0,2.48,27.73]],"ltp":2.38,"tv":11.22,"id":7412809}]}]}
{"op":"mcm","clk":"1009144262","pt":1580642312448,"mc":[{"id":"1.168217556","rc":[{"batb":[[0,1.67,62.17],[1,1.61,29.35],[2,1.01,10.52]],"ltp":0.0,"tv":0.0,"id":2263624},{"batb":[[0,2.2,34.45]],"ltp":2.38,"tv":11.22,"id":7412809}]}]}
{"op":"mcm","clk":"1009144277","pt":1580642312552,"mc":[{"id":"1.168217556","rc":[{"batb":[[0,1.61,29.35],[1,1.01,10.52],[2,1.01,0]],"ltp":0.0,"tv":0.0,"id":2263624},{"batb":[[0,2.08,24.78],[1,1.01,10.52],[2,1.01,0]],"ltp":2.38,"tv":11.22,"id":7412809}]}]}
{"op":"mcm","clk":"1009144677","pt":1580642315364,"mc":[{"id":"1.168217556","rc":[{"batb":[[0,1.64,146.55],[1,1.63,125.23],[2,1.61,29.35]],"batl":[[0,1.92,156.21],[1,1.94,141.72]],"ltp":0.0,"tv":0.0,"id":2263624}]}]}
{"op":"mcm","clk":"1009146102","pt":1580642324184,"mc":[{"id":"1.168217556","rc":[{"batb":[[0,1.61,29.35],[1,1.01,10.52],[2,1.61,0]],"ltp":0.0,"tv":0.0,"id":2263624}]}]}
{"op":"mcm","clk":"1009146638","pt":1580642327483,"mc":[{"id":"1.168217556","rc":[{"batb":[[0,1.84,122.48],[1,1.82,170.52],[2,1.75,55.45]],"batl":[[1,1.94,183.73]],"ltp":0.0,"tv":0.0,"id":2263624},{"batb":[[0,2.08,63.43]],"batl":[[0,2.34,31.09]],"ltp":2.38,"tv":11.22,"id":7412809}]}]}
{"op":"mcm","clk":"1009146678","pt":1580642327804,"mc":[{"id":"1.168217556","rc":[{"batb":[[2,1.81,19.43]],"ltp":0.0,"tv":0.0,"id":2263624},{"batb":[[1,2,27.85],[2,1.01,10.52]],"ltp":2.38,"tv":11.22,"id":7412809}]}]}
{"op":"mcm","clk":"1009149871","pt":1580642346504,"mc":[{"id":"1.168217556","rc":[{"batb":[[0,1.71,23.6],[1,1.01,10.52],[2,1.81,0]],"ltp":0.0,"tv":0.0,"id":2263624},{"batb":[[0,2,27.85],[1,1.01,10.52],[2,1.01,0]],"ltp":2.38,"tv":11.22,"id":7412809}]}]}
{"op":"mcm","clk":"1009150338","pt":1580642349222,"mc":[{"id":"1.168217556","rc":[{"batb":[[0,1.75,111.55],[1,1.73,201.81],[2,1.71,23.6]],"batl":[[0,1.98,118.02],[1,2,129.4]],"ltp":0.0,"tv":0.0,"id":2263624}]}]}
{"op":"mcm","clk":"1009150763","pt":1580642352222,"mc":[{"id":"1.168217556","rc":[{"batb":[[0,1.71,23.6],[1,1.01,10.52],[2,1.71,0]],"ltp":0.0,"tv":0.0,"id":2263624}]}]}
{"op":"mcm","clk":"1009151246","pt":1580642355421,"mc":[{"id":"1.168217556","rc":[{"batb":[[0,1.9,114.33],[1,1.88,153.64],[2,1.71,23.6]],"batl":[[0,1.98,118.02],[1,2,129.4]],"ltp":0.0,"tv":0.0,"id":2263624}]}]}
{"op":"mcm","clk":"1009151324","pt":1580642356002,"mc":[{"id":"1.168217556","rc":[{"batb":[[1,1.88,171.03],[2,1.82,50.41]],"batl":[[1,2,171.41]],"ltp":0.0,"tv":0.0,"id":2263624},{"batb":[[0,2,69.86],[1,1.96,30.21],[2,1.01,10.52]],"batl":[[0,2.24,33.61]],"ltp":2.38,"tv":11.22,"id":7412809}]}]}
{"op":"mcm","clk":"1009151731","pt":1580642358875,"mc":[{"id":"1.168217556","rc":[{"batb":[[2,1.8,19.83]],"ltp":0.0,"tv":0.0,"id":2263624}]}]}
{"op":"mcm","clk":"1009152138","pt":1580642361711,"mc":[{"id":"1.168217556","rc":[{"batb":[[2,1.81,51.25]],"ltp":0.0,"tv":0.0,"id":2263624}]}]}
{"op":"mcm","clk":"1009152926","pt":1580642367453,"mc":[{"id":"1.168217556","rc":[{"batb":[[0,1.81,51.25],[1,1.8,19.83],[2,1.01,10.52]],"batl":[[0,2,42.01],[1,2,0]],"ltp":0.0,"tv":0.0,"id":2263624},{"batb":[[0,2,42.01]],"ltp":2.38,"tv":11.22,"id":7412809}]}]}
{"op":"mcm","clk":"1009153233","pt":1580642369250,"mc":[{"id":"1.168217556","rc":[{"batb":[[0,1.8,19.83],[1,1.01,10.52],[2,1.01,0]],"ltp":0.0,"tv":0.0,"id":2263624},{"batb":[[0,1.96,30.21],[1,1.01,10.52],[2,1.01,0]],"ltp":2.38,"tv":11.22,"id":7412809}]}]}
{"op":"mcm","clk":"1009153665","pt":1580642372238,"mc":[{"id":"1.168217556","rc":[{"batb":[[0,1.89,102.31],[1,1.87,156.26],[2,1.8,19.83]],"batl":[[0,1.97,136.65],[1,1.99,131.32]],"ltp":0.0,"tv":0.0,"id":2263624}]}]}
{"op":"mcm","clk":"1009154571","pt":1580642378437,"mc":[{"id":"1.168217556","rc":[{"batb":[[0,1.8,19.83],[1,1.01,10.52],[2,1.8,0]],"ltp":0.0,"tv":0.0,"id":2263624}]}]}
{"op":"mcm","clk":"1009155011","pt":1580642381461,"mc":[{"id":"1.168217556","rc":[{"batb":[[0,1.84,143.8],[1,1.82,170.55],[2,1.8,19.83]],"batl":[[0,2.02,127.71],[1,2.04,122.06]],"ltp":0.0,"tv":0.0,"id":2263624}]}]}
{"op":"mcm","clk":"1009155388","pt":1580642383973,"mc":[{"id":"1.168217556","rc":[{"batl":[[0,1.92,135.91],[1,1.94,141.75]],"ltp":0.0,"tv":0.0,"id":2263624}]}]}
{"op":"mcm","clk":"1009155590","pt":1580642385459,"mc":[{"id":"1.168217556","rc":[{"batl":[[1,1.93,42.01],[2,1.94,141.75]],"ltp":0.0,"tv":0.0,"id":2263624},{"batb":[[0,2.1,24.31],[1,2.08,38.65],[2,2.02,27.38]],"batl":[[0,2.34,31.09]],"ltp":2.38,"tv":11.22,"id":7412809}]}]}
{"op":"mcm","clk":"1009157860","pt":1580642402477,"mc":[{"id":"1.168217556","rc":[{"batb":[[0,1.71,23.76],[1,1.01,10.52],[2,1.8,0]],"ltp":0.0,"tv":0.0,"id":2263624},{"batb":[[0,2.02,27.38],[1,1.01,10.52],[2,2.02,0]],"ltp":2.38,"tv":11.22,"id":7412809}]}]}
{"op":"mcm","clk":"1009158287","pt":1580642404895,"mc":[{"id":"1.168217556","rc":[{"batb":[[0,1.75,178.61],[1,1.73,202.05],[2,1.71,23.76]],"batl":[[0,1.98,116.12],[1,2,129.4]],"ltp":0.0,"tv":0.0,"id":2263624}]}]}
{"op":"mcm","clk":"1009161557","pt":1580642425446,"mc":[{"id":"1.168217556","rc":[{"batb":[[0,1.71,23.76],[1,1.01,10.52],[2,1.71,0]],"ltp":0.0,"tv":0.0,"id":2263624}]}]}
{"op":"mcm","clk":"1009161970","pt":1580642428151,"mc":[{"id":"1.168217556","rc":[{"batb":[[0,1.9,116.32],[1,1.88,153.64],[2,1.71,23.76]],"ltp":0.0,"tv":0.0,"id":2263624}]}]}
{"op":"mcm","clk":"1009162151","pt":1580642429426,"mc":[{"id":"1.168217556","rc":[{"batb":[[2,1.87,17.7]],"ltp":0.0,"tv":0.0,"id":2263624},{"batb":[[1,1.82,19.12],[2,1.01,10.52]],"ltp":2.38,"tv":11.22,"id":7412809}]}]}
{"op":"mcm","clk":"1009162168","pt":1580642429531,"mc":[{"id":"1.168217556","rc":[{"batl":[[2,2.02,41.17]],"ltp":0.0,"tv":0.0,"id":2263624},{"batb":[[1,1.97,42.85],[2,1.82,19.12]],"batl":[[0,2.22,33.61]],"ltp":2.38,"tv":11.22,"id":7412809}]}]}
{"op":"mcm","clk":"1009164654","pt":1580642446215,"mc":[{"id":"1.168217556","rc":[{"trd":[[2.02,21.11]],"batb":[[0,2.02,16.83]],"ltp":2.02,"tv":32.33,"id":7412809}],"tv":32.33}]}
{"op":"mcm","clk":"1009167444","pt":1580642465251,"mc":[{"id":"1.168217556","rc":[{"batb":[[0,1.87,17.7],[1,1.84,49.57],[2,1.77,21.24]],"batl":[[0,2.02,41.17],[1,2,0],[2,2.02,0]],"ltp":0.0,"tv":0.0,"id":2263624}]}]}
{"op":"mcm","clk":"1009167903","pt":1580642468201,"mc":[{"id":"1.168217556","rc":[{"batb":[[2,1.79,193.06]],"batl":[[1,2.22,96.46],[2,2.24,93.49]],"ltp":0.0,"tv":0.0,"id":2263624}]}]}
{"op":"mcm","clk":"1009169378","pt":1580642478509,"mc":[{"id":"1.168217556","rc":[{"batb":[[0,1.79,193.06],[1,1.77,208.32],[2,1.01,10.52]],"batl":[[0,2.22,96.46],[1,2.24,93.49],[2,2.24,0]],"ltp":0.0,"tv":0.0,"id":2263624},{"batb":[[0,1.82,19.12],[1,1.01,10.52],[2,1.82,0]],"ltp":2.02,"tv":32.33,"id":7412809}]}]}
{"op":"mcm","clk":"1009169707","pt":1580642480992,"mc":[{"id":"1.168217556","rc":[{"batb":[[0,1.79,214.15],[1,1.77,187.08]],"ltp":0.0,"tv":0.0,"id":2263624},{"batb":[[0,1.81,19.28]],"ltp":2.02,"tv":32.33,"id":7412809}]}]}
{"op":"mcm","clk":"1009170844","pt":1580642489502,"mc":[{"id":"1.168217556","rc":[{"batb":[[2,1.75,55.45]],"batl":[[0,1.87,134.1],[1,1.89,153.53],[2,1.92,42.01]],"ltp":0.0,"tv":0.0,"id":2263624},{"batb":[[0,2.1,37.81],[1,1.81,19.28],[2,1.01,10.52]],"batl":[[0,2.36,30.25]],"ltp":2.02,"tv":32.33,"id":7412809}]}]}
{"op":"mcm","clk":"1009170910","pt":1580642490026,"mc":[{"id":"1.168217556","rc":[{"batb":[[0,2.14,22.82],[1,2.1,37.81],[2,1.95,30.53]],"ltp":2.02,"tv":32.33,"id":7412809}]}]}
{"op":"mcm","clk":"1009172204","pt":1580642500455,"mc":[{"id":"1.168217556","rc":[{"batb":[[0,1.79,193.06]],"ltp":0.0,"tv":0.0,"id":2263624},{"batb":[[0,2.1,37.81],[1,1.95,30.53],[2,1.01,10.52]],"ltp":2.02,"tv":32.33,"id":7412809}]}]}
{"op":"mcm","clk":"1009172225","pt":1580642500558,"mc":[{"id":"1.168217556","rc":[{"batb":[[0,1.72,23.84],[1,1.01,10.52],[2,1.75,0]],"ltp":0.0,"tv":0.0,"id":2263624},{"batb":[[0,1.95,30.53],[1,1.01,10.52],[2,1.01,0]],"ltp":2.02,"tv":32.33,"id":7412809}]}]}
{"op":"mcm","clk":"1009172640","pt":1580642503451,"mc":[{"id":"1.168217556","rc":[{"batb":[[0,1.72,219.97],[1,1.7,214.65],[2,1.01,10.52]],"batl":[[0,2.04,160.47],[1,2.06,118.63]],"ltp":0.0,"tv":0.0,"id":2263624}]}]}
{"op":"mcm","clk":"1009173176","pt":1580642507437,"mc":[{"id":"1.168217556","rc":[{"batb":[[2,1.67,26.44]],"batl":[[0,1.79,118.54],[1,1.81,175.93]],"ltp":0.0,"tv":0.0,"id":2263624},{"batb":[[0,2.24,19.91],[1,2.1,24.39],[2,1.95,30.53]],"ltp":2.02,"tv":32.33,"id":7412809}]}]}
{"op":"mcm","clk":"1009173187","pt":1580642507545,"mc":[{"id":"1.168217556","rc":[{"batb":[[2,1.68,61.33]],"batl":[[2,1.82,42.01]],"ltp":0.0,"tv":0.0,"id":2263624},{"batb":[[1,2.2,34.45],[2,2.1,24.39]],"batl":[[0,2.5,27.73]],"ltp":2.02,"tv":32.33,"id":7412809}]}]}
{"op":"mcm","clk":"1009174185","pt":1580642514858,"mc":[{"id":"1.168217556","rc":[{"batb":[[0,1.68,61.33],[1,1.67,26.44],[2,1.01,10.52]],"batl":[[0,1.82,42.01],[1,1.81,0],[2,1.82,0]],"ltp":0.0,"tv":0.0,"id":2263624},{"batb":[[0,2.2,34.45],[1,2.1,24.39],[2,1.01,10.52]],"ltp":2.02,"tv":32.33,"id":7412809}]}]}
{"op":"mcm","clk":"1009174454","pt":1580642516578,"mc":[{"id":"1.168217556","rc":[{"batb":[[0,1.67,26.44],[1,1.01,10.52],[2,1.01,0]],"ltp":0.0,"tv":0.0,"id":2263624},{"batb":[[0,2.1,24.39],[1,1.01,10.52],[2,1.01,0]],"ltp":2.02,"tv":32.33,"id":7412809}]}]}
{"op":"mcm","clk":"1009174680","pt":1580642518067,"mc":[{"id":"1.168217556","rc":[{"batb":[[0,1.68,166.27],[1,1.67,26.44],[2,1.66,233.23]],"batl":[[0,1.89,138.25],[1,1.91,148.64]],"ltp":0.0,"tv":0.0,"id":2263624}]}]}
{"op":"mcm","clk":"1009176057","pt":1580642527483,"mc":[{"id":"1.168217556","rc":[{"batl":[[0,1.75,191.77],[1,1.77,188.81]],"ltp":0.0,"tv":0.0,"id":2263624}]}]}
{"op":"mcm","clk":"1009176154","pt":1580642528077,"mc":[{"id":"1.168217556","rc":[{"batl":[[1,1.77,230.82]],"ltp":0.0,"tv":0.0,"id":2263624},{"batb":[[0,2.34,17.7],[1,2.28,32.77],[2,2.22,20.54]],"batl":[[0,2.58,26.05]],"ltp":2.02,"tv":32.33,"id":7412809}]}]}
{"op":"mcm","clk":"1009177190","pt":1580642535306,"mc":[{"id":"1.168217556","rc":[{"batb":[[0,1.67,26.44],[1,1.66,141.16],[2,1.64,65.54]],"batl":[[0,1.77,42.01],[1,1.77,0]],"ltp":0.0,"tv":0.0,"id":2263624}]}]}
{"op":"mcm","clk":"1009177339","pt":1580642536180,"mc":[{"id":"1.168217556","rc":[{"batb":[[0,1.66,141.16],[1,1.64,65.54],[2,1.63,28.33]],"ltp":0.0,"tv":0.0,"id":2263624},{"batb":[[0,2.28,32.77],[1,2.22,20.54],[2,1.86,398.62]],"ltp":2.02,"tv":32.33,"id":7412809}]}]}
{"op":"mcm","clk":"1009177405","pt":1580642536596,"mc":[{"id":"1.168217556","rc":[{"batb":[[1,1.63,28.33],[2,1.44,436.19]],"ltp":0.0,"tv":0.0,"id":2263624},{"batb":[[0,2.22,20.54],[1,1.86,398.62],[2,1.01,10.52]],"ltp":2.02,"tv":32.33,"id":7412809}]}]}
{"op":"mcm","clk":"1009177662","pt":1580642538408,"mc":[{"id":"1.168217556","rc":[{"batb":[[0,1.63,28.33],[1,1.44,436.19],[2,1.01,10.51]],"ltp":0.0,"tv":0.0,"id":2263624}]}]}
{"op":"mcm","clk":"1009178235","pt":1580642541392,"mc":[{"id":"1.168217556","rc":[{"batb":[[0,1.69,153.13],[1,1.67,228.25],[2,1.63,28.33]],"batl":[[0,1.76,192.41],[1,1.78,185.38]],"ltp":0.0,"tv":0.0,"id":2263624}]}]}
{"op":"mcm","clk":"1009178615","pt":1580642543925,"mc":[{"id":"1.168217556","rc":[{"batb":[[0,1.63,28.33],[1,1.44,436.19],[2,1.01,10.51]],"ltp":0.0,"tv":0.0,"id":2263624}]}]}
{"op":"mcm","clk":"1009179034","pt":1580642546718,"mc":[{"id":"1.168217556","rc":[{"batb":[[0,1.66,141.16],[1,1.65,119.82],[2,1.63,28.33]],"ltp":0.0,"tv":0.0,"id":2263624}]}]}
{"op":"mcm","clk":"1009179461","pt":1580642549522,"mc":[{"id":"1.168217556","rc":[{"batl":[[0,1.72,139.71],[1,1.73,42.01],[2,1.74,199.96]],"ltp":0.0,"tv":0.0,"id":2263624},{"batb":[[0,2.42,16.37],[1,2.34,31.09],[2,2.22,20.38]],"batl":[[0,2.68,24.37]],"ltp":2.02,"tv":32.33,"id":7412809}]}]}
{"op":"mcm","clk":"1009183710","pt":1580642577490,"mc":[{"id":"1.168217556","rc":[{"batb":[[0,1.6,69.74],[1,1.5,39.18],[2,1.44,436.19]],"batl":[[0,1.73,42.01],[1,1.73,0],[2,1.74,0]],"ltp":0.0,"tv":0.0,"id":2263624},{"batb":[[0,2.34,31.09],[1,2.22,20.38],[2,1.86,398.62]],"ltp":2.02,"tv":32.33,"id":7412809}]}]}
{"op":"mcm","clk":"1009183900","pt":1580642578615,"mc":[{"id":"1.168217556","rc":[{"batb":[[0,1.5,39.18],[1,1.44,436.19],[2,1.01,10.51]],"ltp":0.0,"tv":0.0,"id":2263624},{"batb":[[0,2.22,20.38],[1,1.86,398.62],[2,1.01,10.52]],"ltp":2.02,"tv":32.33,"id":7412809}]}]}
{"op":"mcm","clk":"1009184199","pt":1580642580487,"mc":[{"id":"1.168217556","rc":[{"batb":[[0,1.52,233.92],[1,1.51,168.05],[2,1.5,39.18]],"batl":[[0,1.82,108.48],[1,1.84,167]],"ltp":0.0,"tv":0.0,"id":2263624},{"batb":[[0,2.24,20.38],[1,2.22,20.38],[2,1.86,398.62]],"ltp":2.02,"tv":32.33,"id":7412809}]}]}
{"op":"mcm","clk":"1009184310","pt":1580642581287,"mc":[{"id":"1.168217556","rc":[{"batb":[[1,1.86,398.62],[2,1.01,10.52]],"ltp":2.02,"tv":32.33,"id":7412809}]}]}
{"op":"mcm","clk":"1009186184","pt":1580642594410,"mc":[{"id":"1.168217556","rc":[{"batb":[[0,1.5,39.18],[1,1.44,436.19],[2,1.01,10.51]],"ltp":0.0,"tv":0.0,"id":2263624}]}]}
{"op":"mcm","clk":"1009186285","pt":1580642595109,"mc":[{"id":"1.168217556","rc":[{"batb":[[1,1.01,10.52],[2,1.01,0]],"ltp":0.0,"tv":0.0,"id":2263624},{"batb":[[1,1.01,10.52],[2,1.01,0]],"ltp":2.02,"tv":32.33,"id":7412809}]}]}
{"op":"mcm","clk":"1009186582","pt":1580642597251,"mc":[{"id":"1.168217556","rc":[{"batb":[[0,1.52,233.92],[1,1.51,168.05],[2,1.5,39.18]],"batl":[[0,1.58,255.03],[1,1.59,135.38]],"ltp":0.0,"tv":0.0,"id":2263624}]}]}
{"op":"mcm","clk":"1009186707","pt":1580642598127,"mc":[{"id":"1.168217556","rc":[{"batb":[[0,2.8,11.09],[1,2.5,14.95],[2,1.01,10.52]],"batl":[[0,3.05,20.16]],"ltp":2.02,"tv":32.33,"id":7412809}]}]}
{"op":"mcm","clk":"1009186900","pt":1580642599420,"mc":[{"id":"1.168217556","rc":[{"batb":[[2,2.04,394.09]],"ltp":2.02,"tv":32.33,"id":7412809}]}]}
{"op":"mcm","clk":"1009187006","pt":1580642600153,"mc":[{"id":"1.168217556","rc":[{"batl":[[2,1.6,42.01]],"ltp":0.0,"tv":0.0,"id":2263624},{"batb":[[1,2.66,25.21],[2,2.5,14.95]],"ltp":2.02,"tv":32.33,"id":7412809}]}]}
{"op":"mcm","clk":"1009187868","pt":1580642606234,"mc":[{"id":"1.168217556","rc":[{"trd":[[1.52,70.74]],"batb":[[0,1.52,198.54]],"ltp":1.52,"tv":70.74,"id":2263624}],"tv":103.07}]}
{"op":"mcm","clk":"1009187917","pt":1580642606665,"mc":[{"id":"1.168217556","rc":[{"batl":[[0,1.58,139.23],[1,1.6,42.01],[2,1.6,0]],"ltp":1.52,"tv":70.74,"id":2263624}]}]}
{"op":"mcm","clk":"1009188448","pt":1580642610044,"mc":[{"id":"1.168217556","rc":[{"batl":[[0,1.57,129.06],[1,1.58,139.23],[2,1.6,42.01]],"ltp":1.52,"tv":70.74,"id":2263624}]}]}
{"op":"mcm","clk":"1009189818","pt":1580642619465,"mc":[{"id":"1.168217556","rc":[{"batb":[[0,1.5,39.18],[1,1.49,85.7],[2,1.35,61.07]],"batl":[[0,1.6,42.01],[1,1.58,0],[2,1.6,0]],"ltp":1.52,"tv":70.74,"id":2263624}]}]}
{"op":"mcm","clk":"1009189866","pt":1580642619891,"mc":[{"id":"1.168217556","rc":[{"batb":[[0,1.49,85.7],[1,1.35,61.07],[2,1.34,465.43]],"ltp":1.52,"tv":70.74,"id":2263624},{"batb":[[0,2.66,25.21],[1,2.5,14.95],[2,2.04,394.09]],"ltp":2.02,"tv":32.33,"id":7412809}]}]}
{"op":"mcm","clk":"1009189995","pt":1580642620646,"mc":[{"id":"1.168217556","rc":[{"batb":[[0,1.35,61.07],[1,1.34,465.43],[2,1.01,10.51]],"ltp":1.52,"tv":70.74,"id":2263624},{"batb":[[0,2.5,14.95],[1,2.04,394.09],[2,1.01,10.52]],"ltp":2.02,"tv":32.33,"id":7412809}]}]}
{"op":"mcm","clk":"1009190255","pt":1580642622466,"mc":[{"id":"1.168217556","rc":[{"batb":[[0,1.38,158.33],[1,1.37,255.97],[2,1.35,61.06]],"batl":[[0,1.69,177.43],[1,1.71,211.85]],"ltp":1.52,"tv":70.74,"id":2263624}]}]}
{"op":"mcm","clk":"1009190302","pt":1580642622773,"mc":[{"id":"1.168217556","rc":[{"batb":[[0,1.35,61.07],[1,1.34,465.43],[2,1.01,10.51]],"ltp":1.52,"tv":70.74,"id":2263624}]}]}
{"op":"mcm","clk":"1009190855","pt":1580642626648,"mc":[{"id":"1.168217556","rc":[{"batb":[[0,1.49,200.43],[1,1.48,182.29],[2,1.35,61.06]],"batl":[[0,1.54,199.33],[1,1.55,149.2]],"ltp":1.52,"tv":70.74,"id":2263624}]}]}
{"op":"mcm","clk":"1009191569","pt":1580642631753,"mc":[{"id":"1.168217556","rc":[{"batb":[[0,1.35,61.07],[1,1.34,465.43],[2,1.01,10.51]],"ltp":1.52,"tv":70.74,"id":2263624}]}]}
{"op":"mcm","clk":"1009192157","pt":1580642635479,"mc":[{"id":"1.168217556","rc":[{"batb":[[0,1.38,158.33],[1,1.37,255.97],[2,1.35,61.06]],"batl":[[0,1.69,177.43],[1,1.71,211.85]],"ltp":1.52,"tv":70.74,"id":2263624},{"batb":[[1,1.01,10.52],[2,1.01,0]],"ltp":2.02,"tv":32.33,"id":7412809}]}]}
{"op":"mcm","clk":"1009192414","pt":1580642637506,"mc":[{"id":"1.168217556","rc":[{"trd":[[1.48,0.02]],"batb":[[0,1.38,158.32]],"batl":[[0,1.42,296.09],[1,1.43,205.08]],"ltp":1.48,"tv":70.76,"id":2263624}],"tv":103.09}]}
{"op":"mcm","clk":"1009192558","pt":1580642638490,"mc":[{"id":"1.168217556","rc":[{"batb":[[2,1.36,115.95]],"ltp":1.48,"tv":70.76,"id":2263624},{"batb":[[0,3.45,15.89],[1,2.98,23.6],[2,1.01,10.52]],"batl":[[0,3.75,15.12]],"ltp":2.02,"tv":32.33,"id":7412809}]}]}
{"op":"mcm","clk":"1009192855","pt":1580642640414,"mc":[{"id":"1.168217556","rc":[{"batl":[[2,1.46,42.01]],"ltp":1.48,"tv":70.76,"id":2263624},{"batb":[[1,3.2,18.48],[2,2.98,23.6]],"ltp":2.02,"tv":32.33,"id":7412809}]}]}
{"op":"mcm","clk":"1009194507","pt":1580642651700,"mc":[{"id":"1.168217556","rc":[{"batb":[[0,1.36,115.95],[1,1.22,624.97],[2,1.01,10.51]],"batl":[[0,1.46,42.01],[1,1.43,0],[2,1.46,0]],"ltp":1.48,"tv":70.76,"id":2263624},{"batb":[[0,3.2,18.48],[1,2.98,23.6],[2,2.42,381.73]],"ltp":2.02,"tv":32.33,"id":7412809}]}]}
{"op":"mcm","clk":"1009194650","pt":1580642652600,"mc":[{"id":"1.168217556","rc":[{"batb":[[0,1.22,624.97],[1,1.01,10.51],[2,1.01,0]],"ltp":1.48,"tv":70.76,"id":2263624},{"batb":[[0,2.98,23.6],[1,2.42,381.73],[2,1.01,10.52]],"ltp":2.02,"tv":32.33,"id":7412809}]}]}
{"op":"mcm","clk":"1009194957","pt":1580642654578,"mc":[{"id":"1.168217556","rc":[{"batb":[[0,1.25,353.56],[1,1.24,442.86],[2,1.22,624.97]],"batl":[[0,1.52,202.53],[1,1.53,156.73]],"ltp":1.48,"tv":70.76,"id":2263624}]}]}
{"op":"mcm","clk":"1009195859","pt":1580642660449,"mc":[{"id":"1.168217556","rc":[{"batb":[[0,1.22,624.97],[1,1.01,10.51],[2,1.22,0]],"ltp":1.48,"tv":70.76,"id":2263624}]}]}
{"op":"mcm","clk":"1009196310","pt":1580642663505,"mc":[{"id":"1.168217556","rc":[{"batb":[[0,1.47,237.48],[1,1.46,193.22],[2,1.22,101.97]],"batl":[[2,1.55,42.01]],"ltp":1.48,"tv":70.76,"id":2263624},{"batb":[[1,2.84,22.69],[2,2.42,381.73]],"ltp":2.02,"tv":32.33,"id":7412809}]}]}
{"op":"mcm","clk":"1009196424","pt":1580642664311,"mc":[{"id":"1.168217556","rc":[{"batb":[[2,1.44,140.18]],"ltp":1.48,"tv":70.76,"id":2263624},{"batb":[[2,2.56,13.85]],"batl":[[0,3.25,18.48]],"ltp":2.02,"tv":32.33,"id":7412809}]}]}
{"op":"mcm","clk":"1009199585","pt":1580642686165,"mc":[{"id":"1.168217556","rc":[{"batb":[[0,1.44,94.94],[1,1.28,565.44],[2,1.01,10.51]],"batl":[[0,1.55,42.01],[1,1.53,0],[2,1.55,0]],"ltp":1.48,"tv":70.76,"id":2263624},{"batb":[[0,2.84,22.69],[1,2.56,13.85],[2,2.42,381.73]],"ltp":2.02,"tv":32.33,"id":7412809}]}]}
{"op":"mcm","clk":"1009199646","pt":1580642686537,"mc":[{"id":"1.168217556","rc":[{"batb":[[0,1.28,565.44],[1,1.01,10.51],[2,1.01,0]],"ltp":1.48,"tv":70.76,"id":2263624},{"batb":[[0,2.56,13.85],[1,2.42,381.73],[2,1.01,10.52]],"ltp":2.02,"tv":32.33,"id":7412809}]}]}
{"op":"mcm","clk":"1009200000","pt":1580642689034,"mc":[{"id":"1.168217556","rc":[{"batb":[[0,1.3,465.78],[1,1.29,353.37],[2,1.28,565.44]],"batl":[[0,1.66,185.84],[1,1.68,224.93]],"ltp":1.48,"tv":70.76,"id":2263624}]}]}
{"op":"mcm","clk":"1009201738","pt":1580642701456,"mc":[{"id":"1.168217556","rc":[{"batb":[[2,1.28,79.55]],"batl":[[0,1.34,274.11],[1,1.35,266.29]],"ltp":1.48,"tv":70.76,"id":2263624},{"batb":[[1,1.01,10.52],[2,1.01,0]],"ltp":2.02,"tv":32.33,"id":7412809}]}]}
{"op":"mcm","clk":"1009201853","pt":1580642702259,"mc":[{"id":"1.168217556","rc":[{"batb":[[0,1.3,605.25]],"batl":[[2,1.38,42.01]],"ltp":1.48,"tv":70.76,"id":2263624},{"batb":[[0,4,22.35],[1,3.6,15.96],[2,3.3,17.7]],"batl":[[0,4.3,12.6]],"ltp":2.02,"tv":32.33,"id":7412809}]}]}
{"op":"mcm","clk":"1009204994","pt":1580642724906,"mc":[{"id":"1.168217556","rc":[{"batb":[[0,1.3,139.47],[1,1.18,549.72],[2,1.15,154.14]],"batl":[[0,1.38,42.01],[1,1.35,0],[2,1.38,0]],"ltp":1.48,"tv":70.76,"id":2263624},{"batb":[[0,3.6,15.96],[1,3.3,17.7],[2,2.62,379.26]],"ltp":2.02,"tv":32.33,"id":7412809}]}]}
{"op":"mcm","clk":"1009205245","pt":1580642726704,"mc":[{"id":"1.168217556","rc":[{"batb":[[0,1.18,549.72],[1,1.15,154.14],[2,1.01,10.51]],"ltp":1.48,"tv":70.76,"id":2263624},{"batb":[[0,3.3,17.7],[1,2.62,379.26],[2,1.01,10.52]],"ltp":2.02,"tv":32.33,"id":7412809}]}]}
{"op":"mcm","clk":"1009205432","pt":1580642727875,"mc":[{"id":"1.168217556","rc":[{"batb":[[0,1.18,869.37],[1,1.17,664.2],[2,1.15,154.14]],"batl":[[0,1.45,320.95],[1,1.46,187.87]],"ltp":1.48,"tv":70.76,"id":2263624}]}]}
{"op":"mcm","clk":"1009205597","pt":1580642728985,"mc":[{"id":"1.168217556","rc":[{"batb":[[0,1.18,549.72],[1,1.15,154.14],[2,1.01,10.51]],"ltp":1.48,"tv":70.76,"id":2263624}]}]}
{"op":"mcm","clk":"1009206195","pt":1580642733006,"mc":[{"id":"1.168217556","rc":[{"batb":[[0,1.28,214.85],[1,1.27,381.1],[2,1.18,549.72]],"batl":[[0,1.31,295.87],[1,1.32,297.27]],"ltp":1.48,"tv":70.76,"id":2263624}]}]}
{"op":"mcm","clk":"1009206965","pt":1580642738402,"mc":[{"id":"1.168217556","rc":[{"batb":[[0,1.18,549.72],[1,1.15,154.14],[2,1.01,10.51]],"ltp":1.48,"tv":70.76,"id":2263624}]}]}
{"op":"mcm","clk":"1009207388","pt":1580642741409,"mc":[{"id":"1.168217556","rc":[{"batb":[[0,1.18,869.37],[1,1.17,664.2],[2,1.15,154.14]],"batl":[[0,1.45,320.95],[1,1.46,187.87]],"ltp":1.48,"tv":70.76,"id":2263624}]}]}
{"op":"mcm","clk":"1009207823","pt":1580642744515,"mc":[{"id":"1.168217556","rc":[{"batb":[[0,1.18,549.72],[1,1.15,154.14],[2,1.01,10.51]],"ltp":1.48,"tv":70.76,"id":2263624}]}]}
{"op":"mcm","clk":"1009208106","pt":1580642746438,"mc":[{"id":"1.168217556","rc":[{"batb":[[0,1.15,154.14],[1,1.01,10.51],[2,1.01,0]],"ltp":1.48,"tv":70.76,"id":2263624}]}]}
{"op":"mcm","clk":"1009208403","pt":1580642748414,"mc":[{"id":"1.168217556","rc":[{"batb":[[0,1.4,288.79],[1,1.39,240.67],[2,1.38,110.07]],"batl":[[0,1.45,320.95],[1,1.46,187.87],[2,1.48,42.01]],"ltp":1.48,"tv":70.76,"id":2263624},{"batb":[[1,3.1,19.32],[2,2.62,392.47]],"batl":[[0,3.6,15.96]],"ltp":2.02,"tv":32.33,"id":7412809}]}]}
{"op":"mcm","clk":"1009211397","pt":1580642769073,"mc":[{"id":"1.168217556","rc":[{"batb":[[0,1.38,110.07],[1,1.23,516.48],[2,1.16,147.29]],"batl":[[0,1.48,42.01],[1,1.46,0],[2,1.48,0]],"ltp":1.48,"tv":70.76,"id":2263624},{"batb":[[0,3.1,19.32],[1,2.62,392.47],[2,1.01,10.52]],"ltp":2.02,"tv":32.33,"id":7412809}]}]}
{"op":"mcm","clk":"1009211617","pt":1580642770651,"mc":[{"id":"1.168217556","rc":[{"batb":[[0,1.16,147.29],[1,1.01,10.51],[2,1.16,0]],"ltp":1.48,"tv":70.76,"id":2263624},{"batb":[[0,2.62,13.22],[1,1.01,10.52],[2,1.01,0]],"ltp":2.02,"tv":32.33,"id":7412809}]}]}
{"op":"mcm","clk":"1009211804","pt":1580642771836,"mc":[{"id":"1.168217556","rc":[{"batb":[[0,1.18,564.31],[1,1.17,526.34],[2,1.16,147.29]],"batl":[[0,1.65,184.69],[1,1.66,116.57]],"ltp":1.48,"tv":70.76,"id":2263624}]}]}
{"op":"mcm","clk":"1009214889","pt":1580642792460,"mc":[{"id":"1.168217556","rc":[{"batb":[[0,1.18,732.35]],"batl":[[0,1.21,554.92],[1,1.22,457.81],[2,1.23,42.01]],"ltp":1.48,"tv":70.76,"id":2263624},{"batb":[[0,5.9,18.02],[1,5.3,9.24],[2,4.6,16.29]],"batl":[[0,6.6,6.72]],"ltp":2.02,"tv":32.33,"id":7412809}]}]}
{"op":"mcm","clk":"1009217452","pt":1580642808231,"mc":[{"id":"1.168217556","rc":[{"batb":[[0,1.18,695.02]],"ltp":1.48,"tv":70.76,"id":2263624}]}]}
{"op":"mcm","clk":"1009217898","pt":1580642810952,"mc":[{"id":"1.168217556","rc":[{"batb":[[1,1.17,563.99]],"batl":[[0,1.21,591.37]],"ltp":1.48,"tv":70.76,"id":2263624}]}]}
{"op":"mcm","clk":"1009227217","pt":1580642870319,"mc":[{"id":"1.168217556","rc":[{"batb":[[0,1.18,168.04],[1,1.13,183.25],[2,1.09,779.05]],"batl":[[0,1.23,42.01],[1,1.22,0],[2,1.23,0]],"ltp":1.48,"tv":70.76,"id":2263624},{"batb":[[0,5.3,9.24],[1,4.6,16.29],[2,3.15,373.59]],"ltp":2.02,"tv":32.33,"id":7412809}]}]}
{"op":"mcm","clk":"1009227264","pt":1580642870645,"mc":[{"id":"1.168217556","rc":[{"batb":[[0,1.13,183.25],[1,1.09,779.05],[2,1.01,10.51]],"ltp":1.48,"tv":70.76,"id":2263624},{"batb":[[0,4.6,16.29],[1,3.15,373.59],[2,1.01,10.52]],"ltp":2.02,"tv":32.33,"id":7412809}]}]}
{"op":"mcm","clk":"1009227622","pt":1580642873305,"mc":[{"id":"1.168217556","rc":[{"batb":[[0,1.15,496.72],[1,1.14,623.23],[2,1.13,183.25]],"batl":[[0,1.28,341.78],[1,1.29,335.08]],"ltp":1.48,"tv":70.76,"id":2263624}]}]}
{"op":"mcm","clk":"1009228773","pt":1580642881209,"mc":[{"id":"1.168217556","rc":[{"batb":[[0,1.13,183.25],[1,1.09,779.05],[2,1.01,10.51]],"ltp":1.48,"tv":70.76,"id":2263624}]}]}
{"op":"mcm","clk":"1009229249","pt":1580642884538,"mc":[{"id":"1.168217556","rc":[{"batb":[[0,1.19,669.91],[1,1.18,410.61],[2,1.13,183.25]],"batl":[[0,1.22,380.62],[1,1.23,440.73]],"ltp":1.48,"tv":70.76,"id":2263624}]}]}
{"op":"mcm","clk":"1009229822","pt":1580642888362,"mc":[{"id":"1.168217556","rc":[{"batb":[[0,1.13,183.25],[1,1.09,779.05],[2,1.01,10.51]],"ltp":1.48,"tv":70.76,"id":2263624}]}]}
{"op":"mcm","clk":"1009230172","pt":1580642890941,"mc":[{"id":"1.168217556","rc":[{"batb":[[0,1.15,496.52],[1,1.14,623.43],[2,1.13,183.25]],"batl":[[0,1.28,342.12],[1,1.29,335.08]],"ltp":1.48,"tv":70.76,"id":2263624}]}]}
{"op":"mcm","clk":"1009233268","pt":1580642913453,"mc":[{"id":"1.168217556","rc":[{"batb":[[0,1.15,427.58]],"batl":[[0,1.17,347.21],[1,1.18,586.77]],"ltp":1.48,"tv":70.76,"id":2263624},{"batb":[[0,6.8,12.67],[1,5.5,10.7],[2,4.6,16.29]],"ltp":2.02,"tv":32.33,"id":7412809}]}]}
{"op":"mcm","clk":"1009233386","pt":1580642914258,"mc":[{"id":"1.168217556","rc":[{"batb":[[0,1.15,595.62]],"ltp":1.48,"tv":70.76,"id":2263624},{"batb":[[1,6.2,7.56],[2,5.5,10.7]],"batl":[[0,7.8,5.88]],"ltp":2.02,"tv":32.33,"id":7412809}]}]}
{"op":"mcm","clk":"1009233687","pt":1580642916265,"mc":[{"id":"1.168217556","rc":[{"batb":[[1,1.14,692.98]],"batl":[[0,1.17,414.97]],"ltp":1.48,"tv":70.76,"id":2263624}]}]}
{"op":"mcm","clk":"1009235437","pt":1580642927998,"mc":[{"id":"1.168217556","rc":[{"batb":[[0,1.15,168.04],[1,1.11,224.79],[2,1.07,893.98]],"ltp":1.48,"tv":70.76,"id":2263624},{"batb":[[0,6.2,7.56],[1,5.5,10.7],[2,3.15,373.59]],"ltp":2.02,"tv":32.33,"id":7412809}]}]}
{"op":"mcm","clk":"1009235558","pt":1580642928786,"mc":[{"id":"1.168217556","rc":[{"batb":[[0,1.11,224.79],[1,1.07,893.98],[2,1.01,10.51]],"ltp":1.48,"tv":70.76,"id":2263624},{"batb":[[0,5.5,10.7],[1,3.15,373.59],[2,1.01,10.52]],"ltp":2.02,"tv":32.33,"id":7412809}]}]}
{"op":"mcm","clk":"1009235928","pt":1580642931511,"mc":[{"id":"1.168217556","rc":[{"batb":[[0,1.13,295.27],[1,1.12,846.48],[2,1.11,224.79]],"batl":[[0,1.22,302.16],[1,1.23,444.91]],"ltp":1.48,"tv":70.76,"id":2263624}]}]}
{"op":"mcm","clk":"1009237005","pt":1580642938398,"mc":[{"id":"1.168217556","rc":[{"batb":[[1,1.01,10.52],[2,1.01,0]],"ltp":2.02,"tv":32.33,"id":7412809}]}]}
{"op":"mcm","clk":"1009237144","pt":1580642939413,"mc":[{"id":"1.168217556","rc":[{"batl":[[0,1.15,736.85],[1,1.16,374.42]],"ltp":1.48,"tv":70.76,"id":2263624}]}]}
{"op":"mcm","clk":"1009237298","pt":1580642940422,"mc":[{"id":"1.168217556","rc":[{"batl":[[2,1.17,42.01]],"ltp":1.48,"tv":70.76,"id":2263624},{"batb":[[0,8,9.05],[1,6.8,6.72],[2,6.6,14.08]],"batl":[[0,8.8,5.04]],"ltp":2.02,"tv":32.33,"id":7412809}]}]}
{"op":"mcm","clk":"1009238985","pt":1580642950430,"mc":[{"id":"1.168217556","rc":[{"batb":[[0,1.09,259.49],[1,1.06,955.61],[2,1.01,10.51]],"batl":[[0,1.17,42.01],[1,1.16,0],[2,1.17,0]],"ltp":1.48,"tv":70.76,"id":2263624},{"batb":[[0,6.8,6.72],[1,6.6,14.08],[2,3.5,371.08]],"ltp":2.02,"tv":32.33,"id":7412809}]}]}
{"op":"mcm","clk":"1009239051","pt":1580642950758,"mc":[{"id":"1.168217556","rc":[{"batb":[[0,6.6,14.08],[1,3.5,371.08],[2,1.01,10.52]],"ltp":2.02,"tv":32.33,"id":7412809}]}]}
{"op":"mcm","clk":"1009239437","pt":1580642953438,"mc":[{"id":"1.168217556","rc":[{"batb":[[0,1.11,1069.17],[1,1.09,259.49],[2,1.06,955.61]],"batl":[[0,1.18,623.65],[1,1.19,458.66]],"ltp":1.48,"tv":70.76,"id":2263624}]}]}
{"op":"mcm","clk":"1009239718","pt":1580642955352,"mc":[{"id":"1.168217556","rc":[{"batb":[[0,1.09,259.49],[1,1.01,10.51],[2,1.06,0]],"ltp":1.48,"tv":70.76,"id":2263624}]}]}
{"op":"mcm","clk":"1009240256","pt":1580642958332,"mc":[{"id":"1.168217556","rc":[{"batb":[[0,1.15,1034.04],[1,1.14,421.84],[2,1.11,218.11]],"batl":[[2,1.2,42.01]],"ltp":1.48,"tv":70.76,"id":2263624},{"batb":[[1,6,8.4],[2,5,13.22]],"batl":[[0,7.6,5.88]],"ltp":2.02,"tv":32.33,"id":7412809}]}]}
{"op":"mcm","clk":"1009242603","pt":1580642973399,"mc":[{"id":"1.168217556","rc":[{"batb":[[0,1.15,168.04],[1,1.14,171.13]],"batl":[[0,1.2,42.01],[1,1.19,0],[2,1.2,0]],"ltp":1.48,"tv":70.76,"id":2263624}]}]}
{"op":"mcm","clk":"1009242669","pt":1580642973773,"mc":[{"id":"1.168217556","rc":[{"batb":[[1,1.11,218.11],[2,1.08,824.68]],"ltp":1.48,"tv":70.76,"id":2263624},{"batb":[[0,6,8.4],[1,5,13.22],[2,3.5,371.08]],"ltp":2.02,"tv":32.33,"id":7412809}]}]}
{"op":"mcm","clk":"1009242820","pt":1580642974862,"mc":[{"id":"1.168217556","rc":[{"batb":[[0,1.11,218.11],[1,1.08,824.68],[2,1.01,10.51]],"ltp":1.48,"tv":70.76,"id":2263624},{"batb":[[0,5,13.22],[1,3.5,371.08],[2,1.01,10.52]],"ltp":2.02,"tv":32.33,"id":7412809}]}]}
{"op":"mcm","clk":"1009243315","pt":1580642978317,"mc":[{"id":"1.168217556","rc":[{"batb":[[0,1.17,191.15],[1,1.16,711.3],[2,1.11,218.11]],"batl":[[0,1.19,470.72],[1,1.2,517.96]],"ltp":1.48,"tv":70.76,"id":2263624}]}]}
{"op":"mcm","clk":"1009243948","pt":1580642982274,"mc":[{"id":"1.168217556","rc":[{"batb":[[0,1.11,218.11],[1,1.08,824.68],[2,1.01,10.51]],"ltp":1.48,"tv":70.76,"id":2263624}]}]}
{"op":"mcm","clk":"1009244437","pt":1580642985490,"mc":[{"id":"1.168217556","rc":[{"batb":[[0,1.13,302.36],[1,1.12,839.32],[2,1.11,218.11]],"batl":[[0,1.24,326.14],[1,1.25,402.53]],"ltp":1.48,"tv":70.76,"id":2263624}]}]}
{"op":"mcm","clk":"1009245090","pt":1580642989495,"mc":[{"id":"1.168217556","rc":[{"batb":[[0,1.11,218.11],[1,1.08,824.68],[2,1.01,10.51]],"ltp":1.48,"tv":70.76,"id":2263624}]}]}
{"op":"mcm","clk":"1009245252","pt":1580642990571,"mc":[{"id":"1.168217556","rc":[{"batb":[[1,1.01,10.51],[2,1.01,0]],"ltp":1.48,"tv":70.76,"id":2263624}]}]}
{"op":"mcm","clk":"1009245515","pt":1580642992279,"mc":[{"id":"1.168217556","rc":[{"batb":[[0,1.21,572.13],[1,1.2,491.19],[2,1.11,218.11]],"ltp":1.48,"tv":70.76,"id":2263624}]}]}
{"op":"mcm","clk":"1009245612","pt":1580642992962,"mc":[{"id":"1.168217556","rc":[{"batb":[[1,1.2,611.81],[2,1.14,169.8]],"ltp":1.48,"tv":70.76,"id":2263624},{"batb":[[1,3.5,386.66]],"ltp":2.02,"tv":32.33,"id":7412809}]}]}
{"op":"mcm","clk":"1009245836","pt":1580642994508,"mc":[{"id":"1.168217556","rc":[{"batb":[[1,1.2,772.85]],"batl":[[2,1.26,42.01]],"ltp":1.48,"tv":70.76,"id":2263624},{"batb":[[1,4.8,10.92],[2,3.5,386.66]],"batl":[[0,5.9,8.4]],"ltp":2.02,"tv":32.33,"id":7412809}]}]}
{"op":"mcm","clk":"1009248258","pt":1580643009613,"mc":[{"id":"1.168217556","rc":[{"batb":[[0,1.2,168.04],[1,1.14,169.8],[2,1.13,629.97]],"batl":[[0,1.26,42.01],[1,1.25,0],[2,1.26,0]],"ltp":1.48,"tv":70.76,"id":2263624},{"batb":[[0,4.8,10.92],[1,3.5,386.66],[2,1.01,10.52]],"ltp":2.02,"tv":32.33,"id":7412809}]}]}
{"op":"mcm","clk":"1009248459","pt":1580643010835,"mc":[{"id":"1.168217556","rc":[{"batb":[[0,1.14,169.8],[1,1.13,629.97],[2,1.01,10.51]],"ltp":1.48,"tv":70.76,"id":2263624},{"batb":[[0,3.5,386.66],[1,1.01,10.52],[2,1.01,0]],"ltp":2.02,"tv":32.33,"id":7412809}]}]}
{"op":"mcm","clk":"1009248729","pt":1580643012623,"mc":[{"id":"1.168217556","rc":[{"batb":[[0,1.15,748.92],[1,1.14,538.62],[2,1.13,629.97]],"batl":[[0,1.39,317.18],[1,1.4,226.11]],"ltp":1.48,"tv":70.76,"id":2263624}]}]}
{"op":"mcm","clk":"1009249079","pt":1580643014892,"mc":[{"id":"1.168217556","rc":[{"batb":[[2,1.01,10.51]],"ltp":1.48,"tv":70.76,"id":2263624}]}]}
{"op":"mcm","clk":"1009249525","pt":1580643017517,"mc":[{"id":"1.168217556","rc":[{"batb":[[2,1.11,221.33]],"batl":[[0,1.18,723.89],[1,1.19,359.26]],"ltp":1.48,"tv":70.76,"id":2263624},{"batb":[[0,6.4,14.32],[1,4.8,14.48],[2,3.5,371.08]],"ltp":2.02,"tv":32.33,"id":7412809}]}]}
{"op":"mcm","clk":"1009249556","pt":1580643017733,"mc":[{"id":"1.168217556","rc":[{"batb":[[0,1.15,916.96]],"batl":[[2,1.2,42.01]],"ltp":1.48,"tv":70.76,"id":2263624},{"batb":[[1,6,8.4],[2,4.8,14.48]],"batl":[[0,7.6,5.88]],"ltp":2.02,"tv":32.33,"id":7412809}]}]}
{"op":"mcm","clk":"1009250981","pt":1580643026343,"mc":[{"id":"1.168217556","rc":[{"batb":[[0,1.15,168.04],[1,1.11,221.33],[2,1.08,824.68]],"batl":[[0,1.2,42.01],[1,1.19,0],[2,1.2,0]],"ltp":1.48,"tv":70.76,"id":2263624},{"batb":[[0,6,8.4],[1,4.8,14.48],[2,3.5,371.08]],"ltp":2.02,"tv":32.33,"id":7412809}]}]}
{"op":"mcm","clk":"1009251050","pt":1580643026759,"mc":[{"id":"1.168217556","rc":[{"batb":[[0,1.11,221.33],[1,1.08,824.68],[2,1.01,10.51]],"ltp":1.48,"tv":70.76,"id":2263624},{"batb":[[0,4.8,14.48],[1,3.5,371.08],[2,1.01,10.52]],"ltp":2.02,"tv":32.33,"id":7412809}]}]}
{"op":"mcm","clk":"1009251443","pt":1580643029051,"mc":[{"id":"1.168217556","rc":[{"batb":[[0,1.12,741.01],[1,1.11,628.33],[2,1.08,824.68]],"batl":[[0,1.25,416.54],[1,1.26,382.03]],"ltp":1.48,"tv":70.76,"id":2263624}]}]}
{"op":"mcm","clk":"1009252348","pt":1580643034477,"mc":[{"id":"1.168217556","rc":[{"batb":[[2,1.01,10.51]],"ltp":1.48,"tv":70.76,"id":2263624}]}]}
{"op":"mcm","clk":"1009252437","pt":1580643034963,"mc":[{"id":"1.168217556","rc":[{"batl":[[0,1.14,472.72],[1,1.15,645.91]],"ltp":1.48,"tv":70.76,"id":2263624}]}]}
{"op":"mcm","clk":"1009252602","pt":1580643035970,"mc":[{"id":"1.168217556","rc":[{"batb":[[2,1.08,292.15]],"ltp":1.48,"tv":70.76,"id":2263624},{"batb":[[0,7.8,9.28],[1,7.4,5.88],[2,7,11.96]],"batl":[[0,9.6,4.2]],"ltp":2.02,"tv":32.33,"id":7412809}]}]}
{"op":"mcm","clk":"1009254978","pt":1580643050390,"mc":[{"id":"1.168217556","rc":[{"batb":[[0,1.12,679.76]],"batl":[[1,1.15,586.25]],"ltp":1.48,"tv":70.76,"id":2263624}]}]}
{"op":"mcm","clk":"1009255414","pt":1580643053067,"mc":[{"id":"1.168217556","rc":[{"batb":[[1,1.11,690.12]],"batl":[[0,1.14,532.9]],"ltp":1.48,"tv":70.76,"id":2263624}]}]}
{"op":"mcm","clk":"1009255825","pt":1580643055455,"mc":[{"id":"1.168217556","rc":[{"batb":[[0,1.08,292.15],[1,1.06,955.61],[2,1.01,10.51]],"ltp":1.48,"tv":70.76,"id":2263624},{"batb":[[0,7.4,5.88],[1,7,11.96],[2,3.5,371.08]],"ltp":2.02,"tv":32.33,"id":7412809}]}]}
{"op":"mcm","clk":"1009256027","pt":1580643056800,"mc":[{"id":"1.168217556","rc":[{"batb":[[0,7,11.96],[1,3.5,371.08],[2,1.01,10.52]],"ltp":2.02,"tv":32.33,"id":7412809}]}]}
{"op":"mcm","clk":"1009256277","pt":1580643058365,"mc":[{"id":"1.168217556","rc":[{"batb":[[0,1.09,1175.88],[1,1.08,292.15],[2,1.06,955.61]],"batl":[[0,1.16,539.91],[1,1.17,560.17]],"ltp":1.48,"tv":70.76,"id":2263624}]}]}
{"op":"mcm","clk":"1009256591","pt":1580643060198,"mc":[{"id":"1.168217556","rc":[{"batb":[[0,1.08,292.15],[1,1.06,955.61],[2,1.01,10.51]],"ltp":1.48,"tv":70.76,"id":2263624}]}]}
{"op":"mcm","clk":"1009256962","pt":1580643062504,"mc":[{"id":"1.168217556","rc":[{"batb":[[1,1.01,10.51],[2,1.01,0]],"ltp":1.48,"tv":70.76,"id":2263624}]}]}
{"op":"mcm","clk":"1009257058","pt":1580643063203,"mc":[{"id":"1.168217556","rc":[{"batb":[[0,1.14,401.41],[1,1.13,729.29],[2,1.08,292.15]],"ltp":1.48,"tv":70.76,"id":2263624}]}]}
{"op":"mcm","clk":"1009257220","pt":1580643064208,"mc":[{"id":"1.168217556","rc":[{"batb":[[1,1.13,2078.84],[2,1.1,235.49]],"ltp":1.48,"tv":70.76,"id":2263624},{"batb":[[1,6.8,6.72],[2,6.4,14.48]],"batl":[[0,8.6,5.04]],"ltp":2.02,"tv":32.33,"id":7412809}]}]}
{"op":"mcm","clk":"1009258026","pt":1580643069309,"mc":[{"id":"1.168217556","rc":[{"batb":[[0,1.13,358.13],[1,1.1,235.49],[2,1.07,893.98]],"ltp":1.48,"tv":70.76,"id":2263624}]}]}
{"op":"mcm","clk":"1009258176","pt":1580643070291,"mc":[{"id":"1.168217556","rc":[{"batb":[[0,1.13,168.04]],"ltp":1.48,"tv":70.76,"id":2263624},{"batb":[[0,6.8,6.72],[1,6.4,14.48],[2,3.5,371.08]],"ltp":2.02,"tv":32.33,"id":7412809}]}]}
{"op":"mcm","clk":"1009258277","pt":1580643070890,"mc":[{"id":"1.168217556","rc":[{"batb":[[0,1.1,235.49],[1,1.07,893.98],[2,1.01,10.51]],"ltp":1.48,"tv":70.76,"id":2263624},{"batb":[[0,6.4,14.48],[1,3.5,371.08],[2,1.01,10.52]],"ltp":2.02,"tv":32.33,"id":7412809}]}]}
{"op":"mcm","clk":"1009258494","pt":1580643072515,"mc":[{"id":"1.168217556","rc":[{"batb":[[0,1.12,193.69],[1,1.1,235.49],[2,1.07,893.98]],"ltp":1.48,"tv":70.76,"id":2263624}]}]}
{"op":"mcm","clk":"1009258988","pt":1580643075484,"mc":[{"id":"1.168217556","rc":[{"batb":[[0,1.13,911.65],[1,1.12,193.69],[2,1.1,235.49]],"batl":[[0,1.15,199.42],[1,1.16,683.76]],"ltp":1.48,"tv":70.76,"id":2263624}]}]}
{"op":"mcm","clk":"1009259668","pt":1580643080084,"mc":[{"id":"1.168217556","rc":[{"batb":[[0,1.12,193.69],[1,1.1,235.49],[2,1.07,893.98]],"ltp":1.48,"tv":70.76,"id":2263624}]}]}
{"op":"mcm","clk":"1009260221","pt":1580643083505,"mc":[{"id":"1.168217556","rc":[{"batb":[[1,1.11,959.25],[2,1.1,235.49]],"ltp":1.48,"tv":70.76,"id":2263624}]}]}
{"op":"mcm","clk":"1009260703","pt":1580643086502,"mc":[{"id":"1.168217556","rc":[{"batl":[[0,1.14,957.03]],"ltp":1.48,"tv":70.76,"id":2263624},{"batb":[[0,8.2,8.42],[1,7.2,11.57],[2,6.4,14.48]],"ltp":2.02,"tv":32.33,"id":7412809}]}]}
{"op":"mcm","clk":"1009260741","pt":1580643086723,"mc":[{"id":"1.168217556","rc":[{"batb":[[2,3.5,371.08]],"ltp":2.02,"tv":32.33,"id":7412809}]}]}
{"op":"mcm","clk":"1009260936","pt":1580643087802,"mc":[{"id":"1.168217556","rc":[{"batb":[[1,1.11,1127.29]],"batl":[[1,1.15,42.01]],"ltp":1.48,"tv":70.76,"id":2263624},{"batb":[[1,7.6,5.88],[2,7.2,11.57]],"batl":[[0,10,4.2]],"ltp":2.02,"tv":32.33,"id":7412809}]}]}
{"op":"mcm","clk":"1009263870","pt":1580643107328,"mc":[{"id":"1.168217556","rc":[{"batb":[[0,1.07,330.94],[1,1.06,955.61],[2,1.01,10.51]],"ltp":1.48,"tv":70.76,"id":2263624},{"batb":[[0,7.2,11.57],[1,3.5,371.08],[2,1.01,10.52]],"ltp":2.02,"tv":32.33,"id":7412809}]}]}
{"op":"mcm","clk":"1009264212","pt":1580643109570,"mc":[{"id":"1.168217556","rc":[{"batb":[[0,1.08,1186.76],[1,1.07,330.94],[2,1.06,955.61]],"batl":[[0,1.16,627.84],[1,1.17,472.99]],"ltp":1.48,"tv":70.76,"id":2263624}]}]}
{"op":"mcm","clk":"1009265358","pt":1580643117429,"mc":[{"id":"1.168217556","rc":[{"batb":[[1,1.01,10.51],[2,1.06,0]],"ltp":1.48,"tv":70.76,"id":2263624}]}]}
{"op":"mcm","clk":"1009265474","pt":1580643118029,"mc":[{"id":"1.168217556","rc":[{"batl":[[0,1.1,596.97],[1,1.11,563.09]],"ltp":1.48,"tv":70.76,"id":2263624}]}]}
{"op":"mcm","clk":"1009265674","pt":1580643119305,"mc":[{"id":"1.168217556","rc":[{"batb":[[1,1.04,594.99],[2,1.01,10.51]],"ltp":1.48,"tv":70.76,"id":2263624},{"batb":[[0,8.4,7.87]],"ltp":2.02,"tv":32.33,"id":7412809}]}]}
{"op":"mcm","clk":"1009265793","pt":1580643120157,"mc":[{"id":"1.168217556","rc":[{"batl":[[0,13,3.36]],"ltp":2.02,"tv":32.33,"id":7412809}]}]}
{"op":"mcm","clk":"1009265960","pt":1580643121243,"mc":[{"id":"1.168217556","rc":[{"batb":[[1,1.04,1857.99]],"ltp":1.48,"tv":70.76,"id":2263624},{"batb":[[0,9.6,4.2],[1,8.4,7.87],[2,3.5,371.08]],"ltp":2.02,"tv":32.33,"id":7412809}]}]}
{"op":"mcm","clk":"1009267752","pt":1580643134060,"mc":[{"id":"1.168217556","rc":[{"batb":[[0,1.04,1857.99],[1,1.01,10.51],[2,1.01,0]],"ltp":1.48,"tv":70.76,"id":2263624}]}]}
{"op":"mcm","clk":"1009267859","pt":1580643134973,"mc":[{"id":"1.168217556","rc":[{"batb":[[0,8.4,7.87],[1,3.5,371.08],[2,1.01,10.52]],"ltp":2.02,"tv":32.33,"id":7412809}]}]}
{"op":"mcm","clk":"1009268141","pt":1580643136990,"mc":[{"id":"1.168217556","rc":[{"batb":[[0,1.05,649.25],[1,1.04,2434.9],[2,1.01,10.51]],"batl":[[0,1.13,607.3],[1,1.14,522.32]],"ltp":1.48,"tv":70.76,"id":2263624}]}]}
{"op":"mcm","clk":"1009268327","pt":1580643138260,"mc":[{"id":"1.168217556","rc":[{"batb":[[0,1.04,1857.99],[1,1.01,10.51],[2,1.01,0]],"ltp":1.48,"tv":70.76,"id":2263624}]}]}
{"op":"mcm","clk":"1009268488","pt":1580643139264,"mc":[{"id":"1.168217556","rc":[{"batb":[[0,1.04,594.99]],"ltp":1.48,"tv":70.76,"id":2263624}]}]}
{"op":"mcm","clk":"1009268716","pt":1580643140759,"mc":[{"id":"1.168217556","rc":[{"batb":[[0,1.11,767.05],[1,1.1,391.16],[2,1.04,594.99]],"batl":[[0,1.13,607.3],[1,1.14,522.32]],"ltp":1.48,"tv":70.76,"id":2263624}]}]}
{"op":"mcm","clk":"1009268903","pt":1580643142104,"mc":[{"id":"1.168217556","rc":[{"batb":[[1,1.1,635.47],[2,1.06,403.17]],"ltp":1.48,"tv":70.76,"id":2263624},{"batb":[[1,8,5.88],[2,7,11.8]],"batl":[[0,10,4.2]],"ltp":2.02,"tv":32.33,"id":7412809}]}]}
{"op":"mcm","clk":"1009271536","pt":1580643158025,"mc":[{"id":"1.168217556","rc":[{"batb":[[0,1.06,403.17],[1,1.05,1069.56],[2,1.01,10.51]],"ltp":1.48,"tv":70.76,"id":2263624},{"batb":[[0,8,5.88],[1,7,11.8],[2,3.5,371.08]],"ltp":2.02,"tv":32.33,"id":7412809}]}]}
{"op":"mcm","clk":"1009271667","pt":1580643158832,"mc":[{"id":"1.168217556","rc":[{"batb":[[0,7,11.8],[1,3.5,371.08],[2,1.01,10.52]],"ltp":2.02,"tv":32.33,"id":7412809}]}]}
{"op":"mcm","clk":"1009271997","pt":1580643161657,"mc":[{"id":"1.168217556","rc":[{"batb":[[0,1.07,987.19],[1,1.06,615.82],[2,1.05,1069.56]],"batl":[[0,1.16,439.84],[1,1.17,627.86]],"ltp":1.48,"tv":70.76,"id":2263624}]}]}
{"op":"mcm","clk":"1009273499","pt":1580643169583,"mc":[{"id":"1.168217556","rc":[{"batb":[[2,1.01,10.51]],"ltp":1.48,"tv":70.76,"id":2263624}]}]}
{"op":"mcm","clk":"1009273797","pt":1580643171513,"mc":[{"id":"1.168217556","rc":[{"batl":[[0,1.09,1175.88]],"ltp":1.48,"tv":70.76,"id":2263624},{"batb":[[0,12,8.66],[1,8.6,7.63],[2,7,11.8]],"ltp":2.02,"tv":32.33,"id":7412809}]}]}
{"op":"mcm","clk":"1009273947","pt":1580643172471,"mc":[{"id":"1.168217556","rc":[{"batb":[[0,1.07,1155.23]],"ltp":1.48,"tv":70.76,"id":2263624},{"batb":[[2,3.5,371.08]],"ltp":2.02,"tv":32.33,"id":7412809}]}]}
{"op":"mcm","clk":"1009274147","pt":1580643173798,"mc":[{"id":"1.168217556","rc":[{"batb":[[2,1.03,1571.88]],"ltp":1.48,"tv":70.76,"id":2263624}]}]}
{"op":"mcm","clk":"1009275481","pt":1580643182809,"mc":[{"id":"1.168217556","rc":[{"batl":[[1,1.1,42.01]],"ltp":1.48,"tv":70.76,"id":2263624},{"batb":[[1,11,4.2],[2,8.6,7.63]],"ltp":2.02,"tv":32.33,"id":7412809}]}]}
{"op":"mcm","clk":"1009276594","pt":1580643190434,"mc":[{"id":"1.168217556","rc":[{"batb":[[0,1.07,168.04],[1,1.03,1571.88],[2,1.01,10.51]],"batl":[[0,1.1,42.01],[1,1.1,0]],"ltp":1.48,"tv":70.76,"id":2263624},{"batb":[[0,11,4.2],[1,8.6,7.63],[2,3.5,371.08]],"ltp":2.02,"tv":32.33,"id":7412809}]}]}
{"op":"mcm","clk":"1009276693","pt":1580643191056,"mc":[{"id":"1.168217556","rc":[{"batb":[[0,1.03,1571.88],[1,1.01,10.51],[2,1.01,0]],"ltp":1.48,"tv":70.76,"id":2263624},{"batb":[[0,8.6,7.63],[1,3.5,371.08],[2,1.01,10.52]],"ltp":2.02,"tv":32.33,"id":7412809}]}]}
{"op":"mcm","clk":"1009276796","pt":1580643191765,"mc":[{"id":"1.168217556","rc":[{"batb":[[0,1.01,10.51],[1,1.01,0]],"ltp":1.48,"tv":70.76,"id":2263624},{"batb":[[1,1.01,10.52],[2,1.01,0]],"ltp":2.02,"tv":32.33,"id":7412809}]}]}
{"op":"mcm","clk":"1009277042","pt":1580643193342,"mc":[{"id":"1.168217556","rc":[{"batb":[[0,1.02,666.7],[1,1.01,606.22]],"batl":[[0,1.13,749.09],[1,1.14,381.78]],"ltp":1.48,"tv":70.76,"id":2263624}]}]}
{"op":"mcm","clk":"1009278164","pt":1580643200449,"mc":[{"id":"1.168217556","rc":[{"batb":[[0,1.02,834.74]],"batl":[[0,1.03,1244.37]],"ltp":1.48,"tv":70.76,"id":2263624},{"batb":[[0,20,4.88],[1,8.6,7.63],[2,1.01,10.52]],"ltp":2.02,"tv":32.33,"id":7412809}]}]}
{"op":"mcm","clk":"1009278240","pt":1580643200954,"mc":[{"id":"1.168217556","rc":[{"batb":[[1,1.01,10.52],[2,1.01,0]],"ltp":2.02,"tv":32.33,"id":7412809}]}]}
{"op":"mcm","clk":"1009278380","pt":1580643201854,"mc":[{"id":"1.168217556","rc":[{"batb":[[1,4.5,371.06],[2,1.01,10.52]],"ltp":2.02,"tv":32.33,"id":7412809}]}]}
{"op":"mcm","clk":"1009282382","pt":1580643224556,"mc":[{"id":"1.168217556","rc":[{"trd":[[1.02,151.44]],"batb":[[0,1.02,759.02]],"ltp":1.02,"tv":222.2,"id":2263624}],"tv":254.53}]}
{"op":"mcm","clk":"1009282848","pt":1580643227874,"mc":[{"id":"1.168217556","rc":[{"batb":[[0,1.02,807.01]],"ltp":1.02,"tv":222.2,"id":2263624}]}]}
{"op":"mcm","clk":"1009289605","pt":1580643276044,"mc":[{"id":"1.168217556","rc":[{"batb":[[0,1.02,168.04]],"ltp":1.02,"tv":222.2,"id":2263624}]}]}
{"op":"mcm","clk":"1009289730","pt":1580643276953,"mc":[{"id":"1.168217556","rc":[{"batb":[[0,1.01,606.22],[1,1.01,0]],"ltp":1.02,"tv":222.2,"id":2263624}]}]}
{"op":"mcm","clk":"1009290003","pt":1580643279046,"mc":[{"id":"1.168217556","rc":[{"batb":[[0,1.01,1279.53]],"ltp":1.02,"tv":222.2,"id":2263624}]}]}
{"op":"mcm","clk":"1009290382","pt":1580643281937,"mc":[{"id":"1.168217556","rc":[{"batl":[[0,1.02,1256.57]],"ltp":1.02,"tv":222.2,"id":2263624}]}]}
{"op":"mcm","clk":"1009290539","pt":1580643283265,"mc":[{"id":"1.168217556","rc":[{"batb":[[0,27,3.23]],"ltp":2.02,"tv":32.33,"id":7412809}]}]}
{"op":"mcm","clk":"1009290927","pt":1580643286150,"mc":[{"id":"1.168217556","rc":[{"batb":[[0,1.01,10.51]],"ltp":1.02,"tv":222.2,"id":2263624}]}]}
{"op":"mcm","clk":"1009291252","pt":1580643288761,"mc":[{"id":"1.168217556","rc":[{"batl":[[0,1.03,1244.37]],"ltp":1.02,"tv":222.2,"id":2263624}]}]}
{"op":"mcm","clk":"1009291923","pt":1580643294044,"mc":[{"id":"1.168217556","rc":[{"batl":[[0,1.02,1256.57]],"ltp":1.02,"tv":222.2,"id":2263624}]}]}
{"op":"mcm","clk":"1009292113","pt":1580643295441,"mc":[{"id":"1.168217556","rc":[{"batb":[[0,30,2.52]],"ltp":2.02,"tv":32.33,"id":7412809}]}]}
{"op":"mcm","clk":"1009294018","pt":1580643308496,"mc":[{"id":"1.168217556","rc":[{"batb":[[0,1.01,903.44]],"ltp":1.02,"tv":222.2,"id":2263624}]}]}
{"op":"mcm","clk":"1009294866","pt":1580643314374,"mc":[{"id":"1.168217556","rc":[{"batb":[[0,1.01,10.51]],"ltp":1.02,"tv":222.2,"id":2263624}]}]}
{"op":"mcm","clk":"1009295261","pt":1580643317423,"mc":[{"id":"1.168217556","rc":[{"batb":[[0,4.5,371.06],[1,1.01,10.52],[2,1.01,0]],"ltp":2.02,"tv":32.33,"id":7412809}]}]}
{"op":"mcm","clk":"1009295717","pt":1580643320485,"mc":[{"id":"1.168217556","rc":[{"trd":[[1.01,21.02]],"batl":[[0,1.01,1258.51]],"ltp":1.01,"tv":243.21,"id":2263624}],"tv":275.55}]}
{"op":"mcm","clk":"1009297381","pt":1580643331420,"mc":[{"id":"1.168217556","rc":[{"batl":[[0,1.01,537.69]],"ltp":1.01,"tv":243.21,"id":2263624}]}]}
{"op":"mcm","clk":"1009297795","pt":1580643334326,"mc":[{"id":"1.168217556","rc":[{"batl":[[1,1.02,724.15]],"ltp":1.01,"tv":243.21,"id":2263624}]}]}
{"op":"mcm","clk":"1009297897","pt":1580643335026,"mc":[{"id":"1.168217556","rc":[{"batl":[[1,1.02,0]],"ltp":1.01,"tv":243.21,"id":2263624}]}]}
{"op":"mcm","clk":"1009298418","pt":1580643338344,"mc":[{"id":"1.168217556","rc":[{"batl":[[0,1.01,1268.98]],"ltp":1.01,"tv":243.21,"id":2263624}]}]}
{"op":"mcm","clk":"1009300676","pt":1580643353156,"mc":[{"id":"1.168217556","rc":[{"batl":[[0,1.01,2055.8]],"ltp":1.01,"tv":243.21,"id":2263624}]}]}
{"op":"mcm","clk":"1009304071","pt":1580643374162,"mc":[{"id":"1.168217556","rc":[{"batl":[[0,1.01,2093.83]],"ltp":1.01,"tv":243.21,"id":2263624}]}]}
{"op":"mcm","clk":"1009311074","pt":1580643422155,"mc":[{"id":"1.168217556","rc":[{"batl":[[0,1.01,2029.28]],"ltp":1.01,"tv":243.21,"id":2263624}]}]}
{"op":"mcm","clk":"1009312285","pt":1580643429972,"mc":[{"id":"1.168217556","rc":[{"batl":[[0,1.01,2093.83]],"ltp":1.01,"tv":243.21,"id":2263624}]}]}
{"op":"mcm","clk":"1009312684","pt":1580643432445,"mc":[{"id":"1.168217556","rc":[{"batl":[[0,1.01,2029.28]],"ltp":1.01,"tv":243.21,"id":2263624}]}]}
{"op":"mcm","clk":"1009314024","pt":1580643441385,"mc":[{"id":"1.168217556","rc":[{"batl":[[0,1.01,2093.83]],"ltp":1.01,"tv":243.21,"id":2263624}]}]}
{"op":"mcm","clk":"1009317941","pt":1580643467414,"mc":[{"id":"1.168217556","rc":[{"batb":[[0,30,2.6],[1,4.5,371.06],[2,1.01,10.52]],"ltp":2.02,"tv":32.33,"id":7412809}]}]}
{"op":"mcm","clk":"1009323897","pt":1580643506164,"mc":[{"id":"1.168217556","rc":[{"batl":[[0,1.01,2193.83]],"ltp":1.01,"tv":243.21,"id":2263624}]}]}
{"op":"mcm","clk":"1009329271","pt":1580643543612,"mc":[{"id":"1.168217556","rc":[{"batl":[[0,1.01,924.85]],"ltp":1.01,"tv":243.21,"id":2263624}]}]}
{"op":"mcm","clk":"1009329696","pt":1580643546504,"mc":[{"id":"1.168217556","rc":[{"batl":[[1,1.02,1256.54]],"ltp":1.01,"tv":243.21,"id":2263624},{"batb":[[1,1.01,10.52],[2,1.01,0]],"ltp":2.02,"tv":32.33,"id":7412809}]}]}
{"op":"mcm","clk":"1009331157","pt":1580643557236,"mc":[{"id":"1.168217556","rc":[{"batl":[[1,1.02,0]],"ltp":1.01,"tv":243.21,"id":2263624}]}]}
{"op":"mcm","clk":"1009331206","pt":1580643557618,"mc":[{"id":"1.168217556","rc":[{"batb":[[0,1.01,10.52],[1,1.01,0]],"ltp":2.02,"tv":32.33,"id":7412809}]}]}
{"op":"mcm","clk":"1009331529","pt":1580643560132,"mc":[{"id":"1.168217556","rc":[{"batl":[[0,1.01,2235.84]],"ltp":1.01,"tv":243.21,"id":2263624}]}]}
{"op":"mcm","clk":"1009331660","pt":1580643561137,"mc":[{"id":"1.168217556","rc":[{"batb":[[0,4.8,370.06],[1,1.01,10.52]],"ltp":2.02,"tv":32.33,"id":7412809}]}]}
{"op":"mcm","clk":"1009332529","pt":1580643568130,"mc":[{"id":"1.168217556","rc":[{"batl":[[0,1.01,966.86]],"ltp":1.01,"tv":243.21,"id":2263624}]}]}
{"op":"mcm","clk":"1009332678","pt":1580643569246,"mc":[{"id":"1.168217556","rc":[{"batl":[[0,1.01,924.85]],"ltp":1.01,"tv":243.21,"id":2263624}]}]}
{"op":"mcm","clk":"1009332756","pt":1580643569831,"mc":[{"id":"1.168217556","rc":[{"batb":[[0,1.01,10.52],[1,1.01,0]],"ltp":2.02,"tv":32.33,"id":7412809}]}]}
{"op":"mcm","clk":"1009332932","pt":1580643571054,"mc":[{"id":"1.168217556","rc":[{"batl":[[1,1.02,1256.54]],"ltp":1.01,"tv":243.21,"id":2263624}]}]}
{"op":"mcm","clk":"1009333498","pt":1580643575361,"mc":[{"id":"1.168217556","rc":[{"batb":[[0,4.7,374.21],[1,1.01,10.52]],"ltp":2.02,"tv":32.33,"id":7412809}]}]}
{"op":"mcm","clk":"1009334864","pt":1580643585247,"mc":[{"id":"1.168217556","rc":[{"batl":[[1,1.02,0]],"ltp":1.01,"tv":243.21,"id":2263624}]}]}
{"op":"mcm","clk":"1009335054","pt":1580643586850,"mc":[{"id":"1.168217556","rc":[{"batb":[[0,1.01,10.52],[1,1.01,0]],"ltp":2.02,"tv":32.33,"id":7412809}]}]}
{"op":"mcm","clk":"1009335295","pt":1580643588447,"mc":[{"id":"1.168217556","rc":[{"batl":[[1,1.03,1244.34]],"ltp":1.01,"tv":243.21,"id":2263624}]}]}
{"op":"mcm","clk":"1009337261","pt":1580643602028,"mc":[{"id":"1.168217556","rc":[{"batl":[[1,1.03,0]],"ltp":1.01,"tv":243.21,"id":2263624}]}]}
{"op":"mcm","clk":"1009337679","pt":1580643604466,"mc":[{"id":"1.168217556","rc":[{"batl":[[0,1.01,2193.83]],"ltp":1.01,"tv":243.21,"id":2263624}]}]}
{"op":"mcm","clk":"1009337974","pt":1580643606481,"mc":[{"id":"1.168217556","rc":[{"batl":[[0,1.01,2235.84]],"ltp":1.01,"tv":243.21,"id":2263624},{"batb":[[0,4.8,367.63],[1,1.01,10.52]],"ltp":2.02,"tv":32.33,"id":7412809}]}]}
{"op":"mcm","clk":"1009337986","pt":1580643606592,"mc":[{"id":"1.168217556","rc":[{"batl":[[0,1.01,2197.81]],"ltp":1.01,"tv":243.21,"id":2263624}]}]}
{"op":"mcm","clk":"1009341649","pt":1580643632424,"mc":[{"id":"1.168217556","rc":[{"batl":[[0,1.01,928.83]],"ltp":1.01,"tv":243.21,"id":2263624}]}]}
{"op":"mcm","clk":"1009341794","pt":1580643633398,"mc":[{"id":"1.168217556","rc":[{"batl":[[0,1.01,886.82]],"ltp":1.01,"tv":243.21,"id":2263624},{"batb":[[0,1.01,10.52],[1,1.01,0]],"ltp":2.02,"tv":32.33,"id":7412809}]}]}
{"op":"mcm","clk":"1009342021","pt":1580643635016,"mc":[{"id":"1.168217556","rc":[{"batl":[[1,1.02,1256.54]],"ltp":1.01,"tv":243.21,"id":2263624}]}]}
{"op":"mcm","clk":"1009345014","pt":1580643655269,"mc":[{"id":"1.168217556","rc":[{"batl":[[1,1.02,0]],"ltp":1.01,"tv":243.21,"id":2263624}]}]}
{"op":"mcm","clk":"1009345506","pt":1580643658470,"mc":[{"id":"1.168217556","rc":[{"batl":[[0,1.01,2155.8]],"ltp":1.01,"tv":243.21,"id":2263624}]}]}
{"op":"mcm","clk":"1009345965","pt":1580643661482,"mc":[{"id":"1.168217556","rc":[{"batl":[[0,1.01,886.82]],"ltp":1.01,"tv":243.21,"id":2263624}]}]}
{"op":"mcm","clk":"1009346423","pt":1580643664509,"mc":[{"id":"1.168217556","rc":[{"batl":[[1,1.02,1256.54]],"ltp":1.01,"tv":243.21,"id":2263624}]}]}
{"op":"mcm","clk":"1009348552","pt":1580643678414,"mc":[{"id":"1.168217556","rc":[{"trd":[[1.01,1794.61]],"batb":[[0,1.01,592.26]],"batl":[[0,1.02,1256.54],[1,1.02,0]],"ltp":1.01,"tv":2016.8,"id":2263624}],"tv":2049.14}]}
{"op":"mcm","clk":"1009348681","pt":1580643679325,"mc":[{"id":"1.168217556","rc":[{"batb":[[0,1.01,382.21]],"ltp":1.01,"tv":2016.8,"id":2263624},{"batb":[[0,24,5.04],[1,1.01,10.52]],"ltp":2.02,"tv":32.33,"id":7412809}]}]}
{"op":"mcm","clk":"1009349002","pt":1580643681408,"mc":[{"id":"1.168217556","rc":[{"batb":[[0,1.01,1437.02]],"batl":[[0,1.02,1298.55]],"ltp":1.01,"tv":2016.8,"id":2263624},{"batb":[[1,4.7,367.67],[2,1.01,10.52]],"ltp":2.02,"tv":32.33,"id":7412809}]}]}
{"op":"mcm","clk":"1009350211","pt":1580643688490,"mc":[{"id":"1.168217556","rc":[{"batb":[[0,1.01,168.04]],"batl":[[0,1.02,42.01]],"ltp":1.01,"tv":2016.8,"id":2263624}]}]}
{"op":"mcm","clk":"1009350619","pt":1580643691521,"mc":[{"id":"1.168217556","rc":[{"batl":[[0,1.03,294.62],[1,1.04,940.58]],"ltp":1.01,"tv":2016.8,"id":2263624},{"batb":[[1,1.01,10.52],[2,1.01,0]],"ltp":2.02,"tv":32.33,"id":7412809}]}]}
{"op":"mcm","clk":"1009351184","pt":1580643695434,"mc":[{"id":"1.168217556","rc":[{"batb":[[0,1.01,10.52],[1,1.01,0]],"ltp":2.02,"tv":32.33,"id":7412809}]}]}
{"op":"mcm","clk":"1009351420","pt":1580643697137,"mc":[{"id":"1.168217556","rc":[{"batl":[[0,1.01,1268.98]],"ltp":1.01,"tv":2016.8,"id":2263624}]}]}
{"op":"mcm","clk":"1009351579","pt":1580643698321,"mc":[{"id":"1.168217556","rc":[{"batb":[[0,4.8,370.06],[1,1.01,10.52]],"ltp":2.02,"tv":32.33,"id":7412809}]}]}
{"op":"mcm","clk":"1009353586","pt":1580643711066,"mc":[{"id":"1.168217556","rc":[{"batb":[[0,1.01,10.52],[1,1.01,0]],"ltp":2.02,"tv":32.33,"id":7412809}]}]}
{"op":"mcm","clk":"1009353783","pt":1580643712344,"mc":[{"id":"1.168217556","rc":[{"batl":[[0,1.02,1256.54]],"ltp":1.01,"tv":2016.8,"id":2263624}]}]}
{"op":"mcm","clk":"1009354022","pt":1580643713914,"mc":[{"id":"1.168217556","marketDefinition":{"bspMarket":false,"turnInPlayEnabled":true,"persistenceEnabled":true,"marketBaseRate":5.0,"eventId":"29681263","eventTypeId":"2","numberOfWinners":1,"bettingType":"ODDS","marketType":"SET_WINNER","marketTime":"2020-02-02T11:07:00.000Z","suspendTime":"2020-02-02T11:07:00.000Z","bspReconciled":false,"complete":true,"inPlay":true,"crossMatching":true,"runnersVoidable":false,"numberOfActiveRunners":2,"betDelay":3,"status":"SUSPENDED","runners":[{"status":"ACTIVE","sortPriority":1,"id":7412809,"name":"Evgeny Karlovskiy"},{"status":"ACTIVE","sortPriority":2,"id":2263624,"name":"Viktor Troicki"}],"regulators":["MR_INT"],"countryCode":"IN","discountAllowed":true,"timezone":"UTC","openDate":"2020-02-02T11:07:00.000Z","version":3148589613,"name":"Set 1 Winner","eventName":"Karlovskiy v Troicki"}}]}
{"op":"mcm","clk":"1009359633","pt":1580643750311,"mc":[{"id":"1.168217556","tv":0.0}]}
{"op":"mcm","clk":"1009359758","pt":1580643751052,"mc":[{"id":"1.168217556","marketDefinition":{"bspMarket":false,"turnInPlayEnabled":true,"persistenceEnabled":true,"marketBaseRate":5.0,"eventId":"29681263","eventTypeId":"2","numberOfWinners":1,"bettingType":"ODDS","marketType":"SET_WINNER","marketTime":"2020-02-02T11:07:00.000Z","suspendTime":"2020-02-02T11:07:00.000Z","bspReconciled":false,"complete":true,"inPlay":true,"crossMatching":false,"runnersVoidable":false,"numberOfActiveRunners":0,"betDelay":3,"status":"CLOSED","settledTime":"2020-02-02T11:42:28.000Z","runners":[{"status":"LOSER","sortPriority":1,"id":7412809,"name":"Evgeny Karlovskiy"},{"status":"WINNER","sortPriority":2,"id":2263624,"name":"Viktor Troicki"}],"regulators":["MR_INT"],"countryCode":"IN","discountAllowed":true,"timezone":"UTC","openDate":"2020-02-02T11:07:00.000Z","version":3148591021,"name":"Set 1 Winner","eventName":"Karlovskiy v Troicki"}}]}
