{"op":"mcm","clk":"1001415471","pt":1580567750513,"mc":[{"id":"1.168217555","marketDefinition":{"bspMarket":false,"turnInPlayEnabled":true,"persistenceEnabled":true,"marketBaseRate":5.0,"eventId":"29681263","eventTypeId":"2","numberOfWinners":1,"bettingType":"ODDS","marketType":"SET_BETTING","marketTime":"2020-02-02T11:30:00.000Z","suspendTime":"2020-02-02T11:30:00.000Z","bspReconciled":false,"complete":true,"inPlay":false,"crossMatching":false,"runnersVoidable":false,"numberOfActiveRunners":4,"betDelay":0,"status":"OPEN","runners":[{"status":"ACTIVE","sortPriority":1,"id":16574983,"name":"Karlovskiy 2-0"},{"status":"ACTIVE","sortPriority":2,"id":16574984,"name":"Karlovskiy 2-1"},{"status":"ACTIVE","sortPriority":3,"id":12984952,"name":"Troicki 2-0"},{"status":"ACTIVE","sortPriority":4,"id":12984951,"name":"Troicki 2-1"}],"regulators":["MR_INT"],"countryCode":"IN","discountAllowed":false,"timezone":"UTC","openDate":"2020-02-02T11:30:00.000Z","version":3145496358,"name":"Set Betting","eventName":"Karlovskiy v Troicki"}}]}
{"op":"mcm","clk":"1001415705","pt":1580567751514,"mc":[{"id":"1.168217555","marketDefinition":{"bspMarket":false,"turnInPlayEnabled":true,"persistenceEnabled":true,"marketBaseRate":5.0,"eventId":"29681263","eventTypeId":"2","numberOfWinners":1,"bettingType":"ODDS","marketType":"SET_BETTING","marketTime":"2020-02-02T11:30:00.000Z","suspendTime":"2020-02-02T11:30:00.000Z","bspReconciled":false,"complete":true,"inPlay":false,"crossMatching":false,"runnersVoidable":false,"numberOfActiveRunners":4,"betDelay":0,"status":"OPEN","runners":[{"status":"ACTIVE","sortPriority":1,"id":16574983,"name":"Karlovskiy 2-0"},{"status":"ACTIVE","sortPriority":2,"id":16574984,"name":"Karlovskiy 2-1"},{"status":"ACTIVE","sortPriority":3,"id":12984952,"name":"Troicki 2-0"},{"status":"ACTIVE","sortPriority":4,"id":12984951,"name":"Troicki 2-1"}],"regulators":["MR_INT"],"countryCode":"IN","discountAllowed":false,"timezone":"UTC","openDate":"2020-02-02T11:30:00.000Z","version":3145496358,"name":"Set Betting","eventName":"Karlovskiy v Troicki"}}]}
{"op":"mcm","clk":"1001415945","pt":1580567752496,"mc":[{"id":"1.168217555","marketDefinition":{"bspMarket":false,"turnInPlayEnabled":true,"persistenceEnabled":true,"marketBaseRate":5.0,"eventId":"29681263","eventTypeId":"2","numberOfWinners":1,"bettingType":"ODDS","marketType":"SET_BETTING","marketTime":"2020-02-02T11:30:00.000Z","suspendTime":"2020-02-02T11:30:00.000Z","bspReconciled":false,"complete":true,"inPlay":false,"crossMatching":false,"runnersVoidable":false,"numberOfActiveRunners":4,"betDelay":0,"status":"OPEN","runners":[{"status":"ACTIVE","sortPriority":1,"id":16574983,"name":"Karlovskiy 2-0"},{"status":"ACTIVE","sortPriority":2,"id":16574984,"name":"Karlovskiy 2-1"},{"status":"ACTIVE","sortPriority":3,"id":12984952,"name":"Troicki 2-0"},{"status":"ACTIVE","sortPriority":4,"id":12984951,"name":"Troicki 2-1"}],"regulators":["MR_INT"],"countryCode":"IN","discountAllowed":true,"timezone":"UTC","openDate":"2020-02-02T11:30:00.000Z","version":3145496358,"name":"Set Betting","eventName":"Karlovskiy v Troicki"}}]}
{"op":"mcm","clk":"1001909093","pt":1580569936591,"mc":[{"id":"1.168217555","rc":[{"batb":[[0,1.02,2]],"ltp":0.0,"tv":0.0,"id":12984951},{"batb":[[0,1.02,2]],"ltp":0.0,"tv":0.0,"id":12984952},{"batb":[[0,1.02,2]],"ltp":0.0,"tv":0.0,"id":16574984},{"batb":[[0,1.02,2]],"ltp":0.0,"tv":0.0,"id":16574983}]}]}
{"op":"mcm","clk":"1004215599","pt":1580581062264,"mc":[{"id":"1.168217555","rc":[{"batb":[[0,1.98,30.29],[1,1.02,2]],"ltp":0.0,"tv":0.0,"id":12984952}]}]}
{"op":"mcm","clk":"1004302824","pt":1580581550097,"mc":[{"id":"1.168217555","rc":[{"batb":[[0,2.12,30.29]],"ltp":0.0,"tv":0.0,"id":12984952}]}]}
{"op":"mcm","clk":"1005712759","pt":1580590079119,"mc":[{"id":"1.168217555","rc":[{"batb":[[0,2.04,30.29]],"ltp":0.0,"tv":0.0,"id":12984952}]}]}
{"op":"mcm","clk":"1006449364","pt":1580596402274,"mc":[{"id":"1.168217555","rc":[{"batb":[[0,1.02,2],[1,1.02,0]],"ltp":0.0,"tv":0.0,"id":12984952}]}]}
{"op":"mcm","clk":"1006471909","pt":1580596608965,"mc":[{"id":"1.168217555","rc":[{"batb":[[0,2.04,30.29],[1,1.02,2]],"ltp":0.0,"tv":0.0,"id":12984952}]}]}
{"op":"mcm","clk":"1006948413","pt":1580602466518,"mc":[{"id":"1.168217555","rc":[{"batb":[[1,1.01,2.53]],"ltp":0.0,"tv":0.0,"id":12984951},{"batb":[[2,1.01,2.53]],"ltp":0.0,"tv":0.0,"id":12984952},{"batb":[[1,1.01,2.53]],"ltp":0.0,"tv":0.0,"id":16574984},{"batb":[[1,1.01,2.53]],"ltp":0.0,"tv":0.0,"id":16574983}]}]}
{"op":"mcm","clk":"1006948497","pt":1580602467406,"mc":[{"id":"1.168217555","rc":[{"batb":[[1,1.01,0.51]],"ltp":0.0,"tv":0.0,"id":12984951},{"batb":[[2,1.01,0.51]],"ltp":0.0,"tv":0.0,"id":12984952},{"batb":[[1,1.01,0.51]],"ltp":0.0,"tv":0.0,"id":16574984},{"batb":[[1,1.01,0.51]],"ltp":0.0,"tv":0.0,"id":16574983}]}]}
{"op":"mcm","clk":"1007059766","pt":1580604000402,"mc":[{"id":"1.168217555","rc":[{"batb":[[1,1.01,3.04]],"ltp":0.0,"tv":0.0,"id":12984951},{"batb":[[2,1.01,3.04]],"ltp":0.0,"tv":0.0,"id":12984952},{"batb":[[1,1.01,3.04]],"ltp":0.0,"tv":0.0,"id":16574984},{"batb":[[1,1.01,3.04]],"ltp":0.0,"tv":0.0,"id":16574983}]}]}
{"op":"mcm","clk":"1007059835","pt":1580604001488,"mc":[{"id":"1.168217555","rc":[{"batb":[[1,1.01,1.01]],"ltp":0.0,"tv":0.0,"id":12984951},{"batb":[[2,1.01,1.01]],"ltp":0.0,"tv":0.0,"id":12984952},{"batb":[[1,1.01,1.01]],"ltp":0.0,"tv":0.0,"id":16574984},{"batb":[[1,1.01,1.01]],"ltp":0.0,"tv":0.0,"id":16574983}]}]}
{"op":"mcm","clk":"1008458746","pt":1580635606316,"mc":[{"id":"1.168217555","marketDefinition":{"bspMarket":false,"turnInPlayEnabled":true,"persistenceEnabled":true,"marketBaseRate":5.0,"eventId":"29681263","eventTypeId":"2","numberOfWinners":1,"bettingType":"ODDS","marketType":"SET_BETTING","marketTime":"2020-02-02T11:21:00.000Z","suspendTime":"2020-02-02T11:21:00.000Z","bspReconciled":false,"complete":true,"inPlay":false,"crossMatching":false,"runnersVoidable":false,"numberOfActiveRunners":4,"betDelay":0,"status":"OPEN","runners":[{"status":"ACTIVE","sortPriority":1,"id":16574983,"name":"Karlovskiy 2-0"},{"status":"ACTIVE","sortPriority":2,"id":16574984,"name":"Karlovskiy 2-1"},{"status":"ACTIVE","sortPriority":3,"id":12984952,"name":"Troicki 2-0"},{"status":"ACTIVE","sortPriority":4,"id":12984951,"name":"Troicki 2-1"}],"regulators":["MR_INT"],"countryCode":"IN","discountAllowed":true,"timezone":"UTC","openDate":"2020-02-02T11:30:00.000Z","version":3148345097,"name":"Set Betting","eventName":"Karlovskiy v Troicki"}}]}
{"op":"mcm","clk":"1008459143","pt":1580635610325,"mc":[{"id":"1.168217555","marketDefinition":{"bspMarket":false,"turnInPlayEnabled":true,"persistenceEnabled":true,"marketBaseRate":5.0,"eventId":"29681263","eventTypeId":"2","numberOfWinners":1,"bettingType":"ODDS","marketType":"SET_BETTING","marketTime":"2020-02-02T11:21:00.000Z","suspendTime":"2020-02-02T11:21:00.000Z","bspReconciled":false,"complete":true,"inPlay":false,"crossMatching":false,"runnersVoidable":false,"numberOfActiveRunners":4,"betDelay":0,"status":"OPEN","runners":[{"status":"ACTIVE","sortPriority":1,"id":16574983,"name":"Karlovskiy 2-0"},{"status":"ACTIVE","sortPriority":2,"id":16574984,"name":"Karlovskiy 2-1"},{"status":"ACTIVE","sortPriority":3,"id":12984952,"name":"Troicki 2-0"},{"status":"ACTIVE","sortPriority":4,"id":12984951,"name":"Troicki 2-1"}],"regulators":["MR_INT"],"countryCode":"IN","discountAllowed":true,"timezone":"UTC","openDate":"2020-02-02T11:21:00.000Z","version":3148345097,"name":"Set Betting","eventName":"Karlovskiy v Troicki"}}]}
{"op":"mcm","clk":"1008679337","pt":1580638599948,"mc":[{"id":"1.168217555","rc":[{"batb":[[0,1.02,2],[1,1.01,1.01],[2,1.01,0]],"ltp":0.0,"tv":0.0,"id":12984952}]}]}
{"op":"mcm","clk":"1008838906","pt":1580640119751,"mc":[{"id":"1.168217555","rc":[{"batb":[[0,1.03,137],[1,1.02,2],[2,1.01,1.01]],"ltp":0.0,"tv":0.0,"id":12984951},{"batb":[[0,1.03,137],[1,1.02,2],[2,1.01,1.01]],"ltp":0.0,"tv":0.0,"id":12984952},{"batb":[[0,1.03,137],[1,1.02,2],[2,1.01,1.01]],"ltp":0.0,"tv":0.0,"id":16574984},{"batb":[[0,1.03,137],[1,1.02,2],[2,1.01,1.01]],"ltp":0.0,"tv":0.0,"id":16574983}]}]}
{"op":"mcm","clk":"1008964053","pt":1580641136179,"mc":[{"id":"1.168217555","rc":[{"batl":[[0,5.2,10.64]],"ltp":0.0,"tv":0.0,"id":12984951},{"batl":[[0,5.2,10.64]],"ltp":0.0,"tv":0.0,"id":16574984}]}]}
{"op":"mcm","clk":"1008965963","pt":1580641150965,"mc":[{"id":"1.168217555","marketDefinition":{"bspMarket":false,"turnInPlayEnabled":true,"persistenceEnabled":true,"marketBaseRate":5.0,"eventId":"29681263","eventTypeId":"2","numberOfWinners":1,"bettingType":"ODDS","marketType":"SET_BETTING","marketTime":"2020-02-02T11:21:00.000Z","suspendTime":"2020-02-02T11:21:00.000Z","bspReconciled":false,"complete":true,"inPlay":false,"crossMatching":true,"runnersVoidable":false,"numberOfActiveRunners":4,"betDelay":0,"status":"OPEN","runners":[{"status":"ACTIVE","sortPriority":1,"id":16574983,"name":"Karlovskiy 2-0"},{"status":"ACTIVE","sortPriority":2,"id":16574984,"name":"Karlovskiy 2-1"},{"status":"ACTIVE","sortPriority":3,"id":12984952,"name":"Troicki 2-0"},{"status":"ACTIVE","sortPriority":4,"id":12984951,"name":"Troicki 2-1"}],"regulators":["MR_INT"],"countryCode":"IN","discountAllowed":true,"timezone":"UTC","openDate":"2020-02-02T11:21:00.000Z","version":3148345097,"name":"Set Betting","eventName":"Karlovskiy v Troicki"}}]}
{"op":"mcm","clk":"1008984124","pt":1580641271477,"mc":[{"id":"1.168217555","rc":[{"batb":[[0,1.02,2],[1,1.01,1.01],[2,1.01,0]],"ltp":0.0,"tv":0.0,"id":16574983}]}]}
{"op":"mcm","clk":"1008984218","pt":1580641272165,"mc":[{"id":"1.168217555","rc":[{"batb":[[0,1.02,2],[1,1.01,1.01],[2,1.01,0]],"ltp":0.0,"tv":0.0,"id":12984951},{"batb":[[0,1.02,2],[1,1.01,1.01],[2,1.01,0]],"ltp":0.0,"tv":0.0,"id":12984952},{"batb":[[0,1.02,2],[1,1.01,1.01],[2,1.01,0]],"ltp":0.0,"tv":0.0,"id":16574984}]}]}
{"op":"mcm","clk":"1008984530","pt":1580641274372,"mc":[{"id":"1.168217555","rc":[{"batb":[[0,1.03,137],[1,1.02,2],[2,1.01,1.01]],"ltp":0.0,"tv":0.0,"id":12984951},{"batb":[[0,1.03,137],[1,1.02,2],[2,1.01,1.01]],"ltp":0.0,"tv":0.0,"id":12984952},{"batb":[[0,1.03,137],[1,1.02,2],[2,1.01,1.01]],"ltp":0.0,"tv":0.0,"id":16574984},{"batb":[[0,1.03,137],[1,1.02,2],[2,1.01,1.01]],"ltp":0.0,"tv":0.0,"id":16574983}]}]}
{"op":"mcm","clk":"1009033963","pt":1580641605793,"mc":[{"id":"1.168217555","marketDefinition":{"bspMarket":false,"turnInPlayEnabled":true,"persistenceEnabled":true,"marketBaseRate":5.0,"eventId":"29681263","eventTypeId":"2","numberOfWinners":1,"bettingType":"ODDS","marketType":"SET_BETTING","marketTime":"2020-02-02T11:09:00.000Z","suspendTime":"2020-02-02T11:09:00.000Z","bspReconciled":false,"complete":true,"inPlay":false,"crossMatching":true,"runnersVoidable":false,"numberOfActiveRunners":4,"betDelay":0,"status":"OPEN","runners":[{"status":"ACTIVE","sortPriority":1,"id":16574983,"name":"Karlovskiy 2-0"},{"status":"ACTIVE","sortPriority":2,"id":16574984,"name":"Karlovskiy 2-1"},{"status":"ACTIVE","sortPriority":3,"id":12984952,"name":"Troicki 2-0"},{"status":"ACTIVE","sortPriority":4,"id":12984951,"name":"Troicki 2-1"}],"regulators":["MR_INT"],"countryCode":"IN","discountAllowed":true,"timezone":"UTC","openDate":"2020-02-02T11:21:00.000Z","version":3148499125,"name":"Set Betting","eventName":"Karlovskiy v Troicki"}}]}
{"op":"mcm","clk":"1009034829","pt":1580641610805,"mc":[{"id":"1.168217555","marketDefinition":{"bspMarket":false,"turnInPlayEnabled":true,"persistenceEnabled":true,"marketBaseRate":5.0,"eventId":"29681263","eventTypeId":"2","numberOfWinners":1,"bettingType":"ODDS","marketType":"SET_BETTING","marketTime":"2020-02-02T11:09:00.000Z","suspendTime":"2020-02-02T11:09:00.000Z","bspReconciled":false,"complete":true,"inPlay":false,"crossMatching":true,"runnersVoidable":false,"numberOfActiveRunners":4,"betDelay":0,"status":"OPEN","runners":[{"status":"ACTIVE","sortPriority":1,"id":16574983,"name":"Karlovskiy 2-0"},{"status":"ACTIVE","sortPriority":2,"id":16574984,"name":"Karlovskiy 2-1"},{"status":"ACTIVE","sortPriority":3,"id":12984952,"name":"Troicki 2-0"},{"status":"ACTIVE","sortPriority":4,"id":12984951,"name":"Troicki 2-1"}],"regulators":["MR_INT"],"countryCode":"IN","discountAllowed":true,"timezone":"UTC","openDate":"2020-02-02T11:09:00.000Z","version":3148499125,"name":"Set Betting","eventName":"Karlovskiy v Troicki"}}]}
{"op":"mcm","clk":"1009048276","pt":1580641697415,"mc":[{"id":"1.168217555","rc":[{"batb":[[0,1.02,2],[1,1.01,1.01],[2,1.01,0]],"ltp":0.0,"tv":0.0,"id":16574984},{"batb":[[0,1.02,2],[1,1.01,1.01],[2,1.01,0]],"ltp":0.0,"tv":0.0,"id":16574983}]}]}
{"op":"mcm","clk":"1009048417","pt":1580641698333,"mc":[{"id":"1.168217555","rc":[{"batb":[[0,1.03,137],[1,1.02,2],[2,1.01,1.01]],"ltp":0.0,"tv":0.0,"id":16574984},{"batb":[[0,1.03,137],[1,1.02,2],[2,1.01,1.01]],"ltp":0.0,"tv":0.0,"id":16574983}]}]}
{"op":"mcm","clk":"1009058427","pt":1580641763010,"mc":[{"id":"1.168217555","rc":[{"batb":[[0,4.3,18.73],[1,1.03,137],[2,1.02,2]],"batl":[[0,5,17.78],[1,5.2,10.64]],"ltp":0.0,"tv":0.0,"id":12984951},{"batb":[[0,2.38,17],[1,1.03,137],[2,1.02,2]],"batl":[[0,2.58,16.6]],"ltp":0.0,"tv":0.0,"id":12984952},{"trd":[[5.2,21.28]],"batb":[[0,5.6,9.81],[1,1.03,137],[2,1.02,2]],"batl":[[0,6.8,19.04]],"ltp":5.2,"tv":21.28,"id":16574984},{"batb":[[0,4.3,19.12],[1,1.03,137],[2,1.02,2]],"batl":[[0,4.9,18.25]],"ltp":0.0,"tv":0.0,"id":16574983}],"tv":21.28}]}
{"op":"mcm","clk":"1009058596","pt":1580641764227,"mc":[{"id":"1.168217555","rc":[{"batb":[[1,2.98,5.76],[2,1.03,137]],"ltp":0.0,"tv":0.0,"id":12984951},{"batb":[[1,1.86,4.68],[2,1.03,137]],"ltp":0.0,"tv":0.0,"id":12984952},{"batb":[[1,3.35,3.27],[2,1.03,137]],"ltp":5.2,"tv":21.28,"id":16574984},{"batb":[[1,2.72,6.34],[2,1.03,137]],"ltp":0.0,"tv":0.0,"id":16574983}]}]}
{"op":"mcm","clk":"1009059739","pt":1580641771242,"mc":[{"id":"1.168217555","rc":[{"batb":[[0,2.4,16.92]],"ltp":0.0,"tv":0.0,"id":12984952},{"batb":[[0,5.5,10.54]],"batl":[[0,6.6,19.59]],"ltp":5.2,"tv":21.28,"id":16574984},{"batb":[[0,4.3,18.88]],"batl":[[0,4.9,18.02]],"ltp":0.0,"tv":0.0,"id":16574983}]}]}
{"op":"mcm","clk":"1009061288","pt":1580641781459,"mc":[{"id":"1.168217555","rc":[{"batl":[[0,2.56,16.6]],"ltp":0.0,"tv":0.0,"id":12984952},{"batl":[[0,6.6,19.43]],"ltp":5.2,"tv":21.28,"id":16574984},{"batl":[[0,5,17.94]],"ltp":0.0,"tv":0.0,"id":16574983}]}]}
{"op":"mcm","clk":"1009062747","pt":1580641791469,"mc":[{"id":"1.168217555","rc":[{"batb":[[0,5.5,10.39]],"ltp":5.2,"tv":21.28,"id":16574984},{"batb":[[0,4.3,18.73]],"batl":[[0,5,17.78]],"ltp":0.0,"tv":0.0,"id":16574983}]}]}
{"op":"mcm","clk":"1009064113","pt":1580641801397,"mc":[{"id":"1.168217555","rc":[{"batb":[[0,5.6,10.31]],"batl":[[0,6.6,19.2]],"ltp":5.2,"tv":21.28,"id":16574984},{"batb":[[0,4.3,18.57]],"ltp":0.0,"tv":0.0,"id":16574983}]}]}
{"op":"mcm","clk":"1009079667","pt":1580641907335,"mc":[{"id":"1.168217555","marketDefinition":{"bspMarket":false,"turnInPlayEnabled":true,"persistenceEnabled":true,"marketBaseRate":5.0,"eventId":"29681263","eventTypeId":"2","numberOfWinners":1,"bettingType":"ODDS","marketType":"SET_BETTING","marketTime":"2020-02-02T11:07:00.000Z","suspendTime":"2020-02-02T11:07:00.000Z","bspReconciled":false,"complete":true,"inPlay":false,"crossMatching":true,"runnersVoidable":false,"numberOfActiveRunners":4,"betDelay":0,"status":"OPEN","runners":[{"status":"ACTIVE","sortPriority":1,"id":16574983,"name":"Karlovskiy 2-0"},{"status":"ACTIVE","sortPriority":2,"id":16574984,"name":"Karlovskiy 2-1"},{"status":"ACTIVE","sortPriority":3,"id":12984952,"name":"Troicki 2-0"},{"status":"ACTIVE","sortPriority":4,"id":12984951,"name":"Troicki 2-1"}],"regulators":["MR_INT"],"countryCode":"IN","discountAllowed":true,"timezone":"UTC","openDate":"2020-02-02T11:09:00.000Z","version":3148508170,"name":"Set Betting","eventName":"Karlovskiy v Troicki"},"rc":[{"batb":[[1,1.03,137],[2,1.02,2]],"ltp":0.0,"tv":0.0,"id":12984951},{"batb":[[1,1.03,137],[2,1.02,2]],"ltp":0.0,"tv":0.0,"id":12984952},{"batb":[[1,1.03,137],[2,1.02,2]],"ltp":5.2,"tv":21.28,"id":16574984},{"batb":[[1,1.03,137],[2,1.02,2]],"ltp":0.0,"tv":0.0,"id":16574983}]}]}
{"op":"mcm","clk":"1009080067","pt":1580641909607,"mc":[{"id":"1.168217555","marketDefinition":{"bspMarket":false,"turnInPlayEnabled":true,"persistenceEnabled":true,"marketBaseRate":5.0,"eventId":"29681263","eventTypeId":"2","numberOfWinners":1,"bettingType":"ODDS","marketType":"SET_BETTING","marketTime":"2020-02-02T11:07:00.000Z","suspendTime":"2020-02-02T11:07:00.000Z","bspReconciled":false,"complete":true,"inPlay":false,"crossMatching":true,"runnersVoidable":false,"numberOfActiveRunners":4,"betDelay":0,"status":"OPEN","runners":[{"status":"ACTIVE","sortPriority":1,"id":16574983,"name":"Karlovskiy 2-0"},{"status":"ACTIVE","sortPriority":2,"id":16574984,"name":"Karlovskiy 2-1"},{"status":"ACTIVE","sortPriority":3,"id":12984952,"name":"Troicki 2-0"},{"status":"ACTIVE","sortPriority":4,"id":12984951,"name":"Troicki 2-1"}],"regulators":["MR_INT"],"countryCode":"IN","discountAllowed":true,"timezone":"UTC","openDate":"2020-02-02T11:07:00.000Z","version":3148508170,"name":"Set Betting","eventName":"Karlovskiy v Troicki"}}]}
{"op":"mcm","clk":"1009087884","pt":1580641959322,"mc":[{"id":"1.168217555","rc":[{"batb":[[1,4,30],[2,1.03,137]],"ltp":0.0,"tv":0.0,"id":12984951},{"batb":[[1,2.24,72.58],[2,1.03,137]],"ltp":0.0,"tv":0.0,"id":12984952},{"batb":[[1,5.5,20],[2,1.03,137]],"ltp":5.2,"tv":21.28,"id":16574984},{"batb":[[1,4,30],[2,1.03,137]],"ltp":0.0,"tv":0.0,"id":16574983}]}]}
{"op":"mcm","clk":"1009102038","pt":1580642049085,"mc":[{"id":"1.168217555","rc":[{"batb":[[1,4.2,12.6],[2,4,30]],"batl":[[0,5,27.86]],"ltp":0.0,"tv":0.0,"id":12984951},{"batb":[[1,2.34,31.09],[2,2.24,72.58]],"batl":[[1,2.62,25.21]],"ltp":0.0,"tv":0.0,"id":12984952},{"batb":[[2,5.4,9.24]],"batl":[[0,6.6,25.92]],"ltp":5.2,"tv":21.28,"id":16574984},{"batb":[[0,4.4,11.76],[1,4.3,18.57],[2,4,30]],"batl":[[1,5.3,9.24]],"ltp":0.0,"tv":0.0,"id":16574983}]}]}
{"op":"mcm","clk":"1009124489","pt":1580642183378,"mc":[{"id":"1.168217555","rc":[{"batl":[[0,4.9,17.94],[1,5,27.86],[2,5.2,10.64]],"ltp":0.0,"tv":0.0,"id":12984951}]}]}
{"op":"mcm","clk":"1009124520","pt":1580642183555,"mc":[{"id":"1.168217555","rc":[{"batl":[[1,5,10.08]],"ltp":0.0,"tv":0.0,"id":12984951}]}]}
{"op":"mcm","clk":"1009129154","pt":1580642213516,"mc":[{"id":"1.168217555","rc":[{"batb":[[0,4.4,2],[1,4.3,18.73],[2,4.2,12.6]],"ltp":0.0,"tv":0.0,"id":12984951},{"batb":[[0,2.42,2],[1,2.4,16.92],[2,2.34,31.09]],"ltp":0.0,"tv":0.0,"id":12984952},{"batb":[[0,4.5,2],[1,4.4,11.76],[2,4.3,18.57]],"ltp":0.0,"tv":0.0,"id":16574983}]}]}
{"op":"mcm","clk":"1009142257","pt":1580642298506,"mc":[{"id":"1.168217555","marketDefinition":{"bspMarket":false,"turnInPlayEnabled":true,"persistenceEnabled":true,"marketBaseRate":5.0,"eventId":"29681263","eventTypeId":"2","numberOfWinners":1,"bettingType":"ODDS","marketType":"SET_BETTING","marketTime":"2020-02-02T11:07:00.000Z","suspendTime":"2020-02-02T11:07:00.000Z","bspReconciled":false,"complete":true,"inPlay":true,"crossMatching":true,"runnersVoidable":false,"numberOfActiveRunners":4,"betDelay":3,"status":"OPEN","runners":[{"status":"ACTIVE","sortPriority":1,"id":16574983,"name":"Karlovskiy 2-0"},{"status":"ACTIVE","sortPriority":2,"id":16574984,"name":"Karlovskiy 2-1"},{"status":"ACTIVE","sortPriority":3,"id":12984952,"name":"Troicki 2-0"},{"status":"ACTIVE","sortPriority":4,"id":12984951,"name":"Troicki 2-1"}],"regulators":["MR_INT"],"countryCode":"IN","discountAllowed":true,"timezone":"UTC","openDate":"2020-02-02T11:07:00.000Z","version":3148519501,"name":"Set Betting","eventName":"Karlovskiy v Troicki"},"rc":[{"batb":[[1,4.2,12.6],[2,4,30]],"batl":[[0,5,10.08],[1,5.2,10.64],[2,5.2,0]],"ltp":0.0,"tv":0.0,"id":12984951},{"batb":[[1,2.34,31.09],[2,2.24,72.58]],"batl":[[0,2.62,25.21],[1,2.62,0]],"ltp":0.0,"tv":0.0,"id":12984952},{"batb":[[0,5.5,20],[1,5.4,9.24],[2,1.03,137]],"batl":[[0,6.6,6.72]],"ltp":5.2,"tv":21.28,"id":16574984},{"batb":[[2,4,30]],"batl":[[0,5.3,9.24],[1,5.3,0]],"ltp":0.0,"tv":0.0,"id":16574983}]}]}
{"op":"mcm","clk":"1009142281","pt":1580642298583,"mc":[{"id":"1.168217555","rc":[{"batb":[[0,1.01,0.51],[1,4.2,0],[2,4,0]],"batl":[[0,5.2,10.64],[1,5.2,0]],"ltp":0.0,"tv":0.0,"id":12984951},{"batb":[[0,1.01,0.51],[1,2.34,0],[2,2.24,0]],"ltp":0.0,"tv":0.0,"id":12984952},{"batb":[[0,1.01,0.51],[1,5.4,0],[2,1.03,0]],"ltp":5.2,"tv":21.28,"id":16574984},{"batb":[[0,1.01,0.51],[1,4.4,0],[2,4,0]],"ltp":0.0,"tv":0.0,"id":16574983}]}]}
{"op":"mcm","clk":"1009143285","pt":1580642305432,"mc":[{"id":"1.168217555","rc":[{"batb":[[0,4.2,20.22],[1,4.1,13.44],[2,1.01,0.51]],"batl":[[0,4.9,28.73],[1,5,17.62],[2,5.2,10.64]],"ltp":0.0,"tv":0.0,"id":12984951},{"batb":[[0,2.56,14.32],[1,2.42,29.41],[2,2.34,18.1]],"batl":[[0,2.74,14.08],[1,2.78,23.53],[2,2.86,12.59]],"ltp":0.0,"tv":0.0,"id":12984952},{"batb":[[0,5.5,10.54],[1,5.3,9.24],[2,1.01,0.51]],"batl":[[0,6.6,25.61]],"ltp":5.2,"tv":21.28,"id":16574984},{"batb":[[0,4.1,13.44],[1,4,22.82],[2,3.8,12.9]],"batl":[[0,4.6,21.64],[1,5,10.08],[2,5.1,16.76]],"ltp":0.0,"tv":0.0,"id":16574983}]}]}
{"op":"mcm","clk":"1009143343","pt":1580642305846,"mc":[{"id":"1.168217555","rc":[{"batb":[[1,2.34,18.1],[2,1.01,0.51]],"ltp":0.0,"tv":0.0,"id":12984952},{"batl":[[1,5.1,16.76],[2,5.1,0]],"ltp":0.0,"tv":0.0,"id":16574983}]}]}
{"op":"mcm","clk":"1009143550","pt":1580642307246,"mc":[{"id":"1.168217555","rc":[{"batb":[[1,2.44,28.57],[2,2.34,18.1]],"ltp":0.0,"tv":0.0,"id":12984952},{"batl":[[1,4.9,10.08],[2,5.1,16.76]],"ltp":0.0,"tv":0.0,"id":16574983}]}]}
{"op":"mcm","clk":"1009144262","pt":1580642312448,"mc":[{"id":"1.168217555","rc":[{"batb":[[1,1.01,0.51],[2,1.01,0]],"batl":[[0,5,17.62],[1,5.2,10.64],[2,5.2,0]],"ltp":0.0,"tv":0.0,"id":12984951},{"batb":[[0,2.34,18.1],[1,1.01,0.51],[2,2.34,0]],"batl":[[0,2.86,12.59],[1,2.78,0],[2,2.86,0]],"ltp":0.0,"tv":0.0,"id":12984952},{"batb":[[1,1.01,0.51],[2,1.01,0]],"batl":[[0,6.6,18.88]],"ltp":5.2,"tv":21.28,"id":16574984},{"batb":[[0,3.8,12.9],[1,1.01,0.51],[2,3.8,0]],"batl":[[0,5.1,16.76],[1,4.9,0],[2,5.1,0]],"ltp":0.0,"tv":0.0,"id":16574983}]}]}
{"op":"mcm","clk":"1009144677","pt":1580642315364,"mc":[{"id":"1.168217555","rc":[{"batb":[[1,4.1,26.77],[2,4,53.71]],"ltp":0.0,"tv":0.0,"id":12984951},{"batb":[[0,2.42,68.33],[1,2.38,80.13],[2,2.34,18.1]],"ltp":0.0,"tv":0.0,"id":12984952},{"batb":[[0,5.6,34.96],[1,5.5,36.38],[2,1.01,0.51]],"ltp":5.2,"tv":21.28,"id":16574984},{"batb":[[0,4,56.26],[1,3.95,27.75],[2,3.8,12.9]],"ltp":0.0,"tv":0.0,"id":16574983}]}]}
{"op":"mcm","clk":"1009146102","pt":1580642324184,"mc":[{"id":"1.168217555","rc":[{"batb":[[0,2.34,18.1],[1,1.01,0.51],[2,2.34,0]],"ltp":0.0,"tv":0.0,"id":12984952}]}]}
{"op":"mcm","clk":"1009146638","pt":1580642327483,"mc":[{"id":"1.168217555","rc":[{"batb":[[1,4.1,40.21]],"batl":[[0,4.9,10.08],[1,5,17.62],[2,5.2,10.64]],"ltp":0.0,"tv":0.0,"id":12984951},{"batb":[[0,2.74,54.94],[1,2.7,57.2],[2,2.54,26.89]],"batl":[[1,2.92,21.85]],"ltp":0.0,"tv":0.0,"id":12984952},{"batb":[[2,5.2,9.24]],"batl":[[0,6.4,7.56],[1,6.6,18.88]],"ltp":5.2,"tv":21.28,"id":16574984},{"batb":[[2,3.9,14.28]],"batl":[[0,4.6,10.92],[1,5.1,16.76]],"ltp":0.0,"tv":0.0,"id":16574983}]}]}
{"op":"mcm","clk":"1009146678","pt":1580642327804,"mc":[{"id":"1.168217555","rc":[{"batl":[[0,4.9,28.57],[1,5.2,10.64],[2,5.2,0]],"ltp":0.0,"tv":0.0,"id":12984951},{"batb":[[2,2.68,12.83]],"batl":[[2,2.98,11.33]],"ltp":0.0,"tv":0.0,"id":12984952},{"batl":[[0,4.3,24.31],[1,4.6,10.92],[2,4.7,20.3]],"ltp":0.0,"tv":0.0,"id":16574983}]}]}
{"op":"mcm","clk":"1009149871","pt":1580642346504,"mc":[{"id":"1.168217555","rc":[{"batb":[[1,4,53.71],[2,1.01,0.51]],"batl":[[0,4.9,18.49]],"ltp":0.0,"tv":0.0,"id":12984951},{"batb":[[0,2.5,15.26],[1,1.01,0.51],[2,2.68,0]],"batl":[[0,2.98,11.33],[1,2.92,0],[2,2.98,0]],"ltp":0.0,"tv":0.0,"id":12984952},{"batb":[[0,5.6,23.68],[2,1.01,0.51]],"batl":[[0,6.6,18.88],[1,6.6,0]],"ltp":5.2,"tv":21.28,"id":16574984},{"batb":[[0,3.65,14.24],[1,1.01,0.51],[2,3.9,0]],"batl":[[0,4.7,20.3],[1,4.6,0],[2,4.7,0]],"ltp":0.0,"tv":0.0,"id":16574983}]}]}
{"op":"mcm","clk":"1009150338","pt":1580642349222,"mc":[{"id":"1.168217555","rc":[{"batb":[[1,4,67.2],[2,3.95,27.65]],"ltp":0.0,"tv":0.0,"id":12984951},{"batb":[[0,2.58,70.73],[1,2.54,67.13],[2,2.5,15.26]],"ltp":0.0,"tv":0.0,"id":12984952},{"batb":[[0,3.9,26.17],[1,3.85,29.76],[2,3.65,14.24]],"ltp":0.0,"tv":0.0,"id":16574983}]}]}
{"op":"mcm","clk":"1009150763","pt":1580642352222,"mc":[{"id":"1.168217555","rc":[{"batb":[[1,4,53.71],[2,1.01,0.51]],"ltp":0.0,"tv":0.0,"id":12984951},{"batb":[[0,2.5,15.26],[1,1.01,0.51],[2,2.5,0]],"ltp":0.0,"tv":0.0,"id":12984952},{"batb":[[0,3.65,14.24],[1,1.01,0.51],[2,3.65,0]],"ltp":0.0,"tv":0.0,"id":16574983}]}]}
{"op":"mcm","clk":"1009151246","pt":1580642355421,"mc":[{"id":"1.168217555","rc":[{"batb":[[1,4.1,13.44],[2,4,67.2]],"batl":[[0,4.9,28.57]],"ltp":0.0,"tv":0.0,"id":12984951},{"batb":[[0,2.84,52.43],[1,2.8,52.06],[2,2.64,25.21]],"batl":[[1,3.05,20.16]],"ltp":0.0,"tv":0.0,"id":12984952},{"batb":[[2,5.2,9.24]],"batl":[[0,6.4,7.56],[1,6.6,18.88]],"ltp":5.2,"tv":21.28,"id":16574984},{"batb":[[0,3.9,26.17],[1,3.85,29.76],[2,3.75,15.12]],"batl":[[0,4.4,11.76],[1,4.7,20.3]],"ltp":0.0,"tv":0.0,"id":16574983}]}]}
{"op":"mcm","clk":"1009151324","pt":1580642356002,"mc":[{"id":"1.168217555","rc":[{"batb":[[0,4.1,34.22],[1,4,67.2],[2,3.95,27.65]],"batl":[[0,4.8,19.28],[1,4.9,10.08],[2,5.2,10.64]],"ltp":0.0,"tv":0.0,"id":12984951},{"batb":[[2,2.78,11.57]],"batl":[[2,3.1,10.46]],"ltp":0.0,"tv":0.0,"id":12984952},{"batb":[[1,5.5,25.84],[2,5.4,10.86]],"batl":[[0,6.4,28.1]],"ltp":5.2,"tv":21.28,"id":16574984},{"batl":[[0,4.1,13.77],[1,4.4,35.68]],"ltp":0.0,"tv":0.0,"id":16574983}]}]}
{"op":"mcm","clk":"1009152926","pt":1580642367453,"mc":[{"id":"1.168217555","rc":[{"batb":[[0,2.66,13.06],[1,2.64,25.21],[2,1.01,0.51]],"batl":[[0,3.05,20.16],[1,3.1,10.46],[2,3.1,0]],"ltp":0.0,"tv":0.0,"id":12984952},{"batb":[[0,5.5,25.84],[1,5.4,10.86],[2,5.2,9.24]],"batl":[[0,6.4,7.56]],"ltp":5.2,"tv":21.28,"id":16574984},{"batb":[[0,3.75,15.12],[1,3.55,15.42],[2,1.01,0.51]],"batl":[[0,4.4,35.68],[1,4.4,0]],"ltp":0.0,"tv":0.0,"id":16574983}]}]}
{"op":"mcm","clk":"1009153233","pt":1580642369250,"mc":[{"id":"1.168217555","rc":[{"batb":[[0,4.1,20.77]],"batl":[[1,5.2,10.64],[2,5.2,0]],"ltp":0.0,"tv":0.0,"id":12984951},{"batb":[[1,1.01,0.51],[2,1.01,0]],"batl":[[0,3.1,10.46],[1,3.1,0]],"ltp":0.0,"tv":0.0,"id":12984952},{"batb":[[2,1.01,0.51]],"batl":[[0,6.6,18.88],[1,6.6,0]],"ltp":5.2,"tv":21.28,"id":16574984},{"batb":[[0,3.55,15.42],[1,1.01,0.51],[2,1.01,0]],"batl":[[0,4.4,23.92]],"ltp":0.0,"tv":0.0,"id":16574983}]}]}
{"op":"mcm","clk":"1009153405","pt":1580642370480,"mc":[{"id":"1.168217555","rc":[{"batb":[[0,5.5,25.96]],"ltp":5.2,"tv":21.28,"id":16574984}]}]}
{"op":"mcm","clk":"1009153665","pt":1580642372238,"mc":[{"id":"1.168217555","rc":[{"batb":[[0,2.82,50.81],[1,2.78,53.05],[2,2.66,13.06]],"ltp":0.0,"tv":0.0,"id":12984952},{"batb":[[0,5.6,26.75],[1,5.5,25.96],[2,5.4,10.86]],"ltp":5.2,"tv":21.28,"id":16574984},{"batb":[[0,3.9,45.35],[1,3.85,29.59],[2,3.55,15.42]],"ltp":0.0,"tv":0.0,"id":16574983}]}]}
{"op":"mcm","clk":"1009154571","pt":1580642378437,"mc":[{"id":"1.168217555","rc":[{"batb":[[0,2.66,13.06],[1,1.01,0.51],[2,2.66,0]],"ltp":0.0,"tv":0.0,"id":12984952},{"batb":[[0,5.5,25.96],[1,5.4,10.86],[2,1.01,0.51]],"ltp":5.2,"tv":21.28,"id":16574984},{"batb":[[0,3.55,15.42],[1,1.01,0.51],[2,3.55,0]],"ltp":0.0,"tv":0.0,"id":16574983}]}]}
{"op":"mcm","clk":"1009155011","pt":1580642381461,"mc":[{"id":"1.168217555","rc":[{"batb":[[0,2.74,47.63],[1,2.7,57.25],[2,2.66,13.06]],"ltp":0.0,"tv":0.0,"id":12984952},{"batb":[[0,5.5,25.84]],"ltp":5.2,"tv":21.28,"id":16574984}]}]}
{"op":"mcm","clk":"1009155388","pt":1580642383973,"mc":[{"id":"1.168217555","rc":[{"batb":[[0,5.6,39.19],[1,5.5,25.84],[2,5.4,10.86]],"ltp":5.2,"tv":21.28,"id":16574984},{"batb":[[0,4,63.88],[1,3.95,27.68],[2,3.55,15.42]],"ltp":0.0,"tv":0.0,"id":16574983}]}]}
{"op":"mcm","clk":"1009155590","pt":1580642385459,"mc":[{"id":"1.168217555","rc":[{"batb":[[1,4,80.64]],"batl":[[0,4.8,29.73]],"ltp":0.0,"tv":0.0,"id":12984951},{"batl":[[0,2.84,12.83],[1,2.92,21.85],[2,2.94,11.57]],"ltp":0.0,"tv":0.0,"id":12984952},{"batb":[[1,5.5,36.38],[2,5.3,9.24]],"batl":[[0,6.6,25.61]],"ltp":5.2,"tv":21.28,"id":16574984},{"batb":[[2,3.9,14.28]],"batl":[[1,4.7,10.92],[2,4.8,19.67]],"ltp":0.0,"tv":0.0,"id":16574983}]}]}
{"op":"mcm","clk":"1009157860","pt":1580642402477,"mc":[{"id":"1.168217555","rc":[{"batb":[[1,4,67.2]],"batl":[[0,4.8,18.8]],"ltp":0.0,"tv":0.0,"id":12984951},{"batb":[[0,2.48,15.5],[1,1.01,0.51],[2,2.66,0]],"batl":[[0,2.94,11.57],[1,2.92,0],[2,2.94,0]],"ltp":0.0,"tv":0.0,"id":12984952},{"batb":[[0,5.6,27.76],[2,1.01,0.51]],"batl":[[0,6.6,18.88]],"ltp":5.2,"tv":21.28,"id":16574984},{"batb":[[0,3.7,13.77],[1,1.01,0.51],[2,3.9,0]],"batl":[[0,4.8,19.67],[1,4.7,0],[2,4.8,0]],"ltp":0.0,"tv":0.0,"id":16574983}]}]}
{"op":"mcm","clk":"1009158287","pt":1580642404895,"mc":[{"id":"1.168217555","rc":[{"batb":[[0,2.6,39.95],[1,2.56,65.93],[2,2.48,15.5]],"ltp":0.0,"tv":0.0,"id":12984952},{"batb":[[0,3.9,37.03],[1,3.85,29.67],[2,3.7,13.77]],"ltp":0.0,"tv":0.0,"id":16574983}]}]}
{"op":"mcm","clk":"1009161557","pt":1580642425446,"mc":[{"id":"1.168217555","rc":[{"batb":[[0,2.48,15.5],[1,1.01,0.51],[2,2.48,0]],"ltp":0.0,"tv":0.0,"id":12984952}]}]}
{"op":"mcm","clk":"1009161970","pt":1580642428151,"mc":[{"id":"1.168217555","rc":[{"batb":[[0,2.84,41.35],[1,2.8,52.14],[2,2.48,15.5]],"ltp":0.0,"tv":0.0,"id":12984952}]}]}
{"op":"mcm","clk":"1009162151","pt":1580642429426,"mc":[{"id":"1.168217555","rc":[{"batb":[[1,4,80.64]],"batl":[[0,4.7,19.75],[1,4.8,29.73],[2,5.2,10.64]],"ltp":0.0,"tv":0.0,"id":12984951},{"batb":[[2,2.76,11.8]],"batl":[[1,3.1,19.32],[2,3.4,21.32]],"ltp":0.0,"tv":0.0,"id":12984952},{"batb":[[1,5.5,25.84],[2,5.4,10.86]],"batl":[[0,6.4,27.78]],"ltp":5.2,"tv":21.28,"id":16574984},{"batb":[[2,3.7,28.89]],"batl":[[0,4.1,13.38],[1,4.4,11.76],[2,4.5,22.27]],"ltp":0.0,"tv":0.0,"id":16574983}]}]}
{"op":"mcm","clk":"1009165473","pt":1580642451880,"mc":[{"id":"1.168217555","rc":[{"batl":[[1,4.5,22.27],[2,4.5,0]],"ltp":0.0,"tv":0.0,"id":16574983}]}]}
{"op":"mcm","clk":"1009165938","pt":1580642454885,"mc":[{"id":"1.168217555","rc":[{"batl":[[1,4.3,12.6],[2,4.5,22.27]],"ltp":0.0,"tv":0.0,"id":16574983}]}]}
{"op":"mcm","clk":"1009167444","pt":1580642465251,"mc":[{"id":"1.168217555","rc":[{"batb":[[1,4,13.44]],"ltp":0.0,"tv":0.0,"id":12984951},{"batb":[[0,2.76,11.8],[1,2.68,24.37],[2,2.6,13.77]],"ltp":0.0,"tv":0.0,"id":12984952},{"batb":[[0,5.5,25.84],[1,5.4,10.86],[2,5.2,9.24]],"ltp":5.2,"tv":21.28,"id":16574984},{"batb":[[0,3.7,28.89],[1,3.3,18.33],[2,1.01,0.51]],"ltp":0.0,"tv":0.0,"id":16574983}]}]}
{"op":"mcm","clk":"1009167903","pt":1580642468201,"mc":[{"id":"1.168217555","rc":[{"batb":[[2,3.95,44.09]],"ltp":0.0,"tv":0.0,"id":12984951},{"batb":[[1,2.68,71.28],[2,2.64,60.73]],"ltp":0.0,"tv":0.0,"id":12984952},{"batb":[[0,5.5,32.37],[1,5.4,37.83]],"ltp":5.2,"tv":21.28,"id":16574984},{"batb":[[1,3.5,31.18],[2,3.45,38.65]],"ltp":0.0,"tv":0.0,"id":16574983}]}]}
{"op":"mcm","clk":"1009168959","pt":1580642475525,"mc":[{"id":"1.168217555","rc":[{"batl":[[0,4.7,444.8]],"ltp":0.0,"tv":0.0,"id":12984951}]}]}
{"op":"mcm","clk":"1009169378","pt":1580642478509,"mc":[{"id":"1.168217555","rc":[{"batb":[[1,3.95,44.09],[2,3.9,28.71]],"batl":[[0,4.8,18.8],[1,5.2,10.64],[2,5.2,0]],"ltp":0.0,"tv":0.0,"id":12984951},{"batb":[[0,2.68,46.91],[1,2.64,60.73],[2,2.6,13.77]],"batl":[[0,3.4,21.09],[1,3.1,0],[2,3.4,0]],"ltp":0.0,"tv":0.0,"id":12984952},{"batb":[[2,1.01,0.51]],"batl":[[0,6.4,20.22]],"ltp":5.2,"tv":21.28,"id":16574984},{"batb":[[0,3.5,31.18],[1,3.45,38.65],[2,3.3,18.33]],"batl":[[0,4.5,22.27],[1,4.3,0],[2,4.5,0]],"ltp":0.0,"tv":0.0,"id":16574983}]}]}
{"op":"mcm","clk":"1009170365","pt":1580642486120,"mc":[{"id":"1.168217555","rc":[{"batb":[[1,1.01,0.51],[2,3.9,0]],"ltp":0.0,"tv":0.0,"id":12984951},{"batb":[[0,5.5,25.84],[1,5.4,10.86]],"ltp":5.2,"tv":21.28,"id":16574984},{"batb":[[0,3.3,18.33],[1,1.01,0.51],[2,3.3,0]],"ltp":0.0,"tv":0.0,"id":16574983}]}]}
{"op":"mcm","clk":"1009170844","pt":1580642489502,"mc":[{"id":"1.168217555","rc":[{"batb":[[0,4.1,66.37],[1,4,53.61],[2,1.01,0.51]],"batl":[[0,4.8,29.73]],"ltp":0.0,"tv":0.0,"id":12984951},{"batl":[[0,2.94,21],[1,3.4,21.09]],"ltp":0.0,"tv":0.0,"id":12984952},{"batb":[[0,5.6,39.71],[1,5.5,25.84],[2,5.4,10.86]],"batl":[[0,6.4,27.78]],"ltp":5.2,"tv":21.28,"id":16574984},{"batb":[[0,4.1,71.23],[1,4,52.93],[2,3.9,14.28]],"batl":[[1,4.6,10.92]],"ltp":0.0,"tv":0.0,"id":16574983}]}]}
{"op":"mcm","clk":"1009170910","pt":1580642490026,"mc":[{"id":"1.168217555","rc":[{"batl":[[1,4.9,18.73],[2,5.2,10.64]],"ltp":0.0,"tv":0.0,"id":12984951},{"batl":[[0,2.78,13.45],[1,2.94,21],[2,3.1,10.54]],"ltp":0.0,"tv":0.0,"id":12984952},{"batl":[[1,6.6,19.51]],"ltp":5.2,"tv":21.28,"id":16574984},{"batb":[[2,3.95,23.76]],"batl":[[2,4.7,20.14]],"ltp":0.0,"tv":0.0,"id":16574983}]}]}
{"op":"mcm","clk":"1009172225","pt":1580642500558,"mc":[{"id":"1.168217555","rc":[{"batb":[[0,4.1,20.77]],"batl":[[0,4.9,18.73],[1,5.2,10.64],[2,5.2,0]],"ltp":0.0,"tv":0.0,"id":12984951},{"batb":[[0,2.5,15.19],[1,1.01,0.51],[2,2.6,0]],"batl":[[0,3.1,10.54],[1,2.94,0],[2,3.1,0]],"ltp":0.0,"tv":0.0,"id":12984952},{"batb":[[0,5.6,19.55]],"batl":[[0,6.6,19.51],[1,6.6,0]],"ltp":5.2,"tv":21.28,"id":16574984},{"batb":[[0,3.55,15.11],[1,1.01,0.51],[2,3.95,0]],"batl":[[0,4.7,20.14],[1,4.6,0],[2,4.7,0]],"ltp":0.0,"tv":0.0,"id":16574983}]}]}
{"op":"mcm","clk":"1009172640","pt":1580642503451,"mc":[{"id":"1.168217555","rc":[{"batb":[[2,3.95,27.78]],"ltp":0.0,"tv":0.0,"id":12984951},{"batb":[[0,2.56,62.31],[1,2.52,68.63],[2,2.5,15.19]],"ltp":0.0,"tv":0.0,"id":12984952},{"batb":[[0,3.8,29.04],[1,3.75,31.65],[2,3.55,15.11]],"ltp":0.0,"tv":0.0,"id":16574983}]}]}
{"op":"mcm","clk":"1009172723","pt":1580642504172,"mc":[{"id":"1.168217555","rc":[{"batb":[[2,1.01,0.51]],"ltp":0.0,"tv":0.0,"id":12984951},{"batb":[[1,5.4,10.86],[2,1.01,0.51]],"ltp":5.2,"tv":21.28,"id":16574984},{"batb":[[0,3.55,15.11],[1,1.01,0.51],[2,3.55,0]],"ltp":0.0,"tv":0.0,"id":16574983}]}]}
{"op":"mcm","clk":"1009173176","pt":1580642507437,"mc":[{"id":"1.168217555","rc":[{"batb":[[0,4.2,20.14],[1,4.1,84.67],[2,4,53.61]],"batl":[[0,4.9,28.81]],"ltp":0.0,"tv":0.0,"id":12984951},{"batl":[[0,2.68,14.87],[1,2.82,22.69],[2,2.86,12.51]],"ltp":0.0,"tv":0.0,"id":12984952},{"batb":[[0,5.7,25.16],[1,5.6,19.55],[2,5.5,10.62]],"batl":[[0,6.4,7.56],[1,6.6,19.51]],"ltp":5.2,"tv":21.28,"id":16574984},{"batb":[[0,4.4,37.69],[1,4.3,45.21],[2,4.1,34.61]],"batl":[[1,4.9,28.02]],"ltp":0.0,"tv":0.0,"id":16574983}]}]}
{"op":"mcm","clk":"1009173187","pt":1580642507545,"mc":[{"id":"1.168217555","rc":[{"batb":[[1,4.1,63.89]],"batl":[[0,4.9,28.26]],"ltp":0.0,"tv":0.0,"id":12984951}]}]}
{"op":"mcm","clk":"1009174185","pt":1580642514858,"mc":[{"id":"1.168217555","rc":[{"batb":[[1,4.1,44.53]],"ltp":0.0,"tv":0.0,"id":12984951},{"batb":[[0,2.48,27.73],[1,2.42,16.6],[2,1.01,0.51]],"batl":[[0,2.82,22.69],[1,2.86,12.51],[2,2.86,0]],"ltp":0.0,"tv":0.0,"id":12984952},{"batb":[[0,5.6,19.55],[1,5.5,10.62],[2,5.3,9.24]],"ltp":5.2,"tv":21.28,"id":16574984},{"batb":[[0,4.1,13.44],[1,3.8,12.9],[2,1.01,0.51]],"batl":[[0,4.9,28.02],[1,4.9,0]],"ltp":0.0,"tv":0.0,"id":16574983}]}]}
{"op":"mcm","clk":"1009174454","pt":1580642516578,"mc":[{"id":"1.168217555","rc":[{"batb":[[1,4.1,31.09]],"batl":[[0,4.9,18.18]],"ltp":0.0,"tv":0.0,"id":12984951},{"batb":[[0,2.42,16.6],[1,1.01,0.51],[2,1.01,0]],"batl":[[0,2.86,12.51],[1,2.86,0]],"ltp":0.0,"tv":0.0,"id":12984952},{"batb":[[2,1.01,0.51]],"batl":[[0,6.6,19.51],[1,6.6,0]],"ltp":5.2,"tv":21.28,"id":16574984},{"batb":[[0,3.8,12.9],[1,1.01,0.51],[2,1.01,0]],"batl":[[0,4.9,17.94]],"ltp":0.0,"tv":0.0,"id":16574983}]}]}
{"op":"mcm","clk":"1009174680","pt":1580642518067,"mc":[{"id":"1.168217555","rc":[{"batb":[[0,2.5,42.94],[1,2.46,73.35],[2,2.42,16.6]],"ltp":0.0,"tv":0.0,"id":12984952},{"batb":[[0,5.6,32.69],[1,5.5,36.49]],"ltp":5.2,"tv":21.28,"id":16574984},{"batb":[[0,4.1,36.01],[1,4,53.54],[2,3.8,12.9]],"ltp":0.0,"tv":0.0,"id":16574983}]}]}
{"op":"mcm","clk":"1009175517","pt":1580642524176,"mc":[{"id":"1.168217555","rc":[{"batb":[[0,5.6,24.82],[1,5.5,10.62]],"ltp":5.2,"tv":21.28,"id":16574984},{"batb":[[0,3.8,12.9],[1,1.01,0.51],[2,3.8,0]],"ltp":0.0,"tv":0.0,"id":16574983}]}]}
{"op":"mcm","clk":"1009176057","pt":1580642527483,"mc":[{"id":"1.168217555","rc":[{"batb":[[1,4.1,74.34]],"batl":[[0,4.9,28.26]],"ltp":0.0,"tv":0.0,"id":12984951},{"batl":[[0,2.72,24.37],[1,2.86,12.51]],"ltp":0.0,"tv":0.0,"id":12984952},{"batb":[[0,5.7,34.73],[1,5.6,24.82],[2,5.5,10.62]],"batl":[[0,6.6,26.23]],"ltp":5.2,"tv":21.28,"id":16574984},{"batb":[[0,4.6,29.03],[1,4.5,40.85],[2,4.3,12.6]],"batl":[[1,5.2,9.24]],"ltp":0.0,"tv":0.0,"id":16574983}]}]}
{"op":"mcm","clk":"1009176154","pt":1580642528077,"mc":[{"id":"1.168217555","rc":[{"batb":[[0,4.2,19.59]],"ltp":0.0,"tv":0.0,"id":12984951},{"batl":[[0,2.58,16.29],[1,2.72,38.76]],"ltp":0.0,"tv":0.0,"id":12984952},{"batl":[[0,6.6,25.84]],"ltp":5.2,"tv":21.28,"id":16574984},{"batb":[[2,4.3,31.49]],"batl":[[1,5.1,16.52],[2,5.2,9.24]],"ltp":0.0,"tv":0.0,"id":16574983}]}]}
{"op":"mcm","clk":"1009177190","pt":1580642535306,"mc":[{"id":"1.168217555","rc":[{"batb":[[0,2.42,16.6],[1,2.4,29.41],[2,2.36,17.78]],"ltp":0.0,"tv":0.0,"id":12984952},{"batb":[[0,5.7,18.65]],"ltp":5.2,"tv":21.28,"id":16574984},{"batb":[[0,4.3,31.49],[1,4,22.27],[2,1.01,0.51]],"ltp":0.0,"tv":0.0,"id":16574983}]}]}
{"op":"mcm","clk":"1009177339","pt":1580642536180,"mc":[{"id":"1.168217555","rc":[{"batb":[[0,2.4,29.41],[1,2.36,17.78],[2,1.01,0.51]],"batl":[[0,2.72,38.76],[1,2.72,0]],"ltp":0.0,"tv":0.0,"id":12984952},{"batb":[[0,4.3,12.6]],"batl":[[0,5.1,16.52],[1,5.2,9.24],[2,5.2,0]],"ltp":0.0,"tv":0.0,"id":16574983}]}]}
{"op":"mcm","clk":"1009177405","pt":1580642536596,"mc":[{"id":"1.168217555","rc":[{"batb":[[1,4.1,60.9]],"batl":[[0,4.9,18.18]],"ltp":0.0,"tv":0.0,"id":12984951},{"batb":[[0,2.36,17.78],[1,1.01,0.51],[2,1.01,0]],"batl":[[0,2.72,14.4]],"ltp":0.0,"tv":0.0,"id":12984952},{"batl":[[0,6.6,19.12]],"ltp":5.2,"tv":21.28,"id":16574984},{"batb":[[0,4,22.27],[1,1.01,0.51],[2,1.01,0]],"batl":[[1,5.2,0]],"ltp":0.0,"tv":0.0,"id":16574983}]}]}
{"op":"mcm","clk":"1009178235","pt":1580642541392,"mc":[{"id":"1.168217555","rc":[{"batb":[[0,2.5,72.69],[1,2.46,73.18],[2,2.36,17.78]],"ltp":0.0,"tv":0.0,"id":12984952},{"batb":[[0,5.7,31.47]],"ltp":5.2,"tv":21.28,"id":16574984},{"batb":[[0,4.5,52.43],[1,4.4,42.63],[2,4,22.27]],"ltp":0.0,"tv":0.0,"id":16574983}]}]}
{"op":"mcm","clk":"1009178615","pt":1580642543925,"mc":[{"id":"1.168217555","rc":[{"batb":[[0,2.36,17.78],[1,1.01,0.51],[2,2.36,0]],"ltp":0.0,"tv":0.0,"id":12984952},{"batb":[[0,5.7,18.65]],"ltp":5.2,"tv":21.28,"id":16574984},{"batb":[[0,4,22.27],[1,1.01,0.51],[2,4,0]],"ltp":0.0,"tv":0.0,"id":16574983}]}]}
{"op":"mcm","clk":"1009178876","pt":1580642545731,"mc":[{"id":"1.168217555","rc":[{"batb":[[1,5.5,10.62],[2,1.01,0.51]],"ltp":5.2,"tv":21.28,"id":16574984}]}]}
{"op":"mcm","clk":"1009179034","pt":1580642546718,"mc":[{"id":"1.168217555","rc":[{"batb":[[0,2.44,77.96],[1,2.4,78.25],[2,2.36,17.78]],"ltp":0.0,"tv":0.0,"id":12984952}]}]}
{"op":"mcm","clk":"1009179461","pt":1580642549522,"mc":[{"id":"1.168217555","rc":[{"batb":[[0,4.3,19.04],[1,4.2,19.59],[2,4.1,74.34]],"batl":[[0,4.9,28.26],[1,5.1,16.76],[2,5.2,10.64]],"ltp":0.0,"tv":0.0,"id":12984951},{"batl":[[0,2.52,17.39],[1,2.62,25.21],[2,2.68,14.87]],"ltp":0.0,"tv":0.0,"id":12984952},{"batb":[[0,5.8,18.79],[1,5.7,18.65],[2,5.6,10.31]],"batl":[[0,6.8,25.21]],"ltp":5.2,"tv":21.28,"id":16574984},{"batb":[[0,4.7,35.5],[1,4.6,38.74],[2,4.5,29.07]],"batl":[[1,5.4,9.24],[2,6,11.8]],"ltp":0.0,"tv":0.0,"id":16574983}]}]}
{"op":"mcm","clk":"1009179616","pt":1580642550747,"mc":[{"id":"1.168217555","rc":[{"trd":[[5.1,4.54]],"batl":[[0,5.1,14.25]],"ltp":5.1,"tv":4.54,"id":16574983}],"tv":25.82}]}
{"op":"mcm","clk":"1009183710","pt":1580642577490,"mc":[{"id":"1.168217555","rc":[{"batb":[[0,4.2,19.59],[1,4.1,44.53],[2,4,53.61]],"batl":[[0,4.9,10.08]],"ltp":0.0,"tv":0.0,"id":12984951},{"batb":[[0,2.32,31.09],[1,2.16,22.9],[2,1.01,0.51]],"batl":[[0,2.62,25.21],[1,2.68,14.87],[2,2.68,0]],"ltp":0.0,"tv":0.0,"id":12984952},{"batb":[[0,5.7,18.65],[1,5.5,19.86],[2,1.01,0.51]],"ltp":5.2,"tv":21.28,"id":16574984},{"batb":[[0,4.5,11.76],[1,4.1,20.85],[2,1.01,0.51]],"batl":[[0,5.4,9.24],[1,6,11.8],[2,6,0]],"ltp":5.1,"tv":4.54,"id":16574983}]}]}
{"op":"mcm","clk":"1009183900","pt":1580642578615,"mc":[{"id":"1.168217555","rc":[{"batb":[[1,4.1,31.09]],"batl":[[0,5.1,16.76],[1,5.2,10.64],[2,5.2,0]],"ltp":0.0,"tv":0.0,"id":12984951},{"batb":[[0,2.16,22.9],[1,1.01,0.51],[2,1.01,0]],"batl":[[0,2.68,14.87],[1,2.68,0]],"ltp":0.0,"tv":0.0,"id":12984952},{"batb":[[1,5.5,10.62]],"batl":[[0,6.8,18.49]],"ltp":5.2,"tv":21.28,"id":16574984},{"batb":[[0,4.1,20.85],[1,1.01,0.51],[2,1.01,0]],"batl":[[0,6,11.8],[1,6,0]],"ltp":5.1,"tv":4.54,"id":16574983}]}]}
{"op":"mcm","clk":"1009184199","pt":1580642580487,"mc":[{"id":"1.168217555","rc":[{"batb":[[0,2.24,63.93],[1,2.22,49.14],[2,2.16,22.9]],"ltp":0.0,"tv":0.0,"id":12984952},{"batb":[[0,5.7,25.27],[1,5.6,24.96],[2,5.5,10.62]],"ltp":5.2,"tv":21.28,"id":16574984},{"batb":[[0,4.3,60.45],[1,4.2,47.36],[2,4.1,20.85]],"ltp":5.1,"tv":4.54,"id":16574983}]}]}
{"op":"mcm","clk":"1009186184","pt":1580642594410,"mc":[{"id":"1.168217555","rc":[{"batb":[[2,1.01,0.51]],"ltp":0.0,"tv":0.0,"id":12984951},{"batb":[[0,2.16,22.9],[1,1.01,0.51],[2,2.16,0]],"ltp":0.0,"tv":0.0,"id":12984952},{"batb":[[0,5.5,10.62],[1,1.01,0.51],[2,5.5,0]],"ltp":5.2,"tv":21.28,"id":16574984},{"batb":[[0,4.1,20.85],[1,1.01,0.51],[2,4.1,0]],"ltp":5.1,"tv":4.54,"id":16574983}]}]}
{"op":"mcm","clk":"1009186582","pt":1580642597251,"mc":[{"id":"1.168217555","rc":[{"batb":[[0,4.2,91.49],[1,4.1,49.91]],"ltp":0.0,"tv":0.0,"id":12984951},{"batb":[[0,2.24,63.93],[1,2.22,49.14],[2,2.16,22.9]],"ltp":0.0,"tv":0.0,"id":12984952},{"batb":[[0,5.9,24.87],[1,5.8,23.09],[2,5.5,10.62]],"ltp":5.2,"tv":21.28,"id":16574984},{"batb":[[0,5.4,39.52],[1,5.3,28.02],[2,4.1,20.85]],"ltp":5.1,"tv":4.54,"id":16574983}]}]}
{"op":"mcm","clk":"1009186707","pt":1580642598127,"mc":[{"id":"1.168217555","rc":[{"batb":[[0,4.4,17.62],[1,4.3,19.12],[2,4.2,84.5]],"batl":[[0,5,10.08],[1,5.1,16.76],[2,5.2,10.64]],"ltp":0.0,"tv":0.0,"id":12984951},{"batl":[[0,2.3,22.35],[1,2.46,18.57]],"ltp":0.0,"tv":0.0,"id":12984952},{"batb":[[2,5.7,19.91]],"batl":[[0,6.8,25.21],[1,7,17.23]],"ltp":5.2,"tv":21.28,"id":16574984},{"batb":[[2,5.2,12.2]],"batl":[[1,6.2,7.56],[2,7.8,13.93]],"ltp":5.1,"tv":4.54,"id":16574983}]}]}
{"op":"mcm","clk":"1009187006","pt":1580642600153,"mc":[{"id":"1.168217555","rc":[{"batl":[[1,2.4,29.41],[2,2.46,18.57]],"ltp":0.0,"tv":0.0,"id":12984952}]}]}
{"op":"mcm","clk":"1009187917","pt":1580642606665,"mc":[{"id":"1.168217555","rc":[{"batb":[[2,4.2,60.6]],"ltp":0.0,"tv":0.0,"id":12984951}]}]}
{"op":"mcm","clk":"1009188448","pt":1580642610044,"mc":[{"id":"1.168217555","rc":[{"batb":[[1,4.3,42.78]],"batl":[[0,4.9,402.85],[1,5,10.08],[2,5.1,16.76]],"ltp":0.0,"tv":0.0,"id":12984951}]}]}
{"op":"mcm","clk":"1009189076","pt":1580642614562,"mc":[{"id":"1.168217555","rc":[{"batb":[[1,4.3,19.12]],"ltp":0.0,"tv":0.0,"id":12984951}]}]}
{"op":"mcm","clk":"1009189528","pt":1580642617545,"mc":[{"id":"1.168217555","rc":[{"batb":[[2,4.2,83.84]],"ltp":0.0,"tv":0.0,"id":12984951}]}]}
{"op":"mcm","clk":"1009189818","pt":1580642619465,"mc":[{"id":"1.168217555","rc":[{"batb":[[2,4.2,12.6]],"batl":[[0,5,10.08],[1,5.1,16.76],[2,5.2,10.64]],"ltp":0.0,"tv":0.0,"id":12984951},{"batb":[[0,2.16,22.9],[1,2.12,36.97],[2,1.95,15.66]],"ltp":0.0,"tv":0.0,"id":12984952},{"batb":[[0,5.8,23.09],[1,5.7,19.91],[2,5.6,28.86]],"ltp":5.2,"tv":21.28,"id":16574984},{"batb":[[0,5.2,12.2],[1,5.1,10.08],[2,4.7,15.5]],"ltp":5.1,"tv":4.54,"id":16574983}]}]}
{"op":"mcm","clk":"1009189866","pt":1580642619891,"mc":[{"id":"1.168217555","rc":[{"batb":[[0,4.3,19.12],[1,4.2,12.6],[2,4.1,49.92]],"batl":[[1,5.2,10.64],[2,5.3,15.19]],"ltp":0.0,"tv":0.0,"id":12984951},{"batb":[[0,2.12,36.97],[1,1.95,15.66],[2,1.01,0.51]],"batl":[[0,2.4,29.41],[1,2.46,18.57],[2,2.46,0]],"ltp":0.0,"tv":0.0,"id":12984952},{"batb":[[1,5.6,28.86],[2,1.01,0.51]],"batl":[[0,6.8,6.72]],"ltp":5.2,"tv":21.28,"id":16574984},{"batb":[[0,5.1,10.08],[1,4.7,15.5],[2,1.01,0.51]],"batl":[[0,6.2,7.56],[1,7.8,13.93],[2,7.8,0]],"ltp":5.1,"tv":4.54,"id":16574983}]}]}
{"op":"mcm","clk":"1009189995","pt":1580642620646,"mc":[{"id":"1.168217555","rc":[{"batb":[[1,4.1,49.92],[2,1.01,0.51]],"batl":[[0,5.2,10.64],[1,5.3,15.19],[2,5.3,0]],"ltp":0.0,"tv":0.0,"id":12984951},{"batb":[[0,1.95,15.66],[1,1.01,0.51],[2,1.01,0]],"batl":[[0,2.46,18.57],[1,2.46,0]],"ltp":0.0,"tv":0.0,"id":12984952},{"batb":[[1,5.6,20.46]],"batl":[[0,7,17.23],[1,7,0]],"ltp":5.2,"tv":21.28,"id":16574984},{"batb":[[0,4.7,15.5],[1,1.01,0.51],[2,1.01,0]],"batl":[[0,7.8,13.93],[1,7.8,0]],"ltp":5.1,"tv":4.54,"id":16574983}]}]}
{"op":"mcm","clk":"1009190255","pt":1580642622466,"mc":[{"id":"1.168217555","rc":[{"batb":[[1,4.1,72.66],[2,4,52.89]],"ltp":0.0,"tv":0.0,"id":12984951},{"batb":[[0,2.02,66.14],[1,2,66.77],[2,1.95,15.66]],"ltp":0.0,"tv":0.0,"id":12984952},{"batb":[[1,5.7,23.98],[2,5.6,20.46]],"ltp":5.2,"tv":21.28,"id":16574984},{"batb":[[0,4.8,53.86],[1,4.7,52.14],[2,1.01,0.51]],"ltp":5.1,"tv":4.54,"id":16574983}]}]}
{"op":"mcm","clk":"1009190302","pt":1580642622773,"mc":[{"id":"1.168217555","rc":[{"batb":[[1,1.01,0.51],[2,4,0]],"ltp":0.0,"tv":0.0,"id":12984951},{"batb":[[0,1.95,15.66],[1,1.01,0.51],[2,1.95,0]],"ltp":0.0,"tv":0.0,"id":12984952},{"batb":[[1,5.6,20.46],[2,1.01,0.51]],"ltp":5.2,"tv":21.28,"id":16574984},{"batb":[[0,4.7,15.5],[1,1.01,0.51],[2,1.01,0]],"ltp":5.1,"tv":4.54,"id":16574983}]}]}
{"op":"mcm","clk":"1009190855","pt":1580642626648,"mc":[{"id":"1.168217555","rc":[{"batb":[[0,4.3,57.79],[1,4.2,47.72],[2,1.01,0.51]],"ltp":0.0,"tv":0.0,"id":12984951},{"batb":[[0,2.18,92.08],[1,2.16,53.1],[2,1.95,15.66]],"ltp":0.0,"tv":0.0,"id":12984952},{"batb":[[0,5.9,33.48],[1,5.8,23.09],[2,5.6,20.46]],"ltp":5.2,"tv":21.28,"id":16574984},{"batb":[[0,5.7,20.51],[1,5.6,25.07],[2,4.7,15.5]],"ltp":5.1,"tv":4.54,"id":16574983}]}]}
{"op":"mcm","clk":"1009191569","pt":1580642631753,"mc":[{"id":"1.168217555","rc":[{"batb":[[0,4.3,19.12],[1,1.01,0.51],[2,1.01,0]],"ltp":0.0,"tv":0.0,"id":12984951},{"batb":[[0,1.95,15.66],[1,1.01,0.51],[2,1.95,0]],"ltp":0.0,"tv":0.0,"id":12984952},{"batb":[[0,5.8,23.09],[1,5.6,20.46],[2,1.01,0.51]],"ltp":5.2,"tv":21.28,"id":16574984},{"batb":[[0,4.7,15.5],[1,1.01,0.51],[2,4.7,0]],"ltp":5.1,"tv":4.54,"id":16574983}]}]}
{"op":"mcm","clk":"1009191986","pt":1580642634368,"mc":[{"id":"1.168217555","rc":[{"batb":[[0,5.6,20.46],[1,1.01,0.51],[2,1.01,0]],"ltp":5.2,"tv":21.28,"id":16574984}]}]}
{"op":"mcm","clk":"1009192157","pt":1580642635479,"mc":[{"id":"1.168217555","rc":[{"batb":[[1,4.1,72.66],[2,4,52.89]],"ltp":0.0,"tv":0.0,"id":12984951},{"batb":[[0,2.02,66.14],[1,2,66.77],[2,1.95,15.66]],"ltp":0.0,"tv":0.0,"id":12984952},{"batb":[[0,5.7,23.98],[1,5.6,20.46],[2,1.01,0.51]],"ltp":5.2,"tv":21.28,"id":16574984},{"batb":[[0,4.8,53.86],[1,4.7,52.14],[2,1.01,0.51]],"ltp":5.1,"tv":4.54,"id":16574983}]}]}
{"op":"mcm","clk":"1009192170","pt":1580642635581,"mc":[{"id":"1.168217555","rc":[{"batb":[[1,1.01,0.51],[2,4,0]],"ltp":0.0,"tv":0.0,"id":12984951},{"batb":[[0,5.6,20.46],[1,1.01,0.51],[2,1.01,0]],"ltp":5.2,"tv":21.28,"id":16574984},{"batb":[[0,4.7,15.5],[1,1.01,0.51],[2,1.01,0]],"ltp":5.1,"tv":4.54,"id":16574983}]}]}
{"op":"mcm","clk":"1009192414","pt":1580642637506,"mc":[{"id":"1.168217555","rc":[{"batb":[[0,4.4,56.46],[1,4.3,76.6],[2,1.01,0.51]],"batl":[[0,5.2,19.88]],"ltp":0.0,"tv":0.0,"id":12984951},{"batb":[[2,1.96,43.69]],"batl":[[0,2.2,34.45],[1,2.46,18.57]],"ltp":0.0,"tv":0.0,"id":12984952},{"batb":[[0,6,39.25],[1,5.9,22.05],[2,5.7,8.4]],"batl":[[0,7,23.95]],"ltp":5.2,"tv":21.28,"id":16574984},{"batb":[[0,6.8,20.16],[1,6.6,34.36],[2,6,8.4]],"batl":[[0,7.6,5.88],[1,7.8,13.93]],"ltp":5.1,"tv":4.54,"id":16574983}]}]}
{"op":"mcm","clk":"1009192558","pt":1580642638490,"mc":[{"id":"1.168217555","rc":[{"batb":[[0,4.6,15.89],[1,4.5,17.31],[2,4.4,56.46]],"batl":[[2,5.7,13.38]],"ltp":0.0,"tv":0.0,"id":12984951},{"batl":[[0,2.06,15.42],[1,2.18,35.29],[2,2.22,24.71]],"ltp":0.0,"tv":0.0,"id":12984952},{"batb":[[2,5.8,18.49]],"batl":[[1,7.2,16.52]],"ltp":5.2,"tv":21.28,"id":16574984},{"batb":[[2,6.4,14.79]],"batl":[[2,11,7.32]],"ltp":5.1,"tv":4.54,"id":16574983}]}]}
{"op":"mcm","clk":"1009194507","pt":1580642651700,"mc":[{"id":"1.168217555","rc":[{"batb":[[0,4.5,17.31],[1,4.3,57.48],[2,1.01,0.51]],"batl":[[1,5.7,13.38],[2,5.7,0]],"ltp":0.0,"tv":0.0,"id":12984951},{"batb":[[0,1.96,43.69],[1,1.77,21.24],[2,1.01,0.51]],"batl":[[0,2.18,35.29],[1,2.22,24.71],[2,2.22,0]],"ltp":0.0,"tv":0.0,"id":12984952},{"batb":[[0,5.9,22.05],[1,5.7,27.99],[2,1.01,0.51]],"batl":[[0,7,6.72]],"ltp":5.2,"tv":21.28,"id":16574984},{"batb":[[0,6.2,7.56],[1,5.6,10.46],[2,1.01,0.51]],"batl":[[1,11,7.32],[2,11,0]],"ltp":5.1,"tv":4.54,"id":16574983}]}]}
{"op":"mcm","clk":"1009194650","pt":1580642652600,"mc":[{"id":"1.168217555","rc":[{"batb":[[1,4.3,44.88]],"batl":[[0,5.2,10.64]],"ltp":0.0,"tv":0.0,"id":12984951},{"batb":[[0,1.77,21.24],[1,1.01,0.51],[2,1.01,0]],"batl":[[0,2.22,24.71],[1,2.22,0]],"ltp":0.0,"tv":0.0,"id":12984952},{"batb":[[1,5.7,19.59]],"batl":[[0,7.2,16.52],[1,7.2,0]],"ltp":5.2,"tv":21.28,"id":16574984},{"batb":[[0,5.6,10.46],[1,1.01,0.51],[2,1.01,0]],"batl":[[0,11,7.32],[1,11,0]],"ltp":5.1,"tv":4.54,"id":16574983}]}]}
{"op":"mcm","clk":"1009194957","pt":1580642654578,"mc":[{"id":"1.168217555","rc":[{"batb":[[2,4.2,47.6]],"ltp":0.0,"tv":0.0,"id":12984951},{"batb":[[0,1.83,69.91],[1,1.81,91.4],[2,1.77,21.24]],"ltp":0.0,"tv":0.0,"id":12984952},{"batb":[[0,5.9,37.04],[1,5.8,22.94],[2,5.7,19.59]],"ltp":5.2,"tv":21.28,"id":16574984},{"batb":[[0,5.8,32.95],[1,5.7,23.92],[2,5.6,10.46]],"ltp":5.1,"tv":4.54,"id":16574983}]}]}
{"op":"mcm","clk":"1009195859","pt":1580642660449,"mc":[{"id":"1.168217555","rc":[{"batb":[[0,1.77,21.24],[1,1.01,0.51],[2,1.77,0]],"ltp":0.0,"tv":0.0,"id":12984952}]}]}
{"op":"mcm","clk":"1009196310","pt":1580642663505,"mc":[{"id":"1.168217555","rc":[{"batb":[[2,4.2,60.2]],"batl":[[0,5.1,10.08],[1,5.2,10.64],[2,5.7,13.38]],"ltp":0.0,"tv":0.0,"id":12984951},{"batb":[[0,2.16,73.66],[1,2.14,54.59],[2,2.06,39.49]],"batl":[[1,2.32,31.09]],"ltp":0.0,"tv":0.0,"id":12984952},{"batb":[[2,5.7,27.99]],"batl":[[0,7,6.72],[1,7.2,16.52]],"ltp":5.2,"tv":21.28,"id":16574984},{"batl":[[0,6.8,6.72],[1,11,7.32]],"ltp":5.1,"tv":4.54,"id":16574983}]}]}
{"op":"mcm","clk":"1009196424","pt":1580642664311,"mc":[{"id":"1.168217555","rc":[{"batb":[[1,4.3,63.76]],"batl":[[0,5.1,26.61],[2,5.5,14.4]],"ltp":0.0,"tv":0.0,"id":12984951},{"batb":[[2,2.08,25.34]],"batl":[[2,2.42,19.51]],"ltp":0.0,"tv":0.0,"id":12984952},{"batl":[[0,6.8,18.25],[1,7,23.87]],"ltp":5.2,"tv":21.28,"id":16574984},{"batl":[[0,6.6,19.43],[1,6.8,6.72],[2,9,10.07]],"ltp":5.1,"tv":4.54,"id":16574983}]}]}
{"op":"mcm","clk":"1009199585","pt":1580642686165,"mc":[{"id":"1.168217555","rc":[{"batb":[[0,4.3,18.88],[1,4.2,43],[2,1.01,0.51]],"batl":[[0,5.1,10.08]],"ltp":0.0,"tv":0.0,"id":12984951},{"batb":[[0,2.06,39.49],[1,1.86,18.25],[2,1.01,0.51]],"batl":[[0,2.32,31.09],[1,2.42,19.51],[2,2.42,0]],"ltp":0.0,"tv":0.0,"id":12984952},{"batb":[[0,5.8,22.94],[1,5.7,8.4],[2,5.6,20.22]],"batl":[[0,7,23.87],[1,7,0]],"ltp":5.2,"tv":21.28,"id":16574984},{"batb":[[0,5.5,9.24],[1,4.9,14.4],[2,1.01,0.51]],"batl":[[0,6.8,6.72],[1,9,10.07],[2,9,0]],"ltp":5.1,"tv":4.54,"id":16574983}]}]}
{"op":"mcm","clk":"1009199646","pt":1580642686537,"mc":[{"id":"1.168217555","rc":[{"batb":[[1,4.2,30.4]],"batl":[[0,5.2,10.64],[1,5.5,14.4],[2,5.5,0]],"ltp":0.0,"tv":0.0,"id":12984951},{"batb":[[0,1.86,18.25],[1,1.01,0.51],[2,1.01,0]],"batl":[[0,2.42,19.51],[1,2.42,0]],"ltp":0.0,"tv":0.0,"id":12984952},{"batb":[[1,5.6,20.22],[2,1.01,0.51]],"batl":[[0,7,17.15]],"ltp":5.2,"tv":21.28,"id":16574984},{"batb":[[0,4.9,14.4],[1,1.01,0.51],[2,1.01,0]],"batl":[[0,9,10.07],[1,9,0]],"ltp":5.1,"tv":4.54,"id":16574983}]}]}
{"op":"mcm","clk":"1009200000","pt":1580642689034,"mc":[{"id":"1.168217555","rc":[{"batb":[[2,4.1,50.63]],"ltp":0.0,"tv":0.0,"id":12984951},{"batb":[[0,1.92,54.22],[1,1.9,78.22],[2,1.86,18.25]],"ltp":0.0,"tv":0.0,"id":12984952},{"batb":[[0,5.8,34.96],[1,5.7,23.88],[2,5.6,20.22]],"ltp":5.2,"tv":21.28,"id":16574984},{"batb":[[0,5,34.95],[1,4.9,48],[2,1.01,0.51]],"ltp":5.1,"tv":4.54,"id":16574983}]}]}
{"op":"mcm","clk":"1009201315","pt":1580642698251,"mc":[{"id":"1.168217555","rc":[{"batb":[[1,1.01,0.51],[2,4.1,0]],"ltp":0.0,"tv":0.0,"id":12984951},{"batb":[[0,5.6,20.22],[1,1.01,0.51],[2,5.6,0]],"ltp":5.2,"tv":21.28,"id":16574984},{"batb":[[0,4.9,14.4],[1,1.01,0.51],[2,1.01,0]],"ltp":5.1,"tv":4.54,"id":16574983}]}]}
{"op":"mcm","clk":"1009201738","pt":1580642701456,"mc":[{"id":"1.168217555","rc":[{"batb":[[0,4.5,57.35],[1,4.4,54.28],[2,4.3,18.88]],"batl":[[1,5.3,9.24],[2,5.5,14.4]],"ltp":0.0,"tv":0.0,"id":12984951},{"batb":[[2,1.89,47.05]],"batl":[[0,2.1,37.81],[1,2.42,19.51]],"ltp":0.0,"tv":0.0,"id":12984952},{"batb":[[0,6,55.18],[1,5.9,21.82],[2,5.7,8.4]],"batl":[[0,7,23.87]],"ltp":5.2,"tv":21.28,"id":16574984},{"batb":[[0,7.8,29.7],[1,7.6,25.1],[2,6.8,6.72]],"batl":[[0,8.8,5.04],[1,9,10.07]],"ltp":5.1,"tv":4.54,"id":16574983}]}]}
{"op":"mcm","clk":"1009201853","pt":1580642702259,"mc":[{"id":"1.168217555","rc":[{"batb":[[0,4.8,15.03],[1,4.6,16.44],[2,4.5,57.35]],"ltp":0.0,"tv":0.0,"id":12984951},{"batl":[[0,1.95,17.94],[1,2.08,38.65],[2,2.1,28.64]],"ltp":0.0,"tv":0.0,"id":12984952},{"batb":[[1,5.9,40.15],[2,5.7,27.6]],"batl":[[1,7.2,16.21]],"ltp":5.2,"tv":21.28,"id":16574984},{"batb":[[2,7.4,10.62]],"batl":[[2,15,9.99]],"ltp":5.1,"tv":4.54,"id":16574983}]}]}
{"op":"mcm","clk":"1009203938","pt":1580642717471,"mc":[{"id":"1.168217555","rc":[{"batb":[[0,1.89,47.05],[1,1.86,18.25],[2,1.67,25.81]],"ltp":0.0,"tv":0.0,"id":12984952}]}]}
{"op":"mcm","clk":"1009204315","pt":1580642720400,"mc":[{"id":"1.168217555","rc":[{"batb":[[0,1.91,90.04],[1,1.89,126.61],[2,1.86,18.25]],"ltp":0.0,"tv":0.0,"id":12984952}]}]}
{"op":"mcm","clk":"1009204994","pt":1580642724906,"mc":[{"id":"1.168217555","rc":[{"batb":[[0,4.6,16.44],[1,4.4,54.28],[2,1.01,0.51]],"batl":[[2,5.9,12.43]],"ltp":0.0,"tv":0.0,"id":12984951},{"batb":[[0,1.89,47.05],[1,1.67,25.81],[2,1.01,0.51]],"batl":[[0,2.08,38.65],[1,2.1,28.64],[2,2.1,0]],"ltp":0.0,"tv":0.0,"id":12984952},{"batb":[[0,6,29.32],[1,5.9,21.82]],"batl":[[0,7,6.72]],"ltp":5.2,"tv":21.28,"id":16574984},{"batb":[[0,6.8,6.72],[1,6.2,16.05],[2,1.01,0.51]],"batl":[[1,15,9.99],[2,15,0]],"ltp":5.1,"tv":4.54,"id":16574983}]}]}
{"op":"mcm","clk":"1009205245","pt":1580642726704,"mc":[{"id":"1.168217555","rc":[{"batb":[[1,4.4,42.52]],"batl":[[1,5.9,12.43],[2,5.9,0]],"ltp":0.0,"tv":0.0,"id":12984951},{"batb":[[0,1.67,25.81],[1,1.01,0.51],[2,1.01,0]],"batl":[[0,2.1,28.64],[1,2.1,0]],"ltp":0.0,"tv":0.0,"id":12984952},{"batb":[[2,5.7,19.2]],"batl":[[0,7.2,16.21],[1,7.2,0]],"ltp":5.2,"tv":21.28,"id":16574984},{"batb":[[0,6.2,16.05],[1,1.01,0.51],[2,1.01,0]],"batl":[[0,15,9.99],[1,15,0]],"ltp":5.1,"tv":4.54,"id":16574983}]}]}
{"op":"mcm","clk":"1009205432","pt":1580642727875,"mc":[{"id":"1.168217555","rc":[{"batb":[[2,4.3,45.22]],"ltp":0.0,"tv":0.0,"id":12984951},{"batb":[[0,1.72,101.32],[1,1.7,112.99],[2,1.67,25.81]],"ltp":0.0,"tv":0.0,"id":12984952},{"batb":[[0,6.4,40.55],[1,6.2,54.93],[2,1.01,0.51]],"ltp":5.1,"tv":4.54,"id":16574983}]}]}
{"op":"mcm","clk":"1009205597","pt":1580642728985,"mc":[{"id":"1.168217555","rc":[{"batb":[[1,1.01,0.51],[2,4.3,0]],"ltp":0.0,"tv":0.0,"id":12984951},{"batb":[[0,1.67,25.81],[1,1.01,0.51],[2,1.67,0]],"ltp":0.0,"tv":0.0,"id":12984952},{"batb":[[1,5.7,19.2],[2,1.01,0.51]],"ltp":5.2,"tv":21.28,"id":16574984},{"batb":[[0,6.2,16.05],[1,1.01,0.51],[2,1.01,0]],"ltp":5.1,"tv":4.54,"id":16574983}]}]}
{"op":"mcm","clk":"1009206195","pt":1580642733006,"mc":[{"id":"1.168217555","rc":[{"batb":[[0,4.6,51.51],[1,4.5,40.72],[2,1.01,0.51]],"ltp":0.0,"tv":0.0,"id":12984951},{"batb":[[0,1.87,86.84],[1,1.85,85.17],[2,1.67,25.81]],"ltp":0.0,"tv":0.0,"id":12984952},{"batb":[[0,6.2,22.16],[1,6,42.27],[2,5.7,19.2]],"ltp":5.2,"tv":21.28,"id":16574984},{"batb":[[0,8.4,24.67],[1,8.2,21.42],[2,6.2,16.05]],"ltp":5.1,"tv":4.54,"id":16574983}]}]}
{"op":"mcm","clk":"1009206965","pt":1580642738402,"mc":[{"id":"1.168217555","rc":[{"batb":[[0,4.6,16.44],[1,1.01,0.51],[2,1.01,0]],"ltp":0.0,"tv":0.0,"id":12984951},{"batb":[[0,1.67,25.81],[1,1.01,0.51],[2,1.67,0]],"ltp":0.0,"tv":0.0,"id":12984952},{"batb":[[0,6,29.32],[1,5.7,19.2],[2,1.01,0.51]],"ltp":5.2,"tv":21.28,"id":16574984},{"batb":[[0,6.2,16.05],[1,1.01,0.51],[2,6.2,0]],"ltp":5.1,"tv":4.54,"id":16574983}]}]}
{"op":"mcm","clk":"1009207388","pt":1580642741409,"mc":[{"id":"1.168217555","rc":[{"batb":[[1,4.4,35.54],[2,4.3,45.22]],"ltp":0.0,"tv":0.0,"id":12984951},{"batb":[[0,1.72,101.32],[1,1.7,112.99],[2,1.67,25.81]],"ltp":0.0,"tv":0.0,"id":12984952},{"batb":[[1,5.9,22.21],[2,5.7,19.2]],"ltp":5.2,"tv":21.28,"id":16574984},{"batb":[[0,6.4,40.55],[1,6.2,54.93],[2,1.01,0.51]],"ltp":5.1,"tv":4.54,"id":16574983}]}]}
{"op":"mcm","clk":"1009207823","pt":1580642744515,"mc":[{"id":"1.168217555","rc":[{"batb":[[1,1.01,0.51],[2,4.3,0]],"ltp":0.0,"tv":0.0,"id":12984951},{"batb":[[0,1.67,25.81],[1,1.01,0.51],[2,1.67,0]],"ltp":0.0,"tv":0.0,"id":12984952},{"batb":[[1,5.7,19.2],[2,1.01,0.51]],"ltp":5.2,"tv":21.28,"id":16574984},{"batb":[[0,6.2,16.05],[1,1.01,0.51],[2,1.01,0]],"ltp":5.1,"tv":4.54,"id":16574983}]}]}
{"op":"mcm","clk":"1009208262","pt":1580642747508,"mc":[{"id":"1.168217555","rc":[{"batb":[[1,4.2,12.6],[2,1.01,0.51]],"batl":[[0,5.1,10.08],[1,5.2,10.64],[2,5.9,12.43]],"ltp":0.0,"tv":0.0,"id":12984951},{"batb":[[0,1.98,42.85],[1,1.67,25.81],[2,1.01,0.51]],"batl":[[1,2.2,34.45]],"ltp":0.0,"tv":0.0,"id":12984952},{"batb":[[1,5.8,8.4],[2,5.7,19.2]],"batl":[[0,7.2,22.93]],"ltp":5.2,"tv":21.28,"id":16574984},{"batb":[[1,6,8.4],[2,1.01,0.51]],"batl":[[0,7.6,5.88],[1,15,9.99]],"ltp":5.1,"tv":4.54,"id":16574983}]}]}
{"op":"mcm","clk":"1009208403","pt":1580642748414,"mc":[{"id":"1.168217555","rc":[{"batb":[[1,4.4,53.87],[2,4.3,57.82]],"batl":[[2,5.3,15.74]],"ltp":0.0,"tv":0.0,"id":12984951},{"batb":[[0,2.06,71.96],[1,2.04,62.89],[2,1.99,42.01]],"batl":[[1,2.22,33.61],[2,2.38,20.38]],"ltp":0.0,"tv":0.0,"id":12984952},{"batb":[[1,5.9,22.21],[2,5.7,27.6]],"batl":[[0,7,23.72]],"ltp":5.2,"tv":21.28,"id":16574984},{"batb":[[0,6.4,40.55],[1,6.2,54.93],[2,6,8.4]],"batl":[[0,7.4,20.99],[1,14,10.94]],"ltp":5.1,"tv":4.54,"id":16574983}]}]}
{"op":"mcm","clk":"1009211397","pt":1580642769073,"mc":[{"id":"1.168217555","rc":[{"batb":[[0,4.4,18.33],[1,4.3,12.6],[2,1.01,0.51]],"batl":[[2,5.8,12.59]],"ltp":0.0,"tv":0.0,"id":12984951},{"batb":[[0,1.99,42.01],[1,1.69,24.63],[2,1.01,0.51]],"batl":[[0,2.22,33.61],[1,2.38,20.38],[2,2.38,0]],"ltp":0.0,"tv":0.0,"id":12984952},{"batb":[[0,5.9,22.21],[1,5.7,27.6],[2,1.01,0.51]],"ltp":5.2,"tv":21.28,"id":16574984},{"batb":[[0,6,8.4],[1,4.9,14.01],[2,1.01,0.51]],"batl":[[0,7.4,5.88]],"ltp":5.1,"tv":4.54,"id":16574983}]}]}
{"op":"mcm","clk":"1009211617","pt":1580642770651,"mc":[{"id":"1.168217555","rc":[{"batb":[[1,1.01,0.51],[2,1.01,0]],"batl":[[0,5.2,10.64],[1,5.8,12.59],[2,5.8,0]],"ltp":0.0,"tv":0.0,"id":12984951},{"batb":[[0,1.69,24.63],[1,1.01,0.51],[2,1.01,0]],"batl":[[0,2.38,20.38],[1,2.38,0]],"ltp":0.0,"tv":0.0,"id":12984952},{"batb":[[1,5.7,19.2]],"batl":[[0,7,17]],"ltp":5.2,"tv":21.28,"id":16574984},{"batb":[[0,4.9,14.01],[1,1.01,0.51],[2,1.01,0]],"batl":[[0,14,10.94],[1,14,0]],"ltp":5.1,"tv":4.54,"id":16574983}]}]}
{"op":"mcm","clk":"1009211804","pt":1580642771836,"mc":[{"id":"1.168217555","rc":[{"batb":[[1,4.2,31.81],[2,4.1,50.59]],"ltp":0.0,"tv":0.0,"id":12984951},{"batb":[[0,1.74,78.63],[1,1.72,108.44],[2,1.69,24.63]],"ltp":0.0,"tv":0.0,"id":12984952},{"batb":[[1,5.8,23.22],[2,5.7,19.2]],"ltp":5.2,"tv":21.28,"id":16574984},{"batb":[[0,5.1,23.3],[1,5,32.3],[2,4.9,14.01]],"ltp":5.1,"tv":4.54,"id":16574983}]}]}
{"op":"mcm","clk":"1009214350","pt":1580642788990,"mc":[{"id":"1.168217555","rc":[{"batb":[[1,1.01,0.51],[2,4.1,0]],"ltp":0.0,"tv":0.0,"id":12984951},{"batb":[[0,5.7,19.2],[1,1.01,0.51],[2,5.7,0]],"ltp":5.2,"tv":21.28,"id":16574984},{"batb":[[0,4.9,14.01],[1,1.01,0.51],[2,4.9,0]],"ltp":5.1,"tv":4.54,"id":16574983}]}]}
{"op":"mcm","clk":"1009214737","pt":1580642791485,"mc":[{"id":"1.168217555","rc":[{"batb":[[0,4.6,10.92],[1,4.4,18.33],[2,1.01,0.51]],"batl":[[1,5.5,9.24],[2,5.8,12.59]],"ltp":0.0,"tv":0.0,"id":12984951},{"batb":[[2,1.69,85.12]],"batl":[[0,1.85,42.01],[1,2.38,20.38]],"ltp":0.0,"tv":0.0,"id":12984952},{"batb":[[0,6,8.4],[1,5.7,19.2],[2,1.01,0.51]],"batl":[[1,7.6,5.88]],"ltp":5.2,"tv":21.28,"id":16574984},{"batb":[[0,10,4.2],[1,4.9,14.01],[2,1.01,0.51]],"batl":[[0,13.5,3.36],[1,14,10.94]],"ltp":5.1,"tv":4.54,"id":16574983}]}]}
{"op":"mcm","clk":"1009214889","pt":1580642792460,"mc":[{"id":"1.168217555","rc":[{"batb":[[0,5,13.14],[1,4.9,14.32],[2,4.8,27.04]],"ltp":0.0,"tv":0.0,"id":12984951},{"batl":[[0,1.78,24.16],[1,1.85,42.01],[2,1.9,19.51]],"ltp":0.0,"tv":0.0,"id":12984952},{"batb":[[0,6.2,39.03],[1,6,50.2],[2,5.7,19.2]],"batl":[[0,7,16.6]],"ltp":5.2,"tv":21.28,"id":16574984},{"batb":[[0,11.5,20.17],[1,11,27.98],[2,10.5,11.96]],"batl":[[2,17,7.79]],"ltp":5.1,"tv":4.54,"id":16574983}]}]}
{"op":"mcm","clk":"1009217898","pt":1580642810952,"mc":[{"id":"1.168217555","rc":[{"batb":[[0,6.2,44.88]],"ltp":5.2,"tv":21.28,"id":16574984}]}]}
{"op":"mcm","clk":"1009220713","pt":1580642828274,"mc":[{"id":"1.168217555","rc":[{"batb":[[0,11.5,23.22]],"ltp":5.1,"tv":4.54,"id":16574983}]}]}
{"op":"mcm","clk":"1009227217","pt":1580642870319,"mc":[{"id":"1.168217555","rc":[{"batb":[[0,4.9,14.32],[1,4.6,10.92],[2,1.01,0.51]],"batl":[[2,5.9,12.04]],"ltp":0.0,"tv":0.0,"id":12984951},{"batb":[[0,1.69,60.49],[1,1.64,27.38],[2,1.01,0.51]],"batl":[[0,1.85,42.01],[1,1.9,19.51],[2,1.9,0]],"ltp":0.0,"tv":0.0,"id":12984952},{"batb":[[0,6,50.2],[1,5.7,19.2],[2,1.01,0.51]],"ltp":5.2,"tv":21.28,"id":16574984},{"batb":[[0,10,4.2],[1,8.4,8.26],[2,1.01,0.51]],"batl":[[1,17,7.79],[2,17,0]],"ltp":5.1,"tv":4.54,"id":16574983}]}]}
{"op":"mcm","clk":"1009227264","pt":1580642870645,"mc":[{"id":"1.168217555","rc":[{"batb":[[1,1.01,0.51],[2,1.01,0]],"batl":[[1,5.9,12.04],[2,5.9,0]],"ltp":0.0,"tv":0.0,"id":12984951},{"batb":[[0,1.64,27.38],[1,1.01,0.51],[2,1.01,0]],"batl":[[0,1.9,19.51],[1,1.9,0]],"ltp":0.0,"tv":0.0,"id":12984952},{"batb":[[0,6,41.8]],"batl":[[1,7.6,0]],"ltp":5.2,"tv":21.28,"id":16574984},{"batb":[[0,8.4,8.26],[1,1.01,0.51],[2,1.01,0]],"batl":[[0,17,7.79],[1,17,0]],"ltp":5.1,"tv":4.54,"id":16574983}]}]}
{"op":"mcm","clk":"1009227622","pt":1580642873305,"mc":[{"id":"1.168217555","rc":[{"batb":[[1,4.6,45.2],[2,4.5,40.51]],"ltp":0.0,"tv":0.0,"id":12984951},{"batb":[[0,1.69,60.43],[1,1.67,120.11],[2,1.64,27.38]],"ltp":0.0,"tv":0.0,"id":12984952},{"batb":[[0,6,54.18],[1,5.9,21.95],[2,5.7,19.2]],"ltp":5.2,"tv":21.28,"id":16574984},{"batb":[[0,9,22.7],[1,8.8,18.53],[2,8.4,8.26]],"ltp":5.1,"tv":4.54,"id":16574983}]}]}
{"op":"mcm","clk":"1009228773","pt":1580642881209,"mc":[{"id":"1.168217555","rc":[{"batb":[[1,1.01,0.51],[2,4.5,0]],"ltp":0.0,"tv":0.0,"id":12984951},{"batb":[[0,1.64,27.38],[1,1.01,0.51],[2,1.64,0]],"ltp":0.0,"tv":0.0,"id":12984952},{"batb":[[0,6,41.8],[1,5.7,19.2],[2,1.01,0.51]],"ltp":5.2,"tv":21.28,"id":16574984},{"batb":[[0,8.4,8.26],[1,1.01,0.51],[2,8.4,0]],"ltp":5.1,"tv":4.54,"id":16574983}]}]}
{"op":"mcm","clk":"1009229249","pt":1580642884538,"mc":[{"id":"1.168217555","rc":[{"batb":[[1,4.7,50.76],[2,4.6,38.41]],"ltp":0.0,"tv":0.0,"id":12984951},{"batb":[[0,1.76,70.22],[1,1.74,104.26],[2,1.64,27.38]],"ltp":0.0,"tv":0.0,"id":12984952},{"batb":[[0,6.2,38.38],[1,6,41.8],[2,5.7,19.2]],"ltp":5.2,"tv":21.28,"id":16574984},{"batb":[[0,11,16.69],[1,10.5,31.14],[2,8.4,8.26]],"ltp":5.1,"tv":4.54,"id":16574983}]}]}
{"op":"mcm","clk":"1009229822","pt":1580642888362,"mc":[{"id":"1.168217555","rc":[{"batb":[[1,4.6,38.41],[2,1.01,0.51]],"ltp":0.0,"tv":0.0,"id":12984951},{"batb":[[0,1.64,27.38],[1,1.01,0.51],[2,1.64,0]],"ltp":0.0,"tv":0.0,"id":12984952},{"batb":[[0,6,41.8],[1,5.7,19.2],[2,1.01,0.51]],"ltp":5.2,"tv":21.28,"id":16574984},{"batb":[[0,8.4,8.26],[1,1.01,0.51],[2,8.4,0]],"ltp":5.1,"tv":4.54,"id":16574983}]}]}
{"op":"mcm","clk":"1009230172","pt":1580642890941,"mc":[{"id":"1.168217555","rc":[{"batb":[[2,4.5,40.51]],"ltp":0.0,"tv":0.0,"id":12984951},{"batb":[[0,1.69,60.41],[1,1.67,120.11],[2,1.64,27.38]],"ltp":0.0,"tv":0.0,"id":12984952},{"batb":[[0,6,54.19],[1,5.9,21.95],[2,5.7,19.2]],"ltp":5.2,"tv":21.28,"id":16574984},{"batb":[[0,9,22.72],[1,8.8,18.53],[2,8.4,8.26]],"ltp":5.1,"tv":4.54,"id":16574983}]}]}
{"op":"mcm","clk":"1009232712","pt":1580642909637,"mc":[{"id":"1.168217555","rc":[{"batb":[[1,1.01,0.51],[2,4.5,0]],"ltp":0.0,"tv":0.0,"id":12984951},{"batb":[[0,5.7,19.2],[1,1.01,0.51],[2,5.7,0]],"ltp":5.2,"tv":21.28,"id":16574984},{"batb":[[0,8.4,8.26],[1,1.01,0.51],[2,8.4,0]],"ltp":5.1,"tv":4.54,"id":16574983}]}]}
{"op":"mcm","clk":"1009233268","pt":1580642913453,"mc":[{"id":"1.168217555","rc":[{"batb":[[0,5.1,12.51],[1,5,13.61],[2,4.9,14.32]],"batl":[[2,6.2,11.49]],"ltp":0.0,"tv":0.0,"id":12984951},{"batb":[[0,1.64,27.38],[1,1.6,30.21],[2,1.01,0.51]],"batl":[[0,1.72,26.75],[1,1.82,22.27],[2,1.9,19.51]],"ltp":0.0,"tv":0.0,"id":12984952},{"batb":[[0,6.4,22.27],[1,6.2,39.49],[2,5.9,17.78]],"batl":[[1,7.2,15.82]],"ltp":5.2,"tv":21.28,"id":16574984},{"batb":[[0,13.5,19.01],[1,13,19.86],[2,12,8.42]],"batl":[[1,20,5.74]],"ltp":5.1,"tv":4.54,"id":16574983}]}]}
{"op":"mcm","clk":"1009233386","pt":1580642914258,"mc":[{"id":"1.168217555","rc":[{"batb":[[2,4.8,52.81]],"batl":[[1,5.6,8.4],[2,5.9,12.04]],"ltp":0.0,"tv":0.0,"id":12984951},{"batb":[[0,1.64,92.92]],"batl":[[1,1.79,42.01],[2,1.82,22.27]],"ltp":0.0,"tv":0.0,"id":12984952},{"batb":[[1,6.2,47.05]],"batl":[[2,7.6,5.88]],"ltp":5.2,"tv":21.28,"id":16574984}]}]}
{"op":"mcm","clk":"1009233687","pt":1580642916265,"mc":[{"id":"1.168217555","rc":[{"batb":[[0,1.68,97.55],[1,1.66,122.98],[2,1.64,92.92]],"ltp":0.0,"tv":0.0,"id":12984952},{"batb":[[0,6.4,32.63]],"ltp":5.2,"tv":21.28,"id":16574984},{"batb":[[0,13.5,23.51]],"ltp":5.1,"tv":4.54,"id":16574983}]}]}
{"op":"mcm","clk":"1009235437","pt":1580642927998,"mc":[{"id":"1.168217555","rc":[{"batb":[[0,5,13.61],[1,4.7,47.44],[2,1.01,0.51]],"batl":[[2,6.2,11.49]],"ltp":0.0,"tv":0.0,"id":12984951},{"batb":[[0,1.64,65.54],[1,1.6,30.21],[2,1.01,0.51]],"batl":[[0,1.79,42.01],[1,1.82,22.27],[2,1.82,0]],"ltp":0.0,"tv":0.0,"id":12984952},{"batb":[[0,6.2,47.05],[1,5.8,19.04],[2,1.01,0.51]],"batl":[[0,7.2,15.82],[1,7.6,5.88],[2,7.6,0]],"ltp":5.2,"tv":21.28,"id":16574984},{"batb":[[0,11.5,3.36],[1,9.8,14.56],[2,1.01,0.51]],"batl":[[0,20,5.74],[1,20,0]],"ltp":5.1,"tv":4.54,"id":16574983}]}]}
{"op":"mcm","clk":"1009235558","pt":1580642928786,"mc":[{"id":"1.168217555","rc":[{"batb":[[1,4.7,36.52]],"batl":[[1,6.2,11.49],[2,6.2,0]],"ltp":0.0,"tv":0.0,"id":12984951},{"batb":[[0,1.6,30.21],[1,1.01,0.51],[2,1.01,0]],"batl":[[0,1.82,22.27],[1,1.82,0]],"ltp":0.0,"tv":0.0,"id":12984952},{"batb":[[0,6.2,39.49]],"batl":[[1,7.6,0]],"ltp":5.2,"tv":21.28,"id":16574984},{"batb":[[0,9.8,14.56],[1,1.01,0.51],[2,1.01,0]],"ltp":5.1,"tv":4.54,"id":16574983}]}]}
{"op":"mcm","clk":"1009235928","pt":1580642931511,"mc":[{"id":"1.168217555","rc":[{"batb":[[2,4.6,38.52]],"ltp":0.0,"tv":0.0,"id":12984951},{"batb":[[0,1.64,116.72],[1,1.63,66.13],[2,1.6,30.21]],"ltp":0.0,"tv":0.0,"id":12984952},{"batb":[[1,6,42.27],[2,5.8,19.04]],"ltp":5.2,"tv":21.28,"id":16574984},{"batb":[[0,11,13.04],[1,10.5,31.54],[2,9.8,14.56]],"ltp":5.1,"tv":4.54,"id":16574983}]}]}
{"op":"mcm","clk":"1009236658","pt":1580642936303,"mc":[{"id":"1.168217555","rc":[{"batb":[[1,1.01,0.51],[2,4.6,0]],"ltp":0.0,"tv":0.0,"id":12984951},{"batb":[[1,5.8,19.04],[2,1.01,0.51]],"ltp":5.2,"tv":21.28,"id":16574984},{"batb":[[0,9.8,14.56],[1,1.01,0.51],[2,9.8,0]],"ltp":5.1,"tv":4.54,"id":16574983}]}]}
{"op":"mcm","clk":"1009237144","pt":1580642939413,"mc":[{"id":"1.168217555","rc":[{"batb":[[1,4.9,36.05],[2,4.8,35]],"ltp":0.0,"tv":0.0,"id":12984951},{"batb":[[0,6.4,49.33],[1,6.2,39.49],[2,5.8,19.04]],"ltp":5.2,"tv":21.28,"id":16574984},{"batb":[[0,15.5,20.04],[1,15,14.82],[2,9.8,14.56]],"ltp":5.1,"tv":4.54,"id":16574983}]}]}
{"op":"mcm","clk":"1009237298","pt":1580642940422,"mc":[{"id":"1.168217555","rc":[{"trd":[[5.2,21.28]],"batb":[[0,5.2,1.31],[1,5.1,12.98],[2,4.9,36.05]],"batl":[[0,5.7,8.4],[1,6.2,11.33]],"ltp":5.2,"tv":21.28,"id":12984951},{"batb":[[2,1.6,99.95]],"batl":[[0,1.67,29.58],[1,1.74,42.01],[2,1.75,25.34]],"ltp":0.0,"tv":0.0,"id":12984952},{"batb":[[1,6.2,47.05],[2,5.9,18.33]],"batl":[[0,7.2,15.58],[1,7.8,5.88]],"ltp":5.2,"tv":21.28,"id":16574984},{"batb":[[2,14,6.14]],"batl":[[1,23,4.48]],"ltp":5.1,"tv":4.54,"id":16574983}],"tv":47.11}]}
{"op":"mcm","clk":"1009238985","pt":1580642950430,"mc":[{"id":"1.168217555","rc":[{"batb":[[0,5.1,12.98],[1,4.8,35],[2,4.7,10.92]],"ltp":5.2,"tv":21.28,"id":12984951},{"batb":[[0,1.6,69.74],[1,1.58,31.87],[2,1.01,0.51]],"batl":[[0,1.74,42.01],[1,1.75,25.34],[2,1.75,0]],"ltp":0.0,"tv":0.0,"id":12984952},{"batb":[[0,6.4,16.66]],"ltp":5.2,"tv":21.28,"id":16574984},{"batb":[[0,13,3.36],[1,11.5,9.52],[2,1.01,0.51]],"batl":[[0,23,4.48],[1,23,0]],"ltp":5.1,"tv":4.54,"id":16574983}]}]}
{"op":"mcm","clk":"1009239051","pt":1580642950758,"mc":[{"id":"1.168217555","rc":[{"batb":[[2,1.01,0.51]],"batl":[[0,6.2,11.33],[1,6.2,0]],"ltp":5.2,"tv":21.28,"id":12984951},{"batb":[[0,1.58,31.87],[1,1.01,0.51],[2,1.01,0]],"batl":[[0,1.75,25.34],[1,1.75,0]],"ltp":0.0,"tv":0.0,"id":12984952},{"batb":[[1,6.2,39.49]],"batl":[[1,7.8,0]],"ltp":5.2,"tv":21.28,"id":16574984},{"batb":[[0,11.5,9.52],[1,1.01,0.51],[2,1.01,0]],"ltp":5.1,"tv":4.54,"id":16574983}]}]}
{"op":"mcm","clk":"1009239437","pt":1580642953438,"mc":[{"id":"1.168217555","rc":[{"batb":[[0,5,13.45],[2,4.7,36.7]],"batl":[[0,5.9,11.72]],"ltp":5.2,"tv":21.28,"id":12984951},{"batb":[[0,1.62,82.75],[1,1.61,69.07],[2,1.59,31.47]],"batl":[[0,1.76,25.1]],"ltp":0.0,"tv":0.0,"id":12984952},{"batb":[[2,5.9,18.18]],"batl":[[0,7.4,15.5]],"ltp":5.2,"tv":21.28,"id":16574984},{"batb":[[0,13,25.09],[1,12.5,21.5],[2,11.5,9.52]],"ltp":5.1,"tv":4.54,"id":16574983}]}]}
{"op":"mcm","clk":"1009239718","pt":1580642955352,"mc":[{"id":"1.168217555","rc":[{"batb":[[0,1.59,31.47],[1,1.01,0.51],[2,1.59,0]],"ltp":0.0,"tv":0.0,"id":12984952}]}]}
{"op":"mcm","clk":"1009240256","pt":1580642958332,"mc":[{"id":"1.168217555","rc":[{"batb":[[1,4.8,49.63],[2,4.7,47.62]],"batl":[[0,5.7,21.31],[1,5.8,12.43]],"ltp":5.2,"tv":21.28,"id":12984951},{"batb":[[0,1.7,77.07],[1,1.69,25.57],[2,1.68,117.79]],"batl":[[1,1.79,42.01],[2,1.88,20.22]],"ltp":0.0,"tv":0.0,"id":12984952},{"batb":[[2,6,8.4]],"batl":[[0,7,16.6],[1,7.6,5.88]],"ltp":5.2,"tv":21.28,"id":16574984},{"batb":[[2,11.5,12.88]],"batl":[[0,16,8.73],[1,19.5,6.06]],"ltp":5.1,"tv":4.54,"id":16574983}]}]}
{"op":"mcm","clk":"1009242603","pt":1580642973399,"mc":[{"id":"1.168217555","rc":[{"batb":[[1,4.8,14.63],[2,4.7,10.92]],"ltp":5.2,"tv":21.28,"id":12984951},{"batb":[[0,1.69,25.57],[1,1.65,63.85],[2,1.64,28.33]],"ltp":0.0,"tv":0.0,"id":12984952},{"batb":[[0,6.2,22.29],[1,6,8.4],[2,5.9,18.18]],"ltp":5.2,"tv":21.28,"id":16574984},{"batb":[[0,11.5,12.88],[1,9,7],[2,1.01,0.51]],"ltp":5.1,"tv":4.54,"id":16574983}]}]}
{"op":"mcm","clk":"1009242669","pt":1580642973773,"mc":[{"id":"1.168217555","rc":[{"batb":[[0,4.8,14.63],[1,4.7,10.92],[2,1.01,0.51]],"batl":[[0,5.7,8.4]],"ltp":5.2,"tv":21.28,"id":12984951},{"batb":[[0,1.65,63.85],[1,1.64,28.33],[2,1.01,0.51]],"batl":[[0,1.79,42.01],[1,1.88,20.22],[2,1.88,0]],"ltp":0.0,"tv":0.0,"id":12984952},{"batb":[[2,5.7,19.67]],"ltp":5.2,"tv":21.28,"id":16574984},{"batb":[[0,11.5,3.36]],"batl":[[0,19.5,6.06],[1,19.5,0]],"ltp":5.1,"tv":4.54,"id":16574983}]}]}
{"op":"mcm","clk":"1009242820","pt":1580642974862,"mc":[{"id":"1.168217555","rc":[{"batb":[[1,1.01,0.51],[2,1.01,0]],"batl":[[0,5.8,12.43],[1,5.8,0]],"ltp":5.2,"tv":21.28,"id":12984951},{"batb":[[0,1.64,28.33],[1,1.01,0.51],[2,1.01,0]],"batl":[[0,1.88,20.22],[1,1.88,0]],"ltp":0.0,"tv":0.0,"id":12984952},{"batb":[[1,5.7,19.67],[2,1.01,0.51]],"batl":[[1,7.6,0]],"ltp":5.2,"tv":21.28,"id":16574984},{"batb":[[0,9,7],[1,1.01,0.51],[2,1.01,0]],"ltp":5.1,"tv":4.54,"id":16574983}]}]}
{"op":"mcm","clk":"1009243029","pt":1580642976288,"mc":[{"id":"1.168217555","rc":[{"batb":[[1,6,42.73],[2,5.7,19.67]],"ltp":5.2,"tv":21.28,"id":16574984}]}]}
{"op":"mcm","clk":"1009243315","pt":1580642978317,"mc":[{"id":"1.168217555","rc":[{"batb":[[0,4.8,41.44],[1,4.7,36.87],[2,1.01,0.51]],"ltp":5.2,"tv":21.28,"id":12984951},{"batb":[[0,1.72,69.25],[1,1.7,112.99],[2,1.64,28.33]],"ltp":0.0,"tv":0.0,"id":12984952},{"batb":[[0,6.2,50.19]],"ltp":5.2,"tv":21.28,"id":16574984},{"batb":[[0,12.5,15.16],[1,12,23.81],[2,9,7]],"ltp":5.1,"tv":4.54,"id":16574983}]}]}
{"op":"mcm","clk":"1009243948","pt":1580642982274,"mc":[{"id":"1.168217555","rc":[{"batb":[[0,4.8,14.63],[1,1.01,0.51],[2,1.01,0]],"ltp":5.2,"tv":21.28,"id":12984951},{"batb":[[0,1.64,28.33],[1,1.01,0.51],[2,1.64,0]],"ltp":0.0,"tv":0.0,"id":12984952},{"batb":[[0,6.2,22.29]],"ltp":5.2,"tv":21.28,"id":16574984},{"batb":[[0,9,7],[1,1.01,0.51],[2,9,0]],"ltp":5.1,"tv":4.54,"id":16574983}]}]}
{"op":"mcm","clk":"1009244437","pt":1580642985490,"mc":[{"id":"1.168217555","rc":[{"batb":[[1,4.6,60.76],[2,4.5,40.17]],"ltp":5.2,"tv":21.28,"id":12984951},{"batb":[[0,1.65,105.98],[1,1.64,92.98],[2,1.01,0.51]],"ltp":0.0,"tv":0.0,"id":12984952},{"batb":[[0,10,31.49],[1,9.8,14.67],[2,9,7]],"ltp":5.1,"tv":4.54,"id":16574983}]}]}
{"op":"mcm","clk":"1009245090","pt":1580642989495,"mc":[{"id":"1.168217555","rc":[{"batb":[[0,1.64,28.33],[1,1.01,0.51],[2,1.01,0]],"ltp":0.0,"tv":0.0,"id":12984952}]}]}
{"op":"mcm","clk":"1009245515","pt":1580642992279,"mc":[{"id":"1.168217555","rc":[{"batb":[[0,1.8,65.28],[1,1.78,96.67],[2,1.64,28.33]],"ltp":0.0,"tv":0.0,"id":12984952}]}]}
{"op":"mcm","clk":"1009245612","pt":1580642992962,"mc":[{"id":"1.168217555","rc":[{"batb":[[2,4.5,56.77]],"batl":[[0,5.5,14.01],[1,5.6,13.06]],"ltp":5.2,"tv":21.28,"id":12984951},{"batb":[[0,1.8,85.82],[2,1.7,24.78]],"batl":[[1,2.12,28.4]],"ltp":0.0,"tv":0.0,"id":12984952},{"batl":[[0,6.8,17.78]],"ltp":5.2,"tv":21.28,"id":16574984},{"batl":[[0,11.5,15.74],[1,15.5,9.05]],"ltp":5.1,"tv":4.54,"id":16574983}]}]}
{"op":"mcm","clk":"1009245836","pt":1580642994508,"mc":[{"id":"1.168217555","rc":[{"batb":[[2,4.5,68.53]],"batl":[[0,5.5,23.25]],"ltp":5.2,"tv":21.28,"id":12984951},{"batb":[[2,1.73,57.13]],"batl":[[1,1.9,42.01],[2,2.12,28.4]],"ltp":0.0,"tv":0.0,"id":12984952},{"batb":[[2,5.9,8.4]],"batl":[[1,7.2,6.72]],"ltp":5.2,"tv":21.28,"id":16574984},{"batb":[[2,9.4,4.2]],"batl":[[1,12,3.36],[2,15.5,9.05]],"ltp":5.1,"tv":4.54,"id":16574983}]}]}
{"op":"mcm","clk":"1009248258","pt":1580643009613,"mc":[{"id":"1.168217555","rc":[{"batb":[[0,4.5,28.36],[1,1.01,0.51],[2,4.5,0]],"batl":[[0,5.5,9.24]],"ltp":5.2,"tv":21.28,"id":12984951},{"batb":[[0,1.73,57.13],[1,1.7,24.78],[2,1.01,0.51]],"batl":[[0,1.9,42.01],[1,2.12,28.4],[2,2.12,0]],"ltp":0.0,"tv":0.0,"id":12984952},{"batb":[[0,6,26.12],[1,5.9,8.4],[2,5.6,20.38]],"ltp":5.2,"tv":21.28,"id":16574984},{"batb":[[0,9.4,4.2],[1,6.4,15.26],[2,1.01,0.51]],"batl":[[0,12,3.36],[1,15.5,9.05],[2,15.5,0]],"ltp":5.1,"tv":4.54,"id":16574983}]}]}
{"op":"mcm","clk":"1009248459","pt":1580643010835,"mc":[{"id":"1.168217555","rc":[{"batb":[[0,4.5,16.6]],"batl":[[0,5.6,13.06],[1,5.6,0]],"ltp":5.2,"tv":21.28,"id":12984951},{"batb":[[0,1.7,24.78],[1,1.01,0.51],[2,1.01,0]],"batl":[[0,2.12,28.4],[1,2.12,0]],"ltp":0.0,"tv":0.0,"id":12984952},{"batb":[[1,5.6,20.38],[2,1.01,0.51]],"batl":[[1,7.2,0]],"ltp":5.2,"tv":21.28,"id":16574984},{"batb":[[0,6.4,15.26],[1,1.01,0.51],[2,1.01,0]],"batl":[[0,15.5,9.05],[1,15.5,0]],"ltp":5.1,"tv":4.54,"id":16574983}]}]}
{"op":"mcm","clk":"1009248729","pt":1580643012623,"mc":[{"id":"1.168217555","rc":[{"batb":[[1,4.4,52.27],[2,4.3,44.82]],"ltp":5.2,"tv":21.28,"id":12984951},{"batb":[[0,1.7,137.87],[1,1.68,117.95],[2,1.01,0.51]],"ltp":0.0,"tv":0.0,"id":12984952},{"batb":[[1,5.9,22.5],[2,5.6,20.38]],"ltp":5.2,"tv":21.28,"id":16574984},{"batb":[[0,7,34.13],[1,6.8,32.26],[2,6.4,15.26]],"ltp":5.1,"tv":4.54,"id":16574983}]}]}
{"op":"mcm","clk":"1009248860","pt":1580643013548,"mc":[{"id":"1.168217555","rc":[{"batb":[[1,1.01,0.51],[2,4.3,0]],"ltp":5.2,"tv":21.28,"id":12984951},{"batb":[[1,5.6,20.38],[2,1.01,0.51]],"ltp":5.2,"tv":21.28,"id":16574984},{"batb":[[0,6.4,15.26],[1,1.01,0.51],[2,6.4,0]],"ltp":5.1,"tv":4.54,"id":16574983}]}]}
{"op":"mcm","clk":"1009249525","pt":1580643017517,"mc":[{"id":"1.168217555","rc":[{"batb":[[0,5,13.61],[1,4.8,47.27],[2,4.7,36.78]],"batl":[[1,5.8,12.51]],"ltp":5.2,"tv":21.28,"id":12984951},{"batb":[[2,1.65,27.77]],"batl":[[0,1.77,24.31],[1,1.91,19.28]],"ltp":0.0,"tv":0.0,"id":12984952},{"batb":[[0,6.2,42.95],[1,6,42.16],[2,5.6,20.22]],"batl":[[1,7,17.39]],"ltp":5.2,"tv":21.28,"id":16574984},{"batb":[[0,13,26.05],[1,12.5,21.46],[2,11.5,9.76]],"batl":[[1,19.5,5.9]],"ltp":5.1,"tv":4.54,"id":16574983}]}]}
{"op":"mcm","clk":"1009249556","pt":1580643017733,"mc":[{"id":"1.168217555","rc":[{"batl":[[0,5.6,21.46]],"ltp":5.2,"tv":21.28,"id":12984951},{"batb":[[2,1.65,91.63]],"batl":[[1,1.82,42.01],[2,1.91,19.28]],"ltp":0.0,"tv":0.0,"id":12984952},{"batb":[[1,6,50.56]],"batl":[[2,7.4,5.88]],"ltp":5.2,"tv":21.28,"id":16574984},{"batb":[[2,11.5,13.12]],"ltp":5.1,"tv":4.54,"id":16574983}]}]}
{"op":"mcm","clk":"1009250981","pt":1580643026343,"mc":[{"id":"1.168217555","rc":[{"batb":[[0,4.8,14.79],[1,4.6,10.92],[2,1.01,0.51]],"batl":[[0,5.6,8.4]],"ltp":5.2,"tv":21.28,"id":12984951},{"batb":[[0,1.65,91.63],[1,1.01,0.51],[2,1.65,0]],"batl":[[0,1.82,42.01],[1,1.91,19.28],[2,1.91,0]],"ltp":0.0,"tv":0.0,"id":12984952},{"batb":[[0,6,50.56],[1,5.6,20.22],[2,1.01,0.51]],"batl":[[0,7,17.39],[1,7.4,5.88],[2,7.4,0]],"ltp":5.2,"tv":21.28,"id":16574984},{"batb":[[0,11.5,3.36],[1,8.8,7.55],[2,1.01,0.51]],"batl":[[0,19.5,5.9],[1,19.5,0]],"ltp":5.1,"tv":4.54,"id":16574983}]}]}
{"op":"mcm","clk":"1009251050","pt":1580643026759,"mc":[{"id":"1.168217555","rc":[{"batb":[[1,1.01,0.51],[2,1.01,0]],"batl":[[0,5.8,12.51],[1,5.8,0]],"ltp":5.2,"tv":21.28,"id":12984951},{"batb":[[0,1.65,27.77]],"batl":[[0,1.91,19.28],[1,1.91,0]],"ltp":0.0,"tv":0.0,"id":12984952},{"batb":[[0,6,42.16]],"batl":[[1,7.4,0]],"ltp":5.2,"tv":21.28,"id":16574984},{"batb":[[0,8.8,7.55],[1,1.01,0.51],[2,1.01,0]],"ltp":5.1,"tv":4.54,"id":16574983}]}]}
{"op":"mcm","clk":"1009251443","pt":1580643029051,"mc":[{"id":"1.168217555","rc":[{"batb":[[1,4.6,52.17],[2,4.5,40.32]],"ltp":5.2,"tv":21.28,"id":12984951},{"batb":[[0,1.65,135.83],[1,1.64,64.65],[2,1.01,0.51]],"ltp":0.0,"tv":0.0,"id":12984952},{"batb":[[0,6,51.88],[1,5.9,22.14],[2,5.6,20.22]],"ltp":5.2,"tv":21.28,"id":16574984},{"batb":[[0,9.8,23.83],[1,9.6,15.48],[2,8.8,7.55]],"ltp":5.1,"tv":4.54,"id":16574983}]}]}
{"op":"mcm","clk":"1009251978","pt":1580643032159,"mc":[{"id":"1.168217555","rc":[{"batb":[[1,1.01,0.51],[2,4.5,0]],"ltp":5.2,"tv":21.28,"id":12984951},{"batb":[[0,5.6,20.22],[1,1.01,0.51],[2,5.6,0]],"ltp":5.2,"tv":21.28,"id":16574984},{"batb":[[0,8.8,7.55],[1,1.01,0.51],[2,8.8,0]],"ltp":5.1,"tv":4.54,"id":16574983}]}]}
{"op":"mcm","clk":"1009252437","pt":1580643034963,"mc":[{"id":"1.168217555","rc":[{"batb":[[0,4.9,26.07],[1,4.8,49.94],[2,1.01,0.51]],"ltp":5.2,"tv":21.28,"id":12984951},{"batb":[[0,6.4,20.18],[1,6.2,39.82],[2,5.6,20.22]],"ltp":5.2,"tv":21.28,"id":16574984},{"batb":[[0,16,16.59],[1,15.5,13.94],[2,8.8,7.55]],"ltp":5.1,"tv":4.54,"id":16574983}]}]}
{"op":"mcm","clk":"1009252602","pt":1580643035970,"mc":[{"id":"1.168217555","rc":[{"batb":[[0,5.1,12.98],[1,4.9,39.68],[2,4.8,35.15]],"batl":[[0,5.8,20.91],[1,5.9,11.72]],"ltp":5.2,"tv":21.28,"id":12984951},{"batb":[[2,1.6,69.74]],"batl":[[0,1.72,27.22],[1,1.74,42.01],[2,1.76,24.94]],"ltp":0.0,"tv":0.0,"id":12984952},{"batb":[[1,6.2,47.38],[2,5.8,18.57]],"batl":[[1,7.2,15.97],[2,7.6,5.88]],"ltp":5.2,"tv":21.28,"id":16574984},{"batb":[[2,14,6.29]],"batl":[[1,26,7.47]],"ltp":5.1,"tv":4.54,"id":16574983}]}]}
{"op":"mcm","clk":"1009254978","pt":1580643050390,"mc":[{"id":"1.168217555","rc":[{"batb":[[0,16,13.45],[1,14,6.29],[2,13.5,3.36]],"ltp":5.1,"tv":4.54,"id":16574983}]}]}
{"op":"mcm","clk":"1009255414","pt":1580643053067,"mc":[{"id":"1.168217555","rc":[{"batb":[[0,6.4,29.25]],"ltp":5.2,"tv":21.28,"id":16574984},{"batb":[[0,16.5,6.23],[1,16,13.45],[2,14,6.29]],"ltp":5.1,"tv":4.54,"id":16574983}]}]}
{"op":"mcm","clk":"1009255825","pt":1580643055455,"mc":[{"id":"1.168217555","rc":[{"batb":[[0,4.9,13.61],[1,4.8,35.15],[2,4.7,10.92]],"batl":[[0,5.8,8.4]],"ltp":5.2,"tv":21.28,"id":12984951},{"batb":[[0,1.6,69.74],[1,1.59,31.79],[2,1.01,0.51]],"batl":[[0,1.74,42.01],[1,1.76,24.94],[2,1.76,0]],"ltp":0.0,"tv":0.0,"id":12984952},{"batb":[[0,6.2,47.38],[1,5.7,19.43],[2,1.01,0.51]],"batl":[[0,7.2,15.97],[1,7.6,5.88],[2,7.6,0]],"ltp":5.2,"tv":21.28,"id":16574984},{"batb":[[0,13.5,3.36],[1,12.5,8.18],[2,1.01,0.51]],"batl":[[0,26,7.47],[1,26,0]],"ltp":5.1,"tv":4.54,"id":16574983}]}]}
{"op":"mcm","clk":"1009256027","pt":1580643056800,"mc":[{"id":"1.168217555","rc":[{"batb":[[2,1.01,0.51]],"batl":[[0,5.9,11.72],[1,5.9,0]],"ltp":5.2,"tv":21.28,"id":12984951},{"batb":[[0,1.59,31.79],[1,1.01,0.51],[2,1.01,0]],"batl":[[0,1.76,24.94],[1,1.76,0]],"ltp":0.0,"tv":0.0,"id":12984952},{"batb":[[0,6.2,39.82]],"batl":[[1,7.6,0]],"ltp":5.2,"tv":21.28,"id":16574984},{"batb":[[0,12.5,8.18],[1,1.01,0.51],[2,1.01,0]],"ltp":5.1,"tv":4.54,"id":16574983}]}]}
{"op":"mcm","clk":"1009256277","pt":1580643058365,"mc":[{"id":"1.168217555","rc":[{"batb":[[2,4.7,36.72]],"ltp":5.2,"tv":21.28,"id":12984951},{"batb":[[0,1.6,72.04],[1,1.59,104.16],[2,1.01,0.51]],"ltp":0.0,"tv":0.0,"id":12984952},{"batb":[[0,6.2,47.33],[1,6,42.3],[2,5.7,19.43]],"ltp":5.2,"tv":21.28,"id":16574984},{"batb":[[0,14.5,12.74],[1,14,17.48],[2,12.5,8.18]],"ltp":5.1,"tv":4.54,"id":16574983}]}]}
{"op":"mcm","clk":"1009256591","pt":1580643060198,"mc":[{"id":"1.168217555","rc":[{"batb":[[0,1.59,31.79],[1,1.01,0.51],[2,1.01,0]],"ltp":0.0,"tv":0.0,"id":12984952}]}]}
{"op":"mcm","clk":"1009257058","pt":1580643063203,"mc":[{"id":"1.168217555","rc":[{"batb":[[0,1.69,64.06],[1,1.67,120.31],[2,1.59,31.79]],"ltp":0.0,"tv":0.0,"id":12984952}]}]}
{"op":"mcm","clk":"1009257220","pt":1580643064208,"mc":[{"id":"1.168217555","rc":[{"batb":[[2,4.7,47.64]],"batl":[[0,5.6,13.06],[1,5.7,8.4],[2,5.8,12.35]],"ltp":5.2,"tv":21.28,"id":12984951},{"batb":[[0,1.69,89.47],[2,1.64,65.54]],"batl":[[1,1.78,42.01],[2,1.8,23.13]],"ltp":0.0,"tv":0.0,"id":12984952},{"batb":[[1,6,50.7]],"batl":[[0,6.8,18.1],[1,7,16.68],[2,7.4,5.88]],"ltp":5.2,"tv":21.28,"id":16574984},{"batb":[[2,12.5,11.54]],"batl":[[0,17,7.63],[1,21,5.43]],"ltp":5.1,"tv":4.54,"id":16574983}]}]}
{"op":"mcm","clk":"1009258026","pt":1580643069309,"mc":[{"id":"1.168217555","rc":[{"batb":[[1,4.7,47.64],[2,1.01,0.51]],"ltp":5.2,"tv":21.28,"id":12984951},{"batb":[[0,1.69,25.41],[1,1.64,65.54],[2,1.63,28.88]],"ltp":0.0,"tv":0.0,"id":12984952},{"batb":[[0,6.2,26.03]],"ltp":5.2,"tv":21.28,"id":16574984},{"batb":[[0,12.5,11.54],[1,11.5,9.99],[2,1.01,0.51]],"ltp":5.1,"tv":4.54,"id":16574983}]}]}
{"op":"mcm","clk":"1009258176","pt":1580643070291,"mc":[{"id":"1.168217555","rc":[{"batl":[[0,5.7,8.4],[1,5.8,12.35],[2,5.8,0]],"ltp":5.2,"tv":21.28,"id":12984951},{"batb":[[0,1.64,65.54],[1,1.63,28.88],[2,1.01,0.51]],"batl":[[0,1.78,42.01],[1,1.8,23.13],[2,1.8,0]],"ltp":0.0,"tv":0.0,"id":12984952},{"batl":[[0,7,16.68],[1,7.4,5.88],[2,7.4,0]],"ltp":5.2,"tv":21.28,"id":16574984},{"batb":[[0,12.5,3.36]],"batl":[[0,21,5.43],[1,21,0]],"ltp":5.1,"tv":4.54,"id":16574983}]}]}
{"op":"mcm","clk":"1009258277","pt":1580643070890,"mc":[{"id":"1.168217555","rc":[{"batb":[[1,4.7,36.72]],"batl":[[0,5.8,12.35],[1,5.8,0]],"ltp":5.2,"tv":21.28,"id":12984951},{"batb":[[0,1.63,28.88],[1,1.01,0.51],[2,1.01,0]],"batl":[[0,1.8,23.13],[1,1.8,0]],"ltp":0.0,"tv":0.0,"id":12984952},{"batb":[[1,6,42.3]],"batl":[[1,7.4,0]],"ltp":5.2,"tv":21.28,"id":16574984},{"batb":[[0,11.5,9.99],[1,1.01,0.51],[2,1.01,0]],"ltp":5.1,"tv":4.54,"id":16574983}]}]}
{"op":"mcm","clk":"1009258988","pt":1580643075484,"mc":[{"id":"1.168217555","rc":[{"batb":[[1,4.8,39.73],[2,4.7,36.72]],"ltp":5.2,"tv":21.28,"id":12984951},{"batb":[[0,1.68,64.51],[1,1.66,122.9],[2,1.63,28.88]],"ltp":0.0,"tv":0.0,"id":12984952},{"batb":[[0,6.2,54.03]],"ltp":5.2,"tv":21.28,"id":16574984},{"batb":[[0,15,10.21],[1,14.5,16.34],[2,11.5,9.99]],"ltp":5.1,"tv":4.54,"id":16574983}]}]}
{"op":"mcm","clk":"1009259668","pt":1580643080084,"mc":[{"id":"1.168217555","rc":[{"batb":[[1,4.7,36.72],[2,1.01,0.51]],"ltp":5.2,"tv":21.28,"id":12984951},{"batb":[[0,1.63,28.88],[1,1.01,0.51],[2,1.63,0]],"ltp":0.0,"tv":0.0,"id":12984952},{"batb":[[0,6.2,26.03]],"ltp":5.2,"tv":21.28,"id":16574984},{"batb":[[0,11.5,9.99],[1,1.01,0.51],[2,11.5,0]],"ltp":5.1,"tv":4.54,"id":16574983}]}]}
{"op":"mcm","clk":"1009260221","pt":1580643083505,"mc":[{"id":"1.168217555","rc":[{"batb":[[1,1.01,0.51],[2,1.01,0]],"ltp":5.2,"tv":21.28,"id":12984951},{"batb":[[0,1.64,73.57],[1,1.63,94.92],[2,1.01,0.51]],"ltp":0.0,"tv":0.0,"id":12984952},{"batb":[[1,5.7,19.43],[2,1.01,0.51]],"ltp":5.2,"tv":21.28,"id":16574984}]}]}
{"op":"mcm","clk":"1009260703","pt":1580643086502,"mc":[{"id":"1.168217555","rc":[{"batb":[[0,5.1,12.83],[1,5,13.53],[2,4.9,45.5]],"batl":[[1,6,11.25]],"ltp":5.2,"tv":21.28,"id":12984951},{"batb":[[2,1.57,33.6]],"batl":[[0,1.7,28.25],[1,1.75,25.41],[2,1.8,23.13]],"ltp":0.0,"tv":0.0,"id":12984952},{"batb":[[0,6.4,39.95],[1,6.2,39.53],[2,5.8,18.96]],"batl":[[1,7.2,15.74]],"ltp":5.2,"tv":21.28,"id":16574984},{"batb":[[0,17,9.99],[1,16.5,12.52],[2,14.5,5.74]],"batl":[[1,29,6.06]],"ltp":5.1,"tv":4.54,"id":16574983}]}]}
{"op":"mcm","clk":"1009260741","pt":1580643086723,"mc":[{"id":"1.168217555","rc":[{"batb":[[2,4.9,31.89]],"ltp":5.2,"tv":21.28,"id":12984951},{"batl":[[2,1.8,0]],"ltp":0.0,"tv":0.0,"id":12984952}]}]}
{"op":"mcm","clk":"1009260936","pt":1580643087802,"mc":[{"id":"1.168217555","rc":[{"batl":[[0,5.8,20.76]],"ltp":5.2,"tv":21.28,"id":12984951},{"batb":[[2,1.59,70.58]],"batl":[[1,1.73,42.01],[2,1.75,25.41]],"ltp":0.0,"tv":0.0,"id":12984952},{"batb":[[1,6.2,47.09]],"batl":[[2,7.8,5.88]],"ltp":5.2,"tv":21.28,"id":16574984}]}]}
{"op":"mcm","clk":"1009263870","pt":1580643107328,"mc":[{"id":"1.168217555","rc":[{"batb":[[0,5,13.53],[1,4.8,35],[2,1.01,0.51]],"batl":[[0,6,11.25],[1,6,0]],"ltp":5.2,"tv":21.28,"id":12984951},{"batb":[[0,1.57,33.6],[1,1.01,0.51],[2,1.59,0]],"batl":[[0,1.75,25.41],[1,1.73,0],[2,1.75,0]],"ltp":0.0,"tv":0.0,"id":12984952},{"batb":[[0,6.4,16.21],[1,6.2,39.53]],"batl":[[0,7.2,15.74],[1,7.2,0],[2,7.8,0]],"ltp":5.2,"tv":21.28,"id":16574984},{"batb":[[0,12.5,7.87],[1,1.01,0.51],[2,14.5,0]],"batl":[[0,29,6.06],[1,29,0]],"ltp":5.1,"tv":4.54,"id":16574983}]}]}
{"op":"mcm","clk":"1009264212","pt":1580643109570,"mc":[{"id":"1.168217555","rc":[{"batb":[[2,4.7,36.63]],"ltp":5.2,"tv":21.28,"id":12984951},{"batb":[[0,1.58,79.34],[1,1.57,109.53],[2,1.01,0.51]],"ltp":0.0,"tv":0.0,"id":12984952},{"batb":[[0,14.5,18.5],[1,14,17.29],[2,12.5,7.87]],"ltp":5.1,"tv":4.54,"id":16574983}]}]}
{"op":"mcm","clk":"1009265038","pt":1580643115293,"mc":[{"id":"1.168217555","rc":[{"batb":[[1,1.01,0.51],[2,4.7,0]],"ltp":5.2,"tv":21.28,"id":12984951},{"batb":[[1,5.8,18.96],[2,1.01,0.51]],"ltp":5.2,"tv":21.28,"id":16574984},{"batb":[[0,12.5,7.87],[1,1.01,0.51],[2,12.5,0]],"ltp":5.1,"tv":4.54,"id":16574983}]}]}
{"op":"mcm","clk":"1009265358","pt":1580643117429,"mc":[{"id":"1.168217555","rc":[{"batb":[[1,1.57,75.93]],"ltp":0.0,"tv":0.0,"id":12984952}]}]}
{"op":"mcm","clk":"1009265474","pt":1580643118029,"mc":[{"id":"1.168217555","rc":[{"batb":[[0,5,56.28],[1,4.9,33.22],[2,1.01,0.51]],"ltp":5.2,"tv":21.28,"id":12984951},{"batb":[[0,6.6,37.87],[1,6.4,36.92],[2,5.8,18.96]],"ltp":5.2,"tv":21.28,"id":16574984},{"batb":[[0,22,12.72],[1,21,14.75],[2,12.5,7.87]],"ltp":5.1,"tv":4.54,"id":16574983}]}]}
{"op":"mcm","clk":"1009265674","pt":1580643119305,"mc":[{"id":"1.168217555","rc":[{"batb":[[0,5.1,12.59],[1,5,42.75],[2,4.9,33.22]],"batl":[[0,6.4,10.39]],"ltp":5.2,"tv":21.28,"id":12984951},{"batb":[[2,1.49,40.05]],"batl":[[0,1.68,29.03]],"ltp":0.0,"tv":0.0,"id":12984952},{"batb":[[2,6,17.47]],"batl":[[0,7.6,14.4]],"ltp":5.2,"tv":21.28,"id":16574984},{"batb":[[2,15,5.43]],"ltp":5.1,"tv":4.54,"id":16574983}]}]}
{"op":"mcm","clk":"1009265793","pt":1580643120157,"mc":[{"id":"1.168217555","rc":[{"batb":[[2,4.9,43.3]],"batl":[[0,5.9,8.4],[1,6.4,10.39]],"ltp":5.2,"tv":21.28,"id":12984951},{"batb":[[2,1.54,77.3]],"batl":[[0,1.67,42.01],[1,1.68,29.03]],"ltp":0.0,"tv":0.0,"id":12984952},{"batb":[[1,6.4,44.48]],"batl":[[1,8,5.88]],"ltp":5.2,"tv":21.28,"id":16574984}]}]}
{"op":"mcm","clk":"1009267752","pt":1580643134060,"mc":[{"id":"1.168217555","rc":[{"batb":[[1,4.9,43.3],[2,1.01,0.51]],"ltp":5.2,"tv":21.28,"id":12984951},{"batb":[[0,1.54,77.3],[1,1.49,40.05],[2,1.01,0.51]],"ltp":0.0,"tv":0.0,"id":12984952},{"batb":[[0,6.4,44.48],[1,6,17.47],[2,1.01,0.51]],"ltp":5.2,"tv":21.28,"id":16574984},{"batb":[[0,15,5.43],[1,1.01,0.51],[2,15,0]],"ltp":5.1,"tv":4.54,"id":16574983}]}]}
{"op":"mcm","clk":"1009267859","pt":1580643134973,"mc":[{"id":"1.168217555","rc":[{"batb":[[1,4.9,33.22]],"batl":[[0,6.4,10.39],[1,6.4,0]],"ltp":5.2,"tv":21.28,"id":12984951},{"batb":[[0,1.49,40.05],[1,1.01,0.51],[2,1.01,0]],"batl":[[0,1.68,29.03],[1,1.68,0]],"ltp":0.0,"tv":0.0,"id":12984952},{"batb":[[0,6.4,36.92]],"batl":[[1,8,0]],"ltp":5.2,"tv":21.28,"id":16574984}]}]}
{"op":"mcm","clk":"1009268141","pt":1580643136990,"mc":[{"id":"1.168217555","rc":[{"batb":[[2,4.8,34.87]],"ltp":5.2,"tv":21.28,"id":12984951},{"batb":[[0,1.51,112.59],[1,1.5,90.98],[2,1.49,40.05]],"ltp":0.0,"tv":0.0,"id":12984952},{"batb":[[0,6.4,49.41],[1,6.2,39.28],[2,6,17.47]],"ltp":5.2,"tv":21.28,"id":16574984},{"batb":[[0,17.5,14],[1,17,11.66],[2,15,5.43]],"ltp":5.1,"tv":4.54,"id":16574983}]}]}
{"op":"mcm","clk":"1009268327","pt":1580643138260,"mc":[{"id":"1.168217555","rc":[{"batb":[[2,1.01,0.51]],"ltp":5.2,"tv":21.28,"id":12984951},{"batb":[[0,1.49,40.05],[1,1.01,0.51],[2,1.49,0]],"ltp":0.0,"tv":0.0,"id":12984952},{"batb":[[0,6.4,36.92],[1,6,17.47],[2,1.01,0.51]],"ltp":5.2,"tv":21.28,"id":16574984},{"batb":[[0,15,5.43],[1,1.01,0.51],[2,15,0]],"ltp":5.1,"tv":4.54,"id":16574983}]}]}
{"op":"mcm","clk":"1009268716","pt":1580643140759,"mc":[{"id":"1.168217555","rc":[{"batb":[[2,4.8,34.87]],"ltp":5.2,"tv":21.28,"id":12984951},{"batb":[[0,1.63,63.97],[1,1.62,67.51],[2,1.49,40.05]],"ltp":0.0,"tv":0.0,"id":12984952},{"batb":[[0,6.4,49.41],[1,6.2,39.28],[2,6,17.47]],"ltp":5.2,"tv":21.28,"id":16574984},{"batb":[[0,17.5,14],[1,17,11.66],[2,15,5.43]],"ltp":5.1,"tv":4.54,"id":16574983}]}]}
{"op":"mcm","clk":"1009268903","pt":1580643142104,"mc":[{"id":"1.168217555","rc":[{"batb":[[1,5,13.38],[2,4.9,33.22]],"batl":[[0,5.8,20.52],[1,6.2,11.09]],"ltp":5.2,"tv":21.28,"id":12984951},{"batb":[[1,1.62,97.17],[2,1.58,72.26]],"batl":[[1,1.74,25.73]],"ltp":0.0,"tv":0.0,"id":12984952},{"batb":[[1,6.2,46.84]],"batl":[[0,7.2,16.37],[1,7.4,15.26],[2,7.8,5.88]],"ltp":5.2,"tv":21.28,"id":16574984},{"batl":[[0,22,5.11]],"ltp":5.1,"tv":4.54,"id":16574983}]}]}
{"op":"mcm","clk":"1009269167","pt":1580643143753,"mc":[{"id":"1.168217555","rc":[{"batl":[[1,1.7,42.01],[2,1.74,25.73]],"ltp":0.0,"tv":0.0,"id":12984952}]}]}
{"op":"mcm","clk":"1009271536","pt":1580643158025,"mc":[{"id":"1.168217555","rc":[{"batb":[[0,5,13.38],[1,4.8,45.79],[2,1.01,0.51]],"batl":[[0,5.8,8.4]],"ltp":5.2,"tv":21.28,"id":12984951},{"batb":[[0,1.58,72.26],[1,1.54,35.64],[2,1.01,0.51]],"batl":[[0,1.7,42.01],[1,1.74,25.73],[2,1.74,0]],"ltp":0.0,"tv":0.0,"id":12984952},{"batb":[[0,6.4,23.84],[2,5.8,18.57]],"batl":[[0,7.4,15.26],[1,7.8,5.88],[2,7.8,0]],"ltp":5.2,"tv":21.28,"id":16574984},{"batb":[[0,12.5,7.95],[1,1.01,0.51],[2,15,0]],"ltp":5.1,"tv":4.54,"id":16574983}]}]}
{"op":"mcm","clk":"1009271667","pt":1580643158832,"mc":[{"id":"1.168217555","rc":[{"batb":[[1,4.8,34.87]],"batl":[[0,6.2,11.09],[1,6.2,0]],"ltp":5.2,"tv":21.28,"id":12984951},{"batb":[[0,1.54,35.64],[1,1.01,0.51],[2,1.01,0]],"batl":[[0,1.74,25.73],[1,1.74,0]],"ltp":0.0,"tv":0.0,"id":12984952},{"batb":[[1,6.2,39.28]],"batl":[[1,7.8,0]],"ltp":5.2,"tv":21.28,"id":16574984}]}]}
{"op":"mcm","clk":"1009271997","pt":1580643161657,"mc":[{"id":"1.168217555","rc":[{"batb":[[2,4.7,36.61]],"ltp":5.2,"tv":21.28,"id":12984951},{"batb":[[0,1.55,124.25],[1,1.54,117.64],[2,1.01,0.51]],"ltp":0.0,"tv":0.0,"id":12984952},{"batb":[[0,14.5,13.46],[1,14,17.46],[2,12.5,7.95]],"ltp":5.1,"tv":4.54,"id":16574983}]}]}
{"op":"mcm","clk":"1009273254","pt":1580643168341,"mc":[{"id":"1.168217555","rc":[{"batb":[[1,1.01,0.51],[2,4.7,0]],"ltp":5.2,"tv":21.28,"id":12984951},{"batb":[[1,5.8,18.57],[2,1.01,0.51]],"ltp":5.2,"tv":21.28,"id":16574984},{"batb":[[0,12.5,7.95],[1,1.01,0.51],[2,12.5,0]],"ltp":5.1,"tv":4.54,"id":16574983}]}]}
{"op":"mcm","clk":"1009273797","pt":1580643171513,"mc":[{"id":"1.168217555","rc":[{"batb":[[0,5.3,11.49],[1,5.2,12.35],[2,5.1,28.45]],"batl":[[1,6.6,19.36]],"ltp":5.2,"tv":21.28,"id":12984951},{"batb":[[2,1.45,45.56]],"batl":[[0,1.6,34.78],[1,1.68,29.51],[2,1.74,25.73]],"ltp":0.0,"tv":0.0,"id":12984952},{"batb":[[0,6.6,49.81],[1,6.4,36.6],[2,6.2,16.29]],"batl":[[1,7.8,13.85]],"ltp":5.2,"tv":21.28,"id":16574984},{"batb":[[0,26,10.02],[1,25,10.42],[2,21,4.48]],"ltp":5.1,"tv":4.54,"id":16574983}]}]}
{"op":"mcm","clk":"1009273947","pt":1580643172471,"mc":[{"id":"1.168217555","rc":[{"batl":[[0,6,8.4],[1,6.2,11.09],[2,6.6,19.36]],"ltp":5.2,"tv":21.28,"id":12984951},{"batb":[[2,1.52,80.66]],"batl":[[1,1.64,42.01],[2,1.68,29.51]],"ltp":0.0,"tv":0.0,"id":12984952},{"batb":[[1,6.4,44.16]],"batl":[[2,8,5.88]],"ltp":5.2,"tv":21.28,"id":16574984}]}]}
{"op":"mcm","clk":"1009274924","pt":1580643178704,"mc":[{"id":"1.168217555","rc":[{"batb":[[0,6.6,35.1],[1,6.4,7.56]],"ltp":5.2,"tv":21.28,"id":16574984}]}]}
{"op":"mcm","clk":"1009275343","pt":1580643181728,"mc":[{"id":"1.168217555","rc":[{"batb":[[0,6.8,18.02],[1,6.6,35.1],[2,6.4,7.56]],"ltp":5.2,"tv":21.28,"id":16574984}]}]}
{"op":"mcm","clk":"1009276594","pt":1580643190434,"mc":[{"id":"1.168217555","rc":[{"batb":[[0,5.2,12.35],[1,4.9,10.08],[2,1.01,0.51]],"batl":[[1,6.6,19.36],[2,6.6,0]],"ltp":5.2,"tv":21.28,"id":12984951},{"batb":[[0,1.52,80.66],[1,1.45,45.56],[2,1.01,0.51]],"batl":[[0,1.64,42.01],[1,1.68,29.51],[2,1.68,0]],"ltp":0.0,"tv":0.0,"id":12984952},{"batb":[[0,6.6,23.31],[1,6.4,7.56],[2,6,17.55]],"batl":[[0,7.8,13.85],[1,8,5.88],[2,8,0]],"ltp":5.2,"tv":21.28,"id":16574984},{"batb":[[0,15,5.11],[1,1.01,0.51],[2,21,0]],"ltp":5.1,"tv":4.54,"id":16574983}]}]}
{"op":"mcm","clk":"1009276693","pt":1580643191056,"mc":[{"id":"1.168217555","rc":[{"batb":[[1,1.01,0.51],[2,1.01,0]],"batl":[[0,6.6,19.36],[1,6.6,0]],"ltp":5.2,"tv":21.28,"id":12984951},{"batb":[[0,1.45,45.56],[1,1.01,0.51],[2,1.01,0]],"batl":[[0,1.68,29.51],[1,1.68,0]],"ltp":0.0,"tv":0.0,"id":12984952},{"batb":[[1,6,17.55],[2,1.01,0.51]],"batl":[[1,8,0]],"ltp":5.2,"tv":21.28,"id":16574984}]}]}
{"op":"mcm","clk":"1009277042","pt":1580643193342,"mc":[{"id":"1.168217555","rc":[{"batb":[[1,4.9,44.54],[2,4.8,34.78]],"ltp":5.2,"tv":21.28,"id":12984951},{"batb":[[0,1.46,142.59],[1,1.45,150.58],[2,1.01,0.51]],"ltp":0.0,"tv":0.0,"id":12984952},{"batb":[[1,6.4,37.4],[2,6,17.55]],"ltp":5.2,"tv":21.28,"id":16574984},{"batb":[[0,18,8.79],[1,17.5,11.15],[2,15,5.11]],"ltp":5.1,"tv":4.54,"id":16574983}]}]}
{"op":"mcm","clk":"1009277606","pt":1580643197073,"mc":[{"id":"1.168217555","rc":[{"batb":[[1,1.01,0.51],[2,4.8,0]],"ltp":5.2,"tv":21.28,"id":12984951},{"batb":[[0,6,17.55],[1,1.01,0.51],[2,6,0]],"ltp":5.2,"tv":21.28,"id":16574984},{"batb":[[0,15,5.11],[1,1.01,0.51],[2,15,0]],"ltp":5.1,"tv":4.54,"id":16574983}]}]}
{"op":"mcm","clk":"1009278164","pt":1580643200449,"mc":[{"id":"1.168217555","rc":[{"batb":[[0,5.6,10.39],[1,5.4,11.02],[2,5.3,39.3]],"batl":[[0,6.2,7.56],[1,6.6,19.36],[2,6.8,18.41]],"ltp":5.2,"tv":21.28,"id":12984951},{"batb":[[2,1.42,148.61]],"batl":[[0,1.5,44.3],[1,1.52,42.01],[2,1.55,38.95]],"ltp":0.0,"tv":0.0,"id":12984952},{"batb":[[0,7,36.03],[1,6.8,32.62],[2,6.4,14.71]],"batl":[[1,8.8,5.04]],"ltp":5.2,"tv":21.28,"id":16574984},{"batb":[[0,85,4.66],[1,80,3.47],[2,15,5.11]],"ltp":5.1,"tv":4.54,"id":16574983}]}]}
{"op":"mcm","clk":"1009278240","pt":1580643200954,"mc":[{"id":"1.168217555","rc":[{"batl":[[0,7.8,13.22]],"ltp":5.2,"tv":21.28,"id":16574984},{"batb":[[2,1.01,0.51]],"ltp":5.1,"tv":4.54,"id":16574983}]}]}
{"op":"mcm","clk":"1009289605","pt":1580643276044,"mc":[{"id":"1.168217555","rc":[{"batb":[[0,5.4,11.02],[1,5.2,29.05],[2,5.1,10.08]],"batl":[[1,6.8,18.41],[2,6.8,0]],"ltp":5.2,"tv":21.28,"id":12984951},{"batb":[[0,1.45,72.72],[1,1.42,148.61],[2,1.01,0.51]],"batl":[[0,1.52,42.01],[1,1.55,38.95],[2,1.55,0]],"ltp":0.0,"tv":0.0,"id":12984952},{"batb":[[0,7,6.72],[1,6.8,22.07],[2,6.2,16.52]],"ltp":5.2,"tv":21.28,"id":16574984},{"batb":[[0,1.01,0.51],[1,80,0],[2,1.01,0]],"ltp":5.1,"tv":4.54,"id":16574983}]}]}
{"op":"mcm","clk":"1009289730","pt":1580643276953,"mc":[{"id":"1.168217555","rc":[{"batb":[[2,1.01,0.51]],"batl":[[0,6.8,18.41],[1,6.8,0]],"ltp":5.2,"tv":21.28,"id":12984951},{"batb":[[1,1.42,48.63]],"batl":[[0,1.55,38.95],[1,1.55,0]],"ltp":0.0,"tv":0.0,"id":12984952},{"batb":[[0,6.8,22.07],[1,6.2,16.52],[2,1.01,0.51]],"batl":[[1,8.8,0]],"ltp":5.2,"tv":21.28,"id":16574984}]}]}
{"op":"mcm","clk":"1009290003","pt":1580643279046,"mc":[{"id":"1.168217555","rc":[{"batb":[[1,1.01,0.51],[2,1.01,0]],"ltp":5.2,"tv":21.28,"id":12984951},{"batb":[[1,1.44,107.62],[2,1.42,48.63]],"ltp":0.0,"tv":0.0,"id":12984952},{"batb":[[0,6.2,16.52],[1,1.01,0.51],[2,1.01,0]],"ltp":5.2,"tv":21.28,"id":16574984}]}]}
{"op":"mcm","clk":"1009290382","pt":1580643281937,"mc":[{"id":"1.168217555","rc":[{"batb":[[0,5.4,39.68],[1,5.3,27.98],[2,5.2,9.24]],"batl":[[0,6.4,7.56],[1,6.8,18.41]],"ltp":5.2,"tv":21.28,"id":12984951},{"batl":[[0,1.5,42.01],[1,1.55,38.95]],"ltp":0.0,"tv":0.0,"id":12984952},{"batb":[[0,7.2,17.75],[1,7,37.62],[2,6.2,16.52]],"batl":[[1,8.8,5.04]],"ltp":5.2,"tv":21.28,"id":16574984}]}]}
{"op":"mcm","clk":"1009290539","pt":1580643283265,"mc":[{"id":"1.168217555","rc":[{"batb":[[0,5.7,19.83],[1,5.5,10.62],[2,5.4,28.66]],"batl":[[1,6.8,17.62]],"ltp":5.2,"tv":21.28,"id":12984951},{"batl":[[0,1.48,47.21],[1,1.5,42.01],[2,1.53,42.02]],"ltp":0.0,"tv":0.0,"id":12984952},{"batb":[[2,6.6,14.01]],"batl":[[1,8.2,12.51]],"ltp":5.2,"tv":21.28,"id":16574984}]}]}
{"op":"mcm","clk":"1009290927","pt":1580643286150,"mc":[{"id":"1.168217555","rc":[{"batb":[[0,5.5,10.62],[1,5.3,27.98],[2,5.2,9.24]],"ltp":5.2,"tv":21.28,"id":12984951},{"batb":[[0,1.4,156.72],[1,1.01,0.51],[2,1.42,0]],"batl":[[0,1.5,42.01],[1,1.53,42.02],[2,1.53,0]],"ltp":0.0,"tv":0.0,"id":12984952},{"batb":[[0,7,6.72],[1,6.2,15.66],[2,1.01,0.51]],"batl":[[0,8.2,12.51],[1,9,5.04]],"ltp":5.2,"tv":21.28,"id":16574984}]}]}
{"op":"mcm","clk":"1009291017","pt":1580643286946,"mc":[{"id":"1.168217555","rc":[{"batb":[[2,1.01,0.51]],"batl":[[0,6.8,17.62],[1,6.8,0]],"ltp":5.2,"tv":21.28,"id":12984951},{"batb":[[0,1.4,51.69]],"batl":[[0,1.53,42.02],[1,1.53,0]],"ltp":0.0,"tv":0.0,"id":12984952},{"batb":[[0,6.2,15.66],[1,1.01,0.51],[2,1.01,0]],"batl":[[1,9,0]],"ltp":5.2,"tv":21.28,"id":16574984}]}]}
{"op":"mcm","clk":"1009291252","pt":1580643288761,"mc":[{"id":"1.168217555","rc":[{"batb":[[2,5.2,29.3]],"ltp":5.2,"tv":21.28,"id":12984951},{"batb":[[0,1.43,140.55],[1,1.42,115],[2,1.4,51.69]],"ltp":0.0,"tv":0.0,"id":12984952},{"batb":[[0,6.8,41.27],[1,6.6,34.51],[2,6.2,15.66]],"ltp":5.2,"tv":21.28,"id":16574984},{"batb":[[0,75,4.44],[1,70,4.87],[2,1.01,0.51]],"ltp":5.1,"tv":4.54,"id":16574983}]}]}
{"op":"mcm","clk":"1009291499","pt":1580643290793,"mc":[{"id":"1.168217555","rc":[{"batb":[[2,1.01,0.51]],"ltp":5.2,"tv":21.28,"id":12984951},{"batb":[[0,6.2,15.66],[1,1.01,0.51],[2,6.2,0]],"ltp":5.2,"tv":21.28,"id":16574984},{"batb":[[0,1.01,0.51],[1,70,0],[2,1.01,0]],"ltp":5.1,"tv":4.54,"id":16574983}]}]}
{"op":"mcm","clk":"1009291923","pt":1580643294044,"mc":[{"id":"1.168217555","rc":[{"batb":[[1,5.4,45.05],[2,5.3,27.98]],"ltp":5.2,"tv":21.28,"id":12984951},{"batb":[[0,7.2,37.16],[1,7,30.43],[2,6.2,15.66]],"ltp":5.2,"tv":21.28,"id":16574984}]}]}
{"op":"mcm","clk":"1009292113","pt":1580643295441,"mc":[{"id":"1.168217555","rc":[{"batb":[[0,5.8,18.88],[1,5.6,10.31],[2,5.4,45.05]],"batl":[[1,7,17]],"ltp":5.2,"tv":21.28,"id":12984951},{"batl":[[0,1.46,50.12],[1,1.5,44.93]],"ltp":0.0,"tv":0.0,"id":12984952},{"batb":[[2,6.4,15.03]],"batl":[[1,8.4,11.88]],"ltp":5.2,"tv":21.28,"id":16574984}]}]}
{"op":"mcm","clk":"1009292200","pt":1580643296085,"mc":[{"id":"1.168217555","rc":[{"batl":[[0,6.4,7.56],[1,6.8,17.62],[2,7,17]],"ltp":5.2,"tv":21.28,"id":12984951},{"batl":[[1,1.48,42.01],[2,1.5,44.93]],"ltp":0.0,"tv":0.0,"id":12984952},{"batb":[[0,7.2,43.88]],"batl":[[2,9.2,5.04]],"ltp":5.2,"tv":21.28,"id":16574984}]}]}
{"op":"mcm","clk":"1009293353","pt":1580643304006,"mc":[{"id":"1.168217555","rc":[{"batb":[[0,5.6,10.31],[1,5.3,37.22],[2,1.01,0.51]],"batl":[[1,7,17],[2,7,0]],"ltp":5.2,"tv":21.28,"id":12984951},{"batb":[[0,1.42,115],[1,1.39,161.91],[2,1.01,0.51]],"batl":[[0,1.48,42.01],[1,1.5,44.93],[2,1.5,0]],"ltp":0.0,"tv":0.0,"id":12984952},{"batb":[[0,7.2,6.72]],"batl":[[0,8.4,11.88],[1,9.2,5.04],[2,9.2,0]],"ltp":5.2,"tv":21.28,"id":16574984}]}]}
{"op":"mcm","clk":"1009293581","pt":1580643305494,"mc":[{"id":"1.168217555","rc":[{"batb":[[1,5.3,27.98]],"batl":[[0,7,17],[1,7,0]],"ltp":5.2,"tv":21.28,"id":12984951},{"batb":[[0,1.39,54.37],[1,1.01,0.51],[2,1.01,0]],"batl":[[0,1.5,44.93],[1,1.5,0]],"ltp":0.0,"tv":0.0,"id":12984952},{"batb":[[0,7,30.43],[1,6.4,15.03],[2,1.01,0.51]],"batl":[[1,9.2,0]],"ltp":5.2,"tv":21.28,"id":16574984}]}]}
{"op":"mcm","clk":"1009294018","pt":1580643308496,"mc":[{"id":"1.168217555","rc":[{"batb":[[1,5.4,38.78],[2,5.3,27.98]],"ltp":5.2,"tv":21.28,"id":12984951},{"batb":[[0,1.44,81.96],[1,1.43,111],[2,1.39,54.37]],"ltp":0.0,"tv":0.0,"id":12984952},{"batb":[[0,7.2,29],[1,7,30.43],[2,6.4,15.03]],"ltp":5.2,"tv":21.28,"id":16574984}]}]}
{"op":"mcm","clk":"1009294866","pt":1580643314374,"mc":[{"id":"1.168217555","rc":[{"batb":[[1,5.3,27.98],[2,1.01,0.51]],"ltp":5.2,"tv":21.28,"id":12984951},{"batb":[[0,1.39,54.37],[1,1.01,0.51],[2,1.39,0]],"ltp":0.0,"tv":0.0,"id":12984952},{"batb":[[0,7,30.43],[1,6.4,15.03],[2,1.01,0.51]],"ltp":5.2,"tv":21.28,"id":16574984}]}]}
{"op":"mcm","clk":"1009295261","pt":1580643317423,"mc":[{"id":"1.168217555","rc":[{"batb":[[1,5.3,14.25],[2,5.2,29]],"ltp":5.2,"tv":21.28,"id":12984951},{"batb":[[0,1.42,128.43],[1,1.41,118.57],[2,1.39,54.37]],"ltp":0.0,"tv":0.0,"id":12984952},{"batb":[[0,6.8,32.67]],"ltp":5.2,"tv":21.28,"id":16574984}]}]}
{"op":"mcm","clk":"1009295379","pt":1580643318180,"mc":[{"id":"1.168217555","rc":[{"batb":[[1,1.01,0.51],[2,5.2,0]],"ltp":5.2,"tv":21.28,"id":12984951},{"batb":[[0,6.4,15.03],[1,1.01,0.51],[2,1.01,0]],"ltp":5.2,"tv":21.28,"id":16574984}]}]}
{"op":"mcm","clk":"1009295717","pt":1580643320485,"mc":[{"id":"1.168217555","rc":[{"batb":[[0,5.9,18.18],[1,5.7,19.83],[2,5.5,32.65]],"batl":[[0,6.6,6.72],[1,7,16.52]],"ltp":5.2,"tv":21.28,"id":12984951},{"batl":[[0,1.44,52.64],[1,1.47,42.01],[2,1.48,47.68]],"ltp":0.0,"tv":0.0,"id":12984952},{"batb":[[0,7.4,32.74],[1,7.2,28.86],[2,6.8,12.59]],"batl":[[1,8.6,11.09],[2,9.4,4.2]],"ltp":5.2,"tv":21.28,"id":16574984}]}]}
{"op":"mcm","clk":"1009297381","pt":1580643331420,"mc":[{"id":"1.168217555","rc":[{"batb":[[2,5.4,26.77]],"ltp":5.2,"tv":21.28,"id":12984951},{"batb":[[0,1.41,118.57],[1,1.39,54.37],[2,1.37,170.16]],"ltp":0.0,"tv":0.0,"id":12984952},{"batb":[[0,7.4,5.88],[1,7.2,15.12]],"ltp":5.2,"tv":21.28,"id":16574984}]}]}
{"op":"mcm","clk":"1009297458","pt":1580643331802,"mc":[{"id":"1.168217555","rc":[{"batb":[[0,5.7,19.83],[1,5.4,26.77],[2,5.3,9.24]],"ltp":5.2,"tv":21.28,"id":12984951},{"batb":[[1,1.37,170.16],[2,1.01,0.51]],"batl":[[0,1.47,42.01],[1,1.48,47.68],[2,1.48,0]],"ltp":0.0,"tv":0.0,"id":12984952},{"batb":[[2,6.6,14.24]],"batl":[[0,8.6,11.09],[1,9.4,4.2],[2,9.4,0]],"ltp":5.2,"tv":21.28,"id":16574984}]}]}
{"op":"mcm","clk":"1009297607","pt":1580643333029,"mc":[{"id":"1.168217555","rc":[{"batb":[[2,1.01,0.51]],"batl":[[0,7,16.52],[1,7,0]],"ltp":5.2,"tv":21.28,"id":12984951},{"batb":[[1,1.37,56.73]],"batl":[[0,1.48,47.68],[1,1.48,0]],"ltp":0.0,"tv":0.0,"id":12984952},{"batb":[[0,7.2,15.12],[1,6.6,14.24],[2,1.01,0.51]],"batl":[[1,9.4,0]],"ltp":5.2,"tv":21.28,"id":16574984}]}]}
{"op":"mcm","clk":"1009297795","pt":1580643334326,"mc":[{"id":"1.168217555","rc":[{"batb":[[2,5.3,27.95]],"ltp":5.2,"tv":21.28,"id":12984951},{"batb":[[1,1.4,122.58],[2,1.37,56.73]],"ltp":0.0,"tv":0.0,"id":12984952},{"batb":[[1,7,30.96],[2,6.6,14.24]],"ltp":5.2,"tv":21.28,"id":16574984}]}]}
{"op":"mcm","clk":"1009297897","pt":1580643335026,"mc":[{"id":"1.168217555","rc":[{"batb":[[1,1.01,0.51],[2,5.3,0]],"ltp":5.2,"tv":21.28,"id":12984951},{"batb":[[1,1.37,56.73],[2,1.01,0.51]],"ltp":0.0,"tv":0.0,"id":12984952},{"batb":[[0,6.6,14.24],[1,1.01,0.51],[2,6.6,0]],"ltp":5.2,"tv":21.28,"id":16574984}]}]}
{"op":"mcm","clk":"1009298418","pt":1580643338344,"mc":[{"id":"1.168217555","rc":[{"batb":[[0,6,17.62],[1,5.8,18.73],[2,5.7,19.83]],"batl":[[0,6.6,6.72],[1,7,16.52],[2,7.4,15.19]],"ltp":5.2,"tv":21.28,"id":12984951},{"batb":[[1,1.4,122.58],[2,1.37,56.73]],"batl":[[0,1.43,54.92],[1,1.45,94.02],[2,1.48,47.68]],"ltp":0.0,"tv":0.0,"id":12984952},{"batb":[[0,7.6,23.86],[1,7.4,27.41],[2,7,11.72]],"batl":[[1,9,9.84],[2,9.8,4.2]],"ltp":5.2,"tv":21.28,"id":16574984}]}]}
{"op":"mcm","clk":"1009298449","pt":1580643338556,"mc":[{"id":"1.168217555","rc":[{"batb":[[2,5.6,20.18]],"ltp":5.2,"tv":21.28,"id":12984951},{"batl":[[2,1.48,0]],"ltp":0.0,"tv":0.0,"id":12984952}]}]}
{"op":"mcm","clk":"1009302224","pt":1580643362255,"mc":[{"id":"1.168217555","rc":[{"batb":[[0,5.8,18.73],[1,5.5,25.87],[2,5.4,9.24]],"batl":[[1,7.4,15.19],[2,7.4,0]],"ltp":5.2,"tv":21.28,"id":12984951},{"batb":[[0,1.36,115.95],[1,1.35,61.92],[2,1.01,0.51]],"batl":[[0,1.45,94.02],[1,1.45,0]],"ltp":0.0,"tv":0.0,"id":12984952},{"batb":[[0,7.6,5.88],[1,7.4,17.5],[2,6.8,12.59]],"batl":[[0,9,9.84],[1,9.8,4.2],[2,9.8,0]],"ltp":5.2,"tv":21.28,"id":16574984}]}]}
{"op":"mcm","clk":"1009302347","pt":1580643363054,"mc":[{"id":"1.168217555","rc":[{"batb":[[2,1.01,0.51]],"batl":[[0,7.4,15.19],[1,7.4,0]],"ltp":5.2,"tv":21.28,"id":12984951},{"batb":[[0,1.35,61.92],[1,1.01,0.51],[2,1.01,0]],"batl":[[0,1.45,52.01]],"ltp":0.0,"tv":0.0,"id":12984952},{"batb":[[0,7.4,17.5],[1,6.8,12.59],[2,1.01,0.51]],"batl":[[1,9.8,0]],"ltp":5.2,"tv":21.28,"id":16574984}]}]}
{"op":"mcm","clk":"1009302690","pt":1580643365467,"mc":[{"id":"1.168217555","rc":[{"batb":[[2,5.4,26.93]],"ltp":5.2,"tv":21.28,"id":12984951},{"batb":[[0,1.39,146.35],[1,1.38,131.07],[2,1.35,61.92]],"ltp":0.0,"tv":0.0,"id":12984952},{"batb":[[1,7.2,29.08],[2,6.8,12.59]],"ltp":5.2,"tv":21.28,"id":16574984}]}]}
{"op":"mcm","clk":"1009302737","pt":1580643365781,"mc":[{"id":"1.168217555","rc":[{"batb":[[0,1.35,61.92],[1,1.01,0.51],[2,1.35,0]],"ltp":0.0,"tv":0.0,"id":12984952}]}]}
{"op":"mcm","clk":"1009303396","pt":1580643369489,"mc":[{"id":"1.168217555","rc":[{"batb":[[1,5.7,19.91],[2,5.5,25.87]],"batl":[[0,7.2,16.05],[1,7.4,15.19]],"ltp":5.2,"tv":21.28,"id":12984951},{"batb":[[0,1.43,71.42],[1,1.42,114.37],[2,1.39,53.66]],"batl":[[1,1.47,48.94]],"ltp":0.0,"tv":0.0,"id":12984952},{"batl":[[0,8.4,11.88],[1,8.6,10.86],[2,9,9.84]],"ltp":5.2,"tv":21.28,"id":16574984}]}]}
{"op":"mcm","clk":"1009303470","pt":1580643369964,"mc":[{"id":"1.168217555","rc":[{"batl":[[0,6.6,6.72],[1,7.2,16.05]],"ltp":5.2,"tv":21.28,"id":12984951},{"batl":[[1,1.46,42.01],[2,1.47,48.94]],"ltp":0.0,"tv":0.0,"id":12984952},{"batb":[[0,7.4,23.38]],"batl":[[2,9.6,4.2]],"ltp":5.2,"tv":21.28,"id":16574984}]}]}
{"op":"mcm","clk":"1009304560","pt":1580643377370,"mc":[{"id":"1.168217555","rc":[{"batb":[[0,5.7,19.91],[1,5.4,26.93],[2,1.01,0.51]],"batl":[[0,7.2,16.05],[1,7.2,0]],"ltp":5.2,"tv":21.28,"id":12984951},{"batb":[[0,1.37,57.99],[1,1.01,0.51],[2,1.39,0]],"batl":[[0,1.47,48.94],[1,1.46,0],[2,1.47,0]],"ltp":0.0,"tv":0.0,"id":12984952},{"batb":[[0,7.2,19.99],[1,6.6,13.69],[2,1.01,0.51]],"batl":[[0,8.6,10.86],[1,8.6,0],[2,9.6,0]],"ltp":5.2,"tv":21.28,"id":16574984}]}]}
{"op":"mcm","clk":"1009304983","pt":1580643380309,"mc":[{"id":"1.168217555","rc":[{"batb":[[2,5.3,28.02]],"ltp":5.2,"tv":21.28,"id":12984951},{"batb":[[1,7,30.85],[2,6.6,13.69]],"ltp":5.2,"tv":21.28,"id":16574984}]}]}
{"op":"mcm","clk":"1009305570","pt":1580643384311,"mc":[{"id":"1.168217555","rc":[{"batb":[[1,5.6,10.39],[2,5.4,26.93]],"batl":[[0,6.6,6.72],[1,6.8,18.49],[2,7,17.31]],"ltp":5.2,"tv":21.28,"id":12984951},{"batb":[[0,1.44,108.7],[1,1.43,111.21],[2,1.41,50.44]],"batl":[[0,1.47,90.95],[1,1.49,46.66]],"ltp":0.0,"tv":0.0,"id":12984952},{"batb":[[0,7.2,26.71]],"batl":[[0,8,12.9],[1,8.4,11.64],[2,9.4,4.2]],"ltp":5.2,"tv":21.28,"id":16574984}]}]}
{"op":"mcm","clk":"1009305932","pt":1580643386808,"mc":[{"id":"1.168217555","rc":[{"batb":[[0,7.2,38.03]],"ltp":5.2,"tv":21.28,"id":16574984}]}]}
{"op":"mcm","clk":"1009306583","pt":1580643391070,"mc":[{"id":"1.168217555","rc":[{"batb":[[0,5.6,10.39],[1,5.3,28.02],[2,1.01,0.51]],"batl":[[0,7,17.31],[1,6.8,0],[2,7,0]],"ltp":5.2,"tv":21.28,"id":12984951},{"batb":[[0,1.39,54.37],[1,1.01,0.51],[2,1.41,0]],"batl":[[0,1.49,46.66],[1,1.49,0]],"ltp":0.0,"tv":0.0,"id":12984952},{"batb":[[0,7,30.85],[1,6.4,14.56],[2,1.01,0.51]],"batl":[[0,8.4,11.64],[1,8.4,0],[2,9.4,0]],"ltp":5.2,"tv":21.28,"id":16574984}]}]}
{"op":"mcm","clk":"1009306941","pt":1580643393618,"mc":[{"id":"1.168217555","rc":[{"batb":[[2,5.2,29.13]],"ltp":5.2,"tv":21.28,"id":12984951},{"batb":[[0,1.42,106.59],[1,1.41,118.55],[2,1.39,54.37]],"ltp":0.0,"tv":0.0,"id":12984952},{"batb":[[0,7,37.09],[1,6.8,32.71],[2,6.4,14.56]],"ltp":5.2,"tv":21.28,"id":16574984}]}]}
{"op":"mcm","clk":"1009308380","pt":1580643403626,"mc":[{"id":"1.168217555","rc":[{"batb":[[0,1.39,54.37],[1,1.01,0.51],[2,1.39,0]],"ltp":0.0,"tv":0.0,"id":12984952}]}]}
{"op":"mcm","clk":"1009308945","pt":1580643407336,"mc":[{"id":"1.168217555","rc":[{"batb":[[1,5.5,10.7],[2,5.3,28.02]],"batl":[[0,6.6,19.36],[1,6.8,18.1]],"ltp":5.2,"tv":21.28,"id":12984951},{"batb":[[0,1.45,109.89],[1,1.44,108.08],[2,1.43,48]],"batl":[[1,1.51,43.98]],"ltp":0.0,"tv":0.0,"id":12984952},{"batl":[[0,7.8,13.69],[1,8.2,12.43]],"ltp":5.2,"tv":21.28,"id":16574984}]}]}
{"op":"mcm","clk":"1009309038","pt":1580643408027,"mc":[{"id":"1.168217555","rc":[{"batb":[[2,5.3,37.26]],"batl":[[0,6.4,7.56],[1,6.6,19.36],[2,6.8,18.1]],"ltp":5.2,"tv":21.28,"id":12984951},{"batl":[[0,1.48,42.01],[1,1.49,46.66],[2,1.51,43.98]],"ltp":0.0,"tv":0.0,"id":12984952},{"batb":[[0,7.2,6.72],[1,7,37.09],[2,6.8,32.71]],"batl":[[2,9,5.04]],"ltp":5.2,"tv":21.28,"id":16574984}]}]}
{"op":"mcm","clk":"1009311074","pt":1580643422155,"mc":[{"id":"1.168217555","rc":[{"batb":[[0,5.5,10.7],[1,5.3,9.24],[2,5.2,29.13]],"batl":[[1,6.8,18.1],[2,6.8,0]],"ltp":5.2,"tv":21.28,"id":12984951},{"batb":[[0,1.4,51.69],[1,1.39,107.54],[2,1.01,0.51]],"batl":[[1,1.51,43.98],[2,1.51,0]],"ltp":0.0,"tv":0.0,"id":12984952},{"batb":[[1,6.8,32.71],[2,6.2,15.97]],"batl":[[0,8.2,12.43],[1,9,5.04],[2,9,0]],"ltp":5.2,"tv":21.28,"id":16574984}]}]}
{"op":"mcm","clk":"1009311257","pt":1580643423334,"mc":[{"id":"1.168217555","rc":[{"batb":[[1,5.2,29.13],[2,1.01,0.51]],"batl":[[0,6.8,18.1],[1,6.8,0]],"ltp":5.2,"tv":21.28,"id":12984951},{"batb":[[1,1.01,0.51],[2,1.01,0]],"batl":[[0,1.51,43.98],[1,1.51,0]],"ltp":0.0,"tv":0.0,"id":12984952},{"batb":[[0,6.8,32.71],[1,6.2,15.97],[2,1.01,0.51]],"batl":[[1,9,0]],"ltp":5.2,"tv":21.28,"id":16574984}]}]}
{"op":"mcm","clk":"1009311571","pt":1580643425338,"mc":[{"id":"1.168217555","rc":[{"batb":[[1,5.2,41.44],[2,5.1,30.28]],"ltp":5.2,"tv":21.28,"id":12984951},{"batb":[[0,1.43,141.89],[1,1.42,115.2],[2,1.4,51.69]],"ltp":0.0,"tv":0.0,"id":12984952},{"batb":[[0,6.8,45.98],[1,6.6,34.7],[2,6.2,15.97]],"ltp":5.2,"tv":21.28,"id":16574984}]}]}
{"op":"mcm","clk":"1009311694","pt":1580643426136,"mc":[{"id":"1.168217555","rc":[{"batb":[[1,5.2,29.13],[2,1.01,0.51]],"ltp":5.2,"tv":21.28,"id":12984951},{"batb":[[0,1.4,51.69],[1,1.01,0.51],[2,1.4,0]],"ltp":0.0,"tv":0.0,"id":12984952},{"batb":[[0,6.8,32.71],[1,6.2,15.97],[2,1.01,0.51]],"ltp":5.2,"tv":21.28,"id":16574984}]}]}
{"op":"mcm","clk":"1009312285","pt":1580643429972,"mc":[{"id":"1.168217555","rc":[{"batb":[[1,5.3,36.41],[2,5.2,29.13]],"ltp":5.2,"tv":21.28,"id":12984951},{"batb":[[0,1.45,72.23],[1,1.44,107.77],[2,1.4,51.69]],"ltp":0.0,"tv":0.0,"id":12984952},{"batb":[[0,7,45.03],[1,6.8,32.71],[2,6.2,15.97]],"ltp":5.2,"tv":21.28,"id":16574984}]}]}
{"op":"mcm","clk":"1009312684","pt":1580643432445,"mc":[{"id":"1.168217555","rc":[{"batb":[[1,5.2,29.13],[2,1.01,0.51]],"ltp":5.2,"tv":21.28,"id":12984951},{"batb":[[0,1.4,51.69],[1,1.01,0.51],[2,1.4,0]],"ltp":0.0,"tv":0.0,"id":12984952},{"batb":[[0,6.8,32.71],[1,6.2,15.97],[2,1.01,0.51]],"ltp":5.2,"tv":21.28,"id":16574984}]}]}
{"op":"mcm","clk":"1009313107","pt":1580643435490,"mc":[{"id":"1.168217555","rc":[{"batb":[[1,5.2,41.44],[2,5.1,30.28]],"ltp":5.2,"tv":21.28,"id":12984951},{"batb":[[0,1.43,141.89],[1,1.42,115.2],[2,1.4,51.69]],"ltp":0.0,"tv":0.0,"id":12984952},{"batb":[[0,6.8,45.98],[1,6.6,34.7],[2,6.2,15.97]],"ltp":5.2,"tv":21.28,"id":16574984}]}]}
{"op":"mcm","clk":"1009313518","pt":1580643438055,"mc":[{"id":"1.168217555","rc":[{"batb":[[1,1.01,0.51],[2,5.1,0]],"ltp":5.2,"tv":21.28,"id":12984951},{"batb":[[0,6.2,15.97],[1,1.01,0.51],[2,6.2,0]],"ltp":5.2,"tv":21.28,"id":16574984}]}]}
{"op":"mcm","clk":"1009314024","pt":1580643441385,"mc":[{"id":"1.168217555","rc":[{"batb":[[1,5.4,31.17],[2,5.3,27.9]],"ltp":5.2,"tv":21.28,"id":12984951},{"batb":[[0,7.2,43.3],[1,7,30.57],[2,6.2,15.97]],"ltp":5.2,"tv":21.28,"id":16574984}]}]}
{"op":"mcm","clk":"1009314140","pt":1580643442083,"mc":[{"id":"1.168217555","rc":[{"batb":[[0,5.7,19.43],[1,5.6,20.14],[2,5.4,31.17]],"batl":[[0,6.6,6.72],[1,6.8,18.1],[2,7,16.68]],"ltp":5.2,"tv":21.28,"id":12984951},{"batl":[[0,1.46,50.2],[1,1.47,42.01],[2,1.48,47.84]],"ltp":0.0,"tv":0.0,"id":12984952},{"batb":[[0,7.4,5.88],[1,7.2,43.3],[2,7,30.57]],"batl":[[1,8.6,11.09],[2,9.4,4.2]],"ltp":5.2,"tv":21.28,"id":16574984}]}]}
{"op":"mcm","clk":"1009316652","pt":1580643458413,"mc":[{"id":"1.168217555","rc":[{"batb":[[0,5.6,20.14],[1,5.3,37.14],[2,1.01,0.51]],"batl":[[1,7,16.68],[2,7,0]],"ltp":5.2,"tv":21.28,"id":12984951},{"batb":[[0,1.38,56.26],[1,1.37,113.43],[2,1.01,0.51]],"batl":[[0,1.47,42.01],[1,1.48,47.84],[2,1.48,0]],"ltp":0.0,"tv":0.0,"id":12984952},{"batb":[[1,7.2,17.82]],"batl":[[0,8.6,11.09],[1,9.4,4.2],[2,9.4,0]],"ltp":5.2,"tv":21.28,"id":16574984}]}]}
{"op":"mcm","clk":"1009316744","pt":1580643459098,"mc":[{"id":"1.168217555","rc":[{"batb":[[1,5.3,27.9]],"batl":[[0,7,16.68],[1,7,0]],"ltp":5.2,"tv":21.28,"id":12984951},{"batb":[[1,1.01,0.51],[2,1.01,0]],"batl":[[0,1.48,47.84],[1,1.48,0]],"ltp":0.0,"tv":0.0,"id":12984952},{"batb":[[0,7.2,17.82],[1,7,30.57],[2,6.6,14.16]],"batl":[[1,9.4,0]],"ltp":5.2,"tv":21.28,"id":16574984}]}]}
{"op":"mcm","clk":"1009317051","pt":1580643461405,"mc":[{"id":"1.168217555","rc":[{"batb":[[1,5.3,39.11],[2,5.2,29.01]],"ltp":5.2,"tv":21.28,"id":12984951},{"batb":[[0,1.41,175.73],[1,1.4,123.12],[2,1.38,56.26]],"ltp":0.0,"tv":0.0,"id":12984952}]}]}
{"op":"mcm","clk":"1009317264","pt":1580643462799,"mc":[{"id":"1.168217555","rc":[{"batb":[[0,7.2,28.7]],"ltp":5.2,"tv":21.28,"id":16574984}]}]}
{"op":"mcm","clk":"1009317458","pt":1580643464106,"mc":[{"id":"1.168217555","rc":[{"batb":[[0,1.38,56.26],[1,1.01,0.51],[2,1.38,0]],"ltp":0.0,"tv":0.0,"id":12984952}]}]}
{"op":"mcm","clk":"1009317941","pt":1580643467414,"mc":[{"id":"1.168217555","rc":[{"batb":[[1,5.4,10.94],[2,5.3,39.11]],"batl":[[0,6.6,18.8],[1,6.8,18.02],[2,7,16.68]],"ltp":5.2,"tv":21.28,"id":12984951},{"batb":[[0,1.44,139.67],[1,1.43,111.84],[2,1.42,49.33]],"batl":[[1,1.53,41.94]],"ltp":0.0,"tv":0.0,"id":12984952},{"batl":[[0,7.8,13.3],[1,8,12.67],[2,8.6,11.09]],"ltp":5.2,"tv":21.28,"id":16574984}]}]}
{"op":"mcm","clk":"1009318050","pt":1580643468113,"mc":[{"id":"1.168217555","rc":[{"batb":[[2,5.3,48.35]],"batl":[[0,6.4,7.56],[1,6.6,18.8],[2,6.8,18.02]],"ltp":5.2,"tv":21.28,"id":12984951},{"batl":[[1,1.49,42.01],[2,1.53,41.94]],"ltp":0.0,"tv":0.0,"id":12984952},{"batb":[[1,7,37.29],[2,6.2,16.44]],"batl":[[2,9,5.04]],"ltp":5.2,"tv":21.28,"id":16574984}]}]}
{"op":"mcm","clk":"1009329271","pt":1580643543612,"mc":[{"id":"1.168217555","rc":[{"batb":[[0,5.4,10.94],[1,5.3,9.24],[2,5.2,29.01]],"batl":[[1,6.8,18.02],[2,6.8,0]],"ltp":5.2,"tv":21.28,"id":12984951},{"batb":[[0,1.43,111.84],[1,1.4,52.01],[2,1.39,107.54]],"batl":[[0,1.49,42.01],[1,1.53,41.94],[2,1.53,0]],"ltp":0.0,"tv":0.0,"id":12984952},{"batb":[[0,7,26.1],[1,6.2,16.44],[2,1.01,0.51]],"batl":[[0,8,12.67],[1,9,5.04],[2,9,0]],"ltp":5.2,"tv":21.28,"id":16574984}]}]}
{"op":"mcm","clk":"1009329506","pt":1580643545114,"mc":[{"id":"1.168217555","rc":[{"batb":[[1,5.2,29.01],[2,1.01,0.51]],"batl":[[0,6.8,18.02],[1,6.8,0]],"ltp":5.2,"tv":21.28,"id":12984951},{"batb":[[2,1.01,0.51]],"batl":[[0,1.53,41.94],[1,1.53,0]],"ltp":0.0,"tv":0.0,"id":12984952},{"batb":[[0,7,19.38]],"batl":[[1,9,0]],"ltp":5.2,"tv":21.28,"id":16574984}]}]}
{"op":"mcm","clk":"1009329696","pt":1580643546504,"mc":[{"id":"1.168217555","rc":[{"batb":[[2,5.1,30.39]],"ltp":5.2,"tv":21.28,"id":12984951},{"batb":[[1,1.42,115.01],[2,1.4,52.01]],"ltp":0.0,"tv":0.0,"id":12984952},{"batb":[[1,6.8,33.54],[2,6.2,16.44]],"ltp":5.2,"tv":21.28,"id":16574984},{"batb":[[0,110,3.19],[1,100,3.23],[2,1.01,0.51]],"ltp":5.1,"tv":4.54,"id":16574983}]}]}
{"op":"mcm","clk":"1009331157","pt":1580643557236,"mc":[{"id":"1.168217555","rc":[{"batb":[[1,1.01,0.51],[2,5.1,0]],"ltp":5.2,"tv":21.28,"id":12984951},{"batb":[[0,6.2,16.44],[1,1.01,0.51],[2,6.2,0]],"ltp":5.2,"tv":21.28,"id":16574984},{"batb":[[0,1.01,0.51],[1,100,0],[2,1.01,0]],"ltp":5.1,"tv":4.54,"id":16574983}]}]}
{"op":"mcm","clk":"1009331529","pt":1580643560132,"mc":[{"id":"1.168217555","rc":[{"batb":[[0,5.4,35.01],[1,5.3,37.2],[2,1.01,0.51]],"batl":[[0,6.6,6.72],[1,6.8,18.02]],"ltp":5.2,"tv":21.28,"id":12984951},{"batl":[[0,1.47,42.01],[1,1.53,41.94]],"ltp":0.0,"tv":0.0,"id":12984952},{"batb":[[0,7.4,23.18],[1,7.2,36.27],[2,6.2,16.44]],"batl":[[1,9.2,5.04]],"ltp":5.2,"tv":21.28,"id":16574984}]}]}
{"op":"mcm","clk":"1009331660","pt":1580643561137,"mc":[{"id":"1.168217555","rc":[{"batb":[[0,5.7,19.36],[1,5.5,10.62],[2,5.4,24.07]],"batl":[[1,6.8,17.47]],"ltp":5.2,"tv":21.28,"id":12984951},{"batl":[[0,1.46,50.44],[1,1.47,42.01],[2,1.5,44.93]],"ltp":0.0,"tv":0.0,"id":12984952},{"batb":[[2,6.6,13.38]],"batl":[[1,8.4,11.8],[2,9.2,5.04]],"ltp":5.2,"tv":21.28,"id":16574984}]}]}
{"op":"mcm","clk":"1009331851","pt":1580643562636,"mc":[{"id":"1.168217555","rc":[{"batb":[[0,1.43,84.25]],"ltp":0.0,"tv":0.0,"id":12984952}]}]}
{"op":"mcm","clk":"1009332230","pt":1580643565507,"mc":[{"id":"1.168217555","rc":[{"batb":[[0,7.4,28.96]],"ltp":5.2,"tv":21.28,"id":16574984}]}]}
{"op":"mcm","clk":"1009332529","pt":1580643568130,"mc":[{"id":"1.168217555","rc":[{"batb":[[0,5.5,10.62],[1,5.3,9.24],[2,1.01,0.51]],"ltp":5.2,"tv":21.28,"id":12984951},{"batb":[[0,1.38,164.91],[1,1.01,0.51],[2,1.4,0]],"batl":[[0,1.47,42.01],[1,1.5,44.93],[2,1.5,0]],"ltp":0.0,"tv":0.0,"id":12984952},{"batb":[[0,7.2,6.72],[1,6.2,15.42],[2,1.01,0.51]],"batl":[[0,8.4,11.8],[1,9.2,5.04],[2,9.2,0]],"ltp":5.2,"tv":21.28,"id":16574984}]}]}
{"op":"mcm","clk":"1009332678","pt":1580643569246,"mc":[{"id":"1.168217555","rc":[{"batb":[[1,1.01,0.51],[2,1.01,0]],"batl":[[0,6.8,17.47],[1,6.8,0]],"ltp":5.2,"tv":21.28,"id":12984951},{"batb":[[0,1.38,54.84]],"batl":[[0,1.5,44.93],[1,1.5,0]],"ltp":0.0,"tv":0.0,"id":12984952},{"batb":[[0,6.2,15.42],[1,1.01,0.51],[2,1.01,0]],"batl":[[1,9.2,0]],"ltp":5.2,"tv":21.28,"id":16574984}]}]}
{"op":"mcm","clk":"1009332932","pt":1580643571054,"mc":[{"id":"1.168217555","rc":[{"batb":[[1,5.2,46.97],[2,5.1,30.12]],"ltp":5.2,"tv":21.28,"id":12984951},{"batb":[[0,7,45.81],[1,6.8,33.04],[2,6.2,15.42]],"ltp":5.2,"tv":21.28,"id":16574984}]}]}
{"op":"mcm","clk":"1009333361","pt":1580643574358,"mc":[{"id":"1.168217555","rc":[{"batb":[[1,5.2,56.21]],"batl":[[0,6.4,7.56],[1,6.8,17.47]],"ltp":5.2,"tv":21.28,"id":12984951},{"batb":[[0,1.45,143.59],[1,1.44,108.67],[2,1.4,105.02]],"batl":[[0,1.5,86.94]],"ltp":0.0,"tv":0.0,"id":12984952},{"batb":[[1,6.8,39.76]],"batl":[[1,8.8,5.04]],"ltp":5.2,"tv":21.28,"id":16574984}]}]}
{"op":"mcm","clk":"1009333498","pt":1580643575361,"mc":[{"id":"1.168217555","rc":[{"batb":[[1,5.4,11.33],[2,5.2,56.21]],"batl":[[1,6.6,18.88]],"ltp":5.2,"tv":21.28,"id":12984951},{"batb":[[1,1.44,154.86],[2,1.42,49.18]],"batl":[[1,1.55,39.42]],"ltp":0.0,"tv":0.0,"id":12984952},{"batl":[[0,7.6,14.48],[1,7.8,13.69],[2,8.8,5.04]],"ltp":5.2,"tv":21.28,"id":16574984}]}]}
{"op":"mcm","clk":"1009334864","pt":1580643585247,"mc":[{"id":"1.168217555","rc":[{"batb":[[0,5.4,11.33],[1,5.1,30.12],[2,1.01,0.51]],"batl":[[0,6.6,18.88],[1,6.6,0]],"ltp":5.2,"tv":21.28,"id":12984951},{"batb":[[0,1.44,108.67],[1,1.42,49.18],[2,1.01,0.51]],"batl":[[0,1.55,39.42],[1,1.55,0]],"ltp":0.0,"tv":0.0,"id":12984952},{"batb":[[0,6.8,33.04],[1,6,17.7],[2,1.01,0.51]],"batl":[[0,7.8,13.69],[1,7.8,0],[2,8.8,0]],"ltp":5.2,"tv":21.28,"id":16574984}]}]}
{"op":"mcm","clk":"1009335295","pt":1580643588447,"mc":[{"id":"1.168217555","rc":[{"batb":[[1,5.1,41.1],[2,5,31.61]],"ltp":5.2,"tv":21.28,"id":12984951},{"batb":[[1,1.43,111.52],[2,1.42,49.18]],"ltp":0.0,"tv":0.0,"id":12984952},{"batb":[[1,6.6,35.57],[2,6,17.7]],"ltp":5.2,"tv":21.28,"id":16574984},{"batb":[[0,85,5.72],[1,80,2.35],[2,1.01,0.51]],"ltp":5.1,"tv":4.54,"id":16574983}]}]}
{"op":"mcm","clk":"1009337261","pt":1580643602028,"mc":[{"id":"1.168217555","rc":[{"batb":[[1,1.01,0.51],[2,5,0]],"ltp":5.2,"tv":21.28,"id":12984951},{"batb":[[0,6,17.7],[1,1.01,0.51],[2,6,0]],"ltp":5.2,"tv":21.28,"id":16574984},{"batb":[[0,1.01,0.51],[1,80,0],[2,1.01,0]],"ltp":5.1,"tv":4.54,"id":16574983}]}]}
{"op":"mcm","clk":"1009337679","pt":1580643604466,"mc":[{"id":"1.168217555","rc":[{"batb":[[1,5.3,35.19],[2,5.2,28.99]],"ltp":5.2,"tv":21.28,"id":12984951},{"batb":[[0,7.2,35.34],[1,7,31.26],[2,6,17.7]],"ltp":5.2,"tv":21.28,"id":16574984}]}]}
{"op":"mcm","clk":"1009337974","pt":1580643606481,"mc":[{"id":"1.168217555","rc":[{"batb":[[0,5.6,20.3],[1,5.4,11.02],[2,5.3,44.43]],"batl":[[0,6.4,7.56],[1,6.6,18.88],[2,6.8,18.18]],"ltp":5.2,"tv":21.28,"id":12984951},{"batl":[[0,1.48,89.77],[1,1.52,42.25]],"ltp":0.0,"tv":0.0,"id":12984952},{"batb":[[1,7,37.98],[2,6.4,14.56]],"batl":[[1,8,12.59],[2,9,5.04]],"ltp":5.2,"tv":21.28,"id":16574984}]}]}
{"op":"mcm","clk":"1009341649","pt":1580643632424,"mc":[{"id":"1.168217555","rc":[{"batb":[[0,5.4,11.02],[1,5.3,9.24],[2,5.2,28.99]],"batl":[[1,6.8,18.18],[2,6.8,0]],"ltp":5.2,"tv":21.28,"id":12984951},{"batb":[[0,1.4,52.4],[1,1.39,107.54],[2,1.01,0.51]],"batl":[[0,1.48,42.01]],"ltp":0.0,"tv":0.0,"id":12984952},{"batb":[[0,7,27.76],[1,6.2,16.52],[2,1.01,0.51]],"batl":[[0,8,12.59],[1,9,5.04],[2,9,0]],"ltp":5.2,"tv":21.28,"id":16574984}]}]}
{"op":"mcm","clk":"1009341794","pt":1580643633398,"mc":[{"id":"1.168217555","rc":[{"batb":[[1,5.2,28.99],[2,1.01,0.51]],"batl":[[0,6.8,18.18],[1,6.8,0]],"ltp":5.2,"tv":21.28,"id":12984951},{"batb":[[1,1.01,0.51],[2,1.01,0]],"batl":[[0,1.52,42.25],[1,1.52,0]],"ltp":0.0,"tv":0.0,"id":12984952},{"batb":[[0,7,21.04]],"batl":[[1,9,0]],"ltp":5.2,"tv":21.28,"id":16574984}]}]}
{"op":"mcm","clk":"1009342021","pt":1580643635016,"mc":[{"id":"1.168217555","rc":[{"batb":[[2,5.1,30.38]],"ltp":5.2,"tv":21.28,"id":12984951},{"batb":[[0,1.42,168.27],[1,1.41,119.45],[2,1.4,52.4]],"ltp":0.0,"tv":0.0,"id":12984952},{"batb":[[1,6.8,33.65],[2,6.2,16.52]],"ltp":5.2,"tv":21.28,"id":16574984},{"batb":[[0,150,2.39],[1,140,2.25],[2,1.01,0.51]],"ltp":5.1,"tv":4.54,"id":16574983}]}]}
{"op":"mcm","clk":"1009345014","pt":1580643655269,"mc":[{"id":"1.168217555","rc":[{"batb":[[2,1.01,0.51]],"ltp":5.2,"tv":21.28,"id":12984951},{"batb":[[0,1.4,52.4],[1,1.01,0.51],[2,1.4,0]],"ltp":0.0,"tv":0.0,"id":12984952},{"batb":[[1,6.2,16.52],[2,1.01,0.51]],"ltp":5.2,"tv":21.28,"id":16574984},{"batb":[[0,1.01,0.51],[1,140,0],[2,1.01,0]],"ltp":5.1,"tv":4.54,"id":16574983}]}]}
{"op":"mcm","clk":"1009345506","pt":1580643658470,"mc":[{"id":"1.168217555","rc":[{"batb":[[1,5.3,28.2],[2,5.2,28.99]],"ltp":5.2,"tv":21.28,"id":12984951},{"batb":[[0,1.44,146.53],[1,1.43,112.04],[2,1.4,52.4]],"ltp":0.0,"tv":0.0,"id":12984952},{"batb":[[0,7.2,26.25],[1,7,31.48],[2,6.2,16.52]],"ltp":5.2,"tv":21.28,"id":16574984}]}]}
{"op":"mcm","clk":"1009345965","pt":1580643661482,"mc":[{"id":"1.168217555","rc":[{"batb":[[1,5.2,28.99],[2,1.01,0.51]],"ltp":5.2,"tv":21.28,"id":12984951},{"batb":[[0,1.4,52.4],[1,1.01,0.51],[2,1.4,0]],"ltp":0.0,"tv":0.0,"id":12984952},{"batb":[[0,7,21.09],[1,6.2,16.52],[2,1.01,0.51]],"ltp":5.2,"tv":21.28,"id":16574984}]}]}
{"op":"mcm","clk":"1009346423","pt":1580643664509,"mc":[{"id":"1.168217555","rc":[{"batb":[[2,5.1,30.38]],"ltp":5.2,"tv":21.28,"id":12984951},{"batb":[[0,1.42,168.16],[1,1.41,119.46],[2,1.4,52.4]],"ltp":0.0,"tv":0.0,"id":12984952},{"batb":[[1,6.8,33.65],[2,6.2,16.52]],"ltp":5.2,"tv":21.28,"id":16574984},{"batb":[[0,150,2.39],[1,140,2.25],[2,1.01,0.51]],"ltp":5.1,"tv":4.54,"id":16574983}]}]}
{"op":"mcm","clk":"1009348063","pt":1580643675100,"mc":[{"id":"1.168217555","rc":[{"batb":[[0,1.4,52.4],[1,1.01,0.51],[2,1.4,0]],"ltp":0.0,"tv":0.0,"id":12984952}]}]}
{"op":"mcm","clk":"1009348552","pt":1580643678414,"mc":[{"id":"1.168217555","rc":[{"batb":[[1,5.2,38.23]],"batl":[[0,6.4,7.56],[1,6.8,18.18]],"ltp":5.2,"tv":21.28,"id":12984951},{"batb":[[0,1.46,170.27],[1,1.45,105.69],[2,1.41,101.66]],"batl":[[0,1.51,42.01],[1,1.52,42.25]],"ltp":0.0,"tv":0.0,"id":12984952},{"batb":[[1,6.8,40.37]],"batl":[[1,8.6,5.04]],"ltp":5.2,"tv":21.28,"id":16574984},{"batb":[[1,1.01,0.51],[2,1.01,0]],"ltp":5.1,"tv":4.54,"id":16574983}]}]}
{"op":"mcm","clk":"1009348681","pt":1580643679325,"mc":[{"id":"1.168217555","rc":[{"batb":[[1,5.2,50.19]],"batl":[[0,6.2,10.62],[1,6.4,7.56],[2,6.6,19.75]],"ltp":5.2,"tv":21.28,"id":12984951},{"batb":[[0,1.46,213.7],[2,1.44,46.89]],"batl":[[2,1.58,36.19]],"ltp":0.0,"tv":0.0,"id":12984952},{"batb":[[2,5.8,19.12]],"batl":[[0,7.4,15.5],[1,7.6,14.63],[2,8.6,5.04]],"ltp":5.2,"tv":21.28,"id":16574984}]}]}
{"op":"mcm","clk":"1009350211","pt":1580643688490,"mc":[{"id":"1.168217555","rc":[{"batb":[[1,5.2,21.2],[2,5.1,20.82]],"ltp":5.2,"tv":21.28,"id":12984951},{"batb":[[0,1.46,43.43],[1,1.45,74.66]],"ltp":0.0,"tv":0.0,"id":12984952},{"batb":[[0,6.8,6.72],[1,5.8,19.12],[2,1.01,0.51]],"ltp":5.2,"tv":21.28,"id":16574984},{"batb":[[0,1.01,0.51],[1,1.01,0]],"ltp":5.1,"tv":4.54,"id":16574983}]}]}
{"op":"mcm","clk":"1009350326","pt":1580643689330,"mc":[{"id":"1.168217555","rc":[{"batb":[[0,5.2,11.96],[1,5.1,20.82],[2,1.01,0.51]],"batl":[[0,6.6,19.75],[1,6.4,0],[2,6.6,0]],"ltp":5.2,"tv":21.28,"id":12984951},{"batb":[[0,1.45,74.66],[1,1.44,46.89],[2,1.01,0.51]],"batl":[[0,1.58,36.19],[1,1.52,0],[2,1.58,0]],"ltp":0.0,"tv":0.0,"id":12984952},{"batb":[[0,5.8,19.12],[1,1.01,0.51],[2,1.01,0]],"batl":[[0,7.6,14.63],[1,7.6,0],[2,8.6,0]],"ltp":5.2,"tv":21.28,"id":16574984}]}]}
{"op":"mcm","clk":"1009350619","pt":1580643691521,"mc":[{"id":"1.168217555","rc":[{"batb":[[2,5,31.95]],"ltp":5.2,"tv":21.28,"id":12984951},{"batb":[[1,1.44,154.98]],"ltp":0.0,"tv":0.0,"id":12984952},{"batb":[[0,6.6,45.68],[1,6.4,37.78],[2,5.8,19.12]],"ltp":5.2,"tv":21.28,"id":16574984},{"batb":[[0,65,7.74],[1,60,2.85],[2,1.01,0.51]],"ltp":5.1,"tv":4.54,"id":16574983}]}]}
{"op":"mcm","clk":"1009351047","pt":1580643694518,"mc":[{"id":"1.168217555","rc":[{"batb":[[1,1.01,0.51],[2,5,0]],"ltp":5.2,"tv":21.28,"id":12984951},{"batb":[[0,5.8,19.12],[1,1.01,0.51],[2,5.8,0]],"ltp":5.2,"tv":21.28,"id":16574984},{"batb":[[0,1.01,0.51],[1,60,0],[2,1.01,0]],"ltp":5.1,"tv":4.54,"id":16574983}]}]}
{"op":"mcm","clk":"1009351420","pt":1580643697137,"mc":[{"id":"1.168217555","rc":[{"batb":[[0,5.3,20.3],[1,5.2,41.18],[2,1.01,0.51]],"ltp":5.2,"tv":21.28,"id":12984951},{"batb":[[0,7,43.67],[1,6.8,33.09],[2,5.8,19.12]],"ltp":5.2,"tv":21.28,"id":16574984}]}]}
{"op":"mcm","clk":"1009351579","pt":1580643698321,"mc":[{"id":"1.168217555","rc":[{"batb":[[0,5.5,10.62],[1,5.3,31.71],[2,5.2,38.46]],"batl":[[0,6.4,7.56],[1,6.6,19.04]],"ltp":5.2,"tv":21.28,"id":12984951},{"batb":[[2,1.41,50.12]],"batl":[[0,1.49,87.65],[1,1.54,40.05]],"ltp":0.0,"tv":0.0,"id":12984952},{"batb":[[1,6.8,39.81],[2,6.2,15.58]],"batl":[[1,7.8,13.53],[2,8.6,5.04]],"ltp":5.2,"tv":21.28,"id":16574984}]}]}
{"op":"mcm","clk":"1009353310","pt":1580643709293,"mc":[{"id":"1.168217555","rc":[{"batb":[[0,5.3,11.41],[1,1.01,0.51],[2,5.2,0]],"batl":[[0,6.6,19.04],[1,6.6,0]],"ltp":5.2,"tv":21.28,"id":12984951},{"batb":[[0,1.41,50.12],[1,1.01,0.51],[2,1.41,0]],"batl":[[0,1.54,40.05],[1,1.54,0]],"ltp":0.0,"tv":0.0,"id":12984952},{"batb":[[0,6.8,33.09],[1,5.9,17.94],[2,1.01,0.51]],"batl":[[0,7.8,13.53],[1,7.8,0],[2,8.6,0]],"ltp":5.2,"tv":21.28,"id":16574984}]}]}
{"op":"mcm","clk":"1009353783","pt":1580643712344,"mc":[{"id":"1.168217555","rc":[{"batb":[[1,5.1,45.2],[2,5,31.55]],"ltp":5.2,"tv":21.28,"id":12984951},{"batb":[[0,1.43,140.33],[1,1.42,115.55],[2,1.41,50.12]],"ltp":0.0,"tv":0.0,"id":12984952},{"batb":[[1,6.6,35.66],[2,5.9,17.94]],"ltp":5.2,"tv":21.28,"id":16574984},{"batb":[[0,140,3.99],[1,1.01,0.51]],"ltp":5.1,"tv":4.54,"id":16574983}]}]}
{"op":"mcm","clk":"1009353944","pt":1580643713458,"mc":[{"id":"1.168217555","rc":[{"batb":[[1,1.01,0.51],[2,5,0]],"ltp":5.2,"tv":21.28,"id":12984951},{"batb":[[0,5.9,17.94],[1,1.01,0.51],[2,5.9,0]],"ltp":5.2,"tv":21.28,"id":16574984},{"batb":[[0,1.01,0.51],[1,1.01,0]],"ltp":5.1,"tv":4.54,"id":16574983}]}]}
{"op":"mcm","clk":"1009354453","pt":1580643716469,"mc":[{"id":"1.168217555","rc":[{"batb":[[0,5.3,49.02],[1,5.2,28.95],[2,1.01,0.51]],"ltp":5.2,"tv":21.28,"id":12984951},{"batb":[[0,7.2,28.73],[1,7,31.29],[2,5.9,17.94]],"ltp":5.2,"tv":21.28,"id":16574984}]}]}
{"op":"mcm","clk":"1009354569","pt":1580643717180,"mc":[{"id":"1.168217555","rc":[{"batb":[[0,5.6,20.46],[1,5.3,37.61],[2,5.2,41.22]],"batl":[[1,7.8,13.53]],"ltp":5.2,"tv":21.28,"id":12984951},{"batl":[[0,1.47,48.63],[1,1.54,40.05]],"ltp":0.0,"tv":0.0,"id":12984952},{"batb":[[2,6.4,14.4]],"batl":[[1,9.2,9.6]],"ltp":5.2,"tv":21.28,"id":16574984}]}]}
{"op":"mcm","clk":"1009355004","pt":1580643719469,"mc":[{"id":"1.168217555","rc":[{"batb":[[1,5.3,46.85]],"batl":[[0,6.4,7.56],[1,6.6,19.04],[2,7.8,13.53]],"ltp":5.2,"tv":21.28,"id":12984951},{"batl":[[1,1.48,42.01],[2,1.54,40.05]],"ltp":0.0,"tv":0.0,"id":12984952},{"batl":[[1,8.8,5.04],[2,9.2,9.6]],"ltp":5.2,"tv":21.28,"id":16574984}]}]}
{"op":"mcm","clk":"1009355057","pt":1580643719783,"mc":[{"id":"1.168217555","rc":[{"batb":[[1,7,38.01]],"ltp":5.2,"tv":21.28,"id":16574984}]}]}
{"op":"mcm","clk":"1009367261","pt":1580643802249,"mc":[{"id":"1.168217555","rc":[{"batb":[[0,5.3,9.24],[1,5.2,12.27],[2,1.01,0.51]],"batl":[[1,7.8,13.53],[2,7.8,0]],"ltp":5.2,"tv":21.28,"id":12984951},{"batb":[[0,1.38,110.07],[1,1.33,66.96],[2,1.01,0.51]],"batl":[[0,1.48,42.01],[1,1.54,40.05],[2,1.54,0]],"ltp":0.0,"tv":0.0,"id":12984952},{"batb":[[0,7,6.72],[1,5.9,17.94],[2,1.01,0.51]],"batl":[[0,8.8,5.04],[1,9.2,9.6],[2,9.2,0]],"ltp":5.2,"tv":21.28,"id":16574984}]}]}
{"op":"mcm","clk":"1009367432","pt":1580643803450,"mc":[{"id":"1.168217555","rc":[{"batb":[[0,5.2,12.27],[1,1.01,0.51],[2,1.01,0]],"batl":[[0,7.8,13.53],[1,7.8,0]],"ltp":5.2,"tv":21.28,"id":12984951},{"batb":[[0,1.33,66.96],[1,1.01,0.51],[2,1.01,0]],"batl":[[0,1.54,40.05],[1,1.54,0]],"ltp":0.0,"tv":0.0,"id":12984952},{"batb":[[0,5.9,17.94],[1,1.01,0.51],[2,1.01,0]],"batl":[[0,9.2,9.6],[1,9.2,0]],"ltp":5.2,"tv":21.28,"id":16574984}]}]}
{"op":"mcm","clk":"1009367616","pt":1580643804745,"mc":[{"id":"1.168217555","rc":[{"batb":[[1,4.9,21.83],[2,4.8,35.02]],"ltp":5.2,"tv":21.28,"id":12984951},{"batb":[[0,1.35,86.22],[1,1.34,150.93],[2,1.33,66.96]],"ltp":0.0,"tv":0.0,"id":12984952},{"batb":[[0,6.6,20.8],[1,6.4,38.15],[2,5.9,17.94]],"ltp":5.2,"tv":21.28,"id":16574984}]}]}
{"op":"mcm","clk":"1009368539","pt":1580643811316,"mc":[{"id":"1.168217555","rc":[{"batb":[[0,1.33,66.96],[1,1.01,0.51],[2,1.33,0]],"ltp":0.0,"tv":0.0,"id":12984952},{"batb":[[0,9,15.96],[1,1.01,0.51]],"ltp":5.1,"tv":4.54,"id":16574983}]}]}
{"op":"mcm","clk":"1009368926","pt":1580643814322,"mc":[{"id":"1.168217555","rc":[{"batb":[[0,1.5,90.12],[1,1.49,93.58],[2,1.33,66.96]],"ltp":0.0,"tv":0.0,"id":12984952}]}]}
{"op":"mcm","clk":"1009369071","pt":1580643815339,"mc":[{"id":"1.168217555","rc":[{"batb":[[2,4.8,49.5]],"batl":[[0,5.9,11.8],[1,6.8,17.86]],"ltp":5.2,"tv":21.28,"id":12984951},{"batb":[[2,1.48,41.7]],"batl":[[1,1.6,34.86]],"ltp":0.0,"tv":0.0,"id":12984952},{"batl":[[0,7,16.76],[1,8,12.51]],"ltp":5.2,"tv":21.28,"id":16574984}]}]}
{"op":"mcm","clk":"1009369224","pt":1580643816355,"mc":[{"id":"1.168217555","rc":[{"batb":[[1,4.9,31.91]],"batl":[[0,5.9,20.2]],"ltp":5.2,"tv":21.28,"id":12984951},{"batl":[[0,1.54,82.06]],"ltp":0.0,"tv":0.0,"id":12984952},{"batb":[[0,6.6,27.52]],"batl":[[2,8.2,5.04]],"ltp":5.2,"tv":21.28,"id":16574984}]}]}
{"op":"mcm","clk":"1009371791","pt":1580643834436,"mc":[{"id":"1.168217555","rc":[{"batb":[[0,4.9,10.08],[1,4.8,14.48],[2,1.01,0.51]],"batl":[[0,5.9,8.4]],"ltp":5.2,"tv":21.28,"id":12984951},{"batb":[[0,1.43,97.46],[1,1.39,53.35],[2,1.01,0.51]],"batl":[[0,1.54,42.01]],"ltp":0.0,"tv":0.0,"id":12984952},{"batb":[[0,6.6,6.72],[1,5.5,10.62],[2,1.01,0.51]],"batl":[[0,8,12.51],[1,8.2,5.04],[2,8.2,0]],"ltp":5.2,"tv":21.28,"id":16574984}]}]}
{"op":"mcm","clk":"1009371943","pt":1580643835457,"mc":[{"id":"1.168217555","rc":[{"batb":[[0,4.8,14.48],[1,1.01,0.51],[2,1.01,0]],"batl":[[0,6.8,17.86],[1,6.8,0]],"ltp":5.2,"tv":21.28,"id":12984951},{"batb":[[0,1.39,53.35],[1,1.01,0.51],[2,1.01,0]],"batl":[[0,1.6,34.86],[1,1.6,0]],"ltp":0.0,"tv":0.0,"id":12984952},{"batb":[[0,5.5,10.62],[1,1.01,0.51],[2,1.01,0]],"batl":[[1,8.2,0]],"ltp":5.2,"tv":21.28,"id":16574984}]}]}
{"op":"mcm","clk":"1009372267","pt":1580643837515,"mc":[{"id":"1.168217555","rc":[{"batb":[[0,5.6,10.31],[1,5.5,10.62],[2,1.01,0.51]],"batl":[[1,8.2,12.2]],"ltp":5.2,"tv":21.28,"id":16574984}]}]}
{"op":"mcm","clk":"1009372366","pt":1580643838126,"mc":[{"id":"1.168217555","rc":[{"batb":[[1,1.01,0.51],[2,1.01,0]],"batl":[[0,8.2,12.2],[1,8.2,0]],"ltp":5.2,"tv":21.28,"id":16574984}]}]}
{"op":"mcm","clk":"1009372590","pt":1580643839403,"mc":[{"id":"1.168217555","rc":[{"batb":[[0,5,23.38],[1,4.9,33.38],[2,4.8,14.48]],"ltp":5.2,"tv":21.28,"id":12984951},{"batb":[[0,1.48,116.35],[1,1.47,99.19],[2,1.39,53.35]],"ltp":0.0,"tv":0.0,"id":12984952},{"batb":[[0,6.8,15.46],[1,6.6,35.89],[2,5.6,10.31]],"ltp":5.2,"tv":21.28,"id":16574984}]}]}
{"op":"mcm","clk":"1009372885","pt":1580643841310,"mc":[{"id":"1.168217555","rc":[{"batb":[[0,1.01,0.51],[1,1.01,0]],"ltp":5.1,"tv":4.54,"id":16574983}]}]}
{"op":"mcm","clk":"1009373614","pt":1580643845510,"mc":[{"id":"1.168217555","rc":[{"batb":[[0,4.8,14.48],[1,1.01,0.51],[2,4.8,0]],"ltp":5.2,"tv":21.28,"id":12984951},{"batb":[[0,1.39,53.35],[1,1.01,0.51],[2,1.39,0]],"ltp":0.0,"tv":0.0,"id":12984952},{"batb":[[0,5.6,10.31],[1,1.01,0.51],[2,5.6,0]],"ltp":5.2,"tv":21.28,"id":16574984}]}]}
{"op":"mcm","clk":"1009374048","pt":1580643848515,"mc":[{"id":"1.168217555","rc":[{"batb":[[1,4.5,54.01],[2,4.4,42.18]],"ltp":5.2,"tv":21.28,"id":12984951},{"batb":[[0,1.42,83.5],[1,1.41,118.57],[2,1.39,53.35]],"ltp":0.0,"tv":0.0,"id":12984952},{"batb":[[0,6,56.42],[1,5.9,22.72],[2,5.6,10.31]],"ltp":5.2,"tv":21.28,"id":16574984}]}]}
{"op":"mcm","clk":"1009374409","pt":1580643850825,"mc":[{"id":"1.168217555","rc":[{"batb":[[0,1.39,53.35],[1,1.01,0.51],[2,1.39,0]],"ltp":0.0,"tv":0.0,"id":12984952}]}]}
{"op":"mcm","clk":"1009374943","pt":1580643854334,"mc":[{"id":"1.168217555","rc":[{"batb":[[1,4.6,16.13],[2,4.5,65.77]],"batl":[[0,5.5,23.17],[1,5.9,11.64],[2,6.8,17.86]],"ltp":5.2,"tv":21.28,"id":12984951},{"batb":[[0,1.56,66.33],[1,1.55,79.86],[2,1.54,36.04]],"batl":[[0,1.6,76.87],[1,1.65,31.32]],"ltp":0.0,"tv":0.0,"id":12984952},{"batb":[[0,6,64.82]],"batl":[[0,6.6,19.2],[1,7.4,15.5],[2,7.6,5.88]],"ltp":5.2,"tv":21.28,"id":16574984}]}]}
{"op":"mcm","clk":"1009374983","pt":1580643854557,"mc":[{"id":"1.168217555","rc":[{"batl":[[2,6.8,0]],"ltp":5.2,"tv":21.28,"id":12984951}]}]}
{"op":"mcm","clk":"1009376196","pt":1580643862322,"mc":[{"id":"1.168217555","rc":[{"batb":[[0,6,57.3]],"ltp":5.2,"tv":21.28,"id":16574984}]}]}
{"op":"mcm","clk":"1009376614","pt":1580643865428,"mc":[{"id":"1.168217555","rc":[{"batb":[[0,4.6,16.13],[1,1.01,0.51],[2,4.5,0]],"batl":[[0,5.9,11.64],[1,5.9,0]],"ltp":5.2,"tv":21.28,"id":12984951},{"batb":[[0,1.47,43.28],[1,1.01,0.51],[2,1.54,0]],"batl":[[0,1.65,31.32],[1,1.65,0]],"ltp":0.0,"tv":0.0,"id":12984952},{"batb":[[0,5.3,11.64],[1,1.01,0.51],[2,5.6,0]],"batl":[[0,7.4,15.5],[1,7.4,0],[2,7.6,0]],"ltp":5.2,"tv":21.28,"id":16574984}]}]}
{"op":"mcm","clk":"1009376927","pt":1580643867943,"mc":[{"id":"1.168217555","rc":[{"batb":[[1,4.3,63.59],[2,4.2,46.89]],"ltp":5.2,"tv":21.28,"id":12984951},{"batb":[[0,1.49,149.09],[1,1.48,96.58],[2,1.47,43.28]],"ltp":0.0,"tv":0.0,"id":12984952},{"batb":[[0,5.8,27.89],[1,5.7,24.83],[2,5.3,11.64]],"ltp":5.2,"tv":21.28,"id":16574984}]}]}
{"op":"mcm","clk":"1009377125","pt":1580643869348,"mc":[{"id":"1.168217555","rc":[{"batb":[[0,1.47,43.28],[1,1.01,0.51],[2,1.47,0]],"ltp":0.0,"tv":0.0,"id":12984952}]}]}
{"op":"mcm","clk":"1009377427","pt":1580643871432,"mc":[{"id":"1.168217555","rc":[{"batb":[[0,1.6,101.12],[1,1.59,72.57],[2,1.47,43.28]],"ltp":0.0,"tv":0.0,"id":12984952}]}]}
{"op":"mcm","clk":"1009377551","pt":1580643872329,"mc":[{"id":"1.168217555","rc":[{"batb":[[1,4.5,17.31],[2,4.4,11.76]],"batl":[[0,5.2,15.42],[1,5.3,9.24],[2,5.4,14.08]],"ltp":5.2,"tv":21.28,"id":12984951},{"batb":[[1,1.59,104.59],[2,1.53,36.35]],"batl":[[0,1.64,42.01],[1,1.65,31.32],[2,1.68,29.11]],"ltp":0.0,"tv":0.0,"id":12984952},{"batb":[[0,5.8,36.29]],"batl":[[0,6.2,11.25],[1,6.8,18.65],[2,7.2,6.72]],"ltp":5.2,"tv":21.28,"id":16574984}]}]}
{"op":"mcm","clk":"1009378736","pt":1580643880335,"mc":[{"id":"1.168217555","rc":[{"batb":[[0,4.5,17.31],[1,4.4,11.76],[2,1.01,0.51]],"batl":[[0,5.3,9.24],[1,5.4,14.08],[2,5.4,0]],"ltp":5.2,"tv":21.28,"id":12984951},{"batb":[[0,1.53,36.35],[1,1.52,80.66],[2,1.01,0.51]],"batl":[[1,1.68,29.11],[2,1.68,0]],"ltp":0.0,"tv":0.0,"id":12984952},{"batb":[[0,5.8,8.4],[1,5.1,12.67],[2,1.01,0.51]],"batl":[[0,6.8,18.65],[1,7.2,6.72],[2,7.2,0]],"ltp":5.2,"tv":21.28,"id":16574984}]}]}
{"op":"mcm","clk":"1009378885","pt":1580643881349,"mc":[{"id":"1.168217555","rc":[{"batb":[[1,1.01,0.51],[2,1.01,0]],"batl":[[0,5.4,14.08],[1,5.4,0]],"ltp":5.2,"tv":21.28,"id":12984951},{"batb":[[1,1.01,0.51],[2,1.01,0]],"batl":[[0,1.68,29.11],[1,1.68,0]],"ltp":0.0,"tv":0.0,"id":12984952},{"batb":[[0,5.1,12.67],[1,1.01,0.51],[2,1.01,0]],"batl":[[1,7.2,0]],"ltp":5.2,"tv":21.28,"id":16574984}]}]}
{"op":"mcm","clk":"1009379207","pt":1580643883436,"mc":[{"id":"1.168217555","rc":[{"batb":[[1,4.2,47.6],[2,1.01,0.51]],"ltp":5.2,"tv":21.28,"id":12984951},{"batb":[[0,1.56,116.9],[1,1.55,80.05],[2,1.53,36.35]],"ltp":0.0,"tv":0.0,"id":12984952},{"batb":[[0,5.6,35.4],[1,5.5,26.78],[2,5.1,12.67]],"ltp":5.2,"tv":21.28,"id":16574984}]}]}
{"op":"mcm","clk":"1009379262","pt":1580643883764,"mc":[{"id":"1.168217555","rc":[{"batb":[[1,4.3,24.24],[2,4.2,47.6]],"ltp":5.2,"tv":21.28,"id":12984951}]}]}
{"op":"mcm","clk":"1009379770","pt":1580643887152,"mc":[{"id":"1.168217555","rc":[{"batb":[[0,1.53,36.35],[1,1.01,0.51],[2,1.53,0]],"ltp":0.0,"tv":0.0,"id":12984952}]}]}
{"op":"mcm","clk":"1009380247","pt":1580643890352,"mc":[{"id":"1.168217555","rc":[{"batb":[[2,4.2,60.2]],"batl":[[0,5.1,10.08],[1,5.4,14.08]],"ltp":5.2,"tv":21.28,"id":12984951},{"batb":[[0,1.63,73.67],[1,1.62,67.6],[2,1.55,75.62]],"batl":[[0,1.68,71.12]],"ltp":0.0,"tv":0.0,"id":12984952},{"batb":[[0,5.6,43.8]],"batl":[[0,6.8,25.37]],"ltp":5.2,"tv":21.28,"id":16574984}]}]}
{"op":"mcm","clk":"1009380371","pt":1580643891261,"mc":[{"id":"1.168217555","rc":[{"batl":[[0,5.1,26.61]],"ltp":5.2,"tv":21.28,"id":12984951},{"batb":[[1,1.62,97.34],[2,1.56,34.38]],"batl":[[1,1.86,21.01]],"ltp":0.0,"tv":0.0,"id":12984952},{"batl":[[0,5.8,12.12],[1,6.4,10.39],[2,6.8,6.72]],"ltp":5.2,"tv":21.28,"id":16574984}]}]}
{"op":"mcm","clk":"1009386164","pt":1580643926998,"mc":[{"id":"1.168217555","rc":[{"batb":[[1,4.2,12.6],[2,3.95,23.45]],"ltp":5.2,"tv":21.28,"id":12984951},{"batb":[[0,1.62,29.74],[1,1.56,34.38],[2,1.55,75.62]],"ltp":0.0,"tv":0.0,"id":12984952},{"batb":[[0,5.6,8.4],[1,5.1,12.67],[2,4.5,17.31]],"ltp":5.2,"tv":21.28,"id":16574984}]}]}
{"op":"mcm","clk":"1009386726","pt":1580643930511,"mc":[{"id":"1.168217555","rc":[{"batb":[[0,4.2,12.6],[1,3.95,23.45],[2,3.8,32.07]],"batl":[[0,5.1,10.08],[1,5.4,373.87]],"ltp":5.2,"tv":21.28,"id":12984951},{"batb":[[0,1.56,136.86],[1,1.55,155.6],[2,1.01,0.51]],"batl":[[0,1.68,42.01]],"ltp":0.0,"tv":0.0,"id":12984952},{"batb":[[1,4.9,37.57],[2,4.8,36.26]],"batl":[[0,6.4,10.39],[1,6.8,6.72],[2,6.8,0]],"ltp":5.2,"tv":21.28,"id":16574984}]}]}
{"op":"mcm","clk":"1009386853","pt":1580643931418,"mc":[{"id":"1.168217555","rc":[{"batb":[[0,3.95,23.45],[1,3.8,32.07],[2,3.75,31.4]],"batl":[[0,5.4,14.08],[1,5.4,0]],"ltp":5.2,"tv":21.28,"id":12984951},{"batb":[[1,1.55,79.98]],"batl":[[0,1.86,21.01],[1,1.86,0]],"ltp":0.0,"tv":0.0,"id":12984952},{"batb":[[0,4.9,37.57],[1,4.8,36.26],[2,4.5,17.31]],"batl":[[1,6.8,0]],"ltp":5.2,"tv":21.28,"id":16574984}]}]}
{"op":"mcm","clk":"1009387909","pt":1580643938122,"mc":[{"id":"1.168217555","rc":[{"batb":[[1,1.01,0.51],[2,3.75,0]],"ltp":5.2,"tv":21.28,"id":12984951},{"batb":[[0,4.5,17.31],[1,1.01,0.51],[2,4.5,0]],"ltp":5.2,"tv":21.28,"id":16574984}]}]}
{"op":"mcm","clk":"1009388423","pt":1580643941289,"mc":[{"id":"1.168217555","rc":[{"batb":[[0,4.5,60.96],[1,4.4,42.12],[2,3.95,23.45]],"ltp":5.2,"tv":21.28,"id":12984951},{"batb":[[0,6,33.13],[1,5.9,22.88],[2,4.5,17.31]],"ltp":5.2,"tv":21.28,"id":16574984}]}]}
{"op":"mcm","clk":"1009388595","pt":1580643942422,"mc":[{"id":"1.168217555","rc":[{"batb":[[0,4.7,15.19],[1,4.5,72.72],[2,4.4,42.12]],"batl":[[0,5.4,23.33],[1,5.6,12.98]],"ltp":5.2,"tv":21.28,"id":12984951},{"batb":[[2,1.51,38.55]],"batl":[[0,1.61,42.01],[1,1.62,33.52],[2,1.74,26.2]],"ltp":0.0,"tv":0.0,"id":12984952},{"batb":[[2,5.8,8.4]],"batl":[[1,6.8,17.86],[2,7.4,5.88]],"ltp":5.2,"tv":21.28,"id":16574984},{"batb":[[0,9,15.12],[1,1.01,0.51]],"ltp":5.1,"tv":4.54,"id":16574983}]}]}
{"op":"mcm","clk":"1009390151","pt":1580643952346,"mc":[{"id":"1.168217555","rc":[{"batb":[[1,4.5,11.76],[2,4.3,19.04]],"ltp":5.2,"tv":21.28,"id":12984951},{"batb":[[0,1.56,34.38],[1,1.51,38.55],[2,1.49,85.7]],"ltp":0.0,"tv":0.0,"id":12984952},{"batb":[[0,5.8,8.4],[1,5.5,10.78],[2,4.9,14.24]],"ltp":5.2,"tv":21.28,"id":16574984}]}]}
{"op":"mcm","clk":"1009390324","pt":1580643953446,"mc":[{"id":"1.168217555","rc":[{"batb":[[0,4.3,19.04],[1,1.01,0.51],[2,4.3,0]],"batl":[[0,5.6,12.98],[1,5.6,0]],"ltp":5.2,"tv":21.28,"id":12984951},{"batb":[[0,1.51,38.55],[1,1.01,0.51],[2,1.49,0]],"batl":[[0,1.74,26.2],[1,1.62,0],[2,1.74,0]],"ltp":0.0,"tv":0.0,"id":12984952},{"batb":[[0,4.9,14.24],[1,1.01,0.51],[2,4.9,0]],"batl":[[0,6.8,17.86],[1,6.8,0],[2,7.4,0]],"ltp":5.2,"tv":21.28,"id":16574984}]}]}
{"op":"mcm","clk":"1009390654","pt":1580643955347,"mc":[{"id":"1.168217555","rc":[{"batb":[[1,4.1,59.81],[2,4,52.71]],"ltp":5.2,"tv":21.28,"id":12984951},{"batb":[[0,1.51,181.68],[1,1.5,91.34],[2,1.01,0.51]],"ltp":0.0,"tv":0.0,"id":12984952},{"batb":[[0,5.4,26.57],[1,5.3,29.15],[2,4.9,14.24]],"ltp":5.2,"tv":21.28,"id":16574984}]}]}
{"op":"mcm","clk":"1009391088","pt":1580643958129,"mc":[{"id":"1.168217555","rc":[{"batb":[[0,1.51,38.55],[1,1.01,0.51],[2,1.01,0]],"ltp":0.0,"tv":0.0,"id":12984952}]}]}
{"op":"mcm","clk":"1009391592","pt":1580643961350,"mc":[{"id":"1.168217555","rc":[{"batb":[[0,1.67,63.27],[1,1.66,61.87],[2,1.51,38.55]],"ltp":0.0,"tv":0.0,"id":12984952}]}]}
{"op":"mcm","clk":"1009391753","pt":1580643962351,"mc":[{"id":"1.168217555","rc":[{"batb":[[1,4.1,73.25]],"batl":[[0,4.9,18.1],[1,5,10.08],[2,5.3,15.11]],"ltp":5.2,"tv":21.28,"id":12984951},{"batb":[[0,1.67,89.94],[2,1.59,32.18]],"batl":[[0,1.72,42.01],[1,1.74,26.2],[2,1.98,17.39]],"ltp":0.0,"tv":0.0,"id":12984952},{"batb":[[0,5.4,35.81]],"batl":[[0,5.5,13.61],[1,6,11.41],[2,6.6,6.72]],"ltp":5.2,"tv":21.28,"id":16574984}]}]}
{"op":"mcm","clk":"1009393397","pt":1580643972454,"mc":[{"id":"1.168217555","rc":[{"batb":[[0,4.1,13.44],[1,3.75,13.45],[2,1.01,0.51]],"batl":[[0,5,10.08],[1,5.3,15.11],[2,5.3,0]],"ltp":5.2,"tv":21.28,"id":12984951},{"batb":[[0,1.59,32.18],[1,1.57,73.1],[2,1.01,0.51]],"batl":[[1,1.98,17.39],[2,1.98,0]],"ltp":0.0,"tv":0.0,"id":12984952},{"batb":[[0,5.4,9.24],[1,4.1,20.69],[2,1.01,0.51]],"batl":[[0,6,11.41],[1,6.6,6.72],[2,6.6,0]],"ltp":5.2,"tv":21.28,"id":16574984}]}]}
{"op":"mcm","clk":"1009393541","pt":1580643973463,"mc":[{"id":"1.168217555","rc":[{"batb":[[0,3.75,13.45],[1,1.01,0.51],[2,1.01,0]],"batl":[[0,5.3,15.11],[1,5.3,0]],"ltp":5.2,"tv":21.28,"id":12984951},{"batb":[[1,1.01,0.51],[2,1.01,0]],"batl":[[0,1.98,17.39],[1,1.98,0]],"ltp":0.0,"tv":0.0,"id":12984952},{"batb":[[0,4.1,20.69],[1,1.01,0.51],[2,1.01,0]],"batl":[[1,6.6,0]],"ltp":5.2,"tv":21.28,"id":16574984},{"batb":[[0,1.01,0.51],[1,1.01,0]],"ltp":5.1,"tv":4.54,"id":16574983}]}]}
{"op":"mcm","clk":"1009393818","pt":1580643975436,"mc":[{"id":"1.168217555","rc":[{"batb":[[1,1.58,66.66],[2,1.57,75.98]],"ltp":0.0,"tv":0.0,"id":12984952}]}]}
{"op":"mcm","clk":"1009394220","pt":1580643978443,"mc":[{"id":"1.168217555","rc":[{"batb":[[0,4.6,15.82],[1,4.5,50.52],[2,4.4,42.5]],"batl":[[1,5.4,9.24],[2,5.6,13.22]],"ltp":5.2,"tv":21.28,"id":12984951},{"batl":[[0,1.63,42.01],[1,1.65,31.47],[2,1.8,23.37]],"ltp":0.0,"tv":0.0,"id":12984952},{"batb":[[0,5.9,24.9],[1,5.8,23.88],[2,5.7,8.4]],"batl":[[1,6.6,19.04],[2,7.2,6.72]],"ltp":5.2,"tv":21.28,"id":16574984}]}]}
{"op":"mcm","clk":"1009395310","pt":1580643986461,"mc":[{"id":"1.168217555","rc":[{"batb":[[1,4.5,11.76],[2,4.1,20.93]],"ltp":5.2,"tv":21.28,"id":12984951},{"batb":[[1,1.52,37.22],[2,1.5,84.02]],"ltp":0.0,"tv":0.0,"id":12984952},{"batb":[[0,5.7,8.4],[1,5.3,11.88],[2,4.6,16.05]],"ltp":5.2,"tv":21.28,"id":16574984}]}]}
{"op":"mcm","clk":"1009395429","pt":1580643987369,"mc":[{"id":"1.168217555","rc":[{"batb":[[0,4.1,20.93],[1,1.01,0.51],[2,4.1,0]],"batl":[[0,5.6,13.22],[1,5.4,0],[2,5.6,0]],"ltp":5.2,"tv":21.28,"id":12984951},{"batb":[[0,1.52,37.22],[1,1.01,0.51],[2,1.5,0]],"batl":[[0,1.8,23.37],[1,1.65,0],[2,1.8,0]],"ltp":0.0,"tv":0.0,"id":12984952},{"batb":[[0,4.6,15.89],[1,1.01,0.51],[2,4.6,0]],"batl":[[0,6.6,18.8],[1,6.6,0],[2,7.2,0]],"ltp":5.2,"tv":21.28,"id":16574984}]}]}
{"op":"mcm","clk":"1009395705","pt":1580643989387,"mc":[{"id":"1.168217555","rc":[{"batb":[[1,4,44.75],[2,3.95,27.64]],"ltp":5.2,"tv":21.28,"id":12984951},{"batb":[[0,1.52,123.66],[1,1.51,88.6],[2,1.01,0.51]],"ltp":0.0,"tv":0.0,"id":12984952},{"batb":[[0,5.2,23.06],[1,5.1,31.83],[2,4.6,15.89]],"ltp":5.2,"tv":21.28,"id":16574984}]}]}
{"op":"mcm","clk":"1009398582","pt":1580644008098,"mc":[{"id":"1.168217555","rc":[{"batb":[[0,9,14.28],[1,1.01,0.51]],"ltp":5.1,"tv":4.54,"id":16574983}]}]}
{"op":"mcm","clk":"1009401392","pt":1580644028826,"mc":[{"id":"1.168217555","rc":[{"batb":[[0,1.52,37.22],[1,1.01,0.51],[2,1.01,0]],"ltp":0.0,"tv":0.0,"id":12984952}]}]}
{"op":"mcm","clk":"1009401844","pt":1580644031511,"mc":[{"id":"1.168217555","rc":[{"batl":[[0,5.7,150.94],[1,6.6,18.8]],"ltp":5.2,"tv":21.28,"id":16574984}]}]}
{"op":"mcm","clk":"1009402026","pt":1580644032420,"mc":[{"id":"1.168217555","rc":[{"batb":[[1,4,58.19]],"batl":[[0,4.7,19.91],[1,4.8,10.92],[2,5.2,15.34]],"ltp":5.2,"tv":21.28,"id":12984951},{"batb":[[0,1.73,23.92],[1,1.71,78.14],[2,1.69,115.53]],"batl":[[0,1.75,42.01],[1,1.8,23.37],[2,2.18,26.36]],"ltp":0.0,"tv":0.0,"id":12984952},{"batb":[[0,5.2,32.3]],"batl":[[0,5.3,15.19],[1,5.9,11.8],[2,6.4,7.56]],"ltp":5.2,"tv":21.28,"id":16574984}]}]}
{"op":"mcm","clk":"1009402889","pt":1580644038431,"mc":[{"id":"1.168217555","rc":[{"batb":[[1,1.6,101.05],[2,1.01,0.51]],"ltp":0.0,"tv":0.0,"id":12984952},{"batb":[[0,1.01,0.51],[1,1.01,0]],"ltp":5.1,"tv":4.54,"id":16574983}]}]}
{"op":"mcm","clk":"1009403308","pt":1580644041454,"mc":[{"id":"1.168217555","rc":[{"batb":[[1,4,67.92]],"ltp":5.2,"tv":21.28,"id":12984951},{"batb":[[1,1.7,107.2],[2,1.68,118.2]],"ltp":0.0,"tv":0.0,"id":12984952},{"batb":[[0,5.2,39.19]],"ltp":5.2,"tv":21.28,"id":16574984}]}]}
{"op":"mcm","clk":"1009405388","pt":1580644055458,"mc":[{"id":"1.168217555","rc":[{"batb":[[1,4,13.44],[2,3.4,16.92]],"ltp":5.2,"tv":21.28,"id":12984951},{"batb":[[1,1.6,101.05],[2,1.01,0.51]],"ltp":0.0,"tv":0.0,"id":12984952},{"batb":[[0,5.2,9.24],[1,4.6,15.89],[2,3.85,25.1]],"ltp":5.2,"tv":21.28,"id":16574984}]}]}
{"op":"mcm","clk":"1009405498","pt":1580644056256,"mc":[{"id":"1.168217555","rc":[{"batb":[[0,4,13.44],[1,3.4,16.92],[2,1.01,0.51]],"batl":[[0,4.8,10.92],[1,5.2,15.34],[2,5.2,0]],"ltp":5.2,"tv":21.28,"id":12984951},{"batb":[[0,1.6,101.05],[1,1.01,0.51],[2,1.01,0]],"batl":[[1,2.18,26.36],[2,2.18,0]],"ltp":0.0,"tv":0.0,"id":12984952},{"batb":[[1,3.85,24.86],[2,1.01,0.51]],"batl":[[0,5.9,11.64],[1,6.4,7.56],[2,6.4,0]],"ltp":5.2,"tv":21.28,"id":16574984}]}]}
{"op":"mcm","clk":"1009405655","pt":1580644057429,"mc":[{"id":"1.168217555","rc":[{"batb":[[0,3.4,16.92],[1,1.01,0.51],[2,1.01,0]],"batl":[[0,5.2,15.34],[1,5.2,0]],"ltp":5.2,"tv":21.28,"id":12984951},{"batb":[[0,1.6,31.32]],"batl":[[0,2.18,26.36],[1,2.18,0]],"ltp":0.0,"tv":0.0,"id":12984952},{"batb":[[0,3.85,24.86],[1,1.01,0.51],[2,1.01,0]],"batl":[[1,6.4,0]],"ltp":5.2,"tv":21.28,"id":16574984}]}]}
{"op":"mcm","clk":"1009405785","pt":1580644058342,"mc":[{"id":"1.168217555","rc":[{"batb":[[1,3.3,33.76],[2,3.25,44.58]],"ltp":5.2,"tv":21.28,"id":12984951},{"batb":[[1,1.57,116.07],[2,1.56,78.2]],"ltp":0.0,"tv":0.0,"id":12984952},{"batb":[[0,4.2,59.26],[1,4.1,51.86],[2,3.85,24.86]],"ltp":5.2,"tv":21.28,"id":16574984}]}]}
{"op":"mcm","clk":"1009405896","pt":1580644059186,"mc":[{"id":"1.168217555","rc":[{"batb":[[1,1.01,0.51],[2,3.25,0]],"ltp":5.2,"tv":21.28,"id":12984951},{"batb":[[1,1.01,0.51],[2,1.56,0]],"ltp":0.0,"tv":0.0,"id":12984952},{"batb":[[0,3.85,24.86],[1,1.01,0.51],[2,3.85,0]],"ltp":5.2,"tv":21.28,"id":16574984}]}]}
{"op":"mcm","clk":"1009406334","pt":1580644062446,"mc":[{"id":"1.168217555","rc":[{"batb":[[0,3.85,42.87],[1,3.8,30.42],[2,3.4,16.92]],"ltp":5.2,"tv":21.28,"id":12984951},{"batb":[[0,1.76,90.47],[1,1.74,104.6],[2,1.6,31.32]],"ltp":0.0,"tv":0.0,"id":12984952},{"batb":[[0,5,22.99],[1,4.9,34.94],[2,3.85,24.86]],"ltp":5.2,"tv":21.28,"id":16574984}]}]}
{"op":"mcm","clk":"1009406607","pt":1580644063973,"mc":[{"id":"1.168217555","rc":[{"batb":[[0,3.4,16.92],[1,1.01,0.51],[2,3.4,0]],"ltp":5.2,"tv":21.28,"id":12984951},{"batb":[[0,1.6,31.32],[1,1.01,0.51],[2,1.6,0]],"ltp":0.0,"tv":0.0,"id":12984952},{"batb":[[0,3.85,24.86],[1,1.01,0.51],[2,3.85,0]],"ltp":5.2,"tv":21.28,"id":16574984}]}]}
{"op":"mcm","clk":"1009407016","pt":1580644066978,"mc":[{"id":"1.168217555","rc":[{"batb":[[1,3.3,33.76],[2,3.25,44.58]],"ltp":5.2,"tv":21.28,"id":12984951},{"batb":[[1,1.57,116.07],[2,1.56,78.2]],"ltp":0.0,"tv":0.0,"id":12984952},{"batb":[[0,4.2,59.26],[1,4.1,51.86],[2,3.85,24.86]],"ltp":5.2,"tv":21.28,"id":16574984}]}]}
{"op":"mcm","clk":"1009407925","pt":1580644074191,"mc":[{"id":"1.168217555","rc":[{"batb":[[0,6,12.6],[1,1.01,0.51]],"ltp":5.1,"tv":4.54,"id":16574983}]}]}
{"op":"mcm","clk":"1009408090","pt":1580644075355,"mc":[{"id":"1.168217555","rc":[{"batb":[[1,1.01,0.51],[2,1.56,0]],"ltp":0.0,"tv":0.0,"id":12984952}]}]}
{"op":"mcm","clk":"1009408488","pt":1580644078394,"mc":[{"id":"1.168217555","rc":[{"batb":[[1,3.3,51.4]],"batl":[[0,3.7,16.44],[1,3.9,14.28],[2,4.6,20.61]],"ltp":5.2,"tv":21.28,"id":12984951},{"trd":[[2.06,54.45]],"batb":[[0,2.04,71.97],[1,2.02,64.83],[2,1.85,48.73]],"batl":[[0,2.06,12.27],[1,2.18,26.36],[2,3.45,20.46]],"ltp":2.06,"tv":54.44,"id":12984952},{"trd":[[4.4,23.53]],"batl":[[0,4.4,11.76],[1,4.7,1.79],[2,5.1,16.05]],"ltp":4.4,"tv":44.81,"id":16574984}],"tv":125.08}]}
{"op":"mcm","clk":"1009408570","pt":1580644078888,"mc":[{"id":"1.168217555","rc":[{"batl":[[1,4.6,20.61],[2,4.6,0]],"ltp":5.2,"tv":21.28,"id":12984951},{"batb":[[2,1.75,22.66]],"batl":[[0,2.18,26.36],[1,3.45,20.46],[2,3.45,0]],"ltp":2.06,"tv":54.44,"id":12984952},{"batl":[[1,5.1,16.05],[2,5.1,0]],"ltp":4.4,"tv":44.81,"id":16574984}]}]}
{"op":"mcm","clk":"1009408981","pt":1580644082084,"mc":[{"id":"1.168217555","rc":[{"batl":[[1,3.8,14.28],[2,4.6,20.61]],"ltp":5.2,"tv":21.28,"id":12984951},{"batb":[[2,1.91,45.37]],"batl":[[0,2.1,37.81],[1,2.18,26.36],[2,3.45,20.46]],"ltp":2.06,"tv":54.44,"id":12984952},{"batb":[[0,4.2,71.86]],"batl":[[1,5,10.08],[2,5.1,16.05]],"ltp":4.4,"tv":44.81,"id":16574984}]}]}
{"op":"mcm","clk":"1009410550","pt":1580644094415,"mc":[{"id":"1.168217555","rc":[{"batb":[[0,3.3,17.64],[1,2.56,14.16],[2,1.01,0.51]],"batl":[[0,3.8,14.28],[1,4.6,20.61],[2,4.6,0]],"ltp":5.2,"tv":21.28,"id":12984951},{"batb":[[0,1.91,45.37],[1,1.75,22.66],[2,1.01,0.51]],"batl":[[1,3.45,20.46],[2,3.45,0]],"ltp":2.06,"tv":54.44,"id":12984952},{"batb":[[0,4.2,12.6],[1,3,23.21],[2,1.01,0.51]],"batl":[[0,5,10.08],[1,5.1,16.05],[2,5.1,0]],"ltp":4.4,"tv":44.81,"id":16574984}]}]}
{"op":"mcm","clk":"1009410706","pt":1580644095481,"mc":[{"id":"1.168217555","rc":[{"batb":[[0,2.56,14.16],[1,1.01,0.51],[2,1.01,0]],"batl":[[0,4.6,20.61],[1,4.6,0]],"ltp":5.2,"tv":21.28,"id":12984951},{"batb":[[0,1.75,22.66],[1,1.01,0.51],[2,1.01,0]],"batl":[[0,3.45,20.46],[1,3.45,0]],"ltp":2.06,"tv":54.44,"id":12984952},{"batb":[[0,3,23.21],[1,1.01,0.51],[2,1.01,0]],"batl":[[0,5.1,16.05],[1,5.1,0]],"ltp":4.4,"tv":44.81,"id":16574984}]}]}
{"op":"mcm","clk":"1009410980","pt":1580644097492,"mc":[{"id":"1.168217555","rc":[{"batl":[[1,4.7,20.38]],"ltp":5.2,"tv":21.28,"id":12984951},{"batb":[[1,1.71,23.68],[2,1.01,0.51]],"batl":[[0,3.35,21.48],[1,3.45,20.46]],"ltp":2.06,"tv":54.44,"id":12984952},{"batb":[[0,3.1,21.87],[1,3,23.21],[2,1.01,0.51]],"batl":[[1,5.4,15.03]],"ltp":4.4,"tv":44.81,"id":16574984}]}]}
{"op":"mcm","clk":"1009411004","pt":1580644097708,"mc":[{"id":"1.168217555","rc":[{"batl":[[0,4.7,20.38],[1,4.7,0]],"ltp":5.2,"tv":21.28,"id":12984951},{"batb":[[0,1.71,23.68],[1,1.01,0.51],[2,1.01,0]],"batl":[[1,3.45,0]],"ltp":2.06,"tv":54.44,"id":12984952},{"batb":[[1,1.01,0.51],[2,1.01,0]],"batl":[[0,5.4,15.03],[1,5.4,0]],"ltp":4.4,"tv":44.81,"id":16574984}]}]}
{"op":"mcm","clk":"1009411197","pt":1580644099331,"mc":[{"id":"1.168217555","rc":[{"batb":[[0,3.05,83.63],[1,3,54.04],[2,2.56,14.16]],"ltp":5.2,"tv":21.28,"id":12984951},{"batb":[[0,2.2,61.2],[1,2.18,51.75],[2,1.71,23.68]],"ltp":2.06,"tv":54.44,"id":12984952},{"batb":[[0,4,26.69],[1,3.95,28.88],[2,3.1,21.87]],"ltp":4.4,"tv":44.81,"id":16574984}]}]}
{"op":"mcm","clk":"1009411611","pt":1580644102795,"mc":[{"id":"1.168217555","rc":[{"batb":[[0,2.56,14.16],[1,1.01,0.51],[2,2.56,0]],"ltp":5.2,"tv":21.28,"id":12984951},{"batb":[[0,1.71,23.68],[1,1.01,0.51],[2,1.71,0]],"ltp":2.06,"tv":54.44,"id":12984952},{"batb":[[0,3.1,21.87],[1,1.01,0.51],[2,3.1,0]],"ltp":4.4,"tv":44.81,"id":16574984}]}]}
{"op":"mcm","clk":"1009411943","pt":1580644105810,"mc":[{"id":"1.168217555","rc":[{"batb":[[1,2.46,58.22],[2,2.42,76.84]],"ltp":5.2,"tv":21.28,"id":12984951},{"batb":[[0,1.72,89.91],[1,1.71,23.68],[2,1.7,113.35]],"ltp":2.06,"tv":54.44,"id":12984952},{"batb":[[0,3.2,54.72],[1,3.15,49.46],[2,3.1,21.87]],"ltp":4.4,"tv":44.81,"id":16574984}]}]}
{"op":"mcm","clk":"1009412481","pt":1580644111423,"mc":[{"id":"1.168217555","rc":[{"batb":[[1,1.01,0.51],[2,2.42,0]],"ltp":5.2,"tv":21.28,"id":12984951},{"batb":[[0,3.1,21.87],[1,1.01,0.51],[2,3.1,0]],"ltp":4.4,"tv":44.81,"id":16574984}]}]}
{"op":"mcm","clk":"1009412768","pt":1580644114410,"mc":[{"id":"1.168217555","rc":[{"batb":[[0,4,53.63],[1,3.95,27.8],[2,2.56,14.16]],"batl":[[0,4.7,31.3]],"ltp":5.2,"tv":21.28,"id":12984951},{"batl":[[0,1.8,42.01],[1,3.35,21.48]],"ltp":2.06,"tv":54.44,"id":12984952},{"batb":[[0,5.1,24.87],[1,5,33.29],[2,4.8,10.92]],"batl":[[1,5.7,8.4]],"ltp":4.4,"tv":44.81,"id":16574984}]}]}
{"op":"mcm","clk":"1009412859","pt":1580644115204,"mc":[{"id":"1.168217555","rc":[{"batb":[[0,4.1,21.48],[1,4,53.63],[2,3.95,27.8]],"batl":[[1,5.3,15.66]],"ltp":5.2,"tv":21.28,"id":12984951},{"batl":[[0,1.78,23.29],[1,1.8,42.01],[2,2.16,26.2]],"ltp":2.06,"tv":54.44,"id":12984952},{"batb":[[2,4.9,10.08]],"batl":[[2,6.2,11.72]],"ltp":4.4,"tv":44.81,"id":16574984}]}]}
{"op":"mcm","clk":"1009414826","pt":1580644133451,"mc":[{"id":"1.168217555","rc":[{"batb":[[0,4,13.44],[1,3.4,17.23],[2,1.01,0.51]],"batl":[[0,4.7,10.92]],"ltp":5.2,"tv":21.28,"id":12984951},{"batb":[[0,1.67,62.17],[1,1.58,31.16],[2,1.01,0.51]],"batl":[[0,1.8,42.01],[1,2.16,26.2],[2,2.16,0]],"ltp":2.06,"tv":54.44,"id":12984952},{"batb":[[0,4.9,10.08],[1,3.9,24.78],[2,1.01,0.51]],"batl":[[0,5.7,8.4],[1,6.2,11.72],[2,6.2,0]],"ltp":4.4,"tv":44.81,"id":16574984}]}]}
{"op":"mcm","clk":"1009414843","pt":1580644133569,"mc":[{"id":"1.168217555","rc":[{"batb":[[0,3.4,17.23],[1,1.01,0.51],[2,1.01,0]],"batl":[[0,5.3,15.66],[1,5.3,0]],"ltp":5.2,"tv":21.28,"id":12984951},{"batb":[[0,1.58,31.16],[1,1.01,0.51],[2,1.01,0]],"batl":[[0,2.16,26.2],[1,2.16,0]],"ltp":2.06,"tv":54.44,"id":12984952},{"batb":[[0,3.9,24.78],[1,1.01,0.51],[2,1.01,0]],"batl":[[0,6.2,11.72],[1,6.2,0]],"ltp":4.4,"tv":44.81,"id":16574984}]}]}
{"op":"mcm","clk":"1009415081","pt":1580644135459,"mc":[{"id":"1.168217555","rc":[{"batb":[[1,3.25,68.27],[2,3.2,46.05]],"ltp":5.2,"tv":21.28,"id":12984951},{"batb":[[0,1.58,167.31],[1,1.57,76.4],[2,1.01,0.51]],"ltp":2.06,"tv":54.44,"id":12984952},{"batb":[[0,4.1,69.01],[1,4,54.68],[2,3.9,24.78]],"ltp":4.4,"tv":44.81,"id":16574984}]}]}
{"op":"mcm","clk":"1009415163","pt":1580644136243,"mc":[{"id":"1.168217555","rc":[{"batl":[[0,5.2,15.74],[1,5.3,15.66]],"ltp":5.2,"tv":21.28,"id":12984951}]}]}
{"op":"mcm","clk":"1009415189","pt":1580644136554,"mc":[{"id":"1.168217555","rc":[{"batl":[[1,5.3,0]],"ltp":5.2,"tv":21.28,"id":12984951},{"batl":[[0,2.16,26.04]],"ltp":2.06,"tv":54.44,"id":12984952}]}]}
{"op":"mcm","clk":"1009415523","pt":1580644139440,"mc":[{"id":"1.168217555","rc":[{"batb":[[1,1.01,0.51],[2,3.2,0]],"ltp":5.2,"tv":21.28,"id":12984951},{"batb":[[0,3.9,24.78],[1,1.01,0.51],[2,3.9,0]],"ltp":4.4,"tv":44.81,"id":16574984}]}]}
{"op":"mcm","clk":"1009415880","pt":1580644142453,"mc":[{"id":"1.168217555","rc":[{"batb":[[0,4.6,16.44],[1,4.5,56.32],[2,4.4,42.6]],"batl":[[1,5.3,9.24],[2,5.7,13.38]],"ltp":5.2,"tv":21.28,"id":12984951},{"batb":[[2,1.55,75.62]],"batl":[[0,1.64,30.53],[1,1.66,42.01],[2,1.81,21.95]],"ltp":2.06,"tv":54.44,"id":12984952},{"batb":[[0,5.7,37.63],[1,5.6,25.66],[2,5.4,9.24]],"batl":[[1,6.4,7.56],[2,6.8,19.12]],"ltp":4.4,"tv":44.81,"id":16574984}]}]}
{"op":"mcm","clk":"1009418124","pt":1580644162295,"mc":[{"id":"1.168217555","rc":[{"batb":[[0,4.5,11.76],[1,4,22.27],[2,1.01,0.51]],"batl":[[0,5.3,9.24],[1,5.7,13.38],[2,5.7,0]],"ltp":5.2,"tv":21.28,"id":12984951},{"batb":[[0,1.55,75.62],[1,1.51,36.9],[2,1.01,0.51]],"batl":[[0,1.66,42.01],[1,1.81,21.95],[2,1.81,0]],"ltp":2.06,"tv":54.44,"id":12984952},{"batb":[[0,5.4,9.24],[1,4.6,16.92],[2,1.01,0.51]],"batl":[[0,6.4,7.56],[1,6.8,19.12],[2,6.8,0]],"ltp":4.4,"tv":44.81,"id":16574984}]}]}
{"op":"mcm","clk":"1009418305","pt":1580644164181,"mc":[{"id":"1.168217555","rc":[{"batb":[[0,4,22.27],[1,1.01,0.51],[2,1.01,0]],"batl":[[0,5.7,13.38],[1,5.7,0]],"ltp":5.2,"tv":21.28,"id":12984951},{"batb":[[0,1.51,36.9],[1,1.01,0.51],[2,1.01,0]],"batl":[[0,1.81,21.95],[1,1.81,0]],"ltp":2.06,"tv":54.44,"id":12984952},{"batb":[[0,4.6,16.92],[1,1.01,0.51],[2,1.01,0]],"batl":[[0,6.8,19.12],[1,6.8,0]],"ltp":4.4,"tv":44.81,"id":16574984}]}]}
{"op":"mcm","clk":"1009418415","pt":1580644165288,"mc":[{"id":"1.168217555","rc":[{"batb":[[1,3.95,50.87],[2,3.9,28.56]],"ltp":5.2,"tv":21.28,"id":12984951},{"batb":[[0,1.52,86.13],[1,1.51,125.67],[2,1.01,0.51]],"ltp":2.06,"tv":54.44,"id":12984952},{"batb":[[0,5,24.78],[1,4.9,34.84],[2,4.6,16.92]],"ltp":4.4,"tv":44.81,"id":16574984}]}]}
{"op":"mcm","clk":"1009418958","pt":1580644170307,"mc":[{"id":"1.168217555","rc":[{"batb":[[0,1.01,0.51],[1,1.01,0]],"ltp":5.1,"tv":4.54,"id":16574983}]}]}
{"op":"mcm","clk":"1009419835","pt":1580644178497,"mc":[{"id":"1.168217555","rc":[{"batb":[[1,1.01,0.51],[2,3.9,0]],"ltp":5.2,"tv":21.28,"id":12984951},{"batb":[[0,4.6,16.92],[1,1.01,0.51],[2,4.6,0]],"ltp":4.4,"tv":44.81,"id":16574984}]}]}
{"op":"mcm","clk":"1009420139","pt":1580644181483,"mc":[{"id":"1.168217555","rc":[{"batb":[[0,4.9,20.79],[1,4.8,35.24],[2,4,22.27]],"ltp":5.2,"tv":21.28,"id":12984951},{"batb":[[0,6.2,29.44],[1,6,43.53],[2,4.6,16.92]],"ltp":4.4,"tv":44.81,"id":16574984}]}]}
{"op":"mcm","clk":"1009420245","pt":1580644182427,"mc":[{"id":"1.168217555","rc":[{"batb":[[0,4.9,34.72],[1,4.8,46.16],[2,4.5,16.92]],"batl":[[0,5.7,21.78],[1,6.8,18.41]],"ltp":5.2,"tv":21.28,"id":12984951},{"batb":[[2,1.48,87.38]],"batl":[[0,1.57,35.96],[1,1.58,42.01],[2,1.66,29.66]],"ltp":2.06,"tv":54.44,"id":12984952},{"batb":[[2,5.9,8.4]],"batl":[[1,7.2,6.72],[2,8,13.14]],"ltp":4.4,"tv":44.81,"id":16574984}]}]}
{"op":"mcm","clk":"1009423417","pt":1580644212445,"mc":[{"id":"1.168217555","rc":[{"batb":[[0,4.8,10.92],[1,4.5,16.92],[2,1.01,0.51]],"batl":[[0,5.7,8.4]],"ltp":5.2,"tv":21.28,"id":12984951},{"batb":[[0,1.48,87.38],[1,1.39,51.54],[2,1.01,0.51]],"batl":[[0,1.58,42.01],[1,1.66,29.66],[2,1.66,0]],"ltp":2.06,"tv":54.44,"id":12984952},{"batb":[[0,5.9,8.4],[1,5.3,12.43],[2,1.01,0.51]],"batl":[[0,7.2,6.72],[1,8,13.14],[2,8,0]],"ltp":4.4,"tv":44.81,"id":16574984}]}]}
{"op":"mcm","clk":"1009423541","pt":1580644213552,"mc":[{"id":"1.168217555","rc":[{"batb":[[0,4.5,16.92],[1,1.01,0.51],[2,1.01,0]],"batl":[[0,6.8,18.41],[1,6.8,0]],"ltp":5.2,"tv":21.28,"id":12984951},{"batb":[[0,1.39,51.54],[1,1.01,0.51],[2,1.01,0]],"batl":[[0,1.66,29.66],[1,1.66,0]],"ltp":2.06,"tv":54.44,"id":12984952},{"batb":[[0,5.3,12.43],[1,1.01,0.51],[2,1.01,0]],"batl":[[0,8,13.14],[1,8,0]],"ltp":4.4,"tv":44.81,"id":16574984}]}]}
{"op":"mcm","clk":"1009423929","pt":1580644217146,"mc":[{"id":"1.168217555","rc":[{"batb":[[0,5,34.42],[1,4.9,33.42],[2,4.5,16.92]],"ltp":5.2,"tv":21.28,"id":12984951},{"batb":[[0,1.49,153.16],[1,1.48,96.78],[2,1.39,51.54]],"ltp":2.06,"tv":54.44,"id":12984952},{"batb":[[0,6.4,26.51],[1,6.2,40.59],[2,5.3,12.43]],"ltp":4.4,"tv":44.81,"id":16574984}]}]}
{"op":"mcm","clk":"1009424455","pt":1580644222176,"mc":[{"id":"1.168217555","rc":[{"batb":[[0,4.5,16.92],[1,1.01,0.51],[2,4.5,0]],"ltp":5.2,"tv":21.28,"id":12984951},{"batb":[[0,1.39,51.54],[1,1.01,0.51],[2,1.39,0]],"ltp":2.06,"tv":54.44,"id":12984952},{"batb":[[0,5.3,12.43],[1,1.01,0.51],[2,5.3,0]],"ltp":4.4,"tv":44.81,"id":16574984}]}]}
{"op":"mcm","clk":"1009424712","pt":1580644225152,"mc":[{"id":"1.168217555","rc":[{"batb":[[1,4.4,63.74],[2,4.3,44.61]],"ltp":5.2,"tv":21.28,"id":12984951},{"batb":[[0,1.41,112.41],[1,1.4,122.93],[2,1.39,51.54]],"ltp":2.06,"tv":54.44,"id":12984952},{"batb":[[0,5.7,23.2],[1,5.6,25.87],[2,5.3,12.43]],"ltp":4.4,"tv":44.81,"id":16574984}]}]}
{"op":"mcm","clk":"1009425224","pt":1580644230100,"mc":[{"id":"1.168217555","rc":[{"batb":[[0,1.39,51.54],[1,1.01,0.51],[2,1.39,0]],"ltp":2.06,"tv":54.44,"id":12984952}]}]}
{"op":"mcm","clk":"1009425562","pt":1580644233469,"mc":[{"id":"1.168217555","rc":[{"batb":[[2,4.3,64.28]],"batl":[[0,5.2,16.21],[1,5.8,12.59]],"ltp":5.2,"tv":21.28,"id":12984951},{"batb":[[0,1.6,70.93],[1,1.59,102.94],[2,1.48,39.73]],"batl":[[1,1.73,25.49]],"ltp":2.06,"tv":54.44,"id":12984952},{"batl":[[0,6,11.96],[1,7,17.39]],"ltp":4.4,"tv":44.81,"id":16574984}]}]}
{"op":"mcm","clk":"1009425651","pt":1580644234460,"mc":[{"id":"1.168217555","rc":[{"batb":[[1,4.4,75.5]],"batl":[[1,5.3,9.24],[2,5.8,12.59]],"ltp":5.2,"tv":21.28,"id":12984951},{"batb":[[2,1.54,77.3]],"batl":[[0,1.66,71.67]],"ltp":2.06,"tv":54.44,"id":12984952},{"batb":[[2,5.5,9.24]],"batl":[[1,6.6,6.72],[2,7,17.39]],"ltp":4.4,"tv":44.81,"id":16574984}]}]}
{"op":"mcm","clk":"1009425979","pt":1580644237772,"mc":[{"id":"1.168217555","rc":[{"batb":[[0,8,15.96],[1,1.01,0.51]],"ltp":5.1,"tv":4.54,"id":16574983}]}]}
{"op":"mcm","clk":"1009426753","pt":1580644244510,"mc":[{"id":"1.168217555","rc":[{"batb":[[0,4.4,11.76],[1,4.3,19.67],[2,1.01,0.51]],"batl":[[0,5.3,9.24],[1,5.8,12.59],[2,5.8,0]],"ltp":5.2,"tv":21.28,"id":12984951},{"batb":[[0,1.54,77.3],[1,1.48,39.73],[2,1.01,0.51]],"batl":[[0,1.66,42.01]],"ltp":2.06,"tv":54.44,"id":12984952},{"batb":[[0,5.5,9.24],[1,4.9,14.48],[2,1.01,0.51]],"batl":[[0,6.6,6.72],[1,7,17.39],[2,7,0]],"ltp":4.4,"tv":44.81,"id":16574984}]}]}
{"op":"mcm","clk":"1009426883","pt":1580644245509,"mc":[{"id":"1.168217555","rc":[{"batb":[[0,4.3,19.67],[1,1.01,0.51],[2,1.01,0]],"batl":[[0,5.8,12.59],[1,5.8,0]],"ltp":5.2,"tv":21.28,"id":12984951},{"batb":[[0,1.48,39.73],[1,1.01,0.51],[2,1.01,0]],"batl":[[0,1.73,25.49],[1,1.73,0]],"ltp":2.06,"tv":54.44,"id":12984952},{"batb":[[0,4.9,14.48],[1,1.01,0.51],[2,1.01,0]],"batl":[[0,7,17.39],[1,7,0]],"ltp":4.4,"tv":44.81,"id":16574984}]}]}
{"op":"mcm","clk":"1009427043","pt":1580644246809,"mc":[{"id":"1.168217555","rc":[{"batb":[[1,4.2,33.03],[2,4.1,50.42]],"ltp":5.2,"tv":21.28,"id":12984951},{"batb":[[0,1.5,69.78],[1,1.49,93.6],[2,1.48,39.73]],"ltp":2.06,"tv":54.44,"id":12984952},{"batb":[[0,5.3,30.15],[1,5.2,30.41],[2,4.9,14.48]],"ltp":4.4,"tv":44.81,"id":16574984}]}]}
{"op":"mcm","clk":"1009427658","pt":1580644252003,"mc":[{"id":"1.168217555","rc":[{"batb":[[0,1.48,39.73],[1,1.01,0.51],[2,1.48,0]],"ltp":2.06,"tv":54.44,"id":12984952}]}]}
{"op":"mcm","clk":"1009427937","pt":1580644254522,"mc":[{"id":"1.168217555","rc":[{"batb":[[0,1.67,69.34],[1,1.66,61.98],[2,1.48,39.73]],"ltp":2.06,"tv":54.44,"id":12984952}]}]}
{"op":"mcm","clk":"1009428055","pt":1580644255420,"mc":[{"id":"1.168217555","rc":[{"batb":[[2,4.1,71.9]],"batl":[[0,4.8,18.73],[1,5.2,15.89],[2,5.8,12.59]],"ltp":5.2,"tv":21.28,"id":12984951},{"batb":[[1,1.66,87.95],[2,1.58,31.39]],"batl":[[1,1.79,22.74]],"ltp":2.06,"tv":54.44,"id":12984952},{"batl":[[0,5.6,13.85],[1,6.2,11.33],[2,7,17.39]],"ltp":4.4,"tv":44.81,"id":16574984}]}]}
{"op":"mcm","clk":"1009428184","pt":1580644256476,"mc":[{"id":"1.168217555","rc":[{"batb":[[1,4.2,45.63]],"batl":[[1,4.9,10.08],[2,5.2,15.89]],"ltp":5.2,"tv":21.28,"id":12984951},{"batb":[[2,1.6,69.74]],"batl":[[1,1.74,42.01],[2,1.79,22.74]],"ltp":2.06,"tv":54.44,"id":12984952},{"batb":[[1,5.2,39.65]],"batl":[[1,6.2,18.89],[2,7,0]],"ltp":4.4,"tv":44.81,"id":16574984}]}]}
{"op":"mcm","clk":"1009429506","pt":1580644267413,"mc":[{"id":"1.168217555","rc":[{"batb":[[0,1.01,0.51],[1,1.01,0]],"ltp":5.1,"tv":4.54,"id":16574983}]}]}
{"op":"mcm","clk":"1009430431","pt":1580644275430,"mc":[{"id":"1.168217555","rc":[{"batb":[[0,4.2,12.6],[1,4.1,21.48],[2,1.01,0.51]],"batl":[[0,4.9,10.08],[1,5.2,15.89],[2,5.2,0]],"ltp":5.2,"tv":21.28,"id":12984951},{"batb":[[0,1.6,69.74],[1,1.58,31.39],[2,1.01,0.51]],"batl":[[0,1.74,42.01],[1,1.79,22.74],[2,1.79,0]],"ltp":2.06,"tv":54.44,"id":12984952},{"batb":[[0,5.2,9.24],[1,4.7,16.44],[2,1.01,0.51]],"batl":[[0,6.2,18.89],[1,6.2,0]],"ltp":4.4,"tv":44.81,"id":16574984}]}]}
{"op":"mcm","clk":"1009430456","pt":1580644275643,"mc":[{"id":"1.168217555","rc":[{"batb":[[0,4.1,21.48],[1,1.01,0.51],[2,1.01,0]],"batl":[[0,5.2,15.89],[1,5.2,0]],"ltp":5.2,"tv":21.28,"id":12984951},{"batb":[[0,1.58,31.39],[1,1.01,0.51],[2,1.01,0]],"batl":[[0,1.79,22.74],[1,1.79,0]],"ltp":2.06,"tv":54.44,"id":12984952},{"batb":[[0,4.7,16.44],[1,1.01,0.51],[2,1.01,0]],"batl":[[0,6.2,11.33]],"ltp":4.4,"tv":44.81,"id":16574984}]}]}
{"op":"mcm","clk":"1009430694","pt":1580644277748,"mc":[{"id":"1.168217555","rc":[{"batb":[[1,4,56.78],[2,3.95,27.66]],"ltp":5.2,"tv":21.28,"id":12984951},{"batb":[[0,1.59,91.88],[1,1.58,105.79],[2,1.01,0.51]],"ltp":2.06,"tv":54.44,"id":12984952},{"batb":[[0,5,50.09],[1,4.9,34.46],[2,4.7,16.44]],"ltp":4.4,"tv":44.81,"id":16574984}]}]}
{"op":"mcm","clk":"1009431387","pt":1580644283837,"mc":[{"id":"1.168217555","rc":[{"batb":[[0,1.58,31.39],[1,1.01,0.51],[2,1.01,0]],"ltp":2.06,"tv":54.44,"id":12984952}]}]}
{"op":"mcm","clk":"1009431753","pt":1580644287467,"mc":[{"id":"1.168217555","rc":[{"batb":[[1,4,79.44]],"batl":[[0,4.7,20.38],[1,4.8,18.88],[2,5.2,15.89]],"ltp":5.2,"tv":21.28,"id":12984951},{"batb":[[0,1.72,99.05],[1,1.7,113.31],[2,1.66,26.28]],"batl":[[1,1.83,21.01]],"ltp":2.06,"tv":54.44,"id":12984952},{"batl":[[0,5.3,15.74],[1,5.7,13.38],[2,6.2,11.33]],"ltp":4.4,"tv":44.81,"id":16574984}]}]}
{"op":"mcm","clk":"1009431802","pt":1580644287734,"mc":[{"id":"1.168217555","rc":[{"batl":[[2,5.2,0]],"ltp":5.2,"tv":21.28,"id":12984951},{"batl":[[2,6.2,0]],"ltp":4.4,"tv":44.81,"id":16574984}]}]}
{"op":"mcm","clk":"1009431890","pt":1580644288542,"mc":[{"id":"1.168217555","rc":[{"batb":[[1,4,92.88]],"batl":[[0,4.7,31.3]],"ltp":5.2,"tv":21.28,"id":12984951},{"batb":[[2,1.66,89.29]],"batl":[[0,1.79,64.75]],"ltp":2.06,"tv":54.44,"id":12984952},{"batb":[[1,4.9,44.54]],"batl":[[2,5.9,8.4]],"ltp":4.4,"tv":44.81,"id":16574984}]}]}
{"op":"mcm","clk":"1009433470","pt":1580644302442,"mc":[{"id":"1.168217555","rc":[{"batb":[[0,4,36.1],[1,3.95,27.66],[2,1.01,0.51]],"batl":[[0,4.7,10.92]],"ltp":5.2,"tv":21.28,"id":12984951},{"batb":[[0,1.66,89.29],[1,1.01,0.51],[2,1.66,0]],"batl":[[0,1.79,42.01]],"ltp":2.06,"tv":54.44,"id":12984952},{"batb":[[0,4.9,44.54],[1,4.5,18.02],[2,1.01,0.51]],"batl":[[0,5.7,13.38],[1,5.9,8.4],[2,5.9,0]],"ltp":4.4,"tv":44.81,"id":16574984}]}]}
{"op":"mcm","clk":"1009433616","pt":1580644303551,"mc":[{"id":"1.168217555","rc":[{"batb":[[0,4,22.66]],"batl":[[0,4.8,18.88],[1,4.8,0]],"ltp":5.2,"tv":21.28,"id":12984951},{"batb":[[0,1.66,26.28]],"batl":[[0,1.83,21.01],[1,1.83,0]],"ltp":2.06,"tv":54.44,"id":12984952},{"batb":[[0,4.9,34.46]],"batl":[[1,5.9,0]],"ltp":4.4,"tv":44.81,"id":16574984}]}]}
{"op":"mcm","clk":"1009433845","pt":1580644305385,"mc":[{"id":"1.168217555","rc":[{"batb":[[1,3.95,48.96],[2,3.9,28.58]],"ltp":5.2,"tv":21.28,"id":12984951},{"batb":[[0,1.67,100.23],[1,1.66,88.33],[2,1.01,0.51]],"ltp":2.06,"tv":54.44,"id":12984952},{"batb":[[1,4.8,36.31],[2,4.5,18.02]],"ltp":4.4,"tv":44.81,"id":16574984}]}]}
{"op":"mcm","clk":"1009434047","pt":1580644307160,"mc":[{"id":"1.168217555","rc":[{"batb":[[0,1.66,26.28],[1,1.01,0.51],[2,1.01,0]],"ltp":2.06,"tv":54.44,"id":12984952}]}]}
{"op":"mcm","clk":"1009434408","pt":1580644310367,"mc":[{"id":"1.168217555","rc":[{"batl":[[0,4.6,21.48],[1,4.8,18.88],[2,4.9,18.65]],"ltp":5.2,"tv":21.28,"id":12984951},{"batb":[[0,1.76,21.4],[1,1.75,66.59],[2,1.73,106.64]],"batl":[[1,2.08,28.95]],"ltp":2.06,"tv":54.44,"id":12984952},{"batl":[[0,5.1,17.15],[1,5.5,14.48],[2,5.7,13.38]],"ltp":4.4,"tv":44.81,"id":16574984}]}]}
{"op":"mcm","clk":"1009434427","pt":1580644310579,"mc":[{"id":"1.168217555","rc":[{"batb":[[1,3.95,62.4]],"batl":[[0,4.6,32.4],[1,4.9,18.65],[2,4.9,0]],"ltp":5.2,"tv":21.28,"id":12984951},{"batl":[[1,1.84,42.01],[2,2.08,28.95]],"ltp":2.06,"tv":54.44,"id":12984952},{"batb":[[2,4.7,10.92]],"batl":[[1,5.5,23.72],[2,5.7,0]],"ltp":4.4,"tv":44.81,"id":16574984}]}]}
{"op":"mcm","clk":"1009444191","pt":1580644399378,"mc":[{"id":"1.168217555","rc":[{"batb":[[0,3.95,13.44],[1,3.6,14.87],[2,1.01,0.51]],"batl":[[0,4.6,10.92]],"ltp":5.2,"tv":21.28,"id":12984951},{"batb":[[0,1.7,59.65],[1,1.67,25.41],[2,1.01,0.51]],"batl":[[0,1.84,42.01],[1,2.08,28.95],[2,2.08,0]],"ltp":2.06,"tv":54.44,"id":12984952},{"batb":[[0,4.7,10.92],[1,3.95,24.78],[2,1.01,0.51]],"batl":[[0,5.5,23.72],[1,5.5,0]],"ltp":4.4,"tv":44.81,"id":16574984}]}]}
{"op":"mcm","clk":"1009444288","pt":1580644400274,"mc":[{"id":"1.168217555","rc":[{"batb":[[0,3.6,14.87],[1,1.01,0.51],[2,1.01,0]],"batl":[[0,4.9,18.65],[1,4.9,0]],"ltp":5.2,"tv":21.28,"id":12984951},{"batb":[[0,1.67,25.41],[1,1.01,0.51],[2,1.01,0]],"batl":[[0,2.08,28.95],[1,2.08,0]],"ltp":2.06,"tv":54.44,"id":12984952},{"batb":[[0,3.95,24.78],[1,1.01,0.51],[2,1.01,0]],"batl":[[0,5.5,14.48]],"ltp":4.4,"tv":44.81,"id":16574984}]}]}
{"op":"mcm","clk":"1009444480","pt":1580644401865,"mc":[{"id":"1.168217555","rc":[{"batb":[[1,3.5,62.06],[2,3.45,38.31]],"ltp":5.2,"tv":21.28,"id":12984951},{"batb":[[1,1.66,96.71],[2,1.65,63.41]],"ltp":2.06,"tv":54.44,"id":12984952},{"batb":[[0,4.3,39.39],[1,4.2,49.28],[2,3.95,24.78]],"ltp":4.4,"tv":44.81,"id":16574984}]}]}
{"op":"mcm","clk":"1009446744","pt":1580644423019,"mc":[{"id":"1.168217555","rc":[{"batb":[[1,1.01,0.51],[2,3.45,0]],"ltp":5.2,"tv":21.28,"id":12984951},{"batb":[[1,1.01,0.51],[2,1.65,0]],"ltp":2.06,"tv":54.44,"id":12984952},{"batb":[[0,3.95,24.78],[1,1.01,0.51],[2,3.95,0]],"ltp":4.4,"tv":44.81,"id":16574984}]}]}
{"op":"mcm","clk":"1009447064","pt":1580644426491,"mc":[{"id":"1.168217555","rc":[{"batb":[[0,3.95,49.34],[1,3.9,28.58],[2,3.6,14.87]],"batl":[[1,5.1,394.35]],"ltp":5.2,"tv":21.28,"id":12984951},{"batb":[[0,1.75,65.9],[1,1.73,106.64],[2,1.67,25.41]],"ltp":2.06,"tv":54.44,"id":12984952},{"batb":[[0,4.9,37.37],[1,4.8,36.31],[2,3.95,24.78]],"ltp":4.4,"tv":44.81,"id":16574984}]}]}
{"op":"mcm","clk":"1009447774","pt":1580644433834,"mc":[{"id":"1.168217555","rc":[{"batb":[[0,8,15.96],[1,1.01,0.51]],"ltp":5.1,"tv":4.54,"id":16574983}]}]}
{"op":"mcm","clk":"1009448489","pt":1580644441036,"mc":[{"id":"1.168217555","rc":[{"batb":[[0,3.6,14.87],[1,1.01,0.51],[2,3.6,0]],"batl":[[1,5.1,0]],"ltp":5.2,"tv":21.28,"id":12984951},{"batb":[[0,1.67,25.41],[1,1.01,0.51],[2,1.67,0]],"ltp":2.06,"tv":54.44,"id":12984952},{"batb":[[0,3.95,24.78],[1,1.01,0.51],[2,3.95,0]],"ltp":4.4,"tv":44.81,"id":16574984}]}]}
{"op":"mcm","clk":"1009448762","pt":1580644443815,"mc":[{"id":"1.168217555","rc":[{"batb":[[1,3.5,62.06],[2,3.45,38.31]],"ltp":5.2,"tv":21.28,"id":12984951},{"batb":[[1,1.66,96.71],[2,1.65,63.41]],"ltp":2.06,"tv":54.44,"id":12984952},{"batb":[[0,4.3,39.39],[1,4.2,49.28],[2,3.95,24.78]],"ltp":4.4,"tv":44.81,"id":16574984}]}]}
{"op":"mcm","clk":"1009449516","pt":1580644451270,"mc":[{"id":"1.168217555","rc":[{"batb":[[1,1.01,0.51],[2,3.45,0]],"ltp":5.2,"tv":21.28,"id":12984951},{"batb":[[0,3.95,24.78],[1,1.01,0.51],[2,3.95,0]],"ltp":4.4,"tv":44.81,"id":16574984}]}]}
{"op":"mcm","clk":"1009449813","pt":1580644454229,"mc":[{"id":"1.168217555","rc":[{"batb":[[0,4.2,54.58],[1,4.1,50.05],[2,3.6,14.87]],"ltp":5.2,"tv":21.28,"id":12984951},{"batb":[[0,5.3,26.85],[1,5.2,30.46],[2,3.95,24.78]],"ltp":4.4,"tv":44.81,"id":16574984}]}]}
{"op":"mcm","clk":"1009449892","pt":1580644455065,"mc":[{"id":"1.168217555","rc":[{"batb":[[0,4.3,19.59],[1,4.2,67.18],[2,4.1,50.05]],"batl":[[0,4.9,28.73],[1,5.1,16.6]],"ltp":5.2,"tv":21.28,"id":12984951},{"batl":[[0,1.74,24.94],[1,1.75,42.01],[2,1.9,18.96]],"ltp":2.06,"tv":54.44,"id":12984952},{"batb":[[2,5,10.08]],"batl":[[1,5.9,21.07]],"ltp":4.4,"tv":44.81,"id":16574984}]}]}
{"op":"mcm","clk":"1009450808","pt":1580644464044,"mc":[{"id":"1.168217555","rc":[{"batb":[[0,1.01,0.51],[1,1.01,0]],"ltp":5.1,"tv":4.54,"id":16574983}]}]}
{"op":"mcm","clk":"1009452265","pt":1580644479063,"mc":[{"id":"1.168217555","rc":[{"batb":[[0,4.2,12.6],[1,3.9,24.47],[2,1.01,0.51]],"batl":[[0,4.9,10.08]],"ltp":5.2,"tv":21.28,"id":12984951},{"batb":[[0,1.63,66.38],[1,1.61,29.11],[2,1.01,0.51]],"batl":[[0,1.75,42.01],[1,1.9,18.96],[2,1.9,0]],"ltp":2.06,"tv":54.44,"id":12984952},{"batb":[[0,5,10.08],[1,4.3,19.99],[2,1.01,0.51]],"batl":[[0,5.9,21.07],[1,5.9,0]],"ltp":4.4,"tv":44.81,"id":16574984}]}]}
{"op":"mcm","clk":"1009452334","pt":1580644479685,"mc":[{"id":"1.168217555","rc":[{"batb":[[0,3.9,24.47],[1,1.01,0.51],[2,1.01,0]],"batl":[[0,5.1,16.6],[1,5.1,0]],"ltp":5.2,"tv":21.28,"id":12984951},{"batb":[[0,1.61,29.11],[1,1.01,0.51],[2,1.01,0]],"batl":[[0,1.9,18.96],[1,1.9,0]],"ltp":2.06,"tv":54.44,"id":12984952},{"batb":[[0,4.3,19.99],[1,1.01,0.51],[2,1.01,0]],"batl":[[0,5.9,12.67]],"ltp":4.4,"tv":44.81,"id":16574984}]}]}
{"op":"mcm","clk":"1009452514","pt":1580644481470,"mc":[{"id":"1.168217555","rc":[{"batb":[[1,3.85,43.38],[2,3.8,30.47]],"ltp":5.2,"tv":21.28,"id":12984951},{"batb":[[1,1.6,116.72],[2,1.59,72.74]],"ltp":2.06,"tv":54.44,"id":12984952},{"batb":[[0,4.7,45.14],[1,4.6,39.88],[2,4.3,19.99]],"ltp":4.4,"tv":44.81,"id":16574984}]}]}
{"op":"mcm","clk":"1009452708","pt":1580644483089,"mc":[{"id":"1.168217555","rc":[{"batb":[[1,1.01,0.51],[2,3.8,0]],"ltp":5.2,"tv":21.28,"id":12984951},{"batb":[[1,1.01,0.51],[2,1.59,0]],"ltp":2.06,"tv":54.44,"id":12984952},{"batb":[[0,4.3,19.99],[1,1.01,0.51],[2,4.3,0]],"ltp":4.4,"tv":44.81,"id":16574984}]}]}
{"op":"mcm","clk":"1009453046","pt":1580644486390,"mc":[{"id":"1.168217555","rc":[{"batb":[[0,4.1,65.53],[1,4,52.85],[2,3.9,24.47]],"ltp":5.2,"tv":21.28,"id":12984951},{"batb":[[0,1.69,63.18],[1,1.67,120.57],[2,1.61,29.11]],"ltp":2.06,"tv":54.44,"id":12984952},{"batb":[[0,5.2,20.43],[1,5.1,31.91],[2,4.3,19.99]],"ltp":4.4,"tv":44.81,"id":16574984}]}]}
{"op":"mcm","clk":"1009453268","pt":1580644488686,"mc":[{"id":"1.168217555","rc":[{"batb":[[0,3.9,24.47],[1,1.01,0.51],[2,3.9,0]],"ltp":5.2,"tv":21.28,"id":12984951},{"batb":[[0,1.61,29.11],[1,1.01,0.51],[2,1.61,0]],"ltp":2.06,"tv":54.44,"id":12984952},{"batb":[[0,4.3,19.99],[1,1.01,0.51],[2,4.3,0]],"ltp":4.4,"tv":44.81,"id":16574984}]}]}
{"op":"mcm","clk":"1009453557","pt":1580644491989,"mc":[{"id":"1.168217555","rc":[{"batb":[[1,3.85,43.38],[2,3.8,30.47]],"ltp":5.2,"tv":21.28,"id":12984951},{"batb":[[0,4.7,45.14],[1,4.6,39.88],[2,4.3,19.99]],"ltp":4.4,"tv":44.81,"id":16574984}]}]}
{"op":"mcm","clk":"1009453721","pt":1580644493508,"mc":[{"id":"1.168217555","rc":[{"batb":[[0,1.79,96.43],[1,1.77,98.78],[2,1.61,29.11]],"ltp":2.06,"tv":54.44,"id":12984952}]}]}
{"op":"mcm","clk":"1009453817","pt":1580644494508,"mc":[{"id":"1.168217555","rc":[{"batl":[[0,4.4,23.13],[1,4.8,19.2]],"ltp":5.2,"tv":21.28,"id":12984951},{"batb":[[0,1.82,19.28],[1,1.79,96.43],[2,1.77,98.78]],"batl":[[1,2.22,23.76]],"ltp":2.06,"tv":54.44,"id":12984952},{"batl":[[0,4.9,19.04],[1,5.3,15.58]],"ltp":4.4,"tv":44.81,"id":16574984}]}]}
{"op":"mcm","clk":"1009453841","pt":1580644494779,"mc":[{"id":"1.168217555","rc":[{"batb":[[1,3.85,57.66]],"batl":[[1,4.5,11.76],[2,4.8,19.2]],"ltp":5.2,"tv":21.28,"id":12984951},{"batl":[[0,1.89,42.01],[1,1.9,18.96],[2,2.22,23.76]],"ltp":2.06,"tv":54.44,"id":12984952},{"batb":[[2,4.5,11.76]],"batl":[[2,5.4,9.24]],"ltp":4.4,"tv":44.81,"id":16574984}]}]}
{"op":"mcm","clk":"1009455585","pt":1580644510124,"mc":[{"id":"1.168217555","rc":[{"batb":[[0,3.4,17.07],[1,1.01,0.51],[2,3.8,0]],"batl":[[0,4.8,19.2],[1,4.5,0],[2,4.8,0]],"ltp":5.2,"tv":21.28,"id":12984951},{"batb":[[0,1.7,24.08],[1,1.01,0.51],[2,1.77,0]],"batl":[[0,2.22,23.76],[1,1.9,0],[2,2.22,0]],"ltp":2.06,"tv":54.44,"id":12984952},{"batb":[[0,3.7,14.32],[1,1.01,0.51],[2,4.5,0]],"batl":[[0,5.3,15.58],[1,5.3,0],[2,5.4,0]],"ltp":4.4,"tv":44.81,"id":16574984}]}]}
{"op":"mcm","clk":"1009455873","pt":1580644512435,"mc":[{"id":"1.168217555","rc":[{"batb":[[1,3.3,69.2],[2,3.25,44.33]],"ltp":5.2,"tv":21.28,"id":12984951},{"batb":[[1,1.68,76.99],[2,1.67,60.69]],"ltp":2.06,"tv":54.44,"id":12984952},{"batb":[[0,4,63.42],[1,3.95,28.58],[2,3.7,14.32]],"ltp":4.4,"tv":44.81,"id":16574984}]}]}
{"op":"mcm","clk":"1009455936","pt":1580644513022,"mc":[{"id":"1.168217555","rc":[{"batb":[[0,1.69,24.39]],"ltp":2.06,"tv":54.44,"id":12984952},{"batb":[[2,3.8,13.77]],"batl":[[0,5.4,15.03]],"ltp":4.4,"tv":44.81,"id":16574984}]}]}
{"op":"mcm","clk":"1009456076","pt":1580644514329,"mc":[{"id":"1.168217555","rc":[{"batb":[[1,1.01,0.51],[2,3.25,0]],"ltp":5.2,"tv":21.28,"id":12984951},{"batb":[[1,1.01,0.51],[2,1.67,0]],"ltp":2.06,"tv":54.44,"id":12984952},{"batb":[[0,3.8,13.77],[1,1.01,0.51],[2,3.8,0]],"ltp":4.4,"tv":44.81,"id":16574984}]}]}
{"op":"mcm","clk":"1009456397","pt":1580644517318,"mc":[{"id":"1.168217555","rc":[{"batb":[[0,3.75,32.54],[1,3.7,32.58],[2,3.4,17.07]],"ltp":5.2,"tv":21.28,"id":12984951},{"batb":[[0,1.84,90.75],[1,1.82,90.06],[2,1.69,24.39]],"ltp":2.06,"tv":54.44,"id":12984952},{"batb":[[0,4.6,23.81],[1,4.5,42.28],[2,3.8,13.77]],"ltp":4.4,"tv":44.81,"id":16574984}]}]}
{"op":"mcm","clk":"1009456481","pt":1580644518129,"mc":[{"id":"1.168217555","rc":[{"batb":[[0,3.4,17.07],[1,1.01,0.51],[2,3.4,0]],"ltp":5.2,"tv":21.28,"id":12984951},{"batb":[[0,1.69,24.39],[1,1.01,0.51],[2,1.69,0]],"ltp":2.06,"tv":54.44,"id":12984952},{"batb":[[0,3.8,13.77],[1,1.01,0.51],[2,3.8,0]],"ltp":4.4,"tv":44.81,"id":16574984}]}]}
{"op":"mcm","clk":"1009456766","pt":1580644521031,"mc":[{"id":"1.168217555","rc":[{"batb":[[1,3.3,69.2],[2,3.25,44.33]],"ltp":5.2,"tv":21.28,"id":12984951},{"batb":[[1,1.68,76.99],[2,1.67,60.69]],"ltp":2.06,"tv":54.44,"id":12984952},{"batb":[[0,4,63.42],[1,3.95,28.58],[2,3.8,13.77]],"ltp":4.4,"tv":44.81,"id":16574984}]}]}
{"op":"mcm","clk":"1009458331","pt":1580644535286,"mc":[{"id":"1.168217555","rc":[{"batb":[[0,7,15.96],[1,1.01,0.51]],"ltp":5.1,"tv":4.54,"id":16574983}]}]}
{"op":"mcm","clk":"1009458941","pt":1580644541486,"mc":[{"id":"1.168217555","rc":[{"batb":[[1,1.01,0.51],[2,1.67,0]],"ltp":2.06,"tv":54.44,"id":12984952}]}]}
{"op":"mcm","clk":"1009459229","pt":1580644544509,"mc":[{"id":"1.168217555","rc":[{"batb":[[0,2.08,48.85],[1,2.06,61.18],[2,1.69,24.39]],"ltp":2.06,"tv":54.44,"id":12984952}]}]}
{"op":"mcm","clk":"1009459332","pt":1580644545504,"mc":[{"id":"1.168217555","rc":[{"batb":[[1,3.35,17.64],[2,3.3,69.2]],"batl":[[0,3.7,16.68],[1,3.85,14.28],[2,4.2,12.9]],"ltp":5.2,"tv":21.28,"id":12984951},{"batb":[[0,2.1,24.78],[1,2.08,48.85],[2,2.06,61.18]],"batl":[[1,2.96,11.25]],"ltp":2.06,"tv":54.44,"id":12984952},{"batl":[[0,4.2,13.38],[1,4.6,10.92],[2,4.7,20.38]],"ltp":4.4,"tv":44.81,"id":16574984}]}]}
{"op":"mcm","clk":"1009459617","pt":1580644548187,"mc":[{"id":"1.168217555","rc":[{"batl":[[0,2.16,36.13],[1,2.22,23.76],[2,2.96,11.25]],"ltp":2.06,"tv":54.44,"id":12984952}]}]}
{"op":"mcm","clk":"1009459704","pt":1580644548974,"mc":[{"id":"1.168217555","rc":[{"batb":[[1,3.95,42.02]],"ltp":4.4,"tv":44.81,"id":16574984}]}]}
{"op":"mcm","clk":"1009461658","pt":1580644566423,"mc":[{"id":"1.168217555","rc":[{"batb":[[0,3.35,17.64],[1,2.82,11.09],[2,1.01,0.51]],"batl":[[0,3.85,14.28],[1,4.2,12.9],[2,4.2,0]],"ltp":5.2,"tv":21.28,"id":12984951},{"batb":[[0,1.96,43.69],[1,1.88,17.39],[2,1.01,0.51]],"batl":[[1,2.96,11.25],[2,2.96,0]],"ltp":2.06,"tv":54.44,"id":12984952},{"batb":[[0,3.95,13.44],[1,3.1,22.11],[2,1.01,0.51]],"batl":[[0,4.6,10.92],[1,4.7,20.38],[2,4.7,0]],"ltp":4.4,"tv":44.81,"id":16574984}]}]}
{"op":"mcm","clk":"1009461708","pt":1580644566841,"mc":[{"id":"1.168217555","rc":[{"batb":[[0,1.01,0.51],[1,1.01,0]],"ltp":5.1,"tv":4.54,"id":16574983}]}]}
{"op":"mcm","clk":"1009461843","pt":1580644567844,"mc":[{"id":"1.168217555","rc":[{"batb":[[0,2.82,11.09],[1,1.01,0.51],[2,1.01,0]],"batl":[[0,4.2,12.9],[1,4.2,0]],"ltp":5.2,"tv":21.28,"id":12984951},{"batb":[[0,1.88,17.39],[1,1.01,0.51],[2,1.01,0]],"batl":[[0,2.96,11.25],[1,2.96,0]],"ltp":2.06,"tv":54.44,"id":12984952},{"batb":[[0,3.1,22.11],[1,1.01,0.51],[2,1.01,0]],"batl":[[0,4.7,20.38],[1,4.7,0]],"ltp":4.4,"tv":44.81,"id":16574984}]}]}
{"op":"mcm","clk":"1009462052","pt":1580644569428,"mc":[{"id":"1.168217555","rc":[{"batb":[[1,2.8,11.25],[2,2.74,63.33]],"ltp":5.2,"tv":21.28,"id":12984951},{"batb":[[1,1.87,17.7],[2,1.84,97.79]],"batl":[[0,2.94,11.49],[1,2.96,11.25]],"ltp":2.06,"tv":54.44,"id":12984952},{"batb":[[0,3.3,73.77],[1,3.25,45.65],[2,3.15,21.17]],"batl":[[1,4.8,19.51]],"ltp":4.4,"tv":44.81,"id":16574984}]}]}
{"op":"mcm","clk":"1009462080","pt":1580644569634,"mc":[{"id":"1.168217555","rc":[{"batb":[[0,2.8,11.25],[1,2.74,63.33],[2,2.7,57.26]],"ltp":5.2,"tv":21.28,"id":12984951},{"batb":[[0,1.87,17.7],[1,1.84,97.79],[2,1.82,90.07]],"batl":[[1,2.96,0]],"ltp":2.06,"tv":54.44,"id":12984952},{"batl":[[0,4.8,19.51],[1,4.8,0]],"ltp":4.4,"tv":44.81,"id":16574984}]}]}
{"op":"mcm","clk":"1009462477","pt":1580644573216,"mc":[{"id":"1.168217555","rc":[{"batb":[[1,1.01,0.51],[2,2.7,0]],"ltp":5.2,"tv":21.28,"id":12984951},{"batb":[[0,3.15,21.17],[1,1.01,0.51],[2,3.15,0]],"ltp":4.4,"tv":44.81,"id":16574984}]}]}
{"op":"mcm","clk":"1009462889","pt":1580644576442,"mc":[{"id":"1.168217555","rc":[{"batb":[[0,3.75,50.09],[1,3.7,32.54],[2,3.1,21.56]],"batl":[[1,4.7,19.67]],"ltp":5.2,"tv":21.28,"id":12984951},{"batl":[[0,1.95,17.47],[1,2.46,18.18],[2,2.94,11.49]],"ltp":2.06,"tv":54.44,"id":12984952},{"batb":[[0,4.5,58.37],[1,4.4,43.95],[2,4.2,20.54]],"batl":[[1,5.4,14.87]],"ltp":4.4,"tv":44.81,"id":16574984}]}]}
{"op":"mcm","clk":"1009462964","pt":1580644577024,"mc":[{"id":"1.168217555","rc":[{"batb":[[0,3.75,65.22]],"batl":[[1,4.3,12.6],[2,4.7,19.67]],"ltp":5.2,"tv":21.28,"id":12984951},{"batl":[[0,1.94,42.01],[1,1.95,17.47],[2,2.46,18.18]],"ltp":2.06,"tv":54.44,"id":12984952},{"batb":[[2,4.3,12.6]],"batl":[[1,5.1,10.08],[2,5.4,14.87]],"ltp":4.4,"tv":44.81,"id":16574984}]}]}
{"op":"mcm","clk":"1009464122","pt":1580644586865,"mc":[{"id":"1.168217555","rc":[{"batb":[[1,1.84,68.87]],"ltp":2.06,"tv":54.44,"id":12984952},{"batb":[[0,4.5,42.42],[1,4.3,12.6],[2,4.2,20.54]],"ltp":4.4,"tv":44.81,"id":16574984}]}]}
{"op":"mcm","clk":"1009464537","pt":1580644590485,"mc":[{"id":"1.168217555","rc":[{"batb":[[0,3.1,21.56],[1,1.01,0.51],[2,3.1,0]],"batl":[[0,4.7,19.67],[1,4.3,0],[2,4.7,0]],"ltp":5.2,"tv":21.28,"id":12984951},{"batb":[[0,1.69,24.31],[1,1.01,0.51],[2,1.82,0]],"batl":[[0,2.46,18.18],[1,1.95,0],[2,2.46,0]],"ltp":2.06,"tv":54.44,"id":12984952},{"batb":[[0,3.55,16.29],[1,1.01,0.51],[2,4.2,0]],"batl":[[0,5.4,14.87],[1,5.1,0],[2,5.4,0]],"ltp":4.4,"tv":44.81,"id":16574984}]}]}
{"op":"mcm","clk":"1009464852","pt":1580644593146,"mc":[{"id":"1.168217555","rc":[{"batb":[[0,3.05,22.03]],"ltp":5.2,"tv":21.28,"id":12984951},{"batb":[[0,1.68,24.94]],"batl":[[0,2.44,18.65]],"ltp":2.06,"tv":54.44,"id":12984952},{"batb":[[0,3.6,15.34]],"batl":[[0,5.6,14.01]],"ltp":4.4,"tv":44.81,"id":16574984}]}]}
{"op":"mcm","clk":"1009465182","pt":1580644596453,"mc":[{"id":"1.168217555","rc":[{"batb":[[0,3.55,57.69],[1,3.5,36.93],[2,3.05,22.03]],"ltp":5.2,"tv":21.28,"id":12984951},{"batb":[[0,1.91,84.03],[1,1.89,79.73],[2,1.68,24.94]],"ltp":2.06,"tv":54.44,"id":12984952},{"batb":[[0,4.4,44.86],[1,4.3,47.05],[2,3.6,15.34]],"ltp":4.4,"tv":44.81,"id":16574984}]}]}
{"op":"mcm","clk":"1009465812","pt":1580644602079,"mc":[{"id":"1.168217555","rc":[{"batb":[[0,3.05,22.03],[1,1.01,0.51],[2,3.05,0]],"ltp":5.2,"tv":21.28,"id":12984951},{"batb":[[0,1.68,24.94],[1,1.01,0.51],[2,1.68,0]],"ltp":2.06,"tv":54.44,"id":12984952},{"batb":[[0,3.6,15.34],[1,1.01,0.51],[2,3.6,0]],"ltp":4.4,"tv":44.81,"id":16574984}]}]}
{"op":"mcm","clk":"1009466063","pt":1580644604364,"mc":[{"id":"1.168217555","rc":[{"batb":[[0,6,12.6],[1,1.01,0.51]],"ltp":5.1,"tv":4.54,"id":16574983}]}]}
{"op":"mcm","clk":"1009466143","pt":1580644605261,"mc":[{"id":"1.168217555","rc":[{"batb":[[0,3.05,70.09],[1,3,54.32],[2,1.01,0.51]],"ltp":5.2,"tv":21.28,"id":12984951},{"batb":[[0,3.75,54.13],[1,3.7,33.78],[2,3.6,15.34]],"ltp":4.4,"tv":44.81,"id":16574984}]}]}
{"op":"mcm","clk":"1009466511","pt":1580644608474,"mc":[{"id":"1.168217555","rc":[{"batb":[[2,2.3,18.96]],"batl":[[0,3.35,21.24],[1,4.1,13.45]],"ltp":5.2,"tv":21.28,"id":12984951},{"batb":[[0,2.3,19.12],[1,2.28,75.76],[2,2.26,46.63]],"batl":[[1,4.6,20.54]],"ltp":2.06,"tv":54.44,"id":12984952},{"batl":[[0,3.95,14.87],[1,4.8,19.43]],"ltp":4.4,"tv":44.81,"id":16574984}]}]}
{"op":"mcm","clk":"1009466586","pt":1580644609160,"mc":[{"id":"1.168217555","rc":[{"batb":[[0,3.1,19.32],[1,3.05,70.09],[2,3,54.32]],"batl":[[1,3.55,15.96],[2,4.1,13.45]],"ltp":5.2,"tv":21.28,"id":12984951},{"batl":[[0,2.38,30.25],[1,2.44,18.65],[2,4.6,20.54]],"ltp":2.06,"tv":54.44,"id":12984952},{"batb":[[1,3.7,48.9]],"batl":[[1,4.2,12.6],[2,4.8,19.43]],"ltp":4.4,"tv":44.81,"id":16574984}]}]}
{"op":"mcm","clk":"1009468135","pt":1580644623440,"mc":[{"id":"1.168217555","rc":[{"batb":[[1,3.05,22.03],[2,2.3,18.96]],"ltp":5.2,"tv":21.28,"id":12984951},{"batb":[[1,2.14,36.13],[2,1.88,17.39]],"ltp":2.06,"tv":54.44,"id":12984952},{"batb":[[0,3.7,15.12],[1,3.6,15.34],[2,2.8,11.8]],"ltp":4.4,"tv":44.81,"id":16574984}]}]}
{"op":"mcm","clk":"1009468212","pt":1580644624199,"mc":[{"id":"1.168217555","rc":[{"batb":[[0,2.3,18.96],[1,1.01,0.51],[2,2.3,0]],"batl":[[0,4.1,13.45],[1,3.55,0],[2,4.1,0]],"ltp":5.2,"tv":21.28,"id":12984951},{"batb":[[0,1.88,17.39],[1,1.01,0.51],[2,1.88,0]],"batl":[[0,4.6,20.54],[1,2.44,0],[2,4.6,0]],"ltp":2.06,"tv":54.44,"id":12984952},{"batb":[[0,2.8,11.8],[1,1.01,0.51],[2,2.8,0]],"batl":[[0,4.8,19.43],[1,4.2,0],[2,4.8,0]],"ltp":4.4,"tv":44.81,"id":16574984}]}]}
{"op":"mcm","clk":"1009468425","pt":1580644626390,"mc":[{"id":"1.168217555","rc":[{"batb":[[1,2.28,74.76],[2,2.26,46.97]],"ltp":5.2,"tv":21.28,"id":12984951},{"batb":[[1,1.86,58.03],[2,1.84,86.88]],"ltp":2.06,"tv":54.44,"id":12984952},{"batb":[[0,2.86,45.08],[1,2.82,52.91],[2,2.8,11.8]],"ltp":4.4,"tv":44.81,"id":16574984}]}]}
{"op":"mcm","clk":"1009468562","pt":1580644627389,"mc":[{"id":"1.168217555","rc":[{"batb":[[0,2.32,18.73],[1,1.01,0.51],[2,2.26,0]],"batl":[[0,4.1,13.22]],"ltp":5.2,"tv":21.28,"id":12984951},{"batb":[[1,1.01,0.51],[2,1.84,0]],"ltp":2.06,"tv":54.44,"id":12984952},{"batb":[[0,2.8,11.8],[1,1.01,0.51],[2,2.8,0]],"ltp":4.4,"tv":44.81,"id":16574984}]}]}
{"op":"mcm","clk":"1009468762","pt":1580644629033,"mc":[{"id":"1.168217555","rc":[{"batb":[[0,2.86,50.21],[1,2.82,51.11],[2,2.32,18.73]],"ltp":5.2,"tv":21.28,"id":12984951},{"batb":[[0,2.5,67.97],[1,2.46,73.03],[2,1.88,17.39]],"ltp":2.06,"tv":54.44,"id":12984952},{"batb":[[0,3.55,37.9],[1,3.5,38.73],[2,2.8,11.8]],"ltp":4.4,"tv":44.81,"id":16574984}]}]}
{"op":"mcm","clk":"1009469107","pt":1580644632628,"mc":[{"id":"1.168217555","rc":[{"batb":[[0,2.32,18.73],[1,1.01,0.51],[2,2.32,0]],"ltp":5.2,"tv":21.28,"id":12984951},{"batb":[[0,1.88,17.39],[1,1.01,0.51],[2,1.88,0]],"ltp":2.06,"tv":54.44,"id":12984952},{"batb":[[0,2.8,11.8],[1,1.01,0.51],[2,2.8,0]],"ltp":4.4,"tv":44.81,"id":16574984}]}]}
{"op":"mcm","clk":"1009469493","pt":1580644635930,"mc":[{"id":"1.168217555","rc":[{"batb":[[1,2.28,73.93],[2,2.26,46.97]],"ltp":5.2,"tv":21.28,"id":12984951},{"batb":[[0,2.86,46.24],[1,2.82,52.91],[2,2.8,11.8]],"ltp":4.4,"tv":44.81,"id":16574984}]}]}
{"op":"mcm","clk":"1009469752","pt":1580644638506,"mc":[{"id":"1.168217555","rc":[{"batb":[[0,4.1,48.49],[1,4,52.92],[2,1.88,17.39]],"ltp":2.06,"tv":54.44,"id":12984952}]}]}
{"op":"mcm","clk":"1009469841","pt":1580644639451,"mc":[{"id":"1.168217555","rc":[{"batb":[[0,2.36,30.25],[1,2.32,18.73],[2,2.28,73.93]],"batl":[[0,2.44,18.33],[1,2.66,14.63]],"ltp":5.2,"tv":21.28,"id":12984951},{"trd":[[4.1,26.88]],"batb":[[0,4.1,57],[2,3.2,19.91]],"batl":[[1,5.5,14.01]],"ltp":4.1,"tv":81.32,"id":12984952},{"batl":[[0,2.98,11.57],[1,3.15,19.32],[2,3.35,22.35]],"ltp":4.4,"tv":44.81,"id":16574984}],"tv":151.96}]}
{"op":"mcm","clk":"1009470092","pt":1580644641434,"mc":[{"id":"1.168217555","rc":[{"batl":[[1,2.62,25.21],[2,2.66,14.63]],"ltp":5.2,"tv":21.28,"id":12984951},{"batb":[[2,3.7,15.12]],"ltp":4.1,"tv":81.32,"id":12984952}]}]}
{"op":"mcm","clk":"1009470186","pt":1580644642330,"mc":[{"id":"1.168217555","rc":[{"batl":[[1,2.66,14.63],[2,2.66,0]],"ltp":5.2,"tv":21.28,"id":12984951},{"batl":[[0,4.3,12.6],[1,4.6,20.54],[2,5.5,14.01]],"ltp":4.1,"tv":81.32,"id":12984952}]}]}
{"op":"mcm","clk":"1009470210","pt":1580644642549,"mc":[{"id":"1.168217555","rc":[{"batl":[[1,2.6,26.05],[2,2.66,14.63]],"ltp":5.2,"tv":21.28,"id":12984951}]}]}
{"op":"mcm","clk":"1009471150","pt":1580644651264,"mc":[{"id":"1.168217555","rc":[{"batb":[[2,2.28,45.98]],"ltp":5.2,"tv":21.28,"id":12984951}]}]}
{"op":"mcm","clk":"1009471466","pt":1580644654253,"mc":[{"id":"1.168217555","rc":[{"batb":[[2,2.3,47.42]],"ltp":5.2,"tv":21.28,"id":12984951}]}]}
{"op":"mcm","clk":"1009472230","pt":1580644661648,"mc":[{"id":"1.168217555","rc":[{"batb":[[0,2.32,18.73],[1,2.3,47.42],[2,2.28,45.98]],"ltp":5.2,"tv":21.28,"id":12984951},{"batb":[[0,2.8,11.8],[1,2.76,23.53],[2,2.64,13.69]],"ltp":4.4,"tv":44.81,"id":16574984}]}]}
{"op":"mcm","clk":"1009472549","pt":1580644664485,"mc":[{"id":"1.168217555","rc":[{"batb":[[1,2.3,65.87]],"ltp":5.2,"tv":21.28,"id":12984951},{"batb":[[0,4.1,68.92]],"ltp":4.1,"tv":81.32,"id":12984952},{"batb":[[0,2.84,40.44],[1,2.8,65.57],[2,2.76,23.53]],"ltp":4.4,"tv":44.81,"id":16574984}]}]}
{"op":"mcm","clk":"1009472559","pt":1580644664576,"mc":[{"id":"1.168217555","rc":[{"batb":[[0,2.32,49.81]],"ltp":5.2,"tv":21.28,"id":12984951}]}]}
{"op":"mcm","clk":"1009472979","pt":1580644668452,"mc":[{"id":"1.168217555","rc":[{"batb":[[0,1.01,0.51],[1,1.01,0]],"ltp":5.1,"tv":4.54,"id":16574983}]}]}
{"op":"mcm","clk":"1009473203","pt":1580644670385,"mc":[{"id":"1.168217555","rc":[{"batb":[[0,2.32,31.09],[1,2.22,20.85],[2,1.01,0.51]],"batl":[[0,2.6,26.05],[1,2.66,14.63],[2,2.66,0]],"ltp":5.2,"tv":21.28,"id":12984951},{"batb":[[0,3.7,15.12],[1,3.2,19.91],[2,1.01,0.51]],"batl":[[1,5.5,14.01],[2,5.5,0]],"ltp":4.1,"tv":81.32,"id":12984952},{"batb":[[0,2.76,23.53],[1,2.64,13.69],[2,1.01,0.51]],"batl":[[0,3.15,19.32],[1,3.35,22.35],[2,3.35,0]],"ltp":4.4,"tv":44.81,"id":16574984}]}]}
{"op":"mcm","clk":"1009473358","pt":1580644671854,"mc":[{"id":"1.168217555","rc":[{"batb":[[0,2.22,20.85],[1,1.01,0.51],[2,1.01,0]],"batl":[[0,2.66,14.63],[1,2.66,0]],"ltp":5.2,"tv":21.28,"id":12984951},{"batb":[[0,3.2,19.91],[1,1.01,0.51],[2,1.01,0]],"batl":[[0,5.5,14.01],[1,5.5,0]],"ltp":4.1,"tv":81.32,"id":12984952},{"batb":[[0,2.64,13.69],[1,1.01,0.51],[2,1.01,0]],"batl":[[0,3.35,22.35],[1,3.35,0]],"ltp":4.4,"tv":44.81,"id":16574984}]}]}
{"op":"mcm","clk":"1009473520","pt":1580644673476,"mc":[{"id":"1.168217555","rc":[{"batb":[[1,2.2,73.56],[2,2.18,52.36]],"ltp":5.2,"tv":21.28,"id":12984951},{"batb":[[0,3.25,34.16],[1,3.2,66.11],[2,1.01,0.51]],"ltp":4.1,"tv":81.32,"id":12984952},{"batb":[[0,2.68,67.76],[1,2.64,76.14],[2,1.01,0.51]],"batl":[[0,3.3,22.42]],"ltp":4.4,"tv":44.81,"id":16574984}]}]}
{"op":"mcm","clk":"1009473714","pt":1580644675047,"mc":[{"id":"1.168217555","rc":[{"batb":[[1,1.01,0.51],[2,2.18,0]],"ltp":5.2,"tv":21.28,"id":12984951},{"batb":[[0,3.2,19.91],[1,1.01,0.51],[2,1.01,0]],"ltp":4.1,"tv":81.32,"id":12984952},{"batb":[[0,2.64,13.69],[1,1.01,0.51],[2,1.01,0]],"ltp":4.4,"tv":44.81,"id":16574984}]}]}
{"op":"mcm","clk":"1009474050","pt":1580644678271,"mc":[{"id":"1.168217555","rc":[{"batb":[[0,2.34,55.72],[1,2.32,43.81],[2,2.22,20.85]],"ltp":5.2,"tv":21.28,"id":12984951},{"batb":[[0,3.9,41.98],[1,3.85,29.41],[2,3.2,19.91]],"ltp":4.1,"tv":81.32,"id":12984952},{"batb":[[0,2.88,56.26],[1,2.84,51.75],[2,2.64,13.69]],"ltp":4.4,"tv":44.81,"id":16574984}]}]}
{"op":"mcm","clk":"1009474403","pt":1580644681453,"mc":[{"id":"1.168217555","rc":[{"batb":[[0,2.22,20.85],[1,1.01,0.51],[2,2.22,0]],"ltp":5.2,"tv":21.28,"id":12984951},{"batb":[[0,3.2,19.91],[1,1.01,0.51],[2,3.2,0]],"ltp":4.1,"tv":81.32,"id":12984952},{"batb":[[0,2.64,13.69],[1,1.01,0.51],[2,2.64,0]],"ltp":4.4,"tv":44.81,"id":16574984}]}]}
{"op":"mcm","clk":"1009474726","pt":1580644684383,"mc":[{"id":"1.168217555","rc":[{"batb":[[1,2.2,76.86],[2,2.18,52.36]],"ltp":5.2,"tv":21.28,"id":12984951},{"batb":[[0,3.25,36.21],[1,3.2,66.12],[2,1.01,0.51]],"ltp":4.1,"tv":81.32,"id":12984952},{"batb":[[0,2.68,63.05],[1,2.64,76.14],[2,1.01,0.51]],"ltp":4.4,"tv":44.81,"id":16574984}]}]}
{"op":"mcm","clk":"1009474936","pt":1580644686164,"mc":[{"id":"1.168217555","rc":[{"batb":[[0,3.2,19.91],[1,1.01,0.51],[2,1.01,0]],"ltp":4.1,"tv":81.32,"id":12984952}]}]}
{"op":"mcm","clk":"1009475314","pt":1580644689357,"mc":[{"id":"1.168217555","rc":[{"batb":[[0,4.9,33.89],[1,4.8,34.88],[2,3.2,19.91]],"ltp":4.1,"tv":81.32,"id":12984952},{"batb":[[0,2.64,13.69],[1,1.01,0.51],[2,1.01,0]],"ltp":4.4,"tv":44.81,"id":16574984}]}]}
{"op":"mcm","clk":"1009475392","pt":1580644689980,"mc":[{"id":"1.168217555","rc":[{"batl":[[0,2.36,20.3],[1,2.48,17.47]],"ltp":5.2,"tv":21.28,"id":12984951},{"batb":[[1,4.8,49.44],[2,3.8,25.65]],"batl":[[1,6.8,18.8]],"ltp":4.1,"tv":81.32,"id":12984952},{"batb":[[1,2.52,15.5],[2,1.01,0.51]],"batl":[[0,2.8,13.45],[1,3.05,10.86]],"ltp":4.4,"tv":44.81,"id":16574984}]}]}
{"op":"mcm","clk":"1009475542","pt":1580644690908,"mc":[{"id":"1.168217555","rc":[{"batb":[[0,2.22,54.46]],"batl":[[1,2.48,45.19]],"ltp":5.2,"tv":21.28,"id":12984951},{"batl":[[0,5.1,10.08],[1,5.5,14.01],[2,6.8,18.8]],"ltp":4.1,"tv":81.32,"id":12984952},{"batb":[[0,2.64,38.9]],"ltp":4.4,"tv":44.81,"id":16574984}]}]}
{"op":"mcm","clk":"1009475749","pt":1580644692476,"mc":[{"id":"1.168217555","rc":[{"batb":[[1,2.2,96.89]],"ltp":5.2,"tv":21.28,"id":12984951},{"batb":[[0,2.66,68.44],[1,2.64,38.9],[2,2.62,63.51]],"ltp":4.4,"tv":44.81,"id":16574984}]}]}
{"op":"mcm","clk":"1009476009","pt":1580644694792,"mc":[{"id":"1.168217555","rc":[{"batb":[[1,2.2,51.13],[2,2.16,22.58]],"ltp":5.2,"tv":21.28,"id":12984951},{"batb":[[0,2.66,46.01]],"ltp":4.4,"tv":44.81,"id":16574984}]}]}
{"op":"mcm","clk":"1009476399","pt":1580644698492,"mc":[{"id":"1.168217555","rc":[{"batb":[[0,2.22,117.06]],"ltp":5.2,"tv":21.28,"id":12984951},{"batb":[[0,4.9,45.57]],"ltp":4.1,"tv":81.32,"id":12984952}]}]}
{"op":"mcm","clk":"1009477119","pt":1580644705005,"mc":[{"id":"1.168217555","rc":[{"batb":[[0,14,13.44],[1,1.01,0.51]],"ltp":5.1,"tv":4.54,"id":16574983}]}]}
{"op":"mcm","clk":"1009477542","pt":1580644708406,"mc":[{"id":"1.168217555","rc":[{"batb":[[0,2.22,33.61],[1,2.16,22.58],[2,1.01,0.51]],"batl":[[0,2.48,45.19],[1,2.48,0]],"ltp":5.2,"tv":21.28,"id":12984951},{"batb":[[0,3.8,25.65],[1,1.01,0.51],[2,3.8,0]],"batl":[[1,6.8,18.8],[2,6.8,0]],"ltp":4.1,"tv":81.32,"id":12984952},{"batb":[[0,2.64,25.21],[1,2.52,15.5],[2,1.01,0.51]],"batl":[[0,3.05,10.86],[1,3.05,0]],"ltp":4.4,"tv":44.81,"id":16574984}]}]}
{"op":"mcm","clk":"1009477718","pt":1580644710019,"mc":[{"id":"1.168217555","rc":[{"batb":[[0,2.16,22.58],[1,1.01,0.51],[2,1.01,0]],"batl":[[0,2.48,17.47]],"ltp":5.2,"tv":21.28,"id":12984951},{"batl":[[0,6.8,18.8],[1,6.8,0]],"ltp":4.1,"tv":81.32,"id":12984952},{"batb":[[0,2.52,15.5],[1,1.01,0.51],[2,1.01,0]],"ltp":4.4,"tv":44.81,"id":16574984}]}]}
{"op":"mcm","clk":"1009477850","pt":1580644711327,"mc":[{"id":"1.168217555","rc":[{"batb":[[0,2.16,71.78],[1,2.14,55.47],[2,1.01,0.51]],"batl":[[1,2.5,17.47]],"ltp":5.2,"tv":21.28,"id":12984951},{"batb":[[0,3.95,28.64],[1,3.9,28.81],[2,3.8,25.65]],"ltp":4.1,"tv":81.32,"id":12984952},{"batb":[[0,2.54,74.5],[1,2.52,15.5],[2,2.5,71.77]],"ltp":4.4,"tv":44.81,"id":16574984}]}]}
{"op":"mcm","clk":"1009477937","pt":1580644712006,"mc":[{"id":"1.168217555","rc":[{"batb":[[0,2.16,22.58],[1,1.01,0.51],[2,1.01,0]],"batl":[[0,2.5,17.47],[1,2.5,0]],"ltp":5.2,"tv":21.28,"id":12984951},{"batb":[[0,3.8,25.65],[1,1.01,0.51],[2,3.8,0]],"ltp":4.1,"tv":81.32,"id":12984952},{"batb":[[0,2.52,15.5],[1,1.01,0.51],[2,2.5,0]],"ltp":4.4,"tv":44.81,"id":16574984}]}]}
{"op":"mcm","clk":"1009478303","pt":1580644715503,"mc":[{"id":"1.168217555","rc":[{"batb":[[0,2.24,71.55],[1,2.22,49.79],[2,2.16,22.58]],"ltp":5.2,"tv":21.28,"id":12984951},{"batb":[[0,4.7,32.74],[1,4.6,38.69],[2,3.8,25.65]],"ltp":4.1,"tv":81.32,"id":12984952},{"batb":[[0,2.7,43.51],[1,2.66,61.05],[2,2.52,15.5]],"ltp":4.4,"tv":44.81,"id":16574984}]}]}
{"op":"mcm","clk":"1009478668","pt":1580644719408,"mc":[{"id":"1.168217555","rc":[{"batb":[[0,2.16,22.58],[1,1.01,0.51],[2,2.16,0]],"ltp":5.2,"tv":21.28,"id":12984951},{"batb":[[0,3.8,25.65],[1,1.01,0.51],[2,3.8,0]],"ltp":4.1,"tv":81.32,"id":12984952},{"batb":[[0,2.52,15.5],[1,1.01,0.51],[2,2.52,0]],"ltp":4.4,"tv":44.81,"id":16574984}]}]}
{"op":"mcm","clk":"1009478980","pt":1580644722433,"mc":[{"id":"1.168217555","rc":[{"batb":[[0,2.16,77.21],[1,2.14,55.47],[2,1.01,0.51]],"ltp":5.2,"tv":21.28,"id":12984951},{"batb":[[0,3.95,30.56],[1,3.9,28.81],[2,3.8,25.65]],"ltp":4.1,"tv":81.32,"id":12984952},{"batb":[[0,2.54,67.78],[1,2.52,15.5],[2,2.5,71.77]],"ltp":4.4,"tv":44.81,"id":16574984}]}]}
{"op":"mcm","clk":"1009480677","pt":1580644739046,"mc":[{"id":"1.168217555","rc":[{"batb":[[0,2.16,22.58],[1,1.01,0.51],[2,1.01,0]],"ltp":5.2,"tv":21.28,"id":12984951},{"batb":[[0,3.95,42.51]],"ltp":4.1,"tv":81.32,"id":12984952},{"batb":[[0,2.52,15.5],[1,1.01,0.51],[2,2.5,0]],"ltp":4.4,"tv":44.81,"id":16574984}]}]}
{"op":"mcm","clk":"1009481125","pt":1580644742448,"mc":[{"id":"1.168217555","rc":[{"batb":[[0,2.36,17.86],[1,2.34,68.83],[2,2.32,43.94]],"batl":[[1,2.78,13.22]],"ltp":5.2,"tv":21.28,"id":12984951},{"batl":[[0,4.3,24.23],[1,5.3,15.03],[2,6.8,18.8]],"ltp":4.1,"tv":81.32,"id":12984952},{"batb":[[0,2.88,11.09],[1,2.86,36.22],[2,2.82,52.46]],"batl":[[1,3.5,19.59]],"ltp":4.4,"tv":44.81,"id":16574984}]}]}
