{"op":"mcm","clk":"1001415471","pt":1580567750513,"mc":[{"id":"1.168217554","marketDefinition":{"bspMarket":false,"turnInPlayEnabled":true,"persistenceEnabled":true,"marketBaseRate":5.0,"eventId":"29681263","eventTypeId":"2","numberOfWinners":1,"bettingType":"ODDS","marketType":"MATCH_ODDS","marketTime":"2020-02-02T11:30:00.000Z","suspendTime":"2020-02-02T11:30:00.000Z","bspReconciled":false,"complete":true,"inPlay":false,"crossMatching":false,"runnersVoidable":false,"numberOfActiveRunners":2,"betDelay":0,"status":"OPEN","runners":[{"status":"ACTIVE","sortPriority":1,"id":7412809,"name":"Evgeny Karlovskiy"},{"status":"ACTIVE","sortPriority":2,"id":2263624,"name":"Viktor Troicki"}],"regulators":["MR_INT"],"countryCode":"IN","discountAllowed":false,"timezone":"UTC","openDate":"2020-02-02T11:30:00.000Z","version":3145496345,"name":"Match Odds","eventName":"Karlovskiy v Troicki"},"rc":[{"batb":[[0,1.03,47.71],[1,1.02,3840.68],[2,1.01,3879.77]],"ltp":0.0,"tv":0.0,"id":2263624},{"batb":[[0,1.02,3786.16],[1,1.01,3879.77]],"ltp":0.0,"tv":0.0,"id":7412809}]}]}
{"op":"mcm","clk":"1001415705","pt":1580567751514,"mc":[{"id":"1.168217554","marketDefinition":{"bspMarket":false,"turnInPlayEnabled":true,"persistenceEnabled":true,"marketBaseRate":5.0,"eventId":"29681263","eventTypeId":"2","numberOfWinners":1,"bettingType":"ODDS","marketType":"MATCH_ODDS","marketTime":"2020-02-02T11:30:00.000Z","suspendTime":"2020-02-02T11:30:00.000Z","bspReconciled":false,"complete":true,"inPlay":false,"crossMatching":false,"runnersVoidable":false,"numberOfActiveRunners":2,"betDelay":0,"status":"OPEN","runners":[{"status":"ACTIVE","sortPriority":1,"id":7412809,"name":"Evgeny Karlovskiy"},{"status":"ACTIVE","sortPriority":2,"id":2263624,"name":"Viktor Troicki"}],"regulators":["MR_INT"],"countryCode":"IN","discountAllowed":false,"timezone":"UTC","openDate":"2020-02-02T11:30:00.000Z","version":3145496345,"name":"Match Odds","eventName":"Karlovskiy v Troicki"},"rc":[{"batb":[[0,1.05,152.2],[1,1.04,168.86],[2,1.03,237.77]],"ltp":0.0,"tv":0.0,"id":2263624},{"batb":[[1,1.01,4132.68]],"ltp":0.0,"tv":0.0,"id":7412809}]}]}
{"op":"mcm","clk":"1001415945","pt":1580567752496,"mc":[{"id":"1.168217554","marketDefinition":{"bspMarket":false,"turnInPlayEnabled":true,"persistenceEnabled":true,"marketBaseRate":5.0,"eventId":"29681263","eventTypeId":"2","numberOfWinners":1,"bettingType":"ODDS","marketType":"MATCH_ODDS","marketTime":"2020-02-02T11:30:00.000Z","suspendTime":"2020-02-02T11:30:00.000Z","bspReconciled":false,"complete":true,"inPlay":false,"crossMatching":false,"runnersVoidable":false,"numberOfActiveRunners":2,"betDelay":0,"status":"OPEN","runners":[{"status":"ACTIVE","sortPriority":1,"id":7412809,"name":"Evgeny Karlovskiy"},{"status":"ACTIVE","sortPriority":2,"id":2263624,"name":"Viktor Troicki"}],"regulators":["MR_INT"],"countryCode":"IN","discountAllowed":true,"timezone":"UTC","openDate":"2020-02-02T11:30:00.000Z","version":3145496345,"name":"Match Odds","eventName":"Karlovskiy v Troicki"}}]}
{"op":"mcm","clk":"1001422102","pt":1580567781601,"mc":[{"id":"1.168217554","marketDefinition":{"bspMarket":false,"turnInPlayEnabled":true,"persistenceEnabled":true,"marketBaseRate":5.0,"eventId":"29681263","eventTypeId":"2","numberOfWinners":1,"bettingType":"ODDS","marketType":"MATCH_ODDS","marketTime":"2020-02-02T11:30:00.000Z","suspendTime":"2020-02-02T11:30:00.000Z","bspReconciled":false,"complete":true,"inPlay":false,"crossMatching":true,"runnersVoidable":false,"numberOfActiveRunners":2,"betDelay":0,"status":"OPEN","runners":[{"status":"ACTIVE","sortPriority":1,"id":7412809,"name":"Evgeny Karlovskiy"},{"status":"ACTIVE","sortPriority":2,"id":2263624,"name":"Viktor Troicki"}],"regulators":["MR_INT"],"countryCode":"IN","discountAllowed":true,"timezone":"UTC","openDate":"2020-02-02T11:30:00.000Z","version":3145496345,"name":"Match Odds","eventName":"Karlovskiy v Troicki"}}]}
{"op":"mcm","clk":"1001428908","pt":1580567812969,"mc":[{"id":"1.168217554","rc":[{"batb":[[1,1.01,4432.68]],"ltp":0.0,"tv":0.0,"id":7412809}]}]}
{"op":"mcm","clk":"1001430015","pt":1580567817957,"mc":[{"id":"1.168217554","rc":[{"batb":[[1,1.01,4132.68]],"ltp":0.0,"tv":0.0,"id":7412809}]}]}
{"op":"mcm","clk":"1001487340","pt":1580568080191,"mc":[{"id":"1.168217554","rc":[{"batb":[[0,1.06,50.48],[1,1.05,152.2],[2,1.04,168.86]],"ltp":0.0,"tv":0.0,"id":2263624},{"batb":[[0,1.03,100.96],[1,1.02,3786.16],[2,1.01,4132.68]],"ltp":0.0,"tv":0.0,"id":7412809}]}]}
{"op":"mcm","clk":"1001538085","pt":1580568313307,"mc":[{"id":"1.168217554","rc":[{"batb":[[2,1.01,4112.68]],"ltp":0.0,"tv":0.0,"id":7412809}]}]}
{"op":"mcm","clk":"1001545936","pt":1580568349180,"mc":[{"id":"1.168217554","rc":[{"batb":[[0,1.03,109.36],[1,1.02,3811.36]],"ltp":0.0,"tv":0.0,"id":7412809}]}]}
{"op":"mcm","clk":"1001657227","pt":1580568869897,"mc":[{"id":"1.168217554","rc":[{"batb":[[0,1.13,75.72],[1,1.03,109.36],[2,1.02,3811.36]],"ltp":0.0,"tv":0.0,"id":7412809}]}]}
{"op":"mcm","clk":"1001908985","pt":1580569936152,"mc":[{"id":"1.168217554","rc":[{"batl":[[0,990,2.2]],"ltp":0.0,"tv":0.0,"id":2263624},{"batl":[[0,990,2.2]],"ltp":0.0,"tv":0.0,"id":7412809}]}]}
{"op":"mcm","clk":"1002141592","pt":1580570931178,"mc":[{"id":"1.168217554","rc":[{"batb":[[2,1.02,25.21]],"ltp":0.0,"tv":0.0,"id":7412809}]}]}
{"op":"mcm","clk":"1003363684","pt":1580576338318,"mc":[{"id":"1.168217554","rc":[{"batb":[[0,1.07,15.12],[1,1.06,50.48],[2,1.05,152.2]],"batl":[[0,10.5,3.36],[1,990,2.2]],"ltp":0.0,"tv":0.0,"id":2263624},{"batb":[[0,1.14,15.12],[1,1.13,75.72],[2,1.03,109.36]],"ltp":0.0,"tv":0.0,"id":7412809}]}]}
{"op":"mcm","clk":"1003363715","pt":1580576338534,"mc":[{"id":"1.168217554","rc":[{"batl":[[0,15,3.36],[1,990,2.2]],"ltp":0.0,"tv":0.0,"id":7412809}]}]}
{"op":"mcm","clk":"1003403140","pt":1580576559941,"mc":[{"id":"1.168217554","rc":[{"batb":[[0,1.08,37.86],[1,1.07,15.12]],"ltp":0.0,"tv":0.0,"id":2263624}]}]}
{"op":"mcm","clk":"1003407112","pt":1580576580684,"mc":[{"id":"1.168217554","rc":[{"batb":[[1,1.05,152.2],[2,1.04,168.86]],"ltp":0.0,"tv":0.0,"id":2263624}]}]}
{"op":"mcm","clk":"1003419006","pt":1580576641837,"mc":[{"id":"1.168217554","rc":[{"batb":[[0,1.09,15.12],[1,1.08,37.86],[2,1.05,152.2]],"ltp":0.0,"tv":0.0,"id":2263624}]}]}
{"op":"mcm","clk":"1003423224","pt":1580576662834,"mc":[{"id":"1.168217554","rc":[{"batb":[[0,1.43,36.73],[1,1.09,15.12],[2,1.08,37.86]],"ltp":0.0,"tv":0.0,"id":2263624},{"batb":[[0,2.04,22.37],[1,1.14,15.12],[2,1.13,75.72]],"ltp":0.0,"tv":0.0,"id":7412809}]}]}
{"op":"mcm","clk":"1003424507","pt":1580576669752,"mc":[{"id":"1.168217554","rc":[{"batb":[[0,1.09,15.12],[1,1.08,37.86],[2,1.05,152.2]],"ltp":0.0,"tv":0.0,"id":2263624},{"batb":[[0,1.14,15.12],[1,1.13,75.72],[2,1.03,109.36]],"ltp":0.0,"tv":0.0,"id":7412809}]}]}
{"op":"mcm","clk":"1003424770","pt":1580576671051,"mc":[{"id":"1.168217554","rc":[{"batb":[[0,1.43,36.73],[1,1.09,15.12],[2,1.08,37.86]],"ltp":0.0,"tv":0.0,"id":2263624},{"batb":[[0,2.04,22.37],[1,1.14,15.12],[2,1.13,75.72]],"ltp":0.0,"tv":0.0,"id":7412809}]}]}
{"op":"mcm","clk":"1003431025","pt":1580576703218,"mc":[{"id":"1.168217554","rc":[{"batb":[[1,1.08,37.86],[2,1.05,152.2]],"ltp":0.0,"tv":0.0,"id":2263624}]}]}
{"op":"mcm","clk":"1003431120","pt":1580576703695,"mc":[{"id":"1.168217554","rc":[{"batb":[[1,1.13,75.72],[2,1.03,109.36]],"ltp":0.0,"tv":0.0,"id":7412809}]}]}
{"op":"mcm","clk":"1003442797","pt":1580576763463,"mc":[{"id":"1.168217554","rc":[{"batb":[[0,2.06,10.08]],"ltp":0.0,"tv":0.0,"id":7412809}]}]}
{"op":"mcm","clk":"1003442879","pt":1580576763934,"mc":[{"id":"1.168217554","rc":[{"batb":[[0,1.51,34.77],[1,1.44,10.08],[2,1.08,37.86]],"ltp":0.0,"tv":0.0,"id":2263624},{"batb":[[0,2.08,21.81],[1,2.06,10.08],[2,1.13,75.72]],"ltp":0.0,"tv":0.0,"id":7412809}]}]}
{"op":"mcm","clk":"1003448731","pt":1580576791484,"mc":[{"id":"1.168217554","rc":[{"batb":[[2,2.02,45.43]],"ltp":0.0,"tv":0.0,"id":7412809}]}]}
{"op":"mcm","clk":"1003448795","pt":1580576791754,"mc":[{"id":"1.168217554","rc":[{"batb":[[1,1.46,35.59],[2,1.44,10.08]],"ltp":0.0,"tv":0.0,"id":2263624}]}]}
{"op":"mcm","clk":"1003449800","pt":1580576796869,"mc":[{"id":"1.168217554","rc":[{"batb":[[0,1.46,35.59],[1,1.44,10.08],[2,1.08,37.86]],"ltp":0.0,"tv":0.0,"id":2263624}]}]}
{"op":"mcm","clk":"1003450098","pt":1580576798333,"mc":[{"id":"1.168217554","rc":[{"batb":[[0,1.45,42.41]],"ltp":0.0,"tv":0.0,"id":2263624},{"batb":[[0,2.14,45.43],[1,2.08,21.81],[2,2.06,10.08]],"ltp":0.0,"tv":0.0,"id":7412809}]}]}
{"op":"mcm","clk":"1003450246","pt":1580576799101,"mc":[{"id":"1.168217554","rc":[{"batb":[[0,2.3,22.58],[1,2.14,45.43]],"ltp":0.0,"tv":0.0,"id":7412809}]}]}
{"op":"mcm","clk":"1003450773","pt":1580576801497,"mc":[{"id":"1.168217554","rc":[{"batb":[[2,1.36,35.59]],"ltp":0.0,"tv":0.0,"id":2263624},{"batb":[[1,2.12,45.43]],"ltp":0.0,"tv":0.0,"id":7412809}]}]}
{"op":"mcm","clk":"1003450996","pt":1580576802487,"mc":[{"id":"1.168217554","rc":[{"batb":[[0,1.47,35.59],[1,1.45,42.41],[2,1.44,10.08]],"ltp":0.0,"tv":0.0,"id":2263624},{"batb":[[1,2.06,10.08],[2,1.13,75.72]],"ltp":0.0,"tv":0.0,"id":7412809}]}]}
{"op":"mcm","clk":"1003451111","pt":1580576802972,"mc":[{"id":"1.168217554","rc":[{"batb":[[0,1.48,35.26],[1,1.47,35.59]],"ltp":0.0,"tv":0.0,"id":2263624}]}]}
{"op":"mcm","clk":"1003453160","pt":1580576814074,"mc":[{"id":"1.168217554","rc":[{"batb":[[1,1.46,35.59]],"ltp":0.0,"tv":0.0,"id":2263624},{"batb":[[2,2.02,45.43]],"ltp":0.0,"tv":0.0,"id":7412809}]}]}
{"op":"mcm","clk":"1003454979","pt":1580576823961,"mc":[{"id":"1.168217554","rc":[{"batb":[[2,1.08,37.86]],"ltp":0.0,"tv":0.0,"id":2263624},{"batb":[[1,2.02,45.43],[2,1.13,75.72]],"ltp":0.0,"tv":0.0,"id":7412809}]}]}
{"op":"mcm","clk":"1003459235","pt":1580576848298,"mc":[{"id":"1.168217554","rc":[{"batb":[[0,1.55,33.79],[1,1.54,35.59]],"ltp":0.0,"tv":0.0,"id":2263624},{"batb":[[1,2.2,45.43]],"ltp":0.0,"tv":0.0,"id":7412809}]}]}
{"op":"mcm","clk":"1003524328","pt":1580577201893,"mc":[{"id":"1.168217554","rc":[{"batb":[[0,1.54,35.59],[1,1.08,37.86],[2,1.05,152.2]],"ltp":0.0,"tv":0.0,"id":2263624}]}]}
{"op":"mcm","clk":"1003525359","pt":1580577207134,"mc":[{"id":"1.168217554","rc":[{"batb":[[0,1.08,37.86],[1,1.05,152.2],[2,1.04,168.86]],"ltp":0.0,"tv":0.0,"id":2263624}]}]}
{"op":"mcm","clk":"1003525502","pt":1580577207834,"mc":[{"id":"1.168217554","rc":[{"batb":[[0,1.36,41.68],[1,1.08,37.86],[2,1.05,152.2]],"ltp":0.0,"tv":0.0,"id":2263624}]}]}
{"op":"mcm","clk":"1003526988","pt":1580577215479,"mc":[{"id":"1.168217554","rc":[{"batb":[[0,1.48,35.59]],"ltp":0.0,"tv":0.0,"id":2263624},{"batb":[[1,2.22,45.43]],"ltp":0.0,"tv":0.0,"id":7412809}]}]}
{"op":"mcm","clk":"1003527022","pt":1580577215653,"mc":[{"id":"1.168217554","rc":[{"batb":[[0,1.49,38.01],[1,1.48,35.59],[2,1.08,37.86]],"ltp":0.0,"tv":0.0,"id":2263624}]}]}
{"op":"mcm","clk":"1003557722","pt":1580577379467,"mc":[{"id":"1.168217554","rc":[{"batb":[[0,2.34,45.43],[1,1.13,75.72],[2,1.03,109.36]],"ltp":0.0,"tv":0.0,"id":7412809}]}]}
{"op":"mcm","clk":"1003557751","pt":1580577379709,"mc":[{"id":"1.168217554","rc":[{"batb":[[0,2.4,20.26],[1,2.34,45.43],[2,1.13,75.72]],"ltp":0.0,"tv":0.0,"id":7412809}]}]}
{"op":"mcm","clk":"1004069495","pt":1580580271452,"mc":[{"id":"1.168217554","rc":[{"batb":[[0,2.34,45.43],[1,1.13,75.72],[2,1.03,109.36]],"ltp":0.0,"tv":0.0,"id":7412809}]}]}
{"op":"mcm","clk":"1004069559","pt":1580580271821,"mc":[{"id":"1.168217554","rc":[{"batb":[[0,2.42,20.13],[1,2.34,45.43],[2,1.13,75.72]],"ltp":0.0,"tv":0.0,"id":7412809}]}]}
{"op":"mcm","clk":"1004107043","pt":1580580482217,"mc":[{"id":"1.168217554","rc":[{"batb":[[0,1.49,56.72]],"ltp":0.0,"tv":0.0,"id":2263624},{"batb":[[0,2.42,30.13]],"ltp":0.0,"tv":0.0,"id":7412809}]}]}
{"op":"mcm","clk":"1004107309","pt":1580580483722,"mc":[{"id":"1.168217554","rc":[{"batb":[[2,1.44,65.39]],"ltp":0.0,"tv":0.0,"id":2263624},{"batb":[[2,2.2,23.98]],"ltp":0.0,"tv":0.0,"id":7412809}]}]}
{"op":"mcm","clk":"1004167321","pt":1580580809095,"mc":[{"id":"1.168217554","rc":[{"batb":[[0,1.5,56.82]],"ltp":0.0,"tv":0.0,"id":2263624}]}]}
{"op":"mcm","clk":"1004173108","pt":1580580838365,"mc":[{"id":"1.168217554","rc":[{"batb":[[0,1.51,56.44]],"ltp":0.0,"tv":0.0,"id":2263624},{"batb":[[0,2.44,30.17]],"ltp":0.0,"tv":0.0,"id":7412809}]}]}
{"op":"mcm","clk":"1004177283","pt":1580580860389,"mc":[{"id":"1.168217554","rc":[{"batb":[[1,1.44,65.39],[2,1.08,37.86]],"ltp":0.0,"tv":0.0,"id":2263624}]}]}
{"op":"mcm","clk":"1004177344","pt":1580580860722,"mc":[{"id":"1.168217554","rc":[{"batb":[[1,1.48,61.34],[2,1.44,65.39]],"ltp":0.0,"tv":0.0,"id":2263624}]}]}
{"op":"mcm","clk":"1004212256","pt":1580581045537,"mc":[{"id":"1.168217554","rc":[{"batb":[[0,2.34,45.43],[1,2.2,23.98],[2,1.13,75.72]],"ltp":0.0,"tv":0.0,"id":7412809}]}]}
{"op":"mcm","clk":"1004212856","pt":1580581048439,"mc":[{"id":"1.168217554","rc":[{"batb":[[0,1.55,61.34],[1,1.51,56.44],[2,1.08,37.86]],"ltp":0.0,"tv":0.0,"id":2263624},{"batb":[[0,1.13,75.72],[1,1.03,109.36],[2,1.02,25.41]],"ltp":0.0,"tv":0.0,"id":7412809}]}]}
{"op":"mcm","clk":"1004212953","pt":1580581048928,"mc":[{"id":"1.168217554","rc":[{"batb":[[2,1.5,57.55]],"ltp":0.0,"tv":0.0,"id":2263624},{"batb":[[0,2.22,40.89],[1,2.06,27.15],[2,1.13,75.72]],"ltp":0.0,"tv":0.0,"id":7412809}]}]}
{"op":"mcm","clk":"1004214913","pt":1580581058852,"mc":[{"id":"1.168217554","rc":[{"batb":[[0,1.54,40.89]],"ltp":0.0,"tv":0.0,"id":2263624}]}]}
{"op":"mcm","clk":"1004246814","pt":1580581226422,"mc":[{"id":"1.168217554","rc":[{"batb":[[0,1.54,59.06],[1,1.5,57.55],[2,1.08,37.86]],"ltp":0.0,"tv":0.0,"id":2263624},{"batb":[[0,2.24,30.52],[1,2.22,40.89],[2,2.06,27.15]],"ltp":0.0,"tv":0.0,"id":7412809}]}]}
{"op":"mcm","clk":"1004246833","pt":1580581226531,"mc":[{"id":"1.168217554","rc":[{"batb":[[0,1.57,49.92],[1,1.54,59.06],[2,1.5,57.55]],"ltp":0.0,"tv":0.0,"id":2263624}]}]}
{"op":"mcm","clk":"1004247391","pt":1580581229565,"mc":[{"id":"1.168217554","rc":[{"batb":[[1,1.54,118.13]],"ltp":0.0,"tv":0.0,"id":2263624}]}]}
{"op":"mcm","clk":"1004247643","pt":1580581230976,"mc":[{"id":"1.168217554","rc":[{"batb":[[1,1.54,59.06]],"ltp":0.0,"tv":0.0,"id":2263624}]}]}
{"op":"mcm","clk":"1004699804","pt":1580583875491,"mc":[{"id":"1.168217554","rc":[{"batb":[[0,1.57,66.34],[2,1.08,37.86]],"ltp":0.0,"tv":0.0,"id":2263624},{"batb":[[0,2.24,40.52],[2,1.13,75.72]],"ltp":0.0,"tv":0.0,"id":7412809}]}]}
{"op":"mcm","clk":"1004699929","pt":1580583876174,"mc":[{"id":"1.168217554","rc":[{"batb":[[2,1.5,75.72]],"ltp":0.0,"tv":0.0,"id":2263624},{"batb":[[2,2.06,35.72]],"ltp":0.0,"tv":0.0,"id":7412809}]}]}
{"op":"mcm","clk":"1004808359","pt":1580584438508,"mc":[{"id":"1.168217554","rc":[{"batb":[[0,1.54,59.06],[1,1.5,75.72],[2,1.08,37.86]],"ltp":0.0,"tv":0.0,"id":2263624}]}]}
{"op":"mcm","clk":"1004808447","pt":1580584438895,"mc":[{"id":"1.168217554","rc":[{"batb":[[0,1.56,67.08],[1,1.54,59.06],[2,1.5,75.72]],"ltp":0.0,"tv":0.0,"id":2263624}]}]}
{"op":"mcm","clk":"1004886003","pt":1580584827129,"mc":[{"id":"1.168217554","rc":[{"batb":[[0,2.24,40.77]],"ltp":0.0,"tv":0.0,"id":7412809}]}]}
{"op":"mcm","clk":"1004968465","pt":1580585303369,"mc":[{"id":"1.168217554","rc":[{"batl":[[1,95,15.9],[2,990,2.2]],"ltp":0.0,"tv":0.0,"id":2263624},{"batl":[[1,95,15.9],[2,990,2.2]],"ltp":0.0,"tv":0.0,"id":7412809}]}]}
{"op":"mcm","clk":"1005222362","pt":1580586929223,"mc":[{"id":"1.168217554","rc":[{"batb":[[0,1.6,100.02]],"ltp":0.0,"tv":0.0,"id":2263624},{"batb":[[0,2.38,64.54]],"ltp":0.0,"tv":0.0,"id":7412809}]}]}
{"op":"mcm","clk":"1005313298","pt":1580587551849,"mc":[{"id":"1.168217554","rc":[{"batb":[[2,1.08,37.86]],"ltp":0.0,"tv":0.0,"id":2263624},{"batb":[[2,1.13,75.72]],"ltp":0.0,"tv":0.0,"id":7412809}]}]}
{"op":"mcm","clk":"1005313428","pt":1580587552534,"mc":[{"id":"1.168217554","rc":[{"batb":[[2,1.5,95.41]],"ltp":0.0,"tv":0.0,"id":2263624},{"batb":[[2,2.06,45]],"ltp":0.0,"tv":0.0,"id":7412809}]}]}
{"op":"mcm","clk":"1005559838","pt":1580589036155,"mc":[{"id":"1.168217554","rc":[{"batb":[[0,2.4,50.91],[1,2.38,64.54],[2,2.22,40.89]],"ltp":0.0,"tv":0.0,"id":7412809}]}]}
{"op":"mcm","clk":"1005560069","pt":1580589037335,"mc":[{"id":"1.168217554","rc":[{"batb":[[1,1.44,108.42],[2,1.08,37.86]],"ltp":0.0,"tv":0.0,"id":2263624}]}]}
{"op":"mcm","clk":"1005560123","pt":1580589037615,"mc":[{"id":"1.168217554","rc":[{"batb":[[1,2.38,105.43],[2,2.2,39.75]],"ltp":0.0,"tv":0.0,"id":7412809}]}]}
{"op":"mcm","clk":"1005560424","pt":1580589039031,"mc":[{"id":"1.168217554","rc":[{"batb":[[1,1.48,61.34],[2,1.44,108.42]],"ltp":0.0,"tv":0.0,"id":2263624},{"batb":[[1,2.38,64.54],[2,2.34,40.89]],"ltp":0.0,"tv":0.0,"id":7412809}]}]}
{"op":"mcm","clk":"1005569195","pt":1580589087285,"mc":[{"id":"1.168217554","rc":[{"batb":[[1,2.34,40.89],[2,2.2,39.75]],"ltp":0.0,"tv":0.0,"id":7412809}]}]}
{"op":"mcm","clk":"1005569296","pt":1580589088083,"mc":[{"id":"1.168217554","rc":[{"batb":[[0,2.44,50.17],[1,2.42,44.07],[2,2.34,40.89]],"ltp":0.0,"tv":0.0,"id":7412809}]}]}
{"op":"mcm","clk":"1005592019","pt":1580589229408,"mc":[{"id":"1.168217554","rc":[{"batb":[[0,2.46,74.53],[1,2.34,40.89],[2,2.2,39.75]],"ltp":0.0,"tv":0.0,"id":7412809}]}]}
{"op":"mcm","clk":"1005767334","pt":1580590580032,"mc":[{"id":"1.168217554","rc":[{"batb":[[0,2.46,24.65]],"ltp":0.0,"tv":0.0,"id":7412809}]}]}
{"op":"mcm","clk":"1005767401","pt":1580590580644,"mc":[{"id":"1.168217554","rc":[{"batb":[[0,2.46,74.53]],"ltp":0.0,"tv":0.0,"id":7412809}]}]}
{"op":"mcm","clk":"1005768675","pt":1580590593473,"mc":[{"id":"1.168217554","rc":[{"batb":[[0,2.46,24.65]],"ltp":0.0,"tv":0.0,"id":7412809}]}]}
{"op":"mcm","clk":"1005768732","pt":1580590593999,"mc":[{"id":"1.168217554","rc":[{"batb":[[0,2.46,114.03]],"ltp":0.0,"tv":0.0,"id":7412809}]}]}
{"op":"mcm","clk":"1005768777","pt":1580590594575,"mc":[{"id":"1.168217554","rc":[{"batb":[[0,2.46,24.65]],"ltp":0.0,"tv":0.0,"id":7412809}]}]}
{"op":"mcm","clk":"1005768919","pt":1580590596304,"mc":[{"id":"1.168217554","rc":[{"batb":[[2,1.46,186.01]],"ltp":0.0,"tv":0.0,"id":2263624},{"batb":[[2,2.26,67.91]],"ltp":0.0,"tv":0.0,"id":7412809}]}]}
{"op":"mcm","clk":"1005769154","pt":1580590598791,"mc":[{"id":"1.168217554","rc":[{"batb":[[0,2.46,114.29]],"ltp":0.0,"tv":0.0,"id":7412809}]}]}
{"op":"mcm","clk":"1005874136","pt":1580591445434,"mc":[{"id":"1.168217554","rc":[{"batb":[[0,1.59,101.32]],"ltp":0.0,"tv":0.0,"id":2263624},{"batb":[[0,2.48,10.9],[1,2.46,24.65],[2,2.34,40.89]],"ltp":0.0,"tv":0.0,"id":7412809}]}]}
{"op":"mcm","clk":"1005877094","pt":1580591468431,"mc":[{"id":"1.168217554","rc":[{"batb":[[0,2.4,65.2],[1,2.34,40.89],[2,2.26,67.91]],"ltp":0.0,"tv":0.0,"id":7412809}]}]}
{"op":"mcm","clk":"1005877132","pt":1580591468741,"mc":[{"id":"1.168217554","rc":[{"batb":[[0,2.42,91.13],[1,2.4,65.2],[2,2.34,40.89]],"ltp":0.0,"tv":0.0,"id":7412809}]}]}
{"op":"mcm","clk":"1005896447","pt":1580591606321,"mc":[{"id":"1.168217554","rc":[{"batb":[[0,2.44,45.18],[1,2.42,91.13]],"ltp":0.0,"tv":0.0,"id":7412809}]}]}
{"op":"mcm","clk":"1005896517","pt":1580591606848,"mc":[{"id":"1.168217554","rc":[{"batb":[[0,2.46,89.64],[1,2.44,45.18]],"ltp":0.0,"tv":0.0,"id":7412809}]}]}
{"op":"mcm","clk":"1005916573","pt":1580591750509,"mc":[{"id":"1.168217554","rc":[{"batb":[[0,2.48,26.17],[1,2.46,89.64]],"ltp":0.0,"tv":0.0,"id":7412809}]}]}
{"op":"mcm","clk":"1005916603","pt":1580591750715,"mc":[{"id":"1.168217554","rc":[{"batb":[[1,2.34,40.89],[2,2.26,67.91]],"ltp":0.0,"tv":0.0,"id":7412809}]}]}
{"op":"mcm","clk":"1005935633","pt":1580591886410,"mc":[{"id":"1.168217554","rc":[{"batb":[[0,2.4,65.2]],"ltp":0.0,"tv":0.0,"id":7412809}]}]}
{"op":"mcm","clk":"1005935660","pt":1580591886626,"mc":[{"id":"1.168217554","rc":[{"batb":[[0,2.42,91.13],[1,2.4,65.2],[2,2.34,40.89]],"ltp":0.0,"tv":0.0,"id":7412809}]}]}
{"op":"mcm","clk":"1005953769","pt":1580592017468,"mc":[{"id":"1.168217554","rc":[{"batb":[[1,2.34,40.89],[2,2.26,67.91]],"ltp":0.0,"tv":0.0,"id":7412809}]}]}
{"op":"mcm","clk":"1005953846","pt":1580592018007,"mc":[{"id":"1.168217554","rc":[{"batb":[[0,2.46,89.64],[1,2.44,45.18],[2,2.34,40.89]],"ltp":0.0,"tv":0.0,"id":7412809}]}]}
{"op":"mcm","clk":"1005971344","pt":1580592147384,"mc":[{"id":"1.168217554","rc":[{"batb":[[0,2.48,26.17],[1,2.46,89.64]],"ltp":0.0,"tv":0.0,"id":7412809}]}]}
{"op":"mcm","clk":"1005971391","pt":1580592147687,"mc":[{"id":"1.168217554","rc":[{"batb":[[1,2.34,40.89],[2,2.26,67.91]],"ltp":0.0,"tv":0.0,"id":7412809}]}]}
{"op":"mcm","clk":"1005988796","pt":1580592277128,"mc":[{"id":"1.168217554","rc":[{"batb":[[0,2.42,91.13],[1,2.4,65.2],[2,2.34,40.89]],"ltp":0.0,"tv":0.0,"id":7412809}]}]}
{"op":"mcm","clk":"1006007342","pt":1580592412273,"mc":[{"id":"1.168217554","rc":[{"batb":[[0,2.44,45.18],[1,2.42,91.13]],"ltp":0.0,"tv":0.0,"id":7412809}]}]}
{"op":"mcm","clk":"1006007392","pt":1580592412654,"mc":[{"id":"1.168217554","rc":[{"batb":[[0,2.46,89.64],[1,2.44,45.18]],"ltp":0.0,"tv":0.0,"id":7412809}]}]}
{"op":"mcm","clk":"1006022868","pt":1580592541345,"mc":[{"id":"1.168217554","rc":[{"batb":[[0,2.48,26.17],[1,2.34,40.89],[2,2.26,67.91]],"ltp":0.0,"tv":0.0,"id":7412809}]}]}
{"op":"mcm","clk":"1006039003","pt":1580592672328,"mc":[{"id":"1.168217554","rc":[{"batb":[[0,2.4,65.2],[1,2.36,93.43],[2,2.34,40.89]],"ltp":0.0,"tv":0.0,"id":7412809}]}]}
{"op":"mcm","clk":"1006039045","pt":1580592672639,"mc":[{"id":"1.168217554","rc":[{"batb":[[0,2.42,91.13],[1,2.4,65.2]],"ltp":0.0,"tv":0.0,"id":7412809}]}]}
{"op":"mcm","clk":"1006056095","pt":1580592807498,"mc":[{"id":"1.168217554","rc":[{"batb":[[0,2.46,89.64],[1,2.44,45.18]],"ltp":0.0,"tv":0.0,"id":7412809}]}]}
{"op":"mcm","clk":"1006073365","pt":1580592939425,"mc":[{"id":"1.168217554","rc":[{"batb":[[0,2.48,26.17],[1,2.34,40.89],[2,2.26,67.91]],"ltp":0.0,"tv":0.0,"id":7412809}]}]}
{"op":"mcm","clk":"1006089827","pt":1580593074348,"mc":[{"id":"1.168217554","rc":[{"batb":[[0,2.4,65.2]],"ltp":0.0,"tv":0.0,"id":7412809}]}]}
{"op":"mcm","clk":"1006089897","pt":1580593074932,"mc":[{"id":"1.168217554","rc":[{"batb":[[0,2.42,91.13],[1,2.4,65.2],[2,2.34,40.89]],"ltp":0.0,"tv":0.0,"id":7412809}]}]}
{"op":"mcm","clk":"1006104868","pt":1580593206503,"mc":[{"id":"1.168217554","rc":[{"batb":[[0,2.44,45.18],[1,2.34,40.89],[2,2.26,67.91]],"ltp":0.0,"tv":0.0,"id":7412809}]}]}
{"op":"mcm","clk":"1006104882","pt":1580593206606,"mc":[{"id":"1.168217554","rc":[{"batb":[[0,2.46,89.64],[1,2.44,45.18],[2,2.34,40.89]],"ltp":0.0,"tv":0.0,"id":7412809}]}]}
{"op":"mcm","clk":"1006120764","pt":1580593337266,"mc":[{"id":"1.168217554","rc":[{"batb":[[0,2.48,26.17],[1,2.34,40.89],[2,2.26,67.91]],"ltp":0.0,"tv":0.0,"id":7412809}]}]}
{"op":"mcm","clk":"1006137754","pt":1580593469180,"mc":[{"id":"1.168217554","rc":[{"batb":[[0,2.4,157.06]],"ltp":0.0,"tv":0.0,"id":7412809}]}]}
{"op":"mcm","clk":"1006163002","pt":1580593677486,"mc":[{"id":"1.168217554","rc":[{"batb":[[0,2.4,155.38]],"ltp":0.0,"tv":0.0,"id":7412809}]}]}
{"op":"mcm","clk":"1006163024","pt":1580593677685,"mc":[{"id":"1.168217554","rc":[{"batb":[[0,1.59,103.88]],"ltp":0.0,"tv":0.0,"id":2263624}]}]}
{"op":"mcm","clk":"1006211582","pt":1580594189044,"mc":[{"id":"1.168217554","rc":[{"batb":[[0,1.6,6.5],[1,1.59,103.88],[2,1.48,61.34]],"ltp":0.0,"tv":0.0,"id":2263624}]}]}
{"op":"mcm","clk":"1006217941","pt":1580594261732,"mc":[{"id":"1.168217554","rc":[{"batb":[[0,1.61,68.32],[1,1.6,6.5]],"ltp":0.0,"tv":0.0,"id":2263624}]}]}
{"op":"mcm","clk":"1006363532","pt":1580595573446,"mc":[{"id":"1.168217554","rc":[{"batb":[[1,2.36,40.89]],"ltp":0.0,"tv":0.0,"id":7412809}]}]}
{"op":"mcm","clk":"1006470294","pt":1580596592744,"mc":[{"id":"1.168217554","rc":[{"batb":[[0,1.62,420.1],[1,1.61,68.32],[2,1.6,6.5]],"ltp":0.0,"tv":0.0,"id":2263624}]}]}
{"op":"mcm","clk":"1006470524","pt":1580596595044,"mc":[{"id":"1.168217554","rc":[{"batb":[[1,1.61,488.42]],"ltp":0.0,"tv":0.0,"id":2263624}]}]}
{"op":"mcm","clk":"1006471031","pt":1580596600014,"mc":[{"id":"1.168217554","rc":[{"batb":[[2,1.6,426.6]],"ltp":0.0,"tv":0.0,"id":2263624}]}]}
{"op":"mcm","clk":"1006478856","pt":1580596680063,"mc":[{"id":"1.168217554","rc":[{"batb":[[1,1.61,420.1]],"ltp":0.0,"tv":0.0,"id":2263624}]}]}
{"op":"mcm","clk":"1006478920","pt":1580596680687,"mc":[{"id":"1.168217554","rc":[{"batb":[[0,1.63,34.54],[1,1.62,420.1],[2,1.61,420.1]],"ltp":0.0,"tv":0.0,"id":2263624}]}]}
{"op":"mcm","clk":"1006497789","pt":1580596868030,"mc":[{"id":"1.168217554","rc":[{"batb":[[0,1.62,454.79],[1,1.61,420.1],[2,1.6,426.6]],"ltp":0.0,"tv":0.0,"id":2263624},{"batb":[[0,2.42,64.26],[1,2.4,91.86],[2,2.36,40.89]],"ltp":0.0,"tv":0.0,"id":7412809}]}]}
{"op":"mcm","clk":"1006500487","pt":1580596893273,"mc":[{"id":"1.168217554","rc":[{"batb":[[1,2.36,40.89],[2,2.26,67.91]],"ltp":0.0,"tv":0.0,"id":7412809}]}]}
{"op":"mcm","clk":"1006500629","pt":1580596894364,"mc":[{"id":"1.168217554","rc":[{"batb":[[0,2.44,90.92],[1,2.42,64.26],[2,2.36,40.89]],"ltp":0.0,"tv":0.0,"id":7412809}]}]}
{"op":"mcm","clk":"1006505973","pt":1580596947602,"mc":[{"id":"1.168217554","rc":[{"batb":[[0,2.46,44.67],[1,2.44,90.92]],"ltp":0.0,"tv":0.0,"id":7412809}]}]}
{"op":"mcm","clk":"1006516695","pt":1580597070193,"mc":[{"id":"1.168217554","rc":[{"batb":[[1,2.36,40.89],[2,2.26,67.91]],"ltp":0.0,"tv":0.0,"id":7412809}]}]}
{"op":"mcm","clk":"1006518194","pt":1580597086904,"mc":[{"id":"1.168217554","rc":[{"batb":[[0,2.46,90.01],[1,2.42,64.26],[2,2.36,40.89]],"ltp":0.0,"tv":0.0,"id":7412809}]}]}
{"op":"mcm","clk":"1006529462","pt":1580597219442,"mc":[{"id":"1.168217554","rc":[{"batb":[[0,2.48,35.25],[1,2.46,90.01]],"ltp":0.0,"tv":0.0,"id":7412809}]}]}
{"op":"mcm","clk":"1006536530","pt":1580597304489,"mc":[{"id":"1.168217554","rc":[{"batb":[[0,1.62,444.96]],"ltp":0.0,"tv":0.0,"id":2263624}]}]}
{"op":"mcm","clk":"1006536535","pt":1580597304596,"mc":[{"id":"1.168217554","rc":[{"batb":[[0,2.48,41.61]],"ltp":0.0,"tv":0.0,"id":7412809}]}]}
{"op":"mcm","clk":"1006583639","pt":1580597969240,"mc":[{"id":"1.168217554","rc":[{"trd":[[2.48,83.21]],"batb":[[0,2.36,40.89],[1,2.26,67.91],[2,2.22,37.86]],"ltp":2.48,"tv":83.21,"id":7412809}],"tv":83.21}]}
{"op":"mcm","clk":"1006583760","pt":1580597971203,"mc":[{"id":"1.168217554","rc":[{"batb":[[1,2.22,37.86],[2,2,37.86]],"ltp":2.48,"tv":83.21,"id":7412809}]}]}
{"op":"mcm","clk":"1006583814","pt":1580597972029,"mc":[{"id":"1.168217554","rc":[{"batb":[[0,1.63,73.72],[1,1.62,444.96],[2,1.61,420.1]],"ltp":0.0,"tv":0.0,"id":2263624},{"batb":[[0,2.38,42.01],[1,2.36,40.89],[2,2.22,37.86]],"ltp":2.48,"tv":83.21,"id":7412809}]}]}
{"op":"mcm","clk":"1006583935","pt":1580597974330,"mc":[{"id":"1.168217554","rc":[{"batb":[[1,2.22,37.86],[2,2.16,73.76]],"ltp":2.48,"tv":83.21,"id":7412809}]}]}
{"op":"mcm","clk":"1006584228","pt":1580597979152,"mc":[{"id":"1.168217554","rc":[{"batb":[[1,2.24,40.89],[2,2.22,37.86]],"ltp":2.48,"tv":83.21,"id":7412809}]}]}
{"op":"mcm","clk":"1006586758","pt":1580598018337,"mc":[{"id":"1.168217554","rc":[{"batb":[[1,2.22,37.86],[2,2,37.86]],"ltp":2.48,"tv":83.21,"id":7412809}]}]}
{"op":"mcm","clk":"1006586802","pt":1580598018800,"mc":[{"id":"1.168217554","rc":[{"batb":[[2,2.12,76.4]],"ltp":2.48,"tv":83.21,"id":7412809}]}]}
{"op":"mcm","clk":"1006586983","pt":1580598020188,"mc":[{"id":"1.168217554","rc":[{"batb":[[1,2.22,78.75]],"ltp":2.48,"tv":83.21,"id":7412809}]}]}
{"op":"mcm","clk":"1006587272","pt":1580598024495,"mc":[{"id":"1.168217554","rc":[{"batb":[[0,2.22,78.75],[1,2.12,76.4],[2,2,37.86]],"ltp":2.48,"tv":83.21,"id":7412809}]}]}
{"op":"mcm","clk":"1006587278","pt":1580598024596,"mc":[{"id":"1.168217554","rc":[{"batb":[[0,2.34,63.41],[1,2.22,78.75],[2,2.12,76.4]],"ltp":2.48,"tv":83.21,"id":7412809}]}]}
{"op":"mcm","clk":"1006599761","pt":1580598219237,"mc":[{"id":"1.168217554","rc":[{"batb":[[1,2.22,37.86],[2,2.08,79.23]],"ltp":2.48,"tv":83.21,"id":7412809}]}]}
{"op":"mcm","clk":"1006600371","pt":1580598227859,"mc":[{"id":"1.168217554","rc":[{"batb":[[2,2.16,42.4]],"ltp":2.48,"tv":83.21,"id":7412809}]}]}
{"op":"mcm","clk":"1006624567","pt":1580598531099,"mc":[{"id":"1.168217554","rc":[{"batb":[[2,2.18,42.4]],"ltp":2.48,"tv":83.21,"id":7412809}]}]}
{"op":"mcm","clk":"1006649546","pt":1580598841441,"mc":[{"id":"1.168217554","rc":[{"batb":[[0,1.63,80.22]],"ltp":0.0,"tv":0.0,"id":2263624}]}]}
{"op":"mcm","clk":"1006658737","pt":1580598940061,"mc":[{"id":"1.168217554","rc":[{"batb":[[0,1.64,8.04],[1,1.63,80.22],[2,1.62,420.1]],"ltp":0.0,"tv":0.0,"id":2263624}]}]}
{"op":"mcm","clk":"1006875032","pt":1580601490385,"mc":[{"id":"1.168217554","rc":[{"batb":[[1,1.63,73.72]],"ltp":0.0,"tv":0.0,"id":2263624}]}]}
{"op":"mcm","clk":"1006875880","pt":1580601504470,"mc":[{"id":"1.168217554","rc":[{"batb":[[0,1.63,81.76],[1,1.62,420.1],[2,1.61,420.1]],"ltp":0.0,"tv":0.0,"id":2263624}]}]}
{"op":"mcm","clk":"1007064737","pt":1580604085806,"mc":[{"id":"1.168217554","rc":[{"batb":[[0,1.64,6.36],[1,1.63,81.76],[2,1.62,420.1]],"ltp":0.0,"tv":0.0,"id":2263624}]}]}
{"op":"mcm","clk":"1007068871","pt":1580604171209,"mc":[{"id":"1.168217554","rc":[{"batb":[[0,1.65,49.34],[1,1.64,6.36]],"ltp":0.0,"tv":0.0,"id":2263624}]}]}
{"op":"mcm","clk":"1007148369","pt":1580605875231,"mc":[{"id":"1.168217554","rc":[{"batl":[[0,1.67,2],[1,10.5,3.36],[2,95,15.9]],"ltp":0.0,"tv":0.0,"id":2263624}]}]}
{"op":"mcm","clk":"1007149441","pt":1580605898243,"mc":[{"id":"1.168217554","rc":[{"trd":[[1.67,4]],"batb":[[0,1.65,47.33]],"batl":[[0,10.5,3.36],[1,95,15.9],[2,990,2.2]],"ltp":1.67,"tv":3.99,"id":2263624}],"tv":87.21}]}
{"op":"mcm","clk":"1007181522","pt":1580606556977,"mc":[{"id":"1.168217554","rc":[{"batb":[[0,1.65,46.55]],"ltp":1.67,"tv":3.99,"id":2263624},{"batb":[[0,2.34,65.33]],"ltp":2.48,"tv":83.21,"id":7412809}]}]}
{"op":"mcm","clk":"1007182378","pt":1580606577433,"mc":[{"id":"1.168217554","rc":[{"batb":[[0,1.65,46.16]],"ltp":1.67,"tv":3.99,"id":2263624}]}]}
{"op":"mcm","clk":"1007188079","pt":1580606704748,"mc":[{"id":"1.168217554","rc":[{"batb":[[1,1.62,420.1],[2,1.61,420.1]],"ltp":1.67,"tv":3.99,"id":2263624}]}]}
{"op":"mcm","clk":"1007190468","pt":1580606758817,"mc":[{"id":"1.168217554","rc":[{"batb":[[0,1.63,78.57]],"ltp":1.67,"tv":3.99,"id":2263624}]}]}
{"op":"mcm","clk":"1007192896","pt":1580606817480,"mc":[{"id":"1.168217554","rc":[{"batb":[[0,1.63,270.53]],"ltp":1.67,"tv":3.99,"id":2263624}]}]}
{"op":"mcm","clk":"1007193015","pt":1580606821418,"mc":[{"id":"1.168217554","rc":[{"batb":[[2,2.1,107.39]],"ltp":2.48,"tv":83.21,"id":7412809}]}]}
{"op":"mcm","clk":"1007193088","pt":1580606823581,"mc":[{"id":"1.168217554","rc":[{"batb":[[2,2.14,42.4]],"ltp":2.48,"tv":83.21,"id":7412809}]}]}
{"op":"mcm","clk":"1007247233","pt":1580608220384,"mc":[{"id":"1.168217554","rc":[{"batl":[[0,1.7,112.44],[1,10.5,3.36],[2,95,15.9]],"ltp":1.67,"tv":3.99,"id":2263624}]}]}
{"op":"mcm","clk":"1007249148","pt":1580608268592,"mc":[{"id":"1.168217554","rc":[{"batl":[[1,95,15.9],[2,990,2.2]],"ltp":1.67,"tv":3.99,"id":2263624}]}]}
{"op":"mcm","clk":"1007333249","pt":1580610801400,"mc":[{"id":"1.168217554","rc":[{"batb":[[0,1.63,368.99]],"ltp":1.67,"tv":3.99,"id":2263624}]}]}
{"op":"mcm","clk":"1007384281","pt":1580612343559,"mc":[{"id":"1.168217554","rc":[{"batb":[[0,1.63,78.57]],"ltp":1.67,"tv":3.99,"id":2263624}]}]}
{"op":"mcm","clk":"1007384352","pt":1580612346287,"mc":[{"id":"1.168217554","rc":[{"batb":[[2,2.14,200.49]],"ltp":2.48,"tv":83.21,"id":7412809}]}]}
{"op":"mcm","clk":"1007388007","pt":1580612446184,"mc":[{"id":"1.168217554","rc":[{"batb":[[2,2.18,42.4]],"ltp":2.48,"tv":83.21,"id":7412809}]}]}
{"op":"mcm","clk":"1007440354","pt":1580614137361,"mc":[{"id":"1.168217554","rc":[{"trd":[[1.63,5.04]],"batb":[[0,1.63,76.05]],"ltp":1.63,"tv":9.04,"id":2263624}],"tv":92.25}]}
{"op":"mcm","clk":"1007440375","pt":1580614138234,"mc":[{"id":"1.168217554","rc":[{"batb":[[0,2.44,15.82]],"ltp":2.48,"tv":83.21,"id":7412809}]}]}
{"op":"mcm","clk":"1007466449","pt":1580615110300,"mc":[{"id":"1.168217554","rc":[{"batl":[[1,990,2.2],[2,1000,0.02]],"ltp":1.63,"tv":9.04,"id":2263624},{"batl":[[1,990,2.2],[2,1000,0.02]],"ltp":2.48,"tv":83.21,"id":7412809}]}]}
{"op":"mcm","clk":"1007522136","pt":1580616636416,"mc":[{"id":"1.168217554","rc":[{"batl":[[1,95,15.9],[2,990,2.2]],"ltp":1.63,"tv":9.04,"id":2263624},{"batl":[[1,95,15.9],[2,990,2.2]],"ltp":2.48,"tv":83.21,"id":7412809}]}]}
{"op":"mcm","clk":"1007525894","pt":1580616756385,"mc":[{"id":"1.168217554","rc":[{"batl":[[1,1.8,10.13],[2,95,15.9]],"ltp":1.63,"tv":9.04,"id":2263624}]}]}
{"op":"mcm","clk":"1007589926","pt":1580618401448,"mc":[{"id":"1.168217554","rc":[{"trd":[[1.63,13.96]],"batb":[[0,1.63,67.13]],"ltp":1.63,"tv":17.95,"id":2263624},{"trd":[[2.6,5.59]],"batb":[[0,2.44,21.73]],"ltp":2.6,"tv":88.8,"id":7412809}],"tv":106.75}]}
{"op":"mcm","clk":"1007592401","pt":1580618467426,"mc":[{"id":"1.168217554","rc":[{"trd":[[1.63,148.22]],"batb":[[0,1.63,18.35]],"ltp":1.63,"tv":152.21,"id":2263624}],"tv":241.01}]}
{"op":"mcm","clk":"1007592429","pt":1580618468451,"mc":[{"id":"1.168217554","rc":[{"batb":[[0,1.62,420.1],[1,1.61,454.26],[2,1.6,420.1]],"ltp":1.63,"tv":152.21,"id":2263624},{"batb":[[0,2.44,65.73]],"ltp":2.6,"tv":88.8,"id":7412809}]}]}
{"op":"mcm","clk":"1007592457","pt":1580618469229,"mc":[{"id":"1.168217554","rc":[{"batb":[[1,2.42,126.92],[2,2.22,37.86]],"ltp":2.6,"tv":88.8,"id":7412809}]}]}
{"op":"mcm","clk":"1007592611","pt":1580618471524,"mc":[{"id":"1.168217554","rc":[{"batb":[[2,2.4,42.4]],"ltp":2.6,"tv":88.8,"id":7412809}]}]}
{"op":"mcm","clk":"1007593149","pt":1580618480436,"mc":[{"id":"1.168217554","rc":[{"batb":[[2,2.36,42.4]],"ltp":2.6,"tv":88.8,"id":7412809}]}]}
{"op":"mcm","clk":"1007593153","pt":1580618480641,"mc":[{"id":"1.168217554","rc":[{"batb":[[0,2.5,194.74],[1,2.44,65.73],[2,2.42,126.92]],"ltp":2.6,"tv":88.8,"id":7412809}]}]}
{"op":"mcm","clk":"1007594288","pt":1580618511503,"mc":[{"id":"1.168217554","rc":[{"batb":[[0,2.44,65.73],[1,2.42,126.92],[2,2.36,42.4]],"ltp":2.6,"tv":88.8,"id":7412809}]}]}
{"op":"mcm","clk":"1007594293","pt":1580618511606,"mc":[{"id":"1.168217554","rc":[{"batb":[[0,2.5,190.16],[1,2.44,65.73],[2,2.42,126.92]],"ltp":2.6,"tv":88.8,"id":7412809}]}]}
{"op":"mcm","clk":"1007594336","pt":1580618513195,"mc":[{"id":"1.168217554","rc":[{"batb":[[2,2.36,42.4]],"ltp":2.6,"tv":88.8,"id":7412809}]}]}
{"op":"mcm","clk":"1007594356","pt":1580618513812,"mc":[{"id":"1.168217554","rc":[{"batb":[[2,2.38,130.59]],"ltp":2.6,"tv":88.8,"id":7412809}]}]}
{"op":"mcm","clk":"1007595278","pt":1580618537260,"mc":[{"id":"1.168217554","rc":[{"batb":[[2,2.4,38.62]],"ltp":2.6,"tv":88.8,"id":7412809}]}]}
{"op":"mcm","clk":"1007595888","pt":1580618553444,"mc":[{"id":"1.168217554","rc":[{"batb":[[0,2.52,28.32],[1,2.5,190.16]],"ltp":2.6,"tv":88.8,"id":7412809}]}]}
{"op":"mcm","clk":"1007596452","pt":1580618571186,"mc":[{"id":"1.168217554","rc":[{"batb":[[2,2.38,130.59]],"ltp":2.6,"tv":88.8,"id":7412809}]}]}
{"op":"mcm","clk":"1007598321","pt":1580618620428,"mc":[{"id":"1.168217554","rc":[{"batb":[[2,2.4,38.62]],"ltp":2.6,"tv":88.8,"id":7412809}]}]}
{"op":"mcm","clk":"1007601212","pt":1580618709994,"mc":[{"id":"1.168217554","rc":[{"trd":[[1.62,57.13]],"batb":[[0,1.62,391.53]],"ltp":1.62,"tv":209.34,"id":2263624}],"tv":298.15}]}
{"op":"mcm","clk":"1007604408","pt":1580618809626,"mc":[{"id":"1.168217554","rc":[{"batb":[[0,2.52,217.81],[1,2.4,38.62],[2,2.38,130.59]],"ltp":2.6,"tv":88.8,"id":7412809}]}]}
{"op":"mcm","clk":"1007606959","pt":1580618878520,"mc":[{"id":"1.168217554","rc":[{"batb":[[0,1.63,13.33],[1,1.62,391.53],[2,1.61,454.26]],"ltp":1.62,"tv":209.34,"id":2263624},{"batl":[[0,2.6,8.4],[1,15,3.36],[2,95,15.9]],"ltp":2.6,"tv":88.8,"id":7412809}]}]}
{"op":"mcm","clk":"1007606977","pt":1580618878931,"mc":[{"id":"1.168217554","rc":[{"batl":[[0,1.65,8.4],[1,1.7,112.44],[2,1.8,10.13]],"ltp":1.62,"tv":209.34,"id":2263624},{"batb":[[0,2.54,5.45],[1,2.52,217.81],[2,2.4,38.62]],"ltp":2.6,"tv":88.8,"id":7412809}]}]}
{"op":"mcm","clk":"1007607923","pt":1580618912144,"mc":[{"id":"1.168217554","rc":[{"batl":[[1,95,15.9],[2,990,2.2]],"ltp":2.6,"tv":88.8,"id":7412809}]}]}
{"op":"mcm","clk":"1007615700","pt":1580619161318,"mc":[{"id":"1.168217554","rc":[{"batl":[[0,1.64,1.8],[1,1.65,8.4],[2,1.7,112.44]],"ltp":1.62,"tv":209.34,"id":2263624},{"batb":[[1,2.52,28.32]],"ltp":2.6,"tv":88.8,"id":7412809}]}]}
{"op":"mcm","clk":"1007616436","pt":1580619183680,"mc":[{"id":"1.168217554","rc":[{"batb":[[1,2.44,65.73]],"ltp":2.6,"tv":88.8,"id":7412809}]}]}
{"op":"mcm","clk":"1007616708","pt":1580619190672,"mc":[{"id":"1.168217554","rc":[{"batl":[[1,1.7,112.44],[2,1.8,10.13]],"ltp":1.62,"tv":209.34,"id":2263624}]}]}
{"op":"mcm","clk":"1007648988","pt":1580619987369,"mc":[{"id":"1.168217554","rc":[{"trd":[[1.64,3.41]],"batl":[[0,1.7,112.53],[1,1.8,10.13],[2,95,15.9]],"ltp":1.64,"tv":212.76,"id":2263624}],"tv":301.56}]}
{"op":"mcm","clk":"1007649798","pt":1580619996946,"mc":[{"id":"1.168217554","rc":[{"batl":[[0,1.65,8.49],[1,1.7,112.44],[2,1.8,10.13]],"ltp":1.64,"tv":212.76,"id":2263624}]}]}
{"op":"mcm","clk":"1007661548","pt":1580620224188,"mc":[{"id":"1.168217554","rc":[{"trd":[[1.63,149.73]],"batb":[[0,1.63,12.58]],"ltp":1.63,"tv":214.27,"id":2263624}],"tv":303.07}]}
{"op":"mcm","clk":"1007663779","pt":1580620267490,"mc":[{"id":"1.168217554","rc":[{"batl":[[2,1.8,10.36]],"ltp":1.63,"tv":214.27,"id":2263624}]}]}
{"op":"mcm","clk":"1007669355","pt":1580620359257,"mc":[{"id":"1.168217554","rc":[{"batl":[[1,4.1,153.72],[2,95,15.9]],"ltp":2.6,"tv":88.8,"id":7412809}]}]}
{"op":"mcm","clk":"1007719246","pt":1580621512462,"mc":[{"id":"1.168217554","rc":[{"batb":[[2,2.4,207.91]],"ltp":2.6,"tv":88.8,"id":7412809}]}]}
{"op":"mcm","clk":"1007719299","pt":1580621513486,"mc":[{"id":"1.168217554","rc":[{"trd":[[2.6,13.51]],"batl":[[0,2.6,4.44]],"ltp":2.6,"tv":96.72,"id":7412809}],"tv":310.99}]}
{"op":"mcm","clk":"1007758811","pt":1580622296703,"mc":[{"id":"1.168217554","rc":[{"trd":[[1.63,164.05]],"batb":[[0,1.63,5.42]],"ltp":1.63,"tv":228.59,"id":2263624}],"tv":325.31}]}
{"op":"mcm","clk":"1007759245","pt":1580622304505,"mc":[{"id":"1.168217554","rc":[{"batb":[[0,1.62,391.53],[1,1.61,454.26],[2,1.6,420.1]],"ltp":1.63,"tv":228.59,"id":2263624},{"batl":[[0,4.1,153.72],[1,95,15.9],[2,990,2.2]],"ltp":2.6,"tv":96.72,"id":7412809}]}]}
{"op":"mcm","clk":"1007812185","pt":1580623502532,"mc":[{"id":"1.168217554","rc":[{"batl":[[0,1.64,15.83],[1,1.65,8.4],[2,1.7,112.44]],"ltp":1.63,"tv":228.59,"id":2263624}]}]}
{"op":"mcm","clk":"1007812380","pt":1580623506519,"mc":[{"id":"1.168217554","rc":[{"trd":[[1.63,193.94]],"batl":[[0,1.65,9.28],[1,1.7,112.44],[2,1.8,10.36]],"ltp":1.63,"tv":258.48,"id":2263624}],"tv":355.2}]}
{"op":"mcm","clk":"1007816641","pt":1580623618525,"mc":[{"id":"1.168217554","rc":[{"trd":[[1.63,195.52],[1.64,3.6],[1.65,11.12]],"batl":[[0,1.65,2.84]],"ltp":1.65,"tv":271.37,"id":2263624}],"tv":368.09}]}
{"op":"mcm","clk":"1007817316","pt":1580623635423,"mc":[{"id":"1.168217554","rc":[{"trd":[[1.65,27.92]],"batl":[[0,1.7,112.44],[1,1.8,10.36],[2,2.2,15.14]],"ltp":1.65,"tv":288.17,"id":2263624}],"tv":384.89}]}
{"op":"mcm","clk":"1007818704","pt":1580623667096,"mc":[{"id":"1.168217554","rc":[{"trd":[[1.65,44.73]],"batb":[[0,1.63,13.33],[1,1.62,391.53],[2,1.61,454.26]],"ltp":1.65,"tv":304.97,"id":2263624},{"batl":[[0,2.6,8.4],[1,4.1,153.72],[2,95,15.9]],"ltp":2.6,"tv":96.72,"id":7412809}],"tv":401.69}]}
{"op":"mcm","clk":"1007830272","pt":1580623926242,"mc":[{"id":"1.168217554","rc":[{"trd":[[1.63,213.28]],"batb":[[0,1.63,4.45]],"ltp":1.63,"tv":322.73,"id":2263624}],"tv":419.45}]}
{"op":"mcm","clk":"1007831206","pt":1580623947394,"mc":[{"id":"1.168217554","rc":[{"batb":[[0,1.63,13.33]],"batl":[[0,1.65,8.4],[1,1.7,112.44],[2,1.8,10.36]],"ltp":1.63,"tv":322.73,"id":2263624}]}]}
{"op":"mcm","clk":"1007834961","pt":1580624043943,"mc":[{"id":"1.168217554","rc":[{"trd":[[1.63,231.14]],"batb":[[0,1.63,4.4]],"ltp":1.63,"tv":340.59,"id":2263624}],"tv":437.31}]}
{"op":"mcm","clk":"1007841897","pt":1580624211110,"mc":[{"id":"1.168217554","rc":[{"trd":[[1.62,170.26],[1.63,235.54]],"batb":[[0,1.62,278.41],[1,1.61,454.26],[2,1.6,420.1]],"ltp":1.62,"tv":458.12,"id":2263624},{"trd":[[2.6,33.08],[2.62,69.95]],"batl":[[0,4.1,153.72],[1,95,15.9],[2,990,2.2]],"ltp":2.62,"tv":186.23,"id":7412809}],"tv":644.35}]}
{"op":"mcm","clk":"1007852202","pt":1580624436902,"mc":[{"id":"1.168217554","rc":[{"trd":[[1.62,195.46]],"batb":[[0,1.62,265.8]],"ltp":1.62,"tv":483.32,"id":2263624}],"tv":669.56}]}
{"op":"mcm","clk":"1007971022","pt":1580626978806,"mc":[{"id":"1.168217554","rc":[{"batb":[[0,2.54,253.57]],"ltp":2.62,"tv":186.23,"id":7412809}]}]}
{"op":"mcm","clk":"1007971218","pt":1580626982483,"mc":[{"id":"1.168217554","rc":[{"batb":[[2,2.42,166.91]],"ltp":2.62,"tv":186.23,"id":7412809}]}]}
{"op":"mcm","clk":"1007971608","pt":1580626988686,"mc":[{"id":"1.168217554","rc":[{"batb":[[2,2.42,205.53]],"ltp":2.62,"tv":186.23,"id":7412809}]}]}
{"op":"mcm","clk":"1008009015","pt":1580627650898,"mc":[{"id":"1.168217554","rc":[{"trd":[[1.62,205.46]],"batb":[[0,1.62,260.8]],"ltp":1.62,"tv":493.32,"id":2263624}],"tv":679.56}]}
{"op":"mcm","clk":"1008069443","pt":1580628779194,"mc":[{"id":"1.168217554","rc":[{"batb":[[0,2.54,253.76]],"ltp":2.62,"tv":186.23,"id":7412809}]}]}
{"op":"mcm","clk":"1008076369","pt":1580628910773,"mc":[{"id":"1.168217554","rc":[{"trd":[[1.62,726.38]],"batb":[[0,1.61,454.6],[1,1.6,420.1],[2,1.59,420.1]],"ltp":1.62,"tv":1014.24,"id":2263624}],"tv":1200.48}]}
{"op":"mcm","clk":"1008079959","pt":1580628981203,"mc":[{"id":"1.168217554","rc":[{"batb":[[0,1.62,4.84],[1,1.61,454.26],[2,1.6,420.1]],"batl":[[0,1.64,3],[1,1.65,8.4],[2,1.7,112.44]],"ltp":1.62,"tv":1014.24,"id":2263624}]}]}
{"op":"mcm","clk":"1008080177","pt":1580628985390,"mc":[{"id":"1.168217554","rc":[{"batl":[[1,1.7,112.44],[2,1.8,10.36]],"ltp":1.62,"tv":1014.24,"id":2263624}]}]}
{"op":"mcm","clk":"1008080226","pt":1580628986270,"mc":[{"id":"1.168217554","rc":[{"batl":[[0,1.64,15.6]],"ltp":1.62,"tv":1014.24,"id":2263624},{"batb":[[0,2.56,8.27],[1,2.54,248.12],[2,2.44,65.73]],"ltp":2.62,"tv":186.23,"id":7412809}]}]}
{"op":"mcm","clk":"1008083512","pt":1580629048493,"mc":[{"id":"1.168217554","rc":[{"batb":[[1,2.44,65.73],[2,2.42,205.53]],"ltp":2.62,"tv":186.23,"id":7412809}]}]}
{"op":"mcm","clk":"1008084953","pt":1580629079036,"mc":[{"id":"1.168217554","rc":[{"batb":[[0,1.62,4.98]],"ltp":1.62,"tv":1014.24,"id":2263624}]}]}
{"op":"mcm","clk":"1008088920","pt":1580629159315,"mc":[{"id":"1.168217554","rc":[{"trd":[[1.62,741.04],[1.63,235.82]],"batb":[[0,1.61,454.26],[1,1.6,420.1],[2,1.59,420.1]],"batl":[[0,1.64,15.73]],"ltp":1.62,"tv":1029.18,"id":2263624}],"tv":1215.41}]}
{"op":"mcm","clk":"1008168439","pt":1580630642502,"mc":[{"id":"1.168217554","rc":[{"trd":[[1.62,741.31]],"batb":[[0,1.62,16.74],[1,1.61,454.26],[2,1.6,420.1]],"batl":[[0,1.64,15.6]],"ltp":1.62,"tv":1029.44,"id":2263624},{"batl":[[0,2.62,8.4],[1,4.1,153.72],[2,95,15.9]],"ltp":2.62,"tv":186.23,"id":7412809}],"tv":1215.68}]}
{"op":"mcm","clk":"1008183628","pt":1580630917685,"mc":[{"id":"1.168217554","rc":[{"trd":[[1.62,774.76]],"batb":[[0,1.61,454.26],[1,1.6,420.1],[2,1.59,420.1]],"ltp":1.62,"tv":1062.9,"id":2263624}],"tv":1249.13}]}
{"op":"mcm","clk":"1008238882","pt":1580631751622,"mc":[{"id":"1.168217554","rc":[{"trd":[[1.64,6.96]],"batl":[[0,1.64,13.92]],"ltp":1.64,"tv":1066.26,"id":2263624}],"tv":1252.49}]}
{"op":"mcm","clk":"1008239368","pt":1580631758125,"mc":[{"id":"1.168217554","rc":[{"trd":[[1.61,102]],"batb":[[0,1.61,403.26]],"ltp":1.61,"tv":1168.26,"id":2263624}],"tv":1354.49}]}
{"op":"mcm","clk":"1008260263","pt":1580632124300,"mc":[{"id":"1.168217554","rc":[{"trd":[[1.61,105.8]],"batb":[[0,1.61,401.36]],"ltp":1.61,"tv":1172.05,"id":2263624}],"tv":1358.29}]}
{"op":"mcm","clk":"1008271068","pt":1580632287165,"mc":[{"id":"1.168217554","rc":[{"batb":[[2,2.42,38.62]],"ltp":2.62,"tv":186.23,"id":7412809}]}]}
{"op":"mcm","clk":"1008274216","pt":1580632330008,"mc":[{"id":"1.168217554","rc":[{"batl":[[2,1.72,239.68]],"ltp":1.61,"tv":1172.05,"id":2263624}]}]}
{"op":"mcm","clk":"1008304529","pt":1580632810404,"mc":[{"id":"1.168217554","rc":[{"trd":[[2.62,73.95]],"batl":[[0,2.62,6.4]],"ltp":2.62,"tv":190.23,"id":7412809}],"tv":1362.29}]}
{"op":"mcm","clk":"1008308386","pt":1580632867766,"mc":[{"id":"1.168217554","rc":[{"batb":[[2,1.59,422.21]],"batl":[[1,1.66,2.22],[2,1.67,2.01]],"ltp":1.61,"tv":1172.05,"id":2263624},{"batb":[[1,2.52,2],[2,2.5,2]],"batl":[[1,2.66,2.22],[2,2.68,2.14]],"ltp":2.62,"tv":190.23,"id":7412809}]}]}
{"op":"mcm","clk":"1008311395","pt":1580632911327,"mc":[{"id":"1.168217554","rc":[{"batb":[[1,2.52,30.32]],"ltp":2.62,"tv":190.23,"id":7412809}]}]}
{"op":"mcm","clk":"1008314666","pt":1580632974401,"mc":[{"id":"1.168217554","rc":[{"trd":[[1.61,115.93]],"batb":[[0,1.61,396.29]],"batl":[[2,1.7,112.44]],"ltp":1.61,"tv":1182.19,"id":2263624},{"batb":[[2,2.42,38.62]],"batl":[[2,4.1,153.72]],"ltp":2.62,"tv":190.23,"id":7412809}],"tv":1372.42}]}
{"op":"mcm","clk":"1008314679","pt":1580632974609,"mc":[{"id":"1.168217554","rc":[{"batl":[[2,1.67,2.01]],"ltp":1.61,"tv":1182.19,"id":2263624},{"batb":[[2,2.5,2]],"batl":[[2,2.68,2.14]],"ltp":2.62,"tv":190.23,"id":7412809}]}]}
{"op":"mcm","clk":"1008319432","pt":1580633073322,"mc":[{"id":"1.168217554","rc":[{"batb":[[0,1.62,6.15],[1,1.61,396.29],[2,1.6,422.14]],"batl":[[1,1.65,5],[2,1.66,2.22]],"ltp":1.61,"tv":1182.19,"id":2263624},{"batb":[[2,2.42,38.62]],"batl":[[0,2.62,9.4],[2,4.1,153.72]],"ltp":2.62,"tv":190.23,"id":7412809}]}]}
{"op":"mcm","clk":"1008319441","pt":1580633073631,"mc":[{"id":"1.168217554","rc":[{"batb":[[2,2.5,2]],"batl":[[2,2.68,2.14]],"ltp":2.62,"tv":190.23,"id":7412809}]}]}
{"op":"mcm","clk":"1008320158","pt":1580633093426,"mc":[{"id":"1.168217554","rc":[{"batb":[[2,2.42,38.62]],"batl":[[0,2.6,4.18],[1,2.62,9.4],[2,2.64,2.18]],"ltp":2.62,"tv":190.23,"id":7412809}]}]}
{"op":"mcm","clk":"1008320179","pt":1580633093947,"mc":[{"id":"1.168217554","rc":[{"batb":[[2,2.5,2]],"ltp":2.62,"tv":190.23,"id":7412809}]}]}
{"op":"mcm","clk":"1008321041","pt":1580633113472,"mc":[{"id":"1.168217554","rc":[{"batb":[[1,1.61,404.29]],"ltp":1.61,"tv":1182.19,"id":2263624}]}]}
{"op":"mcm","clk":"1008321070","pt":1580633114400,"mc":[{"id":"1.168217554","rc":[{"trd":[[2.6,40.14]],"batl":[[0,2.6,4],[2,2.66,2.25]],"ltp":2.6,"tv":197.29,"id":7412809}],"tv":1379.48}]}
{"op":"mcm","clk":"1008321104","pt":1580633115071,"mc":[{"id":"1.168217554","rc":[{"batb":[[0,1.61,396.29],[1,1.6,422.14],[2,1.59,422.14]],"ltp":1.61,"tv":1182.19,"id":2263624},{"batl":[[2,2.64,2.18]],"ltp":2.6,"tv":197.29,"id":7412809}]}]}
{"op":"mcm","clk":"1008323957","pt":1580633180441,"mc":[{"id":"1.168217554","rc":[{"batb":[[0,1.63,7.08],[1,1.62,7],[2,1.61,396.29]],"ltp":1.61,"tv":1182.19,"id":2263624},{"batb":[[1,2.52,36.32]],"ltp":2.6,"tv":197.29,"id":7412809}]}]}
{"op":"mcm","clk":"1008324009","pt":1580633181469,"mc":[{"id":"1.168217554","rc":[{"trd":[[1.63,248.2],[1.64,33.39]],"batb":[[0,1.63,7]],"batl":[[0,1.65,8.71],[1,1.66,8],[2,1.67,2.01]],"ltp":1.63,"tv":1221.0,"id":2263624},{"batb":[[2,2.5,8.11]],"ltp":2.6,"tv":197.29,"id":7412809}],"tv":1418.29}]}
{"op":"mcm","clk":"1008324021","pt":1580633181626,"mc":[{"id":"1.168217554","rc":[{"batb":[[2,1.61,398.38]],"ltp":1.63,"tv":1221.0,"id":2263624}]}]}
{"op":"mcm","clk":"1008324054","pt":1580633182548,"mc":[{"id":"1.168217554","rc":[{"batl":[[0,1.65,25.27]],"ltp":1.63,"tv":1221.0,"id":2263624}]}]}
{"op":"mcm","clk":"1008324387","pt":1580633190475,"mc":[{"id":"1.168217554","rc":[{"batl":[[0,1.65,20.6]],"ltp":1.63,"tv":1221.0,"id":2263624},{"batb":[[2,2.5,10.11]],"ltp":2.6,"tv":197.29,"id":7412809}]}]}
{"op":"mcm","clk":"1008326625","pt":1580633244519,"mc":[{"id":"1.168217554","rc":[{"trd":[[1.63,260.6]],"batb":[[0,1.62,7.8],[1,1.61,396.29],[2,1.6,422.14]],"batl":[[0,1.65,37.16]],"ltp":1.63,"tv":1233.4,"id":2263624},{"batb":[[2,2.5,8.11]],"ltp":2.6,"tv":197.29,"id":7412809}],"tv":1430.69}]}
{"op":"mcm","clk":"1008328707","pt":1580633294487,"mc":[{"id":"1.168217554","rc":[{"trd":[[2.6,47.22]],"batl":[[0,2.62,9.86],[1,2.66,2.25],[2,2.68,2.14]],"ltp":2.6,"tv":204.37,"id":7412809}],"tv":1437.77}]}
{"op":"mcm","clk":"1008329802","pt":1580633317412,"mc":[{"id":"1.168217554","rc":[{"batb":[[0,1.62,19.8]],"batl":[[0,1.64,6],[1,1.65,37.16],[2,1.66,8]],"ltp":1.63,"tv":1233.4,"id":2263624}]}]}
{"op":"mcm","clk":"1008329869","pt":1580633318400,"mc":[{"id":"1.168217554","rc":[{"batb":[[0,1.63,7],[1,1.62,19],[2,1.61,398.29]],"batl":[[2,1.66,10.25]],"ltp":1.63,"tv":1233.4,"id":2263624},{"batb":[[1,2.54,8.2],[2,2.52,36.32]],"batl":[[0,2.6,4],[1,2.62,9.4],[2,2.64,2.18]],"ltp":2.6,"tv":204.37,"id":7412809}]}]}
{"op":"mcm","clk":"1008331203","pt":1580633345464,"mc":[{"id":"1.168217554","rc":[{"trd":[[1.63,273.02]],"batb":[[2,1.61,405.29]],"batl":[[1,1.65,28.56]],"ltp":1.63,"tv":1245.82,"id":2263624},{"batb":[[2,2.52,39.32]],"ltp":2.6,"tv":204.37,"id":7412809}],"tv":1450.19}]}
{"op":"mcm","clk":"1008331218","pt":1580633345762,"mc":[{"id":"1.168217554","rc":[{"batb":[[2,1.61,405.38]],"ltp":1.63,"tv":1245.82,"id":2263624}]}]}
{"op":"mcm","clk":"1008334995","pt":1580633423388,"mc":[{"id":"1.168217554","rc":[{"trd":[[1.63,285.46]],"batb":[[0,1.62,19.78],[1,1.61,405.38],[2,1.6,422.14]],"ltp":1.63,"tv":1258.26,"id":2263624}],"tv":1462.63}]}
{"op":"mcm","clk":"1008335016","pt":1580633423855,"mc":[{"id":"1.168217554","rc":[{"batb":[[1,1.61,403.29]],"ltp":1.63,"tv":1258.26,"id":2263624}]}]}
{"op":"mcm","clk":"1008335638","pt":1580633437394,"mc":[{"id":"1.168217554","rc":[{"batl":[[0,1.64,18.6]],"ltp":1.63,"tv":1258.26,"id":2263624}]}]}
{"op":"mcm","clk":"1008345705","pt":1580633649404,"mc":[{"id":"1.168217554","rc":[{"trd":[[1.63,286.24]],"batb":[[0,1.62,19]],"batl":[[2,1.66,16.25]],"ltp":1.63,"tv":1259.04,"id":2263624},{"trd":[[2.6,55.71],[2.62,85.12]],"batl":[[0,2.6,4.04],[1,2.62,3.81],[2,2.64,2.04]],"ltp":2.62,"tv":224.04,"id":7412809}],"tv":1483.08}]}
{"op":"mcm","clk":"1008369031","pt":1580634068384,"mc":[{"id":"1.168217554","rc":[{"batl":[[0,2.62,3.81],[1,2.64,2.04],[2,4.1,153.72]],"ltp":2.62,"tv":224.04,"id":7412809}]}]}
{"op":"mcm","clk":"1008369044","pt":1580634068590,"mc":[{"id":"1.168217554","rc":[{"batl":[[1,2.66,2.25],[2,2.68,2.01]],"ltp":2.62,"tv":224.04,"id":7412809}]}]}
{"op":"mcm","clk":"1008369497","pt":1580634076380,"mc":[{"id":"1.168217554","rc":[{"batl":[[1,2.64,2.18],[2,2.66,2.1]],"ltp":2.62,"tv":224.04,"id":7412809}]}]}
{"op":"mcm","clk":"1008369507","pt":1580634076584,"mc":[{"id":"1.168217554","rc":[{"batl":[[1,2.66,2.1],[2,2.68,2]],"ltp":2.62,"tv":224.04,"id":7412809}]}]}
{"op":"mcm","clk":"1008370590","pt":1580634097406,"mc":[{"id":"1.168217554","rc":[{"batl":[[0,2.6,4.09],[1,2.62,3.81],[2,2.64,2.18]],"ltp":2.62,"tv":224.04,"id":7412809}]}]}
{"op":"mcm","clk":"1008370617","pt":1580634097918,"mc":[{"id":"1.168217554","rc":[{"batl":[[0,2.62,3.81],[1,2.66,2.25],[2,2.68,2.01]],"ltp":2.62,"tv":224.04,"id":7412809}]}]}
{"op":"mcm","clk":"1008371771","pt":1580634119439,"mc":[{"id":"1.168217554","rc":[{"batl":[[1,2.66,2.1],[2,2.68,2.14]],"ltp":2.62,"tv":224.04,"id":7412809}]}]}
{"op":"mcm","clk":"1008372406","pt":1580634129371,"mc":[{"id":"1.168217554","rc":[{"batl":[[1,2.66,2.25],[2,2.68,2.01]],"ltp":2.62,"tv":224.04,"id":7412809}]}]}
{"op":"mcm","clk":"1008373623","pt":1580634150382,"mc":[{"id":"1.168217554","rc":[{"batl":[[0,2.6,4.05],[1,2.62,3.81],[2,2.64,2.18]],"ltp":2.62,"tv":224.04,"id":7412809}]}]}
{"op":"mcm","clk":"1008373646","pt":1580634150793,"mc":[{"id":"1.168217554","rc":[{"batl":[[0,2.62,3.81],[1,2.66,2.22],[2,2.68,2.01]],"ltp":2.62,"tv":224.04,"id":7412809}]}]}
{"op":"mcm","clk":"1008374856","pt":1580634171498,"mc":[{"id":"1.168217554","rc":[{"batl":[[0,2.6,4.16],[1,2.62,3.81],[2,2.64,2.04]],"ltp":2.62,"tv":224.04,"id":7412809}]}]}
{"op":"mcm","clk":"1008374906","pt":1580634172244,"mc":[{"id":"1.168217554","rc":[{"batl":[[0,2.62,3.81],[1,2.66,2.13],[2,2.68,2.01]],"ltp":2.62,"tv":224.04,"id":7412809}]}]}
{"op":"mcm","clk":"1008376252","pt":1580634193342,"mc":[{"id":"1.168217554","rc":[{"batl":[[1,2.64,2.18],[2,2.66,2.25]],"ltp":2.62,"tv":224.04,"id":7412809}]}]}
{"op":"mcm","clk":"1008376264","pt":1580634193544,"mc":[{"id":"1.168217554","rc":[{"batl":[[1,2.66,2.25],[2,2.68,2.01]],"ltp":2.62,"tv":224.04,"id":7412809}]}]}
{"op":"mcm","clk":"1008377552","pt":1580634214471,"mc":[{"id":"1.168217554","rc":[{"batl":[[0,2.6,4.07],[1,2.62,3.81],[2,2.64,2.01]],"ltp":2.62,"tv":224.04,"id":7412809}]}]}
{"op":"mcm","clk":"1008377569","pt":1580634214779,"mc":[{"id":"1.168217554","rc":[{"batl":[[0,2.62,3.81],[1,2.66,2.04],[2,2.68,2]],"ltp":2.62,"tv":224.04,"id":7412809}]}]}
{"op":"mcm","clk":"1008378785","pt":1580634235494,"mc":[{"id":"1.168217554","rc":[{"batl":[[0,2.6,4.19],[1,2.62,3.81],[2,2.64,2.18]],"ltp":2.62,"tv":224.04,"id":7412809}]}]}
{"op":"mcm","clk":"1008378824","pt":1580634236112,"mc":[{"id":"1.168217554","rc":[{"batl":[[0,2.62,3.81],[1,2.66,2.1],[2,2.68,2.14]],"ltp":2.62,"tv":224.04,"id":7412809}]}]}
{"op":"mcm","clk":"1008379906","pt":1580634255468,"mc":[{"id":"1.168217554","rc":[{"batl":[[1,2.66,2.13],[2,2.68,2.01]],"ltp":2.62,"tv":224.04,"id":7412809}]}]}
{"op":"mcm","clk":"1008380997","pt":1580634276483,"mc":[{"id":"1.168217554","rc":[{"batl":[[0,2.6,4.08],[1,2.62,3.81],[2,2.64,2.04]],"ltp":2.62,"tv":224.04,"id":7412809}]}]}
{"op":"mcm","clk":"1008381012","pt":1580634276744,"mc":[{"id":"1.168217554","rc":[{"batl":[[0,2.62,3.81],[1,2.66,2.25],[2,2.68,2.01]],"ltp":2.62,"tv":224.04,"id":7412809}]}]}
{"op":"mcm","clk":"1008381938","pt":1580634297384,"mc":[{"id":"1.168217554","rc":[{"batl":[[0,2.6,4.2],[1,2.62,3.81],[2,2.64,2.18]],"ltp":2.62,"tv":224.04,"id":7412809}]}]}
{"op":"mcm","clk":"1008381977","pt":1580634298404,"mc":[{"id":"1.168217554","rc":[{"batl":[[0,2.62,3.81],[1,2.66,2.25],[2,2.68,2.14]],"ltp":2.62,"tv":224.04,"id":7412809}]}]}
{"op":"mcm","clk":"1008383164","pt":1580634319420,"mc":[{"id":"1.168217554","rc":[{"batl":[[1,2.64,2.18],[2,2.66,2.16]],"ltp":2.62,"tv":224.04,"id":7412809}]}]}
{"op":"mcm","clk":"1008383190","pt":1580634319829,"mc":[{"id":"1.168217554","rc":[{"batl":[[1,2.66,2.16],[2,2.68,2.14]],"ltp":2.62,"tv":224.04,"id":7412809}]}]}
{"op":"mcm","clk":"1008384331","pt":1580634340433,"mc":[{"id":"1.168217554","rc":[{"batl":[[0,2.6,4.1],[1,2.62,3.81],[2,2.64,2.01]],"ltp":2.62,"tv":224.04,"id":7412809}]}]}
{"op":"mcm","clk":"1008384352","pt":1580634340844,"mc":[{"id":"1.168217554","rc":[{"batl":[[0,2.62,3.81],[1,2.66,2.16],[2,2.68,2.14]],"ltp":2.62,"tv":224.04,"id":7412809}]}]}
{"op":"mcm","clk":"1008385545","pt":1580634361383,"mc":[{"id":"1.168217554","rc":[{"batl":[[0,2.6,4.22],[1,2.62,3.81],[2,2.64,2.04]],"ltp":2.62,"tv":224.04,"id":7412809}]}]}
{"op":"mcm","clk":"1008385588","pt":1580634362157,"mc":[{"id":"1.168217554","rc":[{"batl":[[0,2.62,3.81],[1,2.66,4.5],[2,2.68,2.14]],"ltp":2.62,"tv":224.04,"id":7412809}]}]}
{"op":"mcm","clk":"1008386771","pt":1580634383511,"mc":[{"id":"1.168217554","rc":[{"batl":[[1,2.64,2.18],[2,2.66,2.01]],"ltp":2.62,"tv":224.04,"id":7412809}]}]}
{"op":"mcm","clk":"1008386785","pt":1580634383769,"mc":[{"id":"1.168217554","rc":[{"batl":[[1,2.66,2.01],[2,2.68,2.14]],"ltp":2.62,"tv":224.04,"id":7412809}]}]}
{"op":"mcm","clk":"1008387914","pt":1580634404442,"mc":[{"id":"1.168217554","rc":[{"batl":[[0,2.6,4.13],[1,2.62,3.81],[2,2.64,2]],"ltp":2.62,"tv":224.04,"id":7412809}]}]}
{"op":"mcm","clk":"1008387933","pt":1580634404747,"mc":[{"id":"1.168217554","rc":[{"batl":[[0,2.62,3.81],[1,2.66,2.22],[2,2.68,2.14]],"ltp":2.62,"tv":224.04,"id":7412809}]}]}
{"op":"mcm","clk":"1008389298","pt":1580634425487,"mc":[{"id":"1.168217554","rc":[{"batl":[[0,2.6,4.24],[1,2.62,3.81],[2,2.64,2]],"ltp":2.62,"tv":224.04,"id":7412809}]}]}
{"op":"mcm","clk":"1008389365","pt":1580634426263,"mc":[{"id":"1.168217554","rc":[{"batl":[[0,2.62,3.81],[1,2.66,2],[2,2.68,2.01]],"ltp":2.62,"tv":224.04,"id":7412809}]}]}
{"op":"mcm","clk":"1008392001","pt":1580634468441,"mc":[{"id":"1.168217554","rc":[{"batl":[[1,2.64,2.18],[2,2.66,2]],"ltp":2.62,"tv":224.04,"id":7412809}]}]}
{"op":"mcm","clk":"1008392017","pt":1580634468646,"mc":[{"id":"1.168217554","rc":[{"batl":[[1,2.66,2],[2,2.68,2]],"ltp":2.62,"tv":224.04,"id":7412809}]}]}
{"op":"mcm","clk":"1008393299","pt":1580634489472,"mc":[{"id":"1.168217554","rc":[{"batl":[[0,2.6,4.26],[1,2.62,3.81],[2,2.64,2.04]],"ltp":2.62,"tv":224.04,"id":7412809}]}]}
{"op":"mcm","clk":"1008393350","pt":1580634490085,"mc":[{"id":"1.168217554","rc":[{"batl":[[0,2.62,3.81],[1,2.66,2.25],[2,2.68,2.01]],"ltp":2.62,"tv":224.04,"id":7412809}]}]}
{"op":"mcm","clk":"1008394596","pt":1580634510480,"mc":[{"id":"1.168217554","rc":[{"batl":[[0,2.6,4.05],[1,2.62,3.81],[2,2.66,2.25]],"ltp":2.62,"tv":224.04,"id":7412809}]}]}
{"op":"mcm","clk":"1008394665","pt":1580634511403,"mc":[{"id":"1.168217554","rc":[{"batl":[[0,2.62,3.81],[1,2.66,2.19],[2,2.68,2.14]],"ltp":2.62,"tv":224.04,"id":7412809}]}]}
{"op":"mcm","clk":"1008395048","pt":1580634518400,"mc":[{"id":"1.168217554","rc":[{"batl":[[1,1.65,30.83]],"ltp":1.63,"tv":1259.04,"id":2263624},{"batl":[[0,2.6,4.2],[1,2.62,3.81],[2,2.64,2.18]],"ltp":2.62,"tv":224.04,"id":7412809}]}]}
{"op":"mcm","clk":"1008395087","pt":1580634519014,"mc":[{"id":"1.168217554","rc":[{"batl":[[0,2.62,3.81],[1,2.66,2.16],[2,2.68,2.14]],"ltp":2.62,"tv":224.04,"id":7412809}]}]}
{"op":"mcm","clk":"1008396446","pt":1580634539429,"mc":[{"id":"1.168217554","rc":[{"batl":[[0,2.6,4.21],[1,2.62,3.81],[2,2.64,2.18]],"ltp":2.62,"tv":224.04,"id":7412809}]}]}
{"op":"mcm","clk":"1008396478","pt":1580634539835,"mc":[{"id":"1.168217554","rc":[{"batl":[[0,2.62,3.81],[1,2.66,2.1],[2,2.68,2.01]],"ltp":2.62,"tv":224.04,"id":7412809}]}]}
{"op":"mcm","clk":"1008397720","pt":1580634560445,"mc":[{"id":"1.168217554","rc":[{"batl":[[0,2.6,4.32],[1,2.62,3.81],[2,2.64,2.04]],"ltp":2.62,"tv":224.04,"id":7412809}]}]}
{"op":"mcm","clk":"1008397769","pt":1580634561167,"mc":[{"id":"1.168217554","rc":[{"batl":[[0,2.62,3.81],[1,2.66,2.25],[2,2.68,2.01]],"ltp":2.62,"tv":224.04,"id":7412809}]}]}
{"op":"mcm","clk":"1008399088","pt":1580634582474,"mc":[{"id":"1.168217554","rc":[{"batl":[[2,2.68,2.14]],"ltp":2.62,"tv":224.04,"id":7412809}]}]}
{"op":"mcm","clk":"1008400238","pt":1580634603521,"mc":[{"id":"1.168217554","rc":[{"batl":[[0,2.6,4.23],[1,2.62,3.81],[2,2.64,2.04]],"ltp":2.62,"tv":224.04,"id":7412809}]}]}
{"op":"mcm","clk":"1008400260","pt":1580634603787,"mc":[{"id":"1.168217554","rc":[{"batl":[[0,2.62,3.81],[1,2.66,2.19],[2,2.68,2.14]],"ltp":2.62,"tv":224.04,"id":7412809}]}]}
{"op":"mcm","clk":"1008401528","pt":1580634624486,"mc":[{"id":"1.168217554","rc":[{"batl":[[0,2.6,4.02],[1,2.62,3.81],[2,2.64,2.18]],"ltp":2.62,"tv":224.04,"id":7412809}]}]}
{"op":"mcm","clk":"1008401575","pt":1580634625110,"mc":[{"id":"1.168217554","rc":[{"batl":[[0,2.62,3.81],[1,2.66,2.22],[2,2.68,2.01]],"ltp":2.62,"tv":224.04,"id":7412809}]}]}
{"op":"mcm","clk":"1008402915","pt":1580634646422,"mc":[{"id":"1.168217554","rc":[{"batl":[[1,2.64,2.18],[2,2.66,2.07]],"ltp":2.62,"tv":224.04,"id":7412809}]}]}
{"op":"mcm","clk":"1008402930","pt":1580634646628,"mc":[{"id":"1.168217554","rc":[{"batl":[[1,2.66,2.07],[2,2.68,2.14]],"ltp":2.62,"tv":224.04,"id":7412809}]}]}
{"op":"mcm","clk":"1008404119","pt":1580634667329,"mc":[{"id":"1.168217554","rc":[{"batl":[[0,2.6,4.25],[1,2.62,3.81],[2,2.64,2.18]],"ltp":2.62,"tv":224.04,"id":7412809}]}]}
{"op":"mcm","clk":"1008404167","pt":1580634668154,"mc":[{"id":"1.168217554","rc":[{"batl":[[0,2.62,3.81],[1,2.66,2.04],[2,2.68,2.01]],"ltp":2.62,"tv":224.04,"id":7412809}]}]}
{"op":"mcm","clk":"1008405627","pt":1580634688465,"mc":[{"id":"1.168217554","rc":[{"batl":[[0,2.6,4.04],[1,2.62,3.81],[2,2.64,2.04]],"ltp":2.62,"tv":224.04,"id":7412809}]}]}
{"op":"mcm","clk":"1008405691","pt":1580634689081,"mc":[{"id":"1.168217554","rc":[{"batl":[[0,2.62,3.81],[1,2.66,2.01],[2,2.68,2.14]],"ltp":2.62,"tv":224.04,"id":7412809}]}]}
{"op":"mcm","clk":"1008407554","pt":1580634710409,"mc":[{"id":"1.168217554","rc":[{"batl":[[1,2.64,2.04],[2,2.66,2.01]],"ltp":2.62,"tv":224.04,"id":7412809}]}]}
{"op":"mcm","clk":"1008407570","pt":1580634710616,"mc":[{"id":"1.168217554","rc":[{"batl":[[1,2.66,2.01],[2,2.68,2.14]],"ltp":2.62,"tv":224.04,"id":7412809}]}]}
{"op":"mcm","clk":"1008408748","pt":1580634731521,"mc":[{"id":"1.168217554","rc":[{"batl":[[0,2.6,4.27],[1,2.62,3.81],[2,2.64,2.18]],"ltp":2.62,"tv":224.04,"id":7412809}]}]}
{"op":"mcm","clk":"1008408776","pt":1580634731932,"mc":[{"id":"1.168217554","rc":[{"batl":[[0,2.62,3.81],[1,2.66,2.25],[2,2.68,2.14]],"ltp":2.62,"tv":224.04,"id":7412809}]}]}
{"op":"mcm","clk":"1008409981","pt":1580634752442,"mc":[{"id":"1.168217554","rc":[{"batl":[[0,2.6,4.06],[1,2.62,3.81],[2,2.64,2.18]],"ltp":2.62,"tv":224.04,"id":7412809}]}]}
{"op":"mcm","clk":"1008410043","pt":1580634753374,"mc":[{"id":"1.168217554","rc":[{"batl":[[0,2.62,3.81],[1,2.66,2.25],[2,2.68,2.14]],"ltp":2.62,"tv":224.04,"id":7412809}]}]}
{"op":"mcm","clk":"1008411444","pt":1580634774386,"mc":[{"id":"1.168217554","rc":[{"batl":[[2,2.68,2.01]],"ltp":2.62,"tv":224.04,"id":7412809}]}]}
{"op":"mcm","clk":"1008412634","pt":1580634795500,"mc":[{"id":"1.168217554","rc":[{"batl":[[0,2.6,4.29],[1,2.62,3.81],[2,2.64,2.18]],"ltp":2.62,"tv":224.04,"id":7412809}]}]}
{"op":"mcm","clk":"1008412663","pt":1580634796013,"mc":[{"id":"1.168217554","rc":[{"batl":[[0,2.62,3.81],[1,2.66,2.19],[2,2.68,2.01]],"ltp":2.62,"tv":224.04,"id":7412809}]}]}
{"op":"mcm","clk":"1008413824","pt":1580634816510,"mc":[{"id":"1.168217554","rc":[{"batl":[[0,2.6,4.08],[1,2.62,3.81],[2,2.64,2]],"ltp":2.62,"tv":224.04,"id":7412809}]}]}
{"op":"mcm","clk":"1008413894","pt":1580634817386,"mc":[{"id":"1.168217554","rc":[{"batl":[[0,2.62,3.81],[1,2.66,2.25],[2,2.68,2.14]],"ltp":2.62,"tv":224.04,"id":7412809}]}]}
{"op":"mcm","clk":"1008415094","pt":1580634838425,"mc":[{"id":"1.168217554","rc":[{"batl":[[1,2.64,2.18],[2,2.66,2.13]],"ltp":2.62,"tv":224.04,"id":7412809}]}]}
{"op":"mcm","clk":"1008415118","pt":1580634838732,"mc":[{"id":"1.168217554","rc":[{"batl":[[1,2.66,2.13],[2,2.68,2.14]],"ltp":2.62,"tv":224.04,"id":7412809}]}]}
{"op":"mcm","clk":"1008416363","pt":1580634859450,"mc":[{"id":"1.168217554","rc":[{"batl":[[1,2.64,2.18],[2,2.66,2.01]],"ltp":2.62,"tv":224.04,"id":7412809}]}]}
{"op":"mcm","clk":"1008416375","pt":1580634859657,"mc":[{"id":"1.168217554","rc":[{"batl":[[1,2.66,2.01],[2,2.68,2.14]],"ltp":2.62,"tv":224.04,"id":7412809}]}]}
{"op":"mcm","clk":"1008417530","pt":1580634880513,"mc":[{"id":"1.168217554","rc":[{"batl":[[0,2.6,4.1],[1,2.62,3.81],[2,2.64,2.18]],"ltp":2.62,"tv":224.04,"id":7412809}]}]}
{"op":"mcm","clk":"1008417595","pt":1580634881395,"mc":[{"id":"1.168217554","rc":[{"batl":[[0,2.62,3.81],[1,2.66,2.25],[2,2.68,2.01]],"ltp":2.62,"tv":224.04,"id":7412809}]}]}
{"op":"mcm","clk":"1008418761","pt":1580634901515,"mc":[{"id":"1.168217554","rc":[{"batl":[[0,2.6,4.22],[1,2.62,3.81],[2,2.66,2.25]],"ltp":2.62,"tv":224.04,"id":7412809}]}]}
{"op":"mcm","clk":"1008418842","pt":1580634902496,"mc":[{"id":"1.168217554","rc":[{"batl":[[0,2.62,3.81],[1,2.66,2.25],[2,2.68,2.14]],"ltp":2.62,"tv":224.04,"id":7412809}]}]}
{"op":"mcm","clk":"1008420109","pt":1580634923428,"mc":[{"id":"1.168217554","rc":[{"batl":[[0,2.6,4.01],[1,2.62,3.81],[2,2.64,2.18]],"ltp":2.62,"tv":224.04,"id":7412809}]}]}
{"op":"mcm","clk":"1008420137","pt":1580634923844,"mc":[{"id":"1.168217554","rc":[{"batl":[[0,2.62,3.81],[1,2.66,2.25],[2,2.68,2.14]],"ltp":2.62,"tv":224.04,"id":7412809}]}]}
{"op":"mcm","clk":"1008421302","pt":1580634944491,"mc":[{"id":"1.168217554","rc":[{"batl":[[0,2.6,4.13],[1,2.62,3.81],[2,2.64,2.18]],"ltp":2.62,"tv":224.04,"id":7412809}]}]}
{"op":"mcm","clk":"1008421350","pt":1580634945262,"mc":[{"id":"1.168217554","rc":[{"batl":[[0,2.62,3.81],[1,2.66,2.01],[2,2.68,2.01]],"ltp":2.62,"tv":224.04,"id":7412809}]}]}
{"op":"mcm","clk":"1008422457","pt":1580634965508,"mc":[{"id":"1.168217554","rc":[{"batl":[[0,2.6,4.24],[1,2.62,3.81],[2,2.66,2.01]],"ltp":2.62,"tv":224.04,"id":7412809}]}]}
{"op":"mcm","clk":"1008422514","pt":1580634966485,"mc":[{"id":"1.168217554","rc":[{"batl":[[2,2.64,2.04]],"ltp":2.62,"tv":224.04,"id":7412809}]}]}
{"op":"mcm","clk":"1008422544","pt":1580634966998,"mc":[{"id":"1.168217554","rc":[{"batl":[[0,2.62,3.81],[1,2.66,2.19],[2,2.68,2.14]],"ltp":2.62,"tv":224.04,"id":7412809}]}]}
{"op":"mcm","clk":"1008423694","pt":1580634987427,"mc":[{"id":"1.168217554","rc":[{"batl":[[0,2.6,4.03],[1,2.62,3.81],[2,2.64,2.18]],"ltp":2.62,"tv":224.04,"id":7412809}]}]}
{"op":"mcm","clk":"1008423726","pt":1580634987844,"mc":[{"id":"1.168217554","rc":[{"batl":[[0,2.62,3.81],[1,2.66,2.07],[2,2.68,2.01]],"ltp":2.62,"tv":224.04,"id":7412809}]}]}
{"op":"mcm","clk":"1008424920","pt":1580635008446,"mc":[{"id":"1.168217554","rc":[{"batl":[[0,2.6,4.15],[1,2.62,3.81],[2,2.64,2.04]],"ltp":2.62,"tv":224.04,"id":7412809}]}]}
{"op":"mcm","clk":"1008424983","pt":1580635009270,"mc":[{"id":"1.168217554","rc":[{"batl":[[0,2.62,3.81],[1,2.66,2.19],[2,2.68,2.14]],"ltp":2.62,"tv":224.04,"id":7412809}]}]}
{"op":"mcm","clk":"1008426168","pt":1580635029395,"mc":[{"id":"1.168217554","rc":[{"batl":[[0,2.6,4.27],[1,2.62,3.81],[2,2.66,2.19]],"ltp":2.62,"tv":224.04,"id":7412809}]}]}
{"op":"mcm","clk":"1008426243","pt":1580635030329,"mc":[{"id":"1.168217554","rc":[{"batl":[[0,2.62,3.81],[1,2.66,2.1],[2,2.68,2.01]],"ltp":2.62,"tv":224.04,"id":7412809}]}]}
{"op":"mcm","clk":"1008427589","pt":1580635051321,"mc":[{"id":"1.168217554","rc":[{"batl":[[0,2.6,4.05],[1,2.62,3.81],[2,2.64,2.18]],"ltp":2.62,"tv":224.04,"id":7412809}]}]}
{"op":"mcm","clk":"1008427622","pt":1580635051934,"mc":[{"id":"1.168217554","rc":[{"batl":[[0,2.62,3.81],[1,2.66,2.25],[2,2.68,2.01]],"ltp":2.62,"tv":224.04,"id":7412809}]}]}
{"op":"mcm","clk":"1008428671","pt":1580635072348,"mc":[{"id":"1.168217554","rc":[{"batl":[[0,2.6,4.17],[1,2.62,3.81],[2,2.64,2.18]],"ltp":2.62,"tv":224.04,"id":7412809}]}]}
{"op":"mcm","clk":"1008428700","pt":1580635072969,"mc":[{"id":"1.168217554","rc":[{"batl":[[0,2.62,3.81],[1,2.66,2.07],[2,2.68,2.14]],"ltp":2.62,"tv":224.04,"id":7412809}]}]}
{"op":"mcm","clk":"1008429806","pt":1580635093408,"mc":[{"id":"1.168217554","rc":[{"batl":[[0,2.6,4.29],[1,2.62,3.81],[2,2.66,2.07]],"ltp":2.62,"tv":224.04,"id":7412809}]}]}
{"op":"mcm","clk":"1008429871","pt":1580635094495,"mc":[{"id":"1.168217554","rc":[{"batl":[[0,2.62,3.81],[1,2.64,2.04],[2,2.66,2.13]],"ltp":2.62,"tv":224.04,"id":7412809}]}]}
{"op":"mcm","clk":"1008429879","pt":1580635094696,"mc":[{"id":"1.168217554","rc":[{"batl":[[1,2.66,2.13],[2,2.68,2.14]],"ltp":2.62,"tv":224.04,"id":7412809}]}]}
{"op":"mcm","clk":"1008431105","pt":1580635115520,"mc":[{"id":"1.168217554","rc":[{"batl":[[1,2.64,2.18],[2,2.66,2.25]],"ltp":2.62,"tv":224.04,"id":7412809}]}]}
{"op":"mcm","clk":"1008431132","pt":1580635115623,"mc":[{"id":"1.168217554","rc":[{"batl":[[1,2.66,2.25],[2,2.68,2.14]],"ltp":2.62,"tv":224.04,"id":7412809}]}]}
{"op":"mcm","clk":"1008432219","pt":1580635136354,"mc":[{"id":"1.168217554","rc":[{"batl":[[0,2.6,4.19],[1,2.62,3.81],[2,2.64,2.18]],"ltp":2.62,"tv":224.04,"id":7412809}]}]}
{"op":"mcm","clk":"1008432248","pt":1580635136871,"mc":[{"id":"1.168217554","rc":[{"batl":[[0,2.62,3.81],[1,2.66,2.04],[2,2.68,2.01]],"ltp":2.62,"tv":224.04,"id":7412809}]}]}
{"op":"mcm","clk":"1008433341","pt":1580635157386,"mc":[{"id":"1.168217554","rc":[{"batl":[[0,2.6,4.31],[1,2.62,3.81],[2,2.66,2.04]],"ltp":2.62,"tv":224.04,"id":7412809}]}]}
{"op":"mcm","clk":"1008433403","pt":1580635158413,"mc":[{"id":"1.168217554","rc":[{"batl":[[0,2.62,3.81],[1,2.66,2.19],[2,2.68,2.14]],"ltp":2.62,"tv":224.04,"id":7412809}]}]}
{"op":"mcm","clk":"1008434490","pt":1580635179227,"mc":[{"id":"1.168217554","rc":[{"batl":[[0,2.6,4.1],[1,2.62,3.81],[2,2.64,2.04]],"ltp":2.62,"tv":224.04,"id":7412809}]}]}
{"op":"mcm","clk":"1008434546","pt":1580635180209,"mc":[{"id":"1.168217554","rc":[{"batl":[[0,2.62,3.81],[1,2.66,2.07],[2,2.68,2.14]],"ltp":2.62,"tv":224.04,"id":7412809}]}]}
{"op":"mcm","clk":"1008435737","pt":1580635201453,"mc":[{"id":"1.168217554","rc":[{"batl":[[0,2.6,4.22],[1,2.62,3.81],[2,2.64,2.04]],"ltp":2.62,"tv":224.04,"id":7412809}]}]}
{"op":"mcm","clk":"1008435773","pt":1580635202069,"mc":[{"id":"1.168217554","rc":[{"batl":[[0,2.62,3.81],[1,2.66,2.25],[2,2.68,2.01]],"ltp":2.62,"tv":224.04,"id":7412809}]}]}
{"op":"mcm","clk":"1008436984","pt":1580635222365,"mc":[{"id":"1.168217554","rc":[{"batl":[[0,2.6,4.01],[1,2.62,3.81],[2,2.66,2.25]],"ltp":2.62,"tv":224.04,"id":7412809}]}]}
{"op":"mcm","clk":"1008437036","pt":1580635223189,"mc":[{"id":"1.168217554","rc":[{"batl":[[0,2.62,3.81],[1,2.66,2.16],[2,2.68,2.01]],"ltp":2.62,"tv":224.04,"id":7412809}]}]}
{"op":"mcm","clk":"1008438243","pt":1580635244405,"mc":[{"id":"1.168217554","rc":[{"batl":[[1,2.64,2.04],[2,2.66,2.25]],"ltp":2.62,"tv":224.04,"id":7412809}]}]}
{"op":"mcm","clk":"1008438259","pt":1580635244610,"mc":[{"id":"1.168217554","rc":[{"batl":[[1,2.66,2.25],[2,2.68,2.14]],"ltp":2.62,"tv":224.04,"id":7412809}]}]}
{"op":"mcm","clk":"1008439418","pt":1580635265319,"mc":[{"id":"1.168217554","rc":[{"batl":[[0,2.6,4.24],[1,2.62,3.81],[2,2.64,2.18]],"ltp":2.62,"tv":224.04,"id":7412809}]}]}
{"op":"mcm","clk":"1008439470","pt":1580635266037,"mc":[{"id":"1.168217554","rc":[{"batl":[[0,2.62,3.81],[1,2.66,2.13],[2,2.68,2.14]],"ltp":2.62,"tv":224.04,"id":7412809}]}]}
{"op":"mcm","clk":"1008440423","pt":1580635283460,"mc":[{"id":"1.168217554","rc":[{"trd":[[1.64,36.09]],"batl":[[0,1.64,15.9]],"ltp":1.64,"tv":1261.74,"id":2263624},{"trd":[[2.56,18.27]],"batb":[[0,2.54,8.2],[1,2.52,37.32],[2,2.5,11]],"batl":[[0,2.6,4.12],[1,2.62,3.81],[2,2.66,2.13]],"ltp":2.56,"tv":242.31,"id":7412809}],"tv":1504.05}]}
{"op":"mcm","clk":"1008440473","pt":1580635284132,"mc":[{"id":"1.168217554","rc":[{"batb":[[1,2.52,39.32]],"batl":[[0,2.62,3.81],[1,2.66,2.25],[2,2.68,2.14]],"ltp":2.56,"tv":242.31,"id":7412809}]}]}
{"op":"mcm","clk":"1008440947","pt":1580635293473,"mc":[{"id":"1.168217554","rc":[{"batl":[[0,2.6,4.18],[1,2.62,12.22],[2,2.66,2.25]],"ltp":2.56,"tv":242.31,"id":7412809}]}]}
{"op":"mcm","clk":"1008441026","pt":1580635294447,"mc":[{"id":"1.168217554","rc":[{"batb":[[0,1.63,7.18],[1,1.62,32.55],[2,1.61,405.38]],"ltp":1.64,"tv":1261.74,"id":2263624},{"batb":[[0,2.56,5.39],[1,2.54,8.2],[2,2.52,39.32]],"batl":[[0,2.62,12.22],[1,2.64,2.01],[2,2.66,2.04]],"ltp":2.56,"tv":242.31,"id":7412809}]}]}
{"op":"mcm","clk":"1008442157","pt":1580635315400,"mc":[{"id":"1.168217554","rc":[{"batl":[[0,2.6,4],[1,2.62,12.22],[2,2.64,2.01]],"ltp":2.56,"tv":242.31,"id":7412809}]}]}
{"op":"mcm","clk":"1008442823","pt":1580635325509,"mc":[{"id":"1.168217554","rc":[{"batl":[[1,2.62,3.81]],"ltp":2.56,"tv":242.31,"id":7412809}]}]}
{"op":"mcm","clk":"1008442840","pt":1580635325872,"mc":[{"id":"1.168217554","rc":[{"batb":[[1,1.62,19]],"ltp":1.64,"tv":1261.74,"id":2263624},{"batl":[[0,2.6,12.4]],"ltp":2.56,"tv":242.31,"id":7412809}]}]}
{"op":"mcm","clk":"1008458746","pt":1580635606316,"mc":[{"id":"1.168217554","marketDefinition":{"bspMarket":false,"turnInPlayEnabled":true,"persistenceEnabled":true,"marketBaseRate":5.0,"eventId":"29681263","eventTypeId":"2","numberOfWinners":1,"bettingType":"ODDS","marketType":"MATCH_ODDS","marketTime":"2020-02-02T11:21:00.000Z","suspendTime":"2020-02-02T11:21:00.000Z","bspReconciled":false,"complete":true,"inPlay":false,"crossMatching":true,"runnersVoidable":false,"numberOfActiveRunners":2,"betDelay":0,"status":"OPEN","runners":[{"status":"ACTIVE","sortPriority":1,"id":7412809,"name":"Evgeny Karlovskiy"},{"status":"ACTIVE","sortPriority":2,"id":2263624,"name":"Viktor Troicki"}],"regulators":["MR_INT"],"countryCode":"IN","discountAllowed":true,"timezone":"UTC","openDate":"2020-02-02T11:30:00.000Z","version":3148345095,"name":"Match Odds","eventName":"Karlovskiy v Troicki"}}]}
{"op":"mcm","clk":"1008459143","pt":1580635610325,"mc":[{"id":"1.168217554","marketDefinition":{"bspMarket":false,"turnInPlayEnabled":true,"persistenceEnabled":true,"marketBaseRate":5.0,"eventId":"29681263","eventTypeId":"2","numberOfWinners":1,"bettingType":"ODDS","marketType":"MATCH_ODDS","marketTime":"2020-02-02T11:21:00.000Z","suspendTime":"2020-02-02T11:21:00.000Z","bspReconciled":false,"complete":true,"inPlay":false,"crossMatching":true,"runnersVoidable":false,"numberOfActiveRunners":2,"betDelay":0,"status":"OPEN","runners":[{"status":"ACTIVE","sortPriority":1,"id":7412809,"name":"Evgeny Karlovskiy"},{"status":"ACTIVE","sortPriority":2,"id":2263624,"name":"Viktor Troicki"}],"regulators":["MR_INT"],"countryCode":"IN","discountAllowed":true,"timezone":"UTC","openDate":"2020-02-02T11:21:00.000Z","version":3148345095,"name":"Match Odds","eventName":"Karlovskiy v Troicki"}}]}
{"op":"mcm","clk":"1008470358","pt":1580635795419,"mc":[{"id":"1.168217554","rc":[{"batb":[[2,1.61,439.55]],"ltp":1.64,"tv":1261.74,"id":2263624},{"batb":[[1,2.54,36.52]],"ltp":2.56,"tv":242.31,"id":7412809}]}]}
{"op":"mcm","clk":"1008470825","pt":1580635802362,"mc":[{"id":"1.168217554","rc":[{"batl":[[1,2.62,3]],"ltp":2.56,"tv":242.31,"id":7412809}]}]}
{"op":"mcm","clk":"1008470910","pt":1580635803454,"mc":[{"id":"1.168217554","rc":[{"batb":[[1,2.54,44.35]],"ltp":2.56,"tv":242.31,"id":7412809}]}]}
{"op":"mcm","clk":"1008489995","pt":1580636086338,"mc":[{"id":"1.168217554","rc":[{"trd":[[1.63,300.32]],"batb":[[0,1.63,7]],"ltp":1.63,"tv":1275.82,"id":2263624},{"trd":[[2.6,88.03]],"batb":[[1,2.54,48.15]],"batl":[[0,2.62,3.24],[1,2.64,2.01],[2,2.66,2]],"ltp":2.6,"tv":274.63,"id":7412809}],"tv":1550.46}]}
{"op":"mcm","clk":"1008490082","pt":1580636087471,"mc":[{"id":"1.168217554","rc":[{"trd":[[1.48,669.65],[1.51,75.72],[1.59,848.02],[1.6,952.84],[1.61,854.19],[1.62,813.15],[1.63,314.32]],"batb":[[0,1.48,158.96],[1,1.41,37.86],[2,1.32,49.98]],"batl":[[0,1.62,2.07],[1,1.64,15.9],[2,1.65,30.83]],"ltp":1.48,"tv":4612.7,"id":2263624},{"trd":[[2.6,88.27],[2.62,91.12],[2.66,4.1],[2.68,2.14]],"batb":[[0,2.56,48.93],[2,2.52,11]],"batl":[[0,4.1,153.72],[1,95,15.9],[2,990,2.2]],"ltp":2.68,"tv":287.11,"id":7412809}],"tv":4899.82}]}
{"op":"mcm","clk":"1008490162","pt":1580636088352,"mc":[{"id":"1.168217554","rc":[{"trd":[[1.61,866.2],[1.62,825.15]],"batb":[[0,1.59,6.26],[1,1.58,6.26],[2,1.54,223.11]],"batl":[[0,1.62,17.72],[1,1.63,15.26],[2,1.64,33.58]],"ltp":1.61,"tv":4636.7,"id":2263624},{"batb":[[0,2.62,159.56],[1,2.58,46.06],[2,2.56,68.8]],"batl":[[0,2.7,3],[1,4.1,153.72],[2,95,15.9]],"ltp":2.68,"tv":287.11,"id":7412809}],"tv":4923.82}]}
{"op":"mcm","clk":"1008490189","pt":1580636088761,"mc":[{"id":"1.168217554","rc":[{"batb":[[0,1.58,6.26],[1,1.57,6.26]],"batl":[[0,1.6,16.26],[1,1.61,16.26],[2,1.62,20.68]],"ltp":1.61,"tv":4636.7,"id":2263624},{"batb":[[0,2.66,12.26],[1,2.62,163.1],[2,2.6,4.09]],"batl":[[0,2.74,3]],"ltp":2.68,"tv":287.11,"id":7412809}]}]}
{"op":"mcm","clk":"1008490341","pt":1580636090362,"mc":[{"id":"1.168217554","rc":[{"batl":[[0,1.61,33.23],[1,1.62,20.68],[2,1.63,3.04]],"ltp":1.61,"tv":4636.7,"id":2263624},{"batb":[[0,2.64,20.8],[1,2.62,16.8]],"ltp":2.68,"tv":287.11,"id":7412809}]}]}
{"op":"mcm","clk":"1008490427","pt":1580636091341,"mc":[{"id":"1.168217554","rc":[{"batl":[[0,1.62,17.72],[1,1.63,3.04],[2,1.64,18.58]],"ltp":1.61,"tv":4636.7,"id":2263624},{"batb":[[0,2.62,13.26],[1,2.6,17.09],[2,2.58,46.06]],"batl":[[1,2.76,3],[2,2.78,3.28]],"ltp":2.68,"tv":287.11,"id":7412809}]}]}
{"op":"mcm","clk":"1008490443","pt":1580636091547,"mc":[{"id":"1.168217554","rc":[{"batl":[[1,1.64,18.58],[2,1.65,7.67]],"ltp":1.61,"tv":4636.7,"id":2263624},{"batb":[[1,2.6,13]],"ltp":2.68,"tv":287.11,"id":7412809}]}]}
{"op":"mcm","clk":"1008490548","pt":1580636092938,"mc":[{"id":"1.168217554","rc":[{"batl":[[0,1.62,23.66]],"ltp":1.61,"tv":4636.7,"id":2263624},{"batb":[[0,2.62,31.52]],"ltp":2.68,"tv":287.11,"id":7412809}]}]}
{"op":"mcm","clk":"1008491391","pt":1580636103476,"mc":[{"id":"1.168217554","rc":[{"batl":[[0,1.62,36.26],[1,1.64,5.98],[2,1.65,4.97]],"ltp":1.61,"tv":4636.7,"id":2263624}]}]}
{"op":"mcm","clk":"1008491429","pt":1580636103837,"mc":[{"id":"1.168217554","rc":[{"batl":[[2,1.65,5.37]],"ltp":1.61,"tv":4636.7,"id":2263624},{"batb":[[0,2.62,39.3]],"ltp":2.68,"tv":287.11,"id":7412809}]}]}
{"op":"mcm","clk":"1008491706","pt":1580636107455,"mc":[{"id":"1.168217554","rc":[{"batb":[[1,2.6,20.65]],"ltp":2.68,"tv":287.11,"id":7412809}]}]}
{"op":"mcm","clk":"1008492284","pt":1580636115291,"mc":[{"id":"1.168217554","rc":[{"trd":[[1.58,12.52]],"batb":[[0,1.56,9],[1,1.55,9.08],[2,1.54,232.11]],"batl":[[0,1.58,29.93],[1,1.59,20.08],[2,1.6,22.99]],"ltp":1.58,"tv":4649.22,"id":2263624},{"batb":[[0,2.68,18.69],[1,2.66,19.86],[2,2.62,39.3]],"batl":[[0,2.8,4.08],[1,4.1,153.72],[2,95,15.9]],"ltp":2.68,"tv":287.11,"id":7412809}],"tv":4936.34}]}
{"op":"mcm","clk":"1008492396","pt":1580636116898,"mc":[{"id":"1.168217554","rc":[{"batl":[[1,1.59,37.27]],"ltp":1.58,"tv":4649.22,"id":2263624}]}]}
{"op":"mcm","clk":"1008492813","pt":1580636122420,"mc":[{"id":"1.168217554","rc":[{"trd":[[1.58,44.71]],"batl":[[0,1.58,13.83]],"ltp":1.58,"tv":4681.41,"id":2263624},{"batb":[[1,2.66,16.08]],"ltp":2.68,"tv":287.11,"id":7412809}],"tv":4968.52}]}
{"op":"mcm","clk":"1008492829","pt":1580636122623,"mc":[{"id":"1.168217554","rc":[{"batb":[[1,2.66,19.92]],"ltp":2.68,"tv":287.11,"id":7412809}]}]}
{"op":"mcm","clk":"1008493426","pt":1580636129434,"mc":[{"id":"1.168217554","rc":[{"trd":[[1.58,57.58]],"batl":[[0,1.58,7.4]],"ltp":1.58,"tv":4694.28,"id":2263624}],"tv":4981.4}]}
{"op":"mcm","clk":"1008493496","pt":1580636130209,"mc":[{"id":"1.168217554","rc":[{"batl":[[1,1.59,20.08]],"ltp":1.58,"tv":4694.28,"id":2263624},{"batb":[[1,2.66,19.86]],"ltp":2.68,"tv":287.11,"id":7412809}]}]}
{"op":"mcm","clk":"1008493894","pt":1580636135339,"mc":[{"id":"1.168217554","rc":[{"batl":[[2,1.6,40.07]],"ltp":1.58,"tv":4694.28,"id":2263624},{"batb":[[2,2.62,31.52]],"ltp":2.68,"tv":287.11,"id":7412809}]}]}
{"op":"mcm","clk":"1008493940","pt":1580636135851,"mc":[{"id":"1.168217554","rc":[{"batl":[[0,1.58,20]],"ltp":1.58,"tv":4694.28,"id":2263624},{"batb":[[0,2.72,7.33],[1,2.68,18.69],[2,2.66,19.86]],"ltp":2.68,"tv":287.11,"id":7412809}]}]}
{"op":"mcm","clk":"1008494042","pt":1580636137152,"mc":[{"id":"1.168217554","rc":[{"trd":[[1.58,83.33]],"batl":[[0,1.58,7.12]],"ltp":1.58,"tv":4720.03,"id":2263624},{"batb":[[1,2.68,26.11]],"ltp":2.68,"tv":287.11,"id":7412809}],"tv":5007.15}]}
{"op":"mcm","clk":"1008494502","pt":1580636142361,"mc":[{"id":"1.168217554","rc":[{"batb":[[2,2.66,20.36]],"ltp":2.68,"tv":287.11,"id":7412809}]}]}
{"op":"mcm","clk":"1008495544","pt":1580636156059,"mc":[{"id":"1.168217554","rc":[{"batb":[[2,2.66,19.86]],"ltp":2.68,"tv":287.11,"id":7412809}]}]}
{"op":"mcm","clk":"1008495844","pt":1580636159755,"mc":[{"id":"1.168217554","rc":[{"trd":[[2.72,7.41]],"batb":[[0,2.72,3.62],[1,2.7,15.32],[2,2.68,26.11]],"ltp":2.72,"tv":294.52,"id":7412809}],"tv":5014.56}]}
{"op":"mcm","clk":"1008498497","pt":1580636195505,"mc":[{"id":"1.168217554","rc":[{"trd":[[1.58,97.58]],"batb":[[2,1.54,9]],"batl":[[0,1.6,37.16],[1,1.61,22.99],[2,1.62,10.15]],"ltp":1.58,"tv":4734.28,"id":2263624},{"trd":[[2.7,19.88],[2.72,14.65]],"batb":[[0,2.68,22.5],[1,2.66,19.86],[2,2.64,20.26]],"batl":[[1,2.82,4],[2,2.84,4.19]],"ltp":2.7,"tv":321.65,"id":7412809}],"tv":5055.93}]}
{"op":"mcm","clk":"1008498573","pt":1580636196437,"mc":[{"id":"1.168217554","rc":[{"batb":[[0,1.57,9.19],[1,1.56,121.67],[2,1.55,9.08]],"batl":[[1,1.61,20.08]],"ltp":1.58,"tv":4734.28,"id":2263624},{"batb":[[0,2.68,15.19],[1,2.66,23.55],[2,2.64,61.52]],"ltp":2.7,"tv":321.65,"id":7412809}]}]}
{"op":"mcm","clk":"1008498727","pt":1580636198442,"mc":[{"id":"1.168217554","rc":[{"batb":[[0,1.57,31.3]],"ltp":1.58,"tv":4734.28,"id":2263624},{"batl":[[0,2.76,16.6],[1,2.8,4.08],[2,2.82,4]],"ltp":2.7,"tv":321.65,"id":7412809}]}]}
{"op":"mcm","clk":"1008504597","pt":1580636282269,"mc":[{"id":"1.168217554","rc":[{"batb":[[0,2.68,55.37]],"ltp":2.7,"tv":321.65,"id":7412809}]}]}
{"op":"mcm","clk":"1008507812","pt":1580636329352,"mc":[{"id":"1.168217554","rc":[{"batb":[[0,1.58,420.1],[1,1.57,31.3],[2,1.56,121.67]],"ltp":1.58,"tv":4734.28,"id":2263624}]}]}
{"op":"mcm","clk":"1008507833","pt":1580636329615,"mc":[{"id":"1.168217554","rc":[{"batb":[[0,1.58,431.1]],"batl":[[0,1.6,17.08],[2,1.62,32.15]],"ltp":1.58,"tv":4734.28,"id":2263624},{"batb":[[0,2.68,40.18]],"batl":[[0,2.74,5],[1,2.76,16.6],[2,2.8,4.08]],"ltp":2.7,"tv":321.65,"id":7412809}]}]}
{"op":"mcm","clk":"1008507973","pt":1580636331731,"mc":[{"id":"1.168217554","rc":[{"batb":[[1,1.57,451.4]],"ltp":1.58,"tv":4734.28,"id":2263624}]}]}
{"op":"mcm","clk":"1008508212","pt":1580636335145,"mc":[{"id":"1.168217554","rc":[{"batb":[[2,1.56,541.77]],"ltp":1.58,"tv":4734.28,"id":2263624}]}]}
{"op":"mcm","clk":"1008509001","pt":1580636346664,"mc":[{"id":"1.168217554","rc":[{"batb":[[1,1.57,456.21],[2,1.56,546.77]],"batl":[[1,1.61,27]],"ltp":1.58,"tv":4734.28,"id":2263624},{"batl":[[0,2.72,6.03],[1,2.74,5],[2,2.76,16.6]],"ltp":2.7,"tv":321.65,"id":7412809}]}]}
{"op":"mcm","clk":"1008509193","pt":1580636349861,"mc":[{"id":"1.168217554","rc":[{"trd":[[1.6,1054.3]],"batb":[[0,1.6,41.65],[1,1.59,14.05],[2,1.58,431.1]],"batl":[[0,1.62,29.4],[1,1.63,30.09],[2,1.64,33.03]],"ltp":1.6,"tv":4835.74,"id":2263624},{"trd":[[2.68,42.32]],"batb":[[0,2.66,7.47],[1,2.64,57.45],[2,2.62,41.88]],"batl":[[0,2.7,6.05],[1,2.72,6.03],[2,2.74,5]],"ltp":2.68,"tv":361.82,"id":7412809}],"tv":5197.57}]}
{"op":"mcm","clk":"1008509280","pt":1580636351460,"mc":[{"id":"1.168217554","rc":[{"batb":[[0,2.64,64.98],[1,2.62,41.88],[2,2.6,3.64]],"ltp":2.68,"tv":361.82,"id":7412809}]}]}
{"op":"mcm","clk":"1008509301","pt":1580636351772,"mc":[{"id":"1.168217554","rc":[{"batb":[[2,1.58,436.1]],"batl":[[0,1.62,37.4]],"ltp":1.6,"tv":4835.74,"id":2263624},{"batb":[[0,2.64,48.79],[1,2.62,38.26],[2,2.6,24.64]],"ltp":2.68,"tv":361.82,"id":7412809}]}]}
{"op":"mcm","clk":"1008509432","pt":1580636353473,"mc":[{"id":"1.168217554","rc":[{"batb":[[0,2.64,41.26]],"batl":[[0,2.68,12.6],[1,2.7,6.05],[2,2.72,6.03]],"ltp":2.68,"tv":361.82,"id":7412809}]}]}
{"op":"mcm","clk":"1008510551","pt":1580636369312,"mc":[{"id":"1.168217554","rc":[{"batb":[[1,2.62,45.85]],"ltp":2.68,"tv":361.82,"id":7412809}]}]}
{"op":"mcm","clk":"1008510593","pt":1580636369778,"mc":[{"id":"1.168217554","rc":[{"batl":[[2,1.64,33.53]],"ltp":1.6,"tv":4835.74,"id":2263624}]}]}
{"op":"mcm","clk":"1008511436","pt":1580636381404,"mc":[{"id":"1.168217554","rc":[{"batl":[[2,1.64,33.03]],"ltp":1.6,"tv":4835.74,"id":2263624},{"batl":[[0,2.68,20.6]],"ltp":2.68,"tv":361.82,"id":7412809}]}]}
{"op":"mcm","clk":"1008514337","pt":1580636424198,"mc":[{"id":"1.168217554","rc":[{"batb":[[0,1.6,58.65]],"batl":[[2,1.64,35.96]],"ltp":1.6,"tv":4835.74,"id":2263624}]}]}
{"op":"mcm","clk":"1008516141","pt":1580636455399,"mc":[{"id":"1.168217554","rc":[{"trd":[[1.6,1123.21]],"batb":[[0,1.6,24.19]],"batl":[[2,1.64,33.28]],"ltp":1.6,"tv":4904.65,"id":2263624}],"tv":5266.48}]}
{"op":"mcm","clk":"1008516274","pt":1580636457477,"mc":[{"id":"1.168217554","rc":[{"batb":[[2,1.58,507.89]],"batl":[[0,1.62,7.4]],"ltp":1.6,"tv":4904.65,"id":2263624},{"batb":[[0,2.62,62.17],[1,2.6,24.64],[2,2.58,3.87]],"batl":[[0,2.66,8.31],[1,2.68,20.6],[2,2.7,6.05]],"ltp":2.68,"tv":361.82,"id":7412809}]}]}
{"op":"mcm","clk":"1008516330","pt":1580636458495,"mc":[{"id":"1.168217554","rc":[{"batl":[[1,1.63,27.05]],"ltp":1.6,"tv":4904.65,"id":2263624},{"batb":[[0,2.62,54.58],[1,2.6,28.65]],"ltp":2.68,"tv":361.82,"id":7412809}]}]}
{"op":"mcm","clk":"1008517479","pt":1580636476484,"mc":[{"id":"1.168217554","rc":[{"batl":[[1,2.68,8]],"ltp":2.68,"tv":361.82,"id":7412809}]}]}
{"op":"mcm","clk":"1008517534","pt":1580636477312,"mc":[{"id":"1.168217554","rc":[{"batb":[[0,1.6,7.19]],"batl":[[0,1.62,38.4]],"ltp":1.6,"tv":4904.65,"id":2263624},{"batb":[[0,2.62,76.58],[2,2.58,26.87]],"batl":[[0,2.66,5.21]],"ltp":2.68,"tv":361.82,"id":7412809}]}]}
{"op":"mcm","clk":"1008521305","pt":1580636528478,"mc":[{"id":"1.168217554","rc":[{"trd":[[1.6,1138.81]],"batb":[[0,1.6,16.04]],"ltp":1.6,"tv":4920.25,"id":2263624},{"trd":[[2.66,4.83]],"batb":[[0,2.62,54.58]],"batl":[[0,2.66,4.48]],"ltp":2.66,"tv":362.55,"id":7412809}],"tv":5282.81}]}
{"op":"mcm","clk":"1008521373","pt":1580636529468,"mc":[{"id":"1.168217554","rc":[{"batb":[[0,1.59,14.05],[1,1.58,507.89],[2,1.57,434.1]],"ltp":1.6,"tv":4920.25,"id":2263624},{"batb":[[0,2.62,75.58]],"ltp":2.66,"tv":362.55,"id":7412809}]}]}
{"op":"mcm","clk":"1008521534","pt":1580636531491,"mc":[{"id":"1.168217554","rc":[{"batb":[[0,1.6,16.06],[1,1.59,14.05],[2,1.58,507.89]],"ltp":1.6,"tv":4920.25,"id":2263624}]}]}
{"op":"mcm","clk":"1008521601","pt":1580636532391,"mc":[{"id":"1.168217554","rc":[{"batb":[[0,2.62,54.58]],"ltp":2.66,"tv":362.55,"id":7412809}]}]}
{"op":"mcm","clk":"1008521709","pt":1580636533483,"mc":[{"id":"1.168217554","rc":[{"batb":[[0,1.59,14.05],[1,1.58,507.89],[2,1.57,434.1]],"ltp":1.6,"tv":4920.25,"id":2263624},{"batb":[[0,2.62,75.58]],"ltp":2.66,"tv":362.55,"id":7412809}]}]}
{"op":"mcm","clk":"1008521822","pt":1580636534475,"mc":[{"id":"1.168217554","rc":[{"batb":[[0,1.6,16.07],[1,1.59,14.05],[2,1.58,507.89]],"ltp":1.6,"tv":4920.25,"id":2263624},{"batb":[[0,2.62,54.58]],"ltp":2.66,"tv":362.55,"id":7412809}]}]}
{"op":"mcm","clk":"1008521919","pt":1580636535404,"mc":[{"id":"1.168217554","rc":[{"batb":[[0,1.6,16.08]],"ltp":1.6,"tv":4920.25,"id":2263624}]}]}
{"op":"mcm","clk":"1008522033","pt":1580636536391,"mc":[{"id":"1.168217554","rc":[{"batb":[[0,1.59,14.05],[1,1.58,507.89],[2,1.57,434.1]],"ltp":1.6,"tv":4920.25,"id":2263624},{"batb":[[0,2.62,75.58]],"ltp":2.66,"tv":362.55,"id":7412809}]}]}
{"op":"mcm","clk":"1008522127","pt":1580636537219,"mc":[{"id":"1.168217554","rc":[{"batl":[[1,1.63,30.09]],"ltp":1.6,"tv":4920.25,"id":2263624},{"batb":[[0,2.64,30.14],[1,2.62,75.58],[2,2.6,32.54]],"batl":[[1,2.7,6.05],[2,2.72,6.03]],"ltp":2.66,"tv":362.55,"id":7412809}]}]}
{"op":"mcm","clk":"1008522252","pt":1580636538302,"mc":[{"id":"1.168217554","rc":[{"batb":[[0,2.64,37.67],[2,2.6,24.89]],"ltp":2.66,"tv":362.55,"id":7412809}]}]}
{"op":"mcm","clk":"1008524468","pt":1580636570037,"mc":[{"id":"1.168217554","rc":[{"batl":[[2,1.64,33.53]],"ltp":1.6,"tv":4920.25,"id":2263624},{"batl":[[0,2.7,6.05],[1,2.72,6.03],[2,2.74,8]],"ltp":2.66,"tv":362.55,"id":7412809}]}]}
{"op":"mcm","clk":"1008531678","pt":1580636675421,"mc":[{"id":"1.168217554","rc":[{"batb":[[2,1.57,435.57]],"ltp":1.6,"tv":4920.25,"id":2263624}]}]}
{"op":"mcm","clk":"1008536042","pt":1580636732289,"mc":[{"id":"1.168217554","rc":[{"batl":[[2,1.64,33.03]],"ltp":1.6,"tv":4920.25,"id":2263624},{"batb":[[0,2.64,7.53]],"ltp":2.66,"tv":362.55,"id":7412809}]}]}
{"op":"mcm","clk":"1008536127","pt":1580636733377,"mc":[{"id":"1.168217554","rc":[{"batb":[[0,1.59,23],[1,1.58,514.89],[2,1.57,444.57]],"batl":[[0,1.62,7.4],[1,1.63,27.05]],"ltp":1.6,"tv":4920.25,"id":2263624},{"batb":[[0,2.62,62.17],[1,2.6,21],[2,2.58,26.56]],"batl":[[0,2.7,11],[1,2.72,11]],"ltp":2.66,"tv":362.55,"id":7412809}]}]}
{"op":"mcm","clk":"1008536260","pt":1580636735024,"mc":[{"id":"1.168217554","rc":[{"batb":[[0,2.62,54.58],[1,2.6,28.65]],"ltp":2.66,"tv":362.55,"id":7412809}]}]}
{"op":"mcm","clk":"1008540242","pt":1580636785259,"mc":[{"id":"1.168217554","rc":[{"trd":[[1.59,856.46]],"batb":[[0,1.59,33.02]],"ltp":1.59,"tv":4928.69,"id":2263624},{"batl":[[0,2.7,19.4]],"ltp":2.66,"tv":362.55,"id":7412809}],"tv":5291.25}]}
{"op":"mcm","clk":"1008540800","pt":1580636792495,"mc":[{"id":"1.168217554","rc":[{"batl":[[0,1.62,43.4],[1,1.63,38.77],[2,1.64,39.3]],"ltp":1.59,"tv":4928.69,"id":2263624},{"batb":[[0,2.64,30.14],[1,2.62,54.58],[2,2.6,32.59]],"ltp":2.66,"tv":362.55,"id":7412809}]}]}
{"op":"mcm","clk":"1008540853","pt":1580636793217,"mc":[{"id":"1.168217554","rc":[{"batl":[[2,1.64,42.23]],"ltp":1.59,"tv":4928.69,"id":2263624},{"batb":[[0,2.64,37.67],[2,2.6,24.94]],"ltp":2.66,"tv":362.55,"id":7412809}]}]}
{"op":"mcm","clk":"1008544902","pt":1580636847392,"mc":[{"id":"1.168217554","rc":[{"batb":[[0,1.59,18.78]],"ltp":1.59,"tv":4928.69,"id":2263624},{"batb":[[1,2.62,80.58]],"batl":[[0,2.7,11]],"ltp":2.66,"tv":362.55,"id":7412809}]}]}
{"op":"mcm","clk":"1008552445","pt":1580636970358,"mc":[{"id":"1.168217554","rc":[{"batl":[[2,1.64,39.3]],"ltp":1.59,"tv":4928.69,"id":2263624},{"batl":[[0,2.7,19.4]],"ltp":2.66,"tv":362.55,"id":7412809}]}]}
{"op":"mcm","clk":"1008552460","pt":1580636970564,"mc":[{"id":"1.168217554","rc":[{"batl":[[2,1.64,41.98]],"ltp":1.59,"tv":4928.69,"id":2263624}]}]}
{"op":"mcm","clk":"1008553565","pt":1580636987416,"mc":[{"id":"1.168217554","rc":[{"batl":[[2,1.64,39.3]],"ltp":1.59,"tv":4928.69,"id":2263624},{"batb":[[0,2.64,7.53]],"ltp":2.66,"tv":362.55,"id":7412809}]}]}
{"op":"mcm","clk":"1008553583","pt":1580636987627,"mc":[{"id":"1.168217554","rc":[{"batl":[[2,1.64,41.98]],"ltp":1.59,"tv":4928.69,"id":2263624}]}]}
{"op":"mcm","clk":"1008557519","pt":1580637046396,"mc":[{"id":"1.168217554","rc":[{"batb":[[0,2.64,37.67]],"ltp":2.66,"tv":362.55,"id":7412809}]}]}
{"op":"mcm","clk":"1008557547","pt":1580637046811,"mc":[{"id":"1.168217554","rc":[{"batl":[[2,1.64,42.23]],"ltp":1.59,"tv":4928.69,"id":2263624}]}]}
{"op":"mcm","clk":"1008557734","pt":1580637049808,"mc":[{"id":"1.168217554","rc":[{"batl":[[0,1.61,2.27],[1,1.62,43.4],[2,1.63,38.77]],"ltp":1.59,"tv":4928.69,"id":2263624}]}]}
{"op":"mcm","clk":"1008558307","pt":1580637058331,"mc":[{"id":"1.168217554","rc":[{"batb":[[2,1.57,443.1]],"ltp":1.59,"tv":4928.69,"id":2263624}]}]}
{"op":"mcm","clk":"1008562198","pt":1580637124127,"mc":[{"id":"1.168217554","rc":[{"batb":[[0,1.59,33.02]],"ltp":1.59,"tv":4928.69,"id":2263624}]}]}
{"op":"mcm","clk":"1008569923","pt":1580637243154,"mc":[{"id":"1.168217554","rc":[{"batb":[[0,2.64,7.53]],"ltp":2.66,"tv":362.55,"id":7412809}]}]}
{"op":"mcm","clk":"1008573975","pt":1580637301438,"mc":[{"id":"1.168217554","rc":[{"batb":[[0,2.66,30.14],[1,2.64,7.53],[2,2.62,84.62]],"ltp":2.66,"tv":362.55,"id":7412809}]}]}
{"op":"mcm","clk":"1008577002","pt":1580637340404,"mc":[{"id":"1.168217554","rc":[{"batl":[[0,2.7,11]],"ltp":2.66,"tv":362.55,"id":7412809}]}]}
{"op":"mcm","clk":"1008579171","pt":1580637371444,"mc":[{"id":"1.168217554","rc":[{"batl":[[0,2.7,19.4]],"ltp":2.66,"tv":362.55,"id":7412809}]}]}
{"op":"mcm","clk":"1008588685","pt":1580637497362,"mc":[{"id":"1.168217554","rc":[{"batb":[[0,2.64,7.53],[1,2.62,80.58],[2,2.6,24.39]],"ltp":2.66,"tv":362.55,"id":7412809}]}]}
{"op":"mcm","clk":"1008592523","pt":1580637556326,"mc":[{"id":"1.168217554","rc":[{"batb":[[0,2.66,30.14],[1,2.64,7.53],[2,2.62,84.2]],"ltp":2.66,"tv":362.55,"id":7412809}]}]}
{"op":"mcm","clk":"1008605189","pt":1580637730443,"mc":[{"id":"1.168217554","rc":[{"trd":[[1.61,932.87],[1.62,899.76]],"batb":[[0,1.61,659.12],[1,1.6,23.05],[2,1.59,33.02]],"batl":[[0,1.63,36],[1,1.64,39.3],[2,1.65,38.15]],"ltp":1.62,"tv":5069.98,"id":2263624},{"trd":[[2.62,128.11],[2.64,7.53],[2.66,34.97]],"batb":[[0,2.62,17.59],[1,2.6,21],[2,2.58,26.68]],"batl":[[0,2.64,13.73],[1,2.66,37.75],[2,2.68,24.3]],"ltp":2.62,"tv":437.21,"id":7412809}],"tv":5507.19}]}
{"op":"mcm","clk":"1008605264","pt":1580637731481,"mc":[{"id":"1.168217554","rc":[{"batb":[[0,1.62,22.06],[1,1.61,659.12],[2,1.6,23.05]],"batl":[[1,1.64,42.48]],"ltp":1.62,"tv":5069.98,"id":2263624},{"batb":[[0,2.6,54.81],[1,2.58,26.68],[2,2.56,30.83]],"batl":[[0,2.64,24.73]],"ltp":2.62,"tv":437.21,"id":7412809}]}]}
{"op":"mcm","clk":"1008605286","pt":1580637731787,"mc":[{"id":"1.168217554","rc":[{"batb":[[0,1.61,659.12],[1,1.6,23.05],[2,1.59,63.84]],"batl":[[0,1.64,39.3],[1,1.65,38.15],[2,1.66,2.75]],"ltp":1.62,"tv":5069.98,"id":2263624},{"batb":[[0,2.6,33.81],[1,2.58,26]],"ltp":2.62,"tv":437.21,"id":7412809}]}]}
{"op":"mcm","clk":"1008606156","pt":1580637743103,"mc":[{"id":"1.168217554","rc":[{"batb":[[2,1.59,49.6]],"batl":[[2,1.66,3.25]],"ltp":1.62,"tv":5069.98,"id":2263624},{"batb":[[1,2.56,30.83],[2,2.54,30.68]],"ltp":2.62,"tv":437.21,"id":7412809}]}]}
{"op":"mcm","clk":"1008606685","pt":1580637750476,"mc":[{"id":"1.168217554","rc":[{"batl":[[2,1.66,2.75]],"ltp":1.62,"tv":5069.98,"id":2263624},{"batb":[[2,2.54,31.18]],"ltp":2.62,"tv":437.21,"id":7412809}]}]}
{"op":"mcm","clk":"1008611139","pt":1580637810407,"mc":[{"id":"1.168217554","rc":[{"trd":[[2.64,52.73]],"batl":[[0,2.64,2.13]],"ltp":2.64,"tv":482.41,"id":7412809}],"tv":5552.39}]}
{"op":"mcm","clk":"1008611206","pt":1580637810771,"mc":[{"id":"1.168217554","rc":[{"batb":[[0,1.61,636.6]],"batl":[[0,1.63,39],[1,1.64,39.3],[2,1.65,38.15]],"ltp":1.62,"tv":5069.98,"id":2263624},{"batb":[[1,2.58,28.16],[2,2.56,30.83]],"batl":[[0,2.66,11.05],[1,2.68,11.05],[2,2.7,11]],"ltp":2.64,"tv":482.41,"id":7412809}]}]}
{"op":"mcm","clk":"1008622735","pt":1580637950918,"mc":[{"id":"1.168217554","rc":[{"batb":[[1,1.6,25.32]],"ltp":1.62,"tv":5069.98,"id":2263624}]}]}
{"op":"mcm","clk":"1008626761","pt":1580638001235,"mc":[{"id":"1.168217554","rc":[{"batb":[[1,1.6,23.05]],"ltp":1.62,"tv":5069.98,"id":2263624}]}]}
{"op":"mcm","clk":"1008631917","pt":1580638063221,"mc":[{"id":"1.168217554","rc":[{"trd":[[1.61,988.45]],"batb":[[0,1.61,581.02]],"batl":[[0,1.64,82.68],[1,1.65,38.15],[2,1.66,3.25]],"ltp":1.61,"tv":5125.56,"id":2263624},{"trd":[[2.64,86.63]],"batl":[[0,2.64,11],[1,2.66,11.05],[2,2.68,11.05]],"ltp":2.64,"tv":516.31,"id":7412809}],"tv":5641.87}]}
{"op":"mcm","clk":"1008653483","pt":1580638316345,"mc":[{"id":"1.168217554","rc":[{"trd":[[1.61,1026]],"batb":[[0,1.61,543.47]],"ltp":1.61,"tv":5163.11,"id":2263624},{"trd":[[2.64,131.53]],"ltp":2.64,"tv":561.21,"id":7412809}],"tv":5724.32}]}
{"op":"mcm","clk":"1008676959","pt":1580638569500,"mc":[{"id":"1.168217554","rc":[{"batl":[[0,1.63,43],[1,1.64,85.36],[2,1.65,38.15]],"ltp":1.61,"tv":5163.11,"id":2263624},{"batb":[[0,2.62,26.35],[1,2.6,63.81],[2,2.58,32.22]],"batl":[[0,2.66,11.05],[1,2.68,11.05],[2,2.7,11]],"ltp":2.64,"tv":561.21,"id":7412809}]}]}
{"op":"mcm","clk":"1008677875","pt":1580638581315,"mc":[{"id":"1.168217554","rc":[{"batb":[[1,1.6,443.15],[2,1.59,469.7]],"batl":[[2,1.65,35.05]],"ltp":1.61,"tv":5163.11,"id":2263624},{"batb":[[1,2.6,33.81]],"ltp":2.64,"tv":561.21,"id":7412809}]}]}
{"op":"mcm","clk":"1008677893","pt":1580638581527,"mc":[{"id":"1.168217554","rc":[{"batl":[[2,1.65,37.75]],"ltp":1.61,"tv":5163.11,"id":2263624}]}]}
{"op":"mcm","clk":"1008695254","pt":1580638765945,"mc":[{"id":"1.168217554","rc":[{"batl":[[1,1.64,82.68],[2,1.65,38.15]],"ltp":1.61,"tv":5163.11,"id":2263624},{"batb":[[0,2.6,33.81],[1,2.58,28.16],[2,2.56,30.58]],"ltp":2.64,"tv":561.21,"id":7412809}]}]}
{"op":"mcm","clk":"1008700408","pt":1580638822475,"mc":[{"id":"1.168217554","rc":[{"batb":[[0,1.61,520.47]],"batl":[[1,1.64,85.36],[2,1.65,35.05]],"ltp":1.61,"tv":5163.11,"id":2263624},{"batb":[[0,2.62,26.35],[1,2.6,64.81],[2,2.58,31.72]],"ltp":2.64,"tv":561.21,"id":7412809}]}]}
{"op":"mcm","clk":"1008700439","pt":1580638822738,"mc":[{"id":"1.168217554","rc":[{"batl":[[2,1.65,37.75]],"ltp":1.61,"tv":5163.11,"id":2263624}]}]}
{"op":"mcm","clk":"1008704502","pt":1580638865236,"mc":[{"id":"1.168217554","rc":[{"batb":[[0,1.61,543.47]],"batl":[[1,1.64,82.68],[2,1.65,39.95]],"ltp":1.61,"tv":5163.11,"id":2263624},{"batb":[[0,2.6,33.81],[1,2.58,28.16],[2,2.56,31.08]],"ltp":2.64,"tv":561.21,"id":7412809}]}]}
{"op":"mcm","clk":"1008706886","pt":1580638891444,"mc":[{"id":"1.168217554","rc":[{"batb":[[0,1.61,520.47]],"ltp":1.61,"tv":5163.11,"id":2263624},{"batb":[[0,2.62,22.53],[1,2.6,64.81],[2,2.58,31.03]],"ltp":2.64,"tv":561.21,"id":7412809}]}]}
{"op":"mcm","clk":"1008706962","pt":1580638892277,"mc":[{"id":"1.168217554","rc":[{"batl":[[1,1.64,87.61],[2,1.65,39.55]],"ltp":1.61,"tv":5163.11,"id":2263624}]}]}
{"op":"mcm","clk":"1008725849","pt":1580639075434,"mc":[{"id":"1.168217554","rc":[{"trd":[[1.61,1068.87]],"batb":[[0,1.61,477.6]],"ltp":1.61,"tv":5205.98,"id":2263624},{"trd":[[2.64,157.67]],"ltp":2.64,"tv":587.35,"id":7412809}],"tv":5793.34}]}
{"op":"mcm","clk":"1008749498","pt":1580639299229,"mc":[{"id":"1.168217554","rc":[{"trd":[[1.61,1079]],"batb":[[0,1.61,472.53]],"batl":[[2,1.65,40.15]],"ltp":1.61,"tv":5216.11,"id":2263624}],"tv":5803.47}]}
{"op":"mcm","clk":"1008752924","pt":1580639336453,"mc":[{"id":"1.168217554","rc":[{"batl":[[2,1.65,39.55]],"ltp":1.61,"tv":5216.11,"id":2263624}]}]}
{"op":"mcm","clk":"1008759986","pt":1580639404431,"mc":[{"id":"1.168217554","rc":[{"batb":[[0,1.61,480.73]],"batl":[[2,1.65,35.05]],"ltp":1.61,"tv":5216.11,"id":2263624}]}]}
{"op":"mcm","clk":"1008759996","pt":1580639404543,"mc":[{"id":"1.168217554","rc":[{"batl":[[2,1.65,39.95]],"ltp":1.61,"tv":5216.11,"id":2263624}]}]}
{"op":"mcm","clk":"1008762750","pt":1580639430076,"mc":[{"id":"1.168217554","rc":[{"trd":[[1.62,907.3]],"batl":[[2,1.65,39.75]],"ltp":1.62,"tv":5223.65,"id":2263624},{"trd":[[2.62,132.77]],"batb":[[0,2.62,17.87]],"ltp":2.62,"tv":592.01,"id":7412809}],"tv":5815.66}]}
{"op":"mcm","clk":"1008763796","pt":1580639439506,"mc":[{"id":"1.168217554","rc":[{"trd":[[1.62,912.3]],"batl":[[2,1.65,40.15]],"ltp":1.62,"tv":5228.65,"id":2263624},{"trd":[[2.62,135.86]],"batb":[[0,2.62,14.78]],"ltp":2.62,"tv":595.1,"id":7412809}],"tv":5823.75}]}
{"op":"mcm","clk":"1008765615","pt":1580639455471,"mc":[{"id":"1.168217554","rc":[{"batl":[[2,1.65,35.05]],"ltp":1.62,"tv":5228.65,"id":2263624}]}]}
{"op":"mcm","clk":"1008765653","pt":1580639455693,"mc":[{"id":"1.168217554","rc":[{"batl":[[2,1.65,39.75]],"ltp":1.62,"tv":5228.65,"id":2263624}]}]}
{"op":"mcm","clk":"1008767330","pt":1580639471153,"mc":[{"id":"1.168217554","rc":[{"batl":[[2,1.65,40.15]],"ltp":1.62,"tv":5228.65,"id":2263624}]}]}
{"op":"mcm","clk":"1008787019","pt":1580639653420,"mc":[{"id":"1.168217554","rc":[{"batl":[[2,1.65,35.05]],"ltp":1.62,"tv":5228.65,"id":2263624}]}]}
{"op":"mcm","clk":"1008787044","pt":1580639653631,"mc":[{"id":"1.168217554","rc":[{"batl":[[2,1.65,39.95]],"ltp":1.62,"tv":5228.65,"id":2263624}]}]}
{"op":"mcm","clk":"1008795995","pt":1580639735443,"mc":[{"id":"1.168217554","rc":[{"trd":[[1.61,1193.78]],"batb":[[0,1.61,423.31]],"ltp":1.61,"tv":5343.43,"id":2263624}],"tv":5938.53}]}
{"op":"mcm","clk":"1008796134","pt":1580639736443,"mc":[{"id":"1.168217554","rc":[{"trd":[[1.62,935]],"batb":[[0,1.61,447.31]],"batl":[[1,1.64,82.68],[2,1.65,39.55]],"ltp":1.62,"tv":5366.13,"id":2263624},{"trd":[[2.62,149.88]],"batb":[[0,2.6,65.57],[1,2.58,28.16],[2,2.56,30.08]],"ltp":2.62,"tv":609.12,"id":7412809}],"tv":5975.26}]}
{"op":"mcm","clk":"1008824480","pt":1580639983477,"mc":[{"id":"1.168217554","rc":[{"trd":[[1.6,1587.04],[1.61,2088.4],[1.62,937.13]],"batb":[[0,1.61,23],[1,1.6,242.03]],"batl":[[0,1.63,83.83]],"ltp":1.62,"tv":6711.11,"id":2263624},{"trd":[[2.62,150.64]],"batb":[[0,2.6,33.81],[2,2.56,40.08]],"batl":[[0,2.64,11],[1,2.66,11.05],[2,2.68,11.05]],"ltp":2.62,"tv":609.88,"id":7412809}],"tv":7321.0}]}
{"op":"mcm","clk":"1008824496","pt":1580639983624,"mc":[{"id":"1.168217554","rc":[{"batb":[[2,1.59,469.45]],"ltp":1.62,"tv":6711.11,"id":2263624}]}]}
{"op":"mcm","clk":"1008825258","pt":1580639990412,"mc":[{"id":"1.168217554","rc":[{"batl":[[0,1.62,7.57],[1,1.63,83.83],[2,1.64,82.68]],"ltp":1.62,"tv":6711.11,"id":2263624}]}]}
{"op":"mcm","clk":"1008825326","pt":1580639991007,"mc":[{"id":"1.168217554","rc":[{"batl":[[2,1.64,87.86]],"ltp":1.62,"tv":6711.11,"id":2263624}]}]}
{"op":"mcm","clk":"1008825498","pt":1580639992514,"mc":[{"id":"1.168217554","rc":[{"batl":[[0,1.63,83.83],[1,1.64,87.86],[2,1.65,39.75]],"ltp":1.62,"tv":6711.11,"id":2263624}]}]}
{"op":"mcm","clk":"1008825611","pt":1580639993501,"mc":[{"id":"1.168217554","rc":[{"batb":[[0,1.62,23],[1,1.61,23],[2,1.6,242.03]],"batl":[[0,1.64,82.68],[1,1.65,39.75],[2,1.66,53.93]],"ltp":1.62,"tv":6711.11,"id":2263624},{"trd":[[2.6,155.89]],"batb":[[0,2.58,25.88],[1,2.56,37],[2,2.54,40.12]],"batl":[[0,2.6,12.4],[1,2.62,11.29],[2,2.64,11]],"ltp":2.6,"tv":677.5,"id":7412809}],"tv":7388.61}]}
{"op":"mcm","clk":"1008825726","pt":1580639994390,"mc":[{"id":"1.168217554","rc":[{"trd":[[1.62,962.33]],"batb":[[0,1.6,301.56],[1,1.59,469.45],[2,1.58,443.1]],"batl":[[0,1.62,41.33],[1,1.63,86.02],[2,1.64,87.11]],"ltp":1.62,"tv":6736.31,"id":2263624},{"trd":[[2.6,180.69]],"batb":[[0,2.62,25.56],[1,2.6,427.36],[2,2.58,97.65]],"batl":[[0,2.66,11.05],[1,2.68,11.05],[2,2.7,11]],"ltp":2.6,"tv":702.31,"id":7412809}],"tv":7438.62}]}
{"op":"mcm","clk":"1008825929","pt":1580639996321,"mc":[{"id":"1.168217554","rc":[{"batl":[[0,1.62,48.9]],"ltp":1.62,"tv":6736.31,"id":2263624}]}]}
{"op":"mcm","clk":"1008825948","pt":1580639996527,"mc":[{"id":"1.168217554","rc":[{"batl":[[0,1.62,94.9]],"ltp":1.62,"tv":6736.31,"id":2263624}]}]}
{"op":"mcm","clk":"1008826155","pt":1580639998513,"mc":[{"id":"1.168217554","rc":[{"batb":[[0,1.61,23.32],[1,1.6,301.56],[2,1.59,469.45]],"ltp":1.62,"tv":6736.31,"id":2263624},{"batb":[[0,2.6,61.74],[1,2.58,97.65],[2,2.56,40.08]],"ltp":2.6,"tv":702.31,"id":7412809}]}]}
{"op":"mcm","clk":"1008826255","pt":1580639999503,"mc":[{"id":"1.168217554","rc":[{"batl":[[0,1.62,7.57]],"ltp":1.62,"tv":6736.31,"id":2263624},{"batb":[[0,2.6,25.74],[1,2.58,94.59]],"batl":[[0,2.64,11],[1,2.66,11.05],[2,2.68,11.05]],"ltp":2.6,"tv":702.31,"id":7412809}]}]}
{"op":"mcm","clk":"1008829539","pt":1580640031450,"mc":[{"id":"1.168217554","rc":[{"trd":[[1.61,2135.04]],"batb":[[0,1.6,301.56],[1,1.59,469.45],[2,1.58,443.1]],"batl":[[0,1.61,19.39],[1,1.62,7.57],[2,1.63,86.02]],"ltp":1.61,"tv":6782.95,"id":2263624}],"tv":7485.26}]}
{"op":"mcm","clk":"1008829654","pt":1580640032340,"mc":[{"id":"1.168217554","rc":[{"trd":[[1.61,2180.82]],"batb":[[0,1.6,301.67]],"batl":[[0,1.62,7.57],[1,1.63,86.02],[2,1.64,87.61]],"ltp":1.61,"tv":6828.73,"id":2263624},{"batb":[[0,2.6,62.74]],"batl":[[0,2.68,11.05],[1,2.7,11],[2,3.95,153.72]],"ltp":2.6,"tv":702.31,"id":7412809}],"tv":7531.04}]}
{"op":"mcm","clk":"1008829763","pt":1580640033297,"mc":[{"id":"1.168217554","rc":[{"trd":[[1.6,1720.8],[1.61,2181.04]],"batb":[[0,1.61,22.18],[1,1.6,175.15],[2,1.59,507.16]],"ltp":1.6,"tv":6962.71,"id":2263624},{"batb":[[0,2.6,79.28]],"ltp":2.6,"tv":702.31,"id":7412809}],"tv":7665.02}]}
{"op":"mcm","clk":"1008829875","pt":1580640034250,"mc":[{"id":"1.168217554","rc":[{"trd":[[1.6,2071.11],[1.61,2225.4]],"batb":[[0,1.59,507.16],[1,1.58,443.1],[2,1.57,441.1]],"batl":[[0,1.6,85.78],[1,1.61,46.18],[2,1.62,58.21]],"ltp":1.6,"tv":7357.38,"id":2263624},{"batb":[[0,2.64,36.18],[1,2.62,64.83],[2,2.6,82.07]],"batl":[[0,2.7,11],[1,2.72,9.18]],"ltp":2.6,"tv":702.31,"id":7412809}],"tv":8059.69}]}
{"op":"mcm","clk":"1008830313","pt":1580640038485,"mc":[{"id":"1.168217554","rc":[{"batl":[[0,1.61,89.15],[1,1.62,53.75],[2,1.63,91.06]],"ltp":1.6,"tv":7357.38,"id":2263624},{"batb":[[0,2.64,124.74]],"ltp":2.6,"tv":702.31,"id":7412809}]}]}
{"op":"mcm","clk":"1008830333","pt":1580640038702,"mc":[{"id":"1.168217554","rc":[{"batl":[[0,1.61,42.97]],"ltp":1.6,"tv":7357.38,"id":2263624},{"batb":[[0,2.64,88.56],[1,2.62,62.21]],"batl":[[0,2.68,10.21],[1,2.7,11],[2,2.72,9.18]],"ltp":2.6,"tv":702.31,"id":7412809}]}]}
{"op":"mcm","clk":"1008848847","pt":1580640188257,"mc":[{"id":"1.168217554","rc":[{"batl":[[1,1.62,46.18]],"ltp":1.6,"tv":7357.38,"id":2263624}]}]}
{"op":"mcm","clk":"1008857315","pt":1580640249515,"mc":[{"id":"1.168217554","rc":[{"trd":[[1.61,2230.44]],"batl":[[0,1.61,40.45]],"ltp":1.61,"tv":7362.42,"id":2263624}],"tv":8064.73}]}
{"op":"mcm","clk":"1008886043","pt":1580640468146,"mc":[{"id":"1.168217554","rc":[{"batl":[[0,2.68,27.01]],"ltp":2.6,"tv":702.31,"id":7412809}]}]}
{"op":"mcm","clk":"1008902755","pt":1580640607361,"mc":[{"id":"1.168217554","rc":[{"trd":[[1.59,1336.46]],"batb":[[0,1.59,258.45],[1,1.58,517.37],[2,1.57,449.1]],"ltp":1.59,"tv":7842.42,"id":2263624},{"batb":[[1,2.62,96.67]],"batl":[[2,2.72,13]],"ltp":2.6,"tv":702.31,"id":7412809}],"tv":8544.73}]}
{"op":"mcm","clk":"1008912563","pt":1580640689506,"mc":[{"id":"1.168217554","rc":[{"trd":[[2.64,233.43]],"batb":[[0,2.64,50.68]],"ltp":2.64,"tv":778.07,"id":7412809}],"tv":8620.49}]}
{"op":"mcm","clk":"1008917669","pt":1580640733223,"mc":[{"id":"1.168217554","rc":[{"batl":[[0,1.61,82.46]],"ltp":1.59,"tv":7842.42,"id":2263624}]}]}
{"op":"mcm","clk":"1008921829","pt":1580640769468,"mc":[{"id":"1.168217554","rc":[{"batl":[[0,1.6,2],[1,1.61,141.46],[2,1.62,52.14]],"ltp":1.59,"tv":7842.42,"id":2263624},{"batb":[[0,2.64,96.68]],"batl":[[0,2.68,16.8]],"ltp":2.64,"tv":778.07,"id":7412809}]}]}
{"op":"mcm","clk":"1008963527","pt":1580641131484,"mc":[{"id":"1.168217554","rc":[{"batl":[[0,1.6,103.3]],"ltp":1.59,"tv":7842.42,"id":2263624},{"batb":[[1,2.62,99.79],[2,2.6,82.12]],"ltp":2.64,"tv":778.07,"id":7412809}]}]}
{"op":"mcm","clk":"1008965760","pt":1580641149327,"mc":[{"id":"1.168217554","rc":[{"batb":[[2,2.6,82.22]],"ltp":2.64,"tv":778.07,"id":7412809}]}]}
{"op":"mcm","clk":"1008973737","pt":1580641206443,"mc":[{"id":"1.168217554","rc":[{"batb":[[2,2.6,81.82]],"ltp":2.64,"tv":778.07,"id":7412809}]}]}
{"op":"mcm","clk":"1008975123","pt":1580641214774,"mc":[{"id":"1.168217554","rc":[{"batb":[[2,2.6,82.32]],"ltp":2.64,"tv":778.07,"id":7412809}]}]}
{"op":"mcm","clk":"1008980331","pt":1580641247431,"mc":[{"id":"1.168217554","rc":[{"batb":[[2,2.6,79.28]],"ltp":2.64,"tv":778.07,"id":7412809}]}]}
{"op":"mcm","clk":"1008980369","pt":1580641247615,"mc":[{"id":"1.168217554","rc":[{"batb":[[2,2.6,81.92]],"ltp":2.64,"tv":778.07,"id":7412809}]}]}
{"op":"mcm","clk":"1008982890","pt":1580641262366,"mc":[{"id":"1.168217554","rc":[{"trd":[[1.59,1437.82]],"batb":[[0,1.59,207.74]],"ltp":1.59,"tv":7943.78,"id":2263624}],"tv":8721.85}]}
{"op":"mcm","clk":"1008982984","pt":1580641262863,"mc":[{"id":"1.168217554","rc":[{"batb":[[2,2.6,82.07]],"ltp":2.64,"tv":778.07,"id":7412809}]}]}
{"op":"mcm","clk":"1008985194","pt":1580641279505,"mc":[{"id":"1.168217554","rc":[{"batb":[[2,2.6,79.28]],"ltp":2.64,"tv":778.07,"id":7412809}]}]}
{"op":"mcm","clk":"1008985219","pt":1580641279675,"mc":[{"id":"1.168217554","rc":[{"batb":[[2,2.6,81.97]],"ltp":2.64,"tv":778.07,"id":7412809}]}]}
{"op":"mcm","clk":"1008994997","pt":1580641349951,"mc":[{"id":"1.168217554","rc":[{"trd":[[1.6,2088.17]],"batl":[[0,1.6,94.77]],"ltp":1.6,"tv":7960.84,"id":2263624},{"batb":[[2,2.6,82.12]],"ltp":2.64,"tv":778.07,"id":7412809}],"tv":8738.91}]}
{"op":"mcm","clk":"1009028846","pt":1580641576493,"mc":[{"id":"1.168217554","rc":[{"trd":[[1.59,1449.98]],"batb":[[0,1.59,201.66]],"ltp":1.59,"tv":7973.01,"id":2263624},{"batb":[[2,2.6,79.28]],"ltp":2.64,"tv":778.07,"id":7412809}],"tv":8751.08}]}
{"op":"mcm","clk":"1009028877","pt":1580641576704,"mc":[{"id":"1.168217554","rc":[{"batb":[[2,2.6,82.37]],"ltp":2.64,"tv":778.07,"id":7412809}]}]}
{"op":"mcm","clk":"1009033963","pt":1580641605793,"mc":[{"id":"1.168217554","marketDefinition":{"bspMarket":false,"turnInPlayEnabled":true,"persistenceEnabled":true,"marketBaseRate":5.0,"eventId":"29681263","eventTypeId":"2","numberOfWinners":1,"bettingType":"ODDS","marketType":"MATCH_ODDS","marketTime":"2020-02-02T11:09:00.000Z","suspendTime":"2020-02-02T11:09:00.000Z","bspReconciled":false,"complete":true,"inPlay":false,"crossMatching":true,"runnersVoidable":false,"numberOfActiveRunners":2,"betDelay":0,"status":"OPEN","runners":[{"status":"ACTIVE","sortPriority":1,"id":7412809,"name":"Evgeny Karlovskiy"},{"status":"ACTIVE","sortPriority":2,"id":2263624,"name":"Viktor Troicki"}],"regulators":["MR_INT"],"countryCode":"IN","discountAllowed":true,"timezone":"UTC","openDate":"2020-02-02T11:21:00.000Z","version":3148499123,"name":"Match Odds","eventName":"Karlovskiy v Troicki"}}]}
{"op":"mcm","clk":"1009034829","pt":1580641610805,"mc":[{"id":"1.168217554","marketDefinition":{"bspMarket":false,"turnInPlayEnabled":true,"persistenceEnabled":true,"marketBaseRate":5.0,"eventId":"29681263","eventTypeId":"2","numberOfWinners":1,"bettingType":"ODDS","marketType":"MATCH_ODDS","marketTime":"2020-02-02T11:09:00.000Z","suspendTime":"2020-02-02T11:09:00.000Z","bspReconciled":false,"complete":true,"inPlay":false,"crossMatching":true,"runnersVoidable":false,"numberOfActiveRunners":2,"betDelay":0,"status":"OPEN","runners":[{"status":"ACTIVE","sortPriority":1,"id":7412809,"name":"Evgeny Karlovskiy"},{"status":"ACTIVE","sortPriority":2,"id":2263624,"name":"Viktor Troicki"}],"regulators":["MR_INT"],"countryCode":"IN","discountAllowed":true,"timezone":"UTC","openDate":"2020-02-02T11:09:00.000Z","version":3148499123,"name":"Match Odds","eventName":"Karlovskiy v Troicki"}}]}
{"op":"mcm","clk":"1009037094","pt":1580641624862,"mc":[{"id":"1.168217554","rc":[{"batb":[[2,2.6,82.17]],"batl":[[2,2.72,15.05]],"ltp":2.64,"tv":778.07,"id":7412809}]}]}
{"op":"mcm","clk":"1009042996","pt":1580641662511,"mc":[{"id":"1.168217554","rc":[{"trd":[[2.68,75.92]],"batb":[[0,2.64,117.69],[2,2.6,79.28]],"batl":[[0,2.7,11],[1,2.72,13],[2,2.74,15.25]],"ltp":2.68,"tv":811.67,"id":7412809}],"tv":8784.68}]}
{"op":"mcm","clk":"1009043027","pt":1580641662721,"mc":[{"id":"1.168217554","rc":[{"batb":[[2,2.6,82.07]],"ltp":2.68,"tv":811.67,"id":7412809}]}]}
{"op":"mcm","clk":"1009044076","pt":1580641669490,"mc":[{"id":"1.168217554","rc":[{"trd":[[1.59,1905.3]],"batb":[[0,1.58,517.37],[1,1.57,449.1],[2,1.56,29]],"batl":[[0,1.59,72.23],[1,1.6,94.77],[2,1.61,146.96]],"ltp":1.59,"tv":8428.33,"id":2263624},{"batb":[[0,2.64,120.51],[2,2.6,81.87]],"ltp":2.68,"tv":811.67,"id":7412809}],"tv":9240.0}]}
{"op":"mcm","clk":"1009044250","pt":1580641670502,"mc":[{"id":"1.168217554","rc":[{"batl":[[1,1.6,150.77]],"ltp":1.59,"tv":8428.33,"id":2263624},{"batb":[[0,2.66,43],[1,2.64,120.51],[2,2.62,99.71]],"batl":[[0,2.78,2.02],[1,2.8,2.02],[2,2.82,2.25]],"ltp":2.68,"tv":811.67,"id":7412809}]}]}
{"op":"mcm","clk":"1009046236","pt":1580641683413,"mc":[{"id":"1.168217554","rc":[{"batb":[[0,1.58,443.1],[2,1.56,104.61]],"ltp":1.59,"tv":8428.33,"id":2263624},{"batb":[[0,2.68,32.25],[1,2.66,43],[2,2.64,120.51]],"ltp":2.68,"tv":811.67,"id":7412809}]}]}
{"op":"mcm","clk":"1009046321","pt":1580641683947,"mc":[{"id":"1.168217554","rc":[{"batb":[[0,2.68,75.25]],"batl":[[2,3.95,153.72]],"ltp":2.68,"tv":811.67,"id":7412809}]}]}
{"op":"mcm","clk":"1009049335","pt":1580641704430,"mc":[{"id":"1.168217554","rc":[{"batl":[[1,1.6,224.98]],"ltp":1.59,"tv":8428.33,"id":2263624}]}]}
{"op":"mcm","clk":"1009053170","pt":1580641730498,"mc":[{"id":"1.168217554","rc":[{"batb":[[0,1.58,445.1]],"ltp":1.59,"tv":8428.33,"id":2263624}]}]}
{"op":"mcm","clk":"1009058427","pt":1580641763010,"mc":[{"id":"1.168217554","rc":[{"batb":[[0,1.58,570.2]],"ltp":1.59,"tv":8428.33,"id":2263624}]}]}
{"op":"mcm","clk":"1009059739","pt":1580641771242,"mc":[{"id":"1.168217554","rc":[{"batb":[[0,1.58,569.49]],"ltp":1.59,"tv":8428.33,"id":2263624}]}]}
{"op":"mcm","clk":"1009064113","pt":1580641801397,"mc":[{"id":"1.168217554","rc":[{"batb":[[0,1.58,445.1],[1,1.57,575.7]],"ltp":1.59,"tv":8428.33,"id":2263624}]}]}
{"op":"mcm","clk":"1009064177","pt":1580641801786,"mc":[{"id":"1.168217554","rc":[{"batl":[[2,1.61,141.46]],"ltp":1.59,"tv":8428.33,"id":2263624},{"batb":[[2,2.64,117.69]],"batl":[[0,3.95,153.72],[1,95,15.9],[2,990,2.2]],"ltp":2.68,"tv":811.67,"id":7412809}]}]}
{"op":"mcm","clk":"1009066605","pt":1580641817977,"mc":[{"id":"1.168217554","rc":[{"batb":[[2,1.56,29]],"ltp":1.59,"tv":8428.33,"id":2263624}]}]}
{"op":"mcm","clk":"1009069014","pt":1580641836220,"mc":[{"id":"1.168217554","rc":[{"batb":[[2,1.56,449.1]],"ltp":1.59,"tv":8428.33,"id":2263624}]}]}
{"op":"mcm","clk":"1009076660","pt":1580641888936,"mc":[{"id":"1.168217554","rc":[{"trd":[[1.58,204.26]],"batb":[[0,1.58,391.75]],"ltp":1.58,"tv":8535.01,"id":2263624}],"tv":9346.68}]}
{"op":"mcm","clk":"1009077456","pt":1580641893918,"mc":[{"id":"1.168217554","rc":[{"trd":[[1.58,204.6]],"batb":[[0,1.58,391.59]],"ltp":1.58,"tv":8535.35,"id":2263624}],"tv":9347.02}]}
{"op":"mcm","clk":"1009079667","pt":1580641907335,"mc":[{"id":"1.168217554","marketDefinition":{"bspMarket":false,"turnInPlayEnabled":true,"persistenceEnabled":true,"marketBaseRate":5.0,"eventId":"29681263","eventTypeId":"2","numberOfWinners":1,"bettingType":"ODDS","marketType":"MATCH_ODDS","marketTime":"2020-02-02T11:07:00.000Z","suspendTime":"2020-02-02T11:07:00.000Z","bspReconciled":false,"complete":true,"inPlay":false,"crossMatching":true,"runnersVoidable":false,"numberOfActiveRunners":2,"betDelay":0,"status":"OPEN","runners":[{"status":"ACTIVE","sortPriority":1,"id":7412809,"name":"Evgeny Karlovskiy"},{"status":"ACTIVE","sortPriority":2,"id":2263624,"name":"Viktor Troicki"}],"regulators":["MR_INT"],"countryCode":"IN","discountAllowed":true,"timezone":"UTC","openDate":"2020-02-02T11:09:00.000Z","version":3148508168,"name":"Match Odds","eventName":"Karlovskiy v Troicki"}}]}
{"op":"mcm","clk":"1009080067","pt":1580641909607,"mc":[{"id":"1.168217554","marketDefinition":{"bspMarket":false,"turnInPlayEnabled":true,"persistenceEnabled":true,"marketBaseRate":5.0,"eventId":"29681263","eventTypeId":"2","numberOfWinners":1,"bettingType":"ODDS","marketType":"MATCH_ODDS","marketTime":"2020-02-02T11:07:00.000Z","suspendTime":"2020-02-02T11:07:00.000Z","bspReconciled":false,"complete":true,"inPlay":false,"crossMatching":true,"runnersVoidable":false,"numberOfActiveRunners":2,"betDelay":0,"status":"OPEN","runners":[{"status":"ACTIVE","sortPriority":1,"id":7412809,"name":"Evgeny Karlovskiy"},{"status":"ACTIVE","sortPriority":2,"id":2263624,"name":"Viktor Troicki"}],"regulators":["MR_INT"],"countryCode":"IN","discountAllowed":true,"timezone":"UTC","openDate":"2020-02-02T11:07:00.000Z","version":3148508168,"name":"Match Odds","eventName":"Karlovskiy v Troicki"}}]}
{"op":"mcm","clk":"1009080681","pt":1580641913014,"mc":[{"id":"1.168217554","rc":[{"trd":[[1.58,204.63]],"batb":[[0,1.58,391.57]],"ltp":1.58,"tv":8535.38,"id":2263624}],"tv":9347.05}]}
{"op":"mcm","clk":"1009081948","pt":1580641920232,"mc":[{"id":"1.168217554","rc":[{"trd":[[1.59,2049.76]],"batb":[[0,1.59,11.79],[1,1.58,391.57],[2,1.57,575.7]],"batl":[[0,1.6,224.98],[1,1.61,141.46],[2,1.62,46.18]],"ltp":1.59,"tv":8679.84,"id":2263624}],"tv":9491.52}]}
{"op":"mcm","clk":"1009082053","pt":1580641920870,"mc":[{"id":"1.168217554","rc":[{"batl":[[0,1.6,168.98]],"ltp":1.59,"tv":8679.84,"id":2263624},{"batb":[[0,2.68,32.25]],"ltp":2.68,"tv":811.67,"id":7412809}]}]}
{"op":"mcm","clk":"1009087604","pt":1580641957506,"mc":[{"id":"1.168217554","rc":[{"trd":[[1.59,2073.34]],"batb":[[0,1.59,25.2],[2,1.57,625.01]],"ltp":1.59,"tv":8703.42,"id":2263624},{"batb":[[0,2.66,40.51],[1,2.64,117.69],[2,2.62,62.21]],"ltp":2.68,"tv":811.67,"id":7412809}],"tv":9515.09}]}
{"op":"mcm","clk":"1009090194","pt":1580641973494,"mc":[{"id":"1.168217554","rc":[{"batb":[[1,1.58,391.58]],"ltp":1.59,"tv":8703.42,"id":2263624}]}]}
{"op":"mcm","clk":"1009102038","pt":1580642049085,"mc":[{"id":"1.168217554","rc":[{"batl":[[0,2.88,21.85],[1,3.95,153.72],[2,95,15.9]],"ltp":2.68,"tv":811.67,"id":7412809}]}]}
{"op":"mcm","clk":"1009107718","pt":1580642084346,"mc":[{"id":"1.168217554","rc":[{"batl":[[0,1.6,94.77]],"ltp":1.59,"tv":8703.42,"id":2263624}]}]}
{"op":"mcm","clk":"1009108495","pt":1580642089347,"mc":[{"id":"1.168217554","rc":[{"trd":[[1.59,2121.46]],"batb":[[0,1.59,1.14],[1,1.58,415.82]],"ltp":1.59,"tv":8751.54,"id":2263624},{"batb":[[0,2.64,159.43],[1,2.62,62.21],[2,2.6,37]],"ltp":2.68,"tv":811.67,"id":7412809}],"tv":9563.21}]}
{"op":"mcm","clk":"1009112398","pt":1580642112649,"mc":[{"id":"1.168217554","rc":[{"batl":[[0,1.6,220.8]],"ltp":1.59,"tv":8751.54,"id":2263624}]}]}
{"op":"mcm","clk":"1009117480","pt":1580642142032,"mc":[{"id":"1.168217554","rc":[{"trd":[[1.59,2168.21]],"batb":[[0,1.58,415.82],[1,1.57,625.01],[2,1.56,449.1]],"batl":[[0,1.59,102.66],[1,1.6,94.77],[2,1.61,141.46]],"ltp":1.59,"tv":8798.28,"id":2263624}],"tv":9609.96}]}
{"op":"mcm","clk":"1009120379","pt":1580642158223,"mc":[{"id":"1.168217554","rc":[{"trd":[[1.59,2168.89]],"batl":[[0,1.59,101.97],[1,1.6,147.77]],"ltp":1.59,"tv":8798.96,"id":2263624},{"trd":[[2.68,76.33]],"batb":[[0,2.66,40],[1,2.64,159.43],[2,2.62,62.21]],"ltp":2.68,"tv":812.07,"id":7412809}],"tv":9611.04}]}
{"op":"mcm","clk":"1009124489","pt":1580642183378,"mc":[{"id":"1.168217554","rc":[{"batb":[[1,1.57,624.61]],"ltp":1.59,"tv":8798.96,"id":2263624}]}]}
{"op":"mcm","clk":"1009128669","pt":1580642210393,"mc":[{"id":"1.168217554","rc":[{"trd":[[1.58,204.65]],"batb":[[0,1.58,415.82]],"ltp":1.58,"tv":8798.98,"id":2263624}],"tv":9611.06}]}
{"op":"mcm","clk":"1009130612","pt":1580642223545,"mc":[{"id":"1.168217554","rc":[{"trd":[[1.58,205.66]],"batb":[[0,1.58,415.31]],"ltp":1.58,"tv":8799.99,"id":2263624}],"tv":9612.07}]}
{"op":"mcm","clk":"1009142257","pt":1580642298506,"mc":[{"id":"1.168217554","marketDefinition":{"bspMarket":false,"turnInPlayEnabled":true,"persistenceEnabled":true,"marketBaseRate":5.0,"eventId":"29681263","eventTypeId":"2","numberOfWinners":1,"bettingType":"ODDS","marketType":"MATCH_ODDS","marketTime":"2020-02-02T11:07:00.000Z","suspendTime":"2020-02-02T11:07:00.000Z","bspReconciled":false,"complete":true,"inPlay":true,"crossMatching":true,"runnersVoidable":false,"numberOfActiveRunners":2,"betDelay":3,"status":"OPEN","runners":[{"status":"ACTIVE","sortPriority":1,"id":7412809,"name":"Evgeny Karlovskiy"},{"status":"ACTIVE","sortPriority":2,"id":2263624,"name":"Viktor Troicki"}],"regulators":["MR_INT"],"countryCode":"IN","discountAllowed":true,"timezone":"UTC","openDate":"2020-02-02T11:07:00.000Z","version":3148519483,"name":"Match Odds","eventName":"Karlovskiy v Troicki"},"rc":[{"batb":[[1,1.57,498.41]],"ltp":1.58,"tv":8799.99,"id":2263624}]}]}
{"op":"mcm","clk":"1009142281","pt":1580642298583,"mc":[{"id":"1.168217554","rc":[{"batb":[[0,1.58,2.02],[1,1.11,37.96],[2,1.05,152.3]],"batl":[[1,1.6,94.77],[2,1.66,4.89]],"ltp":1.58,"tv":8799.99,"id":2263624},{"batb":[[0,2.08,21.65],[1,1.11,37.97],[2,1.03,9]],"batl":[[0,1000,0.02],[1,3.95,0],[2,95,0]],"ltp":2.68,"tv":812.07,"id":7412809}]}]}
{"op":"mcm","clk":"1009142778","pt":1580642301810,"mc":[{"id":"1.168217554","rc":[{"batb":[[0,1.58,22.02],[1,1.57,20],[2,1.56,20]],"batl":[[0,1.59,122.22],[1,1.6,144.77],[2,1.61,50]],"ltp":1.58,"tv":8799.99,"id":2263624},{"batb":[[0,2.66,38],[1,2.08,21.65],[2,1.8,75.72]],"ltp":2.68,"tv":812.07,"id":7412809}]}]}
{"op":"mcm","clk":"1009143147","pt":1580642304425,"mc":[{"id":"1.168217554","rc":[{"trd":[[1.59,2291.11],[1.6,2232.94]],"batb":[[0,1.59,101.72],[1,1.58,2.02],[2,1.11,37.96]],"batl":[[0,1.66,4.89],[1,1.68,635],[2,1.8,10.36]],"ltp":1.6,"tv":9066.99,"id":2263624},{"trd":[[2.66,198.11],[2.68,148.84]],"batb":[[0,2.08,21.65],[1,1.8,75.72],[2,1.11,37.97]],"batl":[[0,2.7,376],[1,1000,0.02]],"ltp":2.66,"tv":1047.72,"id":7412809}],"tv":10114.72}]}
{"op":"mcm","clk":"1009143285","pt":1580642305432,"mc":[{"id":"1.168217554","rc":[{"batb":[[0,1.63,111.1],[2,1.56,131.71]],"ltp":1.6,"tv":9066.99,"id":2263624},{"batb":[[0,2.4,67.19],[1,2.32,73.25],[2,2.08,21.65]],"ltp":2.66,"tv":1047.72,"id":7412809}]}]}
{"op":"mcm","clk":"1009143550","pt":1580642307246,"mc":[{"id":"1.168217554","rc":[{"batb":[[1,1.58,74.27]],"batl":[[2,1.71,42.01]],"ltp":1.6,"tv":9066.99,"id":2263624},{"batb":[[0,2.4,96.6]],"batl":[[1,2.74,23.53],[2,1000,0.02]],"ltp":2.66,"tv":1047.72,"id":7412809}]}]}
{"op":"mcm","clk":"1009144081","pt":1580642311338,"mc":[{"id":"1.168217554","rc":[{"batb":[[1,1.6,494.03],[2,1.58,585.11]],"batl":[[1,1.7,480.59]],"ltp":1.6,"tv":9066.99,"id":2263624},{"batl":[[0,2.74,23.53],[1,1000,0.02],[2,1000,0]],"ltp":2.66,"tv":1047.72,"id":7412809}]}]}
{"op":"mcm","clk":"1009144262","pt":1580642312448,"mc":[{"id":"1.168217554","rc":[{"batb":[[0,1.6,494.03],[1,1.58,585.11],[2,1.56,131.71]],"ltp":1.6,"tv":9066.99,"id":2263624},{"batb":[[0,2.4,29.41]],"ltp":2.66,"tv":1047.72,"id":7412809}]}]}
{"op":"mcm","clk":"1009144277","pt":1580642312552,"mc":[{"id":"1.168217554","rc":[{"batb":[[1,1.58,512.85]],"batl":[[2,1.72,497.62]],"ltp":1.6,"tv":9066.99,"id":2263624},{"batb":[[0,2.32,73.25],[1,2.08,21.65],[2,1.8,75.72]],"batl":[[0,1000,0.02],[1,1000,0]],"ltp":2.66,"tv":1047.72,"id":7412809}]}]}
{"op":"mcm","clk":"1009144677","pt":1580642315364,"mc":[{"id":"1.168217554","rc":[{"batb":[[2,1.57,277.59]],"ltp":1.6,"tv":9066.99,"id":2263624}]}]}
{"op":"mcm","clk":"1009144872","pt":1580642316335,"mc":[{"id":"1.168217554","rc":[{"trd":[[1.66,3.42]],"batl":[[0,1.66,1.47]],"ltp":1.66,"tv":9070.41,"id":2263624},{"trd":[[2.5,2.27]],"ltp":2.5,"tv":1050.0,"id":7412809}],"tv":10120.41}]}
{"op":"mcm","clk":"1009145330","pt":1580642318948,"mc":[{"id":"1.168217554","rc":[{"trd":[[1.6,2234.52]],"batb":[[0,1.6,493.24]],"ltp":1.6,"tv":9071.99,"id":2263624}],"tv":10121.99}]}
{"op":"mcm","clk":"1009146102","pt":1580642324184,"mc":[{"id":"1.168217554","rc":[{"batb":[[2,1.56,131.71]],"batl":[[1,1.73,290.44],[2,1.75,296.08]],"ltp":1.6,"tv":9071.99,"id":2263624}]}]}
{"op":"mcm","clk":"1009146460","pt":1580642326468,"mc":[{"id":"1.168217554","rc":[{"batl":[[1,1.73,906.44]],"ltp":1.6,"tv":9071.99,"id":2263624},{"batl":[[0,2.54,2168.64],[1,2.58,379],[2,1000,0.02]],"ltp":2.5,"tv":1050.0,"id":7412809}]}]}
{"op":"mcm","clk":"1009146638","pt":1580642327483,"mc":[{"id":"1.168217554","rc":[{"trd":[[1.66,6.36]],"batb":[[0,1.68,7.68],[1,1.67,299.15],[2,1.66,176.93]],"batl":[[0,1.73,906.44],[1,1.75,296.08],[2,1.76,42.01]],"ltp":1.66,"tv":9074.93,"id":2263624},{"batb":[[0,2.42,5.72],[1,2.36,399.84],[2,2.32,73.25]],"batl":[[0,2.56,544.08],[2,2.62,25.21]],"ltp":2.5,"tv":1050.0,"id":7412809}],"tv":10124.93}]}
{"op":"mcm","clk":"1009146678","pt":1580642327804,"mc":[{"id":"1.168217554","rc":[{"batb":[[1,1.67,401.99]],"ltp":1.66,"tv":9074.93,"id":2263624}]}]}
{"op":"mcm","clk":"1009147609","pt":1580642333203,"mc":[{"id":"1.168217554","rc":[{"batl":[[1,1.75,776.67]],"ltp":1.66,"tv":9074.93,"id":2263624}]}]}
{"op":"mcm","clk":"1009148162","pt":1580642336697,"mc":[{"id":"1.168217554","rc":[{"batb":[[0,1.67,401.99],[1,1.66,176.93],[2,1.65,494.03]],"ltp":1.66,"tv":9074.93,"id":2263624},{"batb":[[0,2.36,399.84],[1,2.32,73.25],[2,2.3,31.93]],"ltp":2.5,"tv":1050.0,"id":7412809}]}]}
{"op":"mcm","clk":"1009148642","pt":1580642339386,"mc":[{"id":"1.168217554","rc":[{"batl":[[0,1.73,907.19]],"ltp":1.66,"tv":9074.93,"id":2263624}]}]}
{"op":"mcm","clk":"1009148693","pt":1580642339698,"mc":[{"id":"1.168217554","rc":[{"batb":[[0,2.42,6.73],[1,2.36,399.84],[2,2.32,73.25]],"batl":[[0,2.5,11.8],[1,2.56,544.08],[2,2.58,379]],"ltp":2.5,"tv":1050.0,"id":7412809}]}]}
{"op":"mcm","clk":"1009149871","pt":1580642346504,"mc":[{"id":"1.168217554","rc":[{"batb":[[0,1.65,494.03],[1,1.63,510.84],[2,1.61,116.53]],"batl":[[0,1.75,481.57],[1,1.77,497.4],[2,1.8,10.13]],"ltp":1.66,"tv":9074.93,"id":2263624},{"batb":[[0,2.26,79.63],[1,2.08,21.65],[2,1.7,75.72]],"batl":[[0,1000,0.02],[1,2.56,0],[2,2.58,0]],"ltp":2.5,"tv":1050.0,"id":7412809}]}]}
{"op":"mcm","clk":"1009150338","pt":1580642349222,"mc":[{"id":"1.168217554","rc":[{"batb":[[2,1.62,329.81]],"batl":[[1,1.76,237.63],[2,1.77,497.4]],"ltp":1.66,"tv":9074.93,"id":2263624}]}]}
{"op":"mcm","clk":"1009150763","pt":1580642352222,"mc":[{"id":"1.168217554","rc":[{"batb":[[2,1.61,116.53]],"batl":[[0,1.8,10.36],[1,3,42.01],[2,7,2.27]],"ltp":1.66,"tv":9074.93,"id":2263624}]}]}
{"op":"mcm","clk":"1009151246","pt":1580642355421,"mc":[{"id":"1.168217554","rc":[{"batb":[[0,1.7,303.39],[1,1.68,337.14],[2,1.65,494.03]],"batl":[[0,1.76,237.86],[1,1.77,576],[2,1.78,867.89]],"ltp":1.66,"tv":9074.93,"id":2263624},{"batb":[[0,2.32,13.04],[1,2.26,79.63],[2,2.08,21.65]],"batl":[[0,2.4,7.82],[1,2.46,476.25],[2,2.5,428]],"ltp":2.5,"tv":1050.0,"id":7412809}]}]}
{"op":"mcm","clk":"1009151324","pt":1580642356002,"mc":[{"id":"1.168217554","rc":[{"batb":[[0,1.7,398.83],[2,1.66,167.82]],"ltp":1.66,"tv":9074.93,"id":2263624},{"batb":[[2,2.24,33.61]],"ltp":2.5,"tv":1050.0,"id":7412809}]}]}
{"op":"mcm","clk":"1009152098","pt":1580642361443,"mc":[{"id":"1.168217554","rc":[{"batb":[[2,1.67,494.03]],"ltp":1.66,"tv":9074.93,"id":2263624}]}]}
{"op":"mcm","clk":"1009152789","pt":1580642366345,"mc":[{"id":"1.168217554","rc":[{"trd":[[1.71,0.74]],"ltp":1.71,"tv":9075.66,"id":2263624},{"trd":[[2.4,0.53]],"batl":[[0,2.4,7.29]],"ltp":2.4,"tv":1050.53,"id":7412809}],"tv":10126.2}]}
{"op":"mcm","clk":"1009152926","pt":1580642367453,"mc":[{"id":"1.168217554","rc":[{"batb":[[0,1.67,494.03],[1,1.66,167.82],[2,1.65,510.84]],"batl":[[0,1.78,202.54],[1,1.8,532.73],[2,1.82,497.4]],"ltp":1.71,"tv":9075.66,"id":2263624},{"batb":[[0,2.24,33.61],[1,2.2,85.13],[2,2.08,21.65]],"batl":[[0,2.54,26.89],[1,1000,0.02],[2,2.5,0]],"ltp":2.4,"tv":1050.53,"id":7412809}]}]}
{"op":"mcm","clk":"1009153233","pt":1580642369250,"mc":[{"id":"1.168217554","rc":[{"batb":[[1,1.66,104.8]],"batl":[[0,1.8,490.95],[1,1.82,497.4],[2,3,42.01]],"ltp":1.71,"tv":9075.66,"id":2263624},{"batb":[[0,2.2,85.13],[1,2.08,21.65],[2,1.7,75.72]],"batl":[[0,1000,0.02],[1,1000,0]],"ltp":2.4,"tv":1050.53,"id":7412809}]}]}
{"op":"mcm","clk":"1009153665","pt":1580642372238,"mc":[{"id":"1.168217554","rc":[{"batb":[[0,1.7,188.93],[1,1.68,336.59],[2,1.67,494.03]],"batl":[[0,1.75,203.46],[1,1.77,285.6],[2,1.8,490.72]],"ltp":1.71,"tv":9075.66,"id":2263624}]}]}
{"op":"mcm","clk":"1009154571","pt":1580642378437,"mc":[{"id":"1.168217554","rc":[{"batb":[[0,1.67,494.03],[1,1.66,104.8],[2,1.65,510.84]],"batl":[[0,1.8,490.95],[1,1.82,497.4],[2,3,42.01]],"ltp":1.71,"tv":9075.66,"id":2263624}]}]}
{"op":"mcm","clk":"1009154628","pt":1580642378750,"mc":[{"id":"1.168217554","rc":[{"trd":[[1.72,0.23],[1.8,445.66]],"batl":[[0,1.8,45.06]],"ltp":1.8,"tv":9521.55,"id":2263624},{"trd":[[2.24,358.15],[2.38,0.16]],"ltp":2.24,"tv":1408.84,"id":7412809}],"tv":10930.4}]}
{"op":"mcm","clk":"1009155011","pt":1580642381461,"mc":[{"id":"1.168217554","rc":[{"batb":[[0,1.67,234.83],[1,1.66,281.54],[2,1.58,368.07]],"ltp":1.8,"tv":9521.55,"id":2263624}]}]}
{"op":"mcm","clk":"1009155388","pt":1580642383973,"mc":[{"id":"1.168217554","rc":[{"batb":[[1,1.66,291.8]],"batl":[[0,1.71,565],[1,1.72,199.33],[2,1.74,302.18]],"ltp":1.8,"tv":9521.55,"id":2263624},{"batb":[[0,2.46,5.66],[1,2.32,967.33],[2,2.2,85.13]],"batl":[[0,2.56,306.46],[1,2.62,384],[2,1000,0.02]],"ltp":2.24,"tv":1408.84,"id":7412809}]}]}
{"op":"mcm","clk":"1009155590","pt":1580642385459,"mc":[{"id":"1.168217554","rc":[{"batb":[[2,1.62,67.22]],"ltp":1.8,"tv":9521.55,"id":2263624},{"batb":[[1,2.34,102.85],[2,2.32,967.33]],"batl":[[2,2.64,25.21]],"ltp":2.24,"tv":1408.84,"id":7412809}]}]}
{"op":"mcm","clk":"1009156194","pt":1580642390064,"mc":[{"id":"1.168217554","rc":[{"batb":[[2,1.64,494.03]],"batl":[[2,1.73,480.59]],"ltp":1.8,"tv":9521.55,"id":2263624}]}]}
{"op":"mcm","clk":"1009156440","pt":1580642392179,"mc":[{"id":"1.168217554","rc":[{"trd":[[1.69,8.24]],"batb":[[0,1.69,455.64],[1,1.67,234.83],[2,1.66,291.8]],"ltp":1.69,"tv":9529.8,"id":2263624},{"trd":[[2.46,5.66]],"batb":[[0,2.34,102.85],[1,2.32,967.33],[2,2.28,77.5]],"ltp":2.46,"tv":1414.5,"id":7412809}],"tv":10944.3}]}
{"op":"mcm","clk":"1009157709","pt":1580642401496,"mc":[{"id":"1.168217554","rc":[{"batb":[[2,1.66,281.54]],"batl":[[0,1.72,199.33],[1,1.73,480.59],[2,1.74,302.18]],"ltp":1.69,"tv":9529.8,"id":2263624},{"batb":[[1,2.28,77.5],[2,2.2,85.13]],"batl":[[0,2.64,25.21],[1,1000,0.02],[2,2.64,0]],"ltp":2.46,"tv":1414.5,"id":7412809}]}]}
{"op":"mcm","clk":"1009157860","pt":1580642402477,"mc":[{"id":"1.168217554","rc":[{"batb":[[1,1.64,494.03],[2,1.62,510.84]],"batl":[[0,1.73,480.59],[1,1.75,497.4],[2,3,42.01]],"ltp":1.69,"tv":9529.8,"id":2263624},{"batb":[[0,2.28,77.5],[1,2.08,21.65],[2,1.7,75.72]],"batl":[[0,1000,0.02],[1,1000,0]],"ltp":2.46,"tv":1414.5,"id":7412809}]}]}
{"op":"mcm","clk":"1009158287","pt":1580642404895,"mc":[{"id":"1.168217554","rc":[{"batb":[[2,1.62,811.6]],"batl":[[1,1.75,667.87],[2,1.77,285.73]],"ltp":1.69,"tv":9529.8,"id":2263624}]}]}
{"op":"mcm","clk":"1009160629","pt":1580642419293,"mc":[{"id":"1.168217554","rc":[{"trd":[[1.73,19.01]],"batl":[[0,1.73,461.59]],"ltp":1.73,"tv":9548.8,"id":2263624},{"trd":[[2.36,13.93]],"ltp":2.36,"tv":1428.44,"id":7412809}],"tv":10977.24}]}
{"op":"mcm","clk":"1009161011","pt":1580642421832,"mc":[{"id":"1.168217554","rc":[{"trd":[[1.69,196.86]],"batb":[[0,1.69,361.33]],"ltp":1.69,"tv":9737.41,"id":2263624}],"tv":11165.86}]}
{"op":"mcm","clk":"1009161557","pt":1580642425446,"mc":[{"id":"1.168217554","rc":[{"batb":[[2,1.62,510.84]],"batl":[[0,1.75,170.47],[1,1.77,285.73],[2,3,42.01]],"ltp":1.69,"tv":9737.41,"id":2263624}]}]}
{"op":"mcm","clk":"1009161970","pt":1580642428151,"mc":[{"id":"1.168217554","rc":[{"batb":[[0,1.7,223.02],[1,1.69,361.33],[2,1.68,336.76]],"batl":[[0,1.75,739.47]],"ltp":1.69,"tv":9737.41,"id":2263624},{"batb":[[0,2.36,5.96],[1,2.32,414.06],[2,2.28,77.5]],"batl":[[0,2.42,9.04],[1,2.5,560.4],[2,2.54,429]],"ltp":2.36,"tv":1428.44,"id":7412809}]}]}
{"op":"mcm","clk":"1009162151","pt":1580642429426,"mc":[{"id":"1.168217554","rc":[{"batb":[[1,1.69,459.14]],"ltp":1.69,"tv":9737.41,"id":2263624}]}]}
{"op":"mcm","clk":"1009162168","pt":1580642429531,"mc":[{"id":"1.168217554","rc":[{"batl":[[2,1.82,42.01]],"ltp":1.69,"tv":9737.41,"id":2263624},{"batl":[[1,2.5,588.13]],"ltp":2.36,"tv":1428.44,"id":7412809}]}]}
{"op":"mcm","clk":"1009162943","pt":1580642434737,"mc":[{"id":"1.168217554","rc":[{"batb":[[1,1.69,97.8]],"ltp":1.69,"tv":9737.41,"id":2263624}]}]}
{"op":"mcm","clk":"1009163111","pt":1580642435840,"mc":[{"id":"1.168217554","rc":[{"trd":[[1.7,0.32]],"batb":[[0,1.7,222.86]],"ltp":1.7,"tv":9737.73,"id":2263624}],"tv":11166.17}]}
{"op":"mcm","clk":"1009163389","pt":1580642437716,"mc":[{"id":"1.168217554","rc":[{"trd":[[1.74,8.08]],"batb":[[0,1.74,361.76],[1,1.7,222.86],[2,1.69,97.8]],"ltp":1.74,"tv":9745.81,"id":2263624},{"trd":[[2.36,19.89]],"batb":[[0,2.32,414.06],[1,2.28,77.5],[2,2.22,33.61]],"ltp":2.36,"tv":1434.4,"id":7412809}],"tv":11180.22}]}
{"op":"mcm","clk":"1009164120","pt":1580642442950,"mc":[{"id":"1.168217554","rc":[{"trd":[[1.74,41.59]],"batb":[[0,1.74,345.01]],"ltp":1.74,"tv":9779.32,"id":2263624}],"tv":11213.72}]}
{"op":"mcm","clk":"1009164378","pt":1580642444543,"mc":[{"id":"1.168217554","rc":[{"trd":[[1.74,42.75]],"batb":[[0,1.74,344.43]],"ltp":1.74,"tv":9780.48,"id":2263624}],"tv":11214.88}]}
{"op":"mcm","clk":"1009164738","pt":1580642446851,"mc":[{"id":"1.168217554","rc":[{"trd":[[1.74,76.25]],"batb":[[0,1.74,327.68]],"ltp":1.74,"tv":9813.98,"id":2263624}],"tv":11248.38}]}
{"op":"mcm","clk":"1009164900","pt":1580642447967,"mc":[{"id":"1.168217554","rc":[{"batl":[[0,2.5,588.13],[1,2.54,429],[2,1000,0.02]],"ltp":2.36,"tv":1434.4,"id":7412809}]}]}
{"op":"mcm","clk":"1009165090","pt":1580642449349,"mc":[{"id":"1.168217554","rc":[{"trd":[[1.74,79.61]],"batb":[[0,1.74,326]],"ltp":1.74,"tv":9817.34,"id":2263624}],"tv":11251.74}]}
{"op":"mcm","clk":"1009165331","pt":1580642450860,"mc":[{"id":"1.168217554","rc":[{"trd":[[1.74,113.11]],"batb":[[0,1.74,309.24],[1,1.72,10.16],[2,1.7,222.86]],"ltp":1.74,"tv":9850.85,"id":2263624},{"batb":[[0,2.32,424.71]],"ltp":2.36,"tv":1434.4,"id":7412809}],"tv":11285.25}]}
{"op":"mcm","clk":"1009165938","pt":1580642454885,"mc":[{"id":"1.168217554","rc":[{"trd":[[1.74,371.48]],"batb":[[0,1.74,180.06]],"ltp":1.74,"tv":10109.22,"id":2263624}],"tv":11543.62}]}
{"op":"mcm","clk":"1009167141","pt":1580642463139,"mc":[{"id":"1.168217554","rc":[{"trd":[[1.74,388.29]],"batb":[[0,1.74,171.66]],"ltp":1.74,"tv":10126.02,"id":2263624}],"tv":11560.42}]}
{"op":"mcm","clk":"1009167444","pt":1580642465251,"mc":[{"id":"1.168217554","rc":[{"batb":[[2,1.69,97.8]],"batl":[[0,1.75,569],[1,1.82,42.01],[2,3,42.01]],"ltp":1.74,"tv":10126.02,"id":2263624}]}]}
{"op":"mcm","clk":"1009167903","pt":1580642468201,"mc":[{"id":"1.168217554","rc":[{"batl":[[2,1.86,239.63]],"ltp":1.74,"tv":10126.02,"id":2263624}]}]}
{"op":"mcm","clk":"1009168656","pt":1580642473513,"mc":[{"id":"1.168217554","rc":[{"trd":[[1.74,421.79]],"batb":[[0,1.74,154.91]],"ltp":1.74,"tv":10159.52,"id":2263624}],"tv":11593.92}]}
{"op":"mcm","clk":"1009169215","pt":1580642477349,"mc":[{"id":"1.168217554","rc":[{"trd":[[1.74,455.3]],"batb":[[0,1.74,138.15],[1,1.69,97.8],[2,1.67,62.17]],"batl":[[0,1.82,42.01],[1,1.86,239.63],[2,1.88,235.58]],"ltp":1.74,"tv":10193.03,"id":2263624},{"batb":[[0,2.28,77.5],[1,2.22,33.61],[2,2.12,96.62]],"batl":[[0,2.5,27.73],[1,1000,0.02],[2,1000,0]],"ltp":2.36,"tv":1434.4,"id":7412809}],"tv":11627.43}]}
{"op":"mcm","clk":"1009169378","pt":1580642478509,"mc":[{"id":"1.168217554","rc":[{"batb":[[1,1.65,258.41],[2,1.64,292.99]],"batl":[[0,1.86,239.63],[1,1.88,235.58],[2,3,42.01]],"ltp":1.74,"tv":10193.03,"id":2263624},{"batb":[[0,2.12,96.62],[1,2.08,21.65],[2,1.7,75.72]],"batl":[[0,1000,0.02],[1,1000,0]],"ltp":2.36,"tv":1434.4,"id":7412809}]}]}
{"op":"mcm","clk":"1009169707","pt":1580642480992,"mc":[{"id":"1.168217554","rc":[{"batb":[[1,1.65,366.2],[2,1.64,184.64]],"ltp":1.74,"tv":10193.03,"id":2263624},{"batb":[[0,2.1,97.25]],"ltp":2.36,"tv":1434.4,"id":7412809}]}]}
{"op":"mcm","clk":"1009170048","pt":1580642483527,"mc":[{"id":"1.168217554","rc":[{"trd":[[1.74,497.29]],"batb":[[0,1.74,117.16]],"ltp":1.74,"tv":10235.02,"id":2263624}],"tv":11669.42}]}
{"op":"mcm","clk":"1009170365","pt":1580642486120,"mc":[{"id":"1.168217554","rc":[{"batl":[[0,3,42.01],[1,7,2.27],[2,10,2.53]],"ltp":1.74,"tv":10235.02,"id":2263624}]}]}
{"op":"mcm","clk":"1009170844","pt":1580642489502,"mc":[{"id":"1.168217554","rc":[{"trd":[[1.74,731.61]],"batb":[[0,1.65,366.2],[1,1.64,184.64],[2,1.63,66.38]],"batl":[[0,1.69,386.84],[1,1.7,220.2],[2,1.72,314.06]],"ltp":1.74,"tv":10469.34,"id":2263624},{"batb":[[0,2.32,1257.96],[1,2.1,97.25],[2,2.08,21.65]],"batl":[[0,2.5,6.49],[1,2.6,310.82],[2,2.62,25.21]],"ltp":2.36,"tv":1434.4,"id":7412809}],"tv":11903.74}]}
{"op":"mcm","clk":"1009170910","pt":1580642490026,"mc":[{"id":"1.168217554","rc":[{"trd":[[1.69,204.32]],"batl":[[0,1.69,383.11]],"ltp":1.69,"tv":10476.8,"id":2263624},{"batb":[[0,2.38,69.48],[1,2.32,1257.96],[2,2.22,83.8]],"ltp":2.36,"tv":1434.4,"id":7412809}],"tv":11911.2}]}
{"op":"mcm","clk":"1009171625","pt":1580642495648,"mc":[{"id":"1.168217554","rc":[{"batl":[[2,1.72,794.65]],"ltp":1.69,"tv":10476.8,"id":2263624}]}]}
{"op":"mcm","clk":"1009172072","pt":1580642499459,"mc":[{"id":"1.168217554","rc":[{"batl":[[1,2.54,3.88],[2,2.6,310.82]],"ltp":2.36,"tv":1434.4,"id":7412809}]}]}
{"op":"mcm","clk":"1009172204","pt":1580642500455,"mc":[{"id":"1.168217554","rc":[{"batb":[[0,1.65,258.41]],"batl":[[0,1.7,205.98],[1,1.72,794.65],[2,1.74,497.4]],"ltp":1.69,"tv":10476.8,"id":2263624},{"batb":[[0,2.32,31.09],[1,2.22,83.8],[2,2.18,2.37]],"batl":[[0,2.62,25.21],[1,1000,0.02],[2,2.6,0]],"ltp":2.36,"tv":1434.4,"id":7412809}]}]}
{"op":"mcm","clk":"1009172225","pt":1580642500558,"mc":[{"id":"1.168217554","rc":[{"batb":[[0,1.62,494.03],[1,1.61,116.76],[2,1.6,510.84]],"batl":[[0,1.72,480.59],[1,1.74,497.4],[2,1.76,24.77]],"ltp":1.69,"tv":10476.8,"id":2263624},{"batb":[[0,2.22,83.8],[1,2.18,2.37],[2,2.08,21.65]],"batl":[[0,1000,0.02],[1,1000,0]],"ltp":2.36,"tv":1434.4,"id":7412809}]}]}
{"op":"mcm","clk":"1009172640","pt":1580642503451,"mc":[{"id":"1.168217554","rc":[{"batb":[[0,1.65,24.13],[1,1.62,494.03],[2,1.61,452.59]],"ltp":1.69,"tv":10476.8,"id":2263624},{"batb":[[0,2.3,3.98],[1,2.26,4.21],[2,2.22,83.8]],"ltp":2.36,"tv":1434.4,"id":7412809}]}]}
{"op":"mcm","clk":"1009172723","pt":1580642504172,"mc":[{"id":"1.168217554","rc":[{"batb":[[1,1.61,452.59],[2,1.6,202.35]],"ltp":1.69,"tv":10476.8,"id":2263624},{"batl":[[0,2.54,3.88],[1,1000,0.02]],"ltp":2.36,"tv":1434.4,"id":7412809}]}]}
{"op":"mcm","clk":"1009173176","pt":1580642507437,"mc":[{"id":"1.168217554","rc":[{"batl":[[0,1.66,1531.88],[1,1.68,340.29],[2,1.72,480.59]],"ltp":1.69,"tv":10476.8,"id":2263624},{"batb":[[0,2.48,81.44],[1,2.46,63.42],[2,2.44,80.82]],"batl":[[1,2.6,6.12],[2,2.72,374.94]],"ltp":2.36,"tv":1434.4,"id":7412809}]}]}
{"op":"mcm","clk":"1009173187","pt":1580642507545,"mc":[{"id":"1.168217554","rc":[{"batl":[[2,2.72,399.31]],"ltp":2.36,"tv":1434.4,"id":7412809}]}]}
{"op":"mcm","clk":"1009173787","pt":1580642512156,"mc":[{"id":"1.168217554","rc":[{"batl":[[2,1.73,42.01]],"ltp":1.69,"tv":10476.8,"id":2263624}]}]}
{"op":"mcm","clk":"1009173907","pt":1580642512959,"mc":[{"id":"1.168217554","rc":[{"batb":[[1,1.61,946.63]],"batl":[[2,1.69,480.59]],"ltp":1.69,"tv":10476.8,"id":2263624}]}]}
{"op":"mcm","clk":"1009174112","pt":1580642514376,"mc":[{"id":"1.168217554","rc":[{"batb":[[1,1.64,29.07],[2,1.63,26.23]],"batl":[[0,1.66,857.88]],"ltp":1.69,"tv":10476.8,"id":2263624},{"batl":[[1,2.58,4.25],[2,2.6,9.53]],"ltp":2.36,"tv":1434.4,"id":7412809}]}]}
{"op":"mcm","clk":"1009174185","pt":1580642514858,"mc":[{"id":"1.168217554","rc":[{"batb":[[0,1.63,26.23],[1,1.61,494.03],[2,1.59,581.41]],"batl":[[0,1.69,480.59],[1,1.7,27.05],[2,1.71,497.4]],"ltp":1.69,"tv":10476.8,"id":2263624},{"batb":[[0,2.42,4.13],[1,2.4,29.41],[2,2.38,4.17]],"batl":[[0,2.72,24.37],[1,1000,0.02],[2,2.6,0]],"ltp":2.36,"tv":1434.4,"id":7412809}]}]}
{"op":"mcm","clk":"1009174454","pt":1580642516578,"mc":[{"id":"1.168217554","rc":[{"batb":[[2,1.59,510.84]],"ltp":1.69,"tv":10476.8,"id":2263624},{"batb":[[1,2.38,4.17],[2,2.32,73.72]],"batl":[[0,1000,0.02],[1,1000,0]],"ltp":2.36,"tv":1434.4,"id":7412809}]}]}
{"op":"mcm","clk":"1009174680","pt":1580642518067,"mc":[{"id":"1.168217554","rc":[{"batb":[[2,1.59,753.24]],"ltp":1.69,"tv":10476.8,"id":2263624},{"batl":[[0,2.6,3.61],[1,1000,0.02]],"ltp":2.36,"tv":1434.4,"id":7412809}]}]}
{"op":"mcm","clk":"1009175654","pt":1580642525078,"mc":[{"id":"1.168217554","rc":[{"batb":[[1,1.59,242.4],[2,1.58,704.01]],"ltp":1.69,"tv":10476.8,"id":2263624}]}]}
{"op":"mcm","clk":"1009176057","pt":1580642527483,"mc":[{"id":"1.168217554","rc":[{"trd":[[1.62,968.12],[1.63,366.78]],"batb":[[0,1.59,242.4],[1,1.58,704.01],[2,1.56,420.1]],"batl":[[0,1.62,973.42],[1,1.64,322.72],[2,1.65,179.62]],"ltp":1.62,"tv":10535.05,"id":2263624},{"trd":[[2.6,184.3]],"batb":[[0,2.52,77.02],[1,2.42,4.13],[2,2.38,4.17]],"batl":[[0,2.72,12.47],[1,2.84,847.47],[2,1000,0.02]],"ltp":2.6,"tv":1438.01,"id":7412809}],"tv":11973.06}]}
{"op":"mcm","clk":"1009176154","pt":1580642528077,"mc":[{"id":"1.168217554","rc":[{"batb":[[2,1.56,626.67]],"ltp":1.62,"tv":10535.05,"id":2263624},{"batb":[[0,2.52,136.03],[1,2.46,28.57],[2,2.42,69.75]],"batl":[[1,2.82,22.69],[2,2.84,847.47]],"ltp":2.6,"tv":1438.01,"id":7412809}]}]}
{"op":"mcm","clk":"1009177190","pt":1580642535306,"mc":[{"id":"1.168217554","rc":[{"batb":[[0,1.58,492.31],[1,1.56,626.67],[2,1.54,354.56]],"batl":[[0,1.68,46.07],[1,1.7,27.05],[2,1.72,23.91]],"ltp":1.62,"tv":10535.05,"id":2263624},{"batb":[[0,2.52,59.01]],"batl":[[0,2.82,22.69],[1,3.65,170.41],[2,1000,0.02]],"ltp":2.6,"tv":1438.01,"id":7412809}]}]}
{"op":"mcm","clk":"1009177339","pt":1580642536180,"mc":[{"id":"1.168217554","rc":[{"batb":[[0,1.6,28.54],[1,1.59,29.11],[2,1.58,368.07]],"batl":[[1,1.69,23.5],[2,3,42.01]],"ltp":1.62,"tv":10535.05,"id":2263624},{"batb":[[0,2.46,28.57],[1,2.44,4.17],[2,2.42,65.62]],"batl":[[0,2.68,3.64],[1,2.82,22.69],[2,3.65,170.41]],"ltp":2.6,"tv":1438.01,"id":7412809}]}]}
{"op":"mcm","clk":"1009177405","pt":1580642536596,"mc":[{"id":"1.168217554","rc":[{"batl":[[0,1.68,4.06]],"ltp":1.62,"tv":10535.05,"id":2263624},{"batb":[[0,2.44,4.17],[1,2.42,65.62],[2,2.08,21.65]],"batl":[[1,3.65,170.41],[2,1000,0.02]],"ltp":2.6,"tv":1438.01,"id":7412809}]}]}
{"op":"mcm","clk":"1009177869","pt":1580642539379,"mc":[{"id":"1.168217554","rc":[{"batl":[[0,1.67,25.5],[1,1.68,4.06],[2,1.69,23.5]],"ltp":1.62,"tv":10535.05,"id":2263624},{"batb":[[0,2.48,4.51],[1,2.44,4.17],[2,2.42,65.62]],"batl":[[1,2.7,3.35],[2,3.65,170.41]],"ltp":2.6,"tv":1438.01,"id":7412809}]}]}
{"op":"mcm","clk":"1009177912","pt":1580642539699,"mc":[{"id":"1.168217554","rc":[{"trd":[[1.6,2251.58]],"batb":[[0,1.6,20.01]],"batl":[[0,1.68,4.06],[1,1.69,23.5],[2,3,42.01]],"ltp":1.6,"tv":10552.11,"id":2263624},{"batb":[[0,2.44,4.17],[1,2.42,65.62],[2,2.08,21.65]],"ltp":2.6,"tv":1438.01,"id":7412809}],"tv":11990.13}]}
{"op":"mcm","clk":"1009178235","pt":1580642541392,"mc":[{"id":"1.168217554","rc":[{"batb":[[0,1.6,30.15],[1,1.59,398.59],[2,1.58,580.3]],"batl":[[0,1.61,11.5],[1,1.64,201.87],[2,1.65,180.06]],"ltp":1.6,"tv":10552.11,"id":2263624},{"batb":[[0,2.62,11.54],[1,2.44,4.17],[2,2.42,65.62]],"batl":[[0,2.68,14.78]],"ltp":2.6,"tv":1438.01,"id":7412809}]}]}
{"op":"mcm","clk":"1009178265","pt":1580642541615,"mc":[{"id":"1.168217554","rc":[{"batb":[[0,1.6,20.01]],"batl":[[0,1.64,201.87],[1,1.65,180.06],[2,1.68,4.06]],"ltp":1.6,"tv":10552.11,"id":2263624},{"batb":[[0,2.44,4.17],[1,2.42,65.62],[2,2.08,21.65]],"batl":[[0,2.68,3.64]],"ltp":2.6,"tv":1438.01,"id":7412809}]}]}
{"op":"mcm","clk":"1009178481","pt":1580642542896,"mc":[{"id":"1.168217554","rc":[{"batl":[[2,1.67,27.5]],"ltp":1.6,"tv":10552.11,"id":2263624},{"batb":[[0,2.48,5.26],[1,2.44,4.17],[2,2.42,65.62]],"ltp":2.6,"tv":1438.01,"id":7412809}]}]}
{"op":"mcm","clk":"1009178615","pt":1580642543925,"mc":[{"id":"1.168217554","rc":[{"batb":[[1,1.59,29.11],[2,1.58,368.07]],"batl":[[0,1.68,4.06],[1,1.69,23.5],[2,3,42.01]],"ltp":1.6,"tv":10552.11,"id":2263624},{"batb":[[0,2.44,4.17],[1,2.42,65.62],[2,2.08,21.65]],"ltp":2.6,"tv":1438.01,"id":7412809}]}]}
{"op":"mcm","clk":"1009179314","pt":1580642548509,"mc":[{"id":"1.168217554","rc":[{"trd":[[1.6,2291.6]],"batb":[[0,1.59,29.11],[1,1.58,368.07],[2,1.57,339.8]],"batl":[[0,1.6,1067.35],[1,1.63,235.21],[2,1.68,4.06]],"ltp":1.6,"tv":10592.13,"id":2263624},{"batl":[[2,2.78,11.8]],"ltp":2.6,"tv":1438.01,"id":7412809}],"tv":12030.15}]}
{"op":"mcm","clk":"1009179461","pt":1580642549522,"mc":[{"id":"1.168217554","rc":[{"batl":[[1,1.62,269.48],[2,1.63,422.93]],"ltp":1.6,"tv":10592.13,"id":2263624},{"batb":[[0,2.58,55.08],[1,2.56,26.89],[2,2.5,5.36]],"ltp":2.6,"tv":1438.01,"id":7412809}]}]}
{"op":"mcm","clk":"1009180011","pt":1580642552903,"mc":[{"id":"1.168217554","rc":[{"batb":[[2,2.52,3.34]],"ltp":2.6,"tv":1438.01,"id":7412809}]}]}
{"op":"mcm","clk":"1009180155","pt":1580642553804,"mc":[{"id":"1.168217554","rc":[{"batb":[[2,2.5,5.36]],"ltp":2.6,"tv":1438.01,"id":7412809}]}]}
{"op":"mcm","clk":"1009181480","pt":1580642562659,"mc":[{"id":"1.168217554","rc":[{"trd":[[1.59,2299.7]],"batb":[[0,1.59,24.82]],"ltp":1.59,"tv":10600.72,"id":2263624}],"tv":12038.73}]}
{"op":"mcm","clk":"1009181652","pt":1580642563896,"mc":[{"id":"1.168217554","rc":[{"trd":[[1.59,2354.52]],"batb":[[0,1.58,368.07],[1,1.57,339.8],[2,1.56,774.51]],"ltp":1.59,"tv":10655.54,"id":2263624},{"trd":[[2.68,151.91]],"batl":[[0,2.7,3.92],[1,2.78,11.8],[2,2.9,310]],"ltp":2.68,"tv":1441.08,"id":7412809}],"tv":12096.62}]}
{"op":"mcm","clk":"1009183710","pt":1580642577490,"mc":[{"id":"1.168217554","rc":[{"batb":[[1,1.56,420.1],[2,1.54,354.56]],"batl":[[0,1.64,42.01],[1,1.68,32.89],[2,1.69,23.5]],"ltp":1.59,"tv":10655.54,"id":2263624},{"batb":[[0,2.56,26.89],[1,2.46,70.38],[2,2.44,4.17]],"batl":[[0,2.94,24.41],[1,3.05,3.1],[2,3.65,170.41]],"ltp":2.68,"tv":1441.08,"id":7412809}]}]}
{"op":"mcm","clk":"1009183817","pt":1580642578124,"mc":[{"id":"1.168217554","rc":[{"batl":[[1,1.71,31.5],[2,3,42.01]],"ltp":1.59,"tv":10655.54,"id":2263624},{"batb":[[1,2.46,62.87],[2,2.4,7.46]],"ltp":2.68,"tv":1441.08,"id":7412809}]}]}
{"op":"mcm","clk":"1009183900","pt":1580642578615,"mc":[{"id":"1.168217554","rc":[{"batl":[[0,1.71,31.5],[1,3,42.01],[2,7,2.27]],"ltp":1.59,"tv":10655.54,"id":2263624},{"batb":[[0,2.46,62.87],[1,2.4,7.46],[2,2.08,21.65]],"batl":[[0,2.94,3.41]],"ltp":2.68,"tv":1441.08,"id":7412809}]}]}
{"op":"mcm","clk":"1009184199","pt":1580642580487,"mc":[{"id":"1.168217554","rc":[{"batl":[[0,1.67,246.84],[1,1.69,333.13],[2,1.71,31.5]],"ltp":1.59,"tv":10655.54,"id":2263624}]}]}
{"op":"mcm","clk":"1009184310","pt":1580642581287,"mc":[{"id":"1.168217554","rc":[{"batl":[[1,1.68,50.89],[2,1.69,333.13]],"ltp":1.59,"tv":10655.54,"id":2263624},{"batb":[[0,2.46,74.75]],"ltp":2.68,"tv":1441.08,"id":7412809}]}]}
{"op":"mcm","clk":"1009186184","pt":1580642594410,"mc":[{"id":"1.168217554","rc":[{"batl":[[0,1.71,31.5],[1,3,42.01],[2,7,2.27]],"ltp":1.59,"tv":10655.54,"id":2263624},{"batb":[[0,2.46,62.87]],"ltp":2.68,"tv":1441.08,"id":7412809}]}]}
{"op":"mcm","clk":"1009186285","pt":1580642595109,"mc":[{"id":"1.168217554","rc":[{"batl":[[2,1000,0.02]],"ltp":2.68,"tv":1441.08,"id":7412809}]}]}
{"op":"mcm","clk":"1009186582","pt":1580642597251,"mc":[{"id":"1.168217554","rc":[{"trd":[[1.52,73.48],[1.54,709.12],[1.56,420.1],[1.58,573.73]],"batb":[[0,1.5,334.04],[1,1.49,301.74],[2,1.48,159.33]],"batl":[[0,1.52,274.94],[1,1.54,234.7],[2,1.55,225.89]],"ltp":1.52,"tv":12226.31,"id":2263624},{"trd":[[2.74,212.25],[2.8,234.05]],"batb":[[0,2.88,499.85],[1,2.84,149.81],[2,2.74,11.52]],"batl":[[0,3.05,10.83],[1,3.2,317.44],[2,3.25,404]],"ltp":2.8,"tv":1887.38,"id":7412809}],"tv":14113.69}]}
{"op":"mcm","clk":"1009186707","pt":1580642598127,"mc":[{"id":"1.168217554","rc":[{"trd":[[1.52,88.28]],"batl":[[0,1.52,267.54]],"ltp":1.52,"tv":12241.1,"id":2263624},{"batb":[[2,2.82,43.67]],"ltp":2.8,"tv":1887.38,"id":7412809}],"tv":14128.49}]}
{"op":"mcm","clk":"1009187006","pt":1580642600153,"mc":[{"id":"1.168217554","rc":[{"batl":[[1,3.15,19.32],[2,3.2,317.44]],"ltp":2.8,"tv":1887.38,"id":7412809}]}]}
{"op":"mcm","clk":"1009187609","pt":1580642604341,"mc":[{"id":"1.168217554","rc":[{"batb":[[2,1.48,653.37]],"batl":[[2,1.55,706.48]],"ltp":1.52,"tv":12241.1,"id":2263624}]}]}
{"op":"mcm","clk":"1009189021","pt":1580642614141,"mc":[{"id":"1.168217554","rc":[{"trd":[[1.5,106.11]],"batb":[[0,1.5,280.97]],"ltp":1.5,"tv":12347.21,"id":2263624}],"tv":14234.6}]}
{"op":"mcm","clk":"1009189528","pt":1580642617545,"mc":[{"id":"1.168217554","rc":[{"batl":[[1,1.54,263.77]],"ltp":1.5,"tv":12347.21,"id":2263624}]}]}
{"op":"mcm","clk":"1009189818","pt":1580642619465,"mc":[{"id":"1.168217554","rc":[{"batb":[[0,1.48,653.37],[1,1.46,601.58],[2,1.41,37.89]],"batl":[[0,1.55,480.59],[1,1.57,667.36],[2,1.63,68.5]],"ltp":1.5,"tv":12347.21,"id":2263624},{"batb":[[0,2.84,149.81],[1,2.82,43.67],[2,2.74,23.53]],"batl":[[0,3.15,19.32],[1,3.45,2.5],[2,3.75,2.38]],"ltp":2.8,"tv":1887.38,"id":7412809}]}]}
{"op":"mcm","clk":"1009189866","pt":1580642619891,"mc":[{"id":"1.168217554","rc":[{"batb":[[0,1.48,494.03]],"batl":[[1,1.57,539.41]],"ltp":1.5,"tv":12347.21,"id":2263624},{"batb":[[0,2.74,23.53],[1,2.66,51.3],[2,2.58,14.56]],"ltp":2.8,"tv":1887.38,"id":7412809}]}]}
{"op":"mcm","clk":"1009189995","pt":1580642620646,"mc":[{"id":"1.168217554","rc":[{"batb":[[1,1.46,510.84]],"batl":[[1,1.57,497.4]],"ltp":1.5,"tv":12347.21,"id":2263624},{"batb":[[0,2.66,51.3],[1,2.58,14.56],[2,2.5,1.87]],"batl":[[0,3.45,2.5],[1,3.75,2.38],[2,4.6,136.05]],"ltp":2.8,"tv":1887.38,"id":7412809}]}]}
{"op":"mcm","clk":"1009190255","pt":1580642622466,"mc":[{"id":"1.168217554","rc":[{"batb":[[2,1.42,269.68]],"batl":[[2,1.6,266.14]],"ltp":1.5,"tv":12347.21,"id":2263624}]}]}
{"op":"mcm","clk":"1009190302","pt":1580642622773,"mc":[{"id":"1.168217554","rc":[{"batb":[[2,1.41,37.89]],"batl":[[2,1.63,68.5]],"ltp":1.5,"tv":12347.21,"id":2263624}]}]}
{"op":"mcm","clk":"1009190855","pt":1580642626648,"mc":[{"id":"1.168217554","rc":[{"batb":[[0,1.48,867.12],[1,1.47,282.64],[2,1.46,510.84]],"batl":[[0,1.52,225.38],[1,1.53,237.62],[2,1.55,480.59]],"ltp":1.5,"tv":12347.21,"id":2263624}]}]}
{"op":"mcm","clk":"1009191569","pt":1580642631753,"mc":[{"id":"1.168217554","rc":[{"batb":[[0,1.48,494.03],[1,1.46,510.84],[2,1.41,37.89]],"batl":[[0,1.55,480.59],[1,1.57,497.4],[2,1.63,68.5]],"ltp":1.5,"tv":12347.21,"id":2263624}]}]}
{"op":"mcm","clk":"1009191720","pt":1580642632660,"mc":[{"id":"1.168217554","rc":[{"batb":[[2,2.48,14.26]],"ltp":2.8,"tv":1887.38,"id":7412809}]}]}
{"op":"mcm","clk":"1009191986","pt":1580642634368,"mc":[{"id":"1.168217554","rc":[{"batb":[[0,1.41,37.89],[1,1.39,207.25],[2,1.37,46.77]],"ltp":1.5,"tv":12347.21,"id":2263624}]}]}
{"op":"mcm","clk":"1009192157","pt":1580642635479,"mc":[{"id":"1.168217554","rc":[{"batb":[[0,1.42,269.68],[1,1.41,337.42],[2,1.39,207.25]],"batl":[[2,1.6,266.14]],"ltp":1.5,"tv":12347.21,"id":2263624},{"batl":[[0,3.75,2.38],[1,1000,0.02],[2,4.6,0]],"ltp":2.8,"tv":1887.38,"id":7412809}]}]}
{"op":"mcm","clk":"1009192170","pt":1580642635581,"mc":[{"id":"1.168217554","rc":[{"batl":[[2,1.63,68.5]],"ltp":1.5,"tv":12347.21,"id":2263624}]}]}
{"op":"mcm","clk":"1009192414","pt":1580642637506,"mc":[{"id":"1.168217554","rc":[{"batb":[[2,1.4,9.53]],"batl":[[0,1.44,709],[1,1.45,204.26],[2,1.46,286.63]],"ltp":1.5,"tv":12347.21,"id":2263624},{"batb":[[0,3.35,7.31],[1,3.3,353.11],[2,3.25,218.52]],"batl":[[0,3.5,3.81],[1,3.65,305],[2,3.7,314.97]],"ltp":2.8,"tv":1887.38,"id":7412809}]}]}
{"op":"mcm","clk":"1009192558","pt":1580642638490,"mc":[{"id":"1.168217554","rc":[{"batl":[[1,3.55,15.96],[2,3.65,305]],"ltp":2.8,"tv":1887.38,"id":7412809}]}]}
{"op":"mcm","clk":"1009193318","pt":1580642643292,"mc":[{"id":"1.168217554","rc":[{"batl":[[2,1.46,767.22]],"ltp":1.5,"tv":12347.21,"id":2263624}]}]}
{"op":"mcm","clk":"1009194473","pt":1580642651481,"mc":[{"id":"1.168217554","rc":[{"batb":[[2,1.39,808.83]],"batl":[[0,1.45,204.26],[1,1.46,767.22],[2,1.48,497.4]],"ltp":1.5,"tv":12347.21,"id":2263624},{"batb":[[0,3.2,79.23],[1,3.1,2.66],[2,3.05,20.16]],"batl":[[0,3.55,15.96],[1,4.2,2.03],[2,4.6,2]],"ltp":2.8,"tv":1887.38,"id":7412809}]}]}
{"op":"mcm","clk":"1009194507","pt":1580642651700,"mc":[{"id":"1.168217554","rc":[{"batb":[[0,1.39,601.58],[1,1.37,510.84],[2,1.32,321.15]],"batl":[[0,1.46,480.59],[1,1.48,497.4],[2,1.49,42.01]],"ltp":1.5,"tv":12347.21,"id":2263624},{"batb":[[0,3.1,2.66],[1,3.05,20.16],[2,2.94,98.9]],"ltp":2.8,"tv":1887.38,"id":7412809}]}]}
{"op":"mcm","clk":"1009194650","pt":1580642652600,"mc":[{"id":"1.168217554","rc":[{"batb":[[0,1.39,494.03]],"batl":[[2,1.54,69.75]],"ltp":1.5,"tv":12347.21,"id":2263624},{"batb":[[1,2.94,98.9],[2,2.84,12.72]],"batl":[[0,4.2,2.03],[1,4.6,2],[2,5.3,118.79]],"ltp":2.8,"tv":1887.38,"id":7412809}]}]}
{"op":"mcm","clk":"1009194957","pt":1580642654578,"mc":[{"id":"1.168217554","rc":[{"batb":[[2,1.34,435.27]],"batl":[[2,1.51,258.19]],"ltp":1.5,"tv":12347.21,"id":2263624}]}]}
{"op":"mcm","clk":"1009195859","pt":1580642660449,"mc":[{"id":"1.168217554","rc":[{"batb":[[2,1.32,321.15]],"ltp":1.5,"tv":12347.21,"id":2263624}]}]}
{"op":"mcm","clk":"1009196007","pt":1580642661405,"mc":[{"id":"1.168217554","rc":[{"batl":[[0,1.51,258.2],[1,1.52,243.52],[2,1.54,69.75]],"ltp":1.5,"tv":12347.21,"id":2263624},{"batb":[[0,2.94,98.9],[1,2.84,12.72],[2,2.72,12.59]],"ltp":2.8,"tv":1887.38,"id":7412809}]}]}
{"op":"mcm","clk":"1009196310","pt":1580642663505,"mc":[{"id":"1.168217554","rc":[{"batb":[[0,1.47,364.48],[1,1.46,302.17],[2,1.4,137.96]],"batl":[[0,1.48,12.55],[1,1.5,692],[2,1.51,258.19]],"ltp":1.5,"tv":12347.21,"id":2263624},{"batb":[[0,3.05,330.5],[1,2.94,98.9],[2,2.84,12.72]],"batl":[[0,3.25,115.39],[1,3.3,58.98],[2,3.35,710.71]],"ltp":2.8,"tv":1887.38,"id":7412809}]}]}
{"op":"mcm","clk":"1009196424","pt":1580642664311,"mc":[{"id":"1.168217554","rc":[{"batb":[[2,1.45,174.52]],"ltp":1.5,"tv":12347.21,"id":2263624},{"batb":[[2,2.88,21.85]],"batl":[[1,3.3,76.62]],"ltp":2.8,"tv":1887.38,"id":7412809}]}]}
{"op":"mcm","clk":"1009197260","pt":1580642669902,"mc":[{"id":"1.168217554","rc":[{"batb":[[2,1.45,668.55]],"batl":[[2,1.51,738.78]],"ltp":1.5,"tv":12347.21,"id":2263624}]}]}
{"op":"mcm","clk":"1009199465","pt":1580642685262,"mc":[{"id":"1.168217554","rc":[{"batl":[[1,1.51,738.78],[2,1.52,243.52]],"ltp":1.5,"tv":12347.21,"id":2263624},{"batl":[[2,3.35,310.71]],"ltp":2.8,"tv":1887.38,"id":7412809}]}]}
{"op":"mcm","clk":"1009199585","pt":1580642686165,"mc":[{"id":"1.168217554","rc":[{"batb":[[0,1.45,494.03],[1,1.43,608.3],[2,1.35,236.2]],"batl":[[0,1.51,480.6],[1,1.53,497.4],[2,1.54,42.01]],"ltp":1.5,"tv":12347.21,"id":2263624},{"batb":[[0,2.88,21.85],[1,2.72,48.7],[2,2.68,13.61]],"batl":[[0,3.3,17.64],[1,4.6,136.05],[2,1000,0.02]],"ltp":2.8,"tv":1887.38,"id":7412809}]}]}
{"op":"mcm","clk":"1009199646","pt":1580642686537,"mc":[{"id":"1.168217554","rc":[{"batb":[[1,1.43,510.84]],"batl":[[2,1.59,69.5]],"ltp":1.5,"tv":12347.21,"id":2263624},{"batb":[[0,2.72,48.7],[1,2.68,13.61],[2,2.58,14.56]],"batl":[[0,4.6,136.05],[1,1000,0.02],[2,1000,0]],"ltp":2.8,"tv":1887.38,"id":7412809}]}]}
{"op":"mcm","clk":"1009200000","pt":1580642689034,"mc":[{"id":"1.168217554","rc":[{"batb":[[2,1.38,233.29]],"batl":[[2,1.58,214.06]],"ltp":1.5,"tv":12347.21,"id":2263624}]}]}
{"op":"mcm","clk":"1009201315","pt":1580642698251,"mc":[{"id":"1.168217554","rc":[{"batl":[[2,1.59,69.5]],"ltp":1.5,"tv":12347.21,"id":2263624}]}]}
{"op":"mcm","clk":"1009201364","pt":1580642698568,"mc":[{"id":"1.168217554","rc":[{"batb":[[0,1.38,233.29],[1,1.37,384.79],[2,1.35,236.2]],"ltp":1.5,"tv":12347.21,"id":2263624}]}]}
{"op":"mcm","clk":"1009201738","pt":1580642701456,"mc":[{"id":"1.168217554","rc":[{"trd":[[1.38,36.78]],"batb":[[0,1.38,214.9],[2,1.36,14.11]],"batl":[[0,1.39,858.71],[1,1.4,1158.84],[2,1.41,591.15]],"ltp":1.38,"tv":12383.99,"id":2263624},{"batb":[[0,3.5,16.12],[1,3.4,220.59],[2,2.72,48.7]],"batl":[[0,4,319],[1,4.1,405.73],[2,1000,0.02]],"ltp":2.8,"tv":1887.38,"id":7412809}],"tv":14271.38}]}
{"op":"mcm","clk":"1009201853","pt":1580642702259,"mc":[{"id":"1.168217554","rc":[{"batb":[[2,1.36,130.06]],"ltp":1.38,"tv":12383.99,"id":2263624},{"batb":[[1,3.45,66.64],[2,3.4,220.59]],"batl":[[0,3.8,14.28],[1,4,319],[2,4.1,405.73]],"ltp":2.8,"tv":1887.38,"id":7412809}]}]}
{"op":"mcm","clk":"1009202661","pt":1580642708340,"mc":[{"id":"1.168217554","rc":[{"batl":[[2,1.41,1071.74]],"ltp":1.38,"tv":12383.99,"id":2263624}]}]}
{"op":"mcm","clk":"1009203050","pt":1580642711176,"mc":[{"id":"1.168217554","rc":[{"batb":[[2,1.36,115.95]],"ltp":1.38,"tv":12383.99,"id":2263624}]}]}
{"op":"mcm","clk":"1009203495","pt":1580642714175,"mc":[{"id":"1.168217554","rc":[{"batl":[[0,1.39,873.83]],"ltp":1.38,"tv":12383.99,"id":2263624},{"batl":[[0,3.7,5.68],[1,3.8,14.28],[2,4,319]],"ltp":2.8,"tv":1887.38,"id":7412809}]}]}
{"op":"mcm","clk":"1009203938","pt":1580642717471,"mc":[{"id":"1.168217554","rc":[{"trd":[[1.38,78.78]],"batb":[[0,1.38,193.9]],"ltp":1.38,"tv":12426.0,"id":2263624}],"tv":14313.38}]}
{"op":"mcm","clk":"1009204697","pt":1580642723026,"mc":[{"id":"1.168217554","rc":[{"batl":[[1,1.4,101.84]],"ltp":1.38,"tv":12426.0,"id":2263624},{"batl":[[2,4.1,405.73]],"ltp":2.8,"tv":1887.38,"id":7412809}]}]}
{"op":"mcm","clk":"1009204994","pt":1580642724906,"mc":[{"id":"1.168217554","rc":[{"batb":[[0,1.36,115.95],[1,1.33,494.03],[2,1.31,510.84]],"batl":[[0,1.41,480.59],[1,1.43,497.4],[2,1.45,42.01]],"ltp":1.38,"tv":12426.0,"id":2263624},{"batb":[[0,3.2,21.11],[1,3.1,84.58],[2,3.05,11.89]],"batl":[[0,3.8,14.28],[1,5.5,115.06],[2,1000,0.02]],"ltp":2.8,"tv":1887.38,"id":7412809}]}]}
{"op":"mcm","clk":"1009205245","pt":1580642726704,"mc":[{"id":"1.168217554","rc":[{"batb":[[0,1.33,494.03],[1,1.31,510.84],[2,1.27,322.99]],"batl":[[2,1.48,73.5]],"ltp":1.38,"tv":12426.0,"id":2263624},{"batb":[[0,3.2,2.62]],"batl":[[0,5.5,115.06],[1,1000,0.02],[2,1000,0]],"ltp":2.8,"tv":1887.38,"id":7412809}]}]}
{"op":"mcm","clk":"1009205432","pt":1580642727875,"mc":[{"id":"1.168217554","rc":[{"batb":[[2,1.29,707.77]],"batl":[[2,1.47,302.96]],"ltp":1.38,"tv":12426.0,"id":2263624}]}]}
{"op":"mcm","clk":"1009205597","pt":1580642728985,"mc":[{"id":"1.168217554","rc":[{"batb":[[2,1.27,322.99]],"batl":[[2,1.48,73.5]],"ltp":1.38,"tv":12426.0,"id":2263624}]}]}
{"op":"mcm","clk":"1009205763","pt":1580642730206,"mc":[{"id":"1.168217554","rc":[{"batb":[[0,3.1,84.58],[1,3.05,11.89],[2,2.96,11.88]],"ltp":2.8,"tv":1887.38,"id":7412809}]}]}
{"op":"mcm","clk":"1009206195","pt":1580642733006,"mc":[{"id":"1.168217554","rc":[{"batb":[[0,1.36,339.71],[1,1.35,414.68],[2,1.33,494.03]],"batl":[[0,1.39,310.39],[1,1.4,342.34],[2,1.41,480.59]],"ltp":1.38,"tv":12426.0,"id":2263624}]}]}
{"op":"mcm","clk":"1009206965","pt":1580642738402,"mc":[{"id":"1.168217554","rc":[{"batb":[[0,1.33,494.03],[1,1.31,510.84],[2,1.27,322.99]],"batl":[[0,1.41,480.59],[1,1.43,497.4],[2,1.48,73.5]],"ltp":1.38,"tv":12426.0,"id":2263624}]}]}
{"op":"mcm","clk":"1009207388","pt":1580642741409,"mc":[{"id":"1.168217554","rc":[{"batb":[[2,1.29,707.77]],"batl":[[2,1.47,302.96]],"ltp":1.38,"tv":12426.0,"id":2263624}]}]}
{"op":"mcm","clk":"1009207823","pt":1580642744515,"mc":[{"id":"1.168217554","rc":[{"batb":[[2,1.27,322.99]],"batl":[[2,1.48,73.5]],"ltp":1.38,"tv":12426.0,"id":2263624}]}]}
{"op":"mcm","clk":"1009207963","pt":1580642745429,"mc":[{"id":"1.168217554","rc":[{"batl":[[0,1.51,69.51],[1,1.67,64.5],[2,1.71,31.5]],"ltp":1.38,"tv":12426.0,"id":2263624},{"batb":[[1,2.96,11.88],[2,2.52,381.46]],"ltp":2.8,"tv":1887.38,"id":7412809}]}]}
{"op":"mcm","clk":"1009208106","pt":1580642746438,"mc":[{"id":"1.168217554","rc":[{"batl":[[0,1000,0.02],[1,1000,0]],"ltp":2.8,"tv":1887.38,"id":7412809}]}]}
{"op":"mcm","clk":"1009208262","pt":1580642747508,"mc":[{"id":"1.168217554","rc":[{"batb":[[0,1.43,1587.93],[1,1.33,494.03],[2,1.31,510.84]],"batl":[[0,1.45,11.3],[1,1.46,875],[2,1.47,1530.61]],"ltp":1.38,"tv":12426.0,"id":2263624},{"batb":[[0,3.25,295.53],[1,3.1,84.58],[2,2.96,11.88]],"batl":[[0,3.55,284],[1,3.75,705.64],[2,1000,0.02]],"ltp":2.8,"tv":1887.38,"id":7412809}]}]}
{"op":"mcm","clk":"1009208403","pt":1580642748414,"mc":[{"id":"1.168217554","rc":[{"batb":[[0,1.43,2023.68],[1,1.42,328.71],[2,1.41,197.18]],"batl":[[2,1.47,1833.57]],"ltp":1.38,"tv":12426.0,"id":2263624},{"batb":[[2,3,23.57]],"batl":[[0,3.5,16.8],[1,3.55,284],[2,3.75,705.64]],"ltp":2.8,"tv":1887.38,"id":7412809}]}]}
{"op":"mcm","clk":"1009209229","pt":1580642753941,"mc":[{"id":"1.168217554","rc":[{"batl":[[2,1.47,2314.16]],"ltp":1.38,"tv":12426.0,"id":2263624}]}]}
{"op":"mcm","clk":"1009209340","pt":1580642754636,"mc":[{"id":"1.168217554","rc":[{"trd":[[1.43,1462.89]],"batb":[[0,1.43,1292.25]],"ltp":1.43,"tv":13888.89,"id":2263624}],"tv":15776.27}]}
{"op":"mcm","clk":"1009209590","pt":1580642756312,"mc":[{"id":"1.168217554","rc":[{"trd":[[1.43,1468.35]],"batb":[[0,1.43,1289.52]],"ltp":1.43,"tv":13894.35,"id":2263624}],"tv":15781.73}]}
{"op":"mcm","clk":"1009209843","pt":1580642758029,"mc":[{"id":"1.168217554","rc":[{"trd":[[1.43,1473.25]],"batb":[[0,1.43,1284.62]],"ltp":1.43,"tv":13899.25,"id":2263624},{"trd":[[3.35,2.09]],"ltp":3.35,"tv":1889.47,"id":7412809}],"tv":15788.72}]}
{"op":"mcm","clk":"1009210191","pt":1580642760449,"mc":[{"id":"1.168217554","rc":[{"trd":[[1.43,1903.71]],"batb":[[0,1.43,1069.39]],"ltp":1.43,"tv":14329.71,"id":2263624}],"tv":16219.18}]}
{"op":"mcm","clk":"1009210488","pt":1580642762645,"mc":[{"id":"1.168217554","rc":[{"trd":[[1.43,2004.76]],"batb":[[0,1.43,979.34]],"ltp":1.43,"tv":14430.76,"id":2263624},{"trd":[[3.35,35.84]],"ltp":3.35,"tv":1923.21,"id":7412809}],"tv":16353.98}]}
{"op":"mcm","clk":"1009211313","pt":1580642768451,"mc":[{"id":"1.168217554","rc":[{"batb":[[0,1.43,964.84]],"batl":[[0,1.47,2314.16],[1,1.48,270.52],[2,1.49,497.4]],"ltp":1.43,"tv":14430.76,"id":2263624},{"batb":[[0,3.1,84.58],[1,3,23.57],[2,2.96,11.88]],"batl":[[1,4.9,126.27],[2,1000,0.02]],"ltp":3.35,"tv":1923.21,"id":7412809}]}]}
{"op":"mcm","clk":"1009211397","pt":1580642769073,"mc":[{"id":"1.168217554","rc":[{"batb":[[0,1.4,105.02],[1,1.38,494.03],[2,1.36,510.84]],"batl":[[0,1.47,480.59],[1,1.49,497.4],[2,1.5,42.01]],"ltp":1.43,"tv":14430.76,"id":2263624},{"batb":[[0,3,23.57],[1,2.74,60.31],[2,2.6,12.79]],"ltp":3.35,"tv":1923.21,"id":7412809}]}]}
{"op":"mcm","clk":"1009211617","pt":1580642770651,"mc":[{"id":"1.168217554","rc":[{"batb":[[0,1.38,494.03],[1,1.36,510.84],[2,1.29,307.65]],"batl":[[2,1.57,67.5]],"ltp":1.43,"tv":14430.76,"id":2263624},{"batb":[[0,3,2.56]],"batl":[[0,4.9,126.27],[1,1000,0.02],[2,1000,0]],"ltp":3.35,"tv":1923.21,"id":7412809}]}]}
{"op":"mcm","clk":"1009211804","pt":1580642771836,"mc":[{"id":"1.168217554","rc":[{"batb":[[2,1.3,524.58]],"ltp":1.43,"tv":14430.76,"id":2263624}]}]}
{"op":"mcm","clk":"1009212451","pt":1580642776272,"mc":[{"id":"1.168217554","rc":[{"batb":[[0,2.74,60.31],[1,2.6,12.79],[2,2.52,381.46]],"ltp":3.35,"tv":1923.21,"id":7412809}]}]}
{"op":"mcm","clk":"1009214350","pt":1580642788990,"mc":[{"id":"1.168217554","rc":[{"batb":[[0,1.3,524.58],[1,1.29,835.72],[2,1.15,378.72]],"ltp":1.43,"tv":14430.76,"id":2263624}]}]}
{"op":"mcm","clk":"1009214737","pt":1580642791485,"mc":[{"id":"1.168217554","rc":[{"batb":[[2,1.25,782.71]],"batl":[[0,1.31,16.57],[1,1.32,2541.22],[2,1.35,639.93]],"ltp":1.43,"tv":14430.76,"id":2263624},{"batl":[[0,4.4,4.77],[1,4.8,256],[2,5,195.68]],"ltp":3.35,"tv":1923.21,"id":7412809}]}]}
{"op":"mcm","clk":"1009214889","pt":1580642792460,"mc":[{"id":"1.168217554","rc":[{"batb":[[2,1.27,155.44]],"batl":[[2,1.33,384.12]],"ltp":1.43,"tv":14430.76,"id":2263624},{"batb":[[0,3.95,93.79],[1,3.9,14.28],[2,3.55,61.06]],"batl":[[1,4.7,10.92],[2,4.8,256]],"ltp":3.35,"tv":1923.21,"id":7412809}]}]}
{"op":"mcm","clk":"1009214916","pt":1580642792665,"mc":[{"id":"1.168217554","rc":[{"batb":[[2,3.8,2.54]],"ltp":3.35,"tv":1923.21,"id":7412809}]}]}
{"op":"mcm","clk":"1009216593","pt":1580642802926,"mc":[{"id":"1.168217554","rc":[{"trd":[[1.31,23.82]],"batl":[[0,1.31,4.66]],"ltp":1.31,"tv":14454.58,"id":2263624}],"tv":16377.8}]}
{"op":"mcm","clk":"1009217000","pt":1580642805549,"mc":[{"id":"1.168217554","rc":[{"trd":[[1.31,33.14]],"batb":[[0,1.31,17.4],[1,1.3,524.58],[2,1.29,835.72]],"batl":[[0,1.32,2541.22],[1,1.33,384.12],[2,1.34,460.94]],"ltp":1.31,"tv":14463.9,"id":2263624}],"tv":16387.12}]}
{"op":"mcm","clk":"1009217283","pt":1580642807428,"mc":[{"id":"1.168217554","rc":[{"trd":[[1.3,319.76],[1.31,67.94]],"batb":[[0,1.3,364.7],[1,1.29,835.72],[2,1.27,155.44]],"ltp":1.3,"tv":14818.46,"id":2263624}],"tv":16741.68}]}
{"op":"mcm","clk":"1009217452","pt":1580642808231,"mc":[{"id":"1.168217554","rc":[{"trd":[[1.32,0.18]],"batl":[[0,1.32,2541.13]],"ltp":1.32,"tv":14818.64,"id":2263624}],"tv":16741.86}]}
{"op":"mcm","clk":"1009217717","pt":1580642809814,"mc":[{"id":"1.168217554","rc":[{"trd":[[1.32,1000.18]],"batl":[[0,1.32,2041.13]],"ltp":1.32,"tv":15818.64,"id":2263624}],"tv":17741.86}]}
{"op":"mcm","clk":"1009217898","pt":1580642810952,"mc":[{"id":"1.168217554","rc":[{"batb":[[0,1.3,436.22]],"batl":[[1,1.33,470.53]],"ltp":1.32,"tv":15818.64,"id":2263624}]}]}
{"op":"mcm","clk":"1009218232","pt":1580642813155,"mc":[{"id":"1.168217554","rc":[{"batl":[[0,4.7,10.92],[1,4.8,256],[2,5,195.68]],"ltp":3.35,"tv":1923.21,"id":7412809}]}]}
{"op":"mcm","clk":"1009218574","pt":1580642815035,"mc":[{"id":"1.168217554","rc":[{"trd":[[1.3,325.22]],"batb":[[0,1.3,433.49]],"ltp":1.3,"tv":15824.11,"id":2263624}],"tv":17747.32}]}
{"op":"mcm","clk":"1009219277","pt":1580642819124,"mc":[{"id":"1.168217554","rc":[{"batl":[[0,1.32,2060.22]],"ltp":1.3,"tv":15824.11,"id":2263624},{"batl":[[0,4.3,4.26],[1,4.7,10.92],[2,4.8,256]],"ltp":3.35,"tv":1923.21,"id":7412809}]}]}
{"op":"mcm","clk":"1009219524","pt":1580642820662,"mc":[{"id":"1.168217554","rc":[{"batb":[[2,3.55,61.06]],"ltp":3.35,"tv":1923.21,"id":7412809}]}]}
{"op":"mcm","clk":"1009219969","pt":1580642823231,"mc":[{"id":"1.168217554","rc":[{"batl":[[2,1.34,466.4]],"ltp":1.3,"tv":15824.11,"id":2263624}]}]}
{"op":"mcm","clk":"1009220005","pt":1580642823553,"mc":[{"id":"1.168217554","rc":[{"batl":[[2,1.34,463.21]],"ltp":1.3,"tv":15824.11,"id":2263624}]}]}
{"op":"mcm","clk":"1009220247","pt":1580642825139,"mc":[{"id":"1.168217554","rc":[{"trd":[[1.3,337.14]],"batb":[[0,1.3,427.53]],"ltp":1.3,"tv":15836.03,"id":2263624}],"tv":17759.24}]}
{"op":"mcm","clk":"1009227217","pt":1580642870319,"mc":[{"id":"1.168217554","rc":[{"batb":[[0,1.27,155.44],[1,1.26,339.98],[2,1.11,37.96]],"batl":[[0,1.34,44.28],[1,1.57,67.51],[2,3,42.01]],"ltp":1.3,"tv":15836.03,"id":2263624},{"batb":[[0,3.9,14.28],[1,3.55,61.06],[2,2.74,13.02]],"batl":[[0,4.7,10.92],[1,6.6,98.95],[2,1000,0.02]],"ltp":3.35,"tv":1923.21,"id":7412809}]}]}
{"op":"mcm","clk":"1009227264","pt":1580642870645,"mc":[{"id":"1.168217554","rc":[{"batb":[[0,1.26,339.98],[1,1.11,37.96],[2,1.1,568.02]],"batl":[[0,1.34,2.27]],"ltp":1.3,"tv":15836.03,"id":2263624},{"batb":[[0,3.55,61.06],[1,2.74,13.02],[2,2.52,381.46]],"batl":[[0,6.6,98.95],[1,1000,0.02],[2,1000,0]],"ltp":3.35,"tv":1923.21,"id":7412809}]}]}
{"op":"mcm","clk":"1009227622","pt":1580642873305,"mc":[{"id":"1.168217554","rc":[{"batb":[[0,1.28,347.64],[1,1.27,573.76],[2,1.26,339.98]],"batl":[[1,1.38,470.36],[2,1.39,353.72]],"ltp":1.3,"tv":15836.03,"id":2263624},{"batb":[[0,3.6,10.04],[1,3.55,61.06]],"batl":[[0,4.6,2.01],[1,6.6,98.95],[2,1000,0.02]],"ltp":3.35,"tv":1923.21,"id":7412809}]}]}
{"op":"mcm","clk":"1009228073","pt":1580642876324,"mc":[{"id":"1.168217554","rc":[{"batl":[[0,4.1,2],[1,4.6,2.01],[2,6.6,98.95]],"ltp":3.35,"tv":1923.21,"id":7412809}]}]}
{"op":"mcm","clk":"1009228339","pt":1580642878031,"mc":[{"id":"1.168217554","rc":[{"trd":[[4.1,4]],"batb":[[0,4.5,6.44],[1,3.6,10.04],[2,3.55,61.06]],"batl":[[0,4.6,2.01],[1,6.6,98.95],[2,1000,0.02]],"ltp":4.1,"tv":1927.21,"id":7412809}],"tv":17763.24}]}
{"op":"mcm","clk":"1009228773","pt":1580642881209,"mc":[{"id":"1.168217554","rc":[{"batb":[[0,1.28,55.41],[1,1.26,339.98],[2,1.11,37.96]],"batl":[[1,1.38,79.25],[2,3,42.02]],"ltp":1.3,"tv":15836.03,"id":2263624},{"trd":[[4.5,12.88]],"batb":[[0,3.6,10.04],[1,3.55,61.06],[2,2.52,381.46]],"ltp":4.5,"tv":1940.1,"id":7412809}],"tv":17776.13}]}
{"op":"mcm","clk":"1009229070","pt":1580642883428,"mc":[{"id":"1.168217554","rc":[{"batl":[[1,1.36,83.82],[2,1.38,79.25]],"ltp":1.3,"tv":15836.03,"id":2263624},{"batb":[[0,3.75,10.03],[1,3.6,10.04],[2,3.55,61.06]],"ltp":4.5,"tv":1940.1,"id":7412809}]}]}
{"op":"mcm","clk":"1009229139","pt":1580642883823,"mc":[{"id":"1.168217554","rc":[{"batl":[[1,1.38,79.25],[2,3,42.02]],"ltp":1.3,"tv":15836.03,"id":2263624},{"batb":[[0,3.6,10.04],[1,3.55,61.06],[2,2.52,381.46]],"ltp":4.5,"tv":1940.1,"id":7412809}]}]}
{"op":"mcm","clk":"1009229249","pt":1580642884538,"mc":[{"id":"1.168217554","rc":[{"batb":[[0,1.31,386.05],[1,1.3,505.57],[2,1.28,55.41]],"batl":[[0,1.34,471.62],[1,1.35,404.22],[2,1.38,79.25]],"ltp":1.3,"tv":15836.03,"id":2263624}]}]}
{"op":"mcm","clk":"1009229617","pt":1580642886875,"mc":[{"id":"1.168217554","rc":[{"batl":[[2,1.36,83.82]],"ltp":1.3,"tv":15836.03,"id":2263624},{"batb":[[0,3.75,10.03],[1,3.6,10.04],[2,3.55,61.06]],"ltp":4.5,"tv":1940.1,"id":7412809}]}]}
{"op":"mcm","clk":"1009229822","pt":1580642888362,"mc":[{"id":"1.168217554","rc":[{"batb":[[0,1.28,55.41],[1,1.26,339.98],[2,1.11,37.96]],"batl":[[0,1.34,2.27],[1,1.38,79.25],[2,3,42.02]],"ltp":1.3,"tv":15836.03,"id":2263624},{"batb":[[0,3.6,10.04],[1,3.55,61.06],[2,2.52,381.46]],"ltp":4.5,"tv":1940.1,"id":7412809}]}]}
{"op":"mcm","clk":"1009230172","pt":1580642890941,"mc":[{"id":"1.168217554","rc":[{"batb":[[0,1.28,347.53],[1,1.27,573.75],[2,1.26,339.98]],"batl":[[1,1.38,470.6],[2,1.39,353.72]],"ltp":1.3,"tv":15836.03,"id":2263624}]}]}
{"op":"mcm","clk":"1009231147","pt":1580642898356,"mc":[{"id":"1.168217554","rc":[{"batl":[[1,1.36,83.82],[2,1.38,470.6]],"ltp":1.3,"tv":15836.03,"id":2263624},{"batb":[[0,3.75,10.03],[1,3.6,10.04],[2,3.55,61.06]],"ltp":4.5,"tv":1940.1,"id":7412809}]}]}
{"op":"mcm","clk":"1009231179","pt":1580642898542,"mc":[{"id":"1.168217554","rc":[{"batl":[[1,1.38,470.6],[2,1.39,353.72]],"ltp":1.3,"tv":15836.03,"id":2263624},{"batb":[[0,3.6,10.04],[1,3.55,61.06],[2,2.52,381.46]],"ltp":4.5,"tv":1940.1,"id":7412809}]}]}
{"op":"mcm","clk":"1009232104","pt":1580642905255,"mc":[{"id":"1.168217554","rc":[{"batl":[[1,1.36,83.82],[2,1.38,470.6]],"ltp":1.3,"tv":15836.03,"id":2263624},{"batb":[[0,3.75,10.03],[1,3.6,10.04],[2,3.55,61.06]],"ltp":4.5,"tv":1940.1,"id":7412809}]}]}
{"op":"mcm","clk":"1009232140","pt":1580642905600,"mc":[{"id":"1.168217554","rc":[{"batl":[[1,1.38,470.6],[2,1.39,353.72]],"ltp":1.3,"tv":15836.03,"id":2263624},{"batb":[[0,3.6,10.04],[1,3.55,61.06],[2,2.52,381.46]],"ltp":4.5,"tv":1940.1,"id":7412809}]}]}
{"op":"mcm","clk":"1009232712","pt":1580642909637,"mc":[{"id":"1.168217554","rc":[{"batl":[[1,1.38,79.25],[2,3,42.02]],"ltp":1.3,"tv":15836.03,"id":2263624}]}]}
{"op":"mcm","clk":"1009233087","pt":1580642912253,"mc":[{"id":"1.168217554","rc":[{"trd":[[1.28,1941.12]],"batb":[[0,1.28,1134.78]],"batl":[[0,1.29,15.72],[1,1.3,1238],[2,1.31,1717.56]],"ltp":1.28,"tv":17777.15,"id":2263624},{"batb":[[0,3.75,10.03],[1,3.6,10.04],[2,3.55,61.06]],"batl":[[1,4.7,7.73],[2,5.1,302]],"ltp":4.5,"tv":1940.1,"id":7412809}],"tv":19717.25}]}
{"op":"mcm","clk":"1009233268","pt":1580642913453,"mc":[{"id":"1.168217554","rc":[{"batl":[[1,1.3,1577.23],[2,1.31,2191.28]],"ltp":1.28,"tv":17777.15,"id":2263624},{"batb":[[0,4.3,10.08],[1,4.2,81.28],[2,4,2.59]],"ltp":4.5,"tv":1940.1,"id":7412809}]}]}
{"op":"mcm","clk":"1009233386","pt":1580642914258,"mc":[{"id":"1.168217554","rc":[{"trd":[[1.29,1]],"batl":[[0,1.29,15.22],[2,1.31,2233.29]],"ltp":1.29,"tv":17778.15,"id":2263624},{"batb":[[1,4.2,93.88]],"batl":[[2,5,10.08]],"ltp":4.5,"tv":1940.1,"id":7412809}],"tv":19718.25}]}
{"op":"mcm","clk":"1009233687","pt":1580642916265,"mc":[{"id":"1.168217554","rc":[{"batb":[[1,1.27,705.55],[2,1.26,953.01]],"batl":[[1,1.3,1736.22]],"ltp":1.29,"tv":17778.15,"id":2263624}]}]}
{"op":"mcm","clk":"1009234083","pt":1580642918988,"mc":[{"id":"1.168217554","rc":[{"batb":[[2,1.26,1455.45]],"batl":[[1,1.3,2225.21],[2,1.31,2739.09]],"ltp":1.29,"tv":17778.15,"id":2263624}]}]}
{"op":"mcm","clk":"1009234216","pt":1580642919882,"mc":[{"id":"1.168217554","rc":[{"batb":[[1,1.27,779.42],[2,1.26,1520.93]],"ltp":1.29,"tv":17778.15,"id":2263624},{"batb":[[2,4.1,12.54]],"batl":[[2,4.8,2]],"ltp":4.5,"tv":1940.1,"id":7412809}]}]}
{"op":"mcm","clk":"1009234921","pt":1580642924482,"mc":[{"id":"1.168217554","rc":[{"batl":[[0,1.3,2225.21],[1,1.31,2739.09],[2,1.32,117.61]],"ltp":1.29,"tv":17778.15,"id":2263624},{"batl":[[1,4.8,2],[2,4.9,2]],"ltp":4.5,"tv":1940.1,"id":7412809}]}]}
{"op":"mcm","clk":"1009235359","pt":1580642927465,"mc":[{"id":"1.168217554","rc":[{"batl":[[0,1.29,15.22],[1,1.3,987.21],[2,1.31,2739.09]],"ltp":1.29,"tv":17778.15,"id":2263624},{"batl":[[1,4.7,7.87],[2,4.8,2]],"ltp":4.5,"tv":1940.1,"id":7412809}]}]}
{"op":"mcm","clk":"1009235437","pt":1580642927998,"mc":[{"id":"1.168217554","rc":[{"batb":[[0,1.26,871.29],[1,1.25,687.28],[2,1.24,374.13]],"batl":[[0,1.3,488.99],[1,1.31,547.81],[2,1.32,117.61]],"ltp":1.29,"tv":17778.15,"id":2263624},{"batb":[[0,4.2,12.6],[1,4.1,12.54],[2,4,2.59]],"batl":[[0,4.9,2],[1,5,10.08],[2,7.8,87.91]],"ltp":4.5,"tv":1940.1,"id":7412809}]}]}
{"op":"mcm","clk":"1009235558","pt":1580642928786,"mc":[{"id":"1.168217554","rc":[{"batb":[[1,1.25,519.24]],"batl":[[1,1.31,505.8]],"ltp":1.29,"tv":17778.15,"id":2263624},{"batb":[[0,4.1,12.54],[1,4,2.59],[2,3.9,12.56]],"batl":[[1,7.8,87.91],[2,1000,0.02]],"ltp":4.5,"tv":1940.1,"id":7412809}]}]}
{"op":"mcm","clk":"1009235660","pt":1580642929579,"mc":[{"id":"1.168217554","rc":[{"batb":[[1,4,15.31]],"ltp":4.5,"tv":1940.1,"id":7412809}]}]}
{"op":"mcm","clk":"1009235928","pt":1580642931511,"mc":[{"id":"1.168217554","rc":[{"batb":[[1,1.25,1153.16]],"ltp":1.29,"tv":17778.15,"id":2263624}]}]}
{"op":"mcm","clk":"1009236744","pt":1580642936798,"mc":[{"id":"1.168217554","rc":[{"batb":[[0,1.26,368.85],[1,1.25,633.92]],"ltp":1.29,"tv":17778.15,"id":2263624}]}]}
{"op":"mcm","clk":"1009237005","pt":1580642938398,"mc":[{"id":"1.168217554","rc":[{"batl":[[1,1000,0.02],[2,1000,0]],"ltp":4.5,"tv":1940.1,"id":7412809}]}]}
{"op":"mcm","clk":"1009237144","pt":1580642939413,"mc":[{"id":"1.168217554","rc":[{"batb":[[1,1.25,649.01]],"batl":[[0,1.27,18.89],[1,1.28,1803.54],[2,1.29,665.74]],"ltp":1.29,"tv":17778.15,"id":2263624},{"batb":[[0,4.5,12.56],[1,4.4,721.33],[2,4.1,12.54]],"batl":[[1,5,3.77],[2,5.3,255.5]],"ltp":4.5,"tv":1940.1,"id":7412809}]}]}
{"op":"mcm","clk":"1009237298","pt":1580642940422,"mc":[{"id":"1.168217554","rc":[{"batl":[[2,1.29,707.75]],"ltp":1.29,"tv":17778.15,"id":2263624},{"batb":[[0,4.5,83.22],[1,4.4,733.09],[2,4.1,99.48]],"batl":[[2,5.3,264.74]],"ltp":4.5,"tv":1940.1,"id":7412809}]}]}
{"op":"mcm","clk":"1009238258","pt":1580642945900,"mc":[{"id":"1.168217554","rc":[{"batb":[[2,1.24,876.57]],"batl":[[1,1.28,2292.53],[2,1.29,1213.55]],"ltp":1.29,"tv":17778.15,"id":2263624}]}]}
{"op":"mcm","clk":"1009238640","pt":1580642948229,"mc":[{"id":"1.168217554","rc":[{"batb":[[1,1.25,718.06],[2,1.24,957.84]],"batl":[[2,1.29,1336.05]],"ltp":1.29,"tv":17778.15,"id":2263624},{"batb":[[1,4.4,744.95],[2,4.3,11.88]],"batl":[[1,5,5.77],[2,5.2,2]],"ltp":4.5,"tv":1940.1,"id":7412809}]}]}
{"op":"mcm","clk":"1009238985","pt":1580642950430,"mc":[{"id":"1.168217554","rc":[{"batb":[[0,1.24,583.71],[1,1.23,1083.84],[2,1.11,37.96]],"batl":[[0,1.28,623.33],[1,1.29,670.31],[2,1.3,118.45]],"ltp":1.29,"tv":17778.15,"id":2263624},{"batb":[[0,4.5,12.56],[1,4.4,23.62]],"batl":[[0,5.2,2],[1,5.3,9.24],[2,8.6,81.89]],"ltp":4.5,"tv":1940.1,"id":7412809}]}]}
{"op":"mcm","clk":"1009239051","pt":1580642950758,"mc":[{"id":"1.168217554","rc":[{"batb":[[1,1.23,915.8]],"batl":[[1,1.29,628.3]],"ltp":1.29,"tv":17778.15,"id":2263624},{"batb":[[1,4.4,11.86]],"batl":[[1,8.6,81.89],[2,1000,0.02]],"ltp":4.5,"tv":1940.1,"id":7412809}]}]}
{"op":"mcm","clk":"1009239437","pt":1580642953438,"mc":[{"id":"1.168217554","rc":[{"batb":[[0,1.25,76.73],[1,1.24,1458.12],[2,1.23,1606.73]],"batl":[[0,1.28,488.99]],"ltp":1.29,"tv":17778.15,"id":2263624},{"batb":[[0,4.4,11.86],[1,4.3,11.88],[2,4.1,98.78]],"batl":[[0,5,2],[1,5.2,2],[2,8.6,81.89]],"ltp":4.5,"tv":1940.1,"id":7412809}]}]}
{"op":"mcm","clk":"1009239486","pt":1580642953753,"mc":[{"id":"1.168217554","rc":[{"batb":[[0,1.24,1458.12],[1,1.23,1606.73],[2,1.11,37.96]],"ltp":1.29,"tv":17778.15,"id":2263624},{"batl":[[0,5.2,2],[1,8.6,81.89],[2,1000,0.02]],"ltp":4.5,"tv":1940.1,"id":7412809}]}]}
{"op":"mcm","clk":"1009239718","pt":1580642955352,"mc":[{"id":"1.168217554","rc":[{"batb":[[0,1.24,583.71],[1,1.23,915.8]],"batl":[[0,1.3,118.45],[1,1.31,498.82],[2,1.32,571.53]],"ltp":1.29,"tv":17778.15,"id":2263624},{"batb":[[0,4.3,11.88],[1,4.1,98.78],[2,4,12.72]],"batl":[[1,1000,0.02],[2,1000,0]],"ltp":4.5,"tv":1940.1,"id":7412809}]}]}
{"op":"mcm","clk":"1009240045","pt":1580642957258,"mc":[{"id":"1.168217554","rc":[{"batb":[[0,1.28,1757.81],[1,1.24,583.71],[2,1.23,915.8]],"batl":[[0,1.3,131.72],[1,1.31,3370.38]],"ltp":1.29,"tv":17778.15,"id":2263624},{"batb":[[0,4.3,240.07]],"batl":[[0,4.5,4.85],[1,4.8,221.21],[2,4.9,255]],"ltp":4.5,"tv":1940.1,"id":7412809}]}]}
{"op":"mcm","clk":"1009240256","pt":1580642958332,"mc":[{"id":"1.168217554","rc":[{"batb":[[0,1.28,2288.55],[1,1.27,908.05],[2,1.25,529.35]],"batl":[[2,1.32,613.54]],"ltp":1.29,"tv":17778.15,"id":2263624},{"batb":[[0,4.3,242.73],[1,4.1,112.22]],"batl":[[2,4.9,265.08]],"ltp":4.5,"tv":1940.1,"id":7412809}]}]}
{"op":"mcm","clk":"1009241133","pt":1580642963485,"mc":[{"id":"1.168217554","rc":[{"batl":[[2,1.32,613.62]],"ltp":1.29,"tv":17778.15,"id":2263624}]}]}
{"op":"mcm","clk":"1009241203","pt":1580642963968,"mc":[{"id":"1.168217554","rc":[{"batb":[[2,1.26,502.44]],"batl":[[1,1.31,3859.37],[2,1.32,1119.42]],"ltp":1.29,"tv":17778.15,"id":2263624}]}]}
{"op":"mcm","clk":"1009241324","pt":1580642964659,"mc":[{"id":"1.168217554","rc":[{"batb":[[1,1.27,973.92],[2,1.26,579.92]],"ltp":1.29,"tv":17778.15,"id":2263624},{"batl":[[1,4.8,223.21],[2,4.9,267.08]],"ltp":4.5,"tv":1940.1,"id":7412809}]}]}
{"op":"mcm","clk":"1009242603","pt":1580642973399,"mc":[{"id":"1.168217554","rc":[{"batb":[[0,1.27,392.09],[1,1.26,579.92],[2,1.25,1048.59]],"batl":[[0,1.31,488.99],[1,1.32,547.89],[2,1.33,115.5]],"ltp":1.29,"tv":17778.15,"id":2263624},{"batb":[[0,4.3,2.66],[1,4.1,99.68]],"batl":[[0,4.8,2],[1,4.9,12.08],[2,5.2,2]],"ltp":4.5,"tv":1940.1,"id":7412809}]}]}
{"op":"mcm","clk":"1009242669","pt":1580642973773,"mc":[{"id":"1.168217554","rc":[{"batb":[[0,1.26,579.92],[1,1.25,1048.59],[2,1.24,81.27]],"ltp":1.29,"tv":17778.15,"id":2263624},{"batb":[[1,4.1,13.44]],"batl":[[0,4.9,12.08],[1,5.2,2],[2,7.2,92.18]],"ltp":4.5,"tv":1940.1,"id":7412809}]}]}
{"op":"mcm","clk":"1009242820","pt":1580642974862,"mc":[{"id":"1.168217554","rc":[{"batb":[[1,1.25,880.55]],"batl":[[1,1.32,505.88]],"ltp":1.29,"tv":17778.15,"id":2263624},{"batb":[[1,4,12.72],[2,3.9,12.56]],"batl":[[0,4.9,2]],"ltp":4.5,"tv":1940.1,"id":7412809}]}]}
{"op":"mcm","clk":"1009243196","pt":1580642977468,"mc":[{"id":"1.168217554","rc":[{"batb":[[0,1.27,71.87],[1,1.26,579.92],[2,1.25,880.55]],"ltp":1.29,"tv":17778.15,"id":2263624},{"batl":[[0,4.8,2],[1,4.9,2],[2,5.2,2]],"ltp":4.5,"tv":1940.1,"id":7412809}]}]}
{"op":"mcm","clk":"1009243315","pt":1580642978317,"mc":[{"id":"1.168217554","rc":[{"batb":[[0,1.29,429.82],[1,1.28,554.48],[2,1.26,579.92]],"batl":[[1,1.32,1042.32],[2,1.33,551.89]],"ltp":1.29,"tv":17778.15,"id":2263624},{"batl":[[0,4.9,2],[1,5.2,2],[2,7.2,92.18]],"ltp":4.5,"tv":1940.1,"id":7412809}]}]}
{"op":"mcm","clk":"1009243733","pt":1580642980889,"mc":[{"id":"1.168217554","rc":[{"batb":[[2,1.27,60.87]],"ltp":1.29,"tv":17778.15,"id":2263624},{"batl":[[0,4.8,2],[1,4.9,2],[2,5.2,2]],"ltp":4.5,"tv":1940.1,"id":7412809}]}]}
{"op":"mcm","clk":"1009243948","pt":1580642982274,"mc":[{"id":"1.168217554","rc":[{"batb":[[0,1.26,579.92],[1,1.25,880.55],[2,1.24,81.27]],"batl":[[1,1.32,505.88],[2,1.33,115.5]],"ltp":1.29,"tv":17778.15,"id":2263624},{"batl":[[0,4.9,2],[1,5.2,2],[2,7.2,92.18]],"ltp":4.5,"tv":1940.1,"id":7412809}]}]}
{"op":"mcm","clk":"1009244118","pt":1580642983397,"mc":[{"id":"1.168217554","rc":[{"batl":[[2,1.33,119.28]],"ltp":1.29,"tv":17778.15,"id":2263624}]}]}
{"op":"mcm","clk":"1009244151","pt":1580642983562,"mc":[{"id":"1.168217554","rc":[{"batl":[[2,1.33,117.68]],"ltp":1.29,"tv":17778.15,"id":2263624}]}]}
{"op":"mcm","clk":"1009244437","pt":1580642985490,"mc":[{"id":"1.168217554","rc":[{"batb":[[0,1.26,1096.86],[1,1.25,1519.33]],"ltp":1.29,"tv":17778.15,"id":2263624},{"batl":[[0,4.8,2],[1,4.9,2],[2,5.2,2]],"ltp":4.5,"tv":1940.1,"id":7412809}]}]}
{"op":"mcm","clk":"1009244588","pt":1580642986396,"mc":[{"id":"1.168217554","rc":[{"batb":[[0,4,12.72],[1,3.9,12.56],[2,3.85,12.97]],"batl":[[0,4.9,2],[1,5.2,2],[2,7.2,92.18]],"ltp":4.5,"tv":1940.1,"id":7412809}]}]}
{"op":"mcm","clk":"1009245090","pt":1580642989495,"mc":[{"id":"1.168217554","rc":[{"batb":[[0,1.26,579.92],[1,1.25,880.55]],"batl":[[0,1.33,2.27],[1,1.35,110.18],[2,1.36,605.4]],"ltp":1.29,"tv":17778.15,"id":2263624},{"batb":[[0,3.85,12.97],[1,3.65,56.65],[2,3.6,10.04]],"ltp":4.5,"tv":1940.1,"id":7412809}]}]}
{"op":"mcm","clk":"1009245252","pt":1580642990571,"mc":[{"id":"1.168217554","rc":[{"batl":[[2,1000,0.02]],"ltp":4.5,"tv":1940.1,"id":7412809}]}]}
{"op":"mcm","clk":"1009245515","pt":1580642992279,"mc":[{"id":"1.168217554","rc":[{"trd":[[1.32,1000.34],[1.33,37.97]],"batb":[[0,1.33,1672.67],[1,1.32,621.74],[2,1.31,491.72]],"batl":[[0,1.35,110.18],[1,1.36,4088.87],[2,1.37,377.43]],"ltp":1.33,"tv":17816.28,"id":2263624},{"batl":[[0,4,7.08],[1,4.3,622.45],[2,4.9,2]],"ltp":4.5,"tv":1940.1,"id":7412809}],"tv":19756.38}]}
{"op":"mcm","clk":"1009245612","pt":1580642992962,"mc":[{"id":"1.168217554","rc":[{"batb":[[1,1.32,887.68]],"ltp":1.33,"tv":17816.28,"id":2263624}]}]}
{"op":"mcm","clk":"1009245836","pt":1580642994508,"mc":[{"id":"1.168217554","rc":[{"batl":[[2,1.37,419.44]],"ltp":1.33,"tv":17816.28,"id":2263624},{"batb":[[1,3.75,15.12],[2,3.65,56.65]],"batl":[[2,4.4,11.76]],"ltp":4.5,"tv":1940.1,"id":7412809}]}]}
{"op":"mcm","clk":"1009246484","pt":1580642998421,"mc":[{"id":"1.168217554","rc":[{"batl":[[2,1.37,900.03]],"ltp":1.33,"tv":17816.28,"id":2263624}]}]}
{"op":"mcm","clk":"1009247922","pt":1580643007495,"mc":[{"id":"1.168217554","rc":[{"trd":[[1.33,53.11]],"batb":[[0,1.33,1665.1]],"ltp":1.33,"tv":17831.42,"id":2263624}],"tv":19771.53}]}
{"op":"mcm","clk":"1009248225","pt":1580643009440,"mc":[{"id":"1.168217554","rc":[{"batb":[[0,1.32,887.68],[1,1.31,491.72],[2,1.3,494.03]],"batl":[[1,1.36,605.4]],"ltp":1.33,"tv":17831.42,"id":2263624},{"batl":[[0,4.4,11.76],[1,4.9,2],[2,6,106.18]],"ltp":4.5,"tv":1940.1,"id":7412809}]}]}
{"op":"mcm","clk":"1009248258","pt":1580643009613,"mc":[{"id":"1.168217554","rc":[{"batb":[[0,1.3,494.03],[1,1.29,144.51],[2,1.28,827.38]],"batl":[[0,1.37,522.69],[1,1.39,497.4],[2,1.44,98.08]],"ltp":1.33,"tv":17831.42,"id":2263624},{"batb":[[0,3.75,15.12],[1,3.45,2.58],[2,3.25,14.37]],"ltp":4.5,"tv":1940.1,"id":7412809}]}]}
{"op":"mcm","clk":"1009248459","pt":1580643010835,"mc":[{"id":"1.168217554","rc":[{"batb":[[1,1.28,827.38],[2,1.26,77.48]],"batl":[[0,1.37,480.68]],"ltp":1.33,"tv":17831.42,"id":2263624},{"batb":[[0,3.45,2.58],[1,3.25,14.37],[2,3.1,99.73]],"batl":[[0,4.9,2],[1,6,106.18],[2,1000,0.02]],"ltp":4.5,"tv":1940.1,"id":7412809}]}]}
{"op":"mcm","clk":"1009248729","pt":1580643012623,"mc":[{"id":"1.168217554","rc":[{"batb":[[1,1.28,1499.41],[2,1.27,584.65]],"ltp":1.33,"tv":17831.42,"id":2263624}]}]}
{"op":"mcm","clk":"1009248860","pt":1580643013548,"mc":[{"id":"1.168217554","rc":[{"batb":[[0,1.28,988.57],[1,1.27,584.65],[2,1.26,77.48]],"ltp":1.33,"tv":17831.42,"id":2263624}]}]}
{"op":"mcm","clk":"1009249342","pt":1580643016507,"mc":[{"id":"1.168217554","rc":[{"batb":[[0,1.29,20.54],[1,1.28,2746.38],[2,1.27,584.65]],"batl":[[0,1.31,3395.47],[1,1.37,480.68],[2,1.39,497.4]],"ltp":1.33,"tv":17831.42,"id":2263624},{"batb":[[0,4.2,14.22],[1,3.45,2.58],[2,3.25,14.37]],"batl":[[0,4.8,555.03],[1,4.9,2],[2,6,106.18]],"ltp":4.5,"tv":1940.1,"id":7412809}]}]}
{"op":"mcm","clk":"1009249525","pt":1580643017517,"mc":[{"id":"1.168217554","rc":[{"batl":[[0,1.31,3763.62],[1,1.32,456.09],[2,1.37,480.68]],"ltp":1.33,"tv":17831.42,"id":2263624},{"batb":[[1,4,90.09],[2,3.55,60.59]],"ltp":4.5,"tv":1940.1,"id":7412809}]}]}
{"op":"mcm","clk":"1009249556","pt":1580643017733,"mc":[{"id":"1.168217554","rc":[{"batl":[[2,1.33,42.01]],"ltp":1.33,"tv":17831.42,"id":2263624},{"batb":[[1,4,103.53]],"batl":[[1,4.9,12.08]],"ltp":4.5,"tv":1940.1,"id":7412809}]}]}
{"op":"mcm","clk":"1009250619","pt":1580643024246,"mc":[{"id":"1.168217554","rc":[{"batb":[[2,1.27,862.61]],"ltp":1.33,"tv":17831.42,"id":2263624},{"batb":[[2,3.9,13.06]],"batl":[[0,4.8,557.03]],"ltp":4.5,"tv":1940.1,"id":7412809}]}]}
{"op":"mcm","clk":"1009250702","pt":1580643024633,"mc":[{"id":"1.168217554","rc":[{"batb":[[1,1.28,2840.48]],"ltp":1.33,"tv":17831.42,"id":2263624}]}]}
{"op":"mcm","clk":"1009250981","pt":1580643026343,"mc":[{"id":"1.168217554","rc":[{"batb":[[0,1.28,94.1],[1,1.27,277.96],[2,1.26,238.8]],"batl":[[0,1.31,137.5],[1,1.33,42.01],[2,1.34,115.33]],"ltp":1.33,"tv":17831.42,"id":2263624},{"batb":[[1,4,13.44]],"batl":[[0,4.8,2]],"ltp":4.5,"tv":1940.1,"id":7412809}]}]}
{"op":"mcm","clk":"1009251050","pt":1580643026759,"mc":[{"id":"1.168217554","rc":[{"batb":[[2,1.26,77.48]],"batl":[[1,1.36,108.9],[2,1.44,98.08]],"ltp":1.33,"tv":17831.42,"id":2263624},{"batb":[[1,3.75,13.07],[2,3.55,60.59]],"batl":[[1,4.9,2]],"ltp":4.5,"tv":1940.1,"id":7412809}]}]}
{"op":"mcm","clk":"1009251309","pt":1580643028249,"mc":[{"id":"1.168217554","rc":[{"batb":[[0,1.27,277.96],[1,1.26,77.48],[2,1.25,354.07]],"ltp":1.33,"tv":17831.42,"id":2263624}]}]}
{"op":"mcm","clk":"1009251443","pt":1580643029051,"mc":[{"id":"1.168217554","rc":[{"batb":[[1,1.26,547.02],[2,1.25,991.77]],"batl":[[1,1.36,372.75],[2,1.37,381.85]],"ltp":1.33,"tv":17831.42,"id":2263624}]}]}
{"op":"mcm","clk":"1009251593","pt":1580643029965,"mc":[{"id":"1.168217554","rc":[{"batl":[[0,1.36,372.75],[1,1.37,381.85],[2,1.44,98.08]],"ltp":1.33,"tv":17831.42,"id":2263624},{"batb":[[0,3.75,13.07],[1,3.55,60.59],[2,3.25,14.37]],"ltp":4.5,"tv":1940.1,"id":7412809}]}]}
{"op":"mcm","clk":"1009251978","pt":1580643032159,"mc":[{"id":"1.168217554","rc":[{"batb":[[0,1.27,215.09]],"batl":[[0,1.36,108.9],[1,1.44,98.08],[2,1.47,92.5]],"ltp":1.33,"tv":17831.42,"id":2263624},{"batl":[[0,4.9,2],[1,6,106.18],[2,1000,0.02]],"ltp":4.5,"tv":1940.1,"id":7412809}]}]}
{"op":"mcm","clk":"1009252178","pt":1580643033337,"mc":[{"id":"1.168217554","rc":[{"batb":[[0,1.26,547.02],[1,1.25,991.77],[2,1.11,37.96]],"ltp":1.33,"tv":17831.42,"id":2263624}]}]}
{"op":"mcm","clk":"1009252348","pt":1580643034477,"mc":[{"id":"1.168217554","rc":[{"batb":[[0,1.26,2332.73]],"batl":[[0,1.28,711.93],[1,1.29,2979.19],[2,1.36,108.9]],"ltp":1.33,"tv":17831.42,"id":2263624},{"batl":[[0,4.8,5.86],[1,4.9,2],[2,5.1,219.85]],"ltp":4.5,"tv":1940.1,"id":7412809}]}]}
{"op":"mcm","clk":"1009252437","pt":1580643034963,"mc":[{"id":"1.168217554","rc":[{"batl":[[1,1.29,3794.48],[2,1.3,487.94]],"ltp":1.33,"tv":17831.42,"id":2263624},{"batb":[[0,4.4,13.06],[1,3.75,13.07],[2,3.55,60.59]],"ltp":4.5,"tv":1940.1,"id":7412809}]}]}
{"op":"mcm","clk":"1009252602","pt":1580643035970,"mc":[{"id":"1.168217554","rc":[{"batb":[[2,1.23,571.91]],"batl":[[1,1.29,3836.49]],"ltp":1.33,"tv":17831.42,"id":2263624},{"batb":[[0,4.4,27.38],[1,4.3,76.56],[2,4.1,86.08]],"ltp":4.5,"tv":1940.1,"id":7412809}]}]}
{"op":"mcm","clk":"1009253937","pt":1580643043793,"mc":[{"id":"1.168217554","rc":[{"batb":[[1,1.25,1067.62],[2,1.24,72.52]],"ltp":1.33,"tv":17831.42,"id":2263624},{"batl":[[2,5,2]],"ltp":4.5,"tv":1940.1,"id":7412809}]}]}
{"op":"mcm","clk":"1009254978","pt":1580643050390,"mc":[{"id":"1.168217554","rc":[{"trd":[[1.26,667.58],[1.28,2302.4]],"batb":[[0,1.26,1998.94]],"batl":[[0,1.28,531.29],[1,1.29,3675.38],[2,1.36,108.9]],"ltp":1.28,"tv":18860.29,"id":2263624}],"tv":20800.39}]}
{"op":"mcm","clk":"1009255283","pt":1580643052168,"mc":[{"id":"1.168217554","rc":[{"batl":[[2,1.31,251.22]],"ltp":1.28,"tv":18860.29,"id":2263624}]}]}
{"op":"mcm","clk":"1009255414","pt":1580643053067,"mc":[{"id":"1.168217554","rc":[{"batb":[[0,1.26,2113.61]],"batl":[[0,1.28,833.11]],"ltp":1.28,"tv":18860.29,"id":2263624}]}]}
{"op":"mcm","clk":"1009255825","pt":1580643055455,"mc":[{"id":"1.168217554","rc":[{"batb":[[0,1.26,1785.71],[1,1.25,75.85]],"batl":[[0,1.29,1921.7],[1,1.31,251.22],[2,1.36,108.9]],"ltp":1.28,"tv":18860.29,"id":2263624},{"batb":[[0,4.4,14.32],[1,4.1,86.08],[2,3.75,13.07]],"batl":[[0,5,2],[1,5.2,2],[2,5.3,9.24]],"ltp":4.5,"tv":1940.1,"id":7412809}]}]}
{"op":"mcm","clk":"1009255896","pt":1580643055887,"mc":[{"id":"1.168217554","rc":[{"batb":[[0,1.24,72.52],[1,1.23,571.91],[2,1.16,233.67]],"batl":[[0,1.29,177.51]],"ltp":1.28,"tv":18860.29,"id":2263624},{"batl":[[0,5.2,2],[1,5.3,9.24],[2,7.8,87.91]],"ltp":4.5,"tv":1940.1,"id":7412809}]}]}
{"op":"mcm","clk":"1009256027","pt":1580643056800,"mc":[{"id":"1.168217554","rc":[{"batb":[[1,1.23,403.87]],"batl":[[0,1.29,135.5]],"ltp":1.28,"tv":18860.29,"id":2263624},{"batb":[[0,4.4,2.55]],"batl":[[1,7.8,87.91],[2,1000,0.02]],"ltp":4.5,"tv":1940.1,"id":7412809}]}]}
{"op":"mcm","clk":"1009256277","pt":1580643058365,"mc":[{"id":"1.168217554","rc":[{"batb":[[1,1.23,1215.45],[2,1.22,756.83]],"batl":[[1,1.3,455.97],[2,1.31,726.47]],"ltp":1.28,"tv":18860.29,"id":2263624},{"batb":[[0,4.4,18.81]],"ltp":4.5,"tv":1940.1,"id":7412809}]}]}
{"op":"mcm","clk":"1009256591","pt":1580643060198,"mc":[{"id":"1.168217554","rc":[{"batb":[[1,1.23,403.87],[2,1.16,233.67]],"ltp":1.28,"tv":18860.29,"id":2263624}]}]}
{"op":"mcm","clk":"1009256962","pt":1580643062504,"mc":[{"id":"1.168217554","rc":[{"batb":[[0,1.25,70.89],[1,1.24,72.52],[2,1.23,403.87]],"ltp":1.28,"tv":18860.29,"id":2263624},{"batb":[[0,4.4,16.26]],"batl":[[0,5,2],[1,5.2,2]],"ltp":4.5,"tv":1940.1,"id":7412809}]}]}
{"op":"mcm","clk":"1009257058","pt":1580643063203,"mc":[{"id":"1.168217554","rc":[{"batb":[[0,1.27,2422.66],[1,1.26,614.87],[2,1.24,72.52]],"batl":[[1,1.3,2186.74],[2,1.31,1917.47]],"ltp":1.28,"tv":18860.29,"id":2263624},{"trd":[[4.4,7.5]],"batb":[[0,4.4,12.51],[1,4.3,222.08],[2,4.1,86.08]],"batl":[[0,4.8,259.94],[1,4.9,244],[2,5.2,2]],"ltp":4.4,"tv":1947.6,"id":7412809}],"tv":20807.89}]}
{"op":"mcm","clk":"1009257220","pt":1580643064208,"mc":[{"id":"1.168217554","rc":[{"batb":[[0,1.27,2749.27],[2,1.24,609.34]],"batl":[[2,1.31,1959.48]],"ltp":1.28,"tv":18860.29,"id":2263624},{"batb":[[2,4.2,12.6]],"batl":[[2,5,10.08]],"ltp":4.4,"tv":1947.6,"id":7412809}]}]}
{"op":"mcm","clk":"1009257598","pt":1580643066480,"mc":[{"id":"1.168217554","rc":[{"batl":[[2,1.31,1978.38]],"ltp":1.28,"tv":18860.29,"id":2263624},{"trd":[[4.4,15]],"batb":[[0,4.4,8.76]],"ltp":4.4,"tv":1955.1,"id":7412809}],"tv":20815.39}]}
{"op":"mcm","clk":"1009257845","pt":1580643067976,"mc":[{"id":"1.168217554","rc":[{"batb":[[2,1.25,233.57]],"ltp":1.28,"tv":18860.29,"id":2263624}]}]}
{"op":"mcm","clk":"1009258026","pt":1580643069309,"mc":[{"id":"1.168217554","rc":[{"batb":[[0,1.27,2098.26],[1,1.25,233.57],[2,1.24,609.34]],"batl":[[0,1.3,1730.77],[1,1.31,293.23],[2,1.36,108.9]],"ltp":1.28,"tv":18860.29,"id":2263624},{"batb":[[0,4.2,12.6],[1,4.1,86.08],[2,3.95,94.34]],"batl":[[0,5,10.08],[1,5.2,2],[2,7.2,92.18]],"ltp":4.4,"tv":1955.1,"id":7412809}]}]}
{"op":"mcm","clk":"1009258176","pt":1580643070291,"mc":[{"id":"1.168217554","rc":[{"batb":[[0,1.26,574.42],[1,1.25,752.81]],"batl":[[0,1.3,152.35],[1,1.31,782.22],[2,1.32,505.8]],"ltp":1.28,"tv":18860.29,"id":2263624},{"batb":[[0,4.3,15.28],[1,4.2,12.6]],"batl":[[0,4.9,2],[1,5,10.08],[2,5.2,2]],"ltp":4.4,"tv":1955.1,"id":7412809}]}]}
{"op":"mcm","clk":"1009258277","pt":1580643070890,"mc":[{"id":"1.168217554","rc":[{"batb":[[2,1.24,441.3]],"batl":[[1,1.31,740.21]],"ltp":1.28,"tv":18860.29,"id":2263624},{"batb":[[1,3.95,94.34],[2,3.75,13.07]],"batl":[[1,5.2,2],[2,7.2,92.18]],"ltp":4.4,"tv":1955.1,"id":7412809}]}]}
{"op":"mcm","clk":"1009258494","pt":1580643072515,"mc":[{"id":"1.168217554","rc":[{"batl":[[0,1.29,158.5],[1,1.3,152.35],[2,1.31,740.21]],"ltp":1.28,"tv":18860.29,"id":2263624},{"batb":[[0,4.4,15.26],[1,4.3,15.28],[2,3.95,94.34]],"ltp":4.4,"tv":1955.1,"id":7412809}]}]}
{"op":"mcm","clk":"1009258650","pt":1580643073487,"mc":[{"id":"1.168217554","rc":[{"batb":[[0,1.27,61.87],[1,1.26,574.42],[2,1.25,752.81]],"batl":[[0,1.3,152.35],[1,1.31,740.21],[2,1.32,505.8]],"ltp":1.28,"tv":18860.29,"id":2263624},{"batb":[[0,4.3,15.28],[1,3.95,94.34],[2,3.75,13.07]],"batl":[[0,4.8,2],[1,4.9,2],[2,5.2,2]],"ltp":4.4,"tv":1955.1,"id":7412809}]}]}
{"op":"mcm","clk":"1009258681","pt":1580643073700,"mc":[{"id":"1.168217554","rc":[{"batb":[[0,1.26,574.42],[1,1.25,752.81],[2,1.24,441.3]],"ltp":1.28,"tv":18860.29,"id":2263624},{"batl":[[0,4.9,2],[1,5.2,2],[2,7.2,92.18]],"ltp":4.4,"tv":1955.1,"id":7412809}]}]}
{"op":"mcm","clk":"1009258988","pt":1580643075484,"mc":[{"id":"1.168217554","rc":[{"batb":[[0,1.27,413.92],[1,1.26,1184.03],[2,1.25,752.81]],"batl":[[0,1.29,10.5],[1,1.3,836.88],[2,1.31,1211.44]],"ltp":1.28,"tv":18860.29,"id":2263624},{"batb":[[0,4.5,12.3],[1,4.3,15.28],[2,3.95,94.34]],"batl":[[0,4.7,10.15],[1,4.9,2],[2,5.2,2]],"ltp":4.4,"tv":1955.1,"id":7412809}]}]}
{"op":"mcm","clk":"1009259068","pt":1580643076113,"mc":[{"id":"1.168217554","rc":[{"batb":[[0,1.27,403.05]],"batl":[[0,1.3,836.88],[1,1.31,1211.44],[2,1.32,505.8]],"ltp":1.28,"tv":18860.29,"id":2263624},{"batb":[[0,4.3,15.28],[1,3.95,94.34],[2,3.75,13.07]],"batl":[[0,4.9,2],[1,5.2,2],[2,7.2,92.18]],"ltp":4.4,"tv":1955.1,"id":7412809}]}]}
{"op":"mcm","clk":"1009259179","pt":1580643076904,"mc":[{"id":"1.168217554","rc":[{"batb":[[0,1.27,465.92]],"ltp":1.28,"tv":18860.29,"id":2263624},{"batl":[[0,4.8,2],[1,4.9,2],[2,5.2,2]],"ltp":4.4,"tv":1955.1,"id":7412809}]}]}
{"op":"mcm","clk":"1009259534","pt":1580643079309,"mc":[{"id":"1.168217554","rc":[{"batl":[[0,1.29,158.5],[1,1.3,836.88],[2,1.31,1211.44]],"ltp":1.28,"tv":18860.29,"id":2263624},{"batb":[[0,4.4,15.26],[1,4.3,15.28],[2,3.95,94.34]],"ltp":4.4,"tv":1955.1,"id":7412809}]}]}
{"op":"mcm","clk":"1009259668","pt":1580643080084,"mc":[{"id":"1.168217554","rc":[{"batb":[[0,1.26,574.42],[1,1.25,752.81],[2,1.24,441.3]],"batl":[[0,1.3,152.35],[1,1.31,740.21],[2,1.32,505.8]],"ltp":1.28,"tv":18860.29,"id":2263624},{"batb":[[0,4.3,15.28],[1,3.95,94.34],[2,3.75,13.07]],"batl":[[0,4.9,2],[1,5.2,2],[2,7.2,92.18]],"ltp":4.4,"tv":1955.1,"id":7412809}]}]}
{"op":"mcm","clk":"1009260221","pt":1580643083505,"mc":[{"id":"1.168217554","rc":[{"batb":[[0,1.26,71.98],[1,1.25,856.91],[2,1.24,1118.37]],"batl":[[2,1.32,505.97]],"ltp":1.28,"tv":18860.29,"id":2263624}]}]}
{"op":"mcm","clk":"1009260463","pt":1580643084934,"mc":[{"id":"1.168217554","rc":[{"batb":[[1,1.25,623.34]],"ltp":1.28,"tv":18860.29,"id":2263624}]}]}
{"op":"mcm","clk":"1009260703","pt":1580643086502,"mc":[{"id":"1.168217554","rc":[{"batb":[[1,1.25,2437.17],[2,1.24,1913.75]],"batl":[[0,1.27,21.65],[1,1.28,4749.15],[2,1.29,512.52]],"ltp":1.28,"tv":18860.29,"id":2263624},{"batb":[[0,4.5,16.26],[1,4.4,72.15],[2,4.3,15.28]],"batl":[[1,5,3.46],[2,5.2,2]],"ltp":4.4,"tv":1955.1,"id":7412809}]}]}
{"op":"mcm","clk":"1009260741","pt":1580643086723,"mc":[{"id":"1.168217554","rc":[{"batb":[[2,4.3,17.93]],"ltp":4.4,"tv":1955.1,"id":7412809}]}]}
{"op":"mcm","clk":"1009260936","pt":1580643087802,"mc":[{"id":"1.168217554","rc":[{"batl":[[2,1.29,554.53]],"ltp":1.28,"tv":18860.29,"id":2263624},{"batb":[[0,4.5,28.02]],"ltp":4.4,"tv":1955.1,"id":7412809}]}]}
{"op":"mcm","clk":"1009261284","pt":1580643089811,"mc":[{"id":"1.168217554","rc":[{"batl":[[2,1.29,750.3]],"ltp":1.28,"tv":18860.29,"id":2263624}]}]}
{"op":"mcm","clk":"1009261674","pt":1580643092435,"mc":[{"id":"1.168217554","rc":[{"batb":[[1,1.25,2939.61],[2,1.24,2432.99]],"batl":[[2,1.29,1239.29]],"ltp":1.28,"tv":18860.29,"id":2263624}]}]}
{"op":"mcm","clk":"1009261759","pt":1580643093129,"mc":[{"id":"1.168217554","rc":[{"batl":[[2,1.29,1390.79]],"ltp":1.28,"tv":18860.29,"id":2263624},{"batb":[[1,4.4,86.76]],"ltp":4.4,"tv":1955.1,"id":7412809}]}]}
{"op":"mcm","clk":"1009261836","pt":1580643093718,"mc":[{"id":"1.168217554","rc":[{"batl":[[0,1.27,31.65]],"ltp":1.28,"tv":18860.29,"id":2263624}]}]}
{"op":"mcm","clk":"1009262293","pt":1580643096758,"mc":[{"id":"1.168217554","rc":[{"trd":[[1.26,723.58]],"batb":[[0,1.26,43.98]],"ltp":1.26,"tv":18916.29,"id":2263624}],"tv":20871.39}]}
{"op":"mcm","clk":"1009263432","pt":1580643104232,"mc":[{"id":"1.168217554","rc":[{"batl":[[0,1.27,21.65]],"ltp":1.26,"tv":18916.29,"id":2263624}]}]}
{"op":"mcm","clk":"1009263723","pt":1580643106353,"mc":[{"id":"1.168217554","rc":[{"batb":[[1,1.25,2925.78],[2,1.24,1637.61]],"batl":[[0,1.28,2538.66],[1,1.29,1390.79],[2,1.3,658.15]],"ltp":1.26,"tv":18916.29,"id":2263624},{"batl":[[1,5.2,2],[2,5.4,11.24]],"ltp":4.4,"tv":1955.1,"id":7412809}]}]}
{"op":"mcm","clk":"1009263870","pt":1580643107328,"mc":[{"id":"1.168217554","rc":[{"batb":[[0,1.25,502.44],[1,1.24,591.76],[2,1.23,357.41]],"batl":[[0,1.26,10],[1,1.29,836.26]],"ltp":1.26,"tv":18916.29,"id":2263624},{"batb":[[0,4.4,14.61],[1,4.3,17.93],[2,4.1,83.56]],"batl":[[0,5.2,2],[1,5.4,2],[2,7.2,92.18]],"ltp":4.4,"tv":1955.1,"id":7412809}]}]}
{"op":"mcm","clk":"1009263939","pt":1580643107747,"mc":[{"id":"1.168217554","rc":[{"trd":[[1.26,743.58]],"batb":[[0,1.27,221.88],[1,1.25,502.44],[2,1.24,591.76]],"batl":[[0,1.29,836.26],[1,1.3,658.15],[2,1.36,109.07]],"ltp":1.26,"tv":18936.29,"id":2263624}],"tv":20891.39}]}
{"op":"mcm","clk":"1009264212","pt":1580643109570,"mc":[{"id":"1.168217554","rc":[{"batl":[[1,1.3,1277.15],[2,1.31,472.39]],"ltp":1.26,"tv":18936.29,"id":2263624}]}]}
{"op":"mcm","clk":"1009264913","pt":1580643114332,"mc":[{"id":"1.168217554","rc":[{"batl":[[0,1.28,23.51],[1,1.29,836.26],[2,1.3,1277.15]],"ltp":1.26,"tv":18936.29,"id":2263624},{"batb":[[1,4.3,15.28]],"ltp":4.4,"tv":1955.1,"id":7412809}]}]}
{"op":"mcm","clk":"1009265038","pt":1580643115293,"mc":[{"id":"1.168217554","rc":[{"batb":[[1,1.24,72.52],[2,1.23,357.41]],"batl":[[2,1.3,658.15]],"ltp":1.26,"tv":18936.29,"id":2263624}]}]}
{"op":"mcm","clk":"1009265069","pt":1580643115560,"mc":[{"id":"1.168217554","rc":[{"batl":[[0,1.28,117.61]],"ltp":1.26,"tv":18936.29,"id":2263624}]}]}
{"op":"mcm","clk":"1009265358","pt":1580643117429,"mc":[{"id":"1.168217554","rc":[{"trd":[[1.27,47.02]],"batb":[[0,1.27,198.37],[2,1.23,77.63]],"ltp":1.27,"tv":18983.3,"id":2263624},{"batl":[[2,1000,0.02]],"ltp":4.4,"tv":1955.1,"id":7412809}],"tv":20938.41}]}
{"op":"mcm","clk":"1009265474","pt":1580643118029,"mc":[{"id":"1.168217554","rc":[{"trd":[[1.24,145.04],[1.27,443.76]],"batb":[[0,1.23,77.63],[1,1.22,2784],[2,1.21,650.92]],"batl":[[0,1.24,1742],[1,1.25,773.74],[2,1.26,585.56]],"ltp":1.24,"tv":19525.08,"id":2263624},{"batb":[[0,5,16.07],[1,4.4,14.61],[2,4.3,15.28]],"batl":[[0,5.4,2],[1,1000,0.02],[2,1000,0]],"ltp":4.4,"tv":1955.1,"id":7412809}],"tv":21480.19}]}
{"op":"mcm","clk":"1009265674","pt":1580643119305,"mc":[{"id":"1.168217554","rc":[{"batb":[[1,4.5,69.87],[2,4.4,14.61]],"ltp":4.4,"tv":1955.1,"id":7412809}]}]}
{"op":"mcm","clk":"1009265960","pt":1580643121243,"mc":[{"id":"1.168217554","rc":[{"batl":[[2,1.26,627.57]],"ltp":1.24,"tv":19525.08,"id":2263624},{"batb":[[1,4.9,10.08],[2,4.5,69.87]],"batl":[[1,5.9,8.4],[2,9.8,75.27]],"ltp":4.4,"tv":1955.1,"id":7412809}]}]}
{"op":"mcm","clk":"1009266435","pt":1580643124452,"mc":[{"id":"1.168217554","rc":[{"batb":[[1,1.22,3286.44],[2,1.21,1170.16]],"batl":[[2,1.26,1116.56]],"ltp":1.24,"tv":19525.08,"id":2263624}]}]}
{"op":"mcm","clk":"1009266447","pt":1580643124560,"mc":[{"id":"1.168217554","rc":[{"batb":[[2,4.7,18.12]],"batl":[[2,6,2]],"ltp":4.4,"tv":1955.1,"id":7412809}]}]}
{"op":"mcm","clk":"1009266641","pt":1580643125944,"mc":[{"id":"1.168217554","rc":[{"trd":[[1.24,193.2]],"batl":[[0,1.24,1717.92]],"ltp":1.24,"tv":19573.24,"id":2263624}],"tv":21528.35}]}
{"op":"mcm","clk":"1009267095","pt":1580643129361,"mc":[{"id":"1.168217554","rc":[{"batl":[[2,1.26,1323.25]],"ltp":1.24,"tv":19573.24,"id":2263624}]}]}
{"op":"mcm","clk":"1009267312","pt":1580643130980,"mc":[{"id":"1.168217554","rc":[{"batl":[[1,1.25,580.88]],"ltp":1.24,"tv":19573.24,"id":2263624}]}]}
{"op":"mcm","clk":"1009267752","pt":1580643134060,"mc":[{"id":"1.168217554","rc":[{"batb":[[0,1.22,2346.7],[1,1.21,519.24],[2,1.2,459.02]],"batl":[[1,1.26,737.69],[2,1.27,707.3]],"ltp":1.24,"tv":19573.24,"id":2263624},{"batb":[[0,4.9,10.08],[1,4.7,18.12],[2,4.5,69.87]],"batl":[[0,5.9,8.4],[1,6,2],[2,6.6,2]],"ltp":4.4,"tv":1955.1,"id":7412809}]}]}
{"op":"mcm","clk":"1009267859","pt":1580643134973,"mc":[{"id":"1.168217554","rc":[{"batb":[[0,1.22,502.44],[2,1.2,290.99]],"batl":[[0,1.26,695.68],[1,1.27,707.3],[2,1.29,151.5]],"ltp":1.24,"tv":19573.24,"id":2263624},{"batb":[[0,4.7,18.12],[1,4.5,69.87],[2,4.4,14.61]],"batl":[[0,6,2],[1,6.6,2],[2,9.8,75.27]],"ltp":4.4,"tv":1955.1,"id":7412809}]}]}
{"op":"mcm","clk":"1009268141","pt":1580643136990,"mc":[{"id":"1.168217554","rc":[{"batl":[[1,1.27,1084.66],[2,1.28,539.77]],"ltp":1.24,"tv":19573.24,"id":2263624}]}]}
{"op":"mcm","clk":"1009268327","pt":1580643138260,"mc":[{"id":"1.168217554","rc":[{"batl":[[0,1.26,206.69],[1,1.27,201.5],[2,1.29,151.5]],"ltp":1.24,"tv":19573.24,"id":2263624}]}]}
{"op":"mcm","clk":"1009268488","pt":1580643139264,"mc":[{"id":"1.168217554","rc":[{"batl":[[0,1.27,201.5],[1,1.29,151.5],[2,1.3,152.35]],"ltp":1.24,"tv":19573.24,"id":2263624},{"batl":[[2,1000,0.02]],"ltp":4.4,"tv":1955.1,"id":7412809}]}]}
{"op":"mcm","clk":"1009268658","pt":1580643140395,"mc":[{"id":"1.168217554","rc":[{"batb":[[0,1.24,1814.52],[1,1.22,502.44],[2,1.21,519.24]],"batl":[[0,1.26,16.98],[1,1.27,3758.87],[2,1.29,151.5]],"ltp":1.24,"tv":19573.24,"id":2263624},{"batb":[[0,4.5,69.87],[1,4.4,14.61],[2,4.3,15.28]],"batl":[[0,5,1483],[1,5.1,5.91],[2,5.3,193.59]],"ltp":4.4,"tv":1955.1,"id":7412809}]}]}
{"op":"mcm","clk":"1009268716","pt":1580643140759,"mc":[{"id":"1.168217554","rc":[{"batb":[[0,1.25,298.89],[1,1.24,2483.77],[2,1.22,502.44]],"batl":[[1,1.27,4136.23],[2,1.28,539.77]],"ltp":1.24,"tv":19573.24,"id":2263624},{"batl":[[0,5.1,5.91],[1,5.3,193.59],[2,5.5,269]],"ltp":4.4,"tv":1955.1,"id":7412809}]}]}
{"op":"mcm","clk":"1009268903","pt":1580643142104,"mc":[{"id":"1.168217554","rc":[{"batb":[[1,1.24,2860.81],[2,1.22,670.48]],"batl":[[2,1.28,581.78]],"ltp":1.24,"tv":19573.24,"id":2263624},{"batb":[[0,4.6,10.92],[1,4.5,69.87],[2,4.4,14.61]],"ltp":4.4,"tv":1955.1,"id":7412809}]}]}
{"op":"mcm","clk":"1009269598","pt":1580643146477,"mc":[{"id":"1.168217554","rc":[{"batb":[[2,1.22,168.04]],"batl":[[2,1.28,832.16]],"ltp":1.24,"tv":19573.24,"id":2263624}]}]}
{"op":"mcm","clk":"1009269738","pt":1580643147273,"mc":[{"id":"1.168217554","rc":[{"batb":[[1,1.24,3363.25],[2,1.23,519.24]],"batl":[[2,1.28,1321.15]],"ltp":1.24,"tv":19573.24,"id":2263624}]}]}
{"op":"mcm","clk":"1009269864","pt":1580643148090,"mc":[{"id":"1.168217554","rc":[{"batl":[[2,1.28,1527.99]],"ltp":1.24,"tv":19573.24,"id":2263624},{"batb":[[1,4.5,89.29]],"ltp":4.4,"tv":1955.1,"id":7412809}]}]}
{"op":"mcm","clk":"1009271440","pt":1580643157518,"mc":[{"id":"1.168217554","rc":[{"batl":[[1,1.27,3106.23]],"ltp":1.24,"tv":19573.24,"id":2263624},{"batl":[[2,5.6,10.4]],"ltp":4.4,"tv":1955.1,"id":7412809}]}]}
{"op":"mcm","clk":"1009271536","pt":1580643158025,"mc":[{"id":"1.168217554","rc":[{"batb":[[0,1.24,502.44],[1,1.23,519.24],[2,1.22,250.38]],"batl":[[0,1.28,988.22],[1,1.29,657.3],[2,1.3,152.35]],"ltp":1.24,"tv":19573.24,"id":2263624},{"batb":[[1,4.5,19.42]],"batl":[[0,5.6,10.4],[1,6,2],[2,6.6,2]],"ltp":4.4,"tv":1955.1,"id":7412809}]}]}
{"op":"mcm","clk":"1009271667","pt":1580643158832,"mc":[{"id":"1.168217554","rc":[{"batb":[[2,1.22,82.34]],"batl":[[0,1.28,946.21]],"ltp":1.24,"tv":19573.24,"id":2263624},{"batb":[[0,4.5,19.42],[1,4.4,14.61],[2,4.3,17.82]],"batl":[[0,5.6,2]],"ltp":4.4,"tv":1955.1,"id":7412809}]}]}
{"op":"mcm","clk":"1009271997","pt":1580643161657,"mc":[{"id":"1.168217554","rc":[{"batl":[[2,1.3,792.71]],"ltp":1.24,"tv":19573.24,"id":2263624}]}]}
