{"op":"mcm","clk":"1009481196","pt":1580644742970,"mc":[{"id":"1.168217555","rc":[{"batb":[[1,2.34,99.92]],"batl":[[1,2.6,26.05],[2,2.78,13.22]],"ltp":5.2,"tv":21.28,"id":12984951},{"batl":[[0,4.2,12.6],[1,4.3,24.23],[2,5.3,15.03]],"ltp":4.1,"tv":81.32,"id":12984952}]}]}
{"op":"mcm","clk":"1009483732","pt":1580644765214,"mc":[{"id":"1.168217555","rc":[{"batb":[[0,2.34,31.09],[1,2.22,21.01],[2,1.01,0.51]],"batl":[[0,2.6,26.05],[1,2.78,13.22],[2,2.78,0]],"ltp":5.2,"tv":21.28,"id":12984951},{"batb":[[0,2.9,25.41],[1,1.01,0.51],[2,3.8,0]],"batl":[[1,5.3,15.03],[2,5.3,0]],"ltp":4.1,"tv":81.32,"id":12984952},{"batb":[[0,2.78,23.53],[1,2.7,13.06],[2,1.01,0.51]],"batl":[[0,3.5,19.59],[1,3.5,0]],"ltp":4.4,"tv":44.81,"id":16574984}]}]}
{"op":"mcm","clk":"1009483836","pt":1580644766096,"mc":[{"id":"1.168217555","rc":[{"batb":[[0,2.22,21.01],[1,1.01,0.51],[2,1.01,0]],"batl":[[0,2.78,13.22],[1,2.78,0]],"ltp":5.2,"tv":21.28,"id":12984951},{"batl":[[0,5.3,15.03],[1,5.3,0]],"ltp":4.1,"tv":81.32,"id":12984952},{"batb":[[0,2.7,13.06],[1,1.01,0.51],[2,1.01,0]],"ltp":4.4,"tv":44.81,"id":16574984}]}]}
{"op":"mcm","clk":"1009484084","pt":1580644768298,"mc":[{"id":"1.168217555","rc":[{"batb":[[0,2.22,72.06],[1,2.2,51.17],[2,1.01,0.51]],"ltp":5.2,"tv":21.28,"id":12984951},{"batb":[[0,3,41.97],[1,2.96,45.48],[2,2.92,25.34]],"batl":[[0,5.4,14.95]],"ltp":4.1,"tv":81.32,"id":12984952},{"batb":[[0,2.68,59.73],[1,2.64,62.18],[2,1.01,0.51]],"ltp":4.4,"tv":44.81,"id":16574984}]}]}
{"op":"mcm","clk":"1009484337","pt":1580644770569,"mc":[{"id":"1.168217555","rc":[{"batb":[[0,2.22,20.85],[1,1.01,0.51],[2,1.01,0]],"ltp":5.2,"tv":21.28,"id":12984951},{"batb":[[0,2.92,25.34],[1,1.01,0.51],[2,2.92,0]],"ltp":4.1,"tv":81.32,"id":12984952},{"batb":[[0,2.68,13.14],[1,1.01,0.51],[2,1.01,0]],"ltp":4.4,"tv":44.81,"id":16574984}]}]}
{"op":"mcm","clk":"1009484728","pt":1580644773474,"mc":[{"id":"1.168217555","rc":[{"batb":[[0,2.38,82.29],[1,2.34,84.96],[2,2.22,20.85]],"ltp":5.2,"tv":21.28,"id":12984951},{"batb":[[0,3.7,51.88],[1,3.65,33.7],[2,2.92,25.34]],"ltp":4.1,"tv":81.32,"id":12984952},{"batb":[[0,2.92,41.08],[1,2.88,49.69],[2,2.68,13.14]],"ltp":4.4,"tv":44.81,"id":16574984}]}]}
{"op":"mcm","clk":"1009485574","pt":1580644780606,"mc":[{"id":"1.168217555","rc":[{"batb":[[0,2.22,20.85],[1,1.01,0.51],[2,2.22,0]],"ltp":5.2,"tv":21.28,"id":12984951},{"batb":[[0,2.92,25.34],[1,1.01,0.51],[2,2.92,0]],"ltp":4.1,"tv":81.32,"id":12984952},{"batb":[[0,2.68,13.14],[1,1.01,0.51],[2,2.68,0]],"ltp":4.4,"tv":44.81,"id":16574984}]}]}
{"op":"mcm","clk":"1009485939","pt":1580644783600,"mc":[{"id":"1.168217555","rc":[{"batb":[[0,2.22,72.06],[1,2.2,51.17],[2,1.01,0.51]],"ltp":5.2,"tv":21.28,"id":12984951},{"batb":[[0,3,41.97],[1,2.96,45.48],[2,2.92,25.34]],"ltp":4.1,"tv":81.32,"id":12984952},{"batb":[[0,2.68,59.73],[1,2.64,62.18],[2,1.01,0.51]],"ltp":4.4,"tv":44.81,"id":16574984}]}]}
{"op":"mcm","clk":"1009486578","pt":1580644789024,"mc":[{"id":"1.168217555","rc":[{"batb":[[0,2.22,20.85],[1,1.01,0.51],[2,1.01,0]],"ltp":5.2,"tv":21.28,"id":12984951},{"batb":[[0,2.68,13.14],[1,1.01,0.51],[2,1.01,0]],"ltp":4.4,"tv":44.81,"id":16574984}]}]}
{"op":"mcm","clk":"1009486956","pt":1580644792228,"mc":[{"id":"1.168217555","rc":[{"batb":[[0,2.6,55.86],[1,2.56,66.59],[2,2.22,20.85]],"ltp":5.2,"tv":21.28,"id":12984951},{"batb":[[0,3.2,46.92],[1,3.15,49.38],[2,2.68,13.14]],"ltp":4.4,"tv":44.81,"id":16574984}]}]}
{"op":"mcm","clk":"1009487067","pt":1580644793226,"mc":[{"id":"1.168217555","rc":[{"batb":[[0,2.62,13.45],[1,2.6,55.86],[2,2.56,93.48]],"batl":[[1,2.86,21.85],[2,3.4,20.77]],"ltp":5.2,"tv":21.28,"id":12984951},{"batl":[[0,3.2,24.31],[1,3.25,18.48],[2,4,14.08]],"ltp":4.1,"tv":81.32,"id":12984952},{"batb":[[0,3.2,67.46],[2,3.05,20.16]],"batl":[[1,4.3,25.57]],"ltp":4.4,"tv":44.81,"id":16574984}]}]}
{"op":"mcm","clk":"1009488274","pt":1580644802350,"mc":[{"id":"1.168217555","rc":[{"batb":[[1,2.56,26.89],[2,2.38,17.15]],"ltp":5.2,"tv":21.28,"id":12984951},{"batb":[[0,3.2,20.54]],"ltp":4.4,"tv":44.81,"id":16574984},{"batb":[[0,1.01,0.51],[1,1.01,0]],"ltp":5.1,"tv":4.54,"id":16574983}]}]}
{"op":"mcm","clk":"1009488395","pt":1580644803217,"mc":[{"id":"1.168217555","rc":[{"batl":[[2,3.4,2.47]],"ltp":4.1,"tv":81.32,"id":12984952}]}]}
{"op":"mcm","clk":"1009488584","pt":1580644804251,"mc":[{"id":"1.168217555","rc":[{"batl":[[2,4,14.08]],"ltp":4.1,"tv":81.32,"id":12984952}]}]}
{"op":"mcm","clk":"1009488844","pt":1580644805342,"mc":[{"id":"1.168217555","rc":[{"batb":[[0,2.62,59.52],[1,2.58,65.46],[2,2.56,26.89]],"ltp":5.2,"tv":21.28,"id":12984951},{"batb":[[0,3,60.43]],"ltp":4.1,"tv":81.32,"id":12984952},{"batb":[[2,3.1,50.93]],"ltp":4.4,"tv":44.81,"id":16574984}]}]}
{"op":"mcm","clk":"1009490289","pt":1580644815474,"mc":[{"id":"1.168217555","rc":[{"batb":[[0,2.62,13.45],[1,2.56,26.89],[2,2.38,17.15]],"ltp":5.2,"tv":21.28,"id":12984951},{"batb":[[0,2.92,25.34],[1,2.2,21.64],[2,1.01,0.51]],"ltp":4.1,"tv":81.32,"id":12984952},{"batb":[[1,3.05,20.16],[2,2.94,10.39]],"ltp":4.4,"tv":44.81,"id":16574984}]}]}
{"op":"mcm","clk":"1009490364","pt":1580644815961,"mc":[{"id":"1.168217555","rc":[{"batb":[[0,2.38,17.15],[1,1.01,0.51],[2,2.38,0]],"batl":[[0,3.4,20.77],[1,2.86,0],[2,3.4,0]],"ltp":5.2,"tv":21.28,"id":12984951},{"batb":[[0,2.2,21.64],[1,1.01,0.51],[2,1.01,0]],"batl":[[0,4,14.08],[1,3.25,0],[2,4,0]],"ltp":4.1,"tv":81.32,"id":12984952},{"batb":[[0,2.94,10.39],[1,1.01,0.51],[2,2.94,0]],"batl":[[0,4.3,25.57],[1,4.3,0]],"ltp":4.4,"tv":44.81,"id":16574984}]}]}
{"op":"mcm","clk":"1009490692","pt":1580644818470,"mc":[{"id":"1.168217555","rc":[{"batb":[[0,2.38,91.73],[1,2.34,85.16],[2,1.01,0.51]],"ltp":5.2,"tv":21.28,"id":12984951},{"batb":[[0,2.26,56.84],[1,2.24,48.39],[2,2.2,21.64]],"ltp":4.1,"tv":81.32,"id":12984952},{"batb":[[1,2.88,52.29],[2,2.84,51.1]],"ltp":4.4,"tv":44.81,"id":16574984}]}]}
{"op":"mcm","clk":"1009490754","pt":1580644818947,"mc":[{"id":"1.168217555","rc":[{"batb":[[0,2.4,16.84],[1,2.38,74.58],[2,2.34,85.16]],"batl":[[0,3.4,20.54]],"ltp":5.2,"tv":21.28,"id":12984951},{"batb":[[2,2.22,21.32]],"batl":[[0,4.1,13.85]],"ltp":4.1,"tv":81.32,"id":12984952},{"batb":[[0,2.9,10.78]],"batl":[[0,4.2,13.3]],"ltp":4.4,"tv":44.81,"id":16574984}]}]}
{"op":"mcm","clk":"1009491740","pt":1580644827359,"mc":[{"id":"1.168217555","rc":[{"batb":[[0,2.22,21.32],[1,1.01,0.51],[2,2.22,0]],"ltp":4.1,"tv":81.32,"id":12984952}]}]}
{"op":"mcm","clk":"1009492112","pt":1580644830491,"mc":[{"id":"1.168217555","rc":[{"batb":[[0,3.75,58.82],[1,3.7,32.67],[2,2.22,21.32]],"ltp":4.1,"tv":81.32,"id":12984952}]}]}
{"op":"mcm","clk":"1009492239","pt":1580644831475,"mc":[{"id":"1.168217555","rc":[{"batb":[[1,2.38,104.83]],"batl":[[0,2.54,16.44],[1,2.64,25.21],[2,2.98,11.02]],"ltp":5.2,"tv":21.28,"id":12984951},{"batb":[[2,3.65,14.24]],"batl":[[0,4,13.44],[1,4.1,13.85],[2,5.5,14.32]],"ltp":4.1,"tv":81.32,"id":12984952},{"batb":[[2,2.86,21.85]],"batl":[[0,3.1,10.54],[1,3.7,17.31]],"ltp":4.4,"tv":44.81,"id":16574984}]}]}
{"op":"mcm","clk":"1009493062","pt":1580644838490,"mc":[{"id":"1.168217555","rc":[{"batb":[[0,12,12.6],[1,1.01,0.51]],"ltp":5.1,"tv":4.54,"id":16574983}]}]}
{"op":"mcm","clk":"1009493628","pt":1580644843112,"mc":[{"id":"1.168217555","rc":[{"batb":[[0,3.75,31.92],[1,3.65,14.24],[2,2.6,13.53]],"ltp":4.1,"tv":81.32,"id":12984952}]}]}
{"op":"mcm","clk":"1009494075","pt":1580644846125,"mc":[{"id":"1.168217555","rc":[{"batb":[[0,3.8,26.88],[1,3.75,31.92],[2,3.65,14.24]],"ltp":4.1,"tv":81.32,"id":12984952}]}]}
{"op":"mcm","clk":"1009495150","pt":1580644853506,"mc":[{"id":"1.168217555","rc":[{"batb":[[1,2.38,30.25],[2,2.22,21.09]],"ltp":5.2,"tv":21.28,"id":12984951},{"batb":[[0,3.65,14.24],[1,2.6,13.53],[2,1.01,0.51]],"ltp":4.1,"tv":81.32,"id":12984952},{"batb":[[1,2.86,21.85],[2,2.68,13.38]],"ltp":4.4,"tv":44.81,"id":16574984}]}]}
{"op":"mcm","clk":"1009495257","pt":1580644854194,"mc":[{"id":"1.168217555","rc":[{"batb":[[0,2.22,21.09],[1,1.01,0.51],[2,2.22,0]],"batl":[[0,2.98,11.02],[1,2.64,0],[2,2.98,0]],"ltp":5.2,"tv":21.28,"id":12984951},{"batb":[[0,2.6,13.53],[1,1.01,0.51],[2,1.01,0]],"batl":[[0,5.5,14.32],[1,4.1,0],[2,5.5,0]],"ltp":4.1,"tv":81.32,"id":12984952},{"batb":[[0,2.68,13.38],[1,1.01,0.51],[2,2.68,0]],"batl":[[0,3.7,17.31],[1,3.7,0]],"ltp":4.4,"tv":44.81,"id":16574984}]}]}
{"op":"mcm","clk":"1009495572","pt":1580644856525,"mc":[{"id":"1.168217555","rc":[{"batb":[[1,2.2,68.85],[2,2.18,52.55]],"ltp":5.2,"tv":21.28,"id":12984951},{"batb":[[0,2.66,60.52],[1,2.62,62.44],[2,2.6,13.53]],"ltp":4.1,"tv":81.32,"id":12984952},{"batb":[[1,2.64,68.38],[2,2.6,64.22]],"ltp":4.4,"tv":44.81,"id":16574984}]}]}
{"op":"mcm","clk":"1009499420","pt":1580644885956,"mc":[{"id":"1.168217555","rc":[{"batb":[[1,1.01,0.51],[2,2.18,0]],"ltp":5.2,"tv":21.28,"id":12984951},{"batb":[[1,1.01,0.51],[2,2.6,0]],"ltp":4.4,"tv":44.81,"id":16574984}]}]}
{"op":"mcm","clk":"1009499930","pt":1580644889442,"mc":[{"id":"1.168217555","rc":[{"batb":[[0,2.8,11.25],[1,2.78,54.69],[2,2.74,55.83]],"batl":[[1,3.05,20.16],[2,4.3,24.86]],"ltp":5.2,"tv":21.28,"id":12984951},{"batl":[[0,2.76,13.3],[1,2.94,21],[2,3.9,14.87]],"ltp":4.1,"tv":81.32,"id":12984952},{"batb":[[0,3.4,17.94],[1,3.35,67.14],[2,3.3,43.52]],"batl":[[1,5,17.47]],"ltp":4.4,"tv":44.81,"id":16574984}]}]}
{"op":"mcm","clk":"1009501577","pt":1580644901667,"mc":[{"id":"1.168217555","rc":[{"batb":[[0,1.01,0.51],[1,1.01,0]],"ltp":5.1,"tv":4.54,"id":16574983}]}]}
{"op":"mcm","clk":"1009504089","pt":1580644918193,"mc":[{"id":"1.168217555","rc":[{"batb":[[0,2.4,16.76],[1,1.01,0.51],[2,2.74,0]],"batl":[[0,4.3,24.86],[1,3.05,0],[2,4.3,0]],"ltp":5.2,"tv":21.28,"id":12984951},{"batb":[[0,1.82,19.28],[1,1.01,0.51],[2,2.6,0]],"batl":[[0,3.9,14.87],[1,2.94,0],[2,3.9,0]],"ltp":4.1,"tv":81.32,"id":12984952},{"batb":[[0,2.96,10.31],[1,1.01,0.51],[2,3.3,0]],"batl":[[0,5,17.47],[1,5,0]],"ltp":4.4,"tv":44.81,"id":16574984}]}]}
{"op":"mcm","clk":"1009504562","pt":1580644921013,"mc":[{"id":"1.168217555","rc":[{"batb":[[0,2.42,16.68]],"ltp":5.2,"tv":21.28,"id":12984951},{"batb":[[0,2.94,10.39]],"ltp":4.4,"tv":44.81,"id":16574984}]}]}
{"op":"mcm","clk":"1009504899","pt":1580644923096,"mc":[{"id":"1.168217555","rc":[{"batb":[[0,2.94,49.49],[1,2.9,48.26],[2,2.42,16.68]],"ltp":5.2,"tv":21.28,"id":12984951},{"batb":[[0,2.44,59.32],[1,2.4,79.11],[2,1.82,19.28]],"ltp":4.1,"tv":81.32,"id":12984952},{"batb":[[0,3.55,50.22],[1,3.5,37.84],[2,2.94,10.39]],"ltp":4.4,"tv":44.81,"id":16574984}]}]}
{"op":"mcm","clk":"1009505872","pt":1580644929526,"mc":[{"id":"1.168217555","rc":[{"batb":[[0,2.42,16.68],[1,1.01,0.51],[2,2.42,0]],"ltp":5.2,"tv":21.28,"id":12984951},{"batb":[[0,1.82,19.28],[1,1.01,0.51],[2,1.82,0]],"ltp":4.1,"tv":81.32,"id":12984952},{"batb":[[0,2.94,10.39],[1,1.01,0.51],[2,2.94,0]],"ltp":4.4,"tv":44.81,"id":16574984}]}]}
{"op":"mcm","clk":"1009506326","pt":1580644932516,"mc":[{"id":"1.168217555","rc":[{"batb":[[1,2.38,77.98],[2,2.34,85.15]],"ltp":5.2,"tv":21.28,"id":12984951},{"batb":[[0,1.83,81.05],[1,1.82,19.28],[2,1.81,92.48]],"ltp":4.1,"tv":81.32,"id":12984952},{"batb":[[1,2.92,45.98],[2,2.88,49.34]],"ltp":4.4,"tv":44.81,"id":16574984}]}]}
{"op":"mcm","clk":"1009506602","pt":1580644934320,"mc":[{"id":"1.168217555","rc":[{"batb":[[1,1.01,0.51],[2,2.34,0]],"ltp":5.2,"tv":21.28,"id":12984951},{"batb":[[1,1.01,0.51],[2,2.88,0]],"ltp":4.4,"tv":44.81,"id":16574984}]}]}
{"op":"mcm","clk":"1009507070","pt":1580644937293,"mc":[{"id":"1.168217555","rc":[{"batb":[[0,3.8,44.79],[1,3.75,31.95],[2,2.42,16.68]],"ltp":5.2,"tv":21.28,"id":12984951},{"batb":[[0,4.5,57.08],[1,4.4,43.35],[2,2.94,10.39]],"ltp":4.4,"tv":44.81,"id":16574984}]}]}
{"op":"mcm","clk":"1009507181","pt":1580644937990,"mc":[{"id":"1.168217555","rc":[{"batb":[[0,3.8,57.93],[2,3.35,17.86]],"batl":[[1,4.6,20.61]],"ltp":5.2,"tv":21.28,"id":12984951},{"batl":[[0,1.9,18.88],[1,2.2,24.78]],"ltp":4.1,"tv":81.32,"id":12984952},{"batb":[[1,4.4,61.84],[2,3.9,12.98]],"batl":[[1,5.5,14.48]],"ltp":4.4,"tv":44.81,"id":16574984}]}]}
{"op":"mcm","clk":"1009507349","pt":1580644939104,"mc":[{"id":"1.168217555","rc":[{"batb":[[2,3.55,15.96]],"batl":[[0,4.1,13.44],[1,4.3,24.86],[2,4.6,20.61]],"ltp":5.2,"tv":21.28,"id":12984951},{"batl":[[1,2.02,41.17],[2,2.2,24.78]],"ltp":4.1,"tv":81.32,"id":12984952},{"batb":[[2,4.2,12.6]],"ltp":4.4,"tv":44.81,"id":16574984},{"batb":[[0,4,13.44],[1,1.01,0.51]],"ltp":5.1,"tv":4.54,"id":16574983}]}]}
{"op":"mcm","clk":"1009509880","pt":1580644956813,"mc":[{"id":"1.168217555","rc":[{"batb":[[0,4.5,41.85],[1,4.4,18.49]],"ltp":4.4,"tv":44.81,"id":16574984}]}]}
{"op":"mcm","clk":"1009510303","pt":1580644959856,"mc":[{"id":"1.168217555","rc":[{"batb":[[0,4.6,29.94],[1,4.5,41.85],[2,4.4,18.49]],"ltp":4.4,"tv":44.81,"id":16574984}]}]}
{"op":"mcm","clk":"1009511287","pt":1580644966581,"mc":[{"id":"1.168217555","rc":[{"batb":[[0,1.82,19.28],[1,1.7,24],[2,1.01,0.51]],"ltp":4.1,"tv":81.32,"id":12984952}]}]}
{"op":"mcm","clk":"1009511724","pt":1580644969449,"mc":[{"id":"1.168217555","rc":[{"batb":[[0,3.8,70.28]],"ltp":5.2,"tv":21.28,"id":12984951},{"batb":[[0,1.82,78.82],[1,1.8,94.25],[2,1.7,24]],"ltp":4.1,"tv":81.32,"id":12984952},{"batb":[[0,4.6,43.77]],"ltp":4.4,"tv":44.81,"id":16574984}]}]}
{"op":"mcm","clk":"1009511865","pt":1580644970347,"mc":[{"id":"1.168217555","rc":[{"batb":[[0,3.8,70.12]],"batl":[[1,4.3,24.47],[2,4.7,20.3]],"ltp":5.2,"tv":21.28,"id":12984951},{"batb":[[0,1.82,59.54],[1,1.81,19.59],[2,1.8,94.25]],"batl":[[0,1.89,19.2],[2,2.18,25.18]],"ltp":4.1,"tv":81.32,"id":12984952},{"batb":[[1,4.5,60.1],[2,4.2,12.6]],"batl":[[0,5.1,17.39],[1,5.5,14.24]],"ltp":4.4,"tv":44.81,"id":16574984},{"batb":[[0,1.01,0.51],[1,1.01,0]],"ltp":5.1,"tv":4.54,"id":16574983}]}]}
{"op":"mcm","clk":"1009512591","pt":1580644975350,"mc":[{"id":"1.168217555","rc":[{"batb":[[0,3.8,44.22],[1,3.55,15.96],[2,3.35,17.7]],"ltp":5.2,"tv":21.28,"id":12984951},{"batb":[[0,1.81,19.59],[1,1.69,24.39],[2,1.01,0.51]],"ltp":4.1,"tv":81.32,"id":12984952}]}]}
{"op":"mcm","clk":"1009512965","pt":1580644978165,"mc":[{"id":"1.168217555","rc":[{"batb":[[0,3.85,27.86],[1,3.8,44.22],[2,3.55,15.96]],"ltp":5.2,"tv":21.28,"id":12984951},{"batb":[[0,1.81,120.51],[1,1.79,96.1],[2,1.69,24.39]],"ltp":4.1,"tv":81.32,"id":12984952}]}]}
{"op":"mcm","clk":"1009517112","pt":1580645006584,"mc":[{"id":"1.168217555","rc":[{"batb":[[0,16,13.44],[1,1.01,0.51]],"ltp":5.1,"tv":4.54,"id":16574983}]}]}
{"op":"mcm","clk":"1009520178","pt":1580645026302,"mc":[{"id":"1.168217555","rc":[{"batb":[[0,3.55,15.96],[1,3.35,17.7],[2,1.01,0.51]],"batl":[[1,4.7,20.3],[2,4.7,0]],"ltp":5.2,"tv":21.28,"id":12984951},{"batb":[[0,1.69,24.39],[1,1.01,0.51],[2,1.69,0]],"batl":[[0,2.02,41.17],[1,2.18,25.18],[2,2.18,0]],"ltp":4.1,"tv":81.32,"id":12984952},{"batb":[[0,4.2,12.6],[1,3.85,25.65],[2,1.01,0.51]],"batl":[[0,5.5,14.24],[1,5.5,0]],"ltp":4.4,"tv":44.81,"id":16574984}]}]}
{"op":"mcm","clk":"1009520505","pt":1580645028086,"mc":[{"id":"1.168217555","rc":[{"batb":[[0,3.35,17.7],[1,1.01,0.51],[2,1.01,0]],"batl":[[0,4.7,20.3],[1,4.7,0]],"ltp":5.2,"tv":21.28,"id":12984951},{"batl":[[0,2.18,25.18],[1,2.18,0]],"ltp":4.1,"tv":81.32,"id":12984952},{"batb":[[0,3.85,25.65],[1,1.01,0.51],[2,1.01,0]],"ltp":4.4,"tv":44.81,"id":16574984}]}]}
{"op":"mcm","clk":"1009520665","pt":1580645029211,"mc":[{"id":"1.168217555","rc":[{"batb":[[0,1.7,113.89],[1,1.69,24.39],[2,1.68,119.43]],"ltp":4.1,"tv":81.32,"id":12984952}]}]}
{"op":"mcm","clk":"1009521143","pt":1580645032305,"mc":[{"id":"1.168217555","rc":[{"batb":[[0,4.1,53.6],[1,4,54.21],[2,3.35,17.7]],"ltp":5.2,"tv":21.28,"id":12984951},{"batb":[[0,5,43.42],[1,4.9,34.47],[2,3.85,25.65]],"ltp":4.4,"tv":44.81,"id":16574984}]}]}
{"op":"mcm","clk":"1009521310","pt":1580645033111,"mc":[{"id":"1.168217555","rc":[{"batb":[[0,4.1,75],[2,3.8,14.28]],"batl":[[0,4.4,11.76],[1,4.7,20.3],[2,4.9,17.94]],"ltp":5.2,"tv":21.28,"id":12984951},{"batl":[[0,1.76,23.92],[1,1.89,42.01],[2,1.95,17.39]],"ltp":4.1,"tv":81.32,"id":12984952},{"batb":[[1,4.9,49.34],[2,4.6,10.92]],"batl":[[1,6,11.88]],"ltp":4.4,"tv":44.81,"id":16574984}]}]}
{"op":"mcm","clk":"1009522669","pt":1580645042039,"mc":[{"id":"1.168217555","rc":[{"batb":[[0,3.75,13.69],[1,1.01,0.51],[2,3.8,0]],"batl":[[0,4.9,17.94],[1,4.7,0],[2,4.9,0]],"ltp":5.2,"tv":21.28,"id":12984951},{"batb":[[0,1.62,28.72],[1,1.01,0.51],[2,1.68,0]],"batl":[[0,1.95,17.39],[1,1.89,0],[2,1.95,0]],"ltp":4.1,"tv":81.32,"id":12984952},{"batb":[[0,4.3,20.14],[1,1.01,0.51],[2,4.6,0]],"batl":[[0,6,11.88],[1,6,0]],"ltp":4.4,"tv":44.81,"id":16574984}]}]}
{"op":"mcm","clk":"1009523004","pt":1580645044507,"mc":[{"id":"1.168217555","rc":[{"batb":[[1,3.7,60.09],[2,3.65,34.13]],"ltp":5.2,"tv":21.28,"id":12984951},{"batb":[[0,1.63,103.37],[1,1.62,97.18],[2,1.01,0.51]],"ltp":4.1,"tv":81.32,"id":12984952},{"batb":[[0,4.4,63.03],[1,4.3,66.37],[2,1.01,0.51]],"ltp":4.4,"tv":44.81,"id":16574984}]}]}
{"op":"mcm","clk":"1009523648","pt":1580645049313,"mc":[{"id":"1.168217555","rc":[{"batb":[[0,1.62,28.72],[1,1.01,0.51],[2,1.01,0]],"ltp":4.1,"tv":81.32,"id":12984952}]}]}
{"op":"mcm","clk":"1009524023","pt":1580645052354,"mc":[{"id":"1.168217555","rc":[{"batl":[[0,4.1,13.3],[1,4.6,21.01],[2,4.9,17.94]],"ltp":5.2,"tv":21.28,"id":12984951},{"batb":[[0,1.87,17.7],[1,1.86,96.93],[2,1.84,87.79]],"batl":[[1,2.34,20.61]],"ltp":4.1,"tv":81.32,"id":12984952},{"batb":[[2,3.7,14.71]],"batl":[[0,4.8,19.12],[1,5.4,15.11],[2,6,11.88]],"ltp":4.4,"tv":44.81,"id":16574984}]}]}
{"op":"mcm","clk":"1009524142","pt":1580645053507,"mc":[{"id":"1.168217555","rc":[{"batl":[[0,4,13.44],[1,4.1,13.3],[2,4.6,21.01]],"ltp":5.2,"tv":21.28,"id":12984951},{"batl":[[1,2.06,39.49],[2,2.34,20.61]],"ltp":4.1,"tv":81.32,"id":12984952},{"batb":[[2,4.1,13.44]],"batl":[[2,6,0]],"ltp":4.4,"tv":44.81,"id":16574984}]}]}
{"op":"mcm","clk":"1009525539","pt":1580645064522,"mc":[{"id":"1.168217555","rc":[{"batb":[[1,1.72,23.21],[2,1.01,0.51]],"ltp":4.1,"tv":81.32,"id":12984952}]}]}
{"op":"mcm","clk":"1009525763","pt":1580645066135,"mc":[{"id":"1.168217555","rc":[{"batb":[[0,3.2,20.14],[1,1.01,0.51],[2,3.65,0]],"batl":[[0,4.6,21.01],[1,4.1,0],[2,4.6,0]],"ltp":5.2,"tv":21.28,"id":12984951},{"batb":[[0,1.72,23.21],[1,1.01,0.51],[2,1.01,0]],"batl":[[0,2.34,20.61],[1,2.06,0],[2,2.34,0]],"ltp":4.1,"tv":81.32,"id":12984952},{"batb":[[0,3.7,14.71],[1,1.01,0.51],[2,4.1,0]],"batl":[[0,5.4,15.11],[1,5.4,0]],"ltp":4.4,"tv":44.81,"id":16574984}]}]}
{"op":"mcm","clk":"1009526084","pt":1580645068462,"mc":[{"id":"1.168217555","rc":[{"batb":[[0,3.2,59.43],[1,3.15,49.23],[2,1.01,0.51]],"ltp":5.2,"tv":21.28,"id":12984951},{"batb":[[0,1.72,111.34],[1,1.7,114.47],[2,1.01,0.51]],"ltp":4.1,"tv":81.32,"id":12984952},{"batb":[[0,3.8,27.58],[1,3.75,32.67],[2,3.7,14.71]],"ltp":4.4,"tv":44.81,"id":16574984}]}]}
{"op":"mcm","clk":"1009528280","pt":1580645085255,"mc":[{"id":"1.168217555","rc":[{"batb":[[0,3.2,20.14],[1,1.01,0.51],[2,1.01,0]],"ltp":5.2,"tv":21.28,"id":12984951},{"batb":[[0,3.7,14.71],[1,1.01,0.51],[2,3.7,0]],"ltp":4.4,"tv":44.81,"id":16574984}]}]}
{"op":"mcm","clk":"1009528746","pt":1580645088480,"mc":[{"id":"1.168217555","rc":[{"batb":[[0,4.1,38.65],[1,4,54.48],[2,3.2,20.14]],"ltp":5.2,"tv":21.28,"id":12984951},{"batb":[[0,4.9,45.88],[1,4.8,36.08],[2,3.7,14.71]],"ltp":4.4,"tv":44.81,"id":16574984}]}]}
{"op":"mcm","clk":"1009528830","pt":1580645089069,"mc":[{"id":"1.168217555","rc":[{"batb":[[0,4.1,60.76],[2,3.75,15.12]],"batl":[[0,4.4,11.76],[1,4.6,21.01],[2,5,17.78]],"ltp":5.2,"tv":21.28,"id":12984951},{"batb":[[2,1.62,28.33]],"batl":[[0,1.79,22.74],[1,1.9,42.01],[2,2.02,15.82]],"ltp":4.1,"tv":81.32,"id":12984952},{"batb":[[2,4.7,15.82]],"batl":[[1,5.9,12.35]],"ltp":4.4,"tv":44.81,"id":16574984}]}]}
{"op":"mcm","clk":"1009529833","pt":1580645096480,"mc":[{"id":"1.168217555","rc":[{"batb":[[0,3.75,15.12],[1,3.6,14.71],[2,1.01,0.51]],"batl":[[1,5,17.78],[2,5,0]],"ltp":5.2,"tv":21.28,"id":12984951},{"batb":[[0,1.62,28.33],[1,1.01,0.51],[2,1.62,0]],"batl":[[0,1.9,42.01],[1,2.02,15.82],[2,2.02,0]],"ltp":4.1,"tv":81.32,"id":12984952},{"batb":[[0,4.5,11.76],[1,4.1,22.11],[2,1.01,0.51]],"batl":[[0,5.9,12.35],[1,5.9,0]],"ltp":4.4,"tv":44.81,"id":16574984}]}]}
{"op":"mcm","clk":"1009530050","pt":1580645098098,"mc":[{"id":"1.168217555","rc":[{"batb":[[0,3.6,14.71],[1,1.01,0.51],[2,1.01,0]],"batl":[[0,5,17.78],[1,5,0]],"ltp":5.2,"tv":21.28,"id":12984951},{"batl":[[0,2.02,15.82],[1,2.02,0]],"ltp":4.1,"tv":81.32,"id":12984952},{"batb":[[0,4.1,22.11],[1,1.01,0.51],[2,1.01,0]],"ltp":4.4,"tv":44.81,"id":16574984}]}]}
{"op":"mcm","clk":"1009530657","pt":1580645102505,"mc":[{"id":"1.168217555","rc":[{"batb":[[0,4,36.41],[1,3.95,28.44],[2,3.6,14.71]],"ltp":5.2,"tv":21.28,"id":12984951},{"batb":[[0,1.76,68.39],[1,1.74,105.61],[2,1.62,28.33]],"ltp":4.1,"tv":81.32,"id":12984952},{"batb":[[0,4.8,31.25],[1,4.7,38.1],[2,4.1,22.11]],"ltp":4.4,"tv":44.81,"id":16574984}]}]}
{"op":"mcm","clk":"1009531679","pt":1580645109099,"mc":[{"id":"1.168217555","rc":[{"batb":[[0,3.6,14.71],[1,1.01,0.51],[2,3.6,0]],"ltp":5.2,"tv":21.28,"id":12984951},{"batb":[[0,1.62,28.33],[1,1.01,0.51],[2,1.62,0]],"ltp":4.1,"tv":81.32,"id":12984952},{"batb":[[0,4.1,22.11],[1,1.01,0.51],[2,4.1,0]],"ltp":4.4,"tv":44.81,"id":16574984}]}]}
{"op":"mcm","clk":"1009532147","pt":1580645112307,"mc":[{"id":"1.168217555","rc":[{"batb":[[0,3.6,74.01],[1,3.55,36.53],[2,1.01,0.51]],"ltp":5.2,"tv":21.28,"id":12984951},{"batb":[[0,1.63,89.6],[1,1.62,96.75],[2,1.01,0.51]],"ltp":4.1,"tv":81.32,"id":12984952},{"batb":[[0,4.3,35],[1,4.2,49.31],[2,4.1,22.11]],"ltp":4.4,"tv":44.81,"id":16574984}]}]}
{"op":"mcm","clk":"1009534443","pt":1580645128313,"mc":[{"id":"1.168217555","rc":[{"batb":[[0,3.6,14.71],[1,1.01,0.51],[2,1.01,0]],"ltp":5.2,"tv":21.28,"id":12984951},{"batb":[[0,4.1,22.11],[1,1.01,0.51],[2,4.1,0]],"ltp":4.4,"tv":44.81,"id":16574984}]}]}
{"op":"mcm","clk":"1009534879","pt":1580645131442,"mc":[{"id":"1.168217555","rc":[{"batb":[[0,4.4,41.84],[1,4.3,45.96],[2,3.6,14.71]],"ltp":5.2,"tv":21.28,"id":12984951},{"batb":[[0,5.4,20.14],[1,5.3,29.18],[2,4.1,22.11]],"ltp":4.4,"tv":44.81,"id":16574984}]}]}
{"op":"mcm","clk":"1009534973","pt":1580645132138,"mc":[{"id":"1.168217555","rc":[{"batb":[[0,4.4,60.57],[2,4.1,22.03]],"batl":[[1,5.2,16.21]],"ltp":5.2,"tv":21.28,"id":12984951},{"batb":[[2,1.57,31.71]],"batl":[[0,1.69,27.7],[1,1.79,22.66]],"ltp":4.1,"tv":81.32,"id":12984952},{"batb":[[2,5.2,12.83]],"batl":[[1,6.4,10.86]],"ltp":4.4,"tv":44.81,"id":16574984}]}]}
{"op":"mcm","clk":"1009535139","pt":1580645133435,"mc":[{"id":"1.168217555","rc":[{"batl":[[0,4.7,10.92],[1,5,17.78],[2,5.2,16.21]],"ltp":5.2,"tv":21.28,"id":12984951},{"batl":[[2,1.8,42.01]],"ltp":4.1,"tv":81.32,"id":12984952}]}]}
{"op":"mcm","clk":"1009537389","pt":1580645149364,"mc":[{"id":"1.168217555","rc":[{"batb":[[0,4.1,22.03],[1,4,13.44],[2,1.01,0.51]],"batl":[[1,5.2,16.21],[2,5.2,0]],"ltp":5.2,"tv":21.28,"id":12984951},{"batb":[[0,1.57,31.71],[1,1.01,0.51],[2,1.57,0]],"batl":[[0,1.79,22.66],[1,1.8,42.01],[2,1.8,0]],"ltp":4.1,"tv":81.32,"id":12984952},{"batb":[[0,4.8,10.92],[1,4.7,16.05],[2,1.01,0.51]],"batl":[[0,6.4,10.86],[1,6.4,0]],"ltp":4.4,"tv":44.81,"id":16574984}]}]}
{"op":"mcm","clk":"1009537491","pt":1580645150155,"mc":[{"id":"1.168217555","rc":[{"batb":[[1,1.01,0.51],[2,1.01,0]],"batl":[[0,5.2,16.21],[1,5.2,0]],"ltp":5.2,"tv":21.28,"id":12984951},{"batl":[[1,1.8,0]],"ltp":4.1,"tv":81.32,"id":12984952},{"batb":[[0,4.7,16.05],[1,1.01,0.51],[2,1.01,0]],"ltp":4.4,"tv":44.81,"id":16574984}]}]}
{"op":"mcm","clk":"1009537739","pt":1580645151864,"mc":[{"id":"1.168217555","rc":[{"batb":[[0,4.1,87.39],[1,4,54.02],[2,1.01,0.51]],"ltp":5.2,"tv":21.28,"id":12984951},{"batb":[[0,1.59,88.17],[1,1.58,75.17],[2,1.57,31.71]],"ltp":4.1,"tv":81.32,"id":12984952},{"batb":[[0,4.9,42.36],[1,4.8,36.13],[2,4.7,16.05]],"ltp":4.4,"tv":44.81,"id":16574984}]}]}
{"op":"mcm","clk":"1009538109","pt":1580645154463,"mc":[{"id":"1.168217555","rc":[{"batb":[[0,4.1,22.03],[1,1.01,0.51],[2,1.01,0]],"ltp":5.2,"tv":21.28,"id":12984951},{"batb":[[0,4.7,16.05],[1,1.01,0.51],[2,4.7,0]],"ltp":4.4,"tv":44.81,"id":16574984}]}]}
{"op":"mcm","clk":"1009538501","pt":1580645157188,"mc":[{"id":"1.168217555","rc":[{"batb":[[0,4.5,62.66],[1,4.4,43.21],[2,4.1,22.03]],"ltp":5.2,"tv":21.28,"id":12984951},{"batb":[[0,5.6,36.4],[1,5.5,26.63],[2,4.7,16.05]],"ltp":4.4,"tv":44.81,"id":16574984}]}]}
{"op":"mcm","clk":"1009538645","pt":1580645158255,"mc":[{"id":"1.168217555","rc":[{"batb":[[0,4.5,79.66],[2,4.1,21.48]],"batl":[[1,6.2,10.86]],"ltp":5.2,"tv":21.28,"id":12984951},{"batl":[[0,1.64,31],[1,1.76,24.23]],"ltp":4.1,"tv":81.32,"id":12984952},{"batb":[[1,5.5,37.88],[2,4.9,14.48]],"batl":[[1,7.8,14.01]],"ltp":4.4,"tv":44.81,"id":16574984}]}]}
{"op":"mcm","clk":"1009538800","pt":1580645159471,"mc":[{"id":"1.168217555","rc":[{"batb":[[2,4.2,12.6]],"batl":[[0,4.9,10.08],[1,5.2,16.21],[2,6.2,10.86]],"ltp":5.2,"tv":21.28,"id":12984951},{"batl":[[1,1.74,42.01],[2,1.76,24.23]],"ltp":4.1,"tv":81.32,"id":12984952},{"batb":[[2,5.1,10.08]],"ltp":4.4,"tv":44.81,"id":16574984}]}]}
{"op":"mcm","clk":"1009541930","pt":1580645182242,"mc":[{"id":"1.168217555","rc":[{"batb":[[0,4.5,58.72],[1,4.2,12.6],[2,4.1,21.48]],"ltp":5.2,"tv":21.28,"id":12984951},{"batb":[[0,5.5,37.88],[1,5.1,10.08],[2,4.9,14.48]],"ltp":4.4,"tv":44.81,"id":16574984}]}]}
{"op":"mcm","clk":"1009542437","pt":1580645185237,"mc":[{"id":"1.168217555","rc":[{"batb":[[0,4.6,25.59],[1,4.5,58.72],[2,4.2,12.6]],"ltp":5.2,"tv":21.28,"id":12984951},{"batb":[[0,1.59,119.3]],"ltp":4.1,"tv":81.32,"id":12984952},{"batb":[[0,5.5,54.85],[1,5.4,27.35],[2,5.1,10.08]],"ltp":4.4,"tv":44.81,"id":16574984}]}]}
{"op":"mcm","clk":"1009543023","pt":1580645189273,"mc":[{"id":"1.168217555","rc":[{"batb":[[0,4.2,12.6],[1,4.1,21.48],[2,1.01,0.51]],"batl":[[1,6.2,10.86],[2,6.2,0]],"ltp":5.2,"tv":21.28,"id":12984951},{"batb":[[0,1.42,46.74],[1,1.01,0.51],[2,1.57,0]],"batl":[[0,1.74,42.01],[1,1.76,24.23],[2,1.76,0]],"ltp":4.1,"tv":81.32,"id":12984952},{"batb":[[0,5.1,10.08],[1,4.9,14.48],[2,1.01,0.51]],"batl":[[0,7.8,14.01],[1,7.8,0]],"ltp":4.4,"tv":44.81,"id":16574984}]}]}
{"op":"mcm","clk":"1009543114","pt":1580645190072,"mc":[{"id":"1.168217555","rc":[{"batb":[[0,4.1,21.48],[1,1.01,0.51],[2,1.01,0]],"batl":[[0,6.2,10.86],[1,6.2,0]],"ltp":5.2,"tv":21.28,"id":12984951},{"batl":[[0,1.76,24.23],[1,1.76,0]],"ltp":4.1,"tv":81.32,"id":12984952},{"batb":[[0,4.9,14.48],[1,1.01,0.51],[2,1.01,0]],"ltp":4.4,"tv":44.81,"id":16574984}]}]}
{"op":"mcm","clk":"1009543459","pt":1580645192393,"mc":[{"id":"1.168217555","rc":[{"batb":[[0,4.1,84.72],[1,4,54.12],[2,1.01,0.51]],"ltp":5.2,"tv":21.28,"id":12984951},{"batb":[[0,1.45,78.05],[1,1.44,109.01],[2,1.43,46.74]],"ltp":4.1,"tv":81.32,"id":12984952},{"batb":[[0,5,32.91],[1,4.9,48.72],[2,1.01,0.51]],"ltp":4.4,"tv":44.81,"id":16574984}]}]}
{"op":"mcm","clk":"1009545971","pt":1580645210081,"mc":[{"id":"1.168217555","rc":[{"batb":[[0,1.43,46.74],[1,1.01,0.51],[2,1.43,0]],"ltp":4.1,"tv":81.32,"id":12984952}]}]}
{"op":"mcm","clk":"1009546488","pt":1580645213377,"mc":[{"id":"1.168217555","rc":[{"batb":[[0,1.7,115.06],[1,1.68,119.23],[2,1.43,46.74]],"ltp":4.1,"tv":81.32,"id":12984952}]}]}
{"op":"mcm","clk":"1009546627","pt":1580645214287,"mc":[{"id":"1.168217555","rc":[{"batb":[[2,3.85,25.34]],"batl":[[0,4.7,20.38],[1,5.3,15.26]],"ltp":5.2,"tv":21.28,"id":12984951},{"batb":[[1,1.69,24.71],[2,1.68,119.23]],"batl":[[1,1.86,20.06]],"ltp":4.1,"tv":81.32,"id":12984952},{"batb":[[2,4.6,17.31]],"batl":[[0,5.6,13.85],[1,6.6,19.51]],"ltp":4.4,"tv":44.81,"id":16574984}]}]}
{"op":"mcm","clk":"1009546733","pt":1580645215102,"mc":[{"id":"1.168217555","rc":[{"batb":[[2,3.85,39.62]],"batl":[[0,4.4,11.76],[1,4.7,20.38],[2,5.3,15.26]],"ltp":5.2,"tv":21.28,"id":12984951},{"batl":[[1,1.85,42.01],[2,1.86,20.06]],"ltp":4.1,"tv":81.32,"id":12984952},{"batb":[[2,4.7,10.92]],"ltp":4.4,"tv":44.81,"id":16574984}]}]}
{"op":"mcm","clk":"1009549420","pt":1580645232324,"mc":[{"id":"1.168217555","rc":[{"batb":[[0,3.85,25.34],[1,1.01,0.51],[2,3.85,0]],"batl":[[0,5.3,15.26],[1,4.7,0],[2,5.3,0]],"ltp":5.2,"tv":21.28,"id":12984951},{"batb":[[0,1.54,34.07],[1,1.01,0.51],[2,1.68,0]],"batl":[[0,1.86,20.06],[1,1.85,0],[2,1.86,0]],"ltp":4.1,"tv":81.32,"id":12984952},{"batb":[[0,4.6,17.31],[1,1.01,0.51],[2,4.7,0]],"batl":[[0,6.6,19.51],[1,6.6,0]],"ltp":4.4,"tv":44.81,"id":16574984}]}]}
{"op":"mcm","clk":"1009550380","pt":1580645238247,"mc":[{"id":"1.168217555","rc":[{"batb":[[0,4.2,60.38],[1,4.1,51.11],[2,3.85,25.34]],"ltp":5.2,"tv":21.28,"id":12984951},{"batb":[[0,1.67,119.68],[1,1.66,62.61],[2,1.54,34.07]],"ltp":4.1,"tv":81.32,"id":12984952},{"batb":[[0,5.1,42.95],[1,5,32.56],[2,4.6,17.31]],"ltp":4.4,"tv":44.81,"id":16574984}]}]}
{"op":"mcm","clk":"1009551055","pt":1580645242331,"mc":[{"id":"1.168217555","rc":[{"batb":[[0,3.85,25.34],[1,1.01,0.51],[2,3.85,0]],"ltp":5.2,"tv":21.28,"id":12984951},{"batb":[[0,1.54,34.07],[1,1.01,0.51],[2,1.54,0]],"ltp":4.1,"tv":81.32,"id":12984952},{"batb":[[0,4.6,17.31],[1,1.01,0.51],[2,4.6,0]],"ltp":4.4,"tv":44.81,"id":16574984}]}]}
{"op":"mcm","clk":"1009551542","pt":1580645245264,"mc":[{"id":"1.168217555","rc":[{"batb":[[0,3.85,74.51],[1,3.8,31.09],[2,1.01,0.51]],"ltp":5.2,"tv":21.28,"id":12984951},{"batb":[[0,1.56,140.89],[1,1.55,80.95],[2,1.54,34.07]],"ltp":4.1,"tv":81.32,"id":12984952},{"batb":[[0,4.6,61.05],[1,4.5,41.41],[2,1.01,0.51]],"ltp":4.4,"tv":44.81,"id":16574984}]}]}
{"op":"mcm","clk":"1009552926","pt":1580645254476,"mc":[{"id":"1.168217555","rc":[{"batb":[[0,3.85,25.34],[1,1.01,0.51],[2,1.01,0]],"ltp":5.2,"tv":21.28,"id":12984951},{"batb":[[0,4.6,17.31],[1,1.01,0.51],[2,1.01,0]],"ltp":4.4,"tv":44.81,"id":16574984}]}]}
{"op":"mcm","clk":"1009553335","pt":1580645257441,"mc":[{"id":"1.168217555","rc":[{"batb":[[0,4.7,31.33],[1,4.6,39.58],[2,3.85,25.34]],"ltp":5.2,"tv":21.28,"id":12984951},{"batb":[[0,5.7,41.12],[1,5.6,25.23],[2,4.6,17.31]],"ltp":4.4,"tv":44.81,"id":16574984}]}]}
{"op":"mcm","clk":"1009553596","pt":1580645259101,"mc":[{"id":"1.168217555","rc":[{"batb":[[0,4.7,47.3],[2,4.2,12.6]],"batl":[[0,5,10.08],[1,5.3,15.26],[2,7,17.86]],"ltp":5.2,"tv":21.28,"id":12984951},{"batl":[[0,1.61,33.28],[1,1.71,42.01],[2,1.74,24.94]],"ltp":4.1,"tv":81.32,"id":12984952},{"batb":[[0,5.7,51.66],[2,5.2,9.24]],"batl":[[1,8.6,11.41]],"ltp":4.4,"tv":44.81,"id":16574984}]}]}
{"op":"mcm","clk":"1009555398","pt":1580645272178,"mc":[{"id":"1.168217555","rc":[{"batb":[[2,4.1,21.32]],"ltp":5.2,"tv":21.28,"id":12984951}]}]}
{"op":"mcm","clk":"1009555795","pt":1580645275109,"mc":[{"id":"1.168217555","rc":[{"batb":[[2,4.3,12.6]],"ltp":5.2,"tv":21.28,"id":12984951}]}]}
{"op":"mcm","clk":"1009556690","pt":1580645281213,"mc":[{"id":"1.168217555","rc":[{"batb":[[0,4.3,12.6],[1,4.1,21.32],[2,1.01,0.51]],"batl":[[1,7,17.86],[2,7,0]],"ltp":5.2,"tv":21.28,"id":12984951},{"batb":[[0,1.37,55.31],[1,1.01,0.51],[2,1.54,0]],"batl":[[0,1.71,42.01],[1,1.74,24.94],[2,1.74,0]],"ltp":4.1,"tv":81.32,"id":12984952},{"batb":[[0,5.2,9.24],[1,5,13.77],[2,1.01,0.51]],"batl":[[0,8.6,11.41],[1,8.6,0]],"ltp":4.4,"tv":44.81,"id":16574984}]}]}
{"op":"mcm","clk":"1009556840","pt":1580645282173,"mc":[{"id":"1.168217555","rc":[{"batb":[[0,4.1,21.32],[1,1.01,0.51],[2,1.01,0]],"batl":[[0,7,17.86],[1,7,0]],"ltp":5.2,"tv":21.28,"id":12984951},{"batl":[[0,1.74,24.94],[1,1.74,0]],"ltp":4.1,"tv":81.32,"id":12984952},{"batb":[[0,5,13.77],[1,1.01,0.51],[2,1.01,0]],"ltp":4.4,"tv":44.81,"id":16574984}]}]}
{"op":"mcm","clk":"1009557091","pt":1580645284029,"mc":[{"id":"1.168217555","rc":[{"batb":[[0,4.1,82.18],[1,4,54.16],[2,1.01,0.51]],"ltp":5.2,"tv":21.28,"id":12984951},{"batb":[[0,1.4,79.29],[1,1.39,127.7],[2,1.37,55.31]],"ltp":4.1,"tv":81.32,"id":12984952},{"batb":[[0,5,64.49],[1,4.9,33.96],[2,1.01,0.51]],"ltp":4.4,"tv":44.81,"id":16574984}]}]}
{"op":"mcm","clk":"1009558061","pt":1580645291002,"mc":[{"id":"1.168217555","rc":[{"batb":[[0,4.1,21.32],[1,1.01,0.51],[2,1.01,0]],"ltp":5.2,"tv":21.28,"id":12984951},{"batb":[[0,5,13.77],[1,1.01,0.51],[2,1.01,0]],"ltp":4.4,"tv":44.81,"id":16574984}]}]}
{"op":"mcm","clk":"1009558421","pt":1580645293498,"mc":[{"id":"1.168217555","rc":[{"batb":[[0,5.9,27.74],[1,5.8,23.53],[2,4.1,21.32]],"ltp":5.2,"tv":21.28,"id":12984951},{"batb":[[0,7.2,36.91],[1,7,30.41],[2,5,13.77]],"ltp":4.4,"tv":44.81,"id":16574984}]}]}
{"op":"mcm","clk":"1009558549","pt":1580645294405,"mc":[{"id":"1.168217555","rc":[{"batb":[[1,5.8,42.73],[2,4.8,14.95]],"batl":[[1,11,7.4]],"ltp":5.2,"tv":21.28,"id":12984951},{"batl":[[0,1.43,53.5],[1,1.57,36.19],[2,1.74,24.94]],"ltp":4.1,"tv":81.32,"id":12984952},{"batb":[[0,7.2,48.95],[2,6,18.65]],"batl":[[1,14,11.49]],"ltp":4.4,"tv":44.81,"id":16574984}]}]}
{"op":"mcm","clk":"1009558650","pt":1580645295097,"mc":[{"id":"1.168217555","rc":[{"batb":[[2,5.2,9.24]],"batl":[[0,6.2,7.56],[1,7,17.86],[2,11,7.4]],"ltp":5.2,"tv":21.28,"id":12984951},{"batl":[[1,1.51,42.01],[2,1.57,36.19]],"ltp":4.1,"tv":81.32,"id":12984952},{"batb":[[2,6.4,7.56]],"ltp":4.4,"tv":44.81,"id":16574984}]}]}
{"op":"mcm","clk":"1009559674","pt":1580645302652,"mc":[{"id":"1.168217555","rc":[{"batb":[[0,7.2,43.61]],"ltp":4.4,"tv":44.81,"id":16574984}]}]}
{"op":"mcm","clk":"1009560029","pt":1580645305105,"mc":[{"id":"1.168217555","rc":[{"batb":[[0,1.01,0.51],[1,1.01,0]],"ltp":5.1,"tv":4.54,"id":16574983}]}]}
{"op":"mcm","clk":"1009561313","pt":1580645314451,"mc":[{"id":"1.168217555","rc":[{"batb":[[0,5.8,19.2],[1,5.2,9.24],[2,4.8,14.95]],"ltp":5.2,"tv":21.28,"id":12984951},{"batb":[[0,1.37,55.31],[1,1.21,109.53],[2,1.01,0.51]],"ltp":4.1,"tv":81.32,"id":12984952},{"batb":[[0,7.2,12.04],[1,6.4,7.56],[2,6,18.65]],"ltp":4.4,"tv":44.81,"id":16574984}]}]}
{"op":"mcm","clk":"1009561403","pt":1580645315044,"mc":[{"id":"1.168217555","rc":[{"batb":[[0,5.2,9.24],[1,4.8,14.95],[2,1.01,0.51]],"batl":[[1,11,7.4],[2,11,0]],"ltp":5.2,"tv":21.28,"id":12984951},{"batb":[[0,1.21,109.53],[1,1.01,0.51],[2,1.01,0]],"batl":[[0,1.51,42.01],[1,1.57,36.19],[2,1.57,0]],"ltp":4.1,"tv":81.32,"id":12984952},{"batb":[[0,6.4,7.56],[1,6,18.65],[2,1.01,0.51]],"batl":[[0,14,11.49],[1,14,0]],"ltp":4.4,"tv":44.81,"id":16574984}]}]}
{"op":"mcm","clk":"1009561588","pt":1580645316429,"mc":[{"id":"1.168217555","rc":[{"batb":[[0,4.8,14.95],[1,1.01,0.51],[2,1.01,0]],"batl":[[0,11,7.4],[1,11,0]],"ltp":5.2,"tv":21.28,"id":12984951},{"batl":[[0,1.57,36.19],[1,1.57,0]],"ltp":4.1,"tv":81.32,"id":12984952},{"batb":[[0,6,18.65],[1,1.01,0.51],[2,1.01,0]],"ltp":4.4,"tv":44.81,"id":16574984}]}]}
{"op":"mcm","clk":"1009561693","pt":1580645317353,"mc":[{"id":"1.168217555","rc":[{"batb":[[0,4.8,55.78],[1,4.7,37.56],[2,1.01,0.51]],"ltp":5.2,"tv":21.28,"id":12984951},{"batb":[[0,1.23,138.92],[1,1.22,261.43],[2,1.21,109.53]],"ltp":4.1,"tv":81.32,"id":12984952},{"batb":[[1,5.9,34.44],[2,5.8,23.33]],"ltp":4.4,"tv":44.81,"id":16574984}]}]}
{"op":"mcm","clk":"1009561821","pt":1580645318244,"mc":[{"id":"1.168217555","rc":[{"batb":[[0,4.8,55.62]],"ltp":5.2,"tv":21.28,"id":12984951},{"batb":[[2,1.21,107.79]],"batl":[[0,1.58,35.49]],"ltp":4.1,"tv":81.32,"id":12984952},{"batb":[[0,5.9,34.44],[1,5.8,43.08],[2,1.01,0.51]],"batl":[[0,13.5,12.2]],"ltp":4.4,"tv":44.81,"id":16574984}]}]}
{"op":"mcm","clk":"1009565028","pt":1580645339776,"mc":[{"id":"1.168217555","rc":[{"batb":[[0,4.8,14.79],[1,1.01,0.51],[2,1.01,0]],"ltp":5.2,"tv":21.28,"id":12984951},{"batb":[[0,5.8,19.75],[1,1.01,0.51],[2,1.01,0]],"ltp":4.4,"tv":44.81,"id":16574984}]}]}
{"op":"mcm","clk":"1009565173","pt":1580645340805,"mc":[{"id":"1.168217555","rc":[{"batb":[[0,5,14.28],[1,1.01,0.51]],"ltp":5.1,"tv":4.54,"id":16574983}]}]}
{"op":"mcm","clk":"1009565633","pt":1580645343493,"mc":[{"id":"1.168217555","rc":[{"batb":[[0,9,11.38],[1,8.8,19.04],[2,8.6,7.71]],"batl":[[0,9.4,4.2],[1,11,7.4],[2,22,4.88]],"ltp":5.2,"tv":21.28,"id":12984951},{"batb":[[0,1.25,168.04],[1,1.23,138.92],[2,1.22,261.43]],"batl":[[0,1.26,102.52],[1,1.31,42.01],[2,1.36,66.64]],"ltp":4.1,"tv":81.32,"id":12984952},{"batb":[[0,11,12.04],[1,10.5,31.64],[2,10,13.3]],"batl":[[0,11.5,3.36],[1,13.5,12.2],[2,27,6.77]],"ltp":4.4,"tv":44.81,"id":16574984}]}]}
{"op":"mcm","clk":"1009569148","pt":1580645366506,"mc":[{"id":"1.168217555","rc":[{"batb":[[0,8.6,7.71],[1,7.4,5.88],[2,6.6,14.16]],"ltp":5.2,"tv":21.28,"id":12984951},{"batb":[[1,1.21,107.79],[2,1.09,255.32]],"ltp":4.1,"tv":81.32,"id":12984952},{"batb":[[0,10,13.3],[1,8.8,5.04],[2,8,9.36]],"ltp":4.4,"tv":44.81,"id":16574984}]}]}
{"op":"mcm","clk":"1009569174","pt":1580645366741,"mc":[{"id":"1.168217555","rc":[{"batb":[[0,7.4,5.88],[1,6.6,14.16],[2,1.01,0.51]],"batl":[[1,22,4.88],[2,22,0]],"ltp":5.2,"tv":21.28,"id":12984951},{"batb":[[1,1.09,255.09],[2,1.01,0.51]],"batl":[[0,1.31,42.01],[1,1.36,66.64],[2,1.36,0]],"ltp":4.1,"tv":81.32,"id":12984952},{"batb":[[0,8.8,5.04],[1,8,9.36],[2,1.01,0.51]],"batl":[[1,27,6.77],[2,27,0]],"ltp":4.4,"tv":44.81,"id":16574984}]}]}
{"op":"mcm","clk":"1009569400","pt":1580645368224,"mc":[{"id":"1.168217555","rc":[{"batb":[[0,6.6,14.16],[1,1.01,0.51],[2,1.01,0]],"batl":[[0,22,4.88],[1,22,0]],"ltp":5.2,"tv":21.28,"id":12984951},{"batb":[[0,1.09,255.09],[1,1.01,0.51],[2,1.01,0]],"batl":[[0,1.36,66.64],[1,1.36,0]],"ltp":4.1,"tv":81.32,"id":12984952},{"batb":[[0,8,9.36],[1,1.01,0.51],[2,1.01,0]],"batl":[[0,27,6.77],[1,27,0]],"ltp":4.4,"tv":44.81,"id":16574984}]}]}
{"op":"mcm","clk":"1009569560","pt":1580645369401,"mc":[{"id":"1.168217555","rc":[{"batb":[[0,6.8,17.79],[1,6.6,49.28],[2,1.01,0.51]],"ltp":5.2,"tv":21.28,"id":12984951},{"batb":[[0,1.11,177.22],[1,1.1,434.14],[2,1.09,255.09]],"ltp":4.1,"tv":81.32,"id":12984952},{"batb":[[0,8.4,12.16],[1,8.2,21.99],[2,8,9.36]],"ltp":4.4,"tv":44.81,"id":16574984}]}]}
{"op":"mcm","clk":"1009570467","pt":1580645375327,"mc":[{"id":"1.168217555","rc":[{"batb":[[0,1.01,0.51],[1,1.01,0]],"ltp":5.1,"tv":4.54,"id":16574983}]}]}
{"op":"mcm","clk":"1009572161","pt":1580645387114,"mc":[{"id":"1.168217555","rc":[{"batb":[[0,8.4,20.77]],"ltp":4.4,"tv":44.81,"id":16574984}]}]}
{"op":"mcm","clk":"1009574010","pt":1580645401474,"mc":[{"id":"1.168217555","rc":[{"batb":[[0,6.6,14.16],[1,1.01,0.51],[2,1.01,0]],"ltp":5.2,"tv":21.28,"id":12984951},{"batb":[[0,8,9.36],[1,1.01,0.51],[2,8,0]],"ltp":4.4,"tv":44.81,"id":16574984}]}]}
{"op":"mcm","clk":"1009574430","pt":1580645404463,"mc":[{"id":"1.168217555","rc":[{"batb":[[0,16.5,17.28],[1,16,13.13],[2,6.6,14.16]],"ltp":5.2,"tv":21.28,"id":12984951},{"batb":[[0,20,16.8],[1,19.5,8.74],[2,8,9.36]],"ltp":4.4,"tv":44.81,"id":16574984}]}]}
{"op":"mcm","clk":"1009574558","pt":1580645405469,"mc":[{"id":"1.168217555","rc":[{"batb":[[2,15.5,5.11]],"ltp":5.2,"tv":21.28,"id":12984951},{"batl":[[0,1.13,138.95],[1,1.21,137.46],[2,1.36,66.64]],"ltp":4.1,"tv":81.32,"id":12984952},{"batb":[[2,17.5,7.47]],"ltp":4.4,"tv":44.81,"id":16574984}]}]}
{"op":"mcm","clk":"1009574576","pt":1580645405575,"mc":[{"id":"1.168217555","rc":[{"batl":[[2,1.36,0]],"ltp":4.1,"tv":81.32,"id":12984952}]}]}
{"op":"mcm","clk":"1009574927","pt":1580645408138,"mc":[{"id":"1.168217555","rc":[{"batb":[[0,16.5,15.15]],"ltp":5.2,"tv":21.28,"id":12984951},{"batl":[[1,1.15,42.01],[2,1.21,137.46]],"ltp":4.1,"tv":81.32,"id":12984952}]}]}
{"op":"mcm","clk":"1009587730","pt":1580645500301,"mc":[{"id":"1.168217555","rc":[{"batb":[[0,10.5,12.43],[1,1.01,0.51],[2,15.5,0]],"ltp":5.2,"tv":21.28,"id":12984951},{"batb":[[0,1.06,373.27],[1,1.01,0.51],[2,1.09,0]],"batl":[[0,1.21,137.46],[1,1.15,0],[2,1.21,0]],"ltp":4.1,"tv":81.32,"id":12984952},{"batb":[[0,12.5,8.66],[1,1.01,0.51],[2,17.5,0]],"ltp":4.4,"tv":44.81,"id":16574984}]}]}
{"op":"mcm","clk":"1009588036","pt":1580645502711,"mc":[{"id":"1.168217555","rc":[{"batb":[[0,11,26.84],[1,10.5,43.46],[2,1.01,0.51]],"ltp":5.2,"tv":21.28,"id":12984951},{"batb":[[0,1.08,183.56],[1,1.07,444.89],[2,1.06,373.27]],"ltp":4.1,"tv":81.32,"id":12984952},{"batb":[[0,13.5,17.04],[1,13,20.22],[2,12.5,8.66]],"ltp":4.4,"tv":44.81,"id":16574984}]}]}
{"op":"mcm","clk":"1009588193","pt":1580645504016,"mc":[{"id":"1.168217555","rc":[{"batb":[[0,1.06,373.27],[1,1.01,0.51],[2,1.06,0]],"ltp":4.1,"tv":81.32,"id":12984952}]}]}
{"op":"mcm","clk":"1009588657","pt":1580645507389,"mc":[{"id":"1.168217555","rc":[{"batb":[[2,9.6,4.2]],"batl":[[0,12,3.36]],"ltp":5.2,"tv":21.28,"id":12984951},{"batb":[[0,1.18,168.04],[1,1.17,334.78],[2,1.16,243.61]],"batl":[[1,1.23,42.01]],"ltp":4.1,"tv":81.32,"id":12984952}]}]}
{"op":"mcm","clk":"1009588767","pt":1580645508314,"mc":[{"id":"1.168217555","rc":[{"batl":[[1,14,11.41],[2,19.5,6.06]],"ltp":5.2,"tv":21.28,"id":12984951},{"batb":[[2,1.16,389.96]],"batl":[[2,1.33,75.61]],"ltp":4.1,"tv":81.32,"id":12984952},{"batl":[[0,16.5,8.1],[1,24,4.33]],"ltp":4.4,"tv":44.81,"id":16574984}]}]}
{"op":"mcm","clk":"1009590096","pt":1580645518499,"mc":[{"id":"1.168217555","rc":[{"batb":[[0,10.5,12.43],[1,9.6,4.2],[2,7.2,11.57]],"ltp":5.2,"tv":21.28,"id":12984951},{"batb":[[1,1.16,146.35],[2,1.11,220.78]],"ltp":4.1,"tv":81.32,"id":12984952},{"batb":[[0,12.5,8.66],[1,11.5,3.36],[2,8.6,8.26]],"ltp":4.4,"tv":44.81,"id":16574984}]}]}
{"op":"mcm","clk":"1009590132","pt":1580645518776,"mc":[{"id":"1.168217555","rc":[{"batb":[[0,9.6,4.2],[1,7.2,11.57],[2,1.01,0.51]],"batl":[[1,19.5,6.06],[2,19.5,0]],"ltp":5.2,"tv":21.28,"id":12984951},{"batb":[[1,1.11,220.78],[2,1.01,0.51]],"batl":[[0,1.23,42.01],[1,1.33,75.61],[2,1.33,0]],"ltp":4.1,"tv":81.32,"id":12984952},{"batb":[[0,11.5,3.36],[1,8.6,8.26],[2,1.01,0.51]],"batl":[[0,24,4.33],[1,24,0]],"ltp":4.4,"tv":44.81,"id":16574984}]}]}
{"op":"mcm","clk":"1009590338","pt":1580645520477,"mc":[{"id":"1.168217555","rc":[{"batb":[[0,7.2,11.57],[1,1.01,0.51],[2,1.01,0]],"batl":[[0,19.5,6.06],[1,19.5,0]],"ltp":5.2,"tv":21.28,"id":12984951},{"batb":[[0,1.11,220.78],[1,1.01,0.51],[2,1.01,0]],"batl":[[0,1.33,75.61],[1,1.33,0]],"ltp":4.1,"tv":81.32,"id":12984952},{"batb":[[0,8.6,8.26],[1,1.01,0.51],[2,1.01,0]],"ltp":4.4,"tv":44.81,"id":16574984}]}]}
{"op":"mcm","clk":"1009590478","pt":1580645521487,"mc":[{"id":"1.168217555","rc":[{"batb":[[0,7.4,36.22],[1,7.2,40.09],[2,1.01,0.51]],"ltp":5.2,"tv":21.28,"id":12984951},{"batb":[[0,1.12,357.69],[1,1.11,467.32],[2,1.01,0.51]],"ltp":4.1,"tv":81.32,"id":12984952},{"batb":[[0,9,28.73],[1,8.8,18.67],[2,8.6,8.26]],"ltp":4.4,"tv":44.81,"id":16574984}]}]}
{"op":"mcm","clk":"1009590611","pt":1580645522399,"mc":[{"id":"1.168217555","rc":[{"batb":[[0,7.2,11.57],[1,1.01,0.51],[2,1.01,0]],"ltp":5.2,"tv":21.28,"id":12984951},{"batb":[[0,1.11,220.78],[1,1.01,0.51],[2,1.01,0]],"ltp":4.1,"tv":81.32,"id":12984952},{"batb":[[0,8.6,8.26],[1,1.01,0.51],[2,8.6,0]],"ltp":4.4,"tv":44.81,"id":16574984}]}]}
{"op":"mcm","clk":"1009590804","pt":1580645523876,"mc":[{"id":"1.168217555","rc":[{"batb":[[0,10,30.57],[1,9.8,14.73],[2,7.2,11.57]],"ltp":5.2,"tv":21.28,"id":12984951},{"batb":[[0,1.19,339.07],[1,1.18,229.47],[2,1.11,220.78]],"ltp":4.1,"tv":81.32,"id":12984952},{"batb":[[0,12.5,8.5],[1,12,24.22],[2,8.6,8.26]],"ltp":4.4,"tv":44.81,"id":16574984}]}]}
{"op":"mcm","clk":"1009591298","pt":1580645527278,"mc":[{"id":"1.168217555","rc":[{"batb":[[0,7.2,11.57],[1,1.01,0.51],[2,7.2,0]],"ltp":5.2,"tv":21.28,"id":12984951},{"batb":[[0,1.11,220.78],[1,1.01,0.51],[2,1.11,0]],"ltp":4.1,"tv":81.32,"id":12984952},{"batb":[[0,8.6,8.26],[1,1.01,0.51],[2,8.6,0]],"ltp":4.4,"tv":44.81,"id":16574984}]}]}
{"op":"mcm","clk":"1009591677","pt":1580645530300,"mc":[{"id":"1.168217555","rc":[{"batb":[[0,7.4,36.22],[1,7.2,40.09],[2,1.01,0.51]],"ltp":5.2,"tv":21.28,"id":12984951},{"batb":[[0,1.12,357.69],[1,1.11,467.32],[2,1.01,0.51]],"ltp":4.1,"tv":81.32,"id":12984952},{"batb":[[0,9,28.73],[1,8.8,18.67],[2,8.6,8.26]],"ltp":4.4,"tv":44.81,"id":16574984}]}]}
{"op":"mcm","clk":"1009591858","pt":1580645531622,"mc":[{"id":"1.168217555","rc":[{"batb":[[0,7.2,11.57],[1,1.01,0.51],[2,1.01,0]],"ltp":5.2,"tv":21.28,"id":12984951},{"batb":[[0,8.6,8.26],[1,1.01,0.51],[2,8.6,0]],"ltp":4.4,"tv":44.81,"id":16574984}]}]}
{"op":"mcm","clk":"1009592235","pt":1580645534485,"mc":[{"id":"1.168217555","rc":[{"batb":[[0,15,14.46],[1,14.5,16.13],[2,7.2,11.57]],"ltp":5.2,"tv":21.28,"id":12984951},{"batb":[[0,18.5,6.64],[1,18,10.55],[2,8.6,8.26]],"ltp":4.4,"tv":44.81,"id":16574984}]}]}
{"op":"mcm","clk":"1009592386","pt":1580645535484,"mc":[{"id":"1.168217555","rc":[{"batb":[[2,14,6.53]],"batl":[[1,30,5.67]],"ltp":5.2,"tv":21.28,"id":12984951},{"batb":[[0,1.13,168.04],[1,1.12,357.69],[2,1.11,467.32]],"batl":[[0,1.15,144.7],[1,1.17,42.01],[2,1.25,108.97]],"ltp":4.1,"tv":81.32,"id":12984952},{"batb":[[2,16,4.64]],"ltp":4.4,"tv":44.81,"id":16574984}]}]}
{"op":"mcm","clk":"1009594627","pt":1580645551509,"mc":[{"id":"1.168217555","rc":[{"batb":[[0,14,6.53],[1,12.5,3.36],[2,9,7.08]],"ltp":5.2,"tv":21.28,"id":12984951},{"batb":[[1,1.11,220.78],[2,1.06,352.42]],"ltp":4.1,"tv":81.32,"id":12984952},{"batb":[[0,16,4.64],[1,10.5,12.67],[2,1.01,0.51]],"ltp":4.4,"tv":44.81,"id":16574984}]}]}
{"op":"mcm","clk":"1009594786","pt":1580645552313,"mc":[{"id":"1.168217555","rc":[{"batb":[[0,9,7.08],[1,1.01,0.51],[2,9,0]],"batl":[[0,30,5.67],[1,30,0]],"ltp":5.2,"tv":21.28,"id":12984951},{"batb":[[0,1.06,352.42],[1,1.01,0.51],[2,1.06,0]],"batl":[[0,1.25,108.97],[1,1.17,0],[2,1.25,0]],"ltp":4.1,"tv":81.32,"id":12984952},{"batb":[[0,10.5,12.67],[1,1.01,0.51],[2,1.01,0]],"ltp":4.4,"tv":44.81,"id":16574984}]}]}
{"op":"mcm","clk":"1009595118","pt":1580645554338,"mc":[{"id":"1.168217555","rc":[{"batb":[[0,9.6,14.77],[1,9.4,16.41],[2,9,7.08]],"ltp":5.2,"tv":21.28,"id":12984951},{"batb":[[0,1.08,445.05],[1,1.07,180.95],[2,1.06,352.42]],"ltp":4.1,"tv":81.32,"id":12984952},{"batb":[[0,11.5,22.39],[1,11,28.43],[2,10.5,12.67]],"ltp":4.4,"tv":44.81,"id":16574984}]}]}
{"op":"mcm","clk":"1009595407","pt":1580645555640,"mc":[{"id":"1.168217555","rc":[{"batb":[[0,9,7.08],[1,1.01,0.51],[2,9,0]],"ltp":5.2,"tv":21.28,"id":12984951},{"batb":[[0,10.5,12.67],[1,1.01,0.51],[2,10.5,0]],"ltp":4.4,"tv":44.81,"id":16574984}]}]}
{"op":"mcm","clk":"1009596104","pt":1580645559393,"mc":[{"id":"1.168217555","rc":[{"batb":[[0,21,16.6],[1,20,16.05],[2,19,6.22]],"ltp":5.2,"tv":21.28,"id":12984951},{"batl":[[0,1.11,150.99],[1,1.17,146.82]],"ltp":4.1,"tv":81.32,"id":12984952},{"batb":[[0,26,8.71],[1,25,10.47],[2,22,3.89]],"ltp":4.4,"tv":44.81,"id":16574984}]}]}
{"op":"mcm","clk":"1009597167","pt":1580645566252,"mc":[{"id":"1.168217555","rc":[{"batb":[[0,19,6.22],[1,12.5,8.1],[2,1.01,0.51]],"ltp":5.2,"tv":21.28,"id":12984951},{"batb":[[0,1.06,352.42],[1,1.04,561.71],[2,1.01,0.51]],"ltp":4.1,"tv":81.32,"id":12984952},{"batb":[[0,22,3.89],[1,14.5,5.82],[2,1.01,0.51]],"ltp":4.4,"tv":44.81,"id":16574984}]}]}
{"op":"mcm","clk":"1009597344","pt":1580645567344,"mc":[{"id":"1.168217555","rc":[{"batb":[[0,12.5,8.1],[1,1.01,0.51],[2,1.01,0]],"ltp":5.2,"tv":21.28,"id":12984951},{"batb":[[0,1.04,561.71],[1,1.01,0.51],[2,1.01,0]],"batl":[[0,1.17,146.82],[1,1.17,0]],"ltp":4.1,"tv":81.32,"id":12984952},{"batb":[[0,14.5,5.82],[1,1.01,0.51],[2,1.01,0]],"ltp":4.4,"tv":44.81,"id":16574984}]}]}
{"op":"mcm","clk":"1009597633","pt":1580645569262,"mc":[{"id":"1.168217555","rc":[{"batb":[[0,13.5,19.15],[1,13,20.08],[2,12.5,8.1]],"ltp":5.2,"tv":21.28,"id":12984951},{"batb":[[0,1.05,642.17],[1,1.04,561.71],[2,1.01,0.51]],"ltp":4.1,"tv":81.32,"id":12984952},{"batb":[[0,16.5,10.46],[1,16,13.27],[2,14.5,5.82]],"ltp":4.4,"tv":44.81,"id":16574984}]}]}
{"op":"mcm","clk":"1009597785","pt":1580645570134,"mc":[{"id":"1.168217555","rc":[{"batb":[[0,1.04,561.71],[1,1.01,0.51],[2,1.01,0]],"ltp":4.1,"tv":81.32,"id":12984952}]}]}
{"op":"mcm","clk":"1009598330","pt":1580645573448,"mc":[{"id":"1.168217555","rc":[{"batb":[[0,1.14,119.38],[1,1.13,476.27],[2,1.04,561.71]],"ltp":4.1,"tv":81.32,"id":12984952}]}]}
{"op":"mcm","clk":"1009598407","pt":1580645573941,"mc":[{"id":"1.168217555","rc":[{"batl":[[0,17.5,7.55]],"ltp":5.2,"tv":21.28,"id":12984951},{"batb":[[2,1.12,191.43]],"batl":[[1,1.31,81.12]],"ltp":4.1,"tv":81.32,"id":12984952},{"batl":[[0,21,5.51]],"ltp":4.4,"tv":44.81,"id":16574984}]}]}
{"op":"mcm","clk":"1009598623","pt":1580645575262,"mc":[{"id":"1.168217555","rc":[{"batb":[[0,1.14,287.42]],"batl":[[1,1.18,42.01],[2,1.31,81.12]],"ltp":4.1,"tv":81.32,"id":12984952}]}]}
{"op":"mcm","clk":"1009600494","pt":1580645587464,"mc":[{"id":"1.168217555","rc":[{"batb":[[0,12.5,8.1],[1,11.5,3.36],[2,7.4,10.7]],"ltp":5.2,"tv":21.28,"id":12984951},{"batb":[[0,1.14,168.04],[1,1.12,191.43],[2,1.06,366.89]],"ltp":4.1,"tv":81.32,"id":12984952},{"batb":[[0,14.5,5.82],[1,9,7.32],[2,1.01,0.51]],"ltp":4.4,"tv":44.81,"id":16574984}]}]}
{"op":"mcm","clk":"1009600625","pt":1580645588350,"mc":[{"id":"1.168217555","rc":[{"batb":[[0,7.4,10.7],[1,1.01,0.51],[2,7.4,0]],"ltp":5.2,"tv":21.28,"id":12984951},{"batb":[[0,1.06,366.89],[1,1.01,0.51],[2,1.06,0]],"batl":[[0,1.31,81.12],[1,1.18,0],[2,1.31,0]],"ltp":4.1,"tv":81.32,"id":12984952},{"batb":[[0,9,7.32],[1,1.01,0.51],[2,1.01,0]],"ltp":4.4,"tv":44.81,"id":16574984}]}]}
{"op":"mcm","clk":"1009601442","pt":1580645593058,"mc":[{"id":"1.168217555","rc":[{"batb":[[0,11.5,34.72],[1,11,24.99],[2,7.4,10.7]],"ltp":5.2,"tv":21.28,"id":12984951},{"batb":[[0,1.16,294.57],[1,1.15,289.19],[2,1.06,366.89]],"ltp":4.1,"tv":81.32,"id":12984952},{"batb":[[0,14.5,7.43],[1,14,17.59],[2,9,7.32]],"ltp":4.4,"tv":44.81,"id":16574984}]}]}
{"op":"mcm","clk":"1009601859","pt":1580645595575,"mc":[{"id":"1.168217555","rc":[{"batb":[[0,7.4,10.7],[1,1.01,0.51],[2,7.4,0]],"ltp":5.2,"tv":21.28,"id":12984951},{"batb":[[0,1.06,366.89],[1,1.01,0.51],[2,1.06,0]],"ltp":4.1,"tv":81.32,"id":12984952},{"batb":[[0,9,7.32],[1,1.01,0.51],[2,9,0]],"ltp":4.4,"tv":44.81,"id":16574984}]}]}
{"op":"mcm","clk":"1009602318","pt":1580645598574,"mc":[{"id":"1.168217555","rc":[{"batb":[[0,7.8,20.83],[1,7.6,25.71],[2,7.4,10.7]],"ltp":5.2,"tv":21.28,"id":12984951},{"batb":[[0,1.08,139.73],[1,1.07,489.12],[2,1.06,366.89]],"ltp":4.1,"tv":81.32,"id":12984952},{"batb":[[0,9.4,24.47],[1,9.2,17],[2,9,7.32]],"ltp":4.4,"tv":44.81,"id":16574984}]}]}
{"op":"mcm","clk":"1009603448","pt":1580645606296,"mc":[{"id":"1.168217555","rc":[{"batb":[[0,1.06,366.89],[1,1.01,0.51],[2,1.06,0]],"ltp":4.1,"tv":81.32,"id":12984952}]}]}
{"op":"mcm","clk":"1009603953","pt":1580645609492,"mc":[{"id":"1.168217555","rc":[{"batb":[[0,1.27,224.24],[1,1.26,215.2],[2,1.06,366.89]],"ltp":4.1,"tv":81.32,"id":12984952}]}]}
{"op":"mcm","clk":"1009604086","pt":1580645610284,"mc":[{"id":"1.168217555","rc":[{"batl":[[0,9,10.15],[1,16.5,8.03]],"ltp":5.2,"tv":21.28,"id":12984951},{"batb":[[1,1.26,299.86],[2,1.13,180.73]],"batl":[[1,1.67,28.88]],"ltp":4.1,"tv":81.32,"id":12984952},{"batl":[[0,11,7],[1,19.5,6.14]],"ltp":4.4,"tv":44.81,"id":16574984}]}]}
{"op":"mcm","clk":"1009604248","pt":1580645611287,"mc":[{"id":"1.168217555","rc":[{"batl":[[0,8.4,5.04],[1,9,10.15],[2,16.5,8.03]],"ltp":5.2,"tv":21.28,"id":12984951},{"batb":[[1,1.26,461.18]],"batl":[[1,1.33,42.01],[2,1.67,28.88]],"ltp":4.1,"tv":81.32,"id":12984952},{"batb":[[1,9.2,22.04]],"batl":[[1,11.5,3.36],[2,19.5,6.14]],"ltp":4.4,"tv":44.81,"id":16574984}]}]}
{"op":"mcm","clk":"1009604772","pt":1580645614715,"mc":[{"id":"1.168217555","rc":[{"batb":[[1,1.26,299.86]],"ltp":4.1,"tv":81.32,"id":12984952},{"batb":[[1,9.2,17]],"batl":[[1,19.5,6.14],[2,19.5,0]],"ltp":4.4,"tv":44.81,"id":16574984}]}]}
{"op":"mcm","clk":"1009604952","pt":1580645615790,"mc":[{"id":"1.168217555","rc":[{"batb":[[0,5,15.12],[1,1.01,0.51]],"ltp":5.1,"tv":4.54,"id":16574983}]}]}
{"op":"mcm","clk":"1009605227","pt":1580645617744,"mc":[{"id":"1.168217555","rc":[{"batb":[[0,1.27,379.68]],"ltp":4.1,"tv":81.32,"id":12984952},{"batl":[[0,11,11.2]],"ltp":4.4,"tv":44.81,"id":16574984}]}]}
{"op":"mcm","clk":"1009606333","pt":1580645624348,"mc":[{"id":"1.168217555","rc":[{"batb":[[0,4.4,18.33],[1,1.01,0.51],[2,7.4,0]],"batl":[[0,16.5,8.03],[1,9,0],[2,16.5,0]],"ltp":5.2,"tv":21.28,"id":12984951},{"batb":[[0,1.13,180.73],[1,1.01,0.51],[2,1.13,0]],"batl":[[0,1.67,28.88],[1,1.33,0],[2,1.67,0]],"ltp":4.1,"tv":81.32,"id":12984952},{"batb":[[0,5.3,12.04],[1,1.01,0.51],[2,9,0]],"batl":[[0,19.5,6.14],[1,19.5,0]],"ltp":4.4,"tv":44.81,"id":16574984}]}]}
{"op":"mcm","clk":"1009606870","pt":1580645627445,"mc":[{"id":"1.168217555","rc":[{"batb":[[0,4.4,58.66],[1,4.3,45.91],[2,1.01,0.51]],"ltp":5.2,"tv":21.28,"id":12984951},{"batb":[[0,1.14,318.26],[1,1.13,456.35],[2,1.01,0.51]],"batl":[[0,1.66,29.27]],"ltp":4.1,"tv":81.32,"id":12984952},{"batb":[[0,5.4,48.47],[1,5.3,28.54],[2,1.01,0.51]],"batl":[[0,20,5.9]],"ltp":4.4,"tv":44.81,"id":16574984}]}]}
{"op":"mcm","clk":"1009607030","pt":1580645628354,"mc":[{"id":"1.168217555","rc":[{"batb":[[0,4.4,18.33],[1,1.01,0.51],[2,1.01,0]],"ltp":5.2,"tv":21.28,"id":12984951},{"batb":[[0,5.4,11.57],[1,1.01,0.51],[2,1.01,0]],"ltp":4.4,"tv":44.81,"id":16574984}]}]}
{"op":"mcm","clk":"1009607611","pt":1580645631439,"mc":[{"id":"1.168217555","rc":[{"batb":[[0,13.5,8.21],[1,13,20.47],[2,4.4,18.33]],"ltp":5.2,"tv":21.28,"id":12984951},{"batb":[[0,16,8.76],[1,15.5,14.22],[2,5.4,11.57]],"ltp":4.4,"tv":44.81,"id":16574984}]}]}
{"op":"mcm","clk":"1009607763","pt":1580645632344,"mc":[{"id":"1.168217555","rc":[{"batb":[[2,12,8.66]],"ltp":5.2,"tv":21.28,"id":12984951},{"batb":[[2,1.06,355.48]],"batl":[[0,1.17,140.76],[1,1.32,78.84]],"ltp":4.1,"tv":81.32,"id":12984952},{"batb":[[2,14,6.29]],"ltp":4.4,"tv":44.81,"id":16574984}]}]}
{"op":"mcm","clk":"1009607935","pt":1580645633346,"mc":[{"id":"1.168217555","rc":[{"batb":[[0,1.14,486.3]],"ltp":4.1,"tv":81.32,"id":12984952}]}]}
{"op":"mcm","clk":"1009609764","pt":1580645644366,"mc":[{"id":"1.168217555","rc":[{"batb":[[0,7.4,11.17],[1,1.01,0.51],[2,12,0]],"ltp":5.2,"tv":21.28,"id":12984951},{"batb":[[0,1.06,355.48],[1,1.01,0.51],[2,1.06,0]],"batl":[[0,1.32,78.84],[1,1.32,0]],"ltp":4.1,"tv":81.32,"id":12984952},{"batb":[[0,8.8,7.55],[1,1.01,0.51],[2,14,0]],"ltp":4.4,"tv":44.81,"id":16574984}]}]}
{"op":"mcm","clk":"1009610143","pt":1580645646465,"mc":[{"id":"1.168217555","rc":[{"batb":[[0,7.6,34.07],[1,7.4,38.1],[2,1.01,0.51]],"ltp":5.2,"tv":21.28,"id":12984951},{"batb":[[0,1.08,354.89],[1,1.07,271.96],[2,1.06,355.48]],"ltp":4.1,"tv":81.32,"id":12984952},{"batb":[[0,9.2,19.71],[1,9,17.91],[2,8.8,7.55]],"ltp":4.4,"tv":44.81,"id":16574984},{"batb":[[0,1.01,0.51],[1,1.01,0]],"ltp":5.1,"tv":4.54,"id":16574983}]}]}
{"op":"mcm","clk":"1009611578","pt":1580645655766,"mc":[{"id":"1.168217555","rc":[{"batb":[[0,7.4,11.17],[1,1.01,0.51],[2,1.01,0]],"ltp":5.2,"tv":21.28,"id":12984951},{"batb":[[0,8.8,7.55],[1,1.01,0.51],[2,8.8,0]],"ltp":4.4,"tv":44.81,"id":16574984}]}]}
{"op":"mcm","clk":"1009612183","pt":1580645659483,"mc":[{"id":"1.168217555","rc":[{"batb":[[0,22,9.81],[1,21,14.83],[2,19.5,5.9]],"ltp":5.2,"tv":21.28,"id":12984951},{"batb":[[0,1.08,522.93]],"batl":[[0,1.11,194.1],[1,1.18,144.07],[2,1.32,78.84]],"ltp":4.1,"tv":81.32,"id":12984952},{"batb":[[0,26,7.13],[1,25,10.49],[2,22,3.97]],"ltp":4.4,"tv":44.81,"id":16574984}]}]}
{"op":"mcm","clk":"1009612210","pt":1580645659651,"mc":[{"id":"1.168217555","rc":[{"batl":[[2,1.32,0]],"ltp":4.1,"tv":81.32,"id":12984952}]}]}
{"op":"mcm","clk":"1009615037","pt":1580645678357,"mc":[{"id":"1.168217555","rc":[{"batb":[[0,12,9.28],[1,1.01,0.51],[2,19.5,0]],"ltp":5.2,"tv":21.28,"id":12984951},{"batb":[[0,1.03,628.83],[1,1.01,0.51],[2,1.06,0]],"batl":[[0,1.18,143.67],[1,1.18,0]],"ltp":4.1,"tv":81.32,"id":12984952},{"batb":[[0,13.5,6.77],[1,1.01,0.51],[2,22,0]],"ltp":4.4,"tv":44.81,"id":16574984}]}]}
{"op":"mcm","clk":"1009615487","pt":1580645681041,"mc":[{"id":"1.168217555","rc":[{"batb":[[0,13,17.68],[1,12.5,21.85],[2,12,9.28]],"ltp":5.2,"tv":21.28,"id":12984951},{"batb":[[0,1.05,275.69],[1,1.04,370],[2,1.03,628.83]],"ltp":4.1,"tv":81.32,"id":12984952},{"batb":[[0,15.5,7.32],[1,15,15.26],[2,13.5,6.77]],"ltp":4.4,"tv":44.81,"id":16574984}]}]}
{"op":"mcm","clk":"1009615989","pt":1580645684174,"mc":[{"id":"1.168217555","rc":[{"batb":[[0,12,9.28],[1,1.01,0.51],[2,12,0]],"ltp":5.2,"tv":21.28,"id":12984951},{"batb":[[0,13.5,6.77],[1,1.01,0.51],[2,13.5,0]],"ltp":4.4,"tv":44.81,"id":16574984}]}]}
{"op":"mcm","clk":"1009616497","pt":1580645687423,"mc":[{"id":"1.168217555","rc":[{"batb":[[0,34,9.11],[1,32,11.38],[2,12,9.28]],"ltp":5.2,"tv":21.28,"id":12984951},{"batb":[[0,40,8.36],[1,38,8.64],[2,13.5,6.77]],"ltp":4.4,"tv":44.81,"id":16574984}]}]}
{"op":"mcm","clk":"1009616561","pt":1580645687834,"mc":[{"id":"1.168217555","rc":[{"batb":[[2,28,2.74]],"ltp":5.2,"tv":21.28,"id":12984951},{"batl":[[0,1.07,131.95],[1,1.08,135.88]],"ltp":4.1,"tv":81.32,"id":12984952},{"batb":[[2,27,3.27]],"ltp":4.4,"tv":44.81,"id":16574984}]}]}
{"op":"mcm","clk":"1009616792","pt":1580645689331,"mc":[{"id":"1.168217555","rc":[{"batb":[[0,1.05,443.73]],"batl":[[0,1.07,173.96]],"ltp":4.1,"tv":81.32,"id":12984952}]}]}
{"op":"mcm","clk":"1009619751","pt":1580645708073,"mc":[{"id":"1.168217555","rc":[{"batb":[[0,6.2,10.27],[1,1.01,0.51]],"ltp":5.1,"tv":4.54,"id":16574983}]}]}
{"op":"mcm","clk":"1009619928","pt":1580645709172,"mc":[{"id":"1.168217555","rc":[{"trd":[[1.07,0.24]],"batl":[[0,1.07,173.72]],"ltp":1.07,"tv":81.56,"id":12984952},{"trd":[[15,0.02]],"ltp":15.0,"tv":4.56,"id":16574983}],"tv":152.22}]}
{"op":"mcm","clk":"1009622170","pt":1580645724256,"mc":[{"id":"1.168217555","rc":[{"batb":[[0,28,2.74],[1,25,4.84],[2,1.01,0.51]],"ltp":5.2,"tv":21.28,"id":12984951},{"batb":[[0,1.05,168.04],[1,1.03,628.83],[2,1.02,897.76]],"ltp":1.07,"tv":81.56,"id":12984952},{"batb":[[0,27,3.27],[1,1.01,0.51],[2,27,0]],"ltp":4.4,"tv":44.81,"id":16574984}]}]}
{"op":"mcm","clk":"1009622617","pt":1580645727180,"mc":[{"id":"1.168217555","rc":[{"batb":[[0,29,10.08],[1,28,10.96],[2,25,4.84]],"ltp":5.2,"tv":21.28,"id":12984951},{"batb":[[1,1.03,1283.47]],"ltp":1.07,"tv":81.56,"id":12984952},{"batb":[[0,34,8.97],[1,32,11.53],[2,27,3.27]],"ltp":4.4,"tv":44.81,"id":16574984}]}]}
{"op":"mcm","clk":"1009622706","pt":1580645727763,"mc":[{"id":"1.168217555","rc":[{"batl":[[0,710,2.14]],"ltp":5.2,"tv":21.28,"id":12984951}]}]}
{"op":"mcm","clk":"1009623359","pt":1580645732321,"mc":[{"id":"1.168217555","rc":[{"batb":[[1,28,8.22]],"ltp":5.2,"tv":21.28,"id":12984951},{"batb":[[0,1.03,654.64],[1,1.02,897.76],[2,1.01,0.51]],"batl":[[0,1.08,135.88],[1,1.08,0]],"ltp":1.07,"tv":81.56,"id":12984952},{"batb":[[0,1.01,0.51],[1,1.01,0]],"ltp":15.0,"tv":4.56,"id":16574983}]}]}
{"op":"mcm","clk":"1009623933","pt":1580645736194,"mc":[{"id":"1.168217555","rc":[{"batb":[[0,25,4.84],[1,1.01,0.51],[2,25,0]],"ltp":5.2,"tv":21.28,"id":12984951},{"batb":[[0,27,3.27],[1,1.01,0.51],[2,27,0]],"ltp":4.4,"tv":44.81,"id":16574984}]}]}
{"op":"mcm","clk":"1009624464","pt":1580645739501,"mc":[{"id":"1.168217555","rc":[{"batb":[[0,46,3.68],[1,44,6.62],[2,25,4.84]],"ltp":5.2,"tv":21.28,"id":12984951},{"batb":[[0,50,10.19],[1,27,3.27],[2,1.01,0.51]],"ltp":4.4,"tv":44.81,"id":16574984}]}]}
{"op":"mcm","clk":"1009624580","pt":1580645740289,"mc":[{"id":"1.168217555","rc":[{"batb":[[2,1.01,0.51]],"ltp":5.2,"tv":21.28,"id":12984951},{"batl":[[0,1.07,137.22]],"ltp":1.07,"tv":81.56,"id":12984952},{"batb":[[1,30,2.48]],"ltp":4.4,"tv":44.81,"id":16574984}]}]}
{"op":"mcm","clk":"1009624900","pt":1580645742508,"mc":[{"id":"1.168217555","rc":[{"batb":[[0,50,13.48]],"ltp":4.4,"tv":44.81,"id":16574984}]}]}
{"op":"mcm","clk":"1009626207","pt":1580645751320,"mc":[{"id":"1.168217555","rc":[{"batb":[[0,1.01,0.51],[1,44,0],[2,1.01,0]],"ltp":5.2,"tv":21.28,"id":12984951},{"batb":[[0,1.02,897.76],[1,1.01,0.51],[2,1.01,0]],"ltp":1.07,"tv":81.56,"id":12984952},{"batb":[[0,30,2.48],[1,1.01,0.51],[2,1.01,0]],"ltp":4.4,"tv":44.81,"id":16574984}]}]}
{"op":"mcm","clk":"1009626249","pt":1580645751641,"mc":[{"id":"1.168217555","rc":[{"batb":[[0,1.01,0.51],[1,1.01,0]],"ltp":1.07,"tv":81.56,"id":12984952},{"batb":[[0,1.01,0.51],[1,1.01,0]],"ltp":4.4,"tv":44.81,"id":16574984}]}]}
{"op":"mcm","clk":"1009626580","pt":1580645754133,"mc":[{"id":"1.168217555","rc":[{"batb":[[0,36,3.68],[1,34,11.09],[2,1.01,0.51]],"ltp":5.2,"tv":21.28,"id":12984951},{"batb":[[0,1.02,661.06],[1,1.01,0.51]],"ltp":1.07,"tv":81.56,"id":12984952},{"batb":[[0,42,4.91],[1,40,7.87],[2,1.01,0.51]],"ltp":4.4,"tv":44.81,"id":16574984}]}]}
{"op":"mcm","clk":"1009626714","pt":1580645755232,"mc":[{"id":"1.168217555","rc":[{"batb":[[0,1.01,0.51],[1,34,0],[2,1.01,0]],"ltp":5.2,"tv":21.28,"id":12984951},{"batb":[[0,1.01,0.51],[1,1.01,0]],"ltp":1.07,"tv":81.56,"id":12984952},{"batb":[[0,1.01,0.51],[1,40,0],[2,1.01,0]],"ltp":4.4,"tv":44.81,"id":16574984}]}]}
{"op":"mcm","clk":"1009627131","pt":1580645758370,"mc":[{"id":"1.168217555","rc":[{"batb":[[0,50,3.14],[1,48,5.58],[2,1.01,0.51]],"ltp":5.2,"tv":21.28,"id":12984951},{"batb":[[0,1.03,654.64],[1,1.01,0.51]],"ltp":1.07,"tv":81.56,"id":12984952},{"batb":[[0,55,10.56],[1,1.01,0.51]],"ltp":4.4,"tv":44.81,"id":16574984}]}]}
{"op":"mcm","clk":"1009628044","pt":1580645765348,"mc":[{"id":"1.168217555","rc":[{"batb":[[0,1.01,0.51],[1,48,0],[2,1.01,0]],"ltp":5.2,"tv":21.28,"id":12984951},{"batb":[[0,1.01,0.51],[1,1.01,0]],"ltp":1.07,"tv":81.56,"id":12984952},{"batb":[[0,1.01,0.51],[1,1.01,0]],"ltp":4.4,"tv":44.81,"id":16574984}]}]}
{"op":"mcm","clk":"1009628389","pt":1580645768050,"mc":[{"id":"1.168217555","rc":[{"batb":[[0,36,3.71],[1,34,11.09],[2,1.01,0.51]],"ltp":5.2,"tv":21.28,"id":12984951},{"batb":[[0,1.02,661.06],[1,1.01,0.51]],"ltp":1.07,"tv":81.56,"id":12984952},{"batb":[[0,42,3.77],[1,40,7.87],[2,1.01,0.51]],"ltp":4.4,"tv":44.81,"id":16574984}]}]}
{"op":"mcm","clk":"1009629695","pt":1580645778344,"mc":[{"id":"1.168217555","rc":[{"batb":[[0,1.01,0.51],[1,1.01,0]],"ltp":1.07,"tv":81.56,"id":12984952}]}]}
{"op":"mcm","clk":"1009630154","pt":1580645781427,"mc":[{"id":"1.168217555","rc":[{"batb":[[0,1.04,648.34],[1,1.01,0.51]],"batl":[[0,1.07,179.23]],"ltp":1.07,"tv":81.56,"id":12984952}]}]}
{"op":"mcm","clk":"1009630188","pt":1580645781747,"mc":[{"id":"1.168217555","rc":[{"batb":[[2,24,5.35]],"ltp":5.2,"tv":21.28,"id":12984951},{"batb":[[1,1.03,659.12],[2,1.01,0.51]],"batl":[[1,1.08,135.8]],"ltp":1.07,"tv":81.56,"id":12984952},{"batb":[[2,28,2.88]],"ltp":4.4,"tv":44.81,"id":16574984}]}]}
{"op":"mcm","clk":"1009631945","pt":1580645794442,"mc":[{"id":"1.168217555","rc":[{"batb":[[0,24,5.35],[1,1.01,0.51],[2,24,0]],"ltp":5.2,"tv":21.28,"id":12984951},{"batb":[[0,1.01,0.51],[1,1.03,0],[2,1.01,0]],"batl":[[0,1.08,135.8],[1,1.08,0]],"ltp":1.07,"tv":81.56,"id":12984952},{"batb":[[0,28,2.88],[1,1.01,0.51],[2,28,0]],"ltp":4.4,"tv":44.81,"id":16574984}]}]}
{"op":"mcm","clk":"1009632347","pt":1580645797472,"mc":[{"id":"1.168217555","rc":[{"batb":[[0,29,8.78],[1,28,8.27],[2,24,5.35]],"ltp":5.2,"tv":21.28,"id":12984951},{"batb":[[0,1.03,654.64],[1,1.01,0.51]],"ltp":1.07,"tv":81.56,"id":12984952},{"batb":[[0,34,6.36],[1,32,12.14],[2,28,2.88]],"ltp":4.4,"tv":44.81,"id":16574984}]}]}
{"op":"mcm","clk":"1009632883","pt":1580645801348,"mc":[{"id":"1.168217555","rc":[{"batb":[[0,1.01,0.51],[1,1.01,0]],"ltp":1.07,"tv":81.56,"id":12984952}]}]}
{"op":"mcm","clk":"1009633142","pt":1580645803368,"mc":[{"id":"1.168217555","rc":[{"batl":[[0,46,45.44]],"ltp":4.4,"tv":44.81,"id":16574984}]}]}
{"op":"mcm","clk":"1009633242","pt":1580645804058,"mc":[{"id":"1.168217555","rc":[{"batb":[[0,1.06,276.84],[1,1.05,362.68],[2,1.04,512.85]],"batl":[[1,1.09,135.96]],"ltp":1.07,"tv":81.56,"id":12984952}]}]}
{"op":"mcm","clk":"1009633429","pt":1580645805462,"mc":[{"id":"1.168217555","rc":[{"batl":[[0,1.08,177.81]],"ltp":1.07,"tv":81.56,"id":12984952}]}]}
{"op":"mcm","clk":"1009634620","pt":1580645814504,"mc":[{"id":"1.168217555","rc":[{"batb":[[0,24,5.35],[1,22,3.89],[2,1.01,0.51]],"ltp":5.2,"tv":21.28,"id":12984951},{"batb":[[0,1.04,512.85],[1,1.03,692.4],[2,1.01,0.51]],"batl":[[0,1.08,135.8]],"ltp":1.07,"tv":81.56,"id":12984952},{"batb":[[0,28,2.88],[1,24,5.54],[2,1.01,0.51]],"ltp":4.4,"tv":44.81,"id":16574984}]}]}
{"op":"mcm","clk":"1009634629","pt":1580645814563,"mc":[{"id":"1.168217555","rc":[{"batb":[[0,22,3.89],[1,1.01,0.51],[2,1.01,0]],"ltp":5.2,"tv":21.28,"id":12984951},{"batb":[[0,1.03,692.4],[1,1.01,0.51],[2,1.01,0]],"batl":[[0,1.09,135.96],[1,1.09,0]],"ltp":1.07,"tv":81.56,"id":12984952},{"batb":[[0,24,5.54],[1,1.01,0.51],[2,1.01,0]],"ltp":4.4,"tv":44.81,"id":16574984}]}]}
{"op":"mcm","clk":"1009634959","pt":1580645816879,"mc":[{"id":"1.168217555","rc":[{"batb":[[0,25,13.64],[1,24,11.14],[2,22,3.89]],"ltp":5.2,"tv":21.28,"id":12984951},{"batb":[[0,1.04,648.34],[1,1.03,692.4],[2,1.01,0.51]],"ltp":1.07,"tv":81.56,"id":12984952},{"batb":[[0,30,3.37],[1,29,7.75],[2,24,5.54]],"ltp":4.4,"tv":44.81,"id":16574984}]}]}
{"op":"mcm","clk":"1009635195","pt":1580645818578,"mc":[{"id":"1.168217555","rc":[{"batb":[[0,1.03,692.4],[1,1.01,0.51],[2,1.01,0]],"ltp":1.07,"tv":81.56,"id":12984952}]}]}
{"op":"mcm","clk":"1009635595","pt":1580645821502,"mc":[{"id":"1.168217555","rc":[{"batb":[[0,1.07,236.78],[1,1.06,397.1],[2,1.03,692.4]],"ltp":1.07,"tv":81.56,"id":12984952},{"batl":[[0,42,47.65]],"ltp":4.4,"tv":44.81,"id":16574984}]}]}
{"op":"mcm","clk":"1009635748","pt":1580645822487,"mc":[{"id":"1.168217555","rc":[{"batb":[[2,1.05,423.86]],"batl":[[1,1.1,147.14]],"ltp":1.07,"tv":81.56,"id":12984952}]}]}
{"op":"mcm","clk":"1009635885","pt":1580645823500,"mc":[{"id":"1.168217555","rc":[{"batl":[[0,1.09,177.97]],"ltp":1.07,"tv":81.56,"id":12984952}]}]}
{"op":"mcm","clk":"1009636876","pt":1580645830512,"mc":[{"id":"1.168217555","rc":[{"batb":[[0,24,7.86],[1,21,4.63],[2,1.01,0.51]],"ltp":5.2,"tv":21.28,"id":12984951},{"batb":[[0,1.06,397.1],[1,1.04,494.44],[2,1.01,0.51]],"batl":[[0,1.1,147.14],[1,1.1,0]],"ltp":1.07,"tv":81.56,"id":12984952},{"batb":[[0,23,3.27],[1,1.01,0.51],[2,24,0]],"ltp":4.4,"tv":44.81,"id":16574984}]}]}
{"op":"mcm","clk":"1009637235","pt":1580645833427,"mc":[{"id":"1.168217555","rc":[{"batb":[[1,23,12.4],[2,21,4.63]],"ltp":5.2,"tv":21.28,"id":12984951},{"batb":[[0,1.06,499.16],[1,1.05,138.25],[2,1.04,494.44]],"ltp":1.07,"tv":81.56,"id":12984952},{"batb":[[0,27,11.18],[1,26,9.37],[2,23,3.27]],"ltp":4.4,"tv":44.81,"id":16574984}]}]}
{"op":"mcm","clk":"1009638982","pt":1580645847328,"mc":[{"id":"1.168217555","rc":[{"batb":[[0,1.04,494.44],[1,1.01,0.51],[2,1.04,0]],"ltp":1.07,"tv":81.56,"id":12984952}]}]}
{"op":"mcm","clk":"1009639399","pt":1580645850411,"mc":[{"id":"1.168217555","rc":[{"batb":[[0,1.07,630.17],[1,1.06,394.04],[2,1.04,494.44]],"batl":[[1,1.18,143.67]],"ltp":1.07,"tv":81.56,"id":12984952}]}]}
{"op":"mcm","clk":"1009639550","pt":1580645851521,"mc":[{"id":"1.168217555","rc":[{"batb":[[0,1.07,798.21],[2,1.02,820.34]],"batl":[[0,1.1,189.14]],"ltp":1.07,"tv":81.56,"id":12984952}]}]}
{"op":"mcm","clk":"1009641216","pt":1580645863661,"mc":[{"id":"1.168217555","rc":[{"batb":[[0,27,9],[1,23,3.27],[2,13.5,7.16]],"ltp":4.4,"tv":44.81,"id":16574984}]}]}
{"op":"mcm","clk":"1009641651","pt":1580645866689,"mc":[{"id":"1.168217555","rc":[{"batb":[[0,28,8.4],[1,27,9],[2,23,3.27]],"ltp":4.4,"tv":44.81,"id":16574984}]}]}
{"op":"mcm","clk":"1009642983","pt":1580645876484,"mc":[{"id":"1.168217555","rc":[{"batb":[[0,28,11.39]],"ltp":4.4,"tv":44.81,"id":16574984}]}]}
{"op":"mcm","clk":"1009643360","pt":1580645879362,"mc":[{"id":"1.168217555","rc":[{"batb":[[0,28,8.65],[1,23,3.27],[2,13.5,7.16]],"ltp":4.4,"tv":44.81,"id":16574984}]}]}
{"op":"mcm","clk":"1009643767","pt":1580645882468,"mc":[{"id":"1.168217555","rc":[{"batb":[[0,29,4.03],[1,28,8.65],[2,23,3.27]],"ltp":4.4,"tv":44.81,"id":16574984}]}]}
{"op":"mcm","clk":"1009644722","pt":1580645889703,"mc":[{"id":"1.168217555","rc":[{"batb":[[0,1.07,749.67]],"ltp":1.07,"tv":81.56,"id":12984952}]}]}
{"op":"mcm","clk":"1009645150","pt":1580645892702,"mc":[{"id":"1.168217555","rc":[{"batb":[[0,29,7.62]],"ltp":4.4,"tv":44.81,"id":16574984}]}]}
{"op":"mcm","clk":"1009645517","pt":1580645895494,"mc":[{"id":"1.168217555","rc":[{"batl":[[0,680,2.37]],"ltp":4.4,"tv":44.81,"id":16574984}]}]}
{"op":"mcm","clk":"1009645529","pt":1580645895594,"mc":[{"id":"1.168217555","rc":[{"batb":[[0,1.07,688.14]],"ltp":1.07,"tv":81.56,"id":12984952},{"batb":[[1,23,3.27],[2,13.5,7.16]],"ltp":4.4,"tv":44.81,"id":16574984}]}]}
{"op":"mcm","clk":"1009645903","pt":1580645898482,"mc":[{"id":"1.168217555","rc":[{"batb":[[1,1.06,505.14]],"ltp":1.07,"tv":81.56,"id":12984952},{"batb":[[0,30,4.31],[1,29,7.62],[2,23,3.27]],"ltp":4.4,"tv":44.81,"id":16574984}]}]}
{"op":"mcm","clk":"1009649492","pt":1580645927316,"mc":[{"id":"1.168217555","rc":[{"batb":[[0,21,4.63],[1,12,8.89],[2,1.01,0.51]],"ltp":5.2,"tv":21.28,"id":12984951},{"batb":[[0,1.07,168.04],[1,1.06,394.04]],"ltp":1.07,"tv":81.56,"id":12984952},{"batb":[[0,23,3.27],[1,13.5,7.16],[2,1.01,0.51]],"ltp":4.4,"tv":44.81,"id":16574984}]}]}
{"op":"mcm","clk":"1009649577","pt":1580645927947,"mc":[{"id":"1.168217555","rc":[{"batb":[[0,12,8.89],[1,1.01,0.51],[2,1.01,0]],"ltp":5.2,"tv":21.28,"id":12984951},{"batb":[[1,1.02,820.34],[2,1.01,0.51]],"batl":[[0,1.1,42.01]],"ltp":1.07,"tv":81.56,"id":12984952},{"batb":[[0,13.5,7.16],[1,1.01,0.51],[2,1.01,0]],"ltp":4.4,"tv":44.81,"id":16574984}]}]}
{"op":"mcm","clk":"1009649683","pt":1580645928735,"mc":[{"id":"1.168217555","rc":[{"batb":[[0,1.02,820.34],[1,1.01,0.51],[2,1.01,0]],"batl":[[0,1.18,143.67],[1,1.18,0]],"ltp":1.07,"tv":81.56,"id":12984952}]}]}
{"op":"mcm","clk":"1009649902","pt":1580645930320,"mc":[{"id":"1.168217555","rc":[{"batb":[[0,13,9.64],[1,12.5,22.09],[2,12,8.89]],"ltp":5.2,"tv":21.28,"id":12984951},{"batb":[[0,1.03,654.64],[1,1.02,820.34],[2,1.01,0.51]],"ltp":1.07,"tv":81.56,"id":12984952},{"batb":[[0,16,14.58],[1,15.5,14.97],[2,13.5,7.16]],"ltp":4.4,"tv":44.81,"id":16574984}]}]}
{"op":"mcm","clk":"1009650181","pt":1580645932439,"mc":[{"id":"1.168217555","rc":[{"batb":[[0,1.02,820.34],[1,1.01,0.51],[2,1.01,0]],"ltp":1.07,"tv":81.56,"id":12984952}]}]}
{"op":"mcm","clk":"1009650586","pt":1580645935521,"mc":[{"id":"1.168217555","rc":[{"batb":[[0,1.14,443.4],[1,1.13,149.37],[2,1.02,820.34]],"ltp":1.07,"tv":81.56,"id":12984952}]}]}
{"op":"mcm","clk":"1009650678","pt":1580645936252,"mc":[{"id":"1.168217555","rc":[{"batl":[[0,16.5,8.26],[1,29,6.22]],"ltp":5.2,"tv":21.28,"id":12984951},{"batb":[[0,1.14,611.44],[1,1.13,323.65],[2,1.07,322.44]],"batl":[[0,1.18,185.68],[1,1.33,75.3]],"ltp":1.07,"tv":81.56,"id":12984952},{"batl":[[0,18.5,6.69]],"ltp":4.4,"tv":44.81,"id":16574984}]}]}
{"op":"mcm","clk":"1009651135","pt":1580645940235,"mc":[{"id":"1.168217555","rc":[{"batb":[[0,7,15.96],[1,1.01,0.51]],"ltp":15.0,"tv":4.56,"id":16574983}]}]}
{"op":"mcm","clk":"1009652446","pt":1580645950393,"mc":[{"id":"1.168217555","rc":[{"batb":[[0,11.5,3.36],[1,7.4,11.25],[2,1.01,0.51]],"batl":[[0,29,6.22],[1,29,0]],"ltp":5.2,"tv":21.28,"id":12984951},{"batb":[[0,1.14,168.04],[1,1.07,322.44],[2,1.01,0.51]],"batl":[[0,1.18,42.01]],"ltp":1.07,"tv":81.56,"id":12984952},{"batb":[[0,8.4,8.58],[1,1.01,0.51],[2,13.5,0]],"ltp":4.4,"tv":44.81,"id":16574984}]}]}
{"op":"mcm","clk":"1009652484","pt":1580645950688,"mc":[{"id":"1.168217555","rc":[{"batb":[[0,7.4,11.25],[1,1.01,0.51],[2,1.01,0]],"ltp":5.2,"tv":21.28,"id":12984951},{"batb":[[0,1.07,322.44],[1,1.01,0.51],[2,1.01,0]],"batl":[[0,1.33,75.3],[1,1.33,0]],"ltp":1.07,"tv":81.56,"id":12984952}]}]}
{"op":"mcm","clk":"1009652840","pt":1580645953459,"mc":[{"id":"1.168217555","rc":[{"batb":[[0,1.08,624.33],[1,1.07,322.44],[2,1.01,0.51]],"ltp":1.07,"tv":81.56,"id":12984952}]}]}
{"op":"mcm","clk":"1009653217","pt":1580645956453,"mc":[{"id":"1.168217555","rc":[{"batb":[[0,20,17.77],[1,19.5,8.62],[2,7.4,11.25]],"ltp":5.2,"tv":21.28,"id":12984951},{"batb":[[0,25,15.12],[1,24,11.84],[2,8.4,8.58]],"ltp":4.4,"tv":44.81,"id":16574984}]}]}
{"op":"mcm","clk":"1009653348","pt":1580645957463,"mc":[{"id":"1.168217555","rc":[{"batb":[[2,18.5,6.85]],"ltp":5.2,"tv":21.28,"id":12984951},{"batb":[[2,1.02,765.81]],"batl":[[0,1.11,139.35],[1,1.23,121.8]],"ltp":1.07,"tv":81.56,"id":12984952},{"batb":[[2,20,5.35]],"ltp":4.4,"tv":44.81,"id":16574984}]}]}
{"op":"mcm","clk":"1009653374","pt":1580645957668,"mc":[{"id":"1.168217555","rc":[{"batl":[[0,1.11,181.36]],"ltp":1.07,"tv":81.56,"id":12984952}]}]}
{"op":"mcm","clk":"1009654728","pt":1580645969496,"mc":[{"id":"1.168217555","rc":[{"batb":[[0,9.8,14.32],[1,1.01,0.51],[2,18.5,0]],"ltp":5.2,"tv":21.28,"id":12984951},{"batb":[[0,1.02,765.81],[1,1.01,0.51],[2,1.02,0]],"batl":[[0,1.11,42.01]],"ltp":1.07,"tv":81.56,"id":12984952},{"batb":[[0,11,11.09],[1,1.01,0.51],[2,20,0]],"ltp":4.4,"tv":44.81,"id":16574984},{"batb":[[0,1.01,0.51],[1,1.01,0]],"ltp":15.0,"tv":4.56,"id":16574983}]}]}
{"op":"mcm","clk":"1009654880","pt":1580645970825,"mc":[{"id":"1.168217555","rc":[{"batl":[[0,1.23,121.8],[1,1.23,0]],"ltp":1.07,"tv":81.56,"id":12984952}]}]}
{"op":"mcm","clk":"1009654967","pt":1580645971598,"mc":[{"id":"1.168217555","rc":[{"batb":[[0,10.5,16.17],[1,10,34.81],[2,9.8,14.32]],"ltp":5.2,"tv":21.28,"id":12984951},{"batb":[[0,1.04,288.03],[1,1.03,363.81],[2,1.02,765.81]],"ltp":1.07,"tv":81.56,"id":12984952},{"batb":[[0,13,19.82],[1,12.5,23.18],[2,11,11.09]],"ltp":4.4,"tv":44.81,"id":16574984}]}]}
{"op":"mcm","clk":"1009655256","pt":1580645973909,"mc":[{"id":"1.168217555","rc":[{"batb":[[0,9.8,14.32],[1,1.01,0.51],[2,9.8,0]],"ltp":5.2,"tv":21.28,"id":12984951},{"batb":[[0,11,11.09],[1,1.01,0.51],[2,11,0]],"ltp":4.4,"tv":44.81,"id":16574984}]}]}
{"op":"mcm","clk":"1009655694","pt":1580645977514,"mc":[{"id":"1.168217555","rc":[{"batb":[[0,42,3.79],[1,40,7.99],[2,16,4.8]],"ltp":5.2,"tv":21.28,"id":12984951},{"batl":[[0,1.13,141.63]],"ltp":1.07,"tv":81.56,"id":12984952},{"batb":[[0,50,9.94],[1,48,3.68],[2,17.5,7.55]],"ltp":4.4,"tv":44.81,"id":16574984}]}]}
{"op":"mcm","clk":"1009656665","pt":1580645985472,"mc":[{"id":"1.168217555","rc":[{"batb":[[0,16,4.8],[1,1.01,0.51],[2,16,0]],"ltp":5.2,"tv":21.28,"id":12984951},{"batb":[[0,1.01,0.51],[1,1.03,0],[2,1.02,0]],"ltp":1.07,"tv":81.56,"id":12984952},{"batb":[[0,17.5,7.55],[1,1.01,0.51],[2,17.5,0]],"ltp":4.4,"tv":44.81,"id":16574984}]}]}
{"op":"mcm","clk":"1009657239","pt":1580645990431,"mc":[{"id":"1.168217555","rc":[{"batb":[[0,32,11.54],[1,30,10.16],[2,16,4.8]],"ltp":5.2,"tv":21.28,"id":12984951},{"batb":[[0,1.05,491.87],[1,1.04,151.74],[2,1.01,0.51]],"ltp":1.07,"tv":81.56,"id":12984952},{"batb":[[0,40,9.67],[1,38,7.56],[2,17.5,7.55]],"ltp":4.4,"tv":44.81,"id":16574984}]}]}
{"op":"mcm","clk":"1009657885","pt":1580645995210,"mc":[{"id":"1.168217555","rc":[{"batb":[[0,16,4.8],[1,1.01,0.51],[2,16,0]],"ltp":5.2,"tv":21.28,"id":12984951},{"batb":[[0,1.01,0.51],[1,1.04,0],[2,1.01,0]],"ltp":1.07,"tv":81.56,"id":12984952},{"batb":[[0,17.5,7.55],[1,1.01,0.51],[2,17.5,0]],"ltp":4.4,"tv":44.81,"id":16574984}]}]}
{"op":"mcm","clk":"1009658301","pt":1580645998423,"mc":[{"id":"1.168217555","rc":[{"batb":[[0,17.5,15.6],[1,17,11.54],[2,16,4.8]],"ltp":5.2,"tv":21.28,"id":12984951},{"batb":[[0,1.01,668.11]],"ltp":1.07,"tv":81.56,"id":12984952},{"batb":[[0,22,11.51],[1,21,15.74],[2,17.5,7.55]],"ltp":4.4,"tv":44.81,"id":16574984}]}]}
{"op":"mcm","clk":"1009659047","pt":1580646004034,"mc":[{"id":"1.168217555","rc":[{"batb":[[0,9,15.12],[1,1.01,0.51]],"ltp":15.0,"tv":4.56,"id":16574983}]}]}
{"op":"mcm","clk":"1009659548","pt":1580646007435,"mc":[{"id":"1.168217555","rc":[{"batb":[[0,16,4.8],[1,1.01,0.51],[2,16,0]],"ltp":5.2,"tv":21.28,"id":12984951},{"batb":[[0,17.5,7.55],[1,1.01,0.51],[2,17.5,0]],"ltp":4.4,"tv":44.81,"id":16574984}]}]}
{"op":"mcm","clk":"1009659951","pt":1580646010434,"mc":[{"id":"1.168217555","rc":[{"batb":[[0,140,3.25],[1,30,3.03],[2,16,4.8]],"ltp":5.2,"tv":21.28,"id":12984951},{"batl":[[0,1.06,141],[1,1.13,141.63]],"ltp":1.07,"tv":81.56,"id":12984952},{"batb":[[0,30,2.44],[1,17.5,7.55],[2,1.01,0.51]],"ltp":4.4,"tv":44.81,"id":16574984}]}]}
{"op":"mcm","clk":"1009659977","pt":1580646010637,"mc":[{"id":"1.168217555","rc":[{"batb":[[2,1.01,0.51]],"ltp":5.2,"tv":21.28,"id":12984951},{"batl":[[1,1.13,0]],"ltp":1.07,"tv":81.56,"id":12984952},{"batb":[[1,1.01,0.51],[2,1.01,0]],"ltp":4.4,"tv":44.81,"id":16574984}]}]}
{"op":"mcm","clk":"1009660224","pt":1580646012343,"mc":[{"id":"1.168217555","rc":[{"batl":[[0,1.02,42.01],[1,1.06,141]],"ltp":1.07,"tv":81.56,"id":12984952}]}]}
{"op":"mcm","clk":"1009661811","pt":1580646025263,"mc":[{"id":"1.168217555","rc":[{"batb":[[0,30,3.03],[1,1.01,0.51],[2,1.01,0]],"ltp":5.2,"tv":21.28,"id":12984951},{"batb":[[0,1.01,0.51]],"ltp":1.07,"tv":81.56,"id":12984952}]}]}
{"op":"mcm","clk":"1009661970","pt":1580646026755,"mc":[{"id":"1.168217555","rc":[{"batl":[[0,1.06,141],[1,1.06,0]],"ltp":1.07,"tv":81.56,"id":12984952}]}]}
{"op":"mcm","clk":"1009662090","pt":1580646027665,"mc":[{"id":"1.168217555","rc":[{"batb":[[0,50,3.16],[1,48,5.57],[2,30,3.03]],"ltp":5.2,"tv":21.28,"id":12984951},{"batb":[[0,60,5.86],[1,55,5.86],[2,30,2.44]],"ltp":4.4,"tv":44.81,"id":16574984}]}]}
{"op":"mcm","clk":"1009662977","pt":1580646034871,"mc":[{"id":"1.168217555","rc":[{"batb":[[0,1.01,0.51],[1,1.01,0]],"ltp":15.0,"tv":4.56,"id":16574983}]}]}
{"op":"mcm","clk":"1009663587","pt":1580646039463,"mc":[{"id":"1.168217555","rc":[{"batb":[[0,1.03,654.64],[1,1.01,0.51]],"ltp":1.07,"tv":81.56,"id":12984952}]}]}
{"op":"mcm","clk":"1009663711","pt":1580646040292,"mc":[{"id":"1.168217555","rc":[{"batb":[[0,1.03,822.68],[1,1.02,934.27],[2,1.01,0.51]],"batl":[[1,1.14,148.16]],"ltp":1.07,"tv":81.56,"id":12984952}]}]}
{"op":"mcm","clk":"1009665798","pt":1580646056098,"mc":[{"id":"1.168217555","rc":[{"batb":[[1,55,5.09]],"ltp":4.4,"tv":44.81,"id":16574984}]}]}
{"op":"mcm","clk":"1009666346","pt":1580646059473,"mc":[{"id":"1.168217555","rc":[{"batb":[[0,30,3.03],[1,15.5,5.04],[2,1.01,0.51]],"ltp":5.2,"tv":21.28,"id":12984951},{"batb":[[0,1.03,168.04]],"ltp":1.07,"tv":81.56,"id":12984952},{"batb":[[0,30,2.44],[1,17,4.25],[2,1.01,0.51]],"ltp":4.4,"tv":44.81,"id":16574984}]}]}
{"op":"mcm","clk":"1009666385","pt":1580646059822,"mc":[{"id":"1.168217555","rc":[{"batb":[[0,15.5,5.04],[1,1.01,0.51],[2,1.01,0]],"ltp":5.2,"tv":21.28,"id":12984951},{"batb":[[1,1.01,0.51],[2,1.01,0]],"batl":[[0,1.14,148.16],[1,1.14,0]],"ltp":1.07,"tv":81.56,"id":12984952},{"batb":[[0,17,4.25],[1,1.01,0.51],[2,1.01,0]],"ltp":4.4,"tv":44.81,"id":16574984}]}]}
{"op":"mcm","clk":"1009666499","pt":1580646060790,"mc":[{"id":"1.168217555","rc":[{"batb":[[0,1.01,0.51],[1,1.01,0]],"ltp":1.07,"tv":81.56,"id":12984952}]}]}
{"op":"mcm","clk":"1009666747","pt":1580646062399,"mc":[{"id":"1.168217555","rc":[{"batb":[[0,17.5,6.08],[1,17,11.8],[2,15.5,5.04]],"ltp":5.2,"tv":21.28,"id":12984951},{"batb":[[0,21,16.4],[1,20,16.48],[2,17,4.25]],"ltp":4.4,"tv":44.81,"id":16574984}]}]}
{"op":"mcm","clk":"1009666864","pt":1580646063097,"mc":[{"id":"1.168217555","rc":[{"batb":[[0,15.5,5.04],[1,1.01,0.51],[2,15.5,0]],"ltp":5.2,"tv":21.28,"id":12984951},{"batb":[[0,17,4.25],[1,1.01,0.51],[2,17,0]],"ltp":4.4,"tv":44.81,"id":16574984}]}]}
{"op":"mcm","clk":"1009667132","pt":1580646064888,"mc":[{"id":"1.168217555","rc":[{"batb":[[0,36,6.24],[1,34,10.92],[2,15.5,5.04]],"ltp":5.2,"tv":21.28,"id":12984951},{"batb":[[0,1.04,648.34],[1,1.01,0.51]],"ltp":1.07,"tv":81.56,"id":12984952},{"batb":[[0,44,7.65],[1,42,7.63],[2,17,4.25]],"ltp":4.4,"tv":44.81,"id":16574984}]}]}
{"op":"mcm","clk":"1009667608","pt":1580646068305,"mc":[{"id":"1.168217555","rc":[{"batb":[[0,15.5,5.04],[1,1.01,0.51],[2,15.5,0]],"ltp":5.2,"tv":21.28,"id":12984951},{"batb":[[0,1.01,0.51],[1,1.01,0]],"ltp":1.07,"tv":81.56,"id":12984952},{"batb":[[0,17,4.25],[1,1.01,0.51],[2,17,0]],"ltp":4.4,"tv":44.81,"id":16574984}]}]}
{"op":"mcm","clk":"1009668004","pt":1580646071303,"mc":[{"id":"1.168217555","rc":[{"batb":[[0,17.5,6],[1,17,11.81],[2,15.5,5.04]],"ltp":5.2,"tv":21.28,"id":12984951},{"batb":[[0,21,17.81],[1,20,15],[2,17,4.25]],"ltp":4.4,"tv":44.81,"id":16574984}]}]}
{"op":"mcm","clk":"1009671489","pt":1580646098033,"mc":[{"id":"1.168217555","rc":[{"batb":[[0,15.5,5.04],[1,1.01,0.51],[2,15.5,0]],"ltp":5.2,"tv":21.28,"id":12984951},{"batb":[[0,17,4.25],[1,1.01,0.51],[2,17,0]],"ltp":4.4,"tv":44.81,"id":16574984}]}]}
{"op":"mcm","clk":"1009671592","pt":1580646098707,"mc":[{"id":"1.168217555","marketDefinition":{"bspMarket":false,"turnInPlayEnabled":true,"persistenceEnabled":true,"marketBaseRate":5.0,"eventId":"29681263","eventTypeId":"2","numberOfWinners":1,"bettingType":"ODDS","marketType":"SET_BETTING","marketTime":"2020-02-02T11:07:00.000Z","suspendTime":"2020-02-02T11:07:00.000Z","bspReconciled":false,"complete":true,"inPlay":true,"crossMatching":true,"runnersVoidable":false,"numberOfActiveRunners":4,"betDelay":3,"status":"SUSPENDED","runners":[{"status":"ACTIVE","sortPriority":1,"id":16574983,"name":"Karlovskiy 2-0"},{"status":"ACTIVE","sortPriority":2,"id":16574984,"name":"Karlovskiy 2-1"},{"status":"ACTIVE","sortPriority":3,"id":12984952,"name":"Troicki 2-0"},{"status":"ACTIVE","sortPriority":4,"id":12984951,"name":"Troicki 2-1"}],"regulators":["MR_INT"],"countryCode":"IN","discountAllowed":true,"timezone":"UTC","openDate":"2020-02-02T11:07:00.000Z","version":3148696933,"name":"Set Betting","eventName":"Karlovskiy v Troicki"},"rc":[{"batb":[[0,1.01,0.51],[1,1.01,0]],"ltp":5.2,"tv":21.28,"id":12984951},{"batb":[[0,1.01,0.51],[1,1.01,0]],"ltp":4.4,"tv":44.81,"id":16574984}]}]}
{"op":"mcm","clk":"1009675943","pt":1580646129601,"mc":[{"id":"1.168217555","tv":0.0}]}
{"op":"mcm","clk":"1009676102","pt":1580646130786,"mc":[{"id":"1.168217555","marketDefinition":{"bspMarket":false,"turnInPlayEnabled":true,"persistenceEnabled":true,"marketBaseRate":5.0,"eventId":"29681263","eventTypeId":"2","numberOfWinners":1,"bettingType":"ODDS","marketType":"SET_BETTING","marketTime":"2020-02-02T11:07:00.000Z","suspendTime":"2020-02-02T11:07:00.000Z","bspReconciled":false,"complete":true,"inPlay":true,"crossMatching":false,"runnersVoidable":false,"numberOfActiveRunners":0,"betDelay":3,"status":"CLOSED","settledTime":"2020-02-02T12:22:08.000Z","runners":[{"status":"LOSER","sortPriority":1,"id":16574983,"name":"Karlovskiy 2-0"},{"status":"LOSER","sortPriority":2,"id":16574984,"name":"Karlovskiy 2-1"},{"status":"WINNER","sortPriority":3,"id":12984952,"name":"Troicki 2-0"},{"status":"LOSER","sortPriority":4,"id":12984951,"name":"Troicki 2-1"}],"regulators":["MR_INT"],"countryCode":"IN","discountAllowed":true,"timezone":"UTC","openDate":"2020-02-02T11:07:00.000Z","version":3148697630,"name":"Set Betting","eventName":"Karlovskiy v Troicki"}}]}
