{"op":"mcm","clk":"1001415471","pt":1580567750513,"mc":[{"id":"1.168217557","marketDefinition":{"bspMarket":false,"turnInPlayEnabled":true,"persistenceEnabled":true,"marketBaseRate":5.0,"eventId":"29681263","eventTypeId":"2","numberOfWinners":1,"bettingType":"ODDS","marketType":"SET_WINNER","marketTime":"2020-02-02T11:30:00.000Z","suspendTime":"2020-02-02T11:30:00.000Z","bspReconciled":false,"complete":true,"inPlay":false,"crossMatching":false,"runnersVoidable":false,"numberOfActiveRunners":2,"betDelay":0,"status":"OPEN","runners":[{"status":"ACTIVE","sortPriority":1,"id":7412809,"name":"Evgeny Karlovskiy"},{"status":"ACTIVE","sortPriority":2,"id":2263624,"name":"Viktor Troicki"}],"regulators":["MR_INT"],"countryCode":"IN","discountAllowed":false,"timezone":"UTC","openDate":"2020-02-02T11:30:00.000Z","version":3145496349,"name":"Set 2 Winner","eventName":"Karlovskiy v Troicki"}}]}
{"op":"mcm","clk":"1001415705","pt":1580567751514,"mc":[{"id":"1.168217557","marketDefinition":{"bspMarket":false,"turnInPlayEnabled":true,"persistenceEnabled":true,"marketBaseRate":5.0,"eventId":"29681263","eventTypeId":"2","numberOfWinners":1,"bettingType":"ODDS","marketType":"SET_WINNER","marketTime":"2020-02-02T11:30:00.000Z","suspendTime":"2020-02-02T11:30:00.000Z","bspReconciled":false,"complete":true,"inPlay":false,"crossMatching":false,"runnersVoidable":false,"numberOfActiveRunners":2,"betDelay":0,"status":"OPEN","runners":[{"status":"ACTIVE","sortPriority":1,"id":7412809,"name":"Evgeny Karlovskiy"},{"status":"ACTIVE","sortPriority":2,"id":2263624,"name":"Viktor Troicki"}],"regulators":["MR_INT"],"countryCode":"IN","discountAllowed":false,"timezone":"UTC","openDate":"2020-02-02T11:30:00.000Z","version":3145496349,"name":"Set 2 Winner","eventName":"Karlovskiy v Troicki"}}]}
{"op":"mcm","clk":"1001415945","pt":1580567752496,"mc":[{"id":"1.168217557","marketDefinition":{"bspMarket":false,"turnInPlayEnabled":true,"persistenceEnabled":true,"marketBaseRate":5.0,"eventId":"29681263","eventTypeId":"2","numberOfWinners":1,"bettingType":"ODDS","marketType":"SET_WINNER","marketTime":"2020-02-02T11:30:00.000Z","suspendTime":"2020-02-02T11:30:00.000Z","bspReconciled":false,"complete":true,"inPlay":false,"crossMatching":false,"runnersVoidable":false,"numberOfActiveRunners":2,"betDelay":0,"status":"OPEN","runners":[{"status":"ACTIVE","sortPriority":1,"id":7412809,"name":"Evgeny Karlovskiy"},{"status":"ACTIVE","sortPriority":2,"id":2263624,"name":"Viktor Troicki"}],"regulators":["MR_INT"],"countryCode":"IN","discountAllowed":true,"timezone":"UTC","openDate":"2020-02-02T11:30:00.000Z","version":3145496349,"name":"Set 2 Winner","eventName":"Karlovskiy v Troicki"}}]}
{"op":"mcm","clk":"1001422883","pt":1580567785309,"mc":[{"id":"1.168217557","rc":[{"batb":[[0,1.01,20]],"ltp":0.0,"tv":0.0,"id":2263624},{"batb":[[0,1.01,20]],"ltp":0.0,"tv":0.0,"id":7412809}]}]}
{"op":"mcm","clk":"1001538126","pt":1580568313525,"mc":[{"id":"1.168217557","rc":[{"batb":[[0,1.01,10]],"ltp":0.0,"tv":0.0,"id":2263624},{"batb":[[0,1.01,10]],"ltp":0.0,"tv":0.0,"id":7412809}]}]}
{"op":"mcm","clk":"1006948413","pt":1580602466518,"mc":[{"id":"1.168217557","rc":[{"batb":[[0,1.01,10.51]],"ltp":0.0,"tv":0.0,"id":2263624},{"batb":[[0,1.01,10.51]],"ltp":0.0,"tv":0.0,"id":7412809}]}]}
{"op":"mcm","clk":"1007059766","pt":1580604000402,"mc":[{"id":"1.168217557","rc":[{"batb":[[0,1.01,11.01]],"ltp":0.0,"tv":0.0,"id":2263624},{"batb":[[0,1.01,11.01]],"ltp":0.0,"tv":0.0,"id":7412809}]}]}
{"op":"mcm","clk":"1007202965","pt":1580607093378,"mc":[{"id":"1.168217557","rc":[{"batb":[[0,1.01,11.02]],"ltp":0.0,"tv":0.0,"id":2263624},{"batb":[[0,1.01,11.02]],"ltp":0.0,"tv":0.0,"id":7412809}]}]}
{"op":"mcm","clk":"1008458746","pt":1580635606316,"mc":[{"id":"1.168217557","marketDefinition":{"bspMarket":false,"turnInPlayEnabled":true,"persistenceEnabled":true,"marketBaseRate":5.0,"eventId":"29681263","eventTypeId":"2","numberOfWinners":1,"bettingType":"ODDS","marketType":"SET_WINNER","marketTime":"2020-02-02T11:21:00.000Z","suspendTime":"2020-02-02T11:21:00.000Z","bspReconciled":false,"complete":true,"inPlay":false,"crossMatching":false,"runnersVoidable":false,"numberOfActiveRunners":2,"betDelay":0,"status":"OPEN","runners":[{"status":"ACTIVE","sortPriority":1,"id":7412809,"name":"Evgeny Karlovskiy"},{"status":"ACTIVE","sortPriority":2,"id":2263624,"name":"Viktor Troicki"}],"regulators":["MR_INT"],"countryCode":"IN","discountAllowed":true,"timezone":"UTC","openDate":"2020-02-02T11:30:00.000Z","version":3148345101,"name":"Set 2 Winner","eventName":"Karlovskiy v Troicki"}}]}
{"op":"mcm","clk":"1008459143","pt":1580635610325,"mc":[{"id":"1.168217557","marketDefinition":{"bspMarket":false,"turnInPlayEnabled":true,"persistenceEnabled":true,"marketBaseRate":5.0,"eventId":"29681263","eventTypeId":"2","numberOfWinners":1,"bettingType":"ODDS","marketType":"SET_WINNER","marketTime":"2020-02-02T11:21:00.000Z","suspendTime":"2020-02-02T11:21:00.000Z","bspReconciled":false,"complete":true,"inPlay":false,"crossMatching":false,"runnersVoidable":false,"numberOfActiveRunners":2,"betDelay":0,"status":"OPEN","runners":[{"status":"ACTIVE","sortPriority":1,"id":7412809,"name":"Evgeny Karlovskiy"},{"status":"ACTIVE","sortPriority":2,"id":2263624,"name":"Viktor Troicki"}],"regulators":["MR_INT"],"countryCode":"IN","discountAllowed":true,"timezone":"UTC","openDate":"2020-02-02T11:21:00.000Z","version":3148345101,"name":"Set 2 Winner","eventName":"Karlovskiy v Troicki"}}]}
{"op":"mcm","clk":"1009033963","pt":1580641605793,"mc":[{"id":"1.168217557","marketDefinition":{"bspMarket":false,"turnInPlayEnabled":true,"persistenceEnabled":true,"marketBaseRate":5.0,"eventId":"29681263","eventTypeId":"2","numberOfWinners":1,"bettingType":"ODDS","marketType":"SET_WINNER","marketTime":"2020-02-02T11:09:00.000Z","suspendTime":"2020-02-02T11:09:00.000Z","bspReconciled":false,"complete":true,"inPlay":false,"crossMatching":false,"runnersVoidable":false,"numberOfActiveRunners":2,"betDelay":0,"status":"OPEN","runners":[{"status":"ACTIVE","sortPriority":1,"id":7412809,"name":"Evgeny Karlovskiy"},{"status":"ACTIVE","sortPriority":2,"id":2263624,"name":"Viktor Troicki"}],"regulators":["MR_INT"],"countryCode":"IN","discountAllowed":true,"timezone":"UTC","openDate":"2020-02-02T11:21:00.000Z","version":3148499129,"name":"Set 2 Winner","eventName":"Karlovskiy v Troicki"}}]}
{"op":"mcm","clk":"1009034829","pt":1580641610805,"mc":[{"id":"1.168217557","marketDefinition":{"bspMarket":false,"turnInPlayEnabled":true,"persistenceEnabled":true,"marketBaseRate":5.0,"eventId":"29681263","eventTypeId":"2","numberOfWinners":1,"bettingType":"ODDS","marketType":"SET_WINNER","marketTime":"2020-02-02T11:09:00.000Z","suspendTime":"2020-02-02T11:09:00.000Z","bspReconciled":false,"complete":true,"inPlay":false,"crossMatching":false,"runnersVoidable":false,"numberOfActiveRunners":2,"betDelay":0,"status":"OPEN","runners":[{"status":"ACTIVE","sortPriority":1,"id":7412809,"name":"Evgeny Karlovskiy"},{"status":"ACTIVE","sortPriority":2,"id":2263624,"name":"Viktor Troicki"}],"regulators":["MR_INT"],"countryCode":"IN","discountAllowed":true,"timezone":"UTC","openDate":"2020-02-02T11:09:00.000Z","version":3148499129,"name":"Set 2 Winner","eventName":"Karlovskiy v Troicki"}}]}
{"op":"mcm","clk":"1009058427","pt":1580641763010,"mc":[{"id":"1.168217557","rc":[{"batb":[[0,1.64,26.67],[1,1.01,11.02]],"ltp":0.0,"tv":0.0,"id":2263624},{"batb":[[0,2.36,17.55],[1,1.01,11.02]],"ltp":0.0,"tv":0.0,"id":7412809}]}]}
{"op":"mcm","clk":"1009061288","pt":1580641781459,"mc":[{"id":"1.168217557","marketDefinition":{"bspMarket":false,"turnInPlayEnabled":true,"persistenceEnabled":true,"marketBaseRate":5.0,"eventId":"29681263","eventTypeId":"2","numberOfWinners":1,"bettingType":"ODDS","marketType":"SET_WINNER","marketTime":"2020-02-02T11:09:00.000Z","suspendTime":"2020-02-02T11:09:00.000Z","bspReconciled":false,"complete":true,"inPlay":false,"crossMatching":true,"runnersVoidable":false,"numberOfActiveRunners":2,"betDelay":0,"status":"OPEN","runners":[{"status":"ACTIVE","sortPriority":1,"id":7412809,"name":"Evgeny Karlovskiy"},{"status":"ACTIVE","sortPriority":2,"id":2263624,"name":"Viktor Troicki"}],"regulators":["MR_INT"],"countryCode":"IN","discountAllowed":true,"timezone":"UTC","openDate":"2020-02-02T11:09:00.000Z","version":3148499129,"name":"Set 2 Winner","eventName":"Karlovskiy v Troicki"}}]}
{"op":"mcm","clk":"1009062747","pt":1580641791469,"mc":[{"id":"1.168217557","rc":[{"batb":[[0,2.36,17.39]],"ltp":0.0,"tv":0.0,"id":7412809}]}]}
{"op":"mcm","clk":"1009079667","pt":1580641907335,"mc":[{"id":"1.168217557","marketDefinition":{"bspMarket":false,"turnInPlayEnabled":true,"persistenceEnabled":true,"marketBaseRate":5.0,"eventId":"29681263","eventTypeId":"2","numberOfWinners":1,"bettingType":"ODDS","marketType":"SET_WINNER","marketTime":"2020-02-02T11:07:00.000Z","suspendTime":"2020-02-02T11:07:00.000Z","bspReconciled":false,"complete":true,"inPlay":false,"crossMatching":true,"runnersVoidable":false,"numberOfActiveRunners":2,"betDelay":0,"status":"OPEN","runners":[{"status":"ACTIVE","sortPriority":1,"id":7412809,"name":"Evgeny Karlovskiy"},{"status":"ACTIVE","sortPriority":2,"id":2263624,"name":"Viktor Troicki"}],"regulators":["MR_INT"],"countryCode":"IN","discountAllowed":true,"timezone":"UTC","openDate":"2020-02-02T11:09:00.000Z","version":3148508174,"name":"Set 2 Winner","eventName":"Karlovskiy v Troicki"}}]}
{"op":"mcm","clk":"1009080067","pt":1580641909607,"mc":[{"id":"1.168217557","marketDefinition":{"bspMarket":false,"turnInPlayEnabled":true,"persistenceEnabled":true,"marketBaseRate":5.0,"eventId":"29681263","eventTypeId":"2","numberOfWinners":1,"bettingType":"ODDS","marketType":"SET_WINNER","marketTime":"2020-02-02T11:07:00.000Z","suspendTime":"2020-02-02T11:07:00.000Z","bspReconciled":false,"complete":true,"inPlay":false,"crossMatching":true,"runnersVoidable":false,"numberOfActiveRunners":2,"betDelay":0,"status":"OPEN","runners":[{"status":"ACTIVE","sortPriority":1,"id":7412809,"name":"Evgeny Karlovskiy"},{"status":"ACTIVE","sortPriority":2,"id":2263624,"name":"Viktor Troicki"}],"regulators":["MR_INT"],"countryCode":"IN","discountAllowed":true,"timezone":"UTC","openDate":"2020-02-02T11:07:00.000Z","version":3148508174,"name":"Set 2 Winner","eventName":"Karlovskiy v Troicki"}}]}
{"op":"mcm","clk":"1009102038","pt":1580642049085,"mc":[{"id":"1.168217557","rc":[{"batb":[[1,1.61,68.06],[2,1.01,11.02]],"batl":[[0,1.75,42.01]],"ltp":0.0,"tv":0.0,"id":2263624},{"batb":[[0,2.36,47.64]],"batl":[[0,2.66,25.21]],"ltp":0.0,"tv":0.0,"id":7412809}]}]}
{"op":"mcm","clk":"1009129154","pt":1580642213516,"mc":[{"id":"1.168217557","rc":[{"batb":[[0,1.65,2],[1,1.64,26.67],[2,1.61,68.06]],"ltp":0.0,"tv":0.0,"id":2263624},{"batb":[[0,2.38,2],[1,2.36,47.64],[2,1.01,11.02]],"ltp":0.0,"tv":0.0,"id":7412809}]}]}
{"op":"mcm","clk":"1009142257","pt":1580642298506,"mc":[{"id":"1.168217557","marketDefinition":{"bspMarket":false,"turnInPlayEnabled":true,"persistenceEnabled":true,"marketBaseRate":5.0,"eventId":"29681263","eventTypeId":"2","numberOfWinners":1,"bettingType":"ODDS","marketType":"SET_WINNER","marketTime":"2020-02-02T11:07:00.000Z","suspendTime":"2020-02-02T11:07:00.000Z","bspReconciled":false,"complete":true,"inPlay":true,"crossMatching":true,"runnersVoidable":false,"numberOfActiveRunners":2,"betDelay":3,"status":"OPEN","runners":[{"status":"ACTIVE","sortPriority":1,"id":7412809,"name":"Evgeny Karlovskiy"},{"status":"ACTIVE","sortPriority":2,"id":2263624,"name":"Viktor Troicki"}],"regulators":["MR_INT"],"countryCode":"IN","discountAllowed":true,"timezone":"UTC","openDate":"2020-02-02T11:07:00.000Z","version":3148519505,"name":"Set 2 Winner","eventName":"Karlovskiy v Troicki"},"rc":[{"batb":[[1,1.61,68.06],[2,1.01,11.02]],"ltp":0.0,"tv":0.0,"id":2263624},{"batb":[[1,2.36,30.25]],"ltp":0.0,"tv":0.0,"id":7412809}]}]}
{"op":"mcm","clk":"1009142281","pt":1580642298583,"mc":[{"id":"1.168217557","rc":[{"batb":[[0,1.01,10.52],[1,1.61,0],[2,1.01,0]],"ltp":0.0,"tv":0.0,"id":2263624},{"batb":[[0,1.01,10.52],[1,2.36,0],[2,1.01,0]],"ltp":0.0,"tv":0.0,"id":7412809}]}]}
{"op":"mcm","clk":"1009143285","pt":1580642305432,"mc":[{"id":"1.168217557","rc":[{"batb":[[0,1.67,25.1],[1,1.63,27.3],[2,1.01,10.52]],"ltp":0.0,"tv":0.0,"id":2263624},{"batb":[[0,2.3,18.8],[1,2.28,19.28],[2,1.01,10.52]],"ltp":0.0,"tv":0.0,"id":7412809}]}]}
{"op":"mcm","clk":"1009143343","pt":1580642305846,"mc":[{"id":"1.168217557","rc":[{"batb":[[2,1.62,67.22]],"batl":[[0,1.76,42.01]],"ltp":0.0,"tv":0.0,"id":2263624},{"batb":[[0,2.3,50.73]],"ltp":0.0,"tv":0.0,"id":7412809}]}]}
{"op":"mcm","clk":"1009143550","pt":1580642307246,"mc":[{"id":"1.168217557","rc":[{"batl":[[0,2.62,25.21]],"ltp":0.0,"tv":0.0,"id":7412809}]}]}
{"op":"mcm","clk":"1009144262","pt":1580642312448,"mc":[{"id":"1.168217557","rc":[{"batb":[[0,1.63,27.3],[1,1.01,10.52],[2,1.62,0]],"ltp":0.0,"tv":0.0,"id":2263624},{"batb":[[0,2.28,19.28],[1,1.01,10.52],[2,1.01,0]],"ltp":0.0,"tv":0.0,"id":7412809}]}]}
{"op":"mcm","clk":"1009146638","pt":1580642327483,"mc":[{"id":"1.168217557","rc":[{"batb":[[0,1.64,65.54],[1,1.63,185.53],[2,1.01,10.52]],"batl":[[0,1.79,42.01]],"ltp":0.0,"tv":0.0,"id":2263624},{"batb":[[1,2.26,32.77],[2,1.01,10.52]],"batl":[[0,2.58,26.05]],"ltp":0.0,"tv":0.0,"id":7412809}]}]}
{"op":"mcm","clk":"1009146678","pt":1580642327804,"mc":[{"id":"1.168217557","rc":[{"batb":[[0,1.68,24.55],[1,1.65,26.12],[2,1.64,65.54]],"ltp":0.0,"tv":0.0,"id":2263624},{"batb":[[2,2.24,20.3]],"ltp":0.0,"tv":0.0,"id":7412809}]}]}
{"op":"mcm","clk":"1009149871","pt":1580642346504,"mc":[{"id":"1.168217557","rc":[{"batb":[[0,1.65,26.12],[1,1.01,10.52],[2,1.64,0]],"ltp":0.0,"tv":0.0,"id":2263624},{"batb":[[0,2.24,20.3],[1,1.01,10.52],[2,2.24,0]],"ltp":0.0,"tv":0.0,"id":7412809}]}]}
{"op":"mcm","clk":"1009151324","pt":1580642356002,"mc":[{"id":"1.168217557","rc":[{"batb":[[0,1.71,23.45],[1,1.68,24.78],[2,1.66,63.01]],"batl":[[0,1.82,42.01]],"ltp":0.0,"tv":0.0,"id":2263624},{"batb":[[1,2.22,33.61],[2,2.2,21.24]],"batl":[[0,2.54,26.89]],"ltp":0.0,"tv":0.0,"id":7412809}]}]}
{"op":"mcm","clk":"1009152926","pt":1580642367453,"mc":[{"id":"1.168217557","rc":[{"batb":[[0,1.68,24.78],[1,1.66,63.01],[2,1.01,10.52]],"ltp":0.0,"tv":0.0,"id":2263624},{"batb":[[0,2.22,33.61],[1,2.2,21.24],[2,1.01,10.52]],"ltp":0.0,"tv":0.0,"id":7412809}]}]}
{"op":"mcm","clk":"1009153233","pt":1580642369250,"mc":[{"id":"1.168217557","rc":[{"batb":[[1,1.01,10.52],[2,1.01,0]],"ltp":0.0,"tv":0.0,"id":2263624},{"batb":[[0,2.2,21.24],[1,1.01,10.52],[2,1.01,0]],"ltp":0.0,"tv":0.0,"id":7412809}]}]}
{"op":"mcm","clk":"1009155590","pt":1580642385459,"mc":[{"id":"1.168217557","rc":[{"batb":[[1,1.64,26.83],[2,1.63,66.38]],"batl":[[0,1.78,42.01]],"ltp":0.0,"tv":0.0,"id":2263624},{"batb":[[0,2.28,51.89],[1,2.26,19.83],[2,1.01,10.52]],"batl":[[0,2.6,26.05]],"ltp":0.0,"tv":0.0,"id":7412809}]}]}
{"op":"mcm","clk":"1009157860","pt":1580642402477,"mc":[{"id":"1.168217557","rc":[{"batb":[[0,1.64,26.83],[1,1.01,10.52],[2,1.63,0]],"ltp":0.0,"tv":0.0,"id":2263624},{"batb":[[0,2.26,19.83],[1,1.01,10.52],[2,1.01,0]],"ltp":0.0,"tv":0.0,"id":7412809}]}]}
{"op":"mcm","clk":"1009162151","pt":1580642429426,"mc":[{"id":"1.168217557","rc":[{"batb":[[0,1.7,23.92],[1,1.67,25.18],[2,1.01,10.52]],"ltp":0.0,"tv":0.0,"id":2263624},{"batb":[[1,2.18,21.87],[2,1.01,10.52]],"ltp":0.0,"tv":0.0,"id":7412809}]}]}
{"op":"mcm","clk":"1009162168","pt":1580642429531,"mc":[{"id":"1.168217557","rc":[{"batb":[[1,1.67,87.35]],"batl":[[0,1.82,42.01]],"ltp":0.0,"tv":0.0,"id":2263624},{"batb":[[1,2.22,33.61],[2,2.18,21.87]],"batl":[[0,2.52,26.89]],"ltp":0.0,"tv":0.0,"id":7412809}]}]}
{"op":"mcm","clk":"1009169378","pt":1580642478509,"mc":[{"id":"1.168217557","rc":[{"batb":[[0,1.67,25.18],[1,1.01,10.52],[2,1.01,0]],"ltp":0.0,"tv":0.0,"id":2263624},{"batb":[[0,2.18,21.87],[1,1.01,10.52],[2,2.18,0]],"ltp":0.0,"tv":0.0,"id":7412809}]}]}
{"op":"mcm","clk":"1009170844","pt":1580642489502,"mc":[{"id":"1.168217557","rc":[{"batb":[[1,1.65,63.85],[2,1.01,10.52]],"batl":[[0,1.8,42.01]],"ltp":0.0,"tv":0.0,"id":2263624},{"batb":[[0,2.26,32.77],[1,2.18,21.87],[2,1.01,10.52]],"batl":[[0,2.56,26.89]],"ltp":0.0,"tv":0.0,"id":7412809}]}]}
{"op":"mcm","clk":"1009170910","pt":1580642490026,"mc":[{"id":"1.168217557","rc":[{"batb":[[1,1.66,25.89],[2,1.65,63.85]],"ltp":0.0,"tv":0.0,"id":2263624},{"batb":[[0,2.3,18.8],[1,2.26,32.77],[2,2.22,20.54]],"ltp":0.0,"tv":0.0,"id":7412809}]}]}
{"op":"mcm","clk":"1009172225","pt":1580642500558,"mc":[{"id":"1.168217557","rc":[{"batb":[[0,1.66,25.89],[1,1.01,10.52],[2,1.65,0]],"ltp":0.0,"tv":0.0,"id":2263624},{"batb":[[0,2.22,20.54],[1,1.01,10.52],[2,2.22,0]],"ltp":0.0,"tv":0.0,"id":7412809}]}]}
{"op":"mcm","clk":"1009173176","pt":1580642507437,"mc":[{"id":"1.168217557","rc":[{"batb":[[1,1.64,26.91],[2,1.01,10.52]],"ltp":0.0,"tv":0.0,"id":2263624},{"batb":[[0,2.32,18.18],[1,2.26,19.75],[2,2.22,20.54]],"ltp":0.0,"tv":0.0,"id":7412809}]}]}
{"op":"mcm","clk":"1009173187","pt":1580642507545,"mc":[{"id":"1.168217557","rc":[{"batb":[[2,1.63,66.38]],"batl":[[0,1.78,42.01]],"ltp":0.0,"tv":0.0,"id":2263624},{"batb":[[1,2.3,31.93],[2,2.26,19.75]],"batl":[[0,2.6,26.05]],"ltp":0.0,"tv":0.0,"id":7412809}]}]}
{"op":"mcm","clk":"1009174185","pt":1580642514858,"mc":[{"id":"1.168217557","rc":[{"batb":[[0,1.64,26.91],[1,1.63,66.38],[2,1.01,10.52]],"ltp":0.0,"tv":0.0,"id":2263624},{"batb":[[0,2.3,31.93],[1,2.26,19.75],[2,1.01,10.52]],"ltp":0.0,"tv":0.0,"id":7412809}]}]}
{"op":"mcm","clk":"1009174454","pt":1580642516578,"mc":[{"id":"1.168217557","rc":[{"batb":[[1,1.01,10.52],[2,1.01,0]],"ltp":0.0,"tv":0.0,"id":2263624},{"batb":[[0,2.26,19.75],[1,1.01,10.52],[2,1.01,0]],"ltp":0.0,"tv":0.0,"id":7412809}]}]}
{"op":"mcm","clk":"1009176057","pt":1580642527483,"mc":[{"id":"1.168217557","rc":[{"batb":[[1,1.62,67.22],[2,1.01,10.52]],"batl":[[0,1.76,42.01],[1,2.22,329.01]],"ltp":0.0,"tv":0.0,"id":2263624},{"batb":[[0,2.32,31.09],[1,2.26,19.75],[2,1.01,10.52]],"batl":[[0,2.64,25.21],[1,3.15,200.42]],"ltp":0.0,"tv":0.0,"id":7412809}]}]}
{"op":"mcm","clk":"1009176154","pt":1580642528077,"mc":[{"id":"1.168217557","rc":[{"batb":[[1,1.62,95.15]],"ltp":0.0,"tv":0.0,"id":2263624},{"batb":[[0,2.36,17.39],[1,2.32,31.09],[2,2.3,18.73]],"ltp":0.0,"tv":0.0,"id":7412809}]}]}
{"op":"mcm","clk":"1009177339","pt":1580642536180,"mc":[{"id":"1.168217557","rc":[{"batb":[[0,1.62,95.15],[1,1.01,10.52],[2,1.01,0]],"ltp":0.0,"tv":0.0,"id":2263624},{"batb":[[0,2.32,31.09],[1,2.3,18.73],[2,1.01,10.52]],"ltp":0.0,"tv":0.0,"id":7412809}]}]}
{"op":"mcm","clk":"1009177405","pt":1580642536596,"mc":[{"id":"1.168217557","rc":[{"batb":[[0,1.62,27.93]],"batl":[[0,2.22,329.01],[1,2.22,0]],"ltp":0.0,"tv":0.0,"id":2263624},{"batb":[[0,2.3,18.73],[1,1.01,10.52],[2,1.01,0]],"batl":[[0,3.15,200.42],[1,3.15,0]],"ltp":0.0,"tv":0.0,"id":7412809}]}]}
{"op":"mcm","clk":"1009179461","pt":1580642549522,"mc":[{"id":"1.168217557","rc":[{"batb":[[1,1.59,100.87],[2,1.01,10.52]],"batl":[[0,1.73,42.01],[1,2.22,329.01]],"ltp":0.0,"tv":0.0,"id":2263624},{"batb":[[0,2.4,16.68],[1,2.38,30.25],[2,2.36,17.62]],"batl":[[0,2.72,24.37],[1,3.15,200.42]],"ltp":0.0,"tv":0.0,"id":7412809}]}]}
{"op":"mcm","clk":"1009183710","pt":1580642577490,"mc":[{"id":"1.168217557","rc":[{"batb":[[0,1.59,100.87],[1,1.01,10.52],[2,1.01,0]],"ltp":0.0,"tv":0.0,"id":2263624},{"batb":[[0,2.38,30.25],[1,2.36,17.62],[2,1.01,10.52]],"ltp":0.0,"tv":0.0,"id":7412809}]}]}
{"op":"mcm","clk":"1009183900","pt":1580642578615,"mc":[{"id":"1.168217557","rc":[{"batb":[[0,1.59,30.29]],"batl":[[0,2.22,329.01],[1,2.22,0]],"ltp":0.0,"tv":0.0,"id":2263624},{"batb":[[0,2.36,17.62],[1,1.01,10.52],[2,1.01,0]],"batl":[[0,3.15,200.42],[1,3.15,0]],"ltp":0.0,"tv":0.0,"id":7412809}]}]}
{"op":"mcm","clk":"1009186707","pt":1580642598127,"mc":[{"id":"1.168217557","rc":[{"batb":[[1,1.54,33.83],[2,1.01,10.52]],"batl":[[0,1.7,42.01]],"ltp":0.0,"tv":0.0,"id":2263624},{"batb":[[0,2.48,15.11],[1,2.44,44.54],[2,1.01,10.52]],"batl":[[0,2.8,22.69],[1,3.15,200.42]],"ltp":0.0,"tv":0.0,"id":7412809}]}]}
{"op":"mcm","clk":"1009186900","pt":1580642599420,"mc":[{"id":"1.168217557","rc":[{"batl":[[1,2.1,363.31]],"ltp":0.0,"tv":0.0,"id":2263624}]}]}
{"op":"mcm","clk":"1009187006","pt":1580642600153,"mc":[{"id":"1.168217557","rc":[{"batb":[[1,1.56,74.78],[2,1.54,33.83]],"ltp":0.0,"tv":0.0,"id":2263624}]}]}
{"op":"mcm","clk":"1009189866","pt":1580642619891,"mc":[{"id":"1.168217557","rc":[{"batb":[[0,1.56,74.78],[1,1.54,33.83],[2,1.01,10.52]],"ltp":0.0,"tv":0.0,"id":2263624},{"batb":[[0,2.44,44.54],[1,1.01,10.52],[2,1.01,0]],"ltp":0.0,"tv":0.0,"id":7412809}]}]}
{"op":"mcm","clk":"1009189995","pt":1580642620646,"mc":[{"id":"1.168217557","rc":[{"batb":[[0,1.54,33.83],[1,1.01,10.52],[2,1.01,0]],"batl":[[0,2.1,363.31],[1,2.1,0]],"ltp":0.0,"tv":0.0,"id":2263624},{"batb":[[0,2.44,15.97]],"batl":[[0,3.15,200.42],[1,3.15,0]],"ltp":0.0,"tv":0.0,"id":7412809}]}]}
{"op":"mcm","clk":"1009192558","pt":1580642638490,"mc":[{"id":"1.168217557","rc":[{"batb":[[0,1.54,111.13],[1,1.5,37.14],[2,1.01,10.52]],"batl":[[0,1.67,42.01],[1,2.1,363.31]],"ltp":0.0,"tv":0.0,"id":2263624},{"batb":[[0,2.6,13.38],[1,2.52,41.36],[2,1.01,10.52]],"batl":[[0,2.88,21.85]],"ltp":0.0,"tv":0.0,"id":7412809}]}]}
{"op":"mcm","clk":"1009192855","pt":1580642640414,"mc":[{"id":"1.168217557","rc":[{"batl":[[1,3.65,170.41]],"ltp":0.0,"tv":0.0,"id":7412809}]}]}
{"op":"mcm","clk":"1009194507","pt":1580642651700,"mc":[{"id":"1.168217557","rc":[{"batb":[[0,1.54,77.3]],"ltp":0.0,"tv":0.0,"id":2263624},{"batb":[[0,2.52,41.36],[1,1.01,10.52],[2,1.01,0]],"ltp":0.0,"tv":0.0,"id":7412809}]}]}
{"op":"mcm","clk":"1009194650","pt":1580642652600,"mc":[{"id":"1.168217557","rc":[{"batb":[[0,1.5,37.14],[1,1.01,10.52],[2,1.01,0]],"batl":[[0,2.1,363.31],[1,2.1,0]],"ltp":0.0,"tv":0.0,"id":2263624},{"batb":[[0,2.52,14.48]],"batl":[[0,3.65,170.41],[1,3.65,0]],"ltp":0.0,"tv":0.0,"id":7412809}]}]}
{"op":"mcm","clk":"1009196424","pt":1580642664311,"mc":[{"id":"1.168217557","rc":[{"batb":[[0,1.57,31.55],[1,1.55,75.62],[2,1.53,35.17]],"batl":[[0,1.68,42.01],[1,2.1,363.31]],"ltp":0.0,"tv":0.0,"id":2263624},{"batb":[[1,2.48,27.73],[2,2.46,15.66]],"batl":[[0,2.84,22.69],[1,3.65,170.41]],"ltp":0.0,"tv":0.0,"id":7412809}]}]}
{"op":"mcm","clk":"1009199585","pt":1580642686165,"mc":[{"id":"1.168217557","rc":[{"batb":[[0,1.55,75.62],[1,1.53,35.17],[2,1.01,10.52]],"ltp":0.0,"tv":0.0,"id":2263624},{"batb":[[0,2.48,27.73],[1,2.46,15.66],[2,1.01,10.52]],"ltp":0.0,"tv":0.0,"id":7412809}]}]}
{"op":"mcm","clk":"1009199646","pt":1580642686537,"mc":[{"id":"1.168217557","rc":[{"batb":[[0,1.53,35.17],[1,1.01,10.52],[2,1.01,0]],"batl":[[0,2.1,363.31],[1,2.1,0]],"ltp":0.0,"tv":0.0,"id":2263624},{"batb":[[0,2.46,15.66],[1,1.01,10.52],[2,1.01,0]],"batl":[[0,3.65,170.41],[1,3.65,0]],"ltp":0.0,"tv":0.0,"id":7412809}]}]}
{"op":"mcm","clk":"1009201853","pt":1580642702259,"mc":[{"id":"1.168217557","rc":[{"batb":[[0,1.53,114.15],[1,1.48,39.19],[2,1.01,10.51]],"batl":[[0,1.66,42.01]],"ltp":0.0,"tv":0.0,"id":2263624},{"batb":[[0,2.66,12.75],[1,2.58,13.77],[2,2.54,26.89]],"batl":[[0,2.9,21.85],[1,3.65,170.41]],"ltp":0.0,"tv":0.0,"id":7412809}]}]}
{"op":"mcm","clk":"1009202150","pt":1580642704561,"mc":[{"id":"1.168217557","rc":[{"batl":[[1,1.95,409.86]],"ltp":0.0,"tv":0.0,"id":2263624}]}]}
{"op":"mcm","clk":"1009204994","pt":1580642724906,"mc":[{"id":"1.168217557","rc":[{"batb":[[0,1.53,78.98]],"ltp":0.0,"tv":0.0,"id":2263624},{"batb":[[0,2.58,13.77],[1,2.54,26.89],[2,1.01,10.52]],"ltp":0.0,"tv":0.0,"id":7412809}]}]}
{"op":"mcm","clk":"1009205245","pt":1580642726704,"mc":[{"id":"1.168217557","rc":[{"batb":[[0,1.48,39.19],[1,1.01,10.51],[2,1.01,0]],"batl":[[0,1.95,409.86],[1,1.95,0]],"ltp":0.0,"tv":0.0,"id":2263624},{"batb":[[1,1.01,10.52],[2,1.01,0]],"batl":[[0,3.65,170.41],[1,3.65,0]],"ltp":0.0,"tv":0.0,"id":7412809}]}]}
{"op":"mcm","clk":"1009208403","pt":1580642748414,"mc":[{"id":"1.168217557","rc":[{"batb":[[0,1.55,32.97],[1,1.54,77.3],[2,1.5,37.69]],"batl":[[0,1.67,42.01],[1,1.95,409.86]],"ltp":0.0,"tv":0.0,"id":2263624},{"batb":[[1,2.52,26.89],[2,2.48,15.34]],"batl":[[0,2.86,21.85],[1,3.65,170.41]],"ltp":0.0,"tv":0.0,"id":7412809}]}]}
{"op":"mcm","clk":"1009211397","pt":1580642769073,"mc":[{"id":"1.168217557","rc":[{"batb":[[0,1.54,77.3],[1,1.5,37.69],[2,1.01,10.52]],"ltp":0.0,"tv":0.0,"id":2263624},{"batb":[[0,2.52,26.89],[1,2.48,15.34],[2,1.01,10.52]],"ltp":0.0,"tv":0.0,"id":7412809}]}]}
{"op":"mcm","clk":"1009211617","pt":1580642770651,"mc":[{"id":"1.168217557","rc":[{"batb":[[0,1.5,37.69],[1,1.01,10.52],[2,1.01,0]],"batl":[[0,1.95,409.86],[1,1.95,0]],"ltp":0.0,"tv":0.0,"id":2263624},{"batb":[[0,2.48,15.34],[1,1.01,10.52],[2,1.01,0]],"batl":[[0,3.65,170.41],[1,3.65,0]],"ltp":0.0,"tv":0.0,"id":7412809}]}]}
{"op":"mcm","clk":"1009214889","pt":1580642792460,"mc":[{"id":"1.168217557","rc":[{"batb":[[1,1.48,39.43],[2,1.47,89.06]],"batl":[[0,1.59,42.01],[1,1.95,409.86]],"ltp":0.0,"tv":0.0,"id":2263624},{"batb":[[0,2.74,11.72],[1,2.68,24.37],[2,2.64,12.98]],"batl":[[0,3.1,19.32],[1,3.65,170.41]],"ltp":0.0,"tv":0.0,"id":7412809}]}]}
{"op":"mcm","clk":"1009220247","pt":1580642825139,"mc":[{"id":"1.168217557","rc":[{"batb":[[2,1.01,10.51]],"ltp":0.0,"tv":0.0,"id":2263624}]}]}
{"op":"mcm","clk":"1009220713","pt":1580642828274,"mc":[{"id":"1.168217557","rc":[{"batb":[[1,1.48,126.81]],"ltp":0.0,"tv":0.0,"id":2263624}]}]}
{"op":"mcm","clk":"1009227217","pt":1580642870319,"mc":[{"id":"1.168217557","rc":[{"batb":[[0,1.48,126.81],[1,1.01,10.51],[2,1.01,0]],"ltp":0.0,"tv":0.0,"id":2263624},{"batb":[[0,2.68,24.37],[1,2.64,12.98],[2,1.01,10.52]],"ltp":0.0,"tv":0.0,"id":7412809}]}]}
{"op":"mcm","clk":"1009227264","pt":1580642870645,"mc":[{"id":"1.168217557","rc":[{"batb":[[0,1.48,39.43]],"batl":[[0,1.95,409.86],[1,1.95,0]],"ltp":0.0,"tv":0.0,"id":2263624},{"batb":[[0,2.64,12.98],[1,1.01,10.52],[2,1.01,0]],"batl":[[0,3.65,170.41],[1,3.65,0]],"ltp":0.0,"tv":0.0,"id":7412809}]}]}
{"op":"mcm","clk":"1009233268","pt":1580642913453,"mc":[{"id":"1.168217557","rc":[{"batb":[[1,1.47,41.31],[2,1.01,10.51]],"ltp":0.0,"tv":0.0,"id":2263624},{"batb":[[0,2.8,11.09],[1,2.68,12.43],[2,2.64,292.55]],"ltp":0.0,"tv":0.0,"id":7412809}]}]}
{"op":"mcm","clk":"1009233386","pt":1580642914258,"mc":[{"id":"1.168217557","rc":[{"batb":[[1,1.47,130.37]],"batl":[[0,1.58,42.01],[1,1.95,409.86]],"ltp":0.0,"tv":0.0,"id":2263624},{"batb":[[1,2.72,24.37],[2,2.68,12.43]],"batl":[[0,3.15,19.32]],"ltp":0.0,"tv":0.0,"id":7412809}]}]}
{"op":"mcm","clk":"1009233687","pt":1580642916265,"mc":[{"id":"1.168217557","rc":[{"batl":[[1,4.2,148.03]],"ltp":0.0,"tv":0.0,"id":7412809}]}]}
{"op":"mcm","clk":"1009235437","pt":1580642927998,"mc":[{"id":"1.168217557","rc":[{"batb":[[0,1.47,130.38],[1,1.01,10.51],[2,1.01,0]],"ltp":0.0,"tv":0.0,"id":2263624},{"batb":[[0,2.72,24.37],[1,2.68,12.43],[2,1.01,10.52]],"ltp":0.0,"tv":0.0,"id":7412809}]}]}
{"op":"mcm","clk":"1009235558","pt":1580642928786,"mc":[{"id":"1.168217557","rc":[{"batb":[[0,1.47,41.32]],"batl":[[0,1.95,409.86],[1,1.95,0]],"ltp":0.0,"tv":0.0,"id":2263624},{"batb":[[0,2.68,12.43],[1,1.01,10.52],[2,1.01,0]],"batl":[[0,4.2,148.03],[1,4.2,0]],"ltp":0.0,"tv":0.0,"id":7412809}]}]}
{"op":"mcm","clk":"1009237298","pt":1580642940422,"mc":[{"id":"1.168217557","rc":[{"batb":[[1,1.46,42.33],[2,1.45,93.26]],"batl":[[0,1.57,42.01],[1,1.95,409.86]],"ltp":0.0,"tv":0.0,"id":2263624},{"batb":[[0,2.86,10.46],[1,2.78,23.53],[2,2.74,11.64]],"batl":[[0,3.2,18.48],[1,4.2,148.03]],"ltp":0.0,"tv":0.0,"id":7412809}]}]}
{"op":"mcm","clk":"1009238985","pt":1580642950430,"mc":[{"id":"1.168217557","rc":[{"batb":[[0,1.46,42.34],[1,1.45,93.26],[2,1.01,10.51]],"ltp":0.0,"tv":0.0,"id":2263624},{"batb":[[0,2.78,23.53],[1,2.74,11.64],[2,1.01,10.52]],"ltp":0.0,"tv":0.0,"id":7412809}]}]}
{"op":"mcm","clk":"1009239051","pt":1580642950758,"mc":[{"id":"1.168217557","rc":[{"batb":[[1,1.01,10.51],[2,1.01,0]],"batl":[[0,1.95,409.86],[1,1.95,0]],"ltp":0.0,"tv":0.0,"id":2263624},{"batb":[[0,2.74,11.64],[1,1.01,10.52],[2,1.01,0]],"batl":[[0,4.2,148.03],[1,4.2,0]],"ltp":0.0,"tv":0.0,"id":7412809}]}]}
{"op":"mcm","clk":"1009239437","pt":1580642953438,"mc":[{"id":"1.168217557","rc":[{"batb":[[0,1.46,41.87]],"ltp":0.0,"tv":0.0,"id":2263624},{"batb":[[0,2.72,11.8]],"ltp":0.0,"tv":0.0,"id":7412809}]}]}
{"op":"mcm","clk":"1009240256","pt":1580642958332,"mc":[{"id":"1.168217557","rc":[{"batb":[[0,1.5,37.45],[1,1.49,38.95],[2,1.48,87.39]],"batl":[[0,1.59,42.01],[1,1.95,409.86]],"ltp":0.0,"tv":0.0,"id":2263624},{"batb":[[1,2.7,24.37],[2,2.62,13.14]],"batl":[[0,3.1,19.32]],"ltp":0.0,"tv":0.0,"id":7412809}]}]}
{"op":"mcm","clk":"1009240416","pt":1580642959156,"mc":[{"id":"1.168217557","rc":[{"batl":[[1,3.9,158.24]],"ltp":0.0,"tv":0.0,"id":7412809}]}]}
{"op":"mcm","clk":"1009242669","pt":1580642973773,"mc":[{"id":"1.168217557","rc":[{"batb":[[0,1.49,38.95],[1,1.48,87.39],[2,1.01,10.51]],"ltp":0.0,"tv":0.0,"id":2263624},{"batb":[[0,2.7,24.37],[1,2.62,13.14],[2,1.01,10.52]],"ltp":0.0,"tv":0.0,"id":7412809}]}]}
{"op":"mcm","clk":"1009242820","pt":1580642974862,"mc":[{"id":"1.168217557","rc":[{"batb":[[1,1.01,10.52],[2,1.01,0]],"batl":[[0,1.95,409.86],[1,1.95,0]],"ltp":0.0,"tv":0.0,"id":2263624},{"batb":[[0,2.62,13.14],[1,1.01,10.52],[2,1.01,0]],"batl":[[0,3.9,158.24],[1,3.9,0]],"ltp":0.0,"tv":0.0,"id":7412809}]}]}
{"op":"mcm","clk":"1009245612","pt":1580642992962,"mc":[{"id":"1.168217557","rc":[{"batb":[[0,1.54,34.23],[1,1.51,36.19],[2,1.01,10.52]],"ltp":0.0,"tv":0.0,"id":2263624},{"batb":[[1,2.5,15.03],[2,1.01,10.52]],"ltp":0.0,"tv":0.0,"id":7412809}]}]}
{"op":"mcm","clk":"1009245836","pt":1580642994508,"mc":[{"id":"1.168217557","rc":[{"batb":[[2,1.5,84.02]],"batl":[[0,1.62,42.01],[1,1.95,409.86]],"ltp":0.0,"tv":0.0,"id":2263624},{"batb":[[1,2.6,26.05],[2,2.5,15.03]],"batl":[[0,3,21],[1,3.65,170.41]],"ltp":0.0,"tv":0.0,"id":7412809}]}]}
{"op":"mcm","clk":"1009248258","pt":1580643009613,"mc":[{"id":"1.168217557","rc":[{"batb":[[0,1.51,36.19],[1,1.5,84.02],[2,1.01,10.52]],"ltp":0.0,"tv":0.0,"id":2263624},{"batb":[[0,2.6,26.05],[1,2.5,15.03],[2,1.01,10.52]],"ltp":0.0,"tv":0.0,"id":7412809}]}]}
{"op":"mcm","clk":"1009248459","pt":1580643010835,"mc":[{"id":"1.168217557","rc":[{"batb":[[1,1.01,10.52],[2,1.01,0]],"batl":[[0,1.95,409.86],[1,1.95,0]],"ltp":0.0,"tv":0.0,"id":2263624},{"batb":[[0,2.5,15.03],[1,1.01,10.52],[2,1.01,0]],"batl":[[0,3.65,170.41],[1,3.65,0]],"ltp":0.0,"tv":0.0,"id":7412809}]}]}
{"op":"mcm","clk":"1009249525","pt":1580643017517,"mc":[{"id":"1.168217557","rc":[{"batb":[[1,1.5,38.08],[2,1.01,10.52]],"ltp":0.0,"tv":0.0,"id":2263624},{"batb":[[0,2.68,12.27],[1,2.58,13.69],[2,1.01,10.52]],"ltp":0.0,"tv":0.0,"id":7412809}]}]}
{"op":"mcm","clk":"1009249556","pt":1580643017733,"mc":[{"id":"1.168217557","rc":[{"batb":[[2,1.49,85.7]],"batl":[[0,1.61,42.01],[1,1.95,409.86]],"ltp":0.0,"tv":0.0,"id":2263624},{"batb":[[1,2.64,25.21],[2,2.58,13.69]],"batl":[[0,3.05,20.16],[1,3.65,170.41]],"ltp":0.0,"tv":0.0,"id":7412809}]}]}
{"op":"mcm","clk":"1009250981","pt":1580643026343,"mc":[{"id":"1.168217557","rc":[{"batb":[[0,1.5,38.08],[1,1.49,85.7],[2,1.01,10.52]],"ltp":0.0,"tv":0.0,"id":2263624},{"batb":[[0,2.64,25.21],[1,2.58,13.69],[2,1.01,10.52]],"ltp":0.0,"tv":0.0,"id":7412809}]}]}
{"op":"mcm","clk":"1009251050","pt":1580643026759,"mc":[{"id":"1.168217557","rc":[{"batb":[[1,1.01,10.52],[2,1.01,0]],"batl":[[0,1.95,409.86],[1,1.95,0]],"ltp":0.0,"tv":0.0,"id":2263624},{"batb":[[0,2.58,13.69],[1,1.01,10.52],[2,1.01,0]],"batl":[[0,3.65,170.41],[1,3.65,0]],"ltp":0.0,"tv":0.0,"id":7412809}]}]}
{"op":"mcm","clk":"1009252602","pt":1580643035970,"mc":[{"id":"1.168217557","rc":[{"batb":[[1,1.47,41],[2,1.46,90.74]],"batl":[[0,1.58,42.01],[1,1.95,409.86]],"ltp":0.0,"tv":0.0,"id":2263624},{"batb":[[0,2.76,11.57],[1,2.72,24.37],[2,2.68,12.35]],"batl":[[0,3.15,19.32],[1,3.65,170.41]],"ltp":0.0,"tv":0.0,"id":7412809}]}]}
{"op":"mcm","clk":"1009255825","pt":1580643055455,"mc":[{"id":"1.168217557","rc":[{"batb":[[0,1.47,41],[1,1.46,90.74],[2,1.01,10.51]],"ltp":0.0,"tv":0.0,"id":2263624},{"batb":[[0,2.72,24.37],[1,2.68,12.35],[2,1.01,10.52]],"ltp":0.0,"tv":0.0,"id":7412809}]}]}
{"op":"mcm","clk":"1009256027","pt":1580643056800,"mc":[{"id":"1.168217557","rc":[{"batb":[[1,1.01,10.51],[2,1.01,0]],"batl":[[0,1.95,409.86],[1,1.95,0]],"ltp":0.0,"tv":0.0,"id":2263624},{"batb":[[0,2.68,12.35],[1,1.01,10.52],[2,1.01,0]],"batl":[[0,3.65,170.41],[1,3.65,0]],"ltp":0.0,"tv":0.0,"id":7412809}]}]}
{"op":"mcm","clk":"1009257220","pt":1580643064208,"mc":[{"id":"1.168217557","rc":[{"batb":[[0,1.52,35.96],[1,1.49,38.95],[2,1.48,87.39]],"batl":[[0,1.59,42.01],[1,1.95,409.86]],"ltp":0.0,"tv":0.0,"id":2263624},{"batb":[[0,2.68,36.72],[1,2.62,13.06],[2,1.01,10.52]],"batl":[[0,3.1,19.32],[1,3.65,170.41]],"ltp":0.0,"tv":0.0,"id":7412809}]}]}
{"op":"mcm","clk":"1009258176","pt":1580643070291,"mc":[{"id":"1.168217557","rc":[{"batb":[[0,1.49,38.95],[1,1.48,87.39],[2,1.01,10.51]],"ltp":0.0,"tv":0.0,"id":2263624},{"batb":[[0,2.68,24.37]],"ltp":0.0,"tv":0.0,"id":7412809}]}]}
{"op":"mcm","clk":"1009258277","pt":1580643070890,"mc":[{"id":"1.168217557","rc":[{"batb":[[1,1.01,10.52],[2,1.01,0]],"batl":[[0,1.95,409.86],[1,1.95,0]],"ltp":0.0,"tv":0.0,"id":2263624},{"batb":[[0,2.62,13.06],[1,1.01,10.52],[2,1.01,0]],"batl":[[0,3.65,170.41],[1,3.65,0]],"ltp":0.0,"tv":0.0,"id":7412809}]}]}
{"op":"mcm","clk":"1009260703","pt":1580643086502,"mc":[{"id":"1.168217557","rc":[{"batb":[[1,1.46,42.34],[2,1.01,10.51]],"ltp":0.0,"tv":0.0,"id":2263624},{"batb":[[0,2.78,11.25],[1,2.7,12.12],[2,2.62,13.06]],"ltp":0.0,"tv":0.0,"id":7412809}]}]}
{"op":"mcm","clk":"1009260741","pt":1580643086723,"mc":[{"id":"1.168217557","rc":[{"batb":[[2,1.01,10.52]],"ltp":0.0,"tv":0.0,"id":7412809}]}]}
{"op":"mcm","clk":"1009260936","pt":1580643087802,"mc":[{"id":"1.168217557","rc":[{"batb":[[1,1.46,133.08]],"batl":[[0,1.57,42.01],[1,1.95,409.86]],"ltp":0.0,"tv":0.0,"id":2263624},{"batb":[[1,2.74,23.53],[2,2.7,12.12]],"batl":[[0,3.2,18.48],[1,3.65,170.41]],"ltp":0.0,"tv":0.0,"id":7412809}]}]}
{"op":"mcm","clk":"1009263870","pt":1580643107328,"mc":[{"id":"1.168217557","rc":[{"batb":[[0,1.46,42.34],[1,1.01,10.51],[2,1.01,0]],"batl":[[0,1.95,409.86],[1,1.95,0]],"ltp":0.0,"tv":0.0,"id":2263624},{"batb":[[0,2.7,12.12],[1,1.01,10.52],[2,2.7,0]],"batl":[[0,3.65,170.41],[1,3.65,0]],"ltp":0.0,"tv":0.0,"id":7412809}]}]}
{"op":"mcm","clk":"1009265358","pt":1580643117429,"mc":[{"id":"1.168217557","rc":[{"batb":[[0,1.01,10.52],[1,1.01,0]],"ltp":0.0,"tv":0.0,"id":2263624}]}]}
{"op":"mcm","clk":"1009265674","pt":1580643119305,"mc":[{"id":"1.168217557","rc":[{"batb":[[0,1.43,46.35],[1,1.01,10.51]],"ltp":0.0,"tv":0.0,"id":2263624},{"batb":[[0,2.8,11.02]],"ltp":0.0,"tv":0.0,"id":7412809}]}]}
{"op":"mcm","clk":"1009265793","pt":1580643120157,"mc":[{"id":"1.168217557","rc":[{"batb":[[0,1.44,94.95],[1,1.43,46.34],[2,1.01,10.51]],"batl":[[0,1.55,42.01],[1,1.95,409.86]],"ltp":0.0,"tv":0.0,"id":2263624},{"batb":[[0,2.82,22.69],[1,2.8,11.02],[2,1.01,10.52]],"batl":[[0,3.25,18.48]],"ltp":0.0,"tv":0.0,"id":7412809}]}]}
{"op":"mcm","clk":"1009265960","pt":1580643121243,"mc":[{"id":"1.168217557","rc":[{"batl":[[1,4.2,148.03]],"ltp":0.0,"tv":0.0,"id":7412809}]}]}
{"op":"mcm","clk":"1009267859","pt":1580643134973,"mc":[{"id":"1.168217557","rc":[{"batb":[[0,1.43,46.35],[1,1.01,10.51],[2,1.01,0]],"batl":[[0,1.95,409.86],[1,1.95,0]],"ltp":0.0,"tv":0.0,"id":2263624},{"batb":[[0,2.8,11.02],[1,1.01,10.52],[2,1.01,0]],"batl":[[0,4.2,148.03],[1,4.2,0]],"ltp":0.0,"tv":0.0,"id":7412809}]}]}
{"op":"mcm","clk":"1009268903","pt":1580643142104,"mc":[{"id":"1.168217557","rc":[{"batb":[[0,1.48,39.74],[1,1.45,136.77],[2,1.01,10.51]],"batl":[[0,1.56,42.01],[1,1.95,409.86]],"ltp":0.0,"tv":0.0,"id":2263624},{"batb":[[1,2.78,23.53],[2,2.72,11.88]],"batl":[[0,3.2,18.48],[1,4.2,148.03]],"ltp":0.0,"tv":0.0,"id":7412809}]}]}
{"op":"mcm","clk":"1009271536","pt":1580643158025,"mc":[{"id":"1.168217557","rc":[{"batb":[[0,1.45,136.78],[1,1.01,10.51],[2,1.01,0]],"ltp":0.0,"tv":0.0,"id":2263624},{"batb":[[0,2.78,23.53],[1,2.72,11.88],[2,1.01,10.52]],"ltp":0.0,"tv":0.0,"id":7412809}]}]}
{"op":"mcm","clk":"1009271667","pt":1580643158832,"mc":[{"id":"1.168217557","rc":[{"batb":[[0,1.45,43.52]],"batl":[[0,1.95,409.86],[1,1.95,0]],"ltp":0.0,"tv":0.0,"id":2263624},{"batb":[[0,2.72,11.88],[1,1.01,10.52],[2,1.01,0]],"batl":[[0,4.2,148.03],[1,4.2,0]],"ltp":0.0,"tv":0.0,"id":7412809}]}]}
{"op":"mcm","clk":"1009273797","pt":1580643171513,"mc":[{"id":"1.168217557","rc":[{"batb":[[1,1.41,48.63],[2,1.01,10.51]],"ltp":0.0,"tv":0.0,"id":2263624},{"batb":[[0,2.92,24.78],[1,2.82,10.78],[2,2.72,11.88]],"ltp":0.0,"tv":0.0,"id":7412809}]}]}
{"op":"mcm","clk":"1009273947","pt":1580643172471,"mc":[{"id":"1.168217557","rc":[{"batb":[[1,1.43,97.46],[2,1.41,48.63]],"batl":[[0,1.54,42.01]],"ltp":0.0,"tv":0.0,"id":2263624},{"batb":[[1,2.84,22.69],[2,2.82,10.78]],"batl":[[0,3.3,17.64],[1,4.2,148.03]],"ltp":0.0,"tv":0.0,"id":7412809}]}]}
{"op":"mcm","clk":"1009274147","pt":1580643173798,"mc":[{"id":"1.168217557","rc":[{"batl":[[1,1.82,469.11]],"ltp":0.0,"tv":0.0,"id":2263624}]}]}
{"op":"mcm","clk":"1009276594","pt":1580643190434,"mc":[{"id":"1.168217557","rc":[{"batb":[[0,1.43,97.47],[1,1.41,48.63],[2,1.01,10.51]],"ltp":0.0,"tv":0.0,"id":2263624},{"batb":[[0,2.84,22.69],[1,2.82,10.78],[2,1.01,10.52]],"ltp":0.0,"tv":0.0,"id":7412809}]}]}
{"op":"mcm","clk":"1009276693","pt":1580643191056,"mc":[{"id":"1.168217557","rc":[{"batb":[[0,1.41,48.64],[1,1.01,10.51],[2,1.01,0]],"batl":[[0,1.82,469.11],[1,1.82,0]],"ltp":0.0,"tv":0.0,"id":2263624},{"batb":[[0,2.82,10.78],[1,1.01,10.52],[2,1.01,0]],"batl":[[0,4.2,148.03],[1,4.2,0]],"ltp":0.0,"tv":0.0,"id":7412809}]}]}
{"op":"mcm","clk":"1009278164","pt":1580643200449,"mc":[{"id":"1.168217557","rc":[{"batb":[[1,1.4,50.91],[2,1.39,107.54]],"batl":[[0,1.49,42.01],[1,1.82,469.11]],"ltp":0.0,"tv":0.0,"id":2263624},{"batb":[[0,3.05,41.64],[1,2.94,24.16],[2,2.82,10.78]],"batl":[[0,3.55,15.96],[1,4.2,148.03]],"ltp":0.0,"tv":0.0,"id":7412809}]}]}
{"op":"mcm","clk":"1009278240","pt":1580643200954,"mc":[{"id":"1.168217557","rc":[{"batb":[[2,1.01,10.52]],"ltp":0.0,"tv":0.0,"id":7412809}]}]}
{"op":"mcm","clk":"1009289605","pt":1580643276044,"mc":[{"id":"1.168217557","rc":[{"batb":[[0,1.4,50.92],[1,1.39,107.54],[2,1.01,10.51]],"ltp":0.0,"tv":0.0,"id":2263624},{"batb":[[0,3.05,20.16]],"ltp":0.0,"tv":0.0,"id":7412809}]}]}
{"op":"mcm","clk":"1009289730","pt":1580643276953,"mc":[{"id":"1.168217557","rc":[{"batb":[[1,1.01,10.51],[2,1.01,0]],"batl":[[0,1.82,469.11],[1,1.82,0]],"ltp":0.0,"tv":0.0,"id":2263624},{"batb":[[0,2.94,24.16],[1,1.01,10.52],[2,1.01,0]],"batl":[[0,4.2,148.03],[1,4.2,0]],"ltp":0.0,"tv":0.0,"id":7412809}]}]}
{"op":"mcm","clk":"1009290382","pt":1580643281937,"mc":[{"id":"1.168217557","rc":[{"batb":[[1,1.39,107.54],[2,1.01,10.51]],"batl":[[0,1.49,42.01],[1,1.82,469.11]],"ltp":0.0,"tv":0.0,"id":2263624},{"batb":[[0,3.05,20.16],[1,2.94,24.16],[2,1.01,10.52]],"batl":[[0,3.6,15.96]],"ltp":0.0,"tv":0.0,"id":7412809}]}]}
{"op":"mcm","clk":"1009290539","pt":1580643283265,"mc":[{"id":"1.168217557","rc":[{"trd":[[1.48,0.01]],"batb":[[0,1.4,50.91],[1,1.38,53.19]],"batl":[[0,1.82,469.11],[1,1.82,0]],"ltp":1.48,"tv":0.01,"id":2263624},{"trd":[[3.1,0]],"batb":[[0,3.15,20.3],[1,3,22.74]],"ltp":3.1,"tv":0.0,"id":7412809}],"tv":0.01}]}
{"op":"mcm","clk":"1009290829","pt":1580643285456,"mc":[{"id":"1.168217557","rc":[{"batl":[[1,4.9,126.27]],"ltp":3.1,"tv":0.0,"id":7412809}]}]}
{"op":"mcm","clk":"1009290927","pt":1580643286150,"mc":[{"id":"1.168217557","rc":[{"batb":[[0,1.38,163.25],[1,1.01,10.51],[2,1.01,0]],"batl":[[0,1.48,42.01],[1,1.82,469.11]],"ltp":1.48,"tv":0.01,"id":2263624},{"batb":[[0,3.1,19.32]],"ltp":3.1,"tv":0.0,"id":7412809}]}]}
{"op":"mcm","clk":"1009291017","pt":1580643286946,"mc":[{"id":"1.168217557","rc":[{"batb":[[0,1.38,53.19]],"batl":[[0,1.82,469.11],[1,1.82,0]],"ltp":1.48,"tv":0.01,"id":2263624},{"batb":[[0,3,22.74],[1,1.01,10.52],[2,1.01,0]],"batl":[[0,4.9,126.27],[1,4.9,0]],"ltp":3.1,"tv":0.0,"id":7412809}]}]}
{"op":"mcm","clk":"1009292113","pt":1580643295441,"mc":[{"id":"1.168217557","rc":[{"batb":[[1,1.37,55.47],[2,1.01,10.51]],"ltp":1.48,"tv":0.01,"id":2263624},{"batb":[[0,3.2,19.12],[1,3.05,21.64],[2,1.01,10.52]],"ltp":3.1,"tv":0.0,"id":7412809}]}]}
{"op":"mcm","clk":"1009292200","pt":1580643296085,"mc":[{"id":"1.168217557","rc":[{"batb":[[1,1.37,168.9]],"batl":[[0,1.47,42.01],[1,1.82,469.11]],"ltp":1.48,"tv":0.01,"id":2263624},{"batb":[[1,3.15,19.32],[2,3.05,21.64]],"batl":[[0,3.7,15.12],[1,4.9,126.27]],"ltp":3.1,"tv":0.0,"id":7412809}]}]}
{"op":"mcm","clk":"1009293353","pt":1580643304006,"mc":[{"id":"1.168217557","rc":[{"batb":[[0,1.37,168.9],[1,1.01,10.51],[2,1.01,0]],"ltp":1.48,"tv":0.01,"id":2263624},{"batb":[[0,3.15,19.32],[1,3.05,21.64],[2,1.01,10.52]],"ltp":3.1,"tv":0.0,"id":7412809}]}]}
{"op":"mcm","clk":"1009293581","pt":1580643305494,"mc":[{"id":"1.168217557","rc":[{"batb":[[0,1.37,55.47]],"batl":[[0,1.82,469.11],[1,1.82,0]],"ltp":1.48,"tv":0.01,"id":2263624},{"batb":[[0,3.05,21.64],[1,1.01,10.52],[2,1.01,0]],"batl":[[0,4.9,126.27],[1,4.9,0]],"ltp":3.1,"tv":0.0,"id":7412809}]}]}
{"op":"mcm","clk":"1009295717","pt":1580643320485,"mc":[{"id":"1.168217557","rc":[{"batb":[[0,1.37,168.9],[1,1.36,57.67],[2,1.01,10.51]],"batl":[[0,1.46,42.01]],"ltp":1.48,"tv":0.01,"id":2263624},{"batb":[[0,3.3,18.1],[1,3.15,39.78],[2,1.01,10.52]],"batl":[[0,3.75,15.12],[1,4.9,126.27]],"ltp":3.1,"tv":0.0,"id":7412809}]}]}
{"op":"mcm","clk":"1009296016","pt":1580643322513,"mc":[{"id":"1.168217557","rc":[{"batl":[[1,1.73,527.57]],"ltp":1.48,"tv":0.01,"id":2263624}]}]}
{"op":"mcm","clk":"1009297458","pt":1580643331802,"mc":[{"id":"1.168217557","rc":[{"batb":[[0,1.37,113.43]],"ltp":1.48,"tv":0.01,"id":2263624},{"batb":[[0,3.15,39.78],[1,1.01,10.52],[2,1.01,0]],"ltp":3.1,"tv":0.0,"id":7412809}]}]}
{"op":"mcm","clk":"1009297607","pt":1580643333029,"mc":[{"id":"1.168217557","rc":[{"batb":[[0,1.36,57.67],[1,1.01,10.51],[2,1.01,0]],"batl":[[0,1.73,527.57],[1,1.73,0]],"ltp":1.48,"tv":0.01,"id":2263624},{"batb":[[0,3.15,20.46]],"batl":[[0,4.9,126.27],[1,4.9,0]],"ltp":3.1,"tv":0.0,"id":7412809}]}]}
{"op":"mcm","clk":"1009298418","pt":1580643338344,"mc":[{"id":"1.168217557","rc":[{"batb":[[1,1.35,119.31],[2,1.33,62.79]],"batl":[[0,1.44,42.01],[1,1.73,527.57]],"ltp":1.48,"tv":0.01,"id":2263624},{"batb":[[0,3.35,17.15],[1,3.3,17.64],[2,3.25,18.41]],"batl":[[0,3.85,14.28],[1,4.9,126.27]],"ltp":3.1,"tv":0.0,"id":7412809}]}]}
{"op":"mcm","clk":"1009302224","pt":1580643362255,"mc":[{"id":"1.168217557","rc":[{"batb":[[0,1.35,119.31],[1,1.33,62.79],[2,1.01,10.51]],"ltp":1.48,"tv":0.01,"id":2263624},{"batb":[[0,3.3,17.64],[1,3.25,18.41],[2,1.01,10.52]],"ltp":3.1,"tv":0.0,"id":7412809}]}]}
{"op":"mcm","clk":"1009302347","pt":1580643363054,"mc":[{"id":"1.168217557","rc":[{"batb":[[0,1.33,62.79],[1,1.01,10.51],[2,1.01,0]],"batl":[[0,1.73,527.57],[1,1.73,0]],"ltp":1.48,"tv":0.01,"id":2263624},{"batb":[[0,3.25,18.41],[1,1.01,10.52],[2,1.01,0]],"batl":[[0,4.9,126.27],[1,4.9,0]],"ltp":3.1,"tv":0.0,"id":7412809}]}]}
{"op":"mcm","clk":"1009303396","pt":1580643369489,"mc":[{"id":"1.168217557","rc":[{"batb":[[0,1.37,54.76],[1,1.35,59.01],[2,1.01,10.51]],"ltp":1.48,"tv":0.01,"id":2263624},{"batb":[[1,3.15,19.91],[2,1.01,10.52]],"ltp":3.1,"tv":0.0,"id":7412809}]}]}
{"op":"mcm","clk":"1009303470","pt":1580643369964,"mc":[{"id":"1.168217557","rc":[{"batb":[[1,1.36,115.95],[2,1.35,59.01]],"batl":[[0,1.45,42.01],[1,1.73,527.57]],"ltp":1.48,"tv":0.01,"id":2263624},{"batb":[[0,3.25,36.9]],"batl":[[0,3.8,14.28],[1,4.9,126.27]],"ltp":3.1,"tv":0.0,"id":7412809}]}]}
{"op":"mcm","clk":"1009304560","pt":1580643377370,"mc":[{"id":"1.168217557","rc":[{"batb":[[0,1.35,59.01],[1,1.01,10.51],[2,1.35,0]],"batl":[[0,1.73,527.57],[1,1.73,0]],"ltp":1.48,"tv":0.01,"id":2263624},{"batb":[[0,3.15,19.91],[1,1.01,10.52],[2,1.01,0]],"batl":[[0,4.9,126.27],[1,4.9,0]],"ltp":3.1,"tv":0.0,"id":7412809}]}]}
{"op":"mcm","clk":"1009305570","pt":1580643384311,"mc":[{"id":"1.168217557","rc":[{"batb":[[0,1.39,51.54],[1,1.37,168.9],[2,1.01,10.51]],"batl":[[0,1.46,42.01],[1,1.73,527.57]],"ltp":1.48,"tv":0.01,"id":2263624},{"batb":[[0,3.15,39.23],[1,3.1,21.17],[2,1.01,10.52]],"batl":[[0,3.75,15.12],[1,4.9,126.27]],"ltp":3.1,"tv":0.0,"id":7412809}]}]}
{"op":"mcm","clk":"1009306583","pt":1580643391070,"mc":[{"id":"1.168217557","rc":[{"batb":[[0,1.37,55.47],[1,1.01,10.51],[2,1.01,0]],"batl":[[0,1.73,527.57],[1,1.73,0]],"ltp":1.48,"tv":0.01,"id":2263624},{"batb":[[0,3.1,21.17],[1,1.01,10.52],[2,1.01,0]],"batl":[[0,4.9,126.27],[1,4.9,0]],"ltp":3.1,"tv":0.0,"id":7412809}]}]}
{"op":"mcm","clk":"1009308945","pt":1580643407336,"mc":[{"id":"1.168217557","rc":[{"batb":[[0,1.41,49.18],[1,1.38,52.95],[2,1.01,10.51]],"ltp":1.48,"tv":0.01,"id":2263624},{"batb":[[1,3,22.9],[2,1.01,10.52]],"ltp":3.1,"tv":0.0,"id":7412809}]}]}
{"op":"mcm","clk":"1009309038","pt":1580643408027,"mc":[{"id":"1.168217557","rc":[{"batb":[[1,1.38,163.02]],"batl":[[0,1.47,42.01],[1,1.73,527.57]],"ltp":1.48,"tv":0.01,"id":2263624},{"batb":[[0,3.1,40.49]],"batl":[[0,3.65,15.12],[1,4.9,126.27]],"ltp":3.1,"tv":0.0,"id":7412809}]}]}
{"op":"mcm","clk":"1009309477","pt":1580643411449,"mc":[{"id":"1.168217557","rc":[{"batb":[[0,1.42,921.94],[1,1.41,49.18],[2,1.38,163.02]],"ltp":1.48,"tv":0.01,"id":2263624}]}]}
{"op":"mcm","clk":"1009311074","pt":1580643422155,"mc":[{"id":"1.168217557","rc":[{"batb":[[0,1.38,163.02],[1,1.01,10.51],[2,1.38,0]],"ltp":1.48,"tv":0.01,"id":2263624},{"batb":[[0,3.1,19.32]],"ltp":3.1,"tv":0.0,"id":7412809}]}]}
{"op":"mcm","clk":"1009311257","pt":1580643423334,"mc":[{"id":"1.168217557","rc":[{"batb":[[0,1.38,52.95]],"batl":[[0,1.73,527.57],[1,1.73,0]],"ltp":1.48,"tv":0.01,"id":2263624},{"batb":[[0,3,22.9],[1,1.01,10.52],[2,1.01,0]],"batl":[[0,4.9,126.27],[1,4.9,0]],"ltp":3.1,"tv":0.0,"id":7412809}]}]}
{"op":"mcm","clk":"1009314140","pt":1580643442083,"mc":[{"id":"1.168217557","rc":[{"batb":[[1,1.36,173.46],[2,1.01,10.51]],"batl":[[0,1.46,42.01],[1,1.73,527.57]],"ltp":1.48,"tv":0.01,"id":2263624},{"batb":[[0,3.2,37.76],[1,3.15,20.46],[2,1.01,10.52]],"batl":[[0,3.75,15.12],[1,4.9,126.27]],"ltp":3.1,"tv":0.0,"id":7412809}]}]}
{"op":"mcm","clk":"1009316652","pt":1580643458413,"mc":[{"id":"1.168217557","rc":[{"batb":[[0,1.36,173.46],[1,1.01,10.51],[2,1.01,0]],"ltp":1.48,"tv":0.01,"id":2263624},{"batb":[[0,3.2,18.48]],"ltp":3.1,"tv":0.0,"id":7412809}]}]}
{"op":"mcm","clk":"1009316744","pt":1580643459098,"mc":[{"id":"1.168217557","rc":[{"batb":[[0,1.36,57.52]],"batl":[[0,1.73,527.57],[1,1.73,0]],"ltp":1.48,"tv":0.01,"id":2263624},{"batb":[[0,3.15,20.46],[1,1.01,10.52],[2,1.01,0]],"batl":[[0,4.9,126.27],[1,4.9,0]],"ltp":3.1,"tv":0.0,"id":7412809}]}]}
{"op":"mcm","clk":"1009317941","pt":1580643467414,"mc":[{"id":"1.168217557","rc":[{"batb":[[0,1.4,50.59],[1,1.38,52.8],[2,1.36,57.52]],"ltp":1.48,"tv":0.01,"id":2263624},{"batb":[[1,2.98,23.6],[2,1.01,10.52]],"ltp":3.1,"tv":0.0,"id":7412809}]}]}
{"op":"mcm","clk":"1009318050","pt":1580643468113,"mc":[{"id":"1.168217557","rc":[{"batb":[[1,1.38,162.86],[2,1.01,10.51]],"batl":[[0,1.48,42.01],[1,1.73,527.57]],"ltp":1.48,"tv":0.01,"id":2263624},{"batb":[[1,3.1,19.32],[2,2.98,23.6]],"batl":[[0,3.65,15.12],[1,4.9,126.27]],"ltp":3.1,"tv":0.0,"id":7412809}]}]}
{"op":"mcm","clk":"1009318516","pt":1580643471105,"mc":[{"id":"1.168217557","rc":[{"batb":[[0,1.41,183.28],[1,1.4,50.59],[2,1.38,162.86]],"ltp":1.48,"tv":0.01,"id":2263624}]}]}
{"op":"mcm","clk":"1009329271","pt":1580643543612,"mc":[{"id":"1.168217557","rc":[{"batb":[[0,1.38,162.86],[1,1.01,10.51],[2,1.38,0]],"ltp":1.48,"tv":0.01,"id":2263624},{"batb":[[0,3.1,19.32],[1,2.98,23.6],[2,1.01,10.52]],"ltp":3.1,"tv":0.0,"id":7412809}]}]}
{"op":"mcm","clk":"1009329506","pt":1580643545114,"mc":[{"id":"1.168217557","rc":[{"batb":[[0,1.38,52.8]],"batl":[[0,1.73,527.57],[1,1.73,0]],"ltp":1.48,"tv":0.01,"id":2263624},{"batb":[[0,2.98,23.6],[1,1.01,10.52],[2,1.01,0]],"batl":[[0,4.9,126.27],[1,4.9,0]],"ltp":3.1,"tv":0.0,"id":7412809}]}]}
{"op":"mcm","clk":"1009331529","pt":1580643560132,"mc":[{"id":"1.168217557","rc":[{"batb":[[1,1.37,113.43],[2,1.01,10.51]],"batl":[[0,1.47,42.01],[1,1.73,527.57]],"ltp":1.48,"tv":0.01,"id":2263624},{"batb":[[0,3.15,19.32],[1,2.98,23.6],[2,1.01,10.52]],"batl":[[0,3.7,15.12],[1,4.9,126.27]],"ltp":3.1,"tv":0.0,"id":7412809}]}]}
{"op":"mcm","clk":"1009331660","pt":1580643561137,"mc":[{"id":"1.168217557","rc":[{"batb":[[1,1.37,168.5]],"ltp":1.48,"tv":0.01,"id":2263624},{"batb":[[0,3.2,19.36],[1,3.15,19.32],[2,3.05,22.11]],"ltp":3.1,"tv":0.0,"id":7412809}]}]}
{"op":"mcm","clk":"1009332529","pt":1580643568130,"mc":[{"id":"1.168217557","rc":[{"batb":[[0,1.37,168.5],[1,1.01,10.51],[2,1.01,0]],"ltp":1.48,"tv":0.01,"id":2263624},{"batb":[[0,3.15,19.32],[1,3.05,22.11],[2,1.01,10.52]],"ltp":3.1,"tv":0.0,"id":7412809}]}]}
{"op":"mcm","clk":"1009332678","pt":1580643569246,"mc":[{"id":"1.168217557","rc":[{"batb":[[0,1.37,55.08]],"batl":[[0,1.73,527.57],[1,1.73,0]],"ltp":1.48,"tv":0.01,"id":2263624},{"batb":[[0,3.05,22.11],[1,1.01,10.52],[2,1.01,0]],"batl":[[0,4.9,126.27],[1,4.9,0]],"ltp":3.1,"tv":0.0,"id":7412809}]}]}
{"op":"mcm","clk":"1009333361","pt":1580643574358,"mc":[{"id":"1.168217557","rc":[{"batb":[[0,1.39,107.54],[1,1.37,55.08],[2,1.01,10.51]],"batl":[[0,1.49,42.01],[1,1.73,527.57]],"ltp":1.48,"tv":0.01,"id":2263624},{"batb":[[0,3.05,42.27]],"batl":[[0,3.6,15.96],[1,4.9,126.27]],"ltp":3.1,"tv":0.0,"id":7412809}]}]}
{"op":"mcm","clk":"1009333498","pt":1580643575361,"mc":[{"id":"1.168217557","rc":[{"batb":[[0,1.42,47.68],[1,1.4,49.96],[2,1.39,107.54]],"ltp":1.48,"tv":0.01,"id":2263624},{"batb":[[1,2.9,25.1],[2,1.01,10.52]],"ltp":3.1,"tv":0.0,"id":7412809}]}]}
{"op":"mcm","clk":"1009334864","pt":1580643585247,"mc":[{"id":"1.168217557","rc":[{"batb":[[0,1.4,49.96],[1,1.01,10.51],[2,1.39,0]],"batl":[[0,1.73,527.57],[1,1.73,0]],"ltp":1.48,"tv":0.01,"id":2263624},{"batb":[[0,2.9,25.1],[1,1.01,10.52],[2,1.01,0]],"batl":[[0,4.9,126.27],[1,4.9,0]],"ltp":3.1,"tv":0.0,"id":7412809}]}]}
{"op":"mcm","clk":"1009337974","pt":1580643606481,"mc":[{"id":"1.168217557","rc":[{"batb":[[1,1.39,52.56],[2,1.38,110.07]],"batl":[[0,1.48,42.01],[1,1.73,527.57]],"ltp":1.48,"tv":0.01,"id":2263624},{"batb":[[0,3.1,40.1],[1,2.96,23.76],[2,1.01,10.52]],"batl":[[0,3.65,15.12],[1,4.9,126.27]],"ltp":3.1,"tv":0.0,"id":7412809}]}]}
{"op":"mcm","clk":"1009338255","pt":1580643608393,"mc":[{"id":"1.168217557","rc":[{"batb":[[2,2.92,287.94]],"ltp":3.1,"tv":0.0,"id":7412809}]}]}
{"op":"mcm","clk":"1009338293","pt":1580643608611,"mc":[{"id":"1.168217557","rc":[{"batb":[[2,1.01,10.52]],"ltp":3.1,"tv":0.0,"id":7412809}]}]}
{"op":"mcm","clk":"1009341649","pt":1580643632424,"mc":[{"id":"1.168217557","rc":[{"batb":[[0,1.39,52.56],[1,1.38,110.07],[2,1.01,10.51]],"ltp":1.48,"tv":0.01,"id":2263624},{"batb":[[0,3.1,19.32]],"ltp":3.1,"tv":0.0,"id":7412809}]}]}
{"op":"mcm","clk":"1009341794","pt":1580643633398,"mc":[{"id":"1.168217557","rc":[{"batb":[[1,1.01,10.51],[2,1.01,0]],"batl":[[0,1.73,527.57],[1,1.73,0]],"ltp":1.48,"tv":0.01,"id":2263624},{"batb":[[0,2.96,23.76],[1,1.01,10.52],[2,1.01,0]],"batl":[[0,4.9,126.27],[1,4.9,0]],"ltp":3.1,"tv":0.0,"id":7412809}]}]}
{"op":"mcm","clk":"1009348552","pt":1580643678414,"mc":[{"id":"1.168217557","rc":[{"batb":[[0,1.4,105.02],[1,1.39,52.56],[2,1.01,10.51]],"batl":[[0,1.5,42.01],[1,1.73,527.57]],"ltp":1.48,"tv":0.01,"id":2263624},{"batb":[[0,3,21],[1,2.96,23.76],[2,1.01,10.52]],"batl":[[0,3.55,15.96]],"ltp":3.1,"tv":0.0,"id":7412809}]}]}
{"op":"mcm","clk":"1009348681","pt":1580643679325,"mc":[{"id":"1.168217557","rc":[{"batb":[[0,1.43,45.08],[1,1.42,47.52],[2,1.41,183.28]],"ltp":1.48,"tv":0.01,"id":2263624},{"batb":[[2,2.82,10.78]],"ltp":3.1,"tv":0.0,"id":7412809}]}]}
{"op":"mcm","clk":"1009348757","pt":1580643679820,"mc":[{"id":"1.168217557","rc":[{"batb":[[2,1.4,105.02]],"ltp":1.48,"tv":0.01,"id":2263624}]}]}
{"op":"mcm","clk":"1009349002","pt":1580643681408,"mc":[{"id":"1.168217557","rc":[{"batl":[[1,4.6,136.05]],"ltp":3.1,"tv":0.0,"id":7412809}]}]}
{"op":"mcm","clk":"1009349238","pt":1580643682712,"mc":[{"id":"1.168217557","rc":[{"batb":[[0,1.44,179.42],[1,1.43,45.08],[2,1.42,47.52]],"ltp":1.48,"tv":0.01,"id":2263624}]}]}
{"op":"mcm","clk":"1009350211","pt":1580643688490,"mc":[{"id":"1.168217557","rc":[{"batb":[[0,1.43,45.08],[1,1.42,47.52],[2,1.4,105.02]],"ltp":1.48,"tv":0.01,"id":2263624}]}]}
{"op":"mcm","clk":"1009350326","pt":1580643689330,"mc":[{"id":"1.168217557","rc":[{"batb":[[0,1.42,47.52],[1,1.01,10.51],[2,1.4,0]],"batl":[[0,1.73,527.57],[1,1.73,0]],"ltp":1.48,"tv":0.01,"id":2263624},{"batb":[[0,2.82,10.78],[1,1.01,10.52],[2,2.82,0]],"batl":[[0,4.6,136.05],[1,4.6,0]],"ltp":3.1,"tv":0.0,"id":7412809}]}]}
{"op":"mcm","clk":"1009351579","pt":1580643698321,"mc":[{"id":"1.168217557","rc":[{"batb":[[1,1.4,50.12],[2,1.39,107.54]],"batl":[[0,1.49,42.01],[1,1.73,527.57]],"ltp":1.48,"tv":0.01,"id":2263624},{"batb":[[0,3.05,42.27],[1,2.9,25.41],[2,1.01,10.52]],"batl":[[0,3.6,15.96],[1,4.6,136.05]],"ltp":3.1,"tv":0.0,"id":7412809}]}]}
{"op":"mcm","clk":"1009351681","pt":1580643699225,"mc":[{"id":"1.168217557","rc":[{"batl":[[0,4.6,136.05],[1,4.6,0]],"ltp":3.1,"tv":0.0,"id":7412809}]}]}
{"op":"mcm","clk":"1009352210","pt":1580643702231,"mc":[{"id":"1.168217557","rc":[{"batl":[[0,3.55,15.96],[1,4.6,136.05]],"ltp":3.1,"tv":0.0,"id":7412809}]}]}
{"op":"mcm","clk":"1009353310","pt":1580643709293,"mc":[{"id":"1.168217557","rc":[{"batb":[[0,1.4,50.12],[1,1.01,10.51],[2,1.39,0]],"batl":[[0,1.73,527.57],[1,1.73,0]],"ltp":1.48,"tv":0.01,"id":2263624},{"batb":[[0,2.9,25.41],[1,1.01,10.52],[2,1.01,0]],"batl":[[0,4.6,136.05],[1,4.6,0]],"ltp":3.1,"tv":0.0,"id":7412809}]}]}
{"op":"mcm","clk":"1009354453","pt":1580643716469,"mc":[{"id":"1.168217557","rc":[{"batb":[[0,1.43,261.82],[1,1.42,219.45],[2,1.4,50.12]],"batl":[[0,1.48,273.65],[1,1.49,174.47],[2,1.73,527.57]],"ltp":1.48,"tv":0.01,"id":2263624}]}]}
{"op":"mcm","clk":"1009354569","pt":1580643717180,"mc":[{"id":"1.168217557","rc":[{"batb":[[0,3.1,20.69],[1,2.86,10.46],[2,1.01,10.52]],"ltp":3.1,"tv":0.0,"id":7412809}]}]}
{"op":"mcm","clk":"1009355004","pt":1580643719469,"mc":[{"id":"1.168217557","rc":[{"batl":[[0,1.48,315.66]],"ltp":1.48,"tv":0.01,"id":2263624},{"batb":[[0,3.1,40.02]],"batl":[[0,3.6,15.96],[1,4.6,136.05]],"ltp":3.1,"tv":0.0,"id":7412809}]}]}
{"op":"mcm","clk":"1009360210","pt":1580643753896,"mc":[{"id":"1.168217557","rc":[{"batl":[[0,1.48,285.84]],"ltp":1.48,"tv":0.01,"id":2263624}]}]}
{"op":"mcm","clk":"1009360679","pt":1580643756793,"mc":[{"id":"1.168217557","rc":[{"batb":[[0,1.43,292.82]],"ltp":1.48,"tv":0.01,"id":2263624}]}]}
{"op":"mcm","clk":"1009367261","pt":1580643802249,"mc":[{"id":"1.168217557","rc":[{"batb":[[0,1.38,110.07],[1,1.32,66.96],[2,1.01,10.51]],"batl":[[0,1.48,42.01],[1,1.73,527.57],[2,1.73,0]],"ltp":1.48,"tv":0.01,"id":2263624},{"batb":[[0,3.1,19.32]],"ltp":3.1,"tv":0.0,"id":7412809}]}]}
{"op":"mcm","clk":"1009367432","pt":1580643803450,"mc":[{"id":"1.168217557","rc":[{"batb":[[0,1.32,66.96],[1,1.01,10.51],[2,1.01,0]],"batl":[[0,1.73,527.57],[1,1.73,0]],"ltp":1.48,"tv":0.01,"id":2263624},{"batb":[[0,2.86,10.46],[1,1.01,10.52],[2,1.01,0]],"batl":[[0,4.6,136.05],[1,4.6,0]],"ltp":3.1,"tv":0.0,"id":7412809}]}]}
{"op":"mcm","clk":"1009367616","pt":1580643804745,"mc":[{"id":"1.168217557","rc":[{"batb":[[0,1.35,160.01],[1,1.34,286.83],[2,1.32,66.96]],"batl":[[0,1.55,216.14],[1,1.56,146.23],[2,1.73,527.57]],"ltp":1.48,"tv":0.01,"id":2263624}]}]}
{"op":"mcm","clk":"1009368539","pt":1580643811316,"mc":[{"id":"1.168217557","rc":[{"batb":[[0,1.32,66.96],[1,1.01,10.51],[2,1.32,0]],"ltp":1.48,"tv":0.01,"id":2263624}]}]}
{"op":"mcm","clk":"1009368926","pt":1580643814322,"mc":[{"id":"1.168217557","rc":[{"batb":[[0,1.5,167.8],[1,1.49,177.85],[2,1.32,66.96]],"ltp":1.48,"tv":0.01,"id":2263624}]}]}
{"op":"mcm","clk":"1009369071","pt":1580643815339,"mc":[{"id":"1.168217557","rc":[{"batb":[[2,1.46,41.7]],"ltp":1.48,"tv":0.01,"id":2263624},{"batb":[[1,2.66,12.51],[2,1.01,10.52]],"ltp":3.1,"tv":0.0,"id":7412809}]}]}
{"op":"mcm","clk":"1009369224","pt":1580643816355,"mc":[{"id":"1.168217557","rc":[{"batl":[[0,1.54,42.01],[1,1.55,216.14],[2,1.56,146.23]],"ltp":1.48,"tv":0.01,"id":2263624},{"batb":[[0,2.86,32.31]],"batl":[[0,3.3,17.64]],"ltp":3.1,"tv":0.0,"id":7412809}]}]}
{"op":"mcm","clk":"1009369448","pt":1580643817805,"mc":[{"id":"1.168217557","rc":[{"batl":[[1,4.2,148.03]],"ltp":3.1,"tv":0.0,"id":7412809}]}]}
{"op":"mcm","clk":"1009371791","pt":1580643834436,"mc":[{"id":"1.168217557","rc":[{"batb":[[0,1.43,97.46],[1,1.38,53.35],[2,1.01,10.51]],"batl":[[1,1.73,527.57],[2,1.56,0]],"ltp":1.48,"tv":0.01,"id":2263624},{"batb":[[0,2.86,21.85]],"ltp":3.1,"tv":0.0,"id":7412809}]}]}
{"op":"mcm","clk":"1009371943","pt":1580643835457,"mc":[{"id":"1.168217557","rc":[{"batb":[[0,1.38,53.35],[1,1.01,10.51],[2,1.01,0]],"batl":[[0,1.73,527.57],[1,1.73,0]],"ltp":1.48,"tv":0.01,"id":2263624},{"batb":[[0,2.66,12.51],[1,1.01,10.52],[2,1.01,0]],"batl":[[0,4.2,148.03],[1,4.2,0]],"ltp":3.1,"tv":0.0,"id":7412809}]}]}
{"op":"mcm","clk":"1009372267","pt":1580643837515,"mc":[{"id":"1.168217557","rc":[{"batb":[[0,2.68,12.35],[1,2.66,12.51],[2,1.01,10.52]],"ltp":3.1,"tv":0.0,"id":7412809}]}]}
{"op":"mcm","clk":"1009372366","pt":1580643838126,"mc":[{"id":"1.168217557","rc":[{"batb":[[1,1.01,10.52],[2,1.01,0]],"ltp":3.1,"tv":0.0,"id":7412809}]}]}
{"op":"mcm","clk":"1009372590","pt":1580643839403,"mc":[{"id":"1.168217557","rc":[{"batb":[[0,1.48,217.26],[1,1.47,188.51],[2,1.38,53.35]],"batl":[[0,1.53,206.52],[1,1.54,153.66],[2,1.73,527.57]],"ltp":1.48,"tv":0.01,"id":2263624}]}]}
{"op":"mcm","clk":"1009373614","pt":1580643845510,"mc":[{"id":"1.168217557","rc":[{"batb":[[0,1.38,53.35],[1,1.01,10.51],[2,1.38,0]],"batl":[[0,1.73,527.57],[1,1.54,0],[2,1.73,0]],"ltp":1.48,"tv":0.01,"id":2263624}]}]}
{"op":"mcm","clk":"1009374048","pt":1580643848515,"mc":[{"id":"1.168217557","rc":[{"batb":[[0,1.42,154.67],[1,1.41,225.35],[2,1.38,53.35]],"batl":[[0,1.61,167.5],[1,1.62,127.6],[2,1.73,527.57]],"ltp":1.48,"tv":0.01,"id":2263624}]}]}
{"op":"mcm","clk":"1009374409","pt":1580643850825,"mc":[{"id":"1.168217557","rc":[{"batb":[[0,1.38,53.35],[1,1.01,10.51],[2,1.38,0]],"ltp":1.48,"tv":0.01,"id":2263624}]}]}
{"op":"mcm","clk":"1009374769","pt":1580643853221,"mc":[{"id":"1.168217557","rc":[{"batl":[[2,1.73,0]],"ltp":1.48,"tv":0.01,"id":2263624}]}]}
{"op":"mcm","clk":"1009374943","pt":1580643854334,"mc":[{"id":"1.168217557","rc":[{"batb":[[0,1.55,151.79],[1,1.52,36.04],[2,1.48,87.38]],"batl":[[0,1.6,42.01],[1,1.61,167.5],[2,1.62,127.6]],"ltp":1.48,"tv":0.01,"id":2263624},{"batb":[[0,2.68,36.72],[1,2.54,14.24],[2,1.01,10.52]],"batl":[[0,3.1,19.32]],"ltp":3.1,"tv":0.0,"id":7412809}]}]}
{"op":"mcm","clk":"1009375434","pt":1580643857327,"mc":[{"id":"1.168217557","rc":[{"batb":[[0,1.56,134.12],[1,1.55,151.79],[2,1.52,36.04]],"ltp":1.48,"tv":0.01,"id":2263624},{"batl":[[1,3.9,158.24]],"ltp":3.1,"tv":0.0,"id":7412809}]}]}
{"op":"mcm","clk":"1009376196","pt":1580643862322,"mc":[{"id":"1.168217557","rc":[{"batl":[[1,1.61,144.82]],"ltp":1.48,"tv":0.01,"id":2263624}]}]}
{"op":"mcm","clk":"1009376614","pt":1580643865428,"mc":[{"id":"1.168217557","rc":[{"batb":[[0,1.45,43.28],[1,1.01,10.51],[2,1.52,0]],"batl":[[0,1.95,409.86],[1,1.61,0],[2,1.62,0]],"ltp":1.48,"tv":0.01,"id":2263624},{"batb":[[0,2.54,14.24],[1,1.01,10.52],[2,1.01,0]],"batl":[[0,3.9,158.24],[1,3.9,0]],"ltp":3.1,"tv":0.0,"id":7412809}]}]}
{"op":"mcm","clk":"1009376927","pt":1580643867943,"mc":[{"id":"1.168217557","rc":[{"batb":[[0,1.49,280.24],[1,1.48,183.52],[2,1.45,43.28]],"batl":[[0,1.66,170.96],[1,1.68,225.8],[2,1.95,409.86]],"ltp":1.48,"tv":0.01,"id":2263624}]}]}
{"op":"mcm","clk":"1009377125","pt":1580643869348,"mc":[{"id":"1.168217557","rc":[{"batb":[[0,1.45,43.28],[1,1.01,10.51],[2,1.45,0]],"ltp":1.48,"tv":0.01,"id":2263624}]}]}
{"op":"mcm","clk":"1009377427","pt":1580643871432,"mc":[{"id":"1.168217557","rc":[{"batb":[[0,1.6,189.28],[1,1.59,137.91],[2,1.45,43.28]],"ltp":1.48,"tv":0.01,"id":2263624}]}]}
{"op":"mcm","clk":"1009377551","pt":1580643872329,"mc":[{"id":"1.168217557","rc":[{"batb":[[2,1.56,32.02]],"batl":[[0,1.64,42.01],[1,1.66,170.96],[2,1.68,225.8]],"ltp":1.48,"tv":0.01,"id":2263624},{"batb":[[0,2.56,26.89],[1,2.54,14.24],[2,2.46,15.5]],"batl":[[0,2.96,21]],"ltp":3.1,"tv":0.0,"id":7412809}]}]}
{"op":"mcm","clk":"1009377952","pt":1580643875147,"mc":[{"id":"1.168217557","rc":[{"batl":[[1,3.65,170.41]],"ltp":3.1,"tv":0.0,"id":7412809}]}]}
{"op":"mcm","clk":"1009378736","pt":1580643880335,"mc":[{"id":"1.168217557","rc":[{"batb":[[0,1.52,80.66],[1,1.51,36.35],[2,1.01,10.51]],"batl":[[1,1.95,409.86],[2,1.68,0]],"ltp":1.48,"tv":0.01,"id":2263624},{"batb":[[1,2.46,15.5],[2,1.01,10.52]],"ltp":3.1,"tv":0.0,"id":7412809}]}]}
{"op":"mcm","clk":"1009378885","pt":1580643881349,"mc":[{"id":"1.168217557","rc":[{"batb":[[0,1.51,36.35],[1,1.01,10.51],[2,1.01,0]],"batl":[[0,1.95,409.86],[1,1.95,0]],"ltp":1.48,"tv":0.01,"id":2263624},{"batb":[[0,2.46,15.5],[1,1.01,10.52],[2,1.01,0]],"batl":[[0,3.65,170.41],[1,3.65,0]],"ltp":3.1,"tv":0.0,"id":7412809}]}]}
{"op":"mcm","clk":"1009379207","pt":1580643883436,"mc":[{"id":"1.168217557","rc":[{"batb":[[0,1.56,219.19],[1,1.55,152.12],[2,1.51,36.35]],"batl":[[0,1.69,191.63],[1,1.71,212.47],[2,1.95,409.86]],"ltp":1.48,"tv":0.01,"id":2263624}]}]}
{"op":"mcm","clk":"1009379770","pt":1580643887152,"mc":[{"id":"1.168217557","rc":[{"batb":[[0,1.51,36.35],[1,1.01,10.51],[2,1.51,0]],"ltp":1.48,"tv":0.01,"id":2263624}]}]}
{"op":"mcm","clk":"1009380247","pt":1580643890352,"mc":[{"id":"1.168217557","rc":[{"batb":[[0,1.63,137.48],[1,1.62,128.46],[2,1.55,75.62]],"batl":[[0,1.68,42.01],[1,1.69,191.63],[2,1.71,212.47]],"ltp":1.48,"tv":0.01,"id":2263624},{"batb":[[0,2.46,44.07]],"batl":[[0,2.84,22.69],[1,3.65,170.41]],"ltp":3.1,"tv":0.0,"id":7412809}]}]}
{"op":"mcm","clk":"1009380371","pt":1580643891261,"mc":[{"id":"1.168217557","rc":[{"batb":[[2,1.6,29.74]],"ltp":1.48,"tv":0.01,"id":2263624},{"batb":[[1,2.16,22.35],[2,1.01,10.52]],"ltp":3.1,"tv":0.0,"id":7412809}]}]}
{"op":"mcm","clk":"1009386164","pt":1580643926998,"mc":[{"id":"1.168217557","rc":[{"batb":[[0,1.6,29.74],[1,1.55,75.62],[2,1.53,34.38]],"batl":[[1,1.95,409.86],[2,1.71,0]],"ltp":1.48,"tv":0.01,"id":2263624}]}]}
{"op":"mcm","clk":"1009386726","pt":1580643930511,"mc":[{"id":"1.168217557","rc":[{"batb":[[0,1.56,192.15],[1,1.55,227.59]],"batl":[[1,1.86,156.87],[2,1.88,156.4]],"ltp":1.48,"tv":0.01,"id":2263624},{"batb":[[0,2.46,28.57]],"ltp":3.1,"tv":0.0,"id":7412809}]}]}
{"op":"mcm","clk":"1009386853","pt":1580643931418,"mc":[{"id":"1.168217557","rc":[{"batb":[[1,1.55,151.97]],"batl":[[0,1.86,156.87],[1,1.88,156.4],[2,1.95,409.86]],"ltp":1.48,"tv":0.01,"id":2263624},{"batb":[[0,2.16,22.35],[1,1.01,10.52],[2,1.01,0]],"batl":[[0,3.65,170.41],[1,3.65,0]],"ltp":3.1,"tv":0.0,"id":7412809}]}]}
{"op":"mcm","clk":"1009387909","pt":1580643938122,"mc":[{"id":"1.168217557","rc":[{"batl":[[0,1.95,409.86],[1,1.88,0],[2,1.95,0]],"ltp":1.48,"tv":0.01,"id":2263624}]}]}
{"op":"mcm","clk":"1009388423","pt":1580643941289,"mc":[{"id":"1.168217557","rc":[{"batl":[[0,1.62,227.93],[1,1.63,124.48],[2,1.95,409.86]],"ltp":1.48,"tv":0.01,"id":2263624}]}]}
{"op":"mcm","clk":"1009388595","pt":1580643942422,"mc":[{"id":"1.168217557","rc":[{"batl":[[0,1.61,42.01],[1,1.62,227.93],[2,1.63,124.48]],"ltp":1.48,"tv":0.01,"id":2263624},{"batb":[[0,2.62,38.27],[1,2.36,17.55],[2,1.01,10.52]],"batl":[[0,3.05,20.16],[1,3.65,170.41]],"ltp":3.1,"tv":0.0,"id":7412809}]}]}
{"op":"mcm","clk":"1009390151","pt":1580643952346,"mc":[{"id":"1.168217557","rc":[{"batb":[[0,1.53,34.38],[1,1.49,124.25],[2,1.01,10.51]],"batl":[[1,1.95,409.86],[2,1.63,0]],"ltp":1.48,"tv":0.01,"id":2263624}]}]}
{"op":"mcm","clk":"1009390324","pt":1580643953446,"mc":[{"id":"1.168217557","rc":[{"batb":[[0,1.49,38.55],[1,1.01,10.51],[2,1.01,0]],"batl":[[0,1.95,409.86],[1,1.95,0]],"ltp":1.48,"tv":0.01,"id":2263624},{"batb":[[0,2.36,17.55],[1,1.01,10.52],[2,1.01,0]],"batl":[[0,3.65,170.41],[1,3.65,0]],"ltp":3.1,"tv":0.0,"id":7412809}]}]}
{"op":"mcm","clk":"1009390654","pt":1580643955347,"mc":[{"id":"1.168217557","rc":[{"batb":[[0,1.51,269.3],[1,1.5,173.55],[2,1.49,38.55]],"batl":[[0,1.73,153.46],[1,1.75,196.79],[2,1.95,409.86]],"ltp":1.48,"tv":0.01,"id":2263624}]}]}
{"op":"mcm","clk":"1009391088","pt":1580643958129,"mc":[{"id":"1.168217557","rc":[{"batb":[[0,1.49,38.55],[1,1.01,10.51],[2,1.49,0]],"ltp":1.48,"tv":0.01,"id":2263624}]}]}
{"op":"mcm","clk":"1009391404","pt":1580643960248,"mc":[{"id":"1.168217557","rc":[{"batl":[[2,1.95,0]],"ltp":1.48,"tv":0.01,"id":2263624}]}]}
{"op":"mcm","clk":"1009391592","pt":1580643961350,"mc":[{"id":"1.168217557","rc":[{"batb":[[0,1.67,117.81],[1,1.66,117.56],[2,1.49,38.55]],"ltp":1.48,"tv":0.01,"id":2263624}]}]}
{"op":"mcm","clk":"1009391753","pt":1580643962351,"mc":[{"id":"1.168217557","rc":[{"batb":[[2,1.64,26.67]],"batl":[[0,1.72,42.01],[1,1.73,153.46],[2,1.75,196.79]],"ltp":1.48,"tv":0.01,"id":2263624},{"batb":[[0,2.4,29.41],[1,2.36,17.55],[2,2.02,27.46]],"batl":[[0,2.76,23.53]],"ltp":3.1,"tv":0.0,"id":7412809}]}]}
{"op":"mcm","clk":"1009392064","pt":1580643963943,"mc":[{"id":"1.168217557","rc":[{"batl":[[1,3.3,191.92]],"ltp":3.1,"tv":0.0,"id":7412809}]}]}
{"op":"mcm","clk":"1009393397","pt":1580643972454,"mc":[{"id":"1.168217557","rc":[{"batb":[[0,1.57,73.1],[1,1.56,32.18],[2,1.01,10.51]],"batl":[[1,2.16,342.82],[2,1.75,0]],"ltp":1.48,"tv":0.01,"id":2263624},{"batb":[[1,2.02,27.46],[2,1.01,10.52]],"ltp":3.1,"tv":0.0,"id":7412809}]}]}
{"op":"mcm","clk":"1009393541","pt":1580643973463,"mc":[{"id":"1.168217557","rc":[{"batb":[[0,1.56,32.18],[1,1.01,10.51],[2,1.01,0]],"batl":[[0,2.16,342.82],[1,2.16,0]],"ltp":1.48,"tv":0.01,"id":2263624},{"batb":[[0,2.02,27.46],[1,1.01,10.52],[2,1.01,0]],"batl":[[0,3.3,191.92],[1,3.3,0]],"ltp":3.1,"tv":0.0,"id":7412809}]}]}
{"op":"mcm","clk":"1009393818","pt":1580643975436,"mc":[{"id":"1.168217557","rc":[{"batb":[[0,1.58,124.11],[1,1.57,144.38],[2,1.56,32.18]],"ltp":1.48,"tv":0.01,"id":2263624}]}]}
{"op":"mcm","clk":"1009394220","pt":1580643978443,"mc":[{"id":"1.168217557","rc":[{"batl":[[0,1.63,181.61],[1,1.64,122.15]],"ltp":1.48,"tv":0.01,"id":2263624},{"batb":[[0,2.6,26.05],[1,2.54,14.16],[2,2.24,19.91]],"batl":[[0,3,21]],"ltp":3.1,"tv":0.0,"id":7412809}]}]}
{"op":"mcm","clk":"1009394579","pt":1580643981163,"mc":[{"id":"1.168217557","rc":[{"batl":[[2,2.04,383.01]],"ltp":1.48,"tv":0.01,"id":2263624},{"batl":[[1,3.65,170.41]],"ltp":3.1,"tv":0.0,"id":7412809}]}]}
{"op":"mcm","clk":"1009395310","pt":1580643986461,"mc":[{"id":"1.168217557","rc":[{"batb":[[0,1.56,32.18],[1,1.5,121.24],[2,1.01,10.51]],"batl":[[0,1.63,42.01],[1,2.04,383.01],[2,2.04,0]],"ltp":1.48,"tv":0.01,"id":2263624}]}]}
{"op":"mcm","clk":"1009395429","pt":1580643987369,"mc":[{"id":"1.168217557","rc":[{"batb":[[0,1.5,37.22],[1,1.01,10.51],[2,1.01,0]],"batl":[[0,2.04,383.01],[1,2.04,0]],"ltp":1.48,"tv":0.01,"id":2263624},{"batb":[[0,2.24,19.91],[1,1.01,10.52],[2,2.24,0]],"batl":[[0,3.65,170.41],[1,3.65,0]],"ltp":3.1,"tv":0.0,"id":7412809}]}]}
{"op":"mcm","clk":"1009395530","pt":1580643988058,"mc":[{"id":"1.168217557","rc":[{"batl":[[0,1.58,8.84],[1,2.04,383.01]],"ltp":1.48,"tv":0.01,"id":2263624}]}]}
{"op":"mcm","clk":"1009395705","pt":1580643989387,"mc":[{"id":"1.168217557","rc":[{"batb":[[0,1.52,161.6],[1,1.51,168.35],[2,1.5,37.22]],"batl":[[1,1.78,176.17],[2,1.8,179.43]],"ltp":1.48,"tv":0.01,"id":2263624}]}]}
{"op":"mcm","clk":"1009395847","pt":1580643990490,"mc":[{"id":"1.168217557","rc":[{"batb":[[0,2.26,19.83]],"ltp":3.1,"tv":0.0,"id":7412809}]}]}
{"op":"mcm","clk":"1009397143","pt":1580643998613,"mc":[{"id":"1.168217557","rc":[{"batl":[[0,1.78,176.17],[1,1.8,179.43],[2,2.04,383.01]],"ltp":1.48,"tv":0.01,"id":2263624}]}]}
{"op":"mcm","clk":"1009398582","pt":1580644008098,"mc":[{"id":"1.168217557","rc":[{"trd":[[1.52,17.69]],"batb":[[0,1.52,152.75]],"ltp":1.52,"tv":17.7,"id":2263624}],"tv":17.7}]}
{"op":"mcm","clk":"1009401392","pt":1580644028826,"mc":[{"id":"1.168217557","rc":[{"batb":[[0,1.5,37.22],[1,1.01,10.51],[2,1.5,0]],"ltp":1.52,"tv":17.7,"id":2263624}]}]}
{"op":"mcm","clk":"1009402026","pt":1580644032420,"mc":[{"id":"1.168217557","rc":[{"batb":[[0,1.71,146.11],[1,1.7,23.92],[2,1.69,219.51]],"batl":[[0,1.75,42.01],[1,1.78,176.17],[2,1.8,179.43]],"ltp":1.52,"tv":17.7,"id":2263624},{"batb":[[0,2.32,31.09],[1,2.26,19.83],[2,1.85,17.86]],"batl":[[0,2.66,25.21]],"ltp":3.1,"tv":0.0,"id":7412809}]}]}
{"op":"mcm","clk":"1009402396","pt":1580644034934,"mc":[{"id":"1.168217557","rc":[{"batl":[[1,3.15,200.42]],"ltp":3.1,"tv":0.0,"id":7412809}]}]}
{"op":"mcm","clk":"1009402889","pt":1580644038431,"mc":[{"id":"1.168217557","rc":[{"trd":[[1.71,292.22]],"batb":[[0,1.7,23.92],[1,1.6,69.74],[2,1.57,31.32]],"batl":[[1,2.04,383.01],[2,1.8,0]],"ltp":1.71,"tv":309.91,"id":2263624}],"tv":309.92}]}
{"op":"mcm","clk":"1009403308","pt":1580644041454,"mc":[{"id":"1.168217557","rc":[{"trd":[[1.75,26.52]],"batb":[[0,1.7,225.26],[1,1.68,224.59]],"batl":[[0,1.75,28.75],[1,1.77,138.48],[2,1.79,183.03]],"ltp":1.75,"tv":336.43,"id":2263624},{"batl":[[0,3.15,200.42],[1,3.15,0]],"ltp":3.1,"tv":0.0,"id":7412809}],"tv":336.44}]}
{"op":"mcm","clk":"1009403706","pt":1580644044447,"mc":[{"id":"1.168217557","rc":[{"batb":[[2,1.61,68.06]],"batl":[[0,1.75,41.35]],"ltp":1.75,"tv":336.43,"id":2263624},{"batl":[[0,2.64,25.21],[1,3.15,200.42]],"ltp":3.1,"tv":0.0,"id":7412809}]}]}
{"op":"mcm","clk":"1009405388","pt":1580644055458,"mc":[{"id":"1.168217557","rc":[{"batb":[[0,1.7,23.92],[1,1.61,68.06],[2,1.57,31.32]],"batl":[[1,2.04,383.01],[2,1.79,0]],"ltp":1.75,"tv":336.43,"id":2263624}]}]}
{"op":"mcm","clk":"1009405498","pt":1580644056256,"mc":[{"id":"1.168217557","rc":[{"batb":[[0,1.61,68.06],[1,1.57,31.32],[2,1.01,10.51]],"ltp":1.75,"tv":336.43,"id":2263624},{"batb":[[1,1.85,17.86],[2,1.01,10.52]],"ltp":3.1,"tv":0.0,"id":7412809}]}]}
{"op":"mcm","clk":"1009405655","pt":1580644057429,"mc":[{"id":"1.168217557","rc":[{"batb":[[0,1.57,31.32],[1,1.01,10.51],[2,1.01,0]],"batl":[[0,2.04,383.01],[1,2.04,0]],"ltp":1.75,"tv":336.43,"id":2263624},{"batb":[[0,1.85,17.86],[1,1.01,10.52],[2,1.01,0]],"batl":[[0,3.15,200.42],[1,3.15,0]],"ltp":3.1,"tv":0.0,"id":7412809}]}]}
{"op":"mcm","clk":"1009405785","pt":1580644058342,"mc":[{"id":"1.168217557","rc":[{"batb":[[0,1.57,249.32],[1,1.56,148.6],[2,1.01,10.51]],"batl":[[1,2.14,122.93],[2,2.16,103.68]],"ltp":1.75,"tv":336.43,"id":2263624}]}]}
{"op":"mcm","clk":"1009405896","pt":1580644059186,"mc":[{"id":"1.168217557","rc":[{"batb":[[0,1.57,31.32],[1,1.01,10.51],[2,1.01,0]],"batl":[[1,2.14,0],[2,2.16,0]],"ltp":1.75,"tv":336.43,"id":2263624},{"batb":[[0,1.86,17.78]],"ltp":3.1,"tv":0.0,"id":7412809}]}]}
{"op":"mcm","clk":"1009406334","pt":1580644062446,"mc":[{"id":"1.168217557","rc":[{"batb":[[0,1.76,169.62],[1,1.74,198.74],[2,1.57,31.32]],"batl":[[0,1.83,106.67],[1,1.85,164.77]],"ltp":1.75,"tv":336.43,"id":2263624}]}]}
{"op":"mcm","clk":"1009406607","pt":1580644063973,"mc":[{"id":"1.168217557","rc":[{"batb":[[0,1.57,31.32],[1,1.01,10.51],[2,1.57,0]],"ltp":1.75,"tv":336.43,"id":2263624}]}]}
{"op":"mcm","clk":"1009406753","pt":1580644064870,"mc":[{"id":"1.168217557","rc":[{"batl":[[0,2.3,309.75]],"ltp":1.75,"tv":336.43,"id":2263624},{"batl":[[0,3,213.45]],"ltp":3.1,"tv":0.0,"id":7412809}]}]}
{"op":"mcm","clk":"1009407016","pt":1580644066978,"mc":[{"id":"1.168217557","rc":[{"batb":[[0,1.57,249.32],[1,1.56,148.6],[2,1.01,10.51]],"batl":[[0,2.14,122.93],[1,2.16,103.68],[2,2.3,309.75]],"ltp":1.75,"tv":336.43,"id":2263624}]}]}
{"op":"mcm","clk":"1009408090","pt":1580644075355,"mc":[{"id":"1.168217557","rc":[{"batb":[[0,1.57,31.32],[1,1.01,10.51],[2,1.01,0]],"batl":[[0,2.3,309.75],[1,2.16,0],[2,2.3,0]],"ltp":1.75,"tv":336.43,"id":2263624}]}]}
{"op":"mcm","clk":"1009408488","pt":1580644078394,"mc":[{"id":"1.168217557","rc":[{"batb":[[0,2.02,27.22],[1,1.86,48.73],[2,1.72,22.66]],"batl":[[0,2.06,39.49]],"ltp":1.75,"tv":336.43,"id":2263624},{"batb":[[0,1.93,44.53],[1,1.88,118.06],[2,1.86,176.94]],"batl":[[0,1.96,129.82],[1,1.98,133.44],[2,2.16,36.13]],"ltp":3.1,"tv":0.0,"id":7412809}]}]}
{"op":"mcm","clk":"1009408570","pt":1580644078888,"mc":[{"id":"1.168217557","rc":[{"batb":[[1,1.72,22.66],[2,1.01,10.51]],"ltp":1.75,"tv":336.43,"id":2263624},{"batb":[[0,1.88,118.06],[1,1.86,176.94],[2,1.41,49.19]],"batl":[[2,2.16,0]],"ltp":3.1,"tv":0.0,"id":7412809}]}]}
{"op":"mcm","clk":"1009408880","pt":1580644081293,"mc":[{"id":"1.168217557","rc":[{"batl":[[0,2.72,241.55]],"ltp":1.75,"tv":336.43,"id":2263624},{"trd":[[1.96,42]],"batl":[[0,1.96,108.82],[2,2.5,274.54]],"ltp":1.96,"tv":42.0,"id":7412809}],"tv":378.44}]}
{"op":"mcm","clk":"1009408981","pt":1580644082084,"mc":[{"id":"1.168217557","rc":[{"batb":[[1,1.91,45.37],[2,1.72,22.66]],"batl":[[0,2.1,37.81],[1,2.72,241.55]],"ltp":1.75,"tv":336.43,"id":2263624},{"batb":[[0,1.91,45.37],[1,1.88,118.06],[2,1.86,176.94]],"batl":[[2,2.1,37.81]],"ltp":1.96,"tv":42.0,"id":7412809}]}]}
{"op":"mcm","clk":"1009410049","pt":1580644090471,"mc":[{"id":"1.168217557","rc":[{"batl":[[0,1.96,134.78]],"ltp":1.96,"tv":42.0,"id":7412809}]}]}
{"op":"mcm","clk":"1009410550","pt":1580644094415,"mc":[{"id":"1.168217557","rc":[{"batb":[[0,1.91,45.37],[1,1.72,22.66],[2,1.01,10.51]],"ltp":1.75,"tv":336.43,"id":2263624},{"batb":[[1,1.41,49.19],[2,1.01,10.51]],"batl":[[0,2.1,37.81],[1,2.5,274.54],[2,2.1,0]],"ltp":1.96,"tv":42.0,"id":7412809}]}]}
{"op":"mcm","clk":"1009410706","pt":1580644095481,"mc":[{"id":"1.168217557","rc":[{"batb":[[0,1.72,22.66],[1,1.01,10.51],[2,1.01,0]],"batl":[[0,2.72,241.55],[1,2.72,0]],"ltp":1.75,"tv":336.43,"id":2263624},{"batb":[[0,1.41,49.19],[1,1.01,10.51],[2,1.01,0]],"batl":[[0,2.5,274.54],[1,2.5,0]],"ltp":1.96,"tv":42.0,"id":7412809}]}]}
{"op":"mcm","clk":"1009410980","pt":1580644097492,"mc":[{"id":"1.168217557","rc":[{"batb":[[0,1.7,23.68]],"ltp":1.75,"tv":336.43,"id":2263624},{"batb":[[0,1.42,47.22]],"ltp":1.96,"tv":42.0,"id":7412809}]}]}
{"op":"mcm","clk":"1009411197","pt":1580644099331,"mc":[{"id":"1.168217557","rc":[{"batb":[[0,1.76,163.97],[1,1.74,198.13],[2,1.42,47.22]],"batl":[[0,1.83,109.98],[1,1.85,164.17]],"ltp":1.96,"tv":42.0,"id":7412809}]}]}
{"op":"mcm","clk":"1009411441","pt":1580644101313,"mc":[{"id":"1.168217557","rc":[{"batl":[[0,2.82,231.28]],"ltp":1.75,"tv":336.43,"id":2263624},{"batl":[[2,2.42,286.52]],"ltp":1.96,"tv":42.0,"id":7412809}]}]}
{"op":"mcm","clk":"1009411611","pt":1580644102795,"mc":[{"id":"1.168217557","rc":[{"batb":[[0,1.42,47.22],[1,1.01,10.51],[2,1.42,0]],"batl":[[0,2.42,286.52],[1,1.85,0],[2,2.42,0]],"ltp":1.96,"tv":42.0,"id":7412809}]}]}
{"op":"mcm","clk":"1009411943","pt":1580644105810,"mc":[{"id":"1.168217557","rc":[{"batb":[[1,1.41,301.17],[2,1.4,231.83]],"batl":[[0,2.38,87.07],[1,2.42,439.8]],"ltp":1.96,"tv":42.0,"id":7412809}]}]}
{"op":"mcm","clk":"1009412481","pt":1580644111423,"mc":[{"id":"1.168217557","rc":[{"batb":[[1,1.01,10.51],[2,1.4,0]],"batl":[[0,2.42,286.52],[1,2.42,0]],"ltp":1.96,"tv":42.0,"id":7412809}]}]}
{"op":"mcm","clk":"1009412768","pt":1580644114410,"mc":[{"id":"1.168217557","rc":[{"batb":[[0,1.72,168.86],[1,1.7,239.03],[2,1.67,62.17]],"batl":[[0,1.79,147.34],[1,1.81,176.57]],"ltp":1.75,"tv":336.43,"id":2263624},{"batl":[[0,2.48,27.73]],"ltp":1.96,"tv":42.0,"id":7412809}]}]}
{"op":"mcm","clk":"1009412859","pt":1580644115204,"mc":[{"id":"1.168217557","rc":[{"batb":[[2,1.66,63.01]],"ltp":1.75,"tv":336.43,"id":2263624},{"batb":[[0,2.24,20.06],[1,1.85,17.94],[2,1.01,10.52]],"ltp":1.96,"tv":42.0,"id":7412809}]}]}
{"op":"mcm","clk":"1009413092","pt":1580644117313,"mc":[{"id":"1.168217557","rc":[{"batl":[[1,1.8,42.01],[2,1.81,176.57]],"ltp":1.75,"tv":336.43,"id":2263624},{"batb":[[0,2.26,32.77],[1,2.24,20.06],[2,1.85,17.94]],"batl":[[1,3.15,200.42]],"ltp":1.96,"tv":42.0,"id":7412809}]}]}
{"op":"mcm","clk":"1009414826","pt":1580644133451,"mc":[{"id":"1.168217557","rc":[{"batb":[[0,1.57,31.16],[1,1.01,10.51],[2,1.66,0]],"batl":[[0,1.72,2.12],[1,2.22,329.01],[2,1.81,0]],"ltp":1.75,"tv":336.43,"id":2263624},{"batb":[[0,1.85,17.94],[1,1.01,10.52],[2,1.85,0]],"batl":[[0,3.15,200.42],[1,3.15,0]],"ltp":1.96,"tv":42.0,"id":7412809}]}]}
{"op":"mcm","clk":"1009415081","pt":1580644135459,"mc":[{"id":"1.168217557","rc":[{"batb":[[0,1.58,256.55],[1,1.57,176.33],[2,1.01,10.51]],"batl":[[0,2.18,186.68],[1,2.2,98.54],[2,2.22,329.01]],"ltp":1.75,"tv":336.43,"id":2263624}]}]}
{"op":"mcm","clk":"1009415523","pt":1580644139440,"mc":[{"id":"1.168217557","rc":[{"batl":[[0,2.22,329.01],[1,2.2,0],[2,2.22,0]],"ltp":1.75,"tv":336.43,"id":2263624}]}]}
{"op":"mcm","clk":"1009415880","pt":1580644142453,"mc":[{"id":"1.168217557","rc":[{"batb":[[2,1.55,75.62]],"batl":[[0,1.64,137.53],[1,1.65,119.78],[2,1.66,42.01]],"ltp":1.75,"tv":336.43,"id":2263624},{"batb":[[0,2.52,41.52],[1,2.2,21.4],[2,1.85,17.94]],"batl":[[0,2.84,22.69]],"ltp":1.96,"tv":42.0,"id":7412809}]}]}
{"op":"mcm","clk":"1009415893","pt":1580644142553,"mc":[{"id":"1.168217557","rc":[{"batb":[[2,1.01,10.52]],"ltp":1.96,"tv":42.0,"id":7412809}]}]}
{"op":"mcm","clk":"1009416238","pt":1580644145551,"mc":[{"id":"1.168217557","rc":[{"batl":[[1,3.65,170.41]],"ltp":1.96,"tv":42.0,"id":7412809}]}]}
{"op":"mcm","clk":"1009417177","pt":1580644153259,"mc":[{"id":"1.168217557","rc":[{"trd":[[1.58,4.24]],"batb":[[0,1.58,254.43]],"ltp":1.58,"tv":340.68,"id":2263624}],"tv":382.69}]}
{"op":"mcm","clk":"1009418124","pt":1580644162295,"mc":[{"id":"1.168217557","rc":[{"batb":[[0,1.55,75.62],[1,1.51,36.9],[2,1.01,10.51]],"batl":[[0,1.66,42.01],[1,2.04,383.01],[2,1.66,0]],"ltp":1.58,"tv":340.68,"id":2263624},{"batb":[[0,2.52,26.89]],"ltp":1.96,"tv":42.0,"id":7412809}]}]}
{"op":"mcm","clk":"1009418233","pt":1580644163493,"mc":[{"id":"1.168217557","rc":[{"batb":[[0,1.51,36.9],[1,1.01,10.51],[2,1.01,0]],"batl":[[0,2.04,383.01],[1,2.04,0]],"ltp":1.58,"tv":340.68,"id":2263624},{"batb":[[0,2.2,21.4],[1,1.01,10.52],[2,1.01,0]],"batl":[[0,3.65,170.41],[1,3.65,0]],"ltp":1.96,"tv":42.0,"id":7412809}]}]}
{"op":"mcm","clk":"1009418415","pt":1580644165288,"mc":[{"id":"1.168217557","rc":[{"batb":[[0,1.52,161.44],[1,1.51,205.55],[2,1.01,10.51]],"batl":[[0,1.81,154.17],[1,1.83,170.47],[2,2.04,383.01]],"ltp":1.58,"tv":340.68,"id":2263624}]}]}
{"op":"mcm","clk":"1009419835","pt":1580644178497,"mc":[{"id":"1.168217557","rc":[{"batl":[[0,2.04,383.01],[1,1.83,0],[2,2.04,0]],"ltp":1.58,"tv":340.68,"id":2263624}]}]}
{"op":"mcm","clk":"1009420139","pt":1580644181483,"mc":[{"id":"1.168217557","rc":[{"batl":[[0,1.57,189.84],[1,1.58,139.78],[2,2.04,383.01]],"ltp":1.58,"tv":340.68,"id":2263624}]}]}
{"op":"mcm","clk":"1009420245","pt":1580644182427,"mc":[{"id":"1.168217557","rc":[{"batb":[[2,1.48,87.38]],"batl":[[1,1.58,181.79]],"ltp":1.58,"tv":340.68,"id":2263624},{"batb":[[0,2.72,24.37],[1,2.7,12.04],[2,2.48,15.19]],"batl":[[0,3.1,19.32],[1,3.65,170.41]],"ltp":1.96,"tv":42.0,"id":7412809}]}]}
{"op":"mcm","clk":"1009423417","pt":1580644212445,"mc":[{"id":"1.168217557","rc":[{"batb":[[0,1.48,87.38],[1,1.39,51.54],[2,1.01,10.51]],"batl":[[0,1.58,42.01],[1,2.04,383.01],[2,2.04,0]],"ltp":1.58,"tv":340.68,"id":2263624},{"batb":[[1,2.48,15.19],[2,1.01,10.52]],"ltp":1.96,"tv":42.0,"id":7412809}]}]}
{"op":"mcm","clk":"1009423541","pt":1580644213552,"mc":[{"id":"1.168217557","rc":[{"batb":[[0,1.39,51.54],[1,1.01,10.51],[2,1.01,0]],"batl":[[0,2.04,383.01],[1,2.04,0]],"ltp":1.58,"tv":340.68,"id":2263624},{"batb":[[0,2.48,15.19],[1,1.01,10.52],[2,1.01,0]],"batl":[[0,3.65,170.41],[1,3.65,0]],"ltp":1.96,"tv":42.0,"id":7412809}]}]}
{"op":"mcm","clk":"1009423929","pt":1580644217146,"mc":[{"id":"1.168217557","rc":[{"batb":[[0,1.49,288.74],[1,1.48,183.89],[2,1.39,51.54]],"batl":[[0,1.55,271.34],[1,1.56,146.14],[2,2.04,383.01]],"ltp":1.58,"tv":340.68,"id":2263624}]}]}
{"op":"mcm","clk":"1009424455","pt":1580644222176,"mc":[{"id":"1.168217557","rc":[{"batb":[[0,1.39,51.54],[1,1.01,10.51],[2,1.39,0]],"batl":[[0,2.04,383.01],[1,1.56,0],[2,2.04,0]],"ltp":1.58,"tv":340.68,"id":2263624}]}]}
{"op":"mcm","clk":"1009424712","pt":1580644225152,"mc":[{"id":"1.168217557","rc":[{"batb":[[0,1.41,211.2],[1,1.4,233.56],[2,1.39,51.54]],"batl":[[0,1.66,225.43],[1,1.68,225.79],[2,2.04,383.01]],"ltp":1.58,"tv":340.68,"id":2263624}]}]}
{"op":"mcm","clk":"1009425224","pt":1580644230100,"mc":[{"id":"1.168217557","rc":[{"batb":[[0,1.39,51.54],[1,1.01,10.51],[2,1.39,0]],"ltp":1.58,"tv":340.68,"id":2263624}]}]}
{"op":"mcm","clk":"1009425562","pt":1580644233469,"mc":[{"id":"1.168217557","rc":[{"batb":[[0,1.6,132.66],[1,1.59,168.25],[2,1.48,39.73]],"ltp":1.58,"tv":340.68,"id":2263624},{"batb":[[1,2.32,18.1],[2,1.01,10.52]],"ltp":1.96,"tv":42.0,"id":7412809}]}]}
{"op":"mcm","clk":"1009425651","pt":1580644234460,"mc":[{"id":"1.168217557","rc":[{"batb":[[2,1.54,77.3]],"batl":[[0,1.66,267.44]],"ltp":1.58,"tv":340.68,"id":2263624},{"batb":[[0,2.52,26.89],[1,2.48,15.19],[2,2.32,18.1]],"batl":[[0,2.84,22.69]],"ltp":1.96,"tv":42.0,"id":7412809}]}]}
{"op":"mcm","clk":"1009425802","pt":1580644236089,"mc":[{"id":"1.168217557","rc":[{"batl":[[1,3.45,180.4]],"ltp":1.96,"tv":42.0,"id":7412809}]}]}
{"op":"mcm","clk":"1009426753","pt":1580644244510,"mc":[{"id":"1.168217557","rc":[{"batb":[[0,1.54,77.3],[1,1.48,39.73],[2,1.01,10.51]],"batl":[[0,1.66,42.01],[1,2.04,383.01],[2,2.04,0]],"ltp":1.58,"tv":340.68,"id":2263624},{"batb":[[1,2.32,18.1],[2,1.01,10.52]],"ltp":1.96,"tv":42.0,"id":7412809}]}]}
{"op":"mcm","clk":"1009426883","pt":1580644245509,"mc":[{"id":"1.168217557","rc":[{"batb":[[0,1.48,39.73],[1,1.01,10.51],[2,1.01,0]],"batl":[[0,2.04,383.01],[1,2.04,0]],"ltp":1.58,"tv":340.68,"id":2263624},{"batb":[[0,2.32,18.1],[1,1.01,10.52],[2,1.01,0]],"batl":[[0,3.45,180.4],[1,3.45,0]],"ltp":1.96,"tv":42.0,"id":7412809}]}]}
{"op":"mcm","clk":"1009427043","pt":1580644246809,"mc":[{"id":"1.168217557","rc":[{"batb":[[0,1.5,130.33],[1,1.49,177.84],[2,1.48,39.73]],"batl":[[0,1.73,143.03],[1,1.75,197.13],[2,2.04,383.01]],"ltp":1.58,"tv":340.68,"id":2263624}]}]}
{"op":"mcm","clk":"1009427658","pt":1580644252003,"mc":[{"id":"1.168217557","rc":[{"batb":[[0,1.48,39.73],[1,1.01,10.51],[2,1.48,0]],"ltp":1.58,"tv":340.68,"id":2263624}]}]}
{"op":"mcm","clk":"1009427937","pt":1580644254522,"mc":[{"id":"1.168217557","rc":[{"batb":[[0,1.67,129.73],[1,1.66,117.76],[2,1.48,39.73]],"ltp":1.58,"tv":340.68,"id":2263624}]}]}
{"op":"mcm","clk":"1009428055","pt":1580644255420,"mc":[{"id":"1.168217557","rc":[{"batb":[[1,1.66,143.73],[2,1.57,31.39]],"ltp":1.58,"tv":340.68,"id":2263624},{"batb":[[1,2.22,20.54],[2,1.01,10.52]],"ltp":1.96,"tv":42.0,"id":7412809}]}]}
{"op":"mcm","clk":"1009428184","pt":1580644256476,"mc":[{"id":"1.168217557","rc":[{"batb":[[2,1.6,69.74]],"batl":[[1,1.74,42.01],[2,1.75,197.13]],"ltp":1.58,"tv":340.68,"id":2263624},{"batb":[[0,2.36,30.25],[1,2.32,18.1],[2,2.22,20.54]],"batl":[[0,2.64,25.21]],"ltp":1.96,"tv":42.0,"id":7412809}]}]}
{"op":"mcm","clk":"1009428279","pt":1580644257417,"mc":[{"id":"1.168217557","rc":[{"batl":[[1,3.3,191.92]],"ltp":1.96,"tv":42.0,"id":7412809}]}]}
{"op":"mcm","clk":"1009430431","pt":1580644275430,"mc":[{"id":"1.168217557","rc":[{"batb":[[0,1.6,69.74],[1,1.57,31.39],[2,1.01,10.51]],"batl":[[0,1.74,42.01],[1,2.04,383.01],[2,1.75,0]],"ltp":1.58,"tv":340.68,"id":2263624},{"batb":[[1,2.22,20.54],[2,1.01,10.52]],"ltp":1.96,"tv":42.0,"id":7412809}]}]}
{"op":"mcm","clk":"1009430456","pt":1580644275643,"mc":[{"id":"1.168217557","rc":[{"batb":[[0,1.57,31.39],[1,1.01,10.51],[2,1.01,0]],"batl":[[0,2.04,383.01],[1,2.04,0]],"ltp":1.58,"tv":340.68,"id":2263624},{"batb":[[0,2.22,20.54],[1,1.01,10.52],[2,1.01,0]],"batl":[[0,3.3,191.92],[1,3.3,0]],"ltp":1.96,"tv":42.0,"id":7412809}]}]}
{"op":"mcm","clk":"1009430694","pt":1580644277748,"mc":[{"id":"1.168217557","rc":[{"batb":[[0,1.59,172.46],[1,1.58,141.35],[2,1.57,31.39]],"batl":[[0,1.79,172.63],[1,1.81,176.51],[2,2.04,383.01]],"ltp":1.58,"tv":340.68,"id":2263624}]}]}
{"op":"mcm","clk":"1009431387","pt":1580644283837,"mc":[{"id":"1.168217557","rc":[{"batb":[[0,1.57,31.39],[1,1.01,10.51],[2,1.57,0]],"ltp":1.58,"tv":340.68,"id":2263624}]}]}
{"op":"mcm","clk":"1009431753","pt":1580644287467,"mc":[{"id":"1.168217557","rc":[{"batb":[[0,1.72,142.29],[1,1.71,23.13],[2,1.7,215.28]],"ltp":1.58,"tv":340.68,"id":2263624},{"batb":[[1,2.16,22.42],[2,1.01,10.52]],"ltp":1.96,"tv":42.0,"id":7412809}]}]}
{"op":"mcm","clk":"1009431890","pt":1580644288542,"mc":[{"id":"1.168217557","rc":[{"batl":[[0,1.79,214.64]],"ltp":1.58,"tv":340.68,"id":2263624},{"batb":[[0,2.26,32.77],[1,2.22,20.54],[2,2.16,22.42]],"batl":[[0,2.52,26.89],[1,3.3,191.92]],"ltp":1.96,"tv":42.0,"id":7412809}]}]}
{"op":"mcm","clk":"1009433470","pt":1580644302442,"mc":[{"id":"1.168217557","rc":[{"batb":[[0,1.66,63.01],[1,1.65,26.28],[2,1.01,10.51]],"batl":[[0,1.79,42.01],[1,2.04,383.01],[2,2.04,0]],"ltp":1.58,"tv":340.68,"id":2263624},{"batb":[[1,2.16,22.42],[2,1.01,10.52]],"ltp":1.96,"tv":42.0,"id":7412809}]}]}
{"op":"mcm","clk":"1009433616","pt":1580644303551,"mc":[{"id":"1.168217557","rc":[{"batb":[[0,1.65,26.28],[1,1.01,10.51],[2,1.01,0]],"batl":[[0,2.04,383.01],[1,2.04,0]],"ltp":1.58,"tv":340.68,"id":2263624},{"batb":[[0,2.16,22.42],[1,1.01,10.52],[2,1.01,0]],"batl":[[0,3.3,191.92],[1,3.3,0]],"ltp":1.96,"tv":42.0,"id":7412809}]}]}
{"op":"mcm","clk":"1009433845","pt":1580644305385,"mc":[{"id":"1.168217557","rc":[{"batb":[[0,1.67,188.42],[1,1.66,117.9],[2,1.65,26.28]],"batl":[[0,1.82,159.2],[1,1.84,167.55],[2,2.04,383.01]],"ltp":1.58,"tv":340.68,"id":2263624}]}]}
{"op":"mcm","clk":"1009434047","pt":1580644307160,"mc":[{"id":"1.168217557","rc":[{"batb":[[0,1.65,26.28],[1,1.01,10.51],[2,1.65,0]],"ltp":1.58,"tv":340.68,"id":2263624}]}]}
{"op":"mcm","clk":"1009434408","pt":1580644310367,"mc":[{"id":"1.168217557","rc":[{"batb":[[0,1.75,146],[1,1.73,202.62],[2,1.67,25.41]],"batl":[[2,2.04,0]],"ltp":1.58,"tv":340.68,"id":2263624},{"batb":[[1,1.91,16.29],[2,1.01,10.52]],"ltp":1.96,"tv":42.0,"id":7412809}]}]}
{"op":"mcm","clk":"1009434427","pt":1580644310579,"mc":[{"id":"1.168217557","rc":[{"batb":[[2,1.7,59.65]],"batl":[[1,1.84,209.56]],"ltp":1.58,"tv":340.68,"id":2263624},{"batb":[[0,2.18,35.29],[1,2.16,22.42],[2,1.91,16.29]],"batl":[[0,2.44,28.57]],"ltp":1.96,"tv":42.0,"id":7412809}]}]}
{"op":"mcm","clk":"1009434864","pt":1580644314152,"mc":[{"id":"1.168217557","rc":[{"batl":[[2,2.3,309.75]],"ltp":1.58,"tv":340.68,"id":2263624},{"batl":[[1,3,213.45]],"ltp":1.96,"tv":42.0,"id":7412809}]}]}
{"op":"mcm","clk":"1009444191","pt":1580644399378,"mc":[{"id":"1.168217557","rc":[{"batb":[[0,1.7,59.65],[1,1.67,25.41],[2,1.01,10.51]],"batl":[[0,1.84,42.01],[1,2.3,309.75],[2,2.3,0]],"ltp":1.58,"tv":340.68,"id":2263624},{"batb":[[1,1.91,16.29],[2,1.01,10.52]],"ltp":1.96,"tv":42.0,"id":7412809}]}]}
{"op":"mcm","clk":"1009444288","pt":1580644400274,"mc":[{"id":"1.168217557","rc":[{"batb":[[0,1.67,25.41],[1,1.01,10.51],[2,1.01,0]],"batl":[[0,2.3,309.75],[1,2.3,0]],"ltp":1.58,"tv":340.68,"id":2263624},{"batb":[[0,1.91,16.29],[1,1.01,10.52],[2,1.01,0]],"batl":[[0,3,213.45],[1,3,0]],"ltp":1.96,"tv":42.0,"id":7412809}]}]}
{"op":"mcm","clk":"1009444480","pt":1580644401865,"mc":[{"id":"1.168217557","rc":[{"batb":[[1,1.66,181.73],[2,1.65,120.48]],"batl":[[0,2.04,144.23],[1,2.06,118.94],[2,2.3,309.75]],"ltp":1.58,"tv":340.68,"id":2263624}]}]}
{"op":"mcm","clk":"1009446744","pt":1580644423019,"mc":[{"id":"1.168217557","rc":[{"batb":[[1,1.01,10.51],[2,1.65,0]],"batl":[[0,2.3,309.75],[1,2.06,0],[2,2.3,0]],"ltp":1.58,"tv":340.68,"id":2263624}]}]}
{"op":"mcm","clk":"1009447064","pt":1580644426491,"mc":[{"id":"1.168217557","rc":[{"batb":[[0,1.75,123.28],[1,1.73,202.62],[2,1.67,25.41]],"batl":[[0,1.82,160.48],[1,1.84,167.55],[2,2.3,309.75]],"ltp":1.58,"tv":340.68,"id":2263624}]}]}
{"op":"mcm","clk":"1009448489","pt":1580644441036,"mc":[{"id":"1.168217557","rc":[{"batb":[[0,1.67,25.41],[1,1.01,10.51],[2,1.67,0]],"batl":[[0,2.3,309.75],[1,1.84,0],[2,2.3,0]],"ltp":1.58,"tv":340.68,"id":2263624}]}]}
{"op":"mcm","clk":"1009448762","pt":1580644443815,"mc":[{"id":"1.168217557","rc":[{"batb":[[1,1.66,181.73],[2,1.65,120.48]],"batl":[[0,2.04,144.23],[1,2.06,118.94],[2,2.3,309.75]],"ltp":1.58,"tv":340.68,"id":2263624}]}]}
{"op":"mcm","clk":"1009449516","pt":1580644451270,"mc":[{"id":"1.168217557","rc":[{"batl":[[0,2.3,309.75],[1,2.06,0],[2,2.3,0]],"ltp":1.58,"tv":340.68,"id":2263624}]}]}
{"op":"mcm","clk":"1009449813","pt":1580644454229,"mc":[{"id":"1.168217557","rc":[{"batl":[[0,1.73,205.84],[1,1.75,196.87]],"ltp":1.58,"tv":340.68,"id":2263624}]}]}
{"op":"mcm","clk":"1009449892","pt":1580644455065,"mc":[{"id":"1.168217557","rc":[{"batl":[[1,1.75,238.88]],"ltp":1.58,"tv":340.68,"id":2263624},{"batb":[[0,2.32,31.09],[1,2.3,18.57],[2,2.08,25.1]],"batl":[[0,2.6,26.05],[1,3,213.45]],"ltp":1.96,"tv":42.0,"id":7412809}]}]}
{"op":"mcm","clk":"1009450223","pt":1580644457946,"mc":[{"id":"1.168217557","rc":[{"batl":[[2,2.16,342.82]],"ltp":1.58,"tv":340.68,"id":2263624}]}]}
{"op":"mcm","clk":"1009452265","pt":1580644479063,"mc":[{"id":"1.168217557","rc":[{"batb":[[0,1.62,67.22],[1,1.6,29.11],[2,1.01,10.51]],"batl":[[0,1.75,42.01],[1,2.16,342.82],[2,2.16,0]],"ltp":1.58,"tv":340.68,"id":2263624},{"batb":[[1,2.08,25.1],[2,1.01,10.52]],"ltp":1.96,"tv":42.0,"id":7412809}]}]}
{"op":"mcm","clk":"1009452334","pt":1580644479685,"mc":[{"id":"1.168217557","rc":[{"batb":[[0,1.6,29.11],[1,1.01,10.51],[2,1.01,0]],"batl":[[0,2.16,342.82],[1,2.16,0]],"ltp":1.58,"tv":340.68,"id":2263624},{"batb":[[0,2.08,25.1],[1,1.01,10.52],[2,1.01,0]],"batl":[[0,3,213.45],[1,3,0]],"ltp":1.96,"tv":42.0,"id":7412809}]}]}
{"op":"mcm","clk":"1009452514","pt":1580644481470,"mc":[{"id":"1.168217557","rc":[{"batb":[[0,1.6,248.78],[1,1.59,138.2],[2,1.01,10.51]],"batl":[[0,1.87,147.88],[1,1.89,154.08],[2,2.16,342.82]],"ltp":1.58,"tv":340.68,"id":2263624}]}]}
{"op":"mcm","clk":"1009452708","pt":1580644483089,"mc":[{"id":"1.168217557","rc":[{"batb":[[0,1.6,29.11],[1,1.01,10.51],[2,1.01,0]],"batl":[[0,2.16,342.82],[1,1.89,0],[2,2.16,0]],"ltp":1.58,"tv":340.68,"id":2263624}]}]}
{"op":"mcm","clk":"1009453046","pt":1580644486390,"mc":[{"id":"1.168217557","rc":[{"batb":[[0,1.69,118.06],[1,1.67,229.07],[2,1.6,29.11]],"batl":[[0,1.75,133.54],[1,1.77,189.93],[2,2.16,342.82]],"ltp":1.58,"tv":340.68,"id":2263624}]}]}
{"op":"mcm","clk":"1009453268","pt":1580644488686,"mc":[{"id":"1.168217557","rc":[{"batb":[[0,1.6,29.11],[1,1.01,10.51],[2,1.6,0]],"batl":[[0,2.16,342.82],[1,1.77,0],[2,2.16,0]],"ltp":1.58,"tv":340.68,"id":2263624}]}]}
{"op":"mcm","clk":"1009453557","pt":1580644491989,"mc":[{"id":"1.168217557","rc":[{"batl":[[0,1.87,147.88],[1,1.89,154.08],[2,2.16,342.82]],"ltp":1.58,"tv":340.68,"id":2263624}]}]}
{"op":"mcm","clk":"1009453721","pt":1580644493508,"mc":[{"id":"1.168217557","rc":[{"batb":[[0,1.79,181.33],[1,1.77,187.68],[2,1.6,29.11]],"ltp":1.58,"tv":340.68,"id":2263624}]}]}
{"op":"mcm","clk":"1009453817","pt":1580644494508,"mc":[{"id":"1.168217557","rc":[{"batb":[[0,1.81,19.28],[1,1.79,181.33],[2,1.77,187.68]],"ltp":1.58,"tv":340.68,"id":2263624},{"batb":[[1,1.8,19.75],[2,1.01,10.52]],"ltp":1.96,"tv":42.0,"id":7412809}]}]}
{"op":"mcm","clk":"1009453841","pt":1580644494779,"mc":[{"id":"1.168217557","rc":[{"batl":[[1,1.89,196.09]],"ltp":1.58,"tv":340.68,"id":2263624},{"batb":[[0,2.14,36.13],[1,2.08,25.1],[2,1.8,19.75]],"batl":[[0,2.36,30.25],[1,3,213.45]],"ltp":1.96,"tv":42.0,"id":7412809}]}]}
{"op":"mcm","clk":"1009455585","pt":1580644510124,"mc":[{"id":"1.168217557","rc":[{"batb":[[0,1.69,24.08],[1,1.01,10.51],[2,1.77,0]],"batl":[[0,2.16,342.82],[1,1.89,0],[2,2.16,0]],"ltp":1.58,"tv":340.68,"id":2263624},{"batb":[[0,1.8,19.75],[1,1.01,10.52],[2,1.8,0]],"batl":[[0,3,213.45],[1,3,0]],"ltp":1.96,"tv":42.0,"id":7412809}]}]}
{"op":"mcm","clk":"1009455873","pt":1580644512435,"mc":[{"id":"1.168217557","rc":[{"batb":[[1,1.68,144.28],[2,1.67,115.31]],"batl":[[1,2.18,140.98],[2,2.2,98.53]],"ltp":1.58,"tv":340.68,"id":2263624}]}]}
{"op":"mcm","clk":"1009455936","pt":1580644513022,"mc":[{"id":"1.168217557","rc":[{"batb":[[0,1.81,19.43]],"ltp":1.96,"tv":42.0,"id":7412809}]}]}
{"op":"mcm","clk":"1009456076","pt":1580644514329,"mc":[{"id":"1.168217557","rc":[{"batb":[[1,1.01,10.51],[2,1.67,0]],"batl":[[1,2.18,0],[2,2.2,0]],"ltp":1.58,"tv":340.68,"id":2263624}]}]}
{"op":"mcm","clk":"1009456397","pt":1580644517318,"mc":[{"id":"1.168217557","rc":[{"batb":[[0,1.84,170.6],[1,1.82,171.1],[2,1.69,24.08]],"batl":[[0,1.92,112.57],[1,1.94,142.24]],"ltp":1.58,"tv":340.68,"id":2263624}]}]}
{"op":"mcm","clk":"1009456481","pt":1580644518129,"mc":[{"id":"1.168217557","rc":[{"batb":[[0,1.69,24.08],[1,1.01,10.51],[2,1.69,0]],"ltp":1.58,"tv":340.68,"id":2263624}]}]}
{"op":"mcm","clk":"1009456597","pt":1580644519346,"mc":[{"id":"1.168217557","rc":[{"batl":[[0,2.42,286.52]],"ltp":1.58,"tv":340.68,"id":2263624},{"batl":[[0,2.82,231.28]],"ltp":1.96,"tv":42.0,"id":7412809}]}]}
{"op":"mcm","clk":"1009456766","pt":1580644521031,"mc":[{"id":"1.168217557","rc":[{"batb":[[1,1.68,144.28],[2,1.67,115.31]],"batl":[[0,2.18,140.98],[1,2.2,98.53],[2,2.42,286.52]],"ltp":1.58,"tv":340.68,"id":2263624}]}]}
{"op":"mcm","clk":"1009458941","pt":1580644541486,"mc":[{"id":"1.168217557","rc":[{"batb":[[1,1.01,10.51],[2,1.67,0]],"batl":[[0,2.42,286.52],[1,2.2,0],[2,2.42,0]],"ltp":1.58,"tv":340.68,"id":2263624}]}]}
{"op":"mcm","clk":"1009459229","pt":1580644544509,"mc":[{"id":"1.168217557","rc":[{"batb":[[0,1.85,145.27],[1,1.83,167.82],[2,1.81,19.43]],"batl":[[0,1.93,127.44],[1,1.95,139.76]],"ltp":1.96,"tv":42.0,"id":7412809}]}]}
{"op":"mcm","clk":"1009459332","pt":1580644545504,"mc":[{"id":"1.168217557","rc":[{"batb":[[0,2.08,24.78],[1,1.96,43.69],[2,1.87,17.39]],"ltp":1.58,"tv":340.68,"id":2263624},{"batl":[[2,2.04,40.33]],"ltp":1.96,"tv":42.0,"id":7412809}]}]}
{"op":"mcm","clk":"1009459449","pt":1580644546660,"mc":[{"id":"1.168217557","rc":[{"batl":[[0,2.72,241.55]],"ltp":1.58,"tv":340.68,"id":2263624}]}]}
{"op":"mcm","clk":"1009459617","pt":1580644548187,"mc":[{"id":"1.168217557","rc":[{"batl":[[0,2.16,36.13],[1,2.72,241.55]],"ltp":1.58,"tv":340.68,"id":2263624},{"batb":[[0,1.85,194]],"ltp":1.96,"tv":42.0,"id":7412809}]}]}
{"op":"mcm","clk":"1009461202","pt":1580644562609,"mc":[{"id":"1.168217557","rc":[{"trd":[[2.08,4.54]],"batb":[[0,2.08,22.51]],"ltp":2.08,"tv":345.22,"id":2263624}],"tv":387.23}]}
{"op":"mcm","clk":"1009461658","pt":1580644566423,"mc":[{"id":"1.168217557","rc":[{"batb":[[0,1.96,43.69],[1,1.87,17.39],[2,1.01,10.51]],"ltp":2.08,"tv":345.22,"id":2263624},{"batb":[[0,1.85,48.73],[1,1.49,38.48],[2,1.01,10.52]],"batl":[[0,2.04,40.33],[1,2.5,274.54],[2,2.04,0]],"ltp":1.96,"tv":42.0,"id":7412809}]}]}
{"op":"mcm","clk":"1009461843","pt":1580644567844,"mc":[{"id":"1.168217557","rc":[{"batb":[[0,1.87,17.39],[1,1.01,10.51],[2,1.01,0]],"batl":[[0,2.72,241.55],[1,2.72,0]],"ltp":2.08,"tv":345.22,"id":2263624},{"batb":[[0,1.49,38.48],[1,1.01,10.52],[2,1.01,0]],"batl":[[0,2.5,274.54],[1,2.5,0]],"ltp":1.96,"tv":42.0,"id":7412809}]}]}
{"op":"mcm","clk":"1009462052","pt":1580644569428,"mc":[{"id":"1.168217557","rc":[{"batb":[[1,1.86,17.7],[2,1.01,10.51]],"ltp":2.08,"tv":345.22,"id":2263624},{"batb":[[0,1.53,157.33],[1,1.52,162.99],[2,1.5,37.77]],"batl":[[0,2.18,102.95],[1,2.2,98.62],[2,2.5,274.54]],"ltp":1.96,"tv":42.0,"id":7412809}]}]}
{"op":"mcm","clk":"1009462080","pt":1580644569634,"mc":[{"id":"1.168217557","rc":[{"batb":[[0,1.86,17.7],[1,1.01,10.51],[2,1.01,0]],"ltp":2.08,"tv":345.22,"id":2263624}]}]}
{"op":"mcm","clk":"1009462477","pt":1580644573216,"mc":[{"id":"1.168217557","rc":[{"batb":[[0,1.5,37.77],[1,1.01,10.52],[2,1.5,0]],"batl":[[0,2.5,274.54],[1,2.2,0],[2,2.5,0]],"ltp":1.96,"tv":42.0,"id":7412809}]}]}
{"op":"mcm","clk":"1009462889","pt":1580644576442,"mc":[{"id":"1.168217557","rc":[{"batb":[[1,1.84,183.99],[2,1.82,171.13]],"batl":[[0,1.93,171.2],[1,1.95,140]],"ltp":2.08,"tv":345.22,"id":2263624},{"batb":[[0,2.02,27.3],[1,1.67,25.34],[2,1.5,37.77]],"ltp":1.96,"tv":42.0,"id":7412809}]}]}
{"op":"mcm","clk":"1009462964","pt":1580644577024,"mc":[{"id":"1.168217557","rc":[{"batb":[[2,1.01,10.52]],"batl":[[0,2.28,32.77]],"ltp":1.96,"tv":42.0,"id":7412809}]}]}
{"op":"mcm","clk":"1009463110","pt":1580644578082,"mc":[{"id":"1.168217557","rc":[{"batl":[[2,2.42,286.52]],"ltp":2.08,"tv":345.22,"id":2263624},{"batl":[[1,2.82,231.28]],"ltp":1.96,"tv":42.0,"id":7412809}]}]}
{"op":"mcm","clk":"1009464122","pt":1580644586865,"mc":[{"id":"1.168217557","rc":[{"batb":[[1,1.84,127.48]],"batl":[[0,2.42,286.52],[1,1.95,0],[2,2.42,0]],"ltp":2.08,"tv":345.22,"id":2263624}]}]}
{"op":"mcm","clk":"1009464537","pt":1580644590485,"mc":[{"id":"1.168217557","rc":[{"batb":[[0,1.69,24.31],[1,1.01,10.51],[2,1.82,0]],"ltp":2.08,"tv":345.22,"id":2263624},{"batb":[[0,1.67,25.34],[1,1.01,10.52],[2,1.01,0]],"batl":[[0,2.82,231.28],[1,2.82,0]],"ltp":1.96,"tv":42.0,"id":7412809}]}]}
{"op":"mcm","clk":"1009464852","pt":1580644593146,"mc":[{"id":"1.168217557","rc":[{"batb":[[0,1.68,24.94]],"ltp":2.08,"tv":345.22,"id":2263624},{"batb":[[0,1.68,24.78]],"ltp":1.96,"tv":42.0,"id":7412809}]}]}
{"op":"mcm","clk":"1009465182","pt":1580644596453,"mc":[{"id":"1.168217557","rc":[{"batb":[[0,1.91,156.42],[1,1.89,151.52],[2,1.68,24.94]],"batl":[[0,2,136.86],[1,2.02,126.03],[2,2.42,286.52]],"ltp":2.08,"tv":345.22,"id":2263624}]}]}
{"op":"mcm","clk":"1009465812","pt":1580644602079,"mc":[{"id":"1.168217557","rc":[{"batb":[[0,1.68,24.94],[1,1.01,10.51],[2,1.68,0]],"batl":[[0,2.42,286.52],[1,2.02,0],[2,2.42,0]],"ltp":2.08,"tv":345.22,"id":2263624}]}]}
{"op":"mcm","clk":"1009466511","pt":1580644608474,"mc":[{"id":"1.168217557","rc":[{"batb":[[0,2.28,19.12],[1,1.87,17.39],[2,1.01,10.51]],"ltp":2.08,"tv":345.22,"id":2263624},{"batb":[[0,1.71,153.91],[1,1.69,218.93],[2,1.68,24.78]],"batl":[[0,1.78,169.44],[1,1.8,178.84]],"ltp":1.96,"tv":42.0,"id":7412809}]}]}
{"op":"mcm","clk":"1009466586","pt":1580644609160,"mc":[{"id":"1.168217557","rc":[{"batb":[[1,2.14,36.13],[2,1.87,17.39]],"batl":[[0,2.38,30.25]],"ltp":2.08,"tv":345.22,"id":2263624},{"batb":[[0,1.72,57.97],[1,1.71,153.91],[2,1.69,218.93]],"batl":[[2,1.88,42.01]],"ltp":1.96,"tv":42.0,"id":7412809}]}]}
{"op":"mcm","clk":"1009466695","pt":1580644610255,"mc":[{"id":"1.168217557","rc":[{"batl":[[1,3,213.45]],"ltp":2.08,"tv":345.22,"id":2263624}]}]}
{"op":"mcm","clk":"1009468135","pt":1580644623440,"mc":[{"id":"1.168217557","rc":[{"batb":[[1,1.68,24.78],[2,1.27,81.37]],"batl":[[0,1.88,42.01],[1,2.3,309.75],[2,1.88,0]],"ltp":1.96,"tv":42.0,"id":7412809}]}]}
{"op":"mcm","clk":"1009468212","pt":1580644624199,"mc":[{"id":"1.168217557","rc":[{"batb":[[0,1.87,17.39],[1,1.01,10.51],[2,1.87,0]],"batl":[[0,3,213.45],[1,3,0]],"ltp":2.08,"tv":345.22,"id":2263624},{"batb":[[0,1.27,80.58],[1,1.01,10.51],[2,1.27,0]],"batl":[[0,2.3,309.75],[1,2.3,0]],"ltp":1.96,"tv":42.0,"id":7412809}]}]}
{"op":"mcm","clk":"1009468425","pt":1580644626390,"mc":[{"id":"1.168217557","rc":[{"batb":[[0,1.29,262.67],[1,1.28,362.14],[2,1.27,80.57]],"batl":[[0,2.18,178.25],[1,2.2,98.73]],"ltp":1.96,"tv":42.0,"id":7412809}]}]}
{"op":"mcm","clk":"1009468562","pt":1580644627389,"mc":[{"id":"1.168217557","rc":[{"batb":[[0,1.27,80.58],[1,1.01,10.51],[2,1.27,0]],"ltp":1.96,"tv":42.0,"id":7412809}]}]}
{"op":"mcm","clk":"1009468762","pt":1580644629033,"mc":[{"id":"1.168217557","rc":[{"batb":[[0,1.6,245.44],[1,1.59,137.44],[2,1.27,80.58]],"batl":[[0,1.67,227.48],[1,1.69,219.61]],"ltp":1.96,"tv":42.0,"id":7412809}]}]}
{"op":"mcm","clk":"1009468934","pt":1580644630583,"mc":[{"id":"1.168217557","rc":[{"batl":[[0,3.45,180.4]],"ltp":2.08,"tv":345.22,"id":2263624},{"batl":[[2,2.1,363.31]],"ltp":1.96,"tv":42.0,"id":7412809}]}]}
{"op":"mcm","clk":"1009469107","pt":1580644632628,"mc":[{"id":"1.168217557","rc":[{"batb":[[0,1.27,80.58],[1,1.01,10.51],[2,1.27,0]],"batl":[[0,2.1,363.31],[1,1.69,0],[2,2.1,0]],"ltp":1.96,"tv":42.0,"id":7412809}]}]}
{"op":"mcm","clk":"1009469493","pt":1580644635930,"mc":[{"id":"1.168217557","rc":[{"batb":[[0,1.29,264.85],[1,1.28,362.16],[2,1.27,80.57]],"ltp":1.96,"tv":42.0,"id":7412809}]}]}
{"op":"mcm","clk":"1009469752","pt":1580644638506,"mc":[{"id":"1.168217557","rc":[{"batb":[[0,1.92,342.94],[1,1.87,17.39],[2,1.01,10.51]],"ltp":2.08,"tv":345.22,"id":2263624},{"trd":[[1.48,0.02]],"batb":[[0,1.29,264.84]],"batl":[[0,1.32,206.02],[1,1.33,285.14]],"ltp":1.48,"tv":42.02,"id":7412809}],"tv":387.25}]}
{"op":"mcm","clk":"1009469841","pt":1580644639451,"mc":[{"id":"1.168217557","rc":[{"trd":[[4.1,13.44]],"batb":[[0,4,21.95],[1,3.15,19.91]],"ltp":4.1,"tv":358.66,"id":2263624},{"trd":[[1.32,303.9]],"batl":[[0,1.33,285.14],[1,1.33,0]],"ltp":1.32,"tv":345.93,"id":7412809}],"tv":704.59}]}
{"op":"mcm","clk":"1009470092","pt":1580644641434,"mc":[{"id":"1.168217557","rc":[{"batb":[[1,3.7,15.12],[2,3.15,19.91]],"batl":[[0,6,106.18]],"ltp":4.1,"tv":358.66,"id":2263624},{"batl":[[1,1.37,42.01],[2,1.66,579.81]],"ltp":1.32,"tv":345.93,"id":7412809}]}]}
{"op":"mcm","clk":"1009470186","pt":1580644642330,"mc":[{"id":"1.168217557","rc":[{"batl":[[0,4.3,12.6],[1,6,106.18]],"ltp":4.1,"tv":358.66,"id":2263624},{"batb":[[0,1.3,139.47],[1,1.29,345.54],[2,1.28,362.16]],"batl":[[0,1.33,411.71],[1,1.34,270.38],[2,1.37,42.01]],"ltp":1.32,"tv":345.93,"id":7412809}]}]}
{"op":"mcm","clk":"1009471150","pt":1580644651264,"mc":[{"id":"1.168217557","rc":[{"batl":[[0,1.33,285.17],[1,1.37,42.01],[2,1.66,579.81]],"ltp":1.32,"tv":345.93,"id":7412809}]}]}
{"op":"mcm","clk":"1009471278","pt":1580644652519,"mc":[{"id":"1.168217557","rc":[{"batb":[[1,1.29,316.77]],"ltp":1.32,"tv":345.93,"id":7412809}]}]}
{"op":"mcm","clk":"1009471466","pt":1580644654253,"mc":[{"id":"1.168217557","rc":[{"batl":[[0,1.32,151.83],[1,1.33,285.17],[2,1.37,42.01]],"ltp":1.32,"tv":345.93,"id":7412809}]}]}
{"op":"mcm","clk":"1009472184","pt":1580644661268,"mc":[{"id":"1.168217557","rc":[{"trd":[[1.3,52.74]],"batb":[[0,1.3,113.1]],"ltp":1.3,"tv":398.66,"id":7412809}],"tv":757.33}]}
{"op":"mcm","clk":"1009472230","pt":1580644661648,"mc":[{"id":"1.168217557","rc":[{"batb":[[1,1.29,272.44]],"ltp":1.3,"tv":398.66,"id":7412809}]}]}
{"op":"mcm","clk":"1009472549","pt":1580644664485,"mc":[{"id":"1.168217557","rc":[{"batl":[[0,1.32,199.07]],"ltp":1.3,"tv":398.66,"id":7412809}]}]}
{"op":"mcm","clk":"1009472559","pt":1580644664576,"mc":[{"id":"1.168217557","rc":[{"batb":[[0,1.3,139.14]],"ltp":1.3,"tv":398.66,"id":7412809}]}]}
{"op":"mcm","clk":"1009473203","pt":1580644670385,"mc":[{"id":"1.168217557","rc":[{"batb":[[0,3.7,15.12],[1,3.15,19.91],[2,1.01,10.51]],"ltp":4.1,"tv":358.66,"id":2263624},{"batb":[[1,1.21,106.14],[2,1.01,10.51]],"batl":[[0,1.37,42.01],[1,1.66,579.81],[2,1.37,0]],"ltp":1.3,"tv":398.66,"id":7412809}]}]}
{"op":"mcm","clk":"1009473358","pt":1580644671854,"mc":[{"id":"1.168217557","rc":[{"batb":[[0,3.15,19.91],[1,1.01,10.51],[2,1.01,0]],"batl":[[0,6,106.18],[1,6,0]],"ltp":4.1,"tv":358.66,"id":2263624},{"batb":[[0,1.21,106.14],[1,1.01,10.51],[2,1.01,0]],"batl":[[0,1.66,579.81],[1,1.66,0]],"ltp":1.3,"tv":398.66,"id":7412809}]}]}
{"op":"mcm","clk":"1009473520","pt":1580644673476,"mc":[{"id":"1.168217557","rc":[{"batb":[[0,1.23,362.5],[1,1.22,487.38],[2,1.21,106.14]],"batl":[[0,1.45,250.35],[1,1.46,187.29],[2,1.66,579.81]],"ltp":1.3,"tv":398.66,"id":7412809}]}]}
{"op":"mcm","clk":"1009473714","pt":1580644675047,"mc":[{"id":"1.168217557","rc":[{"batb":[[0,1.21,106.14],[1,1.01,10.51],[2,1.21,0]],"batl":[[0,1.66,579.81],[1,1.46,0],[2,1.66,0]],"ltp":1.3,"tv":398.66,"id":7412809}]}]}
{"op":"mcm","clk":"1009474050","pt":1580644678271,"mc":[{"id":"1.168217557","rc":[{"batb":[[0,1.31,313.05],[1,1.3,333.79],[2,1.21,106.14]],"batl":[[0,1.35,364.38],[1,1.36,253.78],[2,1.66,579.81]],"ltp":1.3,"tv":398.66,"id":7412809}]}]}
{"op":"mcm","clk":"1009474253","pt":1580644680253,"mc":[{"id":"1.168217557","rc":[{"trd":[[1.31,10.61]],"batb":[[0,1.31,307.74]],"ltp":1.31,"tv":409.28,"id":7412809}],"tv":767.94}]}
{"op":"mcm","clk":"1009474403","pt":1580644681453,"mc":[{"id":"1.168217557","rc":[{"batb":[[0,1.21,106.14],[1,1.01,10.51],[2,1.21,0]],"batl":[[0,1.66,579.81],[1,1.36,0],[2,1.66,0]],"ltp":1.31,"tv":409.28,"id":7412809}]}]}
{"op":"mcm","clk":"1009474726","pt":1580644684383,"mc":[{"id":"1.168217557","rc":[{"batb":[[0,1.23,351.95],[1,1.22,487.36],[2,1.21,106.14]],"batl":[[0,1.45,259.29],[1,1.46,187.32],[2,1.66,579.81]],"ltp":1.31,"tv":409.28,"id":7412809}]}]}
{"op":"mcm","clk":"1009474936","pt":1580644686164,"mc":[{"id":"1.168217557","rc":[{"batl":[[0,1.66,579.81],[1,1.46,0],[2,1.66,0]],"ltp":1.31,"tv":409.28,"id":7412809}]}]}
{"op":"mcm","clk":"1009475314","pt":1580644689357,"mc":[{"id":"1.168217557","rc":[{"batb":[[0,1.23,303.89]],"batl":[[0,1.26,383.46],[1,1.27,359.73]],"ltp":1.31,"tv":409.28,"id":7412809}]}]}
{"op":"mcm","clk":"1009475392","pt":1580644689980,"mc":[{"id":"1.168217557","rc":[{"batb":[[0,4.8,14.56],[1,3.8,25.65],[2,1.01,10.51]],"ltp":4.1,"tv":358.66,"id":2263624}]}]}
{"op":"mcm","clk":"1009475542","pt":1580644690908,"mc":[{"id":"1.168217557","rc":[{"batl":[[0,5.1,10.08]],"ltp":4.1,"tv":358.66,"id":2263624},{"batb":[[0,1.24,168.04],[1,1.23,303.89],[2,1.22,487.36]],"ltp":1.31,"tv":409.28,"id":7412809}]}]}
{"op":"mcm","clk":"1009475749","pt":1580644692476,"mc":[{"id":"1.168217557","rc":[{"batl":[[1,7.8,87.91]],"ltp":4.1,"tv":358.66,"id":2263624},{"batl":[[0,1.26,430.51],[2,1.56,675.59]],"ltp":1.31,"tv":409.28,"id":7412809}]}]}
{"op":"mcm","clk":"1009476009","pt":1580644694792,"mc":[{"id":"1.168217557","rc":[{"batb":[[1,1.23,262.15]],"ltp":1.31,"tv":409.28,"id":7412809}]}]}
{"op":"mcm","clk":"1009476399","pt":1580644698492,"mc":[{"id":"1.168217557","rc":[{"batl":[[0,1.26,471.41]],"ltp":1.31,"tv":409.28,"id":7412809}]}]}
{"op":"mcm","clk":"1009477542","pt":1580644708406,"mc":[{"id":"1.168217557","rc":[{"batb":[[0,3.8,25.65],[1,1.01,10.51],[2,1.01,0]],"ltp":4.1,"tv":358.66,"id":2263624},{"batb":[[1,1.17,136.67],[2,1.01,10.51]],"batl":[[0,1.56,675.59],[1,1.27,0],[2,1.56,0]],"ltp":1.31,"tv":409.28,"id":7412809}]}]}
{"op":"mcm","clk":"1009477718","pt":1580644710019,"mc":[{"id":"1.168217557","rc":[{"batl":[[0,7.8,87.91],[1,7.8,0]],"ltp":4.1,"tv":358.66,"id":2263624},{"batb":[[0,1.17,136.67],[1,1.01,10.51],[2,1.01,0]],"ltp":1.31,"tv":409.28,"id":7412809}]}]}
{"op":"mcm","clk":"1009477850","pt":1580644711327,"mc":[{"id":"1.168217557","rc":[{"batb":[[0,1.19,213.12],[1,1.18,614.74],[2,1.17,136.67]],"batl":[[0,1.34,187.5],[1,1.35,266.97],[2,1.56,675.59]],"ltp":1.31,"tv":409.28,"id":7412809}]}]}
{"op":"mcm","clk":"1009477937","pt":1580644712006,"mc":[{"id":"1.168217557","rc":[{"batb":[[0,1.17,136.67],[1,1.01,10.51],[2,1.17,0]],"batl":[[0,1.56,675.59],[1,1.35,0],[2,1.56,0]],"ltp":1.31,"tv":409.28,"id":7412809}]}]}
{"op":"mcm","clk":"1009478303","pt":1580644715503,"mc":[{"id":"1.168217557","rc":[{"batb":[[0,1.24,482.15],[1,1.23,468.12],[2,1.17,136.67]],"batl":[[0,1.27,219.43],[1,1.28,349.93],[2,1.56,675.59]],"ltp":1.31,"tv":409.28,"id":7412809}]}]}
{"op":"mcm","clk":"1009478438","pt":1580644716911,"mc":[{"id":"1.168217557","rc":[{"batl":[[0,7.2,92.18]],"ltp":4.1,"tv":358.66,"id":2263624}]}]}
{"op":"mcm","clk":"1009478668","pt":1580644719408,"mc":[{"id":"1.168217557","rc":[{"batb":[[0,1.17,136.67],[1,1.01,10.51],[2,1.17,0]],"batl":[[0,1.56,675.59],[1,1.28,0],[2,1.56,0]],"ltp":1.31,"tv":409.28,"id":7412809}]}]}
{"op":"mcm","clk":"1009478980","pt":1580644722433,"mc":[{"id":"1.168217557","rc":[{"batb":[[0,1.19,200.67],[1,1.18,614.72],[2,1.17,136.67]],"batl":[[0,1.34,198.43],[1,1.35,266.99],[2,1.56,675.59]],"ltp":1.31,"tv":409.28,"id":7412809}]}]}
{"op":"mcm","clk":"1009480295","pt":1580644735235,"mc":[{"id":"1.168217557","rc":[{"trd":[[1.19,373.04]],"batb":[[0,1.19,14.15]],"ltp":1.19,"tv":782.32,"id":7412809}],"tv":1140.99}]}
{"op":"mcm","clk":"1009480337","pt":1580644735754,"mc":[{"id":"1.168217557","rc":[{"batb":[[0,1.18,614.72],[1,1.17,136.67],[2,1.01,10.51]],"ltp":1.19,"tv":782.32,"id":7412809}]}]}
{"op":"mcm","clk":"1009480677","pt":1580644739046,"mc":[{"id":"1.168217557","rc":[{"batb":[[0,1.17,136.67],[1,1.01,10.51],[2,1.01,0]],"batl":[[0,1.34,265.37]],"ltp":1.19,"tv":782.32,"id":7412809}]}]}
{"op":"mcm","clk":"1009481125","pt":1580644742448,"mc":[{"id":"1.168217557","rc":[{"batb":[[1,2.9,25.41],[2,1.01,10.51]],"ltp":4.1,"tv":358.66,"id":2263624},{"batb":[[0,1.3,551.2],[1,1.29,354.65],[2,1.22,101.34]],"ltp":1.19,"tv":782.32,"id":7412809}]}]}
{"op":"mcm","clk":"1009481196","pt":1580644742970,"mc":[{"id":"1.168217557","rc":[{"batl":[[0,4.2,12.6]],"ltp":4.1,"tv":358.66,"id":2263624},{"batb":[[0,1.31,135.27],[1,1.3,551.2],[2,1.29,354.65]],"ltp":1.19,"tv":782.32,"id":7412809}]}]}
{"op":"mcm","clk":"1009481355","pt":1580644744128,"mc":[{"id":"1.168217557","rc":[{"batl":[[1,6.6,98.95]],"ltp":4.1,"tv":358.66,"id":2263624}]}]}
{"op":"mcm","clk":"1009483732","pt":1580644765214,"mc":[{"id":"1.168217557","rc":[{"batb":[[0,2.9,25.41],[1,1.01,10.51],[2,1.01,0]],"ltp":4.1,"tv":358.66,"id":2263624},{"batb":[[1,1.22,101.34],[2,1.01,10.51]],"batl":[[0,1.56,675.59],[1,1.35,0],[2,1.56,0]],"ltp":1.19,"tv":782.32,"id":7412809}]}]}
{"op":"mcm","clk":"1009483836","pt":1580644766096,"mc":[{"id":"1.168217557","rc":[{"batl":[[0,6.6,98.95],[1,6.6,0]],"ltp":4.1,"tv":358.66,"id":2263624},{"batb":[[0,1.22,101.34],[1,1.01,10.51],[2,1.01,0]],"ltp":1.19,"tv":782.32,"id":7412809}]}]}
{"op":"mcm","clk":"1009484084","pt":1580644768298,"mc":[{"id":"1.168217557","rc":[{"batb":[[0,1.23,398.87],[1,1.22,595.07],[2,1.01,10.51]],"batl":[[0,1.5,158.86],[1,1.51,166.01],[2,1.56,675.59]],"ltp":1.19,"tv":782.32,"id":7412809}]}]}
{"op":"mcm","clk":"1009484337","pt":1580644770569,"mc":[{"id":"1.168217557","rc":[{"batb":[[0,1.22,101.34],[1,1.01,10.51],[2,1.01,0]],"batl":[[0,1.56,675.59],[1,1.51,0],[2,1.56,0]],"ltp":1.19,"tv":782.32,"id":7412809}]}]}
{"op":"mcm","clk":"1009484728","pt":1580644773474,"mc":[{"id":"1.168217557","rc":[{"batb":[[0,1.33,364.18],[1,1.32,311.89],[2,1.22,101.34]],"batl":[[0,1.37,256.3],[1,1.38,241.23],[2,1.56,675.59]],"ltp":1.19,"tv":782.32,"id":7412809}]}]}
{"op":"mcm","clk":"1009485077","pt":1580644776269,"mc":[{"id":"1.168217557","rc":[{"batl":[[0,6,106.18]],"ltp":4.1,"tv":358.66,"id":2263624}]}]}
{"op":"mcm","clk":"1009485574","pt":1580644780606,"mc":[{"id":"1.168217557","rc":[{"batb":[[0,1.22,101.34],[1,1.01,10.51],[2,1.22,0]],"batl":[[0,1.56,675.59],[1,1.38,0],[2,1.56,0]],"ltp":1.19,"tv":782.32,"id":7412809}]}]}
{"op":"mcm","clk":"1009485939","pt":1580644783600,"mc":[{"id":"1.168217557","rc":[{"batb":[[0,1.23,398.87],[1,1.22,595.07],[2,1.01,10.51]],"batl":[[0,1.5,158.86],[1,1.51,166.01],[2,1.56,675.59]],"ltp":1.19,"tv":782.32,"id":7412809}]}]}
{"op":"mcm","clk":"1009486578","pt":1580644789024,"mc":[{"id":"1.168217557","rc":[{"batb":[[0,1.22,101.34],[1,1.01,10.51],[2,1.01,0]],"ltp":1.19,"tv":782.32,"id":7412809}]}]}
{"op":"mcm","clk":"1009486825","pt":1580644791026,"mc":[{"id":"1.168217557","rc":[{"batl":[[2,1.56,0]],"ltp":1.19,"tv":782.32,"id":7412809}]}]}
{"op":"mcm","clk":"1009486956","pt":1580644792228,"mc":[{"id":"1.168217557","rc":[{"batb":[[0,1.46,133.5],[1,1.45,199.07],[2,1.22,101.34]],"ltp":1.19,"tv":782.32,"id":7412809}]}]}
{"op":"mcm","clk":"1009487067","pt":1580644793226,"mc":[{"id":"1.168217557","rc":[{"batb":[[1,2.18,21.64],[2,1.01,10.51]],"ltp":4.1,"tv":358.66,"id":2263624},{"batb":[[1,1.45,241.87],[2,1.32,65.38]],"ltp":1.19,"tv":782.32,"id":7412809}]}]}
{"op":"mcm","clk":"1009487207","pt":1580644794424,"mc":[{"id":"1.168217557","rc":[{"batl":[[0,4.9,126.27]],"ltp":4.1,"tv":358.66,"id":2263624}]}]}
{"op":"mcm","clk":"1009487314","pt":1580644795319,"mc":[{"id":"1.168217557","rc":[{"batl":[[2,1.77,500.61]],"ltp":1.19,"tv":782.32,"id":7412809}]}]}
{"op":"mcm","clk":"1009488274","pt":1580644802350,"mc":[{"id":"1.168217557","rc":[{"batb":[[0,1.45,241.87],[1,1.32,65.38],[2,1.01,10.51]],"ltp":1.19,"tv":782.32,"id":7412809}]}]}
{"op":"mcm","clk":"1009488844","pt":1580644805342,"mc":[{"id":"1.168217557","rc":[{"batb":[[0,1.45,303.42],[1,1.44,206.76],[2,1.32,65.38]],"batl":[[0,1.5,229.51]],"ltp":1.19,"tv":782.32,"id":7412809}]}]}
{"op":"mcm","clk":"1009489034","pt":1580644806717,"mc":[{"id":"1.168217557","rc":[{"batl":[[0,3.25,18.48],[1,4.9,126.27]],"ltp":4.1,"tv":358.66,"id":2263624},{"batb":[[1,1.44,301.7]],"ltp":1.19,"tv":782.32,"id":7412809}]}]}
{"op":"mcm","clk":"1009489740","pt":1580644811436,"mc":[{"id":"1.168217557","rc":[{"trd":[[1.5,26.52]],"batl":[[0,1.5,216.25]],"ltp":1.5,"tv":808.84,"id":7412809}],"tv":1167.51}]}
{"op":"mcm","clk":"1009490289","pt":1580644815474,"mc":[{"id":"1.168217557","rc":[{"batb":[[0,1.45,42.8],[1,1.44,94.94]],"batl":[[0,1.77,500.61],[1,1.51,0],[2,1.77,0]],"ltp":1.5,"tv":808.84,"id":7412809}]}]}
{"op":"mcm","clk":"1009490364","pt":1580644815961,"mc":[{"id":"1.168217557","rc":[{"batb":[[0,2.18,21.64],[1,1.01,10.51],[2,1.01,0]],"batl":[[0,4.9,126.27],[1,4.9,0]],"ltp":4.1,"tv":358.66,"id":2263624},{"batb":[[0,1.32,65.38],[1,1.01,10.51],[2,1.32,0]],"ltp":1.5,"tv":808.84,"id":7412809}]}]}
{"op":"mcm","clk":"1009490692","pt":1580644818470,"mc":[{"id":"1.168217557","rc":[{"batb":[[0,1.32,517.57],[1,1.31,327.03],[2,1.01,10.51]],"batl":[[1,1.8,192.52],[2,1.82,174.35]],"ltp":1.5,"tv":808.84,"id":7412809}]}]}
{"op":"mcm","clk":"1009490754","pt":1580644818947,"mc":[{"id":"1.168217557","rc":[{"batb":[[0,2.2,21.32]],"ltp":4.1,"tv":358.66,"id":2263624}]}]}
{"op":"mcm","clk":"1009491740","pt":1580644827359,"mc":[{"id":"1.168217557","rc":[{"batl":[[1,1.8,0],[2,1.82,0]],"ltp":1.5,"tv":808.84,"id":7412809}]}]}
{"op":"mcm","clk":"1009492112","pt":1580644830491,"mc":[{"id":"1.168217557","rc":[{"batl":[[0,1.36,214.91],[1,1.37,250.87]],"ltp":1.5,"tv":808.84,"id":7412809}]}]}
{"op":"mcm","clk":"1009492239","pt":1580644831475,"mc":[{"id":"1.168217557","rc":[{"batb":[[0,3.65,14.24],[1,2.6,13.53],[2,1.01,10.51]],"batl":[[0,4,13.44]],"ltp":4.1,"tv":358.66,"id":2263624},{"batb":[[0,1.33,126.87],[1,1.32,517.57],[2,1.31,327.03]],"ltp":1.5,"tv":808.84,"id":7412809}]}]}
{"op":"mcm","clk":"1009492409","pt":1580644832952,"mc":[{"id":"1.168217557","rc":[{"batl":[[1,6,106.18]],"ltp":4.1,"tv":358.66,"id":2263624},{"batl":[[2,1.66,579.81]],"ltp":1.5,"tv":808.84,"id":7412809}]}]}
{"op":"mcm","clk":"1009495150","pt":1580644853506,"mc":[{"id":"1.168217557","rc":[{"batb":[[1,1.32,65.38],[2,1.22,104.73]],"batl":[[0,1.66,579.81],[1,1.37,0],[2,1.66,0]],"ltp":1.5,"tv":808.84,"id":7412809}]}]}
{"op":"mcm","clk":"1009495257","pt":1580644854194,"mc":[{"id":"1.168217557","rc":[{"batb":[[0,2.6,13.53],[1,1.01,10.51],[2,1.01,0]],"batl":[[0,6,106.18],[1,6,0]],"ltp":4.1,"tv":358.66,"id":2263624},{"batb":[[0,1.22,104.73],[1,1.01,10.51],[2,1.22,0]],"ltp":1.5,"tv":808.84,"id":7412809}]}]}
{"op":"mcm","clk":"1009495572","pt":1580644856525,"mc":[{"id":"1.168217557","rc":[{"batb":[[0,1.22,550.2],[1,1.21,525.15],[2,1.01,10.51]],"batl":[[0,1.6,159.03],[1,1.61,131.02],[2,1.66,579.81]],"ltp":1.5,"tv":808.84,"id":7412809}]}]}
{"op":"mcm","clk":"1009499420","pt":1580644885956,"mc":[{"id":"1.168217557","rc":[{"batb":[[0,1.22,104.73],[1,1.01,10.51],[2,1.01,0]],"ltp":1.5,"tv":808.84,"id":7412809}]}]}
{"op":"mcm","clk":"1009499930","pt":1580644889442,"mc":[{"id":"1.168217557","rc":[{"batb":[[1,1.81,19.28],[2,1.01,10.51]],"batl":[[0,2.94,21]],"ltp":4.1,"tv":358.66,"id":2263624},{"batb":[[0,1.55,181.82],[1,1.54,156.43],[2,1.52,80.66]],"batl":[[2,1.66,0]],"ltp":1.5,"tv":808.84,"id":7412809}]}]}
{"op":"mcm","clk":"1009500342","pt":1580644892361,"mc":[{"id":"1.168217557","rc":[{"batl":[[1,3.9,158.24]],"ltp":4.1,"tv":358.66,"id":2263624},{"batl":[[2,1.95,409.86]],"ltp":1.5,"tv":808.84,"id":7412809}]}]}
{"op":"mcm","clk":"1009504089","pt":1580644918193,"mc":[{"id":"1.168217557","rc":[{"batb":[[0,1.81,19.28],[1,1.01,10.51],[2,1.01,0]],"batl":[[0,3.9,158.24],[1,3.9,0]],"ltp":4.1,"tv":358.66,"id":2263624},{"batb":[[0,1.33,62.71],[1,1.01,10.51],[2,1.52,0]],"batl":[[0,1.95,409.86],[1,1.61,0],[2,1.95,0]],"ltp":1.5,"tv":808.84,"id":7412809}]}]}
{"op":"mcm","clk":"1009504899","pt":1580644923096,"mc":[{"id":"1.168217557","rc":[{"batb":[[0,1.63,211.98],[1,1.62,129.51],[2,1.33,62.71]],"batl":[[0,1.69,113.87],[1,1.71,214.1]],"ltp":1.5,"tv":808.84,"id":7412809}]}]}
{"op":"mcm","clk":"1009505132","pt":1580644924646,"mc":[{"id":"1.168217557","rc":[{"batl":[[0,3.65,170.41]],"ltp":4.1,"tv":358.66,"id":2263624},{"batl":[[2,2.04,383.01]],"ltp":1.5,"tv":808.84,"id":7412809}]}]}
{"op":"mcm","clk":"1009505872","pt":1580644929526,"mc":[{"id":"1.168217557","rc":[{"batb":[[0,1.33,62.71],[1,1.01,10.51],[2,1.33,0]],"batl":[[0,2.04,383.01],[1,1.71,0],[2,2.04,0]],"ltp":1.5,"tv":808.84,"id":7412809}]}]}
{"op":"mcm","clk":"1009506326","pt":1580644932516,"mc":[{"id":"1.168217557","rc":[{"batb":[[0,1.33,435.53],[1,1.32,313.06],[2,1.01,10.51]],"batl":[[1,2.2,104.31],[2,2.22,96.96]],"ltp":1.5,"tv":808.84,"id":7412809}]}]}
{"op":"mcm","clk":"1009506602","pt":1580644934320,"mc":[{"id":"1.168217557","rc":[{"batb":[[0,1.33,62.71],[1,1.01,10.51],[2,1.01,0]],"batl":[[1,2.2,0],[2,2.22,0]],"ltp":1.5,"tv":808.84,"id":7412809}]}]}
{"op":"mcm","clk":"1009507070","pt":1580644937293,"mc":[{"id":"1.168217557","rc":[{"batb":[[0,1.83,153.9],[1,1.81,194.91],[2,1.01,10.51]],"batl":[[0,1.91,141.74],[1,1.93,145.64]],"ltp":4.1,"tv":358.66,"id":2263624}]}]}
{"op":"mcm","clk":"1009507181","pt":1580644937990,"mc":[{"id":"1.168217557","rc":[{"batb":[[2,1.69,24]],"ltp":4.1,"tv":358.66,"id":2263624},{"batb":[[0,2.08,25.1],[1,1.82,18.96],[2,1.01,10.51]],"ltp":1.5,"tv":808.84,"id":7412809}]}]}
{"op":"mcm","clk":"1009507349","pt":1580644939104,"mc":[{"id":"1.168217557","rc":[{"batl":[[2,2.02,41.17]],"ltp":4.1,"tv":358.66,"id":2263624},{"batb":[[1,1.98,42.85],[2,1.82,18.96]],"ltp":1.5,"tv":808.84,"id":7412809}]}]}
{"op":"mcm","clk":"1009507433","pt":1580644939693,"mc":[{"id":"1.168217557","rc":[{"batl":[[0,2.6,257.57]],"ltp":1.5,"tv":808.84,"id":7412809}]}]}
{"op":"mcm","clk":"1009509880","pt":1580644956813,"mc":[{"id":"1.168217557","rc":[{"batb":[[0,1.83,121.34]],"ltp":4.1,"tv":358.66,"id":2263624}]}]}
{"op":"mcm","clk":"1009510303","pt":1580644959856,"mc":[{"id":"1.168217557","rc":[{"batl":[[0,1.91,172.96]],"ltp":4.1,"tv":358.66,"id":2263624}]}]}
{"op":"mcm","clk":"1009511226","pt":1580644966257,"mc":[{"id":"1.168217557","rc":[{"trd":[[1.81,316.89],[1.83,242.68]],"batb":[[0,1.81,36.46],[1,1.69,24],[2,1.01,10.51]],"ltp":1.81,"tv":918.23,"id":2263624}],"tv":1727.08}]}
{"op":"mcm","clk":"1009511287","pt":1580644966581,"mc":[{"id":"1.168217557","rc":[{"batb":[[0,1.69,24],[1,1.01,10.51],[2,1.01,0]],"batl":[[0,1.91,150.61],[1,2.02,41.17],[2,2.6,257.57]],"ltp":1.81,"tv":918.23,"id":2263624}]}]}
{"op":"mcm","clk":"1009511724","pt":1580644969449,"mc":[{"id":"1.168217557","rc":[{"batb":[[0,1.82,112.87],[1,1.8,179.01],[2,1.69,24]],"batl":[[0,1.89,114.99],[1,1.91,150.61],[2,2.02,41.17]],"ltp":1.81,"tv":918.23,"id":2263624}]}]}
{"op":"mcm","clk":"1009511865","pt":1580644970347,"mc":[{"id":"1.168217557","rc":[{"batb":[[1,1.8,198.6]],"ltp":1.81,"tv":918.23,"id":2263624},{"batb":[[0,2.1,24.63],[2,1.83,18.65]],"ltp":1.5,"tv":808.84,"id":7412809}]}]}
{"op":"mcm","clk":"1009512591","pt":1580644975350,"mc":[{"id":"1.168217557","rc":[{"trd":[[1.82,63.66]],"batb":[[0,1.8,19.59],[1,1.69,24],[2,1.01,10.51]],"ltp":1.82,"tv":981.9,"id":2263624}],"tv":1790.74}]}
{"op":"mcm","clk":"1009512965","pt":1580644978165,"mc":[{"id":"1.168217557","rc":[{"batb":[[0,1.81,191.48],[1,1.8,19.59],[2,1.79,182.51]],"ltp":1.82,"tv":981.9,"id":2263624}]}]}
{"op":"mcm","clk":"1009513105","pt":1580644979175,"mc":[{"id":"1.168217557","rc":[{"batb":[[0,2.12,24.63],[2,1.86,18.65]],"ltp":1.5,"tv":808.84,"id":7412809}]}]}
{"op":"mcm","clk":"1009518758","pt":1580645017088,"mc":[{"id":"1.168217557","rc":[{"batl":[[0,1.89,135.94]],"ltp":1.82,"tv":981.9,"id":2263624}]}]}
{"op":"mcm","clk":"1009520178","pt":1580645026302,"mc":[{"id":"1.168217557","rc":[{"batb":[[0,1.69,24],[1,1.01,10.51],[2,1.79,0]],"batl":[[0,2.02,41.17],[1,2.42,286.52],[2,2.02,0]],"ltp":1.82,"tv":981.9,"id":2263624},{"batb":[[0,1.98,42.85],[1,1.86,18.65],[2,1.01,10.51]],"ltp":1.5,"tv":808.84,"id":7412809}]}]}
{"op":"mcm","clk":"1009520505","pt":1580645028086,"mc":[{"id":"1.168217557","rc":[{"batl":[[0,2.42,286.52],[1,2.42,0]],"ltp":1.82,"tv":981.9,"id":2263624},{"batb":[[0,1.86,18.65],[1,1.01,10.51],[2,1.01,0]],"ltp":1.5,"tv":808.84,"id":7412809}]}]}
{"op":"mcm","clk":"1009520665","pt":1580645029211,"mc":[{"id":"1.168217557","rc":[{"batb":[[0,1.7,216.09],[1,1.69,24],[2,1.68,226.83]],"ltp":1.82,"tv":981.9,"id":2263624}]}]}
{"op":"mcm","clk":"1009521143","pt":1580645032305,"mc":[{"id":"1.168217557","rc":[{"batl":[[0,1.77,130.89],[1,1.79,184.86]],"ltp":1.82,"tv":981.9,"id":2263624}]}]}
{"op":"mcm","clk":"1009521310","pt":1580645033111,"mc":[{"id":"1.168217557","rc":[{"batl":[[2,1.89,42.01]],"ltp":1.82,"tv":981.9,"id":2263624},{"batb":[[0,2.32,19.43],[1,2.12,36.97],[2,2.04,27.38]],"ltp":1.5,"tv":808.84,"id":7412809}]}]}
{"op":"mcm","clk":"1009521563","pt":1580645034608,"mc":[{"id":"1.168217557","rc":[{"batl":[[0,3.15,200.42]],"ltp":1.5,"tv":808.84,"id":7412809}]}]}
{"op":"mcm","clk":"1009522669","pt":1580645042039,"mc":[{"id":"1.168217557","rc":[{"batb":[[0,1.61,28.72],[1,1.01,10.51],[2,1.68,0]],"batl":[[0,2.22,329.01],[1,1.79,0],[2,1.89,0]],"ltp":1.82,"tv":981.9,"id":2263624},{"batb":[[0,2.04,27.38],[1,1.01,10.51],[2,2.04,0]],"ltp":1.5,"tv":808.84,"id":7412809}]}]}
{"op":"mcm","clk":"1009523004","pt":1580645044507,"mc":[{"id":"1.168217557","rc":[{"batb":[[0,1.63,196.09],[1,1.62,130.03],[2,1.61,28.72]],"batl":[[0,1.95,158.8],[1,1.97,137.1],[2,2.22,329.01]],"ltp":1.82,"tv":981.9,"id":2263624}]}]}
{"op":"mcm","clk":"1009523648","pt":1580645049313,"mc":[{"id":"1.168217557","rc":[{"batb":[[0,1.61,28.72],[1,1.01,10.51],[2,1.61,0]],"ltp":1.82,"tv":981.9,"id":2263624}]}]}
{"op":"mcm","clk":"1009523885","pt":1580645051333,"mc":[{"id":"1.168217557","rc":[{"trd":[[1.61,0.03]],"batb":[[0,1.61,28.7]],"batl":[[2,2.22,0]],"ltp":1.61,"tv":981.93,"id":2263624}],"tv":1790.77}]}
{"op":"mcm","clk":"1009524023","pt":1580645052354,"mc":[{"id":"1.168217557","rc":[{"batb":[[0,1.86,201.59],[1,1.84,166.74],[2,1.71,23.21]],"ltp":1.61,"tv":981.93,"id":2263624},{"batb":[[1,1.75,22.58],[2,1.01,10.51]],"ltp":1.5,"tv":808.84,"id":7412809}]}]}
{"op":"mcm","clk":"1009524142","pt":1580645053507,"mc":[{"id":"1.168217557","rc":[{"batl":[[2,2.06,39.49]],"ltp":1.61,"tv":981.93,"id":2263624},{"batb":[[1,1.95,43.69],[2,1.75,22.58]],"ltp":1.5,"tv":808.84,"id":7412809}]}]}
{"op":"mcm","clk":"1009524293","pt":1580645054737,"mc":[{"id":"1.168217557","rc":[{"batl":[[0,2.72,241.55]],"ltp":1.5,"tv":808.84,"id":7412809}]}]}
{"op":"mcm","clk":"1009525539","pt":1580645064522,"mc":[{"id":"1.168217557","rc":[{"batb":[[0,1.86,17.7],[1,1.71,23.21],[2,1.01,10.51]],"ltp":1.61,"tv":981.93,"id":2263624}]}]}
{"op":"mcm","clk":"1009525763","pt":1580645066135,"mc":[{"id":"1.168217557","rc":[{"batb":[[0,1.71,23.21],[1,1.01,10.51],[2,1.01,0]],"batl":[[0,2.5,274.54],[1,1.97,0],[2,2.06,0]],"ltp":1.61,"tv":981.93,"id":2263624},{"batb":[[0,1.75,22.58],[1,1.01,10.51],[2,1.75,0]],"ltp":1.5,"tv":808.84,"id":7412809}]}]}
{"op":"mcm","clk":"1009526084","pt":1580645068462,"mc":[{"id":"1.168217557","rc":[{"batb":[[0,1.72,167.19],[1,1.71,23.21],[2,1.7,217.42]],"batl":[[0,2.32,92.51],[1,2.34,83.83],[2,2.5,274.54]],"ltp":1.61,"tv":981.93,"id":2263624}]}]}
{"op":"mcm","clk":"1009528280","pt":1580645085255,"mc":[{"id":"1.168217557","rc":[{"batl":[[0,2.5,274.54],[1,2.34,0],[2,2.5,0]],"ltp":1.61,"tv":981.93,"id":2263624}]}]}
{"op":"mcm","clk":"1009528746","pt":1580645088480,"mc":[{"id":"1.168217557","rc":[{"batl":[[0,1.79,155.01],[1,1.81,178.27]],"ltp":1.61,"tv":981.93,"id":2263624}]}]}
{"op":"mcm","clk":"1009528830","pt":1580645089069,"mc":[{"id":"1.168217557","rc":[{"batl":[[2,1.9,42.01]],"ltp":1.61,"tv":981.93,"id":2263624},{"batb":[[0,2.26,20.54],[1,2.1,37.81],[2,1.98,30.29]],"ltp":1.5,"tv":808.84,"id":7412809}]}]}
{"op":"mcm","clk":"1009529833","pt":1580645096480,"mc":[{"id":"1.168217557","rc":[{"batb":[[0,1.62,28.33],[1,1.01,10.51],[2,1.7,0]],"batl":[[0,1.9,42.01],[1,2.3,309.75],[2,1.9,0]],"ltp":1.61,"tv":981.93,"id":2263624},{"batb":[[0,2.1,37.81],[1,1.98,30.29],[2,1.01,10.51]],"ltp":1.5,"tv":808.84,"id":7412809}]}]}
{"op":"mcm","clk":"1009530050","pt":1580645098098,"mc":[{"id":"1.168217557","rc":[{"batl":[[0,2.3,309.75],[1,2.3,0]],"ltp":1.61,"tv":981.93,"id":2263624},{"batb":[[0,1.98,30.29],[1,1.01,10.51],[2,1.01,0]],"ltp":1.5,"tv":808.84,"id":7412809}]}]}
{"op":"mcm","clk":"1009530657","pt":1580645102505,"mc":[{"id":"1.168217557","rc":[{"trd":[[1.72,12.34]],"batb":[[0,1.76,117.37],[1,1.74,200.59],[2,1.62,28.33]],"batl":[[0,1.83,150.48],[1,1.85,166.32],[2,2.3,309.75]],"ltp":1.72,"tv":994.27,"id":2263624},{"trd":[[2.4,8.84]],"ltp":2.4,"tv":817.68,"id":7412809}],"tv":1811.95}]}
{"op":"mcm","clk":"1009531679","pt":1580645109099,"mc":[{"id":"1.168217557","rc":[{"batb":[[0,1.62,28.33],[1,1.01,10.51],[2,1.62,0]],"batl":[[0,2.3,309.75],[1,1.85,0],[2,2.3,0]],"ltp":1.72,"tv":994.27,"id":2263624}]}]}
{"op":"mcm","clk":"1009531869","pt":1580645110425,"mc":[{"id":"1.168217557","rc":[{"batb":[[1,1.01,13.55]],"ltp":1.72,"tv":994.27,"id":2263624}]}]}
{"op":"mcm","clk":"1009532038","pt":1580645111390,"mc":[{"id":"1.168217557","rc":[{"batb":[[1,1.01,10.51]],"ltp":1.72,"tv":994.27,"id":2263624}]}]}
{"op":"mcm","clk":"1009532147","pt":1580645112307,"mc":[{"id":"1.168217557","rc":[{"batb":[[0,1.63,169.96],[1,1.62,158.28],[2,1.01,10.51]],"batl":[[0,2.02,200.2],[1,2.04,123.61],[2,2.3,309.75]],"ltp":1.72,"tv":994.27,"id":2263624}]}]}
{"op":"mcm","clk":"1009532473","pt":1580645114508,"mc":[{"id":"1.168217557","rc":[{"batb":[[2,1.01,10.52]],"ltp":1.72,"tv":994.27,"id":2263624}]}]}
{"op":"mcm","clk":"1009534443","pt":1580645128313,"mc":[{"id":"1.168217557","rc":[{"batl":[[0,2.3,309.75],[1,2.04,0],[2,2.3,0]],"ltp":1.72,"tv":994.27,"id":2263624}]}]}
{"op":"mcm","clk":"1009534879","pt":1580645131442,"mc":[{"id":"1.168217557","rc":[{"batl":[[0,1.69,156.94],[1,1.71,214.94],[2,2.3,309.75]],"ltp":1.72,"tv":994.27,"id":2263624}]}]}
{"op":"mcm","clk":"1009534973","pt":1580645132138,"mc":[{"id":"1.168217557","rc":[{"batb":[[2,1.57,31.72]],"batl":[[2,2.3,0]],"ltp":1.72,"tv":994.27,"id":2263624},{"batb":[[0,2.46,16.44],[1,2.26,20.61],[2,1.01,10.51]],"ltp":2.4,"tv":817.68,"id":7412809}]}]}
{"op":"mcm","clk":"1009535139","pt":1580645133435,"mc":[{"id":"1.168217557","rc":[{"batl":[[2,1.8,42.01]],"ltp":1.72,"tv":994.27,"id":2263624},{"batb":[[1,2.26,53.38]],"ltp":2.4,"tv":817.68,"id":7412809}]}]}
{"op":"mcm","clk":"1009535445","pt":1580645135457,"mc":[{"id":"1.168217557","rc":[{"batl":[[0,3.3,191.92]],"ltp":2.4,"tv":817.68,"id":7412809}]}]}
{"op":"mcm","clk":"1009537389","pt":1580645149364,"mc":[{"id":"1.168217557","rc":[{"batb":[[0,1.57,31.72],[1,1.01,10.51],[2,1.57,0]],"batl":[[0,1.8,42.01],[1,2.16,342.82],[2,1.8,0]],"ltp":1.72,"tv":994.27,"id":2263624},{"batb":[[0,2.26,53.38],[1,1.01,10.51],[2,1.01,0]],"ltp":2.4,"tv":817.68,"id":7412809}]}]}
{"op":"mcm","clk":"1009537491","pt":1580645150155,"mc":[{"id":"1.168217557","rc":[{"batl":[[0,2.16,342.82],[1,2.16,0]],"ltp":1.72,"tv":994.27,"id":2263624},{"batb":[[0,2.26,20.61]],"ltp":2.4,"tv":817.68,"id":7412809}]}]}
{"op":"mcm","clk":"1009537739","pt":1580645151864,"mc":[{"id":"1.168217557","rc":[{"batb":[[0,1.59,167.25],[1,1.58,142.76],[2,1.57,31.71]],"batl":[[0,1.78,138.51],[1,1.8,181.53],[2,2.16,342.82]],"ltp":1.72,"tv":994.27,"id":2263624}]}]}
{"op":"mcm","clk":"1009538109","pt":1580645154463,"mc":[{"id":"1.168217557","rc":[{"batl":[[0,2.16,342.82],[1,1.8,0],[2,2.16,0]],"ltp":1.72,"tv":994.27,"id":2263624}]}]}
{"op":"mcm","clk":"1009538501","pt":1580645157188,"mc":[{"id":"1.168217557","rc":[{"batl":[[0,1.65,213.94],[1,1.66,118.1],[2,2.16,342.82]],"ltp":1.72,"tv":994.27,"id":2263624}]}]}
{"op":"mcm","clk":"1009538645","pt":1580645158255,"mc":[{"id":"1.168217557","rc":[{"batb":[[0,2.6,14.4],[1,2.34,19.12],[2,1.01,10.51]],"ltp":2.4,"tv":817.68,"id":7412809}]}]}
{"op":"mcm","clk":"1009538800","pt":1580645159471,"mc":[{"id":"1.168217557","rc":[{"batl":[[2,1.74,42.01]],"ltp":1.72,"tv":994.27,"id":2263624},{"batb":[[1,2.38,30.25],[2,2.34,19.12]],"ltp":2.4,"tv":817.68,"id":7412809}]}]}
{"op":"mcm","clk":"1009541930","pt":1580645182242,"mc":[{"id":"1.168217557","rc":[{"batl":[[0,1.65,156.76]],"ltp":1.72,"tv":994.27,"id":2263624}]}]}
{"op":"mcm","clk":"1009542437","pt":1580645185237,"mc":[{"id":"1.168217557","rc":[{"batb":[[0,1.59,226.58]],"ltp":1.72,"tv":994.27,"id":2263624}]}]}
{"op":"mcm","clk":"1009543023","pt":1580645189273,"mc":[{"id":"1.168217557","rc":[{"batb":[[0,1.42,46.75],[1,1.01,10.51],[2,1.57,0]],"batl":[[0,1.74,42.01],[1,2.16,342.82],[2,1.74,0]],"ltp":1.72,"tv":994.27,"id":2263624},{"batb":[[0,2.38,30.25],[1,2.34,19.12],[2,1.01,10.51]],"ltp":2.4,"tv":817.68,"id":7412809}]}]}
{"op":"mcm","clk":"1009543114","pt":1580645190072,"mc":[{"id":"1.168217557","rc":[{"batl":[[0,2.16,342.82],[1,2.16,0]],"ltp":1.72,"tv":994.27,"id":2263624},{"batb":[[0,2.34,19.12],[1,1.01,10.51],[2,1.01,0]],"ltp":2.4,"tv":817.68,"id":7412809}]}]}
{"op":"mcm","clk":"1009543459","pt":1580645192393,"mc":[{"id":"1.168217557","rc":[{"batb":[[0,1.45,148.26],[1,1.44,207.03],[2,1.42,46.74]],"batl":[[0,1.77,127.69],[1,1.79,184.52],[2,2.16,342.82]],"ltp":1.72,"tv":994.27,"id":2263624},{"batb":[[0,2.32,19.12]],"ltp":2.4,"tv":817.68,"id":7412809}]}]}
{"op":"mcm","clk":"1009545971","pt":1580645210081,"mc":[{"id":"1.168217557","rc":[{"batb":[[0,1.42,46.75],[1,1.01,10.51],[2,1.42,0]],"ltp":1.72,"tv":994.27,"id":2263624}]}]}
{"op":"mcm","clk":"1009546488","pt":1580645213377,"mc":[{"id":"1.168217557","rc":[{"batb":[[0,1.7,218.51],[1,1.68,226.44],[2,1.42,46.75]],"ltp":1.72,"tv":994.27,"id":2263624}]}]}
{"op":"mcm","clk":"1009546627","pt":1580645214287,"mc":[{"id":"1.168217557","rc":[{"batb":[[1,1.68,251.15],[2,1.54,34.08]],"ltp":1.72,"tv":994.27,"id":2263624},{"batb":[[1,2.16,23.53],[2,1.01,10.51]],"ltp":2.4,"tv":817.68,"id":7412809}]}]}
{"op":"mcm","clk":"1009546733","pt":1580645215102,"mc":[{"id":"1.168217557","rc":[{"batl":[[2,1.85,42.01]],"ltp":1.72,"tv":994.27,"id":2263624},{"batb":[[1,2.18,35.29],[2,2.16,23.53]],"ltp":2.4,"tv":817.68,"id":7412809}]}]}
{"op":"mcm","clk":"1009546932","pt":1580645216213,"mc":[{"id":"1.168217557","rc":[{"batl":[[0,3,213.45]],"ltp":2.4,"tv":817.68,"id":7412809}]}]}
{"op":"mcm","clk":"1009549420","pt":1580645232324,"mc":[{"id":"1.168217557","rc":[{"batb":[[0,1.54,34.08],[1,1.01,10.51],[2,1.54,0]],"batl":[[0,2.16,342.82],[1,1.79,0],[2,1.85,0]],"ltp":1.72,"tv":994.27,"id":2263624},{"batb":[[0,2.16,23.53],[1,1.01,10.51],[2,2.16,0]],"ltp":2.4,"tv":817.68,"id":7412809}]}]}
{"op":"mcm","clk":"1009550380","pt":1580645238247,"mc":[{"id":"1.168217557","rc":[{"batb":[[0,1.67,227.29],[1,1.66,118.91],[2,1.54,34.08]],"batl":[[0,1.74,155.68],[1,1.76,194.9],[2,2.16,342.82]],"ltp":1.72,"tv":994.27,"id":2263624}]}]}
{"op":"mcm","clk":"1009551055","pt":1580645242331,"mc":[{"id":"1.168217557","rc":[{"batb":[[0,1.54,34.08],[1,1.01,10.51],[2,1.54,0]],"batl":[[0,2.16,342.82],[1,1.76,0],[2,2.16,0]],"ltp":1.72,"tv":994.27,"id":2263624}]}]}
{"op":"mcm","clk":"1009551542","pt":1580645245264,"mc":[{"id":"1.168217557","rc":[{"batb":[[0,1.56,267.59],[1,1.55,153.73],[2,1.54,34.07]],"batl":[[0,1.88,109.64],[1,1.9,152.81],[2,2.16,342.82]],"ltp":1.72,"tv":994.27,"id":2263624}]}]}
{"op":"mcm","clk":"1009552926","pt":1580645254476,"mc":[{"id":"1.168217557","rc":[{"batl":[[0,2.16,342.82],[1,1.9,0],[2,2.16,0]],"ltp":1.72,"tv":994.27,"id":2263624}]}]}
{"op":"mcm","clk":"1009553335","pt":1580645257441,"mc":[{"id":"1.168217557","rc":[{"batl":[[0,1.62,164.69],[1,1.63,125.91],[2,2.16,342.82]],"ltp":1.72,"tv":994.27,"id":2263624}]}]}
{"op":"mcm","clk":"1009553471","pt":1580645258282,"mc":[{"id":"1.168217557","rc":[{"batl":[[2,2.16,0]],"ltp":1.72,"tv":994.27,"id":2263624}]}]}
{"op":"mcm","clk":"1009553596","pt":1580645259101,"mc":[{"id":"1.168217557","rc":[{"trd":[[1.61,0.05]],"batb":[[0,1.56,267.57]],"batl":[[2,1.71,42.01]],"ltp":1.61,"tv":994.28,"id":2263624},{"trd":[[2.64,0.01]],"batb":[[0,2.68,13.21],[1,2.42,29.41],[2,2.36,18.49]],"ltp":2.64,"tv":817.69,"id":7412809}],"tv":1811.98}]}
{"op":"mcm","clk":"1009553964","pt":1580645261553,"mc":[{"id":"1.168217557","rc":[{"batl":[[0,3.65,170.41]],"ltp":2.64,"tv":817.69,"id":7412809}]}]}
{"op":"mcm","clk":"1009556690","pt":1580645281213,"mc":[{"id":"1.168217557","rc":[{"batb":[[0,1.37,55.31],[1,1.01,10.51],[2,1.54,0]],"batl":[[0,1.71,42.01],[1,2.04,383.01],[2,1.71,0]],"ltp":1.61,"tv":994.28,"id":2263624},{"batb":[[0,2.42,29.41],[1,2.36,18.49],[2,1.01,10.51]],"ltp":2.64,"tv":817.69,"id":7412809}]}]}
{"op":"mcm","clk":"1009556840","pt":1580645282173,"mc":[{"id":"1.168217557","rc":[{"batl":[[0,2.04,383.01],[1,2.04,0]],"ltp":1.61,"tv":994.28,"id":2263624},{"batb":[[0,2.36,18.49],[1,1.01,10.51],[2,1.01,0]],"ltp":2.64,"tv":817.69,"id":7412809}]}]}
{"op":"mcm","clk":"1009557091","pt":1580645284029,"mc":[{"id":"1.168217557","rc":[{"batb":[[0,1.4,150.58],[1,1.39,242.52],[2,1.37,55.31]],"batl":[[0,1.77,181.66],[1,1.79,184.35],[2,2.04,383.01]],"ltp":1.61,"tv":994.28,"id":2263624}]}]}
{"op":"mcm","clk":"1009558061","pt":1580645291002,"mc":[{"id":"1.168217557","rc":[{"batl":[[0,2.04,383.01],[1,1.79,0],[2,2.04,0]],"ltp":1.61,"tv":994.28,"id":2263624}]}]}
{"op":"mcm","clk":"1009558421","pt":1580645293498,"mc":[{"id":"1.168217557","rc":[{"batl":[[0,1.44,268.21],[1,1.45,196.6]],"ltp":1.61,"tv":994.28,"id":2263624}]}]}
{"op":"mcm","clk":"1009558549","pt":1580645294405,"mc":[{"id":"1.168217557","rc":[{"batb":[[0,3.35,18.18],[1,2.78,11.96],[2,2.36,18.49]],"ltp":2.64,"tv":817.69,"id":7412809}]}]}
{"op":"mcm","clk":"1009558650","pt":1580645295097,"mc":[{"id":"1.168217557","rc":[{"batb":[[0,1.42,99.98],[1,1.4,150.58],[2,1.39,242.52]],"batl":[[2,1.51,42.01]],"ltp":1.61,"tv":994.28,"id":2263624},{"batb":[[1,2.94,21],[2,2.78,11.96]],"ltp":2.64,"tv":817.69,"id":7412809}]}]}
{"op":"mcm","clk":"1009558863","pt":1580645296699,"mc":[{"id":"1.168217557","rc":[{"batl":[[0,4.6,136.05]],"ltp":2.64,"tv":817.69,"id":7412809}]}]}
{"op":"mcm","clk":"1009561178","pt":1580645313428,"mc":[{"id":"1.168217557","rc":[{"batb":[[1,2.78,11.96],[2,1.01,10.51]],"ltp":2.64,"tv":817.69,"id":7412809}]}]}
{"op":"mcm","clk":"1009561313","pt":1580645314451,"mc":[{"id":"1.168217557","rc":[{"batb":[[1,1.37,55.31],[2,1.21,109.53]],"batl":[[0,1.51,42.01],[1,1.82,469.11],[2,1.51,0]],"ltp":1.61,"tv":994.28,"id":2263624}]}]}
{"op":"mcm","clk":"1009561403","pt":1580645315044,"mc":[{"id":"1.168217557","rc":[{"batb":[[1,1.21,109.53],[2,1.01,10.51]],"ltp":1.61,"tv":994.28,"id":2263624},{"batb":[[0,2.78,11.96],[1,1.01,10.51],[2,1.01,0]],"ltp":2.64,"tv":817.69,"id":7412809}]}]}
{"op":"mcm","clk":"1009561588","pt":1580645316429,"mc":[{"id":"1.168217557","rc":[{"batb":[[0,1.21,109.53],[1,1.01,10.51],[2,1.01,0]],"batl":[[0,1.82,469.11],[1,1.82,0]],"ltp":1.61,"tv":994.28,"id":2263624},{"batb":[[0,3,21],[1,2.78,11.96],[2,1.01,10.51]],"ltp":2.64,"tv":817.69,"id":7412809}]}]}
{"op":"mcm","clk":"1009561693","pt":1580645317353,"mc":[{"id":"1.168217557","rc":[{"batb":[[0,1.23,263.78],[1,1.22,496.5],[2,1.21,109.53]],"batl":[[0,1.59,135.08],[1,1.6,134.63],[2,1.82,469.11]],"ltp":1.61,"tv":994.28,"id":2263624},{"batb":[[0,2.78,11.96],[1,1.01,10.51],[2,1.01,0]],"ltp":2.64,"tv":817.69,"id":7412809}]}]}
{"op":"mcm","clk":"1009561821","pt":1580645318244,"mc":[{"id":"1.168217557","rc":[{"batb":[[2,1.21,107.79]],"ltp":1.61,"tv":994.28,"id":2263624},{"batb":[[0,2.76,12.2]],"ltp":2.64,"tv":817.69,"id":7412809}]}]}
{"op":"mcm","clk":"1009565028","pt":1580645339776,"mc":[{"id":"1.168217557","rc":[{"batl":[[0,1.82,469.11],[1,1.6,0],[2,1.82,0]],"ltp":1.61,"tv":994.28,"id":2263624}]}]}
{"op":"mcm","clk":"1009565633","pt":1580645343493,"mc":[{"id":"1.168217557","rc":[{"batl":[[0,1.26,493.66],[1,1.27,366.75],[2,1.29,6.51]],"ltp":1.61,"tv":994.28,"id":2263624},{"batb":[[0,4.9,14.32],[1,3.8,13.45],[2,2.76,12.2]],"ltp":2.64,"tv":817.69,"id":7412809}]}]}
{"op":"mcm","clk":"1009565755","pt":1580645344311,"mc":[{"id":"1.168217557","rc":[{"batl":[[2,1.31,42.01]],"ltp":1.61,"tv":994.28,"id":2263624},{"batb":[[1,4.2,12.6],[2,3.8,13.45]],"ltp":2.64,"tv":817.69,"id":7412809}]}]}
{"op":"mcm","clk":"1009566045","pt":1580645346091,"mc":[{"id":"1.168217557","rc":[{"batl":[[0,7.8,87.91]],"ltp":2.64,"tv":817.69,"id":7412809}]}]}
{"op":"mcm","clk":"1009569148","pt":1580645366506,"mc":[{"id":"1.168217557","rc":[{"batb":[[0,1.21,107.79],[1,1.09,255.32],[2,1.01,10.51]],"batl":[[0,1.31,42.01],[1,1.56,675.59],[2,1.31,0]],"ltp":1.61,"tv":994.28,"id":2263624}]}]}
{"op":"mcm","clk":"1009569174","pt":1580645366741,"mc":[{"id":"1.168217557","rc":[{"batb":[[0,1.09,255.09],[1,1.01,10.51],[2,1.01,0]],"ltp":1.61,"tv":994.28,"id":2263624},{"batb":[[0,4.2,12.6],[1,3.8,13.45],[2,1.01,10.51]],"ltp":2.64,"tv":817.69,"id":7412809}]}]}
{"op":"mcm","clk":"1009569400","pt":1580645368224,"mc":[{"id":"1.168217557","rc":[{"batl":[[0,1.56,675.59],[1,1.56,0]],"ltp":1.61,"tv":994.28,"id":2263624},{"batb":[[0,3.8,13.45],[1,1.01,10.51],[2,1.01,0]],"ltp":2.64,"tv":817.69,"id":7412809}]}]}
{"op":"mcm","clk":"1009569560","pt":1580645369401,"mc":[{"id":"1.168217557","rc":[{"batb":[[0,1.11,336.51],[1,1.1,824.57],[2,1.09,255.09]],"batl":[[0,1.36,158.54],[1,1.37,253.64]],"ltp":1.61,"tv":994.28,"id":2263624}]}]}
{"op":"mcm","clk":"1009571754","pt":1580645384118,"mc":[{"id":"1.168217557","rc":[{"batb":[[0,1.11,280.73]],"ltp":1.61,"tv":994.28,"id":2263624}]}]}
{"op":"mcm","clk":"1009572161","pt":1580645387114,"mc":[{"id":"1.168217557","rc":[{"batb":[[1,1.1,880.86]],"batl":[[0,1.36,203.66]],"ltp":1.61,"tv":994.28,"id":2263624}]}]}
{"op":"mcm","clk":"1009574430","pt":1580645404463,"mc":[{"id":"1.168217557","rc":[{"batl":[[0,1.12,171.95],[1,1.13,872.89]],"ltp":1.61,"tv":994.28,"id":2263624}]}]}
{"op":"mcm","clk":"1009574558","pt":1580645405469,"mc":[{"id":"1.168217557","rc":[{"batb":[[0,9,7.32],[1,6,18.18],[2,3.8,13.45]],"ltp":2.64,"tv":817.69,"id":7412809}]}]}
{"op":"mcm","clk":"1009574576","pt":1580645405575,"mc":[{"id":"1.168217557","rc":[{"batb":[[2,1.01,10.51]],"ltp":2.64,"tv":817.69,"id":7412809}]}]}
{"op":"mcm","clk":"1009574927","pt":1580645408138,"mc":[{"id":"1.168217557","rc":[{"trd":[[1.12,342.8]],"batb":[[1,1.1,824.57]],"batl":[[0,1.13,872.89],[1,1.15,42.01],[2,1.4,927.7]],"ltp":1.12,"tv":1337.08,"id":2263624},{"batb":[[1,7.6,5.88],[2,6,18.18]],"batl":[[0,9.8,4.2],[1,17,57.33]],"ltp":2.64,"tv":817.69,"id":7412809}],"tv":2154.78}]}
{"op":"mcm","clk":"1009575326","pt":1580645411051,"mc":[{"id":"1.168217557","rc":[{"batb":[[0,1.11,344.1]],"batl":[[0,1.13,981.19]],"ltp":1.12,"tv":1337.08,"id":2263624}]}]}
{"op":"mcm","clk":"1009587730","pt":1580645500301,"mc":[{"id":"1.168217557","rc":[{"batb":[[0,1.06,373.27],[1,1.01,10.51],[2,1.09,0]],"batl":[[0,1.4,927.7],[1,1.15,0],[2,1.4,0]],"ltp":1.12,"tv":1337.08,"id":2263624},{"batb":[[0,6,18.18],[1,1.01,10.51],[2,6,0]],"batl":[[0,17,57.33],[1,17,0]],"ltp":2.64,"tv":817.69,"id":7412809}]}]}
{"op":"mcm","clk":"1009588036","pt":1580645502711,"mc":[{"id":"1.168217557","rc":[{"batb":[[0,1.08,348.59],[1,1.07,844.93],[2,1.06,373.27]],"batl":[[0,1.2,612.08],[1,1.21,451.29],[2,1.4,927.7]],"ltp":1.12,"tv":1337.08,"id":2263624}]}]}
{"op":"mcm","clk":"1009588193","pt":1580645504016,"mc":[{"id":"1.168217557","rc":[{"batb":[[0,1.06,373.27],[1,1.01,10.51],[2,1.06,0]],"ltp":1.12,"tv":1337.08,"id":2263624}]}]}
{"op":"mcm","clk":"1009588657","pt":1580645507389,"mc":[{"id":"1.168217557","rc":[{"batb":[[0,1.17,635.77],[1,1.16,462.67],[2,1.06,373.27]],"batl":[[2,1.22,42.01]],"ltp":1.12,"tv":1337.08,"id":2263624},{"batb":[[1,5.5,9.24],[2,1.01,10.51]],"ltp":2.64,"tv":817.69,"id":7412809}]}]}
{"op":"mcm","clk":"1009588767","pt":1580645508314,"mc":[{"id":"1.168217557","rc":[{"batb":[[0,1.18,168.04],[1,1.17,635.77],[2,1.16,609.02]],"ltp":1.12,"tv":1337.08,"id":2263624},{"batb":[[2,4,22.66]],"batl":[[0,6.6,6.72]],"ltp":2.64,"tv":817.69,"id":7412809}]}]}
{"op":"mcm","clk":"1009589067","pt":1580645510891,"mc":[{"id":"1.168217557","rc":[{"batl":[[1,11.5,70.11]],"ltp":2.64,"tv":817.69,"id":7412809}]}]}
{"op":"mcm","clk":"1009590096","pt":1580645518499,"mc":[{"id":"1.168217557","rc":[{"batb":[[1,1.16,146.35],[2,1.11,220.78]],"batl":[[0,1.22,42.01],[1,1.4,927.7],[2,1.22,0]],"ltp":1.12,"tv":1337.08,"id":2263624}]}]}
{"op":"mcm","clk":"1009590132","pt":1580645518776,"mc":[{"id":"1.168217557","rc":[{"batb":[[1,1.11,220.78],[2,1.01,10.51]],"ltp":1.12,"tv":1337.08,"id":2263624},{"batb":[[0,5.5,9.24],[1,4,22.66],[2,1.01,10.51]],"ltp":2.64,"tv":817.69,"id":7412809}]}]}
{"op":"mcm","clk":"1009590338","pt":1580645520477,"mc":[{"id":"1.168217557","rc":[{"batb":[[0,1.11,220.78],[1,1.01,10.51],[2,1.01,0]],"batl":[[0,1.4,927.7],[1,1.4,0]],"ltp":1.12,"tv":1337.08,"id":2263624},{"batb":[[0,4,22.66],[1,1.01,10.51],[2,1.01,0]],"batl":[[0,11.5,70.11],[1,11.5,0]],"ltp":2.64,"tv":817.69,"id":7412809}]}]}
{"op":"mcm","clk":"1009590478","pt":1580645521487,"mc":[{"id":"1.168217557","rc":[{"batb":[[0,1.12,679.29],[1,1.11,689.02],[2,1.01,10.51]],"batl":[[0,1.32,280.4],[1,1.33,290.63],[2,1.4,927.7]],"ltp":1.12,"tv":1337.08,"id":2263624}]}]}
{"op":"mcm","clk":"1009590611","pt":1580645522399,"mc":[{"id":"1.168217557","rc":[{"batb":[[0,1.11,220.78],[1,1.01,10.51],[2,1.01,0]],"batl":[[0,1.4,927.7],[1,1.33,0],[2,1.4,0]],"ltp":1.12,"tv":1337.08,"id":2263624}]}]}
{"op":"mcm","clk":"1009590804","pt":1580645523876,"mc":[{"id":"1.168217557","rc":[{"batb":[[0,1.19,643.93],[1,1.18,435.82],[2,1.11,220.78]],"batl":[[0,1.22,422.88],[1,1.23,445.43],[2,1.4,927.7]],"ltp":1.12,"tv":1337.08,"id":2263624}]}]}
{"op":"mcm","clk":"1009591298","pt":1580645527278,"mc":[{"id":"1.168217557","rc":[{"batb":[[0,1.11,220.78],[1,1.01,10.51],[2,1.11,0]],"batl":[[0,1.4,927.7],[1,1.23,0],[2,1.4,0]],"ltp":1.12,"tv":1337.08,"id":2263624},{"batl":[[0,9.8,75.27]],"ltp":2.64,"tv":817.69,"id":7412809}]}]}
{"op":"mcm","clk":"1009591677","pt":1580645530300,"mc":[{"id":"1.168217557","rc":[{"batb":[[0,1.12,679.29],[1,1.11,689.02],[2,1.01,10.51]],"batl":[[0,1.32,280.4],[1,1.33,290.63],[2,1.4,927.7]],"ltp":1.12,"tv":1337.08,"id":2263624}]}]}
{"op":"mcm","clk":"1009591858","pt":1580645531622,"mc":[{"id":"1.168217557","rc":[{"batl":[[0,1.4,927.7],[1,1.33,0],[2,1.4,0]],"ltp":1.12,"tv":1337.08,"id":2263624}]}]}
{"op":"mcm","clk":"1009592235","pt":1580645534485,"mc":[{"id":"1.168217557","rc":[{"batl":[[0,1.14,541.84],[1,1.15,576.4],[2,1.4,927.7]],"ltp":1.12,"tv":1337.08,"id":2263624}]}]}
{"op":"mcm","clk":"1009592386","pt":1580645535484,"mc":[{"id":"1.168217557","rc":[{"batb":[[2,1.06,352.42]],"batl":[[2,1.16,42.01]],"ltp":1.12,"tv":1337.08,"id":2263624},{"batb":[[0,8,9.36],[1,5.2,12.98],[2,1.01,10.51]],"batl":[[0,8.8,5.04]],"ltp":2.64,"tv":817.69,"id":7412809}]}]}
{"op":"mcm","clk":"1009592638","pt":1580645537132,"mc":[{"id":"1.168217557","rc":[{"batl":[[1,17,57.33]],"ltp":2.64,"tv":817.69,"id":7412809}]}]}
{"op":"mcm","clk":"1009592730","pt":1580645538291,"mc":[{"id":"1.168217557","rc":[{"batb":[[1,7.2,6.72],[2,5.2,12.98]],"ltp":2.64,"tv":817.69,"id":7412809}]}]}
{"op":"mcm","clk":"1009594627","pt":1580645551509,"mc":[{"id":"1.168217557","rc":[{"batb":[[0,1.11,220.78],[1,1.06,352.42],[2,1.01,10.51]],"batl":[[0,1.16,42.01],[1,1.4,927.7],[2,1.16,0]],"ltp":1.12,"tv":1337.08,"id":2263624}]}]}
{"op":"mcm","clk":"1009594786","pt":1580645552313,"mc":[{"id":"1.168217557","rc":[{"batb":[[0,1.06,352.42],[1,1.01,10.51],[2,1.01,0]],"batl":[[0,1.4,927.7],[1,1.4,0]],"ltp":1.12,"tv":1337.08,"id":2263624},{"batb":[[0,5.2,12.98],[1,1.01,10.51],[2,5.2,0]],"batl":[[0,17,57.33],[1,17,0]],"ltp":2.64,"tv":817.69,"id":7412809}]}]}
{"op":"mcm","clk":"1009595118","pt":1580645554338,"mc":[{"id":"1.168217557","rc":[{"batb":[[0,1.08,845.21],[1,1.07,343.67],[2,1.06,352.42]],"batl":[[0,1.24,519.63],[1,1.25,401.19],[2,1.4,927.7]],"ltp":1.12,"tv":1337.08,"id":2263624}]}]}
{"op":"mcm","clk":"1009595407","pt":1580645555640,"mc":[{"id":"1.168217557","rc":[{"batl":[[0,1.4,927.7],[1,1.25,0],[2,1.4,0]],"ltp":1.12,"tv":1337.08,"id":2263624}]}]}
{"op":"mcm","clk":"1009596104","pt":1580645559393,"mc":[{"id":"1.168217557","rc":[{"batl":[[0,1.1,1164.14],[1,1.4,927.7]],"ltp":1.12,"tv":1337.08,"id":2263624},{"batb":[[0,11,10.94],[1,7.2,11.8],[2,1.01,10.51]],"batl":[[0,12.5,3.36]],"ltp":2.64,"tv":817.69,"id":7412809}]}]}
{"op":"mcm","clk":"1009596407","pt":1580645561515,"mc":[{"id":"1.168217557","rc":[{"batb":[[1,9.6,4.2],[2,7.2,11.8]],"batl":[[1,30,47.16]],"ltp":2.64,"tv":817.69,"id":7412809}]}]}
{"op":"mcm","clk":"1009597167","pt":1580645566252,"mc":[{"id":"1.168217557","rc":[{"batb":[[0,1.06,352.42],[1,1.04,561.71],[2,1.01,10.51]],"batl":[[0,1.4,927.7],[1,1.4,0]],"ltp":1.12,"tv":1337.08,"id":2263624}]}]}
{"op":"mcm","clk":"1009597344","pt":1580645567344,"mc":[{"id":"1.168217557","rc":[{"batb":[[0,1.04,561.71],[1,1.01,10.51],[2,1.01,0]],"ltp":1.12,"tv":1337.08,"id":2263624},{"batb":[[0,9.6,4.2],[1,7.2,11.8],[2,1.01,10.51]],"ltp":2.64,"tv":817.69,"id":7412809}]}]}
{"op":"mcm","clk":"1009597481","pt":1580645568245,"mc":[{"id":"1.168217557","rc":[{"batb":[[0,7.2,11.8],[1,1.01,10.51],[2,1.01,0]],"batl":[[0,30,47.16],[1,30,0]],"ltp":2.64,"tv":817.69,"id":7412809}]}]}
{"op":"mcm","clk":"1009597633","pt":1580645569262,"mc":[{"id":"1.168217557","rc":[{"batb":[[0,1.05,1219.58],[1,1.04,561.71],[2,1.01,10.51]],"batl":[[0,1.16,701.14],[1,1.17,399.34],[2,1.4,927.7]],"ltp":1.12,"tv":1337.08,"id":2263624}]}]}
{"op":"mcm","clk":"1009597785","pt":1580645570134,"mc":[{"id":"1.168217557","rc":[{"batb":[[0,1.04,561.71],[1,1.01,10.51],[2,1.01,0]],"ltp":1.12,"tv":1337.08,"id":2263624}]}]}
{"op":"mcm","clk":"1009598330","pt":1580645573448,"mc":[{"id":"1.168217557","rc":[{"batb":[[0,1.14,226.72],[1,1.13,904.5],[2,1.04,561.71]],"ltp":1.12,"tv":1337.08,"id":2263624}]}]}
{"op":"mcm","clk":"1009598407","pt":1580645573941,"mc":[{"id":"1.168217557","rc":[{"batb":[[2,1.12,191.43]],"ltp":1.12,"tv":1337.08,"id":2263624},{"batb":[[1,4.2,20.46],[2,1.01,10.51]],"ltp":2.64,"tv":817.69,"id":7412809}]}]}
{"op":"mcm","clk":"1009598623","pt":1580645575262,"mc":[{"id":"1.168217557","rc":[{"batb":[[0,1.14,394.76]],"batl":[[2,1.18,42.01]],"ltp":1.12,"tv":1337.08,"id":2263624},{"batb":[[1,6.6,6.72],[2,4.2,20.46]],"batl":[[0,8.2,5.04]],"ltp":2.64,"tv":817.69,"id":7412809}]}]}
{"op":"mcm","clk":"1009598814","pt":1580645576439,"mc":[{"id":"1.168217557","rc":[{"batl":[[1,14,62.58]],"ltp":2.64,"tv":817.69,"id":7412809}]}]}
{"op":"mcm","clk":"1009600494","pt":1580645587464,"mc":[{"id":"1.168217557","rc":[{"batb":[[0,1.14,168.04],[1,1.12,191.43],[2,1.06,366.89]],"batl":[[0,1.18,42.01],[1,1.4,927.7],[2,1.18,0]],"ltp":1.12,"tv":1337.08,"id":2263624}]}]}
{"op":"mcm","clk":"1009600625","pt":1580645588350,"mc":[{"id":"1.168217557","rc":[{"batb":[[0,1.06,366.89],[1,1.01,10.51],[2,1.06,0]],"batl":[[0,1.4,927.7],[1,1.4,0]],"ltp":1.12,"tv":1337.08,"id":2263624},{"batb":[[0,4.2,20.46],[1,1.01,10.51],[2,4.2,0]],"batl":[[0,14,62.58],[1,14,0]],"ltp":2.64,"tv":817.69,"id":7412809}]}]}
{"op":"mcm","clk":"1009601442","pt":1580645593058,"mc":[{"id":"1.168217557","rc":[{"batb":[[0,1.16,559.44],[1,1.15,549.21],[2,1.06,366.89]],"batl":[[0,1.18,221.11],[1,1.19,563.12]],"ltp":1.12,"tv":1337.08,"id":2263624}]}]}
{"op":"mcm","clk":"1009601703","pt":1580645594668,"mc":[{"id":"1.168217557","rc":[{"batl":[[2,1.45,839.84]],"ltp":1.12,"tv":1337.08,"id":2263624},{"batl":[[0,12.5,65.97]],"ltp":2.64,"tv":817.69,"id":7412809}]}]}
{"op":"mcm","clk":"1009601859","pt":1580645595575,"mc":[{"id":"1.168217557","rc":[{"batb":[[0,1.06,366.89],[1,1.01,10.51],[2,1.06,0]],"batl":[[0,1.45,839.84],[1,1.19,0],[2,1.45,0]],"ltp":1.12,"tv":1337.08,"id":2263624}]}]}
{"op":"mcm","clk":"1009602318","pt":1580645598574,"mc":[{"id":"1.168217557","rc":[{"batb":[[0,1.08,265.38],[1,1.07,928.92],[2,1.06,366.89]],"batl":[[0,1.3,153.29],[1,1.31,315.82]],"ltp":1.12,"tv":1337.08,"id":2263624}]}]}
{"op":"mcm","clk":"1009603448","pt":1580645606296,"mc":[{"id":"1.168217557","rc":[{"batb":[[0,1.06,366.89],[1,1.01,10.51],[2,1.06,0]],"ltp":1.12,"tv":1337.08,"id":2263624}]}]}
{"op":"mcm","clk":"1009603953","pt":1580645609492,"mc":[{"id":"1.168217557","rc":[{"batb":[[0,1.27,425.86],[1,1.26,408.69],[2,1.06,366.89]],"ltp":1.12,"tv":1337.08,"id":2263624}]}]}
{"op":"mcm","clk":"1009604086","pt":1580645610284,"mc":[{"id":"1.168217557","rc":[{"batb":[[1,1.26,493.35],[2,1.13,180.73]],"ltp":1.12,"tv":1337.08,"id":2263624},{"batb":[[1,2.52,15.66],[2,1.01,10.51]],"ltp":2.64,"tv":817.69,"id":7412809}]}]}
{"op":"mcm","clk":"1009604248","pt":1580645611287,"mc":[{"id":"1.168217557","rc":[{"batb":[[1,1.26,654.67]],"batl":[[2,1.32,42.01]],"ltp":1.12,"tv":1337.08,"id":2263624},{"batb":[[1,4.1,13.44],[2,2.52,15.66]],"batl":[[0,4.8,10.92]],"ltp":2.64,"tv":817.69,"id":7412809}]}]}
{"op":"mcm","clk":"1009604290","pt":1580645611604,"mc":[{"id":"1.168217557","rc":[{"batl":[[1,7.2,92.18]],"ltp":2.64,"tv":817.69,"id":7412809}]}]}
{"op":"mcm","clk":"1009604772","pt":1580645614715,"mc":[{"id":"1.168217557","rc":[{"batb":[[1,1.26,493.35]],"batl":[[2,1.58,650.58]],"ltp":1.12,"tv":1337.08,"id":2263624},{"batl":[[0,7.2,92.18],[1,7.2,0]],"ltp":2.64,"tv":817.69,"id":7412809}]}]}
{"op":"mcm","clk":"1009605227","pt":1580645617744,"mc":[{"id":"1.168217557","rc":[{"batb":[[0,1.27,581.3]],"batl":[[2,1.33,42.01]],"ltp":1.12,"tv":1337.08,"id":2263624},{"batl":[[0,4.7,10.92],[1,7.2,92.18]],"ltp":2.64,"tv":817.69,"id":7412809}]}]}
{"op":"mcm","clk":"1009606333","pt":1580645624348,"mc":[{"id":"1.168217557","rc":[{"batb":[[0,1.13,180.73],[1,1.01,10.51],[2,1.13,0]],"batl":[[0,1.58,650.58],[1,1.31,0],[2,1.33,0]],"ltp":1.12,"tv":1337.08,"id":2263624},{"batb":[[0,2.52,15.42],[1,1.01,10.51],[2,2.52,0]],"batl":[[0,7.2,92.18],[1,7.2,0]],"ltp":2.64,"tv":817.69,"id":7412809}]}]}
{"op":"mcm","clk":"1009606870","pt":1580645627445,"mc":[{"id":"1.168217557","rc":[{"batb":[[0,1.14,604.43],[1,1.13,704.18],[2,1.01,10.51]],"batl":[[0,1.69,216.22],[1,1.71,213.88]],"ltp":1.12,"tv":1337.08,"id":2263624}]}]}
{"op":"mcm","clk":"1009607611","pt":1580645631439,"mc":[{"id":"1.168217557","rc":[{"batl":[[0,1.16,364.59],[1,1.17,633.51]],"ltp":1.12,"tv":1337.08,"id":2263624}]}]}
{"op":"mcm","clk":"1009607763","pt":1580645632344,"mc":[{"id":"1.168217557","rc":[{"batb":[[2,1.06,355.48]],"ltp":1.12,"tv":1337.08,"id":2263624},{"batb":[[0,7,12.67],[1,4.1,21.32],[2,1.01,10.51]],"ltp":2.64,"tv":817.69,"id":7412809}]}]}
{"op":"mcm","clk":"1009607935","pt":1580645633346,"mc":[{"id":"1.168217557","rc":[{"batb":[[0,1.14,772.47]],"batl":[[2,1.18,42.01]],"ltp":1.12,"tv":1337.08,"id":2263624},{"batb":[[1,6.6,6.72],[2,4.1,21.32]],"batl":[[0,8,5.88]],"ltp":2.64,"tv":817.69,"id":7412809}]}]}
{"op":"mcm","clk":"1009608017","pt":1580645633838,"mc":[{"id":"1.168217557","rc":[{"batl":[[1,14,62.58]],"ltp":2.64,"tv":817.69,"id":7412809}]}]}
{"op":"mcm","clk":"1009609764","pt":1580645644366,"mc":[{"id":"1.168217557","rc":[{"batb":[[0,1.06,355.48],[1,1.01,10.51],[2,1.06,0]],"batl":[[0,1.43,872.38],[1,1.17,0],[2,1.18,0]],"ltp":1.12,"tv":1337.08,"id":2263624},{"batb":[[0,4.1,21.32],[1,1.01,10.51],[2,4.1,0]],"batl":[[0,14,62.58],[1,14,0]],"ltp":2.64,"tv":817.69,"id":7412809}]}]}
{"op":"mcm","clk":"1009610143","pt":1580645646465,"mc":[{"id":"1.168217557","rc":[{"batb":[[0,1.08,673.98],[1,1.07,516.5],[2,1.06,355.48]],"batl":[[0,1.31,218.37],[1,1.32,302.6]],"ltp":1.12,"tv":1337.08,"id":2263624}]}]}
{"op":"mcm","clk":"1009612183","pt":1580645659483,"mc":[{"id":"1.168217557","rc":[{"batb":[[0,1.08,842.02]],"batl":[[0,1.09,177.74],[1,1.1,988.02]],"ltp":1.12,"tv":1337.08,"id":2263624},{"batb":[[0,11,10.78],[1,6.8,13.69],[2,4.1,21.32]],"batl":[[0,13,3.36]],"ltp":2.64,"tv":817.69,"id":7412809}]}]}
{"op":"mcm","clk":"1009612210","pt":1580645659651,"mc":[{"id":"1.168217557","rc":[{"batb":[[2,1.01,10.51]],"ltp":2.64,"tv":817.69,"id":7412809}]}]}
{"op":"mcm","clk":"1009612584","pt":1580645662095,"mc":[{"id":"1.168217557","rc":[{"batl":[[2,1.35,1057.18]],"ltp":1.12,"tv":1337.08,"id":2263624},{"batl":[[1,30,47.16]],"ltp":2.64,"tv":817.69,"id":7412809}]}]}
{"op":"mcm","clk":"1009614470","pt":1580645674324,"mc":[{"id":"1.168217557","rc":[{"batl":[[2,1.11,42.01]],"ltp":1.12,"tv":1337.08,"id":2263624},{"batb":[[1,10,4.2],[2,6.8,13.69]],"ltp":2.64,"tv":817.69,"id":7412809}]}]}
{"op":"mcm","clk":"1009615037","pt":1580645678357,"mc":[{"id":"1.168217557","rc":[{"batb":[[0,1.03,628.83],[1,1.01,10.51],[2,1.06,0]],"batl":[[0,1.35,1057.18],[1,1.1,0],[2,1.11,0]],"ltp":1.12,"tv":1337.08,"id":2263624},{"batb":[[0,6.8,13.69],[1,1.01,10.51],[2,6.8,0]],"batl":[[0,30,47.16],[1,30,0]],"ltp":2.64,"tv":817.69,"id":7412809}]}]}
{"op":"mcm","clk":"1009615487","pt":1580645681041,"mc":[{"id":"1.168217557","rc":[{"batb":[[0,1.05,523.57],[1,1.04,702.69],[2,1.03,628.83]],"batl":[[0,1.17,664.06],[1,1.18,426.78],[2,1.35,1057.18]],"ltp":1.12,"tv":1337.08,"id":2263624}]}]}
{"op":"mcm","clk":"1009615989","pt":1580645684174,"mc":[{"id":"1.168217557","rc":[{"batl":[[0,1.35,1057.18],[1,1.18,0],[2,1.35,0]],"ltp":1.12,"tv":1337.08,"id":2263624}]}]}
{"op":"mcm","clk":"1009616497","pt":1580645687423,"mc":[{"id":"1.168217557","rc":[{"batl":[[0,1.06,1072.83],[1,1.35,1057.18]],"ltp":1.12,"tv":1337.08,"id":2263624}]}]}
{"op":"mcm","clk":"1009616561","pt":1580645687834,"mc":[{"id":"1.168217557","rc":[{"batb":[[0,17,4.17],[1,14.5,5.74],[2,1.01,10.51]],"ltp":2.64,"tv":817.69,"id":7412809}]}]}
{"op":"mcm","clk":"1009616792","pt":1580645689331,"mc":[{"id":"1.168217557","rc":[{"batb":[[0,1.05,691.61]],"batl":[[1,1.07,42.01],[2,1.35,1057.18]],"ltp":1.12,"tv":1337.08,"id":2263624}]}]}
{"op":"mcm","clk":"1009617004","pt":1580645690756,"mc":[{"id":"1.168217557","rc":[{"batl":[[0,65,40.67]],"ltp":2.64,"tv":817.69,"id":7412809}]}]}
{"op":"mcm","clk":"1009619633","pt":1580645707257,"mc":[{"id":"1.168217557","rc":[{"trd":[[1.06,20.59]],"batl":[[0,1.06,1052.24]],"ltp":1.06,"tv":1357.67,"id":2263624},{"trd":[[17.5,1.25]],"ltp":17.5,"tv":818.94,"id":7412809}],"tv":2176.62}]}
{"op":"mcm","clk":"1009620095","pt":1580645710260,"mc":[{"id":"1.168217557","rc":[{"batl":[[1,1000,1.7]],"ltp":17.5,"tv":818.94,"id":7412809}]}]}
{"op":"mcm","clk":"1009620181","pt":1580645710881,"mc":[{"id":"1.168217557","rc":[{"batl":[[1,1000,0]],"ltp":17.5,"tv":818.94,"id":7412809}]}]}
{"op":"mcm","clk":"1009620689","pt":1580645713960,"mc":[{"id":"1.168217557","rc":[{"trd":[[1.05,1.14],[1.06,20.87]],"batb":[[0,1.05,691.04]],"batl":[[0,1.06,1051.96]],"ltp":1.06,"tv":1359.1,"id":2263624},{"trd":[[17.5,1.26]],"ltp":17.5,"tv":818.95,"id":7412809}],"tv":2178.06}]}
{"op":"mcm","clk":"1009622170","pt":1580645724256,"mc":[{"id":"1.168217557","rc":[{"batb":[[0,1.05,168.04],[1,1.03,628.83],[2,1.02,897.76]],"batl":[[0,1.07,42.01],[1,1.35,1057.18],[2,1.35,0]],"ltp":1.06,"tv":1359.1,"id":2263624}]}]}
{"op":"mcm","clk":"1009622617","pt":1580645727180,"mc":[{"id":"1.168217557","rc":[{"batb":[[1,1.03,1872.09]],"batl":[[0,1.07,884.95],[1,1.08,350.56],[2,1.35,1057.18]],"ltp":1.06,"tv":1359.1,"id":2263624}]}]}
{"op":"mcm","clk":"1009623359","pt":1580645732321,"mc":[{"id":"1.168217557","rc":[{"batb":[[0,1.03,1243.26],[1,1.02,897.76],[2,1.01,10.51]],"batl":[[0,1.07,842.94]],"ltp":1.06,"tv":1359.1,"id":2263624},{"batb":[[0,14.5,5.74],[1,1.01,10.51],[2,1.01,0]],"ltp":17.5,"tv":818.95,"id":7412809}]}]}
{"op":"mcm","clk":"1009623933","pt":1580645736194,"mc":[{"id":"1.168217557","rc":[{"batl":[[0,1.35,1057.18],[1,1.08,0],[2,1.35,0]],"ltp":1.06,"tv":1359.1,"id":2263624}]}]}
{"op":"mcm","clk":"1009624464","pt":1580645739501,"mc":[{"id":"1.168217557","rc":[{"batl":[[0,1.05,1219.58],[1,1.35,1057.18]],"ltp":1.06,"tv":1359.1,"id":2263624}]}]}
{"op":"mcm","clk":"1009624580","pt":1580645740289,"mc":[{"id":"1.168217557","rc":[{"batb":[[0,22,4.04],[1,17.5,7.63],[2,1.01,10.51]],"ltp":17.5,"tv":818.95,"id":7412809}]}]}
{"op":"mcm","clk":"1009624900","pt":1580645742508,"mc":[{"id":"1.168217557","rc":[{"batl":[[0,160,37.1]],"ltp":17.5,"tv":818.95,"id":7412809}]}]}
{"op":"mcm","clk":"1009626207","pt":1580645751320,"mc":[{"id":"1.168217557","rc":[{"batb":[[0,1.02,897.76],[1,1.01,10.51],[2,1.01,0]],"batl":[[0,1.35,1057.18],[1,1.35,0]],"ltp":1.06,"tv":1359.1,"id":2263624}]}]}
{"op":"mcm","clk":"1009626249","pt":1580645751641,"mc":[{"id":"1.168217557","rc":[{"batb":[[0,1.01,10.51],[1,1.01,0]],"ltp":1.06,"tv":1359.1,"id":2263624},{"batb":[[0,17.5,7.63],[1,1.01,10.51],[2,1.01,0]],"ltp":17.5,"tv":818.95,"id":7412809}]}]}
{"op":"mcm","clk":"1009626580","pt":1580645754133,"mc":[{"id":"1.168217557","rc":[{"batb":[[0,1.02,1255.45],[1,1.01,10.51]],"batl":[[0,1.06,1208.07]],"ltp":1.06,"tv":1359.1,"id":2263624}]}]}
{"op":"mcm","clk":"1009626714","pt":1580645755232,"mc":[{"id":"1.168217557","rc":[{"batb":[[0,1.01,10.51],[1,1.01,0]],"ltp":1.06,"tv":1359.1,"id":2263624}]}]}
{"op":"mcm","clk":"1009627131","pt":1580645758370,"mc":[{"id":"1.168217557","rc":[{"batb":[[0,1.03,1243.26],[1,1.01,10.51]],"batl":[[0,1.04,767.21],[1,1.05,422.98]],"ltp":1.06,"tv":1359.1,"id":2263624}]}]}
{"op":"mcm","clk":"1009627521","pt":1580645761222,"mc":[{"id":"1.168217557","rc":[{"batl":[[1,1.05,459.66]],"ltp":1.06,"tv":1359.1,"id":2263624}]}]}
{"op":"mcm","clk":"1009628044","pt":1580645765348,"mc":[{"id":"1.168217557","rc":[{"batb":[[0,1.01,10.51],[1,1.01,0]],"ltp":1.06,"tv":1359.1,"id":2263624}]}]}
{"op":"mcm","clk":"1009628389","pt":1580645768050,"mc":[{"id":"1.168217557","rc":[{"batb":[[0,1.02,1255.45],[1,1.01,10.51]],"batl":[[0,1.06,1208.07]],"ltp":1.06,"tv":1359.1,"id":2263624}]}]}
{"op":"mcm","clk":"1009628880","pt":1580645772004,"mc":[{"id":"1.168217557","rc":[{"batl":[[0,1.03,15.14],[1,1.06,1208.07]],"ltp":1.06,"tv":1359.1,"id":2263624}]}]}
{"op":"mcm","clk":"1009629695","pt":1580645778344,"mc":[{"id":"1.168217557","rc":[{"batb":[[0,1.01,10.51],[1,1.01,0]],"ltp":1.06,"tv":1359.1,"id":2263624}]}]}
{"op":"mcm","clk":"1009630154","pt":1580645781427,"mc":[{"id":"1.168217557","rc":[{"trd":[[1.03,30.28]],"batb":[[0,1.04,1216.16],[1,1.03,15.12],[2,1.01,10.51]],"batl":[[0,1.06,1208.07],[1,1.06,0]],"ltp":1.03,"tv":1389.38,"id":2263624}],"tv":2208.34}]}
{"op":"mcm","clk":"1009630188","pt":1580645781747,"mc":[{"id":"1.168217557","rc":[{"batb":[[1,1.03,659.12]],"ltp":1.03,"tv":1389.38,"id":2263624},{"batb":[[1,14.5,5.74],[2,1.01,10.51]],"ltp":17.5,"tv":818.95,"id":7412809}]}]}
{"op":"mcm","clk":"1009630553","pt":1580645784343,"mc":[{"id":"1.168217557","rc":[{"batl":[[1,1.32,1159.8]],"ltp":1.03,"tv":1389.38,"id":2263624},{"batl":[[0,65,40.67]],"ltp":17.5,"tv":818.95,"id":7412809}]}]}
{"op":"mcm","clk":"1009631945","pt":1580645794442,"mc":[{"id":"1.168217557","rc":[{"batb":[[0,1.01,10.51],[1,1.03,0],[2,1.01,0]],"batl":[[0,1.32,1159.8],[1,1.32,0]],"ltp":1.03,"tv":1389.38,"id":2263624},{"batb":[[0,14.5,5.74],[1,1.01,10.51],[2,1.01,0]],"ltp":17.5,"tv":818.95,"id":7412809}]}]}
{"op":"mcm","clk":"1009632347","pt":1580645797472,"mc":[{"id":"1.168217557","rc":[{"batb":[[0,1.03,1243.26],[1,1.01,10.51]],"batl":[[0,1.07,731.29],[1,1.08,461.18],[2,1.32,1159.8]],"ltp":1.03,"tv":1389.38,"id":2263624}]}]}
{"op":"mcm","clk":"1009632883","pt":1580645801348,"mc":[{"id":"1.168217557","rc":[{"batb":[[0,1.01,10.51],[1,1.01,0]],"ltp":1.03,"tv":1389.38,"id":2263624}]}]}
{"op":"mcm","clk":"1009633242","pt":1580645804058,"mc":[{"id":"1.168217557","rc":[{"batb":[[0,1.06,525.37],[1,1.05,689.2],[2,1.04,512.85]],"ltp":1.03,"tv":1389.38,"id":2263624},{"batb":[[1,12.5,7.95],[2,1.01,10.51]],"ltp":17.5,"tv":818.95,"id":7412809}]}]}
{"op":"mcm","clk":"1009633429","pt":1580645805462,"mc":[{"id":"1.168217557","rc":[{"batl":[[1,1.08,503.19]],"ltp":1.03,"tv":1389.38,"id":2263624},{"batb":[[1,13.5,3.36],[2,12.5,7.95]],"ltp":17.5,"tv":818.95,"id":7412809}]}]}
{"op":"mcm","clk":"1009633538","pt":1580645806467,"mc":[{"id":"1.168217557","rc":[{"batl":[[0,42,43.68]],"ltp":17.5,"tv":818.95,"id":7412809}]}]}
{"op":"mcm","clk":"1009634620","pt":1580645814504,"mc":[{"id":"1.168217557","rc":[{"batb":[[0,1.04,512.85],[1,1.03,692.4],[2,1.01,10.51]],"batl":[[0,1.08,461.18],[1,1.32,1159.8],[2,1.32,0]],"ltp":1.03,"tv":1389.38,"id":2263624},{"batb":[[1,12.5,7.95],[2,1.01,10.51]],"ltp":17.5,"tv":818.95,"id":7412809}]}]}
{"op":"mcm","clk":"1009634629","pt":1580645814563,"mc":[{"id":"1.168217557","rc":[{"batb":[[0,1.03,692.4],[1,1.01,10.51],[2,1.01,0]],"ltp":1.03,"tv":1389.38,"id":2263624},{"batb":[[0,12.5,7.95],[1,1.01,10.51],[2,1.01,0]],"ltp":17.5,"tv":818.95,"id":7412809}]}]}
{"op":"mcm","clk":"1009634959","pt":1580645816879,"mc":[{"id":"1.168217557","rc":[{"batb":[[0,1.04,1231.3],[1,1.03,692.4],[2,1.01,10.51]],"batl":[[0,1.08,556.18],[1,1.09,623.74],[2,1.32,1159.8]],"ltp":1.03,"tv":1389.38,"id":2263624}]}]}
{"op":"mcm","clk":"1009635195","pt":1580645818578,"mc":[{"id":"1.168217557","rc":[{"batb":[[0,1.03,692.4],[1,1.01,10.51],[2,1.01,0]],"ltp":1.03,"tv":1389.38,"id":2263624}]}]}
{"op":"mcm","clk":"1009635595","pt":1580645821502,"mc":[{"id":"1.168217557","rc":[{"batb":[[0,1.07,449.29],[1,1.06,754.54],[2,1.03,692.4]],"ltp":1.03,"tv":1389.38,"id":2263624}]}]}
{"op":"mcm","clk":"1009635748","pt":1580645822487,"mc":[{"id":"1.168217557","rc":[{"batb":[[2,1.05,423.86]],"ltp":1.03,"tv":1389.38,"id":2263624},{"batb":[[1,12,8.97],[2,1.01,10.51]],"ltp":17.5,"tv":818.95,"id":7412809}]}]}
{"op":"mcm","clk":"1009635885","pt":1580645823500,"mc":[{"id":"1.168217557","rc":[{"batl":[[1,1.09,665.75]],"ltp":1.03,"tv":1389.38,"id":2263624},{"batb":[[1,12,12.33]],"ltp":17.5,"tv":818.95,"id":7412809}]}]}
{"op":"mcm","clk":"1009636876","pt":1580645830512,"mc":[{"id":"1.168217557","rc":[{"batb":[[0,1.06,754.54],[1,1.04,494.44],[2,1.01,10.51]],"batl":[[0,1.09,623.74],[1,1.32,1159.8],[2,1.32,0]],"ltp":1.03,"tv":1389.38,"id":2263624},{"batb":[[0,12,8.97],[1,1.01,10.51],[2,1.01,0]],"ltp":17.5,"tv":818.95,"id":7412809}]}]}
{"op":"mcm","clk":"1009637235","pt":1580645833427,"mc":[{"id":"1.168217557","rc":[{"batb":[[0,1.06,947.61],[1,1.05,262.93],[2,1.04,494.44]],"batl":[[0,1.09,1028.22]],"ltp":1.03,"tv":1389.38,"id":2263624}]}]}
{"op":"mcm","clk":"1009638017","pt":1580645839695,"mc":[{"id":"1.168217557","rc":[{"batl":[[0,13.5,3.79],[1,42,43.68]],"ltp":17.5,"tv":818.95,"id":7412809}]}]}
{"op":"mcm","clk":"1009638729","pt":1580645845443,"mc":[{"id":"1.168217557","rc":[{"trd":[[1.09,106.31]],"batl":[[0,1.09,975.05]],"ltp":1.09,"tv":1495.69,"id":2263624},{"batl":[[0,42,43.68],[1,42,0]],"ltp":17.5,"tv":818.95,"id":7412809}],"tv":2314.65}]}
{"op":"mcm","clk":"1009638982","pt":1580645847328,"mc":[{"id":"1.168217557","rc":[{"batb":[[0,1.04,494.44],[1,1.01,10.51],[2,1.04,0]],"ltp":1.09,"tv":1495.69,"id":2263624}]}]}
{"op":"mcm","clk":"1009639155","pt":1580645848662,"mc":[{"id":"1.168217557","rc":[{"batl":[[0,1.09,1008.75]],"ltp":1.09,"tv":1495.69,"id":2263624}]}]}
{"op":"mcm","clk":"1009639399","pt":1580645850411,"mc":[{"id":"1.168217557","rc":[{"batb":[[0,1.07,1196.78],[1,1.06,394.04],[2,1.04,494.44]],"ltp":1.09,"tv":1495.69,"id":2263624},{"batb":[[1,6.8,13.77],[2,1.01,10.51]],"ltp":17.5,"tv":818.95,"id":7412809}]}]}
{"op":"mcm","clk":"1009639550","pt":1580645851521,"mc":[{"id":"1.168217557","rc":[{"batb":[[0,1.07,1364.82],[2,1.02,820.34]],"ltp":1.09,"tv":1495.69,"id":2263624},{"batb":[[1,11.5,3.36],[2,6.8,13.77]],"ltp":17.5,"tv":818.95,"id":7412809}]}]}
{"op":"mcm","clk":"1009641651","pt":1580645866689,"mc":[{"id":"1.168217557","rc":[{"batl":[[0,1.09,1159.77]],"ltp":1.09,"tv":1495.69,"id":2263624}]}]}
{"op":"mcm","clk":"1009643767","pt":1580645882468,"mc":[{"id":"1.168217557","rc":[{"trd":[[1.07,76]],"batb":[[0,1.07,1326.82]],"ltp":1.07,"tv":1571.69,"id":2263624}],"tv":2390.65}]}
{"op":"mcm","clk":"1009644722","pt":1580645889703,"mc":[{"id":"1.168217557","rc":[{"batb":[[0,1.07,1270.47]],"ltp":1.07,"tv":1571.69,"id":2263624}]}]}
{"op":"mcm","clk":"1009645529","pt":1580645895594,"mc":[{"id":"1.168217557","rc":[{"batb":[[0,1.07,1150.78]],"ltp":1.07,"tv":1571.69,"id":2263624}]}]}
{"op":"mcm","clk":"1009645903","pt":1580645898482,"mc":[{"id":"1.168217557","rc":[{"batb":[[1,1.06,610.09]],"ltp":1.07,"tv":1571.69,"id":2263624}]}]}
{"op":"mcm","clk":"1009649492","pt":1580645927316,"mc":[{"id":"1.168217557","rc":[{"batb":[[0,1.07,168.04],[1,1.06,394.04]],"batl":[[0,1.32,1159.8],[1,1.32,0]],"ltp":1.07,"tv":1571.69,"id":2263624}]}]}
{"op":"mcm","clk":"1009649577","pt":1580645927947,"mc":[{"id":"1.168217557","rc":[{"batb":[[1,1.02,820.34],[2,1.01,10.51]],"ltp":1.07,"tv":1571.69,"id":2263624},{"batb":[[0,11.5,3.36],[1,6.8,13.77],[2,1.01,10.51]],"ltp":17.5,"tv":818.95,"id":7412809}]}]}
{"op":"mcm","clk":"1009649683","pt":1580645928735,"mc":[{"id":"1.168217557","rc":[{"batb":[[0,1.02,820.34],[1,1.01,10.51],[2,1.01,0]],"ltp":1.07,"tv":1571.69,"id":2263624},{"batb":[[0,6.8,13.77],[1,1.01,10.51],[2,1.01,0]],"ltp":17.5,"tv":818.95,"id":7412809}]}]}
{"op":"mcm","clk":"1009649902","pt":1580645930320,"mc":[{"id":"1.168217557","rc":[{"batb":[[0,1.03,1243.26],[1,1.02,820.34],[2,1.01,10.51]],"batl":[[0,1.16,192.84],[1,1.17,657.09]],"ltp":1.07,"tv":1571.69,"id":2263624}]}]}
{"op":"mcm","clk":"1009650181","pt":1580645932439,"mc":[{"id":"1.168217557","rc":[{"batb":[[0,1.02,820.34],[1,1.01,10.51],[2,1.01,0]],"ltp":1.07,"tv":1571.69,"id":2263624}]}]}
{"op":"mcm","clk":"1009650586","pt":1580645935521,"mc":[{"id":"1.168217557","rc":[{"batb":[[0,1.14,836.56],[1,1.13,289.26],[2,1.02,820.34]],"ltp":1.07,"tv":1571.69,"id":2263624}]}]}
{"op":"mcm","clk":"1009650678","pt":1580645936252,"mc":[{"id":"1.168217557","rc":[{"batb":[[0,1.14,1004.6],[1,1.13,463.54],[2,1.07,322.44]],"batl":[[2,1.18,42.01]],"ltp":1.07,"tv":1571.69,"id":2263624},{"batb":[[0,6.8,20.49],[1,4,22.82],[2,1.01,10.51]],"batl":[[0,8.2,5.04]],"ltp":17.5,"tv":818.95,"id":7412809}]}]}
{"op":"mcm","clk":"1009650818","pt":1580645937459,"mc":[{"id":"1.168217557","rc":[{"batl":[[1,14,62.58]],"ltp":17.5,"tv":818.95,"id":7412809}]}]}
{"op":"mcm","clk":"1009652446","pt":1580645950393,"mc":[{"id":"1.168217557","rc":[{"batb":[[0,1.14,168.04],[1,1.07,322.44],[2,1.01,10.51]],"batl":[[0,1.18,42.01],[1,1.43,872.38],[2,1.18,0]],"ltp":1.07,"tv":1571.69,"id":2263624},{"batb":[[0,6.8,6.72]],"ltp":17.5,"tv":818.95,"id":7412809}]}]}
{"op":"mcm","clk":"1009652484","pt":1580645950688,"mc":[{"id":"1.168217557","rc":[{"batb":[[0,1.07,322.44],[1,1.01,10.51],[2,1.01,0]],"batl":[[0,1.43,872.38],[1,1.43,0]],"ltp":1.07,"tv":1571.69,"id":2263624},{"batb":[[0,4,22.82],[1,1.01,10.51],[2,1.01,0]],"batl":[[0,14,62.58],[1,14,0]],"ltp":17.5,"tv":818.95,"id":7412809}]}]}
{"op":"mcm","clk":"1009652840","pt":1580645953459,"mc":[{"id":"1.168217557","rc":[{"batb":[[0,1.08,1185.7],[1,1.07,322.44],[2,1.01,10.51]],"ltp":1.07,"tv":1571.69,"id":2263624}]}]}
{"op":"mcm","clk":"1009653217","pt":1580645956453,"mc":[{"id":"1.168217557","rc":[{"batl":[[0,1.1,806.29],[1,1.11,354.62]],"ltp":1.07,"tv":1571.69,"id":2263624}]}]}
{"op":"mcm","clk":"1009653348","pt":1580645957463,"mc":[{"id":"1.168217557","rc":[{"batb":[[2,1.02,765.81]],"ltp":1.07,"tv":1571.69,"id":2263624},{"batb":[[0,10.5,12.75],[1,5.6,10.86],[2,1.01,10.51]],"ltp":17.5,"tv":818.95,"id":7412809}]}]}
{"op":"mcm","clk":"1009653374","pt":1580645957668,"mc":[{"id":"1.168217557","rc":[{"batb":[[0,1.08,1353.74]],"batl":[[1,1.11,396.63]],"ltp":1.07,"tv":1571.69,"id":2263624},{"batb":[[1,10,4.2],[2,5.6,10.86]],"batl":[[0,13,3.36]],"ltp":17.5,"tv":818.95,"id":7412809}]}]}
{"op":"mcm","clk":"1009653604","pt":1580645959669,"mc":[{"id":"1.168217557","rc":[{"batl":[[2,1.35,1057.18]],"ltp":1.07,"tv":1571.69,"id":2263624},{"batl":[[1,30,47.16]],"ltp":17.5,"tv":818.95,"id":7412809}]}]}
{"op":"mcm","clk":"1009654728","pt":1580645969496,"mc":[{"id":"1.168217557","rc":[{"batb":[[0,1.08,168.04],[1,1.02,765.81],[2,1.01,10.51]],"batl":[[0,1.11,42.01],[1,1.35,1057.18],[2,1.35,0]],"ltp":1.07,"tv":1571.69,"id":2263624},{"batb":[[0,10,4.2],[1,5.6,10.86],[2,1.01,10.51]],"ltp":17.5,"tv":818.95,"id":7412809}]}]}
{"op":"mcm","clk":"1009654836","pt":1580645970403,"mc":[{"id":"1.168217557","rc":[{"batl":[[1,1.35,0]],"ltp":1.07,"tv":1571.69,"id":2263624},{"batl":[[1,30,0]],"ltp":17.5,"tv":818.95,"id":7412809}]}]}
{"op":"mcm","clk":"1009654880","pt":1580645970825,"mc":[{"id":"1.168217557","rc":[{"batb":[[0,1.02,765.81],[1,1.01,10.51],[2,1.01,0]],"ltp":1.07,"tv":1571.69,"id":2263624},{"batb":[[0,5.6,10.86],[1,1.01,10.51],[2,1.01,0]],"ltp":17.5,"tv":818.95,"id":7412809}]}]}
{"op":"mcm","clk":"1009654967","pt":1580645971598,"mc":[{"id":"1.168217557","rc":[{"batb":[[0,1.04,540.63],[1,1.03,697.37],[2,1.02,765.81]],"batl":[[0,1.21,493.68],[1,1.22,478.15]],"ltp":1.07,"tv":1571.69,"id":2263624}]}]}
{"op":"mcm","clk":"1009655694","pt":1580645977514,"mc":[{"id":"1.168217557","rc":[{"batl":[[0,1.05,1219.58]],"ltp":1.07,"tv":1571.69,"id":2263624},{"batb":[[0,19.5,5.9],[1,9,7.08],[2,1.01,10.51]],"ltp":17.5,"tv":818.95,"id":7412809}]}]}
{"op":"mcm","clk":"1009655917","pt":1580645979240,"mc":[{"id":"1.168217557","rc":[{"batl":[[1,1.3,1224.86]],"ltp":1.07,"tv":1571.69,"id":2263624},{"batl":[[0,160,37.1]],"ltp":17.5,"tv":818.95,"id":7412809}]}]}
{"op":"mcm","clk":"1009656665","pt":1580645985472,"mc":[{"id":"1.168217557","rc":[{"batb":[[0,1.01,10.51],[1,1.03,0],[2,1.02,0]],"batl":[[0,1.3,1224.86],[1,1.3,0]],"ltp":1.07,"tv":1571.69,"id":2263624},{"batb":[[0,9,7.08],[1,1.01,10.51],[2,1.01,0]],"ltp":17.5,"tv":818.95,"id":7412809}]}]}
{"op":"mcm","clk":"1009657239","pt":1580645990431,"mc":[{"id":"1.168217557","rc":[{"batb":[[0,1.05,928.15],[1,1.04,294.22],[2,1.01,10.51]],"batl":[[0,1.06,788.55],[1,1.07,415.6]],"ltp":1.07,"tv":1571.69,"id":2263624}]}]}
{"op":"mcm","clk":"1009657502","pt":1580645992299,"mc":[{"id":"1.168217557","rc":[{"batl":[[2,1.32,1159.8]],"ltp":1.07,"tv":1571.69,"id":2263624},{"batl":[[0,65,40.67]],"ltp":17.5,"tv":818.95,"id":7412809}]}]}
{"op":"mcm","clk":"1009657885","pt":1580645995210,"mc":[{"id":"1.168217557","rc":[{"batb":[[0,1.01,10.51],[1,1.04,0],[2,1.01,0]],"batl":[[0,1.32,1159.8],[1,1.07,0],[2,1.32,0]],"ltp":1.07,"tv":1571.69,"id":2263624}]}]}
{"op":"mcm","clk":"1009658301","pt":1580645998423,"mc":[{"id":"1.168217557","rc":[{"batb":[[0,1.01,1278.39]],"batl":[[0,1.12,1033.58]],"ltp":1.07,"tv":1571.69,"id":2263624}]}]}
{"op":"mcm","clk":"1009659951","pt":1580646010434,"mc":[{"id":"1.168217557","rc":[{"batl":[[0,1.02,1255.45]],"ltp":1.07,"tv":1571.69,"id":2263624},{"batb":[[0,22,3.82],[1,9,7.08],[2,1.01,10.51]],"ltp":17.5,"tv":818.95,"id":7412809}]}]}
{"op":"mcm","clk":"1009659977","pt":1580646010637,"mc":[{"id":"1.168217557","rc":[{"batb":[[1,1.01,10.51],[2,1.01,0]],"ltp":17.5,"tv":818.95,"id":7412809}]}]}
{"op":"mcm","clk":"1009660224","pt":1580646012343,"mc":[{"id":"1.168217557","rc":[{"batl":[[1,1.27,1360.38]],"ltp":1.07,"tv":1571.69,"id":2263624}]}]}
{"op":"mcm","clk":"1009661811","pt":1580646025263,"mc":[{"id":"1.168217557","rc":[{"batb":[[0,1.01,10.51]],"batl":[[0,1.27,1360.38],[1,1.27,0]],"ltp":1.07,"tv":1571.69,"id":2263624}]}]}
{"op":"mcm","clk":"1009662090","pt":1580646027665,"mc":[{"id":"1.168217557","rc":[{"batl":[[0,1.04,1056.82]],"ltp":1.07,"tv":1571.69,"id":2263624}]}]}
{"op":"mcm","clk":"1009663587","pt":1580646039463,"mc":[{"id":"1.168217557","rc":[{"batb":[[0,1.03,1243.26],[1,1.01,10.51]],"ltp":1.07,"tv":1571.69,"id":2263624}]}]}
{"op":"mcm","clk":"1009663711","pt":1580646040292,"mc":[{"id":"1.168217557","rc":[{"batb":[[0,1.03,1411.3],[1,1.02,934.27],[2,1.01,10.51]],"ltp":1.07,"tv":1571.69,"id":2263624},{"batb":[[1,8.8,7.71],[2,1.01,10.51]],"ltp":17.5,"tv":818.95,"id":7412809}]}]}
{"op":"mcm","clk":"1009663956","pt":1580646041781,"mc":[{"id":"1.168217557","rc":[{"batl":[[1,1.3,1255.97]],"ltp":1.07,"tv":1571.69,"id":2263624},{"batl":[[0,520,35.52]],"ltp":17.5,"tv":818.95,"id":7412809}]}]}
{"op":"mcm","clk":"1009666346","pt":1580646059473,"mc":[{"id":"1.168217557","rc":[{"batb":[[0,1.03,168.04]],"batl":[[0,1.3,1255.97],[1,1.3,0]],"ltp":1.07,"tv":1571.69,"id":2263624}]}]}
{"op":"mcm","clk":"1009666385","pt":1580646059822,"mc":[{"id":"1.168217557","rc":[{"batb":[[1,1.01,10.51],[2,1.01,0]],"ltp":1.07,"tv":1571.69,"id":2263624},{"batb":[[0,8.8,7.71],[1,1.01,10.51],[2,1.01,0]],"ltp":17.5,"tv":818.95,"id":7412809}]}]}
{"op":"mcm","clk":"1009666499","pt":1580646060790,"mc":[{"id":"1.168217557","rc":[{"batb":[[0,1.01,10.51],[1,1.01,0]],"ltp":1.07,"tv":1571.69,"id":2263624}]}]}
{"op":"mcm","clk":"1009666747","pt":1580646062399,"mc":[{"id":"1.168217557","rc":[{"batl":[[0,1.12,686.15],[1,1.13,453.15]],"ltp":1.07,"tv":1571.69,"id":2263624}]}]}
{"op":"mcm","clk":"1009667132","pt":1580646064888,"mc":[{"id":"1.168217557","rc":[{"batb":[[0,1.04,1231.3],[1,1.01,10.51]],"batl":[[0,1.06,1208.07]],"ltp":1.07,"tv":1571.69,"id":2263624}]}]}
{"op":"mcm","clk":"1009667379","pt":1580646066696,"mc":[{"id":"1.168217557","rc":[{"batl":[[1,1.31,1193.43]],"ltp":1.07,"tv":1571.69,"id":2263624},{"batl":[[0,95,38.77]],"ltp":17.5,"tv":818.95,"id":7412809}]}]}
{"op":"mcm","clk":"1009667608","pt":1580646068305,"mc":[{"id":"1.168217557","rc":[{"batb":[[0,1.01,10.51],[1,1.01,0]],"batl":[[0,1.31,1193.43],[1,1.31,0]],"ltp":1.07,"tv":1571.69,"id":2263624}]}]}
{"op":"mcm","clk":"1009668004","pt":1580646071303,"mc":[{"id":"1.168217557","rc":[{"batl":[[0,1.12,708.71],[1,1.13,430.8]],"ltp":1.07,"tv":1571.69,"id":2263624}]}]}
{"op":"mcm","clk":"1009671592","pt":1580646098707,"mc":[{"id":"1.168217557","marketDefinition":{"bspMarket":false,"turnInPlayEnabled":true,"persistenceEnabled":true,"marketBaseRate":5.0,"eventId":"29681263","eventTypeId":"2","numberOfWinners":1,"bettingType":"ODDS","marketType":"SET_WINNER","marketTime":"2020-02-02T11:07:00.000Z","suspendTime":"2020-02-02T11:07:00.000Z","bspReconciled":false,"complete":true,"inPlay":true,"crossMatching":true,"runnersVoidable":false,"numberOfActiveRunners":2,"betDelay":3,"status":"SUSPENDED","runners":[{"status":"ACTIVE","sortPriority":1,"id":7412809,"name":"Evgeny Karlovskiy"},{"status":"ACTIVE","sortPriority":2,"id":2263624,"name":"Viktor Troicki"}],"regulators":["MR_INT"],"countryCode":"IN","discountAllowed":true,"timezone":"UTC","openDate":"2020-02-02T11:07:00.000Z","version":3148696931,"name":"Set 2 Winner","eventName":"Karlovskiy v Troicki"},"rc":[{"batb":[[0,1.01,10.51],[1,1.01,0]],"ltp":17.5,"tv":818.95,"id":7412809}]}]}
{"op":"mcm","clk":"1009679007","pt":1580646150836,"mc":[{"id":"1.168217557","tv":0.0}]}
{"op":"mcm","clk":"1009679152","pt":1580646151815,"mc":[{"id":"1.168217557","marketDefinition":{"bspMarket":false,"turnInPlayEnabled":true,"persistenceEnabled":true,"marketBaseRate":5.0,"eventId":"29681263","eventTypeId":"2","numberOfWinners":1,"bettingType":"ODDS","marketType":"SET_WINNER","marketTime":"2020-02-02T11:07:00.000Z","suspendTime":"2020-02-02T11:07:00.000Z","bspReconciled":false,"complete":true,"inPlay":true,"crossMatching":false,"runnersVoidable":false,"numberOfActiveRunners":0,"betDelay":3,"status":"CLOSED","settledTime":"2020-02-02T12:22:29.000Z","runners":[{"status":"LOSER","sortPriority":1,"id":7412809,"name":"Evgeny Karlovskiy"},{"status":"WINNER","sortPriority":2,"id":2263624,"name":"Viktor Troicki"}],"regulators":["MR_INT"],"countryCode":"IN","discountAllowed":true,"timezone":"UTC","openDate":"2020-02-02T11:07:00.000Z","version":3148697752,"name":"Set 2 Winner","eventName":"Karlovskiy v Troicki"}}]}
