{"op":"mcm","clk":"1004962286","pt":1580585267691,"mc":[{"id":"1.168224343","marketDefinition":{"bspMarket":false,"turnInPlayEnabled":true,"persistenceEnabled":true,"marketBaseRate":5.0,"eventId":"29681722","eventTypeId":"2","numberOfWinners":1,"bettingType":"ODDS","marketType":"SET_WINNER","marketTime":"2020-02-02T09:00:00.000Z","suspendTime":"2020-02-02T09:00:00.000Z","bspReconciled":false,"complete":true,"inPlay":false,"crossMatching":false,"runnersVoidable":false,"numberOfActiveRunners":2,"betDelay":0,"status":"OPEN","runners":[{"status":"ACTIVE","sortPriority":1,"id":8979329,"name":"Emil Ruusuvuori"},{"status":"ACTIVE","sortPriority":2,"id":2397396,"name":"Matthias Bachinger"}],"regulators":["MR_INT"],"countryCode":"FR","discountAllowed":false,"timezone":"UTC","openDate":"2020-02-02T09:00:00.000Z","version":3147098027,"name":"Set 2 Winner","eventName":"Emil Ruusuvuori v Bachinger"},"rc":[{"batb":[[0,1.01,20]],"ltp":0.0,"tv":0.0,"id":2397396},{"batb":[[0,1.01,20]],"ltp":0.0,"tv":0.0,"id":8979329}]}]}
{"op":"mcm","clk":"1004962420","pt":1580585268465,"mc":[{"id":"1.168224343","marketDefinition":{"bspMarket":false,"turnInPlayEnabled":true,"persistenceEnabled":true,"marketBaseRate":5.0,"eventId":"29681722","eventTypeId":"2","numberOfWinners":1,"bettingType":"ODDS","marketType":"SET_WINNER","marketTime":"2020-02-02T09:00:00.000Z","suspendTime":"2020-02-02T09:00:00.000Z","bspReconciled":false,"complete":true,"inPlay":false,"crossMatching":false,"runnersVoidable":false,"numberOfActiveRunners":2,"betDelay":0,"status":"OPEN","runners":[{"status":"ACTIVE","sortPriority":1,"id":8979329,"name":"Emil Ruusuvuori"},{"status":"ACTIVE","sortPriority":2,"id":2397396,"name":"Matthias Bachinger"}],"regulators":["MR_INT"],"countryCode":"FR","discountAllowed":false,"timezone":"UTC","openDate":"2020-02-02T09:00:00.000Z","version":3147098027,"name":"Set 2 Winner","eventName":"Emil Ruusuvuori v Bachinger"}}]}
{"op":"mcm","clk":"1004962808","pt":1580585270546,"mc":[{"id":"1.168224343","marketDefinition":{"bspMarket":false,"turnInPlayEnabled":true,"persistenceEnabled":true,"marketBaseRate":5.0,"eventId":"29681722","eventTypeId":"2","numberOfWinners":1,"bettingType":"ODDS","marketType":"SET_WINNER","marketTime":"2020-02-02T09:00:00.000Z","suspendTime":"2020-02-02T09:00:00.000Z","bspReconciled":false,"complete":true,"inPlay":false,"crossMatching":false,"runnersVoidable":false,"numberOfActiveRunners":2,"betDelay":0,"status":"OPEN","runners":[{"status":"ACTIVE","sortPriority":1,"id":8979329,"name":"Emil Ruusuvuori"},{"status":"ACTIVE","sortPriority":2,"id":2397396,"name":"Matthias Bachinger"}],"regulators":["MR_INT"],"countryCode":"FR","discountAllowed":true,"timezone":"UTC","openDate":"2020-02-02T09:00:00.000Z","version":3147098027,"name":"Set 2 Winner","eventName":"Emil Ruusuvuori v Bachinger"}}]}
{"op":"mcm","clk":"1004986096","pt":1580585417007,"mc":[{"id":"1.168224343","rc":[{"batb":[[0,1.01,15]],"ltp":0.0,"tv":0.0,"id":2397396},{"batb":[[0,1.01,15]],"ltp":0.0,"tv":0.0,"id":8979329}]}]}
{"op":"mcm","clk":"1005002549","pt":1580585515430,"mc":[{"id":"1.168224343","marketDefinition":{"bspMarket":false,"turnInPlayEnabled":true,"persistenceEnabled":true,"marketBaseRate":5.0,"eventId":"29681722","eventTypeId":"2","numberOfWinners":1,"bettingType":"ODDS","marketType":"SET_WINNER","marketTime":"2020-02-02T11:30:00.000Z","suspendTime":"2020-02-02T11:30:00.000Z","bspReconciled":false,"complete":true,"inPlay":false,"crossMatching":false,"runnersVoidable":false,"numberOfActiveRunners":2,"betDelay":0,"status":"OPEN","runners":[{"status":"ACTIVE","sortPriority":1,"id":8979329,"name":"Emil Ruusuvuori"},{"status":"ACTIVE","sortPriority":2,"id":2397396,"name":"Matthias Bachinger"}],"regulators":["MR_INT"],"countryCode":"FR","discountAllowed":true,"timezone":"UTC","openDate":"2020-02-02T09:00:00.000Z","version":3147124995,"name":"Set 2 Winner","eventName":"Emil Ruusuvuori v Bachinger"}}]}
{"op":"mcm","clk":"1005003169","pt":1580585518494,"mc":[{"id":"1.168224343","marketDefinition":{"bspMarket":false,"turnInPlayEnabled":true,"persistenceEnabled":true,"marketBaseRate":5.0,"eventId":"29681722","eventTypeId":"2","numberOfWinners":1,"bettingType":"ODDS","marketType":"SET_WINNER","marketTime":"2020-02-02T11:30:00.000Z","suspendTime":"2020-02-02T11:30:00.000Z","bspReconciled":false,"complete":true,"inPlay":false,"crossMatching":false,"runnersVoidable":false,"numberOfActiveRunners":2,"betDelay":0,"status":"OPEN","runners":[{"status":"ACTIVE","sortPriority":1,"id":8979329,"name":"Emil Ruusuvuori"},{"status":"ACTIVE","sortPriority":2,"id":2397396,"name":"Matthias Bachinger"}],"regulators":["MR_INT"],"countryCode":"FR","discountAllowed":true,"timezone":"UTC","openDate":"2020-02-02T11:30:00.000Z","version":3147124995,"name":"Set 2 Winner","eventName":"Emil Ruusuvuori v Bachinger"}}]}
{"op":"mcm","clk":"1006924581","pt":1580602185254,"mc":[{"id":"1.168224343","rc":[{"batb":[[0,1.01,17.53]],"ltp":0.0,"tv":0.0,"id":2397396},{"batb":[[0,1.01,17.53]],"ltp":0.0,"tv":0.0,"id":8979329}]}]}
{"op":"mcm","clk":"1006924687","pt":1580602186352,"mc":[{"id":"1.168224343","rc":[{"batb":[[0,1.01,15.51]],"ltp":0.0,"tv":0.0,"id":2397396},{"batb":[[0,1.01,15.51]],"ltp":0.0,"tv":0.0,"id":8979329}]}]}
{"op":"mcm","clk":"1007043396","pt":1580603725304,"mc":[{"id":"1.168224343","rc":[{"batb":[[0,1.01,16.01]],"ltp":0.0,"tv":0.0,"id":2397396},{"batb":[[0,1.01,16.01]],"ltp":0.0,"tv":0.0,"id":8979329}]}]}
{"op":"mcm","clk":"1007202905","pt":1580607092391,"mc":[{"id":"1.168224343","rc":[{"batb":[[0,1.01,18.01]],"ltp":0.0,"tv":0.0,"id":2397396},{"batb":[[0,1.01,18.01]],"ltp":0.0,"tv":0.0,"id":8979329}]}]}
{"op":"mcm","clk":"1007202945","pt":1580607092964,"mc":[{"id":"1.168224343","rc":[{"batb":[[0,1.01,16.02]],"ltp":0.0,"tv":0.0,"id":2397396},{"batb":[[0,1.01,16.02]],"ltp":0.0,"tv":0.0,"id":8979329}]}]}
{"op":"mcm","clk":"1008459426","pt":1580635613340,"mc":[{"id":"1.168224343","marketDefinition":{"bspMarket":false,"turnInPlayEnabled":true,"persistenceEnabled":true,"marketBaseRate":5.0,"eventId":"29681722","eventTypeId":"2","numberOfWinners":1,"bettingType":"ODDS","marketType":"SET_WINNER","marketTime":"2020-02-02T11:24:00.000Z","suspendTime":"2020-02-02T11:24:00.000Z","bspReconciled":false,"complete":true,"inPlay":false,"crossMatching":false,"runnersVoidable":false,"numberOfActiveRunners":2,"betDelay":0,"status":"OPEN","runners":[{"status":"ACTIVE","sortPriority":1,"id":8979329,"name":"Emil Ruusuvuori"},{"status":"ACTIVE","sortPriority":2,"id":2397396,"name":"Matthias Bachinger"}],"regulators":["MR_INT"],"countryCode":"FR","discountAllowed":true,"timezone":"UTC","openDate":"2020-02-02T11:30:00.000Z","version":3148345459,"name":"Set 2 Winner","eventName":"Emil Ruusuvuori v Bachinger"}}]}
{"op":"mcm","clk":"1008459775","pt":1580635616342,"mc":[{"id":"1.168224343","marketDefinition":{"bspMarket":false,"turnInPlayEnabled":true,"persistenceEnabled":true,"marketBaseRate":5.0,"eventId":"29681722","eventTypeId":"2","numberOfWinners":1,"bettingType":"ODDS","marketType":"SET_WINNER","marketTime":"2020-02-02T11:24:00.000Z","suspendTime":"2020-02-02T11:24:00.000Z","bspReconciled":false,"complete":true,"inPlay":false,"crossMatching":false,"runnersVoidable":false,"numberOfActiveRunners":2,"betDelay":0,"status":"OPEN","runners":[{"status":"ACTIVE","sortPriority":1,"id":8979329,"name":"Emil Ruusuvuori"},{"status":"ACTIVE","sortPriority":2,"id":2397396,"name":"Matthias Bachinger"}],"regulators":["MR_INT"],"countryCode":"FR","discountAllowed":true,"timezone":"UTC","openDate":"2020-02-02T11:24:00.000Z","version":3148345459,"name":"Set 2 Winner","eventName":"Emil Ruusuvuori v Bachinger"}}]}
{"op":"mcm","clk":"1008879044","pt":1580640413444,"mc":[{"id":"1.168224343","marketDefinition":{"bspMarket":false,"turnInPlayEnabled":true,"persistenceEnabled":true,"marketBaseRate":5.0,"eventId":"29681722","eventTypeId":"2","numberOfWinners":1,"bettingType":"ODDS","marketType":"SET_WINNER","marketTime":"2020-02-02T10:51:00.000Z","suspendTime":"2020-02-02T10:51:00.000Z","bspReconciled":false,"complete":true,"inPlay":false,"crossMatching":false,"runnersVoidable":false,"numberOfActiveRunners":2,"betDelay":0,"status":"OPEN","runners":[{"status":"ACTIVE","sortPriority":1,"id":8979329,"name":"Emil Ruusuvuori"},{"status":"ACTIVE","sortPriority":2,"id":2397396,"name":"Matthias Bachinger"}],"regulators":["MR_INT"],"countryCode":"FR","discountAllowed":true,"timezone":"UTC","openDate":"2020-02-02T11:24:00.000Z","version":3148437425,"name":"Set 2 Winner","eventName":"Emil Ruusuvuori v Bachinger"}}]}
{"op":"mcm","clk":"1008880280","pt":1580640421273,"mc":[{"id":"1.168224343","marketDefinition":{"bspMarket":false,"turnInPlayEnabled":true,"persistenceEnabled":true,"marketBaseRate":5.0,"eventId":"29681722","eventTypeId":"2","numberOfWinners":1,"bettingType":"ODDS","marketType":"SET_WINNER","marketTime":"2020-02-02T10:51:00.000Z","suspendTime":"2020-02-02T10:51:00.000Z","bspReconciled":false,"complete":true,"inPlay":false,"crossMatching":false,"runnersVoidable":false,"numberOfActiveRunners":2,"betDelay":0,"status":"OPEN","runners":[{"status":"ACTIVE","sortPriority":1,"id":8979329,"name":"Emil Ruusuvuori"},{"status":"ACTIVE","sortPriority":2,"id":2397396,"name":"Matthias Bachinger"}],"regulators":["MR_INT"],"countryCode":"FR","discountAllowed":true,"timezone":"UTC","openDate":"2020-02-02T10:51:00.000Z","version":3148437425,"name":"Set 2 Winner","eventName":"Emil Ruusuvuori v Bachinger"}}]}
{"op":"mcm","clk":"1008903211","pt":1580640611123,"mc":[{"id":"1.168224343","rc":[{"batb":[[0,3.2,19.75],[1,1.01,16.02]],"ltp":0.0,"tv":0.0,"id":2397396},{"batb":[[0,1.39,51.86],[1,1.01,16.01]],"ltp":0.0,"tv":0.0,"id":8979329}]}]}
{"op":"mcm","clk":"1008903436","pt":1580640612891,"mc":[{"id":"1.168224343","marketDefinition":{"bspMarket":false,"turnInPlayEnabled":true,"persistenceEnabled":true,"marketBaseRate":5.0,"eventId":"29681722","eventTypeId":"2","numberOfWinners":1,"bettingType":"ODDS","marketType":"SET_WINNER","marketTime":"2020-02-02T10:51:00.000Z","suspendTime":"2020-02-02T10:51:00.000Z","bspReconciled":false,"complete":true,"inPlay":false,"crossMatching":true,"runnersVoidable":false,"numberOfActiveRunners":2,"betDelay":0,"status":"OPEN","runners":[{"status":"ACTIVE","sortPriority":1,"id":8979329,"name":"Emil Ruusuvuori"},{"status":"ACTIVE","sortPriority":2,"id":2397396,"name":"Matthias Bachinger"}],"regulators":["MR_INT"],"countryCode":"FR","discountAllowed":true,"timezone":"UTC","openDate":"2020-02-02T10:51:00.000Z","version":3148437425,"name":"Set 2 Winner","eventName":"Emil Ruusuvuori v Bachinger"}}]}
{"op":"mcm","clk":"1008906814","pt":1580640640009,"mc":[{"id":"1.168224343","rc":[{"trd":[[3.1,0]],"batb":[[0,3.15,19.82]],"ltp":3.1,"tv":0.0,"id":2397396},{"trd":[[1.48,0.01]],"batb":[[0,1.39,51.85]],"ltp":1.48,"tv":0.01,"id":8979329}],"tv":0.01}]}
{"op":"mcm","clk":"1008910085","pt":1580640668174,"mc":[{"id":"1.168224343","rc":[{"batb":[[0,1.39,51.38]],"ltp":1.48,"tv":0.01,"id":8979329}]}]}
{"op":"mcm","clk":"1008912298","pt":1580640686881,"mc":[{"id":"1.168224343","rc":[{"batb":[[0,1.39,51.14]],"ltp":1.48,"tv":0.01,"id":8979329}]}]}
{"op":"mcm","clk":"1008915480","pt":1580640714233,"mc":[{"id":"1.168224343","marketDefinition":{"bspMarket":false,"turnInPlayEnabled":true,"persistenceEnabled":true,"marketBaseRate":5.0,"eventId":"29681722","eventTypeId":"2","numberOfWinners":1,"bettingType":"ODDS","marketType":"SET_WINNER","marketTime":"2020-02-02T10:48:00.000Z","suspendTime":"2020-02-02T10:48:00.000Z","bspReconciled":false,"complete":true,"inPlay":false,"crossMatching":true,"runnersVoidable":false,"numberOfActiveRunners":2,"betDelay":0,"status":"OPEN","runners":[{"status":"ACTIVE","sortPriority":1,"id":8979329,"name":"Emil Ruusuvuori"},{"status":"ACTIVE","sortPriority":2,"id":2397396,"name":"Matthias Bachinger"}],"regulators":["MR_INT"],"countryCode":"FR","discountAllowed":true,"timezone":"UTC","openDate":"2020-02-02T10:51:00.000Z","version":3148443647,"name":"Set 2 Winner","eventName":"Emil Ruusuvuori v Bachinger"}}]}
{"op":"mcm","clk":"1008915826","pt":1580640717144,"mc":[{"id":"1.168224343","marketDefinition":{"bspMarket":false,"turnInPlayEnabled":true,"persistenceEnabled":true,"marketBaseRate":5.0,"eventId":"29681722","eventTypeId":"2","numberOfWinners":1,"bettingType":"ODDS","marketType":"SET_WINNER","marketTime":"2020-02-02T10:48:00.000Z","suspendTime":"2020-02-02T10:48:00.000Z","bspReconciled":false,"complete":true,"inPlay":false,"crossMatching":true,"runnersVoidable":false,"numberOfActiveRunners":2,"betDelay":0,"status":"OPEN","runners":[{"status":"ACTIVE","sortPriority":1,"id":8979329,"name":"Emil Ruusuvuori"},{"status":"ACTIVE","sortPriority":2,"id":2397396,"name":"Matthias Bachinger"}],"regulators":["MR_INT"],"countryCode":"FR","discountAllowed":true,"timezone":"UTC","openDate":"2020-02-02T10:48:00.000Z","version":3148443647,"name":"Set 2 Winner","eventName":"Emil Ruusuvuori v Bachinger"}}]}
{"op":"mcm","clk":"1008940367","pt":1580640933281,"mc":[{"id":"1.168224343","rc":[{"batb":[[1,3,21],[2,1.01,16.02]],"batl":[[0,3.5,16.8]],"ltp":3.1,"tv":0.0,"id":2397396},{"batb":[[0,1.4,105.02],[1,1.39,51.14],[2,1.01,16.01]],"batl":[[0,1.5,42.01]],"ltp":1.48,"tv":0.01,"id":8979329}]}]}
{"op":"mcm","clk":"1008941438","pt":1580640943369,"mc":[{"id":"1.168224343","rc":[{"batb":[[2,1.01,16.81]],"ltp":3.1,"tv":0.0,"id":2397396},{"batb":[[0,1.41,1.79],[1,1.4,105.02],[2,1.39,51.14]],"ltp":1.48,"tv":0.01,"id":8979329}]}]}
{"op":"mcm","clk":"1008941477","pt":1580640943782,"mc":[{"id":"1.168224343","rc":[{"batb":[[0,3.15,20.61],[2,1.01,16.02]],"ltp":3.1,"tv":0.0,"id":2397396}]}]}
{"op":"mcm","clk":"1008970578","pt":1580641185073,"mc":[{"id":"1.168224343","rc":[{"batb":[[0,3,21.79],[1,1.01,16.02],[2,1.01,0]],"ltp":3.1,"tv":0.0,"id":2397396},{"batb":[[2,1.01,16.01]],"ltp":1.48,"tv":0.01,"id":8979329}]}]}
{"op":"mcm","clk":"1008970700","pt":1580641186080,"mc":[{"id":"1.168224343","marketDefinition":{"bspMarket":false,"turnInPlayEnabled":true,"persistenceEnabled":true,"marketBaseRate":5.0,"eventId":"29681722","eventTypeId":"2","numberOfWinners":1,"bettingType":"ODDS","marketType":"SET_WINNER","marketTime":"2020-02-02T10:48:00.000Z","suspendTime":"2020-02-02T10:48:00.000Z","bspReconciled":false,"complete":true,"inPlay":true,"crossMatching":true,"runnersVoidable":false,"numberOfActiveRunners":2,"betDelay":3,"status":"OPEN","runners":[{"status":"ACTIVE","sortPriority":1,"id":8979329,"name":"Emil Ruusuvuori"},{"status":"ACTIVE","sortPriority":2,"id":2397396,"name":"Matthias Bachinger"}],"regulators":["MR_INT"],"countryCode":"FR","discountAllowed":true,"timezone":"UTC","openDate":"2020-02-02T10:48:00.000Z","version":3148454340,"name":"Set 2 Winner","eventName":"Emil Ruusuvuori v Bachinger"},"rc":[{"batb":[[0,1.01,15.52],[1,1.01,0]],"ltp":3.1,"tv":0.0,"id":2397396},{"batb":[[0,1.01,15.51],[1,1.4,0],[2,1.01,0]],"ltp":1.48,"tv":0.01,"id":8979329}]}]}
{"op":"mcm","clk":"1008971485","pt":1580641192365,"mc":[{"id":"1.168224343","rc":[{"batb":[[0,3.05,21.48],[1,3,22.98],[2,1.01,15.52]],"ltp":3.1,"tv":0.0,"id":2397396},{"batb":[[0,1.41,48.7],[1,1.39,52.17],[2,1.01,15.51]],"ltp":1.48,"tv":0.01,"id":8979329}]}]}
{"op":"mcm","clk":"1008971541","pt":1580641192785,"mc":[{"id":"1.168224343","rc":[{"batb":[[2,2.94,21]],"batl":[[0,3.45,16.8]],"ltp":3.1,"tv":0.0,"id":2397396},{"batb":[[0,1.41,150.37]],"batl":[[0,1.51,42.01]],"ltp":1.48,"tv":0.01,"id":8979329}]}]}
{"op":"mcm","clk":"1008972907","pt":1580641201950,"mc":[{"id":"1.168224343","rc":[{"batb":[[0,3,22.98],[1,2.94,21],[2,1.01,15.52]],"ltp":3.1,"tv":0.0,"id":2397396},{"batb":[[0,1.41,101.66]],"ltp":1.48,"tv":0.01,"id":8979329}]}]}
{"op":"mcm","clk":"1008973312","pt":1580641204264,"mc":[{"id":"1.168224343","rc":[{"batb":[[1,1.01,15.52],[2,1.01,0]],"ltp":3.1,"tv":0.0,"id":2397396},{"batb":[[0,1.39,52.17],[1,1.01,15.51],[2,1.01,0]],"ltp":1.48,"tv":0.01,"id":8979329}]}]}
{"op":"mcm","clk":"1008974280","pt":1580641209372,"mc":[{"id":"1.168224343","rc":[{"batb":[[1,2.96,24],[2,1.01,15.52]],"ltp":3.1,"tv":0.0,"id":2397396},{"batb":[[0,1.43,46.26],[1,1.4,49.41],[2,1.39,734.9]],"ltp":1.48,"tv":0.01,"id":8979329}]}]}
{"op":"mcm","clk":"1008974365","pt":1580641209880,"mc":[{"id":"1.168224343","rc":[{"batb":[[2,1.01,15.51]],"ltp":1.48,"tv":0.01,"id":8979329}]}]}
{"op":"mcm","clk":"1008974489","pt":1580641210667,"mc":[{"id":"1.168224343","rc":[{"batb":[[2,2.9,21.85]],"batl":[[0,3.4,16.8]],"ltp":3.1,"tv":0.0,"id":2397396},{"batb":[[1,1.42,99.98],[2,1.4,49.41]],"batl":[[0,1.53,42.01]],"ltp":1.48,"tv":0.01,"id":8979329}]}]}
{"op":"mcm","clk":"1008975840","pt":1580641219165,"mc":[{"id":"1.168224343","rc":[{"batb":[[0,2.96,24],[1,2.9,21.85],[2,1.01,15.52]],"ltp":3.1,"tv":0.0,"id":2397396},{"batb":[[0,1.42,99.98],[1,1.4,49.41],[2,1.01,15.51]],"ltp":1.48,"tv":0.01,"id":8979329}]}]}
{"op":"mcm","clk":"1008975903","pt":1580641219667,"mc":[{"id":"1.168224343","rc":[{"batb":[[1,1.01,15.52],[2,1.01,0]],"ltp":3.1,"tv":0.0,"id":2397396},{"batb":[[0,1.4,49.41],[1,1.01,15.51],[2,1.01,0]],"ltp":1.48,"tv":0.01,"id":8979329}]}]}
{"op":"mcm","clk":"1008978513","pt":1580641236299,"mc":[{"id":"1.168224343","rc":[{"batb":[[0,3.1,21.09],[1,3,107.92],[2,2.96,24]],"ltp":3.1,"tv":0.0,"id":2397396},{"batb":[[1,1.38,53.43],[2,1.01,15.51]],"ltp":1.48,"tv":0.01,"id":8979329}]}]}
{"op":"mcm","clk":"1008978565","pt":1580641236674,"mc":[{"id":"1.168224343","rc":[{"batb":[[1,3,43.35],[2,1.01,15.52]],"batl":[[0,3.5,16.8]],"ltp":3.1,"tv":0.0,"id":2397396},{"batb":[[0,1.4,154.44]],"batl":[[0,1.51,42.01]],"ltp":1.48,"tv":0.01,"id":8979329}]}]}
{"op":"mcm","clk":"1008979082","pt":1580641239864,"mc":[{"id":"1.168224343","rc":[{"batb":[[0,3.1,302.73]],"ltp":3.1,"tv":0.0,"id":2397396}]}]}
{"op":"mcm","clk":"1008980812","pt":1580641250120,"mc":[{"id":"1.168224343","rc":[{"batb":[[0,3,43.35],[1,1.01,15.52],[2,1.01,0]],"ltp":3.1,"tv":0.0,"id":2397396},{"batb":[[0,1.4,105.02]],"ltp":1.48,"tv":0.01,"id":8979329}]}]}
{"op":"mcm","clk":"1008981174","pt":1580641251748,"mc":[{"id":"1.168224343","rc":[{"batb":[[0,3,22.35]],"ltp":3.1,"tv":0.0,"id":2397396},{"batb":[[0,1.38,53.43],[1,1.01,15.51],[2,1.01,0]],"ltp":1.48,"tv":0.01,"id":8979329}]}]}
{"op":"mcm","clk":"1008981440","pt":1580641253317,"mc":[{"id":"1.168224343","rc":[{"batb":[[0,3.05,21.72]],"ltp":3.1,"tv":0.0,"id":2397396},{"batb":[[0,1.37,54.53]],"ltp":1.48,"tv":0.01,"id":8979329}]}]}
{"op":"mcm","clk":"1008983482","pt":1580641266364,"mc":[{"id":"1.168224343","rc":[{"batb":[[1,3,22.98],[2,1.01,15.52]],"ltp":3.1,"tv":0.0,"id":2397396},{"batb":[[0,1.41,48.31],[1,1.39,51.38],[2,1.01,15.51]],"ltp":1.48,"tv":0.01,"id":8979329}]}]}
{"op":"mcm","clk":"1008983524","pt":1580641266684,"mc":[{"id":"1.168224343","rc":[{"batb":[[2,2.96,21]],"batl":[[0,3.4,16.8]],"ltp":3.1,"tv":0.0,"id":2397396},{"batb":[[0,1.41,149.97]],"batl":[[0,1.52,42.01]],"ltp":1.48,"tv":0.01,"id":8979329}]}]}
{"op":"mcm","clk":"1008984668","pt":1580641275391,"mc":[{"id":"1.168224343","rc":[{"batb":[[0,3,22.98],[1,2.96,21],[2,1.01,15.52]],"ltp":3.1,"tv":0.0,"id":2397396},{"batb":[[0,1.41,101.66]],"ltp":1.48,"tv":0.01,"id":8979329}]}]}
{"op":"mcm","clk":"1008984739","pt":1580641275865,"mc":[{"id":"1.168224343","rc":[{"batb":[[1,1.01,15.52],[2,1.01,0]],"ltp":3.1,"tv":0.0,"id":2397396},{"batb":[[0,1.39,51.38],[1,1.01,15.51],[2,1.01,0]],"ltp":1.48,"tv":0.01,"id":8979329}]}]}
{"op":"mcm","clk":"1008987477","pt":1580641295916,"mc":[{"id":"1.168224343","rc":[{"batb":[[0,3.15,19.99],[1,3.1,21.17],[2,1.01,15.52]],"ltp":3.1,"tv":0.0,"id":2397396},{"batb":[[1,1.37,55.71],[2,1.01,15.51]],"ltp":1.48,"tv":0.01,"id":8979329}]}]}
{"op":"mcm","clk":"1008987591","pt":1580641296717,"mc":[{"id":"1.168224343","rc":[{"batb":[[2,3,21]],"batl":[[0,3.5,16.8]],"ltp":3.1,"tv":0.0,"id":2397396},{"batb":[[0,1.4,105.02],[1,1.39,51.38],[2,1.37,55.71]],"batl":[[0,1.5,42.01]],"ltp":1.48,"tv":0.01,"id":8979329}]}]}
{"op":"mcm","clk":"1008989485","pt":1580641309804,"mc":[{"id":"1.168224343","rc":[{"batb":[[0,3.1,21.17],[1,3,21],[2,1.01,15.52]],"ltp":3.1,"tv":0.0,"id":2397396},{"batb":[[1,1.37,55.71],[2,1.01,15.51]],"ltp":1.48,"tv":0.01,"id":8979329}]}]}
{"op":"mcm","clk":"1008989773","pt":1580641312027,"mc":[{"id":"1.168224343","rc":[{"batb":[[1,1.01,15.52],[2,1.01,0]],"ltp":3.1,"tv":0.0,"id":2397396},{"batb":[[0,1.37,55.71],[1,1.01,15.51],[2,1.01,0]],"ltp":1.48,"tv":0.01,"id":8979329}]}]}
{"op":"mcm","clk":"1008990573","pt":1580641317717,"mc":[{"id":"1.168224343","rc":[{"batb":[[1,2.96,23.84],[2,1.01,15.52]],"ltp":3.1,"tv":0.0,"id":2397396},{"batb":[[0,1.41,49.25],[1,1.39,51.06],[2,1.01,15.51]],"ltp":1.48,"tv":0.01,"id":8979329}]}]}
{"op":"mcm","clk":"1008990739","pt":1580641318718,"mc":[{"id":"1.168224343","rc":[{"batb":[[2,2.94,21]],"batl":[[0,3.4,16.8]],"ltp":3.1,"tv":0.0,"id":2397396},{"batb":[[0,1.42,99.98],[1,1.41,49.25],[2,1.39,51.06]],"batl":[[0,1.53,42.01]],"ltp":1.48,"tv":0.01,"id":8979329}]}]}
{"op":"mcm","clk":"1008992441","pt":1580641331370,"mc":[{"id":"1.168224343","rc":[{"batl":[[0,1.52,42.01]],"ltp":1.48,"tv":0.01,"id":8979329}]}]}
{"op":"mcm","clk":"1008995471","pt":1580641353378,"mc":[{"id":"1.168224343","rc":[{"batb":[[0,2.96,23.84],[1,2.94,21],[2,1.01,15.52]],"ltp":3.1,"tv":0.0,"id":2397396},{"batb":[[1,1.39,51.06],[2,1.01,15.51]],"ltp":1.48,"tv":0.01,"id":8979329}]}]}
{"op":"mcm","clk":"1008995545","pt":1580641353856,"mc":[{"id":"1.168224343","rc":[{"batb":[[1,1.01,15.52],[2,1.01,0]],"ltp":3.1,"tv":0.0,"id":2397396},{"batb":[[0,1.39,51.06],[1,1.01,15.51],[2,1.01,0]],"ltp":1.48,"tv":0.01,"id":8979329}]}]}
{"op":"mcm","clk":"1009000971","pt":1580641394246,"mc":[{"id":"1.168224343","rc":[{"batb":[[1,2.82,10.78],[2,1.01,15.52]],"ltp":3.1,"tv":0.0,"id":2397396},{"batb":[[0,1.44,44.93],[1,1.42,47.29],[2,1.01,15.51]],"ltp":1.48,"tv":0.01,"id":8979329}]}]}
{"op":"mcm","clk":"1009001047","pt":1580641394789,"mc":[{"id":"1.168224343","rc":[{"batb":[[1,2.88,21.85],[2,2.82,10.78]],"batl":[[0,3.3,17.64]],"ltp":3.1,"tv":0.0,"id":2397396},{"batb":[[1,1.43,97.46],[2,1.42,47.29]],"batl":[[0,1.54,42.01]],"ltp":1.48,"tv":0.01,"id":8979329}]}]}
{"op":"mcm","clk":"1009002766","pt":1580641406316,"mc":[{"id":"1.168224343","rc":[{"batb":[[0,2.88,21.85],[1,2.82,10.78],[2,1.01,15.52]],"ltp":3.1,"tv":0.0,"id":2397396},{"batb":[[0,1.43,97.46],[1,1.42,47.29],[2,1.01,15.51]],"ltp":1.48,"tv":0.01,"id":8979329}]}]}
{"op":"mcm","clk":"1009002983","pt":1580641407840,"mc":[{"id":"1.168224343","rc":[{"batb":[[0,2.82,10.78],[1,1.01,15.52],[2,1.01,0]],"ltp":3.1,"tv":0.0,"id":2397396},{"batb":[[0,1.42,47.29],[1,1.01,15.51],[2,1.01,0]],"ltp":1.48,"tv":0.01,"id":8979329}]}]}
{"op":"mcm","clk":"1009005340","pt":1580641423346,"mc":[{"id":"1.168224343","rc":[{"batb":[[0,3.05,22.35],[1,2.9,47.02],[2,1.01,15.52]],"batl":[[0,3.35,17.64]],"ltp":3.1,"tv":0.0,"id":2397396},{"batb":[[0,1.42,147.27],[1,1.4,49.81],[2,1.01,15.51]],"batl":[[0,1.53,42.01]],"ltp":1.48,"tv":0.01,"id":8979329}]}]}
{"op":"mcm","clk":"1009005894","pt":1580641427217,"mc":[{"id":"1.168224343","rc":[{"trd":[[3.35,34.94]],"batb":[[1,2.9,25.18]],"batl":[[0,3.35,0.18]],"ltp":3.35,"tv":34.94,"id":2397396}],"tv":34.95}]}
{"op":"mcm","clk":"1009006322","pt":1580641430243,"mc":[{"id":"1.168224343","rc":[{"batb":[[1,2.96,21],[2,2.9,25.18]],"batl":[[0,3.35,16.98]],"ltp":3.35,"tv":34.94,"id":2397396},{"batl":[[0,1.51,42.01]],"ltp":1.48,"tv":0.01,"id":8979329}]}]}
{"op":"mcm","clk":"1009006973","pt":1580641435048,"mc":[{"id":"1.168224343","rc":[{"batb":[[0,2.96,21],[1,2.9,25.18],[2,1.01,15.52]],"ltp":3.35,"tv":34.94,"id":2397396},{"batb":[[0,1.42,99.98]],"ltp":1.48,"tv":0.01,"id":8979329}]}]}
{"op":"mcm","clk":"1009007083","pt":1580641435738,"mc":[{"id":"1.168224343","rc":[{"batb":[[0,2.9,25.18],[1,1.01,15.52],[2,1.01,0]],"ltp":3.35,"tv":34.94,"id":2397396},{"batb":[[0,1.4,49.81],[1,1.01,15.51],[2,1.01,0]],"ltp":1.48,"tv":0.01,"id":8979329}]}]}
{"op":"mcm","clk":"1009007960","pt":1580641442356,"mc":[{"id":"1.168224343","rc":[{"batb":[[0,3.1,20.85],[1,2.98,23.45],[2,1.01,15.52]],"ltp":3.35,"tv":34.94,"id":2397396},{"batb":[[1,1.39,51.3],[2,1.01,15.51]],"ltp":1.48,"tv":0.01,"id":8979329}]}]}
{"op":"mcm","clk":"1009008059","pt":1580641442940,"mc":[{"id":"1.168224343","rc":[{"batb":[[1,3,21],[2,2.98,23.45]],"batl":[[0,3.45,16.8]],"ltp":3.35,"tv":34.94,"id":2397396},{"batb":[[0,1.41,101.66],[1,1.4,49.81],[2,1.39,51.3]],"batl":[[0,1.5,42.01]],"ltp":1.48,"tv":0.01,"id":8979329}]}]}
{"op":"mcm","clk":"1009008357","pt":1580641445251,"mc":[{"id":"1.168224343","rc":[{"batl":[[1,4.6,136.05]],"ltp":3.35,"tv":34.94,"id":2397396},{"batl":[[1,1.82,469.11]],"ltp":1.48,"tv":0.01,"id":8979329}]}]}
{"op":"mcm","clk":"1009009452","pt":1580641453251,"mc":[{"id":"1.168224343","rc":[{"batb":[[0,3,21],[1,2.98,23.45],[2,1.01,15.52]],"ltp":3.35,"tv":34.94,"id":2397396},{"batb":[[1,1.39,51.3],[2,1.01,15.51]],"ltp":1.48,"tv":0.01,"id":8979329}]}]}
{"op":"mcm","clk":"1009009576","pt":1580641454162,"mc":[{"id":"1.168224343","rc":[{"batb":[[0,2.98,23.45],[1,1.01,15.52],[2,1.01,0]],"batl":[[0,4.6,136.05],[1,4.6,0]],"ltp":3.35,"tv":34.94,"id":2397396},{"batb":[[0,1.39,51.3],[1,1.01,15.51],[2,1.01,0]],"batl":[[0,1.82,469.11],[1,1.82,0]],"ltp":1.48,"tv":0.01,"id":8979329}]}]}
{"op":"mcm","clk":"1009010875","pt":1580641463275,"mc":[{"id":"1.168224343","rc":[{"batb":[[0,3.15,20.06],[1,3.05,41.96],[2,1.01,15.52]],"batl":[[0,3.5,16.8],[1,4.6,136.05]],"ltp":3.35,"tv":34.94,"id":2397396},{"batb":[[0,1.4,105.02],[1,1.39,51.3],[2,1.38,53.66]],"batl":[[0,1.49,42.01],[1,1.82,469.11]],"ltp":1.48,"tv":0.01,"id":8979329}]}]}
{"op":"mcm","clk":"1009011740","pt":1580641468698,"mc":[{"id":"1.168224343","rc":[{"batb":[[0,3.05,41.96],[1,1.01,15.52],[2,1.01,0]],"ltp":3.35,"tv":34.94,"id":2397396},{"batb":[[1,1.38,53.66],[2,1.01,15.51]],"ltp":1.48,"tv":0.01,"id":8979329}]}]}
{"op":"mcm","clk":"1009011901","pt":1580641469771,"mc":[{"id":"1.168224343","rc":[{"batb":[[0,3.05,21.79]],"batl":[[0,4.6,136.05],[1,4.6,0]],"ltp":3.35,"tv":34.94,"id":2397396},{"batb":[[0,1.38,53.66],[1,1.01,15.51],[2,1.01,0]],"batl":[[0,1.82,469.11],[1,1.82,0]],"ltp":1.48,"tv":0.01,"id":8979329}]}]}
{"op":"mcm","clk":"1009012705","pt":1580641475379,"mc":[{"id":"1.168224343","rc":[{"batb":[[0,3.25,18.96],[1,3.15,39.7],[2,1.01,15.52]],"batl":[[0,3.6,15.96],[1,4.6,136.05]],"ltp":3.35,"tv":34.94,"id":2397396},{"batb":[[0,1.38,163.73],[1,1.36,57.99],[2,1.01,15.51]],"batl":[[0,1.47,42.01],[1,1.82,469.11]],"ltp":1.48,"tv":0.01,"id":8979329}]}]}
{"op":"mcm","clk":"1009015533","pt":1580641494208,"mc":[{"id":"1.168224343","rc":[{"batb":[[2,3,297.62]],"ltp":3.35,"tv":34.94,"id":2397396}]}]}
{"op":"mcm","clk":"1009016057","pt":1580641498126,"mc":[{"id":"1.168224343","rc":[{"batb":[[0,3.15,39.7],[1,1.01,15.52],[2,3,0]],"ltp":3.35,"tv":34.94,"id":2397396},{"batb":[[0,1.38,110.07]],"ltp":1.48,"tv":0.01,"id":8979329}]}]}
{"op":"mcm","clk":"1009016317","pt":1580641499934,"mc":[{"id":"1.168224343","rc":[{"batb":[[0,3.15,20.38]],"batl":[[0,4.6,136.05],[1,4.6,0]],"ltp":3.35,"tv":34.94,"id":2397396},{"batb":[[0,1.36,57.99],[1,1.01,15.51],[2,1.01,0]],"batl":[[0,1.82,469.11],[1,1.82,0]],"ltp":1.48,"tv":0.01,"id":8979329}]}]}
{"op":"mcm","clk":"1009018635","pt":1580641514331,"mc":[{"id":"1.168224343","rc":[{"batb":[[0,3.35,17.07],[1,3.25,18.49],[2,3,85.57]],"ltp":3.35,"tv":34.94,"id":2397396},{"batb":[[1,1.33,62.95],[2,1.01,15.51]],"ltp":1.48,"tv":0.01,"id":8979329}]}]}
{"op":"mcm","clk":"1009018793","pt":1580641515263,"mc":[{"id":"1.168224343","rc":[{"batb":[[1,3.25,36.97]],"batl":[[0,3.7,15.12]],"ltp":3.35,"tv":34.94,"id":2397396},{"batb":[[0,1.37,113.43],[1,1.36,57.99],[2,1.33,62.95]],"batl":[[0,1.45,42.01]],"ltp":1.48,"tv":0.01,"id":8979329}]}]}
{"op":"mcm","clk":"1009019185","pt":1580641517254,"mc":[{"id":"1.168224343","rc":[{"batl":[[1,5.3,118.79]],"ltp":3.35,"tv":34.94,"id":2397396},{"batl":[[1,1.73,527.57]],"ltp":1.48,"tv":0.01,"id":8979329}]}]}
{"op":"mcm","clk":"1009020237","pt":1580641524134,"mc":[{"id":"1.168224343","rc":[{"batb":[[0,3.25,36.97],[1,1.01,15.52],[2,3,0]],"ltp":3.35,"tv":34.94,"id":2397396},{"batb":[[1,1.33,62.95],[2,1.01,15.51]],"ltp":1.48,"tv":0.01,"id":8979329}]}]}
{"op":"mcm","clk":"1009020575","pt":1580641526373,"mc":[{"id":"1.168224343","rc":[{"batb":[[0,3.25,18.49]],"batl":[[0,5.3,118.79],[1,5.3,0]],"ltp":3.35,"tv":34.94,"id":2397396},{"batb":[[0,1.33,62.95],[1,1.01,15.51],[2,1.01,0]],"batl":[[0,1.73,527.57],[1,1.73,0]],"ltp":1.48,"tv":0.01,"id":8979329}]}]}
{"op":"mcm","clk":"1009021630","pt":1580641532338,"mc":[{"id":"1.168224343","rc":[{"batb":[[0,3.55,15.26],[1,3.4,16.52],[2,1.01,15.52]],"ltp":3.35,"tv":34.94,"id":2397396},{"batb":[[1,1.3,70.03],[2,1.01,15.51]],"ltp":1.48,"tv":0.01,"id":8979329}]}]}
{"op":"mcm","clk":"1009021751","pt":1580641533175,"mc":[{"id":"1.168224343","rc":[{"batb":[[2,3.35,17.64]],"batl":[[0,3.8,14.28],[1,5.3,118.79]],"ltp":3.35,"tv":34.94,"id":2397396},{"batb":[[0,1.36,115.95],[1,1.33,62.95],[2,1.3,70.03]],"batl":[[0,1.43,42.01],[1,1.73,527.57]],"ltp":1.48,"tv":0.01,"id":8979329}]}]}
{"op":"mcm","clk":"1009023683","pt":1580641544982,"mc":[{"id":"1.168224343","rc":[{"batb":[[0,3.4,16.52],[1,3.35,17.64],[2,1.01,15.52]],"ltp":3.35,"tv":34.94,"id":2397396},{"batb":[[1,1.3,70.03],[2,1.01,15.51]],"ltp":1.48,"tv":0.01,"id":8979329}]}]}
{"op":"mcm","clk":"1009023846","pt":1580641545980,"mc":[{"id":"1.168224343","rc":[{"batb":[[1,1.01,15.52],[2,1.01,0]],"batl":[[0,5.3,118.79],[1,5.3,0]],"ltp":3.35,"tv":34.94,"id":2397396},{"batb":[[0,1.3,70.03],[1,1.01,15.51],[2,1.01,0]],"batl":[[0,1.73,527.57],[1,1.73,0]],"ltp":1.48,"tv":0.01,"id":8979329}]}]}
{"op":"mcm","clk":"1009025195","pt":1580641554389,"mc":[{"id":"1.168224343","rc":[{"batb":[[1,3.3,17.94],[2,1.01,15.52]],"ltp":3.35,"tv":34.94,"id":2397396},{"batb":[[0,1.35,59.33],[1,1.32,66.25],[2,1.01,15.51]],"ltp":1.48,"tv":0.01,"id":8979329}]}]}
{"op":"mcm","clk":"1009025279","pt":1580641554882,"mc":[{"id":"1.168224343","rc":[{"batb":[[1,3.3,35.58]],"batl":[[0,3.75,15.12],[1,5.3,118.79]],"ltp":3.35,"tv":34.94,"id":2397396},{"batb":[[0,1.37,113.43],[1,1.35,59.33],[2,1.32,66.25]],"batl":[[0,1.44,42.01],[1,1.73,527.57]],"ltp":1.48,"tv":0.01,"id":8979329}]}]}
{"op":"mcm","clk":"1009027949","pt":1580641571316,"mc":[{"id":"1.168224343","rc":[{"batb":[[0,3.3,17.64],[1,1.01,15.52],[2,1.01,0]],"batl":[[0,5.3,118.79],[1,5.3,0]],"ltp":3.35,"tv":34.94,"id":2397396},{"trd":[[1.37,226.46]],"batb":[[0,1.01,15.7],[1,1.35,0],[2,1.32,0]],"ltp":1.37,"tv":226.47,"id":8979329}],"tv":261.41}]}
{"op":"mcm","clk":"1009028156","pt":1580641572393,"mc":[{"id":"1.168224343","rc":[{"batb":[[0,1.01,15.51]],"batl":[[0,1.73,527.57],[1,1.73,0]],"ltp":1.37,"tv":226.47,"id":8979329}]}]}
{"op":"mcm","clk":"1009028472","pt":1580641574298,"mc":[{"id":"1.168224343","rc":[{"batl":[[0,3.7,15.12],[1,5.3,118.79]],"ltp":3.35,"tv":34.94,"id":2397396}]}]}
{"op":"mcm","clk":"1009028640","pt":1580641575322,"mc":[{"id":"1.168224343","rc":[{"batb":[[0,1.37,113.43],[1,1.01,15.51]],"batl":[[0,1.44,42.01],[1,1.73,527.57]],"ltp":1.37,"tv":226.47,"id":8979329}]}]}
{"op":"mcm","clk":"1009030586","pt":1580641586250,"mc":[{"id":"1.168224343","rc":[{"batb":[[0,1.01,15.52],[1,1.01,0]],"batl":[[0,5.3,118.79],[1,5.3,0]],"ltp":3.35,"tv":34.94,"id":2397396},{"batb":[[0,1.01,15.51],[1,1.01,0]],"batl":[[0,1.73,527.57],[1,1.73,0]],"ltp":1.37,"tv":226.47,"id":8979329}]}]}
{"op":"mcm","clk":"1009031697","pt":1580641592149,"mc":[{"id":"1.168224343","rc":[{"batb":[[0,1.37,719.04],[1,1.01,15.51]],"ltp":1.37,"tv":226.47,"id":8979329}]}]}
{"op":"mcm","clk":"1009031921","pt":1580641593339,"mc":[{"id":"1.168224343","rc":[{"batb":[[0,3.2,18.48],[1,1.01,15.52]],"batl":[[0,3.65,15.12]],"ltp":3.35,"tv":34.94,"id":2397396},{"batb":[[0,1.37,832.47]],"batl":[[0,1.45,42.01],[1,1.73,527.57]],"ltp":1.37,"tv":226.47,"id":8979329}]}]}
{"op":"mcm","clk":"1009032047","pt":1580641594139,"mc":[{"id":"1.168224343","rc":[{"batl":[[1,4.9,126.27]],"ltp":3.35,"tv":34.94,"id":2397396}]}]}
{"op":"mcm","clk":"1009034017","pt":1580641606025,"mc":[{"id":"1.168224343","rc":[{"batb":[[0,1.01,15.52],[1,1.01,0]],"batl":[[0,4.9,126.27],[1,4.9,0]],"ltp":3.35,"tv":34.94,"id":2397396},{"batb":[[0,1.01,15.51],[1,1.01,0]],"batl":[[0,1.73,527.57],[1,1.73,0]],"ltp":1.37,"tv":226.47,"id":8979329}]}]}
{"op":"mcm","clk":"1009036155","pt":1580641618949,"mc":[{"id":"1.168224343","rc":[{"batb":[[0,3.1,19.32],[1,1.01,15.52]],"batl":[[0,3.55,15.96],[1,4.9,126.27]],"ltp":3.35,"tv":34.94,"id":2397396},{"batb":[[0,1.39,107.54],[1,1.01,15.51]],"batl":[[0,1.48,42.01],[1,1.73,527.57]],"ltp":1.37,"tv":226.47,"id":8979329}]}]}
{"op":"mcm","clk":"1009036697","pt":1580641622360,"mc":[{"id":"1.168224343","rc":[{"batb":[[1,1.38,695.67],[2,1.01,15.51]],"ltp":1.37,"tv":226.47,"id":8979329}]}]}
{"op":"mcm","clk":"1009036920","pt":1580641623792,"mc":[{"id":"1.168224343","rc":[{"batb":[[1,2.96,23.92],[2,1.01,15.52]],"ltp":3.35,"tv":34.94,"id":2397396},{"batb":[[0,1.39,158.85]],"ltp":1.37,"tv":226.47,"id":8979329}]}]}
{"op":"mcm","clk":"1009040709","pt":1580641647591,"mc":[{"id":"1.168224343","rc":[{"batl":[[0,1.73,527.57],[1,1.73,0]],"ltp":1.37,"tv":226.47,"id":8979329}]}]}
{"op":"mcm","clk":"1009041151","pt":1580641650570,"mc":[{"id":"1.168224343","rc":[{"batl":[[0,1.47,42.01],[1,1.73,527.57]],"ltp":1.37,"tv":226.47,"id":8979329}]}]}
{"op":"mcm","clk":"1009047883","pt":1580641694633,"mc":[{"id":"1.168224343","rc":[{"batb":[[1,1.01,15.51],[2,1.01,0]],"ltp":1.37,"tv":226.47,"id":8979329}]}]}
{"op":"mcm","clk":"1009048132","pt":1580641696237,"mc":[{"id":"1.168224343","rc":[{"batb":[[0,2.96,23.92],[1,1.01,15.52],[2,1.01,0]],"batl":[[0,4.9,126.27],[1,4.9,0]],"ltp":3.35,"tv":34.94,"id":2397396},{"batb":[[0,1.39,51.3]],"batl":[[0,1.73,527.57],[1,1.73,0]],"ltp":1.37,"tv":226.47,"id":8979329}]}]}
{"op":"mcm","clk":"1009049086","pt":1580641702740,"mc":[{"id":"1.168224343","rc":[{"batl":[[0,4.6,136.05]],"ltp":3.35,"tv":34.94,"id":2397396}]}]}
{"op":"mcm","clk":"1009051127","pt":1580641716380,"mc":[{"id":"1.168224343","rc":[{"batb":[[0,3.15,20.06],[1,3,22.5],[2,1.01,15.52]],"ltp":3.35,"tv":34.94,"id":2397396},{"batb":[[1,1.38,53.5],[2,1.01,15.51]],"ltp":1.37,"tv":226.47,"id":8979329}]}]}
{"op":"mcm","clk":"1009051232","pt":1580641717170,"mc":[{"id":"1.168224343","rc":[{"batb":[[0,3.15,39.39]],"batl":[[0,3.6,15.96],[1,4.6,136.05]],"ltp":3.35,"tv":34.94,"id":2397396},{"batb":[[1,1.38,163.57]],"batl":[[0,1.47,42.01],[1,1.73,527.57]],"ltp":1.37,"tv":226.47,"id":8979329}]}]}
{"op":"mcm","clk":"1009053020","pt":1580641729381,"mc":[{"id":"1.168224343","rc":[{"batb":[[0,3.15,19.32]],"ltp":3.35,"tv":34.94,"id":2397396},{"batb":[[0,1.38,163.57],[1,1.01,15.51],[2,1.01,0]],"ltp":1.37,"tv":226.47,"id":8979329}]}]}
{"op":"mcm","clk":"1009053131","pt":1580641730231,"mc":[{"id":"1.168224343","rc":[{"batb":[[0,3,22.5],[1,1.01,15.52],[2,1.01,0]],"batl":[[0,4.6,136.05],[1,4.6,0]],"ltp":3.35,"tv":34.94,"id":2397396},{"batb":[[0,1.38,53.5]],"batl":[[0,1.73,527.57],[1,1.73,0]],"ltp":1.37,"tv":226.47,"id":8979329}]}]}
{"op":"mcm","clk":"1009055733","pt":1580641747111,"mc":[{"id":"1.168224343","rc":[{"batb":[[0,3.25,18.96],[1,3.2,18.48],[2,3.1,21.01]],"batl":[[0,3.65,15.12],[1,4.6,136.05]],"ltp":3.35,"tv":34.94,"id":2397396},{"batb":[[0,1.38,163.57],[1,1.37,55.79],[2,1.01,15.51]],"batl":[[0,1.46,42.01],[1,1.73,527.57]],"ltp":1.37,"tv":226.47,"id":8979329}]}]}
{"op":"mcm","clk":"1009057604","pt":1580641758141,"mc":[{"id":"1.168224343","rc":[{"batb":[[0,3.1,21.01],[1,1.01,15.52],[2,3.1,0]],"batl":[[0,4.6,136.05],[1,4.6,0]],"ltp":3.35,"tv":34.94,"id":2397396},{"batb":[[0,1.37,55.79],[1,1.01,15.51],[2,1.01,0]],"batl":[[0,1.73,527.57],[1,1.73,0]],"ltp":1.37,"tv":226.47,"id":8979329}]}]}
{"op":"mcm","clk":"1009059099","pt":1580641767211,"mc":[{"id":"1.168224343","rc":[{"batb":[[0,3.3,17.94],[1,3.25,18.48],[2,3.15,19.91]],"batl":[[0,3.7,15.12]],"ltp":3.35,"tv":34.94,"id":2397396},{"batb":[[0,1.37,169.21],[1,1.36,57.44],[2,1.01,15.51]],"batl":[[0,1.45,42.01],[1,1.73,527.57]],"ltp":1.37,"tv":226.47,"id":8979329}]}]}
{"op":"mcm","clk":"1009059559","pt":1580641770131,"mc":[{"id":"1.168224343","rc":[{"batl":[[1,5.3,118.79]],"ltp":3.35,"tv":34.94,"id":2397396}]}]}
{"op":"mcm","clk":"1009060808","pt":1580641778181,"mc":[{"id":"1.168224343","rc":[{"batb":[[0,3.15,19.91],[1,1.01,15.52],[2,3.15,0]],"batl":[[0,5.3,118.79],[1,5.3,0]],"ltp":3.35,"tv":34.94,"id":2397396},{"batb":[[0,1.36,57.44],[1,1.01,15.51],[2,1.01,0]],"batl":[[0,1.73,527.57],[1,1.73,0]],"ltp":1.37,"tv":226.47,"id":8979329}]}]}
{"op":"mcm","clk":"1009062150","pt":1580641787363,"mc":[{"id":"1.168224343","rc":[{"batb":[[0,3.3,17.64],[1,3.15,19.91],[2,1.01,15.52]],"batl":[[0,3.8,14.28],[1,5.3,118.79]],"ltp":3.35,"tv":34.94,"id":2397396},{"batb":[[0,1.36,173.38]],"batl":[[0,1.43,42.01],[1,1.73,527.57]],"ltp":1.37,"tv":226.47,"id":8979329}]}]}
{"op":"mcm","clk":"1009062270","pt":1580641788162,"mc":[{"id":"1.168224343","rc":[{"batb":[[0,3.35,17.31],[1,3.3,17.64],[2,3.25,18.73]],"ltp":3.35,"tv":34.94,"id":2397396},{"batb":[[1,1.33,63.02],[2,1.01,15.51]],"ltp":1.37,"tv":226.47,"id":8979329}]}]}
{"op":"mcm","clk":"1009065194","pt":1580641808971,"mc":[{"id":"1.168224343","rc":[{"batb":[[0,3.3,17.64],[1,3.25,18.33],[2,1.01,15.52]],"ltp":3.35,"tv":34.94,"id":2397396},{"batb":[[0,1.36,115.95]],"ltp":1.37,"tv":226.47,"id":8979329}]}]}
{"op":"mcm","clk":"1009065383","pt":1580641810192,"mc":[{"id":"1.168224343","rc":[{"batb":[[0,3.25,18.33],[1,1.01,15.52],[2,1.01,0]],"batl":[[0,5.3,118.79],[1,5.3,0]],"ltp":3.35,"tv":34.94,"id":2397396},{"batb":[[0,1.33,63.02],[1,1.01,15.51],[2,1.01,0]],"batl":[[0,1.73,527.57],[1,1.73,0]],"ltp":1.37,"tv":226.47,"id":8979329}]}]}
{"op":"mcm","clk":"1009066286","pt":1580641816096,"mc":[{"id":"1.168224343","rc":[{"batb":[[1,3.2,19.67],[2,1.01,15.52]],"ltp":3.35,"tv":34.94,"id":2397396},{"batb":[[0,1.37,54.92],[1,1.35,59.72],[2,1.01,15.51]],"ltp":1.37,"tv":226.47,"id":8979329}]}]}
{"op":"mcm","clk":"1009066462","pt":1580641817232,"mc":[{"id":"1.168224343","rc":[{"batb":[[0,3.25,36.82]],"batl":[[0,3.75,15.12],[1,5.3,118.79]],"ltp":3.35,"tv":34.94,"id":2397396},{"batb":[[1,1.36,115.95],[2,1.35,59.72]],"batl":[[0,1.44,42.01],[1,1.73,527.57]],"ltp":1.37,"tv":226.47,"id":8979329}]}]}
{"op":"mcm","clk":"1009066666","pt":1580641818402,"mc":[{"id":"1.168224343","rc":[{"batb":[[0,3.3,17.64],[1,3.25,18.33],[2,3.2,19.67]],"ltp":3.35,"tv":34.94,"id":2397396},{"batl":[[0,1.43,42.01]],"ltp":1.37,"tv":226.47,"id":8979329}]}]}
{"op":"mcm","clk":"1009066696","pt":1580641818606,"mc":[{"id":"1.168224343","rc":[{"batl":[[0,1.73,527.57],[1,1.73,0]],"ltp":1.37,"tv":226.47,"id":8979329}]}]}
{"op":"mcm","clk":"1009067022","pt":1580641821009,"mc":[{"id":"1.168224343","rc":[{"batl":[[0,1.44,42.01],[1,1.73,527.57]],"ltp":1.37,"tv":226.47,"id":8979329}]}]}
{"op":"mcm","clk":"1009067746","pt":1580641826309,"mc":[{"id":"1.168224343","rc":[{"batb":[[0,3.2,19.67],[1,1.01,15.52],[2,3.2,0]],"batl":[[0,5.3,118.79],[1,5.3,0]],"ltp":3.35,"tv":34.94,"id":2397396},{"batb":[[0,1.35,59.72],[1,1.01,15.51],[2,1.35,0]],"batl":[[0,1.73,527.57],[1,1.73,0]],"ltp":1.37,"tv":226.47,"id":8979329}]}]}
{"op":"mcm","clk":"1009070959","pt":1580641850223,"mc":[{"id":"1.168224343","rc":[{"batb":[[0,3.45,16.44],[1,3.35,17.62],[2,1.01,15.52]],"ltp":3.35,"tv":34.94,"id":2397396},{"batb":[[1,1.32,66.41],[2,1.01,15.51]],"ltp":1.37,"tv":226.47,"id":8979329}]}]}
{"op":"mcm","clk":"1009071068","pt":1580641851136,"mc":[{"id":"1.168224343","rc":[{"batb":[[1,3.35,35.27]],"batl":[[0,3.85,14.28],[1,5.3,118.79]],"ltp":3.35,"tv":34.94,"id":2397396},{"batb":[[0,1.35,179.03]],"batl":[[0,1.43,42.01],[1,1.73,527.57]],"ltp":1.37,"tv":226.47,"id":8979329}]}]}
{"op":"mcm","clk":"1009071130","pt":1580641851523,"mc":[{"id":"1.168224343","rc":[{"batl":[[0,1.73,527.57],[1,1.73,0]],"ltp":1.37,"tv":226.47,"id":8979329}]}]}
{"op":"mcm","clk":"1009071410","pt":1580641853345,"mc":[{"id":"1.168224343","rc":[{"batl":[[0,1.42,42.01],[1,1.73,527.57]],"ltp":1.37,"tv":226.47,"id":8979329}]}]}
{"op":"mcm","clk":"1009072998","pt":1580641864373,"mc":[{"id":"1.168224343","rc":[{"batb":[[0,3.35,35.27],[1,1.01,15.52],[2,1.01,0]],"ltp":3.35,"tv":34.94,"id":2397396},{"batb":[[0,1.35,119.31]],"ltp":1.37,"tv":226.47,"id":8979329}]}]}
{"op":"mcm","clk":"1009073245","pt":1580641866281,"mc":[{"id":"1.168224343","rc":[{"batb":[[0,3.35,17.62]],"batl":[[0,5.3,118.79],[1,5.3,0]],"ltp":3.35,"tv":34.94,"id":2397396},{"batb":[[0,1.32,66.41],[1,1.01,15.51],[2,1.01,0]],"batl":[[0,1.73,527.57],[1,1.73,0]],"ltp":1.37,"tv":226.47,"id":8979329}]}]}
{"op":"mcm","clk":"1009073405","pt":1580641867362,"mc":[{"id":"1.168224343","rc":[{"batb":[[1,3.3,17.86],[2,1.01,15.52]],"ltp":3.35,"tv":34.94,"id":2397396}]}]}
{"op":"mcm","clk":"1009073437","pt":1580641867578,"mc":[{"id":"1.168224343","rc":[{"batb":[[0,3.3,17.86],[1,1.01,15.52],[2,1.01,0]],"ltp":3.35,"tv":34.94,"id":2397396},{"batb":[[0,1.32,65.7]],"ltp":1.37,"tv":226.47,"id":8979329}]}]}
{"op":"mcm","clk":"1009075315","pt":1580641880308,"mc":[{"id":"1.168224343","rc":[{"batb":[[0,3.4,281.36],[1,3.3,17.86],[2,1.01,15.52]],"ltp":3.35,"tv":34.94,"id":2397396}]}]}
{"op":"mcm","clk":"1009075490","pt":1580641881182,"mc":[{"id":"1.168224343","rc":[{"batb":[[0,3.6,14.4],[1,3.45,32.7],[2,3.4,281.36]],"batl":[[0,3.95,13.44]],"ltp":3.35,"tv":34.94,"id":2397396},{"batb":[[0,1.34,123.51],[1,1.32,65.7],[2,1.29,73.17]],"batl":[[0,1.41,42.01]],"ltp":1.37,"tv":226.47,"id":8979329}]}]}
{"op":"mcm","clk":"1009075578","pt":1580641881821,"mc":[{"id":"1.168224343","rc":[{"batb":[[2,1.01,15.52]],"batl":[[1,6,106.18]],"ltp":3.35,"tv":34.94,"id":2397396},{"batl":[[1,1.66,579.81]],"ltp":1.37,"tv":226.47,"id":8979329}]}]}
{"op":"mcm","clk":"1009077540","pt":1580641894403,"mc":[{"id":"1.168224343","rc":[{"batb":[[0,3.45,15.89],[1,1.01,15.52],[2,1.01,0]],"batl":[[0,6,106.18],[1,6,0]],"ltp":3.35,"tv":34.94,"id":2397396},{"batb":[[0,1.29,73.02],[1,1.01,15.51],[2,1.29,0]],"batl":[[0,1.66,579.81],[1,1.66,0]],"ltp":1.37,"tv":226.47,"id":8979329}]}]}
{"op":"mcm","clk":"1009080408","pt":1580641911365,"mc":[{"id":"1.168224343","rc":[{"batb":[[1,3.4,16.8],[2,3.35,17.62]],"batl":[[0,3.9,14.28]],"ltp":3.35,"tv":34.94,"id":2397396},{"batb":[[0,1.35,119.31],[1,1.34,61.06],[2,1.31,68.14]],"batl":[[0,1.42,42.01],[1,1.66,579.81]],"ltp":1.37,"tv":226.47,"id":8979329}]}]}
{"op":"mcm","clk":"1009080844","pt":1580641913861,"mc":[{"id":"1.168224343","rc":[{"batl":[[1,5.5,115.06]],"ltp":3.35,"tv":34.94,"id":2397396}]}]}
{"op":"mcm","clk":"1009083165","pt":1580641928363,"mc":[{"id":"1.168224343","rc":[{"batb":[[0,3.35,17.62],[1,1.01,15.52],[2,3.35,0]],"batl":[[0,5.5,115.06],[1,5.5,0]],"ltp":3.35,"tv":34.94,"id":2397396},{"batb":[[0,1.31,68.14],[1,1.01,15.51],[2,1.31,0]],"batl":[[0,1.66,579.81],[1,1.66,0]],"ltp":1.37,"tv":226.47,"id":8979329}]}]}
{"op":"mcm","clk":"1009084372","pt":1580641936390,"mc":[{"id":"1.168224343","rc":[{"batb":[[0,3.7,13.69],[1,3.5,15.42],[2,3.45,11.21]],"ltp":3.35,"tv":34.94,"id":2397396},{"batb":[[1,1.28,77.74],[2,1.01,15.51]],"ltp":1.37,"tv":226.47,"id":8979329}]}]}
{"op":"mcm","clk":"1009084481","pt":1580641937178,"mc":[{"id":"1.168224343","rc":[{"batb":[[1,3.5,32.23]],"batl":[[0,4,13.44],[1,5.5,115.06]],"ltp":3.35,"tv":34.94,"id":2397396},{"batb":[[0,1.33,126.87],[1,1.31,68.14],[2,1.28,77.74]],"batl":[[0,1.41,42.01],[1,1.66,579.81]],"ltp":1.37,"tv":226.47,"id":8979329}]}]}
{"op":"mcm","clk":"1009084600","pt":1580641937757,"mc":[{"id":"1.168224343","rc":[{"batl":[[0,1.66,579.81],[1,1.66,0]],"ltp":1.37,"tv":226.47,"id":8979329}]}]}
{"op":"mcm","clk":"1009084995","pt":1580641940307,"mc":[{"id":"1.168224343","rc":[{"batb":[[2,1.01,15.52]],"ltp":3.35,"tv":34.94,"id":2397396},{"batl":[[0,1.4,42.01],[1,1.66,579.81]],"ltp":1.37,"tv":226.47,"id":8979329}]}]}
{"op":"mcm","clk":"1009086760","pt":1580641952178,"mc":[{"id":"1.168224343","rc":[{"batb":[[0,3.5,15.42],[1,1.01,15.52],[2,1.01,0]],"batl":[[0,5.5,115.06],[1,5.5,0]],"ltp":3.35,"tv":34.94,"id":2397396},{"batb":[[0,1.28,76.24],[1,1.01,15.51],[2,1.28,0]],"batl":[[0,1.66,579.81],[1,1.66,0]],"ltp":1.37,"tv":226.47,"id":8979329}]}]}
{"op":"mcm","clk":"1009089504","pt":1580641969387,"mc":[{"id":"1.168224343","rc":[{"batb":[[0,3.5,32.23],[1,3.45,16.8],[2,1.01,15.52]],"batl":[[0,3.95,13.44],[1,4,13.44],[2,5.5,115.06]],"ltp":3.35,"tv":34.94,"id":2397396},{"batb":[[0,1.34,123.51],[1,1.28,76.24],[2,1.01,15.51]],"batl":[[0,1.41,42.01],[1,1.66,579.81]],"ltp":1.37,"tv":226.47,"id":8979329}]}]}
{"op":"mcm","clk":"1009089569","pt":1580641969811,"mc":[{"id":"1.168224343","rc":[{"batb":[[0,3.5,15.42],[2,3.35,17.47]],"batl":[[1,5.5,115.06],[2,5.5,0]],"ltp":3.35,"tv":34.94,"id":2397396},{"batb":[[0,1.34,184.96],[1,1.31,68.06]],"ltp":1.37,"tv":226.47,"id":8979329}]}]}
{"op":"mcm","clk":"1009092560","pt":1580641988223,"mc":[{"id":"1.168224343","rc":[{"batb":[[0,3.35,17.47],[1,1.01,15.52],[2,3.35,0]],"batl":[[0,5.5,115.06],[1,5.5,0]],"ltp":3.35,"tv":34.94,"id":2397396},{"batb":[[0,1.31,68.06],[1,1.01,15.51],[2,1.01,0]],"batl":[[0,1.66,579.81],[1,1.66,0]],"ltp":1.37,"tv":226.47,"id":8979329}]}]}
{"op":"mcm","clk":"1009096779","pt":1580642016165,"mc":[{"id":"1.168224343","rc":[{"batb":[[0,3.7,13.69],[1,3.5,15.5],[2,3.45,74.21]],"ltp":3.35,"tv":34.94,"id":2397396},{"batb":[[1,1.28,78.29],[2,1.01,15.51]],"ltp":1.37,"tv":226.47,"id":8979329}]}]}
{"op":"mcm","clk":"1009096945","pt":1580642017271,"mc":[{"id":"1.168224343","rc":[{"batb":[[1,3.5,32.3]],"batl":[[0,4,13.44],[1,5.5,115.06]],"ltp":3.35,"tv":34.94,"id":2397396},{"batb":[[0,1.33,126.87],[1,1.31,68.06],[2,1.28,78.29]],"batl":[[0,1.4,42.01],[1,1.66,579.81]],"ltp":1.37,"tv":226.47,"id":8979329}]}]}
{"op":"mcm","clk":"1009097040","pt":1580642017753,"mc":[{"id":"1.168224343","rc":[{"batb":[[2,1.01,15.52]],"ltp":3.35,"tv":34.94,"id":2397396}]}]}
{"op":"mcm","clk":"1009099940","pt":1580642036402,"mc":[{"id":"1.168224343","rc":[{"batb":[[0,3.5,15.5],[1,1.01,15.52],[2,1.01,0]],"batl":[[0,5.5,115.06],[1,5.5,0]],"ltp":3.35,"tv":34.94,"id":2397396},{"batb":[[0,1.28,77.97],[1,1.01,15.51],[2,1.28,0]],"batl":[[0,1.66,579.81],[1,1.66,0]],"ltp":1.37,"tv":226.47,"id":8979329}]}]}
{"op":"mcm","clk":"1009104028","pt":1580642061395,"mc":[{"id":"1.168224343","rc":[{"batb":[[0,3.5,32.3]],"batl":[[0,4,13.44],[1,5.5,115.06]],"ltp":3.35,"tv":34.94,"id":2397396},{"batb":[[0,1.34,123.51],[1,1.28,77.97],[2,1.01,15.51]],"batl":[[0,1.41,42.01],[1,1.66,579.81]],"ltp":1.37,"tv":226.47,"id":8979329}]}]}
{"op":"mcm","clk":"1009104136","pt":1580642061981,"mc":[{"id":"1.168224343","rc":[{"batb":[[1,3.4,17],[2,1.01,15.52]],"batl":[[0,5.5,115.06],[1,5.5,0]],"ltp":3.35,"tv":34.94,"id":2397396},{"batb":[[0,1.34,185.51],[1,1.31,69.48]],"ltp":1.37,"tv":226.47,"id":8979329}]}]}
{"op":"mcm","clk":"1009104517","pt":1580642064320,"mc":[{"id":"1.168224343","rc":[{"batl":[[0,3.95,13.44],[1,5.5,115.06]],"ltp":3.35,"tv":34.94,"id":2397396}]}]}
{"op":"mcm","clk":"1009106888","pt":1580642079155,"mc":[{"id":"1.168224343","rc":[{"batb":[[0,3.5,16.8]],"ltp":3.35,"tv":34.94,"id":2397396},{"batb":[[0,1.34,123.51]],"ltp":1.37,"tv":226.47,"id":8979329}]}]}
{"op":"mcm","clk":"1009107095","pt":1580642080332,"mc":[{"id":"1.168224343","rc":[{"batb":[[0,3.4,17],[1,1.01,15.52],[2,1.01,0]],"batl":[[0,5.5,115.06],[1,5.5,0]],"ltp":3.35,"tv":34.94,"id":2397396},{"batb":[[0,1.31,69.48],[1,1.01,15.51],[2,1.01,0]],"batl":[[0,1.66,579.81],[1,1.66,0]],"ltp":1.37,"tv":226.47,"id":8979329}]}]}
{"op":"mcm","clk":"1009108011","pt":1580642086159,"mc":[{"id":"1.168224343","rc":[{"batb":[[1,3.25,18.49],[2,1.01,15.52]],"ltp":3.35,"tv":34.94,"id":2397396},{"batb":[[0,1.36,58.15],[1,1.33,63.65],[2,1.01,15.51]],"ltp":1.37,"tv":226.47,"id":8979329}]}]}
{"op":"mcm","clk":"1009108194","pt":1580642087329,"mc":[{"id":"1.168224343","rc":[{"batb":[[0,3.4,33.8]],"batl":[[0,3.9,14.28],[1,5.5,115.06]],"ltp":3.35,"tv":34.94,"id":2397396},{"batb":[[1,1.34,123.51],[2,1.33,63.65]],"batl":[[0,1.42,42.01],[1,1.66,579.81]],"ltp":1.37,"tv":226.47,"id":8979329}]}]}
{"op":"mcm","clk":"1009110468","pt":1580642101250,"mc":[{"id":"1.168224343","rc":[{"batb":[[0,3.4,16.8]],"ltp":3.35,"tv":34.94,"id":2397396},{"batb":[[0,1.34,123.51],[1,1.33,63.65],[2,1.01,15.51]],"ltp":1.37,"tv":226.47,"id":8979329}]}]}
{"op":"mcm","clk":"1009110623","pt":1580642102262,"mc":[{"id":"1.168224343","rc":[{"batb":[[0,3.25,18.49],[1,1.01,15.52],[2,1.01,0]],"batl":[[0,5.5,115.06],[1,5.5,0]],"ltp":3.35,"tv":34.94,"id":2397396},{"batb":[[0,1.33,63.65],[1,1.01,15.51],[2,1.01,0]],"batl":[[0,1.66,579.81],[1,1.66,0]],"ltp":1.37,"tv":226.47,"id":8979329}]}]}
{"op":"mcm","clk":"1009112196","pt":1580642111362,"mc":[{"id":"1.168224343","rc":[{"batb":[[0,3.45,16.8],[1,3.25,18.49],[2,1.01,15.52]],"batl":[[0,4,13.44],[1,5.5,115.06]],"ltp":3.35,"tv":34.94,"id":2397396},{"batb":[[0,1.33,190.52]],"batl":[[0,1.4,42.01],[1,1.66,579.81]],"ltp":1.37,"tv":226.47,"id":8979329}]}]}
{"op":"mcm","clk":"1009112353","pt":1580642112381,"mc":[{"id":"1.168224343","rc":[{"batb":[[0,3.55,15.03],[1,3.4,16.52]],"ltp":3.35,"tv":34.94,"id":2397396},{"batb":[[1,1.3,70.97],[2,1.01,15.51]],"ltp":1.37,"tv":226.47,"id":8979329}]}]}
{"op":"mcm","clk":"1009112645","pt":1580642114052,"mc":[{"id":"1.168224343","rc":[{"batb":[[1,3.5,16.8],[2,3.4,16.52]],"ltp":3.35,"tv":34.94,"id":2397396}]}]}
{"op":"mcm","clk":"1009115093","pt":1580642128276,"mc":[{"id":"1.168224343","rc":[{"batb":[[0,3.4,16.52],[1,1.01,15.52],[2,3.4,0]],"batl":[[0,5.5,115.06],[1,5.5,0]],"ltp":3.35,"tv":34.94,"id":2397396},{"batb":[[0,1.3,70.97],[1,1.01,15.51],[2,1.01,0]],"batl":[[0,1.66,579.81],[1,1.66,0]],"ltp":1.37,"tv":226.47,"id":8979329}]}]}
{"op":"mcm","clk":"1009117006","pt":1580642139308,"mc":[{"id":"1.168224343","rc":[{"batb":[[0,3.4,33.33]],"batl":[[0,3.95,13.44],[1,5.5,115.06]],"ltp":3.35,"tv":34.94,"id":2397396},{"batb":[[0,1.34,123.51],[1,1.3,70.97],[2,1.01,15.51]],"batl":[[0,1.41,42.01],[1,1.66,579.81]],"ltp":1.37,"tv":226.47,"id":8979329}]}]}
{"op":"mcm","clk":"1009117125","pt":1580642140001,"mc":[{"id":"1.168224343","rc":[{"batb":[[1,3.3,17.94],[2,1.01,15.52]],"ltp":3.35,"tv":34.94,"id":2397396},{"batb":[[0,1.35,59.4],[1,1.34,123.51],[2,1.32,64.91]],"ltp":1.37,"tv":226.47,"id":8979329}]}]}
{"op":"mcm","clk":"1009119885","pt":1580642155227,"mc":[{"id":"1.168224343","rc":[{"batb":[[0,3.4,16.8]],"ltp":3.35,"tv":34.94,"id":2397396},{"batb":[[0,1.34,123.51],[1,1.32,64.91],[2,1.01,15.51]],"ltp":1.37,"tv":226.47,"id":8979329}]}]}
{"op":"mcm","clk":"1009120084","pt":1580642156344,"mc":[{"id":"1.168224343","rc":[{"batb":[[0,3.3,17.94],[1,1.01,15.52],[2,1.01,0]],"batl":[[0,5.5,115.06],[1,5.5,0]],"ltp":3.35,"tv":34.94,"id":2397396},{"batb":[[0,1.32,64.91],[1,1.01,15.51],[2,1.01,0]],"batl":[[0,1.66,579.81],[1,1.66,0]],"ltp":1.37,"tv":226.47,"id":8979329}]}]}
{"op":"mcm","clk":"1009121285","pt":1580642163347,"mc":[{"id":"1.168224343","rc":[{"batb":[[0,3.3,35.58],[1,3.15,20.22],[2,1.01,15.52]],"batl":[[0,3.8,14.28],[1,5.5,115.06]],"ltp":3.35,"tv":34.94,"id":2397396},{"batb":[[0,1.37,55.79],[1,1.36,115.95],[2,1.35,58.46]],"batl":[[0,1.43,42.01],[1,1.66,579.81]],"ltp":1.37,"tv":226.47,"id":8979329}]}]}
{"op":"mcm","clk":"1009133860","pt":1580642244793,"mc":[{"id":"1.168224343","rc":[{"batb":[[0,3.15,20.22],[1,1.01,15.52],[2,1.01,0]],"batl":[[0,5.5,115.06],[1,5.5,0]],"ltp":3.35,"tv":34.94,"id":2397396},{"batb":[[0,1.35,58.46],[1,1.01,15.51],[2,1.35,0]],"batl":[[0,1.66,579.81],[1,1.66,0]],"ltp":1.37,"tv":226.47,"id":8979329}]}]}
{"op":"mcm","clk":"1009136891","pt":1580642263369,"mc":[{"id":"1.168224343","rc":[{"batb":[[0,3.4,16.92],[1,3.25,19.04],[2,3.2,14.62]],"ltp":3.35,"tv":34.94,"id":2397396},{"batb":[[1,1.34,60.74],[2,1.01,15.51]],"ltp":1.37,"tv":226.47,"id":8979329}]}]}
{"op":"mcm","clk":"1009136907","pt":1580642263471,"mc":[{"id":"1.168224343","rc":[{"batb":[[1,3.35,17.64],[2,3.25,19.04]],"batl":[[0,3.85,14.28],[1,5.5,115.06]],"ltp":3.35,"tv":34.94,"id":2397396},{"batb":[[0,1.35,177.77]],"batl":[[0,1.43,42.01],[1,1.66,579.81]],"ltp":1.37,"tv":226.47,"id":8979329}]}]}
{"op":"mcm","clk":"1009138394","pt":1580642273856,"mc":[{"id":"1.168224343","rc":[{"batb":[[0,3.35,17.64],[1,3.25,19.04],[2,1.01,15.52]],"ltp":3.35,"tv":34.94,"id":2397396},{"batb":[[0,1.35,119.31]],"ltp":1.37,"tv":226.47,"id":8979329}]}]}
{"op":"mcm","clk":"1009138477","pt":1580642274498,"mc":[{"id":"1.168224343","rc":[{"batb":[[0,3.25,19.04],[1,1.01,15.52],[2,1.01,0]],"batl":[[0,5.5,115.06],[1,5.5,0]],"ltp":3.35,"tv":34.94,"id":2397396},{"batb":[[0,1.34,60.74],[1,1.01,15.51],[2,1.01,0]],"batl":[[0,1.66,579.81],[1,1.66,0]],"ltp":1.37,"tv":226.47,"id":8979329}]}]}
{"op":"mcm","clk":"1009139395","pt":1580642280396,"mc":[{"id":"1.168224343","rc":[{"batb":[[0,3.45,16.05],[1,3.3,18.1],[2,3.25,19.04]],"ltp":3.35,"tv":34.94,"id":2397396},{"batb":[[1,1.33,62.87],[2,1.01,15.51]],"ltp":1.37,"tv":226.47,"id":8979329}]}]}
{"op":"mcm","clk":"1009139537","pt":1580642281404,"mc":[{"id":"1.168224343","rc":[{"batb":[[2,1.01,15.52]],"ltp":3.35,"tv":34.94,"id":2397396}]}]}
{"op":"mcm","clk":"1009139645","pt":1580642282106,"mc":[{"id":"1.168224343","rc":[{"batb":[[1,3.4,16.8],[2,3.3,18.1]],"batl":[[0,3.9,14.28],[1,5.5,115.06]],"ltp":3.35,"tv":34.94,"id":2397396},{"batb":[[0,1.35,119.31],[1,1.34,60.74],[2,1.33,62.87]],"batl":[[0,1.42,42.01],[1,1.66,579.81]],"ltp":1.37,"tv":226.47,"id":8979329}]}]}
{"op":"mcm","clk":"1009141065","pt":1580642291212,"mc":[{"id":"1.168224343","rc":[{"batb":[[0,3.4,16.8],[1,3.3,18.1],[2,1.01,15.52]],"ltp":3.35,"tv":34.94,"id":2397396},{"batb":[[1,1.33,62.87],[2,1.01,15.51]],"ltp":1.37,"tv":226.47,"id":8979329}]}]}
{"op":"mcm","clk":"1009141230","pt":1580642292312,"mc":[{"id":"1.168224343","rc":[{"batb":[[0,1.33,62.87],[1,1.01,15.51],[2,1.01,0]],"batl":[[0,1.66,579.81],[1,1.66,0]],"ltp":1.37,"tv":226.47,"id":8979329}]}]}
{"op":"mcm","clk":"1009141294","pt":1580642292591,"mc":[{"id":"1.168224343","rc":[{"batb":[[0,3.3,18.1],[1,1.01,15.52],[2,1.01,0]],"batl":[[0,5.5,115.06],[1,5.5,0]],"ltp":3.35,"tv":34.94,"id":2397396}]}]}
{"op":"mcm","clk":"1009141807","pt":1580642295207,"mc":[{"id":"1.168224343","rc":[{"batb":[[0,1.34,123.51],[1,1.33,62.87],[2,1.01,15.51]],"batl":[[0,1.41,42.01],[1,1.66,579.81]],"ltp":1.37,"tv":226.47,"id":8979329}]}]}
{"op":"mcm","clk":"1009141863","pt":1580642295618,"mc":[{"id":"1.168224343","rc":[{"batb":[[0,1.33,62.87],[1,1.01,15.51],[2,1.01,0]],"batl":[[0,1.66,579.81],[1,1.66,0]],"ltp":1.37,"tv":226.47,"id":8979329}]}]}
{"op":"mcm","clk":"1009142990","pt":1580642303315,"mc":[{"id":"1.168224343","rc":[{"batb":[[1,3.1,20.61],[2,1.01,15.52]],"ltp":3.35,"tv":34.94,"id":2397396},{"batb":[[0,1.37,55.55],[1,1.35,58.78],[2,1.33,62.87]],"ltp":1.37,"tv":226.47,"id":8979329}]}]}
{"op":"mcm","clk":"1009143015","pt":1580642303526,"mc":[{"id":"1.168224343","rc":[{"batb":[[0,3.35,17.64],[1,3.3,18.1],[2,3.1,20.61]],"batl":[[0,3.8,14.28],[1,5.5,115.06]],"ltp":3.35,"tv":34.94,"id":2397396},{"batb":[[1,1.35,178.08],[2,1.01,15.51]],"batl":[[0,1.43,42.01],[1,1.66,579.81]],"ltp":1.37,"tv":226.47,"id":8979329}]}]}
{"op":"mcm","clk":"1009145471","pt":1580642319961,"mc":[{"id":"1.168224343","rc":[{"batb":[[1,3.1,20.61],[2,1.01,15.52]],"ltp":3.35,"tv":34.94,"id":2397396},{"batb":[[0,1.35,178.08],[1,1.01,15.51],[2,1.01,0]],"ltp":1.37,"tv":226.47,"id":8979329}]}]}
{"op":"mcm","clk":"1009145562","pt":1580642320554,"mc":[{"id":"1.168224343","rc":[{"batb":[[0,3.1,20.61],[1,1.01,15.52],[2,1.01,0]],"batl":[[0,5.5,115.06],[1,5.5,0]],"ltp":3.35,"tv":34.94,"id":2397396},{"batb":[[0,1.35,58.78]],"batl":[[0,1.66,579.81],[1,1.66,0]],"ltp":1.37,"tv":226.47,"id":8979329}]}]}
{"op":"mcm","clk":"1009146960","pt":1580642329193,"mc":[{"id":"1.168224343","rc":[{"batb":[[0,3.4,16.76],[1,3.25,19.04],[2,1.01,15.52]],"ltp":3.35,"tv":34.94,"id":2397396},{"batb":[[1,1.34,60.51],[2,1.01,15.51]],"ltp":1.37,"tv":226.47,"id":8979329}]}]}
{"op":"mcm","clk":"1009147014","pt":1580642329464,"mc":[{"id":"1.168224343","rc":[{"batb":[[1,3.35,17.64],[2,3.25,19.04]],"batl":[[0,3.85,14.28],[1,5.5,115.06]],"ltp":3.35,"tv":34.94,"id":2397396},{"batb":[[0,1.35,178.08]],"batl":[[0,1.42,42.01],[1,1.66,579.81]],"ltp":1.37,"tv":226.47,"id":8979329}]}]}
{"op":"mcm","clk":"1009149297","pt":1580642343281,"mc":[{"id":"1.168224343","rc":[{"batb":[[0,3.35,17.64],[1,3.25,19.04],[2,1.01,15.52]],"ltp":3.35,"tv":34.94,"id":2397396},{"batb":[[0,1.35,119.31]],"ltp":1.37,"tv":226.47,"id":8979329}]}]}
{"op":"mcm","clk":"1009149592","pt":1580642344997,"mc":[{"id":"1.168224343","rc":[{"batb":[[0,3.25,19.04],[1,1.01,15.52],[2,1.01,0]],"batl":[[0,5.5,115.06],[1,5.5,0]],"ltp":3.35,"tv":34.94,"id":2397396},{"batb":[[0,1.34,60.51],[1,1.01,15.51],[2,1.01,0]],"batl":[[0,1.66,579.81],[1,1.66,0]],"ltp":1.37,"tv":226.47,"id":8979329}]}]}
{"op":"mcm","clk":"1009151786","pt":1580642359247,"mc":[{"id":"1.168224343","rc":[{"batb":[[1,3.05,21.79],[2,1.01,15.52]],"ltp":3.35,"tv":34.94,"id":2397396},{"batb":[[0,1.38,53.5],[1,1.37,56.02],[2,1.35,743.87]],"ltp":1.37,"tv":226.47,"id":8979329}]}]}
{"op":"mcm","clk":"1009151826","pt":1580642359519,"mc":[{"id":"1.168224343","rc":[{"batb":[[0,3.3,17.64],[1,3.25,19.04],[2,3.05,21.79]],"batl":[[0,3.75,15.12]],"ltp":3.35,"tv":34.94,"id":2397396},{"batb":[[2,1.36,115.95]],"batl":[[0,1.44,42.01],[1,1.66,579.81]],"ltp":1.37,"tv":226.47,"id":8979329}]}]}
{"op":"mcm","clk":"1009152047","pt":1580642361125,"mc":[{"id":"1.168224343","rc":[{"batl":[[1,4.9,126.27]],"ltp":3.35,"tv":34.94,"id":2397396}]}]}
{"op":"mcm","clk":"1009153487","pt":1580642370906,"mc":[{"id":"1.168224343","rc":[{"batb":[[0,3.05,21.79],[1,1.01,15.52],[2,3.05,0]],"batl":[[0,4.9,126.27],[1,4.9,0]],"ltp":3.35,"tv":34.94,"id":2397396},{"batb":[[0,1.37,56.02],[1,1.01,15.51],[2,1.36,0]],"batl":[[0,1.66,579.81],[1,1.66,0]],"ltp":1.37,"tv":226.47,"id":8979329}]}]}
{"op":"mcm","clk":"1009153911","pt":1580642373936,"mc":[{"id":"1.168224343","rc":[{"batb":[[0,3.1,21.17]],"ltp":3.35,"tv":34.94,"id":2397396},{"batb":[[0,1.36,57.28]],"ltp":1.37,"tv":226.47,"id":8979329}]}]}
{"op":"mcm","clk":"1009158724","pt":1580642407302,"mc":[{"id":"1.168224343","rc":[{"batb":[[0,3.35,17.39],[1,3.25,18.8],[2,1.01,15.52]],"ltp":3.35,"tv":34.94,"id":2397396},{"batb":[[1,1.33,62.55],[2,1.01,15.51]],"ltp":1.37,"tv":226.47,"id":8979329}]}]}
{"op":"mcm","clk":"1009158865","pt":1580642407998,"mc":[{"id":"1.168224343","rc":[{"batb":[[0,3.35,35.03]],"batl":[[0,3.85,14.28],[1,4.9,126.27]],"ltp":3.35,"tv":34.94,"id":2397396},{"batb":[[1,1.35,119.31],[2,1.33,62.55]],"batl":[[0,1.42,42.01],[1,1.66,579.81]],"ltp":1.37,"tv":226.47,"id":8979329}]}]}
{"op":"mcm","clk":"1009163050","pt":1580642435319,"mc":[{"id":"1.168224343","rc":[{"batb":[[0,3.35,17.64]],"ltp":3.35,"tv":34.94,"id":2397396},{"batb":[[0,1.35,119.31],[1,1.33,62.55],[2,1.01,15.51]],"ltp":1.37,"tv":226.47,"id":8979329}]}]}
{"op":"mcm","clk":"1009163303","pt":1580642437125,"mc":[{"id":"1.168224343","rc":[{"batb":[[0,3.25,18.8],[1,1.01,15.52],[2,1.01,0]],"batl":[[0,4.9,126.27],[1,4.9,0]],"ltp":3.35,"tv":34.94,"id":2397396},{"batb":[[0,1.33,62.55],[1,1.01,15.51],[2,1.01,0]],"batl":[[0,1.66,579.81],[1,1.66,0]],"ltp":1.37,"tv":226.47,"id":8979329}]}]}
{"op":"mcm","clk":"1009164419","pt":1580642444764,"mc":[{"id":"1.168224343","rc":[{"batb":[[0,3.5,15.42],[1,3.4,16.76],[2,1.01,15.52]],"ltp":3.35,"tv":34.94,"id":2397396},{"batb":[[1,1.31,69.63],[2,1.01,15.51]],"ltp":1.37,"tv":226.47,"id":8979329}]}]}
{"op":"mcm","clk":"1009164558","pt":1580642445626,"mc":[{"id":"1.168224343","rc":[{"batb":[[1,3.45,16.8],[2,3.4,16.76]],"batl":[[0,3.95,13.44]],"ltp":3.35,"tv":34.94,"id":2397396},{"batb":[[0,1.34,123.51],[1,1.33,62.55],[2,1.31,69.63]],"batl":[[0,1.41,42.01],[1,1.66,579.81]],"ltp":1.37,"tv":226.47,"id":8979329}]}]}
{"op":"mcm","clk":"1009164758","pt":1580642446955,"mc":[{"id":"1.168224343","rc":[{"batl":[[1,5.5,115.06]],"ltp":3.35,"tv":34.94,"id":2397396}]}]}
{"op":"mcm","clk":"1009166598","pt":1580642459268,"mc":[{"id":"1.168224343","rc":[{"batb":[[0,3.45,16.8],[1,3.4,16.76],[2,1.01,15.52]],"ltp":3.35,"tv":34.94,"id":2397396},{"batb":[[1,1.31,69.63],[2,1.01,15.51]],"ltp":1.37,"tv":226.47,"id":8979329}]}]}
{"op":"mcm","clk":"1009166758","pt":1580642460652,"mc":[{"id":"1.168224343","rc":[{"batb":[[0,3.4,16.76],[1,1.01,15.52],[2,1.01,0]],"batl":[[0,5.5,115.06],[1,5.5,0]],"ltp":3.35,"tv":34.94,"id":2397396},{"batb":[[0,1.31,69.63],[1,1.01,15.51],[2,1.01,0]],"batl":[[0,1.66,579.81],[1,1.66,0]],"ltp":1.37,"tv":226.47,"id":8979329}]}]}
{"op":"mcm","clk":"1009169181","pt":1580642477018,"mc":[{"id":"1.168224343","rc":[{"batb":[[1,3.3,18.25],[2,1.01,15.52]],"ltp":3.35,"tv":34.94,"id":2397396},{"batb":[[0,1.35,58.78],[1,1.32,64.91],[2,1.01,15.51]],"ltp":1.37,"tv":226.47,"id":8979329}]}]}
{"op":"mcm","clk":"1009169277","pt":1580642477706,"mc":[{"id":"1.168224343","rc":[{"batb":[[0,3.4,33.56]],"batl":[[0,3.9,14.28],[1,5.5,115.06]],"ltp":3.35,"tv":34.94,"id":2397396},{"batb":[[1,1.34,123.51],[2,1.32,64.91]],"batl":[[0,1.42,42.01],[1,1.66,579.81]],"ltp":1.37,"tv":226.47,"id":8979329}]}]}
{"op":"mcm","clk":"1009171056","pt":1580642491050,"mc":[{"id":"1.168224343","rc":[{"batb":[[0,3.4,16.8]],"ltp":3.35,"tv":34.94,"id":2397396},{"batb":[[0,1.34,123.51],[1,1.32,64.91],[2,1.01,15.51]],"ltp":1.37,"tv":226.47,"id":8979329}]}]}
{"op":"mcm","clk":"1009171249","pt":1580642492653,"mc":[{"id":"1.168224343","rc":[{"batb":[[0,3.3,18.25],[1,1.01,15.52],[2,1.01,0]],"batl":[[0,5.5,115.06],[1,5.5,0]],"ltp":3.35,"tv":34.94,"id":2397396},{"batb":[[0,1.32,64.91],[1,1.01,15.51],[2,1.01,0]],"batl":[[0,1.66,579.81],[1,1.66,0]],"ltp":1.37,"tv":226.47,"id":8979329}]}]}
{"op":"mcm","clk":"1009174839","pt":1580642519067,"mc":[{"id":"1.168224343","rc":[{"batb":[[1,3.15,19.91],[2,1.01,15.52]],"ltp":3.35,"tv":34.94,"id":2397396},{"batb":[[0,1.37,55.16],[1,1.35,60.19],[2,1.01,15.51]],"ltp":1.37,"tv":226.47,"id":8979329}]}]}
{"op":"mcm","clk":"1009174903","pt":1580642519551,"mc":[{"id":"1.168224343","rc":[{"batb":[[0,3.35,17.64],[1,3.3,18.25],[2,3.15,19.91]],"batl":[[0,3.85,14.28]],"ltp":3.35,"tv":34.94,"id":2397396},{"batb":[[1,1.35,179.5]],"batl":[[0,1.43,42.01],[1,1.66,579.81]],"ltp":1.37,"tv":226.47,"id":8979329}]}]}
{"op":"mcm","clk":"1009175145","pt":1580642521265,"mc":[{"id":"1.168224343","rc":[{"batl":[[1,4.9,126.27]],"ltp":3.35,"tv":34.94,"id":2397396}]}]}
{"op":"mcm","clk":"1009177348","pt":1580642536180,"mc":[{"id":"1.168224343","rc":[{"batb":[[1,3.15,19.91],[2,1.01,15.52]],"ltp":3.35,"tv":34.94,"id":2397396},{"batb":[[0,1.35,179.5],[1,1.01,15.51],[2,1.01,0]],"ltp":1.37,"tv":226.47,"id":8979329}]}]}
{"op":"mcm","clk":"1009177414","pt":1580642536597,"mc":[{"id":"1.168224343","rc":[{"batb":[[0,3.15,19.91],[1,1.01,15.52],[2,1.01,0]],"batl":[[0,4.9,126.27],[1,4.9,0]],"ltp":3.35,"tv":34.94,"id":2397396},{"batb":[[0,1.35,60.19]],"batl":[[0,1.66,579.81],[1,1.66,0]],"ltp":1.37,"tv":226.47,"id":8979329}]}]}
{"op":"mcm","clk":"1009180069","pt":1580642553225,"mc":[{"id":"1.168224343","rc":[{"batb":[[1,3.1,21.24],[2,1.01,15.52]],"ltp":3.35,"tv":34.94,"id":2397396},{"batb":[[0,1.39,51.62],[1,1.37,56.02],[2,1.35,60.19]],"ltp":1.37,"tv":226.47,"id":8979329}]}]}
{"op":"mcm","clk":"1009180162","pt":1580642553804,"mc":[{"id":"1.168224343","rc":[{"batb":[[0,3.3,17.64],[1,3.15,19.91],[2,3.1,21.24]],"batl":[[0,3.75,15.12],[1,4.9,126.27]],"ltp":3.35,"tv":34.94,"id":2397396},{"batb":[[2,1.36,115.95]],"batl":[[0,1.44,42.01],[1,1.66,579.81]],"ltp":1.37,"tv":226.47,"id":8979329}]}]}
{"op":"mcm","clk":"1009180518","pt":1580642556360,"mc":[{"id":"1.168224343","rc":[{"batb":[[2,1.36,1402.13]],"ltp":1.37,"tv":226.47,"id":8979329}]}]}
{"op":"mcm","clk":"1009180540","pt":1580642556474,"mc":[{"id":"1.168224343","rc":[{"batb":[[2,1.36,115.95]],"ltp":1.37,"tv":226.47,"id":8979329}]}]}
{"op":"mcm","clk":"1009181956","pt":1580642565712,"mc":[{"id":"1.168224343","rc":[{"batb":[[1,3.1,21.24],[2,1.01,15.52]],"ltp":3.35,"tv":34.94,"id":2397396},{"batb":[[0,1.37,56.02],[1,1.36,115.95],[2,1.01,15.51]],"ltp":1.37,"tv":226.47,"id":8979329}]}]}
{"op":"mcm","clk":"1009182101","pt":1580642566613,"mc":[{"id":"1.168224343","rc":[{"batb":[[0,3.1,21.24],[1,1.01,15.52],[2,1.01,0]],"batl":[[0,4.9,126.27],[1,4.9,0]],"ltp":3.35,"tv":34.94,"id":2397396},{"batb":[[1,1.01,15.51],[2,1.01,0]],"batl":[[0,1.66,579.81],[1,1.66,0]],"ltp":1.37,"tv":226.47,"id":8979329}]}]}
{"op":"mcm","clk":"1009183491","pt":1580642576016,"mc":[{"id":"1.168224343","rc":[{"batb":[[0,3.35,17.64],[1,3.3,17.86],[2,3.2,19.36]],"batl":[[0,3.85,14.28],[1,4.9,126.27]],"ltp":3.35,"tv":34.94,"id":2397396},{"batb":[[1,1.35,119.31],[2,1.33,62.71]],"batl":[[0,1.42,42.01],[1,1.66,579.81]],"ltp":1.37,"tv":226.47,"id":8979329}]}]}
{"op":"mcm","clk":"1009185939","pt":1580642592601,"mc":[{"id":"1.168224343","rc":[{"batb":[[0,3.2,19.36],[1,1.01,15.52],[2,3.2,0]],"batl":[[0,4.9,126.27],[1,4.9,0]],"ltp":3.35,"tv":34.94,"id":2397396},{"batb":[[0,1.33,62.71],[1,1.01,15.51],[2,1.33,0]],"batl":[[0,1.66,579.81],[1,1.66,0]],"ltp":1.37,"tv":226.47,"id":8979329}]}]}
{"op":"mcm","clk":"1009187148","pt":1580642601146,"mc":[{"id":"1.168224343","rc":[{"batb":[[0,3.5,15.34],[1,3.35,17.23],[2,1.01,15.52]],"ltp":3.35,"tv":34.94,"id":2397396},{"batb":[[1,1.31,69.55],[2,1.01,15.51]],"ltp":1.37,"tv":226.47,"id":8979329}]}]}
{"op":"mcm","clk":"1009187316","pt":1580642602312,"mc":[{"id":"1.168224343","rc":[{"batb":[[1,3.45,16.8],[2,3.35,17.23]],"batl":[[0,3.95,13.44]],"ltp":3.35,"tv":34.94,"id":2397396},{"batb":[[0,1.34,123.51],[1,1.33,62.71],[2,1.31,69.55]],"batl":[[0,1.41,42.01],[1,1.66,579.81]],"ltp":1.37,"tv":226.47,"id":8979329}]}]}
{"op":"mcm","clk":"1009187488","pt":1580642603436,"mc":[{"id":"1.168224343","rc":[{"batl":[[1,5.5,115.06]],"ltp":3.35,"tv":34.94,"id":2397396}]}]}
{"op":"mcm","clk":"1009189881","pt":1580642619892,"mc":[{"id":"1.168224343","rc":[{"batb":[[0,3.45,16.8],[1,3.35,17.23],[2,1.01,15.52]],"ltp":3.35,"tv":34.94,"id":2397396},{"batb":[[1,1.31,69.55],[2,1.01,15.51]],"ltp":1.37,"tv":226.47,"id":8979329}]}]}
{"op":"mcm","clk":"1009190006","pt":1580642620646,"mc":[{"id":"1.168224343","rc":[{"batb":[[0,3.35,17.23],[1,1.01,15.52],[2,1.01,0]],"batl":[[0,5.5,115.06],[1,5.5,0]],"ltp":3.35,"tv":34.94,"id":2397396},{"batb":[[0,1.31,69.55],[1,1.01,15.51],[2,1.01,0]],"batl":[[0,1.66,579.81],[1,1.66,0]],"ltp":1.37,"tv":226.47,"id":8979329}]}]}
{"op":"mcm","clk":"1009192266","pt":1580642636272,"mc":[{"id":"1.168224343","rc":[{"batb":[[0,3.75,13.3],[1,3.55,30.99],[2,1.01,15.52]],"batl":[[0,4,13.44],[1,5.5,115.06]],"ltp":3.35,"tv":34.94,"id":2397396},{"batb":[[0,1.33,126.87],[1,1.31,69.55],[2,1.27,80.65]],"batl":[[0,1.39,42.01],[1,1.66,579.81]],"ltp":1.37,"tv":226.47,"id":8979329}]}]}
{"op":"mcm","clk":"1009194296","pt":1580642650098,"mc":[{"id":"1.168224343","rc":[{"batb":[[0,3.55,30.99],[1,1.01,15.52],[2,1.01,0]],"ltp":3.35,"tv":34.94,"id":2397396},{"batb":[[1,1.27,80.65],[2,1.01,15.51]],"ltp":1.37,"tv":226.47,"id":8979329}]}]}
{"op":"mcm","clk":"1009194410","pt":1580642651037,"mc":[{"id":"1.168224343","rc":[{"batb":[[0,3.55,15.03]],"batl":[[0,5.5,115.06],[1,5.5,0]],"ltp":3.35,"tv":34.94,"id":2397396},{"batb":[[0,1.27,80.65],[1,1.01,15.51],[2,1.01,0]],"batl":[[0,1.66,579.81],[1,1.66,0]],"ltp":1.37,"tv":226.47,"id":8979329}]}]}
{"op":"mcm","clk":"1009195488","pt":1580642658012,"mc":[{"id":"1.168224343","rc":[{"batb":[[0,4,21.87],[1,3.8,39.46],[2,1.01,15.52]],"batl":[[0,4.4,11.76],[1,5.5,115.06]],"ltp":3.35,"tv":34.94,"id":2397396},{"batb":[[0,1.29,144.51],[1,1.27,80.65],[2,1.26,84.98]],"batl":[[0,1.36,42.01],[1,1.66,579.81]],"ltp":1.37,"tv":226.47,"id":8979329}]}]}
{"op":"mcm","clk":"1009203353","pt":1580642713073,"mc":[{"id":"1.168224343","rc":[{"batb":[[1,3.8,27.11]],"ltp":3.35,"tv":34.94,"id":2397396},{"batb":[[1,1.27,79.47],[2,1.26,83.72]],"ltp":1.37,"tv":226.47,"id":8979329}]}]}
{"op":"mcm","clk":"1009207278","pt":1580642740604,"mc":[{"id":"1.168224343","rc":[{"batb":[[0,3.8,12.83],[1,1.01,15.52],[2,1.01,0]],"batl":[[0,5.5,115.06],[1,5.5,0]],"ltp":3.35,"tv":34.94,"id":2397396},{"batb":[[0,1.26,83.72],[1,1.01,15.51],[2,1.26,0]],"batl":[[0,1.66,579.81],[1,1.66,0]],"ltp":1.37,"tv":226.47,"id":8979329}]}]}
{"op":"mcm","clk":"1009208208","pt":1580642747089,"mc":[{"id":"1.168224343","rc":[{"batb":[[0,4.1,20.77],[1,3.9,24.08],[2,3.85,282.97]],"ltp":3.35,"tv":34.94,"id":2397396},{"batb":[[1,1.25,87.02],[2,1.01,15.51]],"ltp":1.37,"tv":226.47,"id":8979329}]}]}
{"op":"mcm","clk":"1009208331","pt":1580642747939,"mc":[{"id":"1.168224343","rc":[{"batb":[[1,3.9,38.36],[2,1.01,15.52]],"batl":[[0,4.4,11.76]],"ltp":3.35,"tv":34.94,"id":2397396},{"batb":[[0,1.29,144.51],[1,1.26,83.72],[2,1.25,87.02]],"batl":[[0,1.35,42.01],[1,1.66,579.81]],"ltp":1.37,"tv":226.47,"id":8979329}]}]}
{"op":"mcm","clk":"1009208478","pt":1580642748894,"mc":[{"id":"1.168224343","rc":[{"batl":[[1,6.6,98.95]],"ltp":3.35,"tv":34.94,"id":2397396}]}]}
{"op":"mcm","clk":"1009209299","pt":1580642754320,"mc":[{"id":"1.168224343","rc":[{"batb":[[0,3.9,38.36],[1,1.01,15.52],[2,1.01,0]],"ltp":3.35,"tv":34.94,"id":2397396},{"batb":[[1,1.25,87.02],[2,1.01,15.51]],"ltp":1.37,"tv":226.47,"id":8979329}]}]}
{"op":"mcm","clk":"1009209363","pt":1580642754749,"mc":[{"id":"1.168224343","rc":[{"batb":[[0,3.9,24.08]],"batl":[[0,6.6,98.95],[1,6.6,0]],"ltp":3.35,"tv":34.94,"id":2397396},{"batb":[[0,1.25,87.02],[1,1.01,15.51],[2,1.01,0]],"batl":[[0,1.66,579.81],[1,1.66,0]],"ltp":1.37,"tv":226.47,"id":8979329}]}]}
{"op":"mcm","clk":"1009209746","pt":1580642757330,"mc":[{"id":"1.168224343","rc":[{"batb":[[1,3.85,24.71],[2,1.01,15.52]],"ltp":3.35,"tv":34.94,"id":2397396}]}]}
{"op":"mcm","clk":"1009209863","pt":1580642758139,"mc":[{"id":"1.168224343","rc":[{"batb":[[0,3.85,24.71],[1,1.01,15.52],[2,1.01,0]],"ltp":3.35,"tv":34.94,"id":2397396},{"batb":[[0,1.01,15.51],[1,1.01,0]],"ltp":1.37,"tv":226.47,"id":8979329}]}]}
{"op":"mcm","clk":"1009213097","pt":1580642780244,"mc":[{"id":"1.168224343","rc":[{"batb":[[1,3.65,14.16],[2,1.01,15.52]],"ltp":3.35,"tv":34.94,"id":2397396},{"batb":[[0,1.29,74.12],[1,1.28,78.29],[2,1.01,15.51]],"ltp":1.37,"tv":226.47,"id":8979329}]}]}
{"op":"mcm","clk":"1009213414","pt":1580642782375,"mc":[{"id":"1.168224343","rc":[{"batb":[[1,3.8,14.28],[2,3.65,14.16]],"batl":[[0,4.3,12.6]],"ltp":3.35,"tv":34.94,"id":2397396},{"batb":[[0,1.3,139.47],[1,1.29,74.12],[2,1.28,78.29]],"batl":[[0,1.36,42.01],[1,1.66,579.81]],"ltp":1.37,"tv":226.47,"id":8979329}]}]}
{"op":"mcm","clk":"1009213440","pt":1580642782544,"mc":[{"id":"1.168224343","rc":[{"batl":[[1,6,106.18]],"ltp":3.35,"tv":34.94,"id":2397396}]}]}
{"op":"mcm","clk":"1009215633","pt":1580642797169,"mc":[{"id":"1.168224343","rc":[{"batb":[[0,3.8,14.28],[1,3.65,14.16],[2,1.01,15.52]],"ltp":3.35,"tv":34.94,"id":2397396},{"batb":[[1,1.28,78.29],[2,1.01,15.51]],"ltp":1.37,"tv":226.47,"id":8979329}]}]}
{"op":"mcm","clk":"1009215923","pt":1580642798606,"mc":[{"id":"1.168224343","rc":[{"batb":[[0,3.65,14.16],[1,1.01,15.52],[2,1.01,0]],"batl":[[0,6,106.18],[1,6,0]],"ltp":3.35,"tv":34.94,"id":2397396},{"batb":[[0,1.28,78.29],[1,1.01,15.51],[2,1.01,0]],"batl":[[0,1.66,579.81],[1,1.66,0]],"ltp":1.37,"tv":226.47,"id":8979329}]}]}
{"op":"mcm","clk":"1009219832","pt":1580642822383,"mc":[{"id":"1.168224343","rc":[{"batb":[[0,4,22.9],[1,3.8,14.28],[2,3.75,13.06]],"batl":[[0,4.4,11.76],[1,6,106.18]],"ltp":3.35,"tv":34.94,"id":2397396},{"batb":[[0,1.29,144.51],[1,1.28,78.29],[2,1.27,82.14]],"batl":[[0,1.36,42.01],[1,1.66,579.81]],"ltp":1.37,"tv":226.47,"id":8979329}]}]}
{"op":"mcm","clk":"1009222845","pt":1580642843084,"mc":[{"id":"1.168224343","rc":[{"batb":[[0,3.75,13.06],[1,1.01,15.52],[2,3.75,0]],"batl":[[0,6,106.18],[1,6,0]],"ltp":3.35,"tv":34.94,"id":2397396},{"batb":[[0,1.27,81.44],[1,1.01,15.51],[2,1.27,0]],"batl":[[0,1.66,579.81],[1,1.66,0]],"ltp":1.37,"tv":226.47,"id":8979329}]}]}
{"op":"mcm","clk":"1009223891","pt":1580642849376,"mc":[{"id":"1.168224343","rc":[{"batb":[[0,4,21.64],[1,3.85,24.94],[2,1.01,15.52]],"ltp":3.35,"tv":34.94,"id":2397396},{"batb":[[1,1.26,85.13],[2,1.01,15.51]],"ltp":1.37,"tv":226.47,"id":8979329}]}]}
{"op":"mcm","clk":"1009224037","pt":1580642850380,"mc":[{"id":"1.168224343","rc":[{"batb":[[1,3.9,14.28],[2,3.85,24.94]],"batl":[[0,4.4,11.76],[1,6,106.18]],"ltp":3.35,"tv":34.94,"id":2397396},{"batb":[[0,1.29,144.51],[1,1.27,81.44],[2,1.26,85.13]],"batl":[[0,1.35,42.01],[1,1.66,579.81]],"ltp":1.37,"tv":226.47,"id":8979329}]}]}
{"op":"mcm","clk":"1009225761","pt":1580642860714,"mc":[{"id":"1.168224343","rc":[{"batb":[[0,3.85,24.94],[1,1.01,15.52],[2,3.85,0]],"batl":[[0,6,106.18],[1,6,0]],"ltp":3.35,"tv":34.94,"id":2397396},{"batb":[[0,1.26,85.13],[1,1.01,15.51],[2,1.26,0]],"batl":[[0,1.66,579.81],[1,1.66,0]],"ltp":1.37,"tv":226.47,"id":8979329}]}]}
{"op":"mcm","clk":"1009228779","pt":1580642881209,"mc":[{"id":"1.168224343","rc":[{"batb":[[0,4.2,20.3],[1,4,22.11],[2,3.85,24.94]],"ltp":3.35,"tv":34.94,"id":2397396},{"batb":[[1,1.24,92.69],[2,1.01,15.51]],"ltp":1.37,"tv":226.47,"id":8979329}]}]}
{"op":"mcm","clk":"1009228886","pt":1580642882030,"mc":[{"id":"1.168224343","rc":[{"batb":[[1,4,35.55],[2,1.01,15.52]],"batl":[[0,4.6,10.92],[1,6,106.18]],"ltp":3.35,"tv":34.94,"id":2397396},{"batb":[[0,1.28,149.55],[1,1.26,85.13],[2,1.24,92.69]],"batl":[[0,1.34,42.01],[1,1.66,579.81]],"ltp":1.37,"tv":226.47,"id":8979329}]}]}
{"op":"mcm","clk":"1009231408","pt":1580642900174,"mc":[{"id":"1.168224343","rc":[{"batb":[[0,4,35.55],[1,1.01,15.52],[2,1.01,0]],"ltp":3.35,"tv":34.94,"id":2397396},{"batb":[[1,1.24,92.69],[2,1.01,15.51]],"ltp":1.37,"tv":226.47,"id":8979329}]}]}
{"op":"mcm","clk":"1009231492","pt":1580642900770,"mc":[{"id":"1.168224343","rc":[{"batb":[[0,4,22.11]],"batl":[[0,6,106.18],[1,6,0]],"ltp":3.35,"tv":34.94,"id":2397396},{"batb":[[0,1.24,92.69],[1,1.01,15.51],[2,1.01,0]],"batl":[[0,1.66,579.81],[1,1.66,0]],"ltp":1.37,"tv":226.47,"id":8979329}]}]}
{"op":"mcm","clk":"1009233866","pt":1580642917386,"mc":[{"id":"1.168224343","rc":[{"batb":[[0,4.4,17.94],[1,4.2,19.99],[2,4,64.07]],"ltp":3.35,"tv":34.94,"id":2397396},{"batb":[[1,1.22,100.79],[2,1.01,15.51]],"ltp":1.37,"tv":226.47,"id":8979329}]}]}
{"op":"mcm","clk":"1009233908","pt":1580642917658,"mc":[{"id":"1.168224343","rc":[{"batb":[[2,4,13.44]],"batl":[[0,4.7,10.92]],"ltp":3.35,"tv":34.94,"id":2397396},{"batb":[[0,1.27,155.44],[1,1.24,92.69],[2,1.22,100.79]],"batl":[[0,1.33,42.01]],"ltp":1.37,"tv":226.47,"id":8979329}]}]}
{"op":"mcm","clk":"1009234028","pt":1580642918557,"mc":[{"id":"1.168224343","rc":[{"batl":[[1,1.58,650.58]],"ltp":1.37,"tv":226.47,"id":8979329}]}]}
{"op":"mcm","clk":"1009234193","pt":1580642919676,"mc":[{"id":"1.168224343","rc":[{"batl":[[1,7.2,92.18]],"ltp":3.35,"tv":34.94,"id":2397396}]}]}
{"op":"mcm","clk":"1009235644","pt":1580642929372,"mc":[{"id":"1.168224343","rc":[{"batb":[[0,4.2,19.99],[1,4,13.44],[2,1.01,15.52]],"ltp":3.35,"tv":34.94,"id":2397396},{"batb":[[1,1.22,100.79],[2,1.01,15.51]],"ltp":1.37,"tv":226.47,"id":8979329}]}]}
{"op":"mcm","clk":"1009235889","pt":1580642931187,"mc":[{"id":"1.168224343","rc":[{"batb":[[1,1.01,15.52],[2,1.01,0]],"batl":[[0,7.2,92.18],[1,7.2,0]],"ltp":3.35,"tv":34.94,"id":2397396},{"batb":[[0,1.22,100.79],[1,1.01,15.51],[2,1.01,0]],"batl":[[0,1.58,650.58],[1,1.58,0]],"ltp":1.37,"tv":226.47,"id":8979329}]}]}
{"op":"mcm","clk":"1009238014","pt":1580642944306,"mc":[{"id":"1.168224343","rc":[{"batb":[[1,4,21.72],[2,1.01,15.52]],"ltp":3.35,"tv":34.94,"id":2397396},{"batb":[[0,1.26,86],[1,1.24,94.58],[2,1.22,100.79]],"ltp":1.37,"tv":226.47,"id":8979329}]}]}
{"op":"mcm","clk":"1009238173","pt":1580642945329,"mc":[{"id":"1.168224343","rc":[{"batl":[[0,6.6,98.95]],"ltp":3.35,"tv":34.94,"id":2397396},{"batb":[[2,1.01,15.51]],"ltp":1.37,"tv":226.47,"id":8979329}]}]}
{"op":"mcm","clk":"1009238278","pt":1580642946009,"mc":[{"id":"1.168224343","rc":[{"batb":[[1,4,35.16]],"batl":[[0,4.6,10.92],[1,6.6,98.95]],"ltp":3.35,"tv":34.94,"id":2397396},{"batb":[[0,1.28,149.55],[1,1.26,86],[2,1.24,94.58]],"batl":[[0,1.34,42.01],[1,1.58,650.58]],"ltp":1.37,"tv":226.47,"id":8979329}]}]}
{"op":"mcm","clk":"1009239001","pt":1580642950432,"mc":[{"id":"1.168224343","rc":[{"batl":[[1,6.6,0]],"ltp":3.35,"tv":34.94,"id":2397396}]}]}
{"op":"mcm","clk":"1009239580","pt":1580642954346,"mc":[{"id":"1.168224343","rc":[{"batl":[[1,6,106.18]],"ltp":3.35,"tv":34.94,"id":2397396}]}]}
{"op":"mcm","clk":"1009239908","pt":1580642956338,"mc":[{"id":"1.168224343","rc":[{"batb":[[0,4,35.16],[1,1.01,15.52],[2,1.01,0]],"ltp":3.35,"tv":34.94,"id":2397396},{"batb":[[1,1.24,94.58],[2,1.01,15.51]],"ltp":1.37,"tv":226.47,"id":8979329}]}]}
{"op":"mcm","clk":"1009239991","pt":1580642956880,"mc":[{"id":"1.168224343","rc":[{"batb":[[0,4,21.72]],"batl":[[0,6,106.18],[1,6,0]],"ltp":3.35,"tv":34.94,"id":2397396},{"batb":[[0,1.24,94.58],[1,1.01,15.51],[2,1.01,0]],"batl":[[0,1.58,650.58],[1,1.58,0]],"ltp":1.37,"tv":226.47,"id":8979329}]}]}
{"op":"mcm","clk":"1009244579","pt":1580642986290,"mc":[{"id":"1.168224343","rc":[{"batb":[[1,3.95,13.44],[2,3.9,23.68]],"batl":[[0,4.5,11.76],[1,6,106.18]],"ltp":3.35,"tv":34.94,"id":2397396},{"batb":[[0,1.28,149.55],[1,1.27,81.2],[2,1.25,87.97]],"batl":[[0,1.34,42.01],[1,1.58,650.58]],"ltp":1.37,"tv":226.47,"id":8979329}]}]}
{"op":"mcm","clk":"1009246990","pt":1580643001617,"mc":[{"id":"1.168224343","rc":[{"batb":[[0,3.95,13.44],[1,3.9,23.68],[2,1.01,15.52]],"ltp":3.35,"tv":34.94,"id":2397396},{"batb":[[1,1.25,87.97],[2,1.01,15.51]],"ltp":1.37,"tv":226.47,"id":8979329}]}]}
{"op":"mcm","clk":"1009247175","pt":1580643002830,"mc":[{"id":"1.168224343","rc":[{"batb":[[0,3.9,23.68],[1,1.01,15.52],[2,1.01,0]],"batl":[[0,6,106.18],[1,6,0]],"ltp":3.35,"tv":34.94,"id":2397396},{"batb":[[0,1.25,87.97],[1,1.01,15.51],[2,1.01,0]],"batl":[[0,1.58,650.58],[1,1.58,0]],"ltp":1.37,"tv":226.47,"id":8979329}]}]}
{"op":"mcm","clk":"1009249161","pt":1580643015324,"mc":[{"id":"1.168224343","rc":[{"batb":[[0,4.2,19.36],[1,4.1,21.32],[2,1.01,15.52]],"ltp":3.35,"tv":34.94,"id":2397396},{"batb":[[1,1.23,97.41],[2,1.01,15.51]],"ltp":1.37,"tv":226.47,"id":8979329}]}]}
{"op":"mcm","clk":"1009249223","pt":1580643016005,"mc":[{"id":"1.168224343","rc":[{"batb":[[2,4,13.44]],"batl":[[0,4.6,10.92],[1,6,106.18]],"ltp":3.35,"tv":34.94,"id":2397396},{"batb":[[0,1.27,155.44],[1,1.25,87.97],[2,1.23,97.41]],"batl":[[0,1.33,42.01],[1,1.58,650.58]],"ltp":1.37,"tv":226.47,"id":8979329}]}]}
{"op":"mcm","clk":"1009252135","pt":1580643033064,"mc":[{"id":"1.168224343","rc":[{"batb":[[0,4.1,21.32],[1,4,13.44],[2,1.01,15.52]],"ltp":3.35,"tv":34.94,"id":2397396},{"batb":[[1,1.23,97.41],[2,1.01,15.51]],"ltp":1.37,"tv":226.47,"id":8979329}]}]}
{"op":"mcm","clk":"1009252411","pt":1580643034763,"mc":[{"id":"1.168224343","rc":[{"batb":[[1,1.01,15.52],[2,1.01,0]],"batl":[[0,6,106.18],[1,6,0]],"ltp":3.35,"tv":34.94,"id":2397396},{"batb":[[0,1.23,97.41],[1,1.01,15.51],[2,1.01,0]],"batl":[[0,1.58,650.58],[1,1.58,0]],"ltp":1.37,"tv":226.47,"id":8979329}]}]}
{"op":"mcm","clk":"1009253186","pt":1580643039270,"mc":[{"id":"1.168224343","rc":[{"batb":[[1,4,22.9],[2,1.01,15.52]],"ltp":3.35,"tv":34.94,"id":2397396},{"batb":[[0,1.27,82.3],[1,1.25,89.62],[2,1.01,15.51]],"ltp":1.37,"tv":226.47,"id":8979329}]}]}
{"op":"mcm","clk":"1009253313","pt":1580643039967,"mc":[{"id":"1.168224343","rc":[{"batb":[[2,3.95,13.44]],"batl":[[0,4.6,10.92],[1,6,106.18]],"ltp":3.35,"tv":34.94,"id":2397396},{"batb":[[0,1.28,149.55],[1,1.27,82.3],[2,1.25,89.62]],"batl":[[0,1.34,42.01],[1,1.58,650.58]],"ltp":1.37,"tv":226.47,"id":8979329}]}]}
{"op":"mcm","clk":"1009255307","pt":1580643052272,"mc":[{"id":"1.168224343","rc":[{"batb":[[0,4,22.9],[1,3.95,13.44],[2,1.01,15.52]],"ltp":3.35,"tv":34.94,"id":2397396},{"batb":[[1,1.25,89.62],[2,1.01,15.51]],"ltp":1.37,"tv":226.47,"id":8979329}]}]}
{"op":"mcm","clk":"1009255394","pt":1580643052855,"mc":[{"id":"1.168224343","rc":[{"batb":[[1,1.01,15.52],[2,1.01,0]],"batl":[[0,6,106.18],[1,6,0]],"ltp":3.35,"tv":34.94,"id":2397396},{"batb":[[0,1.25,89.62],[1,1.01,15.51],[2,1.01,0]],"batl":[[0,1.58,650.58],[1,1.58,0]],"ltp":1.37,"tv":226.47,"id":8979329}]}]}
{"op":"mcm","clk":"1009256766","pt":1580643061187,"mc":[{"id":"1.168224343","rc":[{"batb":[[0,4.3,18.8],[1,4.1,20.69],[2,1.01,15.52]],"ltp":3.35,"tv":34.94,"id":2397396},{"batb":[[1,1.23,98.67],[2,1.01,15.51]],"ltp":1.37,"tv":226.47,"id":8979329}]}]}
{"op":"mcm","clk":"1009256856","pt":1580643061809,"mc":[{"id":"1.168224343","rc":[{"batb":[[2,4,13.44]],"batl":[[0,4.7,10.92],[1,6,106.18]],"ltp":3.35,"tv":34.94,"id":2397396},{"batb":[[0,1.27,155.44],[1,1.25,89.62],[2,1.23,98.67]],"batl":[[0,1.33,42.01],[1,1.58,650.58]],"ltp":1.37,"tv":226.47,"id":8979329}]}]}
{"op":"mcm","clk":"1009258870","pt":1580643074845,"mc":[{"id":"1.168224343","rc":[{"batb":[[0,4.1,20.69],[1,1.01,15.52],[2,4,0]],"batl":[[0,6,106.18],[1,6,0]],"ltp":3.35,"tv":34.94,"id":2397396},{"batb":[[0,1.23,98.67],[1,1.01,15.51],[2,1.23,0]],"batl":[[0,1.58,650.58],[1,1.58,0]],"ltp":1.37,"tv":226.47,"id":8979329}]}]}
{"op":"mcm","clk":"1009262374","pt":1580643097350,"mc":[{"id":"1.168224343","rc":[{"batb":[[0,4.6,16.29],[1,4.3,18.49],[2,4.1,62.34]],"ltp":3.35,"tv":34.94,"id":2397396},{"batb":[[1,1.2,111.1],[2,1.01,15.51]],"ltp":1.37,"tv":226.47,"id":8979329}]}]}
{"op":"mcm","clk":"1009262453","pt":1580643097834,"mc":[{"id":"1.168224343","rc":[{"batb":[[2,4.1,13.44]],"batl":[[0,4.8,10.92],[1,6,106.18]],"ltp":3.35,"tv":34.94,"id":2397396},{"batb":[[0,1.26,161.32],[1,1.23,98.67],[2,1.2,111.1]],"batl":[[0,1.32,42.01],[1,1.58,650.58]],"ltp":1.37,"tv":226.47,"id":8979329}]}]}
{"op":"mcm","clk":"1009264843","pt":1580643113857,"mc":[{"id":"1.168224343","rc":[{"batb":[[0,4.3,18.49],[1,4.1,13.44],[2,1.01,15.52]],"ltp":3.35,"tv":34.94,"id":2397396},{"batb":[[1,1.2,111.1],[2,1.01,15.51]],"ltp":1.37,"tv":226.47,"id":8979329}]}]}
{"op":"mcm","clk":"1009265006","pt":1580643114976,"mc":[{"id":"1.168224343","rc":[{"batb":[[1,1.01,15.52],[2,1.01,0]],"batl":[[0,6,106.18],[1,6,0]],"ltp":3.35,"tv":34.94,"id":2397396},{"batb":[[0,1.2,111.1],[1,1.01,15.51],[2,1.01,0]],"batl":[[0,1.58,650.58],[1,1.58,0]],"ltp":1.37,"tv":226.47,"id":8979329}]}]}
{"op":"mcm","clk":"1009265329","pt":1580643117266,"mc":[{"id":"1.168224343","rc":[{"batb":[[0,1.21,109.92]],"ltp":1.37,"tv":226.47,"id":8979329}]}]}
{"op":"mcm","clk":"1009267632","pt":1580643133167,"mc":[{"id":"1.168224343","rc":[{"batb":[[1,4.1,20.85],[2,1.01,15.52]],"ltp":3.35,"tv":34.94,"id":2397396},{"batb":[[0,1.25,89.93],[1,1.23,97.96],[2,1.21,109.92]],"ltp":1.37,"tv":226.47,"id":8979329}]}]}
{"op":"mcm","clk":"1009267779","pt":1580643134271,"mc":[{"id":"1.168224343","rc":[{"batb":[[1,4.1,34.29]],"batl":[[0,4.7,10.92],[1,6,106.18]],"ltp":3.35,"tv":34.94,"id":2397396},{"batb":[[0,1.27,155.44],[1,1.25,89.93],[2,1.23,97.96]],"batl":[[0,1.33,42.01],[1,1.58,650.58]],"ltp":1.37,"tv":226.47,"id":8979329}]}]}
{"op":"mcm","clk":"1009270084","pt":1580643149379,"mc":[{"id":"1.168224343","rc":[{"batb":[[0,4.1,34.29],[1,1.01,15.52],[2,1.01,0]],"ltp":3.35,"tv":34.94,"id":2397396},{"batb":[[1,1.23,97.96],[2,1.01,15.51]],"ltp":1.37,"tv":226.47,"id":8979329}]}]}
{"op":"mcm","clk":"1009270432","pt":1580643151273,"mc":[{"id":"1.168224343","rc":[{"batb":[[0,4.1,20.85]],"batl":[[0,6,106.18],[1,6,0]],"ltp":3.35,"tv":34.94,"id":2397396},{"batb":[[0,1.23,97.96],[1,1.01,15.51],[2,1.01,0]],"batl":[[0,1.58,650.58],[1,1.58,0]],"ltp":1.37,"tv":226.47,"id":8979329}]}]}
{"op":"mcm","clk":"1009271114","pt":1580643155215,"mc":[{"id":"1.168224343","rc":[{"batb":[[1,4,22.27],[2,1.01,15.52]],"ltp":3.35,"tv":34.94,"id":2397396},{"batb":[[0,1.26,83.56],[1,1.25,90.17],[2,1.23,97.96]],"ltp":1.37,"tv":226.47,"id":8979329}]}]}
{"op":"mcm","clk":"1009271214","pt":1580643155829,"mc":[{"id":"1.168224343","rc":[{"batb":[[1,4,35.71]],"batl":[[0,4.6,10.92],[1,6,106.18]],"ltp":3.35,"tv":34.94,"id":2397396},{"batb":[[0,1.27,155.44],[1,1.26,83.56],[2,1.25,90.17]],"batl":[[0,1.33,42.01],[1,1.58,650.58]],"ltp":1.37,"tv":226.47,"id":8979329}]}]}
{"op":"mcm","clk":"1009272751","pt":1580643165369,"mc":[{"id":"1.168224343","rc":[{"batb":[[0,4,35.71],[1,1.01,15.52],[2,1.01,0]],"ltp":3.35,"tv":34.94,"id":2397396},{"batb":[[1,1.25,90.17],[2,1.01,15.51]],"ltp":1.37,"tv":226.47,"id":8979329}]}]}
{"op":"mcm","clk":"1009273019","pt":1580643166904,"mc":[{"id":"1.168224343","rc":[{"batb":[[0,4,22.27]],"batl":[[0,6,106.18],[1,6,0]],"ltp":3.35,"tv":34.94,"id":2397396},{"batb":[[0,1.25,90.17],[1,1.01,15.51],[2,1.01,0]],"batl":[[0,1.58,650.58],[1,1.58,0]],"ltp":1.37,"tv":226.47,"id":8979329}]}]}
{"op":"mcm","clk":"1009277485","pt":1580643196207,"mc":[{"id":"1.168224343","rc":[{"batb":[[1,3.9,14.28],[2,3.75,13.22]],"batl":[[0,4.5,11.76],[1,6,106.18]],"ltp":3.35,"tv":34.94,"id":2397396},{"batb":[[0,1.29,144.51],[1,1.27,79.7],[2,1.26,82.93]],"batl":[[0,1.35,42.01],[1,1.58,650.58]],"ltp":1.37,"tv":226.47,"id":8979329}]}]}
{"op":"mcm","clk":"1009290776","pt":1580643284974,"mc":[{"id":"1.168224343","rc":[{"batb":[[0,3.75,13.06],[1,1.01,15.52],[2,3.75,0]],"batl":[[0,6,106.18],[1,6,0]],"ltp":3.35,"tv":34.94,"id":2397396},{"batb":[[0,1.26,82.93],[1,1.01,15.51],[2,1.26,0]],"batl":[[0,1.58,650.58],[1,1.58,0]],"ltp":1.37,"tv":226.47,"id":8979329}]}]}
{"op":"mcm","clk":"1009291840","pt":1580643293367,"mc":[{"id":"1.168224343","rc":[{"batb":[[0,4.1,21.09],[1,3.85,24.47],[2,1.01,15.52]],"ltp":3.35,"tv":34.94,"id":2397396},{"batb":[[1,1.25,87.42],[2,1.01,15.51]],"ltp":1.37,"tv":226.47,"id":8979329}]}]}
{"op":"mcm","clk":"1009291914","pt":1580643293944,"mc":[{"id":"1.168224343","rc":[{"batb":[[1,3.95,13.44],[2,3.85,24.47]],"batl":[[0,4.5,11.76],[1,6,106.18]],"ltp":3.35,"tv":34.94,"id":2397396},{"batb":[[0,1.28,149.55],[1,1.26,82.93],[2,1.25,87.42]],"batl":[[0,1.34,42.01],[1,1.58,650.58]],"ltp":1.37,"tv":226.47,"id":8979329}]}]}
{"op":"mcm","clk":"1009292778","pt":1580643300283,"mc":[{"id":"1.168224343","rc":[{"batb":[[0,3.95,13.44],[1,3.85,24.47],[2,1.01,15.52]],"ltp":3.35,"tv":34.94,"id":2397396},{"batb":[[1,1.25,87.42],[2,1.01,15.51]],"ltp":1.37,"tv":226.47,"id":8979329}]}]}
{"op":"mcm","clk":"1009292888","pt":1580643300997,"mc":[{"id":"1.168224343","rc":[{"batb":[[0,3.85,24.47],[1,1.01,15.52],[2,1.01,0]],"batl":[[0,6,106.18],[1,6,0]],"ltp":3.35,"tv":34.94,"id":2397396},{"batb":[[0,1.25,87.42],[1,1.01,15.51],[2,1.01,0]],"batl":[[0,1.58,650.58],[1,1.58,0]],"ltp":1.37,"tv":226.47,"id":8979329}]}]}
{"op":"mcm","clk":"1009294150","pt":1580643309295,"mc":[{"id":"1.168224343","rc":[{"batb":[[0,4.2,19.51],[1,3.95,22.98],[2,3.85,24.47]],"ltp":3.35,"tv":34.94,"id":2397396},{"batb":[[1,1.24,91.51],[2,1.01,15.51]],"ltp":1.37,"tv":226.47,"id":8979329}]}]}
{"op":"mcm","clk":"1009294257","pt":1580643310001,"mc":[{"id":"1.168224343","rc":[{"batb":[[1,4,13.44],[2,3.95,22.98]],"batl":[[0,4.6,10.92],[1,6,106.18]],"ltp":3.35,"tv":34.94,"id":2397396},{"batb":[[0,1.28,149.55],[1,1.25,87.42],[2,1.24,91.51]],"batl":[[0,1.34,42.01],[1,1.58,650.58]],"ltp":1.37,"tv":226.47,"id":8979329}]}]}
{"op":"mcm","clk":"1009295421","pt":1580643318398,"mc":[{"id":"1.168224343","rc":[{"batb":[[0,4,13.44],[1,3.95,22.98],[2,1.01,15.52]],"ltp":3.35,"tv":34.94,"id":2397396},{"batb":[[1,1.24,91.51],[2,1.01,15.51]],"ltp":1.37,"tv":226.47,"id":8979329}]}]}
{"op":"mcm","clk":"1009295513","pt":1580643318980,"mc":[{"id":"1.168224343","rc":[{"batb":[[0,3.95,22.98],[1,1.01,15.52],[2,1.01,0]],"batl":[[0,6,106.18],[1,6,0]],"ltp":3.35,"tv":34.94,"id":2397396},{"batb":[[0,1.24,91.51],[1,1.01,15.51],[2,1.01,0]],"batl":[[0,1.58,650.58],[1,1.58,0]],"ltp":1.37,"tv":226.47,"id":8979329}]}]}
{"op":"mcm","clk":"1009297528","pt":1580643332334,"mc":[{"id":"1.168224343","rc":[{"batb":[[1,3.9,14.28],[2,3.75,13.3]],"batl":[[0,4.5,11.76],[1,6,106.18]],"ltp":3.35,"tv":34.94,"id":2397396},{"batb":[[0,1.29,144.51],[1,1.28,78.05],[2,1.27,82.54]],"batl":[[0,1.35,42.01],[1,1.58,650.58]],"ltp":1.37,"tv":226.47,"id":8979329}]}]}
{"op":"mcm","clk":"1009299111","pt":1580643343261,"mc":[{"id":"1.168224343","rc":[{"batb":[[0,3.75,13.3],[1,1.01,15.52],[2,3.75,0]],"batl":[[0,6,106.18],[1,6,0]],"ltp":3.35,"tv":34.94,"id":2397396},{"batb":[[0,1.27,82.54],[1,1.01,15.51],[2,1.27,0]],"batl":[[0,1.58,650.58],[1,1.58,0]],"ltp":1.37,"tv":226.47,"id":8979329}]}]}
{"op":"mcm","clk":"1009302228","pt":1580643362255,"mc":[{"id":"1.168224343","rc":[{"batb":[[0,4.1,21.24],[1,3.9,14.28],[2,3.85,24.39]],"batl":[[0,4.5,11.76],[1,6,106.18]],"ltp":3.35,"tv":34.94,"id":2397396},{"batb":[[0,1.28,149.55],[1,1.27,82.54],[2,1.25,86.63]],"batl":[[0,1.34,42.01],[1,1.58,650.58]],"ltp":1.37,"tv":226.47,"id":8979329}]}]}
{"op":"mcm","clk":"1009304347","pt":1580643376102,"mc":[{"id":"1.168224343","rc":[{"batb":[[0,3.9,14.28],[1,3.85,24.39],[2,1.01,15.52]],"ltp":3.35,"tv":34.94,"id":2397396},{"batb":[[1,1.25,86.63],[2,1.01,15.51]],"ltp":1.37,"tv":226.47,"id":8979329}]}]}
{"op":"mcm","clk":"1009304550","pt":1580643377320,"mc":[{"id":"1.168224343","rc":[{"batb":[[0,3.85,24.39],[1,1.01,15.52],[2,1.01,0]],"batl":[[0,6,106.18],[1,6,0]],"ltp":3.35,"tv":34.94,"id":2397396},{"batb":[[0,1.25,86.63],[1,1.01,15.51],[2,1.01,0]],"batl":[[0,1.58,650.58],[1,1.58,0]],"ltp":1.37,"tv":226.47,"id":8979329}]}]}
{"op":"mcm","clk":"1009305138","pt":1580643381286,"mc":[{"id":"1.168224343","rc":[{"batb":[[0,1.27,392.95],[1,1.26,399],[2,1.25,86.63]],"batl":[[0,1.3,164.44],[1,1.31,308.31],[2,1.58,650.58]],"ltp":1.37,"tv":226.47,"id":8979329}]}]}
{"op":"mcm","clk":"1009305236","pt":1580643381968,"mc":[{"id":"1.168224343","rc":[{"batb":[[0,4.2,19.75],[1,4,13.44],[2,3.75,13.06]],"batl":[[0,4.6,10.92],[1,6,106.18]],"ltp":3.35,"tv":34.94,"id":2397396},{"batb":[[0,1.28,149.55],[1,1.27,392.95],[2,1.26,399]],"batl":[[2,1.34,42.01]],"ltp":1.37,"tv":226.47,"id":8979329}]}]}
{"op":"mcm","clk":"1009310762","pt":1580643420051,"mc":[{"id":"1.168224343","rc":[{"batl":[[0,1.31,308.31],[1,1.34,42.01],[2,1.58,650.58]],"ltp":1.37,"tv":226.47,"id":8979329}]}]}
{"op":"mcm","clk":"1009311204","pt":1580643422957,"mc":[{"id":"1.168224343","rc":[{"batl":[[0,1.31,445.17],[1,1.32,291.33],[2,1.34,42.01]],"ltp":1.37,"tv":226.47,"id":8979329}]}]}
{"op":"mcm","clk":"1009317136","pt":1580643461884,"mc":[{"id":"1.168224343","rc":[{"batb":[[1,1.27,423.93]],"ltp":1.37,"tv":226.47,"id":8979329}]}]}
{"op":"mcm","clk":"1009323275","pt":1580643501863,"mc":[{"id":"1.168224343","rc":[{"batb":[[0,4,13.44],[1,3.75,13.06],[2,1.01,15.52]],"ltp":3.35,"tv":34.94,"id":2397396},{"batb":[[1,1.2,116.53],[2,1.01,15.51]],"batl":[[0,1.34,42.01],[1,1.58,650.58],[2,1.34,0]],"ltp":1.37,"tv":226.47,"id":8979329}]}]}
{"op":"mcm","clk":"1009323471","pt":1580643503156,"mc":[{"id":"1.168224343","rc":[{"batb":[[0,3.75,13.06],[1,1.01,15.52],[2,1.01,0]],"batl":[[0,6,106.18],[1,6,0]],"ltp":3.35,"tv":34.94,"id":2397396},{"batb":[[0,1.2,116.53],[1,1.01,15.51],[2,1.01,0]],"batl":[[0,1.58,650.58],[1,1.58,0]],"ltp":1.37,"tv":226.47,"id":8979329}]}]}
{"op":"mcm","clk":"1009323682","pt":1580643504584,"mc":[{"id":"1.168224343","rc":[{"batb":[[0,1.21,663.78],[1,1.2,505.1],[2,1.01,15.51]],"batl":[[0,1.36,376.38],[1,1.37,244.25],[2,1.58,650.58]],"ltp":1.37,"tv":226.47,"id":8979329}]}]}
{"op":"mcm","clk":"1009324289","pt":1580643508715,"mc":[{"id":"1.168224343","rc":[{"batl":[[0,1.58,650.58],[1,1.37,0],[2,1.58,0]],"ltp":1.37,"tv":226.47,"id":8979329}]}]}
{"op":"mcm","clk":"1009324838","pt":1580643512383,"mc":[{"id":"1.168224343","rc":[{"batb":[[0,5.1,12.67],[1,4.6,10.92],[2,4.3,18.49]],"batl":[[0,5.4,9.24]],"ltp":3.35,"tv":34.94,"id":2397396},{"batb":[[0,1.23,168.04],[1,1.21,663.78],[2,1.2,505.1]],"batl":[[0,1.24,225.18],[1,1.25,397.75],[2,1.28,42.01]],"ltp":1.37,"tv":226.47,"id":8979329}]}]}
{"op":"mcm","clk":"1009325043","pt":1580643513769,"mc":[{"id":"1.168224343","rc":[{"batl":[[1,7.8,87.91]],"ltp":3.35,"tv":34.94,"id":2397396}]}]}
{"op":"mcm","clk":"1009326502","pt":1580643524218,"mc":[{"id":"1.168224343","rc":[{"batb":[[0,4.6,10.92],[1,4.3,18.49],[2,1.01,15.52]],"ltp":3.35,"tv":34.94,"id":2397396},{"batb":[[1,1.14,171.53],[2,1.01,15.51]],"batl":[[0,1.28,42.01],[1,1.58,650.58],[2,1.28,0]],"ltp":1.37,"tv":226.47,"id":8979329}]}]}
{"op":"mcm","clk":"1009326649","pt":1580643525198,"mc":[{"id":"1.168224343","rc":[{"batb":[[0,4.3,18.49],[1,1.01,15.52],[2,1.01,0]],"batl":[[0,7.8,87.91],[1,7.8,0]],"ltp":3.35,"tv":34.94,"id":2397396},{"batb":[[0,1.14,171.53],[1,1.01,15.51],[2,1.01,0]],"batl":[[0,1.58,650.58],[1,1.58,0]],"ltp":1.37,"tv":226.47,"id":8979329}]}]}
{"op":"mcm","clk":"1009326869","pt":1580643526713,"mc":[{"id":"1.168224343","rc":[{"batb":[[0,1.16,243.86],[1,1.15,755.05],[2,1.14,171.53]],"batl":[[0,1.3,413.63],[1,1.31,303.34],[2,1.58,650.58]],"ltp":1.37,"tv":226.47,"id":8979329}]}]}
{"op":"mcm","clk":"1009327038","pt":1580643528000,"mc":[{"id":"1.168224343","rc":[{"batb":[[0,1.14,171.53],[1,1.01,15.51],[2,1.14,0]],"batl":[[0,1.58,650.58],[1,1.31,0],[2,1.58,0]],"ltp":1.37,"tv":226.47,"id":8979329}]}]}
{"op":"mcm","clk":"1009327336","pt":1580643530303,"mc":[{"id":"1.168224343","rc":[{"batb":[[0,1.2,575.84],[1,1.19,486.09],[2,1.14,171.53]],"batl":[[0,1.23,373.02],[1,1.24,413.58],[2,1.58,650.58]],"ltp":1.37,"tv":226.47,"id":8979329}]}]}
{"op":"mcm","clk":"1009327805","pt":1580643533808,"mc":[{"id":"1.168224343","rc":[{"batb":[[0,1.14,171.53],[1,1.01,15.51],[2,1.14,0]],"batl":[[0,1.58,650.58],[1,1.24,0],[2,1.58,0]],"ltp":1.37,"tv":226.47,"id":8979329}]}]}
{"op":"mcm","clk":"1009328278","pt":1580643536911,"mc":[{"id":"1.168224343","rc":[{"batb":[[0,1.16,243.86],[1,1.15,755.05],[2,1.14,171.53]],"ltp":1.37,"tv":226.47,"id":8979329}]}]}
{"op":"mcm","clk":"1009328716","pt":1580643540330,"mc":[{"id":"1.168224343","rc":[{"batb":[[0,6.6,14.08],[1,5.6,8.4],[2,5.4,11.02]],"batl":[[0,6.8,6.72]],"ltp":3.35,"tv":34.94,"id":2397396},{"batl":[[0,1.18,479.89],[1,1.19,539.09],[2,1.22,42.01]],"ltp":1.37,"tv":226.47,"id":8979329}]}]}
{"op":"mcm","clk":"1009329048","pt":1580643542215,"mc":[{"id":"1.168224343","rc":[{"batl":[[1,9.8,75.27]],"ltp":3.35,"tv":34.94,"id":2397396}]}]}
{"op":"mcm","clk":"1009329297","pt":1580643543713,"mc":[{"id":"1.168224343","rc":[{"trd":[[6.6,13.44]],"batb":[[0,6.6,7.36]],"ltp":6.6,"tv":48.38,"id":2397396},{"batb":[[0,1.17,168.04],[1,1.16,243.86],[2,1.15,755.05]],"ltp":1.37,"tv":226.47,"id":8979329}],"tv":274.85}]}
{"op":"mcm","clk":"1009330500","pt":1580643552324,"mc":[{"id":"1.168224343","rc":[{"batb":[[0,5.6,8.4],[1,5.4,11.02],[2,1.01,15.52]],"ltp":6.6,"tv":48.38,"id":2397396},{"batb":[[1,1.09,271.92],[2,1.01,15.51]],"batl":[[0,1.22,42.01],[1,1.49,761.67],[2,1.22,0]],"ltp":1.37,"tv":226.47,"id":8979329}]}]}
{"op":"mcm","clk":"1009330651","pt":1580643553238,"mc":[{"id":"1.168224343","rc":[{"batb":[[0,5.4,11.02],[1,1.01,15.52],[2,1.01,0]],"batl":[[0,9.8,75.27],[1,9.8,0]],"ltp":6.6,"tv":48.38,"id":2397396},{"batb":[[0,1.09,271.92],[1,1.01,15.51],[2,1.01,0]],"batl":[[0,1.49,761.67],[1,1.49,0]],"ltp":1.37,"tv":226.47,"id":8979329}]}]}
{"op":"mcm","clk":"1009330899","pt":1580643555323,"mc":[{"id":"1.168224343","rc":[{"batb":[[1,5.3,11.41],[2,1.01,15.52]],"ltp":6.6,"tv":48.38,"id":2397396}]}]}
{"op":"mcm","clk":"1009330928","pt":1580643555432,"mc":[{"id":"1.168224343","rc":[{"batb":[[0,5.3,11.41],[1,1.01,15.52],[2,1.01,0]],"ltp":6.6,"tv":48.38,"id":2397396},{"batb":[[0,1.09,265.71]],"ltp":1.37,"tv":226.47,"id":8979329}]}]}
{"op":"mcm","clk":"1009331138","pt":1580643557033,"mc":[{"id":"1.168224343","rc":[{"batb":[[0,1.15,225.7],[1,1.14,815.63],[2,1.09,265.71]],"batl":[[0,1.17,578.07],[1,1.18,502.64],[2,1.49,761.67]],"ltp":1.37,"tv":226.47,"id":8979329}]}]}
{"op":"mcm","clk":"1009331513","pt":1580643559912,"mc":[{"id":"1.168224343","rc":[{"batl":[[0,11.5,70.11]],"ltp":6.6,"tv":48.38,"id":2397396}]}]}
{"op":"mcm","clk":"1009331745","pt":1580643561841,"mc":[{"id":"1.168224343","rc":[{"batb":[[0,1.09,265.71],[1,1.01,15.51],[2,1.09,0]],"batl":[[0,1.49,761.67],[1,1.18,0],[2,1.49,0]],"ltp":1.37,"tv":226.47,"id":8979329}]}]}
{"op":"mcm","clk":"1009332155","pt":1580643564819,"mc":[{"id":"1.168224343","rc":[{"batb":[[0,1.11,308.3],[1,1.1,842.95],[2,1.09,265.71]],"batl":[[0,1.23,574.08],[1,1.24,408.2],[2,1.49,761.67]],"ltp":1.37,"tv":226.47,"id":8979329}]}]}
{"op":"mcm","clk":"1009332834","pt":1580643570360,"mc":[{"id":"1.168224343","rc":[{"batb":[[0,1.09,265.71],[1,1.01,15.51],[2,1.09,0]],"ltp":1.37,"tv":226.47,"id":8979329}]}]}
{"op":"mcm","clk":"1009333225","pt":1580643573264,"mc":[{"id":"1.168224343","rc":[{"batb":[[0,1.2,350.3],[1,1.19,578.36],[2,1.09,265.71]],"ltp":1.37,"tv":226.47,"id":8979329}]}]}
{"op":"mcm","clk":"1009333350","pt":1580643574249,"mc":[{"id":"1.168224343","rc":[{"batb":[[1,4.9,10.08],[2,4.4,17.86]],"batl":[[0,5.8,8.4]],"ltp":6.6,"tv":48.38,"id":2397396},{"batb":[[0,1.21,168.04],[1,1.2,350.3],[2,1.19,703.31]],"batl":[[2,1.26,42.01]],"ltp":1.37,"tv":226.47,"id":8979329}]}]}
{"op":"mcm","clk":"1009333645","pt":1580643576287,"mc":[{"id":"1.168224343","rc":[{"batl":[[1,8.6,81.89]],"ltp":6.6,"tv":48.38,"id":2397396}]}]}
{"op":"mcm","clk":"1009335548","pt":1580643590366,"mc":[{"id":"1.168224343","rc":[{"batb":[[0,4.9,10.08],[1,4.4,17.86],[2,1.01,15.52]],"ltp":6.6,"tv":48.38,"id":2397396},{"batb":[[1,1.11,207.48],[2,1.01,15.51]],"batl":[[0,1.26,42.01],[1,1.49,761.67],[2,1.26,0]],"ltp":1.37,"tv":226.47,"id":8979329}]}]}
{"op":"mcm","clk":"1009335715","pt":1580643591588,"mc":[{"id":"1.168224343","rc":[{"batb":[[0,4.4,17.86],[1,1.01,15.52],[2,1.01,0]],"batl":[[0,8.6,81.89],[1,8.6,0]],"ltp":6.6,"tv":48.38,"id":2397396},{"batb":[[0,1.11,207.48],[1,1.01,15.51],[2,1.01,0]],"batl":[[0,1.49,761.67],[1,1.49,0]],"ltp":1.37,"tv":226.47,"id":8979329}]}]}
{"op":"mcm","clk":"1009335919","pt":1580643592981,"mc":[{"id":"1.168224343","rc":[{"batb":[[0,1.13,656.12],[1,1.12,471.47],[2,1.11,207.48]],"batl":[[0,1.29,363.75],[1,1.3,316.64],[2,1.49,761.67]],"ltp":1.37,"tv":226.47,"id":8979329}]}]}
{"op":"mcm","clk":"1009336374","pt":1580643596294,"mc":[{"id":"1.168224343","rc":[{"batl":[[0,1.49,761.67],[1,1.3,0],[2,1.49,0]],"ltp":1.37,"tv":226.47,"id":8979329}]}]}
{"op":"mcm","clk":"1009336848","pt":1580643599298,"mc":[{"id":"1.168224343","rc":[{"batl":[[0,1.15,397.03],[1,1.16,659.52],[2,1.49,761.67]],"ltp":1.37,"tv":226.47,"id":8979329}]}]}
{"op":"mcm","clk":"1009336998","pt":1580643600168,"mc":[{"id":"1.168224343","rc":[{"batb":[[0,7.4,10.31],[1,6.4,7.56],[2,5.9,17.94]],"batl":[[0,7.8,5.88]],"ltp":6.6,"tv":48.38,"id":2397396}]}]}
{"op":"mcm","clk":"1009337435","pt":1580643603008,"mc":[{"id":"1.168224343","rc":[{"batl":[[1,12.5,65.97]],"ltp":6.6,"tv":48.38,"id":2397396},{"trd":[[1.15,193.24]],"batb":[[1,1.12,435.08]],"batl":[[0,1.15,300.41],[2,1.18,42.01]],"ltp":1.15,"tv":419.71,"id":8979329}],"tv":468.1}]}
{"op":"mcm","clk":"1009337909","pt":1580643606004,"mc":[{"id":"1.168224343","rc":[{"batb":[[0,1.13,692.18]],"batl":[[0,1.15,361.65]],"ltp":1.15,"tv":419.71,"id":8979329}]}]}
{"op":"mcm","clk":"1009338967","pt":1580643613211,"mc":[{"id":"1.168224343","rc":[{"batb":[[0,5.9,17.94],[1,1.01,15.52],[2,5.9,0]],"batl":[[0,12.5,65.97],[1,12.5,0]],"ltp":6.6,"tv":48.38,"id":2397396},{"batb":[[0,1.06,385.46],[1,1.01,15.51],[2,1.11,0]],"batl":[[0,1.49,761.67],[1,1.16,0],[2,1.18,0]],"ltp":1.15,"tv":419.71,"id":8979329}]}]}
{"op":"mcm","clk":"1009339641","pt":1580643617816,"mc":[{"id":"1.168224343","rc":[{"batb":[[0,1.12,693.77],[1,1.11,443.64],[2,1.06,385.46]],"batl":[[0,1.14,486.35],[1,1.15,621.75]],"ltp":1.15,"tv":419.71,"id":8979329}]}]}
{"op":"mcm","clk":"1009339979","pt":1580643620121,"mc":[{"id":"1.168224343","rc":[{"batl":[[2,1.43,872.38]],"ltp":1.15,"tv":419.71,"id":8979329}]}]}
{"op":"mcm","clk":"1009340274","pt":1580643622217,"mc":[{"id":"1.168224343","rc":[{"batb":[[0,1.06,385.46],[1,1.01,15.51],[2,1.06,0]],"batl":[[0,1.43,872.38],[1,1.15,0],[2,1.43,0]],"ltp":1.15,"tv":419.71,"id":8979329}]}]}
{"op":"mcm","clk":"1009340669","pt":1580643625320,"mc":[{"id":"1.168224343","rc":[{"batb":[[0,1.08,954.51],[1,1.07,222.98],[2,1.06,385.46]],"batl":[[0,1.2,473.69],[1,1.21,479.82],[2,1.43,872.38]],"ltp":1.15,"tv":419.71,"id":8979329}]}]}
{"op":"mcm","clk":"1009341591","pt":1580643632005,"mc":[{"id":"1.168224343","rc":[{"batb":[[0,1.06,385.46],[1,1.01,15.51],[2,1.06,0]],"ltp":1.15,"tv":419.71,"id":8979329}]}]}
{"op":"mcm","clk":"1009342040","pt":1580643635127,"mc":[{"id":"1.168224343","rc":[{"batb":[[0,1.17,747.45],[1,1.16,340.46],[2,1.06,385.46]],"ltp":1.15,"tv":419.71,"id":8979329}]}]}
{"op":"mcm","clk":"1009342196","pt":1580643636234,"mc":[{"id":"1.168224343","rc":[{"batb":[[1,4.4,17.7],[2,1.01,15.52]],"batl":[[0,6.4,7.56]],"ltp":6.6,"tv":48.38,"id":2397396},{"batb":[[0,1.18,168.04],[1,1.17,747.45],[2,1.16,487.99]],"batl":[[2,1.23,42.01]],"ltp":1.15,"tv":419.71,"id":8979329}]}]}
{"op":"mcm","clk":"1009342451","pt":1580643637810,"mc":[{"id":"1.168224343","rc":[{"batl":[[1,9.8,75.27]],"ltp":6.6,"tv":48.38,"id":2397396}]}]}
{"op":"mcm","clk":"1009342677","pt":1580643639314,"mc":[{"id":"1.168224343","rc":[{"batb":[[1,1.17,712.47]],"ltp":1.15,"tv":419.71,"id":8979329}]}]}
{"op":"mcm","clk":"1009343128","pt":1580643642039,"mc":[{"id":"1.168224343","rc":[{"batb":[[2,1.16,523.27]],"batl":[[0,1.2,507.92]],"ltp":1.15,"tv":419.71,"id":8979329}]}]}
{"op":"mcm","clk":"1009344890","pt":1580643654354,"mc":[{"id":"1.168224343","rc":[{"batb":[[1,1.16,147.53],[2,1.06,364.22]],"batl":[[0,1.23,42.01],[1,1.43,872.38],[2,1.23,0]],"ltp":1.15,"tv":419.71,"id":8979329}]}]}
{"op":"mcm","clk":"1009345022","pt":1580643655269,"mc":[{"id":"1.168224343","rc":[{"batb":[[0,4.4,17.7],[1,1.01,15.52],[2,1.01,0]],"batl":[[0,9.8,75.27],[1,9.8,0]],"ltp":6.6,"tv":48.38,"id":2397396},{"batb":[[0,1.06,364.22],[1,1.01,15.51],[2,1.06,0]],"batl":[[0,1.43,872.38],[1,1.43,0]],"ltp":1.15,"tv":419.71,"id":8979329}]}]}
{"op":"mcm","clk":"1009345258","pt":1580643656864,"mc":[{"id":"1.168224343","rc":[{"batb":[[0,1.08,1175.42],[1,1.06,364.22],[2,1.01,15.51]],"batl":[[0,1.29,436.07],[1,1.3,315.48]],"ltp":1.15,"tv":419.71,"id":8979329}]}]}
{"op":"mcm","clk":"1009345366","pt":1580643657566,"mc":[{"id":"1.168224343","rc":[{"batb":[[0,1.06,364.22],[1,1.01,15.51],[2,1.01,0]],"ltp":1.15,"tv":419.71,"id":8979329}]}]}
{"op":"mcm","clk":"1009345908","pt":1580643661091,"mc":[{"id":"1.168224343","rc":[{"batb":[[0,1.15,846.07],[1,1.14,260.06],[2,1.06,364.22]],"batl":[[0,1.18,615.03],[1,1.19,456.91]],"ltp":1.15,"tv":419.71,"id":8979329}]}]}
{"op":"mcm","clk":"1009346178","pt":1580643662850,"mc":[{"id":"1.168224343","rc":[{"batb":[[0,1.06,364.22],[1,1.01,15.51],[2,1.06,0]],"ltp":1.15,"tv":419.71,"id":8979329}]}]}
{"op":"mcm","clk":"1009346604","pt":1580643665689,"mc":[{"id":"1.168224343","rc":[{"batb":[[0,1.08,1175.42],[1,1.06,364.22],[2,1.01,15.51]],"batl":[[0,1.29,436.07],[1,1.3,315.48]],"ltp":1.15,"tv":419.71,"id":8979329}]}]}
{"op":"mcm","clk":"1009348674","pt":1580643679221,"mc":[{"id":"1.168224343","rc":[{"batb":[[0,1.06,364.22],[1,1.01,15.51],[2,1.01,0]],"ltp":1.15,"tv":419.71,"id":8979329}]}]}
{"op":"mcm","clk":"1009349146","pt":1580643682224,"mc":[{"id":"1.168224343","rc":[{"batb":[[0,1.25,554.29],[1,1.24,443.18],[2,1.06,364.22]],"ltp":1.15,"tv":419.71,"id":8979329}]}]}
{"op":"mcm","clk":"1009349348","pt":1580643683202,"mc":[{"id":"1.168224343","rc":[{"batb":[[1,3.75,13.22],[2,1.01,15.52]],"ltp":6.6,"tv":48.38,"id":2397396},{"batb":[[1,1.24,536.5],[2,1.16,150.83]],"ltp":1.15,"tv":419.71,"id":8979329}]}]}
{"op":"mcm","clk":"1009349558","pt":1580643684309,"mc":[{"id":"1.168224343","rc":[{"batb":[[1,4.2,12.6],[2,3.75,13.22]],"batl":[[0,4.9,10.08],[1,6.6,98.95]],"ltp":6.6,"tv":48.38,"id":2397396},{"batb":[[0,1.25,722.33]],"batl":[[2,1.62,614.4]],"ltp":1.15,"tv":419.71,"id":8979329}]}]}
{"op":"mcm","clk":"1009352743","pt":1580643705839,"mc":[{"id":"1.168224343","rc":[{"batb":[[0,4.2,12.6],[1,3.75,13.22],[2,1.01,15.52]],"ltp":6.6,"tv":48.38,"id":2397396},{"batb":[[0,1.25,168.04],[1,1.16,150.83],[2,1.01,15.51]],"batl":[[0,1.62,614.4],[1,1.3,0],[2,1.62,0]],"ltp":1.15,"tv":419.71,"id":8979329}]}]}
{"op":"mcm","clk":"1009352974","pt":1580643707243,"mc":[{"id":"1.168224343","rc":[{"batb":[[0,3.75,13.22],[1,1.01,15.52],[2,1.01,0]],"batl":[[0,6.6,98.95],[1,6.6,0]],"ltp":6.6,"tv":48.38,"id":2397396},{"batb":[[0,1.16,150.83],[1,1.01,15.51],[2,1.01,0]],"ltp":1.15,"tv":419.71,"id":8979329}]}]}
{"op":"mcm","clk":"1009353289","pt":1580643709164,"mc":[{"id":"1.168224343","rc":[{"batb":[[0,1.17,620.3],[1,1.16,619.54],[2,1.01,15.51]],"batl":[[0,1.36,187.25],[1,1.37,246.77],[2,1.62,614.4]],"ltp":1.15,"tv":419.71,"id":8979329}]}]}
{"op":"mcm","clk":"1009353826","pt":1580643712666,"mc":[{"id":"1.168224343","rc":[{"batb":[[0,1.16,150.83],[1,1.01,15.51],[2,1.01,0]],"ltp":1.15,"tv":419.71,"id":8979329}]}]}
{"op":"mcm","clk":"1009354440","pt":1580643716358,"mc":[{"id":"1.168224343","rc":[{"batb":[[1,3.35,17.31],[2,1.01,15.52]],"batl":[[0,4.2,12.6]],"ltp":6.6,"tv":48.38,"id":2397396},{"batb":[[0,1.33,160.71],[1,1.32,304.37],[2,1.31,205.22]],"ltp":1.15,"tv":419.71,"id":8979329}]}]}
{"op":"mcm","clk":"1009354814","pt":1580643718374,"mc":[{"id":"1.168224343","rc":[{"batl":[[1,5.5,115.06]],"ltp":6.6,"tv":48.38,"id":2397396}]}]}
{"op":"mcm","clk":"1009357050","pt":1580643731374,"mc":[{"id":"1.168224343","rc":[{"batb":[[0,1.31,205.22],[1,1.24,94.89],[2,1.01,15.51]],"batl":[[0,1.62,614.4],[1,1.37,0],[2,1.62,0]],"ltp":1.15,"tv":419.71,"id":8979329}]}]}
{"op":"mcm","clk":"1009357105","pt":1580643731757,"mc":[{"id":"1.168224343","rc":[{"batb":[[0,3.35,17.31],[1,1.01,15.52],[2,1.01,0]],"ltp":6.6,"tv":48.38,"id":2397396},{"batb":[[0,1.31,135.27]],"ltp":1.15,"tv":419.71,"id":8979329}]}]}
{"op":"mcm","clk":"1009357325","pt":1580643733369,"mc":[{"id":"1.168224343","rc":[{"batl":[[0,5.5,115.06],[1,5.5,0]],"ltp":6.6,"tv":48.38,"id":2397396},{"batb":[[0,1.24,94.89],[1,1.01,15.51],[2,1.01,0]],"ltp":1.15,"tv":419.71,"id":8979329}]}]}
{"op":"mcm","clk":"1009357441","pt":1580643734274,"mc":[{"id":"1.168224343","rc":[{"batb":[[0,1.25,439.43],[1,1.24,535.72],[2,1.01,15.51]],"batl":[[0,1.43,287.74],[1,1.44,197.12],[2,1.62,614.4]],"ltp":1.15,"tv":419.71,"id":8979329}]}]}
{"op":"mcm","clk":"1009357786","pt":1580643737183,"mc":[{"id":"1.168224343","rc":[{"batb":[[0,1.24,94.89],[1,1.01,15.51],[2,1.01,0]],"ltp":1.15,"tv":419.71,"id":8979329}]}]}
{"op":"mcm","clk":"1009358184","pt":1580643740293,"mc":[{"id":"1.168224343","rc":[{"batl":[[0,3.7,15.12]],"ltp":6.6,"tv":48.38,"id":2397396},{"batb":[[0,1.38,381.46],[1,1.37,369.26],[2,1.24,94.89]],"ltp":1.15,"tv":419.71,"id":8979329}]}]}
{"op":"mcm","clk":"1009358240","pt":1580643740787,"mc":[{"id":"1.168224343","rc":[{"batb":[[1,2.86,10.39],[2,1.01,15.52]],"ltp":6.6,"tv":48.38,"id":2397396},{"batb":[[1,1.37,426.69],[2,1.33,65.54]],"ltp":1.15,"tv":419.71,"id":8979329}]}]}
{"op":"mcm","clk":"1009358576","pt":1580643743259,"mc":[{"id":"1.168224343","rc":[{"batl":[[1,4.9,126.27]],"ltp":6.6,"tv":48.38,"id":2397396}]}]}
{"op":"mcm","clk":"1009360995","pt":1580643758599,"mc":[{"id":"1.168224343","rc":[{"batb":[[0,1.38,344.13]],"ltp":1.15,"tv":419.71,"id":8979329}]}]}
{"op":"mcm","clk":"1009361529","pt":1580643762112,"mc":[{"id":"1.168224343","rc":[{"batl":[[0,1.43,323.68]],"ltp":1.15,"tv":419.71,"id":8979329}]}]}
{"op":"mcm","clk":"1009363670","pt":1580643777189,"mc":[{"id":"1.168224343","rc":[{"batb":[[0,1.37,170.86],[1,1.33,65.54],[2,1.01,15.51]],"batl":[[0,1.62,614.4],[1,1.44,0],[2,1.62,0]],"ltp":1.15,"tv":419.71,"id":8979329}]}]}
{"op":"mcm","clk":"1009364064","pt":1580643780135,"mc":[{"id":"1.168224343","rc":[{"batb":[[1,1.34,301.06],[2,1.33,360.61]],"batl":[[0,1.53,138.04],[1,1.54,152.38],[2,1.62,614.4]],"ltp":1.15,"tv":419.71,"id":8979329}]}]}
{"op":"mcm","clk":"1009365976","pt":1580643793664,"mc":[{"id":"1.168224343","rc":[{"batb":[[0,2.86,10.39],[1,1.01,15.52],[2,1.01,0]],"ltp":6.6,"tv":48.38,"id":2397396},{"batb":[[0,1.37,113.43]],"ltp":1.15,"tv":419.71,"id":8979329}]}]}
{"op":"mcm","clk":"1009366341","pt":1580643796350,"mc":[{"id":"1.168224343","rc":[{"batl":[[0,4.9,126.27],[1,4.9,0]],"ltp":6.6,"tv":48.38,"id":2397396},{"batb":[[0,1.34,301.06],[1,1.33,360.61],[2,1.01,15.51]],"ltp":1.15,"tv":419.71,"id":8979329}]}]}
{"op":"mcm","clk":"1009366493","pt":1580643797250,"mc":[{"id":"1.168224343","rc":[{"batl":[[0,1.62,614.4],[1,1.54,0],[2,1.62,0]],"ltp":1.15,"tv":419.71,"id":8979329}]}]}
{"op":"mcm","clk":"1009366963","pt":1580643800340,"mc":[{"id":"1.168224343","rc":[{"batl":[[0,1.38,271.95],[1,1.39,230.1],[2,1.62,614.4]],"ltp":1.15,"tv":419.71,"id":8979329}]}]}
{"op":"mcm","clk":"1009367042","pt":1580643800858,"mc":[{"id":"1.168224343","rc":[{"batb":[[0,3.6,14.48],[1,3.15,20.22],[2,1.01,15.52]],"ltp":6.6,"tv":48.38,"id":2397396},{"batb":[[2,1.3,72.23]],"ltp":1.15,"tv":419.71,"id":8979329}]}]}
{"op":"mcm","clk":"1009367275","pt":1580643802353,"mc":[{"id":"1.168224343","rc":[{"batl":[[0,4,13.44],[1,4.9,126.27]],"ltp":6.6,"tv":48.38,"id":2397396},{"batb":[[1,1.33,487.48]],"ltp":1.15,"tv":419.71,"id":8979329}]}]}
{"op":"mcm","clk":"1009368225","pt":1580643809123,"mc":[{"id":"1.168224343","rc":[{"batb":[[0,3.15,20.22],[1,1.01,15.52],[2,1.01,0]],"ltp":6.6,"tv":48.38,"id":2397396},{"batb":[[0,1.33,126.87],[1,1.3,72.23],[2,1.01,15.51]],"batl":[[0,1.62,614.4],[1,1.39,0],[2,1.62,0]],"ltp":1.15,"tv":419.71,"id":8979329}]}]}
{"op":"mcm","clk":"1009368404","pt":1580643810292,"mc":[{"id":"1.168224343","rc":[{"batl":[[0,4.9,126.27],[1,4.9,0]],"ltp":6.6,"tv":48.38,"id":2397396},{"batb":[[0,1.3,72.23],[1,1.01,15.51],[2,1.01,0]],"ltp":1.15,"tv":419.71,"id":8979329}]}]}
{"op":"mcm","clk":"1009368906","pt":1580643814102,"mc":[{"id":"1.168224343","rc":[{"batb":[[0,1.35,345.72],[1,1.34,285.33],[2,1.3,72.23]],"batl":[[0,1.39,169.27],[1,1.4,224.12],[2,1.62,614.4]],"ltp":1.15,"tv":419.71,"id":8979329}]}]}
{"op":"mcm","clk":"1009369211","pt":1580643816253,"mc":[{"id":"1.168224343","rc":[{"batb":[[0,1.3,72.23],[1,1.01,15.51],[2,1.3,0]],"batl":[[0,1.62,614.4],[1,1.4,0],[2,1.62,0]],"ltp":1.15,"tv":419.71,"id":8979329}]}]}
{"op":"mcm","clk":"1009369658","pt":1580643819124,"mc":[{"id":"1.168224343","rc":[{"batb":[[0,1.31,310.97],[1,1.3,405.01],[2,1.01,15.51]],"batl":[[0,1.45,185.93],[1,1.46,187.75],[2,1.62,614.4]],"ltp":1.15,"tv":419.71,"id":8979329}]}]}
{"op":"mcm","clk":"1009370099","pt":1580643822264,"mc":[{"id":"1.168224343","rc":[{"batl":[[0,1.62,614.4],[1,1.46,0],[2,1.62,0]],"ltp":1.15,"tv":419.71,"id":8979329}]}]}
{"op":"mcm","clk":"1009370526","pt":1580643825308,"mc":[{"id":"1.168224343","rc":[{"batl":[[0,1.35,368.12],[1,1.36,253.2],[2,1.62,614.4]],"ltp":1.15,"tv":419.71,"id":8979329}]}]}
{"op":"mcm","clk":"1009370681","pt":1580643826322,"mc":[{"id":"1.168224343","rc":[{"batb":[[0,3.8,25.65],[1,3.65,15.12],[2,3.45,15.97]],"batl":[[0,4.2,12.6]],"ltp":6.6,"tv":48.38,"id":2397396},{"batb":[[0,1.31,446.24],[2,1.28,78.45]],"ltp":1.15,"tv":419.71,"id":8979329}]}]}
{"op":"mcm","clk":"1009370836","pt":1580643827438,"mc":[{"id":"1.168224343","rc":[{"batl":[[1,5.5,115.06]],"ltp":6.6,"tv":48.38,"id":2397396}]}]}
{"op":"mcm","clk":"1009372433","pt":1580643838403,"mc":[{"id":"1.168224343","rc":[{"batb":[[0,3.65,15.12],[1,3.45,15.97],[2,1.01,15.52]],"ltp":6.6,"tv":48.38,"id":2397396},{"batb":[[0,1.31,135.27],[1,1.28,78.45],[2,1.01,15.51]],"batl":[[0,1.62,614.4],[1,1.36,0],[2,1.62,0]],"ltp":1.15,"tv":419.71,"id":8979329}]}]}
{"op":"mcm","clk":"1009372642","pt":1580643839658,"mc":[{"id":"1.168224343","rc":[{"batb":[[0,3.45,15.97],[1,1.01,15.52],[2,1.01,0]],"batl":[[0,5.5,115.06],[1,5.5,0]],"ltp":6.6,"tv":48.38,"id":2397396},{"batb":[[0,1.28,78.45],[1,1.01,15.51],[2,1.01,0]],"ltp":1.15,"tv":419.71,"id":8979329}]}]}
{"op":"mcm","clk":"1009373382","pt":1580643844016,"mc":[{"id":"1.168224343","rc":[{"batb":[[0,1.32,230.98],[1,1.31,318.41],[2,1.28,78.45]],"batl":[[0,1.35,149.7],[1,1.36,256.41],[2,1.62,614.4]],"ltp":1.15,"tv":419.71,"id":8979329}]}]}
{"op":"mcm","clk":"1009373604","pt":1580643845405,"mc":[{"id":"1.168224343","rc":[{"batb":[[0,1.28,78.45],[1,1.01,15.51],[2,1.28,0]],"batl":[[0,1.62,614.4],[1,1.36,0],[2,1.62,0]],"ltp":1.15,"tv":419.71,"id":8979329}]}]}
{"op":"mcm","clk":"1009374004","pt":1580643848202,"mc":[{"id":"1.168224343","rc":[{"batb":[[0,1.29,395.62],[1,1.28,442.41],[2,1.01,15.51]],"batl":[[0,1.39,245.76],[1,1.4,223.67],[2,1.62,614.4]],"ltp":1.15,"tv":419.71,"id":8979329}]}]}
{"op":"mcm","clk":"1009374711","pt":1580643852799,"mc":[{"id":"1.168224343","rc":[{"batl":[[0,1.62,614.4],[1,1.4,0],[2,1.62,0]],"ltp":1.15,"tv":419.71,"id":8979329}]}]}
{"op":"mcm","clk":"1009375286","pt":1580643856312,"mc":[{"id":"1.168224343","rc":[{"batb":[[0,3.8,14.28],[1,3.7,13.69],[2,3.45,15.97]],"batl":[[0,4.4,11.76],[1,5.5,115.06]],"ltp":6.6,"tv":48.38,"id":2397396},{"batb":[[0,1.29,540.13],[2,1.27,81.2]],"batl":[[0,1.33,373.23],[1,1.34,271.65],[2,1.36,42.01]],"ltp":1.15,"tv":419.71,"id":8979329}]}]}
{"op":"mcm","clk":"1009375308","pt":1580643856418,"mc":[{"id":"1.168224343","rc":[{"batb":[[2,1.01,15.52]],"ltp":6.6,"tv":48.38,"id":2397396}]}]}
{"op":"mcm","clk":"1009377130","pt":1580643869349,"mc":[{"id":"1.168224343","rc":[{"batb":[[0,3.7,13.69],[1,1.01,15.52],[2,1.01,0]],"batl":[[0,5.5,115.06],[1,5.5,0]],"ltp":6.6,"tv":48.38,"id":2397396},{"batb":[[0,1.28,363.96],[1,1.27,81.2],[2,1.01,15.51]],"batl":[[0,1.62,614.4],[1,1.34,0],[2,1.36,0]],"ltp":1.15,"tv":419.71,"id":8979329}]}]}
{"op":"mcm","clk":"1009377490","pt":1580643871853,"mc":[{"id":"1.168224343","rc":[{"batb":[[0,1.28,437.52],[1,1.27,463.57]],"ltp":1.15,"tv":419.71,"id":8979329}]}]}
{"op":"mcm","clk":"1009377989","pt":1580643875331,"mc":[{"id":"1.168224343","rc":[{"batl":[[0,1.32,383.15],[1,1.33,281.61],[2,1.62,614.4]],"ltp":1.15,"tv":419.71,"id":8979329}]}]}
{"op":"mcm","clk":"1009378135","pt":1580643876335,"mc":[{"id":"1.168224343","rc":[{"batb":[[0,4,21.72],[1,3.9,14.28],[2,3.65,14.01]],"batl":[[0,4.5,11.76],[1,5.5,115.06]],"ltp":6.6,"tv":48.38,"id":2397396},{"batb":[[0,1.28,587.07],[2,1.21,111.65]],"ltp":1.15,"tv":419.71,"id":8979329}]}]}
{"op":"mcm","clk":"1009381470","pt":1580643898190,"mc":[{"id":"1.168224343","rc":[{"batb":[[0,3.9,14.28],[1,3.65,14.01],[2,1.01,15.52]],"ltp":6.6,"tv":48.38,"id":2397396},{"batb":[[0,1.28,149.55],[1,1.21,111.65],[2,1.01,15.51]],"batl":[[0,1.62,614.4],[1,1.33,0],[2,1.62,0]],"ltp":1.15,"tv":419.71,"id":8979329}]}]}
{"op":"mcm","clk":"1009381668","pt":1580643899367,"mc":[{"id":"1.168224343","rc":[{"batb":[[0,3.65,14.01],[1,1.01,15.52],[2,1.01,0]],"batl":[[0,5.5,115.06],[1,5.5,0]],"ltp":6.6,"tv":48.38,"id":2397396},{"batb":[[0,1.21,111.65],[1,1.01,15.51],[2,1.01,0]],"ltp":1.15,"tv":419.71,"id":8979329}]}]}
{"op":"mcm","clk":"1009382518","pt":1580643904381,"mc":[{"id":"1.168224343","rc":[{"batb":[[0,1.27,332.94],[1,1.26,397.23],[2,1.21,111.65]],"batl":[[0,1.3,220.01],[1,1.31,306.97],[2,1.62,614.4]],"ltp":1.15,"tv":419.71,"id":8979329}]}]}
{"op":"mcm","clk":"1009383000","pt":1580643907488,"mc":[{"id":"1.168224343","rc":[{"batl":[[0,6.6,98.95]],"ltp":6.6,"tv":48.38,"id":2397396}]}]}
{"op":"mcm","clk":"1009383234","pt":1580643908880,"mc":[{"id":"1.168224343","rc":[{"batb":[[0,1.21,111.65],[1,1.01,15.51],[2,1.21,0]],"batl":[[0,1.62,614.4],[1,1.31,0],[2,1.62,0]],"ltp":1.15,"tv":419.71,"id":8979329}]}]}
{"op":"mcm","clk":"1009383726","pt":1580643911794,"mc":[{"id":"1.168224343","rc":[{"batb":[[0,1.22,396.5],[1,1.21,627.25],[2,1.01,15.51]],"batl":[[0,1.37,216.96],[1,1.38,238.27],[2,1.62,614.4]],"ltp":1.15,"tv":419.71,"id":8979329}]}]}
{"op":"mcm","clk":"1009384140","pt":1580643914263,"mc":[{"id":"1.168224343","rc":[{"batl":[[0,1.62,614.4],[1,1.38,0],[2,1.62,0]],"ltp":1.15,"tv":419.71,"id":8979329}]}]}
{"op":"mcm","clk":"1009384642","pt":1580643917380,"mc":[{"id":"1.168224343","rc":[{"batb":[[0,4.9,13.53],[1,4.2,19.91],[2,1.01,15.52]],"ltp":6.6,"tv":48.38,"id":2397396},{"batb":[[2,1.14,171.68]],"batl":[[0,1.25,404.95],[1,1.26,375.58],[2,1.62,614.4]],"ltp":1.15,"tv":419.71,"id":8979329}]}]}
{"op":"mcm","clk":"1009384813","pt":1580643918399,"mc":[{"id":"1.168224343","rc":[{"batl":[[0,5.4,9.24]],"ltp":6.6,"tv":48.38,"id":2397396},{"batb":[[0,1.23,168.04],[1,1.22,396.5],[2,1.21,627.25]],"batl":[[2,1.28,42.01]],"ltp":1.15,"tv":419.71,"id":8979329}]}]}
{"op":"mcm","clk":"1009385068","pt":1580643919878,"mc":[{"id":"1.168224343","rc":[{"batl":[[1,7.8,87.91]],"ltp":6.6,"tv":48.38,"id":2397396}]}]}
{"op":"mcm","clk":"1009386696","pt":1580643930306,"mc":[{"id":"1.168224343","rc":[{"trd":[[1.23,0.03]],"batb":[[0,1.23,168.02],[1,1.21,111.65],[2,1.14,171.68]],"batl":[[0,1.28,42.01],[1,1.62,614.4],[2,1.28,0]],"ltp":1.23,"tv":419.74,"id":8979329}],"tv":468.13}]}
{"op":"mcm","clk":"1009386763","pt":1580643930716,"mc":[{"id":"1.168224343","rc":[{"batb":[[0,4.2,19.91],[1,1.01,15.52],[2,1.01,0]],"ltp":6.6,"tv":48.38,"id":2397396},{"batb":[[1,1.14,171.68],[2,1.01,15.51]],"ltp":1.23,"tv":419.74,"id":8979329}]}]}
{"op":"mcm","clk":"1009386858","pt":1580643931418,"mc":[{"id":"1.168224343","rc":[{"batl":[[0,7.8,87.91],[1,7.8,0]],"ltp":6.6,"tv":48.38,"id":2397396},{"batb":[[0,1.14,171.68],[1,1.01,15.51],[2,1.01,0]],"batl":[[0,1.62,614.4],[1,1.62,0]],"ltp":1.23,"tv":419.74,"id":8979329}]}]}
{"op":"mcm","clk":"1009387169","pt":1580643933307,"mc":[{"id":"1.168224343","rc":[{"batb":[[0,1.16,170.67],[1,1.15,752.06],[2,1.14,171.68]],"batl":[[0,1.31,389.03],[1,1.32,292.36],[2,1.62,614.4]],"ltp":1.23,"tv":419.74,"id":8979329}]}]}
{"op":"mcm","clk":"1009387324","pt":1580643934300,"mc":[{"id":"1.168224343","rc":[{"batb":[[0,1.25,26.52],[1,1.16,170.67],[2,1.15,752.06]],"batl":[[0,1.62,614.4],[1,1.32,0],[2,1.62,0]],"ltp":1.23,"tv":419.74,"id":8979329}]}]}
{"op":"mcm","clk":"1009387750","pt":1580643937010,"mc":[{"id":"1.168224343","rc":[{"trd":[[1.25,53.04]],"batb":[[0,1.16,170.67],[1,1.15,752.06],[2,1.14,171.68]],"batl":[[0,1.18,522.1],[1,1.19,519.39]],"ltp":1.25,"tv":472.79,"id":8979329}],"tv":521.17}]}
{"op":"mcm","clk":"1009387871","pt":1580643937811,"mc":[{"id":"1.168224343","rc":[{"batb":[[0,6.6,14.08],[1,5.4,11.17],[2,1.01,15.52]],"ltp":6.6,"tv":48.38,"id":2397396}]}]}
{"op":"mcm","clk":"1009388022","pt":1580643938718,"mc":[{"id":"1.168224343","rc":[{"batl":[[0,6.8,6.72]],"ltp":6.6,"tv":48.38,"id":2397396},{"batb":[[0,1.17,168.04],[1,1.16,170.67],[2,1.15,752.06]],"ltp":1.25,"tv":472.79,"id":8979329}]}]}
{"op":"mcm","clk":"1009388256","pt":1580643940210,"mc":[{"id":"1.168224343","rc":[{"batb":[[1,5.7,8.4],[2,5.4,11.17]],"batl":[[1,11.5,70.11]],"ltp":6.6,"tv":48.38,"id":2397396},{"batl":[[2,1.21,42.01]],"ltp":1.25,"tv":472.79,"id":8979329}]}]}
{"op":"mcm","clk":"1009390006","pt":1580643951324,"mc":[{"id":"1.168224343","rc":[{"batb":[[1,1.14,171.68],[2,1.08,298.91]],"batl":[[0,1.21,42.01],[1,1.47,803.22],[2,1.21,0]],"ltp":1.25,"tv":472.79,"id":8979329}]}]}
{"op":"mcm","clk":"1009390143","pt":1580643952247,"mc":[{"id":"1.168224343","rc":[{"batb":[[0,5.7,8.4],[1,5.4,11.17],[2,1.01,15.52]],"ltp":6.6,"tv":48.38,"id":2397396},{"batb":[[1,1.08,297.1],[2,1.01,15.51]],"ltp":1.25,"tv":472.79,"id":8979329}]}]}
{"op":"mcm","clk":"1009390475","pt":1580643954228,"mc":[{"id":"1.168224343","rc":[{"batb":[[0,5.4,11.17],[1,1.01,15.52],[2,1.01,0]],"batl":[[0,11.5,70.11],[1,11.5,0]],"ltp":6.6,"tv":48.38,"id":2397396},{"batb":[[0,1.1,800.04],[1,1.09,353.58],[2,1.08,297.1]],"batl":[[0,1.23,426.21],[1,1.24,412.22],[2,1.47,803.22]],"ltp":1.25,"tv":472.79,"id":8979329}]}]}
{"op":"mcm","clk":"1009390610","pt":1580643955057,"mc":[{"id":"1.168224343","rc":[{"batb":[[0,1.08,297.1],[1,1.01,15.51],[2,1.08,0]],"batl":[[0,1.47,803.22],[1,1.24,0],[2,1.47,0]],"ltp":1.25,"tv":472.79,"id":8979329}]}]}
{"op":"mcm","clk":"1009390968","pt":1580643957241,"mc":[{"id":"1.168224343","rc":[{"batb":[[0,1.14,882.55],[1,1.13,229.51],[2,1.08,297.1]],"batl":[[0,1.17,716.06],[1,1.18,362.43],[2,1.47,803.22]],"ltp":1.25,"tv":472.79,"id":8979329}]}]}
{"op":"mcm","clk":"1009391759","pt":1580643962351,"mc":[{"id":"1.168224343","rc":[{"batb":[[0,1.08,297.1],[1,1.01,15.51],[2,1.08,0]],"batl":[[0,1.47,803.22],[1,1.18,0],[2,1.47,0]],"ltp":1.25,"tv":472.79,"id":8979329}]}]}
{"op":"mcm","clk":"1009392280","pt":1580643965246,"mc":[{"id":"1.168224343","rc":[{"batb":[[0,1.1,800.04],[1,1.09,353.58],[2,1.08,297.1]],"batl":[[0,1.23,426.21],[1,1.24,412.22],[2,1.47,803.22]],"ltp":1.25,"tv":472.79,"id":8979329}]}]}
{"op":"mcm","clk":"1009395603","pt":1580643988589,"mc":[{"id":"1.168224343","rc":[{"batb":[[0,1.08,297.1],[1,1.01,15.51],[2,1.08,0]],"batl":[[0,1.47,803.22],[1,1.24,0],[2,1.47,0]],"ltp":1.25,"tv":472.79,"id":8979329}]}]}
{"op":"mcm","clk":"1009395791","pt":1580643989947,"mc":[{"id":"1.168224343","rc":[{"trd":[[5.4,0]],"batb":[[0,5.4,11.17]],"ltp":5.4,"tv":48.38,"id":2397396},{"trd":[[1.23,0.05]],"ltp":1.23,"tv":472.8,"id":8979329}],"tv":521.19}]}
{"op":"mcm","clk":"1009396097","pt":1580643992394,"mc":[{"id":"1.168224343","rc":[{"batb":[[0,9.6,14.63],[1,7.8,15.09],[2,5.4,11.17]],"batl":[[0,9.8,4.2]],"ltp":5.4,"tv":48.38,"id":2397396},{"batb":[[0,1.1,800.04],[1,1.09,353.58],[2,1.08,297.1]],"batl":[[0,1.12,721.14],[1,1.13,405.11],[2,1.15,42.01]],"ltp":1.23,"tv":472.8,"id":8979329}]}]}
{"op":"mcm","clk":"1009396156","pt":1580643992770,"mc":[{"id":"1.168224343","rc":[{"batb":[[2,1.01,15.52]],"ltp":5.4,"tv":48.38,"id":2397396}]}]}
{"op":"mcm","clk":"1009396617","pt":1580643995174,"mc":[{"id":"1.168224343","rc":[{"batl":[[1,17,57.33]],"ltp":5.4,"tv":48.38,"id":2397396}]}]}
{"op":"mcm","clk":"1009396730","pt":1580643995761,"mc":[{"id":"1.168224343","rc":[{"trd":[[9.6,8.4]],"batb":[[0,9.6,10.43]],"ltp":9.6,"tv":56.79,"id":2397396}],"tv":529.59}]}
{"op":"mcm","clk":"1009397235","pt":1580643999201,"mc":[{"id":"1.168224343","rc":[{"trd":[[9.6,16.81]],"batb":[[0,9.6,6.23]],"ltp":9.6,"tv":65.19,"id":2397396}],"tv":537.99}]}
{"op":"mcm","clk":"1009397893","pt":1580644003402,"mc":[{"id":"1.168224343","rc":[{"trd":[[9.6,25.21]],"batb":[[0,9.6,2.03]],"ltp":9.6,"tv":73.59,"id":2397396},{"batb":[[0,1.1,689.3]],"batl":[[1,1.13,296.82]],"ltp":1.23,"tv":472.8,"id":8979329}],"tv":546.4}]}
{"op":"mcm","clk":"1009398178","pt":1580644005380,"mc":[{"id":"1.168224343","rc":[{"batb":[[1,1.09,397.31]],"batl":[[0,1.12,763.75]],"ltp":1.23,"tv":472.8,"id":8979329}]}]}
{"op":"mcm","clk":"1009398307","pt":1580644006312,"mc":[{"id":"1.168224343","rc":[{"batb":[[1,1.09,465.34]],"batl":[[0,1.12,830.4]],"ltp":1.23,"tv":472.8,"id":8979329}]}]}
{"op":"mcm","clk":"1009399414","pt":1580644014200,"mc":[{"id":"1.168224343","rc":[{"batb":[[0,1.08,297.1],[1,1.04,495.07],[2,1.01,15.51]],"batl":[[0,1.15,42.01],[1,1.4,927.7],[2,1.15,0]],"ltp":1.23,"tv":472.8,"id":8979329}]}]}
{"op":"mcm","clk":"1009399464","pt":1580644014604,"mc":[{"id":"1.168224343","rc":[{"batb":[[0,7.8,15.09],[1,1.01,15.52],[2,1.01,0]],"ltp":9.6,"tv":73.59,"id":2397396},{"batb":[[0,1.04,495.07],[1,1.01,15.51],[2,1.01,0]],"ltp":1.23,"tv":472.8,"id":8979329}]}]}
{"op":"mcm","clk":"1009399573","pt":1580644015464,"mc":[{"id":"1.168224343","rc":[{"batb":[[0,7.8,9.21]],"batl":[[0,17,57.33],[1,17,0]],"ltp":9.6,"tv":73.59,"id":2397396},{"batl":[[0,1.4,927.7],[1,1.4,0]],"ltp":1.23,"tv":472.8,"id":8979329}]}]}
{"op":"mcm","clk":"1009399788","pt":1580644017042,"mc":[{"id":"1.168224343","rc":[{"batb":[[0,1.07,659.07],[1,1.06,528.53],[2,1.04,495.07]],"batl":[[0,1.15,797.99],[1,1.16,299.79],[2,1.4,927.7]],"ltp":1.23,"tv":472.8,"id":8979329}]}]}
{"op":"mcm","clk":"1009399876","pt":1580644017605,"mc":[{"id":"1.168224343","rc":[{"batb":[[0,7.6,9.91]],"ltp":9.6,"tv":73.59,"id":2397396},{"batb":[[2,1.05,472.96]],"ltp":1.23,"tv":472.8,"id":8979329}]}]}
{"op":"mcm","clk":"1009400818","pt":1580644024716,"mc":[{"id":"1.168224343","rc":[{"batl":[[0,1.4,927.7],[1,1.16,0],[2,1.4,0]],"ltp":1.23,"tv":472.8,"id":8979329}]}]}
{"op":"mcm","clk":"1009401314","pt":1580644028248,"mc":[{"id":"1.168224343","rc":[{"batl":[[0,1.08,363.62],[1,1.09,800.68],[2,1.4,927.7]],"ltp":1.23,"tv":472.8,"id":8979329}]}]}
{"op":"mcm","clk":"1009401398","pt":1580644028826,"mc":[{"id":"1.168224343","rc":[{"batb":[[0,13.5,6.61],[1,11,4.2],[2,9.6,14.32]],"ltp":9.6,"tv":73.59,"id":2397396},{"batl":[[2,1.1,42.01]],"ltp":1.23,"tv":472.8,"id":8979329}]}]}
{"op":"mcm","clk":"1009401815","pt":1580644031338,"mc":[{"id":"1.168224343","rc":[{"batl":[[0,30,47.16]],"ltp":9.6,"tv":73.59,"id":2397396}]}]}
{"op":"mcm","clk":"1009402928","pt":1580644038750,"mc":[{"id":"1.168224343","rc":[{"batb":[[2,1.05,470.36]],"ltp":1.23,"tv":472.8,"id":8979329}]}]}
{"op":"mcm","clk":"1009412588","pt":1580644112628,"mc":[{"id":"1.168224343","rc":[{"batb":[[0,11,4.2],[1,9.6,14.32],[2,1.01,15.52]],"ltp":9.6,"tv":73.59,"id":2397396},{"batb":[[0,1.04,588.15],[1,1.01,15.51],[2,1.05,0]],"batl":[[0,1.1,42.01],[1,1.4,927.7],[2,1.1,0]],"ltp":1.23,"tv":472.8,"id":8979329}]}]}
{"op":"mcm","clk":"1009412678","pt":1580644113623,"mc":[{"id":"1.168224343","rc":[{"batb":[[0,9.6,14.32],[1,1.01,15.52],[2,1.01,0]],"ltp":9.6,"tv":73.59,"id":2397396},{"batl":[[0,1.4,927.7],[1,1.4,0]],"ltp":1.23,"tv":472.8,"id":8979329}]}]}
{"op":"mcm","clk":"1009412874","pt":1580644115312,"mc":[{"id":"1.168224343","rc":[{"batb":[[0,1.05,1205.19],[1,1.04,588.15],[2,1.01,15.51]],"batl":[[0,1.12,919.89],[1,1.13,208.11],[2,1.4,927.7]],"ltp":1.23,"tv":472.8,"id":8979329}]}]}
{"op":"mcm","clk":"1009412963","pt":1580644116208,"mc":[{"id":"1.168224343","rc":[{"batl":[[0,1.4,927.7],[1,1.13,0],[2,1.4,0]],"ltp":1.23,"tv":472.8,"id":8979329}]}]}
{"op":"mcm","clk":"1009413289","pt":1580644119137,"mc":[{"id":"1.168224343","rc":[{"batl":[[0,1.07,1081.19]],"ltp":1.23,"tv":472.8,"id":8979329}]}]}
{"op":"mcm","clk":"1009413364","pt":1580644119922,"mc":[{"id":"1.168224343","rc":[{"batb":[[0,16,4.48],[1,12,8.97],[2,1.01,15.52]],"ltp":9.6,"tv":73.59,"id":2397396},{"batb":[[2,1.03,720.88]],"ltp":1.23,"tv":472.8,"id":8979329}]}]}
{"op":"mcm","clk":"1009413504","pt":1580644121334,"mc":[{"id":"1.168224343","rc":[{"batb":[[1,12.5,3.36],[2,12,8.97]],"ltp":9.6,"tv":73.59,"id":2397396}]}]}
{"op":"mcm","clk":"1009413596","pt":1580644122225,"mc":[{"id":"1.168224343","rc":[{"batl":[[0,42,43.68]],"ltp":9.6,"tv":73.59,"id":2397396},{"batl":[[1,1.34,1109.8]],"ltp":1.23,"tv":472.8,"id":8979329}]}]}
{"op":"mcm","clk":"1009414353","pt":1580644129011,"mc":[{"id":"1.168224343","rc":[{"batl":[[0,1.07,1121.69]],"ltp":1.23,"tv":472.8,"id":8979329}]}]}
{"op":"mcm","clk":"1009414537","pt":1580644130836,"mc":[{"id":"1.168224343","rc":[{"batb":[[0,12.5,3.36],[1,12,8.97],[2,1.01,15.52]],"ltp":9.6,"tv":73.59,"id":2397396},{"batb":[[0,1.05,330.22],[1,1.03,720.88],[2,1.01,15.51]],"batl":[[0,1.34,1109.8],[1,1.34,0]],"ltp":1.23,"tv":472.8,"id":8979329}]}]}
{"op":"mcm","clk":"1009414679","pt":1580644132252,"mc":[{"id":"1.168224343","rc":[{"batb":[[0,12,8.97],[1,1.01,15.52],[2,1.01,0]],"ltp":9.6,"tv":73.59,"id":2397396}]}]}
{"op":"mcm","clk":"1009414713","pt":1580644132557,"mc":[{"id":"1.168224343","rc":[{"batb":[[0,1.05,259.1]],"ltp":1.23,"tv":472.8,"id":8979329}]}]}
{"op":"mcm","clk":"1009415070","pt":1580644135355,"mc":[{"id":"1.168224343","rc":[{"batb":[[0,1.06,937.16],[1,1.05,259.1],[2,1.03,720.88]],"batl":[[0,1.07,370.09],[1,1.08,805.04],[2,1.34,1109.8]],"ltp":1.23,"tv":472.8,"id":8979329}]}]}
{"op":"mcm","clk":"1009415352","pt":1580644138034,"mc":[{"id":"1.168224343","rc":[{"batb":[[0,1.05,259.1],[1,1.03,720.88],[2,1.01,15.51]],"batl":[[0,1.34,1109.8],[1,1.08,0],[2,1.34,0]],"ltp":1.23,"tv":472.8,"id":8979329}]}]}
{"op":"mcm","clk":"1009415529","pt":1580644139441,"mc":[{"id":"1.168224343","rc":[{"batl":[[0,30,47.16]],"ltp":9.6,"tv":73.59,"id":2397396}]}]}
{"op":"mcm","clk":"1009415662","pt":1580644140561,"mc":[{"id":"1.168224343","rc":[{"batb":[[0,1.05,330.22],[1,1.04,883.38],[2,1.03,720.88]],"batl":[[0,1.09,508.64],[1,1.1,646.39],[2,1.34,1109.8]],"ltp":1.23,"tv":472.8,"id":8979329}]}]}
{"op":"mcm","clk":"1009416116","pt":1580644144561,"mc":[{"id":"1.168224343","rc":[{"batb":[[0,1.03,720.88],[1,1.01,15.51],[2,1.03,0]],"ltp":1.23,"tv":472.8,"id":8979329}]}]}
{"op":"mcm","clk":"1009416607","pt":1580644148324,"mc":[{"id":"1.168224343","rc":[{"batb":[[1,8.2,8.66],[2,1.01,15.52]],"ltp":9.6,"tv":73.59,"id":2397396},{"batb":[[0,1.08,297.01],[1,1.07,882.87],[2,1.06,395.22]],"ltp":1.23,"tv":472.8,"id":8979329}]}]}
{"op":"mcm","clk":"1009416675","pt":1580644148867,"mc":[{"id":"1.168224343","rc":[{"batb":[[1,10.5,4.2],[2,8.2,8.66]],"batl":[[0,13.5,3.36]],"ltp":9.6,"tv":73.59,"id":2397396},{"batb":[[0,1.08,465.05]],"batl":[[2,1.11,42.01]],"ltp":1.23,"tv":472.8,"id":8979329}]}]}
{"op":"mcm","clk":"1009417000","pt":1580644151574,"mc":[{"id":"1.168224343","rc":[{"batl":[[1,24,50.52]],"ltp":9.6,"tv":73.59,"id":2397396}]}]}
{"op":"mcm","clk":"1009418432","pt":1580644165394,"mc":[{"id":"1.168224343","rc":[{"batb":[[0,1.08,168.04],[1,1.06,395.22],[2,1.04,535.19]],"batl":[[0,1.11,42.01],[1,1.34,1109.8],[2,1.11,0]],"ltp":1.23,"tv":472.8,"id":8979329}]}]}
{"op":"mcm","clk":"1009418476","pt":1580644165760,"mc":[{"id":"1.168224343","rc":[{"batb":[[0,8.2,8.66],[1,1.01,15.52],[2,8.2,0]],"batl":[[0,24,50.52],[1,24,0]],"ltp":9.6,"tv":73.59,"id":2397396},{"batb":[[0,1.04,535.19],[1,1.01,15.51],[2,1.04,0]],"batl":[[0,1.34,1109.8],[1,1.34,0]],"ltp":1.23,"tv":472.8,"id":8979329}]}]}
{"op":"mcm","clk":"1009418773","pt":1580644168276,"mc":[{"id":"1.168224343","rc":[{"batb":[[0,1.06,791.02],[1,1.05,406.63],[2,1.04,535.19]],"batl":[[0,1.14,706.96],[1,1.15,399.57],[2,1.34,1109.8]],"ltp":1.23,"tv":472.8,"id":8979329}]}]}
{"op":"mcm","clk":"1009418811","pt":1580644168788,"mc":[{"id":"1.168224343","rc":[{"batb":[[0,1.04,535.19],[1,1.01,15.51],[2,1.04,0]],"batl":[[0,1.34,1109.8],[1,1.15,0],[2,1.34,0]],"ltp":1.23,"tv":472.8,"id":8979329}]}]}
{"op":"mcm","clk":"1009418943","pt":1580644170094,"mc":[{"id":"1.168224343","rc":[{"batb":[[0,1.08,1171.72],[1,1.04,535.19],[2,1.01,15.51]],"batl":[[0,1.1,604.68],[1,1.11,540.81],[2,1.34,1109.8]],"ltp":1.23,"tv":472.8,"id":8979329}]}]}
{"op":"mcm","clk":"1009419301","pt":1580644173103,"mc":[{"id":"1.168224343","rc":[{"batl":[[0,21,53.48]],"ltp":9.6,"tv":73.59,"id":2397396},{"batb":[[0,1.04,535.19],[1,1.01,15.51],[2,1.01,0]],"batl":[[0,1.34,1109.8],[1,1.11,0],[2,1.34,0]],"ltp":1.23,"tv":472.8,"id":8979329}]}]}
{"op":"mcm","clk":"1009419580","pt":1580644175837,"mc":[{"id":"1.168224343","rc":[{"batb":[[0,1.06,782.64],[1,1.05,415.09],[2,1.04,535.19]],"batl":[[0,1.14,714.69],[1,1.15,391.91],[2,1.34,1109.8]],"ltp":1.23,"tv":472.8,"id":8979329}]}]}
{"op":"mcm","clk":"1009419677","pt":1580644176778,"mc":[{"id":"1.168224343","rc":[{"batb":[[0,1.04,535.19],[1,1.01,15.51],[2,1.04,0]],"ltp":1.23,"tv":472.8,"id":8979329}]}]}
{"op":"mcm","clk":"1009420039","pt":1580644180384,"mc":[{"id":"1.168224343","rc":[{"batb":[[1,5.3,11.72],[2,1.01,15.52]],"ltp":9.6,"tv":73.59,"id":2397396},{"batb":[[0,1.12,475.44],[1,1.11,660.32],[2,1.1,231.48]],"batl":[[1,1.15,433.92]],"ltp":1.23,"tv":472.8,"id":8979329}]}]}
{"op":"mcm","clk":"1009420179","pt":1580644181795,"mc":[{"id":"1.168224343","rc":[{"batl":[[0,9.6,4.2]],"ltp":9.6,"tv":73.59,"id":2397396},{"batb":[[0,1.12,643.48]],"ltp":1.23,"tv":472.8,"id":8979329}]}]}
{"op":"mcm","clk":"1009420271","pt":1580644182625,"mc":[{"id":"1.168224343","rc":[{"batl":[[1,14,62.58]],"ltp":9.6,"tv":73.59,"id":2397396}]}]}
{"op":"mcm","clk":"1009421662","pt":1580644196228,"mc":[{"id":"1.168224343","rc":[{"batb":[[0,1.12,168.04],[1,1.1,231.48],[2,1.07,331.96]],"batl":[[0,1.15,42.01],[1,1.34,1109.8],[2,1.34,0]],"ltp":1.23,"tv":472.8,"id":8979329}]}]}
{"op":"mcm","clk":"1009421740","pt":1580644197218,"mc":[{"id":"1.168224343","rc":[{"batb":[[0,5.3,11.72],[1,1.01,15.52],[2,1.01,0]],"ltp":9.6,"tv":73.59,"id":2397396},{"batb":[[1,1.07,331.96],[2,1.01,15.51]],"ltp":1.23,"tv":472.8,"id":8979329}]}]}
{"op":"mcm","clk":"1009421834","pt":1580644198006,"mc":[{"id":"1.168224343","rc":[{"batl":[[0,14,62.58],[1,14,0]],"ltp":9.6,"tv":73.59,"id":2397396},{"batb":[[0,1.07,331.96],[1,1.01,15.51],[2,1.01,0]],"batl":[[0,1.34,1109.8],[1,1.34,0]],"ltp":1.23,"tv":472.8,"id":8979329}]}]}
{"op":"mcm","clk":"1009422173","pt":1580644201217,"mc":[{"id":"1.168224343","rc":[{"batb":[[0,1.13,887.74],[1,1.12,234.2],[2,1.07,331.96]],"batl":[[0,1.15,225.59],[1,1.16,681.98],[2,1.34,1109.8]],"ltp":1.23,"tv":472.8,"id":8979329}]}]}
{"op":"mcm","clk":"1009422518","pt":1580644204104,"mc":[{"id":"1.168224343","rc":[{"batl":[[0,12.5,65.97]],"ltp":9.6,"tv":73.59,"id":2397396},{"batb":[[0,1.07,331.96],[1,1.01,15.51],[2,1.07,0]],"batl":[[0,1.34,1109.8],[1,1.16,0],[2,1.34,0]],"ltp":1.23,"tv":472.8,"id":8979329}]}]}
{"op":"mcm","clk":"1009422802","pt":1580644206659,"mc":[{"id":"1.168224343","rc":[{"batb":[[0,1.09,189.85],[1,1.08,980.1],[2,1.07,331.96]],"batl":[[0,1.22,210.92],[1,1.23,450],[2,1.34,1109.8]],"ltp":1.23,"tv":472.8,"id":8979329}]}]}
{"op":"mcm","clk":"1009424569","pt":1580644223549,"mc":[{"id":"1.168224343","rc":[{"batb":[[0,1.07,331.96],[1,1.01,15.51],[2,1.07,0]],"ltp":1.23,"tv":472.8,"id":8979329}]}]}
{"op":"mcm","clk":"1009424842","pt":1580644226370,"mc":[{"id":"1.168224343","rc":[{"batb":[[0,1.2,292.51],[1,1.19,589.26],[2,1.07,331.96]],"batl":[[2,1.34,0]],"ltp":1.23,"tv":472.8,"id":8979329}]}]}
{"op":"mcm","clk":"1009424924","pt":1580644227166,"mc":[{"id":"1.168224343","rc":[{"batb":[[1,3.6,14.32],[2,1.01,15.52]],"ltp":9.6,"tv":73.59,"id":2397396},{"batb":[[1,1.19,711.85],[2,1.14,169.72]],"ltp":1.23,"tv":472.8,"id":8979329}]}]}
{"op":"mcm","clk":"1009425060","pt":1580644228474,"mc":[{"id":"1.168224343","rc":[{"batl":[[0,6.4,7.56]],"ltp":9.6,"tv":73.59,"id":2397396},{"batb":[[1,1.19,879.89]],"ltp":1.23,"tv":472.8,"id":8979329}]}]}
{"op":"mcm","clk":"1009425211","pt":1580644229963,"mc":[{"id":"1.168224343","rc":[{"batl":[[1,8.6,81.89]],"ltp":9.6,"tv":73.59,"id":2397396},{"batl":[[2,1.53,714.1]],"ltp":1.23,"tv":472.8,"id":8979329}]}]}
{"op":"mcm","clk":"1009427699","pt":1580644252312,"mc":[{"id":"1.168224343","rc":[{"batb":[[0,1.19,290.63],[1,1.14,169.72],[2,1.01,15.51]],"batl":[[0,1.53,714.1],[1,1.23,0],[2,1.53,0]],"ltp":1.23,"tv":472.8,"id":8979329}]}]}
{"op":"mcm","clk":"1009427709","pt":1580644252416,"mc":[{"id":"1.168224343","rc":[{"batb":[[0,3.6,14.32],[1,1.01,15.52],[2,1.01,0]],"ltp":9.6,"tv":73.59,"id":2397396},{"batb":[[0,1.19,168.04]],"ltp":1.23,"tv":472.8,"id":8979329}]}]}
{"op":"mcm","clk":"1009427843","pt":1580644253577,"mc":[{"id":"1.168224343","rc":[{"batl":[[0,8.6,81.89],[1,8.6,0]],"ltp":9.6,"tv":73.59,"id":2397396},{"batb":[[0,1.14,169.72],[1,1.01,15.51],[2,1.01,0]],"ltp":1.23,"tv":472.8,"id":8979329}]}]}
{"op":"mcm","clk":"1009427951","pt":1580644254577,"mc":[{"id":"1.168224343","rc":[{"batb":[[0,1.15,529.1],[1,1.14,746.01],[2,1.01,15.51]],"batl":[[0,1.35,305.1],[1,1.36,255.28],[2,1.53,714.1]],"ltp":1.23,"tv":472.8,"id":8979329}]}]}
{"op":"mcm","clk":"1009428196","pt":1580644256584,"mc":[{"id":"1.168224343","rc":[{"batb":[[0,1.14,169.72],[1,1.01,15.51],[2,1.01,0]],"batl":[[0,1.53,714.1],[1,1.36,0],[2,1.53,0]],"ltp":1.23,"tv":472.8,"id":8979329}]}]}
{"op":"mcm","clk":"1009428593","pt":1580644259682,"mc":[{"id":"1.168224343","rc":[{"batb":[[0,1.22,339.71],[1,1.21,525.21],[2,1.14,169.72]],"batl":[[0,1.25,484.7],[1,1.26,382.67],[2,1.53,714.1]],"ltp":1.23,"tv":472.8,"id":8979329}]}]}
{"op":"mcm","clk":"1009428986","pt":1580644262894,"mc":[{"id":"1.168224343","rc":[{"batl":[[0,7.8,87.91]],"ltp":9.6,"tv":73.59,"id":2397396},{"batb":[[0,1.14,169.72],[1,1.01,15.51],[2,1.14,0]],"batl":[[0,1.53,714.1],[1,1.26,0],[2,1.53,0]],"ltp":1.23,"tv":472.8,"id":8979329}]}]}
{"op":"mcm","clk":"1009429337","pt":1580644265801,"mc":[{"id":"1.168224343","rc":[{"batb":[[0,1.15,530.3],[1,1.14,744.81],[2,1.01,15.51]],"batl":[[0,1.35,304.11],[1,1.36,255.28],[2,1.53,714.1]],"ltp":1.23,"tv":472.8,"id":8979329}]}]}
{"op":"mcm","clk":"1009429825","pt":1580644270103,"mc":[{"id":"1.168224343","rc":[{"batb":[[0,1.14,169.72],[1,1.01,15.51],[2,1.01,0]],"ltp":1.23,"tv":472.8,"id":8979329}]}]}
{"op":"mcm","clk":"1009430092","pt":1580644272397,"mc":[{"id":"1.168224343","rc":[{"batl":[[2,1.53,0]],"ltp":1.23,"tv":472.8,"id":8979329}]}]}
{"op":"mcm","clk":"1009430185","pt":1580644273336,"mc":[{"id":"1.168224343","rc":[{"batb":[[0,1.31,395.58],[1,1.3,342.12],[2,1.14,169.72]],"ltp":1.23,"tv":472.8,"id":8979329}]}]}
{"op":"mcm","clk":"1009430285","pt":1580644274120,"mc":[{"id":"1.168224343","rc":[{"batb":[[1,3.15,19.83],[2,1.01,15.52]],"ltp":9.6,"tv":73.59,"id":2397396},{"batb":[[0,1.33,65.94],[1,1.31,395.58],[2,1.3,342.12]],"ltp":1.23,"tv":472.8,"id":8979329}]}]}
{"op":"mcm","clk":"1009430333","pt":1580644274536,"mc":[{"id":"1.168224343","rc":[{"batl":[[0,4.2,12.6]],"ltp":9.6,"tv":73.59,"id":2397396},{"batb":[[1,1.31,530.85]],"ltp":1.23,"tv":472.8,"id":8979329}]}]}
{"op":"mcm","clk":"1009430647","pt":1580644277330,"mc":[{"id":"1.168224343","rc":[{"batl":[[1,5.5,115.06]],"ltp":9.6,"tv":73.59,"id":2397396},{"batl":[[2,1.71,542.06]],"ltp":1.23,"tv":472.8,"id":8979329}]}]}
{"op":"mcm","clk":"1009432549","pt":1580644294241,"mc":[{"id":"1.168224343","rc":[{"batb":[[1,1.31,135.27],[2,1.25,92.45]],"batl":[[0,1.71,542.06],[1,1.36,0],[2,1.71,0]],"ltp":1.23,"tv":472.8,"id":8979329}]}]}
{"op":"mcm","clk":"1009432627","pt":1580644294823,"mc":[{"id":"1.168224343","rc":[{"batb":[[0,3.15,19.83],[1,1.01,15.52],[2,1.01,0]],"ltp":9.6,"tv":73.59,"id":2397396},{"batb":[[0,1.31,135.27],[1,1.25,92.45],[2,1.01,15.51]],"ltp":1.23,"tv":472.8,"id":8979329}]}]}
{"op":"mcm","clk":"1009432793","pt":1580644296343,"mc":[{"id":"1.168224343","rc":[{"batl":[[0,5.5,115.06],[1,5.5,0]],"ltp":9.6,"tv":73.59,"id":2397396},{"batb":[[0,1.25,92.45],[1,1.01,15.51],[2,1.01,0]],"ltp":1.23,"tv":472.8,"id":8979329}]}]}
{"op":"mcm","clk":"1009432919","pt":1580644297247,"mc":[{"id":"1.168224343","rc":[{"batb":[[1,1.24,321.8],[2,1.23,471.91]],"batl":[[0,1.42,258.23],[1,1.43,208.06],[2,1.71,542.06]],"ltp":1.23,"tv":472.8,"id":8979329}]}]}
{"op":"mcm","clk":"1009432980","pt":1580644297768,"mc":[{"id":"1.168224343","rc":[{"batb":[[0,3.25,18.41]],"ltp":9.6,"tv":73.59,"id":2397396},{"batb":[[0,1.24,419.21],[1,1.23,471.91],[2,1.01,15.51]],"ltp":1.23,"tv":472.8,"id":8979329}]}]}
{"op":"mcm","clk":"1009434168","pt":1580644308367,"mc":[{"id":"1.168224343","rc":[{"batl":[[0,1.71,542.06],[1,1.43,0],[2,1.71,0]],"ltp":1.23,"tv":472.8,"id":8979329}]}]}
{"op":"mcm","clk":"1009434515","pt":1580644311363,"mc":[{"id":"1.168224343","rc":[{"batl":[[0,1.27,383.1],[1,1.28,353.02]],"ltp":1.23,"tv":472.8,"id":8979329}]}]}
{"op":"mcm","clk":"1009434600","pt":1580644312154,"mc":[{"id":"1.168224343","rc":[{"batb":[[0,4.5,16.6],[1,3.8,25.49],[2,1.01,15.52]],"ltp":9.6,"tv":73.59,"id":2397396},{"batb":[[2,1.16,152.96]],"ltp":1.23,"tv":472.8,"id":8979329}]}]}
{"op":"mcm","clk":"1009434648","pt":1580644312573,"mc":[{"id":"1.168224343","rc":[{"batl":[[0,5.1,10.08]],"ltp":9.6,"tv":73.59,"id":2397396},{"batb":[[0,1.24,587.25]],"ltp":1.23,"tv":472.8,"id":8979329}]}]}
{"op":"mcm","clk":"1009434870","pt":1580644314152,"mc":[{"id":"1.168224343","rc":[{"batl":[[1,7.2,92.18]],"ltp":9.6,"tv":73.59,"id":2397396},{"batl":[[2,1.58,650.58]],"ltp":1.23,"tv":472.8,"id":8979329}]}]}
{"op":"mcm","clk":"1009437062","pt":1580644335192,"mc":[{"id":"1.168224343","rc":[{"batb":[[0,1.24,265.45],[1,1.16,152.96],[2,1.01,15.51]],"batl":[[0,1.58,650.58],[1,1.28,0],[2,1.58,0]],"ltp":1.23,"tv":472.8,"id":8979329}]}]}
{"op":"mcm","clk":"1009437137","pt":1580644335886,"mc":[{"id":"1.168224343","rc":[{"batb":[[0,3.8,25.49],[1,1.01,15.52],[2,1.01,0]],"batl":[[0,7.2,92.18],[1,7.2,0]],"ltp":9.6,"tv":73.59,"id":2397396},{"batb":[[0,1.16,152.96],[1,1.01,15.51],[2,1.01,0]],"ltp":1.23,"tv":472.8,"id":8979329}]}]}
{"op":"mcm","clk":"1009437355","pt":1580644338309,"mc":[{"id":"1.168224343","rc":[{"batb":[[0,1.17,183.35],[1,1.16,870.64],[2,1.01,15.51]],"batl":[[0,1.34,299.76],[1,1.35,269.8],[2,1.58,650.58]],"ltp":1.23,"tv":472.8,"id":8979329}]}]}
{"op":"mcm","clk":"1009437888","pt":1580644342244,"mc":[{"id":"1.168224343","rc":[{"batb":[[0,1.16,152.96],[1,1.01,15.51],[2,1.01,0]],"ltp":1.23,"tv":472.8,"id":8979329}]}]}
{"op":"mcm","clk":"1009438212","pt":1580644345100,"mc":[{"id":"1.168224343","rc":[{"batb":[[0,1.3,452.18],[1,1.29,357.91],[2,1.16,152.96]],"ltp":1.23,"tv":472.8,"id":8979329}]}]}
{"op":"mcm","clk":"1009438296","pt":1580644345729,"mc":[{"id":"1.168224343","rc":[{"batb":[[1,3.25,18.73],[2,1.01,15.52]],"ltp":9.6,"tv":73.59,"id":2397396},{"batb":[[0,1.31,72.47],[1,1.3,452.18],[2,1.29,357.91]],"ltp":1.23,"tv":472.8,"id":8979329}]}]}
{"op":"mcm","clk":"1009438411","pt":1580644346631,"mc":[{"id":"1.168224343","rc":[{"batl":[[0,4.3,12.6]],"ltp":9.6,"tv":73.59,"id":2397396},{"batb":[[1,1.3,591.65]],"ltp":1.23,"tv":472.8,"id":8979329}]}]}
{"op":"mcm","clk":"1009438610","pt":1580644348210,"mc":[{"id":"1.168224343","rc":[{"batl":[[1,6,106.18]],"ltp":9.6,"tv":73.59,"id":2397396}]}]}
{"op":"mcm","clk":"1009440080","pt":1580644361255,"mc":[{"id":"1.168224343","rc":[{"batb":[[1,1.3,139.47],[2,1.22,107.95]],"batl":[[0,1.58,650.58],[1,1.35,0],[2,1.58,0]],"ltp":1.23,"tv":472.8,"id":8979329}]}]}
{"op":"mcm","clk":"1009440162","pt":1580644362049,"mc":[{"id":"1.168224343","rc":[{"batb":[[0,3.25,18.73],[1,1.01,15.52],[2,1.01,0]],"batl":[[0,6,106.18],[1,6,0]],"ltp":9.6,"tv":73.59,"id":2397396},{"batb":[[0,1.22,107.95],[1,1.01,15.51],[2,1.22,0]],"ltp":1.23,"tv":472.8,"id":8979329}]}]}
{"op":"mcm","clk":"1009440395","pt":1580644364320,"mc":[{"id":"1.168224343","rc":[{"batl":[[0,1.42,202.56],[1,1.43,208.71],[2,1.58,650.58]],"ltp":1.23,"tv":472.8,"id":8979329}]}]}
{"op":"mcm","clk":"1009440613","pt":1580644366121,"mc":[{"id":"1.168224343","rc":[{"batl":[[2,1.58,0]],"ltp":1.23,"tv":472.8,"id":8979329}]}]}
{"op":"mcm","clk":"1009440726","pt":1580644367139,"mc":[{"id":"1.168224343","rc":[{"batb":[[0,1.38,267.78],[1,1.37,260.47],[2,1.22,107.95]],"ltp":1.23,"tv":472.8,"id":8979329}]}]}
{"op":"mcm","clk":"1009440800","pt":1580644367851,"mc":[{"id":"1.168224343","rc":[{"batb":[[1,2.9,25.02],[2,1.01,15.52]],"ltp":9.6,"tv":73.59,"id":2397396},{"batb":[[0,1.39,54.13],[1,1.38,267.78],[2,1.37,260.47]],"ltp":1.23,"tv":472.8,"id":8979329}]}]}
{"op":"mcm","clk":"1009440886","pt":1580644368537,"mc":[{"id":"1.168224343","rc":[{"batl":[[0,3.8,14.28]],"ltp":9.6,"tv":73.59,"id":2397396}]}]}
{"op":"mcm","clk":"1009441073","pt":1580644370149,"mc":[{"id":"1.168224343","rc":[{"batl":[[1,4.9,126.27]],"ltp":9.6,"tv":73.59,"id":2397396},{"batl":[[2,1.77,500.61]],"ltp":1.23,"tv":472.8,"id":8979329}]}]}
{"op":"mcm","clk":"1009442183","pt":1580644380745,"mc":[{"id":"1.168224343","rc":[{"batb":[[0,2.9,25.02],[1,1.01,15.52],[2,1.01,0]],"ltp":9.6,"tv":73.59,"id":2397396},{"batb":[[0,1.36,115.95],[1,1.3,75.53],[2,1.01,15.51]],"batl":[[0,1.77,500.61],[1,1.43,0],[2,1.77,0]],"ltp":1.23,"tv":472.8,"id":8979329}]}]}
{"op":"mcm","clk":"1009442289","pt":1580644381856,"mc":[{"id":"1.168224343","rc":[{"batl":[[0,4.9,126.27],[1,4.9,0]],"ltp":9.6,"tv":73.59,"id":2397396},{"batb":[[0,1.3,75.53],[1,1.01,15.51],[2,1.01,0]],"ltp":1.23,"tv":472.8,"id":8979329}]}]}
{"op":"mcm","clk":"1009442434","pt":1580644383360,"mc":[{"id":"1.168224343","rc":[{"batb":[[1,1.29,496.11],[2,1.28,374.8]],"batl":[[0,1.5,197.82],[1,1.51,167],[2,1.77,500.61]],"ltp":1.23,"tv":472.8,"id":8979329}]}]}
{"op":"mcm","clk":"1009442470","pt":1580644383675,"mc":[{"id":"1.168224343","rc":[{"batb":[[1,1.01,15.51],[2,1.28,0]],"batl":[[0,1.77,500.61],[1,1.51,0],[2,1.77,0]],"ltp":1.23,"tv":472.8,"id":8979329}]}]}
{"op":"mcm","clk":"1009442877","pt":1580644387364,"mc":[{"id":"1.168224343","rc":[{"batb":[[1,2.74,11.72],[2,1.01,15.52]],"ltp":9.6,"tv":73.59,"id":2397396},{"batb":[[0,1.47,43.28],[1,1.45,295.64],[2,1.44,207.84]],"batl":[[0,1.5,197.82],[1,1.51,167],[2,1.77,500.61]],"ltp":1.23,"tv":472.8,"id":8979329}]}]}
{"op":"mcm","clk":"1009443124","pt":1580644389364,"mc":[{"id":"1.168224343","rc":[{"batl":[[0,3.4,16.8],[1,4.2,148.03]],"ltp":9.6,"tv":73.59,"id":2397396}]}]}
{"op":"mcm","clk":"1009444394","pt":1580644401070,"mc":[{"id":"1.168224343","rc":[{"batb":[[0,2.74,11.72],[1,1.01,15.52],[2,1.01,0]],"ltp":9.6,"tv":73.59,"id":2397396},{"batb":[[0,1.41,101.66],[1,1.4,52.4],[2,1.01,15.51]],"batl":[[0,1.77,500.61],[1,1.51,0],[2,1.77,0]],"ltp":1.23,"tv":472.8,"id":8979329}]}]}
{"op":"mcm","clk":"1009444458","pt":1580644401703,"mc":[{"id":"1.168224343","rc":[{"batl":[[0,4.2,148.03],[1,4.2,0]],"ltp":9.6,"tv":73.59,"id":2397396},{"batb":[[0,1.4,52.4],[1,1.01,15.51],[2,1.01,0]],"ltp":1.23,"tv":472.8,"id":8979329}]}]}
{"op":"mcm","clk":"1009444786","pt":1580644404292,"mc":[{"id":"1.168224343","rc":[{"batb":[[0,1.41,51.85],[1,1.39,362.28],[2,1.38,252.7]],"batl":[[0,1.55,153.95],[1,1.56,147.77],[2,1.77,500.61]],"ltp":1.23,"tv":472.8,"id":8979329}]}]}
{"op":"mcm","clk":"1009445180","pt":1580644408097,"mc":[{"id":"1.168224343","rc":[{"batb":[[1,1.01,15.51],[2,1.38,0]],"ltp":1.23,"tv":472.8,"id":8979329}]}]}
{"op":"mcm","clk":"1009445524","pt":1580644411288,"mc":[{"id":"1.168224343","rc":[{"batb":[[0,1.5,237.24],[1,1.49,179.52],[2,1.41,51.85]],"batl":[[2,1.77,0]],"ltp":1.23,"tv":472.8,"id":8979329}]}]}
{"op":"mcm","clk":"1009445605","pt":1580644411869,"mc":[{"id":"1.168224343","rc":[{"batb":[[1,2.3,18.65],[2,1.01,15.52]],"ltp":9.6,"tv":73.59,"id":2397396},{"batb":[[0,1.52,37.61],[1,1.5,237.24],[2,1.49,179.52]],"ltp":1.23,"tv":472.8,"id":8979329}]}]}
{"op":"mcm","clk":"1009445696","pt":1580644412710,"mc":[{"id":"1.168224343","rc":[{"batl":[[0,3.2,18.48]],"ltp":9.6,"tv":73.59,"id":2397396}]}]}
{"op":"mcm","clk":"1009445906","pt":1580644414496,"mc":[{"id":"1.168224343","rc":[{"batl":[[1,3.9,158.24]],"ltp":9.6,"tv":73.59,"id":2397396},{"batl":[[2,1.95,409.86]],"ltp":1.23,"tv":472.8,"id":8979329}]}]}
{"op":"mcm","clk":"1009450013","pt":1580644456165,"mc":[{"id":"1.168224343","rc":[{"batb":[[0,2.76,11.57],[1,2.32,18.33]],"ltp":9.6,"tv":73.59,"id":2397396}]}]}
{"op":"mcm","clk":"1009454155","pt":1580644498001,"mc":[{"id":"1.168224343","rc":[{"batb":[[0,2.32,18.33],[1,1.01,15.52],[2,1.01,0]],"ltp":9.6,"tv":73.59,"id":2397396},{"batb":[[0,1.46,90.74],[1,1.45,45.32],[2,1.01,15.51]],"batl":[[0,1.95,409.86],[1,1.56,0],[2,1.95,0]],"ltp":1.23,"tv":472.8,"id":8979329}]}]}
{"op":"mcm","clk":"1009454351","pt":1580644499705,"mc":[{"id":"1.168224343","rc":[{"batl":[[0,3.9,158.24],[1,3.9,0]],"ltp":9.6,"tv":73.59,"id":2397396},{"batb":[[0,1.45,45.32],[1,1.01,15.51],[2,1.01,0]],"ltp":1.23,"tv":472.8,"id":8979329}]}]}
{"op":"mcm","clk":"1009454475","pt":1580644500698,"mc":[{"id":"1.168224343","rc":[{"batb":[[1,1.43,274.42],[2,1.42,220.92]],"batl":[[0,1.73,178.64],[1,1.75,198.19],[2,1.95,409.86]],"ltp":1.23,"tv":472.8,"id":8979329}]}]}
{"op":"mcm","clk":"1009456115","pt":1580644514738,"mc":[{"id":"1.168224343","rc":[{"batl":[[0,1.95,409.86],[1,1.75,0],[2,1.95,0]],"ltp":1.23,"tv":472.8,"id":8979329}]}]}
{"op":"mcm","clk":"1009456474","pt":1580644518071,"mc":[{"id":"1.168224343","rc":[{"batl":[[0,1.48,265.12],[1,1.49,175.63]],"ltp":1.23,"tv":472.8,"id":8979329}]}]}
{"op":"mcm","clk":"1009456553","pt":1580644518811,"mc":[{"id":"1.168224343","rc":[{"batb":[[0,3,23.13],[1,2.62,13.3],[2,1.01,15.52]],"batl":[[0,3.5,16.8]],"ltp":9.6,"tv":73.59,"id":2397396}]}]}
{"op":"mcm","clk":"1009456844","pt":1580644521635,"mc":[{"id":"1.168224343","rc":[{"batl":[[1,4.6,136.05]],"ltp":9.6,"tv":73.59,"id":2397396},{"batl":[[2,1.82,469.11]],"ltp":1.23,"tv":472.8,"id":8979329}]}]}
{"op":"mcm","clk":"1009458537","pt":1580644537386,"mc":[{"id":"1.168224343","rc":[{"batb":[[0,2.62,13.3],[1,1.01,15.52],[2,1.01,0]],"ltp":9.6,"tv":73.59,"id":2397396},{"batb":[[0,1.4,157.9],[1,1.01,15.51],[2,1.42,0]],"batl":[[0,1.82,469.11],[1,1.49,0],[2,1.82,0]],"ltp":1.23,"tv":472.8,"id":8979329}]}]}
{"op":"mcm","clk":"1009458618","pt":1580644538076,"mc":[{"id":"1.168224343","rc":[{"batl":[[0,4.6,136.05],[1,4.6,0]],"ltp":9.6,"tv":73.59,"id":2397396},{"batb":[[0,1.4,52.87]],"ltp":1.23,"tv":472.8,"id":8979329}]}]}
{"op":"mcm","clk":"1009458799","pt":1580644539964,"mc":[{"id":"1.168224343","rc":[{"batb":[[1,1.39,157.12],[2,1.38,250.32]],"batl":[[0,1.59,133.35],[1,1.6,134.46],[2,1.82,469.11]],"ltp":1.23,"tv":472.8,"id":8979329}]}]}
{"op":"mcm","clk":"1009459157","pt":1580644543775,"mc":[{"id":"1.168224343","rc":[{"batl":[[0,1.82,469.11],[1,1.6,0],[2,1.82,0]],"ltp":1.23,"tv":472.8,"id":8979329}]}]}
{"op":"mcm","clk":"1009459532","pt":1580644547405,"mc":[{"id":"1.168224343","rc":[{"batb":[[0,3.2,19.28],[1,2.92,24.94],[2,2.62,13.3]],"ltp":9.6,"tv":73.59,"id":2397396},{"batl":[[0,1.43,280.86],[1,1.44,201.79],[2,1.82,469.11]],"ltp":1.23,"tv":472.8,"id":8979329}]}]}
{"op":"mcm","clk":"1009459550","pt":1580644547605,"mc":[{"id":"1.168224343","rc":[{"batb":[[2,1.01,15.52]],"ltp":9.6,"tv":73.59,"id":2397396}]}]}
{"op":"mcm","clk":"1009459687","pt":1580644548811,"mc":[{"id":"1.168224343","rc":[{"batl":[[0,3.75,15.12],[1,4.6,136.05]],"ltp":9.6,"tv":73.59,"id":2397396}]}]}
{"op":"mcm","clk":"1009460745","pt":1580644558298,"mc":[{"id":"1.168224343","rc":[{"batb":[[1,1.37,171.65],[2,1.01,15.51]],"batl":[[0,1.82,469.11],[1,1.44,0],[2,1.82,0]],"ltp":1.23,"tv":472.8,"id":8979329}]}]}
{"op":"mcm","clk":"1009460765","pt":1580644558519,"mc":[{"id":"1.168224343","rc":[{"batb":[[0,2.92,24.94],[1,1.01,15.52],[2,1.01,0]],"ltp":9.6,"tv":73.59,"id":2397396},{"batb":[[0,1.37,171.65],[1,1.01,15.51],[2,1.01,0]],"ltp":1.23,"tv":472.8,"id":8979329}]}]}
{"op":"mcm","clk":"1009460924","pt":1580644560007,"mc":[{"id":"1.168224343","rc":[{"batl":[[0,4.6,136.05],[1,4.6,0]],"ltp":9.6,"tv":73.59,"id":2397396},{"batb":[[0,1.37,58.22]],"ltp":1.23,"tv":472.8,"id":8979329}]}]}
{"op":"mcm","clk":"1009461075","pt":1580644561293,"mc":[{"id":"1.168224343","rc":[{"batb":[[1,1.36,243.95],[2,1.35,279.24]],"batl":[[0,1.49,160.19],[1,1.5,171.62],[2,1.82,469.11]],"ltp":1.23,"tv":472.8,"id":8979329}]}]}
{"op":"mcm","clk":"1009461875","pt":1580644568010,"mc":[{"id":"1.168224343","rc":[{"batb":[[1,1.01,15.51],[2,1.35,0]],"ltp":1.23,"tv":472.8,"id":8979329}]}]}
{"op":"mcm","clk":"1009462251","pt":1580644571113,"mc":[{"id":"1.168224343","rc":[{"batb":[[0,1.45,153.09],[1,1.44,206.62],[2,1.37,58.22]],"ltp":1.23,"tv":472.8,"id":8979329}]}]}
{"op":"mcm","clk":"1009462339","pt":1580644571901,"mc":[{"id":"1.168224343","rc":[{"batb":[[1,2.46,15.5],[2,1.01,15.52]],"ltp":9.6,"tv":73.59,"id":2397396},{"batb":[[0,1.47,43.28],[1,1.45,153.09],[2,1.44,206.62]],"ltp":1.23,"tv":472.8,"id":8979329}]}]}
{"op":"mcm","clk":"1009462441","pt":1580644572850,"mc":[{"id":"1.168224343","rc":[{"batl":[[0,3.45,16.8]],"ltp":9.6,"tv":73.59,"id":2397396}]}]}
{"op":"mcm","clk":"1009462555","pt":1580644573849,"mc":[{"id":"1.168224343","rc":[{"batl":[[1,4.2,148.03]],"ltp":9.6,"tv":73.59,"id":2397396}]}]}
{"op":"mcm","clk":"1009464073","pt":1580644586348,"mc":[{"id":"1.168224343","rc":[{"batb":[[0,2.46,15.5],[1,1.01,15.52],[2,1.01,0]],"ltp":9.6,"tv":73.59,"id":2397396},{"batb":[[0,1.41,152.57],[1,1.01,15.51],[2,1.44,0]],"batl":[[0,1.82,469.11],[1,1.5,0],[2,1.82,0]],"ltp":1.23,"tv":472.8,"id":8979329}]}]}
{"op":"mcm","clk":"1009464232","pt":1580644587870,"mc":[{"id":"1.168224343","rc":[{"batl":[[0,4.2,148.03],[1,4.2,0]],"ltp":9.6,"tv":73.59,"id":2397396},{"batb":[[0,1.41,50.91]],"ltp":1.23,"tv":472.8,"id":8979329}]}]}
{"op":"mcm","clk":"1009464371","pt":1580644589067,"mc":[{"id":"1.168224343","rc":[{"batb":[[1,1.39,183.37],[2,1.38,250.61]],"batl":[[0,1.64,168.18],[1,1.65,120.33],[2,1.82,469.11]],"ltp":1.23,"tv":472.8,"id":8979329}]}]}
{"op":"mcm","clk":"1009464716","pt":1580644591981,"mc":[{"id":"1.168224343","rc":[{"batl":[[0,1.82,469.11],[1,1.65,0],[2,1.82,0]],"ltp":1.23,"tv":472.8,"id":8979329}]}]}
{"op":"mcm","clk":"1009465047","pt":1580644595181,"mc":[{"id":"1.168224343","rc":[{"batl":[[0,1.43,256.39],[1,1.44,202.02],[2,1.82,469.11]],"ltp":1.23,"tv":472.8,"id":8979329}]}]}
{"op":"mcm","clk":"1009465097","pt":1580644595664,"mc":[{"id":"1.168224343","rc":[{"batb":[[0,3.15,20.3],[1,2.88,25.57],[2,1.01,15.52]],"ltp":9.6,"tv":73.59,"id":2397396},{"batb":[[2,1.38,306.87]],"ltp":1.23,"tv":472.8,"id":8979329}]}]}
{"op":"mcm","clk":"1009465235","pt":1580644596879,"mc":[{"id":"1.168224343","rc":[{"batl":[[0,3.75,15.12]],"ltp":9.6,"tv":73.59,"id":2397396}]}]}
{"op":"mcm","clk":"1009465384","pt":1580644598075,"mc":[{"id":"1.168224343","rc":[{"batl":[[1,4.9,126.27]],"ltp":9.6,"tv":73.59,"id":2397396}]}]}
{"op":"mcm","clk":"1009466378","pt":1580644607365,"mc":[{"id":"1.168224343","rc":[{"batb":[[1,1.38,56.26],[2,1.36,115.95]],"batl":[[0,1.82,469.11],[1,1.44,0],[2,1.82,0]],"ltp":1.23,"tv":472.8,"id":8979329}]}]}
{"op":"mcm","clk":"1009466452","pt":1580644607995,"mc":[{"id":"1.168224343","rc":[{"batb":[[0,2.88,25.57],[1,1.01,15.52],[2,1.01,0]],"batl":[[0,4.9,126.27],[1,4.9,0]],"ltp":9.6,"tv":73.59,"id":2397396},{"batb":[[0,1.38,56.26],[1,1.01,15.51],[2,1.36,0]],"ltp":1.23,"tv":472.8,"id":8979329}]}]}
{"op":"mcm","clk":"1009466705","pt":1580644610361,"mc":[{"id":"1.168224343","rc":[{"batb":[[1,1.36,294.64],[2,1.35,279.93]],"ltp":1.23,"tv":472.8,"id":8979329}]}]}
{"op":"mcm","clk":"1009467002","pt":1580644613162,"mc":[{"id":"1.168224343","rc":[{"batl":[[0,1.4,232.47],[1,1.41,221.45]],"ltp":1.23,"tv":472.8,"id":8979329}]}]}
{"op":"mcm","clk":"1009467077","pt":1580644614000,"mc":[{"id":"1.168224343","rc":[{"batb":[[0,3.3,17.78],[1,2.94,24.47],[2,1.01,15.52]],"ltp":9.6,"tv":73.59,"id":2397396}]}]}
{"op":"mcm","clk":"1009467170","pt":1580644614791,"mc":[{"id":"1.168224343","rc":[{"batl":[[0,3.95,13.44],[1,4.9,126.27]],"ltp":9.6,"tv":73.59,"id":2397396}]}]}
{"op":"mcm","clk":"1009467373","pt":1580644616384,"mc":[{"id":"1.168224343","rc":[{"batl":[[2,1.73,527.57]],"ltp":1.23,"tv":472.8,"id":8979329}]}]}
{"op":"mcm","clk":"1009471044","pt":1580644650221,"mc":[{"id":"1.168224343","rc":[{"batb":[[1,1.34,123.51],[2,1.28,81.91]],"batl":[[0,1.73,527.57],[1,1.41,0],[2,1.73,0]],"ltp":1.23,"tv":472.8,"id":8979329}]}]}
{"op":"mcm","clk":"1009471343","pt":1580644653047,"mc":[{"id":"1.168224343","rc":[{"batl":[[0,1.49,271.3],[1,1.5,170.81],[2,1.73,527.57]],"ltp":1.23,"tv":472.8,"id":8979329}]}]}
{"op":"mcm","clk":"1009471449","pt":1580644654049,"mc":[{"id":"1.168224343","rc":[{"batb":[[0,2.94,24.47],[1,1.01,15.52],[2,1.01,0]],"batl":[[0,4.9,126.27],[1,4.9,0]],"ltp":9.6,"tv":73.59,"id":2397396},{"batb":[[0,1.28,81.91],[1,1.27,261.58],[2,1.26,405.25]],"ltp":1.23,"tv":472.8,"id":8979329}]}]}
{"op":"mcm","clk":"1009471580","pt":1580644655351,"mc":[{"id":"1.168224343","rc":[{"batb":[[1,1.01,15.51],[2,1.26,0]],"batl":[[0,1.73,527.57],[1,1.5,0],[2,1.73,0]],"ltp":1.23,"tv":472.8,"id":8979329}]}]}
{"op":"mcm","clk":"1009471903","pt":1580644658334,"mc":[{"id":"1.168224343","rc":[{"batb":[[0,1.34,317.32],[1,1.33,302.03],[2,1.28,81.91]],"batl":[[0,1.38,273.21],[1,1.39,235.56],[2,1.73,527.57]],"ltp":1.23,"tv":472.8,"id":8979329}]}]}
{"op":"mcm","clk":"1009472249","pt":1580644661751,"mc":[{"id":"1.168224343","rc":[{"batb":[[0,1.28,81.91],[1,1.01,15.51],[2,1.28,0]],"batl":[[0,1.73,527.57],[1,1.39,0],[2,1.73,0]],"ltp":1.23,"tv":472.8,"id":8979329}]}]}
{"op":"mcm","clk":"1009472534","pt":1580644664359,"mc":[{"id":"1.168224343","rc":[{"batb":[[1,1.27,287.15],[2,1.26,405.32]],"batl":[[0,1.49,249.41],[1,1.5,170.79],[2,1.73,527.57]],"ltp":1.23,"tv":472.8,"id":8979329}]}]}
{"op":"mcm","clk":"1009474172","pt":1580644679575,"mc":[{"id":"1.168224343","rc":[{"batb":[[1,1.01,15.51],[2,1.26,0]],"ltp":1.23,"tv":472.8,"id":8979329}]}]}
{"op":"mcm","clk":"1009474620","pt":1580644683395,"mc":[{"id":"1.168224343","rc":[{"batb":[[1,2.68,12.43],[2,1.01,15.52]],"ltp":9.6,"tv":73.59,"id":2397396},{"batb":[[0,1.46,43.98],[1,1.44,263.66],[2,1.43,213.67]],"ltp":1.23,"tv":472.8,"id":8979329}]}]}
{"op":"mcm","clk":"1009474702","pt":1580644684068,"mc":[{"id":"1.168224343","rc":[{"batl":[[0,3.5,16.8]],"ltp":9.6,"tv":73.59,"id":2397396}]}]}
{"op":"mcm","clk":"1009474778","pt":1580644684801,"mc":[{"id":"1.168224343","rc":[{"batl":[[1,4.2,148.03]],"ltp":9.6,"tv":73.59,"id":2397396}]}]}
{"op":"mcm","clk":"1009476666","pt":1580644700921,"mc":[{"id":"1.168224343","rc":[{"batb":[[0,2.68,12.43],[1,1.01,15.52],[2,1.01,0]],"ltp":9.6,"tv":73.59,"id":2397396},{"batb":[[0,1.4,105.02],[1,1.36,59.88],[2,1.01,15.51]],"batl":[[0,1.73,527.57],[1,1.5,0],[2,1.73,0]],"ltp":1.23,"tv":472.8,"id":8979329}]}]}
{"op":"mcm","clk":"1009476775","pt":1580644701915,"mc":[{"id":"1.168224343","rc":[{"batl":[[0,4.2,148.03],[1,4.2,0]],"ltp":9.6,"tv":73.59,"id":2397396},{"batb":[[0,1.36,59.88],[1,1.01,15.51],[2,1.01,0]],"ltp":1.23,"tv":472.8,"id":8979329}]}]}
{"op":"mcm","clk":"1009476985","pt":1580644703694,"mc":[{"id":"1.168224343","rc":[{"batl":[[0,1.57,178.78],[1,1.58,140.41],[2,1.73,527.57]],"ltp":1.23,"tv":472.8,"id":8979329}]}]}
{"op":"mcm","clk":"1009477277","pt":1580644706320,"mc":[{"id":"1.168224343","rc":[{"batb":[[0,1.52,173.72],[1,1.51,169.42],[2,1.36,59.88]],"batl":[[2,1.73,0]],"ltp":1.23,"tv":472.8,"id":8979329}]}]}
{"op":"mcm","clk":"1009477411","pt":1580644707211,"mc":[{"id":"1.168224343","rc":[{"batb":[[1,2.5,14.79],[2,1.01,15.52]],"batl":[[0,3.15,19.32]],"ltp":9.6,"tv":73.59,"id":2397396},{"batb":[[0,1.54,35.8],[1,1.52,173.72],[2,1.51,169.42]],"ltp":1.23,"tv":472.8,"id":8979329}]}]}
{"op":"mcm","clk":"1009477636","pt":1580644709083,"mc":[{"id":"1.168224343","rc":[{"batl":[[1,3.9,158.24]],"ltp":9.6,"tv":73.59,"id":2397396},{"batl":[[2,1.95,409.86]],"ltp":1.23,"tv":472.8,"id":8979329}]}]}
{"op":"mcm","clk":"1009478814","pt":1580644720822,"mc":[{"id":"1.168224343","rc":[{"batb":[[0,2.5,14.79],[1,1.01,15.52],[2,1.01,0]],"ltp":9.6,"tv":73.59,"id":2397396},{"batb":[[0,1.46,135.28],[1,1.01,15.51],[2,1.51,0]],"batl":[[0,1.95,409.86],[1,1.58,0],[2,1.95,0]],"ltp":1.23,"tv":472.8,"id":8979329}]}]}
{"op":"mcm","clk":"1009478934","pt":1580644721926,"mc":[{"id":"1.168224343","rc":[{"batl":[[0,3.9,158.24],[1,3.9,0]],"ltp":9.6,"tv":73.59,"id":2397396},{"batb":[[0,1.46,44.53]],"ltp":1.23,"tv":472.8,"id":8979329}]}]}
{"op":"mcm","clk":"1009479099","pt":1580644723422,"mc":[{"id":"1.168224343","rc":[{"batb":[[1,1.44,300.96],[2,1.43,213.97]],"batl":[[0,1.64,239.06],[1,1.65,119.94],[2,1.95,409.86]],"ltp":1.23,"tv":472.8,"id":8979329}]}]}
{"op":"mcm","clk":"1009479213","pt":1580644724727,"mc":[{"id":"1.168224343","rc":[{"batb":[[1,1.01,15.51],[2,1.43,0]],"ltp":1.23,"tv":472.8,"id":8979329}]}]}
{"op":"mcm","clk":"1009479485","pt":1580644727341,"mc":[{"id":"1.168224343","rc":[{"batb":[[0,1.58,149.6],[1,1.57,145.35],[2,1.46,44.53]],"ltp":1.23,"tv":472.8,"id":8979329}]}]}
{"op":"mcm","clk":"1009479569","pt":1580644728136,"mc":[{"id":"1.168224343","rc":[{"batb":[[1,2.42,16.21],[2,1.01,15.52]],"ltp":9.6,"tv":73.59,"id":2397396},{"batb":[[0,1.6,31.08],[1,1.58,123.56],[2,1.57,145.35]],"batl":[[0,1.64,122.98],[1,1.95,409.86],[2,1.95,0]],"ltp":1.23,"tv":472.8,"id":8979329}]}]}
{"op":"mcm","clk":"1009479671","pt":1580644728952,"mc":[{"id":"1.168224343","rc":[{"batl":[[0,2.98,21]],"ltp":9.6,"tv":73.59,"id":2397396}]}]}
{"op":"mcm","clk":"1009479786","pt":1580644730148,"mc":[{"id":"1.168224343","rc":[{"batl":[[1,3.65,170.41]],"ltp":9.6,"tv":73.59,"id":2397396}]}]}
{"op":"mcm","clk":"1009479822","pt":1580644730640,"mc":[{"id":"1.168224343","rc":[{"batl":[[0,1.63,142.06],[1,1.64,122.98],[2,1.95,409.86]],"ltp":1.23,"tv":472.8,"id":8979329}]}]}
{"op":"mcm","clk":"1009480553","pt":1580644737747,"mc":[{"id":"1.168224343","rc":[{"trd":[[2.58,26.36]],"ltp":2.58,"tv":99.95,"id":2397396},{"trd":[[1.63,41.74]],"batl":[[0,1.63,100.32]],"ltp":1.63,"tv":514.54,"id":8979329}],"tv":614.5}]}
{"op":"mcm","clk":"1009480933","pt":1580644741159,"mc":[{"id":"1.168224343","rc":[{"batb":[[0,2.42,16.21],[1,1.01,15.52],[2,1.01,0]],"ltp":2.58,"tv":99.95,"id":2397396},{"batb":[[0,1.55,35.41],[1,1.51,82.34],[2,1.01,15.51]],"batl":[[0,1.95,409.86],[1,1.64,0],[2,1.95,0]],"ltp":1.63,"tv":514.54,"id":8979329}]}]}
{"op":"mcm","clk":"1009481058","pt":1580644741968,"mc":[{"id":"1.168224343","rc":[{"batl":[[0,3.65,170.41],[1,3.65,0]],"ltp":2.58,"tv":99.95,"id":2397396},{"batb":[[1,1.01,15.51],[2,1.01,0]],"ltp":1.63,"tv":514.54,"id":8979329}]}]}
{"op":"mcm","clk":"1009481360","pt":1580644744128,"mc":[{"id":"1.168224343","rc":[{"batb":[[1,1.53,255.37],[2,1.52,165.48]],"batl":[[0,1.67,186.13],[1,1.69,222.63],[2,1.95,409.86]],"ltp":1.63,"tv":514.54,"id":8979329}]}]}
{"op":"mcm","clk":"1009481703","pt":1580644747270,"mc":[{"id":"1.168224343","rc":[{"batb":[[1,1.01,15.51],[2,1.52,0]],"ltp":1.63,"tv":514.54,"id":8979329}]}]}
{"op":"mcm","clk":"1009482079","pt":1580644750393,"mc":[{"id":"1.168224343","rc":[{"batb":[[1,2.04,26.44],[2,1.01,15.52]],"ltp":2.58,"tv":99.95,"id":2397396},{"batb":[[0,1.64,28.56],[1,1.61,161.25],[2,1.6,135.45]],"ltp":1.63,"tv":514.54,"id":8979329}]}]}
{"op":"mcm","clk":"1009482150","pt":1580644750973,"mc":[{"id":"1.168224343","rc":[{"batl":[[0,2.86,21.85]],"ltp":2.58,"tv":99.95,"id":2397396}]}]}
{"op":"mcm","clk":"1009482273","pt":1580644752173,"mc":[{"id":"1.168224343","rc":[{"batl":[[1,3.45,180.4]],"ltp":2.58,"tv":99.95,"id":2397396}]}]}
{"op":"mcm","clk":"1009493049","pt":1580644838275,"mc":[{"id":"1.168224343","rc":[{"batb":[[0,2.04,26.44],[1,1.01,15.52],[2,1.01,0]],"batl":[[0,3.45,180.4],[1,3.45,0]],"ltp":2.58,"tv":99.95,"id":2397396},{"batb":[[0,1.55,34.93],[1,1.01,15.51],[2,1.6,0]],"batl":[[0,1.95,409.86],[1,1.69,0],[2,1.95,0]],"ltp":1.63,"tv":514.54,"id":8979329}]}]}
{"op":"mcm","clk":"1009493533","pt":1580644842283,"mc":[{"id":"1.168224343","rc":[{"batb":[[0,1.65,163.67],[1,1.64,123.72],[2,1.55,34.93]],"batl":[[0,1.71,134.01],[1,1.73,205.89]],"ltp":1.63,"tv":514.54,"id":8979329}]}]}
{"op":"mcm","clk":"1009493897","pt":1580644844798,"mc":[{"id":"1.168224343","rc":[{"batl":[[0,3.3,191.92]],"ltp":2.58,"tv":99.95,"id":2397396},{"batl":[[2,2.16,342.82]],"ltp":1.63,"tv":514.54,"id":8979329}]}]}
{"op":"mcm","clk":"1009494055","pt":1580644845910,"mc":[{"id":"1.168224343","rc":[{"batb":[[0,1.55,34.93],[1,1.01,15.51],[2,1.55,0]],"batl":[[0,2.16,342.82],[1,1.73,0],[2,2.16,0]],"ltp":1.63,"tv":514.54,"id":8979329}]}]}
{"op":"mcm","clk":"1009494470","pt":1580644848876,"mc":[{"id":"1.168224343","rc":[{"batb":[[1,1.52,146.83],[2,1.51,169.37]],"batl":[[0,1.92,169.61],[1,1.94,142.91],[2,2.16,342.82]],"ltp":1.63,"tv":514.54,"id":8979329}]}]}
{"op":"mcm","clk":"1009494978","pt":1580644852295,"mc":[{"id":"1.168224343","rc":[{"batl":[[0,2.16,342.82],[1,1.94,0],[2,2.16,0]],"ltp":1.63,"tv":514.54,"id":8979329}]}]}
{"op":"mcm","clk":"1009495405","pt":1580644855207,"mc":[{"id":"1.168224343","rc":[{"batl":[[0,3.15,19.32]],"ltp":2.58,"tv":99.95,"id":2397396},{"batl":[[0,1.57,204.72],[1,1.58,140.37]],"ltp":1.63,"tv":514.54,"id":8979329}]}]}
{"op":"mcm","clk":"1009495477","pt":1580644855725,"mc":[{"id":"1.168224343","rc":[{"batb":[[0,2.64,12.83],[1,2.28,18.96],[2,1.01,15.52]],"ltp":2.58,"tv":99.95,"id":2397396}]}]}
{"op":"mcm","clk":"1009495682","pt":1580644857218,"mc":[{"id":"1.168224343","rc":[{"batl":[[1,3.9,158.24]],"ltp":2.58,"tv":99.95,"id":2397396},{"batl":[[2,1.95,409.86]],"ltp":1.63,"tv":514.54,"id":8979329}]}]}
{"op":"mcm","clk":"1009497301","pt":1580644869229,"mc":[{"id":"1.168224343","rc":[{"batb":[[1,1.49,40.76],[2,1.47,89.06]],"batl":[[0,1.95,409.86],[1,1.58,0],[2,1.95,0]],"ltp":1.63,"tv":514.54,"id":8979329}]}]}
{"op":"mcm","clk":"1009497392","pt":1580644870017,"mc":[{"id":"1.168224343","rc":[{"batb":[[0,2.28,18.96],[1,1.01,15.52],[2,1.01,0]],"batl":[[0,3.9,158.24],[1,3.9,0]],"ltp":2.58,"tv":99.95,"id":2397396},{"batb":[[0,1.49,40.76],[1,1.01,15.51],[2,1.47,0]],"ltp":1.63,"tv":514.54,"id":8979329}]}]}
{"op":"mcm","clk":"1009497690","pt":1580644872345,"mc":[{"id":"1.168224343","rc":[{"batb":[[1,1.46,159.44],[2,1.45,200.46]],"batl":[[0,1.72,130.51],[1,1.74,201.99],[2,1.95,409.86]],"ltp":1.63,"tv":514.54,"id":8979329}]}]}
{"op":"mcm","clk":"1009497764","pt":1580644872926,"mc":[{"id":"1.168224343","rc":[{"batb":[[0,2.3,18.73]],"ltp":2.58,"tv":99.95,"id":2397396},{"batb":[[1,1.01,15.51],[2,1.45,0]],"batl":[[0,1.95,409.86],[1,1.74,0],[2,1.95,0]],"ltp":1.63,"tv":514.54,"id":8979329}]}]}
{"op":"mcm","clk":"1009498194","pt":1580644876348,"mc":[{"id":"1.168224343","rc":[{"batb":[[0,1.54,243.17],[1,1.53,161.22],[2,1.49,40.76]],"batl":[[0,1.6,217.06],[1,1.61,131.02],[2,1.95,409.86]],"ltp":1.63,"tv":514.54,"id":8979329}]}]}
{"op":"mcm","clk":"1009498257","pt":1580644876831,"mc":[{"id":"1.168224343","rc":[{"batb":[[0,1.49,40.76],[1,1.01,15.51],[2,1.49,0]],"batl":[[0,1.95,409.86],[1,1.61,0],[2,1.95,0]],"ltp":1.63,"tv":514.54,"id":8979329}]}]}
{"op":"mcm","clk":"1009498606","pt":1580644879824,"mc":[{"id":"1.168224343","rc":[{"batb":[[1,1.46,159.44],[2,1.45,200.46]],"batl":[[0,1.72,130.51],[1,1.74,201.99],[2,1.95,409.86]],"ltp":1.63,"tv":514.54,"id":8979329}]}]}
{"op":"mcm","clk":"1009501054","pt":1580644897851,"mc":[{"id":"1.168224343","rc":[{"batb":[[1,1.01,15.51],[2,1.45,0]],"ltp":1.63,"tv":514.54,"id":8979329}]}]}
{"op":"mcm","clk":"1009501384","pt":1580644900389,"mc":[{"id":"1.168224343","rc":[{"batl":[[2,1.95,0]],"ltp":1.63,"tv":514.54,"id":8979329}]}]}
{"op":"mcm","clk":"1009501538","pt":1580644901391,"mc":[{"id":"1.168224343","rc":[{"batb":[[1,1.87,17.23],[2,1.01,15.52]],"batl":[[0,2.76,23.53]],"ltp":2.58,"tv":99.95,"id":2397396},{"batb":[[0,1.7,25.26],[1,1.66,155.48],[2,1.65,121.02]],"ltp":1.63,"tv":514.54,"id":8979329}]}]}
{"op":"mcm","clk":"1009501847","pt":1580644903455,"mc":[{"id":"1.168224343","rc":[{"batl":[[0,3.3,191.92]],"ltp":2.58,"tv":99.95,"id":2397396},{"batl":[[2,2.16,342.82]],"ltp":1.63,"tv":514.54,"id":8979329}]}]}
{"op":"mcm","clk":"1009502007","pt":1580644904565,"mc":[{"id":"1.168224343","rc":[{"batl":[[0,2.74,23.53],[1,3.3,191.92]],"ltp":2.58,"tv":99.95,"id":2397396},{"trd":[[1.7,50.41]],"batb":[[0,1.66,155.53],[1,1.65,121.02],[2,1.57,106.22]],"ltp":1.7,"tv":564.95,"id":8979329}],"tv":664.91}]}
{"op":"mcm","clk":"1009504081","pt":1580644918085,"mc":[{"id":"1.168224343","rc":[{"batb":[[0,1.87,17.23],[1,1.01,15.52],[2,1.01,0]],"batl":[[0,3.3,191.92],[1,3.3,0]],"ltp":2.58,"tv":99.95,"id":2397396},{"batb":[[0,1.57,33.13],[1,1.01,15.51],[2,1.57,0]],"batl":[[0,2.16,342.82],[1,1.74,0],[2,2.16,0]],"ltp":1.7,"tv":564.95,"id":8979329}]}]}
{"op":"mcm","clk":"1009504610","pt":1580644921175,"mc":[{"id":"1.168224343","rc":[{"batb":[[0,1.89,16.92]],"ltp":2.58,"tv":99.95,"id":2397396},{"batb":[[0,1.55,33.83],[1,1.53,236.74],[2,1.52,165.46]],"batl":[[0,2.08,105.43],[1,2.1,113.04],[2,2.16,342.82]],"ltp":1.7,"tv":564.95,"id":8979329}]}]}
{"op":"mcm","clk":"1009504919","pt":1580644923209,"mc":[{"id":"1.168224343","rc":[{"batl":[[0,2.16,342.82],[1,2.1,0],[2,2.16,0]],"ltp":1.7,"tv":564.95,"id":8979329}]}]}
{"op":"mcm","clk":"1009505369","pt":1580644926180,"mc":[{"id":"1.168224343","rc":[{"batl":[[0,1.59,241.26],[1,1.6,133.91]],"ltp":1.7,"tv":564.95,"id":8979329}]}]}
{"op":"mcm","clk":"1009505498","pt":1580644926971,"mc":[{"id":"1.168224343","rc":[{"batb":[[0,2.6,13.38],[1,2.2,21.32],[2,1.01,15.52]],"batl":[[0,3.1,19.32]],"ltp":2.58,"tv":99.95,"id":2397396}]}]}
{"op":"mcm","clk":"1009505735","pt":1580644928626,"mc":[{"id":"1.168224343","rc":[{"batl":[[1,3.9,158.24]],"ltp":2.58,"tv":99.95,"id":2397396},{"batl":[[2,1.95,409.86]],"ltp":1.7,"tv":564.95,"id":8979329}]}]}
{"op":"mcm","clk":"1009507232","pt":1580644938306,"mc":[{"id":"1.168224343","rc":[{"batb":[[1,1.48,128.06],[2,1.01,15.51]],"batl":[[0,1.95,409.86],[1,1.6,0],[2,1.95,0]],"ltp":1.7,"tv":564.95,"id":8979329}]}]}
{"op":"mcm","clk":"1009507340","pt":1580644939001,"mc":[{"id":"1.168224343","rc":[{"batb":[[0,2.2,21.32],[1,1.01,15.52],[2,1.01,0]],"ltp":2.58,"tv":99.95,"id":2397396},{"batb":[[0,1.48,128.06],[1,1.01,15.51],[2,1.01,0]],"ltp":1.7,"tv":564.95,"id":8979329}]}]}
{"op":"mcm","clk":"1009507495","pt":1580644940065,"mc":[{"id":"1.168224343","rc":[{"batl":[[0,3.9,158.24],[1,3.9,0]],"ltp":2.58,"tv":99.95,"id":2397396},{"batb":[[0,1.48,40.68]],"ltp":1.7,"tv":564.95,"id":8979329}]}]}
{"op":"mcm","clk":"1009507659","pt":1580644941220,"mc":[{"id":"1.168224343","rc":[{"batb":[[1,1.46,143.99],[2,1.45,200.38]],"batl":[[0,1.79,189.59],[1,1.81,177.38],[2,1.95,409.86]],"ltp":1.7,"tv":564.95,"id":8979329}]}]}
{"op":"mcm","clk":"1009507746","pt":1580644941805,"mc":[{"id":"1.168224343","rc":[{"batl":[[0,1.95,409.86],[1,1.81,0],[2,1.95,0]],"ltp":1.7,"tv":564.95,"id":8979329}]}]}
{"op":"mcm","clk":"1009508239","pt":1580644945306,"mc":[{"id":"1.168224343","rc":[{"batl":[[0,1.51,167.15],[1,1.95,409.86]],"ltp":1.7,"tv":564.95,"id":8979329}]}]}
{"op":"mcm","clk":"1009508276","pt":1580644945621,"mc":[{"id":"1.168224343","rc":[{"batb":[[0,2.84,10.7],[1,2.58,13.77],[2,1.01,15.52]],"ltp":2.58,"tv":99.95,"id":2397396},{"batb":[[2,1.45,245.07]],"ltp":1.7,"tv":564.95,"id":8979329}]}]}
{"op":"mcm","clk":"1009508454","pt":1580644946997,"mc":[{"id":"1.168224343","rc":[{"batl":[[0,3.4,16.8],[1,3.9,158.24]],"ltp":2.58,"tv":99.95,"id":2397396}]}]}
{"op":"mcm","clk":"1009508613","pt":1580644948003,"mc":[{"id":"1.168224343","rc":[{"batb":[[1,1.46,169.59]],"batl":[[0,1.51,292.81],[1,1.52,161.84],[2,1.95,409.86]],"ltp":1.7,"tv":564.95,"id":8979329}]}]}
{"op":"mcm","clk":"1009509783","pt":1580644956231,"mc":[{"id":"1.168224343","rc":[{"batb":[[1,1.45,44.69],[2,1.42,99.98]],"batl":[[0,1.95,409.86],[1,1.52,0],[2,1.95,0]],"ltp":1.7,"tv":564.95,"id":8979329}]}]}
{"op":"mcm","clk":"1009509819","pt":1580644956439,"mc":[{"id":"1.168224343","rc":[{"batb":[[0,2.58,13.77],[1,1.01,15.52],[2,1.01,0]],"ltp":2.58,"tv":99.95,"id":2397396},{"batb":[[0,1.45,44.69],[1,1.42,99.98],[2,1.01,15.51]],"ltp":1.7,"tv":564.95,"id":8979329}]}]}
{"op":"mcm","clk":"1009510065","pt":1580644958160,"mc":[{"id":"1.168224343","rc":[{"batl":[[0,3.9,158.24],[1,3.9,0]],"ltp":2.58,"tv":99.95,"id":2397396},{"batb":[[1,1.01,15.51],[2,1.01,0]],"ltp":1.7,"tv":564.95,"id":8979329}]}]}
{"op":"mcm","clk":"1009510166","pt":1580644958846,"mc":[{"id":"1.168224343","rc":[{"batb":[[1,1.43,142.12],[2,1.42,219.26]],"batl":[[0,1.58,159.61],[1,1.59,137.29],[2,1.95,409.86]],"ltp":1.7,"tv":564.95,"id":8979329}]}]}
{"op":"mcm","clk":"1009510353","pt":1580644960073,"mc":[{"id":"1.168224343","rc":[{"batl":[[0,1.95,409.86],[1,1.59,0],[2,1.95,0]],"ltp":1.7,"tv":564.95,"id":8979329}]}]}
{"op":"mcm","clk":"1009510796","pt":1580644963243,"mc":[{"id":"1.168224343","rc":[{"batl":[[0,1.47,206.74],[1,1.48,180.48]],"ltp":1.7,"tv":564.95,"id":8979329}]}]}
{"op":"mcm","clk":"1009510899","pt":1580644964014,"mc":[{"id":"1.168224343","rc":[{"batb":[[0,2.96,24],[1,2.64,12.98],[2,1.01,15.52]],"ltp":2.58,"tv":99.95,"id":2397396}]}]}
{"op":"mcm","clk":"1009511034","pt":1580644965030,"mc":[{"id":"1.168224343","rc":[{"batl":[[0,3.6,15.96]],"ltp":2.58,"tv":99.95,"id":2397396}]}]}
{"op":"mcm","clk":"1009511157","pt":1580644965828,"mc":[{"id":"1.168224343","rc":[{"batl":[[1,4.6,136.05]],"ltp":2.58,"tv":99.95,"id":2397396},{"batl":[[2,1.82,469.11]],"ltp":1.7,"tv":564.95,"id":8979329}]}]}
{"op":"mcm","clk":"1009512846","pt":1580644977261,"mc":[{"id":"1.168224343","rc":[{"trd":[[1.45,50.41]],"batb":[[0,1.45,19.48]],"ltp":1.45,"tv":615.37,"id":8979329}],"tv":715.33}]}
{"op":"mcm","clk":"1009514200","pt":1580644987191,"mc":[{"id":"1.168224343","rc":[{"batb":[[1,1.39,107.54],[2,1.32,68.53]],"batl":[[0,1.82,469.11],[1,1.48,0],[2,1.82,0]],"ltp":1.45,"tv":615.37,"id":8979329}]}]}
{"op":"mcm","clk":"1009514330","pt":1580644988048,"mc":[{"id":"1.168224343","rc":[{"batb":[[0,2.64,12.98],[1,1.01,15.52],[2,1.01,0]],"batl":[[0,4.6,136.05],[1,4.6,0]],"ltp":2.58,"tv":99.95,"id":2397396},{"batb":[[0,1.32,68.53],[1,1.01,15.51],[2,1.32,0]],"ltp":1.45,"tv":615.37,"id":8979329}]}]}
{"op":"mcm","clk":"1009514601","pt":1580644990083,"mc":[{"id":"1.168224343","rc":[{"batb":[[1,1.3,466.83],[2,1.29,357.15]],"batl":[[0,1.58,158.79],[1,1.59,137.21],[2,1.82,469.11]],"ltp":1.45,"tv":615.37,"id":8979329}]}]}
{"op":"mcm","clk":"1009514792","pt":1580644991268,"mc":[{"id":"1.168224343","rc":[{"batb":[[0,2.68,12.75]],"ltp":2.58,"tv":99.95,"id":2397396},{"batb":[[0,1.31,69.63]],"ltp":1.45,"tv":615.37,"id":8979329}]}]}
{"op":"mcm","clk":"1009515024","pt":1580644992870,"mc":[{"id":"1.168224343","rc":[{"batb":[[1,1.01,15.51],[2,1.29,0]],"ltp":1.45,"tv":615.37,"id":8979329}]}]}
{"op":"mcm","clk":"1009515556","pt":1580644996281,"mc":[{"id":"1.168224343","rc":[{"batb":[[1,2.46,16.05],[2,1.01,15.52]],"ltp":2.58,"tv":99.95,"id":2397396},{"batb":[[0,1.54,35.25],[1,1.53,178.01],[2,1.52,164.95]],"ltp":1.45,"tv":615.37,"id":8979329}]}]}
{"op":"mcm","clk":"1009515670","pt":1580644996978,"mc":[{"id":"1.168224343","rc":[{"batl":[[0,3.1,19.32]],"ltp":2.58,"tv":99.95,"id":2397396}]}]}
{"op":"mcm","clk":"1009515899","pt":1580644998455,"mc":[{"id":"1.168224343","rc":[{"batl":[[1,3.9,158.24]],"ltp":2.58,"tv":99.95,"id":2397396}]}]}
{"op":"mcm","clk":"1009517821","pt":1580645011065,"mc":[{"id":"1.168224343","rc":[{"batb":[[0,2.46,16.05],[1,1.01,15.52],[2,1.01,0]],"ltp":2.58,"tv":99.95,"id":2397396},{"batb":[[0,1.47,89.06],[1,1.41,49.25],[2,1.01,15.51]],"batl":[[0,1.82,469.11],[1,1.59,0],[2,1.82,0]],"ltp":1.45,"tv":615.37,"id":8979329}]}]}
{"op":"mcm","clk":"1009517991","pt":1580645012084,"mc":[{"id":"1.168224343","rc":[{"batl":[[0,3.9,158.24],[1,3.9,0]],"ltp":2.58,"tv":99.95,"id":2397396},{"batb":[[0,1.41,49.25],[1,1.01,15.51],[2,1.01,0]],"ltp":1.45,"tv":615.37,"id":8979329}]}]}
{"op":"mcm","clk":"1009518767","pt":1580645017089,"mc":[{"id":"1.168224343","rc":[{"batb":[[0,1.5,258.73],[1,1.49,179.29],[2,1.41,49.25]],"batl":[[0,1.55,132.05],[1,1.56,147.39],[2,1.82,469.11]],"ltp":1.45,"tv":615.37,"id":8979329}]}]}
{"op":"mcm","clk":"1009519166","pt":1580645019473,"mc":[{"id":"1.168224343","rc":[{"batb":[[0,1.41,49.25],[1,1.01,15.51],[2,1.41,0]],"batl":[[0,1.82,469.11],[1,1.56,0],[2,1.82,0]],"ltp":1.45,"tv":615.37,"id":8979329}]}]}
{"op":"mcm","clk":"1009519636","pt":1580645022502,"mc":[{"id":"1.168224343","rc":[{"batb":[[0,1.41,250.03],[1,1.4,234.18],[2,1.01,15.51]],"batl":[[0,1.69,183.33],[1,1.71,213.64],[2,1.82,469.11]],"ltp":1.45,"tv":615.37,"id":8979329}]}]}
{"op":"mcm","clk":"1009520399","pt":1580645027386,"mc":[{"id":"1.168224343","rc":[{"batb":[[0,1.41,49.25],[1,1.01,15.51],[2,1.01,0]],"ltp":1.45,"tv":615.37,"id":8979329}]}]}
{"op":"mcm","clk":"1009520615","pt":1580645028825,"mc":[{"id":"1.168224343","rc":[{"batl":[[2,1.82,0]],"ltp":1.45,"tv":615.37,"id":8979329}]}]}
{"op":"mcm","clk":"1009520832","pt":1580645030305,"mc":[{"id":"1.168224343","rc":[{"batb":[[0,1.63,136.25],[1,1.62,129.17],[2,1.41,49.25]],"ltp":1.45,"tv":615.37,"id":8979329}]}]}
{"op":"mcm","clk":"1009521021","pt":1580645031399,"mc":[{"id":"1.168224343","rc":[{"batb":[[1,2.3,18.88],[2,1.01,15.52]],"batl":[[0,2.82,22.69]],"ltp":2.58,"tv":99.95,"id":2397396},{"batb":[[1,1.62,158.05],[2,1.55,75.62]],"ltp":1.45,"tv":615.37,"id":8979329}]}]}
{"op":"mcm","clk":"1009521206","pt":1580645032629,"mc":[{"id":"1.168224343","rc":[{"batl":[[1,3.45,180.4]],"ltp":2.58,"tv":99.95,"id":2397396},{"batl":[[2,2.1,363.31]],"ltp":1.45,"tv":615.37,"id":8979329}]}]}
{"op":"mcm","clk":"1009523404","pt":1580645047396,"mc":[{"id":"1.168224343","rc":[{"batb":[[0,2.3,18.88],[1,1.01,15.52],[2,1.01,0]],"ltp":2.58,"tv":99.95,"id":2397396},{"batb":[[0,1.55,75.62],[1,1.52,36.43],[2,1.01,15.51]],"batl":[[0,2.1,363.31],[1,1.71,0],[2,2.1,0]],"ltp":1.45,"tv":615.37,"id":8979329}]}]}
{"op":"mcm","clk":"1009523492","pt":1580645048027,"mc":[{"id":"1.168224343","rc":[{"batl":[[0,3.45,180.4],[1,3.45,0]],"ltp":2.58,"tv":99.95,"id":2397396},{"batb":[[0,1.52,36.43],[1,1.01,15.51],[2,1.01,0]],"ltp":1.45,"tv":615.37,"id":8979329}]}]}
{"op":"mcm","clk":"1009523694","pt":1580645049734,"mc":[{"id":"1.168224343","rc":[{"batb":[[0,1.53,205.03],[1,1.52,201.5],[2,1.01,15.51]],"batl":[[0,1.77,163.05],[1,1.79,183.76],[2,2.1,363.31]],"ltp":1.45,"tv":615.37,"id":8979329}]}]}
{"op":"mcm","clk":"1009523972","pt":1580645051918,"mc":[{"id":"1.168224343","rc":[{"batl":[[0,2.1,363.31],[1,1.79,0],[2,2.1,0]],"ltp":1.45,"tv":615.37,"id":8979329}]}]}
{"op":"mcm","clk":"1009524336","pt":1580645055044,"mc":[{"id":"1.168224343","rc":[{"batl":[[0,3.1,19.32]],"ltp":2.58,"tv":99.95,"id":2397396},{"batb":[[2,1.48,87.38]],"batl":[[0,1.58,133.21],[1,1.59,137.31]],"ltp":1.45,"tv":615.37,"id":8979329}]}]}
{"op":"mcm","clk":"1009524485","pt":1580645056220,"mc":[{"id":"1.168224343","rc":[{"batb":[[0,2.72,12.2],[1,2.44,16.29],[2,1.01,15.52]],"ltp":2.58,"tv":99.95,"id":2397396}]}]}
{"op":"mcm","clk":"1009524680","pt":1580645057725,"mc":[{"id":"1.168224343","rc":[{"batl":[[1,3.9,158.24]],"ltp":2.58,"tv":99.95,"id":2397396},{"batl":[[2,1.95,409.86]],"ltp":1.45,"tv":615.37,"id":8979329}]}]}
{"op":"mcm","clk":"1009526702","pt":1580645073143,"mc":[{"id":"1.168224343","rc":[{"batb":[[0,1.52,36.43],[1,1.48,87.38],[2,1.39,53.74]],"batl":[[0,1.95,409.86],[1,1.59,0],[2,1.95,0]],"ltp":1.45,"tv":615.37,"id":8979329}]}]}
{"op":"mcm","clk":"1009526803","pt":1580645074036,"mc":[{"id":"1.168224343","rc":[{"batb":[[0,2.44,16.29],[1,1.01,15.52],[2,1.01,0]],"batl":[[0,3.9,158.24],[1,3.9,0]],"ltp":2.58,"tv":99.95,"id":2397396},{"batb":[[0,1.39,53.74],[1,1.01,15.51],[2,1.39,0]],"ltp":1.45,"tv":615.37,"id":8979329}]}]}
{"op":"mcm","clk":"1009527042","pt":1580645075847,"mc":[{"id":"1.168224343","rc":[{"batb":[[0,1.39,310.73],[1,1.38,250.9],[2,1.01,15.51]],"batl":[[0,1.71,139.12],[1,1.73,205.65],[2,1.95,409.86]],"ltp":1.45,"tv":615.37,"id":8979329}]}]}
{"op":"mcm","clk":"1009527275","pt":1580645077637,"mc":[{"id":"1.168224343","rc":[{"batb":[[0,1.39,53.74],[1,1.01,15.51],[2,1.01,0]],"batl":[[0,1.95,409.86],[1,1.73,0],[2,1.95,0]],"ltp":1.45,"tv":615.37,"id":8979329}]}]}
{"op":"mcm","clk":"1009527723","pt":1580645081038,"mc":[{"id":"1.168224343","rc":[{"batb":[[0,1.5,209.02],[1,1.49,178.96],[2,1.39,53.74]],"batl":[[0,1.55,178.7],[1,1.56,147.13],[2,1.95,409.86]],"ltp":1.45,"tv":615.37,"id":8979329}]}]}
{"op":"mcm","clk":"1009527855","pt":1580645082162,"mc":[{"id":"1.168224343","rc":[{"batb":[[0,1.39,53.74],[1,1.01,15.51],[2,1.39,0]],"batl":[[0,1.95,409.86],[1,1.56,0],[2,1.95,0]],"ltp":1.45,"tv":615.37,"id":8979329}]}]}
{"op":"mcm","clk":"1009528269","pt":1580645085153,"mc":[{"id":"1.168224343","rc":[{"batb":[[0,1.39,310.73],[1,1.38,250.9],[2,1.01,15.51]],"batl":[[0,1.71,139.12],[1,1.73,205.65],[2,1.95,409.86]],"ltp":1.45,"tv":615.37,"id":8979329}]}]}
{"op":"mcm","clk":"1009528337","pt":1580645085681,"mc":[{"id":"1.168224343","rc":[{"batb":[[0,1.39,53.74],[1,1.01,15.51],[2,1.01,0]],"batl":[[0,1.95,409.86],[1,1.73,0],[2,1.95,0]],"ltp":1.45,"tv":615.37,"id":8979329}]}]}
{"op":"mcm","clk":"1009528881","pt":1580645089381,"mc":[{"id":"1.168224343","rc":[{"batb":[[0,3.25,18.88],[1,2.68,12.83],[2,1.01,15.52]],"batl":[[0,3.8,14.28]],"ltp":2.58,"tv":99.95,"id":2397396},{"batb":[[0,1.39,310.73],[1,1.38,250.9],[2,1.36,115.95]],"batl":[[0,1.43,185.97],[1,1.44,202.22]],"ltp":1.45,"tv":615.37,"id":8979329}]}]}
{"op":"mcm","clk":"1009529268","pt":1580645092059,"mc":[{"id":"1.168224343","rc":[{"batl":[[1,4.9,126.27]],"ltp":2.58,"tv":99.95,"id":2397396},{"batl":[[2,1.77,500.61]],"ltp":1.45,"tv":615.37,"id":8979329}]}]}
{"op":"mcm","clk":"1009531057","pt":1580645105290,"mc":[{"id":"1.168224343","rc":[{"batb":[[0,1.39,53.74],[1,1.36,115.95],[2,1.21,112.28]],"batl":[[0,1.77,500.61],[1,1.44,0],[2,1.77,0]],"ltp":1.45,"tv":615.37,"id":8979329}]}]}
{"op":"mcm","clk":"1009531203","pt":1580645106111,"mc":[{"id":"1.168224343","rc":[{"batb":[[0,2.68,12.83],[1,1.01,15.52],[2,1.01,0]],"batl":[[0,4.9,126.27],[1,4.9,0]],"ltp":2.58,"tv":99.95,"id":2397396},{"batb":[[0,1.21,112.28],[1,1.01,15.51],[2,1.21,0]],"ltp":1.45,"tv":615.37,"id":8979329}]}]}
{"op":"mcm","clk":"1009531540","pt":1580645108203,"mc":[{"id":"1.168224343","rc":[{"batb":[[0,1.21,774.36],[1,1.2,406.02],[2,1.01,15.51]],"batl":[[0,1.61,169.75],[1,1.62,128.16],[2,1.77,500.61]],"ltp":1.45,"tv":615.37,"id":8979329}]}]}
{"op":"mcm","clk":"1009532150","pt":1580645112307,"mc":[{"id":"1.168224343","rc":[{"batl":[[0,1.77,500.61],[1,1.62,0],[2,1.77,0]],"ltp":1.45,"tv":615.37,"id":8979329}]}]}
{"op":"mcm","clk":"1009532594","pt":1580645115308,"mc":[{"id":"1.168224343","rc":[{"trd":[[4.9,126.27]],"ltp":4.9,"tv":226.23,"id":2397396},{"trd":[[1.25,548.03]],"batl":[[0,1.25,160.97],[1,1.77,500.61]],"ltp":1.25,"tv":1110.36,"id":8979329}],"tv":1336.59}]}
{"op":"mcm","clk":"1009532723","pt":1580645116117,"mc":[{"id":"1.168224343","rc":[{"batb":[[0,5,13.45],[1,3.3,18.33],[2,1.01,15.52]],"ltp":4.9,"tv":226.23,"id":2397396},{"batb":[[0,1.21,631.74],[1,1.02,797.52]],"batl":[[1,1.77,0]],"ltp":1.25,"tv":1110.36,"id":8979329}]}]}
{"op":"mcm","clk":"1009532879","pt":1580645117334,"mc":[{"id":"1.168224343","rc":[{"batl":[[0,5.8,8.4]],"ltp":4.9,"tv":226.23,"id":2397396},{"batl":[[0,1.25,198.83]],"ltp":1.25,"tv":1110.36,"id":8979329}]}]}
{"op":"mcm","clk":"1009532911","pt":1580645117552,"mc":[{"id":"1.168224343","rc":[{"batl":[[0,1.25,160.97]],"ltp":1.25,"tv":1110.36,"id":8979329}]}]}
{"op":"mcm","clk":"1009533175","pt":1580645119209,"mc":[{"id":"1.168224343","rc":[{"batb":[[0,1.22,327.52],[1,1.21,631.74],[2,1.2,168.04]],"batl":[[0,1.25,472.76],[1,1.26,378.34],[2,1.56,675.59]],"ltp":1.25,"tv":1110.36,"id":8979329}]}]}
{"op":"mcm","clk":"1009533419","pt":1580645121022,"mc":[{"id":"1.168224343","rc":[{"batl":[[1,7.8,6.93]],"ltp":4.9,"tv":226.23,"id":2397396}]}]}
{"op":"mcm","clk":"1009534858","pt":1580645131229,"mc":[{"id":"1.168224343","rc":[{"batb":[[0,5,23.54]],"ltp":4.9,"tv":226.23,"id":2397396},{"batl":[[0,1.25,514.77]],"ltp":1.25,"tv":1110.36,"id":8979329}]}]}
{"op":"mcm","clk":"1009535432","pt":1580645135350,"mc":[{"id":"1.168224343","rc":[{"batb":[[0,1.21,112.28],[1,1.2,168.04],[2,1.02,797.52]],"batl":[[0,1.25,42.01],[1,1.56,675.59],[2,1.56,0]],"ltp":1.25,"tv":1110.36,"id":8979329}]}]}
{"op":"mcm","clk":"1009535562","pt":1580645136149,"mc":[{"id":"1.168224343","rc":[{"batb":[[0,3.3,18.33],[1,1.01,15.52],[2,1.01,0]],"batl":[[0,7.8,6.93],[1,7.8,0]],"ltp":4.9,"tv":226.23,"id":2397396},{"batb":[[0,1.02,797.52],[1,1.01,15.51],[2,1.02,0]],"batl":[[0,1.56,675.59],[1,1.56,0]],"ltp":1.25,"tv":1110.36,"id":8979329}]}]}
{"op":"mcm","clk":"1009535819","pt":1580645138080,"mc":[{"id":"1.168224343","rc":[{"batb":[[0,1.04,1238.8],[1,1.02,797.52],[2,1.01,15.51]],"batl":[[0,1.44,307.65],[1,1.45,193.55]],"ltp":1.25,"tv":1110.36,"id":8979329}]}]}
{"op":"mcm","clk":"1009536230","pt":1580645141054,"mc":[{"id":"1.168224343","rc":[{"batb":[[0,1.02,797.52],[1,1.01,15.51],[2,1.01,0]],"ltp":1.25,"tv":1110.36,"id":8979329}]}]}
{"op":"mcm","clk":"1009536672","pt":1580645144345,"mc":[{"id":"1.168224343","rc":[{"batb":[[1,2.7,12.43],[2,1.01,15.52]],"ltp":4.9,"tv":226.23,"id":2397396},{"batb":[[0,1.39,293.62],[1,1.38,304.59],[2,1.2,114.4]],"batl":[[0,1.44,201.13],[1,1.45,0]],"ltp":1.25,"tv":1110.36,"id":8979329}]}]}
{"op":"mcm","clk":"1009536778","pt":1580645145033,"mc":[{"id":"1.168224343","rc":[{"batb":[[0,3.3,35.98]],"batl":[[0,3.8,14.28]],"ltp":4.9,"tv":226.23,"id":2397396},{"batb":[[2,1.36,115.95]],"ltp":1.25,"tv":1110.36,"id":8979329}]}]}
{"op":"mcm","clk":"1009537107","pt":1580645147338,"mc":[{"id":"1.168224343","rc":[{"batl":[[0,1.43,145.64],[1,1.44,201.13],[2,1.77,848.96]],"ltp":1.25,"tv":1110.36,"id":8979329}]}]}
{"op":"mcm","clk":"1009538792","pt":1580645159367,"mc":[{"id":"1.168224343","rc":[{"batb":[[0,1.38,55],[1,1.36,115.95],[2,1.2,114.4]],"batl":[[0,1.77,848.96],[1,1.44,0],[2,1.77,0]],"ltp":1.25,"tv":1110.36,"id":8979329}]}]}
{"op":"mcm","clk":"1009538893","pt":1580645160174,"mc":[{"id":"1.168224343","rc":[{"batb":[[0,2.7,12.43],[1,1.01,15.52],[2,1.01,0]],"ltp":4.9,"tv":226.23,"id":2397396},{"batb":[[0,1.2,114.4],[1,1.01,15.51],[2,1.2,0]],"ltp":1.25,"tv":1110.36,"id":8979329}]}]}
{"op":"mcm","clk":"1009539154","pt":1580645162287,"mc":[{"id":"1.168224343","rc":[{"batb":[[0,1.22,163.08],[1,1.21,515.97],[2,1.2,114.4]],"batl":[[0,1.61,130.07],[1,1.62,127.58],[2,1.77,848.96]],"ltp":1.25,"tv":1110.36,"id":8979329}]}]}
{"op":"mcm","clk":"1009539807","pt":1580645167376,"mc":[{"id":"1.168224343","rc":[{"batl":[[0,1.77,848.96],[1,1.62,0],[2,1.77,0]],"ltp":1.25,"tv":1110.36,"id":8979329}]}]}
{"op":"mcm","clk":"1009540203","pt":1580645170284,"mc":[{"id":"1.168224343","rc":[{"batl":[[0,1.24,222.47],[1,1.25,403.85]],"ltp":1.25,"tv":1110.36,"id":8979329}]}]}
{"op":"mcm","clk":"1009540374","pt":1580645171295,"mc":[{"id":"1.168224343","rc":[{"batb":[[0,5.1,13.06],[1,3.35,17.55],[2,2.7,12.43]],"batl":[[0,5.9,8.4]],"ltp":4.9,"tv":226.23,"id":2397396},{"batb":[[2,1.2,282.44]],"ltp":1.25,"tv":1110.36,"id":8979329}]}]}
{"op":"mcm","clk":"1009540406","pt":1580645171505,"mc":[{"id":"1.168224343","rc":[{"batb":[[2,1.01,15.52]],"ltp":4.9,"tv":226.23,"id":2397396}]}]}
{"op":"mcm","clk":"1009540577","pt":1580645172918,"mc":[{"id":"1.168224343","rc":[{"batb":[[1,5,10.08],[2,3.35,17.55]],"batl":[[1,7.8,6.93]],"ltp":4.9,"tv":226.23,"id":2397396},{"batl":[[1,1.25,445.86]],"ltp":1.25,"tv":1110.36,"id":8979329}]}]}
{"op":"mcm","clk":"1009540687","pt":1580645173607,"mc":[{"id":"1.168224343","rc":[{"batl":[[2,1.56,1070.03]],"ltp":1.25,"tv":1110.36,"id":8979329}]}]}
{"op":"mcm","clk":"1009544518","pt":1580645200271,"mc":[{"id":"1.168224343","rc":[{"batb":[[0,1.2,282.44],[1,1.02,809.56],[2,1.01,15.51]],"batl":[[0,1.25,42.01],[1,1.56,1070.03],[2,1.56,0]],"ltp":1.25,"tv":1110.36,"id":8979329}]}]}
{"op":"mcm","clk":"1009544567","pt":1580645200698,"mc":[{"id":"1.168224343","rc":[{"batb":[[0,5,10.08],[1,3.35,17.55],[2,1.01,15.52]],"ltp":4.9,"tv":226.23,"id":2397396},{"batb":[[0,1.2,168.04]],"ltp":1.25,"tv":1110.36,"id":8979329}]}]}
{"op":"mcm","clk":"1009544823","pt":1580645202191,"mc":[{"id":"1.168224343","rc":[{"batb":[[0,3.35,17.55],[1,1.01,15.52],[2,1.01,0]],"ltp":4.9,"tv":226.23,"id":2397396},{"batb":[[0,1.02,809.56],[1,1.01,15.51],[2,1.01,0]],"ltp":1.25,"tv":1110.36,"id":8979329}]}]}
{"op":"mcm","clk":"1009544984","pt":1580645203294,"mc":[{"id":"1.168224343","rc":[{"batb":[[0,1.04,1238.8],[1,1.02,809.56],[2,1.01,15.51]],"batl":[[0,1.43,234.42],[1,1.44,200.4]],"ltp":1.25,"tv":1110.36,"id":8979329}]}]}
{"op":"mcm","clk":"1009545139","pt":1580645204477,"mc":[{"id":"1.168224343","rc":[{"batb":[[0,1.02,809.56],[1,1.01,15.51],[2,1.01,0]],"ltp":1.25,"tv":1110.36,"id":8979329}]}]}
{"op":"mcm","clk":"1009545568","pt":1580645207376,"mc":[{"id":"1.168224343","rc":[{"batb":[[0,1.18,251.45],[1,1.17,663.96],[2,1.02,809.56]],"batl":[[0,1.2,343.9],[1,1.21,492]],"ltp":1.25,"tv":1110.36,"id":8979329}]}]}
{"op":"mcm","clk":"1009545844","pt":1580645209180,"mc":[{"id":"1.168224343","rc":[{"batl":[[0,9.8,11.38]],"ltp":4.9,"tv":226.23,"id":2397396},{"batl":[[2,1.49,1173.28]],"ltp":1.25,"tv":1110.36,"id":8979329}]}]}
{"op":"mcm","clk":"1009546675","pt":1580645214612,"mc":[{"id":"1.168224343","rc":[{"batb":[[0,1.02,809.56],[1,1.01,15.51],[2,1.02,0]],"batl":[[0,1.49,1173.28],[1,1.21,0],[2,1.49,0]],"ltp":1.25,"tv":1110.36,"id":8979329}]}]}
{"op":"mcm","clk":"1009547162","pt":1580645217599,"mc":[{"id":"1.168224343","rc":[{"batb":[[0,1.04,1238.8],[1,1.02,809.56],[2,1.01,15.51]],"batl":[[0,1.43,234.42],[1,1.44,200.4],[2,1.49,1173.28]],"ltp":1.25,"tv":1110.36,"id":8979329}]}]}
{"op":"mcm","clk":"1009551003","pt":1580645241956,"mc":[{"id":"1.168224343","rc":[{"batb":[[0,1.02,809.56],[1,1.01,15.51],[2,1.01,0]],"ltp":1.25,"tv":1110.36,"id":8979329}]}]}
{"op":"mcm","clk":"1009551571","pt":1580645245326,"mc":[{"id":"1.168224343","rc":[{"batl":[[0,3.8,14.28]],"ltp":4.9,"tv":226.23,"id":2397396},{"batb":[[0,1.39,198.93],[1,1.38,248.65],[2,1.36,115.95]],"batl":[[2,1.49,0]],"ltp":1.25,"tv":1110.36,"id":8979329}]}]}
{"op":"mcm","clk":"1009551636","pt":1580645245796,"mc":[{"id":"1.168224343","rc":[{"batb":[[1,2.74,12.12],[2,1.01,15.52]],"ltp":4.9,"tv":226.23,"id":2397396},{"batb":[[2,1.37,56.81]],"ltp":1.25,"tv":1110.36,"id":8979329}]}]}
{"op":"mcm","clk":"1009552094","pt":1580645248632,"mc":[{"id":"1.168224343","rc":[{"batl":[[2,1.77,848.96]],"ltp":1.25,"tv":1110.36,"id":8979329}]}]}
{"op":"mcm","clk":"1009555549","pt":1580645273395,"mc":[{"id":"1.168224343","rc":[{"batb":[[0,1.37,56.81],[1,1.36,115.95],[2,1.2,116.69]],"batl":[[0,1.77,848.96],[1,1.44,0],[2,1.77,0]],"ltp":1.25,"tv":1110.36,"id":8979329}]}]}
{"op":"mcm","clk":"1009555653","pt":1580645274099,"mc":[{"id":"1.168224343","rc":[{"batb":[[0,2.74,12.12],[1,1.01,15.52],[2,1.01,0]],"ltp":4.9,"tv":226.23,"id":2397396},{"batb":[[0,1.2,116.69],[1,1.01,15.51],[2,1.2,0]],"ltp":1.25,"tv":1110.36,"id":8979329}]}]}
{"op":"mcm","clk":"1009555972","pt":1580645276189,"mc":[{"id":"1.168224343","rc":[{"batb":[[0,1.21,575.95],[1,1.2,609.56],[2,1.01,15.51]],"batl":[[0,1.61,184.76],[1,1.62,127.35],[2,1.77,848.96]],"ltp":1.25,"tv":1110.36,"id":8979329}]}]}
{"op":"mcm","clk":"1009556154","pt":1580645277301,"mc":[{"id":"1.168224343","rc":[{"batb":[[0,1.2,116.69],[1,1.01,15.51],[2,1.01,0]],"batl":[[0,1.77,848.96],[1,1.62,0],[2,1.77,0]],"ltp":1.25,"tv":1110.36,"id":8979329}]}]}
{"op":"mcm","clk":"1009556560","pt":1580645280287,"mc":[{"id":"1.168224343","rc":[{"batb":[[0,1.35,241.8],[1,1.34,287.26],[2,1.2,116.69]],"batl":[[0,1.39,302.55],[1,1.4,225.65],[2,1.77,848.96]],"ltp":1.25,"tv":1110.36,"id":8979329}]}]}
{"op":"mcm","clk":"1009556948","pt":1580645282925,"mc":[{"id":"1.168224343","rc":[{"batb":[[0,1.2,116.69],[1,1.01,15.51],[2,1.2,0]],"batl":[[0,1.77,848.96],[1,1.4,0],[2,1.77,0]],"ltp":1.25,"tv":1110.36,"id":8979329}]}]}
{"op":"mcm","clk":"1009557341","pt":1580645285711,"mc":[{"id":"1.168224343","rc":[{"batb":[[0,1.21,575.95],[1,1.2,609.56],[2,1.01,15.51]],"batl":[[0,1.61,184.76],[1,1.62,127.35]],"ltp":1.25,"tv":1110.36,"id":8979329}]}]}
{"op":"mcm","clk":"1009559489","pt":1580645301323,"mc":[{"id":"1.168224343","rc":[{"batl":[[0,1.24,316.14],[1,1.25,401.48]],"ltp":1.25,"tv":1110.36,"id":8979329}]}]}
{"op":"mcm","clk":"1009559586","pt":1580645302024,"mc":[{"id":"1.168224343","rc":[{"batb":[[0,5.2,12.67],[1,3.4,17.23],[2,1.01,15.52]],"ltp":4.9,"tv":226.23,"id":2397396},{"batb":[[2,1.02,817.43]],"ltp":1.25,"tv":1110.36,"id":8979329}]}]}
{"op":"mcm","clk":"1009559763","pt":1580645303145,"mc":[{"id":"1.168224343","rc":[{"batb":[[1,5,10.08],[2,3.4,17.23]],"batl":[[0,6,8.4]],"ltp":4.9,"tv":226.23,"id":2397396},{"batb":[[1,1.2,777.59]],"batl":[[1,1.25,443.49]],"ltp":1.25,"tv":1110.36,"id":8979329}]}]}
{"op":"mcm","clk":"1009559846","pt":1580645303713,"mc":[{"id":"1.168224343","rc":[{"batl":[[1,8.6,8.91]],"ltp":4.9,"tv":226.23,"id":2397396},{"batl":[[2,1.53,1116.57]],"ltp":1.25,"tv":1110.36,"id":8979329}]}]}
{"op":"mcm","clk":"1009563339","pt":1580645328398,"mc":[{"id":"1.168224343","rc":[{"batb":[[0,1.2,284.72],[1,1.02,817.43],[2,1.01,15.51]],"batl":[[0,1.25,42.01],[1,1.53,1116.57],[2,1.53,0]],"ltp":1.25,"tv":1110.36,"id":8979329}]}]}
{"op":"mcm","clk":"1009563396","pt":1580645328781,"mc":[{"id":"1.168224343","rc":[{"batb":[[0,5,10.08],[1,3.4,17.23],[2,1.01,15.52]],"ltp":4.9,"tv":226.23,"id":2397396},{"batb":[[0,1.2,168.04]],"ltp":1.25,"tv":1110.36,"id":8979329}]}]}
{"op":"mcm","clk":"1009563609","pt":1580645330277,"mc":[{"id":"1.168224343","rc":[{"batb":[[0,3.4,17.23],[1,1.01,15.52],[2,1.01,0]],"ltp":4.9,"tv":226.23,"id":2397396},{"batb":[[0,1.02,817.43],[1,1.01,15.51],[2,1.01,0]],"ltp":1.25,"tv":1110.36,"id":8979329}]}]}
{"op":"mcm","clk":"1009563730","pt":1580645331166,"mc":[{"id":"1.168224343","rc":[{"batb":[[0,1.04,1238.8],[1,1.02,817.43],[2,1.01,15.51]],"batl":[[0,1.43,308.34],[1,1.44,199.69]],"ltp":1.25,"tv":1110.36,"id":8979329}]}]}
{"op":"mcm","clk":"1009563879","pt":1580645332414,"mc":[{"id":"1.168224343","rc":[{"batb":[[0,1.02,817.43],[1,1.01,15.51],[2,1.01,0]],"ltp":1.25,"tv":1110.36,"id":8979329}]}]}
{"op":"mcm","clk":"1009564338","pt":1580645335290,"mc":[{"id":"1.168224343","rc":[{"batb":[[0,1.17,814.77],[1,1.16,288.84],[2,1.02,817.43]],"batl":[[0,1.2,433.57],[1,1.21,489.07]],"ltp":1.25,"tv":1110.36,"id":8979329}]}]}
{"op":"mcm","clk":"1009564449","pt":1580645335904,"mc":[{"id":"1.168224343","rc":[{"batb":[[0,1.17,660.04],[1,1.02,817.43],[2,1.01,15.51]],"batl":[[0,1.2,383.77]],"ltp":1.25,"tv":1110.36,"id":8979329}]}]}
{"op":"mcm","clk":"1009564671","pt":1580645337378,"mc":[{"id":"1.168224343","rc":[{"batl":[[0,9.8,11.38]],"ltp":4.9,"tv":226.23,"id":2397396},{"batb":[[0,1.02,817.43],[1,1.01,15.51],[2,1.01,0]],"batl":[[0,1.49,1173.28],[1,1.21,0]],"ltp":1.25,"tv":1110.36,"id":8979329}]}]}
{"op":"mcm","clk":"1009565052","pt":1580645339877,"mc":[{"id":"1.168224343","rc":[{"batb":[[0,1.04,1238.8],[1,1.02,817.43],[2,1.01,15.51]],"batl":[[0,1.43,266.48],[1,1.44,199.58]],"ltp":1.25,"tv":1110.36,"id":8979329}]}]}
{"op":"mcm","clk":"1009566085","pt":1580645346309,"mc":[{"id":"1.168224343","rc":[{"batl":[[0,1.06,1215.43]],"ltp":1.25,"tv":1110.36,"id":8979329}]}]}
{"op":"mcm","clk":"1009566231","pt":1580645347222,"mc":[{"id":"1.168224343","rc":[{"batb":[[0,20,5.27],[1,10.5,12.35],[2,1.01,15.52]],"ltp":4.9,"tv":226.23,"id":2397396},{"batb":[[0,1.04,1406.84]],"ltp":1.25,"tv":1110.36,"id":8979329}]}]}
{"op":"mcm","clk":"1009566385","pt":1580645348196,"mc":[{"id":"1.168224343","rc":[{"batl":[[0,65,30.09]],"ltp":4.9,"tv":226.23,"id":2397396},{"batl":[[1,1.32,1624.72]],"ltp":1.25,"tv":1110.36,"id":8979329}]}]}
{"op":"mcm","clk":"1009577595","pt":1580645427274,"mc":[{"id":"1.168224343","rc":[{"batb":[[0,1.04,168.04]],"batl":[[0,1.32,1624.72],[1,1.32,0]],"ltp":1.25,"tv":1110.36,"id":8979329}]}]}
{"op":"mcm","clk":"1009577739","pt":1580645428384,"mc":[{"id":"1.168224343","rc":[{"batb":[[0,10.5,12.35],[1,1.01,15.52],[2,1.01,0]],"ltp":4.9,"tv":226.23,"id":2397396},{"batb":[[0,1.01,15.51],[1,1.02,0],[2,1.01,0]],"ltp":1.25,"tv":1110.36,"id":8979329}]}]}
{"op":"mcm","clk":"1009577997","pt":1580645430298,"mc":[{"id":"1.168224343","rc":[{"batb":[[0,1.02,1263.09],[1,1.01,15.51]],"batl":[[0,1.11,190.97],[1,1.12,933.26]],"ltp":1.25,"tv":1110.36,"id":8979329}]}]}
{"op":"mcm","clk":"1009578596","pt":1580645434910,"mc":[{"id":"1.168224343","rc":[{"batb":[[0,1.01,15.51],[1,1.01,0]],"ltp":1.25,"tv":1110.36,"id":8979329}]}]}
{"op":"mcm","clk":"1009579002","pt":1580645438102,"mc":[{"id":"1.168224343","rc":[{"batb":[[0,1.05,1227],[1,1.01,15.51]],"batl":[[0,1.07,1162.52]],"ltp":1.25,"tv":1110.36,"id":8979329}]}]}
{"op":"mcm","clk":"1009579065","pt":1580645438618,"mc":[{"id":"1.168224343","rc":[{"batb":[[0,1.01,15.51],[1,1.01,0]],"ltp":1.25,"tv":1110.36,"id":8979329}]}]}
{"op":"mcm","clk":"1009579257","pt":1580645440127,"mc":[{"id":"1.168224343","rc":[{"batl":[[0,42,28.03]],"ltp":4.9,"tv":226.23,"id":2397396},{"batl":[[0,1.34,1569.66]],"ltp":1.25,"tv":1110.36,"id":8979329}]}]}
{"op":"mcm","clk":"1009579437","pt":1580645441404,"mc":[{"id":"1.168224343","rc":[{"batb":[[0,1.02,1263.09],[1,1.01,15.51]],"batl":[[0,1.11,190.97],[1,1.12,933.26]],"ltp":1.25,"tv":1110.36,"id":8979329}]}]}
{"op":"mcm","clk":"1009580864","pt":1580645452339,"mc":[{"id":"1.168224343","rc":[{"batb":[[0,1.01,15.51],[1,1.01,0]],"ltp":1.25,"tv":1110.36,"id":8979329}]}]}
{"op":"mcm","clk":"1009581315","pt":1580645455318,"mc":[{"id":"1.168224343","rc":[{"batb":[[0,1.1,341.01],[1,1.09,837.83],[2,1.01,15.51]],"ltp":1.25,"tv":1110.36,"id":8979329}]}]}
{"op":"mcm","clk":"1009581407","pt":1580645455946,"mc":[{"id":"1.168224343","rc":[{"batb":[[1,5.9,18.57],[2,1.01,15.52]],"ltp":4.9,"tv":226.23,"id":2397396},{"batb":[[2,1.07,328.18]],"ltp":1.25,"tv":1110.36,"id":8979329}]}]}
{"op":"mcm","clk":"1009581625","pt":1580645457345,"mc":[{"id":"1.168224343","rc":[{"batb":[[0,10.5,16.55]],"batl":[[0,13.5,3.36]],"ltp":4.9,"tv":226.23,"id":2397396},{"batb":[[2,1.08,168.04]],"batl":[[0,1.11,232.98]],"ltp":1.25,"tv":1110.36,"id":8979329}]}]}
{"op":"mcm","clk":"1009581648","pt":1580645457540,"mc":[{"id":"1.168224343","rc":[{"batl":[[1,21,21.95]],"ltp":4.9,"tv":226.23,"id":2397396},{"batl":[[2,1.38,1416.98]],"ltp":1.25,"tv":1110.36,"id":8979329}]}]}
{"op":"mcm","clk":"1009584093","pt":1580645474255,"mc":[{"id":"1.168224343","rc":[{"batb":[[0,5.9,18.57],[1,1.01,15.52],[2,1.01,0]],"batl":[[0,21,21.95],[1,21,0]],"ltp":4.9,"tv":226.23,"id":2397396},{"batb":[[0,1.03,621.82],[1,1.01,15.51],[2,1.08,0]],"batl":[[0,1.38,1416.98],[1,1.12,0],[2,1.38,0]],"ltp":1.25,"tv":1110.36,"id":8979329}]}]}
{"op":"mcm","clk":"1009584551","pt":1580645477273,"mc":[{"id":"1.168224343","rc":[{"batb":[[0,1.05,1227],[1,1.03,621.82],[2,1.01,15.51]],"batl":[[0,1.22,534.86],[1,1.23,436.15]],"ltp":1.25,"tv":1110.36,"id":8979329}]}]}
{"op":"mcm","clk":"1009586157","pt":1580645489378,"mc":[{"id":"1.168224343","rc":[{"batb":[[0,16.5,4.25],[1,8.4,8.5],[2,1.01,15.52]],"ltp":4.9,"tv":226.23,"id":2397396},{"batl":[[0,1.07,1049.93]],"ltp":1.25,"tv":1110.36,"id":8979329}]}]}
{"op":"mcm","clk":"1009586443","pt":1580645491397,"mc":[{"id":"1.168224343","rc":[{"batl":[[0,42,28.03]],"ltp":4.9,"tv":226.23,"id":2397396},{"batl":[[1,1.34,1569.66]],"ltp":1.25,"tv":1110.36,"id":8979329}]}]}
{"op":"mcm","clk":"1009588663","pt":1580645507389,"mc":[{"id":"1.168224343","rc":[{"batb":[[0,8.4,8.5],[1,1.01,15.52],[2,1.01,0]],"ltp":4.9,"tv":226.23,"id":2397396},{"batb":[[0,1.01,15.51],[1,1.03,0],[2,1.01,0]],"batl":[[0,1.34,1569.66],[1,1.34,0]],"ltp":1.25,"tv":1110.36,"id":8979329}]}]}
{"op":"mcm","clk":"1009588962","pt":1580645509984,"mc":[{"id":"1.168224343","rc":[{"batb":[[0,1.02,1263.09],[1,1.01,15.51]],"batl":[[0,1.15,658.46],[1,1.16,457.86]],"ltp":1.25,"tv":1110.36,"id":8979329}]}]}
{"op":"mcm","clk":"1009590453","pt":1580645521277,"mc":[{"id":"1.168224343","rc":[{"batb":[[0,14,6.53],[1,8.4,8.5],[2,1.01,15.52]],"ltp":4.9,"tv":226.23,"id":2397396},{"batb":[[0,1.02,1431.13]],"batl":[[0,1.03,196.85],[1,1.04,1043.84]],"ltp":1.25,"tv":1110.36,"id":8979329}]}]}
{"op":"mcm","clk":"1009590486","pt":1580645521488,"mc":[{"id":"1.168224343","rc":[{"batb":[[1,1.01,15.52],[2,1.01,0]],"ltp":4.9,"tv":226.23,"id":2397396}]}]}
{"op":"mcm","clk":"1009590799","pt":1580645523775,"mc":[{"id":"1.168224343","rc":[{"batl":[[0,520,33.8]],"ltp":4.9,"tv":226.23,"id":2397396},{"batl":[[2,1.3,1729.7]],"ltp":1.25,"tv":1110.36,"id":8979329}]}]}
{"op":"mcm","clk":"1009591282","pt":1580645527111,"mc":[{"id":"1.168224343","rc":[{"batb":[[0,1.02,3000.36]],"ltp":1.25,"tv":1110.36,"id":8979329}]}]}
{"op":"mcm","clk":"1009593463","pt":1580645543199,"mc":[{"id":"1.168224343","rc":[{"batb":[[0,1.02,1737.27]],"batl":[[0,1.3,1729.7],[1,1.04,0],[2,1.3,0]],"ltp":1.25,"tv":1110.36,"id":8979329}]}]}
{"op":"mcm","clk":"1009593645","pt":1580645544305,"mc":[{"id":"1.168224343","rc":[{"batb":[[0,1.01,15.51],[1,1.01,0]],"ltp":1.25,"tv":1110.36,"id":8979329}]}]}
{"op":"mcm","clk":"1009593912","pt":1580645546112,"mc":[{"id":"1.168224343","rc":[{"batl":[[0,1.08,432.2],[1,1.09,753.74]],"ltp":1.25,"tv":1110.36,"id":8979329}]}]}
{"op":"mcm","clk":"1009594328","pt":1580645549427,"mc":[{"id":"1.168224343","rc":[{"batb":[[0,1.01,15.52],[1,1.01,0]],"ltp":4.9,"tv":226.23,"id":2397396}]}]}
{"op":"mcm","clk":"1009594676","pt":1580645551731,"mc":[{"id":"1.168224343","rc":[{"trd":[[1.01,31.02]],"batl":[[0,1.01,1260.08]],"ltp":1.01,"tv":1141.37,"id":8979329}],"tv":1367.61}]}
{"op":"mcm","clk":"1009595131","pt":1580645554338,"mc":[{"id":"1.168224343","rc":[{"batl":[[1,1.27,1868.55]],"ltp":1.01,"tv":1141.37,"id":8979329}]}]}
{"op":"mcm","clk":"1009596687","pt":1580645563317,"mc":[{"id":"1.168224343","rc":[{"batl":[[0,1.27,1868.55],[1,1.27,0]],"ltp":1.01,"tv":1141.37,"id":8979329}]}]}
{"op":"mcm","clk":"1009597173","pt":1580645566252,"mc":[{"id":"1.168224343","rc":[{"batl":[[0,1.03,1250.83]],"ltp":1.01,"tv":1141.37,"id":8979329}]}]}
{"op":"mcm","clk":"1009597775","pt":1580645570071,"mc":[{"id":"1.168224343","rc":[{"batb":[[0,1.01,1130.06]],"batl":[[0,1.02,1263.09]],"ltp":1.01,"tv":1141.37,"id":8979329}]}]}
{"op":"mcm","clk":"1009597990","pt":1580645571369,"mc":[{"id":"1.168224343","rc":[{"batl":[[1,1.27,1842.55]],"ltp":1.01,"tv":1141.37,"id":8979329}]}]}
{"op":"mcm","clk":"1009598217","pt":1580645572751,"mc":[{"id":"1.168224343","rc":[{"batl":[[0,1.27,1842.55],[1,1.27,0]],"ltp":1.01,"tv":1141.37,"id":8979329}]}]}
{"op":"mcm","clk":"1009598709","pt":1580645575756,"mc":[{"id":"1.168224343","rc":[{"batl":[[0,1.03,1250.83]],"ltp":1.01,"tv":1141.37,"id":8979329}]}]}
{"op":"mcm","clk":"1009599519","pt":1580645581160,"mc":[{"id":"1.168224343","rc":[{"batb":[[0,13,7.47],[1,1.01,15.52]],"ltp":4.9,"tv":226.23,"id":2397396},{"batb":[[0,1.02,1263.09]],"ltp":1.01,"tv":1141.37,"id":8979329}]}]}
{"op":"mcm","clk":"1009599712","pt":1580645582542,"mc":[{"id":"1.168224343","rc":[{"batl":[[1,1.29,1752.03]],"ltp":1.01,"tv":1141.37,"id":8979329}]}]}
{"op":"mcm","clk":"1009602823","pt":1580645602256,"mc":[{"id":"1.168224343","rc":[{"batl":[[0,1.29,1752.03],[1,1.29,0]],"ltp":1.01,"tv":1141.37,"id":8979329}]}]}
{"op":"mcm","clk":"1009603581","pt":1580645607206,"mc":[{"id":"1.168224343","rc":[{"batb":[[0,1.03,1250.83]],"batl":[[0,1.04,1238.8]],"ltp":1.01,"tv":1141.37,"id":8979329}]}]}
{"op":"mcm","clk":"1009604110","pt":1580645610399,"mc":[{"id":"1.168224343","rc":[{"batl":[[0,160,32.63]],"ltp":4.9,"tv":226.23,"id":2397396},{"batl":[[1,1.3,1695.87]],"ltp":1.01,"tv":1141.37,"id":8979329}]}]}
{"op":"mcm","clk":"1009604255","pt":1580645611287,"mc":[{"id":"1.168224343","rc":[{"batl":[[0,1.3,1695.87],[1,1.3,0]],"ltp":1.01,"tv":1141.37,"id":8979329}]}]}
{"op":"mcm","clk":"1009604556","pt":1580645613281,"mc":[{"id":"1.168224343","rc":[{"trd":[[13,0.03]],"batb":[[0,13,7.46]],"ltp":13.0,"tv":226.26,"id":2397396}],"tv":1367.64}]}
{"op":"mcm","clk":"1009604717","pt":1580645614297,"mc":[{"id":"1.168224343","rc":[{"batl":[[0,1.09,1181.97]],"ltp":1.01,"tv":1141.37,"id":8979329}]}]}
