{"op":"mcm","clk":"1004962286","pt":1580585267691,"mc":[{"id":"1.168224333","marketDefinition":{"bspMarket":false,"turnInPlayEnabled":true,"persistenceEnabled":true,"marketBaseRate":5.0,"eventId":"29681722","eventTypeId":"2","numberOfWinners":1,"bettingType":"ODDS","marketType":"SET_BETTING","marketTime":"2020-02-02T09:00:00.000Z","suspendTime":"2020-02-02T09:00:00.000Z","bspReconciled":false,"complete":true,"inPlay":false,"crossMatching":false,"runnersVoidable":false,"numberOfActiveRunners":4,"betDelay":0,"status":"OPEN","runners":[{"status":"ACTIVE","sortPriority":1,"id":16665613,"name":"Emil Ruusuvuori 2-0"},{"status":"ACTIVE","sortPriority":2,"id":16665614,"name":"Emil Ruusuvuori 2-1"},{"status":"ACTIVE","sortPriority":3,"id":13011472,"name":"Bachinger 2-0"},{"status":"ACTIVE","sortPriority":4,"id":13011471,"name":"Bachinger 2-1"}],"regulators":["MR_INT"],"countryCode":"FR","discountAllowed":false,"timezone":"UTC","openDate":"2020-02-02T09:00:00.000Z","version":3147098025,"name":"Set Betting","eventName":"Emil Ruusuvuori v Bachinger"}}]}
{"op":"mcm","clk":"1004962420","pt":1580585268465,"mc":[{"id":"1.168224333","marketDefinition":{"bspMarket":false,"turnInPlayEnabled":true,"persistenceEnabled":true,"marketBaseRate":5.0,"eventId":"29681722","eventTypeId":"2","numberOfWinners":1,"bettingType":"ODDS","marketType":"SET_BETTING","marketTime":"2020-02-02T09:00:00.000Z","suspendTime":"2020-02-02T09:00:00.000Z","bspReconciled":false,"complete":true,"inPlay":false,"crossMatching":false,"runnersVoidable":false,"numberOfActiveRunners":4,"betDelay":0,"status":"OPEN","runners":[{"status":"ACTIVE","sortPriority":1,"id":16665613,"name":"Emil Ruusuvuori 2-0"},{"status":"ACTIVE","sortPriority":2,"id":16665614,"name":"Emil Ruusuvuori 2-1"},{"status":"ACTIVE","sortPriority":3,"id":13011472,"name":"Bachinger 2-0"},{"status":"ACTIVE","sortPriority":4,"id":13011471,"name":"Bachinger 2-1"}],"regulators":["MR_INT"],"countryCode":"FR","discountAllowed":false,"timezone":"UTC","openDate":"2020-02-02T09:00:00.000Z","version":3147098025,"name":"Set Betting","eventName":"Emil Ruusuvuori v Bachinger"}}]}
{"op":"mcm","clk":"1004962808","pt":1580585270546,"mc":[{"id":"1.168224333","marketDefinition":{"bspMarket":false,"turnInPlayEnabled":true,"persistenceEnabled":true,"marketBaseRate":5.0,"eventId":"29681722","eventTypeId":"2","numberOfWinners":1,"bettingType":"ODDS","marketType":"SET_BETTING","marketTime":"2020-02-02T09:00:00.000Z","suspendTime":"2020-02-02T09:00:00.000Z","bspReconciled":false,"complete":true,"inPlay":false,"crossMatching":false,"runnersVoidable":false,"numberOfActiveRunners":4,"betDelay":0,"status":"OPEN","runners":[{"status":"ACTIVE","sortPriority":1,"id":16665613,"name":"Emil Ruusuvuori 2-0"},{"status":"ACTIVE","sortPriority":2,"id":16665614,"name":"Emil Ruusuvuori 2-1"},{"status":"ACTIVE","sortPriority":3,"id":13011472,"name":"Bachinger 2-0"},{"status":"ACTIVE","sortPriority":4,"id":13011471,"name":"Bachinger 2-1"}],"regulators":["MR_INT"],"countryCode":"FR","discountAllowed":true,"timezone":"UTC","openDate":"2020-02-02T09:00:00.000Z","version":3147098025,"name":"Set Betting","eventName":"Emil Ruusuvuori v Bachinger"}}]}
{"op":"mcm","clk":"1005002549","pt":1580585515430,"mc":[{"id":"1.168224333","marketDefinition":{"bspMarket":false,"turnInPlayEnabled":true,"persistenceEnabled":true,"marketBaseRate":5.0,"eventId":"29681722","eventTypeId":"2","numberOfWinners":1,"bettingType":"ODDS","marketType":"SET_BETTING","marketTime":"2020-02-02T11:30:00.000Z","suspendTime":"2020-02-02T11:30:00.000Z","bspReconciled":false,"complete":true,"inPlay":false,"crossMatching":false,"runnersVoidable":false,"numberOfActiveRunners":4,"betDelay":0,"status":"OPEN","runners":[{"status":"ACTIVE","sortPriority":1,"id":16665613,"name":"Emil Ruusuvuori 2-0"},{"status":"ACTIVE","sortPriority":2,"id":16665614,"name":"Emil Ruusuvuori 2-1"},{"status":"ACTIVE","sortPriority":3,"id":13011472,"name":"Bachinger 2-0"},{"status":"ACTIVE","sortPriority":4,"id":13011471,"name":"Bachinger 2-1"}],"regulators":["MR_INT"],"countryCode":"FR","discountAllowed":true,"timezone":"UTC","openDate":"2020-02-02T09:00:00.000Z","version":3147124991,"name":"Set Betting","eventName":"Emil Ruusuvuori v Bachinger"}}]}
{"op":"mcm","clk":"1005003169","pt":1580585518494,"mc":[{"id":"1.168224333","marketDefinition":{"bspMarket":false,"turnInPlayEnabled":true,"persistenceEnabled":true,"marketBaseRate":5.0,"eventId":"29681722","eventTypeId":"2","numberOfWinners":1,"bettingType":"ODDS","marketType":"SET_BETTING","marketTime":"2020-02-02T11:30:00.000Z","suspendTime":"2020-02-02T11:30:00.000Z","bspReconciled":false,"complete":true,"inPlay":false,"crossMatching":false,"runnersVoidable":false,"numberOfActiveRunners":4,"betDelay":0,"status":"OPEN","runners":[{"status":"ACTIVE","sortPriority":1,"id":16665613,"name":"Emil Ruusuvuori 2-0"},{"status":"ACTIVE","sortPriority":2,"id":16665614,"name":"Emil Ruusuvuori 2-1"},{"status":"ACTIVE","sortPriority":3,"id":13011472,"name":"Bachinger 2-0"},{"status":"ACTIVE","sortPriority":4,"id":13011471,"name":"Bachinger 2-1"}],"regulators":["MR_INT"],"countryCode":"FR","discountAllowed":true,"timezone":"UTC","openDate":"2020-02-02T11:30:00.000Z","version":3147124991,"name":"Set Betting","eventName":"Emil Ruusuvuori v Bachinger"}}]}
{"op":"mcm","clk":"1005380306","pt":1580587946037,"mc":[{"id":"1.168224333","rc":[{"batb":[[0,1.02,2]],"ltp":0.0,"tv":0.0,"id":13011471},{"batb":[[0,1.02,2]],"ltp":0.0,"tv":0.0,"id":16665614},{"batb":[[0,1.02,2]],"ltp":0.0,"tv":0.0,"id":13011472},{"batb":[[0,1.02,2]],"ltp":0.0,"tv":0.0,"id":16665613}]}]}
{"op":"mcm","clk":"1006924581","pt":1580602185254,"mc":[{"id":"1.168224333","rc":[{"batb":[[1,1.01,2.53]],"ltp":0.0,"tv":0.0,"id":13011471},{"batb":[[1,1.01,2.53]],"ltp":0.0,"tv":0.0,"id":16665614},{"batb":[[1,1.01,2.53]],"ltp":0.0,"tv":0.0,"id":13011472},{"batb":[[1,1.01,2.53]],"ltp":0.0,"tv":0.0,"id":16665613}]}]}
{"op":"mcm","clk":"1006924687","pt":1580602186352,"mc":[{"id":"1.168224333","rc":[{"batb":[[1,1.01,0.51]],"ltp":0.0,"tv":0.0,"id":13011471},{"batb":[[1,1.01,0.51]],"ltp":0.0,"tv":0.0,"id":16665614},{"batb":[[1,1.01,0.51]],"ltp":0.0,"tv":0.0,"id":13011472},{"batb":[[1,1.01,0.51]],"ltp":0.0,"tv":0.0,"id":16665613}]}]}
{"op":"mcm","clk":"1007043396","pt":1580603725304,"mc":[{"id":"1.168224333","rc":[{"batb":[[1,1.01,3.04]],"ltp":0.0,"tv":0.0,"id":13011471},{"batb":[[1,1.01,3.04]],"ltp":0.0,"tv":0.0,"id":16665614},{"batb":[[1,1.01,3.04]],"ltp":0.0,"tv":0.0,"id":13011472},{"batb":[[1,1.01,3.04]],"ltp":0.0,"tv":0.0,"id":16665613}]}]}
{"op":"mcm","clk":"1007043453","pt":1580603726341,"mc":[{"id":"1.168224333","rc":[{"batb":[[1,1.01,1.01]],"ltp":0.0,"tv":0.0,"id":13011471},{"batb":[[1,1.01,1.01]],"ltp":0.0,"tv":0.0,"id":16665614},{"batb":[[1,1.01,1.01]],"ltp":0.0,"tv":0.0,"id":13011472},{"batb":[[1,1.01,1.01]],"ltp":0.0,"tv":0.0,"id":16665613}]}]}
{"op":"mcm","clk":"1007817669","pt":1580623644062,"mc":[{"id":"1.168224333","rc":[{"batb":[[0,1.56,30.29],[1,1.02,2],[2,1.01,1.01]],"ltp":0.0,"tv":0.0,"id":16665613}]}]}
{"op":"mcm","clk":"1008459426","pt":1580635613340,"mc":[{"id":"1.168224333","marketDefinition":{"bspMarket":false,"turnInPlayEnabled":true,"persistenceEnabled":true,"marketBaseRate":5.0,"eventId":"29681722","eventTypeId":"2","numberOfWinners":1,"bettingType":"ODDS","marketType":"SET_BETTING","marketTime":"2020-02-02T11:24:00.000Z","suspendTime":"2020-02-02T11:24:00.000Z","bspReconciled":false,"complete":true,"inPlay":false,"crossMatching":false,"runnersVoidable":false,"numberOfActiveRunners":4,"betDelay":0,"status":"OPEN","runners":[{"status":"ACTIVE","sortPriority":1,"id":16665613,"name":"Emil Ruusuvuori 2-0"},{"status":"ACTIVE","sortPriority":2,"id":16665614,"name":"Emil Ruusuvuori 2-1"},{"status":"ACTIVE","sortPriority":3,"id":13011472,"name":"Bachinger 2-0"},{"status":"ACTIVE","sortPriority":4,"id":13011471,"name":"Bachinger 2-1"}],"regulators":["MR_INT"],"countryCode":"FR","discountAllowed":true,"timezone":"UTC","openDate":"2020-02-02T11:30:00.000Z","version":3148345455,"name":"Set Betting","eventName":"Emil Ruusuvuori v Bachinger"}}]}
{"op":"mcm","clk":"1008459775","pt":1580635616342,"mc":[{"id":"1.168224333","marketDefinition":{"bspMarket":false,"turnInPlayEnabled":true,"persistenceEnabled":true,"marketBaseRate":5.0,"eventId":"29681722","eventTypeId":"2","numberOfWinners":1,"bettingType":"ODDS","marketType":"SET_BETTING","marketTime":"2020-02-02T11:24:00.000Z","suspendTime":"2020-02-02T11:24:00.000Z","bspReconciled":false,"complete":true,"inPlay":false,"crossMatching":false,"runnersVoidable":false,"numberOfActiveRunners":4,"betDelay":0,"status":"OPEN","runners":[{"status":"ACTIVE","sortPriority":1,"id":16665613,"name":"Emil Ruusuvuori 2-0"},{"status":"ACTIVE","sortPriority":2,"id":16665614,"name":"Emil Ruusuvuori 2-1"},{"status":"ACTIVE","sortPriority":3,"id":13011472,"name":"Bachinger 2-0"},{"status":"ACTIVE","sortPriority":4,"id":13011471,"name":"Bachinger 2-1"}],"regulators":["MR_INT"],"countryCode":"FR","discountAllowed":true,"timezone":"UTC","openDate":"2020-02-02T11:24:00.000Z","version":3148345455,"name":"Set Betting","eventName":"Emil Ruusuvuori v Bachinger"}}]}
{"op":"mcm","clk":"1008680773","pt":1580638617069,"mc":[{"id":"1.168224333","rc":[{"batb":[[0,1.02,2],[1,1.01,1.01],[2,1.01,0]],"ltp":0.0,"tv":0.0,"id":16665613}]}]}
{"op":"mcm","clk":"1008879044","pt":1580640413444,"mc":[{"id":"1.168224333","marketDefinition":{"bspMarket":false,"turnInPlayEnabled":true,"persistenceEnabled":true,"marketBaseRate":5.0,"eventId":"29681722","eventTypeId":"2","numberOfWinners":1,"bettingType":"ODDS","marketType":"SET_BETTING","marketTime":"2020-02-02T10:51:00.000Z","suspendTime":"2020-02-02T10:51:00.000Z","bspReconciled":false,"complete":true,"inPlay":false,"crossMatching":false,"runnersVoidable":false,"numberOfActiveRunners":4,"betDelay":0,"status":"OPEN","runners":[{"status":"ACTIVE","sortPriority":1,"id":16665613,"name":"Emil Ruusuvuori 2-0"},{"status":"ACTIVE","sortPriority":2,"id":16665614,"name":"Emil Ruusuvuori 2-1"},{"status":"ACTIVE","sortPriority":3,"id":13011472,"name":"Bachinger 2-0"},{"status":"ACTIVE","sortPriority":4,"id":13011471,"name":"Bachinger 2-1"}],"regulators":["MR_INT"],"countryCode":"FR","discountAllowed":true,"timezone":"UTC","openDate":"2020-02-02T11:24:00.000Z","version":3148437421,"name":"Set Betting","eventName":"Emil Ruusuvuori v Bachinger"}}]}
{"op":"mcm","clk":"1008880280","pt":1580640421273,"mc":[{"id":"1.168224333","marketDefinition":{"bspMarket":false,"turnInPlayEnabled":true,"persistenceEnabled":true,"marketBaseRate":5.0,"eventId":"29681722","eventTypeId":"2","numberOfWinners":1,"bettingType":"ODDS","marketType":"SET_BETTING","marketTime":"2020-02-02T10:51:00.000Z","suspendTime":"2020-02-02T10:51:00.000Z","bspReconciled":false,"complete":true,"inPlay":false,"crossMatching":false,"runnersVoidable":false,"numberOfActiveRunners":4,"betDelay":0,"status":"OPEN","runners":[{"status":"ACTIVE","sortPriority":1,"id":16665613,"name":"Emil Ruusuvuori 2-0"},{"status":"ACTIVE","sortPriority":2,"id":16665614,"name":"Emil Ruusuvuori 2-1"},{"status":"ACTIVE","sortPriority":3,"id":13011472,"name":"Bachinger 2-0"},{"status":"ACTIVE","sortPriority":4,"id":13011471,"name":"Bachinger 2-1"}],"regulators":["MR_INT"],"countryCode":"FR","discountAllowed":true,"timezone":"UTC","openDate":"2020-02-02T10:51:00.000Z","version":3148437421,"name":"Set Betting","eventName":"Emil Ruusuvuori v Bachinger"}}]}
{"op":"mcm","clk":"1008903211","pt":1580640611123,"mc":[{"id":"1.168224333","rc":[{"batb":[[0,7.6,9.99],[1,1.02,2],[2,1.01,1.01]],"batl":[[0,9.4,9.52]],"ltp":0.0,"tv":0.0,"id":13011471},{"batb":[[0,4.3,18.8],[1,1.02,2],[2,1.01,1.01]],"batl":[[0,5,17.86]],"ltp":0.0,"tv":0.0,"id":16665614},{"batb":[[0,6.8,13.22],[1,1.02,2],[2,1.01,1.01]],"batl":[[0,8.2,12.43]],"ltp":0.0,"tv":0.0,"id":13011472},{"batb":[[0,1.83,18.73],[1,1.02,2],[2,1.01,1.01]],"batl":[[0,1.94,18.41]],"ltp":0.0,"tv":0.0,"id":16665613}]}]}
{"op":"mcm","clk":"1008903436","pt":1580640612891,"mc":[{"id":"1.168224333","rc":[{"batb":[[1,3.75,4.31],[2,1.02,2]],"ltp":0.0,"tv":0.0,"id":13011471},{"batb":[[1,2.6,6.49],[2,1.02,2]],"ltp":0.0,"tv":0.0,"id":16665614},{"batb":[[1,3.35,5.67],[2,1.02,2]],"ltp":0.0,"tv":0.0,"id":13011472},{"batb":[[1,1.45,5.01],[2,1.02,2]],"ltp":0.0,"tv":0.0,"id":16665613}]}]}
{"op":"mcm","clk":"1008907122","pt":1580640642304,"mc":[{"id":"1.168224333","marketDefinition":{"bspMarket":false,"turnInPlayEnabled":true,"persistenceEnabled":true,"marketBaseRate":5.0,"eventId":"29681722","eventTypeId":"2","numberOfWinners":1,"bettingType":"ODDS","marketType":"SET_BETTING","marketTime":"2020-02-02T10:51:00.000Z","suspendTime":"2020-02-02T10:51:00.000Z","bspReconciled":false,"complete":true,"inPlay":false,"crossMatching":true,"runnersVoidable":false,"numberOfActiveRunners":4,"betDelay":0,"status":"OPEN","runners":[{"status":"ACTIVE","sortPriority":1,"id":16665613,"name":"Emil Ruusuvuori 2-0"},{"status":"ACTIVE","sortPriority":2,"id":16665614,"name":"Emil Ruusuvuori 2-1"},{"status":"ACTIVE","sortPriority":3,"id":13011472,"name":"Bachinger 2-0"},{"status":"ACTIVE","sortPriority":4,"id":13011471,"name":"Bachinger 2-1"}],"regulators":["MR_INT"],"countryCode":"FR","discountAllowed":true,"timezone":"UTC","openDate":"2020-02-02T10:51:00.000Z","version":3148437421,"name":"Set Betting","eventName":"Emil Ruusuvuori v Bachinger"}}]}
{"op":"mcm","clk":"1008910085","pt":1580640668174,"mc":[{"id":"1.168224333","rc":[{"batb":[[0,4.3,18.65]],"ltp":0.0,"tv":0.0,"id":16665614},{"batb":[[0,6.6,13.45]],"ltp":0.0,"tv":0.0,"id":13011472},{"batb":[[0,1.83,18.57]],"batl":[[0,1.94,18.25]],"ltp":0.0,"tv":0.0,"id":16665613}]}]}
{"op":"mcm","clk":"1008912298","pt":1580640686881,"mc":[{"id":"1.168224333","rc":[{"batb":[[0,7.4,10.31]],"ltp":0.0,"tv":0.0,"id":13011471},{"batl":[[0,5,17.7]],"ltp":0.0,"tv":0.0,"id":16665614},{"batl":[[0,1.95,18.18]],"ltp":0.0,"tv":0.0,"id":16665613}]}]}
{"op":"mcm","clk":"1008915480","pt":1580640714233,"mc":[{"id":"1.168224333","marketDefinition":{"bspMarket":false,"turnInPlayEnabled":true,"persistenceEnabled":true,"marketBaseRate":5.0,"eventId":"29681722","eventTypeId":"2","numberOfWinners":1,"bettingType":"ODDS","marketType":"SET_BETTING","marketTime":"2020-02-02T10:48:00.000Z","suspendTime":"2020-02-02T10:48:00.000Z","bspReconciled":false,"complete":true,"inPlay":false,"crossMatching":true,"runnersVoidable":false,"numberOfActiveRunners":4,"betDelay":0,"status":"OPEN","runners":[{"status":"ACTIVE","sortPriority":1,"id":16665613,"name":"Emil Ruusuvuori 2-0"},{"status":"ACTIVE","sortPriority":2,"id":16665614,"name":"Emil Ruusuvuori 2-1"},{"status":"ACTIVE","sortPriority":3,"id":13011472,"name":"Bachinger 2-0"},{"status":"ACTIVE","sortPriority":4,"id":13011471,"name":"Bachinger 2-1"}],"regulators":["MR_INT"],"countryCode":"FR","discountAllowed":true,"timezone":"UTC","openDate":"2020-02-02T10:51:00.000Z","version":3148443643,"name":"Set Betting","eventName":"Emil Ruusuvuori v Bachinger"},"rc":[{"batb":[[1,1.02,2],[2,1.01,1.01]],"ltp":0.0,"tv":0.0,"id":13011471},{"batb":[[1,1.02,2],[2,1.01,1.01]],"ltp":0.0,"tv":0.0,"id":16665614},{"batb":[[1,1.02,2],[2,1.01,1.01]],"ltp":0.0,"tv":0.0,"id":13011472},{"batb":[[1,1.02,2],[2,1.01,1.01]],"ltp":0.0,"tv":0.0,"id":16665613}]}]}
{"op":"mcm","clk":"1008915826","pt":1580640717144,"mc":[{"id":"1.168224333","marketDefinition":{"bspMarket":false,"turnInPlayEnabled":true,"persistenceEnabled":true,"marketBaseRate":5.0,"eventId":"29681722","eventTypeId":"2","numberOfWinners":1,"bettingType":"ODDS","marketType":"SET_BETTING","marketTime":"2020-02-02T10:48:00.000Z","suspendTime":"2020-02-02T10:48:00.000Z","bspReconciled":false,"complete":true,"inPlay":false,"crossMatching":true,"runnersVoidable":false,"numberOfActiveRunners":4,"betDelay":0,"status":"OPEN","runners":[{"status":"ACTIVE","sortPriority":1,"id":16665613,"name":"Emil Ruusuvuori 2-0"},{"status":"ACTIVE","sortPriority":2,"id":16665614,"name":"Emil Ruusuvuori 2-1"},{"status":"ACTIVE","sortPriority":3,"id":13011472,"name":"Bachinger 2-0"},{"status":"ACTIVE","sortPriority":4,"id":13011471,"name":"Bachinger 2-1"}],"regulators":["MR_INT"],"countryCode":"FR","discountAllowed":true,"timezone":"UTC","openDate":"2020-02-02T10:48:00.000Z","version":3148443643,"name":"Set Betting","eventName":"Emil Ruusuvuori v Bachinger"}}]}
{"op":"mcm","clk":"1008940367","pt":1580640933281,"mc":[{"id":"1.168224333","rc":[{"batb":[[1,7.2,6.72],[2,1.02,2]],"batl":[[0,9.2,5.04],[1,9.4,9.52]],"ltp":0.0,"tv":0.0,"id":13011471},{"batb":[[1,3.95,13.44],[2,1.02,2]],"batl":[[0,4.7,10.92],[1,5,17.7]],"ltp":0.0,"tv":0.0,"id":16665614},{"batb":[[0,6.8,6.72],[1,6.6,13.45],[2,1.02,2]],"batl":[[1,8.6,5.04]],"ltp":0.0,"tv":0.0,"id":13011472},{"batb":[[0,1.85,48.73],[1,1.83,18.57],[2,1.02,2]],"batl":[[1,2.04,40.33]],"ltp":0.0,"tv":0.0,"id":16665613}]}]}
{"op":"mcm","clk":"1008970578","pt":1580641185073,"mc":[{"id":"1.168224333","rc":[{"batb":[[0,7.2,6.72],[1,1.02,2],[2,1.01,1.01]],"batl":[[1,9.4,0]],"ltp":0.0,"tv":0.0,"id":13011471},{"batb":[[0,3.95,13.44],[1,1.02,2],[2,1.01,1.01]],"batl":[[1,5,0]],"ltp":0.0,"tv":0.0,"id":16665614},{"batb":[[1,1.02,2],[2,1.01,1.01]],"batl":[[0,8.6,5.04],[1,8.6,0]],"ltp":0.0,"tv":0.0,"id":13011472},{"batb":[[1,1.02,2],[2,1.01,1.01]],"batl":[[0,2.04,40.33],[1,2.04,0]],"ltp":0.0,"tv":0.0,"id":16665613}]}]}
{"op":"mcm","clk":"1008970700","pt":1580641186080,"mc":[{"id":"1.168224333","marketDefinition":{"bspMarket":false,"turnInPlayEnabled":true,"persistenceEnabled":true,"marketBaseRate":5.0,"eventId":"29681722","eventTypeId":"2","numberOfWinners":1,"bettingType":"ODDS","marketType":"SET_BETTING","marketTime":"2020-02-02T10:48:00.000Z","suspendTime":"2020-02-02T10:48:00.000Z","bspReconciled":false,"complete":true,"inPlay":true,"crossMatching":true,"runnersVoidable":false,"numberOfActiveRunners":4,"betDelay":3,"status":"OPEN","runners":[{"status":"ACTIVE","sortPriority":1,"id":16665613,"name":"Emil Ruusuvuori 2-0"},{"status":"ACTIVE","sortPriority":2,"id":16665614,"name":"Emil Ruusuvuori 2-1"},{"status":"ACTIVE","sortPriority":3,"id":13011472,"name":"Bachinger 2-0"},{"status":"ACTIVE","sortPriority":4,"id":13011471,"name":"Bachinger 2-1"}],"regulators":["MR_INT"],"countryCode":"FR","discountAllowed":true,"timezone":"UTC","openDate":"2020-02-02T10:48:00.000Z","version":3148454241,"name":"Set Betting","eventName":"Emil Ruusuvuori v Bachinger"},"rc":[{"batb":[[0,1.01,0.51],[1,1.02,0],[2,1.01,0]],"ltp":0.0,"tv":0.0,"id":13011471},{"batb":[[0,1.01,0.51],[1,1.02,0],[2,1.01,0]],"ltp":0.0,"tv":0.0,"id":16665614},{"batb":[[0,1.01,0.51],[1,1.02,0],[2,1.01,0]],"ltp":0.0,"tv":0.0,"id":13011472},{"batb":[[0,1.01,0.51],[1,1.02,0],[2,1.01,0]],"ltp":0.0,"tv":0.0,"id":16665613}]}]}
{"op":"mcm","clk":"1008971485","pt":1580641192365,"mc":[{"id":"1.168224333","rc":[{"batb":[[0,7.4,10.86],[1,7.2,11.25],[2,1.01,0.51]],"batl":[[0,9.4,9.52]],"ltp":0.0,"tv":0.0,"id":13011471},{"batb":[[0,4.2,19.83],[1,4.1,21.48],[2,1.01,0.51]],"batl":[[0,4.9,18.88],[1,5.1,17.07]],"ltp":0.0,"tv":0.0,"id":16665614},{"batb":[[0,6,16.84],[1,5.6,20.22],[2,1.01,0.51]],"batl":[[0,7.4,15.74],[1,8.4,11.96]],"ltp":0.0,"tv":0.0,"id":13011472},{"batb":[[0,1.92,16.13],[1,1.8,19.51],[2,1.01,0.51]],"batl":[[0,2.04,15.89],[1,2.14,27.54]],"ltp":0.0,"tv":0.0,"id":16665613}]}]}
{"op":"mcm","clk":"1008971541","pt":1580641192785,"mc":[{"id":"1.168224333","rc":[{"batb":[[2,6.8,6.72]],"batl":[[0,8.8,5.04],[1,9.4,9.52]],"ltp":0.0,"tv":0.0,"id":13011471},{"batb":[[2,3.8,14.28]],"batl":[[0,4.6,10.92],[1,4.9,18.88],[2,5.1,17.07]],"ltp":0.0,"tv":0.0,"id":16665614},{"batb":[[0,6.4,7.56],[1,6,16.84],[2,5.6,20.22]],"batl":[[1,8,5.88],[2,8.4,11.96]],"ltp":0.0,"tv":0.0,"id":13011472},{"batb":[[0,1.93,44.53],[1,1.92,16.13],[2,1.8,19.51]],"batl":[[1,2.14,63.67]],"ltp":0.0,"tv":0.0,"id":16665613}]}]}
{"op":"mcm","clk":"1008972907","pt":1580641201950,"mc":[{"id":"1.168224333","rc":[{"batb":[[0,7.2,11.25],[1,6.8,6.72],[2,1.01,0.51]],"ltp":0.0,"tv":0.0,"id":13011471},{"batb":[[0,4.1,21.48],[1,3.8,14.28],[2,1.01,0.51]],"batl":[[1,5.1,17.07],[2,5.1,0]],"ltp":0.0,"tv":0.0,"id":16665614},{"batb":[[1,5.6,20.22],[2,1.01,0.51]],"batl":[[0,8,5.88],[1,8.4,11.96],[2,8.4,0]],"ltp":0.0,"tv":0.0,"id":13011472},{"batb":[[1,1.8,19.51],[2,1.01,0.51]],"batl":[[0,2.14,63.67],[1,2.14,0]],"ltp":0.0,"tv":0.0,"id":16665613}]}]}
{"op":"mcm","clk":"1008973312","pt":1580641204264,"mc":[{"id":"1.168224333","rc":[{"batb":[[0,8,22.35],[1,7.2,11.25]],"batl":[[0,9.4,9.52],[1,9.4,0]],"ltp":0.0,"tv":0.0,"id":13011471},{"batb":[[1,1.01,0.51],[2,1.01,0]],"batl":[[0,5.1,17.07],[1,5.1,0]],"ltp":0.0,"tv":0.0,"id":16665614},{"batb":[[0,5.6,20.22],[1,1.01,0.51],[2,1.01,0]],"batl":[[0,8.4,11.96],[1,8.4,0]],"ltp":0.0,"tv":0.0,"id":13011472},{"batb":[[0,1.8,19.51],[1,1.01,0.51],[2,1.01,0]],"batl":[[0,2.14,27.54]],"ltp":0.0,"tv":0.0,"id":16665613}]}]}
{"op":"mcm","clk":"1008973484","pt":1580641204988,"mc":[{"id":"1.168224333","rc":[{"batb":[[0,8,32.24],[1,7.8,23.63],[2,7.2,11.25]],"ltp":0.0,"tv":0.0,"id":13011471},{"batb":[[1,3.9,52.4],[2,3.85,29.53]],"ltp":0.0,"tv":0.0,"id":16665614},{"batb":[[0,6.4,34.27],[1,6.2,38.95],[2,5.6,20.22]],"ltp":0.0,"tv":0.0,"id":13011472},{"batb":[[0,1.81,89.19],[1,1.8,19.51],[2,1.79,94.86]],"ltp":0.0,"tv":0.0,"id":16665613}]}]}
{"op":"mcm","clk":"1008973646","pt":1580641205958,"mc":[{"id":"1.168224333","rc":[{"batb":[[0,8,22.35],[1,7.2,11.25],[2,1.01,0.51]],"ltp":0.0,"tv":0.0,"id":13011471},{"batb":[[1,1.01,0.51],[2,3.85,0]],"ltp":0.0,"tv":0.0,"id":16665614},{"batb":[[0,5.6,20.22],[1,1.01,0.51],[2,5.6,0]],"ltp":0.0,"tv":0.0,"id":13011472},{"batb":[[0,1.8,19.51],[1,1.01,0.51],[2,1.79,0]],"ltp":0.0,"tv":0.0,"id":16665613}]}]}
{"op":"mcm","clk":"1008974280","pt":1580641209372,"mc":[{"id":"1.168224333","rc":[{"batb":[[0,8,32.24],[1,7.8,23.63],[2,7.2,11.25]],"batl":[[0,9,10.7],[1,9.2,10.07],[2,9.4,9.52]],"ltp":0.0,"tv":0.0,"id":13011471},{"batb":[[1,4,22.5],[2,3.9,52.4]],"batl":[[0,4.7,20.38],[1,4.9,18.88],[2,5.1,17.07]],"ltp":0.0,"tv":0.0,"id":16665614},{"batb":[[0,6.4,34.27],[1,6.2,38.95],[2,5.6,20.22]],"batl":[[0,6.8,18.8],[1,7.4,15.42],[2,8.4,11.96]],"ltp":0.0,"tv":0.0,"id":13011472},{"batb":[[0,2,114.36],[1,1.98,68.85],[2,1.9,16.44]],"batl":[[1,2.22,25.02]],"ltp":0.0,"tv":0.0,"id":16665613}]}]}
{"op":"mcm","clk":"1008974365","pt":1580641209880,"mc":[{"id":"1.168224333","rc":[{"batl":[[2,9.4,0]],"ltp":0.0,"tv":0.0,"id":13011471},{"batl":[[2,5.1,0]],"ltp":0.0,"tv":0.0,"id":16665614},{"batl":[[2,8.4,0]],"ltp":0.0,"tv":0.0,"id":13011472}]}]}
{"op":"mcm","clk":"1008974489","pt":1580641210667,"mc":[{"id":"1.168224333","rc":[{"batl":[[0,8.6,5.04],[1,9,10.7],[2,9.2,10.07]],"ltp":0.0,"tv":0.0,"id":13011471},{"batl":[[0,4.5,11.76],[1,4.7,20.38],[2,4.9,18.88]],"ltp":0.0,"tv":0.0,"id":16665614},{"batb":[[2,5.9,8.4]],"batl":[[1,7.4,21.3]],"ltp":0.0,"tv":0.0,"id":13011472},{"batb":[[0,2,156.37]],"batl":[[2,2.24,33.61]],"ltp":0.0,"tv":0.0,"id":16665613}]}]}
{"op":"mcm","clk":"1008975684","pt":1580641218208,"mc":[{"id":"1.168224333","rc":[{"batb":[[0,8,13.06]],"ltp":0.0,"tv":0.0,"id":13011471},{"batb":[[2,3.85,29.53]],"ltp":0.0,"tv":0.0,"id":16665614},{"batb":[[0,5.9,8.4],[1,5.6,20.22],[2,5.4,11.17]],"ltp":0.0,"tv":0.0,"id":13011472},{"batb":[[0,2,70.34],[1,1.9,16.44],[2,1.01,0.51]],"ltp":0.0,"tv":0.0,"id":16665613}]}]}
{"op":"mcm","clk":"1008975840","pt":1580641219165,"mc":[{"id":"1.168224333","rc":[{"batb":[[2,7,11.72]],"batl":[[1,9.2,10.07],[2,9.2,0]],"ltp":0.0,"tv":0.0,"id":13011471},{"batb":[[0,4,22.5],[1,3.85,29.53],[2,3.75,15.12]],"batl":[[1,4.9,18.88],[2,4.9,0]],"ltp":0.0,"tv":0.0,"id":16665614},{"batb":[[1,5.4,11.17],[2,1.01,0.51]],"batl":[[0,7.4,21.3],[1,7.4,0]],"ltp":0.0,"tv":0.0,"id":13011472},{"batb":[[0,2,42.01]],"batl":[[0,2.22,25.02],[1,2.24,33.61],[2,2.24,0]],"ltp":0.0,"tv":0.0,"id":16665613}]}]}
{"op":"mcm","clk":"1008975903","pt":1580641219667,"mc":[{"id":"1.168224333","rc":[{"batl":[[0,9.2,10.07],[1,9.2,0]],"ltp":0.0,"tv":0.0,"id":13011471},{"batb":[[2,1.01,0.51]],"batl":[[0,4.9,18.88],[1,4.9,0]],"ltp":0.0,"tv":0.0,"id":16665614},{"batb":[[0,5.4,11.17],[1,1.01,0.51],[2,1.01,0]],"batl":[[0,7.4,15.42]],"ltp":0.0,"tv":0.0,"id":13011472},{"batb":[[0,1.9,16.44],[1,1.01,0.51],[2,1.01,0]],"batl":[[1,2.24,0]],"ltp":0.0,"tv":0.0,"id":16665613}]}]}
{"op":"mcm","clk":"1008976223","pt":1580641221384,"mc":[{"id":"1.168224333","rc":[{"batb":[[1,7,11.72],[2,1.01,0.51]],"ltp":0.0,"tv":0.0,"id":13011471},{"batb":[[1,1.01,0.51],[2,1.01,0]],"ltp":0.0,"tv":0.0,"id":16665614}]}]}
{"op":"mcm","clk":"1008976673","pt":1580641224080,"mc":[{"id":"1.168224333","rc":[{"batb":[[0,8.2,14.74],[1,8,22.75],[2,7,11.72]],"ltp":0.0,"tv":0.0,"id":13011471},{"batb":[[1,3.95,36.38],[2,3.9,28.78]],"ltp":0.0,"tv":0.0,"id":16665614},{"batb":[[0,6.6,17.45],[1,6.4,36.76],[2,5.4,11.17]],"ltp":0.0,"tv":0.0,"id":13011472},{"batb":[[0,1.99,56.11],[1,1.97,69.93],[2,1.9,16.44]],"ltp":0.0,"tv":0.0,"id":16665613}]}]}
{"op":"mcm","clk":"1008977021","pt":1580641226307,"mc":[{"id":"1.168224333","rc":[{"batb":[[0,8,13.06],[1,7,11.72],[2,1.01,0.51]],"ltp":0.0,"tv":0.0,"id":13011471},{"batb":[[1,1.01,0.51],[2,3.9,0]],"ltp":0.0,"tv":0.0,"id":16665614},{"batb":[[0,5.4,11.17],[1,1.01,0.51],[2,5.4,0]],"ltp":0.0,"tv":0.0,"id":13011472},{"batb":[[0,1.9,16.44],[1,1.01,0.51],[2,1.9,0]],"ltp":0.0,"tv":0.0,"id":16665613}]}]}
{"op":"mcm","clk":"1008977464","pt":1580641229184,"mc":[{"id":"1.168224333","rc":[{"batb":[[1,7.8,24.05],[2,7,11.72]],"ltp":0.0,"tv":0.0,"id":13011471},{"batb":[[1,3.85,37.43],[2,3.8,30.6]],"ltp":0.0,"tv":0.0,"id":16665614},{"batb":[[0,6,46.89],[1,5.9,21.92],[2,5.4,11.17]],"ltp":0.0,"tv":0.0,"id":13011472},{"batb":[[0,1.91,87.7],[1,1.9,16.44],[2,1.89,79.57]],"ltp":0.0,"tv":0.0,"id":16665613}]}]}
{"op":"mcm","clk":"1008978010","pt":1580641232897,"mc":[{"id":"1.168224333","rc":[{"batb":[[0,7,11.72],[1,1.01,0.51],[2,7,0]],"ltp":0.0,"tv":0.0,"id":13011471},{"batb":[[1,1.01,0.51],[2,3.8,0]],"ltp":0.0,"tv":0.0,"id":16665614},{"batb":[[0,5.4,11.17],[1,1.01,0.51],[2,5.4,0]],"ltp":0.0,"tv":0.0,"id":13011472}]}]}
{"op":"mcm","clk":"1008978513","pt":1580641236299,"mc":[{"id":"1.168224333","rc":[{"batb":[[0,8.4,15.26],[1,8.2,21.56],[2,7.4,10.54]],"batl":[[1,9.6,9.44]],"ltp":0.0,"tv":0.0,"id":13011471},{"batb":[[0,4.2,19.91],[1,4.1,21.48],[2,4,83.27]],"batl":[[1,5.2,16.6]],"ltp":0.0,"tv":0.0,"id":16665614},{"batb":[[0,7,30.86],[1,6.8,31.88],[2,6.2,16.37]],"batl":[[1,8.8,10.86]],"ltp":0.0,"tv":0.0,"id":13011472},{"batl":[[0,2.02,16.21],[1,2.12,28.25],[2,2.22,25.02]],"ltp":0.0,"tv":0.0,"id":16665613}]}]}
{"op":"mcm","clk":"1008978565","pt":1580641236674,"mc":[{"id":"1.168224333","rc":[{"batl":[[0,9,5.04],[1,9.2,10.07],[2,9.6,9.44]],"ltp":0.0,"tv":0.0,"id":13011471},{"batb":[[2,4,60.77]],"batl":[[0,4.6,10.92],[1,4.9,18.88],[2,5.2,16.6]],"ltp":0.0,"tv":0.0,"id":16665614},{"batb":[[2,6.4,7.56]],"batl":[[1,8,5.88],[2,8.8,10.86]],"ltp":0.0,"tv":0.0,"id":13011472},{"batb":[[0,1.92,45.37],[1,1.91,87.7],[2,1.9,16.44]],"batl":[[2,2.14,36.13]],"ltp":0.0,"tv":0.0,"id":16665613}]}]}
{"op":"mcm","clk":"1008980812","pt":1580641250120,"mc":[{"id":"1.168224333","rc":[{"batb":[[0,7.2,10.94],[1,7,6.72],[2,1.01,0.51]],"batl":[[1,9.6,9.44],[2,9.6,0]],"ltp":0.0,"tv":0.0,"id":13011471},{"batb":[[0,4.1,21.48],[1,3.85,14.28],[2,1.01,0.51]],"batl":[[1,5.2,16.6],[2,5.2,0]],"ltp":0.0,"tv":0.0,"id":16665614},{"batb":[[0,6.4,7.56],[1,5.7,19.59],[2,1.01,0.51]],"batl":[[0,8,5.88],[1,8.8,10.86],[2,8.8,0]],"ltp":0.0,"tv":0.0,"id":13011472},{"batb":[[1,1.77,20.54],[2,1.01,0.51]],"batl":[[0,2.12,28.25],[1,2.14,36.13],[2,2.14,0]],"ltp":0.0,"tv":0.0,"id":16665613}]}]}
{"op":"mcm","clk":"1008981174","pt":1580641251748,"mc":[{"id":"1.168224333","rc":[{"batb":[[1,1.01,0.51],[2,1.01,0]],"batl":[[0,9.6,9.44],[1,9.6,0]],"ltp":0.0,"tv":0.0,"id":13011471},{"batb":[[1,1.01,0.51],[2,1.01,0]],"batl":[[0,5.2,16.6],[1,5.2,0]],"ltp":0.0,"tv":0.0,"id":16665614},{"batb":[[0,5.7,19.59],[1,1.01,0.51],[2,1.01,0]],"batl":[[0,8.8,10.86],[1,8.8,0]],"ltp":0.0,"tv":0.0,"id":13011472},{"batb":[[0,1.77,20.54],[1,1.01,0.51],[2,1.01,0]],"batl":[[1,2.14,0]],"ltp":0.0,"tv":0.0,"id":16665613}]}]}
{"op":"mcm","clk":"1008981440","pt":1580641253317,"mc":[{"id":"1.168224333","rc":[{"batb":[[0,1.01,0.51],[1,1.01,0]],"batl":[[0,9.8,9.05]],"ltp":0.0,"tv":0.0,"id":13011471},{"batb":[[0,4,21.79]],"batl":[[0,5.1,16.92]],"ltp":0.0,"tv":0.0,"id":16665614},{"batb":[[0,5.8,18.73]],"batl":[[0,9,10.39]],"ltp":0.0,"tv":0.0,"id":13011472},{"batb":[[0,1.76,21.01]],"ltp":0.0,"tv":0.0,"id":16665613}]}]}
{"op":"mcm","clk":"1008981994","pt":1580641256748,"mc":[{"id":"1.168224333","rc":[{"batb":[[0,8.4,22.82],[1,8.2,21.4],[2,1.01,0.51]],"ltp":0.0,"tv":0.0,"id":13011471},{"batb":[[0,4.1,27.78],[1,4,75.48],[2,1.01,0.51]],"ltp":0.0,"tv":0.0,"id":16665614},{"batb":[[0,7.2,29.69],[1,7,29.96],[2,5.8,18.73]],"ltp":0.0,"tv":0.0,"id":13011472},{"batb":[[0,1.89,66.02],[1,1.87,82.29],[2,1.76,21.01]],"ltp":0.0,"tv":0.0,"id":16665613}]}]}
{"op":"mcm","clk":"1008982326","pt":1580641258945,"mc":[{"id":"1.168224333","rc":[{"batb":[[0,1.01,0.51],[1,8.2,0],[2,1.01,0]],"ltp":0.0,"tv":0.0,"id":13011471},{"batb":[[0,4,21.79],[1,1.01,0.51],[2,1.01,0]],"ltp":0.0,"tv":0.0,"id":16665614},{"batb":[[0,5.8,18.73],[1,1.01,0.51],[2,5.8,0]],"ltp":0.0,"tv":0.0,"id":13011472},{"batb":[[0,1.76,21.01],[1,1.01,0.51],[2,1.76,0]],"ltp":0.0,"tv":0.0,"id":16665613}]}]}
{"op":"mcm","clk":"1008983033","pt":1580641263169,"mc":[{"id":"1.168224333","rc":[{"batb":[[0,8,33.48],[1,7.8,23.59],[2,1.01,0.51]],"ltp":0.0,"tv":0.0,"id":13011471},{"batb":[[1,3.9,43.44],[2,3.85,29.61]],"ltp":0.0,"tv":0.0,"id":16665614},{"batb":[[0,6.4,30.86],[1,6.2,39.03],[2,5.8,18.73]],"ltp":0.0,"tv":0.0,"id":13011472}]}]}
{"op":"mcm","clk":"1008983300","pt":1580641265251,"mc":[{"id":"1.168224333","rc":[{"batb":[[0,2,102.89],[1,1.98,68.84],[2,1.76,21.01]],"ltp":0.0,"tv":0.0,"id":16665613}]}]}
{"op":"mcm","clk":"1008983482","pt":1580641266364,"mc":[{"id":"1.168224333","rc":[{"batb":[[2,7.4,10.46]],"batl":[[0,9.2,9.99],[1,9.4,9.52]],"ltp":0.0,"tv":0.0,"id":13011471},{"batl":[[0,4.7,20.69],[1,4.8,19.36]],"ltp":0.0,"tv":0.0,"id":16665614},{"batl":[[0,7,17.47],[1,7.8,14.32]],"ltp":0.0,"tv":0.0,"id":13011472},{"batb":[[2,1.97,29.74]],"batl":[[1,2.18,26.04]],"ltp":0.0,"tv":0.0,"id":16665613}]}]}
{"op":"mcm","clk":"1008983524","pt":1580641266684,"mc":[{"id":"1.168224333","rc":[{"batl":[[0,8.6,5.04],[1,9.2,9.99],[2,9.4,9.52]],"ltp":0.0,"tv":0.0,"id":13011471},{"batl":[[0,4.4,11.76],[1,4.7,20.69],[2,4.8,19.36]],"ltp":0.0,"tv":0.0,"id":16665614},{"batb":[[2,6,8.4]],"batl":[[1,7.4,5.88],[2,7.8,14.32]],"ltp":0.0,"tv":0.0,"id":13011472},{"batb":[[0,2,144.9]],"batl":[[2,2.24,33.61]],"ltp":0.0,"tv":0.0,"id":16665613}]}]}
{"op":"mcm","clk":"1008984668","pt":1580641275391,"mc":[{"id":"1.168224333","rc":[{"batb":[[0,8,14.58],[2,7.2,10.94]],"batl":[[1,9.4,9.52],[2,9.4,0]],"ltp":0.0,"tv":0.0,"id":13011471},{"batb":[[1,3.85,29.61],[2,3.75,15.12]],"batl":[[1,4.8,19.36],[2,4.8,0]],"ltp":0.0,"tv":0.0,"id":16665614},{"batb":[[0,6,8.4],[1,5.5,10.54],[2,1.01,0.51]],"batl":[[0,7.4,5.88],[1,7.8,14.32],[2,7.8,0]],"ltp":0.0,"tv":0.0,"id":13011472},{"batb":[[0,2,42.01],[1,1.88,17],[2,1.01,0.51]],"batl":[[0,2.18,26.04],[1,2.24,33.61],[2,2.24,0]],"ltp":0.0,"tv":0.0,"id":16665613}]}]}
{"op":"mcm","clk":"1008984739","pt":1580641275865,"mc":[{"id":"1.168224333","rc":[{"batl":[[0,9.4,9.52],[1,9.4,0]],"ltp":0.0,"tv":0.0,"id":13011471},{"batb":[[2,1.01,0.51]],"batl":[[0,4.8,19.36],[1,4.8,0]],"ltp":0.0,"tv":0.0,"id":16665614},{"batb":[[0,5.5,10.54],[1,1.01,0.51],[2,1.01,0]],"batl":[[0,7.8,14.32],[1,7.8,0]],"ltp":0.0,"tv":0.0,"id":13011472},{"batb":[[0,1.88,17],[1,1.01,0.51],[2,1.01,0]],"batl":[[1,2.24,0]],"ltp":0.0,"tv":0.0,"id":16665613}]}]}
{"op":"mcm","clk":"1008985025","pt":1580641278079,"mc":[{"id":"1.168224333","rc":[{"batb":[[2,3.8,30.67]],"ltp":0.0,"tv":0.0,"id":16665614},{"batb":[[0,6,45.96],[1,5.9,21.93],[2,5.5,10.54]],"ltp":0.0,"tv":0.0,"id":13011472},{"batb":[[0,1.92,78.17],[1,1.9,78.25],[2,1.88,17]],"ltp":0.0,"tv":0.0,"id":16665613}]}]}
{"op":"mcm","clk":"1008986929","pt":1580641292329,"mc":[{"id":"1.168224333","rc":[{"batb":[[0,7.2,10.94],[1,1.01,0.51],[2,7.2,0]],"ltp":0.0,"tv":0.0,"id":13011471},{"batb":[[1,1.01,0.51],[2,3.8,0]],"ltp":0.0,"tv":0.0,"id":16665614},{"batb":[[0,5.5,10.54],[1,1.01,0.51],[2,5.5,0]],"ltp":0.0,"tv":0.0,"id":13011472}]}]}
{"op":"mcm","clk":"1008987379","pt":1580641295329,"mc":[{"id":"1.168224333","rc":[{"batb":[[0,8.4,16.03],[1,8.2,21.54],[2,7.2,10.94]],"ltp":0.0,"tv":0.0,"id":13011471},{"batb":[[0,4,71.49],[1,3.95,27.81],[2,1.01,0.51]],"ltp":0.0,"tv":0.0,"id":16665614},{"batb":[[0,7,23.65],[1,6.8,32.06],[2,5.5,10.54]],"ltp":0.0,"tv":0.0,"id":13011472}]}]}
{"op":"mcm","clk":"1008987477","pt":1580641295916,"mc":[{"id":"1.168224333","rc":[{"batb":[[2,7.6,9.99]],"batl":[[1,9.8,8.73]],"ltp":0.0,"tv":0.0,"id":13011471},{"batb":[[0,4.1,20.38],[1,4,71.49],[2,3.95,27.81]],"batl":[[1,5.2,16.6]],"ltp":0.0,"tv":0.0,"id":16665614},{"batb":[[2,6.4,15.26]],"batl":[[1,9.2,9.91]],"ltp":0.0,"tv":0.0,"id":13011472},{"batl":[[0,2,16.68],[1,2.12,28.33]],"ltp":0.0,"tv":0.0,"id":16665613}]}]}
{"op":"mcm","clk":"1008987591","pt":1580641296717,"mc":[{"id":"1.168224333","rc":[{"batl":[[0,9,5.04],[1,9.4,9.52],[2,9.8,8.73]],"ltp":0.0,"tv":0.0,"id":13011471},{"batl":[[0,4.5,11.76],[1,4.8,19.36],[2,5.2,16.6]],"ltp":0.0,"tv":0.0,"id":16665614},{"batb":[[2,6.4,22.83]],"batl":[[1,8,5.88],[2,9.2,9.91]],"ltp":0.0,"tv":0.0,"id":13011472},{"batb":[[0,1.92,123.54]],"batl":[[2,2.14,36.13]],"ltp":0.0,"tv":0.0,"id":16665613}]}]}
{"op":"mcm","clk":"1008989485","pt":1580641309804,"mc":[{"id":"1.168224333","rc":[{"batb":[[0,7.4,10.7],[1,7,6.72],[2,1.01,0.51]],"batl":[[1,9.8,8.73],[2,9.8,0]],"ltp":0.0,"tv":0.0,"id":13011471},{"batb":[[0,4,21.79],[1,3.8,14.28],[2,1.01,0.51]],"batl":[[1,5.2,16.6],[2,5.2,0]],"ltp":0.0,"tv":0.0,"id":16665614},{"batb":[[0,6.4,7.56],[1,5.8,18.65],[2,1.01,0.51]],"batl":[[0,8,5.88],[1,9.2,9.91],[2,9.2,0]],"ltp":0.0,"tv":0.0,"id":13011472},{"batb":[[0,1.92,45.37],[1,1.74,21.79],[2,1.01,0.51]],"batl":[[0,2.12,28.33],[1,2.14,36.13],[2,2.14,0]],"ltp":0.0,"tv":0.0,"id":16665613}]}]}
{"op":"mcm","clk":"1008989773","pt":1580641312027,"mc":[{"id":"1.168224333","rc":[{"batb":[[1,1.01,0.51],[2,1.01,0]],"batl":[[0,9.8,8.73],[1,9.8,0]],"ltp":0.0,"tv":0.0,"id":13011471},{"batb":[[1,1.01,0.51],[2,1.01,0]],"batl":[[0,5.2,16.6],[1,5.2,0]],"ltp":0.0,"tv":0.0,"id":16665614},{"batb":[[0,5.8,18.65],[1,1.01,0.51],[2,1.01,0]],"batl":[[0,9.2,9.91],[1,9.2,0]],"ltp":0.0,"tv":0.0,"id":13011472},{"batb":[[0,1.74,21.79],[1,1.01,0.51],[2,1.01,0]],"batl":[[1,2.14,0]],"ltp":0.0,"tv":0.0,"id":16665613}]}]}
{"op":"mcm","clk":"1008989881","pt":1580641312813,"mc":[{"id":"1.168224333","rc":[{"batb":[[0,8,30.87],[1,7.8,23.65],[2,7.4,10.7]],"ltp":0.0,"tv":0.0,"id":13011471},{"batb":[[1,3.85,47.38],[2,3.8,30.52]],"ltp":0.0,"tv":0.0,"id":16665614},{"batb":[[0,6.2,48.35],[1,6,41.48],[2,5.8,18.65]],"ltp":0.0,"tv":0.0,"id":13011472},{"batb":[[0,1.78,84.35],[1,1.76,100.35],[2,1.74,21.79]],"ltp":0.0,"tv":0.0,"id":16665613}]}]}
{"op":"mcm","clk":"1008990067","pt":1580641314190,"mc":[{"id":"1.168224333","rc":[{"batb":[[0,1.74,21.79],[1,1.01,0.51],[2,1.74,0]],"ltp":0.0,"tv":0.0,"id":16665613}]}]}
{"op":"mcm","clk":"1008990382","pt":1580641316530,"mc":[{"id":"1.168224333","rc":[{"batb":[[0,2.04,50.93],[1,2.02,64.81],[2,1.74,21.79]],"ltp":0.0,"tv":0.0,"id":16665613}]}]}
{"op":"mcm","clk":"1008990573","pt":1580641317717,"mc":[{"id":"1.168224333","rc":[{"batl":[[0,9.2,10.15],[1,9.4,9.76]],"ltp":0.0,"tv":0.0,"id":13011471},{"batb":[[2,3.8,56.09]],"batl":[[0,4.6,21.09],[1,4.8,19.91]],"ltp":0.0,"tv":0.0,"id":16665614},{"batl":[[0,7,17.47],[1,7.6,14.79]],"ltp":0.0,"tv":0.0,"id":13011472},{"batb":[[2,1.98,29.19]],"batl":[[1,2.34,21.72]],"ltp":0.0,"tv":0.0,"id":16665613}]}]}
{"op":"mcm","clk":"1008990739","pt":1580641318718,"mc":[{"id":"1.168224333","rc":[{"batl":[[0,8.4,5.04],[1,9.2,10.15],[2,9.4,9.76]],"ltp":0.0,"tv":0.0,"id":13011471},{"batl":[[0,4.4,11.76],[1,4.6,21.09],[2,4.8,19.91]],"ltp":0.0,"tv":0.0,"id":16665614},{"batb":[[2,5.8,27.05]],"batl":[[1,7.2,6.72],[2,7.6,14.79]],"ltp":0.0,"tv":0.0,"id":13011472},{"batb":[[0,2.04,91.26]],"batl":[[1,2.28,32.77],[2,2.34,21.72]],"ltp":0.0,"tv":0.0,"id":16665613}]}]}
{"op":"mcm","clk":"1008991058","pt":1580641321021,"mc":[{"id":"1.168224333","rc":[{"batb":[[0,7.4,10.7],[1,7.2,11.49],[2,6.6,6.72]],"ltp":0.0,"tv":0.0,"id":13011471},{"batb":[[1,3.8,25.57],[2,3.7,15.12]],"ltp":0.0,"tv":0.0,"id":16665614},{"batb":[[0,5.8,27.05],[1,5.1,12.75],[2,1.01,0.51]],"ltp":0.0,"tv":0.0,"id":13011472},{"batb":[[0,2.04,40.33],[1,1.98,29.19],[2,1.91,16.37]],"ltp":0.0,"tv":0.0,"id":16665613}]}]}
{"op":"mcm","clk":"1008992013","pt":1580641328119,"mc":[{"id":"1.168224333","rc":[{"trd":[[2.04,53.37]],"batb":[[0,2.04,13.64]],"ltp":2.04,"tv":53.36,"id":16665613}],"tv":53.36}]}
{"op":"mcm","clk":"1008992052","pt":1580641328450,"mc":[{"id":"1.168224333","rc":[{"batb":[[2,1.01,0.51]],"ltp":0.0,"tv":0.0,"id":13011471},{"batb":[[2,1.01,0.51]],"ltp":0.0,"tv":0.0,"id":16665614},{"batb":[[0,5.8,18.65]],"ltp":0.0,"tv":0.0,"id":13011472},{"batl":[[1,2.34,21.72],[2,2.34,0]],"ltp":2.04,"tv":53.36,"id":16665613}]}]}
{"op":"mcm","clk":"1008992185","pt":1580641329462,"mc":[{"id":"1.168224333","rc":[{"batb":[[0,8,30.87],[1,7.8,23.65],[2,7.4,10.7]],"ltp":0.0,"tv":0.0,"id":13011471},{"batb":[[1,3.85,47.38],[2,3.8,56.09]],"ltp":0.0,"tv":0.0,"id":16665614},{"batb":[[0,6.2,48.35],[1,6,41.48],[2,5.8,18.65]],"ltp":0.0,"tv":0.0,"id":13011472},{"batb":[[0,2.04,64.57],[1,2.02,64.81],[2,1.98,29.19]],"ltp":2.04,"tv":53.36,"id":16665613}]}]}
{"op":"mcm","clk":"1008992441","pt":1580641331370,"mc":[{"id":"1.168224333","rc":[{"batb":[[2,3.8,70.37]],"ltp":0.0,"tv":0.0,"id":16665614},{"batb":[[1,6,49.88]],"ltp":0.0,"tv":0.0,"id":13011472},{"batb":[[0,2.04,90.62]],"batl":[[1,2.24,33.61],[2,2.34,21.72]],"ltp":2.04,"tv":53.36,"id":16665613}]}]}
{"op":"mcm","clk":"1008995471","pt":1580641353378,"mc":[{"id":"1.168224333","rc":[{"batb":[[0,7.4,10.7],[1,7.2,11.49],[2,6.8,6.72]],"ltp":0.0,"tv":0.0,"id":13011471},{"batb":[[1,3.8,39.85],[2,1.01,0.51]],"ltp":0.0,"tv":0.0,"id":16665614},{"batb":[[0,6,8.4],[1,5.8,18.65],[2,5.1,12.75]],"ltp":0.0,"tv":0.0,"id":13011472},{"batb":[[0,2.04,39.69],[1,1.98,29.19],[2,1.91,16.37]],"ltp":2.04,"tv":53.36,"id":16665613}]}]}
{"op":"mcm","clk":"1008995545","pt":1580641353856,"mc":[{"id":"1.168224333","rc":[{"batb":[[0,7.2,11.49],[1,1.01,0.51],[2,6.8,0]],"batl":[[0,9.4,9.76],[1,9.2,0],[2,9.4,0]],"ltp":0.0,"tv":0.0,"id":13011471},{"batb":[[0,3.8,25.57],[1,1.01,0.51],[2,1.01,0]],"batl":[[0,4.8,19.91],[1,4.6,0],[2,4.8,0]],"ltp":0.0,"tv":0.0,"id":16665614},{"batb":[[0,5.1,12.75],[1,1.01,0.51],[2,5.1,0]],"batl":[[0,7.6,14.79],[1,7.2,0],[2,7.6,0]],"ltp":0.0,"tv":0.0,"id":13011472},{"batb":[[0,1.91,16.37],[1,1.01,0.51],[2,1.91,0]],"batl":[[0,2.34,21.72],[1,2.24,0],[2,2.34,0]],"ltp":2.04,"tv":53.36,"id":16665613}]}]}
{"op":"mcm","clk":"1008995881","pt":1580641356387,"mc":[{"id":"1.168224333","rc":[{"batb":[[0,7.6,37.91],[1,7.4,26.36],[2,7.2,11.49]],"ltp":0.0,"tv":0.0,"id":13011471},{"batb":[[1,3.65,51.96],[2,3.6,34.71]],"ltp":0.0,"tv":0.0,"id":16665614},{"batb":[[0,5.5,22.37],[1,5.4,27.13],[2,5.1,12.75]],"ltp":0.0,"tv":0.0,"id":13011472},{"batb":[[0,1.95,53.69],[1,1.93,74.49],[2,1.91,16.37]],"ltp":2.04,"tv":53.36,"id":16665613}]}]}
{"op":"mcm","clk":"1008995911","pt":1580641356605,"mc":[{"id":"1.168224333","rc":[{"batb":[[0,7.2,11.49],[1,1.01,0.51],[2,7.2,0]],"ltp":0.0,"tv":0.0,"id":13011471},{"batb":[[1,1.01,0.51],[2,3.6,0]],"ltp":0.0,"tv":0.0,"id":16665614},{"batb":[[0,5.1,12.75],[1,1.01,0.51],[2,5.1,0]],"ltp":0.0,"tv":0.0,"id":13011472},{"batb":[[0,1.91,16.37],[1,1.01,0.51],[2,1.91,0]],"ltp":2.04,"tv":53.36,"id":16665613}]}]}
{"op":"mcm","clk":"1008996196","pt":1580641358783,"mc":[{"id":"1.168224333","rc":[{"batb":[[0,8,22.27],[1,7.8,23.85],[2,7.2,11.49]],"ltp":0.0,"tv":0.0,"id":13011471},{"batb":[[0,3.8,79.05],[1,3.75,31.44],[2,1.01,0.51]],"ltp":0.0,"tv":0.0,"id":16665614},{"batb":[[0,6,53.46],[1,5.9,21.83],[2,5.1,12.75]],"ltp":0.0,"tv":0.0,"id":13011472},{"batb":[[0,2.06,100.18],[1,2.04,62.88],[2,1.91,16.37]],"ltp":2.04,"tv":53.36,"id":16665613}]}]}
{"op":"mcm","clk":"1008997144","pt":1580641365907,"mc":[{"id":"1.168224333","rc":[{"batb":[[0,7.2,11.49],[1,1.01,0.51],[2,7.2,0]],"ltp":0.0,"tv":0.0,"id":13011471},{"batb":[[0,3.8,25.57],[1,1.01,0.51],[2,1.01,0]],"ltp":0.0,"tv":0.0,"id":16665614},{"batb":[[0,5.1,12.75],[1,1.01,0.51],[2,5.1,0]],"ltp":0.0,"tv":0.0,"id":13011472},{"batb":[[0,1.91,16.37],[1,1.01,0.51],[2,1.91,0]],"ltp":2.04,"tv":53.36,"id":16665613}]}]}
{"op":"mcm","clk":"1008997625","pt":1580641369328,"mc":[{"id":"1.168224333","rc":[{"batb":[[0,7.6,37.91],[1,7.4,26.36],[2,7.2,11.49]],"ltp":0.0,"tv":0.0,"id":13011471},{"batb":[[1,3.65,51.96],[2,3.6,34.71]],"ltp":0.0,"tv":0.0,"id":16665614},{"batb":[[0,5.5,22.37],[1,5.4,27.13],[2,5.1,12.75]],"ltp":0.0,"tv":0.0,"id":13011472},{"batb":[[0,1.95,53.69],[1,1.93,74.49],[2,1.91,16.37]],"ltp":2.04,"tv":53.36,"id":16665613}]}]}
{"op":"mcm","clk":"1009000401","pt":1580641390028,"mc":[{"id":"1.168224333","rc":[{"batb":[[0,1.91,16.37],[1,1.01,0.51],[2,1.91,0]],"ltp":2.04,"tv":53.36,"id":16665613}]}]}
{"op":"mcm","clk":"1009000813","pt":1580641393023,"mc":[{"id":"1.168224333","rc":[{"batb":[[0,2.22,84.92],[1,2.2,50.4],[2,1.91,16.37]],"ltp":2.04,"tv":53.36,"id":16665613}]}]}
{"op":"mcm","clk":"1009000971","pt":1580641394246,"mc":[{"id":"1.168224333","rc":[{"batb":[[2,6.8,12.59]],"batl":[[0,8.8,10.86],[1,9,10.46]],"ltp":0.0,"tv":0.0,"id":13011471},{"batl":[[0,4.4,24.16],[1,4.6,21.79]],"ltp":0.0,"tv":0.0,"id":16665614},{"batl":[[0,5.9,12.27],[1,6.6,19.51]],"ltp":0.0,"tv":0.0,"id":13011472},{"batb":[[2,2.16,22.27]],"batl":[[1,2.72,14.56]],"ltp":2.04,"tv":53.36,"id":16665613}]}]}
{"op":"mcm","clk":"1009001047","pt":1580641394789,"mc":[{"id":"1.168224333","rc":[{"batl":[[0,8,5.88],[1,8.8,10.86],[2,9,10.46]],"ltp":0.0,"tv":0.0,"id":13011471},{"batb":[[1,3.65,67.08]],"batl":[[0,4.2,12.6],[1,4.4,24.16],[2,4.6,21.79]],"ltp":0.0,"tv":0.0,"id":16665614},{"batb":[[2,5.3,9.24]],"batl":[[1,6.4,7.56],[2,6.6,19.51]],"ltp":0.0,"tv":0.0,"id":13011472},{"batb":[[1,2.2,84.85]],"batl":[[1,2.42,29.41],[2,2.72,14.56]],"ltp":2.04,"tv":53.36,"id":16665613}]}]}
{"op":"mcm","clk":"1009001948","pt":1580641400988,"mc":[{"id":"1.168224333","rc":[{"batb":[[0,7.6,25.46],[1,6.8,12.59],[2,6.6,6.72]],"ltp":0.0,"tv":0.0,"id":13011471},{"batb":[[0,2.22,63.44]],"ltp":2.04,"tv":53.36,"id":16665613}]}]}
{"op":"mcm","clk":"1009002301","pt":1580641404004,"mc":[{"id":"1.168224333","rc":[{"batb":[[0,7.8,14.16],[1,7.6,25.46],[2,6.8,12.59]],"ltp":0.0,"tv":0.0,"id":13011471},{"batb":[[0,5.5,30.45]],"ltp":0.0,"tv":0.0,"id":13011472}]}]}
{"op":"mcm","clk":"1009002766","pt":1580641406316,"mc":[{"id":"1.168224333","rc":[{"batb":[[0,6.8,12.59],[1,6.6,6.72],[2,1.01,0.51]],"batl":[[1,9,10.46],[2,9,0]],"ltp":0.0,"tv":0.0,"id":13011471},{"batb":[[0,3.65,15.12],[1,3.55,15.19],[2,1.01,0.51]],"batl":[[1,4.6,21.79],[2,4.6,0]],"ltp":0.0,"tv":0.0,"id":16665614},{"batb":[[0,5.3,9.24],[1,4.3,19.2],[2,1.01,0.51]],"batl":[[0,6.4,7.56],[1,6.6,19.51],[2,6.6,0]],"ltp":0.0,"tv":0.0,"id":13011472},{"batb":[[0,2.2,34.45],[1,2.02,26.91],[2,1.01,0.51]],"batl":[[0,2.42,29.41],[1,2.72,14.56],[2,2.72,0]],"ltp":2.04,"tv":53.36,"id":16665613}]}]}
{"op":"mcm","clk":"1009002983","pt":1580641407840,"mc":[{"id":"1.168224333","rc":[{"batb":[[1,1.01,0.51],[2,1.01,0]],"batl":[[0,9,10.46],[1,9,0]],"ltp":0.0,"tv":0.0,"id":13011471},{"batb":[[0,3.55,15.19],[1,1.01,0.51],[2,1.01,0]],"batl":[[0,4.6,21.79],[1,4.6,0]],"ltp":0.0,"tv":0.0,"id":16665614},{"batb":[[0,4.3,19.2],[1,1.01,0.51],[2,1.01,0]],"batl":[[0,6.6,19.51],[1,6.6,0]],"ltp":0.0,"tv":0.0,"id":13011472},{"batb":[[0,2.02,26.91],[1,1.01,0.51],[2,1.01,0]],"batl":[[0,2.72,14.56],[1,2.72,0]],"ltp":2.04,"tv":53.36,"id":16665613}]}]}
{"op":"mcm","clk":"1009003658","pt":1580641412305,"mc":[{"id":"1.168224333","rc":[{"batb":[[0,7.6,28.92],[1,7.4,26.63],[2,6.8,12.59]],"ltp":0.0,"tv":0.0,"id":13011471},{"batb":[[0,3.6,56.94],[1,3.55,51.11],[2,1.01,0.51]],"ltp":0.0,"tv":0.0,"id":16665614},{"batb":[[0,5.3,33.43],[1,5.2,29.49],[2,4.3,19.2]],"ltp":0.0,"tv":0.0,"id":13011472},{"batb":[[0,2.28,60.3],[1,2.26,46.69],[2,2.02,26.91]],"ltp":2.04,"tv":53.36,"id":16665613}]}]}
{"op":"mcm","clk":"1009004064","pt":1580641414531,"mc":[{"id":"1.168224333","rc":[{"batb":[[0,6.8,12.59],[1,1.01,0.51],[2,6.8,0]],"ltp":0.0,"tv":0.0,"id":13011471},{"batb":[[0,3.55,15.19],[1,1.01,0.51],[2,1.01,0]],"ltp":0.0,"tv":0.0,"id":16665614},{"batb":[[0,4.3,19.2],[1,1.01,0.51],[2,4.3,0]],"ltp":0.0,"tv":0.0,"id":13011472},{"batb":[[0,2.02,26.91],[1,1.01,0.51],[2,2.02,0]],"ltp":2.04,"tv":53.36,"id":16665613}]}]}
{"op":"mcm","clk":"1009004464","pt":1580641417536,"mc":[{"id":"1.168224333","rc":[{"batb":[[0,7.2,40.63],[1,7,29.79],[2,6.8,12.59]],"ltp":0.0,"tv":0.0,"id":13011471},{"batb":[[1,3.4,66.66],[2,3.35,41.33]],"ltp":0.0,"tv":0.0,"id":16665614},{"batb":[[0,4.6,56.29],[1,4.5,40.62],[2,4.3,19.2]],"ltp":0.0,"tv":0.0,"id":13011472},{"batb":[[0,2.06,109.58],[1,2.04,62.83],[2,2.02,26.91]],"ltp":2.04,"tv":53.36,"id":16665613}]}]}
{"op":"mcm","clk":"1009004793","pt":1580641419809,"mc":[{"id":"1.168224333","rc":[{"batb":[[0,6.8,12.59],[1,1.01,0.51],[2,6.8,0]],"ltp":0.0,"tv":0.0,"id":13011471},{"batb":[[1,1.01,0.51],[2,3.35,0]],"ltp":0.0,"tv":0.0,"id":16665614},{"batb":[[0,4.3,19.2],[1,1.01,0.51],[2,4.3,0]],"ltp":0.0,"tv":0.0,"id":13011472}]}]}
{"op":"mcm","clk":"1009005340","pt":1580641423346,"mc":[{"id":"1.168224333","rc":[{"batb":[[0,8,19.68],[1,7.8,23.94],[2,7.2,11.02]],"batl":[[0,8.2,5.04],[1,9,10.46],[2,9.2,10.07]],"ltp":0.0,"tv":0.0,"id":13011471},{"batb":[[0,3.95,22.98],[1,3.8,53.49],[2,3.75,46.6]],"batl":[[0,4.3,12.6],[1,4.6,21.79],[2,4.7,20.3]],"ltp":0.0,"tv":0.0,"id":16665614},{"batb":[[0,6,50.78],[1,5.9,21.97],[2,5.7,8.4]],"batl":[[1,7.4,15.74]],"ltp":0.0,"tv":0.0,"id":13011472},{"batb":[[0,2.08,38.65],[1,2.06,109.58],[2,2.04,62.83]],"batl":[[0,2.18,26.2],[1,2.48,18.65]],"ltp":2.04,"tv":53.36,"id":16665613}]}]}
{"op":"mcm","clk":"1009005687","pt":1580641425729,"mc":[{"id":"1.168224333","rc":[{"batl":[[1,7,6.72],[2,7.4,15.74]],"ltp":0.0,"tv":0.0,"id":13011472},{"batl":[[1,2.3,31.93],[2,2.48,18.65]],"ltp":2.04,"tv":53.36,"id":16665613}]}]}
{"op":"mcm","clk":"1009006973","pt":1580641435048,"mc":[{"id":"1.168224333","rc":[{"batb":[[0,7,12.12],[1,6.8,6.72],[2,1.01,0.51]],"batl":[[1,9.2,10.07],[2,9.2,0]],"ltp":0.0,"tv":0.0,"id":13011471},{"batb":[[0,3.75,15.12],[1,3.7,13.61],[2,1.01,0.51]],"batl":[[1,4.7,20.3],[2,4.7,0]],"ltp":0.0,"tv":0.0,"id":16665614},{"batb":[[0,5.7,8.4],[1,4.7,14.95],[2,1.01,0.51]],"batl":[[0,7,6.72],[1,7.4,15.74],[2,7.4,0]],"ltp":0.0,"tv":0.0,"id":13011472},{"batb":[[1,1.93,15.58],[2,1.01,0.51]],"batl":[[0,2.3,31.93],[1,2.48,18.65],[2,2.48,0]],"ltp":2.04,"tv":53.36,"id":16665613}]}]}
{"op":"mcm","clk":"1009007083","pt":1580641435738,"mc":[{"id":"1.168224333","rc":[{"batb":[[1,1.01,0.51],[2,1.01,0]],"batl":[[0,9.2,10.07],[1,9.2,0]],"ltp":0.0,"tv":0.0,"id":13011471},{"batb":[[0,3.7,13.61],[1,1.01,0.51],[2,1.01,0]],"batl":[[0,4.7,20.3],[1,4.7,0]],"ltp":0.0,"tv":0.0,"id":16665614},{"batb":[[0,4.7,14.95],[1,1.01,0.51],[2,1.01,0]],"batl":[[0,7.4,15.74],[1,7.4,0]],"ltp":0.0,"tv":0.0,"id":13011472},{"batb":[[0,1.93,15.58],[1,1.01,0.51],[2,1.01,0]],"batl":[[0,2.48,18.65],[1,2.48,0]],"ltp":2.04,"tv":53.36,"id":16665613}]}]}
{"op":"mcm","clk":"1009007960","pt":1580641442356,"mc":[{"id":"1.168224333","rc":[{"batb":[[0,8.2,23.73],[1,8,22.57],[2,7.4,10.54]],"batl":[[1,9.4,9.6]],"ltp":0.0,"tv":0.0,"id":13011471},{"batb":[[0,4.1,21.32],[1,3.95,46.87],[2,3.9,52.71]],"batl":[[1,4.9,18.73]],"ltp":0.0,"tv":0.0,"id":16665614},{"batb":[[0,6.8,18.98],[1,6.6,34.49],[2,6,16.76]],"batl":[[1,8,13.61]],"ltp":0.0,"tv":0.0,"id":13011472},{"batb":[[0,1.96,68.11],[1,1.94,73.26],[2,1.93,15.58]],"batl":[[0,2.06,30.76],[1,2.26,23.92]],"ltp":2.04,"tv":53.36,"id":16665613}]}]}
{"op":"mcm","clk":"1009008059","pt":1580641442940,"mc":[{"id":"1.168224333","rc":[{"batl":[[0,8.6,5.04],[1,9.2,10.07],[2,9.4,9.6]],"ltp":0.0,"tv":0.0,"id":13011471},{"batl":[[0,4.4,11.76],[1,4.7,20.3],[2,4.9,18.73]],"ltp":0.0,"tv":0.0,"id":16665614},{"batb":[[2,6.2,7.56]],"batl":[[1,7.6,5.88],[2,8,13.61]],"ltp":0.0,"tv":0.0,"id":13011472},{"batb":[[0,1.97,42.85],[1,1.96,68.11],[2,1.94,73.26]],"batl":[[1,2.18,35.29],[2,2.26,23.92]],"ltp":2.04,"tv":53.36,"id":16665613}]}]}
{"op":"mcm","clk":"1009009452","pt":1580641453251,"mc":[{"id":"1.168224333","rc":[{"batb":[[0,7.2,11.33],[1,7,6.72],[2,1.01,0.51]],"batl":[[1,9.4,9.6],[2,9.4,0]],"ltp":0.0,"tv":0.0,"id":13011471},{"batb":[[0,3.9,24],[1,3.85,14.28],[2,1.01,0.51]],"batl":[[1,4.9,18.73],[2,4.9,0]],"ltp":0.0,"tv":0.0,"id":16665614},{"batb":[[0,6.2,7.56],[1,5.3,11.57],[2,1.01,0.51]],"batl":[[0,7.6,5.88],[1,8,13.61],[2,8,0]],"ltp":0.0,"tv":0.0,"id":13011472},{"batb":[[1,1.86,17.62],[2,1.01,0.51]],"batl":[[0,2.18,35.29],[1,2.26,23.92],[2,2.26,0]],"ltp":2.04,"tv":53.36,"id":16665613}]}]}
{"op":"mcm","clk":"1009009576","pt":1580641454162,"mc":[{"id":"1.168224333","rc":[{"batb":[[1,1.01,0.51],[2,1.01,0]],"batl":[[0,9.4,9.6],[1,9.4,0]],"ltp":0.0,"tv":0.0,"id":13011471},{"batb":[[1,1.01,0.51],[2,1.01,0]],"batl":[[0,4.9,18.73],[1,4.9,0]],"ltp":0.0,"tv":0.0,"id":16665614},{"batb":[[0,5.3,11.57],[1,1.01,0.51],[2,1.01,0]],"batl":[[0,8,13.61],[1,8,0]],"ltp":0.0,"tv":0.0,"id":13011472},{"batb":[[0,1.86,17.62],[1,1.01,0.51],[2,1.01,0]],"batl":[[0,2.26,23.92],[1,2.26,0]],"ltp":2.04,"tv":53.36,"id":16665613}]}]}
{"op":"mcm","clk":"1009009832","pt":1580641455759,"mc":[{"id":"1.168224333","rc":[{"batb":[[0,7.8,30.28],[1,7.6,25.08],[2,7.2,11.33]],"ltp":0.0,"tv":0.0,"id":13011471},{"batb":[[1,3.75,53.74],[2,3.7,32.51]],"ltp":0.0,"tv":0.0,"id":16665614},{"batb":[[0,5.9,21.32],[1,5.8,23.25],[2,5.3,11.57]],"ltp":0.0,"tv":0.0,"id":13011472},{"batb":[[0,1.88,82.84],[1,1.86,101.26],[2,1.01,0.51]],"ltp":2.04,"tv":53.36,"id":16665613}]}]}
{"op":"mcm","clk":"1009010268","pt":1580641459090,"mc":[{"id":"1.168224333","rc":[{"batb":[[0,7.2,11.33],[1,1.01,0.51],[2,7.2,0]],"ltp":0.0,"tv":0.0,"id":13011471},{"batb":[[1,1.01,0.51],[2,3.7,0]],"ltp":0.0,"tv":0.0,"id":16665614},{"batb":[[0,5.3,11.57],[1,1.01,0.51],[2,5.3,0]],"ltp":0.0,"tv":0.0,"id":13011472},{"batb":[[0,1.86,17.62],[1,1.01,0.51],[2,1.01,0]],"ltp":2.04,"tv":53.36,"id":16665613}]}]}
{"op":"mcm","clk":"1009010723","pt":1580641462161,"mc":[{"id":"1.168224333","rc":[{"batb":[[0,8.4,23.22],[1,8.2,21.4],[2,7.2,11.33]],"ltp":0.0,"tv":0.0,"id":13011471},{"batb":[[0,4,78.67],[1,3.95,27.56],[2,3.9,24]],"ltp":0.0,"tv":0.0,"id":16665614},{"batb":[[0,7.4,16.67],[1,7.2,28.61],[2,5.3,11.57]],"ltp":0.0,"tv":0.0,"id":13011472},{"batb":[[0,1.88,82.84],[1,1.86,101.26],[2,1.01,0.51]],"ltp":2.04,"tv":53.36,"id":16665613}]}]}
{"op":"mcm","clk":"1009010875","pt":1580641463275,"mc":[{"id":"1.168224333","rc":[{"batb":[[2,7.4,10.62]],"batl":[[0,8.8,5.04],[1,9.4,9.6],[2,9.6,9.28]],"ltp":0.0,"tv":0.0,"id":13011471},{"batb":[[0,4.2,19.75],[1,4.1,21.48],[2,4,78.67]],"batl":[[0,4.5,11.76],[1,4.9,18.25]],"ltp":0.0,"tv":0.0,"id":16665614},{"batb":[[2,6.6,6.72]],"batl":[[1,8.2,5.04],[2,8.4,12.12]],"ltp":0.0,"tv":0.0,"id":13011472},{"batb":[[0,1.91,45.37],[1,1.88,82.84],[2,1.86,101.26]],"batl":[[0,1.98,17.31],[1,2.1,67.47]],"ltp":2.04,"tv":53.36,"id":16665613}]}]}
{"op":"mcm","clk":"1009011740","pt":1580641468698,"mc":[{"id":"1.168224333","rc":[{"batb":[[0,8.2,21.4],[1,7.4,10.62],[2,7,6.72]],"batl":[[1,9.6,9.28],[2,9.6,0]],"ltp":0.0,"tv":0.0,"id":13011471},{"batb":[[0,4.1,21.48],[1,3.95,41],[2,1.01,0.51]],"ltp":0.0,"tv":0.0,"id":16665614},{"batb":[[0,6.6,6.72],[1,5.9,17.86],[2,1.01,0.51]],"batl":[[0,8.2,5.04],[1,8.4,12.12],[2,8.4,0]],"ltp":0.0,"tv":0.0,"id":13011472},{"batb":[[1,1.82,18.88],[2,1.01,0.51]],"batl":[[0,2.1,67.47],[1,2.1,0]],"ltp":2.04,"tv":53.36,"id":16665613}]}]}
{"op":"mcm","clk":"1009011901","pt":1580641469771,"mc":[{"id":"1.168224333","rc":[{"batb":[[2,1.01,0.51]],"batl":[[0,9.6,9.28],[1,9.6,0]],"ltp":0.0,"tv":0.0,"id":13011471},{"batb":[[1,3.95,27.56]],"batl":[[0,4.9,18.25],[1,4.9,0]],"ltp":0.0,"tv":0.0,"id":16665614},{"batb":[[0,5.9,17.86],[1,1.01,0.51],[2,1.01,0]],"batl":[[0,8.4,12.12],[1,8.4,0]],"ltp":0.0,"tv":0.0,"id":13011472},{"batb":[[0,1.82,18.88],[1,1.01,0.51],[2,1.01,0]],"batl":[[0,2.1,29.66]],"ltp":2.04,"tv":53.36,"id":16665613}]}]}
{"op":"mcm","clk":"1009012193","pt":1580641471784,"mc":[{"id":"1.168224333","rc":[{"batb":[[0,7.4,10.62],[1,1.01,0.51],[2,1.01,0]],"ltp":0.0,"tv":0.0,"id":13011471},{"batb":[[1,1.01,0.51],[2,1.01,0]],"ltp":0.0,"tv":0.0,"id":16665614},{"batb":[[0,1.84,88.12],[1,1.82,18.88],[2,1.01,0.51]],"ltp":2.04,"tv":53.36,"id":16665613}]}]}
{"op":"mcm","clk":"1009012564","pt":1580641474381,"mc":[{"id":"1.168224333","rc":[{"batb":[[0,8.6,16.18],[1,8.4,20.46],[2,7.4,10.62]],"ltp":0.0,"tv":0.0,"id":13011471},{"batb":[[0,4.1,75.08],[1,4,53.25],[2,1.01,0.51]],"ltp":0.0,"tv":0.0,"id":16665614},{"batb":[[0,7.6,38.22],[1,7.4,26.46],[2,5.9,17.86]],"ltp":0.0,"tv":0.0,"id":13011472}]}]}
{"op":"mcm","clk":"1009012705","pt":1580641475379,"mc":[{"id":"1.168224333","rc":[{"batb":[[2,7.6,9.76]],"batl":[[0,9,5.04],[1,9.6,9.28],[2,10,8.42]],"ltp":0.0,"tv":0.0,"id":13011471},{"batb":[[0,4.3,19.2],[1,4.1,74.92],[2,4,53.25]],"batl":[[0,4.6,10.92],[1,4.9,18.25],[2,5.3,15.82]],"ltp":0.0,"tv":0.0,"id":16665614},{"batb":[[2,7.2,6.72]],"batl":[[1,8.8,5.04],[2,10,8.34]],"ltp":0.0,"tv":0.0,"id":13011472},{"batb":[[0,1.86,48.73],[1,1.84,88.12],[2,1.82,108.61]],"batl":[[0,1.93,18.57],[1,2.04,56.22]],"ltp":2.04,"tv":53.36,"id":16665613}]}]}
{"op":"mcm","clk":"1009016057","pt":1580641498126,"mc":[{"id":"1.168224333","rc":[{"batb":[[0,7.4,16.19],[1,1.01,0.51],[2,7.6,0]],"batl":[[1,10,8.42],[2,10,0]],"ltp":0.0,"tv":0.0,"id":13011471},{"batb":[[0,4.1,21.32],[1,3.95,13.44],[2,1.01,0.51]],"batl":[[1,5.3,15.82],[2,5.3,0]],"ltp":0.0,"tv":0.0,"id":16665614},{"batb":[[0,7.2,6.72],[1,6.2,15.82],[2,1.01,0.51]],"batl":[[0,8.8,5.04],[1,10,8.34],[2,10,0]],"ltp":0.0,"tv":0.0,"id":13011472},{"batb":[[1,1.7,23.92],[2,1.01,0.51]],"batl":[[0,2.04,56.22],[1,2.04,0]],"ltp":2.04,"tv":53.36,"id":16665613}]}]}
{"op":"mcm","clk":"1009016317","pt":1580641499934,"mc":[{"id":"1.168224333","rc":[{"batb":[[0,7.4,10.31]],"batl":[[0,10,8.42],[1,10,0]],"ltp":0.0,"tv":0.0,"id":13011471},{"batb":[[1,1.01,0.51],[2,1.01,0]],"batl":[[0,5.3,15.82],[1,5.3,0]],"ltp":0.0,"tv":0.0,"id":16665614},{"batb":[[0,6.2,15.82],[1,1.01,0.51],[2,1.01,0]],"batl":[[0,10,8.34],[1,10,0]],"ltp":0.0,"tv":0.0,"id":13011472},{"batb":[[0,1.7,23.92],[1,1.01,0.51],[2,1.01,0]],"batl":[[0,2.04,15.89]],"ltp":2.04,"tv":53.36,"id":16665613}]}]}
{"op":"mcm","clk":"1009016566","pt":1580641501316,"mc":[{"id":"1.168224333","rc":[{"batb":[[0,8.2,30.02],[1,8,22.42],[2,7.4,10.31]],"ltp":0.0,"tv":0.0,"id":13011471},{"batb":[[1,3.95,53.27],[2,3.9,28.64]],"ltp":0.0,"tv":0.0,"id":16665614},{"batb":[[0,7,16.61],[1,6.8,32.36],[2,6.2,15.82]],"ltp":0.0,"tv":0.0,"id":13011472},{"batb":[[0,1.72,88.8],[1,1.7,136.76],[2,1.01,0.51]],"ltp":2.04,"tv":53.36,"id":16665613}]}]}
{"op":"mcm","clk":"1009016643","pt":1580641501800,"mc":[{"id":"1.168224333","rc":[{"batb":[[0,7.4,10.31],[1,1.01,0.51],[2,7.4,0]],"ltp":0.0,"tv":0.0,"id":13011471},{"batb":[[1,1.01,0.51],[2,3.9,0]],"ltp":0.0,"tv":0.0,"id":16665614},{"batb":[[0,6.2,15.82],[1,1.01,0.51],[2,6.2,0]],"ltp":0.0,"tv":0.0,"id":13011472},{"batb":[[0,1.7,23.92],[1,1.01,0.51],[2,1.01,0]],"ltp":2.04,"tv":53.36,"id":16665613}]}]}
{"op":"mcm","clk":"1009017148","pt":1580641505239,"mc":[{"id":"1.168224333","rc":[{"batb":[[0,8.6,24.43],[1,8.4,20.29],[2,7.4,10.31]],"ltp":0.0,"tv":0.0,"id":13011471},{"batb":[[0,4.2,25.9],[1,4.1,72.04],[2,1.01,0.51]],"ltp":0.0,"tv":0.0,"id":16665614},{"batb":[[0,8,18.69],[1,7.8,24.03],[2,6.2,15.82]],"ltp":0.0,"tv":0.0,"id":13011472},{"batb":[[0,1.82,63.89],[1,1.8,92.99],[2,1.7,23.92]],"ltp":2.04,"tv":53.36,"id":16665613}]}]}
{"op":"mcm","clk":"1009017248","pt":1580641505824,"mc":[{"id":"1.168224333","rc":[{"batb":[[0,8.6,16.31]],"ltp":0.0,"tv":0.0,"id":13011471},{"batb":[[0,7.8,24.03],[1,6.2,15.82],[2,1.01,0.51]],"ltp":0.0,"tv":0.0,"id":13011472}]}]}
{"op":"mcm","clk":"1009017700","pt":1580641508405,"mc":[{"id":"1.168224333","rc":[{"batb":[[0,7.4,10.31],[1,1.01,0.51],[2,7.4,0]],"ltp":0.0,"tv":0.0,"id":13011471},{"batb":[[0,4.1,21.32],[1,1.01,0.51],[2,1.01,0]],"ltp":0.0,"tv":0.0,"id":16665614},{"batb":[[0,6.2,15.82],[1,1.01,0.51],[2,1.01,0]],"ltp":0.0,"tv":0.0,"id":13011472},{"batb":[[0,1.7,23.92],[1,1.01,0.51],[2,1.7,0]],"ltp":2.04,"tv":53.36,"id":16665613}]}]}
{"op":"mcm","clk":"1009018172","pt":1580641511331,"mc":[{"id":"1.168224333","rc":[{"batb":[[0,8.2,21.7],[1,8,22.42],[2,7.4,10.31]],"ltp":0.0,"tv":0.0,"id":13011471},{"batb":[[1,4,31.67],[2,3.95,28.03]],"ltp":0.0,"tv":0.0,"id":16665614},{"batb":[[0,6.8,39.18],[1,6.6,33.68],[2,6.2,15.82]],"ltp":0.0,"tv":0.0,"id":13011472},{"batb":[[0,1.72,111.94],[1,1.7,136.81],[2,1.01,0.51]],"ltp":2.04,"tv":53.36,"id":16665613}]}]}
{"op":"mcm","clk":"1009018212","pt":1580641511547,"mc":[{"id":"1.168224333","rc":[{"batb":[[0,7.4,10.31],[1,1.01,0.51],[2,7.4,0]],"ltp":0.0,"tv":0.0,"id":13011471},{"batb":[[1,1.01,0.51],[2,3.95,0]],"ltp":0.0,"tv":0.0,"id":16665614},{"batb":[[0,6.2,15.82],[1,1.01,0.51],[2,6.2,0]],"ltp":0.0,"tv":0.0,"id":13011472}]}]}
{"op":"mcm","clk":"1009018635","pt":1580641514331,"mc":[{"id":"1.168224333","rc":[{"batb":[[0,8.8,29.39],[1,8.6,19.02],[2,8,8.89]],"batl":[[1,10.5,7.71]],"ltp":0.0,"tv":0.0,"id":13011471},{"batb":[[0,4.5,16.52],[1,4.4,29.89],[2,4.3,64.24]],"batl":[[1,5.7,13.22]],"ltp":0.0,"tv":0.0,"id":16665614},{"batb":[[0,9,27.7],[1,8.8,18.22],[2,8,8.81]],"batl":[[1,13.5,11.88]],"ltp":0.0,"tv":0.0,"id":13011472},{"batb":[[2,1.57,31.32]],"batl":[[0,1.8,23.45],[1,1.9,19.51]],"ltp":2.04,"tv":53.36,"id":16665613}]}]}
{"op":"mcm","clk":"1009018793","pt":1580641515263,"mc":[{"id":"1.168224333","rc":[{"batl":[[0,9.4,4.2],[1,10,8.42],[2,10.5,7.71]],"ltp":0.0,"tv":0.0,"id":13011471},{"batl":[[0,4.8,10.92],[1,5.3,15.82],[2,5.7,13.22]],"ltp":0.0,"tv":0.0,"id":16665614},{"batb":[[2,8.2,5.04]],"batl":[[1,10.5,4.2],[2,13.5,11.88]],"ltp":0.0,"tv":0.0,"id":13011472},{"batb":[[0,1.75,55.45],[1,1.72,111.94],[2,1.7,136.81]],"ltp":2.04,"tv":53.36,"id":16665613}]}]}
{"op":"mcm","clk":"1009019185","pt":1580641517254,"mc":[{"id":"1.168224333","rc":[{"batl":[[2,1.91,42.01]],"ltp":2.04,"tv":53.36,"id":16665613}]}]}
{"op":"mcm","clk":"1009020237","pt":1580641524134,"mc":[{"id":"1.168224333","rc":[{"batb":[[0,8.6,19.02],[1,7.8,9.52],[2,7.6,5.88]],"batl":[[1,10.5,7.71],[2,10.5,0]],"ltp":0.0,"tv":0.0,"id":13011471},{"batb":[[0,4.3,18.8],[1,4.1,13.44],[2,1.01,0.51]],"batl":[[1,5.7,13.22],[2,5.7,0]],"ltp":0.0,"tv":0.0,"id":16665614},{"batb":[[0,8.2,5.04],[1,7,11.8],[2,1.01,0.51]],"batl":[[0,10.5,4.2],[1,13.5,11.88],[2,13.5,0]],"ltp":0.0,"tv":0.0,"id":13011472},{"batb":[[1,1.57,31.32],[2,1.01,0.51]],"batl":[[0,1.9,19.51],[1,1.91,42.01],[2,1.91,0]],"ltp":2.04,"tv":53.36,"id":16665613}]}]}
{"op":"mcm","clk":"1009020575","pt":1580641526373,"mc":[{"id":"1.168224333","rc":[{"batb":[[2,1.01,0.51]],"batl":[[0,10.5,7.71],[1,10.5,0]],"ltp":0.0,"tv":0.0,"id":13011471},{"batb":[[1,1.01,0.51],[2,1.01,0]],"batl":[[0,5.7,13.22],[1,5.7,0]],"ltp":0.0,"tv":0.0,"id":16665614},{"batb":[[0,7,11.8],[1,1.01,0.51],[2,1.01,0]],"batl":[[0,13.5,11.88],[1,13.5,0]],"ltp":0.0,"tv":0.0,"id":13011472},{"batb":[[0,1.57,31.32],[1,1.01,0.51],[2,1.01,0]],"batl":[[1,1.91,0]],"ltp":2.04,"tv":53.36,"id":16665613}]}]}
{"op":"mcm","clk":"1009020664","pt":1580641526854,"mc":[{"id":"1.168224333","rc":[{"batb":[[1,8.4,20.3],[2,7.8,9.52]],"ltp":0.0,"tv":0.0,"id":13011471},{"batb":[[1,4.2,24.65],[2,4.1,50.85]],"ltp":0.0,"tv":0.0,"id":16665614},{"batb":[[0,7.8,30.62],[1,7.6,24.93],[2,7,11.8]],"ltp":0.0,"tv":0.0,"id":13011472},{"batb":[[0,1.6,103.6],[1,1.59,72.23],[2,1.57,31.32]],"ltp":2.04,"tv":53.36,"id":16665613}]}]}
{"op":"mcm","clk":"1009020889","pt":1580641528151,"mc":[{"id":"1.168224333","rc":[{"batb":[[0,7.8,9.52],[1,1.01,0.51],[2,7.8,0]],"ltp":0.0,"tv":0.0,"id":13011471},{"batb":[[1,1.01,0.51],[2,4.1,0]],"ltp":0.0,"tv":0.0,"id":16665614},{"batb":[[0,7,11.8],[1,1.01,0.51],[2,7,0]],"ltp":0.0,"tv":0.0,"id":13011472}]}]}
{"op":"mcm","clk":"1009021412","pt":1580641531155,"mc":[{"id":"1.168224333","rc":[{"batb":[[0,9.4,22.09],[1,9.2,16.58],[2,7.8,9.52]],"ltp":0.0,"tv":0.0,"id":13011471},{"batb":[[0,4.7,42.37],[1,4.6,38.69],[2,4.3,18.8]],"ltp":0.0,"tv":0.0,"id":16665614},{"batb":[[0,11.5,22.17],[1,11,27.69],[2,7,11.8]],"ltp":0.0,"tv":0.0,"id":13011472}]}]}
{"op":"mcm","clk":"1009021630","pt":1580641532338,"mc":[{"id":"1.168224333","rc":[{"batb":[[2,8.4,8.03]],"batl":[[1,11.5,16.84]],"ltp":0.0,"tv":0.0,"id":13011471},{"batb":[[0,4.9,13.77],[1,4.7,42.37],[2,4.6,54.35]],"batl":[[1,6.4,10.54]],"ltp":0.0,"tv":0.0,"id":16665614},{"batb":[[2,10,12.98]],"batl":[[1,20,5.74]],"ltp":0.0,"tv":0.0,"id":13011472},{"batl":[[0,1.66,30.61],[1,1.75,25.41]],"ltp":2.04,"tv":53.36,"id":16665613}]}]}
{"op":"mcm","clk":"1009021751","pt":1580641533175,"mc":[{"id":"1.168224333","rc":[{"batl":[[0,10,4.2],[1,10.5,7.71],[2,11.5,16.84]],"ltp":0.0,"tv":0.0,"id":13011471},{"batl":[[0,5.1,10.08],[1,5.7,13.22],[2,6.4,10.54]],"ltp":0.0,"tv":0.0,"id":16665614},{"batl":[[0,13,3.36],[1,13.5,11.88],[2,20,5.74]],"ltp":0.0,"tv":0.0,"id":13011472},{"batb":[[0,1.64,65.54],[1,1.6,103.6],[2,1.59,72.23]],"batl":[[2,1.77,42.01]],"ltp":2.04,"tv":53.36,"id":16665613}]}]}
{"op":"mcm","clk":"1009021946","pt":1580641534240,"mc":[{"id":"1.168224333","rc":[{"batb":[[2,10,17.18]],"ltp":0.0,"tv":0.0,"id":13011472}]}]}
{"op":"mcm","clk":"1009023683","pt":1580641544982,"mc":[{"id":"1.168224333","rc":[{"batb":[[0,8,14.62],[1,1.01,0.51],[2,8.4,0]],"batl":[[1,11.5,16.84],[2,11.5,0]],"ltp":0.0,"tv":0.0,"id":13011471},{"batb":[[0,4.6,15.66],[1,4.4,11.76],[2,1.01,0.51]],"batl":[[1,6.4,10.54],[2,6.4,0]],"ltp":0.0,"tv":0.0,"id":16665614},{"batb":[[0,10,4.2],[1,8.6,7.4],[2,1.01,0.51]],"batl":[[1,20,5.74],[2,20,0]],"ltp":0.0,"tv":0.0,"id":13011472},{"batb":[[1,1.46,42.41],[2,1.01,0.51]],"batl":[[0,1.75,25.41],[1,1.77,42.01],[2,1.77,0]],"ltp":2.04,"tv":53.36,"id":16665613}]}]}
{"op":"mcm","clk":"1009023846","pt":1580641545980,"mc":[{"id":"1.168224333","rc":[{"batb":[[0,8,8.73]],"batl":[[0,11.5,16.84],[1,11.5,0]],"ltp":0.0,"tv":0.0,"id":13011471},{"batb":[[1,1.01,0.51],[2,1.01,0]],"batl":[[0,6.4,10.54],[1,6.4,0]],"ltp":0.0,"tv":0.0,"id":16665614},{"batb":[[0,8.6,7.4],[1,1.01,0.51],[2,1.01,0]],"batl":[[0,20,5.74],[1,20,0]],"ltp":0.0,"tv":0.0,"id":13011472},{"batb":[[0,1.46,42.41],[1,1.01,0.51],[2,1.01,0]],"batl":[[1,1.77,0]],"ltp":2.04,"tv":53.36,"id":16665613}]}]}
{"op":"mcm","clk":"1009024153","pt":1580641547899,"mc":[{"id":"1.168224333","rc":[{"batb":[[0,9,22.98],[1,8.8,18.22],[2,8,8.73]],"ltp":0.0,"tv":0.0,"id":13011471},{"batb":[[1,4.5,23.36],[2,4.4,43.19]],"ltp":0.0,"tv":0.0,"id":16665614},{"batb":[[0,9.8,11.63],[1,9.6,15.41],[2,8.6,7.4]],"ltp":0.0,"tv":0.0,"id":13011472},{"batb":[[0,1.5,76.53],[1,1.49,92.89],[2,1.46,42.41]],"ltp":2.04,"tv":53.36,"id":16665613}]}]}
{"op":"mcm","clk":"1009024545","pt":1580641550291,"mc":[{"id":"1.168224333","rc":[{"batb":[[0,1.46,42.41],[1,1.01,0.51],[2,1.46,0]],"ltp":2.04,"tv":53.36,"id":16665613}]}]}
{"op":"mcm","clk":"1009025029","pt":1580641553286,"mc":[{"id":"1.168224333","rc":[{"batb":[[0,1.69,76.67],[1,1.67,119.97],[2,1.46,42.41]],"ltp":2.04,"tv":53.36,"id":16665613}]}]}
{"op":"mcm","clk":"1009025195","pt":1580641554389,"mc":[{"id":"1.168224333","rc":[{"batl":[[0,10,8.34],[1,11,7.16]],"ltp":0.0,"tv":0.0,"id":13011471},{"batb":[[2,4.4,61.44]],"batl":[[0,5.4,14.95],[1,6,11.96]],"ltp":0.0,"tv":0.0,"id":16665614},{"batl":[[0,11,7.08],[1,16.5,8.34]],"ltp":0.0,"tv":0.0,"id":13011472},{"batb":[[2,1.66,25.89]],"batl":[[1,1.87,20.54]],"ltp":2.04,"tv":53.36,"id":16665613}]}]}
{"op":"mcm","clk":"1009025279","pt":1580641554882,"mc":[{"id":"1.168224333","rc":[{"batl":[[0,9.8,4.2],[1,10,8.34],[2,11,7.16]],"ltp":0.0,"tv":0.0,"id":13011471},{"batl":[[0,4.9,10.08],[1,5.4,14.95],[2,6,11.96]],"ltp":0.0,"tv":0.0,"id":16665614},{"batb":[[2,8.8,5.04]],"batl":[[0,11,11.28]],"ltp":0.0,"tv":0.0,"id":13011472},{"batb":[[0,1.71,58.81],[1,1.69,76.67],[2,1.67,119.97]],"batl":[[1,1.85,42.01],[2,1.87,20.54]],"ltp":2.04,"tv":53.36,"id":16665613}]}]}
{"op":"mcm","clk":"1009027949","pt":1580641571316,"mc":[{"id":"1.168224333","rc":[{"batb":[[0,7.8,5.88],[1,1.01,0.51],[2,8,0]],"ltp":0.0,"tv":0.0,"id":13011471},{"batb":[[0,4.2,12.6],[1,1.01,0.51],[2,4.4,0]],"batl":[[1,5.4,0],[2,6,0]],"ltp":0.0,"tv":0.0,"id":16665614},{"batb":[[0,8.8,5.04],[1,1.01,0.51],[2,8.8,0]],"batl":[[0,11,4.2],[1,16.5,0]],"ltp":0.0,"tv":0.0,"id":13011472},{"batb":[[0,1.01,0.51],[1,1.69,0],[2,1.67,0]],"ltp":2.04,"tv":53.36,"id":16665613}]}]}
{"op":"mcm","clk":"1009028156","pt":1580641572393,"mc":[{"id":"1.168224333","rc":[{"batb":[[0,1.01,0.51],[1,1.01,0]],"ltp":0.0,"tv":0.0,"id":13011471},{"batb":[[0,1.01,0.51],[1,1.01,0]],"ltp":0.0,"tv":0.0,"id":16665614},{"batb":[[0,1.01,0.51],[1,1.01,0]],"ltp":0.0,"tv":0.0,"id":13011472}]}]}
{"op":"mcm","clk":"1009028472","pt":1580641574298,"mc":[{"id":"1.168224333","rc":[{"batb":[[0,8.6,22.64],[1,8.4,20.16],[2,1.01,0.51]],"batl":[[0,9.6,4.2]],"ltp":0.0,"tv":0.0,"id":13011471},{"batb":[[0,4.2,40.35],[1,4.1,50.58],[2,1.01,0.51]],"ltp":0.0,"tv":0.0,"id":16665614},{"batb":[[0,8,32.23],[1,7.8,23.53],[2,1.01,0.51]],"ltp":0.0,"tv":0.0,"id":13011472},{"batb":[[0,1.81,61.51],[1,1.79,94.67],[2,1.72,57.97]],"batl":[[0,1.86,42.01]],"ltp":2.04,"tv":53.36,"id":16665613}]}]}
{"op":"mcm","clk":"1009028640","pt":1580641575322,"mc":[{"id":"1.168224333","rc":[{"batb":[[2,7.4,5.88]],"batl":[[0,9.4,4.2]],"ltp":0.0,"tv":0.0,"id":13011471},{"batb":[[2,4,13.44]],"batl":[[0,4.6,10.92]],"ltp":0.0,"tv":0.0,"id":16665614},{"batb":[[1,7.8,29.41]],"batl":[[0,9.6,4.2]],"ltp":0.0,"tv":0.0,"id":13011472},{"batb":[[0,1.81,112.76],[2,1.01,0.51]],"batl":[[0,1.97,42.01]],"ltp":2.04,"tv":53.36,"id":16665613}]}]}
{"op":"mcm","clk":"1009030586","pt":1580641586250,"mc":[{"id":"1.168224333","rc":[{"batb":[[0,1.01,0.51],[1,8.4,0],[2,7.4,0]],"ltp":0.0,"tv":0.0,"id":13011471},{"batb":[[0,1.01,0.51],[1,4.1,0],[2,4,0]],"ltp":0.0,"tv":0.0,"id":16665614},{"batb":[[0,1.01,0.51],[1,7.8,0],[2,1.01,0]],"ltp":0.0,"tv":0.0,"id":13011472},{"batb":[[0,1.01,0.51],[1,1.79,0],[2,1.01,0]],"ltp":2.04,"tv":53.36,"id":16665613}]}]}
{"op":"mcm","clk":"1009031097","pt":1580641588966,"mc":[{"id":"1.168224333","rc":[{"batb":[[0,8.2,25.01],[1,8,22.36],[2,1.01,0.51]],"ltp":0.0,"tv":0.0,"id":13011471},{"batb":[[0,3.95,45.26],[1,3.9,28.78],[2,1.01,0.51]],"ltp":0.0,"tv":0.0,"id":16665614},{"batb":[[0,6.8,36.98],[1,6.6,33.78],[2,1.01,0.51]],"ltp":0.0,"tv":0.0,"id":13011472}]}]}
{"op":"mcm","clk":"1009031697","pt":1580641592149,"mc":[{"id":"1.168224333","rc":[{"batb":[[0,1.95,72.42],[1,1.93,74.43],[2,1.01,0.51]],"ltp":2.04,"tv":53.36,"id":16665613}]}]}
{"op":"mcm","clk":"1009031921","pt":1580641593339,"mc":[{"id":"1.168224333","rc":[{"batb":[[2,7.2,6.72]],"batl":[[0,9,5.04]],"ltp":0.0,"tv":0.0,"id":13011471},{"batb":[[2,3.8,14.28]],"batl":[[0,4.4,11.76]],"ltp":0.0,"tv":0.0,"id":16665614},{"batb":[[0,6.8,43.7]],"batl":[[0,8.4,5.04]],"ltp":0.0,"tv":0.0,"id":13011472},{"batb":[[2,1.92,45.37]],"batl":[[0,2.12,36.97]],"ltp":2.04,"tv":53.36,"id":16665613}]}]}
{"op":"mcm","clk":"1009034017","pt":1580641606025,"mc":[{"id":"1.168224333","rc":[{"batb":[[0,8,16.01],[1,1.01,0.51],[2,7.2,0]],"ltp":0.0,"tv":0.0,"id":13011471},{"batb":[[0,1.01,0.51],[1,3.9,0],[2,3.8,0]],"ltp":0.0,"tv":0.0,"id":16665614},{"batb":[[0,1.01,0.51],[1,6.6,0],[2,1.01,0]],"ltp":0.0,"tv":0.0,"id":13011472},{"batb":[[0,1.01,0.51],[1,1.93,0],[2,1.92,0]],"ltp":2.04,"tv":53.36,"id":16665613}]}]}
{"op":"mcm","clk":"1009034452","pt":1580641608643,"mc":[{"id":"1.168224333","rc":[{"batb":[[1,7.8,23.82],[2,1.01,0.51]],"ltp":0.0,"tv":0.0,"id":13011471},{"batb":[[0,3.8,39.39],[1,3.75,31.66],[2,1.01,0.51]],"ltp":0.0,"tv":0.0,"id":16665614},{"batb":[[0,6.2,23.41],[1,6,42.04],[2,1.01,0.51]],"ltp":0.0,"tv":0.0,"id":13011472},{"batb":[[0,1.8,57.19],[1,1.78,96.44],[2,1.01,0.51]],"ltp":2.04,"tv":53.36,"id":16665613}]}]}
{"op":"mcm","clk":"1009035556","pt":1580641615357,"mc":[{"id":"1.168224333","rc":[{"batb":[[0,1.01,0.51],[1,1.78,0],[2,1.01,0]],"ltp":2.04,"tv":53.36,"id":16665613}]}]}
{"op":"mcm","clk":"1009036043","pt":1580641618389,"mc":[{"id":"1.168224333","rc":[{"batb":[[0,2.06,109.64],[1,2.04,62.81],[2,1.01,0.51]],"ltp":2.04,"tv":53.36,"id":16665613}]}]}
{"op":"mcm","clk":"1009036155","pt":1580641618949,"mc":[{"id":"1.168224333","rc":[{"batb":[[2,6.8,6.72]],"batl":[[0,8.4,5.04]],"ltp":0.0,"tv":0.0,"id":13011471},{"batb":[[2,3.65,15.12]],"batl":[[0,4.2,12.6]],"ltp":0.0,"tv":0.0,"id":16665614},{"batb":[[1,6,50.44]],"batl":[[0,7.4,5.88]],"ltp":0.0,"tv":0.0,"id":13011472},{"batb":[[0,2.06,149.13]],"batl":[[0,2.28,32.77]],"ltp":2.04,"tv":53.36,"id":16665613}]}]}
{"op":"mcm","clk":"1009036920","pt":1580641623792,"mc":[{"id":"1.168224333","rc":[{"batb":[[2,7,11.72]],"batl":[[1,9.4,9.84]],"ltp":0.0,"tv":0.0,"id":13011471},{"batb":[[1,3.75,45.04]],"batl":[[1,4.7,20.61]],"ltp":0.0,"tv":0.0,"id":16665614},{"batb":[[2,5,13.45]],"batl":[[1,7.6,15.03]],"ltp":0.0,"tv":0.0,"id":13011472},{"batb":[[2,1.93,15.89]],"batl":[[1,2.4,20.22]],"ltp":2.04,"tv":53.36,"id":16665613}]}]}
{"op":"mcm","clk":"1009037484","pt":1580641627197,"mc":[{"id":"1.168224333","rc":[{"batl":[[0,7.4,251.12]],"ltp":0.0,"tv":0.0,"id":13011472}]}]}
{"op":"mcm","clk":"1009040662","pt":1580641647283,"mc":[{"id":"1.168224333","rc":[{"trd":[[7.4,4]],"batl":[[0,7.4,249.12]],"ltp":7.4,"tv":3.99,"id":13011472}],"tv":57.36}]}
{"op":"mcm","clk":"1009047883","pt":1580641694633,"mc":[{"id":"1.168224333","rc":[{"batb":[[0,7,11.72],[1,6.8,6.72],[2,1.01,0.51]],"ltp":0.0,"tv":0.0,"id":13011471},{"batb":[[0,3.75,13.38],[1,3.65,15.12],[2,1.01,0.51]],"ltp":0.0,"tv":0.0,"id":16665614},{"batb":[[0,6,8.4],[1,5,13.45],[2,1.01,0.51]],"batl":[[0,7.4,3.88]],"ltp":7.4,"tv":3.99,"id":13011472},{"batb":[[0,2.06,39.49],[1,1.93,15.89],[2,1.01,0.51]],"ltp":2.04,"tv":53.36,"id":16665613}]}]}
{"op":"mcm","clk":"1009048132","pt":1580641696237,"mc":[{"id":"1.168224333","rc":[{"batb":[[1,1.01,0.51],[2,1.01,0]],"batl":[[0,9.4,9.84],[1,9.4,0]],"ltp":0.0,"tv":0.0,"id":13011471},{"batb":[[1,1.01,0.51],[2,1.01,0]],"batl":[[0,4.7,20.61],[1,4.7,0]],"ltp":0.0,"tv":0.0,"id":16665614},{"batb":[[0,5,13.45],[1,1.01,0.51],[2,1.01,0]],"batl":[[0,7.6,15.03],[1,7.6,0]],"ltp":7.4,"tv":3.99,"id":13011472},{"batb":[[0,1.93,15.89],[1,1.01,0.51],[2,1.01,0]],"batl":[[0,2.4,20.22],[1,2.4,0]],"ltp":2.04,"tv":53.36,"id":16665613}]}]}
{"op":"mcm","clk":"1009048353","pt":1580641697846,"mc":[{"id":"1.168224333","rc":[{"batb":[[0,7.6,18.11],[1,7,11.72],[2,1.01,0.51]],"ltp":0.0,"tv":0.0,"id":13011471}]}]}
{"op":"mcm","clk":"1009048718","pt":1580641700356,"mc":[{"id":"1.168224333","rc":[{"batb":[[0,7.8,30.72],[1,7.6,24.86],[2,7,11.72]],"ltp":0.0,"tv":0.0,"id":13011471},{"batb":[[0,3.75,57.01],[1,3.7,32.66],[2,1.01,0.51]],"ltp":0.0,"tv":0.0,"id":16665614},{"batb":[[0,6,25.02],[1,5.9,22.16],[2,5,13.45]],"ltp":7.4,"tv":3.99,"id":13011472},{"batb":[[0,2.12,51.29],[1,2.1,57.68],[2,1.93,15.89]],"ltp":2.04,"tv":53.36,"id":16665613}]}]}
{"op":"mcm","clk":"1009048840","pt":1580641701270,"mc":[{"id":"1.168224333","rc":[{"batb":[[0,7.8,24.04],[1,7,11.72],[2,1.01,0.51]],"ltp":0.0,"tv":0.0,"id":13011471},{"batb":[[0,3.75,44.59]],"ltp":0.0,"tv":0.0,"id":16665614},{"batb":[[0,2.1,57.68],[1,1.93,15.89],[2,1.01,0.51]],"ltp":2.04,"tv":53.36,"id":16665613}]}]}
{"op":"mcm","clk":"1009049086","pt":1580641702740,"mc":[{"id":"1.168224333","rc":[{"batb":[[0,7,11.72],[1,1.01,0.51],[2,1.01,0]],"ltp":0.0,"tv":0.0,"id":13011471},{"batb":[[0,3.75,13.38],[1,1.01,0.51],[2,1.01,0]],"ltp":0.0,"tv":0.0,"id":16665614},{"batb":[[0,5,13.45],[1,1.01,0.51],[2,5,0]],"ltp":7.4,"tv":3.99,"id":13011472},{"batb":[[0,1.93,15.89],[1,1.01,0.51],[2,1.01,0]],"ltp":2.04,"tv":53.36,"id":16665613}]}]}
{"op":"mcm","clk":"1009049540","pt":1580641705758,"mc":[{"id":"1.168224333","rc":[{"batb":[[0,7.6,31.13],[1,7.4,26.67],[2,7,11.72]],"ltp":0.0,"tv":0.0,"id":13011471},{"batb":[[1,3.55,55.91],[2,3.5,37.12]],"ltp":0.0,"tv":0.0,"id":16665614},{"batb":[[0,5.4,26.7],[1,5.3,28.44],[2,5,13.45]],"ltp":7.4,"tv":3.99,"id":13011472},{"batb":[[0,1.97,54.15],[1,1.95,72.05],[2,1.93,15.89]],"ltp":2.04,"tv":53.36,"id":16665613}]}]}
{"op":"mcm","clk":"1009050572","pt":1580641712554,"mc":[{"id":"1.168224333","rc":[{"batb":[[0,7,11.72],[1,1.01,0.51],[2,7,0]],"ltp":0.0,"tv":0.0,"id":13011471},{"batb":[[1,1.01,0.51],[2,3.5,0]],"ltp":0.0,"tv":0.0,"id":16665614},{"batb":[[0,5,13.45],[1,1.01,0.51],[2,5,0]],"ltp":7.4,"tv":3.99,"id":13011472}]}]}
{"op":"mcm","clk":"1009050981","pt":1580641715388,"mc":[{"id":"1.168224333","rc":[{"batl":[[0,7.6,5],[1,9.4,9.84]],"ltp":0.0,"tv":0.0,"id":13011471}]}]}
{"op":"mcm","clk":"1009051127","pt":1580641716380,"mc":[{"id":"1.168224333","rc":[{"trd":[[7.6,10]],"batb":[[0,8.2,25.31],[1,8,22.52],[2,7.4,10.39]],"batl":[[0,9.4,9.84],[1,9.6,9.36]],"ltp":7.6,"tv":10.0,"id":13011471},{"batb":[[0,4,21.72],[1,3.9,38.8],[2,3.85,54.34]],"batl":[[1,4.8,19.67]],"ltp":0.0,"tv":0.0,"id":16665614},{"batb":[[0,6.8,32.52],[1,6.6,34.29],[2,6.2,15.97]],"batl":[[1,8.2,12.98]],"ltp":7.4,"tv":3.99,"id":13011472},{"batl":[[0,2.06,15.66],[1,2.24,24.55]],"ltp":2.04,"tv":53.36,"id":16665613}],"tv":67.36}]}
{"op":"mcm","clk":"1009051232","pt":1580641717170,"mc":[{"id":"1.168224333","rc":[{"batl":[[0,8.8,5.04],[1,9.4,9.84],[2,9.6,9.36]],"ltp":7.6,"tv":10.0,"id":13011471},{"batl":[[0,4.3,12.6],[1,4.7,20.61],[2,4.8,19.67]],"ltp":0.0,"tv":0.0,"id":16665614},{"batb":[[1,6.6,41.01]],"batl":[[1,8,5.88],[2,8.2,12.98]],"ltp":7.4,"tv":3.99,"id":13011472},{"batb":[[0,1.97,97]],"batl":[[1,2.18,35.29],[2,2.24,24.55]],"ltp":2.04,"tv":53.36,"id":16665613}]}]}
{"op":"mcm","clk":"1009053020","pt":1580641729381,"mc":[{"id":"1.168224333","rc":[{"batb":[[0,7.2,11.02],[1,7,6.72],[2,1.01,0.51]],"batl":[[1,9.6,9.36],[2,9.6,0]],"ltp":7.6,"tv":10.0,"id":13011471},{"batb":[[0,3.85,24.71],[1,3.75,15.12],[2,1.01,0.51]],"batl":[[1,4.8,19.67],[2,4.8,0]],"ltp":0.0,"tv":0.0,"id":16665614},{"batb":[[0,6.6,6.72],[1,5.5,10.7],[2,1.01,0.51]],"batl":[[0,8,5.88],[1,8.2,12.98],[2,8.2,0]],"ltp":7.4,"tv":3.99,"id":13011472},{"batb":[[0,1.97,42.85],[1,1.86,17.55],[2,1.01,0.51]],"batl":[[0,2.18,35.29],[1,2.24,24.55],[2,2.24,0]],"ltp":2.04,"tv":53.36,"id":16665613}]}]}
{"op":"mcm","clk":"1009053131","pt":1580641730231,"mc":[{"id":"1.168224333","rc":[{"batb":[[1,1.01,0.51],[2,1.01,0]],"batl":[[0,9.6,9.36],[1,9.6,0]],"ltp":7.6,"tv":10.0,"id":13011471},{"batb":[[1,1.01,0.51],[2,1.01,0]],"batl":[[0,4.8,19.67],[1,4.8,0]],"ltp":0.0,"tv":0.0,"id":16665614},{"batb":[[0,5.5,10.7],[1,1.01,0.51],[2,1.01,0]],"batl":[[0,8.2,12.98],[1,8.2,0]],"ltp":7.4,"tv":3.99,"id":13011472},{"batb":[[0,1.86,17.55],[1,1.01,0.51],[2,1.01,0]],"batl":[[0,2.24,24.55],[1,2.24,0]],"ltp":2.04,"tv":53.36,"id":16665613}]}]}
{"op":"mcm","clk":"1009054069","pt":1580641736381,"mc":[{"id":"1.168224333","rc":[{"batb":[[0,8.2,21.44],[1,8,22.69],[2,7.2,11.02]],"ltp":7.6,"tv":10.0,"id":13011471},{"batb":[[0,3.85,72.67],[1,3.8,30.49],[2,1.01,0.51]],"ltp":0.0,"tv":0.0,"id":16665614},{"batb":[[0,6.6,36.31],[1,6.4,36.58],[2,5.5,10.7]],"ltp":7.4,"tv":3.99,"id":13011472},{"batb":[[0,1.99,84.42],[1,1.97,69.82],[2,1.86,17.55]],"ltp":2.04,"tv":53.36,"id":16665613}]}]}
{"op":"mcm","clk":"1009054214","pt":1580641737392,"mc":[{"id":"1.168224333","rc":[{"batb":[[0,8,22.69],[1,7.2,11.02],[2,1.01,0.51]],"ltp":7.6,"tv":10.0,"id":13011471},{"batb":[[0,3.85,24.71],[1,1.01,0.51],[2,1.01,0]],"ltp":0.0,"tv":0.0,"id":16665614},{"batb":[[0,5.5,10.7],[1,1.01,0.51],[2,5.5,0]],"ltp":7.4,"tv":3.99,"id":13011472},{"batb":[[0,1.86,17.55],[1,1.01,0.51],[2,1.86,0]],"ltp":2.04,"tv":53.36,"id":16665613}]}]}
{"op":"mcm","clk":"1009054733","pt":1580641740698,"mc":[{"id":"1.168224333","rc":[{"batb":[[1,7.8,24.18],[2,7.2,11.02]],"ltp":7.6,"tv":10.0,"id":13011471},{"batb":[[1,3.7,51.61],[2,3.65,33.5]],"ltp":0.0,"tv":0.0,"id":16665614},{"batb":[[0,6,38.81],[1,5.9,22.37],[2,5.5,10.7]],"ltp":7.4,"tv":3.99,"id":13011472},{"batb":[[0,1.89,81.62],[1,1.87,82.18],[2,1.86,17.55]],"ltp":2.04,"tv":53.36,"id":16665613}]}]}
{"op":"mcm","clk":"1009055074","pt":1580641742886,"mc":[{"id":"1.168224333","rc":[{"batb":[[0,7.2,11.02],[1,1.01,0.51],[2,7.2,0]],"ltp":7.6,"tv":10.0,"id":13011471},{"batb":[[1,1.01,0.51],[2,3.65,0]],"ltp":0.0,"tv":0.0,"id":16665614},{"batb":[[0,5.5,10.7],[1,1.01,0.51],[2,5.5,0]],"ltp":7.4,"tv":3.99,"id":13011472}]}]}
{"op":"mcm","clk":"1009055455","pt":1580641745481,"mc":[{"id":"1.168224333","rc":[{"batb":[[0,8.6,13.49],[1,8.4,20.73],[2,7.2,11.02]],"ltp":7.6,"tv":10.0,"id":13011471},{"batb":[[0,4,29.86],[1,3.95,27.9],[2,3.85,24.71]],"ltp":0.0,"tv":0.0,"id":16665614},{"batb":[[0,7.4,26.77],[1,7.2,28.69],[2,5.5,10.7]],"ltp":7.4,"tv":3.99,"id":13011472}]}]}
{"op":"mcm","clk":"1009055733","pt":1580641747111,"mc":[{"id":"1.168224333","rc":[{"batb":[[2,7.6,9.76]],"batl":[[0,9,5.04],[1,9.6,9.36],[2,9.8,8.97]],"ltp":7.6,"tv":10.0,"id":13011471},{"batb":[[0,4.1,20.77],[1,4,52.28],[2,3.95,27.9]],"batl":[[0,4.4,11.76],[1,4.8,19.67],[2,4.9,18.88]],"ltp":0.0,"tv":0.0,"id":16665614},{"batb":[[2,7,6.72]],"batl":[[1,8.4,5.04],[2,8.6,11.57]],"ltp":7.4,"tv":3.99,"id":13011472},{"batb":[[0,1.91,45.37],[1,1.89,81.62],[2,1.87,82.18]],"batl":[[0,1.98,17.31],[1,2.1,66.84]],"ltp":2.04,"tv":53.36,"id":16665613}]}]}
{"op":"mcm","clk":"1009057604","pt":1580641758141,"mc":[{"id":"1.168224333","rc":[{"batb":[[0,7.4,10.54],[1,1.01,0.51],[2,7.6,0]],"batl":[[0,9.8,8.97],[1,9.6,0],[2,9.8,0]],"ltp":7.6,"tv":10.0,"id":13011471},{"batb":[[0,4,22.42],[1,1.01,0.51],[2,3.95,0]],"batl":[[0,4.9,18.88],[1,4.8,0],[2,4.9,0]],"ltp":0.0,"tv":0.0,"id":16665614},{"batb":[[0,5.9,17.7],[1,1.01,0.51],[2,7,0]],"batl":[[0,8.6,11.57],[1,8.4,0],[2,8.6,0]],"ltp":7.4,"tv":3.99,"id":13011472},{"batb":[[0,1.82,19.04],[1,1.01,0.51],[2,1.87,0]],"batl":[[0,2.1,29.03],[1,2.1,0]],"ltp":2.04,"tv":53.36,"id":16665613}]}]}
{"op":"mcm","clk":"1009058159","pt":1580641761319,"mc":[{"id":"1.168224333","rc":[{"batb":[[0,8.2,25.78],[1,8,22.75],[2,7.4,10.54]],"ltp":7.6,"tv":10.0,"id":13011471},{"batb":[[1,3.85,49.81],[2,3.8,30.42]],"ltp":0.0,"tv":0.0,"id":16665614},{"batb":[[0,6.6,48.49],[1,6.4,36.5],[2,5.9,17.7]],"ltp":7.4,"tv":3.99,"id":13011472},{"batb":[[0,1.85,69.15],[1,1.83,88.09],[2,1.82,19.04]],"ltp":2.04,"tv":53.36,"id":16665613}]}]}
{"op":"mcm","clk":"1009058603","pt":1580641764227,"mc":[{"id":"1.168224333","rc":[{"batb":[[0,7.4,10.54],[1,1.01,0.51],[2,7.4,0]],"ltp":7.6,"tv":10.0,"id":13011471},{"batb":[[1,1.01,0.51],[2,3.8,0]],"ltp":0.0,"tv":0.0,"id":16665614},{"batb":[[0,5.9,17.7],[1,1.01,0.51],[2,5.9,0]],"ltp":7.4,"tv":3.99,"id":13011472}]}]}
{"op":"mcm","clk":"1009059099","pt":1580641767211,"mc":[{"id":"1.168224333","rc":[{"batb":[[0,8.6,28.92],[1,8.4,20.41],[2,7.6,9.99]],"batl":[[0,9.2,5.04],[1,9.8,8.97]],"ltp":7.6,"tv":10.0,"id":13011471},{"batb":[[0,4.1,21.24],[1,4,86.02],[2,3.95,27.6]],"batl":[[0,4.4,11.76],[1,4.9,18.88]],"ltp":0.0,"tv":0.0,"id":16665614},{"batb":[[0,7.8,25.62],[1,7.6,25.54],[2,7.2,6.72]],"batl":[[1,8.8,5.04],[2,9,10.7]],"ltp":7.4,"tv":3.99,"id":13011472},{"batb":[[0,1.87,47.89],[1,1.85,69.15],[2,1.83,88.09]],"batl":[[0,1.93,18.73],[1,2.02,16.52],[2,2.04,40.33]],"ltp":2.04,"tv":53.36,"id":16665613}]}]}
{"op":"mcm","clk":"1009059132","pt":1580641767423,"mc":[{"id":"1.168224333","rc":[{"batl":[[1,9.8,8.81]],"ltp":7.6,"tv":10.0,"id":13011471},{"batb":[[1,4,63.6]],"batl":[[1,4.9,18.49]],"ltp":0.0,"tv":0.0,"id":16665614}]}]}
{"op":"mcm","clk":"1009060808","pt":1580641778181,"mc":[{"id":"1.168224333","rc":[{"batb":[[0,8.4,20.41],[1,7.6,9.99],[2,1.01,0.51]],"batl":[[0,9.8,8.81],[1,9.8,0]],"ltp":7.6,"tv":10.0,"id":13011471},{"batb":[[1,4,28.56]],"batl":[[0,4.9,18.49],[1,4.9,0]],"ltp":0.0,"tv":0.0,"id":16665614},{"batb":[[0,8.6,8.44],[1,6.4,14.79],[2,1.01,0.51]],"batl":[[0,9,10.7],[1,8.8,0],[2,9,0]],"ltp":7.4,"tv":3.99,"id":13011472},{"batb":[[0,1.79,19.99],[1,1.01,0.51],[2,1.83,0]],"batl":[[0,2.02,16.52],[1,2.02,0],[2,2.04,0]],"ltp":2.04,"tv":53.36,"id":16665613}]}]}
{"op":"mcm","clk":"1009061277","pt":1580641781357,"mc":[{"id":"1.168224333","rc":[{"batb":[[0,8.4,26.57],[1,8.2,21.55],[2,7.6,9.99]],"ltp":7.6,"tv":10.0,"id":13011471},{"batb":[[1,7.4,14.2],[2,7.2,28.98]],"ltp":7.4,"tv":3.99,"id":13011472},{"batb":[[0,1.82,97.35],[1,1.8,93.02],[2,1.79,19.99]],"ltp":2.04,"tv":53.36,"id":16665613}]}]}
{"op":"mcm","clk":"1009061658","pt":1580641784163,"mc":[{"id":"1.168224333","rc":[{"batb":[[0,7.6,9.99],[1,1.01,0.51],[2,7.6,0]],"ltp":7.6,"tv":10.0,"id":13011471},{"batb":[[2,1.01,0.51]],"ltp":0.0,"tv":0.0,"id":16665614},{"batb":[[0,6.4,14.79],[1,1.01,0.51],[2,7.2,0]],"ltp":7.4,"tv":3.99,"id":13011472}]}]}
{"op":"mcm","clk":"1009062150","pt":1580641787363,"mc":[{"id":"1.168224333","rc":[{"batb":[[0,8.8,20.07],[1,8.6,19.58],[2,7.6,15.87]],"batl":[[0,9.4,4.2],[1,9.8,8.81]],"ltp":7.6,"tv":10.0,"id":13011471},{"batb":[[0,4.1,47.15],[1,4,53.56],[2,3.85,14.28]],"batl":[[0,4.4,11.76],[1,4.9,18.49]],"ltp":0.0,"tv":0.0,"id":16665614},{"trd":[[9,16.89]],"batb":[[0,8,30.97],[1,7.8,29.91],[2,6.4,14.79]],"batl":[[0,9,2.26],[1,9.4,4.2]],"ltp":9.0,"tv":20.88,"id":13011472},{"batb":[[0,1.84,49.57],[1,1.82,97.35],[2,1.8,93.02]],"batl":[[0,2,42.01],[1,2.02,16.52]],"ltp":2.04,"tv":53.36,"id":16665613}],"tv":84.25}]}
{"op":"mcm","clk":"1009062270","pt":1580641788162,"mc":[{"id":"1.168224333","rc":[{"batb":[[2,7.8,9.28]],"batl":[[2,10.5,7.87]],"ltp":7.6,"tv":10.0,"id":13011471},{"batb":[[0,4.2,19.43],[1,4.1,25.91],[2,4,75.2]],"batl":[[2,5.3,15.82]],"ltp":0.0,"tv":0.0,"id":16665614},{"batb":[[2,7.2,11.25]],"batl":[[2,11.5,6.92]],"ltp":9.0,"tv":20.88,"id":13011472},{"batl":[[0,1.9,19.67],[1,2,58.69]],"ltp":2.04,"tv":53.36,"id":16665613}]}]}
{"op":"mcm","clk":"1009063760","pt":1580641798749,"mc":[{"id":"1.168224333","rc":[{"batb":[[1,4,75.2],[2,3.85,14.28]],"ltp":0.0,"tv":0.0,"id":16665614}]}]}
{"op":"mcm","clk":"1009064184","pt":1580641801787,"mc":[{"id":"1.168224333","rc":[{"batb":[[1,4,99.96],[2,3.95,27.45]],"ltp":0.0,"tv":0.0,"id":16665614}]}]}
{"op":"mcm","clk":"1009065194","pt":1580641808971,"mc":[{"id":"1.168224333","rc":[{"batb":[[0,7.6,15.72],[1,1.01,0.51],[2,7.8,0]],"batl":[[1,10.5,7.87],[2,10.5,0]],"ltp":7.6,"tv":10.0,"id":13011471},{"batb":[[0,4,21.64],[1,3.85,14.28],[2,1.01,0.51]],"batl":[[1,5.3,15.82],[2,5.3,0]],"ltp":0.0,"tv":0.0,"id":16665614},{"batb":[[0,7.8,5.88],[1,6.6,14.16],[2,1.01,0.51]],"batl":[[0,9.4,4.2],[1,11.5,6.92],[2,11.5,0]],"ltp":9.0,"tv":20.88,"id":13011472},{"batb":[[1,1.66,25.81],[2,1.01,0.51]],"batl":[[0,2,58.69],[1,2,0]],"ltp":2.04,"tv":53.36,"id":16665613}]}]}
{"op":"mcm","clk":"1009065383","pt":1580641810192,"mc":[{"id":"1.168224333","rc":[{"batb":[[0,7.6,9.84]],"batl":[[0,10.5,7.87],[1,10.5,0]],"ltp":7.6,"tv":10.0,"id":13011471},{"batb":[[1,1.01,0.51],[2,1.01,0]],"batl":[[0,5.3,15.82],[1,5.3,0]],"ltp":0.0,"tv":0.0,"id":16665614},{"batb":[[0,6.6,14.16],[1,1.01,0.51],[2,1.01,0]],"batl":[[0,11.5,6.92],[1,11.5,0]],"ltp":9.0,"tv":20.88,"id":13011472},{"batb":[[0,1.66,25.81],[1,1.01,0.51],[2,1.01,0]],"batl":[[0,2,16.68]],"ltp":2.04,"tv":53.36,"id":16665613}]}]}
{"op":"mcm","clk":"1009065565","pt":1580641811392,"mc":[{"id":"1.168224333","rc":[{"batb":[[0,8.4,30.78],[1,8.2,21.5],[2,7.6,9.84]],"ltp":7.6,"tv":10.0,"id":13011471},{"batb":[[1,3.9,40.85],[2,3.85,29.55]],"ltp":0.0,"tv":0.0,"id":16665614},{"batb":[[0,7.2,28.56],[1,7,30.51],[2,6.6,14.16]],"ltp":9.0,"tv":20.88,"id":13011472},{"batb":[[0,1.69,108.94],[1,1.67,120.19],[2,1.66,25.81]],"ltp":2.04,"tv":53.36,"id":16665613}]}]}
{"op":"mcm","clk":"1009065706","pt":1580641812299,"mc":[{"id":"1.168224333","rc":[{"batb":[[2,1.01,0.51]],"ltp":7.6,"tv":10.0,"id":13011471},{"batb":[[0,4.1,21.79]],"ltp":0.0,"tv":0.0,"id":16665614},{"batb":[[2,6.8,13.53]],"batl":[[0,11.5,16.05]],"ltp":9.0,"tv":20.88,"id":13011472},{"batb":[[0,1.66,25.81],[1,1.01,0.51],[2,1.66,0]],"batl":[[0,1.98,16.84]],"ltp":2.04,"tv":53.36,"id":16665613}]}]}
{"op":"mcm","clk":"1009066160","pt":1580641815402,"mc":[{"id":"1.168224333","rc":[{"batb":[[0,1.93,53.91],[1,1.91,76.85],[2,1.66,25.81]],"ltp":2.04,"tv":53.36,"id":16665613}]}]}
{"op":"mcm","clk":"1009066286","pt":1580641816096,"mc":[{"id":"1.168224333","rc":[{"batb":[[2,7.8,9.91]],"batl":[[0,9.4,9.44],[1,10,8.58]],"ltp":7.6,"tv":10.0,"id":13011471},{"batb":[[1,3.95,23.6],[2,3.9,40.85]],"batl":[[0,4.7,20.69],[1,5,17.94]],"ltp":0.0,"tv":0.0,"id":16665614},{"batl":[[0,8.2,12.75],[1,9.6,9.28]],"ltp":9.0,"tv":20.88,"id":13011472},{"batb":[[2,1.88,17.15]],"batl":[[1,2.1,29.03]],"ltp":2.04,"tv":53.36,"id":16665613}]}]}
{"op":"mcm","clk":"1009066462","pt":1580641817232,"mc":[{"id":"1.168224333","rc":[{"batl":[[0,9,5.04],[1,9.4,9.44],[2,10,8.58]],"ltp":7.6,"tv":10.0,"id":13011471},{"batl":[[0,4.3,12.6],[1,4.7,20.69],[2,5,17.94]],"ltp":0.0,"tv":0.0,"id":16665614},{"batb":[[1,7,37.23]],"batl":[[1,8.6,5.04],[2,9.6,9.28]],"ltp":9.0,"tv":20.88,"id":13011472},{"batb":[[0,1.93,98.44]],"batl":[[2,2.12,36.97]],"ltp":2.04,"tv":53.36,"id":16665613}]}]}
{"op":"mcm","clk":"1009066666","pt":1580641818402,"mc":[{"id":"1.168224333","rc":[{"batl":[[0,4.2,12.6]],"ltp":0.0,"tv":0.0,"id":16665614},{"batb":[[0,7.2,35.28],[1,7,30.51]],"ltp":9.0,"tv":20.88,"id":13011472},{"batl":[[1,2.1,66.84],[2,2.12,0]],"ltp":2.04,"tv":53.36,"id":16665613}]}]}
{"op":"mcm","clk":"1009066696","pt":1580641818606,"mc":[{"id":"1.168224333","rc":[{"batb":[[0,7.2,28.56]],"ltp":9.0,"tv":20.88,"id":13011472},{"batl":[[1,2.1,29.03]],"ltp":2.04,"tv":53.36,"id":16665613}]}]}
{"op":"mcm","clk":"1009067022","pt":1580641821009,"mc":[{"id":"1.168224333","rc":[{"batb":[[1,7,37.23]],"ltp":9.0,"tv":20.88,"id":13011472},{"batl":[[2,2.12,36.97]],"ltp":2.04,"tv":53.36,"id":16665613}]}]}
{"op":"mcm","clk":"1009067746","pt":1580641826309,"mc":[{"id":"1.168224333","rc":[{"batb":[[0,8.2,21.5],[1,7.6,10.46],[2,1.01,0.51]],"batl":[[0,10,8.58],[1,9.4,0],[2,10,0]],"ltp":7.6,"tv":10.0,"id":13011471},{"batb":[[0,3.95,23.6],[1,1.01,0.51],[2,3.9,0]],"batl":[[0,5,17.94],[1,4.7,0],[2,5,0]],"ltp":0.0,"tv":0.0,"id":16665614},{"batb":[[0,6.2,16.52],[1,1.01,0.51],[2,6.8,0]],"batl":[[0,9.6,9.28],[1,8.6,0],[2,9.6,0]],"ltp":9.0,"tv":20.88,"id":13011472},{"batb":[[0,1.76,21.48],[1,1.01,0.51],[2,1.88,0]],"batl":[[0,2.1,29.03],[1,2.1,0],[2,2.12,0]],"ltp":2.04,"tv":53.36,"id":16665613}]}]}
{"op":"mcm","clk":"1009068141","pt":1580641829285,"mc":[{"id":"1.168224333","rc":[{"batb":[[0,7.6,10.46],[1,1.01,0.51],[2,1.01,0]],"ltp":7.6,"tv":10.0,"id":13011471}]}]}
{"op":"mcm","clk":"1009068610","pt":1580641833189,"mc":[{"id":"1.168224333","rc":[{"batb":[[0,8.6,17.96],[1,8.4,20.68],[2,7.6,10.46]],"ltp":7.6,"tv":10.0,"id":13011471},{"batb":[[0,3.95,58.45],[1,3.9,28.7],[2,1.01,0.51]],"ltp":0.0,"tv":0.0,"id":16665614},{"batb":[[0,7.4,27.87],[1,7.2,28.71],[2,6.2,16.52]],"ltp":9.0,"tv":20.88,"id":13011472},{"batb":[[0,1.9,68.28],[1,1.88,80.79],[2,1.76,21.48]],"ltp":2.04,"tv":53.36,"id":16665613}]}]}
{"op":"mcm","clk":"1009068997","pt":1580641836006,"mc":[{"id":"1.168224333","rc":[{"batb":[[0,7.6,10.46],[1,1.01,0.51],[2,7.6,0]],"ltp":7.6,"tv":10.0,"id":13011471},{"batb":[[0,3.95,23.6],[1,1.01,0.51],[2,1.01,0]],"ltp":0.0,"tv":0.0,"id":16665614},{"batb":[[0,6.2,16.52],[1,1.01,0.51],[2,6.2,0]],"ltp":9.0,"tv":20.88,"id":13011472},{"batb":[[0,1.76,21.48],[1,1.01,0.51],[2,1.76,0]],"ltp":2.04,"tv":53.36,"id":16665613}]}]}
{"op":"mcm","clk":"1009069366","pt":1580641838856,"mc":[{"id":"1.168224333","rc":[{"batb":[[0,8.2,24.85],[1,8,22.82],[2,7.6,10.46]],"ltp":7.6,"tv":10.0,"id":13011471},{"batb":[[1,3.75,54.88],[2,3.7,32.37]],"ltp":0.0,"tv":0.0,"id":16665614},{"batb":[[0,6.6,30.27],[1,6.4,37.04],[2,6.2,16.52]],"ltp":9.0,"tv":20.88,"id":13011472},{"batb":[[0,1.8,77.11],[1,1.78,96.49],[2,1.76,21.48]],"ltp":2.04,"tv":53.36,"id":16665613}]}]}
{"op":"mcm","clk":"1009070432","pt":1580641846322,"mc":[{"id":"1.168224333","rc":[{"batb":[[0,7.6,10.46],[1,1.01,0.51],[2,7.6,0]],"ltp":7.6,"tv":10.0,"id":13011471},{"batb":[[1,1.01,0.51],[2,3.7,0]],"ltp":0.0,"tv":0.0,"id":16665614},{"batb":[[0,6.2,16.52],[1,1.01,0.51],[2,6.2,0]],"ltp":9.0,"tv":20.88,"id":13011472}]}]}
{"op":"mcm","clk":"1009070835","pt":1580641849322,"mc":[{"id":"1.168224333","rc":[{"batb":[[0,9,11.85],[1,8.8,18.84],[2,7.6,10.46]],"ltp":7.6,"tv":10.0,"id":13011471},{"batb":[[0,4.1,44.32],[1,4,53.21],[2,3.95,23.6]],"ltp":0.0,"tv":0.0,"id":16665614},{"batb":[[0,8.4,17.02],[1,8.2,21.91],[2,6.2,16.52]],"ltp":9.0,"tv":20.88,"id":13011472}]}]}
{"op":"mcm","clk":"1009070959","pt":1580641850223,"mc":[{"id":"1.168224333","rc":[{"batb":[[2,8,8.97]],"batl":[[1,10.5,7.55]],"ltp":7.6,"tv":10.0,"id":13011471},{"batb":[[0,4.3,18.8],[1,4.1,65.96],[2,4,53.21]],"batl":[[1,5.5,14.63]],"ltp":0.0,"tv":0.0,"id":16665614},{"batb":[[2,8,9.84]],"batl":[[1,13,13.22]],"ltp":9.0,"tv":20.88,"id":13011472},{"batl":[[0,1.84,21.09],[1,1.96,17.39]],"ltp":2.04,"tv":53.36,"id":16665613}]}]}
{"op":"mcm","clk":"1009071068","pt":1580641851136,"mc":[{"id":"1.168224333","rc":[{"batl":[[0,9.6,4.2],[1,10,8.58],[2,10.5,7.55]],"ltp":7.6,"tv":10.0,"id":13011471},{"batl":[[0,4.5,11.76],[1,5,17.94],[2,5.5,14.63]],"ltp":0.0,"tv":0.0,"id":16665614},{"batl":[[0,9.6,13.49]],"ltp":9.0,"tv":20.88,"id":13011472},{"batb":[[0,1.82,50.41],[1,1.8,77.11],[2,1.78,96.49]],"batl":[[2,1.99,42.01]],"ltp":2.04,"tv":53.36,"id":16665613}]}]}
{"op":"mcm","clk":"1009071130","pt":1580641851523,"mc":[{"id":"1.168224333","rc":[{"batl":[[0,9.6,9.28]],"ltp":9.0,"tv":20.88,"id":13011472},{"batl":[[2,1.99,0]],"ltp":2.04,"tv":53.36,"id":16665613}]}]}
{"op":"mcm","clk":"1009071431","pt":1580641853445,"mc":[{"id":"1.168224333","rc":[{"batl":[[1,9.8,4.2],[2,13,13.22]],"ltp":9.0,"tv":20.88,"id":13011472},{"trd":[[1.84,33.61]],"batl":[[0,1.84,4.28],[2,1.98,42.01]],"ltp":1.84,"tv":86.97,"id":16665613}],"tv":117.86}]}
{"op":"mcm","clk":"1009072998","pt":1580641864373,"mc":[{"id":"1.168224333","rc":[{"batb":[[0,7.8,9.76],[1,7.6,5.88],[2,1.01,0.51]],"batl":[[1,10.5,7.55],[2,10.5,0]],"ltp":7.6,"tv":10.0,"id":13011471},{"batb":[[0,4.1,21.64],[1,3.9,14.28],[2,1.01,0.51]],"batl":[[1,5.5,14.63],[2,5.5,0]],"ltp":0.0,"tv":0.0,"id":16665614},{"batb":[[0,7.8,5.88],[1,7,12.75],[2,1.01,0.51]],"batl":[[0,9.8,4.2],[1,13,13.22],[2,13,0]],"ltp":9.0,"tv":20.88,"id":13011472},{"batb":[[1,1.61,29.03],[2,1.01,0.51]],"batl":[[0,1.96,17.39],[1,1.98,42.01],[2,1.98,0]],"ltp":1.84,"tv":86.97,"id":16665613}]}]}
{"op":"mcm","clk":"1009073245","pt":1580641866281,"mc":[{"id":"1.168224333","rc":[{"batb":[[1,1.01,0.51],[2,1.01,0]],"batl":[[0,10.5,7.55],[1,10.5,0]],"ltp":7.6,"tv":10.0,"id":13011471},{"batb":[[1,1.01,0.51],[2,1.01,0]],"batl":[[0,5.5,14.63],[1,5.5,0]],"ltp":0.0,"tv":0.0,"id":16665614},{"batb":[[0,7,12.75],[1,1.01,0.51],[2,1.01,0]],"batl":[[0,13,13.22],[1,13,0]],"ltp":9.0,"tv":20.88,"id":13011472},{"batb":[[0,1.61,29.03],[1,1.01,0.51],[2,1.01,0]],"batl":[[1,1.98,0]],"ltp":1.84,"tv":86.97,"id":16665613}]}]}
{"op":"mcm","clk":"1009073405","pt":1580641867362,"mc":[{"id":"1.168224333","rc":[{"batb":[[0,8.6,13.99],[1,8.4,20.77],[2,7.8,9.76]],"ltp":7.6,"tv":10.0,"id":13011471},{"batb":[[1,4,21.87],[2,3.9,40.78]],"batl":[[0,5.4,14.79],[1,5.5,14.63]],"ltp":0.0,"tv":0.0,"id":16665614},{"batb":[[0,7.2,38.19],[1,7,43.02],[2,1.01,0.51]],"ltp":9.0,"tv":20.88,"id":13011472},{"batb":[[0,1.65,108.3],[1,1.64,64.51],[2,1.62,28.64]],"batl":[[1,1.98,17.15]],"ltp":1.84,"tv":86.97,"id":16665613}]}]}
{"op":"mcm","clk":"1009073437","pt":1580641867578,"mc":[{"id":"1.168224333","rc":[{"batb":[[0,7.6,9.84],[1,1.01,0.51],[2,7.8,0]],"ltp":7.6,"tv":10.0,"id":13011471},{"batb":[[0,4,21.87],[1,1.01,0.51],[2,3.9,0]],"batl":[[1,5.5,0]],"ltp":0.0,"tv":0.0,"id":16665614},{"batb":[[0,7,12.75],[1,1.01,0.51],[2,1.01,0]],"ltp":9.0,"tv":20.88,"id":13011472},{"batb":[[0,1.62,28.64],[1,1.01,0.51],[2,1.62,0]],"batl":[[0,1.98,17.15],[1,1.98,0]],"ltp":1.84,"tv":86.97,"id":16665613}]}]}
{"op":"mcm","clk":"1009073810","pt":1580641870195,"mc":[{"id":"1.168224333","rc":[{"batb":[[0,9,22.42],[1,8.8,18.62],[2,7.6,9.84]],"ltp":7.6,"tv":10.0,"id":13011471},{"batb":[[0,4.2,25.91],[1,4.1,50.53],[2,4,21.87]],"ltp":0.0,"tv":0.0,"id":16665614},{"batb":[[0,8.8,13.32],[1,8.6,19.86],[2,7,12.75]],"ltp":9.0,"tv":20.88,"id":13011472},{"batb":[[0,1.77,71.63],[1,1.75,102.13],[2,1.62,28.64]],"ltp":1.84,"tv":86.97,"id":16665613}]}]}
{"op":"mcm","clk":"1009074189","pt":1580641872600,"mc":[{"id":"1.168224333","rc":[{"batb":[[0,7.6,9.84],[1,1.01,0.51],[2,7.6,0]],"ltp":7.6,"tv":10.0,"id":13011471},{"batb":[[0,4,21.87],[1,1.01,0.51],[2,4,0]],"ltp":0.0,"tv":0.0,"id":16665614},{"batb":[[0,7,12.75],[1,1.01,0.51],[2,7,0]],"ltp":9.0,"tv":20.88,"id":13011472},{"batb":[[0,1.62,28.64],[1,1.01,0.51],[2,1.62,0]],"ltp":1.84,"tv":86.97,"id":16665613}]}]}
{"op":"mcm","clk":"1009074593","pt":1580641875495,"mc":[{"id":"1.168224333","rc":[{"batb":[[0,8.6,13.99],[1,8.4,20.77],[2,7.6,9.84]],"ltp":7.6,"tv":10.0,"id":13011471},{"batb":[[1,3.9,40.78],[2,3.85,29.55]],"ltp":0.0,"tv":0.0,"id":16665614},{"batb":[[0,7.2,38.19],[1,7,43.02],[2,1.01,0.51]],"ltp":9.0,"tv":20.88,"id":13011472},{"batb":[[0,1.65,108.3],[1,1.64,64.51],[2,1.62,28.64]],"ltp":1.84,"tv":86.97,"id":16665613}]}]}
{"op":"mcm","clk":"1009074850","pt":1580641877291,"mc":[{"id":"1.168224333","rc":[{"batb":[[0,7.6,9.84],[1,1.01,0.51],[2,7.6,0]],"ltp":7.6,"tv":10.0,"id":13011471},{"batb":[[1,1.01,0.51],[2,3.85,0]],"ltp":0.0,"tv":0.0,"id":16665614},{"batb":[[0,7,12.75],[1,1.01,0.51],[2,1.01,0]],"ltp":9.0,"tv":20.88,"id":13011472}]}]}
{"op":"mcm","clk":"1009075315","pt":1580641880308,"mc":[{"id":"1.168224333","rc":[{"batb":[[0,9.6,12.21],[1,9.4,16.36],[2,7.6,9.84]],"ltp":7.6,"tv":10.0,"id":13011471},{"batb":[[0,4.4,60.64],[1,4.3,44.62],[2,4,21.87]],"ltp":0.0,"tv":0.0,"id":16665614},{"batb":[[0,10.5,22.95],[1,10,34.57],[2,7,12.75]],"ltp":9.0,"tv":20.88,"id":13011472}]}]}
{"op":"mcm","clk":"1009075490","pt":1580641881182,"mc":[{"id":"1.168224333","rc":[{"batb":[[2,8.4,8.03]],"batl":[[0,10,4.2],[1,10.5,7.55],[2,11.5,15.66]],"ltp":7.6,"tv":10.0,"id":13011471},{"batb":[[0,4.7,15.5],[1,4.4,60.64],[2,4.3,63.35]],"batl":[[0,4.9,10.08],[1,5.4,14.79],[2,6.2,11.09]],"ltp":0.0,"tv":0.0,"id":16665614},{"batb":[[2,9.8,14.71]],"batl":[[0,12,3.36],[1,13,13.22],[2,20,5.74]],"ltp":9.0,"tv":20.88,"id":13011472},{"batb":[[0,1.68,61.33],[1,1.65,108.3],[2,1.64,64.51]],"batl":[[0,1.7,28.01],[1,1.82,42.01],[2,1.83,21.95]],"ltp":1.84,"tv":86.97,"id":16665613}]}]}
{"op":"mcm","clk":"1009075920","pt":1580641884004,"mc":[{"id":"1.168224333","rc":[{"trd":[[1.7,6.72]],"batl":[[0,1.7,24.65]],"ltp":1.7,"tv":93.69,"id":16665613}],"tv":124.58}]}
{"op":"mcm","clk":"1009077540","pt":1580641894403,"mc":[{"id":"1.168224333","rc":[{"batb":[[0,8,8.81],[1,1.01,0.51],[2,8.4,0]],"batl":[[0,11.5,15.66],[1,10.5,0],[2,11.5,0]],"ltp":7.6,"tv":10.0,"id":13011471},{"batb":[[0,4.3,18.73],[1,1.01,0.51],[2,4.3,0]],"batl":[[0,6.2,11.09],[1,5.4,0],[2,6.2,0]],"ltp":0.0,"tv":0.0,"id":16665614},{"batb":[[0,8.2,8.89],[1,1.01,0.51],[2,9.8,0]],"batl":[[0,20,5.74],[1,13,0],[2,20,0]],"ltp":9.0,"tv":20.88,"id":13011472},{"batb":[[0,1.47,41.78],[1,1.01,0.51],[2,1.64,0]],"batl":[[0,1.83,21.95],[1,1.82,0],[2,1.83,0]],"ltp":1.7,"tv":93.69,"id":16665613}]}]}
{"op":"mcm","clk":"1009078283","pt":1580641899116,"mc":[{"id":"1.168224333","rc":[{"batb":[[0,9.6,25.38],[1,9.4,16.12],[2,8,8.81]],"ltp":7.6,"tv":10.0,"id":13011471},{"batb":[[0,4.5,56.05],[1,4.4,42.35],[2,4.3,18.73]],"ltp":0.0,"tv":0.0,"id":16665614},{"batb":[[0,11,34.96],[1,10.5,27.61],[2,8.2,8.89]],"ltp":9.0,"tv":20.88,"id":13011472},{"batb":[[0,1.62,97.8],[1,1.61,68.98],[2,1.47,41.78]],"ltp":1.7,"tv":93.69,"id":16665613}]}]}
{"op":"mcm","clk":"1009078753","pt":1580641902138,"mc":[{"id":"1.168224333","rc":[{"batb":[[0,8,8.81],[1,1.01,0.51],[2,8,0]],"ltp":7.6,"tv":10.0,"id":13011471},{"batb":[[0,4.3,18.73],[1,1.01,0.51],[2,4.3,0]],"ltp":0.0,"tv":0.0,"id":16665614},{"batb":[[0,8.2,8.89],[1,1.01,0.51],[2,8.2,0]],"ltp":9.0,"tv":20.88,"id":13011472},{"batb":[[0,1.47,41.78],[1,1.01,0.51],[2,1.47,0]],"ltp":1.7,"tv":93.69,"id":16665613}]}]}
{"op":"mcm","clk":"1009079230","pt":1580641905001,"mc":[{"id":"1.168224333","rc":[{"batb":[[0,9,21.06],[1,8.8,18.67],[2,8,8.81]],"ltp":7.6,"tv":10.0,"id":13011471},{"batb":[[1,4.1,62.74],[2,4,52.87]],"ltp":0.0,"tv":0.0,"id":16665614},{"batb":[[0,8.6,25],[1,8.4,20.66],[2,8.2,8.89]],"ltp":9.0,"tv":20.88,"id":13011472},{"batb":[[0,1.5,155.48],[1,1.49,93.49],[2,1.47,41.78]],"ltp":1.7,"tv":93.69,"id":16665613}]}]}
{"op":"mcm","clk":"1009079653","pt":1580641907228,"mc":[{"id":"1.168224333","rc":[{"batb":[[0,1.47,41.78],[1,1.01,0.51],[2,1.47,0]],"ltp":1.7,"tv":93.69,"id":16665613}]}]}
{"op":"mcm","clk":"1009080191","pt":1580641910244,"mc":[{"id":"1.168224333","rc":[{"batb":[[0,1.78,66.64],[1,1.76,100.18],[2,1.47,41.78]],"ltp":1.7,"tv":93.69,"id":16665613}]}]}
{"op":"mcm","clk":"1009080408","pt":1580641911365,"mc":[{"id":"1.168224333","rc":[{"batl":[[0,9.6,4.2],[1,9.8,8.42],[2,11,7.24]],"ltp":7.6,"tv":10.0,"id":13011471},{"batb":[[2,4,75.06]],"batl":[[0,4.5,11.76],[1,4.9,17.86],[2,5.6,13.61]],"ltp":0.0,"tv":0.0,"id":16665614},{"batb":[[2,8.2,13.93]],"batl":[[0,10,12.7],[1,15,9.84]],"ltp":9.0,"tv":20.88,"id":13011472},{"batb":[[0,1.79,52.93],[1,1.78,66.64],[2,1.76,100.18]],"batl":[[1,1.93,42.01],[2,1.99,17]],"ltp":1.7,"tv":93.69,"id":16665613}]}]}
{"op":"mcm","clk":"1009083165","pt":1580641928363,"mc":[{"id":"1.168224333","rc":[{"batb":[[0,7.6,9.84],[1,1.01,0.51],[2,8,0]],"batl":[[0,11,7.24],[1,9.8,0],[2,11,0]],"ltp":7.6,"tv":10.0,"id":13011471},{"batb":[[0,4,22.19],[1,1.01,0.51],[2,4,0]],"batl":[[0,5.6,13.61],[1,4.9,0],[2,5.6,0]],"ltp":0.0,"tv":0.0,"id":16665614},{"batb":[[0,7,12.9],[1,1.01,0.51],[2,8.2,0]],"batl":[[0,15,9.84],[1,15,0]],"ltp":9.0,"tv":20.88,"id":13011472},{"batb":[[0,1.57,32.89],[1,1.01,0.51],[2,1.76,0]],"batl":[[0,1.99,17],[1,1.93,0],[2,1.99,0]],"ltp":1.7,"tv":93.69,"id":16665613}]}]}
{"op":"mcm","clk":"1009083501","pt":1580641930746,"mc":[{"id":"1.168224333","rc":[{"batb":[[0,8.6,14.2],[1,8.4,20.78],[2,7.6,9.84]],"ltp":7.6,"tv":10.0,"id":13011471},{"batb":[[1,3.85,51.17],[2,3.8,30.39]],"ltp":0.0,"tv":0.0,"id":16665614},{"batb":[[0,7.2,27.45],[1,7,43.46],[2,1.01,0.51]],"ltp":9.0,"tv":20.88,"id":13011472},{"batb":[[0,1.6,68.82],[1,1.59,72.15],[2,1.57,32.89]],"ltp":1.7,"tv":93.69,"id":16665613}]}]}
{"op":"mcm","clk":"1009083872","pt":1580641933194,"mc":[{"id":"1.168224333","rc":[{"batb":[[0,7.6,9.84],[1,1.01,0.51],[2,7.6,0]],"ltp":7.6,"tv":10.0,"id":13011471},{"batb":[[1,1.01,0.51],[2,3.8,0]],"ltp":0.0,"tv":0.0,"id":16665614},{"batb":[[0,7,12.9],[1,1.01,0.51],[2,1.01,0]],"ltp":9.0,"tv":20.88,"id":13011472}]}]}
{"op":"mcm","clk":"1009084372","pt":1580641936390,"mc":[{"id":"1.168224333","rc":[{"batb":[[0,9.8,17.64],[1,9.6,15.55],[2,8.6,7.55]],"batl":[[1,12.5,14.24]],"ltp":7.6,"tv":10.0,"id":13011471},{"batb":[[0,4.9,14.16],[1,4.6,44.53],[2,4.5,40.38]],"batl":[[1,7,16.84]],"ltp":0.0,"tv":0.0,"id":16665614},{"batb":[[0,12,16.12],[1,11.5,26.08],[2,11,10.62]],"ltp":9.0,"tv":20.88,"id":13011472},{"batl":[[0,1.64,32.18],[1,1.81,22.74],[2,1.99,17]],"ltp":1.7,"tv":93.69,"id":16665613}]}]}
{"op":"mcm","clk":"1009084481","pt":1580641937178,"mc":[{"id":"1.168224333","rc":[{"batl":[[0,5.1,10.08],[1,5.6,13.61],[2,7,16.84]],"ltp":0.0,"tv":0.0,"id":16665614},{"batb":[[0,1.62,67.22],[1,1.6,68.82],[2,1.59,72.15]],"batl":[[1,1.75,42.01],[2,1.81,22.74]],"ltp":1.7,"tv":93.69,"id":16665613}]}]}
{"op":"mcm","clk":"1009084600","pt":1580641937757,"mc":[{"id":"1.168224333","rc":[{"batl":[[1,1.81,22.74],[2,1.81,0]],"ltp":1.7,"tv":93.69,"id":16665613}]}]}
{"op":"mcm","clk":"1009084995","pt":1580641940307,"mc":[{"id":"1.168224333","rc":[{"batl":[[0,10.5,4.2],[1,11,7.24],[2,12.5,14.24]],"ltp":7.6,"tv":10.0,"id":13011471},{"trd":[[1.64,60.5]],"batl":[[0,1.64,1.93],[1,1.74,42.01],[2,1.81,22.74]],"ltp":1.64,"tv":154.19,"id":16665613}],"tv":185.08}]}
{"op":"mcm","clk":"1009086760","pt":1580641952178,"mc":[{"id":"1.168224333","rc":[{"batb":[[0,8.2,8.66],[1,1.01,0.51],[2,8.6,0]],"batl":[[0,12.5,14.24],[1,11,0],[2,12.5,0]],"ltp":7.6,"tv":10.0,"id":13011471},{"batb":[[0,4.4,18.33],[1,1.01,0.51],[2,4.5,0]],"batl":[[0,7,16.84],[1,5.6,0],[2,7,0]],"ltp":0.0,"tv":0.0,"id":16665614},{"batb":[[0,8.4,8.34],[1,1.01,0.51],[2,11,0]],"ltp":9.0,"tv":20.88,"id":13011472},{"batb":[[0,1.37,57.12],[1,1.01,0.51],[2,1.59,0]],"batl":[[0,1.81,22.74],[1,1.74,0],[2,1.81,0]],"ltp":1.64,"tv":154.19,"id":16665613}]}]}
{"op":"mcm","clk":"1009087236","pt":1580641955180,"mc":[{"id":"1.168224333","rc":[{"batb":[[0,9,28.27],[1,8.8,18.57],[2,8,8.81]],"batl":[[0,12,14.56]],"ltp":7.6,"tv":10.0,"id":13011471},{"batb":[[0,4.3,18.73],[1,4.1,67.58],[2,4,52.75]],"ltp":0.0,"tv":0.0,"id":16665614},{"batb":[[0,8.8,16.66],[1,8.6,19.85],[2,8.2,8.5]],"ltp":9.0,"tv":20.88,"id":13011472},{"batb":[[0,1.41,78.06],[1,1.4,121.52],[2,1.38,55.94]],"batl":[[0,1.82,22.27]],"ltp":1.64,"tv":154.19,"id":16665613}]}]}
{"op":"mcm","clk":"1009087561","pt":1580641957193,"mc":[{"id":"1.168224333","rc":[{"batb":[[0,8,8.81],[1,1.01,0.51],[2,8,0]],"ltp":7.6,"tv":10.0,"id":13011471},{"batb":[[1,1.01,0.51],[2,4,0]],"ltp":0.0,"tv":0.0,"id":16665614},{"batb":[[0,8.2,8.5],[1,1.01,0.51],[2,8.2,0]],"ltp":9.0,"tv":20.88,"id":13011472},{"batb":[[0,1.38,55.94],[1,1.01,0.51],[2,1.38,0]],"ltp":1.64,"tv":154.19,"id":16665613}]}]}
{"op":"mcm","clk":"1009088071","pt":1580641960384,"mc":[{"id":"1.168224333","rc":[{"batb":[[0,10,20.91],[1,9.8,14.85],[2,8,8.81]],"ltp":7.6,"tv":10.0,"id":13011471},{"batb":[[0,4.8,22.49],[1,4.7,36.86],[2,4.3,18.73]],"ltp":0.0,"tv":0.0,"id":16665614},{"batb":[[0,13.5,11.57],[1,13,20.41],[2,8.2,8.5]],"ltp":9.0,"tv":20.88,"id":13011472},{"batb":[[0,1.55,129.92],[1,1.54,81.82],[2,1.38,55.94]],"ltp":1.64,"tv":154.19,"id":16665613}]}]}
{"op":"mcm","clk":"1009088117","pt":1580641960695,"mc":[{"id":"1.168224333","rc":[{"batb":[[0,8,8.81],[1,1.01,0.51],[2,8,0]],"ltp":7.6,"tv":10.0,"id":13011471},{"batb":[[0,4.3,18.73],[1,1.01,0.51],[2,4.3,0]],"ltp":0.0,"tv":0.0,"id":16665614},{"batb":[[0,8.2,8.5],[1,1.01,0.51],[2,8.2,0]],"ltp":9.0,"tv":20.88,"id":13011472},{"batb":[[0,1.38,55.94],[1,1.01,0.51],[2,1.38,0]],"ltp":1.64,"tv":154.19,"id":16665613}]}]}
{"op":"mcm","clk":"1009088742","pt":1580641964680,"mc":[{"id":"1.168224333","rc":[{"batb":[[0,9,27.41],[1,8.8,18.57],[2,8,8.81]],"ltp":7.6,"tv":10.0,"id":13011471},{"batb":[[1,4.1,68.16],[2,4,52.75]],"ltp":0.0,"tv":0.0,"id":16665614},{"batb":[[0,8.8,15.77],[1,8.6,19.85],[2,8.2,8.5]],"ltp":9.0,"tv":20.88,"id":13011472},{"batb":[[0,1.41,80.64],[1,1.4,121.53],[2,1.38,55.94]],"ltp":1.64,"tv":154.19,"id":16665613}]}]}
{"op":"mcm","clk":"1009088950","pt":1580641966003,"mc":[{"id":"1.168224333","rc":[{"batb":[[0,1.38,55.94],[1,1.01,0.51],[2,1.38,0]],"ltp":1.64,"tv":154.19,"id":16665613}]}]}
{"op":"mcm","clk":"1009089504","pt":1580641969387,"mc":[{"id":"1.168224333","rc":[{"batb":[[2,8,14.69]],"batl":[[0,9.8,4.2],[1,10,4.2],[2,12,14.56]],"ltp":7.6,"tv":10.0,"id":13011471},{"batl":[[0,4.5,11.76],[1,7,16.84]],"ltp":0.0,"tv":0.0,"id":16665614},{"batb":[[1,8.6,24.89],[2,8.4,5.04]],"batl":[[0,10.5,4.2]],"ltp":9.0,"tv":20.88,"id":13011472},{"batb":[[0,1.77,126.27],[1,1.76,54.61],[2,1.75,102.15]],"batl":[[1,1.9,42.01],[2,1.91,42.01]],"ltp":1.64,"tv":154.19,"id":16665613}]}]}
{"op":"mcm","clk":"1009089569","pt":1580641969811,"mc":[{"id":"1.168224333","rc":[{"batb":[[2,8,8.81]],"batl":[[0,9.8,12.62],[1,10.5,7.24],[2,12,0]],"ltp":7.6,"tv":10.0,"id":13011471},{"batb":[[2,4,74.94]],"batl":[[1,4.9,17.78],[2,5.5,13.38]],"ltp":0.0,"tv":0.0,"id":16665614},{"batb":[[1,8.6,19.85]],"batl":[[0,10.5,12.31],[1,15,9.84]],"ltp":9.0,"tv":20.88,"id":13011472},{"batb":[[1,1.75,124.81],[2,1.57,33.13]],"batl":[[1,1.91,42.01],[2,1.98,17.15]],"ltp":1.64,"tv":154.19,"id":16665613}]}]}
{"op":"mcm","clk":"1009092560","pt":1580641988223,"mc":[{"id":"1.168224333","rc":[{"batb":[[0,7.8,9.76],[1,1.01,0.51],[2,8,0]],"batl":[[0,10.5,7.24],[1,10.5,0]],"ltp":7.6,"tv":10.0,"id":13011471},{"batb":[[0,4,22.19],[1,1.01,0.51],[2,4,0]],"batl":[[0,5.5,13.38],[1,4.9,0],[2,5.5,0]],"ltp":0.0,"tv":0.0,"id":16665614},{"batb":[[0,7,12.67],[1,1.01,0.51],[2,8.4,0]],"batl":[[0,15,9.84],[1,15,0]],"ltp":9.0,"tv":20.88,"id":13011472},{"batb":[[0,1.57,33.13],[1,1.01,0.51],[2,1.57,0]],"batl":[[0,1.98,17.15],[1,1.91,0],[2,1.98,0]],"ltp":1.64,"tv":154.19,"id":16665613}]}]}
{"op":"mcm","clk":"1009093019","pt":1580641991104,"mc":[{"id":"1.168224333","rc":[{"batb":[[0,8.6,20.16],[1,8.4,20.69],[2,7.8,9.76]],"ltp":7.6,"tv":10.0,"id":13011471},{"batb":[[1,3.85,54.82],[2,3.8,30.34]],"ltp":0.0,"tv":0.0,"id":16665614},{"batb":[[0,7.2,39.3],[1,7,42.98],[2,1.01,0.51]],"ltp":9.0,"tv":20.88,"id":13011472},{"batb":[[0,1.59,93.35],[1,1.58,73.99],[2,1.57,33.13]],"ltp":1.64,"tv":154.19,"id":16665613}]}]}
{"op":"mcm","clk":"1009096216","pt":1580642012342,"mc":[{"id":"1.168224333","rc":[{"batb":[[0,7.8,9.76],[1,1.01,0.51],[2,7.8,0]],"ltp":7.6,"tv":10.0,"id":13011471},{"batb":[[1,1.01,0.51],[2,3.8,0]],"ltp":0.0,"tv":0.0,"id":16665614},{"batb":[[0,7,12.67],[1,1.01,0.51],[2,1.01,0]],"ltp":9.0,"tv":20.88,"id":13011472}]}]}
{"op":"mcm","clk":"1009096621","pt":1580642015261,"mc":[{"id":"1.168224333","rc":[{"batb":[[0,9.8,24.04],[1,9.6,15.45],[2,7.8,9.76]],"ltp":7.6,"tv":10.0,"id":13011471},{"batb":[[0,4.6,50.79],[1,4.5,40.26],[2,4,22.19]],"ltp":0.0,"tv":0.0,"id":16665614},{"batb":[[0,12,24.27],[1,11.5,25.79],[2,7,12.67]],"ltp":9.0,"tv":20.88,"id":13011472}]}]}
{"op":"mcm","clk":"1009096779","pt":1580642016165,"mc":[{"id":"1.168224333","rc":[{"batb":[[0,9.8,15.07],[1,8.6,7.55],[2,8.2,8.73]],"batl":[[1,12.5,14.08]],"ltp":7.6,"tv":10.0,"id":13011471},{"batb":[[0,4.9,13.93],[1,4.6,50.79],[2,4.5,40.26]],"batl":[[1,7,17]],"ltp":0.0,"tv":0.0,"id":16665614},{"batb":[[2,11,10.7]],"ltp":9.0,"tv":20.88,"id":13011472},{"batb":[[0,1.58,73.99],[1,1.57,33.13],[2,1.37,57.2]],"batl":[[0,1.63,32.34],[1,1.81,22.82]],"ltp":1.64,"tv":154.19,"id":16665613}]}]}
{"op":"mcm","clk":"1009096945","pt":1580642017271,"mc":[{"id":"1.168224333","rc":[{"batb":[[2,8.2,13.77]],"batl":[[0,10.5,11.44]],"ltp":7.6,"tv":10.0,"id":13011471},{"batl":[[0,5.1,10.08],[1,5.5,13.38],[2,7,17]],"ltp":0.0,"tv":0.0,"id":16665614},{"batb":[[2,11,14.9]],"ltp":9.0,"tv":20.88,"id":13011472},{"batb":[[0,1.61,68.06],[1,1.58,73.99],[2,1.57,33.13]],"batl":[[1,1.73,42.01],[2,1.81,22.82]],"ltp":1.64,"tv":154.19,"id":16665613}]}]}
{"op":"mcm","clk":"1009097287","pt":1580642019346,"mc":[{"id":"1.168224333","rc":[{"batb":[[0,10,19.32],[1,9.8,15.07],[2,8.6,7.55]],"ltp":7.6,"tv":10.0,"id":13011471},{"batb":[[0,12,32.88]],"ltp":9.0,"tv":20.88,"id":13011472},{"trd":[[1.63,10.08]],"batb":[[1,1.58,135.33],[2,1.57,109.21]],"batl":[[0,1.63,27.3]],"ltp":1.63,"tv":164.27,"id":16665613}],"tv":195.16}]}
{"op":"mcm","clk":"1009099940","pt":1580642036402,"mc":[{"id":"1.168224333","rc":[{"batb":[[0,8.2,8.73],[1,1.01,0.51],[2,8.6,0]],"batl":[[0,12.5,14.08],[1,12.5,0]],"ltp":7.6,"tv":10.0,"id":13011471},{"batb":[[0,4.3,18.41],[1,1.01,0.51],[2,4.5,0]],"batl":[[0,7,17],[1,5.5,0],[2,7,0]],"ltp":0.0,"tv":0.0,"id":16665614},{"batb":[[0,8.4,8.18],[1,1.01,0.51],[2,11,0]],"ltp":9.0,"tv":20.88,"id":13011472},{"batb":[[0,1.37,57.2],[1,1.01,0.51],[2,1.57,0]],"batl":[[0,1.81,22.82],[1,1.73,0],[2,1.81,0]],"ltp":1.63,"tv":164.27,"id":16665613}]}]}
{"op":"mcm","clk":"1009100392","pt":1580642039370,"mc":[{"id":"1.168224333","rc":[{"batb":[[0,9.2,25.07],[1,9,17.97],[2,8,8.73]],"batl":[[0,12,14.16]],"ltp":7.6,"tv":10.0,"id":13011471},{"batb":[[1,4.1,67.29],[2,4,52.65]],"ltp":0.0,"tv":0.0,"id":16665614},{"batb":[[0,9,17.34],[1,8.8,19.11],[2,8.4,8.18]],"ltp":9.0,"tv":20.88,"id":13011472},{"batb":[[0,1.4,127.24],[1,1.39,126.28],[2,1.38,56.73]],"batl":[[0,1.82,22.5]],"ltp":1.63,"tv":164.27,"id":16665613}]}]}
{"op":"mcm","clk":"1009103557","pt":1580642058221,"mc":[{"id":"1.168224333","rc":[{"batb":[[0,1.38,56.73],[1,1.01,0.51],[2,1.38,0]],"ltp":1.63,"tv":164.27,"id":16665613}]}]}
{"op":"mcm","clk":"1009104028","pt":1580642061395,"mc":[{"id":"1.168224333","rc":[{"batb":[[2,8,14.62]],"batl":[[0,10,4.2],[1,12,14.16]],"ltp":7.6,"tv":10.0,"id":13011471},{"batb":[[2,4,66.09]],"batl":[[0,4.6,10.92],[1,7,17]],"ltp":0.0,"tv":0.0,"id":16665614},{"batb":[[2,8.6,5.04]],"batl":[[0,10.5,4.2]],"ltp":9.0,"tv":20.88,"id":13011472},{"batb":[[0,1.76,54.61],[1,1.75,104.04],[2,1.73,106.45]],"batl":[[1,1.9,42.01]],"ltp":1.63,"tv":164.27,"id":16665613}]}]}
{"op":"mcm","clk":"1009104136","pt":1580642061981,"mc":[{"id":"1.168224333","rc":[{"batl":[[0,9.8,8.34],[1,10,4.2],[2,11,7.08]],"ltp":7.6,"tv":10.0,"id":13011471},{"batb":[[2,4,88.2]],"batl":[[1,4.9,17.7],[2,5.5,13.38]],"ltp":0.0,"tv":0.0,"id":16665614},{"batl":[[0,10.5,12.15],[1,15,9.44]],"ltp":9.0,"tv":20.88,"id":13011472},{"batb":[[2,1.74,22.9]],"batl":[[2,1.97,17.55]],"ltp":1.63,"tv":164.27,"id":16665613}]}]}
{"op":"mcm","clk":"1009106748","pt":1580642078351,"mc":[{"id":"1.168224333","rc":[{"batb":[[0,8,14.62],[1,7.8,9.52],[2,1.01,0.51]],"ltp":7.6,"tv":10.0,"id":13011471},{"batb":[[1,4,35.55],[2,1.01,0.51]],"ltp":0.0,"tv":0.0,"id":16665614},{"batb":[[0,8.6,5.04],[1,8.4,8.18],[2,7,12.35]],"ltp":9.0,"tv":20.88,"id":13011472},{"batb":[[1,1.74,22.9],[2,1.56,33.6]],"ltp":1.63,"tv":164.27,"id":16665613}]}]}
{"op":"mcm","clk":"1009106888","pt":1580642079155,"mc":[{"id":"1.168224333","rc":[{"batb":[[0,8,5.88]],"batl":[[0,10,4.2],[1,11,7.08],[2,11,0]],"ltp":7.6,"tv":10.0,"id":13011471},{"batb":[[0,4,35.55],[1,1.01,0.51],[2,1.01,0]],"batl":[[1,5.5,13.38],[2,5.5,0]],"ltp":0.0,"tv":0.0,"id":16665614},{"batb":[[1,7,12.35],[2,1.01,0.51]],"batl":[[0,10.5,4.2]],"ltp":9.0,"tv":20.88,"id":13011472},{"batb":[[1,1.56,33.6],[2,1.01,0.51]],"batl":[[0,1.9,42.01],[1,1.97,17.55],[2,1.97,0]],"ltp":1.63,"tv":164.27,"id":16665613}]}]}
{"op":"mcm","clk":"1009107095","pt":1580642080332,"mc":[{"id":"1.168224333","rc":[{"batb":[[0,7.8,9.52],[1,1.01,0.51],[2,1.01,0]],"batl":[[0,11,7.08],[1,11,0]],"ltp":7.6,"tv":10.0,"id":13011471},{"batb":[[0,4,22.11]],"batl":[[0,5.5,13.38],[1,5.5,0]],"ltp":0.0,"tv":0.0,"id":16665614},{"batb":[[0,7,12.35],[1,1.01,0.51],[2,1.01,0]],"batl":[[0,15,9.44],[1,15,0]],"ltp":9.0,"tv":20.88,"id":13011472},{"batb":[[0,1.56,33.6],[1,1.01,0.51],[2,1.01,0]],"batl":[[0,1.97,17.55],[1,1.97,0]],"ltp":1.63,"tv":164.27,"id":16665613}]}]}
{"op":"mcm","clk":"1009107249","pt":1580642081323,"mc":[{"id":"1.168224333","rc":[{"batb":[[0,8.8,15.79],[1,8.6,20.01],[2,7.8,9.52]],"ltp":7.6,"tv":10.0,"id":13011471},{"batb":[[1,3.85,50.8],[2,3.8,30.32]],"ltp":0.0,"tv":0.0,"id":16665614},{"batb":[[0,7.4,33.57],[1,7.2,28.99],[2,7,12.35]],"ltp":9.0,"tv":20.88,"id":13011472},{"batb":[[0,1.58,91.22],[1,1.57,75.89],[2,1.56,33.6]],"ltp":1.63,"tv":164.27,"id":16665613}]}]}
{"op":"mcm","clk":"1009107389","pt":1580642082232,"mc":[{"id":"1.168224333","rc":[{"batb":[[0,1.56,33.6],[1,1.01,0.51],[2,1.56,0]],"ltp":1.63,"tv":164.27,"id":16665613}]}]}
{"op":"mcm","clk":"1009107851","pt":1580642085148,"mc":[{"id":"1.168224333","rc":[{"batb":[[0,1.91,55.63],[1,1.89,79.53],[2,1.56,33.6]],"ltp":1.63,"tv":164.27,"id":16665613}]}]}
{"op":"mcm","clk":"1009108011","pt":1580642086159,"mc":[{"id":"1.168224333","rc":[{"batl":[[0,9.4,9.05],[1,10,8.18]],"ltp":7.6,"tv":10.0,"id":13011471},{"batb":[[1,3.85,75.9]],"batl":[[0,4.5,20.93],[1,4.9,17.39]],"ltp":0.0,"tv":0.0,"id":16665614},{"batl":[[0,8.4,11.64],[1,10.5,7.55]],"ltp":9.0,"tv":20.88,"id":13011472},{"batb":[[1,1.89,97.39],[2,1.73,23.6]],"batl":[[1,2.12,28.64]],"ltp":1.63,"tv":164.27,"id":16665613}]}]}
{"op":"mcm","clk":"1009108194","pt":1580642087329,"mc":[{"id":"1.168224333","rc":[{"batl":[[0,9.4,13.25]],"ltp":7.6,"tv":10.0,"id":13011471},{"batl":[[0,4.3,12.6],[1,4.5,20.93],[2,4.9,17.39]],"ltp":0.0,"tv":0.0,"id":16665614},{"batb":[[0,7.4,39.45]],"batl":[[1,9,5.04],[2,10.5,7.55]],"ltp":9.0,"tv":20.88,"id":13011472},{"batb":[[1,1.89,144.44]],"batl":[[1,2.06,39.49],[2,2.12,28.64]],"ltp":1.63,"tv":164.27,"id":16665613}]}]}
{"op":"mcm","clk":"1009110468","pt":1580642101250,"mc":[{"id":"1.168224333","rc":[{"batb":[[0,7.6,16.27],[1,1.01,0.51],[2,7.8,0]],"batl":[[0,9.4,4.2]],"ltp":7.6,"tv":10.0,"id":13011471},{"batb":[[0,3.85,25.1],[1,3.75,15.12],[2,1.01,0.51]],"batl":[[1,4.9,17.39],[2,4.9,0]],"ltp":0.0,"tv":0.0,"id":16665614},{"batb":[[0,7.4,5.88],[1,6.2,15.66],[2,1.01,0.51]],"batl":[[0,9,5.04],[1,10.5,7.55],[2,10.5,0]],"ltp":9.0,"tv":20.88,"id":13011472},{"batb":[[0,1.89,47.05],[1,1.73,23.6],[2,1.01,0.51]],"batl":[[0,2.06,39.49],[1,2.12,28.64],[2,2.12,0]],"ltp":1.63,"tv":164.27,"id":16665613}]}]}
{"op":"mcm","clk":"1009110623","pt":1580642102262,"mc":[{"id":"1.168224333","rc":[{"batb":[[0,7.6,10.39]],"batl":[[0,10,8.18],[1,10,0]],"ltp":7.6,"tv":10.0,"id":13011471},{"batb":[[1,1.01,0.51],[2,1.01,0]],"batl":[[0,4.9,17.39],[1,4.9,0]],"ltp":0.0,"tv":0.0,"id":16665614},{"batb":[[0,6.2,15.66],[1,1.01,0.51],[2,1.01,0]],"batl":[[0,10.5,7.55],[1,10.5,0]],"ltp":9.0,"tv":20.88,"id":13011472},{"batb":[[0,1.73,23.6],[1,1.01,0.51],[2,1.01,0]],"batl":[[0,2.12,28.64],[1,2.12,0]],"ltp":1.63,"tv":164.27,"id":16665613}]}]}
{"op":"mcm","clk":"1009110912","pt":1580642104160,"mc":[{"id":"1.168224333","rc":[{"batb":[[0,8.4,20.97],[1,8.2,22.05],[2,7.6,10.39]],"ltp":7.6,"tv":10.0,"id":13011471},{"batb":[[1,3.7,30.02],[2,3.65,33.61]],"ltp":0.0,"tv":0.0,"id":16665614},{"batb":[[0,6.6,36.32],[1,6.4,37.41],[2,6.2,15.66]],"ltp":9.0,"tv":20.88,"id":13011472},{"batb":[[0,1.75,59.95],[1,1.73,129.9],[2,1.01,0.51]],"ltp":1.63,"tv":164.27,"id":16665613}]}]}
{"op":"mcm","clk":"1009111547","pt":1580642107973,"mc":[{"id":"1.168224333","rc":[{"batb":[[0,7.6,10.39],[1,1.01,0.51],[2,7.6,0]],"ltp":7.6,"tv":10.0,"id":13011471},{"batb":[[1,1.01,0.51],[2,3.65,0]],"ltp":0.0,"tv":0.0,"id":16665614},{"batb":[[0,6.2,15.66],[1,1.01,0.51],[2,6.2,0]],"ltp":9.0,"tv":20.88,"id":13011472}]}]}
{"op":"mcm","clk":"1009112196","pt":1580642111362,"mc":[{"id":"1.168224333","rc":[{"batb":[[0,9.4,12.71],[1,9.2,17.38],[2,8,5.88]],"batl":[[0,10,12.38]],"ltp":7.6,"tv":10.0,"id":13011471},{"batb":[[0,4.1,74.54],[1,4,52.52],[2,3.95,13.44]],"batl":[[0,4.6,10.92],[1,4.9,17.39]],"ltp":0.0,"tv":0.0,"id":16665614},{"batb":[[0,9,27.51],[1,8.8,18.91],[2,8.4,5.04]],"batl":[[0,10.5,11.75]],"ltp":9.0,"tv":20.88,"id":13011472},{"batb":[[0,1.75,115.4]],"batl":[[0,1.91,42.01],[1,2.12,28.64]],"ltp":1.63,"tv":164.27,"id":16665613}]}]}
{"op":"mcm","clk":"1009112353","pt":1580642112381,"mc":[{"id":"1.168224333","rc":[{"batb":[[2,8.2,8.58]],"batl":[[1,11,7]],"ltp":7.6,"tv":10.0,"id":13011471},{"batb":[[0,4.4,18.25],[1,4.1,74.54],[2,4,74.39]],"batl":[[2,5.6,13.06]],"ltp":0.0,"tv":0.0,"id":16665614},{"batb":[[2,8.6,7.95]],"batl":[[1,15.5,8.89]],"ltp":9.0,"tv":20.88,"id":13011472},{"batb":[[2,1.55,34.62]],"batl":[[0,1.8,23.13],[1,1.95,18.02]],"ltp":1.63,"tv":164.27,"id":16665613}]}]}
{"op":"mcm","clk":"1009112645","pt":1580642114052,"mc":[{"id":"1.168224333","rc":[{"batl":[[1,1.9,42.01],[2,1.95,18.02]],"ltp":1.63,"tv":164.27,"id":16665613}]}]}
{"op":"mcm","clk":"1009115093","pt":1580642128276,"mc":[{"id":"1.168224333","rc":[{"batb":[[0,7.8,9.44],[1,1.01,0.51],[2,8.2,0]],"batl":[[0,11,7],[1,11,0]],"ltp":7.6,"tv":10.0,"id":13011471},{"batb":[[0,4,21.87],[1,1.01,0.51],[2,4,0]],"batl":[[0,5.6,13.06],[1,4.9,0],[2,5.6,0]],"ltp":0.0,"tv":0.0,"id":16665614},{"batb":[[0,7.2,11.57],[1,1.01,0.51],[2,8.6,0]],"batl":[[0,15.5,8.89],[1,15.5,0]],"ltp":9.0,"tv":20.88,"id":13011472},{"batb":[[0,1.55,34.62],[1,1.01,0.51],[2,1.55,0]],"batl":[[0,1.95,18.02],[1,1.9,0],[2,1.95,0]],"ltp":1.63,"tv":164.27,"id":16665613}]}]}
{"op":"mcm","clk":"1009115445","pt":1580642130401,"mc":[{"id":"1.168224333","rc":[{"batb":[[0,8.8,20.72],[1,8.6,19.91],[2,7.8,9.44]],"ltp":7.6,"tv":10.0,"id":13011471},{"batb":[[1,3.9,26.5],[2,3.85,29.6]],"ltp":0.0,"tv":0.0,"id":16665614},{"batb":[[0,7.6,16.33],[1,7.4,27.71],[2,7.2,11.57]],"ltp":9.0,"tv":20.88,"id":13011472},{"batb":[[0,1.57,119.4],[1,1.56,77.9],[2,1.55,34.62]],"ltp":1.63,"tv":164.27,"id":16665613}]}]}
{"op":"mcm","clk":"1009116484","pt":1580642136225,"mc":[{"id":"1.168224333","rc":[{"batb":[[0,1.55,34.62],[1,1.01,0.51],[2,1.55,0]],"ltp":1.63,"tv":164.27,"id":16665613}]}]}
{"op":"mcm","clk":"1009117006","pt":1580642139308,"mc":[{"id":"1.168224333","rc":[{"batl":[[0,9.6,4.2],[1,11,7]],"ltp":7.6,"tv":10.0,"id":13011471},{"batl":[[0,4.3,12.6],[1,5.6,13.06]],"ltp":0.0,"tv":0.0,"id":16665614},{"batb":[[1,7.4,33.59]],"batl":[[0,9.2,5.04],[1,15.5,8.89]],"ltp":9.0,"tv":20.88,"id":13011472},{"batb":[[0,1.9,58.03],[1,1.88,127.93],[2,1.55,34.62]],"batl":[[1,2.04,40.33]],"ltp":1.63,"tv":164.27,"id":16665613}]}]}
{"op":"mcm","clk":"1009117125","pt":1580642140001,"mc":[{"id":"1.168224333","rc":[{"batl":[[0,9.4,8.97],[1,9.6,4.2],[2,10,8.03]],"ltp":7.6,"tv":10.0,"id":13011471},{"batb":[[2,3.85,54.23]],"batl":[[1,4.6,20.77],[2,4.9,17.23]],"ltp":0.0,"tv":0.0,"id":16665614},{"batl":[[0,8.8,10.94],[1,9.2,5.04],[2,11,7.24]],"ltp":9.0,"tv":20.88,"id":13011472},{"batb":[[2,1.87,18.33]],"batl":[[2,2.1,29.58]],"ltp":1.63,"tv":164.27,"id":16665613}]}]}
{"op":"mcm","clk":"1009119885","pt":1580642155227,"mc":[{"id":"1.168224333","rc":[{"batb":[[0,7.6,16.11],[1,1.01,0.51],[2,7.8,0]],"batl":[[0,9.6,4.2],[1,10,8.03],[2,10,0]],"ltp":7.6,"tv":10.0,"id":13011471},{"batb":[[0,3.85,24.63],[1,3.75,15.12],[2,1.01,0.51]],"batl":[[1,4.9,17.23],[2,4.9,0]],"ltp":0.0,"tv":0.0,"id":16665614},{"batb":[[0,7.4,5.88],[1,6.4,15.03],[2,1.01,0.51]],"batl":[[0,9.2,5.04],[1,11,7.24],[2,11,0]],"ltp":9.0,"tv":20.88,"id":13011472},{"batb":[[0,1.88,47.05],[1,1.72,24.23],[2,1.01,0.51]],"batl":[[0,2.04,40.33],[1,2.1,29.58],[2,2.1,0]],"ltp":1.63,"tv":164.27,"id":16665613}]}]}
{"op":"mcm","clk":"1009120084","pt":1580642156344,"mc":[{"id":"1.168224333","rc":[{"batb":[[0,7.6,10.23]],"batl":[[0,10,8.03],[1,10,0]],"ltp":7.6,"tv":10.0,"id":13011471},{"batb":[[1,1.01,0.51],[2,1.01,0]],"batl":[[0,4.9,17.23],[1,4.9,0]],"ltp":0.0,"tv":0.0,"id":16665614},{"batb":[[0,6.4,15.03],[1,1.01,0.51],[2,1.01,0]],"batl":[[0,11,7.24],[1,11,0]],"ltp":9.0,"tv":20.88,"id":13011472},{"batb":[[0,1.72,24.23],[1,1.01,0.51],[2,1.01,0]],"batl":[[0,2.1,29.58],[1,2.1,0]],"ltp":1.63,"tv":164.27,"id":16665613}]}]}
{"op":"mcm","clk":"1009120361","pt":1580642158118,"mc":[{"id":"1.168224333","rc":[{"batb":[[0,8.4,25.49],[1,8.2,21.96],[2,7.6,10.23]],"ltp":7.6,"tv":10.0,"id":13011471},{"batb":[[1,3.7,33.84],[2,3.65,33.57]],"ltp":0.0,"tv":0.0,"id":16665614},{"batb":[[0,6.6,47.16],[1,6.4,52.16],[2,1.01,0.51]],"ltp":9.0,"tv":20.88,"id":13011472},{"batb":[[0,1.74,69.64],[1,1.72,132.69],[2,1.01,0.51]],"ltp":1.63,"tv":164.27,"id":16665613}]}]}
{"op":"mcm","clk":"1009120516","pt":1580642158913,"mc":[{"id":"1.168224333","rc":[{"batb":[[0,1.72,24.23],[1,1.01,0.51],[2,1.01,0]],"ltp":1.63,"tv":164.27,"id":16665613}]}]}
{"op":"mcm","clk":"1009121039","pt":1580642162018,"mc":[{"id":"1.168224333","rc":[{"batb":[[0,2.02,84.68],[1,2,66.72],[2,1.72,24.23]],"ltp":1.63,"tv":164.27,"id":16665613}]}]}
{"op":"mcm","clk":"1009121285","pt":1580642163347,"mc":[{"id":"1.168224333","rc":[{"batl":[[0,9,5.04],[1,9.2,9.68],[2,9.4,9.21]],"ltp":7.6,"tv":10.0,"id":13011471},{"batl":[[0,4.1,13.44],[1,4.3,23.29],[2,4.5,21.56]],"ltp":0.0,"tv":0.0,"id":16665614},{"batb":[[0,6.6,53.88],[2,5.5,10.7]],"batl":[[0,7.8,14.16],[1,8,5.88],[2,8.4,11.72]],"ltp":9.0,"tv":20.88,"id":13011472},{"batb":[[0,2.02,125.85],[2,1.99,30.45]],"batl":[[1,2.2,34.45],[2,2.34,21.48]],"ltp":1.63,"tv":164.27,"id":16665613}]}]}
{"op":"mcm","clk":"1009121904","pt":1580642167256,"mc":[{"id":"1.168224333","rc":[{"batl":[[1,4.2,2],[2,4.3,23.29]],"ltp":0.0,"tv":0.0,"id":16665614}]}]}
{"op":"mcm","clk":"1009122027","pt":1580642168036,"mc":[{"id":"1.168224333","rc":[{"batl":[[1,4.3,23.29],[2,4.5,21.56]],"ltp":0.0,"tv":0.0,"id":16665614}]}]}
{"op":"mcm","clk":"1009133788","pt":1580642244363,"mc":[{"id":"1.168224333","rc":[{"batb":[[0,7.6,10.23],[1,7.2,18.21],[2,1.01,0.51]],"ltp":7.6,"tv":10.0,"id":13011471},{"batb":[[1,3.6,14.63],[2,3.55,15.96]],"ltp":0.0,"tv":0.0,"id":16665614},{"batb":[[0,6.6,6.72],[1,6.4,15.03]],"ltp":9.0,"tv":20.88,"id":13011472},{"batb":[[0,2.02,41.17],[1,1.99,30.45],[2,1.9,17.39]],"ltp":1.63,"tv":164.27,"id":16665613}]}]}
{"op":"mcm","clk":"1009133860","pt":1580642244793,"mc":[{"id":"1.168224333","rc":[{"batb":[[0,7.2,11.49],[1,1.01,0.51],[2,1.01,0]],"batl":[[0,9.4,9.21],[1,9.2,0],[2,9.4,0]],"ltp":7.6,"tv":10.0,"id":13011471},{"batb":[[0,3.6,14.63],[1,1.01,0.51],[2,3.55,0]],"batl":[[0,4.5,21.56],[1,4.3,0],[2,4.5,0]],"ltp":0.0,"tv":0.0,"id":16665614},{"batb":[[0,5.5,10.7],[1,1.01,0.51],[2,5.5,0]],"batl":[[0,8.4,11.72],[1,8,0],[2,8.4,0]],"ltp":9.0,"tv":20.88,"id":13011472},{"batb":[[0,1.9,17.39],[1,1.01,0.51],[2,1.9,0]],"batl":[[0,2.34,21.48],[1,2.2,0],[2,2.34,0]],"ltp":1.63,"tv":164.27,"id":16665613}]}]}
{"op":"mcm","clk":"1009134664","pt":1580642249370,"mc":[{"id":"1.168224333","rc":[{"batb":[[0,8.4,15.22],[1,8.2,22.2],[2,7.2,11.49]],"ltp":7.6,"tv":10.0,"id":13011471},{"batb":[[0,3.65,35.43],[1,3.6,49.36],[2,1.01,0.51]],"ltp":0.0,"tv":0.0,"id":16665614},{"batb":[[0,6.4,46.19],[1,6.2,39.95],[2,5.5,10.7]],"ltp":9.0,"tv":20.88,"id":13011472},{"batb":[[0,2.06,83.63],[1,2.04,62.82],[2,1.9,17.39]],"ltp":1.63,"tv":164.27,"id":16665613}]}]}
{"op":"mcm","clk":"1009135413","pt":1580642253681,"mc":[{"id":"1.168224333","rc":[{"batb":[[0,7.2,11.49],[1,1.01,0.51],[2,7.2,0]],"ltp":7.6,"tv":10.0,"id":13011471},{"batb":[[0,3.6,14.63],[1,1.01,0.51],[2,1.01,0]],"ltp":0.0,"tv":0.0,"id":16665614},{"batb":[[0,5.5,10.7],[1,1.01,0.51],[2,5.5,0]],"ltp":9.0,"tv":20.88,"id":13011472},{"batb":[[0,1.9,17.39],[1,1.01,0.51],[2,1.9,0]],"ltp":1.63,"tv":164.27,"id":16665613}]}]}
{"op":"mcm","clk":"1009135899","pt":1580642256662,"mc":[{"id":"1.168224333","rc":[{"batb":[[0,8,15.63],[1,7.8,24.72],[2,7.2,11.49]],"ltp":7.6,"tv":10.0,"id":13011471},{"batb":[[1,3.45,39.01],[2,3.4,39.9]],"ltp":0.0,"tv":0.0,"id":16665614},{"batb":[[0,5.7,28.39],[1,5.6,25.74],[2,5.5,10.7]],"ltp":9.0,"tv":20.88,"id":13011472},{"batb":[[0,1.92,70.56],[1,1.9,95.6],[2,1.01,0.51]],"ltp":1.63,"tv":164.27,"id":16665613}]}]}
{"op":"mcm","clk":"1009136437","pt":1580642260231,"mc":[{"id":"1.168224333","rc":[{"batb":[[0,7.2,11.49],[1,1.01,0.51],[2,7.2,0]],"ltp":7.6,"tv":10.0,"id":13011471},{"batb":[[1,1.01,0.51],[2,3.4,0]],"ltp":0.0,"tv":0.0,"id":16665614},{"batb":[[0,5.5,10.7],[1,1.01,0.51],[2,5.5,0]],"ltp":9.0,"tv":20.88,"id":13011472}]}]}
{"op":"mcm","clk":"1009136891","pt":1580642263369,"mc":[{"id":"1.168224333","rc":[{"batb":[[0,8.8,13.05],[1,8.6,20.09],[2,7.4,16.58]],"batl":[[0,9.2,5.04],[1,9.4,9.21],[2,9.6,8.89]],"ltp":7.6,"tv":10.0,"id":13011471},{"batb":[[0,4,22.74],[1,3.85,28.78],[2,3.8,30.54]],"batl":[[0,4.2,12.6],[1,4.5,21.56],[2,4.6,20.3]],"ltp":0.0,"tv":0.0,"id":16665614},{"batb":[[0,7.4,25.43],[1,7.2,29.26],[2,7,19.15]],"batl":[[1,8.6,5.04],[2,9,10.07]],"ltp":9.0,"tv":20.88,"id":13011472},{"batb":[[0,1.93,44.53],[1,1.92,70.56],[2,1.9,95.6]],"batl":[[0,1.98,17.07],[1,2.12,36.97],[2,2.18,26.44]],"ltp":1.63,"tv":164.27,"id":16665613}]}]}
{"op":"mcm","clk":"1009138316","pt":1580642273384,"mc":[{"id":"1.168224333","rc":[{"batb":[[0,7.4,16.58],[1,1.01,0.51],[2,7.4,0]],"ltp":7.6,"tv":10.0,"id":13011471},{"batb":[[1,3.75,13.22],[2,3.7,15.12]],"ltp":0.0,"tv":0.0,"id":16665614},{"batb":[[0,7,19.15],[1,6,17.15],[2,1.01,0.51]],"ltp":9.0,"tv":20.88,"id":13011472},{"batb":[[1,1.9,17.39],[2,1.84,19.2]],"ltp":1.63,"tv":164.27,"id":16665613}]}]}
{"op":"mcm","clk":"1009138394","pt":1580642273856,"mc":[{"id":"1.168224333","rc":[{"batl":[[1,9.6,8.89],[2,9.6,0]],"ltp":7.6,"tv":10.0,"id":13011471},{"batb":[[0,3.75,13.22],[1,3.7,15.12],[2,1.01,0.51]],"batl":[[1,4.6,20.3],[2,4.6,0]],"ltp":0.0,"tv":0.0,"id":16665614},{"batb":[[0,7,6.72]],"batl":[[0,8.6,5.04],[1,9,10.07],[2,9,0]],"ltp":9.0,"tv":20.88,"id":13011472},{"batb":[[1,1.84,19.2],[2,1.01,0.51]],"batl":[[0,2.12,36.97],[1,2.18,26.44],[2,2.18,0]],"ltp":1.63,"tv":164.27,"id":16665613}]}]}
{"op":"mcm","clk":"1009138477","pt":1580642274498,"mc":[{"id":"1.168224333","rc":[{"batb":[[0,7.4,10.7]],"batl":[[0,9.6,8.89],[1,9.6,0]],"ltp":7.6,"tv":10.0,"id":13011471},{"batb":[[1,1.01,0.51],[2,1.01,0]],"batl":[[0,4.6,20.3],[1,4.6,0]],"ltp":0.0,"tv":0.0,"id":16665614},{"batb":[[0,6,17.15],[1,1.01,0.51],[2,1.01,0]],"batl":[[0,9,10.07],[1,9,0]],"ltp":9.0,"tv":20.88,"id":13011472},{"batb":[[0,1.84,19.2],[1,1.01,0.51],[2,1.01,0]],"batl":[[0,2.18,26.44],[1,2.18,0]],"ltp":1.63,"tv":164.27,"id":16665613}]}]}
{"op":"mcm","clk":"1009138912","pt":1580642277277,"mc":[{"id":"1.168224333","rc":[{"batb":[[0,8.2,31.39],[1,8,23.07],[2,7.4,10.7]],"ltp":7.6,"tv":10.0,"id":13011471},{"batb":[[1,3.6,61.26],[2,3.55,35.68]],"ltp":0.0,"tv":0.0,"id":16665614},{"batb":[[0,6.4,30.75],[1,6.2,40.39],[2,6,17.15]],"ltp":9.0,"tv":20.88,"id":13011472},{"batb":[[0,1.85,71.58],[1,1.84,19.2],[2,1.83,88.2]],"ltp":1.63,"tv":164.27,"id":16665613}]}]}
{"op":"mcm","clk":"1009139064","pt":1580642278279,"mc":[{"id":"1.168224333","rc":[{"batb":[[0,7.4,10.7],[1,1.01,0.51],[2,7.4,0]],"ltp":7.6,"tv":10.0,"id":13011471},{"batb":[[1,1.01,0.51],[2,3.55,0]],"ltp":0.0,"tv":0.0,"id":16665614},{"batb":[[0,6,17.15],[1,1.01,0.51],[2,6,0]],"ltp":9.0,"tv":20.88,"id":13011472}]}]}
{"op":"mcm","clk":"1009139395","pt":1580642280396,"mc":[{"id":"1.168224333","rc":[{"batb":[[0,9,16.96],[1,8.8,19.06],[2,7.8,9.28]],"batl":[[1,9.8,8.42]],"ltp":7.6,"tv":10.0,"id":13011471},{"batb":[[0,3.95,56.4],[1,3.9,28.66],[2,3.75,13.22]],"batl":[[1,4.7,19.51]],"ltp":0.0,"tv":0.0,"id":16665614},{"batb":[[0,8,25.05],[1,7.8,24.64],[2,7.4,10.62]],"batl":[[1,9.6,9.05]],"ltp":9.0,"tv":20.88,"id":13011472},{"batl":[[0,1.92,18.88],[1,2.04,15.82],[2,2.18,26.44]],"ltp":1.63,"tv":164.27,"id":16665613}]}]}
{"op":"mcm","clk":"1009139537","pt":1580642281404,"mc":[{"id":"1.168224333","rc":[{"batl":[[0,9.4,4.2],[1,9.6,8.89],[2,9.8,8.42]],"ltp":7.6,"tv":10.0,"id":13011471},{"batb":[[2,3.75,15.12]],"batl":[[0,4.3,12.6],[1,4.6,20.3],[2,4.7,19.51]],"ltp":0.0,"tv":0.0,"id":16665614},{"batb":[[2,7.4,16.5]],"batl":[[1,9.2,5.04],[2,9.6,9.05]],"ltp":9.0,"tv":20.88,"id":13011472},{"batb":[[0,1.87,47.89],[1,1.85,71.58],[2,1.84,19.2]],"batl":[[1,2.04,56.14],[2,2.18,0]],"ltp":1.63,"tv":164.27,"id":16665613}]}]}
{"op":"mcm","clk":"1009141065","pt":1580642291212,"mc":[{"id":"1.168224333","rc":[{"batb":[[0,7.6,15.95],[1,1.01,0.51],[2,7.8,0]],"batl":[[1,9.8,8.42],[2,9.8,0]],"ltp":7.6,"tv":10.0,"id":13011471},{"batb":[[0,3.95,23.76],[1,3.75,15.12],[2,1.01,0.51]],"batl":[[1,4.7,19.51],[2,4.7,0]],"ltp":0.0,"tv":0.0,"id":16665614},{"batb":[[0,7.4,5.88],[1,6.6,13.93],[2,1.01,0.51]],"batl":[[0,9.2,5.04],[1,9.6,9.05],[2,9.6,0]],"ltp":9.0,"tv":20.88,"id":13011472},{"batb":[[1,1.8,20.77],[2,1.01,0.51]],"batl":[[0,2.04,56.14],[1,2.04,0]],"ltp":1.63,"tv":164.27,"id":16665613}]}]}
{"op":"mcm","clk":"1009141230","pt":1580642292312,"mc":[{"id":"1.168224333","rc":[{"batb":[[0,6.6,13.93],[1,1.01,0.51],[2,1.01,0]],"batl":[[0,9.6,9.05],[1,9.6,0]],"ltp":9.0,"tv":20.88,"id":13011472}]}]}
{"op":"mcm","clk":"1009141294","pt":1580642292591,"mc":[{"id":"1.168224333","rc":[{"batb":[[0,7.6,10.07]],"batl":[[0,9.8,8.42],[1,9.8,0]],"ltp":7.6,"tv":10.0,"id":13011471},{"batb":[[1,1.01,0.51],[2,1.01,0]],"batl":[[0,4.7,19.51],[1,4.7,0]],"ltp":0.0,"tv":0.0,"id":16665614},{"batb":[[0,1.8,20.77],[1,1.01,0.51],[2,1.01,0]],"batl":[[0,2.04,15.82]],"ltp":1.63,"tv":164.27,"id":16665613}]}]}
{"op":"mcm","clk":"1009141587","pt":1580642293714,"mc":[{"id":"1.168224333","rc":[{"batb":[[0,8.6,21.69],[1,8.4,20.96],[2,7.6,10.07]],"ltp":7.6,"tv":10.0,"id":13011471},{"batb":[[1,3.8,42.23],[2,3.75,31.4]],"ltp":0.0,"tv":0.0,"id":16665614},{"batb":[[0,7.2,25.7],[1,7,31.12],[2,6.6,13.93]],"ltp":9.0,"tv":20.88,"id":13011472},{"batb":[[0,1.81,58.68],[1,1.8,20.77],[2,1.79,94.8]],"ltp":1.63,"tv":164.27,"id":16665613}]}]}
{"op":"mcm","clk":"1009141807","pt":1580642295207,"mc":[{"id":"1.168224333","rc":[{"batb":[[0,7.6,5.88],[1,7.2,25.7],[2,7,31.12]],"batl":[[0,9.4,4.2],[1,9.6,9.05]],"ltp":9.0,"tv":20.88,"id":13011472}]}]}
{"op":"mcm","clk":"1009141863","pt":1580642295618,"mc":[{"id":"1.168224333","rc":[{"batb":[[0,7.2,25.7],[1,7,31.12],[2,6.6,13.93]],"batl":[[0,9.6,9.05],[1,9.6,0]],"ltp":9.0,"tv":20.88,"id":13011472}]}]}
{"op":"mcm","clk":"1009142496","pt":1580642300157,"mc":[{"id":"1.168224333","rc":[{"batb":[[0,1.8,20.77],[1,1.01,0.51],[2,1.79,0]],"ltp":1.63,"tv":164.27,"id":16665613}]}]}
{"op":"mcm","clk":"1009142990","pt":1580642303315,"mc":[{"id":"1.168224333","rc":[{"batl":[[0,9.2,9.6],[1,9.4,9.21],[2,9.8,8.42]],"ltp":7.6,"tv":10.0,"id":13011471},{"batl":[[0,4.4,22.42],[1,4.6,20.61],[2,4.7,19.51]],"ltp":0.0,"tv":0.0,"id":16665614},{"batl":[[0,8,13.06],[1,8.8,10.7],[2,9.6,9.05]],"ltp":9.0,"tv":20.88,"id":13011472},{"batb":[[0,1.95,72.55],[1,1.93,74.46],[2,1.87,18.41]],"batl":[[1,2.28,23.05]],"ltp":1.63,"tv":164.27,"id":16665613}]}]}
{"op":"mcm","clk":"1009143015","pt":1580642303526,"mc":[{"id":"1.168224333","rc":[{"batl":[[0,9.2,14.64],[2,9.8,0]],"ltp":7.6,"tv":10.0,"id":13011471},{"batl":[[0,4.2,12.6],[1,4.4,22.42],[2,4.6,20.61]],"ltp":0.0,"tv":0.0,"id":16665614},{"batb":[[1,7,37.84]],"batl":[[1,8.6,5.04],[2,8.8,10.7]],"ltp":9.0,"tv":20.88,"id":13011472},{"batb":[[1,1.94,44.53],[2,1.93,74.46]],"batl":[[1,2.12,36.97],[2,2.28,23.05]],"ltp":1.63,"tv":164.27,"id":16665613}]}]}
{"op":"mcm","clk":"1009145471","pt":1580642319961,"mc":[{"id":"1.168224333","rc":[{"batb":[[0,7.4,5.88],[1,7.2,11.33],[2,1.01,0.51]],"batl":[[0,9.2,5.04]],"ltp":7.6,"tv":10.0,"id":13011471},{"batb":[[0,3.7,13.85],[1,3.65,15.12],[2,1.01,0.51]],"batl":[[1,4.6,20.61],[2,4.6,0]],"ltp":0.0,"tv":0.0,"id":16665614},{"batb":[[0,7,6.72],[1,5.6,20.46],[2,1.01,0.51]],"batl":[[0,8.6,5.04],[1,8.8,10.7],[2,8.8,0]],"ltp":9.0,"tv":20.88,"id":13011472},{"batb":[[0,1.94,44.53],[1,1.87,18.41],[2,1.01,0.51]],"batl":[[0,2.12,36.97],[1,2.28,23.05],[2,2.28,0]],"ltp":1.63,"tv":164.27,"id":16665613}]}]}
{"op":"mcm","clk":"1009145562","pt":1580642320554,"mc":[{"id":"1.168224333","rc":[{"batb":[[0,7.2,11.33],[1,1.01,0.51],[2,1.01,0]],"batl":[[0,9.4,9.21],[1,9.4,0]],"ltp":7.6,"tv":10.0,"id":13011471},{"batb":[[1,1.01,0.51],[2,1.01,0]],"batl":[[0,4.6,20.61],[1,4.6,0]],"ltp":0.0,"tv":0.0,"id":16665614},{"batb":[[0,5.6,20.46],[1,1.01,0.51],[2,1.01,0]],"batl":[[0,8.8,10.7],[1,8.8,0]],"ltp":9.0,"tv":20.88,"id":13011472},{"batb":[[0,1.87,18.41],[1,1.01,0.51],[2,1.01,0]],"batl":[[0,2.28,23.05],[1,2.28,0]],"ltp":1.63,"tv":164.27,"id":16665613}]}]}
{"op":"mcm","clk":"1009145983","pt":1580642323280,"mc":[{"id":"1.168224333","rc":[{"batb":[[0,8,35.57],[1,7.8,24.29],[2,7.2,11.33]],"ltp":7.6,"tv":10.0,"id":13011471},{"batb":[[1,3.55,49.75],[2,3.5,37.06]],"ltp":0.0,"tv":0.0,"id":16665614},{"batb":[[0,6,50.94],[1,5.9,22.63],[2,5.6,20.46]],"ltp":9.0,"tv":20.88,"id":13011472},{"batb":[[1,1.86,68.47],[2,1.84,86.65]],"ltp":1.63,"tv":164.27,"id":16665613}]}]}
{"op":"mcm","clk":"1009146279","pt":1580642325398,"mc":[{"id":"1.168224333","rc":[{"batb":[[0,7.2,11.33],[1,1.01,0.51],[2,7.2,0]],"ltp":7.6,"tv":10.0,"id":13011471},{"batb":[[1,1.01,0.51],[2,3.5,0]],"ltp":0.0,"tv":0.0,"id":16665614},{"batb":[[0,5.6,20.46],[1,1.01,0.51],[2,5.6,0]],"ltp":9.0,"tv":20.88,"id":13011472}]}]}
{"op":"mcm","clk":"1009146754","pt":1580642328077,"mc":[{"id":"1.168224333","rc":[{"batb":[[0,8.8,27.87],[1,8.6,19.79],[2,7.2,11.33]],"ltp":7.6,"tv":10.0,"id":13011471},{"batb":[[0,3.95,31.75],[1,3.9,28.67],[2,3.7,13.85]],"ltp":0.0,"tv":0.0,"id":16665614},{"batb":[[0,8,12.77],[1,7.8,24.92],[2,5.6,20.46]],"ltp":9.0,"tv":20.88,"id":13011472}]}]}
{"op":"mcm","clk":"1009146960","pt":1580642329193,"mc":[{"id":"1.168224333","rc":[{"batb":[[2,7.8,9.68]],"batl":[[1,9.6,8.81]],"ltp":7.6,"tv":10.0,"id":13011471},{"batb":[[0,4,21.79],[1,3.95,31.75],[2,3.9,52.51]],"batl":[[0,4.6,19.83]],"ltp":0.0,"tv":0.0,"id":16665614},{"batb":[[2,7.2,11.33]],"batl":[[1,9.2,9.76]],"ltp":9.0,"tv":20.88,"id":13011472},{"batl":[[0,1.95,18.1],[1,2.08,30.06]],"ltp":1.63,"tv":164.27,"id":16665613}]}]}
{"op":"mcm","clk":"1009147014","pt":1580642329464,"mc":[{"id":"1.168224333","rc":[{"batl":[[0,9.4,13.41]],"ltp":7.6,"tv":10.0,"id":13011471},{"batl":[[0,4.3,12.6],[1,4.6,19.83]],"ltp":0.0,"tv":0.0,"id":16665614},{"batb":[[2,7.6,5.88]],"batl":[[1,9.2,14.8]],"ltp":9.0,"tv":20.88,"id":13011472},{"batb":[[0,1.87,66.3]],"batl":[[1,2.04,40.33],[2,2.08,30.06]],"ltp":1.63,"tv":164.27,"id":16665613}]}]}
{"op":"mcm","clk":"1009148509","pt":1580642338677,"mc":[{"id":"1.168224333","rc":[{"batb":[[0,7.8,24.92],[1,7.6,5.88],[2,7.2,11.33]],"ltp":9.0,"tv":20.88,"id":13011472}]}]}
{"op":"mcm","clk":"1009149143","pt":1580642342213,"mc":[{"id":"1.168224333","rc":[{"batb":[[0,7.8,37.7],[1,7.6,31.65]],"ltp":9.0,"tv":20.88,"id":13011472}]}]}
{"op":"mcm","clk":"1009149297","pt":1580642343281,"mc":[{"id":"1.168224333","rc":[{"batb":[[0,8.6,14.42],[1,7.6,5.88],[2,7.4,10.46]],"batl":[[0,9.4,4.2]],"ltp":7.6,"tv":10.0,"id":13011471},{"batb":[[0,3.9,23.84],[1,3.75,15.12],[2,1.01,0.51]],"ltp":0.0,"tv":0.0,"id":16665614},{"batb":[[0,7.6,5.88],[1,6.4,14.95],[2,1.01,0.51]],"batl":[[0,9.2,14.8],[1,9.2,0]],"ltp":9.0,"tv":20.88,"id":13011472},{"batb":[[0,1.87,47.89],[1,1.82,19.83],[2,1.01,0.51]],"batl":[[0,2.04,40.33],[1,2.08,30.06],[2,2.08,0]],"ltp":1.63,"tv":164.27,"id":16665613}]}]}
{"op":"mcm","clk":"1009149592","pt":1580642344997,"mc":[{"id":"1.168224333","rc":[{"batb":[[1,7.4,10.46],[2,1.01,0.51]],"batl":[[0,9.6,8.81],[1,9.6,0]],"ltp":7.6,"tv":10.0,"id":13011471},{"batb":[[1,1.01,0.51],[2,1.01,0]],"batl":[[0,4.6,19.83],[1,4.6,0]],"ltp":0.0,"tv":0.0,"id":16665614},{"batb":[[0,6.4,14.95],[1,1.01,0.51],[2,1.01,0]],"batl":[[0,9.2,9.76]],"ltp":9.0,"tv":20.88,"id":13011472},{"batb":[[0,1.82,19.83],[1,1.01,0.51],[2,1.01,0]],"batl":[[0,2.08,30.06],[1,2.08,0]],"ltp":1.63,"tv":164.27,"id":16665613}]}]}
{"op":"mcm","clk":"1009150189","pt":1580642348229,"mc":[{"id":"1.168224333","rc":[{"batb":[[0,8.8,21.03],[1,8.6,19.93],[2,7.4,10.46]],"ltp":7.6,"tv":10.0,"id":13011471},{"batb":[[0,3.9,69.64],[1,3.85,29.44],[2,1.01,0.51]],"ltp":0.0,"tv":0.0,"id":16665614},{"batb":[[0,7.8,16.74],[1,7.6,26.24],[2,6.4,14.95]],"ltp":9.0,"tv":20.88,"id":13011472},{"batb":[[0,1.88,59.91],[1,1.86,83.68],[2,1.82,19.83]],"ltp":1.63,"tv":164.27,"id":16665613}]}]}
{"op":"mcm","clk":"1009150650","pt":1580642351320,"mc":[{"id":"1.168224333","rc":[{"batb":[[0,8.6,14.42],[1,7.4,10.46],[2,1.01,0.51]],"ltp":7.6,"tv":10.0,"id":13011471},{"batb":[[0,3.9,23.84],[1,1.01,0.51],[2,1.01,0]],"ltp":0.0,"tv":0.0,"id":16665614},{"batb":[[0,6.4,14.95],[1,1.01,0.51],[2,6.4,0]],"ltp":9.0,"tv":20.88,"id":13011472},{"batb":[[0,1.82,19.83],[1,1.01,0.51],[2,1.82,0]],"ltp":1.63,"tv":164.27,"id":16665613}]}]}
{"op":"mcm","clk":"1009151137","pt":1580642354708,"mc":[{"id":"1.168224333","rc":[{"batb":[[1,8.4,21.1],[2,7.4,10.46]],"ltp":7.6,"tv":10.0,"id":13011471},{"batb":[[1,3.8,47.63],[2,3.75,31.35]],"ltp":0.0,"tv":0.0,"id":16665614},{"batb":[[0,7.2,16.58],[1,7,31.33],[2,6.4,14.95]],"ltp":9.0,"tv":20.88,"id":13011472}]}]}
{"op":"mcm","clk":"1009151609","pt":1580642357914,"mc":[{"id":"1.168224333","rc":[{"batb":[[0,1.95,76.66],[1,1.93,74.46],[2,1.82,19.83]],"ltp":1.63,"tv":164.27,"id":16665613}]}]}
{"op":"mcm","clk":"1009151786","pt":1580642359247,"mc":[{"id":"1.168224333","rc":[{"batl":[[0,9,9.91],[1,9.2,9.52]],"ltp":7.6,"tv":10.0,"id":13011471},{"batl":[[0,4.4,22.5],[1,4.5,20.93]],"ltp":0.0,"tv":0.0,"id":16665614},{"batl":[[0,7.8,14.01],[1,8.6,11.49]],"ltp":9.0,"tv":20.88,"id":13011472},{"batb":[[0,1.97,15.5],[1,1.95,76.66],[2,1.93,74.46]],"batl":[[1,2.34,21.56]],"ltp":1.63,"tv":164.27,"id":16665613}]}]}
{"op":"mcm","clk":"1009151826","pt":1580642359519,"mc":[{"id":"1.168224333","rc":[{"batb":[[2,7.4,16.35]],"batl":[[0,9,14.96]],"ltp":7.6,"tv":10.0,"id":13011471},{"batl":[[0,4.2,12.6],[1,4.4,22.5],[2,4.5,20.93]],"ltp":0.0,"tv":0.0,"id":16665614},{"batb":[[1,7,38.05]],"batl":[[1,8.6,16.53]],"ltp":9.0,"tv":20.88,"id":13011472},{"batb":[[2,1.94,44.53]],"batl":[[1,2.12,36.97],[2,2.34,21.56]],"ltp":1.63,"tv":164.27,"id":16665613}]}]}
{"op":"mcm","clk":"1009153487","pt":1580642370906,"mc":[{"id":"1.168224333","rc":[{"batb":[[0,7.2,11.8],[1,1.01,0.51],[2,7.4,0]],"batl":[[0,9.2,9.52],[1,9.2,0]],"ltp":7.6,"tv":10.0,"id":13011471},{"batb":[[0,3.65,14.08],[1,1.01,0.51],[2,3.75,0]],"batl":[[0,4.5,20.93],[1,4.4,0],[2,4.5,0]],"ltp":0.0,"tv":0.0,"id":16665614},{"batb":[[0,5.5,11.02],[1,1.01,0.51],[2,6.4,0]],"batl":[[0,8.6,11.49],[1,8.6,0]],"ltp":9.0,"tv":20.88,"id":13011472},{"batb":[[0,1.89,17.62],[1,1.01,0.51],[2,1.94,0]],"batl":[[0,2.34,21.56],[1,2.12,0],[2,2.34,0]],"ltp":1.63,"tv":164.27,"id":16665613}]}]}
{"op":"mcm","clk":"1009153911","pt":1580642373936,"mc":[{"id":"1.168224333","rc":[{"batb":[[0,8,24.62],[1,7.8,24.53],[2,7.2,11.25]],"batl":[[0,9.4,9.05]],"ltp":7.6,"tv":10.0,"id":13011471},{"batb":[[1,3.55,39.44],[2,3.5,37.15]],"ltp":0.0,"tv":0.0,"id":16665614},{"batb":[[0,5.9,39.36],[1,5.8,23.67],[2,5.6,10.54]],"batl":[[0,8.8,10.94]],"ltp":9.0,"tv":20.88,"id":13011472},{"batb":[[0,1.88,18.02],[1,1.85,95.11],[2,1.83,88.22]],"batl":[[0,2.32,22.03]],"ltp":1.63,"tv":164.27,"id":16665613}]}]}
{"op":"mcm","clk":"1009158022","pt":1580642403389,"mc":[{"id":"1.168224333","rc":[{"batb":[[0,7.2,11.25],[1,1.01,0.51],[2,7.2,0]],"ltp":7.6,"tv":10.0,"id":13011471},{"batb":[[1,1.01,0.51],[2,3.5,0]],"ltp":0.0,"tv":0.0,"id":16665614},{"batb":[[0,5.6,10.54],[1,1.01,0.51],[2,5.6,0]],"ltp":9.0,"tv":20.88,"id":13011472}]}]}
{"op":"mcm","clk":"1009158568","pt":1580642406292,"mc":[{"id":"1.168224333","rc":[{"batb":[[0,8.8,22.48],[1,8.6,19.9],[2,7.2,11.25]],"ltp":7.6,"tv":10.0,"id":13011471},{"batb":[[0,3.95,44.35],[1,3.9,28.55],[2,3.65,14.08]],"ltp":0.0,"tv":0.0,"id":16665614},{"batb":[[0,8,16.02],[1,7.8,24.84],[2,5.6,10.54]],"ltp":9.0,"tv":20.88,"id":13011472}]}]}
{"op":"mcm","clk":"1009158724","pt":1580642407302,"mc":[{"id":"1.168224333","rc":[{"batb":[[2,7.8,9.52]],"batl":[[1,10,8.1]],"ltp":7.6,"tv":10.0,"id":13011471},{"batb":[[0,4,22.42],[1,3.95,44.35],[2,3.9,28.55]],"batl":[[1,4.9,17.47]],"ltp":0.0,"tv":0.0,"id":16665614},{"batb":[[2,7.2,11.57]],"batl":[[1,11,7]],"ltp":9.0,"tv":20.88,"id":13011472},{"batl":[[0,1.96,17.7],[1,2.1,29.19]],"ltp":1.63,"tv":164.27,"id":16665613}]}]}
{"op":"mcm","clk":"1009158865","pt":1580642407998,"mc":[{"id":"1.168224333","rc":[{"batl":[[1,9.6,4.2],[2,10,8.1]],"ltp":7.6,"tv":10.0,"id":13011471},{"batl":[[0,4.3,12.6],[1,4.5,20.93],[2,4.9,17.47]],"ltp":0.0,"tv":0.0,"id":16665614},{"batb":[[1,7.8,30.72]],"batl":[[1,9.6,4.2],[2,11,7]],"ltp":9.0,"tv":20.88,"id":13011472},{"batb":[[1,1.87,47.89],[2,1.85,95.11]],"batl":[[1,2.02,41.17],[2,2.1,29.19]],"ltp":1.63,"tv":164.27,"id":16665613}]}]}
{"op":"mcm","clk":"1009163050","pt":1580642435319,"mc":[{"id":"1.168224333","rc":[{"batb":[[0,7.6,16.27],[1,1.01,0.51],[2,7.8,0]],"batl":[[0,9.6,4.2],[1,10,8.1],[2,10,0]],"ltp":7.6,"tv":10.0,"id":13011471},{"batb":[[0,3.85,25.18],[1,3.75,15.12],[2,1.01,0.51]],"batl":[[1,4.9,17.47],[2,4.9,0]],"ltp":0.0,"tv":0.0,"id":16665614},{"batb":[[0,7.8,5.88],[1,6.4,14.79],[2,1.01,0.51]],"batl":[[0,9.6,4.2],[1,11,7],[2,11,0]],"ltp":9.0,"tv":20.88,"id":13011472},{"batb":[[0,1.87,47.89],[1,1.72,24.16],[2,1.01,0.51]],"batl":[[0,2.02,41.17],[1,2.1,29.19],[2,2.1,0]],"ltp":1.63,"tv":164.27,"id":16665613}]}]}
{"op":"mcm","clk":"1009163303","pt":1580642437125,"mc":[{"id":"1.168224333","rc":[{"batb":[[0,7.6,10.39]],"batl":[[0,10,8.1],[1,10,0]],"ltp":7.6,"tv":10.0,"id":13011471},{"batb":[[1,1.01,0.51],[2,1.01,0]],"batl":[[0,4.9,17.47],[1,4.9,0]],"ltp":0.0,"tv":0.0,"id":16665614},{"batb":[[0,6.4,14.79],[1,1.01,0.51],[2,1.01,0]],"batl":[[0,11,7],[1,11,0]],"ltp":9.0,"tv":20.88,"id":13011472},{"batb":[[0,1.72,24.16],[1,1.01,0.51],[2,1.01,0]],"batl":[[0,2.1,29.19],[1,2.1,0]],"ltp":1.63,"tv":164.27,"id":16665613}]}]}
{"op":"mcm","clk":"1009163433","pt":1580642438016,"mc":[{"id":"1.168224333","rc":[{"batb":[[0,8.4,27.93],[1,8.2,21.93],[2,7.6,10.39]],"ltp":7.6,"tv":10.0,"id":13011471},{"batb":[[1,3.75,54.75],[2,3.7,32.31]],"ltp":0.0,"tv":0.0,"id":16665614},{"batb":[[0,7,29.26],[1,6.8,33.04],[2,6.4,14.79]],"ltp":9.0,"tv":20.88,"id":13011472},{"batb":[[1,1.7,115.8],[2,1.68,117.9]],"ltp":1.63,"tv":164.27,"id":16665613}]}]}
{"op":"mcm","clk":"1009163813","pt":1580642440619,"mc":[{"id":"1.168224333","rc":[{"batb":[[0,7.6,10.39],[1,1.01,0.51],[2,7.6,0]],"ltp":7.6,"tv":10.0,"id":13011471},{"batb":[[1,1.01,0.51],[2,3.7,0]],"ltp":0.0,"tv":0.0,"id":16665614},{"batb":[[0,6.4,14.79],[1,1.01,0.51],[2,6.4,0]],"ltp":9.0,"tv":20.88,"id":13011472}]}]}
{"op":"mcm","clk":"1009164243","pt":1580642443643,"mc":[{"id":"1.168224333","rc":[{"batb":[[0,9.4,18.63],[1,9.2,17.29],[2,7.6,10.39]],"ltp":7.6,"tv":10.0,"id":13011471},{"batb":[[0,4.2,68.15],[1,4.1,49.65],[2,3.85,25.18]],"ltp":0.0,"tv":0.0,"id":16665614},{"batb":[[0,9.8,18.75],[1,9.6,15.91],[2,6.4,14.79]],"ltp":9.0,"tv":20.88,"id":13011472}]}]}
{"op":"mcm","clk":"1009164419","pt":1580642444764,"mc":[{"id":"1.168224333","rc":[{"batb":[[2,8.2,8.5]],"batl":[[1,11,6.85]],"ltp":7.6,"tv":10.0,"id":13011471},{"batb":[[0,4.3,18.33],[1,4.2,68.15],[2,4.1,49.65]],"batl":[[1,5.5,13.53]],"ltp":0.0,"tv":0.0,"id":16665614},{"batb":[[2,8.8,7.32]],"batl":[[1,16,8.73]],"ltp":9.0,"tv":20.88,"id":13011472},{"batl":[[0,1.79,23.68],[1,1.92,18.8]],"ltp":1.63,"tv":164.27,"id":16665613}]}]}
{"op":"mcm","clk":"1009164558","pt":1580642445626,"mc":[{"id":"1.168224333","rc":[{"batl":[[0,10,12.31]],"ltp":7.6,"tv":10.0,"id":13011471},{"batl":[[0,4.6,10.92],[1,4.9,17.47],[2,5.5,13.53]],"ltp":0.0,"tv":0.0,"id":16665614},{"batb":[[2,9.2,5.04]],"batl":[[1,11.5,3.36],[2,16,8.73]],"ltp":9.0,"tv":20.88,"id":13011472},{"batb":[[0,1.72,82.13]],"batl":[[1,1.86,42.01],[2,1.92,18.8]],"ltp":1.63,"tv":164.27,"id":16665613}]}]}
{"op":"mcm","clk":"1009166598","pt":1580642459268,"mc":[{"id":"1.168224333","rc":[{"batb":[[0,8,5.88],[1,7.8,9.36],[2,1.01,0.51]],"batl":[[0,10,4.2]],"ltp":7.6,"tv":10.0,"id":13011471},{"batb":[[0,4,35.24],[1,1.01,0.51],[2,4.1,0]],"batl":[[1,5.5,13.53],[2,5.5,0]],"ltp":0.0,"tv":0.0,"id":16665614},{"batb":[[0,9.2,5.04],[1,7.6,10.39],[2,1.01,0.51]],"batl":[[0,11.5,3.36],[1,16,8.73],[2,16,0]],"ltp":9.0,"tv":20.88,"id":13011472},{"batb":[[0,1.72,57.97],[1,1.56,34.38],[2,1.01,0.51]],"batl":[[0,1.86,42.01],[1,1.92,18.8],[2,1.92,0]],"ltp":1.63,"tv":164.27,"id":16665613}]}]}
{"op":"mcm","clk":"1009166758","pt":1580642460652,"mc":[{"id":"1.168224333","rc":[{"batb":[[0,7.8,9.36],[1,1.01,0.51],[2,1.01,0]],"batl":[[0,11,6.85],[1,11,0]],"ltp":7.6,"tv":10.0,"id":13011471},{"batb":[[0,4,21.79]],"batl":[[0,5.5,13.53],[1,5.5,0]],"ltp":0.0,"tv":0.0,"id":16665614},{"batb":[[0,7.6,10.39],[1,1.01,0.51],[2,1.01,0]],"batl":[[0,16,8.73],[1,16,0]],"ltp":9.0,"tv":20.88,"id":13011472},{"batb":[[0,1.56,34.38],[1,1.01,0.51],[2,1.01,0]],"batl":[[0,1.92,18.8],[1,1.92,0]],"ltp":1.63,"tv":164.27,"id":16665613}]}]}
{"op":"mcm","clk":"1009167177","pt":1580642463359,"mc":[{"id":"1.168224333","rc":[{"batb":[[0,9.6,13.65],[1,9.4,16.6],[2,7.8,9.36]],"ltp":7.6,"tv":10.0,"id":13011471},{"batb":[[0,4.3,57.71],[1,4.2,47.08],[2,4,21.79]],"ltp":0.0,"tv":0.0,"id":16665614},{"batb":[[0,10,44.52],[1,9.8,14.76],[2,7.6,10.39]],"ltp":9.0,"tv":20.88,"id":13011472},{"batb":[[0,1.67,109.25],[1,1.66,61.88],[2,1.56,34.38]],"ltp":1.63,"tv":164.27,"id":16665613}]}]}
{"op":"mcm","clk":"1009167601","pt":1580642466269,"mc":[{"id":"1.168224333","rc":[{"batb":[[0,7.8,9.36],[1,1.01,0.51],[2,7.8,0]],"ltp":7.6,"tv":10.0,"id":13011471},{"batb":[[0,4,21.79],[1,1.01,0.51],[2,4,0]],"ltp":0.0,"tv":0.0,"id":16665614},{"batb":[[0,7.6,10.39],[1,1.01,0.51],[2,7.6,0]],"ltp":9.0,"tv":20.88,"id":13011472},{"batb":[[0,1.56,34.38],[1,1.01,0.51],[2,1.56,0]],"ltp":1.63,"tv":164.27,"id":16665613}]}]}
{"op":"mcm","clk":"1009168050","pt":1580642469198,"mc":[{"id":"1.168224333","rc":[{"batb":[[0,9,12.06],[1,8.8,19.15],[2,7.8,9.36]],"ltp":7.6,"tv":10.0,"id":13011471},{"batb":[[0,4,58.36],[1,3.95,27.77],[2,1.01,0.51]],"ltp":0.0,"tv":0.0,"id":16665614},{"batb":[[0,8.2,23.58],[1,8,23.36],[2,7.6,10.39]],"ltp":9.0,"tv":20.88,"id":13011472},{"batb":[[0,1.56,115.06],[1,1.55,79.68],[2,1.01,0.51]],"ltp":1.63,"tv":164.27,"id":16665613}]}]}
{"op":"mcm","clk":"1009168647","pt":1580642473396,"mc":[{"id":"1.168224333","rc":[{"batb":[[0,1.56,34.38],[1,1.01,0.51],[2,1.01,0]],"ltp":1.63,"tv":164.27,"id":16665613}]}]}
{"op":"mcm","clk":"1009169089","pt":1580642476392,"mc":[{"id":"1.168224333","rc":[{"batb":[[0,1.83,74.64],[1,1.81,91.42],[2,1.56,34.38]],"ltp":1.63,"tv":164.27,"id":16665613}]}]}
{"op":"mcm","clk":"1009169181","pt":1580642477018,"mc":[{"id":"1.168224333","rc":[{"batl":[[0,9.6,8.89],[1,10.5,7.79]],"ltp":7.6,"tv":10.0,"id":13011471},{"batb":[[2,3.85,24.94]],"batl":[[0,4.6,20.69],[1,5,16.44]],"ltp":0.0,"tv":0.0,"id":16665614},{"batl":[[0,9.2,9.84],[1,12.5,13.61]],"ltp":9.0,"tv":20.88,"id":13011472},{"batb":[[0,1.84,19.12],[1,1.83,74.64],[2,1.81,91.42]],"batl":[[1,2.08,30.06]],"ltp":1.63,"tv":164.27,"id":16665613}]}]}
{"op":"mcm","clk":"1009169277","pt":1580642477706,"mc":[{"id":"1.168224333","rc":[{"batb":[[2,7.8,15.24]],"batl":[[0,9.6,13.09]],"ltp":7.6,"tv":10.0,"id":13011471},{"batl":[[0,4.3,12.6],[1,4.6,20.69],[2,5,16.44]],"ltp":0.0,"tv":0.0,"id":16665614},{"batb":[[0,8.2,28.62]],"batl":[[1,10,4.2],[2,12.5,13.61]],"ltp":9.0,"tv":20.88,"id":13011472},{"batb":[[1,1.83,125.05]],"batl":[[1,1.98,42.01],[2,2.08,30.06]],"ltp":1.63,"tv":164.27,"id":16665613}]}]}
{"op":"mcm","clk":"1009171056","pt":1580642491050,"mc":[{"id":"1.168224333","rc":[{"batb":[[0,7.8,5.88],[1,7.6,10.07],[2,1.01,0.51]],"batl":[[0,9.6,4.2]],"ltp":7.6,"tv":10.0,"id":13011471},{"batb":[[0,3.85,24.94],[1,3.8,14.28],[2,1.01,0.51]],"batl":[[1,5,16.44],[2,5,0]],"ltp":0.0,"tv":0.0,"id":16665614},{"batb":[[0,8.2,5.04],[1,6.6,14.32],[2,1.01,0.51]],"batl":[[0,10,4.2],[1,12.5,13.61],[2,12.5,0]],"ltp":9.0,"tv":20.88,"id":13011472},{"batb":[[0,1.83,50.41],[1,1.66,26.91],[2,1.01,0.51]],"batl":[[0,1.98,42.01],[1,2.08,30.06],[2,2.08,0]],"ltp":1.63,"tv":164.27,"id":16665613}]}]}
{"op":"mcm","clk":"1009171249","pt":1580642492653,"mc":[{"id":"1.168224333","rc":[{"batb":[[0,7.6,10.07],[1,1.01,0.51],[2,1.01,0]],"batl":[[0,10.5,7.79],[1,10.5,0]],"ltp":7.6,"tv":10.0,"id":13011471},{"batb":[[1,1.01,0.51],[2,1.01,0]],"batl":[[0,5,16.44],[1,5,0]],"ltp":0.0,"tv":0.0,"id":16665614},{"batb":[[0,6.6,14.32],[1,1.01,0.51],[2,1.01,0]],"batl":[[0,12.5,13.61],[1,12.5,0]],"ltp":9.0,"tv":20.88,"id":13011472},{"batb":[[0,1.66,26.91],[1,1.01,0.51],[2,1.01,0]],"batl":[[0,2.08,30.06],[1,2.08,0]],"ltp":1.63,"tv":164.27,"id":16665613}]}]}
{"op":"mcm","clk":"1009171700","pt":1580642496230,"mc":[{"id":"1.168224333","rc":[{"batb":[[0,9,23.83],[1,8.8,18.91],[2,7.6,10.07]],"ltp":7.6,"tv":10.0,"id":13011471},{"batb":[[0,4,74.85],[1,3.95,27.42],[2,3.85,24.94]],"ltp":0.0,"tv":0.0,"id":16665614},{"batb":[[0,8.6,22.07],[1,8.4,21.07],[2,6.6,14.32]],"ltp":9.0,"tv":20.88,"id":13011472},{"batb":[[0,1.79,92.94],[1,1.77,98.49],[2,1.66,26.91]],"ltp":1.63,"tv":164.27,"id":16665613}]}]}
{"op":"mcm","clk":"1009172036","pt":1580642499144,"mc":[{"id":"1.168224333","rc":[{"batb":[[0,7.6,10.07],[1,1.01,0.51],[2,7.6,0]],"ltp":7.6,"tv":10.0,"id":13011471},{"batb":[[0,3.85,24.94],[1,1.01,0.51],[2,3.85,0]],"ltp":0.0,"tv":0.0,"id":16665614},{"batb":[[0,6.6,14.32],[1,1.01,0.51],[2,6.6,0]],"ltp":9.0,"tv":20.88,"id":13011472},{"batb":[[0,1.66,26.91],[1,1.01,0.51],[2,1.66,0]],"ltp":1.63,"tv":164.27,"id":16665613}]}]}
{"op":"mcm","clk":"1009172474","pt":1580642502125,"mc":[{"id":"1.168224333","rc":[{"batb":[[0,8.4,31.19],[1,8.2,21.86],[2,7.6,10.07]],"ltp":7.6,"tv":10.0,"id":13011471},{"batb":[[1,3.75,51.53],[2,3.7,32.34]],"ltp":0.0,"tv":0.0,"id":16665614},{"batb":[[0,7,36.83],[1,6.8,32.85],[2,6.6,14.32]],"ltp":9.0,"tv":20.88,"id":13011472},{"batb":[[0,1.66,116.59],[1,1.65,63.17],[2,1.01,0.51]],"ltp":1.63,"tv":164.27,"id":16665613}]}]}
{"op":"mcm","clk":"1009174244","pt":1580642515286,"mc":[{"id":"1.168224333","rc":[{"batb":[[0,1.66,26.91],[1,1.01,0.51],[2,1.01,0]],"ltp":1.63,"tv":164.27,"id":16665613}]}]}
{"op":"mcm","clk":"1009174707","pt":1580642518171,"mc":[{"id":"1.168224333","rc":[{"batb":[[0,1.97,74.02],[1,1.95,72.1],[2,1.66,26.91]],"ltp":1.63,"tv":164.27,"id":16665613}]}]}
{"op":"mcm","clk":"1009174839","pt":1580642519067,"mc":[{"id":"1.168224333","rc":[{"batl":[[0,9.2,9.6],[1,9.6,8.66]],"ltp":7.6,"tv":10.0,"id":13011471},{"batb":[[2,3.7,46.03]],"batl":[[0,4.3,23.6],[1,4.6,19.91]],"ltp":0.0,"tv":0.0,"id":16665614},{"batl":[[0,8,13.45],[1,9.8,8.89]],"ltp":9.0,"tv":20.88,"id":13011472},{"batb":[[0,1.97,89.52],[2,1.81,20.46]],"batl":[[1,2.22,24.94]],"ltp":1.63,"tv":164.27,"id":16665613}]}]}
{"op":"mcm","clk":"1009174903","pt":1580642519551,"mc":[{"id":"1.168224333","rc":[{"batl":[[0,9.2,14.64]],"ltp":7.6,"tv":10.0,"id":13011471},{"batl":[[0,4.1,13.44],[1,4.3,23.6],[2,4.6,19.91]],"ltp":0.0,"tv":0.0,"id":16665614},{"batb":[[0,7.2,6.72],[1,7,36.83],[2,6.8,32.85]],"batl":[[1,8.8,5.04],[2,9.8,8.89]],"ltp":9.0,"tv":20.88,"id":13011472},{"batb":[[1,1.95,115.79]],"batl":[[1,2.12,36.97],[2,2.22,24.94]],"ltp":1.63,"tv":164.27,"id":16665613}]}]}
{"op":"mcm","clk":"1009177348","pt":1580642536180,"mc":[{"id":"1.168224333","rc":[{"batb":[[0,8.2,21.86],[1,7.4,16.74],[2,1.01,0.51]],"batl":[[0,9.2,5.04]],"ltp":7.6,"tv":10.0,"id":13011471},{"batb":[[0,3.7,13.69],[1,3.6,15.96],[2,1.01,0.51]],"batl":[[1,4.6,19.91],[2,4.6,0]],"ltp":0.0,"tv":0.0,"id":16665614},{"batb":[[1,6,18.02],[2,1.01,0.51]],"batl":[[0,8.8,5.04],[1,9.8,8.89],[2,9.8,0]],"ltp":9.0,"tv":20.88,"id":13011472},{"batb":[[0,1.95,43.69],[1,1.81,20.46],[2,1.01,0.51]],"batl":[[0,2.12,36.97],[1,2.22,24.94],[2,2.22,0]],"ltp":1.63,"tv":164.27,"id":16665613}]}]}
{"op":"mcm","clk":"1009177414","pt":1580642536597,"mc":[{"id":"1.168224333","rc":[{"batb":[[1,7.4,10.86]],"batl":[[0,9.6,8.66],[1,9.6,0]],"ltp":7.6,"tv":10.0,"id":13011471},{"batb":[[1,1.01,0.51],[2,1.01,0]],"batl":[[0,4.6,19.91],[1,4.6,0]],"ltp":0.0,"tv":0.0,"id":16665614},{"batb":[[0,6,18.02],[1,1.01,0.51],[2,1.01,0]],"batl":[[0,9.8,8.89],[1,9.8,0]],"ltp":9.0,"tv":20.88,"id":13011472},{"batb":[[0,1.81,20.46],[1,1.01,0.51],[2,1.01,0]],"batl":[[0,2.22,24.94],[1,2.22,0]],"ltp":1.63,"tv":164.27,"id":16665613}]}]}
{"op":"mcm","clk":"1009177575","pt":1580642537822,"mc":[{"id":"1.168224333","rc":[{"batb":[[0,7.4,10.86],[1,1.01,0.51],[2,1.01,0]],"ltp":7.6,"tv":10.0,"id":13011471}]}]}
{"op":"mcm","clk":"1009178102","pt":1580642540756,"mc":[{"id":"1.168224333","rc":[{"batb":[[0,8.6,20.11],[1,8.4,20.98],[2,7.4,10.86]],"ltp":7.6,"tv":10.0,"id":13011471},{"batb":[[0,3.8,51.26],[1,3.75,31.31],[2,3.7,13.69]],"ltp":0.0,"tv":0.0,"id":16665614},{"batb":[[0,7.2,42.46],[1,7,30.7],[2,6,18.02]],"ltp":9.0,"tv":20.88,"id":13011472},{"batb":[[0,1.94,53.73],[1,1.92,75.67],[2,1.81,20.46]],"ltp":1.63,"tv":164.27,"id":16665613}]}]}
{"op":"mcm","clk":"1009178728","pt":1580642544733,"mc":[{"id":"1.168224333","rc":[{"batb":[[0,7.4,10.86],[1,1.01,0.51],[2,7.4,0]],"ltp":7.6,"tv":10.0,"id":13011471},{"batb":[[0,3.7,13.69],[1,1.01,0.51],[2,3.7,0]],"ltp":0.0,"tv":0.0,"id":16665614},{"batb":[[0,6,18.02],[1,1.01,0.51],[2,6,0]],"ltp":9.0,"tv":20.88,"id":13011472},{"batb":[[0,1.81,20.46],[1,1.01,0.51],[2,1.81,0]],"ltp":1.63,"tv":164.27,"id":16665613}]}]}
{"op":"mcm","clk":"1009179199","pt":1580642547710,"mc":[{"id":"1.168224333","rc":[{"batb":[[0,8.2,17.95],[1,8,23.35],[2,7.4,10.86]],"ltp":7.6,"tv":10.0,"id":13011471},{"batb":[[1,3.6,43.82],[2,3.55,35.83]],"ltp":0.0,"tv":0.0,"id":16665614},{"batb":[[0,6.2,56.46],[1,6,60.7],[2,1.01,0.51]],"ltp":9.0,"tv":20.88,"id":13011472},{"batb":[[1,1.8,98.14],[2,1.78,96.66]],"ltp":1.63,"tv":164.27,"id":16665613}]}]}
{"op":"mcm","clk":"1009179479","pt":1580642549619,"mc":[{"id":"1.168224333","rc":[{"batb":[[1,1.01,0.51],[2,1.78,0]],"ltp":1.63,"tv":164.27,"id":16665613}]}]}
{"op":"mcm","clk":"1009179923","pt":1580642552373,"mc":[{"id":"1.168224333","rc":[{"batb":[[0,2.1,80.88],[1,2.08,59.26],[2,1.81,20.46]],"ltp":1.63,"tv":164.27,"id":16665613}]}]}
{"op":"mcm","clk":"1009180069","pt":1580642553225,"mc":[{"id":"1.168224333","rc":[{"batl":[[0,8.8,10.31],[1,9.2,9.52],[2,9.6,8.66]],"ltp":7.6,"tv":10.0,"id":13011471},{"batb":[[1,3.6,58.22]],"batl":[[0,4.1,13.3],[1,4.3,23.76],[2,4.6,19.91]],"ltp":0.0,"tv":0.0,"id":16665614},{"batb":[[2,5.6,10.39]],"batl":[[0,7,16.84],[1,8,13.38],[2,9.8,8.89]],"ltp":9.0,"tv":20.88,"id":13011472},{"batb":[[0,2.1,106.53],[2,1.97,15.5]],"batl":[[1,2.32,22.19]],"ltp":1.63,"tv":164.27,"id":16665613}]}]}
{"op":"mcm","clk":"1009180162","pt":1580642553804,"mc":[{"id":"1.168224333","rc":[{"batl":[[0,8.8,15.35],[2,9.6,0]],"ltp":7.6,"tv":10.0,"id":13011471},{"batl":[[0,3.9,14.28],[1,4.1,13.3],[2,4.3,23.76]],"ltp":0.0,"tv":0.0,"id":16665614},{"batb":[[0,6.6,6.72],[1,6.2,56.46],[2,6,60.7]],"batl":[[1,8,19.26],[2,9.8,0]],"ltp":9.0,"tv":20.88,"id":13011472},{"batb":[[2,2.06,39.49]],"batl":[[1,2.26,32.77],[2,2.32,22.19]],"ltp":1.63,"tv":164.27,"id":16665613}]}]}
{"op":"mcm","clk":"1009181902","pt":1580642565390,"mc":[{"id":"1.168224333","rc":[{"batb":[[0,8,18.41],[1,7.4,10.86],[2,7.2,18.13]],"ltp":7.6,"tv":10.0,"id":13011471},{"batb":[[1,3.6,14.4],[2,3.45,16.8]],"ltp":0.0,"tv":0.0,"id":16665614},{"batb":[[1,6,40.87],[2,5.6,10.39]],"ltp":9.0,"tv":20.88,"id":13011472},{"batb":[[0,2.1,25.65],[1,2.06,39.49],[2,1.97,15.5]],"ltp":1.63,"tv":164.27,"id":16665613}]}]}
{"op":"mcm","clk":"1009181956","pt":1580642565712,"mc":[{"id":"1.168224333","rc":[{"batb":[[1,7.2,18.13],[2,1.01,0.51]],"batl":[[0,8.8,5.04]],"ltp":7.6,"tv":10.0,"id":13011471},{"batb":[[0,3.6,14.4],[1,3.45,16.8],[2,1.01,0.51]],"batl":[[1,4.3,23.76],[2,4.3,0]],"ltp":0.0,"tv":0.0,"id":16665614},{"batb":[[1,6,22.85]],"batl":[[0,8,19.26],[1,8,0]],"ltp":9.0,"tv":20.88,"id":13011472},{"batb":[[0,2.06,39.49],[1,1.97,15.5],[2,1.01,0.51]],"batl":[[0,2.26,32.77],[1,2.32,22.19],[2,2.32,0]],"ltp":1.63,"tv":164.27,"id":16665613}]}]}
{"op":"mcm","clk":"1009182101","pt":1580642566613,"mc":[{"id":"1.168224333","rc":[{"batb":[[1,7.2,11.41]],"batl":[[0,9.2,9.52],[1,9.2,0]],"ltp":7.6,"tv":10.0,"id":13011471},{"batb":[[1,1.01,0.51],[2,1.01,0]],"batl":[[0,4.3,23.76],[1,4.3,0]],"ltp":0.0,"tv":0.0,"id":16665614},{"batb":[[0,6,22.85],[1,5.6,10.39],[2,1.01,0.51]],"batl":[[0,8,13.38]],"ltp":9.0,"tv":20.88,"id":13011472},{"batb":[[0,1.97,15.5],[1,1.01,0.51],[2,1.01,0]],"batl":[[0,2.32,22.19],[1,2.32,0]],"ltp":1.63,"tv":164.27,"id":16665613}]}]}
{"op":"mcm","clk":"1009182339","pt":1580642568173,"mc":[{"id":"1.168224333","rc":[{"batb":[[1,7.8,24.66],[2,7.2,11.41]],"ltp":7.6,"tv":10.0,"id":13011471},{"batb":[[1,3.5,61.84],[2,3.45,38.27]],"ltp":0.0,"tv":0.0,"id":16665614},{"batb":[[1,5.9,23.01],[2,5.6,10.39]],"ltp":9.0,"tv":20.88,"id":13011472},{"batb":[[0,1.99,62.93],[1,1.97,85.36],[2,1.01,0.51]],"ltp":1.63,"tv":164.27,"id":16665613}]}]}
{"op":"mcm","clk":"1009182894","pt":1580642572012,"mc":[{"id":"1.168224333","rc":[{"batb":[[0,7.2,11.41],[1,1.01,0.51],[2,7.2,0]],"ltp":7.6,"tv":10.0,"id":13011471},{"batb":[[1,1.01,0.51],[2,3.45,0]],"ltp":0.0,"tv":0.0,"id":16665614},{"batb":[[0,5.6,10.39],[1,1.01,0.51],[2,5.6,0]],"ltp":9.0,"tv":20.88,"id":13011472}]}]}
{"op":"mcm","clk":"1009183326","pt":1580642575007,"mc":[{"id":"1.168224333","rc":[{"batb":[[0,8.4,30.65],[1,8.2,21.87],[2,7.2,11.41]],"ltp":7.6,"tv":10.0,"id":13011471},{"batb":[[0,3.75,27.07],[1,3.7,32.56],[2,3.6,14.4]],"ltp":0.0,"tv":0.0,"id":16665614},{"batb":[[0,7,23.79],[1,6.8,33.17],[2,5.6,10.39]],"ltp":9.0,"tv":20.88,"id":13011472}]}]}
{"op":"mcm","clk":"1009183491","pt":1580642576016,"mc":[{"id":"1.168224333","rc":[{"batb":[[2,7.6,9.99]],"batl":[[0,9.2,14.56],[1,9.8,8.26]],"ltp":7.6,"tv":10.0,"id":13011471},{"batb":[[0,3.85,25.1],[1,3.75,27.07],[2,3.7,32.56]],"batl":[[0,4,13.44],[1,4.3,23.76],[2,4.7,19.36]],"ltp":0.0,"tv":0.0,"id":16665614},{"batb":[[0,7,30.51],[2,6.6,14.24]],"batl":[[1,8.6,5.04],[2,10,8.42]],"ltp":9.0,"tv":20.88,"id":13011472},{"batb":[[0,1.99,104.94],[2,1.78,21.4]],"batl":[[0,2.08,30.06],[1,2.16,36.13],[2,2.24,24.23]],"ltp":1.63,"tv":164.27,"id":16665613}]}]}
{"op":"mcm","clk":"1009185885","pt":1580642592331,"mc":[{"id":"1.168224333","rc":[{"batb":[[0,8.2,12.64],[1,7.6,9.99],[2,7.4,16.82]],"ltp":7.6,"tv":10.0,"id":13011471},{"batb":[[1,3.65,14.16],[2,3.55,15.96]],"ltp":0.0,"tv":0.0,"id":16665614},{"batb":[[0,7,6.72],[1,6.6,14.24],[2,5.9,18.25]],"ltp":9.0,"tv":20.88,"id":13011472},{"batb":[[0,1.99,42.01],[1,1.97,15.5]],"ltp":1.63,"tv":164.27,"id":16665613}]}]}
{"op":"mcm","clk":"1009185939","pt":1580642592601,"mc":[{"id":"1.168224333","rc":[{"batb":[[1,7.4,10.94],[2,1.01,0.51]],"batl":[[0,9.8,8.26],[1,9.8,0]],"ltp":7.6,"tv":10.0,"id":13011471},{"batb":[[0,3.65,14.16],[1,1.01,0.51],[2,3.55,0]],"batl":[[0,4.7,19.36],[1,4.3,0],[2,4.7,0]],"ltp":0.0,"tv":0.0,"id":16665614},{"batb":[[0,5.9,18.25],[1,1.01,0.51],[2,5.9,0]],"batl":[[0,10,8.42],[1,8.6,0],[2,10,0]],"ltp":9.0,"tv":20.88,"id":13011472},{"batb":[[0,1.78,21.4],[1,1.01,0.51],[2,1.78,0]],"batl":[[0,2.24,24.23],[1,2.16,0],[2,2.24,0]],"ltp":1.63,"tv":164.27,"id":16665613}]}]}
{"op":"mcm","clk":"1009186293","pt":1580642595109,"mc":[{"id":"1.168224333","rc":[{"batb":[[1,8,23.49],[2,7.4,10.94]],"ltp":7.6,"tv":10.0,"id":13011471},{"batb":[[1,3.55,33.3],[2,3.5,37.21]],"ltp":0.0,"tv":0.0,"id":16665614},{"batb":[[0,6.2,26.01],[1,6,43.54],[2,5.9,18.25]],"ltp":9.0,"tv":20.88,"id":13011472},{"batb":[[0,1.79,93.79],[1,1.78,21.4],[2,1.77,98.49]],"ltp":1.63,"tv":164.27,"id":16665613}]}]}
{"op":"mcm","clk":"1009186596","pt":1580642597307,"mc":[{"id":"1.168224333","rc":[{"batb":[[0,7.4,10.94],[1,1.01,0.51],[2,7.4,0]],"ltp":7.6,"tv":10.0,"id":13011471},{"batb":[[1,1.01,0.51],[2,3.5,0]],"ltp":0.0,"tv":0.0,"id":16665614},{"batb":[[0,5.9,18.25],[1,1.01,0.51],[2,5.9,0]],"ltp":9.0,"tv":20.88,"id":13011472}]}]}
{"op":"mcm","clk":"1009187051","pt":1580642600329,"mc":[{"id":"1.168224333","rc":[{"batb":[[0,9,28.23],[1,8.8,18.82],[2,7.4,10.94]],"ltp":7.6,"tv":10.0,"id":13011471},{"batb":[[0,4,66.31],[1,3.95,27.51],[2,3.65,14.16]],"ltp":0.0,"tv":0.0,"id":16665614},{"batb":[[0,8.6,24.75],[1,8.4,21.02],[2,5.9,18.25]],"ltp":9.0,"tv":20.88,"id":13011472}]}]}
{"op":"mcm","clk":"1009187148","pt":1580642601146,"mc":[{"id":"1.168224333","rc":[{"batb":[[2,8.2,8.66]],"batl":[[1,11,7]],"ltp":7.6,"tv":10.0,"id":13011471},{"batb":[[0,4.2,20.38],[1,4,66.31],[2,3.95,27.51]],"batl":[[1,5.4,14.32]],"ltp":0.0,"tv":0.0,"id":16665614},{"batb":[[2,8,8.89]],"batl":[[1,15.5,9.21]],"ltp":9.0,"tv":20.88,"id":13011472},{"batl":[[0,1.86,21.01],[1,2.04,15.66]],"ltp":1.63,"tv":164.27,"id":16665613}]}]}
{"op":"mcm","clk":"1009187316","pt":1580642602312,"mc":[{"id":"1.168224333","rc":[{"batl":[[0,9.8,12.46]],"ltp":7.6,"tv":10.0,"id":13011471},{"batl":[[0,4.4,11.76],[1,4.7,19.36],[2,5.4,14.32]],"ltp":0.0,"tv":0.0,"id":16665614},{"batb":[[1,8.4,26.06]],"batl":[[1,10.5,4.2],[2,15.5,9.21]],"ltp":9.0,"tv":20.88,"id":13011472},{"batb":[[0,1.8,52.09],[1,1.79,93.79],[2,1.78,21.4]],"batl":[[1,1.96,42.01],[2,2.04,15.66]],"ltp":1.63,"tv":164.27,"id":16665613}]}]}
{"op":"mcm","clk":"1009189881","pt":1580642619892,"mc":[{"id":"1.168224333","rc":[{"batb":[[0,7.8,5.88],[1,7.6,9.84],[2,1.01,0.51]],"batl":[[0,9.8,4.2]],"ltp":7.6,"tv":10.0,"id":13011471},{"batb":[[0,3.85,24.86],[1,3.8,14.28],[2,1.01,0.51]],"batl":[[1,5.4,14.32],[2,5.4,0]],"ltp":0.0,"tv":0.0,"id":16665614},{"batb":[[0,8.4,5.04],[1,6.8,13.38],[2,1.01,0.51]],"batl":[[0,10.5,4.2],[1,15.5,9.21],[2,15.5,0]],"ltp":9.0,"tv":20.88,"id":13011472},{"batb":[[1,1.57,32.81],[2,1.01,0.51]],"batl":[[0,1.96,42.01],[1,2.04,15.66],[2,2.04,0]],"ltp":1.63,"tv":164.27,"id":16665613}]}]}
{"op":"mcm","clk":"1009190006","pt":1580642620646,"mc":[{"id":"1.168224333","rc":[{"batb":[[0,7.6,9.84],[1,1.01,0.51],[2,1.01,0]],"batl":[[0,11,7],[1,11,0]],"ltp":7.6,"tv":10.0,"id":13011471},{"batb":[[1,1.01,0.51],[2,1.01,0]],"batl":[[0,5.4,14.32],[1,5.4,0]],"ltp":0.0,"tv":0.0,"id":16665614},{"batb":[[0,6.8,13.38],[1,1.01,0.51],[2,1.01,0]],"batl":[[0,15.5,9.21],[1,15.5,0]],"ltp":9.0,"tv":20.88,"id":13011472},{"batb":[[0,1.57,32.81],[1,1.01,0.51],[2,1.01,0]],"batl":[[0,2.04,15.66],[1,2.04,0]],"ltp":1.63,"tv":164.27,"id":16665613}]}]}
{"op":"mcm","clk":"1009190246","pt":1580642622365,"mc":[{"id":"1.168224333","rc":[{"batb":[[0,8.6,14.71],[1,8.4,21.1],[2,7.6,9.84]],"ltp":7.6,"tv":10.0,"id":13011471},{"batb":[[1,3.75,32.38],[2,3.7,32.52]],"ltp":0.0,"tv":0.0,"id":16665614},{"batb":[[0,7,36.51],[1,6.8,46.24],[2,1.01,0.51]],"ltp":9.0,"tv":20.88,"id":13011472},{"batb":[[0,1.59,75.27],[1,1.58,74.04],[2,1.57,32.81]],"ltp":1.63,"tv":164.27,"id":16665613}]}]}
{"op":"mcm","clk":"1009190395","pt":1580642623371,"mc":[{"id":"1.168224333","rc":[{"batb":[[0,7.6,9.84],[1,1.01,0.51],[2,7.6,0]],"ltp":7.6,"tv":10.0,"id":13011471},{"batb":[[1,1.01,0.51],[2,3.7,0]],"ltp":0.0,"tv":0.0,"id":16665614},{"batb":[[0,6.8,13.38],[1,1.01,0.51],[2,1.01,0]],"ltp":9.0,"tv":20.88,"id":13011472},{"batb":[[0,1.57,32.81],[1,1.01,0.51],[2,1.57,0]],"ltp":1.63,"tv":164.27,"id":16665613}]}]}
{"op":"mcm","clk":"1009190818","pt":1580642626372,"mc":[{"id":"1.168224333","rc":[{"batb":[[0,9.2,24.54],[1,9,18],[2,7.6,9.84]],"ltp":7.6,"tv":10.0,"id":13011471},{"batb":[[0,4.1,62.98],[1,4,52.75],[2,3.85,24.86]],"ltp":0.0,"tv":0.0,"id":16665614},{"batb":[[0,9.2,20.63],[1,9,18.22],[2,6.8,13.38]],"ltp":9.0,"tv":20.88,"id":13011472},{"batb":[[0,1.75,69.12],[1,1.73,106.33],[2,1.57,32.81]],"ltp":1.63,"tv":164.27,"id":16665613}]}]}
{"op":"mcm","clk":"1009190943","pt":1580642627275,"mc":[{"id":"1.168224333","rc":[{"batb":[[0,7.6,9.84],[1,1.01,0.51],[2,7.6,0]],"ltp":7.6,"tv":10.0,"id":13011471},{"batb":[[0,3.85,24.86],[1,1.01,0.51],[2,3.85,0]],"ltp":0.0,"tv":0.0,"id":16665614},{"batb":[[0,6.8,13.38],[1,1.01,0.51],[2,6.8,0]],"ltp":9.0,"tv":20.88,"id":13011472},{"batb":[[0,1.57,32.81],[1,1.01,0.51],[2,1.57,0]],"ltp":1.63,"tv":164.27,"id":16665613}]}]}
{"op":"mcm","clk":"1009191360","pt":1580642630184,"mc":[{"id":"1.168224333","rc":[{"batb":[[0,8.6,14.71],[1,8.4,21.1],[2,7.6,9.84]],"ltp":7.6,"tv":10.0,"id":13011471},{"batb":[[1,3.75,32.38],[2,3.7,32.52]],"ltp":0.0,"tv":0.0,"id":16665614},{"batb":[[0,7,36.51],[1,6.8,46.24],[2,1.01,0.51]],"ltp":9.0,"tv":20.88,"id":13011472},{"batb":[[0,1.59,75.27],[1,1.58,74.04],[2,1.57,32.81]],"ltp":1.63,"tv":164.27,"id":16665613}]}]}
{"op":"mcm","clk":"1009191642","pt":1580642632184,"mc":[{"id":"1.168224333","rc":[{"batb":[[0,7.6,9.84],[1,1.01,0.51],[2,7.6,0]],"ltp":7.6,"tv":10.0,"id":13011471},{"batb":[[1,1.01,0.51],[2,3.7,0]],"ltp":0.0,"tv":0.0,"id":16665614},{"batb":[[0,6.8,13.38],[1,1.01,0.51],[2,1.01,0]],"ltp":9.0,"tv":20.88,"id":13011472}]}]}
{"op":"mcm","clk":"1009192137","pt":1580642635262,"mc":[{"id":"1.168224333","rc":[{"batb":[[0,10,16.95],[1,9.8,15.13],[2,7.6,9.84]],"ltp":7.6,"tv":10.0,"id":13011471},{"batb":[[0,4.6,31.84],[1,4.5,40.49],[2,3.85,24.86]],"ltp":0.0,"tv":0.0,"id":16665614},{"batb":[[0,12.5,16.63],[1,12,24.29],[2,6.8,13.38]],"ltp":9.0,"tv":20.88,"id":13011472}]}]}
{"op":"mcm","clk":"1009192266","pt":1580642636272,"mc":[{"id":"1.168224333","rc":[{"batb":[[2,8.8,7.32]],"batl":[[0,10.5,4.2],[1,11,7],[2,12.5,13.22]],"ltp":7.6,"tv":10.0,"id":13011471},{"batb":[[0,4.8,14.95],[1,4.6,31.84],[2,4.5,40.49]],"batl":[[0,5,10.08],[1,5.4,14.32],[2,7,16.29]],"ltp":0.0,"tv":0.0,"id":16665614},{"batb":[[2,11.5,13.35]],"ltp":9.0,"tv":20.88,"id":13011472},{"batb":[[0,1.61,68.06],[1,1.59,75.27],[2,1.58,74.04]],"batl":[[0,1.64,32.1],[1,1.73,42.01],[2,1.84,21.56]],"ltp":1.63,"tv":164.27,"id":16665613}]}]}
{"op":"mcm","clk":"1009194296","pt":1580642650098,"mc":[{"id":"1.168224333","rc":[{"batb":[[0,8.4,5.04],[1,8.2,8.34],[2,1.01,0.51]],"batl":[[1,12.5,13.22],[2,12.5,0]],"ltp":7.6,"tv":10.0,"id":13011471},{"batb":[[0,4.3,12.6],[1,4.2,20.22],[2,1.01,0.51]],"batl":[[1,7,16.29],[2,7,0]],"ltp":0.0,"tv":0.0,"id":16665614},{"batb":[[0,11.5,3.36],[1,8.2,8.58],[2,1.01,0.51]],"ltp":9.0,"tv":20.88,"id":13011472},{"batb":[[1,1.35,61.61],[2,1.01,0.51]],"batl":[[0,1.73,42.01],[1,1.84,21.56],[2,1.84,0]],"ltp":1.63,"tv":164.27,"id":16665613}]}]}
{"op":"mcm","clk":"1009194410","pt":1580642651037,"mc":[{"id":"1.168224333","rc":[{"batb":[[0,8.2,8.34],[1,1.01,0.51],[2,1.01,0]],"batl":[[0,12.5,13.22],[1,12.5,0]],"ltp":7.6,"tv":10.0,"id":13011471},{"batb":[[0,4.2,20.22],[1,1.01,0.51],[2,1.01,0]],"batl":[[0,7,16.29],[1,7,0]],"ltp":0.0,"tv":0.0,"id":16665614},{"batb":[[0,8.2,8.58],[1,1.01,0.51],[2,1.01,0]],"ltp":9.0,"tv":20.88,"id":13011472},{"batb":[[0,1.35,61.61],[1,1.01,0.51],[2,1.01,0]],"batl":[[0,1.84,21.56],[1,1.84,0]],"ltp":1.63,"tv":164.27,"id":16665613}]}]}
{"op":"mcm","clk":"1009194699","pt":1580642652914,"mc":[{"id":"1.168224333","rc":[{"batb":[[0,9.2,14.83],[1,9,18.2],[2,8.2,8.34]],"ltp":7.6,"tv":10.0,"id":13011471},{"batb":[[1,4,72.62],[2,3.95,27.45]],"ltp":0.0,"tv":0.0,"id":16665614},{"batb":[[0,8.8,14.06],[1,8.6,20.21],[2,8.2,8.58]],"ltp":9.0,"tv":20.88,"id":13011472},{"batb":[[0,1.38,125.12],[1,1.37,134.99],[2,1.35,61.61]],"ltp":1.63,"tv":164.27,"id":16665613}]}]}
{"op":"mcm","clk":"1009194908","pt":1580642654203,"mc":[{"id":"1.168224333","rc":[{"batb":[[0,8.2,8.34],[1,1.01,0.51],[2,8.2,0]],"ltp":7.6,"tv":10.0,"id":13011471},{"batb":[[1,1.01,0.51],[2,3.95,0]],"ltp":0.0,"tv":0.0,"id":16665614},{"batb":[[0,8.2,8.58],[1,1.01,0.51],[2,8.2,0]],"ltp":9.0,"tv":20.88,"id":13011472}]}]}
{"op":"mcm","clk":"1009195372","pt":1580642657314,"mc":[{"id":"1.168224333","rc":[{"batb":[[0,11.5,10.42],[1,11,29.02],[2,8.2,8.34]],"ltp":7.6,"tv":10.0,"id":13011471},{"batb":[[0,5.6,28.58],[1,5.5,25.65],[2,4.2,20.22]],"ltp":0.0,"tv":0.0,"id":16665614},{"batb":[[0,30,15.09],[1,29,7.66],[2,8.2,8.58]],"ltp":9.0,"tv":20.88,"id":13011472}]}]}
{"op":"mcm","clk":"1009195488","pt":1580642658012,"mc":[{"id":"1.168224333","rc":[{"batb":[[2,9.8,4.2]],"batl":[[0,12.5,16.58],[1,13,12.27]],"ltp":7.6,"tv":10.0,"id":13011471},{"batb":[[0,6,17.47],[1,5.6,28.58],[2,5.5,36.43]],"batl":[[0,6.2,7.56],[1,7,16.29],[2,7.4,14.79]],"ltp":0.0,"tv":0.0,"id":16665614},{"batb":[[2,26,3.64]],"ltp":9.0,"tv":20.88,"id":13011472},{"batb":[[0,1.38,235.19]],"batl":[[0,1.4,59.56],[1,1.46,42.01],[2,1.49,46.42]],"ltp":1.63,"tv":164.27,"id":16665613}]}]}
{"op":"mcm","clk":"1009197882","pt":1580642674120,"mc":[{"id":"1.168224333","rc":[{"batb":[[1,29,6.23]],"ltp":9.0,"tv":20.88,"id":13011472}]}]}
{"op":"mcm","clk":"1009198296","pt":1580642677219,"mc":[{"id":"1.168224333","rc":[{"batb":[[0,11.5,14.18]],"ltp":7.6,"tv":10.0,"id":13011471}]}]}
{"op":"mcm","clk":"1009203353","pt":1580642713073,"mc":[{"id":"1.168224333","rc":[{"batb":[[0,11,29.02],[1,9.8,4.2],[2,9.6,14.56]],"ltp":7.6,"tv":10.0,"id":13011471}]}]}
{"op":"mcm","clk":"1009203793","pt":1580642716395,"mc":[{"id":"1.168224333","rc":[{"batb":[[0,11,38.01],[1,10.5,24.49],[2,9.8,4.2]],"ltp":7.6,"tv":10.0,"id":13011471},{"batb":[[0,6,17.31]],"batl":[[1,7.2,16.21]],"ltp":0.0,"tv":0.0,"id":16665614},{"batb":[[2,1.36,60.66]],"batl":[[0,1.41,58.7],[2,1.49,45.71]],"ltp":1.63,"tv":164.27,"id":16665613}]}]}
{"op":"mcm","clk":"1009207215","pt":1580642740244,"mc":[{"id":"1.168224333","rc":[{"batb":[[0,10.5,24.49],[1,9.8,4.2],[2,9.4,15.26]],"ltp":7.6,"tv":10.0,"id":13011471},{"batb":[[1,5.5,10.78],[2,5.2,9.24]],"ltp":0.0,"tv":0.0,"id":16665614},{"batb":[[0,26,3.64],[1,17.5,7.08],[2,1.01,0.51]],"ltp":9.0,"tv":20.88,"id":13011472},{"batb":[[0,1.38,110.07],[1,1.36,60.66],[2,1.32,68.45]],"ltp":1.63,"tv":164.27,"id":16665613}]}]}
{"op":"mcm","clk":"1009207278","pt":1580642740604,"mc":[{"id":"1.168224333","rc":[{"batb":[[1,8.8,7.08],[2,1.01,0.51]],"batl":[[0,13,12.27],[1,13,0]],"ltp":7.6,"tv":10.0,"id":13011471},{"batb":[[0,5.5,10.78],[1,1.01,0.51],[2,5.2,0]],"batl":[[0,7.4,14.79],[1,7.2,0],[2,7.4,0]],"ltp":0.0,"tv":0.0,"id":16665614},{"batb":[[0,17.5,7.08],[1,1.01,0.51],[2,1.01,0]],"ltp":9.0,"tv":20.88,"id":13011472},{"batb":[[0,1.32,68.45],[1,1.01,0.51],[2,1.32,0]],"batl":[[0,1.49,45.71],[1,1.46,0],[2,1.49,0]],"ltp":1.63,"tv":164.27,"id":16665613}]}]}
{"op":"mcm","clk":"1009207655","pt":1580642743322,"mc":[{"id":"1.168224333","rc":[{"batb":[[1,10,34.76],[2,8.8,7.08]],"ltp":7.6,"tv":10.0,"id":13011471},{"batb":[[1,5.2,20.23],[2,5.1,30.59]],"ltp":0.0,"tv":0.0,"id":16665614},{"batb":[[0,20,11.61],[1,19.5,8.97],[2,17.5,7.08]],"ltp":9.0,"tv":20.88,"id":13011472},{"batb":[[0,1.35,90.26],[1,1.34,149.87],[2,1.32,68.45]],"ltp":1.63,"tv":164.27,"id":16665613}]}]}
{"op":"mcm","clk":"1009207708","pt":1580642743731,"mc":[{"id":"1.168224333","rc":[{"batb":[[0,8.8,7.08],[1,1.01,0.51],[2,8.8,0]],"ltp":7.6,"tv":10.0,"id":13011471},{"batb":[[1,1.01,0.51],[2,5.1,0]],"ltp":0.0,"tv":0.0,"id":16665614},{"batb":[[0,17.5,7.08],[1,1.01,0.51],[2,17.5,0]],"ltp":9.0,"tv":20.88,"id":13011472}]}]}
{"op":"mcm","clk":"1009208208","pt":1580642747089,"mc":[{"id":"1.168224333","rc":[{"batb":[[0,11.5,26.62],[1,9.8,14.08],[2,9,16.84]],"batl":[[1,13.5,12.04]],"ltp":7.6,"tv":10.0,"id":13011471},{"batb":[[0,6.2,15.66],[1,5.8,56.42],[2,5.7,23.55]],"batl":[[1,7.8,13.69]],"ltp":0.0,"tv":0.0,"id":16665614},{"batb":[[0,42,5.59],[1,40,6.59],[2,23,3.15]],"ltp":9.0,"tv":20.88,"id":13011472},{"batb":[[0,1.34,149.87],[1,1.32,68.45],[2,1.3,74.75]],"batl":[[0,1.37,66.01],[1,1.44,53.19],[2,1.49,45.71]],"ltp":1.63,"tv":164.27,"id":16665613}]}]}
{"op":"mcm","clk":"1009208331","pt":1580642747939,"mc":[{"id":"1.168224333","rc":[{"batb":[[1,10,4.2],[2,9.8,14.08]],"batl":[[0,13,15.64]],"ltp":7.6,"tv":10.0,"id":13011471},{"batl":[[0,6.4,7.56],[1,7.4,14.79],[2,7.8,13.69]],"ltp":0.0,"tv":0.0,"id":16665614},{"batb":[[0,1.35,119.31],[1,1.34,149.87],[2,1.32,68.45]],"batl":[[1,1.42,42.01],[2,1.44,53.19]],"ltp":1.63,"tv":164.27,"id":16665613}]}]}
{"op":"mcm","clk":"1009208545","pt":1580642749557,"mc":[{"id":"1.168224333","rc":[{"batb":[[0,12,19.83],[1,11.5,26.62],[2,10,4.2]],"ltp":7.6,"tv":10.0,"id":13011471},{"batb":[[0,42,9.79]],"ltp":9.0,"tv":20.88,"id":13011472},{"batb":[[1,1.34,187.71],[2,1.33,157.69]],"ltp":1.63,"tv":164.27,"id":16665613}]}]}
{"op":"mcm","clk":"1009208994","pt":1580642752245,"mc":[{"id":"1.168224333","rc":[{"trd":[[1.37,68.9]],"batl":[[0,1.37,31.56]],"ltp":1.37,"tv":233.17,"id":16665613}],"tv":264.06}]}
{"op":"mcm","clk":"1009209299","pt":1580642754320,"mc":[{"id":"1.168224333","rc":[{"batb":[[0,10,4.2],[1,9.8,14.08],[2,9,16.84]],"ltp":7.6,"tv":10.0,"id":13011471},{"batb":[[1,5.8,19.12],[2,5.4,9.24]],"ltp":0.0,"tv":0.0,"id":16665614},{"batb":[[0,23,3.15],[1,1.01,0.51],[2,23,0]],"ltp":9.0,"tv":20.88,"id":13011472},{"batb":[[1,1.32,68.45],[2,1.3,74.75]],"ltp":1.37,"tv":233.17,"id":16665613}]}]}
{"op":"mcm","clk":"1009209363","pt":1580642754749,"mc":[{"id":"1.168224333","rc":[{"batb":[[0,9,16.84],[1,1.01,0.51],[2,9,0]],"batl":[[0,13.5,12.04],[1,13.5,0]],"ltp":7.6,"tv":10.0,"id":13011471},{"batb":[[0,5.8,19.12],[1,1.01,0.51],[2,5.4,0]],"batl":[[0,7.8,13.69],[1,7.4,0],[2,7.8,0]],"ltp":0.0,"tv":0.0,"id":16665614},{"batb":[[0,1.3,74.75],[1,1.01,0.51],[2,1.3,0]],"batl":[[0,1.44,53.19],[1,1.42,0],[2,1.44,0]],"ltp":1.37,"tv":233.17,"id":16665613}]}]}
{"op":"mcm","clk":"1009209746","pt":1580642757330,"mc":[{"id":"1.168224333","rc":[{"batb":[[0,11,35.95],[1,10.5,26.65],[2,9,16.84]],"ltp":7.6,"tv":10.0,"id":13011471},{"batb":[[1,5.7,19.59],[2,5.4,41.24]],"batl":[[0,7.6,14.01],[1,7.8,13.69]],"ltp":0.0,"tv":0.0,"id":16665614},{"batb":[[0,28,8.91],[1,27,9.31],[2,23,3.15]],"ltp":9.0,"tv":20.88,"id":13011472},{"batb":[[0,1.39,13.51],[1,1.32,134.41],[2,1.31,242.86]],"batl":[[1,1.45,52.17]],"ltp":1.37,"tv":233.17,"id":16665613}]}]}
{"op":"mcm","clk":"1009209863","pt":1580642758139,"mc":[{"id":"1.168224333","rc":[{"batb":[[0,9,6.85],[1,1.01,0.51],[2,9,0]],"ltp":7.6,"tv":10.0,"id":13011471},{"batb":[[0,5.7,19.59],[1,1.01,0.51],[2,5.4,0]],"batl":[[1,7.8,0]],"ltp":0.0,"tv":0.0,"id":16665614},{"batb":[[0,23,3.15],[1,1.01,0.51],[2,23,0]],"ltp":9.0,"tv":20.88,"id":13011472},{"batb":[[1,1.31,73.25],[2,1.01,0.51]],"batl":[[0,1.45,52.17],[1,1.45,0]],"ltp":1.37,"tv":233.17,"id":16665613}]}]}
{"op":"mcm","clk":"1009210131","pt":1580642759911,"mc":[{"id":"1.168224333","rc":[{"batb":[[0,12,11.65],[1,11.5,26.95],[2,9,6.85]],"ltp":7.6,"tv":10.0,"id":13011471},{"batb":[[0,5.7,58.42],[1,5.6,24.43],[2,1.01,0.51]],"ltp":0.0,"tv":0.0,"id":16665614},{"batb":[[0,38,10.6],[1,36,7.56],[2,23,3.15]],"ltp":9.0,"tv":20.88,"id":13011472},{"batb":[[1,1.35,187.45],[2,1.34,151.87]],"ltp":1.37,"tv":233.17,"id":16665613}]}]}
{"op":"mcm","clk":"1009210433","pt":1580642762164,"mc":[{"id":"1.168224333","rc":[{"batb":[[0,9,6.85],[1,1.01,0.51],[2,9,0]],"ltp":7.6,"tv":10.0,"id":13011471},{"batb":[[0,5.7,19.59],[1,1.01,0.51],[2,1.01,0]],"ltp":0.0,"tv":0.0,"id":16665614},{"batb":[[0,23,3.15],[1,1.01,0.51],[2,23,0]],"ltp":9.0,"tv":20.88,"id":13011472},{"batb":[[1,1.31,73.25],[2,1.01,0.51]],"ltp":1.37,"tv":233.17,"id":16665613}]}]}
{"op":"mcm","clk":"1009210817","pt":1580642765061,"mc":[{"id":"1.168224333","rc":[{"batb":[[0,11,35.42],[1,10.5,27.2],[2,9,6.85]],"ltp":7.6,"tv":10.0,"id":13011471},{"batb":[[1,5.4,41.4],[2,5.3,27.64]],"ltp":0.0,"tv":0.0,"id":16665614},{"batb":[[0,28,8.71],[1,27,9.31],[2,23,3.15]],"ltp":9.0,"tv":20.88,"id":13011472},{"batb":[[1,1.32,136.04],[2,1.31,242.87]],"ltp":1.37,"tv":233.17,"id":16665613}]}]}
{"op":"mcm","clk":"1009210989","pt":1580642766133,"mc":[{"id":"1.168224333","rc":[{"batb":[[0,1.32,136.04],[1,1.31,242.87],[2,1.01,0.51]],"ltp":1.37,"tv":233.17,"id":16665613}]}]}
{"op":"mcm","clk":"1009212530","pt":1580642776751,"mc":[{"id":"1.168224333","rc":[{"batb":[[0,1.31,73.25],[1,1.01,0.51],[2,1.01,0]],"ltp":1.37,"tv":233.17,"id":16665613}]}]}
{"op":"mcm","clk":"1009213097","pt":1580642780244,"mc":[{"id":"1.168224333","rc":[{"batl":[[0,11.5,15.5],[1,12,14.16]],"ltp":7.6,"tv":10.0,"id":13011471},{"batl":[[0,6.6,18.25],[1,7,16.21],[2,7.6,14.01]],"ltp":0.0,"tv":0.0,"id":16665614},{"batb":[[0,1.4,85.31],[1,1.39,180.18],[2,1.35,62.71]],"batl":[[1,1.56,38.55]],"ltp":1.37,"tv":233.17,"id":16665613}]}]}
{"op":"mcm","clk":"1009213134","pt":1580642780462,"mc":[{"id":"1.168224333","rc":[{"batl":[[2,7.6,0]],"ltp":0.0,"tv":0.0,"id":16665614}]}]}
{"op":"mcm","clk":"1009213414","pt":1580642782375,"mc":[{"id":"1.168224333","rc":[{"batb":[[2,9.8,4.2]],"batl":[[2,12.5,3.36]],"ltp":7.6,"tv":10.0,"id":13011471},{"batl":[[0,6,8.4],[1,6.6,18.25],[2,7,16.21]],"ltp":0.0,"tv":0.0,"id":16665614},{"batb":[[0,1.4,190.33]],"batl":[[1,1.48,42.01],[2,1.56,38.55]],"ltp":1.37,"tv":233.17,"id":16665613}]}]}
{"op":"mcm","clk":"1009215633","pt":1580642797169,"mc":[{"id":"1.168224333","rc":[{"batb":[[0,10.5,14.01],[1,9.8,4.2],[2,8.6,7.79]],"batl":[[0,12,14.16],[1,12.5,3.36],[2,12.5,0]],"ltp":7.6,"tv":10.0,"id":13011471},{"batb":[[0,5.2,12.35],[1,5.1,10.08],[2,1.01,0.51]],"batl":[[1,7,16.21],[2,7,0]],"ltp":0.0,"tv":0.0,"id":16665614},{"batb":[[0,15,5.43],[1,1.01,0.51],[2,23,0]],"ltp":9.0,"tv":20.88,"id":13011472},{"batb":[[0,1.4,105.02],[1,1.35,62.71],[2,1.01,0.51]],"batl":[[0,1.48,42.01],[1,1.56,38.55],[2,1.56,0]],"ltp":1.37,"tv":233.17,"id":16665613}]}]}
{"op":"mcm","clk":"1009215923","pt":1580642798606,"mc":[{"id":"1.168224333","rc":[{"batb":[[1,8.6,7.79],[2,1.01,0.51]],"batl":[[1,12.5,0]],"ltp":7.6,"tv":10.0,"id":13011471},{"batb":[[1,1.01,0.51],[2,1.01,0]],"batl":[[0,7,16.21],[1,7,0]],"ltp":0.0,"tv":0.0,"id":16665614},{"batb":[[0,1.35,62.71],[1,1.01,0.51],[2,1.01,0]],"batl":[[0,1.56,38.55],[1,1.56,0]],"ltp":1.37,"tv":233.17,"id":16665613}]}]}
{"op":"mcm","clk":"1009216467","pt":1580642802233,"mc":[{"id":"1.168224333","rc":[{"batb":[[0,11,24.61],[1,10.5,32.02],[2,8.6,7.79]],"ltp":7.6,"tv":10.0,"id":13011471},{"batb":[[0,5.3,39.58],[1,5.2,41.25],[2,1.01,0.51]],"ltp":0.0,"tv":0.0,"id":16665614},{"batb":[[0,25,8.13],[1,24,11.86],[2,15,5.43]],"ltp":9.0,"tv":20.88,"id":13011472},{"batb":[[0,1.41,182.71],[1,1.4,123.29],[2,1.35,62.71]],"ltp":1.37,"tv":233.17,"id":16665613}]}]}
{"op":"mcm","clk":"1009217253","pt":1580642807213,"mc":[{"id":"1.168224333","rc":[{"batb":[[0,10.5,14.01],[1,8.6,7.79],[2,1.01,0.51]],"ltp":7.6,"tv":10.0,"id":13011471},{"batb":[[0,5.2,12.35],[1,1.01,0.51],[2,1.01,0]],"ltp":0.0,"tv":0.0,"id":16665614},{"batb":[[0,15,5.43],[1,1.01,0.51],[2,15,0]],"ltp":9.0,"tv":20.88,"id":13011472},{"batb":[[0,1.35,62.71],[1,1.01,0.51],[2,1.35,0]],"ltp":1.37,"tv":233.17,"id":16665613}]}]}
{"op":"mcm","clk":"1009217806","pt":1580642810347,"mc":[{"id":"1.168224333","rc":[{"batb":[[1,10,36],[2,8.6,7.79]],"ltp":7.6,"tv":10.0,"id":13011471},{"batb":[[1,4.9,43.65],[2,4.8,34.67]],"ltp":0.0,"tv":0.0,"id":16665614},{"batb":[[0,17,17.86],[1,16.5,12.78],[2,15,5.43]],"ltp":9.0,"tv":20.88,"id":13011472},{"batb":[[0,1.35,251.87],[1,1.34,151.84],[2,1.01,0.51]],"ltp":1.37,"tv":233.17,"id":16665613}]}]}
{"op":"mcm","clk":"1009219137","pt":1580642818257,"mc":[{"id":"1.168224333","rc":[{"batb":[[0,8.6,7.79],[1,1.01,0.51],[2,8.6,0]],"ltp":7.6,"tv":10.0,"id":13011471},{"batb":[[1,1.01,0.51],[2,4.8,0]],"ltp":0.0,"tv":0.0,"id":16665614},{"batb":[[0,15,5.43],[1,1.01,0.51],[2,15,0]],"ltp":9.0,"tv":20.88,"id":13011472}]}]}
{"op":"mcm","clk":"1009219626","pt":1580642821255,"mc":[{"id":"1.168224333","rc":[{"batb":[[0,11.5,31.84],[1,11,28.1],[2,8.6,7.79]],"ltp":7.6,"tv":10.0,"id":13011471},{"batb":[[0,5.7,36.92],[1,5.6,24.45],[2,5.2,12.35]],"ltp":0.0,"tv":0.0,"id":16665614},{"batb":[[0,40,9.22],[1,38,8.06],[2,15,5.43]],"ltp":9.0,"tv":20.88,"id":13011472}]}]}
{"op":"mcm","clk":"1009219832","pt":1580642822383,"mc":[{"id":"1.168224333","rc":[{"batb":[[2,10,4.2]],"batl":[[1,12.5,16.58]],"ltp":7.6,"tv":10.0,"id":13011471},{"batb":[[0,6,17.31],[1,5.7,36.92],[2,5.6,24.45]],"batl":[[0,6.4,7.56],[1,7,16.21],[2,7.4,14.56]],"ltp":0.0,"tv":0.0,"id":16665614},{"batb":[[2,20,4.96]],"ltp":9.0,"tv":20.88,"id":13011472},{"batb":[[0,1.36,115.95],[1,1.35,251.87],[2,1.34,151.84]],"batl":[[0,1.4,60.59],[1,1.44,42.01],[2,1.48,47.76]],"ltp":1.37,"tv":233.17,"id":16665613}]}]}
{"op":"mcm","clk":"1009220111","pt":1580642824248,"mc":[{"id":"1.168224333","rc":[{"batb":[[0,1.38,27.02],[1,1.36,115.95],[2,1.35,251.87]],"ltp":1.37,"tv":233.17,"id":16665613}]}]}
{"op":"mcm","clk":"1009220535","pt":1580642827092,"mc":[{"id":"1.168224333","rc":[{"batb":[[0,1.36,115.95],[1,1.35,251.87],[2,1.34,151.84]],"ltp":1.37,"tv":233.17,"id":16665613}]}]}
{"op":"mcm","clk":"1009221009","pt":1580642830355,"mc":[{"id":"1.168224333","rc":[{"trd":[[11.5,3.27]],"batb":[[0,11.5,28.57]],"ltp":11.5,"tv":13.27,"id":13011471},{"trd":[[6,6.26]],"batb":[[0,6,11.05]],"ltp":6.0,"tv":6.25,"id":16665614},{"trd":[[40,0.94]],"batb":[[0,40,8.28]],"ltp":40.0,"tv":21.82,"id":13011472},{"trd":[[1.39,27.02]],"ltp":1.39,"tv":260.19,"id":16665613}],"tv":301.55}]}
{"op":"mcm","clk":"1009222845","pt":1580642843084,"mc":[{"id":"1.168224333","rc":[{"batb":[[0,11,15.46],[1,8.8,7.16],[2,1.01,0.51]],"batl":[[0,12.5,13.22],[1,12.5,0]],"ltp":11.5,"tv":13.27,"id":13011471},{"batb":[[0,5.5,10.46],[1,1.01,0.51],[2,5.6,0]],"batl":[[0,7.4,14.56],[1,7,0],[2,7.4,0]],"ltp":6.0,"tv":6.25,"id":16665614},{"batb":[[0,20,4.96],[1,1.01,0.51],[2,20,0]],"ltp":40.0,"tv":21.82,"id":13011472},{"batb":[[0,1.32,69.95],[1,1.01,0.51],[2,1.34,0]],"batl":[[0,1.48,47.29],[1,1.44,0],[2,1.48,0]],"ltp":1.39,"tv":260.19,"id":16665613}]}]}
{"op":"mcm","clk":"1009223400","pt":1580642846300,"mc":[{"id":"1.168224333","rc":[{"batb":[[0,8.8,7.16],[1,1.01,0.51],[2,1.01,0]],"ltp":11.5,"tv":13.27,"id":13011471},{"batb":[[0,1.32,282.91],[1,1.31,170.8],[2,1.01,0.51]],"ltp":1.39,"tv":260.19,"id":16665613}]}]}
{"op":"mcm","clk":"1009223891","pt":1580642849376,"mc":[{"id":"1.168224333","rc":[{"batb":[[0,12,25.69],[1,11.5,26.33],[2,9.8,14.48]],"batl":[[1,13,12.2]],"ltp":11.5,"tv":13.27,"id":13011471},{"batb":[[0,6.2,15.82],[1,6,21.23],[2,5.9,40.45]],"batl":[[1,7.6,13.93]],"ltp":6.0,"tv":6.25,"id":16665614},{"batb":[[0,1.01,0.51],[1,1.01,0]],"ltp":40.0,"tv":21.82,"id":13011472},{"batb":[[2,1.3,75.38]],"batl":[[0,1.37,67.35],[1,1.42,57.44]],"ltp":1.39,"tv":260.19,"id":16665613}]}]}
{"op":"mcm","clk":"1009224037","pt":1580642850380,"mc":[{"id":"1.168224333","rc":[{"batb":[[2,10,4.2]],"batl":[[1,13,15.56]],"ltp":11.5,"tv":13.27,"id":13011471},{"batl":[[0,6.6,6.72],[1,7.4,14.56],[2,7.6,13.93]],"ltp":6.0,"tv":6.25,"id":16665614},{"batb":[[0,1.33,126.87],[1,1.32,282.91],[2,1.31,170.8]],"batl":[[1,1.41,42.01],[2,1.42,57.44]],"ltp":1.39,"tv":260.19,"id":16665613}]}]}
{"op":"mcm","clk":"1009225761","pt":1580642860714,"mc":[{"id":"1.168224333","rc":[{"batb":[[0,11.5,18.3],[1,9,16.92],[2,1.01,0.51]],"batl":[[0,13,12.2],[1,13,0]],"ltp":11.5,"tv":13.27,"id":13011471},{"batb":[[0,5.9,18.49],[1,1.01,0.51],[2,5.9,0]],"batl":[[0,7.6,13.93],[1,7.4,0],[2,7.6,0]],"ltp":6.0,"tv":6.25,"id":16665614},{"batb":[[0,1.31,129.37],[1,1.3,75.38],[2,1.01,0.51]],"batl":[[0,1.42,57.44],[1,1.41,0],[2,1.42,0]],"ltp":1.39,"tv":260.19,"id":16665613}]}]}
{"op":"mcm","clk":"1009226201","pt":1580642863789,"mc":[{"id":"1.168224333","rc":[{"batb":[[1,11,29.22],[2,9,16.92]],"ltp":11.5,"tv":13.27,"id":13011471},{"batb":[[1,5.7,27.45],[2,5.6,24.59]],"ltp":6.0,"tv":6.25,"id":16665614},{"batb":[[0,42,4.86],[1,40,8.3],[2,1.01,0.51]],"ltp":40.0,"tv":21.82,"id":13011472},{"batb":[[1,1.3,251.89]],"ltp":1.39,"tv":260.19,"id":16665613}]}]}
{"op":"mcm","clk":"1009226287","pt":1580642864426,"mc":[{"id":"1.168224333","rc":[{"batb":[[1,9,16.92],[2,1.01,0.51]],"ltp":11.5,"tv":13.27,"id":13011471},{"batb":[[1,1.01,0.51],[2,5.6,0]],"ltp":6.0,"tv":6.25,"id":16665614},{"batb":[[0,1.01,0.51],[1,40,0],[2,1.01,0]],"ltp":40.0,"tv":21.82,"id":13011472},{"batb":[[0,1.3,75.38],[1,1.01,0.51],[2,1.01,0]],"ltp":1.39,"tv":260.19,"id":16665613}]}]}
{"op":"mcm","clk":"1009226757","pt":1580642867399,"mc":[{"id":"1.168224333","rc":[{"batb":[[0,12,18.81],[1,11.5,26.6],[2,9,16.92]],"ltp":11.5,"tv":13.27,"id":13011471},{"batb":[[0,5.9,49.43],[1,5.8,22.68],[2,1.01,0.51]],"ltp":6.0,"tv":6.25,"id":16665614},{"batb":[[0,55,3.18],[1,50,9.99],[2,1.01,0.51]],"ltp":40.0,"tv":21.82,"id":13011472},{"batb":[[0,1.33,154.04],[1,1.32,163.26],[2,1.3,75.38]],"ltp":1.39,"tv":260.19,"id":16665613}]}]}
{"op":"mcm","clk":"1009227037","pt":1580642869099,"mc":[{"id":"1.168224333","rc":[{"batb":[[0,11.5,18.3],[1,9,16.92],[2,1.01,0.51]],"ltp":11.5,"tv":13.27,"id":13011471},{"batb":[[0,5.9,18.49],[1,1.01,0.51],[2,1.01,0]],"ltp":6.0,"tv":6.25,"id":16665614},{"batb":[[0,1.01,0.51],[1,50,0],[2,1.01,0]],"ltp":40.0,"tv":21.82,"id":13011472},{"batb":[[0,1.3,75.38],[1,1.01,0.51],[2,1.3,0]],"ltp":1.39,"tv":260.19,"id":16665613}]}]}
{"op":"mcm","clk":"1009227459","pt":1580642872027,"mc":[{"id":"1.168224333","rc":[{"batb":[[1,11,29.22],[2,9,16.92]],"ltp":11.5,"tv":13.27,"id":13011471},{"batb":[[1,5.7,27.45],[2,5.6,24.59]],"ltp":6.0,"tv":6.25,"id":16665614},{"batb":[[0,42,4.86],[1,40,8.3],[2,1.01,0.51]],"ltp":40.0,"tv":21.82,"id":13011472},{"batb":[[0,1.31,129.37],[1,1.3,251.89],[2,1.01,0.51]],"ltp":1.39,"tv":260.19,"id":16665613}]}]}
{"op":"mcm","clk":"1009228326","pt":1580642877935,"mc":[{"id":"1.168224333","rc":[{"batb":[[0,9,16.92],[1,1.01,0.51],[2,9,0]],"ltp":11.5,"tv":13.27,"id":13011471},{"batb":[[1,1.01,0.51],[2,5.6,0]],"ltp":6.0,"tv":6.25,"id":16665614},{"batb":[[0,1.01,0.51],[1,40,0],[2,1.01,0]],"ltp":40.0,"tv":21.82,"id":13011472}]}]}
{"op":"mcm","clk":"1009228779","pt":1580642881209,"mc":[{"id":"1.168224333","rc":[{"batb":[[0,12.5,16.87],[1,12,24.41],[2,10,13.38]],"batl":[[1,14,10.78]],"ltp":11.5,"tv":13.27,"id":13011471},{"batb":[[0,6.4,14.79],[1,6.2,16.13],[2,6,51.08]],"batl":[[1,8,12.51]],"ltp":6.0,"tv":6.25,"id":16665614},{"batb":[[0,70,7.55],[1,65,2.25],[2,1.01,0.51]],"ltp":40.0,"tv":21.82,"id":13011472},{"batb":[[2,1.27,83.95]],"batl":[[0,1.35,72.47],[1,1.37,66.72],[2,1.42,57.44]],"ltp":1.39,"tv":260.19,"id":16665613}]}]}
{"op":"mcm","clk":"1009228886","pt":1580642882030,"mc":[{"id":"1.168224333","rc":[{"batb":[[2,10.5,4.2]],"batl":[[1,13.5,3.36],[2,14,10.78]],"ltp":11.5,"tv":13.27,"id":13011471},{"batl":[[0,6.8,6.72],[1,7.6,13.93],[2,8,12.51]],"ltp":6.0,"tv":6.25,"id":16665614},{"batb":[[0,1.32,131.07],[1,1.31,129.37],[2,1.3,251.89]],"batl":[[2,1.38,42.01]],"ltp":1.39,"tv":260.19,"id":16665613}]}]}
{"op":"mcm","clk":"1009231408","pt":1580642900174,"mc":[{"id":"1.168224333","rc":[{"batb":[[0,12,18.58],[1,10.5,4.2],[2,9.6,15.11]],"batl":[[0,13.5,3.36],[1,14,10.78],[2,14,0]],"ltp":11.5,"tv":13.27,"id":13011471},{"batb":[[0,6.2,16.13],[1,5.9,21.54],[2,5.7,8.4]],"batl":[[1,8,12.51],[2,8,0]],"ltp":6.0,"tv":6.25,"id":16665614},{"batb":[[0,1.01,0.51],[1,65,0],[2,1.01,0]],"ltp":40.0,"tv":21.82,"id":13011472},{"batb":[[1,1.27,83.95],[2,1.01,0.51]],"batl":[[0,1.37,66.72],[1,1.38,42.01],[2,1.38,0]],"ltp":1.39,"tv":260.19,"id":16665613}]}]}
{"op":"mcm","clk":"1009231492","pt":1580642900770,"mc":[{"id":"1.168224333","rc":[{"batb":[[1,9.6,15.11],[2,1.01,0.51]],"batl":[[0,14,10.78],[1,14,0]],"ltp":11.5,"tv":13.27,"id":13011471},{"batb":[[2,1.01,0.51]],"batl":[[0,8,12.51],[1,8,0]],"ltp":6.0,"tv":6.25,"id":16665614},{"batb":[[0,1.27,83.95],[1,1.01,0.51],[2,1.01,0]],"batl":[[1,1.38,0]],"ltp":1.39,"tv":260.19,"id":16665613}]}]}
{"op":"mcm","clk":"1009231619","pt":1580642901643,"mc":[{"id":"1.168224333","rc":[{"batb":[[1,1.01,0.51],[2,1.01,0]],"ltp":6.0,"tv":6.25,"id":16665614}]}]}
{"op":"mcm","clk":"1009232082","pt":1580642905051,"mc":[{"id":"1.168224333","rc":[{"batb":[[0,12.5,22.82],[1,12,24.17],[2,9.6,15.11]],"ltp":11.5,"tv":13.27,"id":13011471},{"batb":[[0,6.2,35.96],[1,6,41.64],[2,1.01,0.51]],"ltp":6.0,"tv":6.25,"id":16665614},{"batb":[[0,75,5.68],[1,70,3.55],[2,1.01,0.51]],"ltp":40.0,"tv":21.82,"id":13011472},{"batb":[[0,1.3,223.61],[1,1.29,185.69],[2,1.27,83.95]],"ltp":1.39,"tv":260.19,"id":16665613}]}]}
{"op":"mcm","clk":"1009232299","pt":1580642906780,"mc":[{"id":"1.168224333","rc":[{"batb":[[0,12,18.58],[1,9.6,15.11],[2,1.01,0.51]],"ltp":11.5,"tv":13.27,"id":13011471},{"batb":[[0,6.2,16.13],[1,1.01,0.51],[2,1.01,0]],"ltp":6.0,"tv":6.25,"id":16665614},{"batb":[[0,1.01,0.51],[1,70,0],[2,1.01,0]],"ltp":40.0,"tv":21.82,"id":13011472},{"batb":[[0,1.27,83.95],[1,1.01,0.51],[2,1.27,0]],"ltp":1.39,"tv":260.19,"id":16665613}]}]}
{"op":"mcm","clk":"1009232836","pt":1580642910559,"mc":[{"id":"1.168224333","rc":[{"batb":[[1,11.5,26.59],[2,9.6,15.11]],"ltp":11.5,"tv":13.27,"id":13011471},{"batb":[[1,5.9,33.17],[2,5.8,22.64]],"ltp":6.0,"tv":6.25,"id":16665614},{"batb":[[0,60,5.82],[1,55,5.92],[2,1.01,0.51]],"ltp":40.0,"tv":21.82,"id":13011472},{"batb":[[0,1.28,263.72],[1,1.27,287.4],[2,1.01,0.51]],"ltp":1.39,"tv":260.19,"id":16665613}]}]}
{"op":"mcm","clk":"1009233241","pt":1580642913290,"mc":[{"id":"1.168224333","rc":[{"batb":[[0,9.6,15.11],[1,1.01,0.51],[2,9.6,0]],"ltp":11.5,"tv":13.27,"id":13011471},{"batb":[[1,1.01,0.51],[2,5.8,0]],"ltp":6.0,"tv":6.25,"id":16665614},{"batb":[[0,1.01,0.51],[1,55,0],[2,1.01,0]],"ltp":40.0,"tv":21.82,"id":13011472}]}]}
{"op":"mcm","clk":"1009233698","pt":1580642916266,"mc":[{"id":"1.168224333","rc":[{"batb":[[0,13,19.59],[1,12.5,22.12],[2,9.6,15.11]],"ltp":11.5,"tv":13.27,"id":13011471},{"batb":[[0,6.4,24.47],[1,6.2,54.76],[2,1.01,0.51]],"ltp":6.0,"tv":6.25,"id":16665614},{"batb":[[0,1.28,190.93],[1,1.27,83.95]],"ltp":1.39,"tv":260.19,"id":16665613}]}]}
{"op":"mcm","clk":"1009233866","pt":1580642917386,"mc":[{"id":"1.168224333","rc":[{"batb":[[2,10.5,11.72]],"batl":[[1,15,9.36]],"ltp":11.5,"tv":13.27,"id":13011471},{"batb":[[0,6.8,13.22],[1,6.4,39.18],[2,6.2,38.63]],"batl":[[1,8.6,11.02]],"ltp":6.0,"tv":6.25,"id":16665614},{"batb":[[2,1.25,94.73]],"batl":[[0,1.32,80.49],[1,1.34,73.25]],"ltp":1.39,"tv":260.19,"id":16665613}]}]}
{"op":"mcm","clk":"1009233908","pt":1580642917658,"mc":[{"id":"1.168224333","rc":[{"batb":[[2,11,4.2]],"ltp":11.5,"tv":13.27,"id":13011471},{"batl":[[0,7,6.72],[1,8,12.51],[2,8.6,11.02]],"ltp":6.0,"tv":6.25,"id":16665614},{"batb":[[0,1.3,139.47],[1,1.28,190.93],[2,1.27,83.95]],"batl":[[2,1.36,42.01]],"ltp":1.39,"tv":260.19,"id":16665613}]}]}
{"op":"mcm","clk":"1009234193","pt":1580642919676,"mc":[{"id":"1.168224333","rc":[{"batb":[[1,1.29,83.2],[2,1.28,190.93]],"ltp":1.39,"tv":260.19,"id":16665613}]}]}
{"op":"mcm","clk":"1009234631","pt":1580642922372,"mc":[{"id":"1.168224333","rc":[{"batl":[[2,1.35,6.23]],"ltp":1.39,"tv":260.19,"id":16665613}]}]}
{"op":"mcm","clk":"1009234778","pt":1580642923371,"mc":[{"id":"1.168224333","rc":[{"batl":[[2,1.36,42.01]],"ltp":1.39,"tv":260.19,"id":16665613}]}]}
{"op":"mcm","clk":"1009235010","pt":1580642925066,"mc":[{"id":"1.168224333","rc":[{"batb":[[0,13,13.59]],"ltp":11.5,"tv":13.27,"id":13011471}]}]}
{"op":"mcm","clk":"1009235458","pt":1580642928095,"mc":[{"id":"1.168224333","rc":[{"batb":[[0,95,4.08],[1,90,3.19],[2,1.01,0.51]],"ltp":40.0,"tv":21.82,"id":13011472}]}]}
{"op":"mcm","clk":"1009235644","pt":1580642929372,"mc":[{"id":"1.168224333","rc":[{"batb":[[0,12.5,11.49],[1,11,4.2],[2,10,13.22]],"batl":[[0,15,9.36],[1,15,0]],"ltp":11.5,"tv":13.27,"id":13011471},{"batb":[[0,6.4,14.71],[1,6.2,20.38],[2,5.9,8.4]],"batl":[[1,8.6,11.02],[2,8.6,0]],"ltp":6.0,"tv":6.25,"id":16665614},{"batb":[[0,1.01,0.51],[1,90,0],[2,1.01,0]],"ltp":40.0,"tv":21.82,"id":13011472},{"batb":[[1,1.25,94.73],[2,1.01,0.51]],"batl":[[0,1.34,73.25],[1,1.36,42.01],[2,1.36,0]],"ltp":1.39,"tv":260.19,"id":16665613}]}]}
{"op":"mcm","clk":"1009235889","pt":1580642931187,"mc":[{"id":"1.168224333","rc":[{"batb":[[1,10,13.22],[2,1.01,0.51]],"ltp":11.5,"tv":13.27,"id":13011471},{"batb":[[2,1.01,0.51]],"batl":[[0,8.6,11.02],[1,8.6,0]],"ltp":6.0,"tv":6.25,"id":16665614},{"batb":[[0,1.25,94.73],[1,1.01,0.51],[2,1.01,0]],"batl":[[1,1.36,0]],"ltp":1.39,"tv":260.19,"id":16665613}]}]}
{"op":"mcm","clk":"1009236060","pt":1580642932313,"mc":[{"id":"1.168224333","rc":[{"batb":[[1,12,24.17],[2,10,13.22]],"ltp":11.5,"tv":13.27,"id":13011471},{"batb":[[2,6,41.7]],"ltp":6.0,"tv":6.25,"id":16665614},{"batb":[[0,75,2.51],[1,70,6.45],[2,1.01,0.51]],"ltp":40.0,"tv":21.82,"id":13011472},{"batb":[[0,1.26,207.26],[1,1.25,316.27],[2,1.01,0.51]],"ltp":1.39,"tv":260.19,"id":16665613}]}]}
{"op":"mcm","clk":"1009236184","pt":1580642933109,"mc":[{"id":"1.168224333","rc":[{"batb":[[1,10,13.22],[2,1.01,0.51]],"ltp":11.5,"tv":13.27,"id":13011471},{"batb":[[2,1.01,0.51]],"ltp":6.0,"tv":6.25,"id":16665614},{"batb":[[0,1.01,0.51],[1,70,0],[2,1.01,0]],"ltp":40.0,"tv":21.82,"id":13011472},{"batb":[[0,1.25,94.73],[1,1.01,0.51],[2,1.01,0]],"ltp":1.39,"tv":260.19,"id":16665613}]}]}
{"op":"mcm","clk":"1009236510","pt":1580642935292,"mc":[{"id":"1.168224333","rc":[{"batb":[[0,13,20.12],[1,12.5,21.88],[2,10,13.22]],"ltp":11.5,"tv":13.27,"id":13011471},{"batb":[[0,6.4,52.86],[1,6.2,38.31]],"ltp":6.0,"tv":6.25,"id":16665614},{"batb":[[0,100,5.99],[1,1.01,0.51]],"ltp":40.0,"tv":21.82,"id":13011472},{"batb":[[0,1.28,198.74],[1,1.27,201.59],[2,1.25,94.73]],"ltp":1.39,"tv":260.19,"id":16665613}]}]}
{"op":"mcm","clk":"1009236797","pt":1580642937106,"mc":[{"id":"1.168224333","rc":[{"batb":[[0,12.5,11.49],[1,10,13.22],[2,1.01,0.51]],"ltp":11.5,"tv":13.27,"id":13011471},{"batb":[[0,6.4,14.71],[1,6.2,20.38]],"ltp":6.0,"tv":6.25,"id":16665614},{"batb":[[0,1.01,0.51],[1,1.01,0]],"ltp":40.0,"tv":21.82,"id":13011472},{"batb":[[0,1.25,94.73],[1,1.01,0.51],[2,1.25,0]],"ltp":1.39,"tv":260.19,"id":16665613}]}]}
{"op":"mcm","clk":"1009237289","pt":1580642940314,"mc":[{"id":"1.168224333","rc":[{"batb":[[1,12,24.17],[2,10,13.22]],"ltp":11.5,"tv":13.27,"id":13011471},{"batb":[[2,6,41.7]],"ltp":6.0,"tv":6.25,"id":16665614},{"batb":[[0,75,2.51],[1,70,6.45],[2,1.01,0.51]],"ltp":40.0,"tv":21.82,"id":13011472},{"batb":[[0,1.26,207.26],[1,1.25,316.27],[2,1.01,0.51]],"ltp":1.39,"tv":260.19,"id":16665613}]}]}
{"op":"mcm","clk":"1009237367","pt":1580642940710,"mc":[{"id":"1.168224333","rc":[{"batb":[[0,1.25,94.73],[1,1.01,0.51],[2,1.01,0]],"ltp":1.39,"tv":260.19,"id":16665613}]}]}
{"op":"mcm","clk":"1009238014","pt":1580642944306,"mc":[{"id":"1.168224333","rc":[{"batl":[[0,13,12.04],[1,14.5,10.39],[2,15,9.36]],"ltp":11.5,"tv":13.27,"id":13011471},{"batb":[[1,6.2,36.35]],"batl":[[0,7.6,13.85],[1,8.2,12.2],[2,8.6,11.02]],"ltp":6.0,"tv":6.25,"id":16665614},{"batb":[[0,1.31,98.6],[1,1.3,251.59],[2,1.27,86.55]],"batl":[[1,1.37,67.51]],"ltp":1.39,"tv":260.19,"id":16665613}]}]}
{"op":"mcm","clk":"1009238173","pt":1580642945329,"mc":[{"id":"1.168224333","rc":[{"batl":[[2,15,0]],"ltp":11.5,"tv":13.27,"id":13011471},{"batl":[[2,8.6,0]],"ltp":6.0,"tv":6.25,"id":16665614}]}]}
{"op":"mcm","clk":"1009238278","pt":1580642946009,"mc":[{"id":"1.168224333","rc":[{"batb":[[2,10.5,4.2]],"ltp":11.5,"tv":13.27,"id":13011471},{"batl":[[0,6.8,6.72],[1,7.6,13.85],[2,8.2,12.2]],"ltp":6.0,"tv":6.25,"id":16665614},{"batb":[[0,1.31,233.87]],"batl":[[2,1.38,42.01]],"ltp":1.39,"tv":260.19,"id":16665613}]}]}
{"op":"mcm","clk":"1009239908","pt":1580642956338,"mc":[{"id":"1.168224333","rc":[{"batb":[[0,12,12.62],[1,10.5,4.2],[2,9.6,14.56]],"batl":[[0,14.5,10.39],[1,14.5,0]],"ltp":11.5,"tv":13.27,"id":13011471},{"batb":[[0,6.2,15.97],[1,6,17.59],[2,5.7,8.4]],"batl":[[1,8.2,12.2],[2,8.2,0]],"ltp":6.0,"tv":6.25,"id":16665614},{"batb":[[0,1.01,0.51],[1,70,0],[2,1.01,0]],"ltp":40.0,"tv":21.82,"id":13011472},{"batb":[[0,1.31,135.27],[1,1.27,86.55],[2,1.01,0.51]],"batl":[[0,1.37,67.51],[1,1.38,42.01],[2,1.38,0]],"ltp":1.39,"tv":260.19,"id":16665613}]}]}
{"op":"mcm","clk":"1009239991","pt":1580642956880,"mc":[{"id":"1.168224333","rc":[{"batb":[[1,9.6,14.56],[2,1.01,0.51]],"ltp":11.5,"tv":13.27,"id":13011471},{"batb":[[2,1.01,0.51]],"batl":[[0,8.2,12.2],[1,8.2,0]],"ltp":6.0,"tv":6.25,"id":16665614},{"batb":[[0,1.27,86.55],[1,1.01,0.51],[2,1.01,0]],"batl":[[1,1.38,0]],"ltp":1.39,"tv":260.19,"id":16665613}]}]}
{"op":"mcm","clk":"1009240421","pt":1580642959156,"mc":[{"id":"1.168224333","rc":[{"batb":[[1,11.5,26.4],[2,9.6,14.56]],"ltp":11.5,"tv":13.27,"id":13011471},{"batb":[[2,5.9,22.04]],"ltp":6.0,"tv":6.25,"id":16665614},{"batb":[[0,60,4.31],[1,55,7.56],[2,1.01,0.51]],"ltp":40.0,"tv":21.82,"id":13011472},{"batb":[[0,1.28,168.12],[1,1.27,287.57],[2,1.01,0.51]],"ltp":1.39,"tv":260.19,"id":16665613}]}]}
{"op":"mcm","clk":"1009240649","pt":1580642960356,"mc":[{"id":"1.168224333","rc":[{"batb":[[1,9.6,14.56],[2,1.01,0.51]],"ltp":11.5,"tv":13.27,"id":13011471},{"batb":[[2,1.01,0.51]],"ltp":6.0,"tv":6.25,"id":16665614},{"batb":[[0,1.01,0.51],[1,55,0],[2,1.01,0]],"ltp":40.0,"tv":21.82,"id":13011472},{"batb":[[0,1.27,86.55],[1,1.01,0.51],[2,1.01,0]],"ltp":1.39,"tv":260.19,"id":16665613}]}]}
{"op":"mcm","clk":"1009240789","pt":1580642961159,"mc":[{"id":"1.168224333","rc":[{"batb":[[0,12.5,19.03],[1,12,23.92],[2,9.6,14.56]],"ltp":11.5,"tv":13.27,"id":13011471},{"batb":[[0,6.2,48.19],[1,6,41.36]],"ltp":6.0,"tv":6.25,"id":16665614},{"batb":[[0,80,2.67],[1,75,5.63],[2,1.01,0.51]],"ltp":40.0,"tv":21.82,"id":13011472},{"batb":[[0,1.3,177.79],[1,1.29,184.33],[2,1.27,86.55]],"ltp":1.39,"tv":260.19,"id":16665613}]}]}
{"op":"mcm","clk":"1009241375","pt":1580642964975,"mc":[{"id":"1.168224333","rc":[{"batb":[[0,12,12.62],[1,9.6,14.56],[2,1.01,0.51]],"ltp":11.5,"tv":13.27,"id":13011471},{"batb":[[0,6.2,15.97],[1,6,17.62]],"ltp":6.0,"tv":6.25,"id":16665614},{"batb":[[0,1.01,0.51],[1,75,0],[2,1.01,0]],"ltp":40.0,"tv":21.82,"id":13011472},{"batb":[[0,1.27,86.55],[1,1.01,0.51],[2,1.27,0]],"ltp":1.39,"tv":260.19,"id":16665613}]}]}
{"op":"mcm","clk":"1009241957","pt":1580642968968,"mc":[{"id":"1.168224333","rc":[{"batb":[[1,11.5,26.4],[2,9.6,14.56]],"ltp":11.5,"tv":13.27,"id":13011471},{"batb":[[2,5.9,22.04]],"ltp":6.0,"tv":6.25,"id":16665614},{"batb":[[0,60,4.29],[1,55,7.58],[2,1.01,0.51]],"ltp":40.0,"tv":21.82,"id":13011472},{"batb":[[0,1.28,168.57],[1,1.27,287.58],[2,1.01,0.51]],"ltp":1.39,"tv":260.19,"id":16665613}]}]}
{"op":"mcm","clk":"1009243916","pt":1580642982003,"mc":[{"id":"1.168224333","rc":[{"batb":[[0,1.27,86.55],[1,1.01,0.51],[2,1.01,0]],"ltp":1.39,"tv":260.19,"id":16665613}]}]}
{"op":"mcm","clk":"1009244370","pt":1580642985002,"mc":[{"id":"1.168224333","rc":[{"batb":[[0,1.33,98.86],[1,1.32,161.87],[2,1.27,86.55]],"ltp":1.39,"tv":260.19,"id":16665613}]}]}
{"op":"mcm","clk":"1009244579","pt":1580642986290,"mc":[{"id":"1.168224333","rc":[{"batb":[[2,10.5,4.2]],"batl":[[0,12.5,13.22],[1,13.5,14.85]],"ltp":11.5,"tv":13.27,"id":13011471},{"batb":[[1,6,35.01]],"batl":[[0,6.6,6.72],[1,7.4,15.03],[2,7.6,13.61]],"ltp":6.0,"tv":6.25,"id":16665614},{"batb":[[0,1.33,225.73],[1,1.32,231.98],[2,1.29,78.21]],"batl":[[1,1.39,104.48]],"ltp":1.39,"tv":260.19,"id":16665613}]}]}
{"op":"mcm","clk":"1009246611","pt":1580642999195,"mc":[{"id":"1.168224333","rc":[{"batb":[[1,55,5.2]],"ltp":40.0,"tv":21.82,"id":13011472}]}]}
{"op":"mcm","clk":"1009246934","pt":1580643001296,"mc":[{"id":"1.168224333","rc":[{"batb":[[0,11.5,17.42],[1,10.5,4.2],[2,9.6,14.56]],"ltp":11.5,"tv":13.27,"id":13011471},{"batb":[[1,6,17.39],[2,5.6,8.4]],"ltp":6.0,"tv":6.25,"id":16665614},{"batb":[[0,60,2.18],[1,1.01,0.51],[2,1.01,0]],"ltp":40.0,"tv":21.82,"id":13011472},{"batb":[[0,1.33,126.87],[1,1.32,70.11]],"ltp":1.39,"tv":260.19,"id":16665613}]}]}
{"op":"mcm","clk":"1009246990","pt":1580643001617,"mc":[{"id":"1.168224333","rc":[{"batb":[[2,9.2,16.05]],"batl":[[0,13.5,14.85],[1,13.5,0]],"ltp":11.5,"tv":13.27,"id":13011471},{"batb":[[0,6,17.39],[1,5.6,8.4],[2,1.01,0.51]],"batl":[[1,7.6,13.61],[2,7.6,0]],"ltp":6.0,"tv":6.25,"id":16665614},{"batb":[[0,1.01,0.51],[1,1.01,0]],"ltp":40.0,"tv":21.82,"id":13011472},{"batb":[[1,1.29,78.21],[2,1.01,0.51]],"batl":[[0,1.39,104.48],[1,1.39,0]],"ltp":1.39,"tv":260.19,"id":16665613}]}]}
{"op":"mcm","clk":"1009247175","pt":1580643002830,"mc":[{"id":"1.168224333","rc":[{"batb":[[1,9.2,16.05],[2,1.01,0.51]],"batl":[[0,13.5,11.49]],"ltp":11.5,"tv":13.27,"id":13011471},{"batb":[[1,1.01,0.51],[2,1.01,0]],"batl":[[0,7.6,13.61],[1,7.6,0]],"ltp":6.0,"tv":6.25,"id":16665614},{"batb":[[0,1.29,78.21],[1,1.01,0.51],[2,1.01,0]],"batl":[[0,1.39,62.47]],"ltp":1.39,"tv":260.19,"id":16665613}]}]}
{"op":"mcm","clk":"1009247428","pt":1580643004338,"mc":[{"id":"1.168224333","rc":[{"batb":[[1,11,28.8],[2,9.2,16.05]],"ltp":11.5,"tv":13.27,"id":13011471},{"batb":[[1,5.8,25.08],[2,5.7,23.72]],"ltp":6.0,"tv":6.25,"id":16665614},{"batb":[[0,50,11.86],[1,1.01,0.51]],"ltp":40.0,"tv":21.82,"id":13011472},{"batb":[[0,1.3,183.46],[1,1.29,262.88],[2,1.01,0.51]],"ltp":1.39,"tv":260.19,"id":16665613}]}]}
{"op":"mcm","clk":"1009247998","pt":1580643008023,"mc":[{"id":"1.168224333","rc":[{"batb":[[0,11.5,17.59]],"ltp":11.5,"tv":13.27,"id":13011471}]}]}
{"op":"mcm","clk":"1009248534","pt":1580643011216,"mc":[{"id":"1.168224333","rc":[{"batb":[[0,9.2,16.22],[1,1.01,0.51],[2,9.2,0]],"ltp":11.5,"tv":13.27,"id":13011471},{"batb":[[1,1.01,0.51],[2,5.7,0]],"ltp":6.0,"tv":6.25,"id":16665614},{"batb":[[0,1.01,0.51],[1,1.01,0]],"ltp":40.0,"tv":21.82,"id":13011472}]}]}
{"op":"mcm","clk":"1009248918","pt":1580643013825,"mc":[{"id":"1.168224333","rc":[{"batb":[[0,12.5,19.48],[1,12,23.92],[2,9.2,16.22]],"ltp":11.5,"tv":13.27,"id":13011471},{"batb":[[0,6.2,31.13],[1,6,58.83],[2,1.01,0.51]],"ltp":6.0,"tv":6.25,"id":16665614},{"batb":[[0,80,2.09],[1,75,5.77],[2,1.01,0.51]],"ltp":40.0,"tv":21.82,"id":13011472}]}]}
{"op":"mcm","clk":"1009249161","pt":1580643015324,"mc":[{"id":"1.168224333","rc":[{"batb":[[2,10,12.76]],"batl":[[1,14.5,9.99]],"ltp":11.5,"tv":13.27,"id":13011471},{"batb":[[0,6.4,14.4],[1,6.2,47.02],[2,6,41.44]],"batl":[[1,8.4,11.49]],"ltp":6.0,"tv":6.25,"id":16665614},{"batb":[[2,1.26,90.72]],"batl":[[0,1.34,75.14],[1,1.36,68.22]],"ltp":1.39,"tv":260.19,"id":16665613}]}]}
{"op":"mcm","clk":"1009249223","pt":1580643016005,"mc":[{"id":"1.168224333","rc":[{"batb":[[2,11,4.37]],"ltp":11.5,"tv":13.27,"id":13011471},{"batl":[[0,6.8,6.72],[1,7.6,13.61],[2,8.4,11.49]],"ltp":6.0,"tv":6.25,"id":16665614},{"batb":[[0,1.31,135.27],[1,1.3,183.46],[2,1.29,262.88]],"batl":[[2,1.37,42.01]],"ltp":1.39,"tv":260.19,"id":16665613}]}]}
{"op":"mcm","clk":"1009252135","pt":1580643033064,"mc":[{"id":"1.168224333","rc":[{"batb":[[0,12,17.19],[1,11,4.37],[2,9.8,14.16]],"batl":[[0,14.5,9.99],[1,14.5,0]],"ltp":11.5,"tv":13.27,"id":13011471},{"batb":[[0,6.2,15.89],[1,6,20.6],[2,5.8,8.4]],"batl":[[1,8.4,11.49],[2,8.4,0]],"ltp":6.0,"tv":6.25,"id":16665614},{"batb":[[0,1.01,0.51],[1,75,0],[2,1.01,0]],"ltp":40.0,"tv":21.82,"id":13011472},{"batb":[[1,1.26,90.72],[2,1.01,0.51]],"batl":[[0,1.36,68.22],[1,1.37,42.01],[2,1.37,0]],"ltp":1.39,"tv":260.19,"id":16665613}]}]}
{"op":"mcm","clk":"1009252411","pt":1580643034763,"mc":[{"id":"1.168224333","rc":[{"batb":[[1,9.8,14.33],[2,1.01,0.51]],"ltp":11.5,"tv":13.27,"id":13011471},{"batb":[[2,1.01,0.51]],"batl":[[0,8.4,11.49],[1,8.4,0]],"ltp":6.0,"tv":6.25,"id":16665614},{"batb":[[0,1.26,90.72],[1,1.01,0.51],[2,1.01,0]],"batl":[[1,1.37,0]],"ltp":1.39,"tv":260.19,"id":16665613}]}]}
{"op":"mcm","clk":"1009252591","pt":1580643035874,"mc":[{"id":"1.168224333","rc":[{"batb":[[1,11.5,26.42],[2,9.8,14.16]],"ltp":11.5,"tv":13.27,"id":13011471},{"batb":[[2,5.9,22.03]],"ltp":6.0,"tv":6.25,"id":16665614},{"batb":[[0,60,3.39],[1,55,8.57],[2,1.01,0.51]],"ltp":40.0,"tv":21.82,"id":13011472}]}]}
{"op":"mcm","clk":"1009253026","pt":1580643038369,"mc":[{"id":"1.168224333","rc":[{"batb":[[0,1.33,76.35],[1,1.32,161.79],[2,1.26,90.72]],"ltp":1.39,"tv":260.19,"id":16665613}]}]}
{"op":"mcm","clk":"1009253186","pt":1580643039270,"mc":[{"id":"1.168224333","rc":[{"batl":[[0,13,12.9],[1,13.5,11.33]],"ltp":11.5,"tv":13.27,"id":13011471},{"batb":[[1,6,37.75]],"batl":[[0,7.4,14.95],[1,7.8,13.3]],"ltp":6.0,"tv":6.25,"id":16665614},{"batb":[[2,30,2.52]],"ltp":40.0,"tv":21.82,"id":13011472},{"batb":[[2,1.31,70.81]],"batl":[[1,1.39,63.42]],"ltp":1.39,"tv":260.19,"id":16665613}]}]}
