{"op":"mcm","clk":"1004962286","pt":1580585267691,"mc":[{"id":"1.168224338","marketDefinition":{"bspMarket":false,"turnInPlayEnabled":true,"persistenceEnabled":true,"marketBaseRate":5.0,"eventId":"29681722","eventTypeId":"2","numberOfWinners":1,"bettingType":"ODDS","marketType":"SET_WINNER","marketTime":"2020-02-02T09:00:00.000Z","suspendTime":"2020-02-02T09:00:00.000Z","bspReconciled":false,"complete":true,"inPlay":false,"crossMatching":false,"runnersVoidable":false,"numberOfActiveRunners":2,"betDelay":0,"status":"OPEN","runners":[{"status":"ACTIVE","sortPriority":1,"id":8979329,"name":"Emil Ruusuvuori"},{"status":"ACTIVE","sortPriority":2,"id":2397396,"name":"Matthias Bachinger"}],"regulators":["MR_INT"],"countryCode":"FR","discountAllowed":false,"timezone":"UTC","openDate":"2020-02-02T09:00:00.000Z","version":3147098022,"name":"Set 1 Winner","eventName":"Emil Ruusuvuori v Bachinger"},"rc":[{"batb":[[0,1.01,20]],"ltp":0.0,"tv":0.0,"id":2397396},{"batb":[[0,1.01,20]],"ltp":0.0,"tv":0.0,"id":8979329}]}]}
{"op":"mcm","clk":"1004962420","pt":1580585268465,"mc":[{"id":"1.168224338","marketDefinition":{"bspMarket":false,"turnInPlayEnabled":true,"persistenceEnabled":true,"marketBaseRate":5.0,"eventId":"29681722","eventTypeId":"2","numberOfWinners":1,"bettingType":"ODDS","marketType":"SET_WINNER","marketTime":"2020-02-02T09:00:00.000Z","suspendTime":"2020-02-02T09:00:00.000Z","bspReconciled":false,"complete":true,"inPlay":false,"crossMatching":false,"runnersVoidable":false,"numberOfActiveRunners":2,"betDelay":0,"status":"OPEN","runners":[{"status":"ACTIVE","sortPriority":1,"id":8979329,"name":"Emil Ruusuvuori"},{"status":"ACTIVE","sortPriority":2,"id":2397396,"name":"Matthias Bachinger"}],"regulators":["MR_INT"],"countryCode":"FR","discountAllowed":false,"timezone":"UTC","openDate":"2020-02-02T09:00:00.000Z","version":3147098022,"name":"Set 1 Winner","eventName":"Emil Ruusuvuori v Bachinger"}}]}
{"op":"mcm","clk":"1004962808","pt":1580585270546,"mc":[{"id":"1.168224338","marketDefinition":{"bspMarket":false,"turnInPlayEnabled":true,"persistenceEnabled":true,"marketBaseRate":5.0,"eventId":"29681722","eventTypeId":"2","numberOfWinners":1,"bettingType":"ODDS","marketType":"SET_WINNER","marketTime":"2020-02-02T09:00:00.000Z","suspendTime":"2020-02-02T09:00:00.000Z","bspReconciled":false,"complete":true,"inPlay":false,"crossMatching":false,"runnersVoidable":false,"numberOfActiveRunners":2,"betDelay":0,"status":"OPEN","runners":[{"status":"ACTIVE","sortPriority":1,"id":8979329,"name":"Emil Ruusuvuori"},{"status":"ACTIVE","sortPriority":2,"id":2397396,"name":"Matthias Bachinger"}],"regulators":["MR_INT"],"countryCode":"FR","discountAllowed":true,"timezone":"UTC","openDate":"2020-02-02T09:00:00.000Z","version":3147098022,"name":"Set 1 Winner","eventName":"Emil Ruusuvuori v Bachinger"}}]}
{"op":"mcm","clk":"1004986096","pt":1580585417007,"mc":[{"id":"1.168224338","rc":[{"batb":[[0,1.01,15]],"ltp":0.0,"tv":0.0,"id":2397396},{"batb":[[0,1.01,15]],"ltp":0.0,"tv":0.0,"id":8979329}]}]}
{"op":"mcm","clk":"1005002549","pt":1580585515430,"mc":[{"id":"1.168224338","marketDefinition":{"bspMarket":false,"turnInPlayEnabled":true,"persistenceEnabled":true,"marketBaseRate":5.0,"eventId":"29681722","eventTypeId":"2","numberOfWinners":1,"bettingType":"ODDS","marketType":"SET_WINNER","marketTime":"2020-02-02T11:30:00.000Z","suspendTime":"2020-02-02T11:30:00.000Z","bspReconciled":false,"complete":true,"inPlay":false,"crossMatching":false,"runnersVoidable":false,"numberOfActiveRunners":2,"betDelay":0,"status":"OPEN","runners":[{"status":"ACTIVE","sortPriority":1,"id":8979329,"name":"Emil Ruusuvuori"},{"status":"ACTIVE","sortPriority":2,"id":2397396,"name":"Matthias Bachinger"}],"regulators":["MR_INT"],"countryCode":"FR","discountAllowed":true,"timezone":"UTC","openDate":"2020-02-02T09:00:00.000Z","version":3147124993,"name":"Set 1 Winner","eventName":"Emil Ruusuvuori v Bachinger"}}]}
{"op":"mcm","clk":"1005003169","pt":1580585518494,"mc":[{"id":"1.168224338","marketDefinition":{"bspMarket":false,"turnInPlayEnabled":true,"persistenceEnabled":true,"marketBaseRate":5.0,"eventId":"29681722","eventTypeId":"2","numberOfWinners":1,"bettingType":"ODDS","marketType":"SET_WINNER","marketTime":"2020-02-02T11:30:00.000Z","suspendTime":"2020-02-02T11:30:00.000Z","bspReconciled":false,"complete":true,"inPlay":false,"crossMatching":false,"runnersVoidable":false,"numberOfActiveRunners":2,"betDelay":0,"status":"OPEN","runners":[{"status":"ACTIVE","sortPriority":1,"id":8979329,"name":"Emil Ruusuvuori"},{"status":"ACTIVE","sortPriority":2,"id":2397396,"name":"Matthias Bachinger"}],"regulators":["MR_INT"],"countryCode":"FR","discountAllowed":true,"timezone":"UTC","openDate":"2020-02-02T11:30:00.000Z","version":3147124993,"name":"Set 1 Winner","eventName":"Emil Ruusuvuori v Bachinger"}}]}
{"op":"mcm","clk":"1006924687","pt":1580602186352,"mc":[{"id":"1.168224338","rc":[{"batb":[[0,1.01,15.51]],"ltp":0.0,"tv":0.0,"id":2397396},{"batb":[[0,1.01,15.51]],"ltp":0.0,"tv":0.0,"id":8979329}]}]}
{"op":"mcm","clk":"1007043453","pt":1580603726341,"mc":[{"id":"1.168224338","rc":[{"batb":[[0,1.01,16.01]],"ltp":0.0,"tv":0.0,"id":2397396},{"batb":[[0,1.01,16.01]],"ltp":0.0,"tv":0.0,"id":8979329}]}]}
{"op":"mcm","clk":"1007203004","pt":1580607094153,"mc":[{"id":"1.168224338","rc":[{"batb":[[0,1.01,16.02]],"ltp":0.0,"tv":0.0,"id":2397396},{"batb":[[0,1.01,16.02]],"ltp":0.0,"tv":0.0,"id":8979329}]}]}
{"op":"mcm","clk":"1007979835","pt":1580627144088,"mc":[{"id":"1.168224338","rc":[{"batl":[[0,1.81,7.57]],"ltp":0.0,"tv":0.0,"id":8979329}]}]}
{"op":"mcm","clk":"1007980744","pt":1580627161837,"mc":[{"id":"1.168224338","marketDefinition":{"bspMarket":false,"turnInPlayEnabled":true,"persistenceEnabled":true,"marketBaseRate":5.0,"eventId":"29681722","eventTypeId":"2","numberOfWinners":1,"bettingType":"ODDS","marketType":"SET_WINNER","marketTime":"2020-02-02T11:30:00.000Z","suspendTime":"2020-02-02T11:30:00.000Z","bspReconciled":false,"complete":true,"inPlay":false,"crossMatching":true,"runnersVoidable":false,"numberOfActiveRunners":2,"betDelay":0,"status":"OPEN","runners":[{"status":"ACTIVE","sortPriority":1,"id":8979329,"name":"Emil Ruusuvuori"},{"status":"ACTIVE","sortPriority":2,"id":2397396,"name":"Matthias Bachinger"}],"regulators":["MR_INT"],"countryCode":"FR","discountAllowed":true,"timezone":"UTC","openDate":"2020-02-02T11:30:00.000Z","version":3147124993,"name":"Set 1 Winner","eventName":"Emil Ruusuvuori v Bachinger"}}]}
{"op":"mcm","clk":"1008459426","pt":1580635613340,"mc":[{"id":"1.168224338","marketDefinition":{"bspMarket":false,"turnInPlayEnabled":true,"persistenceEnabled":true,"marketBaseRate":5.0,"eventId":"29681722","eventTypeId":"2","numberOfWinners":1,"bettingType":"ODDS","marketType":"SET_WINNER","marketTime":"2020-02-02T11:24:00.000Z","suspendTime":"2020-02-02T11:24:00.000Z","bspReconciled":false,"complete":true,"inPlay":false,"crossMatching":true,"runnersVoidable":false,"numberOfActiveRunners":2,"betDelay":0,"status":"OPEN","runners":[{"status":"ACTIVE","sortPriority":1,"id":8979329,"name":"Emil Ruusuvuori"},{"status":"ACTIVE","sortPriority":2,"id":2397396,"name":"Matthias Bachinger"}],"regulators":["MR_INT"],"countryCode":"FR","discountAllowed":true,"timezone":"UTC","openDate":"2020-02-02T11:30:00.000Z","version":3148345457,"name":"Set 1 Winner","eventName":"Emil Ruusuvuori v Bachinger"}}]}
{"op":"mcm","clk":"1008459775","pt":1580635616342,"mc":[{"id":"1.168224338","marketDefinition":{"bspMarket":false,"turnInPlayEnabled":true,"persistenceEnabled":true,"marketBaseRate":5.0,"eventId":"29681722","eventTypeId":"2","numberOfWinners":1,"bettingType":"ODDS","marketType":"SET_WINNER","marketTime":"2020-02-02T11:24:00.000Z","suspendTime":"2020-02-02T11:24:00.000Z","bspReconciled":false,"complete":true,"inPlay":false,"crossMatching":true,"runnersVoidable":false,"numberOfActiveRunners":2,"betDelay":0,"status":"OPEN","runners":[{"status":"ACTIVE","sortPriority":1,"id":8979329,"name":"Emil Ruusuvuori"},{"status":"ACTIVE","sortPriority":2,"id":2397396,"name":"Matthias Bachinger"}],"regulators":["MR_INT"],"countryCode":"FR","discountAllowed":true,"timezone":"UTC","openDate":"2020-02-02T11:24:00.000Z","version":3148345457,"name":"Set 1 Winner","eventName":"Emil Ruusuvuori v Bachinger"}}]}
{"op":"mcm","clk":"1008879044","pt":1580640413444,"mc":[{"id":"1.168224338","marketDefinition":{"bspMarket":false,"turnInPlayEnabled":true,"persistenceEnabled":true,"marketBaseRate":5.0,"eventId":"29681722","eventTypeId":"2","numberOfWinners":1,"bettingType":"ODDS","marketType":"SET_WINNER","marketTime":"2020-02-02T10:51:00.000Z","suspendTime":"2020-02-02T10:51:00.000Z","bspReconciled":false,"complete":true,"inPlay":false,"crossMatching":true,"runnersVoidable":false,"numberOfActiveRunners":2,"betDelay":0,"status":"OPEN","runners":[{"status":"ACTIVE","sortPriority":1,"id":8979329,"name":"Emil Ruusuvuori"},{"status":"ACTIVE","sortPriority":2,"id":2397396,"name":"Matthias Bachinger"}],"regulators":["MR_INT"],"countryCode":"FR","discountAllowed":true,"timezone":"UTC","openDate":"2020-02-02T11:24:00.000Z","version":3148437423,"name":"Set 1 Winner","eventName":"Emil Ruusuvuori v Bachinger"}}]}
{"op":"mcm","clk":"1008880280","pt":1580640421273,"mc":[{"id":"1.168224338","marketDefinition":{"bspMarket":false,"turnInPlayEnabled":true,"persistenceEnabled":true,"marketBaseRate":5.0,"eventId":"29681722","eventTypeId":"2","numberOfWinners":1,"bettingType":"ODDS","marketType":"SET_WINNER","marketTime":"2020-02-02T10:51:00.000Z","suspendTime":"2020-02-02T10:51:00.000Z","bspReconciled":false,"complete":true,"inPlay":false,"crossMatching":true,"runnersVoidable":false,"numberOfActiveRunners":2,"betDelay":0,"status":"OPEN","runners":[{"status":"ACTIVE","sortPriority":1,"id":8979329,"name":"Emil Ruusuvuori"},{"status":"ACTIVE","sortPriority":2,"id":2397396,"name":"Matthias Bachinger"}],"regulators":["MR_INT"],"countryCode":"FR","discountAllowed":true,"timezone":"UTC","openDate":"2020-02-02T10:51:00.000Z","version":3148437423,"name":"Set 1 Winner","eventName":"Emil Ruusuvuori v Bachinger"}}]}
{"op":"mcm","clk":"1008903211","pt":1580640611123,"mc":[{"id":"1.168224338","rc":[{"trd":[[3.1,0]],"batb":[[0,3.1,21],[1,1.01,16.02]],"ltp":3.1,"tv":0.0,"id":2397396},{"trd":[[1.48,0.01]],"batb":[[0,1.4,49.49],[1,1.01,16.01]],"ltp":1.48,"tv":0.01,"id":8979329}],"tv":0.01}]}
{"op":"mcm","clk":"1008910085","pt":1580640668174,"mc":[{"id":"1.168224338","rc":[{"batb":[[0,1.41,49.18]],"ltp":1.48,"tv":0.01,"id":8979329}]}]}
{"op":"mcm","clk":"1008910880","pt":1580640675263,"mc":[{"id":"1.168224338","rc":[{"batb":[[0,3.1,21.8]],"ltp":3.1,"tv":0.0,"id":2397396},{"batb":[[0,1.42,1.77],[1,1.41,49.18],[2,1.01,16.01]],"ltp":1.48,"tv":0.01,"id":8979329}]}]}
{"op":"mcm","clk":"1008912298","pt":1580640686881,"mc":[{"id":"1.168224338","rc":[{"batb":[[1,1.41,48.94]],"ltp":1.48,"tv":0.01,"id":8979329}]}]}
{"op":"mcm","clk":"1008915480","pt":1580640714233,"mc":[{"id":"1.168224338","marketDefinition":{"bspMarket":false,"turnInPlayEnabled":true,"persistenceEnabled":true,"marketBaseRate":5.0,"eventId":"29681722","eventTypeId":"2","numberOfWinners":1,"bettingType":"ODDS","marketType":"SET_WINNER","marketTime":"2020-02-02T10:48:00.000Z","suspendTime":"2020-02-02T10:48:00.000Z","bspReconciled":false,"complete":true,"inPlay":false,"crossMatching":true,"runnersVoidable":false,"numberOfActiveRunners":2,"betDelay":0,"status":"OPEN","runners":[{"status":"ACTIVE","sortPriority":1,"id":8979329,"name":"Emil Ruusuvuori"},{"status":"ACTIVE","sortPriority":2,"id":2397396,"name":"Matthias Bachinger"}],"regulators":["MR_INT"],"countryCode":"FR","discountAllowed":true,"timezone":"UTC","openDate":"2020-02-02T10:51:00.000Z","version":3148443645,"name":"Set 1 Winner","eventName":"Emil Ruusuvuori v Bachinger"}}]}
{"op":"mcm","clk":"1008915826","pt":1580640717144,"mc":[{"id":"1.168224338","marketDefinition":{"bspMarket":false,"turnInPlayEnabled":true,"persistenceEnabled":true,"marketBaseRate":5.0,"eventId":"29681722","eventTypeId":"2","numberOfWinners":1,"bettingType":"ODDS","marketType":"SET_WINNER","marketTime":"2020-02-02T10:48:00.000Z","suspendTime":"2020-02-02T10:48:00.000Z","bspReconciled":false,"complete":true,"inPlay":false,"crossMatching":true,"runnersVoidable":false,"numberOfActiveRunners":2,"betDelay":0,"status":"OPEN","runners":[{"status":"ACTIVE","sortPriority":1,"id":8979329,"name":"Emil Ruusuvuori"},{"status":"ACTIVE","sortPriority":2,"id":2397396,"name":"Matthias Bachinger"}],"regulators":["MR_INT"],"countryCode":"FR","discountAllowed":true,"timezone":"UTC","openDate":"2020-02-02T10:48:00.000Z","version":3148443645,"name":"Set 1 Winner","eventName":"Emil Ruusuvuori v Bachinger"}}]}
{"op":"mcm","clk":"1008940367","pt":1580640933281,"mc":[{"id":"1.168224338","rc":[{"batb":[[1,3,21],[2,1.01,16.02]],"batl":[[0,3.5,16.8]],"ltp":3.1,"tv":0.0,"id":2397396},{"batb":[[2,1.4,105.02]],"batl":[[0,1.5,42.01],[1,1.81,7.57]],"ltp":1.48,"tv":0.01,"id":8979329}]}]}
{"op":"mcm","clk":"1008970578","pt":1580641185073,"mc":[{"id":"1.168224338","rc":[{"batb":[[0,3,21.8],[1,1.01,16.02],[2,1.01,0]],"ltp":3.1,"tv":0.0,"id":2397396},{"batb":[[1,1.4,105.02],[2,1.01,16.01]],"ltp":1.48,"tv":0.01,"id":8979329}]}]}
{"op":"mcm","clk":"1008970700","pt":1580641186080,"mc":[{"id":"1.168224338","marketDefinition":{"bspMarket":false,"turnInPlayEnabled":true,"persistenceEnabled":true,"marketBaseRate":5.0,"eventId":"29681722","eventTypeId":"2","numberOfWinners":1,"bettingType":"ODDS","marketType":"SET_WINNER","marketTime":"2020-02-02T10:48:00.000Z","suspendTime":"2020-02-02T10:48:00.000Z","bspReconciled":false,"complete":true,"inPlay":true,"crossMatching":true,"runnersVoidable":false,"numberOfActiveRunners":2,"betDelay":3,"status":"OPEN","runners":[{"status":"ACTIVE","sortPriority":1,"id":8979329,"name":"Emil Ruusuvuori"},{"status":"ACTIVE","sortPriority":2,"id":2397396,"name":"Matthias Bachinger"}],"regulators":["MR_INT"],"countryCode":"FR","discountAllowed":true,"timezone":"UTC","openDate":"2020-02-02T10:48:00.000Z","version":3148454350,"name":"Set 1 Winner","eventName":"Emil Ruusuvuori v Bachinger"},"rc":[{"batb":[[0,1.01,15.52],[1,1.01,0]],"ltp":3.1,"tv":0.0,"id":2397396},{"batb":[[0,1.01,15.51],[1,1.4,0],[2,1.01,0]],"ltp":1.48,"tv":0.01,"id":8979329}]}]}
{"op":"mcm","clk":"1008971485","pt":1580641192365,"mc":[{"id":"1.168224338","rc":[{"batb":[[0,2.84,10.54],[1,2.64,12.83],[2,1.01,15.52]],"ltp":3.1,"tv":0.0,"id":2397396},{"batb":[[0,1.47,40.99],[1,1.39,52.24],[2,1.01,15.51]],"ltp":1.48,"tv":0.01,"id":8979329}]}]}
{"op":"mcm","clk":"1008971541","pt":1580641192785,"mc":[{"id":"1.168224338","rc":[{"batb":[[1,2.76,23.53],[2,2.64,12.83]],"batl":[[0,3.2,18.48]],"ltp":3.1,"tv":0.0,"id":2397396},{"batb":[[1,1.45,93.26],[2,1.39,52.24]],"batl":[[0,1.57,42.01]],"ltp":1.48,"tv":0.01,"id":8979329}]}]}
{"op":"mcm","clk":"1008972907","pt":1580641201950,"mc":[{"id":"1.168224338","rc":[{"batb":[[0,2.76,23.53],[1,2.64,12.83],[2,1.01,15.52]],"ltp":3.1,"tv":0.0,"id":2397396},{"batb":[[0,1.45,93.26],[1,1.39,52.24],[2,1.01,15.51]],"ltp":1.48,"tv":0.01,"id":8979329}]}]}
{"op":"mcm","clk":"1008973147","pt":1580641203379,"mc":[{"id":"1.168224338","rc":[{"batb":[[0,1.47,219.08],[1,1.46,192.94],[2,1.45,93.26]],"batl":[[0,1.52,219.09],[1,1.53,156.51],[2,1.57,42.01]],"ltp":1.48,"tv":0.01,"id":8979329}]}]}
{"op":"mcm","clk":"1008973312","pt":1580641204264,"mc":[{"id":"1.168224338","rc":[{"batb":[[0,2.64,12.83],[1,1.01,15.52],[2,1.01,0]],"ltp":3.1,"tv":0.0,"id":2397396},{"batb":[[0,1.39,52.24],[1,1.01,15.51],[2,1.45,0]],"ltp":1.48,"tv":0.01,"id":8979329}]}]}
{"op":"mcm","clk":"1008973484","pt":1580641204988,"mc":[{"id":"1.168224338","rc":[{"batb":[[0,1.39,349.31],[1,1.38,248.69],[2,1.01,15.51]],"batl":[[0,1.58,139.46],[1,1.59,135.94]],"ltp":1.48,"tv":0.01,"id":8979329}]}]}
{"op":"mcm","clk":"1008973646","pt":1580641205958,"mc":[{"id":"1.168224338","rc":[{"batb":[[0,1.39,52.24],[1,1.01,15.51],[2,1.01,0]],"ltp":1.48,"tv":0.01,"id":8979329}]}]}
{"op":"mcm","clk":"1008974280","pt":1580641209372,"mc":[{"id":"1.168224338","rc":[{"batb":[[1,2.52,14.63],[2,1.01,15.52]],"ltp":3.1,"tv":0.0,"id":2397396},{"batb":[[0,1.53,228.01],[1,1.52,163.45],[2,1.46,41.62]],"batl":[[0,1.58,139.46],[1,1.59,135.94]],"ltp":1.48,"tv":0.01,"id":8979329}]}]}
{"op":"mcm","clk":"1008974489","pt":1580641210667,"mc":[{"id":"1.168224338","rc":[{"batb":[[1,2.62,25.21],[2,2.52,14.63]],"batl":[[0,3,21]],"ltp":3.1,"tv":0.0,"id":2397396},{"batb":[[2,1.5,84.02]],"batl":[[2,1.63,42.01]],"ltp":1.48,"tv":0.01,"id":8979329}]}]}
{"op":"mcm","clk":"1008975684","pt":1580641218208,"mc":[{"id":"1.168224338","rc":[{"batb":[[0,1.53,34.86],[1,1.5,84.02],[2,1.46,41.62]],"batl":[[0,1.63,42.01],[1,1.59,0],[2,1.63,0]],"ltp":1.48,"tv":0.01,"id":8979329}]}]}
{"op":"mcm","clk":"1008975840","pt":1580641219165,"mc":[{"id":"1.168224338","rc":[{"batb":[[0,2.62,25.21],[1,2.52,14.63],[2,1.01,15.52]],"ltp":3.1,"tv":0.0,"id":2397396},{"batb":[[0,1.5,84.02],[1,1.46,41.62],[2,1.01,15.51]],"ltp":1.48,"tv":0.01,"id":8979329}]}]}
{"op":"mcm","clk":"1008975903","pt":1580641219667,"mc":[{"id":"1.168224338","rc":[{"batb":[[0,2.52,14.63],[1,1.01,15.52],[2,1.01,0]],"ltp":3.1,"tv":0.0,"id":2397396},{"batb":[[0,1.46,41.62],[1,1.01,15.51],[2,1.01,0]],"ltp":1.48,"tv":0.01,"id":8979329}]}]}
{"op":"mcm","clk":"1008976673","pt":1580641224080,"mc":[{"id":"1.168224338","rc":[{"batb":[[0,1.52,146.61],[1,1.51,167.53],[2,1.46,41.62]],"batl":[[0,1.57,198.78],[1,1.58,138.82]],"ltp":1.48,"tv":0.01,"id":8979329}]}]}
{"op":"mcm","clk":"1008977021","pt":1580641226307,"mc":[{"id":"1.168224338","rc":[{"batb":[[0,1.46,41.62],[1,1.01,15.51],[2,1.46,0]],"ltp":1.48,"tv":0.01,"id":8979329}]}]}
{"op":"mcm","clk":"1008977464","pt":1580641229184,"mc":[{"id":"1.168224338","rc":[{"batb":[[0,1.47,157.06],[1,1.46,234.09],[2,1.01,15.51]],"batl":[[0,1.63,135],[1,1.64,121.67]],"ltp":1.48,"tv":0.01,"id":8979329}]}]}
{"op":"mcm","clk":"1008978513","pt":1580641236299,"mc":[{"id":"1.168224338","rc":[{"batb":[[0,2.86,10.46],[1,2.66,12.59],[2,2.52,14.63]],"ltp":3.1,"tv":0.0,"id":2397396},{"batb":[[2,1.37,55.94]],"batl":[[0,1.52,277.05],[1,1.53,156.14]],"ltp":1.48,"tv":0.01,"id":8979329}]}]}
{"op":"mcm","clk":"1008978565","pt":1580641236674,"mc":[{"id":"1.168224338","rc":[{"batb":[[1,2.78,23.53],[2,2.66,12.59]],"batl":[[0,3.2,18.48]],"ltp":3.1,"tv":0.0,"id":2397396},{"batb":[[2,1.45,93.26]],"batl":[[2,1.56,42.01]],"ltp":1.48,"tv":0.01,"id":8979329}]}]}
{"op":"mcm","clk":"1008980812","pt":1580641250120,"mc":[{"id":"1.168224338","rc":[{"batb":[[0,2.78,23.53],[1,2.66,12.59],[2,1.01,15.52]],"ltp":3.1,"tv":0.0,"id":2397396},{"batb":[[0,1.45,93.26],[1,1.37,55.94],[2,1.01,15.51]],"batl":[[0,1.56,42.01],[1,1.53,0],[2,1.56,0]],"ltp":1.48,"tv":0.01,"id":8979329}]}]}
{"op":"mcm","clk":"1008981174","pt":1580641251748,"mc":[{"id":"1.168224338","rc":[{"batb":[[0,2.66,12.59],[1,1.01,15.52],[2,1.01,0]],"ltp":3.1,"tv":0.0,"id":2397396},{"batb":[[0,1.37,55.94],[1,1.01,15.51],[2,1.01,0]],"ltp":1.48,"tv":0.01,"id":8979329}]}]}
{"op":"mcm","clk":"1008981440","pt":1580641253317,"mc":[{"id":"1.168224338","rc":[{"batb":[[0,2.68,12.27]],"ltp":3.1,"tv":0.0,"id":2397396},{"batb":[[0,1.36,56.97]],"ltp":1.48,"tv":0.01,"id":8979329}]}]}
{"op":"mcm","clk":"1008981994","pt":1580641256748,"mc":[{"id":"1.168224338","rc":[{"batb":[[0,1.45,186.1],[1,1.44,204.38],[2,1.36,56.97]],"batl":[[0,1.5,291.3],[1,1.51,164.18]],"ltp":1.48,"tv":0.01,"id":8979329}]}]}
{"op":"mcm","clk":"1008982326","pt":1580641258945,"mc":[{"id":"1.168224338","rc":[{"batb":[[0,1.36,56.97],[1,1.01,15.51],[2,1.36,0]],"ltp":1.48,"tv":0.01,"id":8979329}]}]}
{"op":"mcm","clk":"1008983033","pt":1580641263169,"mc":[{"id":"1.168224338","rc":[{"batl":[[0,1.59,173.64],[1,1.6,132.71]],"ltp":1.48,"tv":0.01,"id":8979329}]}]}
{"op":"mcm","clk":"1008983300","pt":1580641265251,"mc":[{"id":"1.168224338","rc":[{"batb":[[0,1.54,141.26],[1,1.53,158.98],[2,1.36,56.97]],"ltp":1.48,"tv":0.01,"id":8979329}]}]}
{"op":"mcm","clk":"1008983482","pt":1580641266364,"mc":[{"id":"1.168224338","rc":[{"batb":[[1,2.54,14.16],[2,1.01,15.52]],"ltp":3.1,"tv":0.0,"id":2397396},{"batb":[[2,1.51,36.19]],"ltp":1.48,"tv":0.01,"id":8979329}]}]}
{"op":"mcm","clk":"1008983524","pt":1580641266684,"mc":[{"id":"1.168224338","rc":[{"batb":[[1,2.6,26.05],[2,2.54,14.16]],"batl":[[0,2.98,21]],"ltp":3.1,"tv":0.0,"id":2397396},{"batl":[[2,1.63,42.01]],"ltp":1.48,"tv":0.01,"id":8979329}]}]}
{"op":"mcm","clk":"1008984668","pt":1580641275391,"mc":[{"id":"1.168224338","rc":[{"batb":[[0,2.6,26.05],[1,2.54,14.16],[2,1.01,15.52]],"ltp":3.1,"tv":0.0,"id":2397396},{"batb":[[0,1.5,84.02],[1,1.45,42.72],[2,1.01,15.51]],"batl":[[0,1.63,42.01],[1,1.6,0],[2,1.63,0]],"ltp":1.48,"tv":0.01,"id":8979329}]}]}
{"op":"mcm","clk":"1008984739","pt":1580641275865,"mc":[{"id":"1.168224338","rc":[{"batb":[[0,2.54,14.16],[1,1.01,15.52],[2,1.01,0]],"ltp":3.1,"tv":0.0,"id":2397396},{"batb":[[0,1.45,42.72],[1,1.01,15.51],[2,1.01,0]],"ltp":1.48,"tv":0.01,"id":8979329}]}]}
{"op":"mcm","clk":"1008985025","pt":1580641278079,"mc":[{"id":"1.168224338","rc":[{"batb":[[0,1.48,135.26],[1,1.47,186.88],[2,1.45,42.72]],"batl":[[0,1.64,185.01],[1,1.65,118.93]],"ltp":1.48,"tv":0.01,"id":8979329}]}]}
{"op":"mcm","clk":"1008987379","pt":1580641295329,"mc":[{"id":"1.168224338","rc":[{"batb":[[0,2.56,285.08],[1,2.54,14.16],[2,1.01,15.52]],"ltp":3.1,"tv":0.0,"id":2397396},{"batl":[[0,1.53,280.32],[1,1.54,152.31]],"ltp":1.48,"tv":0.01,"id":8979329}]}]}
{"op":"mcm","clk":"1008987477","pt":1580641295916,"mc":[{"id":"1.168224338","rc":[{"batb":[[0,2.9,25.41],[1,2.64,12.83]],"ltp":3.1,"tv":0.0,"id":2397396}]}]}
{"op":"mcm","clk":"1008987591","pt":1580641296717,"mc":[{"id":"1.168224338","rc":[{"batb":[[1,2.74,23.53],[2,2.64,12.83]],"batl":[[0,3.2,18.48]],"ltp":3.1,"tv":0.0,"id":2397396},{"batb":[[2,1.45,135.99]],"batl":[[2,1.57,42.01]],"ltp":1.48,"tv":0.01,"id":8979329}]}]}
{"op":"mcm","clk":"1008989485","pt":1580641309804,"mc":[{"id":"1.168224338","rc":[{"batb":[[0,2.74,23.53],[1,2.64,12.83],[2,1.01,15.52]],"ltp":3.1,"tv":0.0,"id":2397396},{"batb":[[0,1.45,93.26],[1,1.35,59.09],[2,1.01,15.51]],"batl":[[0,1.57,42.01],[1,1.54,0],[2,1.57,0]],"ltp":1.48,"tv":0.01,"id":8979329}]}]}
{"op":"mcm","clk":"1008989773","pt":1580641312027,"mc":[{"id":"1.168224338","rc":[{"batb":[[0,2.64,12.83],[1,1.01,15.52],[2,1.01,0]],"ltp":3.1,"tv":0.0,"id":2397396},{"batb":[[0,1.35,59.09],[1,1.01,15.51],[2,1.01,0]],"ltp":1.48,"tv":0.01,"id":8979329}]}]}
{"op":"mcm","clk":"1008989881","pt":1580641312813,"mc":[{"id":"1.168224338","rc":[{"batb":[[0,1.37,311.3],[1,1.36,266.82],[2,1.35,59.09]],"batl":[[0,1.62,241.82],[1,1.63,123.92]],"ltp":1.48,"tv":0.01,"id":8979329}]}]}
{"op":"mcm","clk":"1008990067","pt":1580641314190,"mc":[{"id":"1.168224338","rc":[{"batb":[[0,1.35,59.09],[1,1.01,15.51],[2,1.35,0]],"ltp":1.48,"tv":0.01,"id":8979329}]}]}
{"op":"mcm","clk":"1008990382","pt":1580641316530,"mc":[{"id":"1.168224338","rc":[{"batb":[[0,1.56,173.68],[1,1.55,151.32],[2,1.35,59.09]],"ltp":1.48,"tv":0.01,"id":8979329}]}]}
{"op":"mcm","clk":"1008990573","pt":1580641317717,"mc":[{"id":"1.168224338","rc":[{"batb":[[1,2.3,18.49],[2,1.01,15.52]],"ltp":3.1,"tv":0.0,"id":2397396},{"batb":[[2,1.53,34.93]],"ltp":1.48,"tv":0.01,"id":8979329}]}]}
{"op":"mcm","clk":"1008990739","pt":1580641318718,"mc":[{"id":"1.168224338","rc":[{"batb":[[1,2.52,26.89],[2,2.3,18.49]],"batl":[[0,2.86,21.85]],"ltp":3.1,"tv":0.0,"id":2397396},{"batb":[[2,1.53,113.91]],"batl":[[2,1.66,42.01]],"ltp":1.48,"tv":0.01,"id":8979329}]}]}
{"op":"mcm","clk":"1008991058","pt":1580641321021,"mc":[{"id":"1.168224338","rc":[{"batb":[[0,1.53,113.91],[1,1.47,40.84],[2,1.01,15.51]],"batl":[[0,1.66,42.01],[1,1.63,0],[2,1.66,0]],"ltp":1.48,"tv":0.01,"id":8979329}]}]}
{"op":"mcm","clk":"1008992185","pt":1580641329462,"mc":[{"id":"1.168224338","rc":[{"batb":[[0,1.56,173.68],[1,1.55,151.32],[2,1.53,113.91]],"batl":[[0,1.62,241.82],[1,1.63,123.92],[2,1.66,42.01]],"ltp":1.48,"tv":0.01,"id":8979329}]}]}
{"op":"mcm","clk":"1008995471","pt":1580641353378,"mc":[{"id":"1.168224338","rc":[{"batb":[[0,1.53,113.91],[1,1.47,40.84],[2,1.01,15.51]],"batl":[[0,1.66,42.01],[1,1.63,0],[2,1.66,0]],"ltp":1.48,"tv":0.01,"id":8979329}]}]}
{"op":"mcm","clk":"1008995545","pt":1580641353856,"mc":[{"id":"1.168224338","rc":[{"batb":[[0,2.3,18.49],[1,1.01,15.52],[2,2.3,0]],"ltp":3.1,"tv":0.0,"id":2397396},{"batb":[[0,1.47,40.84],[1,1.01,15.51],[2,1.01,0]],"ltp":1.48,"tv":0.01,"id":8979329}]}]}
{"op":"mcm","clk":"1008995881","pt":1580641356387,"mc":[{"id":"1.168224338","rc":[{"batb":[[0,1.49,251.11],[1,1.48,182.47],[2,1.47,40.84]],"batl":[[0,1.77,143.27],[1,1.79,182.32]],"ltp":1.48,"tv":0.01,"id":8979329}]}]}
{"op":"mcm","clk":"1008995911","pt":1580641356605,"mc":[{"id":"1.168224338","rc":[{"batb":[[0,1.47,40.84],[1,1.01,15.51],[2,1.47,0]],"ltp":1.48,"tv":0.01,"id":8979329}]}]}
{"op":"mcm","clk":"1008996196","pt":1580641358783,"mc":[{"id":"1.168224338","rc":[{"batb":[[0,1.59,123.32],[1,1.58,140.45],[2,1.47,40.84]],"batl":[[0,1.64,125.6],[1,1.65,119.16]],"ltp":1.48,"tv":0.01,"id":8979329}]}]}
{"op":"mcm","clk":"1008997144","pt":1580641365907,"mc":[{"id":"1.168224338","rc":[{"batb":[[0,1.47,40.84],[1,1.01,15.51],[2,1.47,0]],"ltp":1.48,"tv":0.01,"id":8979329}]}]}
{"op":"mcm","clk":"1008997625","pt":1580641369328,"mc":[{"id":"1.168224338","rc":[{"batb":[[0,1.49,251.11],[1,1.48,182.47],[2,1.47,40.84]],"batl":[[0,1.77,143.27],[1,1.79,182.32]],"ltp":1.48,"tv":0.01,"id":8979329}]}]}
{"op":"mcm","clk":"1009000401","pt":1580641390028,"mc":[{"id":"1.168224338","rc":[{"batb":[[0,1.47,40.84],[1,1.01,15.51],[2,1.47,0]],"ltp":1.48,"tv":0.01,"id":8979329}]}]}
{"op":"mcm","clk":"1009000813","pt":1580641393023,"mc":[{"id":"1.168224338","rc":[{"batb":[[0,1.7,193.33],[1,1.68,223.79],[2,1.47,40.84]],"ltp":1.48,"tv":0.01,"id":8979329}]}]}
{"op":"mcm","clk":"1009000971","pt":1580641394246,"mc":[{"id":"1.168224338","rc":[{"batb":[[1,1.95,30.53],[2,1.01,15.52]],"ltp":3.1,"tv":0.0,"id":2397396},{"batb":[[2,1.67,25.49]],"ltp":1.48,"tv":0.01,"id":8979329}]}]}
{"op":"mcm","clk":"1009001047","pt":1580641394789,"mc":[{"id":"1.168224338","rc":[{"batb":[[1,2.26,32.77],[2,1.95,30.53]],"batl":[[0,2.54,26.89]],"ltp":3.1,"tv":0.0,"id":2397396},{"batl":[[2,1.8,42.01]],"ltp":1.48,"tv":0.01,"id":8979329}]}]}
{"op":"mcm","clk":"1009001948","pt":1580641400988,"mc":[{"id":"1.168224338","rc":[{"trd":[[1.7,386.66]],"batb":[[0,1.68,223.79],[1,1.67,25.49],[2,1.65,63.85]],"batl":[[0,1.8,42.01],[1,1.79,0],[2,1.8,0]],"ltp":1.7,"tv":386.66,"id":8979329}],"tv":386.67}]}
{"op":"mcm","clk":"1009002301","pt":1580641404004,"mc":[{"id":"1.168224338","rc":[{"batb":[[0,1.7,122.53],[1,1.68,223.79],[2,1.67,25.49]],"batl":[[0,1.76,117.75],[1,1.78,186.05],[2,1.8,42.01]],"ltp":1.7,"tv":386.66,"id":8979329}]}]}
{"op":"mcm","clk":"1009002766","pt":1580641406316,"mc":[{"id":"1.168224338","rc":[{"batb":[[0,2.26,32.77],[1,1.95,30.53],[2,1.01,15.52]],"ltp":3.1,"tv":0.0,"id":2397396},{"batb":[[0,1.65,63.85],[1,1.56,32.02],[2,1.01,15.51]],"batl":[[0,1.8,42.01],[1,1.78,0],[2,1.8,0]],"ltp":1.7,"tv":386.66,"id":8979329}]}]}
{"op":"mcm","clk":"1009002983","pt":1580641407840,"mc":[{"id":"1.168224338","rc":[{"batb":[[0,1.95,30.53],[1,1.01,15.52],[2,1.01,0]],"ltp":3.1,"tv":0.0,"id":2397396},{"batb":[[0,1.56,32.02],[1,1.01,15.51],[2,1.01,0]],"ltp":1.7,"tv":386.66,"id":8979329}]}]}
{"op":"mcm","clk":"1009003658","pt":1580641412305,"mc":[{"id":"1.168224338","rc":[{"batb":[[0,1.74,168.54],[1,1.72,206.44],[2,1.56,32.02]],"batl":[[0,1.81,125.58],[1,1.83,170.2]],"ltp":1.7,"tv":386.66,"id":8979329}]}]}
{"op":"mcm","clk":"1009004064","pt":1580641414531,"mc":[{"id":"1.168224338","rc":[{"batb":[[0,1.56,32.02],[1,1.01,15.51],[2,1.56,0]],"ltp":1.7,"tv":386.66,"id":8979329}]}]}
{"op":"mcm","clk":"1009004464","pt":1580641417536,"mc":[{"id":"1.168224338","rc":[{"batb":[[0,1.58,259.4],[1,1.57,144.71],[2,1.56,32.02]],"batl":[[0,2.04,138.92],[1,2.06,118.84]],"ltp":1.7,"tv":386.66,"id":8979329}]}]}
{"op":"mcm","clk":"1009005340","pt":1580641423346,"mc":[{"id":"1.168224338","rc":[{"batb":[[0,2.54,14.24],[1,2.16,22.5],[2,1.01,15.52]],"batl":[[0,2.78,23.53]],"ltp":3.1,"tv":0.0,"id":2397396},{"batl":[[0,1.64,131.93],[1,1.65,119.37],[2,1.7,42.01]],"ltp":1.7,"tv":386.66,"id":8979329}]}]}
{"op":"mcm","clk":"1009005687","pt":1580641425729,"mc":[{"id":"1.168224338","rc":[{"batb":[[1,2.44,28.57],[2,2.16,22.5]],"ltp":3.1,"tv":0.0,"id":2397396},{"batb":[[2,1.56,106.8]],"ltp":1.7,"tv":386.66,"id":8979329}]}]}
{"op":"mcm","clk":"1009006973","pt":1580641435048,"mc":[{"id":"1.168224338","rc":[{"batb":[[0,2.44,28.57],[1,2.16,22.5],[2,1.01,15.52]],"ltp":3.1,"tv":0.0,"id":2397396},{"batb":[[0,1.56,74.78],[1,1.49,38.95],[2,1.01,15.51]],"batl":[[0,1.7,42.01],[1,1.65,0],[2,1.7,0]],"ltp":1.7,"tv":386.66,"id":8979329}]}]}
{"op":"mcm","clk":"1009007083","pt":1580641435738,"mc":[{"id":"1.168224338","rc":[{"batb":[[0,2.16,22.5],[1,1.01,15.52],[2,1.01,0]],"ltp":3.1,"tv":0.0,"id":2397396},{"batb":[[0,1.49,38.95],[1,1.01,15.51],[2,1.01,0]],"ltp":1.7,"tv":386.66,"id":8979329}]}]}
{"op":"mcm","clk":"1009007960","pt":1580641442356,"mc":[{"id":"1.168224338","rc":[{"batb":[[0,2.78,11.25],[1,2.42,16.13],[2,1.01,15.52]],"ltp":3.1,"tv":0.0,"id":2397396},{"batb":[[0,1.5,191.81],[1,1.49,216.43],[2,1.43,45.24]],"batl":[[0,1.55,190.88],[1,1.56,145.9]],"ltp":1.7,"tv":386.66,"id":8979329}]}]}
{"op":"mcm","clk":"1009008059","pt":1580641442940,"mc":[{"id":"1.168224338","rc":[{"batb":[[1,2.64,25.21],[2,2.42,16.13]],"batl":[[0,3.05,20.16]],"ltp":3.1,"tv":0.0,"id":2397396},{"batb":[[1,1.49,302.13]],"batl":[[2,1.61,42.01]],"ltp":1.7,"tv":386.66,"id":8979329}]}]}
{"op":"mcm","clk":"1009009452","pt":1580641453251,"mc":[{"id":"1.168224338","rc":[{"batb":[[0,2.64,25.21],[1,2.42,16.13],[2,1.01,15.52]],"ltp":3.1,"tv":0.0,"id":2397396},{"batb":[[0,1.49,85.7],[1,1.43,45.24],[2,1.01,15.51]],"batl":[[0,1.61,42.01],[1,1.56,0],[2,1.61,0]],"ltp":1.7,"tv":386.66,"id":8979329}]}]}
{"op":"mcm","clk":"1009009576","pt":1580641454162,"mc":[{"id":"1.168224338","rc":[{"batb":[[0,2.42,16.13],[1,1.01,15.52],[2,1.01,0]],"ltp":3.1,"tv":0.0,"id":2397396},{"batb":[[0,1.43,45.24],[1,1.01,15.51],[2,1.01,0]],"ltp":1.7,"tv":386.66,"id":8979329}]}]}
{"op":"mcm","clk":"1009009832","pt":1580641455759,"mc":[{"id":"1.168224338","rc":[{"batb":[[0,1.44,276.55],[1,1.43,257.14],[2,1.01,15.51]],"batl":[[0,1.68,145.54],[1,1.7,216.59]],"ltp":1.7,"tv":386.66,"id":8979329}]}]}
{"op":"mcm","clk":"1009010268","pt":1580641459090,"mc":[{"id":"1.168224338","rc":[{"batb":[[0,1.43,45.24],[1,1.01,15.51],[2,1.01,0]],"ltp":1.7,"tv":386.66,"id":8979329}]}]}
{"op":"mcm","clk":"1009010723","pt":1580641462161,"mc":[{"id":"1.168224338","rc":[{"batb":[[0,1.44,276.55],[1,1.43,257.14],[2,1.01,15.51]],"batl":[[0,1.49,231.46],[1,1.5,169.33]],"ltp":1.7,"tv":386.66,"id":8979329}]}]}
{"op":"mcm","clk":"1009010875","pt":1580641463275,"mc":[{"id":"1.168224338","rc":[{"batb":[[0,2.98,23.6],[1,2.82,22.69],[2,2.74,11.57]],"batl":[[0,3.3,17.64]],"ltp":3.1,"tv":0.0,"id":2397396},{"batb":[[0,1.44,371.49],[2,1.41,48.94]],"batl":[[2,1.55,42.01]],"ltp":1.7,"tv":386.66,"id":8979329}]}]}
{"op":"mcm","clk":"1009011740","pt":1580641468698,"mc":[{"id":"1.168224338","rc":[{"batb":[[0,2.82,22.69],[1,2.74,11.57],[2,2.3,385.09]],"ltp":3.1,"tv":0.0,"id":2397396},{"batb":[[0,1.44,94.94],[1,1.41,48.94],[2,1.25,505.09]],"batl":[[0,1.55,42.01],[1,1.5,0],[2,1.55,0]],"ltp":1.7,"tv":386.66,"id":8979329}]}]}
{"op":"mcm","clk":"1009011901","pt":1580641469771,"mc":[{"id":"1.168224338","rc":[{"batb":[[0,2.74,11.57],[1,2.3,385.09],[2,1.01,15.52]],"ltp":3.1,"tv":0.0,"id":2397396},{"batb":[[0,1.41,48.94],[1,1.25,505.09],[2,1.01,15.51]],"ltp":1.7,"tv":386.66,"id":8979329}]}]}
{"op":"mcm","clk":"1009012193","pt":1580641471784,"mc":[{"id":"1.168224338","rc":[{"batb":[[0,1.42,140.27],[1,1.41,48.94],[2,1.25,505.09]],"ltp":1.7,"tv":386.66,"id":8979329}]}]}
{"op":"mcm","clk":"1009012564","pt":1580641474381,"mc":[{"id":"1.168224338","rc":[{"batl":[[0,1.46,222.93],[1,1.47,183.69]],"ltp":1.7,"tv":386.66,"id":8979329}]}]}
{"op":"mcm","clk":"1009012705","pt":1580641475379,"mc":[{"id":"1.168224338","rc":[{"batb":[[0,3.1,21.32],[1,2.94,21],[2,2.82,10.78]],"batl":[[0,3.45,16.8]],"ltp":3.1,"tv":0.0,"id":2397396},{"batb":[[1,1.41,374.87],[2,1.32,66.96]],"batl":[[2,1.51,42.01]],"ltp":1.7,"tv":386.66,"id":8979329}]}]}
{"op":"mcm","clk":"1009016057","pt":1580641498126,"mc":[{"id":"1.168224338","rc":[{"batb":[[0,2.94,21],[1,2.82,10.78],[2,2.3,385.09]],"ltp":3.1,"tv":0.0,"id":2397396},{"batb":[[0,1.41,101.66],[1,1.32,66.96],[2,1.25,505.09]],"batl":[[0,1.51,42.01],[1,1.47,0],[2,1.51,0]],"ltp":1.7,"tv":386.66,"id":8979329}]}]}
{"op":"mcm","clk":"1009016317","pt":1580641499934,"mc":[{"id":"1.168224338","rc":[{"batb":[[0,2.82,10.78],[1,2.3,385.09],[2,1.01,15.52]],"ltp":3.1,"tv":0.0,"id":2397396},{"batb":[[0,1.32,66.96],[1,1.25,505.09],[2,1.01,15.51]],"ltp":1.7,"tv":386.66,"id":8979329}]}]}
{"op":"mcm","clk":"1009016566","pt":1580641501316,"mc":[{"id":"1.168224338","rc":[{"batb":[[0,1.33,190.88],[1,1.32,375.68],[2,1.25,505.09]],"batl":[[0,1.54,270.32],[1,1.55,148.97]],"ltp":1.7,"tv":386.66,"id":8979329}]}]}
{"op":"mcm","clk":"1009016643","pt":1580641501800,"mc":[{"id":"1.168224338","rc":[{"batb":[[0,1.32,66.96],[1,1.25,505.09],[2,1.01,15.51]],"ltp":1.7,"tv":386.66,"id":8979329}]}]}
{"op":"mcm","clk":"1009017148","pt":1580641505239,"mc":[{"id":"1.168224338","rc":[{"batb":[[0,1.4,173.54],[1,1.39,239.68],[2,1.32,66.96]],"batl":[[0,1.44,235.51],[1,1.45,194.26]],"ltp":1.7,"tv":386.66,"id":8979329}]}]}
{"op":"mcm","clk":"1009017248","pt":1580641505824,"mc":[{"id":"1.168224338","rc":[{"batl":[[0,1.44,179.8]],"ltp":1.7,"tv":386.66,"id":8979329}]}]}
{"op":"mcm","clk":"1009017700","pt":1580641508405,"mc":[{"id":"1.168224338","rc":[{"batb":[[0,1.32,66.96],[1,1.25,505.09],[2,1.01,15.51]],"ltp":1.7,"tv":386.66,"id":8979329}]}]}
{"op":"mcm","clk":"1009018172","pt":1580641511331,"mc":[{"id":"1.168224338","rc":[{"batb":[[0,1.33,251.48],[1,1.32,375.81],[2,1.25,505.09]],"ltp":1.7,"tv":386.66,"id":8979329}]}]}
{"op":"mcm","clk":"1009018469","pt":1580641513323,"mc":[{"id":"1.168224338","rc":[{"batb":[[1,1.01,15.52],[2,1.01,0]],"ltp":3.1,"tv":0.0,"id":2397396},{"batb":[[2,1.01,15.51]],"ltp":1.7,"tv":386.66,"id":8979329}]}]}
{"op":"mcm","clk":"1009018635","pt":1580641514331,"mc":[{"id":"1.168224338","rc":[{"batb":[[0,3.65,14.01],[1,3.2,19.59],[2,1.01,15.52]],"ltp":3.1,"tv":0.0,"id":2397396},{"batb":[[2,1.22,101.5]],"batl":[[0,1.37,355.66],[1,1.38,238.97]],"ltp":1.7,"tv":386.66,"id":8979329}]}]}
{"op":"mcm","clk":"1009018793","pt":1580641515263,"mc":[{"id":"1.168224338","rc":[{"batb":[[1,3.4,16.8],[2,3.2,19.59]],"batl":[[0,4,13.44]],"ltp":3.1,"tv":0.0,"id":2397396},{"batb":[[0,1.33,378.35]],"batl":[[2,1.42,42.01]],"ltp":1.7,"tv":386.66,"id":8979329}]}]}
{"op":"mcm","clk":"1009020237","pt":1580641524134,"mc":[{"id":"1.168224338","rc":[{"batb":[[0,3.4,16.8],[1,3.2,19.59],[2,2.52,381.46]],"ltp":3.1,"tv":0.0,"id":2397396},{"batb":[[0,1.33,126.87],[1,1.22,101.5],[2,1.2,530.86]],"batl":[[0,1.42,42.01],[1,1.38,0],[2,1.42,0]],"ltp":1.7,"tv":386.66,"id":8979329}]}]}
{"op":"mcm","clk":"1009020575","pt":1580641526373,"mc":[{"id":"1.168224338","rc":[{"batb":[[0,3.2,19.59],[1,2.52,381.46],[2,1.01,15.52]],"ltp":3.1,"tv":0.0,"id":2397396},{"batb":[[0,1.22,101.5],[1,1.2,530.86],[2,1.01,15.51]],"ltp":1.7,"tv":386.66,"id":8979329}]}]}
{"op":"mcm","clk":"1009020664","pt":1580641526854,"mc":[{"id":"1.168224338","rc":[{"batb":[[0,1.24,250.92],[1,1.23,463],[2,1.22,101.5]],"batl":[[0,1.45,288.18],[1,1.46,187.88]],"ltp":1.7,"tv":386.66,"id":8979329}]}]}
{"op":"mcm","clk":"1009021251","pt":1580641530252,"mc":[{"id":"1.168224338","rc":[{"batb":[[1,1.01,15.52],[2,1.01,0]],"ltp":3.1,"tv":0.0,"id":2397396}]}]}
{"op":"mcm","clk":"1009021412","pt":1580641531155,"mc":[{"id":"1.168224338","rc":[{"batl":[[0,1.27,432.76],[1,1.28,346.29]],"ltp":1.7,"tv":386.66,"id":8979329}]}]}
{"op":"mcm","clk":"1009021630","pt":1580641532338,"mc":[{"id":"1.168224338","rc":[{"batb":[[0,4.6,15.66],[1,3.9,23.92],[2,1.01,15.52]],"ltp":3.1,"tv":0.0,"id":2397396}]}]}
{"op":"mcm","clk":"1009021751","pt":1580641533175,"mc":[{"id":"1.168224338","rc":[{"batb":[[1,4.2,12.6],[2,3.9,23.92]],"batl":[[0,5.1,10.08]],"ltp":3.1,"tv":0.0,"id":2397396},{"batb":[[0,1.24,418.96]],"batl":[[2,1.31,42.01]],"ltp":1.7,"tv":386.66,"id":8979329}]}]}
{"op":"mcm","clk":"1009023683","pt":1580641544982,"mc":[{"id":"1.168224338","rc":[{"batb":[[0,4.2,12.6],[1,3.9,23.92],[2,2.9,375.84]],"ltp":3.1,"tv":0.0,"id":2397396},{"batb":[[0,1.24,168.04],[1,1.14,169.8],[2,1.13,629.97]],"batl":[[0,1.31,42.01],[1,1.28,0],[2,1.31,0]],"ltp":1.7,"tv":386.66,"id":8979329}]}]}
{"op":"mcm","clk":"1009023846","pt":1580641545980,"mc":[{"id":"1.168224338","rc":[{"batb":[[0,3.9,23.92],[1,2.9,375.84],[2,1.01,15.52]],"ltp":3.1,"tv":0.0,"id":2397396},{"batb":[[0,1.14,169.8],[1,1.13,629.97],[2,1.01,15.51]],"ltp":1.7,"tv":386.66,"id":8979329}]}]}
{"op":"mcm","clk":"1009024153","pt":1580641547899,"mc":[{"id":"1.168224338","rc":[{"batb":[[0,1.16,535.63],[1,1.15,573.83],[2,1.14,169.8]],"batl":[[0,1.34,384.42],[1,1.35,264.41]],"ltp":1.7,"tv":386.66,"id":8979329}]}]}
{"op":"mcm","clk":"1009024545","pt":1580641550291,"mc":[{"id":"1.168224338","rc":[{"batb":[[0,1.14,169.8],[1,1.13,629.97],[2,1.01,15.51]],"ltp":1.7,"tv":386.66,"id":8979329}]}]}
{"op":"mcm","clk":"1009024799","pt":1580641551886,"mc":[{"id":"1.168224338","rc":[{"batb":[[1,1.01,15.51],[2,1.01,0]],"ltp":1.7,"tv":386.66,"id":8979329}]}]}
{"op":"mcm","clk":"1009025029","pt":1580641553286,"mc":[{"id":"1.168224338","rc":[{"batb":[[0,1.3,343.43],[1,1.29,350.84],[2,1.14,169.8]],"ltp":1.7,"tv":386.66,"id":8979329}]}]}
{"op":"mcm","clk":"1009025195","pt":1580641554389,"mc":[{"id":"1.168224338","rc":[{"batb":[[1,3.3,17.94],[2,2.9,375.84]],"ltp":3.1,"tv":0.0,"id":2397396},{"batb":[[1,1.29,426.69],[2,1.18,131.4]],"ltp":1.7,"tv":386.66,"id":8979329}]}]}
{"op":"mcm","clk":"1009025279","pt":1580641554882,"mc":[{"id":"1.168224338","rc":[{"batb":[[1,3.65,15.12],[2,3.3,17.94]],"batl":[[0,4.3,12.6]],"ltp":3.1,"tv":0.0,"id":2397396},{"batb":[[0,1.3,482.9]],"batl":[[2,1.38,42.01]],"ltp":1.7,"tv":386.66,"id":8979329}]}]}
{"op":"mcm","clk":"1009025407","pt":1580641555681,"mc":[{"id":"1.168224338","rc":[{"batb":[[2,1.18,681.12]],"ltp":1.7,"tv":386.66,"id":8979329}]}]}
{"op":"mcm","clk":"1009027949","pt":1580641571316,"mc":[{"id":"1.168224338","rc":[{"batb":[[0,2.9,375.84],[1,1.01,15.52],[2,3.3,0]],"ltp":3.1,"tv":0.0,"id":2397396},{"batb":[[0,1.3,139.47],[1,1.18,549.72],[2,1.01,15.51]],"batl":[[0,1.38,42.01],[1,1.35,0],[2,1.38,0]],"ltp":1.7,"tv":386.66,"id":8979329}]}]}
{"op":"mcm","clk":"1009028156","pt":1580641572393,"mc":[{"id":"1.168224338","rc":[{"batb":[[0,1.18,549.72],[1,1.01,15.51],[2,1.01,0]],"ltp":1.7,"tv":386.66,"id":8979329}]}]}
{"op":"mcm","clk":"1009028329","pt":1580641573304,"mc":[{"id":"1.168224338","rc":[{"batb":[[0,1.01,15.52],[1,1.01,0]],"ltp":3.1,"tv":0.0,"id":2397396},{"batb":[[0,1.01,15.51],[1,1.01,0]],"ltp":1.7,"tv":386.66,"id":8979329}]}]}
{"op":"mcm","clk":"1009028472","pt":1580641574298,"mc":[{"id":"1.168224338","rc":[{"trd":[[3.6,15.96]],"ltp":3.6,"tv":15.96,"id":2397396},{"trd":[[1.39,41.34]],"batb":[[0,1.39,192.99],[1,1.38,247.96],[2,1.01,15.51]],"batl":[[0,1.43,199.98],[1,1.44,199.82]],"ltp":1.39,"tv":428.0,"id":8979329}],"tv":443.97}]}
{"op":"mcm","clk":"1009028640","pt":1580641575322,"mc":[{"id":"1.168224338","rc":[{"batb":[[0,3.1,19.32],[1,1.01,15.52]],"ltp":3.6,"tv":15.96,"id":2397396},{"batl":[[2,1.48,42.01]],"ltp":1.39,"tv":428.0,"id":8979329}]}]}
{"op":"mcm","clk":"1009028923","pt":1580641576921,"mc":[{"id":"1.168224338","rc":[{"batb":[[1,2.42,381.73],[2,1.01,15.52]],"ltp":3.6,"tv":15.96,"id":2397396},{"batb":[[2,1.22,523]],"ltp":1.39,"tv":428.0,"id":8979329}]}]}
{"op":"mcm","clk":"1009029059","pt":1580641577811,"mc":[{"id":"1.168224338","rc":[{"batl":[[0,3.5,16.8]],"ltp":3.6,"tv":15.96,"id":2397396},{"batb":[[0,1.39,326.73]],"ltp":1.39,"tv":428.0,"id":8979329}]}]}
{"op":"mcm","clk":"1009030586","pt":1580641586250,"mc":[{"id":"1.168224338","rc":[{"batb":[[0,2.42,381.73],[1,1.01,15.52],[2,1.01,0]],"ltp":3.6,"tv":15.96,"id":2397396},{"batb":[[0,1.22,523],[1,1.01,15.51],[2,1.22,0]],"ltp":1.39,"tv":428.0,"id":8979329}]}]}
{"op":"mcm","clk":"1009031097","pt":1580641588966,"mc":[{"id":"1.168224338","rc":[{"batl":[[0,1.55,212.77],[1,1.56,145.51]],"ltp":1.39,"tv":428.0,"id":8979329}]}]}
{"op":"mcm","clk":"1009031312","pt":1580641590130,"mc":[{"id":"1.168224338","rc":[{"batb":[[0,1.01,15.52],[1,1.01,0]],"ltp":3.6,"tv":15.96,"id":2397396},{"batb":[[0,1.01,15.51],[1,1.01,0]],"ltp":1.39,"tv":428.0,"id":8979329}]}]}
{"op":"mcm","clk":"1009031697","pt":1580641592149,"mc":[{"id":"1.168224338","rc":[{"batb":[[0,1.5,167.18],[1,1.49,177.01],[2,1.01,15.51]],"ltp":1.39,"tv":428.0,"id":8979329}]}]}
{"op":"mcm","clk":"1009031921","pt":1580641593339,"mc":[{"id":"1.168224338","rc":[{"batb":[[0,2.68,24.37],[1,1.01,15.52]],"batl":[[0,3,21]],"ltp":3.6,"tv":15.96,"id":2397396},{"batb":[[2,1.48,87.38]],"batl":[[2,1.59,42.01]],"ltp":1.39,"tv":428.0,"id":8979329}]}]}
{"op":"mcm","clk":"1009032047","pt":1580641594139,"mc":[{"id":"1.168224338","rc":[{"batb":[[1,2.12,388.65],[2,1.01,15.52]],"ltp":3.6,"tv":15.96,"id":2397396}]}]}
{"op":"mcm","clk":"1009034017","pt":1580641606025,"mc":[{"id":"1.168224338","rc":[{"batb":[[0,2.12,388.65],[1,1.01,15.52],[2,1.01,0]],"ltp":3.6,"tv":15.96,"id":2397396},{"batb":[[0,1.31,477.51],[1,1.01,15.51],[2,1.48,0]],"ltp":1.39,"tv":428.0,"id":8979329}]}]}
{"op":"mcm","clk":"1009034452","pt":1580641608643,"mc":[{"id":"1.168224338","rc":[{"batb":[[0,1.38,339.65],[1,1.37,258.02],[2,1.31,477.51]],"batl":[[0,1.65,209.08],[1,1.66,116.39]],"ltp":1.39,"tv":428.0,"id":8979329}]}]}
{"op":"mcm","clk":"1009035556","pt":1580641615357,"mc":[{"id":"1.168224338","rc":[{"batb":[[0,1.31,477.51],[1,1.01,15.51],[2,1.31,0]],"ltp":1.39,"tv":428.0,"id":8979329}]}]}
{"op":"mcm","clk":"1009035570","pt":1580641615558,"mc":[{"id":"1.168224338","rc":[{"batb":[[0,1.01,15.51],[1,1.01,0]],"ltp":1.39,"tv":428.0,"id":8979329}]}]}
{"op":"mcm","clk":"1009036043","pt":1580641618389,"mc":[{"id":"1.168224338","rc":[{"batb":[[0,1.59,160.58],[1,1.58,140.6],[2,1.01,15.51]],"ltp":1.39,"tv":428.0,"id":8979329}]}]}
{"op":"mcm","clk":"1009036155","pt":1580641618949,"mc":[{"id":"1.168224338","rc":[{"batb":[[0,2.42,29.41],[1,2.12,388.65],[2,1.01,15.52]],"batl":[[0,2.72,24.37]],"ltp":3.6,"tv":15.96,"id":2397396},{"batb":[[2,1.57,73.1]],"batl":[[2,1.69,42.01]],"ltp":1.39,"tv":428.0,"id":8979329}]}]}
{"op":"mcm","clk":"1009036920","pt":1580641623792,"mc":[{"id":"1.168224338","rc":[{"batb":[[1,2.22,20.46],[2,2.12,388.65]],"ltp":3.6,"tv":15.96,"id":2397396}]}]}
{"op":"mcm","clk":"1009047883","pt":1580641694633,"mc":[{"id":"1.168224338","rc":[{"batb":[[0,1.57,73.1],[1,1.48,39.18],[2,1.34,465.43]],"batl":[[0,1.69,42.01],[1,1.66,0],[2,1.69,0]],"ltp":1.39,"tv":428.0,"id":8979329}]}]}
{"op":"mcm","clk":"1009048132","pt":1580641696237,"mc":[{"id":"1.168224338","rc":[{"batb":[[0,2.22,20.46],[1,2.12,388.65],[2,1.01,15.52]],"ltp":3.6,"tv":15.96,"id":2397396},{"batb":[[0,1.48,39.18],[1,1.34,465.43],[2,1.01,15.51]],"ltp":1.39,"tv":428.0,"id":8979329}]}]}
{"op":"mcm","clk":"1009048467","pt":1580641698645,"mc":[{"id":"1.168224338","rc":[{"batb":[[1,1.01,15.51],[2,1.01,0]],"ltp":1.39,"tv":428.0,"id":8979329}]}]}
{"op":"mcm","clk":"1009048718","pt":1580641700356,"mc":[{"id":"1.168224338","rc":[{"batb":[[0,1.62,162.76],[1,1.61,131.08],[2,1.48,39.18]],"batl":[[0,1.68,166.67],[1,1.7,216.05]],"ltp":1.39,"tv":428.0,"id":8979329}]}]}
{"op":"mcm","clk":"1009048840","pt":1580641701270,"mc":[{"id":"1.168224338","rc":[{"batb":[[0,1.61,131.08],[1,1.48,39.18],[2,1.01,15.51]],"ltp":1.39,"tv":428.0,"id":8979329}]}]}
{"op":"mcm","clk":"1009049086","pt":1580641702740,"mc":[{"id":"1.168224338","rc":[{"batb":[[0,1.48,39.18],[1,1.38,448.45]],"ltp":1.39,"tv":428.0,"id":8979329}]}]}
{"op":"mcm","clk":"1009049540","pt":1580641705758,"mc":[{"id":"1.168224338","rc":[{"batb":[[0,1.51,198.94],[1,1.5,172.87],[2,1.48,39.18]],"batl":[[0,1.82,156.6],[1,1.84,167.15]],"ltp":1.39,"tv":428.0,"id":8979329}]}]}
{"op":"mcm","clk":"1009051127","pt":1580641716380,"mc":[{"id":"1.168224338","rc":[{"batb":[[0,2.78,11.17],[1,2.46,15.58],[2,2.12,388.65]],"ltp":3.6,"tv":15.96,"id":2397396},{"batl":[[0,1.56,167.92],[1,1.57,142.69]],"ltp":1.39,"tv":428.0,"id":8979329}]}]}
{"op":"mcm","clk":"1009051232","pt":1580641717170,"mc":[{"id":"1.168224338","rc":[{"batb":[[1,2.6,26.05],[2,2.46,15.58]],"batl":[[0,2.94,21]],"ltp":3.6,"tv":15.96,"id":2397396},{"batb":[[0,1.51,281.28]],"batl":[[2,1.63,42.01]],"ltp":1.39,"tv":428.0,"id":8979329}]}]}
{"op":"mcm","clk":"1009053020","pt":1580641729381,"mc":[{"id":"1.168224338","rc":[{"batb":[[0,2.6,26.05],[1,2.46,15.58],[2,2.12,388.65]],"ltp":3.6,"tv":15.96,"id":2397396},{"batb":[[0,1.51,82.34],[1,1.44,44.14],[2,1.31,477.51]],"batl":[[0,1.63,42.01],[1,1.57,0],[2,1.63,0]],"ltp":1.39,"tv":428.0,"id":8979329}]}]}
{"op":"mcm","clk":"1009053131","pt":1580641730231,"mc":[{"id":"1.168224338","rc":[{"batb":[[0,2.46,15.58],[1,2.12,388.65],[2,1.01,15.52]],"ltp":3.6,"tv":15.96,"id":2397396},{"batb":[[0,1.44,44.14],[1,1.31,477.51],[2,1.01,15.51]],"ltp":1.39,"tv":428.0,"id":8979329}]}]}
{"op":"mcm","clk":"1009054069","pt":1580641736381,"mc":[{"id":"1.168224338","rc":[{"batb":[[0,1.53,163.31],[1,1.52,163.95],[2,1.44,44.14]],"batl":[[0,1.58,128.57],[1,1.59,136.37]],"ltp":1.39,"tv":428.0,"id":8979329}]}]}
{"op":"mcm","clk":"1009054214","pt":1580641737392,"mc":[{"id":"1.168224338","rc":[{"batb":[[0,1.44,44.14],[1,1.31,477.51],[2,1.01,15.51]],"ltp":1.39,"tv":428.0,"id":8979329}]}]}
{"op":"mcm","clk":"1009054733","pt":1580641740698,"mc":[{"id":"1.168224338","rc":[{"batb":[[0,1.46,165.37],[1,1.45,199.16],[2,1.44,44.14]],"batl":[[0,1.68,192.8],[1,1.7,216.66]],"ltp":1.39,"tv":428.0,"id":8979329}]}]}
{"op":"mcm","clk":"1009055455","pt":1580641745481,"mc":[{"id":"1.168224338","rc":[{"batl":[[0,1.5,128.45],[1,1.51,166.12]],"ltp":1.39,"tv":428.0,"id":8979329}]}]}
{"op":"mcm","clk":"1009055733","pt":1580641747111,"mc":[{"id":"1.168224338","rc":[{"batb":[[0,2.94,24.31],[1,2.74,23.53],[2,2.7,12.2]],"batl":[[0,3.1,19.32]],"ltp":3.6,"tv":15.96,"id":2397396},{"batb":[[0,1.46,256.11]],"batl":[[2,1.57,42.01]],"ltp":1.39,"tv":428.0,"id":8979329}]}]}
{"op":"mcm","clk":"1009057604","pt":1580641758141,"mc":[{"id":"1.168224338","rc":[{"batb":[[0,2.7,12.2],[1,2.12,388.65],[2,1.01,15.52]],"ltp":3.6,"tv":15.96,"id":2397396},{"batb":[[0,1.41,48.31],[1,1.31,477.51],[2,1.01,15.51]],"ltp":1.39,"tv":428.0,"id":8979329}]}]}
{"op":"mcm","clk":"1009058159","pt":1580641761319,"mc":[{"id":"1.168224338","rc":[{"batb":[[0,1.43,174.62],[1,1.42,218.24],[2,1.41,48.31]],"batl":[[0,1.57,134.54],[1,1.58,139.76]],"ltp":1.39,"tv":428.0,"id":8979329}]}]}
{"op":"mcm","clk":"1009058793","pt":1580641765343,"mc":[{"id":"1.168224338","rc":[{"batb":[[1,1.01,15.52],[2,1.01,0]],"ltp":3.6,"tv":15.96,"id":2397396}]}]}
{"op":"mcm","clk":"1009059099","pt":1580641767211,"mc":[{"id":"1.168224338","rc":[{"batb":[[0,3.05,21.72],[1,2.88,25.65],[2,2.84,22.69]],"batl":[[0,3.2,18.48]],"ltp":3.6,"tv":15.96,"id":2397396},{"batb":[[0,1.44,94.94],[1,1.43,174.62],[2,1.42,218.24]],"batl":[[0,1.47,173.87],[1,1.48,179.62],[2,1.53,83.85]],"ltp":1.39,"tv":428.0,"id":8979329}]}]}
{"op":"mcm","clk":"1009060808","pt":1580641778181,"mc":[{"id":"1.168224338","rc":[{"batb":[[0,2.88,25.65],[1,2.3,385.09],[2,1.01,15.52]],"ltp":3.6,"tv":15.96,"id":2397396},{"batb":[[0,1.4,50.83],[1,1.25,505.09],[2,1.01,15.51]],"ltp":1.39,"tv":428.0,"id":8979329}]}]}
{"op":"mcm","clk":"1009061277","pt":1580641781357,"mc":[{"id":"1.168224338","rc":[{"batb":[[0,1.41,307.31],[1,1.4,284.75],[2,1.25,505.09]],"batl":[[0,1.51,255.41],[1,1.52,161.08]],"ltp":1.39,"tv":428.0,"id":8979329}]}]}
{"op":"mcm","clk":"1009062150","pt":1580641787363,"mc":[{"id":"1.168224338","rc":[{"batb":[[0,2.94,21],[1,2.88,25.65],[2,2.3,385.09]],"batl":[[0,3.35,17.64]],"ltp":3.6,"tv":15.96,"id":2397396},{"batb":[[0,1.42,99.98],[1,1.41,307.31],[2,1.4,284.75]],"batl":[[0,1.46,280.48],[1,1.47,183.78],[2,1.52,42.01]],"ltp":1.39,"tv":428.0,"id":8979329}]}]}
{"op":"mcm","clk":"1009062270","pt":1580641788162,"mc":[{"id":"1.168224338","rc":[{"batb":[[0,3.15,20.3],[1,2.94,21],[2,2.86,10.46]],"ltp":3.6,"tv":15.96,"id":2397396}]}]}
{"op":"mcm","clk":"1009065194","pt":1580641808971,"mc":[{"id":"1.168224338","rc":[{"batb":[[0,2.94,21],[1,2.86,10.46],[2,2.3,385.09]],"ltp":3.6,"tv":15.96,"id":2397396},{"batb":[[1,1.3,71.52],[2,1.25,505.09]],"batl":[[0,1.52,42.01],[1,1.47,0],[2,1.52,0]],"ltp":1.39,"tv":428.0,"id":8979329}]}]}
{"op":"mcm","clk":"1009065383","pt":1580641810192,"mc":[{"id":"1.168224338","rc":[{"batb":[[0,2.86,10.46],[1,2.3,385.09],[2,1.01,15.52]],"ltp":3.6,"tv":15.96,"id":2397396},{"batb":[[0,1.3,71.52],[1,1.25,505.09],[2,1.01,15.51]],"ltp":1.39,"tv":428.0,"id":8979329}]}]}
{"op":"mcm","clk":"1009065565","pt":1580641811392,"mc":[{"id":"1.168224338","rc":[{"batb":[[0,1.32,211.78],[1,1.31,322.85],[2,1.3,71.52]],"batl":[[0,1.54,248.47],[1,1.55,149.58]],"ltp":1.39,"tv":428.0,"id":8979329}]}]}
{"op":"mcm","clk":"1009065706","pt":1580641812299,"mc":[{"id":"1.168224338","rc":[{"batb":[[0,2.88,10.31]],"ltp":3.6,"tv":15.96,"id":2397396},{"batb":[[0,1.3,71.52],[1,1.25,505.09],[2,1.01,15.51]],"ltp":1.39,"tv":428.0,"id":8979329}]}]}
{"op":"mcm","clk":"1009066160","pt":1580641815402,"mc":[{"id":"1.168224338","rc":[{"batb":[[0,1.49,151.79],[1,1.48,182.69],[2,1.3,71.52]],"ltp":1.39,"tv":428.0,"id":8979329}]}]}
{"op":"mcm","clk":"1009066286","pt":1580641816096,"mc":[{"id":"1.168224338","rc":[{"batb":[[1,2.66,12.51],[2,2.3,385.09]],"ltp":3.6,"tv":15.96,"id":2397396},{"batb":[[2,1.46,42.33]],"ltp":1.39,"tv":428.0,"id":8979329}]}]}
{"op":"mcm","clk":"1009066462","pt":1580641817232,"mc":[{"id":"1.168224338","rc":[{"batb":[[1,2.7,24.37],[2,2.66,12.51]],"batl":[[0,3,21]],"ltp":3.6,"tv":15.96,"id":2397396},{"batb":[[1,1.48,270.07]],"batl":[[2,1.59,42.01]],"ltp":1.39,"tv":428.0,"id":8979329}]}]}
{"op":"mcm","clk":"1009067746","pt":1580641826309,"mc":[{"id":"1.168224338","rc":[{"batb":[[0,2.66,12.51],[1,2.3,385.09],[2,1.01,15.52]],"ltp":3.6,"tv":15.96,"id":2397396},{"batb":[[0,1.37,55.47],[1,1.28,485.89],[2,1.01,15.51]],"ltp":1.39,"tv":428.0,"id":8979329}]}]}
{"op":"mcm","clk":"1009068610","pt":1580641833189,"mc":[{"id":"1.168224338","rc":[{"batb":[[0,1.47,172.89],[1,1.46,193.55],[2,1.37,55.47]],"batl":[[0,1.52,266.73],[1,1.53,157.05]],"ltp":1.39,"tv":428.0,"id":8979329}]}]}
{"op":"mcm","clk":"1009068997","pt":1580641836006,"mc":[{"id":"1.168224338","rc":[{"batb":[[0,1.37,55.47],[1,1.28,485.89],[2,1.01,15.51]],"ltp":1.39,"tv":428.0,"id":8979329}]}]}
{"op":"mcm","clk":"1009069366","pt":1580641838856,"mc":[{"id":"1.168224338","rc":[{"batb":[[0,1.4,154.99],[1,1.39,240.31],[2,1.37,55.47]],"batl":[[0,1.61,169.98],[1,1.62,127.51]],"ltp":1.39,"tv":428.0,"id":8979329}]}]}
{"op":"mcm","clk":"1009070835","pt":1580641849322,"mc":[{"id":"1.168224338","rc":[{"batl":[[0,1.44,255.84],[1,1.45,194.8]],"ltp":1.39,"tv":428.0,"id":8979329}]}]}
{"op":"mcm","clk":"1009070959","pt":1580641850223,"mc":[{"id":"1.168224338","rc":[{"batb":[[0,3.3,18.1],[1,2.92,24.86],[2,2.3,385.09]],"ltp":3.6,"tv":15.96,"id":2397396}]}]}
{"op":"mcm","clk":"1009071068","pt":1580641851136,"mc":[{"id":"1.168224338","rc":[{"batb":[[1,2.98,21],[2,2.92,24.86]],"batl":[[0,3.4,16.8]],"ltp":3.6,"tv":15.96,"id":2397396},{"batb":[[0,1.4,260.01]],"batl":[[2,1.5,42.01]],"ltp":1.39,"tv":428.0,"id":8979329}]}]}
{"op":"mcm","clk":"1009071130","pt":1580641851523,"mc":[{"id":"1.168224338","rc":[{"batb":[[1,2.92,24.86],[2,2.3,385.09]],"ltp":3.6,"tv":15.96,"id":2397396}]}]}
{"op":"mcm","clk":"1009071410","pt":1580641853345,"mc":[{"id":"1.168224338","rc":[{"batb":[[1,3,21],[2,2.92,24.86]],"ltp":3.6,"tv":15.96,"id":2397396}]}]}
{"op":"mcm","clk":"1009072998","pt":1580641864373,"mc":[{"id":"1.168224338","rc":[{"batb":[[0,3,21],[1,2.92,24.86],[2,2.3,385.09]],"ltp":3.6,"tv":15.96,"id":2397396},{"batb":[[0,1.4,105.02],[1,1.26,84.03],[2,1.23,516.48]],"batl":[[0,1.5,42.01],[1,1.45,0],[2,1.5,0]],"ltp":1.39,"tv":428.0,"id":8979329}]}]}
{"op":"mcm","clk":"1009073245","pt":1580641866281,"mc":[{"id":"1.168224338","rc":[{"batb":[[0,2.92,24.86],[1,2.3,385.09],[2,1.01,15.52]],"ltp":3.6,"tv":15.96,"id":2397396},{"batb":[[0,1.26,84.03],[1,1.23,516.48],[2,1.01,15.51]],"ltp":1.39,"tv":428.0,"id":8979329}]}]}
{"op":"mcm","clk":"1009073405","pt":1580641867362,"mc":[{"id":"1.168224338","rc":[{"batb":[[1,2.9,25.26],[2,2.3,385.09]],"ltp":3.6,"tv":15.96,"id":2397396}]}]}
{"op":"mcm","clk":"1009073437","pt":1580641867578,"mc":[{"id":"1.168224338","rc":[{"batb":[[0,2.9,25.26],[1,2.3,385.09],[2,1.01,15.52]],"ltp":3.6,"tv":15.96,"id":2397396},{"batb":[[0,1.26,83.25]],"ltp":1.39,"tv":428.0,"id":8979329}]}]}
{"op":"mcm","clk":"1009073810","pt":1580641870195,"mc":[{"id":"1.168224338","rc":[{"batb":[[0,1.37,329.94],[1,1.36,268.56],[2,1.26,83.25]],"batl":[[0,1.41,167.55],[1,1.42,213.83]],"ltp":1.39,"tv":428.0,"id":8979329}]}]}
{"op":"mcm","clk":"1009074189","pt":1580641872600,"mc":[{"id":"1.168224338","rc":[{"batb":[[0,1.26,83.25],[1,1.23,516.48],[2,1.01,15.51]],"ltp":1.39,"tv":428.0,"id":8979329}]}]}
{"op":"mcm","clk":"1009074593","pt":1580641875495,"mc":[{"id":"1.168224338","rc":[{"batb":[[0,1.29,199.26],[1,1.28,366.15],[2,1.26,83.25]],"batl":[[0,1.53,133.03],[1,1.54,153.96]],"ltp":1.39,"tv":428.0,"id":8979329}]}]}
{"op":"mcm","clk":"1009074944","pt":1580641877931,"mc":[{"id":"1.168224338","rc":[{"batb":[[1,1.01,15.52],[2,1.01,0]],"ltp":3.6,"tv":15.96,"id":2397396}]}]}
{"op":"mcm","clk":"1009075315","pt":1580641880308,"mc":[{"id":"1.168224338","rc":[{"batl":[[0,1.32,280.44],[1,1.33,288.16]],"ltp":1.39,"tv":428.0,"id":8979329}]}]}
{"op":"mcm","clk":"1009075490","pt":1580641881182,"mc":[{"id":"1.168224338","rc":[{"batb":[[0,4.1,20.93],[1,3.65,15.12],[2,3.4,16.84]],"batl":[[0,4.2,12.6]],"ltp":3.6,"tv":15.96,"id":2397396},{"batb":[[0,1.3,139.47],[1,1.29,199.26],[2,1.28,366.15]],"batl":[[2,1.37,42.01]],"ltp":1.39,"tv":428.0,"id":8979329}]}]}
{"op":"mcm","clk":"1009077540","pt":1580641894403,"mc":[{"id":"1.168224338","rc":[{"batb":[[0,3.4,16.84],[1,2.72,378.25],[2,1.01,15.52]],"ltp":3.6,"tv":15.96,"id":2397396},{"batb":[[0,1.16,576.13],[1,1.15,156.03],[2,1.01,15.51]],"ltp":1.39,"tv":428.0,"id":8979329}]}]}
{"op":"mcm","clk":"1009078283","pt":1580641899116,"mc":[{"id":"1.168224338","rc":[{"batb":[[0,1.26,444.29],[1,1.25,426.3],[2,1.16,576.13]],"batl":[[0,1.29,171.11],[1,1.3,326.12]],"ltp":1.39,"tv":428.0,"id":8979329}]}]}
{"op":"mcm","clk":"1009078753","pt":1580641902138,"mc":[{"id":"1.168224338","rc":[{"batb":[[0,1.16,576.13],[1,1.15,156.03],[2,1.01,15.51]],"ltp":1.39,"tv":428.0,"id":8979329}]}]}
{"op":"mcm","clk":"1009079230","pt":1580641905001,"mc":[{"id":"1.168224338","rc":[{"batb":[[0,1.18,165.76],[1,1.17,662.72],[2,1.16,576.13]],"batl":[[0,1.42,199.37],[1,1.43,207.2]],"ltp":1.39,"tv":428.0,"id":8979329}]}]}
{"op":"mcm","clk":"1009079653","pt":1580641907228,"mc":[{"id":"1.168224338","rc":[{"batb":[[0,1.16,576.13],[1,1.15,156.03],[2,1.01,15.51]],"ltp":1.39,"tv":428.0,"id":8979329}]}]}
{"op":"mcm","clk":"1009080013","pt":1580641909349,"mc":[{"id":"1.168224338","rc":[{"batb":[[0,1.15,156.03],[1,1.01,15.51],[2,1.01,0]],"ltp":1.39,"tv":428.0,"id":8979329}]}]}
{"op":"mcm","clk":"1009080191","pt":1580641910244,"mc":[{"id":"1.168224338","rc":[{"batb":[[0,1.38,267.57],[1,1.37,258.6],[2,1.15,156.03]],"ltp":1.39,"tv":428.0,"id":8979329}]}]}
{"op":"mcm","clk":"1009080408","pt":1580641911365,"mc":[{"id":"1.168224338","rc":[{"batb":[[1,3.1,19.32],[2,2.88,10.39]],"batl":[[0,3.5,16.8]],"ltp":3.6,"tv":15.96,"id":2397396},{"batb":[[0,1.39,107.54],[1,1.38,267.57],[2,1.37,258.6]],"batl":[[2,1.47,42.01]],"ltp":1.39,"tv":428.0,"id":8979329}]}]}
{"op":"mcm","clk":"1009083165","pt":1580641928363,"mc":[{"id":"1.168224338","rc":[{"batb":[[0,2.88,10.39],[1,2.72,378.25],[2,1.01,15.52]],"ltp":3.6,"tv":15.96,"id":2397396},{"batb":[[0,1.22,627.64],[1,1.01,15.51],[2,1.37,0]],"ltp":1.39,"tv":428.0,"id":8979329}]}]}
{"op":"mcm","clk":"1009083501","pt":1580641930746,"mc":[{"id":"1.168224338","rc":[{"batb":[[0,1.24,490.59],[1,1.23,472.78],[2,1.22,627.64]],"batl":[[0,1.55,216.18],[1,1.56,146.21]],"ltp":1.39,"tv":428.0,"id":8979329}]}]}
{"op":"mcm","clk":"1009084195","pt":1580641935372,"mc":[{"id":"1.168224338","rc":[{"batb":[[2,1.22,104.65]],"ltp":1.39,"tv":428.0,"id":8979329}]}]}
{"op":"mcm","clk":"1009084372","pt":1580641936390,"mc":[{"id":"1.168224338","rc":[{"batb":[[0,4.7,14.95],[1,3.45,15.89],[2,2.88,10.39]],"ltp":3.6,"tv":15.96,"id":2397396},{"batl":[[0,1.27,223.8],[1,1.28,353.61]],"ltp":1.39,"tv":428.0,"id":8979329}]}]}
{"op":"mcm","clk":"1009084481","pt":1580641937178,"mc":[{"id":"1.168224338","rc":[{"batb":[[1,4.1,13.44],[2,3.45,15.89]],"batl":[[0,4.8,10.92]],"ltp":3.6,"tv":15.96,"id":2397396},{"batb":[[0,1.25,168.04],[1,1.24,490.59],[2,1.23,472.78]],"batl":[[2,1.32,42.01]],"ltp":1.39,"tv":428.0,"id":8979329}]}]}
{"op":"mcm","clk":"1009084600","pt":1580641937757,"mc":[{"id":"1.168224338","rc":[{"batb":[[1,3.45,15.89],[2,2.72,378.25]],"ltp":3.6,"tv":15.96,"id":2397396}]}]}
{"op":"mcm","clk":"1009084789","pt":1580641939085,"mc":[{"id":"1.168224338","rc":[{"trd":[[1.27,36.96]],"batl":[[0,1.27,205.32]],"ltp":1.27,"tv":464.97,"id":8979329}],"tv":480.94}]}
{"op":"mcm","clk":"1009084995","pt":1580641940307,"mc":[{"id":"1.168224338","rc":[{"batb":[[1,4.2,12.6],[2,3.45,15.89]],"ltp":3.6,"tv":15.96,"id":2397396}]}]}
{"op":"mcm","clk":"1009085445","pt":1580641943257,"mc":[{"id":"1.168224338","rc":[{"batl":[[0,1.27,234.83]],"ltp":1.27,"tv":464.97,"id":8979329}]}]}
{"op":"mcm","clk":"1009086760","pt":1580641952178,"mc":[{"id":"1.168224338","rc":[{"batb":[[0,3.45,15.89],[1,2.72,378.25],[2,1.01,15.52]],"ltp":3.6,"tv":15.96,"id":2397396},{"batb":[[0,1.14,627.92],[1,1.07,339.75],[2,1.01,15.51]],"ltp":1.27,"tv":464.97,"id":8979329}]}]}
{"op":"mcm","clk":"1009086862","pt":1580641952921,"mc":[{"id":"1.168224338","rc":[{"batb":[[1,1.01,15.52],[2,1.01,0]],"ltp":3.6,"tv":15.96,"id":2397396},{"batb":[[0,1.07,339.75],[1,1.01,15.51],[2,1.01,0]],"ltp":1.27,"tv":464.97,"id":8979329}]}]}
{"op":"mcm","clk":"1009087236","pt":1580641955180,"mc":[{"id":"1.168224338","rc":[{"batb":[[0,1.1,303.73],[1,1.09,868.93],[2,1.07,339.75]],"batl":[[0,1.42,308.11],[1,1.43,206.26]],"ltp":1.27,"tv":464.97,"id":8979329}]}]}
{"op":"mcm","clk":"1009087561","pt":1580641957193,"mc":[{"id":"1.168224338","rc":[{"batb":[[0,1.07,339.75],[1,1.01,15.51],[2,1.07,0]],"ltp":1.27,"tv":464.97,"id":8979329}]}]}
{"op":"mcm","clk":"1009088071","pt":1580641960384,"mc":[{"id":"1.168224338","rc":[{"batb":[[0,1.21,416.79],[1,1.2,556.65],[2,1.07,339.75]],"batl":[[0,1.24,466.98],[1,1.25,399.45]],"ltp":1.27,"tv":464.97,"id":8979329}]}]}
{"op":"mcm","clk":"1009088117","pt":1580641960695,"mc":[{"id":"1.168224338","rc":[{"batb":[[0,1.07,339.75],[1,1.01,15.51],[2,1.07,0]],"ltp":1.27,"tv":464.97,"id":8979329}]}]}
{"op":"mcm","clk":"1009088345","pt":1580641962184,"mc":[{"id":"1.168224338","rc":[{"batb":[[1,2.9,375.84],[2,1.01,15.52]],"ltp":3.6,"tv":15.96,"id":2397396},{"batb":[[0,1.13,629.97],[1,1.07,339.75],[2,1.01,15.51]],"ltp":1.27,"tv":464.97,"id":8979329}]}]}
{"op":"mcm","clk":"1009088478","pt":1580641963079,"mc":[{"id":"1.168224338","rc":[{"batb":[[1,1.01,15.52],[2,1.01,0]],"ltp":3.6,"tv":15.96,"id":2397396},{"batb":[[0,1.07,339.75],[1,1.01,15.51],[2,1.01,0]],"ltp":1.27,"tv":464.97,"id":8979329}]}]}
{"op":"mcm","clk":"1009088742","pt":1580641964680,"mc":[{"id":"1.168224338","rc":[{"batb":[[0,1.1,311.76],[1,1.09,860.83],[2,1.07,339.75]],"batl":[[0,1.42,302.13],[1,1.43,206.25]],"ltp":1.27,"tv":464.97,"id":8979329}]}]}
{"op":"mcm","clk":"1009088950","pt":1580641966003,"mc":[{"id":"1.168224338","rc":[{"batb":[[0,1.07,339.75],[1,1.01,15.51],[2,1.07,0]],"ltp":1.27,"tv":464.97,"id":8979329}]}]}
{"op":"mcm","clk":"1009089504","pt":1580641969387,"mc":[{"id":"1.168224338","rc":[{"batb":[[1,3.2,18.48],[2,3.15,19.32]],"ltp":3.6,"tv":15.96,"id":2397396},{"batb":[[0,1.38,157.44],[1,1.37,257.38],[2,1.07,339.75]],"batl":[[2,1.46,42.01]],"ltp":1.27,"tv":464.97,"id":8979329}]}]}
{"op":"mcm","clk":"1009089569","pt":1580641969811,"mc":[{"id":"1.168224338","rc":[{"batb":[[1,3.15,19.32],[2,2.9,25.41]],"batl":[[0,3.6,15.96]],"ltp":3.6,"tv":15.96,"id":2397396},{"batb":[[0,1.38,267.51],[2,1.35,60.03]],"ltp":1.27,"tv":464.97,"id":8979329}]}]}
{"op":"mcm","clk":"1009092560","pt":1580641988223,"mc":[{"id":"1.168224338","rc":[{"batb":[[0,2.9,25.41],[1,2.38,382.3],[2,1.01,15.52]],"ltp":3.6,"tv":15.96,"id":2397396},{"batb":[[0,1.23,516.48],[1,1.21,105.36],[2,1.01,15.51]],"ltp":1.27,"tv":464.97,"id":8979329}]}]}
{"op":"mcm","clk":"1009093019","pt":1580641991104,"mc":[{"id":"1.168224338","rc":[{"batb":[[0,1.24,363.49],[1,1.23,986.1],[2,1.21,105.36]],"batl":[[0,1.54,148.9],[1,1.55,150.19]],"ltp":1.27,"tv":464.97,"id":8979329}]}]}
{"op":"mcm","clk":"1009096621","pt":1580642015261,"mc":[{"id":"1.168224338","rc":[{"batb":[[1,1.01,15.52],[2,1.01,0]],"ltp":3.6,"tv":15.96,"id":2397396},{"batb":[[1,1.23,469.62]],"batl":[[0,1.27,339.83],[1,1.28,351.29]],"ltp":1.27,"tv":464.97,"id":8979329}]}]}
{"op":"mcm","clk":"1009096779","pt":1580642016165,"mc":[{"id":"1.168224338","rc":[{"batb":[[0,4.8,14.79],[1,3.5,15.74],[2,1.01,15.52]],"ltp":3.6,"tv":15.96,"id":2397396},{"batb":[[0,1.24,274.1]],"ltp":1.27,"tv":464.97,"id":8979329}]}]}
{"op":"mcm","clk":"1009096945","pt":1580642017271,"mc":[{"id":"1.168224338","rc":[{"batb":[[1,4.2,12.6],[2,3.5,15.74]],"batl":[[0,4.9,10.08]],"ltp":3.6,"tv":15.96,"id":2397396},{"batb":[[0,1.25,168.04],[1,1.24,274.1],[2,1.23,469.62]],"batl":[[2,1.31,42.01]],"ltp":1.27,"tv":464.97,"id":8979329}]}]}
{"op":"mcm","clk":"1009097040","pt":1580642017753,"mc":[{"id":"1.168224338","rc":[{"batb":[[0,1.24,274.1],[1,1.23,469.62],[2,1.21,105.36]],"ltp":1.27,"tv":464.97,"id":8979329}]}]}
{"op":"mcm","clk":"1009097287","pt":1580642019346,"mc":[{"id":"1.168224338","rc":[{"trd":[[4.8,13.44]],"batb":[[0,4.8,8.07]],"batl":[[0,5,10.08]],"ltp":4.8,"tv":29.41,"id":2397396},{"batl":[[0,1.27,427.08]],"ltp":1.27,"tv":464.97,"id":8979329}],"tv":494.38}]}
{"op":"mcm","clk":"1009099940","pt":1580642036402,"mc":[{"id":"1.168224338","rc":[{"batb":[[0,3.5,15.74],[1,2.8,375.33],[2,1.01,15.52]],"ltp":4.8,"tv":29.41,"id":2397396},{"batb":[[0,1.14,627.92],[1,1.07,341.4],[2,1.01,15.51]],"ltp":1.27,"tv":464.97,"id":8979329}]}]}
{"op":"mcm","clk":"1009100107","pt":1580642037368,"mc":[{"id":"1.168224338","rc":[{"batb":[[1,1.01,15.52],[2,1.01,0]],"ltp":4.8,"tv":29.41,"id":2397396},{"batb":[[0,1.07,341.4],[1,1.01,15.51],[2,1.01,0]],"ltp":1.27,"tv":464.97,"id":8979329}]}]}
{"op":"mcm","clk":"1009100392","pt":1580642039370,"mc":[{"id":"1.168224338","rc":[{"batb":[[0,3.45,16.05]],"ltp":4.8,"tv":29.41,"id":2397396},{"batb":[[0,1.09,1175.45],[1,1.07,336.52],[2,1.01,15.51]],"batl":[[0,1.41,262.8],[1,1.42,213.92]],"ltp":1.27,"tv":464.97,"id":8979329}]}]}
{"op":"mcm","clk":"1009103557","pt":1580642058221,"mc":[{"id":"1.168224338","rc":[{"batb":[[0,1.07,336.52],[1,1.01,15.51],[2,1.01,0]],"ltp":1.27,"tv":464.97,"id":8979329}]}]}
{"op":"mcm","clk":"1009104028","pt":1580642061395,"mc":[{"id":"1.168224338","rc":[{"batb":[[1,3.2,18.48],[2,1.01,15.52]],"ltp":4.8,"tv":29.41,"id":2397396},{"batb":[[0,1.37,232.13],[1,1.36,268.61],[2,1.07,336.52]],"batl":[[2,1.46,42.01]],"ltp":1.27,"tv":464.97,"id":8979329}]}]}
{"op":"mcm","clk":"1009104136","pt":1580642061981,"mc":[{"id":"1.168224338","rc":[{"batb":[[2,2.9,25.1]],"batl":[[0,3.7,15.12]],"ltp":4.8,"tv":29.41,"id":2397396},{"batb":[[0,1.37,345.56],[2,1.35,60.59]],"ltp":1.27,"tv":464.97,"id":8979329}]}]}
{"op":"mcm","clk":"1009106748","pt":1580642078351,"mc":[{"id":"1.168224338","rc":[{"batb":[[0,1.37,113.43],[1,1.35,60.59],[2,1.23,516.48]],"batl":[[0,1.46,42.01],[1,1.42,0],[2,1.46,0]],"ltp":1.27,"tv":464.97,"id":8979329}]}]}
{"op":"mcm","clk":"1009106888","pt":1580642079155,"mc":[{"id":"1.168224338","rc":[{"batb":[[0,3.2,18.48],[1,2.9,25.1],[2,2.38,382.3]],"ltp":4.8,"tv":29.41,"id":2397396},{"batb":[[1,1.23,516.48],[2,1.22,106.46]],"ltp":1.27,"tv":464.97,"id":8979329}]}]}
{"op":"mcm","clk":"1009107095","pt":1580642080332,"mc":[{"id":"1.168224338","rc":[{"batb":[[0,2.9,25.1],[1,2.38,382.3],[2,1.01,15.52]],"ltp":4.8,"tv":29.41,"id":2397396},{"batb":[[0,1.23,516.48],[1,1.22,106.46],[2,1.01,15.51]],"ltp":1.27,"tv":464.97,"id":8979329}]}]}
{"op":"mcm","clk":"1009107249","pt":1580642081323,"mc":[{"id":"1.168224338","rc":[{"batb":[[0,1.24,156.51],[1,1.23,983.02],[2,1.22,106.46]],"batl":[[0,1.53,143.18],[1,1.54,154.55]],"ltp":1.27,"tv":464.97,"id":8979329}]}]}
{"op":"mcm","clk":"1009107389","pt":1580642082232,"mc":[{"id":"1.168224338","rc":[{"batb":[[0,1.23,516.48],[1,1.22,106.46],[2,1.01,15.51]],"ltp":1.27,"tv":464.97,"id":8979329}]}]}
{"op":"mcm","clk":"1009107713","pt":1580642084251,"mc":[{"id":"1.168224338","rc":[{"batb":[[0,1.22,106.46],[1,1.01,15.51],[2,1.01,0]],"ltp":1.27,"tv":464.97,"id":8979329}]}]}
{"op":"mcm","clk":"1009107851","pt":1580642085148,"mc":[{"id":"1.168224338","rc":[{"batb":[[0,1.48,287.64],[1,1.47,189.62],[2,1.22,106.46]],"ltp":1.27,"tv":464.97,"id":8979329}]}]}
{"op":"mcm","clk":"1009108011","pt":1580642086159,"mc":[{"id":"1.168224338","rc":[{"batb":[[1,2.62,13.06],[2,2.38,382.3]],"ltp":4.8,"tv":29.41,"id":2397396},{"batb":[[2,1.46,43.12]],"ltp":1.27,"tv":464.97,"id":8979329}]}]}
{"op":"mcm","clk":"1009108194","pt":1580642087329,"mc":[{"id":"1.168224338","rc":[{"batb":[[1,2.74,23.53],[2,2.62,13.06]],"batl":[[0,3.1,19.32]],"ltp":4.8,"tv":29.41,"id":2397396},{"batb":[[1,1.47,278.68]],"batl":[[2,1.58,42.01]],"ltp":1.27,"tv":464.97,"id":8979329}]}]}
{"op":"mcm","clk":"1009108864","pt":1580642091326,"mc":[{"id":"1.168224338","rc":[{"batb":[[1,1.47,284.39]],"ltp":1.27,"tv":464.97,"id":8979329}]}]}
{"op":"mcm","clk":"1009108966","pt":1580642092069,"mc":[{"id":"1.168224338","rc":[{"batb":[[1,1.47,278.68]],"ltp":1.27,"tv":464.97,"id":8979329}]}]}
{"op":"mcm","clk":"1009110468","pt":1580642101250,"mc":[{"id":"1.168224338","rc":[{"batb":[[0,2.74,23.53],[1,2.62,13.06],[2,2.38,382.3]],"ltp":4.8,"tv":29.41,"id":2397396},{"batb":[[0,1.47,89.06],[1,1.34,61.92],[2,1.31,477.51]],"batl":[[0,1.58,42.01],[1,1.54,0],[2,1.58,0]],"ltp":1.27,"tv":464.97,"id":8979329}]}]}
{"op":"mcm","clk":"1009110623","pt":1580642102262,"mc":[{"id":"1.168224338","rc":[{"batb":[[0,2.62,13.06],[1,2.38,382.3],[2,1.01,15.52]],"ltp":4.8,"tv":29.41,"id":2397396},{"batb":[[0,1.34,61.92],[1,1.31,477.51],[2,1.01,15.51]],"ltp":1.27,"tv":464.97,"id":8979329}]}]}
{"op":"mcm","clk":"1009110912","pt":1580642104160,"mc":[{"id":"1.168224338","rc":[{"batb":[[0,1.36,388.1],[1,1.35,280.43],[2,1.34,61.92]],"batl":[[0,1.64,206.82],[1,1.65,119.82]],"ltp":1.27,"tv":464.97,"id":8979329}]}]}
{"op":"mcm","clk":"1009112196","pt":1580642111362,"mc":[{"id":"1.168224338","rc":[{"batl":[[0,3.7,15.12]],"ltp":4.8,"tv":29.41,"id":2397396},{"batb":[[0,1.37,113.43],[1,1.36,388.1],[2,1.35,280.43]],"batl":[[0,1.4,146.18],[1,1.41,221.84]],"ltp":1.27,"tv":464.97,"id":8979329}]}]}
{"op":"mcm","clk":"1009112353","pt":1580642112381,"mc":[{"id":"1.168224338","rc":[{"batb":[[0,3.5,15.66],[1,3.2,18.48],[2,2.96,24.08]],"ltp":4.8,"tv":29.41,"id":2397396},{"batl":[[2,1.46,42.01]],"ltp":1.27,"tv":464.97,"id":8979329}]}]}
{"op":"mcm","clk":"1009115093","pt":1580642128276,"mc":[{"id":"1.168224338","rc":[{"batb":[[0,2.96,24.08],[1,2.38,382.3],[2,1.01,15.52]],"ltp":4.8,"tv":29.41,"id":2397396},{"batb":[[0,1.22,523],[1,1.21,110],[2,1.01,15.51]],"ltp":1.27,"tv":464.97,"id":8979329}]}]}
{"op":"mcm","clk":"1009115445","pt":1580642130401,"mc":[{"id":"1.168224338","rc":[{"batb":[[0,1.23,493.29],[1,1.22,1024.23],[2,1.21,110]],"batl":[[0,1.53,226.89],[1,1.54,154.07]],"ltp":1.27,"tv":464.97,"id":8979329}]}]}
{"op":"mcm","clk":"1009116484","pt":1580642136225,"mc":[{"id":"1.168224338","rc":[{"batb":[[0,1.22,523],[1,1.21,110],[2,1.01,15.51]],"ltp":1.27,"tv":464.97,"id":8979329}]}]}
{"op":"mcm","clk":"1009116851","pt":1580642138399,"mc":[{"id":"1.168224338","rc":[{"batb":[[0,1.21,110],[1,1.01,15.51],[2,1.01,0]],"ltp":1.27,"tv":464.97,"id":8979329}]}]}
{"op":"mcm","clk":"1009117006","pt":1580642139308,"mc":[{"id":"1.168224338","rc":[{"batb":[[1,2.74,23.53],[2,2.38,382.3]],"ltp":4.8,"tv":29.41,"id":2397396},{"batb":[[0,1.48,198.24],[1,1.47,189],[2,1.21,110]],"batl":[[2,1.57,42.01]],"ltp":1.27,"tv":464.97,"id":8979329}]}]}
{"op":"mcm","clk":"1009117125","pt":1580642140001,"mc":[{"id":"1.168224338","rc":[{"batb":[[2,2.66,12.67]],"batl":[[0,3.15,19.32]],"ltp":4.8,"tv":29.41,"id":2397396},{"batb":[[1,1.47,278.06],[2,1.45,44.61]],"ltp":1.27,"tv":464.97,"id":8979329}]}]}
{"op":"mcm","clk":"1009119885","pt":1580642155227,"mc":[{"id":"1.168224338","rc":[{"batb":[[0,2.74,23.53],[1,2.66,12.67],[2,2.38,382.3]],"ltp":4.8,"tv":29.41,"id":2397396},{"batb":[[0,1.47,89.06],[1,1.34,63.65],[2,1.31,477.51]],"batl":[[0,1.57,42.01],[1,1.54,0],[2,1.57,0]],"ltp":1.27,"tv":464.97,"id":8979329}]}]}
{"op":"mcm","clk":"1009120084","pt":1580642156344,"mc":[{"id":"1.168224338","rc":[{"batb":[[0,2.66,12.67],[1,2.38,382.3],[2,1.01,15.52]],"ltp":4.8,"tv":29.41,"id":2397396},{"batb":[[0,1.34,63.65],[1,1.31,477.51],[2,1.01,15.51]],"ltp":1.27,"tv":464.97,"id":8979329}]}]}
{"op":"mcm","clk":"1009120361","pt":1580642158118,"mc":[{"id":"1.168224338","rc":[{"batb":[[0,1.36,277.15],[1,1.35,279.02],[2,1.34,63.65]],"batl":[[0,1.63,149.32],[1,1.64,122.61]],"ltp":1.27,"tv":464.97,"id":8979329}]}]}
{"op":"mcm","clk":"1009120516","pt":1580642158913,"mc":[{"id":"1.168224338","rc":[{"batb":[[0,1.34,63.65],[1,1.31,477.51],[2,1.01,15.51]],"ltp":1.27,"tv":464.97,"id":8979329}]}]}
{"op":"mcm","clk":"1009120823","pt":1580642160740,"mc":[{"id":"1.168224338","rc":[{"batb":[[1,1.01,15.52],[2,1.01,0]],"ltp":4.8,"tv":29.41,"id":2397396},{"batb":[[1,1.01,15.51],[2,1.01,0]],"ltp":1.27,"tv":464.97,"id":8979329}]}]}
{"op":"mcm","clk":"1009121039","pt":1580642162018,"mc":[{"id":"1.168224338","rc":[{"batb":[[0,1.57,262.06],[1,1.56,149.13],[2,1.34,63.65]],"ltp":1.27,"tv":464.97,"id":8979329}]}]}
{"op":"mcm","clk":"1009121285","pt":1580642163347,"mc":[{"id":"1.168224338","rc":[{"batb":[[1,2.46,28.57],[2,2.26,19.59]],"batl":[[0,2.78,23.53]],"ltp":4.8,"tv":29.41,"id":2397396},{"batb":[[1,1.56,223.91],[2,1.54,35.33]],"batl":[[2,1.69,42.01]],"ltp":1.27,"tv":464.97,"id":8979329}]}]}
{"op":"mcm","clk":"1009124156","pt":1580642181374,"mc":[{"id":"1.168224338","rc":[{"batl":[[0,2.78,26.55]],"ltp":4.8,"tv":29.41,"id":2397396}]}]}
{"op":"mcm","clk":"1009124275","pt":1580642182058,"mc":[{"id":"1.168224338","rc":[{"batl":[[0,2.78,23.53]],"ltp":4.8,"tv":29.41,"id":2397396}]}]}
{"op":"mcm","clk":"1009128180","pt":1580642207277,"mc":[{"id":"1.168224338","rc":[{"trd":[[1.57,223.5]],"batb":[[0,1.57,150.31]],"ltp":1.57,"tv":688.46,"id":8979329}],"tv":717.88}]}
{"op":"mcm","clk":"1009128733","pt":1580642210818,"mc":[{"id":"1.168224338","rc":[{"batb":[[0,1.57,221.14]],"batl":[[0,1.63,188.76]],"ltp":1.57,"tv":688.46,"id":8979329}]}]}
{"op":"mcm","clk":"1009133788","pt":1580642244363,"mc":[{"id":"1.168224338","rc":[{"batb":[[0,1.56,74.78],[1,1.54,35.33],[2,1.47,41.78]],"batl":[[0,1.69,42.01],[1,1.64,0],[2,1.69,0]],"ltp":1.57,"tv":688.46,"id":8979329}]}]}
{"op":"mcm","clk":"1009133860","pt":1580642244793,"mc":[{"id":"1.168224338","rc":[{"batb":[[0,2.26,19.59],[1,2.04,394.09],[2,1.01,15.52]],"ltp":4.8,"tv":29.41,"id":2397396},{"batb":[[0,1.47,41.78],[1,1.34,465.43],[2,1.01,15.51]],"ltp":1.57,"tv":688.46,"id":8979329}]}]}
{"op":"mcm","clk":"1009134664","pt":1580642249370,"mc":[{"id":"1.168224338","rc":[{"batb":[[0,1.6,254.39],[1,1.59,138.8],[2,1.47,41.78]],"batl":[[0,1.67,227.53],[1,1.69,222.01]],"ltp":1.57,"tv":688.46,"id":8979329}]}]}
{"op":"mcm","clk":"1009135413","pt":1580642253681,"mc":[{"id":"1.168224338","rc":[{"batb":[[0,1.47,41.78],[1,1.38,448.45],[2,1.01,15.51]],"ltp":1.57,"tv":688.46,"id":8979329}]}]}
{"op":"mcm","clk":"1009135899","pt":1580642256662,"mc":[{"id":"1.168224338","rc":[{"batb":[[0,1.5,132.05],[1,1.49,178.51],[2,1.47,41.78]],"batl":[[0,1.83,179.19],[1,1.85,165.16]],"ltp":1.57,"tv":688.46,"id":8979329}]}]}
{"op":"mcm","clk":"1009136891","pt":1580642263369,"mc":[{"id":"1.168224338","rc":[{"batb":[[0,2.86,10.46],[1,2.52,14.63],[2,2.26,19.59]],"ltp":4.8,"tv":29.41,"id":2397396},{"batl":[[0,1.55,253.52],[1,1.56,146.79]],"ltp":1.57,"tv":688.46,"id":8979329}]}]}
{"op":"mcm","clk":"1009136907","pt":1580642263471,"mc":[{"id":"1.168224338","rc":[{"batb":[[1,2.62,25.21],[2,2.52,14.63]],"batl":[[0,3,21]],"ltp":4.8,"tv":29.41,"id":2397396},{"batb":[[1,1.49,264.21]],"batl":[[2,1.61,42.01]],"ltp":1.57,"tv":688.46,"id":8979329}]}]}
{"op":"mcm","clk":"1009138316","pt":1580642273384,"mc":[{"id":"1.168224338","rc":[{"batb":[[0,1.49,85.7],[1,1.47,41.78],[2,1.43,47.21]],"batl":[[0,1.61,42.01],[1,1.56,0],[2,1.61,0]],"ltp":1.57,"tv":688.46,"id":8979329}]}]}
{"op":"mcm","clk":"1009138394","pt":1580642273856,"mc":[{"id":"1.168224338","rc":[{"batb":[[0,2.62,25.21],[1,2.52,14.63],[2,2.04,394.09]],"ltp":4.8,"tv":29.41,"id":2397396},{"batb":[[1,1.43,47.21],[2,1.31,477.51]],"ltp":1.57,"tv":688.46,"id":8979329}]}]}
{"op":"mcm","clk":"1009138477","pt":1580642274498,"mc":[{"id":"1.168224338","rc":[{"batb":[[0,2.52,14.63],[1,2.04,394.09],[2,1.01,15.52]],"ltp":4.8,"tv":29.41,"id":2397396},{"batb":[[0,1.43,47.21],[1,1.31,477.51],[2,1.01,15.51]],"ltp":1.57,"tv":688.46,"id":8979329}]}]}
{"op":"mcm","clk":"1009138912","pt":1580642277277,"mc":[{"id":"1.168224338","rc":[{"batb":[[0,1.44,311.03],[1,1.43,261.25],[2,1.31,477.51]],"batl":[[0,1.67,123.85],[1,1.69,222.64]],"ltp":1.57,"tv":688.46,"id":8979329}]}]}
{"op":"mcm","clk":"1009139240","pt":1580642279285,"mc":[{"id":"1.168224338","rc":[{"batb":[[1,1.01,15.52],[2,1.01,0]],"ltp":4.8,"tv":29.41,"id":2397396}]}]}
{"op":"mcm","clk":"1009139395","pt":1580642280396,"mc":[{"id":"1.168224338","rc":[{"batb":[[0,3,22.35],[1,2.78,11.33],[2,2.52,14.63]],"ltp":4.8,"tv":29.41,"id":2397396},{"batb":[[2,1.4,51.38]],"batl":[[0,1.49,207.88],[1,1.5,171.1]],"ltp":1.57,"tv":688.46,"id":8979329}]}]}
{"op":"mcm","clk":"1009139537","pt":1580642281404,"mc":[{"id":"1.168224338","rc":[{"batb":[[2,1.01,15.52]],"ltp":4.8,"tv":29.41,"id":2397396}]}]}
{"op":"mcm","clk":"1009139645","pt":1580642282106,"mc":[{"id":"1.168224338","rc":[{"batb":[[1,2.78,34.86]],"batl":[[0,3.2,18.48]],"ltp":4.8,"tv":29.41,"id":2397396},{"batb":[[0,1.45,93.26],[1,1.44,311.03],[2,1.43,261.25]],"batl":[[2,1.55,42.01]],"ltp":1.57,"tv":688.46,"id":8979329}]}]}
{"op":"mcm","clk":"1009139839","pt":1580642283272,"mc":[{"id":"1.168224338","rc":[{"batb":[[2,2.22,384.52]],"ltp":4.8,"tv":29.41,"id":2397396}]}]}
{"op":"mcm","clk":"1009141065","pt":1580642291212,"mc":[{"id":"1.168224338","rc":[{"batb":[[0,2.78,34.86],[1,2.22,384.52],[2,1.01,15.52]],"ltp":4.8,"tv":29.41,"id":2397396},{"batb":[[1,1.4,51.38],[2,1.31,477.51]],"batl":[[0,1.55,42.01],[1,1.5,0],[2,1.55,0]],"ltp":1.57,"tv":688.46,"id":8979329}]}]}
{"op":"mcm","clk":"1009141230","pt":1580642292312,"mc":[{"id":"1.168224338","rc":[{"batb":[[0,2.78,11.33]],"ltp":4.8,"tv":29.41,"id":2397396}]}]}
{"op":"mcm","clk":"1009141294","pt":1580642292591,"mc":[{"id":"1.168224338","rc":[{"batb":[[0,1.4,51.38],[1,1.31,477.51],[2,1.01,15.51]],"ltp":1.57,"tv":688.46,"id":8979329}]}]}
{"op":"mcm","clk":"1009141587","pt":1580642293714,"mc":[{"id":"1.168224338","rc":[{"batb":[[0,1.41,334.75],[1,1.4,287.05],[2,1.31,477.51]],"batl":[[0,1.56,159.57],[1,1.57,143.83]],"ltp":1.57,"tv":688.46,"id":8979329}]}]}
{"op":"mcm","clk":"1009141807","pt":1580642295207,"mc":[{"id":"1.168224338","rc":[{"batb":[[0,2.8,22.69],[1,2.78,11.33],[2,2.22,384.52]],"ltp":4.8,"tv":29.41,"id":2397396}]}]}
{"op":"mcm","clk":"1009141863","pt":1580642295618,"mc":[{"id":"1.168224338","rc":[{"batb":[[0,2.78,11.33],[1,2.22,384.52],[2,1.01,15.52]],"ltp":4.8,"tv":29.41,"id":2397396}]}]}
{"op":"mcm","clk":"1009142496","pt":1580642300157,"mc":[{"id":"1.168224338","rc":[{"batb":[[0,1.4,51.38],[1,1.31,477.51],[2,1.01,15.51]],"ltp":1.57,"tv":688.46,"id":8979329}]}]}
{"op":"mcm","clk":"1009142717","pt":1580642301333,"mc":[{"id":"1.168224338","rc":[{"batb":[[1,1.01,15.51],[2,1.01,0]],"ltp":1.57,"tv":688.46,"id":8979329}]}]}
{"op":"mcm","clk":"1009142990","pt":1580642303315,"mc":[{"id":"1.168224338","rc":[{"batb":[[1,2.36,17.31],[2,2.22,384.52]],"ltp":4.8,"tv":29.41,"id":2397396},{"batb":[[0,1.51,213.88],[1,1.5,213.01],[2,1.44,45.64]],"ltp":1.57,"tv":688.46,"id":8979329}]}]}
{"op":"mcm","clk":"1009143015","pt":1580642303526,"mc":[{"id":"1.168224338","rc":[{"batb":[[1,2.64,25.21],[2,2.36,17.31]],"batl":[[0,3,21]],"ltp":4.8,"tv":29.41,"id":2397396},{"batb":[[1,1.5,297.03]],"batl":[[2,1.61,42.01]],"ltp":1.57,"tv":688.46,"id":8979329}]}]}
{"op":"mcm","clk":"1009145471","pt":1580642319961,"mc":[{"id":"1.168224338","rc":[{"batb":[[0,2.64,25.21],[1,2.36,17.31],[2,2.22,384.52]],"ltp":4.8,"tv":29.41,"id":2397396},{"batb":[[0,1.5,84.02],[1,1.44,45.64],[2,1.34,465.43]],"batl":[[0,1.61,42.01],[1,1.57,0],[2,1.61,0]],"ltp":1.57,"tv":688.46,"id":8979329}]}]}
{"op":"mcm","clk":"1009145562","pt":1580642320554,"mc":[{"id":"1.168224338","rc":[{"batb":[[0,2.36,17.31],[1,2.22,384.52],[2,1.01,15.52]],"ltp":4.8,"tv":29.41,"id":2397396},{"batb":[[0,1.44,45.64],[1,1.34,465.43],[2,1.01,15.51]],"ltp":1.57,"tv":688.46,"id":8979329}]}]}
{"op":"mcm","clk":"1009145983","pt":1580642323280,"mc":[{"id":"1.168224338","rc":[{"batb":[[0,1.45,133.91],[1,1.44,251.86],[2,1.34,465.43]],"batl":[[0,1.73,199.52],[1,1.75,197.6]],"ltp":1.57,"tv":688.46,"id":8979329}]}]}
{"op":"mcm","clk":"1009146484","pt":1580642326573,"mc":[{"id":"1.168224338","rc":[{"batb":[[2,1.01,15.51]],"ltp":1.57,"tv":688.46,"id":8979329}]}]}
{"op":"mcm","clk":"1009146754","pt":1580642328077,"mc":[{"id":"1.168224338","rc":[{"batl":[[0,1.49,180.01],[1,1.5,171.31]],"ltp":1.57,"tv":688.46,"id":8979329}]}]}
{"op":"mcm","clk":"1009146960","pt":1580642329193,"mc":[{"id":"1.168224338","rc":[{"batb":[[0,2.98,23.37],[1,2.74,11.8],[2,2.22,384.52]],"ltp":4.8,"tv":29.41,"id":2397396},{"batb":[[2,1.41,49.57]],"ltp":1.57,"tv":688.46,"id":8979329}]}]}
{"op":"mcm","clk":"1009147014","pt":1580642329464,"mc":[{"id":"1.168224338","rc":[{"batb":[[1,2.8,22.69],[2,2.74,11.8]],"batl":[[0,3.25,18.48]],"ltp":4.8,"tv":29.41,"id":2397396},{"batb":[[1,1.44,346.8]],"batl":[[2,1.55,42.01]],"ltp":1.57,"tv":688.46,"id":8979329}]}]}
{"op":"mcm","clk":"1009149297","pt":1580642343281,"mc":[{"id":"1.168224338","rc":[{"batb":[[0,2.8,22.69],[1,2.74,11.8],[2,2.22,384.52]],"ltp":4.8,"tv":29.41,"id":2397396},{"batb":[[0,1.44,94.94],[1,1.41,49.57],[2,1.28,485.89]],"batl":[[0,1.55,42.01],[1,1.5,0],[2,1.55,0]],"ltp":1.57,"tv":688.46,"id":8979329}]}]}
{"op":"mcm","clk":"1009149592","pt":1580642344997,"mc":[{"id":"1.168224338","rc":[{"batb":[[0,2.74,11.8],[1,2.22,384.52],[2,1.01,15.52]],"ltp":4.8,"tv":29.41,"id":2397396},{"batb":[[0,1.41,49.57],[1,1.28,485.89],[2,1.01,15.51]],"ltp":1.57,"tv":688.46,"id":8979329}]}]}
{"op":"mcm","clk":"1009150189","pt":1580642348229,"mc":[{"id":"1.168224338","rc":[{"batb":[[0,1.46,177.99],[1,1.45,200.47],[2,1.41,49.57]],"batl":[[0,1.51,287.4],[1,1.52,161.91]],"ltp":1.57,"tv":688.46,"id":8979329}]}]}
{"op":"mcm","clk":"1009150650","pt":1580642351320,"mc":[{"id":"1.168224338","rc":[{"batb":[[0,1.41,49.57],[1,1.28,485.89],[2,1.01,15.51]],"ltp":1.57,"tv":688.46,"id":8979329}]}]}
{"op":"mcm","clk":"1009151137","pt":1580642354708,"mc":[{"id":"1.168224338","rc":[{"batl":[[0,1.56,192.58],[1,1.57,143.68]],"ltp":1.57,"tv":688.46,"id":8979329}]}]}
{"op":"mcm","clk":"1009151522","pt":1580642357326,"mc":[{"id":"1.168224338","rc":[{"batb":[[1,1.01,15.51],[2,1.01,0]],"ltp":1.57,"tv":688.46,"id":8979329}]}]}
{"op":"mcm","clk":"1009151609","pt":1580642357914,"mc":[{"id":"1.168224338","rc":[{"batb":[[0,1.51,178.83],[1,1.5,174.02],[2,1.41,49.57]],"ltp":1.57,"tv":688.46,"id":8979329}]}]}
{"op":"mcm","clk":"1009151786","pt":1580642359247,"mc":[{"id":"1.168224338","rc":[{"batb":[[1,2.3,18.65],[2,2.22,384.52]],"ltp":4.8,"tv":29.41,"id":2397396},{"batb":[[0,1.51,216.36],[2,1.46,176.88]],"ltp":1.57,"tv":688.46,"id":8979329}]}]}
{"op":"mcm","clk":"1009151826","pt":1580642359519,"mc":[{"id":"1.168224338","rc":[{"batb":[[1,2.66,25.21],[2,2.3,18.65]],"batl":[[0,3,21]],"ltp":4.8,"tv":29.41,"id":2397396},{"batb":[[2,1.49,85.7]],"batl":[[2,1.61,42.01]],"ltp":1.57,"tv":688.46,"id":8979329}]}]}
{"op":"mcm","clk":"1009153487","pt":1580642370906,"mc":[{"id":"1.168224338","rc":[{"batb":[[0,2.3,18.65],[1,2.22,384.52],[2,1.01,15.52]],"ltp":4.8,"tv":29.41,"id":2397396},{"batb":[[0,1.45,44.53],[1,1.34,465.43],[2,1.01,15.51]],"ltp":1.57,"tv":688.46,"id":8979329}]}]}
{"op":"mcm","clk":"1009153911","pt":1580642373936,"mc":[{"id":"1.168224338","rc":[{"batb":[[0,2.32,18.25]],"ltp":4.8,"tv":29.41,"id":2397396},{"batb":[[0,1.44,192.17],[1,1.43,212.69],[2,1.34,465.43]],"batl":[[0,1.75,199.17],[1,1.77,190.35]],"ltp":1.57,"tv":688.46,"id":8979329}]}]}
{"op":"mcm","clk":"1009158222","pt":1580642404476,"mc":[{"id":"1.168224338","rc":[{"batb":[[2,1.01,15.51]],"ltp":1.57,"tv":688.46,"id":8979329}]}]}
{"op":"mcm","clk":"1009158568","pt":1580642406292,"mc":[{"id":"1.168224338","rc":[{"batl":[[0,1.48,185.97],[1,1.49,175.91]],"ltp":1.57,"tv":688.46,"id":8979329}]}]}
{"op":"mcm","clk":"1009158724","pt":1580642407302,"mc":[{"id":"1.168224338","rc":[{"batb":[[0,2.98,23.53],[1,2.7,12.27],[2,2.32,18.25]],"ltp":4.8,"tv":29.41,"id":2397396},{"batb":[[2,1.32,66.49]],"ltp":1.57,"tv":688.46,"id":8979329}]}]}
{"op":"mcm","clk":"1009158865","pt":1580642407998,"mc":[{"id":"1.168224338","rc":[{"batb":[[1,2.86,21.85],[2,2.7,12.27]],"batl":[[0,3.35,17.64]],"ltp":4.8,"tv":29.41,"id":2397396},{"batb":[[1,1.43,310.15]],"batl":[[2,1.53,42.01]],"ltp":1.57,"tv":688.46,"id":8979329}]}]}
{"op":"mcm","clk":"1009163050","pt":1580642435319,"mc":[{"id":"1.168224338","rc":[{"batb":[[0,2.86,21.85],[1,2.7,12.27],[2,2.22,384.52]],"ltp":4.8,"tv":29.41,"id":2397396},{"batb":[[0,1.43,97.46],[1,1.32,66.49],[2,1.28,485.89]],"batl":[[0,1.53,42.01],[1,1.49,0],[2,1.53,0]],"ltp":1.57,"tv":688.46,"id":8979329}]}]}
{"op":"mcm","clk":"1009163303","pt":1580642437125,"mc":[{"id":"1.168224338","rc":[{"batb":[[0,2.7,12.27],[1,2.22,384.52],[2,1.01,15.52]],"ltp":4.8,"tv":29.41,"id":2397396},{"batb":[[0,1.32,66.49],[1,1.28,485.89],[2,1.01,15.51]],"ltp":1.57,"tv":688.46,"id":8979329}]}]}
{"op":"mcm","clk":"1009163433","pt":1580642438016,"mc":[{"id":"1.168224338","rc":[{"batb":[[0,1.33,168.45],[1,1.32,378.22],[2,1.28,485.89]],"batl":[[0,1.58,229.62],[1,1.59,136.92]],"ltp":1.57,"tv":688.46,"id":8979329}]}]}
{"op":"mcm","clk":"1009164193","pt":1580642443320,"mc":[{"id":"1.168224338","rc":[{"batb":[[1,1.01,15.52],[2,1.01,0]],"ltp":4.8,"tv":29.41,"id":2397396},{"batb":[[2,1.01,15.51]],"ltp":1.57,"tv":688.46,"id":8979329}]}]}
{"op":"mcm","clk":"1009164243","pt":1580642443643,"mc":[{"id":"1.168224338","rc":[{"batl":[[0,1.36,194.99],[1,1.37,252.78]],"ltp":1.57,"tv":688.46,"id":8979329}]}]}
{"op":"mcm","clk":"1009164419","pt":1580642444764,"mc":[{"id":"1.168224338","rc":[{"batb":[[0,3.65,14.16],[1,3.1,21.4],[2,1.01,15.52]],"ltp":4.8,"tv":29.41,"id":2397396},{"batb":[[2,1.21,111.81]],"ltp":1.57,"tv":688.46,"id":8979329}]}]}
{"op":"mcm","clk":"1009164558","pt":1580642445626,"mc":[{"id":"1.168224338","rc":[{"batb":[[1,3.4,16.8],[2,3.1,21.4]],"batl":[[0,4,13.44]],"ltp":4.8,"tv":29.41,"id":2397396},{"batb":[[0,1.33,295.32]],"batl":[[2,1.41,42.01]],"ltp":1.57,"tv":688.46,"id":8979329}]}]}
{"op":"mcm","clk":"1009166598","pt":1580642459268,"mc":[{"id":"1.168224338","rc":[{"batb":[[0,3.4,16.8],[1,3.1,21.4],[2,2.52,381.46]],"ltp":4.8,"tv":29.41,"id":2397396},{"batb":[[0,1.33,126.87],[1,1.21,111.81],[2,1.2,530.86]],"batl":[[0,1.41,42.01],[1,1.37,0],[2,1.41,0]],"ltp":1.57,"tv":688.46,"id":8979329}]}]}
{"op":"mcm","clk":"1009166758","pt":1580642460652,"mc":[{"id":"1.168224338","rc":[{"batb":[[0,3.1,21.4],[1,2.52,381.46],[2,1.01,15.52]],"ltp":4.8,"tv":29.41,"id":2397396},{"batb":[[0,1.21,111.81],[1,1.2,530.86],[2,1.01,15.51]],"ltp":1.57,"tv":688.46,"id":8979329}]}]}
{"op":"mcm","clk":"1009167177","pt":1580642463359,"mc":[{"id":"1.168224338","rc":[{"batb":[[0,1.3,387.1],[1,1.29,356.43],[2,1.21,111.81]],"batl":[[0,1.34,361.36],[1,1.35,268.74]],"ltp":1.57,"tv":688.46,"id":8979329}]}]}
{"op":"mcm","clk":"1009167601","pt":1580642466269,"mc":[{"id":"1.168224338","rc":[{"batb":[[0,1.21,111.81],[1,1.2,530.86],[2,1.01,15.51]],"ltp":1.57,"tv":688.46,"id":8979329}]}]}
{"op":"mcm","clk":"1009168050","pt":1580642469198,"mc":[{"id":"1.168224338","rc":[{"batb":[[0,1.22,177.41],[1,1.21,633.75],[2,1.2,530.86]],"batl":[[0,1.46,171.53],[1,1.47,185.93]],"ltp":1.57,"tv":688.46,"id":8979329}]}]}
{"op":"mcm","clk":"1009168647","pt":1580642473396,"mc":[{"id":"1.168224338","rc":[{"batb":[[0,1.21,111.81],[1,1.2,530.86],[2,1.01,15.51]],"ltp":1.57,"tv":688.46,"id":8979329}]}]}
{"op":"mcm","clk":"1009168917","pt":1580642475216,"mc":[{"id":"1.168224338","rc":[{"batb":[[1,1.01,15.52],[2,1.01,0]],"ltp":4.8,"tv":29.41,"id":2397396},{"batb":[[1,1.01,15.51],[2,1.01,0]],"ltp":1.57,"tv":688.46,"id":8979329}]}]}
{"op":"mcm","clk":"1009169089","pt":1580642476392,"mc":[{"id":"1.168224338","rc":[{"batb":[[0,1.42,203.97],[1,1.41,226.98],[2,1.21,111.81]],"ltp":1.57,"tv":688.46,"id":8979329}]}]}
{"op":"mcm","clk":"1009169181","pt":1580642477018,"mc":[{"id":"1.168224338","rc":[{"batb":[[1,2.72,11.96],[2,1.01,15.52]],"ltp":4.8,"tv":29.41,"id":2397396},{"batb":[[0,1.42,252.75],[2,1.28,77.66]],"ltp":1.57,"tv":688.46,"id":8979329}]}]}
{"op":"mcm","clk":"1009169277","pt":1580642477706,"mc":[{"id":"1.168224338","rc":[{"batb":[[1,2.98,21],[2,2.72,11.96]],"batl":[[0,3.45,16.8]],"ltp":4.8,"tv":29.41,"id":2397396},{"batb":[[1,1.41,328.64]],"batl":[[2,1.51,42.01]],"ltp":1.57,"tv":688.46,"id":8979329}]}]}
{"op":"mcm","clk":"1009169457","pt":1580642479120,"mc":[{"id":"1.168224338","rc":[{"batb":[[2,1.28,563.55]],"ltp":1.57,"tv":688.46,"id":8979329}]}]}
{"op":"mcm","clk":"1009171056","pt":1580642491050,"mc":[{"id":"1.168224338","rc":[{"batb":[[0,2.98,21],[1,2.72,11.96],[2,2.22,384.52]],"ltp":4.8,"tv":29.41,"id":2397396},{"batb":[[0,1.41,101.66],[1,1.28,563.55],[2,1.01,15.51]],"batl":[[0,1.51,42.01],[1,1.47,0],[2,1.51,0]],"ltp":1.57,"tv":688.46,"id":8979329}]}]}
{"op":"mcm","clk":"1009171249","pt":1580642492653,"mc":[{"id":"1.168224338","rc":[{"batb":[[0,2.72,11.96],[1,2.22,384.52],[2,1.01,15.52]],"ltp":4.8,"tv":29.41,"id":2397396},{"batb":[[0,1.28,563.55],[1,1.01,15.51],[2,1.01,0]],"ltp":1.57,"tv":688.46,"id":8979329}]}]}
{"op":"mcm","clk":"1009171700","pt":1580642496230,"mc":[{"id":"1.168224338","rc":[{"batb":[[0,1.39,278.2],[1,1.38,251.42],[2,1.28,563.55]],"batl":[[0,1.43,169.74],[1,1.44,202.67]],"ltp":1.57,"tv":688.46,"id":8979329}]}]}
{"op":"mcm","clk":"1009172036","pt":1580642499144,"mc":[{"id":"1.168224338","rc":[{"batb":[[0,1.28,563.55],[1,1.01,15.51],[2,1.28,0]],"ltp":1.57,"tv":688.46,"id":8979329}]}]}
{"op":"mcm","clk":"1009172474","pt":1580642502125,"mc":[{"id":"1.168224338","rc":[{"batb":[[0,1.29,377.27],[1,1.28,935.67],[2,1.01,15.51]],"batl":[[0,1.58,234.83],[1,1.59,136.88]],"ltp":1.57,"tv":688.46,"id":8979329}]}]}
{"op":"mcm","clk":"1009174244","pt":1580642515286,"mc":[{"id":"1.168224338","rc":[{"batb":[[0,1.28,563.55],[1,1.01,15.51],[2,1.01,0]],"ltp":1.57,"tv":688.46,"id":8979329}]}]}
{"op":"mcm","clk":"1009174568","pt":1580642517269,"mc":[{"id":"1.168224338","rc":[{"batb":[[0,1.28,77.66]],"ltp":1.57,"tv":688.46,"id":8979329}]}]}
{"op":"mcm","clk":"1009174707","pt":1580642518171,"mc":[{"id":"1.168224338","rc":[{"batb":[[0,1.52,265.04],[1,1.51,169.83],[2,1.28,77.66]],"ltp":1.57,"tv":688.46,"id":8979329}]}]}
{"op":"mcm","clk":"1009174839","pt":1580642519067,"mc":[{"id":"1.168224338","rc":[{"batb":[[1,2.48,15.34],[2,2.22,384.52]],"ltp":4.8,"tv":29.41,"id":2397396},{"batb":[[0,1.52,302.1],[2,1.39,53.11]],"ltp":1.57,"tv":688.46,"id":8979329}]}]}
{"op":"mcm","clk":"1009174903","pt":1580642519551,"mc":[{"id":"1.168224338","rc":[{"batb":[[1,2.62,25.21],[2,2.48,15.34]],"batl":[[0,3,21]],"ltp":4.8,"tv":29.41,"id":2397396},{"batb":[[2,1.5,84.02]],"batl":[[2,1.62,42.01]],"ltp":1.57,"tv":688.46,"id":8979329}]}]}
{"op":"mcm","clk":"1009177348","pt":1580642536180,"mc":[{"id":"1.168224338","rc":[{"batb":[[0,2.62,25.21],[1,2.48,15.34],[2,2.22,384.52]],"ltp":4.8,"tv":29.41,"id":2397396},{"batb":[[0,1.5,84.02],[1,1.39,53.11],[2,1.34,465.43]],"batl":[[0,1.62,42.01],[1,1.59,0],[2,1.62,0]],"ltp":1.57,"tv":688.46,"id":8979329}]}]}
{"op":"mcm","clk":"1009177414","pt":1580642536597,"mc":[{"id":"1.168224338","rc":[{"batb":[[0,2.48,15.34],[1,2.22,384.52],[2,1.01,15.52]],"ltp":4.8,"tv":29.41,"id":2397396},{"batb":[[0,1.39,53.11],[1,1.34,465.43],[2,1.01,15.51]],"ltp":1.57,"tv":688.46,"id":8979329}]}]}
{"op":"mcm","clk":"1009178102","pt":1580642540756,"mc":[{"id":"1.168224338","rc":[{"batb":[[0,1.5,164],[1,1.49,178.72],[2,1.39,53.11]],"batl":[[0,1.55,223.51],[1,1.56,146.96]],"ltp":1.57,"tv":688.46,"id":8979329}]}]}
{"op":"mcm","clk":"1009178728","pt":1580642544733,"mc":[{"id":"1.168224338","rc":[{"batb":[[0,1.39,53.11],[1,1.34,465.43],[2,1.01,15.51]],"ltp":1.57,"tv":688.46,"id":8979329}]}]}
{"op":"mcm","clk":"1009179199","pt":1580642547710,"mc":[{"id":"1.168224338","rc":[{"batb":[[0,1.4,265.05],[1,1.39,296.03],[2,1.34,465.43]],"batl":[[0,1.68,132.94],[1,1.7,218.08]],"ltp":1.57,"tv":688.46,"id":8979329}]}]}
{"op":"mcm","clk":"1009179479","pt":1580642549619,"mc":[{"id":"1.168224338","rc":[{"batb":[[0,1.39,53.11],[1,1.34,465.43],[2,1.01,15.51]],"ltp":1.57,"tv":688.46,"id":8979329}]}]}
{"op":"mcm","clk":"1009179923","pt":1580642552373,"mc":[{"id":"1.168224338","rc":[{"batb":[[1,1.01,15.52],[2,1.01,0]],"ltp":4.8,"tv":29.41,"id":2397396},{"batb":[[0,1.62,204.54],[1,1.61,132.28],[2,1.39,53.11]],"ltp":1.57,"tv":688.46,"id":8979329}]}]}
{"op":"mcm","clk":"1009180069","pt":1580642553225,"mc":[{"id":"1.168224338","rc":[{"batb":[[1,2.34,17.78],[2,1.01,15.52]],"ltp":4.8,"tv":29.41,"id":2397396},{"batb":[[1,1.61,162.26],[2,1.52,36.51]],"ltp":1.57,"tv":688.46,"id":8979329}]}]}
{"op":"mcm","clk":"1009180162","pt":1580642553804,"mc":[{"id":"1.168224338","rc":[{"batb":[[1,2.4,29.41],[2,2.34,17.78]],"batl":[[0,2.7,24.37]],"ltp":4.8,"tv":29.41,"id":2397396},{"batb":[[2,1.59,70.58]],"batl":[[2,1.72,42.01]],"ltp":1.57,"tv":688.46,"id":8979329}]}]}
{"op":"mcm","clk":"1009181902","pt":1580642565390,"mc":[{"id":"1.168224338","rc":[{"batb":[[0,1.61,29.98],[1,1.59,70.58],[2,1.52,36.51]],"batl":[[0,1.72,42.01],[1,1.7,0],[2,1.72,0]],"ltp":1.57,"tv":688.46,"id":8979329}]}]}
{"op":"mcm","clk":"1009181956","pt":1580642565712,"mc":[{"id":"1.168224338","rc":[{"batb":[[0,2.4,29.41],[1,2.34,17.78],[2,1.92,394.91]],"ltp":4.8,"tv":29.41,"id":2397396},{"batb":[[0,1.59,70.58],[1,1.52,36.51],[2,1.4,451]],"ltp":1.57,"tv":688.46,"id":8979329}]}]}
{"op":"mcm","clk":"1009182101","pt":1580642566613,"mc":[{"id":"1.168224338","rc":[{"batb":[[0,2.34,17.78],[1,1.92,394.91],[2,1.01,15.52]],"ltp":4.8,"tv":29.41,"id":2397396},{"batb":[[0,1.52,36.51],[1,1.4,451],[2,1.01,15.51]],"ltp":1.57,"tv":688.46,"id":8979329}]}]}
{"op":"mcm","clk":"1009182339","pt":1580642568173,"mc":[{"id":"1.168224338","rc":[{"batb":[[0,1.54,212.48],[1,1.53,160.84],[2,1.52,36.51]],"batl":[[0,1.75,199.39],[1,1.77,190.36]],"ltp":1.57,"tv":688.46,"id":8979329}]}]}
{"op":"mcm","clk":"1009183173","pt":1580642574003,"mc":[{"id":"1.168224338","rc":[{"batb":[[1,1.01,15.52],[2,1.01,0]],"ltp":4.8,"tv":29.41,"id":2397396}]}]}
{"op":"mcm","clk":"1009183326","pt":1580642575007,"mc":[{"id":"1.168224338","rc":[{"batl":[[0,1.6,246.82],[1,1.61,130.73]],"ltp":1.57,"tv":688.46,"id":8979329}]}]}
{"op":"mcm","clk":"1009183491","pt":1580642576016,"mc":[{"id":"1.168224338","rc":[{"batb":[[0,2.7,12.2],[1,2.54,26.89],[2,2.42,16.37]],"batl":[[0,2.92,21.85]],"ltp":4.8,"tv":29.41,"id":2397396},{"batb":[[2,1.52,117.17]],"batl":[[2,1.64,42.01]],"ltp":1.57,"tv":688.46,"id":8979329}]}]}
{"op":"mcm","clk":"1009185885","pt":1580642592331,"mc":[{"id":"1.168224338","rc":[{"batb":[[0,1.52,117.17],[1,1.38,54.61],[2,1.34,465.43]],"batl":[[0,1.64,42.01],[1,1.61,0],[2,1.64,0]],"ltp":1.57,"tv":688.46,"id":8979329}]}]}
{"op":"mcm","clk":"1009185939","pt":1580642592601,"mc":[{"id":"1.168224338","rc":[{"batb":[[0,2.42,16.37],[1,2.04,394.09],[2,1.01,15.52]],"ltp":4.8,"tv":29.41,"id":2397396},{"batb":[[0,1.38,54.61],[1,1.34,465.43],[2,1.01,15.51]],"ltp":1.57,"tv":688.46,"id":8979329}]}]}
{"op":"mcm","clk":"1009186293","pt":1580642595109,"mc":[{"id":"1.168224338","rc":[{"batb":[[0,1.39,378.9],[1,1.38,307.12],[2,1.34,465.43]],"batl":[[0,1.72,123.82],[1,1.74,201.73]],"ltp":1.57,"tv":688.46,"id":8979329}]}]}
{"op":"mcm","clk":"1009186873","pt":1580642599244,"mc":[{"id":"1.168224338","rc":[{"batb":[[1,1.01,15.52],[2,1.01,0]],"ltp":4.8,"tv":29.41,"id":2397396},{"batb":[[2,1.01,15.51]],"ltp":1.57,"tv":688.46,"id":8979329}]}]}
{"op":"mcm","clk":"1009187051","pt":1580642600329,"mc":[{"id":"1.168224338","rc":[{"batl":[[0,1.44,278.78],[1,1.45,195.9]],"ltp":1.57,"tv":688.46,"id":8979329}]}]}
{"op":"mcm","clk":"1009187148","pt":1580642601146,"mc":[{"id":"1.168224338","rc":[{"batb":[[0,3.25,18.49],[1,2.74,11.72],[2,1.01,15.52]],"ltp":4.8,"tv":29.41,"id":2397396},{"batb":[[2,1.22,103.62]],"ltp":1.57,"tv":688.46,"id":8979329}]}]}
{"op":"mcm","clk":"1009187316","pt":1580642602312,"mc":[{"id":"1.168224338","rc":[{"batb":[[1,3.05,20.16],[2,2.74,11.72]],"batl":[[0,3.55,15.96]],"ltp":4.8,"tv":29.41,"id":2397396},{"batb":[[0,1.39,486.44]],"batl":[[2,1.49,42.01]],"ltp":1.57,"tv":688.46,"id":8979329}]}]}
{"op":"mcm","clk":"1009187488","pt":1580642603436,"mc":[{"id":"1.168224338","rc":[{"batb":[[2,1.25,505.09]],"ltp":1.57,"tv":688.46,"id":8979329}]}]}
{"op":"mcm","clk":"1009189881","pt":1580642619892,"mc":[{"id":"1.168224338","rc":[{"batb":[[0,3.05,20.16],[1,2.74,11.72],[2,2.3,385.09]],"ltp":4.8,"tv":29.41,"id":2397396},{"batb":[[0,1.39,107.54],[1,1.25,505.09],[2,1.22,103.62]],"batl":[[0,1.49,42.01],[1,1.45,0],[2,1.49,0]],"ltp":1.57,"tv":688.46,"id":8979329}]}]}
{"op":"mcm","clk":"1009190006","pt":1580642620646,"mc":[{"id":"1.168224338","rc":[{"batb":[[0,2.74,11.72],[1,2.3,385.09],[2,1.01,15.52]],"ltp":4.8,"tv":29.41,"id":2397396},{"batb":[[0,1.25,505.09],[1,1.22,103.62],[2,1.01,15.51]],"ltp":1.57,"tv":688.46,"id":8979329}]}]}
{"op":"mcm","clk":"1009190246","pt":1580642622365,"mc":[{"id":"1.168224338","rc":[{"batb":[[1,1.24,281],[2,1.23,470.94]],"batl":[[0,1.59,197.11],[1,1.6,133.94]],"ltp":1.57,"tv":688.46,"id":8979329}]}]}
{"op":"mcm","clk":"1009190395","pt":1580642623371,"mc":[{"id":"1.168224338","rc":[{"batb":[[1,1.22,103.62],[2,1.01,15.51]],"ltp":1.57,"tv":688.46,"id":8979329}]}]}
{"op":"mcm","clk":"1009190818","pt":1580642626372,"mc":[{"id":"1.168224338","rc":[{"batb":[[0,1.36,282.74],[1,1.35,279.65],[2,1.25,505.09]],"batl":[[0,1.4,245.8],[1,1.41,221.26]],"ltp":1.57,"tv":688.46,"id":8979329}]}]}
{"op":"mcm","clk":"1009190943","pt":1580642627275,"mc":[{"id":"1.168224338","rc":[{"batb":[[0,1.25,505.09],[1,1.22,103.62],[2,1.01,15.51]],"ltp":1.57,"tv":688.46,"id":8979329}]}]}
{"op":"mcm","clk":"1009191360","pt":1580642630184,"mc":[{"id":"1.168224338","rc":[{"batb":[[1,1.24,281],[2,1.23,470.94]],"batl":[[0,1.59,197.11],[1,1.6,133.94]],"ltp":1.57,"tv":688.46,"id":8979329}]}]}
{"op":"mcm","clk":"1009191998","pt":1580642634368,"mc":[{"id":"1.168224338","rc":[{"batb":[[1,1.01,15.52],[2,1.01,0]],"ltp":4.8,"tv":29.41,"id":2397396},{"batb":[[0,1.24,281],[1,1.23,470.94],[2,1.22,103.62]],"ltp":1.57,"tv":688.46,"id":8979329}]}]}
{"op":"mcm","clk":"1009192137","pt":1580642635262,"mc":[{"id":"1.168224338","rc":[{"batl":[[0,1.27,423.78],[1,1.28,352.34]],"ltp":1.57,"tv":688.46,"id":8979329}]}]}
{"op":"mcm","clk":"1009192266","pt":1580642636272,"mc":[{"id":"1.168224338","rc":[{"batb":[[0,4.7,15.19],[1,4.2,12.6],[2,3.3,18.02]],"batl":[[0,5.1,10.08]],"ltp":4.8,"tv":29.41,"id":2397396},{"batb":[[0,1.24,449.04]],"batl":[[2,1.31,42.01]],"ltp":1.57,"tv":688.46,"id":8979329}]}]}
{"op":"mcm","clk":"1009194296","pt":1580642650098,"mc":[{"id":"1.168224338","rc":[{"batb":[[0,4.2,12.6],[1,3.3,18.02],[2,2.8,375.33]],"ltp":4.8,"tv":29.41,"id":2397396},{"batb":[[0,1.24,168.04],[1,1.14,627.92],[2,1.05,425.75]],"batl":[[0,1.31,42.01],[1,1.28,0],[2,1.31,0]],"ltp":1.57,"tv":688.46,"id":8979329}]}]}
{"op":"mcm","clk":"1009194410","pt":1580642651037,"mc":[{"id":"1.168224338","rc":[{"batb":[[0,3.3,18.02],[1,2.8,375.33],[2,1.01,15.52]],"ltp":4.8,"tv":29.41,"id":2397396},{"batb":[[0,1.14,627.92],[1,1.05,425.75],[2,1.01,15.51]],"ltp":1.57,"tv":688.46,"id":8979329}]}]}
{"op":"mcm","clk":"1009194500","pt":1580642651600,"mc":[{"id":"1.168224338","rc":[{"batb":[[1,1.01,15.52],[2,1.01,0]],"ltp":4.8,"tv":29.41,"id":2397396},{"batb":[[0,1.05,425.75],[1,1.01,15.51],[2,1.01,0]],"ltp":1.57,"tv":688.46,"id":8979329}]}]}
{"op":"mcm","clk":"1009194699","pt":1580642652914,"mc":[{"id":"1.168224338","rc":[{"batb":[[0,1.08,509.24],[1,1.07,683.45],[2,1.05,425.75]],"batl":[[0,1.43,167.1],[1,1.44,202.7]],"ltp":1.57,"tv":688.46,"id":8979329}]}]}
{"op":"mcm","clk":"1009195372","pt":1580642657314,"mc":[{"id":"1.168224338","rc":[{"batl":[[0,1.09,330.59],[1,1.1,838.45]],"ltp":1.57,"tv":688.46,"id":8979329}]}]}
{"op":"mcm","clk":"1009195488","pt":1580642658012,"mc":[{"id":"1.168224338","rc":[{"batb":[[0,12.5,7.87],[1,10.5,4.2],[2,8,8.66]],"ltp":4.8,"tv":29.41,"id":2397396}]}]}
{"op":"mcm","clk":"1009197882","pt":1580642674120,"mc":[{"id":"1.168224338","rc":[{"batb":[[0,1.08,468.19]],"batl":[[1,1.1,797.64]],"ltp":1.57,"tv":688.46,"id":8979329}]}]}
{"op":"mcm","clk":"1009198296","pt":1580642677219,"mc":[{"id":"1.168224338","rc":[{"batb":[[1,1.07,726.15]],"batl":[[0,1.09,371.77]],"ltp":1.57,"tv":688.46,"id":8979329}]}]}
{"op":"mcm","clk":"1009203353","pt":1580642713073,"mc":[{"id":"1.168224338","rc":[{"batb":[[1,1.07,683.45],[2,1.05,419.37]],"batl":[[0,1.09,330.59]],"ltp":1.57,"tv":688.46,"id":8979329}]}]}
{"op":"mcm","clk":"1009203793","pt":1580642716395,"mc":[{"id":"1.168224338","rc":[{"batb":[[0,1.08,528.49]],"batl":[[1,1.1,856.69]],"ltp":1.57,"tv":688.46,"id":8979329}]}]}
{"op":"mcm","clk":"1009207215","pt":1580642740244,"mc":[{"id":"1.168224338","rc":[{"batb":[[0,1.05,419.37],[1,1.03,2195.04],[2,1.01,15.51]],"ltp":1.57,"tv":688.46,"id":8979329}]}]}
{"op":"mcm","clk":"1009207278","pt":1580642740604,"mc":[{"id":"1.168224338","rc":[{"batb":[[0,8,8.66],[1,3.85,370.95],[2,1.01,15.52]],"ltp":4.8,"tv":29.41,"id":2397396},{"batb":[[0,1.03,2195.04],[1,1.01,15.51],[2,1.01,0]],"ltp":1.57,"tv":688.46,"id":8979329}]}]}
{"op":"mcm","clk":"1009207655","pt":1580642743322,"mc":[{"id":"1.168224338","rc":[{"batb":[[0,1.05,1221.56],[1,1.03,2195.04],[2,1.01,15.51]],"batl":[[0,1.15,611.09],[1,1.16,499.9]],"ltp":1.57,"tv":688.46,"id":8979329}]}]}
{"op":"mcm","clk":"1009208097","pt":1580642746336,"mc":[{"id":"1.168224338","rc":[{"batb":[[1,1.03,623.16]],"ltp":1.57,"tv":688.46,"id":8979329}]}]}
{"op":"mcm","clk":"1009208208","pt":1580642747089,"mc":[{"id":"1.168224338","rc":[{"batb":[[0,16.5,4.17],[1,10.5,11.57],[2,8,8.66]],"ltp":4.8,"tv":29.41,"id":2397396},{"batb":[[2,1.02,897.92]],"batl":[[0,1.07,1183.58]],"ltp":1.57,"tv":688.46,"id":8979329}]}]}
{"op":"mcm","clk":"1009208331","pt":1580642747939,"mc":[{"id":"1.168224338","rc":[{"batb":[[1,13.5,3.36],[2,10.5,11.57]],"ltp":4.8,"tv":29.41,"id":2397396},{"batl":[[1,1.08,42.01]],"ltp":1.57,"tv":688.46,"id":8979329}]}]}
{"op":"mcm","clk":"1009208478","pt":1580642748894,"mc":[{"id":"1.168224338","rc":[{"batb":[[2,1.02,3082]],"ltp":1.57,"tv":688.46,"id":8979329}]}]}
{"op":"mcm","clk":"1009209299","pt":1580642754320,"mc":[{"id":"1.168224338","rc":[{"batb":[[0,1.03,623.16],[1,1.02,3069.09],[2,1.01,15.51]],"batl":[[0,1.08,42.01],[1,1.08,0]],"ltp":1.57,"tv":688.46,"id":8979329}]}]}
{"op":"mcm","clk":"1009209363","pt":1580642754749,"mc":[{"id":"1.168224338","rc":[{"batb":[[0,10.5,11.57],[1,3.85,370.95],[2,1.01,15.52]],"ltp":4.8,"tv":29.41,"id":2397396},{"batb":[[0,1.02,3069.09],[1,1.01,15.51],[2,1.01,0]],"ltp":1.57,"tv":688.46,"id":8979329}]}]}
{"op":"mcm","clk":"1009209746","pt":1580642757330,"mc":[{"id":"1.168224338","rc":[{"batb":[[0,1.04,1203.38],[1,1.02,3069.09],[2,1.01,15.51]],"batl":[[0,1.1,200.29],[1,1.11,957.04]],"ltp":1.57,"tv":688.46,"id":8979329}]}]}
{"op":"mcm","clk":"1009209863","pt":1580642758139,"mc":[{"id":"1.168224338","rc":[{"batb":[[0,1.02,3069.09],[1,1.01,15.51],[2,1.01,0]],"ltp":1.57,"tv":688.46,"id":8979329}]}]}
{"op":"mcm","clk":"1009210131","pt":1580642759911,"mc":[{"id":"1.168224338","rc":[{"batb":[[0,1.06,1210.03],[1,1.02,3069.09],[2,1.01,15.51]],"batl":[[0,1.08,1187.63]],"ltp":1.57,"tv":688.46,"id":8979329}]}]}
{"op":"mcm","clk":"1009210433","pt":1580642762164,"mc":[{"id":"1.168224338","rc":[{"batb":[[0,1.02,3069.09],[1,1.01,15.51],[2,1.01,0]],"ltp":1.57,"tv":688.46,"id":8979329}]}]}
{"op":"mcm","clk":"1009210817","pt":1580642765061,"mc":[{"id":"1.168224338","rc":[{"batb":[[0,1.04,1209.09],[1,1.02,3069.09],[2,1.01,15.51]],"batl":[[0,1.1,194.96],[1,1.11,962.32]],"ltp":1.57,"tv":688.46,"id":8979329}]}]}
{"op":"mcm","clk":"1009212530","pt":1580642776751,"mc":[{"id":"1.168224338","rc":[{"batb":[[0,1.02,3069.09],[1,1.01,15.51],[2,1.01,0]],"ltp":1.57,"tv":688.46,"id":8979329}]}]}
{"op":"mcm","clk":"1009212953","pt":1580642779237,"mc":[{"id":"1.168224338","rc":[{"batb":[[0,1.02,885.01]],"ltp":1.57,"tv":688.46,"id":8979329}]}]}
{"op":"mcm","clk":"1009213097","pt":1580642780244,"mc":[{"id":"1.168224338","rc":[{"batb":[[1,6.4,14.32],[2,3.85,370.95]],"ltp":4.8,"tv":29.41,"id":2397396},{"batb":[[0,1.09,507.97],[1,1.08,674.95],[2,1.07,336.68]],"ltp":1.57,"tv":688.46,"id":8979329}]}]}
{"op":"mcm","clk":"1009213414","pt":1580642782375,"mc":[{"id":"1.168224338","rc":[{"batb":[[1,9.8,4.2],[2,6.4,14.32]],"batl":[[0,12.5,3.36]],"ltp":4.8,"tv":29.41,"id":2397396}]}]}
{"op":"mcm","clk":"1009215633","pt":1580642797169,"mc":[{"id":"1.168224338","rc":[{"batb":[[0,9.8,4.2],[1,6.4,14.32],[2,3.85,370.95]],"ltp":4.8,"tv":29.41,"id":2397396},{"batb":[[0,1.04,1807.71],[1,1.01,15.51],[2,1.07,0]],"ltp":1.57,"tv":688.46,"id":8979329}]}]}
{"op":"mcm","clk":"1009215923","pt":1580642798606,"mc":[{"id":"1.168224338","rc":[{"batb":[[0,6.4,14.32],[1,3.85,370.95],[2,1.01,15.52]],"ltp":4.8,"tv":29.41,"id":2397396}]}]}
{"op":"mcm","clk":"1009216319","pt":1580642801015,"mc":[{"id":"1.168224338","rc":[{"batb":[[0,1.04,544.71]],"ltp":1.57,"tv":688.46,"id":8979329}]}]}
{"op":"mcm","clk":"1009216467","pt":1580642802233,"mc":[{"id":"1.168224338","rc":[{"batb":[[0,1.1,843.19],[1,1.09,325.8],[2,1.04,544.71]],"batl":[[0,1.12,756.54],[1,1.13,385.23]],"ltp":1.57,"tv":688.46,"id":8979329}]}]}
{"op":"mcm","clk":"1009216882","pt":1580642804531,"mc":[{"id":"1.168224338","rc":[{"batb":[[2,1.05,1069.56]],"ltp":1.57,"tv":688.46,"id":8979329}]}]}
{"op":"mcm","clk":"1009217253","pt":1580642807213,"mc":[{"id":"1.168224338","rc":[{"batb":[[0,1.05,1069.56],[1,1.04,544.71],[2,1.01,15.51]],"ltp":1.57,"tv":688.46,"id":8979329}]}]}
{"op":"mcm","clk":"1009217806","pt":1580642810347,"mc":[{"id":"1.168224338","rc":[{"batb":[[0,1.06,511.91],[1,1.05,1774.33],[2,1.04,544.71]],"batl":[[0,1.18,521.15],[1,1.19,560.17]],"ltp":1.57,"tv":688.46,"id":8979329}]}]}
{"op":"mcm","clk":"1009219626","pt":1580642821255,"mc":[{"id":"1.168224338","rc":[{"batb":[[1,1.05,704.77]],"batl":[[0,1.07,782.58],[1,1.08,412.29]],"ltp":1.57,"tv":688.46,"id":8979329}]}]}
{"op":"mcm","clk":"1009219832","pt":1580642822383,"mc":[{"id":"1.168224338","rc":[{"batb":[[0,15,5.19],[1,13,3.36],[2,9.2,15.97]],"ltp":4.8,"tv":29.41,"id":2397396},{"batl":[[1,1.08,454.3]],"ltp":1.57,"tv":688.46,"id":8979329}]}]}
{"op":"mcm","clk":"1009222845","pt":1580642843084,"mc":[{"id":"1.168224338","rc":[{"batb":[[0,9.2,15.97],[1,3.85,370.95],[2,1.01,15.52]],"ltp":4.8,"tv":29.41,"id":2397396},{"batb":[[0,1.02,3056.27],[1,1.01,15.51],[2,1.04,0]],"ltp":1.57,"tv":688.46,"id":8979329}]}]}
{"op":"mcm","clk":"1009223400","pt":1580642846300,"mc":[{"id":"1.168224338","rc":[{"batb":[[0,1.04,757.74],[1,1.03,480.18],[2,1.02,3056.27]],"ltp":1.57,"tv":688.46,"id":8979329}]}]}
{"op":"mcm","clk":"1009223551","pt":1580642847284,"mc":[{"id":"1.168224338","rc":[{"batb":[[2,1.02,872.19]],"ltp":1.57,"tv":688.46,"id":8979329}]}]}
{"op":"mcm","clk":"1009223891","pt":1580642849376,"mc":[{"id":"1.168224338","rc":[{"batb":[[0,21,4.48],[1,15,5.19],[2,3.85,370.95]],"ltp":4.8,"tv":29.41,"id":2397396},{"batl":[[0,1.05,1221.56]],"ltp":1.57,"tv":688.46,"id":8979329}]}]}
{"op":"mcm","clk":"1009225761","pt":1580642860714,"mc":[{"id":"1.168224338","rc":[{"batb":[[0,15,5.19],[1,3.85,370.95],[2,1.01,15.52]],"ltp":4.8,"tv":29.41,"id":2397396},{"batb":[[0,1.03,480.18],[1,1.01,3892.94],[2,1.02,0]],"ltp":1.57,"tv":688.46,"id":8979329}]}]}
{"op":"mcm","clk":"1009226201","pt":1580642863789,"mc":[{"id":"1.168224338","rc":[{"batb":[[0,1.03,1245.28]],"batl":[[0,1.07,1198.73]],"ltp":1.57,"tv":688.46,"id":8979329}]}]}
{"op":"mcm","clk":"1009226287","pt":1580642864426,"mc":[{"id":"1.168224338","rc":[{"batb":[[0,1.01,3892.94],[1,1.01,0]],"ltp":1.57,"tv":688.46,"id":8979329}]}]}
{"op":"mcm","clk":"1009226757","pt":1580642867399,"mc":[{"id":"1.168224338","rc":[{"batb":[[0,1.04,1233.3],[1,1.01,3892.94]],"batl":[[0,1.05,474.2],[1,1.06,740.3]],"ltp":1.57,"tv":688.46,"id":8979329}]}]}
{"op":"mcm","clk":"1009227037","pt":1580642869099,"mc":[{"id":"1.168224338","rc":[{"batb":[[0,1.01,3892.94],[1,1.01,0]],"ltp":1.57,"tv":688.46,"id":8979329}]}]}
{"op":"mcm","clk":"1009227459","pt":1580642872027,"mc":[{"id":"1.168224338","rc":[{"batb":[[0,1.03,1245.28],[1,1.01,3892.94]],"batl":[[0,1.07,1198.73]],"ltp":1.57,"tv":688.46,"id":8979329}]}]}
{"op":"mcm","clk":"1009228652","pt":1580642880334,"mc":[{"id":"1.168224338","rc":[{"batb":[[1,1.01,15.51]],"ltp":1.57,"tv":688.46,"id":8979329}]}]}
{"op":"mcm","clk":"1009228779","pt":1580642881209,"mc":[{"id":"1.168224338","rc":[{"batb":[[0,25,4.42],[1,22,3.68],[2,15,5.19]],"ltp":4.8,"tv":29.41,"id":2397396},{"batl":[[0,1.04,1232.96]],"ltp":1.57,"tv":688.46,"id":8979329}]}]}
{"op":"mcm","clk":"1009228886","pt":1580642882030,"mc":[{"id":"1.168224338","rc":[{"batb":[[2,3.85,370.95]],"ltp":4.8,"tv":29.41,"id":2397396},{"batb":[[0,1.03,1413.32]],"ltp":1.57,"tv":688.46,"id":8979329}]}]}
{"op":"mcm","clk":"1009229081","pt":1580642883428,"mc":[{"id":"1.168224338","rc":[{"batl":[[0,160,37.1]],"ltp":4.8,"tv":29.41,"id":2397396}]}]}
{"op":"mcm","clk":"1009231408","pt":1580642900174,"mc":[{"id":"1.168224338","rc":[{"batb":[[0,22,3.68],[1,3.85,370.95],[2,1.01,15.52]],"ltp":4.8,"tv":29.41,"id":2397396},{"batb":[[0,1.03,168.04]],"ltp":1.57,"tv":688.46,"id":8979329}]}]}
{"op":"mcm","clk":"1009231492","pt":1580642900770,"mc":[{"id":"1.168224338","rc":[{"batb":[[0,1.01,15.51],[1,1.01,0]],"ltp":1.57,"tv":688.46,"id":8979329}]}]}
{"op":"mcm","clk":"1009231864","pt":1580642903387,"mc":[{"id":"1.168224338","rc":[{"batb":[[0,1.02,209.05],[1,1.01,15.51]],"ltp":1.57,"tv":688.46,"id":8979329}]}]}
{"op":"mcm","clk":"1009232082","pt":1580642905051,"mc":[{"id":"1.168224338","rc":[{"batb":[[0,1.03,1037.9],[1,1.02,209.05],[2,1.01,15.51]],"batl":[[0,1.04,1232.96]],"ltp":1.57,"tv":688.46,"id":8979329}]}]}
{"op":"mcm","clk":"1009232299","pt":1580642906780,"mc":[{"id":"1.168224338","rc":[{"batb":[[0,1.02,209.05],[1,1.01,15.51],[2,1.01,0]],"ltp":1.57,"tv":688.46,"id":8979329}]}]}
{"op":"mcm","clk":"1009232836","pt":1580642910559,"mc":[{"id":"1.168224338","rc":[{"batb":[[0,1.02,1257.13]],"batl":[[0,1.05,1221.21]],"ltp":1.57,"tv":688.46,"id":8979329}]}]}
{"op":"mcm","clk":"1009233698","pt":1580642916266,"mc":[{"id":"1.168224338","rc":[{"batb":[[1,1.01,15.52],[2,1.01,0]],"ltp":4.8,"tv":29.41,"id":2397396},{"batl":[[0,1.03,1244.92]],"ltp":1.57,"tv":688.46,"id":8979329}]}]}
{"op":"mcm","clk":"1009233866","pt":1580642917386,"mc":[{"id":"1.168224338","rc":[{"batb":[[0,25,4.13]],"ltp":4.8,"tv":29.41,"id":2397396}]}]}
{"op":"mcm","clk":"1009234193","pt":1580642919676,"mc":[{"id":"1.168224338","rc":[{"batb":[[1,4.4,375.46],[2,1.01,15.52]],"ltp":4.8,"tv":29.41,"id":2397396}]}]}
{"op":"mcm","clk":"1009235644","pt":1580642929372,"mc":[{"id":"1.168224338","rc":[{"batb":[[0,1.01,15.51],[1,1.01,0]],"ltp":1.57,"tv":688.46,"id":8979329}]}]}
{"op":"mcm","clk":"1009235889","pt":1580642931187,"mc":[{"id":"1.168224338","rc":[{"batb":[[1,1.01,15.52],[2,1.01,0]],"ltp":4.8,"tv":29.41,"id":2397396}]}]}
{"op":"mcm","clk":"1009236060","pt":1580642932313,"mc":[{"id":"1.168224338","rc":[{"batb":[[0,1.01,1285.09]],"batl":[[0,1.04,1232.96]],"ltp":1.57,"tv":688.46,"id":8979329}]}]}
{"op":"mcm","clk":"1009236184","pt":1580642933109,"mc":[{"id":"1.168224338","rc":[{"batb":[[0,1.01,15.51]],"ltp":1.57,"tv":688.46,"id":8979329}]}]}
{"op":"mcm","clk":"1009236510","pt":1580642935292,"mc":[{"id":"1.168224338","rc":[{"batb":[[0,1.02,1257.13],[1,1.01,15.51]],"batl":[[0,1.03,1244.92]],"ltp":1.57,"tv":688.46,"id":8979329}]}]}
{"op":"mcm","clk":"1009236797","pt":1580642937106,"mc":[{"id":"1.168224338","rc":[{"batb":[[0,1.01,15.51],[1,1.01,0]],"ltp":1.57,"tv":688.46,"id":8979329}]}]}
{"op":"mcm","clk":"1009237289","pt":1580642940314,"mc":[{"id":"1.168224338","rc":[{"batb":[[0,1.01,1285.09]],"batl":[[0,1.04,1232.96]],"ltp":1.57,"tv":688.46,"id":8979329}]}]}
{"op":"mcm","clk":"1009237367","pt":1580642940710,"mc":[{"id":"1.168224338","rc":[{"batb":[[0,1.01,15.51]],"ltp":1.57,"tv":688.46,"id":8979329}]}]}
{"op":"mcm","clk":"1009238014","pt":1580642944306,"mc":[{"id":"1.168224338","rc":[{"batb":[[1,22,3.75],[2,1.01,15.52]],"ltp":4.8,"tv":29.41,"id":2397396},{"batb":[[0,1.03,1244.92],[1,1.01,15.51]],"ltp":1.57,"tv":688.46,"id":8979329}]}]}
{"op":"mcm","clk":"1009238278","pt":1580642946009,"mc":[{"id":"1.168224338","rc":[{"batb":[[2,4.3,371.17]],"batl":[[0,160,37.1]],"ltp":4.8,"tv":29.41,"id":2397396},{"batb":[[0,1.03,1412.96]],"ltp":1.57,"tv":688.46,"id":8979329}]}]}
{"op":"mcm","clk":"1009239908","pt":1580642956338,"mc":[{"id":"1.168224338","rc":[{"batb":[[0,22,3.75],[1,4.3,371.17],[2,1.01,15.52]],"ltp":4.8,"tv":29.41,"id":2397396},{"batb":[[0,1.03,168.04]],"ltp":1.57,"tv":688.46,"id":8979329}]}]}
{"op":"mcm","clk":"1009239991","pt":1580642956880,"mc":[{"id":"1.168224338","rc":[{"batb":[[0,1.01,15.51],[1,1.01,0]],"ltp":1.57,"tv":688.46,"id":8979329}]}]}
{"op":"mcm","clk":"1009240421","pt":1580642959156,"mc":[{"id":"1.168224338","rc":[{"batb":[[0,1.02,1257.13],[1,1.01,15.51]],"batl":[[0,1.05,1221.21]],"ltp":1.57,"tv":688.46,"id":8979329}]}]}
{"op":"mcm","clk":"1009240649","pt":1580642960356,"mc":[{"id":"1.168224338","rc":[{"batb":[[0,1.02,746.62]],"ltp":1.57,"tv":688.46,"id":8979329}]}]}
{"op":"mcm","clk":"1009240789","pt":1580642961159,"mc":[{"id":"1.168224338","rc":[{"batb":[[0,1.03,505.55],[1,1.02,746.62],[2,1.01,15.51]],"batl":[[0,1.04,1232.96]],"ltp":1.57,"tv":688.46,"id":8979329}]}]}
{"op":"mcm","clk":"1009241375","pt":1580642964975,"mc":[{"id":"1.168224338","rc":[{"batb":[[0,1.02,746.62],[1,1.01,15.51],[2,1.01,0]],"ltp":1.57,"tv":688.46,"id":8979329}]}]}
{"op":"mcm","clk":"1009241957","pt":1580642968968,"mc":[{"id":"1.168224338","rc":[{"batb":[[0,1.02,1257.13]],"batl":[[0,1.05,1221.21]],"ltp":1.57,"tv":688.46,"id":8979329}]}]}
{"op":"mcm","clk":"1009243916","pt":1580642982003,"mc":[{"id":"1.168224338","rc":[{"batb":[[0,1.01,15.51],[1,1.01,0]],"ltp":1.57,"tv":688.46,"id":8979329}]}]}
{"op":"mcm","clk":"1009244370","pt":1580642985002,"mc":[{"id":"1.168224338","rc":[{"batb":[[0,1.04,510.38],[1,1.03,729.58],[2,1.01,15.51]],"ltp":1.57,"tv":688.46,"id":8979329}]}]}
{"op":"mcm","clk":"1009244579","pt":1580642986290,"mc":[{"id":"1.168224338","rc":[{"batb":[[1,19.5,5.59],[2,4.3,371.17]],"ltp":4.8,"tv":29.41,"id":2397396}]}]}
{"op":"mcm","clk":"1009244812","pt":1580642987790,"mc":[{"id":"1.168224338","rc":[{"batb":[[2,1.01,4081.97]],"ltp":1.57,"tv":688.46,"id":8979329}]}]}
{"op":"mcm","clk":"1009246611","pt":1580642999195,"mc":[{"id":"1.168224338","rc":[{"batb":[[0,1.04,265.01]],"ltp":1.57,"tv":688.46,"id":8979329}]}]}
{"op":"mcm","clk":"1009246934","pt":1580643001296,"mc":[{"id":"1.168224338","rc":[{"batb":[[0,1.03,729.58],[1,1.01,4081.97],[2,1.01,0]],"ltp":1.57,"tv":688.46,"id":8979329}]}]}
{"op":"mcm","clk":"1009246990","pt":1580643001617,"mc":[{"id":"1.168224338","rc":[{"batb":[[0,19.5,5.59],[1,4.3,371.17],[2,1.01,15.52]],"ltp":4.8,"tv":29.41,"id":2397396}]}]}
{"op":"mcm","clk":"1009247428","pt":1580643004338,"mc":[{"id":"1.168224338","rc":[{"batb":[[1,1.02,554.01],[2,1.01,4081.97]],"batl":[[0,1.06,1209.69]],"ltp":1.57,"tv":688.46,"id":8979329}]}]}
{"op":"mcm","clk":"1009248770","pt":1580643012839,"mc":[{"id":"1.168224338","rc":[{"batb":[[2,1.01,15.51]],"ltp":1.57,"tv":688.46,"id":8979329}]}]}
{"op":"mcm","clk":"1009248918","pt":1580643013825,"mc":[{"id":"1.168224338","rc":[{"batl":[[0,1.04,1232.96]],"ltp":1.57,"tv":688.46,"id":8979329}]}]}
{"op":"mcm","clk":"1009249161","pt":1580643015324,"mc":[{"id":"1.168224338","rc":[{"batb":[[0,26,3.58],[1,21,4.11],[2,4.3,371.17]],"ltp":4.8,"tv":29.41,"id":2397396}]}]}
{"op":"mcm","clk":"1009249379","pt":1580643016648,"mc":[{"id":"1.168224338","rc":[{"batl":[[0,160,37.1]],"ltp":4.8,"tv":29.41,"id":2397396}]}]}
{"op":"mcm","clk":"1009252135","pt":1580643033064,"mc":[{"id":"1.168224338","rc":[{"batb":[[0,21,4.11],[1,4.3,371.17],[2,1.01,15.52]],"ltp":4.8,"tv":29.41,"id":2397396},{"batb":[[0,1.01,15.51],[1,1.02,0],[2,1.01,0]],"ltp":1.57,"tv":688.46,"id":8979329}]}]}
{"op":"mcm","clk":"1009252299","pt":1580643034059,"mc":[{"id":"1.168224338","rc":[{"batb":[[1,1.01,15.52],[2,1.01,0]],"ltp":4.8,"tv":29.41,"id":2397396}]}]}
{"op":"mcm","clk":"1009252591","pt":1580643035874,"mc":[{"id":"1.168224338","rc":[{"batl":[[0,1.05,1221.21]],"ltp":1.57,"tv":688.46,"id":8979329}]}]}
{"op":"mcm","clk":"1009253026","pt":1580643038369,"mc":[{"id":"1.168224338","rc":[{"batb":[[0,1.04,753.98],[1,1.03,483.61],[2,1.01,15.51]],"ltp":1.57,"tv":688.46,"id":8979329}]}]}
{"op":"mcm","clk":"1009253186","pt":1580643039270,"mc":[{"id":"1.168224338","rc":[{"batb":[[1,18.5,6.14],[2,1.01,15.52]],"ltp":4.8,"tv":29.41,"id":2397396},{"batb":[[2,1.02,923.41]],"ltp":1.57,"tv":688.46,"id":8979329}]}]}
{"op":"mcm","clk":"1009253313","pt":1580643039967,"mc":[{"id":"1.168224338","rc":[{"batb":[[2,4.1,374.13]],"ltp":4.8,"tv":29.41,"id":2397396}]}]}
{"op":"mcm","clk":"1009255307","pt":1580643052272,"mc":[{"id":"1.168224338","rc":[{"batb":[[0,18.5,6.14],[1,4.1,374.13],[2,1.01,15.52]],"ltp":4.8,"tv":29.41,"id":2397396},{"batb":[[0,1.03,483.61],[1,1.01,4081.97],[2,1.02,0]],"ltp":1.57,"tv":688.46,"id":8979329}]}]}
{"op":"mcm","clk":"1009255734","pt":1580643054984,"mc":[{"id":"1.168224338","rc":[{"batb":[[0,1.03,606.92],[1,1.02,644.25],[2,1.01,4081.97]],"batl":[[0,1.06,1209.69]],"ltp":1.57,"tv":688.46,"id":8979329}]}]}
{"op":"mcm","clk":"1009256419","pt":1580643059181,"mc":[{"id":"1.168224338","rc":[{"batb":[[2,1.01,15.51]],"ltp":1.57,"tv":688.46,"id":8979329}]}]}
{"op":"mcm","clk":"1009256560","pt":1580643059980,"mc":[{"id":"1.168224338","rc":[{"batl":[[0,1.04,1232.96]],"ltp":1.57,"tv":688.46,"id":8979329}]}]}
{"op":"mcm","clk":"1009256766","pt":1580643061187,"mc":[{"id":"1.168224338","rc":[{"batb":[[0,26,3.58],[1,21,4.11],[2,4.1,374.13]],"ltp":4.8,"tv":29.41,"id":2397396}]}]}
{"op":"mcm","clk":"1009257054","pt":1580643063091,"mc":[{"id":"1.168224338","rc":[{"batl":[[0,160,37.1]],"ltp":4.8,"tv":29.41,"id":2397396}]}]}
{"op":"mcm","clk":"1009258870","pt":1580643074845,"mc":[{"id":"1.168224338","rc":[{"batb":[[0,21,4.11],[1,4.1,374.13],[2,1.01,15.52]],"ltp":4.8,"tv":29.41,"id":2397396},{"batb":[[0,1.01,15.51],[1,1.02,0],[2,1.01,0]],"ltp":1.57,"tv":688.46,"id":8979329}]}]}
{"op":"mcm","clk":"1009259254","pt":1580643077392,"mc":[{"id":"1.168224338","rc":[{"batb":[[1,1.01,15.52],[2,1.01,0]],"ltp":4.8,"tv":29.41,"id":2397396}]}]}
{"op":"mcm","clk":"1009259690","pt":1580643080121,"mc":[{"id":"1.168224338","rc":[{"batb":[[0,1.02,1257.13],[1,1.01,15.51]],"batl":[[0,1.04,1232.96]],"ltp":1.57,"tv":688.46,"id":8979329}]}]}
{"op":"mcm","clk":"1009260067","pt":1580643082384,"mc":[{"id":"1.168224338","rc":[{"batb":[[0,1.01,15.51],[1,1.01,0]],"ltp":1.57,"tv":688.46,"id":8979329}]}]}
{"op":"mcm","clk":"1009260525","pt":1580643085312,"mc":[{"id":"1.168224338","rc":[{"batb":[[0,1.01,1285.09]],"batl":[[0,1.05,1221.21]],"ltp":1.57,"tv":688.46,"id":8979329}]}]}
{"op":"mcm","clk":"1009262374","pt":1580643097350,"mc":[{"id":"1.168224338","rc":[{"batb":[[0,27,3.17]],"ltp":4.8,"tv":29.41,"id":2397396},{"batl":[[0,1.02,1110.94]],"ltp":1.57,"tv":688.46,"id":8979329}]}]}
{"op":"mcm","clk":"1009262568","pt":1580643098521,"mc":[{"id":"1.168224338","rc":[{"batb":[[1,4.5,371.06],[2,1.01,15.52]],"ltp":4.8,"tv":29.41,"id":2397396}]}]}
{"op":"mcm","clk":"1009264843","pt":1580643113857,"mc":[{"id":"1.168224338","rc":[{"batb":[[0,1.01,15.51]],"ltp":1.57,"tv":688.46,"id":8979329}]}]}
{"op":"mcm","clk":"1009265006","pt":1580643114976,"mc":[{"id":"1.168224338","rc":[{"batb":[[1,1.01,15.52],[2,1.01,0]],"ltp":4.8,"tv":29.41,"id":2397396}]}]}
{"op":"mcm","clk":"1009265329","pt":1580643117266,"mc":[{"id":"1.168224338","rc":[{"batl":[[0,1.04,1232.96]],"ltp":1.57,"tv":688.46,"id":8979329}]}]}
{"op":"mcm","clk":"1009266543","pt":1580643125149,"mc":[{"id":"1.168224338","rc":[{"batb":[[0,1.01,1285.09]],"batl":[[0,1.02,1257.13]],"ltp":1.57,"tv":688.46,"id":8979329}]}]}
{"op":"mcm","clk":"1009266645","pt":1580643125944,"mc":[{"id":"1.168224338","rc":[{"batb":[[0,1.01,15.51]],"ltp":1.57,"tv":688.46,"id":8979329}]}]}
{"op":"mcm","clk":"1009266827","pt":1580643127341,"mc":[{"id":"1.168224338","rc":[{"batb":[[1,4.6,368.39],[2,1.01,15.52]],"ltp":4.8,"tv":29.41,"id":2397396}]}]}
{"op":"mcm","clk":"1009266925","pt":1580643128041,"mc":[{"id":"1.168224338","rc":[{"batb":[[1,1.01,15.52],[2,1.01,0]],"ltp":4.8,"tv":29.41,"id":2397396}]}]}
{"op":"mcm","clk":"1009267075","pt":1580643129152,"mc":[{"id":"1.168224338","rc":[{"batl":[[0,1.04,1232.96]],"ltp":1.57,"tv":688.46,"id":8979329}]}]}
{"op":"mcm","clk":"1009267632","pt":1580643133167,"mc":[{"id":"1.168224338","rc":[{"batb":[[1,21,4.11],[2,1.01,15.52]],"ltp":4.8,"tv":29.41,"id":2397396},{"batb":[[0,1.03,539.71],[1,1.02,712.13],[2,1.01,15.51]],"ltp":1.57,"tv":688.46,"id":8979329}]}]}
{"op":"mcm","clk":"1009267903","pt":1580643135276,"mc":[{"id":"1.168224338","rc":[{"batb":[[2,4.3,371.17]],"batl":[[0,160,37.1]],"ltp":4.8,"tv":29.41,"id":2397396}]}]}
{"op":"mcm","clk":"1009270084","pt":1580643149379,"mc":[{"id":"1.168224338","rc":[{"batb":[[0,21,4.11],[1,4.3,371.17],[2,1.01,15.52]],"ltp":4.8,"tv":29.41,"id":2397396},{"batb":[[0,1.01,15.51],[1,1.02,0],[2,1.01,0]],"ltp":1.57,"tv":688.46,"id":8979329}]}]}
{"op":"mcm","clk":"1009270432","pt":1580643151273,"mc":[{"id":"1.168224338","rc":[{"batb":[[1,1.01,15.52],[2,1.01,0]],"ltp":4.8,"tv":29.41,"id":2397396}]}]}
{"op":"mcm","clk":"1009270620","pt":1580643152115,"mc":[{"id":"1.168224338","rc":[{"batl":[[0,1.05,1221.21]],"ltp":1.57,"tv":688.46,"id":8979329}]}]}
{"op":"mcm","clk":"1009271114","pt":1580643155215,"mc":[{"id":"1.168224338","rc":[{"batb":[[1,18.5,6.06],[2,1.01,15.52]],"ltp":4.8,"tv":29.41,"id":2397396},{"batb":[[0,1.04,643.11],[1,1.03,595.57],[2,1.02,918.38]],"ltp":1.57,"tv":688.46,"id":8979329}]}]}
{"op":"mcm","clk":"1009271299","pt":1580643156406,"mc":[{"id":"1.168224338","rc":[{"batb":[[2,4.1,374.13]],"ltp":4.8,"tv":29.41,"id":2397396}]}]}
{"op":"mcm","clk":"1009272204","pt":1580643162127,"mc":[{"id":"1.168224338","rc":[{"batb":[[0,1.04,592.45]],"ltp":1.57,"tv":688.46,"id":8979329}]}]}
{"op":"mcm","clk":"1009272751","pt":1580643165369,"mc":[{"id":"1.168224338","rc":[{"batb":[[0,18.5,6.06],[1,4.1,374.13],[2,1.01,15.52]],"ltp":4.8,"tv":29.41,"id":2397396},{"batb":[[0,1.03,404.88],[1,1.01,4081.97],[2,1.02,0]],"ltp":1.57,"tv":688.46,"id":8979329}]}]}
{"op":"mcm","clk":"1009273195","pt":1580643168016,"mc":[{"id":"1.168224338","rc":[{"batb":[[1,1.02,848.27],[2,1.01,4081.97]],"batl":[[0,1.06,1209.69]],"ltp":1.57,"tv":688.46,"id":8979329}]}]}
{"op":"mcm","clk":"1009276981","pt":1580643192937,"mc":[{"id":"1.168224338","rc":[{"batb":[[0,1.01,4081.97],[1,1.02,0],[2,1.01,0]],"ltp":1.57,"tv":688.46,"id":8979329}]}]}
{"op":"mcm","clk":"1009277485","pt":1580643196207,"mc":[{"id":"1.168224338","rc":[{"batb":[[1,9.8,14.16],[2,4.1,374.13]],"ltp":4.8,"tv":29.41,"id":2397396},{"batb":[[0,1.04,1232.96],[1,1.03,751.57],[2,1.02,932.74]],"ltp":1.57,"tv":688.46,"id":8979329}]}]}
{"op":"mcm","clk":"1009277661","pt":1580643197329,"mc":[{"id":"1.168224338","rc":[{"batb":[[2,1.01,4081.97]],"ltp":1.57,"tv":688.46,"id":8979329}]}]}
{"op":"mcm","clk":"1009278017","pt":1580643199638,"mc":[{"id":"1.168224338","rc":[{"batb":[[0,1.04,1997.08]],"ltp":1.57,"tv":688.46,"id":8979329}]}]}
{"op":"mcm","clk":"1009279753","pt":1580643209170,"mc":[{"id":"1.168224338","rc":[{"trd":[[1.04,1028.4]],"batb":[[0,1.04,1482.88]],"ltp":1.04,"tv":1716.86,"id":8979329}],"tv":1746.28}]}
{"op":"mcm","clk":"1009280329","pt":1580643212684,"mc":[{"id":"1.168224338","rc":[{"batb":[[0,1.04,1997.08]],"ltp":1.04,"tv":1716.86,"id":8979329}]}]}
{"op":"mcm","clk":"1009282542","pt":1580643225775,"mc":[{"id":"1.168224338","rc":[{"batl":[[0,1.06,1212.72]],"ltp":1.04,"tv":1716.86,"id":8979329}]}]}
{"op":"mcm","clk":"1009289111","pt":1580643272356,"mc":[{"id":"1.168224338","rc":[{"trd":[[18.5,12.12]],"batb":[[0,9.8,14.16],[1,4.1,374.13],[2,1.01,15.52]],"batl":[[0,18.5,3.94]],"ltp":18.5,"tv":41.53,"id":2397396}],"tv":1758.39}]}
{"op":"mcm","clk":"1009289140","pt":1580643272570,"mc":[{"id":"1.168224338","rc":[{"batb":[[0,1.04,1232.96]],"ltp":1.04,"tv":1716.86,"id":8979329}]}]}
{"op":"mcm","clk":"1009290242","pt":1580643280966,"mc":[{"id":"1.168224338","rc":[{"batb":[[0,1.04,2804.33]],"ltp":1.04,"tv":1716.86,"id":8979329}]}]}
{"op":"mcm","clk":"1009290671","pt":1580643284274,"mc":[{"id":"1.168224338","rc":[{"batb":[[0,1.03,751.57],[1,1.01,4081.97],[2,1.01,0]],"batl":[[0,1.06,3.03]],"ltp":1.04,"tv":1716.86,"id":8979329}]}]}
{"op":"mcm","clk":"1009290776","pt":1580643284974,"mc":[{"id":"1.168224338","rc":[{"batb":[[0,1.01,4081.97],[1,1.01,0]],"ltp":1.04,"tv":1716.86,"id":8979329}]}]}
{"op":"mcm","clk":"1009291058","pt":1580643287264,"mc":[{"id":"1.168224338","rc":[{"batb":[[1,1.01,15.52],[2,1.01,0]],"ltp":18.5,"tv":41.53,"id":2397396},{"batb":[[0,1.02,1257.13],[1,1.01,15.51]],"batl":[[1,1.11,339.55],[2,1.12,808.36]],"ltp":1.04,"tv":1716.86,"id":8979329}]}]}
{"op":"mcm","clk":"1009291169","pt":1580643288167,"mc":[{"id":"1.168224338","rc":[{"trd":[[17.5,0.18]],"batb":[[0,9.4,15.19]],"batl":[[0,17.5,9.82]],"ltp":17.5,"tv":41.71,"id":2397396},{"trd":[[1.06,3.03]],"batl":[[0,1.11,339.55],[1,1.12,808.36],[2,1.12,0]],"ltp":1.06,"tv":1719.89,"id":8979329}],"tv":1761.6}]}
{"op":"mcm","clk":"1009291292","pt":1580643289040,"mc":[{"id":"1.168224338","rc":[{"trd":[[17.5,0.33]],"batl":[[0,17.5,9.67]],"ltp":17.5,"tv":41.86,"id":2397396},{"trd":[[1.06,5.56]],"ltp":1.06,"tv":1722.43,"id":8979329}],"tv":1764.29}]}
{"op":"mcm","clk":"1009291840","pt":1580643293367,"mc":[{"id":"1.168224338","rc":[{"trd":[[17.5,10]],"batb":[[0,15,5.19]],"ltp":17.5,"tv":51.53,"id":2397396},{"trd":[[1.06,165.21]],"batl":[[0,1.03,1085.27]],"ltp":1.06,"tv":1882.08,"id":8979329}],"tv":1933.61}]}
{"op":"mcm","clk":"1009292089","pt":1580643295185,"mc":[{"id":"1.168224338","rc":[{"batb":[[1,4.4,369.4],[2,1.01,15.52]],"batl":[[0,520,35.52]],"ltp":17.5,"tv":51.53,"id":2397396}]}]}
{"op":"mcm","clk":"1009292162","pt":1580643295761,"mc":[{"id":"1.168224338","rc":[{"batl":[[0,1.03,1155.81]],"ltp":1.06,"tv":1882.08,"id":8979329}]}]}
{"op":"mcm","clk":"1009292778","pt":1580643300283,"mc":[{"id":"1.168224338","rc":[{"batb":[[0,1.01,15.51],[1,1.01,0]],"ltp":1.06,"tv":1882.08,"id":8979329}]}]}
{"op":"mcm","clk":"1009293000","pt":1580643301689,"mc":[{"id":"1.168224338","rc":[{"batb":[[1,1.01,15.52],[2,1.01,0]],"ltp":17.5,"tv":51.53,"id":2397396}]}]}
{"op":"mcm","clk":"1009293175","pt":1580643302864,"mc":[{"id":"1.168224338","rc":[{"batb":[[0,1.01,579.02]],"batl":[[0,1.07,1083.3]],"ltp":1.06,"tv":1882.08,"id":8979329}]}]}
{"op":"mcm","clk":"1009293718","pt":1580643306358,"mc":[{"id":"1.168224338","rc":[{"batb":[[0,1.01,15.51]],"ltp":1.06,"tv":1882.08,"id":8979329}]}]}
{"op":"mcm","clk":"1009294150","pt":1580643309295,"mc":[{"id":"1.168224338","rc":[{"batb":[[0,27,3.02],[1,15,5.19],[2,1.01,15.52]],"ltp":17.5,"tv":51.53,"id":2397396},{"batb":[[0,1.01,579.02]],"batl":[[0,1.02,1257.13]],"ltp":1.06,"tv":1882.08,"id":8979329}]}]}
{"op":"mcm","clk":"1009294257","pt":1580643310001,"mc":[{"id":"1.168224338","rc":[{"batb":[[1,4.7,367.67]],"ltp":17.5,"tv":51.53,"id":2397396}]}]}
{"op":"mcm","clk":"1009294689","pt":1580643312988,"mc":[{"id":"1.168224338","rc":[{"batl":[[1,1.04,55]],"ltp":1.06,"tv":1882.08,"id":8979329}]}]}
{"op":"mcm","clk":"1009295003","pt":1580643315482,"mc":[{"id":"1.168224338","rc":[{"batb":[[0,1.01,479.26]],"ltp":1.06,"tv":1882.08,"id":8979329}]}]}
{"op":"mcm","clk":"1009295256","pt":1580643317328,"mc":[{"id":"1.168224338","rc":[{"trd":[[1.01,190]],"batb":[[0,1.01,384.26]],"ltp":1.01,"tv":2072.07,"id":8979329}],"tv":2123.6}]}
{"op":"mcm","clk":"1009295513","pt":1580643318980,"mc":[{"id":"1.168224338","rc":[{"batb":[[1,1.01,15.52],[2,1.01,0]],"ltp":17.5,"tv":51.53,"id":2397396}]}]}
{"op":"mcm","clk":"1009296135","pt":1580643323315,"mc":[{"id":"1.168224338","rc":[{"batb":[[0,1.01,1269.58]],"batl":[[0,1.02,1257.13]],"ltp":1.01,"tv":2072.07,"id":8979329}]}]}
{"op":"mcm","clk":"1009296240","pt":1580643324003,"mc":[{"id":"1.168224338","rc":[{"batb":[[1,4.6,373.8],[2,1.01,15.52]],"ltp":17.5,"tv":51.53,"id":2397396}]}]}
{"op":"mcm","clk":"1009296787","pt":1580643327833,"mc":[{"id":"1.168224338","rc":[{"batb":[[1,1.01,15.52],[2,1.01,0]],"ltp":17.5,"tv":51.53,"id":2397396}]}]}
{"op":"mcm","clk":"1009297190","pt":1580643330397,"mc":[{"id":"1.168224338","rc":[{"batl":[[0,1.03,347.18],[1,1.04,889.1]],"ltp":1.01,"tv":2072.07,"id":8979329}]}]}
{"op":"mcm","clk":"1009297528","pt":1580643332334,"mc":[{"id":"1.168224338","rc":[{"batb":[[1,12,8.42],[2,1.01,15.52]],"ltp":17.5,"tv":51.53,"id":2397396},{"batb":[[0,1.02,1257.13]],"batl":[[1,1.04,931.11]],"ltp":1.01,"tv":2072.07,"id":8979329}]}]}
{"op":"mcm","clk":"1009297641","pt":1580643333247,"mc":[{"id":"1.168224338","rc":[{"batb":[[2,4.4,369.4]],"batl":[[0,520,35.52]],"ltp":17.5,"tv":51.53,"id":2397396}]}]}
{"op":"mcm","clk":"1009299111","pt":1580643343261,"mc":[{"id":"1.168224338","rc":[{"batb":[[0,12,8.42],[1,4.4,369.4],[2,1.01,15.52]],"ltp":17.5,"tv":51.53,"id":2397396}]}]}
{"op":"mcm","clk":"1009299224","pt":1580643343961,"mc":[{"id":"1.168224338","rc":[{"batb":[[1,1.01,15.52],[2,1.01,0]],"ltp":17.5,"tv":51.53,"id":2397396},{"batl":[[0,1.01,16.8]],"ltp":1.01,"tv":2072.07,"id":8979329}]}]}
{"op":"mcm","clk":"1009299892","pt":1580643348377,"mc":[{"id":"1.168224338","rc":[{"trd":[[1.01,223.6]],"batb":[[0,1.03,1228.12]],"batl":[[0,1.04,544.26],[1,1.05,682.13]],"ltp":1.01,"tv":2105.68,"id":8979329}],"tv":2157.21}]}
{"op":"mcm","clk":"1009300193","pt":1580643350127,"mc":[{"id":"1.168224338","rc":[{"batb":[[1,4.2,372.95],[2,1.01,15.52]],"ltp":17.5,"tv":51.53,"id":2397396},{"batb":[[1,1.01,3877.43]],"ltp":1.01,"tv":2105.68,"id":8979329}]}]}
{"op":"mcm","clk":"1009300350","pt":1580643351151,"mc":[{"id":"1.168224338","rc":[{"batb":[[0,1.01,3877.43],[1,1.01,0]],"ltp":1.01,"tv":2105.68,"id":8979329}]}]}
{"op":"mcm","clk":"1009300505","pt":1580643352129,"mc":[{"id":"1.168224338","rc":[{"batb":[[1,1.01,15.52],[2,1.01,0]],"ltp":17.5,"tv":51.53,"id":2397396}]}]}
{"op":"mcm","clk":"1009300865","pt":1580643354272,"mc":[{"id":"1.168224338","rc":[{"batl":[[0,1.08,530.28],[1,1.09,650.98]],"ltp":1.01,"tv":2105.68,"id":8979329}]}]}
{"op":"mcm","clk":"1009301667","pt":1580643359195,"mc":[{"id":"1.168224338","rc":[{"batb":[[0,1.01,15.52],[1,1.01,0]],"ltp":17.5,"tv":51.53,"id":2397396}]}]}
{"op":"mcm","clk":"1009302228","pt":1580643362255,"mc":[{"id":"1.168224338","rc":[{"batl":[[0,1.01,1269.58]],"ltp":1.01,"tv":2105.68,"id":8979329}]}]}
{"op":"mcm","clk":"1009302408","pt":1580643363472,"mc":[{"id":"1.168224338","rc":[{"batb":[[0,4.7,374.21],[1,1.01,15.52]],"ltp":17.5,"tv":51.53,"id":2397396}]}]}
{"op":"mcm","clk":"1009304550","pt":1580643377320,"mc":[{"id":"1.168224338","rc":[{"batb":[[0,1.01,15.52],[1,1.01,0]],"ltp":17.5,"tv":51.53,"id":2397396}]}]}
{"op":"mcm","clk":"1009304847","pt":1580643379284,"mc":[{"id":"1.168224338","marketDefinition":{"bspMarket":false,"turnInPlayEnabled":true,"persistenceEnabled":true,"marketBaseRate":5.0,"eventId":"29681722","eventTypeId":"2","numberOfWinners":1,"bettingType":"ODDS","marketType":"SET_WINNER","marketTime":"2020-02-02T10:48:00.000Z","suspendTime":"2020-02-02T10:48:00.000Z","bspReconciled":false,"complete":true,"inPlay":true,"crossMatching":true,"runnersVoidable":false,"numberOfActiveRunners":2,"betDelay":3,"status":"SUSPENDED","runners":[{"status":"ACTIVE","sortPriority":1,"id":8979329,"name":"Emil Ruusuvuori"},{"status":"ACTIVE","sortPriority":2,"id":2397396,"name":"Matthias Bachinger"}],"regulators":["MR_INT"],"countryCode":"FR","discountAllowed":true,"timezone":"UTC","openDate":"2020-02-02T10:48:00.000Z","version":3148574096,"name":"Set 1 Winner","eventName":"Emil Ruusuvuori v Bachinger"}}]}
{"op":"mcm","clk":"1009309402","pt":1580643410855,"mc":[{"id":"1.168224338","tv":0.0}]}
{"op":"mcm","clk":"1009309551","pt":1580643411914,"mc":[{"id":"1.168224338","marketDefinition":{"bspMarket":false,"turnInPlayEnabled":true,"persistenceEnabled":true,"marketBaseRate":5.0,"eventId":"29681722","eventTypeId":"2","numberOfWinners":1,"bettingType":"ODDS","marketType":"SET_WINNER","marketTime":"2020-02-02T10:48:00.000Z","suspendTime":"2020-02-02T10:48:00.000Z","bspReconciled":false,"complete":true,"inPlay":true,"crossMatching":false,"runnersVoidable":false,"numberOfActiveRunners":0,"betDelay":3,"status":"CLOSED","settledTime":"2020-02-02T11:36:49.000Z","runners":[{"status":"WINNER","sortPriority":1,"id":8979329,"name":"Emil Ruusuvuori"},{"status":"LOSER","sortPriority":2,"id":2397396,"name":"Matthias Bachinger"}],"regulators":["MR_INT"],"countryCode":"FR","discountAllowed":true,"timezone":"UTC","openDate":"2020-02-02T10:48:00.000Z","version":3148575963,"name":"Set 1 Winner","eventName":"Emil Ruusuvuori v Bachinger"}}]}
