{"op":"mcm","clk":"1004962286","pt":1580585267691,"mc":[{"id":"1.168224328","marketDefinition":{"bspMarket":false,"turnInPlayEnabled":true,"persistenceEnabled":true,"marketBaseRate":5.0,"eventId":"29681722","eventTypeId":"2","numberOfWinners":1,"bettingType":"ODDS","marketType":"MATCH_ODDS","marketTime":"2020-02-02T09:00:00.000Z","suspendTime":"2020-02-02T09:00:00.000Z","bspReconciled":false,"complete":true,"inPlay":false,"crossMatching":false,"runnersVoidable":false,"numberOfActiveRunners":2,"betDelay":0,"status":"OPEN","runners":[{"status":"ACTIVE","sortPriority":1,"id":8979329,"name":"Emil Ruusuvuori"},{"status":"ACTIVE","sortPriority":2,"id":2397396,"name":"Matthias Bachinger"}],"regulators":["MR_INT"],"countryCode":"FR","discountAllowed":false,"timezone":"UTC","openDate":"2020-02-02T09:00:00.000Z","version":3147098034,"name":"Match Odds","eventName":"Emil Ruusuvuori v Bachinger"},"rc":[{"batb":[[0,1.02,3786.16],[1,1.01,4069.07]],"ltp":0.0,"tv":0.0,"id":2397396},{"batb":[[0,1.05,152.2],[1,1.04,168.86],[2,1.03,190.07]],"ltp":0.0,"tv":0.0,"id":8979329}]}]}
{"op":"mcm","clk":"1004962420","pt":1580585268465,"mc":[{"id":"1.168224328","marketDefinition":{"bspMarket":false,"turnInPlayEnabled":true,"persistenceEnabled":true,"marketBaseRate":5.0,"eventId":"29681722","eventTypeId":"2","numberOfWinners":1,"bettingType":"ODDS","marketType":"MATCH_ODDS","marketTime":"2020-02-02T09:00:00.000Z","suspendTime":"2020-02-02T09:00:00.000Z","bspReconciled":false,"complete":true,"inPlay":false,"crossMatching":false,"runnersVoidable":false,"numberOfActiveRunners":2,"betDelay":0,"status":"OPEN","runners":[{"status":"ACTIVE","sortPriority":1,"id":8979329,"name":"Emil Ruusuvuori"},{"status":"ACTIVE","sortPriority":2,"id":2397396,"name":"Matthias Bachinger"}],"regulators":["MR_INT"],"countryCode":"FR","discountAllowed":false,"timezone":"UTC","openDate":"2020-02-02T09:00:00.000Z","version":3147098034,"name":"Match Odds","eventName":"Emil Ruusuvuori v Bachinger"}}]}
{"op":"mcm","clk":"1004962808","pt":1580585270546,"mc":[{"id":"1.168224328","marketDefinition":{"bspMarket":false,"turnInPlayEnabled":true,"persistenceEnabled":true,"marketBaseRate":5.0,"eventId":"29681722","eventTypeId":"2","numberOfWinners":1,"bettingType":"ODDS","marketType":"MATCH_ODDS","marketTime":"2020-02-02T09:00:00.000Z","suspendTime":"2020-02-02T09:00:00.000Z","bspReconciled":false,"complete":true,"inPlay":false,"crossMatching":false,"runnersVoidable":false,"numberOfActiveRunners":2,"betDelay":0,"status":"OPEN","runners":[{"status":"ACTIVE","sortPriority":1,"id":8979329,"name":"Emil Ruusuvuori"},{"status":"ACTIVE","sortPriority":2,"id":2397396,"name":"Matthias Bachinger"}],"regulators":["MR_INT"],"countryCode":"FR","discountAllowed":true,"timezone":"UTC","openDate":"2020-02-02T09:00:00.000Z","version":3147098034,"name":"Match Odds","eventName":"Emil Ruusuvuori v Bachinger"}}]}
{"op":"mcm","clk":"1004972005","pt":1580585325071,"mc":[{"id":"1.168224328","rc":[{"batb":[[1,1.01,4369.07]],"ltp":0.0,"tv":0.0,"id":2397396}]}]}
{"op":"mcm","clk":"1004972556","pt":1580585328702,"mc":[{"id":"1.168224328","rc":[{"batb":[[1,1.01,4069.07]],"ltp":0.0,"tv":0.0,"id":2397396}]}]}
{"op":"mcm","clk":"1004986096","pt":1580585417007,"mc":[{"id":"1.168224328","rc":[{"batb":[[1,1.01,4059.07]],"ltp":0.0,"tv":0.0,"id":2397396}]}]}
{"op":"mcm","clk":"1005002549","pt":1580585515430,"mc":[{"id":"1.168224328","marketDefinition":{"bspMarket":false,"turnInPlayEnabled":true,"persistenceEnabled":true,"marketBaseRate":5.0,"eventId":"29681722","eventTypeId":"2","numberOfWinners":1,"bettingType":"ODDS","marketType":"MATCH_ODDS","marketTime":"2020-02-02T11:30:00.000Z","suspendTime":"2020-02-02T11:30:00.000Z","bspReconciled":false,"complete":true,"inPlay":false,"crossMatching":false,"runnersVoidable":false,"numberOfActiveRunners":2,"betDelay":0,"status":"OPEN","runners":[{"status":"ACTIVE","sortPriority":1,"id":8979329,"name":"Emil Ruusuvuori"},{"status":"ACTIVE","sortPriority":2,"id":2397396,"name":"Matthias Bachinger"}],"regulators":["MR_INT"],"countryCode":"FR","discountAllowed":true,"timezone":"UTC","openDate":"2020-02-02T09:00:00.000Z","version":3147124989,"name":"Match Odds","eventName":"Emil Ruusuvuori v Bachinger"}}]}
{"op":"mcm","clk":"1005003169","pt":1580585518494,"mc":[{"id":"1.168224328","marketDefinition":{"bspMarket":false,"turnInPlayEnabled":true,"persistenceEnabled":true,"marketBaseRate":5.0,"eventId":"29681722","eventTypeId":"2","numberOfWinners":1,"bettingType":"ODDS","marketType":"MATCH_ODDS","marketTime":"2020-02-02T11:30:00.000Z","suspendTime":"2020-02-02T11:30:00.000Z","bspReconciled":false,"complete":true,"inPlay":false,"crossMatching":false,"runnersVoidable":false,"numberOfActiveRunners":2,"betDelay":0,"status":"OPEN","runners":[{"status":"ACTIVE","sortPriority":1,"id":8979329,"name":"Emil Ruusuvuori"},{"status":"ACTIVE","sortPriority":2,"id":2397396,"name":"Matthias Bachinger"}],"regulators":["MR_INT"],"countryCode":"FR","discountAllowed":true,"timezone":"UTC","openDate":"2020-02-02T11:30:00.000Z","version":3147124989,"name":"Match Odds","eventName":"Emil Ruusuvuori v Bachinger"}}]}
{"op":"mcm","clk":"1005007345","pt":1580585543181,"mc":[{"id":"1.168224328","rc":[{"batb":[[0,1.06,50.48],[1,1.05,152.2],[2,1.04,168.86]],"ltp":0.0,"tv":0.0,"id":8979329}]}]}
{"op":"mcm","clk":"1005007410","pt":1580585543622,"mc":[{"id":"1.168224328","rc":[{"batb":[[0,1.03,100.96],[1,1.02,3786.16],[2,1.01,4059.07]],"ltp":0.0,"tv":0.0,"id":2397396}]}]}
{"op":"mcm","clk":"1005008553","pt":1580585550620,"mc":[{"id":"1.168224328","marketDefinition":{"bspMarket":false,"turnInPlayEnabled":true,"persistenceEnabled":true,"marketBaseRate":5.0,"eventId":"29681722","eventTypeId":"2","numberOfWinners":1,"bettingType":"ODDS","marketType":"MATCH_ODDS","marketTime":"2020-02-02T11:30:00.000Z","suspendTime":"2020-02-02T11:30:00.000Z","bspReconciled":false,"complete":true,"inPlay":false,"crossMatching":true,"runnersVoidable":false,"numberOfActiveRunners":2,"betDelay":0,"status":"OPEN","runners":[{"status":"ACTIVE","sortPriority":1,"id":8979329,"name":"Emil Ruusuvuori"},{"status":"ACTIVE","sortPriority":2,"id":2397396,"name":"Matthias Bachinger"}],"regulators":["MR_INT"],"countryCode":"FR","discountAllowed":true,"timezone":"UTC","openDate":"2020-02-02T11:30:00.000Z","version":3147124989,"name":"Match Odds","eventName":"Emil Ruusuvuori v Bachinger"}}]}
{"op":"mcm","clk":"1005025262","pt":1580585648363,"mc":[{"id":"1.168224328","rc":[{"batb":[[2,1.01,4122.68]],"ltp":0.0,"tv":0.0,"id":2397396}]}]}
{"op":"mcm","clk":"1005058106","pt":1580585849977,"mc":[{"id":"1.168224328","rc":[{"batl":[[0,48,31.05]],"ltp":0.0,"tv":0.0,"id":2397396},{"batl":[[0,48,31.05]],"ltp":0.0,"tv":0.0,"id":8979329}]}]}
{"op":"mcm","clk":"1005133117","pt":1580586322013,"mc":[{"id":"1.168224328","rc":[{"batb":[[0,1.03,109.36],[1,1.02,3811.36]],"ltp":0.0,"tv":0.0,"id":2397396}]}]}
{"op":"mcm","clk":"1005380306","pt":1580587946037,"mc":[{"id":"1.168224328","rc":[{"batl":[[1,990,2.2]],"ltp":0.0,"tv":0.0,"id":2397396},{"batl":[[1,990,2.2]],"ltp":0.0,"tv":0.0,"id":8979329}]}]}
{"op":"mcm","clk":"1005659050","pt":1580589682194,"mc":[{"id":"1.168224328","rc":[{"batb":[[1,1.02,25.21],[2,1.01,336.52]],"ltp":0.0,"tv":0.0,"id":2397396}]}]}
{"op":"mcm","clk":"1006879544","pt":1580601561354,"mc":[{"id":"1.168224328","rc":[{"batb":[[2,1.01,339.02]],"batl":[[2,1000,0.02]],"ltp":0.0,"tv":0.0,"id":2397396},{"batl":[[2,1000,0.02]],"ltp":0.0,"tv":0.0,"id":8979329}]}]}
{"op":"mcm","clk":"1006879558","pt":1580601561559,"mc":[{"id":"1.168224328","rc":[{"batb":[[0,1.03,109.96],[2,1.01,338.52]],"ltp":0.0,"tv":0.0,"id":2397396},{"batb":[[0,1.06,50.58],[2,1.04,169.36]],"ltp":0.0,"tv":0.0,"id":8979329}]}]}
{"op":"mcm","clk":"1006884152","pt":1580601630932,"mc":[{"id":"1.168224328","rc":[{"batb":[[0,1.03,110.06]],"ltp":0.0,"tv":0.0,"id":2397396},{"batb":[[0,1.06,50.68]],"ltp":0.0,"tv":0.0,"id":8979329}]}]}
{"op":"mcm","clk":"1006924687","pt":1580602186352,"mc":[{"id":"1.168224328","rc":[{"batb":[[2,1.01,339.03]],"ltp":0.0,"tv":0.0,"id":2397396}]}]}
{"op":"mcm","clk":"1007043396","pt":1580603725304,"mc":[{"id":"1.168224328","rc":[{"batb":[[2,1.01,341.56]],"ltp":0.0,"tv":0.0,"id":2397396}]}]}
{"op":"mcm","clk":"1007043453","pt":1580603726341,"mc":[{"id":"1.168224328","rc":[{"batb":[[2,1.01,339.03]],"ltp":0.0,"tv":0.0,"id":2397396}]}]}
{"op":"mcm","clk":"1007043457","pt":1580603726444,"mc":[{"id":"1.168224328","rc":[{"batb":[[2,1.01,339.54]],"ltp":0.0,"tv":0.0,"id":2397396}]}]}
{"op":"mcm","clk":"1007075686","pt":1580604311668,"mc":[{"id":"1.168224328","rc":[{"batl":[[0,2,189.04],[1,48,31.05],[2,990,2.2]],"ltp":0.0,"tv":0.0,"id":8979329}]}]}
{"op":"mcm","clk":"1007200059","pt":1580607031303,"mc":[{"id":"1.168224328","rc":[{"batb":[[2,1.01,339.55]],"ltp":0.0,"tv":0.0,"id":2397396}]}]}
{"op":"mcm","clk":"1007200078","pt":1580607031611,"mc":[{"id":"1.168224328","rc":[{"batb":[[0,1.03,110.07],[2,1.01,339.54]],"ltp":0.0,"tv":0.0,"id":2397396},{"batb":[[0,1.06,50.69]],"ltp":0.0,"tv":0.0,"id":8979329}]}]}
{"op":"mcm","clk":"1007465919","pt":1580615093191,"mc":[{"id":"1.168224328","rc":[{"batl":[[0,990,2.2],[1,1000,0.02],[2,1000,0]],"ltp":0.0,"tv":0.0,"id":2397396},{"batl":[[1,990,2.2],[2,1000,0.02]],"ltp":0.0,"tv":0.0,"id":8979329}]}]}
{"op":"mcm","clk":"1007516101","pt":1580616416712,"mc":[{"id":"1.168224328","rc":[{"batl":[[0,95,15.9],[1,990,2.2],[2,1000,0.02]],"ltp":0.0,"tv":0.0,"id":2397396},{"batl":[[1,95,15.9],[2,990,2.2]],"ltp":0.0,"tv":0.0,"id":8979329}]}]}
{"op":"mcm","clk":"1007516715","pt":1580616436501,"mc":[{"id":"1.168224328","rc":[{"batb":[[0,1.09,151.66],[1,1.06,50.48],[2,1.05,152.2]],"batl":[[0,1.98,15.14],[1,2,189.04],[2,95,15.9]],"ltp":0.0,"tv":0.0,"id":8979329}]}]}
{"op":"mcm","clk":"1007517655","pt":1580616466086,"mc":[{"id":"1.168224328","rc":[{"batb":[[0,1.13,25.1],[1,1.09,151.55],[2,1.06,50.48]],"batl":[[0,1.8,3.03],[1,1.98,15.14],[2,2,189.04]],"ltp":0.0,"tv":0.0,"id":8979329}]}]}
{"op":"mcm","clk":"1007555510","pt":1580617646927,"mc":[{"id":"1.168224328","rc":[{"batb":[[1,1.1,6.87],[2,1.09,151.45]],"ltp":0.0,"tv":0.0,"id":8979329}]}]}
{"op":"mcm","clk":"1007656829","pt":1580620129860,"mc":[{"id":"1.168224328","rc":[{"batb":[[1,1.09,151.55],[2,1.06,50.48]],"ltp":0.0,"tv":0.0,"id":8979329}]}]}
{"op":"mcm","clk":"1007662390","pt":1580620241033,"mc":[{"id":"1.168224328","rc":[{"batl":[[0,8.6,153.72],[1,95,15.9],[2,990,2.2]],"ltp":0.0,"tv":0.0,"id":2397396},{"batl":[[0,1.8,156.75]],"ltp":0.0,"tv":0.0,"id":8979329}]}]}
{"op":"mcm","clk":"1007720844","pt":1580621544150,"mc":[{"id":"1.168224328","rc":[{"batl":[[0,8.4,1.68],[1,8.6,153.72],[2,95,15.9]],"ltp":0.0,"tv":0.0,"id":2397396}]}]}
{"op":"mcm","clk":"1007721258","pt":1580621550348,"mc":[{"id":"1.168224328","rc":[{"batl":[[0,8.2,1.68]],"ltp":0.0,"tv":0.0,"id":2397396}]}]}
{"op":"mcm","clk":"1007721511","pt":1580621554267,"mc":[{"id":"1.168224328","rc":[{"batl":[[0,8,1.68]],"ltp":0.0,"tv":0.0,"id":2397396}]}]}
{"op":"mcm","clk":"1007721690","pt":1580621557168,"mc":[{"id":"1.168224328","rc":[{"batl":[[0,7.8,1.68]],"ltp":0.0,"tv":0.0,"id":2397396}]}]}
{"op":"mcm","clk":"1007721843","pt":1580621559856,"mc":[{"id":"1.168224328","rc":[{"batl":[[0,7.6,1.68]],"ltp":0.0,"tv":0.0,"id":2397396}]}]}
{"op":"mcm","clk":"1007722048","pt":1580621562641,"mc":[{"id":"1.168224328","rc":[{"batl":[[0,7.4,1.68]],"ltp":0.0,"tv":0.0,"id":2397396}]}]}
{"op":"mcm","clk":"1007722197","pt":1580621565260,"mc":[{"id":"1.168224328","rc":[{"batl":[[0,7.2,1.68]],"ltp":0.0,"tv":0.0,"id":2397396}]}]}
{"op":"mcm","clk":"1007722352","pt":1580621567780,"mc":[{"id":"1.168224328","rc":[{"batl":[[0,7,1.68]],"ltp":0.0,"tv":0.0,"id":2397396}]}]}
{"op":"mcm","clk":"1007722496","pt":1580621569991,"mc":[{"id":"1.168224328","rc":[{"batl":[[0,6.8,1.68]],"ltp":0.0,"tv":0.0,"id":2397396}]}]}
{"op":"mcm","clk":"1007722625","pt":1580621572251,"mc":[{"id":"1.168224328","rc":[{"batl":[[0,6.6,1.68]],"ltp":0.0,"tv":0.0,"id":2397396}]}]}
{"op":"mcm","clk":"1007722758","pt":1580621574765,"mc":[{"id":"1.168224328","rc":[{"batl":[[0,6.4,1.68]],"ltp":0.0,"tv":0.0,"id":2397396}]}]}
{"op":"mcm","clk":"1007722873","pt":1580621577107,"mc":[{"id":"1.168224328","rc":[{"batl":[[0,6.2,1.68]],"ltp":0.0,"tv":0.0,"id":2397396}]}]}
{"op":"mcm","clk":"1007722974","pt":1580621579316,"mc":[{"id":"1.168224328","rc":[{"batl":[[0,8.6,153.72],[1,95,15.9],[2,990,2.2]],"ltp":0.0,"tv":0.0,"id":2397396}]}]}
{"op":"mcm","clk":"1007722977","pt":1580621579416,"mc":[{"id":"1.168224328","rc":[{"batl":[[0,6,1.68],[1,8.6,153.72],[2,95,15.9]],"ltp":0.0,"tv":0.0,"id":2397396}]}]}
{"op":"mcm","clk":"1007723110","pt":1580621581897,"mc":[{"id":"1.168224328","rc":[{"batl":[[0,5.9,1.68]],"ltp":0.0,"tv":0.0,"id":2397396}]}]}
{"op":"mcm","clk":"1007723216","pt":1580621584106,"mc":[{"id":"1.168224328","rc":[{"batl":[[0,5.8,1.68]],"ltp":0.0,"tv":0.0,"id":2397396}]}]}
{"op":"mcm","clk":"1007723321","pt":1580621586326,"mc":[{"id":"1.168224328","rc":[{"batl":[[0,8.6,153.72],[1,95,15.9],[2,990,2.2]],"ltp":0.0,"tv":0.0,"id":2397396}]}]}
{"op":"mcm","clk":"1007723331","pt":1580621586432,"mc":[{"id":"1.168224328","rc":[{"batl":[[0,5.7,1.68],[1,8.6,153.72],[2,95,15.9]],"ltp":0.0,"tv":0.0,"id":2397396}]}]}
{"op":"mcm","clk":"1007723474","pt":1580621588802,"mc":[{"id":"1.168224328","rc":[{"batl":[[0,5.6,1.68]],"ltp":0.0,"tv":0.0,"id":2397396}]}]}
{"op":"mcm","clk":"1007723587","pt":1580621591118,"mc":[{"id":"1.168224328","rc":[{"batl":[[0,5.5,1.68]],"ltp":0.0,"tv":0.0,"id":2397396}]}]}
{"op":"mcm","clk":"1007723703","pt":1580621593327,"mc":[{"id":"1.168224328","rc":[{"batl":[[0,5.4,1.68]],"ltp":0.0,"tv":0.0,"id":2397396}]}]}
{"op":"mcm","clk":"1007723799","pt":1580621595340,"mc":[{"id":"1.168224328","rc":[{"batl":[[0,8.6,153.72],[1,95,15.9],[2,990,2.2]],"ltp":0.0,"tv":0.0,"id":2397396}]}]}
{"op":"mcm","clk":"1007723804","pt":1580621595442,"mc":[{"id":"1.168224328","rc":[{"batl":[[0,5.3,1.68],[1,8.6,153.72],[2,95,15.9]],"ltp":0.0,"tv":0.0,"id":2397396}]}]}
{"op":"mcm","clk":"1007723913","pt":1580621597611,"mc":[{"id":"1.168224328","rc":[{"batl":[[0,5.2,1.68]],"ltp":0.0,"tv":0.0,"id":2397396}]}]}
{"op":"mcm","clk":"1007724031","pt":1580621599626,"mc":[{"id":"1.168224328","rc":[{"batl":[[0,5.1,1.68]],"ltp":0.0,"tv":0.0,"id":2397396}]}]}
{"op":"mcm","clk":"1007724150","pt":1580621601734,"mc":[{"id":"1.168224328","rc":[{"batl":[[0,5,1.68]],"ltp":0.0,"tv":0.0,"id":2397396}]}]}
{"op":"mcm","clk":"1007724269","pt":1580621603946,"mc":[{"id":"1.168224328","rc":[{"batl":[[0,4.9,1.68]],"ltp":0.0,"tv":0.0,"id":2397396}]}]}
{"op":"mcm","clk":"1007724386","pt":1580621606275,"mc":[{"id":"1.168224328","rc":[{"batl":[[0,4.8,1.68]],"ltp":0.0,"tv":0.0,"id":2397396}]}]}
{"op":"mcm","clk":"1007724491","pt":1580621608228,"mc":[{"id":"1.168224328","rc":[{"batl":[[0,4.7,1.68]],"ltp":0.0,"tv":0.0,"id":2397396}]}]}
{"op":"mcm","clk":"1007724673","pt":1580621611936,"mc":[{"id":"1.168224328","rc":[{"batl":[[0,4.6,1.68]],"ltp":0.0,"tv":0.0,"id":2397396}]}]}
{"op":"mcm","clk":"1007724782","pt":1580621614353,"mc":[{"id":"1.168224328","rc":[{"batl":[[0,8.6,153.72],[1,95,15.9],[2,990,2.2]],"ltp":0.0,"tv":0.0,"id":2397396}]}]}
{"op":"mcm","clk":"1007724788","pt":1580621614456,"mc":[{"id":"1.168224328","rc":[{"batl":[[0,4.5,1.68],[1,8.6,153.72],[2,95,15.9]],"ltp":0.0,"tv":0.0,"id":2397396}]}]}
{"op":"mcm","clk":"1007724905","pt":1580621616873,"mc":[{"id":"1.168224328","rc":[{"batl":[[0,4.4,1.68]],"ltp":0.0,"tv":0.0,"id":2397396}]}]}
{"op":"mcm","clk":"1007725030","pt":1580621619246,"mc":[{"id":"1.168224328","rc":[{"batl":[[0,4.3,1.68]],"ltp":0.0,"tv":0.0,"id":2397396}]}]}
{"op":"mcm","clk":"1007725171","pt":1580621621685,"mc":[{"id":"1.168224328","rc":[{"batl":[[0,4.2,1.68]],"ltp":0.0,"tv":0.0,"id":2397396}]}]}
{"op":"mcm","clk":"1007725284","pt":1580621623976,"mc":[{"id":"1.168224328","rc":[{"batl":[[0,4.1,1.68]],"ltp":0.0,"tv":0.0,"id":2397396}]}]}
{"op":"mcm","clk":"1007725409","pt":1580621626286,"mc":[{"id":"1.168224328","rc":[{"batl":[[0,4,1.68]],"ltp":0.0,"tv":0.0,"id":2397396}]}]}
{"op":"mcm","clk":"1007725528","pt":1580621628697,"mc":[{"id":"1.168224328","rc":[{"batl":[[0,3.95,1.68]],"ltp":0.0,"tv":0.0,"id":2397396}]}]}
{"op":"mcm","clk":"1007725658","pt":1580621630963,"mc":[{"id":"1.168224328","rc":[{"batl":[[0,3.9,1.68]],"ltp":0.0,"tv":0.0,"id":2397396}]}]}
{"op":"mcm","clk":"1007725796","pt":1580621633389,"mc":[{"id":"1.168224328","rc":[{"batl":[[0,8.6,153.72],[1,95,15.9],[2,990,2.2]],"ltp":0.0,"tv":0.0,"id":2397396}]}]}
{"op":"mcm","clk":"1007725804","pt":1580621633496,"mc":[{"id":"1.168224328","rc":[{"batl":[[0,3.85,1.68],[1,8.6,153.72],[2,95,15.9]],"ltp":0.0,"tv":0.0,"id":2397396}]}]}
{"op":"mcm","clk":"1007725893","pt":1580621635607,"mc":[{"id":"1.168224328","rc":[{"batl":[[0,3.8,1.68]],"ltp":0.0,"tv":0.0,"id":2397396}]}]}
{"op":"mcm","clk":"1007726011","pt":1580621637975,"mc":[{"id":"1.168224328","rc":[{"batl":[[0,3.75,1.68]],"ltp":0.0,"tv":0.0,"id":2397396}]}]}
{"op":"mcm","clk":"1007726139","pt":1580621640286,"mc":[{"id":"1.168224328","rc":[{"batl":[[0,3.7,1.68]],"ltp":0.0,"tv":0.0,"id":2397396}]}]}
{"op":"mcm","clk":"1007726259","pt":1580621642704,"mc":[{"id":"1.168224328","rc":[{"batl":[[0,3.65,1.68]],"ltp":0.0,"tv":0.0,"id":2397396}]}]}
{"op":"mcm","clk":"1007726377","pt":1580621644871,"mc":[{"id":"1.168224328","rc":[{"batl":[[0,3.6,1.68]],"ltp":0.0,"tv":0.0,"id":2397396}]}]}
{"op":"mcm","clk":"1007726500","pt":1580621647082,"mc":[{"id":"1.168224328","rc":[{"batl":[[0,3.55,1.68]],"ltp":0.0,"tv":0.0,"id":2397396}]}]}
{"op":"mcm","clk":"1007726601","pt":1580621649242,"mc":[{"id":"1.168224328","rc":[{"batl":[[0,3.5,1.68]],"ltp":0.0,"tv":0.0,"id":2397396}]}]}
{"op":"mcm","clk":"1007726736","pt":1580621651510,"mc":[{"id":"1.168224328","rc":[{"batl":[[0,3.45,1.68]],"ltp":0.0,"tv":0.0,"id":2397396}]}]}
{"op":"mcm","clk":"1007726839","pt":1580621653619,"mc":[{"id":"1.168224328","rc":[{"batl":[[0,3.4,1.68]],"ltp":0.0,"tv":0.0,"id":2397396}]}]}
{"op":"mcm","clk":"1007726917","pt":1580621655686,"mc":[{"id":"1.168224328","rc":[{"batl":[[0,3.35,1.68]],"ltp":0.0,"tv":0.0,"id":2397396}]}]}
{"op":"mcm","clk":"1007727087","pt":1580621659709,"mc":[{"id":"1.168224328","rc":[{"batl":[[0,3.3,1.68]],"ltp":0.0,"tv":0.0,"id":2397396}]}]}
{"op":"mcm","clk":"1007727215","pt":1580621662205,"mc":[{"id":"1.168224328","rc":[{"batl":[[0,3.25,1.68]],"ltp":0.0,"tv":0.0,"id":2397396}]}]}
{"op":"mcm","clk":"1007727288","pt":1580621664310,"mc":[{"id":"1.168224328","rc":[{"batl":[[0,3.2,1.68]],"ltp":0.0,"tv":0.0,"id":2397396}]}]}
{"op":"mcm","clk":"1007727409","pt":1580621666729,"mc":[{"id":"1.168224328","rc":[{"batl":[[0,3.15,1.68]],"ltp":0.0,"tv":0.0,"id":2397396}]}]}
{"op":"mcm","clk":"1007727539","pt":1580621669354,"mc":[{"id":"1.168224328","rc":[{"batl":[[0,8.6,153.72],[1,95,15.9],[2,990,2.2]],"ltp":0.0,"tv":0.0,"id":2397396}]}]}
{"op":"mcm","clk":"1007727546","pt":1580621669455,"mc":[{"id":"1.168224328","rc":[{"batl":[[0,3.1,1.68],[1,8.6,153.72],[2,95,15.9]],"ltp":0.0,"tv":0.0,"id":2397396}]}]}
{"op":"mcm","clk":"1007727665","pt":1580621671731,"mc":[{"id":"1.168224328","rc":[{"batl":[[0,3.05,1.68]],"ltp":0.0,"tv":0.0,"id":2397396}]}]}
{"op":"mcm","clk":"1007727944","pt":1580621677968,"mc":[{"id":"1.168224328","rc":[{"batl":[[0,2.9,1.68]],"ltp":0.0,"tv":0.0,"id":2397396}]}]}
{"op":"mcm","clk":"1007728180","pt":1580621682648,"mc":[{"id":"1.168224328","rc":[{"batl":[[0,2.8,1.68]],"ltp":0.0,"tv":0.0,"id":2397396}]}]}
{"op":"mcm","clk":"1007728464","pt":1580621688365,"mc":[{"id":"1.168224328","rc":[{"batl":[[0,8.6,153.72],[1,95,15.9],[2,990,2.2]],"ltp":0.0,"tv":0.0,"id":2397396}]}]}
{"op":"mcm","clk":"1007728469","pt":1580621688468,"mc":[{"id":"1.168224328","rc":[{"batl":[[0,2.7,1.68],[1,8.6,153.72],[2,95,15.9]],"ltp":0.0,"tv":0.0,"id":2397396}]}]}
{"op":"mcm","clk":"1007728746","pt":1580621693785,"mc":[{"id":"1.168224328","rc":[{"batl":[[0,2.6,1.68]],"ltp":0.0,"tv":0.0,"id":2397396}]}]}
{"op":"mcm","clk":"1007729000","pt":1580621698584,"mc":[{"id":"1.168224328","rc":[{"batl":[[0,2.5,1.68]],"ltp":0.0,"tv":0.0,"id":2397396}]}]}
{"op":"mcm","clk":"1007729252","pt":1580621703169,"mc":[{"id":"1.168224328","rc":[{"batl":[[0,2.4,1.68]],"ltp":0.0,"tv":0.0,"id":2397396}]}]}
{"op":"mcm","clk":"1007729514","pt":1580621708600,"mc":[{"id":"1.168224328","rc":[{"batl":[[0,2.34,1.68]],"ltp":0.0,"tv":0.0,"id":2397396}]}]}
{"op":"mcm","clk":"1007729715","pt":1580621712820,"mc":[{"id":"1.168224328","rc":[{"batl":[[0,2.32,1.68]],"ltp":0.0,"tv":0.0,"id":2397396}]}]}
{"op":"mcm","clk":"1007730211","pt":1580621721997,"mc":[{"id":"1.168224328","rc":[{"batl":[[0,2.3,1.68]],"ltp":0.0,"tv":0.0,"id":2397396}]}]}
{"op":"mcm","clk":"1007730410","pt":1580621725549,"mc":[{"id":"1.168224328","rc":[{"batl":[[0,2.28,1.68]],"ltp":0.0,"tv":0.0,"id":2397396}]}]}
{"op":"mcm","clk":"1007730593","pt":1580621729142,"mc":[{"id":"1.168224328","rc":[{"batl":[[0,2.26,1.68]],"ltp":0.0,"tv":0.0,"id":2397396}]}]}
{"op":"mcm","clk":"1007730755","pt":1580621732342,"mc":[{"id":"1.168224328","rc":[{"trd":[[2.24,1.68]],"batl":[[0,8.6,153.72],[1,95,15.9],[2,990,2.2]],"ltp":2.24,"tv":1.68,"id":2397396},{"trd":[[1.8,2.09]],"batl":[[0,1.8,154.66]],"ltp":1.8,"tv":2.08,"id":8979329}],"tv":3.77}]}
{"op":"mcm","clk":"1007740515","pt":1580621919311,"mc":[{"id":"1.168224328","rc":[{"trd":[[2.24,19.36]],"ltp":2.24,"tv":19.36,"id":2397396},{"trd":[[1.8,24.1]],"batl":[[0,1.8,132.64]],"ltp":1.8,"tv":24.1,"id":8979329}],"tv":43.46}]}
{"op":"mcm","clk":"1007741567","pt":1580621941334,"mc":[{"id":"1.168224328","rc":[{"batl":[[0,1.78,75.72],[1,1.8,132.64],[2,1.98,15.14]],"ltp":1.8,"tv":24.1,"id":8979329}]}]}
{"op":"mcm","clk":"1007741862","pt":1580621947935,"mc":[{"id":"1.168224328","rc":[{"batb":[[0,1.14,151.56],[1,1.13,24.99],[2,1.06,50.58]],"ltp":1.8,"tv":24.1,"id":8979329}]}]}
{"op":"mcm","clk":"1007768954","pt":1580622489635,"mc":[{"id":"1.168224328","rc":[{"batl":[[0,8.2,153.72]],"ltp":2.24,"tv":19.36,"id":2397396},{"batl":[[0,1.77,132.64],[1,1.78,75.72]],"ltp":1.8,"tv":24.1,"id":8979329}]}]}
{"op":"mcm","clk":"1007769303","pt":1580622496583,"mc":[{"id":"1.168224328","rc":[{"batl":[[0,8,153.72]],"ltp":2.24,"tv":19.36,"id":2397396}]}]}
{"op":"mcm","clk":"1007772716","pt":1580622561862,"mc":[{"id":"1.168224328","rc":[{"batb":[[0,1.16,151.56]],"batl":[[0,1.73,75.72],[1,1.77,132.64]],"ltp":1.8,"tv":24.1,"id":8979329}]}]}
{"op":"mcm","clk":"1007775608","pt":1580622619229,"mc":[{"id":"1.168224328","rc":[{"batb":[[0,1.17,6.83],[1,1.16,151.45],[2,1.13,24.99]],"ltp":1.8,"tv":24.1,"id":8979329}]}]}
{"op":"mcm","clk":"1007775635","pt":1580622619742,"mc":[{"id":"1.168224328","rc":[{"batb":[[0,2.3,7.14],[1,1.03,110.07],[2,1.02,25.21]],"ltp":2.24,"tv":19.36,"id":2397396}]}]}
{"op":"mcm","clk":"1007776841","pt":1580622645087,"mc":[{"id":"1.168224328","rc":[{"batb":[[0,1.18,7.68],[1,1.17,6.72],[2,1.16,151.45]],"ltp":1.8,"tv":24.1,"id":8979329}]}]}
{"op":"mcm","clk":"1007801130","pt":1580623235351,"mc":[{"id":"1.168224328","rc":[{"trd":[[1.48,0.02]],"batb":[[0,1.22,77.93],[1,1.18,7.67],[2,1.17,6.72]],"batl":[[0,1.42,53.05],[1,1.73,75.72],[2,1.77,132.64]],"ltp":1.48,"tv":24.12,"id":8979329}],"tv":43.48}]}
{"op":"mcm","clk":"1007801167","pt":1580623236123,"mc":[{"id":"1.168224328","rc":[{"trd":[[1.42,93.18]],"batb":[[0,1.22,48.93]],"batl":[[0,1.47,51.16]],"ltp":1.42,"tv":117.3,"id":8979329}],"tv":136.66}]}
{"op":"mcm","clk":"1007802025","pt":1580623259799,"mc":[{"id":"1.168224328","rc":[{"batb":[[0,3.4,26.5],[1,2.3,7.14],[2,1.03,110.07]],"ltp":2.24,"tv":19.36,"id":2397396},{"batb":[[0,1.26,47.71],[1,1.25,72.69],[2,1.18,7.67]],"ltp":1.42,"tv":117.3,"id":8979329}]}]}
{"op":"mcm","clk":"1007803446","pt":1580623295235,"mc":[{"id":"1.168224328","rc":[{"batb":[[0,1.27,50.27]],"ltp":1.42,"tv":117.3,"id":8979329}]}]}
{"op":"mcm","clk":"1007805941","pt":1580623350397,"mc":[{"id":"1.168224328","rc":[{"batl":[[0,1.39,15.74],[1,1.47,51.16],[2,1.73,75.72]],"ltp":1.42,"tv":117.3,"id":8979329}]}]}
{"op":"mcm","clk":"1007805953","pt":1580623350704,"mc":[{"id":"1.168224328","rc":[{"batl":[[0,1.39,67.6],[1,1.73,75.72],[2,1.77,132.64]],"ltp":1.42,"tv":117.3,"id":8979329}]}]}
{"op":"mcm","clk":"1007837951","pt":1580624117823,"mc":[{"id":"1.168224328","rc":[{"batb":[[0,1.27,3.03]],"ltp":1.42,"tv":117.3,"id":8979329}]}]}
{"op":"mcm","clk":"1007838748","pt":1580624135896,"mc":[{"id":"1.168224328","rc":[{"batb":[[0,3.45,26.5]],"ltp":2.24,"tv":19.36,"id":2397396}]}]}
{"op":"mcm","clk":"1007848976","pt":1580624373094,"mc":[{"id":"1.168224328","rc":[{"trd":[[1.27,25.2]],"batb":[[0,1.25,72.69],[1,1.18,7.67],[2,1.17,6.72]],"batl":[[0,1.38,52.54],[1,1.39,15.74],[2,1.73,75.72]],"ltp":1.27,"tv":142.5,"id":8979329}],"tv":161.86}]}
{"op":"mcm","clk":"1007855012","pt":1580624494351,"mc":[{"id":"1.168224328","rc":[{"batl":[[0,7.2,153.72]],"ltp":2.24,"tv":19.36,"id":2397396},{"batb":[[0,1.26,72.21],[1,1.25,72.69],[2,1.18,7.67]],"ltp":1.27,"tv":142.5,"id":8979329}]}]}
{"op":"mcm","clk":"1007856915","pt":1580624535343,"mc":[{"id":"1.168224328","rc":[{"batb":[[0,1.27,28.77],[1,1.26,72.21],[2,1.25,72.69]],"ltp":1.27,"tv":142.5,"id":8979329}]}]}
{"op":"mcm","clk":"1007856925","pt":1580624535552,"mc":[{"id":"1.168224328","rc":[{"batb":[[1,1.25,72.69],[2,1.18,7.67]],"ltp":1.27,"tv":142.5,"id":8979329}]}]}
{"op":"mcm","clk":"1007887417","pt":1580625200384,"mc":[{"id":"1.168224328","rc":[{"batb":[[1,2.04,7.14]],"ltp":2.24,"tv":19.36,"id":2397396}]}]}
{"op":"mcm","clk":"1007909558","pt":1580625758209,"mc":[{"id":"1.168224328","rc":[{"batb":[[0,1.28,67.41],[1,1.27,28.77],[2,1.25,72.69]],"batl":[[0,1.39,15.74],[1,1.73,75.72],[2,1.97,132.64]],"ltp":1.27,"tv":142.5,"id":8979329}]}]}
{"op":"mcm","clk":"1007909790","pt":1580625764089,"mc":[{"id":"1.168224328","rc":[{"batb":[[0,2.04,7.14],[1,1.03,110.07],[2,1.02,25.21]],"ltp":2.24,"tv":19.36,"id":2397396},{"batb":[[1,1.27,101.47],[2,1.18,7.67]],"ltp":1.27,"tv":142.5,"id":8979329}]}]}
{"op":"mcm","clk":"1007910327","pt":1580625776734,"mc":[{"id":"1.168224328","rc":[{"batb":[[0,2.06,15.12],[1,2.04,7.14],[2,1.03,110.07]],"ltp":2.24,"tv":19.36,"id":2397396}]}]}
{"op":"mcm","clk":"1007910518","pt":1580625780322,"mc":[{"id":"1.168224328","rc":[{"batb":[[1,1.27,28.77],[2,1.26,72.69]],"ltp":1.27,"tv":142.5,"id":8979329}]}]}
{"op":"mcm","clk":"1007910530","pt":1580625780527,"mc":[{"id":"1.168224328","rc":[{"batb":[[0,3.3,27.26],[1,2.06,15.12],[2,2.04,7.14]],"ltp":2.24,"tv":19.36,"id":2397396}]}]}
{"op":"mcm","clk":"1007912487","pt":1580625833087,"mc":[{"id":"1.168224328","rc":[{"batb":[[1,2.04,7.14],[2,1.03,110.07]],"ltp":2.24,"tv":19.36,"id":2397396}]}]}
{"op":"mcm","clk":"1007917584","pt":1580625958805,"mc":[{"id":"1.168224328","rc":[{"batl":[[1,1.73,3.03]],"ltp":1.27,"tv":142.5,"id":8979329}]}]}
{"op":"mcm","clk":"1007970755","pt":1580626973582,"mc":[{"id":"1.168224328","rc":[{"batb":[[0,1.28,101.16]],"ltp":1.27,"tv":142.5,"id":8979329}]}]}
{"op":"mcm","clk":"1007978505","pt":1580627118252,"mc":[{"id":"1.168224328","rc":[{"batb":[[0,1.3,28.77],[1,1.28,101.16]],"ltp":1.27,"tv":142.5,"id":8979329}]}]}
{"op":"mcm","clk":"1007978514","pt":1580627118457,"mc":[{"id":"1.168224328","rc":[{"batb":[[1,1.26,72.69],[2,1.17,6.82]],"ltp":1.27,"tv":142.5,"id":8979329}]}]}
{"op":"mcm","clk":"1008017798","pt":1580627814610,"mc":[{"id":"1.168224328","rc":[{"batb":[[1,1.03,110.07],[2,1.02,25.21]],"ltp":2.24,"tv":19.36,"id":2397396}]}]}
{"op":"mcm","clk":"1008057329","pt":1580628529745,"mc":[{"id":"1.168224328","rc":[{"batb":[[0,3.65,39.81],[1,3.3,27.26],[2,1.03,110.07]],"ltp":2.24,"tv":19.36,"id":2397396},{"batb":[[0,1.31,75.51],[1,1.3,28.77],[2,1.26,72.69]],"ltp":1.27,"tv":142.5,"id":8979329}]}]}
{"op":"mcm","clk":"1008062648","pt":1580628633102,"mc":[{"id":"1.168224328","rc":[{"batb":[[2,1.26,35.59]],"ltp":1.27,"tv":142.5,"id":8979329}]}]}
{"op":"mcm","clk":"1008069575","pt":1580628781524,"mc":[{"id":"1.168224328","rc":[{"batb":[[0,1.31,75.58]],"ltp":1.27,"tv":142.5,"id":8979329}]}]}
{"op":"mcm","clk":"1008085087","pt":1580629081700,"mc":[{"id":"1.168224328","rc":[{"batb":[[0,3.65,39.88]],"ltp":2.24,"tv":19.36,"id":2397396}]}]}
{"op":"mcm","clk":"1008093170","pt":1580629254252,"mc":[{"id":"1.168224328","rc":[{"batb":[[2,1.11,37.97]],"ltp":2.24,"tv":19.36,"id":2397396}]}]}
{"op":"mcm","clk":"1008093175","pt":1580629254456,"mc":[{"id":"1.168224328","rc":[{"batb":[[2,1.21,37.87]],"ltp":2.24,"tv":19.36,"id":2397396}]}]}
{"op":"mcm","clk":"1008093216","pt":1580629255582,"mc":[{"id":"1.168224328","rc":[{"batb":[[2,1.31,37.87]],"ltp":2.24,"tv":19.36,"id":2397396}]}]}
{"op":"mcm","clk":"1008093267","pt":1580629256969,"mc":[{"id":"1.168224328","rc":[{"batb":[[2,1.51,37.86]],"ltp":2.24,"tv":19.36,"id":2397396}]}]}
{"op":"mcm","clk":"1008093327","pt":1580629258573,"mc":[{"id":"1.168224328","rc":[{"batb":[[2,1.61,37.86]],"ltp":2.24,"tv":19.36,"id":2397396}]}]}
{"op":"mcm","clk":"1008093385","pt":1580629259957,"mc":[{"id":"1.168224328","rc":[{"batb":[[2,1.71,37.86]],"ltp":2.24,"tv":19.36,"id":2397396}]}]}
{"op":"mcm","clk":"1008093451","pt":1580629261649,"mc":[{"id":"1.168224328","rc":[{"batb":[[2,2.22,37.86]],"ltp":2.24,"tv":19.36,"id":2397396}]}]}
{"op":"mcm","clk":"1008093521","pt":1580629263191,"mc":[{"id":"1.168224328","rc":[{"batb":[[2,3,18.93]],"ltp":2.24,"tv":19.36,"id":2397396}]}]}
{"op":"mcm","clk":"1008098936","pt":1580629356907,"mc":[{"id":"1.168224328","rc":[{"batb":[[2,3.05,14.04]],"ltp":2.24,"tv":19.36,"id":2397396}]}]}
{"op":"mcm","clk":"1008154158","pt":1580630400130,"mc":[{"id":"1.168224328","rc":[{"batb":[[2,3.05,18.47]],"ltp":2.24,"tv":19.36,"id":2397396}]}]}
{"op":"mcm","clk":"1008166942","pt":1580630618856,"mc":[{"id":"1.168224328","rc":[{"batb":[[2,3,18.93]],"ltp":2.24,"tv":19.36,"id":2397396}]}]}
{"op":"mcm","clk":"1008166974","pt":1580630619488,"mc":[{"id":"1.168224328","rc":[{"batb":[[2,3.1,18.03]],"ltp":2.24,"tv":19.36,"id":2397396}]}]}
{"op":"mcm","clk":"1008167252","pt":1580630623388,"mc":[{"id":"1.168224328","rc":[{"batb":[[1,3.4,27.26]],"ltp":2.24,"tv":19.36,"id":2397396}]}]}
{"op":"mcm","clk":"1008167424","pt":1580630626278,"mc":[{"id":"1.168224328","rc":[{"batb":[[2,3,18.93]],"ltp":2.24,"tv":19.36,"id":2397396}]}]}
{"op":"mcm","clk":"1008167477","pt":1580630626890,"mc":[{"id":"1.168224328","rc":[{"batb":[[2,3.15,17.61]],"ltp":2.24,"tv":19.36,"id":2397396}]}]}
{"op":"mcm","clk":"1008167622","pt":1580630629210,"mc":[{"id":"1.168224328","rc":[{"batb":[[1,3.5,27.26]],"ltp":2.24,"tv":19.36,"id":2397396}]}]}
{"op":"mcm","clk":"1008167671","pt":1580630629781,"mc":[{"id":"1.168224328","rc":[{"batb":[[1,3.45,27.26]],"ltp":2.24,"tv":19.36,"id":2397396},{"batb":[[2,1.25,35.59]],"ltp":1.27,"tv":142.5,"id":8979329}]}]}
{"op":"mcm","clk":"1008168624","pt":1580630644926,"mc":[{"id":"1.168224328","rc":[{"batb":[[2,1.25,72.69]],"ltp":1.27,"tv":142.5,"id":8979329}]}]}
{"op":"mcm","clk":"1008169023","pt":1580630649835,"mc":[{"id":"1.168224328","rc":[{"trd":[[1.31,4.89],[1.32,0.15]],"batb":[[0,1.31,73.06]],"ltp":1.31,"tv":147.54,"id":8979329}],"tv":166.9}]}
{"op":"mcm","clk":"1008169885","pt":1580630663228,"mc":[{"id":"1.168224328","rc":[{"batb":[[0,3.65,80.01]],"ltp":2.24,"tv":19.36,"id":2397396}]}]}
{"op":"mcm","clk":"1008170012","pt":1580630665230,"mc":[{"id":"1.168224328","rc":[{"batb":[[2,3,18.93]],"ltp":2.24,"tv":19.36,"id":2397396}]}]}
{"op":"mcm","clk":"1008170059","pt":1580630665858,"mc":[{"id":"1.168224328","rc":[{"batb":[[1,3.55,27.26],[2,3.2,17.21]],"ltp":2.24,"tv":19.36,"id":2397396}]}]}
{"op":"mcm","clk":"1008170528","pt":1580630670558,"mc":[{"id":"1.168224328","rc":[{"batb":[[1,3.5,27.26]],"ltp":2.24,"tv":19.36,"id":2397396}]}]}
{"op":"mcm","clk":"1008174030","pt":1580630731278,"mc":[{"id":"1.168224328","rc":[{"batb":[[0,3.65,39.88]],"ltp":2.24,"tv":19.36,"id":2397396}]}]}
{"op":"mcm","clk":"1008175910","pt":1580630769227,"mc":[{"id":"1.168224328","rc":[{"batb":[[0,3.65,80.01]],"ltp":2.24,"tv":19.36,"id":2397396}]}]}
{"op":"mcm","clk":"1008204605","pt":1580631250922,"mc":[{"id":"1.168224328","rc":[{"batb":[[2,3,18.93]],"ltp":2.24,"tv":19.36,"id":2397396}]}]}
{"op":"mcm","clk":"1008204666","pt":1580631251598,"mc":[{"id":"1.168224328","rc":[{"batb":[[2,3.25,16.83]],"ltp":2.24,"tv":19.36,"id":2397396}]}]}
{"op":"mcm","clk":"1008207363","pt":1580631289191,"mc":[{"id":"1.168224328","rc":[{"batb":[[2,3,18.93]],"ltp":2.24,"tv":19.36,"id":2397396}]}]}
{"op":"mcm","clk":"1008207400","pt":1580631289806,"mc":[{"id":"1.168224328","rc":[{"batb":[[2,3.25,16.83]],"ltp":2.24,"tv":19.36,"id":2397396}]}]}
{"op":"mcm","clk":"1008244926","pt":1580631854653,"mc":[{"id":"1.168224328","rc":[{"batb":[[0,1.32,28.77],[1,1.31,73.06]],"batl":[[2,1.99,132.64]],"ltp":1.31,"tv":147.54,"id":8979329}]}]}
{"op":"mcm","clk":"1008248722","pt":1580631927856,"mc":[{"id":"1.168224328","rc":[{"batb":[[1,1.3,105.1]],"ltp":1.31,"tv":147.54,"id":8979329}]}]}
{"op":"mcm","clk":"1008262896","pt":1580632169024,"mc":[{"id":"1.168224328","rc":[{"trd":[[1.32,5.21]],"batb":[[0,1.32,26.25]],"ltp":1.32,"tv":152.6,"id":8979329}],"tv":171.96}]}
{"op":"mcm","clk":"1008272946","pt":1580632312387,"mc":[{"id":"1.168224328","rc":[{"batb":[[2,3,18.93]],"ltp":2.24,"tv":19.36,"id":2397396}]}]}
{"op":"mcm","clk":"1008273004","pt":1580632313007,"mc":[{"id":"1.168224328","rc":[{"batb":[[2,3.25,16.83]],"ltp":2.24,"tv":19.36,"id":2397396}]}]}
{"op":"mcm","clk":"1008281876","pt":1580632440863,"mc":[{"id":"1.168224328","rc":[{"batb":[[0,3.65,39.88]],"ltp":2.24,"tv":19.36,"id":2397396},{"trd":[[1.32,57.71]],"batb":[[0,1.3,105.1],[1,1.25,72.69],[2,1.21,180.3]],"ltp":1.32,"tv":205.1,"id":8979329}],"tv":224.46}]}
{"op":"mcm","clk":"1008283361","pt":1580632462080,"mc":[{"id":"1.168224328","rc":[{"batb":[[0,3.7,40],[1,3.65,39.81],[2,3.5,27.26]],"ltp":2.24,"tv":19.36,"id":2397396}]}]}
{"op":"mcm","clk":"1008290398","pt":1580632569518,"mc":[{"id":"1.168224328","rc":[{"batb":[[0,3.75,27.56],[1,3.7,40]],"ltp":2.24,"tv":19.36,"id":2397396}]}]}
{"op":"mcm","clk":"1008290482","pt":1580632571022,"mc":[{"id":"1.168224328","rc":[{"batb":[[1,3.5,27.34],[2,3.25,16.83]],"ltp":2.24,"tv":19.36,"id":2397396}]}]}
{"op":"mcm","clk":"1008293103","pt":1580632615782,"mc":[{"id":"1.168224328","rc":[{"batb":[[1,3.5,27.26]],"ltp":2.24,"tv":19.36,"id":2397396}]}]}
{"op":"mcm","clk":"1008296619","pt":1580632676677,"mc":[{"id":"1.168224328","rc":[{"batb":[[0,3.75,27.63]],"ltp":2.24,"tv":19.36,"id":2397396}]}]}
{"op":"mcm","clk":"1008298172","pt":1580632700399,"mc":[{"id":"1.168224328","rc":[{"batb":[[0,3.5,27.34],[1,3.25,16.83],[2,3,18.93]],"ltp":2.24,"tv":19.36,"id":2397396}]}]}
{"op":"mcm","clk":"1008298212","pt":1580632700859,"mc":[{"id":"1.168224328","rc":[{"batb":[[0,3.65,40.72],[1,3.5,27.26],[2,3.25,16.83]],"ltp":2.24,"tv":19.36,"id":2397396},{"batl":[[0,1.38,107.33],[1,1.39,15.74],[2,1.73,3.03]],"ltp":1.32,"tv":205.1,"id":8979329}]}]}
{"op":"mcm","clk":"1008310138","pt":1580632893400,"mc":[{"id":"1.168224328","rc":[{"batl":[[0,1.35,2.53],[1,1.38,107.33],[2,1.39,15.74]],"ltp":1.32,"tv":205.1,"id":8979329}]}]}
{"op":"mcm","clk":"1008310151","pt":1580632893597,"mc":[{"id":"1.168224328","rc":[{"batl":[[1,1.39,15.74],[2,1.73,3.03]],"ltp":1.32,"tv":205.1,"id":8979329}]}]}
{"op":"mcm","clk":"1008321449","pt":1580633122599,"mc":[{"id":"1.168224328","rc":[{"batb":[[0,1.31,6.8],[1,1.3,105.1],[2,1.25,72.69]],"ltp":1.32,"tv":205.1,"id":8979329}]}]}
{"op":"mcm","clk":"1008331512","pt":1580633351288,"mc":[{"id":"1.168224328","rc":[{"batb":[[0,3.65,43.89]],"batl":[[0,4.3,8.4],[1,7.2,153.72],[2,95,15.9]],"ltp":2.24,"tv":19.36,"id":2397396},{"batl":[[0,1.35,10.93]],"ltp":1.32,"tv":205.1,"id":8979329}]}]}
{"op":"mcm","clk":"1008331527","pt":1580633351451,"mc":[{"id":"1.168224328","rc":[{"batb":[[0,1.31,33.9]],"ltp":1.32,"tv":205.1,"id":8979329}]}]}
{"op":"mcm","clk":"1008333187","pt":1580633383123,"mc":[{"id":"1.168224328","rc":[{"batb":[[0,3.85,2.95],[1,3.65,40.72],[2,3.5,27.26]],"ltp":2.24,"tv":19.36,"id":2397396}]}]}
{"op":"mcm","clk":"1008337295","pt":1580633467522,"mc":[{"id":"1.168224328","rc":[{"batb":[[0,1.32,42.44],[1,1.31,33.9]],"ltp":1.32,"tv":205.1,"id":8979329}]}]}
{"op":"mcm","clk":"1008337732","pt":1580633476241,"mc":[{"id":"1.168224328","rc":[{"batl":[[0,7.2,153.72],[1,95,15.9],[2,990,2.2]],"ltp":2.24,"tv":19.36,"id":2397396}]}]}
{"op":"mcm","clk":"1008337774","pt":1580633477218,"mc":[{"id":"1.168224328","rc":[{"batl":[[0,4.2,8.4],[1,7.2,153.72],[2,95,15.9]],"ltp":2.24,"tv":19.36,"id":2397396},{"batb":[[0,1.32,68.69],[1,1.31,6.8]],"ltp":1.32,"tv":205.1,"id":8979329}]}]}
{"op":"mcm","clk":"1008339415","pt":1580633514362,"mc":[{"id":"1.168224328","rc":[{"batb":[[1,3.65,40.65]],"ltp":2.24,"tv":19.36,"id":2397396}]}]}
{"op":"mcm","clk":"1008342149","pt":1580633574586,"mc":[{"id":"1.168224328","rc":[{"batb":[[0,3.85,3.02]],"ltp":2.24,"tv":19.36,"id":2397396}]}]}
{"op":"mcm","clk":"1008348149","pt":1580633701428,"mc":[{"id":"1.168224328","rc":[{"trd":[[1.35,17.83]],"batl":[[0,1.35,2.02]],"ltp":1.35,"tv":222.93,"id":8979329}],"tv":242.29}]}
{"op":"mcm","clk":"1008368160","pt":1580634053279,"mc":[{"id":"1.168224328","rc":[{"batb":[[2,3.55,27.26]],"ltp":2.24,"tv":19.36,"id":2397396},{"batb":[[2,1.24,72.69]],"ltp":1.35,"tv":222.93,"id":8979329}]}]}
{"op":"mcm","clk":"1008369113","pt":1580634069567,"mc":[{"id":"1.168224328","rc":[{"trd":[[1.35,21.19]],"batl":[[0,1.39,16.08],[1,1.73,3.03],[2,1.99,132.64]],"ltp":1.35,"tv":226.29,"id":8979329}],"tv":245.65}]}
{"op":"mcm","clk":"1008396344","pt":1580634537934,"mc":[{"id":"1.168224328","rc":[{"batl":[[1,1.5,2.27],[2,1.73,3.03]],"ltp":1.35,"tv":226.29,"id":8979329}]}]}
{"op":"mcm","clk":"1008425123","pt":1580635011437,"mc":[{"id":"1.168224328","rc":[{"trd":[[1.32,157.71]],"batb":[[0,1.32,18.69]],"ltp":1.32,"tv":326.29,"id":8979329}],"tv":345.65}]}
{"op":"mcm","clk":"1008425363","pt":1580635015563,"mc":[{"id":"1.168224328","rc":[{"batb":[[0,3.9,23.85],[1,3.85,2.95]],"ltp":2.24,"tv":19.36,"id":2397396},{"batb":[[2,1.28,130.61]],"ltp":1.32,"tv":326.29,"id":8979329}]}]}
{"op":"mcm","clk":"1008426661","pt":1580635036226,"mc":[{"id":"1.168224328","rc":[{"batb":[[0,3.9,26.75],[1,3.55,27.26],[2,3.25,21.2]],"ltp":2.24,"tv":19.36,"id":2397396},{"batl":[[0,1.35,8.4],[1,1.39,15.74],[2,1.5,2.27]],"ltp":1.32,"tv":326.29,"id":8979329}]}]}
{"op":"mcm","clk":"1008448515","pt":1580635424838,"mc":[{"id":"1.168224328","rc":[{"trd":[[4.2,8.4]],"batl":[[0,7.2,153.72],[1,95,15.9],[2,990,2.2]],"ltp":4.2,"tv":27.76,"id":2397396},{"trd":[[1.31,45.39],[1.32,195.08]],"batb":[[0,1.28,130.61],[1,1.24,72.69],[2,1.21,227.17]],"batl":[[0,1.31,2.32],[1,1.35,8.4],[2,1.39,15.74]],"ltp":1.31,"tv":404.16,"id":8979329}],"tv":431.92}]}
{"op":"mcm","clk":"1008449471","pt":1580635442353,"mc":[{"id":"1.168224328","rc":[{"batl":[[0,1.31,14.93],[1,1.39,15.74],[2,1.5,2.27]],"ltp":1.31,"tv":404.16,"id":8979329}]}]}
{"op":"mcm","clk":"1008449645","pt":1580635445384,"mc":[{"id":"1.168224328","rc":[{"trd":[[1.31,75.25]],"batb":[[0,1.28,115.55]],"batl":[[0,1.39,15.74],[1,1.5,2.27],[2,1.66,74.21]],"ltp":1.31,"tv":434.02,"id":8979329}],"tv":461.78}]}
{"op":"mcm","clk":"1008449655","pt":1580635445488,"mc":[{"id":"1.168224328","rc":[{"batb":[[0,3.95,4.86],[1,3.9,26.75],[2,3.55,27.26]],"ltp":4.2,"tv":27.76,"id":2397396}]}]}
{"op":"mcm","clk":"1008451293","pt":1580635473988,"mc":[{"id":"1.168224328","rc":[{"batb":[[0,3.95,9.13],[1,3.9,23.85]],"ltp":4.2,"tv":27.76,"id":2397396},{"batl":[[0,1.34,12.6],[1,1.39,15.74],[2,1.5,2.27]],"ltp":1.31,"tv":434.02,"id":8979329}]}]}
{"op":"mcm","clk":"1008456795","pt":1580635577758,"mc":[{"id":"1.168224328","rc":[{"batb":[[0,4,17.53],[1,3.95,9.13],[2,3.55,27.34]],"ltp":4.2,"tv":27.76,"id":2397396}]}]}
{"op":"mcm","clk":"1008456871","pt":1580635578887,"mc":[{"id":"1.168224328","rc":[{"trd":[[1.34,22.02]],"batl":[[0,1.34,1.6]],"ltp":1.34,"tv":456.04,"id":8979329}],"tv":483.8}]}
{"op":"mcm","clk":"1008458115","pt":1580635598179,"mc":[{"id":"1.168224328","rc":[{"batb":[[1,3.95,4.86]],"ltp":4.2,"tv":27.76,"id":2397396}]}]}
{"op":"mcm","clk":"1008458171","pt":1580635599101,"mc":[{"id":"1.168224328","rc":[{"batb":[[0,4,20.32]],"ltp":4.2,"tv":27.76,"id":2397396},{"batl":[[0,1.34,8.4]],"ltp":1.34,"tv":456.04,"id":8979329}]}]}
{"op":"mcm","clk":"1008459426","pt":1580635613340,"mc":[{"id":"1.168224328","marketDefinition":{"bspMarket":false,"turnInPlayEnabled":true,"persistenceEnabled":true,"marketBaseRate":5.0,"eventId":"29681722","eventTypeId":"2","numberOfWinners":1,"bettingType":"ODDS","marketType":"MATCH_ODDS","marketTime":"2020-02-02T11:24:00.000Z","suspendTime":"2020-02-02T11:24:00.000Z","bspReconciled":false,"complete":true,"inPlay":false,"crossMatching":true,"runnersVoidable":false,"numberOfActiveRunners":2,"betDelay":0,"status":"OPEN","runners":[{"status":"ACTIVE","sortPriority":1,"id":8979329,"name":"Emil Ruusuvuori"},{"status":"ACTIVE","sortPriority":2,"id":2397396,"name":"Matthias Bachinger"}],"regulators":["MR_INT"],"countryCode":"FR","discountAllowed":true,"timezone":"UTC","openDate":"2020-02-02T11:30:00.000Z","version":3148345453,"name":"Match Odds","eventName":"Emil Ruusuvuori v Bachinger"},"rc":[{"batb":[[2,3.55,27.26]],"ltp":4.2,"tv":27.76,"id":2397396}]}]}
{"op":"mcm","clk":"1008459775","pt":1580635616342,"mc":[{"id":"1.168224328","marketDefinition":{"bspMarket":false,"turnInPlayEnabled":true,"persistenceEnabled":true,"marketBaseRate":5.0,"eventId":"29681722","eventTypeId":"2","numberOfWinners":1,"bettingType":"ODDS","marketType":"MATCH_ODDS","marketTime":"2020-02-02T11:24:00.000Z","suspendTime":"2020-02-02T11:24:00.000Z","bspReconciled":false,"complete":true,"inPlay":false,"crossMatching":true,"runnersVoidable":false,"numberOfActiveRunners":2,"betDelay":0,"status":"OPEN","runners":[{"status":"ACTIVE","sortPriority":1,"id":8979329,"name":"Emil Ruusuvuori"},{"status":"ACTIVE","sortPriority":2,"id":2397396,"name":"Matthias Bachinger"}],"regulators":["MR_INT"],"countryCode":"FR","discountAllowed":true,"timezone":"UTC","openDate":"2020-02-02T11:24:00.000Z","version":3148345453,"name":"Match Odds","eventName":"Emil Ruusuvuori v Bachinger"}}]}
{"op":"mcm","clk":"1008462087","pt":1580635652482,"mc":[{"id":"1.168224328","rc":[{"batb":[[2,3.25,21.2]],"ltp":4.2,"tv":27.76,"id":2397396},{"batb":[[1,1.21,227.17],[2,1.2,377.2]],"ltp":1.34,"tv":456.04,"id":8979329}]}]}
{"op":"mcm","clk":"1008463144","pt":1580635672554,"mc":[{"id":"1.168224328","rc":[{"batb":[[0,4,20.4]],"ltp":4.2,"tv":27.76,"id":2397396}]}]}
{"op":"mcm","clk":"1008465442","pt":1580635711528,"mc":[{"id":"1.168224328","rc":[{"batb":[[0,4,2.87],[1,3.95,22.99]],"ltp":4.2,"tv":27.76,"id":2397396}]}]}
{"op":"mcm","clk":"1008473291","pt":1580635844319,"mc":[{"id":"1.168224328","rc":[{"batb":[[1,3.95,45.98]],"ltp":4.2,"tv":27.76,"id":2397396},{"batb":[[0,1.28,231.1]],"ltp":1.34,"tv":456.04,"id":8979329}]}]}
{"op":"mcm","clk":"1008483125","pt":1580635993081,"mc":[{"id":"1.168224328","rc":[{"batb":[[2,3,18.93]],"ltp":4.2,"tv":27.76,"id":2397396},{"batb":[[1,1.2,377.2],[2,1.16,151.45]],"ltp":1.34,"tv":456.04,"id":8979329}]}]}
{"op":"mcm","clk":"1008483190","pt":1580635993804,"mc":[{"id":"1.168224328","rc":[{"batb":[[2,3.35,36.42]],"ltp":4.2,"tv":27.76,"id":2397396},{"batb":[[1,1.22,388.94],[2,1.2,377.2]],"ltp":1.34,"tv":456.04,"id":8979329}]}]}
{"op":"mcm","clk":"1008499962","pt":1580636214072,"mc":[{"id":"1.168224328","rc":[{"batb":[[2,3,18.93]],"ltp":4.2,"tv":27.76,"id":2397396},{"batb":[[1,1.2,377.2],[2,1.16,151.45]],"ltp":1.34,"tv":456.04,"id":8979329}]}]}
{"op":"mcm","clk":"1008500006","pt":1580636214645,"mc":[{"id":"1.168224328","rc":[{"batb":[[2,3.3,37.2]],"ltp":4.2,"tv":27.76,"id":2397396},{"batb":[[1,1.22,388.94],[2,1.2,377.2]],"ltp":1.34,"tv":456.04,"id":8979329}]}]}
{"op":"mcm","clk":"1008530195","pt":1580636655100,"mc":[{"id":"1.168224328","rc":[{"batb":[[0,4.1,90.62],[1,4,2.8],[2,3.95,45.98]],"ltp":4.2,"tv":27.76,"id":2397396}]}]}
{"op":"mcm","clk":"1008530303","pt":1580636656286,"mc":[{"id":"1.168224328","rc":[{"batb":[[1,1.2,377.2],[2,1.16,151.45]],"ltp":1.34,"tv":456.04,"id":8979329}]}]}
{"op":"mcm","clk":"1008530335","pt":1580636656901,"mc":[{"id":"1.168224328","rc":[{"batb":[[2,1.18,475.37]],"ltp":1.34,"tv":456.04,"id":8979329}]}]}
{"op":"mcm","clk":"1008531981","pt":1580636679342,"mc":[{"id":"1.168224328","rc":[{"batl":[[0,1.39,15.74],[1,1.5,2.27],[2,1.66,74.21]],"ltp":1.34,"tv":456.04,"id":8979329}]}]}
{"op":"mcm","clk":"1008532073","pt":1580636680321,"mc":[{"id":"1.168224328","rc":[{"batb":[[0,4.2,2.62],[1,4.1,90.62]],"ltp":4.2,"tv":27.76,"id":2397396},{"batl":[[0,1.32,8.4],[1,1.39,15.74],[2,1.5,2.27]],"ltp":1.34,"tv":456.04,"id":8979329}]}]}
{"op":"mcm","clk":"1008538588","pt":1580636763966,"mc":[{"id":"1.168224328","rc":[{"batb":[[1,3.85,85.91],[2,3.7,31.69]],"ltp":4.2,"tv":27.76,"id":2397396},{"batb":[[0,1.27,251.57]],"ltp":1.34,"tv":456.04,"id":8979329}]}]}
{"op":"mcm","clk":"1008542273","pt":1580636811330,"mc":[{"id":"1.168224328","rc":[{"batb":[[1,3.85,85.83]],"ltp":4.2,"tv":27.76,"id":2397396}]}]}
{"op":"mcm","clk":"1008546586","pt":1580636871426,"mc":[{"id":"1.168224328","rc":[{"batb":[[0,4.2,2.7]],"ltp":4.2,"tv":27.76,"id":2397396}]}]}
{"op":"mcm","clk":"1008559927","pt":1580637087003,"mc":[{"id":"1.168224328","rc":[{"batb":[[2,3,18.93]],"ltp":4.2,"tv":27.76,"id":2397396},{"batb":[[2,1.16,151.45]],"ltp":1.34,"tv":456.04,"id":8979329}]}]}
{"op":"mcm","clk":"1008559970","pt":1580637087572,"mc":[{"id":"1.168224328","rc":[{"batb":[[2,3.55,33.55]],"ltp":4.2,"tv":27.76,"id":2397396},{"batb":[[1,1.2,805.04]],"ltp":1.34,"tv":456.04,"id":8979329}]}]}
{"op":"mcm","clk":"1008561132","pt":1580637106322,"mc":[{"id":"1.168224328","rc":[{"batl":[[0,1.31,7.57],[1,1.32,8.4],[2,1.39,15.74]],"ltp":1.34,"tv":456.04,"id":8979329}]}]}
{"op":"mcm","clk":"1008561477","pt":1580637112342,"mc":[{"id":"1.168224328","rc":[{"batl":[[0,1.31,15.97],[1,1.39,15.74],[2,1.5,2.27]],"ltp":1.34,"tv":456.04,"id":8979329}]}]}
{"op":"mcm","clk":"1008563453","pt":1580637143303,"mc":[{"id":"1.168224328","rc":[{"batl":[[0,1.31,8.4]],"ltp":1.34,"tv":456.04,"id":8979329}]}]}
{"op":"mcm","clk":"1008603697","pt":1580637712220,"mc":[{"id":"1.168224328","rc":[{"batl":[[0,1.29,88.22],[1,1.31,8.4],[2,1.39,15.74]],"ltp":1.34,"tv":456.04,"id":8979329}]}]}
{"op":"mcm","clk":"1008603727","pt":1580637712739,"mc":[{"id":"1.168224328","rc":[{"trd":[[1.29,46]],"batl":[[0,1.29,65.22]],"ltp":1.29,"tv":502.03,"id":8979329}],"tv":529.79}]}
{"op":"mcm","clk":"1008605185","pt":1580637730389,"mc":[{"id":"1.168224328","rc":[{"batb":[[0,4.4,2.47],[1,3.85,85.91]],"ltp":4.2,"tv":27.76,"id":2397396},{"batl":[[1,1.39,15.74],[2,1.5,2.27]],"ltp":1.29,"tv":502.03,"id":8979329}]}]}
{"op":"mcm","clk":"1008607061","pt":1580637755315,"mc":[{"id":"1.168224328","rc":[{"trd":[[1.28,81.52]],"batl":[[0,1.28,24.47]],"ltp":1.28,"tv":583.55,"id":8979329}],"tv":611.31}]}
{"op":"mcm","clk":"1008607470","pt":1580637761606,"mc":[{"id":"1.168224328","rc":[{"batb":[[0,3.85,85.91],[1,3.55,33.55],[2,3.5,18.93]],"ltp":4.2,"tv":27.76,"id":2397396}]}]}
{"op":"mcm","clk":"1008610289","pt":1580637799391,"mc":[{"id":"1.168224328","rc":[{"batb":[[0,3.9,172.3]],"ltp":4.2,"tv":27.76,"id":2397396},{"trd":[[1.28,130.45]],"batb":[[0,1.27,227.24]],"batl":[[0,1.39,15.74],[1,1.5,2.27],[2,1.66,74.21]],"ltp":1.28,"tv":632.48,"id":8979329}],"tv":660.25}]}
{"op":"mcm","clk":"1008611189","pt":1580637810636,"mc":[{"id":"1.168224328","rc":[{"batl":[[0,1.34,7.57],[1,1.39,15.74],[2,1.5,2.27]],"ltp":1.28,"tv":632.48,"id":8979329}]}]}
{"op":"mcm","clk":"1008614551","pt":1580637854154,"mc":[{"id":"1.168224328","rc":[{"trd":[[4.3,0.08]],"batb":[[0,3.95,2.85],[1,3.9,81.67],[2,3.55,33.55]],"ltp":4.3,"tv":27.83,"id":2397396},{"trd":[[1.31,75.5],[1.34,50]],"batl":[[0,1.34,265.76]],"ltp":1.34,"tv":660.71,"id":8979329}],"tv":688.55}]}
{"op":"mcm","clk":"1008614647","pt":1580637855348,"mc":[{"id":"1.168224328","rc":[{"batb":[[0,3.95,92.36]],"ltp":4.3,"tv":27.83,"id":2397396},{"trd":[[1.33,15.26]],"batb":[[1,1.21,37.86],[2,1.2,805.04]],"batl":[[0,1.34,1.98]],"ltp":1.33,"tv":675.98,"id":8979329}],"tv":703.82}]}
{"op":"mcm","clk":"1008614790","pt":1580637857058,"mc":[{"id":"1.168224328","rc":[{"batl":[[0,1.33,7.57],[1,1.34,1.98],[2,1.39,15.74]],"ltp":1.33,"tv":675.98,"id":8979329}]}]}
{"op":"mcm","clk":"1008614888","pt":1580637858147,"mc":[{"id":"1.168224328","rc":[{"batb":[[0,3.95,2.85]],"ltp":4.3,"tv":27.83,"id":2397396}]}]}
{"op":"mcm","clk":"1008615053","pt":1580637860170,"mc":[{"id":"1.168224328","rc":[{"batb":[[2,3,18.93]],"ltp":4.3,"tv":27.83,"id":2397396},{"batb":[[2,1.2,377.2]],"batl":[[1,1.34,9.56]],"ltp":1.33,"tv":675.98,"id":8979329}]}]}
{"op":"mcm","clk":"1008615103","pt":1580637860790,"mc":[{"id":"1.168224328","rc":[{"batb":[[2,3.55,35.34]],"ltp":4.3,"tv":27.83,"id":2397396},{"batb":[[2,1.2,827.75]],"batl":[[1,1.34,17.13]],"ltp":1.33,"tv":675.98,"id":8979329}]}]}
{"op":"mcm","clk":"1008615200","pt":1580637862199,"mc":[{"id":"1.168224328","rc":[{"batl":[[0,1.34,17.13],[1,1.39,15.74],[2,1.5,2.27]],"ltp":1.33,"tv":675.98,"id":8979329}]}]}
{"op":"mcm","clk":"1008615722","pt":1580637868480,"mc":[{"id":"1.168224328","rc":[{"batb":[[0,3.95,97.16]],"ltp":4.3,"tv":27.83,"id":2397396}]}]}
{"op":"mcm","clk":"1008617051","pt":1580637885313,"mc":[{"id":"1.168224328","rc":[{"batl":[[0,1.33,8.4],[1,1.34,15.14],[2,1.39,15.74]],"ltp":1.33,"tv":675.98,"id":8979329}]}]}
{"op":"mcm","clk":"1008617090","pt":1580637885930,"mc":[{"id":"1.168224328","rc":[{"trd":[[1.33,32.06],[1.34,61.7]],"batl":[[0,1.34,9.29],[1,1.39,15.74],[2,1.5,2.27]],"ltp":1.34,"tv":704.48,"id":8979329}],"tv":732.32}]}
{"op":"mcm","clk":"1008617930","pt":1580637897540,"mc":[{"id":"1.168224328","rc":[{"batl":[[0,1.39,15.74],[1,1.5,2.27],[2,1.66,74.21]],"ltp":1.34,"tv":704.48,"id":8979329}]}]}
{"op":"mcm","clk":"1008618022","pt":1580637898638,"mc":[{"id":"1.168224328","rc":[{"batb":[[0,1.3,6.03],[1,1.27,227.24],[2,1.21,37.86]],"ltp":1.34,"tv":704.48,"id":8979329}]}]}
{"op":"mcm","clk":"1008619767","pt":1580637917183,"mc":[{"id":"1.168224328","rc":[{"batb":[[0,3.95,2.85]],"batl":[[0,4.4,8.4],[1,7.2,153.72],[2,95,15.9]],"ltp":4.3,"tv":27.83,"id":2397396},{"batb":[[0,1.3,34.03]],"batl":[[0,1.33,8.4],[1,1.39,15.74],[2,1.5,2.27]],"ltp":1.34,"tv":704.48,"id":8979329}]}]}
{"op":"mcm","clk":"1008620442","pt":1580637924539,"mc":[{"id":"1.168224328","rc":[{"batl":[[1,1.34,7.57],[2,1.39,15.74]],"ltp":1.34,"tv":704.48,"id":8979329}]}]}
{"op":"mcm","clk":"1008621158","pt":1580637932304,"mc":[{"id":"1.168224328","rc":[{"batb":[[1,3.55,35.34],[2,3,18.93]],"ltp":4.3,"tv":27.83,"id":2397396}]}]}
{"op":"mcm","clk":"1008621169","pt":1580637932414,"mc":[{"id":"1.168224328","rc":[{"batb":[[0,4.1,38.1],[1,3.95,2.85],[2,3.55,35.34]],"ltp":4.3,"tv":27.83,"id":2397396}]}]}
{"op":"mcm","clk":"1008622519","pt":1580637948218,"mc":[{"id":"1.168224328","rc":[{"batl":[[0,1.34,7.57],[1,1.39,15.74],[2,1.5,2.27]],"ltp":1.34,"tv":704.48,"id":8979329}]}]}
{"op":"mcm","clk":"1008622587","pt":1580637949256,"mc":[{"id":"1.168224328","rc":[{"batl":[[0,7.2,153.72],[1,95,15.9],[2,990,2.2]],"ltp":4.3,"tv":27.83,"id":2397396},{"batb":[[0,1.3,6.03]],"ltp":1.34,"tv":704.48,"id":8979329}]}]}
{"op":"mcm","clk":"1008622617","pt":1580637949625,"mc":[{"id":"1.168224328","rc":[{"batb":[[1,3.55,35.34],[2,3,18.93]],"ltp":4.3,"tv":27.83,"id":2397396}]}]}
{"op":"mcm","clk":"1008632031","pt":1580638064328,"mc":[{"id":"1.168224328","rc":[{"batb":[[0,3.95,70.19]],"ltp":4.3,"tv":27.83,"id":2397396}]}]}
{"op":"mcm","clk":"1008632075","pt":1580638064735,"mc":[{"id":"1.168224328","rc":[{"batl":[[0,1.34,286.03]],"ltp":1.34,"tv":704.48,"id":8979329}]}]}
{"op":"mcm","clk":"1008640161","pt":1580638162391,"mc":[{"id":"1.168224328","rc":[{"trd":[[1.34,119.7]],"batl":[[0,1.39,15.74],[1,1.5,2.27],[2,1.66,74.21]],"ltp":1.34,"tv":762.48,"id":8979329}],"tv":790.32}]}
{"op":"mcm","clk":"1008640223","pt":1580638163172,"mc":[{"id":"1.168224328","rc":[{"batb":[[0,3.95,164.5]],"ltp":4.3,"tv":27.83,"id":2397396},{"batb":[[0,1.33,7.63],[1,1.3,6.03],[2,1.27,227.24]],"ltp":1.34,"tv":762.48,"id":8979329}]}]}
{"op":"mcm","clk":"1008643022","pt":1580638195699,"mc":[{"id":"1.168224328","rc":[{"batb":[[0,4,2.47],[1,3.95,159.57],[2,3.55,35.34]],"ltp":4.3,"tv":27.83,"id":2397396},{"trd":[[1.33,47.33]],"batb":[[0,1.3,6.03],[1,1.27,235.13],[2,1.21,37.86]],"ltp":1.33,"tv":777.75,"id":8979329}],"tv":805.58}]}
{"op":"mcm","clk":"1008646383","pt":1580638238567,"mc":[{"id":"1.168224328","rc":[{"batb":[[1,1.28,7.57],[2,1.27,235.13]],"ltp":1.33,"tv":777.75,"id":8979329}]}]}
{"op":"mcm","clk":"1008647734","pt":1580638256289,"mc":[{"id":"1.168224328","rc":[{"batb":[[1,3.95,65.26]],"ltp":4.3,"tv":27.83,"id":2397396},{"batb":[[0,1.3,34.03]],"batl":[[0,1.33,8.4],[1,1.39,15.74],[2,1.5,2.27]],"ltp":1.33,"tv":777.75,"id":8979329}]}]}
{"op":"mcm","clk":"1008654496","pt":1580638325337,"mc":[{"id":"1.168224328","rc":[{"batb":[[1,3.55,35.34],[2,3,18.93]],"ltp":4.3,"tv":27.83,"id":2397396}]}]}
{"op":"mcm","clk":"1008654504","pt":1580638325440,"mc":[{"id":"1.168224328","rc":[{"batb":[[0,4.1,35.68],[1,4,2.47],[2,3.55,35.34]],"ltp":4.3,"tv":27.83,"id":2397396}]}]}
{"op":"mcm","clk":"1008660145","pt":1580638379890,"mc":[{"id":"1.168224328","rc":[{"batb":[[0,4.1,38.4]],"batl":[[0,4.4,8.4],[1,7.2,153.72],[2,95,15.9]],"ltp":4.3,"tv":27.83,"id":2397396}]}]}
{"op":"mcm","clk":"1008661720","pt":1580638396839,"mc":[{"id":"1.168224328","rc":[{"batb":[[1,1.27,235.13],[2,1.21,37.86]],"ltp":1.33,"tv":777.75,"id":8979329}]}]}
{"op":"mcm","clk":"1008663388","pt":1580638415641,"mc":[{"id":"1.168224328","rc":[{"batb":[[1,1.29,6.82],[2,1.27,235.13]],"ltp":1.33,"tv":777.75,"id":8979329}]}]}
{"op":"mcm","clk":"1008673171","pt":1580638525547,"mc":[{"id":"1.168224328","rc":[{"batb":[[1,1.27,235.13],[2,1.21,37.86]],"ltp":1.33,"tv":777.75,"id":8979329}]}]}
{"op":"mcm","clk":"1008673948","pt":1580638533962,"mc":[{"id":"1.168224328","rc":[{"batb":[[1,1.28,7.57],[2,1.27,235.13]],"ltp":1.33,"tv":777.75,"id":8979329}]}]}
{"op":"mcm","clk":"1008722502","pt":1580639041870,"mc":[{"id":"1.168224328","rc":[{"batb":[[2,3,18.93]],"ltp":4.3,"tv":27.83,"id":2397396}]}]}
{"op":"mcm","clk":"1008722880","pt":1580639045211,"mc":[{"id":"1.168224328","rc":[{"batb":[[1,4,10.87]],"ltp":4.3,"tv":27.83,"id":2397396}]}]}
{"op":"mcm","clk":"1008733098","pt":1580639151342,"mc":[{"id":"1.168224328","rc":[{"trd":[[4.4,15.95]],"batb":[[0,4.1,52.27],[2,3.5,18.93]],"batl":[[0,7.2,154.15],[1,95,15.9],[2,990,2.2]],"ltp":4.4,"tv":43.78,"id":2397396},{"trd":[[1.3,68.03]],"batb":[[0,1.28,7.57],[1,1.27,235.13],[2,1.23,109.59]],"batl":[[0,1.3,380.67],[1,1.33,8.4],[2,1.39,15.74]],"ltp":1.3,"tv":845.77,"id":8979329}],"tv":889.56}]}
{"op":"mcm","clk":"1008733129","pt":1580639151552,"mc":[{"id":"1.168224328","rc":[{"batb":[[0,4.2,4.72],[1,4.1,52.27],[2,4,10.87]],"ltp":4.4,"tv":43.78,"id":2397396}]}]}
{"op":"mcm","clk":"1008734146","pt":1580639160036,"mc":[{"id":"1.168224328","rc":[{"batl":[[1,1.39,15.74],[2,1.5,2.27]],"ltp":1.3,"tv":845.77,"id":8979329}]}]}
{"op":"mcm","clk":"1008734302","pt":1580639161364,"mc":[{"id":"1.168224328","rc":[{"batb":[[1,4.1,49.56]],"batl":[[0,7.2,153.72]],"ltp":4.4,"tv":43.78,"id":2397396},{"trd":[[1.3,149.98]],"batl":[[0,1.3,339.72]],"ltp":1.3,"tv":927.73,"id":8979329}],"tv":971.52}]}
{"op":"mcm","clk":"1008734432","pt":1580639162361,"mc":[{"id":"1.168224328","rc":[{"batb":[[0,4.4,3.71],[1,4.2,4.72],[2,4.1,43.82]],"ltp":4.4,"tv":43.78,"id":2397396}]}]}
{"op":"mcm","clk":"1008735298","pt":1580639169475,"mc":[{"id":"1.168224328","rc":[{"trd":[[1.3,239.94]],"batl":[[0,1.3,294.76]],"ltp":1.3,"tv":1017.68,"id":8979329}],"tv":1061.47}]}
{"op":"mcm","clk":"1008742032","pt":1580639227231,"mc":[{"id":"1.168224328","rc":[{"trd":[[1.3,339.89]],"batl":[[0,1.3,244.81]],"ltp":1.3,"tv":1117.64,"id":8979329}],"tv":1161.42}]}
{"op":"mcm","clk":"1008744118","pt":1580639245251,"mc":[{"id":"1.168224328","rc":[{"trd":[[4.4,23.36]],"batb":[[0,4.2,4.72],[1,4.1,47.71],[2,4,10.87]],"ltp":4.4,"tv":51.19,"id":2397396},{"batb":[[1,1.27,222.45]],"ltp":1.3,"tv":1117.64,"id":8979329}],"tv":1168.83}]}
{"op":"mcm","clk":"1008745152","pt":1580639255253,"mc":[{"id":"1.168224328","rc":[{"batb":[[0,4.3,3.82],[1,4.2,4.72],[2,4.1,47.71]],"ltp":4.4,"tv":51.19,"id":2397396},{"trd":[[1.3,453.83]],"batl":[[0,1.3,187.87]],"ltp":1.3,"tv":1231.58,"id":8979329}],"tv":1282.77}]}
{"op":"mcm","clk":"1008759753","pt":1580639402354,"mc":[{"id":"1.168224328","rc":[{"batb":[[0,1.28,25.43],[2,1.24,105.02]],"ltp":1.3,"tv":1231.58,"id":8979329}]}]}
{"op":"mcm","clk":"1008759765","pt":1580639402449,"mc":[{"id":"1.168224328","rc":[{"trd":[[1.3,577.77]],"batl":[[0,1.3,125.93]],"ltp":1.3,"tv":1355.51,"id":8979329}],"tv":1406.71}]}
{"op":"mcm","clk":"1008824183","pt":1580639981007,"mc":[{"id":"1.168224328","rc":[{"trd":[[4.3,5.89]],"batb":[[0,4.2,5.63],[1,4.1,47.71],[2,4,10.87]],"ltp":4.3,"tv":57.01,"id":2397396},{"trd":[[1.3,829.7]],"batl":[[0,1.39,15.77],[1,1.5,2.27],[2,1.66,74.21]],"ltp":1.3,"tv":1607.45,"id":8979329}],"tv":1664.46}]}
{"op":"mcm","clk":"1008824246","pt":1580639981489,"mc":[{"id":"1.168224328","rc":[{"batb":[[2,1.25,100.82]],"ltp":1.3,"tv":1607.45,"id":8979329}]}]}
{"op":"mcm","clk":"1008827118","pt":1580640008030,"mc":[{"id":"1.168224328","rc":[{"trd":[[4.2,11.68],[4.3,10.03]],"batb":[[0,4.2,3.08]],"ltp":4.2,"tv":64.42,"id":2397396},{"trd":[[1.3,837.3]],"batl":[[0,1.39,15.74]],"ltp":1.3,"tv":1615.05,"id":8979329}],"tv":1679.47}]}
{"op":"mcm","clk":"1008827190","pt":1580640008752,"mc":[{"id":"1.168224328","rc":[{"batb":[[1,4.1,39.57]],"ltp":4.2,"tv":64.42,"id":2397396},{"batb":[[0,1.29,7.63],[1,1.28,25.43],[2,1.27,222.45]],"ltp":1.3,"tv":1615.05,"id":8979329}]}]}
{"op":"mcm","clk":"1008827380","pt":1580640010450,"mc":[{"id":"1.168224328","rc":[{"batl":[[0,1.31,7.57],[1,1.39,15.74],[2,1.5,2.27]],"ltp":1.3,"tv":1615.05,"id":8979329}]}]}
{"op":"mcm","clk":"1008827492","pt":1580640011542,"mc":[{"id":"1.168224328","rc":[{"batb":[[1,4.1,47.71]],"ltp":4.2,"tv":64.42,"id":2397396}]}]}
{"op":"mcm","clk":"1008828702","pt":1580640023543,"mc":[{"id":"1.168224328","rc":[{"batl":[[0,1.31,43.28]],"ltp":1.3,"tv":1615.05,"id":8979329}]}]}
{"op":"mcm","clk":"1008833859","pt":1580640073334,"mc":[{"id":"1.168224328","rc":[{"batb":[[2,4,12.89]],"batl":[[0,4.7,2.05],[1,4.8,2.02],[2,7.2,153.72]],"ltp":4.2,"tv":64.42,"id":2397396},{"trd":[[1.31,159.27]],"batb":[[2,1.27,224.69]],"batl":[[0,1.31,1.39],[1,1.34,2.25],[2,1.35,2.1]],"ltp":1.31,"tv":1698.81,"id":8979329}],"tv":1763.24}]}
{"op":"mcm","clk":"1008833908","pt":1580640073905,"mc":[{"id":"1.168224328","rc":[{"batb":[[1,4.1,39.57]],"batl":[[0,4.6,2],[1,4.7,2.05],[2,4.8,2.02]],"ltp":4.2,"tv":64.42,"id":2397396},{"batb":[[0,1.3,7.63],[1,1.29,7.63],[2,1.28,27.48]],"ltp":1.31,"tv":1698.81,"id":8979329}]}]}
{"op":"mcm","clk":"1008834505","pt":1580640079012,"mc":[{"id":"1.168224328","rc":[{"batb":[[0,1.29,15.27],[1,1.28,27.48],[2,1.27,224.69]],"ltp":1.31,"tv":1698.81,"id":8979329}]}]}
{"op":"mcm","clk":"1008834607","pt":1580640079801,"mc":[{"id":"1.168224328","rc":[{"batl":[[0,4.7,2.05],[1,4.8,2.02],[2,7.2,153.72]],"ltp":4.2,"tv":64.42,"id":2397396},{"batb":[[1,1.28,25.43]],"ltp":1.31,"tv":1698.81,"id":8979329}]}]}
{"op":"mcm","clk":"1008838507","pt":1580640116288,"mc":[{"id":"1.168224328","rc":[{"batl":[[0,1.34,2.25],[1,1.35,2.1],[2,1.39,15.74]],"ltp":1.31,"tv":1698.81,"id":8979329}]}]}
{"op":"mcm","clk":"1008838635","pt":1580640117393,"mc":[{"id":"1.168224328","rc":[{"trd":[[4.2,17.52]],"batb":[[0,4.1,39.74],[1,4,12.89],[2,3.95,2.11]],"ltp":4.2,"tv":70.26,"id":2397396},{"batl":[[0,1.35,2.1],[1,1.36,2.07]],"ltp":1.31,"tv":1698.81,"id":8979329}],"tv":1769.08}]}
{"op":"mcm","clk":"1008838648","pt":1580640117496,"mc":[{"id":"1.168224328","rc":[{"batb":[[1,4,10.87]],"ltp":4.2,"tv":70.26,"id":2397396}]}]}
{"op":"mcm","clk":"1008842522","pt":1580640145335,"mc":[{"id":"1.168224328","rc":[{"batl":[[0,1.32,7.57],[1,1.35,2.1],[2,1.36,2.07]],"ltp":1.31,"tv":1698.81,"id":8979329}]}]}
{"op":"mcm","clk":"1008842678","pt":1580640146228,"mc":[{"id":"1.168224328","rc":[{"trd":[[4.1,45.68],[4.2,17.84]],"batb":[[0,4.1,16.74]],"ltp":4.1,"tv":116.26,"id":2397396},{"batl":[[1,1.34,2.02],[2,1.35,2.1]],"ltp":1.31,"tv":1698.81,"id":8979329}],"tv":1815.07}]}
{"op":"mcm","clk":"1008843033","pt":1580640148320,"mc":[{"id":"1.168224328","rc":[{"batb":[[1,4,12.89]],"ltp":4.1,"tv":116.26,"id":2397396},{"batb":[[2,1.27,2.24]],"batl":[[0,1.31,7.57],[1,1.32,7.57],[2,1.33,2.32]],"ltp":1.31,"tv":1698.81,"id":8979329}]}]}
{"op":"mcm","clk":"1008843177","pt":1580640149208,"mc":[{"id":"1.168224328","rc":[{"batb":[[0,1.29,167.89]],"batl":[[0,1.32,7.57],[1,1.33,2.32],[2,1.34,2.02]],"ltp":1.31,"tv":1698.81,"id":8979329}]}]}
{"op":"mcm","clk":"1008843299","pt":1580640150004,"mc":[{"id":"1.168224328","rc":[{"batb":[[1,4,2.47],[2,3.95,10.65]],"ltp":4.1,"tv":116.26,"id":2397396},{"batl":[[0,1.35,2.1],[1,1.36,2.07],[2,1.39,15.74]],"ltp":1.31,"tv":1698.81,"id":8979329}]}]}
{"op":"mcm","clk":"1008843664","pt":1580640152313,"mc":[{"id":"1.168224328","rc":[{"batl":[[1,7.2,153.72],[2,95,15.9]],"ltp":4.1,"tv":116.26,"id":2397396},{"batb":[[0,1.29,152.62]],"ltp":1.31,"tv":1698.81,"id":8979329}]}]}
{"op":"mcm","clk":"1008843799","pt":1580640153303,"mc":[{"id":"1.168224328","rc":[{"batl":[[1,4.8,2.02],[2,7.2,153.72]],"ltp":4.1,"tv":116.26,"id":2397396},{"batb":[[0,1.3,15.2],[1,1.29,152.62],[2,1.28,27.59]],"ltp":1.31,"tv":1698.81,"id":8979329}]}]}
{"op":"mcm","clk":"1008843903","pt":1580640154034,"mc":[{"id":"1.168224328","rc":[{"batl":[[0,4.6,2.01],[1,4.7,2.01],[2,4.8,2.02]],"ltp":4.1,"tv":116.26,"id":2397396}]}]}
{"op":"mcm","clk":"1008857183","pt":1580640248325,"mc":[{"id":"1.168224328","rc":[{"batb":[[0,4,2.47],[1,3.95,10.65],[2,3.9,2.06]],"ltp":4.1,"tv":116.26,"id":2397396}]}]}
{"op":"mcm","clk":"1008857259","pt":1580640249048,"mc":[{"id":"1.168224328","rc":[{"batb":[[0,4,37.88],[1,3.95,8.54]],"batl":[[2,7.2,153.72]],"ltp":4.1,"tv":116.26,"id":2397396},{"batl":[[0,1.36,2.07],[1,1.37,2.07]],"ltp":1.31,"tv":1698.81,"id":8979329}]}]}
{"op":"mcm","clk":"1008857333","pt":1580640249618,"mc":[{"id":"1.168224328","rc":[{"batb":[[1,3.9,10.75],[2,3.85,2.17]],"ltp":4.1,"tv":116.26,"id":2397396}]}]}
{"op":"mcm","clk":"1008875536","pt":1580640385221,"mc":[{"id":"1.168224328","rc":[{"batb":[[0,3.95,48.82],[1,3.9,8.69]],"batl":[[0,4.7,2.05],[1,4.8,2.02]],"ltp":4.1,"tv":116.26,"id":2397396},{"batb":[[0,1.29,152.62],[1,1.28,25.43],[2,1.27,2.09]],"batl":[[1,1.37,2.15]],"ltp":1.31,"tv":1698.81,"id":8979329}]}]}
{"op":"mcm","clk":"1008875691","pt":1580640386331,"mc":[{"id":"1.168224328","rc":[{"trd":[[3.95,19.54]],"batb":[[0,3.95,39.04],[1,3.85,11.02],[2,3.8,2.03]],"batl":[[0,4.5,2.01],[1,4.6,2.01],[2,4.7,2.05]],"ltp":3.95,"tv":135.8,"id":2397396},{"batb":[[0,1.31,15.08],[1,1.29,154.67],[2,1.28,27.59]],"ltp":1.31,"tv":1698.81,"id":8979329}],"tv":1834.62}]}
{"op":"mcm","clk":"1008875830","pt":1580640387430,"mc":[{"id":"1.168224328","rc":[{"batb":[[1,1.29,184.3]],"ltp":1.31,"tv":1698.81,"id":8979329}]}]}
{"op":"mcm","clk":"1008876989","pt":1580640396940,"mc":[{"id":"1.168224328","rc":[{"batb":[[0,1.29,184.3],[1,1.28,27.59],[2,1.27,2.09]],"ltp":1.31,"tv":1698.81,"id":8979329}]}]}
{"op":"mcm","clk":"1008877171","pt":1580640398353,"mc":[{"id":"1.168224328","rc":[{"batb":[[1,3.9,2.06],[2,3.85,8.85]],"batl":[[0,4.7,2.05],[1,4.8,2.02],[2,4.9,2.05]],"ltp":3.95,"tv":135.8,"id":2397396},{"batb":[[0,1.3,15.2],[1,1.29,182.25],[2,1.28,25.43]],"batl":[[0,1.33,7.57],[1,1.35,2.1],[2,1.37,2.07]],"ltp":1.31,"tv":1698.81,"id":8979329}]}]}
{"op":"mcm","clk":"1008877252","pt":1580640398927,"mc":[{"id":"1.168224328","rc":[{"batb":[[2,3.85,11.02]],"batl":[[0,4.6,2.01],[1,4.7,2.05],[2,4.8,2.02]],"ltp":3.95,"tv":135.8,"id":2397396},{"batb":[[2,1.28,27.48]],"batl":[[2,1.36,2.07]],"ltp":1.31,"tv":1698.81,"id":8979329}]}]}
{"op":"mcm","clk":"1008879044","pt":1580640413444,"mc":[{"id":"1.168224328","marketDefinition":{"bspMarket":false,"turnInPlayEnabled":true,"persistenceEnabled":true,"marketBaseRate":5.0,"eventId":"29681722","eventTypeId":"2","numberOfWinners":1,"bettingType":"ODDS","marketType":"MATCH_ODDS","marketTime":"2020-02-02T10:51:00.000Z","suspendTime":"2020-02-02T10:51:00.000Z","bspReconciled":false,"complete":true,"inPlay":false,"crossMatching":true,"runnersVoidable":false,"numberOfActiveRunners":2,"betDelay":0,"status":"OPEN","runners":[{"status":"ACTIVE","sortPriority":1,"id":8979329,"name":"Emil Ruusuvuori"},{"status":"ACTIVE","sortPriority":2,"id":2397396,"name":"Matthias Bachinger"}],"regulators":["MR_INT"],"countryCode":"FR","discountAllowed":true,"timezone":"UTC","openDate":"2020-02-02T11:24:00.000Z","version":3148437419,"name":"Match Odds","eventName":"Emil Ruusuvuori v Bachinger"}}]}
{"op":"mcm","clk":"1008879338","pt":1580640415335,"mc":[{"id":"1.168224328","rc":[{"trd":[[3.95,66.5],[4,2.52]],"batb":[[0,3.85,8.85],[1,3.75,2.03],[2,3.7,78.12]],"batl":[[0,4.4,2],[1,4.5,2.01],[2,4.6,2.01]],"ltp":3.95,"tv":185.28,"id":2397396},{"trd":[[1.33,54.9]],"batb":[[0,1.32,7.63],[1,1.31,122.45],[2,1.3,17.28]],"batl":[[0,1.36,2.07],[1,1.37,2.23],[2,1.38,2.04]],"ltp":1.33,"tv":1706.39,"id":8979329}],"tv":1891.67}]}
{"op":"mcm","clk":"1008879489","pt":1580640416385,"mc":[{"id":"1.168224328","rc":[{"batb":[[0,3.7,76.1],[1,3.65,9.51],[2,3.6,2]],"batl":[[2,4.7,2.01]],"ltp":3.95,"tv":185.28,"id":2397396},{"batl":[[0,1.39,15.74],[1,1.4,2.04],[2,1.41,2]],"ltp":1.33,"tv":1706.39,"id":8979329}]}]}
{"op":"mcm","clk":"1008879982","pt":1580640419651,"mc":[{"id":"1.168224328","rc":[{"batl":[[0,1.37,7.57],[1,1.39,17.83],[2,1.4,2.04]],"ltp":1.33,"tv":1706.39,"id":8979329}]}]}
{"op":"mcm","clk":"1008880280","pt":1580640421273,"mc":[{"id":"1.168224328","marketDefinition":{"bspMarket":false,"turnInPlayEnabled":true,"persistenceEnabled":true,"marketBaseRate":5.0,"eventId":"29681722","eventTypeId":"2","numberOfWinners":1,"bettingType":"ODDS","marketType":"MATCH_ODDS","marketTime":"2020-02-02T10:51:00.000Z","suspendTime":"2020-02-02T10:51:00.000Z","bspReconciled":false,"complete":true,"inPlay":false,"crossMatching":true,"runnersVoidable":false,"numberOfActiveRunners":2,"betDelay":0,"status":"OPEN","runners":[{"status":"ACTIVE","sortPriority":1,"id":8979329,"name":"Emil Ruusuvuori"},{"status":"ACTIVE","sortPriority":2,"id":2397396,"name":"Matthias Bachinger"}],"regulators":["MR_INT"],"countryCode":"FR","discountAllowed":true,"timezone":"UTC","openDate":"2020-02-02T10:51:00.000Z","version":3148437419,"name":"Match Odds","eventName":"Emil Ruusuvuori v Bachinger"},"rc":[{"batb":[[1,3.65,11.64]],"batl":[[2,7.2,153.72]],"ltp":3.95,"tv":185.28,"id":2397396},{"batl":[[0,1.36,7.57],[1,1.37,7.57],[2,1.38,2.04]],"ltp":1.33,"tv":1706.39,"id":8979329}]}]}
{"op":"mcm","clk":"1008880341","pt":1580640421793,"mc":[{"id":"1.168224328","rc":[{"batb":[[2,3.6,2.04]],"ltp":3.95,"tv":185.28,"id":2397396}]}]}
{"op":"mcm","clk":"1008880805","pt":1580640425242,"mc":[{"id":"1.168224328","rc":[{"batb":[[0,1.31,122.45],[1,1.3,2.08],[2,1.29,89.04]],"batl":[[0,1.38,2.04],[1,1.39,17.83],[2,1.4,2.04]],"ltp":1.33,"tv":1706.39,"id":8979329}]}]}
{"op":"mcm","clk":"1008880932","pt":1580640426357,"mc":[{"id":"1.168224328","rc":[{"batb":[[1,3.65,9.51]],"batl":[[0,4.5,2.01],[1,4.6,2.01]],"ltp":3.95,"tv":185.28,"id":2397396},{"batb":[[1,1.29,89.04],[2,1.28,27.59]],"batl":[[0,1.36,7.57],[1,1.38,2],[2,1.39,17.83]],"ltp":1.33,"tv":1706.39,"id":8979329}]}]}
{"op":"mcm","clk":"1008880996","pt":1580640426776,"mc":[{"id":"1.168224328","rc":[{"batb":[[1,3.65,11.53]],"batl":[[0,4.4,2],[1,4.5,2.01],[2,4.6,2.01]],"ltp":3.95,"tv":185.28,"id":2397396},{"batb":[[0,1.32,22.6],[1,1.31,122.45],[2,1.3,2.08]],"ltp":1.33,"tv":1706.39,"id":8979329}]}]}
{"op":"mcm","clk":"1008881482","pt":1580640430299,"mc":[{"id":"1.168224328","rc":[{"batb":[[0,3.75,2.03],[1,3.7,78.12],[2,3.65,11.53]],"ltp":3.95,"tv":185.28,"id":2397396},{"batl":[[0,1.35,7.57],[1,1.36,7.57],[2,1.37,2.02]],"ltp":1.33,"tv":1706.39,"id":8979329}]}]}
{"op":"mcm","clk":"1008882005","pt":1580640434277,"mc":[{"id":"1.168224328","rc":[{"batl":[[0,1.35,410.07]],"ltp":1.33,"tv":1706.39,"id":8979329}]}]}
{"op":"mcm","clk":"1008882155","pt":1580640435379,"mc":[{"id":"1.168224328","rc":[{"batb":[[0,3.75,9.17],[1,3.7,76.1],[2,3.65,11.64]],"batl":[[2,7.2,153.72]],"ltp":3.95,"tv":185.28,"id":2397396},{"trd":[[1.35,189.19]],"batb":[[0,1.34,7.63],[1,1.32,22.6],[2,1.31,122.45]],"batl":[[0,1.35,402.5],[2,1.38,2.04]],"ltp":1.35,"tv":1874.39,"id":8979329}],"tv":2059.67}]}
{"op":"mcm","clk":"1008882292","pt":1580640436271,"mc":[{"id":"1.168224328","rc":[{"batl":[[0,4.1,2.05],[1,4.2,2.03],[2,4.5,2.01]],"ltp":3.95,"tv":185.28,"id":2397396},{"trd":[[1.34,134.5]],"batb":[[0,1.32,24.83],[1,1.31,124.53],[2,1.29,2.01]],"batl":[[0,1.36,7.57],[1,1.38,2.04],[2,1.39,17.83]],"ltp":1.34,"tv":1889.19,"id":8979329}],"tv":2074.47}]}
{"op":"mcm","clk":"1008882402","pt":1580640437212,"mc":[{"id":"1.168224328","rc":[{"batb":[[0,3.7,76.1],[1,3.65,11.64],[2,3.6,2.04]],"batl":[[0,4.4,2],[1,4.5,2.01],[2,4.6,2.01]],"ltp":3.95,"tv":185.28,"id":2397396},{"batb":[[0,1.32,22.83],[1,1.31,122.45],[2,1.3,2.08]],"ltp":1.34,"tv":1889.19,"id":8979329}]}]}
{"op":"mcm","clk":"1008882630","pt":1580640438691,"mc":[{"id":"1.168224328","rc":[{"batb":[[0,3.75,2.03],[1,3.7,78.12],[2,3.65,11.64]],"ltp":3.95,"tv":185.28,"id":2397396},{"batl":[[0,1.35,7.57],[1,1.36,7.57],[2,1.37,2.07]],"ltp":1.34,"tv":1889.19,"id":8979329}]}]}
{"op":"mcm","clk":"1008882807","pt":1580640440110,"mc":[{"id":"1.168224328","rc":[{"batl":[[0,1.35,15.14]],"ltp":1.34,"tv":1889.19,"id":8979329}]}]}
{"op":"mcm","clk":"1008883318","pt":1580640444401,"mc":[{"id":"1.168224328","rc":[{"batb":[[0,1.31,145.28],[1,1.3,2.08],[2,1.29,88.97]],"ltp":1.34,"tv":1889.19,"id":8979329}]}]}
{"op":"mcm","clk":"1008883401","pt":1580640444924,"mc":[{"id":"1.168224328","rc":[{"batb":[[2,3.65,9.51]],"batl":[[0,4.5,2.01],[1,4.6,2.01],[2,7.2,153.72]],"ltp":3.95,"tv":185.28,"id":2397396},{"batb":[[1,1.29,2.05],[2,1.28,117.5]],"ltp":1.34,"tv":1889.19,"id":8979329}]}]}
{"op":"mcm","clk":"1008886138","pt":1580640468967,"mc":[{"id":"1.168224328","rc":[{"batb":[[2,1.28,117.61]],"batl":[[0,1.35,425.22]],"ltp":1.34,"tv":1889.19,"id":8979329}]}]}
{"op":"mcm","clk":"1008886296","pt":1580640470329,"mc":[{"id":"1.168224328","rc":[{"batb":[[0,3.75,11.2]],"batl":[[0,4.1,2.05],[1,4.2,2.03],[2,4.5,2.01]],"ltp":3.95,"tv":185.28,"id":2397396},{"trd":[[1.35,232.22]],"batb":[[0,1.34,21.89],[1,1.32,2.14],[2,1.31,147.13]],"batl":[[0,1.35,1.2]],"ltp":1.35,"tv":1932.21,"id":8979329}],"tv":2117.49}]}
{"op":"mcm","clk":"1008886413","pt":1580640471319,"mc":[{"id":"1.168224328","rc":[{"batb":[[0,3.8,2.03],[1,3.75,2.03],[2,3.7,76.1]],"batl":[[0,4.5,2.01],[1,4.6,2.01],[2,7.2,153.72]],"ltp":3.95,"tv":185.28,"id":2397396},{"trd":[[1.34,178.29]],"batb":[[0,1.31,145.05],[1,1.3,86.1],[2,1.29,2.05]],"batl":[[0,1.34,194.51],[1,1.35,1.2],[2,1.36,9.64]],"ltp":1.34,"tv":1976.0,"id":8979329}],"tv":2161.29}]}
{"op":"mcm","clk":"1008886448","pt":1580640471629,"mc":[{"id":"1.168224328","rc":[{"batb":[[0,3.8,11.03]],"ltp":3.95,"tv":185.28,"id":2397396},{"batb":[[1,1.29,2.05],[2,1.28,27.59]],"ltp":1.34,"tv":1976.0,"id":8979329}]}]}
{"op":"mcm","clk":"1008886521","pt":1580640472455,"mc":[{"id":"1.168224328","rc":[{"batl":[[1,1.35,8.78]],"ltp":1.34,"tv":1976.0,"id":8979329}]}]}
{"op":"mcm","clk":"1008886708","pt":1580640473832,"mc":[{"id":"1.168224328","rc":[{"batl":[[1,1.35,16.35]],"ltp":1.34,"tv":1976.0,"id":8979329}]}]}
{"op":"mcm","clk":"1008886967","pt":1580640476166,"mc":[{"id":"1.168224328","rc":[{"batb":[[0,3.8,9],[2,3.7,78.12]],"ltp":3.95,"tv":185.28,"id":2397396},{"batb":[[2,1.28,27.48]],"batl":[[0,1.35,16.35],[1,1.36,7.57],[2,1.37,2.23]],"ltp":1.34,"tv":1976.0,"id":8979329}]}]}
{"op":"mcm","clk":"1008887066","pt":1580640476956,"mc":[{"id":"1.168224328","rc":[{"batb":[[0,3.75,2.03],[1,3.7,78.12],[2,3.65,9.51]],"ltp":3.95,"tv":185.28,"id":2397396},{"batb":[[2,1.28,117.5]],"ltp":1.34,"tv":1976.0,"id":8979329}]}]}
{"op":"mcm","clk":"1008887260","pt":1580640478159,"mc":[{"id":"1.168224328","rc":[{"batl":[[0,1.35,23.92]],"ltp":1.34,"tv":1976.0,"id":8979329}]}]}
{"op":"mcm","clk":"1008887313","pt":1580640478644,"mc":[{"id":"1.168224328","rc":[{"batb":[[0,3.75,11.2]],"ltp":3.95,"tv":185.28,"id":2397396}]}]}
{"op":"mcm","clk":"1008889577","pt":1580640498373,"mc":[{"id":"1.168224328","rc":[{"batb":[[2,1.28,117.61]],"batl":[[0,1.35,433.99]],"ltp":1.34,"tv":1976.0,"id":8979329}]}]}
{"op":"mcm","clk":"1008889689","pt":1580640499298,"mc":[{"id":"1.168224328","rc":[{"batl":[[0,4.1,2.05],[1,4.2,2],[2,4.5,2.01]],"ltp":3.95,"tv":185.28,"id":2397396},{"trd":[[1.34,236.96],[1.35,292.89]],"batb":[[0,1.32,2.16],[1,1.31,147.13],[2,1.29,2.05]],"batl":[[0,1.35,1.15]],"ltp":1.34,"tv":2095.34,"id":8979329}],"tv":2280.63}]}
{"op":"mcm","clk":"1008889809","pt":1580640500396,"mc":[{"id":"1.168224328","rc":[{"batb":[[0,3.8,2],[1,3.75,2.03],[2,3.7,78.12]],"batl":[[0,4.5,2.01],[1,4.6,2.01],[2,7.2,153.72]],"ltp":3.95,"tv":185.28,"id":2397396},{"trd":[[1.34,236.99]],"batb":[[0,1.31,145.05],[1,1.29,2.05],[2,1.28,117.61]],"batl":[[0,1.34,194.65],[1,1.35,403.65],[2,1.36,9.57]],"ltp":1.34,"tv":2095.37,"id":8979329}],"tv":2280.66}]}
{"op":"mcm","clk":"1008889836","pt":1580640500662,"mc":[{"id":"1.168224328","rc":[{"batb":[[0,3.8,11]],"ltp":3.95,"tv":185.28,"id":2397396},{"trd":[[1.34,239.42]],"batb":[[2,1.28,27.59]],"batl":[[0,1.34,193.44]],"ltp":1.34,"tv":2097.8,"id":8979329}],"tv":2283.08}]}
{"op":"mcm","clk":"1008890094","pt":1580640503171,"mc":[{"id":"1.168224328","rc":[{"batl":[[1,1.35,418.8]],"ltp":1.34,"tv":2097.8,"id":8979329}]}]}
{"op":"mcm","clk":"1008890250","pt":1580640504373,"mc":[{"id":"1.168224328","rc":[{"batl":[[0,1.35,418.8],[1,1.36,7.57],[2,1.37,2.07]],"ltp":1.34,"tv":2097.8,"id":8979329}]}]}
{"op":"mcm","clk":"1008890317","pt":1580640504993,"mc":[{"id":"1.168224328","rc":[{"batb":[[0,3.75,11.2],[1,3.7,78.12],[2,3.65,11.64]],"ltp":3.95,"tv":185.28,"id":2397396},{"batb":[[2,1.28,117.61]],"batl":[[0,1.35,426.37]],"ltp":1.34,"tv":2097.8,"id":8979329}]}]}
{"op":"mcm","clk":"1008891104","pt":1580640512177,"mc":[{"id":"1.168224328","rc":[{"batb":[[2,3.65,9.51]],"ltp":3.95,"tv":185.28,"id":2397396},{"batb":[[2,1.28,117.5]],"batl":[[0,1.35,433.94]],"ltp":1.34,"tv":2097.8,"id":8979329}]}]}
{"op":"mcm","clk":"1008891503","pt":1580640515308,"mc":[{"id":"1.168224328","rc":[{"batb":[[0,1.32,22.6],[1,1.31,122.45],[2,1.29,2.05]],"ltp":1.34,"tv":2097.8,"id":8979329}]}]}
{"op":"mcm","clk":"1008891579","pt":1580640515986,"mc":[{"id":"1.168224328","rc":[{"batl":[[0,4.4,2.04],[1,4.5,2.01],[2,4.6,2.01]],"ltp":3.95,"tv":185.28,"id":2397396},{"batb":[[2,1.3,2.08]],"ltp":1.34,"tv":2097.8,"id":8979329}]}]}
{"op":"mcm","clk":"1008891743","pt":1580640517300,"mc":[{"id":"1.168224328","rc":[{"trd":[[1.35,502.89]],"batl":[[0,1.35,30.29]],"ltp":1.35,"tv":2307.8,"id":8979329}],"tv":2493.08}]}
{"op":"mcm","clk":"1008891837","pt":1580640517981,"mc":[{"id":"1.168224328","rc":[{"batl":[[0,1.35,427.94]],"ltp":1.35,"tv":2307.8,"id":8979329}]}]}
{"op":"mcm","clk":"1008891996","pt":1580640519207,"mc":[{"id":"1.168224328","rc":[{"batl":[[2,7.2,153.72]],"ltp":3.95,"tv":185.28,"id":2397396},{"trd":[[1.34,241.73]],"ltp":1.34,"tv":2310.12,"id":8979329}],"tv":2495.4}]}
{"op":"mcm","clk":"1008892247","pt":1580640521397,"mc":[{"id":"1.168224328","rc":[{"batb":[[0,1.31,122.45],[1,1.29,2.05],[2,1.28,117.61]],"batl":[[0,1.35,397.65],[1,1.37,2.07],[2,1.38,2.04]],"ltp":1.34,"tv":2310.12,"id":8979329}]}]}
{"op":"mcm","clk":"1008892363","pt":1580640522394,"mc":[{"id":"1.168224328","rc":[{"batb":[[0,3.9,27.31],[1,3.8,2.03],[2,3.75,11.2]],"batl":[[0,4.7,2.05],[1,4.8,2.02]],"ltp":3.95,"tv":185.28,"id":2397396},{"batb":[[0,1.32,22.63],[1,1.3,186.38]],"batl":[[0,1.35,405.22]],"ltp":1.34,"tv":2310.12,"id":8979329}]}]}
{"op":"mcm","clk":"1008892404","pt":1580640522810,"mc":[{"id":"1.168224328","rc":[{"batb":[[1,3.8,11.03],[2,3.75,11.17]],"batl":[[0,4.4,2],[1,4.5,2.01],[2,4.6,2.01]],"ltp":3.95,"tv":185.28,"id":2397396},{"batb":[[1,1.3,188.39],[2,1.29,2.12]],"batl":[[0,1.35,412.79]],"ltp":1.34,"tv":2310.12,"id":8979329}]}]}
{"op":"mcm","clk":"1008892505","pt":1580640523594,"mc":[{"id":"1.168224328","rc":[{"batl":[[1,1.36,7.57],[2,1.37,2.07]],"ltp":1.34,"tv":2310.12,"id":8979329}]}]}
{"op":"mcm","clk":"1008892715","pt":1580640525294,"mc":[{"id":"1.168224328","rc":[{"batl":[[1,1.37,2.07],[2,1.38,2.04]],"ltp":1.34,"tv":2310.12,"id":8979329}]}]}
{"op":"mcm","clk":"1008892832","pt":1580640526329,"mc":[{"id":"1.168224328","rc":[{"batl":[[0,1.35,420.37]],"ltp":1.34,"tv":2310.12,"id":8979329}]}]}
{"op":"mcm","clk":"1008892853","pt":1580640526441,"mc":[{"id":"1.168224328","rc":[{"batl":[[0,1.35,427.94]],"ltp":1.34,"tv":2310.12,"id":8979329}]}]}
{"op":"mcm","clk":"1008894088","pt":1580640537129,"mc":[{"id":"1.168224328","rc":[{"batl":[[0,1.35,435.51]],"ltp":1.34,"tv":2310.12,"id":8979329}]}]}
{"op":"mcm","clk":"1008894179","pt":1580640537921,"mc":[{"id":"1.168224328","rc":[{"trd":[[3.9,52.84]],"batb":[[0,3.8,9.88],[1,3.75,11.2],[2,3.7,2.02]],"batl":[[2,7.2,153.72]],"ltp":3.9,"tv":238.12,"id":2397396},{"batl":[[0,1.35,37.86],[2,1.38,2.02]],"ltp":1.34,"tv":2310.12,"id":8979329}],"tv":2548.24}]}
{"op":"mcm","clk":"1008894309","pt":1580640539223,"mc":[{"id":"1.168224328","rc":[{"batb":[[0,3.75,47.67],[1,3.7,2.02],[2,3.65,9.51]],"ltp":3.9,"tv":238.12,"id":2397396},{"batb":[[1,1.31,200.31],[2,1.3,2.01]],"batl":[[0,1.35,435.51]],"ltp":1.34,"tv":2310.12,"id":8979329}]}]}
{"op":"mcm","clk":"1008896093","pt":1580640554359,"mc":[{"id":"1.168224328","rc":[{"batl":[[1,1.36,7.57],[2,1.37,2.07]],"ltp":1.34,"tv":2310.12,"id":8979329}]}]}
{"op":"mcm","clk":"1008896564","pt":1580640558353,"mc":[{"id":"1.168224328","rc":[{"batl":[[0,4.3,2.05]],"ltp":3.9,"tv":238.12,"id":2397396},{"batb":[[0,1.33,22.63],[1,1.31,202.39],[2,1.3,2.08]],"ltp":1.34,"tv":2310.12,"id":8979329}]}]}
{"op":"mcm","clk":"1008896691","pt":1580640559402,"mc":[{"id":"1.168224328","rc":[{"batb":[[2,3.65,11.53]],"batl":[[1,4.4,2.04],[2,4.5,2.01]],"ltp":3.9,"tv":238.12,"id":2397396},{"trd":[[1.35,724.9]],"batb":[[0,1.34,38.13],[1,1.33,22.63],[2,1.31,202.39]],"batl":[[0,1.36,7.57],[1,1.38,2.04],[2,1.39,17.78]],"ltp":1.35,"tv":2532.13,"id":8979329}],"tv":2770.26}]}
{"op":"mcm","clk":"1008896781","pt":1580640560124,"mc":[{"id":"1.168224328","rc":[{"batb":[[0,3.75,38.5]],"batl":[[0,4.1,2.05],[1,4.2,2.03],[2,4.3,2.05]],"ltp":3.9,"tv":238.12,"id":2397396},{"batb":[[2,1.32,2.14]],"batl":[[0,1.35,405.22],[1,1.36,7.57],[2,1.37,2.23]],"ltp":1.35,"tv":2532.13,"id":8979329}]}]}
{"op":"mcm","clk":"1008896893","pt":1580640561125,"mc":[{"id":"1.168224328","rc":[{"batb":[[1,3.7,11.35]],"ltp":3.9,"tv":238.12,"id":2397396}]}]}
{"op":"mcm","clk":"1008897050","pt":1580640562326,"mc":[{"id":"1.168224328","rc":[{"batb":[[1,1.32,2.14],[2,1.31,202.39]],"ltp":1.35,"tv":2532.13,"id":8979329}]}]}
{"op":"mcm","clk":"1008897088","pt":1580640562637,"mc":[{"id":"1.168224328","rc":[{"batb":[[0,3.75,47.67]],"ltp":3.9,"tv":238.12,"id":2397396}]}]}
{"op":"mcm","clk":"1008897534","pt":1580640566324,"mc":[{"id":"1.168224328","rc":[{"batb":[[0,1.32,2.14],[1,1.31,202.39],[2,1.3,2.08]],"batl":[[0,1.35,397.65],[1,1.37,2.23],[2,1.38,2.04]],"ltp":1.35,"tv":2532.13,"id":8979329}]}]}
{"op":"mcm","clk":"1008897647","pt":1580640567363,"mc":[{"id":"1.168224328","rc":[{"batb":[[2,3.65,9.51]],"batl":[[0,4.5,2.01],[1,4.6,2.01],[2,7.2,153.72]],"ltp":3.9,"tv":238.12,"id":2397396},{"trd":[[1.34,317.43]],"batb":[[0,1.34,22.59],[1,1.31,200.31],[2,1.29,2.12]],"batl":[[2,1.38,2]],"ltp":1.34,"tv":2607.82,"id":8979329}],"tv":2845.95}]}
{"op":"mcm","clk":"1008897687","pt":1580640567629,"mc":[{"id":"1.168224328","rc":[{"batl":[[0,4.1,2.05],[1,4.2,2.03],[2,4.5,2.01]],"ltp":3.9,"tv":238.12,"id":2397396},{"batb":[[1,1.32,2.01],[2,1.31,202.39]],"ltp":1.34,"tv":2607.82,"id":8979329}]}]}
{"op":"mcm","clk":"1008898013","pt":1580640570298,"mc":[{"id":"1.168224328","rc":[{"batl":[[1,1.36,7.57],[2,1.37,2.23]],"ltp":1.34,"tv":2607.82,"id":8979329}]}]}
{"op":"mcm","clk":"1008898224","pt":1580640572230,"mc":[{"id":"1.168224328","rc":[{"batl":[[0,4.3,2],[1,4.4,2.04]],"ltp":3.9,"tv":238.12,"id":2397396},{"batb":[[0,1.31,200.31],[1,1.29,89.04],[2,1.28,117.61]],"ltp":1.34,"tv":2607.82,"id":8979329}]}]}
{"op":"mcm","clk":"1008898315","pt":1580640572816,"mc":[{"id":"1.168224328","rc":[{"batl":[[0,4.5,2.01],[1,4.6,2.01],[2,7.2,153.72]],"ltp":3.9,"tv":238.12,"id":2397396},{"batb":[[1,1.29,2.12]],"ltp":1.34,"tv":2607.82,"id":8979329}]}]}
{"op":"mcm","clk":"1008898517","pt":1580640574233,"mc":[{"id":"1.168224328","rc":[{"batl":[[1,1.37,2.23],[2,1.38,2]],"ltp":1.34,"tv":2607.82,"id":8979329}]}]}
{"op":"mcm","clk":"1008898642","pt":1580640575228,"mc":[{"id":"1.168224328","rc":[{"batl":[[0,4.1,2.05],[1,4.2,2],[2,4.6,2.01]],"ltp":3.9,"tv":238.12,"id":2397396},{"trd":[[1.34,321.43]],"batb":[[0,1.34,20.59],[1,1.32,2.14],[2,1.31,202.39]],"ltp":1.34,"tv":2611.82,"id":8979329}],"tv":2849.95}]}
{"op":"mcm","clk":"1008899050","pt":1580640578359,"mc":[{"id":"1.168224328","rc":[{"batb":[[0,1.32,2.14],[1,1.31,202.39],[2,1.29,86.92]],"ltp":1.34,"tv":2611.82,"id":8979329}]}]}
{"op":"mcm","clk":"1008899179","pt":1580640579360,"mc":[{"id":"1.168224328","rc":[{"batb":[[0,3.75,45.64],[1,3.7,9.33],[2,3.65,11.64]],"batl":[[0,4.5,2.01],[1,4.6,2.01],[2,7.2,153.72]],"ltp":3.9,"tv":238.12,"id":2397396},{"trd":[[1.35,982.9]],"batb":[[0,1.31,200.31],[1,1.29,2.01],[2,1.28,117.61]],"batl":[[0,1.39,17.83],[1,1.4,2.02],[2,1.5,2.27]],"ltp":1.35,"tv":2869.82,"id":8979329}],"tv":3107.95}]}
{"op":"mcm","clk":"1008899248","pt":1580640579833,"mc":[{"id":"1.168224328","rc":[{"batb":[[0,3.8,138.93],[1,3.75,36.47],[2,3.7,2.02]],"ltp":3.9,"tv":238.12,"id":2397396},{"batl":[[0,1.38,2.04],[1,1.39,17.83],[2,1.4,2.04]],"ltp":1.35,"tv":2869.82,"id":8979329}]}]}
{"op":"mcm","clk":"1008899410","pt":1580640581036,"mc":[{"id":"1.168224328","rc":[{"batb":[[2,3.7,11.35]],"batl":[[0,4.1,2.05],[1,4.2,2.03],[2,4.5,2.01]],"ltp":3.9,"tv":238.12,"id":2397396},{"batb":[[0,1.34,20.59],[1,1.32,2.14],[2,1.31,202.39]],"ltp":1.35,"tv":2869.82,"id":8979329}]}]}
{"op":"mcm","clk":"1008899650","pt":1580640582761,"mc":[{"id":"1.168224328","rc":[{"batb":[[0,3.75,38.5],[1,3.7,11.35],[2,3.65,11.64]],"ltp":3.9,"tv":238.12,"id":2397396},{"batl":[[0,1.35,7.57],[1,1.37,2],[2,1.38,2.04]],"ltp":1.35,"tv":2869.82,"id":8979329}]}]}
{"op":"mcm","clk":"1008899774","pt":1580640583649,"mc":[{"id":"1.168224328","rc":[{"batb":[[1,3.7,2.02]],"ltp":3.9,"tv":238.12,"id":2397396}]}]}
{"op":"mcm","clk":"1008899930","pt":1580640584861,"mc":[{"id":"1.168224328","rc":[{"batl":[[2,7.2,153.72]],"ltp":3.9,"tv":238.12,"id":2397396},{"batl":[[1,1.36,7.57],[2,1.37,2]],"ltp":1.35,"tv":2869.82,"id":8979329}]}]}
{"op":"mcm","clk":"1008900114","pt":1580640586338,"mc":[{"id":"1.168224328","rc":[{"batb":[[0,3.8,138.93],[1,3.75,38.5],[2,3.7,2.02]],"ltp":3.9,"tv":238.12,"id":2397396},{"batl":[[0,1.36,7.57],[1,1.37,2],[2,1.38,2.04]],"ltp":1.35,"tv":2869.82,"id":8979329}]}]}
{"op":"mcm","clk":"1008900176","pt":1580640586859,"mc":[{"id":"1.168224328","rc":[{"batb":[[1,3.75,36.47],[2,3.7,11.35]],"ltp":3.9,"tv":238.12,"id":2397396},{"batl":[[1,1.38,2.04],[2,1.39,17.83]],"ltp":1.35,"tv":2869.82,"id":8979329}]}]}
{"op":"mcm","clk":"1008900775","pt":1580640591361,"mc":[{"id":"1.168224328","rc":[{"batl":[[0,4.1,4.7]],"ltp":3.9,"tv":238.12,"id":2397396},{"batb":[[0,1.33,20.59],[1,1.31,200.31],[2,1.3,2.08]],"ltp":1.35,"tv":2869.82,"id":8979329}]}]}
{"op":"mcm","clk":"1008900845","pt":1580640591877,"mc":[{"id":"1.168224328","rc":[{"batl":[[0,4.3,2.05],[1,4.4,2.04],[2,4.5,2.01]],"ltp":3.9,"tv":238.12,"id":2397396},{"batb":[[1,1.31,202.39]],"ltp":1.35,"tv":2869.82,"id":8979329}]}]}
{"op":"mcm","clk":"1008901013","pt":1580640593344,"mc":[{"id":"1.168224328","rc":[{"batb":[[0,1.31,202.39],[1,1.3,2.08],[2,1.29,89.04]],"ltp":1.35,"tv":2869.82,"id":8979329}]}]}
{"op":"mcm","clk":"1008901109","pt":1580640594073,"mc":[{"id":"1.168224328","rc":[{"batl":[[0,4.4,2.04],[1,4.5,2.01],[2,4.6,2.01]],"ltp":3.9,"tv":238.12,"id":2397396},{"batb":[[0,1.32,20.59],[1,1.31,200.31],[2,1.3,2.08]],"ltp":1.35,"tv":2869.82,"id":8979329}]}]}
{"op":"mcm","clk":"1008901370","pt":1580640596371,"mc":[{"id":"1.168224328","rc":[{"batb":[[0,3.75,38.5],[1,3.7,11.35],[2,3.65,11.53]],"ltp":3.9,"tv":238.12,"id":2397396},{"batl":[[0,1.35,7.57],[1,1.36,7.57],[2,1.37,2.07]],"ltp":1.35,"tv":2869.82,"id":8979329}]}]}
{"op":"mcm","clk":"1008901495","pt":1580640597367,"mc":[{"id":"1.168224328","rc":[{"trd":[[3.85,2.66]],"batb":[[0,3.75,36.47],[1,3.65,11.53],[2,3.6,2.04]],"ltp":3.85,"tv":240.78,"id":2397396},{"trd":[[1.35,990.47]],"batl":[[0,1.36,396.14],[1,1.38,2.04],[2,1.39,17.83]],"ltp":1.35,"tv":2877.39,"id":8979329}],"tv":3118.18}]}
{"op":"mcm","clk":"1008901585","pt":1580640598042,"mc":[{"id":"1.168224328","rc":[{"batl":[[0,4.1,2.05],[1,4.2,2.03],[2,7.2,153.72]],"ltp":3.85,"tv":240.78,"id":2397396},{"batb":[[0,1.34,7.63],[1,1.32,22.73],[2,1.31,202.31]],"ltp":1.35,"tv":2877.39,"id":8979329}]}]}
{"op":"mcm","clk":"1008901982","pt":1580640601370,"mc":[{"id":"1.168224328","rc":[{"batl":[[0,1.36,388.57],[2,1.39,15.74]],"ltp":1.35,"tv":2877.39,"id":8979329}]}]}
{"op":"mcm","clk":"1008902008","pt":1580640601581,"mc":[{"id":"1.168224328","rc":[{"batl":[[2,1.39,17.83]],"ltp":1.35,"tv":2877.39,"id":8979329}]}]}
{"op":"mcm","clk":"1008903005","pt":1580640609401,"mc":[{"id":"1.168224328","rc":[{"batb":[[2,3,18.93]],"batl":[[1,7.2,153.72],[2,95,15.9]],"ltp":3.85,"tv":240.78,"id":2397396},{"batb":[[0,1.31,200.31],[1,1.3,2.08],[2,1.29,88.93]],"batl":[[2,1.39,15.74]],"ltp":1.35,"tv":2877.39,"id":8979329}]}]}
{"op":"mcm","clk":"1008903129","pt":1580640610390,"mc":[{"id":"1.168224328","rc":[{"batb":[[2,3.6,2.04]],"batl":[[1,4.2,2.03],[2,4.5,2.01]],"ltp":3.85,"tv":240.78,"id":2397396},{"batb":[[0,1.34,28.22],[1,1.32,2.14],[2,1.31,202.31]],"batl":[[2,1.39,17.83]],"ltp":1.35,"tv":2877.39,"id":8979329}]}]}
{"op":"mcm","clk":"1008903211","pt":1580640611123,"mc":[{"id":"1.168224328","rc":[{"batb":[[0,3.75,89.82]],"ltp":3.85,"tv":240.78,"id":2397396},{"batb":[[2,1.31,480.14]],"ltp":1.35,"tv":2877.39,"id":8979329}]}]}
{"op":"mcm","clk":"1008904145","pt":1580640618379,"mc":[{"id":"1.168224328","rc":[{"batb":[[2,3,18.93]],"batl":[[0,4.3,2.02],[1,4.4,2.04]],"ltp":3.85,"tv":240.78,"id":2397396},{"batb":[[0,1.31,478.14],[1,1.3,86.03],[2,1.29,2.01]],"batl":[[2,1.39,15.74]],"ltp":1.35,"tv":2877.39,"id":8979329}]}]}
{"op":"mcm","clk":"1008904302","pt":1580640619376,"mc":[{"id":"1.168224328","rc":[{"batb":[[2,3.6,2.04]],"batl":[[0,4.1,2.05],[1,4.2,2.03]],"ltp":3.85,"tv":240.78,"id":2397396},{"trd":[[1.36,286]],"batb":[[0,1.34,7.57],[1,1.32,2.01],[2,1.31,480.22]],"batl":[[0,1.39,17.83],[1,1.4,2.04],[2,1.5,2.27]],"ltp":1.36,"tv":3163.39,"id":8979329}],"tv":3404.18}]}
{"op":"mcm","clk":"1008904612","pt":1580640621986,"mc":[{"id":"1.168224328","rc":[{"batl":[[0,4,2.01],[1,4.1,2.05],[2,4.2,2.03]],"ltp":3.85,"tv":240.78,"id":2397396},{"batb":[[0,1.35,7.57],[1,1.34,7.57],[2,1.33,2.01]],"ltp":1.36,"tv":3163.39,"id":8979329}]}]}
{"op":"mcm","clk":"1008904819","pt":1580640623790,"mc":[{"id":"1.168224328","rc":[{"batb":[[0,1.35,15.14]],"ltp":1.36,"tv":3163.39,"id":8979329}]}]}
{"op":"mcm","clk":"1008906702","pt":1580640639211,"mc":[{"id":"1.168224328","rc":[{"trd":[[3.75,82]],"batb":[[0,3.75,48.82]],"batl":[[0,4.2,2],[1,4.3,2.05],[2,7.2,153.72]],"ltp":3.75,"tv":322.79,"id":2397396},{"batb":[[0,1.31,480.22],[1,1.3,86.1],[2,1.29,86.92]],"batl":[[1,1.4,2.02]],"ltp":1.36,"tv":3163.39,"id":8979329}],"tv":3486.19}]}
{"op":"mcm","clk":"1008906814","pt":1580640640009,"mc":[{"id":"1.168224328","rc":[{"batb":[[2,3.6,41.29]],"batl":[[0,4.1,2.05],[1,4.2,2.03],[2,4.5,2]],"ltp":3.75,"tv":322.79,"id":2397396},{"batb":[[0,1.34,28.22],[1,1.32,243.28],[2,1.31,279.43]],"ltp":1.36,"tv":3163.39,"id":8979329}]}]}
{"op":"mcm","clk":"1008907122","pt":1580640642304,"mc":[{"id":"1.168224328","rc":[{"batb":[[0,1.33,28.22],[1,1.32,241.14],[2,1.31,277.35]],"ltp":1.36,"tv":3163.39,"id":8979329}]}]}
{"op":"mcm","clk":"1008907167","pt":1580640642729,"mc":[{"id":"1.168224328","rc":[{"batl":[[0,4.3,2.05],[1,4.4,2.04]],"ltp":3.75,"tv":322.79,"id":2397396},{"batb":[[2,1.31,279.43]],"ltp":1.36,"tv":3163.39,"id":8979329}]}]}
{"op":"mcm","clk":"1008909884","pt":1580640666353,"mc":[{"id":"1.168224328","rc":[{"batb":[[2,3.6,2.04]],"ltp":3.75,"tv":322.79,"id":2397396},{"batb":[[1,1.32,194.92]],"ltp":1.36,"tv":3163.39,"id":8979329}]}]}
{"op":"mcm","clk":"1008909951","pt":1580640667078,"mc":[{"id":"1.168224328","rc":[{"trd":[[3.75,144.01]],"batb":[[0,3.75,17.81],[1,3.7,29.37],[2,3.65,11.53]],"ltp":3.75,"tv":384.79,"id":2397396},{"batb":[[0,1.32,194.92],[1,1.31,279.43],[2,1.3,2.01]],"ltp":1.36,"tv":3163.39,"id":8979329}],"tv":3548.19}]}
{"op":"mcm","clk":"1008910085","pt":1580640668174,"mc":[{"id":"1.168224328","rc":[{"batb":[[0,3.75,54.4]],"ltp":3.75,"tv":384.79,"id":2397396},{"batb":[[0,1.34,28.22],[1,1.32,194.92],[2,1.31,276.05]],"ltp":1.36,"tv":3163.39,"id":8979329}]}]}
{"op":"mcm","clk":"1008911248","pt":1580640678271,"mc":[{"id":"1.168224328","rc":[{"batb":[[0,1.35,28.22]],"ltp":1.36,"tv":3163.39,"id":8979329}]}]}
{"op":"mcm","clk":"1008912057","pt":1580640684992,"mc":[{"id":"1.168224328","rc":[{"batb":[[0,1.32,194.92],[1,1.31,276.05],[2,1.3,86.03]],"ltp":1.36,"tv":3163.39,"id":8979329}]}]}
{"op":"mcm","clk":"1008912213","pt":1580640686095,"mc":[{"id":"1.168224328","rc":[{"trd":[[3.75,190.01]],"batb":[[0,3.75,31.4]],"ltp":3.75,"tv":430.79,"id":2397396},{"batb":[[0,1.33,28.43],[1,1.32,194.92],[2,1.31,276.05]],"ltp":1.36,"tv":3163.39,"id":8979329}],"tv":3594.19}]}
{"op":"mcm","clk":"1008912298","pt":1580640686881,"mc":[{"id":"1.168224328","rc":[{"batb":[[0,3.7,84.45],[1,3.65,11.53],[2,3.6,2.04]],"ltp":3.75,"tv":430.79,"id":2397396},{"batb":[[1,1.32,466.45],[2,1.31,2.08]],"ltp":1.36,"tv":3163.39,"id":8979329}]}]}
{"op":"mcm","clk":"1008912387","pt":1580640687666,"mc":[{"id":"1.168224328","rc":[{"batb":[[1,3.65,2.02],[2,3.6,11.74]],"ltp":3.75,"tv":430.79,"id":2397396}]}]}
{"op":"mcm","clk":"1008913795","pt":1580640699893,"mc":[{"id":"1.168224328","rc":[{"batl":[[0,1.37,521.8],[1,1.39,17.83],[2,1.4,2.02]],"ltp":1.36,"tv":3163.39,"id":8979329}]}]}
{"op":"mcm","clk":"1008914355","pt":1580640704402,"mc":[{"id":"1.168224328","rc":[{"trd":[[1.37,94]],"batb":[[0,1.35,7.57],[1,1.33,28.43],[2,1.32,466.45]],"batl":[[0,1.39,17.83],[1,1.4,2.02],[2,1.5,2.27]],"ltp":1.37,"tv":3257.4,"id":8979329}],"tv":3688.2}]}
{"op":"mcm","clk":"1008914387","pt":1580640704709,"mc":[{"id":"1.168224328","rc":[{"trd":[[1.36,301.14]],"batb":[[0,1.35,7.63]],"ltp":1.36,"tv":3272.54,"id":8979329}],"tv":3703.34}]}
{"op":"mcm","clk":"1008914704","pt":1580640707317,"mc":[{"id":"1.168224328","rc":[{"trd":[[1.36,316.28]],"batl":[[0,1.37,7.47],[1,1.39,17.83],[2,1.4,2.02]],"ltp":1.36,"tv":3287.68,"id":8979329}],"tv":3718.48}]}
{"op":"mcm","clk":"1008914862","pt":1580640708931,"mc":[{"id":"1.168224328","rc":[{"trd":[[1.36,331.43]],"ltp":1.36,"tv":3302.82,"id":8979329}],"tv":3733.62}]}
{"op":"mcm","clk":"1008915014","pt":1580640710233,"mc":[{"id":"1.168224328","rc":[{"batl":[[0,1.37,14.93]],"ltp":1.36,"tv":3302.82,"id":8979329}]}]}
{"op":"mcm","clk":"1008915110","pt":1580640710912,"mc":[{"id":"1.168224328","rc":[{"batl":[[0,1.37,14.99]],"ltp":1.36,"tv":3302.82,"id":8979329}]}]}
{"op":"mcm","clk":"1008915202","pt":1580640711904,"mc":[{"id":"1.168224328","rc":[{"batb":[[0,1.33,28.49],[1,1.32,466.45],[2,1.31,2.08]],"ltp":1.36,"tv":3302.82,"id":8979329}]}]}
{"op":"mcm","clk":"1008915355","pt":1580640713102,"mc":[{"id":"1.168224328","rc":[{"batb":[[0,1.32,466.5],[1,1.31,2.08],[2,1.3,86.03]],"ltp":1.36,"tv":3302.82,"id":8979329}]}]}
{"op":"mcm","clk":"1008915480","pt":1580640714233,"mc":[{"id":"1.168224328","marketDefinition":{"bspMarket":false,"turnInPlayEnabled":true,"persistenceEnabled":true,"marketBaseRate":5.0,"eventId":"29681722","eventTypeId":"2","numberOfWinners":1,"bettingType":"ODDS","marketType":"MATCH_ODDS","marketTime":"2020-02-02T10:48:00.000Z","suspendTime":"2020-02-02T10:48:00.000Z","bspReconciled":false,"complete":true,"inPlay":false,"crossMatching":true,"runnersVoidable":false,"numberOfActiveRunners":2,"betDelay":0,"status":"OPEN","runners":[{"status":"ACTIVE","sortPriority":1,"id":8979329,"name":"Emil Ruusuvuori"},{"status":"ACTIVE","sortPriority":2,"id":2397396,"name":"Matthias Bachinger"}],"regulators":["MR_INT"],"countryCode":"FR","discountAllowed":true,"timezone":"UTC","openDate":"2020-02-02T10:51:00.000Z","version":3148443641,"name":"Match Odds","eventName":"Emil Ruusuvuori v Bachinger"},"rc":[{"batb":[[2,1.3,2.01]],"ltp":1.36,"tv":3302.82,"id":8979329}]}]}
{"op":"mcm","clk":"1008915619","pt":1580640715334,"mc":[{"id":"1.168224328","rc":[{"batb":[[1,3,18.93],[2,2.92,216.74]],"batl":[[0,7.2,153.72],[1,95,15.9],[2,990,2.2]],"ltp":3.75,"tv":430.79,"id":2397396},{"batb":[[1,1.28,25.43],[2,1.22,588.28]],"batl":[[0,1.37,15.14],[1,1.39,15.74],[2,1.5,2.27]],"ltp":1.36,"tv":3302.82,"id":8979329}]}]}
{"op":"mcm","clk":"1008915671","pt":1580640715702,"mc":[{"id":"1.168224328","rc":[{"batb":[[1,3.6,9.7],[2,3,18.93]],"ltp":3.75,"tv":430.79,"id":2397396},{"batb":[[1,1.29,86.92],[2,1.28,25.43]],"ltp":1.36,"tv":3302.82,"id":8979329}]}]}
{"op":"mcm","clk":"1008915826","pt":1580640717144,"mc":[{"id":"1.168224328","marketDefinition":{"bspMarket":false,"turnInPlayEnabled":true,"persistenceEnabled":true,"marketBaseRate":5.0,"eventId":"29681722","eventTypeId":"2","numberOfWinners":1,"bettingType":"ODDS","marketType":"MATCH_ODDS","marketTime":"2020-02-02T10:48:00.000Z","suspendTime":"2020-02-02T10:48:00.000Z","bspReconciled":false,"complete":true,"inPlay":false,"crossMatching":true,"runnersVoidable":false,"numberOfActiveRunners":2,"betDelay":0,"status":"OPEN","runners":[{"status":"ACTIVE","sortPriority":1,"id":8979329,"name":"Emil Ruusuvuori"},{"status":"ACTIVE","sortPriority":2,"id":2397396,"name":"Matthias Bachinger"}],"regulators":["MR_INT"],"countryCode":"FR","discountAllowed":true,"timezone":"UTC","openDate":"2020-02-02T10:48:00.000Z","version":3148443641,"name":"Match Odds","eventName":"Emil Ruusuvuori v Bachinger"}}]}
{"op":"mcm","clk":"1008915902","pt":1580640717520,"mc":[{"id":"1.168224328","rc":[{"batl":[[0,1.37,22.72]],"ltp":1.36,"tv":3302.82,"id":8979329}]}]}
{"op":"mcm","clk":"1008916633","pt":1580640723957,"mc":[{"id":"1.168224328","rc":[{"trd":[[1.37,137.15]],"batb":[[0,1.36,7.63],[1,1.32,466.45],[2,1.29,86.92]],"batl":[[0,1.37,1.14]],"ltp":1.37,"tv":3345.97,"id":8979329}],"tv":3776.77}]}
{"op":"mcm","clk":"1008916789","pt":1580640725209,"mc":[{"id":"1.168224328","rc":[{"trd":[[1.36,388.34]],"batb":[[0,1.32,467.33],[1,1.29,86.92],[2,1.28,25.43]],"ltp":1.36,"tv":3402.88,"id":8979329}],"tv":3833.68}]}
{"op":"mcm","clk":"1008916856","pt":1580640725829,"mc":[{"id":"1.168224328","rc":[{"batl":[[0,1.37,8.66]],"ltp":1.36,"tv":3402.88,"id":8979329}]}]}
{"op":"mcm","clk":"1008917017","pt":1580640727250,"mc":[{"id":"1.168224328","rc":[{"trd":[[1.36,390.1]],"batb":[[0,1.32,466.45]],"batl":[[0,1.36,523.94],[1,1.37,8.72],[2,1.39,15.74]],"ltp":1.36,"tv":3404.64,"id":8979329}],"tv":3835.44}]}
{"op":"mcm","clk":"1008917143","pt":1580640728236,"mc":[{"id":"1.168224328","rc":[{"batb":[[1,3.65,9.51],[2,3.6,9.7]],"ltp":3.75,"tv":430.79,"id":2397396},{"batl":[[1,1.37,16.29]],"ltp":1.36,"tv":3404.64,"id":8979329}]}]}
{"op":"mcm","clk":"1008917365","pt":1580640730318,"mc":[{"id":"1.168224328","rc":[{"batl":[[1,1.37,7.57]],"ltp":1.36,"tv":3404.64,"id":8979329}]}]}
{"op":"mcm","clk":"1008917392","pt":1580640730523,"mc":[{"id":"1.168224328","rc":[{"batb":[[0,1.33,5.21],[1,1.32,466.45],[2,1.29,86.92]],"ltp":1.36,"tv":3404.64,"id":8979329}]}]}
{"op":"mcm","clk":"1008917881","pt":1580640735241,"mc":[{"id":"1.168224328","rc":[{"batl":[[0,1.35,74.21],[1,1.36,523.94],[2,1.37,7.57]],"ltp":1.36,"tv":3404.64,"id":8979329}]}]}
{"op":"mcm","clk":"1008917931","pt":1580640735717,"mc":[{"id":"1.168224328","rc":[{"batb":[[0,3.7,93.79]],"ltp":3.75,"tv":430.79,"id":2397396},{"batb":[[2,1.28,115.45]],"batl":[[1,1.37,7.57],[2,1.39,15.74]],"ltp":1.36,"tv":3404.64,"id":8979329}]}]}
{"op":"mcm","clk":"1008918321","pt":1580640739525,"mc":[{"id":"1.168224328","rc":[{"batl":[[0,1.35,116.22]],"ltp":1.36,"tv":3404.64,"id":8979329}]}]}
{"op":"mcm","clk":"1008918448","pt":1580640740821,"mc":[{"id":"1.168224328","rc":[{"batl":[[0,1.35,42.01],[1,1.36,74.21],[2,1.37,7.57]],"ltp":1.36,"tv":3404.64,"id":8979329}]}]}
{"op":"mcm","clk":"1008919024","pt":1580640746078,"mc":[{"id":"1.168224328","rc":[{"batb":[[0,1.32,466.45],[1,1.28,115.45],[2,1.22,588.28]],"batl":[[0,1.34,2],[1,1.35,42.01],[2,1.36,74.21]],"ltp":1.36,"tv":3404.64,"id":8979329}]}]}
{"op":"mcm","clk":"1008919141","pt":1580640747234,"mc":[{"id":"1.168224328","rc":[{"trd":[[3.75,199.59],[3.85,17.39],[3.9,53.53]],"ltp":3.75,"tv":455.79,"id":2397396},{"trd":[[1.34,323.43],[1.35,1032.48],[1.36,416.51]],"batb":[[0,1.35,5.13],[1,1.32,466.45],[2,1.28,115.45]],"batl":[[0,1.36,47.8],[1,1.39,15.74],[2,1.5,2.27]],"ltp":1.36,"tv":3475.06,"id":8979329}],"tv":3930.86}]}
{"op":"mcm","clk":"1008919208","pt":1580640747753,"mc":[{"id":"1.168224328","rc":[{"batb":[[0,3.7,84.45]],"ltp":3.75,"tv":455.79,"id":2397396},{"batb":[[2,1.29,86.92]],"ltp":1.36,"tv":3475.06,"id":8979329}]}]}
{"op":"mcm","clk":"1008919393","pt":1580640749259,"mc":[{"id":"1.168224328","rc":[{"batb":[[0,1.32,466.45],[1,1.29,86.92],[2,1.28,115.45]],"batl":[[0,1.36,571.62]],"ltp":1.36,"tv":3475.06,"id":8979329}]}]}
{"op":"mcm","clk":"1008919537","pt":1580640750470,"mc":[{"id":"1.168224328","rc":[{"batb":[[0,1.34,5.17],[1,1.32,466.45],[2,1.29,86.92]],"ltp":1.36,"tv":3475.06,"id":8979329}]}]}
{"op":"mcm","clk":"1008919964","pt":1580640754068,"mc":[{"id":"1.168224328","rc":[{"batb":[[0,1.33,26.5]],"ltp":1.36,"tv":3475.06,"id":8979329}]}]}
{"op":"mcm","clk":"1008920551","pt":1580640758961,"mc":[{"id":"1.168224328","rc":[{"batb":[[0,1.35,5.13],[1,1.33,26.5],[2,1.32,466.45]],"ltp":1.36,"tv":3475.06,"id":8979329}]}]}
{"op":"mcm","clk":"1008923622","pt":1580640783204,"mc":[{"id":"1.168224328","rc":[{"batb":[[0,1.33,26.5],[1,1.32,466.45],[2,1.29,86.92]],"ltp":1.36,"tv":3475.06,"id":8979329}]}]}
{"op":"mcm","clk":"1008923736","pt":1580640784001,"mc":[{"id":"1.168224328","rc":[{"trd":[[1.36,518.51]],"batl":[[0,1.36,520.62]],"ltp":1.36,"tv":3577.06,"id":8979329}],"tv":4032.86}]}
{"op":"mcm","clk":"1008923790","pt":1580640784409,"mc":[{"id":"1.168224328","rc":[{"batb":[[0,1.34,5.17],[1,1.33,26.5],[2,1.32,466.45]],"ltp":1.36,"tv":3577.06,"id":8979329}]}]}
{"op":"mcm","clk":"1008925260","pt":1580640796319,"mc":[{"id":"1.168224328","rc":[{"batb":[[1,1.33,74.21]],"ltp":1.36,"tv":3577.06,"id":8979329}]}]}
{"op":"mcm","clk":"1008925810","pt":1580640801306,"mc":[{"id":"1.168224328","rc":[{"batb":[[0,3.75,11.75],[1,3.7,84.45],[2,3.65,9.51]],"ltp":3.75,"tv":455.79,"id":2397396},{"trd":[[1.36,594.51]],"batb":[[0,1.33,74.21],[1,1.32,433.26],[2,1.29,86.92]],"batl":[[0,1.39,15.74],[1,1.5,2.27],[2,1.78,15.14]],"ltp":1.36,"tv":3653.06,"id":8979329}],"tv":4108.86}]}
{"op":"mcm","clk":"1008925905","pt":1580640802013,"mc":[{"id":"1.168224328","rc":[{"batb":[[0,1.35,5.13],[1,1.33,74.21],[2,1.32,433.26]],"batl":[[0,1.36,524.82],[1,1.39,15.74],[2,1.5,2.27]],"ltp":1.36,"tv":3653.06,"id":8979329}]}]}
{"op":"mcm","clk":"1008928129","pt":1580640821277,"mc":[{"id":"1.168224328","rc":[{"batb":[[1,1.33,76.21]],"ltp":1.36,"tv":3653.06,"id":8979329}]}]}
{"op":"mcm","clk":"1008928299","pt":1580640822379,"mc":[{"id":"1.168224328","rc":[{"trd":[[1.36,650.51]],"batl":[[0,1.39,15.74],[1,1.5,2.27],[2,1.78,15.14]],"ltp":1.36,"tv":3709.06,"id":8979329}],"tv":4164.86}]}
{"op":"mcm","clk":"1008928391","pt":1580640823065,"mc":[{"id":"1.168224328","rc":[{"batl":[[0,1.36,524.82],[1,1.39,15.74],[2,1.5,2.27]],"ltp":1.36,"tv":3709.06,"id":8979329}]}]}
{"op":"mcm","clk":"1008928788","pt":1580640826184,"mc":[{"id":"1.168224328","rc":[{"batb":[[0,1.33,76.21],[1,1.32,433.26],[2,1.29,86.92]],"ltp":1.36,"tv":3709.06,"id":8979329}]}]}
{"op":"mcm","clk":"1008928938","pt":1580640827385,"mc":[{"id":"1.168224328","rc":[{"batb":[[0,1.34,5.17],[1,1.33,76.21],[2,1.32,433.26]],"ltp":1.36,"tv":3709.06,"id":8979329}]}]}
{"op":"mcm","clk":"1008932426","pt":1580640858304,"mc":[{"id":"1.168224328","rc":[{"trd":[[1.34,323.46],[1.36,692.51]],"batb":[[0,1.34,5.16]],"batl":[[0,1.39,15.74],[1,1.5,2.27],[2,1.78,15.14]],"ltp":1.36,"tv":3751.09,"id":8979329}],"tv":4206.89}]}
{"op":"mcm","clk":"1008932482","pt":1580640858721,"mc":[{"id":"1.168224328","rc":[{"batl":[[0,1.36,545.82],[1,1.39,15.74],[2,1.5,2.27]],"ltp":1.36,"tv":3751.09,"id":8979329}]}]}
{"op":"mcm","clk":"1008933707","pt":1580640869204,"mc":[{"id":"1.168224328","rc":[{"trd":[[3.75,238.01]],"batb":[[0,3.7,84.45],[1,3.65,9.51],[2,3.6,9.7]],"ltp":3.75,"tv":494.22,"id":2397396},{"trd":[[1.36,733.65]],"batl":[[0,1.36,524.82]],"ltp":1.36,"tv":3792.23,"id":8979329}],"tv":4286.45}]}
{"op":"mcm","clk":"1008933737","pt":1580640869413,"mc":[{"id":"1.168224328","rc":[{"batb":[[0,3.75,11.75],[1,3.7,84.45],[2,3.65,9.51]],"ltp":3.75,"tv":494.22,"id":2397396}]}]}
{"op":"mcm","clk":"1008937867","pt":1580640909583,"mc":[{"id":"1.168224328","rc":[{"batb":[[0,1.33,76.21],[1,1.32,433.26],[2,1.29,86.92]],"ltp":1.36,"tv":3792.23,"id":8979329}]}]}
{"op":"mcm","clk":"1008937990","pt":1580640910836,"mc":[{"id":"1.168224328","rc":[{"trd":[[1.36,875.65]],"batb":[[0,1.35,5.12],[1,1.33,76.21],[2,1.32,433.26]],"batl":[[0,1.39,15.74],[1,1.5,2.27],[2,1.78,15.14]],"ltp":1.36,"tv":3934.23,"id":8979329}],"tv":4428.45}]}
{"op":"mcm","clk":"1008938062","pt":1580640911451,"mc":[{"id":"1.168224328","rc":[{"batl":[[0,1.36,524.82],[1,1.39,15.74],[2,1.5,2.27]],"ltp":1.36,"tv":3934.23,"id":8979329}]}]}
{"op":"mcm","clk":"1008938365","pt":1580640914053,"mc":[{"id":"1.168224328","rc":[{"batb":[[0,1.33,76.21],[1,1.32,433.26],[2,1.29,86.92]],"ltp":1.36,"tv":3934.23,"id":8979329}]}]}
{"op":"mcm","clk":"1008938500","pt":1580640915144,"mc":[{"id":"1.168224328","rc":[{"trd":[[1.36,885.81]],"batl":[[0,1.36,519.74]],"ltp":1.36,"tv":3944.39,"id":8979329}],"tv":4438.61}]}
{"op":"mcm","clk":"1008938656","pt":1580640916546,"mc":[{"id":"1.168224328","rc":[{"batb":[[0,1.33,76.22]],"ltp":1.36,"tv":3944.39,"id":8979329}]}]}
{"op":"mcm","clk":"1008940367","pt":1580640933281,"mc":[{"id":"1.168224328","rc":[{"batb":[[2,3.65,24.63]],"batl":[[0,4.3,12.6],[1,7.2,153.72],[2,95,15.9]],"ltp":3.75,"tv":494.22,"id":2397396},{"batb":[[2,1.3,139.47]],"batl":[[1,1.38,42.01],[2,1.39,15.74]],"ltp":1.36,"tv":3944.39,"id":8979329}]}]}
{"op":"mcm","clk":"1008940483","pt":1580640934279,"mc":[{"id":"1.168224328","rc":[{"trd":[[1.36,997.81]],"batl":[[0,1.36,463.74]],"ltp":1.36,"tv":4056.39,"id":8979329}],"tv":4550.61}]}
{"op":"mcm","clk":"1008940578","pt":1580640935156,"mc":[{"id":"1.168224328","rc":[{"batl":[[0,1.36,524.82]],"ltp":1.36,"tv":4056.39,"id":8979329}]}]}
{"op":"mcm","clk":"1008944519","pt":1580640972311,"mc":[{"id":"1.168224328","rc":[{"batb":[[0,1.33,118.79]],"ltp":1.36,"tv":4056.39,"id":8979329}]}]}
{"op":"mcm","clk":"1008946706","pt":1580640991336,"mc":[{"id":"1.168224328","rc":[{"trd":[[3.75,259.64]],"batb":[[0,3.7,85.38],[1,3.65,24.63],[2,3.6,9.7]],"ltp":3.75,"tv":515.84,"id":2397396},{"batl":[[0,1.38,42.01],[1,1.39,15.74],[2,1.5,2.27]],"ltp":1.36,"tv":4056.39,"id":8979329}],"tv":4572.23}]}
{"op":"mcm","clk":"1008946821","pt":1580640992333,"mc":[{"id":"1.168224328","rc":[{"batb":[[0,3.7,84.45]],"ltp":3.75,"tv":515.84,"id":2397396},{"batb":[[1,1.32,433.24],[2,1.3,223.49]],"ltp":1.36,"tv":4056.39,"id":8979329}]}]}
{"op":"mcm","clk":"1008946833","pt":1580640992435,"mc":[{"id":"1.168224328","rc":[{"batb":[[0,3.75,8.05],[1,3.7,84.45],[2,3.65,24.63]],"ltp":3.75,"tv":515.84,"id":2397396}]}]}
{"op":"mcm","clk":"1008947356","pt":1580640996860,"mc":[{"id":"1.168224328","rc":[{"batb":[[0,3.75,198.2]],"ltp":3.75,"tv":515.84,"id":2397396},{"batb":[[2,1.3,139.47]],"ltp":1.36,"tv":4056.39,"id":8979329}]}]}
{"op":"mcm","clk":"1008954605","pt":1580641055336,"mc":[{"id":"1.168224328","rc":[{"batb":[[0,3.75,8.05]],"ltp":3.75,"tv":515.84,"id":2397396},{"batl":[[0,1.36,589.18],[1,1.38,42.01],[2,1.39,15.74]],"ltp":1.36,"tv":4056.39,"id":8979329}]}]}
{"op":"mcm","clk":"1008954623","pt":1580641055433,"mc":[{"id":"1.168224328","rc":[{"trd":[[1.36,1065.81]],"batl":[[0,1.36,555.18]],"ltp":1.36,"tv":4124.39,"id":8979329}],"tv":4640.23}]}
{"op":"mcm","clk":"1008957604","pt":1580641080531,"mc":[{"id":"1.168224328","rc":[{"trd":[[1.36,1108.17]],"batl":[[0,1.36,534.01]],"ltp":1.36,"tv":4166.75,"id":8979329}],"tv":4682.59}]}
{"op":"mcm","clk":"1008957804","pt":1580641082347,"mc":[{"id":"1.168224328","rc":[{"trd":[[1.36,1190.16]],"batl":[[0,1.36,524.82]],"ltp":1.36,"tv":4248.74,"id":8979329}],"tv":4764.59}]}
{"op":"mcm","clk":"1008959959","pt":1580641100569,"mc":[{"id":"1.168224328","rc":[{"batb":[[1,1.32,854.15]],"ltp":1.36,"tv":4248.74,"id":8979329}]}]}
{"op":"mcm","clk":"1008960156","pt":1580641102271,"mc":[{"id":"1.168224328","rc":[{"trd":[[1.36,1252.16]],"ltp":1.36,"tv":4310.74,"id":8979329}],"tv":4826.59}]}
{"op":"mcm","clk":"1008962010","pt":1580641118462,"mc":[{"id":"1.168224328","rc":[{"batb":[[1,1.32,920.47]],"ltp":1.36,"tv":4310.74,"id":8979329}]}]}
{"op":"mcm","clk":"1008962234","pt":1580641120399,"mc":[{"id":"1.168224328","rc":[{"trd":[[1.36,1298.16]],"ltp":1.36,"tv":4356.74,"id":8979329}],"tv":4872.59}]}
{"op":"mcm","clk":"1008964748","pt":1580641141748,"mc":[{"id":"1.168224328","rc":[{"batb":[[1,1.32,499.56]],"ltp":1.36,"tv":4356.74,"id":8979329}]}]}
{"op":"mcm","clk":"1008964969","pt":1580641143012,"mc":[{"id":"1.168224328","rc":[{"trd":[[1.36,1332.16]],"batl":[[0,1.38,42.01],[1,1.39,15.74],[2,1.5,2.27]],"ltp":1.36,"tv":4390.74,"id":8979329}],"tv":4906.59}]}
{"op":"mcm","clk":"1008965089","pt":1580641143810,"mc":[{"id":"1.168224328","rc":[{"batb":[[2,1.3,223.49]],"batl":[[0,1.36,524.82],[1,1.38,42.01],[2,1.39,15.74]],"ltp":1.36,"tv":4390.74,"id":8979329}]}]}
{"op":"mcm","clk":"1008965220","pt":1580641144818,"mc":[{"id":"1.168224328","rc":[{"batb":[[2,1.3,139.47]],"ltp":1.36,"tv":4390.74,"id":8979329}]}]}
{"op":"mcm","clk":"1008967456","pt":1580641162131,"mc":[{"id":"1.168224328","rc":[{"batb":[[1,1.32,930.09]],"ltp":1.36,"tv":4390.74,"id":8979329}]}]}
{"op":"mcm","clk":"1008967567","pt":1580641162812,"mc":[{"id":"1.168224328","rc":[{"trd":[[1.36,1358.16]],"batl":[[0,1.38,42.01],[1,1.39,15.74],[2,1.5,2.27]],"ltp":1.36,"tv":4416.74,"id":8979329}],"tv":4932.59}]}
{"op":"mcm","clk":"1008967759","pt":1580641163810,"mc":[{"id":"1.168224328","rc":[{"batb":[[2,1.3,223.49]],"ltp":1.36,"tv":4416.74,"id":8979329}]}]}
{"op":"mcm","clk":"1008970578","pt":1580641185073,"mc":[{"id":"1.168224328","rc":[{"batb":[[1,3.7,29.37]],"ltp":3.75,"tv":515.84,"id":2397396},{"batb":[[1,1.32,658.56]],"ltp":1.36,"tv":4416.74,"id":8979329}]}]}
{"op":"mcm","clk":"1008970700","pt":1580641186080,"mc":[{"id":"1.168224328","marketDefinition":{"bspMarket":false,"turnInPlayEnabled":true,"persistenceEnabled":true,"marketBaseRate":5.0,"eventId":"29681722","eventTypeId":"2","numberOfWinners":1,"bettingType":"ODDS","marketType":"MATCH_ODDS","marketTime":"2020-02-02T10:48:00.000Z","suspendTime":"2020-02-02T10:48:00.000Z","bspReconciled":false,"complete":true,"inPlay":true,"crossMatching":true,"runnersVoidable":false,"numberOfActiveRunners":2,"betDelay":3,"status":"OPEN","runners":[{"status":"ACTIVE","sortPriority":1,"id":8979329,"name":"Emil Ruusuvuori"},{"status":"ACTIVE","sortPriority":2,"id":2397396,"name":"Matthias Bachinger"}],"regulators":["MR_INT"],"countryCode":"FR","discountAllowed":true,"timezone":"UTC","openDate":"2020-02-02T10:48:00.000Z","version":3148454322,"name":"Match Odds","eventName":"Emil Ruusuvuori v Bachinger"},"rc":[{"trd":[[3.75,265.64]],"batb":[[0,1.11,37.97],[1,1.03,9],[2,1.02,25.41]],"batl":[[0,1000,0.02],[1,7.2,0],[2,95,0]],"ltp":3.75,"tv":521.84,"id":2397396},{"batb":[[0,1.33,44.58],[1,1.32,496.85],[2,1.11,37.96]],"batl":[[0,1.5,2.27],[1,3,42.01],[2,10,2.53]],"ltp":1.36,"tv":4416.74,"id":8979329}],"tv":4938.59}]}
{"op":"mcm","clk":"1008971115","pt":1580641189365,"mc":[{"id":"1.168224328","rc":[{"batb":[[0,3.55,36.55],[1,1.8,75.72],[2,1.51,5.49]],"ltp":3.75,"tv":521.84,"id":2397396},{"batb":[[0,1.34,54.41],[1,1.33,44.56],[2,1.32,496.85]],"ltp":1.36,"tv":4416.74,"id":8979329}]}]}
{"op":"mcm","clk":"1008971309","pt":1580641191055,"mc":[{"id":"1.168224328","rc":[{"trd":[[3.8,319.06]],"ltp":3.8,"tv":840.9,"id":2397396},{"trd":[[1.35,1930.58]],"ltp":1.35,"tv":5314.84,"id":8979329}],"tv":6155.75}]}
{"op":"mcm","clk":"1008971485","pt":1580641192365,"mc":[{"id":"1.168224328","rc":[{"batb":[[1,3.5,63.97],[2,3.3,72.7]],"ltp":3.8,"tv":840.9,"id":2397396},{"batb":[[0,1.36,243.44],[1,1.34,54.41],[2,1.33,44.56]],"ltp":1.35,"tv":5314.84,"id":8979329}]}]}
{"op":"mcm","clk":"1008971541","pt":1580641192785,"mc":[{"id":"1.168224328","rc":[{"batb":[[2,3.45,16.8]],"batl":[[0,4,13.44],[1,1000,0.02]],"ltp":3.8,"tv":840.9,"id":2397396},{"batb":[[2,1.33,171.43]],"batl":[[0,1.41,42.01],[1,1.5,2.27],[2,3,42.01]],"ltp":1.35,"tv":5314.84,"id":8979329}]}]}
{"op":"mcm","clk":"1008972379","pt":1580641198544,"mc":[{"id":"1.168224328","rc":[{"batb":[[1,1.34,548.44]],"batl":[[1,1.43,480.59],[2,1.45,497.4]],"ltp":1.35,"tv":5314.84,"id":8979329}]}]}
{"op":"mcm","clk":"1008972907","pt":1580641201950,"mc":[{"id":"1.168224328","rc":[{"batb":[[1,3.45,16.8],[2,3.3,72.7]],"ltp":3.8,"tv":840.9,"id":2397396},{"batb":[[0,1.34,548.44],[1,1.33,171.43],[2,1.32,1007.69]],"ltp":1.35,"tv":5314.84,"id":8979329}]}]}
{"op":"mcm","clk":"1008973147","pt":1580641203379,"mc":[{"id":"1.168224328","rc":[{"batb":[[1,1.33,620.38],[2,1.32,1473.01]],"batl":[[0,1.36,317.52],[1,1.37,377.22],[2,1.41,42.01]],"ltp":1.35,"tv":5314.84,"id":8979329}]}]}
{"op":"mcm","clk":"1008973312","pt":1580641204264,"mc":[{"id":"1.168224328","rc":[{"batb":[[1,3.3,72.7],[2,2,75.72]],"batl":[[0,1000,0.02],[1,1000,0]],"ltp":3.8,"tv":840.9,"id":2397396},{"trd":[[1.34,361.25]],"batb":[[0,1.34,529.55],[1,1.33,44.56],[2,1.32,1007.69]],"batl":[[0,1.43,480.59],[1,1.45,497.4],[2,1.5,2.27]],"ltp":1.34,"tv":5352.64,"id":8979329}],"tv":6193.54}]}
{"op":"mcm","clk":"1008973484","pt":1580641204988,"mc":[{"id":"1.168224328","rc":[{"batb":[[0,1.34,494.03]],"batl":[[0,1.39,399.39],[1,1.4,340.82],[2,1.43,480.59]],"ltp":1.34,"tv":5352.64,"id":8979329}]}]}
{"op":"mcm","clk":"1008973646","pt":1580641205958,"mc":[{"id":"1.168224328","rc":[{"batl":[[0,1.5,2.27],[1,3,42.01],[2,10,2.53]],"ltp":1.34,"tv":5352.64,"id":8979329}]}]}
{"op":"mcm","clk":"1008974086","pt":1580641208379,"mc":[{"id":"1.168224328","rc":[{"trd":[[3.65,476.33]],"batl":[[0,3.65,1600.08],[1,3.95,4.01],[2,1000,0.02]],"ltp":3.65,"tv":1317.23,"id":2397396},{"trd":[[1.37,156.09]],"batb":[[0,1.36,1654.41],[1,1.34,509.15],[2,1.33,44.56]],"batl":[[0,1.39,1618.71],[1,1.5,2.27],[2,3,42.01]],"ltp":1.37,"tv":5371.58,"id":8979329}],"tv":6688.81}]}
{"op":"mcm","clk":"1008974280","pt":1580641209372,"mc":[{"id":"1.168224328","rc":[{"batb":[[2,3.2,79.78]],"batl":[[0,1000,0.02],[1,3.95,0],[2,1000,0]],"ltp":3.65,"tv":1317.23,"id":2397396},{"batb":[[0,1.38,221.17],[1,1.36,1898.12],[2,1.35,661.08]],"batl":[[0,1.39,2018.1],[1,1.4,340.82],[2,1.5,2.27]],"ltp":1.37,"tv":5371.58,"id":8979329}]}]}
{"op":"mcm","clk":"1008974489","pt":1580641210667,"mc":[{"id":"1.168224328","rc":[{"batb":[[2,3.25,18.48]],"batl":[[0,3.85,14.28],[1,1000,0.02]],"ltp":3.65,"tv":1317.23,"id":2397396},{"batb":[[2,1.35,780.39]],"batl":[[2,1.44,42.01]],"ltp":1.37,"tv":5371.58,"id":8979329}]}]}
{"op":"mcm","clk":"1008975188","pt":1580641215152,"mc":[{"id":"1.168224328","rc":[{"batb":[[1,1.36,2392.15]],"batl":[[2,1.42,480.59]],"ltp":1.37,"tv":5371.58,"id":8979329}]}]}
{"op":"mcm","clk":"1008975525","pt":1580641217186,"mc":[{"id":"1.168224328","rc":[{"batl":[[0,3.85,19.65]],"ltp":3.65,"tv":1317.23,"id":2397396},{"trd":[[1.38,31.3]],"batb":[[0,1.38,205.52]],"ltp":1.38,"tv":5402.88,"id":8979329}],"tv":6720.11}]}
{"op":"mcm","clk":"1008975684","pt":1580641218208,"mc":[{"id":"1.168224328","rc":[{"batl":[[0,3.85,14.28]],"ltp":3.65,"tv":1317.23,"id":2397396},{"batb":[[1,1.36,494.03],[2,1.35,367.55]],"batl":[[0,1.42,480.59],[1,1.44,539.41],[2,1.5,2.27]],"ltp":1.38,"tv":5402.88,"id":8979329}]}]}
{"op":"mcm","clk":"1008975840","pt":1580641219165,"mc":[{"id":"1.168224328","rc":[{"batb":[[0,3.25,18.48],[1,3.2,79.55],[2,2,75.72]],"ltp":3.65,"tv":1317.23,"id":2397396},{"batb":[[0,1.36,494.03],[1,1.35,367.55],[2,1.34,510.84]],"ltp":1.38,"tv":5402.88,"id":8979329}]}]}
{"op":"mcm","clk":"1008975903","pt":1580641219667,"mc":[{"id":"1.168224328","rc":[{"batb":[[0,3.2,79.55],[1,2,75.72],[2,1.8,75.72]],"batl":[[0,1000,0.02],[1,1000,0]],"ltp":3.65,"tv":1317.23,"id":2397396},{"batb":[[1,1.35,248.24]],"batl":[[1,1.44,497.4]],"ltp":1.38,"tv":5402.88,"id":8979329}]}]}
{"op":"mcm","clk":"1008976673","pt":1580641224080,"mc":[{"id":"1.168224328","rc":[{"batb":[[1,1.35,665.98],[2,1.34,941.51]],"batl":[[0,1.38,270.16],[1,1.39,353.49],[2,1.42,480.59]],"ltp":1.38,"tv":5402.88,"id":8979329}]}]}
{"op":"mcm","clk":"1008977021","pt":1580641226307,"mc":[{"id":"1.168224328","rc":[{"batb":[[1,1.35,248.24],[2,1.34,510.84]],"batl":[[0,1.42,480.59],[1,1.44,497.4],[2,1.5,2.27]],"ltp":1.38,"tv":5402.88,"id":8979329}]}]}
{"op":"mcm","clk":"1008977464","pt":1580641229184,"mc":[{"id":"1.168224328","rc":[{"batl":[[0,1.41,327.43],[1,1.42,801.56],[2,1.44,497.4]],"ltp":1.38,"tv":5402.88,"id":8979329}]}]}
{"op":"mcm","clk":"1008978010","pt":1580641232897,"mc":[{"id":"1.168224328","rc":[{"batb":[[0,1.35,248.24],[1,1.33,351.49],[2,1.32,959.99]],"batl":[[0,1.42,480.59],[1,1.44,497.4],[2,1.5,2.27]],"ltp":1.38,"tv":5402.88,"id":8979329}]}]}
{"op":"mcm","clk":"1008978365","pt":1580641235397,"mc":[{"id":"1.168224328","rc":[{"batb":[[0,4,3.68],[1,3.2,79.55],[2,2,75.72]],"ltp":3.65,"tv":1317.23,"id":2397396},{"trd":[[1.35,2427.05]],"batb":[[0,1.33,2043.22],[1,1.32,973.04],[2,1.29,906.89]],"batl":[[0,1.34,676.65],[1,1.36,1654.41],[2,1.37,4998]],"ltp":1.35,"tv":5899.35,"id":8979329}],"tv":7216.59}]}
{"op":"mcm","clk":"1008978513","pt":1580641236299,"mc":[{"id":"1.168224328","rc":[{"batb":[[1,3.55,62.08],[2,3.35,70.34]],"ltp":3.65,"tv":1317.23,"id":2397396},{"batb":[[2,1.3,295.21]],"batl":[[1,1.36,2105.06],[2,1.37,375.47]],"ltp":1.35,"tv":5899.35,"id":8979329}]}]}
{"op":"mcm","clk":"1008978565","pt":1580641236674,"mc":[{"id":"1.168224328","rc":[{"batb":[[2,3.45,16.8]],"batl":[[0,4.1,13.44],[1,1000,0.02]],"ltp":3.65,"tv":1317.23,"id":2397396},{"batb":[[1,1.32,1104.11]],"ltp":1.35,"tv":5899.35,"id":8979329}]}]}
{"op":"mcm","clk":"1008978860","pt":1580641238691,"mc":[{"id":"1.168224328","rc":[{"trd":[[1.34,381.73]],"batl":[[0,1.34,666.41]],"ltp":1.34,"tv":5919.83,"id":8979329}],"tv":7237.07}]}
{"op":"mcm","clk":"1008979422","pt":1580641241983,"mc":[{"id":"1.168224328","rc":[{"batb":[[2,1.31,494.03]],"batl":[[2,1.37,856.06]],"ltp":1.34,"tv":5919.83,"id":8979329}]}]}
{"op":"mcm","clk":"1008980812","pt":1580641250120,"mc":[{"id":"1.168224328","rc":[{"batb":[[0,3.45,16.8],[1,3.35,70.34],[2,2.2,75.72]],"ltp":3.65,"tv":1317.23,"id":2397396},{"batb":[[0,1.33,44.56],[1,1.32,627.92]],"batl":[[0,1.37,480.59],[1,1.39,497.4],[2,1.4,42.01]],"ltp":1.34,"tv":5919.83,"id":8979329}]}]}
{"op":"mcm","clk":"1008981174","pt":1580641251748,"mc":[{"id":"1.168224328","rc":[{"batb":[[0,3.35,70.34],[1,2.2,75.72],[2,2,75.72]],"batl":[[0,1000,0.02],[1,1000,0]],"ltp":3.65,"tv":1317.23,"id":2397396},{"batb":[[0,1.34,16.82],[1,1.33,44.56],[2,1.32,496.85]],"batl":[[2,1.5,2.27]],"ltp":1.34,"tv":5919.83,"id":8979329}]}]}
{"op":"mcm","clk":"1008981440","pt":1580641253317,"mc":[{"id":"1.168224328","rc":[{"batb":[[0,3.5,67.12]],"ltp":3.65,"tv":1317.23,"id":2397396}]}]}
{"op":"mcm","clk":"1008981994","pt":1580641256748,"mc":[{"id":"1.168224328","rc":[{"batb":[[2,1.32,897.67]],"batl":[[0,1.35,404.64],[1,1.36,389.23],[2,1.37,480.59]],"ltp":1.34,"tv":5919.83,"id":8979329}]}]}
{"op":"mcm","clk":"1008982326","pt":1580641258945,"mc":[{"id":"1.168224328","rc":[{"trd":[[1.35,2447.23]],"batb":[[2,1.32,496.85]],"batl":[[0,1.37,480.59],[1,1.39,497.4],[2,1.5,2.27]],"ltp":1.35,"tv":5940.01,"id":8979329}],"tv":7257.25}]}
{"op":"mcm","clk":"1008982828","pt":1580641261937,"mc":[{"id":"1.168224328","rc":[{"batb":[[1,1.33,118.77]],"ltp":1.35,"tv":5940.01,"id":8979329}]}]}
{"op":"mcm","clk":"1008983033","pt":1580641263169,"mc":[{"id":"1.168224328","rc":[{"batl":[[0,1.39,381.38],[1,1.4,340.96]],"ltp":1.35,"tv":5940.01,"id":8979329}]}]}
{"op":"mcm","clk":"1008983300","pt":1580641265251,"mc":[{"id":"1.168224328","rc":[{"batl":[[0,3.85,4.67],[1,4.1,309.26],[2,1000,0.02]],"ltp":3.65,"tv":1317.23,"id":2397396},{"trd":[[1.36,1359.06]],"batb":[[0,1.36,1916.54],[1,1.35,413.02],[2,1.34,16.82]],"batl":[[0,1.37,17.16],[1,1.38,1007.18],[2,1.39,2000.09]],"ltp":1.36,"tv":5940.9,"id":8979329}],"tv":7258.14}]}
{"op":"mcm","clk":"1008983482","pt":1580641266364,"mc":[{"id":"1.168224328","rc":[{"batb":[[1,3.35,74.51],[2,2.2,75.72]],"ltp":3.65,"tv":1317.23,"id":2397396},{"batb":[[0,1.36,2151.56]],"ltp":1.36,"tv":5940.9,"id":8979329}]}]}
{"op":"mcm","clk":"1008983524","pt":1580641266684,"mc":[{"id":"1.168224328","rc":[{"batb":[[2,3.3,17.64]],"batl":[[0,3.85,18.95]],"ltp":3.65,"tv":1317.23,"id":2397396},{"batb":[[1,1.35,532.33]],"ltp":1.36,"tv":5940.9,"id":8979329}]}]}
{"op":"mcm","clk":"1008984149","pt":1580641271679,"mc":[{"id":"1.168224328","rc":[{"batb":[[2,1.34,510.85]],"ltp":1.36,"tv":5940.9,"id":8979329}]}]}
{"op":"mcm","clk":"1008984668","pt":1580641275391,"mc":[{"id":"1.168224328","rc":[{"batb":[[0,3.35,74.51],[1,3.3,17.64],[2,2.2,75.72]],"batl":[[0,3.85,14.28],[1,1000,0.02],[2,1000,0]],"ltp":3.65,"tv":1317.23,"id":2397396},{"batb":[[0,1.37,26.52],[1,1.35,119.31]],"batl":[[0,1.4,480.59],[1,1.42,497.4],[2,1.44,42.01]],"ltp":1.36,"tv":5940.9,"id":8979329}]}]}
{"op":"mcm","clk":"1008984739","pt":1580641275865,"mc":[{"id":"1.168224328","rc":[{"batb":[[1,2.2,75.72],[2,2,75.72]],"batl":[[0,1000,0.02],[1,1000,0]],"ltp":3.65,"tv":1317.23,"id":2397396},{"batb":[[1,1.34,510.85],[2,1.33,306.65]],"batl":[[2,1.5,2.27]],"ltp":1.36,"tv":5940.9,"id":8979329}]}]}
{"op":"mcm","clk":"1008985025","pt":1580641278079,"mc":[{"id":"1.168224328","rc":[{"batb":[[2,1.33,678.09]],"batl":[[1,1.41,342.36],[2,1.42,818.19]],"ltp":1.36,"tv":5940.9,"id":8979329}]}]}
{"op":"mcm","clk":"1008985127","pt":1580641278967,"mc":[{"id":"1.168224328","rc":[{"batb":[[1,1.34,585.06]],"ltp":1.36,"tv":5940.9,"id":8979329}]}]}
{"op":"mcm","clk":"1008986929","pt":1580641292329,"mc":[{"id":"1.168224328","rc":[{"batb":[[1,1.34,91.03]],"batl":[[1,1.42,497.4],[2,1.5,2.27]],"ltp":1.36,"tv":5940.9,"id":8979329}]}]}
{"op":"mcm","clk":"1008987035","pt":1580641293125,"mc":[{"id":"1.168224328","rc":[{"batb":[[0,1.34,91.03],[1,1.33,678.09],[2,1.32,960.94]],"ltp":1.36,"tv":5940.9,"id":8979329}]}]}
{"op":"mcm","clk":"1008987379","pt":1580641295329,"mc":[{"id":"1.168224328","rc":[{"trd":[[3.95,90.41]],"batb":[[0,4,238.67],[1,3.35,74.51],[2,2.2,75.72]],"batl":[[0,4.2,3.59],[1,4.5,275.39],[2,1000,0.02]],"ltp":3.95,"tv":1341.14,"id":2397396},{"trd":[[1.34,493.3]],"batb":[[0,1.33,2369.82],[1,1.32,960.94],[2,1.15,378.72]],"batl":[[0,1.36,2046.65],[1,1.37,376.23],[2,1.4,480.59]],"ltp":1.34,"tv":6052.47,"id":8979329}],"tv":7393.62}]}
{"op":"mcm","clk":"1008987477","pt":1580641295916,"mc":[{"id":"1.168224328","rc":[{"batb":[[1,3.7,57.83],[2,3.45,67.67]],"ltp":3.95,"tv":1341.14,"id":2397396},{"batb":[[2,1.28,315.83]],"ltp":1.34,"tv":6052.47,"id":8979329}]}]}
{"op":"mcm","clk":"1008987591","pt":1580641296717,"mc":[{"id":"1.168224328","rc":[{"batb":[[2,3.45,84.47]],"batl":[[0,4.1,13.44],[1,4.2,3.59],[2,4.5,275.39]],"ltp":3.95,"tv":1341.14,"id":2397396},{"batb":[[1,1.32,1092.01]],"batl":[[2,1.4,522.6]],"ltp":1.34,"tv":6052.47,"id":8979329}]}]}
{"op":"mcm","clk":"1008988311","pt":1580641301402,"mc":[{"id":"1.168224328","rc":[{"batb":[[2,3.6,2.24]],"ltp":3.95,"tv":1341.14,"id":2397396},{"batb":[[2,1.31,494.03]],"batl":[[1,1.37,856.82],[2,1.38,44.25]],"ltp":1.34,"tv":6052.47,"id":8979329}]}]}
{"op":"mcm","clk":"1008988368","pt":1580641301813,"mc":[{"id":"1.168224328","rc":[{"batb":[[2,3.45,84.47]],"ltp":3.95,"tv":1341.14,"id":2397396}]}]}
{"op":"mcm","clk":"1008988859","pt":1580641305310,"mc":[{"id":"1.168224328","rc":[{"batl":[[1,4.5,275.39],[2,4.6,2.01]],"ltp":3.95,"tv":1341.14,"id":2397396}]}]}
{"op":"mcm","clk":"1008989197","pt":1580641307728,"mc":[{"id":"1.168224328","rc":[{"batl":[[0,4.1,17.76]],"ltp":3.95,"tv":1341.14,"id":2397396},{"batl":[[0,1.34,16.81],[1,1.36,2046.65],[2,1.37,856.82]],"ltp":1.34,"tv":6052.47,"id":8979329}]}]}
{"op":"mcm","clk":"1008989485","pt":1580641309804,"mc":[{"id":"1.168224328","rc":[{"batb":[[0,3.45,84.47],[1,2.2,75.72],[2,2,75.72]],"batl":[[0,4.1,13.44],[1,4.6,2.01],[2,1000,0.02]],"ltp":3.95,"tv":1341.14,"id":2397396},{"batb":[[0,1.33,44.56],[1,1.32,627.92]],"batl":[[0,1.37,480.59],[1,1.38,44.25],[2,1.39,497.4]],"ltp":1.34,"tv":6052.47,"id":8979329}]}]}
{"op":"mcm","clk":"1008989773","pt":1580641312027,"mc":[{"id":"1.168224328","rc":[{"batb":[[0,3.6,2.04],[1,3.5,2.64],[2,3.45,67.67]],"batl":[[0,4.6,2.01],[1,1000,0.02],[2,1000,0]],"ltp":3.95,"tv":1341.14,"id":2397396},{"batb":[[1,1.32,496.85]],"ltp":1.34,"tv":6052.47,"id":8979329}]}]}
{"op":"mcm","clk":"1008990067","pt":1580641314190,"mc":[{"id":"1.168224328","rc":[{"batb":[[0,3.5,2.64],[1,3.45,67.67],[2,2.2,75.72]],"ltp":3.95,"tv":1341.14,"id":2397396},{"batl":[[0,1.4,567.44],[1,1.41,328.93],[2,1.5,2.27]],"ltp":1.34,"tv":6052.47,"id":8979329}]}]}
{"op":"mcm","clk":"1008990353","pt":1580641316322,"mc":[{"id":"1.168224328","rc":[{"batl":[[0,3.85,1781.69],[1,4.1,3.92],[2,4.6,2.01]],"ltp":3.95,"tv":1341.14,"id":2397396},{"trd":[[1.37,1806.21]],"batb":[[0,1.37,817.28],[1,1.33,44.56],[2,1.32,1293.52]],"batl":[[0,1.38,22.92],[1,1.4,2174.58],[2,1.41,328.93]],"ltp":1.37,"tv":7702.59,"id":8979329}],"tv":9043.74}]}
{"op":"mcm","clk":"1008990382","pt":1580641316530,"mc":[{"id":"1.168224328","rc":[{"batl":[[0,3.85,7.69],[1,4.6,2.01],[2,1000,0.02]],"ltp":3.95,"tv":1341.14,"id":2397396},{"batb":[[1,1.36,476.99],[2,1.35,415.89]],"ltp":1.37,"tv":7702.59,"id":8979329}]}]}
{"op":"mcm","clk":"1008990573","pt":1580641317717,"mc":[{"id":"1.168224328","rc":[{"batb":[[2,3.15,86.31]],"ltp":3.95,"tv":1341.14,"id":2397396},{"batb":[[1,1.36,710.44]],"ltp":1.37,"tv":7702.59,"id":8979329}]}]}
{"op":"mcm","clk":"1008990739","pt":1580641318718,"mc":[{"id":"1.168224328","rc":[{"batb":[[2,3.2,18.48]],"batl":[[0,3.75,15.12],[1,3.85,7.69],[2,4.6,2.01]],"ltp":3.95,"tv":1341.14,"id":2397396},{"batb":[[1,1.36,826.39]],"ltp":1.37,"tv":7702.59,"id":8979329}]}]}
{"op":"mcm","clk":"1008991058","pt":1580641321021,"mc":[{"id":"1.168224328","rc":[{"trd":[[1.38,33.42]],"batb":[[1,1.36,349.4],[2,1.33,300.67]],"batl":[[0,1.38,21.86],[1,1.4,1653.23],[2,1.45,42.01]],"ltp":1.38,"tv":7704.71,"id":8979329}],"tv":9045.86}]}
{"op":"mcm","clk":"1008991745","pt":1580641326240,"mc":[{"id":"1.168224328","rc":[{"trd":[[1.38,33.46]],"batl":[[0,1.38,21.84]],"ltp":1.38,"tv":7704.75,"id":8979329}],"tv":9045.89}]}
{"op":"mcm","clk":"1008991811","pt":1580641326726,"mc":[{"id":"1.168224328","rc":[{"trd":[[1.38,45.65]],"batl":[[0,1.38,15.74]],"ltp":1.38,"tv":7716.94,"id":8979329}],"tv":9058.09}]}
{"op":"mcm","clk":"1008992013","pt":1580641328119,"mc":[{"id":"1.168224328","rc":[{"trd":[[1.37,1806.22]],"batb":[[0,1.37,817.27]],"ltp":1.37,"tv":7716.96,"id":8979329}],"tv":9058.11}]}
{"op":"mcm","clk":"1008992185","pt":1580641329462,"mc":[{"id":"1.168224328","rc":[{"batb":[[1,1.36,826.39],[2,1.35,415.89]],"batl":[[1,1.4,2174.58],[2,1.41,328.93]],"ltp":1.37,"tv":7716.96,"id":8979329}]}]}
{"op":"mcm","clk":"1008992441","pt":1580641331370,"mc":[{"id":"1.168224328","rc":[{"batl":[[1,4.6,2.01],[2,1000,0.02]],"ltp":3.95,"tv":1341.14,"id":2397396},{"trd":[[1.37,1881.95]],"batb":[[0,1.37,779.41]],"batl":[[0,1.4,2174.58],[1,1.41,328.93],[2,1.45,42.01]],"ltp":1.37,"tv":7792.68,"id":8979329}],"tv":9133.83}]}
{"op":"mcm","clk":"1008992750","pt":1580641333572,"mc":[{"id":"1.168224328","rc":[{"batb":[[1,1.36,840.77]],"batl":[[0,1.38,15.74],[1,1.4,2174.58],[2,1.41,328.93]],"ltp":1.37,"tv":7792.68,"id":8979329}]}]}
{"op":"mcm","clk":"1008993134","pt":1580641336484,"mc":[{"id":"1.168224328","rc":[{"batb":[[1,1.36,826.39]],"batl":[[0,1.4,2174.58],[1,1.41,328.93],[2,1.45,42.01]],"ltp":1.37,"tv":7792.68,"id":8979329}]}]}
{"op":"mcm","clk":"1008993510","pt":1580641339353,"mc":[{"id":"1.168224328","rc":[{"batb":[[1,1.36,840.77]],"batl":[[0,1.38,15.74],[1,1.4,2174.58],[2,1.41,328.93]],"ltp":1.37,"tv":7792.68,"id":8979329}]}]}
{"op":"mcm","clk":"1008993537","pt":1580641339565,"mc":[{"id":"1.168224328","rc":[{"batb":[[1,1.36,826.39]],"batl":[[0,1.4,2174.58],[1,1.41,328.93],[2,1.45,42.01]],"ltp":1.37,"tv":7792.68,"id":8979329}]}]}
{"op":"mcm","clk":"1008993929","pt":1580641342601,"mc":[{"id":"1.168224328","rc":[{"batb":[[1,1.36,840.77]],"batl":[[0,1.38,15.74],[1,1.4,2174.58],[2,1.41,328.93]],"ltp":1.37,"tv":7792.68,"id":8979329}]}]}
{"op":"mcm","clk":"1008994165","pt":1580641344254,"mc":[{"id":"1.168224328","rc":[{"trd":[[3.75,282.52]],"batl":[[0,3.75,6.68]],"ltp":3.75,"tv":1358.03,"id":2397396}],"tv":9150.72}]}
{"op":"mcm","clk":"1008994234","pt":1580641344687,"mc":[{"id":"1.168224328","rc":[{"batb":[[2,3.15,86.31]],"ltp":3.75,"tv":1358.03,"id":2397396}]}]}
{"op":"mcm","clk":"1008994690","pt":1580641347564,"mc":[{"id":"1.168224328","rc":[{"batb":[[2,3.3,17.64]],"batl":[[0,3.75,15.08]],"ltp":3.75,"tv":1358.03,"id":2397396}]}]}
{"op":"mcm","clk":"1008994931","pt":1580641349472,"mc":[{"id":"1.168224328","rc":[{"trd":[[1.38,77.13],[1.4,29.1]],"batl":[[0,1.4,2160.03],[1,1.41,328.93],[2,1.44,42.01]],"ltp":1.4,"tv":7853.26,"id":8979329}],"tv":9211.29}]}
{"op":"mcm","clk":"1008995471","pt":1580641353378,"mc":[{"id":"1.168224328","rc":[{"batb":[[0,3.3,17.64],[1,3.15,86.31],[2,2.2,75.72]],"ltp":3.75,"tv":1358.03,"id":2397396},{"batb":[[0,1.36,115.95],[1,1.33,300.67],[2,1.32,496.85]],"batl":[[0,1.44,42.01],[1,1.5,2.27],[2,3,42.01]],"ltp":1.4,"tv":7853.26,"id":8979329}]}]}
{"op":"mcm","clk":"1008995545","pt":1580641353856,"mc":[{"id":"1.168224328","rc":[{"batb":[[0,3.15,86.31],[1,2.2,75.72],[2,2,75.72]],"batl":[[0,4.6,2.01],[1,1000,0.02],[2,1000,0]],"ltp":3.75,"tv":1358.03,"id":2397396},{"batb":[[0,1.33,300.67],[1,1.32,496.85],[2,1.28,59.66]],"batl":[[0,1.5,2.27],[1,3,42.01],[2,10,2.53]],"ltp":1.4,"tv":7853.26,"id":8979329}]}]}
{"op":"mcm","clk":"1008995881","pt":1580641356387,"mc":[{"id":"1.168224328","rc":[{"batb":[[2,2.16,5.03]],"batl":[[0,3.95,2.1],[1,4.2,2.03],[2,4.6,2.01]],"ltp":3.75,"tv":1358.03,"id":2397396},{"batb":[[0,1.34,49.22],[1,1.33,938.48],[2,1.32,1015.08]],"batl":[[0,1.45,227.33],[1,1.46,286.32],[2,1.5,2.27]],"ltp":1.4,"tv":7853.26,"id":8979329}]}]}
{"op":"mcm","clk":"1008995911","pt":1580641356605,"mc":[{"id":"1.168224328","rc":[{"batl":[[0,4.2,2.03],[1,1000,0.02],[2,4.6,0]],"ltp":3.75,"tv":1358.03,"id":2397396},{"batb":[[0,1.33,300.67],[1,1.32,546.99],[2,1.15,378.72]],"batl":[[0,1.5,2.27],[1,1.86,20.75],[2,2.02,5.25]],"ltp":1.4,"tv":7853.26,"id":8979329}]}]}
{"op":"mcm","clk":"1008996196","pt":1580641358783,"mc":[{"id":"1.168224328","rc":[{"batb":[[0,1.37,488.36],[1,1.36,401.39],[2,1.33,300.67]],"batl":[[0,1.41,467.74],[1,1.42,319.55],[2,1.5,2.27]],"ltp":1.4,"tv":7853.26,"id":8979329}]}]}
{"op":"mcm","clk":"1008996336","pt":1580641359859,"mc":[{"id":"1.168224328","rc":[{"batb":[[1,2.16,5.03],[2,2,75.72]],"batl":[[0,3.95,2.1],[1,4.2,2.03],[2,1000,0.02]],"ltp":3.75,"tv":1358.03,"id":2397396},{"batb":[[2,1.34,55.72]],"ltp":1.4,"tv":7853.26,"id":8979329}]}]}
{"op":"mcm","clk":"1008997144","pt":1580641365907,"mc":[{"id":"1.168224328","rc":[{"batl":[[0,4.2,2.03],[1,1000,0.02],[2,1000,0]],"ltp":3.75,"tv":1358.03,"id":2397396},{"batb":[[0,1.33,300.67],[1,1.32,546.99],[2,1.15,378.72]],"batl":[[0,1.5,2.27],[1,1.86,20.75],[2,2.02,5.25]],"ltp":1.4,"tv":7853.26,"id":8979329}]}]}
{"op":"mcm","clk":"1008997625","pt":1580641369328,"mc":[{"id":"1.168224328","rc":[{"batb":[[0,1.33,938.48],[1,1.32,1015.08]],"batl":[[0,1.45,227.33],[1,1.46,286.32],[2,1.5,2.27]],"ltp":1.4,"tv":7853.26,"id":8979329}]}]}
{"op":"mcm","clk":"1008998917","pt":1580641379398,"mc":[{"id":"1.168224328","rc":[{"batl":[[0,3.95,2.1],[1,4.2,2.03],[2,1000,0.02]],"ltp":3.75,"tv":1358.03,"id":2397396},{"batb":[[0,1.34,46.22],[1,1.33,938.48],[2,1.32,1015.08]],"ltp":1.4,"tv":7853.26,"id":8979329}]}]}
{"op":"mcm","clk":"1008998968","pt":1580641379719,"mc":[{"id":"1.168224328","rc":[{"batl":[[0,4.2,2.03],[1,1000,0.02],[2,1000,0]],"ltp":3.75,"tv":1358.03,"id":2397396},{"batb":[[0,1.33,938.48],[1,1.32,1015.08],[2,1.15,378.72]],"ltp":1.4,"tv":7853.26,"id":8979329}]}]}
{"op":"mcm","clk":"1008999873","pt":1580641386227,"mc":[{"id":"1.168224328","rc":[{"batl":[[0,3.95,2.1],[1,4.2,2.03],[2,1000,0.02]],"ltp":3.75,"tv":1358.03,"id":2397396},{"batb":[[0,1.34,50.72],[1,1.33,938.48],[2,1.32,1015.08]],"ltp":1.4,"tv":7853.26,"id":8979329}]}]}
{"op":"mcm","clk":"1008999902","pt":1580641386437,"mc":[{"id":"1.168224328","rc":[{"batl":[[0,4.2,2.03],[1,1000,0.02],[2,1000,0]],"ltp":3.75,"tv":1358.03,"id":2397396},{"batb":[[0,1.33,938.48],[1,1.32,1015.08],[2,1.15,378.72]],"ltp":1.4,"tv":7853.26,"id":8979329}]}]}
{"op":"mcm","clk":"1009000401","pt":1580641390028,"mc":[{"id":"1.168224328","rc":[{"batb":[[0,1.33,300.67],[1,1.32,546.99]],"ltp":1.4,"tv":7853.26,"id":8979329}]}]}
{"op":"mcm","clk":"1009000813","pt":1580641393023,"mc":[{"id":"1.168224328","rc":[{"batl":[[0,3.45,2],[1,3.55,362.88],[2,4.2,2.03]],"ltp":3.75,"tv":1358.03,"id":2397396},{"batb":[[0,1.44,12.87],[1,1.42,501.03],[2,1.41,346.34]],"batl":[[1,1.46,963.71]],"ltp":1.4,"tv":7853.26,"id":8979329}]}]}
{"op":"mcm","clk":"1009000971","pt":1580641394246,"mc":[{"id":"1.168224328","rc":[{"batb":[[1,2.82,46.66],[2,2.16,5.03]],"ltp":3.75,"tv":1358.03,"id":2397396},{"batb":[[2,1.41,540.53]],"ltp":1.4,"tv":7853.26,"id":8979329}]}]}
{"op":"mcm","clk":"1009001047","pt":1580641394789,"mc":[{"id":"1.168224328","rc":[{"batb":[[1,3,21],[2,2.82,46.66]],"batl":[[0,3.45,18.8]],"ltp":3.75,"tv":1358.03,"id":2397396},{"batl":[[2,1.49,42.01]],"ltp":1.4,"tv":7853.26,"id":8979329}]}]}
{"op":"mcm","clk":"1009001738","pt":1580641399385,"mc":[{"id":"1.168224328","rc":[{"batb":[[2,1.41,1034.56]],"batl":[[2,1.47,480.59]],"ltp":1.4,"tv":7853.26,"id":8979329}]}]}
{"op":"mcm","clk":"1009001772","pt":1580641399598,"mc":[{"id":"1.168224328","rc":[{"batl":[[2,3.75,2.42]],"ltp":3.75,"tv":1358.03,"id":2397396}]}]}
{"op":"mcm","clk":"1009001948","pt":1580641400988,"mc":[{"id":"1.168224328","rc":[{"batb":[[1,1.42,255.93]],"ltp":1.4,"tv":7853.26,"id":8979329}]}]}
{"op":"mcm","clk":"1009002301","pt":1580641404004,"mc":[{"id":"1.168224328","rc":[{"batb":[[2,1.41,1202.87]],"batl":[[0,1.45,303.9]],"ltp":1.4,"tv":7853.26,"id":8979329}]}]}
{"op":"mcm","clk":"1009002766","pt":1580641406316,"mc":[{"id":"1.168224328","rc":[{"batb":[[0,3,21],[1,2.82,46.66],[2,2,75.72]],"batl":[[0,3.45,16.8],[1,3.75,2.42],[2,3.95,2.3]],"ltp":3.75,"tv":1358.03,"id":2397396},{"batb":[[0,1.41,494.03],[1,1.4,105.02],[2,1.39,510.84]],"batl":[[0,1.47,480.59],[1,1.49,539.41],[2,1.5,2.27]],"ltp":1.4,"tv":7853.26,"id":8979329}]}]}
{"op":"mcm","clk":"1009002983","pt":1580641407840,"mc":[{"id":"1.168224328","rc":[{"batb":[[0,2.82,46.66],[1,2,75.72],[2,1.99,16.51]],"batl":[[0,3.75,2.42],[1,3.95,2.3],[2,4.2,2.03]],"ltp":3.75,"tv":1358.03,"id":2397396},{"batb":[[1,1.39,510.84],[2,1.38,219.37]],"batl":[[1,1.49,497.4]],"ltp":1.4,"tv":7853.26,"id":8979329}]}]}
{"op":"mcm","clk":"1009003171","pt":1580641409233,"mc":[{"id":"1.168224328","rc":[{"batb":[[1,2.02,6.24],[2,2,75.72]],"ltp":3.75,"tv":1358.03,"id":2397396}]}]}
{"op":"mcm","clk":"1009003209","pt":1580641409498,"mc":[{"id":"1.168224328","rc":[{"batb":[[1,2,75.72],[2,1.99,16.51]],"ltp":3.75,"tv":1358.03,"id":2397396}]}]}
{"op":"mcm","clk":"1009003658","pt":1580641412305,"mc":[{"id":"1.168224328","rc":[{"batb":[[0,3.1,11.44],[1,2.82,46.66],[2,2,75.72]],"batl":[[0,3.3,10.25],[1,3.75,2.42],[2,3.95,2.3]],"ltp":3.75,"tv":1358.03,"id":2397396},{"batb":[[0,1.45,77],[1,1.44,10.17],[2,1.43,341.47]],"batl":[[0,1.47,884.45],[1,1.48,270.22],[2,1.49,497.4]],"ltp":1.4,"tv":7853.26,"id":8979329}]}]}
{"op":"mcm","clk":"1009003789","pt":1580641412941,"mc":[{"id":"1.168224328","rc":[{"batb":[[0,2.82,46.66],[1,2,75.72],[2,1.99,16.51]],"batl":[[0,3.75,2.42],[1,3.95,2.3],[2,4.2,2.03]],"ltp":3.75,"tv":1358.03,"id":2397396},{"batb":[[1,1.43,341.47],[2,1.42,328.33]],"batl":[[0,1.47,873.95]],"ltp":1.4,"tv":7853.26,"id":8979329}]}]}
{"op":"mcm","clk":"1009004064","pt":1580641414531,"mc":[{"id":"1.168224328","rc":[{"batb":[[1,1.41,494.03],[2,1.39,510.84]],"batl":[[0,1.47,480.59],[1,1.49,497.4],[2,1.5,2.27]],"ltp":1.4,"tv":7853.26,"id":8979329}]}]}
{"op":"mcm","clk":"1009004297","pt":1580641416110,"mc":[{"id":"1.168224328","rc":[{"batb":[[1,2.02,6.24],[2,2,75.72]],"ltp":3.75,"tv":1358.03,"id":2397396}]}]}
{"op":"mcm","clk":"1009004337","pt":1580641416427,"mc":[{"id":"1.168224328","rc":[{"batb":[[1,2,75.72],[2,1.99,16.51]],"ltp":3.75,"tv":1358.03,"id":2397396}]}]}
{"op":"mcm","clk":"1009004793","pt":1580641419809,"mc":[{"id":"1.168224328","rc":[{"batb":[[1,1.38,219.37],[2,1.37,587.91]],"ltp":1.4,"tv":7853.26,"id":8979329}]}]}
{"op":"mcm","clk":"1009005180","pt":1580641422347,"mc":[{"id":"1.168224328","rc":[{"trd":[[3.25,34.35]],"batb":[[0,3.4,5.56],[1,3.35,550.42],[2,3.3,626.28]],"batl":[[0,3.55,7.6],[1,3.75,2.42],[2,3.95,2.3]],"ltp":3.25,"tv":1392.38,"id":2397396},{"trd":[[1.45,77]],"batb":[[0,1.38,219.37],[1,1.37,587.91],[2,1.36,1105.65]],"batl":[[0,1.41,1533.39],[1,1.47,480.59],[2,1.49,497.4]],"ltp":1.45,"tv":7930.26,"id":8979329}],"tv":9322.64}]}
{"op":"mcm","clk":"1009005340","pt":1580641423346,"mc":[{"id":"1.168224328","rc":[{"batb":[[1,3.35,132.05],[2,3.3,62.63]],"ltp":3.25,"tv":1392.38,"id":2397396},{"batl":[[0,1.41,1005.24],[1,1.42,320.74],[2,1.47,480.59]],"ltp":1.45,"tv":7930.26,"id":8979329}]}]}
{"op":"mcm","clk":"1009005583","pt":1580641424930,"mc":[{"id":"1.168224328","rc":[{"batl":[[2,1.44,37.86]],"ltp":1.45,"tv":7930.26,"id":8979329}]}]}
{"op":"mcm","clk":"1009005687","pt":1580641425729,"mc":[{"id":"1.168224328","rc":[{"batl":[[1,3.7,15.12],[2,3.75,2.42]],"ltp":3.25,"tv":1392.38,"id":2397396},{"batb":[[1,1.37,701.34]],"batl":[[2,1.45,42.01]],"ltp":1.45,"tv":7930.26,"id":8979329}]}]}
{"op":"mcm","clk":"1009006110","pt":1580641428612,"mc":[{"id":"1.168224328","rc":[{"batb":[[2,1.36,1599.68]],"batl":[[2,1.43,480.59]],"ltp":1.45,"tv":7930.26,"id":8979329}]}]}
{"op":"mcm","clk":"1009006391","pt":1580641430829,"mc":[{"id":"1.168224328","rc":[{"batb":[[2,1.36,1654.11]],"ltp":1.45,"tv":7930.26,"id":8979329}]}]}
{"op":"mcm","clk":"1009006973","pt":1580641435048,"mc":[{"id":"1.168224328","rc":[{"batb":[[0,3.2,18.48],[1,2.98,98.04],[2,2.12,5.29]],"batl":[[0,3.7,15.12],[1,3.8,2.07],[2,3.95,2.3]],"ltp":3.25,"tv":1392.38,"id":2397396},{"batb":[[0,1.37,113.43],[1,1.36,548.46],[2,1.34,806.83]],"batl":[[0,1.43,480.59],[1,1.45,539.41],[2,1.5,2.27]],"ltp":1.45,"tv":7930.26,"id":8979329}]}]}
{"op":"mcm","clk":"1009007083","pt":1580641435738,"mc":[{"id":"1.168224328","rc":[{"batb":[[0,2.98,98.04],[1,2.12,5.29],[2,2,75.72]],"batl":[[0,3.8,2.07],[1,3.95,2.3],[2,4.2,2.03]],"ltp":3.25,"tv":1392.38,"id":2397396},{"batb":[[0,1.36,548.46],[1,1.34,806.83],[2,1.33,44.56]],"batl":[[1,1.45,497.4]],"ltp":1.45,"tv":7930.26,"id":8979329}]}]}
{"op":"mcm","clk":"1009007542","pt":1580641439036,"mc":[{"id":"1.168224328","rc":[{"batl":[[0,3.95,2.3],[1,4.2,2.03],[2,1000,0.02]],"ltp":3.25,"tv":1392.38,"id":2397396},{"batb":[[0,1.34,295.99],[1,1.33,44.56],[2,1.32,546.99]],"ltp":1.45,"tv":7930.26,"id":8979329}]}]}
{"op":"mcm","clk":"1009007822","pt":1580641441250,"mc":[{"id":"1.168224328","rc":[{"batb":[[0,3.6,59.01],[1,2.98,98.04],[2,2.12,5.29]],"batl":[[0,3.9,322],[1,3.95,2.3],[2,4.1,325.39]],"ltp":3.25,"tv":1392.38,"id":2397396},{"batb":[[0,1.36,14.99],[1,1.34,295.99],[2,1.33,44.56]],"batl":[[0,1.38,910.04],[1,1.39,139.51],[2,1.41,923]],"ltp":1.45,"tv":7930.26,"id":8979329}]}]}
{"op":"mcm","clk":"1009007960","pt":1580641442356,"mc":[{"id":"1.168224328","rc":[{"batb":[[1,3.55,62.95],[2,3.2,80.41]],"ltp":3.25,"tv":1392.38,"id":2397396},{"batb":[[1,1.34,706.84],[2,1.33,492.5]],"batl":[[0,1.37,316.01],[1,1.38,1275.52],[2,1.39,139.51]],"ltp":1.45,"tv":7930.26,"id":8979329}]}]}
{"op":"mcm","clk":"1009008059","pt":1580641442940,"mc":[{"id":"1.168224328","rc":[{"batb":[[2,3.5,2.67]],"batl":[[1,3.95,15.74]],"ltp":3.25,"tv":1392.38,"id":2397396},{"batb":[[1,1.35,2.54],[2,1.34,830.35]],"ltp":1.45,"tv":7930.26,"id":8979329}]}]}
{"op":"mcm","clk":"1009008715","pt":1580641447849,"mc":[{"id":"1.168224328","rc":[{"batl":[[2,1.39,620.1]],"ltp":1.45,"tv":7930.26,"id":8979329}]}]}
{"op":"mcm","clk":"1009009050","pt":1580641450150,"mc":[{"id":"1.168224328","rc":[{"batb":[[2,3.5,5.31]],"batl":[[2,4.1,327.44]],"ltp":3.25,"tv":1392.38,"id":2397396}]}]}
{"op":"mcm","clk":"1009009452","pt":1580641453251,"mc":[{"id":"1.168224328","rc":[{"batb":[[0,3.5,5.31],[1,3.35,20.11],[2,3.2,80.41]],"batl":[[0,3.95,13.44],[1,4.1,2.05],[2,4.2,2.03]],"ltp":3.25,"tv":1392.38,"id":2397396},{"batb":[[0,1.35,2.54],[1,1.34,123.51],[2,1.33,589.13]],"batl":[[0,1.39,480.59],[1,1.4,49.39],[2,1.41,497.4]],"ltp":1.45,"tv":7930.26,"id":8979329}]}]}
{"op":"mcm","clk":"1009009576","pt":1580641454162,"mc":[{"id":"1.168224328","rc":[{"batb":[[1,3.35,2.47]],"batl":[[0,4.1,2.05],[1,4.2,2.03],[2,1000,0.02]],"ltp":3.25,"tv":1392.38,"id":2397396},{"batb":[[0,1.37,5.05],[1,1.35,2.54]],"ltp":1.45,"tv":7930.26,"id":8979329}]}]}
{"op":"mcm","clk":"1009010268","pt":1580641459090,"mc":[{"id":"1.168224328","rc":[{"batb":[[0,1.35,2.54],[1,1.33,589.13],[2,1.32,813.8]],"ltp":1.45,"tv":7930.26,"id":8979329}]}]}
{"op":"mcm","clk":"1009010414","pt":1580641460158,"mc":[{"id":"1.168224328","rc":[{"batb":[[0,1.33,95.09],[1,1.32,813.8],[2,1.15,378.72]],"ltp":1.45,"tv":7930.26,"id":8979329}]}]}
{"op":"mcm","clk":"1009010723","pt":1580641462161,"mc":[{"id":"1.168224328","rc":[{"batb":[[0,3.75,53.44],[1,3.5,5.31],[2,3.35,2.47]],"batl":[[0,4,5.62],[1,4.1,288.05],[2,4.2,2.03]],"ltp":3.25,"tv":1392.38,"id":2397396},{"batb":[[1,1.32,1038.27],[2,1.31,481.28]],"batl":[[0,1.35,1379.77],[1,1.36,387.58],[2,1.37,152.6]],"ltp":1.45,"tv":7930.26,"id":8979329}]}]}
{"op":"mcm","clk":"1009010875","pt":1580641463275,"mc":[{"id":"1.168224328","rc":[{"batb":[[0,3.75,109.85],[1,3.55,15.96],[2,3.5,70.78]],"batl":[[1,4.1,301.49]],"ltp":3.25,"tv":1392.38,"id":2397396},{"batb":[[1,1.32,1169.34]],"ltp":1.45,"tv":7930.26,"id":8979329}]}]}
{"op":"mcm","clk":"1009011703","pt":1580641468383,"mc":[{"id":"1.168224328","rc":[{"batb":[[0,3.75,56.41]],"batl":[[0,4.1,13.44],[1,4.2,2.03],[2,1000,0.02]],"ltp":3.25,"tv":1392.38,"id":2397396},{"batb":[[0,1.33,44.56]],"batl":[[0,1.35,571.53],[2,1.39,42.01]],"ltp":1.45,"tv":7930.26,"id":8979329}]}]}
{"op":"mcm","clk":"1009011740","pt":1580641468698,"mc":[{"id":"1.168224328","rc":[{"batb":[[0,3.55,15.96],[1,3.5,70.78],[2,3.35,2.47]],"ltp":3.25,"tv":1392.38,"id":2397396},{"trd":[[1.35,2457.32]],"batb":[[1,1.32,678.06],[2,1.3,778.55]],"batl":[[0,1.37,480.59],[1,1.39,539.41],[2,1.4,49.39]],"ltp":1.35,"tv":7940.35,"id":8979329}],"tv":9332.73}]}
{"op":"mcm","clk":"1009011901","pt":1580641469771,"mc":[{"id":"1.168224328","rc":[{"batb":[[0,3.5,70.78],[1,3.35,2.47],[2,2.2,75.72]],"batl":[[0,4.2,2.03],[1,1000,0.02],[2,1000,0]],"ltp":3.25,"tv":1392.38,"id":2397396},{"batb":[[1,1.32,546.99]],"batl":[[1,1.39,497.4]],"ltp":1.35,"tv":7940.35,"id":8979329}]}]}
{"op":"mcm","clk":"1009012101","pt":1580641471191,"mc":[{"id":"1.168224328","rc":[{"batb":[[0,3.7,2.02],[1,3.5,65.46]],"ltp":3.25,"tv":1392.38,"id":2397396},{"batl":[[0,1.37,523.09],[2,1.5,2.27]],"ltp":1.35,"tv":7940.35,"id":8979329}]}]}
{"op":"mcm","clk":"1009012193","pt":1580641471784,"mc":[{"id":"1.168224328","rc":[{"batb":[[2,1.3,828.51]],"ltp":1.35,"tv":7940.35,"id":8979329}]}]}
{"op":"mcm","clk":"1009012564","pt":1580641474381,"mc":[{"id":"1.168224328","rc":[{"batb":[[0,4,3.93],[1,3.8,50.42],[2,3.7,50.99]],"batl":[[1,4.3,371],[2,1000,0.02]],"ltp":3.25,"tv":1392.38,"id":2397396},{"trd":[[1.33,144.02]],"batb":[[0,1.32,558.23],[1,1.3,828.51],[2,1.29,744.24]],"batl":[[0,1.33,1018.6],[1,1.34,419.2],[2,1.37,1643.09]],"ltp":1.33,"tv":8029.47,"id":8979329}],"tv":9421.85}]}
{"op":"mcm","clk":"1009012705","pt":1580641475379,"mc":[{"id":"1.168224328","rc":[{"batb":[[1,3.85,52.4],[2,3.8,50.42]],"batl":[[1,4.3,383.6]],"ltp":3.25,"tv":1392.38,"id":2397396},{"batb":[[1,1.3,967.99],[2,1.29,1272.66]],"batl":[[2,1.37,1685.1]],"ltp":1.33,"tv":8029.47,"id":8979329}]}]}
{"op":"mcm","clk":"1009012833","pt":1580641476384,"mc":[{"id":"1.168224328","rc":[{"trd":[[1.33,149.34]],"batl":[[0,1.33,1015.94]],"ltp":1.33,"tv":8034.78,"id":8979329}],"tv":9427.17}]}
{"op":"mcm","clk":"1009013534","pt":1580641480987,"mc":[{"id":"1.168224328","rc":[{"batl":[[2,1.37,1204.51]],"ltp":1.33,"tv":8034.78,"id":8979329}]}]}
{"op":"mcm","clk":"1009013825","pt":1580641482786,"mc":[{"id":"1.168224328","rc":[{"batl":[[2,4.6,2]],"ltp":3.25,"tv":1392.38,"id":2397396}]}]}
{"op":"mcm","clk":"1009013956","pt":1580641483720,"mc":[{"id":"1.168224328","rc":[{"trd":[[1.33,150.91]],"batl":[[0,1.33,1015.15]],"ltp":1.33,"tv":8036.36,"id":8979329}],"tv":9428.74}]}
{"op":"mcm","clk":"1009015225","pt":1580641492312,"mc":[{"id":"1.168224328","rc":[{"batb":[[2,3.8,52.63]],"ltp":3.25,"tv":1392.38,"id":2397396}]}]}
{"op":"mcm","clk":"1009015360","pt":1580641493110,"mc":[{"id":"1.168224328","rc":[{"batb":[[2,3.8,50.42]],"ltp":3.25,"tv":1392.38,"id":2397396},{"trd":[[1.32,195.39]],"batb":[[0,1.32,558.07]],"ltp":1.32,"tv":8036.68,"id":8979329}],"tv":9429.06}]}
{"op":"mcm","clk":"1009016057","pt":1580641498126,"mc":[{"id":"1.168224328","rc":[{"batb":[[0,3.7,17.68],[1,3.65,60.11],[2,3.55,2.19]],"batl":[[0,4.3,12.6],[1,4.6,2],[2,4.9,2.01]],"ltp":3.25,"tv":1392.38,"id":2397396},{"batb":[[0,1.32,496.69],[1,1.3,139.47],[2,1.28,58.66]],"batl":[[0,1.37,42.01],[1,1.39,48.5],[2,1.5,2.27]],"ltp":1.32,"tv":8036.68,"id":8979329}]}]}
{"op":"mcm","clk":"1009016317","pt":1580641499934,"mc":[{"id":"1.168224328","rc":[{"batb":[[0,3.7,2.55]],"batl":[[0,4.6,2],[1,4.9,2.01],[2,1000,0.02]],"ltp":3.25,"tv":1392.38,"id":2397396},{"batb":[[1,1.28,58.66],[2,1.26,409.3]],"batl":[[0,1.39,48.5],[1,1.5,2.27],[2,1.62,614.4]],"ltp":1.32,"tv":8036.68,"id":8979329}]}]}
{"op":"mcm","clk":"1009016566","pt":1580641501316,"mc":[{"id":"1.168224328","rc":[{"batb":[[0,3.7,5.07]],"ltp":3.25,"tv":1392.38,"id":2397396},{"batb":[[2,1.26,1008.29]],"batl":[[0,1.36,276.78],[1,1.37,428.83],[2,1.39,48.5]],"ltp":1.32,"tv":8036.68,"id":8979329}]}]}
{"op":"mcm","clk":"1009016643","pt":1580641501800,"mc":[{"id":"1.168224328","rc":[{"batb":[[0,3.7,2.55]],"ltp":3.25,"tv":1392.38,"id":2397396},{"batb":[[2,1.26,409.3]],"batl":[[0,1.39,48.5],[1,1.5,2.27],[2,1.62,614.4]],"ltp":1.32,"tv":8036.68,"id":8979329}]}]}
{"op":"mcm","clk":"1009017005","pt":1580641504335,"mc":[{"id":"1.168224328","rc":[{"trd":[[4.2,31.84]],"ltp":4.2,"tv":1406.38,"id":2397396}],"tv":9443.06}]}
{"op":"mcm","clk":"1009017148","pt":1580641505239,"mc":[{"id":"1.168224328","rc":[{"batb":[[0,3.65,60.11],[1,3.55,2.19],[2,2.2,75.72]],"ltp":4.2,"tv":1406.38,"id":2397396},{"trd":[[1.32,829.62]],"batb":[[0,1.32,179.7],[1,1.29,652.34],[2,1.28,612.45]],"batl":[[0,1.33,435.73],[1,1.39,48.5],[2,1.5,2.27]],"ltp":1.32,"tv":8670.9,"id":8979329}],"tv":10077.29}]}
{"op":"mcm","clk":"1009017248","pt":1580641505824,"mc":[{"id":"1.168224328","rc":[{"batb":[[1,1.29,520.92],[2,1.28,58.66]],"ltp":1.32,"tv":8670.9,"id":8979329}]}]}
{"op":"mcm","clk":"1009017700","pt":1580641508405,"mc":[{"id":"1.168224328","rc":[{"batb":[[0,3.7,2.12],[1,3.65,60.11],[2,3.55,2.19]],"ltp":4.2,"tv":1406.38,"id":2397396},{"batb":[[1,1.28,58.66],[2,1.26,409.3]],"batl":[[0,1.37,43.5]],"ltp":1.32,"tv":8670.9,"id":8979329}]}]}
{"op":"mcm","clk":"1009017773","pt":1580641508834,"mc":[{"id":"1.168224328","rc":[{"batb":[[0,3.65,60.11],[1,3.55,2.19],[2,2.2,75.72]],"ltp":4.2,"tv":1406.38,"id":2397396},{"batl":[[0,1.39,48.5],[1,1.5,2.27],[2,1.62,614.4]],"ltp":1.32,"tv":8670.9,"id":8979329}]}]}
{"op":"mcm","clk":"1009018172","pt":1580641511331,"mc":[{"id":"1.168224328","rc":[{"batb":[[2,1.26,1192.35]],"ltp":1.32,"tv":8670.9,"id":8979329}]}]}
{"op":"mcm","clk":"1009018469","pt":1580641513323,"mc":[{"id":"1.168224328","rc":[{"trd":[[4,5.55]],"batb":[[0,4.5,302.77],[1,3.65,60.11],[2,3.55,2.19]],"batl":[[0,4.8,237.85]],"ltp":4.0,"tv":1409.41,"id":2397396},{"trd":[[1.28,159.03],[1.32,1189.22],[1.33,160.02]],"batb":[[0,1.26,2978.06],[1,1.25,634.98],[2,1.24,813.36]],"batl":[[0,1.29,1744.19],[1,1.3,557.68],[2,1.31,800]],"ltp":1.28,"tv":9068.19,"id":8979329}],"tv":10477.6}]}
{"op":"mcm","clk":"1009018635","pt":1580641514331,"mc":[{"id":"1.168224328","rc":[{"batb":[[1,4.3,80.81],[2,3.95,98.75]],"ltp":4.0,"tv":1409.41,"id":2397396},{"batl":[[0,1.29,2110.61],[1,1.3,485.64]],"ltp":1.28,"tv":9068.19,"id":8979329}]}]}
{"op":"mcm","clk":"1009018793","pt":1580641515263,"mc":[{"id":"1.168224328","rc":[{"batb":[[2,4.2,2.69]],"ltp":4.0,"tv":1409.41,"id":2397396},{"batb":[[0,1.26,3139.38]],"batl":[[2,1.31,837.86]],"ltp":1.28,"tv":9068.19,"id":8979329}]}]}
{"op":"mcm","clk":"1009019004","pt":1580641516349,"mc":[{"id":"1.168224328","rc":[{"batl":[[2,1.31,800]],"ltp":1.28,"tv":9068.19,"id":8979329}]}]}
{"op":"mcm","clk":"1009019185","pt":1580641517254,"mc":[{"id":"1.168224328","rc":[{"batl":[[0,4.8,248.77]],"ltp":4.0,"tv":1409.41,"id":2397396}]}]}
{"op":"mcm","clk":"1009019600","pt":1580641519938,"mc":[{"id":"1.168224328","rc":[{"batb":[[1,1.25,1137.42],[2,1.24,1332.6]],"batl":[[2,1.31,1288.99]],"ltp":1.28,"tv":9068.19,"id":8979329}]}]}
{"op":"mcm","clk":"1009019857","pt":1580641521841,"mc":[{"id":"1.168224328","rc":[{"batl":[[2,5.6,2]],"ltp":4.0,"tv":1409.41,"id":2397396}]}]}
{"op":"mcm","clk":"1009020237","pt":1580641524134,"mc":[{"id":"1.168224328","rc":[{"batb":[[0,4.2,2.69],[1,4.1,13.44],[2,3.95,98.75]],"batl":[[0,4.8,10.92],[1,5.6,2],[2,6,2]],"ltp":4.0,"tv":1409.41,"id":2397396},{"batb":[[0,1.26,161.32],[1,1.25,502.44],[2,1.24,519.24]],"batl":[[0,1.31,488.99],[1,1.32,547.81],[2,1.34,55.75]],"ltp":1.28,"tv":9068.19,"id":8979329}]}]}
{"op":"mcm","clk":"1009020400","pt":1580641525244,"mc":[{"id":"1.168224328","rc":[{"batl":[[0,1.31,722.57]],"ltp":1.28,"tv":9068.19,"id":8979329}]}]}
{"op":"mcm","clk":"1009020575","pt":1580641526373,"mc":[{"id":"1.168224328","rc":[{"batb":[[1,3.95,98.75],[2,3.9,2.06]],"batl":[[0,4.7,5.57]],"ltp":4.0,"tv":1409.41,"id":2397396},{"batb":[[0,1.25,502.44],[1,1.24,519.24],[2,1.22,280.11]],"batl":[[1,1.32,505.8]],"ltp":1.28,"tv":9068.19,"id":8979329}]}]}
{"op":"mcm","clk":"1009020664","pt":1580641526854,"mc":[{"id":"1.168224328","rc":[{"batl":[[0,5.6,2],[1,6,2],[2,1000,0.02]],"ltp":4.0,"tv":1409.41,"id":2397396},{"batb":[[2,1.22,924.7]],"batl":[[2,1.33,535.4]],"ltp":1.28,"tv":9068.19,"id":8979329}]}]}
{"op":"mcm","clk":"1009020889","pt":1580641528151,"mc":[{"id":"1.168224328","rc":[{"batl":[[2,1.34,55.75]],"ltp":1.28,"tv":9068.19,"id":8979329}]}]}
{"op":"mcm","clk":"1009020947","pt":1580641528468,"mc":[{"id":"1.168224328","rc":[{"batb":[[0,1.22,924.7],[1,1.21,1206.17],[2,1.2,88.57]],"ltp":1.28,"tv":9068.19,"id":8979329}]}]}
{"op":"mcm","clk":"1009021251","pt":1580641530252,"mc":[{"id":"1.168224328","rc":[{"batb":[[0,1.22,728.93]],"ltp":1.28,"tv":9068.19,"id":8979329}]}]}
{"op":"mcm","clk":"1009021412","pt":1580641531155,"mc":[{"id":"1.168224328","rc":[{"batl":[[1,5.7,213.02],[2,6,2]],"ltp":4.0,"tv":1409.41,"id":2397396},{"batb":[[0,1.22,2573.19]],"batl":[[0,1.23,1213.53],[1,1.24,1814.52],[2,1.25,803.68]],"ltp":1.28,"tv":9068.19,"id":8979329}]}]}
{"op":"mcm","clk":"1009021630","pt":1580641532338,"mc":[{"id":"1.168224328","rc":[{"batb":[[0,4.9,57.83],[1,4.4,73.57],[2,4.2,2.69]],"ltp":4.0,"tv":1409.41,"id":2397396}]}]}
{"op":"mcm","clk":"1009021751","pt":1580641533175,"mc":[{"id":"1.168224328","rc":[{"batb":[[1,4.6,10.92],[2,4.4,73.57]],"batl":[[0,5.5,9.24],[1,5.6,2],[2,5.7,213.02]],"ltp":4.0,"tv":1409.41,"id":2397396},{"batb":[[0,1.22,2741.23]],"ltp":1.28,"tv":9068.19,"id":8979329}]}]}
{"op":"mcm","clk":"1009021946","pt":1580641534240,"mc":[{"id":"1.168224328","rc":[{"trd":[[1.23,25.2]],"batl":[[0,1.23,1200.93]],"ltp":1.23,"tv":9093.39,"id":8979329}],"tv":10502.8}]}
{"op":"mcm","clk":"1009022598","pt":1580641538197,"mc":[{"id":"1.168224328","rc":[{"trd":[[1.23,95.77]],"batb":[[2,1.2,591.01]],"batl":[[0,1.23,1165.65],[2,1.25,1292.67]],"ltp":1.23,"tv":9163.96,"id":8979329}],"tv":10573.37}]}
{"op":"mcm","clk":"1009022671","pt":1580641538719,"mc":[{"id":"1.168224328","rc":[{"batb":[[2,4.4,75.57]],"ltp":4.0,"tv":1409.41,"id":2397396}]}]}
{"op":"mcm","clk":"1009023683","pt":1580641544982,"mc":[{"id":"1.168224328","rc":[{"batb":[[0,4.6,10.92],[1,4.4,75.57],[2,4.2,2.02]],"batl":[[1,7,2],[2,7.8,2]],"ltp":4.0,"tv":1409.41,"id":2397396},{"batb":[[0,1.22,168.04],[1,1.2,502.54],[2,1.19,752.81]],"batl":[[0,1.25,488.99],[1,1.26,505.8],[2,1.27,163]],"ltp":1.23,"tv":9163.96,"id":8979329}]}]}
{"op":"mcm","clk":"1009023846","pt":1580641545980,"mc":[{"id":"1.168224328","rc":[{"batb":[[0,4.4,75.57],[1,4.2,2.02],[2,3.9,2.06]],"batl":[[0,7,2],[1,7.8,2],[2,1000,0.02]],"ltp":4.0,"tv":1409.41,"id":2397396},{"batb":[[0,1.2,502.54],[1,1.19,752.81],[2,1.17,651.3]],"batl":[[2,1.27,120.99]],"ltp":1.23,"tv":9163.96,"id":8979329}]}]}
{"op":"mcm","clk":"1009024072","pt":1580641547380,"mc":[{"id":"1.168224328","rc":[{"batl":[[0,5.5,4.51],[1,7,2],[2,7.8,2]],"ltp":4.0,"tv":1409.41,"id":2397396},{"batl":[[0,1.24,24.14],[1,1.25,488.99],[2,1.26,505.8]],"ltp":1.23,"tv":9163.96,"id":8979329}]}]}
{"op":"mcm","clk":"1009024153","pt":1580641547899,"mc":[{"id":"1.168224328","rc":[{"trd":[[5.5,0.14]],"batl":[[0,7,2],[1,7.8,2],[2,1000,0.02]],"ltp":5.5,"tv":1409.55,"id":2397396},{"trd":[[1.22,0.65]],"batb":[[2,1.18,814.11]],"batl":[[0,1.25,488.99],[1,1.26,505.8],[2,1.27,120.99]],"ltp":1.22,"tv":9164.61,"id":8979329}],"tv":10574.16}]}
{"op":"mcm","clk":"1009024545","pt":1580641550291,"mc":[{"id":"1.168224328","rc":[{"batb":[[2,1.17,651.3]],"ltp":1.22,"tv":9164.61,"id":8979329}]}]}
{"op":"mcm","clk":"1009024625","pt":1580641550779,"mc":[{"id":"1.168224328","rc":[{"batl":[[0,1.27,120.99],[1,1.28,575.55],[2,1.29,563.33]],"ltp":1.22,"tv":9164.61,"id":8979329}]}]}
{"op":"mcm","clk":"1009024799","pt":1580641551886,"mc":[{"id":"1.168224328","rc":[{"batl":[[0,1.28,575.55],[1,1.29,563.33],[2,1.31,63.5]],"ltp":1.22,"tv":9164.61,"id":8979329}]}]}
{"op":"mcm","clk":"1009025029","pt":1580641553286,"mc":[{"id":"1.168224328","rc":[{"batl":[[0,5.1,247],[1,5.2,2],[2,5.3,1165.65]],"ltp":5.5,"tv":1409.55,"id":2397396},{"trd":[[1.26,32.26]],"batb":[[0,1.25,629.8],[1,1.24,665.28],[2,1.23,1641.91]],"batl":[[0,1.26,756.45],[1,1.28,601.01],[2,1.29,1398.33]],"ltp":1.26,"tv":9196.87,"id":8979329}],"tv":10606.42}]}
{"op":"mcm","clk":"1009025195","pt":1580641554389,"mc":[{"id":"1.168224328","rc":[{"batb":[[0,4.5,2.58],[1,4.4,75.57],[2,4.2,2.02]],"ltp":5.5,"tv":1409.55,"id":2397396},{"batb":[[0,1.25,993.94]],"ltp":1.26,"tv":9196.87,"id":8979329}]}]}
{"op":"mcm","clk":"1009025279","pt":1580641554882,"mc":[{"id":"1.168224328","rc":[{"batb":[[2,4.3,12.6]],"batl":[[0,5,10.08],[1,5.1,247],[2,5.2,2]],"ltp":5.5,"tv":1409.55,"id":2397396},{"batb":[[0,1.25,1161.98],[2,1.23,164.19]],"ltp":1.26,"tv":9196.87,"id":8979329}]}]}
{"op":"mcm","clk":"1009025765","pt":1580641558085,"mc":[{"id":"1.168224328","rc":[{"batl":[[1,1.28,575.55]],"ltp":1.26,"tv":9196.87,"id":8979329}]}]}
{"op":"mcm","clk":"1009026133","pt":1580641560195,"mc":[{"id":"1.168224328","rc":[{"batb":[[1,1.24,1167.72],[2,1.23,683.43]],"batl":[[1,1.28,1064.54],[2,1.29,1904.13]],"ltp":1.26,"tv":9196.87,"id":8979329}]}]}
{"op":"mcm","clk":"1009026276","pt":1580641560990,"mc":[{"id":"1.168224328","rc":[{"batl":[[0,5,15.87]],"ltp":5.5,"tv":1409.55,"id":2397396},{"batl":[[1,1.27,21.47],[2,1.28,1064.54]],"ltp":1.26,"tv":9196.87,"id":8979329}]}]}
{"op":"mcm","clk":"1009026603","pt":1580641563088,"mc":[{"id":"1.168224328","rc":[{"batl":[[0,5,10.08]],"ltp":5.5,"tv":1409.55,"id":2397396},{"batl":[[1,1.28,1064.54],[2,1.29,1904.13]],"ltp":1.26,"tv":9196.87,"id":8979329}]}]}
{"op":"mcm","clk":"1009027125","pt":1580641566386,"mc":[{"id":"1.168224328","rc":[{"batl":[[0,5,15.87]],"ltp":5.5,"tv":1409.55,"id":2397396},{"batl":[[1,1.27,21.47],[2,1.28,1064.54]],"ltp":1.26,"tv":9196.87,"id":8979329}]}]}
{"op":"mcm","clk":"1009027778","pt":1580641570306,"mc":[{"id":"1.168224328","rc":[{"batl":[[0,5,10.08],[1,5.2,2],[2,5.3,116.56]],"ltp":5.5,"tv":1409.55,"id":2397396},{"batl":[[0,1.28,1064.54],[1,1.29,1069.13],[2,1.3,42.01]],"ltp":1.26,"tv":9196.87,"id":8979329}]}]}
{"op":"mcm","clk":"1009027949","pt":1580641571316,"mc":[{"id":"1.168224328","rc":[{"batb":[[0,4.3,12.6],[1,4.2,2.02],[2,3.75,2.23]],"batl":[[1,5.3,116.56],[2,6.4,2]],"ltp":5.5,"tv":1409.55,"id":2397396},{"batb":[[0,1.25,168.04],[1,1.24,502.44]],"batl":[[0,1.31,63.5],[1,1.32,94.1],[2,1.36,43.32]],"ltp":1.26,"tv":9196.87,"id":8979329}]}]}
{"op":"mcm","clk":"1009028156","pt":1580641572393,"mc":[{"id":"1.168224328","rc":[{"batb":[[0,4.2,2.02],[1,3.75,2.23],[2,3.55,2.19]],"batl":[[0,5.3,116.56],[1,6.4,2],[2,7,4.27]],"ltp":5.5,"tv":1409.55,"id":2397396},{"batb":[[0,1.24,502.44],[1,1.23,683.43],[2,1.21,222.65]],"ltp":1.26,"tv":9196.87,"id":8979329}]}]}
{"op":"mcm","clk":"1009028329","pt":1580641573304,"mc":[{"id":"1.168224328","rc":[{"batb":[[0,4.3,213.34],[1,4.2,2.02],[2,3.75,2.23]],"batl":[[0,4.4,5.44],[1,4.6,362],[2,5.3,116.56]],"ltp":5.5,"tv":1409.55,"id":2397396},{"batb":[[0,1.26,888.94],[1,1.24,502.44],[2,1.23,683.43]],"batl":[[0,1.31,74.8],[2,1.34,1102]],"ltp":1.26,"tv":9196.87,"id":8979329}]}]}
{"op":"mcm","clk":"1009028472","pt":1580641574298,"mc":[{"id":"1.168224328","rc":[{"batb":[[0,1.29,517.21],[1,1.28,547.88],[2,1.26,888.94]],"batl":[[0,1.31,116.81],[1,1.32,527.79],[2,1.33,431.04]],"ltp":1.26,"tv":9196.87,"id":8979329}]}]}
{"op":"mcm","clk":"1009028640","pt":1580641575322,"mc":[{"id":"1.168224328","rc":[{"batb":[[2,3.95,13.44]],"batl":[[1,4.6,372.92]],"ltp":5.5,"tv":1409.55,"id":2397396},{"batb":[[1,1.28,697.43]],"batl":[[0,1.31,74.8]],"ltp":1.26,"tv":9196.87,"id":8979329}]}]}
{"op":"mcm","clk":"1009028707","pt":1580641575682,"mc":[{"id":"1.168224328","rc":[{"batl":[[1,1.32,433.69]],"ltp":1.26,"tv":9196.87,"id":8979329}]}]}
{"op":"mcm","clk":"1009030408","pt":1580641585341,"mc":[{"id":"1.168224328","rc":[{"batb":[[0,4.2,2.02],[1,3.95,13.44],[2,3.75,2.23]],"batl":[[0,4.6,10.92],[1,5.3,116.56],[2,5.4,2]],"ltp":5.5,"tv":1409.55,"id":2397396},{"batb":[[2,1.25,130.23]],"batl":[[0,1.31,63.5]],"ltp":1.26,"tv":9196.87,"id":8979329}]}]}
{"op":"mcm","clk":"1009030586","pt":1580641586250,"mc":[{"id":"1.168224328","rc":[{"batb":[[0,3.6,2.24],[1,2.6,75.72],[2,2.2,75.72]],"batl":[[0,5.4,2],[1,6,2],[2,6.4,2]],"ltp":5.5,"tv":1409.55,"id":2397396},{"trd":[[1.28,259.03]],"batb":[[0,1.25,130.23],[1,1.23,237.82],[2,1.2,99.97]],"batl":[[0,1.38,42.75],[1,1.49,761.67],[2,1.5,2.27]],"ltp":1.28,"tv":9296.87,"id":8979329}],"tv":10706.42}]}
{"op":"mcm","clk":"1009031097","pt":1580641588966,"mc":[{"id":"1.168224328","rc":[{"batl":[[0,1.37,494.93],[1,1.38,403.83],[2,1.49,761.67]],"ltp":1.28,"tv":9296.87,"id":8979329}]}]}
{"op":"mcm","clk":"1009031312","pt":1580641590130,"mc":[{"id":"1.168224328","rc":[{"batl":[[2,1.5,2.27]],"ltp":1.28,"tv":9296.87,"id":8979329}]}]}
{"op":"mcm","clk":"1009031536","pt":1580641591353,"mc":[{"id":"1.168224328","rc":[{"batl":[[0,3.9,3.54],[1,4.1,1223.47],[2,4.3,227.22]],"ltp":5.5,"tv":1409.55,"id":2397396},{"batl":[[0,1.35,688.82],[1,1.36,13.21],[2,1.37,494.93]],"ltp":1.28,"tv":9296.87,"id":8979329}]}]}
{"op":"mcm","clk":"1009031697","pt":1580641592149,"mc":[{"id":"1.168224328","rc":[{"batb":[[1,2.2,75.72],[2,2,75.72]],"batl":[[1,4.1,404.38]],"ltp":5.5,"tv":1409.55,"id":2397396},{"batb":[[0,1.33,659.66],[1,1.32,466.77],[2,1.25,130.23]],"ltp":1.28,"tv":9296.87,"id":8979329}]}]}
{"op":"mcm","clk":"1009031921","pt":1580641593339,"mc":[{"id":"1.168224328","rc":[{"batb":[[0,3.7,15.12],[1,3.65,2.59],[2,3.6,2.24]],"batl":[[2,4.2,12.6]],"ltp":5.5,"tv":1409.55,"id":2397396},{"batb":[[2,1.31,135.27]],"batl":[[2,1.37,536.94]],"ltp":1.28,"tv":9296.87,"id":8979329}]}]}
{"op":"mcm","clk":"1009032727","pt":1580641598341,"mc":[{"id":"1.168224328","rc":[{"batb":[[1,1.32,960.8]],"ltp":1.28,"tv":9296.87,"id":8979329}]}]}
{"op":"mcm","clk":"1009033872","pt":1580641605375,"mc":[{"id":"1.168224328","rc":[{"batl":[[0,4.1,2],[1,4.2,12.6],[2,4.4,2.04]],"ltp":5.5,"tv":1409.55,"id":2397396},{"batl":[[0,1.37,536.94],[1,1.38,884.42],[2,1.4,541.69]],"ltp":1.28,"tv":9296.87,"id":8979329}]}]}
{"op":"mcm","clk":"1009034017","pt":1580641606025,"mc":[{"id":"1.168224328","rc":[{"batb":[[0,3.65,2.59],[1,3.6,2.24],[2,3.5,2.64]],"batl":[[0,4.4,2.04],[1,4.6,2.01],[2,5.4,2]],"ltp":5.5,"tv":1409.55,"id":2397396},{"trd":[[1.32,1239.22]],"batb":[[0,1.32,469.03],[1,1.3,568.72],[2,1.28,295.73]],"batl":[[0,1.38,523.34],[1,1.4,541.69],[2,1.5,2.27]],"ltp":1.32,"tv":9346.87,"id":8979329}],"tv":10756.43}]}
{"op":"mcm","clk":"1009034452","pt":1580641608643,"mc":[{"id":"1.168224328","rc":[{"batb":[[2,1.29,309.38]],"batl":[[2,1.41,535.1]],"ltp":1.32,"tv":9346.87,"id":8979329}]}]}
{"op":"mcm","clk":"1009035556","pt":1580641615357,"mc":[{"id":"1.168224328","rc":[{"batb":[[1,3.5,2.64],[2,2.2,75.72]],"batl":[[2,7,2.27]],"ltp":5.5,"tv":1409.55,"id":2397396},{"batb":[[2,1.28,295.73]],"batl":[[0,1.4,44.29],[1,1.41,535.1],[2,1.42,317.68]],"ltp":1.32,"tv":9346.87,"id":8979329}]}]}
{"op":"mcm","clk":"1009035874","pt":1580641617374,"mc":[{"id":"1.168224328","rc":[{"batb":[[0,3.6,239.43]],"batl":[[0,3.8,475.76],[1,4,303.75],[2,4.4,2.04]],"ltp":5.5,"tv":1409.55,"id":2397396},{"batb":[[0,1.38,1642.74],[1,1.32,469.03],[2,1.3,568.72]],"batl":[[0,1.4,51.79],[1,1.41,2130.84],[2,1.42,1147.68]],"ltp":1.32,"tv":9346.87,"id":8979329}]}]}
{"op":"mcm","clk":"1009036043","pt":1580641618389,"mc":[{"id":"1.168224328","rc":[{"batb":[[2,2,75.72]],"batl":[[0,3.8,299]],"ltp":5.5,"tv":1409.55,"id":2397396},{"batb":[[1,1.37,410.78],[2,1.36,401.06]],"ltp":1.32,"tv":9346.87,"id":8979329}]}]}
{"op":"mcm","clk":"1009036155","pt":1580641618949,"mc":[{"id":"1.168224328","rc":[{"batb":[[2,3.4,16.8]],"batl":[[1,3.85,14.28],[2,4,303.75]],"ltp":5.5,"tv":1409.55,"id":2397396},{"batl":[[2,1.42,1189.69]],"ltp":1.32,"tv":9346.87,"id":8979329}]}]}
{"op":"mcm","clk":"1009037532","pt":1580641627461,"mc":[{"id":"1.168224328","rc":[{"trd":[[1.38,124.97]],"batb":[[0,1.38,1618.82]],"ltp":1.38,"tv":9394.71,"id":8979329}],"tv":10804.27}]}
{"op":"mcm","clk":"1009037828","pt":1580641629277,"mc":[{"id":"1.168224328","rc":[{"batb":[[2,1.36,651.44]],"ltp":1.38,"tv":9394.71,"id":8979329}]}]}
{"op":"mcm","clk":"1009038347","pt":1580641632399,"mc":[{"id":"1.168224328","rc":[{"batb":[[2,1.36,401.06]],"ltp":1.38,"tv":9394.71,"id":8979329}]}]}
{"op":"mcm","clk":"1009038432","pt":1580641632982,"mc":[{"id":"1.168224328","rc":[{"trd":[[3.6,0.9]],"batb":[[0,3.6,238.53]],"ltp":3.6,"tv":1410.45,"id":2397396},{"trd":[[1.39,2.34]],"ltp":1.39,"tv":9397.06,"id":8979329}],"tv":10807.51}]}
{"op":"mcm","clk":"1009038827","pt":1580641635797,"mc":[{"id":"1.168224328","rc":[{"batb":[[2,1.36,495.16]],"ltp":1.39,"tv":9397.06,"id":8979329}]}]}
{"op":"mcm","clk":"1009042797","pt":1580641661072,"mc":[{"id":"1.168224328","rc":[{"trd":[[1.38,125.64]],"batb":[[0,1.38,1618.49]],"ltp":1.38,"tv":9397.72,"id":8979329}],"tv":10808.17}]}
{"op":"mcm","clk":"1009044122","pt":1580641669714,"mc":[{"id":"1.168224328","rc":[{"trd":[[1.38,3362.62]],"batb":[[0,1.37,410.78],[1,1.36,495.16],[2,1.35,119.31]],"batl":[[0,1.38,3381.51],[1,1.4,51.79],[2,1.41,2130.84]],"ltp":1.38,"tv":12634.7,"id":8979329}],"tv":14045.15}]}
{"op":"mcm","clk":"1009045742","pt":1580641679934,"mc":[{"id":"1.168224328","rc":[{"batl":[[1,1.4,44.29]],"ltp":1.38,"tv":12634.7,"id":8979329}]}]}
{"op":"mcm","clk":"1009045936","pt":1580641681322,"mc":[{"id":"1.168224328","rc":[{"trd":[[1.38,3366.48]],"batl":[[0,1.38,3379.58]],"ltp":1.38,"tv":12638.56,"id":8979329}],"tv":14049.01}]}
{"op":"mcm","clk":"1009046168","pt":1580641682923,"mc":[{"id":"1.168224328","rc":[{"batl":[[0,3.7,5.23],[1,3.8,299],[2,3.85,14.28]],"ltp":3.6,"tv":1410.45,"id":2397396},{"batl":[[1,1.39,13.93],[2,1.4,44.29]],"ltp":1.38,"tv":12638.56,"id":8979329}]}]}
{"op":"mcm","clk":"1009046312","pt":1580641683835,"mc":[{"id":"1.168224328","rc":[{"trd":[[1.38,3389.98]],"batl":[[0,1.38,3367.83]],"ltp":1.38,"tv":12662.06,"id":8979329}],"tv":14072.51}]}
{"op":"mcm","clk":"1009047828","pt":1580641694359,"mc":[{"id":"1.168224328","rc":[{"batb":[[0,3.5,2.64],[1,3.4,16.8],[2,3.05,90.25]],"batl":[[0,3.8,2],[1,3.85,14.28],[2,4.4,2.04]],"ltp":3.6,"tv":1410.45,"id":2397396},{"batl":[[1,1.4,44.29],[2,1.41,2130.84]],"ltp":1.38,"tv":12662.06,"id":8979329}]}]}
{"op":"mcm","clk":"1009047883","pt":1580641694633,"mc":[{"id":"1.168224328","rc":[{"batb":[[0,3.4,16.8],[1,3.05,90.25],[2,2,75.72]],"batl":[[0,3.85,14.28],[1,4.4,2.04],[2,7,2.27]],"ltp":3.6,"tv":1410.45,"id":2397396},{"batb":[[0,1.36,94.1],[1,1.35,119.31],[2,1.34,496.01]],"batl":[[1,1.42,42.01],[2,1.5,2.27]],"ltp":1.38,"tv":12662.06,"id":8979329}]}]}
{"op":"mcm","clk":"1009048132","pt":1580641696237,"mc":[{"id":"1.168224328","rc":[{"batb":[[0,3.05,90.25],[1,2,75.72],[2,1.8,75.72]],"batl":[[0,4.4,2.04],[1,7,2.27],[2,1000,0.02]],"ltp":3.6,"tv":1410.45,"id":2397396},{"batb":[[1,1.34,496.01],[2,1.3,57.88]],"batl":[[1,1.5,2.27],[2,1.66,579.81]],"ltp":1.38,"tv":12662.06,"id":8979329}]}]}
{"op":"mcm","clk":"1009048353","pt":1580641697846,"mc":[{"id":"1.168224328","rc":[{"batb":[[1,2,93.77]],"batl":[[0,3.95,2.1],[1,4.2,2.03],[2,7,2.27]],"ltp":3.6,"tv":1410.45,"id":2397396},{"batb":[[1,1.34,549.23],[2,1.32,52.39]],"ltp":1.38,"tv":12662.06,"id":8979329}]}]}
{"op":"mcm","clk":"1009048718","pt":1580641700356,"mc":[{"id":"1.168224328","rc":[{"trd":[[1.38,4322.16]],"batb":[[0,1.37,386],[1,1.36,94.1],[2,1.34,549.23]],"batl":[[0,1.38,2901.74],[1,1.42,443.21],[2,1.43,309.2]],"ltp":1.38,"tv":13594.24,"id":8979329}],"tv":15004.69}]}
{"op":"mcm","clk":"1009048840","pt":1580641701270,"mc":[{"id":"1.168224328","rc":[{"batl":[[1,1.42,322.07],[2,1.5,2.27]],"ltp":1.38,"tv":13594.24,"id":8979329}]}]}
{"op":"mcm","clk":"1009049086","pt":1580641702740,"mc":[{"id":"1.168224328","rc":[{"batb":[[0,1.36,94.1],[1,1.34,549.23],[2,1.32,52.39]],"batl":[[1,1.5,2.27],[2,1.66,579.81]],"ltp":1.38,"tv":13594.24,"id":8979329}]}]}
{"op":"mcm","clk":"1009049310","pt":1580641704265,"mc":[{"id":"1.168224328","rc":[{"trd":[[1.38,4345.66]],"batl":[[0,1.38,2889.99]],"ltp":1.38,"tv":13617.74,"id":8979329}],"tv":15028.2}]}
{"op":"mcm","clk":"1009049540","pt":1580641705758,"mc":[{"id":"1.168224328","rc":[{"batb":[[0,1.34,549.23],[1,1.33,647.23],[2,1.32,522.82]],"batl":[[1,1.46,306.03],[2,1.47,279]],"ltp":1.38,"tv":13617.74,"id":8979329}]}]}
{"op":"mcm","clk":"1009050008","pt":1580641708864,"mc":[{"id":"1.168224328","rc":[{"batl":[[0,1.37,78.68],[1,1.38,2889.99],[2,1.46,306.03]],"ltp":1.38,"tv":13617.74,"id":8979329}]}]}
{"op":"mcm","clk":"1009050572","pt":1580641712554,"mc":[{"id":"1.168224328","rc":[{"batl":[[2,1.5,2.27]],"ltp":1.38,"tv":13617.74,"id":8979329}]}]}
{"op":"mcm","clk":"1009050714","pt":1580641713577,"mc":[{"id":"1.168224328","rc":[{"batb":[[0,1.34,306.42]],"ltp":1.38,"tv":13617.74,"id":8979329}]}]}
{"op":"mcm","clk":"1009050981","pt":1580641715388,"mc":[{"id":"1.168224328","rc":[{"batl":[[1,4.1,421],[2,4.2,204.56]],"ltp":3.6,"tv":1410.45,"id":2397396},{"batb":[[0,1.34,2002.48]],"batl":[[0,1.36,14.74],[1,1.37,3989.38],[2,1.38,2889.99]],"ltp":1.38,"tv":13617.74,"id":8979329}]}]}
{"op":"mcm","clk":"1009051127","pt":1580641716380,"mc":[{"id":"1.168224328","rc":[{"batb":[[0,3.65,60.66],[1,3.55,2.6],[2,3.3,75.69]],"ltp":3.6,"tv":1410.45,"id":2397396},{"batl":[[1,1.37,2239.01],[2,1.38,3254.01]],"ltp":1.38,"tv":13617.74,"id":8979329}]}]}
{"op":"mcm","clk":"1009051232","pt":1580641717170,"mc":[{"id":"1.168224328","rc":[{"batb":[[2,3.5,16.8]],"batl":[[1,4,13.44],[2,4.1,421]],"ltp":3.6,"tv":1410.45,"id":2397396},{"batb":[[1,1.33,774.1]],"ltp":1.38,"tv":13617.74,"id":8979329}]}]}
{"op":"mcm","clk":"1009051342","pt":1580641717972,"mc":[{"id":"1.168224328","rc":[{"trd":[[1.34,541.73]],"batb":[[0,1.34,1978.26]],"ltp":1.34,"tv":13666.18,"id":8979329}],"tv":15076.63}]}
{"op":"mcm","clk":"1009051670","pt":1580641720095,"mc":[{"id":"1.168224328","rc":[{"trd":[[1.36,1372.5]],"batl":[[0,1.36,8.02]],"ltp":1.36,"tv":13679.62,"id":8979329}],"tv":15090.07}]}
{"op":"mcm","clk":"1009051994","pt":1580641722302,"mc":[{"id":"1.168224328","rc":[{"batl":[[2,1.38,3734.6]],"ltp":1.36,"tv":13679.62,"id":8979329}]}]}
{"op":"mcm","clk":"1009052126","pt":1580641723277,"mc":[{"id":"1.168224328","rc":[{"batb":[[1,3.6,2.49],[2,3.55,4.79]],"batl":[[2,4.1,423.05]],"ltp":3.6,"tv":1410.45,"id":2397396},{"batb":[[1,1.33,825.63]],"batl":[[2,1.38,3787.35]],"ltp":1.36,"tv":13679.62,"id":8979329}]}]}
{"op":"mcm","clk":"1009052363","pt":1580641724993,"mc":[{"id":"1.168224328","rc":[{"batb":[[1,1.33,919.73]],"ltp":1.36,"tv":13679.62,"id":8979329}]}]}
{"op":"mcm","clk":"1009053020","pt":1580641729381,"mc":[{"id":"1.168224328","rc":[{"batb":[[0,3.6,2.49],[1,3.55,4.79],[2,3.5,16.8]],"batl":[[0,4,13.44],[1,4.1,2.05],[2,4.2,2.03]],"ltp":3.6,"tv":1410.45,"id":2397396},{"batb":[[0,1.33,272.5],[1,1.32,52.39],[2,1.31,769.03]],"batl":[[0,1.37,78.68],[1,1.38,3423.33],[2,1.39,86.51]],"ltp":1.36,"tv":13679.62,"id":8979329}]}]}
{"op":"mcm","clk":"1009053131","pt":1580641730231,"mc":[{"id":"1.168224328","rc":[{"batb":[[2,3.3,75.3]],"batl":[[0,4.1,2.05],[1,4.2,2.03],[2,7,2.27]],"ltp":3.6,"tv":1410.45,"id":2397396},{"batb":[[0,1.33,145.63]],"batl":[[2,1.39,44.5]],"ltp":1.36,"tv":13679.62,"id":8979329}]}]}
{"op":"mcm","clk":"1009053175","pt":1580641730498,"mc":[{"id":"1.168224328","rc":[{"batl":[[0,4.2,2.03],[1,7,2.27],[2,1000,0.02]],"ltp":3.6,"tv":1410.45,"id":2397396},{"batb":[[0,1.33,94.1]],"ltp":1.36,"tv":13679.62,"id":8979329}]}]}
{"op":"mcm","clk":"1009053748","pt":1580641734290,"mc":[{"id":"1.168224328","rc":[{"batl":[[0,1.34,303.91],[1,1.37,78.68],[2,1.38,3423.33]],"ltp":1.36,"tv":13679.62,"id":8979329}]}]}
{"op":"mcm","clk":"1009053874","pt":1580641735077,"mc":[{"id":"1.168224328","rc":[{"trd":[[3.9,64.18]],"batb":[[0,3.75,10.19],[1,3.6,2.49],[2,3.55,4.79]],"ltp":3.9,"tv":1421.1,"id":2397396},{"trd":[[1.34,592.02]],"batl":[[0,1.34,263.28],[1,1.36,11.32],[2,1.37,78.68]],"ltp":1.34,"tv":13729.91,"id":8979329}],"tv":15151.01}]}
{"op":"mcm","clk":"1009054069","pt":1580641736381,"mc":[{"id":"1.168224328","rc":[{"batb":[[0,3.6,2.49],[1,3.55,4.79],[2,3.3,75.3]],"ltp":3.9,"tv":1421.1,"id":2397396},{"trd":[[1.34,1118.86]],"batb":[[0,1.34,317.61],[1,1.33,545.61],[2,1.32,52.39]],"batl":[[0,1.37,78.68],[1,1.38,3791.78],[2,1.39,44.5]],"ltp":1.34,"tv":14256.74,"id":8979329}],"tv":15677.85}]}
{"op":"mcm","clk":"1009054214","pt":1580641737392,"mc":[{"id":"1.168224328","rc":[{"batb":[[0,1.33,94.1],[1,1.32,52.39],[2,1.31,769.03]],"batl":[[1,1.38,3423.33]],"ltp":1.34,"tv":14256.74,"id":8979329}]}]}
{"op":"mcm","clk":"1009054733","pt":1580641740698,"mc":[{"id":"1.168224328","rc":[{"batb":[[2,1.31,1238.38]],"ltp":1.34,"tv":14256.74,"id":8979329}]}]}
{"op":"mcm","clk":"1009055074","pt":1580641742886,"mc":[{"id":"1.168224328","rc":[{"batb":[[2,1.31,744.34]],"ltp":1.34,"tv":14256.74,"id":8979329}]}]}
{"op":"mcm","clk":"1009055269","pt":1580641744207,"mc":[{"id":"1.168224328","rc":[{"batb":[[1,3.55,2.19]],"ltp":3.9,"tv":1421.1,"id":2397396},{"batb":[[0,1.32,52.39],[1,1.31,744.34],[2,1.3,509.31]],"ltp":1.34,"tv":14256.74,"id":8979329}]}]}
{"op":"mcm","clk":"1009055418","pt":1580641745321,"mc":[{"id":"1.168224328","rc":[{"batb":[[0,3.8,560.6],[1,3.6,2.49],[2,3.55,2.19]],"batl":[[1,4.3,400],[2,7,2.27]],"ltp":3.9,"tv":1421.1,"id":2397396},{"batl":[[0,1.35,5170.6],[1,1.36,1545.87],[2,1.37,1116.68]],"ltp":1.34,"tv":14256.74,"id":8979329}]}]}
{"op":"mcm","clk":"1009055455","pt":1580641745481,"mc":[{"id":"1.168224328","rc":[{"batb":[[0,3.8,56.06],[1,3.75,777.67],[2,3.6,2.49]],"batl":[[0,4.1,5.23],[1,4.2,2.03],[2,4.3,400]],"ltp":3.9,"tv":1421.1,"id":2397396},{"batl":[[0,1.34,411.2],[1,1.35,407.24],[2,1.36,154.59]],"ltp":1.34,"tv":14256.74,"id":8979329}]}]}
{"op":"mcm","clk":"1009055733","pt":1580641747111,"mc":[{"id":"1.168224328","rc":[{"batb":[[0,3.85,56.5],[1,3.8,56.06],[2,3.75,777.67]],"batl":[[1,4.2,14.63]],"ltp":3.9,"tv":1421.1,"id":2397396},{"batb":[[1,1.31,879.61],[2,1.3,802.56]],"ltp":1.34,"tv":14256.74,"id":8979329}]}]}
{"op":"mcm","clk":"1009056201","pt":1580641749699,"mc":[{"id":"1.168224328","rc":[{"batb":[[1,1.31,973.72]],"ltp":1.34,"tv":14256.74,"id":8979329}]}]}
{"op":"mcm","clk":"1009056505","pt":1580641751770,"mc":[{"id":"1.168224328","rc":[{"batl":[[2,1.36,635.18]],"ltp":1.34,"tv":14256.74,"id":8979329}]}]}
{"op":"mcm","clk":"1009056705","pt":1580641752901,"mc":[{"id":"1.168224328","rc":[{"batb":[[0,3.85,58.67],[2,3.75,779.94]],"batl":[[2,4.3,402.05]],"ltp":3.9,"tv":1421.1,"id":2397396},{"batb":[[1,1.31,1026.51]],"batl":[[1,1.35,464.14],[2,1.36,680]],"ltp":1.34,"tv":14256.74,"id":8979329}]}]}
{"op":"mcm","clk":"1009057493","pt":1580641757392,"mc":[{"id":"1.168224328","rc":[{"batb":[[1,3.75,2.27],[2,3.65,15.12]],"batl":[[0,4.2,14.63],[1,4.3,2.05],[2,7,2.27]],"ltp":3.9,"tv":1421.1,"id":2397396},{"batl":[[0,1.34,398.07],[2,1.36,525.41]],"ltp":1.34,"tv":14256.74,"id":8979329}]}]}
{"op":"mcm","clk":"1009057604","pt":1580641758141,"mc":[{"id":"1.168224328","rc":[{"batb":[[0,3.85,2.6],[2,3.6,2.49]],"batl":[[0,4.3,2.05],[1,7,2.27],[2,1000,0.02]],"ltp":3.9,"tv":1421.1,"id":2397396},{"batb":[[0,1.31,146.89],[1,1.3,553.85],[2,1.29,494.03]],"batl":[[0,1.36,525.41],[1,1.37,78.68],[2,1.38,3440.14]],"ltp":1.34,"tv":14256.74,"id":8979329}]}]}
{"op":"mcm","clk":"1009058159","pt":1580641761319,"mc":[{"id":"1.168224328","rc":[{"batb":[[2,1.29,1021.46]],"batl":[[1,1.37,384.74],[2,1.38,3808.52]],"ltp":1.34,"tv":14256.74,"id":8979329}]}]}
{"op":"mcm","clk":"1009058603","pt":1580641764227,"mc":[{"id":"1.168224328","rc":[{"batl":[[0,4.2,2.03],[1,4.3,2.05],[2,7,2.27]],"ltp":3.9,"tv":1421.1,"id":2397396},{"batb":[[0,1.32,49.89],[1,1.31,146.89],[2,1.3,553.85]],"batl":[[1,1.37,78.68],[2,1.38,3440.14]],"ltp":1.34,"tv":14256.74,"id":8979329}]}]}
{"op":"mcm","clk":"1009058793","pt":1580641765343,"mc":[{"id":"1.168224328","rc":[{"batl":[[0,4.3,2.05],[1,7,2.27],[2,1000,0.02]],"ltp":3.9,"tv":1421.1,"id":2397396},{"batb":[[0,1.31,52.79],[1,1.3,553.85],[2,1.29,527.43]],"ltp":1.34,"tv":14256.74,"id":8979329}]}]}
{"op":"mcm","clk":"1009058963","pt":1580641766357,"mc":[{"id":"1.168224328","rc":[{"batb":[[0,4.2,170.44],[1,4.1,4.08],[2,3.85,52.92]],"batl":[[0,4.3,8.96],[1,4.4,296],[2,4.7,327.4]],"ltp":3.9,"tv":1421.1,"id":2397396},{"batl":[[0,1.35,1023.71],[1,1.36,525.41],[2,1.37,78.68]],"ltp":1.34,"tv":14256.74,"id":8979329}]}]}
{"op":"mcm","clk":"1009059099","pt":1580641767211,"mc":[{"id":"1.168224328","rc":[{"batb":[[2,3.9,100.4]],"batl":[[1,4.4,307.76]],"ltp":3.9,"tv":1421.1,"id":2397396},{"batb":[[2,1.29,977.23]],"batl":[[0,1.33,640.81],[1,1.34,418.55],[2,1.35,1023.71]],"ltp":1.34,"tv":14256.74,"id":8979329}]}]}
{"op":"mcm","clk":"1009059559","pt":1580641770131,"mc":[{"id":"1.168224328","rc":[{"trd":[[1.31,264.53]],"batb":[[0,1.3,554.01],[1,1.29,977.23],[2,1.18,549.82]],"ltp":1.31,"tv":14362.0,"id":8979329}],"tv":15783.11}]}
{"op":"mcm","clk":"1009059748","pt":1580641771242,"mc":[{"id":"1.168224328","rc":[{"batb":[[2,1.28,215.09]],"ltp":1.31,"tv":14362.0,"id":8979329}]}]}
{"op":"mcm","clk":"1009060076","pt":1580641773370,"mc":[{"id":"1.168224328","rc":[{"batb":[[2,4,3.29]],"batl":[[1,4.4,309.76]],"ltp":3.9,"tv":1421.1,"id":2397396},{"batb":[[0,1.3,616.49],[2,1.28,709.12]],"batl":[[0,1.33,694.31],[1,1.34,469.3],[2,1.35,1504.3]],"ltp":1.31,"tv":14362.0,"id":8979329}]}]}
{"op":"mcm","clk":"1009060339","pt":1580641774927,"mc":[{"id":"1.168224328","rc":[{"batl":[[2,4.5,2.01]],"ltp":3.9,"tv":1421.1,"id":2397396},{"batb":[[1,1.29,1039.04]],"batl":[[1,1.34,693.63]],"ltp":1.31,"tv":14362.0,"id":8979329}]}]}
{"op":"mcm","clk":"1009060808","pt":1580641778181,"mc":[{"id":"1.168224328","rc":[{"batb":[[0,3.9,3.26],[1,3.75,59.08],[2,3.6,2.49]],"batl":[[0,4.5,2.01],[1,7,2.27],[2,1000,0.02]],"ltp":3.9,"tv":1421.1,"id":2397396},{"batb":[[0,1.29,693.23],[1,1.28,709.12],[2,1.26,510.84]],"batl":[[0,1.34,275.08],[1,1.35,480.59],[2,1.36,44.82]],"ltp":1.31,"tv":14362.0,"id":8979329}]}]}
{"op":"mcm","clk":"1009061277","pt":1580641781357,"mc":[{"id":"1.168224328","rc":[{"batb":[[0,4,3.2],[1,3.9,3.26],[2,3.75,59.08]],"batl":[[0,4.4,2.04],[1,4.5,2.01],[2,7,2.27]],"ltp":3.9,"tv":1421.1,"id":2397396},{"batb":[[0,1.3,54.78],[1,1.29,693.23],[2,1.28,1261.1]],"batl":[[0,1.33,51.5],[1,1.34,275.08],[2,1.35,1089.4]],"ltp":1.31,"tv":14362.0,"id":8979329}]}]}
{"op":"mcm","clk":"1009061310","pt":1580641781518,"mc":[{"id":"1.168224328","rc":[{"batb":[[0,3.9,3.26],[1,3.75,59.08],[2,3.6,2.49]],"batl":[[0,4.5,2.01],[1,7,2.27],[2,1000,0.02]],"ltp":3.9,"tv":1421.1,"id":2397396},{"batb":[[0,1.29,693.23],[1,1.28,1261.1],[2,1.26,510.84]],"batl":[[0,1.34,275.08],[1,1.35,1089.4],[2,1.36,435.05]],"ltp":1.31,"tv":14362.0,"id":8979329}]}]}
{"op":"mcm","clk":"1009061658","pt":1580641784163,"mc":[{"id":"1.168224328","rc":[{"batb":[[1,1.28,767.07],[2,1.18,549.82]],"batl":[[1,1.35,480.59],[2,1.36,44.82]],"ltp":1.31,"tv":14362.0,"id":8979329}]}]}
{"op":"mcm","clk":"1009061916","pt":1580641785757,"mc":[{"id":"1.168224328","rc":[{"batb":[[1,1.28,551.98]],"ltp":1.31,"tv":14362.0,"id":8979329}]}]}
{"op":"mcm","clk":"1009062150","pt":1580641787363,"mc":[{"id":"1.168224328","rc":[{"batb":[[0,4.3,205.76],[1,4.1,3.24],[2,4,13.44]],"batl":[[0,4.4,5.46],[1,4.5,272.01],[2,4.6,10.92]],"ltp":3.9,"tv":1421.1,"id":2397396},{"batb":[[1,1.28,701.53]],"batl":[[0,1.31,11.42],[1,1.32,661.55],[2,1.33,741.69]],"ltp":1.31,"tv":14362.0,"id":8979329}]}]}
{"op":"mcm","clk":"1009062270","pt":1580641788162,"mc":[{"id":"1.168224328","rc":[{"batb":[[2,4,108.33]],"ltp":3.9,"tv":1421.1,"id":2397396},{"batb":[[2,1.24,375.71]],"ltp":1.31,"tv":14362.0,"id":8979329}]}]}
{"op":"mcm","clk":"1009062426","pt":1580641789168,"mc":[{"id":"1.168224328","rc":[{"batl":[[2,4.8,271.84]],"ltp":3.9,"tv":1421.1,"id":2397396}]}]}
{"op":"mcm","clk":"1009062855","pt":1580641792164,"mc":[{"id":"1.168224328","rc":[{"batl":[[1,4.5,283.77]],"ltp":3.9,"tv":1421.1,"id":2397396},{"batl":[[1,1.32,885.88]],"ltp":1.31,"tv":14362.0,"id":8979329}]}]}
{"op":"mcm","clk":"1009063240","pt":1580641794971,"mc":[{"id":"1.168224328","rc":[{"batb":[[2,1.25,73.65]],"batl":[[1,1.32,661.55]],"ltp":1.31,"tv":14362.0,"id":8979329}]}]}
{"op":"mcm","clk":"1009063652","pt":1580641798000,"mc":[{"id":"1.168224328","rc":[{"trd":[[1.31,285.26]],"batl":[[0,1.31,1.05]],"ltp":1.31,"tv":14382.74,"id":8979329}],"tv":15803.84}]}
{"op":"mcm","clk":"1009063760","pt":1580641798749,"mc":[{"id":"1.168224328","rc":[{"trd":[[1.29,246]],"batb":[[0,1.29,593.23]],"batl":[[1,1.32,489.01],[2,1.33,307.23]],"ltp":1.29,"tv":14582.74,"id":8979329}],"tv":16003.84}]}
{"op":"mcm","clk":"1009063924","pt":1580641800070,"mc":[{"id":"1.168224328","rc":[{"trd":[[4.3,13.36]],"batb":[[0,4.3,203.52]],"ltp":4.3,"tv":1424.43,"id":2397396},{"trd":[[1.31,291.14]],"batb":[[2,1.26,242.82]],"batl":[[0,1.32,489.01],[1,1.33,307.23],[2,1.34,1023.76]],"ltp":1.31,"tv":14588.61,"id":8979329}],"tv":16013.05}]}
{"op":"mcm","clk":"1009064184","pt":1580641801787,"mc":[{"id":"1.168224328","rc":[{"batb":[[0,1.29,637.97]],"batl":[[0,1.31,228.26],[1,1.32,489.01],[2,1.33,307.23]],"ltp":1.31,"tv":14588.61,"id":8979329}]}]}
{"op":"mcm","clk":"1009064937","pt":1580641807104,"mc":[{"id":"1.168224328","rc":[{"trd":[[1.31,345.7]],"batl":[[0,1.32,489.01],[1,1.33,307.23],[2,1.34,1023.76]],"ltp":1.31,"tv":14643.17,"id":8979329}],"tv":16067.61}]}
{"op":"mcm","clk":"1009065107","pt":1580641808381,"mc":[{"id":"1.168224328","rc":[{"trd":[[4.3,13.72]],"batb":[[0,4,108.33],[1,3.9,3.26],[2,3.85,2.6]],"batl":[[0,4.5,11.76],[1,5,2],[2,5.4,2]],"ltp":4.3,"tv":1424.79,"id":2397396},{"trd":[[1.31,346.87]],"batb":[[0,1.29,576.16]],"batl":[[0,1.32,458.9],[1,1.34,92.76],[2,1.36,44.82]],"ltp":1.31,"tv":14644.34,"id":8979329}],"tv":16069.14}]}
{"op":"mcm","clk":"1009065194","pt":1580641808971,"mc":[{"id":"1.168224328","rc":[{"batb":[[0,4,13.44],[1,3.85,2.6],[2,3.8,55.08]],"ltp":4.3,"tv":1424.79,"id":2397396},{"batb":[[0,1.28,149.55],[1,1.26,242.82],[2,1.25,73.65]],"batl":[[0,1.34,42.01],[1,1.36,44.82],[2,1.37,78.68]],"ltp":1.31,"tv":14644.34,"id":8979329}]}]}
{"op":"mcm","clk":"1009065383","pt":1580641810192,"mc":[{"id":"1.168224328","rc":[{"batb":[[0,3.85,2.6],[1,3.8,55.08],[2,3.75,2.27]],"batl":[[0,5,2],[1,5.4,2],[2,7,2.27]],"ltp":4.3,"tv":1424.79,"id":2397396},{"batb":[[0,1.26,242.82],[1,1.25,73.65],[2,1.24,375.71]],"batl":[[0,1.36,44.82],[1,1.37,78.68],[2,1.38,2942.74]],"ltp":1.31,"tv":14644.34,"id":8979329}]}]}
{"op":"mcm","clk":"1009065565","pt":1580641811392,"mc":[{"id":"1.168224328","rc":[{"batb":[[2,1.24,1251.15]],"batl":[[0,1.35,519.81],[1,1.36,436.89],[2,1.37,78.68]],"ltp":1.31,"tv":14644.34,"id":8979329}]}]}
{"op":"mcm","clk":"1009065706","pt":1580641812299,"mc":[{"id":"1.168224328","rc":[{"batb":[[0,3.85,56.34],[1,3.75,2.27],[2,3.6,2.49]],"ltp":4.3,"tv":1424.79,"id":2397396},{"batb":[[2,1.24,375.71]],"ltp":1.31,"tv":14644.34,"id":8979329}]}]}
{"op":"mcm","clk":"1009065741","pt":1580641812470,"mc":[{"id":"1.168224328","rc":[{"batb":[[0,3.85,53.74]],"ltp":4.3,"tv":1424.79,"id":2397396}]}]}
{"op":"mcm","clk":"1009066160","pt":1580641815402,"mc":[{"id":"1.168224328","rc":[{"trd":[[4.4,1010.12]],"batb":[[0,3.85,57.28]],"batl":[[0,4,6.03],[1,4.2,333],[2,4.4,241.9]],"ltp":4.4,"tv":2411.55,"id":2397396},{"trd":[[1.29,7015.63]],"batb":[[0,1.32,292.52],[1,1.31,486.76],[2,1.26,242.82]],"batl":[[0,1.34,743.33],[1,1.35,2186.48],[2,1.36,436.89]],"ltp":1.29,"tv":21413.98,"id":8979329}],"tv":23825.54}]}
{"op":"mcm","clk":"1009066286","pt":1580641816096,"mc":[{"id":"1.168224328","rc":[{"batb":[[2,3.6,64.65]],"ltp":4.4,"tv":2411.55,"id":2397396},{"batb":[[1,1.31,763.01],[2,1.27,325.74]],"ltp":1.29,"tv":21413.98,"id":8979329}]}]}
{"op":"mcm","clk":"1009066462","pt":1580641817232,"mc":[{"id":"1.168224328","rc":[{"batb":[[1,3.75,17.39]],"batl":[[2,4.3,12.6]],"ltp":4.4,"tv":2411.55,"id":2397396},{"batb":[[2,1.3,139.47]],"ltp":1.29,"tv":21413.98,"id":8979329}]}]}
{"op":"mcm","clk":"1009066666","pt":1580641818402,"mc":[{"id":"1.168224328","rc":[{"batl":[[2,1.36,478.9]],"ltp":1.29,"tv":21413.98,"id":8979329}]}]}
{"op":"mcm","clk":"1009066696","pt":1580641818606,"mc":[{"id":"1.168224328","rc":[{"batl":[[2,1.36,436.89]],"ltp":1.29,"tv":21413.98,"id":8979329}]}]}
{"op":"mcm","clk":"1009067120","pt":1580641821798,"mc":[{"id":"1.168224328","rc":[{"batb":[[1,1.31,1257.05]],"ltp":1.29,"tv":21413.98,"id":8979329}]}]}
{"op":"mcm","clk":"1009067458","pt":1580641824193,"mc":[{"id":"1.168224328","rc":[{"batb":[[2,3.7,3.42]],"ltp":4.4,"tv":2411.55,"id":2397396},{"batb":[[2,1.3,404.4]],"ltp":1.29,"tv":21413.98,"id":8979329}]}]}
{"op":"mcm","clk":"1009067746","pt":1580641826309,"mc":[{"id":"1.168224328","rc":[{"batb":[[0,3.7,3.42],[1,3.6,64.65],[2,3.55,2.19]],"batl":[[0,4.4,2.04],[1,4.5,2],[2,5,2]],"ltp":4.4,"tv":2411.55,"id":2397396},{"batb":[[0,1.31,494.03],[1,1.3,264.93],[2,1.29,568.65]],"batl":[[0,1.37,609.77],[1,1.38,2942.74],[2,1.39,541.9]],"ltp":1.29,"tv":21413.98,"id":8979329}]}]}
{"op":"mcm","clk":"1009068192","pt":1580641829705,"mc":[{"id":"1.168224328","rc":[{"batb":[[2,1.29,614.65]],"ltp":1.29,"tv":21413.98,"id":8979329}]}]}
{"op":"mcm","clk":"1009068610","pt":1580641833189,"mc":[{"id":"1.168224328","rc":[{"batb":[[0,1.31,895.28],[1,1.3,773.8]],"batl":[[0,1.34,463.51],[1,1.35,406.92],[2,1.37,609.77]],"ltp":1.29,"tv":21413.98,"id":8979329}]}]}
{"op":"mcm","clk":"1009068763","pt":1580641834311,"mc":[{"id":"1.168224328","rc":[{"batb":[[1,1.3,567.95],[2,1.29,568.65]],"batl":[[2,1.36,222.65]],"ltp":1.29,"tv":21413.98,"id":8979329}]}]}
{"op":"mcm","clk":"1009068997","pt":1580641836006,"mc":[{"id":"1.168224328","rc":[{"batb":[[0,1.31,494.03],[1,1.3,59.08]],"batl":[[0,1.36,285.65],[1,1.37,609.77],[2,1.38,2942.74]],"ltp":1.29,"tv":21413.98,"id":8979329}]}]}
{"op":"mcm","clk":"1009069049","pt":1580641836434,"mc":[{"id":"1.168224328","rc":[{"batb":[[0,3.75,3.39],[1,3.7,3.42],[2,3.6,64.65]],"ltp":4.4,"tv":2411.55,"id":2397396},{"batl":[[0,1.36,338.72]],"ltp":1.29,"tv":21413.98,"id":8979329}]}]}
{"op":"mcm","clk":"1009069366","pt":1580641838856,"mc":[{"id":"1.168224328","rc":[{"batl":[[2,1.38,3458.82]],"ltp":1.29,"tv":21413.98,"id":8979329}]}]}
{"op":"mcm","clk":"1009069645","pt":1580641840618,"mc":[{"id":"1.168224328","rc":[{"batl":[[0,1.35,63],[1,1.36,338.72],[2,1.37,609.77]],"ltp":1.29,"tv":21413.98,"id":8979329}]}]}
{"op":"mcm","clk":"1009070532","pt":1580641847222,"mc":[{"id":"1.168224328","rc":[{"batl":[[0,4.5,2],[1,5,2],[2,5.4,2]],"ltp":4.4,"tv":2411.55,"id":2397396},{"trd":[[1.35,2457.52]],"batb":[[0,1.29,57.81],[1,1.28,400.45],[2,1.27,905.19]],"batl":[[0,1.35,62.9]],"ltp":1.35,"tv":21414.18,"id":8979329}],"tv":23825.73}]}
{"op":"mcm","clk":"1009070835","pt":1580641849322,"mc":[{"id":"1.168224328","rc":[{"trd":[[3.85,23.13]],"batb":[[0,4.4,254.35],[1,4.3,4.73],[2,4.1,3.44]],"batl":[[0,4.5,7.02],[1,4.7,327],[2,5,110.39]],"ltp":3.85,"tv":2417.29,"id":2397396},{"trd":[[1.35,2473.9]],"batb":[[1,1.28,2158.26]],"batl":[[0,1.31,2337.68],[1,1.32,483.72],[2,1.33,1140]],"ltp":1.35,"tv":21430.56,"id":8979329}],"tv":23847.86}]}
{"op":"mcm","clk":"1009070959","pt":1580641850223,"mc":[{"id":"1.168224328","rc":[{"batb":[[2,4.1,89.91]],"ltp":3.85,"tv":2417.29,"id":2397396}]}]}
{"op":"mcm","clk":"1009071068","pt":1580641851136,"mc":[{"id":"1.168224328","rc":[{"batl":[[1,4.6,10.92],[2,4.7,327]],"ltp":3.85,"tv":2417.29,"id":2397396},{"batb":[[2,1.27,1060.63]],"batl":[[2,1.33,1182.01]],"ltp":1.35,"tv":21430.56,"id":8979329}]}]}
{"op":"mcm","clk":"1009071130","pt":1580641851523,"mc":[{"id":"1.168224328","rc":[{"batl":[[1,4.7,327],[2,5,110.39]],"ltp":3.85,"tv":2417.29,"id":2397396}]}]}
{"op":"mcm","clk":"1009071410","pt":1580641853345,"mc":[{"id":"1.168224328","rc":[{"batl":[[1,4.7,337.92]],"ltp":3.85,"tv":2417.29,"id":2397396}]}]}
{"op":"mcm","clk":"1009071597","pt":1580641854756,"mc":[{"id":"1.168224328","rc":[{"batl":[[2,1.33,1378.62]],"ltp":1.35,"tv":21430.56,"id":8979329}]}]}
{"op":"mcm","clk":"1009071708","pt":1580641855562,"mc":[{"id":"1.168224328","rc":[{"trd":[[4.4,1015.18]],"batb":[[0,4.4,249.29]],"ltp":4.4,"tv":2422.35,"id":2397396},{"trd":[[1.3,854.41]],"batb":[[1,1.28,2660.7],[2,1.27,1579.87]],"batl":[[1,1.32,972.71],[2,1.33,1884.41]],"ltp":1.3,"tv":21447.67,"id":8979329}],"tv":23870.03}]}
{"op":"mcm","clk":"1009072297","pt":1580641859543,"mc":[{"id":"1.168224328","rc":[{"trd":[[4.4,1016.92]],"batb":[[0,4.4,248.42]],"ltp":4.4,"tv":2424.1,"id":2397396}],"tv":23871.77}]}
{"op":"mcm","clk":"1009072998","pt":1580641864373,"mc":[{"id":"1.168224328","rc":[{"batb":[[0,3.9,57.9],[1,3.75,3.39],[2,3.7,3.42]],"batl":[[0,4.7,10.92],[1,5.2,2],[2,5.4,2]],"ltp":4.4,"tv":2424.1,"id":2397396},{"batb":[[0,1.28,502.44],[1,1.27,674.68],[2,1.26,196.61]],"batl":[[0,1.32,488.99],[1,1.33,744.41],[2,1.34,52.25]],"ltp":1.3,"tv":21447.67,"id":8979329}]}]}
{"op":"mcm","clk":"1009073135","pt":1580641865380,"mc":[{"id":"1.168224328","rc":[{"batb":[[0,4.1,13.44],[1,3.9,57.9],[2,3.75,3.39]],"ltp":4.4,"tv":2424.1,"id":2397396},{"batb":[[0,1.3,1.35],[1,1.28,502.44],[2,1.27,674.68]],"ltp":1.3,"tv":21447.67,"id":8979329}]}]}
{"op":"mcm","clk":"1009073245","pt":1580641866281,"mc":[{"id":"1.168224328","rc":[{"batb":[[0,3.9,57.9],[1,3.75,3.39],[2,3.7,3.42]],"batl":[[0,5.2,2],[1,5.4,2],[2,5.6,2]],"ltp":4.4,"tv":2424.1,"id":2397396},{"batb":[[2,1.27,519.24]],"batl":[[1,1.33,702.4]],"ltp":1.3,"tv":21447.67,"id":8979329}]}]}
{"op":"mcm","clk":"1009073405","pt":1580641867362,"mc":[{"id":"1.168224328","rc":[{"batb":[[1,3.85,52.87],[2,3.75,3.39]],"ltp":4.4,"tv":2424.1,"id":2397396},{"batl":[[0,1.32,551.99]],"ltp":1.3,"tv":21447.67,"id":8979329}]}]}
{"op":"mcm","clk":"1009073437","pt":1580641867578,"mc":[{"id":"1.168224328","rc":[{"batb":[[0,3.9,5.73]],"ltp":4.4,"tv":2424.1,"id":2397396}]}]}
{"op":"mcm","clk":"1009073810","pt":1580641870195,"mc":[{"id":"1.168224328","rc":[{"trd":[[4.4,1017.32]],"batb":[[0,4.4,9.91],[1,3.9,5.73],[2,3.85,52.87]],"batl":[[0,4.6,11.41],[1,5.2,2],[2,5.4,2]],"ltp":4.4,"tv":2424.5,"id":2397396},{"trd":[[1.3,855.76]],"batb":[[0,1.28,502.44],[1,1.27,950.32],[2,1.26,607.19]],"batl":[[0,1.3,672.25],[1,1.31,469.34],[2,1.32,551.99]],"ltp":1.3,"tv":21449.02,"id":8979329}],"tv":23873.52}]}
{"op":"mcm","clk":"1009073850","pt":1580641870407,"mc":[{"id":"1.168224328","rc":[{"batb":[[0,3.9,5.73],[1,3.85,52.87],[2,3.75,3.39]],"batl":[[0,5.2,2],[1,5.4,2],[2,5.6,2]],"ltp":4.4,"tv":2424.5,"id":2397396},{"batb":[[1,1.27,940.08]],"batl":[[0,1.3,661]],"ltp":1.3,"tv":21449.02,"id":8979329}]}]}
{"op":"mcm","clk":"1009074189","pt":1580641872600,"mc":[{"id":"1.168224328","rc":[{"batb":[[1,1.27,519.24],[2,1.24,75.77]],"batl":[[0,1.32,551.99],[1,1.33,505.8],[2,1.34,52.25]],"ltp":1.3,"tv":21449.02,"id":8979329}]}]}
{"op":"mcm","clk":"1009074486","pt":1580641874792,"mc":[{"id":"1.168224328","rc":[{"batl":[[0,1.31,1.68],[1,1.32,551.99],[2,1.33,505.8]],"ltp":1.3,"tv":21449.02,"id":8979329}]}]}
{"op":"mcm","clk":"1009074850","pt":1580641877291,"mc":[{"id":"1.168224328","rc":[{"batl":[[0,5.4,2],[1,5.6,2],[2,7,2.27]],"ltp":4.4,"tv":2424.5,"id":2397396},{"batb":[[0,1.23,696],[1,1.22,1237.94],[2,1.14,628.02]],"ltp":1.3,"tv":21449.02,"id":8979329}]}]}
{"op":"mcm","clk":"1009074944","pt":1580641877931,"mc":[{"id":"1.168224328","rc":[{"batb":[[2,1.1,643.85]],"ltp":1.3,"tv":21449.02,"id":8979329}]}]}
{"op":"mcm","clk":"1009075149","pt":1580641879405,"mc":[{"id":"1.168224328","rc":[{"batb":[[0,5.1,4.01],[1,4.8,781.25],[2,3.9,3.16]],"batl":[[1,5.5,253],[2,5.6,2]],"ltp":4.4,"tv":2424.5,"id":2397396},{"batb":[[0,1.23,713.88]],"batl":[[0,1.24,1009.06],[1,1.26,10866.31],[2,1.27,1093]],"ltp":1.3,"tv":21449.02,"id":8979329}]}]}
{"op":"mcm","clk":"1009075315","pt":1580641880308,"mc":[{"id":"1.168224328","rc":[{"batb":[[1,4.8,81.21]],"ltp":4.4,"tv":2424.5,"id":2397396},{"batb":[[2,1.1,75.92]],"batl":[[1,1.26,1280.3],[2,1.27,1645.58]],"ltp":1.3,"tv":21449.02,"id":8979329}]}]}
{"op":"mcm","clk":"1009075490","pt":1580641881182,"mc":[{"id":"1.168224328","rc":[{"batb":[[1,4.8,142.66],[2,4.5,11.76]],"batl":[[0,5.3,9.24],[1,5.4,2],[2,5.5,253]],"ltp":4.4,"tv":2424.5,"id":2397396},{"batb":[[0,1.23,881.92],[2,1.17,568.5]],"ltp":1.3,"tv":21449.02,"id":8979329}]}]}
{"op":"mcm","clk":"1009076281","pt":1580641886285,"mc":[{"id":"1.168224328","rc":[{"batb":[[1,1.22,1740.38],[2,1.21,519.24]],"batl":[[1,1.26,1769.29],[2,1.27,2151.38]],"ltp":1.3,"tv":21449.02,"id":8979329}]}]}
{"op":"mcm","clk":"1009077308","pt":1580641892911,"mc":[{"id":"1.168224328","rc":[{"trd":[[1.23,303.77]],"batb":[[0,1.23,777.92]],"ltp":1.23,"tv":21657.02,"id":8979329}],"tv":24081.52}]}
{"op":"mcm","clk":"1009077540","pt":1580641894403,"mc":[{"id":"1.168224328","rc":[{"batb":[[0,4.3,80.89],[1,4.2,2.62],[2,4.1,2.56]],"batl":[[0,7,4.27],[1,7.8,2],[2,1000,0.02]],"ltp":4.4,"tv":2424.5,"id":2397396},{"batb":[[0,1.24,1.35],[1,1.22,502.44]],"batl":[[0,1.26,488.99],[1,1.27,505.8],[2,1.28,112.59]],"ltp":1.23,"tv":21657.02,"id":8979329}]}]}
{"op":"mcm","clk":"1009078151","pt":1580641898323,"mc":[{"id":"1.168224328","rc":[{"batl":[[2,1.29,63]],"ltp":1.23,"tv":21657.02,"id":8979329}]}]}
{"op":"mcm","clk":"1009078283","pt":1580641899116,"mc":[{"id":"1.168224328","rc":[{"trd":[[1.24,2.7]],"batb":[[0,1.22,1080.04],[1,1.21,1308.85],[2,1.18,224.43]],"batl":[[0,1.24,281.52],[1,1.25,618.07],[2,1.26,488.99]],"ltp":1.24,"tv":21659.72,"id":8979329}],"tv":24084.22}]}
{"op":"mcm","clk":"1009078564","pt":1580641901019,"mc":[{"id":"1.168224328","rc":[{"batl":[[0,1.23,7.57],[1,1.24,281.52],[2,1.25,618.07]],"ltp":1.24,"tv":21659.72,"id":8979329}]}]}
{"op":"mcm","clk":"1009078753","pt":1580641902138,"mc":[{"id":"1.168224328","rc":[{"batb":[[0,1.22,502.44],[1,1.21,519.24]],"batl":[[1,1.26,488.99],[2,1.27,505.8]],"ltp":1.24,"tv":21659.72,"id":8979329}]}]}
{"op":"mcm","clk":"1009079230","pt":1580641905001,"mc":[{"id":"1.168224328","rc":[{"batb":[[2,1.18,805.97]],"ltp":1.24,"tv":21659.72,"id":8979329}]}]}
{"op":"mcm","clk":"1009079653","pt":1580641907228,"mc":[{"id":"1.168224328","rc":[{"batb":[[2,1.18,224.43]],"ltp":1.24,"tv":21659.72,"id":8979329}]}]}
{"op":"mcm","clk":"1009079800","pt":1580641907985,"mc":[{"id":"1.168224328","rc":[{"batb":[[2,3.9,3.16]],"ltp":4.4,"tv":2424.5,"id":2397396},{"batl":[[1,1.29,63],[2,1.3,555.47]],"ltp":1.24,"tv":21659.72,"id":8979329}]}]}
{"op":"mcm","clk":"1009080013","pt":1580641909349,"mc":[{"id":"1.168224328","rc":[{"batl":[[1,1.3,555.47],[2,1.31,524.08]],"ltp":1.24,"tv":21659.72,"id":8979329}]}]}
{"op":"mcm","clk":"1009080191","pt":1580641910244,"mc":[{"id":"1.168224328","rc":[{"trd":[[5.3,1.76]],"batl":[[0,4.7,5.53],[1,4.8,234],[2,5.3,302.68]],"ltp":5.3,"tv":2426.26,"id":2397396},{"trd":[[1.23,311.34]],"batb":[[0,1.27,2308.32],[1,1.26,610.12],[2,1.22,502.44]],"batl":[[0,1.28,873.97],[1,1.3,2286.24],[2,1.31,1316.08]],"ltp":1.23,"tv":21667.29,"id":8979329}],"tv":24093.56}]}
{"op":"mcm","clk":"1009080408","pt":1580641911365,"mc":[{"id":"1.168224328","rc":[{"batb":[[2,4.1,13.44]],"ltp":5.3,"tv":2426.26,"id":2397396},{"batb":[[1,1.26,950.58],[2,1.23,7.56]],"ltp":1.23,"tv":21667.29,"id":8979329}]}]}
{"op":"mcm","clk":"1009080434","pt":1580641911524,"mc":[{"id":"1.168224328","rc":[{"batb":[[2,1.22,502.44]],"ltp":1.23,"tv":21667.29,"id":8979329}]}]}
{"op":"mcm","clk":"1009080749","pt":1580641913393,"mc":[{"id":"1.168224328","rc":[{"batl":[[1,4.8,251.74]],"ltp":5.3,"tv":2426.26,"id":2397396},{"batb":[[1,1.26,1111.89]],"ltp":1.23,"tv":21667.29,"id":8979329}]}]}
{"op":"mcm","clk":"1009080844","pt":1580641913861,"mc":[{"id":"1.168224328","rc":[{"batl":[[1,4.8,244.92]],"ltp":5.3,"tv":2426.26,"id":2397396}]}]}
{"op":"mcm","clk":"1009081110","pt":1580641915242,"mc":[{"id":"1.168224328","rc":[{"batl":[[2,5.3,303.55]],"ltp":5.3,"tv":2426.26,"id":2397396},{"batb":[[2,1.22,745.25]],"ltp":1.23,"tv":21667.29,"id":8979329}]}]}
{"op":"mcm","clk":"1009081243","pt":1580641915936,"mc":[{"id":"1.168224328","rc":[{"batl":[[2,5.3,305.34]],"ltp":5.3,"tv":2426.26,"id":2397396},{"batb":[[2,1.22,242.82]],"ltp":1.23,"tv":21667.29,"id":8979329}]}]}
{"op":"mcm","clk":"1009081456","pt":1580641917160,"mc":[{"id":"1.168224328","rc":[{"batb":[[1,1.26,1614.33],[2,1.25,519.24]],"batl":[[1,1.3,2775.23],[2,1.31,1821.88]],"ltp":1.23,"tv":21667.29,"id":8979329}]}]}
{"op":"mcm","clk":"1009082379","pt":1580641922935,"mc":[{"id":"1.168224328","rc":[{"batl":[[2,5.3,308.18]],"ltp":5.3,"tv":2426.26,"id":2397396},{"batl":[[2,1.31,1849.16]],"ltp":1.23,"tv":21667.29,"id":8979329}]}]}
{"op":"mcm","clk":"1009082518","pt":1580641923948,"mc":[{"id":"1.168224328","rc":[{"trd":[[1.27,33.5]],"batb":[[0,1.27,2304.17]],"ltp":1.27,"tv":21675.59,"id":8979329}],"tv":24101.86}]}
{"op":"mcm","clk":"1009083165","pt":1580641928363,"mc":[{"id":"1.168224328","rc":[{"batb":[[0,3.9,55.4],[1,3.75,3.39],[2,3.7,3.42]],"batl":[[0,5.3,5.5],[1,6,2],[2,7,4.27]],"ltp":5.3,"tv":2426.26,"id":2397396},{"batb":[[0,1.26,502.44],[1,1.25,519.24],[2,1.24,94.1]],"batl":[[0,1.3,488.99],[1,1.31,533.08],[2,1.32,63]],"ltp":1.27,"tv":21675.59,"id":8979329}]}]}
{"op":"mcm","clk":"1009083330","pt":1580641929472,"mc":[{"id":"1.168224328","rc":[{"batb":[[2,1.22,242.82]],"ltp":1.27,"tv":21675.59,"id":8979329}]}]}
{"op":"mcm","clk":"1009083872","pt":1580641933194,"mc":[{"id":"1.168224328","rc":[{"batb":[[0,1.22,242.82],[1,1.21,704.71],[2,1.2,1406]],"ltp":1.27,"tv":21675.59,"id":8979329}]}]}
{"op":"mcm","clk":"1009084013","pt":1580641934156,"mc":[{"id":"1.168224328","rc":[{"batb":[[0,1.21,704.71],[1,1.2,1406],[2,1.17,112.97]],"ltp":1.27,"tv":21675.59,"id":8979329}]}]}
{"op":"mcm","clk":"1009084195","pt":1580641935372,"mc":[{"id":"1.168224328","rc":[{"trd":[[5.3,5.48]],"batl":[[0,6,226.43],[1,6.8,256.47]],"ltp":5.3,"tv":2429.98,"id":2397396},{"trd":[[1.23,327.38]],"batb":[[0,1.21,2564.21],[1,1.2,1423.17]],"batl":[[0,1.22,1411.14],[1,1.23,1829.27],[2,1.25,1604]],"ltp":1.23,"tv":21691.63,"id":8979329}],"tv":24121.62}]}
{"op":"mcm","clk":"1009084372","pt":1580641936390,"mc":[{"id":"1.168224328","rc":[{"batb":[[0,5.3,57.23],[1,4.4,77.34],[2,3.9,55.4]],"ltp":5.3,"tv":2429.98,"id":2397396},{"batl":[[1,1.23,1913.77],[2,1.24,881.56]],"ltp":1.23,"tv":21691.63,"id":8979329}]}]}
{"op":"mcm","clk":"1009084481","pt":1580641937178,"mc":[{"id":"1.168224328","rc":[{"batb":[[1,4.8,10.92],[2,4.4,77.34]],"batl":[[0,5.6,8.4],[1,6,226.43],[2,6.8,256.47]],"ltp":5.3,"tv":2429.98,"id":2397396},{"batb":[[0,1.21,2732.25]],"ltp":1.23,"tv":21691.63,"id":8979329}]}]}
{"op":"mcm","clk":"1009084600","pt":1580641937757,"mc":[{"id":"1.168224328","rc":[{"batb":[[2,4.5,2.54]],"batl":[[0,6,226.43],[1,6.8,256.47],[2,7,4.27]],"ltp":5.3,"tv":2429.98,"id":2397396}]}]}
{"op":"mcm","clk":"1009084995","pt":1580641940307,"mc":[{"id":"1.168224328","rc":[{"batl":[[0,5.7,8.4],[1,6,226.43],[2,6.8,256.47]],"ltp":5.3,"tv":2429.98,"id":2397396},{"trd":[[1.21,200]],"batb":[[0,1.21,2632.25]],"batl":[[2,1.24,650.11]],"ltp":1.21,"tv":21891.63,"id":8979329}],"tv":24321.62}]}
{"op":"mcm","clk":"1009085297","pt":1580641942245,"mc":[{"id":"1.168224328","rc":[{"batb":[[2,1.18,502.44]],"batl":[[1,1.23,2402.76],[2,1.24,1155.91]],"ltp":1.21,"tv":21891.63,"id":8979329}]}]}
{"op":"mcm","clk":"1009085445","pt":1580641943257,"mc":[{"id":"1.168224328","rc":[{"batb":[[0,1.21,2683.11]],"batl":[[1,1.23,2684.38]],"ltp":1.21,"tv":21891.63,"id":8979329}]}]}
{"op":"mcm","clk":"1009086009","pt":1580641947092,"mc":[{"id":"1.168224328","rc":[{"trd":[[5.5,1.92]],"ltp":5.5,"tv":2431.76,"id":2397396},{"trd":[[1.22,8.68]],"batl":[[0,1.22,1403.11]],"ltp":1.22,"tv":21899.66,"id":8979329}],"tv":24331.43}]}
{"op":"mcm","clk":"1009086476","pt":1580641950271,"mc":[{"id":"1.168224328","rc":[{"trd":[[1.22,15.8]],"batl":[[0,1.22,1399.55]],"ltp":1.22,"tv":21906.79,"id":8979329}],"tv":24338.55}]}
{"op":"mcm","clk":"1009086760","pt":1580641952178,"mc":[{"id":"1.168224328","rc":[{"batb":[[0,4.5,2.54],[1,4.4,77.34],[2,4.3,5.38]],"batl":[[0,9.4,2],[1,12.5,2],[2,1000,0.02]],"ltp":5.5,"tv":2431.76,"id":2397396},{"batb":[[0,1.22,32.73],[1,1.18,502.54],[2,1.17,519.24]],"batl":[[0,1.23,488.99],[1,1.24,505.8],[2,1.29,63]],"ltp":1.22,"tv":21906.79,"id":8979329}]}]}
{"op":"mcm","clk":"1009087236","pt":1580641955180,"mc":[{"id":"1.168224328","rc":[{"batb":[[1,4.3,84.38],[2,4,5.36]],"ltp":5.5,"tv":2431.76,"id":2397396},{"batl":[[2,1.29,330.08]],"ltp":1.22,"tv":21906.79,"id":8979329}]}]}
{"op":"mcm","clk":"1009087561","pt":1580641957193,"mc":[{"id":"1.168224328","rc":[{"batl":[[2,1.29,63]],"ltp":1.22,"tv":21906.79,"id":8979329}]}]}
{"op":"mcm","clk":"1009087911","pt":1580641959378,"mc":[{"id":"1.168224328","rc":[{"batl":[[2,1.28,213.41]],"ltp":1.22,"tv":21906.79,"id":8979329}]}]}
{"op":"mcm","clk":"1009088071","pt":1580641960384,"mc":[{"id":"1.168224328","rc":[{"batb":[[0,5.7,11.52],[1,4.5,2.54],[2,4.3,84.38]],"batl":[[0,6.4,11.39],[1,9.4,2],[2,12.5,2]],"ltp":5.5,"tv":2431.76,"id":2397396},{"trd":[[1.22,90.87]],"batb":[[0,1.2,293.11],[1,1.19,880.03],[2,1.18,513.8]],"batl":[[0,1.22,665.58],[1,1.23,1161.12],[2,1.24,505.8]],"ltp":1.22,"tv":21981.86,"id":8979329}],"tv":24413.62}]}
{"op":"mcm","clk":"1009088117","pt":1580641960695,"mc":[{"id":"1.168224328","rc":[{"batb":[[0,4.5,2.54],[1,4.3,84.38],[2,4,5.36]],"batl":[[0,9.4,2],[1,12.5,2],[2,1000,0.02]],"ltp":5.5,"tv":2431.76,"id":2397396},{"batb":[[0,1.18,502.54],[1,1.17,519.24],[2,1.13,750.63]],"batl":[[0,1.23,488.99],[1,1.24,505.8],[2,1.28,213.41]],"ltp":1.22,"tv":21981.86,"id":8979329}]}]}
{"op":"mcm","clk":"1009088742","pt":1580641964680,"mc":[{"id":"1.168224328","rc":[{"batb":[[2,1.14,906.44]],"ltp":1.22,"tv":21981.86,"id":8979329}]}]}
{"op":"mcm","clk":"1009088950","pt":1580641966003,"mc":[{"id":"1.168224328","rc":[{"batb":[[0,4.3,84.38],[1,4,5.36],[2,3,75.72]],"ltp":5.5,"tv":2431.76,"id":2397396},{"batb":[[2,1.13,750.63]],"batl":[[0,1.28,213.41],[1,1.29,310.46],[2,1.3,554.45]],"ltp":1.22,"tv":21981.86,"id":8979329}]}]}
{"op":"mcm","clk":"1009089174","pt":1580641967314,"mc":[{"id":"1.168224328","rc":[{"batl":[[0,1.29,310.46],[1,1.3,554.45],[2,1.31,27.28]],"ltp":1.22,"tv":21981.86,"id":8979329}]}]}
{"op":"mcm","clk":"1009089504","pt":1580641969387,"mc":[{"id":"1.168224328","rc":[{"batb":[[0,4.5,5.03],[1,4.3,96.98],[2,4.2,12.6]],"batl":[[0,4.7,3.65],[1,4.9,235],[2,5.5,324.87]],"ltp":5.5,"tv":2431.76,"id":2397396},{"batb":[[0,1.27,335.16],[1,1.26,2392.13],[2,1.23,182.32]],"batl":[[0,1.28,1307.01],[1,1.29,2054.65],[2,1.3,596.46]],"ltp":1.22,"tv":21981.86,"id":8979329}]}]}
{"op":"mcm","clk":"1009089569","pt":1580641969811,"mc":[{"id":"1.168224328","rc":[{"batb":[[1,4.3,84.38]],"batl":[[1,4.9,245.08]],"ltp":5.5,"tv":2431.76,"id":2397396},{"batb":[[1,1.26,2900.04],[2,1.2,465.35]],"batl":[[2,1.3,554.45]],"ltp":1.22,"tv":21981.86,"id":8979329}]}]}
{"op":"mcm","clk":"1009089953","pt":1580641972118,"mc":[{"id":"1.168224328","rc":[{"batl":[[1,1.29,1991.65]],"ltp":1.22,"tv":21981.86,"id":8979329}]}]}
{"op":"mcm","clk":"1009090467","pt":1580641975121,"mc":[{"id":"1.168224328","rc":[{"batb":[[1,1.26,3402.48],[2,1.25,519.24]],"batl":[[2,1.3,1043.44]],"ltp":1.22,"tv":21981.86,"id":8979329}]}]}
{"op":"mcm","clk":"1009092399","pt":1580641987210,"mc":[{"id":"1.168224328","rc":[{"batb":[[0,4.3,84.38],[1,4.2,12.6],[2,4,5.36]],"batl":[[0,4.9,10.08],[1,6,2],[2,7,2]],"ltp":5.5,"tv":2431.76,"id":2397396},{"batl":[[0,1.29,1991.65],[1,1.3,1043.44],[2,1.31,575.09]],"ltp":1.22,"tv":21981.86,"id":8979329}]}]}
{"op":"mcm","clk":"1009092560","pt":1580641988223,"mc":[{"id":"1.168224328","rc":[{"batb":[[0,4,5.36],[1,3.9,52.09],[2,3.85,6.57]],"batl":[[0,6,2],[1,7,2],[2,9.4,2]],"ltp":5.5,"tv":2431.76,"id":2397396},{"batb":[[0,1.26,502.44],[1,1.25,519.24],[2,1.24,63]],"batl":[[0,1.27,1.78],[1,1.3,488.99],[2,1.31,533.08]],"ltp":1.22,"tv":21981.86,"id":8979329}]}]}
{"op":"mcm","clk":"1009092853","pt":1580641990035,"mc":[{"id":"1.168224328","rc":[{"batb":[[2,1.2,552.87]],"ltp":1.22,"tv":21981.86,"id":8979329}]}]}
{"op":"mcm","clk":"1009093019","pt":1580641991104,"mc":[{"id":"1.168224328","rc":[{"batb":[[2,1.21,492.27]],"batl":[[0,1.27,3.46]],"ltp":1.22,"tv":21981.86,"id":8979329}]}]}
{"op":"mcm","clk":"1009093267","pt":1580641992650,"mc":[{"id":"1.168224328","rc":[{"batl":[[0,1.27,1.78]],"ltp":1.22,"tv":21981.86,"id":8979329}]}]}
{"op":"mcm","clk":"1009094808","pt":1580642002877,"mc":[{"id":"1.168224328","rc":[{"trd":[[1.26,35.62]],"batb":[[0,1.26,500.76]],"ltp":1.26,"tv":21985.22,"id":8979329}],"tv":24416.98}]}
{"op":"mcm","clk":"1009096216","pt":1580642012342,"mc":[{"id":"1.168224328","rc":[{"batb":[[0,1.21,492.27],[1,1.2,1387.42],[2,1.17,104.97]],"ltp":1.26,"tv":21985.22,"id":8979329}]}]}
{"op":"mcm","clk":"1009096621","pt":1580642015261,"mc":[{"id":"1.168224328","rc":[{"batb":[[0,5.3,6.48],[1,4,5.36],[2,3.9,52.09]],"batl":[[0,6,7.34],[1,6.2,271],[2,7,2]],"ltp":5.5,"tv":2431.76,"id":2397396},{"trd":[[1.21,2444.38]],"batb":[[0,1.21,1229.58],[2,1.17,1236.16]],"batl":[[0,1.22,29.1],[1,1.23,2345.85],[2,1.24,1954.63]],"ltp":1.21,"tv":24229.6,"id":8979329}],"tv":26661.36}]}
{"op":"mcm","clk":"1009096779","pt":1580642016165,"mc":[{"id":"1.168224328","rc":[{"batb":[[0,5.3,57.47],[1,4.4,76.95],[2,4,5.36]],"ltp":5.5,"tv":2431.76,"id":2397396}]}]}
{"op":"mcm","clk":"1009096945","pt":1580642017271,"mc":[{"id":"1.168224328","rc":[{"batb":[[1,4.9,10.08],[2,4.5,2.68]],"batl":[[0,5.8,8.4],[1,6,7.34],[2,6.2,271]],"ltp":5.5,"tv":2431.76,"id":2397396},{"batb":[[0,1.21,1397.62]],"ltp":1.21,"tv":24229.6,"id":8979329}]}]}
{"op":"mcm","clk":"1009097287","pt":1580642019346,"mc":[{"id":"1.168224328","rc":[{"batb":[[1,1.2,1609.7],[2,1.19,558.99]],"batl":[[1,1.23,2613.53]],"ltp":1.21,"tv":24229.6,"id":8979329}]}]}
{"op":"mcm","clk":"1009097709","pt":1580642022066,"mc":[{"id":"1.168224328","rc":[{"batb":[[2,4.5,8.04]],"ltp":5.5,"tv":2431.76,"id":2397396}]}]}
{"op":"mcm","clk":"1009097901","pt":1580642023341,"mc":[{"id":"1.168224328","rc":[{"trd":[[1.21,2447.88]],"batb":[[0,1.21,1395.87]],"ltp":1.21,"tv":24233.09,"id":8979329}],"tv":26664.86}]}
{"op":"mcm","clk":"1009098252","pt":1580642025683,"mc":[{"id":"1.168224328","rc":[{"trd":[[1.21,2449]],"batb":[[0,1.21,1395.31]],"ltp":1.21,"tv":24234.22,"id":8979329}],"tv":26665.99}]}
{"op":"mcm","clk":"1009098366","pt":1580642026482,"mc":[{"id":"1.168224328","rc":[{"trd":[[1.22,94.29]],"batl":[[0,1.22,27.39]],"ltp":1.22,"tv":24237.63,"id":8979329}],"tv":26669.4}]}
{"op":"mcm","clk":"1009099155","pt":1580642031587,"mc":[{"id":"1.168224328","rc":[{"trd":[[5.5,3.7]],"ltp":5.5,"tv":2433.54,"id":2397396},{"trd":[[1.22,102.32]],"batl":[[0,1.22,19.36]],"ltp":1.22,"tv":24245.66,"id":8979329}],"tv":26679.21}]}
{"op":"mcm","clk":"1009099345","pt":1580642032657,"mc":[{"id":"1.168224328","rc":[{"trd":[[1.22,107.66]],"batl":[[0,1.22,16.69]],"ltp":1.22,"tv":24251.01,"id":8979329}],"tv":26684.55}]}
{"op":"mcm","clk":"1009099940","pt":1580642036402,"mc":[{"id":"1.168224328","rc":[{"batb":[[0,4.5,8.04],[1,4.4,76.95],[2,4.3,5.38]],"batl":[[0,9.4,2],[1,12.5,2],[2,1000,0.02]],"ltp":5.5,"tv":2433.54,"id":2397396},{"batb":[[0,1.13,242.92],[1,1.12,910.28],[2,1.11,684.32]],"batl":[[0,1.27,1.78],[1,1.28,130.84],[2,1.3,55.55]],"ltp":1.22,"tv":24251.01,"id":8979329}]}]}
