{"op":"mcm","clk":"1009100107","pt":1580642037368,"mc":[{"id":"1.168224328","rc":[{"batb":[[0,4.5,2.68]],"ltp":5.5,"tv":2433.54,"id":2397396},{"batl":[[0,1.21,15.14],[1,1.27,1.78],[2,1.28,63]],"ltp":1.22,"tv":24251.01,"id":8979329}]}]}
{"op":"mcm","clk":"1009100392","pt":1580642039370,"mc":[{"id":"1.168224328","rc":[{"batb":[[1,4.3,83.43],[2,4,5.36]],"ltp":5.5,"tv":2433.54,"id":2397396},{"batb":[[0,1.14,455.25],[1,1.13,2257.9],[2,1.12,141.79]],"ltp":1.22,"tv":24251.01,"id":8979329}]}]}
{"op":"mcm","clk":"1009100469","pt":1580642039893,"mc":[{"id":"1.168224328","rc":[{"batb":[[0,4.5,8.04]],"ltp":5.5,"tv":2433.54,"id":2397396},{"batl":[[2,1.28,132.84]],"ltp":1.22,"tv":24251.01,"id":8979329}]}]}
{"op":"mcm","clk":"1009101146","pt":1580642043803,"mc":[{"id":"1.168224328","rc":[{"batl":[[1,1.27,252.16]],"ltp":1.22,"tv":24251.01,"id":8979329}]}]}
{"op":"mcm","clk":"1009101396","pt":1580642045292,"mc":[{"id":"1.168224328","rc":[{"batb":[[0,1.15,250.48],[1,1.14,455.15],[2,1.13,2257.9]],"ltp":1.22,"tv":24251.01,"id":8979329}]}]}
{"op":"mcm","clk":"1009101431","pt":1580642045505,"mc":[{"id":"1.168224328","rc":[{"batb":[[0,4.5,5.36]],"ltp":5.5,"tv":2433.54,"id":2397396},{"batb":[[0,1.15,313.48]],"ltp":1.22,"tv":24251.01,"id":8979329}]}]}
{"op":"mcm","clk":"1009103557","pt":1580642058221,"mc":[{"id":"1.168224328","rc":[{"batb":[[0,4.3,83.43],[1,4,5.36],[2,3.85,6.57]],"ltp":5.5,"tv":2433.54,"id":2397396},{"batb":[[1,1.13,1006.11],[2,1.12,141.79]],"batl":[[2,1.28,63]],"ltp":1.22,"tv":24251.01,"id":8979329}]}]}
{"op":"mcm","clk":"1009103758","pt":1580642059700,"mc":[{"id":"1.168224328","rc":[{"batl":[[1,1.27,1.78],[2,1.29,661.85]],"ltp":1.22,"tv":24251.01,"id":8979329}]}]}
{"op":"mcm","clk":"1009104028","pt":1580642061395,"mc":[{"id":"1.168224328","rc":[{"trd":[[5.7,3.21]],"batb":[[0,4.3,96.04]],"batl":[[0,4.8,6.1],[1,5,234],[2,5.3,255.23]],"ltp":5.7,"tv":2436.75,"id":2397396},{"trd":[[1.21,2464.15]],"batb":[[0,1.26,2296.59],[1,1.25,646.22],[2,1.21,30.19]],"batl":[[0,1.27,1.78],[1,1.28,766.45],[2,1.29,2406.04]],"ltp":1.21,"tv":24266.15,"id":8979329}],"tv":26702.91}]}
{"op":"mcm","clk":"1009104136","pt":1580642061981,"mc":[{"id":"1.168224328","rc":[{"batb":[[2,3.9,101.26]],"ltp":5.7,"tv":2436.75,"id":2397396},{"batb":[[0,1.26,2646.1],[2,1.2,475.97]],"ltp":1.21,"tv":24266.15,"id":8979329}]}]}
{"op":"mcm","clk":"1009104517","pt":1580642064320,"mc":[{"id":"1.168224328","rc":[{"batl":[[1,5,244.08]],"ltp":5.7,"tv":2436.75,"id":2397396},{"batb":[[1,1.25,814.26]],"ltp":1.21,"tv":24266.15,"id":8979329}]}]}
{"op":"mcm","clk":"1009105199","pt":1580642068511,"mc":[{"id":"1.168224328","rc":[{"batb":[[1,4.1,6.34],[2,4,5.36]],"ltp":5.7,"tv":2436.75,"id":2397396}]}]}
{"op":"mcm","clk":"1009105707","pt":1580642071906,"mc":[{"id":"1.168224328","rc":[{"batb":[[2,1.21,15.14]],"ltp":1.21,"tv":24266.15,"id":8979329}]}]}
{"op":"mcm","clk":"1009105896","pt":1580642073130,"mc":[{"id":"1.168224328","rc":[{"batb":[[2,1.21,78.14]],"ltp":1.21,"tv":24266.15,"id":8979329}]}]}
{"op":"mcm","clk":"1009106411","pt":1580642076330,"mc":[{"id":"1.168224328","rc":[{"trd":[[1.26,49.87]],"batb":[[0,1.26,2638.98]],"ltp":1.26,"tv":24280.4,"id":8979329}],"tv":26717.15}]}
{"op":"mcm","clk":"1009106748","pt":1580642078351,"mc":[{"id":"1.168224328","rc":[{"batb":[[0,4.3,90.66]],"batl":[[0,5,10.08],[1,6.4,2],[2,7.4,2]],"ltp":5.7,"tv":2436.75,"id":2397396},{"batb":[[0,1.26,2128.1],[1,1.25,168.04]],"batl":[[1,1.29,1744.19],[2,1.31,69.29]],"ltp":1.26,"tv":24280.4,"id":8979329}]}]}
{"op":"mcm","clk":"1009106888","pt":1580642079155,"mc":[{"id":"1.168224328","rc":[{"batb":[[0,4.3,12.6]],"ltp":5.7,"tv":2436.75,"id":2397396},{"batb":[[0,1.25,168.04],[1,1.21,63],[2,1.2,475.97]],"batl":[[1,1.31,69.29],[2,1.32,58.86]],"ltp":1.26,"tv":24280.4,"id":8979329}]}]}
{"op":"mcm","clk":"1009107095","pt":1580642080332,"mc":[{"id":"1.168224328","rc":[{"batb":[[0,4.1,6.34],[1,4,5.36],[2,3.9,107.52]],"batl":[[0,6.4,2],[1,7.4,2],[2,9.4,2]],"ltp":5.7,"tv":2436.75,"id":2397396},{"batb":[[0,1.21,63],[1,1.2,475.97],[2,1.19,81.71]],"batl":[[1,1.31,27.28]],"ltp":1.26,"tv":24280.4,"id":8979329}]}]}
{"op":"mcm","clk":"1009107249","pt":1580642081323,"mc":[{"id":"1.168224328","rc":[{"batb":[[0,3.9,107.52],[1,3.85,6.57],[2,3.8,2.61]],"ltp":5.7,"tv":2436.75,"id":2397396},{"batb":[[1,1.2,1348.85],[2,1.19,826.2]],"batl":[[2,1.33,272.28]],"ltp":1.26,"tv":24280.4,"id":8979329}]}]}
{"op":"mcm","clk":"1009107389","pt":1580642082232,"mc":[{"id":"1.168224328","rc":[{"batb":[[1,1.2,475.97],[2,1.19,81.71]],"ltp":1.26,"tv":24280.4,"id":8979329}]}]}
{"op":"mcm","clk":"1009107569","pt":1580642083147,"mc":[{"id":"1.168224328","rc":[{"batb":[[2,2.6,75.72]],"ltp":5.7,"tv":2436.75,"id":2397396}]}]}
{"op":"mcm","clk":"1009107851","pt":1580642085148,"mc":[{"id":"1.168224328","rc":[{"trd":[[4.2,35.96]],"batb":[[0,4.1,207.53],[1,3.9,107.52],[2,3.85,6.57]],"batl":[[0,4.5,501.58],[1,4.7,352.26],[2,6.4,2]],"ltp":4.2,"tv":2440.87,"id":2397396},{"trd":[[1.27,37.06],[1.31,360.08]],"batb":[[0,1.3,2404.75],[1,1.29,541.46],[2,1.21,63]],"batl":[[0,1.31,14.07],[1,1.33,1980.09],[2,1.34,1197.97]],"ltp":1.31,"tv":24297.16,"id":8979329}],"tv":26738.04}]}
{"op":"mcm","clk":"1009108011","pt":1580642086159,"mc":[{"id":"1.168224328","rc":[{"batl":[[0,4.5,341]],"ltp":4.2,"tv":2440.87,"id":2397396},{"batb":[[0,1.3,2696.35],[2,1.25,358.16]],"ltp":1.31,"tv":24297.16,"id":8979329}]}]}
{"op":"mcm","clk":"1009108194","pt":1580642087329,"mc":[{"id":"1.168224328","rc":[{"batb":[[1,3.9,121.81]],"ltp":4.2,"tv":2440.87,"id":2397396},{"batb":[[2,1.25,433.16]],"ltp":1.31,"tv":24297.16,"id":8979329}]}]}
{"op":"mcm","clk":"1009108364","pt":1580642088444,"mc":[{"id":"1.168224328","rc":[{"batl":[[0,4.5,352.76]],"ltp":4.2,"tv":2440.87,"id":2397396},{"batb":[[1,1.29,685.97]],"ltp":1.31,"tv":24297.16,"id":8979329}]}]}
{"op":"mcm","clk":"1009108864","pt":1580642091326,"mc":[{"id":"1.168224328","rc":[{"batb":[[2,1.26,241.14]],"ltp":1.31,"tv":24297.16,"id":8979329}]}]}
{"op":"mcm","clk":"1009108966","pt":1580642092069,"mc":[{"id":"1.168224328","rc":[{"batb":[[2,1.26,316.14]],"ltp":1.31,"tv":24297.16,"id":8979329}]}]}
{"op":"mcm","clk":"1009109385","pt":1580642094356,"mc":[{"id":"1.168224328","rc":[{"batl":[[2,4.9,2.02]],"ltp":4.2,"tv":2440.87,"id":2397396},{"batb":[[2,1.26,384.12]],"ltp":1.31,"tv":24297.16,"id":8979329}]}]}
{"op":"mcm","clk":"1009109526","pt":1580642095267,"mc":[{"id":"1.168224328","rc":[{"trd":[[1.31,388.23]],"batb":[[0,1.31,1.07],[1,1.3,2696.35],[2,1.29,685.97]],"batl":[[0,1.33,1964.01],[1,1.34,1197.97],[2,1.35,97.31]],"ltp":1.31,"tv":24325.31,"id":8979329}],"tv":26766.19}]}
{"op":"mcm","clk":"1009109942","pt":1580642098040,"mc":[{"id":"1.168224328","rc":[{"batl":[[0,4.3,5.21],[1,4.5,352.76],[2,4.7,352.26]],"ltp":4.2,"tv":2440.87,"id":2397396},{"trd":[[1.3,897.26],[1.31,390.36]],"batb":[[0,1.3,2675.6],[1,1.29,685.97],[2,1.26,384.12]],"batl":[[0,1.32,12.87],[1,1.33,1964.01],[2,1.34,1197.97]],"ltp":1.3,"tv":24368.95,"id":8979329}],"tv":26809.83}]}
{"op":"mcm","clk":"1009110250","pt":1580642099946,"mc":[{"id":"1.168224328","rc":[{"batb":[[2,1.27,71.87]],"ltp":1.3,"tv":24368.95,"id":8979329}]}]}
{"op":"mcm","clk":"1009110468","pt":1580642101250,"mc":[{"id":"1.168224328","rc":[{"batb":[[0,3.9,14.28],[1,3.85,6.57],[2,3.75,6.99]],"batl":[[0,4.5,11.76],[1,4.8,2],[2,5,2]],"ltp":4.2,"tv":2440.87,"id":2397396},{"batb":[[0,1.29,144.51],[1,1.27,71.87],[2,1.26,316.14]],"batl":[[0,1.35,97.31],[1,1.36,58.32],[2,1.37,78.68]],"ltp":1.3,"tv":24368.95,"id":8979329}]}]}
{"op":"mcm","clk":"1009110623","pt":1580642102262,"mc":[{"id":"1.168224328","rc":[{"batb":[[0,3.85,6.57],[1,3.75,6.99],[2,3.65,59.88]],"batl":[[0,4.8,2],[1,5,2],[2,1000,0.02]],"ltp":4.2,"tv":2440.87,"id":2397396},{"batb":[[0,1.27,71.87],[1,1.26,316.14],[2,1.25,507.45]],"batl":[[0,1.35,55.3]],"ltp":1.3,"tv":24368.95,"id":8979329}]}]}
{"op":"mcm","clk":"1009110658","pt":1580642102479,"mc":[{"id":"1.168224328","rc":[{"batl":[[0,5,2],[1,1000,0.02],[2,1000,0]],"ltp":4.2,"tv":2440.87,"id":2397396},{"batb":[[0,1.26,316.14],[1,1.25,507.45],[2,1.21,63]],"ltp":1.3,"tv":24368.95,"id":8979329}]}]}
{"op":"mcm","clk":"1009110912","pt":1580642104160,"mc":[{"id":"1.168224328","rc":[{"batb":[[0,1.26,640.24],[1,1.25,1149.46]],"batl":[[2,1.37,458.34]],"ltp":1.3,"tv":24368.95,"id":8979329}]}]}
{"op":"mcm","clk":"1009111376","pt":1580642107057,"mc":[{"id":"1.168224328","rc":[{"batl":[[0,4.1,7.87],[1,5,2],[2,1000,0.02]],"ltp":4.2,"tv":2440.87,"id":2397396}]}]}
{"op":"mcm","clk":"1009111547","pt":1580642107973,"mc":[{"id":"1.168224328","rc":[{"batl":[[2,1.37,78.68]],"ltp":1.3,"tv":24368.95,"id":8979329}]}]}
{"op":"mcm","clk":"1009111827","pt":1580642109369,"mc":[{"id":"1.168224328","rc":[{"trd":[[4.1,45.86]],"batl":[[0,4.1,7.78],[1,4.8,2.02],[2,5,2]],"ltp":4.1,"tv":2441.05,"id":2397396},{"batb":[[0,1.27,76.87],[1,1.26,399.1],[2,1.25,1149.46]],"batl":[[0,1.34,131.07],[1,1.35,55.3],[2,1.36,58.32]],"ltp":1.3,"tv":24368.95,"id":8979329}],"tv":26810.01}]}
{"op":"mcm","clk":"1009111844","pt":1580642109475,"mc":[{"id":"1.168224328","rc":[{"batl":[[1,5,2],[2,1000,0.02]],"ltp":4.1,"tv":2441.05,"id":2397396},{"batb":[[0,1.26,399.1],[1,1.25,1149.46],[2,1.21,63]],"ltp":1.3,"tv":24368.95,"id":8979329}]}]}
{"op":"mcm","clk":"1009112196","pt":1580642111362,"mc":[{"id":"1.168224328","rc":[{"trd":[[4.1,53.64]],"batb":[[0,4.5,8.38],[1,4.1,15.2],[2,3.85,6.57]],"batl":[[0,4.9,10.08],[1,5,7.37],[2,5.1,229]],"ltp":4.1,"tv":2448.83,"id":2397396},{"trd":[[1.32,1263.38]],"batb":[[0,1.26,2109.81],[1,1.25,1317.5],[2,1.23,799.04]],"batl":[[0,1.27,22.21],[1,1.28,391.35],[2,1.29,3139.27]],"ltp":1.32,"tv":24393.11,"id":8979329}],"tv":26841.95}]}
{"op":"mcm","clk":"1009112353","pt":1580642112381,"mc":[{"id":"1.168224328","rc":[{"batb":[[1,4.4,75.3],[2,3.95,97.33]],"batl":[[0,5,7.37],[1,5.1,229],[2,1000,0.02]],"ltp":4.1,"tv":2448.83,"id":2397396}]}]}
{"op":"mcm","clk":"1009112541","pt":1580642113397,"mc":[{"id":"1.168224328","rc":[{"batb":[[1,1.25,1242.5]],"ltp":1.32,"tv":24393.11,"id":8979329}]}]}
{"op":"mcm","clk":"1009112645","pt":1580642114052,"mc":[{"id":"1.168224328","rc":[{"batb":[[2,4.3,12.6]],"batl":[[0,5,17.45]],"ltp":4.1,"tv":2448.83,"id":2397396}]}]}
{"op":"mcm","clk":"1009113573","pt":1580642119493,"mc":[{"id":"1.168224328","rc":[{"batl":[[2,6.4,2]],"ltp":4.1,"tv":2448.83,"id":2397396}]}]}
{"op":"mcm","clk":"1009114377","pt":1580642124285,"mc":[{"id":"1.168224328","rc":[{"batl":[[1,1.28,313.51]],"ltp":1.32,"tv":24393.11,"id":8979329}]}]}
{"op":"mcm","clk":"1009114640","pt":1580642125879,"mc":[{"id":"1.168224328","rc":[{"trd":[[1.26,53.28],[1.27,43.06]],"batb":[[0,1.26,2108.1]],"batl":[[0,1.27,19.21]],"ltp":1.27,"tv":24402.53,"id":8979329}],"tv":26851.36}]}
{"op":"mcm","clk":"1009114893","pt":1580642127304,"mc":[{"id":"1.168224328","rc":[{"batb":[[0,4.4,75.3],[1,4.3,12.6],[2,4.2,6.27]],"batl":[[0,5,10.08],[1,6.4,2],[2,7.4,2]],"ltp":4.1,"tv":2448.83,"id":2397396},{"batb":[[2,1.21,296.57]],"batl":[[0,1.28,313.51],[1,1.29,2242.27],[2,1.3,45.57]],"ltp":1.27,"tv":24402.53,"id":8979329}]}]}
{"op":"mcm","clk":"1009115093","pt":1580642128276,"mc":[{"id":"1.168224328","rc":[{"batb":[[0,4,6.33],[1,3.95,97.33],[2,3.85,6.57]],"batl":[[0,6.4,2],[1,7.4,2],[2,1000,0.02]],"ltp":4.1,"tv":2448.83,"id":2397396},{"batb":[[0,1.21,296.57],[1,1.2,75.1],[2,1.19,566.46]],"batl":[[0,1.3,3.56],[1,1.32,195.77],[2,1.33,57.5]],"ltp":1.27,"tv":24402.53,"id":8979329}]}]}
{"op":"mcm","clk":"1009115445","pt":1580642130401,"mc":[{"id":"1.168224328","rc":[{"batb":[[1,1.2,748.97],[2,1.19,1468.19]],"batl":[[2,1.33,485.7]],"ltp":1.27,"tv":24402.53,"id":8979329}]}]}
{"op":"mcm","clk":"1009115576","pt":1580642131229,"mc":[{"id":"1.168224328","rc":[{"batb":[[0,4.2,6.27],[1,4,6.33],[2,3.95,97.33]],"ltp":4.1,"tv":2448.83,"id":2397396},{"batl":[[1,1.31,61.5],[2,1.32,195.77]],"ltp":1.27,"tv":24402.53,"id":8979329}]}]}
{"op":"mcm","clk":"1009115640","pt":1580642131521,"mc":[{"id":"1.168224328","rc":[{"batb":[[0,4,6.33],[1,3.95,97.33],[2,3.85,6.57]],"ltp":4.1,"tv":2448.83,"id":2397396},{"batl":[[1,1.32,195.77],[2,1.33,485.7]],"ltp":1.27,"tv":24402.53,"id":8979329}]}]}
{"op":"mcm","clk":"1009116484","pt":1580642136225,"mc":[{"id":"1.168224328","rc":[{"batb":[[1,1.2,75.1],[2,1.19,566.46]],"ltp":1.27,"tv":24402.53,"id":8979329}]}]}
{"op":"mcm","clk":"1009116654","pt":1580642137188,"mc":[{"id":"1.168224328","rc":[{"trd":[[4.1,59.38],[4.3,14.8]],"ltp":4.1,"tv":2455.65,"id":2397396},{"trd":[[1.3,900.83],[1.32,1281.23]],"batl":[[0,1.33,485.7],[1,1.34,427.44],[2,1.35,55.3]],"ltp":1.32,"tv":24423.94,"id":8979329}],"tv":26879.6}]}
{"op":"mcm","clk":"1009116851","pt":1580642138399,"mc":[{"id":"1.168224328","rc":[{"batb":[[0,4.2,6.27],[1,4,6.33],[2,3.95,97.33]],"ltp":4.1,"tv":2455.65,"id":2397396},{"batb":[[0,1.21,63]],"batl":[[0,1.31,62.5],[1,1.33,485.7],[2,1.34,427.44]],"ltp":1.32,"tv":24423.94,"id":8979329}]}]}
{"op":"mcm","clk":"1009117006","pt":1580642139308,"mc":[{"id":"1.168224328","rc":[{"batb":[[0,4,6.33],[1,3.95,110.77],[2,3.85,6.57]],"batl":[[0,4.5,11.76],[1,4.6,356],[2,5,276.72]],"ltp":4.1,"tv":2455.65,"id":2397396},{"batb":[[0,1.3,2239.01],[1,1.29,538.54],[2,1.28,149.55]],"batl":[[0,1.32,999.35],[1,1.33,2177.43],[2,1.34,1590.45]],"ltp":1.32,"tv":24423.94,"id":8979329}]}]}
{"op":"mcm","clk":"1009117125","pt":1580642140001,"mc":[{"id":"1.168224328","rc":[{"batb":[[1,1.29,838.24]],"ltp":1.32,"tv":24423.94,"id":8979329}]}]}
{"op":"mcm","clk":"1009117542","pt":1580642142310,"mc":[{"id":"1.168224328","rc":[{"batb":[[0,4.2,4.2],[1,4,6.33],[2,3.95,110.77]],"batl":[[0,4.4,5.92],[1,4.5,11.76],[2,4.6,356]],"ltp":4.1,"tv":2455.65,"id":2397396}]}]}
{"op":"mcm","clk":"1009117723","pt":1580642143292,"mc":[{"id":"1.168224328","rc":[{"trd":[[1.32,1316.69]],"batl":[[0,1.32,981.62]],"ltp":1.32,"tv":24459.4,"id":8979329}],"tv":26915.06}]}
{"op":"mcm","clk":"1009117898","pt":1580642144307,"mc":[{"id":"1.168224328","rc":[{"batb":[[2,1.28,224.55]],"ltp":1.32,"tv":24459.4,"id":8979329}]}]}
{"op":"mcm","clk":"1009118282","pt":1580642146502,"mc":[{"id":"1.168224328","rc":[{"batl":[[2,1.34,1653.2]],"ltp":1.32,"tv":24459.4,"id":8979329}]}]}
{"op":"mcm","clk":"1009119735","pt":1580642154321,"mc":[{"id":"1.168224328","rc":[{"batb":[[0,4,6.33],[1,3.95,110.77],[2,3.9,7.16]],"batl":[[0,4.5,11.76],[1,4.9,2],[2,5.2,2]],"ltp":4.1,"tv":2455.65,"id":2397396},{"batl":[[0,1.33,2177.43],[1,1.34,532.2],[2,1.35,298.12]],"ltp":1.32,"tv":24459.4,"id":8979329}]}]}
{"op":"mcm","clk":"1009119885","pt":1580642155227,"mc":[{"id":"1.168224328","rc":[{"batb":[[0,3.95,13.44],[1,3.85,6.57],[2,3.75,6.99]],"ltp":4.1,"tv":2455.65,"id":2397396},{"batb":[[0,1.28,224.55],[1,1.26,279.07],[2,1.24,443.61]],"batl":[[0,1.34,42.01],[1,1.35,298.12],[2,1.36,58.32]],"ltp":1.32,"tv":24459.4,"id":8979329}]}]}
{"op":"mcm","clk":"1009120084","pt":1580642156344,"mc":[{"id":"1.168224328","rc":[{"batb":[[0,3.85,6.57],[1,3.75,6.99],[2,3.7,58.15]],"batl":[[0,4.9,2],[1,5.2,2],[2,6.4,2]],"ltp":4.1,"tv":2455.65,"id":2397396},{"batb":[[0,1.28,75]],"batl":[[0,1.35,298.12],[1,1.36,58.32],[2,1.37,78.68]],"ltp":1.32,"tv":24459.4,"id":8979329}]}]}
{"op":"mcm","clk":"1009120361","pt":1580642158118,"mc":[{"id":"1.168224328","rc":[{"batb":[[2,3.7,65.37]],"ltp":4.1,"tv":2455.65,"id":2397396},{"batb":[[2,1.25,782.43]],"batl":[[2,1.37,653.46]],"ltp":1.32,"tv":24459.4,"id":8979329}]}]}
{"op":"mcm","clk":"1009120516","pt":1580642158913,"mc":[{"id":"1.168224328","rc":[{"batb":[[1,3.7,65.37],[2,2.6,75.72]],"batl":[[2,1000,0.02]],"ltp":4.1,"tv":2455.65,"id":2397396},{"batb":[[2,1.24,443.61]],"batl":[[0,1.3,5.34],[1,1.35,298.12]],"ltp":1.32,"tv":24459.4,"id":8979329}]}]}
{"op":"mcm","clk":"1009120823","pt":1580642160740,"mc":[{"id":"1.168224328","rc":[{"batl":[[1,1.35,55.3]],"ltp":1.32,"tv":24459.4,"id":8979329}]}]}
{"op":"mcm","clk":"1009121039","pt":1580642162018,"mc":[{"id":"1.168224328","rc":[{"trd":[[4.3,16.42]],"batb":[[2,3.35,2.6]],"batl":[[0,4.2,278],[1,4.3,211.16],[2,4.9,2]],"ltp":4.3,"tv":2457.27,"id":2397396},{"trd":[[1.3,906.17]],"batb":[[0,1.34,1902.04],[1,1.33,468.77],[2,1.28,75]],"batl":[[0,1.35,839.5],[1,1.37,3192.8],[2,1.38,3260.55]],"ltp":1.3,"tv":24464.75,"id":8979329}],"tv":26922.02}]}
{"op":"mcm","clk":"1009121285","pt":1580642163347,"mc":[{"id":"1.168224328","rc":[{"batb":[[2,3.6,15.96]],"ltp":4.3,"tv":2457.27,"id":2397396},{"batb":[[1,1.33,729.92],[2,1.3,294.35]],"ltp":1.3,"tv":24464.75,"id":8979329}]}]}
{"op":"mcm","clk":"1009121460","pt":1580642164323,"mc":[{"id":"1.168224328","rc":[{"batb":[[2,1.3,289.31]],"ltp":1.3,"tv":24464.75,"id":8979329}]}]}
{"op":"mcm","clk":"1009121551","pt":1580642164966,"mc":[{"id":"1.168224328","rc":[{"batl":[[0,4.1,13.44],[1,4.2,278],[2,4.3,211.16]],"ltp":4.3,"tv":2457.27,"id":2397396},{"batb":[[2,1.32,131.07]],"ltp":1.3,"tv":24464.75,"id":8979329}]}]}
{"op":"mcm","clk":"1009121652","pt":1580642165658,"mc":[{"id":"1.168224328","rc":[{"trd":[[1.35,2481.9]],"batl":[[0,1.35,835.5]],"ltp":1.35,"tv":24472.75,"id":8979329}],"tv":26930.02}]}
{"op":"mcm","clk":"1009122908","pt":1580642173247,"mc":[{"id":"1.168224328","rc":[{"trd":[[1.34,1128.5]],"batb":[[0,1.34,1897.22]],"ltp":1.34,"tv":24482.39,"id":8979329}],"tv":26939.67}]}
{"op":"mcm","clk":"1009122977","pt":1580642173668,"mc":[{"id":"1.168224328","rc":[{"trd":[[1.35,2482.13]],"batl":[[0,1.35,835.38]],"ltp":1.35,"tv":24482.63,"id":8979329}],"tv":26939.91}]}
{"op":"mcm","clk":"1009123172","pt":1580642174836,"mc":[{"id":"1.168224328","rc":[{"trd":[[1.34,1132.06]],"batb":[[0,1.34,1895.44],[2,1.32,373.89]],"ltp":1.34,"tv":24486.19,"id":8979329}],"tv":26943.47}]}
{"op":"mcm","clk":"1009124748","pt":1580642185073,"mc":[{"id":"1.168224328","rc":[{"trd":[[1.34,1165.66]],"batb":[[0,1.34,1878.64]],"ltp":1.34,"tv":24519.79,"id":8979329}],"tv":26977.07}]}
{"op":"mcm","clk":"1009125012","pt":1580642186873,"mc":[{"id":"1.168224328","rc":[{"trd":[[1.34,1172.79]],"batb":[[0,1.34,1875.08]],"ltp":1.34,"tv":24526.91,"id":8979329}],"tv":26984.19}]}
{"op":"mcm","clk":"1009125700","pt":1580642190912,"mc":[{"id":"1.168224328","rc":[{"trd":[[1.34,1704.79]],"batb":[[0,1.34,1609.08]],"ltp":1.34,"tv":25058.91,"id":8979329}],"tv":27516.19}]}
{"op":"mcm","clk":"1009126551","pt":1580642196403,"mc":[{"id":"1.168224328","rc":[{"trd":[[3.85,23.63]],"batb":[[0,3.85,6.32]],"ltp":3.85,"tv":2457.77,"id":2397396}],"tv":27516.69}]}
{"op":"mcm","clk":"1009128261","pt":1580642207796,"mc":[{"id":"1.168224328","rc":[{"batb":[[0,1.34,1386.14]],"ltp":1.34,"tv":25058.91,"id":8979329}]}]}
{"op":"mcm","clk":"1009128733","pt":1580642210818,"mc":[{"id":"1.168224328","rc":[{"batb":[[1,1.33,909.99],[2,1.32,852.55]],"batl":[[1,1.37,3236.26]],"ltp":1.34,"tv":25058.91,"id":8979329}]}]}
{"op":"mcm","clk":"1009128897","pt":1580642211821,"mc":[{"id":"1.168224328","rc":[{"trd":[[1.35,2482.76]],"batl":[[0,1.35,835.07]],"ltp":1.35,"tv":25059.54,"id":8979329}],"tv":27517.31}]}
{"op":"mcm","clk":"1009129340","pt":1580642214906,"mc":[{"id":"1.168224328","rc":[{"trd":[[3.85,40.08]],"batb":[[0,3.7,65.37],[1,3.6,15.96],[2,3.3,76.87]],"ltp":3.85,"tv":2474.22,"id":2397396},{"trd":[[1.35,2493.66]],"batl":[[0,1.35,824.17]],"ltp":1.35,"tv":25070.44,"id":8979329}],"tv":27544.66}]}
{"op":"mcm","clk":"1009133788","pt":1580642244363,"mc":[{"id":"1.168224328","rc":[{"batb":[[0,3.7,58.15]],"batl":[[1,4.9,2],[2,1000,0.02]],"ltp":3.85,"tv":2474.22,"id":2397396},{"batb":[[1,1.33,261.15],[2,1.32,373.89]],"batl":[[0,1.37,1721.02],[1,1.38,2889.99],[2,1.39,42.01]],"ltp":1.35,"tv":25070.44,"id":8979329}]}]}
{"op":"mcm","clk":"1009133860","pt":1580642244793,"mc":[{"id":"1.168224328","rc":[{"batb":[[0,3.3,76.87],[1,2.2,75.72],[2,2,75.72]],"batl":[[0,4.9,2],[1,1000,0.02],[2,1000,0]],"ltp":3.85,"tv":2474.22,"id":2397396},{"batb":[[0,1.32,242.82],[1,1.3,289.31],[2,1.26,63.98]],"batl":[[0,1.37,78.68],[2,1.43,205.85]],"ltp":1.35,"tv":25070.44,"id":8979329}]}]}
{"op":"mcm","clk":"1009134272","pt":1580642247354,"mc":[{"id":"1.168224328","rc":[{"batb":[[1,2.22,5.34],[2,2.2,75.72]],"batl":[[0,4.3,2.05],[1,4.5,2.01],[2,4.9,2]],"ltp":3.85,"tv":2474.22,"id":2397396},{"batb":[[1,1.31,56.79],[2,1.3,289.31]],"ltp":1.35,"tv":25070.44,"id":8979329}]}]}
{"op":"mcm","clk":"1009134446","pt":1580642248264,"mc":[{"id":"1.168224328","rc":[{"batl":[[2,1000,0.02]],"ltp":3.85,"tv":2474.22,"id":2397396}]}]}
{"op":"mcm","clk":"1009134664","pt":1580642249370,"mc":[{"id":"1.168224328","rc":[{"batb":[[0,1.35,253.04],[1,1.34,438.17],[2,1.32,242.82]],"batl":[[1,1.38,3341.82],[2,1.39,359.84]],"ltp":1.35,"tv":25070.44,"id":8979329}]}]}
{"op":"mcm","clk":"1009135413","pt":1580642253681,"mc":[{"id":"1.168224328","rc":[{"batb":[[0,1.32,242.82],[1,1.31,56.79],[2,1.3,289.31]],"batl":[[1,1.38,2889.99],[2,1.43,205.85]],"ltp":1.35,"tv":25070.44,"id":8979329}]}]}
{"op":"mcm","clk":"1009135899","pt":1580642256662,"mc":[{"id":"1.168224328","rc":[{"batb":[[1,1.31,320.02],[2,1.3,802.23]],"batl":[[2,1.43,532.43]],"ltp":1.35,"tv":25070.44,"id":8979329}]}]}
{"op":"mcm","clk":"1009136437","pt":1580642260231,"mc":[{"id":"1.168224328","rc":[{"batb":[[0,1.31,320.02],[1,1.3,802.23],[2,1.29,60.81]],"batl":[[0,1.35,5.05],[1,1.37,78.68],[2,1.38,2889.99]],"ltp":1.35,"tv":25070.44,"id":8979329}]}]}
{"op":"mcm","clk":"1009136760","pt":1580642262362,"mc":[{"id":"1.168224328","rc":[{"trd":[[3.85,41.85]],"batb":[[0,4,5.36],[1,3.3,76.87],[2,2.22,5.34]],"batl":[[0,4.3,6.76],[1,4.5,302.01]],"ltp":3.85,"tv":2475.99,"id":2397396},{"trd":[[1.35,2498.7],[1.37,1886.99]],"batb":[[0,1.31,2037.58]],"batl":[[0,1.32,727.51],[1,1.33,48.5],[2,1.34,2517.1]],"ltp":1.37,"tv":25080.53,"id":8979329}],"tv":27556.52}]}
{"op":"mcm","clk":"1009136891","pt":1580642263369,"mc":[{"id":"1.168224328","rc":[{"batb":[[1,3.9,102.37],[2,3.65,2.7]],"ltp":3.85,"tv":2475.99,"id":2397396},{"batl":[[2,1.34,3126.37]],"ltp":1.37,"tv":25080.53,"id":8979329}]}]}
{"op":"mcm","clk":"1009136907","pt":1580642263471,"mc":[{"id":"1.168224328","rc":[{"batb":[[2,3.75,15.12]],"batl":[[0,4.3,19.36]],"ltp":3.85,"tv":2475.99,"id":2397396},{"batb":[[1,1.3,941.71]],"ltp":1.37,"tv":25080.53,"id":8979329}]}]}
{"op":"mcm","clk":"1009137597","pt":1580642268073,"mc":[{"id":"1.168224328","rc":[{"batb":[[2,1.29,295.22]],"ltp":1.37,"tv":25080.53,"id":8979329}]}]}
{"op":"mcm","clk":"1009137711","pt":1580642268878,"mc":[{"id":"1.168224328","rc":[{"batl":[[2,1.34,3606.96]],"ltp":1.37,"tv":25080.53,"id":8979329}]}]}
{"op":"mcm","clk":"1009137850","pt":1580642269849,"mc":[{"id":"1.168224328","rc":[{"batb":[[2,3.85,4.97]],"batl":[[2,4.6,2.01]],"ltp":3.85,"tv":2475.99,"id":2397396},{"batb":[[1,1.3,1035.81]],"ltp":1.37,"tv":25080.53,"id":8979329}]}]}
{"op":"mcm","clk":"1009138316","pt":1580642273384,"mc":[{"id":"1.168224328","rc":[{"batl":[[0,4.3,14.65],[1,4.5,2.01]],"ltp":3.85,"tv":2475.99,"id":2397396},{"trd":[[1.31,560.36]],"batb":[[0,1.31,1717.56],[1,1.3,522.89]],"batl":[[0,1.33,48.5],[1,1.34,2159.69],[2,1.35,48.1]],"ltp":1.31,"tv":25250.53,"id":8979329}],"tv":27726.52}]}
{"op":"mcm","clk":"1009138394","pt":1580642273856,"mc":[{"id":"1.168224328","rc":[{"batb":[[1,3.85,4.97],[2,3.75,15.12]],"batl":[[0,4.3,12.6]],"ltp":3.85,"tv":2475.99,"id":2397396},{"batb":[[0,1.3,233.57],[1,1.29,295.22],[2,1.28,865.79]],"batl":[[1,1.34,480.59]],"ltp":1.31,"tv":25250.53,"id":8979329}]}]}
{"op":"mcm","clk":"1009138477","pt":1580642274498,"mc":[{"id":"1.168224328","rc":[{"batb":[[2,3.7,5.02]],"batl":[[0,4.5,2.01],[1,4.6,2.01],[2,1000,0.02]],"ltp":3.85,"tv":2475.99,"id":2397396},{"batb":[[0,1.3,94.1]],"ltp":1.31,"tv":25250.53,"id":8979329}]}]}
{"op":"mcm","clk":"1009138744","pt":1580642276267,"mc":[{"id":"1.168224328","rc":[{"batb":[[0,3.85,4.97],[1,3.7,5.02],[2,3.65,2.7]],"ltp":3.85,"tv":2475.99,"id":2397396},{"batb":[[0,1.31,94.1],[1,1.3,94.1],[2,1.29,295.22]],"batl":[[0,1.34,480.59],[1,1.35,48.1],[2,1.36,572.4]],"ltp":1.31,"tv":25250.53,"id":8979329}]}]}
{"op":"mcm","clk":"1009138912","pt":1580642277277,"mc":[{"id":"1.168224328","rc":[{"batb":[[0,1.3,94.1],[1,1.29,295.22],[2,1.28,1140.85]],"ltp":1.31,"tv":25250.53,"id":8979329}]}]}
{"op":"mcm","clk":"1009139064","pt":1580642278279,"mc":[{"id":"1.168224328","rc":[{"batb":[[0,1.29,60.81],[1,1.28,1140.85],[2,1.27,594.48]],"ltp":1.31,"tv":25250.53,"id":8979329}]}]}
{"op":"mcm","clk":"1009139240","pt":1580642279285,"mc":[{"id":"1.168224328","rc":[{"batb":[[0,4.1,524.51],[1,3.85,4.97],[2,3.7,5.02]],"batl":[[0,4.6,2.01],[1,4.7,236]],"ltp":3.85,"tv":2475.99,"id":2397396},{"batb":[[0,1.28,1162.94],[1,1.27,594.48],[2,1.26,765.62]],"batl":[[0,1.3,810.65],[1,1.32,2431.68],[2,1.34,480.59]],"ltp":1.31,"tv":25250.53,"id":8979329}]}]}
{"op":"mcm","clk":"1009139395","pt":1580642280396,"mc":[{"id":"1.168224328","rc":[{"batb":[[0,4.2,8.57],[1,4.1,52.45],[2,4,92.22]],"ltp":3.85,"tv":2475.99,"id":2397396},{"batb":[[1,1.27,926.44]],"batl":[[1,1.31,383.08],[2,1.32,1519.78]],"ltp":1.31,"tv":25250.53,"id":8979329}]}]}
{"op":"mcm","clk":"1009139645","pt":1580642282106,"mc":[{"id":"1.168224328","rc":[{"batl":[[0,4.5,11.76],[1,4.6,2.01],[2,4.7,236]],"ltp":3.85,"tv":2475.99,"id":2397396},{"batb":[[0,1.28,1312.5]],"ltp":1.31,"tv":25250.53,"id":8979329}]}]}
{"op":"mcm","clk":"1009139839","pt":1580642283272,"mc":[{"id":"1.168224328","rc":[{"batb":[[0,4.3,31.09],[1,4.2,8.57],[2,4.1,52.45]],"ltp":3.85,"tv":2475.99,"id":2397396}]}]}
{"op":"mcm","clk":"1009140145","pt":1580642285307,"mc":[{"id":"1.168224328","rc":[{"batb":[[1,1.27,1020.54]],"ltp":1.31,"tv":25250.53,"id":8979329}]}]}
{"op":"mcm","clk":"1009140247","pt":1580642286120,"mc":[{"id":"1.168224328","rc":[{"batb":[[2,4.1,60.49]],"ltp":3.85,"tv":2475.99,"id":2397396},{"batb":[[1,1.27,1085.41],[2,1.26,1268.06]],"batl":[[1,1.31,872.07],[2,1.32,2175.69]],"ltp":1.31,"tv":25250.53,"id":8979329}]}]}
{"op":"mcm","clk":"1009140315","pt":1580642286596,"mc":[{"id":"1.168224328","rc":[{"batb":[[1,1.27,1187.91]],"ltp":1.31,"tv":25250.53,"id":8979329}]}]}
{"op":"mcm","clk":"1009140641","pt":1580642288796,"mc":[{"id":"1.168224328","rc":[{"batb":[[0,4.2,8.57],[1,4.1,60.49],[2,4,100.27]],"ltp":3.85,"tv":2475.99,"id":2397396},{"trd":[[1.3,911.45]],"batl":[[0,1.3,808.01]],"ltp":1.3,"tv":25255.8,"id":8979329}],"tv":27731.8}]}
{"op":"mcm","clk":"1009141065","pt":1580642291212,"mc":[{"id":"1.168224328","rc":[{"batb":[[1,4.1,8.04],[2,4,8.05]],"batl":[[2,4.8,2]],"ltp":3.85,"tv":2475.99,"id":2397396},{"batb":[[0,1.28,209.96],[2,1.26,502.44]],"batl":[[0,1.31,572.49],[1,1.32,655.91],[2,1.33,73.5]],"ltp":1.3,"tv":25255.8,"id":8979329}]}]}
{"op":"mcm","clk":"1009141230","pt":1580642292312,"mc":[{"id":"1.168224328","rc":[{"trd":[[4.5,23.53],[4.6,19.32]],"batl":[[0,4.8,2],[1,1000,0.02],[2,4.8,0]],"ltp":4.6,"tv":2518.84,"id":2397396},{"trd":[[1.28,328.48]],"batb":[[0,1.28,80.1]],"ltp":1.28,"tv":25325.25,"id":8979329}],"tv":27844.1}]}
{"op":"mcm","clk":"1009141294","pt":1580642292591,"mc":[{"id":"1.168224328","rc":[{"batb":[[0,4.1,8.04],[1,4,8.05],[2,3.85,4.97]],"ltp":4.6,"tv":2518.84,"id":2397396},{"batb":[[0,1.27,1187.91],[1,1.26,502.44],[2,1.25,519.24]],"batl":[[0,1.31,488.99]],"ltp":1.28,"tv":25325.25,"id":8979329}]}]}
{"op":"mcm","clk":"1009141587","pt":1580642293714,"mc":[{"id":"1.168224328","rc":[{"trd":[[1.31,560.4]],"batb":[[1,1.26,1121.12]],"batl":[[0,1.31,488.98]],"ltp":1.31,"tv":25325.29,"id":8979329}],"tv":27844.14}]}
{"op":"mcm","clk":"1009141807","pt":1580642295207,"mc":[{"id":"1.168224328","rc":[{"batb":[[1,4,21.49]],"batl":[[0,4.6,10.92],[1,4.8,2],[2,1000,0.02]],"ltp":4.6,"tv":2518.84,"id":2397396},{"batb":[[0,1.28,68.9],[1,1.27,1187.91],[2,1.26,1121.12]],"batl":[[2,1.33,115.51]],"ltp":1.31,"tv":25325.29,"id":8979329}]}]}
{"op":"mcm","clk":"1009141863","pt":1580642295618,"mc":[{"id":"1.168224328","rc":[{"batb":[[1,4,8.05]],"batl":[[0,4.8,2],[1,1000,0.02],[2,1000,0]],"ltp":4.6,"tv":2518.84,"id":2397396},{"batb":[[0,1.27,1187.91],[1,1.26,1121.12],[2,1.25,519.24]],"batl":[[2,1.33,73.5]],"ltp":1.31,"tv":25325.29,"id":8979329}]}]}
{"op":"mcm","clk":"1009142496","pt":1580642300157,"mc":[{"id":"1.168224328","rc":[{"batb":[[0,4,8.05],[1,3.85,4.97],[2,3.8,55]],"ltp":4.6,"tv":2518.84,"id":2397396},{"batb":[[0,1.27,593.43],[1,1.26,502.44]],"batl":[[0,1.32,75],[1,1.33,73.5],[2,1.34,75]],"ltp":1.31,"tv":25325.29,"id":8979329}]}]}
{"op":"mcm","clk":"1009142717","pt":1580642301333,"mc":[{"id":"1.168224328","rc":[{"batl":[[0,1.33,73.5],[1,1.34,75],[2,1.35,675.17]],"ltp":1.31,"tv":25325.29,"id":8979329}]}]}
{"op":"mcm","clk":"1009142855","pt":1580642302352,"mc":[{"id":"1.168224328","rc":[{"batl":[[0,4.1,4.2],[1,4.4,842.21],[2,4.8,2]],"ltp":4.6,"tv":2518.84,"id":2397396},{"batb":[[0,1.29,1661.7],[1,1.28,1546.99],[2,1.27,593.43]],"batl":[[1,1.34,870.15]],"ltp":1.31,"tv":25325.29,"id":8979329}]}]}
{"op":"mcm","clk":"1009142990","pt":1580642303315,"mc":[{"id":"1.168224328","rc":[{"batl":[[1,4.4,419.02]],"ltp":4.6,"tv":2518.84,"id":2397396},{"batb":[[0,1.32,271.77],[1,1.31,689.03],[2,1.3,520.22]],"ltp":1.31,"tv":25325.29,"id":8979329}]}]}
{"op":"mcm","clk":"1009143015","pt":1580642303526,"mc":[{"id":"1.168224328","rc":[{"batb":[[2,3.8,69.28]],"batl":[[1,4.3,12.6],[2,4.4,419.02]],"ltp":4.6,"tv":2518.84,"id":2397396},{"batb":[[2,1.3,659.69]],"ltp":1.31,"tv":25325.29,"id":8979329}]}]}
{"op":"mcm","clk":"1009143509","pt":1580642306915,"mc":[{"id":"1.168224328","rc":[{"batb":[[2,1.3,819.33]],"ltp":1.31,"tv":25325.29,"id":8979329}]}]}
{"op":"mcm","clk":"1009143804","pt":1580642309148,"mc":[{"id":"1.168224328","rc":[{"batb":[[1,1.31,783.13]],"batl":[[2,1.35,1155.76]],"ltp":1.31,"tv":25325.29,"id":8979329}]}]}
{"op":"mcm","clk":"1009144514","pt":1580642314359,"mc":[{"id":"1.168224328","rc":[{"trd":[[1.33,160.06]],"batl":[[0,1.33,73.48]],"ltp":1.33,"tv":25325.33,"id":8979329}],"tv":27844.17}]}
{"op":"mcm","clk":"1009145376","pt":1580642319269,"mc":[{"id":"1.168224328","rc":[{"batl":[[0,4.3,12.6],[1,4.4,47.02],[2,4.5,2.01]],"ltp":4.6,"tv":2518.84,"id":2397396},{"batl":[[1,1.34,75]],"ltp":1.33,"tv":25325.33,"id":8979329}]}]}
{"op":"mcm","clk":"1009145471","pt":1580642319961,"mc":[{"id":"1.168224328","rc":[{"batb":[[0,3.8,14.28],[1,3.7,5.02],[2,3.65,2.63]],"batl":[[1,4.5,2.01],[2,4.8,2]],"ltp":4.6,"tv":2518.84,"id":2397396},{"batb":[[0,1.31,94.1],[1,1.3,299.11],[2,1.29,854.86]],"batl":[[0,1.34,75],[1,1.35,480.59],[2,1.36,42.01]],"ltp":1.33,"tv":25325.33,"id":8979329}]}]}
{"op":"mcm","clk":"1009145562","pt":1580642320554,"mc":[{"id":"1.168224328","rc":[{"batb":[[0,3.7,5.02],[1,3.65,2.63],[2,3.55,8.79]],"batl":[[0,4.5,2.01],[1,4.8,2],[2,1000,0.02]],"ltp":4.6,"tv":2518.84,"id":2397396},{"batb":[[1,1.3,159.64]],"batl":[[2,1.37,548.9]],"ltp":1.33,"tv":25325.33,"id":8979329}]}]}
{"op":"mcm","clk":"1009145836","pt":1580642322363,"mc":[{"id":"1.168224328","rc":[{"batb":[[0,1.3,159.64],[1,1.29,854.86],[2,1.27,575.71]],"ltp":1.33,"tv":25325.33,"id":8979329}]}]}
{"op":"mcm","clk":"1009145983","pt":1580642323280,"mc":[{"id":"1.168224328","rc":[{"batb":[[1,1.29,1292.33],[2,1.28,562.17]],"batl":[[0,1.34,75.17]],"ltp":1.33,"tv":25325.33,"id":8979329}]}]}
{"op":"mcm","clk":"1009146279","pt":1580642325398,"mc":[{"id":"1.168224328","rc":[{"batb":[[1,1.29,798.29]],"ltp":1.33,"tv":25325.33,"id":8979329}]}]}
{"op":"mcm","clk":"1009146416","pt":1580642326203,"mc":[{"id":"1.168224328","rc":[{"batb":[[0,1.29,798.29],[1,1.28,562.17],[2,1.27,64.87]],"ltp":1.33,"tv":25325.33,"id":8979329}]}]}
{"op":"mcm","clk":"1009146754","pt":1580642328077,"mc":[{"id":"1.168224328","rc":[{"batb":[[0,4.2,12.67],[1,3.7,5.02],[2,3.65,2.63]],"batl":[[0,4.4,6.19],[1,4.5,2.01],[2,4.6,252]],"ltp":4.6,"tv":2518.84,"id":2397396},{"batb":[[0,1.29,2542.48]],"batl":[[0,1.31,696.97],[1,1.32,2254.27],[2,1.33,1375.59]],"ltp":1.33,"tv":25325.33,"id":8979329}]}]}
{"op":"mcm","clk":"1009146960","pt":1580642329193,"mc":[{"id":"1.168224328","rc":[{"batb":[[1,3.95,97.25],[2,3.7,63.48]],"ltp":4.6,"tv":2518.84,"id":2397396},{"batb":[[1,1.28,879.42]],"ltp":1.33,"tv":25325.33,"id":8979329}]}]}
{"op":"mcm","clk":"1009147014","pt":1580642329464,"mc":[{"id":"1.168224328","rc":[{"batb":[[2,3.9,14.28]],"batl":[[1,4.5,13.77]],"ltp":4.6,"tv":2518.84,"id":2397396},{"batb":[[1,1.28,1028.97]],"ltp":1.33,"tv":25325.33,"id":8979329}]}]}
{"op":"mcm","clk":"1009147676","pt":1580642333576,"mc":[{"id":"1.168224328","rc":[{"trd":[[4.2,40.5]],"batb":[[0,4.2,10.4]],"ltp":4.2,"tv":2523.38,"id":2397396}],"tv":27848.71}]}
{"op":"mcm","clk":"1009147983","pt":1580642335511,"mc":[{"id":"1.168224328","rc":[{"batb":[[1,4.1,8.24],[2,4,8.22]],"batl":[[2,4.6,254]],"ltp":4.2,"tv":2523.38,"id":2397396},{"batb":[[1,1.28,1091.13]],"batl":[[1,1.32,2331.38],[2,1.33,1451.09]],"ltp":1.33,"tv":25325.33,"id":8979329}]}]}
{"op":"mcm","clk":"1009148174","pt":1580642336697,"mc":[{"id":"1.168224328","rc":[{"trd":[[1.31,564.4]],"batl":[[0,1.31,694.97]],"ltp":1.31,"tv":25329.33,"id":8979329}],"tv":27852.71}]}
{"op":"mcm","clk":"1009149143","pt":1580642342213,"mc":[{"id":"1.168224328","rc":[{"batb":[[1,1.28,1324.7]],"ltp":1.31,"tv":25329.33,"id":8979329}]}]}
{"op":"mcm","clk":"1009149297","pt":1580642343281,"mc":[{"id":"1.168224328","rc":[{"batb":[[0,4.1,8.24],[1,4,8.22],[2,3.7,63.48]],"batl":[[0,4.5,13.77],[1,4.6,2],[2,4.8,2]],"ltp":4.2,"tv":2523.38,"id":2397396},{"batb":[[0,1.29,1805],[1,1.28,1026.41]],"batl":[[0,1.32,1781.83],[1,1.33,75.5],[2,1.34,117.01]],"ltp":1.31,"tv":25329.33,"id":8979329}]}]}
{"op":"mcm","clk":"1009149424","pt":1580642344091,"mc":[{"id":"1.168224328","rc":[{"batb":[[0,4,8.22],[1,3.7,63.48],[2,3.55,8.79]],"batl":[[0,4.5,11.76]],"ltp":4.2,"tv":2523.38,"id":2397396},{"batb":[[0,1.28,1026.41],[1,1.27,64.87],[2,1.2,530.96]],"batl":[[0,1.33,75.67],[1,1.34,117.01],[2,1.37,51.5]],"ltp":1.31,"tv":25329.33,"id":8979329}]}]}
{"op":"mcm","clk":"1009149592","pt":1580642344997,"mc":[{"id":"1.168224328","rc":[{"batb":[[1,3.7,58.46]],"batl":[[0,4.6,2],[1,4.8,2],[2,1000,0.02]],"ltp":4.2,"tv":2523.38,"id":2397396},{"batb":[[0,1.28,876.86]],"batl":[[1,1.34,75],[2,1.38,2889.99]],"ltp":1.31,"tv":25329.33,"id":8979329}]}]}
{"op":"mcm","clk":"1009150016","pt":1580642347316,"mc":[{"id":"1.168224328","rc":[{"batb":[[0,4.1,8.24],[1,4,8.22],[2,3.7,58.46]],"batl":[[0,4.5,2],[1,4.6,2],[2,4.8,2]],"ltp":4.2,"tv":2523.38,"id":2397396},{"batb":[[0,1.29,57.81],[1,1.28,876.86],[2,1.27,64.87]],"batl":[[0,1.32,77.28],[1,1.33,75.5],[2,1.34,75]],"ltp":1.31,"tv":25329.33,"id":8979329}]}]}
{"op":"mcm","clk":"1009150189","pt":1580642348229,"mc":[{"id":"1.168224328","rc":[{"batb":[[0,4,8.22],[1,3.7,58.46],[2,3.55,8.79]],"batl":[[0,4.6,2],[1,4.8,2],[2,1000,0.02]],"ltp":4.2,"tv":2523.38,"id":2397396},{"batb":[[0,1.29,743.41],[1,1.28,1180.75]],"batl":[[0,1.32,265.65],[1,1.33,522.45]],"ltp":1.31,"tv":25329.33,"id":8979329}]}]}
{"op":"mcm","clk":"1009150270","pt":1580642348701,"mc":[{"id":"1.168224328","rc":[{"batb":[[0,1.29,846.75]],"ltp":1.31,"tv":25329.33,"id":8979329}]}]}
{"op":"mcm","clk":"1009150650","pt":1580642351320,"mc":[{"id":"1.168224328","rc":[{"batb":[[0,1.29,103.34],[1,1.28,876.86]],"batl":[[0,1.33,75.67],[1,1.34,75],[2,1.38,2889.99]],"ltp":1.31,"tv":25329.33,"id":8979329}]}]}
{"op":"mcm","clk":"1009151137","pt":1580642354708,"mc":[{"id":"1.168224328","rc":[{"batb":[[1,1.28,612.98]],"batl":[[2,1.35,472.82]],"ltp":1.31,"tv":25329.33,"id":8979329}]}]}
{"op":"mcm","clk":"1009151522","pt":1580642357326,"mc":[{"id":"1.168224328","rc":[{"batl":[[0,4.3,350],[1,4.4,496.34],[2,4.6,2]],"ltp":4.2,"tv":2523.38,"id":2397396},{"batb":[[0,1.3,1642.29],[1,1.29,103.34],[2,1.28,612.98]],"ltp":1.31,"tv":25329.33,"id":8979329}]}]}
{"op":"mcm","clk":"1009151609","pt":1580642357914,"mc":[{"id":"1.168224328","rc":[{"batl":[[1,4.4,49.63]],"ltp":4.2,"tv":2523.38,"id":2397396},{"trd":[[1.32,1317.03],[1.33,184.96]],"batb":[[0,1.32,360.48],[1,1.31,494.03],[2,1.3,1164.96]],"batl":[[0,1.33,63.05],[2,1.35,1098.08]],"ltp":1.33,"tv":25354.57,"id":8979329}],"tv":27877.95}]}
{"op":"mcm","clk":"1009151786","pt":1580642359247,"mc":[{"id":"1.168224328","rc":[{"trd":[[1.33,311.07]],"batb":[[0,1.33,196.91],[1,1.32,360.48],[2,1.31,494.03]],"batl":[[0,1.34,75],[1,1.35,1098.08],[2,1.36,1134.65]],"ltp":1.33,"tv":25480.67,"id":8979329}],"tv":28004.06}]}
{"op":"mcm","clk":"1009151826","pt":1580642359519,"mc":[{"id":"1.168224328","rc":[{"batb":[[1,3.75,15.12],[2,3.7,58.46]],"batl":[[0,4.3,362.6]],"ltp":4.2,"tv":2523.38,"id":2397396},{"batl":[[2,1.36,1176.66]],"ltp":1.33,"tv":25480.67,"id":8979329}]}]}
{"op":"mcm","clk":"1009152209","pt":1580642362242,"mc":[{"id":"1.168224328","rc":[{"batb":[[2,1.31,681.39]],"ltp":1.33,"tv":25480.67,"id":8979329}]}]}
{"op":"mcm","clk":"1009152433","pt":1580642364046,"mc":[{"id":"1.168224328","rc":[{"batb":[[1,1.32,454.58]],"batl":[[2,1.36,1657.25]],"ltp":1.33,"tv":25480.67,"id":8979329}]}]}
{"op":"mcm","clk":"1009152564","pt":1580642364845,"mc":[{"id":"1.168224328","rc":[{"batl":[[2,4.5,2.01]],"ltp":4.2,"tv":2523.38,"id":2397396}]}]}
{"op":"mcm","clk":"1009152967","pt":1580642367663,"mc":[{"id":"1.168224328","rc":[{"batl":[[2,1.36,1639.62]],"ltp":1.33,"tv":25480.67,"id":8979329}]}]}
{"op":"mcm","clk":"1009153153","pt":1580642368624,"mc":[{"id":"1.168224328","rc":[{"trd":[[4,9.11]],"batb":[[0,4,6.44]],"ltp":4.0,"tv":2526.94,"id":2397396}],"tv":28007.62}]}
{"op":"mcm","clk":"1009153372","pt":1580642370256,"mc":[{"id":"1.168224328","rc":[{"trd":[[4.1,123.25],[4.2,41.32]],"batl":[[0,4.3,12.6]],"ltp":4.2,"tv":2591.64,"id":2397396},{"trd":[[1.32,1319.65],[1.33,507.98]],"batb":[[0,1.32,451.96],[1,1.31,681.39],[2,1.3,1085.87]],"batl":[[1,1.35,472.82],[2,1.36,920.62]],"ltp":1.32,"tv":25680.2,"id":8979329}],"tv":28271.84}]}
{"op":"mcm","clk":"1009153487","pt":1580642370906,"mc":[{"id":"1.168224328","rc":[{"batb":[[0,3.6,3.84],[1,3.55,8.79],[2,3.5,4.08]],"batl":[[0,4.5,2.01],[1,4.6,2],[2,4.8,2]],"ltp":4.2,"tv":2591.64,"id":2397396},{"batb":[[0,1.32,94.1],[1,1.31,187.36],[2,1.3,782.17]],"batl":[[1,1.36,480.59],[2,1.38,3432.14]],"ltp":1.32,"tv":25680.2,"id":8979329}]}]}
{"op":"mcm","clk":"1009153614","pt":1580642371912,"mc":[{"id":"1.168224328","rc":[{"batb":[[0,1.31,187.36],[1,1.3,782.17],[2,1.29,58.81]],"ltp":1.32,"tv":25680.2,"id":8979329}]}]}
{"op":"mcm","clk":"1009153700","pt":1580642372444,"mc":[{"id":"1.168224328","rc":[{"batl":[[0,1.36,480.59],[1,1.38,3432.14],[2,1.39,67.5]],"ltp":1.32,"tv":25680.2,"id":8979329}]}]}
{"op":"mcm","clk":"1009153911","pt":1580642373936,"mc":[{"id":"1.168224328","rc":[{"batb":[[1,1.3,494.03],[2,1.29,806.83]],"ltp":1.32,"tv":25680.2,"id":8979329}]}]}
{"op":"mcm","clk":"1009158153","pt":1580642404196,"mc":[{"id":"1.168224328","rc":[{"batb":[[0,1.29,806.83],[1,1.28,858.01],[2,1.27,64.87]],"ltp":1.32,"tv":25680.2,"id":8979329}]}]}
{"op":"mcm","clk":"1009158568","pt":1580642406292,"mc":[{"id":"1.168224328","rc":[{"batb":[[0,4.1,3.54],[1,3.95,54.36],[2,3.6,3.84]],"batl":[[0,4.3,5.25],[1,4.5,2.01],[2,4.6,355]],"ltp":4.2,"tv":2591.64,"id":2397396},{"batb":[[1,1.28,1405.97]],"batl":[[0,1.32,583.52],[1,1.33,442.7],[2,1.34,1284.91]],"ltp":1.32,"tv":25680.2,"id":8979329}]}]}
{"op":"mcm","clk":"1009158724","pt":1580642407302,"mc":[{"id":"1.168224328","rc":[{"batb":[[1,4,97.88],[2,3.95,54.36]],"ltp":4.2,"tv":2591.64,"id":2397396}]}]}
{"op":"mcm","clk":"1009158865","pt":1580642407998,"mc":[{"id":"1.168224328","rc":[{"batb":[[1,4,111.32]],"batl":[[2,4.6,365.92]],"ltp":4.2,"tv":2591.64,"id":2397396},{"batb":[[2,1.27,220.31]],"batl":[[1,1.33,484.71]],"ltp":1.32,"tv":25680.2,"id":8979329}]}]}
{"op":"mcm","clk":"1009159822","pt":1580642414011,"mc":[{"id":"1.168224328","rc":[{"trd":[[4.3,23.14]],"batl":[[0,4.3,1.89]],"ltp":4.3,"tv":2598.36,"id":2397396},{"batl":[[2,1.34,1333.66]],"ltp":1.32,"tv":25680.2,"id":8979329}],"tv":28278.56}]}
{"op":"mcm","clk":"1009160668","pt":1580642419509,"mc":[{"id":"1.168224328","rc":[{"trd":[[1.32,1353.51]],"batl":[[0,1.32,566.59]],"ltp":1.32,"tv":25714.06,"id":8979329}],"tv":28312.42}]}
{"op":"mcm","clk":"1009161374","pt":1580642424126,"mc":[{"id":"1.168224328","rc":[{"batl":[[0,4.5,2.01],[1,4.6,365.92],[2,4.8,2]],"ltp":4.3,"tv":2598.36,"id":2397396}]}]}
{"op":"mcm","clk":"1009161527","pt":1580642425205,"mc":[{"id":"1.168224328","rc":[{"trd":[[1.32,1353.77]],"batl":[[0,1.32,566.46]],"ltp":1.32,"tv":25714.32,"id":8979329}],"tv":28312.68}]}
{"op":"mcm","clk":"1009161819","pt":1580642427091,"mc":[{"id":"1.168224328","rc":[{"batl":[[0,4.3,5.79],[1,4.5,2.01],[2,4.6,365.92]],"ltp":4.3,"tv":2598.36,"id":2397396},{"batl":[[0,1.32,577.43]],"ltp":1.32,"tv":25714.32,"id":8979329}]}]}
{"op":"mcm","clk":"1009162197","pt":1580642429742,"mc":[{"id":"1.168224328","rc":[{"batl":[[0,4.5,2.01],[1,4.6,365.92],[2,4.8,2]],"ltp":4.3,"tv":2598.36,"id":2397396},{"batl":[[0,1.32,566.46]],"ltp":1.32,"tv":25714.32,"id":8979329}]}]}
{"op":"mcm","clk":"1009162493","pt":1580642431708,"mc":[{"id":"1.168224328","rc":[{"batl":[[0,4.3,1.68],[1,4.5,2.01],[2,4.6,365.92]],"ltp":4.3,"tv":2598.36,"id":2397396}]}]}
{"op":"mcm","clk":"1009162634","pt":1580642432608,"mc":[{"id":"1.168224328","rc":[{"batl":[[0,4.3,7.47]],"ltp":4.3,"tv":2598.36,"id":2397396},{"batl":[[0,1.32,577.43]],"ltp":1.32,"tv":25714.32,"id":8979329}]}]}
{"op":"mcm","clk":"1009163050","pt":1580642435319,"mc":[{"id":"1.168224328","rc":[{"trd":[[4.1,125.44]],"batb":[[0,4,13.44],[1,3.9,5.96],[2,3.85,3.37]],"batl":[[0,4.3,1.68],[1,4.6,10.92],[2,5.2,2]],"ltp":4.1,"tv":2600.54,"id":2397396},{"batb":[[0,1.27,155.44],[1,1.26,222.65],[2,1.24,445.95]],"batl":[[0,1.33,42.01],[1,1.34,48.75],[2,1.35,51.1]],"ltp":1.32,"tv":25714.32,"id":8979329}],"tv":28314.86}]}
{"op":"mcm","clk":"1009163176","pt":1580642436217,"mc":[{"id":"1.168224328","rc":[{"batb":[[1,3.85,3.37],[2,3.75,60.9]],"batl":[[0,4.6,10.92],[1,5.2,2],[2,5.6,2]],"ltp":4.1,"tv":2600.54,"id":2397396},{"batb":[[0,1.32,2.41],[1,1.27,155.44],[2,1.26,222.65]],"batl":[[1,1.35,51.1],[2,1.36,292.96]],"ltp":1.32,"tv":25714.32,"id":8979329}]}]}
{"op":"mcm","clk":"1009163303","pt":1580642437125,"mc":[{"id":"1.168224328","rc":[{"batb":[[0,3.85,3.37],[1,3.75,60.9],[2,3.6,3.84]],"batl":[[0,5.2,2],[1,5.6,2],[2,5.8,2]],"ltp":4.1,"tv":2600.54,"id":2397396},{"trd":[[1.32,1358.59]],"batb":[[0,1.26,222.65],[1,1.24,445.95],[2,1.22,82.84]],"batl":[[0,1.35,51.21],[1,1.36,292.96],[2,1.38,2934.74]],"ltp":1.32,"tv":25719.14,"id":8979329}],"tv":28319.69}]}
{"op":"mcm","clk":"1009163433","pt":1580642438016,"mc":[{"id":"1.168224328","rc":[{"batb":[[1,1.24,1219.78],[2,1.23,722.63]],"batl":[[0,1.35,281.22],[1,1.36,694.19]],"ltp":1.32,"tv":25719.14,"id":8979329}]}]}
{"op":"mcm","clk":"1009163634","pt":1580642439329,"mc":[{"id":"1.168224328","rc":[{"trd":[[4.4,1017.35]],"batl":[[0,4.2,1.65],[1,5.2,2],[2,5.6,2]],"ltp":4.4,"tv":2600.57,"id":2397396},{"trd":[[1.29,7015.74]],"batl":[[0,1.35,281.11]],"ltp":1.29,"tv":25719.25,"id":8979329}],"tv":28319.83}]}
{"op":"mcm","clk":"1009163813","pt":1580642440619,"mc":[{"id":"1.168224328","rc":[{"batl":[[0,1.35,51.1],[1,1.36,292.96]],"ltp":1.29,"tv":25719.25,"id":8979329}]}]}
{"op":"mcm","clk":"1009164041","pt":1580642442315,"mc":[{"id":"1.168224328","rc":[{"batb":[[0,1.24,1219.78],[1,1.23,722.63],[2,1.22,82.84]],"batl":[[1,1.36,51.82]],"ltp":1.29,"tv":25719.25,"id":8979329}]}]}
{"op":"mcm","clk":"1009164193","pt":1580642443320,"mc":[{"id":"1.168224328","rc":[{"trd":[[4.2,44.62]],"batb":[[0,4.6,1628.78],[1,3.85,3.37],[2,3.75,60.9]],"batl":[[0,5,4.88],[2,5.3,298]],"ltp":4.2,"tv":2603.87,"id":2397396},{"batl":[[0,1.27,6705.97],[1,1.28,3037.26],[2,1.35,51.1]],"ltp":1.29,"tv":25719.25,"id":8979329}],"tv":28323.13}]}
{"op":"mcm","clk":"1009164243","pt":1580642443643,"mc":[{"id":"1.168224328","rc":[{"batb":[[0,4.6,163.04],[1,4.5,2.82],[2,3.85,3.37]],"ltp":4.2,"tv":2603.87,"id":2397396},{"batl":[[0,1.27,1405.07],[1,1.28,1607.58]],"ltp":1.29,"tv":25719.25,"id":8979329}]}]}
{"op":"mcm","clk":"1009164419","pt":1580642444764,"mc":[{"id":"1.168224328","rc":[{"batb":[[0,4.6,234.72],[2,4.1,91.19]],"ltp":4.2,"tv":2603.87,"id":2397396}]}]}
{"op":"mcm","clk":"1009164558","pt":1580642445626,"mc":[{"id":"1.168224328","rc":[{"batb":[[2,4.4,2.67]],"batl":[[1,5.2,11.24]],"ltp":4.2,"tv":2603.87,"id":2397396}]}]}
{"op":"mcm","clk":"1009164758","pt":1580642446955,"mc":[{"id":"1.168224328","rc":[{"batb":[[1,4.5,14.58]],"ltp":4.2,"tv":2603.87,"id":2397396},{"batl":[[2,1.29,42.01]],"ltp":1.29,"tv":25719.25,"id":8979329}]}]}
{"op":"mcm","clk":"1009164943","pt":1580642448233,"mc":[{"id":"1.168224328","rc":[{"batl":[[0,5,21.68]],"ltp":4.2,"tv":2603.87,"id":2397396}]}]}
{"op":"mcm","clk":"1009165269","pt":1580642450352,"mc":[{"id":"1.168224328","rc":[{"batb":[[1,1.23,1225.07],[2,1.22,602.08]],"ltp":1.29,"tv":25719.25,"id":8979329}]}]}
{"op":"mcm","clk":"1009165758","pt":1580642453689,"mc":[{"id":"1.168224328","rc":[{"trd":[[1.27,46.62]],"batl":[[0,1.27,1403.29]],"ltp":1.27,"tv":25722.81,"id":8979329}],"tv":28326.69}]}
{"op":"mcm","clk":"1009166448","pt":1580642458256,"mc":[{"id":"1.168224328","rc":[{"batl":[[0,5,16.8],[2,5.6,2]],"ltp":4.2,"tv":2603.87,"id":2397396},{"batl":[[0,1.27,572.7],[1,1.28,792.58]],"ltp":1.27,"tv":25722.81,"id":8979329}]}]}
{"op":"mcm","clk":"1009166598","pt":1580642459268,"mc":[{"id":"1.168224328","rc":[{"batb":[[0,4.5,11.76],[1,4.4,2.67],[2,4.3,2.48]],"batl":[[1,5.2,9.24],[2,6.4,2]],"ltp":4.2,"tv":2603.87,"id":2397396},{"batb":[[0,1.23,502.44],[1,1.22,519.24],[2,1.21,241.14]],"batl":[[0,1.29,42.01],[1,1.3,541.04],[2,1.31,505.8]],"ltp":1.27,"tv":25722.81,"id":8979329}]}]}
{"op":"mcm","clk":"1009166758","pt":1580642460652,"mc":[{"id":"1.168224328","rc":[{"batb":[[0,4.4,2.67],[1,4.3,2.48],[2,4.1,93.63]],"batl":[[1,6.4,2],[2,7.4,2]],"ltp":4.2,"tv":2603.87,"id":2397396},{"batl":[[0,1.3,541.04],[1,1.31,505.8],[2,1.32,54.11]],"ltp":1.27,"tv":25722.81,"id":8979329}]}]}
{"op":"mcm","clk":"1009167177","pt":1580642463359,"mc":[{"id":"1.168224328","rc":[{"trd":[[1.27,54.81]],"batb":[[0,1.23,1289.94],[1,1.22,1281.83]],"batl":[[0,1.26,640.26],[1,1.27,563.47],[2,1.3,541.04]],"ltp":1.27,"tv":25730.99,"id":8979329}],"tv":28334.87}]}
{"op":"mcm","clk":"1009167421","pt":1580642465048,"mc":[{"id":"1.168224328","rc":[{"batl":[[2,1.29,251.22]],"ltp":1.27,"tv":25730.99,"id":8979329}]}]}
{"op":"mcm","clk":"1009167601","pt":1580642466269,"mc":[{"id":"1.168224328","rc":[{"batb":[[0,1.23,502.44],[1,1.22,519.24]],"batl":[[0,1.29,251.22],[1,1.3,541.04],[2,1.31,505.8]],"ltp":1.27,"tv":25730.99,"id":8979329}]}]}
{"op":"mcm","clk":"1009167682","pt":1580642466793,"mc":[{"id":"1.168224328","rc":[{"batb":[[2,1.2,25.1]],"ltp":1.27,"tv":25730.99,"id":8979329}]}]}
{"op":"mcm","clk":"1009168050","pt":1580642469198,"mc":[{"id":"1.168224328","rc":[{"batl":[[2,1.31,997.62]],"ltp":1.27,"tv":25730.99,"id":8979329}]}]}
{"op":"mcm","clk":"1009168471","pt":1580642472118,"mc":[{"id":"1.168224328","rc":[{"batl":[[0,6.4,2],[1,7.4,2],[2,1000,0.02]],"ltp":4.2,"tv":2603.87,"id":2397396}]}]}
{"op":"mcm","clk":"1009168647","pt":1580642473396,"mc":[{"id":"1.168224328","rc":[{"trd":[[4.4,1019.14]],"batb":[[0,4.3,2.48],[1,4.1,93.63],[2,2.6,75.72]],"ltp":4.4,"tv":2605.65,"id":2397396},{"trd":[[1.29,7021.82]],"batl":[[0,1.29,245.14],[1,1.3,52.05],[2,1.31,491.82]],"ltp":1.29,"tv":25737.07,"id":8979329}],"tv":28342.72}]}
{"op":"mcm","clk":"1009168753","pt":1580642474138,"mc":[{"id":"1.168224328","rc":[{"batb":[[0,4.1,93.63],[1,2.6,75.72],[2,2.2,75.72]],"ltp":4.4,"tv":2605.65,"id":2397396},{"batl":[[0,1.31,491.82],[1,1.32,514.72],[2,1.38,2889.99]],"ltp":1.29,"tv":25737.07,"id":8979329}]}]}
{"op":"mcm","clk":"1009168917","pt":1580642475216,"mc":[{"id":"1.168224328","rc":[{"batl":[[0,5.2,16.8],[1,6.4,2],[2,7.4,2]],"ltp":4.4,"tv":2605.65,"id":2397396}]}]}
{"op":"mcm","clk":"1009169089","pt":1580642476392,"mc":[{"id":"1.168224328","rc":[{"batb":[[1,4,2.56],[2,2.6,75.72]],"batl":[[0,4.7,270],[1,5,239.69],[2,5.2,16.8]],"ltp":4.4,"tv":2605.65,"id":2397396},{"batb":[[0,1.28,2318.57],[1,1.27,590.21],[2,1.25,958.77]],"batl":[[0,1.31,2991.67],[1,1.32,1302.72]],"ltp":1.29,"tv":25737.07,"id":8979329}]}]}
{"op":"mcm","clk":"1009169181","pt":1580642477018,"mc":[{"id":"1.168224328","rc":[{"batb":[[2,3.8,55.94]],"ltp":4.4,"tv":2605.65,"id":2397396},{"batb":[[0,1.28,2632.35]],"ltp":1.29,"tv":25737.07,"id":8979329}]}]}
{"op":"mcm","clk":"1009169277","pt":1580642477706,"mc":[{"id":"1.168224328","rc":[{"batb":[[0,4.1,107.08]],"batl":[[0,4.7,280.92]],"ltp":4.4,"tv":2605.65,"id":2397396},{"batb":[[1,1.27,745.65]],"batl":[[1,1.32,1344.73]],"ltp":1.29,"tv":25737.07,"id":8979329}]}]}
{"op":"mcm","clk":"1009169457","pt":1580642479120,"mc":[{"id":"1.168224328","rc":[{"batb":[[0,1.3,6.04],[1,1.28,2632.35],[2,1.27,745.65]],"ltp":1.29,"tv":25737.07,"id":8979329}]}]}
{"op":"mcm","clk":"1009169882","pt":1580642482203,"mc":[{"id":"1.168224328","rc":[{"batb":[[2,1.27,1239.68]],"batl":[[2,1.35,480.59]],"ltp":1.29,"tv":25737.07,"id":8979329}]}]}
{"op":"mcm","clk":"1009169996","pt":1580642483103,"mc":[{"id":"1.168224328","rc":[{"batb":[[2,3.9,2.76]],"batl":[[2,5.4,2]],"ltp":4.4,"tv":2605.65,"id":2397396},{"batl":[[2,1.34,49.75]],"ltp":1.29,"tv":25737.07,"id":8979329}]}]}
{"op":"mcm","clk":"1009170069","pt":1580642483626,"mc":[{"id":"1.168224328","rc":[{"batl":[[2,1.34,246.36]],"ltp":1.29,"tv":25737.07,"id":8979329}]}]}
{"op":"mcm","clk":"1009170390","pt":1580642486227,"mc":[{"id":"1.168224328","rc":[{"trd":[[4.2,46.4]],"batl":[[0,4.5,16.8],[1,4.7,280.92],[2,5,239.69]],"ltp":4.2,"tv":2607.43,"id":2397396},{"trd":[[1.31,570.11]],"batl":[[0,1.31,2985.96]],"ltp":1.31,"tv":25742.78,"id":8979329}],"tv":28350.22}]}
{"op":"mcm","clk":"1009170675","pt":1580642488335,"mc":[{"id":"1.168224328","rc":[{"trd":[[1.3,915.01]],"batb":[[0,1.3,4.26]],"ltp":1.3,"tv":25746.34,"id":8979329}],"tv":28353.78}]}
{"op":"mcm","clk":"1009170963","pt":1580642490358,"mc":[{"id":"1.168224328","rc":[{"batl":[[1,4.7,10.92],[2,5.4,2]],"ltp":4.2,"tv":2607.43,"id":2397396},{"batl":[[0,1.31,2203.67],[1,1.32,556.73]],"ltp":1.3,"tv":25746.34,"id":8979329}]}]}
{"op":"mcm","clk":"1009171056","pt":1580642491050,"mc":[{"id":"1.168224328","rc":[{"batb":[[0,4.1,13.44],[2,3.8,55.94]],"ltp":4.2,"tv":2607.43,"id":2397396},{"trd":[[1.3,923.53]],"batb":[[0,1.27,649.47],[1,1.25,510.84],[2,1.23,71.63]],"batl":[[0,1.3,1.97],[1,1.32,42.01],[2,1.34,196.61]],"ltp":1.3,"tv":25754.86,"id":8979329}],"tv":28362.3}]}
{"op":"mcm","clk":"1009171249","pt":1580642492653,"mc":[{"id":"1.168224328","rc":[{"batb":[[0,4,2.56],[1,3.8,55.94],[2,3.75,2.79]],"batl":[[1,5.4,2],[2,6,2]],"ltp":4.2,"tv":2607.43,"id":2397396},{"batb":[[0,1.27,494.03]],"batl":[[1,1.34,196.61],[2,1.35,480.59]],"ltp":1.3,"tv":25754.86,"id":8979329}]}]}
{"op":"mcm","clk":"1009171465","pt":1580642494226,"mc":[{"id":"1.168224328","rc":[{"batb":[[1,3.9,2.76],[2,3.8,55.94]],"ltp":4.2,"tv":2607.43,"id":2397396},{"batl":[[1,1.34,247.86]],"ltp":1.3,"tv":25754.86,"id":8979329}]}]}
{"op":"mcm","clk":"1009171493","pt":1580642494459,"mc":[{"id":"1.168224328","rc":[{"batb":[[1,3.8,55.94],[2,3.75,2.79]],"ltp":4.2,"tv":2607.43,"id":2397396},{"batl":[[1,1.34,196.61]],"ltp":1.3,"tv":25754.86,"id":8979329}]}]}
{"op":"mcm","clk":"1009171700","pt":1580642496230,"mc":[{"id":"1.168224328","rc":[{"batb":[[0,1.27,1016.61],[1,1.26,617.3],[2,1.25,510.84]],"batl":[[0,1.3,590.01],[1,1.31,477.26],[2,1.34,196.61]],"ltp":1.3,"tv":25754.86,"id":8979329}]}]}
{"op":"mcm","clk":"1009171858","pt":1580642497673,"mc":[{"id":"1.168224328","rc":[{"batb":[[1,3.9,2.76],[2,3.8,55.94]],"ltp":4.2,"tv":2607.43,"id":2397396},{"batl":[[2,1.34,242.86]],"ltp":1.3,"tv":25754.86,"id":8979329}]}]}
{"op":"mcm","clk":"1009172036","pt":1580642499144,"mc":[{"id":"1.168224328","rc":[{"batb":[[0,1.27,494.03],[1,1.25,510.84],[2,1.23,71.63]],"batl":[[0,1.3,1.97],[1,1.34,242.86],[2,1.35,480.59]],"ltp":1.3,"tv":25754.86,"id":8979329}]}]}
{"op":"mcm","clk":"1009172474","pt":1580642502125,"mc":[{"id":"1.168224328","rc":[{"batb":[[2,1.23,519.21]],"batl":[[2,1.35,811.6]],"ltp":1.3,"tv":25754.86,"id":8979329}]}]}
{"op":"mcm","clk":"1009172731","pt":1580642504173,"mc":[{"id":"1.168224328","rc":[{"batb":[[0,3.9,2.76],[1,3.8,55.94],[2,3.75,2.79]],"ltp":4.2,"tv":2607.43,"id":2397396}]}]}
{"op":"mcm","clk":"1009172867","pt":1580642505236,"mc":[{"id":"1.168224328","rc":[{"batb":[[0,3.8,55.94],[1,3.75,2.79],[2,2.6,75.72]],"batl":[[2,5.5,2.5]],"ltp":4.2,"tv":2607.43,"id":2397396},{"batl":[[1,1.34,196.61]],"ltp":1.3,"tv":25754.86,"id":8979329}]}]}
{"op":"mcm","clk":"1009174244","pt":1580642515286,"mc":[{"id":"1.168224328","rc":[{"batb":[[2,1.23,71.63]],"batl":[[2,1.35,331.01]],"ltp":1.3,"tv":25754.86,"id":8979329}]}]}
{"op":"mcm","clk":"1009174392","pt":1580642516155,"mc":[{"id":"1.168224328","rc":[{"batl":[[1,1.35,331.01],[2,1.36,447.89]],"ltp":1.3,"tv":25754.86,"id":8979329}]}]}
{"op":"mcm","clk":"1009174707","pt":1580642518171,"mc":[{"id":"1.168224328","rc":[{"trd":[[4.3,23.74]],"batb":[[2,2.2,75.72]],"batl":[[0,4,4.36],[1,4.3,580.02],[2,4.5,16.8]],"ltp":4.3,"tv":2608.03,"id":2397396},{"trd":[[1.3,925.5]],"batb":[[0,1.32,2216.33],[1,1.31,496.31],[2,1.27,494.03]],"batl":[[0,1.35,2654.82],[1,1.36,1175.89],[2,1.38,2889.99]],"ltp":1.3,"tv":25756.83,"id":8979329}],"tv":28364.87}]}
{"op":"mcm","clk":"1009174839","pt":1580642519067,"mc":[{"id":"1.168224328","rc":[{"batb":[[1,3.75,5.38],[2,3.55,66.64]],"ltp":4.3,"tv":2608.03,"id":2397396},{"batb":[[0,1.32,2484.87],[2,1.27,824.42]],"ltp":1.3,"tv":25756.83,"id":8979329}]}]}
{"op":"mcm","clk":"1009174903","pt":1580642519551,"mc":[{"id":"1.168224328","rc":[{"batb":[[0,3.8,70.23]],"ltp":4.3,"tv":2608.03,"id":2397396},{"batl":[[1,1.36,1217.9]],"ltp":1.3,"tv":25756.83,"id":8979329}]}]}
{"op":"mcm","clk":"1009175145","pt":1580642521265,"mc":[{"id":"1.168224328","rc":[{"batl":[[1,4.3,592.62]],"ltp":4.3,"tv":2608.03,"id":2397396},{"batb":[[2,1.3,139.47]],"ltp":1.3,"tv":25756.83,"id":8979329}]}]}
{"op":"mcm","clk":"1009175547","pt":1580642524384,"mc":[{"id":"1.168224328","rc":[{"batb":[[2,1.3,633.51]],"batl":[[2,1.37,224.33]],"ltp":1.3,"tv":25756.83,"id":8979329}]}]}
{"op":"mcm","clk":"1009175580","pt":1580642524551,"mc":[{"id":"1.168224328","rc":[{"batb":[[2,3.7,3.02]],"ltp":4.3,"tv":2608.03,"id":2397396},{"batl":[[2,1.37,273.83]],"ltp":1.3,"tv":25756.83,"id":8979329}]}]}
{"op":"mcm","clk":"1009176219","pt":1580642528507,"mc":[{"id":"1.168224328","rc":[{"trd":[[4,9.7]],"batl":[[0,4,3.77]],"ltp":4.0,"tv":2608.62,"id":2397396},{"trd":[[1.33,509.76]],"ltp":1.33,"tv":25758.62,"id":8979329}],"tv":28367.24}]}
{"op":"mcm","clk":"1009177348","pt":1580642536180,"mc":[{"id":"1.168224328","rc":[{"batb":[[0,3.8,14.28],[1,3.75,2.59]],"batl":[[0,4.3,12.6],[1,4.5,16.8],[2,4.6,2.01]],"ltp":4.0,"tv":2608.62,"id":2397396},{"batb":[[0,1.3,633.51],[1,1.28,576.5],[2,1.27,330.39]],"batl":[[0,1.36,42.01],[1,1.37,273.83],[2,1.38,2936.24]],"ltp":1.33,"tv":25758.62,"id":8979329}]}]}
{"op":"mcm","clk":"1009177414","pt":1580642536597,"mc":[{"id":"1.168224328","rc":[{"batb":[[0,3.75,2.59],[1,3.7,3.02],[2,3.6,2.99]],"batl":[[0,4.5,16.8],[1,4.6,2.01],[2,4.9,2]],"ltp":4.0,"tv":2608.62,"id":2397396},{"batb":[[0,1.3,494.03]],"batl":[[0,1.37,273.83],[1,1.38,2936.24],[2,1.39,480.59]],"ltp":1.33,"tv":25758.62,"id":8979329}]}]}
{"op":"mcm","clk":"1009178102","pt":1580642540756,"mc":[{"id":"1.168224328","rc":[{"batb":[[0,1.31,523.83],[1,1.3,1011.34],[2,1.28,576.5]],"batl":[[0,1.34,366.2],[1,1.35,413.75],[2,1.37,273.83]],"ltp":1.33,"tv":25758.62,"id":8979329}]}]}
{"op":"mcm","clk":"1009178728","pt":1580642544733,"mc":[{"id":"1.168224328","rc":[{"batb":[[0,1.3,494.03],[1,1.28,576.5],[2,1.27,330.39]],"batl":[[0,1.37,273.83],[1,1.38,2936.24],[2,1.39,480.59]],"ltp":1.33,"tv":25758.62,"id":8979329}]}]}
{"op":"mcm","clk":"1009178968","pt":1580642546219,"mc":[{"id":"1.168224328","rc":[{"batb":[[0,3.7,3.02],[1,3.6,2.99],[2,3.55,66.64]],"ltp":4.0,"tv":2608.62,"id":2397396}]}]}
{"op":"mcm","clk":"1009179199","pt":1580642547710,"mc":[{"id":"1.168224328","rc":[{"batb":[[2,1.27,1000.85]],"batl":[[2,1.39,862.45]],"ltp":1.33,"tv":25758.62,"id":8979329}]}]}
{"op":"mcm","clk":"1009179479","pt":1580642549619,"mc":[{"id":"1.168224328","rc":[{"batb":[[2,1.27,330.39]],"batl":[[2,1.39,381.86]],"ltp":1.33,"tv":25758.62,"id":8979329}]}]}
{"op":"mcm","clk":"1009179652","pt":1580642550910,"mc":[{"id":"1.168224328","rc":[{"batb":[[0,3.6,2.99],[1,3.55,66.64],[2,2.2,75.72]],"ltp":4.0,"tv":2608.62,"id":2397396},{"batl":[[0,1.38,2936.24],[1,1.39,381.86],[2,1.4,349.17]],"ltp":1.33,"tv":25758.62,"id":8979329}]}]}
{"op":"mcm","clk":"1009179923","pt":1580642552373,"mc":[{"id":"1.168224328","rc":[{"batb":[[0,3.6,219.48]],"batl":[[0,3.95,272]],"ltp":4.0,"tv":2608.62,"id":2397396},{"batb":[[0,1.37,9.76],[1,1.36,1943.69],[2,1.35,422.76]],"batl":[[1,1.39,2000.57],[2,1.4,1266.17]],"ltp":1.33,"tv":25758.62,"id":8979329}]}]}
{"op":"mcm","clk":"1009180162","pt":1580642553804,"mc":[{"id":"1.168224328","rc":[{"batb":[[1,3.55,82.61],[2,3.5,2.54]],"batl":[[1,4.1,13.44],[2,4.6,2.01]],"ltp":4.0,"tv":2608.62,"id":2397396},{"batb":[[2,1.35,658.96]],"batl":[[1,1.39,2042.58]],"ltp":1.33,"tv":25758.62,"id":8979329}]}]}
{"op":"mcm","clk":"1009180262","pt":1580642554747,"mc":[{"id":"1.168224328","rc":[{"batl":[[1,4,16.8],[2,4.1,13.44]],"ltp":4.0,"tv":2608.62,"id":2397396}]}]}
{"op":"mcm","clk":"1009180997","pt":1580642559279,"mc":[{"id":"1.168224328","rc":[{"batl":[[1,4.1,13.44],[2,4.6,2.01]],"ltp":4.0,"tv":2608.62,"id":2397396}]}]}
{"op":"mcm","clk":"1009181114","pt":1580642560081,"mc":[{"id":"1.168224328","rc":[{"batb":[[1,3.55,86],[2,3.5,5.78]],"batl":[[1,4.1,15.49],[2,4.3,2]],"ltp":4.0,"tv":2608.62,"id":2397396},{"batl":[[1,1.39,2082.08],[2,1.4,1308.81]],"ltp":1.33,"tv":25758.62,"id":8979329}]}]}
{"op":"mcm","clk":"1009181448","pt":1580642562385,"mc":[{"id":"1.168224328","rc":[{"trd":[[3.6,34.5]],"batb":[[0,3.6,202.68]],"ltp":3.6,"tv":2642.23,"id":2397396}],"tv":28400.85}]}
{"op":"mcm","clk":"1009181902","pt":1580642565390,"mc":[{"id":"1.168224328","rc":[{"batb":[[0,3.55,86],[1,3.5,5.78],[2,3.35,74.67]],"batl":[[0,4.1,15.49],[1,4.3,2],[2,4.6,2.01]],"ltp":3.6,"tv":2642.23,"id":2397396},{"batb":[[0,1.35,236.2],[1,1.34,569.03],[2,1.33,187.4]],"batl":[[0,1.38,2889.99],[1,1.39,81.51],[2,1.4,42.64]],"ltp":1.33,"tv":25758.62,"id":8979329}]}]}
{"op":"mcm","clk":"1009181956","pt":1580642565712,"mc":[{"id":"1.168224328","rc":[{"batb":[[0,3.55,19.35]],"ltp":3.6,"tv":2642.23,"id":2397396},{"batb":[[0,1.34,569.03],[1,1.33,187.4],[2,1.32,780.32]],"ltp":1.33,"tv":25758.62,"id":8979329}]}]}
{"op":"mcm","clk":"1009182101","pt":1580642566613,"mc":[{"id":"1.168224328","rc":[{"batb":[[0,3.55,3.39]],"batl":[[0,4.1,2.05]],"ltp":3.6,"tv":2642.23,"id":2397396},{"batb":[[1,1.33,60.53]],"batl":[[1,1.39,39.5]],"ltp":1.33,"tv":25758.62,"id":8979329}]}]}
{"op":"mcm","clk":"1009182339","pt":1580642568173,"mc":[{"id":"1.168224328","rc":[{"batb":[[2,1.32,1426.5]],"ltp":1.33,"tv":25758.62,"id":8979329}]}]}
{"op":"mcm","clk":"1009182974","pt":1580642572703,"mc":[{"id":"1.168224328","rc":[{"batl":[[0,4.3,2],[1,4.6,2.01],[2,4.9,2]],"ltp":3.6,"tv":2642.23,"id":2397396},{"batb":[[0,1.34,75],[1,1.32,915.67],[2,1.31,551.21]],"ltp":1.33,"tv":25758.62,"id":8979329}]}]}
{"op":"mcm","clk":"1009183173","pt":1580642574003,"mc":[{"id":"1.168224328","rc":[{"batb":[[0,1.32,915.67],[1,1.31,551.21],[2,1.28,65.66]],"ltp":1.33,"tv":25758.62,"id":8979329}]}]}
{"op":"mcm","clk":"1009183326","pt":1580642575007,"mc":[{"id":"1.168224328","rc":[{"batb":[[0,3.9,208.47],[1,3.75,2.63],[2,3.65,56.41]],"batl":[[0,4.1,7.21],[1,4.3,310],[2,4.6,2.01]],"ltp":3.6,"tv":2642.23,"id":2397396},{"batb":[[2,1.3,770.3]],"batl":[[0,1.36,1468.39],[1,1.37,382.75],[2,1.38,3032.58]],"ltp":1.33,"tv":25758.62,"id":8979329}]}]}
{"op":"mcm","clk":"1009183491","pt":1580642576016,"mc":[{"id":"1.168224328","rc":[{"batb":[[1,3.8,55.63],[2,3.75,17.75]],"batl":[[1,4.3,322.6]],"ltp":3.6,"tv":2642.23,"id":2397396},{"batb":[[2,1.3,909.77]],"batl":[[0,1.36,1510.4]],"ltp":1.33,"tv":25758.62,"id":8979329}]}]}
{"op":"mcm","clk":"1009184590","pt":1580642582995,"mc":[{"id":"1.168224328","rc":[{"batl":[[2,4.5,2.01]],"ltp":3.6,"tv":2642.23,"id":2397396},{"batl":[[1,1.37,426.25]],"ltp":1.33,"tv":25758.62,"id":8979329}]}]}
{"op":"mcm","clk":"1009185306","pt":1580642588206,"mc":[{"id":"1.168224328","rc":[{"batb":[[2,1.3,1003.87]],"batl":[[2,1.38,3107.58]],"ltp":1.33,"tv":25758.62,"id":8979329}]}]}
{"op":"mcm","clk":"1009185885","pt":1580642592331,"mc":[{"id":"1.168224328","rc":[{"batb":[[0,3.8,55.63],[1,3.75,15.12],[2,3.55,3.39]],"batl":[[0,4.3,12.6],[1,4.5,2.01],[2,4.8,2.02]],"ltp":3.6,"tv":2642.23,"id":2397396},{"batb":[[0,1.32,269.49],[1,1.3,233.57],[2,1.29,548.84]],"batl":[[0,1.36,42.01],[1,1.38,2964.99],[2,1.39,595.09]],"ltp":1.33,"tv":25758.62,"id":8979329}]}]}
{"op":"mcm","clk":"1009185939","pt":1580642592601,"mc":[{"id":"1.168224328","rc":[{"batb":[[0,3.55,3.39],[1,3.5,70.59],[2,2.64,22.91]],"batl":[[0,4.5,2.01],[1,4.8,2.02],[2,5.5,2.5]],"ltp":3.6,"tv":2642.23,"id":2397396},{"batb":[[0,1.3,94.1],[1,1.29,548.84],[2,1.27,572.71]],"batl":[[0,1.38,2964.99],[1,1.39,595.09],[2,1.4,42.64]],"ltp":1.33,"tv":25758.62,"id":8979329}]}]}
{"op":"mcm","clk":"1009186293","pt":1580642595109,"mc":[{"id":"1.168224328","rc":[{"batb":[[2,1.27,1012.67]],"batl":[[2,1.4,485.25]],"ltp":1.33,"tv":25758.62,"id":8979329}]}]}
{"op":"mcm","clk":"1009186596","pt":1580642597307,"mc":[{"id":"1.168224328","rc":[{"batb":[[1,1.29,54.81],[2,1.27,501.83]],"batl":[[2,1.4,42.64]],"ltp":1.33,"tv":25758.62,"id":8979329}]}]}
{"op":"mcm","clk":"1009186635","pt":1580642597536,"mc":[{"id":"1.168224328","rc":[{"batl":[[0,4.8,2.02],[1,5.5,2.5],[2,1000,0.02]],"ltp":3.6,"tv":2642.23,"id":2397396},{"batb":[[1,1.27,501.83],[2,1.26,958.42]],"ltp":1.33,"tv":25758.62,"id":8979329}]}]}
{"op":"mcm","clk":"1009186873","pt":1580642599244,"mc":[{"id":"1.168224328","rc":[{"batb":[[0,3.7,2.42],[1,3.55,3.39],[2,3.5,70.59]],"ltp":3.6,"tv":2642.23,"id":2397396},{"batb":[[0,1.27,501.83],[1,1.26,958.42],[2,1.2,25.1]],"batl":[[0,1.37,44.5],[1,1.38,2964.99],[2,1.39,595.09]],"ltp":1.33,"tv":25758.62,"id":8979329}]}]}
{"op":"mcm","clk":"1009187051","pt":1580642600329,"mc":[{"id":"1.168224328","rc":[{"batb":[[0,4.5,5.07],[1,4.3,2.48],[2,3.55,3.39]],"batl":[[0,4.7,3.59],[1,4.8,2.02],[2,5,309]],"ltp":3.6,"tv":2642.23,"id":2397396},{"batb":[[0,1.27,2273.48]],"batl":[[0,1.29,828.76],[1,1.3,3225.46],[2,1.31,476.04]],"ltp":1.33,"tv":25758.62,"id":8979329}]}]}
{"op":"mcm","clk":"1009187148","pt":1580642601146,"mc":[{"id":"1.168224328","rc":[{"batb":[[1,4.4,80.33],[2,4.3,2.48]],"ltp":3.6,"tv":2642.23,"id":2397396}]}]}
{"op":"mcm","clk":"1009187316","pt":1580642602312,"mc":[{"id":"1.168224328","rc":[{"batl":[[2,4.9,10.08]],"ltp":3.6,"tv":2642.23,"id":2397396},{"batl":[[2,1.31,518.05]],"ltp":1.33,"tv":25758.62,"id":8979329}]}]}
{"op":"mcm","clk":"1009187838","pt":1580642605958,"mc":[{"id":"1.168224328","rc":[{"batb":[[2,1.21,242.82]],"ltp":1.33,"tv":25758.62,"id":8979329}]}]}
{"op":"mcm","clk":"1009188001","pt":1580642607245,"mc":[{"id":"1.168224328","rc":[{"batb":[[2,1.25,502.44]],"ltp":1.33,"tv":25758.62,"id":8979329}]}]}
{"op":"mcm","clk":"1009189749","pt":1580642619083,"mc":[{"id":"1.168224328","rc":[{"batb":[[0,4.4,80.33],[1,4.3,2.48],[2,4.2,15.17]],"batl":[[0,4.8,2.02],[1,4.9,10.08],[2,5.5,2.5]],"ltp":3.6,"tv":2642.23,"id":2397396},{"batl":[[0,1.3,2419.46],[1,1.31,518.05],[2,1.32,488.99]],"ltp":1.33,"tv":25758.62,"id":8979329}]}]}
{"op":"mcm","clk":"1009189881","pt":1580642619892,"mc":[{"id":"1.168224328","rc":[{"batb":[[0,4.2,15.17],[1,3.9,55.37],[2,3.75,2.43]],"batl":[[0,4.9,10.08],[1,5.5,2.5],[2,6,2]],"ltp":3.6,"tv":2642.23,"id":2397396},{"batb":[[0,1.25,502.44],[1,1.24,519.24],[2,1.21,242.82]],"batl":[[0,1.31,42.01],[1,1.32,488.99],[2,1.33,505.8]],"ltp":1.33,"tv":25758.62,"id":8979329}]}]}
{"op":"mcm","clk":"1009190006","pt":1580642620646,"mc":[{"id":"1.168224328","rc":[{"batb":[[0,4.2,2.57]],"batl":[[0,5.5,2.5],[1,6,2],[2,7,2]],"ltp":3.6,"tv":2642.23,"id":2397396},{"batl":[[0,1.32,488.99],[1,1.33,505.8],[2,1.34,123.25]],"ltp":1.33,"tv":25758.62,"id":8979329}]}]}
{"op":"mcm","clk":"1009190818","pt":1580642626372,"mc":[{"id":"1.168224328","rc":[{"batb":[[0,1.25,1368.22],[1,1.24,1205.72]],"batl":[[0,1.28,411.05],[1,1.29,521.36],[2,1.32,488.99]],"ltp":1.33,"tv":25758.62,"id":8979329}]}]}
{"op":"mcm","clk":"1009190943","pt":1580642627275,"mc":[{"id":"1.168224328","rc":[{"batb":[[0,1.25,502.44],[1,1.24,519.24]],"batl":[[0,1.32,488.99],[1,1.33,505.8],[2,1.34,123.25]],"ltp":1.33,"tv":25758.62,"id":8979329}]}]}
{"op":"mcm","clk":"1009191399","pt":1580642630469,"mc":[{"id":"1.168224328","rc":[{"batb":[[0,3.9,55.37],[1,3.75,2.43],[2,3.55,3.39]],"ltp":3.6,"tv":2642.23,"id":2397396}]}]}
{"op":"mcm","clk":"1009191750","pt":1580642632769,"mc":[{"id":"1.168224328","rc":[{"batb":[[0,1.21,242.82],[1,1.2,1036.47],[2,1.19,1180.63]],"ltp":1.33,"tv":25758.62,"id":8979329}]}]}
{"op":"mcm","clk":"1009191998","pt":1580642634368,"mc":[{"id":"1.168224328","rc":[{"batb":[[0,1.2,1036.47],[1,1.19,1180.63],[2,1.17,94.97]],"ltp":1.33,"tv":25758.62,"id":8979329}]}]}
{"op":"mcm","clk":"1009192137","pt":1580642635262,"mc":[{"id":"1.168224328","rc":[{"trd":[[5.5,6.2]],"batb":[[0,5.5,2.12],[1,3.9,55.37],[2,3.75,2.43]],"batl":[[0,6,2],[1,6.4,278],[2,6.8,274.04]],"ltp":5.5,"tv":2644.72,"id":2397396},{"trd":[[1.22,118.91]],"batb":[[0,1.2,2911.47]],"batl":[[0,1.21,14.89],[1,1.22,2906.83],[2,1.23,1955.73]],"ltp":1.22,"tv":25769.87,"id":8979329}],"tv":28414.59}]}
{"op":"mcm","clk":"1009192266","pt":1580642636272,"mc":[{"id":"1.168224328","rc":[{"batb":[[1,5.4,48.39],[2,5.1,2.7]],"batl":[[0,5.9,8.4],[1,6,2],[2,6.4,278]],"ltp":5.5,"tv":2644.72,"id":2397396},{"batb":[[0,1.2,3079.51]],"ltp":1.22,"tv":25769.87,"id":8979329}]}]}
{"op":"mcm","clk":"1009192533","pt":1580642638177,"mc":[{"id":"1.168224328","rc":[{"batl":[[1,1.22,2909.84]],"ltp":1.22,"tv":25769.87,"id":8979329}]}]}
{"op":"mcm","clk":"1009193325","pt":1580642643293,"mc":[{"id":"1.168224328","rc":[{"trd":[[1.21,2467.71]],"batl":[[0,1.21,13.11]],"ltp":1.21,"tv":25773.43,"id":8979329}],"tv":28418.15}]}
{"op":"mcm","clk":"1009194296","pt":1580642650098,"mc":[{"id":"1.168224328","rc":[{"batb":[[0,5.1,2.7],[1,5,10.08],[2,4.4,77.27]],"batl":[[1,11,2],[2,18,2]],"ltp":5.5,"tv":2644.72,"id":2397396},{"batb":[[0,1.2,193.14],[1,1.13,213.41],[2,1.11,1528.82]],"batl":[[0,1.22,3.01],[1,1.25,42.01],[2,1.27,211.73]],"ltp":1.21,"tv":25773.43,"id":8979329}]}]}
{"op":"mcm","clk":"1009194410","pt":1580642651037,"mc":[{"id":"1.168224328","rc":[{"batb":[[1,4.4,77.27],[2,4.3,2.08]],"batl":[[0,11,2],[1,18,2],[2,1000,0.02]],"ltp":5.5,"tv":2644.72,"id":2397396},{"batb":[[0,1.21,8.18],[1,1.2,25.1],[2,1.13,213.41]],"batl":[[1,1.27,211.73],[2,1.29,75]],"ltp":1.21,"tv":25773.43,"id":8979329}]}]}
{"op":"mcm","clk":"1009194500","pt":1580642651600,"mc":[{"id":"1.168224328","rc":[{"batb":[[0,1.21,9.89]],"ltp":1.21,"tv":25773.43,"id":8979329}]}]}
{"op":"mcm","clk":"1009194699","pt":1580642652914,"mc":[{"id":"1.168224328","rc":[{"batb":[[2,1.13,745.18]],"batl":[[2,1.29,401.3]],"ltp":1.21,"tv":25773.43,"id":8979329}]}]}
{"op":"mcm","clk":"1009194908","pt":1580642654203,"mc":[{"id":"1.168224328","rc":[{"batl":[[2,1.29,75]],"ltp":1.21,"tv":25773.43,"id":8979329}]}]}
{"op":"mcm","clk":"1009194979","pt":1580642654681,"mc":[{"id":"1.168224328","rc":[{"batb":[[0,1.21,11.67]],"ltp":1.21,"tv":25773.43,"id":8979329}]}]}
{"op":"mcm","clk":"1009195206","pt":1580642656188,"mc":[{"id":"1.168224328","rc":[{"batb":[[0,1.21,13.02],[2,1.13,531.77]],"ltp":1.21,"tv":25773.43,"id":8979329}]}]}
{"op":"mcm","clk":"1009195372","pt":1580642657314,"mc":[{"id":"1.168224328","rc":[{"batb":[[0,8.6,2],[1,5.1,2.7],[2,4.4,77.27]],"batl":[[0,10.5,201],[1,11,2],[2,12,229.18]],"ltp":5.5,"tv":2644.72,"id":2397396},{"trd":[[1.13,116.2],[1.2,50.2],[1.21,2493.75]],"batb":[[0,1.13,2464.82],[1,1.12,1189.79],[2,1.11,844.49]],"batl":[[0,1.14,1748],[1,1.15,3247.39],[2,1.16,351.01]],"ltp":1.13,"tv":25965.87,"id":8979329}],"tv":28610.59}]}
{"op":"mcm","clk":"1009195488","pt":1580642658012,"mc":[{"id":"1.168224328","rc":[{"batb":[[1,8,40.21],[2,6.8,59.33]],"batl":[[0,9.4,4.2],[1,10.5,201],[2,11,2]],"ltp":5.5,"tv":2644.72,"id":2397396},{"batb":[[1,1.12,1357.83]],"batl":[[2,1.16,319.71]],"ltp":1.13,"tv":25965.87,"id":8979329}]}]}
{"op":"mcm","clk":"1009195816","pt":1580642660113,"mc":[{"id":"1.168224328","rc":[{"batb":[[2,7.6,5.88]],"ltp":5.5,"tv":2644.72,"id":2397396},{"batl":[[1,1.15,3289.4]],"ltp":1.13,"tv":25965.87,"id":8979329}]}]}
{"op":"mcm","clk":"1009195871","pt":1580642660450,"mc":[{"id":"1.168224328","rc":[{"batb":[[1,1.12,1391.47]],"batl":[[1,1.15,3320.97]],"ltp":1.13,"tv":25965.87,"id":8979329}]}]}
{"op":"mcm","clk":"1009197049","pt":1580642668350,"mc":[{"id":"1.168224328","rc":[{"trd":[[1.14,3.56]],"batl":[[0,1.14,1746.22]],"ltp":1.14,"tv":25969.43,"id":8979329}],"tv":28614.16}]}
{"op":"mcm","clk":"1009197257","pt":1580642669849,"mc":[{"id":"1.168224328","rc":[{"batl":[[1,10,5.4],[2,10.5,201]],"ltp":5.5,"tv":2644.72,"id":2397396},{"trd":[[1.13,209.02]],"batb":[[0,1.13,2418.41]],"ltp":1.13,"tv":26062.25,"id":8979329}],"tv":28706.98}]}
{"op":"mcm","clk":"1009197768","pt":1580642673331,"mc":[{"id":"1.168224328","rc":[{"trd":[[1.13,409.02]],"batb":[[0,1.13,2365.73]],"ltp":1.13,"tv":26262.25,"id":8979329}],"tv":28906.98}]}
{"op":"mcm","clk":"1009197882","pt":1580642674120,"mc":[{"id":"1.168224328","rc":[{"trd":[[1.14,10.68]],"batl":[[0,1.14,1742.66],[1,1.15,3096.82],[2,1.22,1048.08]],"ltp":1.14,"tv":26269.37,"id":8979329}],"tv":28914.1}]}
{"op":"mcm","clk":"1009197964","pt":1580642674709,"mc":[{"id":"1.168224328","rc":[{"trd":[[8.6,3.56]],"batb":[[0,8,40.43],[1,7.6,5.88],[2,6.8,59.33]],"ltp":8.6,"tv":2648.28,"id":2397396}],"tv":28917.66}]}
{"op":"mcm","clk":"1009198296","pt":1580642677219,"mc":[{"id":"1.168224328","rc":[{"trd":[[1.14,16.14]],"batb":[[0,1.13,2409.84],[1,1.12,1473.74]],"batl":[[0,1.14,2046.82]],"ltp":1.14,"tv":26274.83,"id":8979329}],"tv":28923.12}]}
{"op":"mcm","clk":"1009198426","pt":1580642678037,"mc":[{"id":"1.168224328","rc":[{"trd":[[1.14,17.12]],"batl":[[0,1.14,2046.33]],"ltp":1.14,"tv":26275.81,"id":8979329}],"tv":28924.1}]}
{"op":"mcm","clk":"1009198606","pt":1580642679221,"mc":[{"id":"1.168224328","rc":[{"trd":[[1.14,20.68]],"batl":[[0,1.14,2044.55]],"ltp":1.14,"tv":26279.37,"id":8979329}],"tv":28927.66}]}
{"op":"mcm","clk":"1009198721","pt":1580642680126,"mc":[{"id":"1.168224328","rc":[{"batl":[[1,10.5,201],[2,11,2]],"ltp":8.6,"tv":2648.28,"id":2397396}]}]}
{"op":"mcm","clk":"1009199187","pt":1580642683043,"mc":[{"id":"1.168224328","rc":[{"batl":[[0,9.2,4.53],[1,9.4,4.2],[2,10.5,201]],"ltp":8.6,"tv":2648.28,"id":2397396},{"trd":[[1.14,24.24]],"batl":[[0,1.14,2082.94]],"ltp":1.14,"tv":26282.93,"id":8979329}],"tv":28931.22}]}
{"op":"mcm","clk":"1009199468","pt":1580642685262,"mc":[{"id":"1.168224328","rc":[{"batl":[[2,1.2,63]],"ltp":1.14,"tv":26282.93,"id":8979329}]}]}
{"op":"mcm","clk":"1009200829","pt":1580642694832,"mc":[{"id":"1.168224328","rc":[{"trd":[[1.13,419.04]],"batb":[[0,1.13,2404.83]],"ltp":1.13,"tv":26292.95,"id":8979329}],"tv":28941.24}]}
{"op":"mcm","clk":"1009202716","pt":1580642708760,"mc":[{"id":"1.168224328","rc":[{"trd":[[1.14,34.84]],"batl":[[0,1.14,2077.64]],"ltp":1.14,"tv":26303.55,"id":8979329}],"tv":28951.84}]}
{"op":"mcm","clk":"1009202857","pt":1580642709783,"mc":[{"id":"1.168224328","rc":[{"trd":[[1.14,38.41]],"batl":[[0,1.14,2075.86]],"ltp":1.14,"tv":26307.11,"id":8979329}],"tv":28955.4}]}
{"op":"mcm","clk":"1009203353","pt":1580642713073,"mc":[{"id":"1.168224328","rc":[{"trd":[[8,375.88],[8.6,4]],"batb":[[0,7.6,5.88],[1,6.8,59.33],[2,4.3,2.08]],"batl":[[0,8,398.55],[1,9.2,4.53],[2,9.4,4.2]],"ltp":8.0,"tv":3024.6,"id":2397396},{"trd":[[1.14,2114.27]],"batb":[[1,1.12,1303.79]],"batl":[[0,1.15,3096.82],[1,1.2,63],[2,1.22,1048.08]],"ltp":1.14,"tv":28382.97,"id":8979329}],"tv":31407.58}]}
{"op":"mcm","clk":"1009203654","pt":1580642715286,"mc":[{"id":"1.168224328","rc":[{"trd":[[8,432.76]],"batl":[[0,8,341.67]],"ltp":8.0,"tv":3081.48,"id":2397396},{"trd":[[1.14,2518.16]],"ltp":1.14,"tv":28786.87,"id":8979329}],"tv":31868.35}]}
{"op":"mcm","clk":"1009203793","pt":1580642716395,"mc":[{"id":"1.168224328","rc":[{"trd":[[8,436.75]],"batb":[[0,7.8,42.25],[1,7.6,5.88],[2,6.6,62.32]],"batl":[[0,8,339.67]],"ltp":8.0,"tv":3085.47,"id":2397396},{"batb":[[0,1.14,12.01],[1,1.13,2578.29],[2,1.12,2122.79]],"batl":[[0,1.15,3235.7],[1,1.16,404.24],[2,1.2,63]],"ltp":1.14,"tv":28786.87,"id":8979329}],"tv":31872.35}]}
{"op":"mcm","clk":"1009204378","pt":1580642720874,"mc":[{"id":"1.168224328","rc":[{"batb":[[0,1.13,2578.29],[1,1.12,2122.79],[2,1.1,1183.21]],"ltp":1.14,"tv":28786.87,"id":8979329}]}]}
{"op":"mcm","clk":"1009204662","pt":1580642722686,"mc":[{"id":"1.168224328","rc":[{"batl":[[1,9.4,4.2],[2,10.5,201]],"ltp":8.0,"tv":3085.47,"id":2397396}]}]}
{"op":"mcm","clk":"1009204863","pt":1580642723990,"mc":[{"id":"1.168224328","rc":[{"trd":[[1.15,24.02]],"batl":[[0,1.15,3223.69]],"ltp":1.15,"tv":28810.88,"id":8979329}],"tv":31896.36}]}
{"op":"mcm","clk":"1009205087","pt":1580642725596,"mc":[{"id":"1.168224328","rc":[{"batl":[[1,8.6,4.43],[2,9.4,4.2]],"ltp":8.0,"tv":3085.47,"id":2397396},{"batl":[[0,1.15,3258.73]],"ltp":1.15,"tv":28810.88,"id":8979329}]}]}
{"op":"mcm","clk":"1009205313","pt":1580642727117,"mc":[{"id":"1.168224328","rc":[{"batb":[[0,1.14,4.64],[1,1.13,2578.29],[2,1.12,2122.79]],"ltp":1.15,"tv":28810.88,"id":8979329}]}]}
{"op":"mcm","clk":"1009205499","pt":1580642728284,"mc":[{"id":"1.168224328","rc":[{"batb":[[0,1.14,6.42]],"ltp":1.15,"tv":28810.88,"id":8979329}]}]}
{"op":"mcm","clk":"1009206409","pt":1580642734297,"mc":[{"id":"1.168224328","rc":[{"batb":[[0,1.14,11.06]],"ltp":1.15,"tv":28810.88,"id":8979329}]}]}
{"op":"mcm","clk":"1009207215","pt":1580642740244,"mc":[{"id":"1.168224328","rc":[{"batl":[[1,9.4,4.2],[2,11,2]],"ltp":8.0,"tv":3085.47,"id":2397396},{"batb":[[1,1.13,1991.15],[2,1.12,987.04]],"batl":[[0,1.15,1948.4],[1,1.2,63],[2,1.22,3.01]],"ltp":1.15,"tv":28810.88,"id":8979329}]}]}
{"op":"mcm","clk":"1009207278","pt":1580642740604,"mc":[{"id":"1.168224328","rc":[{"batb":[[0,6.6,62.32],[1,4,37.86],[2,3.5,37.86]],"batl":[[1,11,2],[2,1000,0.02]],"ltp":8.0,"tv":3085.47,"id":2397396},{"batb":[[1,1.1,1183.21],[2,1.06,955.61]],"batl":[[0,1.2,63],[1,1.22,3.01],[2,1.29,75]],"ltp":1.15,"tv":28810.88,"id":8979329}]}]}
{"op":"mcm","clk":"1009207655","pt":1580642743322,"mc":[{"id":"1.168224328","rc":[{"batl":[[1,10.5,2]],"ltp":8.0,"tv":3085.47,"id":2397396},{"batb":[[1,1.11,1881.4],[2,1.1,1009.07]],"batl":[[0,1.18,999.77],[1,1.19,635.11],[2,1.2,63]],"ltp":1.15,"tv":28810.88,"id":8979329}]}]}
{"op":"mcm","clk":"1009207708","pt":1580642743731,"mc":[{"id":"1.168224328","rc":[{"batb":[[0,6.4,62.32]],"ltp":8.0,"tv":3085.47,"id":2397396},{"batl":[[0,1.2,63],[1,1.22,3.01],[2,1.29,75]],"ltp":1.15,"tv":28810.88,"id":8979329}]}]}
{"op":"mcm","clk":"1009208097","pt":1580642746336,"mc":[{"id":"1.168224328","rc":[{"trd":[[8,776.43]],"batb":[[0,8,340.02],[1,6.4,62.32],[2,4,37.86]],"batl":[[0,10.5,2],[1,11,279],[2,12,95.08]],"ltp":8.0,"tv":3425.15,"id":2397396},{"trd":[[1.11,2090.14],[1.14,4926.46]],"batb":[[0,1.11,836.33],[1,1.1,1009.07],[2,1.05,152.2]],"batl":[[0,1.13,19.42],[1,1.14,2019],[2,1.16,1847.87]],"ltp":1.11,"tv":33309.32,"id":8979329}],"tv":36734.48}]}
{"op":"mcm","clk":"1009208208","pt":1580642747089,"mc":[{"id":"1.168224328","rc":[{"batb":[[0,8.6,34.07],[1,8,34],[2,7.2,49.02]],"ltp":8.0,"tv":3425.15,"id":2397396},{"batb":[[2,1.09,1030.34]],"batl":[[0,1.13,724.64],[1,1.14,2536.89],[2,1.16,184.79]],"ltp":1.11,"tv":33309.32,"id":8979329}]}]}
{"op":"mcm","clk":"1009208331","pt":1580642747939,"mc":[{"id":"1.168224328","rc":[{"batl":[[0,10,4.2],[1,10.5,2],[2,11,279]],"ltp":8.0,"tv":3425.15,"id":2397396},{"batb":[[0,1.11,1004.37]],"ltp":1.11,"tv":33309.32,"id":8979329}]}]}
{"op":"mcm","clk":"1009208545","pt":1580642749557,"mc":[{"id":"1.168224328","rc":[{"batb":[[1,8.2,5.04],[2,8,34]],"ltp":8.0,"tv":3425.15,"id":2397396},{"batb":[[0,1.11,1404.11],[1,1.1,1521.31]],"batl":[[0,1.13,1209.79],[1,1.14,2578.9]],"ltp":1.11,"tv":33309.32,"id":8979329}]}]}
{"op":"mcm","clk":"1009208850","pt":1580642751403,"mc":[{"id":"1.168224328","rc":[{"batl":[[2,1.16,247.79]],"ltp":1.11,"tv":33309.32,"id":8979329}]}]}
{"op":"mcm","clk":"1009209064","pt":1580642752719,"mc":[{"id":"1.168224328","rc":[{"batl":[[2,11,281]],"ltp":8.0,"tv":3425.15,"id":2397396},{"batb":[[1,1.1,1713.45]],"batl":[[2,1.15,117.7]],"ltp":1.11,"tv":33309.32,"id":8979329}]}]}
{"op":"mcm","clk":"1009209299","pt":1580642754320,"mc":[{"id":"1.168224328","rc":[{"batb":[[0,8.2,5.04],[1,8,34],[2,7.6,3.64]],"batl":[[2,11,2]],"ltp":8.0,"tv":3425.15,"id":2397396},{"batb":[[0,1.11,168.04],[1,1.1,780.2],[2,1.09,1015]],"batl":[[0,1.14,42.01],[1,1.15,117.7],[2,1.16,352.26]],"ltp":1.11,"tv":33309.32,"id":8979329}]}]}
{"op":"mcm","clk":"1009209363","pt":1580642754749,"mc":[{"id":"1.168224328","rc":[{"batb":[[0,7.2,52.64],[1,4,37.86],[2,3.5,37.86]],"batl":[[0,11,2],[1,1000,0.02],[2,11,0]],"ltp":8.0,"tv":3425.15,"id":2397396},{"batb":[[0,1.1,780.2],[1,1.09,1015],[2,1.05,1221.76]],"batl":[[0,1.16,167.47],[1,1.18,63],[2,1.2,63]],"ltp":1.11,"tv":33309.32,"id":8979329}]}]}
{"op":"mcm","clk":"1009209746","pt":1580642757330,"mc":[{"id":"1.168224328","rc":[{"batb":[[0,1.11,152.59],[1,1.1,1171.18],[2,1.09,1362.25]],"batl":[[0,1.15,789.34],[1,1.16,1053.47],[2,1.18,63]],"ltp":1.11,"tv":33309.32,"id":8979329}]}]}
{"op":"mcm","clk":"1009209863","pt":1580642758139,"mc":[{"id":"1.168224328","rc":[{"batl":[[0,8.6,2.1],[1,11,2],[2,1000,0.02]],"ltp":8.0,"tv":3425.15,"id":2397396},{"batb":[[0,1.1,267.96],[1,1.09,1015],[2,1.05,1221.76]],"batl":[[0,1.16,167.47],[1,1.18,63],[2,1.2,63]],"ltp":1.11,"tv":33309.32,"id":8979329}]}]}
{"op":"mcm","clk":"1009210131","pt":1580642759911,"mc":[{"id":"1.168224328","rc":[{"trd":[[8.6,6.1]],"batl":[[0,11,2],[1,1000,0.02],[2,1000,0]],"ltp":8.6,"tv":3427.25,"id":2397396},{"trd":[[1.13,458.49]],"batb":[[0,1.11,1743.7],[1,1.1,267.96],[2,1.09,1015]],"batl":[[0,1.13,573.25],[1,1.14,1102.11],[2,1.16,167.47]],"ltp":1.13,"tv":33348.77,"id":8979329}],"tv":36776.03}]}
{"op":"mcm","clk":"1009210326","pt":1580642761312,"mc":[{"id":"1.168224328","rc":[{"batb":[[0,7.6,3.64],[1,7.2,52.64],[2,4,37.86]],"batl":[[0,10.5,2],[1,11,2],[2,1000,0.02]],"ltp":8.6,"tv":3427.25,"id":2397396},{"batb":[[0,1.11,1887.29]],"batl":[[2,1.15,123.9]],"ltp":1.13,"tv":33348.77,"id":8979329}]}]}
{"op":"mcm","clk":"1009210433","pt":1580642762164,"mc":[{"id":"1.168224328","rc":[{"batb":[[0,1.11,143.59]],"batl":[[0,1.15,123.9],[1,1.16,167.47],[2,1.18,63]],"ltp":1.13,"tv":33348.77,"id":8979329}]}]}
{"op":"mcm","clk":"1009210470","pt":1580642762432,"mc":[{"id":"1.168224328","rc":[{"batb":[[0,7.2,52.64],[1,4,37.86],[2,3.5,37.86]],"batl":[[0,11,2],[1,1000,0.02],[2,1000,0]],"ltp":8.6,"tv":3427.25,"id":2397396},{"batb":[[0,1.1,267.96],[1,1.09,1015],[2,1.05,1221.76]],"batl":[[0,1.16,167.47],[1,1.18,63],[2,1.2,63]],"ltp":1.13,"tv":33348.77,"id":8979329}]}]}
{"op":"mcm","clk":"1009210817","pt":1580642765061,"mc":[{"id":"1.168224328","rc":[{"batb":[[0,1.1,1699.22],[1,1.09,1346.3]],"batl":[[0,1.15,774.29],[1,1.16,1068.39],[2,1.18,63]],"ltp":1.13,"tv":33348.77,"id":8979329}]}]}
{"op":"mcm","clk":"1009210989","pt":1580642766133,"mc":[{"id":"1.168224328","rc":[{"batb":[[0,7.6,3.64],[1,7.2,52.64],[2,4,37.86]],"ltp":8.6,"tv":3427.25,"id":2397396},{"batl":[[0,1.15,884.59]],"ltp":1.13,"tv":33348.77,"id":8979329}]}]}
{"op":"mcm","clk":"1009211914","pt":1580642772363,"mc":[{"id":"1.168224328","rc":[{"batl":[[0,10.5,2],[1,11,2],[2,1000,0.02]],"ltp":8.6,"tv":3427.25,"id":2397396},{"batb":[[0,1.11,158.59],[1,1.1,1699.22],[2,1.09,1346.3]],"ltp":1.13,"tv":33348.77,"id":8979329}]}]}
{"op":"mcm","clk":"1009211942","pt":1580642772611,"mc":[{"id":"1.168224328","rc":[{"batl":[[0,11,2],[1,1000,0.02],[2,1000,0]],"ltp":8.6,"tv":3427.25,"id":2397396},{"batb":[[0,1.1,1699.22],[1,1.09,1346.3],[2,1.05,1221.76]],"ltp":1.13,"tv":33348.77,"id":8979329}]}]}
{"op":"mcm","clk":"1009212530","pt":1580642776751,"mc":[{"id":"1.168224328","rc":[{"batb":[[0,1.1,267.96],[1,1.09,1015]],"ltp":1.13,"tv":33348.77,"id":8979329}]}]}
{"op":"mcm","clk":"1009212699","pt":1580642777968,"mc":[{"id":"1.168224328","rc":[{"batl":[[1,1.16,1005.39]],"ltp":1.13,"tv":33348.77,"id":8979329}]}]}
{"op":"mcm","clk":"1009212953","pt":1580642779237,"mc":[{"id":"1.168224328","rc":[{"batl":[[0,10.5,2],[1,11,2],[2,1000,0.02]],"ltp":8.6,"tv":3427.25,"id":2397396},{"batb":[[0,1.11,165.59],[1,1.1,267.96],[2,1.09,1015]],"batl":[[2,1.2,63]],"ltp":1.13,"tv":33348.77,"id":8979329}]}]}
{"op":"mcm","clk":"1009213097","pt":1580642780244,"mc":[{"id":"1.168224328","rc":[{"batb":[[2,5.8,80.02]],"batl":[[0,8,5.18],[1,9,208],[2,10,217.82]],"ltp":8.6,"tv":3427.25,"id":2397396},{"batb":[[0,1.13,3938.39],[1,1.12,506.94],[2,1.11,866.52]],"batl":[[0,1.15,2841.11],[1,1.16,2373.93]],"ltp":1.13,"tv":33348.77,"id":8979329}]}]}
{"op":"mcm","clk":"1009213414","pt":1580642782375,"mc":[{"id":"1.168224328","rc":[{"batb":[[1,7.4,5.88],[2,7.2,52.64]],"batl":[[1,9,213.04]],"ltp":8.6,"tv":3427.25,"id":2397396},{"batb":[[2,1.11,2461.65]],"batl":[[1,1.16,2415.94]],"ltp":1.13,"tv":33348.77,"id":8979329}]}]}
{"op":"mcm","clk":"1009213440","pt":1580642782544,"mc":[{"id":"1.168224328","rc":[{"batb":[[2,1.11,866.52]],"ltp":1.13,"tv":33348.77,"id":8979329}]}]}
{"op":"mcm","clk":"1009213863","pt":1580642785687,"mc":[{"id":"1.168224328","rc":[{"batb":[[0,7.4,5.88],[1,7.2,52.64],[2,6.4,2.63]],"ltp":8.6,"tv":3427.25,"id":2397396},{"batl":[[0,1.15,2730.81]],"ltp":1.13,"tv":33348.77,"id":8979329}]}]}
{"op":"mcm","clk":"1009214088","pt":1580642787191,"mc":[{"id":"1.168224328","rc":[{"batb":[[1,1.12,569.94]],"ltp":1.13,"tv":33348.77,"id":8979329}]}]}
{"op":"mcm","clk":"1009214251","pt":1580642788250,"mc":[{"id":"1.168224328","rc":[{"trd":[[8,781.61]],"batl":[[0,9,213.04],[1,10,217.82],[2,11,2]],"ltp":8.0,"tv":3432.43,"id":2397396},{"trd":[[1.13,501.93],[1.14,4962.81]],"batb":[[0,1.13,3916.67]],"ltp":1.13,"tv":33428.56,"id":8979329}],"tv":36861.0}]}
{"op":"mcm","clk":"1009214311","pt":1580642788670,"mc":[{"id":"1.168224328","rc":[{"batl":[[1,9.4,2],[2,10,217.82]],"ltp":8.0,"tv":3432.43,"id":2397396},{"batb":[[1,1.12,707.48],[2,1.11,1024.11]],"ltp":1.13,"tv":33428.56,"id":8979329}]}]}
{"op":"mcm","clk":"1009214849","pt":1580642792191,"mc":[{"id":"1.168224328","rc":[{"trd":[[1.15,24.65]],"batb":[[0,1.13,3979.67]],"batl":[[0,1.15,2730.49]],"ltp":1.15,"tv":33429.2,"id":8979329}],"tv":36861.64}]}
{"op":"mcm","clk":"1009215261","pt":1580642794895,"mc":[{"id":"1.168224328","rc":[{"trd":[[8.8,2.26]],"ltp":8.8,"tv":3434.69,"id":2397396},{"trd":[[1.13,519.53]],"batb":[[0,1.13,3962.07]],"ltp":1.13,"tv":33446.8,"id":8979329}],"tv":36881.5}]}
{"op":"mcm","clk":"1009215496","pt":1580642796292,"mc":[{"id":"1.168224328","rc":[{"batl":[[0,9,5.04],[2,10.5,2]],"ltp":8.8,"tv":3434.69,"id":2397396},{"batl":[[1,1.16,1047.4]],"ltp":1.13,"tv":33446.8,"id":8979329}]}]}
{"op":"mcm","clk":"1009215633","pt":1580642797169,"mc":[{"id":"1.168224328","rc":[{"batb":[[1,6.4,2.63],[2,5.8,80.02]],"batl":[[1,10.5,2],[2,11,2]],"ltp":8.8,"tv":3434.69,"id":2397396},{"batb":[[0,1.13,63],[1,1.12,63]],"batl":[[0,1.16,42.01],[1,1.2,63],[2,1.22,3.01]],"ltp":1.13,"tv":33446.8,"id":8979329}]}]}
{"op":"mcm","clk":"1009215923","pt":1580642798606,"mc":[{"id":"1.168224328","rc":[{"batb":[[0,6.4,2.63],[1,5.8,80.02],[2,4,37.86]],"batl":[[0,10.5,2],[1,11,2],[2,1000,0.02]],"ltp":8.8,"tv":3434.69,"id":2397396},{"batl":[[0,1.2,63],[1,1.22,3.01],[2,1.29,75]],"ltp":1.13,"tv":33446.8,"id":8979329}]}]}
{"op":"mcm","clk":"1009216228","pt":1580642800369,"mc":[{"id":"1.168224328","rc":[{"batl":[[0,9.4,2],[1,10.5,2],[2,11,2]],"ltp":8.8,"tv":3434.69,"id":2397396},{"batb":[[1,1.12,201.29]],"ltp":1.13,"tv":33446.8,"id":8979329}]}]}
{"op":"mcm","clk":"1009216319","pt":1580642801015,"mc":[{"id":"1.168224328","rc":[{"batl":[[0,10.5,2],[1,11,2],[2,1000,0.02]],"ltp":8.8,"tv":3434.69,"id":2397396},{"batb":[[1,1.12,63]],"ltp":1.13,"tv":33446.8,"id":8979329}]}]}
{"op":"mcm","clk":"1009216467","pt":1580642802233,"mc":[{"id":"1.168224328","rc":[{"batb":[[0,1.14,759.94],[1,1.13,1009.17],[2,1.12,63]],"batl":[[0,1.16,999.19],[1,1.17,663.63],[2,1.2,63]],"ltp":1.13,"tv":33446.8,"id":8979329}]}]}
{"op":"mcm","clk":"1009216773","pt":1580642803940,"mc":[{"id":"1.168224328","rc":[{"batl":[[0,9.4,2],[1,10.5,2],[2,11,2]],"ltp":8.8,"tv":3434.69,"id":2397396},{"batb":[[2,1.12,211.04]],"ltp":1.13,"tv":33446.8,"id":8979329}]}]}
{"op":"mcm","clk":"1009217253","pt":1580642807213,"mc":[{"id":"1.168224328","rc":[{"batl":[[0,10.5,2],[1,11,2],[2,1000,0.02]],"ltp":8.8,"tv":3434.69,"id":2397396},{"batb":[[0,1.13,63],[1,1.12,63],[2,1.11,1024.11]],"batl":[[0,1.2,63],[1,1.22,3.01],[2,1.29,75]],"ltp":1.13,"tv":33446.8,"id":8979329}]}]}
{"op":"mcm","clk":"1009217644","pt":1580642809329,"mc":[{"id":"1.168224328","rc":[{"batb":[[0,5.8,80.02],[1,4,37.86],[2,3.5,37.86]],"ltp":8.8,"tv":3434.69,"id":2397396}]}]}
{"op":"mcm","clk":"1009217806","pt":1580642810347,"mc":[{"id":"1.168224328","rc":[{"batl":[[0,9.4,2],[1,10.5,2],[2,11,2]],"ltp":8.8,"tv":3434.69,"id":2397396},{"batb":[[1,1.12,213.04],[2,1.11,2767.81]],"batl":[[0,1.19,741.88],[1,1.2,877.9],[2,1.22,3.01]],"ltp":1.13,"tv":33446.8,"id":8979329}]}]}
{"op":"mcm","clk":"1009217857","pt":1580642810634,"mc":[{"id":"1.168224328","rc":[{"batl":[[0,10.5,2],[1,11,2],[2,1000,0.02]],"ltp":8.8,"tv":3434.69,"id":2397396},{"batb":[[1,1.12,63]],"ltp":1.13,"tv":33446.8,"id":8979329}]}]}
{"op":"mcm","clk":"1009218817","pt":1580642816334,"mc":[{"id":"1.168224328","rc":[{"trd":[[1.13,523.07]],"batb":[[0,1.13,61.23]],"ltp":1.13,"tv":33450.34,"id":8979329}],"tv":36885.03}]}
{"op":"mcm","clk":"1009218975","pt":1580642817335,"mc":[{"id":"1.168224328","rc":[{"batl":[[0,9.4,2],[1,10.5,2],[2,11,2]],"ltp":8.8,"tv":3434.69,"id":2397396}]}]}
{"op":"mcm","clk":"1009219137","pt":1580642818257,"mc":[{"id":"1.168224328","rc":[{"batl":[[0,10.5,2],[1,11,2],[2,1000,0.02]],"ltp":8.8,"tv":3434.69,"id":2397396},{"batl":[[0,1.2,63],[1,1.22,3.01],[2,1.29,75]],"ltp":1.13,"tv":33450.34,"id":8979329}]}]}
{"op":"mcm","clk":"1009219301","pt":1580642819271,"mc":[{"id":"1.168224328","rc":[{"batb":[[0,1.12,63],[1,1.11,2767.81],[2,1.1,267.96]],"ltp":1.13,"tv":33450.34,"id":8979329}]}]}
{"op":"mcm","clk":"1009219461","pt":1580642820230,"mc":[{"id":"1.168224328","rc":[{"batb":[[0,1.11,2767.81],[1,1.1,267.96],[2,1.06,955.61]],"ltp":1.13,"tv":33450.34,"id":8979329}]}]}
{"op":"mcm","clk":"1009219626","pt":1580642821255,"mc":[{"id":"1.168224328","rc":[{"batb":[[0,8,4.65],[1,5.8,80.02],[2,4,37.86]],"batl":[[0,10.5,288],[1,11,71.82]],"ltp":8.8,"tv":3434.69,"id":2397396},{"batb":[[0,1.12,21.49],[1,1.11,2767.81],[2,1.1,966.2]],"batl":[[0,1.13,651.04],[1,1.14,1321.58],[2,1.15,2604.56]],"ltp":1.13,"tv":33450.34,"id":8979329}]}]}
{"op":"mcm","clk":"1009219832","pt":1580642822383,"mc":[{"id":"1.168224328","rc":[{"batb":[[0,8,49.01],[1,6.8,57.52]],"batl":[[0,10,4.2],[1,10.5,288],[2,11,71.82]],"ltp":8.8,"tv":3434.69,"id":2397396},{"batb":[[1,1.11,2935.85],[2,1.1,1942.25]],"batl":[[1,1.14,1363.59]],"ltp":1.13,"tv":33450.34,"id":8979329}]}]}
{"op":"mcm","clk":"1009220876","pt":1580642829343,"mc":[{"id":"1.168224328","rc":[{"batb":[[1,7.6,3.59],[2,7.2,3.57]],"ltp":8.8,"tv":3434.69,"id":2397396},{"batl":[[2,1.15,2710.26]],"ltp":1.13,"tv":33450.34,"id":8979329}]}]}
{"op":"mcm","clk":"1009221009","pt":1580642830355,"mc":[{"id":"1.168224328","rc":[{"trd":[[8.6,8.59]],"ltp":8.6,"tv":3437.18,"id":2397396},{"trd":[[1.13,542.06]],"batl":[[0,1.13,632.05]],"ltp":1.13,"tv":33469.33,"id":8979329}],"tv":36906.52}]}
{"op":"mcm","clk":"1009221997","pt":1580642837458,"mc":[{"id":"1.168224328","rc":[{"batb":[[1,1.11,3010.85]],"ltp":1.13,"tv":33469.33,"id":8979329}]}]}
{"op":"mcm","clk":"1009222543","pt":1580642841184,"mc":[{"id":"1.168224328","rc":[{"batb":[[0,1.11,3010.85],[1,1.1,1942.25],[2,1.09,75]],"batl":[[0,1.13,627.7]],"ltp":1.13,"tv":33469.33,"id":8979329}]}]}
{"op":"mcm","clk":"1009222702","pt":1580642842269,"mc":[{"id":"1.168224328","rc":[{"batl":[[1,10.5,2]],"ltp":8.6,"tv":3437.18,"id":2397396},{"batb":[[2,1.08,56.22]],"batl":[[2,1.15,262.26]],"ltp":1.13,"tv":33469.33,"id":8979329}]}]}
{"op":"mcm","clk":"1009222845","pt":1580642843084,"mc":[{"id":"1.168224328","rc":[{"batb":[[0,7.2,3.57],[1,6.8,57.2],[2,4,37.86]],"batl":[[0,11,2],[1,1000,0.02],[2,11,0]],"ltp":8.6,"tv":3437.18,"id":2397396},{"batb":[[0,1.11,75],[1,1.1,1244.01]],"batl":[[0,1.16,109.72],[1,1.2,63],[2,1.22,3.01]],"ltp":1.13,"tv":33469.33,"id":8979329}]}]}
{"op":"mcm","clk":"1009223133","pt":1580642844692,"mc":[{"id":"1.168224328","rc":[{"batb":[[2,1.09,56.22]],"ltp":1.13,"tv":33469.33,"id":8979329}]}]}
{"op":"mcm","clk":"1009223400","pt":1580642846300,"mc":[{"id":"1.168224328","rc":[{"batb":[[0,7.6,3.59],[1,7.2,3.57],[2,6.8,57.2]],"batl":[[0,10.5,2],[1,11,2],[2,1000,0.02]],"ltp":8.6,"tv":3437.18,"id":2397396},{"batb":[[0,1.11,235.59],[1,1.1,2970.18]],"batl":[[0,1.15,111.9],[1,1.16,109.72],[2,1.2,63]],"ltp":1.13,"tv":33469.33,"id":8979329}]}]}
{"op":"mcm","clk":"1009223551","pt":1580642847284,"mc":[{"id":"1.168224328","rc":[{"batb":[[0,7.2,3.57],[1,6.8,57.2],[2,4,37.86]],"batl":[[0,11,2],[1,1000,0.02],[2,1000,0]],"ltp":8.6,"tv":3437.18,"id":2397396},{"batb":[[0,1.1,2970.18],[1,1.09,56.22],[2,1.08,56.22]],"batl":[[0,1.16,109.72],[1,1.2,63],[2,1.22,3.01]],"ltp":1.13,"tv":33469.33,"id":8979329}]}]}
{"op":"mcm","clk":"1009223702","pt":1580642848299,"mc":[{"id":"1.168224328","rc":[{"batl":[[0,11,167],[1,12,111.48],[2,1000,0.02]],"ltp":8.6,"tv":3437.18,"id":2397396},{"batl":[[0,1.12,7518.12],[1,1.13,5110.94],[2,1.14,20.75]],"ltp":1.13,"tv":33469.33,"id":8979329}]}]}
{"op":"mcm","clk":"1009223891","pt":1580642849376,"mc":[{"id":"1.168224328","rc":[{"batb":[[0,9.2,3.57],[1,8.8,31.47],[2,7.8,41.39]],"ltp":8.6,"tv":3437.18,"id":2397396},{"batb":[[1,1.09,1117.95]],"batl":[[0,1.12,1150.99],[1,1.13,2502.59],[2,1.16,109.72]],"ltp":1.13,"tv":33469.33,"id":8979329}]}]}
{"op":"mcm","clk":"1009224037","pt":1580642850380,"mc":[{"id":"1.168224328","rc":[{"batb":[[2,8.6,5.04]],"batl":[[0,11,171.2]],"ltp":8.6,"tv":3437.18,"id":2397396},{"batb":[[0,1.1,3138.22]],"batl":[[1,1.13,2544.6]],"ltp":1.13,"tv":33469.33,"id":8979329}]}]}
{"op":"mcm","clk":"1009224468","pt":1580642852910,"mc":[{"id":"1.168224328","rc":[{"batl":[[2,1.14,75]],"ltp":1.13,"tv":33469.33,"id":8979329}]}]}
{"op":"mcm","clk":"1009224804","pt":1580642855023,"mc":[{"id":"1.168224328","rc":[{"batb":[[2,8.6,8.38]],"batl":[[0,10.5,2],[1,11,171.2],[2,12,111.48]],"ltp":8.6,"tv":3437.18,"id":2397396},{"batb":[[0,1.11,177.59],[1,1.1,3138.22],[2,1.09,1117.95]],"batl":[[1,1.13,2680.1],[2,1.14,194.25]],"ltp":1.13,"tv":33469.33,"id":8979329}]}]}
{"op":"mcm","clk":"1009225681","pt":1580642860314,"mc":[{"id":"1.168224328","rc":[{"batl":[[1,11,6.2],[2,1000,0.02]],"ltp":8.6,"tv":3437.18,"id":2397396},{"batl":[[0,1.12,1132.87],[1,1.13,1221.1]],"ltp":1.13,"tv":33469.33,"id":8979329}]}]}
{"op":"mcm","clk":"1009225761","pt":1580642860714,"mc":[{"id":"1.168224328","rc":[{"batb":[[1,8.6,3.34],[2,8,3.33]],"batl":[[0,11,2],[1,1000,0.02],[2,1000,0]],"ltp":8.6,"tv":3437.18,"id":2397396},{"batb":[[0,1.1,751.39],[1,1.09,1117.95],[2,1.08,56.22]],"batl":[[0,1.12,89.21],[1,1.13,557.26]],"ltp":1.13,"tv":33469.33,"id":8979329}]}]}
{"op":"mcm","clk":"1009225919","pt":1580642861827,"mc":[{"id":"1.168224328","rc":[{"batb":[[0,8.6,3.34],[1,8,3.33],[2,7.8,41.39]],"ltp":8.6,"tv":3437.18,"id":2397396},{"batb":[[0,1.1,826.39]],"batl":[[0,1.13,557.26],[1,1.14,119.25],[2,1.15,75]],"ltp":1.13,"tv":33469.33,"id":8979329}]}]}
{"op":"mcm","clk":"1009226201","pt":1580642863789,"mc":[{"id":"1.168224328","rc":[{"batb":[[1,1.09,2405.78]],"batl":[[1,1.14,1355.65]],"ltp":1.13,"tv":33469.33,"id":8979329}]}]}
{"op":"mcm","clk":"1009226287","pt":1580642864426,"mc":[{"id":"1.168224328","rc":[{"batb":[[1,1.09,1117.95]],"batl":[[1,1.14,119.25]],"ltp":1.13,"tv":33469.33,"id":8979329}]}]}
{"op":"mcm","clk":"1009226757","pt":1580642867399,"mc":[{"id":"1.168224328","rc":[{"batb":[[0,1.11,337.27],[1,1.1,1762.18],[2,1.09,1117.95]],"batl":[[0,1.12,634.4],[1,1.13,1219.55],[2,1.14,119.25]],"ltp":1.13,"tv":33469.33,"id":8979329}]}]}
{"op":"mcm","clk":"1009227037","pt":1580642869099,"mc":[{"id":"1.168224328","rc":[{"batb":[[0,1.1,826.39],[1,1.09,1117.95],[2,1.08,56.22]],"batl":[[0,1.13,557.26],[1,1.14,119.25],[2,1.16,109.72]],"ltp":1.13,"tv":33469.33,"id":8979329}]}]}
{"op":"mcm","clk":"1009227166","pt":1580642869941,"mc":[{"id":"1.168224328","rc":[{"trd":[[1.1,200]],"batb":[[0,1.1,726.39]],"ltp":1.1,"tv":33669.33,"id":8979329}],"tv":37106.52}]}
{"op":"mcm","clk":"1009227459","pt":1580642872027,"mc":[{"id":"1.168224328","rc":[{"batb":[[1,1.09,2405.78]],"batl":[[1,1.14,1355.65]],"ltp":1.1,"tv":33669.33,"id":8979329}]}]}
{"op":"mcm","clk":"1009228217","pt":1580642877219,"mc":[{"id":"1.168224328","rc":[{"batl":[[0,10.5,2],[1,11,2],[2,1000,0.02]],"ltp":8.6,"tv":3437.18,"id":2397396},{"batb":[[0,1.11,135.59],[1,1.1,726.39],[2,1.09,2405.78]],"ltp":1.1,"tv":33669.33,"id":8979329}]}]}
{"op":"mcm","clk":"1009228326","pt":1580642877935,"mc":[{"id":"1.168224328","rc":[{"batb":[[0,8,3.33],[1,7.8,41.39],[2,7.2,3.57]],"batl":[[0,11,2],[1,1000,0.02],[2,1000,0]],"ltp":8.6,"tv":3437.18,"id":2397396},{"batb":[[0,1.1,726.39],[1,1.09,2405.78],[2,1.08,56.22]],"batl":[[0,1.14,119.25],[1,1.16,109.72],[2,1.2,63]],"ltp":1.1,"tv":33669.33,"id":8979329}]}]}
{"op":"mcm","clk":"1009228439","pt":1580642878627,"mc":[{"id":"1.168224328","rc":[{"batb":[[0,1.1,651.39]],"ltp":1.1,"tv":33669.33,"id":8979329}]}]}
{"op":"mcm","clk":"1009228652","pt":1580642880334,"mc":[{"id":"1.168224328","rc":[{"batb":[[0,8.8,219.51],[1,8,3.33],[2,7.8,41.39]],"batl":[[0,11,6.97],[1,12,239],[2,13.5,105.61]],"ltp":8.6,"tv":3437.18,"id":2397396},{"batb":[[2,1.08,1376.32]],"batl":[[0,1.12,7550.34],[1,1.13,2459],[2,1.14,1910.79]],"ltp":1.1,"tv":33669.33,"id":8979329}]}]}
{"op":"mcm","clk":"1009228779","pt":1580642881209,"mc":[{"id":"1.168224328","rc":[{"batb":[[0,9.2,32.25],[1,8.8,53.66],[2,8,3.33]],"ltp":8.6,"tv":3437.18,"id":2397396},{"batb":[[2,1.08,2563.55]],"batl":[[0,1.11,652.4],[1,1.12,1228.62],[2,1.13,2459]],"ltp":1.1,"tv":33669.33,"id":8979329}]}]}
{"op":"mcm","clk":"1009228886","pt":1580642882030,"mc":[{"id":"1.168224328","rc":[{"batb":[[0,9.2,37.29]],"batl":[[1,11.5,3.36],[2,12,239]],"ltp":8.6,"tv":3437.18,"id":2397396},{"batl":[[1,1.12,1270.63]],"ltp":1.1,"tv":33669.33,"id":8979329}]}]}
{"op":"mcm","clk":"1009229694","pt":1580642887401,"mc":[{"id":"1.168224328","rc":[{"batb":[[2,8.6,3.64]],"ltp":8.6,"tv":3437.18,"id":2397396},{"batb":[[1,1.09,2596.39]],"batl":[[2,1.13,2605.5]],"ltp":1.1,"tv":33669.33,"id":8979329}]}]}
{"op":"mcm","clk":"1009229756","pt":1580642887826,"mc":[{"id":"1.168224328","rc":[{"trd":[[1.1,201.29]],"batb":[[0,1.1,650.75]],"ltp":1.1,"tv":33670.62,"id":8979329}],"tv":37107.81}]}
{"op":"mcm","clk":"1009230561","pt":1580642893727,"mc":[{"id":"1.168224328","rc":[{"trd":[[10,1.78]],"ltp":10.0,"tv":3438.96,"id":2397396},{"trd":[[1.11,2106.19]],"batl":[[0,1.11,636.35]],"ltp":1.11,"tv":33686.67,"id":8979329}],"tv":37125.64}]}
{"op":"mcm","clk":"1009231305","pt":1580642899322,"mc":[{"id":"1.168224328","rc":[{"batl":[[2,12.5,2]],"ltp":10.0,"tv":3438.96,"id":2397396},{"batl":[[2,1.13,146.5]],"ltp":1.11,"tv":33686.67,"id":8979329}]}]}
{"op":"mcm","clk":"1009231408","pt":1580642900174,"mc":[{"id":"1.168224328","rc":[{"batb":[[0,9.2,5.04],[1,8.8,31.71]],"batl":[[0,11.5,3.36],[1,12.5,2],[2,1000,0.02]],"ltp":10.0,"tv":3438.96,"id":2397396},{"batb":[[0,1.09,1056.36],[1,1.08,1243.45],[2,1.07,56.22]],"batl":[[0,1.12,1123.08],[1,1.13,146.5],[2,1.14,119.25]],"ltp":1.11,"tv":33686.67,"id":8979329}]}]}
{"op":"mcm","clk":"1009231492","pt":1580642900770,"mc":[{"id":"1.168224328","rc":[{"batb":[[0,8.8,31.71],[1,8.6,3.64],[2,8,3.33]],"batl":[[0,12.5,2],[1,1000,0.02],[2,1000,0]],"ltp":10.0,"tv":3438.96,"id":2397396},{"batl":[[0,1.12,1081.07]],"ltp":1.11,"tv":33686.67,"id":8979329}]}]}
{"op":"mcm","clk":"1009231619","pt":1580642901643,"mc":[{"id":"1.168224328","rc":[{"batl":[[0,1.12,792.9]],"ltp":1.11,"tv":33686.67,"id":8979329}]}]}
{"op":"mcm","clk":"1009231864","pt":1580642903387,"mc":[{"id":"1.168224328","rc":[{"batb":[[0,9.2,3.67],[1,8.8,31.71],[2,8.6,3.64]],"ltp":10.0,"tv":3438.96,"id":2397396},{"batl":[[0,1.12,920.86]],"ltp":1.11,"tv":33686.67,"id":8979329}]}]}
{"op":"mcm","clk":"1009232082","pt":1580642905051,"mc":[{"id":"1.168224328","rc":[{"batb":[[0,1.09,2022.02]],"batl":[[0,1.11,943.15],[1,1.12,920.86],[2,1.13,146.5]],"ltp":1.11,"tv":33686.67,"id":8979329}]}]}
{"op":"mcm","clk":"1009232299","pt":1580642906780,"mc":[{"id":"1.168224328","rc":[{"trd":[[10,13.9]],"ltp":10.0,"tv":3451.08,"id":2397396},{"trd":[[1.11,2215.34]],"batb":[[0,1.09,1056.36]],"batl":[[0,1.12,920.86],[1,1.13,146.5],[2,1.14,119.25]],"ltp":1.11,"tv":33795.82,"id":8979329}],"tv":37246.9}]}
{"op":"mcm","clk":"1009232446","pt":1580642907844,"mc":[{"id":"1.168224328","rc":[{"batb":[[1,1.08,1478.76]],"ltp":1.11,"tv":33795.82,"id":8979329}]}]}
{"op":"mcm","clk":"1009232836","pt":1580642910559,"mc":[{"id":"1.168224328","rc":[{"batb":[[0,1.09,1117.92],[1,1.08,2391.23]],"batl":[[0,1.12,1131.98],[1,1.13,863.72]],"ltp":1.11,"tv":33795.82,"id":8979329}]}]}
{"op":"mcm","clk":"1009233241","pt":1580642913290,"mc":[{"id":"1.168224328","rc":[{"batb":[[0,8.8,31.71],[1,8.6,3.64],[2,4,37.86]],"batl":[[0,11,2],[1,12.5,2],[2,1000,0.02]],"ltp":10.0,"tv":3451.08,"id":2397396},{"batb":[[0,1.1,175.14],[1,1.09,1117.92],[2,1.08,2391.23]],"batl":[[0,1.13,146.5],[1,1.22,3.01],[2,1.38,2889.99]],"ltp":1.11,"tv":33795.82,"id":8979329}]}]}
{"op":"mcm","clk":"1009233698","pt":1580642916266,"mc":[{"id":"1.168224328","rc":[{"trd":[[11,2]],"batb":[[0,10,3.64],[1,9.6,19.18],[2,8.8,31.71]],"batl":[[0,12,3.67],[2,13,197]],"ltp":11.0,"tv":3453.08,"id":2397396},{"trd":[[1.1,571.57]],"batb":[[0,1.09,1117.92],[1,1.08,2281.28],[2,1.07,56.22]],"batl":[[0,1.1,284.5],[1,1.11,1430.19],[2,1.12,2881.33]],"ltp":1.1,"tv":34166.1,"id":8979329}],"tv":37619.18}]}
{"op":"mcm","clk":"1009233866","pt":1580642917386,"mc":[{"id":"1.168224328","rc":[{"batb":[[0,10,62.26],[2,9.4,27.7]],"ltp":11.0,"tv":3453.08,"id":2397396},{"batb":[[2,1.07,1411.52]],"ltp":1.1,"tv":34166.1,"id":8979329}]}]}
{"op":"mcm","clk":"1009233908","pt":1580642917658,"mc":[{"id":"1.168224328","rc":[{"batb":[[1,9.6,23.38]],"batl":[[1,12.5,5.36]],"ltp":11.0,"tv":3453.08,"id":2397396}]}]}
{"op":"mcm","clk":"1009234193","pt":1580642919676,"mc":[{"id":"1.168224328","rc":[{"batb":[[0,1.09,1226.86]],"batl":[[0,1.1,371.8],[1,1.11,1537.06]],"ltp":1.1,"tv":34166.1,"id":8979329}]}]}
{"op":"mcm","clk":"1009234778","pt":1580642923371,"mc":[{"id":"1.168224328","rc":[{"trd":[[1.1,706]],"batb":[[1,1.08,2243.41],[2,1.07,1672.59]],"batl":[[0,1.1,304.58],[2,1.12,3062.54]],"ltp":1.1,"tv":34300.53,"id":8979329}],"tv":37753.62}]}
{"op":"mcm","clk":"1009234901","pt":1580642924284,"mc":[{"id":"1.168224328","rc":[{"batb":[[1,1.08,2318.41],[2,1.07,1747.59]],"ltp":1.1,"tv":34300.53,"id":8979329}]}]}
{"op":"mcm","clk":"1009235010","pt":1580642925066,"mc":[{"id":"1.168224328","rc":[{"trd":[[1.1,1315.16]],"batb":[[0,1.1,158.37],[1,1.09,1226.86],[2,1.08,2146.79]],"batl":[[0,1.11,1537.06],[1,1.12,3062.54],[2,1.13,146.5]],"ltp":1.1,"tv":34909.69,"id":8979329}],"tv":38362.78}]}
{"op":"mcm","clk":"1009235181","pt":1580642926281,"mc":[{"id":"1.168224328","rc":[{"batb":[[0,1.09,1264.38],[1,1.08,2146.79],[2,1.07,1747.59]],"batl":[[0,1.11,1573.87]],"ltp":1.1,"tv":34909.69,"id":8979329}]}]}
{"op":"mcm","clk":"1009235458","pt":1580642928095,"mc":[{"id":"1.168224328","rc":[{"batb":[[0,1.09,1434.43]],"batl":[[0,1.11,1905.51]],"ltp":1.1,"tv":34909.69,"id":8979329}]}]}
{"op":"mcm","clk":"1009235644","pt":1580642929372,"mc":[{"id":"1.168224328","rc":[{"batb":[[0,9.6,4.2],[1,9.4,27.7],[2,9.2,7.27]],"batl":[[0,12.5,5.36],[1,13.5,2],[2,1000,0.02]],"ltp":11.0,"tv":3453.08,"id":2397396},{"batb":[[0,1.09,246.83],[1,1.08,959.56]],"batl":[[0,1.11,534.34],[1,1.12,181.21]],"ltp":1.1,"tv":34909.69,"id":8979329}]}]}
{"op":"mcm","clk":"1009235727","pt":1580642930069,"mc":[{"id":"1.168224328","rc":[{"batl":[[0,12.5,3.36]],"ltp":11.0,"tv":3453.08,"id":2397396},{"batb":[[0,1.09,56.22]],"ltp":1.1,"tv":34909.69,"id":8979329}]}]}
{"op":"mcm","clk":"1009235889","pt":1580642931187,"mc":[{"id":"1.168224328","rc":[{"batb":[[0,9.4,27.7],[1,9.2,7.27],[2,8.6,3.64]],"batl":[[0,13.5,2],[1,1000,0.02],[2,1000,0]],"ltp":11.0,"tv":3453.08,"id":2397396}]}]}
{"op":"mcm","clk":"1009236060","pt":1580642932313,"mc":[{"id":"1.168224328","rc":[{"batb":[[1,1.08,1809.88],[2,1.07,2099.11]],"batl":[[1,1.12,1379.27]],"ltp":1.1,"tv":34909.69,"id":8979329}]}]}
{"op":"mcm","clk":"1009236184","pt":1580642933109,"mc":[{"id":"1.168224328","rc":[{"batb":[[1,1.08,1355.04],[2,1.07,1747.59]],"batl":[[1,1.12,181.21]],"ltp":1.1,"tv":34909.69,"id":8979329}]}]}
{"op":"mcm","clk":"1009236510","pt":1580642935292,"mc":[{"id":"1.168224328","rc":[{"batb":[[0,1.09,851.96]],"batl":[[0,1.1,522.09],[1,1.11,1225.82],[2,1.12,181.21]],"ltp":1.1,"tv":34909.69,"id":8979329}]}]}
{"op":"mcm","clk":"1009236666","pt":1580642936303,"mc":[{"id":"1.168224328","rc":[{"batl":[[0,12.5,2],[1,13.5,2],[2,1000,0.02]],"ltp":11.0,"tv":3453.08,"id":2397396},{"batb":[[0,1.09,1045.57]],"ltp":1.1,"tv":34909.69,"id":8979329}]}]}
{"op":"mcm","clk":"1009236797","pt":1580642937106,"mc":[{"id":"1.168224328","rc":[{"batl":[[0,13.5,2],[1,1000,0.02],[2,1000,0]],"ltp":11.0,"tv":3453.08,"id":2397396},{"batb":[[0,1.09,56.22]],"batl":[[0,1.11,609.34],[1,1.12,181.21],[2,1.13,146.5]],"ltp":1.1,"tv":34909.69,"id":8979329}]}]}
{"op":"mcm","clk":"1009237289","pt":1580642940314,"mc":[{"id":"1.168224328","rc":[{"batl":[[0,12.5,2],[1,13.5,2],[2,1000,0.02]],"ltp":11.0,"tv":3453.08,"id":2397396},{"batb":[[0,1.09,255.83],[1,1.08,1809.88],[2,1.07,2099.11]],"batl":[[1,1.12,1379.27]],"ltp":1.1,"tv":34909.69,"id":8979329}]}]}
{"op":"mcm","clk":"1009237367","pt":1580642940710,"mc":[{"id":"1.168224328","rc":[{"batl":[[0,13.5,2],[1,1000,0.02],[2,1000,0]],"ltp":11.0,"tv":3453.08,"id":2397396},{"batb":[[0,1.09,56.22],[1,1.08,366.53],[2,1.07,1747.59]],"ltp":1.1,"tv":34909.69,"id":8979329}]}]}
{"op":"mcm","clk":"1009237589","pt":1580642941828,"mc":[{"id":"1.168224328","rc":[{"batb":[[0,1.09,56.78]],"batl":[[0,1.11,534.34]],"ltp":1.1,"tv":34909.69,"id":8979329}]}]}
{"op":"mcm","clk":"1009237840","pt":1580642943326,"mc":[{"id":"1.168224328","rc":[{"batl":[[0,11,925.2],[1,12,183],[2,12.5,154.11]],"ltp":11.0,"tv":3453.08,"id":2397396},{"batb":[[0,1.09,1911.52]],"batl":[[2,1.13,3026.5]],"ltp":1.1,"tv":34909.69,"id":8979329}]}]}
{"op":"mcm","clk":"1009238014","pt":1580642944306,"mc":[{"id":"1.168224328","rc":[{"batb":[[2,9,30.84]],"batl":[[0,12,183],[1,12.5,15.41],[2,13.5,81.11]],"ltp":11.0,"tv":3453.08,"id":2397396},{"batb":[[0,1.1,581.86],[1,1.09,2507.71],[2,1.08,2586.84]],"batl":[[0,1.11,555.36]],"ltp":1.1,"tv":34909.69,"id":8979329}]}]}
{"op":"mcm","clk":"1009238173","pt":1580642945329,"mc":[{"id":"1.168224328","rc":[{"batb":[[1,1.09,4080.98]],"ltp":1.1,"tv":34909.69,"id":8979329}]}]}
{"op":"mcm","clk":"1009238278","pt":1580642946009,"mc":[{"id":"1.168224328","rc":[{"batb":[[1,9.2,12.31]],"batl":[[0,12,186.36]],"ltp":11.0,"tv":3453.08,"id":2397396},{"batb":[[1,1.09,2675.75]],"batl":[[1,1.12,1421.28]],"ltp":1.1,"tv":34909.69,"id":8979329}]}]}
{"op":"mcm","clk":"1009238696","pt":1580642948496,"mc":[{"id":"1.168224328","rc":[{"batb":[[0,1.1,1044.81]],"ltp":1.1,"tv":34909.69,"id":8979329}]}]}
{"op":"mcm","clk":"1009238944","pt":1580642949999,"mc":[{"id":"1.168224328","rc":[{"batl":[[1,12.5,17.41]],"ltp":11.0,"tv":3453.08,"id":2397396},{"batb":[[1,1.09,2860.36]],"ltp":1.1,"tv":34909.69,"id":8979329}]}]}
{"op":"mcm","clk":"1009239001","pt":1580642950432,"mc":[{"id":"1.168224328","rc":[{"trd":[[1.1,1431.17]],"batb":[[0,1.1,986.81]],"ltp":1.1,"tv":35025.7,"id":8979329}],"tv":38478.78}]}
{"op":"mcm","clk":"1009239580","pt":1580642954346,"mc":[{"id":"1.168224328","rc":[{"batb":[[0,1.1,1061.81]],"ltp":1.1,"tv":35025.7,"id":8979329}]}]}
{"op":"mcm","clk":"1009239908","pt":1580642956338,"mc":[{"id":"1.168224328","rc":[{"batb":[[0,9.2,12.31],[1,9,30.84],[2,8.6,3.64]],"batl":[[0,12,3.36],[1,12.5,2],[2,13.5,2]],"ltp":11.0,"tv":3453.08,"id":2397396},{"batb":[[0,1.1,537.95],[1,1.09,1046],[2,1.08,1597.98]],"batl":[[0,1.12,1071.33],[1,1.13,146.5],[2,1.14,155.75]],"ltp":1.1,"tv":35025.7,"id":8979329}]}]}
{"op":"mcm","clk":"1009239991","pt":1580642956880,"mc":[{"id":"1.168224328","rc":[{"batb":[[0,9.2,7.27]],"batl":[[0,12.5,2],[1,13.5,2],[2,1000,0.02]],"ltp":11.0,"tv":3453.08,"id":2397396},{"batb":[[1,1.09,877.96]],"batl":[[0,1.12,1029.32]],"ltp":1.1,"tv":35025.7,"id":8979329}]}]}
{"op":"mcm","clk":"1009240421","pt":1580642959156,"mc":[{"id":"1.168224328","rc":[{"batb":[[0,1.11,2.84],[1,1.1,537.95],[2,1.09,877.96]],"batl":[[1,1.13,1018.24]],"ltp":1.1,"tv":35025.7,"id":8979329}]}]}
{"op":"mcm","clk":"1009240649","pt":1580642960356,"mc":[{"id":"1.168224328","rc":[{"batl":[[1,1.13,146.5]],"ltp":1.1,"tv":35025.7,"id":8979329}]}]}
{"op":"mcm","clk":"1009240789","pt":1580642961159,"mc":[{"id":"1.168224328","rc":[{"trd":[[1.11,2221.02]],"batb":[[0,1.1,549.09],[1,1.09,2016.02],[2,1.08,1597.98]],"batl":[[0,1.11,908.06],[1,1.12,1029.32],[2,1.13,146.5]],"ltp":1.11,"tv":35031.38,"id":8979329}],"tv":38484.46}]}
{"op":"mcm","clk":"1009240837","pt":1580642961444,"mc":[{"id":"1.168224328","rc":[{"batb":[[0,1.1,537.95]],"batl":[[0,1.11,896.56]],"ltp":1.11,"tv":35031.38,"id":8979329}]}]}
{"op":"mcm","clk":"1009241259","pt":1580642964235,"mc":[{"id":"1.168224328","rc":[{"trd":[[1.11,2230.66]],"batl":[[0,1.11,891.74]],"ltp":1.11,"tv":35041.02,"id":8979329}],"tv":38494.11}]}
{"op":"mcm","clk":"1009241375","pt":1580642964975,"mc":[{"id":"1.168224328","rc":[{"batb":[[1,1.09,882.28]],"batl":[[0,1.12,1029.32],[1,1.13,146.5],[2,1.14,155.75]],"ltp":1.11,"tv":35041.02,"id":8979329}]}]}
{"op":"mcm","clk":"1009241609","pt":1580642966659,"mc":[{"id":"1.168224328","rc":[{"batb":[[0,1.1,543.4]],"ltp":1.11,"tv":35041.02,"id":8979329}]}]}
{"op":"mcm","clk":"1009241957","pt":1580642968968,"mc":[{"id":"1.168224328","rc":[{"batb":[[2,1.08,2742.21]],"batl":[[1,1.13,1022.4]],"ltp":1.11,"tv":35041.02,"id":8979329}]}]}
{"op":"mcm","clk":"1009242405","pt":1580642972116,"mc":[{"id":"1.168224328","rc":[{"batb":[[0,1.1,537.95]],"ltp":1.11,"tv":35041.02,"id":8979329}]}]}
{"op":"mcm","clk":"1009242735","pt":1580642974299,"mc":[{"id":"1.168224328","rc":[{"trd":[[1.12,3.36]],"batl":[[0,1.12,1027.64]],"ltp":1.12,"tv":35044.38,"id":8979329}],"tv":38497.47}]}
{"op":"mcm","clk":"1009243916","pt":1580642982003,"mc":[{"id":"1.168224328","rc":[{"batb":[[1,1.09,240.83],[2,1.08,1597.98]],"ltp":1.12,"tv":35044.38,"id":8979329}]}]}
{"op":"mcm","clk":"1009244370","pt":1580642985002,"mc":[{"id":"1.168224328","rc":[{"batl":[[0,11,18.21],[1,11.5,243],[2,12,89.41]],"ltp":11.0,"tv":3453.08,"id":2397396},{"batb":[[0,1.1,2297],[1,1.09,438.29]],"batl":[[0,1.12,1053.53],[1,1.13,2681.4]],"ltp":1.12,"tv":35044.38,"id":8979329}]}]}
{"op":"mcm","clk":"1009244579","pt":1580642986290,"mc":[{"id":"1.168224328","rc":[{"batb":[[2,8.8,5.04]],"batl":[[1,11.5,246.36]],"ltp":11.0,"tv":3453.08,"id":2397396},{"trd":[[1.12,16.8]],"batb":[[0,1.1,3287.21],[1,1.09,1552.66],[2,1.08,366.53]],"batl":[[0,1.12,1046.81]],"ltp":1.12,"tv":35057.82,"id":8979329}],"tv":38510.91}]}
{"op":"mcm","clk":"1009244705","pt":1580642987091,"mc":[{"id":"1.168224328","rc":[{"batb":[[0,1.11,462.95],[1,1.1,3287.21],[2,1.09,1552.66]],"ltp":1.12,"tv":35057.82,"id":8979329}]}]}
{"op":"mcm","clk":"1009244812","pt":1580642987790,"mc":[{"id":"1.168224328","rc":[{"batb":[[0,9.2,7.44]],"ltp":11.0,"tv":3453.08,"id":2397396}]}]}
{"op":"mcm","clk":"1009244941","pt":1580642988593,"mc":[{"id":"1.168224328","rc":[{"batb":[[0,9,31.01],[1,8.8,5.04],[2,8.6,3.64]],"ltp":11.0,"tv":3453.08,"id":2397396},{"batl":[[0,1.12,874]],"ltp":1.12,"tv":35057.82,"id":8979329}]}]}
{"op":"mcm","clk":"1009245460","pt":1580642991903,"mc":[{"id":"1.168224328","rc":[{"batb":[[0,9.2,8.14],[1,9,30.84],[2,8.8,5.04]],"batl":[[0,11,20.21]],"ltp":11.0,"tv":3453.08,"id":2397396},{"batb":[[1,1.1,3469.35]],"ltp":1.12,"tv":35057.82,"id":8979329}]}]}
{"op":"mcm","clk":"1009246611","pt":1580642999195,"mc":[{"id":"1.168224328","rc":[{"trd":[[10.5,1.8]],"ltp":10.5,"tv":3454.88,"id":2397396},{"trd":[[1.11,2247.71]],"batb":[[0,1.11,445.9]],"batl":[[1,1.13,2603.72]],"ltp":1.11,"tv":35074.87,"id":8979329}],"tv":38529.76}]}
{"op":"mcm","clk":"1009246934","pt":1580643001296,"mc":[{"id":"1.168224328","rc":[{"batl":[[1,11.5,3.36],[2,12.5,2]],"ltp":10.5,"tv":3454.88,"id":2397396},{"batb":[[1,1.1,1710.3]],"batl":[[0,1.12,74.17],[1,1.13,944.72]],"ltp":1.11,"tv":35074.87,"id":8979329}]}]}
{"op":"mcm","clk":"1009246990","pt":1580643001617,"mc":[{"id":"1.168224328","rc":[{"batb":[[0,8.8,5.21],[1,8.6,3.64],[2,8.4,35.09]],"batl":[[0,11,2]],"ltp":10.5,"tv":3454.88,"id":2397396},{"batb":[[1,1.1,720.09],[2,1.09,1355.2]],"batl":[[0,1.13,944.72],[1,1.14,155.75],[2,1.15,12.01]],"ltp":1.11,"tv":35074.87,"id":8979329}]}]}
{"op":"mcm","clk":"1009247175","pt":1580643002830,"mc":[{"id":"1.168224328","rc":[{"batb":[[0,8.6,3.81],[1,8.4,35.09],[2,4,37.86]],"batl":[[1,12.5,2],[2,13.5,2]],"ltp":10.5,"tv":3454.88,"id":2397396}]}]}
{"op":"mcm","clk":"1009247428","pt":1580643004338,"mc":[{"id":"1.168224328","rc":[{"batb":[[2,1.09,3130.39]],"batl":[[0,1.13,1413.61],[1,1.14,597.08]],"ltp":1.11,"tv":35074.87,"id":8979329}]}]}
{"op":"mcm","clk":"1009248534","pt":1580643011216,"mc":[{"id":"1.168224328","rc":[{"batl":[[0,1.13,146.5],[1,1.15,12.01],[2,1.22,3.01]],"ltp":1.11,"tv":35074.87,"id":8979329}]}]}
{"op":"mcm","clk":"1009248650","pt":1580643012019,"mc":[{"id":"1.168224328","rc":[{"batb":[[0,9.2,8.14],[1,8.6,3.64],[2,8.4,35.09]],"ltp":10.5,"tv":3454.88,"id":2397396},{"batb":[[0,1.1,645.09],[1,1.09,3130.39],[2,1.08,291.53]],"ltp":1.11,"tv":35074.87,"id":8979329}]}]}
{"op":"mcm","clk":"1009248770","pt":1580643012839,"mc":[{"id":"1.168224328","rc":[{"batb":[[0,8.6,3.81],[1,8.4,35.09],[2,4,37.86]],"ltp":10.5,"tv":3454.88,"id":2397396}]}]}
{"op":"mcm","clk":"1009248918","pt":1580643013825,"mc":[{"id":"1.168224328","rc":[{"batb":[[0,10,9.13],[1,8.8,23.96],[2,8.6,3.64]],"batl":[[1,12,6.36],[2,12.5,216]],"ltp":10.5,"tv":3454.88,"id":2397396},{"batb":[[2,1.08,918.54]],"batl":[[0,1.11,1156.28],[1,1.12,2681.98],[2,1.13,315.44]],"ltp":1.11,"tv":35074.87,"id":8979329}]}]}
{"op":"mcm","clk":"1009249161","pt":1580643015324,"mc":[{"id":"1.168224328","rc":[{"batb":[[1,9.6,65.31],[2,9,30.14]],"ltp":10.5,"tv":3454.88,"id":2397396}]}]}
{"op":"mcm","clk":"1009249223","pt":1580643016005,"mc":[{"id":"1.168224328","rc":[{"batb":[[1,9.6,69.51]],"batl":[[1,12,9.72]],"ltp":10.5,"tv":3454.88,"id":2397396},{"batb":[[1,1.09,3298.43]],"batl":[[1,1.12,2723.99]],"ltp":1.11,"tv":35074.87,"id":8979329}]}]}
{"op":"mcm","clk":"1009250132","pt":1580643021143,"mc":[{"id":"1.168224328","rc":[{"trd":[[11,2.16]],"batb":[[2,9.2,7.72]],"batl":[[0,11,1.92]],"ltp":11.0,"tv":3455.04,"id":2397396},{"batl":[[1,1.12,2917.2]],"ltp":1.11,"tv":35074.87,"id":8979329}],"tv":38529.91}]}
{"op":"mcm","clk":"1009252135","pt":1580643033064,"mc":[{"id":"1.168224328","rc":[{"batb":[[0,9.6,4.37],[1,9.2,7.72],[2,9,30.14]],"batl":[[0,12,3.36],[1,12.5,2],[2,13.5,2]],"ltp":11.0,"tv":3455.04,"id":2397396},{"batb":[[0,1.1,462.95],[1,1.09,408.87],[2,1.08,291.53]],"batl":[[0,1.12,1070.2],[1,1.13,146.5],[2,1.15,12.01]],"ltp":1.11,"tv":35074.87,"id":8979329}]}]}
{"op":"mcm","clk":"1009252299","pt":1580643034059,"mc":[{"id":"1.168224328","rc":[{"trd":[[1.1,1456.37]],"batb":[[0,1.1,450.34]],"ltp":1.1,"tv":35100.08,"id":8979329}],"tv":38555.12}]}
{"op":"mcm","clk":"1009252411","pt":1580643034763,"mc":[{"id":"1.168224328","rc":[{"batb":[[0,9.2,7.89],[1,9,30.14],[2,8.6,3.64]],"batl":[[0,12.5,2],[1,13.5,2],[2,15,2.73]],"ltp":11.0,"tv":3455.04,"id":2397396},{"batb":[[1,1.09,240.83]],"batl":[[0,1.12,1028.19]],"ltp":1.1,"tv":35100.08,"id":8979329}]}]}
{"op":"mcm","clk":"1009252591","pt":1580643035874,"mc":[{"id":"1.168224328","rc":[{"batl":[[0,1.12,1134.64],[1,1.13,925.75]],"ltp":1.1,"tv":35100.08,"id":8979329}]}]}
{"op":"mcm","clk":"1009253026","pt":1580643038369,"mc":[{"id":"1.168224328","rc":[{"batl":[[0,11,6.64],[1,11.5,209],[2,12,18.27]],"ltp":11.0,"tv":3455.04,"id":2397396},{"batb":[[0,1.1,2209.39],[1,1.09,411.21],[2,1.08,1890.22]],"batl":[[0,1.12,1170.88],[1,1.13,2860.75]],"ltp":1.1,"tv":35100.08,"id":8979329}]}]}
{"op":"mcm","clk":"1009253186","pt":1580643039270,"mc":[{"id":"1.168224328","rc":[{"batb":[[2,8.6,37.63]],"ltp":11.0,"tv":3455.04,"id":2397396},{"batb":[[1,1.09,1536.36]],"ltp":1.1,"tv":35100.08,"id":8979329}]}]}
{"op":"mcm","clk":"1009253313","pt":1580643039967,"mc":[{"id":"1.168224328","rc":[{"batb":[[0,9.2,12.93]],"batl":[[1,11.5,212.36]],"ltp":11.0,"tv":3455.04,"id":2397396}]}]}
{"op":"mcm","clk":"1009253924","pt":1580643043686,"mc":[{"id":"1.168224328","rc":[{"batb":[[0,9.2,5.21]],"ltp":11.0,"tv":3455.04,"id":2397396},{"batl":[[0,1.12,977.67]],"ltp":1.1,"tv":35100.08,"id":8979329}]}]}
{"op":"mcm","clk":"1009254467","pt":1580643047166,"mc":[{"id":"1.168224328","rc":[{"batb":[[0,9.2,13.28]],"batl":[[0,11,8.64]],"ltp":11.0,"tv":3455.04,"id":2397396},{"batb":[[0,1.1,2390.03]],"batl":[[0,1.11,18.48],[1,1.12,1178.63],[2,1.13,2860.75]],"ltp":1.1,"tv":35100.08,"id":8979329}]}]}
{"op":"mcm","clk":"1009255307","pt":1580643052272,"mc":[{"id":"1.168224328","rc":[{"batb":[[0,9.2,5.21],[1,8.6,37.63],[2,4,37.86]],"batl":[[0,11,2],[1,11.5,3.36],[2,12.5,2]],"ltp":11.0,"tv":3455.04,"id":2397396},{"batb":[[0,1.1,630.98],[1,1.09,1365.98],[2,1.08,291.53]],"batl":[[1,1.13,925.75],[2,1.15,12.01]],"ltp":1.1,"tv":35100.08,"id":8979329}]}]}
{"op":"mcm","clk":"1009255394","pt":1580643052855,"mc":[{"id":"1.168224328","rc":[{"trd":[[10,16.28]],"batb":[[0,8.6,37.63],[1,4,37.86],[2,3.5,37.86]],"batl":[[0,9.2,6.18],[1,11,2]],"ltp":10.0,"tv":3457.42,"id":2397396},{"trd":[[1.11,2266.2]],"batl":[[0,1.13,925.75],[1,1.15,12.01],[2,1.22,3.01]],"ltp":1.11,"tv":35118.56,"id":8979329}],"tv":38575.99}]}
{"op":"mcm","clk":"1009255541","pt":1580643053801,"mc":[{"id":"1.168224328","rc":[{"batb":[[0,1.12,2],[1,1.1,630.98],[2,1.09,1365.98]],"ltp":1.11,"tv":35118.56,"id":8979329}]}]}
{"op":"mcm","clk":"1009255734","pt":1580643054984,"mc":[{"id":"1.168224328","rc":[{"batb":[[2,1.09,3141.17]],"batl":[[0,1.13,1358.4],[1,1.14,496.06],[2,1.15,12.01]],"ltp":1.11,"tv":35118.56,"id":8979329}]}]}
{"op":"mcm","clk":"1009255950","pt":1580643056202,"mc":[{"id":"1.168224328","rc":[{"trd":[[9.2,6.18]],"batb":[[0,9.2,7.77],[1,8.6,37.63],[2,4,37.86]],"batl":[[0,11,2],[1,12.5,2],[2,13.5,2]],"ltp":9.2,"tv":3463.61,"id":2397396},{"trd":[[1.12,71.59]],"batb":[[0,1.1,630.98],[1,1.09,3141.17],[2,1.08,291.53]],"batl":[[0,1.12,149.91],[1,1.13,1358.4],[2,1.14,496.06]],"ltp":1.12,"tv":35173.35,"id":8979329}],"tv":38636.97}]}
{"op":"mcm","clk":"1009256059","pt":1580643056963,"mc":[{"id":"1.168224328","rc":[{"batb":[[0,8.6,37.63],[1,4,37.86],[2,3.5,37.86]],"ltp":9.2,"tv":3463.61,"id":2397396},{"batl":[[0,1.13,146.5],[1,1.15,12.01],[2,1.22,3.01]],"ltp":1.12,"tv":35173.35,"id":8979329}]}]}
{"op":"mcm","clk":"1009256560","pt":1580643059980,"mc":[{"id":"1.168224328","rc":[{"batb":[[0,10,6.98],[1,8.6,37.63],[2,4,37.86]],"batl":[[1,12,5.05],[2,12.5,173]],"ltp":9.2,"tv":3463.61,"id":2397396},{"batl":[[0,1.11,1459.35],[1,1.12,3103.99],[2,1.13,146.5]],"ltp":1.12,"tv":35173.35,"id":8979329}]}]}
{"op":"mcm","clk":"1009256766","pt":1580643061187,"mc":[{"id":"1.168224328","rc":[{"batb":[[1,9.6,64.2],[2,9.2,29.43]],"ltp":9.2,"tv":3463.61,"id":2397396},{"batb":[[1,1.09,2016.02]],"ltp":1.12,"tv":35173.35,"id":8979329}]}]}
{"op":"mcm","clk":"1009256856","pt":1580643061809,"mc":[{"id":"1.168224328","rc":[{"batb":[[2,9.4,4.2]],"batl":[[1,12,8.41]],"ltp":9.2,"tv":3463.61,"id":2397396},{"batb":[[1,1.09,2184.06]],"ltp":1.12,"tv":35173.35,"id":8979329}]}]}
{"op":"mcm","clk":"1009258769","pt":1580643074199,"mc":[{"id":"1.168224328","rc":[{"batl":[[1,12,3.36],[2,12.5,2]],"ltp":9.2,"tv":3463.61,"id":2397396},{"batl":[[0,1.11,1409.2],[1,1.12,875.99]],"ltp":1.12,"tv":35173.35,"id":8979329}]}]}
{"op":"mcm","clk":"1009258870","pt":1580643074845,"mc":[{"id":"1.168224328","rc":[{"batb":[[0,9.2,35.95],[1,8.6,3.64],[2,4,37.86]],"batl":[[0,12.5,2],[1,13.5,2],[2,15,2.73]],"ltp":9.2,"tv":3463.61,"id":2397396},{"batb":[[0,1.1,450.34],[1,1.09,240.83]],"batl":[[0,1.12,703.87],[1,1.13,146.5],[2,1.15,12.01]],"ltp":1.12,"tv":35173.35,"id":8979329}]}]}
{"op":"mcm","clk":"1009258978","pt":1580643075425,"mc":[{"id":"1.168224328","rc":[{"batb":[[0,1.11,27.28],[1,1.1,450.34],[2,1.09,240.83]],"ltp":1.12,"tv":35173.35,"id":8979329}]}]}
{"op":"mcm","clk":"1009259254","pt":1580643077392,"mc":[{"id":"1.168224328","rc":[{"batl":[[0,1.12,481.51]],"ltp":1.12,"tv":35173.35,"id":8979329}]}]}
{"op":"mcm","clk":"1009259332","pt":1580643077930,"mc":[{"id":"1.168224328","rc":[{"batb":[[0,9.2,29.43]],"ltp":9.2,"tv":3463.61,"id":2397396},{"batl":[[0,1.12,313.8]],"ltp":1.12,"tv":35173.35,"id":8979329}]}]}
{"op":"mcm","clk":"1009259690","pt":1580643080121,"mc":[{"id":"1.168224328","rc":[{"trd":[[1.11,2320.76]],"batb":[[0,1.1,450.34],[1,1.09,1856.15],[2,1.08,291.53]],"batl":[[0,1.11,1399.3],[1,1.12,313.8],[2,1.13,146.5]],"ltp":1.11,"tv":35227.91,"id":8979329}],"tv":38691.53}]}
{"op":"mcm","clk":"1009259815","pt":1580643080942,"mc":[{"id":"1.168224328","rc":[{"batb":[[0,9.2,35.95]],"ltp":9.2,"tv":3463.61,"id":2397396},{"batl":[[1,1.12,476.51]],"ltp":1.11,"tv":35227.91,"id":8979329}]}]}
{"op":"mcm","clk":"1009260067","pt":1580643082384,"mc":[{"id":"1.168224328","rc":[{"batb":[[1,1.09,240.83]],"batl":[[0,1.12,476.51],[1,1.13,146.5],[2,1.15,12.01]],"ltp":1.11,"tv":35227.91,"id":8979329}]}]}
{"op":"mcm","clk":"1009260212","pt":1580643083399,"mc":[{"id":"1.168224328","rc":[{"batb":[[1,1.09,212.72],[2,1.08,263.42]],"ltp":1.11,"tv":35227.91,"id":8979329}]}]}
{"op":"mcm","clk":"1009260378","pt":1580643084300,"mc":[{"id":"1.168224328","rc":[{"batb":[[0,1.1,525.34]],"ltp":1.11,"tv":35227.91,"id":8979329}]}]}
{"op":"mcm","clk":"1009260525","pt":1580643085312,"mc":[{"id":"1.168224328","rc":[{"batb":[[2,1.08,2055.05]],"batl":[[0,1.12,1212.49],[1,1.13,818.36]],"ltp":1.11,"tv":35227.91,"id":8979329}]}]}
{"op":"mcm","clk":"1009261633","pt":1580643092117,"mc":[{"id":"1.168224328","rc":[{"batl":[[0,10,1.78],[1,12.5,2],[2,13.5,2]],"ltp":9.2,"tv":3463.61,"id":2397396}]}]}
{"op":"mcm","clk":"1009261843","pt":1580643093718,"mc":[{"id":"1.168224328","rc":[{"batb":[[0,9.2,29.43]],"ltp":9.2,"tv":3463.61,"id":2397396},{"batl":[[0,1.13,146.5],[1,1.15,12.01],[2,1.22,3.01]],"ltp":1.11,"tv":35227.91,"id":8979329}]}]}
{"op":"mcm","clk":"1009262022","pt":1580643094934,"mc":[{"id":"1.168224328","rc":[{"batb":[[0,1.09,212.72],[1,1.08,2055.05],[2,1.07,1611.51]],"ltp":1.11,"tv":35227.91,"id":8979329}]}]}
{"op":"mcm","clk":"1009262212","pt":1580643096218,"mc":[{"id":"1.168224328","rc":[{"trd":[[10,18.06]],"batb":[[0,10,206.2],[1,9.2,29.43],[2,8.6,3.64]],"batl":[[0,12.5,2],[1,13.5,6.03],[2,14.5,208]],"ltp":10.0,"tv":3465.39,"id":2397396},{"trd":[[1.09,34.52],[1.11,2336.81]],"batb":[[0,1.09,195.46]],"batl":[[0,1.1,7500],[1,1.11,4454.95],[2,1.12,22.94]],"ltp":1.09,"tv":35278.49,"id":8979329}],"tv":38743.88}]}
{"op":"mcm","clk":"1009262374","pt":1580643097350,"mc":[{"id":"1.168224328","rc":[{"batb":[[0,11,55.36],[1,10,20.62],[2,9.8,62.87]],"ltp":10.0,"tv":3465.39,"id":2397396},{"batl":[[0,1.1,1679.1],[1,1.11,3268.61],[2,1.13,146.5]],"ltp":1.09,"tv":35278.49,"id":8979329}]}]}
{"op":"mcm","clk":"1009262453","pt":1580643097834,"mc":[{"id":"1.168224328","rc":[{"batl":[[1,13.5,9.39]],"ltp":10.0,"tv":3465.39,"id":2397396},{"batb":[[1,1.08,2223.09]],"ltp":1.09,"tv":35278.49,"id":8979329}]}]}
{"op":"mcm","clk":"1009262744","pt":1580643099963,"mc":[{"id":"1.168224328","rc":[{"batb":[[1,10.5,4.2],[2,10,20.62]],"ltp":10.0,"tv":3465.39,"id":2397396},{"trd":[[1.09,58.54]],"batb":[[0,1.09,183.45]],"ltp":1.09,"tv":35302.5,"id":8979329}],"tv":38767.89}]}
{"op":"mcm","clk":"1009263191","pt":1580643102837,"mc":[{"id":"1.168224328","rc":[{"batb":[[2,10,26.86]],"ltp":10.0,"tv":3465.39,"id":2397396},{"batl":[[1,1.11,3436.11],[2,1.12,163.46]],"ltp":1.09,"tv":35302.5,"id":8979329}]}]}
{"op":"mcm","clk":"1009263731","pt":1580643106354,"mc":[{"id":"1.168224328","rc":[{"batl":[[1,13.5,5.36]],"ltp":10.0,"tv":3465.39,"id":2397396}]}]}
{"op":"mcm","clk":"1009264181","pt":1580643109343,"mc":[{"id":"1.168224328","rc":[{"batl":[[1,13.5,10.78]],"ltp":10.0,"tv":3465.39,"id":2397396},{"batl":[[0,1.1,1706.17]],"ltp":1.09,"tv":35302.5,"id":8979329}]}]}
{"op":"mcm","clk":"1009264249","pt":1580643109778,"mc":[{"id":"1.168224328","rc":[{"trd":[[1.1,1459.93]],"batl":[[0,1.1,1704.39]],"ltp":1.1,"tv":35306.06,"id":8979329}],"tv":38771.46}]}
{"op":"mcm","clk":"1009264843","pt":1580643113857,"mc":[{"id":"1.168224328","rc":[{"batb":[[0,10.5,4.2],[1,10,6.24],[2,9.8,62.63]],"batl":[[0,13.5,3.36],[1,15,2.73],[2,15.5,2]],"ltp":10.0,"tv":3465.39,"id":2397396},{"batb":[[0,1.08,196.15],[1,1.07,289.18],[2,1.06,1937.66]],"batl":[[0,1.11,440.21],[1,1.12,163.46],[2,1.13,146.5]],"ltp":1.1,"tv":35306.06,"id":8979329}]}]}
{"op":"mcm","clk":"1009265006","pt":1580643114976,"mc":[{"id":"1.168224328","rc":[{"batb":[[0,10,6.24],[1,9.8,62.63],[2,9.2,6.12]],"batl":[[0,15,2.73],[1,15.5,2],[2,1000,0.02]],"ltp":10.0,"tv":3465.39,"id":2397396},{"batb":[[0,1.08,28.11]],"ltp":1.1,"tv":35306.06,"id":8979329}]}]}
{"op":"mcm","clk":"1009265329","pt":1580643117266,"mc":[{"id":"1.168224328","rc":[{"batb":[[1,1.07,1136.23],[2,1.06,2908.04]],"batl":[[0,1.11,1289.86],[1,1.12,778.76]],"ltp":1.1,"tv":35306.06,"id":8979329}]}]}
{"op":"mcm","clk":"1009266112","pt":1580643122269,"mc":[{"id":"1.168224328","rc":[{"batb":[[0,9.8,62.63],[1,9.2,6.12],[2,5,37.86]],"ltp":10.0,"tv":3465.39,"id":2397396},{"batb":[[1,1.07,711.55],[2,1.06,1937.66]],"batl":[[0,1.12,163.46],[1,1.22,3.01],[2,1.38,2889.99]],"ltp":1.1,"tv":35306.06,"id":8979329}]}]}
{"op":"mcm","clk":"1009266543","pt":1580643125149,"mc":[{"id":"1.168224328","rc":[{"batb":[[0,1.09,9.72],[1,1.08,1401.27],[2,1.07,711.55]],"batl":[[0,1.1,1770.6],[1,1.12,163.46],[2,1.22,3.01]],"ltp":1.1,"tv":35306.06,"id":8979329}]}]}
{"op":"mcm","clk":"1009266645","pt":1580643125944,"mc":[{"id":"1.168224328","rc":[{"batb":[[0,1.08,28.11],[1,1.07,711.55],[2,1.06,1937.66]],"batl":[[0,1.12,163.46],[1,1.13,142.5]],"ltp":1.1,"tv":35306.06,"id":8979329}]}]}
{"op":"mcm","clk":"1009266827","pt":1580643127341,"mc":[{"id":"1.168224328","rc":[{"batl":[[0,13.5,2],[1,15,2.73],[2,15.5,2]],"ltp":10.0,"tv":3465.39,"id":2397396},{"batb":[[0,1.08,245.17]],"ltp":1.1,"tv":35306.06,"id":8979329}]}]}
{"op":"mcm","clk":"1009266925","pt":1580643128041,"mc":[{"id":"1.168224328","rc":[{"batl":[[0,15,2.73],[1,15.5,2],[2,1000,0.02]],"ltp":10.0,"tv":3465.39,"id":2397396},{"batb":[[0,1.08,28.11]],"ltp":1.1,"tv":35306.06,"id":8979329}]}]}
{"op":"mcm","clk":"1009267075","pt":1580643129152,"mc":[{"id":"1.168224328","rc":[{"batb":[[0,10,6.24],[1,9.8,62.63],[2,9.2,6.12]],"ltp":10.0,"tv":3465.39,"id":2397396},{"batb":[[1,1.07,1136.23],[2,1.06,2908.04]],"batl":[[0,1.11,1290.86],[1,1.12,778.76],[2,1.13,142.5]],"ltp":1.1,"tv":35306.06,"id":8979329}]}]}
{"op":"mcm","clk":"1009267144","pt":1580643129688,"mc":[{"id":"1.168224328","rc":[{"batb":[[1,1.07,289.18],[2,1.06,1937.66]],"ltp":1.1,"tv":35306.06,"id":8979329}]}]}
{"op":"mcm","clk":"1009267281","pt":1580643130778,"mc":[{"id":"1.168224328","rc":[{"batl":[[0,13.5,2],[1,15,2.73],[2,15.5,2]],"ltp":10.0,"tv":3465.39,"id":2397396},{"batb":[[0,1.08,261.42]],"ltp":1.1,"tv":35306.06,"id":8979329}]}]}
{"op":"mcm","clk":"1009267522","pt":1580643132370,"mc":[{"id":"1.168224328","rc":[{"batl":[[0,11.5,918],[1,13,209],[2,13.5,2]],"ltp":10.0,"tv":3465.39,"id":2397396},{"batb":[[0,1.1,2045.45],[1,1.08,261.42],[2,1.07,289.18]],"batl":[[0,1.11,3317.89],[1,1.12,3371.76]],"ltp":1.1,"tv":35306.06,"id":8979329}]}]}
{"op":"mcm","clk":"1009267632","pt":1580643133167,"mc":[{"id":"1.168224328","rc":[{"batb":[[2,9.2,35.15]],"batl":[[0,12,5.3]],"ltp":10.0,"tv":3465.39,"id":2397396},{"batb":[[1,1.09,1775.19],[2,1.08,1403.65]],"batl":[[0,1.11,3363.05]],"ltp":1.1,"tv":35306.06,"id":8979329}]}]}
{"op":"mcm","clk":"1009267779","pt":1580643134271,"mc":[{"id":"1.168224328","rc":[{"batb":[[1,9.8,66.83]],"batl":[[1,12.5,3.36],[2,13,209]],"ltp":10.0,"tv":3465.39,"id":2397396},{"batb":[[1,1.09,1943.23]],"ltp":1.1,"tv":35306.06,"id":8979329}]}]}
{"op":"mcm","clk":"1009268093","pt":1580643136571,"mc":[{"id":"1.168224328","rc":[{"batb":[[0,9.8,66.83],[1,9.2,35.15],[2,5,37.86]],"ltp":10.0,"tv":3465.39,"id":2397396},{"batl":[[0,1.11,3194.55]],"ltp":1.1,"tv":35306.06,"id":8979329}]}]}
{"op":"mcm","clk":"1009268536","pt":1580643139577,"mc":[{"id":"1.168224328","rc":[{"batb":[[2,8.6,6.54]],"batl":[[1,12.5,5.36]],"ltp":10.0,"tv":3465.39,"id":2397396},{"batb":[[1,1.09,2135.84]],"ltp":1.1,"tv":35306.06,"id":8979329}]}]}
{"op":"mcm","clk":"1009270084","pt":1580643149379,"mc":[{"id":"1.168224328","rc":[{"batb":[[0,9.8,4.2]],"batl":[[0,12.5,3.36],[1,13.5,2],[2,15,2.73]],"ltp":10.0,"tv":3465.39,"id":2397396},{"batb":[[0,1.09,168.04],[1,1.08,261.42],[2,1.07,1608.6]],"batl":[[0,1.12,778.76],[1,1.13,142.5],[2,1.22,3.01]],"ltp":1.1,"tv":35306.06,"id":8979329}]}]}
{"op":"mcm","clk":"1009270432","pt":1580643151273,"mc":[{"id":"1.168224328","rc":[{"batb":[[0,9.2,35.15],[1,8.6,6.54],[2,5,37.86]],"batl":[[0,13.5,2],[1,15,2.73],[2,15.5,2]],"ltp":10.0,"tv":3465.39,"id":2397396},{"batb":[[0,1.11,5]],"batl":[[0,1.12,1278.76]],"ltp":1.1,"tv":35306.06,"id":8979329}]}]}
{"op":"mcm","clk":"1009270620","pt":1580643152115,"mc":[{"id":"1.168224328","rc":[{"batb":[[2,4,37.86]],"ltp":10.0,"tv":3465.39,"id":2397396},{"batl":[[0,1.12,1810.85],[1,1.13,717.61]],"ltp":1.1,"tv":35306.06,"id":8979329}]}]}
{"op":"mcm","clk":"1009270712","pt":1580643152581,"mc":[{"id":"1.168224328","rc":[{"batl":[[0,12.5,2],[1,13.5,2],[2,15,2.73]],"ltp":10.0,"tv":3465.39,"id":2397396},{"batb":[[1,1.09,188.61],[2,1.08,261.42]],"ltp":1.1,"tv":35306.06,"id":8979329}]}]}
{"op":"mcm","clk":"1009270972","pt":1580643154301,"mc":[{"id":"1.168224328","rc":[{"batl":[[0,10.5,903.26],[1,11.5,182.98],[2,12,214]],"ltp":10.0,"tv":3465.39,"id":2397396},{"batb":[[1,1.09,1936.13]],"batl":[[1,1.13,3380.61],[2,1.14,140.25]],"ltp":1.1,"tv":35306.06,"id":8979329}]}]}
{"op":"mcm","clk":"1009271114","pt":1580643155215,"mc":[{"id":"1.168224328","rc":[{"batb":[[1,8.8,32.34],[2,8.6,6.54]],"batl":[[0,11,5.43],[1,11.5,18.3]],"ltp":10.0,"tv":3465.39,"id":2397396},{"batb":[[1,1.1,1559.27],[2,1.09,1389.84]],"batl":[[0,1.12,1854.75]],"ltp":1.1,"tv":35306.06,"id":8979329}]}]}
{"op":"mcm","clk":"1009271214","pt":1580643155829,"mc":[{"id":"1.168224328","rc":[{"batb":[[0,9.2,40.19]],"batl":[[1,11.5,21.66]],"ltp":10.0,"tv":3465.39,"id":2397396},{"batl":[[0,1.12,1896.76]],"ltp":1.1,"tv":35306.06,"id":8979329}]}]}
{"op":"mcm","clk":"1009271544","pt":1580643158025,"mc":[{"id":"1.168224328","rc":[{"batb":[[0,9.2,34.07]],"ltp":10.0,"tv":3465.39,"id":2397396},{"batl":[[0,1.12,1733.3]],"ltp":1.1,"tv":35306.06,"id":8979329}]}]}
{"op":"mcm","clk":"1009272204","pt":1580643162127,"mc":[{"id":"1.168224328","rc":[{"batb":[[0,9.2,41.04]],"batl":[[0,11,7.43]],"ltp":10.0,"tv":3465.39,"id":2397396},{"trd":[[1.12,78.6]],"batb":[[1,1.1,1730.21]],"batl":[[0,1.12,1903.76]],"ltp":1.12,"tv":35313.06,"id":8979329}],"tv":38778.46}]}
{"op":"mcm","clk":"1009272751","pt":1580643165369,"mc":[{"id":"1.168224328","rc":[{"batb":[[0,9.2,12.01]],"batl":[[0,11.5,3.36],[1,12.5,2],[2,13.5,2]],"ltp":10.0,"tv":3465.39,"id":2397396},{"batb":[[0,1.09,188.61],[1,1.08,1403.49],[2,1.07,289.18]],"batl":[[0,1.12,715.97],[1,1.13,717.61]],"ltp":1.12,"tv":35313.06,"id":8979329}]}]}
{"op":"mcm","clk":"1009273019","pt":1580643166904,"mc":[{"id":"1.168224328","rc":[{"batb":[[0,9.2,6.97]],"batl":[[0,12.5,2],[1,13.5,2],[2,15,2.73]],"ltp":10.0,"tv":3465.39,"id":2397396},{"batl":[[0,1.12,673.96]],"ltp":1.12,"tv":35313.06,"id":8979329}]}]}
{"op":"mcm","clk":"1009273195","pt":1580643168016,"mc":[{"id":"1.168224328","rc":[{"batb":[[0,1.09,1963.8]],"batl":[[1,1.13,1560.6],[2,1.14,431.92]],"ltp":1.12,"tv":35313.06,"id":8979329}]}]}
{"op":"mcm","clk":"1009273373","pt":1580643168786,"mc":[{"id":"1.168224328","rc":[{"batl":[[0,11,2],[1,12.5,2],[2,13.5,2]],"ltp":10.0,"tv":3465.39,"id":2397396},{"batb":[[0,1.1,178.04],[1,1.09,1963.8],[2,1.08,1403.49]],"ltp":1.12,"tv":35313.06,"id":8979329}]}]}
{"op":"mcm","clk":"1009274007","pt":1580643172893,"mc":[{"id":"1.168224328","rc":[{"trd":[[1.12,87.6]],"batl":[[0,1.12,669.46]],"ltp":1.12,"tv":35322.06,"id":8979329}],"tv":38787.46}]}
{"op":"mcm","clk":"1009274398","pt":1580643175640,"mc":[{"id":"1.168224328","rc":[{"batl":[[0,12.5,2],[1,13.5,2],[2,15,2.73]],"ltp":10.0,"tv":3465.39,"id":2397396},{"batb":[[0,1.09,1963.8],[1,1.08,1403.49],[2,1.07,289.18]],"ltp":1.12,"tv":35322.06,"id":8979329}]}]}
{"op":"mcm","clk":"1009274942","pt":1580643178818,"mc":[{"id":"1.168224328","rc":[{"batl":[[0,11,2],[1,12.5,2],[2,13.5,2]],"ltp":10.0,"tv":3465.39,"id":2397396},{"batb":[[0,1.1,194.74],[1,1.09,1963.8],[2,1.08,1403.49]],"ltp":1.12,"tv":35322.06,"id":8979329}]}]}
{"op":"mcm","clk":"1009275175","pt":1580643180544,"mc":[{"id":"1.168224328","rc":[{"batb":[[1,1.09,2038.8]],"ltp":1.12,"tv":35322.06,"id":8979329}]}]}
{"op":"mcm","clk":"1009275796","pt":1580643184929,"mc":[{"id":"1.168224328","rc":[{"batb":[[0,1.1,269.74]],"ltp":1.12,"tv":35322.06,"id":8979329}]}]}
{"op":"mcm","clk":"1009276474","pt":1580643189532,"mc":[{"id":"1.168224328","rc":[{"batl":[[0,12.5,2],[1,13.5,2],[2,15,2.73]],"ltp":10.0,"tv":3465.39,"id":2397396},{"batb":[[0,1.1,75]],"ltp":1.12,"tv":35322.06,"id":8979329}]}]}
{"op":"mcm","clk":"1009276630","pt":1580643190650,"mc":[{"id":"1.168224328","rc":[{"trd":[[1.12,112.35]],"batl":[[0,1.12,657.08]],"ltp":1.12,"tv":35346.82,"id":8979329}],"tv":38812.22}]}
{"op":"mcm","clk":"1009276788","pt":1580643191657,"mc":[{"id":"1.168224328","rc":[{"trd":[[9.2,9.75]],"batb":[[0,9.2,5.19]],"ltp":9.2,"tv":3468.95,"id":2397396}],"tv":38815.78}]}
{"op":"mcm","clk":"1009276981","pt":1580643192937,"mc":[{"id":"1.168224328","rc":[{"batl":[[0,11,2],[1,12.5,2],[2,13.5,2]],"ltp":9.2,"tv":3468.95,"id":2397396},{"batb":[[0,1.1,269.14],[1,1.09,263.61]],"batl":[[2,1.14,291.67]],"ltp":1.12,"tv":35346.82,"id":8979329}]}]}
{"op":"mcm","clk":"1009277115","pt":1580643193758,"mc":[{"id":"1.168224328","rc":[{"batb":[[0,1.1,559.01]],"ltp":1.12,"tv":35346.82,"id":8979329}]}]}
{"op":"mcm","clk":"1009277347","pt":1580643195347,"mc":[{"id":"1.168224328","rc":[{"batl":[[0,10,3.87],[1,10.5,1167.97],[2,11,179.69]],"ltp":9.2,"tv":3468.95,"id":2397396},{"batl":[[1,1.13,3044.6]],"ltp":1.12,"tv":35346.82,"id":8979329}]}]}
{"op":"mcm","clk":"1009277485","pt":1580643196207,"mc":[{"id":"1.168224328","rc":[{"batb":[[2,8.6,11.58]],"batl":[[1,10.5,23.78],[2,11,19.77]],"ltp":9.2,"tv":3468.95,"id":2397396},{"batb":[[0,1.11,924.1],[1,1.1,2516.98],[2,1.09,1361.3]],"batl":[[1,1.13,3086.61]],"ltp":1.12,"tv":35346.82,"id":8979329}]}]}
{"op":"mcm","clk":"1009277661","pt":1580643197329,"mc":[{"id":"1.168224328","rc":[{"batb":[[0,1.11,1503.83]],"ltp":1.12,"tv":35346.82,"id":8979329}]}]}
{"op":"mcm","clk":"1009277808","pt":1580643198350,"mc":[{"id":"1.168224328","rc":[{"batb":[[0,1.11,1793.7]],"ltp":1.12,"tv":35346.82,"id":8979329}]}]}
{"op":"mcm","clk":"1009277950","pt":1580643199268,"mc":[{"id":"1.168224328","rc":[{"batb":[[0,8.8,32.34],[1,8.6,11.58],[2,7,53.58]],"ltp":9.2,"tv":3468.95,"id":2397396},{"batb":[[1,1.1,2227.11]],"batl":[[0,1.12,483.12]],"ltp":1.12,"tv":35346.82,"id":8979329}]}]}
{"op":"mcm","clk":"1009278233","pt":1580643200829,"mc":[{"id":"1.168224328","rc":[{"trd":[[1.12,124.55]],"batl":[[0,1.12,477.02]],"ltp":1.12,"tv":35359.02,"id":8979329}],"tv":38827.97}]}
{"op":"mcm","clk":"1009278757","pt":1580643203850,"mc":[{"id":"1.168224328","rc":[{"trd":[[1.12,704.29]],"batl":[[0,1.12,187.15]],"ltp":1.12,"tv":35938.75,"id":8979329}],"tv":39407.71}]}
{"op":"mcm","clk":"1009278978","pt":1580643204926,"mc":[{"id":"1.168224328","rc":[{"trd":[[1.12,706.53]],"batl":[[0,1.12,186.03]],"ltp":1.12,"tv":35941.0,"id":8979329}],"tv":39409.95}]}
{"op":"mcm","clk":"1009279597","pt":1580643208354,"mc":[{"id":"1.168224328","rc":[{"trd":[[1.12,1078.59]],"batb":[[0,1.12,103.84],[1,1.11,1793.7],[2,1.1,2227.11]],"batl":[[0,1.13,3086.61],[1,1.14,291.67],[2,1.22,3.01]],"ltp":1.12,"tv":36313.05,"id":8979329}],"tv":39782.01}]}
{"op":"mcm","clk":"1009279753","pt":1580643209170,"mc":[{"id":"1.168224328","rc":[{"batb":[[0,1.11,1793.7],[1,1.1,2227.11],[2,1.09,1361.3]],"ltp":1.12,"tv":36313.05,"id":8979329}]}]}
{"op":"mcm","clk":"1009279849","pt":1580643209766,"mc":[{"id":"1.168224328","rc":[{"batb":[[0,1.11,1724.37]],"batl":[[1,1.22,3.01],[2,1.38,2889.99]],"ltp":1.12,"tv":36313.05,"id":8979329}]}]}
{"op":"mcm","clk":"1009280253","pt":1580643212255,"mc":[{"id":"1.168224328","rc":[{"batb":[[0,1.11,1434.5]],"ltp":1.12,"tv":36313.05,"id":8979329}]}]}
{"op":"mcm","clk":"1009280329","pt":1580643212684,"mc":[{"id":"1.168224328","rc":[{"batb":[[1,1.1,2297.07]],"batl":[[0,1.13,3159.95]],"ltp":1.12,"tv":36313.05,"id":8979329}]}]}
{"op":"mcm","clk":"1009283362","pt":1580643231492,"mc":[{"id":"1.168224328","rc":[{"batl":[[0,10,45.88]],"ltp":9.2,"tv":3468.95,"id":2397396}]}]}
{"op":"mcm","clk":"1009285494","pt":1580643246009,"mc":[{"id":"1.168224328","rc":[{"batb":[[0,1.11,1144.64]],"ltp":1.12,"tv":36313.05,"id":8979329}]}]}
{"op":"mcm","clk":"1009285844","pt":1580643248532,"mc":[{"id":"1.168224328","rc":[{"batl":[[1,1.2,13.7],[2,1.22,3.01]],"ltp":1.12,"tv":36313.05,"id":8979329}]}]}
{"op":"mcm","clk":"1009290438","pt":1580643282363,"mc":[{"id":"1.168224328","rc":[{"batl":[[0,1.13,1675.95]],"ltp":1.12,"tv":36313.05,"id":8979329}]}]}
{"op":"mcm","clk":"1009290671","pt":1580643284274,"mc":[{"id":"1.168224328","rc":[{"batb":[[1,8.6,5.04]],"batl":[[0,10,42.01],[1,10.5,4.2],[2,11,2]],"ltp":9.2,"tv":3468.95,"id":2397396},{"batb":[[0,1.11,289.87],[1,1.1,1400.56]],"batl":[[0,1.13,42.01]],"ltp":1.12,"tv":36313.05,"id":8979329}]}]}
{"op":"mcm","clk":"1009290776","pt":1580643284974,"mc":[{"id":"1.168224328","rc":[{"batb":[[0,7,53.58],[1,4,37.86],[2,3.5,37.98]],"batl":[[1,11,2],[2,12.5,2]],"ltp":9.2,"tv":3468.95,"id":2397396},{"batb":[[1,1.1,269.14]],"batl":[[0,1.2,13.7],[1,1.22,3.01],[2,1.38,2889.99]],"ltp":1.12,"tv":36313.05,"id":8979329}]}]}
{"op":"mcm","clk":"1009290906","pt":1580643285937,"mc":[{"id":"1.168224328","rc":[{"batl":[[0,8.8,2.18],[1,10,42.01],[2,11,2]],"ltp":9.2,"tv":3468.95,"id":2397396}]}]}
{"op":"mcm","clk":"1009291058","pt":1580643287264,"mc":[{"id":"1.168224328","rc":[{"batb":[[2,1.09,3136.49]],"batl":[[0,1.16,1037.7],[1,1.17,624.98],[2,1.2,13.7]],"ltp":1.12,"tv":36313.05,"id":8979329}]}]}
{"op":"mcm","clk":"1009291169","pt":1580643288167,"mc":[{"id":"1.168224328","rc":[{"batb":[[0,6.8,54.84]],"ltp":9.2,"tv":3468.95,"id":2397396},{"batb":[[2,1.09,3130.83]],"ltp":1.12,"tv":36313.05,"id":8979329}]}]}
{"op":"mcm","clk":"1009291376","pt":1580643289756,"mc":[{"id":"1.168224328","rc":[{"batl":[[2,12.5,2]],"ltp":9.2,"tv":3468.95,"id":2397396},{"batb":[[1,1.1,75]],"batl":[[0,1.2,13.7],[1,1.22,3.01],[2,1.38,2889.99]],"ltp":1.12,"tv":36313.05,"id":8979329}]}]}
{"op":"mcm","clk":"1009291708","pt":1580643292362,"mc":[{"id":"1.168224328","rc":[{"trd":[[8.8,6.62]],"batb":[[0,8.8,22.67],[1,6.8,54.84],[2,4,37.86]],"batl":[[0,10,42.01],[1,12.5,2],[2,13,232]],"ltp":8.8,"tv":3473.31,"id":2397396},{"trd":[[1.11,2400.01]],"batb":[[0,1.11,258.27]],"batl":[[0,1.12,2387],[1,1.13,193.88],[2,1.2,13.7]],"ltp":1.11,"tv":36376.25,"id":8979329}],"tv":39849.57}]}
{"op":"mcm","clk":"1009291840","pt":1580643293367,"mc":[{"id":"1.168224328","rc":[{"trd":[[10,60.07]],"batb":[[0,10,7.15],[1,9.4,67.59],[2,8.8,22.67]],"batl":[[0,12.5,2],[1,13,232],[2,15,227.86]],"ltp":10.0,"tv":3515.32,"id":2397396},{"trd":[[1.11,3295.01]],"batb":[[0,1.1,75],[1,1.09,2522.75],[2,1.08,1254.68]],"batl":[[0,1.11,417.26],[1,1.12,3262.81],[2,1.13,193.88]],"ltp":1.11,"tv":37271.26,"id":8979329}],"tv":40786.59}]}
{"op":"mcm","clk":"1009291914","pt":1580643293944,"mc":[{"id":"1.168224328","rc":[{"batl":[[0,12,3.36],[1,12.5,2],[2,13,232]],"ltp":10.0,"tv":3515.32,"id":2397396},{"batb":[[1,1.09,2690.79]],"ltp":1.11,"tv":37271.26,"id":8979329}]}]}
{"op":"mcm","clk":"1009292162","pt":1580643295761,"mc":[{"id":"1.168224328","rc":[{"batb":[[1,9.4,71.79]],"ltp":10.0,"tv":3515.32,"id":2397396},{"batb":[[0,1.1,677.55]],"batl":[[0,1.11,688.62],[1,1.12,3666.94]],"ltp":1.11,"tv":37271.26,"id":8979329}]}]}
{"op":"mcm","clk":"1009292584","pt":1580643298768,"mc":[{"id":"1.168224328","rc":[{"batb":[[2,1.08,1473.49]],"batl":[[2,1.13,343.38]],"ltp":1.11,"tv":37271.26,"id":8979329}]}]}
{"op":"mcm","clk":"1009292778","pt":1580643300283,"mc":[{"id":"1.168224328","rc":[{"batb":[[1,9.4,4.2],[2,8,46.15]],"batl":[[2,13.5,2]],"ltp":10.0,"tv":3515.32,"id":2397396},{"batb":[[0,1.1,75],[1,1.09,1072.83]],"batl":[[0,1.11,194.5],[1,1.12,42.01],[2,1.14,138.25]],"ltp":1.11,"tv":37271.26,"id":8979329}]}]}
{"op":"mcm","clk":"1009292888","pt":1580643300997,"mc":[{"id":"1.168224328","rc":[{"batb":[[1,8,46.15],[2,4,37.86]],"batl":[[0,12.5,2],[1,13.5,2],[2,15,2.73]],"ltp":10.0,"tv":3515.32,"id":2397396},{"batb":[[1,1.09,904.79]],"batl":[[1,1.14,138.25],[2,1.2,13.7]],"ltp":1.11,"tv":37271.26,"id":8979329}]}]}
{"op":"mcm","clk":"1009293175","pt":1580643302864,"mc":[{"id":"1.168224328","rc":[{"batb":[[2,1.08,2617.99]],"batl":[[1,1.14,1370.04],[2,1.15,461.48]],"ltp":1.11,"tv":37271.26,"id":8979329}]}]}
{"op":"mcm","clk":"1009293559","pt":1580643305297,"mc":[{"id":"1.168224328","rc":[{"trd":[[10,64.44]],"batb":[[0,10,4.97]],"ltp":10.0,"tv":3519.69,"id":2397396}],"tv":40790.95}]}
{"op":"mcm","clk":"1009293718","pt":1580643306358,"mc":[{"id":"1.168224328","rc":[{"batb":[[0,8,46.15],[1,4,37.86],[2,3.5,37.98]],"ltp":10.0,"tv":3519.69,"id":2397396},{"batb":[[0,1.11,5],[1,1.09,829.79],[2,1.08,1473.49]],"batl":[[0,1.14,138.25],[1,1.2,13.7],[2,1.22,3.01]],"ltp":1.11,"tv":37271.26,"id":8979329}]}]}
{"op":"mcm","clk":"1009293983","pt":1580643308280,"mc":[{"id":"1.168224328","rc":[{"batb":[[0,9.8,191.27],[1,8,46.15],[2,5,42.01]],"batl":[[0,12,4.07],[1,12.5,2],[2,13.5,2]],"ltp":10.0,"tv":3519.69,"id":2397396},{"trd":[[1.11,3305.01]],"batb":[[0,1.09,829.79],[1,1.08,1473.49],[2,1.07,1382.64]],"batl":[[0,1.11,2684.67],[1,1.12,1745.33],[2,1.14,138.25]],"ltp":1.11,"tv":37281.26,"id":8979329}],"tv":40800.95}]}
{"op":"mcm","clk":"1009294150","pt":1580643309295,"mc":[{"id":"1.168224328","rc":[{"batb":[[0,10,55.39],[1,9.8,19.13],[2,9,29.74]],"ltp":10.0,"tv":3519.69,"id":2397396},{"batb":[[1,1.08,2617.99],[2,1.07,2733.84]],"batl":[[0,1.1,630.86],[1,1.11,3802.7],[2,1.12,174.53]],"ltp":1.11,"tv":37281.26,"id":8979329}]}]}
{"op":"mcm","clk":"1009294257","pt":1580643310001,"mc":[{"id":"1.168224328","rc":[{"batb":[[0,10,59.59]],"batl":[[2,13,3.36]],"ltp":10.0,"tv":3519.69,"id":2397396},{"trd":[[1.1,1471.39]],"batl":[[0,1.1,625.13],[1,1.11,3806.9]],"ltp":1.1,"tv":37292.72,"id":8979329}],"tv":40812.41}]}
{"op":"mcm","clk":"1009294332","pt":1580643310422,"mc":[{"id":"1.168224328","rc":[{"batl":[[1,1.11,3802.7]],"ltp":1.1,"tv":37292.72,"id":8979329}]}]}
{"op":"mcm","clk":"1009294561","pt":1580643311975,"mc":[{"id":"1.168224328","rc":[{"batl":[[1,1.11,3844.71]],"ltp":1.1,"tv":37292.72,"id":8979329}]}]}
{"op":"mcm","clk":"1009294780","pt":1580643313681,"mc":[{"id":"1.168224328","rc":[{"batb":[[0,1.09,904.79]],"ltp":1.1,"tv":37292.72,"id":8979329}]}]}
{"op":"mcm","clk":"1009294970","pt":1580643315212,"mc":[{"id":"1.168224328","rc":[{"batb":[[2,9.2,5.27]],"ltp":10.0,"tv":3519.69,"id":2397396},{"trd":[[1.09,1419.02]],"batb":[[0,1.09,224.56],[2,1.07,2966.91]],"batl":[[1,1.11,3989.21],[2,1.12,306.49]],"ltp":1.09,"tv":38653.21,"id":8979329}],"tv":42172.9}]}
{"op":"mcm","clk":"1009295003","pt":1580643315482,"mc":[{"id":"1.168224328","rc":[{"batl":[[1,1.11,3725.48]],"ltp":1.09,"tv":38653.21,"id":8979329}]}]}
{"op":"mcm","clk":"1009295256","pt":1580643317328,"mc":[{"id":"1.168224328","rc":[{"batl":[[0,12.5,2],[1,13,3.36],[2,13.5,2]],"ltp":10.0,"tv":3519.69,"id":2397396},{"batb":[[2,1.07,1612.38]],"batl":[[1,1.11,1040.81]],"ltp":1.09,"tv":38653.21,"id":8979329}]}]}
{"op":"mcm","clk":"1009295421","pt":1580643318398,"mc":[{"id":"1.168224328","rc":[{"batb":[[0,10,4.2],[1,9.2,5.27],[2,9,29.74]],"batl":[[0,13,3.36],[1,13.5,2],[2,15,2.73]],"ltp":10.0,"tv":3519.69,"id":2397396},{"batb":[[0,1.09,298.14],[1,1.08,1662.4]],"batl":[[0,1.1,271.85],[1,1.11,51.25],[2,1.12,131.96]],"ltp":1.09,"tv":38653.21,"id":8979329}]}]}
{"op":"mcm","clk":"1009295513","pt":1580643318980,"mc":[{"id":"1.168224328","rc":[{"batb":[[0,9.2,5.27],[1,9,29.74],[2,8,6.65]],"batl":[[0,13.5,2],[1,15,2.73],[2,1000,0.02]],"ltp":10.0,"tv":3519.69,"id":2397396},{"batb":[[0,1.09,75],[1,1.08,1538.77]],"batl":[[0,1.11,9.24],[1,1.12,131.96],[2,1.13,144.5]],"ltp":1.09,"tv":38653.21,"id":8979329}]}]}
{"op":"mcm","clk":"1009295595","pt":1580643319514,"mc":[{"id":"1.168224328","rc":[{"batb":[[1,1.08,1115.27]],"ltp":1.09,"tv":38653.21,"id":8979329}]}]}
{"op":"mcm","clk":"1009295977","pt":1580643322190,"mc":[{"id":"1.168224328","rc":[{"batb":[[0,1.09,85.61]],"batl":[[0,1.1,10.55],[1,1.11,9.24],[2,1.12,131.96]],"ltp":1.09,"tv":38653.21,"id":8979329}]}]}
{"op":"mcm","clk":"1009296135","pt":1580643323315,"mc":[{"id":"1.168224328","rc":[{"batb":[[0,1.09,989.8]],"batl":[[0,1.1,407.1],[1,1.11,1349.01]],"ltp":1.09,"tv":38653.21,"id":8979329}]}]}
{"op":"mcm","clk":"1009296240","pt":1580643324003,"mc":[{"id":"1.168224328","rc":[{"batb":[[0,10,8.96],[1,9.2,5.27],[2,9,29.74]],"ltp":10.0,"tv":3519.69,"id":2397396}]}]}
{"op":"mcm","clk":"1009296299","pt":1580643324425,"mc":[{"id":"1.168224328","rc":[{"batl":[[1,1.11,1590.51]],"ltp":1.09,"tv":38653.21,"id":8979329}]}]}
{"op":"mcm","clk":"1009296703","pt":1580643327250,"mc":[{"id":"1.168224328","rc":[{"batb":[[0,9.2,5.27],[1,9,29.74],[2,8,6.65]],"ltp":10.0,"tv":3519.69,"id":2397396},{"batb":[[0,1.09,75]],"batl":[[0,1.11,9.24],[1,1.12,131.96],[2,1.13,144.5]],"ltp":1.09,"tv":38653.21,"id":8979329}]}]}
{"op":"mcm","clk":"1009296898","pt":1580643328527,"mc":[{"id":"1.168224328","rc":[{"batb":[[1,1.08,246.92]],"ltp":1.09,"tv":38653.21,"id":8979329}]}]}
{"op":"mcm","clk":"1009297190","pt":1580643330397,"mc":[{"id":"1.168224328","rc":[{"batb":[[0,10,8.96],[1,9.2,5.27],[2,9,29.74]],"ltp":10.0,"tv":3519.69,"id":2397396},{"batl":[[0,1.11,250.74],[1,1.12,1745.75]],"ltp":1.09,"tv":38653.21,"id":8979329}]}]}
{"op":"mcm","clk":"1009297356","pt":1580643331203,"mc":[{"id":"1.168224328","rc":[{"batb":[[0,9.2,5.27],[1,9,29.74],[2,8,6.65]],"batl":[[0,12,339.82],[1,13.5,82.17],[2,15,2.73]],"ltp":10.0,"tv":3519.69,"id":2397396},{"batb":[[1,1.08,3131.83]],"batl":[[0,1.11,9.24],[1,1.12,3271.75]],"ltp":1.09,"tv":38653.21,"id":8979329}]}]}
{"op":"mcm","clk":"1009297528","pt":1580643332334,"mc":[{"id":"1.168224328","rc":[{"batb":[[0,9.2,10.31]],"batl":[[0,11.5,3.36],[1,12,181.58],[2,13.5,82.17]],"ltp":10.0,"tv":3519.69,"id":2397396},{"batb":[[0,1.1,2028.27],[1,1.09,848.01],[2,1.08,2615.98]],"batl":[[1,1.12,3313.76]],"ltp":1.09,"tv":38653.21,"id":8979329}]}]}
{"op":"mcm","clk":"1009298486","pt":1580643338719,"mc":[{"id":"1.168224328","rc":[{"batb":[[2,8.6,9.59]],"batl":[[2,12.5,2]],"ltp":10.0,"tv":3519.69,"id":2397396},{"batb":[[1,1.09,1051.62]],"ltp":1.09,"tv":38653.21,"id":8979329}]}]}
{"op":"mcm","clk":"1009299111","pt":1580643343261,"mc":[{"id":"1.168224328","rc":[{"batb":[[0,8,6.65],[1,7.2,48.07],[2,5,79.87]],"batl":[[0,12.5,2],[1,13.5,2],[2,15,2.73]],"ltp":10.0,"tv":3519.69,"id":2397396},{"batb":[[0,1.1,23.19],[1,1.09,861.05],[2,1.08,1425.58]],"batl":[[1,1.2,13.7],[2,1.22,3.01]],"ltp":1.09,"tv":38653.21,"id":8979329}]}]}
{"op":"mcm","clk":"1009299435","pt":1580643345346,"mc":[{"id":"1.168224328","rc":[{"trd":[[1.11,3310]],"batl":[[0,1.11,6.75]],"ltp":1.11,"tv":38658.2,"id":8979329}],"tv":42177.89}]}
{"op":"mcm","clk":"1009299532","pt":1580643346043,"mc":[{"id":"1.168224328","rc":[{"batl":[[0,13.5,2],[1,15,2.73],[2,1000,0.02]],"ltp":10.0,"tv":3519.69,"id":2397396},{"batb":[[1,1.09,75]],"ltp":1.11,"tv":38658.2,"id":8979329}]}]}
{"op":"mcm","clk":"1009299630","pt":1580643346629,"mc":[{"id":"1.168224328","rc":[{"batl":[[1,1.14,204.75],[2,1.2,13.7]],"ltp":1.11,"tv":38658.2,"id":8979329}]}]}
{"op":"mcm","clk":"1009299892","pt":1580643348377,"mc":[{"id":"1.168224328","rc":[{"batb":[[0,1.1,1782.24]],"batl":[[1,1.12,803.12],[2,1.13,916.34]],"ltp":1.11,"tv":38658.2,"id":8979329}]}]}
{"op":"mcm","clk":"1009299987","pt":1580643348959,"mc":[{"id":"1.168224328","rc":[{"batl":[[0,12.5,2],[1,13.5,2],[2,15,2.73]],"ltp":10.0,"tv":3519.69,"id":2397396},{"batb":[[1,1.09,249.61]],"ltp":1.11,"tv":38658.2,"id":8979329}]}]}
{"op":"mcm","clk":"1009300193","pt":1580643350127,"mc":[{"id":"1.168224328","rc":[{"batb":[[0,8.6,9.59],[1,8,6.65],[2,7.2,48.07]],"ltp":10.0,"tv":3519.69,"id":2397396},{"batl":[[2,1.13,1136.84]],"ltp":1.11,"tv":38658.2,"id":8979329}]}]}
{"op":"mcm","clk":"1009300350","pt":1580643351151,"mc":[{"id":"1.168224328","rc":[{"batb":[[0,8,6.65],[1,7.2,48.07],[2,5,79.87]],"batl":[[0,13.5,2],[1,15,2.73],[2,1000,0.02]],"ltp":10.0,"tv":3519.69,"id":2397396},{"batb":[[0,1.1,98.19],[1,1.09,75]],"batl":[[1,1.14,204.75],[2,1.2,13.7]],"ltp":1.11,"tv":38658.2,"id":8979329}]}]}
{"op":"mcm","clk":"1009300505","pt":1580643352129,"mc":[{"id":"1.168224328","rc":[{"batb":[[2,1.08,1450.58]],"ltp":1.11,"tv":38658.2,"id":8979329}]}]}
{"op":"mcm","clk":"1009300865","pt":1580643354272,"mc":[{"id":"1.168224328","rc":[{"batl":[[0,12.5,2],[1,13.5,2],[2,15,2.73]],"ltp":10.0,"tv":3519.69,"id":2397396},{"batb":[[1,1.09,850.58],[2,1.08,2654.84]],"batl":[[1,1.14,542.12],[2,1.15,1139.03]],"ltp":1.11,"tv":38658.2,"id":8979329}]}]}
{"op":"mcm","clk":"1009301251","pt":1580643356738,"mc":[{"id":"1.168224328","rc":[{"trd":[[11,5.81]],"ltp":11.0,"tv":3523.34,"id":2397396},{"trd":[[1.1,1507.89]],"batb":[[0,1.1,61.69]],"ltp":1.1,"tv":38694.7,"id":8979329}],"tv":42218.04}]}
{"op":"mcm","clk":"1009301667","pt":1580643359195,"mc":[{"id":"1.168224328","rc":[{"batl":[[0,13.5,2],[1,15,2.73],[2,1000,0.02]],"ltp":11.0,"tv":3523.34,"id":2397396},{"batb":[[1,1.09,75],[2,1.08,1450.58]],"batl":[[1,1.14,204.75],[2,1.2,13.7]],"ltp":1.1,"tv":38694.7,"id":8979329}]}]}
{"op":"mcm","clk":"1009301841","pt":1580643360149,"mc":[{"id":"1.168224328","rc":[{"batb":[[0,1.08,1450.58],[1,1.07,261.18],[2,1.06,298.69]],"ltp":1.1,"tv":38694.7,"id":8979329}]}]}
{"op":"mcm","clk":"1009302054","pt":1580643361347,"mc":[{"id":"1.168224328","rc":[{"batb":[[0,10,18.74],[1,9.6,20.44],[2,8,6.65]],"batl":[[1,14,212],[2,15,126.14]],"ltp":11.0,"tv":3523.34,"id":2397396},{"batl":[[0,1.11,2224.71]],"ltp":1.1,"tv":38694.7,"id":8979329}]}]}
{"op":"mcm","clk":"1009302228","pt":1580643362255,"mc":[{"id":"1.168224328","rc":[{"batb":[[0,11,9.63],[1,10,82.27],[2,9.6,20.44]],"batl":[[0,13,3.36],[1,13.5,2],[2,14,212]],"ltp":11.0,"tv":3523.34,"id":2397396},{"batb":[[0,1.09,581.97],[1,1.08,2654.84],[2,1.07,1545.03]],"batl":[[0,1.1,991.43],[1,1.11,3311.39],[2,1.14,204.75]],"ltp":1.1,"tv":38694.7,"id":8979329}]}]}
{"op":"mcm","clk":"1009303211","pt":1580643368288,"mc":[{"id":"1.168224328","rc":[{"batb":[[1,10,91.23]],"ltp":11.0,"tv":3523.34,"id":2397396},{"batl":[[0,1.1,1006.55],[1,1.11,3549.89],[2,1.12,217.96]],"ltp":1.1,"tv":38694.7,"id":8979329}]}]}
{"op":"mcm","clk":"1009304242","pt":1580643375383,"mc":[{"id":"1.168224328","rc":[{"batb":[[0,10,91.23],[1,9.6,20.44],[2,9,30.76]],"batl":[[2,15,2.73]],"ltp":11.0,"tv":3523.34,"id":2397396},{"batb":[[0,1.08,2654.84],[1,1.07,1545.03],[2,1.06,298.69]],"batl":[[0,1.1,15.12],[1,1.11,287.26]],"ltp":1.1,"tv":38694.7,"id":8979329}]}]}
{"op":"mcm","clk":"1009304347","pt":1580643376102,"mc":[{"id":"1.168224328","rc":[{"batb":[[0,10,13.16],[1,9,30.76],[2,8,6.65]],"ltp":11.0,"tv":3523.34,"id":2397396},{"batb":[[0,1.08,1476.18]],"batl":[[2,1.14,204.75]],"ltp":1.1,"tv":38694.7,"id":8979329}]}]}
{"op":"mcm","clk":"1009304550","pt":1580643377320,"mc":[{"id":"1.168224328","rc":[{"batb":[[0,10,8.96]],"batl":[[0,13.5,2],[1,15,2.73],[2,15.5,2]],"ltp":11.0,"tv":3523.34,"id":2397396},{"batl":[[0,1.1,166.56],[1,1.11,245.25]],"ltp":1.1,"tv":38694.7,"id":8979329}]}]}
{"op":"mcm","clk":"1009304688","pt":1580643378274,"mc":[{"id":"1.168224328","rc":[{"batb":[[2,5,79.87]],"ltp":11.0,"tv":3523.34,"id":2397396},{"batb":[[0,1.08,1439.16],[1,1.07,2163.36]],"batl":[[2,1.2,13.7]],"ltp":1.1,"tv":38694.7,"id":8979329}]}]}
{"op":"mcm","clk":"1009304847","pt":1580643379284,"mc":[{"id":"1.168224328","rc":[{"batb":[[0,11,8.81],[1,10,8.96],[2,9,30.76]],"ltp":11.0,"tv":3523.34,"id":2397396},{"batl":[[0,1.1,428.01],[2,1.12,217.96]],"ltp":1.1,"tv":38694.7,"id":8979329}]}]}
{"op":"mcm","clk":"1009304942","pt":1580643379985,"mc":[{"id":"1.168224328","rc":[{"batl":[[0,1.1,276.57],[2,1.2,13.7]],"ltp":1.1,"tv":38694.7,"id":8979329}]}]}
{"op":"mcm","clk":"1009305138","pt":1580643381286,"mc":[{"id":"1.168224328","rc":[{"batb":[[1,10,29.67]],"batl":[[1,15,210.73]],"ltp":11.0,"tv":3523.34,"id":2397396},{"batl":[[0,1.09,403.13],[1,1.1,1629.05],[2,1.11,3125.25]],"ltp":1.1,"tv":38694.7,"id":8979329}]}]}
{"op":"mcm","clk":"1009305236","pt":1580643381968,"mc":[{"id":"1.168224328","rc":[{"batb":[[1,10.5,55.42],[2,10,29.67]],"batl":[[0,13.5,5.36]],"ltp":11.0,"tv":3523.34,"id":2397396},{"batb":[[2,1.06,1950.07]],"ltp":1.1,"tv":38694.7,"id":8979329}]}]}
{"op":"mcm","clk":"1009305855","pt":1580643386174,"mc":[{"id":"1.168224328","rc":[{"trd":[[1.08,3.36]],"batb":[[0,1.08,1437.48]],"ltp":1.08,"tv":38698.06,"id":8979329}],"tv":42221.4}]}
{"op":"mcm","clk":"1009306019","pt":1580643387308,"mc":[{"id":"1.168224328","rc":[{"trd":[[1.09,1452.63]],"batl":[[0,1.09,386.33]],"ltp":1.09,"tv":38731.66,"id":8979329}],"tv":42255.01}]}
{"op":"mcm","clk":"1009306710","pt":1580643391910,"mc":[{"id":"1.168224328","rc":[{"batl":[[1,1.1,1613.93]],"ltp":1.09,"tv":38731.66,"id":8979329}]}]}
{"op":"mcm","clk":"1009306890","pt":1580643393234,"mc":[{"id":"1.168224328","rc":[{"batl":[[2,1.11,3262.92]],"ltp":1.09,"tv":38731.66,"id":8979329}]}]}
{"op":"mcm","clk":"1009307143","pt":1580643395023,"mc":[{"id":"1.168224328","rc":[{"batl":[[2,1.11,3125.25]],"ltp":1.09,"tv":38731.66,"id":8979329}]}]}
{"op":"mcm","clk":"1009307579","pt":1580643398202,"mc":[{"id":"1.168224328","rc":[{"trd":[[12,1.78]],"ltp":12.0,"tv":3525.12,"id":2397396},{"trd":[[1.09,1472.24]],"batl":[[0,1.09,366.72]],"ltp":1.09,"tv":38751.27,"id":8979329}],"tv":42276.4}]}
{"op":"mcm","clk":"1009307736","pt":1580643399135,"mc":[{"id":"1.168224328","rc":[{"batl":[[0,1.09,1488.36]],"ltp":1.09,"tv":38751.27,"id":8979329}]}]}
{"op":"mcm","clk":"1009307856","pt":1580643400033,"mc":[{"id":"1.168224328","rc":[{"trd":[[12,11.78]],"ltp":12.0,"tv":3535.12,"id":2397396},{"trd":[[1.09,1582.33]],"batb":[[1,1.07,2074.63]],"batl":[[0,1.09,1378.27]],"ltp":1.09,"tv":38861.36,"id":8979329}],"tv":42396.49}]}
{"op":"mcm","clk":"1009308291","pt":1580643402926,"mc":[{"id":"1.168224328","rc":[{"batb":[[0,1.08,1519.26]],"batl":[[0,1.09,1443.82],[1,1.1,1694.14]],"ltp":1.09,"tv":38861.36,"id":8979329}]}]}
{"op":"mcm","clk":"1009309092","pt":1580643408440,"mc":[{"id":"1.168224328","rc":[{"batl":[[2,1.11,3118.5]],"ltp":1.09,"tv":38861.36,"id":8979329}]}]}
{"op":"mcm","clk":"1009310762","pt":1580643420051,"mc":[{"id":"1.168224328","rc":[{"trd":[[12,21.78]],"ltp":12.0,"tv":3545.12,"id":2397396},{"trd":[[1.09,1692.42]],"batb":[[1,1.07,2012.59]],"batl":[[0,1.09,1121.64]],"ltp":1.09,"tv":38971.45,"id":8979329}],"tv":42516.58}]}
{"op":"mcm","clk":"1009311204","pt":1580643422957,"mc":[{"id":"1.168224328","rc":[{"batb":[[0,1.08,1580.73]],"batl":[[1,1.1,2013.39]],"ltp":1.09,"tv":38971.45,"id":8979329}]}]}
{"op":"mcm","clk":"1009311781","pt":1580643426667,"mc":[{"id":"1.168224328","rc":[{"trd":[[12,28.02]],"ltp":12.0,"tv":3551.35,"id":2397396},{"trd":[[1.09,1761.05]],"batl":[[0,1.09,1053]],"ltp":1.09,"tv":39040.09,"id":8979329}],"tv":42591.45}]}
{"op":"mcm","clk":"1009313019","pt":1580643434897,"mc":[{"id":"1.168224328","rc":[{"trd":[[1.09,1773.24]],"batl":[[0,1.09,1046.91]],"ltp":1.09,"tv":39052.28,"id":8979329}],"tv":42603.63}]}
{"op":"mcm","clk":"1009316084","pt":1580643454200,"mc":[{"id":"1.168224328","rc":[{"trd":[[12,38.02]],"ltp":12.0,"tv":3561.35,"id":2397396},{"trd":[[1.09,1883.33]],"batl":[[0,1.09,936.82]],"ltp":1.09,"tv":39162.37,"id":8979329}],"tv":42723.73}]}
{"op":"mcm","clk":"1009319302","pt":1580643476833,"mc":[{"id":"1.168224328","rc":[{"trd":[[12,38.89]],"ltp":12.0,"tv":3562.23,"id":2397396},{"trd":[[1.09,1892.95]],"batl":[[0,1.09,927.2]],"ltp":1.09,"tv":39171.99,"id":8979329}],"tv":42734.22}]}
{"op":"mcm","clk":"1009320599","pt":1580643484932,"mc":[{"id":"1.168224328","rc":[{"batb":[[0,1.08,1555.73]],"ltp":1.09,"tv":39171.99,"id":8979329}]}]}
{"op":"mcm","clk":"1009322753","pt":1580643497957,"mc":[{"id":"1.168224328","rc":[{"batl":[[1,15,2.73]],"ltp":12.0,"tv":3562.23,"id":2397396},{"batl":[[2,1.11,238.5]],"ltp":1.09,"tv":39171.99,"id":8979329}]}]}
{"op":"mcm","clk":"1009323061","pt":1580643500287,"mc":[{"id":"1.168224328","rc":[{"trd":[[1.09,2352.67]],"batl":[[0,1.09,697.34]],"ltp":1.09,"tv":39631.7,"id":8979329}],"tv":43193.94}]}
{"op":"mcm","clk":"1009323127","pt":1580643500777,"mc":[{"id":"1.168224328","rc":[{"trd":[[1.08,11.36]],"batb":[[0,1.08,1551.73]],"ltp":1.08,"tv":39639.71,"id":8979329}],"tv":43201.94}]}
{"op":"mcm","clk":"1009323275","pt":1580643501863,"mc":[{"id":"1.168224328","rc":[{"batb":[[0,10.5,4.2],[1,10,8.96],[2,9.6,64.83]],"batl":[[0,13.5,3.36],[2,1000,0.02]],"ltp":12.0,"tv":3562.23,"id":2397396},{"batb":[[0,1.08,22.43],[1,1.07,335.09],[2,1.06,1679.49]],"batl":[[1,1.2,76.01],[2,1.22,3.01]],"ltp":1.08,"tv":39639.71,"id":8979329}]}]}
{"op":"mcm","clk":"1009323471","pt":1580643503156,"mc":[{"id":"1.168224328","rc":[{"batb":[[0,10,8.96],[1,9.6,64.83],[2,5,79.87]],"batl":[[0,15,2.73],[1,1000,0.02],[2,1000,0]],"ltp":12.0,"tv":3562.23,"id":2397396}]}]}
{"op":"mcm","clk":"1009323682","pt":1580643504584,"mc":[{"id":"1.168224328","rc":[{"batb":[[2,1.06,3176.8]],"batl":[[1,1.11,1549.63],[2,1.2,76.01]],"ltp":1.08,"tv":39639.71,"id":8979329}]}]}
{"op":"mcm","clk":"1009323920","pt":1580643506272,"mc":[{"id":"1.168224328","rc":[{"trd":[[1.09,2352.69]],"batl":[[0,1.09,697.33]],"ltp":1.09,"tv":39639.72,"id":8979329}],"tv":43201.96}]}
{"op":"mcm","clk":"1009324223","pt":1580643508285,"mc":[{"id":"1.168224328","rc":[{"batl":[[1,1.1,289.87],[2,1.11,1549.63]],"ltp":1.09,"tv":39639.72,"id":8979329}]}]}
{"op":"mcm","clk":"1009324289","pt":1580643508715,"mc":[{"id":"1.168224328","rc":[{"batl":[[2,1.2,76.01]],"ltp":1.09,"tv":39639.72,"id":8979329}]}]}
{"op":"mcm","clk":"1009324648","pt":1580643511390,"mc":[{"id":"1.168224328","rc":[{"batb":[[0,11.5,174.07],[1,10,8.96],[2,9.6,64.83]],"batl":[[1,18.5,174],[2,1000,0.02]],"ltp":12.0,"tv":3562.23,"id":2397396},{"batl":[[0,1.09,5436.79]],"ltp":1.09,"tv":39639.72,"id":8979329}]}]}
{"op":"mcm","clk":"1009324838","pt":1580643512383,"mc":[{"id":"1.168224328","rc":[{"batb":[[0,13.5,8.66],[1,13,33.28],[2,12,3.36]],"batl":[[2,21,67.27]],"ltp":12.0,"tv":3562.23,"id":2397396},{"trd":[[1.08,56.22]],"batb":[[0,1.07,335.09],[1,1.06,3176.8],[2,1.05,1497.56]],"batl":[[0,1.08,1742.23],[1,1.09,4138.65],[2,1.1,289.87]],"ltp":1.08,"tv":39684.58,"id":8979329}],"tv":43246.81}]}
{"op":"mcm","clk":"1009325559","pt":1580643517485,"mc":[{"id":"1.168224328","rc":[{"trd":[[13.5,4.52]],"batb":[[0,13.5,6.4]],"ltp":13.5,"tv":3566.75,"id":2397396}],"tv":43251.33}]}
{"op":"mcm","clk":"1009325754","pt":1580643518879,"mc":[{"id":"1.168224328","rc":[{"batb":[[2,12,12.17]],"batl":[[2,21,69.27]],"ltp":13.5,"tv":3566.75,"id":2397396},{"batb":[[2,1.05,1844.45]],"batl":[[1,1.09,4384.15],[2,1.1,510.02]],"ltp":1.08,"tv":39684.58,"id":8979329}]}]}
{"op":"mcm","clk":"1009326310","pt":1580643522770,"mc":[{"id":"1.168224328","rc":[{"trd":[[15,0.14]],"batl":[[0,15,2.66]],"ltp":15.0,"tv":3566.89,"id":2397396}],"tv":43251.47}]}
{"op":"mcm","clk":"1009326502","pt":1580643524218,"mc":[{"id":"1.168224328","rc":[{"batb":[[1,12,12.17],[2,11,56.96]],"batl":[[1,21,2],[2,26,2]],"ltp":15.0,"tv":3566.89,"id":2397396},{"batb":[[0,1.07,28.11],[1,1.06,28.11],[2,1.05,499.09]],"batl":[[0,1.08,315.44],[1,1.09,1318.2]],"ltp":1.08,"tv":39684.58,"id":8979329}]}]}
{"op":"mcm","clk":"1009326649","pt":1580643525198,"mc":[{"id":"1.168224328","rc":[{"batb":[[0,12,8.81],[1,11,56.96],[2,10,8.96]],"batl":[[1,26,2],[2,1000,0.02]],"ltp":15.0,"tv":3566.89,"id":2397396},{"batb":[[2,1.05,152.2]],"batl":[[0,1.09,1276.19],[1,1.1,510.02],[2,1.11,200.5]],"ltp":1.08,"tv":39684.58,"id":8979329}]}]}
{"op":"mcm","clk":"1009326869","pt":1580643526713,"mc":[{"id":"1.168224328","rc":[{"batb":[[2,1.05,1976.6]],"batl":[[0,1.09,1648.75],[1,1.1,1551.99]],"ltp":1.08,"tv":39684.58,"id":8979329}]}]}
{"op":"mcm","clk":"1009327038","pt":1580643528000,"mc":[{"id":"1.168224328","rc":[{"batb":[[0,1.07,103.11],[2,1.05,152.2]],"batl":[[0,1.09,942.83],[1,1.1,510.02]],"ltp":1.08,"tv":39684.58,"id":8979329}]}]}
{"op":"mcm","clk":"1009327147","pt":1580643528911,"mc":[{"id":"1.168224328","rc":[{"batb":[[1,1.06,103.11]],"ltp":1.08,"tv":39684.58,"id":8979329}]}]}
{"op":"mcm","clk":"1009327336","pt":1580643530303,"mc":[{"id":"1.168224328","rc":[{"batb":[[0,1.07,28.11]],"ltp":1.08,"tv":39684.58,"id":8979329}]}]}
{"op":"mcm","clk":"1009327463","pt":1580643531216,"mc":[{"id":"1.168224328","rc":[{"batl":[[1,21,2],[2,26,2]],"ltp":15.0,"tv":3566.89,"id":2397396},{"batb":[[1,1.06,1910.3],[2,1.05,506.69]],"batl":[[0,1.08,1773.72],[1,1.09,942.83],[2,1.1,510.02]],"ltp":1.08,"tv":39684.58,"id":8979329}]}]}
{"op":"mcm","clk":"1009327805","pt":1580643533808,"mc":[{"id":"1.168224328","rc":[{"batb":[[1,1.06,103.11]],"batl":[[0,1.09,942.83],[1,1.1,510.02],[2,1.11,200.5]],"ltp":1.08,"tv":39684.58,"id":8979329}]}]}
{"op":"mcm","clk":"1009328278","pt":1580643536911,"mc":[{"id":"1.168224328","rc":[{"batb":[[2,1.05,2331.09]],"ltp":1.08,"tv":39684.58,"id":8979329}]}]}
{"op":"mcm","clk":"1009328420","pt":1580643538094,"mc":[{"id":"1.168224328","rc":[{"batb":[[1,1.06,28.11]],"ltp":1.08,"tv":39684.58,"id":8979329}]}]}
{"op":"mcm","clk":"1009328716","pt":1580643540330,"mc":[{"id":"1.168224328","rc":[{"trd":[[15,2.8]],"batb":[[0,16.5,19.2],[1,15,8.13],[2,14.5,13.65]],"batl":[[0,21,5.49],[1,25,133]],"ltp":15.0,"tv":3569.55,"id":2397396},{"trd":[[1.06,56.22],[1.07,93.56]],"batb":[[0,1.05,2331.09],[1,1.04,2886.83],[2,1.03,858]],"batl":[[0,1.06,828],[1,1.07,4080.12],[2,1.08,176.42]],"ltp":1.06,"tv":39834.36,"id":8979329}],"tv":43403.91}]}
{"op":"mcm","clk":"1009329048","pt":1580643542215,"mc":[{"id":"1.168224328","rc":[{"batl":[[0,1.06,843.69]],"ltp":1.06,"tv":39834.36,"id":8979329}]}]}
{"op":"mcm","clk":"1009329243","pt":1580643543399,"mc":[{"id":"1.168224328","rc":[{"batb":[[0,1.05,2178.89]],"batl":[[0,1.06,846.72]],"ltp":1.06,"tv":39834.36,"id":8979329}]}]}
{"op":"mcm","clk":"1009329719","pt":1580643546608,"mc":[{"id":"1.168224328","rc":[{"batl":[[2,1.08,369.11]],"ltp":1.06,"tv":39834.36,"id":8979329}]}]}
{"op":"mcm","clk":"1009330114","pt":1580643549508,"mc":[{"id":"1.168224328","rc":[{"batl":[[0,21,2]],"ltp":15.0,"tv":3569.55,"id":2397396}]}]}
{"op":"mcm","clk":"1009330500","pt":1580643552324,"mc":[{"id":"1.168224328","rc":[{"batb":[[0,15,8.13],[1,13.5,34.59],[2,12,8.81]],"batl":[[0,36,2],[1,55,2],[2,1000,0.02]],"ltp":15.0,"tv":3569.55,"id":2397396},{"batb":[[0,1.04,169.36],[1,1.03,858],[2,1.02,4720.67]],"batl":[[0,1.06,18.72],[1,1.07,296.5],[2,1.08,192.69]],"ltp":1.06,"tv":39834.36,"id":8979329}]}]}
{"op":"mcm","clk":"1009330651","pt":1580643553238,"mc":[{"id":"1.168224328","rc":[{"batb":[[0,13.5,29.35],[1,12,8.81],[2,11,8.81]],"ltp":15.0,"tv":3569.55,"id":2397396},{"batl":[[1,1.09,1017.83],[2,1.1,585.02]],"ltp":1.06,"tv":39834.36,"id":8979329}]}]}
{"op":"mcm","clk":"1009330899","pt":1580643555323,"mc":[{"id":"1.168224328","rc":[{"batb":[[0,1.04,712.2]],"ltp":1.06,"tv":39834.36,"id":8979329}]}]}
{"op":"mcm","clk":"1009331138","pt":1580643557033,"mc":[{"id":"1.168224328","rc":[{"batb":[[0,1.05,942.76],[1,1.04,1059.47],[2,1.03,858]],"batl":[[0,1.06,1755.04]],"ltp":1.06,"tv":39834.36,"id":8979329}]}]}
{"op":"mcm","clk":"1009331430","pt":1580643559327,"mc":[{"id":"1.168224328","rc":[{"batb":[[0,13.5,34.59]],"ltp":15.0,"tv":3569.55,"id":2397396},{"batl":[[1,1.08,207.69],[2,1.09,1017.83]],"ltp":1.06,"tv":39834.36,"id":8979329}]}]}
{"op":"mcm","clk":"1009331642","pt":1580643560936,"mc":[{"id":"1.168224328","rc":[{"batl":[[1,1.08,282.69]],"ltp":1.06,"tv":39834.36,"id":8979329}]}]}
{"op":"mcm","clk":"1009331745","pt":1580643561841,"mc":[{"id":"1.168224328","rc":[{"batb":[[0,1.04,712.2],[1,1.03,858],[2,1.02,4720.67]],"batl":[[0,1.06,18.72]],"ltp":1.06,"tv":39834.36,"id":8979329}]}]}
{"op":"mcm","clk":"1009332155","pt":1580643564819,"mc":[{"id":"1.168224328","rc":[{"batb":[[1,1.03,2169.71]],"batl":[[1,1.08,2056.41]],"ltp":1.06,"tv":39834.36,"id":8979329}]}]}
{"op":"mcm","clk":"1009332302","pt":1580643566154,"mc":[{"id":"1.168224328","rc":[{"trd":[[1.06,91.17]],"batl":[[0,1.06,1.24]],"ltp":1.06,"tv":39869.31,"id":8979329}],"tv":43438.87}]}
{"op":"mcm","clk":"1009332834","pt":1580643570360,"mc":[{"id":"1.168224328","rc":[{"batb":[[0,1.04,169.36],[1,1.03,858]],"ltp":1.06,"tv":39869.31,"id":8979329}]}]}
{"op":"mcm","clk":"1009333225","pt":1580643573264,"mc":[{"id":"1.168224328","rc":[{"batl":[[0,18.5,10.97],[1,20,152],[2,26,114.61]],"ltp":15.0,"tv":3569.55,"id":2397396},{"trd":[[1.06,93.66]],"batb":[[0,1.06,1810.04],[1,1.04,3235.73],[2,1.03,858]],"batl":[[0,1.08,4779.28],[1,1.09,1017.83],[2,1.1,585.02]],"ltp":1.06,"tv":39871.8,"id":8979329}],"tv":43441.35}]}
{"op":"mcm","clk":"1009333350","pt":1580643574249,"mc":[{"id":"1.168224328","rc":[{"batb":[[1,13,3.36],[2,12,8.81]],"ltp":15.0,"tv":3569.55,"id":2397396},{"batb":[[1,1.05,1739.11],[2,1.04,3235.73]],"batl":[[0,1.08,4704.28]],"ltp":1.06,"tv":39871.8,"id":8979329}]}]}
{"op":"mcm","clk":"1009333456","pt":1580643575096,"mc":[{"id":"1.168224328","rc":[{"batl":[[2,1.1,295.15]],"ltp":1.06,"tv":39871.8,"id":8979329}]}]}
{"op":"mcm","clk":"1009333645","pt":1580643576287,"mc":[{"id":"1.168224328","rc":[{"batb":[[0,1.06,1978.08]],"batl":[[1,1.09,942.83]],"ltp":1.06,"tv":39871.8,"id":8979329}]}]}
{"op":"mcm","clk":"1009333814","pt":1580643577184,"mc":[{"id":"1.168224328","rc":[{"batb":[[0,13.5,29.35]],"ltp":15.0,"tv":3569.55,"id":2397396},{"batl":[[1,1.09,245.5],[2,1.1,220.15]],"ltp":1.06,"tv":39871.8,"id":8979329}]}]}
{"op":"mcm","clk":"1009333961","pt":1580643578142,"mc":[{"id":"1.168224328","rc":[{"batb":[[0,1.06,2053.08]],"ltp":1.06,"tv":39871.8,"id":8979329}]}]}
{"op":"mcm","clk":"1009334138","pt":1580643579531,"mc":[{"id":"1.168224328","rc":[{"batb":[[0,1.06,3623.16]],"ltp":1.06,"tv":39871.8,"id":8979329}]}]}
{"op":"mcm","clk":"1009335213","pt":1580643587857,"mc":[{"id":"1.168224328","rc":[{"trd":[[1.08,147.08]],"batl":[[0,1.08,4658.85]],"ltp":1.08,"tv":39962.66,"id":8979329}],"tv":43532.22}]}
{"op":"mcm","clk":"1009335548","pt":1580643590366,"mc":[{"id":"1.168224328","rc":[{"batb":[[0,13,3.36],[1,11,54.21],[2,10,8.96]],"batl":[[0,26,114.61],[1,36,2],[2,1000,0.02]],"ltp":15.0,"tv":3569.55,"id":2397396},{"batb":[[0,1.06,245.89],[1,1.04,3034.56],[2,1.03,2915.61]],"batl":[[0,1.08,14.87],[1,1.1,220.15],[2,1.11,282.39]],"ltp":1.08,"tv":39962.66,"id":8979329}]}]}
{"op":"mcm","clk":"1009335687","pt":1580643591377,"mc":[{"id":"1.168224328","rc":[{"batb":[[0,11,54.21],[1,10,8.96],[2,6,37.86]],"batl":[[0,36,2],[1,1000,0.02],[2,1000,0]],"ltp":15.0,"tv":3569.55,"id":2397396},{"batb":[[0,1.06,77.85],[1,1.04,169.36]],"batl":[[0,1.1,220.15],[1,1.11,282.39],[2,1.22,3.01]],"ltp":1.08,"tv":39962.66,"id":8979329}]}]}
{"op":"mcm","clk":"1009335919","pt":1580643592981,"mc":[{"id":"1.168224328","rc":[{"batb":[[1,1.04,2011.31]],"batl":[[0,1.09,1128.4],[1,1.1,843.48],[2,1.11,282.39]],"ltp":1.08,"tv":39962.66,"id":8979329}]}]}
{"op":"mcm","clk":"1009335996","pt":1580643593473,"mc":[{"id":"1.168224328","rc":[{"batb":[[0,12,5.4],[1,11,54.21],[2,10,8.96]],"ltp":15.0,"tv":3569.55,"id":2397396},{"batl":[[0,1.09,1312.9]],"ltp":1.08,"tv":39962.66,"id":8979329}]}]}
{"op":"mcm","clk":"1009336374","pt":1580643596294,"mc":[{"id":"1.168224328","rc":[{"batb":[[2,6,37.86]],"ltp":15.0,"tv":3569.55,"id":2397396},{"batl":[[0,1.09,184.5],[1,1.1,220.15],[2,1.11,81.89]],"ltp":1.08,"tv":39962.66,"id":8979329}]}]}
{"op":"mcm","clk":"1009336500","pt":1580643596995,"mc":[{"id":"1.168224328","rc":[{"batb":[[0,1.06,2.85],[1,1.04,2086.31]],"ltp":1.08,"tv":39962.66,"id":8979329}]}]}
{"op":"mcm","clk":"1009336848","pt":1580643599298,"mc":[{"id":"1.168224328","rc":[{"batb":[[0,21,5.4],[1,15.5,12.23],[2,12,5.4]],"batl":[[0,26,4.4],[1,32,152],[2,36,2]],"ltp":15.0,"tv":3569.55,"id":2397396},{"trd":[[1.06,99.36]],"batb":[[0,1.04,2086.31],[1,1.03,2915.61],[2,1.02,297.25]],"batl":[[0,1.05,323.5],[1,1.06,4769.43],[2,1.07,179.23]],"ltp":1.06,"tv":39968.36,"id":8979329}],"tv":43537.92}]}
{"op":"mcm","clk":"1009336998","pt":1580643600168,"mc":[{"id":"1.168224328","rc":[{"batb":[[1,18.5,29.9],[2,15.5,12.23]],"ltp":15.0,"tv":3569.55,"id":2397396}]}]}
{"op":"mcm","clk":"1009337328","pt":1580643602398,"mc":[{"id":"1.168224328","rc":[{"batb":[[0,1.04,1917.45]],"ltp":1.06,"tv":39968.36,"id":8979329}]}]}
{"op":"mcm","clk":"1009337909","pt":1580643606004,"mc":[{"id":"1.168224328","rc":[{"batb":[[2,1.02,1159.49]],"batl":[[2,1.07,410.73]],"ltp":1.06,"tv":39968.36,"id":8979329}]}]}
{"op":"mcm","clk":"1009338354","pt":1580643609019,"mc":[{"id":"1.168224328","rc":[{"trd":[[1.05,3.56]],"batl":[[0,1.05,321.72]],"ltp":1.05,"tv":39971.92,"id":8979329}],"tv":43541.48}]}
{"op":"mcm","clk":"1009338967","pt":1580643613211,"mc":[{"id":"1.168224328","rc":[{"batb":[[0,15,28.38],[1,13.5,4.4],[2,12,5.4]],"batl":[[0,55,2],[1,110,2],[2,160,37.1]],"ltp":15.0,"tv":3569.55,"id":2397396},{"batb":[[0,1.04,75.5],[1,1.03,246.17]],"batl":[[0,1.07,231.5],[1,1.08,219.94],[2,1.09,184.5]],"ltp":1.05,"tv":39971.92,"id":8979329}]}]}
{"op":"mcm","clk":"1009339005","pt":1580643613479,"mc":[{"id":"1.168224328","rc":[{"batb":[[0,15,24.31]],"ltp":15.0,"tv":3569.55,"id":2397396},{"batl":[[0,1.08,219.94],[1,1.09,184.5],[2,1.1,220.15]],"ltp":1.05,"tv":39971.92,"id":8979329}]}]}
{"op":"mcm","clk":"1009339641","pt":1580643617816,"mc":[{"id":"1.168224328","rc":[{"batb":[[0,1.04,1917.45]],"batl":[[0,1.05,1118.8],[1,1.06,698.94],[2,1.08,219.94]],"ltp":1.05,"tv":39971.92,"id":8979329}]}]}
{"op":"mcm","clk":"1009339979","pt":1580643620121,"mc":[{"id":"1.168224328","rc":[{"batb":[[0,15,28.38]],"ltp":15.0,"tv":3569.55,"id":2397396},{"batl":[[2,1.07,278.5]],"ltp":1.05,"tv":39971.92,"id":8979329}]}]}
{"op":"mcm","clk":"1009340274","pt":1580643622217,"mc":[{"id":"1.168224328","rc":[{"batb":[[0,15,24.31],[2,8,37.86]],"ltp":15.0,"tv":3569.55,"id":2397396},{"batb":[[0,1.04,75.5]],"batl":[[0,1.07,10.08],[1,1.08,219.94],[2,1.11,81.89]],"ltp":1.05,"tv":39971.92,"id":8979329}]}]}
{"op":"mcm","clk":"1009340475","pt":1580643623933,"mc":[{"id":"1.168224328","rc":[{"batl":[[0,1.07,85.08]],"ltp":1.05,"tv":39971.92,"id":8979329}]}]}
{"op":"mcm","clk":"1009340669","pt":1580643625320,"mc":[{"id":"1.168224328","rc":[{"batb":[[1,1.03,1952.44]],"batl":[[0,1.06,75],[1,1.07,1875.38],[2,1.08,219.94]],"ltp":1.05,"tv":39971.92,"id":8979329}]}]}
{"op":"mcm","clk":"1009340805","pt":1580643626230,"mc":[{"id":"1.168224328","rc":[{"batb":[[0,15,28.38]],"ltp":15.0,"tv":3569.55,"id":2397396},{"batl":[[1,1.07,2221.23]],"ltp":1.05,"tv":39971.92,"id":8979329}]}]}
{"op":"mcm","clk":"1009341591","pt":1580643632005,"mc":[{"id":"1.168224328","rc":[{"batb":[[1,1.03,246.17]],"ltp":1.05,"tv":39971.92,"id":8979329}]}]}
{"op":"mcm","clk":"1009341785","pt":1580643633346,"mc":[{"id":"1.168224328","rc":[{"batl":[[0,1.07,2146.23],[1,1.08,219.94],[2,1.09,181.5]],"ltp":1.05,"tv":39971.92,"id":8979329}]}]}
{"op":"mcm","clk":"1009341829","pt":1580643633628,"mc":[{"id":"1.168224328","rc":[{"batl":[[0,1.07,2032.8]],"ltp":1.05,"tv":39971.92,"id":8979329}]}]}
{"op":"mcm","clk":"1009342040","pt":1580643635127,"mc":[{"id":"1.168224328","rc":[{"batl":[[0,23,135],[1,24,8.93],[2,26,44.37]],"ltp":15.0,"tv":3569.55,"id":2397396},{"batb":[[0,1.05,1848.38],[1,1.04,1184.63],[2,1.03,445.06]],"batl":[[0,1.07,4696.89]],"ltp":1.05,"tv":39971.92,"id":8979329}]}]}
{"op":"mcm","clk":"1009342196","pt":1580643636234,"mc":[{"id":"1.168224328","rc":[{"batb":[[2,11,44.69]],"ltp":15.0,"tv":3569.55,"id":2397396},{"batb":[[0,1.05,3806.63]],"ltp":1.05,"tv":39971.92,"id":8979329}]}]}
{"op":"mcm","clk":"1009342677","pt":1580643639314,"mc":[{"id":"1.168224328","rc":[{"batb":[[0,15,24.31]],"ltp":15.0,"tv":3569.55,"id":2397396},{"batl":[[1,1.08,323.28]],"ltp":1.05,"tv":39971.92,"id":8979329}]}]}
{"op":"mcm","clk":"1009343128","pt":1580643642039,"mc":[{"id":"1.168224328","rc":[{"batb":[[2,12,4.9]],"ltp":15.0,"tv":3569.55,"id":2397396},{"batb":[[0,1.06,5.89],[1,1.05,3806.63],[2,1.04,1184.63]],"ltp":1.05,"tv":39971.92,"id":8979329}]}]}
{"op":"mcm","clk":"1009343663","pt":1580643645319,"mc":[{"id":"1.168224328","rc":[{"batb":[[0,1.05,3806.63],[1,1.04,1184.63],[2,1.03,445.06]],"ltp":1.05,"tv":39971.92,"id":8979329}]}]}
{"op":"mcm","clk":"1009344021","pt":1580643647946,"mc":[{"id":"1.168224328","rc":[{"batl":[[1,1.08,386.28]],"ltp":1.05,"tv":39971.92,"id":8979329}]}]}
{"op":"mcm","clk":"1009344202","pt":1580643649227,"mc":[{"id":"1.168224328","rc":[{"batb":[[0,1.05,5382.32]],"ltp":1.05,"tv":39971.92,"id":8979329}]}]}
{"op":"mcm","clk":"1009344890","pt":1580643654354,"mc":[{"id":"1.168224328","rc":[{"batl":[[0,24,8.93],[1,55,2],[2,110,2]],"ltp":15.0,"tv":3569.55,"id":2397396},{"batb":[[0,1.05,1982.23],[1,1.04,75.5]],"batl":[[0,1.07,242.5]],"ltp":1.05,"tv":39971.92,"id":8979329}]}]}
{"op":"mcm","clk":"1009345022","pt":1580643655269,"mc":[{"id":"1.168224328","rc":[{"batb":[[0,12,4.9],[1,11,49.72],[2,8,37.86]],"batl":[[0,1000,0.02],[1,55,0],[2,110,0]],"ltp":15.0,"tv":3569.55,"id":2397396},{"batb":[[0,1.04,75.5],[1,1.03,246.17],[2,1.02,297.25]],"batl":[[0,1.08,166.34],[1,1.09,181.5],[2,1.1,169.25]],"ltp":1.05,"tv":39971.92,"id":8979329}]}]}
{"op":"mcm","clk":"1009345258","pt":1580643656864,"mc":[{"id":"1.168224328","rc":[{"batb":[[1,1.03,2106]],"batl":[[1,1.09,1438.26],[2,1.1,665.39]],"ltp":1.05,"tv":39971.92,"id":8979329}]}]}
{"op":"mcm","clk":"1009345366","pt":1580643657566,"mc":[{"id":"1.168224328","rc":[{"batb":[[1,1.03,246.17]],"batl":[[1,1.09,181.5],[2,1.1,169.25]],"ltp":1.05,"tv":39971.92,"id":8979329}]}]}
{"op":"mcm","clk":"1009345908","pt":1580643661091,"mc":[{"id":"1.168224328","rc":[{"batb":[[0,1.05,1824.4],[1,1.04,75.5],[2,1.03,246.17]],"batl":[[0,1.06,967.57],[1,1.07,831.77],[2,1.08,166.34]],"ltp":1.05,"tv":39971.92,"id":8979329}]}]}
{"op":"mcm","clk":"1009346178","pt":1580643662850,"mc":[{"id":"1.168224328","rc":[{"batb":[[0,1.04,75.5],[1,1.03,246.17],[2,1.02,297.25]],"batl":[[0,1.08,166.34],[1,1.09,181.5],[2,1.1,169.25]],"ltp":1.05,"tv":39971.92,"id":8979329}]}]}
{"op":"mcm","clk":"1009346604","pt":1580643665689,"mc":[{"id":"1.168224328","rc":[{"batb":[[1,1.03,2106]],"batl":[[1,1.09,1438.26],[2,1.1,665.39]],"ltp":1.05,"tv":39971.92,"id":8979329}]}]}
{"op":"mcm","clk":"1009348674","pt":1580643679221,"mc":[{"id":"1.168224328","rc":[{"batb":[[1,1.03,246.17]],"ltp":1.05,"tv":39971.92,"id":8979329}]}]}
{"op":"mcm","clk":"1009348884","pt":1580643680727,"mc":[{"id":"1.168224328","rc":[{"batl":[[0,1.09,1438.26],[1,1.1,665.39],[2,1.11,245.39]],"ltp":1.05,"tv":39971.92,"id":8979329}]}]}
{"op":"mcm","clk":"1009349146","pt":1580643682224,"mc":[{"id":"1.168224328","rc":[{"batl":[[0,13.5,5.47],[1,16,13.04],[2,16.5,175]],"ltp":15.0,"tv":3569.55,"id":2397396},{"batb":[[0,1.07,1790.3],[1,1.05,2655.22],[2,1.04,75.5]],"batl":[[1,1.1,3565.8]],"ltp":1.05,"tv":39971.92,"id":8979329}]}]}
{"op":"mcm","clk":"1009349348","pt":1580643683202,"mc":[{"id":"1.168224328","rc":[{"batb":[[2,9.6,65.46]],"ltp":15.0,"tv":3569.55,"id":2397396},{"batb":[[0,1.07,3180.77],[2,1.04,2375.92]],"ltp":1.05,"tv":39971.92,"id":8979329}]}]}
{"op":"mcm","clk":"1009349558","pt":1580643684309,"mc":[{"id":"1.168224328","rc":[{"batb":[[1,11.5,3.36],[2,11,49.72]],"ltp":15.0,"tv":3569.55,"id":2397396},{"batb":[[0,1.07,3348.81]],"ltp":1.05,"tv":39971.92,"id":8979329}]}]}
{"op":"mcm","clk":"1009349697","pt":1580643685117,"mc":[{"id":"1.168224328","rc":[{"batl":[[1,1.1,3722.92]],"ltp":1.05,"tv":39971.92,"id":8979329}]}]}
{"op":"mcm","clk":"1009349939","pt":1580643686582,"mc":[{"id":"1.168224328","rc":[{"batb":[[0,11.5,3.36],[1,11,49.72],[2,9.6,65.46]],"ltp":15.0,"tv":3569.55,"id":2397396}]}]}
{"op":"mcm","clk":"1009350360","pt":1580643689512,"mc":[{"id":"1.168224328","rc":[{"batb":[[2,10,6.74]],"ltp":15.0,"tv":3569.55,"id":2397396},{"batb":[[1,1.05,2975.11],[2,1.04,2822.79]],"ltp":1.05,"tv":39971.92,"id":8979329}]}]}
{"op":"mcm","clk":"1009351382","pt":1580643696827,"mc":[{"id":"1.168224328","rc":[{"batb":[[1,1.06,63],[2,1.05,2975.11]],"ltp":1.05,"tv":39971.92,"id":8979329}]}]}
{"op":"mcm","clk":"1009351469","pt":1580643697407,"mc":[{"id":"1.168224328","rc":[{"trd":[[13.5,9.99]],"batl":[[0,16,13.04],[1,16.5,175],[2,21,125.46]],"ltp":13.5,"tv":3575.02,"id":2397396},{"trd":[[1.08,215.46]],"batl":[[0,1.08,81.62],[1,1.09,1438.26],[2,1.1,3722.92]],"ltp":1.08,"tv":40040.3,"id":8979329}],"tv":43615.33}]}
{"op":"mcm","clk":"1009352070","pt":1580643701209,"mc":[{"id":"1.168224328","rc":[{"batb":[[0,1.07,4923.16],[2,1.05,2979.26]],"ltp":1.08,"tv":40040.3,"id":8979329}]}]}
{"op":"mcm","clk":"1009352477","pt":1580643704051,"mc":[{"id":"1.168224328","rc":[{"batl":[[1,21,125.46],[2,26,2]],"ltp":13.5,"tv":3575.02,"id":2397396},{"batl":[[2,1.1,842.92]],"ltp":1.08,"tv":40040.3,"id":8979329}]}]}
{"op":"mcm","clk":"1009352652","pt":1580643705346,"mc":[{"id":"1.168224328","rc":[{"batl":[[1,21,2]],"ltp":13.5,"tv":3575.02,"id":2397396},{"batb":[[2,1.05,510.05]],"batl":[[2,1.1,822.51]],"ltp":1.08,"tv":40040.3,"id":8979329}]}]}
{"op":"mcm","clk":"1009352743","pt":1580643705839,"mc":[{"id":"1.168224328","rc":[{"batb":[[1,10,6.74],[2,9.6,65.46]],"batl":[[0,21,2],[1,26,2],[2,36,2]],"ltp":13.5,"tv":3575.02,"id":2397396},{"batb":[[0,1.07,168.04],[2,1.05,324.04]],"batl":[[1,1.1,157.12],[2,1.11,245.39]],"ltp":1.08,"tv":40040.3,"id":8979329}]}]}
{"op":"mcm","clk":"1009352974","pt":1580643707243,"mc":[{"id":"1.168224328","rc":[{"batb":[[0,10,6.74],[1,9.6,65.46],[2,5,79.87]],"ltp":13.5,"tv":3575.02,"id":2397396},{"batb":[[0,1.06,63],[1,1.05,324.04],[2,1.04,2557.56]],"ltp":1.08,"tv":40040.3,"id":8979329}]}]}
{"op":"mcm","clk":"1009353028","pt":1580643707529,"mc":[{"id":"1.168224328","rc":[{"batl":[[0,26,2],[1,36,2],[2,1000,0.02]],"ltp":13.5,"tv":3575.02,"id":2397396},{"batb":[[1,1.05,4.15]],"ltp":1.08,"tv":40040.3,"id":8979329}]}]}
{"op":"mcm","clk":"1009353289","pt":1580643709164,"mc":[{"id":"1.168224328","rc":[{"batb":[[1,1.05,1828.55]],"batl":[[2,1.11,1712.06]],"ltp":1.08,"tv":40040.3,"id":8979329}]}]}
{"op":"mcm","clk":"1009353523","pt":1580643710638,"mc":[{"id":"1.168224328","rc":[{"batl":[[0,21,2],[1,26,2],[2,36,2]],"ltp":13.5,"tv":3575.02,"id":2397396},{"batb":[[1,1.05,2207.04]],"ltp":1.08,"tv":40040.3,"id":8979329}]}]}
{"op":"mcm","clk":"1009353790","pt":1580643712344,"mc":[{"id":"1.168224328","rc":[{"batb":[[0,11,6.48],[1,10,6.74],[2,9.6,65.46]],"ltp":13.5,"tv":3575.02,"id":2397396},{"batl":[[1,1.1,347.17]],"ltp":1.08,"tv":40040.3,"id":8979329}]}]}
{"op":"mcm","clk":"1009353826","pt":1580643712666,"mc":[{"id":"1.168224328","rc":[{"batb":[[0,10,6.74],[1,9.6,65.46],[2,5,79.87]],"ltp":13.5,"tv":3575.02,"id":2397396},{"batb":[[1,1.05,382.64]],"batl":[[1,1.1,157.12]],"ltp":1.08,"tv":40040.3,"id":8979329}]}]}
{"op":"mcm","clk":"1009354069","pt":1580643714192,"mc":[{"id":"1.168224328","rc":[{"batl":[[1,1.11,1712.06],[2,1.12,423.76]],"ltp":1.08,"tv":40040.3,"id":8979329}]}]}
{"op":"mcm","clk":"1009354255","pt":1580643715348,"mc":[{"id":"1.168224328","rc":[{"batl":[[0,12,890.6],[1,13.5,176],[2,21,2]],"ltp":13.5,"tv":3575.02,"id":2397396},{"trd":[[1.08,378.7]],"batb":[[0,1.08,1597.21],[1,1.07,2005.12],[2,1.06,63]],"batl":[[0,1.11,3591.06],[1,1.12,423.76],[2,1.22,3.01]],"ltp":1.08,"tv":40203.54,"id":8979329}],"tv":43778.57}]}
{"op":"mcm","clk":"1009354440","pt":1580643716358,"mc":[{"id":"1.168224328","rc":[{"batb":[[0,10,10.94],[2,8.8,31.79]],"batl":[[0,12,3.8],[2,15,126.63]],"ltp":13.5,"tv":3575.02,"id":2397396},{"batb":[[0,1.09,2603.88],[1,1.08,517.74],[2,1.07,1600.26]],"batl":[[0,1.11,3691.66],[2,1.14,241.97]],"ltp":1.08,"tv":40203.54,"id":8979329}]}]}
{"op":"mcm","clk":"1009354483","pt":1580643716596,"mc":[{"id":"1.168224328","rc":[{"batb":[[1,1.08,436.24]],"ltp":1.08,"tv":40203.54,"id":8979329}]}]}
{"op":"mcm","clk":"1009354912","pt":1580643718777,"mc":[{"id":"1.168224328","rc":[{"batl":[[1,13,3.36],[2,13.5,176]],"ltp":13.5,"tv":3575.02,"id":2397396}]}]}
{"op":"mcm","clk":"1009355112","pt":1580643720060,"mc":[{"id":"1.168224328","rc":[{"batl":[[2,1.13,224.33]],"ltp":1.08,"tv":40203.54,"id":8979329}]}]}
{"op":"mcm","clk":"1009355467","pt":1580643721971,"mc":[{"id":"1.168224328","rc":[{"batb":[[2,9.2,7.32]],"ltp":13.5,"tv":3575.02,"id":2397396},{"batb":[[2,1.07,1855.33]],"batl":[[2,1.13,393.83]],"ltp":1.08,"tv":40203.54,"id":8979329}]}]}
{"op":"mcm","clk":"1009356577","pt":1580643728314,"mc":[{"id":"1.168224328","rc":[{"trd":[[1.09,2387.64]],"batb":[[0,1.09,2586.4]],"ltp":1.09,"tv":40238.5,"id":8979329}],"tv":43813.52}]}
{"op":"mcm","clk":"1009356642","pt":1580643728643,"mc":[{"id":"1.168224328","rc":[{"batl":[[1,1.12,166.96]],"ltp":1.09,"tv":40238.5,"id":8979329}]}]}
{"op":"mcm","clk":"1009357050","pt":1580643731374,"mc":[{"id":"1.168224328","rc":[{"batl":[[0,13,3.36],[1,15.5,2],[2,18,2]],"ltp":13.5,"tv":3575.02,"id":2397396},{"batb":[[0,1.09,1112.33],[1,1.08,167.88]],"batl":[[0,1.11,287.4]],"ltp":1.09,"tv":40238.5,"id":8979329}]}]}
{"op":"mcm","clk":"1009357105","pt":1580643731757,"mc":[{"id":"1.168224328","rc":[{"batb":[[0,10,4.2],[1,9.2,7.32],[2,8.8,31.79]],"ltp":13.5,"tv":3575.02,"id":2397396},{"batb":[[0,1.07,1654.82],[1,1.06,394.08],[2,1.05,382.64]],"batl":[[0,1.11,123.9]],"ltp":1.09,"tv":40238.5,"id":8979329}]}]}
{"op":"mcm","clk":"1009357325","pt":1580643733369,"mc":[{"id":"1.168224328","rc":[{"batb":[[0,9.2,7.32],[1,8.8,31.79],[2,5,79.87]],"batl":[[0,15.5,2],[1,18,2],[2,21,2]],"ltp":13.5,"tv":3575.02,"id":2397396},{"batl":[[0,1.11,81.89]],"ltp":1.09,"tv":40238.5,"id":8979329}]}]}
{"op":"mcm","clk":"1009357441","pt":1580643734274,"mc":[{"id":"1.168224328","rc":[{"batb":[[0,1.07,3445.12]],"batl":[[1,1.12,980.16],[2,1.13,1283.06]],"ltp":1.09,"tv":40238.5,"id":8979329}]}]}
{"op":"mcm","clk":"1009357535","pt":1580643735080,"mc":[{"id":"1.168224328","rc":[{"batb":[[0,1.08,75],[1,1.07,3445.12],[2,1.06,394.08]],"ltp":1.09,"tv":40238.5,"id":8979329}]}]}
{"op":"mcm","clk":"1009357786","pt":1580643737183,"mc":[{"id":"1.168224328","rc":[{"batb":[[1,1.07,1654.82]],"batl":[[2,1.13,1113.56]],"ltp":1.09,"tv":40238.5,"id":8979329}]}]}
{"op":"mcm","clk":"1009357929","pt":1580643738370,"mc":[{"id":"1.168224328","rc":[{"batb":[[0,10,7.36],[1,9.2,7.32],[2,8.8,31.79]],"ltp":13.5,"tv":3575.02,"id":2397396},{"batl":[[0,1.11,282.39]],"ltp":1.09,"tv":40238.5,"id":8979329}]}]}
{"op":"mcm","clk":"1009358046","pt":1580643739283,"mc":[{"id":"1.168224328","rc":[{"batb":[[0,9.2,7.32],[1,8.8,31.79],[2,5,79.87]],"ltp":13.5,"tv":3575.02,"id":2397396},{"batl":[[0,1.11,81.89],[2,1.13,889.23]],"ltp":1.09,"tv":40238.5,"id":8979329}]}]}
{"op":"mcm","clk":"1009358184","pt":1580643740293,"mc":[{"id":"1.168224328","rc":[{"batb":[[0,9.2,12.36]],"batl":[[0,11,6.1],[1,11.5,21],[2,12,192]],"ltp":13.5,"tv":3575.02,"id":2397396},{"batb":[[0,1.1,1740.73],[1,1.08,1377.76],[2,1.07,1912.62]],"batl":[[1,1.12,1018.09],[2,1.13,3731.23]],"ltp":1.09,"tv":40238.5,"id":8979329}]}]}
{"op":"mcm","clk":"1009358240","pt":1580643740787,"mc":[{"id":"1.168224328","rc":[{"batb":[[2,7.4,46.89]],"ltp":13.5,"tv":3575.02,"id":2397396},{"batb":[[0,1.1,2713.71],[1,1.09,1065.67],[2,1.08,1377.76]],"ltp":1.09,"tv":40238.5,"id":8979329}]}]}
{"op":"mcm","clk":"1009358731","pt":1580643744385,"mc":[{"id":"1.168224328","rc":[{"trd":[[1.1,1511.45]],"batb":[[0,1.1,2711.93]],"ltp":1.1,"tv":40242.06,"id":8979329}],"tv":43817.08}]}
{"op":"mcm","clk":"1009359229","pt":1580643747704,"mc":[{"id":"1.168224328","rc":[{"batb":[[0,1.1,4281.87]],"ltp":1.1,"tv":40242.06,"id":8979329}]}]}
{"op":"mcm","clk":"1009359942","pt":1580643752189,"mc":[{"id":"1.168224328","rc":[{"trd":[[1.1,1515.02]],"batb":[[0,1.1,4280.09]],"ltp":1.1,"tv":40245.62,"id":8979329}],"tv":43820.65}]}
{"op":"mcm","clk":"1009360995","pt":1580643758599,"mc":[{"id":"1.168224328","rc":[{"batl":[[2,1.13,3675.19]],"ltp":1.1,"tv":40245.62,"id":8979329}]}]}
{"op":"mcm","clk":"1009361529","pt":1580643762112,"mc":[{"id":"1.168224328","rc":[{"batl":[[1,1.12,1073.9]],"ltp":1.1,"tv":40245.62,"id":8979329}]}]}
{"op":"mcm","clk":"1009363670","pt":1580643777189,"mc":[{"id":"1.168224328","rc":[{"batb":[[0,1.1,2542.92]],"batl":[[1,1.12,204.89],[2,1.13,2842]],"ltp":1.1,"tv":40245.62,"id":8979329}]}]}
{"op":"mcm","clk":"1009364064","pt":1580643780135,"mc":[{"id":"1.168224328","rc":[{"batb":[[1,1.09,2822.37]],"ltp":1.1,"tv":40245.62,"id":8979329}]}]}
{"op":"mcm","clk":"1009365702","pt":1580643791850,"mc":[{"id":"1.168224328","rc":[{"batl":[[2,13.5,89.33]],"ltp":13.5,"tv":3575.02,"id":2397396},{"batl":[[2,1.14,705.53]],"ltp":1.1,"tv":40245.62,"id":8979329}]}]}
{"op":"mcm","clk":"1009365933","pt":1580643793344,"mc":[{"id":"1.168224328","rc":[{"batb":[[0,9.2,5.04]],"batl":[[0,11.5,3.36],[1,15.5,2],[2,1000,0.02]],"ltp":13.5,"tv":3575.02,"id":2397396},{"batb":[[0,1.1,972.98],[2,1.08,75]],"batl":[[1,1.14,705.53],[2,1.15,1108.94]],"ltp":1.1,"tv":40245.62,"id":8979329}]}]}
{"op":"mcm","clk":"1009365976","pt":1580643793664,"mc":[{"id":"1.168224328","rc":[{"batb":[[1,7.4,46.89],[2,5,79.87]],"ltp":13.5,"tv":3575.02,"id":2397396},{"batb":[[0,1.09,2822.37],[1,1.08,75],[2,1.07,255.07]],"ltp":1.1,"tv":40245.62,"id":8979329}]}]}
{"op":"mcm","clk":"1009366341","pt":1580643796350,"mc":[{"id":"1.168224328","rc":[{"batb":[[0,7.4,46.89],[1,5,79.87],[2,4,37.86]],"batl":[[0,12.5,2],[1,13.5,2],[2,15.5,2]],"ltp":13.5,"tv":3575.02,"id":2397396},{"batb":[[0,1.09,3007.98],[1,1.08,264.56]],"ltp":1.1,"tv":40245.62,"id":8979329}]}]}
{"op":"mcm","clk":"1009366493","pt":1580643797250,"mc":[{"id":"1.168224328","rc":[{"batl":[[2,1000,0.02]],"ltp":13.5,"tv":3575.02,"id":2397396},{"batb":[[2,1.06,63]],"batl":[[1,1.14,194.93],[2,1.22,3.01]],"ltp":1.1,"tv":40245.62,"id":8979329}]}]}
{"op":"mcm","clk":"1009366709","pt":1580643798717,"mc":[{"id":"1.168224328","rc":[{"batb":[[1,1.08,189.56],[2,1.05,4.15]],"ltp":1.1,"tv":40245.62,"id":8979329}]}]}
{"op":"mcm","clk":"1009366963","pt":1580643800340,"mc":[{"id":"1.168224328","rc":[{"batb":[[0,11,8.81],[1,9.2,22.91],[2,7.4,46.89]],"batl":[[0,12,5.43],[1,12.5,2],[2,13,159]],"ltp":13.5,"tv":3575.02,"id":2397396},{"batb":[[2,1.06,260.23]],"batl":[[0,1.1,263.4],[1,1.11,1087.56],[2,1.12,3810.45]],"ltp":1.1,"tv":40245.62,"id":8979329}]}]}
{"op":"mcm","clk":"1009367042","pt":1580643800858,"mc":[{"id":"1.168224328","rc":[{"batb":[[1,9.2,51.08],[2,8.2,37.61]],"ltp":13.5,"tv":3575.02,"id":2397396},{"batb":[[1,1.08,1339.5]],"batl":[[0,1.1,239.25]],"ltp":1.1,"tv":40245.62,"id":8979329}]}]}
{"op":"mcm","clk":"1009367275","pt":1580643802353,"mc":[{"id":"1.168224328","rc":[{"batb":[[1,9.6,4.2],[2,9.2,51.08]],"batl":[[1,12.5,5.36]],"ltp":13.5,"tv":3575.02,"id":2397396},{"batb":[[0,1.09,3176.02]],"ltp":1.1,"tv":40245.62,"id":8979329}]}]}
{"op":"mcm","clk":"1009367598","pt":1580643804530,"mc":[{"id":"1.168224328","rc":[{"batl":[[2,1.12,3832.3]],"ltp":1.1,"tv":40245.62,"id":8979329}]}]}
{"op":"mcm","clk":"1009367929","pt":1580643806995,"mc":[{"id":"1.168224328","rc":[{"batb":[[2,9.2,58.6]],"ltp":13.5,"tv":3575.02,"id":2397396},{"batb":[[2,1.07,255.07]],"batl":[[2,1.12,4019.51]],"ltp":1.1,"tv":40245.62,"id":8979329}]}]}
{"op":"mcm","clk":"1009368131","pt":1580643808390,"mc":[{"id":"1.168224328","rc":[{"batl":[[0,12.5,5.36],[1,13.5,2],[2,1000,0.02]],"ltp":13.5,"tv":3575.02,"id":2397396},{"batl":[[1,1.11,1043.92],[2,1.12,1139.51]],"ltp":1.1,"tv":40245.62,"id":8979329}]}]}
{"op":"mcm","clk":"1009368225","pt":1580643809123,"mc":[{"id":"1.168224328","rc":[{"batb":[[2,9.2,7.52]],"ltp":13.5,"tv":3575.02,"id":2397396},{"batb":[[0,1.09,1036.08]],"batl":[[1,1.11,81.89],[2,1.12,21.85]],"ltp":1.1,"tv":40245.62,"id":8979329}]}]}
{"op":"mcm","clk":"1009368404","pt":1580643810292,"mc":[{"id":"1.168224328","rc":[{"batb":[[1,9.2,7.52],[2,8.2,37.61]],"batl":[[0,12.5,2]],"ltp":13.5,"tv":3575.02,"id":2397396},{"batb":[[0,1.09,868.04]],"batl":[[2,1.12,236.93]],"ltp":1.1,"tv":40245.62,"id":8979329}]}]}
{"op":"mcm","clk":"1009368494","pt":1580643810996,"mc":[{"id":"1.168224328","rc":[{"batb":[[1,1.08,1414.5]],"ltp":1.1,"tv":40245.62,"id":8979329}]}]}
{"op":"mcm","clk":"1009368692","pt":1580643812320,"mc":[{"id":"1.168224328","rc":[{"batl":[[2,1.12,424.14]],"ltp":1.1,"tv":40245.62,"id":8979329}]}]}
{"op":"mcm","clk":"1009368906","pt":1580643814102,"mc":[{"id":"1.168224328","rc":[{"trd":[[11,14.62]],"batb":[[0,10,8.96]],"ltp":11.0,"tv":3583.83,"id":2397396},{"trd":[[1.1,2101.52]],"batb":[[0,1.1,320.05],[1,1.09,1278.92],[2,1.08,1414.5]],"batl":[[0,1.11,734.29],[1,1.12,1506.79],[2,1.13,324.95]],"ltp":1.1,"tv":40832.12,"id":8979329}],"tv":44415.96}]}
{"op":"mcm","clk":"1009369211","pt":1580643816253,"mc":[{"id":"1.168224328","rc":[{"batb":[[0,1.09,679.8],[1,1.08,1414.5],[2,1.07,255.07]],"batl":[[0,1.11,286.39],[1,1.12,424.14]],"ltp":1.1,"tv":40832.12,"id":8979329}]}]}
{"op":"mcm","clk":"1009369371","pt":1580643817316,"mc":[{"id":"1.168224328","rc":[{"batb":[[0,9.2,7.52],[1,8.2,37.61],[2,5,79.87]],"ltp":11.0,"tv":3583.83,"id":2397396},{"batl":[[0,1.11,81.89]],"ltp":1.1,"tv":40832.12,"id":8979329}]}]}
{"op":"mcm","clk":"1009369658","pt":1580643819124,"mc":[{"id":"1.168224328","rc":[{"batb":[[1,1.08,2688.7]],"batl":[[2,1.13,1780.95]],"ltp":1.1,"tv":40832.12,"id":8979329}]}]}
{"op":"mcm","clk":"1009370099","pt":1580643822264,"mc":[{"id":"1.168224328","rc":[{"batl":[[2,1.13,324.95]],"ltp":1.1,"tv":40832.12,"id":8979329}]}]}
{"op":"mcm","clk":"1009370246","pt":1580643823336,"mc":[{"id":"1.168224328","rc":[{"batb":[[0,10,2],[1,9.2,7.52],[2,8.2,37.61]],"batl":[[0,13.5,2],[1,1000,0.02],[2,1000,0]],"ltp":11.0,"tv":3583.83,"id":2397396},{"batb":[[0,1.09,494.19]],"batl":[[0,1.11,245.39]],"ltp":1.1,"tv":40832.12,"id":8979329}]}]}
{"op":"mcm","clk":"1009370336","pt":1580643823944,"mc":[{"id":"1.168224328","rc":[{"batb":[[0,9.2,7.52],[1,8.2,37.61],[2,5,79.87]],"ltp":11.0,"tv":3583.83,"id":2397396},{"batb":[[1,1.08,2613.7]],"batl":[[0,1.11,81.89]],"ltp":1.1,"tv":40832.12,"id":8979329}]}]}
{"op":"mcm","clk":"1009370526","pt":1580643825308,"mc":[{"id":"1.168224328","rc":[{"batb":[[0,11,2],[1,10,18.7],[2,9.2,7.52]],"batl":[[1,14,155],[2,15,70.43]],"ltp":11.0,"tv":3583.83,"id":2397396},{"batb":[[0,1.09,514.76]],"batl":[[0,1.1,866.11],[1,1.11,3927.11],[2,1.12,424.14]],"ltp":1.1,"tv":40832.12,"id":8979329}]}]}
{"op":"mcm","clk":"1009370681","pt":1580643826322,"mc":[{"id":"1.168224328","rc":[{"batb":[[1,10,22.9],[2,9.8,61.92]],"batl":[[0,13,3.36],[1,13.5,2],[2,14,155]],"ltp":11.0,"tv":3583.83,"id":2397396},{"batl":[[0,1.1,841.62],[1,1.11,3969.12],[2,1.12,187.21]],"ltp":1.1,"tv":40832.12,"id":8979329}]}]}
{"op":"mcm","clk":"1009371386","pt":1580643831658,"mc":[{"id":"1.168224328","rc":[{"batb":[[1,10,24.9]],"ltp":11.0,"tv":3583.83,"id":2397396},{"batb":[[1,1.08,2688.7]],"batl":[[1,1.11,4128.62]],"ltp":1.1,"tv":40832.12,"id":8979329}]}]}
{"op":"mcm","clk":"1009372062","pt":1580643836125,"mc":[{"id":"1.168224328","rc":[{"trd":[[1.09,2587.64]],"batb":[[0,1.09,414.76]],"ltp":1.09,"tv":41032.12,"id":8979329}],"tv":44615.96}]}
{"op":"mcm","clk":"1009372104","pt":1580643836448,"mc":[{"id":"1.168224328","rc":[{"batl":[[1,1.11,4074.35]],"ltp":1.09,"tv":41032.12,"id":8979329}]}]}
{"op":"mcm","clk":"1009372433","pt":1580643838403,"mc":[{"id":"1.168224328","rc":[{"batb":[[0,10,6.2],[1,9.2,7.52],[2,9,30.61]],"batl":[[2,15.5,2]],"ltp":11.0,"tv":3583.83,"id":2397396},{"batb":[[0,1.08,2688.7],[1,1.07,255.07],[2,1.06,352.58]],"batl":[[0,1.11,902.11],[1,1.12,187.21],[2,1.13,324.95]],"ltp":1.09,"tv":41032.12,"id":8979329}]}]}
{"op":"mcm","clk":"1009372599","pt":1580643839403,"mc":[{"id":"1.168224328","rc":[{"batb":[[0,10,2]],"batl":[[0,13.5,2],[1,15.5,2],[2,1000,0.02]],"ltp":11.0,"tv":3583.83,"id":2397396},{"batb":[[0,1.09,44.74],[1,1.08,2744.47],[2,1.07,255.07]],"batl":[[0,1.1,54.77],[1,1.11,860.1],[2,1.12,187.21]],"ltp":1.09,"tv":41032.12,"id":8979329}]}]}
{"op":"mcm","clk":"1009372642","pt":1580643839658,"mc":[{"id":"1.168224328","rc":[{"batb":[[0,1.08,2744.47],[1,1.07,255.07],[2,1.06,352.58]],"batl":[[0,1.11,860.1],[1,1.12,187.21],[2,1.13,324.95]],"ltp":1.09,"tv":41032.12,"id":8979329}]}]}
{"op":"mcm","clk":"1009372851","pt":1580643841005,"mc":[{"id":"1.168224328","rc":[{"batb":[[0,1.08,2319.22]],"ltp":1.09,"tv":41032.12,"id":8979329}]}]}
{"op":"mcm","clk":"1009373382","pt":1580643844016,"mc":[{"id":"1.168224328","rc":[{"batb":[[0,1.09,860.28],[1,1.08,2319.22],[2,1.07,255.07]],"batl":[[0,1.1,461.53],[1,1.11,1509.07],[2,1.12,187.21]],"ltp":1.09,"tv":41032.12,"id":8979329}]}]}
{"op":"mcm","clk":"1009373604","pt":1580643845405,"mc":[{"id":"1.168224328","rc":[{"batb":[[0,11,2],[1,10,2],[2,9.2,7.52]],"ltp":11.0,"tv":3583.83,"id":2397396},{"batb":[[0,1.08,2319.22],[1,1.07,255.07],[2,1.06,352.58]],"batl":[[0,1.1,167.95],[1,1.11,860.1]],"ltp":1.09,"tv":41032.12,"id":8979329}]}]}
{"op":"mcm","clk":"1009373637","pt":1580643845716,"mc":[{"id":"1.168224328","rc":[{"batb":[[0,10,2],[1,9.2,7.52],[2,9,30.61]],"ltp":11.0,"tv":3583.83,"id":2397396},{"batl":[[0,1.11,860.1],[1,1.12,187.21],[2,1.13,324.95]],"ltp":1.09,"tv":41032.12,"id":8979329}]}]}
{"op":"mcm","clk":"1009374004","pt":1580643848202,"mc":[{"id":"1.168224328","rc":[{"batb":[[0,1.08,3130.99]],"batl":[[1,1.12,1283.67]],"ltp":1.09,"tv":41032.12,"id":8979329}]}]}
{"op":"mcm","clk":"1009374711","pt":1580643852799,"mc":[{"id":"1.168224328","rc":[{"batb":[[0,11,2],[1,10,2]],"ltp":11.0,"tv":3583.83,"id":2397396},{"batl":[[0,1.1,180.65],[1,1.11,241.39]],"ltp":1.09,"tv":41032.12,"id":8979329}]}]}
{"op":"mcm","clk":"1009374839","pt":1580643853645,"mc":[{"id":"1.168224328","rc":[{"batb":[[0,1.08,3055.99]],"ltp":1.09,"tv":41032.12,"id":8979329}]}]}
{"op":"mcm","clk":"1009375128","pt":1580643855312,"mc":[{"id":"1.168224328","rc":[{"batb":[[1,10.5,180.5],[2,10,187.37]],"batl":[[0,13.5,6.47],[1,15,181],[2,15.5,2]],"ltp":11.0,"tv":3583.83,"id":2397396},{"batl":[[0,1.1,9511.65],[2,1.12,23.59]],"ltp":1.09,"tv":41032.12,"id":8979329}]}]}
{"op":"mcm","clk":"1009375286","pt":1580643856312,"mc":[{"id":"1.168224328","rc":[{"batb":[[0,12,2],[1,11,2],[2,10.5,22.25]],"batl":[[0,13.5,9.83]],"ltp":11.0,"tv":3583.83,"id":2397396},{"batb":[[0,1.08,3224.03],[1,1.07,1540.81]],"batl":[[0,1.09,37.5],[1,1.1,3720.7],[2,1.11,241.39]],"ltp":1.09,"tv":41032.12,"id":8979329}]}]}
{"op":"mcm","clk":"1009375914","pt":1580643860312,"mc":[{"id":"1.168224328","rc":[{"batb":[[1,10.5,22.25],[2,10,20.54]],"ltp":11.0,"tv":3583.83,"id":2397396},{"batb":[[2,1.06,277.58]],"ltp":1.09,"tv":41032.12,"id":8979329}]}]}
{"op":"mcm","clk":"1009376276","pt":1580643862923,"mc":[{"id":"1.168224328","rc":[{"batb":[[1,11,2],[2,10.5,22.25]],"ltp":11.0,"tv":3583.83,"id":2397396},{"trd":[[1.09,2588.13]],"batl":[[0,1.09,37.26]],"ltp":1.09,"tv":41032.6,"id":8979329}],"tv":44616.44}]}
{"op":"mcm","clk":"1009376991","pt":1580643868339,"mc":[{"id":"1.168224328","rc":[{"batl":[[1,15.5,2],[2,17.5,198.41]],"ltp":11.0,"tv":3583.83,"id":2397396},{"batl":[[1,1.1,1889.7]],"ltp":1.09,"tv":41032.6,"id":8979329}]}]}
{"op":"mcm","clk":"1009377130","pt":1580643869349,"mc":[{"id":"1.168224328","rc":[{"batb":[[0,11,2],[1,10,2],[2,9.4,27.38]],"batl":[[0,13.5,2],[2,1000,0.02]],"ltp":11.0,"tv":3583.83,"id":2397396},{"batb":[[0,1.08,1097.23]],"batl":[[0,1.1,666.82],[1,1.11,241.39],[2,1.12,141.21]],"ltp":1.09,"tv":41032.6,"id":8979329}]}]}
{"op":"mcm","clk":"1009377490","pt":1580643871853,"mc":[{"id":"1.168224328","rc":[{"batb":[[1,1.07,2414.19]],"ltp":1.09,"tv":41032.6,"id":8979329}]}]}
{"op":"mcm","clk":"1009377989","pt":1580643875331,"mc":[{"id":"1.168224328","rc":[{"batb":[[1,10.5,20.08],[2,10,2]],"batl":[[1,15.5,179],[2,17.5,150.51]],"ltp":11.0,"tv":3583.83,"id":2397396},{"batl":[[0,1.09,677.21],[1,1.1,3724.12],[2,1.11,408.11]],"ltp":1.09,"tv":41032.6,"id":8979329}]}]}
{"op":"mcm","clk":"1009378135","pt":1580643876335,"mc":[{"id":"1.168224328","rc":[{"batb":[[0,11,6.2],[1,10.5,71.22]],"ltp":11.0,"tv":3583.83,"id":2397396},{"batb":[[2,1.06,1947.76]],"batl":[[1,1.1,3766.13]],"ltp":1.09,"tv":41032.6,"id":8979329}]}]}
{"op":"mcm","clk":"1009378914","pt":1580643881455,"mc":[{"id":"1.168224328","rc":[{"batl":[[0,1.09,886.42]],"ltp":1.09,"tv":41032.6,"id":8979329}]}]}
{"op":"mcm","clk":"1009381155","pt":1580643896315,"mc":[{"id":"1.168224328","rc":[{"trd":[[1.08,455.1]],"batb":[[0,1.08,1059.03]],"ltp":1.08,"tv":41109.0,"id":8979329}],"tv":44692.83}]}
{"op":"mcm","clk":"1009381329","pt":1580643897381,"mc":[{"id":"1.168224328","rc":[{"batl":[[1,15.5,2]],"ltp":11.0,"tv":3583.83,"id":2397396},{"batl":[[1,1.1,1317.13]],"ltp":1.08,"tv":41109.0,"id":8979329}]}]}
{"op":"mcm","clk":"1009381470","pt":1580643898190,"mc":[{"id":"1.168224328","rc":[{"batb":[[1,10,2],[2,9.6,66.17]],"batl":[[0,18,2],[1,1000,0.02],[2,17.5,0]],"ltp":11.0,"tv":3583.83,"id":2397396},{"batb":[[0,1.06,1947.76],[1,1.05,349.04],[2,1.03,246.67]],"batl":[[0,1.09,209.21],[1,1.1,222.66],[2,1.11,241.39]],"ltp":1.08,"tv":41109.0,"id":8979329}]}]}
{"op":"mcm","clk":"1009381668","pt":1580643899367,"mc":[{"id":"1.168224328","rc":[{"batb":[[0,10,2],[1,9.6,66.17],[2,5,79.87]],"ltp":11.0,"tv":3583.83,"id":2397396},{"trd":[[1.09,2822.66]],"batl":[[0,1.09,91.94],[1,1.11,241.39],[2,1.13,151.45]],"ltp":1.09,"tv":41343.54,"id":8979329}],"tv":44927.37}]}
{"op":"mcm","clk":"1009381993","pt":1580643901369,"mc":[{"id":"1.168224328","rc":[{"batl":[[0,15.5,2],[1,18,2],[2,1000,0.02]],"ltp":11.0,"tv":3583.83,"id":2397396},{"batb":[[0,1.07,2.07],[1,1.06,1947.76],[2,1.05,349.04]],"ltp":1.09,"tv":41343.54,"id":8979329}]}]}
{"op":"mcm","clk":"1009382173","pt":1580643902377,"mc":[{"id":"1.168224328","rc":[{"batl":[[0,18,2],[1,1000,0.02],[2,1000,0]],"ltp":11.0,"tv":3583.83,"id":2397396},{"batb":[[0,1.06,1947.76],[1,1.05,349.04],[2,1.03,246.67]],"ltp":1.09,"tv":41343.54,"id":8979329}]}]}
{"op":"mcm","clk":"1009382287","pt":1580643903080,"mc":[{"id":"1.168224328","rc":[{"batb":[[0,1.07,209.21],[1,1.06,1947.76],[2,1.05,349.04]],"ltp":1.09,"tv":41343.54,"id":8979329}]}]}
{"op":"mcm","clk":"1009382518","pt":1580643904381,"mc":[{"id":"1.168224328","rc":[{"batb":[[0,1.07,1993.86]],"batl":[[0,1.09,1375.39],[1,1.1,464.19],[2,1.11,241.39]],"ltp":1.09,"tv":41343.54,"id":8979329}]}]}
{"op":"mcm","clk":"1009382694","pt":1580643905364,"mc":[{"id":"1.168224328","rc":[{"batb":[[0,11,2.14],[1,10,2],[2,9.6,66.17]],"batl":[[0,15.5,2],[1,18,2],[2,1000,0.02]],"ltp":11.0,"tv":3583.83,"id":2397396},{"batb":[[0,1.07,1995.93]],"batl":[[1,1.1,666.34]],"ltp":1.09,"tv":41343.54,"id":8979329}]}]}
{"op":"mcm","clk":"1009382727","pt":1580643905578,"mc":[{"id":"1.168224328","rc":[{"batl":[[1,1.1,875.55]],"ltp":1.09,"tv":41343.54,"id":8979329}]}]}
{"op":"mcm","clk":"1009383234","pt":1580643908880,"mc":[{"id":"1.168224328","rc":[{"batb":[[0,1.07,211.28]],"batl":[[0,1.09,91.94],[1,1.1,411.36]],"ltp":1.09,"tv":41343.54,"id":8979329}]}]}
{"op":"mcm","clk":"1009383726","pt":1580643911794,"mc":[{"id":"1.168224328","rc":[{"batb":[[1,1.06,3749.25]],"batl":[[2,1.11,1961.73]],"ltp":1.09,"tv":41343.54,"id":8979329}]}]}
{"op":"mcm","clk":"1009384140","pt":1580643914263,"mc":[{"id":"1.168224328","rc":[{"batl":[[0,18,2],[1,1000,0.02],[2,1000,0]],"ltp":11.0,"tv":3583.83,"id":2397396},{"batb":[[0,1.06,3749.25],[1,1.05,349.04],[2,1.03,246.67]],"batl":[[2,1.11,241.39]],"ltp":1.09,"tv":41343.54,"id":8979329}]}]}
{"op":"mcm","clk":"1009384465","pt":1580643916400,"mc":[{"id":"1.168224328","rc":[{"batl":[[0,17.5,3.61],[1,18,2],[2,19.5,164]],"ltp":11.0,"tv":3583.83,"id":2397396},{"batb":[[2,1.04,3127.18]],"batl":[[0,1.07,21.78],[1,1.08,9624],[2,1.09,3775.31]],"ltp":1.09,"tv":41343.54,"id":8979329}]}]}
{"op":"mcm","clk":"1009384642","pt":1580643917380,"mc":[{"id":"1.168224328","rc":[{"batb":[[0,13.5,2],[1,13,32.57],[2,11,48.48]],"ltp":11.0,"tv":3583.83,"id":2397396},{"batb":[[2,1.04,5552.63]],"batl":[[1,1.08,3957.82],[2,1.09,2177.32]],"ltp":1.09,"tv":41343.54,"id":8979329}]}]}
{"op":"mcm","clk":"1009384813","pt":1580643918399,"mc":[{"id":"1.168224328","rc":[{"batb":[[2,12.5,3.36]],"ltp":11.0,"tv":3583.83,"id":2397396}]}]}
{"op":"mcm","clk":"1009385068","pt":1580643919878,"mc":[{"id":"1.168224328","rc":[{"batl":[[2,1.09,2386.53]],"ltp":1.09,"tv":41343.54,"id":8979329}]}]}
{"op":"mcm","clk":"1009385214","pt":1580643920890,"mc":[{"id":"1.168224328","rc":[{"batl":[[2,1.09,669.49]],"ltp":1.09,"tv":41343.54,"id":8979329}]}]}
{"op":"mcm","clk":"1009385374","pt":1580643922002,"mc":[{"id":"1.168224328","rc":[{"trd":[[1.07,137.12]],"batb":[[0,1.07,28.22],[1,1.06,3749.25],[2,1.05,349.04]],"batl":[[0,1.08,3957.82],[1,1.09,669.49],[2,1.1,411.36]],"ltp":1.07,"tv":41387.1,"id":8979329}],"tv":44970.93}]}
{"op":"mcm","clk":"1009385677","pt":1580643923775,"mc":[{"id":"1.168224328","rc":[{"batl":[[1,1.09,858.99]],"ltp":1.07,"tv":41387.1,"id":8979329}]}]}
{"op":"mcm","clk":"1009386696","pt":1580643930306,"mc":[{"id":"1.168224328","rc":[{"batb":[[0,13,32.57],[1,12.5,3.36],[2,12,2]],"batl":[[0,26,2],[1,36,2],[2,1000,0.02]],"ltp":11.0,"tv":3583.83,"id":2397396},{"batb":[[1,1.06,1670.18],[2,1.05,4.15]],"batl":[[0,1.09,858.99],[1,1.1,411.36],[2,1.11,489.89]],"ltp":1.07,"tv":41387.1,"id":8979329}]}]}
{"op":"mcm","clk":"1009386763","pt":1580643930716,"mc":[{"id":"1.168224328","rc":[{"batb":[[0,12.5,3.36],[1,12,2],[2,11,48.48]],"ltp":11.0,"tv":3583.83,"id":2397396},{"batb":[[1,1.05,4.15],[2,1.04,2879.57]],"batl":[[0,1.09,490.65],[2,1.11,241.39]],"ltp":1.07,"tv":41387.1,"id":8979329}]}]}
{"op":"mcm","clk":"1009386858","pt":1580643931418,"mc":[{"id":"1.168224328","rc":[{"batb":[[0,12,2],[1,11,48.48],[2,10,2]],"ltp":11.0,"tv":3583.83,"id":2397396}]}]}
{"op":"mcm","clk":"1009387169","pt":1580643933307,"mc":[{"id":"1.168224328","rc":[{"batb":[[1,1.05,821.22],[2,1.04,3890.76]],"batl":[[0,1.09,1634.35],[1,1.1,1014.03]],"ltp":1.07,"tv":41387.1,"id":8979329}]}]}
{"op":"mcm","clk":"1009387324","pt":1580643934300,"mc":[{"id":"1.168224328","rc":[{"batl":[[0,1.09,490.65],[1,1.1,411.36]],"ltp":1.07,"tv":41387.1,"id":8979329}]}]}
{"op":"mcm","clk":"1009387750","pt":1580643937010,"mc":[{"id":"1.168224328","rc":[{"batb":[[0,17.5,2],[1,12,2],[2,11,48.48]],"batl":[[0,26,7.2],[1,28,157],[2,34,131.15]],"ltp":11.0,"tv":3583.83,"id":2397396},{"trd":[[1.07,193.56]],"batb":[[0,1.05,2964.08],[1,1.04,3890.76],[2,1.03,805]],"batl":[[0,1.06,6385.41],[1,1.09,743.72],[2,1.1,411.36]],"ltp":1.07,"tv":41443.54,"id":8979329}],"tv":45027.37}]}
{"op":"mcm","clk":"1009387871","pt":1580643937811,"mc":[{"id":"1.168224328","rc":[{"batb":[[0,17.5,19.15],[1,14,27.38],[2,12,2]],"ltp":11.0,"tv":3583.83,"id":2397396},{"batb":[[0,1.05,2959.93]],"ltp":1.07,"tv":41443.54,"id":8979329}]}]}
{"op":"mcm","clk":"1009388022","pt":1580643938718,"mc":[{"id":"1.168224328","rc":[{"batb":[[0,1.05,3127.97]],"ltp":1.07,"tv":41443.54,"id":8979329}]}]}
{"op":"mcm","clk":"1009388256","pt":1580643940210,"mc":[{"id":"1.168224328","rc":[{"batl":[[1,1.07,42.01],[2,1.09,743.72]],"ltp":1.07,"tv":41443.54,"id":8979329}]}]}
{"op":"mcm","clk":"1009388789","pt":1580643943529,"mc":[{"id":"1.168224328","rc":[{"batb":[[1,15,2],[2,14,27.38]],"ltp":11.0,"tv":3583.83,"id":2397396},{"batl":[[1,1.07,294.51],[2,1.08,207.69]],"ltp":1.07,"tv":41443.54,"id":8979329}]}]}
{"op":"mcm","clk":"1009389118","pt":1580643945521,"mc":[{"id":"1.168224328","rc":[{"batb":[[1,1.04,3940.76]],"ltp":1.07,"tv":41443.54,"id":8979329}]}]}
{"op":"mcm","clk":"1009390006","pt":1580643951324,"mc":[{"id":"1.168224328","rc":[{"batl":[[0,26,2],[1,36,2],[2,55,2]],"ltp":11.0,"tv":3583.83,"id":2397396},{"batb":[[0,1.05,2310.9],[1,1.04,2929.57]],"batl":[[0,1.06,2165.17]],"ltp":1.07,"tv":41443.54,"id":8979329}]}]}
{"op":"mcm","clk":"1009390143","pt":1580643952247,"mc":[{"id":"1.168224328","rc":[{"batb":[[0,14,27.38],[1,13.5,2],[2,12,2]],"batl":[[0,36,2],[1,55,2],[2,160,37.1]],"ltp":11.0,"tv":3583.83,"id":2397396},{"batb":[[0,1.05,168.04],[1,1.04,50.5]],"batl":[[0,1.07,42.01],[1,1.08,207.69],[2,1.09,490.65]],"ltp":1.07,"tv":41443.54,"id":8979329}]}]}
{"op":"mcm","clk":"1009390475","pt":1580643954228,"mc":[{"id":"1.168224328","rc":[{"batb":[[0,1.04,50.5],[1,1.03,2658.96],[2,1.02,5102.66]],"batl":[[0,1.07,977.2],[1,1.08,1007.66]],"ltp":1.07,"tv":41443.54,"id":8979329}]}]}
{"op":"mcm","clk":"1009390610","pt":1580643955057,"mc":[{"id":"1.168224328","rc":[{"batb":[[1,1.03,805]],"batl":[[0,1.08,207.69],[1,1.09,490.65],[2,1.1,411.36]],"ltp":1.07,"tv":41443.54,"id":8979329}]}]}
{"op":"mcm","clk":"1009390968","pt":1580643957241,"mc":[{"id":"1.168224328","rc":[{"batb":[[0,1.04,1886.63]],"batl":[[0,1.06,1801.49],[1,1.08,207.69],[2,1.09,490.65]],"ltp":1.07,"tv":41443.54,"id":8979329}]}]}
{"op":"mcm","clk":"1009391224","pt":1580643959039,"mc":[{"id":"1.168224328","rc":[{"batb":[[0,15,2],[1,14,27.38],[2,13.5,2]],"ltp":11.0,"tv":3583.83,"id":2397396},{"batl":[[1,1.07,221.5],[2,1.08,207.69]],"ltp":1.07,"tv":41443.54,"id":8979329}]}]}
{"op":"mcm","clk":"1009391759","pt":1580643962351,"mc":[{"id":"1.168224328","rc":[{"batb":[[0,1.04,50.5]],"batl":[[0,1.07,221.5],[1,1.08,207.69],[2,1.09,490.65]],"ltp":1.07,"tv":41443.54,"id":8979329}]}]}
