{"op":"mcm","clk":"1002315141","pt":1580592409750,"mc":[{"id":"1.168237987","marketDefinition":{"bspMarket":false,"turnInPlayEnabled":true,"persistenceEnabled":true,"marketBaseRate":5.0,"eventId":"29681871","eventTypeId":"2","numberOfWinners":1,"bettingType":"ODDS","marketType":"SET_WINNER","marketTime":"2020-02-02T16:00:00.000Z","suspendTime":"2020-02-02T16:00:00.000Z","bspReconciled":false,"complete":true,"inPlay":false,"crossMatching":false,"runnersVoidable":false,"numberOfActiveRunners":2,"betDelay":0,"status":"OPEN","runners":[{"status":"ACTIVE","sortPriority":1,"id":14833204,"name":"Facundo Diaz Acosta"},{"status":"ACTIVE","sortPriority":2,"id":13181195,"name":"Pedro Martinez"}],"regulators":["MR_INT"],"countryCode":"AR","discountAllowed":false,"timezone":"UTC","openDate":"2020-02-02T16:00:00.000Z","version":3147569483,"name":"Set 2 Winner","eventName":"Diaz Acosta v Martinez"},"rc":[{"batb":[[0,1.01,20]],"ltp":0.0,"tv":0.0,"id":14833204},{"batb":[[0,1.01,20]],"ltp":0.0,"tv":0.0,"id":13181195}]}]}
{"op":"mcm","clk":"1002315289","pt":1580592411040,"mc":[{"id":"1.168237987","marketDefinition":{"bspMarket":false,"turnInPlayEnabled":true,"persistenceEnabled":true,"marketBaseRate":5.0,"eventId":"29681871","eventTypeId":"2","numberOfWinners":1,"bettingType":"ODDS","marketType":"SET_WINNER","marketTime":"2020-02-02T16:00:00.000Z","suspendTime":"2020-02-02T16:00:00.000Z","bspReconciled":false,"complete":true,"inPlay":false,"crossMatching":false,"runnersVoidable":false,"numberOfActiveRunners":2,"betDelay":0,"status":"OPEN","runners":[{"status":"ACTIVE","sortPriority":1,"id":14833204,"name":"Facundo Diaz Acosta"},{"status":"ACTIVE","sortPriority":2,"id":13181195,"name":"Pedro Martinez"}],"regulators":["MR_INT"],"countryCode":"AR","discountAllowed":false,"timezone":"UTC","openDate":"2020-02-02T16:00:00.000Z","version":3147569483,"name":"Set 2 Winner","eventName":"Diaz Acosta v Martinez"}}]}
{"op":"mcm","clk":"1002315411","pt":1580592412044,"mc":[{"id":"1.168237987","marketDefinition":{"bspMarket":false,"turnInPlayEnabled":true,"persistenceEnabled":true,"marketBaseRate":5.0,"eventId":"29681871","eventTypeId":"2","numberOfWinners":1,"bettingType":"ODDS","marketType":"SET_WINNER","marketTime":"2020-02-02T16:00:00.000Z","suspendTime":"2020-02-02T16:00:00.000Z","bspReconciled":false,"complete":true,"inPlay":false,"crossMatching":false,"runnersVoidable":false,"numberOfActiveRunners":2,"betDelay":0,"status":"OPEN","runners":[{"status":"ACTIVE","sortPriority":1,"id":14833204,"name":"Facundo Diaz Acosta"},{"status":"ACTIVE","sortPriority":2,"id":13181195,"name":"Pedro Martinez"}],"regulators":["MR_INT"],"countryCode":"AR","discountAllowed":true,"timezone":"UTC","openDate":"2020-02-02T16:00:00.000Z","version":3147569483,"name":"Set 2 Winner","eventName":"Diaz Acosta v Martinez"}}]}
{"op":"mcm","clk":"1002335518","pt":1580592619063,"mc":[{"id":"1.168237987","rc":[{"batb":[[0,1.01,10]],"ltp":0.0,"tv":0.0,"id":14833204},{"batb":[[0,1.01,10]],"ltp":0.0,"tv":0.0,"id":13181195}]}]}
{"op":"mcm","clk":"1003013427","pt":1580601982948,"mc":[{"id":"1.168237987","rc":[{"batb":[[0,1.01,12.53]],"ltp":0.0,"tv":0.0,"id":14833204},{"batb":[[0,1.01,12.53]],"ltp":0.0,"tv":0.0,"id":13181195}]}]}
{"op":"mcm","clk":"1003013522","pt":1580601983932,"mc":[{"id":"1.168237987","rc":[{"batb":[[0,1.01,10.51]],"ltp":0.0,"tv":0.0,"id":14833204},{"batb":[[0,1.01,10.51]],"ltp":0.0,"tv":0.0,"id":13181195}]}]}
{"op":"mcm","clk":"1003143216","pt":1580603525857,"mc":[{"id":"1.168237987","rc":[{"batb":[[0,1.01,13.04]],"ltp":0.0,"tv":0.0,"id":14833204},{"batb":[[0,1.01,13.04]],"ltp":0.0,"tv":0.0,"id":13181195}]}]}
{"op":"mcm","clk":"1003143311","pt":1580603526992,"mc":[{"id":"1.168237987","rc":[{"batb":[[0,1.01,11.01]],"ltp":0.0,"tv":0.0,"id":14833204},{"batb":[[0,1.01,11.01]],"ltp":0.0,"tv":0.0,"id":13181195}]}]}
{"op":"mcm","clk":"1006912530","pt":1580651802470,"mc":[{"id":"1.168237987","marketDefinition":{"bspMarket":false,"turnInPlayEnabled":true,"persistenceEnabled":true,"marketBaseRate":5.0,"eventId":"29681871","eventTypeId":"2","numberOfWinners":1,"bettingType":"ODDS","marketType":"SET_WINNER","marketTime":"2020-02-02T15:52:00.000Z","suspendTime":"2020-02-02T15:52:00.000Z","bspReconciled":false,"complete":true,"inPlay":false,"crossMatching":false,"runnersVoidable":false,"numberOfActiveRunners":2,"betDelay":0,"status":"OPEN","runners":[{"status":"ACTIVE","sortPriority":1,"id":14833204,"name":"Facundo Diaz Acosta"},{"status":"ACTIVE","sortPriority":2,"id":13181195,"name":"Pedro Martinez"}],"regulators":["MR_INT"],"countryCode":"AR","discountAllowed":true,"timezone":"UTC","openDate":"2020-02-02T16:00:00.000Z","version":3149006557,"name":"Set 2 Winner","eventName":"Diaz Acosta v Martinez"}}]}
{"op":"mcm","clk":"1006912941","pt":1580651805472,"mc":[{"id":"1.168237987","marketDefinition":{"bspMarket":false,"turnInPlayEnabled":true,"persistenceEnabled":true,"marketBaseRate":5.0,"eventId":"29681871","eventTypeId":"2","numberOfWinners":1,"bettingType":"ODDS","marketType":"SET_WINNER","marketTime":"2020-02-02T15:52:00.000Z","suspendTime":"2020-02-02T15:52:00.000Z","bspReconciled":false,"complete":true,"inPlay":false,"crossMatching":false,"runnersVoidable":false,"numberOfActiveRunners":2,"betDelay":0,"status":"OPEN","runners":[{"status":"ACTIVE","sortPriority":1,"id":14833204,"name":"Facundo Diaz Acosta"},{"status":"ACTIVE","sortPriority":2,"id":13181195,"name":"Pedro Martinez"}],"regulators":["MR_INT"],"countryCode":"AR","discountAllowed":true,"timezone":"UTC","openDate":"2020-02-02T15:52:00.000Z","version":3149006557,"name":"Set 2 Winner","eventName":"Diaz Acosta v Martinez"}}]}
{"op":"mcm","clk":"1007718413","pt":1580656602839,"mc":[{"id":"1.168237987","marketDefinition":{"bspMarket":false,"turnInPlayEnabled":true,"persistenceEnabled":true,"marketBaseRate":5.0,"eventId":"29681871","eventTypeId":"2","numberOfWinners":1,"bettingType":"ODDS","marketType":"SET_WINNER","marketTime":"2020-02-02T15:20:00.000Z","suspendTime":"2020-02-02T15:20:00.000Z","bspReconciled":false,"complete":true,"inPlay":false,"crossMatching":false,"runnersVoidable":false,"numberOfActiveRunners":2,"betDelay":0,"status":"OPEN","runners":[{"status":"ACTIVE","sortPriority":1,"id":14833204,"name":"Facundo Diaz Acosta"},{"status":"ACTIVE","sortPriority":2,"id":13181195,"name":"Pedro Martinez"}],"regulators":["MR_INT"],"countryCode":"AR","discountAllowed":true,"timezone":"UTC","openDate":"2020-02-02T15:52:00.000Z","version":3149441891,"name":"Set 2 Winner","eventName":"Diaz Acosta v Martinez"}}]}
{"op":"mcm","clk":"1007718966","pt":1580656604846,"mc":[{"id":"1.168237987","marketDefinition":{"bspMarket":false,"turnInPlayEnabled":true,"persistenceEnabled":true,"marketBaseRate":5.0,"eventId":"29681871","eventTypeId":"2","numberOfWinners":1,"bettingType":"ODDS","marketType":"SET_WINNER","marketTime":"2020-02-02T15:20:00.000Z","suspendTime":"2020-02-02T15:20:00.000Z","bspReconciled":false,"complete":true,"inPlay":false,"crossMatching":false,"runnersVoidable":false,"numberOfActiveRunners":2,"betDelay":0,"status":"OPEN","runners":[{"status":"ACTIVE","sortPriority":1,"id":14833204,"name":"Facundo Diaz Acosta"},{"status":"ACTIVE","sortPriority":2,"id":13181195,"name":"Pedro Martinez"}],"regulators":["MR_INT"],"countryCode":"AR","discountAllowed":true,"timezone":"UTC","openDate":"2020-02-02T15:20:00.000Z","version":3149441891,"name":"Set 2 Winner","eventName":"Diaz Acosta v Martinez"}}]}
{"op":"mcm","clk":"1007786256","pt":1580656898010,"mc":[{"id":"1.168237987","rc":[{"batb":[[0,3.2,19.43],[1,1.01,11.01]],"ltp":0.0,"tv":0.0,"id":14833204},{"batb":[[0,1.39,52.64],[1,1.01,11.01]],"ltp":0.0,"tv":0.0,"id":13181195}]}]}
{"op":"mcm","clk":"1007788051","pt":1580656905837,"mc":[{"id":"1.168237987","rc":[{"batb":[[0,1.39,52.32]],"ltp":0.0,"tv":0.0,"id":13181195}]}]}
{"op":"mcm","clk":"1007790359","pt":1580656915738,"mc":[{"id":"1.168237987","rc":[{"batb":[[0,1.39,52.01]],"ltp":0.0,"tv":0.0,"id":13181195}]}]}
{"op":"mcm","clk":"1007871872","pt":1580657275659,"mc":[{"id":"1.168237987","rc":[{"batb":[[0,3.15,20.06]],"ltp":0.0,"tv":0.0,"id":14833204},{"batb":[[0,1.39,51.3]],"ltp":0.0,"tv":0.0,"id":13181195}]}]}
{"op":"mcm","clk":"1007874221","pt":1580657285809,"mc":[{"id":"1.168237987","rc":[{"batb":[[0,1.4,50.59]],"ltp":0.0,"tv":0.0,"id":13181195}]}]}
{"op":"mcm","clk":"1007876473","pt":1580657295612,"mc":[{"id":"1.168237987","rc":[{"batb":[[0,3.1,20.77]],"ltp":0.0,"tv":0.0,"id":14833204},{"batb":[[0,1.4,49.96]],"ltp":0.0,"tv":0.0,"id":13181195}]}]}
{"op":"mcm","clk":"1008031570","pt":1580657987377,"mc":[{"id":"1.168237987","marketDefinition":{"bspMarket":false,"turnInPlayEnabled":true,"persistenceEnabled":true,"marketBaseRate":5.0,"eventId":"29681871","eventTypeId":"2","numberOfWinners":1,"bettingType":"ODDS","marketType":"SET_WINNER","marketTime":"2020-02-02T15:20:00.000Z","suspendTime":"2020-02-02T15:20:00.000Z","bspReconciled":false,"complete":true,"inPlay":false,"crossMatching":false,"runnersVoidable":false,"numberOfActiveRunners":2,"betDelay":0,"status":"OPEN","runners":[{"status":"ACTIVE","sortPriority":1,"id":14833204,"name":"Facundo Diaz Acosta"},{"status":"ACTIVE","sortPriority":2,"id":13181195,"name":"Pedro Martinez"}],"regulators":["MR_INT"],"countryCode":"AR","discountAllowed":true,"timezone":"UTC","openDate":"2020-02-02T15:20:00.000Z","version":3149466724,"name":"Set 2 Winner","eventName":"Diaz Acosta v Martinez"},"rc":[{"batb":[[0,1.01,11.01],[1,1.01,0]],"ltp":0.0,"tv":0.0,"id":14833204},{"batb":[[0,1.01,11.01],[1,1.01,0]],"ltp":0.0,"tv":0.0,"id":13181195}]}]}
{"op":"mcm","clk":"1008031747","pt":1580657988210,"mc":[{"id":"1.168237987","marketDefinition":{"bspMarket":false,"turnInPlayEnabled":true,"persistenceEnabled":true,"marketBaseRate":5.0,"eventId":"29681871","eventTypeId":"2","numberOfWinners":1,"bettingType":"ODDS","marketType":"SET_WINNER","marketTime":"2020-02-02T15:20:00.000Z","suspendTime":"2020-02-02T15:20:00.000Z","bspReconciled":false,"complete":true,"inPlay":true,"crossMatching":false,"runnersVoidable":false,"numberOfActiveRunners":2,"betDelay":3,"status":"OPEN","runners":[{"status":"ACTIVE","sortPriority":1,"id":14833204,"name":"Facundo Diaz Acosta"},{"status":"ACTIVE","sortPriority":2,"id":13181195,"name":"Pedro Martinez"}],"regulators":["MR_INT"],"countryCode":"AR","discountAllowed":true,"timezone":"UTC","openDate":"2020-02-02T15:20:00.000Z","version":3149542072,"name":"Set 2 Winner","eventName":"Diaz Acosta v Martinez"},"rc":[{"batb":[[0,1.01,10.51]],"ltp":0.0,"tv":0.0,"id":14833204},{"batb":[[0,1.01,10.51]],"ltp":0.0,"tv":0.0,"id":13181195}]}]}
{"op":"mcm","clk":"1008033549","pt":1580657995685,"mc":[{"id":"1.168237987","rc":[{"batb":[[0,3,22.66],[1,2.92,24.78],[2,1.01,10.51]],"ltp":0.0,"tv":0.0,"id":14833204},{"batb":[[0,1.42,46.66],[1,1.41,49.02],[2,1.01,10.51]],"ltp":0.0,"tv":0.0,"id":13181195}]}]}
{"op":"mcm","clk":"1008036952","pt":1580658009866,"mc":[{"id":"1.168237987","rc":[{"batb":[[0,2.92,24.78],[1,1.01,10.51],[2,1.01,0]],"ltp":0.0,"tv":0.0,"id":14833204},{"batb":[[0,1.41,49.02],[1,1.01,10.51],[2,1.01,0]],"ltp":0.0,"tv":0.0,"id":13181195}]}]}
{"op":"mcm","clk":"1008041909","pt":1580658030024,"mc":[{"id":"1.168237987","rc":[{"batb":[[0,3.1,21.32],[1,3,23.29],[2,2.94,32.76]],"ltp":0.0,"tv":0.0,"id":14833204},{"batb":[[1,1.39,51.77],[2,1.01,10.51]],"ltp":0.0,"tv":0.0,"id":13181195}]}]}
{"op":"mcm","clk":"1008041953","pt":1580658030192,"mc":[{"id":"1.168237987","rc":[{"batb":[[2,1.01,10.51]],"ltp":0.0,"tv":0.0,"id":14833204}]}]}
{"op":"mcm","clk":"1008046192","pt":1580658047328,"mc":[{"id":"1.168237987","rc":[{"batb":[[0,3,23.29],[1,1.01,10.51],[2,1.01,0]],"ltp":0.0,"tv":0.0,"id":14833204},{"batb":[[0,1.39,51.77],[1,1.01,10.51],[2,1.01,0]],"ltp":0.0,"tv":0.0,"id":13181195}]}]}
{"op":"mcm","clk":"1008049231","pt":1580658059833,"mc":[{"id":"1.168237987","rc":[{"batb":[[1,2.86,10.39],[2,1.01,10.51]],"ltp":0.0,"tv":0.0,"id":14833204},{"batb":[[0,1.43,45.71],[1,1.41,48.55],[2,1.01,10.51]],"ltp":0.0,"tv":0.0,"id":13181195}]}]}
{"op":"mcm","clk":"1008053977","pt":1580658081116,"mc":[{"id":"1.168237987","rc":[{"batb":[[0,2.86,10.39],[1,1.01,10.51],[2,1.01,0]],"ltp":0.0,"tv":0.0,"id":14833204},{"batb":[[0,1.41,48.55],[1,1.01,10.51],[2,1.01,0]],"ltp":0.0,"tv":0.0,"id":13181195}]}]}
{"op":"mcm","clk":"1008058687","pt":1580658101882,"mc":[{"id":"1.168237987","rc":[{"batb":[[1,2.78,11.17],[2,1.01,10.51]],"ltp":0.0,"tv":0.0,"id":14833204},{"batb":[[0,1.46,42.02],[1,1.44,44.85],[2,1.01,10.51]],"ltp":0.0,"tv":0.0,"id":13181195}]}]}
{"op":"mcm","clk":"1008063593","pt":1580658122878,"mc":[{"id":"1.168237987","rc":[{"batb":[[0,2.78,11.17],[1,1.01,10.51],[2,1.01,0]],"ltp":0.0,"tv":0.0,"id":14833204},{"batb":[[0,1.44,44.85],[1,1.01,10.51],[2,1.01,0]],"ltp":0.0,"tv":0.0,"id":13181195}]}]}
{"op":"mcm","clk":"1008064303","pt":1580658125874,"mc":[{"id":"1.168237987","rc":[{"batb":[[0,2.76,11.57]],"ltp":0.0,"tv":0.0,"id":14833204},{"batb":[[0,1.44,43.75]],"ltp":0.0,"tv":0.0,"id":13181195}]}]}
{"op":"mcm","clk":"1008066352","pt":1580658134596,"mc":[{"id":"1.168237987","rc":[{"batb":[[1,2.66,12.59],[2,1.01,10.51]],"ltp":0.0,"tv":0.0,"id":14833204},{"batb":[[0,1.49,38.16],[1,1.47,40.76],[2,1.01,10.51]],"ltp":0.0,"tv":0.0,"id":13181195}]}]}
{"op":"mcm","clk":"1008068341","pt":1580658143006,"mc":[{"id":"1.168237987","rc":[{"batb":[[0,2.74,11.8]],"ltp":0.0,"tv":0.0,"id":14833204},{"batb":[[0,1.5,37.53],[1,1.47,40.29]],"ltp":0.0,"tv":0.0,"id":13181195}]}]}
{"op":"mcm","clk":"1008070213","pt":1580658151022,"mc":[{"id":"1.168237987","rc":[{"batb":[[0,2.72,11.96]],"ltp":0.0,"tv":0.0,"id":14833204},{"batb":[[0,1.51,37.06],[1,1.48,39.81]],"ltp":0.0,"tv":0.0,"id":13181195}]}]}
{"op":"mcm","clk":"1008076404","pt":1580658176252,"mc":[{"id":"1.168237987","rc":[{"batb":[[0,2.66,12.59],[1,1.01,10.51],[2,1.01,0]],"ltp":0.0,"tv":0.0,"id":14833204},{"batb":[[0,1.48,39.81],[1,1.01,10.51],[2,1.01,0]],"ltp":0.0,"tv":0.0,"id":13181195}]}]}
{"op":"mcm","clk":"1008077355","pt":1580658179960,"mc":[{"id":"1.168237987","rc":[{"batb":[[0,2.64,12.75]],"ltp":0.0,"tv":0.0,"id":14833204},{"batb":[[0,1.48,39.66]],"ltp":0.0,"tv":0.0,"id":13181195}]}]}
{"op":"mcm","clk":"1008078240","pt":1580658183863,"mc":[{"id":"1.168237987","rc":[{"batb":[[1,2.56,13.85],[2,1.01,10.51]],"ltp":0.0,"tv":0.0,"id":14833204},{"batb":[[0,1.53,35.09],[1,1.5,37.61],[2,1.01,10.51]],"ltp":0.0,"tv":0.0,"id":13181195}]}]}
{"op":"mcm","clk":"1008080621","pt":1580658193873,"mc":[{"id":"1.168237987","rc":[{"batb":[[0,2.56,13.85],[1,1.01,10.51],[2,1.01,0]],"ltp":0.0,"tv":0.0,"id":14833204},{"batb":[[0,1.5,37.14],[1,1.01,10.51],[2,1.01,0]],"ltp":0.0,"tv":0.0,"id":13181195}]}]}
{"op":"mcm","clk":"1008082252","pt":1580658200874,"mc":[{"id":"1.168237987","rc":[{"batb":[[1,2.5,14.87],[2,1.01,10.51]],"ltp":0.0,"tv":0.0,"id":14833204},{"batb":[[0,1.56,32.34],[1,1.53,34.7],[2,1.01,10.51]],"ltp":0.0,"tv":0.0,"id":13181195}]}]}
{"op":"mcm","clk":"1008085334","pt":1580658213809,"mc":[{"id":"1.168237987","rc":[{"batb":[[0,2.5,14.87],[1,1.01,10.51],[2,1.01,0]],"ltp":0.0,"tv":0.0,"id":14833204},{"batb":[[0,1.53,34.54],[1,1.01,10.51],[2,1.01,0]],"ltp":0.0,"tv":0.0,"id":13181195}]}]}
{"op":"mcm","clk":"1008087758","pt":1580658223889,"mc":[{"id":"1.168237987","rc":[{"batb":[[1,2.44,16.05],[2,1.01,10.51]],"ltp":0.0,"tv":0.0,"id":14833204},{"batb":[[0,1.58,30.53],[1,1.56,32.18],[2,1.53,34.54]],"ltp":0.0,"tv":0.0,"id":13181195}]}]}
{"op":"mcm","clk":"1008087839","pt":1580658224363,"mc":[{"id":"1.168237987","rc":[{"batb":[[2,1.01,10.51]],"ltp":0.0,"tv":0.0,"id":13181195}]}]}
{"op":"mcm","clk":"1008090377","pt":1580658234503,"mc":[{"id":"1.168237987","rc":[{"batb":[[0,2.44,16.05],[1,1.01,10.51],[2,1.01,0]],"ltp":0.0,"tv":0.0,"id":14833204},{"batb":[[0,1.56,32.18],[1,1.01,10.51],[2,1.01,0]],"ltp":0.0,"tv":0.0,"id":13181195}]}]}
{"op":"mcm","clk":"1008092788","pt":1580658244699,"mc":[{"id":"1.168237987","rc":[{"batl":[[0,3.15,200.42]],"ltp":0.0,"tv":0.0,"id":14833204},{"batl":[[0,2.22,329.01]],"ltp":0.0,"tv":0.0,"id":13181195}]}]}
{"op":"mcm","clk":"1008095041","pt":1580658254036,"mc":[{"id":"1.168237987","rc":[{"batb":[[1,2.36,17.47],[2,1.01,10.51]],"ltp":0.0,"tv":0.0,"id":14833204},{"batb":[[0,1.61,28.88],[1,1.58,30.76],[2,1.56,749.08]],"ltp":0.0,"tv":0.0,"id":13181195}]}]}
{"op":"mcm","clk":"1008095208","pt":1580658254728,"mc":[{"id":"1.168237987","rc":[{"batb":[[2,1.01,10.51]],"ltp":0.0,"tv":0.0,"id":13181195}]}]}
{"op":"mcm","clk":"1008095862","pt":1580658257435,"mc":[{"id":"1.168237987","marketDefinition":{"bspMarket":false,"turnInPlayEnabled":true,"persistenceEnabled":true,"marketBaseRate":5.0,"eventId":"29681871","eventTypeId":"2","numberOfWinners":1,"bettingType":"ODDS","marketType":"SET_WINNER","marketTime":"2020-02-02T15:20:00.000Z","suspendTime":"2020-02-02T15:20:00.000Z","bspReconciled":false,"complete":true,"inPlay":true,"crossMatching":true,"runnersVoidable":false,"numberOfActiveRunners":2,"betDelay":3,"status":"OPEN","runners":[{"status":"ACTIVE","sortPriority":1,"id":14833204,"name":"Facundo Diaz Acosta"},{"status":"ACTIVE","sortPriority":2,"id":13181195,"name":"Pedro Martinez"}],"regulators":["MR_INT"],"countryCode":"AR","discountAllowed":true,"timezone":"UTC","openDate":"2020-02-02T15:20:00.000Z","version":3149542072,"name":"Set 2 Winner","eventName":"Diaz Acosta v Martinez"}}]}
{"op":"mcm","clk":"1008103788","pt":1580658293047,"mc":[{"id":"1.168237987","rc":[{"batb":[[0,2.36,17.47],[1,1.01,10.51],[2,1.01,0]],"ltp":0.0,"tv":0.0,"id":14833204},{"batb":[[0,1.58,30.76],[1,1.01,10.51],[2,1.01,0]],"ltp":0.0,"tv":0.0,"id":13181195}]}]}
{"op":"mcm","clk":"1008105328","pt":1580658299910,"mc":[{"id":"1.168237987","rc":[{"batb":[[0,2.5,14.87],[1,2.42,16.21],[2,1.01,10.51]],"ltp":0.0,"tv":0.0,"id":14833204},{"batb":[[1,1.56,32.57],[2,1.01,10.51]],"ltp":0.0,"tv":0.0,"id":13181195}]}]}
{"op":"mcm","clk":"1008108789","pt":1580658314845,"mc":[{"id":"1.168237987","rc":[{"batb":[[0,2.42,16.21],[1,1.01,10.51],[2,1.01,0]],"ltp":0.0,"tv":0.0,"id":14833204},{"batb":[[0,1.56,32.57],[1,1.01,10.51],[2,1.01,0]],"ltp":0.0,"tv":0.0,"id":13181195}]}]}
{"op":"mcm","clk":"1008110522","pt":1580658322874,"mc":[{"id":"1.168237987","rc":[{"batb":[[0,2.56,13.93],[1,2.5,14.95],[2,1.01,10.51]],"ltp":0.0,"tv":0.0,"id":14833204},{"batb":[[1,1.54,34.31],[2,1.01,10.51]],"ltp":0.0,"tv":0.0,"id":13181195}]}]}
{"op":"mcm","clk":"1008113218","pt":1580658334962,"mc":[{"id":"1.168237987","rc":[{"batb":[[0,2.5,14.95],[1,1.01,10.51],[2,1.01,0]],"ltp":0.0,"tv":0.0,"id":14833204},{"batb":[[0,1.54,34.31],[1,1.01,10.51],[2,1.01,0]],"ltp":0.0,"tv":0.0,"id":13181195}]}]}
{"op":"mcm","clk":"1008114597","pt":1580658341975,"mc":[{"id":"1.168237987","rc":[{"batb":[[0,2.62,13.06],[1,2.54,14.16],[2,1.01,10.51]],"ltp":0.0,"tv":0.0,"id":14833204},{"batb":[[1,1.52,35.96],[2,1.01,10.51]],"ltp":0.0,"tv":0.0,"id":13181195}]}]}
{"op":"mcm","clk":"1008114908","pt":1580658343478,"mc":[{"id":"1.168237987","rc":[{"batl":[[0,2.1,363.31]],"ltp":0.0,"tv":0.0,"id":13181195}]}]}
{"op":"mcm","clk":"1008117212","pt":1580658355000,"mc":[{"id":"1.168237987","rc":[{"batb":[[0,2.54,14.16],[1,1.01,10.51],[2,1.01,0]],"ltp":0.0,"tv":0.0,"id":14833204},{"batb":[[0,1.52,35.96],[1,1.01,10.51],[2,1.01,0]],"ltp":0.0,"tv":0.0,"id":13181195}]}]}
{"op":"mcm","clk":"1008120327","pt":1580658369838,"mc":[{"id":"1.168237987","rc":[{"batb":[[1,2.46,15.5],[2,1.01,10.51]],"ltp":0.0,"tv":0.0,"id":14833204},{"batb":[[0,1.56,32.18],[1,1.54,33.83],[2,1.01,10.51]],"ltp":0.0,"tv":0.0,"id":13181195}]}]}
{"op":"mcm","clk":"1008123105","pt":1580658382840,"mc":[{"id":"1.168237987","rc":[{"batb":[[0,2.46,15.5],[1,1.01,10.51],[2,1.01,0]],"ltp":0.0,"tv":0.0,"id":14833204},{"batb":[[0,1.54,33.83],[1,1.01,10.51],[2,1.01,0]],"ltp":0.0,"tv":0.0,"id":13181195}]}]}
{"op":"mcm","clk":"1008126361","pt":1580658399042,"mc":[{"id":"1.168237987","rc":[{"batb":[[0,2.48,441.26],[1,2.46,15.5],[2,1.01,10.51]],"ltp":0.0,"tv":0.0,"id":14833204}]}]}
{"op":"mcm","clk":"1008129711","pt":1580658415864,"mc":[{"id":"1.168237987","rc":[{"batb":[[0,2.46,15.5],[1,1.01,10.51],[2,1.01,0]],"ltp":0.0,"tv":0.0,"id":14833204}]}]}
{"op":"mcm","clk":"1008131849","pt":1580658425970,"mc":[{"id":"1.168237987","rc":[{"batb":[[0,2.6,13.38],[1,2.52,14.56],[2,1.01,10.51]],"ltp":0.0,"tv":0.0,"id":14833204},{"batb":[[1,1.51,36.59],[2,1.01,10.51]],"ltp":0.0,"tv":0.0,"id":13181195}]}]}
{"op":"mcm","clk":"1008134589","pt":1580658439891,"mc":[{"id":"1.168237987","rc":[{"batb":[[0,1.54,33.68],[1,1.51,36.43]],"ltp":0.0,"tv":0.0,"id":13181195}]}]}
{"op":"mcm","clk":"1008137058","pt":1580658451319,"mc":[{"id":"1.168237987","rc":[{"batb":[[0,2.6,452.12]],"ltp":0.0,"tv":0.0,"id":14833204}]}]}
{"op":"mcm","clk":"1008150424","pt":1580658517806,"mc":[{"id":"1.168237987","rc":[{"batb":[[0,2.52,14.56],[1,1.01,10.51],[2,1.01,0]],"ltp":0.0,"tv":0.0,"id":14833204},{"batb":[[0,1.51,36.43],[1,1.01,10.51],[2,1.01,0]],"ltp":0.0,"tv":0.0,"id":13181195}]}]}
{"op":"mcm","clk":"1008151529","pt":1580658523595,"mc":[{"id":"1.168237987","rc":[{"batb":[[1,2.46,15.58],[2,1.01,10.51]],"ltp":0.0,"tv":0.0,"id":14833204},{"batb":[[0,1.57,31.32],[1,1.54,34.23],[2,1.01,10.51]],"ltp":0.0,"tv":0.0,"id":13181195}]}]}
{"op":"mcm","clk":"1008153871","pt":1580658535633,"mc":[{"id":"1.168237987","rc":[{"batb":[[0,2.46,15.58],[1,1.01,10.51],[2,1.01,0]],"ltp":0.0,"tv":0.0,"id":14833204},{"batb":[[0,1.54,34.23],[1,1.01,10.51],[2,1.01,0]],"ltp":0.0,"tv":0.0,"id":13181195}]}]}
{"op":"mcm","clk":"1008158526","pt":1580658561378,"mc":[{"id":"1.168237987","rc":[{"batb":[[0,2.62,13.14],[1,2.54,14.32],[2,1.01,10.51]],"ltp":0.0,"tv":0.0,"id":14833204},{"batb":[[1,1.5,37.3],[2,1.01,10.51]],"ltp":0.0,"tv":0.0,"id":13181195}]}]}
{"op":"mcm","clk":"1008159131","pt":1580658564575,"mc":[{"id":"1.168237987","rc":[{"batb":[[0,2.62,451.97]],"ltp":0.0,"tv":0.0,"id":14833204}]}]}
{"op":"mcm","clk":"1008161524","pt":1580658577800,"mc":[{"id":"1.168237987","rc":[{"batb":[[0,2.54,14.32],[1,1.01,10.51],[2,1.01,0]],"ltp":0.0,"tv":0.0,"id":14833204},{"batb":[[0,1.5,37.3],[1,1.01,10.51],[2,1.01,0]],"ltp":0.0,"tv":0.0,"id":13181195}]}]}
{"op":"mcm","clk":"1008166621","pt":1580658606726,"mc":[{"id":"1.168237987","rc":[{"batb":[[1,2.46,15.58],[2,1.01,10.51]],"ltp":0.0,"tv":0.0,"id":14833204},{"batb":[[0,1.57,31.87],[1,1.53,34.86],[2,1.01,10.51]],"ltp":0.0,"tv":0.0,"id":13181195}]}]}
{"op":"mcm","clk":"1008169589","pt":1580658624010,"mc":[{"id":"1.168237987","rc":[{"batb":[[0,2.46,15.58],[1,1.01,10.51],[2,1.01,0]],"ltp":0.0,"tv":0.0,"id":14833204},{"batb":[[0,1.53,34.86],[1,1.01,10.51],[2,1.01,0]],"ltp":0.0,"tv":0.0,"id":13181195}]}]}
{"op":"mcm","clk":"1008173436","pt":1580658644971,"mc":[{"id":"1.168237987","rc":[{"batb":[[1,2.4,16.68],[2,1.01,10.51]],"ltp":0.0,"tv":0.0,"id":14833204},{"batb":[[0,1.6,29.66],[1,1.56,32.26],[2,1.01,10.51]],"ltp":0.0,"tv":0.0,"id":13181195}]}]}
{"op":"mcm","clk":"1008176498","pt":1580658662985,"mc":[{"id":"1.168237987","rc":[{"batb":[[0,2.4,16.68],[1,1.01,10.51],[2,1.01,0]],"ltp":0.0,"tv":0.0,"id":14833204},{"batb":[[0,1.56,32.26],[1,1.01,10.51],[2,1.01,0]],"ltp":0.0,"tv":0.0,"id":13181195}]}]}
{"op":"mcm","clk":"1008177694","pt":1580658670482,"mc":[{"id":"1.168237987","rc":[{"batb":[[0,2.56,14.08],[1,2.46,15.42],[2,1.01,10.51]],"ltp":0.0,"tv":0.0,"id":14833204},{"batb":[[1,1.52,35.56],[2,1.01,10.51]],"ltp":0.0,"tv":0.0,"id":13181195}]}]}
{"op":"mcm","clk":"1008180176","pt":1580658685232,"mc":[{"id":"1.168237987","rc":[{"batb":[[0,2.46,15.42],[1,1.01,10.51],[2,1.01,0]],"ltp":0.0,"tv":0.0,"id":14833204},{"batb":[[0,1.52,35.56],[1,1.01,10.51],[2,1.01,0]],"ltp":0.0,"tv":0.0,"id":13181195}]}]}
{"op":"mcm","clk":"1008183345","pt":1580658705963,"mc":[{"id":"1.168237987","rc":[{"batb":[[0,2.66,12.59],[1,2.58,13.69],[2,1.01,10.51]],"ltp":0.0,"tv":0.0,"id":14833204},{"batb":[[1,1.48,39.26],[2,1.01,10.51]],"ltp":0.0,"tv":0.0,"id":13181195}]}]}
{"op":"mcm","clk":"1008183888","pt":1580658709349,"mc":[{"id":"1.168237987","rc":[{"batb":[[0,2.66,450.96]],"ltp":0.0,"tv":0.0,"id":14833204}]}]}
{"op":"mcm","clk":"1008186434","pt":1580658725865,"mc":[{"id":"1.168237987","rc":[{"batb":[[0,2.66,12.59]],"ltp":0.0,"tv":0.0,"id":14833204}]}]}
{"op":"mcm","clk":"1008186529","pt":1580658726450,"mc":[{"id":"1.168237987","rc":[{"batb":[[0,2.58,13.69],[1,1.01,10.51],[2,1.01,0]],"ltp":0.0,"tv":0.0,"id":14833204},{"batb":[[0,1.48,39.26],[1,1.01,10.51],[2,1.01,0]],"ltp":0.0,"tv":0.0,"id":13181195}]}]}
{"op":"mcm","clk":"1008189478","pt":1580658745985,"mc":[{"id":"1.168237987","rc":[{"batb":[[0,2.8,11.09],[1,2.68,12.27],[2,2.62,450.04]],"ltp":0.0,"tv":0.0,"id":14833204},{"batb":[[1,1.45,43.43],[2,1.01,10.51]],"ltp":0.0,"tv":0.0,"id":13181195}]}]}
{"op":"mcm","clk":"1008189516","pt":1580658746206,"mc":[{"id":"1.168237987","rc":[{"batb":[[2,1.01,10.51]],"ltp":0.0,"tv":0.0,"id":14833204}]}]}
{"op":"mcm","clk":"1008189921","pt":1580658748597,"mc":[{"id":"1.168237987","rc":[{"batl":[[0,3.65,170.41]],"ltp":0.0,"tv":0.0,"id":14833204}]}]}
{"op":"mcm","clk":"1008192630","pt":1580658765810,"mc":[{"id":"1.168237987","rc":[{"batb":[[0,2.68,12.27],[1,1.01,10.51],[2,1.01,0]],"ltp":0.0,"tv":0.0,"id":14833204},{"batb":[[0,1.45,43.43],[1,1.01,10.51],[2,1.01,0]],"ltp":0.0,"tv":0.0,"id":13181195}]}]}
{"op":"mcm","clk":"1008196505","pt":1580658790023,"mc":[{"id":"1.168237987","rc":[{"batb":[[1,2.6,13.53],[2,1.01,10.51]],"ltp":0.0,"tv":0.0,"id":14833204},{"batb":[[0,1.51,36.27],[1,1.48,39.81],[2,1.46,1088.88]],"ltp":0.0,"tv":0.0,"id":13181195}]}]}
{"op":"mcm","clk":"1008196526","pt":1580658790148,"mc":[{"id":"1.168237987","rc":[{"batb":[[2,1.01,10.51]],"ltp":0.0,"tv":0.0,"id":13181195}]}]}
{"op":"mcm","clk":"1008196795","pt":1580658791825,"mc":[{"id":"1.168237987","rc":[{"batl":[[0,3.45,180.4]],"ltp":0.0,"tv":0.0,"id":14833204}]}]}
{"op":"mcm","clk":"1008199910","pt":1580658809975,"mc":[{"id":"1.168237987","rc":[{"batb":[[0,2.6,13.53],[1,1.01,10.51],[2,1.01,0]],"ltp":0.0,"tv":0.0,"id":14833204},{"batb":[[0,1.48,39.81],[1,1.01,10.51],[2,1.01,0]],"ltp":0.0,"tv":0.0,"id":13181195}]}]}
{"op":"mcm","clk":"1008201540","pt":1580658819893,"mc":[{"id":"1.168237987","rc":[{"batb":[[1,2.5,14.87],[2,1.01,10.51]],"ltp":0.0,"tv":0.0,"id":14833204},{"batb":[[0,1.55,33.44],[1,1.51,36.9],[2,1.01,10.51]],"ltp":0.0,"tv":0.0,"id":13181195}]}]}
{"op":"mcm","clk":"1008204690","pt":1580658838887,"mc":[{"id":"1.168237987","rc":[{"batb":[[0,2.5,14.87],[1,1.01,10.51],[2,1.01,0]],"ltp":0.0,"tv":0.0,"id":14833204},{"batb":[[0,1.51,36.9],[1,1.01,10.51],[2,1.01,0]],"ltp":0.0,"tv":0.0,"id":13181195}]}]}
{"op":"mcm","clk":"1008205875","pt":1580658846285,"mc":[{"id":"1.168237987","rc":[{"batl":[[0,3.3,191.92]],"ltp":0.0,"tv":0.0,"id":14833204}]}]}
{"op":"mcm","clk":"1008209503","pt":1580658869447,"mc":[{"id":"1.168237987","rc":[{"batb":[[1,2.42,16.37],[2,1.01,10.51]],"ltp":0.0,"tv":0.0,"id":14833204},{"batb":[[0,1.58,30.84],[1,1.56,32.57],[2,1.01,10.51]],"ltp":0.0,"tv":0.0,"id":13181195}]}]}
{"op":"mcm","clk":"1008216135","pt":1580658911240,"mc":[{"id":"1.168237987","rc":[{"batb":[[0,2.42,16.37],[1,1.01,10.51],[2,1.01,0]],"ltp":0.0,"tv":0.0,"id":14833204},{"batb":[[0,1.56,32.57],[1,1.01,10.51],[2,1.01,0]],"ltp":0.0,"tv":0.0,"id":13181195}]}]}
{"op":"mcm","clk":"1008217574","pt":1580658919462,"mc":[{"id":"1.168237987","rc":[{"batb":[[0,2.56,13.93],[1,2.48,15.26],[2,1.01,10.51]],"ltp":0.0,"tv":0.0,"id":14833204},{"batb":[[1,1.53,34.7],[2,1.01,10.51]],"ltp":0.0,"tv":0.0,"id":13181195}]}]}
{"op":"mcm","clk":"1008218172","pt":1580658923045,"mc":[{"id":"1.168237987","rc":[{"batb":[[0,2.58,437.37],[1,2.56,13.93],[2,2.48,15.26]],"ltp":0.0,"tv":0.0,"id":14833204}]}]}
{"op":"mcm","clk":"1008220241","pt":1580658936661,"mc":[{"id":"1.168237987","rc":[{"batb":[[0,2.48,15.26],[1,1.01,10.51],[2,2.48,0]],"ltp":0.0,"tv":0.0,"id":14833204},{"batb":[[0,1.53,34.7],[1,1.01,10.51],[2,1.01,0]],"ltp":0.0,"tv":0.0,"id":13181195}]}]}
{"op":"mcm","clk":"1008223762","pt":1580658957997,"mc":[{"id":"1.168237987","rc":[{"batb":[[0,2.64,12.98],[1,2.54,14.24],[2,2.5,460.06]],"ltp":0.0,"tv":0.0,"id":14833204},{"batb":[[1,1.51,36.74],[2,1.01,10.51]],"ltp":0.0,"tv":0.0,"id":13181195}]}]}
{"op":"mcm","clk":"1008223883","pt":1580658958808,"mc":[{"id":"1.168237987","rc":[{"batb":[[2,1.01,10.51]],"ltp":0.0,"tv":0.0,"id":14833204}]}]}
{"op":"mcm","clk":"1008226871","pt":1580658977133,"mc":[{"id":"1.168237987","rc":[{"batb":[[0,2.54,14.24],[1,1.01,10.51],[2,1.01,0]],"ltp":0.0,"tv":0.0,"id":14833204},{"batb":[[0,1.51,36.74],[1,1.01,10.51],[2,1.01,0]],"ltp":0.0,"tv":0.0,"id":13181195}]}]}
{"op":"mcm","clk":"1008233400","pt":1580659016477,"mc":[{"id":"1.168237987","rc":[{"batb":[[0,2.7,12.04],[1,2.62,13.3],[2,1.01,10.51]],"ltp":0.0,"tv":0.0,"id":14833204},{"batb":[[1,1.49,38.24],[2,1.01,10.51]],"ltp":0.0,"tv":0.0,"id":13181195}]}]}
{"op":"mcm","clk":"1008233681","pt":1580659018282,"mc":[{"id":"1.168237987","rc":[{"batl":[[0,3.65,170.41]],"ltp":0.0,"tv":0.0,"id":14833204},{"batl":[[0,2.04,383.01]],"ltp":0.0,"tv":0.0,"id":13181195}]}]}
{"op":"mcm","clk":"1008234111","pt":1580659020900,"mc":[{"id":"1.168237987","rc":[{"batb":[[0,2.62,13.3],[1,1.01,10.51],[2,1.01,0]],"ltp":0.0,"tv":0.0,"id":14833204},{"batb":[[0,1.49,38.24],[1,1.01,10.51],[2,1.01,0]],"ltp":0.0,"tv":0.0,"id":13181195}]}]}
{"op":"mcm","clk":"1008235635","pt":1580659029721,"mc":[{"id":"1.168237987","rc":[{"batb":[[0,2.76,11.49],[1,2.68,12.51],[2,1.01,10.51]],"ltp":0.0,"tv":0.0,"id":14833204},{"batb":[[1,1.46,41.86],[2,1.01,10.51]],"ltp":0.0,"tv":0.0,"id":13181195}]}]}
{"op":"mcm","clk":"1008236989","pt":1580659037602,"mc":[{"id":"1.168237987","rc":[{"batb":[[0,2.72,11.8],[1,2.64,12.83]],"ltp":0.0,"tv":0.0,"id":14833204},{"batb":[[0,1.5,37.37],[1,1.47,40.84]],"ltp":0.0,"tv":0.0,"id":13181195}]}]}
{"op":"mcm","clk":"1008255793","pt":1580659163518,"mc":[{"id":"1.168237987","rc":[{"batb":[[0,2.64,12.83],[1,1.01,10.51],[2,1.01,0]],"ltp":0.0,"tv":0.0,"id":14833204},{"batb":[[0,1.47,40.68],[1,1.01,10.51],[2,1.01,0]],"ltp":0.0,"tv":0.0,"id":13181195}]}]}
{"op":"mcm","clk":"1008257027","pt":1580659170915,"mc":[{"id":"1.168237987","rc":[{"batb":[[1,2.56,13.85],[2,1.01,10.51]],"ltp":0.0,"tv":0.0,"id":14833204},{"batb":[[0,1.53,34.86],[1,1.49,38.16],[2,1.01,10.51]],"ltp":0.0,"tv":0.0,"id":13181195}]}]}
{"op":"mcm","clk":"1008258954","pt":1580659183036,"mc":[{"id":"1.168237987","rc":[{"batb":[[0,2.56,13.85],[1,1.01,10.51],[2,1.01,0]],"ltp":0.0,"tv":0.0,"id":14833204},{"batb":[[0,1.49,38.16],[1,1.01,10.51],[2,1.01,0]],"ltp":0.0,"tv":0.0,"id":13181195}]}]}
{"op":"mcm","clk":"1008262629","pt":1580659204325,"mc":[{"id":"1.168237987","rc":[{"batb":[[1,2.5,14.79],[2,1.01,10.51]],"ltp":0.0,"tv":0.0,"id":14833204},{"batb":[[0,1.55,32.73],[1,1.52,35.56],[2,1.01,10.51]],"ltp":0.0,"tv":0.0,"id":13181195}]}]}
{"op":"mcm","clk":"1008262963","pt":1580659205972,"mc":[{"id":"1.168237987","rc":[{"batl":[[0,3.45,180.4]],"ltp":0.0,"tv":0.0,"id":14833204}]}]}
{"op":"mcm","clk":"1008263205","pt":1580659207016,"mc":[{"id":"1.168237987","rc":[{"batb":[[2,1.5,915.04]],"ltp":0.0,"tv":0.0,"id":13181195}]}]}
{"op":"mcm","clk":"1008263233","pt":1580659207230,"mc":[{"id":"1.168237987","rc":[{"batb":[[2,1.01,10.51]],"ltp":0.0,"tv":0.0,"id":13181195}]}]}
{"op":"mcm","clk":"1008265989","pt":1580659220970,"mc":[{"id":"1.168237987","rc":[{"batb":[[0,2.5,14.79],[1,1.01,10.51],[2,1.01,0]],"ltp":0.0,"tv":0.0,"id":14833204},{"batb":[[0,1.52,35.56],[1,1.01,10.51],[2,1.01,0]],"ltp":0.0,"tv":0.0,"id":13181195}]}]}
{"op":"mcm","clk":"1008266518","pt":1580659223867,"mc":[{"id":"1.168237987","rc":[{"batb":[[0,2.48,15.26]],"ltp":0.0,"tv":0.0,"id":14833204},{"batb":[[0,1.53,34.78]],"ltp":0.0,"tv":0.0,"id":13181195}]}]}
{"op":"mcm","clk":"1008268546","pt":1580659234979,"mc":[{"id":"1.168237987","rc":[{"batb":[[0,2.64,12.9],[1,2.56,14.08],[2,1.01,10.51]],"ltp":0.0,"tv":0.0,"id":14833204},{"batb":[[1,1.49,38.4],[2,1.01,10.51]],"ltp":0.0,"tv":0.0,"id":13181195}]}]}
{"op":"mcm","clk":"1008269140","pt":1580659238574,"mc":[{"id":"1.168237987","rc":[{"batb":[[0,2.64,451.47]],"ltp":0.0,"tv":0.0,"id":14833204}]}]}
{"op":"mcm","clk":"1008274052","pt":1580659266961,"mc":[{"id":"1.168237987","rc":[{"batb":[[0,2.56,14.08],[1,1.01,10.51],[2,1.01,0]],"ltp":0.0,"tv":0.0,"id":14833204},{"batb":[[0,1.49,38.4],[1,1.01,10.51],[2,1.01,0]],"ltp":0.0,"tv":0.0,"id":13181195}]}]}
{"op":"mcm","clk":"1008275250","pt":1580659273950,"mc":[{"id":"1.168237987","rc":[{"batb":[[1,2.5,15.03],[2,1.01,10.51]],"ltp":0.0,"tv":0.0,"id":14833204},{"batb":[[0,1.56,32.42],[1,1.52,35.49],[2,1.01,10.51]],"ltp":0.0,"tv":0.0,"id":13181195}]}]}
{"op":"mcm","clk":"1008277745","pt":1580659287831,"mc":[{"id":"1.168237987","rc":[{"batb":[[0,2.5,15.03],[1,1.01,10.51],[2,1.01,0]],"ltp":0.0,"tv":0.0,"id":14833204},{"batb":[[0,1.52,35.49],[1,1.01,10.51],[2,1.01,0]],"ltp":0.0,"tv":0.0,"id":13181195}]}]}
{"op":"mcm","clk":"1008280029","pt":1580659299943,"mc":[{"id":"1.168237987","rc":[{"batb":[[1,2.38,16.92],[2,1.01,10.51]],"ltp":0.0,"tv":0.0,"id":14833204},{"batb":[[0,1.58,30.53],[1,1.56,32.34],[2,1.52,35.49]],"ltp":0.0,"tv":0.0,"id":13181195}]}]}
{"op":"mcm","clk":"1008280160","pt":1580659300647,"mc":[{"id":"1.168237987","rc":[{"batb":[[2,1.01,10.51]],"ltp":0.0,"tv":0.0,"id":13181195}]}]}
{"op":"mcm","clk":"1008287571","pt":1580659338905,"mc":[{"id":"1.168237987","rc":[{"batb":[[0,2.38,16.92],[1,1.01,10.51],[2,1.01,0]],"ltp":0.0,"tv":0.0,"id":14833204},{"batb":[[0,1.56,32.34],[1,1.01,10.51],[2,1.01,0]],"ltp":0.0,"tv":0.0,"id":13181195}]}]}
{"op":"mcm","clk":"1008288121","pt":1580659342041,"mc":[{"id":"1.168237987","rc":[{"batb":[[0,2.4,16.68]],"ltp":0.0,"tv":0.0,"id":14833204},{"batb":[[0,1.55,32.73]],"ltp":0.0,"tv":0.0,"id":13181195}]}]}
{"op":"mcm","clk":"1008291026","pt":1580659358835,"mc":[{"id":"1.168237987","rc":[{"batb":[[1,2.3,18.73],[2,1.01,10.51]],"ltp":0.0,"tv":0.0,"id":14833204},{"batb":[[0,1.62,27.93],[1,1.59,30.14],[2,1.01,10.51]],"ltp":0.0,"tv":0.0,"id":13181195}]}]}
{"op":"mcm","clk":"1008291344","pt":1580659360661,"mc":[{"id":"1.168237987","rc":[{"batl":[[0,3.3,191.92]],"ltp":0.0,"tv":0.0,"id":14833204}]}]}
{"op":"mcm","clk":"1008295203","pt":1580659380885,"mc":[{"id":"1.168237987","rc":[{"batb":[[0,2.3,18.73],[1,1.01,10.51],[2,1.01,0]],"ltp":0.0,"tv":0.0,"id":14833204},{"batb":[[0,1.59,30.14],[1,1.01,10.51],[2,1.01,0]],"ltp":0.0,"tv":0.0,"id":13181195}]}]}
{"op":"mcm","clk":"1008295778","pt":1580659383868,"mc":[{"id":"1.168237987","rc":[{"batb":[[0,2.32,18.49]],"ltp":0.0,"tv":0.0,"id":14833204},{"batb":[[0,1.58,30.53]],"ltp":0.0,"tv":0.0,"id":13181195}]}]}
{"op":"mcm","clk":"1008299290","pt":1580659402016,"mc":[{"id":"1.168237987","rc":[{"batb":[[1,2.24,20.38],[2,1.01,10.51]],"ltp":0.0,"tv":0.0,"id":14833204},{"batb":[[0,1.66,25.65],[1,1.63,27.77],[2,1.58,30.53]],"ltp":0.0,"tv":0.0,"id":13181195}]}]}
{"op":"mcm","clk":"1008299426","pt":1580659402792,"mc":[{"id":"1.168237987","rc":[{"batb":[[2,1.01,10.51]],"ltp":0.0,"tv":0.0,"id":13181195}]}]}
{"op":"mcm","clk":"1008303438","pt":1580659423496,"mc":[{"id":"1.168237987","rc":[{"batb":[[0,2.24,20.38],[1,1.01,10.51],[2,1.01,0]],"ltp":0.0,"tv":0.0,"id":14833204},{"batb":[[0,1.63,27.77],[1,1.01,10.51],[2,1.01,0]],"ltp":0.0,"tv":0.0,"id":13181195}]}]}
{"op":"mcm","clk":"1008308149","pt":1580659448935,"mc":[{"id":"1.168237987","rc":[{"batb":[[0,2.4,16.76],[1,2.32,440.64],[2,2.28,19.04]],"ltp":0.0,"tv":0.0,"id":14833204},{"batb":[[1,1.59,29.82],[2,1.01,10.51]],"ltp":0.0,"tv":0.0,"id":13181195}]}]}
{"op":"mcm","clk":"1008308274","pt":1580659449537,"mc":[{"id":"1.168237987","rc":[{"batb":[[1,2.28,19.04],[2,1.01,10.51]],"ltp":0.0,"tv":0.0,"id":14833204}]}]}
{"op":"mcm","clk":"1008308821","pt":1580659452328,"mc":[{"id":"1.168237987","rc":[{"batb":[[0,2.4,456.72]],"ltp":0.0,"tv":0.0,"id":14833204}]}]}
{"op":"mcm","clk":"1008314422","pt":1580659482937,"mc":[{"id":"1.168237987","rc":[{"batb":[[0,2.4,439.96]],"ltp":0.0,"tv":0.0,"id":14833204},{"batb":[[0,1.59,29.82],[1,1.01,10.51],[2,1.01,0]],"ltp":0.0,"tv":0.0,"id":13181195}]}]}
{"op":"mcm","clk":"1008316551","pt":1580659493552,"mc":[{"id":"1.168237987","rc":[{"batb":[[0,2.28,19.04],[1,1.01,10.51],[2,1.01,0]],"ltp":0.0,"tv":0.0,"id":14833204}]}]}
{"op":"mcm","clk":"1008322907","pt":1580659526002,"mc":[{"id":"1.168237987","rc":[{"batb":[[0,2.46,15.5],[1,2.36,17.47],[2,2.28,19.04]],"ltp":0.0,"tv":0.0,"id":14833204},{"batb":[[1,1.57,31.94],[2,1.01,10.51]],"ltp":0.0,"tv":0.0,"id":13181195}]}]}
{"op":"mcm","clk":"1008322991","pt":1580659526320,"mc":[{"id":"1.168237987","rc":[{"batb":[[2,1.01,10.51]],"ltp":0.0,"tv":0.0,"id":14833204}]}]}
{"op":"mcm","clk":"1008323980","pt":1580659530935,"mc":[{"id":"1.168237987","rc":[{"batb":[[2,2.3,472.28]],"ltp":0.0,"tv":0.0,"id":14833204}]}]}
{"op":"mcm","clk":"1008324026","pt":1580659531138,"mc":[{"id":"1.168237987","rc":[{"batb":[[2,1.01,10.51]],"ltp":0.0,"tv":0.0,"id":14833204}]}]}
{"op":"mcm","clk":"1008324610","pt":1580659534319,"mc":[{"id":"1.168237987","rc":[{"batb":[[0,2.48,437.76],[1,2.46,15.5],[2,2.36,17.47]],"ltp":0.0,"tv":0.0,"id":14833204}]}]}
{"op":"mcm","clk":"1008327296","pt":1580659548044,"mc":[{"id":"1.168237987","rc":[{"batb":[[0,2.36,17.47],[1,1.01,10.51],[2,2.36,0]],"ltp":0.0,"tv":0.0,"id":14833204},{"batb":[[0,1.57,31.94],[1,1.01,10.51],[2,1.01,0]],"ltp":0.0,"tv":0.0,"id":13181195}]}]}
{"op":"mcm","clk":"1008327893","pt":1580659550865,"mc":[{"id":"1.168237987","rc":[{"batb":[[1,1.56,32.18],[2,1.01,10.51]],"ltp":0.0,"tv":0.0,"id":13181195}]}]}
{"op":"mcm","clk":"1008328114","pt":1580659551889,"mc":[{"id":"1.168237987","rc":[{"batb":[[0,2.36,17.31]],"ltp":0.0,"tv":0.0,"id":14833204},{"batb":[[0,1.56,32.18],[1,1.01,10.51],[2,1.01,0]],"ltp":0.0,"tv":0.0,"id":13181195}]}]}
{"op":"mcm","clk":"1008328881","pt":1580659555860,"mc":[{"id":"1.168237987","rc":[{"batb":[[1,2.24,20.06],[2,1.01,10.51]],"ltp":0.0,"tv":0.0,"id":14833204},{"batb":[[0,1.64,26.99],[1,1.6,29.19],[2,1.58,256.37]],"ltp":0.0,"tv":0.0,"id":13181195}]}]}
{"op":"mcm","clk":"1008328950","pt":1580659556153,"mc":[{"id":"1.168237987","rc":[{"batb":[[2,1.01,10.51]],"ltp":0.0,"tv":0.0,"id":13181195}]}]}
{"op":"mcm","clk":"1008331381","pt":1580659567986,"mc":[{"id":"1.168237987","rc":[{"batb":[[0,2.24,20.06],[1,1.01,10.51],[2,1.01,0]],"ltp":0.0,"tv":0.0,"id":14833204},{"batb":[[0,1.6,29.19],[1,1.01,10.51],[2,1.01,0]],"ltp":0.0,"tv":0.0,"id":13181195}]}]}
{"op":"mcm","clk":"1008335679","pt":1580659588923,"mc":[{"id":"1.168237987","rc":[{"batb":[[0,2.44,15.82],[1,2.34,18.02],[2,1.01,10.51]],"ltp":0.0,"tv":0.0,"id":14833204},{"batb":[[1,1.57,31.39],[2,1.01,10.51]],"ltp":0.0,"tv":0.0,"id":13181195}]}]}
{"op":"mcm","clk":"1008336425","pt":1580659592413,"mc":[{"id":"1.168237987","rc":[{"batb":[[0,2.46,437.88],[1,2.44,15.82],[2,2.34,18.02]],"ltp":0.0,"tv":0.0,"id":14833204}]}]}
{"op":"mcm","clk":"1008339603","pt":1580659607856,"mc":[{"id":"1.168237987","rc":[{"batb":[[0,2.34,18.02],[1,1.01,10.51],[2,2.34,0]],"ltp":0.0,"tv":0.0,"id":14833204},{"batb":[[0,1.57,31.39],[1,1.01,10.51],[2,1.01,0]],"ltp":0.0,"tv":0.0,"id":13181195}]}]}
{"op":"mcm","clk":"1008345512","pt":1580659635025,"mc":[{"id":"1.168237987","rc":[{"batb":[[0,2.52,14.56],[1,2.42,16.44],[2,2.36,469.43]],"ltp":0.0,"tv":0.0,"id":14833204},{"batb":[[1,1.54,33.99],[2,1.01,10.51]],"ltp":0.0,"tv":0.0,"id":13181195}]}]}
{"op":"mcm","clk":"1008345552","pt":1580659635192,"mc":[{"id":"1.168237987","rc":[{"batb":[[2,1.01,10.51]],"ltp":0.0,"tv":0.0,"id":14833204}]}]}
{"op":"mcm","clk":"1008346217","pt":1580659638369,"mc":[{"id":"1.168237987","rc":[{"batb":[[0,2.52,453.8]],"ltp":0.0,"tv":0.0,"id":14833204}]}]}
{"op":"mcm","clk":"1008350295","pt":1580659657845,"mc":[{"id":"1.168237987","rc":[{"batb":[[0,2.42,16.44],[1,1.01,10.51],[2,1.01,0]],"ltp":0.0,"tv":0.0,"id":14833204},{"batb":[[0,1.54,33.99],[1,1.01,10.51],[2,1.01,0]],"ltp":0.0,"tv":0.0,"id":13181195}]}]}
{"op":"mcm","clk":"1008352051","pt":1580659665552,"mc":[{"id":"1.168237987","rc":[{"batb":[[0,2.62,13.22],[1,2.5,14.71],[2,1.01,10.51]],"ltp":0.0,"tv":0.0,"id":14833204},{"batb":[[1,1.5,37.85],[2,1.01,10.51]],"ltp":0.0,"tv":0.0,"id":13181195}]}]}
{"op":"mcm","clk":"1008356720","pt":1580659686782,"mc":[{"id":"1.168237987","rc":[{"batb":[[1,2.52,447.74],[2,2.5,14.71]],"ltp":0.0,"tv":0.0,"id":14833204}]}]}
{"op":"mcm","clk":"1008364517","pt":1580659722045,"mc":[{"id":"1.168237987","rc":[{"batb":[[0,2.6,13.3]],"ltp":0.0,"tv":0.0,"id":14833204},{"batb":[[0,1.54,33.83],[1,1.5,37.61]],"ltp":0.0,"tv":0.0,"id":13181195}]}]}
{"op":"mcm","clk":"1008371986","pt":1580659755489,"mc":[{"id":"1.168237987","rc":[{"batb":[[0,2.5,14.71],[1,1.01,10.51],[2,2.5,0]],"ltp":0.0,"tv":0.0,"id":14833204},{"batb":[[0,1.5,37.61],[1,1.01,10.51],[2,1.01,0]],"ltp":0.0,"tv":0.0,"id":13181195}]}]}
{"op":"mcm","clk":"1008373920","pt":1580659764005,"mc":[{"id":"1.168237987","rc":[{"batb":[[0,2.74,11.72],[1,2.62,12.98],[2,1.01,10.51]],"ltp":0.0,"tv":0.0,"id":14833204},{"batb":[[1,1.47,41.15],[2,1.01,10.51]],"ltp":0.0,"tv":0.0,"id":13181195}]}]}
{"op":"mcm","clk":"1008374128","pt":1580659764943,"mc":[{"id":"1.168237987","rc":[{"batl":[[0,3.65,170.41]],"ltp":0.0,"tv":0.0,"id":14833204}]}]}
{"op":"mcm","clk":"1008377191","pt":1580659778517,"mc":[{"id":"1.168237987","rc":[{"batb":[[0,2.62,12.98],[1,1.01,10.51],[2,1.01,0]],"ltp":0.0,"tv":0.0,"id":14833204},{"batb":[[0,1.47,41.15],[1,1.01,10.51],[2,1.01,0]],"ltp":0.0,"tv":0.0,"id":13181195}]}]}
{"op":"mcm","clk":"1008381874","pt":1580659798888,"mc":[{"id":"1.168237987","rc":[{"batb":[[0,2.86,10.54],[1,2.74,11.57],[2,2.62,12.98]],"ltp":0.0,"tv":0.0,"id":14833204},{"batb":[[1,1.43,45.56],[2,1.01,10.51]],"ltp":0.0,"tv":0.0,"id":13181195}]}]}
{"op":"mcm","clk":"1008381953","pt":1580659799186,"mc":[{"id":"1.168237987","rc":[{"batb":[[2,2.46,163.88]],"ltp":0.0,"tv":0.0,"id":14833204}]}]}
{"op":"mcm","clk":"1008386178","pt":1580659818337,"mc":[{"id":"1.168237987","rc":[{"batb":[[0,2.74,11.57],[1,1.01,10.51],[2,2.46,0]],"ltp":0.0,"tv":0.0,"id":14833204},{"batb":[[0,1.43,45.56],[1,1.01,10.51],[2,1.01,0]],"ltp":0.0,"tv":0.0,"id":13181195}]}]}
{"op":"mcm","clk":"1008390375","pt":1580659836792,"mc":[{"id":"1.168237987","rc":[{"batb":[[1,2.66,12.75],[2,1.01,10.51]],"ltp":0.0,"tv":0.0,"id":14833204},{"batb":[[0,1.5,38],[1,1.45,42.72],[2,1.01,10.51]],"ltp":0.0,"tv":0.0,"id":13181195}]}]}
{"op":"mcm","clk":"1008394012","pt":1580659853503,"mc":[{"id":"1.168237987","rc":[{"batb":[[0,2.66,12.75],[1,1.01,10.51],[2,1.01,0]],"ltp":0.0,"tv":0.0,"id":14833204},{"batb":[[0,1.45,42.72],[1,1.01,10.51],[2,1.01,0]],"ltp":0.0,"tv":0.0,"id":13181195}]}]}
{"op":"mcm","clk":"1008398540","pt":1580659872882,"mc":[{"id":"1.168237987","rc":[{"batb":[[1,2.54,14.24],[2,1.01,10.51]],"ltp":0.0,"tv":0.0,"id":14833204},{"batb":[[0,1.53,35.17],[1,1.48,39.73],[2,1.01,10.51]],"ltp":0.0,"tv":0.0,"id":13181195}]}]}
{"op":"mcm","clk":"1008398972","pt":1580659874773,"mc":[{"id":"1.168237987","rc":[{"batl":[[0,3.45,180.4]],"ltp":0.0,"tv":0.0,"id":14833204}]}]}
{"op":"mcm","clk":"1008402714","pt":1580659891705,"mc":[{"id":"1.168237987","rc":[{"batb":[[0,2.54,14.24],[1,1.01,10.51],[2,1.01,0]],"ltp":0.0,"tv":0.0,"id":14833204},{"batb":[[0,1.48,39.73],[1,1.01,10.51],[2,1.01,0]],"ltp":0.0,"tv":0.0,"id":13181195}]}]}
{"op":"mcm","clk":"1008407136","pt":1580659911586,"mc":[{"id":"1.168237987","rc":[{"batb":[[0,2.8,10.94],[1,2.68,12.27],[2,2.58,156.06]],"ltp":0.0,"tv":0.0,"id":14833204},{"batb":[[1,1.44,44.93],[2,1.01,10.51]],"ltp":0.0,"tv":0.0,"id":13181195}]}]}
{"op":"mcm","clk":"1008411308","pt":1580659929596,"mc":[{"id":"1.168237987","rc":[{"batb":[[0,2.68,12.27],[1,1.01,10.51],[2,2.58,0]],"ltp":0.0,"tv":0.0,"id":14833204},{"batb":[[0,1.44,44.93],[1,1.01,10.51],[2,1.01,0]],"ltp":0.0,"tv":0.0,"id":13181195}]}]}
{"op":"mcm","clk":"1008412078","pt":1580659932767,"mc":[{"id":"1.168237987","rc":[{"batb":[[0,2.7,12.04]],"ltp":0.0,"tv":0.0,"id":14833204},{"batb":[[0,1.43,45.56]],"ltp":0.0,"tv":0.0,"id":13181195}]}]}
{"op":"mcm","clk":"1008416753","pt":1580659953793,"mc":[{"id":"1.168237987","rc":[{"batb":[[0,2.98,23.37],[1,2.84,10.62],[2,1.01,10.51]],"ltp":0.0,"tv":0.0,"id":14833204},{"batb":[[1,1.41,48.63],[2,1.01,10.51]],"ltp":0.0,"tv":0.0,"id":13181195}]}]}
{"op":"mcm","clk":"1008417265","pt":1580659956001,"mc":[{"id":"1.168237987","rc":[{"batl":[[0,3.9,161.91]],"ltp":0.0,"tv":0.0,"id":14833204}]}]}
{"op":"mcm","clk":"1008424967","pt":1580659989791,"mc":[{"id":"1.168237987","rc":[{"batb":[[0,2.84,10.62],[1,1.01,10.51],[2,1.01,0]],"ltp":0.0,"tv":0.0,"id":14833204},{"batb":[[0,1.41,48.63],[1,1.01,10.51],[2,1.01,0]],"ltp":0.0,"tv":0.0,"id":13181195}]}]}
{"op":"mcm","clk":"1008425612","pt":1580659992587,"mc":[{"id":"1.168237987","rc":[{"batb":[[0,2.9,25.41]],"ltp":0.0,"tv":0.0,"id":14833204},{"batb":[[0,1.4,50.75]],"ltp":0.0,"tv":0.0,"id":13181195}]}]}
{"op":"mcm","clk":"1008428430","pt":1580660005019,"mc":[{"id":"1.168237987","rc":[{"batb":[[1,2.74,11.64],[2,1.01,10.51]],"ltp":0.0,"tv":0.0,"id":14833204},{"batb":[[0,1.45,42.72],[1,1.43,46.11],[2,1.4,50.75]],"ltp":0.0,"tv":0.0,"id":13181195}]}]}
{"op":"mcm","clk":"1008428521","pt":1580660005316,"mc":[{"id":"1.168237987","rc":[{"batb":[[2,1.01,10.51]],"ltp":0.0,"tv":0.0,"id":13181195}]}]}
{"op":"mcm","clk":"1008429063","pt":1580660007514,"mc":[{"id":"1.168237987","rc":[{"batl":[[0,3.65,173.93]],"ltp":0.0,"tv":0.0,"id":14833204}]}]}
{"op":"mcm","clk":"1008433147","pt":1580660024978,"mc":[{"id":"1.168237987","rc":[{"batb":[[0,2.74,11.64],[1,1.01,10.51],[2,1.01,0]],"ltp":0.0,"tv":0.0,"id":14833204},{"batb":[[0,1.43,46.11],[1,1.01,10.51],[2,1.01,0]],"ltp":0.0,"tv":0.0,"id":13181195}]}]}
{"op":"mcm","clk":"1008434053","pt":1580660028954,"mc":[{"id":"1.168237987","rc":[{"batb":[[0,2.72,11.88]],"ltp":0.0,"tv":0.0,"id":14833204}]}]}
{"op":"mcm","clk":"1008434950","pt":1580660032862,"mc":[{"id":"1.168237987","rc":[{"batb":[[0,3,22.98],[1,2.84,10.7],[2,1.01,10.51]],"ltp":0.0,"tv":0.0,"id":14833204},{"batb":[[1,1.4,50.12],[2,1.01,10.51]],"ltp":0.0,"tv":0.0,"id":13181195}]}]}
{"op":"mcm","clk":"1008439202","pt":1580660050818,"mc":[{"id":"1.168237987","rc":[{"batb":[[0,2.84,10.7],[1,1.01,10.51],[2,1.01,0]],"ltp":0.0,"tv":0.0,"id":14833204},{"batb":[[0,1.4,50.12],[1,1.01,10.51],[2,1.01,0]],"ltp":0.0,"tv":0.0,"id":13181195}]}]}
{"op":"mcm","clk":"1008441096","pt":1580660058818,"mc":[{"id":"1.168237987","rc":[{"batb":[[0,3.1,20.69],[1,2.94,24.39],[2,2.84,10.7]],"ltp":0.0,"tv":0.0,"id":14833204},{"batb":[[1,1.38,53.58],[2,1.01,10.51]],"ltp":0.0,"tv":0.0,"id":13181195}]}]}
{"op":"mcm","clk":"1008441172","pt":1580660059150,"mc":[{"id":"1.168237987","rc":[{"batb":[[2,1.01,10.51]],"ltp":0.0,"tv":0.0,"id":14833204}]}]}
{"op":"mcm","clk":"1008445637","pt":1580660077927,"mc":[{"id":"1.168237987","rc":[{"batb":[[0,2.94,24.39],[1,1.01,10.51],[2,1.01,0]],"ltp":0.0,"tv":0.0,"id":14833204},{"batb":[[0,1.38,53.58],[1,1.01,10.51],[2,1.01,0]],"ltp":0.0,"tv":0.0,"id":13181195}]}]}
{"op":"mcm","clk":"1008448674","pt":1580660090974,"mc":[{"id":"1.168237987","rc":[{"batb":[[0,3.25,18.96],[1,3.05,21.56],[2,1.01,10.51]],"ltp":0.0,"tv":0.0,"id":14833204},{"batb":[[1,1.36,57.44],[2,1.01,10.51]],"ltp":0.0,"tv":0.0,"id":13181195}]}]}
{"op":"mcm","clk":"1008455501","pt":1580660119999,"mc":[{"id":"1.168237987","rc":[{"batb":[[0,3.05,21.56],[1,1.01,10.51],[2,1.01,0]],"ltp":0.0,"tv":0.0,"id":14833204},{"batb":[[0,1.36,57.44],[1,1.01,10.51],[2,1.01,0]],"ltp":0.0,"tv":0.0,"id":13181195}]}]}
{"op":"mcm","clk":"1008456157","pt":1580660122968,"mc":[{"id":"1.168237987","rc":[{"batb":[[0,3.1,21.4]],"ltp":0.0,"tv":0.0,"id":14833204}]}]}
{"op":"mcm","clk":"1008457887","pt":1580660130536,"mc":[{"id":"1.168237987","rc":[{"batb":[[0,3.35,17.23],[1,3.2,19.28],[2,1.01,10.51]],"ltp":0.0,"tv":0.0,"id":14833204},{"batb":[[1,1.33,63.18],[2,1.01,10.51]],"ltp":0.0,"tv":0.0,"id":13181195}]}]}
{"op":"mcm","clk":"1008458394","pt":1580660132726,"mc":[{"id":"1.168237987","rc":[{"batl":[[0,4.2,151.74]],"ltp":0.0,"tv":0.0,"id":14833204},{"batl":[[0,1.89,428.15]],"ltp":0.0,"tv":0.0,"id":13181195}]}]}
{"op":"mcm","clk":"1008459753","pt":1580660138769,"mc":[{"id":"1.168237987","rc":[{"batb":[[0,1.36,56.65],[1,1.34,62.08]],"ltp":0.0,"tv":0.0,"id":13181195}]}]}
{"op":"mcm","clk":"1008461954","pt":1580660147975,"mc":[{"id":"1.168237987","rc":[{"batb":[[0,3.3,17.7],[1,3.15,19.91]],"ltp":0.0,"tv":0.0,"id":14833204},{"batb":[[0,1.36,56.34],[1,1.34,61.84]],"ltp":0.0,"tv":0.0,"id":13181195}]}]}
{"op":"mcm","clk":"1008465601","pt":1580660164004,"mc":[{"id":"1.168237987","rc":[{"batb":[[0,1.37,55.63],[1,1.36,56.34],[2,1.34,61.84]],"ltp":0.0,"tv":0.0,"id":13181195}]}]}
{"op":"mcm","clk":"1008465771","pt":1580660164796,"mc":[{"id":"1.168237987","rc":[{"batb":[[1,1.34,61.14],[2,1.01,10.51]],"ltp":0.0,"tv":0.0,"id":13181195}]}]}
{"op":"mcm","clk":"1008479628","pt":1580660223865,"mc":[{"id":"1.168237987","rc":[{"batb":[[0,3.15,19.91],[1,1.01,10.51],[2,1.01,0]],"ltp":0.0,"tv":0.0,"id":14833204},{"batb":[[0,1.34,61.14],[1,1.01,10.51],[2,1.01,0]],"ltp":0.0,"tv":0.0,"id":13181195}]}]}
{"op":"mcm","clk":"1008481323","pt":1580660230978,"mc":[{"id":"1.168237987","rc":[{"batb":[[1,3,22.5],[2,1.01,10.51]],"ltp":0.0,"tv":0.0,"id":14833204},{"batb":[[0,1.39,50.99],[1,1.36,56.34],[2,1.34,61.14]],"ltp":0.0,"tv":0.0,"id":13181195}]}]}
{"op":"mcm","clk":"1008481382","pt":1580660231289,"mc":[{"id":"1.168237987","rc":[{"batb":[[2,1.01,10.51]],"ltp":0.0,"tv":0.0,"id":13181195}]}]}
{"op":"mcm","clk":"1008482045","pt":1580660233878,"mc":[{"id":"1.168237987","rc":[{"batl":[[0,3.9,162.05]],"ltp":0.0,"tv":0.0,"id":14833204}]}]}
{"op":"mcm","clk":"1008484719","pt":1580660244997,"mc":[{"id":"1.168237987","rc":[{"batb":[[0,3,22.5],[1,1.01,10.51],[2,1.01,0]],"ltp":0.0,"tv":0.0,"id":14833204},{"batb":[[0,1.36,56.34],[1,1.01,10.51],[2,1.01,0]],"ltp":0.0,"tv":0.0,"id":13181195}]}]}
{"op":"mcm","clk":"1008490375","pt":1580660268429,"mc":[{"id":"1.168237987","rc":[{"batb":[[0,3.3,17.7],[1,3.15,19.99],[2,1.01,10.51]],"ltp":0.0,"tv":0.0,"id":14833204},{"batb":[[1,1.33,63.73],[2,1.01,10.51]],"ltp":0.0,"tv":0.0,"id":13181195}]}]}
{"op":"mcm","clk":"1008495610","pt":1580660290626,"mc":[{"id":"1.168237987","rc":[{"batb":[[0,3.15,19.99],[1,1.01,10.51],[2,1.01,0]],"ltp":0.0,"tv":0.0,"id":14833204},{"batb":[[0,1.33,63.73],[1,1.01,10.51],[2,1.01,0]],"ltp":0.0,"tv":0.0,"id":13181195}]}]}
{"op":"mcm","clk":"1008503783","pt":1580660325985,"mc":[{"id":"1.168237987","rc":[{"batb":[[1,3.05,22.19],[2,1.01,10.51]],"ltp":0.0,"tv":0.0,"id":14833204},{"batb":[[0,1.39,51.62],[1,1.36,57.67],[2,1.01,10.51]],"ltp":0.0,"tv":0.0,"id":13181195}]}]}
{"op":"mcm","clk":"1008509321","pt":1580660350034,"mc":[{"id":"1.168237987","rc":[{"batb":[[0,3.05,22.19],[1,1.01,10.51],[2,1.01,0]],"ltp":0.0,"tv":0.0,"id":14833204},{"batb":[[0,1.36,57.67],[1,1.01,10.51],[2,1.01,0]],"ltp":0.0,"tv":0.0,"id":13181195}]}]}
{"op":"mcm","clk":"1008514705","pt":1580660373560,"mc":[{"id":"1.168237987","rc":[{"batb":[[0,3.35,17.15],[1,3.2,19.67],[2,1.01,10.51]],"ltp":0.0,"tv":0.0,"id":14833204},{"batb":[[1,1.32,65.38],[2,1.01,10.51]],"ltp":0.0,"tv":0.0,"id":13181195}]}]}
{"op":"mcm","clk":"1008515247","pt":1580660375879,"mc":[{"id":"1.168237987","rc":[{"batl":[[0,4.6,139.48]],"ltp":0.0,"tv":0.0,"id":14833204}]}]}
{"op":"mcm","clk":"1008519851","pt":1580660395903,"mc":[{"id":"1.168237987","rc":[{"batb":[[0,3.2,19.67],[1,1.01,10.51],[2,1.01,0]],"ltp":0.0,"tv":0.0,"id":14833204},{"batb":[[0,1.32,65.38],[1,1.01,10.51],[2,1.01,0]],"ltp":0.0,"tv":0.0,"id":13181195}]}]}
{"op":"mcm","clk":"1008520574","pt":1580660398889,"mc":[{"id":"1.168237987","rc":[{"batb":[[1,3.15,20.06],[2,1.01,10.51]],"ltp":0.0,"tv":0.0,"id":14833204},{"batb":[[0,1.33,64.44],[1,1.32,65.38],[2,1.01,10.51]],"ltp":0.0,"tv":0.0,"id":13181195}]}]}
{"op":"mcm","clk":"1008520797","pt":1580660399902,"mc":[{"id":"1.168237987","rc":[{"batb":[[0,3.15,20.06],[1,1.01,10.51],[2,1.01,0]],"ltp":0.0,"tv":0.0,"id":14833204},{"batb":[[1,1.01,10.51],[2,1.01,0]],"ltp":0.0,"tv":0.0,"id":13181195}]}]}
{"op":"mcm","clk":"1008525251","pt":1580660417687,"mc":[{"id":"1.168237987","rc":[{"batb":[[0,3.6,14.79],[1,3.35,17.31],[2,1.01,10.51]],"ltp":0.0,"tv":0.0,"id":14833204},{"batb":[[1,1.29,74.2],[2,1.01,10.51]],"ltp":0.0,"tv":0.0,"id":13181195}]}]}
{"op":"mcm","clk":"1008525614","pt":1580660419311,"mc":[{"id":"1.168237987","rc":[{"batl":[[0,1.77,493.74]],"ltp":0.0,"tv":0.0,"id":13181195}]}]}
{"op":"mcm","clk":"1008530250","pt":1580660439019,"mc":[{"id":"1.168237987","rc":[{"batb":[[0,3.35,17.31],[1,1.01,10.51],[2,1.01,0]],"ltp":0.0,"tv":0.0,"id":14833204},{"batb":[[0,1.29,74.2],[1,1.01,10.51],[2,1.01,0]],"ltp":0.0,"tv":0.0,"id":13181195}]}]}
{"op":"mcm","clk":"1008535680","pt":1580660463045,"mc":[{"id":"1.168237987","rc":[{"batb":[[0,1.31,295.2],[1,1.3,340.09],[2,1.29,74.2]],"batl":[[0,1.35,399.73],[1,1.36,258.7],[2,1.77,493.74]],"ltp":0.0,"tv":0.0,"id":13181195}]}]}
{"op":"mcm","clk":"1008535884","pt":1580660463963,"mc":[{"id":"1.168237987","rc":[{"batb":[[0,3.85,24.63],[1,3.55,113.19],[2,3.3,18.18]],"ltp":0.0,"tv":0.0,"id":14833204}]}]}
{"op":"mcm","clk":"1008536037","pt":1580660464555,"mc":[{"id":"1.168237987","rc":[{"batb":[[1,3.3,18.18],[2,1.01,10.51]],"ltp":0.0,"tv":0.0,"id":14833204}]}]}
{"op":"mcm","clk":"1008539996","pt":1580660481938,"mc":[{"id":"1.168237987","rc":[{"batb":[[0,3.9,24.31],[1,3.3,17.86]],"ltp":0.0,"tv":0.0,"id":14833204}]}]}
{"op":"mcm","clk":"1008551477","pt":1580660531717,"mc":[{"id":"1.168237987","rc":[{"batb":[[0,1.31,267.52]],"batl":[[0,1.35,271.87],[1,1.77,493.74],[2,1.77,0]],"ltp":0.0,"tv":0.0,"id":13181195}]}]}
{"op":"mcm","clk":"1008551671","pt":1580660532590,"mc":[{"id":"1.168237987","rc":[{"batl":[[0,5.3,118.73]],"ltp":0.0,"tv":0.0,"id":14833204}]}]}
{"op":"mcm","clk":"1008552205","pt":1580660534734,"mc":[{"id":"1.168237987","rc":[{"batl":[[0,1.34,155.87],[1,1.35,271.87],[2,1.77,493.74]],"ltp":0.0,"tv":0.0,"id":13181195}]}]}
{"op":"mcm","clk":"1008585821","pt":1580660685248,"mc":[{"id":"1.168237987","rc":[{"batb":[[0,1.31,227.12]],"ltp":0.0,"tv":0.0,"id":13181195}]}]}
{"op":"mcm","clk":"1008586582","pt":1580660688974,"mc":[{"id":"1.168237987","rc":[{"batl":[[0,1.34,195.37]],"ltp":0.0,"tv":0.0,"id":13181195}]}]}
{"op":"mcm","clk":"1008596451","pt":1580660735025,"mc":[{"id":"1.168237987","rc":[{"batb":[[0,1.31,188.62]],"ltp":0.0,"tv":0.0,"id":13181195}]}]}
{"op":"mcm","clk":"1008597045","pt":1580660737928,"mc":[{"id":"1.168237987","rc":[{"batl":[[0,1.34,233.01]],"ltp":0.0,"tv":0.0,"id":13181195}]}]}
{"op":"mcm","clk":"1008599300","pt":1580660748388,"mc":[{"id":"1.168237987","rc":[{"batb":[[0,1.31,147.99]],"ltp":0.0,"tv":0.0,"id":13181195}]}]}
{"op":"mcm","clk":"1008599989","pt":1580660751861,"mc":[{"id":"1.168237987","rc":[{"batb":[[0,1.29,74.2],[1,1.25,88.99],[2,1.01,10.51]],"batl":[[0,1.77,493.74],[1,1.35,0],[2,1.77,0]],"ltp":0.0,"tv":0.0,"id":13181195}]}]}
{"op":"mcm","clk":"1008600028","pt":1580660752086,"mc":[{"id":"1.168237987","rc":[{"batb":[[0,3.3,17.86],[1,1.01,10.51],[2,1.01,0]],"ltp":0.0,"tv":0.0,"id":14833204},{"batb":[[0,1.25,88.99],[1,1.01,10.51],[2,1.01,0]],"ltp":0.0,"tv":0.0,"id":13181195}]}]}
{"op":"mcm","clk":"1008600531","pt":1580660754673,"mc":[{"id":"1.168237987","rc":[{"batb":[[0,1.26,555.57],[1,1.25,523.51],[2,1.01,10.51]],"batl":[[0,1.43,310.74],[1,1.44,203.1],[2,1.77,493.74]],"ltp":0.0,"tv":0.0,"id":13181195}]}]}
{"op":"mcm","clk":"1008602733","pt":1580660765501,"mc":[{"id":"1.168237987","rc":[{"batl":[[0,1.77,493.74],[1,1.44,0],[2,1.77,0]],"ltp":0.0,"tv":0.0,"id":13181195}]}]}
{"op":"mcm","clk":"1008603471","pt":1580660768877,"mc":[{"id":"1.168237987","rc":[{"batb":[[0,4.3,18.73],[1,3.75,13.3],[2,3.3,17.86]],"ltp":0.0,"tv":0.0,"id":14833204},{"batb":[[2,1.22,105.12]],"batl":[[0,1.3,411.15],[1,1.31,313.4]],"ltp":0.0,"tv":0.0,"id":13181195}]}]}
{"op":"mcm","clk":"1008603563","pt":1580660769295,"mc":[{"id":"1.168237987","rc":[{"batb":[[2,1.01,10.51]],"ltp":0.0,"tv":0.0,"id":14833204}]}]}
{"op":"mcm","clk":"1008604079","pt":1580660771860,"mc":[{"id":"1.168237987","rc":[{"batl":[[0,6,106.12]],"ltp":0.0,"tv":0.0,"id":14833204},{"batl":[[2,1.66,580.02]],"ltp":0.0,"tv":0.0,"id":13181195}]}]}
{"op":"mcm","clk":"1008605929","pt":1580660780499,"mc":[{"id":"1.168237987","rc":[{"trd":[[1.3,68.9]],"batl":[[0,1.3,376.7]],"ltp":1.3,"tv":68.89,"id":13181195}],"tv":68.89}]}
{"op":"mcm","clk":"1008606708","pt":1580660783998,"mc":[{"id":"1.168237987","rc":[{"batl":[[0,1.3,418.67]],"ltp":1.3,"tv":68.89,"id":13181195}]}]}
{"op":"mcm","clk":"1008607035","pt":1580660785626,"mc":[{"id":"1.168237987","rc":[{"batb":[[0,3.75,13.3],[1,1.01,10.51],[2,1.01,0]],"ltp":0.0,"tv":0.0,"id":14833204},{"batb":[[0,1.22,105.12],[1,1.01,10.51],[2,1.22,0]],"batl":[[0,1.66,580.02],[1,1.31,0],[2,1.66,0]],"ltp":1.3,"tv":68.89,"id":13181195}]}]}
{"op":"mcm","clk":"1008608139","pt":1580660790813,"mc":[{"id":"1.168237987","rc":[{"batb":[[0,1.28,180.3],[1,1.27,388.04],[2,1.22,105.12]],"batl":[[0,1.31,343.78],[1,1.32,302.72],[2,1.66,580.02]],"ltp":1.3,"tv":68.89,"id":13181195}]}]}
{"op":"mcm","clk":"1008608823","pt":1580660793924,"mc":[{"id":"1.168237987","rc":[{"batb":[[0,1.22,105.12],[1,1.01,10.51],[2,1.22,0]],"batl":[[0,1.66,580.02],[1,1000,3.04],[2,1.66,0]],"ltp":1.3,"tv":68.89,"id":13181195}]}]}
{"op":"mcm","clk":"1008608981","pt":1580660794820,"mc":[{"id":"1.168237987","rc":[{"batl":[[1,1000,0]],"ltp":1.3,"tv":68.89,"id":13181195}]}]}
{"op":"mcm","clk":"1008609360","pt":1580660796724,"mc":[{"id":"1.168237987","rc":[{"batb":[[0,1.24,187.85],[1,1.23,471.33],[2,1.22,105.12]],"batl":[[0,1.36,298.68],[1,1.37,253.41],[2,1.66,580.02]],"ltp":1.3,"tv":68.89,"id":13181195}]}]}
{"op":"mcm","clk":"1008609620","pt":1580660797909,"mc":[{"id":"1.168237987","rc":[{"trd":[[1.24,0.04]],"batb":[[0,1.24,187.83]],"ltp":1.24,"tv":68.93,"id":13181195}],"tv":68.93}]}
{"op":"mcm","clk":"1008610199","pt":1580660800826,"mc":[{"id":"1.168237987","rc":[{"batl":[[0,1.66,580.02],[1,1.37,0],[2,1.66,0]],"ltp":1.24,"tv":68.93,"id":13181195}]}]}
{"op":"mcm","clk":"1008610887","pt":1580660803966,"mc":[{"id":"1.168237987","rc":[{"batb":[[0,4.8,14.87],[1,4.2,19.91],[2,3.75,13.3]],"ltp":0.0,"tv":0.0,"id":14833204},{"batl":[[0,1.27,511.39],[1,1.28,352.58]],"ltp":1.24,"tv":68.93,"id":13181195}]}]}
{"op":"mcm","clk":"1008611051","pt":1580660804735,"mc":[{"id":"1.168237987","rc":[{"batb":[[2,1.01,10.51]],"ltp":0.0,"tv":0.0,"id":14833204}]}]}
{"op":"mcm","clk":"1008611212","pt":1580660805511,"mc":[{"id":"1.168237987","rc":[{"batl":[[0,7.2,92.14]],"ltp":0.0,"tv":0.0,"id":14833204},{"batl":[[2,1.58,650.81]],"ltp":1.24,"tv":68.93,"id":13181195}]}]}
{"op":"mcm","clk":"1008614993","pt":1580660823030,"mc":[{"id":"1.168237987","rc":[{"batb":[[0,1.22,105.12],[1,1.19,118.89],[2,1.01,10.51]],"batl":[[0,1.58,650.81],[1,1.28,0],[2,1.58,0]],"ltp":1.24,"tv":68.93,"id":13181195}]}]}
{"op":"mcm","clk":"1008615051","pt":1580660823349,"mc":[{"id":"1.168237987","rc":[{"batb":[[0,4.2,19.91],[1,1.01,10.51],[2,1.01,0]],"ltp":0.0,"tv":0.0,"id":14833204},{"batb":[[0,1.19,118.89],[1,1.01,10.51],[2,1.01,0]],"ltp":1.24,"tv":68.93,"id":13181195}]}]}
{"op":"mcm","clk":"1008615576","pt":1580660825951,"mc":[{"id":"1.168237987","rc":[{"batb":[[0,1.22,297.37],[1,1.21,528.24],[2,1.19,118.89]],"batl":[[0,1.3,179.76],[1,1.31,317.49],[2,1.58,650.81]],"ltp":1.24,"tv":68.93,"id":13181195}]}]}
{"op":"mcm","clk":"1008615756","pt":1580660826767,"mc":[{"id":"1.168237987","rc":[{"batl":[[0,1.58,650.81],[1,1.31,0],[2,1.58,0]],"ltp":1.24,"tv":68.93,"id":13181195}]}]}
{"op":"mcm","clk":"1008616455","pt":1580660829656,"mc":[{"id":"1.168237987","rc":[{"batl":[[0,1.25,526.42],[1,1.26,384.8],[2,1.58,650.81]],"ltp":1.24,"tv":68.93,"id":13181195}]}]}
{"op":"mcm","clk":"1008616644","pt":1580660830564,"mc":[{"id":"1.168237987","rc":[{"batb":[[0,5.2,12.35],[1,4.7,15.11],[2,1.01,10.51]],"ltp":0.0,"tv":0.0,"id":14833204}]}]}
{"op":"mcm","clk":"1008619929","pt":1580660845905,"mc":[{"id":"1.168237987","rc":[{"batb":[[0,4.7,15.11],[1,1.01,10.51],[2,1.01,0]],"ltp":0.0,"tv":0.0,"id":14833204},{"batb":[[0,1.21,337.98],[1,1.18,128.49],[2,1.01,10.51]],"batl":[[0,1.58,650.81],[1,1.26,0],[2,1.58,0]],"ltp":1.24,"tv":68.93,"id":13181195}]}]}
{"op":"mcm","clk":"1008620468","pt":1580660848467,"mc":[{"id":"1.168237987","rc":[{"batb":[[1,1.2,561.1],[2,1.18,128.49]],"batl":[[0,1.27,498.25],[1,1.28,352.78],[2,1.58,650.81]],"ltp":1.24,"tv":68.93,"id":13181195}]}]}
{"op":"mcm","clk":"1008622795","pt":1580660858788,"mc":[{"id":"1.168237987","rc":[{"batl":[[0,1.58,650.81],[1,1.28,0],[2,1.58,0]],"ltp":1.24,"tv":68.93,"id":13181195}]}]}
{"op":"mcm","clk":"1008623481","pt":1580660862033,"mc":[{"id":"1.168237987","rc":[{"batb":[[0,5.4,10.94],[1,4.7,15.11],[2,1.01,10.51]],"ltp":0.0,"tv":0.0,"id":14833204},{"batl":[[0,1.24,550.04],[1,1.25,402.54],[2,1.58,650.81]],"ltp":1.24,"tv":68.93,"id":13181195}]}]}
{"op":"mcm","clk":"1008626001","pt":1580660873839,"mc":[{"id":"1.168237987","rc":[{"batl":[[0,1.24,511.36]],"ltp":1.24,"tv":68.93,"id":13181195}]}]}
{"op":"mcm","clk":"1008626642","pt":1580660876734,"mc":[{"id":"1.168237987","rc":[{"batb":[[0,1.21,378.05]],"ltp":1.24,"tv":68.93,"id":13181195}]}]}
{"op":"mcm","clk":"1008631039","pt":1580660897030,"mc":[{"id":"1.168237987","rc":[{"trd":[[5.4,0]],"batb":[[0,5.4,10.93]],"ltp":5.4,"tv":0.0,"id":14833204},{"trd":[[1.23,0.02]],"ltp":1.23,"tv":68.94,"id":13181195}],"tv":68.95}]}
{"op":"mcm","clk":"1008631300","pt":1580660899743,"mc":[{"id":"1.168237987","rc":[{"batb":[[0,1.18,128.49],[1,1.14,173.26],[2,1.01,10.51]],"batl":[[0,1.58,650.81],[1,1.25,0],[2,1.58,0]],"ltp":1.23,"tv":68.94,"id":13181195}]}]}
{"op":"mcm","clk":"1008631889","pt":1580660901872,"mc":[{"id":"1.168237987","rc":[{"batb":[[1,1.16,791.56],[2,1.15,324.98]],"batl":[[0,1.28,269.47],[1,1.29,341.51],[2,1.58,650.81]],"ltp":1.23,"tv":68.94,"id":13181195}]}]}
{"op":"mcm","clk":"1008634135","pt":1580660910937,"mc":[{"id":"1.168237987","rc":[{"batb":[[0,4.7,15.11],[1,1.01,10.51],[2,1.01,0]],"ltp":5.4,"tv":0.0,"id":14833204},{"batb":[[0,1.16,791.56],[1,1.15,324.98],[2,1.14,173.26]],"ltp":1.23,"tv":68.94,"id":13181195}]}]}
{"op":"mcm","clk":"1008635952","pt":1580660919028,"mc":[{"id":"1.168237987","rc":[{"batl":[[0,1.58,650.81],[1,1.29,0],[2,1.58,0]],"ltp":1.23,"tv":68.94,"id":13181195}]}]}
{"op":"mcm","clk":"1008636579","pt":1580660921991,"mc":[{"id":"1.168237987","rc":[{"batl":[[0,1.19,576.76],[1,1.2,504.66]],"ltp":1.23,"tv":68.94,"id":13181195}]}]}
{"op":"mcm","clk":"1008636702","pt":1580660922619,"mc":[{"id":"1.168237987","rc":[{"batb":[[0,6.6,13.85],[1,5.5,10.62],[2,1.01,10.51]],"ltp":5.4,"tv":0.0,"id":14833204}]}]}
{"op":"mcm","clk":"1008637387","pt":1580660925628,"mc":[{"id":"1.168237987","rc":[{"batl":[[0,9.8,75.24]],"ltp":5.4,"tv":0.0,"id":14833204},{"batl":[[2,1.49,761.91]],"ltp":1.23,"tv":68.94,"id":13181195}]}]}
{"op":"mcm","clk":"1008640543","pt":1580660940849,"mc":[{"id":"1.168237987","rc":[{"batb":[[0,5.5,10.62],[1,1.01,10.51],[2,1.01,0]],"ltp":5.4,"tv":0.0,"id":14833204},{"batb":[[0,1.1,239.51],[1,1.01,10.51],[2,1.14,0]],"batl":[[0,1.49,761.91],[1,1.2,0],[2,1.49,0]],"ltp":1.23,"tv":68.94,"id":13181195}]}]}
{"op":"mcm","clk":"1008641250","pt":1580660944020,"mc":[{"id":"1.168237987","rc":[{"batb":[[0,1.12,549.3],[1,1.11,609.65],[2,1.1,239.51]],"batl":[[0,1.23,269.01],[1,1.24,428.29],[2,1.49,761.91]],"ltp":1.23,"tv":68.94,"id":13181195}]}]}
{"op":"mcm","clk":"1008642428","pt":1580660949741,"mc":[{"id":"1.168237987","rc":[{"batl":[[0,1.49,761.91],[1,1.24,0],[2,1.49,0]],"ltp":1.23,"tv":68.94,"id":13181195}]}]}
{"op":"mcm","clk":"1008642937","pt":1580660952044,"mc":[{"id":"1.168237987","rc":[{"batl":[[0,1.14,651.53],[1,1.15,477.56]],"ltp":1.23,"tv":68.94,"id":13181195}]}]}
{"op":"mcm","clk":"1008643130","pt":1580660952950,"mc":[{"id":"1.168237987","rc":[{"batb":[[0,8.4,8.18],[1,6.8,12.75],[2,1.01,10.51]],"ltp":5.4,"tv":0.0,"id":14833204}]}]}
{"op":"mcm","clk":"1008643762","pt":1580660955729,"mc":[{"id":"1.168237987","rc":[{"batl":[[0,14,62.55]],"ltp":5.4,"tv":0.0,"id":14833204},{"batl":[[2,1.43,872.64]],"ltp":1.23,"tv":68.94,"id":13181195}]}]}
{"op":"mcm","clk":"1008646580","pt":1580660969870,"mc":[{"id":"1.168237987","rc":[{"batb":[[0,1.1,239.51],[1,1.07,341.48],[2,1.01,10.51]],"batl":[[0,1.43,872.64],[1,1.15,0],[2,1.43,0]],"ltp":1.23,"tv":68.94,"id":13181195}]}]}
{"op":"mcm","clk":"1008646667","pt":1580660970246,"mc":[{"id":"1.168237987","rc":[{"batb":[[0,6.8,12.75],[1,1.01,10.51],[2,1.01,0]],"ltp":5.4,"tv":0.0,"id":14833204},{"batb":[[0,1.07,341.48],[1,1.01,10.51],[2,1.01,0]],"ltp":1.23,"tv":68.94,"id":13181195}]}]}
{"op":"mcm","clk":"1008646970","pt":1580660971854,"mc":[{"id":"1.168237987","rc":[{"batl":[[0,1.12,1.68],[1,1.43,872.64]],"ltp":1.23,"tv":68.94,"id":13181195}]}]}
{"op":"mcm","clk":"1008647161","pt":1580660972855,"mc":[{"id":"1.168237987","rc":[{"batb":[[0,1.08,1196.24],[1,1.07,341.48],[2,1.01,10.51]],"batl":[[0,1.18,711.92],[1,1.19,379.72],[2,1.43,872.64]],"ltp":1.23,"tv":68.94,"id":13181195}]}]}
{"op":"mcm","clk":"1008647848","pt":1580660976443,"mc":[{"id":"1.168237987","rc":[{"batl":[[0,1.43,872.64],[1,1.19,0],[2,1.43,0]],"ltp":1.23,"tv":68.94,"id":13181195}]}]}
{"op":"mcm","clk":"1008648479","pt":1580660979595,"mc":[{"id":"1.168237987","rc":[{"batl":[[0,1.1,813.87],[1,1.11,357.38],[2,1.43,872.64]],"ltp":1.23,"tv":68.94,"id":13181195}]}]}
{"op":"mcm","clk":"1008648644","pt":1580660980381,"mc":[{"id":"1.168237987","rc":[{"batb":[[0,10.5,11.49],[1,9,17],[2,1.01,10.51]],"ltp":5.4,"tv":0.0,"id":14833204},{"batb":[[2,1.05,440.78]],"ltp":1.23,"tv":68.94,"id":13181195}]}]}
{"op":"mcm","clk":"1008649146","pt":1580660982989,"mc":[{"id":"1.168237987","rc":[{"batl":[[0,21,53.46]],"ltp":5.4,"tv":0.0,"id":14833204}]}]}
{"op":"mcm","clk":"1008651925","pt":1580660996030,"mc":[{"id":"1.168237987","rc":[{"trd":[[1.08,3.36]],"batb":[[0,1.08,1194.56]],"ltp":1.08,"tv":72.3,"id":13181195}],"tv":72.31}]}
{"op":"mcm","clk":"1008652324","pt":1580660997816,"mc":[{"id":"1.168237987","rc":[{"batb":[[0,9,17],[1,1.01,10.51],[2,1.01,0]],"ltp":5.4,"tv":0.0,"id":14833204},{"batb":[[0,1.05,440.78],[1,1.01,10.51],[2,1.05,0]],"batl":[[0,1.43,872.64],[1,1.11,0],[2,1.43,0]],"ltp":1.08,"tv":72.3,"id":13181195}]}]}
{"op":"mcm","clk":"1008652869","pt":1580661000522,"mc":[{"id":"1.168237987","rc":[{"batb":[[0,1.06,1218.81],[1,1.05,440.78],[2,1.01,10.51]],"batl":[[0,1.12,650.31],[1,1.13,498.75],[2,1.43,872.64]],"ltp":1.08,"tv":72.3,"id":13181195}]}]}
{"op":"mcm","clk":"1008655009","pt":1580661010670,"mc":[{"id":"1.168237987","rc":[{"batb":[[0,1.05,440.78],[1,1.01,10.51],[2,1.01,0]],"batl":[[0,1.43,872.64],[1,1.13,0],[2,1.43,0]],"ltp":1.08,"tv":72.3,"id":13181195}]}]}
{"op":"mcm","clk":"1008655707","pt":1580661014002,"mc":[{"id":"1.168237987","rc":[{"batb":[[0,1.08,1196.24],[1,1.07,1262.21],[2,1.05,440.78]],"batl":[[0,1.1,818.74],[1,1.11,1391.04],[2,1.43,872.64]],"ltp":1.08,"tv":72.3,"id":13181195}]}]}
{"op":"mcm","clk":"1008655751","pt":1580661014172,"mc":[{"id":"1.168237987","rc":[{"batb":[[1,1.05,440.78],[2,1.01,10.51]],"batl":[[1,1.11,352.54]],"ltp":1.08,"tv":72.3,"id":13181195}]}]}
{"op":"mcm","clk":"1008657590","pt":1580661023011,"mc":[{"id":"1.168237987","rc":[{"batb":[[0,1.05,440.78],[1,1.01,10.51],[2,1.01,0]],"batl":[[0,1.43,872.64],[1,1.11,0],[2,1.43,0]],"ltp":1.08,"tv":72.3,"id":13181195}]}]}
{"op":"mcm","clk":"1008658190","pt":1580661025893,"mc":[{"id":"1.168237987","rc":[{"batb":[[0,1.06,1218.81],[1,1.05,440.78],[2,1.01,10.51]],"batl":[[0,1.12,649.3],[1,1.13,499.76],[2,1.43,872.64]],"ltp":1.08,"tv":72.3,"id":13181195}]}]}
{"op":"mcm","clk":"1008658263","pt":1580661026300,"mc":[{"id":"1.168237987","rc":[{"batb":[[0,1.05,440.78],[1,1.01,10.51],[2,1.01,0]],"batl":[[0,1.43,872.64],[1,1.13,0],[2,1.43,0]],"ltp":1.08,"tv":72.3,"id":13181195}]}]}
{"op":"mcm","clk":"1008658800","pt":1580661028936,"mc":[{"id":"1.168237987","rc":[{"batb":[[0,1.08,667.74],[1,1.07,533.44],[2,1.05,440.78]],"batl":[[0,1.09,179.69],[1,1.1,996.43]],"ltp":1.08,"tv":72.3,"id":13181195}]}]}
{"op":"mcm","clk":"1008659537","pt":1580661032703,"mc":[{"id":"1.168237987","rc":[{"batl":[[0,24,50.5]],"ltp":5.4,"tv":0.0,"id":14833204},{"batb":[[0,1.05,440.78],[1,1.01,10.51],[2,1.05,0]],"batl":[[0,1.37,1010.97],[1,1.1,0]],"ltp":1.08,"tv":72.3,"id":13181195}]}]}
{"op":"mcm","clk":"1008660169","pt":1580661035734,"mc":[{"id":"1.168237987","rc":[{"batb":[[0,1.06,1218.81],[1,1.05,440.78],[2,1.01,10.51]],"batl":[[0,1.12,657.67],[1,1.13,491.46],[2,1.37,1010.97]],"ltp":1.08,"tv":72.3,"id":13181195}]}]}
{"op":"mcm","clk":"1008661280","pt":1580661040945,"mc":[{"id":"1.168237987","rc":[{"batl":[[0,1.37,1010.97],[1,1.13,0],[2,1.37,0]],"ltp":1.08,"tv":72.3,"id":13181195}]}]}
{"op":"mcm","clk":"1008661723","pt":1580661042852,"mc":[{"id":"1.168237987","rc":[{"batl":[[0,1.08,52.73],[1,1.37,1010.97]],"ltp":1.08,"tv":72.3,"id":13181195}]}]}
{"op":"mcm","clk":"1008661953","pt":1580661043940,"mc":[{"id":"1.168237987","rc":[{"batl":[[0,1.08,1248.97]],"ltp":1.08,"tv":72.3,"id":13181195}]}]}
{"op":"mcm","clk":"1008662168","pt":1580661044938,"mc":[{"id":"1.168237987","rc":[{"batb":[[0,13,7.4],[1,10,13.69],[2,1.01,10.51]],"ltp":5.4,"tv":0.0,"id":14833204},{"batb":[[2,1.04,571.86]],"ltp":1.08,"tv":72.3,"id":13181195}]}]}
{"op":"mcm","clk":"1008662470","pt":1580661046426,"mc":[{"id":"1.168237987","rc":[{"batl":[[0,30,47.14]],"ltp":5.4,"tv":0.0,"id":14833204}]}]}
{"op":"mcm","clk":"1008670203","pt":1580661081171,"mc":[{"id":"1.168237987","rc":[{"batb":[[0,1.05,440.78],[1,1.04,571.86],[2,1.01,10.51]],"batl":[[0,1.08,52.73]],"ltp":1.08,"tv":72.3,"id":13181195}]}]}
{"op":"mcm","clk":"1008670805","pt":1580661084002,"mc":[{"id":"1.168237987","rc":[{"batb":[[0,10,13.69],[1,1.01,10.51],[2,1.01,0]],"ltp":5.4,"tv":0.0,"id":14833204},{"batb":[[0,1.05,1172.33]],"batl":[[1,1.11,1163.91],[2,1.37,1010.97]],"ltp":1.08,"tv":72.3,"id":13181195}]}]}
{"op":"mcm","clk":"1008672971","pt":1580661094019,"mc":[{"id":"1.168237987","rc":[{"batl":[[1,1.37,1010.97],[2,1.37,0]],"ltp":1.08,"tv":72.3,"id":13181195}]}]}
{"op":"mcm","clk":"1008673617","pt":1580661097024,"mc":[{"id":"1.168237987","rc":[{"batl":[[0,1.06,524.25],[1,1.07,688.07],[2,1.08,52.73]],"ltp":1.08,"tv":72.3,"id":13181195}]}]}
{"op":"mcm","clk":"1008673803","pt":1580661097818,"mc":[{"id":"1.168237987","rc":[{"batb":[[0,15.5,4.72],[1,12,8.89],[2,1.01,10.51]],"ltp":5.4,"tv":0.0,"id":14833204},{"batb":[[2,1.03,715.61]],"ltp":1.08,"tv":72.3,"id":13181195}]}]}
{"op":"mcm","clk":"1008674272","pt":1580661100006,"mc":[{"id":"1.168237987","rc":[{"batl":[[0,42,43.67]],"ltp":5.4,"tv":0.0,"id":14833204}]}]}
{"op":"mcm","clk":"1008677470","pt":1580661114022,"mc":[{"id":"1.168237987","rc":[{"batb":[[0,12,8.89],[1,1.01,10.51],[2,1.01,0]],"ltp":5.4,"tv":0.0,"id":14833204},{"batb":[[0,1.03,715.61],[1,1.01,10.51],[2,1.03,0]],"batl":[[0,1.08,52.73],[1,1.37,1010.97],[2,1.08,0]],"ltp":1.08,"tv":72.3,"id":13181195}]}]}
{"op":"mcm","clk":"1008678133","pt":1580661116913,"mc":[{"id":"1.168237987","rc":[{"batb":[[0,1.04,1242.25],[1,1.03,715.61],[2,1.01,10.51]],"ltp":1.08,"tv":72.3,"id":13181195}]}]}
{"op":"mcm","clk":"1008678812","pt":1580661119956,"mc":[{"id":"1.168237987","rc":[{"batl":[[0,1.05,622.31],[1,1.06,602.37],[2,1.08,52.73]],"ltp":1.08,"tv":72.3,"id":13181195}]}]}
{"op":"mcm","clk":"1008678993","pt":1580661120735,"mc":[{"id":"1.168237987","rc":[{"batb":[[0,18,6.61],[1,15,5.19],[2,1.01,10.51]],"ltp":5.4,"tv":0.0,"id":14833204},{"batb":[[2,1.02,891.78]],"ltp":1.08,"tv":72.3,"id":13181195}]}]}
{"op":"mcm","clk":"1008679629","pt":1580661123551,"mc":[{"id":"1.168237987","rc":[{"batl":[[0,65,40.66]],"ltp":5.4,"tv":0.0,"id":14833204}]}]}
{"op":"mcm","clk":"1008683175","pt":1580661139978,"mc":[{"id":"1.168237987","rc":[{"batb":[[0,15,5.19],[1,1.01,10.51],[2,1.01,0]],"ltp":5.4,"tv":0.0,"id":14833204},{"batb":[[0,1.02,891.78],[1,1.01,10.51],[2,1.02,0]],"batl":[[0,1.08,52.73],[1,1.37,1010.97],[2,1.08,0]],"ltp":1.08,"tv":72.3,"id":13181195}]}]}
{"op":"mcm","clk":"1008683847","pt":1580661142787,"mc":[{"id":"1.168237987","rc":[{"batb":[[0,1.03,1254.31],[1,1.02,891.78],[2,1.01,10.51]],"batl":[[0,1.07,1207.42],[1,1.08,52.73],[2,1.37,1010.97]],"ltp":1.08,"tv":72.3,"id":13181195}]}]}
{"op":"mcm","clk":"1008684750","pt":1580661146811,"mc":[{"id":"1.168237987","rc":[{"batl":[[0,1.08,52.73],[1,1.37,1010.97],[2,1.37,0]],"ltp":1.08,"tv":72.3,"id":13181195}]}]}
{"op":"mcm","clk":"1008685447","pt":1580661149988,"mc":[{"id":"1.168237987","rc":[{"batl":[[0,1.05,1230.42],[1,1.08,52.73],[2,1.37,1010.97]],"ltp":1.08,"tv":72.3,"id":13181195}]}]}
{"op":"mcm","clk":"1008685582","pt":1580661150607,"mc":[{"id":"1.168237987","rc":[{"batb":[[0,21,4.34],[1,18,6.69],[2,1.01,10.51]],"ltp":5.4,"tv":0.0,"id":14833204}]}]}
{"op":"mcm","clk":"1008688685","pt":1580661164917,"mc":[{"id":"1.168237987","rc":[{"batb":[[0,18,6.69],[1,1.01,10.51],[2,1.01,0]],"ltp":5.4,"tv":0.0,"id":14833204},{"batl":[[0,1.05,655.39]],"ltp":1.08,"tv":72.3,"id":13181195}]}]}
{"op":"mcm","clk":"1008689338","pt":1580661167935,"mc":[{"id":"1.168237987","rc":[{"batl":[[1,1.06,569.61],[2,1.08,52.73]],"ltp":1.08,"tv":72.3,"id":13181195}]}]}
{"op":"mcm","clk":"1008689937","pt":1580661170631,"mc":[{"id":"1.168237987","rc":[{"batb":[[0,1.02,891.78],[1,1.01,10.51],[2,1.01,0]],"ltp":1.08,"tv":72.3,"id":13181195}]}]}
{"op":"mcm","clk":"1008690661","pt":1580661173854,"mc":[{"id":"1.168237987","rc":[{"batb":[[0,1.04,1242.25],[1,1.02,891.78],[2,1.01,10.51]],"ltp":1.08,"tv":72.3,"id":13181195}]}]}
{"op":"mcm","clk":"1008690902","pt":1580661174890,"mc":[{"id":"1.168237987","rc":[{"batb":[[1,15,5.35],[2,1.01,10.51]],"ltp":5.4,"tv":0.0,"id":14833204},{"batb":[[1,1.03,713.09],[2,1.02,869.99]],"ltp":1.08,"tv":72.3,"id":13181195}]}]}
{"op":"mcm","clk":"1008694937","pt":1580661192559,"mc":[{"id":"1.168237987","rc":[{"batb":[[0,15,5.35],[1,1.01,10.51],[2,1.01,0]],"ltp":5.4,"tv":0.0,"id":14833204},{"batb":[[0,1.02,869.99],[1,1.01,10.51],[2,1.02,0]],"batl":[[0,1.08,52.73],[1,1.37,1010.97],[2,1.08,0]],"ltp":1.08,"tv":72.3,"id":13181195}]}]}
{"op":"mcm","clk":"1008695524","pt":1580661195262,"mc":[{"id":"1.168237987","rc":[{"batb":[[0,1.03,1254.31],[1,1.02,869.99],[2,1.01,10.51]],"batl":[[0,1.07,1207.42],[1,1.08,52.73],[2,1.37,1010.97]],"ltp":1.08,"tv":72.3,"id":13181195}]}]}
{"op":"mcm","clk":"1008696774","pt":1580661200947,"mc":[{"id":"1.168237987","rc":[{"batb":[[0,1.02,869.99],[1,1.01,10.51],[2,1.01,0]],"ltp":1.08,"tv":72.3,"id":13181195}]}]}
{"op":"mcm","clk":"1008697395","pt":1580661203855,"mc":[{"id":"1.168237987","rc":[{"batb":[[0,1.05,1230.42],[1,1.02,869.99],[2,1.01,10.51]],"ltp":1.08,"tv":72.3,"id":13181195}]}]}
{"op":"mcm","clk":"1008697597","pt":1580661204845,"mc":[{"id":"1.168237987","rc":[{"batb":[[1,10.5,12.2],[2,1.01,10.51]],"ltp":5.4,"tv":0.0,"id":14833204},{"batb":[[1,1.04,534.49],[2,1.02,773.44]],"ltp":1.08,"tv":72.3,"id":13181195}]}]}
{"op":"mcm","clk":"1008697981","pt":1580661206759,"mc":[{"id":"1.168237987","rc":[{"batl":[[0,42,43.67]],"ltp":5.4,"tv":0.0,"id":14833204}]}]}
{"op":"mcm","clk":"1008702317","pt":1580661227940,"mc":[{"id":"1.168237987","rc":[{"batb":[[0,10.5,12.2],[1,1.01,10.51],[2,1.01,0]],"ltp":5.4,"tv":0.0,"id":14833204},{"batb":[[0,1.02,773.44],[1,1.01,10.51],[2,1.02,0]],"batl":[[0,1.08,52.73],[1,1.37,1010.97],[2,1.37,0]],"ltp":1.08,"tv":72.3,"id":13181195}]}]}
{"op":"mcm","clk":"1008702835","pt":1580661230396,"mc":[{"id":"1.168237987","rc":[{"batb":[[0,1.04,679.79],[1,1.03,567.91],[2,1.02,773.44]],"batl":[[1,1.09,197.63],[2,1.1,978.65]],"ltp":1.08,"tv":72.3,"id":13181195}]}]}
{"op":"mcm","clk":"1008704192","pt":1580661236882,"mc":[{"id":"1.168237987","rc":[{"batb":[[0,1.02,773.44],[1,1.01,10.51],[2,1.02,0]],"batl":[[1,1.37,1010.97],[2,1.1,0]],"ltp":1.08,"tv":72.3,"id":13181195}]}]}
{"op":"mcm","clk":"1008704580","pt":1580661238679,"mc":[{"id":"1.168237987","rc":[{"batl":[[1,1.37,0]],"ltp":1.08,"tv":72.3,"id":13181195}]}]}
{"op":"mcm","clk":"1008708898","pt":1580661258999,"mc":[{"id":"1.168237987","rc":[{"batb":[[0,1.05,1230.42],[1,1.02,773.44],[2,1.01,10.51]],"batl":[[0,1.07,1207.42],[1,1.08,52.73]],"ltp":1.08,"tv":72.3,"id":13181195}]}]}
{"op":"mcm","clk":"1008709713","pt":1580661262675,"mc":[{"id":"1.168237987","rc":[{"batb":[[0,1.02,773.44],[1,1.01,10.51],[2,1.01,0]],"batl":[[0,1.08,52.73],[1,1.08,0]],"ltp":1.08,"tv":72.3,"id":13181195}]}]}
{"op":"mcm","clk":"1008710371","pt":1580661265538,"mc":[{"id":"1.168237987","rc":[{"batb":[[0,1.04,679.79],[1,1.03,567.91],[2,1.02,773.44]],"batl":[[1,1.09,197.63],[2,1.1,978.65]],"ltp":1.08,"tv":72.3,"id":13181195}]}]}
{"op":"mcm","clk":"1008710987","pt":1580661268415,"mc":[{"id":"1.168237987","rc":[{"batl":[[1,1.09,0],[2,1.1,0]],"ltp":1.08,"tv":72.3,"id":13181195}]}]}
{"op":"mcm","clk":"1008711741","pt":1580661271984,"mc":[{"id":"1.168237987","rc":[{"batb":[[0,19,5.82],[1,15.5,4.64],[2,10.5,12.2]],"ltp":5.4,"tv":0.0,"id":14833204},{"batl":[[0,1.05,1230.2],[1,1.08,52.73]],"ltp":1.08,"tv":72.3,"id":13181195}]}]}
{"op":"mcm","clk":"1008711862","pt":1580661272507,"mc":[{"id":"1.168237987","rc":[{"batb":[[2,1.01,10.51]],"ltp":5.4,"tv":0.0,"id":14833204}]}]}
{"op":"mcm","clk":"1008712072","pt":1580661273531,"mc":[{"id":"1.168237987","rc":[{"batl":[[0,65,40.66]],"ltp":5.4,"tv":0.0,"id":14833204},{"batl":[[2,1.32,1160.1]],"ltp":1.08,"tv":72.3,"id":13181195}]}]}
{"op":"mcm","clk":"1008733803","pt":1580661375970,"mc":[{"id":"1.168237987","rc":[{"batb":[[0,15.5,4.64],[1,1.01,10.51],[2,1.01,0]],"ltp":5.4,"tv":0.0,"id":14833204},{"batb":[[0,1.03,567.91],[1,1.01,10.51],[2,1.02,0]],"batl":[[0,1.08,52.73],[1,1.32,1160.1],[2,1.32,0]],"ltp":1.08,"tv":72.3,"id":13181195}]}]}
{"op":"mcm","clk":"1008734414","pt":1580661378792,"mc":[{"id":"1.168237987","rc":[{"batb":[[1,1.02,664.26],[2,1.01,10.51]],"batl":[[0,1.06,1044.16],[1,1.08,52.73],[2,1.32,1160.1]],"ltp":1.08,"tv":72.3,"id":13181195}]}]}
{"op":"mcm","clk":"1008736126","pt":1580661386315,"mc":[{"id":"1.168237987","rc":[{"batb":[[0,1.01,10.51],[1,1.02,0],[2,1.01,0]],"batl":[[0,1.08,52.73],[1,1.32,1160.1],[2,1.32,0]],"ltp":1.08,"tv":72.3,"id":13181195}]}]}
{"op":"mcm","clk":"1008736846","pt":1580661389285,"mc":[{"id":"1.168237987","rc":[{"batl":[[1,1.32,0]],"ltp":1.08,"tv":72.3,"id":13181195}]}]}
{"op":"mcm","clk":"1008741343","pt":1580661408967,"mc":[{"id":"1.168237987","rc":[{"batb":[[0,1.05,554.55],[1,1.04,682.14],[2,1.01,10.51]],"batl":[[0,1.06,1044.16],[1,1.08,52.73]],"ltp":1.08,"tv":72.3,"id":13181195}]}]}
{"op":"mcm","clk":"1008741539","pt":1580661409723,"mc":[{"id":"1.168237987","rc":[{"batb":[[1,13,6.85],[2,1.01,10.51]],"ltp":5.4,"tv":0.0,"id":14833204},{"batb":[[0,1.04,1048.56],[1,1.02,776.67]],"batl":[[0,1.08,52.73],[1,1.08,0]],"ltp":1.08,"tv":72.3,"id":13181195}]}]}
{"op":"mcm","clk":"1008741674","pt":1580661410348,"mc":[{"id":"1.168237987","rc":[{"batb":[[0,13,6.85],[1,1.01,10.51],[2,1.01,0]],"ltp":5.4,"tv":0.0,"id":14833204},{"batb":[[0,1.04,466.79]],"ltp":1.08,"tv":72.3,"id":13181195}]}]}
{"op":"mcm","clk":"1008742024","pt":1580661412013,"mc":[{"id":"1.168237987","rc":[{"batl":[[0,42,43.67]],"ltp":5.4,"tv":0.0,"id":14833204},{"batl":[[1,1.34,1110.09]],"ltp":1.08,"tv":72.3,"id":13181195}]}]}
{"op":"mcm","clk":"1008742172","pt":1580661412649,"mc":[{"id":"1.168237987","rc":[{"batb":[[1,1.03,782.75],[2,1.02,776.67]],"batl":[[0,1.07,832.64],[1,1.08,423.82],[2,1.34,1110.09]],"ltp":1.08,"tv":72.3,"id":13181195}]}]}
{"op":"mcm","clk":"1008742292","pt":1580661413242,"mc":[{"id":"1.168237987","rc":[{"batb":[[1,1.02,776.67],[2,1.01,10.51]],"batl":[[0,1.08,52.73],[1,1.34,1110.09],[2,1.34,0]],"ltp":1.08,"tv":72.3,"id":13181195}]}]}
{"op":"mcm","clk":"1008743037","pt":1580661416537,"mc":[{"id":"1.168237987","rc":[{"batb":[[0,1.04,1242.03]],"batl":[[0,1.06,1218.59],[1,1.08,52.73],[2,1.34,1110.09]],"ltp":1.08,"tv":72.3,"id":13181195}]}]}
{"op":"mcm","clk":"1008743798","pt":1580661419854,"mc":[{"id":"1.168237987","rc":[{"batb":[[0,1.04,466.79]],"batl":[[0,1.08,52.73],[1,1.34,1110.09],[2,1.34,0]],"ltp":1.08,"tv":72.3,"id":13181195}]}]}
{"op":"mcm","clk":"1008744424","pt":1580661422718,"mc":[{"id":"1.168237987","rc":[{"batb":[[1,1.03,782.75],[2,1.02,776.67]],"batl":[[0,1.07,832.64],[1,1.08,423.82],[2,1.34,1110.09]],"ltp":1.08,"tv":72.3,"id":13181195}]}]}
{"op":"mcm","clk":"1008744633","pt":1580661423635,"mc":[{"id":"1.168237987","rc":[{"batb":[[0,1.02,776.67],[1,1.01,10.51],[2,1.02,0]],"ltp":1.08,"tv":72.3,"id":13181195}]}]}
{"op":"mcm","clk":"1008745321","pt":1580661426738,"mc":[{"id":"1.168237987","rc":[{"batb":[[0,1.06,419.36],[1,1.05,806.84],[2,1.02,776.67]],"ltp":1.08,"tv":72.3,"id":13181195}]}]}
{"op":"mcm","clk":"1008745538","pt":1580661427660,"mc":[{"id":"1.168237987","rc":[{"batb":[[1,11.5,9.13],[2,1.01,10.51]],"ltp":5.4,"tv":0.0,"id":14833204},{"batb":[[1,1.05,1268.31],[2,1.04,559.66]],"ltp":1.08,"tv":72.3,"id":13181195}]}]}
{"op":"mcm","clk":"1008745939","pt":1580661429250,"mc":[{"id":"1.168237987","rc":[{"batl":[[0,30,47.14]],"ltp":5.4,"tv":0.0,"id":14833204}]}]}
{"op":"mcm","clk":"1008748586","pt":1580661440781,"mc":[{"id":"1.168237987","rc":[{"batb":[[0,11.5,9.13],[1,1.01,10.51],[2,1.01,0]],"ltp":5.4,"tv":0.0,"id":14833204},{"batb":[[0,1.05,806.84],[1,1.04,559.66],[2,1.01,10.51]],"batl":[[0,1.08,423.82],[1,1.34,1110.09],[2,1.34,0]],"ltp":1.08,"tv":72.3,"id":13181195}]}]}
{"op":"mcm","clk":"1008749158","pt":1580661443302,"mc":[{"id":"1.168237987","rc":[{"batb":[[1,1.04,1013.3]],"batl":[[0,1.08,1018.7],[1,1.09,227.94],[2,1.34,1110.09]],"ltp":1.08,"tv":72.3,"id":13181195}]}]}
{"op":"mcm","clk":"1008749598","pt":1580661444970,"mc":[{"id":"1.168237987","rc":[{"batl":[[0,1.08,52.73],[1,1.34,1110.09],[2,1.34,0]],"ltp":1.08,"tv":72.3,"id":13181195}]}]}
{"op":"mcm","clk":"1008750525","pt":1580661449001,"mc":[{"id":"1.168237987","rc":[{"batb":[[0,15.5,4.96],[1,13,7.4],[2,1.01,10.51]],"ltp":5.4,"tv":0.0,"id":14833204},{"batb":[[2,1.02,780.29]],"batl":[[0,1.06,853.75],[1,1.07,361.42],[2,1.08,52.73]],"ltp":1.08,"tv":72.3,"id":13181195}]}]}
{"op":"mcm","clk":"1008750793","pt":1580661450192,"mc":[{"id":"1.168237987","rc":[{"batl":[[0,42,43.67]],"ltp":5.4,"tv":0.0,"id":14833204}]}]}
{"op":"mcm","clk":"1008753612","pt":1580661462897,"mc":[{"id":"1.168237987","rc":[{"batb":[[0,1.04,789.65],[1,1.02,780.29],[2,1.01,10.51]],"batl":[[0,1.07,361.42],[1,1.08,52.73],[2,1.34,1110.09]],"ltp":1.08,"tv":72.3,"id":13181195}]}]}
{"op":"mcm","clk":"1008753644","pt":1580661463066,"mc":[{"id":"1.168237987","rc":[{"batb":[[0,13,7.4],[1,1.01,10.51],[2,1.01,0]],"ltp":5.4,"tv":0.0,"id":14833204},{"batb":[[0,1.04,229.99]],"ltp":1.08,"tv":72.3,"id":13181195}]}]}
{"op":"mcm","clk":"1008754218","pt":1580661465910,"mc":[{"id":"1.168237987","rc":[{"batb":[[0,1.02,780.29],[1,1.01,10.51],[2,1.01,0]],"batl":[[0,1.07,402.94],[1,1.08,849.54]],"ltp":1.08,"tv":72.3,"id":13181195}]}]}
{"op":"mcm","clk":"1008754888","pt":1580661468797,"mc":[{"id":"1.168237987","rc":[{"batb":[[0,1.06,916.81],[1,1.05,304.65],[2,1.02,780.29]],"ltp":1.08,"tv":72.3,"id":13181195}]}]}
{"op":"mcm","clk":"1008754995","pt":1580661469288,"mc":[{"id":"1.168237987","rc":[{"batb":[[1,11.5,9.91],[2,1.01,10.51]],"ltp":5.4,"tv":0.0,"id":14833204},{"batb":[[1,1.05,745.5],[2,1.04,526.3]],"ltp":1.08,"tv":72.3,"id":13181195}]}]}
{"op":"mcm","clk":"1008755412","pt":1580661471283,"mc":[{"id":"1.168237987","rc":[{"batl":[[0,30,47.14]],"ltp":5.4,"tv":0.0,"id":14833204}]}]}
{"op":"mcm","clk":"1008757507","pt":1580661481007,"mc":[{"id":"1.168237987","rc":[{"batb":[[0,1.05,745.5],[1,1.04,526.3],[2,1.01,10.51]],"batl":[[0,1.08,676.67],[1,1.34,1110.09],[2,1.34,0]],"ltp":1.08,"tv":72.3,"id":13181195}]}]}
{"op":"mcm","clk":"1008757612","pt":1580661481323,"mc":[{"id":"1.168237987","rc":[{"batb":[[0,11.5,9.91],[1,1.01,10.51],[2,1.01,0]],"ltp":5.4,"tv":0.0,"id":14833204},{"batb":[[0,1.05,304.65]],"ltp":1.08,"tv":72.3,"id":13181195}]}]}
{"op":"mcm","clk":"1008758201","pt":1580661483709,"mc":[{"id":"1.168237987","rc":[{"batb":[[0,1.05,1230.2]],"batl":[[1,1.09,566.83],[2,1.34,1110.09]],"ltp":1.08,"tv":72.3,"id":13181195}]}]}
{"op":"mcm","clk":"1008759246","pt":1580661488524,"mc":[{"id":"1.168237987","rc":[{"batl":[[0,1.08,52.73],[1,1.34,1110.09],[2,1.34,0]],"ltp":1.08,"tv":72.3,"id":13181195}]}]}
{"op":"mcm","clk":"1008760028","pt":1580661492014,"mc":[{"id":"1.168237987","rc":[{"batb":[[0,14.5,5.51],[1,12,8.81],[2,11.5,9.91]],"ltp":5.4,"tv":0.0,"id":14833204},{"batb":[[2,1.02,783.04]],"batl":[[0,1.06,304.62],[1,1.07,905.42],[2,1.08,52.73]],"ltp":1.08,"tv":72.3,"id":13181195}]}]}
{"op":"mcm","clk":"1008760168","pt":1580661492717,"mc":[{"id":"1.168237987","rc":[{"batb":[[2,1.01,10.51]],"ltp":5.4,"tv":0.0,"id":14833204}]}]}
{"op":"mcm","clk":"1008760580","pt":1580661494628,"mc":[{"id":"1.168237987","rc":[{"batl":[[0,42,43.67]],"ltp":5.4,"tv":0.0,"id":14833204}]}]}
{"op":"mcm","clk":"1008764813","pt":1580661513746,"mc":[{"id":"1.168237987","rc":[{"batb":[[0,12,8.81],[1,1.01,10.51],[2,1.01,0]],"ltp":5.4,"tv":0.0,"id":14833204},{"batb":[[0,1.02,783.04],[1,1.01,10.51],[2,1.02,0]],"batl":[[0,1.08,52.73],[1,1.34,1110.09],[2,1.08,0]],"ltp":1.08,"tv":72.3,"id":13181195}]}]}
{"op":"mcm","clk":"1008765560","pt":1580661516928,"mc":[{"id":"1.168237987","rc":[{"batb":[[0,1.04,214.06],[1,1.02,783.04],[2,1.01,10.51]],"ltp":1.08,"tv":72.3,"id":13181195}]}]}
{"op":"mcm","clk":"1008766285","pt":1580661519965,"mc":[{"id":"1.168237987","rc":[{"batb":[[0,1.05,668.1],[1,1.04,567.49],[2,1.02,783.04]],"batl":[[0,1.06,949.51],[1,1.07,266.56],[2,1.08,52.73]],"ltp":1.08,"tv":72.3,"id":13181195}]}]}
{"op":"mcm","clk":"1008767364","pt":1580661524576,"mc":[{"id":"1.168237987","rc":[{"batb":[[0,1.04,214.06],[1,1.02,783.04],[2,1.01,10.51]],"batl":[[0,1.08,52.73],[1,1.34,1110.09],[2,1.08,0]],"ltp":1.08,"tv":72.3,"id":13181195}]}]}
{"op":"mcm","clk":"1008768027","pt":1580661527458,"mc":[{"id":"1.168237987","rc":[{"batb":[[1,1.03,1037.94],[2,1.02,783.04]],"batl":[[0,1.08,1092.66]],"ltp":1.08,"tv":72.3,"id":13181195}]}]}
{"op":"mcm","clk":"1008769224","pt":1580661532560,"mc":[{"id":"1.168237987","rc":[{"batl":[[0,1.08,52.73]],"ltp":1.08,"tv":72.3,"id":13181195}]}]}
{"op":"mcm","clk":"1008769914","pt":1580661535791,"mc":[{"id":"1.168237987","rc":[{"batl":[[0,1.05,1230.2],[1,1.08,52.73],[2,1.34,1110.09]],"ltp":1.08,"tv":72.3,"id":13181195}]}]}
{"op":"mcm","clk":"1008770066","pt":1580661536447,"mc":[{"id":"1.168237987","rc":[{"batb":[[0,19.5,5.67],[1,15,5.35],[2,1.01,10.51]],"ltp":5.4,"tv":0.0,"id":14833204}]}]}
{"op":"mcm","clk":"1008770664","pt":1580661539165,"mc":[{"id":"1.168237987","rc":[{"batl":[[0,65,40.66]],"ltp":5.4,"tv":0.0,"id":14833204}]}]}
{"op":"mcm","clk":"1008775243","pt":1580661560024,"mc":[{"id":"1.168237987","rc":[{"batb":[[0,15,5.35],[1,1.01,10.51],[2,1.01,0]],"ltp":5.4,"tv":0.0,"id":14833204},{"batb":[[0,1.01,10.51],[1,1.03,0],[2,1.02,0]],"batl":[[0,1.08,52.73],[1,1.34,1110.09],[2,1.34,0]],"ltp":1.08,"tv":72.3,"id":13181195}]}]}
{"op":"mcm","clk":"1008775789","pt":1580661562577,"mc":[{"id":"1.168237987","rc":[{"batb":[[0,1.02,1266.38],[1,1.01,10.51]],"batl":[[0,1.06,300.2],[1,1.07,909.8],[2,1.08,52.73]],"ltp":1.08,"tv":72.3,"id":13181195}]}]}
{"op":"mcm","clk":"1008777130","pt":1580661569297,"mc":[{"id":"1.168237987","rc":[{"batb":[[0,1.01,10.51],[1,1.01,0]],"ltp":1.08,"tv":72.3,"id":13181195}]}]}
{"op":"mcm","clk":"1008777906","pt":1580661573025,"mc":[{"id":"1.168237987","rc":[{"batb":[[1,11.5,9.05],[2,1.01,10.51]],"ltp":5.4,"tv":0.0,"id":14833204},{"batb":[[0,1.05,1230.2],[1,1.04,535.27],[2,1.02,768.88]],"ltp":1.08,"tv":72.3,"id":13181195}]}]}
{"op":"mcm","clk":"1008778416","pt":1580661575527,"mc":[{"id":"1.168237987","rc":[{"batl":[[0,42,43.67]],"ltp":5.4,"tv":0.0,"id":14833204}]}]}
{"op":"mcm","clk":"1008782600","pt":1580661595022,"mc":[{"id":"1.168237987","rc":[{"batb":[[0,11.5,9.05],[1,1.01,10.51],[2,1.01,0]],"ltp":5.4,"tv":0.0,"id":14833204},{"batb":[[0,1.02,768.88],[1,1.01,10.51],[2,1.02,0]],"batl":[[0,1.08,52.73],[1,1.34,1110.09],[2,1.08,0]],"ltp":1.08,"tv":72.3,"id":13181195}]}]}
{"op":"mcm","clk":"1008783884","pt":1580661600950,"mc":[{"id":"1.168237987","rc":[{"batb":[[0,1.05,672.62],[1,1.04,562.93],[2,1.02,768.88]],"batl":[[0,1.06,945.82],[1,1.07,270.21],[2,1.08,52.73]],"ltp":1.08,"tv":72.3,"id":13181195}]}]}
{"op":"mcm","clk":"1008784725","pt":1580661604555,"mc":[{"id":"1.168237987","rc":[{"batb":[[0,1.04,219.76],[1,1.02,768.88],[2,1.01,10.51]],"batl":[[0,1.08,52.73],[1,1.34,1110.09],[2,1.08,0]],"ltp":1.08,"tv":72.3,"id":13181195}]}]}
{"op":"mcm","clk":"1008785346","pt":1580661607463,"mc":[{"id":"1.168237987","rc":[{"batb":[[1,1.03,1032.18],[2,1.02,768.88]],"batl":[[0,1.08,1090.83]],"ltp":1.08,"tv":72.3,"id":13181195}]}]}
{"op":"mcm","clk":"1008785779","pt":1580661609628,"mc":[{"id":"1.168237987","rc":[{"batl":[[0,1.08,52.73]],"ltp":1.08,"tv":72.3,"id":13181195}]}]}
{"op":"mcm","clk":"1008786499","pt":1580661612945,"mc":[{"id":"1.168237987","rc":[{"batl":[[0,1.05,1230.2],[1,1.08,52.73],[2,1.34,1110.09]],"ltp":1.08,"tv":72.3,"id":13181195}]}]}
{"op":"mcm","clk":"1008786618","pt":1580661613426,"mc":[{"id":"1.168237987","rc":[{"batb":[[0,19,5.82],[1,14.5,5.59],[2,1.01,10.51]],"ltp":5.4,"tv":0.0,"id":14833204}]}]}
{"op":"mcm","clk":"1008787145","pt":1580661615943,"mc":[{"id":"1.168237987","rc":[{"batl":[[0,65,40.66]],"ltp":5.4,"tv":0.0,"id":14833204}]}]}
{"op":"mcm","clk":"1008789925","pt":1580661628968,"mc":[{"id":"1.168237987","rc":[{"batb":[[0,14.5,5.59],[1,1.01,10.51],[2,1.01,0]],"ltp":5.4,"tv":0.0,"id":14833204},{"batb":[[0,1.01,10.51],[1,1.03,0],[2,1.02,0]],"batl":[[0,1.08,52.73],[1,1.34,1110.09],[2,1.34,0]],"ltp":1.08,"tv":72.3,"id":13181195}]}]}
{"op":"mcm","clk":"1008790608","pt":1580661631939,"mc":[{"id":"1.168237987","rc":[{"batb":[[0,14,5.82]],"ltp":5.4,"tv":0.0,"id":14833204}]}]}
{"op":"mcm","clk":"1008791182","pt":1580661634769,"mc":[{"id":"1.168237987","rc":[{"batb":[[0,1.03,1254.08],[1,1.01,10.51]],"batl":[[0,1.04,195.07],[1,1.05,1036.98],[2,1.08,52.73]],"ltp":1.08,"tv":72.3,"id":13181195}]}]}
{"op":"mcm","clk":"1008791791","pt":1580661637669,"mc":[{"id":"1.168237987","rc":[{"batl":[[0,95,38.77]],"ltp":5.4,"tv":0.0,"id":14833204}]}]}
{"op":"mcm","clk":"1008792048","pt":1580661638859,"mc":[{"id":"1.168237987","rc":[{"batb":[[0,1.01,10.51],[1,1.01,0]],"batl":[[0,1.08,52.73],[1,1.34,1110.09],[2,1.08,0]],"ltp":1.08,"tv":72.3,"id":13181195}]}]}
{"op":"mcm","clk":"1008792669","pt":1580661641863,"mc":[{"id":"1.168237987","rc":[{"batb":[[0,1.02,1266.38],[1,1.01,10.51]],"batl":[[0,1.06,296.64],[1,1.07,913.33],[2,1.08,52.73]],"ltp":1.08,"tv":72.3,"id":13181195}]}]}
{"op":"mcm","clk":"1008792862","pt":1580661642776,"mc":[{"id":"1.168237987","rc":[{"batl":[[0,1.08,52.73],[1,1.34,1110.09],[2,1.08,0]],"ltp":1.08,"tv":72.3,"id":13181195}]}]}
{"op":"mcm","clk":"1008793451","pt":1580661645868,"mc":[{"id":"1.168237987","rc":[{"batl":[[0,1.03,1254.08],[1,1.08,52.73],[2,1.34,1110.09]],"ltp":1.08,"tv":72.3,"id":13181195}]}]}
{"op":"mcm","clk":"1008793626","pt":1580661646639,"mc":[{"id":"1.168237987","rc":[{"batb":[[0,27,3.07],[1,18.5,6.37],[2,1.01,10.51]],"ltp":5.4,"tv":0.0,"id":14833204}]}]}
{"op":"mcm","clk":"1008794106","pt":1580661648880,"mc":[{"id":"1.168237987","rc":[{"batl":[[0,520,35.52]],"ltp":5.4,"tv":0.0,"id":14833204}]}]}
{"op":"mcm","clk":"1008798431","pt":1580661667918,"mc":[{"id":"1.168237987","rc":[{"batb":[[0,18.5,6.37],[1,1.01,10.51],[2,1.01,0]],"ltp":5.4,"tv":0.0,"id":14833204},{"batb":[[0,1.01,10.51],[1,1.01,0]],"batl":[[0,1.08,52.73],[1,1.34,1110.09],[2,1.34,0]],"ltp":1.08,"tv":72.3,"id":13181195}]}]}
{"op":"mcm","clk":"1008799004","pt":1580661670477,"mc":[{"id":"1.168237987","rc":[{"batl":[[0,1.05,1230.2],[1,1.08,52.73]],"ltp":1.08,"tv":72.3,"id":13181195}]}]}
{"op":"mcm","clk":"1008799819","pt":1580661674470,"mc":[{"id":"1.168237987","rc":[{"batl":[[0,1.08,52.73],[1,1.08,0]],"ltp":1.08,"tv":72.3,"id":13181195}]}]}
{"op":"mcm","clk":"1008800398","pt":1580661677416,"mc":[{"id":"1.168237987","rc":[{"batb":[[0,1.02,917.69],[1,1.01,362.65]],"batl":[[0,1.03,1254.08],[1,1.08,52.73]],"ltp":1.08,"tv":72.3,"id":13181195}]}]}
{"op":"mcm","clk":"1008800916","pt":1580661679994,"mc":[{"id":"1.168237987","rc":[{"batl":[[2,1.29,1276.86]],"ltp":1.08,"tv":72.3,"id":13181195}]}]}
{"op":"mcm","clk":"1008801565","pt":1580661682980,"mc":[{"id":"1.168237987","rc":[{"batb":[[0,1.01,10.51],[1,1.01,0]],"batl":[[0,1.08,52.73],[1,1.29,1276.86],[2,1.29,0]],"ltp":1.08,"tv":72.3,"id":13181195}]}]}
{"op":"mcm","clk":"1008801830","pt":1580661684385,"mc":[{"id":"1.168237987","rc":[{"batl":[[1,1.29,0]],"ltp":1.08,"tv":72.3,"id":13181195}]}]}
{"op":"mcm","clk":"1008802073","pt":1580661685468,"mc":[{"id":"1.168237987","rc":[{"batl":[[0,1.05,1230.2],[1,1.08,52.73]],"ltp":1.08,"tv":72.3,"id":13181195}]}]}
{"op":"mcm","clk":"1008802975","pt":1580661689598,"mc":[{"id":"1.168237987","rc":[{"batb":[[0,1.04,209.89],[1,1.03,1042.15],[2,1.01,10.51]],"ltp":1.08,"tv":72.3,"id":13181195}]}]}
{"op":"mcm","clk":"1008803322","pt":1580661691008,"mc":[{"id":"1.168237987","rc":[{"batb":[[1,14,5.98],[2,1.01,10.51]],"batl":[[0,65,40.66]],"ltp":5.4,"tv":0.0,"id":14833204},{"batb":[[1,1.03,1775.07]],"batl":[[2,1.32,1160.1]],"ltp":1.08,"tv":72.3,"id":13181195}]}]}
{"op":"mcm","clk":"1008807956","pt":1580661712444,"mc":[{"id":"1.168237987","rc":[{"batb":[[0,14,5.98],[1,1.01,10.51],[2,1.01,0]],"ltp":5.4,"tv":0.0,"id":14833204},{"batb":[[0,1.01,10.51],[1,1.03,0],[2,1.01,0]],"batl":[[0,1.08,52.73],[1,1.32,1160.1],[2,1.32,0]],"ltp":1.08,"tv":72.3,"id":13181195}]}]}
{"op":"mcm","clk":"1008808483","pt":1580661715020,"mc":[{"id":"1.168237987","rc":[{"batb":[[0,1.02,1266.38],[1,1.01,10.51]],"batl":[[0,1.06,312.4],[1,1.07,897.72],[2,1.08,52.73]],"ltp":1.08,"tv":72.3,"id":13181195}]}]}
{"op":"mcm","clk":"1008810385","pt":1580661724465,"mc":[{"id":"1.168237987","rc":[{"batb":[[0,1.01,10.51],[1,1.01,0]],"batl":[[0,1.08,52.73],[1,1.32,1160.1],[2,1.08,0]],"ltp":1.08,"tv":72.3,"id":13181195}]}]}
{"op":"mcm","clk":"1008811101","pt":1580661727853,"mc":[{"id":"1.168237987","rc":[{"batb":[[0,1.03,1254.08],[1,1.01,10.51]],"batl":[[0,1.04,205.61],[1,1.05,1026.54],[2,1.08,52.73]],"ltp":1.08,"tv":72.3,"id":13181195}]}]}
{"op":"mcm","clk":"1008811361","pt":1580661729258,"mc":[{"id":"1.168237987","rc":[{"batl":[[0,95,38.77]],"ltp":5.4,"tv":0.0,"id":14833204}]}]}
{"op":"mcm","clk":"1008812351","pt":1580661734184,"mc":[{"id":"1.168237987","rc":[{"batb":[[0,1.01,10.51],[1,1.01,0]],"batl":[[0,1.08,52.73],[1,1.32,1160.1],[2,1.08,0]],"ltp":1.08,"tv":72.3,"id":13181195}]}]}
{"op":"mcm","clk":"1008812938","pt":1580661737047,"mc":[{"id":"1.168237987","rc":[{"batb":[[0,1.02,1266.38],[1,1.01,10.51]],"batl":[[0,1.06,312.4],[1,1.07,897.72],[2,1.08,52.73]],"ltp":1.08,"tv":72.3,"id":13181195}]}]}
{"op":"mcm","clk":"1008817616","pt":1580661760586,"mc":[{"id":"1.168237987","rc":[{"batb":[[0,1.01,10.51],[1,1.01,0]],"ltp":1.08,"tv":72.3,"id":13181195}]}]}
{"op":"mcm","clk":"1008817728","pt":1580661761144,"mc":[{"id":"1.168237987","rc":[{"batb":[[0,1.01,10.51],[1,1.01,0]],"ltp":5.4,"tv":0.0,"id":14833204}]}]}
{"op":"mcm","clk":"1008818036","pt":1580661762778,"mc":[{"id":"1.168237987","rc":[{"batl":[[0,1.08,52.73],[1,1.32,1160.1],[2,1.08,0]],"ltp":1.08,"tv":72.3,"id":13181195}]}]}
{"op":"mcm","clk":"1008818268","pt":1580661763957,"mc":[{"id":"1.168237987","rc":[{"batb":[[0,13.5,6.29],[1,11,10.23],[2,1.01,10.51]],"ltp":5.4,"tv":0.0,"id":14833204},{"batb":[[0,1.04,484.37],[1,1.03,703.42],[2,1.01,10.51]],"ltp":1.08,"tv":72.3,"id":13181195}]}]}
{"op":"mcm","clk":"1008818859","pt":1580661767005,"mc":[{"id":"1.168237987","rc":[{"batl":[[0,42,43.67]],"ltp":5.4,"tv":0.0,"id":14833204}]}]}
{"op":"mcm","clk":"1008818972","pt":1580661767599,"mc":[{"id":"1.168237987","rc":[{"batb":[[0,11,10.23],[1,1.01,10.51],[2,1.01,0]],"ltp":5.4,"tv":0.0,"id":14833204},{"batb":[[0,1.03,703.42],[1,1.01,10.51],[2,1.01,0]],"ltp":1.08,"tv":72.3,"id":13181195}]}]}
{"op":"mcm","clk":"1008820359","pt":1580661774974,"mc":[{"id":"1.168237987","rc":[{"batb":[[0,1.05,1230.2],[1,1.03,703.42],[2,1.01,10.51]],"batl":[[0,1.06,312.4],[1,1.07,897.72],[2,1.08,52.73]],"ltp":1.08,"tv":72.3,"id":13181195}]}]}
{"op":"mcm","clk":"1008820567","pt":1580661775973,"mc":[{"id":"1.168237987","rc":[{"batb":[[1,1.04,2470.37],[2,1.03,703.42]],"ltp":1.08,"tv":72.3,"id":13181195}]}]}
{"op":"mcm","clk":"1008820660","pt":1580661776405,"mc":[{"id":"1.168237987","rc":[{"batb":[[1,1.03,703.42],[2,1.01,10.51]],"ltp":1.08,"tv":72.3,"id":13181195}]}]}
{"op":"mcm","clk":"1008823414","pt":1580661789932,"mc":[{"id":"1.168237987","rc":[{"batb":[[0,1.03,703.42],[1,1.01,10.51],[2,1.01,0]],"batl":[[0,1.08,52.73],[1,1.32,1160.1],[2,1.08,0]],"ltp":1.08,"tv":72.3,"id":13181195}]}]}
{"op":"mcm","clk":"1008823933","pt":1580661792550,"mc":[{"id":"1.168237987","rc":[{"batb":[[0,1.04,216.24],[1,1.03,1739.16],[2,1.01,10.51]],"batl":[[0,1.08,1109.78]],"ltp":1.08,"tv":72.3,"id":13181195}]}]}
{"op":"mcm","clk":"1008824738","pt":1580661796507,"mc":[{"id":"1.168237987","rc":[{"batb":[[0,1.03,703.42],[1,1.01,10.51],[2,1.01,0]],"ltp":1.08,"tv":72.3,"id":13181195}]}]}
{"op":"mcm","clk":"1008825242","pt":1580661799044,"mc":[{"id":"1.168237987","rc":[{"batb":[[0,1.06,1218.66],[1,1.03,703.42],[2,1.01,10.51]],"ltp":1.08,"tv":72.3,"id":13181195}]}]}
{"op":"mcm","clk":"1008825415","pt":1580661799796,"mc":[{"id":"1.168237987","rc":[{"batb":[[1,8.4,8.03],[2,1.01,10.51]],"ltp":5.4,"tv":0.0,"id":14833204},{"batb":[[0,1.06,1585.4],[1,1.04,491.05]],"batl":[[0,1.08,1068.19]],"ltp":1.08,"tv":72.3,"id":13181195}]}]}
{"op":"mcm","clk":"1008825774","pt":1580661801523,"mc":[{"id":"1.168237987","rc":[{"batl":[[0,30,47.14]],"ltp":5.4,"tv":0.0,"id":14833204}]}]}
{"op":"mcm","clk":"1008825924","pt":1580661802323,"mc":[{"id":"1.168237987","rc":[{"batl":[[1,1.09,178.97],[2,1.32,1160.1]],"ltp":1.08,"tv":72.3,"id":13181195}]}]}
{"op":"mcm","clk":"1008826441","pt":1580661804943,"mc":[{"id":"1.168237987","rc":[{"batb":[[0,1.06,3176.98]],"ltp":1.08,"tv":72.3,"id":13181195}]}]}
{"op":"mcm","clk":"1008827404","pt":1580661809460,"mc":[{"id":"1.168237987","rc":[{"batl":[[0,1.08,1028]],"ltp":1.08,"tv":72.3,"id":13181195}]}]}
{"op":"mcm","clk":"1008828060","pt":1580661812347,"mc":[{"id":"1.168237987","rc":[{"batl":[[1,1.09,218.79]],"ltp":1.08,"tv":72.3,"id":13181195}]}]}
{"op":"mcm","clk":"1008832682","pt":1580661834678,"mc":[{"id":"1.168237987","rc":[{"batb":[[0,8.4,8.03],[1,1.01,10.51],[2,1.01,0]],"ltp":5.4,"tv":0.0,"id":14833204},{"batb":[[0,1.04,491.05],[1,1.01,10.51],[2,1.01,0]],"batl":[[0,1.08,52.73],[1,1.32,1160.1],[2,1.32,0]],"ltp":1.08,"tv":72.3,"id":13181195}]}]}
{"op":"mcm","clk":"1008833165","pt":1580661837174,"mc":[{"id":"1.168237987","rc":[{"batb":[[0,1.05,1067.97],[1,1.04,491.05],[2,1.01,10.51]],"batl":[[1,1.11,387.62],[2,1.12,769.21]],"ltp":1.08,"tv":72.3,"id":13181195}]}]}
{"op":"mcm","clk":"1008833391","pt":1580661838271,"mc":[{"id":"1.168237987","rc":[{"batb":[[0,1.04,491.05],[1,1.01,10.51],[2,1.01,0]],"batl":[[1,1.32,1160.1],[2,1.12,0]],"ltp":1.08,"tv":72.3,"id":13181195}]}]}
{"op":"mcm","clk":"1008834087","pt":1580661841660,"mc":[{"id":"1.168237987","rc":[{"batb":[[0,1.07,1058.24],[1,1.04,491.05],[2,1.01,10.51]],"batl":[[1,1.09,1185.11],[2,1.32,1160.1]],"ltp":1.08,"tv":72.3,"id":13181195}]}]}
{"op":"mcm","clk":"1008834777","pt":1580661844996,"mc":[{"id":"1.168237987","rc":[{"batb":[[0,1.04,491.05],[1,1.01,10.51],[2,1.01,0]],"batl":[[1,1.32,1160.1],[2,1.32,0]],"ltp":1.08,"tv":72.3,"id":13181195}]}]}
{"op":"mcm","clk":"1008835381","pt":1580661847895,"mc":[{"id":"1.168237987","rc":[{"batb":[[0,1.05,1067.97],[1,1.04,491.05],[2,1.01,10.51]],"batl":[[1,1.11,387.62],[2,1.12,769.21]],"ltp":1.08,"tv":72.3,"id":13181195}]}]}
{"op":"mcm","clk":"1008835567","pt":1580661848662,"mc":[{"id":"1.168237987","rc":[{"batb":[[0,1.05,958.51],[1,1.04,765.41]],"batl":[[1,1.11,491.41],[2,1.12,666.35]],"ltp":1.08,"tv":72.3,"id":13181195}]}]}
{"op":"mcm","clk":"1008835751","pt":1580661849588,"mc":[{"id":"1.168237987","rc":[{"batl":[[1,1.32,1160.1],[2,1.12,0]],"ltp":1.08,"tv":72.3,"id":13181195}]}]}
{"op":"mcm","clk":"1008836493","pt":1580661852969,"mc":[{"id":"1.168237987","rc":[{"batb":[[0,14,6.14],[1,10.5,12.2],[2,8.4,8.03]],"ltp":5.4,"tv":0.0,"id":14833204},{"batb":[[2,1.03,667.3]],"batl":[[0,1.06,714.58],[1,1.07,499.36],[2,1.08,52.73]],"ltp":1.08,"tv":72.3,"id":13181195}]}]}
{"op":"mcm","clk":"1008836538","pt":1580661853185,"mc":[{"id":"1.168237987","rc":[{"batb":[[2,1.01,10.51]],"ltp":5.4,"tv":0.0,"id":14833204}]}]}
{"op":"mcm","clk":"1008837072","pt":1580661855696,"mc":[{"id":"1.168237987","rc":[{"batl":[[0,42,43.67]],"ltp":5.4,"tv":0.0,"id":14833204}]}]}
{"op":"mcm","clk":"1008840242","pt":1580661870397,"mc":[{"id":"1.168237987","rc":[{"batb":[[0,10.5,12.2],[1,1.01,10.51],[2,1.01,0]],"ltp":5.4,"tv":0.0,"id":14833204},{"batb":[[0,1.04,274.36],[1,1.03,667.3],[2,1.01,10.51]],"batl":[[0,1.08,52.73],[1,1.32,1160.1],[2,1.08,0]],"ltp":1.08,"tv":72.3,"id":13181195}]}]}
{"op":"mcm","clk":"1008840838","pt":1580661873018,"mc":[{"id":"1.168237987","rc":[{"batb":[[0,1.04,848.36],[1,1.03,1064.86]],"batl":[[1,1.09,1185.11],[2,1.32,1160.1]],"ltp":1.08,"tv":72.3,"id":13181195}]}]}
{"op":"mcm","clk":"1008841302","pt":1580661875316,"mc":[{"id":"1.168237987","rc":[{"batl":[[1,1.32,1160.1],[2,1.32,0]],"ltp":1.08,"tv":72.3,"id":13181195}]}]}
{"op":"mcm","clk":"1008842040","pt":1580661878845,"mc":[{"id":"1.168237987","rc":[{"batb":[[0,17,7.47],[1,13.5,6.69],[2,10.5,12.2]],"ltp":5.4,"tv":0.0,"id":14833204},{"batb":[[2,1.02,841.11]],"batl":[[0,1.05,1230.26],[1,1.08,52.73],[2,1.32,1160.1]],"ltp":1.08,"tv":72.3,"id":13181195}]}]}
{"op":"mcm","clk":"1008842226","pt":1580661879724,"mc":[{"id":"1.168237987","rc":[{"batb":[[2,1.01,10.51]],"ltp":5.4,"tv":0.0,"id":14833204}]}]}
{"op":"mcm","clk":"1008842487","pt":1580661880922,"mc":[{"id":"1.168237987","rc":[{"batl":[[0,65,40.66]],"ltp":5.4,"tv":0.0,"id":14833204}]}]}
{"op":"mcm","clk":"1008845627","pt":1580661895770,"mc":[{"id":"1.168237987","rc":[{"batb":[[0,13.5,6.69],[1,1.01,10.51],[2,1.01,0]],"ltp":5.4,"tv":0.0,"id":14833204},{"batb":[[0,1.03,397.56],[1,1.02,841.11],[2,1.01,10.51]],"batl":[[0,1.08,52.73],[1,1.32,1160.1],[2,1.32,0]],"ltp":1.08,"tv":72.3,"id":13181195}]}]}
{"op":"mcm","clk":"1008846160","pt":1580661898332,"mc":[{"id":"1.168237987","rc":[{"batb":[[0,1.03,1254.15]],"batl":[[0,1.06,278.55],[1,1.07,931.31],[2,1.08,52.73]],"ltp":1.08,"tv":72.3,"id":13181195}]}]}
{"op":"mcm","clk":"1008847582","pt":1580661904954,"mc":[{"id":"1.168237987","rc":[{"batb":[[0,1.02,841.11],[1,1.01,10.51],[2,1.01,0]],"ltp":1.08,"tv":72.3,"id":13181195}]}]}
{"op":"mcm","clk":"1008848224","pt":1580661907960,"mc":[{"id":"1.168237987","rc":[{"batb":[[0,1.05,1230.26],[1,1.02,841.11],[2,1.01,10.51]],"ltp":1.08,"tv":72.3,"id":13181195}]}]}
{"op":"mcm","clk":"1008848357","pt":1580661908550,"mc":[{"id":"1.168237987","rc":[{"batb":[[1,9.6,14.4],[2,1.01,10.51]],"ltp":5.4,"tv":0.0,"id":14833204},{"batb":[[0,1.05,1697.32],[1,1.03,663.21]],"ltp":1.08,"tv":72.3,"id":13181195}]}]}
{"op":"mcm","clk":"1008848929","pt":1580661911364,"mc":[{"id":"1.168237987","rc":[{"batl":[[0,42,43.67]],"ltp":5.4,"tv":0.0,"id":14833204}]}]}
{"op":"mcm","clk":"1008853276","pt":1580661932769,"mc":[{"id":"1.168237987","rc":[{"batb":[[0,9.6,14.4],[1,1.01,10.51],[2,1.01,0]],"ltp":5.4,"tv":0.0,"id":14833204},{"batb":[[0,1.03,663.21],[1,1.01,10.51],[2,1.01,0]],"batl":[[0,1.08,52.73],[1,1.32,1160.1],[2,1.08,0]],"ltp":1.08,"tv":72.3,"id":13181195}]}]}
{"op":"mcm","clk":"1008853810","pt":1580661935403,"mc":[{"id":"1.168237987","rc":[{"batb":[[0,1.04,588.85],[1,1.03,1322.79],[2,1.01,10.51]],"batl":[[1,1.09,299.93],[2,1.1,877.14]],"ltp":1.08,"tv":72.3,"id":13181195}]}]}
{"op":"mcm","clk":"1008855273","pt":1580661942597,"mc":[{"id":"1.168237987","rc":[{"batl":[[1,1.32,1160.1],[2,1.1,0]],"ltp":1.08,"tv":72.3,"id":13181195}]}]}
{"op":"mcm","clk":"1008855908","pt":1580661945797,"mc":[{"id":"1.168237987","rc":[{"batl":[[0,1.05,1230.26],[1,1.08,52.73],[2,1.32,1160.1]],"ltp":1.08,"tv":72.3,"id":13181195}]}]}
{"op":"mcm","clk":"1008856141","pt":1580661947025,"mc":[{"id":"1.168237987","rc":[{"batb":[[0,17,7.55],[1,13.5,6.45],[2,1.01,10.51]],"ltp":5.4,"tv":0.0,"id":14833204},{"batb":[[2,1.02,855.19]],"ltp":1.08,"tv":72.3,"id":13181195}]}]}
{"op":"mcm","clk":"1008856354","pt":1580661948095,"mc":[{"id":"1.168237987","rc":[{"batl":[[0,65,40.66]],"ltp":5.4,"tv":0.0,"id":14833204}]}]}
{"op":"mcm","clk":"1008860208","pt":1580661967021,"mc":[{"id":"1.168237987","rc":[{"batb":[[0,1.03,1322.79],[1,1.02,855.19],[2,1.01,10.51]],"batl":[[0,1.08,52.73],[1,1.32,1160.1],[2,1.32,0]],"ltp":1.08,"tv":72.3,"id":13181195}]}]}
{"op":"mcm","clk":"1008860321","pt":1580661967540,"mc":[{"id":"1.168237987","rc":[{"batb":[[0,13.5,6.45],[1,1.01,10.51],[2,1.01,0]],"ltp":5.4,"tv":0.0,"id":14833204},{"batb":[[0,1.03,659.58]],"ltp":1.08,"tv":72.3,"id":13181195}]}]}
{"op":"mcm","clk":"1008860835","pt":1580661969928,"mc":[{"id":"1.168237987","rc":[{"batb":[[0,1.03,1254.15]],"batl":[[0,1.06,586.94],[1,1.07,625.81],[2,1.08,52.73]],"ltp":1.08,"tv":72.3,"id":13181195}]}]}
{"op":"mcm","clk":"1008861029","pt":1580661970661,"mc":[{"id":"1.168237987","rc":[{"batb":[[0,1.02,855.19],[1,1.01,10.51],[2,1.01,0]],"batl":[[0,1.06,375.04],[1,1.08,52.73],[2,1.32,1160.1]],"ltp":1.08,"tv":72.3,"id":13181195}]}]}
{"op":"mcm","clk":"1008861652","pt":1580661973828,"mc":[{"id":"1.168237987","rc":[{"batb":[[0,1.04,1242.09],[1,1.02,855.19],[2,1.01,10.51]],"batl":[[0,1.05,851.64],[1,1.06,375.04],[2,1.08,52.73]],"ltp":1.08,"tv":72.3,"id":13181195}]}]}
{"op":"mcm","clk":"1008862564","pt":1580661978478,"mc":[{"id":"1.168237987","rc":[{"batb":[[0,1.02,855.19],[1,1.01,10.51],[2,1.01,0]],"batl":[[0,1.06,375.04],[1,1.08,52.73],[2,1.32,1160.1]],"ltp":1.08,"tv":72.3,"id":13181195}]}]}
{"op":"mcm","clk":"1008863159","pt":1580661981465,"mc":[{"id":"1.168237987","rc":[{"batb":[[0,1.03,1254.15],[1,1.02,855.19],[2,1.01,10.51]],"batl":[[0,1.06,586.94],[1,1.07,625.81],[2,1.08,52.73]],"ltp":1.08,"tv":72.3,"id":13181195}]}]}
{"op":"mcm","clk":"1008864879","pt":1580661990287,"mc":[{"id":"1.168237987","rc":[{"batb":[[0,1.02,855.19],[1,1.01,10.51],[2,1.01,0]],"ltp":1.08,"tv":72.3,"id":13181195}]}]}
{"op":"mcm","clk":"1008865638","pt":1580661993954,"mc":[{"id":"1.168237987","rc":[{"batb":[[1,9.2,16.29],[2,1.01,10.51]],"ltp":5.4,"tv":0.0,"id":14833204},{"batb":[[0,1.05,1590.6],[1,1.03,750.86],[2,1.02,855.19]],"ltp":1.08,"tv":72.3,"id":13181195}]}]}
{"op":"mcm","clk":"1008865661","pt":1580661994057,"mc":[{"id":"1.168237987","rc":[{"batb":[[2,1.01,10.51]],"ltp":1.08,"tv":72.3,"id":13181195}]}]}
{"op":"mcm","clk":"1008866155","pt":1580661996575,"mc":[{"id":"1.168237987","rc":[{"batl":[[0,42,43.67]],"ltp":5.4,"tv":0.0,"id":14833204}]}]}
{"op":"mcm","clk":"1008869312","pt":1580662013003,"mc":[{"id":"1.168237987","rc":[{"batl":[[0,1.06,544.19]],"ltp":1.08,"tv":72.3,"id":13181195}]}]}
{"op":"mcm","clk":"1008869935","pt":1580662015953,"mc":[{"id":"1.168237987","rc":[{"batb":[[0,1.05,1633.99]],"batl":[[1,1.07,668.16]],"ltp":1.08,"tv":72.3,"id":13181195}]}]}
{"op":"mcm","clk":"1008870488","pt":1580662018803,"mc":[{"id":"1.168237987","rc":[{"batb":[[0,9.2,16.29],[1,1.01,10.51],[2,1.01,0]],"ltp":5.4,"tv":0.0,"id":14833204},{"batb":[[0,1.03,750.86],[1,1.01,10.51],[2,1.01,0]],"batl":[[0,1.08,52.73],[1,1.32,1160.1],[2,1.08,0]],"ltp":1.08,"tv":72.3,"id":13181195}]}]}
{"op":"mcm","clk":"1008870977","pt":1580662021320,"mc":[{"id":"1.168237987","rc":[{"batb":[[0,1.03,2005.01]],"batl":[[1,1.1,1000.84],[2,1.32,1160.1]],"ltp":1.08,"tv":72.3,"id":13181195}]}]}
{"op":"mcm","clk":"1008872583","pt":1580662029914,"mc":[{"id":"1.168237987","rc":[{"batl":[[1,1.32,1160.1],[2,1.32,0]],"ltp":1.08,"tv":72.3,"id":13181195}]}]}
{"op":"mcm","clk":"1008873196","pt":1580662032932,"mc":[{"id":"1.168237987","rc":[{"batl":[[0,1.05,1230.04],[1,1.08,52.73],[2,1.32,1160.1]],"ltp":1.08,"tv":72.3,"id":13181195}]}]}
{"op":"mcm","clk":"1008873416","pt":1580662033804,"mc":[{"id":"1.168237987","rc":[{"batb":[[0,18.5,6.14],[1,15.5,4.8],[2,1.01,10.51]],"ltp":5.4,"tv":0.0,"id":14833204}]}]}
{"op":"mcm","clk":"1008873923","pt":1580662036676,"mc":[{"id":"1.168237987","rc":[{"batl":[[0,95,38.77]],"ltp":5.4,"tv":0.0,"id":14833204}]}]}
{"op":"mcm","clk":"1008876741","pt":1580662052523,"mc":[{"id":"1.168237987","rc":[{"batl":[[0,1.05,1611.14]],"ltp":1.08,"tv":72.3,"id":13181195}]}]}
{"op":"mcm","clk":"1008878512","pt":1580662063110,"mc":[{"id":"1.168237987","rc":[{"batb":[[0,1.03,3547.5]],"ltp":1.08,"tv":72.3,"id":13181195}]}]}
{"op":"mcm","clk":"1008888903","pt":1580662127020,"mc":[{"id":"1.168237987","rc":[{"batb":[[0,1.03,750.86]],"batl":[[0,1.08,52.73],[1,1.32,1160.1],[2,1.32,0]],"ltp":1.08,"tv":72.3,"id":13181195}]}]}
{"op":"mcm","clk":"1008888922","pt":1580662127126,"mc":[{"id":"1.168237987","rc":[{"batb":[[0,15.5,4.8],[1,1.01,10.51],[2,1.01,0]],"ltp":5.4,"tv":0.0,"id":14833204},{"batb":[[0,1.01,10.51],[1,1.01,0]],"ltp":1.08,"tv":72.3,"id":13181195}]}]}
{"op":"mcm","clk":"1008889877","pt":1580662132915,"mc":[{"id":"1.168237987","rc":[{"batb":[[0,1.03,1253.92],[1,1.01,10.51]],"batl":[[0,1.04,645.84],[1,1.05,590.35],[2,1.08,52.73]],"ltp":1.08,"tv":72.3,"id":13181195}]}]}
{"op":"mcm","clk":"1008890618","pt":1580662137918,"mc":[{"id":"1.168237987","rc":[{"batb":[[0,1.01,10.51],[1,1.01,0]],"batl":[[0,1.08,52.73],[1,1.32,1160.1],[2,1.08,0]],"ltp":1.08,"tv":72.3,"id":13181195}]}]}
{"op":"mcm","clk":"1008891066","pt":1580662140808,"mc":[{"id":"1.168237987","rc":[{"batb":[[0,1.02,1266.21],[1,1.01,10.51]],"batl":[[0,1.06,1218.43],[1,1.08,52.73],[2,1.32,1160.1]],"ltp":1.08,"tv":72.3,"id":13181195}]}]}
{"op":"mcm","clk":"1008891608","pt":1580662144025,"mc":[{"id":"1.168237987","rc":[{"batb":[[0,1.01,10.51],[1,1.01,0]],"ltp":1.08,"tv":72.3,"id":13181195}]}]}
{"op":"mcm","clk":"1008892052","pt":1580662147018,"mc":[{"id":"1.168237987","rc":[{"batb":[[0,1.04,1241.87],[1,1.01,10.51]],"ltp":1.08,"tv":72.3,"id":13181195}]}]}
{"op":"mcm","clk":"1008892153","pt":1580662147715,"mc":[{"id":"1.168237987","rc":[{"batb":[[1,13,7.08],[2,1.01,10.51]],"ltp":5.4,"tv":0.0,"id":14833204},{"batb":[[0,1.04,1809.25],[1,1.02,762.35],[2,1.01,10.51]],"ltp":1.08,"tv":72.3,"id":13181195}]}]}
{"op":"mcm","clk":"1008892563","pt":1580662150142,"mc":[{"id":"1.168237987","rc":[{"batl":[[0,65,40.66]],"ltp":5.4,"tv":0.0,"id":14833204}]}]}
{"op":"mcm","clk":"1008894617","pt":1580662163036,"mc":[{"id":"1.168237987","rc":[{"batb":[[0,13,7.08],[1,1.01,10.51],[2,1.01,0]],"ltp":5.4,"tv":0.0,"id":14833204},{"batb":[[0,1.02,762.35],[1,1.01,10.51],[2,1.01,0]],"batl":[[0,1.08,52.73],[1,1.32,1160.1],[2,1.32,0]],"ltp":1.08,"tv":72.3,"id":13181195}]}]}
{"op":"mcm","clk":"1008894951","pt":1580662165348,"mc":[{"id":"1.168237987","rc":[{"batb":[[0,1.03,1253.92],[1,1.02,762.35],[2,1.01,10.51]],"batl":[[0,1.07,1207.05],[1,1.08,52.73],[2,1.32,1160.1]],"ltp":1.08,"tv":72.3,"id":13181195}]}]}
{"op":"mcm","clk":"1008895250","pt":1580662167251,"mc":[{"id":"1.168237987","rc":[{"batb":[[0,1.02,762.35],[1,1.01,10.51],[2,1.01,0]],"batl":[[0,1.08,52.73],[1,1.32,1160.1],[2,1.32,0]],"ltp":1.08,"tv":72.3,"id":13181195}]}]}
{"op":"mcm","clk":"1008895776","pt":1580662170764,"mc":[{"id":"1.168237987","rc":[{"batb":[[0,1.04,1241.87],[1,1.02,762.35],[2,1.01,10.51]],"batl":[[0,1.05,490.34],[1,1.06,732.71],[2,1.08,52.73]],"ltp":1.08,"tv":72.3,"id":13181195}]}]}
{"op":"mcm","clk":"1008896212","pt":1580662173768,"mc":[{"id":"1.168237987","rc":[{"batb":[[0,1.02,762.35],[1,1.01,10.51],[2,1.01,0]],"batl":[[0,1.08,52.73],[1,1.32,1160.1],[2,1.08,0]],"ltp":1.08,"tv":72.3,"id":13181195}]}]}
{"op":"mcm","clk":"1008896652","pt":1580662176945,"mc":[{"id":"1.168237987","rc":[{"batb":[[0,1.03,1253.92],[1,1.02,762.35],[2,1.01,10.51]],"batl":[[0,1.07,1207.05],[1,1.08,52.73],[2,1.32,1160.1]],"ltp":1.08,"tv":72.3,"id":13181195}]}]}
{"op":"mcm","clk":"1008896755","pt":1580662177739,"mc":[{"id":"1.168237987","rc":[{"batb":[[0,1.02,762.35],[1,1.01,10.51],[2,1.01,0]],"ltp":1.08,"tv":72.3,"id":13181195}]}]}
{"op":"mcm","clk":"1008897229","pt":1580662180967,"mc":[{"id":"1.168237987","rc":[{"batb":[[1,11.5,9.52],[2,1.01,10.51]],"ltp":5.4,"tv":0.0,"id":14833204},{"batb":[[0,1.05,1682.93],[1,1.04,556.28],[2,1.01,10.51]],"ltp":1.08,"tv":72.3,"id":13181195}]}]}
{"op":"mcm","clk":"1008897561","pt":1580662183286,"mc":[{"id":"1.168237987","rc":[{"batl":[[0,42,43.67]],"ltp":5.4,"tv":0.0,"id":14833204}]}]}
{"op":"mcm","clk":"1008899934","pt":1580662198657,"mc":[{"id":"1.168237987","rc":[{"batb":[[0,11.5,9.52],[1,1.01,10.51],[2,1.01,0]],"ltp":5.4,"tv":0.0,"id":14833204},{"batb":[[0,1.04,556.28],[1,1.01,10.51],[2,1.01,0]],"batl":[[0,1.07,478.44]],"ltp":1.08,"tv":72.3,"id":13181195}]}]}
{"op":"mcm","clk":"1008900435","pt":1580662201939,"mc":[{"id":"1.168237987","rc":[{"batb":[[0,1.04,1798.15]],"batl":[[1,1.08,774.58]],"ltp":1.08,"tv":72.3,"id":13181195}]}]}
{"op":"mcm","clk":"1008900585","pt":1580662202846,"mc":[{"id":"1.168237987","rc":[{"batb":[[0,1.04,556.28]],"batl":[[1,1.08,52.73]],"ltp":1.08,"tv":72.3,"id":13181195}]}]}
{"op":"mcm","clk":"1008900915","pt":1580662204961,"mc":[{"id":"1.168237987","rc":[{"batb":[[0,1.05,1230.04],[1,1.04,556.28],[2,1.01,10.51]],"batl":[[0,1.06,422.61],[1,1.07,788.38],[2,1.08,52.73]],"ltp":1.08,"tv":72.3,"id":13181195}]}]}
{"op":"mcm","clk":"1008901988","pt":1580662211928,"mc":[{"id":"1.168237987","rc":[{"batb":[[0,1.04,556.28],[1,1.01,10.51],[2,1.01,0]],"batl":[[0,1.07,500.31],[1,1.08,52.73],[2,1.32,1160.1]],"ltp":1.08,"tv":72.3,"id":13181195}]}]}
{"op":"mcm","clk":"1008902451","pt":1580662214681,"mc":[{"id":"1.168237987","rc":[{"batb":[[0,1.04,1798.15]],"batl":[[1,1.08,752.92]],"ltp":1.08,"tv":72.3,"id":13181195}]}]}
{"op":"mcm","clk":"1008902907","pt":1580662217551,"mc":[{"id":"1.168237987","rc":[{"batl":[[0,1.08,52.73],[1,1.32,1160.1],[2,1.32,0]],"ltp":1.08,"tv":72.3,"id":13181195}]}]}
{"op":"mcm","clk":"1008903381","pt":1580662220972,"mc":[{"id":"1.168237987","rc":[{"batl":[[0,1.06,1218.43],[1,1.07,374.36],[2,1.08,52.73]],"ltp":1.08,"tv":72.3,"id":13181195}]}]}
{"op":"mcm","clk":"1008903520","pt":1580662221982,"mc":[{"id":"1.168237987","rc":[{"batb":[[0,15,4.96],[1,12.5,7.63],[2,1.01,10.51]],"ltp":5.4,"tv":0.0,"id":14833204},{"batb":[[1,1.02,787.84],[2,1.01,10.51]],"batl":[[1,1.08,52.73],[2,1.32,1160.1]],"ltp":1.08,"tv":72.3,"id":13181195}]}]}
{"op":"mcm","clk":"1008903987","pt":1580662224892,"mc":[{"id":"1.168237987","rc":[{"batl":[[0,65,40.66]],"ltp":5.4,"tv":0.0,"id":14833204}]}]}
{"op":"mcm","clk":"1008906583","pt":1580662240684,"mc":[{"id":"1.168237987","rc":[{"batb":[[0,12.5,7.63],[1,1.01,10.51],[2,1.01,0]],"ltp":5.4,"tv":0.0,"id":14833204},{"batb":[[0,1.02,787.84],[1,1.01,10.51],[2,1.01,0]],"batl":[[0,1.08,52.73],[1,1.32,1160.1],[2,1.32,0]],"ltp":1.08,"tv":72.3,"id":13181195}]}]}
{"op":"mcm","clk":"1008907606","pt":1580662246994,"mc":[{"id":"1.168237987","rc":[{"batb":[[0,1.04,1241.87],[1,1.02,787.84],[2,1.01,10.51]],"batl":[[0,1.05,406.62],[1,1.06,815.64],[2,1.08,52.73]],"ltp":1.08,"tv":72.3,"id":13181195}]}]}
{"op":"mcm","clk":"1008908157","pt":1580662250931,"mc":[{"id":"1.168237987","rc":[{"batb":[[0,1.02,787.84],[1,1.01,10.51],[2,1.01,0]],"batl":[[0,1.08,52.73],[1,1.32,1160.1],[2,1.08,0]],"ltp":1.08,"tv":72.3,"id":13181195}]}]}
{"op":"mcm","clk":"1008908586","pt":1580662253819,"mc":[{"id":"1.168237987","rc":[{"batb":[[0,1.03,1253.92],[1,1.02,787.84],[2,1.01,10.51]],"batl":[[0,1.07,1207.05],[1,1.08,52.73],[2,1.32,1160.1]],"ltp":1.08,"tv":72.3,"id":13181195}]}]}
{"op":"mcm","clk":"1008908962","pt":1580662256618,"mc":[{"id":"1.168237987","rc":[{"batb":[[0,1.02,787.84],[1,1.01,10.51],[2,1.01,0]],"ltp":1.08,"tv":72.3,"id":13181195}]}]}
{"op":"mcm","clk":"1008909448","pt":1580662259918,"mc":[{"id":"1.168237987","rc":[{"batb":[[0,1.05,1230.04],[1,1.02,787.84],[2,1.01,10.51]],"ltp":1.08,"tv":72.3,"id":13181195}]}]}
{"op":"mcm","clk":"1008909538","pt":1580662260438,"mc":[{"id":"1.168237987","rc":[{"batb":[[1,11,10.15],[2,1.01,10.51]],"ltp":5.4,"tv":0.0,"id":14833204},{"batb":[[0,1.05,1664.44],[1,1.04,531.18]],"ltp":1.08,"tv":72.3,"id":13181195}]}]}
{"op":"mcm","clk":"1008909889","pt":1580662263024,"mc":[{"id":"1.168237987","rc":[{"batl":[[0,42,43.67]],"ltp":5.4,"tv":0.0,"id":14833204}]}]}
{"op":"mcm","clk":"1008910292","pt":1580662265756,"mc":[{"id":"1.168237987","rc":[{"batb":[[0,1.05,3566.73]],"ltp":1.08,"tv":72.3,"id":13181195}]}]}
{"op":"mcm","clk":"1008912335","pt":1580662279836,"mc":[{"id":"1.168237987","rc":[{"batb":[[0,11,10.15],[1,1.01,10.51],[2,1.01,0]],"ltp":5.4,"tv":0.0,"id":14833204},{"batb":[[0,1.05,184.51]],"batl":[[0,1.08,52.73],[1,1.32,1160.1],[2,1.32,0]],"ltp":1.08,"tv":72.3,"id":13181195}]}]}
{"op":"mcm","clk":"1008912686","pt":1580662282458,"mc":[{"id":"1.168237987","rc":[{"batb":[[1,1.04,1586.75]],"batl":[[0,1.08,1248.6]],"ltp":1.08,"tv":72.3,"id":13181195}]}]}
{"op":"mcm","clk":"1008913229","pt":1580662286441,"mc":[{"id":"1.168237987","rc":[{"batl":[[0,1.08,52.73]],"ltp":1.08,"tv":72.3,"id":13181195}]}]}
{"op":"mcm","clk":"1008913679","pt":1580662289851,"mc":[{"id":"1.168237987","rc":[{"batl":[[0,1.06,1218.43],[1,1.08,52.73],[2,1.32,1160.1]],"ltp":1.08,"tv":72.3,"id":13181195}]}]}
{"op":"mcm","clk":"1008913735","pt":1580662290371,"mc":[{"id":"1.168237987","rc":[{"batb":[[0,14.5,5.35],[1,12,8.97],[2,1.01,10.51]],"ltp":5.4,"tv":0.0,"id":14833204},{"batb":[[2,1.02,787.13]],"ltp":1.08,"tv":72.3,"id":13181195}]}]}
{"op":"mcm","clk":"1008914011","pt":1580662292470,"mc":[{"id":"1.168237987","rc":[{"batl":[[0,65,40.66]],"ltp":5.4,"tv":0.0,"id":14833204}]}]}
{"op":"mcm","clk":"1008915856","pt":1580662307680,"mc":[{"id":"1.168237987","rc":[{"batb":[[0,12,8.97],[1,1.01,10.51],[2,1.01,0]],"ltp":5.4,"tv":0.0,"id":14833204},{"batb":[[0,1.02,787.13],[1,1.01,10.51],[2,1.02,0]],"batl":[[0,1.08,52.73],[1,1.32,1160.1],[2,1.32,0]],"ltp":1.08,"tv":72.3,"id":13181195}]}]}
{"op":"mcm","clk":"1008916146","pt":1580662310160,"mc":[{"id":"1.168237987","rc":[{"batb":[[0,1.03,1253.92],[1,1.02,787.13],[2,1.01,10.51]],"batl":[[0,1.07,580.41],[1,1.08,673.56],[2,1.32,1160.1]],"ltp":1.08,"tv":72.3,"id":13181195}]}]}
{"op":"mcm","clk":"1008916645","pt":1580662313774,"mc":[{"id":"1.168237987","rc":[{"batl":[[0,1.08,52.73],[1,1.32,1160.1],[2,1.32,0]],"ltp":1.08,"tv":72.3,"id":13181195}]}]}
{"op":"mcm","clk":"1008917092","pt":1580662317002,"mc":[{"id":"1.168237987","rc":[{"batl":[[0,1.04,529.9],[1,1.05,705.18],[2,1.08,52.73]],"ltp":1.08,"tv":72.3,"id":13181195}]}]}
{"op":"mcm","clk":"1008917165","pt":1580662317522,"mc":[{"id":"1.168237987","rc":[{"batb":[[0,19.5,5.67],[1,14.5,5.43],[2,1.01,10.51]],"ltp":5.4,"tv":0.0,"id":14833204}]}]}
{"op":"mcm","clk":"1008917701","pt":1580662320827,"mc":[{"id":"1.168237987","rc":[{"batl":[[0,95,38.77]],"ltp":5.4,"tv":0.0,"id":14833204}]}]}
{"op":"mcm","clk":"1008919892","pt":1580662337021,"mc":[{"id":"1.168237987","rc":[{"batb":[[0,1.02,787.13],[1,1.01,10.51],[2,1.01,0]],"batl":[[0,1.08,52.73],[1,1.32,1160.1],[2,1.08,0]],"ltp":1.08,"tv":72.3,"id":13181195}]}]}
{"op":"mcm","clk":"1008919944","pt":1580662337286,"mc":[{"id":"1.168237987","rc":[{"batb":[[0,14.5,5.43],[1,1.01,10.51],[2,1.01,0]],"ltp":5.4,"tv":0.0,"id":14833204},{"batb":[[0,1.01,10.51],[1,1.01,0]],"ltp":1.08,"tv":72.3,"id":13181195}]}]}
{"op":"mcm","clk":"1008920307","pt":1580662339812,"mc":[{"id":"1.168237987","rc":[{"batb":[[0,1.02,635.38],[1,1.01,647.58]],"batl":[[0,1.06,1218.43],[1,1.08,52.73]],"ltp":1.08,"tv":72.3,"id":13181195}]}]}
{"op":"mcm","clk":"1008921429","pt":1580662347853,"mc":[{"id":"1.168237987","rc":[{"batb":[[0,1.01,10.51],[1,1.01,0]],"ltp":1.08,"tv":72.3,"id":13181195}]}]}
{"op":"mcm","clk":"1008921845","pt":1580662350900,"mc":[{"id":"1.168237987","rc":[{"batb":[[0,1.04,1241.87],[1,1.01,10.51]],"ltp":1.08,"tv":72.3,"id":13181195}]}]}
{"op":"mcm","clk":"1008921940","pt":1580662351644,"mc":[{"id":"1.168237987","rc":[{"batb":[[1,12,8.89],[2,1.01,10.51]],"ltp":5.4,"tv":0.0,"id":14833204},{"batb":[[0,1.04,1770.06],[1,1.02,803.42],[2,1.01,10.51]],"ltp":1.08,"tv":72.3,"id":13181195}]}]}
{"op":"mcm","clk":"1008922229","pt":1580662353741,"mc":[{"id":"1.168237987","rc":[{"batl":[[0,65,40.66]],"ltp":5.4,"tv":0.0,"id":14833204},{"batl":[[2,1.32,1160.1]],"ltp":1.08,"tv":72.3,"id":13181195}]}]}
{"op":"mcm","clk":"1008922377","pt":1580662354712,"mc":[{"id":"1.168237987","rc":[{"batb":[[0,1.04,2916.18]],"ltp":1.08,"tv":72.3,"id":13181195}]}]}
{"op":"mcm","clk":"1008924950","pt":1580662373880,"mc":[{"id":"1.168237987","rc":[{"batb":[[0,12,8.89],[1,1.01,10.51],[2,1.01,0]],"ltp":5.4,"tv":0.0,"id":14833204},{"batb":[[0,1.02,803.42],[1,1.01,10.51],[2,1.01,0]],"batl":[[0,1.08,52.73],[1,1.32,1160.1],[2,1.32,0]],"ltp":1.08,"tv":72.3,"id":13181195}]}]}
{"op":"mcm","clk":"1008925363","pt":1580662376969,"mc":[{"id":"1.168237987","rc":[{"batb":[[1,11.5,9.6],[2,1.01,10.51]],"ltp":5.4,"tv":0.0,"id":14833204},{"batb":[[0,1.03,1253.92],[1,1.02,803.42],[2,1.01,10.51]],"batl":[[0,1.07,599.47],[1,1.08,654.68],[2,1.32,1160.1]],"ltp":1.08,"tv":72.3,"id":13181195}]}]}
{"op":"mcm","clk":"1008925403","pt":1580662377279,"mc":[{"id":"1.168237987","rc":[{"batb":[[0,11.5,9.6],[1,1.01,10.51],[2,1.01,0]],"ltp":5.4,"tv":0.0,"id":14833204},{"batb":[[1,1.02,766.13]],"ltp":1.08,"tv":72.3,"id":13181195}]}]}
{"op":"mcm","clk":"1008925723","pt":1580662379569,"mc":[{"id":"1.168237987","rc":[{"batb":[[0,1.02,766.13],[1,1.01,10.51],[2,1.01,0]],"ltp":1.08,"tv":72.3,"id":13181195}]}]}
{"op":"mcm","clk":"1008926220","pt":1580662382985,"mc":[{"id":"1.168237987","rc":[{"batb":[[0,1.06,686.63],[1,1.05,537.11],[2,1.02,766.13]],"ltp":1.08,"tv":72.3,"id":13181195}]}]}
{"op":"mcm","clk":"1008926270","pt":1580662383354,"mc":[{"id":"1.168237987","rc":[{"batb":[[1,8,8.66],[2,1.01,10.51]],"ltp":5.4,"tv":0.0,"id":14833204},{"batb":[[0,1.06,1066.58],[2,1.04,553.45]],"ltp":1.08,"tv":72.3,"id":13181195}]}]}
{"op":"mcm","clk":"1008926655","pt":1580662385987,"mc":[{"id":"1.168237987","rc":[{"batl":[[0,42,43.67]],"ltp":5.4,"tv":0.0,"id":14833204}]}]}
{"op":"mcm","clk":"1008931294","pt":1580662419822,"mc":[{"id":"1.168237987","rc":[{"batb":[[0,1.06,379.95],[1,1.04,553.45],[2,1.01,10.51]],"batl":[[0,1.08,52.73],[1,1.32,1160.1],[2,1.32,0]],"ltp":1.08,"tv":72.3,"id":13181195}]}]}
{"op":"mcm","clk":"1008931666","pt":1580662423004,"mc":[{"id":"1.168237987","rc":[{"batb":[[1,1.04,1795.56]],"batl":[[0,1.08,1513.93],[1,1.11,635.78],[2,1.12,523.28]],"ltp":1.08,"tv":72.3,"id":13181195}]}]}
{"op":"mcm","clk":"1008932117","pt":1580662426530,"mc":[{"id":"1.168237987","rc":[{"batl":[[0,1.08,52.73]],"ltp":1.08,"tv":72.3,"id":13181195}]}]}
{"op":"mcm","clk":"1008932724","pt":1580662431036,"mc":[{"id":"1.168237987","rc":[{"batb":[[0,8,8.66],[1,1.01,10.51],[2,1.01,0]],"ltp":5.4,"tv":0.0,"id":14833204},{"batb":[[0,1.04,1795.56],[1,1.01,10.51],[2,1.01,0]],"ltp":1.08,"tv":72.3,"id":13181195}]}]}
{"op":"mcm","clk":"1008932967","pt":1580662433028,"mc":[{"id":"1.168237987","rc":[{"batb":[[0,8.2,8.58],[1,8,8.66],[2,1.01,10.51]],"ltp":5.4,"tv":0.0,"id":14833204}]}]}
{"op":"mcm","clk":"1008932998","pt":1580662433336,"mc":[{"id":"1.168237987","rc":[{"batb":[[1,1.01,10.51],[2,1.01,0]],"ltp":5.4,"tv":0.0,"id":14833204}]}]}
{"op":"mcm","clk":"1008933556","pt":1580662437945,"mc":[{"id":"1.168237987","rc":[{"batl":[[1,1.32,1160.1],[2,1.12,0]],"ltp":1.08,"tv":72.3,"id":13181195}]}]}
{"op":"mcm","clk":"1008933841","pt":1580662440042,"mc":[{"id":"1.168237987","rc":[{"batl":[[0,1.05,533.01],[1,1.06,690.69],[2,1.08,52.73]],"ltp":1.08,"tv":72.3,"id":13181195}]}]}
{"op":"mcm","clk":"1008933949","pt":1580662440932,"mc":[{"id":"1.168237987","rc":[{"batb":[[0,15,4.96],[1,10.5,11.72],[2,1.01,10.51]],"ltp":5.4,"tv":0.0,"id":14833204},{"batb":[[1,1.02,840.72],[2,1.01,10.51]],"ltp":1.08,"tv":72.3,"id":13181195}]}]}
{"op":"mcm","clk":"1008934211","pt":1580662443153,"mc":[{"id":"1.168237987","rc":[{"batl":[[0,65,40.66]],"ltp":5.4,"tv":0.0,"id":14833204}]}]}
{"op":"mcm","clk":"1008936027","pt":1580662456879,"mc":[{"id":"1.168237987","rc":[{"batb":[[0,10.5,11.72],[1,1.01,10.51],[2,1.01,0]],"ltp":5.4,"tv":0.0,"id":14833204},{"batb":[[0,1.02,840.72],[1,1.01,10.51],[2,1.01,0]],"batl":[[0,1.08,52.73],[1,1.32,1160.1],[2,1.08,0]],"ltp":1.08,"tv":72.3,"id":13181195}]}]}
{"op":"mcm","clk":"1008936421","pt":1580662459785,"mc":[{"id":"1.168237987","rc":[{"batb":[[0,1.03,1212.13],[1,1.02,840.72],[2,1.01,10.51]],"batl":[[0,1.08,910.27],[1,1.09,335.46],[2,1.32,1160.1]],"ltp":1.08,"tv":72.3,"id":13181195}]}]}
{"op":"mcm","clk":"1008938035","pt":1580662471945,"mc":[{"id":"1.168237987","rc":[{"batl":[[0,1.08,52.73],[1,1.32,1160.1],[2,1.32,0]],"ltp":1.08,"tv":72.3,"id":13181195}]}]}
{"op":"mcm","clk":"1008938416","pt":1580662474784,"mc":[{"id":"1.168237987","rc":[{"batl":[[0,1.04,1242.11],[1,1.08,52.73],[2,1.32,1160.1]],"ltp":1.08,"tv":72.3,"id":13181195}]}]}
{"op":"mcm","clk":"1008938566","pt":1580662475793,"mc":[{"id":"1.168237987","rc":[{"batb":[[0,20,5.04],[1,14.5,5.43],[2,1.01,10.51]],"ltp":5.4,"tv":0.0,"id":14833204}]}]}
{"op":"mcm","clk":"1008938922","pt":1580662478510,"mc":[{"id":"1.168237987","rc":[{"batl":[[0,160,37.09]],"ltp":5.4,"tv":0.0,"id":14833204}]}]}
{"op":"mcm","clk":"1008940221","pt":1580662488408,"mc":[{"id":"1.168237987","rc":[{"batb":[[0,1.03,1175.73]],"ltp":1.08,"tv":72.3,"id":13181195}]}]}
{"op":"mcm","clk":"1008940688","pt":1580662491989,"mc":[{"id":"1.168237987","rc":[{"trd":[[1.03,16.86]],"batb":[[0,1.03,1167.3]],"ltp":1.03,"tv":89.16,"id":13181195}],"tv":89.17}]}
{"op":"mcm","clk":"1008941622","pt":1580662498947,"mc":[{"id":"1.168237987","rc":[{"batb":[[0,14.5,5.43],[1,1.01,10.51],[2,1.01,0]],"ltp":5.4,"tv":0.0,"id":14833204},{"batb":[[0,1.01,10.51],[1,1.02,0],[2,1.01,0]],"batl":[[0,1.08,52.73],[1,1.32,1160.1],[2,1.32,0]],"ltp":1.03,"tv":89.16,"id":13181195}]}]}
{"op":"mcm","clk":"1008941900","pt":1580662500894,"mc":[{"id":"1.168237987","rc":[{"batb":[[0,1.02,1266.47],[1,1.01,10.51]],"batl":[[0,1.06,1218.67],[1,1.08,52.73],[2,1.32,1160.1]],"ltp":1.03,"tv":89.16,"id":13181195}]}]}
{"op":"mcm","clk":"1008942016","pt":1580662501747,"mc":[{"id":"1.168237987","rc":[{"batb":[[0,1.01,10.51],[1,1.01,0]],"batl":[[0,1.08,52.73],[1,1.32,1160.1],[2,1.32,0]],"ltp":1.03,"tv":89.16,"id":13181195}]}]}
{"op":"mcm","clk":"1008942493","pt":1580662505027,"mc":[{"id":"1.168237987","rc":[{"batb":[[0,1.03,1254.17],[1,1.01,10.51]],"batl":[[0,1.04,823.9],[1,1.05,414.22],[2,1.08,52.73]],"ltp":1.03,"tv":89.16,"id":13181195}]}]}
{"op":"mcm","clk":"1008943012","pt":1580662508835,"mc":[{"id":"1.168237987","rc":[{"batb":[[0,1.01,10.51],[1,1.01,0]],"batl":[[0,1.08,52.73],[1,1.32,1160.1],[2,1.08,0]],"ltp":1.03,"tv":89.16,"id":13181195}]}]}
{"op":"mcm","clk":"1008943403","pt":1580662511740,"mc":[{"id":"1.168237987","rc":[{"batb":[[0,1.02,1266.47],[1,1.01,10.51]],"batl":[[0,1.06,1218.67],[1,1.08,52.73],[2,1.32,1160.1]],"ltp":1.03,"tv":89.16,"id":13181195}]}]}
{"op":"mcm","clk":"1008944773","pt":1580662522636,"mc":[{"id":"1.168237987","rc":[{"batl":[[0,1.08,52.73],[1,1.32,1160.1],[2,1.32,0]],"ltp":1.03,"tv":89.16,"id":13181195}]}]}
{"op":"mcm","clk":"1008945170","pt":1580662525755,"mc":[{"id":"1.168237987","rc":[{"batl":[[0,1.03,1254.17],[1,1.08,52.73],[2,1.32,1160.1]],"ltp":1.03,"tv":89.16,"id":13181195}]}]}
{"op":"mcm","clk":"1008945281","pt":1580662526540,"mc":[{"id":"1.168237987","rc":[{"batb":[[0,26,3.86],[1,20,4.8],[2,1.01,10.51]],"ltp":5.4,"tv":0.0,"id":14833204}]}]}
{"op":"mcm","clk":"1008945651","pt":1580662529749,"mc":[{"id":"1.168237987","rc":[{"batl":[[0,520,35.52]],"ltp":5.4,"tv":0.0,"id":14833204}]}]}
{"op":"mcm","clk":"1008947978","pt":1580662548871,"mc":[{"id":"1.168237987","rc":[{"batb":[[0,20,4.8],[1,1.01,10.51],[2,1.01,0]],"ltp":5.4,"tv":0.0,"id":14833204},{"batl":[[0,1.08,52.73],[1,1.32,1160.1],[2,1.32,0]],"ltp":1.03,"tv":89.16,"id":13181195}]}]}
{"op":"mcm","clk":"1008948376","pt":1580662551809,"mc":[{"id":"1.168237987","rc":[{"batl":[[0,1.04,1242.11],[1,1.08,52.73],[2,1.32,1160.1]],"ltp":1.03,"tv":89.16,"id":13181195}]}]}
{"op":"mcm","clk":"1008948616","pt":1580662553532,"mc":[{"id":"1.168237987","rc":[{"batl":[[0,1.04,392.18]],"ltp":1.03,"tv":89.16,"id":13181195}]}]}
{"op":"mcm","clk":"1008949047","pt":1580662556979,"mc":[{"id":"1.168237987","rc":[{"batl":[[0,1.03,858.18],[1,1.04,392.18],[2,1.08,52.73]],"ltp":1.03,"tv":89.16,"id":13181195}]}]}
{"op":"mcm","clk":"1008949538","pt":1580662560406,"mc":[{"id":"1.168237987","rc":[{"batl":[[0,1.04,392.18],[1,1.08,52.73],[2,1.32,1160.1]],"ltp":1.03,"tv":89.16,"id":13181195}]}]}
{"op":"mcm","clk":"1008949920","pt":1580662563299,"mc":[{"id":"1.168237987","rc":[{"batl":[[0,1.04,1242.11]],"ltp":1.03,"tv":89.16,"id":13181195}]}]}
{"op":"mcm","clk":"1008950089","pt":1580662564408,"mc":[{"id":"1.168237987","rc":[{"batb":[[0,1.02,765.64]],"ltp":1.03,"tv":89.16,"id":13181195}]}]}
{"op":"mcm","clk":"1008950592","pt":1580662567981,"mc":[{"id":"1.168237987","rc":[{"batb":[[0,1.03,495.96],[1,1.02,765.64],[2,1.01,10.51]],"ltp":1.03,"tv":89.16,"id":13181195}]}]}
{"op":"mcm","clk":"1008950639","pt":1580662568297,"mc":[{"id":"1.168237987","rc":[{"batb":[[1,15,5.04],[2,1.01,10.51]],"ltp":5.4,"tv":0.0,"id":14833204},{"batb":[[1,1.02,1629.96]],"ltp":1.03,"tv":89.16,"id":13181195}]}]}
{"op":"mcm","clk":"1008950871","pt":1580662569907,"mc":[{"id":"1.168237987","rc":[{"batl":[[0,160,37.09]],"ltp":5.4,"tv":0.0,"id":14833204}]}]}
{"op":"mcm","clk":"1008951436","pt":1580662573830,"mc":[{"id":"1.168237987","rc":[{"trd":[[1.03,16.9]],"batb":[[0,1.03,495.94]],"ltp":1.03,"tv":89.2,"id":13181195}],"tv":89.2}]}
{"op":"mcm","clk":"1008953671","pt":1580662590846,"mc":[{"id":"1.168237987","rc":[{"batb":[[0,1.03,378.54]],"ltp":1.03,"tv":89.2,"id":13181195}]}]}
{"op":"mcm","clk":"1008954083","pt":1580662593871,"mc":[{"id":"1.168237987","rc":[{"batb":[[1,1.02,1748.53]],"ltp":1.03,"tv":89.2,"id":13181195}]}]}
{"op":"mcm","clk":"1008955459","pt":1580662604476,"mc":[{"id":"1.168237987","rc":[{"batb":[[0,1.02,1748.53],[1,1.01,10.51],[2,1.01,0]],"batl":[[0,1.08,52.73],[1,1.32,1160.1],[2,1.32,0]],"ltp":1.03,"tv":89.2,"id":13181195}]}]}
{"op":"mcm","clk":"1008955909","pt":1580662607955,"mc":[{"id":"1.168237987","rc":[{"batb":[[0,21,68.05],[1,20,4.8],[2,15,5.04]],"ltp":5.4,"tv":0.0,"id":14833204},{"batb":[[0,1.02,3971.38]],"batl":[[0,1.05,868.57],[1,1.06,358.29],[2,1.08,52.73]],"ltp":1.03,"tv":89.2,"id":13181195}]}]}
{"op":"mcm","clk":"1008956106","pt":1580662609655,"mc":[{"id":"1.168237987","rc":[{"batb":[[0,15,5.04],[1,1.01,10.51],[2,15,0]],"ltp":5.4,"tv":0.0,"id":14833204},{"batb":[[0,1.02,1266.47]],"ltp":1.03,"tv":89.2,"id":13181195}]}]}
{"op":"mcm","clk":"1008956577","pt":1580662613618,"mc":[{"id":"1.168237987","rc":[{"batl":[[0,1.08,52.73],[1,1.32,1160.1],[2,1.08,0]],"ltp":1.03,"tv":89.2,"id":13181195}]}]}
{"op":"mcm","clk":"1008957029","pt":1580662616885,"mc":[{"id":"1.168237987","rc":[{"batl":[[0,1.03,1255.57],[1,1.08,52.73],[2,1.32,1160.1]],"ltp":1.03,"tv":89.2,"id":13181195}]}]}
{"op":"mcm","clk":"1008957089","pt":1580662617398,"mc":[{"id":"1.168237987","rc":[{"batb":[[0,26,3.69],[1,21,4.04],[2,1.01,10.51]],"ltp":5.4,"tv":0.0,"id":14833204}]}]}
{"op":"mcm","clk":"1008961092","pt":1580662648920,"mc":[{"id":"1.168237987","rc":[{"trd":[[1.02,3.36]],"batb":[[0,1.02,1264.79]],"ltp":1.02,"tv":92.56,"id":13181195}],"tv":92.56}]}
{"op":"mcm","clk":"1008964809","pt":1580662680867,"mc":[{"id":"1.168237987","rc":[{"trd":[[1.02,11.76]],"batb":[[0,1.02,1260.59]],"ltp":1.02,"tv":100.96,"id":13181195}],"tv":100.96}]}
{"op":"mcm","clk":"1008967291","pt":1580662699879,"mc":[{"id":"1.168237987","rc":[{"trd":[[1.02,307.76]],"batb":[[0,1.02,1112.59]],"ltp":1.02,"tv":396.96,"id":13181195}],"tv":396.96}]}
{"op":"mcm","clk":"1008967870","pt":1580662703694,"mc":[{"id":"1.168237987","rc":[{"batb":[[0,1.02,1267.88]],"ltp":1.02,"tv":396.96,"id":13181195}]}]}
{"op":"mcm","clk":"1008968421","pt":1580662707632,"mc":[{"id":"1.168237987","rc":[{"batb":[[0,21,4.04],[1,1.01,10.51],[2,1.01,0]],"ltp":5.4,"tv":0.0,"id":14833204},{"batb":[[0,1.01,10.51],[1,1.01,0]],"batl":[[0,1.08,52.73],[1,1.32,1160.1],[2,1.32,0]],"ltp":1.02,"tv":396.96,"id":13181195}]}]}
{"op":"mcm","clk":"1008969305","pt":1580662713975,"mc":[{"id":"1.168237987","rc":[{"batb":[[0,1.02,1267.88],[1,1.01,13.55]],"batl":[[0,1.03,1255.57],[1,1.08,52.73],[2,1.32,1160.1]],"ltp":1.02,"tv":396.96,"id":13181195}]}]}
{"op":"mcm","clk":"1008969387","pt":1580662714613,"mc":[{"id":"1.168237987","rc":[{"batb":[[1,1.01,10.51]],"ltp":1.02,"tv":396.96,"id":13181195}]}]}
{"op":"mcm","clk":"1008969764","pt":1580662717696,"mc":[{"id":"1.168237987","rc":[{"trd":[[1.03,16.93]],"batb":[[0,1.01,10.51],[1,1.01,0]],"batl":[[0,1.08,52.73],[1,1.32,1160.1],[2,1.32,0]],"ltp":1.03,"tv":397.0,"id":13181195}],"tv":397.0}]}
{"op":"mcm","clk":"1008970168","pt":1580662720613,"mc":[{"id":"1.168237987","rc":[{"batb":[[0,1.01,1290.94]],"batl":[[0,1.04,1243.5],[1,1.08,52.73],[2,1.32,1160.1]],"ltp":1.03,"tv":397.0,"id":13181195}]}]}
{"op":"mcm","clk":"1008971837","pt":1580662734142,"mc":[{"id":"1.168237987","rc":[{"batl":[[0,1.08,52.73],[1,1.32,1160.1],[2,1.32,0]],"ltp":1.03,"tv":397.0,"id":13181195}]}]}
{"op":"mcm","clk":"1008972204","pt":1580662737020,"mc":[{"id":"1.168237987","rc":[{"batl":[[0,1.02,1267.88],[1,1.08,52.73],[2,1.32,1160.1]],"ltp":1.03,"tv":397.0,"id":13181195}]}]}
{"op":"mcm","clk":"1008972307","pt":1580662737886,"mc":[{"id":"1.168237987","rc":[{"batb":[[0,30,3.11],[1,27,3.17],[2,1.01,10.51]],"ltp":5.4,"tv":0.0,"id":14833204}]}]}
{"op":"mcm","clk":"1008975046","pt":1580662760650,"mc":[{"id":"1.168237987","rc":[{"batb":[[0,1.01,10.51]],"batl":[[0,1.08,52.73],[1,1.32,1160.1],[2,1.32,0]],"ltp":1.03,"tv":397.0,"id":13181195}]}]}
{"op":"mcm","clk":"1008975097","pt":1580662761072,"mc":[{"id":"1.168237987","rc":[{"batb":[[0,27,3.17],[1,1.01,10.51],[2,1.01,0]],"ltp":5.4,"tv":0.0,"id":14833204}]}]}
{"op":"mcm","clk":"1008975246","pt":1580662762269,"mc":[{"id":"1.168237987","rc":[{"batl":[[1,1.32,0]],"ltp":1.03,"tv":397.0,"id":13181195}]}]}
{"op":"mcm","clk":"1008975632","pt":1580662765879,"mc":[{"id":"1.168237987","rc":[{"batb":[[0,1.01,1290.94]],"batl":[[0,1.02,1267.88],[1,1.08,52.73]],"ltp":1.03,"tv":397.0,"id":13181195}]}]}
{"op":"mcm","clk":"1008975920","pt":1580662768356,"mc":[{"id":"1.168237987","rc":[{"batl":[[2,1.28,1326.53]],"ltp":1.03,"tv":397.0,"id":13181195}]}]}
{"op":"mcm","clk":"1008976453","pt":1580662772973,"mc":[{"id":"1.168237987","rc":[{"batb":[[0,1.01,10.51]],"batl":[[0,1.08,52.73],[1,1.28,1326.53],[2,1.28,0]],"ltp":1.03,"tv":397.0,"id":13181195}]}]}
{"op":"mcm","clk":"1008976604","pt":1580662774389,"mc":[{"id":"1.168237987","rc":[{"batl":[[1,1.28,0]],"ltp":1.03,"tv":397.0,"id":13181195}]}]}
{"op":"mcm","clk":"1008976785","pt":1580662776001,"mc":[{"id":"1.168237987","rc":[{"batl":[[0,1.03,1255.57],[1,1.08,52.73]],"ltp":1.03,"tv":397.0,"id":13181195}]}]}
{"op":"mcm","clk":"1008977266","pt":1580662780004,"mc":[{"id":"1.168237987","rc":[{"batb":[[1,21,4.04],[2,1.01,10.51]],"ltp":5.4,"tv":0.0,"id":14833204},{"batb":[[0,1.02,1267.88],[1,1.01,10.51]],"ltp":1.03,"tv":397.0,"id":13181195}]}]}
{"op":"mcm","clk":"1008977604","pt":1580662782467,"mc":[{"id":"1.168237987","rc":[{"batl":[[2,1.29,1276.86]],"ltp":1.03,"tv":397.0,"id":13181195}]}]}
{"op":"mcm","clk":"1008979657","pt":1580662799852,"mc":[{"id":"1.168237987","rc":[{"batb":[[0,21,4.04],[1,1.01,10.51],[2,1.01,0]],"ltp":5.4,"tv":0.0,"id":14833204},{"batb":[[0,1.01,10.51],[1,1.01,0]],"batl":[[0,1.08,52.73],[1,1.29,1276.86],[2,1.29,0]],"ltp":1.03,"tv":397.0,"id":13181195}]}]}
{"op":"mcm","clk":"1008980043","pt":1580662802399,"mc":[{"id":"1.168237987","rc":[{"batb":[[0,1.01,1290.94]],"batl":[[0,1.04,1243.5],[1,1.08,52.73],[2,1.29,1276.86]],"ltp":1.03,"tv":397.0,"id":13181195}]}]}
{"op":"mcm","clk":"1008980150","pt":1580662803088,"mc":[{"id":"1.168237987","rc":[{"batb":[[0,1.01,10.51]],"ltp":1.03,"tv":397.0,"id":13181195}]}]}
{"op":"mcm","clk":"1008980681","pt":1580662806911,"mc":[{"id":"1.168237987","rc":[{"batb":[[1,18,6.77],[2,1.01,10.51]],"ltp":5.4,"tv":0.0,"id":14833204},{"batb":[[0,1.03,489.95],[1,1.02,1702.05],[2,1.01,10.51]],"ltp":1.03,"tv":397.0,"id":13181195}]}]}
{"op":"mcm","clk":"1008980773","pt":1580662807490,"mc":[{"id":"1.168237987","rc":[{"batl":[[0,160,37.09]],"ltp":5.4,"tv":0.0,"id":14833204}]}]}
{"op":"mcm","clk":"1008982243","pt":1580662819039,"mc":[{"id":"1.168237987","rc":[{"batb":[[0,1.02,1702.05],[1,1.01,10.51],[2,1.01,0]],"batl":[[0,1.08,52.73],[1,1.29,1276.86],[2,1.29,0]],"ltp":1.03,"tv":397.0,"id":13181195}]}]}
{"op":"mcm","clk":"1008982364","pt":1580662819930,"mc":[{"id":"1.168237987","rc":[{"batb":[[0,18,6.77],[1,1.01,10.51],[2,1.01,0]],"ltp":5.4,"tv":0.0,"id":14833204},{"batb":[[0,1.02,773.13]],"ltp":1.03,"tv":397.0,"id":13181195}]}]}
{"op":"mcm","clk":"1008982614","pt":1580662822027,"mc":[{"id":"1.168237987","rc":[{"batb":[[0,1.02,1267.88]],"batl":[[0,1.05,1231.66],[1,1.08,52.73],[2,1.29,1276.86]],"ltp":1.03,"tv":397.0,"id":13181195}]}]}
{"op":"mcm","clk":"1008982952","pt":1580662824913,"mc":[{"id":"1.168237987","rc":[{"batl":[[0,1.08,52.73],[1,1.29,1276.86],[2,1.29,0]],"ltp":1.03,"tv":397.0,"id":13181195}]}]}
{"op":"mcm","clk":"1008983301","pt":1580662828015,"mc":[{"id":"1.168237987","rc":[{"batb":[[0,27,3.02],[1,21,4.41],[2,1.01,10.51]],"ltp":5.4,"tv":0.0,"id":14833204},{"batl":[[0,1.03,1255.57],[1,1.08,52.73],[2,1.29,1276.86]],"ltp":1.03,"tv":397.0,"id":13181195}]}]}
{"op":"mcm","clk":"1008985616","pt":1580662846270,"mc":[{"id":"1.168237987","rc":[{"batb":[[0,1.01,10.51],[1,1.01,0]],"batl":[[0,1.08,52.73],[1,1.29,1276.86],[2,1.29,0]],"ltp":1.03,"tv":397.0,"id":13181195}]}]}
{"op":"mcm","clk":"1008985831","pt":1580662847755,"mc":[{"id":"1.168237987","rc":[{"batb":[[0,21,4.41],[1,1.01,10.51],[2,1.01,0]],"ltp":5.4,"tv":0.0,"id":14833204}]}]}
{"op":"mcm","clk":"1008985954","pt":1580662848644,"mc":[{"id":"1.168237987","rc":[{"batl":[[1,1.29,0]],"ltp":1.03,"tv":397.0,"id":13181195}]}]}
{"op":"mcm","clk":"1008986119","pt":1580662849853,"mc":[{"id":"1.168237987","rc":[{"batb":[[0,1.01,569.9]],"ltp":1.03,"tv":397.0,"id":13181195}]}]}
{"op":"mcm","clk":"1008986563","pt":1580662852861,"mc":[{"id":"1.168237987","rc":[{"batb":[[0,1.02,713.97],[1,1.01,569.9]],"batl":[[0,1.03,1255.57],[1,1.08,52.73]],"ltp":1.03,"tv":397.0,"id":13181195}]}]}
{"op":"mcm","clk":"1008987269","pt":1580662857947,"mc":[{"id":"1.168237987","rc":[{"batb":[[0,1.01,569.9],[1,1.01,0]],"batl":[[0,1.08,52.73],[1,1.08,0]],"ltp":1.03,"tv":397.0,"id":13181195}]}]}
{"op":"mcm","clk":"1008987632","pt":1580662860866,"mc":[{"id":"1.168237987","rc":[{"batb":[[0,1.01,731.55]],"batl":[[0,1.04,1243.5],[1,1.08,52.73]],"ltp":1.03,"tv":397.0,"id":13181195}]}]}
{"op":"mcm","clk":"1008987661","pt":1580662861062,"mc":[{"id":"1.168237987","rc":[{"batb":[[0,1.01,10.51]],"ltp":1.03,"tv":397.0,"id":13181195}]}]}
{"op":"mcm","clk":"1008988045","pt":1580662863873,"mc":[{"id":"1.168237987","rc":[{"batb":[[0,1.03,1255.57],[1,1.01,10.51]],"ltp":1.03,"tv":397.0,"id":13181195}]}]}
{"op":"mcm","clk":"1008988117","pt":1580662864354,"mc":[{"id":"1.168237987","rc":[{"batb":[[1,16.5,8.1],[2,1.01,10.51]],"ltp":5.4,"tv":0.0,"id":14833204},{"batb":[[1,1.02,877.93],[2,1.01,10.51]],"ltp":1.03,"tv":397.0,"id":13181195}]}]}
{"op":"mcm","clk":"1008988298","pt":1580662865778,"mc":[{"id":"1.168237987","rc":[{"batl":[[0,160,37.09]],"ltp":5.4,"tv":0.0,"id":14833204},{"batl":[[2,1.3,1225.16]],"ltp":1.03,"tv":397.0,"id":13181195}]}]}
{"op":"mcm","clk":"1008990296","pt":1580662880002,"mc":[{"id":"1.168237987","rc":[{"batb":[[0,16.5,8.1],[1,1.01,10.51],[2,1.01,0]],"ltp":5.4,"tv":0.0,"id":14833204},{"batb":[[0,1.01,10.51],[1,1.02,0],[2,1.01,0]],"batl":[[0,1.08,52.73],[1,1.3,1225.16],[2,1.3,0]],"ltp":1.03,"tv":397.0,"id":13181195}]}]}
{"op":"mcm","clk":"1008990735","pt":1580662883023,"mc":[{"id":"1.168237987","rc":[{"batb":[[0,1.02,1267.88],[1,1.01,10.51]],"batl":[[0,1.05,1231.66],[1,1.08,52.73],[2,1.3,1225.16]],"ltp":1.03,"tv":397.0,"id":13181195}]}]}
{"op":"mcm","clk":"1008990943","pt":1580662884499,"mc":[{"id":"1.168237987","rc":[{"batb":[[0,1.01,10.51],[1,1.01,0]],"ltp":1.03,"tv":397.0,"id":13181195}]}]}
{"op":"mcm","clk":"1008991412","pt":1580662888029,"mc":[{"id":"1.168237987","rc":[{"batb":[[1,10,13.3],[2,1.01,10.51]],"ltp":5.4,"tv":0.0,"id":14833204},{"batb":[[0,1.04,549.81],[1,1.03,1339.39],[2,1.01,10.51]],"ltp":1.03,"tv":397.0,"id":13181195}]}]}
{"op":"mcm","clk":"1008991833","pt":1580662890917,"mc":[{"id":"1.168237987","rc":[{"batl":[[0,95,38.77]],"ltp":5.4,"tv":0.0,"id":14833204}]}]}
{"op":"mcm","clk":"1008996428","pt":1580662920781,"mc":[{"id":"1.168237987","rc":[{"batb":[[0,10,13.3],[1,1.01,10.51],[2,1.01,0]],"ltp":5.4,"tv":0.0,"id":14833204},{"batb":[[0,1.01,10.51],[1,1.03,0],[2,1.01,0]],"batl":[[0,1.08,52.73],[1,1.3,1225.16],[2,1.3,0]],"ltp":1.03,"tv":397.0,"id":13181195}]}]}
{"op":"mcm","clk":"1008996847","pt":1580662923571,"mc":[{"id":"1.168237987","rc":[{"batb":[[0,1.02,1269.7],[1,1.01,10.51]],"batl":[[1,1.3,0]],"ltp":1.03,"tv":397.0,"id":13181195}]}]}
{"op":"mcm","clk":"1008997317","pt":1580662926570,"mc":[{"id":"1.168237987","rc":[{"batl":[[0,1.03,1257.37],[1,1.08,52.73]],"ltp":1.03,"tv":397.0,"id":13181195}]}]}
{"op":"mcm","clk":"1008997439","pt":1580662927420,"mc":[{"id":"1.168237987","rc":[{"batb":[[0,26,3.52],[1,15,5.27],[2,1.01,10.51]],"ltp":5.4,"tv":0.0,"id":14833204}]}]}
{"op":"mcm","clk":"1008997719","pt":1580662929071,"mc":[{"id":"1.168237987","rc":[{"batl":[[2,1.29,1299.03]],"ltp":1.03,"tv":397.0,"id":13181195}]}]}
{"op":"mcm","clk":"1008999729","pt":1580662942992,"mc":[{"id":"1.168237987","rc":[{"batb":[[0,15,5.27],[1,1.01,10.51],[2,1.01,0]],"ltp":5.4,"tv":0.0,"id":14833204},{"batb":[[0,1.01,10.51],[1,1.01,0]],"batl":[[0,1.08,52.73],[1,1.29,1299.03],[2,1.29,0]],"ltp":1.03,"tv":397.0,"id":13181195}]}]}
{"op":"mcm","clk":"1009000097","pt":1580662945489,"mc":[{"id":"1.168237987","rc":[{"batl":[[0,1.06,1221.78],[1,1.08,52.73]],"ltp":1.03,"tv":397.0,"id":13181195}]}]}
{"op":"mcm","clk":"1009000282","pt":1580662946874,"mc":[{"id":"1.168237987","rc":[{"batl":[[0,1.08,52.73],[1,1.08,0]],"ltp":1.03,"tv":397.0,"id":13181195}]}]}
{"op":"mcm","clk":"1009000607","pt":1580662948984,"mc":[{"id":"1.168237987","rc":[{"batl":[[0,1.02,1269.7],[1,1.08,52.73]],"ltp":1.03,"tv":397.0,"id":13181195}]}]}
{"op":"mcm","clk":"1009000751","pt":1580662950037,"mc":[{"id":"1.168237987","rc":[{"batb":[[0,26,3.86]],"ltp":5.4,"tv":0.0,"id":14833204}]}]}
{"op":"mcm","clk":"1009000996","pt":1580662951413,"mc":[{"id":"1.168237987","rc":[{"batl":[[2,1.27,1360.7]],"ltp":1.03,"tv":397.0,"id":13181195}]}]}
{"op":"mcm","clk":"1009002079","pt":1580662957997,"mc":[{"id":"1.168237987","rc":[{"batl":[[0,1.02,1662.07]],"ltp":1.03,"tv":397.0,"id":13181195}]}]}
{"op":"mcm","clk":"1009003782","pt":1580662969037,"mc":[{"id":"1.168237987","rc":[{"batl":[[0,1.08,52.73],[1,1.27,1360.7],[2,1.27,0]],"ltp":1.03,"tv":397.0,"id":13181195}]}]}
{"op":"mcm","clk":"1009004232","pt":1580662971729,"mc":[{"id":"1.168237987","rc":[{"batl":[[0,1.03,1257.37],[1,1.08,52.73]],"ltp":1.03,"tv":397.0,"id":13181195}]}]}
{"op":"mcm","clk":"1009004452","pt":1580662973113,"mc":[{"id":"1.168237987","rc":[{"batl":[[0,1.08,52.73],[1,1.08,0]],"ltp":1.03,"tv":397.0,"id":13181195}]}]}
{"op":"mcm","clk":"1009004903","pt":1580662976006,"mc":[{"id":"1.168237987","rc":[{"batb":[[0,1.01,1292.78]],"batl":[[0,1.02,1269.7],[1,1.08,52.73]],"ltp":1.03,"tv":397.0,"id":13181195}]}]}
{"op":"mcm","clk":"1009005391","pt":1580662978946,"mc":[{"id":"1.168237987","rc":[{"batb":[[0,1.01,10.51]],"batl":[[0,1.08,52.73],[1,1.08,0]],"ltp":1.03,"tv":397.0,"id":13181195}]}]}
{"op":"mcm","clk":"1009005918","pt":1580662981925,"mc":[{"id":"1.168237987","rc":[{"batl":[[0,1.03,1257.37],[1,1.08,52.73]],"ltp":1.03,"tv":397.0,"id":13181195}]}]}
{"op":"mcm","clk":"1009006042","pt":1580662982737,"mc":[{"id":"1.168237987","rc":[{"batb":[[0,1.01,10.51],[1,1.01,0]],"ltp":5.4,"tv":0.0,"id":14833204},{"batl":[[0,1.08,52.73],[1,1.08,0]],"ltp":1.03,"tv":397.0,"id":13181195}]}]}
{"op":"mcm","clk":"1009006482","pt":1580662985540,"mc":[{"id":"1.168237987","rc":[{"trd":[[1.01,21.02]],"batl":[[0,1.01,1271.76],[1,1.08,52.73]],"ltp":1.01,"tv":418.01,"id":13181195}],"tv":418.01}]}
{"op":"mcm","clk":"1009006921","pt":1580662988423,"mc":[{"id":"1.168237987","rc":[{"batl":[[2,1.26,1405.9]],"ltp":1.01,"tv":418.01,"id":13181195}]}]}
{"op":"mcm","clk":"1009010110","pt":1580663008278,"mc":[{"id":"1.168237987","rc":[{"batl":[[2,1.26,0]],"ltp":1.01,"tv":418.01,"id":13181195}]}]}
{"op":"mcm","clk":"1009011041","pt":1580663013595,"mc":[{"id":"1.168237987","rc":[{"batl":[[0,1.08,52.73],[1,1.08,0]],"ltp":1.01,"tv":418.01,"id":13181195}]}]}
{"op":"mcm","clk":"1009011160","pt":1580663014271,"mc":[{"id":"1.168237987","marketDefinition":{"bspMarket":false,"turnInPlayEnabled":true,"persistenceEnabled":true,"marketBaseRate":5.0,"eventId":"29681871","eventTypeId":"2","numberOfWinners":1,"bettingType":"ODDS","marketType":"SET_WINNER","marketTime":"2020-02-02T15:20:00.000Z","suspendTime":"2020-02-02T15:20:00.000Z","bspReconciled":false,"complete":true,"inPlay":true,"crossMatching":true,"runnersVoidable":false,"numberOfActiveRunners":2,"betDelay":3,"status":"SUSPENDED","runners":[{"status":"ACTIVE","sortPriority":1,"id":14833204,"name":"Facundo Diaz Acosta"},{"status":"ACTIVE","sortPriority":2,"id":13181195,"name":"Pedro Martinez"}],"regulators":["MR_INT"],"countryCode":"AR","discountAllowed":true,"timezone":"UTC","openDate":"2020-02-02T15:20:00.000Z","version":3149951627,"name":"Set 2 Winner","eventName":"Diaz Acosta v Martinez"}}]}
{"op":"mcm","clk":"1009019061","pt":1580663059540,"mc":[{"id":"1.168237987","tv":0.0}]}
{"op":"mcm","clk":"1009019241","pt":1580663060489,"mc":[{"id":"1.168237987","marketDefinition":{"bspMarket":false,"turnInPlayEnabled":true,"persistenceEnabled":true,"marketBaseRate":5.0,"eventId":"29681871","eventTypeId":"2","numberOfWinners":1,"bettingType":"ODDS","marketType":"SET_WINNER","marketTime":"2020-02-02T15:20:00.000Z","suspendTime":"2020-02-02T15:20:00.000Z","bspReconciled":false,"complete":true,"inPlay":true,"crossMatching":false,"runnersVoidable":false,"numberOfActiveRunners":0,"betDelay":3,"status":"CLOSED","settledTime":"2020-02-02T17:04:15.000Z","runners":[{"status":"LOSER","sortPriority":1,"id":14833204,"name":"Facundo Diaz Acosta"},{"status":"WINNER","sortPriority":2,"id":13181195,"name":"Pedro Martinez"}],"regulators":["MR_INT"],"countryCode":"AR","discountAllowed":true,"timezone":"UTC","openDate":"2020-02-02T15:20:00.000Z","version":3149953457,"name":"Set 2 Winner","eventName":"Diaz Acosta v Martinez"}}]}
