{"op":"mcm","clk":"1002315141","pt":1580592409750,"mc":[{"id":"1.168237985","marketDefinition":{"bspMarket":false,"turnInPlayEnabled":true,"persistenceEnabled":true,"marketBaseRate":5.0,"eventId":"29681871","eventTypeId":"2","numberOfWinners":1,"bettingType":"ODDS","marketType":"SET_BETTING","marketTime":"2020-02-02T16:00:00.000Z","suspendTime":"2020-02-02T16:00:00.000Z","bspReconciled":false,"complete":true,"inPlay":false,"crossMatching":false,"runnersVoidable":false,"numberOfActiveRunners":4,"betDelay":0,"status":"OPEN","runners":[{"status":"ACTIVE","sortPriority":1,"id":21483493,"name":"Diaz Acosta 2-0"},{"status":"ACTIVE","sortPriority":2,"id":21483494,"name":"Diaz Acosta 2-1"},{"status":"ACTIVE","sortPriority":3,"id":16676046,"name":"Martinez 2-0"},{"status":"ACTIVE","sortPriority":4,"id":16676048,"name":"Martinez 2-1"}],"regulators":["MR_INT"],"countryCode":"AR","discountAllowed":false,"timezone":"UTC","openDate":"2020-02-02T16:00:00.000Z","version":3147569480,"name":"Set Betting","eventName":"Diaz Acosta v Martinez"}}]}
{"op":"mcm","clk":"1002315289","pt":1580592411040,"mc":[{"id":"1.168237985","marketDefinition":{"bspMarket":false,"turnInPlayEnabled":true,"persistenceEnabled":true,"marketBaseRate":5.0,"eventId":"29681871","eventTypeId":"2","numberOfWinners":1,"bettingType":"ODDS","marketType":"SET_BETTING","marketTime":"2020-02-02T16:00:00.000Z","suspendTime":"2020-02-02T16:00:00.000Z","bspReconciled":false,"complete":true,"inPlay":false,"crossMatching":false,"runnersVoidable":false,"numberOfActiveRunners":4,"betDelay":0,"status":"OPEN","runners":[{"status":"ACTIVE","sortPriority":1,"id":21483493,"name":"Diaz Acosta 2-0"},{"status":"ACTIVE","sortPriority":2,"id":21483494,"name":"Diaz Acosta 2-1"},{"status":"ACTIVE","sortPriority":3,"id":16676046,"name":"Martinez 2-0"},{"status":"ACTIVE","sortPriority":4,"id":16676048,"name":"Martinez 2-1"}],"regulators":["MR_INT"],"countryCode":"AR","discountAllowed":false,"timezone":"UTC","openDate":"2020-02-02T16:00:00.000Z","version":3147569480,"name":"Set Betting","eventName":"Diaz Acosta v Martinez"}}]}
{"op":"mcm","clk":"1002315411","pt":1580592412044,"mc":[{"id":"1.168237985","marketDefinition":{"bspMarket":false,"turnInPlayEnabled":true,"persistenceEnabled":true,"marketBaseRate":5.0,"eventId":"29681871","eventTypeId":"2","numberOfWinners":1,"bettingType":"ODDS","marketType":"SET_BETTING","marketTime":"2020-02-02T16:00:00.000Z","suspendTime":"2020-02-02T16:00:00.000Z","bspReconciled":false,"complete":true,"inPlay":false,"crossMatching":false,"runnersVoidable":false,"numberOfActiveRunners":4,"betDelay":0,"status":"OPEN","runners":[{"status":"ACTIVE","sortPriority":1,"id":21483493,"name":"Diaz Acosta 2-0"},{"status":"ACTIVE","sortPriority":2,"id":21483494,"name":"Diaz Acosta 2-1"},{"status":"ACTIVE","sortPriority":3,"id":16676046,"name":"Martinez 2-0"},{"status":"ACTIVE","sortPriority":4,"id":16676048,"name":"Martinez 2-1"}],"regulators":["MR_INT"],"countryCode":"AR","discountAllowed":true,"timezone":"UTC","openDate":"2020-02-02T16:00:00.000Z","version":3147569480,"name":"Set Betting","eventName":"Diaz Acosta v Martinez"}}]}
{"op":"mcm","clk":"1002548636","pt":1580595201924,"mc":[{"id":"1.168237985","rc":[{"batb":[[0,1.02,2]],"ltp":0.0,"tv":0.0,"id":16676048},{"batb":[[0,1.02,2]],"ltp":0.0,"tv":0.0,"id":16676046},{"batb":[[0,1.02,2]],"ltp":0.0,"tv":0.0,"id":21483494},{"batb":[[0,1.02,2]],"ltp":0.0,"tv":0.0,"id":21483493}]}]}
{"op":"mcm","clk":"1003013311","pt":1580601981866,"mc":[{"id":"1.168237985","rc":[{"batb":[[1,1.01,2.53]],"ltp":0.0,"tv":0.0,"id":16676048},{"batb":[[1,1.01,2.53]],"ltp":0.0,"tv":0.0,"id":16676046},{"batb":[[1,1.01,2.53]],"ltp":0.0,"tv":0.0,"id":21483494},{"batb":[[1,1.01,2.53]],"ltp":0.0,"tv":0.0,"id":21483493}]}]}
{"op":"mcm","clk":"1003013427","pt":1580601982948,"mc":[{"id":"1.168237985","rc":[{"batb":[[1,1.01,0.51]],"ltp":0.0,"tv":0.0,"id":16676048},{"batb":[[1,1.01,0.51]],"ltp":0.0,"tv":0.0,"id":16676046},{"batb":[[1,1.01,0.51]],"ltp":0.0,"tv":0.0,"id":21483494},{"batb":[[1,1.01,0.51]],"ltp":0.0,"tv":0.0,"id":21483493}]}]}
{"op":"mcm","clk":"1003143132","pt":1580603524980,"mc":[{"id":"1.168237985","rc":[{"batb":[[1,1.01,3.04]],"ltp":0.0,"tv":0.0,"id":16676048},{"batb":[[1,1.01,3.04]],"ltp":0.0,"tv":0.0,"id":16676046},{"batb":[[1,1.01,3.04]],"ltp":0.0,"tv":0.0,"id":21483494},{"batb":[[1,1.01,3.04]],"ltp":0.0,"tv":0.0,"id":21483493}]}]}
{"op":"mcm","clk":"1003143216","pt":1580603525857,"mc":[{"id":"1.168237985","rc":[{"batb":[[1,1.01,1.01]],"ltp":0.0,"tv":0.0,"id":16676048},{"batb":[[1,1.01,1.01]],"ltp":0.0,"tv":0.0,"id":16676046},{"batb":[[1,1.01,1.01]],"ltp":0.0,"tv":0.0,"id":21483494},{"batb":[[1,1.01,1.01]],"ltp":0.0,"tv":0.0,"id":21483493}]}]}
{"op":"mcm","clk":"1003544040","pt":1580609292481,"mc":[{"id":"1.168237985","rc":[{"batb":[[0,1.56,30.29],[1,1.02,2],[2,1.01,1.01]],"ltp":0.0,"tv":0.0,"id":16676046}]}]}
{"op":"mcm","clk":"1004733895","pt":1580636321611,"mc":[{"id":"1.168237985","rc":[{"batl":[[0,4.2,40]],"ltp":0.0,"tv":0.0,"id":16676048}]}]}
{"op":"mcm","clk":"1004735036","pt":1580636345607,"mc":[{"id":"1.168237985","marketDefinition":{"bspMarket":false,"turnInPlayEnabled":true,"persistenceEnabled":true,"marketBaseRate":5.0,"eventId":"29681871","eventTypeId":"2","numberOfWinners":1,"bettingType":"ODDS","marketType":"SET_BETTING","marketTime":"2020-02-02T16:00:00.000Z","suspendTime":"2020-02-02T16:00:00.000Z","bspReconciled":false,"complete":true,"inPlay":false,"crossMatching":true,"runnersVoidable":false,"numberOfActiveRunners":4,"betDelay":0,"status":"OPEN","runners":[{"status":"ACTIVE","sortPriority":1,"id":21483493,"name":"Diaz Acosta 2-0"},{"status":"ACTIVE","sortPriority":2,"id":21483494,"name":"Diaz Acosta 2-1"},{"status":"ACTIVE","sortPriority":3,"id":16676046,"name":"Martinez 2-0"},{"status":"ACTIVE","sortPriority":4,"id":16676048,"name":"Martinez 2-1"}],"regulators":["MR_INT"],"countryCode":"AR","discountAllowed":true,"timezone":"UTC","openDate":"2020-02-02T16:00:00.000Z","version":3147569480,"name":"Set Betting","eventName":"Diaz Acosta v Martinez"}}]}
{"op":"mcm","clk":"1006912530","pt":1580651802470,"mc":[{"id":"1.168237985","marketDefinition":{"bspMarket":false,"turnInPlayEnabled":true,"persistenceEnabled":true,"marketBaseRate":5.0,"eventId":"29681871","eventTypeId":"2","numberOfWinners":1,"bettingType":"ODDS","marketType":"SET_BETTING","marketTime":"2020-02-02T15:52:00.000Z","suspendTime":"2020-02-02T15:52:00.000Z","bspReconciled":false,"complete":true,"inPlay":false,"crossMatching":true,"runnersVoidable":false,"numberOfActiveRunners":4,"betDelay":0,"status":"OPEN","runners":[{"status":"ACTIVE","sortPriority":1,"id":21483493,"name":"Diaz Acosta 2-0"},{"status":"ACTIVE","sortPriority":2,"id":21483494,"name":"Diaz Acosta 2-1"},{"status":"ACTIVE","sortPriority":3,"id":16676046,"name":"Martinez 2-0"},{"status":"ACTIVE","sortPriority":4,"id":16676048,"name":"Martinez 2-1"}],"regulators":["MR_INT"],"countryCode":"AR","discountAllowed":true,"timezone":"UTC","openDate":"2020-02-02T16:00:00.000Z","version":3149006553,"name":"Set Betting","eventName":"Diaz Acosta v Martinez"}}]}
{"op":"mcm","clk":"1006912941","pt":1580651805472,"mc":[{"id":"1.168237985","marketDefinition":{"bspMarket":false,"turnInPlayEnabled":true,"persistenceEnabled":true,"marketBaseRate":5.0,"eventId":"29681871","eventTypeId":"2","numberOfWinners":1,"bettingType":"ODDS","marketType":"SET_BETTING","marketTime":"2020-02-02T15:52:00.000Z","suspendTime":"2020-02-02T15:52:00.000Z","bspReconciled":false,"complete":true,"inPlay":false,"crossMatching":true,"runnersVoidable":false,"numberOfActiveRunners":4,"betDelay":0,"status":"OPEN","runners":[{"status":"ACTIVE","sortPriority":1,"id":21483493,"name":"Diaz Acosta 2-0"},{"status":"ACTIVE","sortPriority":2,"id":21483494,"name":"Diaz Acosta 2-1"},{"status":"ACTIVE","sortPriority":3,"id":16676046,"name":"Martinez 2-0"},{"status":"ACTIVE","sortPriority":4,"id":16676048,"name":"Martinez 2-1"}],"regulators":["MR_INT"],"countryCode":"AR","discountAllowed":true,"timezone":"UTC","openDate":"2020-02-02T15:52:00.000Z","version":3149006553,"name":"Set Betting","eventName":"Diaz Acosta v Martinez"}}]}
{"op":"mcm","clk":"1007405272","pt":1580654812943,"mc":[{"id":"1.168237985","rc":[{"batb":[[0,1.02,2],[1,1.01,1.01],[2,1.01,0]],"ltp":0.0,"tv":0.0,"id":16676046}]}]}
{"op":"mcm","clk":"1007507508","pt":1580655627394,"mc":[{"id":"1.168237985","rc":[{"batb":[[0,1.03,2],[1,1.02,2],[2,1.01,1.01]],"ltp":0.0,"tv":0.0,"id":16676048}]}]}
{"op":"mcm","clk":"1007629729","pt":1580656226628,"mc":[{"id":"1.168237985","rc":[{"batb":[[0,1.02,2],[1,1.01,1.01],[2,1.01,0]],"ltp":0.0,"tv":0.0,"id":16676048}]}]}
{"op":"mcm","clk":"1007634678","pt":1580656246041,"mc":[{"id":"1.168237985","rc":[{"batb":[[0,1.03,2],[1,1.02,2],[2,1.01,1.01]],"ltp":0.0,"tv":0.0,"id":16676048}]}]}
{"op":"mcm","clk":"1007718413","pt":1580656602839,"mc":[{"id":"1.168237985","marketDefinition":{"bspMarket":false,"turnInPlayEnabled":true,"persistenceEnabled":true,"marketBaseRate":5.0,"eventId":"29681871","eventTypeId":"2","numberOfWinners":1,"bettingType":"ODDS","marketType":"SET_BETTING","marketTime":"2020-02-02T15:20:00.000Z","suspendTime":"2020-02-02T15:20:00.000Z","bspReconciled":false,"complete":true,"inPlay":false,"crossMatching":true,"runnersVoidable":false,"numberOfActiveRunners":4,"betDelay":0,"status":"OPEN","runners":[{"status":"ACTIVE","sortPriority":1,"id":21483493,"name":"Diaz Acosta 2-0"},{"status":"ACTIVE","sortPriority":2,"id":21483494,"name":"Diaz Acosta 2-1"},{"status":"ACTIVE","sortPriority":3,"id":16676046,"name":"Martinez 2-0"},{"status":"ACTIVE","sortPriority":4,"id":16676048,"name":"Martinez 2-1"}],"regulators":["MR_INT"],"countryCode":"AR","discountAllowed":true,"timezone":"UTC","openDate":"2020-02-02T15:52:00.000Z","version":3149441887,"name":"Set Betting","eventName":"Diaz Acosta v Martinez"}}]}
{"op":"mcm","clk":"1007718966","pt":1580656604846,"mc":[{"id":"1.168237985","marketDefinition":{"bspMarket":false,"turnInPlayEnabled":true,"persistenceEnabled":true,"marketBaseRate":5.0,"eventId":"29681871","eventTypeId":"2","numberOfWinners":1,"bettingType":"ODDS","marketType":"SET_BETTING","marketTime":"2020-02-02T15:20:00.000Z","suspendTime":"2020-02-02T15:20:00.000Z","bspReconciled":false,"complete":true,"inPlay":false,"crossMatching":true,"runnersVoidable":false,"numberOfActiveRunners":4,"betDelay":0,"status":"OPEN","runners":[{"status":"ACTIVE","sortPriority":1,"id":21483493,"name":"Diaz Acosta 2-0"},{"status":"ACTIVE","sortPriority":2,"id":21483494,"name":"Diaz Acosta 2-1"},{"status":"ACTIVE","sortPriority":3,"id":16676046,"name":"Martinez 2-0"},{"status":"ACTIVE","sortPriority":4,"id":16676048,"name":"Martinez 2-1"}],"regulators":["MR_INT"],"countryCode":"AR","discountAllowed":true,"timezone":"UTC","openDate":"2020-02-02T15:20:00.000Z","version":3149441887,"name":"Set Betting","eventName":"Diaz Acosta v Martinez"}}]}
{"op":"mcm","clk":"1007774506","pt":1580656845365,"mc":[{"id":"1.168237985","rc":[{"batb":[[0,1.02,2],[1,1.01,1.01],[2,1.01,0]],"ltp":0.0,"tv":0.0,"id":16676048}]}]}
{"op":"mcm","clk":"1007775723","pt":1580656850873,"mc":[{"id":"1.168237985","rc":[{"batb":[[0,1.03,2],[1,1.02,2],[2,1.01,1.01]],"ltp":0.0,"tv":0.0,"id":16676048}]}]}
{"op":"mcm","clk":"1007786256","pt":1580656898010,"mc":[{"id":"1.168237985","rc":[{"trd":[[4.2,37.46]],"batl":[[0,4.2,21.27],[1,5,17.86]],"ltp":4.2,"tv":37.45,"id":16676048},{"batb":[[0,1.82,19.04],[1,1.02,2],[2,1.01,1.01]],"batl":[[0,1.93,18.73]],"ltp":0.0,"tv":0.0,"id":16676046},{"batb":[[0,7.6,9.84],[1,1.02,2],[2,1.01,1.01]],"batl":[[0,9.6,9.36]],"ltp":0.0,"tv":0.0,"id":21483494},{"batb":[[0,6.8,12.9],[1,1.02,2],[2,1.01,1.01]],"batl":[[0,8.4,12.2]],"ltp":0.0,"tv":0.0,"id":21483493}],"tv":37.45}]}
{"op":"mcm","clk":"1007788051","pt":1580656905837,"mc":[{"id":"1.168237985","rc":[{"trd":[[4.2,76.8]],"batl":[[0,4.2,1.6],[1,4.8,18.65]],"ltp":4.2,"tv":76.79,"id":16676048},{"batb":[[0,1.85,18.73]],"batl":[[0,1.93,18.41]],"ltp":0.0,"tv":0.0,"id":16676046},{"batb":[[0,7.8,9.68]],"batl":[[0,9.4,9.21]],"ltp":0.0,"tv":0.0,"id":21483494},{"batb":[[0,6.8,12.75]],"batl":[[0,8.4,12.04]],"ltp":0.0,"tv":0.0,"id":21483493}],"tv":76.79}]}
{"op":"mcm","clk":"1007790359","pt":1580656915738,"mc":[{"id":"1.168237985","rc":[{"batb":[[0,4.1,20.61],[1,1.03,2],[2,1.02,2]],"batl":[[1,4.6,19.59],[2,4.8,18.65]],"ltp":4.2,"tv":76.79,"id":16676048},{"batb":[[0,1.86,18.33],[1,1.85,18.73],[2,1.02,2]],"batl":[[1,1.94,18.02]],"ltp":0.0,"tv":0.0,"id":16676046},{"batl":[[1,9.6,9.13]],"ltp":0.0,"tv":0.0,"id":21483494},{"batb":[[0,7,12.59],[1,6.8,12.75],[2,1.02,2]],"ltp":0.0,"tv":0.0,"id":21483493}]}]}
{"op":"mcm","clk":"1007790445","pt":1580656916172,"mc":[{"id":"1.168237985","rc":[{"batl":[[2,4.8,0]],"ltp":4.2,"tv":76.79,"id":16676048},{"batb":[[1,1.02,2],[2,1.01,1.01]],"batl":[[0,1.94,18.02],[1,1.94,0]],"ltp":0.0,"tv":0.0,"id":16676046},{"batl":[[0,9.6,9.13],[1,9.6,0]],"ltp":0.0,"tv":0.0,"id":21483494},{"batb":[[1,1.02,2],[2,1.01,1.01]],"batl":[[0,8.4,11.88]],"ltp":0.0,"tv":0.0,"id":21483493}]}]}
{"op":"mcm","clk":"1007794162","pt":1580656932918,"mc":[{"id":"1.168237985","rc":[{"trd":[[1.94,6.92]],"batl":[[0,1.94,14.56]],"ltp":1.94,"tv":6.92,"id":16676046}],"tv":83.71}]}
{"op":"mcm","clk":"1007794285","pt":1580656933503,"mc":[{"id":"1.168237985","rc":[{"trd":[[4.2,79.99]],"batl":[[0,4.6,19.59],[1,4.6,0]],"ltp":4.2,"tv":79.99,"id":16676048},{"batb":[[0,1.87,18.33]],"ltp":1.94,"tv":6.92,"id":16676046}],"tv":86.91}]}
{"op":"mcm","clk":"1007871872","pt":1580657275659,"mc":[{"id":"1.168237985","rc":[{"batb":[[0,4.1,20.46]],"batl":[[0,4.7,19.43]],"ltp":4.2,"tv":79.99,"id":16676048},{"batb":[[0,1.87,18.1]],"batl":[[0,1.95,17.78]],"ltp":1.94,"tv":6.92,"id":16676046},{"batl":[[0,9.4,9.36]],"ltp":0.0,"tv":0.0,"id":21483494},{"batb":[[0,6.8,12.98]],"batl":[[0,8.2,12.27]],"ltp":0.0,"tv":0.0,"id":21483493}]}]}
{"op":"mcm","clk":"1007874221","pt":1580657285809,"mc":[{"id":"1.168237985","rc":[{"batb":[[0,4.2,20.3]],"batl":[[0,4.7,19.28]],"ltp":4.2,"tv":79.99,"id":16676048},{"batb":[[0,1.88,17.86]],"batl":[[0,1.96,17.55]],"ltp":1.94,"tv":6.92,"id":16676046},{"batb":[[0,7.6,10.15]],"batl":[[0,9.2,9.6]],"ltp":0.0,"tv":0.0,"id":21483494}]}]}
{"op":"mcm","clk":"1007876473","pt":1580657295612,"mc":[{"id":"1.168237985","rc":[{"batb":[[0,4.2,20.06]],"batl":[[0,4.7,19.12]],"ltp":4.2,"tv":79.99,"id":16676048},{"batb":[[0,1.89,17.62]],"batl":[[0,1.97,17.31]],"ltp":1.94,"tv":6.92,"id":16676046},{"batb":[[0,6.6,13.69]],"batl":[[0,8,12.9]],"ltp":0.0,"tv":0.0,"id":21483493}]}]}
{"op":"mcm","clk":"1007878677","pt":1580657304603,"mc":[{"id":"1.168237985","rc":[{"batb":[[0,4.3,5],[1,4.2,20.06],[2,1.03,2]],"ltp":4.2,"tv":79.99,"id":16676048},{"batb":[[1,1.87,8],[2,1.02,2]],"ltp":1.94,"tv":6.92,"id":16676046},{"batb":[[0,7.8,6],[1,7.6,10.15],[2,1.02,2]],"ltp":0.0,"tv":0.0,"id":21483494},{"batb":[[1,6.2,4],[2,1.02,2]],"ltp":0.0,"tv":0.0,"id":21483493}]}]}
{"op":"mcm","clk":"1007911135","pt":1580657450146,"mc":[{"id":"1.168237985","rc":[{"batb":[[2,1.02,2]],"ltp":4.2,"tv":79.99,"id":16676048}]}]}
{"op":"mcm","clk":"1008031570","pt":1580657987377,"mc":[{"id":"1.168237985","marketDefinition":{"bspMarket":false,"turnInPlayEnabled":true,"persistenceEnabled":true,"marketBaseRate":5.0,"eventId":"29681871","eventTypeId":"2","numberOfWinners":1,"bettingType":"ODDS","marketType":"SET_BETTING","marketTime":"2020-02-02T15:20:00.000Z","suspendTime":"2020-02-02T15:20:00.000Z","bspReconciled":false,"complete":true,"inPlay":false,"crossMatching":true,"runnersVoidable":false,"numberOfActiveRunners":4,"betDelay":0,"status":"OPEN","runners":[{"status":"ACTIVE","sortPriority":1,"id":21483493,"name":"Diaz Acosta 2-0"},{"status":"ACTIVE","sortPriority":2,"id":21483494,"name":"Diaz Acosta 2-1"},{"status":"ACTIVE","sortPriority":3,"id":16676046,"name":"Martinez 2-0"},{"status":"ACTIVE","sortPriority":4,"id":16676048,"name":"Martinez 2-1"}],"regulators":["MR_INT"],"countryCode":"AR","discountAllowed":true,"timezone":"UTC","openDate":"2020-02-02T15:20:00.000Z","version":3149466720,"name":"Set Betting","eventName":"Diaz Acosta v Martinez"},"rc":[{"batb":[[1,1.02,2],[2,1.01,1.01]],"ltp":4.2,"tv":79.99,"id":16676048},{"batb":[[0,1.87,8],[1,1.02,2],[2,1.01,1.01]],"ltp":1.94,"tv":6.92,"id":16676046},{"batb":[[1,1.02,2],[2,1.01,1.01]],"ltp":0.0,"tv":0.0,"id":21483494},{"batb":[[0,6.2,4],[1,1.02,2],[2,1.01,1.01]],"ltp":0.0,"tv":0.0,"id":21483493}]}]}
{"op":"mcm","clk":"1008031747","pt":1580657988210,"mc":[{"id":"1.168237985","marketDefinition":{"bspMarket":false,"turnInPlayEnabled":true,"persistenceEnabled":true,"marketBaseRate":5.0,"eventId":"29681871","eventTypeId":"2","numberOfWinners":1,"bettingType":"ODDS","marketType":"SET_BETTING","marketTime":"2020-02-02T15:20:00.000Z","suspendTime":"2020-02-02T15:20:00.000Z","bspReconciled":false,"complete":true,"inPlay":true,"crossMatching":true,"runnersVoidable":false,"numberOfActiveRunners":4,"betDelay":3,"status":"OPEN","runners":[{"status":"ACTIVE","sortPriority":1,"id":21483493,"name":"Diaz Acosta 2-0"},{"status":"ACTIVE","sortPriority":2,"id":21483494,"name":"Diaz Acosta 2-1"},{"status":"ACTIVE","sortPriority":3,"id":16676046,"name":"Martinez 2-0"},{"status":"ACTIVE","sortPriority":4,"id":16676048,"name":"Martinez 2-1"}],"regulators":["MR_INT"],"countryCode":"AR","discountAllowed":true,"timezone":"UTC","openDate":"2020-02-02T15:20:00.000Z","version":3149542074,"name":"Set Betting","eventName":"Diaz Acosta v Martinez"},"rc":[{"batb":[[0,1.01,0.51],[1,1.02,0],[2,1.01,0]],"ltp":4.2,"tv":79.99,"id":16676048},{"batb":[[0,1.01,0.51],[1,1.02,0],[2,1.01,0]],"ltp":1.94,"tv":6.92,"id":16676046},{"batb":[[0,1.01,0.51],[1,1.02,0],[2,1.01,0]],"ltp":0.0,"tv":0.0,"id":21483494},{"batb":[[0,1.01,0.51],[1,1.02,0],[2,1.01,0]],"ltp":0.0,"tv":0.0,"id":21483493}]}]}
{"op":"mcm","clk":"1008033549","pt":1580657995685,"mc":[{"id":"1.168237985","rc":[{"batb":[[0,4,22.5],[1,3.8,12.9],[2,1.01,0.51]],"batl":[[0,4.5,21.32],[1,4.7,19.28]],"ltp":4.2,"tv":79.99,"id":16676048},{"batb":[[0,2.02,28.4],[1,1.91,16.92],[2,1.01,0.51]],"batl":[[0,2.14,27.62],[1,2.34,21.17]],"ltp":1.94,"tv":6.92,"id":16676046},{"batb":[[0,7.4,11.17],[1,7.2,11.88],[2,1.01,0.51]],"batl":[[0,8.8,10.62],[1,9,10.07]],"ltp":0.0,"tv":0.0,"id":21483494},{"batb":[[0,5.8,18.96],[1,5.1,13.06],[2,1.01,0.51]],"batl":[[0,7,17.7],[1,7.8,13.93]],"ltp":0.0,"tv":0.0,"id":21483493}]}]}
{"op":"mcm","clk":"1008034798","pt":1580658000875,"mc":[{"id":"1.168237985","rc":[{"batb":[[0,4,80.51],[1,3.95,27.73],[2,3.8,12.9]],"ltp":4.2,"tv":79.99,"id":16676048},{"batb":[[0,2.02,134.88],[1,2,66.76],[2,1.91,16.92]],"ltp":1.94,"tv":6.92,"id":16676046},{"batb":[[0,7.8,16.92],[1,7.6,25.35],[2,7.4,11.17]],"ltp":0.0,"tv":0.0,"id":21483494},{"batb":[[0,6,49.54],[1,5.9,21.89],[2,5.8,18.96]],"ltp":0.0,"tv":0.0,"id":21483493}]}]}
{"op":"mcm","clk":"1008036952","pt":1580658009866,"mc":[{"id":"1.168237985","rc":[{"batb":[[0,3.8,12.9],[1,1.01,0.51],[2,3.8,0]],"batl":[[0,4.7,19.28],[1,4.7,0]],"ltp":4.2,"tv":79.99,"id":16676048},{"batb":[[0,1.91,16.92],[1,1.01,0.51],[2,1.91,0]],"batl":[[0,2.34,21.17],[1,2.34,0]],"ltp":1.94,"tv":6.92,"id":16676046},{"batb":[[0,7.2,11.88],[1,1.01,0.51],[2,7.4,0]],"batl":[[0,9,10.07],[1,9,0]],"ltp":0.0,"tv":0.0,"id":21483494},{"batb":[[0,5.1,13.06],[1,1.01,0.51],[2,5.8,0]],"batl":[[0,7.8,13.93],[1,7.8,0]],"ltp":0.0,"tv":0.0,"id":21483493}]}]}
{"op":"mcm","clk":"1008037741","pt":1580658012881,"mc":[{"id":"1.168237985","rc":[{"batb":[[0,7.4,25.49],[1,7.2,11.88],[2,1.01,0.51]],"ltp":0.0,"tv":0.0,"id":21483494}]}]}
{"op":"mcm","clk":"1008038182","pt":1580658014892,"mc":[{"id":"1.168237985","rc":[{"batb":[[0,4,31.52],[1,3.95,27.97],[2,3.8,12.9]],"ltp":4.2,"tv":79.99,"id":16676048},{"batb":[[0,2.06,106.24],[1,2.04,62.87],[2,1.91,16.92]],"ltp":1.94,"tv":6.92,"id":16676046},{"batb":[[0,7.6,33.85],[1,7.4,25.49],[2,7.2,11.88]],"ltp":0.0,"tv":0.0,"id":21483494},{"batb":[[0,5.9,26.32],[1,5.8,23.07],[2,5.1,13.06]],"ltp":0.0,"tv":0.0,"id":21483493}]}]}
{"op":"mcm","clk":"1008038851","pt":1580658017589,"mc":[{"id":"1.168237985","rc":[{"batb":[[0,3.8,12.9],[1,1.01,0.51],[2,3.8,0]],"ltp":4.2,"tv":79.99,"id":16676048},{"batb":[[0,1.91,16.92],[1,1.01,0.51],[2,1.91,0]],"ltp":1.94,"tv":6.92,"id":16676046},{"batb":[[0,7.4,25.49],[1,7.2,11.88],[2,1.01,0.51]],"ltp":0.0,"tv":0.0,"id":21483494},{"batb":[[0,5.1,13.06],[1,1.01,0.51],[2,5.1,0]],"ltp":0.0,"tv":0.0,"id":21483493}]}]}
{"op":"mcm","clk":"1008039486","pt":1580658020307,"mc":[{"id":"1.168237985","rc":[{"batb":[[0,3.8,56.11],[1,3.75,31.53],[2,1.01,0.51]],"ltp":4.2,"tv":79.99,"id":16676048},{"batb":[[0,1.92,54.69],[1,1.91,16.92],[2,1.9,78.24]],"ltp":1.94,"tv":6.92,"id":16676046},{"batb":[[1,7.2,40.15]],"ltp":0.0,"tv":0.0,"id":21483494},{"batb":[[0,5.2,25.25],[1,5.1,43.84],[2,1.01,0.51]],"ltp":0.0,"tv":0.0,"id":21483493}]}]}
{"op":"mcm","clk":"1008040847","pt":1580658026008,"mc":[{"id":"1.168237985","rc":[{"batb":[[0,3.8,12.9],[1,1.01,0.51],[2,1.01,0]],"ltp":4.2,"tv":79.99,"id":16676048},{"batb":[[0,7.2,11.88],[1,1.01,0.51],[2,1.01,0]],"ltp":0.0,"tv":0.0,"id":21483494},{"batb":[[0,5.1,13.06],[1,1.01,0.51],[2,1.01,0]],"ltp":0.0,"tv":0.0,"id":21483493}]}]}
{"op":"mcm","clk":"1008041658","pt":1580658028990,"mc":[{"id":"1.168237985","rc":[{"batb":[[0,4.2,33.03],[1,4.1,50.59],[2,3.8,12.9]],"ltp":4.2,"tv":79.99,"id":16676048},{"batb":[[0,8,19.54],[1,7.8,23.91],[2,7.2,11.88]],"ltp":0.0,"tv":0.0,"id":21483494},{"batb":[[0,6.8,33.19],[1,6.6,33.97],[2,5.1,13.06]],"ltp":0.0,"tv":0.0,"id":21483493}]}]}
{"op":"mcm","clk":"1008041909","pt":1580658030024,"mc":[{"id":"1.168237985","rc":[{"batb":[[0,4.2,53.33],[2,3.9,23.76]],"batl":[[1,4.9,17.39]],"ltp":4.2,"tv":79.99,"id":16676048},{"batl":[[0,2,16.6],[1,2.2,25.41],[2,2.34,21.17]],"ltp":1.94,"tv":6.92,"id":16676046},{"batb":[[2,7.4,10.62]],"batl":[[1,9.4,9.6]],"ltp":0.0,"tv":0.0,"id":21483494},{"batb":[[2,6.4,14.79]],"batl":[[1,8.8,10.54]],"ltp":0.0,"tv":0.0,"id":21483493}]}]}
{"op":"mcm","clk":"1008041953","pt":1580658030192,"mc":[{"id":"1.168237985","rc":[{"batl":[[2,2.34,0]],"ltp":1.94,"tv":6.92,"id":16676046}]}]}
{"op":"mcm","clk":"1008046192","pt":1580658047328,"mc":[{"id":"1.168237985","rc":[{"batb":[[0,3.9,23.76],[1,1.01,0.51],[2,3.9,0]],"batl":[[0,4.9,17.39],[1,4.9,0]],"ltp":4.2,"tv":79.99,"id":16676048},{"batb":[[0,1.81,20.22],[1,1.01,0.51],[2,1.9,0]],"batl":[[0,2.2,25.41],[1,2.2,0]],"ltp":1.94,"tv":6.92,"id":16676046},{"batb":[[0,7.2,11.57],[1,1.01,0.51],[2,7.4,0]],"batl":[[0,9.4,9.6],[1,9.4,0]],"ltp":0.0,"tv":0.0,"id":21483494},{"batb":[[0,5.7,10.31],[1,1.01,0.51],[2,6.4,0]],"batl":[[0,8.8,10.54],[1,8.8,0]],"ltp":0.0,"tv":0.0,"id":21483493}]}]}
{"op":"mcm","clk":"1008046920","pt":1580658050139,"mc":[{"id":"1.168237985","rc":[{"batb":[[0,3.95,41.67],[1,3.9,52.49],[2,1.01,0.51]],"ltp":4.2,"tv":79.99,"id":16676048},{"batb":[[0,1.82,72.04],[1,1.81,20.22],[2,1.8,93.1]],"ltp":1.94,"tv":6.92,"id":16676046},{"batb":[[0,7.6,26.84],[1,7.4,26.61],[2,7.2,11.57]],"ltp":0.0,"tv":0.0,"id":21483494},{"batb":[[0,5.8,22.03],[1,5.7,34.35],[2,1.01,0.51]],"ltp":0.0,"tv":0.0,"id":21483493}]}]}
{"op":"mcm","clk":"1008048299","pt":1580658055728,"mc":[{"id":"1.168237985","rc":[{"batb":[[0,1.81,20.22],[1,1.01,0.51],[2,1.8,0]],"ltp":1.94,"tv":6.92,"id":16676046}]}]}
{"op":"mcm","clk":"1008048973","pt":1580658058638,"mc":[{"id":"1.168237985","rc":[{"batb":[[0,2.1,66.9],[1,2.08,59.37],[2,1.81,20.22]],"ltp":1.94,"tv":6.92,"id":16676046}]}]}
{"op":"mcm","clk":"1008049231","pt":1580658059833,"mc":[{"id":"1.168237985","rc":[{"batb":[[2,3.7,13.61]],"batl":[[0,4.4,22.5],[1,4.6,19.83]],"ltp":4.2,"tv":79.99,"id":16676048},{"batb":[[1,2.08,85.49],[2,1.94,16.29]],"batl":[[1,2.46,18.49]],"ltp":1.94,"tv":6.92,"id":16676046},{"batl":[[0,8.8,10.94],[1,9,10.31]],"ltp":0.0,"tv":0.0,"id":21483494},{"batb":[[2,4.8,14.95]],"batl":[[0,6.6,19.28],[1,7.6,14.4]],"ltp":0.0,"tv":0.0,"id":21483493}]}]}
{"op":"mcm","clk":"1008053977","pt":1580658081116,"mc":[{"id":"1.168237985","rc":[{"batb":[[0,3.7,13.61],[1,1.01,0.51],[2,3.7,0]],"batl":[[0,4.6,19.83],[1,4.6,0]],"ltp":4.2,"tv":79.99,"id":16676048},{"batb":[[0,1.94,16.29],[1,1.01,0.51],[2,1.94,0]],"batl":[[0,2.46,18.49],[1,2.46,0]],"ltp":1.94,"tv":6.92,"id":16676046},{"batb":[[0,7,12.35],[1,1.01,0.51],[2,7.2,0]],"batl":[[0,9,10.31],[1,9,0]],"ltp":0.0,"tv":0.0,"id":21483494},{"batb":[[0,4.8,14.95],[1,1.01,0.51],[2,4.8,0]],"batl":[[0,7.6,14.4],[1,7.6,0]],"ltp":0.0,"tv":0.0,"id":21483493}]}]}
{"op":"mcm","clk":"1008054702","pt":1580658084291,"mc":[{"id":"1.168237985","rc":[{"batb":[[0,3.7,41.75],[1,3.65,33.77],[2,1.01,0.51]],"ltp":4.2,"tv":79.99,"id":16676048},{"batb":[[0,1.95,61.76],[1,1.94,16.29],[2,1.93,74.5]],"ltp":1.94,"tv":6.92,"id":16676046},{"batb":[[0,7.2,30.39],[1,7,42.29],[2,1.01,0.51]],"ltp":0.0,"tv":0.0,"id":21483494},{"batb":[[0,4.8,41.13],[1,4.7,37.03],[2,1.01,0.51]],"ltp":0.0,"tv":0.0,"id":21483493}]}]}
{"op":"mcm","clk":"1008054957","pt":1580658085368,"mc":[{"id":"1.168237985","rc":[{"batb":[[0,3.7,13.61],[1,1.01,0.51],[2,1.01,0]],"ltp":4.2,"tv":79.99,"id":16676048},{"batb":[[0,1.94,16.29],[1,1.01,0.51],[2,1.93,0]],"ltp":1.94,"tv":6.92,"id":16676046},{"batb":[[0,7,12.35],[1,1.01,0.51],[2,1.01,0]],"ltp":0.0,"tv":0.0,"id":21483494},{"batb":[[0,4.8,14.95],[1,1.01,0.51],[2,1.01,0]],"ltp":0.0,"tv":0.0,"id":21483493}]}]}
{"op":"mcm","clk":"1008055707","pt":1580658088783,"mc":[{"id":"1.168237985","rc":[{"batb":[[0,3.9,37.41],[1,3.85,29.66],[2,3.7,13.61]],"ltp":4.2,"tv":79.99,"id":16676048},{"batb":[[0,2.16,50.56],[1,2.14,54.64],[2,1.94,16.29]],"ltp":1.94,"tv":6.92,"id":16676046},{"batb":[[0,7.6,16.36],[1,7.4,26.86],[2,7,12.35]],"ltp":0.0,"tv":0.0,"id":21483494},{"batb":[[0,5.5,40.91],[1,5.4,26.84],[2,4.8,14.95]],"ltp":0.0,"tv":0.0,"id":21483493}]}]}
{"op":"mcm","clk":"1008055914","pt":1580658089803,"mc":[{"id":"1.168237985","rc":[{"batb":[[0,3.7,13.61],[1,1.01,0.51],[2,3.7,0]],"ltp":4.2,"tv":79.99,"id":16676048},{"batb":[[0,1.94,16.29],[1,1.01,0.51],[2,1.94,0]],"ltp":1.94,"tv":6.92,"id":16676046},{"batb":[[0,7,12.35],[1,1.01,0.51],[2,7,0]],"ltp":0.0,"tv":0.0,"id":21483494},{"batb":[[0,4.8,14.95],[1,1.01,0.51],[2,4.8,0]],"ltp":0.0,"tv":0.0,"id":21483493}]}]}
{"op":"mcm","clk":"1008056576","pt":1580658092680,"mc":[{"id":"1.168237985","rc":[{"batb":[[0,3.7,41.75],[1,3.65,33.77],[2,1.01,0.51]],"ltp":4.2,"tv":79.99,"id":16676048},{"batb":[[0,1.95,61.76],[1,1.94,16.29],[2,1.93,74.5]],"ltp":1.94,"tv":6.92,"id":16676046},{"batb":[[0,7.2,30.39],[1,7,42.29],[2,1.01,0.51]],"ltp":0.0,"tv":0.0,"id":21483494},{"batb":[[0,4.8,41.13],[1,4.7,37.03],[2,1.01,0.51]],"ltp":0.0,"tv":0.0,"id":21483493}]}]}
{"op":"mcm","clk":"1008057753","pt":1580658098012,"mc":[{"id":"1.168237985","rc":[{"batb":[[0,3.7,13.61],[1,1.01,0.51],[2,1.01,0]],"ltp":4.2,"tv":79.99,"id":16676048},{"batb":[[0,1.94,16.29],[1,1.01,0.51],[2,1.93,0]],"ltp":1.94,"tv":6.92,"id":16676046},{"batb":[[0,7,12.35],[1,1.01,0.51],[2,1.01,0]],"ltp":0.0,"tv":0.0,"id":21483494},{"batb":[[0,4.8,14.95],[1,1.01,0.51],[2,1.01,0]],"ltp":0.0,"tv":0.0,"id":21483493}]}]}
{"op":"mcm","clk":"1008058472","pt":1580658101006,"mc":[{"id":"1.168237985","rc":[{"batb":[[0,3.7,41.75],[1,3.65,33.77],[2,1.01,0.51]],"ltp":4.2,"tv":79.99,"id":16676048},{"batb":[[0,2.4,69.95],[1,2.36,82],[2,1.94,16.29]],"ltp":1.94,"tv":6.92,"id":16676046},{"batb":[[0,7.2,30.39],[1,7,42.29],[2,1.01,0.51]],"ltp":0.0,"tv":0.0,"id":21483494},{"batb":[[0,4.8,41.13],[1,4.7,37.03],[2,1.01,0.51]],"ltp":0.0,"tv":0.0,"id":21483493}]}]}
{"op":"mcm","clk":"1008058687","pt":1580658101882,"mc":[{"id":"1.168237985","rc":[{"batb":[[2,3.5,15.74]],"batl":[[0,4.1,13.22],[1,4.3,23.68]],"ltp":4.2,"tv":79.99,"id":16676048},{"batb":[[2,2.32,18.96]],"batl":[[1,2.78,13.45]],"ltp":1.94,"tv":6.92,"id":16676046},{"batb":[[2,6.8,13.3]],"batl":[[0,8.4,11.72],[1,8.8,10.94]],"ltp":0.0,"tv":0.0,"id":21483494},{"batb":[[2,4.2,20.14]],"batl":[[0,5.5,14.32],[1,6.2,11.17]],"ltp":0.0,"tv":0.0,"id":21483493}]}]}
{"op":"mcm","clk":"1008063593","pt":1580658122878,"mc":[{"id":"1.168237985","rc":[{"batb":[[0,3.5,15.74],[1,1.01,0.51],[2,3.5,0]],"batl":[[0,4.3,23.68],[1,4.3,0]],"ltp":4.2,"tv":79.99,"id":16676048},{"batb":[[0,2.16,23.6],[1,1.01,0.51],[2,2.32,0]],"batl":[[0,2.78,13.45],[1,2.78,0]],"ltp":1.94,"tv":6.92,"id":16676046},{"batb":[[0,6.8,13.3],[1,1.01,0.51],[2,6.8,0]],"batl":[[0,8.8,10.94],[1,8.8,0]],"ltp":0.0,"tv":0.0,"id":21483494},{"batb":[[0,4.2,20.14],[1,1.01,0.51],[2,4.2,0]],"batl":[[0,6.2,11.17],[1,6.2,0]],"ltp":0.0,"tv":0.0,"id":21483493}]}]}
{"op":"mcm","clk":"1008064303","pt":1580658125874,"mc":[{"id":"1.168237985","rc":[{"batb":[[0,3.55,15.26],[1,3.45,46.99],[2,3.4,39.9]],"batl":[[0,4.3,23.21]],"ltp":4.2,"tv":79.99,"id":16676048},{"batb":[[0,2.2,79.95],[1,2.18,74.79],[2,1.01,0.51]],"batl":[[0,2.82,13.14]],"ltp":1.94,"tv":6.92,"id":16676046},{"batb":[[0,6.8,42.94],[1,6.6,47.57],[2,1.01,0.51]],"batl":[[0,8.6,11.49]],"ltp":0.0,"tv":0.0,"id":21483494},{"batb":[[1,4.1,32.47],[2,4,53.61]],"batl":[[0,6,11.72]],"ltp":0.0,"tv":0.0,"id":21483493}]}]}
{"op":"mcm","clk":"1008065453","pt":1580658130659,"mc":[{"id":"1.168237985","rc":[{"batb":[[0,2.18,23.05],[1,1.01,0.51],[2,1.01,0]],"ltp":1.94,"tv":6.92,"id":16676046}]}]}
{"op":"mcm","clk":"1008066094","pt":1580658133412,"mc":[{"id":"1.168237985","rc":[{"batb":[[0,2.8,55.81],[1,2.76,54.01],[2,2.18,23.05]],"ltp":1.94,"tv":6.92,"id":16676046}]}]}
{"op":"mcm","clk":"1008066352","pt":1580658134596,"mc":[{"id":"1.168237985","rc":[{"batb":[[2,3.4,56.9]],"batl":[[0,3.85,14.79],[1,4.1,13.14]],"ltp":4.2,"tv":79.99,"id":16676048},{"batb":[[2,2.66,13.38]],"batl":[[1,3.15,24.94]],"ltp":1.94,"tv":6.92,"id":16676046},{"batl":[[0,8,13.06],[1,8.2,12.27]],"ltp":0.0,"tv":0.0,"id":21483494},{"batl":[[0,4.7,19.99],[1,5.3,15.5]],"ltp":0.0,"tv":0.0,"id":21483493}]}]}
{"op":"mcm","clk":"1008068341","pt":1580658143006,"mc":[{"id":"1.168237985","rc":[{"batb":[[2,3.4,56.74]],"ltp":4.2,"tv":79.99,"id":16676048},{"batb":[[2,2.68,12.98]],"batl":[[0,2.84,12.75],[1,3.2,24.47]],"ltp":1.94,"tv":6.92,"id":16676046},{"batb":[[2,6.4,15.03]],"batl":[[0,8,12.75],[1,8.2,0]],"ltp":0.0,"tv":0.0,"id":21483494},{"batb":[[0,4.1,54.26],[1,4,53.61],[2,3.8,13.22]],"batl":[[0,4.6,20.69],[1,5.2,15.82]],"ltp":0.0,"tv":0.0,"id":21483493}]}]}
{"op":"mcm","clk":"1008069510","pt":1580658147983,"mc":[{"id":"1.168237985","rc":[{"batb":[[0,2.68,12.98],[1,2.42,17.15],[2,1.01,0.51]],"ltp":1.94,"tv":6.92,"id":16676046}]}]}
{"op":"mcm","clk":"1008070213","pt":1580658151022,"mc":[{"id":"1.168237985","rc":[{"batb":[[0,3.55,14.95],[2,3.4,56.5]],"batl":[[0,3.9,14.56]],"ltp":4.2,"tv":79.99,"id":16676048},{"batb":[[0,2.82,43.84],[1,2.78,53.2],[2,2.7,12.83]],"batl":[[0,2.86,12.59],[1,3.2,24.08]],"ltp":1.94,"tv":6.92,"id":16676046},{"batb":[[1,6.6,33.72]],"batl":[[0,7.8,13.61],[1,8,12.75]],"ltp":0.0,"tv":0.0,"id":21483494}]}]}
{"op":"mcm","clk":"1008072212","pt":1580658159181,"mc":[{"id":"1.168237985","rc":[{"batb":[[0,4.1,21.79]],"ltp":0.0,"tv":0.0,"id":21483493}]}]}
{"op":"mcm","clk":"1008073151","pt":1580658162996,"mc":[{"id":"1.168237985","rc":[{"batb":[[1,4,73.42],[2,3.95,27.48]],"ltp":0.0,"tv":0.0,"id":21483493}]}]}
{"op":"mcm","clk":"1008075009","pt":1580658170771,"mc":[{"id":"1.168237985","rc":[{"batb":[[1,3.4,16.6],[2,1.01,0.51]],"ltp":4.2,"tv":79.99,"id":16676048},{"batb":[[0,2.7,12.83],[1,2.42,16.92],[2,1.01,0.51]],"ltp":1.94,"tv":6.92,"id":16676046},{"batb":[[0,6.6,33.72],[1,6.4,15.03],[2,1.01,0.51]],"ltp":0.0,"tv":0.0,"id":21483494},{"batb":[[1,3.8,13.22],[2,1.01,0.51]],"ltp":0.0,"tv":0.0,"id":21483493}]}]}
{"op":"mcm","clk":"1008075741","pt":1580658173683,"mc":[{"id":"1.168237985","rc":[{"batb":[[2,3.35,33.32]],"ltp":4.2,"tv":79.99,"id":16676048},{"batb":[[1,2.52,41.87],[2,2.48,72.01]],"ltp":1.94,"tv":6.92,"id":16676046},{"batb":[[0,6.6,44.74],[1,6.4,50.98]],"ltp":0.0,"tv":0.0,"id":21483494},{"batb":[[2,3.75,43.65]],"ltp":0.0,"tv":0.0,"id":21483493}]}]}
{"op":"mcm","clk":"1008076404","pt":1580658176252,"mc":[{"id":"1.168237985","rc":[{"batb":[[0,3.4,16.6],[1,3.35,33.32],[2,3.3,42.98]],"batl":[[0,4.1,13.14],[1,4.1,0]],"ltp":4.2,"tv":79.99,"id":16676048},{"batb":[[0,2.52,41.87],[1,2.48,72.01],[2,2.42,16.92]],"batl":[[0,3.2,24.08],[1,3.2,0]],"ltp":1.94,"tv":6.92,"id":16676046},{"batl":[[0,8,12.75],[1,8,0]],"ltp":0.0,"tv":0.0,"id":21483494},{"batb":[[0,3.8,13.22],[1,3.75,43.65],[2,3.7,32.41]],"batl":[[0,5.2,15.82],[1,5.2,0]],"ltp":0.0,"tv":0.0,"id":21483493}]}]}
{"op":"mcm","clk":"1008077355","pt":1580658179960,"mc":[{"id":"1.168237985","rc":[{"batb":[[0,2.44,16.76],[1,1.01,0.51],[2,2.42,0]],"batl":[[0,3.2,23.76]],"ltp":1.94,"tv":6.92,"id":16676046},{"batl":[[0,5.1,16.37]],"ltp":0.0,"tv":0.0,"id":21483493}]}]}
{"op":"mcm","clk":"1008078038","pt":1580658182956,"mc":[{"id":"1.168237985","rc":[{"batb":[[0,3.1,65.81],[1,3.05,52.25],[2,2.44,16.76]],"ltp":1.94,"tv":6.92,"id":16676046}]}]}
{"op":"mcm","clk":"1008078240","pt":1580658183863,"mc":[{"id":"1.168237985","rc":[{"batb":[[2,3.3,61]],"batl":[[0,3.7,16.13],[1,3.9,14.56]],"ltp":4.2,"tv":79.99,"id":16676048},{"batb":[[2,2.98,24.71]],"batl":[[1,3.6,18.25]],"ltp":1.94,"tv":6.92,"id":16676046},{"batb":[[2,6.2,15.82]],"batl":[[0,7.8,13.53]],"ltp":0.0,"tv":0.0,"id":21483494},{"batl":[[0,4.2,12.98],[1,4.6,20.54]],"ltp":0.0,"tv":0.0,"id":21483493}]}]}
{"op":"mcm","clk":"1008080621","pt":1580658193873,"mc":[{"id":"1.168237985","rc":[{"batb":[[0,3.3,18.02],[1,1.01,0.51],[2,3.3,0]],"batl":[[0,3.9,14.56],[1,3.9,0]],"ltp":4.2,"tv":79.99,"id":16676048},{"batb":[[0,2.68,13.06],[1,1.01,0.51],[2,2.98,0]],"batl":[[0,3.6,18.25],[1,3.6,0]],"ltp":1.94,"tv":6.92,"id":16676046},{"batb":[[0,6.6,17.92],[1,6.4,35.95]],"ltp":0.0,"tv":0.0,"id":21483494},{"batb":[[0,3.5,16.44],[1,1.01,0.51],[2,3.7,0]],"batl":[[0,4.6,20.54],[1,4.6,0]],"ltp":0.0,"tv":0.0,"id":21483493}]}]}
{"op":"mcm","clk":"1008081327","pt":1580658196866,"mc":[{"id":"1.168237985","rc":[{"batb":[[1,3.25,46.98],[2,3.2,46.23]],"ltp":4.2,"tv":79.99,"id":16676048},{"batb":[[0,2.78,49.02],[1,2.74,55.29],[2,2.68,13.06]],"ltp":1.94,"tv":6.92,"id":16676046},{"batb":[[0,3.5,69.89],[1,3.45,55.04],[2,1.01,0.51]],"ltp":0.0,"tv":0.0,"id":21483493}]}]}
{"op":"mcm","clk":"1008081467","pt":1580658197479,"mc":[{"id":"1.168237985","rc":[{"batb":[[0,3.3,17.78],[1,1.01,0.51],[2,3.2,0]],"batl":[[0,3.9,14.4]],"ltp":4.2,"tv":79.99,"id":16676048},{"batb":[[0,2.68,12.9],[1,1.01,0.51],[2,2.68,0]],"batl":[[0,3.6,18.02]],"ltp":1.94,"tv":6.92,"id":16676046},{"batb":[[0,3.45,16.76],[1,1.01,0.51],[2,1.01,0]],"ltp":0.0,"tv":0.0,"id":21483493}]}]}
{"op":"mcm","clk":"1008082252","pt":1580658200874,"mc":[{"id":"1.168237985","rc":[{"batb":[[1,3.25,65.86],[2,3.2,46.23]],"batl":[[0,3.6,17.23],[1,3.7,16.05]],"ltp":4.2,"tv":79.99,"id":16676048},{"batb":[[0,3.45,30.51],[1,3.4,40.22],[2,3.3,18.65]],"batl":[[1,4,14.4]],"ltp":1.94,"tv":6.92,"id":16676046},{"batl":[[0,7.6,14.79]],"ltp":0.0,"tv":0.0,"id":21483494},{"batb":[[0,3.5,53.45],[1,3.45,55.04],[2,3.25,19.2]],"batl":[[0,3.8,16.21],[1,4.1,13.38]],"ltp":0.0,"tv":0.0,"id":21483493}]}]}
{"op":"mcm","clk":"1008084207","pt":1580658209084,"mc":[{"id":"1.168237985","rc":[{"batb":[[0,6.4,35.95],[1,6.2,15.82],[2,1.01,0.51]],"ltp":0.0,"tv":0.0,"id":21483494}]}]}
{"op":"mcm","clk":"1008085101","pt":1580658212772,"mc":[{"id":"1.168237985","rc":[{"batb":[[1,3.25,18.88]],"ltp":4.2,"tv":79.99,"id":16676048},{"batb":[[0,3.3,18.65],[1,3,24.08],[2,1.01,0.51]],"ltp":1.94,"tv":6.92,"id":16676046},{"batb":[[1,6.2,54.08]],"ltp":0.0,"tv":0.0,"id":21483494},{"batb":[[0,3.45,16.76],[1,3.25,19.2],[2,1.01,0.51]],"ltp":0.0,"tv":0.0,"id":21483493}]}]}
{"op":"mcm","clk":"1008085334","pt":1580658213809,"mc":[{"id":"1.168237985","rc":[{"batb":[[0,3.25,18.88],[1,3.2,46.23],[2,1.01,0.51]],"batl":[[0,3.7,16.05],[1,3.7,0]],"ltp":4.2,"tv":79.99,"id":16676048},{"batb":[[0,3,24.08],[1,1.01,0.51],[2,1.01,0]],"batl":[[0,4,14.4],[1,4,0]],"ltp":1.94,"tv":6.92,"id":16676046},{"batb":[[0,3.25,19.2],[1,1.01,0.51],[2,1.01,0]],"batl":[[0,4.1,13.38],[1,4.1,0]],"ltp":0.0,"tv":0.0,"id":21483493}]}]}
{"op":"mcm","clk":"1008085857","pt":1580658215998,"mc":[{"id":"1.168237985","rc":[{"batb":[[2,3.15,48.08]],"ltp":4.2,"tv":79.99,"id":16676048},{"batb":[[0,3.1,70.91],[1,3.05,52.28],[2,3,24.08]],"ltp":1.94,"tv":6.92,"id":16676046},{"batb":[[0,3.35,32.77],[1,3.3,42.79],[2,3.25,19.2]],"ltp":0.0,"tv":0.0,"id":21483493}]}]}
{"op":"mcm","clk":"1008086103","pt":1580658216979,"mc":[{"id":"1.168237985","rc":[{"batl":[[0,3.75,15.97]],"ltp":4.2,"tv":79.99,"id":16676048},{"batl":[[0,7.6,14.32]],"ltp":0.0,"tv":0.0,"id":21483494}]}]}
{"op":"mcm","clk":"1008086800","pt":1580658219891,"mc":[{"id":"1.168237985","rc":[{"batb":[[0,3,24.08],[1,1.01,0.51],[2,3,0]],"ltp":1.94,"tv":6.92,"id":16676046}]}]}
{"op":"mcm","clk":"1008087104","pt":1580658221099,"mc":[{"id":"1.168237985","rc":[{"batb":[[1,1.01,0.51],[2,3.15,0]],"ltp":4.2,"tv":79.99,"id":16676048},{"batb":[[0,6.2,15.82],[1,1.01,0.51],[2,1.01,0]],"ltp":0.0,"tv":0.0,"id":21483494},{"batb":[[0,3.25,19.2],[1,1.01,0.51],[2,3.25,0]],"ltp":0.0,"tv":0.0,"id":21483493}]}]}
{"op":"mcm","clk":"1008087557","pt":1580658222980,"mc":[{"id":"1.168237985","rc":[{"batb":[[0,3.7,55.52],[1,3.65,33.73],[2,3,24.08]],"ltp":1.94,"tv":6.92,"id":16676046}]}]}
{"op":"mcm","clk":"1008087758","pt":1580658223889,"mc":[{"id":"1.168237985","rc":[{"batb":[[1,3.2,19.28],[2,1.01,0.51]],"batl":[[0,3.55,17.7],[1,3.75,15.97]],"ltp":4.2,"tv":79.99,"id":16676048},{"batb":[[0,3.65,14.71],[1,3.4,17.78]],"batl":[[1,4.3,23.92]],"ltp":1.94,"tv":6.92,"id":16676046},{"batl":[[0,7.4,14.95],[1,7.6,14.32]],"ltp":0.0,"tv":0.0,"id":21483494},{"batb":[[1,3.1,21.95],[2,1.01,0.51]],"batl":[[0,3.55,18.8],[1,3.75,16.6],[2,4.1,13.38]],"ltp":0.0,"tv":0.0,"id":21483493}]}]}
{"op":"mcm","clk":"1008087839","pt":1580658224363,"mc":[{"id":"1.168237985","rc":[{"batl":[[1,3.75,0]],"ltp":4.2,"tv":79.99,"id":16676048},{"batb":[[2,1.01,0.51]],"ltp":1.94,"tv":6.92,"id":16676046},{"batl":[[1,7.6,0]],"ltp":0.0,"tv":0.0,"id":21483494},{"batl":[[2,4.1,0]],"ltp":0.0,"tv":0.0,"id":21483493}]}]}
{"op":"mcm","clk":"1008090377","pt":1580658234503,"mc":[{"id":"1.168237985","rc":[{"batb":[[0,3.2,19.28],[1,1.01,0.51],[2,1.01,0]],"ltp":4.2,"tv":79.99,"id":16676048},{"batb":[[0,3.4,17.78],[1,1.01,0.51],[2,1.01,0]],"batl":[[0,4.3,23.92],[1,4.3,0]],"ltp":1.94,"tv":6.92,"id":16676046},{"batb":[[0,3.1,21.95],[1,1.01,0.51],[2,1.01,0]],"batl":[[0,3.75,16.6],[1,3.75,0]],"ltp":0.0,"tv":0.0,"id":21483493}]}]}
{"op":"mcm","clk":"1008091199","pt":1580658237899,"mc":[{"id":"1.168237985","rc":[{"batb":[[0,3.2,55.98],[1,3.15,48.22],[2,1.01,0.51]],"ltp":4.2,"tv":79.99,"id":16676048},{"batb":[[0,6.4,17.73],[1,6.2,54.95],[2,1.01,0.51]],"ltp":0.0,"tv":0.0,"id":21483494}]}]}
{"op":"mcm","clk":"1008091634","pt":1580658239708,"mc":[{"id":"1.168237985","rc":[{"batb":[[0,3.2,76.9]],"ltp":4.2,"tv":79.99,"id":16676048},{"batb":[[0,3.65,57.54],[1,3.6,34.86],[2,3.4,17.78]],"ltp":1.94,"tv":6.92,"id":16676046},{"batb":[[0,6.4,34.24]],"ltp":0.0,"tv":0.0,"id":21483494},{"batb":[[0,3.35,57.27],[1,3.3,42.56],[2,3.1,21.95]],"ltp":0.0,"tv":0.0,"id":21483493}]}]}
{"op":"mcm","clk":"1008092788","pt":1580658244699,"mc":[{"id":"1.168237985","rc":[{"batb":[[0,3.2,55.98]],"ltp":4.2,"tv":79.99,"id":16676048},{"batb":[[0,3.4,17.78],[1,1.01,0.51],[2,3.4,0]],"ltp":1.94,"tv":6.92,"id":16676046},{"batb":[[0,6.4,17.73]],"ltp":0.0,"tv":0.0,"id":21483494},{"batb":[[0,3.1,21.95],[1,1.01,0.51],[2,3.1,0]],"ltp":0.0,"tv":0.0,"id":21483493}]}]}
{"op":"mcm","clk":"1008093593","pt":1580658247917,"mc":[{"id":"1.168237985","rc":[{"batb":[[0,3.5,36.18],[1,3.45,38.84],[2,3.4,17.78]],"ltp":1.94,"tv":6.92,"id":16676046},{"batb":[[0,3.2,76.99],[1,3.15,47.58],[2,3.1,21.95]],"ltp":0.0,"tv":0.0,"id":21483493}]}]}
{"op":"mcm","clk":"1008094076","pt":1580658249938,"mc":[{"id":"1.168237985","rc":[{"batb":[[0,3.4,17.78],[1,1.01,0.51],[2,3.4,0]],"ltp":1.94,"tv":6.92,"id":16676046}]}]}
{"op":"mcm","clk":"1008094808","pt":1580658253031,"mc":[{"id":"1.168237985","rc":[{"batb":[[0,3.95,28.39],[1,3.9,29.14],[2,3.4,17.78]],"ltp":1.94,"tv":6.92,"id":16676046}]}]}
{"op":"mcm","clk":"1008095041","pt":1580658254036,"mc":[{"id":"1.168237985","rc":[{"batb":[[1,3.15,68.52]],"batl":[[0,3.5,18.65],[1,3.55,17.7]],"ltp":4.2,"tv":79.99,"id":16676048},{"batb":[[2,3.85,25.34]],"batl":[[1,5,17.07]],"ltp":1.94,"tv":6.92,"id":16676046},{"batb":[[0,6.2,39.13],[1,6,17.62]],"ltp":0.0,"tv":0.0,"id":21483494},{"batb":[[0,3.2,46.02]],"batl":[[0,3.4,21.17],[1,3.6,18.1]],"ltp":0.0,"tv":0.0,"id":21483493}]}]}
{"op":"mcm","clk":"1008095745","pt":1580658257033,"mc":[{"id":"1.168237985","rc":[{"batb":[[0,3.2,71.73]],"ltp":4.2,"tv":79.99,"id":16676048},{"batb":[[0,3.95,42.68]],"ltp":1.94,"tv":6.92,"id":16676046},{"batb":[[0,6.2,46.33],[1,6,58.57]],"ltp":0.0,"tv":0.0,"id":21483494}]}]}
{"op":"mcm","clk":"1008103159","pt":1580658290175,"mc":[{"id":"1.168237985","rc":[{"batb":[[0,3.2,19.28],[1,3.15,54]],"ltp":4.2,"tv":79.99,"id":16676048},{"batb":[[0,3.85,25.34],[1,3.55,15.89],[2,1.01,0.51]],"ltp":1.94,"tv":6.92,"id":16676046},{"batb":[[0,6.2,18.7]],"ltp":0.0,"tv":0.0,"id":21483494},{"batb":[[0,3.1,21.95],[1,2.92,10.46],[2,1.01,0.51]],"ltp":0.0,"tv":0.0,"id":21483493}]}]}
{"op":"mcm","clk":"1008103788","pt":1580658293047,"mc":[{"id":"1.168237985","rc":[{"batb":[[0,3.15,54],[1,3.1,50.3]],"batl":[[0,3.55,17.7],[1,3.55,0]],"ltp":4.2,"tv":79.99,"id":16676048},{"batb":[[0,3.6,57.8],[1,3.55,52.23]],"batl":[[0,5,17.07],[1,5,0]],"ltp":1.94,"tv":6.92,"id":16676046},{"batb":[[0,2.98,34.14],[1,2.94,45.52],[2,2.92,10.46]],"batl":[[0,3.6,18.1],[1,3.6,0]],"ltp":0.0,"tv":0.0,"id":21483493}]}]}
{"op":"mcm","clk":"1008104419","pt":1580658295851,"mc":[{"id":"1.168237985","rc":[{"batb":[[0,3.15,20.3],[1,1.01,0.51],[2,1.01,0]],"ltp":4.2,"tv":79.99,"id":16676048},{"batb":[[1,6,17.62]],"ltp":0.0,"tv":0.0,"id":21483494},{"batb":[[0,2.92,10.46],[1,1.01,0.51],[2,2.92,0]],"ltp":0.0,"tv":0.0,"id":21483493}]}]}
{"op":"mcm","clk":"1008105046","pt":1580658298761,"mc":[{"id":"1.168237985","rc":[{"batb":[[0,3.25,49.85],[1,3.2,46.43],[2,3.15,20.3]],"ltp":4.2,"tv":79.99,"id":16676048},{"batb":[[0,6.4,25.25],[1,6.2,38.67],[2,6,17.62]],"ltp":0.0,"tv":0.0,"id":21483494},{"batb":[[0,3.35,65.85],[1,3.3,42.22],[2,2.92,10.46]],"ltp":0.0,"tv":0.0,"id":21483493}]}]}
{"op":"mcm","clk":"1008105328","pt":1580658299910,"mc":[{"id":"1.168237985","rc":[{"batb":[[0,3.25,68.34],[1,3.2,65.79],[2,1.01,0.51]],"batl":[[1,3.65,17]],"ltp":4.2,"tv":79.99,"id":16676048},{"batb":[[2,3.25,19.51]],"batl":[[0,3.85,15.5],[1,4.4,22.9]],"ltp":1.94,"tv":6.92,"id":16676046},{"batb":[[2,6,17]],"ltp":0.0,"tv":0.0,"id":21483494},{"batb":[[1,3.3,60.87],[2,3.05,22.42]],"batl":[[1,3.85,15.66]],"ltp":0.0,"tv":0.0,"id":21483493}]}]}
{"op":"mcm","clk":"1008108789","pt":1580658314845,"mc":[{"id":"1.168237985","rc":[{"batb":[[0,3.2,65.79],[1,1.01,0.51],[2,1.01,0]],"batl":[[0,3.65,17],[1,3.65,0]],"ltp":4.2,"tv":79.99,"id":16676048},{"batb":[[0,3.25,19.51],[1,1.01,0.51],[2,3.25,0]],"batl":[[0,4.4,22.9],[1,4.4,0]],"ltp":1.94,"tv":6.92,"id":16676046},{"batb":[[0,6.2,38.67],[1,6,17],[2,1.01,0.51]],"ltp":0.0,"tv":0.0,"id":21483494},{"batb":[[0,3.05,22.42],[1,1.01,0.51],[2,3.05,0]],"batl":[[0,3.85,15.66],[1,3.85,0]],"ltp":0.0,"tv":0.0,"id":21483493}]}]}
{"op":"mcm","clk":"1008109290","pt":1580658317241,"mc":[{"id":"1.168237985","rc":[{"batb":[[1,3.15,48.29],[2,1.01,0.51]],"ltp":4.2,"tv":79.99,"id":16676048},{"batb":[[0,3.4,32.04],[1,3.35,42.07],[2,3.25,19.51]],"ltp":1.94,"tv":6.92,"id":16676046},{"batb":[[1,6,58.11]],"ltp":0.0,"tv":0.0,"id":21483494},{"batb":[[0,3.15,48.14],[1,3.1,49.5],[2,3.05,22.42]],"ltp":0.0,"tv":0.0,"id":21483493}]}]}
{"op":"mcm","clk":"1008109746","pt":1580658319256,"mc":[{"id":"1.168237985","rc":[{"batb":[[0,3.2,19.36],[1,1.01,0.51],[2,1.01,0]],"ltp":4.2,"tv":79.99,"id":16676048},{"batb":[[1,6,17]],"ltp":0.0,"tv":0.0,"id":21483494},{"batb":[[0,3.05,22.42],[1,1.01,0.51],[2,3.05,0]],"ltp":0.0,"tv":0.0,"id":21483493}]}]}
{"op":"mcm","clk":"1008110522","pt":1580658322874,"mc":[{"id":"1.168237985","rc":[{"batb":[[0,3.3,38.83],[1,3.25,63.22],[2,1.01,0.51]],"batl":[[0,3.65,16.68]],"ltp":4.2,"tv":79.99,"id":16676048},{"batl":[[0,3.55,18.8],[1,3.85,15.34]],"ltp":1.94,"tv":6.92,"id":16676046},{"batb":[[0,6.4,41.1],[1,6.2,55.19]],"batl":[[0,7.6,14.95]],"ltp":0.0,"tv":0.0,"id":21483494},{"batb":[[0,3.55,34.65],[1,3.5,52.95],[2,3.3,18.65]],"batl":[[1,4.1,13.85]],"ltp":0.0,"tv":0.0,"id":21483493}]}]}
{"op":"mcm","clk":"1008113218","pt":1580658334962,"mc":[{"id":"1.168237985","rc":[{"batb":[[0,3.25,63.22],[1,1.01,0.51],[2,1.01,0]],"ltp":4.2,"tv":79.99,"id":16676048},{"batb":[[0,3.1,22.42],[1,1.01,0.51],[2,3.25,0]],"batl":[[0,3.85,15.34],[1,3.85,0]],"ltp":1.94,"tv":6.92,"id":16676046},{"batb":[[0,6.4,22.26]],"ltp":0.0,"tv":0.0,"id":21483494},{"batb":[[0,3.3,18.65],[1,1.01,0.51],[2,3.3,0]],"batl":[[0,4.1,13.85],[1,4.1,0]],"ltp":0.0,"tv":0.0,"id":21483493}]}]}
{"op":"mcm","clk":"1008113718","pt":1580658337576,"mc":[{"id":"1.168237985","rc":[{"batb":[[1,3.2,46.38],[2,1.01,0.51]],"ltp":4.2,"tv":79.99,"id":16676048},{"batb":[[0,3.25,33.44],[1,3.2,47.05],[2,3.1,22.42]],"ltp":1.94,"tv":6.92,"id":16676046},{"batb":[[0,3.35,45.24],[1,3.3,61.06],[2,1.01,0.51]],"ltp":0.0,"tv":0.0,"id":21483493}]}]}
{"op":"mcm","clk":"1008113887","pt":1580658338496,"mc":[{"id":"1.168237985","rc":[{"batb":[[1,1.01,0.51],[2,1.01,0]],"ltp":4.2,"tv":79.99,"id":16676048},{"batb":[[1,6.2,16.52]],"ltp":0.0,"tv":0.0,"id":21483494},{"batb":[[0,3.3,18.65],[1,1.01,0.51],[2,1.01,0]],"ltp":0.0,"tv":0.0,"id":21483493}]}]}
{"op":"mcm","clk":"1008114597","pt":1580658341975,"mc":[{"id":"1.168237985","rc":[{"batb":[[0,3.35,17.31],[1,3.3,57.38],[2,3.25,44.81]],"batl":[[0,3.7,16.44]],"ltp":4.2,"tv":79.99,"id":16676048},{"batl":[[0,3.35,21.56],[1,3.55,18.96]],"ltp":1.94,"tv":6.92,"id":16676046},{"batb":[[0,6.6,16.39],[1,6.4,36.33],[2,6.2,15.97]],"batl":[[0,7.6,14.63]],"ltp":0.0,"tv":0.0,"id":21483494},{"batb":[[0,3.7,14.24],[1,3.65,55.3],[2,3.6,34.21]],"batl":[[1,4.3,24.86]],"ltp":0.0,"tv":0.0,"id":21483493}]}]}
{"op":"mcm","clk":"1008117212","pt":1580658355000,"mc":[{"id":"1.168237985","rc":[{"batb":[[0,2.98,24.78],[1,1.01,0.51],[2,3.1,0]],"batl":[[0,3.55,18.96],[1,3.55,0]],"ltp":1.94,"tv":6.92,"id":16676046},{"batb":[[0,6.4,36.33],[1,6.2,15.97],[2,1.01,0.51]],"ltp":0.0,"tv":0.0,"id":21483494},{"batb":[[0,3.5,16.37],[1,1.01,0.51],[2,3.6,0]],"batl":[[0,4.3,24.86],[1,4.3,0]],"ltp":0.0,"tv":0.0,"id":21483493}]}]}
{"op":"mcm","clk":"1008117825","pt":1580658357801,"mc":[{"id":"1.168237985","rc":[{"batb":[[1,6.2,54.26]],"ltp":0.0,"tv":0.0,"id":21483494}]}]}
{"op":"mcm","clk":"1008118490","pt":1580658360913,"mc":[{"id":"1.168237985","rc":[{"batb":[[0,3.25,58.04],[1,3.2,46.84],[2,2.98,24.78]],"ltp":1.94,"tv":6.92,"id":16676046},{"batb":[[0,6.4,50.52]],"ltp":0.0,"tv":0.0,"id":21483494},{"batb":[[0,3.65,36.25],[1,3.6,34.38],[2,3.5,16.37]],"ltp":0.0,"tv":0.0,"id":21483493}]}]}
{"op":"mcm","clk":"1008118868","pt":1580658362808,"mc":[{"id":"1.168237985","rc":[{"batb":[[0,2.98,24.78],[1,1.01,0.51],[2,2.98,0]],"ltp":1.94,"tv":6.92,"id":16676046},{"batb":[[0,6.4,39.97]],"ltp":0.0,"tv":0.0,"id":21483494},{"batb":[[0,3.5,16.37],[1,1.01,0.51],[2,3.5,0]],"ltp":0.0,"tv":0.0,"id":21483493}]}]}
{"op":"mcm","clk":"1008119525","pt":1580658365997,"mc":[{"id":"1.168237985","rc":[{"batb":[[0,3.55,30.42],[1,3.5,53.23],[2,1.01,0.51]],"ltp":0.0,"tv":0.0,"id":21483493}]}]}
{"op":"mcm","clk":"1008120169","pt":1580658368995,"mc":[{"id":"1.168237985","rc":[{"batb":[[0,3.35,42.15],[1,2.98,24.78],[2,1.01,0.51]],"ltp":1.94,"tv":6.92,"id":16676046},{"batb":[[0,6.4,36.33]],"ltp":0.0,"tv":0.0,"id":21483494},{"batb":[[0,3.5,53.23],[1,1.01,0.51],[2,1.01,0]],"ltp":0.0,"tv":0.0,"id":21483493}]}]}
{"op":"mcm","clk":"1008120327","pt":1580658369838,"mc":[{"id":"1.168237985","rc":[{"batb":[[0,3.3,75.4],[1,3.25,44.81],[2,1.01,0.51]],"batl":[[0,3.65,16.76],[1,3.7,16.44]],"ltp":4.2,"tv":79.99,"id":16676048},{"batb":[[1,3.25,19.67],[2,3.05,22.66]],"batl":[[1,3.85,15.5]],"ltp":1.94,"tv":6.92,"id":16676046},{"batb":[[1,3.25,19.2],[2,1.01,0.51]],"batl":[[0,3.8,15.82],[1,4.1,13.93]],"ltp":0.0,"tv":0.0,"id":21483493}]}]}
{"op":"mcm","clk":"1008120807","pt":1580658371899,"mc":[{"id":"1.168237985","rc":[{"batb":[[0,3.4,35.97],[1,3.35,42.15],[2,3.25,19.67]],"ltp":1.94,"tv":6.92,"id":16676046},{"batb":[[0,3.5,67.33],[1,3.45,37.83],[2,3.25,19.2]],"ltp":0.0,"tv":0.0,"id":21483493}]}]}
{"op":"mcm","clk":"1008123105","pt":1580658382840,"mc":[{"id":"1.168237985","rc":[{"batb":[[0,3.3,60.84]],"batl":[[0,3.7,16.44],[1,3.7,0]],"ltp":4.2,"tv":79.99,"id":16676048},{"batb":[[0,3.05,22.66],[1,1.01,0.51],[2,3.25,0]],"batl":[[0,3.85,15.5],[1,3.85,0]],"ltp":1.94,"tv":6.92,"id":16676046},{"batb":[[0,6.2,54.26],[1,1.01,0.51],[2,1.01,0]],"ltp":0.0,"tv":0.0,"id":21483494},{"batb":[[0,3.25,19.2],[1,1.01,0.51],[2,3.25,0]],"batl":[[0,4.1,13.93],[1,4.1,0]],"ltp":0.0,"tv":0.0,"id":21483493}]}]}
{"op":"mcm","clk":"1008123696","pt":1580658385842,"mc":[{"id":"1.168237985","rc":[{"batb":[[0,3.25,43.21],[1,3.2,47.09],[2,3.05,22.66]],"ltp":1.94,"tv":6.92,"id":16676046},{"batb":[[0,6.2,69.9],[1,6,40.54],[2,1.01,0.51]],"ltp":0.0,"tv":0.0,"id":21483494},{"batb":[[0,3.3,72.41],[1,3.25,62.81],[2,1.01,0.51]],"ltp":0.0,"tv":0.0,"id":21483493}]}]}
{"op":"mcm","clk":"1008125472","pt":1580658394748,"mc":[{"id":"1.168237985","rc":[{"batb":[[0,3.05,22.66],[1,1.01,0.51],[2,3.05,0]],"ltp":1.94,"tv":6.92,"id":16676046},{"batb":[[0,6.2,54.26],[1,1.01,0.51],[2,1.01,0]],"ltp":0.0,"tv":0.0,"id":21483494},{"batb":[[0,3.25,19.2],[1,1.01,0.51],[2,1.01,0]],"ltp":0.0,"tv":0.0,"id":21483493}]}]}
{"op":"mcm","clk":"1008126044","pt":1580658397555,"mc":[{"id":"1.168237985","rc":[{"batb":[[0,3.3,85.52]],"ltp":4.2,"tv":79.99,"id":16676048},{"batb":[[0,3.4,35.97],[1,3.35,42.15],[2,3.05,22.66]],"ltp":1.94,"tv":6.92,"id":16676046},{"batb":[[0,6.4,32.2],[1,6.2,54.26],[2,1.01,0.51]],"ltp":0.0,"tv":0.0,"id":21483494},{"batb":[[0,3.5,50.96],[1,3.45,37.83],[2,3.25,19.2]],"ltp":0.0,"tv":0.0,"id":21483493}]}]}
{"op":"mcm","clk":"1008126361","pt":1580658399042,"mc":[{"id":"1.168237985","rc":[{"batl":[[0,3.85,784.2]],"ltp":1.94,"tv":6.92,"id":16676046},{"batl":[[0,4.1,809.58]],"ltp":0.0,"tv":0.0,"id":21483493}]}]}
{"op":"mcm","clk":"1008129711","pt":1580658415864,"mc":[{"id":"1.168237985","rc":[{"batb":[[0,3.3,60.84]],"ltp":4.2,"tv":79.99,"id":16676048},{"batb":[[0,3.05,22.66],[1,1.01,0.51],[2,3.05,0]],"batl":[[0,3.85,15.5]],"ltp":1.94,"tv":6.92,"id":16676046},{"batb":[[0,6.2,54.26],[1,1.01,0.51],[2,1.01,0]],"ltp":0.0,"tv":0.0,"id":21483494},{"batb":[[0,3.25,19.2],[1,1.01,0.51],[2,3.25,0]],"batl":[[0,4.1,13.93]],"ltp":0.0,"tv":0.0,"id":21483493}]}]}
{"op":"mcm","clk":"1008130280","pt":1580658418773,"mc":[{"id":"1.168237985","rc":[{"batb":[[0,3.25,43.21],[1,3.2,47.09],[2,3.05,22.66]],"ltp":1.94,"tv":6.92,"id":16676046},{"batb":[[0,6.2,69.9],[1,6,40.54],[2,1.01,0.51]],"ltp":0.0,"tv":0.0,"id":21483494},{"batb":[[0,3.3,72.41],[1,3.25,62.81],[2,1.01,0.51]],"ltp":0.0,"tv":0.0,"id":21483493}]}]}
{"op":"mcm","clk":"1008131188","pt":1580658422983,"mc":[{"id":"1.168237985","rc":[{"batb":[[1,1.01,0.51],[2,1.01,0]],"ltp":4.2,"tv":79.99,"id":16676048},{"batb":[[0,3.05,22.66],[1,1.01,0.51],[2,3.05,0]],"ltp":1.94,"tv":6.92,"id":16676046},{"batb":[[0,6.2,54.26],[1,1.01,0.51],[2,1.01,0]],"ltp":0.0,"tv":0.0,"id":21483494},{"batb":[[0,3.25,19.2],[1,1.01,0.51],[2,1.01,0]],"ltp":0.0,"tv":0.0,"id":21483493}]}]}
{"op":"mcm","clk":"1008131849","pt":1580658425970,"mc":[{"id":"1.168237985","rc":[{"batb":[[0,3.35,56.86],[1,3.3,60.84],[2,3.25,18.57]],"batl":[[1,3.85,14.79]],"ltp":4.2,"tv":79.99,"id":16676048},{"batb":[[0,3.25,43.21],[1,3.2,47.09],[2,3.05,22.66]],"batl":[[0,3.35,21.79],[1,3.8,15.97],[2,3.85,15.5]],"ltp":1.94,"tv":6.92,"id":16676046},{"batb":[[0,6.4,43.65],[1,6.2,54.26],[2,1.01,0.51]],"ltp":0.0,"tv":0.0,"id":21483494},{"batb":[[0,3.7,14.4],[1,3.65,32.35],[2,3.6,34.28]],"batl":[[1,4.6,20.85]],"ltp":0.0,"tv":0.0,"id":21483493}]}]}
{"op":"mcm","clk":"1008132024","pt":1580658426888,"mc":[{"id":"1.168237985","rc":[{"batb":[[1,3.3,42.82]],"ltp":4.2,"tv":79.99,"id":16676048},{"batl":[[2,3.85,0]],"ltp":1.94,"tv":6.92,"id":16676046},{"batl":[[0,7.6,14.16]],"ltp":0.0,"tv":0.0,"id":21483494}]}]}
{"op":"mcm","clk":"1008135250","pt":1580658442839,"mc":[{"id":"1.168237985","rc":[{"batb":[[0,3.4,17],[1,3.35,39.79],[2,3.3,42.82]],"ltp":4.2,"tv":79.99,"id":16676048},{"batl":[[0,4,14.01]],"ltp":0.0,"tv":0.0,"id":21483493}]}]}
{"op":"mcm","clk":"1008150424","pt":1580658517806,"mc":[{"id":"1.168237985","rc":[{"batb":[[0,3.25,18.57],[1,1.01,0.51],[2,3.3,0]],"batl":[[0,3.85,14.79],[1,3.85,0]],"ltp":4.2,"tv":79.99,"id":16676048},{"batb":[[0,2.72,12.51],[1,1.01,0.51],[2,3.05,0]],"batl":[[0,3.8,15.97],[1,3.8,0]],"ltp":1.94,"tv":6.92,"id":16676046},{"batb":[[0,6.2,54.26],[1,1.01,0.51],[2,1.01,0]],"ltp":0.0,"tv":0.0,"id":21483494},{"batb":[[0,3.35,17.86],[1,1.01,0.51],[2,3.6,0]],"batl":[[0,4.6,20.85],[1,4.6,0]],"ltp":0.0,"tv":0.0,"id":21483493}]}]}
{"op":"mcm","clk":"1008150988","pt":1580658521026,"mc":[{"id":"1.168237985","rc":[{"batb":[[0,3.25,58.06],[1,3.2,46.64],[2,1.01,0.51]],"ltp":4.2,"tv":79.99,"id":16676048},{"batb":[[0,6.2,68.9],[1,6,40.56],[2,1.01,0.51]],"ltp":0.0,"tv":0.0,"id":21483494},{"batb":[[0,3.35,77.66],[1,3.3,42.1],[2,1.01,0.51]],"ltp":0.0,"tv":0.0,"id":21483493}]}]}
{"op":"mcm","clk":"1008151291","pt":1580658522523,"mc":[{"id":"1.168237985","rc":[{"batb":[[0,3.65,51.6],[1,3.6,35.29],[2,2.72,12.51]],"ltp":1.94,"tv":6.92,"id":16676046}]}]}
{"op":"mcm","clk":"1008151529","pt":1580658523595,"mc":[{"id":"1.168237985","rc":[{"batb":[[2,3.15,20.06]],"batl":[[0,3.55,17.86],[1,3.7,16.37]],"ltp":4.2,"tv":79.99,"id":16676048},{"batb":[[2,3.5,16.44]],"batl":[[1,4.4,23.37]],"ltp":1.94,"tv":6.92,"id":16676046},{"batb":[[1,6,57.63]],"batl":[[0,7.4,15.5],[1,7.6,14.16]],"ltp":0.0,"tv":0.0,"id":21483494},{"batb":[[2,3.15,21.32]],"batl":[[0,3.65,17.39],[1,4.1,13.45]],"ltp":0.0,"tv":0.0,"id":21483493}]}]}
{"op":"mcm","clk":"1008153871","pt":1580658535633,"mc":[{"id":"1.168237985","rc":[{"batb":[[0,3.15,20.06],[1,1.01,0.51],[2,3.15,0]],"batl":[[0,3.7,16.37],[1,3.7,0]],"ltp":4.2,"tv":79.99,"id":16676048},{"batb":[[0,3,23.53],[1,1.01,0.51],[2,3.5,0]],"batl":[[0,4.4,23.37],[1,4.4,0]],"ltp":1.94,"tv":6.92,"id":16676046},{"batb":[[0,6.2,27.2]],"batl":[[0,7.6,14.16],[1,7.6,0]],"ltp":0.0,"tv":0.0,"id":21483494},{"batb":[[0,3.15,21.32],[1,1.01,0.51],[2,3.15,0]],"batl":[[0,4.1,13.45],[1,4.1,0]],"ltp":0.0,"tv":0.0,"id":21483493}]}]}
{"op":"mcm","clk":"1008154229","pt":1580658537544,"mc":[{"id":"1.168237985","rc":[{"batb":[[1,6,17.07]],"ltp":0.0,"tv":0.0,"id":21483494}]}]}
{"op":"mcm","clk":"1008154854","pt":1580658540743,"mc":[{"id":"1.168237985","rc":[{"batb":[[0,3.25,59.44],[1,3.2,46.48],[2,3.15,20.06]],"ltp":4.2,"tv":79.99,"id":16676048},{"batb":[[0,3.55,46.18],[1,3.5,37.82],[2,3,23.53]],"ltp":1.94,"tv":6.92,"id":16676046},{"batb":[[0,6.4,20.91],[1,6.2,38.58],[2,6,17.07]],"ltp":0.0,"tv":0.0,"id":21483494},{"batb":[[0,3.4,68.5],[1,3.35,40.48],[2,3.15,21.32]],"ltp":0.0,"tv":0.0,"id":21483493}]}]}
{"op":"mcm","clk":"1008155901","pt":1580658546845,"mc":[{"id":"1.168237985","rc":[{"batb":[[0,3.15,20.06],[1,1.01,0.51],[2,3.15,0]],"ltp":4.2,"tv":79.99,"id":16676048},{"batb":[[0,3,23.53],[1,1.01,0.51],[2,3,0]],"ltp":1.94,"tv":6.92,"id":16676046},{"batb":[[0,6.2,27.2],[1,6,17.07],[2,1.01,0.51]],"ltp":0.0,"tv":0.0,"id":21483494},{"batb":[[0,3.15,21.32],[1,1.01,0.51],[2,3.15,0]],"ltp":0.0,"tv":0.0,"id":21483493}]}]}
{"op":"mcm","clk":"1008156424","pt":1580658549889,"mc":[{"id":"1.168237985","rc":[{"batb":[[0,3.15,84.25],[1,3.1,50.19],[2,1.01,0.51]],"ltp":4.2,"tv":79.99,"id":16676048},{"batb":[[0,3.15,70.96],[1,3.1,50.7],[2,3,23.53]],"ltp":1.94,"tv":6.92,"id":16676046},{"batb":[[1,6,58.31]],"ltp":0.0,"tv":0.0,"id":21483494},{"batb":[[0,3.15,81.38],[1,3.1,49.19],[2,1.01,0.51]],"ltp":0.0,"tv":0.0,"id":21483493}]}]}
{"op":"mcm","clk":"1008157904","pt":1580658557960,"mc":[{"id":"1.168237985","rc":[{"batb":[[0,3.15,20.06],[1,1.01,0.51],[2,1.01,0]],"ltp":4.2,"tv":79.99,"id":16676048},{"batb":[[0,3,23.53],[1,1.01,0.51],[2,3,0]],"ltp":1.94,"tv":6.92,"id":16676046},{"batb":[[1,6,17.07]],"ltp":0.0,"tv":0.0,"id":21483494},{"batb":[[0,3.15,21.32],[1,1.01,0.51],[2,1.01,0]],"ltp":0.0,"tv":0.0,"id":21483493}]}]}
{"op":"mcm","clk":"1008158420","pt":1580658560751,"mc":[{"id":"1.168237985","rc":[{"batb":[[0,3.35,49.73],[1,3.3,43.21],[2,3.15,20.06]],"ltp":4.2,"tv":79.99,"id":16676048},{"batb":[[0,3.15,70.96],[1,3.1,50.7],[2,3,23.53]],"ltp":1.94,"tv":6.92,"id":16676046},{"batb":[[0,6.4,49.9],[1,6.2,37.82],[2,6,17.07]],"ltp":0.0,"tv":0.0,"id":21483494},{"batb":[[0,3.7,45.78],[1,3.65,33.03],[2,3.15,21.32]],"ltp":0.0,"tv":0.0,"id":21483493}]}]}
{"op":"mcm","clk":"1008158526","pt":1580658561378,"mc":[{"id":"1.168237985","rc":[{"batb":[[0,3.4,16.92],[1,3.35,49.73],[2,3.3,43.21]],"batl":[[1,3.95,14.16]],"ltp":4.2,"tv":79.99,"id":16676048},{"batl":[[0,3.3,22.66],[1,3.8,15.97]],"ltp":1.94,"tv":6.92,"id":16676046},{"batb":[[1,6.2,54.34],[2,1.01,0.51]],"batl":[[1,7.8,13.85]],"ltp":0.0,"tv":0.0,"id":21483494},{"batb":[[0,3.75,13.85],[1,3.7,45.78],[2,3.65,33.03]],"batl":[[1,4.8,19.43]],"ltp":0.0,"tv":0.0,"id":21483493}]}]}
{"op":"mcm","clk":"1008161524","pt":1580658577800,"mc":[{"id":"1.168237985","rc":[{"batb":[[0,3.25,18.8],[1,1.01,0.51],[2,3.3,0]],"batl":[[0,3.95,14.16],[1,3.95,0]],"ltp":4.2,"tv":79.99,"id":16676048},{"batb":[[0,2.62,13.77],[1,1.01,0.51],[2,3,0]],"batl":[[0,3.8,15.97],[1,3.8,0]],"ltp":1.94,"tv":6.92,"id":16676046},{"batb":[[0,6.2,54.34],[1,1.01,0.51],[2,1.01,0]],"batl":[[0,7.8,13.85],[1,7.8,0]],"ltp":0.0,"tv":0.0,"id":21483494},{"batb":[[0,3.4,17.62],[1,1.01,0.51],[2,3.65,0]],"batl":[[0,4.8,19.43],[1,4.8,0]],"ltp":0.0,"tv":0.0,"id":21483493}]}]}
{"op":"mcm","clk":"1008162078","pt":1580658580806,"mc":[{"id":"1.168237985","rc":[{"batb":[[0,6.2,16.52]],"ltp":0.0,"tv":0.0,"id":21483494}]}]}
{"op":"mcm","clk":"1008162561","pt":1580658583391,"mc":[{"id":"1.168237985","rc":[{"batb":[[0,3.4,37.6],[1,3.35,41.77],[2,3.25,18.8]],"ltp":4.2,"tv":79.99,"id":16676048},{"batb":[[0,3.05,63.24],[1,3,55.12],[2,2.62,13.77]],"ltp":1.94,"tv":6.92,"id":16676046},{"batb":[[0,6.6,22.77],[1,6.4,35.98],[2,6.2,16.52]],"ltp":0.0,"tv":0.0,"id":21483494},{"batb":[[0,3.8,43.72],[1,3.75,30.97],[2,3.4,17.62]],"ltp":0.0,"tv":0.0,"id":21483493}]}]}
{"op":"mcm","clk":"1008163401","pt":1580658588223,"mc":[{"id":"1.168237985","rc":[{"batb":[[0,3.25,18.8],[1,1.01,0.51],[2,3.25,0]],"ltp":4.2,"tv":79.99,"id":16676048},{"batb":[[0,2.62,13.77],[1,1.01,0.51],[2,2.62,0]],"ltp":1.94,"tv":6.92,"id":16676046},{"batb":[[0,6.2,16.52],[1,1.01,0.51],[2,6.2,0]],"ltp":0.0,"tv":0.0,"id":21483494},{"batb":[[0,3.4,17.62],[1,1.01,0.51],[2,3.4,0]],"ltp":0.0,"tv":0.0,"id":21483493}]}]}
{"op":"mcm","clk":"1008163929","pt":1580658591209,"mc":[{"id":"1.168237985","rc":[{"batb":[[1,3.2,74.82],[2,3.15,48.18]],"ltp":4.2,"tv":79.99,"id":16676048},{"batb":[[0,2.7,38.54],[1,2.66,60.43],[2,2.62,13.77]],"ltp":1.94,"tv":6.92,"id":16676046},{"batb":[[0,6.2,70.64],[1,6,40.52],[2,1.01,0.51]],"ltp":0.0,"tv":0.0,"id":21483494},{"batb":[[0,3.4,50.89],[1,3.35,40.81],[2,1.01,0.51]],"ltp":0.0,"tv":0.0,"id":21483493}]}]}
{"op":"mcm","clk":"1008165938","pt":1580658602823,"mc":[{"id":"1.168237985","rc":[{"batb":[[0,2.62,13.77],[1,1.01,0.51],[2,2.62,0]],"ltp":1.94,"tv":6.92,"id":16676046}]}]}
{"op":"mcm","clk":"1008166413","pt":1580658605426,"mc":[{"id":"1.168237985","rc":[{"batb":[[0,3.65,46.82],[1,3.6,35.33],[2,2.62,13.77]],"ltp":1.94,"tv":6.92,"id":16676046}]}]}
{"op":"mcm","clk":"1008166621","pt":1580658606726,"mc":[{"id":"1.168237985","rc":[{"batb":[[2,3.15,68.64]],"batl":[[0,3.55,18.1],[1,3.7,16.21]],"ltp":4.2,"tv":79.99,"id":16676048},{"batb":[[2,3.5,16.52]],"batl":[[1,4.5,22.19]],"ltp":1.94,"tv":6.92,"id":16676046},{"batb":[[0,6.2,54.12],[1,6,58.07]],"batl":[[0,7.4,15.5],[1,7.6,14.79]],"ltp":0.0,"tv":0.0,"id":21483494},{"batb":[[2,3.1,21.56]],"batl":[[0,3.7,17],[1,4.2,12.9]],"ltp":0.0,"tv":0.0,"id":21483493}]}]}
{"op":"mcm","clk":"1008169589","pt":1580658624010,"mc":[{"id":"1.168237985","rc":[{"batb":[[0,3.15,55.82],[1,1.01,0.51],[2,3.15,0]],"batl":[[0,3.7,16.21],[1,3.7,0]],"ltp":4.2,"tv":79.99,"id":16676048},{"batb":[[0,2.98,24.55],[1,1.01,0.51],[2,3.5,0]],"batl":[[0,4.5,22.19],[1,4.5,0]],"ltp":1.94,"tv":6.92,"id":16676046},{"batb":[[0,6.2,24.41]],"batl":[[0,7.6,14.79],[1,7.6,0]],"ltp":0.0,"tv":0.0,"id":21483494},{"batb":[[0,3.1,21.56],[1,1.01,0.51],[2,3.1,0]],"batl":[[0,4.2,12.9],[1,4.2,0]],"ltp":0.0,"tv":0.0,"id":21483493}]}]}
{"op":"mcm","clk":"1008170137","pt":1580658627042,"mc":[{"id":"1.168237985","rc":[{"batb":[[0,3.15,20.46]],"ltp":4.2,"tv":79.99,"id":16676048},{"batb":[[1,6,17.55]],"ltp":0.0,"tv":0.0,"id":21483494}]}]}
{"op":"mcm","clk":"1008170524","pt":1580658629451,"mc":[{"id":"1.168237985","rc":[{"batb":[[0,3.25,52],[1,3.2,46.55],[2,3.15,20.46]],"ltp":4.2,"tv":79.99,"id":16676048},{"batb":[[0,3.55,28.95],[1,3.5,37.97],[2,2.98,24.55]],"ltp":1.94,"tv":6.92,"id":16676046},{"batb":[[0,6.4,23.12],[1,6.2,38.52],[2,6,17.55]],"ltp":0.0,"tv":0.0,"id":21483494},{"batb":[[0,3.45,49.97],[1,3.4,39.21],[2,3.1,21.56]],"ltp":0.0,"tv":0.0,"id":21483493}]}]}
{"op":"mcm","clk":"1008171366","pt":1580658634174,"mc":[{"id":"1.168237985","rc":[{"batb":[[0,3.15,20.46],[1,1.01,0.51],[2,3.15,0]],"ltp":4.2,"tv":79.99,"id":16676048},{"batb":[[0,2.98,24.55],[1,1.01,0.51],[2,2.98,0]],"ltp":1.94,"tv":6.92,"id":16676046},{"batb":[[0,6.2,24.41],[1,6,17.55],[2,1.01,0.51]],"ltp":0.0,"tv":0.0,"id":21483494},{"batb":[[0,3.1,21.56],[1,1.01,0.51],[2,3.1,0]],"ltp":0.0,"tv":0.0,"id":21483493}]}]}
{"op":"mcm","clk":"1008171946","pt":1580658637057,"mc":[{"id":"1.168237985","rc":[{"batb":[[0,3.15,55.82],[1,3.1,50.44],[2,1.01,0.51]],"ltp":4.2,"tv":79.99,"id":16676048},{"batb":[[0,3.1,52.08],[1,3.05,52.98],[2,2.98,24.55]],"ltp":1.94,"tv":6.92,"id":16676046},{"batb":[[1,6,58.87]],"ltp":0.0,"tv":0.0,"id":21483494},{"batb":[[0,3.15,48.52],[1,3.1,70.86],[2,1.01,0.51]],"ltp":0.0,"tv":0.0,"id":21483493}]}]}
{"op":"mcm","clk":"1008172765","pt":1580658641668,"mc":[{"id":"1.168237985","rc":[{"batb":[[0,2.98,24.55],[1,1.01,0.51],[2,2.98,0]],"ltp":1.94,"tv":6.92,"id":16676046}]}]}
{"op":"mcm","clk":"1008173186","pt":1580658643767,"mc":[{"id":"1.168237985","rc":[{"batb":[[0,4.2,34.81],[1,4.1,51.49],[2,2.98,24.55]],"ltp":1.94,"tv":6.92,"id":16676046}]}]}
{"op":"mcm","clk":"1008173436","pt":1580658644971,"mc":[{"id":"1.168237985","rc":[{"batb":[[1,3.1,71.84]],"batl":[[0,3.4,19.67],[1,3.5,18.57]],"ltp":4.2,"tv":79.99,"id":16676048},{"batb":[[2,4,23.45]],"batl":[[1,5,17.15]],"ltp":1.94,"tv":6.92,"id":16676046},{"batl":[[0,7.2,16.37],[1,7.4,15.42]],"ltp":0.0,"tv":0.0,"id":21483494},{"batb":[[2,2.96,24.78]],"batl":[[0,3.4,20.77],[1,3.7,17.23]],"ltp":0.0,"tv":0.0,"id":21483493}]}]}
{"op":"mcm","clk":"1008176498","pt":1580658662985,"mc":[{"id":"1.168237985","rc":[{"batb":[[0,3.1,71.84],[1,1.01,0.51],[2,1.01,0]],"batl":[[0,3.5,18.57],[1,3.5,0]],"ltp":4.2,"tv":79.99,"id":16676048},{"batb":[[0,3.55,15.89],[1,1.01,0.51],[2,4,0]],"batl":[[0,5,17.15],[1,5,0]],"ltp":1.94,"tv":6.92,"id":16676046},{"batb":[[0,6,58.87],[1,1.01,0.51],[2,1.01,0]],"batl":[[0,7.4,15.42],[1,7.4,0]],"ltp":0.0,"tv":0.0,"id":21483494},{"batb":[[0,2.96,24.78],[1,1.01,0.51],[2,2.96,0]],"batl":[[0,3.7,17.23],[1,3.7,0]],"ltp":0.0,"tv":0.0,"id":21483493}]}]}
{"op":"mcm","clk":"1008176963","pt":1580658665882,"mc":[{"id":"1.168237985","rc":[{"batb":[[1,3.05,52.39],[2,1.01,0.51]],"ltp":4.2,"tv":79.99,"id":16676048},{"batb":[[0,3.75,27.05],[1,3.7,33.26],[2,3.55,15.89]],"ltp":1.94,"tv":6.92,"id":16676046},{"batb":[[0,6,65.22],[1,5.9,21.47],[2,1.01,0.51]],"ltp":0.0,"tv":0.0,"id":21483494},{"batb":[[0,3,65.14],[1,2.96,69.12],[2,1.01,0.51]],"ltp":0.0,"tv":0.0,"id":21483493}]}]}
{"op":"mcm","clk":"1008177103","pt":1580658666685,"mc":[{"id":"1.168237985","rc":[{"batb":[[0,3.1,21.4],[1,1.01,0.51],[2,1.01,0]],"ltp":4.2,"tv":79.99,"id":16676048},{"batb":[[0,6,58.87],[1,1.01,0.51],[2,1.01,0]],"ltp":0.0,"tv":0.0,"id":21483494},{"batb":[[0,2.96,24.78],[1,1.01,0.51],[2,1.01,0]],"ltp":0.0,"tv":0.0,"id":21483493}]}]}
{"op":"mcm","clk":"1008177614","pt":1580658670002,"mc":[{"id":"1.168237985","rc":[{"batb":[[0,3.2,42.83],[1,3.15,48.45],[2,3.1,21.4]],"ltp":4.2,"tv":79.99,"id":16676048},{"batb":[[0,6.2,51.29],[1,6,58.87],[2,1.01,0.51]],"ltp":0.0,"tv":0.0,"id":21483494},{"batb":[[0,3.35,59.82],[1,3.3,42.09],[2,2.96,24.78]],"ltp":0.0,"tv":0.0,"id":21483493}]}]}
{"op":"mcm","clk":"1008177694","pt":1580658670482,"mc":[{"id":"1.168237985","rc":[{"batb":[[0,3.2,62.11],[2,3.05,21.56]],"batl":[[1,3.7,16.13]],"ltp":4.2,"tv":79.99,"id":16676048},{"batl":[[0,3.85,15.42],[1,4.7,19.83]],"ltp":1.94,"tv":6.92,"id":16676046},{"batb":[[0,6.2,67.73]],"batl":[[1,7.6,14.48]],"ltp":0.0,"tv":0.0,"id":21483494},{"batb":[[0,3.35,77.68],[2,3.1,22.35]],"batl":[[1,4.3,24.47]],"ltp":0.0,"tv":0.0,"id":21483493}]}]}
{"op":"mcm","clk":"1008180176","pt":1580658685232,"mc":[{"id":"1.168237985","rc":[{"batb":[[0,3.05,21.56],[1,1.01,0.51],[2,3.05,0]],"batl":[[0,3.7,16.13],[1,3.7,0]],"ltp":4.2,"tv":79.99,"id":16676048},{"batb":[[0,2.94,10.31],[1,1.01,0.51],[2,3.55,0]],"batl":[[0,4.7,19.83],[1,4.7,0]],"ltp":1.94,"tv":6.92,"id":16676046},{"batb":[[0,6,58.87],[1,1.01,0.51],[2,1.01,0]],"batl":[[0,7.6,14.48],[1,7.6,0]],"ltp":0.0,"tv":0.0,"id":21483494},{"batb":[[0,3.1,22.35],[1,1.01,0.51],[2,3.1,0]],"batl":[[0,4.3,24.47],[1,4.3,0]],"ltp":0.0,"tv":0.0,"id":21483493}]}]}
{"op":"mcm","clk":"1008180762","pt":1580658688509,"mc":[{"id":"1.168237985","rc":[{"batb":[[0,3.05,103.1],[1,3,54.31],[2,1.01,0.51]],"ltp":4.2,"tv":79.99,"id":16676048},{"batb":[[0,3.05,64.53],[1,3,55.11],[2,2.94,10.31]],"ltp":1.94,"tv":6.92,"id":16676046},{"batb":[[0,6,75],[1,5.9,21.33],[2,1.01,0.51]],"ltp":0.0,"tv":0.0,"id":21483494},{"batb":[[0,3.1,70.26],[1,3.05,51.35],[2,1.01,0.51]],"ltp":0.0,"tv":0.0,"id":21483493}]}]}
{"op":"mcm","clk":"1008182837","pt":1580658702638,"mc":[{"id":"1.168237985","rc":[{"batb":[[0,3.05,21.56],[1,1.01,0.51],[2,1.01,0]],"ltp":4.2,"tv":79.99,"id":16676048},{"batb":[[0,2.94,10.31],[1,1.01,0.51],[2,2.94,0]],"ltp":1.94,"tv":6.92,"id":16676046},{"batb":[[0,6,17.55],[1,1.01,0.51],[2,1.01,0]],"ltp":0.0,"tv":0.0,"id":21483494},{"batb":[[0,3.1,22.35],[1,1.01,0.51],[2,1.01,0]],"ltp":0.0,"tv":0.0,"id":21483493}]}]}
{"op":"mcm","clk":"1008183345","pt":1580658705963,"mc":[{"id":"1.168237985","rc":[{"batb":[[0,3.4,16.68],[1,3.35,61.68],[2,3.3,43.12]],"batl":[[1,4,13.45]],"ltp":4.2,"tv":79.99,"id":16676048},{"batb":[[0,3.05,64.53],[1,3,55.11],[2,2.94,10.31]],"batl":[[0,3.15,24.63],[1,3.8,15.97]],"ltp":1.94,"tv":6.92,"id":16676046},{"batb":[[0,6.6,24.87],[1,6.4,51.34],[2,6.2,16.52]],"batl":[[1,8,13.3]],"ltp":0.0,"tv":0.0,"id":21483494},{"batb":[[0,3.85,39.58],[1,3.8,30.16],[2,3.45,17]],"batl":[[1,5.1,16.37]],"ltp":0.0,"tv":0.0,"id":21483493}]}]}
{"op":"mcm","clk":"1008186434","pt":1580658725865,"mc":[{"id":"1.168237985","rc":[{"batb":[[1,3.2,19.43],[2,1.01,0.51]],"ltp":4.2,"tv":79.99,"id":16676048},{"batb":[[0,2.94,10.31],[1,2.46,16.29],[2,1.01,0.51]],"ltp":1.94,"tv":6.92,"id":16676046},{"batb":[[0,6.4,31.49],[1,6.2,16.52],[2,1.01,0.51]],"ltp":0.0,"tv":0.0,"id":21483494},{"batb":[[0,3.85,12.98],[1,3.45,17],[2,1.01,0.51]],"ltp":0.0,"tv":0.0,"id":21483493}]}]}
{"op":"mcm","clk":"1008186529","pt":1580658726450,"mc":[{"id":"1.168237985","rc":[{"batb":[[0,3.2,19.43],[1,1.01,0.51],[2,1.01,0]],"batl":[[0,4,13.45],[1,4,0]],"ltp":4.2,"tv":79.99,"id":16676048},{"batb":[[0,2.46,16.29],[1,1.01,0.51],[2,1.01,0]],"batl":[[0,3.8,15.97],[1,3.8,0]],"ltp":1.94,"tv":6.92,"id":16676046},{"batb":[[0,6.4,16.07]],"batl":[[0,8,13.3],[1,8,0]],"ltp":0.0,"tv":0.0,"id":21483494},{"batb":[[0,3.45,17],[1,1.01,0.51],[2,1.01,0]],"batl":[[0,5.1,16.37],[1,5.1,0]],"ltp":0.0,"tv":0.0,"id":21483493}]}]}
{"op":"mcm","clk":"1008186892","pt":1580658728904,"mc":[{"id":"1.168237985","rc":[{"batb":[[0,3.2,60.52],[1,3.15,48.48],[2,1.01,0.51]],"ltp":4.2,"tv":79.99,"id":16676048},{"batb":[[0,2.5,61.51],[1,2.46,90.51],[2,1.01,0.51]],"ltp":1.94,"tv":6.92,"id":16676046},{"batb":[[1,6.2,55.21]],"ltp":0.0,"tv":0.0,"id":21483494},{"batb":[[1,3.4,45.81],[2,3.35,40.69]],"ltp":0.0,"tv":0.0,"id":21483493}]}]}
{"op":"mcm","clk":"1008187110","pt":1580658730166,"mc":[{"id":"1.168237985","rc":[{"batb":[[0,3.2,19.43],[1,1.01,0.51],[2,1.01,0]],"ltp":4.2,"tv":79.99,"id":16676048},{"batb":[[0,2.46,16.29],[1,1.01,0.51],[2,1.01,0]],"ltp":1.94,"tv":6.92,"id":16676046},{"batb":[[1,6.2,16.52]],"ltp":0.0,"tv":0.0,"id":21483494},{"batb":[[1,1.01,0.51],[2,3.35,0]],"ltp":0.0,"tv":0.0,"id":21483493}]}]}
{"op":"mcm","clk":"1008187711","pt":1580658733884,"mc":[{"id":"1.168237985","rc":[{"batb":[[0,3.4,61.01],[1,3.35,41.58],[2,3.2,19.43]],"ltp":4.2,"tv":79.99,"id":16676048},{"batb":[[0,2.94,41.73],[1,2.9,48.36],[2,2.46,16.29]],"ltp":1.94,"tv":6.92,"id":16676046},{"batb":[[0,6.6,37.03],[1,6.4,35.61],[2,6.2,16.52]],"ltp":0.0,"tv":0.0,"id":21483494},{"batb":[[0,3.95,45.17],[1,3.9,28.19],[2,3.45,17]],"ltp":0.0,"tv":0.0,"id":21483493}]}]}
{"op":"mcm","clk":"1008188387","pt":1580658738590,"mc":[{"id":"1.168237985","rc":[{"batb":[[0,3.2,19.43],[1,1.01,0.51],[2,3.2,0]],"ltp":4.2,"tv":79.99,"id":16676048},{"batb":[[0,2.46,16.29],[1,1.01,0.51],[2,2.46,0]],"ltp":1.94,"tv":6.92,"id":16676046},{"batb":[[0,6.4,16.07],[1,6.2,16.52],[2,1.01,0.51]],"ltp":0.0,"tv":0.0,"id":21483494},{"batb":[[0,3.45,17],[1,1.01,0.51],[2,3.45,0]],"ltp":0.0,"tv":0.0,"id":21483493}]}]}
{"op":"mcm","clk":"1008188814","pt":1580658741490,"mc":[{"id":"1.168237985","rc":[{"batb":[[0,3.2,60.52],[1,3.15,48.48],[2,1.01,0.51]],"ltp":4.2,"tv":79.99,"id":16676048},{"batb":[[0,2.5,61.51],[1,2.46,90.51],[2,1.01,0.51]],"ltp":1.94,"tv":6.92,"id":16676046},{"batb":[[1,6.2,55.21]],"ltp":0.0,"tv":0.0,"id":21483494},{"batb":[[1,3.4,45.81],[2,3.35,40.69]],"ltp":0.0,"tv":0.0,"id":21483493}]}]}
{"op":"mcm","clk":"1008189014","pt":1580658742892,"mc":[{"id":"1.168237985","rc":[{"batb":[[0,3.2,19.43],[1,1.01,0.51],[2,1.01,0]],"ltp":4.2,"tv":79.99,"id":16676048},{"batb":[[0,6.2,16.52],[1,1.01,0.51],[2,1.01,0]],"ltp":0.0,"tv":0.0,"id":21483494},{"batb":[[1,1.01,0.51],[2,3.35,0]],"ltp":0.0,"tv":0.0,"id":21483493}]}]}
{"op":"mcm","clk":"1008189478","pt":1580658745985,"mc":[{"id":"1.168237985","rc":[{"batb":[[0,3.65,48.73],[1,3.6,35.21],[2,3.4,16.68]],"batl":[[1,4.5,21.01]],"ltp":4.2,"tv":79.99,"id":16676048},{"batb":[[2,2.08,26.28]],"batl":[[0,2.6,15.97],[1,3.1,25.57]],"ltp":1.94,"tv":6.92,"id":16676046},{"batb":[[0,7,19.1],[1,6.8,31.67],[2,6.6,14.08]],"batl":[[1,8.4,12.04]],"ltp":0.0,"tv":0.0,"id":21483494},{"batb":[[0,4.6,36.9],[1,4.5,57.11],[2,3.9,25.1]],"batl":[[1,6.6,19.36]],"ltp":0.0,"tv":0.0,"id":21483493}]}]}
{"op":"mcm","clk":"1008192630","pt":1580658765810,"mc":[{"id":"1.168237985","rc":[{"batb":[[0,3.4,16.68],[1,1.01,0.51],[2,3.4,0]],"batl":[[0,4.5,21.01],[1,4.5,0]],"ltp":4.2,"tv":79.99,"id":16676048},{"batb":[[0,2.08,26.28],[1,1.01,0.51],[2,2.08,0]],"batl":[[0,3.1,25.57],[1,3.1,0]],"ltp":1.94,"tv":6.92,"id":16676046},{"batb":[[0,6.4,15.5],[1,1.01,0.51],[2,6.6,0]],"batl":[[0,8.4,12.04],[1,8.4,0]],"ltp":0.0,"tv":0.0,"id":21483494},{"batb":[[0,3.9,25.1],[1,1.01,0.51],[2,3.9,0]],"batl":[[0,6.6,19.36],[1,6.6,0]],"ltp":0.0,"tv":0.0,"id":21483493}]}]}
{"op":"mcm","clk":"1008193606","pt":1580658772004,"mc":[{"id":"1.168237985","rc":[{"batb":[[0,3.7,53.15],[1,3.65,33.92],[2,3.4,16.68]],"ltp":4.2,"tv":79.99,"id":16676048},{"batb":[[0,2.4,44.76],[1,2.36,83.19],[2,2.08,26.28]],"ltp":1.94,"tv":6.92,"id":16676046},{"batb":[[0,7,33.82],[1,6.8,31.32],[2,6.4,15.5]],"ltp":0.0,"tv":0.0,"id":21483494},{"batb":[[0,4.8,50.84],[1,4.7,35.93],[2,3.9,25.1]],"ltp":0.0,"tv":0.0,"id":21483493}]}]}
{"op":"mcm","clk":"1008194443","pt":1580658777509,"mc":[{"id":"1.168237985","rc":[{"batb":[[0,3.4,16.68],[1,1.01,0.51],[2,3.4,0]],"ltp":4.2,"tv":79.99,"id":16676048},{"batb":[[0,2.08,26.28],[1,1.01,0.51],[2,2.08,0]],"ltp":1.94,"tv":6.92,"id":16676046},{"batb":[[0,6.4,15.5],[1,1.01,0.51],[2,6.4,0]],"ltp":0.0,"tv":0.0,"id":21483494},{"batb":[[0,3.9,25.1],[1,1.01,0.51],[2,3.9,0]],"ltp":0.0,"tv":0.0,"id":21483493}]}]}
{"op":"mcm","clk":"1008194937","pt":1580658780624,"mc":[{"id":"1.168237985","rc":[{"batb":[[1,3.35,63.05],[2,3.3,43.11]],"ltp":4.2,"tv":79.99,"id":16676048},{"batb":[[1,2.04,55.4],[2,2.02,65.55]],"ltp":1.94,"tv":6.92,"id":16676046},{"batb":[[0,6.6,29.16],[1,6.4,51.31],[2,1.01,0.51]],"ltp":0.0,"tv":0.0,"id":21483494},{"batb":[[1,3.85,49.33],[2,3.8,29.95]],"ltp":0.0,"tv":0.0,"id":21483493}]}]}
{"op":"mcm","clk":"1008195900","pt":1580658786338,"mc":[{"id":"1.168237985","rc":[{"batb":[[1,1.01,0.51],[2,2.02,0]],"ltp":1.94,"tv":6.92,"id":16676046}]}]}
{"op":"mcm","clk":"1008196505","pt":1580658790023,"mc":[{"id":"1.168237985","rc":[{"batl":[[0,3.7,16.13],[1,4,13.45],[2,4.5,21.01]],"ltp":4.2,"tv":79.99,"id":16676048},{"batb":[[0,3,87.59],[1,2.96,45.6],[2,2.92,10.39]],"batl":[[1,3.75,16.44]],"ltp":1.94,"tv":6.92,"id":16676046},{"batb":[[2,6.2,16.37]],"batl":[[0,7.6,14.56],[1,8,13.22],[2,8.4,12.04]],"ltp":0.0,"tv":0.0,"id":21483494},{"batl":[[0,4.4,23.68],[1,5.2,15.82],[2,6.6,19.36]],"ltp":0.0,"tv":0.0,"id":21483493}]}]}
{"op":"mcm","clk":"1008196526","pt":1580658790148,"mc":[{"id":"1.168237985","rc":[{"batl":[[2,4.5,0]],"ltp":4.2,"tv":79.99,"id":16676048},{"batl":[[2,8.4,0]],"ltp":0.0,"tv":0.0,"id":21483494},{"batl":[[2,6.6,0]],"ltp":0.0,"tv":0.0,"id":21483493}]}]}
{"op":"mcm","clk":"1008199910","pt":1580658809975,"mc":[{"id":"1.168237985","rc":[{"batb":[[0,3.35,63.05],[1,3.3,43.11],[2,3.2,19.36]],"batl":[[0,4,13.45],[1,4,0]],"ltp":4.2,"tv":79.99,"id":16676048},{"batb":[[2,2.44,16.68]],"batl":[[0,3.75,16.44],[1,3.75,0]],"ltp":1.94,"tv":6.92,"id":16676046},{"batb":[[1,6.4,35.81]],"batl":[[0,8,13.22],[1,8,0]],"ltp":0.0,"tv":0.0,"id":21483494},{"batb":[[0,3.85,49.33],[1,3.8,29.95],[2,3.45,16.68]],"batl":[[0,5.2,15.82],[1,5.2,0]],"ltp":0.0,"tv":0.0,"id":21483493}]}]}
{"op":"mcm","clk":"1008199991","pt":1580658810453,"mc":[{"id":"1.168237985","rc":[{"batb":[[0,3.2,19.36],[1,1.01,0.51],[2,3.2,0]],"ltp":4.2,"tv":79.99,"id":16676048},{"batb":[[0,2.44,16.68],[1,1.01,0.51],[2,2.44,0]],"ltp":1.94,"tv":6.92,"id":16676046},{"batb":[[0,6.4,19.43],[1,6.2,16.37],[2,1.01,0.51]],"ltp":0.0,"tv":0.0,"id":21483494},{"batb":[[0,3.45,16.68],[1,1.01,0.51],[2,3.45,0]],"ltp":0.0,"tv":0.0,"id":21483493}]}]}
{"op":"mcm","clk":"1008200430","pt":1580658812999,"mc":[{"id":"1.168237985","rc":[{"batb":[[0,3.2,59.29],[1,3.15,48.49],[2,1.01,0.51]],"ltp":4.2,"tv":79.99,"id":16676048},{"batb":[[0,2.48,61.6],[1,2.44,92.56],[2,1.01,0.51]],"ltp":1.94,"tv":6.92,"id":16676046},{"batb":[[1,6.2,54.97]],"ltp":0.0,"tv":0.0,"id":21483494},{"batb":[[1,3.4,69.15],[2,3.35,40.47]],"ltp":0.0,"tv":0.0,"id":21483493}]}]}
{"op":"mcm","clk":"1008200900","pt":1580658815847,"mc":[{"id":"1.168237985","rc":[{"batb":[[0,3.2,19.36],[1,1.01,0.51],[2,1.01,0]],"ltp":4.2,"tv":79.99,"id":16676048},{"batb":[[0,2.44,16.68],[1,1.01,0.51],[2,1.01,0]],"ltp":1.94,"tv":6.92,"id":16676046},{"batb":[[1,6.2,16.37]],"ltp":0.0,"tv":0.0,"id":21483494},{"batb":[[1,1.01,0.51],[2,3.35,0]],"ltp":0.0,"tv":0.0,"id":21483493}]}]}
{"op":"mcm","clk":"1008201381","pt":1580658818954,"mc":[{"id":"1.168237985","rc":[{"batb":[[0,3.2,59.29],[1,3.15,48.49],[2,1.01,0.51]],"ltp":4.2,"tv":79.99,"id":16676048},{"batb":[[0,3.65,38.69],[1,3.6,35.41],[2,2.44,16.68]],"ltp":1.94,"tv":6.92,"id":16676046},{"batb":[[1,6.2,54.97]],"ltp":0.0,"tv":0.0,"id":21483494},{"batb":[[1,3.4,69.15],[2,3.35,40.47]],"ltp":0.0,"tv":0.0,"id":21483493}]}]}
{"op":"mcm","clk":"1008201540","pt":1580658819893,"mc":[{"id":"1.168237985","rc":[{"batb":[[2,3.05,21.87]],"batl":[[0,3.5,18.65],[1,3.7,16.21]],"ltp":4.2,"tv":79.99,"id":16676048},{"batb":[[2,3.45,17]],"batl":[[1,4.6,20.69]],"ltp":1.94,"tv":6.92,"id":16676046},{"batb":[[2,6,17.62]],"batl":[[0,7.4,15.34],[1,7.6,14.24]],"ltp":0.0,"tv":0.0,"id":21483494},{"batl":[[0,3.8,16.21],[1,4.4,22.98]],"ltp":0.0,"tv":0.0,"id":21483493}]}]}
{"op":"mcm","clk":"1008204690","pt":1580658838887,"mc":[{"id":"1.168237985","rc":[{"batb":[[0,3.05,21.87],[1,1.01,0.51],[2,3.05,0]],"batl":[[0,3.7,16.21],[1,3.7,0]],"ltp":4.2,"tv":79.99,"id":16676048},{"batb":[[0,2.88,10.78],[1,1.01,0.51],[2,3.45,0]],"batl":[[0,4.6,20.69],[1,4.6,0]],"ltp":1.94,"tv":6.92,"id":16676046},{"batb":[[0,6.2,21.13],[1,6,17.62],[2,1.01,0.51]],"batl":[[0,7.6,14.24],[1,7.6,0]],"ltp":0.0,"tv":0.0,"id":21483494},{"batb":[[0,3.15,21.32],[1,1.01,0.51],[2,3.35,0]],"batl":[[0,4.4,22.98],[1,4.4,0]],"ltp":0.0,"tv":0.0,"id":21483493}]}]}
{"op":"mcm","clk":"1008205504","pt":1580658843980,"mc":[{"id":"1.168237985","rc":[{"batb":[[0,3.2,72.48],[1,3.15,48.22],[2,3.05,21.87]],"ltp":4.2,"tv":79.99,"id":16676048},{"batb":[[0,3.5,40.16],[1,3.45,39.22],[2,2.88,10.78]],"ltp":1.94,"tv":6.92,"id":16676046},{"batb":[[0,6.4,29.58],[1,6.2,38.34],[2,6,17.62]],"ltp":0.0,"tv":0.0,"id":21483494},{"batb":[[0,3.5,55.57],[1,3.45,37.77],[2,3.15,21.32]],"ltp":0.0,"tv":0.0,"id":21483493}]}]}
{"op":"mcm","clk":"1008206574","pt":1580658851023,"mc":[{"id":"1.168237985","rc":[{"batb":[[0,3.05,21.87],[1,1.01,0.51],[2,3.05,0]],"ltp":4.2,"tv":79.99,"id":16676048},{"batb":[[0,2.88,10.78],[1,1.01,0.51],[2,2.88,0]],"ltp":1.94,"tv":6.92,"id":16676046},{"batb":[[0,6.2,21.13],[1,6,17.62],[2,1.01,0.51]],"ltp":0.0,"tv":0.0,"id":21483494},{"batb":[[0,3.15,21.32],[1,1.01,0.51],[2,3.15,0]],"ltp":0.0,"tv":0.0,"id":21483493}]}]}
{"op":"mcm","clk":"1008207085","pt":1580658854026,"mc":[{"id":"1.168237985","rc":[{"batb":[[0,3.05,93.97],[1,3,54.41],[2,1.01,0.51]],"ltp":4.2,"tv":79.99,"id":16676048},{"batb":[[0,3,52.12],[1,2.96,45.85],[2,2.88,10.78]],"ltp":1.94,"tv":6.92,"id":16676046},{"batb":[[1,6,59.01]],"ltp":0.0,"tv":0.0,"id":21483494},{"batb":[[0,3.15,69.33],[1,3.1,49.29],[2,1.01,0.51]],"ltp":0.0,"tv":0.0,"id":21483493}]}]}
{"op":"mcm","clk":"1008208871","pt":1580658865348,"mc":[{"id":"1.168237985","rc":[{"batb":[[0,2.88,10.78],[1,1.01,0.51],[2,2.88,0]],"ltp":1.94,"tv":6.92,"id":16676046}]}]}
{"op":"mcm","clk":"1008209433","pt":1580658868944,"mc":[{"id":"1.168237985","rc":[{"batb":[[0,4.3,49.98],[1,4.2,48.44],[2,2.88,10.78]],"ltp":1.94,"tv":6.92,"id":16676046}]}]}
{"op":"mcm","clk":"1008209503","pt":1580658869447,"mc":[{"id":"1.168237985","rc":[{"batb":[[1,3,77.7]],"batl":[[0,3.3,21.01],[1,3.4,20.06]],"ltp":4.2,"tv":79.99,"id":16676048},{"batb":[[2,4.1,21.87]],"batl":[[1,5.5,14.08]],"ltp":1.94,"tv":6.92,"id":16676046},{"batb":[[1,6,41.39],[2,5.9,18.25]],"batl":[[0,7.2,15.82]],"ltp":0.0,"tv":0.0,"id":21483494},{"batb":[[2,2.92,10.46]],"batl":[[0,3.4,20.54],[1,3.65,17.78]],"ltp":0.0,"tv":0.0,"id":21483493}]}]}
{"op":"mcm","clk":"1008215184","pt":1580658905679,"mc":[{"id":"1.168237985","rc":[{"batb":[[0,3.05,21.87]],"ltp":4.2,"tv":79.99,"id":16676048},{"batb":[[0,4.1,21.87],[1,3.75,13.93],[2,1.01,0.51]],"ltp":1.94,"tv":6.92,"id":16676046},{"batb":[[0,6,33.99],[1,5.9,18.25],[2,1.01,0.51]],"ltp":0.0,"tv":0.0,"id":21483494},{"batb":[[0,3.15,21.32],[1,2.92,10.46],[2,1.01,0.51]],"ltp":0.0,"tv":0.0,"id":21483493}]}]}
{"op":"mcm","clk":"1008215684","pt":1580658908631,"mc":[{"id":"1.168237985","rc":[{"batb":[[2,2.96,45.23]],"ltp":4.2,"tv":79.99,"id":16676048},{"batb":[[1,3.95,31.58],[2,3.9,29.33]],"ltp":1.94,"tv":6.92,"id":16676046},{"batb":[[1,5.9,39.89]],"ltp":0.0,"tv":0.0,"id":21483494},{"batb":[[1,2.92,63.07],[2,2.88,47.64]],"ltp":0.0,"tv":0.0,"id":21483493}]}]}
{"op":"mcm","clk":"1008216135","pt":1580658911240,"mc":[{"id":"1.168237985","rc":[{"batb":[[0,3,77.7],[1,2.96,45.23],[2,1.01,0.51]],"batl":[[0,3.4,20.06],[1,3.4,0]],"ltp":4.2,"tv":79.99,"id":16676048},{"batb":[[0,3.95,31.58],[1,3.9,29.33],[2,3.75,13.93]],"batl":[[0,5.5,14.08],[1,5.5,0]],"ltp":1.94,"tv":6.92,"id":16676046},{"batb":[[0,2.92,63.07],[1,2.88,47.64],[2,1.01,0.51]],"batl":[[0,3.65,17.78],[1,3.65,0]],"ltp":0.0,"tv":0.0,"id":21483493}]}]}
{"op":"mcm","clk":"1008216931","pt":1580658915657,"mc":[{"id":"1.168237985","rc":[{"batb":[[0,3,23.29],[1,1.01,0.51],[2,1.01,0]],"ltp":4.2,"tv":79.99,"id":16676048},{"batb":[[1,5.9,18.25]],"ltp":0.0,"tv":0.0,"id":21483494},{"batb":[[0,2.92,10.46],[1,1.01,0.51],[2,1.01,0]],"ltp":0.0,"tv":0.0,"id":21483493}]}]}
{"op":"mcm","clk":"1008217448","pt":1580658918648,"mc":[{"id":"1.168237985","rc":[{"batb":[[0,3.1,63.31],[1,3.05,52.31],[2,3,23.29]],"ltp":4.2,"tv":79.99,"id":16676048},{"batb":[[0,6.2,39.88],[1,6,40.89],[2,5.9,18.25]],"ltp":0.0,"tv":0.0,"id":21483494},{"batb":[[0,3.3,60.5],[1,3.25,43.7],[2,2.92,10.46]],"ltp":0.0,"tv":0.0,"id":21483493}]}]}
{"op":"mcm","clk":"1008217574","pt":1580658919462,"mc":[{"id":"1.168237985","rc":[{"batb":[[0,3.1,84.16],[1,3.05,74.34],[2,1.01,0.51]],"batl":[[1,3.45,19.36]],"ltp":4.2,"tv":79.99,"id":16676048},{"batl":[[0,4.1,13.45],[1,4.8,19.51]],"ltp":1.94,"tv":6.92,"id":16676046},{"batb":[[1,6,58.44],[2,1.01,0.51]],"batl":[[0,7.4,15.58]],"ltp":0.0,"tv":0.0,"id":21483494},{"batb":[[0,3.35,18.41],[1,3.3,60.5],[2,3.25,43.7]],"batl":[[1,3.85,15.42]],"ltp":0.0,"tv":0.0,"id":21483493}]}]}
{"op":"mcm","clk":"1008220241","pt":1580658936661,"mc":[{"id":"1.168237985","rc":[{"batb":[[0,3.05,74.34],[1,1.01,0.51],[2,1.01,0]],"batl":[[0,3.45,19.36],[1,3.45,0]],"ltp":4.2,"tv":79.99,"id":16676048},{"batb":[[0,3.45,16.92],[1,1.01,0.51],[2,3.75,0]],"batl":[[0,4.8,19.51],[1,4.8,0]],"ltp":1.94,"tv":6.92,"id":16676046},{"batb":[[0,6,58.44],[1,1.01,0.51],[2,1.01,0]],"ltp":0.0,"tv":0.0,"id":21483494},{"batb":[[0,3.1,22.19],[1,1.01,0.51],[2,3.25,0]],"batl":[[0,3.85,15.42],[1,3.85,0]],"ltp":0.0,"tv":0.0,"id":21483493}]}]}
{"op":"mcm","clk":"1008220775","pt":1580658939875,"mc":[{"id":"1.168237985","rc":[{"batb":[[0,3.05,87.16],[1,3,54.46],[2,1.01,0.51]],"ltp":4.2,"tv":79.99,"id":16676048},{"batb":[[0,3.65,51.77],[1,3.6,35.28],[2,3.45,16.92]],"ltp":1.94,"tv":6.92,"id":16676046},{"batb":[[0,6,74.35],[1,5.9,21.34],[2,1.01,0.51]],"ltp":0.0,"tv":0.0,"id":21483494},{"batb":[[0,3.1,70.13],[1,3.05,51.36],[2,1.01,0.51]],"ltp":0.0,"tv":0.0,"id":21483493}]}]}
{"op":"mcm","clk":"1008223191","pt":1580658954677,"mc":[{"id":"1.168237985","rc":[{"batb":[[0,3.05,22.03],[1,1.01,0.51],[2,1.01,0]],"ltp":4.2,"tv":79.99,"id":16676048},{"batb":[[0,6,17.55],[1,1.01,0.51],[2,1.01,0]],"ltp":0.0,"tv":0.0,"id":21483494},{"batb":[[0,3.1,22.19],[1,1.01,0.51],[2,1.01,0]],"ltp":0.0,"tv":0.0,"id":21483493}]}]}
{"op":"mcm","clk":"1008223762","pt":1580658957997,"mc":[{"id":"1.168237985","rc":[{"batb":[[0,3.15,45.13],[1,3.1,71.1],[2,3.05,22.03]],"ltp":4.2,"tv":79.99,"id":16676048},{"batl":[[0,3.75,16.37],[1,4.2,13.06],[2,4.8,19.51]],"ltp":1.94,"tv":6.92,"id":16676046},{"batb":[[0,6.4,16.85],[1,6.2,38.67],[2,6,17.55]],"ltp":0.0,"tv":0.0,"id":21483494},{"batb":[[0,3.55,15.97],[1,3.45,60.75],[2,3.4,39.1]],"batl":[[1,4.1,13.69]],"ltp":0.0,"tv":0.0,"id":21483493}]}]}
{"op":"mcm","clk":"1008223883","pt":1580658958808,"mc":[{"id":"1.168237985","rc":[{"batb":[[2,1.01,0.51]],"batl":[[0,3.45,19.2]],"ltp":4.2,"tv":79.99,"id":16676048},{"batl":[[2,4.8,0]],"ltp":1.94,"tv":6.92,"id":16676046},{"batb":[[2,6,17.07]],"batl":[[0,7.4,15.11]],"ltp":0.0,"tv":0.0,"id":21483494}]}]}
{"op":"mcm","clk":"1008226838","pt":1580658976965,"mc":[{"id":"1.168237985","rc":[{"batb":[[0,3.1,71.1],[1,1.01,0.51],[2,1.01,0]],"ltp":4.2,"tv":79.99,"id":16676048},{"batb":[[0,3.45,16.92],[1,3.25,19.51],[2,1.01,0.51]],"ltp":1.94,"tv":6.92,"id":16676046},{"batb":[[0,6.2,38.67],[1,6,17.07],[2,1.01,0.51]],"ltp":0.0,"tv":0.0,"id":21483494},{"batb":[[1,3.3,18.96],[2,1.01,0.51]],"ltp":0.0,"tv":0.0,"id":21483493}]}]}
{"op":"mcm","clk":"1008226871","pt":1580658977133,"mc":[{"id":"1.168237985","rc":[{"batb":[[0,3.25,19.51],[1,1.01,0.51],[2,1.01,0]],"batl":[[0,4.2,13.06],[1,4.2,0]],"ltp":1.94,"tv":6.92,"id":16676046},{"batb":[[0,3.3,18.96],[1,1.01,0.51],[2,1.01,0]],"batl":[[0,4.1,13.69],[1,4.1,0]],"ltp":0.0,"tv":0.0,"id":21483493}]}]}
{"op":"mcm","clk":"1008227322","pt":1580658980028,"mc":[{"id":"1.168237985","rc":[{"batb":[[0,3.1,92.9],[1,3.05,52.23],[2,1.01,0.51]],"ltp":4.2,"tv":79.99,"id":16676048},{"batb":[[0,3.5,42.33],[1,3.45,39.19],[2,3.25,19.51]],"ltp":1.94,"tv":6.92,"id":16676046},{"batb":[[1,6,58.05]],"ltp":0.0,"tv":0.0,"id":21483494},{"batb":[[0,3.3,55.35],[1,3.25,43.94],[2,1.01,0.51]],"ltp":0.0,"tv":0.0,"id":21483493}]}]}
{"op":"mcm","clk":"1008229619","pt":1580658993764,"mc":[{"id":"1.168237985","rc":[{"batb":[[0,3.1,20.69],[1,1.01,0.51],[2,1.01,0]],"ltp":4.2,"tv":79.99,"id":16676048},{"batb":[[0,3.25,19.51],[1,1.01,0.51],[2,3.25,0]],"ltp":1.94,"tv":6.92,"id":16676046},{"batb":[[0,6,17.07],[1,1.01,0.51],[2,1.01,0]],"ltp":0.0,"tv":0.0,"id":21483494},{"batb":[[0,3.3,18.96],[1,1.01,0.51],[2,1.01,0]],"ltp":0.0,"tv":0.0,"id":21483493}]}]}
{"op":"mcm","clk":"1008233249","pt":1580659015467,"mc":[{"id":"1.168237985","rc":[{"batb":[[0,3.15,60],[1,3.1,70.99],[2,1.01,0.51]],"ltp":4.2,"tv":79.99,"id":16676048},{"batb":[[0,3.5,42.33],[1,3.45,39.19],[2,3.25,19.51]],"ltp":1.94,"tv":6.92,"id":16676046},{"batb":[[0,6.4,28.85],[1,6.2,38.36],[2,6,17.07]],"ltp":0.0,"tv":0.0,"id":21483494},{"batb":[[0,3.6,38.76],[1,3.55,35.39],[2,3.3,18.96]],"ltp":0.0,"tv":0.0,"id":21483493}]}]}
{"op":"mcm","clk":"1008233400","pt":1580659016477,"mc":[{"id":"1.168237985","rc":[{"batb":[[0,3.15,80.06],[1,3.1,50.3]],"batl":[[0,3.45,18.96]],"ltp":4.2,"tv":79.99,"id":16676048},{"batl":[[0,3.55,18.8],[1,3.75,16.44]],"ltp":1.94,"tv":6.92,"id":16676046},{"batb":[[1,6.2,54.96],[2,1.01,0.51]],"batl":[[0,7.6,14.87]],"ltp":0.0,"tv":0.0,"id":21483494},{"batb":[[0,3.7,14.16],[1,3.6,38.76],[2,3.55,35.39]],"batl":[[1,4.3,24.94]],"ltp":0.0,"tv":0.0,"id":21483493}]}]}
{"op":"mcm","clk":"1008234111","pt":1580659020900,"mc":[{"id":"1.168237985","rc":[{"batb":[[0,3.15,21.4],[1,1.01,0.51],[2,3.25,0]],"batl":[[0,3.75,16.44],[1,3.75,0]],"ltp":1.94,"tv":6.92,"id":16676046},{"batb":[[0,6.2,54.96],[1,1.01,0.51],[2,1.01,0]],"ltp":0.0,"tv":0.0,"id":21483494},{"batb":[[0,3.5,16.21],[1,1.01,0.51],[2,3.55,0]],"batl":[[0,4.3,24.94],[1,4.3,0]],"ltp":0.0,"tv":0.0,"id":21483493}]}]}
{"op":"mcm","clk":"1008234559","pt":1580659023497,"mc":[{"id":"1.168237985","rc":[{"batb":[[0,3.4,55.93],[1,3.35,41.97],[2,3.15,21.4]],"ltp":1.94,"tv":6.92,"id":16676046},{"batb":[[0,6.2,71.5],[1,6,40.5],[2,1.01,0.51]],"ltp":0.0,"tv":0.0,"id":21483494},{"batb":[[1,3.45,52.3],[2,3.4,39.18]],"ltp":0.0,"tv":0.0,"id":21483493}]}]}
{"op":"mcm","clk":"1008234964","pt":1580659025716,"mc":[{"id":"1.168237985","rc":[{"batb":[[0,6.2,54.96],[1,1.01,0.51],[2,1.01,0]],"ltp":0.0,"tv":0.0,"id":21483494},{"batb":[[1,1.01,0.51],[2,3.4,0]],"ltp":0.0,"tv":0.0,"id":21483493}]}]}
{"op":"mcm","clk":"1008235466","pt":1580659028704,"mc":[{"id":"1.168237985","rc":[{"batb":[[0,6.4,36.84],[1,6.2,54.96],[2,1.01,0.51]],"ltp":0.0,"tv":0.0,"id":21483494},{"batb":[[0,3.7,27.56],[1,3.65,33.2],[2,3.5,16.21]],"ltp":0.0,"tv":0.0,"id":21483493}]}]}
{"op":"mcm","clk":"1008235635","pt":1580659029721,"mc":[{"id":"1.168237985","rc":[{"batb":[[0,3.2,19.59],[1,3.15,60],[2,3.1,50.3]],"batl":[[1,3.7,16.44]],"ltp":4.2,"tv":79.99,"id":16676048},{"trd":[[3.4,41.22]],"batb":[[0,3.4,35.32]],"batl":[[0,4,14.32]],"ltp":3.4,"tv":48.14,"id":16676046},{"batb":[[1,6.2,54.25],[2,6,16.92]],"batl":[[1,7.8,13.69]],"ltp":0.0,"tv":0.0,"id":21483494},{"batb":[[0,3.8,13.22],[1,3.7,27.56],[2,3.65,33.2]],"batl":[[1,4.9,18.33]],"ltp":0.0,"tv":0.0,"id":21483493}],"tv":128.14}]}
{"op":"mcm","clk":"1008236135","pt":1580659032720,"mc":[{"id":"1.168237985","rc":[{"batb":[[0,3.4,49.77]],"ltp":3.4,"tv":48.14,"id":16676046}]}]}
{"op":"mcm","clk":"1008236776","pt":1580659036300,"mc":[{"id":"1.168237985","rc":[{"batl":[[0,3.95,777.02],[1,4,14.32]],"ltp":3.4,"tv":48.14,"id":16676046}]}]}
{"op":"mcm","clk":"1008236989","pt":1580659037602,"mc":[{"id":"1.168237985","rc":[{"batb":[[0,3.15,79.99],[1,3.1,50.3],[2,3,22.42]],"batl":[[1,3.65,16.84]],"ltp":4.2,"tv":79.99,"id":16676048},{"batb":[[2,3.2,20.06]],"batl":[[0,3.5,19.36],[1,3.95,777.02],[2,4.1,13.38]],"ltp":3.4,"tv":48.14,"id":16676046},{"batl":[[0,7.4,15.26]],"ltp":0.0,"tv":0.0,"id":21483494},{"batb":[[0,3.75,13.53]],"batl":[[0,4.2,13.14],[1,4.8,19.04]],"ltp":0.0,"tv":0.0,"id":21483493}]}]}
{"op":"mcm","clk":"1008255793","pt":1580659163518,"mc":[{"id":"1.168237985","rc":[{"batb":[[0,3,22.42],[1,1.01,0.51],[2,3,0]],"batl":[[0,3.65,16.84],[1,3.65,0]],"ltp":4.2,"tv":79.99,"id":16676048},{"batb":[[0,2.76,11.96],[1,1.01,0.51],[2,3.2,0]],"batl":[[0,4.1,13.38],[1,3.95,0],[2,4.1,0]],"ltp":3.4,"tv":48.14,"id":16676046},{"batb":[[0,6.2,38.36],[1,6,16.92],[2,1.01,0.51]],"batl":[[0,7.8,13.69],[1,7.8,0]],"ltp":0.0,"tv":0.0,"id":21483494},{"batb":[[0,3.4,16.92],[1,1.01,0.51],[2,3.65,0]],"batl":[[0,4.8,19.04],[1,4.8,0]],"ltp":0.0,"tv":0.0,"id":21483493}]}]}
{"op":"mcm","clk":"1008256313","pt":1580659166748,"mc":[{"id":"1.168237985","rc":[{"batb":[[0,3.05,64.76],[1,3,54.74],[2,1.01,0.51]],"ltp":4.2,"tv":79.99,"id":16676048},{"batb":[[0,2.86,51.93],[1,2.82,51.8],[2,2.76,11.96]],"ltp":3.4,"tv":48.14,"id":16676046},{"batb":[[1,6,57.87]],"batl":[[0,7.6,14.16]],"ltp":0.0,"tv":0.0,"id":21483494},{"batb":[[0,3.4,50.91],[1,3.35,40.83],[2,1.01,0.51]],"ltp":0.0,"tv":0.0,"id":21483493}]}]}
{"op":"mcm","clk":"1008256478","pt":1580659167711,"mc":[{"id":"1.168237985","rc":[{"batb":[[0,2.76,11.96],[1,1.01,0.51],[2,2.76,0]],"ltp":3.4,"tv":48.14,"id":16676046}]}]}
{"op":"mcm","clk":"1008257027","pt":1580659170915,"mc":[{"id":"1.168237985","rc":[{"batb":[[2,2.92,24.63]],"batl":[[0,3.3,21.48],[1,3.45,19.2]],"ltp":4.2,"tv":79.99,"id":16676048},{"batb":[[0,3.95,44.56],[1,3.9,29.17],[2,3.75,13.77]],"batl":[[1,4.9,18.25]],"ltp":3.4,"tv":48.14,"id":16676046},{"batb":[[2,5.9,18.18]],"batl":[[0,7.2,16.29],[1,7.4,15.19]],"ltp":0.0,"tv":0.0,"id":21483494},{"batb":[[2,3.15,20.46]],"batl":[[0,3.75,16.44],[1,4.3,24.55]],"ltp":0.0,"tv":0.0,"id":21483493}]}]}
{"op":"mcm","clk":"1008258954","pt":1580659183036,"mc":[{"id":"1.168237985","rc":[{"batb":[[0,2.92,24.63],[1,1.01,0.51],[2,2.92,0]],"batl":[[0,3.45,19.2],[1,3.45,0]],"ltp":4.2,"tv":79.99,"id":16676048},{"batb":[[0,3.15,21.17],[1,1.01,0.51],[2,3.75,0]],"batl":[[0,4.9,18.25],[1,4.9,0]],"ltp":3.4,"tv":48.14,"id":16676046},{"batb":[[0,6,40.95],[1,5.9,18.18],[2,1.01,0.51]],"batl":[[0,7.4,15.19],[1,7.4,0]],"ltp":0.0,"tv":0.0,"id":21483494},{"batb":[[0,3.15,20.46],[1,1.01,0.51],[2,3.15,0]],"batl":[[0,4.3,24.55],[1,4.3,0]],"ltp":0.0,"tv":0.0,"id":21483493}]}]}
{"op":"mcm","clk":"1008259366","pt":1580659185639,"mc":[{"id":"1.168237985","rc":[{"batb":[[0,2.96,46.58],[1,2.92,71.6],[2,1.01,0.51]],"ltp":4.2,"tv":79.99,"id":16676048},{"batb":[[0,3.3,63.4],[1,3.25,45.09],[2,3.15,21.17]],"ltp":3.4,"tv":48.14,"id":16676046},{"batb":[[0,6,48.44],[1,5.9,39.65]],"ltp":0.0,"tv":0.0,"id":21483494},{"batb":[[0,3.15,81.91],[1,3.1,49.2],[2,1.01,0.51]],"ltp":0.0,"tv":0.0,"id":21483493}]}]}
{"op":"mcm","clk":"1008259619","pt":1580659187150,"mc":[{"id":"1.168237985","rc":[{"batb":[[0,2.92,24.63],[1,1.01,0.51],[2,1.01,0]],"ltp":4.2,"tv":79.99,"id":16676048},{"batb":[[0,3.15,21.17],[1,1.01,0.51],[2,3.15,0]],"ltp":3.4,"tv":48.14,"id":16676046},{"batb":[[0,6,40.95],[1,5.9,18.18]],"ltp":0.0,"tv":0.0,"id":21483494},{"batb":[[0,3.15,20.46],[1,1.01,0.51],[2,1.01,0]],"ltp":0.0,"tv":0.0,"id":21483493}]}]}
{"op":"mcm","clk":"1008260206","pt":1580659190625,"mc":[{"id":"1.168237985","rc":[{"batb":[[0,3.05,68.25],[1,3,54.52],[2,2.92,24.63]],"ltp":4.2,"tv":79.99,"id":16676048},{"batb":[[0,3.8,47.76],[1,3.75,31.98],[2,3.15,21.17]],"ltp":3.4,"tv":48.14,"id":16676046},{"batb":[[0,6.2,48.46],[1,6,40.95],[2,5.9,18.18]],"ltp":0.0,"tv":0.0,"id":21483494},{"batb":[[0,3.45,48.8],[1,3.4,39.25],[2,3.15,20.46]],"ltp":0.0,"tv":0.0,"id":21483493}]}]}
{"op":"mcm","clk":"1008260872","pt":1580659194918,"mc":[{"id":"1.168237985","rc":[{"batb":[[0,2.92,24.63],[1,1.01,0.51],[2,2.92,0]],"ltp":4.2,"tv":79.99,"id":16676048},{"batb":[[0,3.15,21.17],[1,1.01,0.51],[2,3.15,0]],"ltp":3.4,"tv":48.14,"id":16676046},{"batb":[[0,6,40.95],[1,5.9,18.18],[2,1.01,0.51]],"ltp":0.0,"tv":0.0,"id":21483494},{"batb":[[0,3.15,20.46],[1,1.01,0.51],[2,3.15,0]],"ltp":0.0,"tv":0.0,"id":21483493}]}]}
{"op":"mcm","clk":"1008261337","pt":1580659197946,"mc":[{"id":"1.168237985","rc":[{"batb":[[0,2.96,45.4],[1,2.92,71.6],[2,1.01,0.51]],"ltp":4.2,"tv":79.99,"id":16676048},{"batb":[[0,3.3,62.52],[1,3.25,45.09],[2,3.15,21.17]],"ltp":3.4,"tv":48.14,"id":16676046},{"batb":[[0,6,48.97],[1,5.9,39.65]],"ltp":0.0,"tv":0.0,"id":21483494},{"batb":[[0,3.15,83.14],[1,3.1,49.21],[2,1.01,0.51]],"ltp":0.0,"tv":0.0,"id":21483493}]}]}
{"op":"mcm","clk":"1008261826","pt":1580659200723,"mc":[{"id":"1.168237985","rc":[{"batb":[[0,3.15,21.17],[1,1.01,0.51],[2,3.15,0]],"ltp":3.4,"tv":48.14,"id":16676046}]}]}
{"op":"mcm","clk":"1008262568","pt":1580659204040,"mc":[{"id":"1.168237985","rc":[{"batb":[[0,4.6,30.9],[1,4.5,41.52],[2,3.15,21.17]],"ltp":3.4,"tv":48.14,"id":16676046}]}]}
{"op":"mcm","clk":"1008262629","pt":1580659204325,"mc":[{"id":"1.168237985","rc":[{"batb":[[2,2.88,10.39]],"batl":[[0,3.15,23.68],[1,3.25,22.03]],"ltp":4.2,"tv":79.99,"id":16676048},{"batb":[[2,4.4,19.12]],"batl":[[1,5.7,13.38]],"ltp":3.4,"tv":48.14,"id":16676046},{"batb":[[2,5.8,19.04]],"batl":[[0,7.2,16.13]],"ltp":0.0,"tv":0.0,"id":21483494},{"batb":[[2,3,23.68]],"batl":[[0,3.5,19.75],[1,3.8,16.05]],"ltp":0.0,"tv":0.0,"id":21483493}]}]}
{"op":"mcm","clk":"1008265558","pt":1580659219040,"mc":[{"id":"1.168237985","rc":[{"trd":[[3.1,98.42],[3.15,166.28]],"batb":[[0,3,23.68],[1,1.01,0.51],[2,3,0]],"batl":[[0,3.05,67.65],[1,3.5,19.75],[2,3.8,16.05]],"ltp":3.1,"tv":264.69,"id":21483493}],"tv":392.83}]}
{"op":"mcm","clk":"1008265989","pt":1580659220970,"mc":[{"id":"1.168237985","rc":[{"batb":[[0,2.92,46.97],[1,2.88,10.39],[2,1.01,0.51]],"batl":[[0,3.25,22.03],[1,3.25,0]],"ltp":4.2,"tv":79.99,"id":16676048},{"batb":[[0,3.75,13.77],[1,1.01,0.51],[2,4.4,0]],"batl":[[0,5.7,13.38],[1,5.7,0]],"ltp":3.4,"tv":48.14,"id":16676046},{"batb":[[0,6,29.94],[1,5.9,21.47]],"ltp":0.0,"tv":0.0,"id":21483494},{"batl":[[1,3.8,16.05],[2,3.8,0]],"ltp":3.1,"tv":264.69,"id":21483493}]}]}
{"op":"mcm","clk":"1008266172","pt":1580659222036,"mc":[{"id":"1.168237985","rc":[{"trd":[[3.05,135.3]],"batb":[[0,3.1,22.82],[1,3,23.68],[2,1.01,0.51]],"batl":[[0,3.8,16.05],[1,3.8,0]],"ltp":3.05,"tv":399.99,"id":21483493}],"tv":528.13}]}
{"op":"mcm","clk":"1008266200","pt":1580659222258,"mc":[{"id":"1.168237985","rc":[{"batb":[[0,3,23.68],[1,1.01,0.51],[2,1.01,0]],"ltp":3.05,"tv":399.99,"id":21483493}]}]}
{"op":"mcm","clk":"1008266518","pt":1580659223867,"mc":[{"id":"1.168237985","rc":[{"batb":[[1,2.9,25.41],[2,2.88,48.66]],"batl":[[0,3.3,21.72]],"ltp":4.2,"tv":79.99,"id":16676048},{"batb":[[0,3.95,50.14],[1,3.9,29.18],[2,3.8,13.53]],"batl":[[0,5.7,13.22]],"ltp":3.4,"tv":48.14,"id":16676046},{"batb":[[2,1.01,0.51]],"batl":[[0,7.4,15.97]],"ltp":0.0,"tv":0.0,"id":21483494},{"batb":[[0,2.94,24.55]],"batl":[[0,3.7,16.6]],"ltp":3.05,"tv":399.99,"id":21483493}]}]}
{"op":"mcm","clk":"1008267002","pt":1580659226650,"mc":[{"id":"1.168237985","rc":[{"batb":[[0,2.98,52.57],[1,2.94,69.52],[2,1.01,0.51]],"ltp":3.05,"tv":399.99,"id":21483493}]}]}
{"op":"mcm","clk":"1008267783","pt":1580659230900,"mc":[{"id":"1.168237985","rc":[{"batb":[[0,2.9,25.41],[1,1.01,0.51],[2,2.88,0]],"ltp":4.2,"tv":79.99,"id":16676048},{"batb":[[1,1.01,0.51],[2,1.01,0]],"ltp":0.0,"tv":0.0,"id":21483494},{"batb":[[0,2.94,24.55],[1,1.01,0.51],[2,1.01,0]],"ltp":3.05,"tv":399.99,"id":21483493}]}]}
{"op":"mcm","clk":"1008268376","pt":1580659233975,"mc":[{"id":"1.168237985","rc":[{"batb":[[0,3.05,38.93],[1,3,54.92],[2,2.9,25.41]],"ltp":4.2,"tv":79.99,"id":16676048},{"batb":[[0,6.2,46.31],[1,6,40.95],[2,1.01,0.51]],"ltp":0.0,"tv":0.0,"id":21483494},{"batb":[[0,3.35,60.16],[1,3.3,41.85],[2,2.94,24.55]],"ltp":3.05,"tv":399.99,"id":21483493}]}]}
{"op":"mcm","clk":"1008268546","pt":1580659234979,"mc":[{"id":"1.168237985","rc":[{"batb":[[0,3.05,61.51],[2,2.92,24.94]],"batl":[[1,3.5,18.8]],"ltp":4.2,"tv":79.99,"id":16676048},{"batl":[[0,4.2,13.14],[1,5.1,16.84]],"ltp":3.4,"tv":48.14,"id":16676046},{"batb":[[0,6.2,63.31],[1,6,59.28]],"batl":[[1,7.6,14.87]],"ltp":0.0,"tv":0.0,"id":21483494},{"batb":[[0,3.4,17.23],[1,3.35,60.16],[2,3.3,41.85]],"batl":[[1,4.3,24]],"ltp":3.05,"tv":399.99,"id":21483493}]}]}
{"op":"mcm","clk":"1008272069","pt":1580659255436,"mc":[{"id":"1.168237985","rc":[{"batb":[[0,3.05,22.58]],"ltp":4.2,"tv":79.99,"id":16676048},{"batb":[[1,3.35,40.71],[2,3.1,21.4]],"ltp":3.05,"tv":399.99,"id":21483493}]}]}
{"op":"mcm","clk":"1008272630","pt":1580659258229,"mc":[{"id":"1.168237985","rc":[{"batb":[[1,3,81.36],[2,2.96,45.22]],"ltp":4.2,"tv":79.99,"id":16676048},{"batb":[[0,6.2,69.67]],"ltp":0.0,"tv":0.0,"id":21483494},{"batb":[[0,3.4,50.29]],"ltp":3.05,"tv":399.99,"id":21483493}]}]}
{"op":"mcm","clk":"1008274052","pt":1580659266961,"mc":[{"id":"1.168237985","rc":[{"batb":[[0,2.92,24.94],[1,1.01,0.51],[2,2.96,0]],"batl":[[0,3.5,18.8],[1,3.5,0]],"ltp":4.2,"tv":79.99,"id":16676048},{"batb":[[0,3.1,22.35],[1,1.01,0.51],[2,3.8,0]],"batl":[[0,5.1,16.84],[1,5.1,0]],"ltp":3.4,"tv":48.14,"id":16676046},{"batb":[[0,6,59.28],[1,1.01,0.51],[2,1.01,0]],"batl":[[0,7.6,14.87],[1,7.6,0]],"ltp":0.0,"tv":0.0,"id":21483494},{"batb":[[0,3.1,21.24],[1,1.01,0.51],[2,3.1,0]],"batl":[[0,4.3,23.84],[1,4.3,0]],"ltp":3.05,"tv":399.99,"id":21483493}]}]}
{"op":"mcm","clk":"1008274526","pt":1580659269833,"mc":[{"id":"1.168237985","rc":[{"batb":[[0,2.92,79.17],[1,2.88,48.61],[2,1.01,0.51]],"ltp":4.2,"tv":79.99,"id":16676048},{"batb":[[0,6,75.85],[1,5.9,21.55],[2,1.01,0.51]],"ltp":0.0,"tv":0.0,"id":21483494},{"batb":[[0,3.1,101.13],[1,3.05,50.94],[2,1.01,0.51]],"ltp":3.05,"tv":399.99,"id":21483493}]}]}
{"op":"mcm","clk":"1008275017","pt":1580659272653,"mc":[{"id":"1.168237985","rc":[{"batb":[[0,4.7,44.34],[1,4.6,39.31],[2,3.1,22.35]],"ltp":3.4,"tv":48.14,"id":16676046}]}]}
{"op":"mcm","clk":"1008275250","pt":1580659273950,"mc":[{"id":"1.168237985","rc":[{"batb":[[1,2.88,59.15]],"batl":[[0,3.15,24.08],[1,3.25,22.66]],"ltp":4.2,"tv":79.99,"id":16676048},{"batb":[[2,4.5,17.7]],"batl":[[1,5.9,12.2]],"ltp":3.4,"tv":48.14,"id":16676046},{"batb":[[1,5.9,40.43]],"batl":[[0,7.2,16.05]],"ltp":0.0,"tv":0.0,"id":21483494},{"batb":[[2,2.96,24.55]],"batl":[[0,3.4,20.46],[1,3.7,16.52]],"ltp":3.05,"tv":399.99,"id":21483493}]}]}
{"op":"mcm","clk":"1008277745","pt":1580659287831,"mc":[{"id":"1.168237985","rc":[{"batb":[[0,2.88,59.15],[1,1.01,0.51],[2,1.01,0]],"batl":[[0,3.25,22.66],[1,3.25,0]],"ltp":4.2,"tv":79.99,"id":16676048},{"batb":[[0,3.85,13.14],[1,1.01,0.51],[2,4.5,0]],"batl":[[0,5.9,12.2],[1,5.9,0]],"ltp":3.4,"tv":48.14,"id":16676046},{"batb":[[0,6,34.75]],"ltp":0.0,"tv":0.0,"id":21483494},{"batb":[[0,2.96,24.55],[1,1.01,0.51],[2,2.96,0]],"batl":[[0,3.7,16.52],[1,3.7,0]],"ltp":3.05,"tv":399.99,"id":21483493}]}]}
{"op":"mcm","clk":"1008278290","pt":1580659291028,"mc":[{"id":"1.168237985","rc":[{"batb":[[1,2.84,50.37],[2,1.01,0.51]],"ltp":4.2,"tv":79.99,"id":16676048},{"batb":[[0,4.1,27.66],[1,4,54.61],[2,3.85,13.14]],"ltp":3.4,"tv":48.14,"id":16676046},{"batb":[[0,3,37.47],[1,2.96,69],[2,1.01,0.51]],"ltp":3.05,"tv":399.99,"id":21483493}]}]}
{"op":"mcm","clk":"1008279355","pt":1580659296649,"mc":[{"id":"1.168237985","rc":[{"batb":[[0,3.85,13.14],[1,1.01,0.51],[2,3.85,0]],"ltp":3.4,"tv":48.14,"id":16676046}]}]}
{"op":"mcm","clk":"1008280029","pt":1580659299943,"mc":[{"id":"1.168237985","rc":[{"batb":[[1,2.84,61.15]],"batl":[[0,3.15,24.63],[1,3.25,22.66]],"ltp":4.2,"tv":79.99,"id":16676048},{"batb":[[0,5.3,36.76],[1,5.2,42.61],[2,4.7,16.68]],"batl":[[1,7.4,15.42]],"ltp":3.4,"tv":48.14,"id":16676046},{"batb":[[2,5.8,19.43]],"batl":[[0,7,17.23],[1,7.2,16.05]],"ltp":0.0,"tv":0.0,"id":21483494},{"batb":[[2,2.74,11.96]],"batl":[[0,3.2,23.6],[1,3.4,20.77],[2,3.7,16.52]],"ltp":3.05,"tv":399.99,"id":21483493}]}]}
{"op":"mcm","clk":"1008280160","pt":1580659300647,"mc":[{"id":"1.168237985","rc":[{"batl":[[1,3.25,0]],"ltp":4.2,"tv":79.99,"id":16676048},{"batl":[[1,7.2,0]],"ltp":0.0,"tv":0.0,"id":21483494},{"batl":[[2,3.7,0]],"ltp":3.05,"tv":399.99,"id":21483493}]}]}
{"op":"mcm","clk":"1008287095","pt":1580659336649,"mc":[{"id":"1.168237985","rc":[{"batb":[[0,2.88,10.54]],"ltp":4.2,"tv":79.99,"id":16676048},{"batb":[[0,5.2,12.75],[1,4.7,16.68],[2,1.01,0.51]],"ltp":3.4,"tv":48.14,"id":16676046},{"batb":[[0,5.9,40.43],[1,5.8,19.43],[2,1.01,0.51]],"ltp":0.0,"tv":0.0,"id":21483494},{"batb":[[0,2.96,24.55],[1,2.74,11.96],[2,1.01,0.51]],"ltp":3.05,"tv":399.99,"id":21483493}]}]}
{"op":"mcm","clk":"1008287571","pt":1580659338905,"mc":[{"id":"1.168237985","rc":[{"batb":[[0,2.84,61.15],[1,1.01,0.51],[2,1.01,0]],"ltp":4.2,"tv":79.99,"id":16676048},{"batb":[[0,4.7,16.68],[1,1.01,0.51],[2,1.01,0]],"batl":[[0,7.4,15.42],[1,7.4,0]],"ltp":3.4,"tv":48.14,"id":16676046},{"batb":[[0,5.9,21.55]],"ltp":0.0,"tv":0.0,"id":21483494},{"batb":[[0,2.74,11.96],[1,1.01,0.51],[2,1.01,0]],"batl":[[0,3.4,20.77],[1,3.4,0]],"ltp":3.05,"tv":399.99,"id":21483493}]}]}
{"op":"mcm","clk":"1008287733","pt":1580659339950,"mc":[{"id":"1.168237985","rc":[{"batb":[[1,2.8,52.23],[2,1.01,0.51]],"ltp":4.2,"tv":79.99,"id":16676048},{"batb":[[0,4.8,33.38],[1,4.7,54.27],[2,1.01,0.51]],"ltp":3.4,"tv":48.14,"id":16676046},{"batb":[[0,5.9,28.46],[1,5.8,42.21]],"ltp":0.0,"tv":0.0,"id":21483494},{"batb":[[0,2.8,41.66],[1,2.76,53.16],[2,2.74,11.96]],"ltp":3.05,"tv":399.99,"id":21483493}]}]}
{"op":"mcm","clk":"1008287838","pt":1580659340439,"mc":[{"id":"1.168237985","rc":[{"batb":[[1,1.01,0.51],[2,1.01,0]],"ltp":4.2,"tv":79.99,"id":16676048},{"batb":[[0,4.7,16.68],[1,1.01,0.51],[2,1.01,0]],"ltp":3.4,"tv":48.14,"id":16676046},{"batb":[[0,5.9,21.85],[1,5.8,19.43]],"ltp":0.0,"tv":0.0,"id":21483494},{"batb":[[0,2.74,11.96],[1,1.01,0.51],[2,2.74,0]],"ltp":3.05,"tv":399.99,"id":21483493}]}]}
{"op":"mcm","clk":"1008288121","pt":1580659342041,"mc":[{"id":"1.168237985","rc":[{"batb":[[0,2.84,50.37],[1,2.82,10.94],[2,1.01,0.51]],"batl":[[0,3.1,25.02]],"ltp":4.2,"tv":79.99,"id":16676048},{"batb":[[0,4.6,16.92]],"ltp":3.4,"tv":48.14,"id":16676046},{"batb":[[1,1.01,0.51],[2,1.01,0]],"batl":[[0,7.2,17]],"ltp":0.0,"tv":0.0,"id":21483494},{"batb":[[0,2.76,11.8]],"batl":[[0,3.4,20.46]],"ltp":3.05,"tv":399.99,"id":21483493}]}]}
{"op":"mcm","clk":"1008288582","pt":1580659344817,"mc":[{"id":"1.168237985","rc":[{"batb":[[0,2.82,10.94],[1,1.01,0.51],[2,1.01,0]],"ltp":4.2,"tv":79.99,"id":16676048},{"batb":[[0,5.5,34.33],[1,5.4,27.46],[2,4.6,16.92]],"ltp":3.4,"tv":48.14,"id":16676046},{"batb":[[0,6,28.98],[1,5.9,21.85],[2,1.01,0.51]],"ltp":0.0,"tv":0.0,"id":21483494},{"batb":[[0,2.96,35.67],[1,2.92,46.03],[2,2.76,11.8]],"ltp":3.05,"tv":399.99,"id":21483493}]}]}
{"op":"mcm","clk":"1008288958","pt":1580659347014,"mc":[{"id":"1.168237985","rc":[{"batb":[[0,4.6,16.92],[1,1.01,0.51],[2,4.6,0]],"ltp":3.4,"tv":48.14,"id":16676046},{"batb":[[0,5.9,21.85],[1,1.01,0.51],[2,1.01,0]],"ltp":0.0,"tv":0.0,"id":21483494},{"batb":[[0,2.76,11.8],[1,1.01,0.51],[2,2.76,0]],"ltp":3.05,"tv":399.99,"id":21483493}]}]}
{"op":"mcm","clk":"1008289394","pt":1580659349856,"mc":[{"id":"1.168237985","rc":[{"batb":[[0,2.84,36.74],[1,2.82,10.94],[2,2.8,52.23]],"ltp":4.2,"tv":79.99,"id":16676048},{"batb":[[0,4.8,30.26],[1,4.7,37.59],[2,4.6,16.92]],"ltp":3.4,"tv":48.14,"id":16676046},{"batb":[[0,5.9,30.94],[1,5.8,22.78],[2,1.01,0.51]],"ltp":0.0,"tv":0.0,"id":21483494},{"batb":[[0,2.8,48.46],[1,2.76,64.97],[2,1.01,0.51]],"ltp":3.05,"tv":399.99,"id":21483493}]}]}
{"op":"mcm","clk":"1008290467","pt":1580659355828,"mc":[{"id":"1.168237985","rc":[{"batb":[[0,4.6,16.92],[1,1.01,0.51],[2,4.6,0]],"ltp":3.4,"tv":48.14,"id":16676046}]}]}
{"op":"mcm","clk":"1008290885","pt":1580659358029,"mc":[{"id":"1.168237985","rc":[{"batb":[[0,6.4,37.58],[1,6.2,39.6],[2,4.6,16.92]],"ltp":3.4,"tv":48.14,"id":16676046}]}]}
{"op":"mcm","clk":"1008291026","pt":1580659358835,"mc":[{"id":"1.168237985","rc":[{"batl":[[0,3,10.78],[1,3.05,10.39]],"ltp":4.2,"tv":79.99,"id":16676048},{"batb":[[1,6.2,56.28],[2,5.4,11.88]],"batl":[[1,10.5,7.79]],"ltp":3.4,"tv":48.14,"id":16676046},{"batb":[[2,5.7,20.22]],"batl":[[0,7,17.7]],"ltp":0.0,"tv":0.0,"id":21483494},{"batb":[[2,2.54,14.63]],"batl":[[0,2.92,11.57],[1,3.15,24.39]],"ltp":3.05,"tv":399.99,"id":21483493}]}]}
{"op":"mcm","clk":"1008295018","pt":1580659379974,"mc":[{"id":"1.168237985","rc":[{"batb":[[0,2.82,10.94],[1,2.78,11.57],[2,1.01,0.51]],"ltp":4.2,"tv":79.99,"id":16676048},{"batb":[[0,6.2,16.68],[1,5.4,11.88],[2,1.01,0.51]],"ltp":3.4,"tv":48.14,"id":16676046},{"batb":[[0,5.8,22.78],[1,5.7,20.22],[2,1.01,0.51]],"ltp":0.0,"tv":0.0,"id":21483494},{"batb":[[0,2.76,11.8],[1,2.54,14.63],[2,1.01,0.51]],"ltp":3.05,"tv":399.99,"id":21483493}]}]}
{"op":"mcm","clk":"1008295203","pt":1580659380885,"mc":[{"id":"1.168237985","rc":[{"batb":[[0,2.78,11.57],[1,1.01,0.51],[2,1.01,0]],"batl":[[0,3.05,10.39],[1,3.05,0]],"ltp":4.2,"tv":79.99,"id":16676048},{"batb":[[0,5.4,11.88],[1,1.01,0.51],[2,1.01,0]],"batl":[[0,10.5,7.79],[1,10.5,0]],"ltp":3.4,"tv":48.14,"id":16676046},{"batb":[[0,2.54,14.63],[1,1.01,0.51],[2,1.01,0]],"batl":[[0,3.15,24.39],[1,3.15,0]],"ltp":3.05,"tv":399.99,"id":21483493}]}]}
{"op":"mcm","clk":"1008295608","pt":1580659382944,"mc":[{"id":"1.168237985","rc":[{"batb":[[1,2.76,55.5],[2,2.72,56.08]],"ltp":4.2,"tv":79.99,"id":16676048},{"batb":[[0,5.5,30.68],[1,5.4,39.36],[2,1.01,0.51]],"ltp":3.4,"tv":48.14,"id":16676046},{"batb":[[1,5.7,44.06]],"ltp":0.0,"tv":0.0,"id":21483494},{"batb":[[0,2.58,67.04],[1,2.54,80.7],[2,1.01,0.51]],"ltp":3.05,"tv":399.99,"id":21483493}]}]}
{"op":"mcm","clk":"1008295778","pt":1580659383868,"mc":[{"id":"1.168237985","rc":[{"batb":[[0,2.76,67.22],[1,2.72,56.08],[2,1.01,0.51]],"ltp":4.2,"tv":79.99,"id":16676048},{"batb":[[0,5.8,42.77],[1,5.7,23.84]],"batl":[[0,7,17.47]],"ltp":0.0,"tv":0.0,"id":21483494},{"batb":[[1,2.54,80.47]],"batl":[[0,3.2,24]],"ltp":3.05,"tv":399.99,"id":21483493}]}]}
{"op":"mcm","clk":"1008298687","pt":1580659398854,"mc":[{"id":"1.168237985","rc":[{"batb":[[0,5.4,11.88],[1,1.01,0.51],[2,1.01,0]],"ltp":3.4,"tv":48.14,"id":16676046}]}]}
{"op":"mcm","clk":"1008298746","pt":1580659399105,"mc":[{"id":"1.168237985","rc":[{"batb":[[0,2.76,55.5]],"ltp":4.2,"tv":79.99,"id":16676048}]}]}
{"op":"mcm","clk":"1008299290","pt":1580659402016,"mc":[{"id":"1.168237985","rc":[{"batb":[[1,2.74,11.8],[2,2.72,56.08]],"batl":[[0,2.92,11.64],[1,2.94,11.33],[2,3.05,10.39]],"ltp":4.2,"tv":79.99,"id":16676048},{"batb":[[0,9,14.43],[1,8.8,18.94],[2,8.6,8.34]],"batl":[[1,17.5,7.47]],"ltp":3.4,"tv":48.14,"id":16676046},{"batb":[[1,5.7,34.15]],"ltp":0.0,"tv":0.0,"id":21483494},{"batb":[[1,2.56,14.32],[2,2.54,80.47]],"batl":[[0,2.7,14.08],[1,2.88,11.96],[2,3.2,24]],"ltp":3.05,"tv":399.99,"id":21483493}]}]}
{"op":"mcm","clk":"1008299426","pt":1580659402792,"mc":[{"id":"1.168237985","rc":[{"batl":[[2,3.05,0]],"ltp":4.2,"tv":79.99,"id":16676048},{"batb":[[2,2.54,66.07]],"batl":[[2,3.2,0]],"ltp":3.05,"tv":399.99,"id":21483493}]}]}
{"op":"mcm","clk":"1008303438","pt":1580659423496,"mc":[{"id":"1.168237985","rc":[{"batb":[[0,2.7,12.51],[1,1.01,0.51],[2,2.72,0]],"batl":[[0,2.94,11.33],[1,2.94,0]],"ltp":4.2,"tv":79.99,"id":16676048},{"batb":[[0,6.8,13.93],[1,1.01,0.51],[2,8.6,0]],"batl":[[0,17.5,7.47],[1,17.5,0]],"ltp":3.4,"tv":48.14,"id":16676046},{"batb":[[0,5.7,10.31],[1,1.01,0.51],[2,1.01,0]],"ltp":0.0,"tv":0.0,"id":21483494},{"batb":[[0,2.38,17.55],[1,1.01,0.51],[2,2.54,0]],"batl":[[0,2.88,11.96],[1,2.88,0]],"ltp":3.05,"tv":399.99,"id":21483493}]}]}
{"op":"mcm","clk":"1008304006","pt":1580659426368,"mc":[{"id":"1.168237985","rc":[{"batb":[[1,5.6,24.55],[2,1.01,0.51]],"ltp":0.0,"tv":0.0,"id":21483494}]}]}
{"op":"mcm","clk":"1008304670","pt":1580659429756,"mc":[{"id":"1.168237985","rc":[{"batb":[[0,2.76,37.38],[1,2.72,56.18],[2,2.7,12.51]],"ltp":4.2,"tv":79.99,"id":16676048},{"batb":[[0,9.8,13.15],[1,9.6,15.76],[2,6.8,13.93]],"ltp":3.4,"tv":48.14,"id":16676046},{"batb":[[0,5.7,45.9]],"ltp":0.0,"tv":0.0,"id":21483494},{"batb":[[0,2.54,66.93],[1,2.5,68.96],[2,2.38,17.55]],"ltp":3.05,"tv":399.99,"id":21483493}]}]}
{"op":"mcm","clk":"1008305848","pt":1580659435995,"mc":[{"id":"1.168237985","rc":[{"batb":[[0,2.7,12.51],[1,1.01,0.51],[2,2.7,0]],"ltp":4.2,"tv":79.99,"id":16676048},{"batb":[[0,6.8,13.93],[1,1.01,0.51],[2,6.8,0]],"ltp":3.4,"tv":48.14,"id":16676046},{"batb":[[0,5.7,10.31]],"ltp":0.0,"tv":0.0,"id":21483494},{"batb":[[0,2.38,17.55],[1,1.01,0.51],[2,2.38,0]],"ltp":3.05,"tv":399.99,"id":21483493}]}]}
{"op":"mcm","clk":"1008306416","pt":1580659439375,"mc":[{"id":"1.168237985","rc":[{"batb":[[0,2.7,62.14],[1,2.66,59.39],[2,1.01,0.51]],"ltp":4.2,"tv":79.99,"id":16676048},{"batb":[[0,7,38.19],[1,6.8,46.24],[2,1.01,0.51]],"ltp":3.4,"tv":48.14,"id":16676046},{"batb":[[1,5.6,31.98],[2,5.5,25.59]],"ltp":0.0,"tv":0.0,"id":21483494},{"batb":[[0,2.4,51.02],[1,2.38,17.55],[2,2.36,80.82]],"ltp":3.05,"tv":399.99,"id":21483493}]}]}
{"op":"mcm","clk":"1008307373","pt":1580659444872,"mc":[{"id":"1.168237985","rc":[{"batb":[[0,2.7,12.51],[1,1.01,0.51],[2,1.01,0]],"ltp":4.2,"tv":79.99,"id":16676048},{"batb":[[1,1.01,0.51],[2,5.5,0]],"ltp":0.0,"tv":0.0,"id":21483494},{"batb":[[0,2.38,17.55],[1,1.01,0.51],[2,2.36,0]],"ltp":3.05,"tv":399.99,"id":21483493}]}]}
{"op":"mcm","clk":"1008307940","pt":1580659447853,"mc":[{"id":"1.168237985","rc":[{"batb":[[0,2.8,58.65],[1,2.76,54.03],[2,2.7,12.51]],"ltp":4.2,"tv":79.99,"id":16676048},{"batb":[[0,5.9,19],[1,5.8,22.94],[2,5.7,10.31]],"ltp":0.0,"tv":0.0,"id":21483494},{"batb":[[0,2.74,37.26],[1,2.7,56.39],[2,2.38,17.55]],"ltp":3.05,"tv":399.99,"id":21483493}]}]}
{"op":"mcm","clk":"1008308149","pt":1580659448935,"mc":[{"id":"1.168237985","rc":[{"batb":[[1,2.78,11.57],[2,2.76,54.03]],"batl":[[1,3.05,10.7]],"ltp":4.2,"tv":79.99,"id":16676048},{"batb":[[2,5.6,11.09]],"batl":[[0,8,13.14],[1,13.5,12.27]],"ltp":3.4,"tv":48.14,"id":16676046},{"batb":[[1,2.72,12.2],[2,2.7,56.39]],"batl":[[1,3.15,24.78]],"ltp":3.05,"tv":399.99,"id":21483493}]}]}
{"op":"mcm","clk":"1008314422","pt":1580659482937,"mc":[{"id":"1.168237985","rc":[{"batb":[[1,2.76,54.03],[2,2.7,12.51]],"batl":[[0,3.05,10.7],[1,3.05,0]],"ltp":4.2,"tv":79.99,"id":16676048},{"batb":[[1,6.8,32.31]],"batl":[[0,13.5,12.27],[1,13.5,0]],"ltp":3.4,"tv":48.14,"id":16676046},{"batb":[[1,2.7,56.39],[2,2.48,15.58]],"batl":[[0,3.15,24.78],[1,3.15,0]],"ltp":3.05,"tv":399.99,"id":21483493}]}]}
{"op":"mcm","clk":"1008314844","pt":1580659484941,"mc":[{"id":"1.168237985","rc":[{"batb":[[0,2.7,12.51],[1,1.01,0.51],[2,2.7,0]],"ltp":4.2,"tv":79.99,"id":16676048},{"batb":[[0,5.6,11.09],[1,1.01,0.51],[2,5.6,0]],"ltp":3.4,"tv":48.14,"id":16676046},{"batb":[[0,5.7,10.31],[1,1.01,0.51],[2,5.7,0]],"ltp":0.0,"tv":0.0,"id":21483494},{"batb":[[0,2.48,15.58],[1,1.01,0.51],[2,2.48,0]],"ltp":3.05,"tv":399.99,"id":21483493}]}]}
{"op":"mcm","clk":"1008315555","pt":1580659488823,"mc":[{"id":"1.168237985","rc":[{"batb":[[0,2.72,41.52],[1,2.7,12.51],[2,2.68,58.33]],"ltp":4.2,"tv":79.99,"id":16676048},{"batb":[[0,5.7,30.89],[1,5.6,36.42],[2,1.01,0.51]],"ltp":3.4,"tv":48.14,"id":16676046},{"batb":[[0,5.7,32.25],[1,5.6,24.74],[2,1.01,0.51]],"ltp":0.0,"tv":0.0,"id":21483494},{"batb":[[0,2.5,42.93],[1,2.48,15.58],[2,2.46,72.19]],"ltp":3.05,"tv":399.99,"id":21483493}]}]}
{"op":"mcm","clk":"1008322355","pt":1580659522881,"mc":[{"id":"1.168237985","rc":[{"batb":[[0,2.7,12.51],[1,1.01,0.51],[2,2.68,0]],"ltp":4.2,"tv":79.99,"id":16676048},{"batb":[[0,5.6,11.09],[1,1.01,0.51],[2,1.01,0]],"ltp":3.4,"tv":48.14,"id":16676046},{"batb":[[0,5.7,10.31],[1,1.01,0.51],[2,1.01,0]],"ltp":0.0,"tv":0.0,"id":21483494},{"batb":[[0,2.48,15.58],[1,1.01,0.51],[2,2.46,0]],"ltp":3.05,"tv":399.99,"id":21483493}]}]}
{"op":"mcm","clk":"1008322907","pt":1580659526002,"mc":[{"id":"1.168237985","rc":[{"batb":[[0,2.88,35.16],[1,2.84,61.27],[2,2.74,11.96]],"batl":[[1,3.15,24.71]],"ltp":4.2,"tv":79.99,"id":16676048},{"batb":[[0,5.7,30.89],[1,5.6,36.42],[2,4.6,17]],"batl":[[0,6.4,10.7],[1,9.4,9.44],[2,13.5,12.27]],"ltp":3.4,"tv":48.14,"id":16676046},{"batb":[[0,6,24.99],[1,5.9,40.83],[2,5.8,19.75]],"batl":[[1,7.2,16.76]],"ltp":0.0,"tv":0.0,"id":21483494},{"batb":[[0,2.9,65.82],[1,2.86,48.45],[2,2.62,13.3]],"batl":[[1,3.4,20.77]],"ltp":3.05,"tv":399.99,"id":21483493}]}]}
{"op":"mcm","clk":"1008322991","pt":1580659526320,"mc":[{"id":"1.168237985","rc":[{"batl":[[2,13.5,0]],"ltp":3.4,"tv":48.14,"id":16676046}]}]}
{"op":"mcm","clk":"1008327296","pt":1580659548044,"mc":[{"id":"1.168237985","rc":[{"batb":[[0,2.74,11.96],[1,1.01,0.51],[2,2.74,0]],"batl":[[0,3.15,24.71],[1,3.15,0]],"ltp":4.2,"tv":79.99,"id":16676048},{"batb":[[0,4.6,17],[1,1.01,0.51],[2,4.6,0]],"batl":[[0,9.4,9.44],[1,9.4,0]],"ltp":3.4,"tv":48.14,"id":16676046},{"batb":[[0,5.8,19.75],[1,1.01,0.51],[2,5.8,0]],"batl":[[0,7.2,16.76],[1,7.2,0]],"ltp":0.0,"tv":0.0,"id":21483494},{"batb":[[0,2.62,13.3],[1,1.01,0.51],[2,2.62,0]],"batl":[[0,3.4,20.77],[1,3.4,0]],"ltp":3.05,"tv":399.99,"id":21483493}]}]}
{"op":"mcm","clk":"1008327893","pt":1580659550865,"mc":[{"id":"1.168237985","rc":[{"batb":[[0,2.76,56.98],[1,2.74,11.96],[2,2.72,68.21]],"batl":[[0,3.1,24.94],[1,3.15,24.71]],"ltp":4.2,"tv":79.99,"id":16676048},{"batb":[[0,4.8,24.91],[1,4.7,37.67],[2,4.6,17]],"ltp":3.4,"tv":48.14,"id":16676046},{"batb":[[0,5.8,44.05],[1,5.7,23.76],[2,1.01,0.51]],"ltp":0.0,"tv":0.0,"id":21483494},{"batb":[[0,2.64,62.75],[1,2.62,13.3],[2,2.6,62.2]],"ltp":3.05,"tv":399.99,"id":21483493}]}]}
{"op":"mcm","clk":"1008328114","pt":1580659551889,"mc":[{"id":"1.168237985","rc":[{"batb":[[1,2.72,68.21],[2,1.01,0.51]],"batl":[[1,3.15,0]],"ltp":4.2,"tv":79.99,"id":16676048},{"batb":[[0,4.6,17],[1,1.01,0.51],[2,4.6,0]],"ltp":3.4,"tv":48.14,"id":16676046},{"batb":[[0,5.8,43.89]],"batl":[[0,7.2,16.6]],"ltp":0.0,"tv":0.0,"id":21483494},{"batb":[[1,2.6,62.2],[2,1.01,0.51]],"batl":[[0,3.4,20.54]],"ltp":3.05,"tv":399.99,"id":21483493}]}]}
{"op":"mcm","clk":"1008328671","pt":1580659554806,"mc":[{"id":"1.168237985","rc":[{"batb":[[0,8.4,12.55],[1,8.2,22.05],[2,4.6,17]],"ltp":3.4,"tv":48.14,"id":16676046}]}]}
{"op":"mcm","clk":"1008328881","pt":1580659555860,"mc":[{"id":"1.168237985","rc":[{"batb":[[2,2.58,14.01]],"batl":[[0,2.88,11.88],[1,3.05,10.7]],"ltp":4.2,"tv":79.99,"id":16676048},{"batb":[[2,7.8,10.07]],"batl":[[1,29,5.98]],"ltp":3.4,"tv":48.14,"id":16676046},{"batb":[[1,5.7,34.3]],"batl":[[0,6.8,18.25],[1,7,17.23]],"ltp":0.0,"tv":0.0,"id":21483494},{"batb":[[2,2.34,18.33]],"batl":[[0,2.8,12.98],[1,3.05,10.31]],"ltp":3.05,"tv":399.99,"id":21483493}]}]}
{"op":"mcm","clk":"1008331381","pt":1580659567986,"mc":[{"id":"1.168237985","rc":[{"batb":[[0,2.58,14.01],[1,1.01,0.51],[2,2.58,0]],"batl":[[0,3.05,10.7],[1,3.05,0]],"ltp":4.2,"tv":79.99,"id":16676048},{"batb":[[0,5.6,10.78],[1,1.01,0.51],[2,7.8,0]],"batl":[[0,29,5.98],[1,29,0]],"ltp":3.4,"tv":48.14,"id":16676046},{"batb":[[0,5.7,10.54],[1,1.01,0.51],[2,1.01,0]],"batl":[[0,7,17.23],[1,7,0]],"ltp":0.0,"tv":0.0,"id":21483494},{"batb":[[0,2.34,18.33],[1,1.01,0.51],[2,2.34,0]],"batl":[[0,3.05,10.31],[1,3.05,0]],"ltp":3.05,"tv":399.99,"id":21483493}]}]}
{"op":"mcm","clk":"1008332559","pt":1580659573682,"mc":[{"id":"1.168237985","rc":[{"batb":[[0,2.74,37.52],[1,2.7,57.27],[2,2.58,14.01]],"ltp":4.2,"tv":79.99,"id":16676048},{"batb":[[0,9.6,23.94],[1,9.4,16.28],[2,5.6,10.78]],"ltp":3.4,"tv":48.14,"id":16676046},{"batb":[[0,5.7,44.97],[1,5.6,24.57],[2,1.01,0.51]],"ltp":0.0,"tv":0.0,"id":21483494},{"batb":[[0,2.56,70.9],[1,2.52,67.47],[2,2.34,18.33]],"ltp":3.05,"tv":399.99,"id":21483493}]}]}
{"op":"mcm","clk":"1008333614","pt":1580659578929,"mc":[{"id":"1.168237985","rc":[{"batb":[[0,2.58,14.01],[1,1.01,0.51],[2,2.58,0]],"ltp":4.2,"tv":79.99,"id":16676048},{"batb":[[0,5.6,10.78],[1,1.01,0.51],[2,5.6,0]],"ltp":3.4,"tv":48.14,"id":16676046},{"batb":[[0,5.7,10.54],[1,1.01,0.51],[2,1.01,0]],"ltp":0.0,"tv":0.0,"id":21483494},{"batb":[[0,2.34,18.33],[1,1.01,0.51],[2,2.34,0]],"ltp":3.05,"tv":399.99,"id":21483493}]}]}
{"op":"mcm","clk":"1008334486","pt":1580659583021,"mc":[{"id":"1.168237985","rc":[{"batb":[[0,2.6,57.07],[1,2.58,14.01],[2,2.56,65.59]],"ltp":4.2,"tv":79.99,"id":16676048},{"batb":[[0,5.8,20.71],[1,5.7,24.49],[2,5.6,10.78]],"ltp":3.4,"tv":48.14,"id":16676046},{"batb":[[1,5.5,29.47],[2,5.4,26.7]],"ltp":0.0,"tv":0.0,"id":21483494},{"batb":[[1,2.32,84.2],[2,2.28,88.77]],"ltp":3.05,"tv":399.99,"id":21483493}]}]}
{"op":"mcm","clk":"1008334789","pt":1580659584651,"mc":[{"id":"1.168237985","rc":[{"batb":[[0,2.58,14.01],[1,1.01,0.51],[2,2.56,0]],"ltp":4.2,"tv":79.99,"id":16676048},{"batb":[[1,1.01,0.51],[2,5.4,0]],"ltp":0.0,"tv":0.0,"id":21483494},{"batb":[[1,1.01,0.51],[2,2.28,0]],"ltp":3.05,"tv":399.99,"id":21483493}]}]}
{"op":"mcm","clk":"1008335448","pt":1580659587827,"mc":[{"id":"1.168237985","rc":[{"batb":[[0,2.88,49.22],[1,2.84,50.31],[2,2.58,14.01]],"ltp":4.2,"tv":79.99,"id":16676048},{"batb":[[0,6,23.46],[1,5.9,22.05],[2,5.7,10.54]],"ltp":0.0,"tv":0.0,"id":21483494},{"batb":[[0,2.88,50.1],[1,2.84,49.38],[2,2.34,18.33]],"ltp":3.05,"tv":399.99,"id":21483493}]}]}
{"op":"mcm","clk":"1008335679","pt":1580659588923,"mc":[{"id":"1.168237985","rc":[{"batb":[[1,2.84,61.17],[2,2.74,11.8]],"batl":[[1,3.15,24.63]],"ltp":4.2,"tv":79.99,"id":16676048},{"batl":[[0,6.4,10.39],[1,9.6,9.05]],"ltp":3.4,"tv":48.14,"id":16676046},{"batb":[[2,5.8,19.59]],"batl":[[1,7.2,16.6]],"ltp":0.0,"tv":0.0,"id":21483494},{"batb":[[0,2.88,60.56],[2,2.6,13.77]],"batl":[[1,3.35,21.32]],"ltp":3.05,"tv":399.99,"id":21483493}]}]}
{"op":"mcm","clk":"1008339603","pt":1580659607856,"mc":[{"id":"1.168237985","rc":[{"batb":[[0,2.74,11.8],[1,1.01,0.51],[2,2.74,0]],"batl":[[0,3.15,24.63],[1,3.15,0]],"ltp":4.2,"tv":79.99,"id":16676048},{"batb":[[0,4.7,16.52],[1,1.01,0.51],[2,5.6,0]],"batl":[[0,9.6,9.05],[1,9.6,0]],"ltp":3.4,"tv":48.14,"id":16676046},{"batb":[[0,5.8,19.59],[1,1.01,0.51],[2,5.8,0]],"batl":[[0,7.2,16.6],[1,7.2,0]],"ltp":0.0,"tv":0.0,"id":21483494},{"batb":[[0,2.6,13.77],[1,1.01,0.51],[2,2.6,0]],"batl":[[0,3.35,21.32],[1,3.35,0]],"ltp":3.05,"tv":399.99,"id":21483493}]}]}
{"op":"mcm","clk":"1008340158","pt":1580659610553,"mc":[{"id":"1.168237985","rc":[{"batb":[[0,2.78,47.57],[1,2.74,66.89],[2,1.01,0.51]],"ltp":4.2,"tv":79.99,"id":16676048},{"batb":[[0,4.8,39.96],[1,4.7,53.96],[2,1.01,0.51]],"ltp":3.4,"tv":48.14,"id":16676046},{"batb":[[0,5.8,43.36],[1,5.7,23.77],[2,1.01,0.51]],"ltp":0.0,"tv":0.0,"id":21483494},{"batb":[[0,2.62,47.5],[1,2.6,13.77],[2,2.58,63.5]],"ltp":3.05,"tv":399.99,"id":21483493}]}]}
{"op":"mcm","clk":"1008340466","pt":1580659611950,"mc":[{"id":"1.168237985","rc":[{"batb":[[0,2.74,11.8],[1,1.01,0.51],[2,1.01,0]],"ltp":4.2,"tv":79.99,"id":16676048},{"batb":[[0,4.7,16.52],[1,1.01,0.51],[2,1.01,0]],"ltp":3.4,"tv":48.14,"id":16676046},{"batb":[[1,1.01,0.51],[2,1.01,0]],"ltp":0.0,"tv":0.0,"id":21483494},{"batb":[[0,2.6,13.77],[1,1.01,0.51],[2,2.58,0]],"ltp":3.05,"tv":399.99,"id":21483493}]}]}
{"op":"mcm","clk":"1008341105","pt":1580659614963,"mc":[{"id":"1.168237985","rc":[{"batb":[[0,2.86,48.05],[1,2.82,51.22],[2,2.74,11.8]],"ltp":4.2,"tv":79.99,"id":16676048},{"batb":[[0,6.2,18.03],[1,6,43.09],[2,4.7,16.52]],"ltp":3.4,"tv":48.14,"id":16676046},{"batb":[[0,5.9,36.76],[1,5.8,43.36],[2,1.01,0.51]],"ltp":0.0,"tv":0.0,"id":21483494},{"batb":[[0,2.82,54.36],[1,2.78,52.15],[2,2.6,13.77]],"ltp":3.05,"tv":399.99,"id":21483493}]}]}
{"op":"mcm","clk":"1008341266","pt":1580659615671,"mc":[{"id":"1.168237985","rc":[{"batb":[[0,2.82,51.22],[1,2.74,11.8],[2,1.01,0.51]],"ltp":4.2,"tv":79.99,"id":16676048},{"batb":[[0,6,43.09],[1,4.7,16.52],[2,1.01,0.51]],"ltp":3.4,"tv":48.14,"id":16676046},{"batb":[[0,5.9,22.18],[1,5.8,19.59]],"ltp":0.0,"tv":0.0,"id":21483494},{"batb":[[1,2.6,13.77],[2,1.01,0.51]],"ltp":3.05,"tv":399.99,"id":21483493}]}]}
{"op":"mcm","clk":"1008341882","pt":1580659618564,"mc":[{"id":"1.168237985","rc":[{"batb":[[1,2.78,52.8],[2,2.74,11.8]],"ltp":4.2,"tv":79.99,"id":16676048},{"batb":[[1,5.9,22.14],[2,4.7,16.52]],"ltp":3.4,"tv":48.14,"id":16676046},{"batb":[[0,6,29.81],[1,5.9,22.18],[2,5.8,19.59]],"ltp":0.0,"tv":0.0,"id":21483494},{"batb":[[0,2.86,45.44],[1,2.82,54.36],[2,2.6,13.77]],"ltp":3.05,"tv":399.99,"id":21483493}]}]}
{"op":"mcm","clk":"1008342176","pt":1580659619876,"mc":[{"id":"1.168237985","rc":[{"batb":[[0,2.74,11.8],[1,1.01,0.51],[2,2.74,0]],"ltp":4.2,"tv":79.99,"id":16676048},{"batb":[[0,4.7,16.52],[1,1.01,0.51],[2,4.7,0]],"ltp":3.4,"tv":48.14,"id":16676046},{"batb":[[0,5.9,22.18],[1,5.8,19.59],[2,1.01,0.51]],"ltp":0.0,"tv":0.0,"id":21483494},{"batb":[[0,2.6,13.77],[1,1.01,0.51],[2,2.6,0]],"ltp":3.05,"tv":399.99,"id":21483493}]}]}
{"op":"mcm","clk":"1008342718","pt":1580659622441,"mc":[{"id":"1.168237985","rc":[{"batb":[[0,2.74,57.97],[1,2.7,56.94],[2,1.01,0.51]],"ltp":4.2,"tv":79.99,"id":16676048},{"batb":[[0,4.7,70.95],[1,4.6,38.69],[2,1.01,0.51]],"ltp":3.4,"tv":48.14,"id":16676046},{"batb":[[1,5.8,42.82]],"ltp":0.0,"tv":0.0,"id":21483494},{"batb":[[0,2.66,39.14],[1,2.62,61.46],[2,2.6,13.77]],"ltp":3.05,"tv":399.99,"id":21483493}]}]}
{"op":"mcm","clk":"1008344609","pt":1580659631003,"mc":[{"id":"1.168237985","rc":[{"batb":[[0,2.74,11.8],[1,1.01,0.51],[2,1.01,0]],"ltp":4.2,"tv":79.99,"id":16676048},{"batb":[[0,5.8,19.59],[1,1.01,0.51],[2,1.01,0]],"ltp":0.0,"tv":0.0,"id":21483494},{"batb":[[0,2.6,13.77],[1,1.01,0.51],[2,2.6,0]],"ltp":3.05,"tv":399.99,"id":21483493}]}]}
{"op":"mcm","clk":"1008345271","pt":1580659633874,"mc":[{"id":"1.168237985","rc":[{"batb":[[0,2.92,36.01],[1,2.88,48.35],[2,2.74,11.8]],"ltp":4.2,"tv":79.99,"id":16676048},{"batb":[[0,6.2,28.62],[1,6,42.18],[2,5.8,19.59]],"ltp":0.0,"tv":0.0,"id":21483494},{"batb":[[0,3.1,69.63],[1,3.05,51.54],[2,2.6,13.77]],"ltp":3.05,"tv":399.99,"id":21483493}]}]}
{"op":"mcm","clk":"1008345512","pt":1580659635025,"mc":[{"id":"1.168237985","rc":[{"batb":[[1,2.9,25.65],[2,2.88,48.35]],"batl":[[0,3.15,24]],"ltp":4.2,"tv":79.99,"id":16676048},{"batb":[[2,4.1,22.11]],"batl":[[0,5.3,15.74],[1,6.6,19.28]],"ltp":3.4,"tv":48.14,"id":16676046},{"batb":[[1,6,60.67],[2,1.01,0.51]],"batl":[[0,7.2,16.05]],"ltp":0.0,"tv":0.0,"id":21483494},{"batb":[[1,3.05,73.73],[2,2.82,11.02]],"batl":[[1,3.6,17.94]],"ltp":3.05,"tv":399.99,"id":21483493}]}]}
{"op":"mcm","clk":"1008349345","pt":1580659653381,"mc":[{"id":"1.168237985","rc":[{"trd":[[3.35,4.72]],"batl":[[0,3.35,18.96]],"ltp":3.35,"tv":404.71,"id":21483493}],"tv":532.85}]}
{"op":"mcm","clk":"1008350295","pt":1580659657845,"mc":[{"id":"1.168237985","rc":[{"batb":[[0,2.86,10.7],[1,1.01,0.51],[2,2.88,0]],"ltp":4.2,"tv":79.99,"id":16676048},{"batb":[[0,4.1,22.11],[1,1.01,0.51],[2,4.1,0]],"batl":[[0,6.6,19.28],[1,6.6,0]],"ltp":3.4,"tv":48.14,"id":16676046},{"batb":[[0,6,60.67],[1,1.01,0.51],[2,1.01,0]],"ltp":0.0,"tv":0.0,"id":21483494},{"batb":[[0,2.82,11.02],[1,1.01,0.51],[2,2.82,0]],"batl":[[0,3.6,17.94],[1,3.6,0]],"ltp":3.35,"tv":404.71,"id":21483493}]}]}
{"op":"mcm","clk":"1008351018","pt":1580659660962,"mc":[{"id":"1.168237985","rc":[{"batb":[[0,2.86,50.7],[1,2.82,50.97],[2,1.01,0.51]],"ltp":4.2,"tv":79.99,"id":16676048},{"batb":[[0,4.3,38.51],[1,4.2,48.04],[2,4.1,22.11]],"ltp":3.4,"tv":48.14,"id":16676046},{"batb":[[1,5.9,22.08],[2,1.01,0.51]],"ltp":0.0,"tv":0.0,"id":21483494},{"batb":[[0,2.9,43.21],[1,2.86,48.92],[2,2.82,11.02]],"ltp":3.35,"tv":404.71,"id":21483493}]}]}
{"op":"mcm","clk":"1008351254","pt":1580659662036,"mc":[{"id":"1.168237985","rc":[{"batb":[[0,2.86,10.7],[1,1.01,0.51],[2,1.01,0]],"ltp":4.2,"tv":79.99,"id":16676048},{"batb":[[1,1.01,0.51],[2,1.01,0]],"ltp":0.0,"tv":0.0,"id":21483494},{"batb":[[0,2.82,11.02],[1,1.01,0.51],[2,2.82,0]],"ltp":3.35,"tv":404.71,"id":21483493}]}]}
{"op":"mcm","clk":"1008351852","pt":1580659664643,"mc":[{"id":"1.168237985","rc":[{"batb":[[0,2.94,54.87],[1,2.9,47.4],[2,2.86,10.7]],"ltp":4.2,"tv":79.99,"id":16676048},{"batb":[[0,6.2,47.32],[1,6,60.67],[2,1.01,0.51]],"ltp":0.0,"tv":0.0,"id":21483494},{"batb":[[0,3.25,70.27],[1,3.2,45.68],[2,2.82,11.02]],"ltp":3.35,"tv":404.71,"id":21483493}]}]}
{"op":"mcm","clk":"1008352051","pt":1580659665552,"mc":[{"id":"1.168237985","rc":[{"batb":[[1,2.92,25.02],[2,2.9,47.4]],"batl":[[1,3.35,20.77]],"ltp":4.2,"tv":79.99,"id":16676048},{"batl":[[0,4.6,21.01],[1,5.9,12.27]],"ltp":3.4,"tv":48.14,"id":16676046},{"batb":[[1,6,60.43]],"batl":[[1,7.6,14.95]],"ltp":0.0,"tv":0.0,"id":21483494},{"batb":[[0,3.3,18.49],[1,3.25,70.27],[2,3.2,45.68]],"batl":[[1,4.2,25.41]],"ltp":3.35,"tv":404.71,"id":21483493}]}]}
{"op":"mcm","clk":"1008354892","pt":1580659678131,"mc":[{"id":"1.168237985","rc":[{"batb":[[0,2.92,25.02],[1,2.82,11.09],[2,1.01,0.51]],"ltp":4.2,"tv":79.99,"id":16676048},{"batb":[[0,6.2,40.54]],"ltp":0.0,"tv":0.0,"id":21483494},{"batb":[[1,3.25,54.62]],"ltp":3.35,"tv":404.71,"id":21483493}]}]}
{"op":"mcm","clk":"1008355520","pt":1580659681051,"mc":[{"id":"1.168237985","rc":[{"batb":[[0,2.96,46.28],[1,2.92,71.76],[2,2.82,11.09]],"ltp":4.2,"tv":79.99,"id":16676048},{"batb":[[0,4.3,47.26]],"ltp":3.4,"tv":48.14,"id":16676046}]}]}
{"op":"mcm","clk":"1008364517","pt":1580659722045,"mc":[{"id":"1.168237985","rc":[{"batb":[[1,2.94,24.86],[2,2.92,46.74]],"batl":[[0,3.15,23.84]],"ltp":4.2,"tv":79.99,"id":16676048},{"batb":[[2,4.1,21.95]],"batl":[[0,4.6,20.85]],"ltp":3.4,"tv":48.14,"id":16676046},{"batb":[[0,3.25,73.27],[1,3.2,45.68],[2,2.98,23.84]],"ltp":3.35,"tv":404.71,"id":21483493}]}]}
{"op":"mcm","clk":"1008371986","pt":1580659755489,"mc":[{"id":"1.168237985","rc":[{"batb":[[0,2.82,11.09],[1,1.01,0.51],[2,2.92,0]],"batl":[[0,3.35,20.77],[1,3.35,0]],"ltp":4.2,"tv":79.99,"id":16676048},{"batb":[[0,3.3,19.36],[1,1.01,0.51],[2,4.1,0]],"batl":[[0,5.9,12.27],[1,5.9,0]],"ltp":3.4,"tv":48.14,"id":16676046},{"batb":[[0,6,60.43],[1,1.01,0.51],[2,1.01,0]],"batl":[[0,7.6,14.95],[1,7.6,0]],"ltp":0.0,"tv":0.0,"id":21483494},{"batb":[[0,2.98,23.84],[1,1.01,0.51],[2,2.98,0]],"batl":[[0,4.2,25.41],[1,4.2,0]],"ltp":3.35,"tv":404.71,"id":21483493}]}]}
{"op":"mcm","clk":"1008372557","pt":1580659757925,"mc":[{"id":"1.168237985","rc":[{"batb":[[0,2.84,55.95],[1,2.82,11.09],[2,2.8,51.92]],"ltp":4.2,"tv":79.99,"id":16676048},{"batb":[[0,3.35,64.63],[1,3.3,62.49],[2,1.01,0.51]],"ltp":3.4,"tv":48.14,"id":16676046},{"batb":[[1,5.9,21.96],[2,1.01,0.51]],"ltp":0.0,"tv":0.0,"id":21483494},{"batb":[[0,3,40.67],[1,2.98,23.84],[2,2.96,44.7]],"ltp":3.35,"tv":404.71,"id":21483493}]}]}
{"op":"mcm","clk":"1008372915","pt":1580659759505,"mc":[{"id":"1.168237985","rc":[{"batb":[[0,2.82,11.09],[1,1.01,0.51],[2,2.8,0]],"ltp":4.2,"tv":79.99,"id":16676048},{"batb":[[0,6,18.25],[1,1.01,0.51],[2,1.01,0]],"ltp":0.0,"tv":0.0,"id":21483494},{"batb":[[0,2.98,23.84],[1,1.01,0.51],[2,2.96,0]],"ltp":3.35,"tv":404.71,"id":21483493}]}]}
{"op":"mcm","clk":"1008373658","pt":1580659762939,"mc":[{"id":"1.168237985","rc":[{"batb":[[0,3.1,81.22],[1,3.05,51.93],[2,2.82,11.09]],"ltp":4.2,"tv":79.99,"id":16676048},{"batb":[[0,6.6,20.83],[1,6.4,36.7],[2,6,18.25]],"ltp":0.0,"tv":0.0,"id":21483494},{"batb":[[0,3.75,27.47],[1,3.7,32.28],[2,2.98,23.84]],"ltp":3.35,"tv":404.71,"id":21483493}]}]}
{"op":"mcm","clk":"1008373920","pt":1580659764005,"mc":[{"id":"1.168237985","rc":[{"batb":[[0,3.1,102.7],[2,2.94,24.71]],"batl":[[1,3.65,16.84]],"ltp":4.2,"tv":79.99,"id":16676048},{"batb":[[2,2.68,13.06]],"batl":[[0,3.6,18.57],[1,4.5,22.19]],"ltp":3.4,"tv":48.14,"id":16676046},{"batb":[[2,6.2,16.05]],"batl":[[1,8,13.53]],"ltp":0.0,"tv":0.0,"id":21483494},{"batb":[[0,3.75,40.69],[2,3.35,17.78]],"batl":[[1,5,17.39]],"ltp":3.35,"tv":404.71,"id":21483493}]}]}
{"op":"mcm","clk":"1008376500","pt":1580659775347,"mc":[{"id":"1.168237985","rc":[{"batb":[[0,3.1,90.47]],"ltp":4.2,"tv":79.99,"id":16676048},{"batb":[[0,3.35,53.72]],"ltp":3.4,"tv":48.14,"id":16676046}]}]}
{"op":"mcm","clk":"1008377191","pt":1580659778517,"mc":[{"id":"1.168237985","rc":[{"batb":[[0,2.94,24.71],[1,1.01,0.51],[2,2.94,0]],"batl":[[0,3.65,16.84],[1,3.65,0]],"ltp":4.2,"tv":79.99,"id":16676048},{"batb":[[0,2.68,13.06],[1,1.01,0.51],[2,2.68,0]],"batl":[[0,4.5,22.19],[1,4.5,0]],"ltp":3.4,"tv":48.14,"id":16676046},{"batb":[[0,6,17.39],[1,1.01,0.51],[2,6.2,0]],"batl":[[0,8,13.53],[1,8,0]],"ltp":0.0,"tv":0.0,"id":21483494},{"batb":[[0,3.35,17.78],[1,1.01,0.51],[2,3.35,0]],"batl":[[0,5,17.39],[1,5,0]],"ltp":3.35,"tv":404.71,"id":21483493}]}]}
{"op":"mcm","clk":"1008378902","pt":1580659785780,"mc":[{"id":"1.168237985","rc":[{"batb":[[0,3.15,66.36],[1,3.1,49.89],[2,2.94,24.71]],"ltp":4.2,"tv":79.99,"id":16676048},{"batb":[[0,3.2,41.29],[1,3.15,48.5],[2,2.68,13.06]],"ltp":3.4,"tv":48.14,"id":16676046},{"batb":[[0,6.6,41.41],[1,6.4,36.36],[2,6,17.39]],"ltp":0.0,"tv":0.0,"id":21483494},{"batb":[[0,3.9,27.34],[1,3.85,29.48],[2,3.35,17.78]],"ltp":3.35,"tv":404.71,"id":21483493}]}]}
{"op":"mcm","clk":"1008380188","pt":1580659791574,"mc":[{"id":"1.168237985","rc":[{"batb":[[0,2.94,24.71],[1,1.01,0.51],[2,2.94,0]],"ltp":4.2,"tv":79.99,"id":16676048},{"batb":[[0,2.68,13.06],[1,1.01,0.51],[2,2.68,0]],"ltp":3.4,"tv":48.14,"id":16676046},{"batb":[[0,6,17.39],[1,1.01,0.51],[2,6,0]],"ltp":0.0,"tv":0.0,"id":21483494},{"batb":[[0,3.35,17.78],[1,1.01,0.51],[2,3.35,0]],"ltp":3.35,"tv":404.71,"id":21483493}]}]}
{"op":"mcm","clk":"1008380848","pt":1580659794469,"mc":[{"id":"1.168237985","rc":[{"batb":[[0,2.96,44.09],[1,2.94,24.71],[2,2.92,46.69]],"ltp":4.2,"tv":79.99,"id":16676048},{"batb":[[1,2.66,66.4],[2,2.62,62.18]],"ltp":3.4,"tv":48.14,"id":16676046},{"batb":[[0,6.2,54.22],[1,6,58.89],[2,1.01,0.51]],"ltp":0.0,"tv":0.0,"id":21483494},{"batb":[[0,3.35,58.93],[1,3.3,42.6],[2,1.01,0.51]],"ltp":3.35,"tv":404.71,"id":21483493}]}]}
{"op":"mcm","clk":"1008381198","pt":1580659795969,"mc":[{"id":"1.168237985","rc":[{"batb":[[0,2.94,24.71],[1,1.01,0.51],[2,2.92,0]],"ltp":4.2,"tv":79.99,"id":16676048},{"batb":[[0,6,17.39],[1,1.01,0.51],[2,1.01,0]],"ltp":0.0,"tv":0.0,"id":21483494},{"batb":[[0,3.35,17.78],[1,1.01,0.51],[2,1.01,0]],"ltp":3.35,"tv":404.71,"id":21483493}]}]}
{"op":"mcm","clk":"1008381874","pt":1580659798888,"mc":[{"id":"1.168237985","rc":[{"batb":[[0,3.4,29.89],[1,3.35,59],[2,3.15,20.3]],"batl":[[1,4,13.85]],"ltp":4.2,"tv":79.99,"id":16676048},{"batl":[[0,2.86,12.83],[1,3.4,21.24],[2,4.5,22.19]],"ltp":3.4,"tv":48.14,"id":16676046},{"batb":[[0,7,28.1],[1,6.8,32.18],[2,6.6,14.4]],"batl":[[1,8.2,12.27]],"ltp":0.0,"tv":0.0,"id":21483494},{"batb":[[0,4.5,33.79],[1,4.4,60.77],[2,3.85,24.86]],"batl":[[1,6.2,11.17]],"ltp":3.35,"tv":404.71,"id":21483493}]}]}
{"op":"mcm","clk":"1008381953","pt":1580659799186,"mc":[{"id":"1.168237985","rc":[{"batl":[[2,4.5,0]],"ltp":3.4,"tv":48.14,"id":16676046}]}]}
{"op":"mcm","clk":"1008385502","pt":1580659815189,"mc":[{"id":"1.168237985","rc":[{"batb":[[1,2.26,20.54],[2,1.01,0.51]],"ltp":3.4,"tv":48.14,"id":16676046}]}]}
{"op":"mcm","clk":"1008386178","pt":1580659818337,"mc":[{"id":"1.168237985","rc":[{"batb":[[0,3.15,20.3],[1,1.01,0.51],[2,3.15,0]],"batl":[[0,4,13.85],[1,4,0]],"ltp":4.2,"tv":79.99,"id":16676048},{"batb":[[0,2.26,20.54],[1,1.01,0.51],[2,1.01,0]],"batl":[[0,3.4,21.24],[1,3.4,0]],"ltp":3.4,"tv":48.14,"id":16676046},{"batb":[[0,6.4,15.5],[1,1.01,0.51],[2,6.6,0]],"batl":[[0,8.2,12.27],[1,8.2,0]],"ltp":0.0,"tv":0.0,"id":21483494},{"batb":[[0,3.85,24.86],[1,1.01,0.51],[2,3.85,0]],"batl":[[0,6.2,11.17],[1,6.2,0]],"ltp":3.35,"tv":404.71,"id":21483493}]}]}
{"op":"mcm","clk":"1008386747","pt":1580659820908,"mc":[{"id":"1.168237985","rc":[{"batb":[[0,3.2,35.14],[1,3.15,68.56],[2,1.01,0.51]],"ltp":4.2,"tv":79.99,"id":16676048},{"batb":[[1,2.22,81.8],[2,2.2,50.68]],"ltp":3.4,"tv":48.14,"id":16676046},{"batb":[[0,6.6,41.43],[1,6.4,51.76],[2,1.01,0.51]],"ltp":0.0,"tv":0.0,"id":21483494},{"batb":[[0,3.9,53.36],[1,3.85,54.05],[2,1.01,0.51]],"ltp":3.35,"tv":404.71,"id":21483493}]}]}
{"op":"mcm","clk":"1008386873","pt":1580659821400,"mc":[{"id":"1.168237985","rc":[{"batb":[[0,3.15,20.3],[1,1.01,0.51],[2,1.01,0]],"ltp":4.2,"tv":79.99,"id":16676048},{"batb":[[1,1.01,0.51],[2,2.2,0]],"ltp":3.4,"tv":48.14,"id":16676046},{"batb":[[0,6.4,15.5],[1,1.01,0.51],[2,1.01,0]],"ltp":0.0,"tv":0.0,"id":21483494},{"batb":[[0,3.85,24.86],[1,1.01,0.51],[2,1.01,0]],"ltp":3.35,"tv":404.71,"id":21483493}]}]}
{"op":"mcm","clk":"1008387428","pt":1580659823948,"mc":[{"id":"1.168237985","rc":[{"batb":[[0,3.45,39.92],[1,3.4,40.02],[2,3.15,20.3]],"ltp":4.2,"tv":79.99,"id":16676048},{"batb":[[0,2.56,71.82],[1,2.52,68.98],[2,2.26,20.54]],"ltp":3.4,"tv":48.14,"id":16676046},{"batb":[[0,7,38.54],[1,6.8,31.86],[2,6.4,15.5]],"ltp":0.0,"tv":0.0,"id":21483494},{"batb":[[0,4.6,58.04],[1,4.5,39.88],[2,3.85,24.86]],"ltp":3.35,"tv":404.71,"id":21483493}]}]}
{"op":"mcm","clk":"1008387990","pt":1580659826352,"mc":[{"id":"1.168237985","rc":[{"batb":[[0,3.15,20.3],[1,1.01,0.51],[2,3.15,0]],"ltp":4.2,"tv":79.99,"id":16676048},{"batb":[[0,2.26,20.54],[1,1.01,0.51],[2,2.26,0]],"ltp":3.4,"tv":48.14,"id":16676046},{"batb":[[0,6.4,15.5],[1,1.01,0.51],[2,6.4,0]],"ltp":0.0,"tv":0.0,"id":21483494},{"batb":[[0,3.85,24.86],[1,1.01,0.51],[2,3.85,0]],"ltp":3.35,"tv":404.71,"id":21483493}]}]}
{"op":"mcm","clk":"1008388693","pt":1580659829344,"mc":[{"id":"1.168237985","rc":[{"batb":[[0,3.2,35.08],[1,3.15,68.56],[2,1.01,0.51]],"ltp":4.2,"tv":79.99,"id":16676048},{"batb":[[1,2.22,82.09],[2,2.2,50.68]],"ltp":3.4,"tv":48.14,"id":16676046},{"batb":[[0,6.6,41.39],[1,6.4,51.76],[2,1.01,0.51]],"ltp":0.0,"tv":0.0,"id":21483494},{"batb":[[0,3.9,53.23],[1,3.85,54.05],[2,1.01,0.51]],"ltp":3.35,"tv":404.71,"id":21483493}]}]}
{"op":"mcm","clk":"1008389522","pt":1580659832934,"mc":[{"id":"1.168237985","rc":[{"batb":[[1,1.01,0.51],[2,2.2,0]],"ltp":3.4,"tv":48.14,"id":16676046}]}]}
{"op":"mcm","clk":"1008390166","pt":1580659835917,"mc":[{"id":"1.168237985","rc":[{"batb":[[0,3.15,43.95],[1,3.1,50.5],[2,2.26,20.54]],"ltp":3.4,"tv":48.14,"id":16676046}]}]}
{"op":"mcm","clk":"1008390375","pt":1580659836792,"mc":[{"id":"1.168237985","rc":[{"batb":[[2,2.94,24.55]],"batl":[[0,3.45,19.59],[1,3.8,15.26]],"ltp":4.2,"tv":79.99,"id":16676048},{"batb":[[1,3.1,72.53],[2,2.48,16.29]],"batl":[[1,4.4,23.6]],"ltp":3.4,"tv":48.14,"id":16676046},{"batb":[[2,6,17.47]],"batl":[[0,7.6,14.56],[1,8,13.06]],"ltp":0.0,"tv":0.0,"id":21483494},{"batb":[[2,3.4,16.84]],"batl":[[0,4.4,23.53],[1,5.5,14.16]],"ltp":3.35,"tv":404.71,"id":21483493}]}]}
{"op":"mcm","clk":"1008394012","pt":1580659853503,"mc":[{"id":"1.168237985","rc":[{"batb":[[0,2.94,24.55],[1,1.01,0.51],[2,2.94,0]],"batl":[[0,3.8,15.26],[1,3.8,0]],"ltp":4.2,"tv":79.99,"id":16676048},{"batb":[[0,2.48,16.29],[1,1.01,0.51],[2,2.48,0]],"batl":[[0,4.4,23.6],[1,4.4,0]],"ltp":3.4,"tv":48.14,"id":16676046},{"batb":[[0,6.4,17.1],[1,6,17.47],[2,1.01,0.51]],"batl":[[0,8,13.06],[1,8,0]],"ltp":0.0,"tv":0.0,"id":21483494},{"batb":[[0,3.4,16.84],[1,1.01,0.51],[2,3.4,0]],"batl":[[0,5.5,14.16],[1,5.5,0]],"ltp":3.35,"tv":404.71,"id":21483493}]}]}
{"op":"mcm","clk":"1008394608","pt":1580659856109,"mc":[{"id":"1.168237985","rc":[{"batb":[[0,2.98,41.61],[1,2.94,70.5],[2,1.01,0.51]],"ltp":4.2,"tv":79.99,"id":16676048},{"batb":[[1,2.44,42.29],[2,2.4,78.93]],"ltp":3.4,"tv":48.14,"id":16676046},{"batb":[[1,6.2,39.47],[2,6,17.47]],"ltp":0.0,"tv":0.0,"id":21483494},{"batb":[[0,3.4,63.87],[1,3.35,40.91],[2,1.01,0.51]],"ltp":3.35,"tv":404.71,"id":21483493}]}]}
{"op":"mcm","clk":"1008397513","pt":1580659868873,"mc":[{"id":"1.168237985","rc":[{"batb":[[1,1.01,0.51],[2,2.4,0]],"ltp":3.4,"tv":48.14,"id":16676046}]}]}
{"op":"mcm","clk":"1008398290","pt":1580659871753,"mc":[{"id":"1.168237985","rc":[{"batb":[[0,4,53.98],[1,3.95,28],[2,2.48,16.29]],"ltp":3.4,"tv":48.14,"id":16676046}]}]}
{"op":"mcm","clk":"1008398540","pt":1580659872882,"mc":[{"id":"1.168237985","rc":[{"batb":[[2,2.76,11.72]],"batl":[[0,3.2,23.6],[1,3.55,18.33]],"ltp":4.2,"tv":79.99,"id":16676048},{"batb":[[1,3.95,53.02],[2,2.88,10.86]],"batl":[[1,6.4,10.78]],"ltp":3.4,"tv":48.14,"id":16676046},{"batl":[[0,7.2,16.29],[1,7.8,14.24]],"ltp":0.0,"tv":0.0,"id":21483494},{"batb":[[2,3,23.68]],"batl":[[0,3.75,16.29],[1,4.7,19.51]],"ltp":3.35,"tv":404.71,"id":21483493}]}]}
{"op":"mcm","clk":"1008399498","pt":1580659876960,"mc":[{"id":"1.168237985","rc":[{"trd":[[4,30]],"batb":[[0,4,38.98]],"ltp":4.0,"tv":78.14,"id":16676046}],"tv":562.85}]}
{"op":"mcm","clk":"1008400275","pt":1580659880675,"mc":[{"id":"1.168237985","rc":[{"batb":[[0,4,50.8]],"ltp":4.0,"tv":78.14,"id":16676046}]}]}
{"op":"mcm","clk":"1008402714","pt":1580659891705,"mc":[{"id":"1.168237985","rc":[{"batb":[[0,2.76,11.72],[1,1.01,0.51],[2,2.76,0]],"batl":[[0,3.55,18.33],[1,3.55,0]],"ltp":4.2,"tv":79.99,"id":16676048},{"batb":[[0,2.88,10.86],[1,1.01,0.51],[2,2.88,0]],"batl":[[0,6.4,10.78],[1,6.4,0]],"ltp":4.0,"tv":78.14,"id":16676046},{"batb":[[0,5.9,19.04],[1,1.01,0.51],[2,6,0]],"batl":[[0,7.8,14.24],[1,7.8,0]],"ltp":0.0,"tv":0.0,"id":21483494},{"batb":[[0,3,23.68],[1,1.01,0.51],[2,3,0]],"batl":[[0,4.7,19.51],[1,4.7,0]],"ltp":3.35,"tv":404.71,"id":21483493}]}]}
{"op":"mcm","clk":"1008403325","pt":1580659894499,"mc":[{"id":"1.168237985","rc":[{"batb":[[0,2.78,44.02],[1,2.76,11.72],[2,2.74,54.96]],"ltp":4.2,"tv":79.99,"id":16676048},{"batb":[[1,2.84,57.36],[2,2.8,52.33]],"ltp":4.0,"tv":78.14,"id":16676046},{"batb":[[0,6,35.91],[1,5.9,41.13],[2,1.01,0.51]],"ltp":0.0,"tv":0.0,"id":21483494},{"batb":[[1,2.98,50.94],[2,2.94,45.47]],"ltp":3.35,"tv":404.71,"id":21483493}]}]}
{"op":"mcm","clk":"1008403505","pt":1580659895307,"mc":[{"id":"1.168237985","rc":[{"batb":[[0,2.76,11.72],[1,1.01,0.51],[2,2.74,0]],"ltp":4.2,"tv":79.99,"id":16676048},{"batb":[[1,1.01,0.51],[2,2.8,0]],"ltp":4.0,"tv":78.14,"id":16676046},{"batb":[[0,5.9,19.04],[1,1.01,0.51],[2,1.01,0]],"ltp":0.0,"tv":0.0,"id":21483494},{"batb":[[1,1.01,0.51],[2,2.94,0]],"ltp":3.35,"tv":404.71,"id":21483493}]}]}
{"op":"mcm","clk":"1008404363","pt":1580659899000,"mc":[{"id":"1.168237985","rc":[{"batb":[[0,3,87.06],[1,2.96,44.87],[2,2.76,11.72]],"ltp":4.2,"tv":79.99,"id":16676048},{"batb":[[0,3.7,50.36],[1,3.65,33.8],[2,2.88,10.86]],"ltp":4.0,"tv":78.14,"id":16676046},{"batb":[[0,6.4,35.62],[1,6.2,39.01],[2,5.9,19.04]],"ltp":0.0,"tv":0.0,"id":21483494},{"batb":[[0,3.55,39.24],[1,3.5,36.85],[2,3,23.68]],"ltp":3.35,"tv":404.71,"id":21483493}]}]}
{"op":"mcm","clk":"1008405052","pt":1580659901933,"mc":[{"id":"1.168237985","rc":[{"batb":[[0,2.76,11.72],[1,1.01,0.51],[2,2.76,0]],"ltp":4.2,"tv":79.99,"id":16676048},{"batb":[[0,2.88,10.86],[1,1.01,0.51],[2,2.88,0]],"ltp":4.0,"tv":78.14,"id":16676046},{"batb":[[0,5.9,19.04],[1,1.01,0.51],[2,5.9,0]],"ltp":0.0,"tv":0.0,"id":21483494},{"batb":[[0,3,23.68],[1,1.01,0.51],[2,3,0]],"ltp":3.35,"tv":404.71,"id":21483493}]}]}
{"op":"mcm","clk":"1008405677","pt":1580659904857,"mc":[{"id":"1.168237985","rc":[{"batb":[[0,2.78,44.02],[1,2.76,11.72],[2,2.74,54.96]],"ltp":4.2,"tv":79.99,"id":16676048},{"batb":[[1,2.84,57.36],[2,2.8,52.33]],"ltp":4.0,"tv":78.14,"id":16676046},{"batb":[[0,6,35.91],[1,5.9,41.13],[2,1.01,0.51]],"ltp":0.0,"tv":0.0,"id":21483494},{"batb":[[1,2.98,50.94],[2,2.94,45.47]],"ltp":3.35,"tv":404.71,"id":21483493}]}]}
{"op":"mcm","clk":"1008406323","pt":1580659907834,"mc":[{"id":"1.168237985","rc":[{"batb":[[0,2.76,11.72],[1,1.01,0.51],[2,2.74,0]],"ltp":4.2,"tv":79.99,"id":16676048},{"batb":[[0,5.9,19.04],[1,1.01,0.51],[2,1.01,0]],"ltp":0.0,"tv":0.0,"id":21483494},{"batb":[[1,1.01,0.51],[2,2.94,0]],"ltp":3.35,"tv":404.71,"id":21483493}]}]}
{"op":"mcm","clk":"1008406974","pt":1580659910896,"mc":[{"id":"1.168237985","rc":[{"batb":[[0,3.3,49.89],[1,3.25,44.59],[2,2.76,11.72]],"ltp":4.2,"tv":79.99,"id":16676048},{"batb":[[0,6.8,34.15],[1,6.6,34.09],[2,5.9,19.04]],"ltp":0.0,"tv":0.0,"id":21483494},{"batb":[[0,4.2,58.83],[1,4.1,49.55],[2,3,23.68]],"ltp":3.35,"tv":404.71,"id":21483493}]}]}
{"op":"mcm","clk":"1008407136","pt":1580659911586,"mc":[{"id":"1.168237985","rc":[{"batb":[[1,3.25,63.63],[2,2.92,24.94]],"batl":[[1,4.2,24.71]],"ltp":4.2,"tv":79.99,"id":16676048},{"batl":[[0,3.1,10.7],[1,4.3,24.86]],"ltp":4.0,"tv":78.14,"id":16676046},{"batb":[[2,6.4,15.19]],"batl":[[1,8.2,12.2]],"ltp":0.0,"tv":0.0,"id":21483494},{"batb":[[0,4.2,79.37],[2,3.5,16.05]],"batl":[[1,6.8,18.73]],"ltp":3.35,"tv":404.71,"id":21483493}]}]}
{"op":"mcm","clk":"1008411308","pt":1580659929596,"mc":[{"id":"1.168237985","rc":[{"batb":[[0,2.92,24.94],[1,1.01,0.51],[2,2.92,0]],"batl":[[0,4.2,24.71],[1,4.2,0]],"ltp":4.2,"tv":79.99,"id":16676048},{"batb":[[0,2.16,23.84],[1,1.01,0.51],[2,2.8,0]],"batl":[[0,4.3,24.86],[1,4.3,0]],"ltp":4.0,"tv":78.14,"id":16676046},{"batb":[[0,6.2,17.07],[1,1.01,0.51],[2,6.4,0]],"batl":[[0,8.2,12.2],[1,8.2,0]],"ltp":0.0,"tv":0.0,"id":21483494},{"batb":[[0,3.5,16.05],[1,1.01,0.51],[2,3.5,0]],"batl":[[0,6.8,18.73],[1,6.8,0]],"ltp":3.35,"tv":404.71,"id":21483493}]}]}
{"op":"mcm","clk":"1008412078","pt":1580659932767,"mc":[{"id":"1.168237985","rc":[{"batb":[[0,2.98,39.08],[1,2.94,45.98],[2,2.9,25.34]],"ltp":4.2,"tv":79.99,"id":16676048},{"batb":[[0,2.14,24.23],[1,2.06,74.46],[2,2.04,63.24]],"batl":[[0,4.2,25.65]],"ltp":4.0,"tv":78.14,"id":16676046},{"batb":[[0,6.4,22.23],[1,6.2,56.03],[2,1.01,0.51]],"batl":[[0,8.4,11.88]],"ltp":0.0,"tv":0.0,"id":21483494},{"batb":[[0,3.5,15.66],[1,3.45,37.56],[2,3.4,39.55]],"batl":[[0,6.8,18.18]],"ltp":3.35,"tv":404.71,"id":21483493}]}]}
{"op":"mcm","clk":"1008412211","pt":1580659933384,"mc":[{"id":"1.168237985","rc":[{"batb":[[0,2.9,25.34],[1,1.01,0.51],[2,2.9,0]],"ltp":4.2,"tv":79.99,"id":16676048},{"batb":[[1,1.01,0.51],[2,2.04,0]],"ltp":4.0,"tv":78.14,"id":16676046},{"batb":[[0,6.2,16.68],[1,1.01,0.51],[2,1.01,0]],"ltp":0.0,"tv":0.0,"id":21483494},{"batb":[[1,1.01,0.51],[2,3.4,0]],"ltp":3.35,"tv":404.71,"id":21483493}]}]}
{"op":"mcm","clk":"1008413038","pt":1580659936963,"mc":[{"id":"1.168237985","rc":[{"batb":[[0,3.4,51.27],[1,3.35,41.4],[2,2.9,25.34]],"ltp":4.2,"tv":79.99,"id":16676048},{"batb":[[0,2.64,61.26],[1,2.6,63.49],[2,2.14,24.23]],"ltp":4.0,"tv":78.14,"id":16676046},{"batb":[[0,7,23.81],[1,6.8,32.21],[2,6.2,16.68]],"ltp":0.0,"tv":0.0,"id":21483494},{"batb":[[0,4.5,47.68],[1,4.4,42.19],[2,3.5,15.66]],"ltp":3.35,"tv":404.71,"id":21483493}]}]}
{"op":"mcm","clk":"1008413865","pt":1580659940906,"mc":[{"id":"1.168237985","rc":[{"batb":[[0,2.9,25.34],[1,1.01,0.51],[2,2.9,0]],"ltp":4.2,"tv":79.99,"id":16676048},{"batb":[[0,2.14,24.23],[1,1.01,0.51],[2,2.14,0]],"ltp":4.0,"tv":78.14,"id":16676046},{"batb":[[0,6.2,16.68],[1,1.01,0.51],[2,6.2,0]],"ltp":0.0,"tv":0.0,"id":21483494},{"batb":[[0,3.5,15.66],[1,1.01,0.51],[2,3.5,0]],"ltp":3.35,"tv":404.71,"id":21483493}]}]}
{"op":"mcm","clk":"1008414517","pt":1580659943775,"mc":[{"id":"1.168237985","rc":[{"batb":[[0,2.98,39.08],[1,2.94,45.98],[2,2.9,25.34]],"ltp":4.2,"tv":79.99,"id":16676048},{"batb":[[1,2.06,74.46],[2,2.04,63.24]],"ltp":4.0,"tv":78.14,"id":16676046},{"batb":[[0,6.4,22.23],[1,6.2,56.03],[2,1.01,0.51]],"ltp":0.0,"tv":0.0,"id":21483494},{"batb":[[1,3.45,37.56],[2,3.4,39.55]],"ltp":3.35,"tv":404.71,"id":21483493}]}]}
{"op":"mcm","clk":"1008415922","pt":1580659950093,"mc":[{"id":"1.168237985","rc":[{"batb":[[0,2.9,25.34],[1,1.01,0.51],[2,2.9,0]],"ltp":4.2,"tv":79.99,"id":16676048},{"batb":[[0,6.2,16.68],[1,1.01,0.51],[2,1.01,0]],"ltp":0.0,"tv":0.0,"id":21483494},{"batb":[[1,1.01,0.51],[2,3.4,0]],"ltp":3.35,"tv":404.71,"id":21483493}]}]}
{"op":"mcm","clk":"1008416577","pt":1580659952975,"mc":[{"id":"1.168237985","rc":[{"batb":[[0,3.9,40.68],[1,3.85,29.76],[2,2.9,25.34]],"ltp":4.2,"tv":79.99,"id":16676048},{"batb":[[0,7.6,26.34],[1,7.4,26.83],[2,6.2,16.68]],"ltp":0.0,"tv":0.0,"id":21483494},{"batb":[[0,6.2,31.85],[1,6,41.37],[2,3.5,15.66]],"ltp":3.35,"tv":404.71,"id":21483493}]}]}
{"op":"mcm","clk":"1008416753","pt":1580659953793,"mc":[{"id":"1.168237985","rc":[{"batb":[[2,3.8,13.06]],"batl":[[1,4.5,21.64]],"ltp":4.2,"tv":79.99,"id":16676048},{"batl":[[0,2.26,23.6],[1,2.66,15.11]],"ltp":4.0,"tv":78.14,"id":16676046},{"batb":[[2,7,12.59]],"batl":[[1,8.8,10.94]],"ltp":0.0,"tv":0.0,"id":21483494},{"batb":[[2,5.7,19.51]],"batl":[[1,8,12.83]],"ltp":3.35,"tv":404.71,"id":21483493}]}]}
{"op":"mcm","clk":"1008421282","pt":1580659973995,"mc":[{"id":"1.168237985","rc":[{"trd":[[2.14,48.47]],"batb":[[0,2.06,74.46],[1,2.04,63.24],[2,1.96,15.82]],"batl":[[0,2.08,74.21],[1,2.26,23.6],[2,2.66,15.11]],"ltp":2.14,"tv":126.61,"id":16676046}],"tv":611.32}]}
{"op":"mcm","clk":"1008422212","pt":1580659978020,"mc":[{"id":"1.168237985","rc":[{"batb":[[0,6.2,25.82]],"ltp":3.35,"tv":404.71,"id":21483493}]}]}
{"op":"mcm","clk":"1008422640","pt":1580659979790,"mc":[{"id":"1.168237985","rc":[{"batl":[[0,2.26,23.6],[1,2.66,15.11],[2,2.66,0]],"ltp":2.14,"tv":126.61,"id":16676046}]}]}
{"op":"mcm","clk":"1008423384","pt":1580659982978,"mc":[{"id":"1.168237985","rc":[{"trd":[[2.06,148.42]],"batb":[[0,2.04,63.49],[1,1.96,15.82],[2,1.01,0.51]],"ltp":2.06,"tv":275.02,"id":16676046}],"tv":759.74}]}
{"op":"mcm","clk":"1008424053","pt":1580659985882,"mc":[{"id":"1.168237985","rc":[{"batb":[[0,3.9,51.48]],"ltp":4.2,"tv":79.99,"id":16676048},{"batb":[[0,2.06,58.19],[1,2.04,63.24],[2,1.96,15.82]],"ltp":2.06,"tv":275.02,"id":16676046},{"batb":[[0,6.2,33.62]],"ltp":3.35,"tv":404.71,"id":21483493}]}]}
{"op":"mcm","clk":"1008424775","pt":1580659988973,"mc":[{"id":"1.168237985","rc":[{"batb":[[0,3.8,13.06],[1,3.45,16.21],[2,1.01,0.51]],"ltp":4.2,"tv":79.99,"id":16676048},{"batb":[[0,1.96,15.82],[1,1.01,0.51],[2,1.96,0]],"ltp":2.06,"tv":275.02,"id":16676046},{"batb":[[0,7,12.59],[1,6.6,14.01],[2,1.01,0.51]],"ltp":0.0,"tv":0.0,"id":21483494},{"batb":[[0,5.7,19.51],[1,4.7,15.5],[2,1.01,0.51]],"ltp":3.35,"tv":404.71,"id":21483493}]}]}
{"op":"mcm","clk":"1008424967","pt":1580659989791,"mc":[{"id":"1.168237985","rc":[{"batb":[[0,3.45,16.21],[1,1.01,0.51],[2,1.01,0]],"batl":[[0,4.5,21.64],[1,4.5,0]],"ltp":4.2,"tv":79.99,"id":16676048},{"batl":[[0,2.66,15.11],[1,2.66,0]],"ltp":2.06,"tv":275.02,"id":16676046},{"batb":[[0,6.6,14.01],[1,1.01,0.51],[2,1.01,0]],"batl":[[0,8.8,10.94],[1,8.8,0]],"ltp":0.0,"tv":0.0,"id":21483494},{"batb":[[0,4.7,15.5],[1,1.01,0.51],[2,1.01,0]],"batl":[[0,5.9,50]],"ltp":3.35,"tv":404.71,"id":21483493}]}]}
{"op":"mcm","clk":"1008425439","pt":1580659991884,"mc":[{"id":"1.168237985","rc":[{"batb":[[0,3.6,47.74],[1,3.55,36.15],[2,3.45,16.21]],"ltp":4.2,"tv":79.99,"id":16676048},{"batb":[[1,1.9,81.72],[2,1.88,81.35]],"ltp":2.06,"tv":275.02,"id":16676046},{"batb":[[0,7.2,17.99],[1,7,30.41],[2,6.6,14.01]],"ltp":0.0,"tv":0.0,"id":21483494},{"batb":[[0,5,38.55],[1,4.9,33.11],[2,4.7,15.5]],"ltp":3.35,"tv":404.71,"id":21483493}]}]}
{"op":"mcm","clk":"1008425612","pt":1580659992587,"mc":[{"id":"1.168237985","rc":[{"batb":[[0,3.45,16.21],[1,1.01,0.51],[2,3.45,0]],"batl":[[0,4.5,21.4]],"ltp":4.2,"tv":79.99,"id":16676048},{"batb":[[0,1.92,16.84],[1,1.01,0.51],[2,1.88,0]],"batl":[[0,2.6,16.29]],"ltp":2.06,"tv":275.02,"id":16676046},{"batb":[[1,6.8,13.14],[2,1.01,0.51]],"batl":[[0,9,10.23]],"ltp":0.0,"tv":0.0,"id":21483494},{"batb":[[0,4.9,14.32],[1,1.01,0.51],[2,4.7,0]],"batl":[[0,8.4,11.8],[1,8,0]],"ltp":3.35,"tv":404.71,"id":21483493}]}]}
{"op":"mcm","clk":"1008426116","pt":1580659994794,"mc":[{"id":"1.168237985","rc":[{"batb":[[0,3.85,42.05],[1,3.8,30.79],[2,3.45,16.21]],"ltp":4.2,"tv":79.99,"id":16676048},{"batb":[[0,2.12,53.95],[1,2.1,58.03],[2,1.92,16.84]],"ltp":2.06,"tv":275.02,"id":16676046},{"batb":[[0,7.4,40.11],[1,7.2,28.11],[2,6.8,13.14]],"ltp":0.0,"tv":0.0,"id":21483494},{"batb":[[0,5.9,38.11],[1,5.8,22.63],[2,4.9,14.32]],"ltp":3.35,"tv":404.71,"id":21483493}]}]}
{"op":"mcm","clk":"1008426829","pt":1580659997999,"mc":[{"id":"1.168237985","rc":[{"batb":[[0,3.45,16.21],[1,1.01,0.51],[2,3.45,0]],"ltp":4.2,"tv":79.99,"id":16676048},{"batb":[[0,1.92,16.84],[1,1.01,0.51],[2,1.92,0]],"ltp":2.06,"tv":275.02,"id":16676046},{"batb":[[0,7.2,18.11],[1,6.8,13.14],[2,1.01,0.51]],"ltp":0.0,"tv":0.0,"id":21483494},{"batb":[[0,4.9,14.32],[1,1.01,0.51],[2,4.9,0]],"ltp":3.35,"tv":404.71,"id":21483493}]}]}
{"op":"mcm","clk":"1008427462","pt":1580660000839,"mc":[{"id":"1.168237985","rc":[{"batb":[[0,3.6,48.02],[1,3.55,36.15],[2,3.45,16.21]],"ltp":4.2,"tv":79.99,"id":16676048},{"batb":[[1,1.9,80.47],[2,1.88,81.35]],"ltp":2.06,"tv":275.02,"id":16676046},{"batb":[[1,7,30.41],[2,6.8,13.14]],"ltp":0.0,"tv":0.0,"id":21483494},{"batb":[[0,5,39.05],[1,4.9,47.43],[2,1.01,0.51]],"ltp":3.35,"tv":404.71,"id":21483493}]}]}
{"op":"mcm","clk":"1008427673","pt":1580660001731,"mc":[{"id":"1.168237985","rc":[{"batb":[[1,1.01,0.51],[2,1.88,0]],"ltp":2.06,"tv":275.02,"id":16676046}]}]}
{"op":"mcm","clk":"1008428430","pt":1580660005019,"mc":[{"id":"1.168237985","rc":[{"batl":[[0,3.75,15.66],[1,4.1,13.14],[2,4.5,21.4]],"ltp":4.2,"tv":79.99,"id":16676048},{"batb":[[0,2.44,16.6],[1,2.38,78.28],[2,2.34,84.34]],"batl":[[1,3.35,21.87]],"ltp":2.06,"tv":275.02,"id":16676046},{"batl":[[0,8.2,12.43],[1,8.6,11.57],[2,9,10.23]],"ltp":0.0,"tv":0.0,"id":21483494},{"batb":[[2,3.9,24.08]],"batl":[[0,5.6,13.77],[1,6.8,18.33],[2,8.4,11.8]],"ltp":3.35,"tv":404.71,"id":21483493}]}]}
{"op":"mcm","clk":"1008428521","pt":1580660005316,"mc":[{"id":"1.168237985","rc":[{"batl":[[2,4.5,0]],"ltp":4.2,"tv":79.99,"id":16676048},{"batl":[[2,9,0]],"ltp":0.0,"tv":0.0,"id":21483494},{"batl":[[2,8.4,0]],"ltp":3.35,"tv":404.71,"id":21483493}]}]}
{"op":"mcm","clk":"1008430009","pt":1580660011745,"mc":[{"id":"1.168237985","rc":[{"batb":[[1,2.14,23.84],[2,1.01,0.51]],"ltp":2.06,"tv":275.02,"id":16676046},{"trd":[[4.9,21.9],[5,78.1]],"batb":[[0,4.9,36.48],[1,3.9,24.08],[2,1.01,0.51]],"ltp":4.9,"tv":504.71,"id":21483493}],"tv":859.74}]}
{"op":"mcm","clk":"1008430736","pt":1580660014626,"mc":[{"id":"1.168237985","rc":[{"batb":[[1,2.4,42.42],[2,2.36,82.59]],"ltp":2.06,"tv":275.02,"id":16676046},{"batb":[[0,5,31.52],[1,4.9,36.48],[2,3.9,24.08]],"ltp":4.9,"tv":504.71,"id":21483493}]}]}
{"op":"mcm","clk":"1008433147","pt":1580660024978,"mc":[{"id":"1.168237985","rc":[{"batb":[[0,3.1,20.61],[1,1.01,0.51],[2,3.45,0]],"batl":[[0,4.1,13.14],[1,4.1,0]],"ltp":4.2,"tv":79.99,"id":16676048},{"batb":[[0,2.14,23.84],[1,1.01,0.51],[2,2.36,0]],"batl":[[0,3.35,21.87],[1,3.35,0]],"ltp":2.06,"tv":275.02,"id":16676046},{"batb":[[0,6.4,14.95],[1,1.01,0.51],[2,6.8,0]],"batl":[[0,8.6,11.57],[1,8.6,0]],"ltp":0.0,"tv":0.0,"id":21483494},{"batb":[[0,3.9,24.08],[1,1.01,0.51],[2,3.9,0]],"batl":[[0,6.8,18.33],[1,6.8,0]],"ltp":4.9,"tv":504.71,"id":21483493}]}]}
{"op":"mcm","clk":"1008433804","pt":1580660027894,"mc":[{"id":"1.168237985","rc":[{"batb":[[0,3.25,62.9],[1,3.2,46.41],[2,3.1,20.61]],"ltp":4.2,"tv":79.99,"id":16676048},{"batb":[[1,2.12,60.8],[2,2.1,58.04]],"ltp":2.06,"tv":275.02,"id":16676046},{"batb":[[0,6.6,39.57],[1,6.4,51.32],[2,1.01,0.51]],"ltp":0.0,"tv":0.0,"id":21483494},{"batb":[[0,3.95,49.74],[1,3.9,52.36],[2,1.01,0.51]],"ltp":4.9,"tv":504.71,"id":21483493}]}]}
{"op":"mcm","clk":"1008434053","pt":1580660028954,"mc":[{"id":"1.168237985","rc":[{"batb":[[0,3.15,20.54],[1,1.01,0.51],[2,3.1,0]],"ltp":4.2,"tv":79.99,"id":16676048},{"batb":[[0,2.16,23.76],[1,1.01,0.51],[2,2.1,0]],"ltp":2.06,"tv":275.02,"id":16676046},{"batb":[[0,6.6,14.56],[1,1.01,0.51],[2,1.01,0]],"batl":[[0,8.6,11.25]],"ltp":0.0,"tv":0.0,"id":21483494},{"batb":[[0,3.9,24.08],[1,1.01,0.51],[2,1.01,0]],"ltp":4.9,"tv":504.71,"id":21483493}]}]}
{"op":"mcm","clk":"1008434706","pt":1580660031790,"mc":[{"id":"1.168237985","rc":[{"batb":[[0,3.85,44.61],[1,3.8,30.79],[2,3.15,20.54]],"ltp":4.2,"tv":79.99,"id":16676048},{"batb":[[1,2.12,60.8],[2,2.1,58.04]],"ltp":2.06,"tv":275.02,"id":16676046},{"batb":[[0,7.4,37.07],[1,7.2,28.22],[2,6.6,14.56]],"ltp":0.0,"tv":0.0,"id":21483494},{"batb":[[0,5.9,34.66],[1,5.8,22.6],[2,3.9,24.08]],"ltp":4.9,"tv":504.71,"id":21483493}]}]}
{"op":"mcm","clk":"1008434950","pt":1580660032862,"mc":[{"id":"1.168237985","rc":[{"batb":[[2,3.7,13.69]],"batl":[[1,4.4,21.79]],"ltp":4.2,"tv":79.99,"id":16676048},{"batl":[[0,2.28,23.13],[1,2.8,13.53]],"ltp":2.06,"tv":275.02,"id":16676046},{"batb":[[1,7.2,40.1],[2,6.8,13.45]],"batl":[[1,9,10.15]],"ltp":0.0,"tv":0.0,"id":21483494},{"batb":[[2,5.7,19.83]],"batl":[[1,8.2,12.04]],"ltp":4.9,"tv":504.71,"id":21483493}]}]}
{"op":"mcm","clk":"1008439202","pt":1580660050818,"mc":[{"id":"1.168237985","rc":[{"batb":[[0,3.35,17.55],[1,1.01,0.51],[2,3.7,0]],"batl":[[0,4.4,21.79],[1,4.4,0]],"ltp":4.2,"tv":79.99,"id":16676048},{"batb":[[0,1.93,16.52],[1,1.01,0.51],[2,2.1,0]],"batl":[[0,2.8,13.53],[1,2.8,0]],"ltp":2.06,"tv":275.02,"id":16676046},{"batb":[[0,6.8,13.45],[1,1.01,0.51],[2,6.8,0]],"batl":[[0,9,10.15],[1,9,0]],"ltp":0.0,"tv":0.0,"id":21483494},{"batb":[[0,4.5,17.39],[1,1.01,0.51],[2,5.7,0]],"batl":[[0,8.2,12.04],[1,8.2,0]],"ltp":4.9,"tv":504.71,"id":21483493}]}]}
{"op":"mcm","clk":"1008439810","pt":1580660053403,"mc":[{"id":"1.168237985","rc":[{"batb":[[0,3.5,37.26],[1,3.45,38.88],[2,3.35,17.55]],"ltp":4.2,"tv":79.99,"id":16676048},{"batb":[[1,1.92,71.25],[2,1.9,78.7]],"ltp":2.06,"tv":275.02,"id":16676046},{"batb":[[0,7,18.69],[1,6.8,45.75],[2,1.01,0.51]],"ltp":0.0,"tv":0.0,"id":21483494},{"batb":[[0,4.6,35.87],[1,4.5,57.46],[2,1.01,0.51]],"ltp":4.9,"tv":504.71,"id":21483493}]}]}
{"op":"mcm","clk":"1008440240","pt":1580660055332,"mc":[{"id":"1.168237985","rc":[{"batb":[[0,3.35,17.55],[1,1.01,0.51],[2,3.35,0]],"ltp":4.2,"tv":79.99,"id":16676048},{"batb":[[0,6.8,13.45],[1,1.01,0.51],[2,1.01,0]],"ltp":0.0,"tv":0.0,"id":21483494},{"batb":[[0,4.5,17.39],[1,1.01,0.51],[2,1.01,0]],"ltp":4.9,"tv":504.71,"id":21483493}]}]}
{"op":"mcm","clk":"1008441096","pt":1580660058818,"mc":[{"id":"1.168237985","rc":[{"batb":[[0,4.1,50.15],[1,4,76.85],[2,3.65,14.08]],"batl":[[1,4.8,18.57]],"ltp":4.2,"tv":79.99,"id":16676048},{"batl":[[0,2.02,16.29],[1,2.36,21.09],[2,2.8,13.53]],"ltp":2.06,"tv":275.02,"id":16676046},{"batb":[[0,7.8,24.56],[1,7.6,36.02],[2,7,12.43]],"batl":[[1,9.4,9.44]],"ltp":0.0,"tv":0.0,"id":21483494},{"batb":[[0,7,41.71],[1,6.8,43.76],[2,5.4,10.94]],"batl":[[1,10,8.1]],"ltp":4.9,"tv":504.71,"id":21483493}]}]}
{"op":"mcm","clk":"1008441172","pt":1580660059150,"mc":[{"id":"1.168237985","rc":[{"batl":[[2,2.8,0]],"ltp":2.06,"tv":275.02,"id":16676046}]}]}
{"op":"mcm","clk":"1008445637","pt":1580660077927,"mc":[{"id":"1.168237985","rc":[{"batb":[[0,3.65,14.08],[1,1.01,0.51],[2,3.65,0]],"batl":[[0,4.8,18.57],[1,4.8,0]],"ltp":4.2,"tv":79.99,"id":16676048},{"batb":[[0,1.78,21.32],[1,1.01,0.51],[2,1.9,0]],"batl":[[0,2.36,21.09],[1,2.36,0]],"ltp":2.06,"tv":275.02,"id":16676046},{"batb":[[0,7,12.43],[1,1.01,0.51],[2,7,0]],"batl":[[0,9.4,9.44],[1,9.4,0]],"ltp":0.0,"tv":0.0,"id":21483494},{"batb":[[0,5.4,10.94],[1,1.01,0.51],[2,5.4,0]],"batl":[[0,10,8.1],[1,10,0]],"ltp":4.9,"tv":504.71,"id":21483493}]}]}
{"op":"mcm","clk":"1008446147","pt":1580660080160,"mc":[{"id":"1.168237985","rc":[{"batb":[[0,3.8,37.67],[1,3.75,31.86],[2,3.65,14.08]],"ltp":4.2,"tv":79.99,"id":16676048},{"batb":[[0,1.79,87.68],[1,1.78,21.32],[2,1.77,99.08]],"ltp":2.06,"tv":275.02,"id":16676046},{"batb":[[0,7.4,16.22],[1,7.2,28.63],[2,7,12.43]],"ltp":0.0,"tv":0.0,"id":21483494},{"batb":[[0,5.6,40.11],[1,5.5,25.31],[2,5.4,10.94]],"ltp":4.9,"tv":504.71,"id":21483493}]}]}
{"op":"mcm","clk":"1008447555","pt":1580660086370,"mc":[{"id":"1.168237985","rc":[{"batb":[[0,3.65,14.08],[1,1.01,0.51],[2,3.65,0]],"ltp":4.2,"tv":79.99,"id":16676048},{"batb":[[0,7,12.43],[1,1.01,0.51],[2,7,0]],"ltp":0.0,"tv":0.0,"id":21483494},{"batb":[[0,5.4,10.94],[1,1.01,0.51],[2,5.4,0]],"ltp":4.9,"tv":504.71,"id":21483493}]}]}
{"op":"mcm","clk":"1008448377","pt":1580660089735,"mc":[{"id":"1.168237985","rc":[{"batb":[[0,4.3,56.26],[1,4.2,47.99],[2,3.65,14.08]],"ltp":4.2,"tv":79.99,"id":16676048},{"batb":[[0,8.2,12.4],[1,8,22.95],[2,7,12.43]],"ltp":0.0,"tv":0.0,"id":21483494},{"batb":[[0,8.4,20.45],[1,8.2,21.04],[2,5.4,10.94]],"ltp":4.9,"tv":504.71,"id":21483493}]}]}
{"op":"mcm","clk":"1008448674","pt":1580660090974,"mc":[{"id":"1.168237985","rc":[{"batb":[[1,4.2,67.5],[2,4,22.35]],"batl":[[1,4.9,17.07]],"ltp":4.2,"tv":79.99,"id":16676048},{"batl":[[0,1.86,20.93],[1,2,16.52]],"ltp":2.06,"tv":275.02,"id":16676046},{"batb":[[2,7.8,9.91]],"batl":[[1,9.8,8.73]],"ltp":0.0,"tv":0.0,"id":21483494},{"batb":[[1,8.2,29.46],[2,7,12.35]],"batl":[[1,12,14.87]],"ltp":4.9,"tv":504.71,"id":21483493}]}]}
{"op":"mcm","clk":"1008448889","pt":1580660091837,"mc":[{"id":"1.168237985","rc":[{"trd":[[10,5.55]],"batl":[[0,10,5.33]],"ltp":10.0,"tv":510.26,"id":21483493}],"tv":865.28}]}
{"op":"mcm","clk":"1008449938","pt":1580660096140,"mc":[{"id":"1.168237985","rc":[{"batb":[[0,8,22.95],[1,7.8,9.91],[2,7.4,11.09]],"ltp":0.0,"tv":0.0,"id":21483494}]}]}
{"op":"mcm","clk":"1008450608","pt":1580660099164,"mc":[{"id":"1.168237985","rc":[{"batb":[[0,8,35.43],[1,7.8,33.62]],"ltp":0.0,"tv":0.0,"id":21483494}]}]}
{"op":"mcm","clk":"1008455501","pt":1580660119999,"mc":[{"id":"1.168237985","rc":[{"batb":[[0,4,22.35],[1,1.01,0.51],[2,4,0]],"batl":[[0,4.9,17.07],[1,4.9,0]],"ltp":4.2,"tv":79.99,"id":16676048},{"batb":[[0,1.7,24.86],[1,1.01,0.51],[2,1.77,0]],"batl":[[0,2,16.52],[1,2,0]],"ltp":2.06,"tv":275.02,"id":16676046},{"batb":[[0,7.8,18.15],[1,7.4,11.09],[2,1.01,0.51]],"batl":[[0,9.8,8.73],[1,9.8,0]],"ltp":0.0,"tv":0.0,"id":21483494},{"batb":[[0,7,12.12],[1,1.01,0.51],[2,7,0]],"batl":[[0,12,14.56],[1,12,0]],"ltp":10.0,"tv":510.26,"id":21483493}]}]}
{"op":"mcm","clk":"1008456157","pt":1580660122968,"mc":[{"id":"1.168237985","rc":[{"batb":[[0,4.1,69.81],[1,4,75.91],[2,1.01,0.51]],"ltp":4.2,"tv":79.99,"id":16676048},{"batb":[[0,1.73,106.5],[1,1.71,111.45],[2,1.7,24.86]],"ltp":2.06,"tv":275.02,"id":16676046},{"batb":[[1,7.6,25.43],[2,7.4,11.09]],"ltp":0.0,"tv":0.0,"id":21483494},{"batb":[[0,7.2,29.01],[1,7,41.48],[2,1.01,0.51]],"ltp":10.0,"tv":510.26,"id":21483493}]}]}
{"op":"mcm","clk":"1008457031","pt":1580660126894,"mc":[{"id":"1.168237985","rc":[{"batb":[[0,4,22.35],[1,1.01,0.51],[2,1.01,0]],"ltp":4.2,"tv":79.99,"id":16676048},{"batb":[[0,7.4,11.09],[1,1.01,0.51],[2,7.4,0]],"ltp":0.0,"tv":0.0,"id":21483494},{"batb":[[0,7,12.12],[1,1.01,0.51],[2,1.01,0]],"ltp":10.0,"tv":510.26,"id":21483493}]}]}
{"op":"mcm","clk":"1008457658","pt":1580660129623,"mc":[{"id":"1.168237985","rc":[{"batb":[[0,4.4,60.64],[1,4.3,45.39],[2,4,22.35]],"ltp":4.2,"tv":79.99,"id":16676048},{"batb":[[0,8.2,33.4],[1,8,22.47],[2,7.4,11.09]],"ltp":0.0,"tv":0.0,"id":21483494},{"batb":[[0,9.2,19.44],[1,9,17.22],[2,7,12.12]],"ltp":10.0,"tv":510.26,"id":21483493}]}]}
{"op":"mcm","clk":"1008457887","pt":1580660130536,"mc":[{"id":"1.168237985","rc":[{"batb":[[0,4.4,78.58],[2,4.1,21.48]],"batl":[[1,5.5,13.61]],"ltp":4.2,"tv":79.99,"id":16676048},{"batl":[[0,1.77,24.39],[1,1.93,18.57]],"ltp":2.06,"tv":275.02,"id":16676046},{"batb":[[1,8,31.6],[2,7.6,10.54]],"batl":[[1,10.5,7.79]],"ltp":0.0,"tv":0.0,"id":21483494},{"batb":[[0,9.2,35.57],[2,7.6,9.84]],"batl":[[1,17.5,7.16]],"ltp":10.0,"tv":510.26,"id":21483493}]}]}
{"op":"mcm","clk":"1008459753","pt":1580660138769,"mc":[{"id":"1.168237985","rc":[{"batb":[[0,4.4,78.42],[2,4.1,21.17]],"batl":[[0,5,16.92],[1,5.5,13.45]],"ltp":4.2,"tv":79.99,"id":16676048},{"batb":[[1,1.71,135.92],[2,1.56,33.75]],"batl":[[0,1.78,24],[1,1.94,18.25]],"ltp":2.06,"tv":275.02,"id":16676046},{"batb":[[2,7.4,11.02]],"batl":[[0,9.6,9.13]],"ltp":0.0,"tv":0.0,"id":21483494},{"batb":[[0,9.2,19.44],[1,9,34.06]],"batl":[[1,17,7.47]],"ltp":10.0,"tv":510.26,"id":21483493}]}]}
{"op":"mcm","clk":"1008460514","pt":1580660141833,"mc":[{"id":"1.168237985","rc":[{"batl":[[0,12,238.67]],"ltp":10.0,"tv":510.26,"id":21483493}]}]}
{"op":"mcm","clk":"1008461954","pt":1580660147975,"mc":[{"id":"1.168237985","rc":[{"batb":[[1,1.71,135.76],[2,1.56,33.6]],"batl":[[0,1.78,23.84],[1,1.94,18.1]],"ltp":2.06,"tv":275.02,"id":16676046},{"batb":[[1,8,22.47],[2,7.8,9.68]],"batl":[[1,10,8.26]],"ltp":0.0,"tv":0.0,"id":21483494}]}]}
{"op":"mcm","clk":"1008465131","pt":1580660161895,"mc":[{"id":"1.168237985","rc":[{"batb":[[0,8.2,21.77],[1,7.8,9.68],[2,7.4,11.02]],"ltp":0.0,"tv":0.0,"id":21483494}]}]}
{"op":"mcm","clk":"1008465601","pt":1580660164004,"mc":[{"id":"1.168237985","rc":[{"batb":[[1,1.72,24],[2,1.71,135.76]],"batl":[[1,1.79,23.6],[2,1.94,18.1]],"ltp":2.06,"tv":275.02,"id":16676046},{"batl":[[0,9.4,9.44],[1,9.6,9.13],[2,10,8.26]],"ltp":0.0,"tv":0.0,"id":21483494},{"batl":[[0,11.5,15.82],[1,12,238.67],[2,17,7.47]],"ltp":10.0,"tv":510.26,"id":21483493}]}]}
{"op":"mcm","clk":"1008465771","pt":1580660164796,"mc":[{"id":"1.168237985","rc":[{"batb":[[0,4.4,78.19],[2,4.1,20.85]],"batl":[[0,5,16.76]],"ltp":4.2,"tv":79.99,"id":16676048},{"trd":[[1.73,40]],"batb":[[0,1.73,86.5],[2,1.71,111.45]],"batl":[[0,1.79,23.6],[1,1.95,17.94],[2,1.94,0]],"ltp":1.73,"tv":315.02,"id":16676046},{"batb":[[0,8.4,12.17],[1,8.2,21.77],[2,7.8,9.68]],"batl":[[1,10,8.26],[2,10,0]],"ltp":0.0,"tv":0.0,"id":21483494},{"batb":[[1,9,24.22],[2,7.4,10.7]],"batl":[[1,12,224.11]],"ltp":10.0,"tv":510.26,"id":21483493}],"tv":905.28}]}
{"op":"mcm","clk":"1008467238","pt":1580660171032,"mc":[{"id":"1.168237985","rc":[{"batb":[[0,9.2,23.3]],"batl":[[1,17,7.47],[2,17,0]],"ltp":10.0,"tv":510.26,"id":21483493}]}]}
{"op":"mcm","clk":"1008479628","pt":1580660223865,"mc":[{"id":"1.168237985","rc":[{"batb":[[0,4.1,20.85],[1,1.01,0.51],[2,4.1,0]],"batl":[[0,5.5,13.45],[1,5.5,0]],"ltp":4.2,"tv":79.99,"id":16676048},{"batb":[[0,1.57,33.2],[1,1.01,0.51],[2,1.71,0]],"batl":[[0,1.95,17.94],[1,1.95,0]],"ltp":1.73,"tv":315.02,"id":16676046},{"batb":[[0,7.4,11.02],[1,1.01,0.51],[2,7.8,0]],"batl":[[0,10,8.26],[1,10,0]],"ltp":0.0,"tv":0.0,"id":21483494},{"batb":[[0,7.4,10.7],[1,1.01,0.51],[2,7.4,0]],"batl":[[0,17,7.47],[1,17,0]],"ltp":10.0,"tv":510.26,"id":21483493}]}]}
{"op":"mcm","clk":"1008480178","pt":1580660226200,"mc":[{"id":"1.168237985","rc":[{"batb":[[0,4.2,39.72],[1,4.1,71.97],[2,1.01,0.51]],"ltp":4.2,"tv":79.99,"id":16676048},{"batb":[[0,1.59,79.66],[1,1.58,74.57],[2,1.57,33.2]],"ltp":1.73,"tv":315.02,"id":16676046},{"batb":[[0,8,15.76],[1,7.8,24.14],[2,7.4,11.02]],"ltp":0.0,"tv":0.0,"id":21483494},{"batb":[[0,7.6,27],[1,7.4,36.85],[2,1.01,0.51]],"ltp":10.0,"tv":510.26,"id":21483493}]}]}
{"op":"mcm","clk":"1008480424","pt":1580660227185,"mc":[{"id":"1.168237985","rc":[{"batb":[[0,1.57,33.2],[1,1.01,0.51],[2,1.57,0]],"ltp":1.73,"tv":315.02,"id":16676046}]}]}
{"op":"mcm","clk":"1008481323","pt":1580660230978,"mc":[{"id":"1.168237985","rc":[{"batb":[[2,3.9,24.08]],"batl":[[0,4.6,19.83],[1,5.1,16.37],[2,5.5,13.45]],"ltp":4.2,"tv":79.99,"id":16676048},{"batb":[[0,1.87,18.18],[1,1.86,88.72],[2,1.84,87.25]],"batl":[[1,2.14,27.77]],"ltp":1.73,"tv":315.02,"id":16676046},{"batl":[[0,8.8,10.86],[1,9.4,9.44],[2,10,8.26]],"ltp":0.0,"tv":0.0,"id":21483494},{"batb":[[2,6.2,15.74]],"batl":[[0,9,10.15],[1,12,14.63],[2,17,7.47]],"ltp":10.0,"tv":510.26,"id":21483493}]}]}
{"op":"mcm","clk":"1008481382","pt":1580660231289,"mc":[{"id":"1.168237985","rc":[{"batl":[[2,5.5,0]],"ltp":4.2,"tv":79.99,"id":16676048},{"batl":[[2,10,0]],"ltp":0.0,"tv":0.0,"id":21483494},{"batl":[[2,17,0]],"ltp":10.0,"tv":510.26,"id":21483493}]}]}
{"op":"mcm","clk":"1008484719","pt":1580660244997,"mc":[{"id":"1.168237985","rc":[{"batb":[[0,3.9,24.08],[1,1.01,0.51],[2,3.9,0]],"batl":[[0,5.1,16.37],[1,5.1,0]],"ltp":4.2,"tv":79.99,"id":16676048},{"batb":[[0,1.7,24.94],[1,1.01,0.51],[2,1.84,0]],"batl":[[0,2.14,27.77],[1,2.14,0]],"ltp":1.73,"tv":315.02,"id":16676046},{"batb":[[0,7.2,12.12],[1,1.01,0.51],[2,7.4,0]],"batl":[[0,9.4,9.44],[1,9.4,0]],"ltp":0.0,"tv":0.0,"id":21483494},{"batb":[[0,6.2,15.74],[1,1.01,0.51],[2,6.2,0]],"batl":[[0,12,14.63],[1,12,0]],"ltp":10.0,"tv":510.26,"id":21483493}]}]}
{"op":"mcm","clk":"1008485385","pt":1580660247681,"mc":[{"id":"1.168237985","rc":[{"batb":[[0,4,43.6],[1,3.95,28.2],[2,3.9,24.08]],"ltp":4.2,"tv":79.99,"id":16676048},{"batb":[[0,1.71,100.92],[1,1.7,24.94],[2,1.69,116.15]],"ltp":1.73,"tv":315.02,"id":16676046},{"batb":[[0,7.6,28.43],[1,7.4,26.73],[2,7.2,12.12]],"ltp":0.0,"tv":0.0,"id":21483494},{"batb":[[0,6.6,27.92],[1,6.4,35.88],[2,6.2,15.74]],"ltp":10.0,"tv":510.26,"id":21483493}]}]}
{"op":"mcm","clk":"1008485674","pt":1580660248886,"mc":[{"id":"1.168237985","rc":[{"batb":[[0,3.9,24.08],[1,1.01,0.51],[2,3.9,0]],"ltp":4.2,"tv":79.99,"id":16676048},{"batb":[[0,1.7,24.94],[1,1.01,0.51],[2,1.69,0]],"ltp":1.73,"tv":315.02,"id":16676046},{"batb":[[0,7.2,12.12],[1,1.01,0.51],[2,7.2,0]],"ltp":0.0,"tv":0.0,"id":21483494},{"batb":[[0,6.2,15.74],[1,1.01,0.51],[2,6.2,0]],"ltp":10.0,"tv":510.26,"id":21483493}]}]}
{"op":"mcm","clk":"1008486311","pt":1580660251525,"mc":[{"id":"1.168237985","rc":[{"batb":[[0,4.2,66.64],[1,4.1,50.66],[2,3.9,24.08]],"ltp":4.2,"tv":79.99,"id":16676048},{"batb":[[0,1.83,81.69],[1,1.81,92.04],[2,1.7,24.94]],"ltp":1.73,"tv":315.02,"id":16676046},{"batb":[[0,8,25.68],[1,7.8,23.93],[2,7.2,12.12]],"ltp":0.0,"tv":0.0,"id":21483494},{"batb":[[0,8,16.82],[1,7.8,23.56],[2,6.2,15.74]],"ltp":10.0,"tv":510.26,"id":21483493}]}]}
{"op":"mcm","clk":"1008487473","pt":1580660256411,"mc":[{"id":"1.168237985","rc":[{"batb":[[0,3.9,24.08],[1,1.01,0.51],[2,3.9,0]],"ltp":4.2,"tv":79.99,"id":16676048},{"batb":[[0,1.7,24.94],[1,1.01,0.51],[2,1.7,0]],"ltp":1.73,"tv":315.02,"id":16676046},{"batb":[[0,7.2,12.12],[1,1.01,0.51],[2,7.2,0]],"ltp":0.0,"tv":0.0,"id":21483494},{"batb":[[0,6.2,15.74],[1,1.01,0.51],[2,6.2,0]],"ltp":10.0,"tv":510.26,"id":21483493}]}]}
{"op":"mcm","clk":"1008488131","pt":1580660258998,"mc":[{"id":"1.168237985","rc":[{"batb":[[0,4,43.6],[1,3.95,28.2],[2,3.9,24.08]],"ltp":4.2,"tv":79.99,"id":16676048},{"batb":[[0,1.71,100.92],[1,1.7,24.94],[2,1.69,116.15]],"ltp":1.73,"tv":315.02,"id":16676046},{"batb":[[0,7.6,28.43],[1,7.4,26.73],[2,7.2,12.12]],"ltp":0.0,"tv":0.0,"id":21483494},{"batb":[[0,6.6,27.92],[1,6.4,35.88],[2,6.2,15.74]],"ltp":10.0,"tv":510.26,"id":21483493}]}]}
{"op":"mcm","clk":"1008489475","pt":1580660264597,"mc":[{"id":"1.168237985","rc":[{"batb":[[0,3.9,24.08],[1,1.01,0.51],[2,3.9,0]],"ltp":4.2,"tv":79.99,"id":16676048},{"batb":[[0,7.2,12.12],[1,1.01,0.51],[2,7.2,0]],"ltp":0.0,"tv":0.0,"id":21483494},{"batb":[[0,6.2,15.74],[1,1.01,0.51],[2,6.2,0]],"ltp":10.0,"tv":510.26,"id":21483493}]}]}
{"op":"mcm","clk":"1008490173","pt":1580660267558,"mc":[{"id":"1.168237985","rc":[{"batb":[[0,4.5,33.45],[1,4.4,43.53],[2,3.9,24.08]],"ltp":4.2,"tv":79.99,"id":16676048},{"batb":[[0,8.4,20.04],[1,8.2,21.61],[2,7.2,12.12]],"ltp":0.0,"tv":0.0,"id":21483494},{"batb":[[0,9.6,17.7],[1,9.4,15.78],[2,6.2,15.74]],"ltp":10.0,"tv":510.26,"id":21483493}]}]}
{"op":"mcm","clk":"1008490375","pt":1580660268429,"mc":[{"id":"1.168237985","rc":[{"batb":[[0,4.5,50.6],[2,4.1,21.32]],"batl":[[1,5.7,12.59]],"ltp":4.2,"tv":79.99,"id":16676048},{"batl":[[0,1.77,24.39],[1,1.95,17.86]],"ltp":1.73,"tv":315.02,"id":16676046},{"batb":[[2,7.8,9.91]],"batl":[[1,10.5,8.03]],"ltp":0.0,"tv":0.0,"id":21483494},{"batb":[[2,9.2,16.21]],"batl":[[1,19.5,5.82]],"ltp":10.0,"tv":510.26,"id":21483493}]}]}
{"op":"mcm","clk":"1008495488","pt":1580660290028,"mc":[{"id":"1.168237985","rc":[{"batb":[[0,4.5,17.15],[1,4.1,21.32],[2,1.01,0.51]],"ltp":4.2,"tv":79.99,"id":16676048},{"batb":[[0,1.7,24.94],[1,1.52,36.82],[2,1.01,0.51]],"ltp":1.73,"tv":315.02,"id":16676046},{"batb":[[0,7.8,9.91],[1,7.4,10.94],[2,1.01,0.51]],"ltp":0.0,"tv":0.0,"id":21483494},{"batb":[[0,9.2,16.21],[1,7.4,10.86],[2,1.01,0.51]],"ltp":10.0,"tv":510.26,"id":21483493}]}]}
{"op":"mcm","clk":"1008495610","pt":1580660290626,"mc":[{"id":"1.168237985","rc":[{"batb":[[0,4.1,21.32],[1,1.01,0.51],[2,1.01,0]],"batl":[[0,5.7,12.59],[1,5.7,0]],"ltp":4.2,"tv":79.99,"id":16676048},{"batb":[[0,1.52,36.82],[1,1.01,0.51],[2,1.01,0]],"batl":[[0,1.95,17.86],[1,1.95,0]],"ltp":1.73,"tv":315.02,"id":16676046},{"batb":[[0,7.4,10.94],[1,1.01,0.51],[2,1.01,0]],"batl":[[0,10.5,8.03],[1,10.5,0]],"ltp":0.0,"tv":0.0,"id":21483494},{"batb":[[0,7.4,10.86],[1,1.01,0.51],[2,1.01,0]],"batl":[[0,19.5,5.82],[1,19.5,0]],"ltp":10.0,"tv":510.26,"id":21483493}]}]}
{"op":"mcm","clk":"1008496386","pt":1580660293880,"mc":[{"id":"1.168237985","rc":[{"batb":[[0,4.2,31.37],[1,4.1,72.59],[2,1.01,0.51]],"ltp":4.2,"tv":79.99,"id":16676048},{"batb":[[0,1.55,100.53],[1,1.54,82.4],[2,1.52,36.82]],"ltp":1.73,"tv":315.02,"id":16676046},{"batb":[[0,8,17.83],[1,7.8,24.1],[2,7.4,10.94]],"ltp":0.0,"tv":0.0,"id":21483494},{"batb":[[0,7.6,25.84],[1,7.4,37.04],[2,1.01,0.51]],"ltp":10.0,"tv":510.26,"id":21483493}]}]}
{"op":"mcm","clk":"1008496588","pt":1580660294638,"mc":[{"id":"1.168237985","rc":[{"batb":[[0,4.1,21.32],[1,1.01,0.51],[2,1.01,0]],"ltp":4.2,"tv":79.99,"id":16676048},{"batb":[[0,1.52,36.82],[1,1.01,0.51],[2,1.52,0]],"ltp":1.73,"tv":315.02,"id":16676046},{"batb":[[0,7.4,10.94],[1,1.01,0.51],[2,7.4,0]],"ltp":0.0,"tv":0.0,"id":21483494},{"batb":[[0,7.4,10.86],[1,1.01,0.51],[2,1.01,0]],"ltp":10.0,"tv":510.26,"id":21483493}]}]}
{"op":"mcm","clk":"1008497375","pt":1580660297737,"mc":[{"id":"1.168237985","rc":[{"batb":[[0,4.6,27.47],[1,4.5,41.45],[2,4.1,21.32]],"ltp":4.2,"tv":79.99,"id":16676048},{"batb":[[0,1.68,72.68],[1,1.67,60.87],[2,1.52,36.82]],"ltp":1.73,"tv":315.02,"id":16676046},{"batb":[[0,8.4,32.21],[1,8.2,21.36],[2,7.4,10.94]],"ltp":0.0,"tv":0.0,"id":21483494},{"batb":[[0,10,36.55],[1,9.8,14.09],[2,7.4,10.86]],"ltp":10.0,"tv":510.26,"id":21483493}]}]}
{"op":"mcm","clk":"1008498285","pt":1580660301845,"mc":[{"id":"1.168237985","rc":[{"batb":[[0,4.1,21.32],[1,1.01,0.51],[2,4.1,0]],"ltp":4.2,"tv":79.99,"id":16676048},{"batb":[[0,1.52,36.82],[1,1.01,0.51],[2,1.52,0]],"ltp":1.73,"tv":315.02,"id":16676046},{"batb":[[0,7.4,10.94],[1,1.01,0.51],[2,7.4,0]],"ltp":0.0,"tv":0.0,"id":21483494},{"batb":[[0,7.4,10.86],[1,1.01,0.51],[2,7.4,0]],"ltp":10.0,"tv":510.26,"id":21483493}]}]}
{"op":"mcm","clk":"1008498919","pt":1580660304690,"mc":[{"id":"1.168237985","rc":[{"batb":[[0,4.2,31.31],[1,4.1,72.59],[2,1.01,0.51]],"ltp":4.2,"tv":79.99,"id":16676048},{"batb":[[0,1.55,100.28],[1,1.54,82.4],[2,1.52,36.82]],"ltp":1.73,"tv":315.02,"id":16676046},{"batb":[[0,8,17.91],[1,7.8,24.1],[2,7.4,10.94]],"ltp":0.0,"tv":0.0,"id":21483494},{"batb":[[0,7.6,25.93],[1,7.4,37.04],[2,1.01,0.51]],"ltp":10.0,"tv":510.26,"id":21483493}]}]}
{"op":"mcm","clk":"1008502777","pt":1580660321594,"mc":[{"id":"1.168237985","rc":[{"batb":[[0,1.52,36.82],[1,1.01,0.51],[2,1.52,0]],"ltp":1.73,"tv":315.02,"id":16676046}]}]}
{"op":"mcm","clk":"1008503558","pt":1580660325016,"mc":[{"id":"1.168237985","rc":[{"batb":[[0,1.87,57.83],[1,1.85,85.71],[2,1.52,36.82]],"ltp":1.73,"tv":315.02,"id":16676046}]}]}
{"op":"mcm","clk":"1008503783","pt":1580660325985,"mc":[{"id":"1.168237985","rc":[{"batb":[[2,3.85,25.18]],"batl":[[0,4.6,20.22],[1,5.1,16.21]],"ltp":4.2,"tv":79.99,"id":16676048},{"batb":[[0,1.87,76.01],[2,1.68,25.97]],"batl":[[1,2.16,26.59]],"ltp":1.73,"tv":315.02,"id":16676046},{"batl":[[0,9,10.31],[1,9.6,9.13]],"ltp":0.0,"tv":0.0,"id":21483494},{"batb":[[2,6.2,16.37]],"batl":[[0,9,10.23],[1,12.5,13.22]],"ltp":10.0,"tv":510.26,"id":21483493}]}]}
{"op":"mcm","clk":"1008508585","pt":1580660347002,"mc":[{"id":"1.168237985","rc":[{"batb":[[0,7.8,24.1],[1,7.4,10.94],[2,7.2,12.12]],"ltp":0.0,"tv":0.0,"id":21483494},{"batb":[[0,7.6,14.15]],"ltp":10.0,"tv":510.26,"id":21483493}]}]}
{"op":"mcm","clk":"1008509050","pt":1580660348958,"mc":[{"id":"1.168237985","rc":[{"batb":[[0,4.1,21.32],[1,3.85,25.18],[2,1.01,0.51]],"ltp":4.2,"tv":79.99,"id":16676048},{"batb":[[0,1.87,18.18],[1,1.68,25.97],[2,1.01,0.51]],"ltp":1.73,"tv":315.02,"id":16676046},{"batb":[[0,7.4,10.94],[1,7.2,12.12],[2,1.01,0.51]],"ltp":0.0,"tv":0.0,"id":21483494},{"batb":[[0,7.4,10.86],[1,6.2,16.37],[2,1.01,0.51]],"ltp":10.0,"tv":510.26,"id":21483493}]}]}
{"op":"mcm","clk":"1008509321","pt":1580660350034,"mc":[{"id":"1.168237985","rc":[{"batb":[[0,3.85,25.18],[1,1.01,0.51],[2,1.01,0]],"batl":[[0,5.1,16.21],[1,5.1,0]],"ltp":4.2,"tv":79.99,"id":16676048},{"batb":[[0,1.68,25.97],[1,1.01,0.51],[2,1.01,0]],"batl":[[0,2.16,26.59],[1,2.16,0]],"ltp":1.73,"tv":315.02,"id":16676046},{"batb":[[0,7.6,14.85]],"batl":[[0,9.6,9.13],[1,9.6,0]],"ltp":0.0,"tv":0.0,"id":21483494},{"batb":[[0,6.2,16.37],[1,1.01,0.51],[2,1.01,0]],"batl":[[0,12.5,13.22],[1,12.5,0]],"ltp":10.0,"tv":510.26,"id":21483493}]}]}
{"op":"mcm","clk":"1008509742","pt":1580660351849,"mc":[{"id":"1.168237985","rc":[{"batb":[[0,4,26.05],[1,3.95,28.42],[2,3.85,25.18]],"ltp":4.2,"tv":79.99,"id":16676048},{"batb":[[0,1.7,84.4],[1,1.68,144.43],[2,1.01,0.51]],"ltp":1.73,"tv":315.02,"id":16676046},{"batb":[[1,7.4,26.78],[2,7.2,12.12]],"ltp":0.0,"tv":0.0,"id":21483494},{"batb":[[0,6.4,25.14],[1,6.2,54.54],[2,1.01,0.51]],"ltp":10.0,"tv":510.26,"id":21483493}]}]}
{"op":"mcm","clk":"1008510249","pt":1580660353997,"mc":[{"id":"1.168237985","rc":[{"batb":[[0,3.85,25.18],[1,1.01,0.51],[2,3.85,0]],"ltp":4.2,"tv":79.99,"id":16676048},{"batb":[[0,1.68,25.97],[1,1.01,0.51],[2,1.01,0]],"ltp":1.73,"tv":315.02,"id":16676046},{"batb":[[0,7.2,12.12],[1,1.01,0.51],[2,7.2,0]],"ltp":0.0,"tv":0.0,"id":21483494},{"batb":[[0,6.2,16.37],[1,1.01,0.51],[2,1.01,0]],"ltp":10.0,"tv":510.26,"id":21483493}]}]}
{"op":"mcm","clk":"1008510724","pt":1580660356009,"mc":[{"id":"1.168237985","rc":[{"batb":[[0,4.2,70.67],[1,4.1,50.75],[2,3.85,25.18]],"ltp":4.2,"tv":79.99,"id":16676048},{"batb":[[0,1.84,56.91],[1,1.82,90.32],[2,1.68,25.97]],"ltp":1.73,"tv":315.02,"id":16676046},{"batb":[[0,8,17.75],[1,7.8,23.86],[2,7.2,12.12]],"ltp":0.0,"tv":0.0,"id":21483494},{"batb":[[0,7.8,34.23],[1,7.6,24.26],[2,6.2,16.37]],"ltp":10.0,"tv":510.26,"id":21483493}]}]}
{"op":"mcm","clk":"1008512077","pt":1580660361851,"mc":[{"id":"1.168237985","rc":[{"batb":[[0,3.85,25.18],[1,1.01,0.51],[2,3.85,0]],"ltp":4.2,"tv":79.99,"id":16676048},{"batb":[[0,1.68,25.97],[1,1.01,0.51],[2,1.68,0]],"ltp":1.73,"tv":315.02,"id":16676046},{"batb":[[0,7.2,12.12],[1,1.01,0.51],[2,7.2,0]],"ltp":0.0,"tv":0.0,"id":21483494},{"batb":[[0,6.2,16.37],[1,1.01,0.51],[2,6.2,0]],"ltp":10.0,"tv":510.26,"id":21483493}]}]}
{"op":"mcm","clk":"1008512726","pt":1580660364974,"mc":[{"id":"1.168237985","rc":[{"batb":[[0,4,26.05],[1,3.95,28.42],[2,3.85,25.18]],"ltp":4.2,"tv":79.99,"id":16676048},{"batb":[[0,1.7,84.4],[1,1.68,144.43],[2,1.01,0.51]],"ltp":1.73,"tv":315.02,"id":16676046},{"batb":[[0,7.6,14.85],[1,7.4,26.78],[2,7.2,12.12]],"ltp":0.0,"tv":0.0,"id":21483494},{"batb":[[0,6.4,25.14],[1,6.2,54.54],[2,1.01,0.51]],"ltp":10.0,"tv":510.26,"id":21483493}]}]}
{"op":"mcm","clk":"1008513879","pt":1580660369934,"mc":[{"id":"1.168237985","rc":[{"batb":[[0,3.85,25.18],[1,1.01,0.51],[2,3.85,0]],"ltp":4.2,"tv":79.99,"id":16676048},{"batb":[[0,7.2,12.12],[1,1.01,0.51],[2,7.2,0]],"ltp":0.0,"tv":0.0,"id":21483494},{"batb":[[0,6.2,16.37],[1,1.01,0.51],[2,1.01,0]],"ltp":10.0,"tv":510.26,"id":21483493}]}]}
{"op":"mcm","clk":"1008514500","pt":1580660372665,"mc":[{"id":"1.168237985","rc":[{"batb":[[0,4.5,54.17],[1,4.4,43.33],[2,3.85,25.18]],"ltp":4.2,"tv":79.99,"id":16676048},{"batb":[[0,8.4,16.57],[1,8.2,21.47],[2,7.2,12.12]],"ltp":0.0,"tv":0.0,"id":21483494},{"batb":[[0,9.8,20.96],[1,9.6,14.86],[2,6.2,16.37]],"ltp":10.0,"tv":510.26,"id":21483493}]}]}
{"op":"mcm","clk":"1008514705","pt":1580660373560,"mc":[{"id":"1.168237985","rc":[{"batb":[[0,4.5,71.17],[2,4,22.19]],"batl":[[1,6,11.41]],"ltp":4.2,"tv":79.99,"id":16676048},{"batb":[[2,1.48,41.94]],"batl":[[0,1.75,25.41],[1,1.99,17]],"ltp":1.73,"tv":315.02,"id":16676046},{"batb":[[2,8,9.6]],"batl":[[1,10.5,7.87]],"ltp":0.0,"tv":0.0,"id":21483494},{"batb":[[1,9.6,29.42],[2,7.2,11.49]],"batl":[[1,26,7.08]],"ltp":10.0,"tv":510.26,"id":21483493}]}]}
{"op":"mcm","clk":"1008519851","pt":1580660395903,"mc":[{"id":"1.168237985","rc":[{"batb":[[0,4,22.19],[1,1.01,0.51],[2,4,0]],"batl":[[0,6,11.41],[1,6,0]],"ltp":4.2,"tv":79.99,"id":16676048},{"batb":[[0,1.48,41.94],[1,1.01,0.51],[2,1.48,0]],"batl":[[0,1.99,17],[1,1.99,0]],"ltp":1.73,"tv":315.02,"id":16676046},{"batb":[[0,7.4,11.17],[1,1.01,0.51],[2,8,0]],"batl":[[0,10.5,7.87],[1,10.5,0]],"ltp":0.0,"tv":0.0,"id":21483494},{"batb":[[0,7.2,11.49],[1,1.01,0.51],[2,7.2,0]],"batl":[[0,26,7.08],[1,26,0]],"ltp":10.0,"tv":510.26,"id":21483493}]}]}
{"op":"mcm","clk":"1008520574","pt":1580660398889,"mc":[{"id":"1.168237985","rc":[{"batb":[[0,4.1,61.35],[1,4,76.12],[2,1.01,0.51]],"ltp":4.2,"tv":79.99,"id":16676048},{"batb":[[0,1.5,87.72],[1,1.49,93.92],[2,1.48,41.94]],"batl":[[1,2,16.76]],"ltp":1.73,"tv":315.02,"id":16676046},{"batb":[[0,7.8,28.11],[1,7.6,24.99],[2,7.4,11.17]],"batl":[[0,10,8.18],[1,10.5,7.87]],"ltp":0.0,"tv":0.0,"id":21483494},{"batb":[[0,7.2,48.89],[1,7,40.84],[2,1.01,0.51]],"ltp":10.0,"tv":510.26,"id":21483493}]}]}
{"op":"mcm","clk":"1008520797","pt":1580660399902,"mc":[{"id":"1.168237985","rc":[{"batb":[[1,4,75.8]],"ltp":4.2,"tv":79.99,"id":16676048},{"batb":[[2,1.48,41.31]],"batl":[[0,2,16.76],[1,2,0]],"ltp":1.73,"tv":315.02,"id":16676046},{"batb":[[2,7.2,11.57]],"batl":[[1,10.5,0]],"ltp":0.0,"tv":0.0,"id":21483494},{"batb":[[0,7.2,37.4]],"ltp":10.0,"tv":510.26,"id":21483493}]}]}
{"op":"mcm","clk":"1008521022","pt":1580660400795,"mc":[{"id":"1.168237985","rc":[{"batb":[[0,4,21.87],[1,1.01,0.51],[2,1.01,0]],"ltp":4.2,"tv":79.99,"id":16676048},{"batb":[[0,1.48,41.31],[1,1.01,0.51],[2,1.48,0]],"ltp":1.73,"tv":315.02,"id":16676046},{"batb":[[0,7.2,11.57],[1,1.01,0.51],[2,7.2,0]],"ltp":0.0,"tv":0.0,"id":21483494},{"batb":[[0,7,11.88],[1,1.01,0.51],[2,1.01,0]],"ltp":10.0,"tv":510.26,"id":21483493}]}]}
{"op":"mcm","clk":"1008521840","pt":1580660403912,"mc":[{"id":"1.168237985","rc":[{"batb":[[0,4.6,58.6],[1,4.5,41.08],[2,4,21.87]],"ltp":4.2,"tv":79.99,"id":16676048},{"batb":[[0,1.65,63.47],[1,1.48,41.31],[2,1.01,0.51]],"ltp":1.73,"tv":315.02,"id":16676046},{"batb":[[0,8.4,31.21],[1,8.2,21.16],[2,7.2,11.57]],"ltp":0.0,"tv":0.0,"id":21483494},{"batb":[[0,10.5,35.65],[1,10,30.04],[2,7,11.88]],"ltp":10.0,"tv":510.26,"id":21483493}]}]}
{"op":"mcm","clk":"1008522532","pt":1580660406937,"mc":[{"id":"1.168237985","rc":[{"batb":[[0,1.66,63.38],[1,1.65,63.47],[2,1.48,41.31]],"ltp":1.73,"tv":315.02,"id":16676046}]}]}
{"op":"mcm","clk":"1008523431","pt":1580660410428,"mc":[{"id":"1.168237985","rc":[{"batb":[[0,4,21.87],[1,1.01,0.51],[2,4,0]],"ltp":4.2,"tv":79.99,"id":16676048},{"batb":[[0,1.48,41.31],[1,1.01,0.51],[2,1.48,0]],"ltp":1.73,"tv":315.02,"id":16676046},{"batb":[[0,7.2,11.57],[1,1.01,0.51],[2,7.2,0]],"ltp":0.0,"tv":0.0,"id":21483494},{"batb":[[0,7,11.88],[1,1.01,0.51],[2,7,0]],"ltp":10.0,"tv":510.26,"id":21483493}]}]}
{"op":"mcm","clk":"1008524084","pt":1580660413033,"mc":[{"id":"1.168237985","rc":[{"batb":[[0,4.1,62.65],[1,4,75.79],[2,1.01,0.51]],"ltp":4.2,"tv":79.99,"id":16676048},{"batb":[[0,1.5,92.69],[1,1.49,93.93],[2,1.48,41.31]],"ltp":1.73,"tv":315.02,"id":16676046},{"batb":[[0,7.8,26.39],[1,7.6,24.99],[2,7.2,11.57]],"ltp":0.0,"tv":0.0,"id":21483494},{"batb":[[0,7.2,35.51],[1,7,40.83],[2,1.01,0.51]],"ltp":10.0,"tv":510.26,"id":21483493}]}]}
{"op":"mcm","clk":"1008524409","pt":1580660414199,"mc":[{"id":"1.168237985","rc":[{"batb":[[0,4,21.87],[1,1.01,0.51],[2,1.01,0]],"ltp":4.2,"tv":79.99,"id":16676048},{"batb":[[0,7.2,11.57],[1,1.01,0.51],[2,7.2,0]],"ltp":0.0,"tv":0.0,"id":21483494},{"batb":[[0,7,11.88],[1,1.01,0.51],[2,1.01,0]],"ltp":10.0,"tv":510.26,"id":21483493}]}]}
{"op":"mcm","clk":"1008525088","pt":1580660417026,"mc":[{"id":"1.168237985","rc":[{"batb":[[0,5.2,28.16],[1,5.1,31.34],[2,4,21.87]],"ltp":4.2,"tv":79.99,"id":16676048},{"batb":[[0,9,28.33],[1,8.8,18.22],[2,7.2,11.57]],"ltp":0.0,"tv":0.0,"id":21483494},{"batb":[[0,18,6.1],[1,17.5,10.59],[2,7,11.88]],"ltp":10.0,"tv":510.26,"id":21483493}]}]}
{"op":"mcm","clk":"1008525251","pt":1580660417687,"mc":[{"id":"1.168237985","rc":[{"batb":[[0,5.3,11.8],[1,5.2,28.16],[2,5.1,31.34]],"batl":[[1,7.6,14.16]],"ltp":4.2,"tv":79.99,"id":16676048},{"batl":[[0,1.54,40.29],[1,1.75,25.49]],"ltp":1.73,"tv":315.02,"id":16676046},{"batb":[[2,8.4,8.58]],"batl":[[1,11.5,16.84]],"ltp":0.0,"tv":0.0,"id":21483494},{"batb":[[2,16.5,8.1]],"ltp":10.0,"tv":510.26,"id":21483493}]}]}
{"op":"mcm","clk":"1008530000","pt":1580660437887,"mc":[{"id":"1.168237985","rc":[{"batb":[[1,4.5,16.52],[2,1.01,0.51]],"ltp":4.2,"tv":79.99,"id":16676048},{"batb":[[0,1.48,41.31],[1,1.3,74.2],[2,1.01,0.51]],"ltp":1.73,"tv":315.02,"id":16676046},{"batb":[[0,8.4,8.58],[1,7.8,9.76],[2,1.01,0.51]],"ltp":0.0,"tv":0.0,"id":21483494},{"batb":[[0,16.5,8.1],[1,9.6,14.95],[2,1.01,0.51]],"ltp":10.0,"tv":510.26,"id":21483493}]}]}
{"op":"mcm","clk":"1008530250","pt":1580660439019,"mc":[{"id":"1.168237985","rc":[{"batb":[[0,4.5,16.52],[1,1.01,0.51],[2,1.01,0]],"batl":[[0,7.6,14.16],[1,7.6,0]],"ltp":4.2,"tv":79.99,"id":16676048},{"batb":[[0,1.3,74.2],[1,1.01,0.51],[2,1.01,0]],"batl":[[0,1.75,25.49],[1,1.75,0]],"ltp":1.73,"tv":315.02,"id":16676046},{"batb":[[0,7.8,9.76],[1,1.01,0.51],[2,1.01,0]],"batl":[[0,11.5,16.84],[1,11.5,0]],"ltp":0.0,"tv":0.0,"id":21483494},{"batb":[[0,9.6,14.95],[1,1.01,0.51],[2,1.01,0]],"ltp":10.0,"tv":510.26,"id":21483493}]}]}
{"op":"mcm","clk":"1008531364","pt":1580660443887,"mc":[{"id":"1.168237985","rc":[{"batb":[[0,5.4,23.35],[1,5.3,28.83],[2,4.5,16.52]],"ltp":4.2,"tv":79.99,"id":16676048},{"batb":[[0,1.46,78.86],[1,1.45,105.2],[2,1.3,74.2]],"ltp":1.73,"tv":315.02,"id":16676046},{"batb":[[0,9.2,27.17],[1,9,17.39],[2,7.8,9.76]],"ltp":0.0,"tv":0.0,"id":21483494},{"batb":[[0,22,11.32],[1,21,13.99],[2,9.6,14.95]],"ltp":10.0,"tv":510.26,"id":21483493}]}]}
{"op":"mcm","clk":"1008532528","pt":1580660448905,"mc":[{"id":"1.168237985","rc":[{"batb":[[0,4.5,16.52],[1,1.01,0.51],[2,4.5,0]],"ltp":4.2,"tv":79.99,"id":16676048},{"batb":[[0,1.3,74.2],[1,1.01,0.51],[2,1.3,0]],"ltp":1.73,"tv":315.02,"id":16676046},{"batb":[[0,7.8,9.76],[1,1.01,0.51],[2,7.8,0]],"ltp":0.0,"tv":0.0,"id":21483494},{"batb":[[0,9.6,14.95],[1,1.01,0.51],[2,9.6,0]],"ltp":10.0,"tv":510.26,"id":21483493}]}]}
{"op":"mcm","clk":"1008533169","pt":1580660451805,"mc":[{"id":"1.168237985","rc":[{"batb":[[0,4.5,77.01],[1,4.4,43.24],[2,1.01,0.51]],"ltp":4.2,"tv":79.99,"id":16676048},{"batb":[[0,1.31,154.54],[1,1.3,251.77],[2,1.01,0.51]],"ltp":1.73,"tv":315.02,"id":16676046},{"batb":[[0,8.4,19.76],[1,8.2,21.36],[2,7.8,9.76]],"ltp":0.0,"tv":0.0,"id":21483494},{"batb":[[0,10,12.26],[1,9.8,14.36],[2,9.6,14.95]],"ltp":10.0,"tv":510.26,"id":21483493}]}]}
{"op":"mcm","clk":"1008535146","pt":1580660460862,"mc":[{"id":"1.168237985","rc":[{"batb":[[0,4.5,16.52],[1,1.01,0.51],[2,1.01,0]],"ltp":4.2,"tv":79.99,"id":16676048},{"batb":[[0,7.8,9.76],[1,1.01,0.51],[2,7.8,0]],"ltp":0.0,"tv":0.0,"id":21483494},{"batb":[[0,9.6,14.95],[1,1.01,0.51],[2,9.6,0]],"ltp":10.0,"tv":510.26,"id":21483493}]}]}
{"op":"mcm","clk":"1008535680","pt":1580660463045,"mc":[{"id":"1.168237985","rc":[{"batb":[[0,6.2,42.89],[1,6,42.58],[2,4.5,16.52]],"ltp":4.2,"tv":79.99,"id":16676048},{"batb":[[0,10,29.51],[1,9.8,14.46],[2,7.8,9.76]],"ltp":0.0,"tv":0.0,"id":21483494}]}]}
{"op":"mcm","clk":"1008535884","pt":1580660463963,"mc":[{"id":"1.168237985","rc":[{"batb":[[0,6.4,15.03],[1,6.2,42.89],[2,6,42.58]],"batl":[[1,8.4,11.09]],"ltp":4.2,"tv":79.99,"id":16676048},{"batb":[[2,1.26,88.99]],"batl":[[0,1.35,71.44],[1,1.43,53.66]],"ltp":1.73,"tv":315.02,"id":16676046},{"batb":[[2,9,7]],"batl":[[1,13,13.06]],"ltp":0.0,"tv":0.0,"id":21483494},{"batb":[[0,1.01,0.51],[1,1.01,0]],"ltp":10.0,"tv":510.26,"id":21483493}]}]}
{"op":"mcm","clk":"1008539290","pt":1580660478673,"mc":[{"id":"1.168237985","rc":[{"batl":[[0,11.5,15.74],[1,13,12.59]],"ltp":0.0,"tv":0.0,"id":21483494}]}]}
{"op":"mcm","clk":"1008552205","pt":1580660534734,"mc":[{"id":"1.168237985","rc":[{"batb":[[0,10,34.2]],"ltp":0.0,"tv":0.0,"id":21483494}]}]}
{"op":"mcm","clk":"1008585821","pt":1580660685248,"mc":[{"id":"1.168237985","rc":[{"batb":[[0,1.31,119.63]],"ltp":1.73,"tv":315.02,"id":16676046}]}]}
{"op":"mcm","clk":"1008586582","pt":1580660688974,"mc":[{"id":"1.168237985","rc":[{"batb":[[0,10,41.57]],"ltp":0.0,"tv":0.0,"id":21483494}]}]}
{"op":"mcm","clk":"1008596451","pt":1580660735025,"mc":[{"id":"1.168237985","rc":[{"batb":[[0,10,35.18],[1,9,7],[2,7.8,9.76]],"ltp":0.0,"tv":0.0,"id":21483494}]}]}
{"op":"mcm","clk":"1008597045","pt":1580660737928,"mc":[{"id":"1.168237985","rc":[{"batb":[[0,10.5,12.81],[1,10,35.18],[2,9,7]],"ltp":0.0,"tv":0.0,"id":21483494}]}]}
{"op":"mcm","clk":"1008599300","pt":1580660748388,"mc":[{"id":"1.168237985","rc":[{"batb":[[0,1.31,78.01]],"ltp":1.73,"tv":315.02,"id":16676046}]}]}
{"op":"mcm","clk":"1008599989","pt":1580660751861,"mc":[{"id":"1.168237985","rc":[{"batb":[[1,5.5,10.78],[2,1.01,0.51]],"ltp":4.2,"tv":79.99,"id":16676048},{"batb":[[0,1.3,74.2],[1,1.26,88.99],[2,1.01,0.51]],"ltp":1.73,"tv":315.02,"id":16676046},{"batb":[[0,9,7],[1,7.8,9.76],[2,1.01,0.51]],"ltp":0.0,"tv":0.0,"id":21483494}]}]}
{"op":"mcm","clk":"1008600028","pt":1580660752086,"mc":[{"id":"1.168237985","rc":[{"batb":[[0,5.5,10.78],[1,1.01,0.51],[2,1.01,0]],"batl":[[0,8.4,11.09],[1,8.4,0]],"ltp":4.2,"tv":79.99,"id":16676048},{"batb":[[0,1.26,88.99],[1,1.01,0.51],[2,1.01,0]],"batl":[[0,1.43,53.66],[1,1.43,0]],"ltp":1.73,"tv":315.02,"id":16676046},{"batb":[[0,7.8,9.76],[1,1.01,0.51],[2,1.01,0]],"batl":[[0,13,12.59],[1,13,0]],"ltp":0.0,"tv":0.0,"id":21483494}]}]}
{"op":"mcm","clk":"1008600531","pt":1580660754673,"mc":[{"id":"1.168237985","rc":[{"batb":[[1,5.3,34.13],[2,5.2,29.91]],"ltp":4.2,"tv":79.99,"id":16676048},{"batb":[[0,1.26,381.61],[1,1.25,228.79],[2,1.01,0.51]],"ltp":1.73,"tv":315.02,"id":16676046},{"batb":[[0,8.8,28.79],[1,8.6,19.82],[2,7.8,9.76]],"ltp":0.0,"tv":0.0,"id":21483494}]}]}
{"op":"mcm","clk":"1008602733","pt":1580660765501,"mc":[{"id":"1.168237985","rc":[{"batb":[[1,1.01,0.51],[2,5.2,0]],"ltp":4.2,"tv":79.99,"id":16676048},{"batb":[[0,7.8,9.76],[1,1.01,0.51],[2,7.8,0]],"ltp":0.0,"tv":0.0,"id":21483494},{"batb":[[0,10,14.28],[1,1.01,0.51]],"ltp":10.0,"tv":510.26,"id":21483493}]}]}
{"op":"mcm","clk":"1008603471","pt":1580660768877,"mc":[{"id":"1.168237985","rc":[{"batb":[[0,7,26.6],[1,6.8,32.91],[2,6,16.6]],"batl":[[1,9.4,9.05]],"ltp":4.2,"tv":79.99,"id":16676048},{"batb":[[2,1.22,105.12]],"batl":[[0,1.3,86],[1,1.37,67.12],[2,1.43,53.66]],"ltp":1.73,"tv":315.02,"id":16676046},{"batb":[[0,11.5,29.34],[1,11,28.42],[2,10,13.77]],"batl":[[1,14.5,10.15]],"ltp":0.0,"tv":0.0,"id":21483494}]}]}
{"op":"mcm","clk":"1008603563","pt":1580660769295,"mc":[{"id":"1.168237985","rc":[{"batl":[[2,1.43,0]],"ltp":1.73,"tv":315.02,"id":16676046}]}]}
{"op":"mcm","clk":"1008605805","pt":1580660779787,"mc":[{"id":"1.168237985","rc":[{"batb":[[0,7,11.8]],"ltp":4.2,"tv":79.99,"id":16676048}]}]}
{"op":"mcm","clk":"1008606353","pt":1580660782406,"mc":[{"id":"1.168237985","rc":[{"batb":[[1,6.8,47.65],[2,6.6,34.26]],"ltp":4.2,"tv":79.99,"id":16676048},{"batb":[[0,11.5,32.66]],"ltp":0.0,"tv":0.0,"id":21483494}]}]}
{"op":"mcm","clk":"1008607035","pt":1580660785626,"mc":[{"id":"1.168237985","rc":[{"batb":[[0,6,16.6],[1,1.01,0.51],[2,6.6,0]],"batl":[[0,9.4,9.05],[1,9.4,0]],"ltp":4.2,"tv":79.99,"id":16676048},{"batb":[[0,1.22,105.12],[1,1.01,0.51],[2,1.22,0]],"batl":[[0,1.37,67.12],[1,1.37,0]],"ltp":1.73,"tv":315.02,"id":16676046},{"batb":[[0,8.8,7.47],[1,1.01,0.51],[2,10,0]],"batl":[[0,14.5,10.15],[1,14.5,0]],"ltp":0.0,"tv":0.0,"id":21483494}]}]}
{"op":"mcm","clk":"1008608139","pt":1580660790813,"mc":[{"id":"1.168237985","rc":[{"batb":[[0,6.6,47.69],[1,6.4,36.64],[2,6,16.6]],"ltp":4.2,"tv":79.99,"id":16676048},{"batb":[[0,1.28,95.11],[1,1.27,204.31],[2,1.22,105.12]],"ltp":1.73,"tv":315.02,"id":16676046},{"batb":[[0,11.5,11.32],[1,11,29.27],[2,8.8,7.47]],"ltp":0.0,"tv":0.0,"id":21483494}]}]}
{"op":"mcm","clk":"1008608440","pt":1580660792219,"mc":[{"id":"1.168237985","rc":[{"batb":[[0,1.01,0.51],[1,1.01,0]],"ltp":10.0,"tv":510.26,"id":21483493}]}]}
{"op":"mcm","clk":"1008608823","pt":1580660793924,"mc":[{"id":"1.168237985","rc":[{"batb":[[0,6,16.6],[1,1.01,0.51],[2,6,0]],"ltp":4.2,"tv":79.99,"id":16676048},{"batb":[[0,1.22,105.12],[1,1.01,0.51],[2,1.22,0]],"ltp":1.73,"tv":315.02,"id":16676046},{"batb":[[0,8.8,7.47],[1,1.01,0.51],[2,8.8,0]],"ltp":0.0,"tv":0.0,"id":21483494}]}]}
{"op":"mcm","clk":"1008609360","pt":1580660796724,"mc":[{"id":"1.168237985","rc":[{"batb":[[0,6,46.87],[1,5.9,22.56],[2,1.01,0.51]],"ltp":4.2,"tv":79.99,"id":16676048},{"batb":[[0,1.24,99.09],[1,1.23,248.17],[2,1.22,105.12]],"ltp":1.73,"tv":315.02,"id":16676046},{"batb":[[0,10,27.05],[1,9.8,15.06],[2,8.8,7.47]],"ltp":0.0,"tv":0.0,"id":21483494}]}]}
{"op":"mcm","clk":"1008610199","pt":1580660800826,"mc":[{"id":"1.168237985","rc":[{"batb":[[0,6,16.6],[1,1.01,0.51],[2,1.01,0]],"ltp":4.2,"tv":79.99,"id":16676048},{"batb":[[0,8.8,7.47],[1,1.01,0.51],[2,8.8,0]],"ltp":0.0,"tv":0.0,"id":21483494}]}]}
{"op":"mcm","clk":"1008610887","pt":1580660803966,"mc":[{"id":"1.168237985","rc":[{"batb":[[0,7.8,9.52],[1,7.6,17.08],[2,7.4,27.33]],"batl":[[1,10.5,7.71]],"ltp":4.2,"tv":79.99,"id":16676048},{"batl":[[0,1.27,100.08],[1,1.31,82.62],[2,1.37,67.12]],"ltp":1.73,"tv":315.02,"id":16676046},{"batb":[[0,13,12.13],[1,12.5,22.42],[2,11,11.02]],"batl":[[1,16,8.42]],"ltp":0.0,"tv":0.0,"id":21483494}]}]}
{"op":"mcm","clk":"1008611051","pt":1580660804735,"mc":[{"id":"1.168237985","rc":[{"batl":[[2,1.37,0]],"ltp":1.73,"tv":315.02,"id":16676046}]}]}
{"op":"mcm","clk":"1008614993","pt":1580660823030,"mc":[{"id":"1.168237985","rc":[{"batb":[[1,6.8,12.43],[2,1.01,0.51]],"ltp":4.2,"tv":79.99,"id":16676048},{"batb":[[0,1.22,105.12],[1,1.2,118.89],[2,1.01,0.51]],"ltp":1.73,"tv":315.02,"id":16676046},{"batb":[[0,11,11.02],[1,9.8,14.63],[2,1.01,0.51]],"ltp":0.0,"tv":0.0,"id":21483494}]}]}
{"op":"mcm","clk":"1008615051","pt":1580660823349,"mc":[{"id":"1.168237985","rc":[{"batb":[[0,6.8,12.43],[1,1.01,0.51],[2,1.01,0]],"batl":[[0,10.5,7.71],[1,10.5,0]],"ltp":4.2,"tv":79.99,"id":16676048},{"batb":[[0,1.2,118.89],[1,1.01,0.51],[2,1.01,0]],"batl":[[0,1.31,82.62],[1,1.31,0]],"ltp":1.73,"tv":315.02,"id":16676046},{"batb":[[0,9.8,14.63],[1,1.01,0.51],[2,1.01,0]],"batl":[[0,16,8.42],[1,16,0]],"ltp":0.0,"tv":0.0,"id":21483494}]}]}
{"op":"mcm","clk":"1008615576","pt":1580660825951,"mc":[{"id":"1.168237985","rc":[{"batb":[[0,6.8,42.46],[1,6.6,34.69],[2,1.01,0.51]],"ltp":4.2,"tv":79.99,"id":16676048},{"trd":[[1.22,20]],"batb":[[0,1.22,146.72],[1,1.21,278.13],[2,1.2,118.89]],"ltp":1.22,"tv":335.02,"id":16676046},{"batb":[[0,11.5,15.39],[1,11,29.05],[2,9.8,14.63]],"ltp":0.0,"tv":0.0,"id":21483494}],"tv":925.28}]}
{"op":"mcm","clk":"1008615756","pt":1580660826767,"mc":[{"id":"1.168237985","rc":[{"batb":[[0,6.8,12.43],[1,1.01,0.51],[2,1.01,0]],"ltp":4.2,"tv":79.99,"id":16676048},{"batb":[[0,9.8,14.63],[1,1.01,0.51],[2,9.8,0]],"ltp":0.0,"tv":0.0,"id":21483494}]}]}
{"op":"mcm","clk":"1008616455","pt":1580660829656,"mc":[{"id":"1.168237985","rc":[{"batb":[[0,8,23.99],[1,7.8,24.26],[2,6.8,12.43]],"ltp":4.2,"tv":79.99,"id":16676048},{"batb":[[0,14,7.7],[1,13.5,19.24],[2,9.8,14.63]],"ltp":0.0,"tv":0.0,"id":21483494}]}]}
{"op":"mcm","clk":"1008616644","pt":1580660830564,"mc":[{"id":"1.168237985","rc":[{"batb":[[0,8.4,8.1],[1,8,23.99],[2,7.8,33.86]],"batl":[[1,11,7.08]],"ltp":4.2,"tv":79.99,"id":16676048},{"batl":[[0,1.24,112.67],[1,1.27,98.82]],"ltp":1.22,"tv":335.02,"id":16676046},{"batb":[[2,12,9.05]],"batl":[[1,17.5,7.32]],"ltp":0.0,"tv":0.0,"id":21483494}]}]}
{"op":"mcm","clk":"1008619929","pt":1580660845905,"mc":[{"id":"1.168237985","rc":[{"batb":[[0,7.8,9.6],[1,1.01,0.51],[2,7.8,0]],"batl":[[0,11,7.08],[1,11,0]],"ltp":4.2,"tv":79.99,"id":16676048},{"batb":[[0,1.21,178.1],[1,1.19,128.49],[2,1.01,0.51]],"batl":[[0,1.27,98.82],[1,1.27,0]],"ltp":1.22,"tv":335.02,"id":16676046},{"batb":[[0,11,11.33],[1,1.01,0.51],[2,12,0]],"batl":[[0,17.5,7.32],[1,17.5,0]],"ltp":0.0,"tv":0.0,"id":21483494}]}]}
{"op":"mcm","clk":"1008620468","pt":1580660848467,"mc":[{"id":"1.168237985","rc":[{"batb":[[1,7.6,21.25],[2,7.4,27.24]],"ltp":4.2,"tv":79.99,"id":16676048},{"batb":[[1,1.2,295.43],[2,1.19,128.49]],"ltp":1.22,"tv":335.02,"id":16676046},{"batb":[[0,12.5,29.4],[1,12,23.7],[2,11,11.33]],"ltp":0.0,"tv":0.0,"id":21483494}]}]}
{"op":"mcm","clk":"1008622795","pt":1580660858788,"mc":[{"id":"1.168237985","rc":[{"batb":[[1,1.01,0.51],[2,7.4,0]],"ltp":4.2,"tv":79.99,"id":16676048},{"batb":[[0,11,11.33],[1,1.01,0.51],[2,11,0]],"ltp":0.0,"tv":0.0,"id":21483494}]}]}
{"op":"mcm","clk":"1008623481","pt":1580660862033,"mc":[{"id":"1.168237985","rc":[{"batb":[[0,8.6,7.32],[1,8.2,28.54],[2,8,22.87]],"batl":[[1,14,10.86]],"ltp":4.2,"tv":79.99,"id":16676048},{"batl":[[0,1.23,121.33],[1,1.27,98.82]],"ltp":1.22,"tv":335.02,"id":16676046},{"batb":[[0,14.5,11.04],[1,14,17.73],[2,12.5,7.87]],"batl":[[1,22,4.8]],"ltp":0.0,"tv":0.0,"id":21483494}]}]}
{"op":"mcm","clk":"1008623627","pt":1580660862680,"mc":[{"id":"1.168237985","rc":[{"batl":[[1,1.27,97.33]],"ltp":1.22,"tv":335.02,"id":16676046}]}]}
{"op":"mcm","clk":"1008626001","pt":1580660873839,"mc":[{"id":"1.168237985","rc":[{"batb":[[0,14,17.73],[1,12.5,7.87],[2,11,11.02]],"ltp":0.0,"tv":0.0,"id":21483494}]}]}
{"op":"mcm","clk":"1008626642","pt":1580660876734,"mc":[{"id":"1.168237985","rc":[{"batb":[[0,14,24.22],[1,13.5,18.49],[2,12.5,7.87]],"ltp":0.0,"tv":0.0,"id":21483494}]}]}
{"op":"mcm","clk":"1008631300","pt":1580660899743,"mc":[{"id":"1.168237985","rc":[{"batb":[[1,7.6,10.15],[2,1.01,0.51]],"ltp":4.2,"tv":79.99,"id":16676048},{"batb":[[0,1.21,29.32],[1,1.19,128.49],[2,1.14,173.26]],"ltp":1.22,"tv":335.02,"id":16676046},{"batb":[[0,12.5,7.87],[1,11,11.02],[2,1.01,0.51]],"ltp":0.0,"tv":0.0,"id":21483494}]}]}
{"op":"mcm","clk":"1008631490","pt":1580660900283,"mc":[{"id":"1.168237985","rc":[{"batb":[[0,1.19,128.49],[1,1.14,173.26],[2,1.01,0.51]],"ltp":1.22,"tv":335.02,"id":16676046}]}]}
{"op":"mcm","clk":"1008631889","pt":1580660901872,"mc":[{"id":"1.168237985","rc":[{"batb":[[2,7.2,23.54]],"ltp":4.2,"tv":79.99,"id":16676048},{"batb":[[1,1.16,416.8],[2,1.15,171.12]],"ltp":1.22,"tv":335.02,"id":16676046},{"batb":[[0,12.5,16.54],[1,12,24.18],[2,11,11.02]],"ltp":0.0,"tv":0.0,"id":21483494}]}]}
{"op":"mcm","clk":"1008632049","pt":1580660902251,"mc":[{"id":"1.168237985","rc":[{"batb":[[0,12.5,7.87]],"ltp":0.0,"tv":0.0,"id":21483494}]}]}
{"op":"mcm","clk":"1008632327","pt":1580660903210,"mc":[{"id":"1.168237985","rc":[{"batb":[[1,12,32.48],[2,11.5,25.25]],"ltp":0.0,"tv":0.0,"id":21483494}]}]}
{"op":"mcm","clk":"1008634135","pt":1580660910937,"mc":[{"id":"1.168237985","rc":[{"batb":[[0,7.6,10.15],[1,7.2,23.54],[2,7,30.7]],"batl":[[0,14,10.86],[1,14,0]],"ltp":4.2,"tv":79.99,"id":16676048},{"batb":[[0,1.16,416.8],[1,1.15,171.12],[2,1.14,173.26]],"batl":[[0,1.27,97.33],[1,1.27,0]],"ltp":1.22,"tv":335.02,"id":16676046},{"batb":[[0,12,32.48],[1,11.5,25.25],[2,11,11.02]],"batl":[[0,22,4.8],[1,22,0]],"ltp":0.0,"tv":0.0,"id":21483494}]}]}
{"op":"mcm","clk":"1008635952","pt":1580660919028,"mc":[{"id":"1.168237985","rc":[{"batb":[[1,1.01,0.51],[2,7,0]],"ltp":4.2,"tv":79.99,"id":16676048},{"batb":[[0,11,11.02],[1,1.01,0.51],[2,11,0]],"ltp":0.0,"tv":0.0,"id":21483494}]}]}
{"op":"mcm","clk":"1008636579","pt":1580660921991,"mc":[{"id":"1.168237985","rc":[{"batb":[[0,10,24.17],[1,9.8,14.88],[2,7.6,10.15]],"ltp":4.2,"tv":79.99,"id":16676048},{"batb":[[0,17.5,8.25],[1,17,11.78],[2,11,11.02]],"ltp":0.0,"tv":0.0,"id":21483494}]}]}
{"op":"mcm","clk":"1008636702","pt":1580660922619,"mc":[{"id":"1.168237985","rc":[{"batb":[[0,10.5,11.8],[1,10,24.17],[2,9.8,14.88]],"batl":[[1,18,6.53]],"ltp":4.2,"tv":79.99,"id":16676048},{"batl":[[0,1.18,142.89],[1,1.23,123.37]],"ltp":1.22,"tv":335.02,"id":16676046},{"batb":[[2,15.5,5.11]],"batl":[[1,30,5.74]],"ltp":0.0,"tv":0.0,"id":21483494}]}]}
{"op":"mcm","clk":"1008640543","pt":1580660940849,"mc":[{"id":"1.168237985","rc":[{"batb":[[0,8.8,7.16],[1,1.01,0.51],[2,9.8,0]],"batl":[[0,18,6.53],[1,18,0]],"ltp":4.2,"tv":79.99,"id":16676048},{"batb":[[0,1.1,239.51],[1,1.01,0.51],[2,1.14,0]],"batl":[[0,1.23,123.22],[1,1.23,0]],"ltp":1.22,"tv":335.02,"id":16676046},{"batb":[[0,13,7.71],[1,1.01,0.51],[2,15.5,0]],"batl":[[0,30,5.74],[1,30,0]],"ltp":0.0,"tv":0.0,"id":21483494}]}]}
{"op":"mcm","clk":"1008641250","pt":1580660944020,"mc":[{"id":"1.168237985","rc":[{"batb":[[1,8.4,21.2],[2,8.2,21.86]],"ltp":4.2,"tv":79.99,"id":16676048},{"batb":[[0,1.12,289.24],[1,1.11,321.01],[2,1.1,239.51]],"ltp":1.22,"tv":335.02,"id":16676046},{"batb":[[0,14.5,12.84],[1,14,17.42],[2,13,7.71]],"ltp":0.0,"tv":0.0,"id":21483494}]}]}
{"op":"mcm","clk":"1008642428","pt":1580660949741,"mc":[{"id":"1.168237985","rc":[{"batb":[[1,1.01,0.51],[2,8.2,0]],"ltp":4.2,"tv":79.99,"id":16676048},{"batb":[[0,13,7.71],[1,1.01,0.51],[2,13,0]],"ltp":0.0,"tv":0.0,"id":21483494}]}]}
{"op":"mcm","clk":"1008642937","pt":1580660952044,"mc":[{"id":"1.168237985","rc":[{"batb":[[0,13,22.25],[1,12.5,21.71],[2,8.8,7.16]],"ltp":4.2,"tv":79.99,"id":16676048},{"batb":[[0,22,18.36],[1,21,13.15],[2,13,7.71]],"ltp":0.0,"tv":0.0,"id":21483494}]}]}
{"op":"mcm","clk":"1008643130","pt":1580660952950,"mc":[{"id":"1.168237985","rc":[{"batb":[[0,13,29.25],[2,10.5,11.02]],"batl":[[1,26,7.16]],"ltp":4.2,"tv":79.99,"id":16676048},{"batl":[[0,1.14,143.52],[1,1.18,149.89]],"ltp":1.22,"tv":335.02,"id":16676046},{"batb":[[2,18.5,6.29]],"ltp":0.0,"tv":0.0,"id":21483494}]}]}
{"op":"mcm","clk":"1008646580","pt":1580660969870,"mc":[{"id":"1.168237985","rc":[{"batb":[[0,13,7],[1,10.5,11.02],[2,1.01,0.51]],"ltp":4.2,"tv":79.99,"id":16676048},{"batb":[[0,1.1,239.51],[1,1.07,341.48],[2,1.01,0.51]],"ltp":1.22,"tv":335.02,"id":16676046},{"batb":[[0,18.5,6.29],[1,16,4.64],[2,1.01,0.51]],"ltp":0.0,"tv":0.0,"id":21483494}]}]}
{"op":"mcm","clk":"1008646667","pt":1580660970246,"mc":[{"id":"1.168237985","rc":[{"batb":[[0,10.5,11.02],[1,1.01,0.51],[2,1.01,0]],"batl":[[0,26,7.16],[1,26,0]],"ltp":4.2,"tv":79.99,"id":16676048},{"batb":[[0,1.07,341.48],[1,1.01,0.51],[2,1.01,0]],"batl":[[0,1.18,149.89],[1,1.18,0]],"ltp":1.22,"tv":335.02,"id":16676046},{"batb":[[0,16,4.64],[1,1.01,0.51],[2,1.01,0]],"ltp":0.0,"tv":0.0,"id":21483494}]}]}
{"op":"mcm","clk":"1008647161","pt":1580660972855,"mc":[{"id":"1.168237985","rc":[{"batb":[[0,10.5,39.81],[1,10,34.37],[2,1.01,0.51]],"ltp":4.2,"tv":79.99,"id":16676048},{"batb":[[0,1.08,629.88],[1,1.07,341.48],[2,1.01,0.51]],"ltp":1.22,"tv":335.02,"id":16676046},{"batb":[[0,18.5,7.88],[1,18,10.47],[2,16,4.64]],"ltp":0.0,"tv":0.0,"id":21483494}]}]}
{"op":"mcm","clk":"1008647848","pt":1580660976443,"mc":[{"id":"1.168237985","rc":[{"batb":[[0,10.5,11.02],[1,1.01,0.51],[2,1.01,0]],"ltp":4.2,"tv":79.99,"id":16676048},{"batb":[[0,16,4.64],[1,1.01,0.51],[2,16,0]],"ltp":0.0,"tv":0.0,"id":21483494}]}]}
{"op":"mcm","clk":"1008648479","pt":1580660979595,"mc":[{"id":"1.168237985","rc":[{"batb":[[0,18,12.49],[1,17.5,10.99],[2,10.5,11.02]],"ltp":4.2,"tv":79.99,"id":16676048},{"batb":[[0,30,13.36],[1,29,7.54],[2,16,4.64]],"ltp":0.0,"tv":0.0,"id":21483494}]}]}
{"op":"mcm","clk":"1008648644","pt":1580660980381,"mc":[{"id":"1.168237985","rc":[{"batb":[[2,17,7.95]],"ltp":4.2,"tv":79.99,"id":16676048},{"batb":[[2,1.05,440.78]],"batl":[[0,1.11,146.74],[1,1.13,147.37]],"ltp":1.22,"tv":335.02,"id":16676046},{"batb":[[2,23,3.15]],"ltp":0.0,"tv":0.0,"id":21483494}]}]}
{"op":"mcm","clk":"1008652324","pt":1580660997816,"mc":[{"id":"1.168237985","rc":[{"batb":[[0,14.5,5.59],[1,1.01,0.51],[2,17,0]],"ltp":4.2,"tv":79.99,"id":16676048},{"batb":[[0,1.05,440.78],[1,1.01,0.51],[2,1.05,0]],"batl":[[0,1.13,147.37],[1,1.13,0]],"ltp":1.22,"tv":335.02,"id":16676046},{"batb":[[0,20,5.27],[1,1.01,0.51],[2,23,0]],"ltp":0.0,"tv":0.0,"id":21483494}]}]}
{"op":"mcm","clk":"1008652869","pt":1580661000522,"mc":[{"id":"1.168237985","rc":[{"batb":[[0,15,17.55],[1,14.5,21.65],[2,1.01,0.51]],"ltp":4.2,"tv":79.99,"id":16676048},{"batb":[[0,1.06,641.77],[1,1.05,440.78],[2,1.01,0.51]],"ltp":1.22,"tv":335.02,"id":16676046},{"batb":[[0,26,6.1],[1,25,10.52],[2,20,5.27]],"ltp":0.0,"tv":0.0,"id":21483494}]}]}
{"op":"mcm","clk":"1008655009","pt":1580661010670,"mc":[{"id":"1.168237985","rc":[{"batb":[[0,14.5,5.59],[1,1.01,0.51],[2,1.01,0]],"ltp":4.2,"tv":79.99,"id":16676048},{"batb":[[0,1.05,440.78],[1,1.01,0.51],[2,1.01,0]],"ltp":1.22,"tv":335.02,"id":16676046},{"batb":[[0,20,5.27],[1,1.01,0.51],[2,20,0]],"ltp":0.0,"tv":0.0,"id":21483494}]}]}
{"op":"mcm","clk":"1008655707","pt":1580661014002,"mc":[{"id":"1.168237985","rc":[{"batb":[[0,18,12.64],[1,17.5,10.99],[2,14.5,5.59]],"ltp":4.2,"tv":79.99,"id":16676048},{"batb":[[0,1.08,629.88],[1,1.05,440.78],[2,1.01,0.51]],"ltp":1.22,"tv":335.02,"id":16676046},{"batb":[[0,30,13.45],[1,29,7.54],[2,20,5.27]],"ltp":0.0,"tv":0.0,"id":21483494}]}]}
{"op":"mcm","clk":"1008657307","pt":1580661021603,"mc":[{"id":"1.168237985","rc":[{"batb":[[0,9,16.8],[1,1.01,0.51]],"ltp":10.0,"tv":510.26,"id":21483493}]}]}
{"op":"mcm","clk":"1008657590","pt":1580661023011,"mc":[{"id":"1.168237985","rc":[{"batb":[[0,14.5,5.59],[1,1.01,0.51],[2,14.5,0]],"ltp":4.2,"tv":79.99,"id":16676048},{"batb":[[0,1.05,440.78],[1,1.01,0.51],[2,1.01,0]],"ltp":1.22,"tv":335.02,"id":16676046},{"batb":[[0,20,5.27],[1,1.01,0.51],[2,20,0]],"ltp":0.0,"tv":0.0,"id":21483494}]}]}
{"op":"mcm","clk":"1008658190","pt":1580661025893,"mc":[{"id":"1.168237985","rc":[{"batb":[[0,15,17.72],[1,14.5,21.65],[2,1.01,0.51]],"ltp":4.2,"tv":79.99,"id":16676048},{"batb":[[0,1.06,641.77],[1,1.05,440.78],[2,1.01,0.51]],"ltp":1.22,"tv":335.02,"id":16676046},{"batb":[[0,26,5.88],[1,25,10.52],[2,20,5.27]],"ltp":0.0,"tv":0.0,"id":21483494}]}]}
{"op":"mcm","clk":"1008658263","pt":1580661026300,"mc":[{"id":"1.168237985","rc":[{"batb":[[0,14.5,5.59],[1,1.01,0.51],[2,1.01,0]],"ltp":4.2,"tv":79.99,"id":16676048},{"batb":[[0,1.05,440.78],[1,1.01,0.51],[2,1.01,0]],"ltp":1.22,"tv":335.02,"id":16676046},{"batb":[[0,20,5.27],[1,1.01,0.51],[2,20,0]],"ltp":0.0,"tv":0.0,"id":21483494}]}]}
