{"op":"mcm","clk":"1002315141","pt":1580592409750,"mc":[{"id":"1.168237984","marketDefinition":{"bspMarket":false,"turnInPlayEnabled":true,"persistenceEnabled":true,"marketBaseRate":5.0,"eventId":"29681871","eventTypeId":"2","numberOfWinners":1,"bettingType":"ODDS","marketType":"MATCH_ODDS","marketTime":"2020-02-02T16:00:00.000Z","suspendTime":"2020-02-02T16:00:00.000Z","bspReconciled":false,"complete":true,"inPlay":false,"crossMatching":false,"runnersVoidable":false,"numberOfActiveRunners":2,"betDelay":0,"status":"OPEN","runners":[{"status":"ACTIVE","sortPriority":1,"id":14833204,"name":"Facundo Diaz Acosta"},{"status":"ACTIVE","sortPriority":2,"id":13181195,"name":"Pedro Martinez"}],"regulators":["MR_INT"],"countryCode":"AR","discountAllowed":false,"timezone":"UTC","openDate":"2020-02-02T16:00:00.000Z","version":3147569482,"name":"Match Odds","eventName":"Diaz Acosta v Martinez"},"rc":[{"batb":[[0,1.01,333.65]],"ltp":0.0,"tv":0.0,"id":14833204},{"batb":[[0,1.04,160.53],[1,1.03,227.93],[2,1.02,260.49]],"ltp":0.0,"tv":0.0,"id":13181195}]}]}
{"op":"mcm","clk":"1002315289","pt":1580592411040,"mc":[{"id":"1.168237984","marketDefinition":{"bspMarket":false,"turnInPlayEnabled":true,"persistenceEnabled":true,"marketBaseRate":5.0,"eventId":"29681871","eventTypeId":"2","numberOfWinners":1,"bettingType":"ODDS","marketType":"MATCH_ODDS","marketTime":"2020-02-02T16:00:00.000Z","suspendTime":"2020-02-02T16:00:00.000Z","bspReconciled":false,"complete":true,"inPlay":false,"crossMatching":false,"runnersVoidable":false,"numberOfActiveRunners":2,"betDelay":0,"status":"OPEN","runners":[{"status":"ACTIVE","sortPriority":1,"id":14833204,"name":"Facundo Diaz Acosta"},{"status":"ACTIVE","sortPriority":2,"id":13181195,"name":"Pedro Martinez"}],"regulators":["MR_INT"],"countryCode":"AR","discountAllowed":false,"timezone":"UTC","openDate":"2020-02-02T16:00:00.000Z","version":3147569482,"name":"Match Odds","eventName":"Diaz Acosta v Martinez"}}]}
{"op":"mcm","clk":"1002315411","pt":1580592412044,"mc":[{"id":"1.168237984","marketDefinition":{"bspMarket":false,"turnInPlayEnabled":true,"persistenceEnabled":true,"marketBaseRate":5.0,"eventId":"29681871","eventTypeId":"2","numberOfWinners":1,"bettingType":"ODDS","marketType":"MATCH_ODDS","marketTime":"2020-02-02T16:00:00.000Z","suspendTime":"2020-02-02T16:00:00.000Z","bspReconciled":false,"complete":true,"inPlay":false,"crossMatching":false,"runnersVoidable":false,"numberOfActiveRunners":2,"betDelay":0,"status":"OPEN","runners":[{"status":"ACTIVE","sortPriority":1,"id":14833204,"name":"Facundo Diaz Acosta"},{"status":"ACTIVE","sortPriority":2,"id":13181195,"name":"Pedro Martinez"}],"regulators":["MR_INT"],"countryCode":"AR","discountAllowed":true,"timezone":"UTC","openDate":"2020-02-02T16:00:00.000Z","version":3147569482,"name":"Match Odds","eventName":"Diaz Acosta v Martinez"}}]}
{"op":"mcm","clk":"1002319822","pt":1580592454841,"mc":[{"id":"1.168237984","rc":[{"batb":[[0,1.01,633.65]],"ltp":0.0,"tv":0.0,"id":14833204}]}]}
{"op":"mcm","clk":"1002320238","pt":1580592458837,"mc":[{"id":"1.168237984","rc":[{"batb":[[0,1.01,333.65]],"ltp":0.0,"tv":0.0,"id":14833204}]}]}
{"op":"mcm","clk":"1002335495","pt":1580592618850,"mc":[{"id":"1.168237984","rc":[{"batb":[[0,1.01,313.65]],"ltp":0.0,"tv":0.0,"id":14833204}]}]}
{"op":"mcm","clk":"1002347709","pt":1580592741337,"mc":[{"id":"1.168237984","rc":[{"batb":[[0,1.02,151.45],[1,1.01,313.65]],"ltp":0.0,"tv":0.0,"id":14833204},{"batb":[[0,1.05,60.58],[1,1.04,160.53],[2,1.03,227.93]],"ltp":0.0,"tv":0.0,"id":13181195}]}]}
{"op":"mcm","clk":"1002348893","pt":1580592753358,"mc":[{"id":"1.168237984","marketDefinition":{"bspMarket":false,"turnInPlayEnabled":true,"persistenceEnabled":true,"marketBaseRate":5.0,"eventId":"29681871","eventTypeId":"2","numberOfWinners":1,"bettingType":"ODDS","marketType":"MATCH_ODDS","marketTime":"2020-02-02T16:00:00.000Z","suspendTime":"2020-02-02T16:00:00.000Z","bspReconciled":false,"complete":true,"inPlay":false,"crossMatching":true,"runnersVoidable":false,"numberOfActiveRunners":2,"betDelay":0,"status":"OPEN","runners":[{"status":"ACTIVE","sortPriority":1,"id":14833204,"name":"Facundo Diaz Acosta"},{"status":"ACTIVE","sortPriority":2,"id":13181195,"name":"Pedro Martinez"}],"regulators":["MR_INT"],"countryCode":"AR","discountAllowed":true,"timezone":"UTC","openDate":"2020-02-02T16:00:00.000Z","version":3147569482,"name":"Match Odds","eventName":"Diaz Acosta v Martinez"}}]}
{"op":"mcm","clk":"1002548636","pt":1580595201924,"mc":[{"id":"1.168237984","rc":[{"batl":[[0,990,2.2]],"ltp":0.0,"tv":0.0,"id":14833204},{"batl":[[0,990,2.2]],"ltp":0.0,"tv":0.0,"id":13181195}]}]}
{"op":"mcm","clk":"1002964165","pt":1580601267994,"mc":[{"id":"1.168237984","rc":[{"batb":[[0,1.84,2403.8],[1,1.02,151.45],[2,1.01,313.65]],"ltp":0.0,"tv":0.0,"id":14833204}]}]}
{"op":"mcm","clk":"1002964531","pt":1580601273275,"mc":[{"id":"1.168237984","rc":[{"batb":[[0,1.85,8.4],[1,1.84,2403.8],[2,1.02,151.45]],"ltp":0.0,"tv":0.0,"id":14833204}]}]}
{"op":"mcm","clk":"1002965236","pt":1580601283483,"mc":[{"id":"1.168237984","rc":[{"batb":[[0,1.08,3509.49],[1,1.05,60.58],[2,1.04,160.53]],"ltp":0.0,"tv":0.0,"id":13181195}]}]}
{"op":"mcm","clk":"1002965468","pt":1580601286695,"mc":[{"id":"1.168237984","rc":[{"batb":[[0,1.09,8.4],[1,1.08,3509.49],[2,1.05,60.58]],"ltp":0.0,"tv":0.0,"id":13181195}]}]}
{"op":"mcm","clk":"1002985300","pt":1580601560629,"mc":[{"id":"1.168237984","rc":[{"batb":[[2,1.02,151.55]],"batl":[[1,1000,0.02]],"ltp":0.0,"tv":0.0,"id":14833204},{"batb":[[0,1.09,8.5]],"batl":[[1,1000,0.02]],"ltp":0.0,"tv":0.0,"id":13181195}]}]}
{"op":"mcm","clk":"1002985357","pt":1580601561506,"mc":[{"id":"1.168237984","rc":[{"batb":[[2,1.02,152.05]],"ltp":0.0,"tv":0.0,"id":14833204}]}]}
{"op":"mcm","clk":"1002990436","pt":1580601630930,"mc":[{"id":"1.168237984","rc":[{"batb":[[2,1.02,152.15]],"ltp":0.0,"tv":0.0,"id":14833204},{"batb":[[0,1.09,8.6]],"ltp":0.0,"tv":0.0,"id":13181195}]}]}
{"op":"mcm","clk":"1003007256","pt":1580601888413,"mc":[{"id":"1.168237984","rc":[{"batb":[[0,1.85,14.1]],"ltp":0.0,"tv":0.0,"id":14833204}]}]}
{"op":"mcm","clk":"1003315725","pt":1580606116955,"mc":[{"id":"1.168237984","rc":[{"batb":[[2,1.02,177.35]],"ltp":0.0,"tv":0.0,"id":14833204}]}]}
{"op":"mcm","clk":"1003315765","pt":1580606117532,"mc":[{"id":"1.168237984","rc":[{"batb":[[2,1.03,9.1]],"ltp":0.0,"tv":0.0,"id":14833204}]}]}
{"op":"mcm","clk":"1003326228","pt":1580606254851,"mc":[{"id":"1.168237984","rc":[{"batb":[[0,2.72,41.84],[1,1.85,14.1],[2,1.84,2403.8]],"ltp":0.0,"tv":0.0,"id":14833204},{"batb":[[0,1.1,130.74],[1,1.09,8.4],[2,1.08,3509.49]],"ltp":0.0,"tv":0.0,"id":13181195}]}]}
{"op":"mcm","clk":"1003326953","pt":1580606263854,"mc":[{"id":"1.168237984","rc":[{"batb":[[0,3.3,27.26],[1,2.72,41.84],[2,1.85,14.1]],"ltp":0.0,"tv":0.0,"id":14833204}]}]}
{"op":"mcm","clk":"1003327029","pt":1580606264680,"mc":[{"id":"1.168237984","rc":[{"batb":[[0,3.35,33.87],[1,3.3,27.26]],"ltp":0.0,"tv":0.0,"id":14833204},{"batb":[[0,1.25,114.61],[1,1.24,37.86],[2,1.09,8.6]],"ltp":0.0,"tv":0.0,"id":13181195}]}]}
{"op":"mcm","clk":"1003357255","pt":1580606690522,"mc":[{"id":"1.168237984","rc":[{"batb":[[0,3.3,27.26],[1,1.85,14.1],[2,1.84,2403.8]],"ltp":0.0,"tv":0.0,"id":14833204},{"batb":[[0,1.24,37.86],[1,1.09,8.6],[2,1.08,3509.49]],"ltp":0.0,"tv":0.0,"id":13181195}]}]}
{"op":"mcm","clk":"1003357683","pt":1580606696507,"mc":[{"id":"1.168237984","rc":[{"batb":[[0,3.6,31.49],[1,3.3,27.26],[2,1.85,14.1]],"ltp":0.0,"tv":0.0,"id":14833204},{"batb":[[0,1.25,114.61],[1,1.24,37.86],[2,1.09,8.6]],"ltp":0.0,"tv":0.0,"id":13181195}]}]}
{"op":"mcm","clk":"1003364634","pt":1580606785849,"mc":[{"id":"1.168237984","rc":[{"batb":[[1,1.24,26.5]],"ltp":0.0,"tv":0.0,"id":13181195}]}]}
{"op":"mcm","clk":"1003364665","pt":1580606786213,"mc":[{"id":"1.168237984","rc":[{"batb":[[1,3.45,27.26]],"ltp":0.0,"tv":0.0,"id":14833204},{"batb":[[0,1.25,141.11],[1,1.09,8.6],[2,1.08,3509.49]],"ltp":0.0,"tv":0.0,"id":13181195}]}]}
{"op":"mcm","clk":"1003366714","pt":1580606811570,"mc":[{"id":"1.168237984","rc":[{"batb":[[0,1.25,150.2]],"ltp":0.0,"tv":0.0,"id":13181195}]}]}
{"op":"mcm","clk":"1003392518","pt":1580607128195,"mc":[{"id":"1.168237984","rc":[{"batb":[[2,1.85,8.4]],"ltp":0.0,"tv":0.0,"id":14833204}]}]}
{"op":"mcm","clk":"1003414025","pt":1580607419816,"mc":[{"id":"1.168237984","rc":[{"batl":[[0,8.2,3.36],[1,990,2.2],[2,1000,0.02]],"ltp":0.0,"tv":0.0,"id":13181195}]}]}
{"op":"mcm","clk":"1003456302","pt":1580607982813,"mc":[{"id":"1.168237984","rc":[{"batb":[[1,1.11,8.5],[2,1.1,3509.59]],"ltp":0.0,"tv":0.0,"id":13181195}]}]}
{"op":"mcm","clk":"1003584773","pt":1580609867895,"mc":[{"id":"1.168237984","rc":[{"batb":[[0,3.45,27.26],[1,1.85,8.4],[2,1.84,2403.8]],"ltp":0.0,"tv":0.0,"id":14833204},{"batb":[[0,1.25,35.59]],"ltp":0.0,"tv":0.0,"id":13181195}]}]}
{"op":"mcm","clk":"1003584789","pt":1580609868104,"mc":[{"id":"1.168237984","rc":[{"batb":[[0,3.6,47.14],[1,3.45,27.26],[2,1.85,8.4]],"ltp":0.0,"tv":0.0,"id":14833204},{"batb":[[0,1.25,206.8]],"ltp":0.0,"tv":0.0,"id":13181195}]}]}
{"op":"mcm","clk":"1003617177","pt":1580610296814,"mc":[{"id":"1.168237984","rc":[{"batb":[[0,3.45,27.26],[1,1.85,8.4],[2,1.84,2403.8]],"ltp":0.0,"tv":0.0,"id":14833204},{"batb":[[0,1.25,35.59]],"ltp":0.0,"tv":0.0,"id":13181195}]}]}
{"op":"mcm","clk":"1003641351","pt":1580610596982,"mc":[{"id":"1.168237984","rc":[{"batb":[[0,3.55,47.99],[1,3.45,27.26],[2,1.85,8.4]],"ltp":0.0,"tv":0.0,"id":14833204},{"batb":[[0,1.26,170.71],[1,1.25,72.69],[2,1.11,8.5]],"ltp":0.0,"tv":0.0,"id":13181195}]}]}
{"op":"mcm","clk":"1003810884","pt":1580613603042,"mc":[{"id":"1.168237984","rc":[{"batb":[[0,3.45,27.26],[1,1.85,8.4],[2,1.84,2403.8]],"ltp":0.0,"tv":0.0,"id":14833204},{"batb":[[0,1.25,72.69],[1,1.11,8.5],[2,1.1,3509.59]],"ltp":0.0,"tv":0.0,"id":13181195}]}]}
{"op":"mcm","clk":"1003810889","pt":1580613603146,"mc":[{"id":"1.168237984","rc":[{"batb":[[0,3.55,63.79],[1,3.45,27.26],[2,1.85,8.4]],"ltp":0.0,"tv":0.0,"id":14833204},{"batb":[[0,1.26,226.71],[1,1.25,72.69],[2,1.11,8.5]],"ltp":0.0,"tv":0.0,"id":13181195}]}]}
{"op":"mcm","clk":"1003838261","pt":1580614196900,"mc":[{"id":"1.168237984","rc":[{"batb":[[0,1.26,227.71]],"ltp":0.0,"tv":0.0,"id":13181195}]}]}
{"op":"mcm","clk":"1003838312","pt":1580614197931,"mc":[{"id":"1.168237984","rc":[{"batb":[[0,3.5,65.24]],"ltp":0.0,"tv":0.0,"id":14833204}]}]}
{"op":"mcm","clk":"1003845927","pt":1580614345589,"mc":[{"id":"1.168237984","rc":[{"batb":[[0,3.45,27.26],[1,1.85,8.4],[2,1.84,2403.8]],"ltp":0.0,"tv":0.0,"id":14833204},{"batl":[[0,1.29,2.52],[1,8.2,3.36],[2,990,2.2]],"ltp":0.0,"tv":0.0,"id":13181195}]}]}
{"op":"mcm","clk":"1003847266","pt":1580614369062,"mc":[{"id":"1.168237984","rc":[{"batl":[[1,990,2.2],[2,1000,0.02]],"ltp":0.0,"tv":0.0,"id":13181195}]}]}
{"op":"mcm","clk":"1003946364","pt":1580616796658,"mc":[{"id":"1.168237984","rc":[{"batl":[[0,95,15.9],[1,990,2.2],[2,1000,0.02]],"ltp":0.0,"tv":0.0,"id":14833204},{"batl":[[1,95,15.9],[2,990,2.2]],"ltp":0.0,"tv":0.0,"id":13181195}]}]}
{"op":"mcm","clk":"1003973344","pt":1580617348963,"mc":[{"id":"1.168237984","rc":[{"batb":[[0,1.26,283.21]],"ltp":0.0,"tv":0.0,"id":13181195}]}]}
{"op":"mcm","clk":"1003993578","pt":1580617797340,"mc":[{"id":"1.168237984","rc":[{"batb":[[0,1.25,72.69],[1,1.11,8.5],[2,1.1,3509.59]],"ltp":0.0,"tv":0.0,"id":13181195}]}]}
{"op":"mcm","clk":"1004026494","pt":1580618505746,"mc":[{"id":"1.168237984","rc":[{"batb":[[0,1.26,284.71],[1,1.25,72.69],[2,1.12,151.55]],"batl":[[1,2,18.17],[2,95,15.9]],"ltp":0.0,"tv":0.0,"id":13181195}]}]}
{"op":"mcm","clk":"1004046326","pt":1580618905443,"mc":[{"id":"1.168237984","rc":[{"batb":[[0,1.26,509.98]],"ltp":0.0,"tv":0.0,"id":13181195}]}]}
{"op":"mcm","clk":"1004078967","pt":1580619778741,"mc":[{"id":"1.168237984","rc":[{"batb":[[0,1.27,7.04],[1,1.26,509.98],[2,1.25,72.69]],"ltp":0.0,"tv":0.0,"id":13181195}]}]}
{"op":"mcm","clk":"1004078997","pt":1580619779259,"mc":[{"id":"1.168237984","rc":[{"batb":[[1,1.25,72.69],[2,1.12,151.55]],"ltp":0.0,"tv":0.0,"id":13181195}]}]}
{"op":"mcm","clk":"1004177825","pt":1580622255974,"mc":[{"id":"1.168237984","rc":[{"batb":[[0,1.25,72.69],[1,1.12,151.55],[2,1.11,8.4]],"ltp":0.0,"tv":0.0,"id":13181195}]}]}
{"op":"mcm","clk":"1004177835","pt":1580622256283,"mc":[{"id":"1.168237984","rc":[{"batb":[[0,1.26,711.71],[1,1.25,72.69],[2,1.13,7.14]],"ltp":0.0,"tv":0.0,"id":13181195}]}]}
{"op":"mcm","clk":"1004234219","pt":1580624053859,"mc":[{"id":"1.168237984","rc":[{"batb":[[0,1.26,682.48]],"ltp":0.0,"tv":0.0,"id":13181195}]}]}
{"op":"mcm","clk":"1004234409","pt":1580624059726,"mc":[{"id":"1.168237984","rc":[{"batb":[[0,1.85,8.4],[1,1.84,2403.8],[2,1.03,9.1]],"ltp":0.0,"tv":0.0,"id":14833204}]}]}
{"op":"mcm","clk":"1004234422","pt":1580624060242,"mc":[{"id":"1.168237984","rc":[{"batb":[[0,1.27,72.69],[1,1.26,682.48]],"ltp":0.0,"tv":0.0,"id":13181195}]}]}
{"op":"mcm","clk":"1004234634","pt":1580624066867,"mc":[{"id":"1.168237984","rc":[{"trd":[[1.29,5.04]],"batb":[[0,1.29,29.87],[1,1.27,72.69]],"batl":[[0,2,18.17],[1,95,15.9],[2,990,2.2]],"ltp":1.29,"tv":5.04,"id":13181195}],"tv":5.04}]}
{"op":"mcm","clk":"1004234642","pt":1580624067076,"mc":[{"id":"1.168237984","rc":[{"batb":[[0,1.27,72.69],[1,1.13,7.14],[2,1.12,151.45]],"ltp":1.29,"tv":5.04,"id":13181195}]}]}
{"op":"mcm","clk":"1004234848","pt":1580624072641,"mc":[{"id":"1.168237984","rc":[{"batb":[[0,1.28,72.69]],"batl":[[0,1.55,426.3],[1,2,18.17],[2,95,15.9]],"ltp":1.29,"tv":5.04,"id":13181195}]}]}
{"op":"mcm","clk":"1004234886","pt":1580624074041,"mc":[{"id":"1.168237984","rc":[{"batb":[[0,3.2,28.77],[1,1.85,8.4],[2,1.84,2403.8]],"ltp":0.0,"tv":0.0,"id":14833204},{"batb":[[0,1.27,28.77]],"ltp":1.29,"tv":5.04,"id":13181195}]}]}
{"op":"mcm","clk":"1004235245","pt":1580624084901,"mc":[{"id":"1.168237984","rc":[{"batb":[[0,3.25,197.37],[1,3.2,28.77],[2,1.85,8.4]],"ltp":0.0,"tv":0.0,"id":14833204},{"batb":[[0,1.29,612.43],[1,1.27,28.77],[2,1.13,7.14]],"batl":[[0,2,18.17],[1,95,15.9],[2,990,2.2]],"ltp":1.29,"tv":5.04,"id":13181195}]}]}
{"op":"mcm","clk":"1004235307","pt":1580624086968,"mc":[{"id":"1.168237984","rc":[{"batb":[[1,1.85,8.4],[2,1.84,2403.8]],"ltp":0.0,"tv":0.0,"id":14833204}]}]}
{"op":"mcm","clk":"1004235332","pt":1580624087482,"mc":[{"id":"1.168237984","rc":[{"batb":[[1,1.28,28.77]],"ltp":1.29,"tv":5.04,"id":13181195}]}]}
{"op":"mcm","clk":"1004235401","pt":1580624089799,"mc":[{"id":"1.168237984","rc":[{"batb":[[1,3.1,29.53],[2,1.85,8.4]],"ltp":0.0,"tv":0.0,"id":14833204},{"batb":[[1,1.27,28.77]],"ltp":1.29,"tv":5.04,"id":13181195}]}]}
{"op":"mcm","clk":"1004236480","pt":1580624124038,"mc":[{"id":"1.168237984","rc":[{"batb":[[1,1.13,7.14],[2,1.12,151.45]],"ltp":1.29,"tv":5.04,"id":13181195}]}]}
{"op":"mcm","clk":"1004236488","pt":1580624124241,"mc":[{"id":"1.168237984","rc":[{"batb":[[1,1.27,71.18],[2,1.13,7.14]],"ltp":1.29,"tv":5.04,"id":13181195}]}]}
{"op":"mcm","clk":"1004244804","pt":1580624389240,"mc":[{"id":"1.168237984","rc":[{"batb":[[1,3.15,29.53]],"ltp":0.0,"tv":0.0,"id":14833204}]}]}
{"op":"mcm","clk":"1004249864","pt":1580624528783,"mc":[{"id":"1.168237984","rc":[{"batb":[[1,1.27,28.77]],"ltp":1.29,"tv":5.04,"id":13181195}]}]}
{"op":"mcm","clk":"1004249876","pt":1580624529191,"mc":[{"id":"1.168237984","rc":[{"batb":[[1,1.28,28.77]],"ltp":1.29,"tv":5.04,"id":13181195}]}]}
{"op":"mcm","clk":"1004253967","pt":1580624664932,"mc":[{"id":"1.168237984","rc":[{"batb":[[1,1.28,71.18]],"ltp":1.29,"tv":5.04,"id":13181195}]}]}
{"op":"mcm","clk":"1004260303","pt":1580624870991,"mc":[{"id":"1.168237984","rc":[{"batb":[[2,1.12,151.55]],"ltp":1.29,"tv":5.04,"id":13181195}]}]}
{"op":"mcm","clk":"1004260310","pt":1580624871402,"mc":[{"id":"1.168237984","rc":[{"batb":[[0,1.31,607.37],[1,1.3,7.04],[2,1.28,71.18]],"ltp":1.29,"tv":5.04,"id":13181195}]}]}
{"op":"mcm","clk":"1004321326","pt":1580626863948,"mc":[{"id":"1.168237984","rc":[{"batb":[[1,1.85,8.4],[2,1.84,2403.8]],"ltp":0.0,"tv":0.0,"id":14833204}]}]}
{"op":"mcm","clk":"1004321331","pt":1580626864050,"mc":[{"id":"1.168237984","rc":[{"batb":[[1,3.1,29.53],[2,1.85,8.4]],"ltp":0.0,"tv":0.0,"id":14833204}]}]}
{"op":"mcm","clk":"1004324429","pt":1580626989044,"mc":[{"id":"1.168237984","rc":[{"batb":[[0,3.1,29.53],[1,1.85,8.4],[2,1.84,2403.8]],"ltp":0.0,"tv":0.0,"id":14833204},{"batb":[[0,1.3,7.04],[1,1.28,71.18],[2,1.12,151.55]],"ltp":1.29,"tv":5.04,"id":13181195}]}]}
{"op":"mcm","clk":"1004324434","pt":1580626989145,"mc":[{"id":"1.168237984","rc":[{"batb":[[0,3.25,297.41],[1,3.1,29.53],[2,1.85,8.4]],"ltp":0.0,"tv":0.0,"id":14833204},{"batb":[[0,1.31,901.37],[1,1.3,7.04],[2,1.28,71.18]],"ltp":1.29,"tv":5.04,"id":13181195}]}]}
{"op":"mcm","clk":"1004340942","pt":1580627471970,"mc":[{"id":"1.168237984","rc":[{"batb":[[0,1.32,7.04],[1,1.28,71.18],[2,1.12,151.55]],"ltp":1.29,"tv":5.04,"id":13181195}]}]}
{"op":"mcm","clk":"1004340953","pt":1580627472077,"mc":[{"id":"1.168237984","rc":[{"batb":[[0,1.32,903.18]],"ltp":1.29,"tv":5.04,"id":13181195}]}]}
{"op":"mcm","clk":"1004348803","pt":1580627673386,"mc":[{"id":"1.168237984","rc":[{"batb":[[0,3.1,29.53],[1,1.85,8.4],[2,1.84,2403.8]],"ltp":0.0,"tv":0.0,"id":14833204}]}]}
{"op":"mcm","clk":"1004349309","pt":1580627685709,"mc":[{"id":"1.168237984","rc":[{"batb":[[0,3.15,307.43],[1,3.1,29.53],[2,1.85,8.4]],"ltp":0.0,"tv":0.0,"id":14833204}]}]}
{"op":"mcm","clk":"1004373978","pt":1580628280547,"mc":[{"id":"1.168237984","rc":[{"batb":[[0,3.4,39.7]],"ltp":0.0,"tv":0.0,"id":14833204},{"batb":[[0,1.33,116.59],[1,1.32,7.04],[2,1.28,71.18]],"ltp":1.29,"tv":5.04,"id":13181195}]}]}
{"op":"mcm","clk":"1004394578","pt":1580628787687,"mc":[{"id":"1.168237984","rc":[{"batb":[[2,1.26,29.53]],"ltp":1.29,"tv":5.04,"id":13181195}]}]}
{"op":"mcm","clk":"1004395663","pt":1580628815015,"mc":[{"id":"1.168237984","rc":[{"batb":[[2,1.12,151.55]],"ltp":1.29,"tv":5.04,"id":13181195}]}]}
{"op":"mcm","clk":"1004395668","pt":1580628815221,"mc":[{"id":"1.168237984","rc":[{"batb":[[2,1.26,71.94]],"ltp":1.29,"tv":5.04,"id":13181195}]}]}
{"op":"mcm","clk":"1004396232","pt":1580628831649,"mc":[{"id":"1.168237984","rc":[{"batb":[[2,1.28,29.53]],"ltp":1.29,"tv":5.04,"id":13181195}]}]}
{"op":"mcm","clk":"1004402423","pt":1580629003879,"mc":[{"id":"1.168237984","rc":[{"batb":[[2,1.12,151.55]],"ltp":1.29,"tv":5.04,"id":13181195}]}]}
{"op":"mcm","clk":"1004402427","pt":1580629004089,"mc":[{"id":"1.168237984","rc":[{"batb":[[2,1.28,71.18]],"ltp":1.29,"tv":5.04,"id":13181195}]}]}
{"op":"mcm","clk":"1004413369","pt":1580629279859,"mc":[{"id":"1.168237984","rc":[{"batb":[[2,2.22,37.86]],"ltp":0.0,"tv":0.0,"id":14833204}]}]}
{"op":"mcm","clk":"1004413382","pt":1580629280065,"mc":[{"id":"1.168237984","rc":[{"batb":[[2,2.5,37.86]],"ltp":0.0,"tv":0.0,"id":14833204}]}]}
{"op":"mcm","clk":"1004448434","pt":1580630089805,"mc":[{"id":"1.168237984","rc":[{"batb":[[1,1.28,71.18],[2,1.21,37.86]],"ltp":1.29,"tv":5.04,"id":13181195}]}]}
{"op":"mcm","clk":"1004466301","pt":1580630453519,"mc":[{"id":"1.168237984","rc":[{"batb":[[1,1.29,29.53]],"ltp":1.29,"tv":5.04,"id":13181195}]}]}
{"op":"mcm","clk":"1004466401","pt":1580630455620,"mc":[{"id":"1.168237984","rc":[{"batb":[[1,1.29,37.86]],"ltp":1.29,"tv":5.04,"id":13181195}]}]}
{"op":"mcm","clk":"1004472437","pt":1580630584907,"mc":[{"id":"1.168237984","rc":[{"batb":[[1,1.28,29.53]],"ltp":1.29,"tv":5.04,"id":13181195}]}]}
{"op":"mcm","clk":"1004474749","pt":1580630641988,"mc":[{"id":"1.168237984","rc":[{"batb":[[1,1.21,37.86],[2,1.12,151.55]],"ltp":1.29,"tv":5.04,"id":13181195}]}]}
{"op":"mcm","clk":"1004474767","pt":1580630642398,"mc":[{"id":"1.168237984","rc":[{"batb":[[1,1.28,71.18],[2,1.21,37.86]],"ltp":1.29,"tv":5.04,"id":13181195}]}]}
{"op":"mcm","clk":"1004517660","pt":1580631624040,"mc":[{"id":"1.168237984","rc":[{"batb":[[0,3.1,29.53],[1,2.5,37.86],[2,2.22,37.86]],"ltp":0.0,"tv":0.0,"id":14833204},{"batb":[[0,1.28,71.18],[1,1.21,37.86],[2,1.12,151.55]],"ltp":1.29,"tv":5.04,"id":13181195}]}]}
{"op":"mcm","clk":"1004517688","pt":1580631624550,"mc":[{"id":"1.168237984","rc":[{"batb":[[0,3.3,42.53],[1,3.1,29.53],[2,2.5,37.86]],"ltp":0.0,"tv":0.0,"id":14833204},{"batb":[[0,1.35,95.81],[1,1.28,71.18],[2,1.21,37.86]],"ltp":1.29,"tv":5.04,"id":13181195}]}]}
{"op":"mcm","clk":"1004567609","pt":1580632772078,"mc":[{"id":"1.168237984","rc":[{"batb":[[0,3.35,305.87],[1,3.3,42.53],[2,3.1,29.53]],"ltp":0.0,"tv":0.0,"id":14833204}]}]}
{"op":"mcm","clk":"1004567779","pt":1580632776084,"mc":[{"id":"1.168237984","rc":[{"batb":[[1,1.21,37.86],[2,1.12,151.55]],"ltp":1.29,"tv":5.04,"id":13181195}]}]}
{"op":"mcm","clk":"1004569707","pt":1580632820535,"mc":[{"id":"1.168237984","rc":[{"batb":[[0,3.45,296.81],[1,3.4,26]],"ltp":0.0,"tv":0.0,"id":14833204}]}]}
{"op":"mcm","clk":"1004576349","pt":1580632948967,"mc":[{"id":"1.168237984","rc":[{"batb":[[1,3.1,29.53],[2,2.5,37.86]],"ltp":0.0,"tv":0.0,"id":14833204}]}]}
{"op":"mcm","clk":"1004576362","pt":1580632949277,"mc":[{"id":"1.168237984","rc":[{"batb":[[0,3.5,10.81]],"ltp":0.0,"tv":0.0,"id":14833204}]}]}
{"op":"mcm","clk":"1004582767","pt":1580633075848,"mc":[{"id":"1.168237984","rc":[{"batb":[[0,3.3,352.91]],"ltp":0.0,"tv":0.0,"id":14833204}]}]}
{"op":"mcm","clk":"1004631642","pt":1580634082764,"mc":[{"id":"1.168237984","rc":[{"batl":[[2,1000,0.13]],"ltp":0.0,"tv":0.0,"id":14833204}]}]}
{"op":"mcm","clk":"1004631679","pt":1580634083376,"mc":[{"id":"1.168237984","rc":[{"batb":[[1,3.25,29.53]],"ltp":0.0,"tv":0.0,"id":14833204}]}]}
{"op":"mcm","clk":"1004633080","pt":1580634108549,"mc":[{"id":"1.168237984","rc":[{"batb":[[1,1.27,71.18],[2,1.21,37.86]],"ltp":1.29,"tv":5.04,"id":13181195}]}]}
{"op":"mcm","clk":"1004713313","pt":1580635831607,"mc":[{"id":"1.168237984","rc":[{"batb":[[0,3.4,301.21],[1,3.35,22.11],[2,3.3,42.53]],"ltp":0.0,"tv":0.0,"id":14833204}]}]}
{"op":"mcm","clk":"1004713513","pt":1580635835779,"mc":[{"id":"1.168237984","rc":[{"batb":[[0,3.45,318.92],[1,3.3,42.53],[2,3.25,29.53]],"ltp":0.0,"tv":0.0,"id":14833204}]}]}
{"op":"mcm","clk":"1004713548","pt":1580635836804,"mc":[{"id":"1.168237984","rc":[{"batb":[[0,3.5,10.81],[1,3.45,22.11]],"ltp":0.0,"tv":0.0,"id":14833204}]}]}
{"op":"mcm","clk":"1004713656","pt":1580635839996,"mc":[{"id":"1.168237984","rc":[{"batb":[[0,3.5,32.93],[1,3.25,29.53],[2,3,18.93]],"ltp":0.0,"tv":0.0,"id":14833204}]}]}
{"op":"mcm","clk":"1004719239","pt":1580635971567,"mc":[{"id":"1.168237984","rc":[{"batb":[[0,3.5,22.11],[1,3.3,42.53],[2,3.25,29.53]],"ltp":0.0,"tv":0.0,"id":14833204}]}]}
{"op":"mcm","clk":"1004757927","pt":1580636812976,"mc":[{"id":"1.168237984","rc":[{"batl":[[0,1.82,74.21],[1,2,18.17],[2,95,15.9]],"ltp":1.29,"tv":5.04,"id":13181195}]}]}
{"op":"mcm","clk":"1004778745","pt":1580637199519,"mc":[{"id":"1.168237984","rc":[{"batl":[[0,1.5,2.27],[1,1.82,74.21],[2,2,18.17]],"ltp":1.29,"tv":5.04,"id":13181195}]}]}
{"op":"mcm","clk":"1004805218","pt":1580637659999,"mc":[{"id":"1.168237984","rc":[{"batb":[[1,1.28,28.02]],"ltp":1.29,"tv":5.04,"id":13181195}]}]}
{"op":"mcm","clk":"1004806919","pt":1580637683540,"mc":[{"id":"1.168237984","rc":[{"batb":[[1,1.28,71.18]],"ltp":1.29,"tv":5.04,"id":13181195}]}]}
{"op":"mcm","clk":"1004920271","pt":1580639132601,"mc":[{"id":"1.168237984","rc":[{"batl":[[2,1.91,18.17]],"ltp":1.29,"tv":5.04,"id":13181195}]}]}
{"op":"mcm","clk":"1004921647","pt":1580639145027,"mc":[{"id":"1.168237984","rc":[{"batl":[[2,95,15.9]],"ltp":1.29,"tv":5.04,"id":13181195}]}]}
{"op":"mcm","clk":"1004921658","pt":1580639145132,"mc":[{"id":"1.168237984","rc":[{"batl":[[1,1.8,18.17],[2,1.82,74.21]],"ltp":1.29,"tv":5.04,"id":13181195}]}]}
{"op":"mcm","clk":"1005345055","pt":1580642193802,"mc":[{"id":"1.168237984","rc":[{"batl":[[0,1.39,420.1],[1,1.5,2.27],[2,1.8,18.17]],"ltp":1.29,"tv":5.04,"id":13181195}]}]}
{"op":"mcm","clk":"1005345788","pt":1580642197643,"mc":[{"id":"1.168237984","rc":[{"batl":[[1,1.4,420.1],[2,1.5,2.27]],"ltp":1.29,"tv":5.04,"id":13181195}]}]}
{"op":"mcm","clk":"1005349432","pt":1580642218459,"mc":[{"id":"1.168237984","rc":[{"batl":[[2,1.41,420.1]],"ltp":1.29,"tv":5.04,"id":13181195}]}]}
{"op":"mcm","clk":"1005358858","pt":1580642269305,"mc":[{"id":"1.168237984","rc":[{"batb":[[1,3.45,18.25]],"ltp":0.0,"tv":0.0,"id":14833204}]}]}
{"op":"mcm","clk":"1005432736","pt":1580642659792,"mc":[{"id":"1.168237984","rc":[{"batl":[[0,6.8,153.72],[1,95,15.9],[2,990,2.2]],"ltp":0.0,"tv":0.0,"id":14833204}]}]}
{"op":"mcm","clk":"1005825197","pt":1580644964683,"mc":[{"id":"1.168237984","rc":[{"batb":[[0,3.5,22.33]],"ltp":0.0,"tv":0.0,"id":14833204}]}]}
{"op":"mcm","clk":"1005882286","pt":1580645264011,"mc":[{"id":"1.168237984","rc":[{"batb":[[0,1.35,95.92]],"ltp":1.29,"tv":5.04,"id":13181195}]}]}
{"op":"mcm","clk":"1006085639","pt":1580646399018,"mc":[{"id":"1.168237984","rc":[{"trd":[[3.55,7.7],[3.6,0.42]],"batb":[[0,3.5,22.11]],"ltp":3.55,"tv":8.12,"id":14833204},{"trd":[[1.39,19.68]],"batl":[[0,1.39,400.42]],"ltp":1.39,"tv":24.72,"id":13181195}],"tv":32.84}]}
{"op":"mcm","clk":"1006088342","pt":1580646414247,"mc":[{"id":"1.168237984","rc":[{"trd":[[3.55,9.28]],"ltp":3.55,"tv":9.7,"id":14833204},{"trd":[[1.39,23.71]],"batl":[[0,1.39,396.39]],"ltp":1.39,"tv":28.75,"id":13181195}],"tv":38.45}]}
{"op":"mcm","clk":"1006475737","pt":1580648772583,"mc":[{"id":"1.168237984","rc":[{"batb":[[0,1.35,95.53]],"ltp":1.39,"tv":28.75,"id":13181195}]}]}
{"op":"mcm","clk":"1006497542","pt":1580648920873,"mc":[{"id":"1.168237984","rc":[{"batb":[[1,3.45,16.75]],"ltp":3.55,"tv":9.7,"id":14833204}]}]}
{"op":"mcm","clk":"1006497562","pt":1580648921081,"mc":[{"id":"1.168237984","rc":[{"batb":[[0,1.35,99.75]],"ltp":1.39,"tv":28.75,"id":13181195}]}]}
{"op":"mcm","clk":"1006515803","pt":1580649047435,"mc":[{"id":"1.168237984","rc":[{"trd":[[1.35,3.78],[1.36,0.22]],"batb":[[0,1.35,97.75]],"ltp":1.35,"tv":32.75,"id":13181195}],"tv":42.46}]}
{"op":"mcm","clk":"1006521809","pt":1580649088210,"mc":[{"id":"1.168237984","rc":[{"batb":[[1,1.29,71.18]],"ltp":1.35,"tv":32.75,"id":13181195}]}]}
{"op":"mcm","clk":"1006522784","pt":1580649094800,"mc":[{"id":"1.168237984","rc":[{"batb":[[2,3.2,29.53]],"ltp":3.55,"tv":9.7,"id":14833204},{"batb":[[1,1.28,28.77]],"ltp":1.35,"tv":32.75,"id":13181195}]}]}
{"op":"mcm","clk":"1006545016","pt":1580649238252,"mc":[{"id":"1.168237984","rc":[{"batb":[[1,1.28,71.18]],"ltp":1.35,"tv":32.75,"id":13181195}]}]}
{"op":"mcm","clk":"1006622308","pt":1580649767075,"mc":[{"id":"1.168237984","rc":[{"trd":[[1.35,7.14]],"batb":[[0,1.35,96.07]],"ltp":1.35,"tv":36.11,"id":13181195}],"tv":45.82}]}
{"op":"mcm","clk":"1006663625","pt":1580650049044,"mc":[{"id":"1.168237984","rc":[{"trd":[[3.55,17.2]],"ltp":3.55,"tv":17.62,"id":14833204},{"trd":[[1.39,43.93]],"batl":[[0,1.39,376.17]],"ltp":1.39,"tv":56.33,"id":13181195}],"tv":73.95}]}
{"op":"mcm","clk":"1006666064","pt":1580650065957,"mc":[{"id":"1.168237984","rc":[{"batl":[[0,1.38,7.57],[1,1.39,376.17],[2,1.4,420.1]],"ltp":1.39,"tv":56.33,"id":13181195}]}]}
{"op":"mcm","clk":"1006666354","pt":1580650067956,"mc":[{"id":"1.168237984","rc":[{"batl":[[0,1.39,376.17],[1,1.4,420.1],[2,1.41,420.1]],"ltp":1.39,"tv":56.33,"id":13181195}]}]}
{"op":"mcm","clk":"1006697454","pt":1580650288631,"mc":[{"id":"1.168237984","rc":[{"batb":[[0,3.6,22.11]],"ltp":3.55,"tv":17.62,"id":14833204}]}]}
{"op":"mcm","clk":"1006705560","pt":1580650343097,"mc":[{"id":"1.168237984","rc":[{"trd":[[3.6,16.25]],"batb":[[0,3.6,14.2]],"ltp":3.6,"tv":33.45,"id":14833204}],"tv":89.78}]}
{"op":"mcm","clk":"1006864956","pt":1580651435397,"mc":[{"id":"1.168237984","rc":[{"batl":[[0,1.38,80],[1,1.39,376.17],[2,1.4,420.1]],"ltp":1.39,"tv":56.33,"id":13181195}]}]}
{"op":"mcm","clk":"1006871699","pt":1580651489807,"mc":[{"id":"1.168237984","rc":[{"batb":[[1,3.55,11.11]],"ltp":3.6,"tv":33.45,"id":14833204},{"trd":[[1.38,39.08]],"batb":[[0,1.34,103.88]],"batl":[[0,1.38,60.46]],"ltp":1.38,"tv":95.41,"id":13181195}],"tv":128.86}]}
{"op":"mcm","clk":"1006912530","pt":1580651802470,"mc":[{"id":"1.168237984","marketDefinition":{"bspMarket":false,"turnInPlayEnabled":true,"persistenceEnabled":true,"marketBaseRate":5.0,"eventId":"29681871","eventTypeId":"2","numberOfWinners":1,"bettingType":"ODDS","marketType":"MATCH_ODDS","marketTime":"2020-02-02T15:52:00.000Z","suspendTime":"2020-02-02T15:52:00.000Z","bspReconciled":false,"complete":true,"inPlay":false,"crossMatching":true,"runnersVoidable":false,"numberOfActiveRunners":2,"betDelay":0,"status":"OPEN","runners":[{"status":"ACTIVE","sortPriority":1,"id":14833204,"name":"Facundo Diaz Acosta"},{"status":"ACTIVE","sortPriority":2,"id":13181195,"name":"Pedro Martinez"}],"regulators":["MR_INT"],"countryCode":"AR","discountAllowed":true,"timezone":"UTC","openDate":"2020-02-02T16:00:00.000Z","version":3149006551,"name":"Match Odds","eventName":"Diaz Acosta v Martinez"}}]}
{"op":"mcm","clk":"1006912941","pt":1580651805472,"mc":[{"id":"1.168237984","marketDefinition":{"bspMarket":false,"turnInPlayEnabled":true,"persistenceEnabled":true,"marketBaseRate":5.0,"eventId":"29681871","eventTypeId":"2","numberOfWinners":1,"bettingType":"ODDS","marketType":"MATCH_ODDS","marketTime":"2020-02-02T15:52:00.000Z","suspendTime":"2020-02-02T15:52:00.000Z","bspReconciled":false,"complete":true,"inPlay":false,"crossMatching":true,"runnersVoidable":false,"numberOfActiveRunners":2,"betDelay":0,"status":"OPEN","runners":[{"status":"ACTIVE","sortPriority":1,"id":14833204,"name":"Facundo Diaz Acosta"},{"status":"ACTIVE","sortPriority":2,"id":13181195,"name":"Pedro Martinez"}],"regulators":["MR_INT"],"countryCode":"AR","discountAllowed":true,"timezone":"UTC","openDate":"2020-02-02T15:52:00.000Z","version":3149006551,"name":"Match Odds","eventName":"Diaz Acosta v Martinez"}}]}
{"op":"mcm","clk":"1006926229","pt":1580651900349,"mc":[{"id":"1.168237984","rc":[{"batb":[[2,3,18.93]],"ltp":3.6,"tv":33.45,"id":14833204},{"batb":[[1,1.21,37.86],[2,1.18,75.82]],"ltp":1.38,"tv":95.41,"id":13181195}]}]}
{"op":"mcm","clk":"1006949751","pt":1580652067441,"mc":[{"id":"1.168237984","rc":[{"batb":[[2,3.2,28.77]],"ltp":3.6,"tv":33.45,"id":14833204},{"batb":[[1,1.28,71.18],[2,1.21,37.86]],"ltp":1.38,"tv":95.41,"id":13181195}]}]}
{"op":"mcm","clk":"1006951777","pt":1580652081177,"mc":[{"id":"1.168237984","rc":[{"batb":[[1,3.55,22.21]],"ltp":3.6,"tv":33.45,"id":14833204},{"batb":[[0,1.34,207.76]],"ltp":1.38,"tv":95.41,"id":13181195}]}]}
{"op":"mcm","clk":"1006957372","pt":1580652117602,"mc":[{"id":"1.168237984","rc":[{"batl":[[0,1.38,480.56]],"ltp":1.38,"tv":95.41,"id":13181195}]}]}
{"op":"mcm","clk":"1006977590","pt":1580652244547,"mc":[{"id":"1.168237984","rc":[{"trd":[[1.38,39.1]],"batl":[[0,1.38,480.55]],"ltp":1.38,"tv":95.43,"id":13181195}],"tv":128.88}]}
{"op":"mcm","clk":"1007014961","pt":1580652459377,"mc":[{"id":"1.168237984","rc":[{"trd":[[1.38,55.1]],"batl":[[0,1.38,472.55]],"ltp":1.38,"tv":111.43,"id":13181195}],"tv":144.88}]}
{"op":"mcm","clk":"1007048422","pt":1580652641798,"mc":[{"id":"1.168237984","rc":[{"trd":[[1.38,103.1]],"batb":[[2,1.24,217.92]],"batl":[[0,1.38,448.55]],"ltp":1.38,"tv":159.43,"id":13181195}],"tv":192.88}]}
{"op":"mcm","clk":"1007070532","pt":1580652768002,"mc":[{"id":"1.168237984","rc":[{"trd":[[1.38,129.1]],"batl":[[0,1.38,435.55]],"ltp":1.38,"tv":185.43,"id":13181195}],"tv":218.88}]}
{"op":"mcm","clk":"1007128392","pt":1580653094771,"mc":[{"id":"1.168237984","rc":[{"trd":[[1.38,147.1]],"batl":[[0,1.38,426.55]],"ltp":1.38,"tv":203.43,"id":13181195}],"tv":236.88}]}
{"op":"mcm","clk":"1007139947","pt":1580653170978,"mc":[{"id":"1.168237984","rc":[{"trd":[[1.38,167.11]],"batb":[[0,1.35,3],[1,1.34,207.76],[2,1.28,71.18]],"batl":[[0,1.38,416.54]],"ltp":1.38,"tv":223.44,"id":13181195}],"tv":256.89}]}
{"op":"mcm","clk":"1007192091","pt":1580653492814,"mc":[{"id":"1.168237984","rc":[{"batb":[[2,3.35,28.77]],"ltp":3.6,"tv":33.45,"id":14833204},{"trd":[[1.38,187.11]],"batb":[[2,1.24,217.92]],"batl":[[0,1.38,406.55]],"ltp":1.38,"tv":243.43,"id":13181195}],"tv":276.88}]}
{"op":"mcm","clk":"1007192691","pt":1580653496898,"mc":[{"id":"1.168237984","rc":[{"batb":[[2,3.3,28.77]],"ltp":3.6,"tv":33.45,"id":14833204}]}]}
{"op":"mcm","clk":"1007192711","pt":1580653497110,"mc":[{"id":"1.168237984","rc":[{"batb":[[2,1.27,71.18]],"ltp":1.38,"tv":243.43,"id":13181195}]}]}
{"op":"mcm","clk":"1007298059","pt":1580654145627,"mc":[{"id":"1.168237984","rc":[{"trd":[[1.36,24.22]],"batl":[[0,1.36,53],[1,1.38,406.55],[2,1.39,376.17]],"ltp":1.36,"tv":267.43,"id":13181195}],"tv":300.88}]}
{"op":"mcm","clk":"1007306675","pt":1580654195783,"mc":[{"id":"1.168237984","rc":[{"trd":[[1.36,130.22],[1.38,223.1]],"batl":[[0,1.38,388.55],[1,1.39,376.17],[2,1.4,420.1]],"ltp":1.38,"tv":409.43,"id":13181195}],"tv":442.88}]}
{"op":"mcm","clk":"1007306743","pt":1580654196187,"mc":[{"id":"1.168237984","rc":[{"batb":[[0,3.6,34.17]],"ltp":3.6,"tv":33.45,"id":14833204},{"batb":[[1,1.33,211.71]],"ltp":1.38,"tv":409.43,"id":13181195}]}]}
{"op":"mcm","clk":"1007313849","pt":1580654236733,"mc":[{"id":"1.168237984","rc":[{"batl":[[0,1.37,7.57],[1,1.38,388.55],[2,1.39,376.17]],"ltp":1.38,"tv":409.43,"id":13181195}]}]}
{"op":"mcm","clk":"1007314044","pt":1580654237939,"mc":[{"id":"1.168237984","rc":[{"trd":[[3.6,24.65],[3.7,2.8]],"batb":[[0,3.6,29.97]],"ltp":3.6,"tv":44.65,"id":14833204},{"trd":[[1.37,7.57]],"batl":[[0,1.38,388.55],[1,1.39,376.17],[2,1.4,420.1]],"ltp":1.37,"tv":417.0,"id":13181195}],"tv":461.65}]}
{"op":"mcm","clk":"1007314144","pt":1580654238538,"mc":[{"id":"1.168237984","rc":[{"batb":[[0,1.36,7.63],[1,1.35,3],[2,1.33,211.71]],"ltp":1.37,"tv":417.0,"id":13181195}]}]}
{"op":"mcm","clk":"1007344603","pt":1580654423338,"mc":[{"id":"1.168237984","rc":[{"trd":[[1.38,265.1]],"batl":[[0,1.38,367.55]],"ltp":1.38,"tv":459.0,"id":13181195}],"tv":503.65}]}
{"op":"mcm","clk":"1007344875","pt":1580654425328,"mc":[{"id":"1.168237984","rc":[{"trd":[[1.38,311.09]],"batl":[[0,1.38,344.56]],"ltp":1.38,"tv":504.99,"id":13181195}],"tv":549.65}]}
{"op":"mcm","clk":"1007345196","pt":1580654427638,"mc":[{"id":"1.168237984","rc":[{"batl":[[0,1.38,352.13]],"ltp":1.38,"tv":504.99,"id":13181195}]}]}
{"op":"mcm","clk":"1007351674","pt":1580654470816,"mc":[{"id":"1.168237984","rc":[{"batl":[[0,1.37,7.57],[1,1.38,352.13],[2,1.39,376.17]],"ltp":1.38,"tv":504.99,"id":13181195}]}]}
{"op":"mcm","clk":"1007351888","pt":1580654471999,"mc":[{"id":"1.168237984","rc":[{"trd":[[3.6,37.05],[3.7,5.6]],"batb":[[0,3.6,23.77]],"ltp":3.6,"tv":59.85,"id":14833204},{"trd":[[1.37,15.14]],"batb":[[0,1.36,15.25]],"batl":[[0,1.38,352.13],[1,1.39,376.17],[2,1.4,420.1]],"ltp":1.37,"tv":512.57,"id":13181195}],"tv":572.42}]}
{"op":"mcm","clk":"1007353155","pt":1580654479822,"mc":[{"id":"1.168237984","rc":[{"batb":[[0,1.35,3],[1,1.33,211.71],[2,1.27,71.18]],"batl":[[0,1.38,344.56]],"ltp":1.37,"tv":512.57,"id":13181195}]}]}
{"op":"mcm","clk":"1007353338","pt":1580654480931,"mc":[{"id":"1.168237984","rc":[{"batb":[[0,1.36,7.63],[1,1.35,3],[2,1.33,211.71]],"ltp":1.37,"tv":512.57,"id":13181195}]}]}
{"op":"mcm","clk":"1007354070","pt":1580654485637,"mc":[{"id":"1.168237984","rc":[{"batb":[[0,1.35,3],[1,1.33,211.71],[2,1.27,71.18]],"ltp":1.37,"tv":512.57,"id":13181195}]}]}
{"op":"mcm","clk":"1007354235","pt":1580654486835,"mc":[{"id":"1.168237984","rc":[{"batb":[[0,1.36,15.26],[1,1.35,3],[2,1.33,211.71]],"ltp":1.37,"tv":512.57,"id":13181195}]}]}
{"op":"mcm","clk":"1007380691","pt":1580654652783,"mc":[{"id":"1.168237984","rc":[{"trd":[[1.38,365.1]],"batl":[[0,1.38,317.55]],"ltp":1.38,"tv":566.57,"id":13181195}],"tv":626.42}]}
{"op":"mcm","clk":"1007397411","pt":1580654760008,"mc":[{"id":"1.168237984","rc":[{"trd":[[1.38,423.1]],"batb":[[0,1.37,7.57]],"batl":[[0,1.38,288.55]],"ltp":1.38,"tv":624.57,"id":13181195}],"tv":684.43}]}
{"op":"mcm","clk":"1007397530","pt":1580654760718,"mc":[{"id":"1.168237984","rc":[{"trd":[[1.37,30.29]],"batb":[[0,1.35,3],[1,1.33,211.71],[2,1.27,71.18]],"batl":[[0,1.38,296.07]],"ltp":1.37,"tv":639.72,"id":13181195}],"tv":699.57}]}
{"op":"mcm","clk":"1007398100","pt":1580654764202,"mc":[{"id":"1.168237984","rc":[{"batl":[[0,1.38,288.55]],"ltp":1.37,"tv":639.72,"id":13181195}]}]}
{"op":"mcm","clk":"1007398423","pt":1580654766316,"mc":[{"id":"1.168237984","rc":[{"batb":[[0,1.36,7.63],[1,1.35,3],[2,1.33,211.71]],"ltp":1.37,"tv":639.72,"id":13181195}]}]}
{"op":"mcm","clk":"1007407384","pt":1580654829787,"mc":[{"id":"1.168237984","rc":[{"batb":[[0,1.35,3],[1,1.33,211.71],[2,1.27,71.18]],"ltp":1.37,"tv":639.72,"id":13181195}]}]}
{"op":"mcm","clk":"1007407543","pt":1580654830972,"mc":[{"id":"1.168237984","rc":[{"trd":[[1.38,487.11]],"batb":[[0,1.37,7.57],[1,1.35,3],[2,1.33,211.71]],"batl":[[0,1.38,256.55]],"ltp":1.38,"tv":703.72,"id":13181195}],"tv":763.57}]}
{"op":"mcm","clk":"1007407567","pt":1580654831175,"mc":[{"id":"1.168237984","rc":[{"trd":[[1.37,45.43]],"batb":[[0,1.35,3],[1,1.33,211.71],[2,1.27,71.18]],"ltp":1.37,"tv":718.86,"id":13181195}],"tv":778.71}]}
{"op":"mcm","clk":"1007407795","pt":1580654832991,"mc":[{"id":"1.168237984","rc":[{"batl":[[0,1.38,264.12]],"ltp":1.37,"tv":718.86,"id":13181195}]}]}
{"op":"mcm","clk":"1007416364","pt":1580654898804,"mc":[{"id":"1.168237984","rc":[{"batl":[[0,1.38,256.55]],"ltp":1.37,"tv":718.86,"id":13181195}]}]}
{"op":"mcm","clk":"1007416412","pt":1580654899162,"mc":[{"id":"1.168237984","rc":[{"trd":[[1.38,559.11]],"batl":[[0,1.38,220.54]],"ltp":1.38,"tv":790.86,"id":13181195}],"tv":850.72}]}
{"op":"mcm","clk":"1007418185","pt":1580654913643,"mc":[{"id":"1.168237984","rc":[{"batl":[[0,1.38,228.12]],"ltp":1.38,"tv":790.86,"id":13181195}]}]}
{"op":"mcm","clk":"1007444922","pt":1580655126473,"mc":[{"id":"1.168237984","rc":[{"batb":[[2,3.5,10.08]],"ltp":3.6,"tv":59.85,"id":14833204},{"batb":[[2,1.3,84.02]],"ltp":1.38,"tv":790.86,"id":13181195}]}]}
{"op":"mcm","clk":"1007446058","pt":1580655136590,"mc":[{"id":"1.168237984","rc":[{"trd":[[1.38,623.11]],"batl":[[0,1.38,196.11]],"ltp":1.38,"tv":854.87,"id":13181195}],"tv":914.72}]}
{"op":"mcm","clk":"1007450598","pt":1580655176647,"mc":[{"id":"1.168237984","rc":[{"batl":[[0,1.38,188.54]],"ltp":1.38,"tv":854.87,"id":13181195}]}]}
{"op":"mcm","clk":"1007450725","pt":1580655177646,"mc":[{"id":"1.168237984","rc":[{"trd":[[1.38,681.11]],"batl":[[0,1.38,159.54]],"ltp":1.38,"tv":912.87,"id":13181195}],"tv":972.72}]}
{"op":"mcm","clk":"1007451202","pt":1580655181663,"mc":[{"id":"1.168237984","rc":[{"batl":[[0,1.38,167.11]],"ltp":1.38,"tv":912.87,"id":13181195}]}]}
{"op":"mcm","clk":"1007454025","pt":1580655202714,"mc":[{"id":"1.168237984","rc":[{"trd":[[1.38,723.11]],"batl":[[0,1.38,153.68]],"ltp":1.38,"tv":954.87,"id":13181195}],"tv":1014.72}]}
{"op":"mcm","clk":"1007454190","pt":1580655203806,"mc":[{"id":"1.168237984","rc":[{"batl":[[0,1.38,138.54]],"ltp":1.38,"tv":954.87,"id":13181195}]}]}
{"op":"mcm","clk":"1007454373","pt":1580655205213,"mc":[{"id":"1.168237984","rc":[{"batl":[[0,1.38,146.11]],"ltp":1.38,"tv":954.87,"id":13181195}]}]}
{"op":"mcm","clk":"1007454560","pt":1580655206814,"mc":[{"id":"1.168237984","rc":[{"batl":[[0,1.38,138.54]],"ltp":1.38,"tv":954.87,"id":13181195}]}]}
{"op":"mcm","clk":"1007504978","pt":1580655609230,"mc":[{"id":"1.168237984","rc":[{"batb":[[0,1.35,17.29]],"ltp":1.38,"tv":954.87,"id":13181195}]}]}
{"op":"mcm","clk":"1007505260","pt":1580655610453,"mc":[{"id":"1.168237984","rc":[{"trd":[[1.38,755.11]],"batl":[[0,1.38,122.54]],"ltp":1.38,"tv":986.86,"id":13181195}],"tv":1046.72}]}
{"op":"mcm","clk":"1007515562","pt":1580655681682,"mc":[{"id":"1.168237984","rc":[{"batb":[[2,3.5,12.12]],"batl":[[0,4,2.01],[1,4.1,2.05],[2,6.8,153.72]],"ltp":3.6,"tv":59.85,"id":14833204},{"trd":[[1.38,779.11]],"batb":[[1,1.33,213.72],[2,1.32,2.14]],"batl":[[0,1.38,110.54],[2,1.4,422.14]],"ltp":1.38,"tv":1010.86,"id":13181195}],"tv":1070.71}]}
{"op":"mcm","clk":"1007565017","pt":1580655939972,"mc":[{"id":"1.168237984","rc":[{"trd":[[1.35,41.7]],"batb":[[0,1.33,213.72],[1,1.32,2.14],[2,1.31,81.31]],"batl":[[0,1.35,441.18],[1,1.38,110.54],[2,1.39,376.17]],"ltp":1.35,"tv":1045.42,"id":13181195}],"tv":1105.28}]}
{"op":"mcm","clk":"1007565200","pt":1580655940773,"mc":[{"id":"1.168237984","rc":[{"batb":[[0,3.75,2.03],[1,3.7,11.35],[2,3.6,23.77]],"batl":[[0,4.3,2.05],[1,4.4,2.04]],"ltp":3.6,"tv":59.85,"id":14833204},{"batb":[[0,1.33,211.71],[1,1.31,2.08],[2,1.3,2.08]],"batl":[[1,1.37,2.15],[2,1.38,112.58]],"ltp":1.35,"tv":1045.42,"id":13181195}]}]}
{"op":"mcm","clk":"1007565282","pt":1580655941169,"mc":[{"id":"1.168237984","rc":[{"trd":[[1.35,85.68]],"batl":[[0,1.35,419.21]],"ltp":1.35,"tv":1089.4,"id":13181195}],"tv":1149.25}]}
{"op":"mcm","clk":"1007592801","pt":1580656070928,"mc":[{"id":"1.168237984","rc":[{"trd":[[1.35,285.29]],"batl":[[0,1.35,319.45]],"ltp":1.35,"tv":1289.02,"id":13181195}],"tv":1348.87}]}
{"op":"mcm","clk":"1007593015","pt":1580656071898,"mc":[{"id":"1.168237984","rc":[{"batb":[[0,3.75,36.59],[2,3.6,3.8]],"batl":[[0,4.5,2.01],[1,4.6,2.01]],"ltp":3.6,"tv":59.85,"id":14833204},{"trd":[[1.35,405.23]],"batb":[[0,1.31,232.15],[1,1.29,2],[2,1.28,92.18]],"batl":[[0,1.35,259.51]],"ltp":1.35,"tv":1408.96,"id":13181195}],"tv":1468.81}]}
{"op":"mcm","clk":"1007593125","pt":1580656072427,"mc":[{"id":"1.168237984","rc":[{"batl":[[1,4.6,2],[2,4.7,2.05]],"ltp":3.6,"tv":59.85,"id":14833204}]}]}
{"op":"mcm","clk":"1007596280","pt":1580656085977,"mc":[{"id":"1.168237984","rc":[{"batl":[[2,1.38,228.12]],"ltp":1.35,"tv":1408.96,"id":13181195}]}]}
{"op":"mcm","clk":"1007596407","pt":1580656086547,"mc":[{"id":"1.168237984","rc":[{"batl":[[1,4.6,2.01],[2,6.8,153.72]],"ltp":3.6,"tv":59.85,"id":14833204},{"batb":[[2,1.28,92.03]],"ltp":1.35,"tv":1408.96,"id":13181195}]}]}
{"op":"mcm","clk":"1007611600","pt":1580656151911,"mc":[{"id":"1.168237984","rc":[{"batb":[[1,3.7,9.33]],"batl":[[1,6.8,153.72],[2,95,15.9]],"ltp":3.6,"tv":59.85,"id":14833204},{"trd":[[1.35,539.16]],"batb":[[2,1.28,90.02]],"batl":[[0,1.35,192.58],[2,1.38,110.54]],"ltp":1.35,"tv":1542.89,"id":13181195}],"tv":1602.74}]}
{"op":"mcm","clk":"1007611665","pt":1580656152161,"mc":[{"id":"1.168237984","rc":[{"batb":[[1,3.7,11.35]],"batl":[[1,4.6,2.01],[2,6.8,153.72]],"ltp":3.6,"tv":59.85,"id":14833204},{"batb":[[2,1.28,92.18]],"batl":[[2,1.38,112.58]],"ltp":1.35,"tv":1542.89,"id":13181195}]}]}
{"op":"mcm","clk":"1007636987","pt":1580656254952,"mc":[{"id":"1.168237984","rc":[{"trd":[[1.31,3.36]],"batb":[[0,1.31,230.47]],"ltp":1.31,"tv":1546.25,"id":13181195}],"tv":1606.1}]}
{"op":"mcm","clk":"1007637210","pt":1580656255890,"mc":[{"id":"1.168237984","rc":[{"trd":[[1.35,659.11]],"batl":[[0,1.35,132.64],[2,1.38,112.54]],"ltp":1.35,"tv":1666.19,"id":13181195}],"tv":1726.04}]}
{"op":"mcm","clk":"1007644891","pt":1580656286917,"mc":[{"id":"1.168237984","rc":[{"batb":[[1,3.7,11.33]],"ltp":3.6,"tv":59.85,"id":14833204},{"trd":[[1.35,747.06]],"batb":[[2,1.28,92.07]],"batl":[[0,1.35,88.68],[1,1.36,420.1],[2,1.37,422.25]],"ltp":1.35,"tv":1754.14,"id":13181195}],"tv":1813.99}]}
{"op":"mcm","clk":"1007683280","pt":1580656449796,"mc":[{"id":"1.168237984","rc":[{"batb":[[0,1.32,857.84],[1,1.31,230.47],[2,1.29,2]],"ltp":1.35,"tv":1754.14,"id":13181195}]}]}
{"op":"mcm","clk":"1007683574","pt":1580656450991,"mc":[{"id":"1.168237984","rc":[{"batb":[[0,3.75,27.42],[1,3.7,11.35]],"batl":[[0,4.4,2.04],[1,6.8,153.72],[2,95,15.9]],"ltp":3.6,"tv":59.85,"id":14833204},{"trd":[[1.35,813.03]],"batb":[[2,1.3,2.08]],"batl":[[0,1.35,55.72]],"ltp":1.35,"tv":1820.11,"id":13181195}],"tv":1879.96}]}
{"op":"mcm","clk":"1007683596","pt":1580656451102,"mc":[{"id":"1.168237984","rc":[{"batl":[[1,4.5,2.01],[2,6.8,153.72]],"ltp":3.6,"tv":59.85,"id":14833204}]}]}
{"op":"mcm","clk":"1007686673","pt":1580656463944,"mc":[{"id":"1.168237984","rc":[{"batb":[[1,3.7,9.33]],"batl":[[1,6.8,153.72],[2,95,15.9]],"ltp":3.6,"tv":59.85,"id":14833204},{"batb":[[1,1.31,944.64]],"ltp":1.35,"tv":1820.11,"id":13181195}]}]}
{"op":"mcm","clk":"1007686715","pt":1580656464152,"mc":[{"id":"1.168237984","rc":[{"batb":[[1,3.7,11.35]],"batl":[[1,4.5,2.01],[2,6.8,153.72]],"ltp":3.6,"tv":59.85,"id":14833204}]}]}
{"op":"mcm","clk":"1007687065","pt":1580656465725,"mc":[{"id":"1.168237984","rc":[{"batb":[[2,1.3,758.26]],"ltp":1.35,"tv":1820.11,"id":13181195}]}]}
{"op":"mcm","clk":"1007687369","pt":1580656467036,"mc":[{"id":"1.168237984","rc":[{"batb":[[0,1.33,109.81],[1,1.32,857.84],[2,1.31,716.25]],"ltp":1.35,"tv":1820.11,"id":13181195}]}]}
{"op":"mcm","clk":"1007687609","pt":1580656467931,"mc":[{"id":"1.168237984","rc":[{"batl":[[0,4.3,2.05],[1,4.4,2.04],[2,4.5,2.01]],"ltp":3.6,"tv":59.85,"id":14833204}]}]}
{"op":"mcm","clk":"1007687689","pt":1580656468245,"mc":[{"id":"1.168237984","rc":[{"trd":[[1.35,863]],"batl":[[0,1.35,30.74]],"ltp":1.35,"tv":1870.09,"id":13181195}],"tv":1929.94}]}
{"op":"mcm","clk":"1007706285","pt":1580656546954,"mc":[{"id":"1.168237984","rc":[{"trd":[[1.33,219.64]],"batb":[[0,1.32,857.84],[1,1.31,716.25],[2,1.3,758.26]],"batl":[[0,1.33,598.55],[1,1.35,30.74],[2,1.36,420.1]],"ltp":1.33,"tv":2089.72,"id":13181195}],"tv":2149.58}]}
{"op":"mcm","clk":"1007706517","pt":1580656547945,"mc":[{"id":"1.168237984","rc":[{"batb":[[0,3.9,2.06],[1,3.85,2.17],[2,3.8,46.35]],"batl":[[0,4.4,2.04],[1,4.5,2.01],[2,6.8,153.72]],"ltp":3.6,"tv":59.85,"id":14833204},{"trd":[[1.33,439.42]],"batb":[[0,1.32,920.45],[1,1.31,714.17]],"batl":[[0,1.33,488.65],[1,1.35,32.74],[2,1.36,422.17]],"ltp":1.33,"tv":2309.51,"id":13181195}],"tv":2369.36}]}
{"op":"mcm","clk":"1007711719","pt":1580656572943,"mc":[{"id":"1.168237984","rc":[{"batl":[[0,1.35,32.74],[1,1.36,422.17],[2,1.37,420.1]],"ltp":1.33,"tv":2309.51,"id":13181195}]}]}
{"op":"mcm","clk":"1007711950","pt":1580656573865,"mc":[{"id":"1.168237984","rc":[{"trd":[[3.9,0.18]],"batb":[[0,3.8,37.36],[1,3.75,25.39],[2,3.7,9.33]],"ltp":3.9,"tv":60.03,"id":14833204},{"trd":[[1.35,925.04]],"batl":[[0,1.36,420.1],[1,1.37,420.1],[2,1.38,112.54]],"ltp":1.35,"tv":2371.55,"id":13181195}],"tv":2431.58}]}
{"op":"mcm","clk":"1007717211","pt":1580656598026,"mc":[{"id":"1.168237984","rc":[{"trd":[[1.32,1439.17]],"batb":[[0,1.32,200.9]],"ltp":1.32,"tv":3810.72,"id":13181195}],"tv":3870.75}]}
{"op":"mcm","clk":"1007717440","pt":1580656599010,"mc":[{"id":"1.168237984","rc":[{"trd":[[3.8,72.42]],"batb":[[0,3.75,25.39],[1,3.65,9.51],[2,3.6,3.8]],"ltp":3.8,"tv":132.45,"id":14833204},{"batb":[[0,1.33,103.47],[1,1.32,200.9],[2,1.31,714.17]],"ltp":1.32,"tv":3810.72,"id":13181195}],"tv":3943.17}]}
{"op":"mcm","clk":"1007717649","pt":1580656599835,"mc":[{"id":"1.168237984","rc":[{"batl":[[0,4.3,2.05],[1,4.4,2.04],[2,4.5,2.01]],"ltp":3.8,"tv":132.45,"id":14833204},{"batb":[[2,1.31,716.25]],"ltp":1.32,"tv":3810.72,"id":13181195}]}]}
{"op":"mcm","clk":"1007717949","pt":1580656601032,"mc":[{"id":"1.168237984","rc":[{"batl":[[0,1.35,74.21],[1,1.36,420.1],[2,1.37,420.1]],"ltp":1.32,"tv":3810.72,"id":13181195}]}]}
{"op":"mcm","clk":"1007718224","pt":1580656601915,"mc":[{"id":"1.168237984","rc":[{"batb":[[1,3.7,9.33],[2,3.65,9.51]],"ltp":3.8,"tv":132.45,"id":14833204},{"batl":[[2,1.37,422.33]],"ltp":1.32,"tv":3810.72,"id":13181195}]}]}
{"op":"mcm","clk":"1007718413","pt":1580656602839,"mc":[{"id":"1.168237984","marketDefinition":{"bspMarket":false,"turnInPlayEnabled":true,"persistenceEnabled":true,"marketBaseRate":5.0,"eventId":"29681871","eventTypeId":"2","numberOfWinners":1,"bettingType":"ODDS","marketType":"MATCH_ODDS","marketTime":"2020-02-02T15:20:00.000Z","suspendTime":"2020-02-02T15:20:00.000Z","bspReconciled":false,"complete":true,"inPlay":false,"crossMatching":true,"runnersVoidable":false,"numberOfActiveRunners":2,"betDelay":0,"status":"OPEN","runners":[{"status":"ACTIVE","sortPriority":1,"id":14833204,"name":"Facundo Diaz Acosta"},{"status":"ACTIVE","sortPriority":2,"id":13181195,"name":"Pedro Martinez"}],"regulators":["MR_INT"],"countryCode":"AR","discountAllowed":true,"timezone":"UTC","openDate":"2020-02-02T15:52:00.000Z","version":3149441885,"name":"Match Odds","eventName":"Diaz Acosta v Martinez"}}]}
{"op":"mcm","clk":"1007718966","pt":1580656604846,"mc":[{"id":"1.168237984","marketDefinition":{"bspMarket":false,"turnInPlayEnabled":true,"persistenceEnabled":true,"marketBaseRate":5.0,"eventId":"29681871","eventTypeId":"2","numberOfWinners":1,"bettingType":"ODDS","marketType":"MATCH_ODDS","marketTime":"2020-02-02T15:20:00.000Z","suspendTime":"2020-02-02T15:20:00.000Z","bspReconciled":false,"complete":true,"inPlay":false,"crossMatching":true,"runnersVoidable":false,"numberOfActiveRunners":2,"betDelay":0,"status":"OPEN","runners":[{"status":"ACTIVE","sortPriority":1,"id":14833204,"name":"Facundo Diaz Acosta"},{"status":"ACTIVE","sortPriority":2,"id":13181195,"name":"Pedro Martinez"}],"regulators":["MR_INT"],"countryCode":"AR","discountAllowed":true,"timezone":"UTC","openDate":"2020-02-02T15:20:00.000Z","version":3149441885,"name":"Match Odds","eventName":"Diaz Acosta v Martinez"}}]}
{"op":"mcm","clk":"1007736078","pt":1580656676037,"mc":[{"id":"1.168237984","rc":[{"batb":[[1,3.65,11.53],[2,3.6,5.84]],"batl":[[2,6.8,153.72]],"ltp":3.8,"tv":132.45,"id":14833204},{"trd":[[1.33,604.07],[1.35,1070.01]],"batb":[[0,1.33,21.15]],"batl":[[0,1.35,1.73],[2,1.37,420.1]],"ltp":1.35,"tv":4120.33,"id":13181195}],"tv":4252.78}]}
{"op":"mcm","clk":"1007736307","pt":1580656676958,"mc":[{"id":"1.168237984","rc":[{"batb":[[0,3.8,30.1],[1,3.75,25.39],[2,3.7,11.35]],"batl":[[0,4.4,2.04],[1,4.5,2.01]],"ltp":3.8,"tv":132.45,"id":14833204},{"batb":[[0,1.32,222.1],[1,1.31,714.17],[2,1.3,758.26]],"ltp":1.35,"tv":4120.33,"id":13181195}]}]}
{"op":"mcm","clk":"1007768470","pt":1580656819614,"mc":[{"id":"1.168237984","rc":[{"batb":[[0,1.33,74.21],[1,1.32,222.1],[2,1.31,714.17]],"ltp":1.35,"tv":4120.33,"id":13181195}]}]}
{"op":"mcm","clk":"1007768723","pt":1580656820826,"mc":[{"id":"1.168237984","rc":[{"trd":[[3.8,130.04],[3.85,0.61]],"batb":[[0,3.8,1.29]],"ltp":3.8,"tv":190.68,"id":14833204},{"trd":[[1.35,1071.73]],"batl":[[0,1.36,420.1],[1,1.37,420.1],[2,1.38,110.54]],"ltp":1.35,"tv":4122.05,"id":13181195}],"tv":4312.74}]}
{"op":"mcm","clk":"1007768961","pt":1580656821927,"mc":[{"id":"1.168237984","rc":[{"batb":[[0,3.75,25.39],[1,3.7,2.02],[2,3.65,11.53]],"ltp":3.8,"tv":190.68,"id":14833204},{"batb":[[1,1.32,138.29]],"ltp":1.35,"tv":4122.05,"id":13181195}]}]}
{"op":"mcm","clk":"1007769247","pt":1580656823014,"mc":[{"id":"1.168237984","rc":[{"batb":[[2,3.65,2.02]],"ltp":3.8,"tv":190.68,"id":14833204},{"batb":[[0,1.34,50.36],[1,1.33,74.21],[2,1.32,138.29]],"ltp":1.35,"tv":4122.05,"id":13181195}]}]}
{"op":"mcm","clk":"1007771638","pt":1580656832962,"mc":[{"id":"1.168237984","rc":[{"batb":[[1,3.7,11.35]],"ltp":3.8,"tv":190.68,"id":14833204},{"batl":[[0,1.35,74.21],[1,1.36,420.1],[2,1.37,420.1]],"ltp":1.35,"tv":4122.05,"id":13181195}]}]}
{"op":"mcm","clk":"1007775086","pt":1580656847953,"mc":[{"id":"1.168237984","rc":[{"batb":[[0,3.75,34.56]],"ltp":3.8,"tv":190.68,"id":14833204},{"trd":[[1.34,578.72]],"batb":[[0,1.33,74.21],[1,1.32,138.29],[2,1.31,714.17]],"batl":[[0,1.34,872.63],[1,1.35,74.21],[2,1.36,420.1]],"ltp":1.34,"tv":4700.78,"id":13181195}],"tv":4891.46}]}
{"op":"mcm","clk":"1007775480","pt":1580656849793,"mc":[{"id":"1.168237984","rc":[{"batb":[[0,3.8,19.21],[1,3.75,34.56],[2,3.7,11.35]],"ltp":3.8,"tv":190.68,"id":14833204},{"batb":[[0,1.33,130.76]],"ltp":1.34,"tv":4700.78,"id":13181195}]}]}
{"op":"mcm","clk":"1007776373","pt":1580656853668,"mc":[{"id":"1.168237984","rc":[{"batl":[[1,1.35,494.31]],"ltp":1.34,"tv":4700.78,"id":13181195}]}]}
{"op":"mcm","clk":"1007780099","pt":1580656869901,"mc":[{"id":"1.168237984","rc":[{"batb":[[2,3.7,9.33]],"batl":[[0,6.8,153.72],[1,95,15.9],[2,990,2.2]],"ltp":3.8,"tv":190.68,"id":14833204},{"trd":[[1.34,1148.73]],"batb":[[1,1.32,566.79]],"batl":[[0,1.34,587.62]],"ltp":1.34,"tv":5270.78,"id":13181195}],"tv":5461.46}]}
{"op":"mcm","clk":"1007786256","pt":1580656898010,"mc":[{"id":"1.168237984","rc":[{"batb":[[0,3.8,71.29]],"ltp":3.8,"tv":190.68,"id":14833204},{"trd":[[1.34,1838.73]],"batb":[[2,1.31,996.71]],"batl":[[0,1.34,242.62]],"ltp":1.34,"tv":5960.78,"id":13181195}],"tv":6151.46}]}
{"op":"mcm","clk":"1007788051","pt":1580656905837,"mc":[{"id":"1.168237984","rc":[{"batb":[[2,1.31,714.17]],"ltp":1.34,"tv":5960.78,"id":13181195}]}]}
{"op":"mcm","clk":"1007790359","pt":1580656915738,"mc":[{"id":"1.168237984","rc":[{"batb":[[0,3.8,70.66]],"ltp":3.8,"tv":190.68,"id":14833204}]}]}
{"op":"mcm","clk":"1007790445","pt":1580656916172,"mc":[{"id":"1.168237984","rc":[{"trd":[[1.34,2313.99]],"batl":[[0,1.34,4.99]],"ltp":1.34,"tv":6436.04,"id":13181195}],"tv":6626.73}]}
{"op":"mcm","clk":"1007790637","pt":1580656917079,"mc":[{"id":"1.168237984","rc":[{"batb":[[1,3.75,25.39]],"ltp":3.8,"tv":190.68,"id":14833204}]}]}
{"op":"mcm","clk":"1007791461","pt":1580656920741,"mc":[{"id":"1.168237984","rc":[{"batb":[[0,1.33,525.65]],"ltp":1.34,"tv":6436.04,"id":13181195}]}]}
{"op":"mcm","clk":"1007791969","pt":1580656923067,"mc":[{"id":"1.168237984","rc":[{"trd":[[3.85,24.87],[3.9,1.89]],"ltp":3.85,"tv":216.65,"id":14833204},{"trd":[[1.34,2318.98],[1.35,1140.92]],"batl":[[0,1.35,425.12],[1,1.36,420.1],[2,1.37,420.1]],"ltp":1.35,"tv":6510.22,"id":13181195}],"tv":6726.88}]}
{"op":"mcm","clk":"1007793959","pt":1580656931920,"mc":[{"id":"1.168237984","rc":[{"trd":[[1.34,2420.34]],"batb":[[0,1.34,23.5],[1,1.33,525.65],[2,1.32,566.79]],"ltp":1.34,"tv":6611.58,"id":13181195}],"tv":6828.23}]}
{"op":"mcm","clk":"1007794162","pt":1580656932918,"mc":[{"id":"1.168237984","rc":[{"trd":[[1.34,2430.29]],"batb":[[0,1.34,18.53]],"ltp":1.34,"tv":6621.53,"id":13181195}],"tv":6838.18}]}
{"op":"mcm","clk":"1007794285","pt":1580656933503,"mc":[{"id":"1.168237984","rc":[{"batb":[[1,1.33,770.15]],"ltp":1.34,"tv":6621.53,"id":13181195}]}]}
{"op":"mcm","clk":"1007794610","pt":1580656935020,"mc":[{"id":"1.168237984","rc":[{"batb":[[2,3.65,9.51]],"ltp":3.85,"tv":216.65,"id":14833204},{"trd":[[1.35,1975.74]],"batl":[[0,1.35,7.7]],"ltp":1.35,"tv":7456.35,"id":13181195}],"tv":7673.0}]}
{"op":"mcm","clk":"1007796067","pt":1580656941443,"mc":[{"id":"1.168237984","rc":[{"batl":[[0,1.35,233.36]],"ltp":1.35,"tv":7456.35,"id":13181195}]}]}
{"op":"mcm","clk":"1007796193","pt":1580656942048,"mc":[{"id":"1.168237984","rc":[{"batb":[[2,3.7,9.33]],"ltp":3.85,"tv":216.65,"id":14833204}]}]}
{"op":"mcm","clk":"1007797936","pt":1580656949648,"mc":[{"id":"1.168237984","rc":[{"batl":[[0,1.35,415.68]],"ltp":1.35,"tv":7456.35,"id":13181195}]}]}
{"op":"mcm","clk":"1007802488","pt":1580656970518,"mc":[{"id":"1.168237984","rc":[{"batb":[[0,3.85,13.1],[1,3.8,70.66]],"ltp":3.85,"tv":216.65,"id":14833204}]}]}
{"op":"mcm","clk":"1007802641","pt":1580656971116,"mc":[{"id":"1.168237984","rc":[{"trd":[[1.35,2625.74]],"batl":[[0,1.35,90.68]],"ltp":1.35,"tv":8106.35,"id":13181195}],"tv":8323.0}]}
{"op":"mcm","clk":"1007808116","pt":1580656994891,"mc":[{"id":"1.168237984","rc":[{"trd":[[1.34,2430.32]],"batb":[[0,1.34,534.39]],"ltp":1.34,"tv":8106.38,"id":13181195}],"tv":8323.03}]}
{"op":"mcm","clk":"1007808388","pt":1580656996005,"mc":[{"id":"1.168237984","rc":[{"trd":[[1.35,2745.74]],"batl":[[0,1.35,30.68]],"ltp":1.35,"tv":8226.38,"id":13181195}],"tv":8443.03}]}
{"op":"mcm","clk":"1007819739","pt":1580657045104,"mc":[{"id":"1.168237984","rc":[{"batb":[[0,1.34,760.05]],"ltp":1.35,"tv":8226.38,"id":13181195}]}]}
{"op":"mcm","clk":"1007825211","pt":1580657070041,"mc":[{"id":"1.168237984","rc":[{"trd":[[1.35,2745.99]],"batl":[[0,1.35,30.56]],"ltp":1.35,"tv":8226.63,"id":13181195}],"tv":8443.28}]}
{"op":"mcm","clk":"1007827260","pt":1580657078803,"mc":[{"id":"1.168237984","rc":[{"batl":[[0,1.35,100.98]],"ltp":1.35,"tv":8226.63,"id":13181195}]}]}
{"op":"mcm","clk":"1007829203","pt":1580657087273,"mc":[{"id":"1.168237984","rc":[{"batb":[[0,1.34,760.06]],"ltp":1.35,"tv":8226.63,"id":13181195}]}]}
{"op":"mcm","clk":"1007830906","pt":1580657095077,"mc":[{"id":"1.168237984","rc":[{"batb":[[0,1.34,820.56]],"ltp":1.35,"tv":8226.63,"id":13181195}]}]}
{"op":"mcm","clk":"1007841208","pt":1580657143230,"mc":[{"id":"1.168237984","rc":[{"trd":[[1.35,2799.04]],"batl":[[0,1.35,74.46]],"ltp":1.35,"tv":8279.67,"id":13181195}],"tv":8496.33}]}
{"op":"mcm","clk":"1007845157","pt":1580657161042,"mc":[{"id":"1.168237984","rc":[{"trd":[[3.85,77.18]],"batb":[[0,3.8,70.66],[1,3.7,9.33],[2,3.65,9.51]],"batl":[[0,3.85,393.7],[1,6.8,153.72],[2,95,15.9]],"ltp":3.85,"tv":268.96,"id":14833204},{"trd":[[1.35,2873.49]],"batl":[[0,1.36,420.1],[1,1.37,420.1],[2,1.38,110.54]],"ltp":1.35,"tv":8354.13,"id":13181195}],"tv":8623.09}]}
{"op":"mcm","clk":"1007845182","pt":1580657161203,"mc":[{"id":"1.168237984","rc":[{"batb":[[1,3.65,9.51],[2,3.6,13.49]],"ltp":3.85,"tv":268.96,"id":14833204},{"batb":[[0,1.34,858.23]],"ltp":1.35,"tv":8354.13,"id":13181195}]}]}
{"op":"mcm","clk":"1007847323","pt":1580657170773,"mc":[{"id":"1.168237984","rc":[{"batb":[[0,1.34,928.66]],"ltp":1.35,"tv":8354.13,"id":13181195}]}]}
{"op":"mcm","clk":"1007871670","pt":1580657274678,"mc":[{"id":"1.168237984","rc":[{"trd":[[3.8,271.37]],"batb":[[0,3.65,9.51],[1,3.6,13.49],[2,3.5,10.08]],"batl":[[0,3.8,323.03]],"ltp":3.8,"tv":410.29,"id":14833204}],"tv":8764.42}]}
{"op":"mcm","clk":"1007871872","pt":1580657275659,"mc":[{"id":"1.168237984","rc":[{"trd":[[3.8,376.02]],"batb":[[0,3.65,37.77]],"batl":[[0,3.8,270.71]],"ltp":3.8,"tv":514.93,"id":14833204},{"batb":[[0,1.35,37.33],[1,1.34,928.66],[2,1.33,713.6]],"ltp":1.35,"tv":8354.13,"id":13181195}],"tv":8869.07}]}
{"op":"mcm","clk":"1007874221","pt":1580657285809,"mc":[{"id":"1.168237984","rc":[{"trd":[[3.75,260]],"batl":[[0,3.75,64.53]],"ltp":3.75,"tv":774.94,"id":14833204},{"trd":[[1.36,550.32]],"batb":[[2,1.33,989.61]],"batl":[[0,1.37,420.1],[1,1.38,110.54],[2,1.39,376.17]],"ltp":1.36,"tv":8774.23,"id":13181195}],"tv":9549.17}]}
{"op":"mcm","clk":"1007874292","pt":1580657286084,"mc":[{"id":"1.168237984","rc":[{"batb":[[1,3.6,3.8],[2,3.55,9.88]],"ltp":3.75,"tv":774.94,"id":14833204}]}]}
{"op":"mcm","clk":"1007876473","pt":1580657295612,"mc":[{"id":"1.168237984","rc":[{"batb":[[0,3.7,55.47],[1,3.65,37.77],[2,3.6,3.8]],"ltp":3.75,"tv":774.94,"id":14833204},{"batb":[[2,1.33,983.87]],"ltp":1.36,"tv":8774.23,"id":13181195}]}]}
{"op":"mcm","clk":"1007878506","pt":1580657303954,"mc":[{"id":"1.168237984","rc":[{"batl":[[0,1.37,699.88]],"ltp":1.36,"tv":8774.23,"id":13181195}]}]}
{"op":"mcm","clk":"1007878677","pt":1580657304603,"mc":[{"id":"1.168237984","rc":[{"trd":[[3.75,382.54]],"batl":[[0,3.75,3.26]],"ltp":3.75,"tv":897.47,"id":14833204}],"tv":9671.71}]}
{"op":"mcm","clk":"1007879177","pt":1580657306898,"mc":[{"id":"1.168237984","rc":[{"trd":[[3.75,385.8]],"batl":[[0,6.8,153.72],[1,95,15.9],[2,990,2.2]],"ltp":3.75,"tv":900.73,"id":14833204},{"trd":[[1.36,559.29]],"batl":[[0,1.36,65.24],[1,1.37,699.88],[2,1.38,110.54]],"ltp":1.36,"tv":8783.2,"id":13181195}],"tv":9683.93}]}
{"op":"mcm","clk":"1007879455","pt":1580657308159,"mc":[{"id":"1.168237984","rc":[{"batb":[[2,3.6,13.49]],"ltp":3.75,"tv":900.73,"id":14833204}]}]}
{"op":"mcm","clk":"1007880393","pt":1580657312347,"mc":[{"id":"1.168237984","rc":[{"batb":[[0,1.35,459.95]],"ltp":1.36,"tv":8783.2,"id":13181195}]}]}
{"op":"mcm","clk":"1007882440","pt":1580657320921,"mc":[{"id":"1.168237984","rc":[{"batl":[[0,1.36,362.07]],"ltp":1.36,"tv":8783.2,"id":13181195}]}]}
{"op":"mcm","clk":"1007888709","pt":1580657347882,"mc":[{"id":"1.168237984","rc":[{"batb":[[0,3.75,12.19],[1,3.7,55.47]],"ltp":3.75,"tv":900.73,"id":14833204}]}]}
{"op":"mcm","clk":"1007901742","pt":1580657407794,"mc":[{"id":"1.168237984","rc":[{"trd":[[1.35,2873.51]],"batb":[[0,1.35,459.94]],"ltp":1.35,"tv":8783.22,"id":13181195}],"tv":9683.95}]}
{"op":"mcm","clk":"1007954756","pt":1580657643024,"mc":[{"id":"1.168237984","rc":[{"batb":[[0,1.35,468.38]],"ltp":1.35,"tv":8783.22,"id":13181195}]}]}
{"op":"mcm","clk":"1007987825","pt":1580657793857,"mc":[{"id":"1.168237984","rc":[{"trd":[[1.35,2873.87]],"batb":[[0,1.35,468.21]],"ltp":1.35,"tv":8783.58,"id":13181195}],"tv":9684.31}]}
{"op":"mcm","clk":"1007994991","pt":1580657827391,"mc":[{"id":"1.168237984","rc":[{"batl":[[0,3.9,16.8],[1,6.8,153.72],[2,95,15.9]],"ltp":3.75,"tv":900.73,"id":14833204}]}]}
{"op":"mcm","clk":"1007995430","pt":1580657828984,"mc":[{"id":"1.168237984","rc":[{"trd":[[1.35,2909.24]],"batb":[[0,1.35,431.06]],"ltp":1.35,"tv":8818.94,"id":13181195}],"tv":9719.68}]}
{"op":"mcm","clk":"1007995452","pt":1580657829095,"mc":[{"id":"1.168237984","rc":[{"batb":[[0,3.75,18.57]],"ltp":3.75,"tv":900.73,"id":14833204},{"batb":[[1,1.34,964.98]],"ltp":1.35,"tv":8818.94,"id":13181195}]}]}
{"op":"mcm","clk":"1007996009","pt":1580657831700,"mc":[{"id":"1.168237984","rc":[{"batl":[[0,3.85,16.8]],"ltp":3.75,"tv":900.73,"id":14833204}]}]}
{"op":"mcm","clk":"1008014646","pt":1580657913806,"mc":[{"id":"1.168237984","rc":[{"batl":[[0,1.36,65.24]],"ltp":1.35,"tv":8818.94,"id":13181195}]}]}
{"op":"mcm","clk":"1008026150","pt":1580657964427,"mc":[{"id":"1.168237984","rc":[{"batl":[[0,1.36,68.24]],"ltp":1.35,"tv":8818.94,"id":13181195}]}]}
{"op":"mcm","clk":"1008030280","pt":1580657981983,"mc":[{"id":"1.168237984","rc":[{"batb":[[0,3.7,55.47],[1,3.6,13.49],[2,3.55,9.88]],"ltp":3.75,"tv":900.73,"id":14833204},{"batb":[[1,1.34,890.98]],"ltp":1.35,"tv":8818.94,"id":13181195}]}]}
{"op":"mcm","clk":"1008031570","pt":1580657987377,"mc":[{"id":"1.168237984","marketDefinition":{"bspMarket":false,"turnInPlayEnabled":true,"persistenceEnabled":true,"marketBaseRate":5.0,"eventId":"29681871","eventTypeId":"2","numberOfWinners":1,"bettingType":"ODDS","marketType":"MATCH_ODDS","marketTime":"2020-02-02T15:20:00.000Z","suspendTime":"2020-02-02T15:20:00.000Z","bspReconciled":false,"complete":true,"inPlay":false,"crossMatching":true,"runnersVoidable":false,"numberOfActiveRunners":2,"betDelay":0,"status":"OPEN","runners":[{"status":"ACTIVE","sortPriority":1,"id":14833204,"name":"Facundo Diaz Acosta"},{"status":"ACTIVE","sortPriority":2,"id":13181195,"name":"Pedro Martinez"}],"regulators":["MR_INT"],"countryCode":"AR","discountAllowed":true,"timezone":"UTC","openDate":"2020-02-02T15:20:00.000Z","version":3149466718,"name":"Match Odds","eventName":"Diaz Acosta v Martinez"},"rc":[{"batb":[[0,3.6,13.49],[1,3.55,9.88],[2,3.5,10.08]],"ltp":3.75,"tv":900.73,"id":14833204},{"batb":[[2,1.33,713.6]],"ltp":1.35,"tv":8818.94,"id":13181195}]}]}
{"op":"mcm","clk":"1008031747","pt":1580657988210,"mc":[{"id":"1.168237984","marketDefinition":{"bspMarket":false,"turnInPlayEnabled":true,"persistenceEnabled":true,"marketBaseRate":5.0,"eventId":"29681871","eventTypeId":"2","numberOfWinners":1,"bettingType":"ODDS","marketType":"MATCH_ODDS","marketTime":"2020-02-02T15:20:00.000Z","suspendTime":"2020-02-02T15:20:00.000Z","bspReconciled":false,"complete":true,"inPlay":true,"crossMatching":true,"runnersVoidable":false,"numberOfActiveRunners":2,"betDelay":3,"status":"OPEN","runners":[{"status":"ACTIVE","sortPriority":1,"id":14833204,"name":"Facundo Diaz Acosta"},{"status":"ACTIVE","sortPriority":2,"id":13181195,"name":"Pedro Martinez"}],"regulators":["MR_INT"],"countryCode":"AR","discountAllowed":true,"timezone":"UTC","openDate":"2020-02-02T15:20:00.000Z","version":3149542150,"name":"Match Odds","eventName":"Diaz Acosta v Martinez"},"rc":[{"batb":[[0,1.9,134.22],[1,1.11,37.97],[2,1.03,9]],"batl":[[1,1000,0.02],[2,95,0]],"ltp":3.75,"tv":900.73,"id":14833204},{"batb":[[0,1.35,422.62],[1,1.34,60.51],[2,1.32,138.29]],"batl":[[0,1.5,2.27],[1,1000,0.02],[2,1.38,0]],"ltp":1.35,"tv":8818.94,"id":13181195}]}]}
{"op":"mcm","clk":"1008032584","pt":1580657991626,"mc":[{"id":"1.168237984","rc":[{"batb":[[1,1.8,75.72],[2,1.11,37.97]],"ltp":3.75,"tv":900.73,"id":14833204}]}]}
{"op":"mcm","clk":"1008033384","pt":1580657994868,"mc":[{"id":"1.168237984","rc":[{"batl":[[0,3.55,311],[1,3.8,4.02],[2,3.85,16.8]],"ltp":3.75,"tv":900.73,"id":14833204},{"batl":[[0,1.46,813],[1,1.5,2.27],[2,1000,0.02]],"ltp":1.35,"tv":8818.94,"id":13181195}]}]}
{"op":"mcm","clk":"1008033549","pt":1580657995685,"mc":[{"id":"1.168237984","rc":[{"batb":[[0,3.35,69.63],[1,3.05,88.6],[2,1.9,134.22]],"batl":[[1,3.85,16.8],[2,1000,0.02]],"ltp":3.75,"tv":900.73,"id":14833204},{"batb":[[0,1.38,228.41],[1,1.35,422.62],[2,1.34,320.08]],"ltp":1.35,"tv":8818.94,"id":13181195}]}]}
{"op":"mcm","clk":"1008034221","pt":1580657998570,"mc":[{"id":"1.168237984","rc":[{"batb":[[2,2,75.72]],"ltp":3.75,"tv":900.73,"id":14833204}]}]}
{"op":"mcm","clk":"1008034417","pt":1580657999390,"mc":[{"id":"1.168237984","rc":[{"batl":[[1,1000,0.02],[2,1000,0]],"ltp":3.75,"tv":900.73,"id":14833204}]}]}
{"op":"mcm","clk":"1008034798","pt":1580658000875,"mc":[{"id":"1.168237984","rc":[{"batb":[[0,1.38,641.16],[1,1.37,386.63],[2,1.36,494.03]],"batl":[[0,1.42,497.15],[1,1.43,309.73],[2,1.46,1293.59]],"ltp":1.35,"tv":8818.94,"id":13181195}]}]}
{"op":"mcm","clk":"1008035235","pt":1580658002677,"mc":[{"id":"1.168237984","rc":[{"batl":[[0,3.5,16.8],[1,3.55,311],[2,1000,0.02]],"ltp":3.75,"tv":900.73,"id":14833204}]}]}
{"op":"mcm","clk":"1008036152","pt":1580658006586,"mc":[{"id":"1.168237984","rc":[{"trd":[[3.5,0.6]],"batl":[[0,3.5,16.2]],"ltp":3.5,"tv":901.33,"id":14833204},{"trd":[[1.4,1.51]],"ltp":1.4,"tv":8820.46,"id":13181195}],"tv":9721.8}]}
{"op":"mcm","clk":"1008036685","pt":1580658008898,"mc":[{"id":"1.168237984","rc":[{"batl":[[1,1000,0.02],[2,1000,0]],"ltp":3.5,"tv":901.33,"id":14833204},{"batl":[[2,1.46,480.59]],"ltp":1.4,"tv":8820.46,"id":13181195}]}]}
{"op":"mcm","clk":"1008036952","pt":1580658009866,"mc":[{"id":"1.168237984","rc":[{"batb":[[0,3.05,88.6],[1,2,75.72],[2,1.9,134.22]],"ltp":3.5,"tv":901.33,"id":14833204},{"batb":[[0,1.36,494.03],[1,1.35,420.1],[2,1.34,830.92]],"batl":[[0,1.46,480.59],[1,1.48,497.4],[2,1.5,2.27]],"ltp":1.4,"tv":8820.46,"id":13181195}]}]}
{"op":"mcm","clk":"1008037741","pt":1580658012881,"mc":[{"id":"1.168237984","rc":[{"batb":[[2,1.34,770.43]],"ltp":1.4,"tv":8820.46,"id":13181195}]}]}
{"op":"mcm","clk":"1008037922","pt":1580658013693,"mc":[{"id":"1.168237984","rc":[{"batb":[[1,2,76.54]],"ltp":3.5,"tv":901.33,"id":14833204},{"batb":[[0,1.42,6.06],[1,1.36,494.03],[2,1.35,420.1]],"ltp":1.4,"tv":8820.46,"id":13181195}]}]}
{"op":"mcm","clk":"1008038182","pt":1580658014892,"mc":[{"id":"1.168237984","rc":[{"batb":[[1,1.39,502.38],[2,1.38,374.6]],"batl":[[0,1.43,374.96],[1,1.44,301.86],[2,1.46,480.59]],"ltp":1.4,"tv":8820.46,"id":13181195}]}]}
{"op":"mcm","clk":"1008038851","pt":1580658017589,"mc":[{"id":"1.168237984","rc":[{"batb":[[1,1.36,494.03],[2,1.35,420.1]],"batl":[[0,1.46,480.59],[1,1.48,497.4],[2,1.5,2.27]],"ltp":1.4,"tv":8820.46,"id":13181195}]}]}
{"op":"mcm","clk":"1008039486","pt":1580658020307,"mc":[{"id":"1.168237984","rc":[{"batb":[[2,1.35,818.4]],"batl":[[2,1.49,417.55]],"ltp":1.4,"tv":8820.46,"id":13181195}]}]}
{"op":"mcm","clk":"1008040847","pt":1580658026008,"mc":[{"id":"1.168237984","rc":[{"batl":[[2,1.5,2.27]],"ltp":1.4,"tv":8820.46,"id":13181195}]}]}
{"op":"mcm","clk":"1008040873","pt":1580658026116,"mc":[{"id":"1.168237984","rc":[{"batb":[[1,1.35,818.4],[2,1.34,812.14]],"ltp":1.4,"tv":8820.46,"id":13181195}]}]}
{"op":"mcm","clk":"1008041658","pt":1580658028990,"mc":[{"id":"1.168237984","rc":[{"trd":[[3.5,16.8]],"batl":[[0,3.85,286.51]],"ltp":3.5,"tv":917.53,"id":14833204},{"trd":[[1.4,42.01],[1.42,12.12]],"batb":[[0,1.35,818.4],[1,1.34,3225.02],[2,1.33,449.16]],"batl":[[0,1.37,1607.09],[1,1.38,545.82],[2,1.39,1143.83]],"ltp":1.4,"tv":8873.07,"id":13181195}],"tv":9790.61}]}
{"op":"mcm","clk":"1008041909","pt":1580658030024,"mc":[{"id":"1.168237984","rc":[{"batb":[[0,3.6,58.62],[1,3.25,74.75],[2,3.05,88.6]],"ltp":3.5,"tv":917.53,"id":14833204}]}]}
{"op":"mcm","clk":"1008041953","pt":1580658030192,"mc":[{"id":"1.168237984","rc":[{"batb":[[2,2,76.54]],"ltp":3.5,"tv":917.53,"id":14833204}]}]}
{"op":"mcm","clk":"1008042541","pt":1580658032518,"mc":[{"id":"1.168237984","rc":[{"batb":[[2,2.6,22.62]],"ltp":3.5,"tv":917.53,"id":14833204}]}]}
{"op":"mcm","clk":"1008043476","pt":1580658036232,"mc":[{"id":"1.168237984","rc":[{"batb":[[2,1.33,617.2]],"ltp":1.4,"tv":8873.07,"id":13181195}]}]}
{"op":"mcm","clk":"1008044305","pt":1580658039531,"mc":[{"id":"1.168237984","rc":[{"batb":[[0,1.35,420.1]],"ltp":1.4,"tv":8873.07,"id":13181195}]}]}
{"op":"mcm","clk":"1008046068","pt":1580658046831,"mc":[{"id":"1.168237984","rc":[{"batl":[[0,1000,0.02],[1,1000,0]],"ltp":3.5,"tv":917.53,"id":14833204},{"batb":[[1,1.34,812.14]],"batl":[[0,1.38,545.82],[1,1.39,350.2],[2,1.4,480.59]],"ltp":1.4,"tv":8873.07,"id":13181195}]}]}
{"op":"mcm","clk":"1008046192","pt":1580658047328,"mc":[{"id":"1.168237984","rc":[{"batb":[[0,3.25,74.75],[1,2.6,22.62],[2,2,75.72]],"ltp":3.5,"tv":917.53,"id":14833204},{"batb":[[1,1.33,168.05],[2,1.32,1030.38]],"batl":[[0,1.4,480.59],[1,1.42,497.4],[2,1.5,2.27]],"ltp":1.4,"tv":8873.07,"id":13181195}]}]}
{"op":"mcm","clk":"1008046920","pt":1580658050139,"mc":[{"id":"1.168237984","rc":[{"batl":[[2,1.44,406.74]],"ltp":1.4,"tv":8873.07,"id":13181195}]}]}
{"op":"mcm","clk":"1008048299","pt":1580658055728,"mc":[{"id":"1.168237984","rc":[{"batl":[[0,1.44,406.74],[1,1.45,292.92],[2,1.5,2.27]],"ltp":1.4,"tv":8873.07,"id":13181195}]}]}
{"op":"mcm","clk":"1008048544","pt":1580658056744,"mc":[{"id":"1.168237984","rc":[{"batb":[[0,1.33,168.05],[1,1.32,1030.38],[2,1.31,297.26]],"batl":[[0,1.44,407.62]],"ltp":1.4,"tv":8873.07,"id":13181195}]}]}
{"op":"mcm","clk":"1008048834","pt":1580658057941,"mc":[{"id":"1.168237984","rc":[{"batl":[[0,1.39,3],[1,1.44,407.62],[2,1.45,292.92]],"ltp":1.4,"tv":8873.07,"id":13181195}]}]}
{"op":"mcm","clk":"1008048973","pt":1580658058638,"mc":[{"id":"1.168237984","rc":[{"trd":[[3.5,17.15],[3.55,18.37]],"batb":[[1,3.15,352.12],[2,2.6,22.62]],"batl":[[0,3.4,317],[1,3.5,159.38],[2,1000,0.02]],"ltp":3.5,"tv":919.05,"id":14833204},{"trd":[[1.39,46.93],[1.4,42.9]],"batb":[[0,1.42,15.61],[1,1.4,2434.67],[2,1.39,361.44]],"batl":[[0,1.44,1980.81],[1,1.45,292.92],[2,1.49,871]],"ltp":1.4,"tv":8876.96,"id":13181195}],"tv":9796.02}]}
{"op":"mcm","clk":"1008049231","pt":1580658059833,"mc":[{"id":"1.168237984","rc":[{"batb":[[2,2.94,98.82]],"ltp":3.5,"tv":919.05,"id":14833204},{"batb":[[1,1.4,2651.36]],"ltp":1.4,"tv":8876.96,"id":13181195}]}]}
{"op":"mcm","clk":"1008050320","pt":1580658064774,"mc":[{"id":"1.168237984","rc":[{"batb":[[2,1.39,855.47]],"batl":[[2,1.47,480.59]],"ltp":1.4,"tv":8876.96,"id":13181195}]}]}
{"op":"mcm","clk":"1008050782","pt":1580658066738,"mc":[{"id":"1.168237984","rc":[{"batb":[[0,3.3,3.8],[1,3.25,74.75],[2,3.15,352.12]],"ltp":3.5,"tv":919.05,"id":14833204}]}]}
{"op":"mcm","clk":"1008051498","pt":1580658069971,"mc":[{"id":"1.168237984","rc":[{"batl":[[2,4.1,2.05]],"ltp":3.5,"tv":919.05,"id":14833204}]}]}
{"op":"mcm","clk":"1008051677","pt":1580658070777,"mc":[{"id":"1.168237984","rc":[{"batl":[[2,3.95,2.1]],"ltp":3.5,"tv":919.05,"id":14833204}]}]}
{"op":"mcm","clk":"1008052591","pt":1580658074671,"mc":[{"id":"1.168237984","rc":[{"batb":[[0,3.25,74.75],[1,3.15,352.12],[2,2.94,98.82]],"ltp":3.5,"tv":919.05,"id":14833204}]}]}
{"op":"mcm","clk":"1008053249","pt":1580658077888,"mc":[{"id":"1.168237984","rc":[{"batb":[[2,3.05,3.8]],"ltp":3.5,"tv":919.05,"id":14833204}]}]}
{"op":"mcm","clk":"1008053901","pt":1580658080790,"mc":[{"id":"1.168237984","rc":[{"batb":[[1,3.05,3.8],[2,2.94,98.82]],"batl":[[0,3.95,2.1],[1,4.1,2.05],[2,1000,0.02]],"ltp":3.5,"tv":919.05,"id":14833204},{"batb":[[0,1.4,645.78],[1,1.39,855.47],[2,1.37,510.84]],"batl":[[0,1.44,406.74]],"ltp":1.4,"tv":8876.96,"id":13181195}]}]}
{"op":"mcm","clk":"1008053977","pt":1580658081116,"mc":[{"id":"1.168237984","rc":[{"batb":[[0,3.05,3.8],[1,2.94,98.82],[2,2.6,22.62]],"batl":[[0,1000,0.02],[1,4.1,0],[2,1000,0]],"ltp":3.5,"tv":919.05,"id":14833204},{"batb":[[0,1.39,494.03],[1,1.37,510.84],[2,1.35,660.34]],"batl":[[0,1.47,480.59],[1,1.49,497.4],[2,1.5,2.27]],"ltp":1.4,"tv":8876.96,"id":13181195}]}]}
{"op":"mcm","clk":"1008054303","pt":1580658082570,"mc":[{"id":"1.168237984","rc":[{"batb":[[1,2.96,3.13],[2,2.94,98.82]],"ltp":3.5,"tv":919.05,"id":14833204}]}]}
{"op":"mcm","clk":"1008054702","pt":1580658084291,"mc":[{"id":"1.168237984","rc":[{"batl":[[0,4.1,2.15],[1,1000,0.02]],"ltp":3.5,"tv":919.05,"id":14833204},{"batb":[[2,1.35,1229.6]],"ltp":1.4,"tv":8876.96,"id":13181195}]}]}
{"op":"mcm","clk":"1008054957","pt":1580658085368,"mc":[{"id":"1.168237984","rc":[{"batb":[[2,1.35,660.34]],"ltp":1.4,"tv":8876.96,"id":13181195}]}]}
{"op":"mcm","clk":"1008055707","pt":1580658088783,"mc":[{"id":"1.168237984","rc":[{"batb":[[0,1.42,286.78],[1,1.41,337.34],[2,1.39,494.03]],"batl":[[0,1.46,472.58],[1,1.47,756.86],[2,1.49,497.4]],"ltp":1.4,"tv":8876.96,"id":13181195}]}]}
{"op":"mcm","clk":"1008055914","pt":1580658089803,"mc":[{"id":"1.168237984","rc":[{"batb":[[0,1.39,494.03],[1,1.37,510.84],[2,1.35,660.34]],"batl":[[0,1.47,480.59],[1,1.49,497.4],[2,1.5,2.27]],"ltp":1.4,"tv":8876.96,"id":13181195}]}]}
{"op":"mcm","clk":"1008056576","pt":1580658092680,"mc":[{"id":"1.168237984","rc":[{"batb":[[2,1.35,1229.6]],"ltp":1.4,"tv":8876.96,"id":13181195}]}]}
{"op":"mcm","clk":"1008057753","pt":1580658098012,"mc":[{"id":"1.168237984","rc":[{"batb":[[2,1.35,660.34]],"batl":[[0,1.5,2.27],[1,1.51,38.5],[2,1.53,37.5]],"ltp":1.4,"tv":8876.96,"id":13181195}]}]}
{"op":"mcm","clk":"1008057819","pt":1580658098275,"mc":[{"id":"1.168237984","rc":[{"batb":[[1,2.94,98.82],[2,2.84,3.22]],"ltp":3.5,"tv":919.05,"id":14833204},{"batl":[[1,1.53,37.5],[2,1.54,32.75]],"ltp":1.4,"tv":8876.96,"id":13181195}]}]}
{"op":"mcm","clk":"1008058472","pt":1580658101006,"mc":[{"id":"1.168237984","rc":[{"trd":[[2.94,197.64],[3,1.14],[3.05,7.6]],"batb":[[0,2.84,9.58],[1,2.6,22.62],[2,1.9,134.22]],"batl":[[0,2.92,5.96],[1,2.94,542.1],[2,3.05,437.99]],"ltp":2.94,"tv":1125.44,"id":14833204},{"trd":[[1.5,2.27]],"batb":[[0,1.49,225.62],[1,1.48,273.59],[2,1.39,494.03]],"batl":[[0,1.53,341.06],[1,1.54,263.63],[2,1.58,842]],"ltp":1.5,"tv":8879.23,"id":13181195}],"tv":10004.67}]}
{"op":"mcm","clk":"1008058687","pt":1580658101882,"mc":[{"id":"1.168237984","rc":[{"batb":[[1,2.7,49.33],[2,2.6,22.62]],"ltp":2.94,"tv":1125.44,"id":14833204},{"batb":[[2,1.47,174.6]],"ltp":1.5,"tv":8879.23,"id":13181195}]}]}
{"op":"mcm","clk":"1008060071","pt":1580658107714,"mc":[{"id":"1.168237984","rc":[{"batb":[[0,1.51,494.03],[1,1.49,736.46],[2,1.48,273.59]],"ltp":1.5,"tv":8879.23,"id":13181195}]}]}
{"op":"mcm","clk":"1008063391","pt":1580658121965,"mc":[{"id":"1.168237984","rc":[{"batl":[[1,2.94,255.1]],"ltp":2.94,"tv":1125.44,"id":14833204}]}]}
{"op":"mcm","clk":"1008063593","pt":1580658122878,"mc":[{"id":"1.168237984","rc":[{"batb":[[0,2.7,49.33],[1,2.6,22.62],[2,2.46,4.38]],"batl":[[0,3.3,2.35],[1,3.45,2.5],[2,4.1,2.15]],"ltp":2.94,"tv":1125.44,"id":14833204},{"batb":[[1,1.49,510.84],[2,1.44,40.17]],"batl":[[0,1.68,25.89],[1,1000,0.02],[2,1.58,0]],"ltp":1.5,"tv":8879.23,"id":13181195}]}]}
{"op":"mcm","clk":"1008064303","pt":1580658125874,"mc":[{"id":"1.168237984","rc":[{"batb":[[0,2.64,51.85]],"ltp":2.94,"tv":1125.44,"id":14833204},{"batl":[[0,1.63,296.42],[1,1.64,208.28],[2,1.68,25.89]],"ltp":1.5,"tv":8879.23,"id":13181195}]}]}
{"op":"mcm","clk":"1008064350","pt":1580658126080,"mc":[{"id":"1.168237984","rc":[{"batb":[[2,2.56,3.83]],"ltp":2.94,"tv":1125.44,"id":14833204}]}]}
{"op":"mcm","clk":"1008065453","pt":1580658130659,"mc":[{"id":"1.168237984","rc":[{"batl":[[2,1000,0.02]],"ltp":2.94,"tv":1125.44,"id":14833204}]}]}
{"op":"mcm","clk":"1008065859","pt":1580658132394,"mc":[{"id":"1.168237984","rc":[{"trd":[[1.51,3.36]],"batb":[[0,1.51,492.35]],"ltp":1.51,"tv":8882.59,"id":13181195}],"tv":10008.03}]}
{"op":"mcm","clk":"1008066094","pt":1580658133412,"mc":[{"id":"1.168237984","rc":[{"trd":[[2.58,5.47],[2.6,45.23],[2.64,103.7]],"batb":[[0,2.56,3.83],[1,2.5,7.46],[2,2.46,4.38]],"batl":[[0,2.6,249.54],[1,2.66,649.58],[2,2.82,71.33]],"ltp":2.58,"tv":1279.84,"id":14833204},{"trd":[[1.63,8.66]],"batb":[[0,1.58,290.31],[1,1.57,217.05],[2,1.51,492.35]],"batl":[[0,1.63,287.76]],"ltp":1.63,"tv":8891.25,"id":13181195}],"tv":10171.09}]}
{"op":"mcm","clk":"1008066352","pt":1580658134596,"mc":[{"id":"1.168237984","rc":[{"batb":[[2,2.48,61.29]],"ltp":2.58,"tv":1279.84,"id":14833204},{"batb":[[2,1.56,138.64]],"ltp":1.63,"tv":8891.25,"id":13181195}]}]}
{"op":"mcm","clk":"1008068341","pt":1580658143006,"mc":[{"id":"1.168237984","rc":[{"trd":[[2.6,218.73]],"batb":[[2,2.46,67.4]],"batl":[[0,2.6,162.79]],"ltp":2.6,"tv":1453.34,"id":14833204},{"batb":[[1,1.57,351.67],[2,1.5,159.65]],"ltp":1.63,"tv":8891.25,"id":13181195}],"tv":10344.59}]}
{"op":"mcm","clk":"1008068443","pt":1580658143399,"mc":[{"id":"1.168237984","rc":[{"batb":[[1,2.46,67.4],[2,2.42,461.45]],"ltp":2.6,"tv":1453.34,"id":14833204}]}]}
{"op":"mcm","clk":"1008069133","pt":1580658146376,"mc":[{"id":"1.168237984","rc":[{"trd":[[2.6,219.7]],"batl":[[0,2.6,169.95]],"ltp":2.6,"tv":1454.31,"id":14833204},{"trd":[[1.62,1.56]],"batl":[[2,1.66,14.72]],"ltp":1.62,"tv":8892.81,"id":13181195}],"tv":10347.12}]}
{"op":"mcm","clk":"1008069510","pt":1580658147983,"mc":[{"id":"1.168237984","rc":[{"batl":[[0,1.63,243.33]],"ltp":1.62,"tv":8892.81,"id":13181195}]}]}
{"op":"mcm","clk":"1008069855","pt":1580658149492,"mc":[{"id":"1.168237984","rc":[{"trd":[[2.6,228.08]],"batl":[[0,2.6,161.57]],"ltp":2.6,"tv":1462.69,"id":14833204},{"trd":[[1.62,15.02]],"ltp":1.62,"tv":8906.27,"id":13181195}],"tv":10368.96}]}
{"op":"mcm","clk":"1008070213","pt":1580658151022,"mc":[{"id":"1.168237984","rc":[{"batb":[[0,2.58,55],[1,2.56,3.83],[2,2.46,4.38]],"ltp":2.6,"tv":1462.69,"id":14833204},{"batb":[[0,1.58,477.12],[1,1.57,217.05],[2,1.51,156.58]],"ltp":1.62,"tv":8906.27,"id":13181195}]}]}
{"op":"mcm","clk":"1008072212","pt":1580658159181,"mc":[{"id":"1.168237984","rc":[{"batl":[[0,1.63,204.96]],"ltp":1.62,"tv":8906.27,"id":13181195}]}]}
{"op":"mcm","clk":"1008072889","pt":1580658162019,"mc":[{"id":"1.168237984","rc":[{"batb":[[0,1.58,516.76]],"ltp":1.62,"tv":8906.27,"id":13181195}]}]}
{"op":"mcm","clk":"1008073151","pt":1580658162996,"mc":[{"id":"1.168237984","rc":[{"trd":[[2.6,232.5]],"batl":[[0,2.6,157.15]],"ltp":2.6,"tv":1467.11,"id":14833204},{"trd":[[1.62,22.11]],"ltp":1.62,"tv":8913.36,"id":13181195}],"tv":10380.47}]}
{"op":"mcm","clk":"1008075009","pt":1580658170771,"mc":[{"id":"1.168237984","rc":[{"batb":[[0,1.58,131.95],[1,1.51,156.58],[2,1.5,159.65]],"batl":[[0,1.64,24.68],[1,1.66,14.72],[2,1.68,25.89]],"ltp":1.62,"tv":8913.36,"id":13181195}]}]}
{"op":"mcm","clk":"1008075741","pt":1580658173683,"mc":[{"id":"1.168237984","rc":[{"batb":[[1,1.51,517.13],[2,1.5,419.13]],"ltp":1.62,"tv":8913.36,"id":13181195}]}]}
{"op":"mcm","clk":"1008076306","pt":1580658175954,"mc":[{"id":"1.168237984","rc":[{"batb":[[1,2.44,64.44],[2,1.9,134.22]],"batl":[[0,3.3,2.35],[1,1000,0.02],[2,2.82,0]],"ltp":2.6,"tv":1467.11,"id":14833204},{"batl":[[0,1.7,283.08],[1,1.72,313.04],[2,1000,0.02]],"ltp":1.62,"tv":8913.36,"id":13181195}]}]}
{"op":"mcm","clk":"1008076404","pt":1580658176252,"mc":[{"id":"1.168237984","rc":[{"batb":[[0,2.44,64.44],[1,1.9,134.22],[2,1.8,75.72]],"ltp":2.6,"tv":1467.11,"id":14833204},{"batb":[[0,1.51,515.87],[1,1.5,259.48],[2,1.44,40.17]],"ltp":1.62,"tv":8913.36,"id":13181195}]}]}
{"op":"mcm","clk":"1008077126","pt":1580658179030,"mc":[{"id":"1.168237984","rc":[{"batb":[[0,2.46,3.88],[1,2.44,64.44],[2,2.42,3.94]],"batl":[[0,2.98,3.25],[1,3.15,2.9],[2,1000,0.02]],"ltp":2.6,"tv":1467.11,"id":14833204},{"batb":[[0,1.51,548.86],[2,1.47,38.67]],"batl":[[0,1.68,24.89],[1,1.7,311.33],[2,1.72,313.04]],"ltp":1.62,"tv":8913.36,"id":13181195}]}]}
{"op":"mcm","clk":"1008077355","pt":1580658179960,"mc":[{"id":"1.168237984","rc":[{"batb":[[0,2.44,64.44],[1,2.42,3.94],[2,1.9,134.22]],"ltp":2.6,"tv":1467.11,"id":14833204},{"batb":[[0,1.51,188.31],[1,1.47,38.67],[2,1.35,544.79]],"batl":[[0,1.7,311.33],[1,1.72,313.04],[2,1000,0.02]],"ltp":1.62,"tv":8913.36,"id":13181195}]}]}
{"op":"mcm","clk":"1008077518","pt":1580658180768,"mc":[{"id":"1.168237984","rc":[{"batl":[[0,3.15,2.9],[1,1000,0.02],[2,1000,0]],"ltp":2.6,"tv":1467.11,"id":14833204},{"batb":[[0,1.51,155.32]],"ltp":1.62,"tv":8913.36,"id":13181195}]}]}
{"op":"mcm","clk":"1008077661","pt":1580658181232,"mc":[{"id":"1.168237984","rc":[{"batb":[[0,2.6,11.06],[1,2.44,64.44],[2,2.42,3.94]],"ltp":2.6,"tv":1467.11,"id":14833204}]}]}
{"op":"mcm","clk":"1008078038","pt":1580658182956,"mc":[{"id":"1.168237984","rc":[{"trd":[[2.6,254.62]],"batb":[[0,2.44,64.44],[1,2.42,3.94],[2,2.36,10.08]],"batl":[[0,2.46,346],[1,2.56,120.35],[2,3.15,2.9]],"ltp":2.6,"tv":1489.22,"id":14833204},{"trd":[[1.7,20.36]],"batb":[[0,1.68,118.09],[1,1.65,176.17],[2,1.64,184.05]],"batl":[[0,1.7,301.15],[2,1.78,1146.33]],"ltp":1.7,"tv":8933.72,"id":13181195}],"tv":10422.95}]}
{"op":"mcm","clk":"1008078240","pt":1580658183863,"mc":[{"id":"1.168237984","rc":[{"batl":[[1,3.15,2.9],[2,1000,0.02]],"ltp":2.6,"tv":1489.22,"id":14833204},{"batb":[[2,1.64,298.22]],"ltp":1.7,"tv":8933.72,"id":13181195}]}]}
{"op":"mcm","clk":"1008079607","pt":1580658189666,"mc":[{"id":"1.168237984","rc":[{"batb":[[2,2.36,14.26]],"batl":[[1,2.7,3.55],[2,2.8,3.47]],"ltp":2.6,"tv":1489.22,"id":14833204},{"batb":[[2,1.64,792.25]],"batl":[[2,1.73,26.5]],"ltp":1.7,"tv":8933.72,"id":13181195}]}]}
{"op":"mcm","clk":"1008080392","pt":1580658192939,"mc":[{"id":"1.168237984","rc":[{"trd":[[2.44,128.88]],"batb":[[0,2.42,3.94],[1,2.36,4.18],[2,2.32,4.89]],"batl":[[0,2.44,88.83],[1,2.46,346],[2,2.7,3.55]],"ltp":2.44,"tv":1618.1,"id":14833204}],"tv":10551.83}]}
{"op":"mcm","clk":"1008080621","pt":1580658193873,"mc":[{"id":"1.168237984","rc":[{"batb":[[0,2.36,4.18],[1,2.32,4.89],[2,2.3,76.48]],"batl":[[1,2.7,3.55],[2,2.8,3.47]],"ltp":2.44,"tv":1618.1,"id":14833204},{"batb":[[0,1.64,494.03],[1,1.62,510.84],[2,1.59,30.11]],"batl":[[0,1.73,26.5],[1,1.74,480.59],[2,1.75,24.22]],"ltp":1.7,"tv":8933.72,"id":13181195}]}]}
{"op":"mcm","clk":"1008080692","pt":1580658194137,"mc":[{"id":"1.168237984","rc":[{"batb":[[0,2.32,4.89],[1,2.3,76.48],[2,1.9,134.22]],"ltp":2.44,"tv":1618.1,"id":14833204},{"batl":[[0,1.74,480.59],[1,1.75,24.22],[2,1.76,497.4]],"ltp":1.7,"tv":8933.72,"id":13181195}]}]}
{"op":"mcm","clk":"1008081070","pt":1580658195877,"mc":[{"id":"1.168237984","rc":[{"batb":[[0,2.4,7.05],[1,2.32,4.89],[2,2.3,76.48]],"batl":[[1,2.46,7.44],[2,2.7,3.55]],"ltp":2.44,"tv":1618.1,"id":14833204}]}]}
{"op":"mcm","clk":"1008081327","pt":1580658196866,"mc":[{"id":"1.168237984","rc":[{"batb":[[0,2.32,4.89],[1,2.3,76.48],[2,2.28,78.13]],"batl":[[1,2.7,3.55],[2,2.8,3.47]],"ltp":2.44,"tv":1618.1,"id":14833204},{"batl":[[2,1.76,727.64]],"ltp":1.7,"tv":8933.72,"id":13181195}]}]}
{"op":"mcm","clk":"1008081467","pt":1580658197479,"mc":[{"id":"1.168237984","rc":[{"batb":[[1,2.28,78.13],[2,1.9,134.22]],"ltp":2.44,"tv":1618.1,"id":14833204},{"batl":[[0,1.75,24.22],[1,1000,0.02],[2,1.76,0]],"ltp":1.7,"tv":8933.72,"id":13181195}]}]}
{"op":"mcm","clk":"1008082055","pt":1580658199955,"mc":[{"id":"1.168237984","rc":[{"trd":[[2.32,28.05]],"batb":[[0,2.28,78.13],[1,1.9,134.22],[2,1.7,75.72]],"batl":[[0,2.32,331.89],[1,2.36,83.34],[2,2.7,3.55]],"ltp":2.32,"tv":1646.15,"id":14833204},{"trd":[[1.75,24.22]],"batb":[[0,1.74,779.05],[1,1.69,126.99],[2,1.64,494.03]],"batl":[[0,1.8,17.55],[1,1.86,1127.5],[2,1000,0.02]],"ltp":1.75,"tv":8957.94,"id":13181195}],"tv":10604.1}]}
{"op":"mcm","clk":"1008082252","pt":1580658200874,"mc":[{"id":"1.168237984","rc":[{"batb":[[1,2.18,88.36],[2,1.9,134.22]],"ltp":2.32,"tv":1646.15,"id":14833204},{"batb":[[1,1.72,97.09],[2,1.7,309.17]],"batl":[[0,1.76,230.24],[1,1.78,279.69],[2,1.8,17.55]],"ltp":1.75,"tv":8957.94,"id":13181195}]}]}
{"op":"mcm","clk":"1008082741","pt":1580658202957,"mc":[{"id":"1.168237984","rc":[{"batl":[[1,2.34,88.83],[2,2.36,83.34]],"ltp":2.32,"tv":1646.15,"id":14833204}]}]}
{"op":"mcm","clk":"1008082820","pt":1580658203275,"mc":[{"id":"1.168237984","rc":[{"trd":[[2.32,35.59]],"batl":[[0,2.32,324.35]],"ltp":2.32,"tv":1653.69,"id":14833204},{"trd":[[1.75,34.22]],"ltp":1.75,"tv":8967.94,"id":13181195}],"tv":10621.64}]}
{"op":"mcm","clk":"1008083338","pt":1580658205458,"mc":[{"id":"1.168237984","rc":[{"batl":[[1,2.36,83.34],[2,2.7,3.55]],"ltp":2.32,"tv":1653.69,"id":14833204},{"batb":[[1,1.73,1.46],[2,1.72,97.09]],"ltp":1.75,"tv":8967.94,"id":13181195}]}]}
{"op":"mcm","clk":"1008083474","pt":1580658206167,"mc":[{"id":"1.168237984","rc":[{"trd":[[2.32,57.25]],"batl":[[0,2.32,302.69],[1,2.36,84.8]],"ltp":2.32,"tv":1675.35,"id":14833204},{"trd":[[1.75,62.94]],"batl":[[2,1.8,498.14]],"ltp":1.75,"tv":8996.66,"id":13181195}],"tv":10672.02}]}
{"op":"mcm","clk":"1008084118","pt":1580658208655,"mc":[{"id":"1.168237984","rc":[{"trd":[[2.3,88.83]],"batb":[[1,2.24,5.02],[2,2.2,4.97]],"batl":[[2,2.54,4.25]],"ltp":2.3,"tv":1764.19,"id":14833204},{"trd":[[1.76,119.44]],"batl":[[0,1.76,112.48],[2,1.8,520.01]],"ltp":1.76,"tv":9116.1,"id":13181195}],"tv":10880.29}]}
{"op":"mcm","clk":"1008085101","pt":1580658212772,"mc":[{"id":"1.168237984","rc":[{"batb":[[2,2.18,88.36]],"batl":[[0,2.36,1.46],[1,2.54,4.25],[2,2.64,3.93]],"ltp":2.3,"tv":1764.19,"id":14833204},{"batb":[[0,1.73,1.46],[1,1.72,97.09],[2,1.71,494.03]],"batl":[[0,1.8,502.46],[1,1.82,518.15],[2,1000,0.02]],"ltp":1.76,"tv":9116.1,"id":13181195}]}]}
{"op":"mcm","clk":"1008085334","pt":1580658213809,"mc":[{"id":"1.168237984","rc":[{"batb":[[0,2.24,5.02],[1,2.18,88.36],[2,1.9,134.22]],"ltp":2.3,"tv":1764.19,"id":14833204},{"batb":[[1,1.71,494.03],[2,1.69,510.84]],"ltp":1.76,"tv":9116.1,"id":13181195}]}]}
{"op":"mcm","clk":"1008085857","pt":1580658215998,"mc":[{"id":"1.168237984","rc":[{"batb":[[1,2.2,4.87],[2,2.18,88.36]],"ltp":2.3,"tv":1764.19,"id":14833204},{"batl":[[1,1.82,783.88],[2,1.84,251.16]],"ltp":1.76,"tv":9116.1,"id":13181195}]}]}
{"op":"mcm","clk":"1008086800","pt":1580658219891,"mc":[{"id":"1.168237984","rc":[{"trd":[[2.24,4.54]],"batb":[[0,2.24,2.75]],"ltp":2.24,"tv":1768.73,"id":14833204}],"tv":10884.83}]}
{"op":"mcm","clk":"1008087085","pt":1580658220986,"mc":[{"id":"1.168237984","rc":[{"batb":[[0,2.2,4.87],[1,2.18,88.36],[2,1.9,134.22]],"ltp":2.24,"tv":1768.73,"id":14833204},{"batl":[[0,1.82,20.75],[1,1000,0.02],[2,1.84,0]],"ltp":1.76,"tv":9116.1,"id":13181195}]}]}
{"op":"mcm","clk":"1008087557","pt":1580658222980,"mc":[{"id":"1.168237984","rc":[{"batl":[[0,2.36,84.72],[1,2.42,4.56],[2,2.54,4.25]],"ltp":2.24,"tv":1768.73,"id":14833204},{"batb":[[0,1.79,122.36],[1,1.76,183.9],[2,1.74,297.5]],"ltp":1.76,"tv":9116.1,"id":13181195}]}]}
{"op":"mcm","clk":"1008087758","pt":1580658223889,"mc":[{"id":"1.168237984","rc":[{"batb":[[2,2.1,97.72]],"ltp":2.24,"tv":1768.73,"id":14833204},{"batb":[[0,1.79,208.67],[1,1.73,97.06],[2,1.71,513.22]],"ltp":1.76,"tv":9116.1,"id":13181195}]}]}
{"op":"mcm","clk":"1008088757","pt":1580658228001,"mc":[{"id":"1.168237984","rc":[{"batb":[[2,1.71,19.19]],"ltp":1.76,"tv":9116.1,"id":13181195}]}]}
{"op":"mcm","clk":"1008089002","pt":1580658228989,"mc":[{"id":"1.168237984","rc":[{"batb":[[1,1.75,494.03],[2,1.73,607.9]],"batl":[[1,1.86,480.59],[2,1.88,497.4]],"ltp":1.76,"tv":9116.1,"id":13181195}]}]}
{"op":"mcm","clk":"1008089535","pt":1580658231207,"mc":[{"id":"1.168237984","rc":[{"batl":[[2,2.48,4.49]],"ltp":2.24,"tv":1768.73,"id":14833204},{"batl":[[1,1.83,21.5],[2,1.86,480.59]],"ltp":1.76,"tv":9116.1,"id":13181195}]}]}
{"op":"mcm","clk":"1008090377","pt":1580658234503,"mc":[{"id":"1.168237984","rc":[{"batb":[[0,2.1,97.72],[1,1.9,134.22],[2,1.6,75.72]],"batl":[[0,2.36,1.46]],"ltp":2.24,"tv":1768.73,"id":14833204},{"batb":[[0,1.75,494.03],[1,1.73,607.9],[2,1.71,19.19]],"batl":[[0,1.83,21.5],[1,1.86,480.59],[2,1.88,497.4]],"ltp":1.76,"tv":9116.1,"id":13181195}]}]}
{"op":"mcm","clk":"1008091199","pt":1580658237899,"mc":[{"id":"1.168237984","rc":[{"batb":[[0,2.2,5.22],[1,2.1,97.72],[2,1.9,134.22]],"batl":[[1,2.48,4.49],[2,2.54,4.25]],"ltp":2.24,"tv":1768.73,"id":14833204},{"batb":[[2,1.68,24.86]],"ltp":1.76,"tv":9116.1,"id":13181195}]}]}
{"op":"mcm","clk":"1008091634","pt":1580658239708,"mc":[{"id":"1.168237984","rc":[{"batb":[[0,1.75,692.77],[1,1.73,911.31]],"batl":[[0,1.81,264.31],[1,1.83,277.03],[2,1.86,480.59]],"ltp":1.76,"tv":9116.1,"id":13181195}]}]}
{"op":"mcm","clk":"1008091908","pt":1580658240929,"mc":[{"id":"1.168237984","rc":[{"batb":[[1,2.18,35.6],[2,2.1,97.72]],"batl":[[1,2.42,4.75],[2,2.48,4.49]],"ltp":2.24,"tv":1768.73,"id":14833204},{"batb":[[2,1.71,24.19]],"ltp":1.76,"tv":9116.1,"id":13181195}]}]}
{"op":"mcm","clk":"1008091957","pt":1580658241101,"mc":[{"id":"1.168237984","rc":[{"batl":[[1,1.82,19.75],[2,1.83,277.03]],"ltp":1.76,"tv":9116.1,"id":13181195}]}]}
{"op":"mcm","clk":"1008092788","pt":1580658244699,"mc":[{"id":"1.168237984","rc":[{"batb":[[0,1.75,494.03],[1,1.73,607.9]],"batl":[[0,1.83,21.5],[1,1.86,480.59],[2,1.88,497.4]],"ltp":1.76,"tv":9116.1,"id":13181195}]}]}
{"op":"mcm","clk":"1008093593","pt":1580658247917,"mc":[{"id":"1.168237984","rc":[{"batb":[[2,1.71,302.07]],"batl":[[0,1.82,22.25],[1,1.83,21.5],[2,1.85,182.74]],"ltp":1.76,"tv":9116.1,"id":13181195}]}]}
{"op":"mcm","clk":"1008093717","pt":1580658248414,"mc":[{"id":"1.168237984","rc":[{"batl":[[0,1.83,21.5],[1,1.86,480.59],[2,1.88,497.4]],"ltp":1.76,"tv":9116.1,"id":13181195}]}]}
{"op":"mcm","clk":"1008094076","pt":1580658249938,"mc":[{"id":"1.168237984","rc":[{"batb":[[2,1.71,24.19]],"batl":[[1,3,2.82],[2,1000,0.02]],"ltp":1.76,"tv":9116.1,"id":13181195}]}]}
{"op":"mcm","clk":"1008094472","pt":1580658251606,"mc":[{"id":"1.168237984","rc":[{"batb":[[1,2.1,97.72],[2,1.9,134.22]],"ltp":2.24,"tv":1768.73,"id":14833204},{"batl":[[1,1.86,260.83],[2,1.88,234.74]],"ltp":1.76,"tv":9116.1,"id":13181195}]}]}
{"op":"mcm","clk":"1008094808","pt":1580658253031,"mc":[{"id":"1.168237984","rc":[{"trd":[[2.16,229.91],[2.2,28.32]],"batb":[[0,2.12,6.97]],"batl":[[0,2.16,535.41],[1,2.26,96.77],[2,2.32,87.95]],"ltp":2.16,"tv":2026.96,"id":14833204},{"trd":[[1.83,21.5],[1.86,260.83]],"batb":[[0,1.79,276.24],[1,1.77,281.13],[2,1.75,494.03]],"batl":[[0,1.88,234.74],[1,1.96,411.73],[2,1.98,464]],"ltp":1.86,"tv":9398.43,"id":13181195}],"tv":11425.4}]}
{"op":"mcm","clk":"1008095041","pt":1580658254036,"mc":[{"id":"1.168237984","rc":[{"batb":[[2,1.99,115.98]],"ltp":2.16,"tv":2026.96,"id":14833204},{"batb":[[0,1.84,78.92],[1,1.77,89.23]],"batl":[[0,1.96,411.73],[1,1.98,464],[2,3,2.82]],"ltp":1.86,"tv":9398.43,"id":13181195}]}]}
{"op":"mcm","clk":"1008095745","pt":1580658257033,"mc":[{"id":"1.168237984","rc":[{"trd":[[2.16,240.77]],"batl":[[0,2.16,529.98]],"ltp":2.16,"tv":2037.82,"id":14833204},{"batb":[[1,1.8,288.4],[2,1.78,275.62]],"batl":[[0,1.87,234.81],[1,1.89,230.66],[2,1.96,411.73]],"ltp":1.86,"tv":9398.43,"id":13181195}],"tv":11436.26}]}
{"op":"mcm","clk":"1008095862","pt":1580658257435,"mc":[{"id":"1.168237984","rc":[{"batb":[[2,2.06,39.63]],"ltp":2.16,"tv":2037.82,"id":14833204}]}]}
{"op":"mcm","clk":"1008096522","pt":1580658260239,"mc":[{"id":"1.168237984","rc":[{"batl":[[2,1.96,431.85]],"ltp":1.86,"tv":9398.43,"id":13181195}]}]}
{"op":"mcm","clk":"1008096857","pt":1580658261728,"mc":[{"id":"1.168237984","rc":[{"trd":[[2.16,269.33]],"batb":[[2,2.08,38.9]],"batl":[[0,2.16,515.7]],"ltp":2.16,"tv":2066.38,"id":14833204}],"tv":11464.82}]}
{"op":"mcm","clk":"1008098611","pt":1580658269937,"mc":[{"id":"1.168237984","rc":[{"trd":[[2.16,272.48]],"batl":[[0,2.16,512.55]],"ltp":2.16,"tv":2069.53,"id":14833204},{"trd":[[1.86,264.49]],"ltp":1.86,"tv":9402.09,"id":13181195}],"tv":11471.62}]}
{"op":"mcm","clk":"1008102919","pt":1580658289046,"mc":[{"id":"1.168237984","rc":[{"trd":[[2.16,274.44]],"batl":[[0,2.16,510.59]],"ltp":2.16,"tv":2071.49,"id":14833204},{"trd":[[1.86,266.76]],"ltp":1.86,"tv":9404.36,"id":13181195}],"tv":11475.86}]}
{"op":"mcm","clk":"1008103029","pt":1580658289584,"mc":[{"id":"1.168237984","rc":[{"batl":[[0,2.16,408.77]],"ltp":2.16,"tv":2071.49,"id":14833204}]}]}
{"op":"mcm","clk":"1008103159","pt":1580658290175,"mc":[{"id":"1.168237984","rc":[{"batb":[[1,1.77,89.23],[2,1.73,21.59]],"batl":[[0,1.96,431.85],[1,1.97,20.83],[2,1.99,18.5]],"ltp":1.86,"tv":9404.36,"id":13181195}]}]}
{"op":"mcm","clk":"1008103788","pt":1580658293047,"mc":[{"id":"1.168237984","rc":[{"batb":[[0,2.08,38.9],[1,2.06,39.63],[2,2.04,5.62]],"batl":[[0,2.36,1.46],[1,2.38,5.04],[2,2.42,4.75]],"ltp":2.16,"tv":2071.49,"id":14833204},{"batb":[[0,1.77,89.23],[1,1.75,204.09],[2,1.73,324.54]],"batl":[[0,1.96,20.12],[1,1.97,240.59],[2,1.99,215.8]],"ltp":1.86,"tv":9404.36,"id":13181195}]}]}
{"op":"mcm","clk":"1008103825","pt":1580658293263,"mc":[{"id":"1.168237984","rc":[{"batb":[[2,2,15.7]],"batl":[[1,2.42,4.75],[2,2.48,4.49]],"ltp":2.16,"tv":2071.49,"id":14833204},{"batb":[[2,1.73,304.41]],"batl":[[0,1.97,240.59],[1,1.99,215.8],[2,2,19.51]],"ltp":1.86,"tv":9404.36,"id":13181195}]}]}
{"op":"mcm","clk":"1008104045","pt":1580658294187,"mc":[{"id":"1.168237984","rc":[{"batl":[[0,1.86,31.21],[1,1.97,240.59],[2,1.99,215.8]],"ltp":1.86,"tv":9404.36,"id":13181195}]}]}
{"op":"mcm","clk":"1008104419","pt":1580658295851,"mc":[{"id":"1.168237984","rc":[{"batb":[[0,2.06,39.63],[1,2,15.7],[2,1.99,115.43]],"ltp":2.16,"tv":2071.49,"id":14833204},{"batl":[[1,1.99,18.5],[2,2,19.51]],"ltp":1.86,"tv":9404.36,"id":13181195}]}]}
{"op":"mcm","clk":"1008105046","pt":1580658298761,"mc":[{"id":"1.168237984","rc":[{"batb":[[0,2.12,94.94],[1,2.06,39.63],[2,2,15.7]],"batl":[[0,2.28,599.89],[1,2.3,418],[2,2.36,1.46]],"ltp":2.16,"tv":2071.49,"id":14833204},{"batl":[[0,1.81,257.79],[1,1.83,265.38],[2,1.86,145.27]],"ltp":1.86,"tv":9404.36,"id":13181195}]}]}
{"op":"mcm","clk":"1008105328","pt":1580658299910,"mc":[{"id":"1.168237984","rc":[{"batb":[[0,2.2,85.29],[1,2.12,94.94],[2,2.08,100.32]],"ltp":2.16,"tv":2071.49,"id":14833204}]}]}
{"op":"mcm","clk":"1008105490","pt":1580658300570,"mc":[{"id":"1.168237984","rc":[{"batb":[[1,2.16,36.21],[2,2.12,94.94]],"ltp":2.16,"tv":2071.49,"id":14833204}]}]}
{"op":"mcm","clk":"1008105938","pt":1580658302514,"mc":[{"id":"1.168237984","rc":[{"batb":[[1,2.18,35.6]],"ltp":2.16,"tv":2071.49,"id":14833204},{"batl":[[2,1.86,114.06]],"ltp":1.86,"tv":9404.36,"id":13181195}]}]}
{"op":"mcm","clk":"1008106501","pt":1580658304802,"mc":[{"id":"1.168237984","rc":[{"batb":[[2,2.14,36.85]],"ltp":2.16,"tv":2071.49,"id":14833204}]}]}
{"op":"mcm","clk":"1008106695","pt":1580658305623,"mc":[{"id":"1.168237984","rc":[{"batb":[[2,2.16,5.53]],"ltp":2.16,"tv":2071.49,"id":14833204},{"batb":[[2,1.74,494.03]],"batl":[[2,1.85,501.09]],"ltp":1.86,"tv":9404.36,"id":13181195}]}]}
{"op":"mcm","clk":"1008108583","pt":1580658313939,"mc":[{"id":"1.168237984","rc":[{"batl":[[0,2.36,1.46],[1,2.42,4.75],[2,2.44,8.58]],"ltp":2.16,"tv":2071.49,"id":14833204},{"batl":[[1,1.83,255.08]],"ltp":1.86,"tv":9404.36,"id":13181195}]}]}
{"op":"mcm","clk":"1008108789","pt":1580658314845,"mc":[{"id":"1.168237984","rc":[{"batb":[[0,2.18,35.6],[1,2.14,41.67],[2,2.08,100.32]],"batl":[[1,2.44,8.58],[2,2.5,8.23]],"ltp":2.16,"tv":2071.49,"id":14833204},{"batb":[[0,1.74,494.03],[1,1.73,1.46],[2,1.72,510.84]],"batl":[[0,1.78,29.26],[1,1.85,501.09],[2,1.87,518.13]],"ltp":1.86,"tv":9404.36,"id":13181195}]}]}
{"op":"mcm","clk":"1008108828","pt":1580658315060,"mc":[{"id":"1.168237984","rc":[{"batb":[[2,2.1,38.19]],"ltp":2.16,"tv":2071.49,"id":14833204}]}]}
{"op":"mcm","clk":"1008109746","pt":1580658319256,"mc":[{"id":"1.168237984","rc":[{"batb":[[0,1.73,1.46],[1,1.71,99.3],[2,1.7,328.14]],"batl":[[0,1.78,60.47]],"ltp":1.86,"tv":9404.36,"id":13181195}]}]}
{"op":"mcm","clk":"1008110318","pt":1580658321957,"mc":[{"id":"1.168237984","rc":[{"batb":[[0,2.3,110.71],[1,2.26,93.71],[2,2.18,35.6]],"batl":[[1,2.4,409],[2,2.44,8.58]],"ltp":2.16,"tv":2071.49,"id":14833204},{"batb":[[0,1.74,603.46],[1,1.73,1.46],[2,1.71,99.3]],"batl":[[0,1.78,73.47],[1,1.82,533],[2,1.83,419.17]],"ltp":1.86,"tv":9404.36,"id":13181195}]}]}
{"op":"mcm","clk":"1008110522","pt":1580658322874,"mc":[{"id":"1.168237984","rc":[{"batb":[[0,2.3,186.87],[2,2.2,85.84]],"ltp":2.16,"tv":2071.49,"id":14833204},{"batl":[[0,1.76,244.98],[1,1.78,352.29],[2,1.82,533]],"ltp":1.86,"tv":9404.36,"id":13181195}]}]}
{"op":"mcm","clk":"1008110727","pt":1580658323794,"mc":[{"id":"1.168237984","rc":[{"batb":[[1,2.26,127.05]],"ltp":2.16,"tv":2071.49,"id":14833204}]}]}
{"op":"mcm","clk":"1008110994","pt":1580658324954,"mc":[{"id":"1.168237984","rc":[{"batb":[[1,2.26,93.71]],"ltp":2.16,"tv":2071.49,"id":14833204}]}]}
{"op":"mcm","clk":"1008111407","pt":1580658326972,"mc":[{"id":"1.168237984","rc":[{"batb":[[2,2.24,33.88]],"ltp":2.16,"tv":2071.49,"id":14833204}]}]}
{"op":"mcm","clk":"1008111820","pt":1580658328866,"mc":[{"id":"1.168237984","rc":[{"batb":[[1,2.28,4.91],[2,2.26,98.42]],"ltp":2.16,"tv":2071.49,"id":14833204},{"batl":[[1,1.78,375.54],[2,1.79,20.69]],"ltp":1.86,"tv":9404.36,"id":13181195}]}]}
{"op":"mcm","clk":"1008112041","pt":1580658329884,"mc":[{"id":"1.168237984","rc":[{"batl":[[1,1.78,346.28]],"ltp":1.86,"tv":9404.36,"id":13181195}]}]}
{"op":"mcm","clk":"1008113218","pt":1580658334962,"mc":[{"id":"1.168237984","rc":[{"batb":[[0,2.26,38.05],[1,2.24,33.88],[2,2.2,85.84]],"batl":[[1,2.44,8.58],[2,2.46,8.75]],"ltp":2.16,"tv":2071.49,"id":14833204},{"batb":[[0,1.73,1.46],[1,1.7,531.05],[2,1.69,38.21]],"batl":[[0,1.79,20.69],[1,1.8,480.59],[2,1.82,497.4]],"ltp":1.86,"tv":9404.36,"id":13181195}]}]}
{"op":"mcm","clk":"1008113424","pt":1580658335962,"mc":[{"id":"1.168237984","rc":[{"batl":[[0,1.74,29.26],[1,1.79,20.69],[2,1.8,480.59]],"ltp":1.86,"tv":9404.36,"id":13181195}]}]}
{"op":"mcm","clk":"1008113887","pt":1580658338496,"mc":[{"id":"1.168237984","rc":[{"batl":[[1,2.46,8.75],[2,2.5,8.23]],"ltp":2.16,"tv":2071.49,"id":14833204},{"batb":[[1,1.69,38.21],[2,1.67,413.56]],"ltp":1.86,"tv":9404.36,"id":13181195}]}]}
{"op":"mcm","clk":"1008114381","pt":1580658340976,"mc":[{"id":"1.168237984","rc":[{"trd":[[2.36,2.92]],"batb":[[0,2.36,6.56],[1,2.26,38.05],[2,2.24,33.88]],"batl":[[0,2.42,397.04],[2,2.48,364]],"ltp":2.36,"tv":2074.41,"id":14833204},{"batl":[[1,1.75,118.28],[2,1.76,120.68]],"ltp":1.86,"tv":9404.36,"id":13181195}],"tv":11478.78}]}
{"op":"mcm","clk":"1008114597","pt":1580658341975,"mc":[{"id":"1.168237984","rc":[{"batb":[[0,2.38,69],[1,2.36,6.56],[2,2.3,76.56]],"ltp":2.36,"tv":2074.41,"id":14833204},{"trd":[[1.73,2.92]],"batb":[[0,1.69,38.21],[1,1.67,413.56],[2,1.66,175.99]],"batl":[[0,1.73,345.12],[1,1.74,29.26],[2,1.75,412.68]],"ltp":1.73,"tv":9407.28,"id":13181195}],"tv":11481.7}]}
{"op":"mcm","clk":"1008115739","pt":1580658347682,"mc":[{"id":"1.168237984","rc":[{"batb":[[2,1.66,670.02]],"batl":[[1,1.75,412.68],[2,1.76,120.68]],"ltp":1.73,"tv":9407.28,"id":13181195}]}]}
{"op":"mcm","clk":"1008115878","pt":1580658348466,"mc":[{"id":"1.168237984","rc":[{"batb":[[2,2.34,4.72]],"batl":[[1,2.44,9.08],[2,2.46,8.75]],"ltp":2.36,"tv":2074.41,"id":14833204},{"batb":[[0,1.7,38.92],[1,1.69,38.21],[2,1.67,413.56]],"batl":[[0,1.73,313.91],[1,1.74,20.75],[2,1.75,433.46]],"ltp":1.73,"tv":9407.28,"id":13181195}]}]}
{"op":"mcm","clk":"1008116362","pt":1580658350892,"mc":[{"id":"1.168237984","rc":[{"batb":[[1,2.34,4.72],[2,2.32,4.14]],"batl":[[0,2.42,389.9]],"ltp":2.36,"tv":2074.41,"id":14833204}]}]}
{"op":"mcm","clk":"1008116958","pt":1580658353802,"mc":[{"id":"1.168237984","rc":[{"batb":[[1,2.36,6.56],[2,2.34,4.72]],"batl":[[0,2.42,398.47]],"ltp":2.36,"tv":2074.41,"id":14833204}]}]}
{"op":"mcm","clk":"1008117212","pt":1580658355000,"mc":[{"id":"1.168237984","rc":[{"batb":[[0,2.32,4.14],[1,2.3,76.56],[2,2.26,4.71]],"batl":[[0,2.72,241.55],[1,1000,0.02],[2,2.46,0]],"ltp":2.36,"tv":2074.41,"id":14833204},{"trd":[[1.7,25.3]],"batb":[[0,1.7,36.45],[1,1.66,494.03],[2,1.64,626.58]],"batl":[[0,1.75,20.78],[1,1.77,480.59],[2,1.79,518.09]],"ltp":1.7,"tv":9412.21,"id":13181195}],"tv":11486.63}]}
{"op":"mcm","clk":"1008117825","pt":1580658357801,"mc":[{"id":"1.168237984","rc":[{"batl":[[0,2.44,9.08],[1,2.72,241.55],[2,1000,0.02]],"ltp":2.36,"tv":2074.41,"id":14833204}]}]}
{"op":"mcm","clk":"1008118098","pt":1580658358982,"mc":[{"id":"1.168237984","rc":[{"trd":[[1.7,83.81]],"batb":[[0,1.7,7.19]],"ltp":1.7,"tv":9470.73,"id":13181195}],"tv":11545.15}]}
{"op":"mcm","clk":"1008118194","pt":1580658359472,"mc":[{"id":"1.168237984","rc":[{"trd":[[1.7,98.2]],"batb":[[0,1.66,494.03],[1,1.64,626.58],[2,1.6,2.57]],"batl":[[0,1.7,31.82],[1,1.75,20.78],[2,1.77,480.59]],"ltp":1.7,"tv":9485.11,"id":13181195}],"tv":11559.53}]}
{"op":"mcm","clk":"1008118490","pt":1580658360913,"mc":[{"id":"1.168237984","rc":[{"trd":[[2.42,11.25]],"batb":[[0,2.38,9.96],[1,2.32,4.14],[2,2.3,76.56]],"ltp":2.42,"tv":2085.66,"id":14833204},{"trd":[[1.7,137.35]],"batb":[[0,1.68,208.27],[1,1.66,843.53],[2,1.64,626.58]],"batl":[[0,1.7,4.23],[1,1.72,10.16],[2,1.73,207.02]],"ltp":1.7,"tv":9524.27,"id":13181195}],"tv":11609.94}]}
{"op":"mcm","clk":"1008118636","pt":1580658361616,"mc":[{"id":"1.168237984","rc":[{"batb":[[0,2.34,4.22]],"ltp":2.42,"tv":2085.66,"id":14833204},{"batl":[[1,1.73,207.02],[2,1.74,23.25]],"ltp":1.7,"tv":9524.27,"id":13181195}]}]}
{"op":"mcm","clk":"1008118868","pt":1580658362808,"mc":[{"id":"1.168237984","rc":[{"batb":[[0,2.32,4.14],[1,2.3,76.56],[2,2.26,4.71]],"ltp":2.42,"tv":2085.66,"id":14833204},{"trd":[[1.7,144.3]],"batb":[[0,1.66,494.03],[1,1.64,626.58],[2,1.6,2.57]],"batl":[[0,1.75,21.54],[1,1.77,480.59],[2,1.79,518.09]],"ltp":1.7,"tv":9531.22,"id":13181195}],"tv":11616.89}]}
{"op":"mcm","clk":"1008119525","pt":1580658365997,"mc":[{"id":"1.168237984","rc":[{"batb":[[0,2.34,4.22],[1,2.32,4.14],[2,2.3,76.56]],"ltp":2.42,"tv":2085.66,"id":14833204},{"batl":[[0,1.74,26.51],[1,1.75,20.78],[2,1.76,218.77]],"ltp":1.7,"tv":9531.22,"id":13181195}]}]}
{"op":"mcm","clk":"1008119589","pt":1580658366319,"mc":[{"id":"1.168237984","rc":[{"batb":[[0,2.32,4.14],[1,2.3,76.56],[2,2.26,4.71]],"ltp":2.42,"tv":2085.66,"id":14833204},{"batl":[[0,1.75,21.54],[1,1.76,218.77],[2,1.78,278.94]],"ltp":1.7,"tv":9531.22,"id":13181195}]}]}
{"op":"mcm","clk":"1008120169","pt":1580658368995,"mc":[{"id":"1.168237984","rc":[{"trd":[[2.32,61.39],[2.42,11.78]],"batb":[[0,2.3,76.56],[1,2.26,4.71],[2,2.14,4.82]],"batl":[[0,2.38,415],[1,2.4,3.69],[2,2.44,9.08]],"ltp":2.32,"tv":2090.33,"id":14833204},{"trd":[[1.7,145.06],[1.75,104.5],[1.76,562.44]],"batb":[[0,1.76,201.99],[1,1.74,111.49],[2,1.72,15.59]],"batl":[[0,1.79,20.69],[1,1.8,14.98],[2,1.83,498]],"ltp":1.76,"tv":10016.54,"id":13181195}],"tv":12106.88}]}
{"op":"mcm","clk":"1008120327","pt":1580658369838,"mc":[{"id":"1.168237984","rc":[{"batb":[[1,2.2,86.94]],"ltp":2.32,"tv":2090.33,"id":14833204},{"batl":[[0,1.8,14.98],[1,1.83,498],[2,1.85,20.5]],"ltp":1.76,"tv":10016.54,"id":13181195}]}]}
{"op":"mcm","clk":"1008120807","pt":1580658371899,"mc":[{"id":"1.168237984","rc":[{"trd":[[1.76,578.2]],"batb":[[0,1.76,194.11]],"batl":[[0,1.77,238.62],[1,1.79,273.36],[2,1.8,14.98]],"ltp":1.76,"tv":10032.3,"id":13181195}],"tv":12122.64}]}
{"op":"mcm","clk":"1008121558","pt":1580658375433,"mc":[{"id":"1.168237984","rc":[{"batb":[[1,2.26,4.71],[2,2.24,5.02]],"ltp":2.32,"tv":2090.33,"id":14833204},{"batb":[[2,1.72,509.62]],"batl":[[1,1.79,292.86],[2,1.8,37.05]],"ltp":1.76,"tv":10032.3,"id":13181195}]}]}
{"op":"mcm","clk":"1008122278","pt":1580658378706,"mc":[{"id":"1.168237984","rc":[{"batl":[[2,1.8,22.07]],"ltp":1.76,"tv":10032.3,"id":13181195}]}]}
{"op":"mcm","clk":"1008122864","pt":1580658381644,"mc":[{"id":"1.168237984","rc":[{"batb":[[1,1.74,124.39]],"batl":[[1,1.78,12.23],[2,1.79,292.86]],"ltp":1.76,"tv":10032.3,"id":13181195}]}]}
{"op":"mcm","clk":"1008123105","pt":1580658382840,"mc":[{"id":"1.168237984","rc":[{"batb":[[0,2.24,5.02],[1,2.2,86.94],[2,2.14,4.82]],"batl":[[0,2.44,9.08],[1,2.72,241.55],[2,1000,0.02]],"ltp":2.32,"tv":2090.33,"id":14833204},{"batb":[[0,1.72,494.03],[1,1.7,510.84],[2,1.67,108.42]],"batl":[[0,1.8,22.07],[1,1.81,480.59],[2,1.83,497.4]],"ltp":1.76,"tv":10032.3,"id":13181195}]}]}
{"op":"mcm","clk":"1008123696","pt":1580658385842,"mc":[{"id":"1.168237984","rc":[{"batl":[[0,2.4,7.34],[1,2.44,9.08],[2,2.72,241.55]],"ltp":2.32,"tv":2090.33,"id":14833204},{"batb":[[0,1.72,524.87],[1,1.7,541.66],[2,1.68,265.78]],"batl":[[2,1.82,169.08]],"ltp":1.76,"tv":10032.3,"id":13181195}]}]}
{"op":"mcm","clk":"1008125134","pt":1580658392940,"mc":[{"id":"1.168237984","rc":[{"batb":[[0,2.26,5.48],[1,2.24,5.02],[2,2.2,86.94]],"ltp":2.32,"tv":2090.33,"id":14833204},{"batl":[[0,1.79,24.5],[1,1.8,22.07],[2,1.81,480.59]],"ltp":1.76,"tv":10032.3,"id":13181195}]}]}
{"op":"mcm","clk":"1008125181","pt":1580658393214,"mc":[{"id":"1.168237984","rc":[{"batb":[[0,2.24,5.02],[1,2.2,86.94],[2,2.14,4.82]],"ltp":2.32,"tv":2090.33,"id":14833204},{"batl":[[0,1.8,22.07],[1,1.81,480.59],[2,1.82,169.08]],"ltp":1.76,"tv":10032.3,"id":13181195}]}]}
{"op":"mcm","clk":"1008125472","pt":1580658394748,"mc":[{"id":"1.168237984","rc":[{"trd":[[1.72,12.19]],"batb":[[0,1.72,518.78],[2,1.67,108.42]],"batl":[[2,1.83,497.4]],"ltp":1.72,"tv":10044.49,"id":13181195}],"tv":12134.82}]}
{"op":"mcm","clk":"1008125810","pt":1580658396436,"mc":[{"id":"1.168237984","rc":[{"batb":[[0,2.26,4.71],[1,2.24,5.02],[2,2.2,86.94]],"ltp":2.32,"tv":2090.33,"id":14833204},{"batl":[[0,1.79,23.5],[1,1.8,22.07],[2,1.81,480.59]],"ltp":1.72,"tv":10044.49,"id":13181195}]}]}
{"op":"mcm","clk":"1008126044","pt":1580658397555,"mc":[{"id":"1.168237984","rc":[{"batb":[[1,1.71,280.5],[2,1.7,541.66]],"batl":[[0,1.77,238.62],[1,1.79,296.86],[2,1.8,22.07]],"ltp":1.72,"tv":10044.49,"id":13181195}]}]}
{"op":"mcm","clk":"1008127960","pt":1580658406558,"mc":[{"id":"1.168237984","rc":[{"trd":[[1.72,12.87]],"batb":[[0,1.72,518.44]],"ltp":1.72,"tv":10045.17,"id":13181195}],"tv":12135.51}]}
{"op":"mcm","clk":"1008129711","pt":1580658415864,"mc":[{"id":"1.168237984","rc":[{"batb":[[1,1.7,541.66],[2,1.67,108.42]],"batl":[[0,1.79,23.5],[1,1.8,22.07],[2,1.81,480.59]],"ltp":1.72,"tv":10045.17,"id":13181195}]}]}
{"op":"mcm","clk":"1008129741","pt":1580658416076,"mc":[{"id":"1.168237984","rc":[{"batb":[[0,2.2,86.94],[1,2.14,4.82],[2,2,15.7]],"ltp":2.32,"tv":2090.33,"id":14833204},{"batl":[[0,1.8,22.07],[1,1.81,480.59],[2,1.83,497.4]],"ltp":1.72,"tv":10045.17,"id":13181195}]}]}
{"op":"mcm","clk":"1008130280","pt":1580658418773,"mc":[{"id":"1.168237984","rc":[{"batb":[[2,1.68,265.78]],"batl":[[2,1.82,169.08]],"ltp":1.72,"tv":10045.17,"id":13181195}]}]}
{"op":"mcm","clk":"1008130445","pt":1580658419590,"mc":[{"id":"1.168237984","rc":[{"batb":[[0,2.24,4.77],[1,2.2,86.94],[2,2.14,4.82]],"ltp":2.32,"tv":2090.33,"id":14833204}]}]}
{"op":"mcm","clk":"1008131188","pt":1580658422983,"mc":[{"id":"1.168237984","rc":[{"batb":[[2,1.9,134.22]],"batl":[[0,2.44,9.08],[1,2.72,241.55],[2,1000,0.02]],"ltp":2.32,"tv":2090.33,"id":14833204},{"batb":[[0,1.7,30.82],[1,1.67,108.42],[2,1.35,544.79]],"batl":[[0,1.79,22.5],[1,1.8,22.07],[2,1.81,480.59]],"ltp":1.72,"tv":10045.17,"id":13181195}]}]}
{"op":"mcm","clk":"1008131221","pt":1580658423093,"mc":[{"id":"1.168237984","rc":[{"batl":[[0,1.8,22.07],[1,1.81,480.59],[2,1.83,497.4]],"ltp":1.72,"tv":10045.17,"id":13181195}]}]}
{"op":"mcm","clk":"1008131589","pt":1580658424878,"mc":[{"id":"1.168237984","rc":[{"batb":[[0,2.36,6.83],[1,2.28,894.39],[2,2.24,4.77]],"batl":[[0,2.42,413.23],[1,2.44,9.08],[2,2.46,394]],"ltp":2.32,"tv":2090.33,"id":14833204},{"batl":[[0,1.74,3516.4],[1,1.78,440],[2,1.8,686.54]],"ltp":1.72,"tv":10045.17,"id":13181195}]}]}
{"op":"mcm","clk":"1008131849","pt":1580658425970,"mc":[{"id":"1.168237984","rc":[{"batb":[[0,2.38,69],[1,2.36,6.83],[2,2.28,89.44]],"ltp":2.32,"tv":2090.33,"id":14833204},{"batb":[[1,1.68,265.78],[2,1.67,108.42]],"batl":[[0,1.74,298.94],[1,1.76,288.48],[2,1.78,440]],"ltp":1.72,"tv":10045.17,"id":13181195}]}]}
{"op":"mcm","clk":"1008132024","pt":1580658426888,"mc":[{"id":"1.168237984","rc":[{"batb":[[1,1.69,2.62],[2,1.68,265.78]],"ltp":1.72,"tv":10045.17,"id":13181195}]}]}
{"op":"mcm","clk":"1008133505","pt":1580658434173,"mc":[{"id":"1.168237984","rc":[{"trd":[[1.7,158.08]],"batb":[[0,1.7,24.31]],"ltp":1.7,"tv":10058.19,"id":13181195}],"tv":12148.53}]}
{"op":"mcm","clk":"1008134640","pt":1580658440145,"mc":[{"id":"1.168237984","rc":[{"trd":[[2.38,4.5]],"batb":[[0,2.38,66.75]],"ltp":2.38,"tv":2094.83,"id":14833204}],"tv":12153.03}]}
{"op":"mcm","clk":"1008137447","pt":1580658453234,"mc":[{"id":"1.168237984","rc":[{"batl":[[1,2.44,10.76]],"ltp":2.38,"tv":2094.83,"id":14833204}]}]}
{"op":"mcm","clk":"1008137803","pt":1580658454947,"mc":[{"id":"1.168237984","rc":[{"batb":[[1,1.68,265.78],[2,1.67,107.87]],"ltp":1.7,"tv":10058.19,"id":13181195}]}]}
{"op":"mcm","clk":"1008138000","pt":1580658455852,"mc":[{"id":"1.168237984","rc":[{"trd":[[1.7,161.11]],"batb":[[0,1.7,22.8]],"ltp":1.7,"tv":10061.22,"id":13181195}],"tv":12156.06}]}
{"op":"mcm","clk":"1008138488","pt":1580658458255,"mc":[{"id":"1.168237984","rc":[{"batl":[[0,2.4,3.03],[1,2.42,413.23],[2,2.44,10.76]],"ltp":2.38,"tv":2094.83,"id":14833204}]}]}
{"op":"mcm","clk":"1008140493","pt":1580658467953,"mc":[{"id":"1.168237984","rc":[{"trd":[[2.4,5.62]],"batl":[[0,2.42,413.45],[1,2.44,10.76],[2,2.46,394]],"ltp":2.4,"tv":2100.45,"id":14833204}],"tv":12161.68}]}
{"op":"mcm","clk":"1008144972","pt":1580658489675,"mc":[{"id":"1.168237984","rc":[{"batl":[[0,2.4,1.9],[1,2.42,413.23],[2,2.44,10.76]],"ltp":2.4,"tv":2100.45,"id":14833204}]}]}
{"op":"mcm","clk":"1008149334","pt":1580658511916,"mc":[{"id":"1.168237984","rc":[{"batl":[[2,1.8,686.54]],"ltp":1.7,"tv":10061.22,"id":13181195}]}]}
{"op":"mcm","clk":"1008150017","pt":1580658515493,"mc":[{"id":"1.168237984","rc":[{"batl":[[2,1.79,20.5]],"ltp":1.7,"tv":10061.22,"id":13181195}]}]}
{"op":"mcm","clk":"1008150424","pt":1580658517806,"mc":[{"id":"1.168237984","rc":[{"batb":[[0,2.22,82.85],[1,1.9,134.22],[2,1.74,404.28]],"batl":[[1,2.44,1.68],[2,2.5,1.68]],"ltp":2.4,"tv":2100.45,"id":14833204},{"batb":[[0,1.59,163.25],[1,1.35,544.79],[2,1.34,168.05]],"batl":[[0,1.82,20.25],[1,3,2.82],[2,1000,2.02]],"ltp":1.7,"tv":10061.22,"id":13181195}]}]}
{"op":"mcm","clk":"1008150988","pt":1580658521026,"mc":[{"id":"1.168237984","rc":[{"batb":[[0,2.26,4.48],[1,2.22,82.85],[2,2.2,4.57]],"ltp":2.4,"tv":2100.45,"id":14833204},{"batb":[[0,1.62,27.54],[1,1.59,163.25],[2,1.35,544.79]],"batl":[[0,1.79,21.69],[1,1.81,170.03],[2,1.82,20.25]],"ltp":1.7,"tv":10061.22,"id":13181195}]}]}
{"op":"mcm","clk":"1008151048","pt":1580658521351,"mc":[{"id":"1.168237984","rc":[{"batb":[[0,2.22,82.85],[1,2.2,4.57],[2,1.9,134.22]],"ltp":2.4,"tv":2100.45,"id":14833204},{"batb":[[0,1.59,163.25],[1,1.35,544.79],[2,1.34,168.05]],"batl":[[0,1.81,170.03],[1,1.82,20.25],[2,1.83,254.93]],"ltp":1.7,"tv":10061.22,"id":13181195}]}]}
{"op":"mcm","clk":"1008151291","pt":1580658522523,"mc":[{"id":"1.168237984","rc":[{"batl":[[0,2.28,472.3],[1,2.3,398.95],[2,2.36,77.25]],"ltp":2.4,"tv":2100.45,"id":14833204},{"batb":[[0,1.77,27.37],[1,1.75,294.36],[2,1.73,302.81]],"batl":[[2,1.83,268.27]],"ltp":1.7,"tv":10061.22,"id":13181195}]}]}
{"op":"mcm","clk":"1008151529","pt":1580658523595,"mc":[{"id":"1.168237984","rc":[{"batb":[[2,2.12,96.46]],"ltp":2.4,"tv":2100.45,"id":14833204},{"batb":[[1,1.76,94.09],[2,1.75,294.36]],"ltp":1.7,"tv":10061.22,"id":13181195}]}]}
{"op":"mcm","clk":"1008152608","pt":1580658529125,"mc":[{"id":"1.168237984","rc":[{"batb":[[2,2.16,5.53]],"ltp":2.4,"tv":2100.45,"id":14833204}]}]}
{"op":"mcm","clk":"1008153871","pt":1580658535633,"mc":[{"id":"1.168237984","rc":[{"batb":[[0,2.14,4.82],[1,2.12,96.46],[2,1.9,134.22]],"batl":[[0,2.4,7.99],[1,2.44,1.68],[2,2.46,6.25]],"ltp":2.4,"tv":2100.45,"id":14833204},{"batb":[[0,1.76,2.58],[1,1.74,494.03],[2,1.72,536.43]],"batl":[[0,1.85,500.29],[1,1.87,515.9],[2,3,2.82]],"ltp":1.7,"tv":10061.22,"id":13181195}]}]}
{"op":"mcm","clk":"1008154854","pt":1580658540743,"mc":[{"id":"1.168237984","rc":[{"batb":[[1,1.74,663.17],[2,1.72,844.75]],"batl":[[0,1.79,170.24],[1,1.81,264.01],[2,1.85,500.29]],"ltp":1.7,"tv":10061.22,"id":13181195}]}]}
{"op":"mcm","clk":"1008155074","pt":1580658542025,"mc":[{"id":"1.168237984","rc":[{"batb":[[0,2.16,5.28],[1,2.14,4.82],[2,2.12,96.46]],"ltp":2.4,"tv":2100.45,"id":14833204}]}]}
{"op":"mcm","clk":"1008155121","pt":1580658542338,"mc":[{"id":"1.168237984","rc":[{"batb":[[0,2.14,4.82],[1,2.12,96.46],[2,1.9,134.22]],"ltp":2.4,"tv":2100.45,"id":14833204}]}]}
{"op":"mcm","clk":"1008155901","pt":1580658546845,"mc":[{"id":"1.168237984","rc":[{"batb":[[1,1.74,494.03],[2,1.72,536.43]],"batl":[[0,1.85,500.29],[1,1.87,515.9],[2,3,2.82]],"ltp":1.7,"tv":10061.22,"id":13181195}]}]}
{"op":"mcm","clk":"1008156424","pt":1580658549889,"mc":[{"id":"1.168237984","rc":[{"batl":[[2,1.89,226.48]],"ltp":1.7,"tv":10061.22,"id":13181195}]}]}
{"op":"mcm","clk":"1008156688","pt":1580658551352,"mc":[{"id":"1.168237984","rc":[{"batb":[[0,1.74,494.03],[1,1.72,536.43],[2,1.69,27.21]],"ltp":1.7,"tv":10061.22,"id":13181195}]}]}
{"op":"mcm","clk":"1008157549","pt":1580658555963,"mc":[{"id":"1.168237984","rc":[{"batb":[[0,2.16,5.03],[1,2.14,4.82],[2,2.12,96.46]],"ltp":2.4,"tv":2100.45,"id":14833204}]}]}
{"op":"mcm","clk":"1008157584","pt":1580658556180,"mc":[{"id":"1.168237984","rc":[{"batb":[[0,2.14,4.82],[1,2.12,96.46],[2,1.9,134.22]],"ltp":2.4,"tv":2100.45,"id":14833204}]}]}
{"op":"mcm","clk":"1008157904","pt":1580658557960,"mc":[{"id":"1.168237984","rc":[{"batl":[[0,2.4,1.9]],"ltp":2.4,"tv":2100.45,"id":14833204},{"batb":[[0,1.69,27.21],[1,1.66,111.18],[2,1.59,33.11]],"batl":[[2,3,2.82]],"ltp":1.7,"tv":10061.22,"id":13181195}]}]}
{"op":"mcm","clk":"1008158420","pt":1580658560751,"mc":[{"id":"1.168237984","rc":[{"trd":[[2.4,9.42]],"batb":[[0,2.4,5.37],[1,2.14,4.82],[2,2.12,96.46]],"batl":[[0,2.44,1.68],[1,2.46,13.5],[2,2.5,388.68]],"ltp":2.4,"tv":2104.25,"id":14833204},{"batb":[[1,1.68,541.1],[2,1.66,447.09]],"batl":[[0,1.72,265.88],[1,1.74,299.68],[2,1.75,257.42]],"ltp":1.7,"tv":10061.22,"id":13181195}],"tv":12165.48}]}
{"op":"mcm","clk":"1008158526","pt":1580658561378,"mc":[{"id":"1.168237984","rc":[{"batb":[[0,2.4,72.41],[1,2.24,82.14],[2,2.14,4.82]],"ltp":2.4,"tv":2104.25,"id":14833204}]}]}
{"op":"mcm","clk":"1008159336","pt":1580658565668,"mc":[{"id":"1.168237984","rc":[{"trd":[[1.69,54.16]],"batb":[[0,1.68,541.23],[1,1.66,447.09],[2,1.65,182.39]],"ltp":1.69,"tv":10115.38,"id":13181195}],"tv":12219.64}]}
{"op":"mcm","clk":"1008159499","pt":1580658566667,"mc":[{"id":"1.168237984","rc":[{"batb":[[2,1.65,676.43]],"batl":[[0,1.71,177.28],[1,1.72,265.88],[2,1.74,299.68]],"ltp":1.69,"tv":10115.38,"id":13181195}]}]}
{"op":"mcm","clk":"1008159592","pt":1580658567167,"mc":[{"id":"1.168237984","rc":[{"batb":[[1,2.24,86.91],[2,2.2,5.07]],"ltp":2.4,"tv":2104.25,"id":14833204}]}]}
{"op":"mcm","clk":"1008160280","pt":1580658570891,"mc":[{"id":"1.168237984","rc":[{"batb":[[0,2.4,67.04]],"batl":[[1,2.46,6.25]],"ltp":2.4,"tv":2104.25,"id":14833204}]}]}
{"op":"mcm","clk":"1008160621","pt":1580658572792,"mc":[{"id":"1.168237984","rc":[{"trd":[[2.44,128.97]],"batl":[[0,2.44,1.6]],"ltp":2.44,"tv":2104.34,"id":14833204},{"trd":[[1.69,54.54]],"batb":[[0,1.68,541.1]],"ltp":1.69,"tv":10115.76,"id":13181195}],"tv":12220.1}]}
{"op":"mcm","clk":"1008160722","pt":1580658573281,"mc":[{"id":"1.168237984","rc":[{"batl":[[1,2.46,15.35]],"ltp":2.44,"tv":2104.34,"id":14833204},{"batl":[[1,1.72,277.26]],"ltp":1.69,"tv":10115.76,"id":13181195}]}]}
{"op":"mcm","clk":"1008161389","pt":1580658576980,"mc":[{"id":"1.168237984","rc":[{"batl":[[1,2.46,6.25],[2,2.5,1.68]],"ltp":2.44,"tv":2104.34,"id":14833204},{"batb":[[0,1.66,447.09],[1,1.65,676.43],[2,1.63,510.84]],"batl":[[1,1.72,265.88]],"ltp":1.69,"tv":10115.76,"id":13181195}]}]}
{"op":"mcm","clk":"1008161524","pt":1580658577800,"mc":[{"id":"1.168237984","rc":[{"batb":[[0,2.24,86.91],[1,2.2,5.07],[2,2.14,4.82]],"batl":[[1,2.5,1.68],[2,2.7,5.25]],"ltp":2.44,"tv":2104.34,"id":14833204},{"batb":[[0,1.65,496.73],[1,1.63,510.84],[2,1.59,33.11]],"batl":[[1,1.76,480.59],[2,1.78,497.4]],"ltp":1.69,"tv":10115.76,"id":13181195}]}]}
{"op":"mcm","clk":"1008161719","pt":1580658578808,"mc":[{"id":"1.168237984","rc":[{"batl":[[0,1.76,480.59],[1,1.78,497.4],[2,1.8,24.02]],"ltp":1.69,"tv":10115.76,"id":13181195}]}]}
{"op":"mcm","clk":"1008162078","pt":1580658580806,"mc":[{"id":"1.168237984","rc":[{"batl":[[0,1.72,2.06],[1,1.76,480.59],[2,1.78,497.4]],"ltp":1.69,"tv":10115.76,"id":13181195}]}]}
{"op":"mcm","clk":"1008162561","pt":1580658583391,"mc":[{"id":"1.168237984","rc":[{"batb":[[1,1.64,315.31],[2,1.63,698.52]],"batl":[[0,1.7,321.45],[1,1.72,313.18],[2,1.76,480.59]],"ltp":1.69,"tv":10115.76,"id":13181195}]}]}
{"op":"mcm","clk":"1008163401","pt":1580658588223,"mc":[{"id":"1.168237984","rc":[{"batb":[[1,1.63,510.84],[2,1.59,33.11]],"batl":[[0,1.72,2.06],[1,1.76,480.59],[2,1.78,497.4]],"ltp":1.69,"tv":10115.76,"id":13181195}]}]}
{"op":"mcm","clk":"1008163603","pt":1580658589299,"mc":[{"id":"1.168237984","rc":[{"batb":[[0,1.65,494.03]],"ltp":1.69,"tv":10115.76,"id":13181195}]}]}
{"op":"mcm","clk":"1008165487","pt":1580658600506,"mc":[{"id":"1.168237984","rc":[{"batl":[[0,1.76,480.59],[1,1.78,497.4],[2,1.8,24.02]],"ltp":1.69,"tv":10115.76,"id":13181195}]}]}
{"op":"mcm","clk":"1008165938","pt":1580658602823,"mc":[{"id":"1.168237984","rc":[{"batb":[[0,2.24,82.14]],"ltp":2.44,"tv":2104.34,"id":14833204},{"batl":[[0,1.81,242.37],[1,1.83,275.65],[2,1.85,19.7]],"ltp":1.69,"tv":10115.76,"id":13181195}]}]}
{"op":"mcm","clk":"1008166413","pt":1580658605426,"mc":[{"id":"1.168237984","rc":[{"batl":[[0,2.28,7.82],[1,2.3,2.75],[2,2.32,421]],"ltp":2.44,"tv":2104.34,"id":14833204},{"batb":[[0,1.77,11.37],[1,1.75,218.75],[2,1.73,302.5]],"batl":[[1,1.83,293.62]],"ltp":1.69,"tv":10115.76,"id":13181195}]}]}
{"op":"mcm","clk":"1008166621","pt":1580658606726,"mc":[{"id":"1.168237984","rc":[{"batb":[[1,1.75,311.52]],"ltp":1.69,"tv":10115.76,"id":13181195}]}]}
{"op":"mcm","clk":"1008166712","pt":1580658607316,"mc":[{"id":"1.168237984","rc":[{"batb":[[1,1.75,314.1]],"ltp":1.69,"tv":10115.76,"id":13181195}]}]}
{"op":"mcm","clk":"1008167489","pt":1580658611744,"mc":[{"id":"1.168237984","rc":[{"batb":[[2,1.74,494.03]],"batl":[[2,1.85,500.29]],"ltp":1.69,"tv":10115.76,"id":13181195}]}]}
{"op":"mcm","clk":"1008167605","pt":1580658612440,"mc":[{"id":"1.168237984","rc":[{"batb":[[2,2.16,5.28]],"ltp":2.44,"tv":2104.34,"id":14833204}]}]}
{"op":"mcm","clk":"1008168499","pt":1580658617551,"mc":[{"id":"1.168237984","rc":[{"trd":[[2.28,15.32]],"batl":[[0,2.3,2.91],[1,2.32,421],[2,2.36,80.6]],"ltp":2.28,"tv":2119.66,"id":14833204}],"tv":12235.42}]}
{"op":"mcm","clk":"1008168676","pt":1580658618527,"mc":[{"id":"1.168237984","rc":[{"batb":[[0,1.75,314.1],[1,1.74,494.03],[2,1.73,302.5]],"ltp":1.69,"tv":10115.76,"id":13181195}]}]}
{"op":"mcm","clk":"1008169589","pt":1580658624010,"mc":[{"id":"1.168237984","rc":[{"batb":[[0,2.16,5.28],[1,2.14,4.82],[2,2.12,5.29]],"batl":[[0,2.36,80.6],[1,2.42,4.56],[2,2.44,1.6]],"ltp":2.28,"tv":2119.66,"id":14833204},{"batb":[[0,1.75,2.58],[2,1.72,510.84]],"batl":[[0,1.85,480.59],[1,1.86,20.75],[2,1.87,515.9]],"ltp":1.69,"tv":10115.76,"id":13181195}]}]}
{"op":"mcm","clk":"1008169805","pt":1580658625019,"mc":[{"id":"1.168237984","rc":[{"batl":[[0,2.42,4.56],[1,2.44,1.6],[2,2.48,4.74]],"ltp":2.28,"tv":2119.66,"id":14833204}]}]}
{"op":"mcm","clk":"1008170524","pt":1580658629451,"mc":[{"id":"1.168237984","rc":[{"batb":[[2,1.73,207.52]],"batl":[[0,1.79,279.77],[1,1.81,263.59],[2,1.85,480.59]],"ltp":1.69,"tv":10115.76,"id":13181195}]}]}
{"op":"mcm","clk":"1008171366","pt":1580658634174,"mc":[{"id":"1.168237984","rc":[{"batb":[[2,1.72,510.84]],"batl":[[0,1.85,480.59],[1,1.86,20.75],[2,1.87,515.9]],"ltp":1.69,"tv":10115.76,"id":13181195}]}]}
{"op":"mcm","clk":"1008171559","pt":1580658635059,"mc":[{"id":"1.168237984","rc":[{"batb":[[0,1.74,494.03],[1,1.72,510.84],[2,1.71,21.19]],"ltp":1.69,"tv":10115.76,"id":13181195}]}]}
{"op":"mcm","clk":"1008172765","pt":1580658641668,"mc":[{"id":"1.168237984","rc":[{"batb":[[0,2.12,5.29],[1,2.1,98.35],[2,1.9,134.22]],"ltp":2.28,"tv":2119.66,"id":14833204},{"batl":[[0,1.89,182.49],[1,1.91,223.1],[2,2.3,1.1]],"ltp":1.69,"tv":10115.76,"id":13181195}]}]}
{"op":"mcm","clk":"1008173186","pt":1580658643767,"mc":[{"id":"1.168237984","rc":[{"batl":[[0,2.18,430],[1,2.2,19.39],[2,2.24,86.48]],"ltp":2.28,"tv":2119.66,"id":14833204},{"batb":[[0,1.84,10.22],[1,1.83,305.31],[2,1.81,260.32]],"batl":[[0,1.89,192.45],[2,1.97,487]],"ltp":1.69,"tv":10115.76,"id":13181195}]}]}
{"op":"mcm","clk":"1008173436","pt":1580658644971,"mc":[{"id":"1.168237984","rc":[{"batb":[[2,2.02,111.18]],"ltp":2.28,"tv":2119.66,"id":14833204},{"batb":[[0,1.85,2.59],[1,1.84,88.67],[2,1.83,305.31]],"ltp":1.69,"tv":10115.76,"id":13181195}]}]}
{"op":"mcm","clk":"1008174553","pt":1580658651278,"mc":[{"id":"1.168237984","rc":[{"batb":[[1,2.1,103.39],[2,2.08,5.31]],"ltp":2.28,"tv":2119.66,"id":14833204},{"batl":[[1,1.9,19.85],[2,1.91,244.6]],"ltp":1.69,"tv":10115.76,"id":13181195}]}]}
{"op":"mcm","clk":"1008175580","pt":1580658657570,"mc":[{"id":"1.168237984","rc":[{"batl":[[0,1.89,1175.7]],"ltp":1.69,"tv":10115.76,"id":13181195}]}]}
{"op":"mcm","clk":"1008176346","pt":1580658662015,"mc":[{"id":"1.168237984","rc":[{"batl":[[0,2.2,2.83],[1,2.24,86.48],[2,2.26,4.75]],"ltp":2.28,"tv":2119.66,"id":14833204},{"batl":[[0,1.89,1165.74]],"ltp":1.69,"tv":10115.76,"id":13181195}]}]}
{"op":"mcm","clk":"1008176498","pt":1580658662985,"mc":[{"id":"1.168237984","rc":[{"batb":[[0,2.02,111.18],[1,1.9,134.22],[2,1.89,1.82]],"batl":[[0,2.3,4.35],[1,2.44,1.6],[2,2.5,1.68]],"ltp":2.28,"tv":2119.66,"id":14833204},{"batb":[[1,1.77,22.37],[2,1.75,92.14]],"batl":[[0,1.91,21.5],[1,2.3,1.1],[2,3,2.82]],"ltp":1.69,"tv":10115.76,"id":13181195}]}]}
{"op":"mcm","clk":"1008176963","pt":1580658665882,"mc":[{"id":"1.168237984","rc":[{"batb":[[0,2.08,4.81],[1,2.02,111.18],[2,1.9,134.22]],"ltp":2.28,"tv":2119.66,"id":14833204},{"batb":[[2,1.75,395.34]],"batl":[[1,1.95,161.23],[2,1.97,203.13]],"ltp":1.69,"tv":10115.76,"id":13181195}]}]}
{"op":"mcm","clk":"1008177103","pt":1580658666685,"mc":[{"id":"1.168237984","rc":[{"batl":[[1,2.3,1.1],[2,3,2.82]],"ltp":1.69,"tv":10115.76,"id":13181195}]}]}
{"op":"mcm","clk":"1008177414","pt":1580658668795,"mc":[{"id":"1.168237984","rc":[{"trd":[[1.85,4.84]],"batb":[[0,1.77,22.37],[1,1.75,395.34],[2,1.73,302.8]],"ltp":1.85,"tv":10120.59,"id":13181195}],"tv":12240.25}]}
{"op":"mcm","clk":"1008177614","pt":1580658670002,"mc":[{"id":"1.168237984","rc":[{"batb":[[0,2.1,5.84],[1,2.08,4.81],[2,2.02,111.18]],"batl":[[1,2.32,441],[2,2.44,1.6]],"ltp":2.28,"tv":2119.66,"id":14833204},{"trd":[[1.8,23.18]],"batb":[[1,1.76,760.48],[2,1.75,395.34]],"batl":[[0,1.81,161.46],[1,1.83,254.92],[2,1.85,115.11]],"ltp":1.8,"tv":10143.77,"id":13181195}],"tv":12263.43}]}
{"op":"mcm","clk":"1008177694","pt":1580658670482,"mc":[{"id":"1.168237984","rc":[{"batb":[[0,2.22,82.77],[1,2.1,5.84],[2,2.08,106.39]],"ltp":2.28,"tv":2119.66,"id":14833204}]}]}
{"op":"mcm","clk":"1008178127","pt":1580658673135,"mc":[{"id":"1.168237984","rc":[{"batl":[[2,2.82,231.28]],"ltp":2.28,"tv":2119.66,"id":14833204}]}]}
{"op":"mcm","clk":"1008178657","pt":1580658675995,"mc":[{"id":"1.168237984","rc":[{"batl":[[2,1.85,595.7]],"ltp":1.8,"tv":10143.77,"id":13181195}]}]}
{"op":"mcm","clk":"1008178704","pt":1580658676300,"mc":[{"id":"1.168237984","rc":[{"batb":[[1,2.12,5.29],[2,2.1,5.84]],"batl":[[2,2.44,4.08]],"ltp":2.28,"tv":2119.66,"id":14833204},{"batl":[[0,1.81,1244.38]],"ltp":1.8,"tv":10143.77,"id":13181195}]}]}
{"op":"mcm","clk":"1008179290","pt":1580658679595,"mc":[{"id":"1.168237984","rc":[{"batb":[[1,1.76,747.83]],"ltp":1.8,"tv":10143.77,"id":13181195}]}]}
{"op":"mcm","clk":"1008179778","pt":1580658682631,"mc":[{"id":"1.168237984","rc":[{"batl":[[0,2.28,8.74],[1,2.3,4.35],[2,2.32,441]],"ltp":2.28,"tv":2119.66,"id":14833204},{"batl":[[1,1.83,271.76]],"ltp":1.8,"tv":10143.77,"id":13181195}]}]}
{"op":"mcm","clk":"1008180143","pt":1580658685002,"mc":[{"id":"1.168237984","rc":[{"batb":[[1,2.1,5.84],[2,2.08,101.58]],"batl":[[0,2.44,4.08],[1,2.5,4.15],[2,2.82,231.28]],"ltp":2.28,"tv":2119.66,"id":14833204},{"batb":[[0,1.75,395.34],[1,1.73,796.83],[2,1.71,510.84]],"batl":[[0,1.81,161.46],[1,1.83,254.92],[2,1.85,480.59]],"ltp":1.8,"tv":10143.77,"id":13181195}]}]}
{"op":"mcm","clk":"1008180176","pt":1580658685232,"mc":[{"id":"1.168237984","rc":[{"batb":[[0,2.1,5.84],[1,2.08,101.58],[2,1.9,134.22]],"ltp":2.28,"tv":2119.66,"id":14833204},{"batb":[[0,1.73,494.03],[1,1.71,510.84],[2,1.7,26.62]],"batl":[[0,1.85,480.59],[1,1.87,497.4],[2,1.88,20.29]],"ltp":1.8,"tv":10143.77,"id":13181195}]}]}
{"op":"mcm","clk":"1008180653","pt":1580658687941,"mc":[{"id":"1.168237984","rc":[{"batl":[[2,2.52,4.01]],"ltp":2.28,"tv":2119.66,"id":14833204}]}]}
{"op":"mcm","clk":"1008180762","pt":1580658688509,"mc":[{"id":"1.168237984","rc":[{"batb":[[1,2.08,106.89]],"ltp":2.28,"tv":2119.66,"id":14833204}]}]}
{"op":"mcm","clk":"1008182720","pt":1580658701948,"mc":[{"id":"1.168237984","rc":[{"batb":[[0,2.12,5.29],[1,2.1,5.84],[2,2.08,106.89]],"ltp":2.28,"tv":2119.66,"id":14833204},{"batb":[[0,1.7,26.62],[1,1.67,30.47],[2,1.66,23.78]],"ltp":1.8,"tv":10143.77,"id":13181195}]}]}
{"op":"mcm","clk":"1008182837","pt":1580658702638,"mc":[{"id":"1.168237984","rc":[{"batb":[[0,2.1,44.03],[1,2.08,106.89],[2,1.9,134.22]],"batl":[[0,2.5,4.15],[1,2.52,4.01],[2,2.82,231.28]],"ltp":2.28,"tv":2119.66,"id":14833204},{"batb":[[0,1.67,30.47],[1,1.66,23.78],[2,1.63,117.55]],"ltp":1.8,"tv":10143.77,"id":13181195}]}]}
{"op":"mcm","clk":"1008183039","pt":1580658703952,"mc":[{"id":"1.168237984","rc":[{"batb":[[0,2.18,35.6],[1,2.1,44.03],[2,2.08,106.89]],"ltp":2.28,"tv":2119.66,"id":14833204}]}]}
{"op":"mcm","clk":"1008183168","pt":1580658704745,"mc":[{"id":"1.168237984","rc":[{"batb":[[0,2.46,6.52],[1,2.18,35.6],[2,2.1,44.03]],"batl":[[2,2.56,749.87]],"ltp":2.28,"tv":2119.66,"id":14833204},{"batb":[[1,1.66,32.89]],"batl":[[0,1.7,295.39],[1,1.73,733.76],[2,1.83,2104.72]],"ltp":1.8,"tv":10143.77,"id":13181195}]}]}
{"op":"mcm","clk":"1008183345","pt":1580658705963,"mc":[{"id":"1.168237984","rc":[{"batb":[[0,2.46,69.47],[1,2.26,80.1],[2,2.18,35.6]],"ltp":2.28,"tv":2119.66,"id":14833204},{"batb":[[2,1.64,230.27]],"batl":[[0,1.69,242.16],[1,1.7,295.39],[2,1.71,317.71]],"ltp":1.8,"tv":10143.77,"id":13181195}]}]}
{"op":"mcm","clk":"1008183465","pt":1580658706753,"mc":[{"id":"1.168237984","rc":[{"batb":[[2,2.1,44.03]],"ltp":2.28,"tv":2119.66,"id":14833204}]}]}
{"op":"mcm","clk":"1008183564","pt":1580658707436,"mc":[{"id":"1.168237984","rc":[{"batb":[[2,2.1,5.84]],"ltp":2.28,"tv":2119.66,"id":14833204}]}]}
{"op":"mcm","clk":"1008184281","pt":1580658711846,"mc":[{"id":"1.168237984","rc":[{"batb":[[2,2.22,4.84]],"ltp":2.28,"tv":2119.66,"id":14833204}]}]}
{"op":"mcm","clk":"1008185443","pt":1580658719243,"mc":[{"id":"1.168237984","rc":[{"trd":[[1.67,4]],"batb":[[0,1.67,28.47]],"ltp":1.67,"tv":10147.77,"id":13181195}],"tv":12267.43}]}
{"op":"mcm","clk":"1008186434","pt":1580658725865,"mc":[{"id":"1.168237984","rc":[{"batb":[[0,2.46,62.95]],"batl":[[0,2.9,3.35],[1,3.1,2.85],[2,3.15,200.42]],"ltp":2.28,"tv":2119.66,"id":14833204},{"batb":[[0,1.63,611.59],[1,1.61,510.84],[2,1.53,37.33]],"batl":[[0,1.7,295.39],[1,1.73,697.35],[2,1.75,497.4]],"ltp":1.67,"tv":10147.77,"id":13181195}]}]}
{"op":"mcm","clk":"1008186529","pt":1580658726450,"mc":[{"id":"1.168237984","rc":[{"batb":[[0,2.26,80.1],[1,2.22,4.84],[2,2.16,5.28]],"ltp":2.28,"tv":2119.66,"id":14833204},{"batb":[[0,1.63,494.03]],"batl":[[0,1.73,480.59],[1,1.75,497.4],[2,1.81,21.5]],"ltp":1.67,"tv":10147.77,"id":13181195}]}]}
{"op":"mcm","clk":"1008186725","pt":1580658727882,"mc":[{"id":"1.168237984","rc":[{"batl":[[0,1.67,28.22],[1,1.73,480.59],[2,1.75,497.4]],"ltp":1.67,"tv":10147.77,"id":13181195}]}]}
{"op":"mcm","clk":"1008186892","pt":1580658728904,"mc":[{"id":"1.168237984","rc":[{"batl":[[0,1.73,480.59],[1,1.75,497.4],[2,1.8,174.52]],"ltp":1.67,"tv":10147.77,"id":13181195}]}]}
{"op":"mcm","clk":"1008187110","pt":1580658730166,"mc":[{"id":"1.168237984","rc":[{"batl":[[2,1.81,21.5]],"ltp":1.67,"tv":10147.77,"id":13181195}]}]}
{"op":"mcm","clk":"1008187711","pt":1580658733884,"mc":[{"id":"1.168237984","rc":[{"batb":[[1,1.61,820.19],[2,1.6,200.83]],"batl":[[0,1.66,215.88],[1,1.68,337.59],[2,1.73,480.59]],"ltp":1.67,"tv":10147.77,"id":13181195}]}]}
{"op":"mcm","clk":"1008188387","pt":1580658738590,"mc":[{"id":"1.168237984","rc":[{"batb":[[1,1.61,510.84],[2,1.53,37.33]],"batl":[[0,1.73,480.59],[1,1.75,497.4],[2,1.81,21.5]],"ltp":1.67,"tv":10147.77,"id":13181195}]}]}
{"op":"mcm","clk":"1008188814","pt":1580658741490,"mc":[{"id":"1.168237984","rc":[{"batl":[[2,1.8,174.52]],"ltp":1.67,"tv":10147.77,"id":13181195}]}]}
{"op":"mcm","clk":"1008189014","pt":1580658742892,"mc":[{"id":"1.168237984","rc":[{"batl":[[0,3.1,2.85],[1,3.15,200.42],[2,1000,0.02]],"ltp":2.28,"tv":2119.66,"id":14833204},{"batb":[[0,1.52,154.3],[1,1.51,419.19],[2,1.5,258.22]],"batl":[[2,1.81,21.5]],"ltp":1.67,"tv":10147.77,"id":13181195}]}]}
{"op":"mcm","clk":"1008189340","pt":1580658744984,"mc":[{"id":"1.168237984","rc":[{"batb":[[0,2.76,2359.45],[1,2.26,80.1],[2,2.22,4.84]],"batl":[[0,2.92,8.95],[1,2.96,364],[2,3,264.8]],"ltp":2.28,"tv":2119.66,"id":14833204},{"batb":[[2,1.5,787.83]],"batl":[[0,1.56,22.33],[1,1.58,2359.45],[2,1.59,4567.6]],"ltp":1.67,"tv":10147.77,"id":13181195}]}]}
{"op":"mcm","clk":"1008189478","pt":1580658745985,"mc":[{"id":"1.168237984","rc":[{"batb":[[0,2.78,45.56],[1,2.76,235.94],[2,2.48,61.61]],"ltp":2.28,"tv":2119.66,"id":14833204},{"batl":[[0,1.56,346.57],[1,1.57,212.99],[2,1.58,235.94]],"ltp":1.67,"tv":10147.77,"id":13181195}]}]}
{"op":"mcm","clk":"1008190314","pt":1580658750871,"mc":[{"id":"1.168237984","rc":[{"batl":[[0,1.56,500.33]],"ltp":1.67,"tv":10147.77,"id":13181195}]}]}
{"op":"mcm","clk":"1008190418","pt":1580658751460,"mc":[{"id":"1.168237984","rc":[{"batl":[[0,1.55,1592.9],[1,1.56,500.33],[2,1.57,212.99]],"ltp":1.67,"tv":10147.77,"id":13181195}]}]}
{"op":"mcm","clk":"1008190758","pt":1580658753688,"mc":[{"id":"1.168237984","rc":[{"trd":[[1.55,2.02]],"batl":[[0,1.55,1591.89]],"ltp":1.55,"tv":10149.79,"id":13181195}],"tv":12269.45}]}
{"op":"mcm","clk":"1008191663","pt":1580658759797,"mc":[{"id":"1.168237984","rc":[{"trd":[[1.52,1.08]],"batb":[[0,1.52,153.76]],"ltp":1.52,"tv":10150.87,"id":13181195}],"tv":12270.53}]}
{"op":"mcm","clk":"1008192630","pt":1580658765810,"mc":[{"id":"1.168237984","rc":[{"batb":[[0,2.48,61.61],[1,2.4,4.36],[2,2.22,4.84]],"batl":[[0,3.65,170.41],[1,3.75,2.02],[2,4.1,2.05]],"ltp":2.28,"tv":2119.66,"id":14833204},{"batb":[[0,1.41,208.51],[1,1.37,50.77],[2,1.35,544.79]],"batl":[[0,1.56,153.76],[1,1.71,24.81],[2,1.77,25.5]],"ltp":1.52,"tv":10150.87,"id":13181195}]}]}
{"op":"mcm","clk":"1008192952","pt":1580658767922,"mc":[{"id":"1.168237984","rc":[{"batl":[[0,1.71,24.81],[1,1.77,25.5],[2,1.81,21.5]],"ltp":1.52,"tv":10150.87,"id":13181195}]}]}
{"op":"mcm","clk":"1008193097","pt":1580658768817,"mc":[{"id":"1.168237984","rc":[{"batb":[[1,2.28,5.16]],"ltp":2.28,"tv":2119.66,"id":14833204},{"batl":[[0,1.77,25.62],[1,1.81,21.5],[2,1.86,21.75]],"ltp":1.52,"tv":10150.87,"id":13181195}]}]}
{"op":"mcm","clk":"1008193606","pt":1580658772004,"mc":[{"id":"1.168237984","rc":[{"batb":[[0,1.49,233.76],[1,1.48,271.42],[2,1.41,208.51]],"batl":[[0,1.53,325.12],[1,1.54,228.96],[2,1.77,25.5]],"ltp":1.52,"tv":10150.87,"id":13181195}]}]}
{"op":"mcm","clk":"1008194064","pt":1580658774890,"mc":[{"id":"1.168237984","rc":[{"batb":[[1,2.4,3.91],[2,2.28,5.16]],"ltp":2.28,"tv":2119.66,"id":14833204},{"batl":[[2,1.71,21.5]],"ltp":1.52,"tv":10150.87,"id":13181195}]}]}
{"op":"mcm","clk":"1008194443","pt":1580658777509,"mc":[{"id":"1.168237984","rc":[{"batb":[[1,2.28,5.16],[2,2.22,4.84]],"ltp":2.28,"tv":2119.66,"id":14833204},{"batb":[[0,1.41,208.51],[1,1.37,50.77],[2,1.35,544.79]],"batl":[[0,1.77,25.5],[1,1.81,21.5],[2,1.86,21.75]],"ltp":1.52,"tv":10150.87,"id":13181195}]}]}
{"op":"mcm","clk":"1008194839","pt":1580658780006,"mc":[{"id":"1.168237984","rc":[{"batb":[[1,1.38,574.5],[2,1.37,435.94]],"batl":[[0,1.68,221.36],[1,1.7,324.18],[2,1.77,25.5]],"ltp":1.52,"tv":10150.87,"id":13181195}]}]}
{"op":"mcm","clk":"1008194937","pt":1580658780624,"mc":[{"id":"1.168237984","rc":[{"batb":[[1,2.4,4.81],[2,2.28,5.16]],"ltp":2.28,"tv":2119.66,"id":14833204},{"batl":[[2,1.71,27.81]],"ltp":1.52,"tv":10150.87,"id":13181195}]}]}
{"op":"mcm","clk":"1008195660","pt":1580658784913,"mc":[{"id":"1.168237984","rc":[{"batb":[[0,1.53,6.73],[1,1.41,208.51],[2,1.38,574.5]],"ltp":1.52,"tv":10150.87,"id":13181195}]}]}
{"op":"mcm","clk":"1008195900","pt":1580658786338,"mc":[{"id":"1.168237984","rc":[{"batb":[[2,1.37,50.77]],"ltp":1.52,"tv":10150.87,"id":13181195}]}]}
{"op":"mcm","clk":"1008196092","pt":1580658787635,"mc":[{"id":"1.168237984","rc":[{"batl":[[0,3.75,2.02],[1,4.1,2.05],[2,4.2,2.03]],"ltp":2.28,"tv":2119.66,"id":14833204}]}]}
{"op":"mcm","clk":"1008196327","pt":1580658789045,"mc":[{"id":"1.168237984","rc":[{"batb":[[2,2.36,517.23]],"batl":[[0,2.5,3000],[1,2.54,2410.2],[2,2.56,9.83]],"ltp":2.28,"tv":2119.66,"id":14833204},{"batb":[[0,1.41,208.51],[1,1.37,50.77],[2,1.35,544.79]],"batl":[[0,1.68,235.91]],"ltp":1.52,"tv":10150.87,"id":13181195}]}]}
{"op":"mcm","clk":"1008196505","pt":1580658790023,"mc":[{"id":"1.168237984","rc":[{"trd":[[2.48,4],[2.5,3.52]],"batb":[[0,2.48,59.61]],"batl":[[0,2.5,296.48],[1,2.56,9.83],[2,2.6,883.12]],"ltp":2.5,"tv":2127.18,"id":14833204},{"trd":[[1.66,5.3],[1.68,4.64]],"batb":[[0,1.63,268.53],[1,1.62,311.47],[2,1.51,157.52]],"batl":[[0,1.68,233.59]],"ltp":1.66,"tv":10160.81,"id":13181195}],"tv":12287.99}]}
{"op":"mcm","clk":"1008197089","pt":1580658793518,"mc":[{"id":"1.168237984","rc":[{"batl":[[0,1.68,387.35]],"ltp":1.66,"tv":10160.81,"id":13181195}]}]}
{"op":"mcm","clk":"1008197242","pt":1580658794371,"mc":[{"id":"1.168237984","rc":[{"trd":[[2.5,3.6]],"batl":[[0,2.5,296.4]],"ltp":2.5,"tv":2127.26,"id":14833204},{"trd":[[1.66,5.42]],"ltp":1.66,"tv":10160.93,"id":13181195}],"tv":12288.19}]}
{"op":"mcm","clk":"1008197674","pt":1580658796958,"mc":[{"id":"1.168237984","rc":[{"batb":[[2,1.52,28.99]],"ltp":1.66,"tv":10160.93,"id":13181195}]}]}
{"op":"mcm","clk":"1008197782","pt":1580658797544,"mc":[{"id":"1.168237984","rc":[{"trd":[[2.5,7.59]],"batl":[[0,2.5,292.41]],"ltp":2.5,"tv":2131.25,"id":14833204},{"trd":[[1.66,11.42]],"ltp":1.66,"tv":10166.93,"id":13181195}],"tv":12298.18}]}
{"op":"mcm","clk":"1008197897","pt":1580658798132,"mc":[{"id":"1.168237984","rc":[{"trd":[[2.5,8.92]],"batl":[[0,2.5,291.08]],"ltp":2.5,"tv":2132.58,"id":14833204},{"trd":[[1.66,13.42]],"ltp":1.66,"tv":10168.93,"id":13181195}],"tv":12301.51}]}
{"op":"mcm","clk":"1008198570","pt":1580658801842,"mc":[{"id":"1.168237984","rc":[{"trd":[[2.5,591.08]],"batl":[[0,2.56,9.83],[1,2.6,883.12],[2,2.62,143.13]],"ltp":2.5,"tv":2714.74,"id":14833204}],"tv":12883.67}]}
{"op":"mcm","clk":"1008198904","pt":1580658803828,"mc":[{"id":"1.168237984","rc":[{"trd":[[1.68,9.58]],"batl":[[0,1.68,384.88]],"ltp":1.68,"tv":10173.87,"id":13181195}],"tv":12888.61}]}
{"op":"mcm","clk":"1008199910","pt":1580658809975,"mc":[{"id":"1.168237984","rc":[{"batb":[[0,2.28,78.68],[1,2.26,4.71],[2,2.2,5.12]],"batl":[[0,2.62,143.13],[1,2.98,3.25],[2,3.15,2.9]],"ltp":2.5,"tv":2714.74,"id":14833204},{"batb":[[1,1.62,191.72],[2,1.51,194.51]],"batl":[[0,1.68,370.33],[2,1.79,22.5]],"ltp":1.68,"tv":10173.87,"id":13181195}]}]}
{"op":"mcm","clk":"1008199991","pt":1580658810453,"mc":[{"id":"1.168237984","rc":[{"batl":[[0,3.15,2.9],[1,3.2,2.78],[2,3.3,191.92]],"ltp":2.5,"tv":2714.74,"id":14833204},{"batb":[[0,1.51,157.52],[1,1.47,38.67],[2,1.46,43.38]],"batl":[[0,1.68,153.76],[1,1.79,22.5],[2,1.83,21.97]],"ltp":1.68,"tv":10173.87,"id":13181195}]}]}
{"op":"mcm","clk":"1008200430","pt":1580658812999,"mc":[{"id":"1.168237984","rc":[{"batb":[[1,2.26,78.68]],"ltp":2.5,"tv":2714.74,"id":14833204},{"batb":[[0,1.51,418.78],[1,1.5,257.17],[2,1.47,38.67]],"batl":[[0,1.79,165.3],[1,1.81,263.96]],"ltp":1.68,"tv":10173.87,"id":13181195}]}]}
{"op":"mcm","clk":"1008200552","pt":1580658813668,"mc":[{"id":"1.168237984","rc":[{"batb":[[0,2.26,78.68],[1,2.2,5.12],[2,1.97,394.86]],"batl":[[0,2.98,3.25],[1,3.15,2.9],[2,3.2,2.78]],"ltp":2.5,"tv":2714.74,"id":14833204},{"batb":[[0,1.51,455.77]],"ltp":1.68,"tv":10173.87,"id":13181195}]}]}
{"op":"mcm","clk":"1008200900","pt":1580658815847,"mc":[{"id":"1.168237984","rc":[{"batb":[[0,1.51,194.51],[1,1.47,38.67],[2,1.46,43.38]],"batl":[[0,1.83,21.97],[1,2.3,1.1],[2,3,2.82]],"ltp":1.68,"tv":10173.87,"id":13181195}]}]}
{"op":"mcm","clk":"1008200948","pt":1580658816160,"mc":[{"id":"1.168237984","rc":[{"batl":[[0,3.15,2.9],[1,3.2,2.78],[2,3.3,191.92]],"ltp":2.5,"tv":2714.74,"id":14833204},{"batb":[[0,1.51,157.52]],"ltp":1.68,"tv":10173.87,"id":13181195}]}]}
{"op":"mcm","clk":"1008201206","pt":1580658817891,"mc":[{"id":"1.168237984","rc":[{"batb":[[2,1.9,134.22]],"batl":[[2,3.75,2.02]],"ltp":2.5,"tv":2714.74,"id":14833204}]}]}
{"op":"mcm","clk":"1008201381","pt":1580658818954,"mc":[{"id":"1.168237984","rc":[{"batl":[[0,2.28,197.28],[1,2.32,6.7],[2,2.36,411]],"ltp":2.5,"tv":2714.74,"id":14833204},{"batb":[[0,1.74,742.5],[1,1.72,308.27],[2,1.51,157.52]],"batl":[[0,1.79,165.3],[1,1.8,16.73],[2,1.81,263.96]],"ltp":1.68,"tv":10173.87,"id":13181195}]}]}
{"op":"mcm","clk":"1008201540","pt":1580658819893,"mc":[{"id":"1.168237984","rc":[{"batb":[[2,2.1,97.72]],"ltp":2.5,"tv":2714.74,"id":14833204},{"batb":[[1,1.73,96.39],[2,1.72,308.27]],"ltp":1.68,"tv":10173.87,"id":13181195}]}]}
{"op":"mcm","clk":"1008202928","pt":1580658828286,"mc":[{"id":"1.168237984","rc":[{"batb":[[2,2.16,5.28]],"ltp":2.5,"tv":2714.74,"id":14833204},{"batl":[[1,1.8,170.49]],"ltp":1.68,"tv":10173.87,"id":13181195}]}]}
{"op":"mcm","clk":"1008203188","pt":1580658829873,"mc":[{"id":"1.168237984","rc":[{"trd":[[2.28,16.88]],"batl":[[0,2.28,195.72]],"ltp":2.28,"tv":2716.3,"id":14833204},{"trd":[[1.78,2]],"ltp":1.78,"tv":10175.87,"id":13181195}],"tv":12892.17}]}
{"op":"mcm","clk":"1008203576","pt":1580658832086,"mc":[{"id":"1.168237984","rc":[{"trd":[[2.28,17.09]],"batl":[[0,2.28,195.51]],"ltp":2.28,"tv":2716.51,"id":14833204},{"trd":[[1.78,2.27]],"ltp":1.78,"tv":10176.14,"id":13181195}],"tv":12892.65}]}
{"op":"mcm","clk":"1008203840","pt":1580658833896,"mc":[{"id":"1.168237984","rc":[{"trd":[[2.28,408.11]],"batl":[[0,2.32,6.7],[1,2.36,411],[2,2.4,81.41]],"ltp":2.28,"tv":3107.53,"id":14833204}],"tv":13283.67}]}
{"op":"mcm","clk":"1008204690","pt":1580658838887,"mc":[{"id":"1.168237984","rc":[{"batb":[[0,2.16,5.28],[1,2.12,5.79],[2,2.1,97.72]],"batl":[[0,2.48,3.74],[1,2.54,3.88],[2,2.92,221.26]],"ltp":2.28,"tv":3107.53,"id":14833204},{"batb":[[0,1.68,27.61],[1,1.65,27.93],[2,1.61,123.14]],"batl":[[0,1.8,153.76],[1,1.86,21.75],[2,1.89,19.5]],"ltp":1.78,"tv":10176.14,"id":13181195}]}]}
{"op":"mcm","clk":"1008204720","pt":1580658839098,"mc":[{"id":"1.168237984","rc":[{"batl":[[0,2.54,3.88],[1,2.92,221.26],[2,1000,0.02]],"ltp":2.28,"tv":3107.53,"id":14833204},{"batb":[[0,1.65,27.93],[1,1.61,123.14],[2,1.35,544.79]],"ltp":1.78,"tv":10176.14,"id":13181195}]}]}
{"op":"mcm","clk":"1008204944","pt":1580658840463,"mc":[{"id":"1.168237984","rc":[{"batb":[[0,2.12,5.79],[1,2.1,97.72],[2,1.9,134.22]],"ltp":2.28,"tv":3107.53,"id":14833204},{"batl":[[0,1.89,19.5],[1,2.3,1.1],[2,3,2.82]],"ltp":1.78,"tv":10176.14,"id":13181195}]}]}
{"op":"mcm","clk":"1008205504","pt":1580658843980,"mc":[{"id":"1.168237984","rc":[{"trd":[[1.65,4]],"batb":[[0,1.71,272.05],[1,1.69,327.93],[2,1.65,25.93]],"batl":[[0,1.77,246.4],[1,1.79,273.24],[2,1.89,19.5]],"ltp":1.65,"tv":10180.14,"id":13181195}],"tv":13287.67}]}
{"op":"mcm","clk":"1008205781","pt":1580658845720,"mc":[{"id":"1.168237984","rc":[{"batb":[[0,2.14,36.85],[1,2.12,5.79],[2,2.1,97.72]],"batl":[[0,2.48,3.99],[1,2.54,3.88],[2,2.92,221.26]],"ltp":2.28,"tv":3107.53,"id":14833204},{"batb":[[2,1.68,24.61]],"ltp":1.65,"tv":10180.14,"id":13181195}]}]}
{"op":"mcm","clk":"1008206012","pt":1580658847177,"mc":[{"id":"1.168237984","rc":[{"batb":[[0,2.16,5.03],[1,2.14,36.85],[2,2.12,5.79]],"ltp":2.28,"tv":3107.53,"id":14833204},{"batl":[[2,1.86,19.75]],"ltp":1.65,"tv":10180.14,"id":13181195}]}]}
{"op":"mcm","clk":"1008206574","pt":1580658851023,"mc":[{"id":"1.168237984","rc":[{"batb":[[0,1.68,24.61],[1,1.65,25.93],[2,1.61,123.14]],"batl":[[0,1.86,19.75],[1,1.89,19.5],[2,2.3,1.1]],"ltp":1.65,"tv":10180.14,"id":13181195}]}]}
{"op":"mcm","clk":"1008206614","pt":1580658851215,"mc":[{"id":"1.168237984","rc":[{"batb":[[0,2.14,36.85],[1,2.12,5.79],[2,2.1,97.72]],"batl":[[0,2.54,3.88],[1,2.92,221.26],[2,1000,0.02]],"ltp":2.28,"tv":3107.53,"id":14833204},{"batb":[[0,1.65,25.93],[1,1.61,123.14],[2,1.35,544.79]],"batl":[[0,1.89,19.5],[1,2.3,1.1],[2,3,2.82]],"ltp":1.65,"tv":10180.14,"id":13181195}]}]}
{"op":"mcm","clk":"1008206833","pt":1580658852492,"mc":[{"id":"1.168237984","rc":[{"batb":[[0,2.18,35.6],[1,2.14,36.85],[2,2.12,5.79]],"ltp":2.28,"tv":3107.53,"id":14833204}]}]}
{"op":"mcm","clk":"1008207085","pt":1580658854026,"mc":[{"id":"1.168237984","rc":[{"batb":[[1,1.62,301.96],[2,1.61,319.35]],"batl":[[1,1.9,260.29],[2,1.92,219.34]],"ltp":1.65,"tv":10180.14,"id":13181195}]}]}
{"op":"mcm","clk":"1008208871","pt":1580658865348,"mc":[{"id":"1.168237984","rc":[{"batb":[[1,1.61,123.14],[2,1.35,544.79]],"ltp":1.65,"tv":10180.14,"id":13181195}]}]}
{"op":"mcm","clk":"1008209093","pt":1580658866716,"mc":[{"id":"1.168237984","rc":[{"batb":[[0,2.14,36.85],[1,2.12,5.79],[2,2.1,97.72]],"ltp":2.28,"tv":3107.53,"id":14833204}]}]}
{"op":"mcm","clk":"1008209188","pt":1580658867341,"mc":[{"id":"1.168237984","rc":[{"batb":[[0,2.12,5.79],[1,2.1,97.72],[2,2.06,39.63]],"batl":[[1,1000,0.02],[2,1000,0]],"ltp":2.28,"tv":3107.53,"id":14833204}]}]}
{"op":"mcm","clk":"1008209433","pt":1580658868944,"mc":[{"id":"1.168237984","rc":[{"batl":[[0,2.2,949.28],[1,2.48,3.49],[2,2.54,3.88]],"ltp":2.28,"tv":3107.53,"id":14833204},{"batb":[[0,1.84,117.65],[1,1.83,220.96],[2,1.81,260.31]],"batl":[[0,1.89,29.51]],"ltp":1.65,"tv":10180.14,"id":13181195}]}]}
{"op":"mcm","clk":"1008209503","pt":1580658869447,"mc":[{"id":"1.168237984","rc":[{"batb":[[0,1.84,196.57]],"ltp":1.65,"tv":10180.14,"id":13181195}]}]}
{"op":"mcm","clk":"1008210011","pt":1580658872557,"mc":[{"id":"1.168237984","rc":[{"batb":[[0,2.12,43.3]],"ltp":2.28,"tv":3107.53,"id":14833204}]}]}
{"op":"mcm","clk":"1008210276","pt":1580658874542,"mc":[{"id":"1.168237984","rc":[{"trd":[[2.2,51.42]],"batl":[[0,2.2,937.73]],"ltp":2.2,"tv":3130.63,"id":14833204}],"tv":13310.77}]}
{"op":"mcm","clk":"1008210481","pt":1580658875775,"mc":[{"id":"1.168237984","rc":[{"batl":[[1,2.24,5.48],[2,2.28,4.84]],"ltp":2.2,"tv":3130.63,"id":14833204},{"batb":[[2,1.81,281.6]],"ltp":1.65,"tv":10180.14,"id":13181195}]}]}
{"op":"mcm","clk":"1008210572","pt":1580658876455,"mc":[{"id":"1.168237984","rc":[{"trd":[[1.84,4.24]],"batb":[[0,1.84,194.45]],"ltp":1.84,"tv":10184.38,"id":13181195}],"tv":13315.01}]}
{"op":"mcm","clk":"1008210710","pt":1580658877286,"mc":[{"id":"1.168237984","rc":[{"batl":[[0,1.88,153.76],[1,1.89,29.51],[2,1.9,260.29]],"ltp":1.84,"tv":10184.38,"id":13181195}]}]}
{"op":"mcm","clk":"1008210907","pt":1580658878655,"mc":[{"id":"1.168237984","rc":[{"batb":[[0,2.14,36.85],[1,2.12,43.3],[2,2.1,97.72]],"ltp":2.2,"tv":3130.63,"id":14833204}]}]}
{"op":"mcm","clk":"1008211410","pt":1580658881985,"mc":[{"id":"1.168237984","rc":[{"trd":[[1.88,0.25]],"batl":[[0,1.88,153.63]],"ltp":1.88,"tv":10184.63,"id":13181195}],"tv":13315.26}]}
{"op":"mcm","clk":"1008211568","pt":1580658882947,"mc":[{"id":"1.168237984","rc":[{"batl":[[0,1.87,20],[1,1.88,153.63],[2,1.89,29.51]],"ltp":1.88,"tv":10184.63,"id":13181195}]}]}
{"op":"mcm","clk":"1008213226","pt":1580658893877,"mc":[{"id":"1.168237984","rc":[{"batl":[[0,1.88,153.63],[1,1.89,29.51],[2,1.9,260.29]],"ltp":1.88,"tv":10184.63,"id":13181195}]}]}
{"op":"mcm","clk":"1008213711","pt":1580658896781,"mc":[{"id":"1.168237984","rc":[{"trd":[[1.84,44.24]],"batb":[[0,1.84,174.45]],"ltp":1.84,"tv":10224.63,"id":13181195}],"tv":13355.26}]}
{"op":"mcm","clk":"1008215184","pt":1580658905679,"mc":[{"id":"1.168237984","rc":[{"batl":[[0,2.2,512.28]],"ltp":2.2,"tv":3130.63,"id":14833204},{"batb":[[1,1.81,21.29],[2,1.79,125.8]],"batl":[[2,1.94,16.75]],"ltp":1.84,"tv":10224.63,"id":13181195}]}]}
{"op":"mcm","clk":"1008216103","pt":1580658911030,"mc":[{"id":"1.168237984","rc":[{"batb":[[1,2.12,37.51]],"batl":[[0,2.24,5.48],[1,2.28,4.84],[2,2.48,3.49]],"ltp":2.2,"tv":3130.63,"id":14833204},{"batb":[[0,1.84,78.92],[2,1.79,24.31]],"batl":[[1,1.94,16.75],[2,1.95,17.9]],"ltp":1.84,"tv":10224.63,"id":13181195}]}]}
{"op":"mcm","clk":"1008216135","pt":1580658911240,"mc":[{"id":"1.168237984","rc":[{"batb":[[2,2.06,44.21]],"batl":[[0,2.28,4.84],[1,2.48,3.49],[2,2.54,3.88]],"ltp":2.2,"tv":3130.63,"id":14833204},{"batb":[[0,1.79,24.31],[1,1.77,353.96],[2,1.75,291.09]],"ltp":1.84,"tv":10224.63,"id":13181195}]}]}
{"op":"mcm","clk":"1008216578","pt":1580658913756,"mc":[{"id":"1.168237984","rc":[{"batl":[[0,1.94,16.75],[1,1.95,17.9],[2,1.97,17.5]],"ltp":1.84,"tv":10224.63,"id":13181195}]}]}
{"op":"mcm","clk":"1008216931","pt":1580658915657,"mc":[{"id":"1.168237984","rc":[{"batb":[[0,2.12,37.51],[1,2.06,44.21],[2,2.02,5.24]],"ltp":2.2,"tv":3130.63,"id":14833204}]}]}
{"op":"mcm","clk":"1008217114","pt":1580658916845,"mc":[{"id":"1.168237984","rc":[{"batl":[[0,1.84,1.68],[1,1.94,16.75],[2,1.95,17.9]],"ltp":1.84,"tv":10224.63,"id":13181195}]}]}
{"op":"mcm","clk":"1008217281","pt":1580658917856,"mc":[{"id":"1.168237984","rc":[{"batl":[[0,2.24,5.23],[1,2.28,4.84],[2,2.48,3.49]],"ltp":2.2,"tv":3130.63,"id":14833204},{"batb":[[0,1.81,21.29],[1,1.79,24.31],[2,1.77,353.96]],"ltp":1.84,"tv":10224.63,"id":13181195}]}]}
{"op":"mcm","clk":"1008217448","pt":1580658918648,"mc":[{"id":"1.168237984","rc":[{"batb":[[0,2.2,2],[1,2.16,93.38],[2,2.12,37.51]],"batl":[[0,2.28,428.44],[1,2.3,407]],"ltp":2.2,"tv":3130.63,"id":14833204},{"batb":[[0,1.79,24.31],[1,1.77,353.96],[2,1.75,291.09]],"batl":[[0,1.82,2.25],[1,1.83,185.22],[2,1.84,1.68]],"ltp":1.84,"tv":10224.63,"id":13181195}]}]}
{"op":"mcm","clk":"1008217574","pt":1580658919462,"mc":[{"id":"1.168237984","rc":[{"batb":[[0,2.2,87.84]],"ltp":2.2,"tv":3130.63,"id":14833204},{"batl":[[2,1.85,246.24]],"ltp":1.84,"tv":10224.63,"id":13181195}]}]}
{"op":"mcm","clk":"1008217750","pt":1580658920657,"mc":[{"id":"1.168237984","rc":[{"batb":[[1,2.18,35.6],[2,2.16,93.38]],"ltp":2.2,"tv":3130.63,"id":14833204}]}]}
{"op":"mcm","clk":"1008218172","pt":1580658923045,"mc":[{"id":"1.168237984","rc":[{"batl":[[0,1.81,153.76],[1,1.82,2.25],[2,1.83,185.22]],"ltp":1.84,"tv":10224.63,"id":13181195}]}]}
{"op":"mcm","clk":"1008218304","pt":1580658923855,"mc":[{"id":"1.168237984","rc":[{"batb":[[0,2.22,34.43],[1,2.2,87.84],[2,2.18,35.6]],"ltp":2.2,"tv":3130.63,"id":14833204}]}]}
{"op":"mcm","clk":"1008218462","pt":1580658924864,"mc":[{"id":"1.168237984","rc":[{"batb":[[2,1.75,785.12]],"ltp":1.84,"tv":10224.63,"id":13181195}]}]}
{"op":"mcm","clk":"1008218578","pt":1580658925541,"mc":[{"id":"1.168237984","rc":[{"batl":[[1,2.3,411.35]],"ltp":2.2,"tv":3130.63,"id":14833204},{"batb":[[1,1.78,24.66],[2,1.77,377.33]],"ltp":1.84,"tv":10224.63,"id":13181195}]}]}
{"op":"mcm","clk":"1008218702","pt":1580658926337,"mc":[{"id":"1.168237984","rc":[{"batl":[[2,2.32,4.11]],"ltp":2.2,"tv":3130.63,"id":14833204}]}]}
{"op":"mcm","clk":"1008218837","pt":1580658927375,"mc":[{"id":"1.168237984","rc":[{"trd":[[1.79,3.36]],"batb":[[0,1.79,22.63]],"ltp":1.79,"tv":10227.99,"id":13181195}],"tv":13358.62}]}
{"op":"mcm","clk":"1008220241","pt":1580658936661,"mc":[{"id":"1.168237984","rc":[{"batb":[[1,2.18,35.6],[2,2.16,5.78]],"batl":[[0,2.32,4.11],[1,2.48,3.49],[2,2.54,3.88]],"ltp":2.2,"tv":3130.63,"id":14833204},{"batb":[[0,1.76,25.23],[1,1.75,494.03],[2,1.73,510.84]],"batl":[[0,1.79,2.47],[1,1.81,153.76],[2,1.86,501.84]],"ltp":1.79,"tv":10227.99,"id":13181195}]}]}
{"op":"mcm","clk":"1008220514","pt":1580658938261,"mc":[{"id":"1.168237984","rc":[{"batl":[[1,1.86,501.84],[2,1.88,519.94]],"ltp":1.79,"tv":10227.99,"id":13181195}]}]}
{"op":"mcm","clk":"1008220775","pt":1580658939875,"mc":[{"id":"1.168237984","rc":[{"batl":[[0,2.3,4.05],[1,2.32,4.11],[2,2.48,3.49]],"ltp":2.2,"tv":3130.63,"id":14833204},{"batb":[[0,1.77,23.37],[1,1.76,25.23],[2,1.75,494.03]],"batl":[[0,1.86,501.84],[1,1.88,519.94],[2,1.92,243.32]],"ltp":1.79,"tv":10227.99,"id":13181195}]}]}
{"op":"mcm","clk":"1008221277","pt":1580658942885,"mc":[{"id":"1.168237984","rc":[{"batl":[[2,2.34,4.28]],"ltp":2.2,"tv":3130.63,"id":14833204},{"batb":[[2,1.75,519.38]],"batl":[[2,1.89,21.5]],"ltp":1.79,"tv":10227.99,"id":13181195}]}]}
{"op":"mcm","clk":"1008221702","pt":1580658945578,"mc":[{"id":"1.168237984","rc":[{"batb":[[0,2.18,35.6],[1,2.16,5.78],[2,2.12,42.55]],"ltp":2.2,"tv":3130.63,"id":14833204}]}]}
{"op":"mcm","clk":"1008222823","pt":1580658952192,"mc":[{"id":"1.168237984","rc":[{"batl":[[0,2.34,4.28],[1,2.36,4.32],[2,2.48,3.49]],"ltp":2.2,"tv":3130.63,"id":14833204},{"batb":[[0,1.75,519.38],[1,1.74,28.02],[2,1.73,698.14]],"ltp":1.79,"tv":10227.99,"id":13181195}]}]}
{"op":"mcm","clk":"1008223191","pt":1580658954677,"mc":[{"id":"1.168237984","rc":[{"batl":[[0,2.36,4.32],[1,2.48,3.49],[2,2.54,3.88]],"ltp":2.2,"tv":3130.63,"id":14833204},{"batb":[[0,1.74,28.02],[1,1.73,187.3],[2,1.72,98.82]],"ltp":1.79,"tv":10227.99,"id":13181195}]}]}
{"op":"mcm","clk":"1008223378","pt":1580658955716,"mc":[{"id":"1.168237984","rc":[{"batl":[[0,1.77,5.57],[1,1.86,501.84],[2,1.88,519.94]],"ltp":1.79,"tv":10227.99,"id":13181195}]}]}
{"op":"mcm","clk":"1008223583","pt":1580658956879,"mc":[{"id":"1.168237984","rc":[{"batb":[[0,2.22,975.46],[1,2.18,35.6],[2,2.16,5.78]],"batl":[[0,2.36,375.79],[1,2.4,432],[2,2.48,3.49]],"ltp":2.2,"tv":3130.63,"id":14833204},{"batb":[[0,1.74,39.55]],"batl":[[1,1.78,4589.39],[2,1.82,503]],"ltp":1.79,"tv":10227.99,"id":13181195}]}]}
{"op":"mcm","clk":"1008223762","pt":1580658957997,"mc":[{"id":"1.168237984","rc":[{"batb":[[0,2.3,76.56],[1,2.26,2],[2,2.22,97.55]],"ltp":2.2,"tv":3130.63,"id":14833204},{"batl":[[1,1.78,293.21],[2,1.79,3.5]],"ltp":1.79,"tv":10227.99,"id":13181195}]}]}
{"op":"mcm","clk":"1008224172","pt":1580658960491,"mc":[{"id":"1.168237984","rc":[{"batb":[[0,2.3,108.87]],"ltp":2.2,"tv":3130.63,"id":14833204},{"batl":[[0,1.78,293.21],[1,1.79,3.5],[2,1.8,268.68]],"ltp":1.79,"tv":10227.99,"id":13181195}]}]}
{"op":"mcm","clk":"1008224353","pt":1580658961609,"mc":[{"id":"1.168237984","rc":[{"batl":[[0,1.77,153.76],[1,1.78,293.21],[2,1.79,3.5]],"ltp":1.79,"tv":10227.99,"id":13181195}]}]}
{"op":"mcm","clk":"1008224684","pt":1580658963542,"mc":[{"id":"1.168237984","rc":[{"trd":[[1.74,11.14]],"batb":[[0,1.74,33.98]],"ltp":1.74,"tv":10239.13,"id":13181195}],"tv":13369.76}]}
{"op":"mcm","clk":"1008224899","pt":1580658964799,"mc":[{"id":"1.168237984","rc":[{"batb":[[2,2.22,102.48]],"batl":[[1,2.38,3.75],[2,2.4,435.89]],"ltp":2.2,"tv":3130.63,"id":14833204},{"trd":[[1.77,0.25]],"batb":[[1,1.73,211.43],[2,1.72,124.16]],"batl":[[0,1.77,153.63]],"ltp":1.77,"tv":10239.38,"id":13181195}],"tv":13370.01}]}
{"op":"mcm","clk":"1008225049","pt":1580658965927,"mc":[{"id":"1.168237984","rc":[{"batb":[[1,2.26,35.34]],"ltp":2.2,"tv":3130.63,"id":14833204}]}]}
{"op":"mcm","clk":"1008225178","pt":1580658966621,"mc":[{"id":"1.168237984","rc":[{"batb":[[0,2.3,982.35]],"ltp":2.2,"tv":3130.63,"id":14833204}]}]}
{"op":"mcm","clk":"1008226838","pt":1580658976965,"mc":[{"id":"1.168237984","rc":[{"batb":[[0,2.3,108.87],[1,2.26,33.34]],"batl":[[0,2.4,3.89],[1,2.48,3.49],[2,2.54,3.88]],"ltp":2.2,"tv":3130.63,"id":14833204},{"batb":[[0,1.72,124.16],[1,1.7,494.03],[2,1.69,2]],"batl":[[1,1.78,115.98],[2,1.81,500.3]],"ltp":1.77,"tv":10239.38,"id":13181195}]}]}
{"op":"mcm","clk":"1008226871","pt":1580658977133,"mc":[{"id":"1.168237984","rc":[{"batb":[[0,2.3,32.31],[2,2.22,4.93]],"ltp":2.2,"tv":3130.63,"id":14833204},{"batb":[[0,1.72,25.34]],"batl":[[1,1.81,500.3],[2,1.83,522.37]],"ltp":1.77,"tv":10239.38,"id":13181195}]}]}
{"op":"mcm","clk":"1008227322","pt":1580658980028,"mc":[{"id":"1.168237984","rc":[{"batb":[[0,2.3,33.26]],"batl":[[0,2.38,4.54],[1,2.4,3.89],[2,2.48,3.49]],"ltp":2.2,"tv":3130.63,"id":14833204},{"batb":[[0,1.73,24.13],[1,1.72,25.34],[2,1.7,494.03]],"batl":[[0,1.81,500.3],[1,1.83,522.37],[2,1.84,175.54]],"ltp":1.77,"tv":10239.38,"id":13181195}]}]}
{"op":"mcm","clk":"1008227351","pt":1580658980224,"mc":[{"id":"1.168237984","rc":[{"batl":[[0,2.4,3.89],[1,2.48,3.49],[2,2.54,3.88]],"ltp":2.2,"tv":3130.63,"id":14833204},{"batb":[[0,1.72,25.34],[1,1.7,494.03],[2,1.69,323.4]],"ltp":1.77,"tv":10239.38,"id":13181195}]}]}
{"op":"mcm","clk":"1008227583","pt":1580658981544,"mc":[{"id":"1.168237984","rc":[{"batb":[[0,2.26,34.29],[1,2.22,4.93],[2,2.2,4.92]],"ltp":2.2,"tv":3130.63,"id":14833204}]}]}
{"op":"mcm","clk":"1008229619","pt":1580658993764,"mc":[{"id":"1.168237984","rc":[{"batl":[[0,2.38,4.25],[1,2.4,3.89],[2,2.48,3.49]],"ltp":2.2,"tv":3130.63,"id":14833204},{"batb":[[0,1.73,25.13],[1,1.72,25.34],[2,1.7,494.03]],"batl":[[2,2.3,1.1]],"ltp":1.77,"tv":10239.38,"id":13181195}]}]}
{"op":"mcm","clk":"1008230473","pt":1580658998864,"mc":[{"id":"1.168237984","rc":[{"batl":[[2,2.42,3.56]],"ltp":2.2,"tv":3130.63,"id":14833204},{"batb":[[2,1.71,27.19]],"batl":[[2,1.84,22.03]],"ltp":1.77,"tv":10239.38,"id":13181195}]}]}
{"op":"mcm","clk":"1008230861","pt":1580659001077,"mc":[{"id":"1.168237984","rc":[{"batl":[[0,1.8,3.36],[1,1.81,500.3],[2,1.83,522.37]],"ltp":1.77,"tv":10239.38,"id":13181195}]}]}
{"op":"mcm","clk":"1008231182","pt":1580659002877,"mc":[{"id":"1.168237984","rc":[{"trd":[[1.73,10.92]],"batb":[[0,1.73,21.13]],"ltp":1.73,"tv":10247.38,"id":13181195}],"tv":13378.01}]}
{"op":"mcm","clk":"1008231424","pt":1580659004370,"mc":[{"id":"1.168237984","rc":[{"trd":[[1.73,17.74]],"batb":[[0,1.73,17.72]],"ltp":1.73,"tv":10254.2,"id":13181195}],"tv":13384.84}]}
{"op":"mcm","clk":"1008231587","pt":1580659005372,"mc":[{"id":"1.168237984","rc":[{"batb":[[0,2.26,33.34]],"ltp":2.2,"tv":3130.63,"id":14833204}]}]}
{"op":"mcm","clk":"1008231978","pt":1580659007665,"mc":[{"id":"1.168237984","rc":[{"trd":[[2.26,0.35]],"batb":[[0,2.26,33.16]],"ltp":2.26,"tv":3130.98,"id":14833204}],"tv":13385.19}]}
{"op":"mcm","clk":"1008232531","pt":1580659011288,"mc":[{"id":"1.168237984","rc":[{"batl":[[0,1.77,22.72],[1,1.8,3.36],[2,1.81,500.3]],"ltp":1.73,"tv":10254.2,"id":13181195}]}]}
{"op":"mcm","clk":"1008232841","pt":1580659013187,"mc":[{"id":"1.168237984","rc":[{"batl":[[0,2.4,3.89],[1,2.54,3.88],[2,1000,0.02]],"ltp":2.26,"tv":3130.98,"id":14833204},{"batb":[[0,1.72,25.34],[1,1.69,2],[2,1.67,108.27]],"ltp":1.73,"tv":10254.2,"id":13181195}]}]}
{"op":"mcm","clk":"1008233018","pt":1580659014196,"mc":[{"id":"1.168237984","rc":[{"batb":[[0,2.22,4.93],[1,2.2,4.92],[2,2.18,128.58]],"ltp":2.26,"tv":3130.98,"id":14833204}]}]}
{"op":"mcm","clk":"1008233249","pt":1580659015467,"mc":[{"id":"1.168237984","rc":[{"batb":[[0,2.32,80.43],[1,2.28,95.5],[2,2.22,4.93]],"batl":[[1,2.48,417],[2,2.54,3.88]],"ltp":2.26,"tv":3130.98,"id":14833204},{"batb":[[1,1.69,323.4],[2,1.67,450.33]],"batl":[[0,1.75,229.64],[1,1.77,316.74],[2,1.78,586]],"ltp":1.73,"tv":10254.2,"id":13181195}]}]}
{"op":"mcm","clk":"1008233400","pt":1580659016477,"mc":[{"id":"1.168237984","rc":[{"batb":[[0,2.38,69.16],[1,2.32,80.43],[2,2.28,172.92]],"ltp":2.26,"tv":3130.98,"id":14833204}]}]}
{"op":"mcm","clk":"1008233942","pt":1580659019993,"mc":[{"id":"1.168237984","rc":[{"trd":[[1.72,63.19]],"batb":[[0,1.69,323.58],[1,1.67,450.33],[2,1.65,25.93]],"batl":[[0,1.73,153.76],[1,1.75,229.64],[2,1.77,316.74]],"ltp":1.72,"tv":10304.52,"id":13181195}],"tv":13435.51}]}
{"op":"mcm","clk":"1008234111","pt":1580659020900,"mc":[{"id":"1.168237984","rc":[{"batb":[[0,2.28,80.33],[1,2.22,4.93],[2,2.2,4.92]],"batl":[[0,3.15,200.42],[1,1000,0.02],[2,2.54,0]],"ltp":2.26,"tv":3130.98,"id":14833204},{"batb":[[0,1.69,2],[1,1.67,342.06],[2,1.64,114.88]],"batl":[[1,1.77,33.35],[2,1.8,3.36]],"ltp":1.72,"tv":10304.52,"id":13181195}]}]}
{"op":"mcm","clk":"1008234293","pt":1580659021889,"mc":[{"id":"1.168237984","rc":[{"batb":[[1,1.68,494.03],[2,1.67,342.06]],"batl":[[1,1.77,513.94],[2,1.79,497.4]],"ltp":1.72,"tv":10304.52,"id":13181195}]}]}
{"op":"mcm","clk":"1008234452","pt":1580659022902,"mc":[{"id":"1.168237984","rc":[{"batb":[[1,2.26,5.21],[2,2.22,4.93]],"batl":[[0,2.44,3.58],[1,3.15,200.42],[2,1000,0.02]],"ltp":2.26,"tv":3130.98,"id":14833204},{"batb":[[0,1.7,25.32],[1,1.69,2],[2,1.68,494.03]],"batl":[[2,1.79,518.9]],"ltp":1.72,"tv":10304.52,"id":13181195}]}]}
{"op":"mcm","clk":"1008234559","pt":1580659023497,"mc":[{"id":"1.168237984","rc":[{"batl":[[0,1.77,513.94],[1,1.79,772.67],[2,1.8,3.36]],"ltp":1.72,"tv":10304.52,"id":13181195}]}]}
{"op":"mcm","clk":"1008234964","pt":1580659025716,"mc":[{"id":"1.168237984","rc":[{"batb":[[2,1.9,134.22]],"ltp":2.26,"tv":3130.98,"id":14833204},{"batb":[[2,1.67,342.06]],"batl":[[1,1.79,518.9]],"ltp":1.72,"tv":10304.52,"id":13181195}]}]}
{"op":"mcm","clk":"1008235046","pt":1580659026198,"mc":[{"id":"1.168237984","rc":[{"batb":[[0,1.7,30.32]],"ltp":1.72,"tv":10304.52,"id":13181195}]}]}
{"op":"mcm","clk":"1008235194","pt":1580659027087,"mc":[{"id":"1.168237984","rc":[{"batl":[[0,1.72,1.01],[1,1.77,513.94],[2,1.79,518.9]],"ltp":1.72,"tv":10304.52,"id":13181195}]}]}
{"op":"mcm","clk":"1008235466","pt":1580659028704,"mc":[{"id":"1.168237984","rc":[{"batb":[[0,2.4,9.84],[1,2.32,459.51],[2,2.28,77.42]],"batl":[[1,2.54,410],[2,3.15,200.42]],"ltp":2.26,"tv":3130.98,"id":14833204},{"batb":[[2,1.68,425.66]],"batl":[[1,1.73,258.32],[2,1.74,111.03]],"ltp":1.72,"tv":10304.52,"id":13181195}]}]}
{"op":"mcm","clk":"1008235635","pt":1580659029721,"mc":[{"id":"1.168237984","rc":[{"trd":[[2.44,157.25]],"batb":[[0,2.44,39.89],[1,2.4,9.84],[2,2.32,459.51]],"batl":[[0,2.54,410],[1,3.15,200.42],[2,1000,0.02]],"ltp":2.44,"tv":3159.26,"id":14833204},{"trd":[[1.7,191.43]],"batb":[[0,1.69,2],[1,1.68,425.66],[2,1.67,306.69]],"ltp":1.7,"tv":10334.84,"id":13181195}],"tv":13494.11}]}
{"op":"mcm","clk":"1008235848","pt":1580659031020,"mc":[{"id":"1.168237984","rc":[{"batl":[[0,1.7,30.15],[1,1.72,1.01],[2,1.73,258.32]],"ltp":1.7,"tv":10334.84,"id":13181195}]}]}
{"op":"mcm","clk":"1008235864","pt":1580659031082,"mc":[{"id":"1.168237984","rc":[{"batl":[[0,1.72,1.01],[1,1.73,258.32],[2,1.74,111.03]],"ltp":1.7,"tv":10334.84,"id":13181195}]}]}
{"op":"mcm","clk":"1008236621","pt":1580659035447,"mc":[{"id":"1.168237984","rc":[{"trd":[[2.44,160.74]],"batb":[[0,2.44,36.41]],"ltp":2.44,"tv":3162.75,"id":14833204},{"trd":[[1.7,196.43]],"ltp":1.7,"tv":10339.84,"id":13181195}],"tv":13502.6}]}
{"op":"mcm","clk":"1008236989","pt":1580659037602,"mc":[{"id":"1.168237984","rc":[{"batb":[[0,2.4,77.03],[1,2.32,459.51],[2,2.26,5.21]],"ltp":2.44,"tv":3162.75,"id":14833204}]}]}
{"op":"mcm","clk":"1008237129","pt":1580659038403,"mc":[{"id":"1.168237984","rc":[{"batb":[[0,1.7,2],[1,1.69,2],[2,1.68,425.66]],"ltp":1.7,"tv":10339.84,"id":13181195}]}]}
{"op":"mcm","clk":"1008237674","pt":1580659041634,"mc":[{"id":"1.168237984","rc":[{"trd":[[1.7,200.43]],"batb":[[0,1.69,2],[1,1.68,425.66],[2,1.67,306.69]],"ltp":1.7,"tv":10343.84,"id":13181195}],"tv":13506.6}]}
{"op":"mcm","clk":"1008238010","pt":1580659043614,"mc":[{"id":"1.168237984","rc":[{"batb":[[0,1.7,1.68],[1,1.69,2],[2,1.68,425.66]],"ltp":1.7,"tv":10343.84,"id":13181195}]}]}
{"op":"mcm","clk":"1008238854","pt":1580659049387,"mc":[{"id":"1.168237984","rc":[{"trd":[[2.4,19.5]],"batb":[[0,2.4,71.99]],"ltp":2.4,"tv":3172.83,"id":14833204}],"tv":13516.68}]}
{"op":"mcm","clk":"1008239312","pt":1580659052129,"mc":[{"id":"1.168237984","rc":[{"batb":[[0,1.69,2],[1,1.68,425.66],[2,1.67,306.69]],"ltp":1.7,"tv":10343.84,"id":13181195}]}]}
{"op":"mcm","clk":"1008240317","pt":1580659058929,"mc":[{"id":"1.168237984","rc":[{"trd":[[2.4,19.98]],"batb":[[0,2.4,71.51]],"ltp":2.4,"tv":3173.31,"id":14833204},{"trd":[[1.72,63.86]],"batl":[[0,1.73,258.32],[1,1.74,111.03],[2,1.75,915.6]],"ltp":1.72,"tv":10344.52,"id":13181195}],"tv":13517.83}]}
{"op":"mcm","clk":"1008240417","pt":1580659059609,"mc":[{"id":"1.168237984","rc":[{"batb":[[0,2.4,67.19]],"ltp":2.4,"tv":3173.31,"id":14833204},{"batb":[[1,1.68,415.14]],"ltp":1.72,"tv":10344.52,"id":13181195}]}]}
{"op":"mcm","clk":"1008240868","pt":1580659062516,"mc":[{"id":"1.168237984","rc":[{"batl":[[0,2.46,10.1],[1,2.54,410],[2,3.15,200.42]],"ltp":2.4,"tv":3173.31,"id":14833204},{"batl":[[0,1.72,9.9],[1,1.73,258.32],[2,1.74,111.03]],"ltp":1.72,"tv":10344.52,"id":13181195}]}]}
{"op":"mcm","clk":"1008241774","pt":1580659068404,"mc":[{"id":"1.168237984","rc":[{"batb":[[0,1.69,4]],"ltp":1.72,"tv":10344.52,"id":13181195}]}]}
{"op":"mcm","clk":"1008241888","pt":1580659069115,"mc":[{"id":"1.168237984","rc":[{"batl":[[0,2.54,410],[1,3.15,200.42],[2,1000,0.02]],"ltp":2.4,"tv":3173.31,"id":14833204},{"batl":[[0,1.73,258.32],[1,1.74,111.03],[2,1.75,915.6]],"ltp":1.72,"tv":10344.52,"id":13181195}]}]}
{"op":"mcm","clk":"1008242282","pt":1580659072004,"mc":[{"id":"1.168237984","rc":[{"batl":[[0,2.46,10.1],[1,2.54,410],[2,3.15,200.42]],"ltp":2.4,"tv":3173.31,"id":14833204},{"batl":[[0,1.72,9.9],[1,1.73,258.32],[2,1.74,111.03]],"ltp":1.72,"tv":10344.52,"id":13181195}]}]}
{"op":"mcm","clk":"1008242810","pt":1580659075751,"mc":[{"id":"1.168237984","rc":[{"batb":[[0,1.69,6]],"ltp":1.72,"tv":10344.52,"id":13181195}]}]}
{"op":"mcm","clk":"1008243108","pt":1580659077829,"mc":[{"id":"1.168237984","rc":[{"batb":[[0,1.68,415.14],[1,1.67,306.69],[2,1.66,286.7]],"ltp":1.72,"tv":10344.52,"id":13181195}]}]}
{"op":"mcm","clk":"1008244264","pt":1580659085336,"mc":[{"id":"1.168237984","rc":[{"batb":[[0,1.71,15.14],[1,1.68,415.14],[2,1.67,306.69]],"ltp":1.72,"tv":10344.52,"id":13181195}]}]}
{"op":"mcm","clk":"1008245014","pt":1580659090327,"mc":[{"id":"1.168237984","rc":[{"trd":[[1.71,30.29]],"batb":[[0,1.68,415.14],[1,1.67,306.69],[2,1.66,286.7]],"ltp":1.71,"tv":10374.81,"id":13181195}],"tv":13548.12}]}
{"op":"mcm","clk":"1008246096","pt":1580659097423,"mc":[{"id":"1.168237984","rc":[{"batl":[[0,1.71,153.76],[1,1.72,9.9],[2,1.73,258.32]],"ltp":1.71,"tv":10374.81,"id":13181195}]}]}
{"op":"mcm","clk":"1008247276","pt":1580659105657,"mc":[{"id":"1.168237984","rc":[{"trd":[[1.68,58.34]],"batb":[[0,1.68,390.76]],"ltp":1.68,"tv":10423.57,"id":13181195}],"tv":13596.89}]}
{"op":"mcm","clk":"1008248718","pt":1580659115450,"mc":[{"id":"1.168237984","rc":[{"batl":[[1,3.15,200.42],[2,1000,0.02]],"ltp":2.4,"tv":3173.31,"id":14833204}]}]}
{"op":"mcm","clk":"1008249339","pt":1580659119453,"mc":[{"id":"1.168237984","rc":[{"batl":[[0,1.7,9.75],[1,1.71,153.76],[2,1.72,9.9]],"ltp":1.68,"tv":10423.57,"id":13181195}]}]}
{"op":"mcm","clk":"1008252072","pt":1580659138723,"mc":[{"id":"1.168237984","rc":[{"trd":[[2.42,18.63]],"batl":[[0,2.42,141.92],[1,2.46,10.1],[2,3.15,200.42]],"ltp":2.42,"tv":3180.16,"id":14833204},{"trd":[[1.7,210.18]],"batl":[[0,1.71,153.76],[1,1.72,9.9],[2,1.73,258.32]],"ltp":1.7,"tv":10433.32,"id":13181195}],"tv":13613.49}]}
{"op":"mcm","clk":"1008253178","pt":1580659146021,"mc":[{"id":"1.168237984","rc":[{"trd":[[2.42,302.26]],"batl":[[0,2.46,10.2],[1,3.15,200.42],[2,1000,0.02]],"ltp":2.42,"tv":3463.79,"id":14833204}],"tv":13897.12}]}
{"op":"mcm","clk":"1008254720","pt":1580659156006,"mc":[{"id":"1.168237984","rc":[{"batl":[[0,1.71,1383.26]],"ltp":1.7,"tv":10433.32,"id":13181195}]}]}
{"op":"mcm","clk":"1008255169","pt":1580659159265,"mc":[{"id":"1.168237984","rc":[{"trd":[[2.4,50.27]],"batb":[[0,2.4,52.05]],"ltp":2.4,"tv":3494.08,"id":14833204}],"tv":13927.41}]}
{"op":"mcm","clk":"1008255723","pt":1580659163047,"mc":[{"id":"1.168237984","rc":[{"batb":[[1,2.32,6.64]],"batl":[[0,3.15,200.52],[1,1000,0.02],[2,1000,0]],"ltp":2.4,"tv":3494.08,"id":14833204},{"batb":[[0,1.67,306.69],[1,1.66,286.7],[2,1.56,138.17]],"batl":[[1,1.73,258.32],[2,1.74,111.03]],"ltp":1.7,"tv":10433.32,"id":13181195}]}]}
{"op":"mcm","clk":"1008255793","pt":1580659163518,"mc":[{"id":"1.168237984","rc":[{"batb":[[0,2.24,92.05],[1,2.2,10.72],[2,1.9,134.22]],"ltp":2.4,"tv":3494.08,"id":14833204},{"batb":[[0,1.56,137.61],[1,1.35,544.79],[2,1.34,168.05]],"batl":[[0,1.71,153.76],[1,1.8,43.08],[2,1.83,39.5]],"ltp":1.7,"tv":10433.32,"id":13181195}]}]}
{"op":"mcm","clk":"1008256152","pt":1580659165726,"mc":[{"id":"1.168237984","rc":[{"trd":[[2.42,302.36]],"batl":[[0,3.15,200.42]],"ltp":2.42,"tv":3494.18,"id":14833204},{"trd":[[1.7,210.32]],"batl":[[0,1.68,54.86],[1,1.71,153.76],[2,1.8,43.08]],"ltp":1.7,"tv":10433.46,"id":13181195}],"tv":13927.65}]}
{"op":"mcm","clk":"1008256313","pt":1580659166748,"mc":[{"id":"1.168237984","rc":[{"batb":[[0,1.57,355.77],[1,1.56,358.65],[2,1.35,544.79]],"ltp":1.7,"tv":10433.46,"id":13181195}]}]}
{"op":"mcm","clk":"1008256478","pt":1580659167711,"mc":[{"id":"1.168237984","rc":[{"batb":[[0,2.24,81.28]],"ltp":2.42,"tv":3494.18,"id":14833204},{"batb":[[0,1.56,137.61],[1,1.35,544.79],[2,1.34,168.05]],"batl":[[2,1.8,3.36]],"ltp":1.7,"tv":10433.46,"id":13181195}]}]}
{"op":"mcm","clk":"1008256595","pt":1580659168470,"mc":[{"id":"1.168237984","rc":[{"batl":[[1,1.8,3.36],[2,1.81,168.06]],"ltp":1.7,"tv":10433.46,"id":13181195}]}]}
{"op":"mcm","clk":"1008256838","pt":1580659169974,"mc":[{"id":"1.168237984","rc":[{"trd":[[2.46,37.47]],"batb":[[0,2.24,87.37]],"batl":[[0,2.32,130.82],[1,2.36,401],[2,2.4,2833.15]],"ltp":2.46,"tv":3531.65,"id":14833204},{"trd":[[1.68,113.2]],"batb":[[0,1.78,8.02],[1,1.74,761.45],[2,1.56,137.61]],"batl":[[0,1.8,3.36],[1,1.81,168.06],[2,1.83,294.4]],"ltp":1.68,"tv":10488.32,"id":13181195}],"tv":14019.98}]}
{"op":"mcm","clk":"1008257027","pt":1580659170915,"mc":[{"id":"1.168237984","rc":[{"batb":[[2,2.12,95.99]],"batl":[[0,2.36,401],[1,2.4,287.06],[2,1000,0.02]],"ltp":2.46,"tv":3531.65,"id":14833204},{"batb":[[1,1.75,389.45],[2,1.74,761.45]],"ltp":1.68,"tv":10488.32,"id":13181195}]}]}
{"op":"mcm","clk":"1008257328","pt":1580659172724,"mc":[{"id":"1.168237984","rc":[{"batl":[[2,3,213.45]],"ltp":2.46,"tv":3531.65,"id":14833204}]}]}
{"op":"mcm","clk":"1008258010","pt":1580659176800,"mc":[{"id":"1.168237984","rc":[{"trd":[[1.8,24.48]],"batb":[[2,1.74,1255.48]],"batl":[[0,1.8,2.71]],"ltp":1.8,"tv":10489.62,"id":13181195}],"tv":14021.28}]}
{"op":"mcm","clk":"1008258222","pt":1580659178229,"mc":[{"id":"1.168237984","rc":[{"batb":[[2,2.16,11.53]],"ltp":2.46,"tv":3531.65,"id":14833204}]}]}
{"op":"mcm","clk":"1008258738","pt":1580659181750,"mc":[{"id":"1.168237984","rc":[{"trd":[[1.78,17.95]],"batb":[[0,1.75,389.63],[1,1.74,1255.48],[2,1.73,302.77]],"ltp":1.78,"tv":10505.3,"id":13181195}],"tv":14036.96}]}
{"op":"mcm","clk":"1008258954","pt":1580659183036,"mc":[{"id":"1.168237984","rc":[{"batb":[[0,2.16,11.53],[1,2.12,107.53],[2,1.9,134.22]],"batl":[[0,3,213.45],[1,1000,0.02],[2,3,0]],"ltp":2.46,"tv":3531.65,"id":14833204},{"trd":[[1.75,134.26]],"batb":[[0,1.74,494.03],[1,1.72,510.84],[2,1.64,115.03]],"batl":[[0,1.8,2.96],[1,1.84,480.59],[2,1.86,537.15]],"ltp":1.75,"tv":10535.06,"id":13181195}],"tv":14066.72}]}
{"op":"mcm","clk":"1008259136","pt":1580659184224,"mc":[{"id":"1.168237984","rc":[{"batl":[[0,1.78,24.44],[1,1.8,2.71],[2,1.84,480.59]],"ltp":1.75,"tv":10535.06,"id":13181195}]}]}
{"op":"mcm","clk":"1008259366","pt":1580659185639,"mc":[{"id":"1.168237984","rc":[{"batb":[[2,1.66,187.93]],"ltp":1.75,"tv":10535.06,"id":13181195}]}]}
{"op":"mcm","clk":"1008259619","pt":1580659187150,"mc":[{"id":"1.168237984","rc":[{"batb":[[2,1.64,115.03]],"ltp":1.75,"tv":10535.06,"id":13181195}]}]}
{"op":"mcm","clk":"1008260017","pt":1580659189488,"mc":[{"id":"1.168237984","rc":[{"batb":[[0,2.2,35.01],[1,2.16,11.53],[2,2.12,107.53]],"ltp":2.46,"tv":3531.65,"id":14833204}]}]}
{"op":"mcm","clk":"1008260206","pt":1580659190625,"mc":[{"id":"1.168237984","rc":[{"trd":[[1.78,18.1]],"batb":[[1,1.73,287.52],[2,1.72,510.84]],"batl":[[0,1.78,24.37],[1,1.79,203.32],[2,1.8,2.71]],"ltp":1.78,"tv":10535.21,"id":13181195}],"tv":14066.87}]}
{"op":"mcm","clk":"1008260872","pt":1580659194918,"mc":[{"id":"1.168237984","rc":[{"batb":[[1,1.72,510.84],[2,1.64,115.03]],"batl":[[1,1.8,2.71],[2,1.84,480.59]],"ltp":1.78,"tv":10535.21,"id":13181195}]}]}
{"op":"mcm","clk":"1008261148","pt":1580659196634,"mc":[{"id":"1.168237984","rc":[{"batb":[[0,2.24,33.88],[1,2.2,35.01],[2,2.16,11.53]],"ltp":2.46,"tv":3531.65,"id":14833204}]}]}
{"op":"mcm","clk":"1008261337","pt":1580659197946,"mc":[{"id":"1.168237984","rc":[{"batb":[[2,1.66,179.26]],"ltp":1.78,"tv":10535.21,"id":13181195}]}]}
{"op":"mcm","clk":"1008261826","pt":1580659200723,"mc":[{"id":"1.168237984","rc":[{"batb":[[2,1.64,115.03]],"batl":[[2,1.86,39.75]],"ltp":1.78,"tv":10535.21,"id":13181195}]}]}
{"op":"mcm","clk":"1008262057","pt":1580659201811,"mc":[{"id":"1.168237984","rc":[{"batb":[[0,2.2,35.01],[1,2.12,107.53],[2,1.9,134.22]],"ltp":2.46,"tv":3531.65,"id":14833204},{"batl":[[2,1.89,38.5]],"ltp":1.78,"tv":10535.21,"id":13181195}]}]}
{"op":"mcm","clk":"1008262190","pt":1580659202450,"mc":[{"id":"1.168237984","rc":[{"batb":[[0,2.12,107.53],[1,1.9,134.22],[2,1.89,1.82]],"batl":[[0,1000,0.02],[1,1000,0]],"ltp":2.46,"tv":3531.65,"id":14833204}]}]}
{"op":"mcm","clk":"1008262568","pt":1580659204040,"mc":[{"id":"1.168237984","rc":[{"trd":[[2.24,6.72],[2.28,427.13]],"batb":[[0,2.14,36.85],[1,2.12,107.53],[2,1.9,134.22]],"batl":[[0,2.2,13.53],[1,2.22,390],[2,2.24,95.47]],"ltp":2.24,"tv":3552.85,"id":14833204},{"trd":[[1.78,42.47],[1.8,27.19]],"batb":[[0,1.83,233.02],[1,1.81,260.39],[2,1.78,109.27]],"batl":[[0,1.89,51.91],[1,1.9,248.97],[2,1.92,219.42]],"ltp":1.8,"tv":10562.29,"id":13181195}],"tv":14115.15}]}
{"op":"mcm","clk":"1008262629","pt":1580659204325,"mc":[{"id":"1.168237984","rc":[{"batb":[[2,2.02,109.92]],"ltp":2.24,"tv":3552.85,"id":14833204},{"batb":[[0,1.83,313.28]],"ltp":1.8,"tv":10562.29,"id":13181195}]}]}
{"op":"mcm","clk":"1008263761","pt":1580659209840,"mc":[{"id":"1.168237984","rc":[{"batb":[[2,2.08,38.9]],"ltp":2.24,"tv":3552.85,"id":14833204},{"batb":[[2,1.79,494.03]],"batl":[[2,1.92,700.01]],"ltp":1.8,"tv":10562.29,"id":13181195}]}]}
{"op":"mcm","clk":"1008263903","pt":1580659210640,"mc":[{"id":"1.168237984","rc":[{"batb":[[2,2.1,11.94]],"ltp":2.24,"tv":3552.85,"id":14833204},{"batl":[[1,1.9,288.52],[2,1.92,738.82]],"ltp":1.8,"tv":10562.29,"id":13181195}]}]}
{"op":"mcm","clk":"1008264946","pt":1580659216057,"mc":[{"id":"1.168237984","rc":[{"trd":[[2.2,78.06]],"batl":[[0,2.22,390.21],[1,2.24,95.47],[2,2.72,241.55]],"ltp":2.2,"tv":3579.49,"id":14833204}],"tv":14141.79}]}
{"op":"mcm","clk":"1008265558","pt":1580659219040,"mc":[{"id":"1.168237984","rc":[{"batb":[[0,1.83,80.26],[1,1.79,494.03],[2,1.78,109.27]],"batl":[[1,1.9,221.2]],"ltp":1.8,"tv":10562.29,"id":13181195}]}]}
{"op":"mcm","clk":"1008265989","pt":1580659220970,"mc":[{"id":"1.168237984","rc":[{"batb":[[1,2.08,50.96],[2,2.02,109.92]],"batl":[[0,2.72,241.55],[1,1000,0.02],[2,2.72,0]],"ltp":2.2,"tv":3579.49,"id":14833204},{"batb":[[0,1.79,494.03],[1,1.77,510.84],[2,1.74,95.05]],"batl":[[0,1.92,519.4],[1,1.94,497.4],[2,2.3,1.1]],"ltp":1.8,"tv":10562.29,"id":13181195}]}]}
{"op":"mcm","clk":"1008266172","pt":1580659222036,"mc":[{"id":"1.168237984","rc":[{"trd":[[1.84,44.48]],"batb":[[0,1.84,175.65],[1,1.82,255.55],[2,1.79,494.03]],"ltp":1.84,"tv":10562.53,"id":13181195}],"tv":14142.03}]}
{"op":"mcm","clk":"1008266200","pt":1580659222258,"mc":[{"id":"1.168237984","rc":[{"batb":[[0,1.79,494.03],[1,1.77,510.84],[2,1.74,95.05]],"ltp":1.84,"tv":10562.53,"id":13181195}]}]}
{"op":"mcm","clk":"1008266518","pt":1580659223867,"mc":[{"id":"1.168237984","rc":[{"batb":[[2,2,112.36]],"ltp":2.2,"tv":3579.49,"id":14833204},{"batb":[[2,1.75,93.16]],"batl":[[2,1.97,155.51]],"ltp":1.84,"tv":10562.53,"id":13181195}]}]}
{"op":"mcm","clk":"1008267002","pt":1580659226650,"mc":[{"id":"1.168237984","rc":[{"batb":[[2,2.04,40.4]],"ltp":2.2,"tv":3579.49,"id":14833204},{"batb":[[2,1.76,177.83]],"ltp":1.84,"tv":10562.53,"id":13181195}]}]}
{"op":"mcm","clk":"1008267783","pt":1580659230900,"mc":[{"id":"1.168237984","rc":[{"batb":[[0,1.76,177.83],[1,1.75,93.16],[2,1.74,296.26]],"batl":[[2,2.3,1.1]],"ltp":1.84,"tv":10562.53,"id":13181195}]}]}
{"op":"mcm","clk":"1008268376","pt":1580659233975,"mc":[{"id":"1.168237984","rc":[{"trd":[[2.32,68.55]],"batb":[[0,2.22,11.84],[1,2.2,85.78],[2,2.14,36.85]],"batl":[[0,2.38,434],[1,2.72,241.55],[2,1000,0.02]],"ltp":2.32,"tv":3586.65,"id":14833204},{"trd":[[1.76,587.64]],"batb":[[0,1.76,168.39],[2,1.74,850.17]],"batl":[[0,1.81,44.5],[1,1.82,268.14],[2,1.83,474]],"ltp":1.76,"tv":10571.97,"id":13181195}],"tv":14158.63}]}
{"op":"mcm","clk":"1008268546","pt":1580659234979,"mc":[{"id":"1.168237984","rc":[{"batb":[[0,2.24,81.75],[1,2.22,11.84],[2,2.2,85.78]],"ltp":2.32,"tv":3586.65,"id":14833204}]}]}
{"op":"mcm","clk":"1008268710","pt":1580659235998,"mc":[{"id":"1.168237984","rc":[{"batb":[[1,2.22,46.27]],"ltp":2.32,"tv":3586.65,"id":14833204}]}]}
{"op":"mcm","clk":"1008269140","pt":1580659238574,"mc":[{"id":"1.168237984","rc":[{"batl":[[0,1.8,138.63],[1,1.81,44.5],[2,1.82,268.14]],"ltp":1.76,"tv":10571.97,"id":13181195}]}]}
{"op":"mcm","clk":"1008269540","pt":1580659240880,"mc":[{"id":"1.168237984","rc":[{"batb":[[0,2.26,873.98],[1,2.24,81.75],[2,2.22,46.27]],"ltp":2.32,"tv":3586.65,"id":14833204}]}]}
{"op":"mcm","clk":"1008270507","pt":1580659246481,"mc":[{"id":"1.168237984","rc":[{"batb":[[2,1.74,861.51]],"batl":[[0,1.78,13.74],[1,1.8,138.63],[2,1.81,44.5]],"ltp":1.76,"tv":10571.97,"id":13181195}]}]}
{"op":"mcm","clk":"1008270822","pt":1580659248616,"mc":[{"id":"1.168237984","rc":[{"batb":[[0,2.24,81.75],[1,2.22,46.27],[2,2.2,85.78]],"ltp":2.32,"tv":3586.65,"id":14833204}]}]}
{"op":"mcm","clk":"1008271939","pt":1580659254720,"mc":[{"id":"1.168237984","rc":[{"trd":[[1.75,156.64],[1.76,924.42]],"batb":[[0,1.75,81.97],[1,1.74,861.51],[2,1.72,494.03]],"ltp":1.75,"tv":10931.14,"id":13181195}],"tv":14517.79}]}
{"op":"mcm","clk":"1008272069","pt":1580659255436,"mc":[{"id":"1.168237984","rc":[{"batl":[[0,2.72,241.55],[1,1000,0.02],[2,1000,0]],"ltp":2.32,"tv":3586.65,"id":14833204},{"batb":[[1,1.74,565.25]],"ltp":1.75,"tv":10931.14,"id":13181195}]}]}
{"op":"mcm","clk":"1008272630","pt":1580659258229,"mc":[{"id":"1.168237984","rc":[{"batb":[[0,1.75,308.14],[2,1.73,302.65]],"batl":[[2,1.81,280.11]],"ltp":1.75,"tv":10931.14,"id":13181195}]}]}
{"op":"mcm","clk":"1008273714","pt":1580659264831,"mc":[{"id":"1.168237984","rc":[{"trd":[[1.75,156.84]],"batb":[[0,1.75,308.04]],"ltp":1.75,"tv":10931.33,"id":13181195}],"tv":14517.99}]}
{"op":"mcm","clk":"1008273897","pt":1580659266007,"mc":[{"id":"1.168237984","rc":[{"trd":[[1.75,183.36]],"batb":[[0,1.75,294.78]],"ltp":1.75,"tv":10957.85,"id":13181195}],"tv":14544.51}]}
{"op":"mcm","clk":"1008274052","pt":1580659266961,"mc":[{"id":"1.168237984","rc":[{"batb":[[0,2.22,34.43],[1,2.14,48.17],[2,2.1,11.34]],"ltp":2.32,"tv":3586.65,"id":14833204},{"batb":[[0,1.72,494.03],[1,1.7,510.84],[2,1.63,117.71]],"batl":[[0,1.8,138.63],[1,1.85,480.59],[2,1.87,536.9]],"ltp":1.75,"tv":10957.85,"id":13181195}]}]}
{"op":"mcm","clk":"1008274212","pt":1580659267925,"mc":[{"id":"1.168237984","rc":[{"batl":[[0,1.85,480.59],[1,1.87,536.9],[2,1.9,37.65]],"ltp":1.75,"tv":10957.85,"id":13181195}]}]}
{"op":"mcm","clk":"1008274526","pt":1580659269833,"mc":[{"id":"1.168237984","rc":[{"batb":[[2,2.1,110.48]],"ltp":2.32,"tv":3586.65,"id":14833204},{"batl":[[0,1.87,39.5],[1,1.9,193.39],[2,1.91,37.5]],"ltp":1.75,"tv":10957.85,"id":13181195}]}]}
{"op":"mcm","clk":"1008274877","pt":1580659271853,"mc":[{"id":"1.168237984","rc":[{"batb":[[0,2.14,11.32],[1,2.1,110.48],[2,2.08,50.96]],"ltp":2.32,"tv":3586.65,"id":14833204}]}]}
{"op":"mcm","clk":"1008275017","pt":1580659272653,"mc":[{"id":"1.168237984","rc":[{"batb":[[0,2.1,99.14],[1,2.08,50.96],[2,2.04,40.4]],"batl":[[0,2.2,6.85],[1,2.22,405],[2,2.36,1697.53]],"ltp":2.32,"tv":3586.65,"id":14833204},{"batb":[[0,1.84,203.23],[1,1.82,255.8],[2,1.79,111.06]],"batl":[[0,1.89,21.17],[1,1.9,155.74]],"ltp":1.75,"tv":10957.85,"id":13181195}]}]}
{"op":"mcm","clk":"1008275250","pt":1580659273950,"mc":[{"id":"1.168237984","rc":[{"batb":[[0,1.85,77.82],[1,1.84,203.23],[2,1.82,255.8]],"ltp":1.75,"tv":10957.85,"id":13181195}]}]}
{"op":"mcm","clk":"1008275785","pt":1580659276750,"mc":[{"id":"1.168237984","rc":[{"batb":[[0,2.12,37.51],[1,2.1,99.14],[2,2.08,50.96]],"ltp":2.32,"tv":3586.65,"id":14833204}]}]}
{"op":"mcm","clk":"1008276864","pt":1580659282818,"mc":[{"id":"1.168237984","rc":[{"trd":[[1.85,8.84]],"batb":[[0,1.85,75.82]],"ltp":1.85,"tv":10961.85,"id":13181195}],"tv":14548.51}]}
{"op":"mcm","clk":"1008277610","pt":1580659287024,"mc":[{"id":"1.168237984","rc":[{"batl":[[1,2.36,1697.53],[2,2.72,241.55]],"ltp":2.32,"tv":3586.65,"id":14833204}]}]}
{"op":"mcm","clk":"1008277745","pt":1580659287831,"mc":[{"id":"1.168237984","rc":[{"batb":[[1,2.08,50.96],[2,2.04,40.4]],"batl":[[0,2.72,241.55],[1,1000,0.02],[2,2.72,0]],"ltp":2.32,"tv":3586.65,"id":14833204},{"batb":[[0,1.81,494.03],[1,1.79,621.9],[2,1.76,110.72]],"batl":[[0,1.92,38.81],[1,1.93,520.09],[2,1.95,497.4]],"ltp":1.85,"tv":10961.85,"id":13181195}]}]}
{"op":"mcm","clk":"1008277785","pt":1580659288104,"mc":[{"id":"1.168237984","rc":[{"batb":[[1,2.08,38.9]],"ltp":2.32,"tv":3586.65,"id":14833204},{"batb":[[1,1.79,510.84],[2,1.74,93.32]],"batl":[[0,1.93,520.09],[1,1.95,497.4],[2,2.3,1.1]],"ltp":1.85,"tv":10961.85,"id":13181195}]}]}
{"op":"mcm","clk":"1008277984","pt":1580659289243,"mc":[{"id":"1.168237984","rc":[{"batl":[[0,1.88,15.14],[1,1.93,520.09],[2,1.95,497.4]],"ltp":1.85,"tv":10961.85,"id":13181195}]}]}
{"op":"mcm","clk":"1008278290","pt":1580659291028,"mc":[{"id":"1.168237984","rc":[{"batb":[[2,2.06,12.08]],"ltp":2.32,"tv":3586.65,"id":14833204},{"batb":[[2,1.76,203.42]],"batl":[[1,1.91,39.5],[2,1.93,520.09]],"ltp":1.85,"tv":10961.85,"id":13181195}]}]}
{"op":"mcm","clk":"1008278409","pt":1580659291682,"mc":[{"id":"1.168237984","rc":[{"batb":[[0,2.08,38.9],[1,2.06,12.08],[2,2.04,40.4]],"ltp":2.32,"tv":3586.65,"id":14833204},{"batl":[[1,1.93,520.09],[2,1.95,497.4]],"ltp":1.85,"tv":10961.85,"id":13181195}]}]}
{"op":"mcm","clk":"1008278947","pt":1580659294832,"mc":[{"id":"1.168237984","rc":[{"batb":[[0,2.08,50.96]],"ltp":2.32,"tv":3586.65,"id":14833204}]}]}
{"op":"mcm","clk":"1008279007","pt":1580659295099,"mc":[{"id":"1.168237984","rc":[{"batb":[[0,2.08,38.9]],"ltp":2.32,"tv":3586.65,"id":14833204}]}]}
{"op":"mcm","clk":"1008279355","pt":1580659296649,"mc":[{"id":"1.168237984","rc":[{"batb":[[2,1.74,93.32]],"batl":[[1,1.93,39.5],[2,1.97,193.93]],"ltp":1.85,"tv":10961.85,"id":13181195}]}]}
{"op":"mcm","clk":"1008279589","pt":1580659297851,"mc":[{"id":"1.168237984","rc":[{"batl":[[1,1.91,39.5],[2,1.93,39.5]],"ltp":1.85,"tv":10961.85,"id":13181195}]}]}
{"op":"mcm","clk":"1008279842","pt":1580659299038,"mc":[{"id":"1.168237984","rc":[{"trd":[[2.12,13.43]],"batb":[[0,2.06,12.08],[1,2.04,40.4],[2,2,112.59]],"batl":[[0,2.1,2851.17],[1,2.12,500.17],[2,2.14,537]],"ltp":2.12,"tv":3600.08,"id":14833204},{"trd":[[1.88,15.4]],"batb":[[0,1.87,1077.81],[1,1.83,1004.33],[2,1.81,494.03]],"batl":[[0,1.93,39.5],[1,1.94,12.19],[2,1.97,193.93]],"ltp":1.88,"tv":10977.0,"id":13181195}],"tv":14577.09}]}
{"op":"mcm","clk":"1008280029","pt":1580659299943,"mc":[{"id":"1.168237984","rc":[{"batl":[[0,2.12,500.17],[1,2.14,537],[2,2.72,241.55]],"ltp":2.12,"tv":3600.08,"id":14833204},{"batb":[[0,1.92,68.93],[1,1.9,211.46],[2,1.88,230.63]],"ltp":1.88,"tv":10977.0,"id":13181195}]}]}
{"op":"mcm","clk":"1008281176","pt":1580659305837,"mc":[{"id":"1.168237984","rc":[{"trd":[[1.92,4]],"batb":[[0,1.92,66.93]],"ltp":1.92,"tv":10981.0,"id":13181195}],"tv":14581.09}]}
{"op":"mcm","clk":"1008281248","pt":1580659306213,"mc":[{"id":"1.168237984","rc":[{"batb":[[2,2,149.69]],"ltp":2.12,"tv":3600.08,"id":14833204}]}]}
{"op":"mcm","clk":"1008281886","pt":1580659309643,"mc":[{"id":"1.168237984","rc":[{"trd":[[1.92,9.46]],"batb":[[0,1.92,64.19]],"ltp":1.92,"tv":10986.46,"id":13181195}],"tv":14586.55}]}
{"op":"mcm","clk":"1008281995","pt":1580659310120,"mc":[{"id":"1.168237984","rc":[{"trd":[[1.92,15.51]],"batb":[[0,1.92,61.17]],"ltp":1.92,"tv":10992.51,"id":13181195}],"tv":14592.6}]}
{"op":"mcm","clk":"1008282669","pt":1580659314137,"mc":[{"id":"1.168237984","rc":[{"trd":[[1.92,28.23]],"batb":[[0,1.92,54.81]],"ltp":1.92,"tv":11005.23,"id":13181195}],"tv":14605.32}]}
{"op":"mcm","clk":"1008283306","pt":1580659317386,"mc":[{"id":"1.168237984","rc":[{"trd":[[1.92,90.33]],"batb":[[0,1.92,23.76]],"ltp":1.92,"tv":11067.33,"id":13181195}],"tv":14667.42}]}
{"op":"mcm","clk":"1008283497","pt":1580659318284,"mc":[{"id":"1.168237984","rc":[{"trd":[[1.92,107.62]],"batb":[[0,1.92,15.11]],"ltp":1.92,"tv":11084.62,"id":13181195}],"tv":14684.71}]}
{"op":"mcm","clk":"1008283869","pt":1580659320121,"mc":[{"id":"1.168237984","rc":[{"trd":[[1.93,0.1]],"batl":[[0,1.93,39.45]],"ltp":1.93,"tv":11084.72,"id":13181195}],"tv":14684.81}]}
{"op":"mcm","clk":"1008284344","pt":1580659322314,"mc":[{"id":"1.168237984","rc":[{"trd":[[1.92,118.53]],"batb":[[0,1.92,9.66]],"ltp":1.92,"tv":11095.63,"id":13181195}],"tv":14695.71}]}
{"op":"mcm","clk":"1008284626","pt":1580659323722,"mc":[{"id":"1.168237984","rc":[{"batl":[[2,2.18,5.75]],"ltp":2.12,"tv":3600.08,"id":14833204},{"trd":[[1.92,123.46]],"batb":[[0,1.92,7.19]],"ltp":1.92,"tv":11100.56,"id":13181195}],"tv":14700.65}]}
{"op":"mcm","clk":"1008284988","pt":1580659325722,"mc":[{"id":"1.168237984","rc":[{"trd":[[1.92,137.84]],"batb":[[0,1.9,211.46],[1,1.88,230.63],[2,1.87,107.78]],"batl":[[0,1.92,22.63],[1,1.93,39.45],[2,1.94,12.19]],"ltp":1.92,"tv":11114.94,"id":13181195}],"tv":14715.03}]}
{"op":"mcm","clk":"1008285165","pt":1580659326664,"mc":[{"id":"1.168237984","rc":[{"trd":[[1.92,137.86]],"batl":[[0,1.92,22.62]],"ltp":1.92,"tv":11114.96,"id":13181195}],"tv":14715.05}]}
{"op":"mcm","clk":"1008285441","pt":1580659328074,"mc":[{"id":"1.168237984","rc":[{"batl":[[0,1.92,2.62]],"ltp":1.92,"tv":11114.96,"id":13181195}]}]}
{"op":"mcm","clk":"1008286129","pt":1580659331485,"mc":[{"id":"1.168237984","rc":[{"batb":[[0,2.1,1.89],[1,2.06,12.08],[2,2.04,40.4]],"ltp":2.12,"tv":3600.08,"id":14833204}]}]}
{"op":"mcm","clk":"1008287095","pt":1580659336649,"mc":[{"id":"1.168237984","rc":[{"batl":[[1,2.18,5.75],[2,2.22,5.25]],"ltp":2.12,"tv":3600.08,"id":14833204},{"batb":[[0,1.87,107.78],[1,1.85,97.08],[2,1.83,100.43]],"batl":[[0,1.93,39.45],[1,1.94,12.19],[2,1.98,37.75]],"ltp":1.92,"tv":11114.96,"id":13181195}]}]}
{"op":"mcm","clk":"1008287571","pt":1580659338905,"mc":[{"id":"1.168237984","rc":[{"batb":[[1,2.04,40.4],[2,1.99,79.95]],"batl":[[0,2.72,241.55],[1,1000,0.02],[2,2.22,0]],"ltp":2.12,"tv":3600.08,"id":14833204},{"batb":[[0,1.85,76.71],[1,1.63,2],[2,1.35,544.79]],"batl":[[0,2.02,12.25],[1,2.3,1.1],[2,3,2.82]],"ltp":1.92,"tv":11114.96,"id":13181195}]}]}
{"op":"mcm","clk":"1008287733","pt":1580659339950,"mc":[{"id":"1.168237984","rc":[{"batb":[[1,1.84,260.12],[2,1.82,255.92]],"batl":[[0,1.9,38.87],[1,2.02,12.25],[2,2.08,196.92]],"ltp":1.92,"tv":11114.96,"id":13181195}]}]}
{"op":"mcm","clk":"1008287838","pt":1580659340439,"mc":[{"id":"1.168237984","rc":[{"batb":[[1,1.63,2],[2,1.35,544.79]],"batl":[[2,2.3,1.1]],"ltp":1.92,"tv":11114.96,"id":13181195}]}]}
{"op":"mcm","clk":"1008288121","pt":1580659342041,"mc":[{"id":"1.168237984","rc":[{"batb":[[0,1.84,78.21],[1,1.8,15.14],[2,1.63,2]],"ltp":1.92,"tv":11114.96,"id":13181195}]}]}
{"op":"mcm","clk":"1008288170","pt":1580659342292,"mc":[{"id":"1.168237984","rc":[{"batl":[[0,1000,0.02],[1,1000,0]],"ltp":2.12,"tv":3600.08,"id":14833204}]}]}
{"op":"mcm","clk":"1008288362","pt":1580659343633,"mc":[{"id":"1.168237984","rc":[{"trd":[[1.9,41.12]],"batl":[[0,1.9,67.08]],"ltp":1.9,"tv":11156.08,"id":13181195}],"tv":14756.17}]}
{"op":"mcm","clk":"1008288582","pt":1580659344817,"mc":[{"id":"1.168237984","rc":[{"trd":[[2.1,1.89]],"batb":[[0,2.04,40.4],[1,1.99,79.95],[2,1.91,65.78]],"ltp":2.1,"tv":3601.98,"id":14833204},{"trd":[[1.9,175.26],[1.91,2.08]],"batb":[[0,1.92,132.73],[1,1.9,223.07],[2,1.84,78.21]],"batl":[[0,1.99,183.97],[1,2.02,296.51]],"ltp":1.91,"tv":11292.31,"id":13181195}],"tv":14894.29}]}
{"op":"mcm","clk":"1008288958","pt":1580659347014,"mc":[{"id":"1.168237984","rc":[{"batl":[[0,2.6,257.57],[1,1000,0.02]],"ltp":2.1,"tv":3601.98,"id":14833204},{"batb":[[0,1.84,78.21],[1,1.8,15.14],[2,1.63,2]],"batl":[[0,2.02,12.49],[1,2.3,1.1],[2,3,2.82]],"ltp":1.91,"tv":11292.31,"id":13181195}]}]}
{"op":"mcm","clk":"1008289237","pt":1580659348837,"mc":[{"id":"1.168237984","rc":[{"batb":[[1,2.02,12.24],[2,1.99,79.95]],"ltp":2.1,"tv":3601.98,"id":14833204},{"trd":[[1.85,9.32]],"batl":[[0,1.98,37.75],[1,2.02,12.25],[2,2.3,1.1]],"ltp":1.85,"tv":11292.79,"id":13181195}],"tv":14894.77}]}
{"op":"mcm","clk":"1008289394","pt":1580659349856,"mc":[{"id":"1.168237984","rc":[{"batb":[[1,1.99,79.95],[2,1.91,65.78]],"ltp":2.1,"tv":3601.98,"id":14833204},{"batb":[[0,1.84,298.87],[1,1.82,255.9],[2,1.8,15.14]],"batl":[[0,2.02,12.25],[1,2.08,231.95],[2,2.1,168.47]],"ltp":1.85,"tv":11292.79,"id":13181195}]}]}
{"op":"mcm","clk":"1008290467","pt":1580659355828,"mc":[{"id":"1.168237984","rc":[{"batb":[[1,2.02,12.24],[2,1.99,79.95]],"ltp":2.1,"tv":3601.98,"id":14833204},{"batb":[[0,1.84,78.21],[1,1.8,15.14],[2,1.63,2]],"batl":[[0,1.98,37.75],[1,2.02,12.25],[2,2.3,1.1]],"ltp":1.85,"tv":11292.79,"id":13181195}]}]}
{"op":"mcm","clk":"1008290603","pt":1580659356644,"mc":[{"id":"1.168237984","rc":[{"batb":[[0,1.99,37.51],[1,1.91,65.78],[2,1.9,134.22]],"batl":[[0,1000,0.02],[1,1000,0]],"ltp":2.1,"tv":3601.98,"id":14833204},{"batl":[[0,2.02,12.25],[1,2.3,1.1],[2,3,2.82]],"ltp":1.85,"tv":11292.79,"id":13181195}]}]}
{"op":"mcm","clk":"1008290885","pt":1580659358029,"mc":[{"id":"1.168237984","rc":[{"batb":[[1,1.93,206.26],[2,1.91,285.22]],"batl":[[0,2,395.9],[1,2.02,778.73],[2,1000,0.02]],"ltp":2.1,"tv":3601.98,"id":14833204},{"batb":[[0,2,225.1],[1,1.97,104.64],[2,1.94,94.8]],"batl":[[1,2.04,7.94],[2,2.14,507]],"ltp":1.85,"tv":11292.79,"id":13181195}]}]}
{"op":"mcm","clk":"1008291026","pt":1580659358835,"mc":[{"id":"1.168237984","rc":[{"trd":[[1.99,37.51]],"batb":[[0,1.93,206.26],[1,1.91,285.22],[2,1.9,134.22]],"ltp":1.99,"tv":3639.49,"id":14833204},{"trd":[[2,5.46],[2.02,61.46]],"batb":[[0,2.02,68.82],[1,2,222.37],[2,1.97,104.64]],"batl":[[0,2.04,7.94],[1,2.14,507],[2,2.16,736.74]],"ltp":2.02,"tv":11359.71,"id":13181195}],"tv":14999.2}]}
{"op":"mcm","clk":"1008291344","pt":1580659360661,"mc":[{"id":"1.168237984","rc":[{"batl":[[2,2.5,274.54]],"ltp":1.99,"tv":3639.49,"id":14833204}]}]}
{"op":"mcm","clk":"1008291713","pt":1580659362758,"mc":[{"id":"1.168237984","rc":[{"batb":[[0,1.98,42.87],[1,1.93,206.26],[2,1.91,285.22]],"ltp":1.99,"tv":3639.49,"id":14833204}]}]}
{"op":"mcm","clk":"1008291907","pt":1580659363727,"mc":[{"id":"1.168237984","rc":[{"batb":[[0,1.94,44.69]],"ltp":1.99,"tv":3639.49,"id":14833204}]}]}
{"op":"mcm","clk":"1008292200","pt":1580659365452,"mc":[{"id":"1.168237984","rc":[{"batl":[[2,2.12,5.21]],"ltp":1.99,"tv":3639.49,"id":14833204}]}]}
{"op":"mcm","clk":"1008292346","pt":1580659366190,"mc":[{"id":"1.168237984","rc":[{"batl":[[2,2.16,741.46]],"ltp":2.02,"tv":11359.71,"id":13181195}]}]}
{"op":"mcm","clk":"1008292673","pt":1580659367967,"mc":[{"id":"1.168237984","rc":[{"batb":[[0,1.95,44.22],[1,1.94,44.69],[2,1.93,206.26]],"ltp":1.99,"tv":3639.49,"id":14833204}]}]}
{"op":"mcm","clk":"1008292790","pt":1580659368642,"mc":[{"id":"1.168237984","rc":[{"trd":[[1.96,0.2]],"batl":[[0,2,391.75]],"ltp":1.96,"tv":3639.68,"id":14833204},{"trd":[[2.02,65.46],[2.04,0.19]],"batb":[[0,2.02,66.82],[1,2,220.95]],"batl":[[0,2.14,507],[1,2.16,741.46],[2,2.18,5.75]],"ltp":2.02,"tv":11363.9,"id":13181195}],"tv":15003.58}]}
{"op":"mcm","clk":"1008293107","pt":1580659370150,"mc":[{"id":"1.168237984","rc":[{"trd":[[2.02,75.46]],"batb":[[0,2.02,61.82]],"ltp":2.02,"tv":11373.9,"id":13181195}],"tv":15013.58}]}
{"op":"mcm","clk":"1008293439","pt":1580659371975,"mc":[{"id":"1.168237984","rc":[{"batb":[[0,1.94,44.69],[1,1.93,206.26],[2,1.91,285.22]],"batl":[[1,2.02,792.63]],"ltp":1.96,"tv":3639.68,"id":14833204},{"batl":[[0,2.04,10.42],[1,2.14,507],[2,2.16,741.46]],"ltp":2.02,"tv":11373.9,"id":13181195}]}]}
{"op":"mcm","clk":"1008293775","pt":1580659373782,"mc":[{"id":"1.168237984","rc":[{"trd":[[1.96,2.93]],"ltp":1.96,"tv":3642.41,"id":14833204},{"trd":[[2.04,2.81]],"batl":[[0,2.04,7.8]],"ltp":2.04,"tv":11376.52,"id":13181195}],"tv":15018.94}]}
{"op":"mcm","clk":"1008294661","pt":1580659378148,"mc":[{"id":"1.168237984","rc":[{"batl":[[1,2.02,778.73]],"ltp":1.96,"tv":3642.41,"id":14833204},{"batl":[[0,2.14,507],[1,2.16,741.46],[2,2.18,5.75]],"ltp":2.04,"tv":11376.52,"id":13181195}]}]}
{"op":"mcm","clk":"1008295018","pt":1580659379974,"mc":[{"id":"1.168237984","rc":[{"batl":[[0,2,170.8],[1,2.02,188.73]],"ltp":1.96,"tv":3642.41,"id":14833204},{"batb":[[1,1.94,66.88],[2,1.9,20.36]],"batl":[[0,2.16,4.72],[1,2.18,5.75],[2,2.22,5.25]],"ltp":2.04,"tv":11376.52,"id":13181195}]}]}
{"op":"mcm","clk":"1008295203","pt":1580659380885,"mc":[{"id":"1.168237984","rc":[{"batb":[[1,1.9,134.22],[2,1.89,1.82]],"batl":[[0,2.18,5.25],[1,2.5,274.54],[2,1000,0.02]],"ltp":1.96,"tv":3642.41,"id":14833204},{"batb":[[0,1.94,66.88],[1,1.85,19.97],[2,1.8,15.14]],"batl":[[0,2.22,5.25],[1,2.3,1.1],[2,3,2.82]],"ltp":2.04,"tv":11376.52,"id":13181195}]}]}
{"op":"mcm","clk":"1008295608","pt":1580659382944,"mc":[{"id":"1.168237984","rc":[{"batl":[[0,2.1,285.72],[1,2.12,164.03],[2,2.18,5.25]],"ltp":1.96,"tv":3642.41,"id":14833204}]}]}
{"op":"mcm","clk":"1008295778","pt":1580659383868,"mc":[{"id":"1.168237984","rc":[{"batb":[[0,1.93,68.22],[1,1.89,23.41],[2,1.85,19.97]],"batl":[[0,2.18,5.25],[1,2.22,5.25],[2,2.3,1.1]],"ltp":2.04,"tv":11376.52,"id":13181195}]}]}
{"op":"mcm","clk":"1008295993","pt":1580659384956,"mc":[{"id":"1.168237984","rc":[{"batl":[[2,2.14,5.25]],"ltp":1.96,"tv":3642.41,"id":14833204},{"batb":[[1,1.85,19.97],[2,1.8,15.14]],"ltp":2.04,"tv":11376.52,"id":13181195}]}]}
{"op":"mcm","clk":"1008296030","pt":1580659385165,"mc":[{"id":"1.168237984","rc":[{"batl":[[2,2.18,5.25]],"ltp":1.96,"tv":3642.41,"id":14833204}]}]}
{"op":"mcm","clk":"1008296588","pt":1580659387926,"mc":[{"id":"1.168237984","rc":[{"batb":[[1,1.89,18.41],[2,1.85,19.97]],"ltp":2.04,"tv":11376.52,"id":13181195}]}]}
{"op":"mcm","clk":"1008297347","pt":1580659391914,"mc":[{"id":"1.168237984","rc":[{"batl":[[2,2.14,5.75]],"ltp":1.96,"tv":3642.41,"id":14833204}]}]}
{"op":"mcm","clk":"1008297389","pt":1580659392080,"mc":[{"id":"1.168237984","rc":[{"batl":[[2,2.18,5.25]],"ltp":1.96,"tv":3642.41,"id":14833204}]}]}
{"op":"mcm","clk":"1008298687","pt":1580659398854,"mc":[{"id":"1.168237984","rc":[{"batl":[[0,2.14,5.75],[1,2.18,5.25],[2,2.5,274.54]],"ltp":1.96,"tv":3642.41,"id":14833204}]}]}
{"op":"mcm","clk":"1008298746","pt":1580659399105,"mc":[{"id":"1.168237984","rc":[{"batl":[[0,2.18,5.25],[1,2.5,274.54],[2,1000,0.02]],"ltp":1.96,"tv":3642.41,"id":14833204}]}]}
{"op":"mcm","clk":"1008299290","pt":1580659402016,"mc":[{"id":"1.168237984","rc":[{"trd":[[1.89,3.64],[1.9,268.58]],"batb":[[0,1.82,185.63],[1,1.8,344.59],[2,1.76,814.96]],"batl":[[0,1.88,746.44],[1,1.89,644.42],[2,1.9,227.04]],"ltp":1.89,"tv":3914.64,"id":14833204},{"batb":[[0,2.14,97.8],[1,2.1,95.12],[2,2.04,114.56]],"batl":[[0,2.2,11.99],[2,2.3,460.1]],"ltp":2.04,"tv":11376.52,"id":13181195}],"tv":15291.16}]}
{"op":"mcm","clk":"1008299426","pt":1580659402792,"mc":[{"id":"1.168237984","rc":[{"batb":[[1,1.8,344.12]],"ltp":1.89,"tv":3914.64,"id":14833204}]}]}
{"op":"mcm","clk":"1008300118","pt":1580659406414,"mc":[{"id":"1.168237984","rc":[{"batb":[[0,1.84,50.01],[1,1.82,185.63],[2,1.8,344.12]],"ltp":1.89,"tv":3914.64,"id":14833204}]}]}
{"op":"mcm","clk":"1008300689","pt":1580659408916,"mc":[{"id":"1.168237984","rc":[{"batb":[[0,1.85,33.32],[1,1.84,50.01],[2,1.82,185.63]],"ltp":1.89,"tv":3914.64,"id":14833204},{"trd":[[2.14,4]],"batb":[[0,2.14,95.8]],"batl":[[2,2.3,464.65]],"ltp":2.14,"tv":11380.52,"id":13181195}],"tv":15295.16}]}
{"op":"mcm","clk":"1008302917","pt":1580659420633,"mc":[{"id":"1.168237984","rc":[{"trd":[[1.85,46.61]],"batb":[[0,1.85,10.01]],"ltp":1.85,"tv":3961.25,"id":14833204}],"tv":15341.77}]}
{"op":"mcm","clk":"1008303298","pt":1580659422764,"mc":[{"id":"1.168237984","rc":[{"batl":[[0,1.88,309.44],[1,1.9,227.04],[2,1.92,480.59]],"ltp":1.85,"tv":3961.25,"id":14833204},{"batl":[[0,2.22,5.25],[1,2.3,5.65],[2,2.34,4.75]],"ltp":2.14,"tv":11380.52,"id":13181195}]}]}
{"op":"mcm","clk":"1008303438","pt":1580659423496,"mc":[{"id":"1.168237984","rc":[{"batb":[[2,1.81,51.87]],"batl":[[0,1.92,480.59],[1,1.94,497.4],[2,2.02,5.75]],"ltp":1.85,"tv":3961.25,"id":14833204},{"batb":[[0,2.04,114.56],[1,1.99,18.51],[2,1.95,15.51]],"batl":[[0,2.3,1.1],[1,2.34,4.75],[2,2.36,4.82]],"ltp":2.14,"tv":11380.52,"id":13181195}]}]}
{"op":"mcm","clk":"1008304163","pt":1580659427249,"mc":[{"id":"1.168237984","rc":[{"batl":[[0,2.18,1.68],[1,2.3,1.1],[2,2.34,4.75]],"ltp":2.14,"tv":11380.52,"id":13181195}]}]}
{"op":"mcm","clk":"1008304670","pt":1580659429756,"mc":[{"id":"1.168237984","rc":[{"trd":[[1.86,4.44]],"batl":[[0,1.86,262.45],[1,1.88,234.52],[2,1.92,480.59]],"ltp":1.86,"tv":3965.69,"id":14833204},{"trd":[[2.16,3.82]],"ltp":2.16,"tv":11384.34,"id":13181195}],"tv":15350.04}]}
{"op":"mcm","clk":"1008305848","pt":1580659435995,"mc":[{"id":"1.168237984","rc":[{"batl":[[0,1.92,480.59],[1,1.94,497.4],[2,2.02,5.75]],"ltp":1.86,"tv":3965.69,"id":14833204}]}]}
{"op":"mcm","clk":"1008306232","pt":1580659438279,"mc":[{"id":"1.168237984","rc":[{"trd":[[1.85,55.73]],"batb":[[0,1.85,5.45]],"ltp":1.85,"tv":3974.81,"id":14833204}],"tv":15359.15}]}
{"op":"mcm","clk":"1008306416","pt":1580659439375,"mc":[{"id":"1.168237984","rc":[{"batb":[[0,1.86,2.69],[1,1.85,5.45],[2,1.84,50.01]],"batl":[[2,1.96,175.01]],"ltp":1.85,"tv":3974.81,"id":14833204}]}]}
{"op":"mcm","clk":"1008307442","pt":1580659445303,"mc":[{"id":"1.168237984","rc":[{"batl":[[0,1.96,175.01],[1,1.98,200.32],[2,2.02,5.75]],"ltp":1.85,"tv":3974.81,"id":14833204}]}]}
{"op":"mcm","clk":"1008307940","pt":1580659447853,"mc":[{"id":"1.168237984","rc":[{"batb":[[0,1.92,8.32],[1,1.91,9.39],[2,1.89,242.01]],"batl":[[0,1.96,701.21],[1,1.97,506],[2,1.98,200.32]],"ltp":1.85,"tv":3974.81,"id":14833204},{"batl":[[0,2.1,2.75],[1,2.18,413.68],[2,2.2,628.73]],"ltp":2.16,"tv":11384.34,"id":13181195}]}]}
{"op":"mcm","clk":"1008308149","pt":1580659448935,"mc":[{"id":"1.168237984","rc":[{"batb":[[0,1.92,57.08],[2,1.89,309.68]],"ltp":1.85,"tv":3974.81,"id":14833204}]}]}
{"op":"mcm","clk":"1008308274","pt":1580659449537,"mc":[{"id":"1.168237984","rc":[{"batb":[[0,1.93,341.35],[1,1.92,57.08],[2,1.91,9.39]],"ltp":1.85,"tv":3974.81,"id":14833204}]}]}
{"op":"mcm","clk":"1008308774","pt":1580659452016,"mc":[{"id":"1.168237984","rc":[{"batb":[[0,1.92,8.32],[1,1.91,9.39],[2,1.89,356.88]],"ltp":1.85,"tv":3974.81,"id":14833204},{"batb":[[1,1.95,15.51],[2,1.94,66.41]],"ltp":2.16,"tv":11384.34,"id":13181195}]}]}
{"op":"mcm","clk":"1008309013","pt":1580659453245,"mc":[{"id":"1.168237984","rc":[{"batb":[[2,1.9,46.68]],"ltp":1.85,"tv":3974.81,"id":14833204}]}]}
{"op":"mcm","clk":"1008310079","pt":1580659459273,"mc":[{"id":"1.168237984","rc":[{"trd":[[2.04,4.99]],"batb":[[0,2.04,113.47]],"ltp":2.04,"tv":11386.52,"id":13181195}],"tv":15361.34}]}
{"op":"mcm","clk":"1008310455","pt":1580659461467,"mc":[{"id":"1.168237984","rc":[{"batb":[[0,1.92,922.76]],"ltp":1.85,"tv":3974.81,"id":14833204}]}]}
{"op":"mcm","clk":"1008311407","pt":1580659466746,"mc":[{"id":"1.168237984","rc":[{"trd":[[1.92,9.76]],"batb":[[0,1.92,917.88]],"ltp":1.92,"tv":3984.57,"id":14833204}],"tv":15371.09}]}
{"op":"mcm","clk":"1008311817","pt":1580659469015,"mc":[{"id":"1.168237984","rc":[{"trd":[[1.92,16.31]],"batb":[[0,1.92,914.6]],"ltp":1.92,"tv":3991.12,"id":14833204}],"tv":15377.65}]}
{"op":"mcm","clk":"1008311927","pt":1580659469652,"mc":[{"id":"1.168237984","rc":[{"batl":[[1,1.98,200.32],[2,2.02,5.75]],"ltp":1.92,"tv":3991.12,"id":14833204},{"batl":[[1,2.18,1.68]],"ltp":2.04,"tv":11386.52,"id":13181195}]}]}
{"op":"mcm","clk":"1008313247","pt":1580659476831,"mc":[{"id":"1.168237984","rc":[{"batb":[[0,1.92,914.44]],"batl":[[0,1.96,691.22]],"ltp":1.92,"tv":3991.12,"id":14833204}]}]}
{"op":"mcm","clk":"1008313852","pt":1580659480044,"mc":[{"id":"1.168237984","rc":[{"trd":[[1.92,18.33]],"batb":[[0,1.92,913.43]],"ltp":1.92,"tv":3993.14,"id":14833204}],"tv":15379.67}]}
{"op":"mcm","clk":"1008314422","pt":1580659482937,"mc":[{"id":"1.168237984","rc":[{"trd":[[1.96,8.3]],"batl":[[0,1.94,9.11],[1,1.96,688.53],[2,1.98,200.32]],"ltp":1.96,"tv":3998.52,"id":14833204},{"batb":[[0,1.95,15.51],[1,1.94,66.41],[2,1.93,18.36]],"batl":[[1,2.12,11.97],[2,2.18,1.68]],"ltp":2.04,"tv":11386.52,"id":13181195}],"tv":15385.05}]}
{"op":"mcm","clk":"1008314844","pt":1580659484941,"mc":[{"id":"1.168237984","rc":[{"batl":[[1,1.96,516.21],[2,2.02,5.75]],"ltp":1.96,"tv":3998.52,"id":14833204}]}]}
{"op":"mcm","clk":"1008314990","pt":1580659485776,"mc":[{"id":"1.168237984","rc":[{"trd":[[1.92,34.69]],"batb":[[0,1.91,9.39],[1,1.9,46.68],[2,1.86,101.68]],"ltp":1.92,"tv":4014.88,"id":14833204}],"tv":15401.41}]}
{"op":"mcm","clk":"1008315155","pt":1580659486633,"mc":[{"id":"1.168237984","rc":[{"trd":[[1.94,17.84]],"batl":[[0,1.96,516.4],[1,2.02,5.75],[2,2.06,5.75]],"ltp":1.94,"tv":4032.72,"id":14833204}],"tv":15419.25}]}
{"op":"mcm","clk":"1008315555","pt":1580659488823,"mc":[{"id":"1.168237984","rc":[{"batl":[[2,2.06,162.32]],"ltp":1.94,"tv":4032.72,"id":14833204}]}]}
{"op":"mcm","clk":"1008316551","pt":1580659493552,"mc":[{"id":"1.168237984","rc":[{"batb":[[0,1.9,46.68],[1,1.85,5.45],[2,1.84,50.01]],"batl":[[0,2.06,156.57],[1,2.08,178.89],[2,2.14,5.75]],"ltp":1.94,"tv":4032.72,"id":14833204},{"batb":[[0,1.94,66.41],[1,1.93,18.36],[2,1.88,22.71]],"batl":[[0,2.18,1.68],[1,2.28,5.09],[2,2.3,1.1]],"ltp":2.04,"tv":11386.52,"id":13181195}]}]}
{"op":"mcm","clk":"1008316835","pt":1580659495019,"mc":[{"id":"1.168237984","rc":[{"batl":[[0,1.91,6.84],[1,2.06,156.57],[2,2.08,178.89]],"ltp":1.94,"tv":4032.72,"id":14833204}]}]}
{"op":"mcm","clk":"1008317424","pt":1580659498148,"mc":[{"id":"1.168237984","rc":[{"trd":[[1.91,2.24]],"batl":[[0,1.91,5.72]],"ltp":1.91,"tv":4034.97,"id":14833204}],"tv":15421.49}]}
{"op":"mcm","clk":"1008317605","pt":1580659499169,"mc":[{"id":"1.168237984","rc":[{"batl":[[0,2.06,156.57],[1,2.08,178.89],[2,2.14,5.75]],"ltp":1.91,"tv":4034.97,"id":14833204}]}]}
{"op":"mcm","clk":"1008318243","pt":1580659502402,"mc":[{"id":"1.168237984","rc":[{"trd":[[1.9,280.02]],"batb":[[0,1.9,40.96]],"ltp":1.9,"tv":4046.41,"id":14833204},{"batl":[[2,2.3,6.05]],"ltp":2.04,"tv":11386.52,"id":13181195}],"tv":15432.93}]}
{"op":"mcm","clk":"1008320295","pt":1580659513087,"mc":[{"id":"1.168237984","rc":[{"batl":[[1,2.3,6.05],[2,2.34,4.75]],"ltp":2.04,"tv":11386.52,"id":13181195}]}]}
{"op":"mcm","clk":"1008322355","pt":1580659522881,"mc":[{"id":"1.168237984","rc":[{"batl":[[0,2.14,5.75],[1,2.36,299.17],[2,1000,0.02]],"ltp":1.9,"tv":4046.41,"id":14833204},{"trd":[[1.94,2.58]],"batb":[[0,1.94,65.12],[1,1.88,22.71],[2,1.8,15.14]],"ltp":1.94,"tv":11389.11,"id":13181195}],"tv":15435.52}]}
{"op":"mcm","clk":"1008322907","pt":1580659526002,"mc":[{"id":"1.168237984","rc":[{"batb":[[0,2,6.85],[1,1.99,215.53],[2,1.98,93.31]],"batl":[[0,2.06,543.22],[1,2.08,563],[2,2.14,5.75]],"ltp":1.9,"tv":4046.41,"id":14833204},{"batb":[[0,1.94,267.19],[1,1.92,215.94],[2,1.88,22.71]],"batl":[[0,2,6.85],[1,2.02,258.82],[2,2.04,183.23]],"ltp":1.94,"tv":11389.11,"id":13181195}]}]}
{"op":"mcm","clk":"1008324299","pt":1580659532623,"mc":[{"id":"1.168237984","rc":[{"trd":[[1.94,6.15]],"batb":[[0,1.94,265.41]],"ltp":1.94,"tv":11392.67,"id":13181195}],"tv":15439.08}]}
{"op":"mcm","clk":"1008324807","pt":1580659535322,"mc":[{"id":"1.168237984","rc":[{"batl":[[0,1.98,138.63],[1,2,6.85],[2,2.02,258.82]],"ltp":1.94,"tv":11392.67,"id":13181195}]}]}
{"op":"mcm","clk":"1008325701","pt":1580659540032,"mc":[{"id":"1.168237984","rc":[{"trd":[[2.02,12.46]],"ltp":2.02,"tv":4058.87,"id":14833204},{"trd":[[1.98,12.71]],"batl":[[0,1.98,125.92]],"ltp":1.98,"tv":11405.38,"id":13181195}],"tv":15464.25}]}
{"op":"mcm","clk":"1008326207","pt":1580659542610,"mc":[{"id":"1.168237984","rc":[{"trd":[[2.02,14.17]],"ltp":2.02,"tv":4060.58,"id":14833204},{"trd":[[1.98,14.46]],"batl":[[0,1.98,124.17]],"ltp":1.98,"tv":11407.13,"id":13181195}],"tv":15467.71}]}
{"op":"mcm","clk":"1008326604","pt":1580659544753,"mc":[{"id":"1.168237984","rc":[{"trd":[[1.94,103.67]],"batb":[[0,1.94,216.64]],"ltp":1.94,"tv":11504.66,"id":13181195}],"tv":15565.24}]}
{"op":"mcm","clk":"1008326850","pt":1580659545925,"mc":[{"id":"1.168237984","rc":[{"trd":[[2.06,42.72]],"batl":[[0,2.06,521.86]],"ltp":2.06,"tv":4103.3,"id":14833204}],"tv":15607.96}]}
{"op":"mcm","clk":"1008327296","pt":1580659548044,"mc":[{"id":"1.168237984","rc":[{"batb":[[0,1.97,43.31],[1,1.95,44.22],[2,1.9,17.96]],"batl":[[0,2.14,5.75],[1,2.18,4.75],[2,2.36,299.17]],"ltp":2.06,"tv":4103.3,"id":14833204},{"trd":[[1.94,106.14]],"batb":[[0,1.88,22.71],[1,1.85,99.75],[2,1.8,15.14]],"batl":[[1,2.12,5.46],[2,2.18,5.75]],"ltp":1.94,"tv":11507.12,"id":13181195}],"tv":15610.43}]}
{"op":"mcm","clk":"1008327347","pt":1580659548370,"mc":[{"id":"1.168237984","rc":[{"batl":[[0,2.18,4.75],[1,2.36,299.17],[2,1000,0.02]],"ltp":2.06,"tv":4103.3,"id":14833204},{"batb":[[0,1.85,99.75],[1,1.8,15.14],[2,1.77,2]],"ltp":1.94,"tv":11507.12,"id":13181195}]}]}
