{"op":"mcm","clk":"1002315141","pt":1580592409750,"mc":[{"id":"1.168237986","marketDefinition":{"bspMarket":false,"turnInPlayEnabled":true,"persistenceEnabled":true,"marketBaseRate":5.0,"eventId":"29681871","eventTypeId":"2","numberOfWinners":1,"bettingType":"ODDS","marketType":"SET_WINNER","marketTime":"2020-02-02T16:00:00.000Z","suspendTime":"2020-02-02T16:00:00.000Z","bspReconciled":false,"complete":true,"inPlay":false,"crossMatching":false,"runnersVoidable":false,"numberOfActiveRunners":2,"betDelay":0,"status":"OPEN","runners":[{"status":"ACTIVE","sortPriority":1,"id":14833204,"name":"Facundo Diaz Acosta"},{"status":"ACTIVE","sortPriority":2,"id":13181195,"name":"Pedro Martinez"}],"regulators":["MR_INT"],"countryCode":"AR","discountAllowed":false,"timezone":"UTC","openDate":"2020-02-02T16:00:00.000Z","version":3147569478,"name":"Set 1 Winner","eventName":"Diaz Acosta v Martinez"},"rc":[{"batb":[[0,1.01,20]],"ltp":0.0,"tv":0.0,"id":14833204},{"batb":[[0,1.01,20]],"ltp":0.0,"tv":0.0,"id":13181195}]}]}
{"op":"mcm","clk":"1002315289","pt":1580592411040,"mc":[{"id":"1.168237986","marketDefinition":{"bspMarket":false,"turnInPlayEnabled":true,"persistenceEnabled":true,"marketBaseRate":5.0,"eventId":"29681871","eventTypeId":"2","numberOfWinners":1,"bettingType":"ODDS","marketType":"SET_WINNER","marketTime":"2020-02-02T16:00:00.000Z","suspendTime":"2020-02-02T16:00:00.000Z","bspReconciled":false,"complete":true,"inPlay":false,"crossMatching":false,"runnersVoidable":false,"numberOfActiveRunners":2,"betDelay":0,"status":"OPEN","runners":[{"status":"ACTIVE","sortPriority":1,"id":14833204,"name":"Facundo Diaz Acosta"},{"status":"ACTIVE","sortPriority":2,"id":13181195,"name":"Pedro Martinez"}],"regulators":["MR_INT"],"countryCode":"AR","discountAllowed":false,"timezone":"UTC","openDate":"2020-02-02T16:00:00.000Z","version":3147569478,"name":"Set 1 Winner","eventName":"Diaz Acosta v Martinez"}}]}
{"op":"mcm","clk":"1002315411","pt":1580592412044,"mc":[{"id":"1.168237986","marketDefinition":{"bspMarket":false,"turnInPlayEnabled":true,"persistenceEnabled":true,"marketBaseRate":5.0,"eventId":"29681871","eventTypeId":"2","numberOfWinners":1,"bettingType":"ODDS","marketType":"SET_WINNER","marketTime":"2020-02-02T16:00:00.000Z","suspendTime":"2020-02-02T16:00:00.000Z","bspReconciled":false,"complete":true,"inPlay":false,"crossMatching":false,"runnersVoidable":false,"numberOfActiveRunners":2,"betDelay":0,"status":"OPEN","runners":[{"status":"ACTIVE","sortPriority":1,"id":14833204,"name":"Facundo Diaz Acosta"},{"status":"ACTIVE","sortPriority":2,"id":13181195,"name":"Pedro Martinez"}],"regulators":["MR_INT"],"countryCode":"AR","discountAllowed":true,"timezone":"UTC","openDate":"2020-02-02T16:00:00.000Z","version":3147569478,"name":"Set 1 Winner","eventName":"Diaz Acosta v Martinez"}}]}
{"op":"mcm","clk":"1002335495","pt":1580592618850,"mc":[{"id":"1.168237986","rc":[{"batb":[[0,1.01,10]],"ltp":0.0,"tv":0.0,"id":14833204},{"batb":[[0,1.01,10]],"ltp":0.0,"tv":0.0,"id":13181195}]}]}
{"op":"mcm","clk":"1003013621","pt":1580601985140,"mc":[{"id":"1.168237986","rc":[{"batb":[[0,1.01,10.51]],"ltp":0.0,"tv":0.0,"id":14833204},{"batb":[[0,1.01,10.51]],"ltp":0.0,"tv":0.0,"id":13181195}]}]}
{"op":"mcm","clk":"1003143216","pt":1580603525857,"mc":[{"id":"1.168237986","rc":[{"batb":[[0,1.01,13.04]],"ltp":0.0,"tv":0.0,"id":14833204},{"batb":[[0,1.01,13.04]],"ltp":0.0,"tv":0.0,"id":13181195}]}]}
{"op":"mcm","clk":"1003143311","pt":1580603526992,"mc":[{"id":"1.168237986","rc":[{"batb":[[0,1.01,11.01]],"ltp":0.0,"tv":0.0,"id":14833204},{"batb":[[0,1.01,11.01]],"ltp":0.0,"tv":0.0,"id":13181195}]}]}
{"op":"mcm","clk":"1006055670","pt":1580646226385,"mc":[{"id":"1.168237986","rc":[{"batl":[[0,1.94,7.57]],"ltp":0.0,"tv":0.0,"id":13181195}]}]}
{"op":"mcm","clk":"1006912530","pt":1580651802470,"mc":[{"id":"1.168237986","marketDefinition":{"bspMarket":false,"turnInPlayEnabled":true,"persistenceEnabled":true,"marketBaseRate":5.0,"eventId":"29681871","eventTypeId":"2","numberOfWinners":1,"bettingType":"ODDS","marketType":"SET_WINNER","marketTime":"2020-02-02T15:52:00.000Z","suspendTime":"2020-02-02T15:52:00.000Z","bspReconciled":false,"complete":true,"inPlay":false,"crossMatching":false,"runnersVoidable":false,"numberOfActiveRunners":2,"betDelay":0,"status":"OPEN","runners":[{"status":"ACTIVE","sortPriority":1,"id":14833204,"name":"Facundo Diaz Acosta"},{"status":"ACTIVE","sortPriority":2,"id":13181195,"name":"Pedro Martinez"}],"regulators":["MR_INT"],"countryCode":"AR","discountAllowed":true,"timezone":"UTC","openDate":"2020-02-02T16:00:00.000Z","version":3149006555,"name":"Set 1 Winner","eventName":"Diaz Acosta v Martinez"}}]}
{"op":"mcm","clk":"1006912941","pt":1580651805472,"mc":[{"id":"1.168237986","marketDefinition":{"bspMarket":false,"turnInPlayEnabled":true,"persistenceEnabled":true,"marketBaseRate":5.0,"eventId":"29681871","eventTypeId":"2","numberOfWinners":1,"bettingType":"ODDS","marketType":"SET_WINNER","marketTime":"2020-02-02T15:52:00.000Z","suspendTime":"2020-02-02T15:52:00.000Z","bspReconciled":false,"complete":true,"inPlay":false,"crossMatching":false,"runnersVoidable":false,"numberOfActiveRunners":2,"betDelay":0,"status":"OPEN","runners":[{"status":"ACTIVE","sortPriority":1,"id":14833204,"name":"Facundo Diaz Acosta"},{"status":"ACTIVE","sortPriority":2,"id":13181195,"name":"Pedro Martinez"}],"regulators":["MR_INT"],"countryCode":"AR","discountAllowed":true,"timezone":"UTC","openDate":"2020-02-02T15:52:00.000Z","version":3149006555,"name":"Set 1 Winner","eventName":"Diaz Acosta v Martinez"}}]}
{"op":"mcm","clk":"1007507372","pt":1580655626532,"mc":[{"id":"1.168237986","rc":[{"batb":[[0,1.02,2],[1,1.01,11.01]],"ltp":0.0,"tv":0.0,"id":13181195}]}]}
{"op":"mcm","clk":"1007510487","pt":1580655647550,"mc":[{"id":"1.168237986","marketDefinition":{"bspMarket":false,"turnInPlayEnabled":true,"persistenceEnabled":true,"marketBaseRate":5.0,"eventId":"29681871","eventTypeId":"2","numberOfWinners":1,"bettingType":"ODDS","marketType":"SET_WINNER","marketTime":"2020-02-02T15:52:00.000Z","suspendTime":"2020-02-02T15:52:00.000Z","bspReconciled":false,"complete":true,"inPlay":false,"crossMatching":true,"runnersVoidable":false,"numberOfActiveRunners":2,"betDelay":0,"status":"OPEN","runners":[{"status":"ACTIVE","sortPriority":1,"id":14833204,"name":"Facundo Diaz Acosta"},{"status":"ACTIVE","sortPriority":2,"id":13181195,"name":"Pedro Martinez"}],"regulators":["MR_INT"],"countryCode":"AR","discountAllowed":true,"timezone":"UTC","openDate":"2020-02-02T15:52:00.000Z","version":3149006555,"name":"Set 1 Winner","eventName":"Diaz Acosta v Martinez"}}]}
{"op":"mcm","clk":"1007629475","pt":1580656225605,"mc":[{"id":"1.168237986","rc":[{"batb":[[0,1.01,11.01],[1,1.01,0]],"ltp":0.0,"tv":0.0,"id":13181195}]}]}
{"op":"mcm","clk":"1007634416","pt":1580656244963,"mc":[{"id":"1.168237986","rc":[{"batb":[[0,1.02,2],[1,1.01,11.01]],"ltp":0.0,"tv":0.0,"id":13181195}]}]}
{"op":"mcm","clk":"1007718413","pt":1580656602839,"mc":[{"id":"1.168237986","marketDefinition":{"bspMarket":false,"turnInPlayEnabled":true,"persistenceEnabled":true,"marketBaseRate":5.0,"eventId":"29681871","eventTypeId":"2","numberOfWinners":1,"bettingType":"ODDS","marketType":"SET_WINNER","marketTime":"2020-02-02T15:20:00.000Z","suspendTime":"2020-02-02T15:20:00.000Z","bspReconciled":false,"complete":true,"inPlay":false,"crossMatching":true,"runnersVoidable":false,"numberOfActiveRunners":2,"betDelay":0,"status":"OPEN","runners":[{"status":"ACTIVE","sortPriority":1,"id":14833204,"name":"Facundo Diaz Acosta"},{"status":"ACTIVE","sortPriority":2,"id":13181195,"name":"Pedro Martinez"}],"regulators":["MR_INT"],"countryCode":"AR","discountAllowed":true,"timezone":"UTC","openDate":"2020-02-02T15:52:00.000Z","version":3149441889,"name":"Set 1 Winner","eventName":"Diaz Acosta v Martinez"}}]}
{"op":"mcm","clk":"1007718966","pt":1580656604846,"mc":[{"id":"1.168237986","marketDefinition":{"bspMarket":false,"turnInPlayEnabled":true,"persistenceEnabled":true,"marketBaseRate":5.0,"eventId":"29681871","eventTypeId":"2","numberOfWinners":1,"bettingType":"ODDS","marketType":"SET_WINNER","marketTime":"2020-02-02T15:20:00.000Z","suspendTime":"2020-02-02T15:20:00.000Z","bspReconciled":false,"complete":true,"inPlay":false,"crossMatching":true,"runnersVoidable":false,"numberOfActiveRunners":2,"betDelay":0,"status":"OPEN","runners":[{"status":"ACTIVE","sortPriority":1,"id":14833204,"name":"Facundo Diaz Acosta"},{"status":"ACTIVE","sortPriority":2,"id":13181195,"name":"Pedro Martinez"}],"regulators":["MR_INT"],"countryCode":"AR","discountAllowed":true,"timezone":"UTC","openDate":"2020-02-02T15:20:00.000Z","version":3149441889,"name":"Set 1 Winner","eventName":"Diaz Acosta v Martinez"}}]}
{"op":"mcm","clk":"1007774316","pt":1580656844363,"mc":[{"id":"1.168237986","rc":[{"batb":[[0,1.01,11.01],[1,1.01,0]],"ltp":0.0,"tv":0.0,"id":13181195}]}]}
{"op":"mcm","clk":"1007775480","pt":1580656849793,"mc":[{"id":"1.168237986","rc":[{"batb":[[0,1.02,2],[1,1.01,11.01]],"ltp":0.0,"tv":0.0,"id":13181195}]}]}
{"op":"mcm","clk":"1007786256","pt":1580656898010,"mc":[{"id":"1.168237986","rc":[{"batb":[[0,3.1,20.69],[1,1.01,11.01]],"ltp":0.0,"tv":0.0,"id":14833204},{"batb":[[0,1.4,50.12],[1,1.02,2],[2,1.01,11.01]],"ltp":0.0,"tv":0.0,"id":13181195}]}]}
{"op":"mcm","clk":"1007788051","pt":1580656905837,"mc":[{"id":"1.168237986","rc":[{"batb":[[0,1.4,49.65]],"ltp":0.0,"tv":0.0,"id":13181195}]}]}
{"op":"mcm","clk":"1007790359","pt":1580656915738,"mc":[{"id":"1.168237986","rc":[{"batb":[[0,1.41,49.18],[1,1.4,49.65],[2,1.02,2]],"ltp":0.0,"tv":0.0,"id":13181195}]}]}
{"op":"mcm","clk":"1007790445","pt":1580656916172,"mc":[{"id":"1.168237986","rc":[{"batb":[[1,1.02,2],[2,1.01,11.01]],"ltp":0.0,"tv":0.0,"id":13181195}]}]}
{"op":"mcm","clk":"1007871872","pt":1580657275659,"mc":[{"id":"1.168237986","rc":[{"batb":[[0,3.05,21.56]],"ltp":0.0,"tv":0.0,"id":14833204},{"batb":[[0,1.41,48.55]],"ltp":0.0,"tv":0.0,"id":13181195}]}]}
{"op":"mcm","clk":"1007874221","pt":1580657285809,"mc":[{"id":"1.168237986","rc":[{"batb":[[0,1.41,48]],"ltp":0.0,"tv":0.0,"id":13181195}]}]}
{"op":"mcm","clk":"1007876473","pt":1580657295612,"mc":[{"id":"1.168237986","rc":[{"batb":[[0,1.42,47.52]],"ltp":0.0,"tv":0.0,"id":13181195}]}]}
{"op":"mcm","clk":"1007879177","pt":1580657306898,"mc":[{"id":"1.168237986","rc":[{"batb":[[1,1.01,12.69]],"ltp":0.0,"tv":0.0,"id":14833204},{"batb":[[0,1.43,1.76],[1,1.42,47.52],[2,1.02,2]],"ltp":0.0,"tv":0.0,"id":13181195}]}]}
{"op":"mcm","clk":"1007879392","pt":1580657307835,"mc":[{"id":"1.168237986","rc":[{"batb":[[0,3.05,22.37],[1,1.01,11.01]],"ltp":0.0,"tv":0.0,"id":14833204}]}]}
{"op":"mcm","clk":"1007910907","pt":1580657449049,"mc":[{"id":"1.168237986","rc":[{"batb":[[2,1.01,11.01]],"ltp":0.0,"tv":0.0,"id":13181195}]}]}
{"op":"mcm","clk":"1008031570","pt":1580657987377,"mc":[{"id":"1.168237986","marketDefinition":{"bspMarket":false,"turnInPlayEnabled":true,"persistenceEnabled":true,"marketBaseRate":5.0,"eventId":"29681871","eventTypeId":"2","numberOfWinners":1,"bettingType":"ODDS","marketType":"SET_WINNER","marketTime":"2020-02-02T15:20:00.000Z","suspendTime":"2020-02-02T15:20:00.000Z","bspReconciled":false,"complete":true,"inPlay":false,"crossMatching":true,"runnersVoidable":false,"numberOfActiveRunners":2,"betDelay":0,"status":"OPEN","runners":[{"status":"ACTIVE","sortPriority":1,"id":14833204,"name":"Facundo Diaz Acosta"},{"status":"ACTIVE","sortPriority":2,"id":13181195,"name":"Pedro Martinez"}],"regulators":["MR_INT"],"countryCode":"AR","discountAllowed":true,"timezone":"UTC","openDate":"2020-02-02T15:20:00.000Z","version":3149466722,"name":"Set 1 Winner","eventName":"Diaz Acosta v Martinez"},"rc":[{"batb":[[0,1.01,11.83],[1,1.01,0]],"ltp":0.0,"tv":0.0,"id":14833204},{"batb":[[1,1.01,11.01],[2,1.01,0]],"ltp":0.0,"tv":0.0,"id":13181195}]}]}
{"op":"mcm","clk":"1008031747","pt":1580657988210,"mc":[{"id":"1.168237986","marketDefinition":{"bspMarket":false,"turnInPlayEnabled":true,"persistenceEnabled":true,"marketBaseRate":5.0,"eventId":"29681871","eventTypeId":"2","numberOfWinners":1,"bettingType":"ODDS","marketType":"SET_WINNER","marketTime":"2020-02-02T15:20:00.000Z","suspendTime":"2020-02-02T15:20:00.000Z","bspReconciled":false,"complete":true,"inPlay":true,"crossMatching":true,"runnersVoidable":false,"numberOfActiveRunners":2,"betDelay":3,"status":"OPEN","runners":[{"status":"ACTIVE","sortPriority":1,"id":14833204,"name":"Facundo Diaz Acosta"},{"status":"ACTIVE","sortPriority":2,"id":13181195,"name":"Pedro Martinez"}],"regulators":["MR_INT"],"countryCode":"AR","discountAllowed":true,"timezone":"UTC","openDate":"2020-02-02T15:20:00.000Z","version":3149542069,"name":"Set 1 Winner","eventName":"Diaz Acosta v Martinez"},"rc":[{"batb":[[0,1.01,10.51]],"ltp":0.0,"tv":0.0,"id":14833204},{"batb":[[0,1.01,10.51],[1,1.01,0]],"ltp":0.0,"tv":0.0,"id":13181195}]}]}
{"op":"mcm","clk":"1008033549","pt":1580657995685,"mc":[{"id":"1.168237986","rc":[{"batb":[[0,2.66,12.59],[1,2.3,18.57],[2,1.01,10.51]],"ltp":0.0,"tv":0.0,"id":14833204},{"batb":[[0,1.52,35.56],[1,1.44,45.01],[2,1.01,10.51]],"ltp":0.0,"tv":0.0,"id":13181195}]}]}
{"op":"mcm","clk":"1008034798","pt":1580658000875,"mc":[{"id":"1.168237986","rc":[{"batb":[[0,1.53,268],[1,1.52,199.43],[2,1.44,45.01]],"batl":[[0,1.59,204.68],[1,1.6,132.57]],"ltp":0.0,"tv":0.0,"id":13181195}]}]}
{"op":"mcm","clk":"1008036952","pt":1580658009866,"mc":[{"id":"1.168237986","rc":[{"batb":[[0,2.3,18.57],[1,1.01,10.51],[2,1.01,0]],"ltp":0.0,"tv":0.0,"id":14833204},{"batb":[[0,1.44,45.01],[1,1.01,10.51],[2,1.44,0]],"ltp":0.0,"tv":0.0,"id":13181195}]}]}
{"op":"mcm","clk":"1008038182","pt":1580658014892,"mc":[{"id":"1.168237986","rc":[{"batb":[[0,1.56,262.63],[1,1.55,151.73],[2,1.44,45.01]],"batl":[[0,1.62,158.31],[1,1.63,124.23]],"ltp":0.0,"tv":0.0,"id":13181195}]}]}
{"op":"mcm","clk":"1008038851","pt":1580658017589,"mc":[{"id":"1.168237986","rc":[{"batb":[[0,1.44,45.01],[1,1.01,10.51],[2,1.44,0]],"ltp":0.0,"tv":0.0,"id":13181195}]}]}
{"op":"mcm","clk":"1008039486","pt":1580658020307,"mc":[{"id":"1.168237986","rc":[{"batb":[[0,1.45,182.26],[1,1.44,249.36],[2,1.01,10.51]],"batl":[[0,1.77,166.13],[1,1.79,182.16]],"ltp":0.0,"tv":0.0,"id":13181195}]}]}
{"op":"mcm","clk":"1008041658","pt":1580658028990,"mc":[{"id":"1.168237986","rc":[{"batl":[[0,1.5,294.87],[1,1.51,164.16]],"ltp":0.0,"tv":0.0,"id":13181195}]}]}
{"op":"mcm","clk":"1008041909","pt":1580658030024,"mc":[{"id":"1.168237986","rc":[{"batb":[[0,2.96,23.76],[1,2.56,14.08],[2,2.42,452.32]],"ltp":0.0,"tv":0.0,"id":14833204},{"batb":[[2,1.36,57.28]],"ltp":0.0,"tv":0.0,"id":13181195}]}]}
{"op":"mcm","clk":"1008041953","pt":1580658030192,"mc":[{"id":"1.168237986","rc":[{"batb":[[2,1.01,10.51]],"ltp":0.0,"tv":0.0,"id":14833204}]}]}
{"op":"mcm","clk":"1008046192","pt":1580658047328,"mc":[{"id":"1.168237986","rc":[{"batb":[[0,2.56,14.08],[1,1.01,10.51],[2,1.01,0]],"ltp":0.0,"tv":0.0,"id":14833204},{"batb":[[0,1.36,57.28],[1,1.01,10.51],[2,1.36,0]],"ltp":0.0,"tv":0.0,"id":13181195}]}]}
{"op":"mcm","clk":"1008046920","pt":1580658050139,"mc":[{"id":"1.168237986","rc":[{"batb":[[0,1.38,171.21],[1,1.37,255.91],[2,1.36,57.28]],"batl":[[0,1.64,145.4],[1,1.65,119.07]],"ltp":0.0,"tv":0.0,"id":13181195}]}]}
{"op":"mcm","clk":"1008048299","pt":1580658055728,"mc":[{"id":"1.168237986","rc":[{"batb":[[0,1.36,57.28],[1,1.01,10.51],[2,1.36,0]],"ltp":0.0,"tv":0.0,"id":13181195}]}]}
{"op":"mcm","clk":"1008048973","pt":1580658058638,"mc":[{"id":"1.168237986","rc":[{"batb":[[0,1.58,243.39],[1,1.57,144.35],[2,1.36,57.28]],"ltp":0.0,"tv":0.0,"id":13181195}]}]}
{"op":"mcm","clk":"1008049231","pt":1580658059833,"mc":[{"id":"1.168237986","rc":[{"batb":[[1,2.18,22.03],[2,1.01,10.51]],"ltp":0.0,"tv":0.0,"id":14833204},{"batb":[[2,1.56,32.26]],"ltp":0.0,"tv":0.0,"id":13181195}]}]}
{"op":"mcm","clk":"1008053977","pt":1580658081116,"mc":[{"id":"1.168237986","rc":[{"batb":[[0,2.18,22.03],[1,1.01,10.51],[2,1.01,0]],"ltp":0.0,"tv":0.0,"id":14833204},{"batb":[[0,1.45,43.12],[1,1.01,10.51],[2,1.56,0]],"ltp":0.0,"tv":0.0,"id":13181195}]}]}
{"op":"mcm","clk":"1008054702","pt":1580658084291,"mc":[{"id":"1.168237986","rc":[{"batb":[[0,1.47,201.04],[1,1.46,192.81],[2,1.45,43.12]],"batl":[[0,1.89,128.57],[1,1.91,148.65]],"ltp":0.0,"tv":0.0,"id":13181195}]}]}
{"op":"mcm","clk":"1008054957","pt":1580658085368,"mc":[{"id":"1.168237986","rc":[{"batb":[[0,1.45,43.12],[1,1.01,10.51],[2,1.45,0]],"ltp":0.0,"tv":0.0,"id":13181195}]}]}
{"op":"mcm","clk":"1008055707","pt":1580658088783,"mc":[{"id":"1.168237986","rc":[{"batb":[[0,1.62,242.98],[1,1.61,131.35],[2,1.45,43.12]],"batl":[[0,1.69,199.86],[1,1.71,211.59]],"ltp":0.0,"tv":0.0,"id":13181195}]}]}
{"op":"mcm","clk":"1008055914","pt":1580658089803,"mc":[{"id":"1.168237986","rc":[{"batb":[[0,1.45,43.12],[1,1.01,10.51],[2,1.45,0]],"ltp":0.0,"tv":0.0,"id":13181195}]}]}
{"op":"mcm","clk":"1008056576","pt":1580658092680,"mc":[{"id":"1.168237986","rc":[{"batb":[[0,1.47,201.04],[1,1.46,192.81],[2,1.45,43.12]],"batl":[[0,1.89,128.57],[1,1.91,148.65]],"ltp":0.0,"tv":0.0,"id":13181195}]}]}
{"op":"mcm","clk":"1008057753","pt":1580658098012,"mc":[{"id":"1.168237986","rc":[{"batb":[[0,1.45,43.12],[1,1.01,10.51],[2,1.45,0]],"ltp":0.0,"tv":0.0,"id":13181195}]}]}
{"op":"mcm","clk":"1008058472","pt":1580658101006,"mc":[{"id":"1.168237986","rc":[{"batb":[[0,1.81,179.04],[1,1.79,180.19],[2,1.45,43.12]],"batl":[[0,1.89,128.57],[1,1.91,148.65]],"ltp":0.0,"tv":0.0,"id":13181195}]}]}
{"op":"mcm","clk":"1008058687","pt":1580658101882,"mc":[{"id":"1.168237986","rc":[{"batb":[[1,1.91,16.13],[2,1.01,10.51]],"ltp":0.0,"tv":0.0,"id":14833204},{"batb":[[2,1.75,21.72]],"ltp":0.0,"tv":0.0,"id":13181195}]}]}
{"op":"mcm","clk":"1008063593","pt":1580658122878,"mc":[{"id":"1.168237986","rc":[{"batb":[[0,1.91,16.13],[1,1.01,10.51],[2,1.01,0]],"ltp":0.0,"tv":0.0,"id":14833204},{"batb":[[0,1.62,28.17],[1,1.01,10.51],[2,1.75,0]],"ltp":0.0,"tv":0.0,"id":13181195}]}]}
{"op":"mcm","clk":"1008064303","pt":1580658125874,"mc":[{"id":"1.168237986","rc":[{"batb":[[0,1.9,16.52]],"ltp":0.0,"tv":0.0,"id":14833204},{"batb":[[0,1.66,212.82],[1,1.65,120.03],[2,1.63,27.54]],"batl":[[0,2.22,128.3],[1,2.24,93.54]],"ltp":0.0,"tv":0.0,"id":13181195}]}]}
{"op":"mcm","clk":"1008065453","pt":1580658130659,"mc":[{"id":"1.168237986","rc":[{"batb":[[0,1.63,27.54],[1,1.01,10.51],[2,1.63,0]],"ltp":0.0,"tv":0.0,"id":13181195}]}]}
{"op":"mcm","clk":"1008066094","pt":1580658133412,"mc":[{"id":"1.168237986","rc":[{"trd":[[1.9,33.04]],"batb":[[0,1.82,153.67],[1,1.8,176.86],[2,1.01,10.51]],"batl":[[0,1.9,127.18],[1,1.92,146.27]],"ltp":1.9,"tv":33.04,"id":14833204}],"tv":33.04}]}
{"op":"mcm","clk":"1008066352","pt":1580658134596,"mc":[{"id":"1.168237986","rc":[{"batb":[[2,1.75,21.64]],"ltp":1.9,"tv":33.04,"id":14833204},{"batb":[[0,1.97,29.35],[1,1.78,20.22],[2,1.01,10.51]],"ltp":0.0,"tv":0.0,"id":13181195}]}]}
{"op":"mcm","clk":"1008068341","pt":1580658143006,"mc":[{"id":"1.168237986","rc":[{"batb":[[0,1.88,17],[1,1.82,153.67],[2,1.8,176.86]],"ltp":1.9,"tv":33.04,"id":14833204},{"batb":[[0,2.02,28.56],[1,1.83,19.59]],"ltp":0.0,"tv":0.0,"id":13181195}]}]}
{"op":"mcm","clk":"1008069510","pt":1580658147983,"mc":[{"id":"1.168237986","rc":[{"trd":[[1.82,307.34],[1.88,33.99]],"batb":[[0,1.73,22.27],[1,1.01,10.51],[2,1.8,0]],"batl":[[0,1.82,109.12],[1,1.92,0]],"ltp":1.82,"tv":374.37,"id":14833204}],"tv":374.37}]}
{"op":"mcm","clk":"1008070213","pt":1580658151022,"mc":[{"id":"1.168237986","rc":[{"batb":[[0,1.81,190.1],[1,1.79,180.32],[2,1.73,22.27]],"batl":[[1,1.89,118.49],[2,1.91,148.77]],"ltp":1.82,"tv":374.37,"id":14833204},{"batb":[[0,2.02,28.17],[1,1.84,19.36]],"ltp":0.0,"tv":0.0,"id":13181195}]}]}
{"op":"mcm","clk":"1008071269","pt":1580658155403,"mc":[{"id":"1.168237986","rc":[{"batl":[[0,1.89,118.49],[1,1.91,148.77],[2,1.91,0]],"ltp":1.82,"tv":374.37,"id":14833204}]}]}
{"op":"mcm","clk":"1008072040","pt":1580658158529,"mc":[{"id":"1.168237986","rc":[{"trd":[[1.81,218.24]],"batb":[[0,1.81,80.98]],"ltp":1.81,"tv":592.61,"id":14833204}],"tv":592.61}]}
{"op":"mcm","clk":"1008072889","pt":1580658162019,"mc":[{"id":"1.168237986","rc":[{"batb":[[0,1.81,150.14]],"batl":[[0,1.89,156.79]],"ltp":1.81,"tv":592.61,"id":14833204}]}]}
{"op":"mcm","clk":"1008075009","pt":1580658170771,"mc":[{"id":"1.168237986","rc":[{"batb":[[0,1.73,22.27],[1,1.01,10.51],[2,1.73,0]],"ltp":1.81,"tv":592.61,"id":14833204}]}]}
{"op":"mcm","clk":"1008075741","pt":1580658173683,"mc":[{"id":"1.168237986","rc":[{"batb":[[1,1.68,143.83],[2,1.66,233.5]],"batl":[[0,2.12,143.37],[1,2.14,106.39]],"ltp":1.81,"tv":592.61,"id":14833204}]}]}
{"op":"mcm","clk":"1008075902","pt":1580658174325,"mc":[{"id":"1.168237986","rc":[{"batb":[[0,1.74,557.29],[1,1.73,22.27],[2,1.68,143.83]],"ltp":1.81,"tv":592.61,"id":14833204},{"batb":[[0,2.04,436.62],[1,2.02,28.17],[2,1.84,19.36]],"ltp":0.0,"tv":0.0,"id":13181195}]}]}
{"op":"mcm","clk":"1008076306","pt":1580658175954,"mc":[{"id":"1.168237986","rc":[{"batb":[[0,1.73,22.27],[1,1.68,143.83],[2,1.66,233.5]],"ltp":1.81,"tv":592.61,"id":14833204},{"batb":[[0,2.02,28.17],[1,1.84,19.36],[2,1.01,10.51]],"ltp":0.0,"tv":0.0,"id":13181195}]}]}
{"op":"mcm","clk":"1008076404","pt":1580658176252,"mc":[{"id":"1.168237986","rc":[{"batb":[[0,1.84,19.36],[1,1.01,10.51],[2,1.01,0]],"ltp":0.0,"tv":0.0,"id":13181195}]}]}
{"op":"mcm","clk":"1008077355","pt":1580658179960,"mc":[{"id":"1.168237986","rc":[{"batb":[[0,1.72,22.9]],"ltp":1.81,"tv":592.61,"id":14833204},{"batb":[[0,1.85,19.12]],"ltp":0.0,"tv":0.0,"id":13181195}]}]}
{"op":"mcm","clk":"1008078038","pt":1580658182956,"mc":[{"id":"1.168237986","rc":[{"batl":[[0,1.74,117.08],[1,1.76,193.01]],"ltp":1.81,"tv":592.61,"id":14833204}]}]}
{"op":"mcm","clk":"1008078240","pt":1580658183863,"mc":[{"id":"1.168237986","rc":[{"batb":[[0,2.26,20.85],[1,2.02,28.64],[2,1.01,10.51]],"ltp":0.0,"tv":0.0,"id":13181195}]}]}
{"op":"mcm","clk":"1008080621","pt":1580658193873,"mc":[{"id":"1.168237986","rc":[{"batb":[[0,1.6,29.66],[1,1.01,10.51],[2,1.66,0]],"ltp":1.81,"tv":592.61,"id":14833204},{"batb":[[0,2.02,28.64],[1,1.01,10.51],[2,1.01,0]],"ltp":0.0,"tv":0.0,"id":13181195}]}]}
{"op":"mcm","clk":"1008081327","pt":1580658196866,"mc":[{"id":"1.168237986","rc":[{"batb":[[1,1.59,29.98],[2,1.58,151.57]],"batl":[[0,1.91,107.41],[1,1.93,144.2]],"ltp":1.81,"tv":592.61,"id":14833204},{"batb":[[0,2.04,28.4],[1,2.02,28.64],[2,1.01,10.51]],"ltp":0.0,"tv":0.0,"id":13181195}]}]}
{"op":"mcm","clk":"1008081467","pt":1580658197479,"mc":[{"id":"1.168237986","rc":[{"batb":[[0,1.59,29.98],[1,1.01,10.51],[2,1.58,0]],"ltp":1.81,"tv":592.61,"id":14833204},{"batb":[[1,1.01,10.51],[2,1.01,0]],"ltp":0.0,"tv":0.0,"id":13181195}]}]}
{"op":"mcm","clk":"1008082252","pt":1580658200874,"mc":[{"id":"1.168237986","rc":[{"batb":[[1,1.58,151.57],[2,1.57,144.27]],"batl":[[0,1.64,233.51],[1,1.65,119.03]],"ltp":1.81,"tv":592.61,"id":14833204},{"batb":[[0,2.54,15.42],[1,2.28,20.22],[2,1.01,10.51]],"ltp":0.0,"tv":0.0,"id":13181195}]}]}
{"op":"mcm","clk":"1008084207","pt":1580658209084,"mc":[{"id":"1.168237986","rc":[{"batb":[[1,1.58,125.51]],"batl":[[0,1.64,122.06],[1,1.65,0]],"ltp":1.81,"tv":592.61,"id":14833204}]}]}
{"op":"mcm","clk":"1008085101","pt":1580658212772,"mc":[{"id":"1.168237986","rc":[{"batb":[[1,1.51,36.74],[2,1.01,10.51]],"ltp":1.81,"tv":592.61,"id":14833204}]}]}
{"op":"mcm","clk":"1008085334","pt":1580658213809,"mc":[{"id":"1.168237986","rc":[{"batb":[[0,1.51,36.74],[1,1.01,10.51],[2,1.01,0]],"ltp":1.81,"tv":592.61,"id":14833204},{"batb":[[0,2.28,20.22],[1,1.01,10.51],[2,1.01,0]],"ltp":0.0,"tv":0.0,"id":13181195}]}]}
{"op":"mcm","clk":"1008085857","pt":1580658215998,"mc":[{"id":"1.168237986","rc":[{"batb":[[0,1.51,242.9],[1,1.5,173.04],[2,1.01,10.51]],"batl":[[0,1.74,148.87],[1,1.76,193.03]],"ltp":1.81,"tv":592.61,"id":14833204}]}]}
{"op":"mcm","clk":"1008086103","pt":1580658216979,"mc":[{"id":"1.168237986","rc":[{"batb":[[0,2.3,20.14]],"ltp":0.0,"tv":0.0,"id":13181195}]}]}
{"op":"mcm","clk":"1008087085","pt":1580658220986,"mc":[{"id":"1.168237986","rc":[{"batb":[[0,1.51,36.74],[1,1.01,10.51],[2,1.01,0]],"ltp":1.81,"tv":592.61,"id":14833204}]}]}
{"op":"mcm","clk":"1008087557","pt":1580658222980,"mc":[{"id":"1.168237986","rc":[{"batl":[[0,1.56,161.55],[1,1.57,142.84]],"ltp":1.81,"tv":592.61,"id":14833204}]}]}
{"op":"mcm","clk":"1008087758","pt":1580658223889,"mc":[{"id":"1.168237986","rc":[{"batb":[[1,1.46,42.49],[2,1.01,10.51]],"ltp":1.81,"tv":592.61,"id":14833204},{"batb":[[0,2.78,11.96],[1,2.58,14.48],[2,1.01,10.51]],"ltp":0.0,"tv":0.0,"id":13181195}]}]}
{"op":"mcm","clk":"1008090377","pt":1580658234503,"mc":[{"id":"1.168237986","rc":[{"batb":[[0,1.46,42.49],[1,1.01,10.51],[2,1.01,0]],"ltp":1.81,"tv":592.61,"id":14833204},{"batb":[[0,2.58,14.48],[1,1.01,10.51],[2,1.01,0]],"ltp":0.0,"tv":0.0,"id":13181195}]}]}
{"op":"mcm","clk":"1008091634","pt":1580658239708,"mc":[{"id":"1.168237986","rc":[{"batb":[[0,1.52,200.04],[1,1.51,168.42],[2,1.46,42.49]],"batl":[[0,1.57,151.03],[1,1.58,139.57]],"ltp":1.81,"tv":592.61,"id":14833204}]}]}
{"op":"mcm","clk":"1008092788","pt":1580658244699,"mc":[{"id":"1.168237986","rc":[{"batb":[[0,1.46,42.49],[1,1.01,10.51],[2,1.46,0]],"ltp":1.81,"tv":592.61,"id":14833204}]}]}
{"op":"mcm","clk":"1008093593","pt":1580658247917,"mc":[{"id":"1.168237986","rc":[{"trd":[[1.47,391.54]],"batb":[[0,1.47,120.02],[1,1.46,236.85],[2,1.01,10.51]],"batl":[[0,1.62,219.85],[1,1.63,124.41]],"ltp":1.47,"tv":984.14,"id":14833204}],"tv":984.14}]}
{"op":"mcm","clk":"1008093717","pt":1580658248414,"mc":[{"id":"1.168237986","rc":[{"batl":[[0,1.62,127.74],[1,1.63,0]],"ltp":1.47,"tv":984.14,"id":14833204}]}]}
{"op":"mcm","clk":"1008094472","pt":1580658251606,"mc":[{"id":"1.168237986","rc":[{"batb":[[0,1.47,244.09]],"ltp":1.47,"tv":984.14,"id":14833204}]}]}
{"op":"mcm","clk":"1008094808","pt":1580658253031,"mc":[{"id":"1.168237986","rc":[{"batl":[[0,1.52,201.29],[1,1.53,157.7]],"ltp":1.47,"tv":984.14,"id":14833204}]}]}
{"op":"mcm","clk":"1008095041","pt":1580658254036,"mc":[{"id":"1.168237986","rc":[{"batb":[[0,1.47,178],[2,1.36,56.26]],"ltp":1.47,"tv":984.14,"id":14833204},{"batb":[[0,2.96,25.57],[1,2.7,13.06],[2,1.01,10.51]],"ltp":0.0,"tv":0.0,"id":13181195}]}]}
{"op":"mcm","clk":"1008095208","pt":1580658254728,"mc":[{"id":"1.168237986","rc":[{"batb":[[2,2.12,388.65]],"ltp":0.0,"tv":0.0,"id":13181195}]}]}
{"op":"mcm","clk":"1008095745","pt":1580658257033,"mc":[{"id":"1.168237986","rc":[{"batl":[[0,1.52,265.29]],"ltp":1.47,"tv":984.14,"id":14833204}]}]}
{"op":"mcm","clk":"1008103159","pt":1580658290175,"mc":[{"id":"1.168237986","rc":[{"batb":[[0,1.46,42.49],[1,1.36,56.26],[2,1.31,477.51]],"ltp":1.47,"tv":984.14,"id":14833204}]}]}
{"op":"mcm","clk":"1008103788","pt":1580658293047,"mc":[{"id":"1.168237986","rc":[{"batb":[[0,1.38,146.72],[1,1.37,258.31],[2,1.36,56.26]],"batl":[[0,1.59,181.64],[1,1.6,133.82]],"ltp":1.47,"tv":984.14,"id":14833204},{"batb":[[0,2.7,13.06],[1,2.12,388.65],[2,1.01,10.51]],"ltp":0.0,"tv":0.0,"id":13181195}]}]}
{"op":"mcm","clk":"1008104419","pt":1580658295851,"mc":[{"id":"1.168237986","rc":[{"batb":[[0,1.37,56.18],[1,1.36,56.26],[2,1.31,477.51]],"ltp":1.47,"tv":984.14,"id":14833204}]}]}
{"op":"mcm","clk":"1008104457","pt":1580658296062,"mc":[{"id":"1.168237986","rc":[{"batb":[[1,1.31,477.51],[2,1.01,10.51]],"ltp":1.47,"tv":984.14,"id":14833204}]}]}
{"op":"mcm","clk":"1008104704","pt":1580658297260,"mc":[{"id":"1.168237986","rc":[{"batb":[[1,1.01,10.51],[2,1.01,0]],"ltp":1.47,"tv":984.14,"id":14833204}]}]}
{"op":"mcm","clk":"1008105046","pt":1580658298761,"mc":[{"id":"1.168237986","rc":[{"batb":[[0,1.54,139.06],[1,1.53,160.27],[2,1.37,56.18]],"ltp":1.47,"tv":984.14,"id":14833204}]}]}
{"op":"mcm","clk":"1008105328","pt":1580658299910,"mc":[{"id":"1.168237986","rc":[{"batb":[[0,1.54,173.37],[2,1.44,44.06]],"ltp":1.47,"tv":984.14,"id":14833204},{"batb":[[1,2.48,16.21],[2,2.12,388.65]],"ltp":0.0,"tv":0.0,"id":13181195}]}]}
{"op":"mcm","clk":"1008108789","pt":1580658314845,"mc":[{"id":"1.168237986","rc":[{"batb":[[0,1.44,44.06],[1,1.34,465.43],[2,1.01,10.51]],"ltp":1.47,"tv":984.14,"id":14833204},{"batb":[[0,2.48,16.21],[1,2.12,388.65],[2,1.01,10.51]],"ltp":0.0,"tv":0.0,"id":13181195}]}]}
{"op":"mcm","clk":"1008109290","pt":1580658317241,"mc":[{"id":"1.168237986","rc":[{"batb":[[0,1.45,245.75],[1,1.44,250.82],[2,1.34,465.43]],"batl":[[0,1.66,214.11],[1,1.68,226.36]],"ltp":1.47,"tv":984.14,"id":14833204}]}]}
{"op":"mcm","clk":"1008109746","pt":1580658319256,"mc":[{"id":"1.168237986","rc":[{"batb":[[0,1.44,44.06],[1,1.34,465.43],[2,1.01,10.51]],"ltp":1.47,"tv":984.14,"id":14833204}]}]}
{"op":"mcm","clk":"1008109973","pt":1580658320339,"mc":[{"id":"1.168237986","rc":[{"batb":[[1,1.01,10.51],[2,1.01,0]],"ltp":1.47,"tv":984.14,"id":14833204},{"batb":[[1,1.01,10.51],[2,1.01,0]],"ltp":0.0,"tv":0.0,"id":13181195}]}]}
{"op":"mcm","clk":"1008110522","pt":1580658322874,"mc":[{"id":"1.168237986","rc":[{"batb":[[0,1.61,28.64],[1,1.6,146.01],[2,1.59,138.23]],"ltp":1.47,"tv":984.14,"id":14833204},{"batb":[[1,2.34,18.88],[2,1.01,10.51]],"ltp":0.0,"tv":0.0,"id":13181195}]}]}
{"op":"mcm","clk":"1008110994","pt":1580658324954,"mc":[{"id":"1.168237986","rc":[{"batb":[[2,1.92,394.91]],"ltp":0.0,"tv":0.0,"id":13181195}]}]}
{"op":"mcm","clk":"1008113218","pt":1580658334962,"mc":[{"id":"1.168237986","rc":[{"batb":[[0,1.54,34.31],[1,1.4,451],[2,1.01,10.51]],"ltp":1.47,"tv":984.14,"id":14833204},{"batb":[[0,2.34,18.88],[1,1.92,394.91],[2,1.01,10.51]],"ltp":0.0,"tv":0.0,"id":13181195}]}]}
{"op":"mcm","clk":"1008113718","pt":1580658337576,"mc":[{"id":"1.168237986","rc":[{"batb":[[1,1.53,233.33],[2,1.52,165]],"batl":[[0,1.7,114.03],[1,1.72,209.45]],"ltp":1.47,"tv":984.14,"id":14833204}]}]}
{"op":"mcm","clk":"1008113887","pt":1580658338496,"mc":[{"id":"1.168237986","rc":[{"batb":[[1,1.4,451],[2,1.01,10.51]],"ltp":1.47,"tv":984.14,"id":14833204}]}]}
{"op":"mcm","clk":"1008114118","pt":1580658339681,"mc":[{"id":"1.168237986","rc":[{"batb":[[1,1.01,10.51],[2,1.01,0]],"ltp":1.47,"tv":984.14,"id":14833204}]}]}
{"op":"mcm","clk":"1008114597","pt":1580658341975,"mc":[{"id":"1.168237986","rc":[{"batb":[[0,1.67,25.02],[1,1.64,197.21],[2,1.63,126.24]],"ltp":1.47,"tv":984.14,"id":14833204},{"batb":[[1,2.26,20.77],[2,1.92,394.91]],"ltp":0.0,"tv":0.0,"id":13181195}]}]}
{"op":"mcm","clk":"1008117212","pt":1580658355000,"mc":[{"id":"1.168237986","rc":[{"batb":[[0,1.62,28.33],[1,1.44,436.18],[2,1.01,10.51]],"ltp":1.47,"tv":984.14,"id":14833204},{"batb":[[0,2.26,20.77],[1,1.92,394.91],[2,1.01,10.51]],"ltp":0.0,"tv":0.0,"id":13181195}]}]}
{"op":"mcm","clk":"1008118490","pt":1580658360913,"mc":[{"id":"1.168237986","rc":[{"batb":[[0,1.63,227.04],[1,1.62,157.55],[2,1.44,436.18]],"batl":[[0,1.7,205.8],[1,1.72,209]],"ltp":1.47,"tv":984.14,"id":14833204}]}]}
{"op":"mcm","clk":"1008118868","pt":1580658362808,"mc":[{"id":"1.168237986","rc":[{"batb":[[0,1.62,28.33],[1,1.44,436.18],[2,1.01,10.51]],"ltp":1.47,"tv":984.14,"id":14833204}]}]}
{"op":"mcm","clk":"1008119525","pt":1580658365997,"mc":[{"id":"1.168237986","rc":[{"batb":[[1,1.6,230.3],[2,1.59,138.54]],"ltp":1.47,"tv":984.14,"id":14833204}]}]}
{"op":"mcm","clk":"1008120169","pt":1580658368995,"mc":[{"id":"1.168237986","rc":[{"batb":[[1,1.6,182.2]],"batl":[[0,1.66,134.52]],"ltp":1.47,"tv":984.14,"id":14833204}]}]}
{"op":"mcm","clk":"1008120327","pt":1580658369838,"mc":[{"id":"1.168237986","rc":[{"batb":[[0,2.48,16.37],[1,2.34,19.2],[2,1.92,394.91]],"ltp":0.0,"tv":0.0,"id":13181195}]}]}
{"op":"mcm","clk":"1008120807","pt":1580658371899,"mc":[{"id":"1.168237986","rc":[{"batl":[[0,1.66,180.92]],"ltp":1.47,"tv":984.14,"id":14833204}]}]}
{"op":"mcm","clk":"1008123105","pt":1580658382840,"mc":[{"id":"1.168237986","rc":[{"batb":[[0,1.54,33.68],[1,1.44,436.18],[2,1.01,10.51]],"ltp":1.47,"tv":984.14,"id":14833204},{"batb":[[0,2.34,19.2],[1,1.92,394.91],[2,1.01,10.51]],"ltp":0.0,"tv":0.0,"id":13181195}]}]}
{"op":"mcm","clk":"1008123696","pt":1580658385842,"mc":[{"id":"1.168237986","rc":[{"batb":[[0,1.54,202.3],[1,1.53,160.64],[2,1.44,436.18]],"batl":[[0,1.71,211.44],[1,1.73,205.21]],"ltp":1.47,"tv":984.14,"id":14833204}]}]}
{"op":"mcm","clk":"1008125472","pt":1580658394748,"mc":[{"id":"1.168237986","rc":[{"batb":[[0,1.54,33.68],[1,1.44,436.18],[2,1.01,10.51]],"ltp":1.47,"tv":984.14,"id":14833204}]}]}
{"op":"mcm","clk":"1008126044","pt":1580658397555,"mc":[{"id":"1.168237986","rc":[{"batb":[[0,1.6,182.2],[1,1.59,138.55],[2,1.54,33.68]],"batl":[[0,1.66,180.92]],"ltp":1.47,"tv":984.14,"id":14833204}]}]}
{"op":"mcm","clk":"1008129711","pt":1580658415864,"mc":[{"id":"1.168237986","rc":[{"batb":[[0,1.54,33.68],[1,1.44,436.18],[2,1.01,10.51]],"ltp":1.47,"tv":984.14,"id":14833204}]}]}
{"op":"mcm","clk":"1008130280","pt":1580658418773,"mc":[{"id":"1.168237986","rc":[{"batb":[[0,1.54,202.3],[1,1.53,160.64],[2,1.44,436.18]],"batl":[[0,1.71,211.44],[1,1.73,205.21]],"ltp":1.47,"tv":984.14,"id":14833204}]}]}
{"op":"mcm","clk":"1008131188","pt":1580658422983,"mc":[{"id":"1.168237986","rc":[{"batb":[[0,1.54,33.68],[1,1.44,436.18],[2,1.01,10.51]],"ltp":1.47,"tv":984.14,"id":14833204}]}]}
{"op":"mcm","clk":"1008131849","pt":1580658425970,"mc":[{"id":"1.168237986","rc":[{"batb":[[0,1.68,24.63],[1,1.64,206.88],[2,1.63,126.42]],"batl":[[0,1.71,211.44],[1,1.73,205.21]],"ltp":1.47,"tv":984.14,"id":14833204},{"batb":[[1,2.04,28.17],[2,1.92,394.91]],"ltp":0.0,"tv":0.0,"id":13181195}]}]}
{"op":"mcm","clk":"1008150424","pt":1580658517806,"mc":[{"id":"1.168237986","rc":[{"batb":[[0,1.55,33.2],[1,1.44,436.18],[2,1.01,10.51]],"ltp":1.47,"tv":984.14,"id":14833204},{"batb":[[0,2.04,28.17],[1,1.92,394.91],[2,1.01,10.51]],"ltp":0.0,"tv":0.0,"id":13181195}]}]}
{"op":"mcm","clk":"1008150988","pt":1580658521026,"mc":[{"id":"1.168237986","rc":[{"batb":[[1,1.53,163.37],[2,1.52,164.88]],"ltp":1.47,"tv":984.14,"id":14833204}]}]}
{"op":"mcm","clk":"1008151291","pt":1580658522523,"mc":[{"id":"1.168237986","rc":[{"batl":[[0,1.58,174.83],[1,1.59,137.18]],"ltp":1.47,"tv":984.14,"id":14833204},{"batb":[[1,1.01,10.51],[2,1.01,0]],"ltp":0.0,"tv":0.0,"id":13181195}]}]}
{"op":"mcm","clk":"1008151529","pt":1580658523595,"mc":[{"id":"1.168237986","rc":[{"batb":[[0,2.66,13.61],[1,2.3,20.06],[2,1.01,10.51]],"ltp":0.0,"tv":0.0,"id":13181195}]}]}
{"op":"mcm","clk":"1008152122","pt":1580658526509,"mc":[{"id":"1.168237986","rc":[{"batb":[[2,2.04,394.09]],"ltp":0.0,"tv":0.0,"id":13181195}]}]}
{"op":"mcm","clk":"1008153871","pt":1580658535633,"mc":[{"id":"1.168237986","rc":[{"batb":[[0,1.45,43.35],[1,1.34,465.43],[2,1.01,10.51]],"ltp":1.47,"tv":984.14,"id":14833204},{"batb":[[0,2.3,20.06],[1,2.04,394.09],[2,1.01,10.51]],"ltp":0.0,"tv":0.0,"id":13181195}]}]}
{"op":"mcm","clk":"1008154377","pt":1580658538445,"mc":[{"id":"1.168237986","rc":[{"batb":[[1,1.01,10.51],[2,1.01,0]],"ltp":1.47,"tv":984.14,"id":14833204}]}]}
{"op":"mcm","clk":"1008154854","pt":1580658540743,"mc":[{"id":"1.168237986","rc":[{"batb":[[0,1.55,249.92],[1,1.54,156.98],[2,1.45,43.35]],"batl":[[0,1.61,194.49],[1,1.62,128.1]],"ltp":1.47,"tv":984.14,"id":14833204}]}]}
{"op":"mcm","clk":"1008155901","pt":1580658546845,"mc":[{"id":"1.168237986","rc":[{"batb":[[0,1.45,43.35],[1,1.38,448.45],[2,1.01,10.51]],"ltp":1.47,"tv":984.14,"id":14833204}]}]}
{"op":"mcm","clk":"1008156424","pt":1580658549889,"mc":[{"id":"1.168237986","rc":[{"batb":[[1,1.44,274.46],[2,1.43,213.78]],"batl":[[0,1.73,136.28],[1,1.75,197.83]],"ltp":1.47,"tv":984.14,"id":14833204}]}]}
{"op":"mcm","clk":"1008157904","pt":1580658557960,"mc":[{"id":"1.168237986","rc":[{"batb":[[1,1.38,448.45],[2,1.01,10.51]],"ltp":1.47,"tv":984.14,"id":14833204}]}]}
{"op":"mcm","clk":"1008158179","pt":1580658559559,"mc":[{"id":"1.168237986","rc":[{"batb":[[1,1.01,10.51],[2,1.01,0]],"ltp":1.47,"tv":984.14,"id":14833204},{"batb":[[1,1.01,10.51],[2,1.01,0]],"ltp":0.0,"tv":0.0,"id":13181195}]}]}
{"op":"mcm","clk":"1008158420","pt":1580658560751,"mc":[{"id":"1.168237986","rc":[{"batb":[[0,1.67,138.73],[1,1.66,118.17],[2,1.45,43.35]],"batl":[[0,1.73,136.28],[1,1.75,197.83]],"ltp":1.47,"tv":984.14,"id":14833204}]}]}
{"op":"mcm","clk":"1008158526","pt":1580658561378,"mc":[{"id":"1.168237986","rc":[{"batb":[[0,1.7,23.68],[1,1.67,138.73],[2,1.66,118.17]],"ltp":1.47,"tv":984.14,"id":14833204},{"batb":[[1,1.98,15.5],[2,1.01,10.51]],"ltp":0.0,"tv":0.0,"id":13181195}]}]}
{"op":"mcm","clk":"1008158975","pt":1580658563776,"mc":[{"id":"1.168237986","rc":[{"batb":[[2,1.82,401.24]],"ltp":0.0,"tv":0.0,"id":13181195}]}]}
{"op":"mcm","clk":"1008161524","pt":1580658577800,"mc":[{"id":"1.168237986","rc":[{"batb":[[0,1.55,33.28],[1,1.46,435.7],[2,1.01,10.51]],"ltp":1.47,"tv":984.14,"id":14833204},{"batb":[[0,1.98,15.5],[1,1.82,401.24],[2,1.01,10.51]],"ltp":0.0,"tv":0.0,"id":13181195}]}]}
{"op":"mcm","clk":"1008162561","pt":1580658583391,"mc":[{"id":"1.168237986","rc":[{"batb":[[0,1.71,163.33],[1,1.69,220.52],[2,1.55,33.28]],"batl":[[0,1.78,165.3],[1,1.8,180.29]],"ltp":1.47,"tv":984.14,"id":14833204}]}]}
{"op":"mcm","clk":"1008163401","pt":1580658588223,"mc":[{"id":"1.168237986","rc":[{"batb":[[0,1.55,33.28],[1,1.46,435.7],[2,1.01,10.51]],"ltp":1.47,"tv":984.14,"id":14833204}]}]}
{"op":"mcm","clk":"1008163929","pt":1580658591209,"mc":[{"id":"1.168237986","rc":[{"batb":[[1,1.53,166.83],[2,1.52,164.9]],"batl":[[0,1.99,117.76],[1,2.02,190.38]],"ltp":1.47,"tv":984.14,"id":14833204}]}]}
{"op":"mcm","clk":"1008166337","pt":1580658605045,"mc":[{"id":"1.168237986","rc":[{"batb":[[1,1.01,10.51],[2,1.01,0]],"ltp":0.0,"tv":0.0,"id":13181195}]}]}
{"op":"mcm","clk":"1008166413","pt":1580658605426,"mc":[{"id":"1.168237986","rc":[{"batl":[[0,1.58,171.59],[1,1.59,137.2]],"ltp":1.47,"tv":984.14,"id":14833204}]}]}
{"op":"mcm","clk":"1008166621","pt":1580658606726,"mc":[{"id":"1.168237986","rc":[{"batb":[[0,2.66,13.61],[1,2.26,20.93],[2,1.01,10.51]],"ltp":0.0,"tv":0.0,"id":13181195}]}]}
{"op":"mcm","clk":"1008167052","pt":1580658609231,"mc":[{"id":"1.168237986","rc":[{"batb":[[2,2.04,394.09]],"ltp":0.0,"tv":0.0,"id":13181195}]}]}
{"op":"mcm","clk":"1008169589","pt":1580658624010,"mc":[{"id":"1.168237986","rc":[{"batb":[[0,1.43,45.24],[1,1.34,465.43],[2,1.01,10.51]],"ltp":1.47,"tv":984.14,"id":14833204},{"batb":[[0,2.26,20.93],[1,2.04,394.09],[2,1.01,10.51]],"ltp":0.0,"tv":0.0,"id":13181195}]}]}
{"op":"mcm","clk":"1008170356","pt":1580658628334,"mc":[{"id":"1.168237986","rc":[{"batb":[[1,1.01,10.51],[2,1.01,0]],"ltp":1.47,"tv":984.14,"id":14833204}]}]}
{"op":"mcm","clk":"1008170524","pt":1580658629451,"mc":[{"id":"1.168237986","rc":[{"batb":[[0,1.56,165.08],[1,1.55,152.67],[2,1.43,45.24]],"batl":[[0,1.61,129.87],[1,1.62,128.36]],"ltp":1.47,"tv":984.14,"id":14833204}]}]}
{"op":"mcm","clk":"1008171366","pt":1580658634174,"mc":[{"id":"1.168237986","rc":[{"batb":[[0,1.43,45.24],[1,1.38,448.45],[2,1.01,10.51]],"ltp":1.47,"tv":984.14,"id":14833204}]}]}
{"op":"mcm","clk":"1008171946","pt":1580658637057,"mc":[{"id":"1.168237986","rc":[{"batb":[[0,1.43,245.04],[1,1.42,219.89],[2,1.38,448.45]],"batl":[[0,1.76,154.86],[1,1.78,187]],"ltp":1.47,"tv":984.14,"id":14833204}]}]}
{"op":"mcm","clk":"1008172924","pt":1580658642472,"mc":[{"id":"1.168237986","rc":[{"batb":[[2,1.01,10.51]],"ltp":1.47,"tv":984.14,"id":14833204},{"batb":[[1,1.01,10.51],[2,1.01,0]],"ltp":0.0,"tv":0.0,"id":13181195}]}]}
{"op":"mcm","clk":"1008173186","pt":1580658643767,"mc":[{"id":"1.168237986","rc":[{"batl":[[0,1.47,155.23],[1,1.48,181.01]],"ltp":1.47,"tv":984.14,"id":14833204}]}]}
{"op":"mcm","clk":"1008173436","pt":1580658644971,"mc":[{"id":"1.168237986","rc":[{"batb":[[2,1.37,55.71]],"ltp":1.47,"tv":984.14,"id":14833204},{"batb":[[0,3.05,23.6],[1,2.72,12.83],[2,1.01,10.51]],"ltp":0.0,"tv":0.0,"id":13181195}]}]}
{"op":"mcm","clk":"1008173688","pt":1580658646499,"mc":[{"id":"1.168237986","rc":[{"batb":[[2,2.22,384.52]],"ltp":0.0,"tv":0.0,"id":13181195}]}]}
{"op":"mcm","clk":"1008176498","pt":1580658662985,"mc":[{"id":"1.168237986","rc":[{"batb":[[0,1.37,55.71],[1,1.28,485.89],[2,1.01,10.51]],"ltp":1.47,"tv":984.14,"id":14833204},{"batb":[[0,2.72,12.83],[1,2.22,384.52],[2,1.01,10.51]],"ltp":0.0,"tv":0.0,"id":13181195}]}]}
{"op":"mcm","clk":"1008176963","pt":1580658665882,"mc":[{"id":"1.168237986","rc":[{"batb":[[0,1.38,165.7],[1,1.37,314.75],[2,1.28,485.89]],"batl":[[0,1.56,171.61],[1,1.57,143.79]],"ltp":1.47,"tv":984.14,"id":14833204}]}]}
{"op":"mcm","clk":"1008177103","pt":1580658666685,"mc":[{"id":"1.168237986","rc":[{"batb":[[0,1.37,55.71],[1,1.28,485.89],[2,1.01,10.51]],"ltp":1.47,"tv":984.14,"id":14833204}]}]}
{"op":"mcm","clk":"1008177414","pt":1580658668795,"mc":[{"id":"1.168237986","rc":[{"batb":[[1,1.01,10.51],[2,1.01,0]],"ltp":1.47,"tv":984.14,"id":14833204}]}]}
{"op":"mcm","clk":"1008177614","pt":1580658670002,"mc":[{"id":"1.168237986","rc":[{"batb":[[0,1.51,201],[1,1.5,174.16],[2,1.37,55.71]],"ltp":1.47,"tv":984.14,"id":14833204}]}]}
{"op":"mcm","clk":"1008177694","pt":1580658670482,"mc":[{"id":"1.168237986","rc":[{"batb":[[0,1.53,34.86],[1,1.51,201],[2,1.5,174.16]],"ltp":1.47,"tv":984.14,"id":14833204},{"batb":[[1,2.22,406.39]],"ltp":0.0,"tv":0.0,"id":13181195}]}]}
{"op":"mcm","clk":"1008180176","pt":1580658685232,"mc":[{"id":"1.168237986","rc":[{"batb":[[0,1.4,50.44],[1,1.34,465.43],[2,1.01,10.51]],"ltp":1.47,"tv":984.14,"id":14833204},{"batb":[[0,2.22,406.39],[1,1.01,10.51],[2,1.01,0]],"ltp":0.0,"tv":0.0,"id":13181195}]}]}
{"op":"mcm","clk":"1008180762","pt":1580658688509,"mc":[{"id":"1.168237986","rc":[{"batb":[[1,1.39,354.97],[2,1.38,252.31]],"batl":[[0,1.77,115.68],[1,1.79,183.75]],"ltp":1.47,"tv":984.14,"id":14833204}]}]}
{"op":"mcm","clk":"1008182837","pt":1580658702638,"mc":[{"id":"1.168237986","rc":[{"batb":[[1,1.34,465.43],[2,1.01,10.51]],"ltp":1.47,"tv":984.14,"id":14833204}]}]}
{"op":"mcm","clk":"1008183168","pt":1580658704745,"mc":[{"id":"1.168237986","rc":[{"batb":[[1,1.01,10.51],[2,1.01,0]],"ltp":1.47,"tv":984.14,"id":14833204},{"batb":[[0,2.22,21.87]],"ltp":0.0,"tv":0.0,"id":13181195}]}]}
{"op":"mcm","clk":"1008183345","pt":1580658705963,"mc":[{"id":"1.168237986","rc":[{"batb":[[0,1.74,21.87],[1,1.71,118.27],[2,1.69,220.36]],"batl":[[0,1.77,115.68],[1,1.79,183.75]],"ltp":1.47,"tv":984.14,"id":14833204},{"batb":[[1,1.86,18.8],[2,1.01,10.51]],"ltp":0.0,"tv":0.0,"id":13181195}]}]}
{"op":"mcm","clk":"1008183716","pt":1580658708259,"mc":[{"id":"1.168237986","rc":[{"batb":[[2,1.82,401.24]],"ltp":0.0,"tv":0.0,"id":13181195}]}]}
{"op":"mcm","clk":"1008186434","pt":1580658725865,"mc":[{"id":"1.168237986","rc":[{"batb":[[1,1.54,33.83],[2,1.46,435.7]],"ltp":1.47,"tv":984.14,"id":14833204}]}]}
{"op":"mcm","clk":"1008186529","pt":1580658726450,"mc":[{"id":"1.168237986","rc":[{"batb":[[0,1.54,33.83],[1,1.46,435.7],[2,1.01,10.51]],"ltp":1.47,"tv":984.14,"id":14833204},{"batb":[[0,1.86,18.8],[1,1.82,401.24],[2,1.01,10.51]],"ltp":0.0,"tv":0.0,"id":13181195}]}]}
{"op":"mcm","clk":"1008186892","pt":1580658728904,"mc":[{"id":"1.168237986","rc":[{"batb":[[1,1.52,168.96],[2,1.51,169.35]],"batl":[[0,2.16,184.49],[1,2.18,101.35]],"ltp":1.47,"tv":984.14,"id":14833204}]}]}
{"op":"mcm","clk":"1008187110","pt":1580658730166,"mc":[{"id":"1.168237986","rc":[{"batb":[[1,1.46,435.7],[2,1.01,10.51]],"ltp":1.47,"tv":984.14,"id":14833204}]}]}
{"op":"mcm","clk":"1008187439","pt":1580658732392,"mc":[{"id":"1.168237986","rc":[{"batb":[[1,1.01,10.51],[2,1.01,0]],"ltp":1.47,"tv":984.14,"id":14833204}]}]}
{"op":"mcm","clk":"1008187711","pt":1580658733884,"mc":[{"id":"1.168237986","rc":[{"batb":[[0,1.76,199.91],[1,1.74,199.47],[2,1.54,33.83]],"batl":[[0,1.84,162.79],[1,1.86,162.42]],"ltp":1.47,"tv":984.14,"id":14833204}]}]}
{"op":"mcm","clk":"1008188387","pt":1580658738590,"mc":[{"id":"1.168237986","rc":[{"batb":[[0,1.54,33.83],[1,1.5,426.9],[2,1.01,10.51]],"ltp":1.47,"tv":984.14,"id":14833204}]}]}
{"op":"mcm","clk":"1008188814","pt":1580658741490,"mc":[{"id":"1.168237986","rc":[{"batb":[[1,1.52,168.96],[2,1.51,169.35]],"batl":[[0,2.16,184.49],[1,2.18,101.35]],"ltp":1.47,"tv":984.14,"id":14833204}]}]}
{"op":"mcm","clk":"1008189014","pt":1580658742892,"mc":[{"id":"1.168237986","rc":[{"batb":[[1,1.5,426.9],[2,1.01,10.51]],"ltp":1.47,"tv":984.14,"id":14833204}]}]}
{"op":"mcm","clk":"1008189340","pt":1580658744984,"mc":[{"id":"1.168237986","rc":[{"batb":[[1,1.01,10.51],[2,1.01,0]],"ltp":1.47,"tv":984.14,"id":14833204},{"batb":[[1,1.01,10.51],[2,1.01,0]],"ltp":0.0,"tv":0.0,"id":13181195}]}]}
{"op":"mcm","clk":"1008189478","pt":1580658745985,"mc":[{"id":"1.168237986","rc":[{"batb":[[0,2.06,25.65],[1,1.75,21.4],[2,1.01,10.51]],"ltp":1.47,"tv":984.14,"id":14833204},{"batb":[[0,1.87,149.86],[1,1.86,18.8],[2,1.85,162.41]],"batl":[[0,1.95,108.24],[1,1.97,135.85]],"ltp":0.0,"tv":0.0,"id":13181195}]}]}
{"op":"mcm","clk":"1008189921","pt":1580658748597,"mc":[{"id":"1.168237986","rc":[{"batb":[[2,1.67,409.76]],"ltp":1.47,"tv":984.14,"id":14833204}]}]}
{"op":"mcm","clk":"1008192630","pt":1580658765810,"mc":[{"id":"1.168237986","rc":[{"batb":[[0,1.75,21.4],[1,1.67,409.76],[2,1.01,10.51]],"ltp":1.47,"tv":984.14,"id":14833204},{"batb":[[0,1.58,416.47],[1,1.56,33.99],[2,1.01,10.51]],"ltp":0.0,"tv":0.0,"id":13181195}]}]}
{"op":"mcm","clk":"1008193606","pt":1580658772004,"mc":[{"id":"1.168237986","rc":[{"batb":[[0,1.79,133.9],[1,1.77,187.47],[2,1.58,416.47]],"batl":[[0,1.86,113.45],[1,1.88,156.52]],"ltp":0.0,"tv":0.0,"id":13181195}]}]}
{"op":"mcm","clk":"1008194168","pt":1580658775581,"mc":[{"id":"1.168237986","rc":[{"batl":[[1,1.87,138.63],[2,1.88,156.52]],"ltp":0.0,"tv":0.0,"id":13181195}]}]}
{"op":"mcm","clk":"1008194443","pt":1580658777509,"mc":[{"id":"1.168237986","rc":[{"batb":[[0,1.58,416.47],[1,1.56,33.99],[2,1.01,10.51]],"ltp":0.0,"tv":0.0,"id":13181195}]}]}
{"op":"mcm","clk":"1008194839","pt":1580658780006,"mc":[{"id":"1.168237986","rc":[{"batb":[[2,1.52,178.05]],"batl":[[0,2.4,129.87],[1,2.44,150.61]],"ltp":0.0,"tv":0.0,"id":13181195}]}]}
{"op":"mcm","clk":"1008195900","pt":1580658786338,"mc":[{"id":"1.168237986","rc":[{"batb":[[2,1.01,10.51]],"ltp":0.0,"tv":0.0,"id":13181195}]}]}
{"op":"mcm","clk":"1008196092","pt":1580658787635,"mc":[{"id":"1.168237986","rc":[{"batb":[[1,1.01,10.51],[2,1.01,0]],"ltp":1.47,"tv":984.14,"id":14833204},{"batb":[[0,1.56,33.99],[1,1.01,10.51],[2,1.01,0]],"ltp":0.0,"tv":0.0,"id":13181195}]}]}
{"op":"mcm","clk":"1008196505","pt":1580658790023,"mc":[{"id":"1.168237986","rc":[{"batb":[[1,1.72,120.96],[2,1.7,215.88]],"batl":[[0,1.79,194.74],[1,1.81,177.03]],"ltp":1.47,"tv":984.14,"id":14833204},{"batb":[[0,2.2,22.42],[1,1.84,19.28],[2,1.01,10.51]],"ltp":0.0,"tv":0.0,"id":13181195}]}]}
{"op":"mcm","clk":"1008196795","pt":1580658791825,"mc":[{"id":"1.168237986","rc":[{"batb":[[2,1.82,401.24]],"ltp":0.0,"tv":0.0,"id":13181195}]}]}
{"op":"mcm","clk":"1008199910","pt":1580658809975,"mc":[{"id":"1.168237986","rc":[{"batb":[[0,1.72,120.96],[1,1.7,215.88],[2,1.55,33.05]],"ltp":1.47,"tv":984.14,"id":14833204},{"batb":[[0,1.84,19.28],[1,1.82,401.24],[2,1.01,10.51]],"ltp":0.0,"tv":0.0,"id":13181195}]}]}
{"op":"mcm","clk":"1008199991","pt":1580658810453,"mc":[{"id":"1.168237986","rc":[{"batb":[[0,1.55,33.05],[1,1.46,435.7],[2,1.01,10.51]],"ltp":1.47,"tv":984.14,"id":14833204}]}]}
{"op":"mcm","clk":"1008200430","pt":1580658812999,"mc":[{"id":"1.168237986","rc":[{"batb":[[1,1.52,286.94],[2,1.51,170.01]],"batl":[[0,2.16,104.49],[1,2.18,101.26]],"ltp":1.47,"tv":984.14,"id":14833204}]}]}
{"op":"mcm","clk":"1008200900","pt":1580658815847,"mc":[{"id":"1.168237986","rc":[{"batb":[[1,1.46,435.7],[2,1.01,10.51]],"ltp":1.47,"tv":984.14,"id":14833204}]}]}
{"op":"mcm","clk":"1008201206","pt":1580658817891,"mc":[{"id":"1.168237986","rc":[{"batb":[[1,1.01,10.51],[2,1.01,0]],"ltp":1.47,"tv":984.14,"id":14833204},{"batb":[[1,1.01,10.51],[2,1.01,0]],"ltp":0.0,"tv":0.0,"id":13181195}]}]}
{"op":"mcm","clk":"1008201381","pt":1580658818954,"mc":[{"id":"1.168237986","rc":[{"batb":[[1,1.52,286.94],[2,1.51,170.01]],"batl":[[0,1.58,214.61],[1,1.59,137.03]],"ltp":1.47,"tv":984.14,"id":14833204}]}]}
{"op":"mcm","clk":"1008201540","pt":1580658819893,"mc":[{"id":"1.168237986","rc":[{"batb":[[0,2.64,13.69],[1,2.18,23.05],[2,1.01,10.51]],"ltp":0.0,"tv":0.0,"id":13181195}]}]}
{"op":"mcm","clk":"1008201752","pt":1580658821179,"mc":[{"id":"1.168237986","rc":[{"batb":[[2,2.04,394.09]],"ltp":0.0,"tv":0.0,"id":13181195}]}]}
{"op":"mcm","clk":"1008204690","pt":1580658838887,"mc":[{"id":"1.168237986","rc":[{"batb":[[0,1.41,48.86],[1,1.34,465.43],[2,1.01,10.51]],"ltp":1.47,"tv":984.14,"id":14833204},{"batb":[[0,2.18,23.05],[1,2.04,394.09],[2,1.01,10.51]],"ltp":0.0,"tv":0.0,"id":13181195}]}]}
{"op":"mcm","clk":"1008205504","pt":1580658843980,"mc":[{"id":"1.168237986","rc":[{"batb":[[0,1.56,214.75],[1,1.55,152.92],[2,1.41,48.86]],"batl":[[0,1.62,210.93],[1,1.63,125.28]],"ltp":1.47,"tv":984.14,"id":14833204}]}]}
{"op":"mcm","clk":"1008206574","pt":1580658851023,"mc":[{"id":"1.168237986","rc":[{"batb":[[0,1.41,48.86],[1,1.38,448.45],[2,1.01,10.51]],"ltp":1.47,"tv":984.14,"id":14833204}]}]}
{"op":"mcm","clk":"1008207085","pt":1580658854026,"mc":[{"id":"1.168237986","rc":[{"batb":[[1,1.4,361.08],[2,1.39,243.99]],"batl":[[0,1.8,173.46],[1,1.82,174.01]],"ltp":1.47,"tv":984.14,"id":14833204}]}]}
{"op":"mcm","clk":"1008209188","pt":1580658867341,"mc":[{"id":"1.168237986","rc":[{"batb":[[1,1.01,10.51],[2,1.01,0]],"ltp":0.0,"tv":0.0,"id":13181195}]}]}
{"op":"mcm","clk":"1008209433","pt":1580658868944,"mc":[{"id":"1.168237986","rc":[{"batl":[[0,1.45,265.81],[1,1.46,190.55],[2,1.71,617.74]],"ltp":1.47,"tv":984.14,"id":14833204}]}]}
{"op":"mcm","clk":"1008209503","pt":1580658869447,"mc":[{"id":"1.168237986","rc":[{"batl":[[2,1.71,0]],"ltp":1.47,"tv":984.14,"id":14833204},{"batb":[[0,3.15,21.4],[1,2.88,11.09],[2,1.01,10.51]],"ltp":0.0,"tv":0.0,"id":13181195}]}]}
{"op":"mcm","clk":"1008209748","pt":1580658870731,"mc":[{"id":"1.168237986","rc":[{"batb":[[2,2.3,385.09]],"ltp":0.0,"tv":0.0,"id":13181195}]}]}
{"op":"mcm","clk":"1008210011","pt":1580658872557,"mc":[{"id":"1.168237986","rc":[{"batl":[[2,1.71,757.81]],"ltp":1.47,"tv":984.14,"id":14833204}]}]}
{"op":"mcm","clk":"1008215184","pt":1580658905679,"mc":[{"id":"1.168237986","rc":[{"batb":[[1,1.32,66.56],[2,1.25,505.09]],"batl":[[0,1.71,757.81],[1,1.46,0],[2,1.71,0]],"ltp":1.47,"tv":984.14,"id":14833204}]}]}
{"op":"mcm","clk":"1008215684","pt":1580658908631,"mc":[{"id":"1.168237986","rc":[{"batb":[[1,1.32,352.91],[2,1.31,326.36]],"batl":[[0,1.51,144.45],[1,1.52,162.88],[2,1.71,757.81]],"ltp":1.47,"tv":984.14,"id":14833204}]}]}
{"op":"mcm","clk":"1008216103","pt":1580658911030,"mc":[{"id":"1.168237986","rc":[{"batl":[[2,1.71,0]],"ltp":1.47,"tv":984.14,"id":14833204}]}]}
{"op":"mcm","clk":"1008216135","pt":1580658911240,"mc":[{"id":"1.168237986","rc":[{"batb":[[0,1.32,352.91],[1,1.31,326.36],[2,1.25,505.09]],"ltp":1.47,"tv":984.14,"id":14833204},{"batb":[[0,2.88,11.09],[1,2.3,385.09],[2,1.01,10.51]],"ltp":0.0,"tv":0.0,"id":13181195}]}]}
{"op":"mcm","clk":"1008216931","pt":1580658915657,"mc":[{"id":"1.168237986","rc":[{"batb":[[0,1.32,66.56],[1,1.25,505.09],[2,1.01,10.51]],"ltp":1.47,"tv":984.14,"id":14833204}]}]}
{"op":"mcm","clk":"1008217114","pt":1580658916845,"mc":[{"id":"1.168237986","rc":[{"batb":[[1,1.01,10.51],[2,1.01,0]],"ltp":1.47,"tv":984.14,"id":14833204}]}]}
{"op":"mcm","clk":"1008217448","pt":1580658918648,"mc":[{"id":"1.168237986","rc":[{"batb":[[0,1.47,135.87],[1,1.46,194.45],[2,1.32,66.56]],"ltp":1.47,"tv":984.14,"id":14833204}]}]}
{"op":"mcm","clk":"1008217574","pt":1580658919462,"mc":[{"id":"1.168237986","rc":[{"batb":[[0,1.48,39.42],[1,1.47,135.87],[2,1.46,194.45]],"ltp":1.47,"tv":984.14,"id":14833204},{"batb":[[1,2.66,13.53],[2,2.3,385.09]],"ltp":0.0,"tv":0.0,"id":13181195}]}]}
{"op":"mcm","clk":"1008219765","pt":1580658933456,"mc":[{"id":"1.168237986","rc":[{"trd":[[1.51,22.04]],"batl":[[0,1.51,122.41]],"ltp":1.51,"tv":1006.18,"id":14833204},{"trd":[[2.96,11.24]],"ltp":2.96,"tv":11.24,"id":13181195}],"tv":1017.43}]}
{"op":"mcm","clk":"1008220241","pt":1580658936661,"mc":[{"id":"1.168237986","rc":[{"batb":[[0,1.39,51.22],[1,1.31,477.51],[2,1.01,10.51]],"ltp":1.51,"tv":1006.18,"id":14833204},{"batb":[[0,2.66,13.53],[1,2.3,385.09],[2,1.01,10.51]],"ltp":2.96,"tv":11.24,"id":13181195}]}]}
{"op":"mcm","clk":"1008220775","pt":1580658939875,"mc":[{"id":"1.168237986","rc":[{"batb":[[0,1.39,280.05],[1,1.38,250.9],[2,1.31,477.51]],"batl":[[0,1.57,168.69],[1,1.58,140.44]],"ltp":1.51,"tv":1006.18,"id":14833204}]}]}
{"op":"mcm","clk":"1008223191","pt":1580658954677,"mc":[{"id":"1.168237986","rc":[{"batb":[[0,1.39,51.22],[1,1.31,477.51],[2,1.01,10.51]],"ltp":1.51,"tv":1006.18,"id":14833204}]}]}
{"op":"mcm","clk":"1008223583","pt":1580658956879,"mc":[{"id":"1.168237986","rc":[{"batb":[[1,1.01,10.51],[2,1.01,0]],"ltp":1.51,"tv":1006.18,"id":14833204},{"batb":[[1,1.01,10.51],[2,1.01,0]],"ltp":2.96,"tv":11.24,"id":13181195}]}]}
{"op":"mcm","clk":"1008223762","pt":1580658957997,"mc":[{"id":"1.168237986","rc":[{"batb":[[0,1.55,33.36],[1,1.52,186.57],[2,1.51,169.43]],"ltp":1.51,"tv":1006.18,"id":14833204},{"batb":[[1,2.52,15.58],[2,1.01,10.51]],"ltp":2.96,"tv":11.24,"id":13181195}]}]}
{"op":"mcm","clk":"1008224172","pt":1580658960491,"mc":[{"id":"1.168237986","rc":[{"batb":[[2,2.04,394.09]],"ltp":2.96,"tv":11.24,"id":13181195}]}]}
{"op":"mcm","clk":"1008226838","pt":1580658976965,"mc":[{"id":"1.168237986","rc":[{"batb":[[1,1.47,40.29],[2,1.34,465.43]],"ltp":1.51,"tv":1006.18,"id":14833204}]}]}
{"op":"mcm","clk":"1008226871","pt":1580658977133,"mc":[{"id":"1.168237986","rc":[{"batb":[[0,1.47,40.29],[1,1.34,465.43],[2,1.01,10.51]],"ltp":1.51,"tv":1006.18,"id":14833204},{"batb":[[0,2.52,15.58],[1,2.04,394.09],[2,1.01,10.51]],"ltp":2.96,"tv":11.24,"id":13181195}]}]}
{"op":"mcm","clk":"1008227322","pt":1580658980028,"mc":[{"id":"1.168237986","rc":[{"batb":[[1,1.46,259.18],[2,1.45,201.09]],"batl":[[0,1.61,153.13],[1,1.62,128.27]],"ltp":1.51,"tv":1006.18,"id":14833204}]}]}
{"op":"mcm","clk":"1008229619","pt":1580658993764,"mc":[{"id":"1.168237986","rc":[{"batb":[[1,1.34,465.43],[2,1.01,10.51]],"ltp":1.51,"tv":1006.18,"id":14833204}]}]}
{"op":"mcm","clk":"1008229945","pt":1580658995658,"mc":[{"id":"1.168237986","rc":[{"batb":[[1,1.01,10.51],[2,1.01,0]],"ltp":1.51,"tv":1006.18,"id":14833204},{"batb":[[1,1.01,10.51],[2,1.01,0]],"ltp":2.96,"tv":11.24,"id":13181195}]}]}
{"op":"mcm","clk":"1008233249","pt":1580659015467,"mc":[{"id":"1.168237986","rc":[{"batb":[[0,1.56,140.59],[1,1.55,152.57],[2,1.47,40.29]],"batl":[[0,1.61,153.13],[1,1.62,128.27]],"ltp":1.51,"tv":1006.18,"id":14833204}]}]}
{"op":"mcm","clk":"1008233400","pt":1580659016477,"mc":[{"id":"1.168237986","rc":[{"batb":[[0,1.6,29.58],[1,1.56,140.59],[2,1.55,185.46]],"ltp":1.51,"tv":1006.18,"id":14833204},{"batb":[[1,2.44,17.15],[2,1.01,10.51]],"ltp":2.96,"tv":11.24,"id":13181195}]}]}
{"op":"mcm","clk":"1008233681","pt":1580659018282,"mc":[{"id":"1.168237986","rc":[{"batb":[[2,1.97,394.86]],"ltp":2.96,"tv":11.24,"id":13181195}]}]}
{"op":"mcm","clk":"1008234111","pt":1580659020900,"mc":[{"id":"1.168237986","rc":[{"batb":[[0,1.55,32.89],[1,1.38,448.45],[2,1.01,10.51]],"ltp":1.51,"tv":1006.18,"id":14833204},{"batb":[[0,2.44,17.15],[1,1.97,394.86],[2,1.01,10.51]],"ltp":2.96,"tv":11.24,"id":13181195}]}]}
{"op":"mcm","clk":"1008234559","pt":1580659023497,"mc":[{"id":"1.168237986","rc":[{"batb":[[1,1.52,277.86],[2,1.51,169.93]],"batl":[[0,1.63,137.63],[1,1.64,122.84]],"ltp":1.51,"tv":1006.18,"id":14833204}]}]}
{"op":"mcm","clk":"1008234964","pt":1580659025716,"mc":[{"id":"1.168237986","rc":[{"batb":[[1,1.38,448.45],[2,1.01,10.51]],"ltp":1.51,"tv":1006.18,"id":14833204}]}]}
{"op":"mcm","clk":"1008235466","pt":1580659028704,"mc":[{"id":"1.168237986","rc":[{"batb":[[0,1.58,129.58],[1,1.57,145.19],[2,1.55,32.89]],"ltp":1.51,"tv":1006.18,"id":14833204}]}]}
{"op":"mcm","clk":"1008235635","pt":1580659029721,"mc":[{"id":"1.168237986","rc":[{"trd":[[1.63,54.44]],"batb":[[2,1.49,38.24]],"batl":[[0,1.64,122.84],[1,1.64,0]],"ltp":1.63,"tv":1060.63,"id":14833204},{"batb":[[1,2.06,27.07],[2,1.97,394.86]],"ltp":2.96,"tv":11.24,"id":13181195}],"tv":1071.87}]}
{"op":"mcm","clk":"1008236135","pt":1580659032720,"mc":[{"id":"1.168237986","rc":[{"batb":[[0,1.58,152.13]],"batl":[[0,1.64,237.97],[1,1.65,119.82]],"ltp":1.63,"tv":1060.63,"id":14833204}]}]}
{"op":"mcm","clk":"1008236989","pt":1580659037602,"mc":[{"id":"1.168237986","rc":[{"batb":[[0,1.61,28.56],[1,1.58,152.13],[2,1.57,145.19]],"ltp":1.63,"tv":1060.63,"id":14833204},{"batb":[[0,2.48,16.29],[1,2.1,25.65]],"ltp":2.96,"tv":11.24,"id":13181195}]}]}
{"op":"mcm","clk":"1008255793","pt":1580659163518,"mc":[{"id":"1.168237986","rc":[{"batb":[[0,1.48,40.13],[1,1.38,448.45],[2,1.01,10.51]],"ltp":1.63,"tv":1060.63,"id":14833204},{"batb":[[0,2.1,25.65],[1,1.97,394.86],[2,1.01,10.51]],"ltp":2.96,"tv":11.24,"id":13181195}]}]}
{"op":"mcm","clk":"1008256313","pt":1580659166748,"mc":[{"id":"1.168237986","rc":[{"batb":[[0,1.47,40.21],[1,1.46,159.21],[2,1.45,200.24]],"batl":[[0,1.86,178.44],[1,1.88,157.01]],"ltp":1.63,"tv":1060.63,"id":14833204}]}]}
{"op":"mcm","clk":"1008256838","pt":1580659169974,"mc":[{"id":"1.168237986","rc":[{"batb":[[1,1.01,10.51],[2,1.01,0]],"ltp":2.96,"tv":11.24,"id":13181195}]}]}
{"op":"mcm","clk":"1008257027","pt":1580659170915,"mc":[{"id":"1.168237986","rc":[{"batl":[[0,1.5,138.24],[1,1.51,167.04]],"ltp":1.63,"tv":1060.63,"id":14833204},{"batb":[[0,2.9,10.78],[1,2.42,17.23],[2,1.01,10.51]],"ltp":2.96,"tv":11.24,"id":13181195}]}]}
{"op":"mcm","clk":"1008257328","pt":1580659172724,"mc":[{"id":"1.168237986","rc":[{"batb":[[2,2.12,388.65]],"ltp":2.96,"tv":11.24,"id":13181195}]}]}
{"op":"mcm","clk":"1008258954","pt":1580659183036,"mc":[{"id":"1.168237986","rc":[{"batb":[[0,1.37,54.53],[1,1.31,477.51],[2,1.01,10.51]],"ltp":1.63,"tv":1060.63,"id":14833204},{"batb":[[0,2.42,17.23],[1,2.12,388.65],[2,1.01,10.51]],"ltp":2.96,"tv":11.24,"id":13181195}]}]}
{"op":"mcm","clk":"1008259366","pt":1580659185639,"mc":[{"id":"1.168237986","rc":[{"batb":[[0,1.37,277.96],[1,1.36,268.82],[2,1.31,477.51]],"batl":[[0,1.66,155.22],[1,1.67,115.16]],"ltp":1.63,"tv":1060.63,"id":14833204}]}]}
{"op":"mcm","clk":"1008259619","pt":1580659187150,"mc":[{"id":"1.168237986","rc":[{"batb":[[0,1.37,54.53],[1,1.31,477.51],[2,1.01,10.51]],"ltp":1.63,"tv":1060.63,"id":14833204}]}]}
{"op":"mcm","clk":"1008260206","pt":1580659190625,"mc":[{"id":"1.168237986","rc":[{"batb":[[0,1.48,283.36],[1,1.47,189.76],[2,1.37,54.53]],"batl":[[0,1.53,147.82],[1,1.54,154.68]],"ltp":1.63,"tv":1060.63,"id":14833204}]}]}
{"op":"mcm","clk":"1008260872","pt":1580659194918,"mc":[{"id":"1.168237986","rc":[{"batb":[[0,1.37,54.53],[1,1.31,477.51],[2,1.01,10.51]],"ltp":1.63,"tv":1060.63,"id":14833204}]}]}
{"op":"mcm","clk":"1008261337","pt":1580659197946,"mc":[{"id":"1.168237986","rc":[{"batb":[[0,1.37,281.67],[1,1.36,268.83],[2,1.31,477.51]],"batl":[[0,1.66,152.19],[1,1.67,115.16]],"ltp":1.63,"tv":1060.63,"id":14833204}]}]}
{"op":"mcm","clk":"1008262190","pt":1580659202450,"mc":[{"id":"1.168237986","rc":[{"batb":[[2,1.01,10.51]],"ltp":1.63,"tv":1060.63,"id":14833204},{"batb":[[1,1.01,10.51],[2,1.01,0]],"ltp":2.96,"tv":11.24,"id":13181195}]}]}
{"op":"mcm","clk":"1008262568","pt":1580659204040,"mc":[{"id":"1.168237986","rc":[{"batl":[[0,1.41,268.27],[1,1.42,214.1]],"ltp":1.63,"tv":1060.63,"id":14833204}]}]}
{"op":"mcm","clk":"1008262629","pt":1580659204325,"mc":[{"id":"1.168237986","rc":[{"batb":[[2,1.31,69.48]],"ltp":1.63,"tv":1060.63,"id":14833204},{"batb":[[0,3.35,18.57],[1,2.9,10.78],[2,1.01,10.51]],"ltp":2.96,"tv":11.24,"id":13181195}]}]}
{"op":"mcm","clk":"1008262963","pt":1580659205972,"mc":[{"id":"1.168237986","rc":[{"batb":[[2,2.38,382.3]],"ltp":2.96,"tv":11.24,"id":13181195}]}]}
{"op":"mcm","clk":"1008265558","pt":1580659219040,"mc":[{"id":"1.168237986","rc":[{"batb":[[0,1.37,241.95]],"ltp":1.63,"tv":1060.63,"id":14833204}]}]}
{"op":"mcm","clk":"1008265989","pt":1580659220970,"mc":[{"id":"1.168237986","rc":[{"batb":[[0,1.31,69.48],[1,1.23,516.48],[2,1.01,10.51]],"ltp":1.63,"tv":1060.63,"id":14833204},{"batb":[[0,2.9,10.78],[1,2.38,382.3],[2,1.01,10.51]],"ltp":2.96,"tv":11.24,"id":13181195}]}]}
{"op":"mcm","clk":"1008266172","pt":1580659222036,"mc":[{"id":"1.168237986","rc":[{"batl":[[0,1.41,38.7]],"ltp":1.63,"tv":1060.63,"id":14833204}]}]}
{"op":"mcm","clk":"1008266518","pt":1580659223867,"mc":[{"id":"1.168237986","rc":[{"batb":[[0,1.31,371.03],[1,1.3,411.97],[2,1.23,516.48]],"batl":[[0,1.5,190.89],[1,1.51,166.98]],"ltp":1.63,"tv":1060.63,"id":14833204},{"batb":[[0,2.92,10.62]],"ltp":2.96,"tv":11.24,"id":13181195}]}]}
{"op":"mcm","clk":"1008267783","pt":1580659230900,"mc":[{"id":"1.168237986","rc":[{"batb":[[0,1.3,70.26],[1,1.23,516.48],[2,1.01,10.51]],"ltp":1.63,"tv":1060.63,"id":14833204}]}]}
{"op":"mcm","clk":"1008268140","pt":1580659232580,"mc":[{"id":"1.168237986","rc":[{"batb":[[1,1.01,10.51],[2,1.01,0]],"ltp":1.63,"tv":1060.63,"id":14833204}]}]}
{"op":"mcm","clk":"1008268376","pt":1580659233975,"mc":[{"id":"1.168237986","rc":[{"batb":[[0,1.45,283.91],[1,1.44,207.85],[2,1.3,70.26]],"ltp":1.63,"tv":1060.63,"id":14833204}]}]}
{"op":"mcm","clk":"1008268546","pt":1580659234979,"mc":[{"id":"1.168237986","rc":[{"batb":[[0,1.47,40.76],[1,1.45,283.91],[2,1.44,207.85]],"ltp":1.63,"tv":1060.63,"id":14833204},{"batb":[[1,2.38,400.55]],"ltp":2.96,"tv":11.24,"id":13181195}]}]}
{"op":"mcm","clk":"1008272630","pt":1580659258229,"mc":[{"id":"1.168237986","rc":[{"batb":[[1,1.45,325.86]],"ltp":1.63,"tv":1060.63,"id":14833204}]}]}
{"op":"mcm","clk":"1008274052","pt":1580659266961,"mc":[{"id":"1.168237986","rc":[{"batb":[[0,1.35,58.22],[1,1.31,477.51],[2,1.01,10.51]],"ltp":1.63,"tv":1060.63,"id":14833204},{"batb":[[0,2.38,400.55],[1,1.01,10.51],[2,1.01,0]],"ltp":2.96,"tv":11.24,"id":13181195}]}]}
{"op":"mcm","clk":"1008274526","pt":1580659269833,"mc":[{"id":"1.168237986","rc":[{"batb":[[0,1.35,392.98],[1,1.34,291.06],[2,1.31,477.51]],"ltp":1.63,"tv":1060.63,"id":14833204}]}]}
{"op":"mcm","clk":"1008274877","pt":1580659271853,"mc":[{"id":"1.168237986","rc":[{"batb":[[2,1.01,10.51]],"ltp":1.63,"tv":1060.63,"id":14833204}]}]}
{"op":"mcm","clk":"1008275017","pt":1580659272653,"mc":[{"id":"1.168237986","rc":[{"batl":[[0,1.39,228.03],[1,1.4,228.69]],"ltp":1.63,"tv":1060.63,"id":14833204}]}]}
{"op":"mcm","clk":"1008275250","pt":1580659273950,"mc":[{"id":"1.168237986","rc":[{"batb":[[2,1.29,74.28]],"ltp":1.63,"tv":1060.63,"id":14833204},{"batb":[[0,3.5,17],[1,2.98,25.41],[2,2.38,382.3]],"ltp":2.96,"tv":11.24,"id":13181195}]}]}
{"op":"mcm","clk":"1008277745","pt":1580659287831,"mc":[{"id":"1.168237986","rc":[{"batb":[[0,1.29,74.28],[1,1.23,516.48],[2,1.01,10.51]],"ltp":1.63,"tv":1060.63,"id":14833204},{"batb":[[0,2.98,25.41],[1,2.38,382.3],[2,1.01,10.51]],"ltp":2.96,"tv":11.24,"id":13181195}]}]}
{"op":"mcm","clk":"1008278290","pt":1580659291028,"mc":[{"id":"1.168237986","rc":[{"batb":[[0,1.3,331.5],[1,1.29,429.89],[2,1.23,516.48]],"batl":[[0,1.48,240.37],[1,1.49,175.65]],"ltp":1.63,"tv":1060.63,"id":14833204}]}]}
{"op":"mcm","clk":"1008279842","pt":1580659299038,"mc":[{"id":"1.168237986","rc":[{"batb":[[2,1.01,10.51]],"ltp":1.63,"tv":1060.63,"id":14833204},{"batb":[[1,1.01,10.51],[2,1.01,0]],"ltp":2.96,"tv":11.24,"id":13181195}]}]}
{"op":"mcm","clk":"1008280029","pt":1580659299943,"mc":[{"id":"1.168237986","rc":[{"batb":[[2,1.22,102.52]],"batl":[[0,1.34,412.33],[1,1.35,268.14]],"ltp":1.63,"tv":1060.63,"id":14833204},{"batb":[[0,3.95,24.63],[1,3.55,15.97],[2,2.98,25.41]],"ltp":2.96,"tv":11.24,"id":13181195}]}]}
{"op":"mcm","clk":"1008280160","pt":1580659300647,"mc":[{"id":"1.168237986","rc":[{"batb":[[2,1.01,10.51]],"ltp":2.96,"tv":11.24,"id":13181195}]}]}
{"op":"mcm","clk":"1008280642","pt":1580659302910,"mc":[{"id":"1.168237986","rc":[{"batb":[[2,2.52,381.46]],"ltp":2.96,"tv":11.24,"id":13181195}]}]}
{"op":"mcm","clk":"1008287095","pt":1580659336649,"mc":[{"id":"1.168237986","rc":[{"batb":[[0,1.29,74.28],[1,1.22,102.52],[2,1.2,530.86]],"ltp":1.63,"tv":1060.63,"id":14833204}]}]}
{"op":"mcm","clk":"1008287571","pt":1580659338905,"mc":[{"id":"1.168237986","rc":[{"batb":[[0,1.22,101.66],[1,1.2,530.86],[2,1.01,10.51]],"ltp":1.63,"tv":1060.63,"id":14833204},{"batb":[[0,3.55,15.97],[1,2.52,381.46],[2,1.01,10.51]],"ltp":2.96,"tv":11.24,"id":13181195}]}]}
{"op":"mcm","clk":"1008287733","pt":1580659339950,"mc":[{"id":"1.168237986","rc":[{"batb":[[0,1.23,532.34],[1,1.22,605.28],[2,1.2,530.86]],"batl":[[0,1.38,157.65],[1,1.39,237]],"ltp":1.63,"tv":1060.63,"id":14833204}]}]}
{"op":"mcm","clk":"1008287838","pt":1580659340439,"mc":[{"id":"1.168237986","rc":[{"batb":[[0,1.22,101.66],[1,1.2,530.86],[2,1.01,10.51]],"ltp":1.63,"tv":1060.63,"id":14833204}]}]}
{"op":"mcm","clk":"1008288582","pt":1580659344817,"mc":[{"id":"1.168237986","rc":[{"batb":[[0,1.29,195.97],[1,1.28,368.91],[2,1.22,101.66]],"batl":[[0,1.32,290.76],[1,1.33,290.37]],"ltp":1.63,"tv":1060.63,"id":14833204}]}]}
{"op":"mcm","clk":"1008288958","pt":1580659347014,"mc":[{"id":"1.168237986","rc":[{"batb":[[0,1.22,101.66],[1,1.2,530.86],[2,1.01,10.51]],"ltp":1.63,"tv":1060.63,"id":14833204}]}]}
{"op":"mcm","clk":"1008289394","pt":1580659349856,"mc":[{"id":"1.168237986","rc":[{"batb":[[0,1.23,553.44],[1,1.22,594.26],[2,1.2,530.86]],"batl":[[0,1.39,375.26],[1,1.4,226.84]],"ltp":1.63,"tv":1060.63,"id":14833204}]}]}
{"op":"mcm","clk":"1008290603","pt":1580659356644,"mc":[{"id":"1.168237986","rc":[{"batb":[[2,1.01,10.51]],"ltp":1.63,"tv":1060.63,"id":14833204},{"batb":[[1,1.01,10.51],[2,1.01,0]],"ltp":2.96,"tv":11.24,"id":13181195}]}]}
{"op":"mcm","clk":"1008290885","pt":1580659358029,"mc":[{"id":"1.168237986","rc":[{"batl":[[0,1.26,228.75],[1,1.27,372.03]],"ltp":1.63,"tv":1060.63,"id":14833204}]}]}
{"op":"mcm","clk":"1008291026","pt":1580659358835,"mc":[{"id":"1.168237986","rc":[{"batb":[[2,1.14,161.93]],"ltp":1.63,"tv":1060.63,"id":14833204},{"batb":[[0,4.8,15.58],[1,4.1,22.9],[2,1.01,10.51]],"ltp":2.96,"tv":11.24,"id":13181195}]}]}
{"op":"mcm","clk":"1008291344","pt":1580659360661,"mc":[{"id":"1.168237986","rc":[{"batb":[[2,1.14,789.85]],"ltp":1.63,"tv":1060.63,"id":14833204},{"batb":[[2,2.8,375.33]],"ltp":2.96,"tv":11.24,"id":13181195}]}]}
{"op":"mcm","clk":"1008295018","pt":1580659379974,"mc":[{"id":"1.168237986","rc":[{"batb":[[0,1.22,101.66],[1,1.14,789.85],[2,1.01,10.51]],"ltp":1.63,"tv":1060.63,"id":14833204}]}]}
{"op":"mcm","clk":"1008295203","pt":1580659380885,"mc":[{"id":"1.168237986","rc":[{"batb":[[0,1.14,789.85],[1,1.01,10.51],[2,1.01,0]],"ltp":1.63,"tv":1060.63,"id":14833204},{"batb":[[0,4.1,22.9],[1,2.8,375.33],[2,1.01,10.51]],"ltp":2.96,"tv":11.24,"id":13181195}]}]}
{"op":"mcm","clk":"1008295608","pt":1580659382944,"mc":[{"id":"1.168237986","rc":[{"batb":[[0,1.16,232.14],[1,1.15,773.79],[2,1.14,789.85]],"batl":[[0,1.32,236.75],[1,1.33,290.92]],"ltp":1.63,"tv":1060.63,"id":14833204}]}]}
{"op":"mcm","clk":"1008295778","pt":1580659383868,"mc":[{"id":"1.168237986","rc":[{"batb":[[1,1.15,934.46],[2,1.14,627.92]],"ltp":1.63,"tv":1060.63,"id":14833204}]}]}
{"op":"mcm","clk":"1008299290","pt":1580659402016,"mc":[{"id":"1.168237986","rc":[{"batb":[[2,1.08,294.03]],"batl":[[0,1.18,517.53],[1,1.19,552.6]],"ltp":1.63,"tv":1060.63,"id":14833204},{"batb":[[0,6.4,15.74],[1,5.2,13.06],[2,4.1,22.9]],"ltp":2.96,"tv":11.24,"id":13181195}]}]}
{"op":"mcm","clk":"1008299426","pt":1580659402792,"mc":[{"id":"1.168237986","rc":[{"batb":[[1,1.15,934.07]],"ltp":1.63,"tv":1060.63,"id":14833204},{"batb":[[2,1.01,10.51]],"ltp":2.96,"tv":11.24,"id":13181195}]}]}
{"op":"mcm","clk":"1008299812","pt":1580659404925,"mc":[{"id":"1.168237986","rc":[{"batb":[[2,1.09,779.05]],"ltp":1.63,"tv":1060.63,"id":14833204},{"batb":[[2,3.15,373.59]],"ltp":2.96,"tv":11.24,"id":13181195}]}]}
{"op":"mcm","clk":"1008303438","pt":1580659423496,"mc":[{"id":"1.168237986","rc":[{"batb":[[0,1.09,779.05],[1,1.08,294.03],[2,1.01,10.51]],"ltp":1.63,"tv":1060.63,"id":14833204},{"batb":[[0,5.2,13.06],[1,3.15,373.59],[2,1.01,10.51]],"ltp":2.96,"tv":11.24,"id":13181195}]}]}
{"op":"mcm","clk":"1008303610","pt":1580659424239,"mc":[{"id":"1.168237986","rc":[{"batb":[[0,1.08,294.03],[1,1.01,10.51],[2,1.01,0]],"ltp":1.63,"tv":1060.63,"id":14833204},{"batb":[[1,1.01,10.51],[2,1.01,0]],"ltp":2.96,"tv":11.24,"id":13181195}]}]}
{"op":"mcm","clk":"1008304670","pt":1580659429756,"mc":[{"id":"1.168237986","rc":[{"batb":[[0,1.14,650.59],[1,1.13,477.91],[2,1.08,294.03]],"batl":[[0,1.16,324.33],[1,1.17,635.86]],"ltp":1.63,"tv":1060.63,"id":14833204}]}]}
{"op":"mcm","clk":"1008304786","pt":1580659430413,"mc":[{"id":"1.168237986","rc":[{"batb":[[2,1.08,1118.71]],"ltp":1.63,"tv":1060.63,"id":14833204},{"batb":[[1,3.25,373.26],[2,1.01,10.51]],"ltp":2.96,"tv":11.24,"id":13181195}]}]}
{"op":"mcm","clk":"1008305848","pt":1580659435995,"mc":[{"id":"1.168237986","rc":[{"batb":[[0,1.08,1118.71],[1,1.01,10.51],[2,1.08,0]],"ltp":1.63,"tv":1060.63,"id":14833204}]}]}
{"op":"mcm","clk":"1008306084","pt":1580659437431,"mc":[{"id":"1.168237986","rc":[{"batb":[[0,1.08,294.03]],"ltp":1.63,"tv":1060.63,"id":14833204},{"batb":[[1,1.01,10.51],[2,1.01,0]],"ltp":2.96,"tv":11.24,"id":13181195}]}]}
{"op":"mcm","clk":"1008306416","pt":1580659439375,"mc":[{"id":"1.168237986","rc":[{"batb":[[0,1.08,1480.8]],"batl":[[0,1.24,571.51],[1,1.25,399.53]],"ltp":1.63,"tv":1060.63,"id":14833204}]}]}
{"op":"mcm","clk":"1008307373","pt":1580659444872,"mc":[{"id":"1.168237986","rc":[{"batb":[[0,1.08,294.03]],"ltp":1.63,"tv":1060.63,"id":14833204}]}]}
{"op":"mcm","clk":"1008307940","pt":1580659447853,"mc":[{"id":"1.168237986","rc":[{"batb":[[0,1.21,309.57],[1,1.2,556.64],[2,1.08,294.03]],"ltp":1.63,"tv":1060.63,"id":14833204}]}]}
{"op":"mcm","clk":"1008308149","pt":1580659448935,"mc":[{"id":"1.168237986","rc":[{"batb":[[1,1.2,671.28],[2,1.11,214.72]],"ltp":1.63,"tv":1060.63,"id":14833204},{"batb":[[1,4.2,21.64],[2,1.01,10.51]],"ltp":2.96,"tv":11.24,"id":13181195}]}]}
{"op":"mcm","clk":"1008308274","pt":1580659449537,"mc":[{"id":"1.168237986","rc":[{"batb":[[2,1.13,629.97]],"ltp":1.63,"tv":1060.63,"id":14833204},{"batb":[[2,2.9,375.84]],"ltp":2.96,"tv":11.24,"id":13181195}]}]}
{"op":"mcm","clk":"1008314422","pt":1580659482937,"mc":[{"id":"1.168237986","rc":[{"batb":[[1,1.2,556.64]],"ltp":1.63,"tv":1060.63,"id":14833204},{"batb":[[0,4.2,21.64],[1,2.9,375.84],[2,1.01,10.51]],"ltp":2.96,"tv":11.24,"id":13181195}]}]}
{"op":"mcm","clk":"1008314844","pt":1580659484941,"mc":[{"id":"1.168237986","rc":[{"batb":[[0,1.13,629.97],[1,1.11,214.72],[2,1.01,10.51]],"ltp":1.63,"tv":1060.63,"id":14833204}]}]}
{"op":"mcm","clk":"1008315555","pt":1580659488823,"mc":[{"id":"1.168237986","rc":[{"batb":[[0,1.15,2094.43],[1,1.13,629.97],[2,1.12,222.85]],"batl":[[0,1.31,363.07],[1,1.32,300.08]],"ltp":1.63,"tv":1060.63,"id":14833204},{"batb":[[0,4.3,487.38],[1,4.2,21.64],[2,2.9,375.84]],"ltp":2.96,"tv":11.24,"id":13181195}]}]}
{"op":"mcm","clk":"1008316551","pt":1580659493552,"mc":[{"id":"1.168237986","rc":[{"batb":[[0,1.13,629.97],[1,1.12,222.85],[2,1.11,1144.56]],"ltp":1.63,"tv":1060.63,"id":14833204},{"batb":[[0,4.2,21.64],[1,2.9,375.84],[2,1.01,10.51]],"ltp":2.96,"tv":11.24,"id":13181195}]}]}
{"op":"mcm","clk":"1008322355","pt":1580659522881,"mc":[{"id":"1.168237986","rc":[{"batb":[[1,1.11,214.72],[2,1.01,10.51]],"ltp":1.63,"tv":1060.63,"id":14833204}]}]}
{"op":"mcm","clk":"1008322617","pt":1580659524399,"mc":[{"id":"1.168237986","rc":[{"batb":[[0,1.11,214.72],[1,1.01,10.51],[2,1.01,0]],"ltp":1.63,"tv":1060.63,"id":14833204}]}]}
{"op":"mcm","clk":"1008322907","pt":1580659526002,"mc":[{"id":"1.168237986","rc":[{"batb":[[0,1.28,155.49],[1,1.27,465.94],[2,1.16,143.36]],"batl":[[0,1.31,363.07],[1,1.32,300.08]],"ltp":1.63,"tv":1060.63,"id":14833204},{"batb":[[1,3.5,16.52],[2,2.9,375.84]],"ltp":2.96,"tv":11.24,"id":13181195}]}]}
{"op":"mcm","clk":"1008323484","pt":1580659528732,"mc":[{"id":"1.168237986","rc":[{"batb":[[2,1.18,549.72]],"ltp":1.63,"tv":1060.63,"id":14833204}]}]}
{"op":"mcm","clk":"1008327296","pt":1580659548044,"mc":[{"id":"1.168237986","rc":[{"batb":[[0,1.18,549.72],[1,1.16,142.65],[2,1.01,10.51]],"ltp":1.63,"tv":1060.63,"id":14833204},{"batb":[[0,3.5,16.52],[1,2.9,375.84],[2,1.01,10.51]],"ltp":2.96,"tv":11.24,"id":13181195}]}]}
{"op":"mcm","clk":"1008327893","pt":1580659550865,"mc":[{"id":"1.168237986","rc":[{"batb":[[1,1.17,529.16],[2,1.16,713.85]],"batl":[[0,1.39,257.04],[1,1.4,228.11]],"ltp":1.63,"tv":1060.63,"id":14833204}]}]}
{"op":"mcm","clk":"1008328469","pt":1580659553663,"mc":[{"id":"1.168237986","rc":[{"batb":[[0,1.17,529.16],[1,1.16,713.85],[2,1.01,10.51]],"ltp":1.63,"tv":1060.63,"id":14833204}]}]}
{"op":"mcm","clk":"1008328671","pt":1580659554806,"mc":[{"id":"1.168237986","rc":[{"batl":[[0,1.19,172.28],[1,1.2,532.56]],"ltp":1.63,"tv":1060.63,"id":14833204}]}]}
{"op":"mcm","clk":"1008328881","pt":1580659555860,"mc":[{"id":"1.168237986","rc":[{"batb":[[2,1.04,510.57]],"ltp":1.63,"tv":1060.63,"id":14833204},{"batb":[[0,5.9,18.96],[1,4.2,21.09],[2,2.9,375.84]],"ltp":2.96,"tv":11.24,"id":13181195}]}]}
{"op":"mcm","clk":"1008329323","pt":1580659557948,"mc":[{"id":"1.168237986","rc":[{"batb":[[2,1.11,684.32]],"ltp":1.63,"tv":1060.63,"id":14833204}]}]}
{"op":"mcm","clk":"1008331381","pt":1580659567986,"mc":[{"id":"1.168237986","rc":[{"batb":[[0,1.11,684.32],[1,1.04,510.57],[2,1.01,10.51]],"ltp":1.63,"tv":1060.63,"id":14833204},{"batb":[[0,4.2,21.09],[1,2.9,375.84],[2,1.01,10.51]],"ltp":2.96,"tv":11.24,"id":13181195}]}]}
{"op":"mcm","clk":"1008331570","pt":1580659568881,"mc":[{"id":"1.168237986","rc":[{"batb":[[0,1.04,510.57],[1,1.01,10.51],[2,1.01,0]],"ltp":1.63,"tv":1060.63,"id":14833204},{"batb":[[1,1.01,10.51],[2,1.01,0]],"ltp":2.96,"tv":11.24,"id":13181195}]}]}
{"op":"mcm","clk":"1008332559","pt":1580659573682,"mc":[{"id":"1.168237986","rc":[{"batb":[[0,1.14,752.89],[1,1.13,374.7],[2,1.04,510.57]],"batl":[[0,1.16,233.02],[1,1.17,639.68]],"ltp":1.63,"tv":1060.63,"id":14833204}]}]}
{"op":"mcm","clk":"1008332843","pt":1580659575094,"mc":[{"id":"1.168237986","rc":[{"batb":[[2,1.08,824.68]],"ltp":1.63,"tv":1060.63,"id":14833204},{"batb":[[1,3.25,373.26],[2,1.01,10.51]],"ltp":2.96,"tv":11.24,"id":13181195}]}]}
{"op":"mcm","clk":"1008333614","pt":1580659578929,"mc":[{"id":"1.168237986","rc":[{"batb":[[0,1.08,824.68],[1,1.04,510.57],[2,1.01,10.51]],"ltp":1.63,"tv":1060.63,"id":14833204}]}]}
{"op":"mcm","clk":"1008334052","pt":1580659581001,"mc":[{"id":"1.168237986","rc":[{"batb":[[0,1.04,510.57],[1,1.01,10.51],[2,1.01,0]],"ltp":1.63,"tv":1060.63,"id":14833204},{"batb":[[1,1.01,10.51],[2,1.01,0]],"ltp":2.96,"tv":11.24,"id":13181195}]}]}
{"op":"mcm","clk":"1008334486","pt":1580659583021,"mc":[{"id":"1.168237986","rc":[{"batb":[[0,1.04,1742.99]],"batl":[[0,1.3,150.12],[1,1.31,315.73]],"ltp":1.63,"tv":1060.63,"id":14833204}]}]}
{"op":"mcm","clk":"1008334789","pt":1580659584651,"mc":[{"id":"1.168237986","rc":[{"batb":[[0,1.04,510.57]],"ltp":1.63,"tv":1060.63,"id":14833204}]}]}
{"op":"mcm","clk":"1008335448","pt":1580659587827,"mc":[{"id":"1.168237986","rc":[{"batb":[[0,1.27,428.28],[1,1.26,408.52],[2,1.04,510.57]],"ltp":1.63,"tv":1060.63,"id":14833204}]}]}
{"op":"mcm","clk":"1008335679","pt":1580659588923,"mc":[{"id":"1.168237986","rc":[{"batb":[[1,1.26,491.37],[2,1.16,147.29]],"ltp":1.63,"tv":1060.63,"id":14833204},{"batb":[[1,3.55,16.05],[2,1.01,10.51]],"ltp":2.96,"tv":11.24,"id":13181195}]}]}
{"op":"mcm","clk":"1008335912","pt":1580659590062,"mc":[{"id":"1.168237986","rc":[{"batb":[[2,1.18,549.72]],"ltp":1.63,"tv":1060.63,"id":14833204},{"batb":[[2,2.62,379.26]],"ltp":2.96,"tv":11.24,"id":13181195}]}]}
{"op":"mcm","clk":"1008336641","pt":1580659593552,"mc":[{"id":"1.168237986","rc":[{"batb":[[0,1.27,1958.52]],"ltp":1.63,"tv":1060.63,"id":14833204}]}]}
{"op":"mcm","clk":"1008339124","pt":1580659605720,"mc":[{"id":"1.168237986","rc":[{"trd":[[1.27,15.74]],"batb":[[0,1.27,1950.65]],"ltp":1.27,"tv":1076.37,"id":14833204}],"tv":1087.61}]}
{"op":"mcm","clk":"1008339603","pt":1580659607856,"mc":[{"id":"1.168237986","rc":[{"batb":[[0,1.18,549.72],[1,1.16,147.29],[2,1.01,10.51]],"ltp":1.27,"tv":1076.37,"id":14833204},{"batb":[[0,3.55,16.05],[1,2.62,379.26],[2,1.01,10.51]],"ltp":2.96,"tv":11.24,"id":13181195}]}]}
{"op":"mcm","clk":"1008340158","pt":1580659610553,"mc":[{"id":"1.168237986","rc":[{"batb":[[1,1.17,387],[2,1.16,861.88]],"batl":[[0,1.39,335.92],[1,1.4,227.26]],"ltp":1.27,"tv":1076.37,"id":14833204}]}]}
{"op":"mcm","clk":"1008340466","pt":1580659611950,"mc":[{"id":"1.168237986","rc":[{"batb":[[1,1.16,147.29],[2,1.01,10.51]],"ltp":1.27,"tv":1076.37,"id":14833204}]}]}
{"op":"mcm","clk":"1008341105","pt":1580659614963,"mc":[{"id":"1.168237986","rc":[{"batb":[[0,1.25,358.28],[1,1.24,448.81],[2,1.18,549.72]],"batl":[[0,1.28,302.7],[1,1.29,339.72]],"ltp":1.27,"tv":1076.37,"id":14833204}]}]}
{"op":"mcm","clk":"1008341266","pt":1580659615671,"mc":[{"id":"1.168237986","rc":[{"batl":[[0,1.28,177.8]],"ltp":1.27,"tv":1076.37,"id":14833204}]}]}
{"op":"mcm","clk":"1008341882","pt":1580659618564,"mc":[{"id":"1.168237986","rc":[{"batb":[[0,1.25,486.74]],"ltp":1.27,"tv":1076.37,"id":14833204}]}]}
{"op":"mcm","clk":"1008342176","pt":1580659619876,"mc":[{"id":"1.168237986","rc":[{"batb":[[0,1.18,549.72],[1,1.16,147.29],[2,1.01,10.51]],"ltp":1.27,"tv":1076.37,"id":14833204}]}]}
{"op":"mcm","clk":"1008342718","pt":1580659622441,"mc":[{"id":"1.168237986","rc":[{"batb":[[1,1.17,553.26],[2,1.16,694.18]],"batl":[[0,1.39,198.41],[1,1.4,227.11]],"ltp":1.27,"tv":1076.37,"id":14833204}]}]}
{"op":"mcm","clk":"1008344609","pt":1580659631003,"mc":[{"id":"1.168237986","rc":[{"batb":[[1,1.16,147.29],[2,1.01,10.51]],"ltp":1.27,"tv":1076.37,"id":14833204}]}]}
{"op":"mcm","clk":"1008345271","pt":1580659633874,"mc":[{"id":"1.168237986","rc":[{"batb":[[0,1.35,359.45],[1,1.34,289.11],[2,1.16,147.29]],"ltp":1.27,"tv":1076.37,"id":14833204}]}]}
{"op":"mcm","clk":"1008345512","pt":1580659635025,"mc":[{"id":"1.168237986","rc":[{"batb":[[1,1.34,349.77],[2,1.26,85.92]],"ltp":1.27,"tv":1076.37,"id":14833204},{"batb":[[1,3.15,21.72],[2,2.62,379.26]],"ltp":2.96,"tv":11.24,"id":13181195}]}]}
{"op":"mcm","clk":"1008350295","pt":1580659657845,"mc":[{"id":"1.168237986","rc":[{"batb":[[0,1.26,85.92],[1,1.22,523],[2,1.01,10.51]],"ltp":1.27,"tv":1076.37,"id":14833204},{"batb":[[0,3.15,21.72],[1,2.62,379.26],[2,1.01,10.51]],"ltp":2.96,"tv":11.24,"id":13181195}]}]}
{"op":"mcm","clk":"1008351018","pt":1580659660962,"mc":[{"id":"1.168237986","rc":[{"batb":[[0,1.27,457.05],[1,1.26,492.11],[2,1.22,523]],"batl":[[0,1.45,222.37],[1,1.46,189.48]],"ltp":1.27,"tv":1076.37,"id":14833204}]}]}
{"op":"mcm","clk":"1008351254","pt":1580659662036,"mc":[{"id":"1.168237986","rc":[{"batb":[[0,1.26,85.92],[1,1.22,523],[2,1.01,10.51]],"ltp":1.27,"tv":1076.37,"id":14833204}]}]}
{"op":"mcm","clk":"1008351618","pt":1580659663613,"mc":[{"id":"1.168237986","rc":[{"batb":[[1,1.01,10.51],[2,1.01,0]],"ltp":1.27,"tv":1076.37,"id":14833204}]}]}
{"op":"mcm","clk":"1008351852","pt":1580659664643,"mc":[{"id":"1.168237986","rc":[{"batb":[[0,1.41,166.35],[1,1.4,232.51],[2,1.26,85.92]],"ltp":1.27,"tv":1076.37,"id":14833204}]}]}
{"op":"mcm","clk":"1008352051","pt":1580659665552,"mc":[{"id":"1.168237986","rc":[{"batb":[[0,1.41,214.66],[2,1.29,73.25]],"ltp":1.27,"tv":1076.37,"id":14833204},{"batb":[[2,2.5,15.97]],"ltp":2.96,"tv":11.24,"id":13181195}]}]}
{"op":"mcm","clk":"1008354892","pt":1580659678131,"mc":[{"id":"1.168237986","rc":[{"batb":[[0,1.41,48.31]],"ltp":1.27,"tv":1076.37,"id":14833204}]}]}
{"op":"mcm","clk":"1008355520","pt":1580659681051,"mc":[{"id":"1.168237986","rc":[{"batb":[[1,1.4,353.84],[2,1.39,242.7]],"batl":[[0,1.45,267.11]],"ltp":1.27,"tv":1076.37,"id":14833204}]}]}
{"op":"mcm","clk":"1008363798","pt":1580659718799,"mc":[{"id":"1.168237986","rc":[{"batb":[[2,2.5,15.82]],"ltp":2.96,"tv":11.24,"id":13181195}]}]}
{"op":"mcm","clk":"1008371986","pt":1580659755489,"mc":[{"id":"1.168237986","rc":[{"batb":[[0,1.29,73.25],[1,1.25,505.09],[2,1.01,10.51]],"ltp":1.27,"tv":1076.37,"id":14833204},{"batb":[[0,2.62,379.26],[1,2.5,15.82],[2,1.01,10.51]],"ltp":2.96,"tv":11.24,"id":13181195}]}]}
{"op":"mcm","clk":"1008372557","pt":1580659757925,"mc":[{"id":"1.168237986","rc":[{"batb":[[0,1.3,167.76],[1,1.29,423.87],[2,1.25,505.09]],"batl":[[0,1.65,146.39],[1,1.66,117.2]],"ltp":1.27,"tv":1076.37,"id":14833204}]}]}
{"op":"mcm","clk":"1008372915","pt":1580659759505,"mc":[{"id":"1.168237986","rc":[{"batb":[[0,1.29,73.25],[1,1.25,505.09],[2,1.01,10.51]],"ltp":1.27,"tv":1076.37,"id":14833204}]}]}
{"op":"mcm","clk":"1008373164","pt":1580659760597,"mc":[{"id":"1.168237986","rc":[{"batb":[[1,1.01,10.51],[2,1.01,0]],"ltp":1.27,"tv":1076.37,"id":14833204},{"batb":[[0,2.5,15.82],[1,1.01,10.51],[2,1.01,0]],"ltp":2.96,"tv":11.24,"id":13181195}]}]}
{"op":"mcm","clk":"1008373658","pt":1580659762939,"mc":[{"id":"1.168237986","rc":[{"batb":[[0,1.59,230.9],[1,1.58,141.56],[2,1.29,73.25]],"ltp":1.27,"tv":1076.37,"id":14833204}]}]}
{"op":"mcm","clk":"1008373920","pt":1580659764005,"mc":[{"id":"1.168237986","rc":[{"batb":[[0,1.6,29.19],[1,1.59,230.9],[2,1.58,141.56]],"ltp":1.27,"tv":1076.37,"id":14833204},{"batb":[[1,2.02,28.88],[2,1.01,10.51]],"ltp":2.96,"tv":11.24,"id":13181195}]}]}
{"op":"mcm","clk":"1008374128","pt":1580659764943,"mc":[{"id":"1.168237986","rc":[{"batb":[[2,1.97,394.86]],"ltp":2.96,"tv":11.24,"id":13181195}]}]}
{"op":"mcm","clk":"1008376500","pt":1580659775347,"mc":[{"id":"1.168237986","rc":[{"batb":[[1,1.59,137.71],[2,1.43,45.79]],"batl":[[0,1.66,117.2],[1,1.66,0]],"ltp":1.27,"tv":1076.37,"id":14833204}]}]}
{"op":"mcm","clk":"1008377191","pt":1580659778517,"mc":[{"id":"1.168237986","rc":[{"batb":[[0,1.43,45.79],[1,1.38,448.45],[2,1.01,10.51]],"ltp":1.27,"tv":1076.37,"id":14833204},{"batb":[[0,2.02,28.88],[1,1.97,394.86],[2,1.01,10.51]],"ltp":2.96,"tv":11.24,"id":13181195}]}]}
{"op":"mcm","clk":"1008378187","pt":1580659782871,"mc":[{"id":"1.168237986","rc":[{"batb":[[1,1.01,10.51],[2,1.01,0]],"ltp":1.27,"tv":1076.37,"id":14833204}]}]}
{"op":"mcm","clk":"1008378902","pt":1580659785780,"mc":[{"id":"1.168237986","rc":[{"batb":[[0,1.65,164.95],[1,1.64,122.97],[2,1.43,45.79]],"batl":[[0,1.71,130.71],[1,1.73,204.64]],"ltp":1.27,"tv":1076.37,"id":14833204}]}]}
{"op":"mcm","clk":"1008380188","pt":1580659791574,"mc":[{"id":"1.168237986","rc":[{"batb":[[0,1.43,45.79],[1,1.4,451],[2,1.01,10.51]],"ltp":1.27,"tv":1076.37,"id":14833204}]}]}
{"op":"mcm","clk":"1008380848","pt":1580659794469,"mc":[{"id":"1.168237986","rc":[{"batb":[[0,1.43,245.32],[1,1.42,218.57],[2,1.4,451]],"batl":[[0,1.99,134.57],[1,2.02,189.8]],"ltp":1.27,"tv":1076.37,"id":14833204}]}]}
{"op":"mcm","clk":"1008381198","pt":1580659795969,"mc":[{"id":"1.168237986","rc":[{"batb":[[0,1.43,45.79],[1,1.4,451],[2,1.01,10.51]],"ltp":1.27,"tv":1076.37,"id":14833204}]}]}
{"op":"mcm","clk":"1008381413","pt":1580659796857,"mc":[{"id":"1.168237986","rc":[{"batb":[[1,1.01,10.51],[2,1.01,0]],"ltp":1.27,"tv":1076.37,"id":14833204},{"batb":[[1,1.01,10.51],[2,1.01,0]],"ltp":2.96,"tv":11.24,"id":13181195}]}]}
{"op":"mcm","clk":"1008381874","pt":1580659798888,"mc":[{"id":"1.168237986","rc":[{"batb":[[0,1.9,166.35],[1,1.89,16.76],[2,1.88,154]],"ltp":1.27,"tv":1076.37,"id":14833204},{"batb":[[1,1.72,24.39],[2,1.01,10.51]],"ltp":2.96,"tv":11.24,"id":13181195}]}]}
{"op":"mcm","clk":"1008382412","pt":1580659801274,"mc":[{"id":"1.168237986","rc":[{"batb":[[2,1.7,409.32]],"ltp":2.96,"tv":11.24,"id":13181195}]}]}
{"op":"mcm","clk":"1008386178","pt":1580659818337,"mc":[{"id":"1.168237986","rc":[{"batb":[[0,1.67,25.49],[1,1.55,420.5],[2,1.01,10.51]],"ltp":1.27,"tv":1076.37,"id":14833204},{"batb":[[0,1.72,24.39],[1,1.7,409.32],[2,1.01,10.51]],"ltp":2.96,"tv":11.24,"id":13181195}]}]}
{"op":"mcm","clk":"1008386747","pt":1580659820908,"mc":[{"id":"1.168237986","rc":[{"batb":[[0,1.67,175.22],[1,1.66,117.73],[2,1.55,420.5]],"batl":[[0,2.46,86.12],[1,2.5,140.04]],"ltp":1.27,"tv":1076.37,"id":14833204}]}]}
{"op":"mcm","clk":"1008386873","pt":1580659821400,"mc":[{"id":"1.168237986","rc":[{"batb":[[0,1.67,25.49],[1,1.55,420.5],[2,1.01,10.51]],"batl":[[0,1.9,2.27],[1,2.5,0]],"ltp":1.27,"tv":1076.37,"id":14833204}]}]}
{"op":"mcm","clk":"1008387428","pt":1580659823948,"mc":[{"id":"1.168237986","rc":[{"trd":[[1.9,35.31]],"ltp":1.9,"tv":1078.64,"id":14833204},{"trd":[[2.1,2.06]],"batb":[[0,1.94,111.18],[1,1.92,144.08],[2,1.72,24.39]],"batl":[[0,2.02,93.24],[1,2.04,122.27]],"ltp":2.1,"tv":13.3,"id":13181195}],"tv":1091.94}]}
{"op":"mcm","clk":"1008387654","pt":1580659824973,"mc":[{"id":"1.168237986","rc":[{"batl":[[0,2.04,122.27],[1,2.04,0]],"ltp":2.1,"tv":13.3,"id":13181195}]}]}
{"op":"mcm","clk":"1008387990","pt":1580659826352,"mc":[{"id":"1.168237986","rc":[{"batb":[[0,1.72,24.39],[1,1.7,409.32],[2,1.01,10.51]],"ltp":2.1,"tv":13.3,"id":13181195}]}]}
{"op":"mcm","clk":"1008388693","pt":1580659829344,"mc":[{"id":"1.168237986","rc":[{"batb":[[2,1.68,182.69]],"batl":[[0,2.5,125.27],[1,2.54,134.96]],"ltp":2.1,"tv":13.3,"id":13181195}]}]}
{"op":"mcm","clk":"1008389522","pt":1580659832934,"mc":[{"id":"1.168237986","rc":[{"batb":[[2,1.01,10.51]],"ltp":2.1,"tv":13.3,"id":13181195}]}]}
{"op":"mcm","clk":"1008389664","pt":1580659833575,"mc":[{"id":"1.168237986","rc":[{"batl":[[0,3,2.27]],"ltp":2.1,"tv":13.3,"id":13181195}]}]}
{"op":"mcm","clk":"1008390166","pt":1580659835917,"mc":[{"id":"1.168237986","rc":[{"batb":[[0,1.67,174.23],[1,1.66,117.73]],"batl":[[0,1.73,124.18],[1,1.75,197.06]],"ltp":1.9,"tv":1078.64,"id":14833204},{"batb":[[1,1.01,10.51],[2,1.01,0]],"ltp":2.1,"tv":13.3,"id":13181195}]}]}
{"op":"mcm","clk":"1008390375","pt":1580659836792,"mc":[{"id":"1.168237986","rc":[{"batb":[[2,1.45,43.28]],"ltp":1.9,"tv":1078.64,"id":14833204},{"batb":[[0,2.36,18.49],[1,1.86,18.73],[2,1.01,10.51]],"ltp":2.1,"tv":13.3,"id":13181195}]}]}
{"op":"mcm","clk":"1008390723","pt":1580659839059,"mc":[{"id":"1.168237986","rc":[{"batb":[[1,1.86,417.35]],"ltp":2.1,"tv":13.3,"id":13181195}]}]}
{"op":"mcm","clk":"1008394012","pt":1580659853503,"mc":[{"id":"1.168237986","rc":[{"batb":[[0,1.45,43.28],[1,1.44,436.18],[2,1.01,10.51]],"ltp":1.9,"tv":1078.64,"id":14833204},{"batb":[[0,1.86,417.35],[1,1.01,10.51],[2,1.01,0]],"ltp":2.1,"tv":13.3,"id":13181195}]}]}
{"op":"mcm","clk":"1008394608","pt":1580659856109,"mc":[{"id":"1.168237986","rc":[{"batb":[[0,1.45,249.47],[1,1.44,641.92]],"batl":[[0,2.2,90.09],[1,2.22,95.97]],"ltp":1.9,"tv":1078.64,"id":14833204}]}]}
{"op":"mcm","clk":"1008398290","pt":1580659871753,"mc":[{"id":"1.168237986","rc":[{"trd":[[1.5,4.54]],"batb":[[1,1.44,205.74]],"batl":[[0,1.5,273.42],[1,1.51,165.32]],"ltp":1.5,"tv":1083.18,"id":14833204},{"trd":[[3,2.27]],"batb":[[0,1.86,18.73]],"ltp":3.0,"tv":15.57,"id":13181195}],"tv":1098.75}]}
{"op":"mcm","clk":"1008398540","pt":1580659872882,"mc":[{"id":"1.168237986","rc":[{"batb":[[2,1.27,81.44]],"ltp":1.5,"tv":1083.18,"id":14833204},{"batb":[[0,3,25.02],[1,2.16,23.84],[2,1.01,10.51]],"ltp":3.0,"tv":15.57,"id":13181195}]}]}
{"op":"mcm","clk":"1008398972","pt":1580659874773,"mc":[{"id":"1.168237986","rc":[{"batb":[[2,1.28,485.89]],"ltp":1.5,"tv":1083.18,"id":14833204},{"batb":[[1,2.22,384.52],[2,2.16,23.84]],"ltp":3.0,"tv":15.57,"id":13181195}]}]}
{"op":"mcm","clk":"1008402714","pt":1580659891705,"mc":[{"id":"1.168237986","rc":[{"batb":[[0,1.28,485.89],[1,1.27,81.44],[2,1.01,10.51]],"ltp":1.5,"tv":1083.18,"id":14833204},{"batb":[[0,2.22,384.52],[1,2.16,23.84],[2,1.01,10.51]],"ltp":3.0,"tv":15.57,"id":13181195}]}]}
{"op":"mcm","clk":"1008403325","pt":1580659894499,"mc":[{"id":"1.168237986","rc":[{"batb":[[1,1.27,446.43],[2,1.26,404.64]],"batl":[[0,1.88,138.09],[1,1.9,151.47]],"ltp":1.5,"tv":1083.18,"id":14833204}]}]}
{"op":"mcm","clk":"1008403505","pt":1580659895307,"mc":[{"id":"1.168237986","rc":[{"batb":[[1,1.27,81.44],[2,1.01,10.51]],"ltp":1.5,"tv":1083.18,"id":14833204}]}]}
{"op":"mcm","clk":"1008404141","pt":1580659898013,"mc":[{"id":"1.168237986","rc":[{"batb":[[0,1.27,81.44],[1,1.01,10.51],[2,1.01,0]],"ltp":1.5,"tv":1083.18,"id":14833204}]}]}
{"op":"mcm","clk":"1008404363","pt":1580659899000,"mc":[{"id":"1.168237986","rc":[{"batb":[[0,1.51,182.25],[1,1.5,173.12],[2,1.27,81.44]],"batl":[[0,1.56,185.08],[1,1.57,142.91]],"ltp":1.5,"tv":1083.18,"id":14833204}]}]}
{"op":"mcm","clk":"1008405052","pt":1580659901933,"mc":[{"id":"1.168237986","rc":[{"batb":[[0,1.31,477.51],[1,1.27,81.44],[2,1.01,10.51]],"ltp":1.5,"tv":1083.18,"id":14833204}]}]}
{"op":"mcm","clk":"1008405677","pt":1580659904857,"mc":[{"id":"1.168237986","rc":[{"batb":[[1,1.27,446.43],[2,1.26,404.64]],"batl":[[0,1.88,138.09],[1,1.9,151.47]],"ltp":1.5,"tv":1083.18,"id":14833204}]}]}
{"op":"mcm","clk":"1008406323","pt":1580659907834,"mc":[{"id":"1.168237986","rc":[{"batb":[[1,1.27,81.44],[2,1.01,10.51]],"ltp":1.5,"tv":1083.18,"id":14833204}]}]}
{"op":"mcm","clk":"1008406698","pt":1580659909568,"mc":[{"id":"1.168237986","rc":[{"batb":[[0,1.27,81.44],[1,1.01,10.51],[2,1.01,0]],"ltp":1.5,"tv":1083.18,"id":14833204},{"batb":[[0,2.16,23.84],[1,1.01,10.51],[2,1.01,0]],"ltp":3.0,"tv":15.57,"id":13181195}]}]}
{"op":"mcm","clk":"1008406974","pt":1580659910896,"mc":[{"id":"1.168237986","rc":[{"batb":[[0,1.8,180.6],[1,1.78,184.03],[2,1.27,81.44]],"ltp":1.5,"tv":1083.18,"id":14833204}]}]}
{"op":"mcm","clk":"1008407136","pt":1580659911586,"mc":[{"id":"1.168237986","rc":[{"batb":[[1,1.78,204.17],[2,1.46,41.7]],"ltp":1.5,"tv":1083.18,"id":14833204},{"batb":[[1,1.61,30.53],[2,1.01,10.51]],"ltp":3.0,"tv":15.57,"id":13181195}]}]}
{"op":"mcm","clk":"1008407568","pt":1580659913364,"mc":[{"id":"1.168237986","rc":[{"batb":[[2,1.5,426.9]],"ltp":1.5,"tv":1083.18,"id":14833204},{"batb":[[1,1.77,402.27],[2,1.61,30.53]],"ltp":3.0,"tv":15.57,"id":13181195}]}]}
{"op":"mcm","clk":"1008411308","pt":1580659929596,"mc":[{"id":"1.168237986","rc":[{"batb":[[0,1.5,426.9],[1,1.46,41.7],[2,1.01,10.51]],"ltp":1.5,"tv":1083.18,"id":14833204},{"batb":[[0,1.77,402.27],[1,1.61,30.53],[2,1.01,10.51]],"ltp":3.0,"tv":15.57,"id":13181195}]}]}
{"op":"mcm","clk":"1008411651","pt":1580659930862,"mc":[{"id":"1.168237986","rc":[{"batb":[[0,1.46,41.7],[1,1.01,10.51],[2,1.01,0]],"ltp":1.5,"tv":1083.18,"id":14833204},{"batb":[[0,1.61,30.53],[1,1.01,10.51],[2,1.01,0]],"ltp":3.0,"tv":15.57,"id":13181195}]}]}
{"op":"mcm","clk":"1008412078","pt":1580659932767,"mc":[{"id":"1.168237986","rc":[{"batb":[[0,1.47,41.23],[1,1.46,169.37],[2,1.45,199.31]],"batl":[[0,2.82,74.48],[1,2.86,98.82]],"ltp":1.5,"tv":1083.18,"id":14833204},{"batb":[[0,1.6,30.84]],"ltp":3.0,"tv":15.57,"id":13181195}]}]}
{"op":"mcm","clk":"1008412211","pt":1580659933384,"mc":[{"id":"1.168237986","rc":[{"batb":[[1,1.01,10.51],[2,1.45,0]],"ltp":1.5,"tv":1083.18,"id":14833204}]}]}
{"op":"mcm","clk":"1008413038","pt":1580659936963,"mc":[{"id":"1.168237986","rc":[{"batb":[[0,1.93,115.89],[1,1.91,146.43],[2,1.47,41.23]],"batl":[[0,2.02,159.42],[1,2.04,122.3]],"ltp":1.5,"tv":1083.18,"id":14833204}]}]}
{"op":"mcm","clk":"1008413399","pt":1580659938654,"mc":[{"id":"1.168237986","rc":[{"batb":[[2,1.55,420.5]],"ltp":1.5,"tv":1083.18,"id":14833204},{"batb":[[0,1.7,409.32],[1,1.6,30.84],[2,1.01,10.51]],"ltp":3.0,"tv":15.57,"id":13181195}]}]}
{"op":"mcm","clk":"1008413865","pt":1580659940906,"mc":[{"id":"1.168237986","rc":[{"batb":[[0,1.55,420.5],[1,1.47,41.23],[2,1.01,10.51]],"ltp":1.5,"tv":1083.18,"id":14833204}]}]}
{"op":"mcm","clk":"1008414517","pt":1580659943775,"mc":[{"id":"1.168237986","rc":[{"batb":[[2,1.46,169.37]],"batl":[[0,2.82,74.48],[1,2.86,98.82]],"ltp":1.5,"tv":1083.18,"id":14833204}]}]}
{"op":"mcm","clk":"1008414573","pt":1580659944087,"mc":[{"id":"1.168237986","rc":[{"trd":[[1.55,19.09]],"batb":[[0,1.55,410.96]],"ltp":1.55,"tv":1102.26,"id":14833204}],"tv":1117.84}]}
{"op":"mcm","clk":"1008415922","pt":1580659950093,"mc":[{"id":"1.168237986","rc":[{"batb":[[2,1.01,10.51]],"ltp":1.55,"tv":1102.26,"id":14833204}]}]}
{"op":"mcm","clk":"1008416300","pt":1580659951780,"mc":[{"id":"1.168237986","rc":[{"batb":[[0,1.47,41.23],[1,1.01,10.51],[2,1.01,0]],"ltp":1.55,"tv":1102.26,"id":14833204},{"batb":[[0,1.6,30.84],[1,1.01,10.51],[2,1.01,0]],"ltp":3.0,"tv":15.57,"id":13181195}]}]}
{"op":"mcm","clk":"1008416577","pt":1580659952975,"mc":[{"id":"1.168237986","rc":[{"trd":[[1.6,61.68]],"batb":[[0,1.55,127.53],[1,1.54,154.75],[2,1.01,10.51]],"batl":[[0,1.6,140.94],[1,1.61,129.61]],"ltp":1.6,"tv":77.25,"id":13181195}],"tv":1179.52}]}
{"op":"mcm","clk":"1008416753","pt":1580659953793,"mc":[{"id":"1.168237986","rc":[{"batb":[[0,2.5,14.87],[1,2.04,26.59],[2,1.01,10.51]],"ltp":1.55,"tv":1102.26,"id":14833204},{"batb":[[2,1.46,43.67]],"ltp":1.6,"tv":77.25,"id":13181195}]}]}
{"op":"mcm","clk":"1008417265","pt":1580659956001,"mc":[{"id":"1.168237986","rc":[{"batb":[[2,1.92,387.29]],"ltp":1.55,"tv":1102.26,"id":14833204}]}]}
{"op":"mcm","clk":"1008420150","pt":1580659968949,"mc":[{"id":"1.168237986","rc":[{"trd":[[1.6,84.17]],"batl":[[0,1.6,129.7]],"ltp":1.6,"tv":99.74,"id":13181195}],"tv":1202.01}]}
{"op":"mcm","clk":"1008420747","pt":1580659971665,"mc":[{"id":"1.168237986","rc":[{"batl":[[0,1.6,156.41]],"ltp":1.6,"tv":99.74,"id":13181195}]}]}
{"op":"mcm","clk":"1008422420","pt":1580659978865,"mc":[{"id":"1.168237986","rc":[{"batl":[[0,1.6,132.13]],"ltp":1.6,"tv":99.74,"id":13181195}]}]}
{"op":"mcm","clk":"1008422640","pt":1580659979790,"mc":[{"id":"1.168237986","rc":[{"trd":[[1.55,255.06]],"batb":[[0,1.54,154.75],[1,1.46,43.67],[2,1.4,461.76]],"batl":[[0,1.55,53.11],[1,1.6,132.13],[2,1.61,129.61]],"ltp":1.55,"tv":354.8,"id":13181195}],"tv":1457.07}]}
{"op":"mcm","clk":"1008422899","pt":1580659980876,"mc":[{"id":"1.168237986","rc":[{"trd":[[1.55,330.54]],"batl":[[0,1.55,27.66]],"ltp":1.55,"tv":430.28,"id":13181195}],"tv":1532.55}]}
{"op":"mcm","clk":"1008423617","pt":1580659983998,"mc":[{"id":"1.168237986","rc":[{"batb":[[1,1.53,159.6],[2,1.46,43.67]],"batl":[[0,1.55,12.29],[1,1.6,177.44]],"ltp":1.55,"tv":430.28,"id":13181195}]}]}
{"op":"mcm","clk":"1008424053","pt":1580659985882,"mc":[{"id":"1.168237986","rc":[{"batl":[[1,1.6,216.26]],"ltp":1.55,"tv":430.28,"id":13181195}]}]}
{"op":"mcm","clk":"1008424293","pt":1580659986880,"mc":[{"id":"1.168237986","rc":[{"batb":[[0,1.54,237.12]],"ltp":1.55,"tv":430.28,"id":13181195}]}]}
{"op":"mcm","clk":"1008424775","pt":1580659988973,"mc":[{"id":"1.168237986","rc":[{"batb":[[0,1.46,43.67],[1,1.4,461.76],[2,1.01,10.51]],"batl":[[1,1.6,0],[2,1.61,0]],"ltp":1.55,"tv":430.28,"id":13181195}]}]}
{"op":"mcm","clk":"1008424967","pt":1580659989791,"mc":[{"id":"1.168237986","rc":[{"batb":[[0,2.04,26.59],[1,1.92,387.29],[2,1.01,10.51]],"ltp":1.55,"tv":1102.26,"id":14833204}]}]}
{"op":"mcm","clk":"1008425439","pt":1580659991884,"mc":[{"id":"1.168237986","rc":[{"batb":[[1,1.43,223.82],[2,1.42,217.6]],"batl":[[1,1.86,149.65],[2,1.88,156.32]],"ltp":1.55,"tv":430.28,"id":13181195}]}]}
{"op":"mcm","clk":"1008425612","pt":1580659992587,"mc":[{"id":"1.168237986","rc":[{"batb":[[0,2.08,24.86]],"ltp":1.55,"tv":1102.26,"id":14833204},{"batb":[[0,1.44,46.26],[1,1.4,461.76],[2,1.01,10.51]],"batl":[[1,1.86,0],[2,1.88,0]],"ltp":1.55,"tv":430.28,"id":13181195}]}]}
{"op":"mcm","clk":"1008425754","pt":1580659993177,"mc":[{"id":"1.168237986","rc":[{"batb":[[1,1.01,10.51],[2,1.01,0]],"ltp":1.55,"tv":430.28,"id":13181195}]}]}
{"op":"mcm","clk":"1008426116","pt":1580659994794,"mc":[{"id":"1.168237986","rc":[{"trd":[[1.55,355.13]],"batb":[[0,1.59,109.83],[1,1.58,140.53],[2,1.44,46.26]],"batl":[[0,1.64,127.21],[1,1.65,119.22]],"ltp":1.55,"tv":454.86,"id":13181195}],"tv":1557.13}]}
{"op":"mcm","clk":"1008426251","pt":1580659995391,"mc":[{"id":"1.168237986","rc":[{"batb":[[0,1.58,140.53],[1,1.44,46.26],[2,1.01,10.51]],"ltp":1.55,"tv":454.86,"id":13181195}]}]}
{"op":"mcm","clk":"1008426829","pt":1580659997999,"mc":[{"id":"1.168237986","rc":[{"batb":[[0,1.44,492.5],[1,1.01,10.51],[2,1.01,0]],"ltp":1.55,"tv":454.86,"id":13181195}]}]}
{"op":"mcm","clk":"1008427462","pt":1580660000839,"mc":[{"id":"1.168237986","rc":[{"batb":[[1,1.43,218.93],[2,1.42,217.59]],"batl":[[0,1.86,153.42],[1,1.88,156.33]],"ltp":1.55,"tv":454.86,"id":13181195}]}]}
{"op":"mcm","clk":"1008427673","pt":1580660001731,"mc":[{"id":"1.168237986","rc":[{"batb":[[1,1.01,10.51],[2,1.42,0]],"ltp":1.55,"tv":454.86,"id":13181195}]}]}
{"op":"mcm","clk":"1008428052","pt":1580660003289,"mc":[{"id":"1.168237986","rc":[{"batb":[[1,1.01,10.51],[2,1.01,0]],"ltp":1.55,"tv":1102.26,"id":14833204},{"batb":[[0,1.44,46.26]],"ltp":1.55,"tv":454.86,"id":13181195}]}]}
{"op":"mcm","clk":"1008428430","pt":1580660005019,"mc":[{"id":"1.168237986","rc":[{"batb":[[1,1.69,24.39],[2,1.01,10.51]],"ltp":1.55,"tv":1102.26,"id":14833204},{"batb":[[0,1.84,19.43],[1,1.78,184.54],[2,1.76,191.04]],"ltp":1.55,"tv":454.86,"id":13181195}]}]}
{"op":"mcm","clk":"1008429063","pt":1580660007514,"mc":[{"id":"1.168237986","rc":[{"batb":[[2,1.67,401.13]],"ltp":1.55,"tv":1102.26,"id":14833204}]}]}
{"op":"mcm","clk":"1008430009","pt":1580660011745,"mc":[{"id":"1.168237986","rc":[{"batb":[[1,1.61,29.98],[2,1.58,425.61]],"ltp":1.55,"tv":454.86,"id":13181195}]}]}
{"op":"mcm","clk":"1008430736","pt":1580660014626,"mc":[{"id":"1.168237986","rc":[{"batb":[[1,1.79,108.62],[2,1.77,187.2]],"ltp":1.55,"tv":454.86,"id":13181195}]}]}
{"op":"mcm","clk":"1008433147","pt":1580660024978,"mc":[{"id":"1.168237986","rc":[{"batb":[[0,1.69,24.39],[1,1.67,401.13],[2,1.01,10.51]],"ltp":1.55,"tv":1102.26,"id":14833204},{"batb":[[0,1.61,29.98],[1,1.58,425.61],[2,1.01,10.51]],"ltp":1.55,"tv":454.86,"id":13181195}]}]}
{"op":"mcm","clk":"1008433217","pt":1580660025261,"mc":[{"id":"1.168237986","rc":[{"batb":[[0,1.61,29.74]],"ltp":1.55,"tv":454.86,"id":13181195}]}]}
{"op":"mcm","clk":"1008433804","pt":1580660027894,"mc":[{"id":"1.168237986","rc":[{"batb":[[1,1.58,654.56],[2,1.57,144.39]],"batl":[[0,2.38,82.16],[1,2.42,153.24]],"ltp":1.55,"tv":454.86,"id":13181195}]}]}
{"op":"mcm","clk":"1008434053","pt":1580660028954,"mc":[{"id":"1.168237986","rc":[{"batb":[[1,1.58,425.61],[2,1.01,10.51]],"ltp":1.55,"tv":454.86,"id":13181195}]}]}
{"op":"mcm","clk":"1008434503","pt":1580660030873,"mc":[{"id":"1.168237986","rc":[{"batb":[[1,1.01,10.51],[2,1.01,0]],"ltp":1.55,"tv":1102.26,"id":14833204},{"batb":[[1,1.01,10.51],[2,1.01,0]],"ltp":1.55,"tv":454.86,"id":13181195}]}]}
{"op":"mcm","clk":"1008434706","pt":1580660031790,"mc":[{"id":"1.168237986","rc":[{"batb":[[1,1.58,228.95],[2,1.57,144.39]],"batl":[[0,1.64,159.49],[1,1.65,119.08]],"ltp":1.55,"tv":454.86,"id":13181195}]}]}
{"op":"mcm","clk":"1008434950","pt":1580660032862,"mc":[{"id":"1.168237986","rc":[{"batb":[[0,2.46,15.5],[1,1.94,15.5],[2,1.01,10.51]],"ltp":1.55,"tv":1102.26,"id":14833204}]}]}
{"op":"mcm","clk":"1008435333","pt":1580660034488,"mc":[{"id":"1.168237986","rc":[{"batb":[[2,1.86,390.93]],"ltp":1.55,"tv":1102.26,"id":14833204}]}]}
{"op":"mcm","clk":"1008439202","pt":1580660050818,"mc":[{"id":"1.168237986","rc":[{"batb":[[0,1.94,15.5],[1,1.86,390.93],[2,1.01,10.51]],"ltp":1.55,"tv":1102.26,"id":14833204},{"batb":[[0,1.44,491.87],[1,1.01,10.51],[2,1.57,0]],"ltp":1.55,"tv":454.86,"id":13181195}]}]}
{"op":"mcm","clk":"1008439810","pt":1580660053403,"mc":[{"id":"1.168237986","rc":[{"batb":[[0,1.44,648.09],[1,1.43,210.17],[2,1.01,10.51]],"batl":[[0,2.02,219.85],[1,2.04,122.29]],"ltp":1.55,"tv":454.86,"id":13181195}]}]}
{"op":"mcm","clk":"1008440608","pt":1580660056801,"mc":[{"id":"1.168237986","rc":[{"batb":[[1,1.01,10.51],[2,1.01,0]],"ltp":1.55,"tv":1102.26,"id":14833204},{"batb":[[0,1.44,201.86]],"ltp":1.55,"tv":454.86,"id":13181195}]}]}
{"op":"mcm","clk":"1008441096","pt":1580660058818,"mc":[{"id":"1.168237986","rc":[{"batb":[[0,2.98,23.29],[1,2.36,17.23],[2,1.94,15.5]],"ltp":1.55,"tv":1102.26,"id":14833204},{"batb":[[2,1.33,64.6]],"batl":[[0,1.48,167.56],[1,1.49,173.74]],"ltp":1.55,"tv":454.86,"id":13181195}]}]}
{"op":"mcm","clk":"1008441172","pt":1580660059150,"mc":[{"id":"1.168237986","rc":[{"batb":[[2,1.01,10.51]],"ltp":1.55,"tv":1102.26,"id":14833204}]}]}
{"op":"mcm","clk":"1008441586","pt":1580660060983,"mc":[{"id":"1.168237986","rc":[{"batb":[[2,2.04,387.11]],"ltp":1.55,"tv":1102.26,"id":14833204},{"batb":[[2,1.34,476.37]],"ltp":1.55,"tv":454.86,"id":13181195}]}]}
{"op":"mcm","clk":"1008445637","pt":1580660077927,"mc":[{"id":"1.168237986","rc":[{"batb":[[0,2.36,17.23],[1,2.04,387.11],[2,1.01,10.51]],"ltp":1.55,"tv":1102.26,"id":14833204},{"batb":[[0,1.34,476.37],[1,1.33,64.6],[2,1.01,10.51]],"ltp":1.55,"tv":454.86,"id":13181195}]}]}
{"op":"mcm","clk":"1008446147","pt":1580660080160,"mc":[{"id":"1.168237986","rc":[{"batb":[[0,1.34,878.13],[1,1.33,363.33]],"batl":[[0,1.69,158.32],[1,1.71,211.88]],"ltp":1.55,"tv":454.86,"id":13181195}]}]}
{"op":"mcm","clk":"1008447965","pt":1580660088045,"mc":[{"id":"1.168237986","rc":[{"batb":[[1,1.01,10.51],[2,1.01,0]],"ltp":1.55,"tv":1102.26,"id":14833204},{"batb":[[0,1.34,401.76]],"ltp":1.55,"tv":454.86,"id":13181195}]}]}
{"op":"mcm","clk":"1008448377","pt":1580660089735,"mc":[{"id":"1.168237986","rc":[{"batl":[[0,1.38,182.05],[1,1.39,232.84]],"ltp":1.55,"tv":454.86,"id":13181195}]}]}
{"op":"mcm","clk":"1008448674","pt":1580660090974,"mc":[{"id":"1.168237986","rc":[{"batb":[[0,3.6,14.71],[1,3.05,21.64],[2,1.01,10.51]],"ltp":1.55,"tv":1102.26,"id":14833204},{"batb":[[2,1.28,78.45]],"ltp":1.55,"tv":454.86,"id":13181195}]}]}
{"op":"mcm","clk":"1008449192","pt":1580660093030,"mc":[{"id":"1.168237986","rc":[{"batb":[[2,2.3,378.98]],"ltp":1.55,"tv":1102.26,"id":14833204}]}]}
{"op":"mcm","clk":"1008455501","pt":1580660119999,"mc":[{"id":"1.168237986","rc":[{"batb":[[0,3.05,21.48],[1,2.3,378.98],[2,1.01,10.51]],"ltp":1.55,"tv":1102.26,"id":14833204},{"batb":[[0,1.28,78.45],[1,1.25,516.91],[2,1.01,10.51]],"ltp":1.55,"tv":454.86,"id":13181195}]}]}
{"op":"mcm","clk":"1008456157","pt":1580660122968,"mc":[{"id":"1.168237986","rc":[{"batb":[[0,1.31,178.39],[1,1.3,332.56],[2,1.28,78.45]],"batl":[[0,1.46,147.65],[1,1.47,183.5]],"ltp":1.55,"tv":454.86,"id":13181195}]}]}
{"op":"mcm","clk":"1008457658","pt":1580660129623,"mc":[{"id":"1.168237986","rc":[{"batl":[[0,1.34,227.06],[1,1.35,265.84]],"ltp":1.55,"tv":454.86,"id":13181195}]}]}
{"op":"mcm","clk":"1008457887","pt":1580660130536,"mc":[{"id":"1.168237986","rc":[{"batb":[[0,4,22.66],[1,3.25,18.57],[2,2.3,378.98]],"ltp":1.55,"tv":1102.26,"id":14833204}]}]}
{"op":"mcm","clk":"1008459753","pt":1580660138769,"mc":[{"id":"1.168237986","rc":[{"batb":[[0,3.95,23.13]],"ltp":1.55,"tv":1102.26,"id":14833204},{"batb":[[2,1.29,77.58]],"ltp":1.55,"tv":454.86,"id":13181195}]}]}
{"op":"mcm","clk":"1008461727","pt":1580660146937,"mc":[{"id":"1.168237986","rc":[{"trd":[[4.3,25.21]],"ltp":4.3,"tv":1127.47,"id":14833204},{"trd":[[1.31,82.74]],"batb":[[0,1.31,95.65]],"ltp":1.31,"tv":537.6,"id":13181195}],"tv":1665.08}]}
{"op":"mcm","clk":"1008461954","pt":1580660147975,"mc":[{"id":"1.168237986","rc":[{"batb":[[1,3.2,19.04]],"ltp":4.3,"tv":1127.47,"id":14833204},{"batb":[[2,1.29,77.27]],"ltp":1.31,"tv":537.6,"id":13181195}]}]}
{"op":"mcm","clk":"1008462475","pt":1580660150531,"mc":[{"id":"1.168237986","rc":[{"batb":[[0,1.31,148.1]],"batl":[[0,1.34,256.72]],"ltp":1.31,"tv":537.6,"id":13181195}]}]}
{"op":"mcm","clk":"1008465131","pt":1580660161895,"mc":[{"id":"1.168237986","rc":[{"trd":[[1.31,188.22]],"batb":[[0,1.3,332.56],[1,1.29,77.27],[2,1.25,516.91]],"ltp":1.31,"tv":643.08,"id":13181195}],"tv":1770.56}]}
{"op":"mcm","clk":"1008465601","pt":1580660164004,"mc":[{"id":"1.168237986","rc":[{"batb":[[1,3.9,23.6],[2,3.2,19.04]],"ltp":4.3,"tv":1127.47,"id":14833204}]}]}
{"op":"mcm","clk":"1008465771","pt":1580660164796,"mc":[{"id":"1.168237986","rc":[{"batb":[[0,3.9,23.6],[1,3.2,19.04],[2,2.3,378.98]],"ltp":4.3,"tv":1127.47,"id":14833204},{"batb":[[0,1.3,462.4],[1,1.29,429.37]],"ltp":1.31,"tv":643.08,"id":13181195}]}]}
{"op":"mcm","clk":"1008466342","pt":1580660167199,"mc":[{"id":"1.168237986","rc":[{"trd":[[1.3,22.74]],"batb":[[0,1.3,451.03]],"ltp":1.3,"tv":665.82,"id":13181195}],"tv":1793.3}]}
{"op":"mcm","clk":"1008467238","pt":1580660171032,"mc":[{"id":"1.168237986","rc":[{"batl":[[0,1.34,286.76]],"ltp":1.3,"tv":665.82,"id":13181195}]}]}
{"op":"mcm","clk":"1008470581","pt":1580660185308,"mc":[{"id":"1.168237986","rc":[{"trd":[[1.3,29.5]],"batb":[[0,1.3,447.65]],"ltp":1.3,"tv":672.58,"id":13181195}],"tv":1800.06}]}
{"op":"mcm","clk":"1008471087","pt":1580660187618,"mc":[{"id":"1.168237986","rc":[{"batb":[[0,1.32,11.58],[1,1.3,447.65],[2,1.29,429.37]],"ltp":1.3,"tv":672.58,"id":13181195}]}]}
{"op":"mcm","clk":"1008472949","pt":1580660195637,"mc":[{"id":"1.168237986","rc":[{"batb":[[0,1.3,447.65],[1,1.29,429.37],[2,1.25,516.91]],"ltp":1.3,"tv":672.58,"id":13181195}]}]}
{"op":"mcm","clk":"1008473630","pt":1580660198766,"mc":[{"id":"1.168237986","rc":[{"trd":[[1.34,23.16]],"batl":[[0,1.34,275.18]],"ltp":1.34,"tv":695.75,"id":13181195}],"tv":1823.22}]}
{"op":"mcm","clk":"1008476757","pt":1580660212085,"mc":[{"id":"1.168237986","rc":[{"trd":[[1.34,76.21]],"batl":[[0,1.34,248.66]],"ltp":1.34,"tv":748.79,"id":13181195}],"tv":1876.26}]}
{"op":"mcm","clk":"1008479628","pt":1580660223865,"mc":[{"id":"1.168237986","rc":[{"batb":[[0,3.2,19.04],[1,2.3,378.98],[2,1.01,10.51]],"ltp":4.3,"tv":1127.47,"id":14833204},{"batb":[[0,1.25,516.91],[1,1.18,129.75],[2,1.01,10.51]],"ltp":1.34,"tv":748.79,"id":13181195}]}]}
{"op":"mcm","clk":"1008480178","pt":1580660226200,"mc":[{"id":"1.168237986","rc":[{"batb":[[1,1.2,602.51],[2,1.19,469.37]],"batl":[[0,1.44,247.36],[1,1.45,193.74]],"ltp":1.34,"tv":748.79,"id":13181195}]}]}
{"op":"mcm","clk":"1008480424","pt":1580660227185,"mc":[{"id":"1.168237986","rc":[{"batb":[[1,1.18,129.75],[2,1.01,10.51]],"ltp":1.34,"tv":748.79,"id":13181195}]}]}
{"op":"mcm","clk":"1008481085","pt":1580660229957,"mc":[{"id":"1.168237986","rc":[{"batb":[[0,1.18,129.75],[1,1.01,10.51],[2,1.01,0]],"ltp":1.34,"tv":748.79,"id":13181195}]}]}
{"op":"mcm","clk":"1008481323","pt":1580660230978,"mc":[{"id":"1.168237986","rc":[{"batb":[[1,2.76,11.49],[2,2.3,378.98]],"ltp":4.3,"tv":1127.47,"id":14833204},{"batb":[[0,1.4,159.02],[1,1.39,291.89],[2,1.28,80.73]],"ltp":1.34,"tv":748.79,"id":13181195}]}]}
{"op":"mcm","clk":"1008482045","pt":1580660233878,"mc":[{"id":"1.168237986","rc":[{"batb":[[2,1.31,488.76]],"ltp":1.34,"tv":748.79,"id":13181195}]}]}
{"op":"mcm","clk":"1008484719","pt":1580660244997,"mc":[{"id":"1.168237986","rc":[{"batb":[[0,2.76,11.49],[1,2.3,378.98],[2,1.01,10.51]],"ltp":4.3,"tv":1127.47,"id":14833204},{"batb":[[0,1.31,488.76],[1,1.28,80.73],[2,1.01,10.51]],"ltp":1.34,"tv":748.79,"id":13181195}]}]}
{"op":"mcm","clk":"1008485385","pt":1580660247681,"mc":[{"id":"1.168237986","rc":[{"batb":[[1,1.29,388.41],[2,1.28,447.84]],"batl":[[0,1.54,230.48],[1,1.55,149.04]],"ltp":1.34,"tv":748.79,"id":13181195}]}]}
{"op":"mcm","clk":"1008485674","pt":1580660248886,"mc":[{"id":"1.168237986","rc":[{"batb":[[1,1.28,80.73],[2,1.01,10.51]],"ltp":1.34,"tv":748.79,"id":13181195}]}]}
{"op":"mcm","clk":"1008486311","pt":1580660251525,"mc":[{"id":"1.168237986","rc":[{"batb":[[0,1.37,365.47],[1,1.36,267.51],[2,1.31,488.76]],"batl":[[0,1.42,341.03],[1,1.43,204.46]],"ltp":1.34,"tv":748.79,"id":13181195}]}]}
{"op":"mcm","clk":"1008487473","pt":1580660256411,"mc":[{"id":"1.168237986","rc":[{"batb":[[0,1.31,488.76],[1,1.28,80.73],[2,1.01,10.51]],"ltp":1.34,"tv":748.79,"id":13181195}]}]}
{"op":"mcm","clk":"1008488131","pt":1580660258998,"mc":[{"id":"1.168237986","rc":[{"batb":[[1,1.29,388.41],[2,1.28,447.84]],"batl":[[0,1.54,230.48],[1,1.55,149.04]],"ltp":1.34,"tv":748.79,"id":13181195}]}]}
{"op":"mcm","clk":"1008489789","pt":1580660265907,"mc":[{"id":"1.168237986","rc":[{"batl":[[0,3,2.27]],"ltp":4.3,"tv":1127.47,"id":14833204}]}]}
{"op":"mcm","clk":"1008490059","pt":1580660267039,"mc":[{"id":"1.168237986","rc":[{"batb":[[0,1.29,388.41],[1,1.28,447.84],[2,1.01,10.51]],"ltp":1.34,"tv":748.79,"id":13181195}]}]}
{"op":"mcm","clk":"1008490173","pt":1580660267558,"mc":[{"id":"1.168237986","rc":[{"trd":[[3,2.27]],"ltp":3.0,"tv":1129.74,"id":14833204},{"trd":[[1.5,4.54]],"batl":[[0,1.33,381.31],[1,1.34,273.87]],"ltp":1.5,"tv":753.33,"id":13181195}],"tv":1883.08}]}
{"op":"mcm","clk":"1008490375","pt":1580660268429,"mc":[{"id":"1.168237986","rc":[{"batb":[[0,4,21.87],[1,3.2,19.75],[2,2.3,378.98]],"ltp":3.0,"tv":1129.74,"id":14833204},{"batb":[[2,1.15,155.32]],"ltp":1.5,"tv":753.33,"id":13181195}]}]}
{"op":"mcm","clk":"1008491011","pt":1580660270892,"mc":[{"id":"1.168237986","rc":[{"batb":[[2,1.22,535.09]],"ltp":1.5,"tv":753.33,"id":13181195}]}]}
{"op":"mcm","clk":"1008493331","pt":1580660280539,"mc":[{"id":"1.168237986","rc":[{"batl":[[2,3,4.54]],"ltp":1.5,"tv":753.33,"id":13181195}]}]}
{"op":"mcm","clk":"1008494647","pt":1580660286042,"mc":[{"id":"1.168237986","rc":[{"trd":[[1.29,16.8]],"batb":[[0,1.29,380.01]],"ltp":1.29,"tv":770.13,"id":13181195}],"tv":1899.88}]}
{"op":"mcm","clk":"1008495488","pt":1580660290028,"mc":[{"id":"1.168237986","rc":[{"batb":[[0,1.28,80.73],[1,1.22,535.09],[2,1.15,155.32]],"batl":[[0,3,4.54],[1,1.34,0],[2,3,0]],"ltp":1.29,"tv":770.13,"id":13181195}]}]}
{"op":"mcm","clk":"1008495610","pt":1580660290626,"mc":[{"id":"1.168237986","rc":[{"batb":[[0,3.2,19.75],[1,2.3,378.98],[2,1.01,10.51]],"ltp":3.0,"tv":1129.74,"id":14833204},{"batb":[[0,1.22,535.09],[1,1.15,155.32],[2,1.01,10.51]],"ltp":1.29,"tv":770.13,"id":13181195}]}]}
{"op":"mcm","clk":"1008496386","pt":1580660293880,"mc":[{"id":"1.168237986","rc":[{"batb":[[1,1.18,187.86],[2,1.17,656.75]],"batl":[[0,1.44,149.75],[1,1.45,194.66],[2,3,4.54]],"ltp":1.29,"tv":770.13,"id":13181195}]}]}
{"op":"mcm","clk":"1008496588","pt":1580660294638,"mc":[{"id":"1.168237986","rc":[{"batb":[[1,1.15,155.32],[2,1.01,10.51]],"batl":[[0,3,4.54],[1,1.45,0],[2,3,0]],"ltp":1.29,"tv":770.13,"id":13181195}]}]}
{"op":"mcm","clk":"1008496726","pt":1580660295290,"mc":[{"id":"1.168237986","rc":[{"batb":[[1,1.01,10.51],[2,1.01,0]],"ltp":3.0,"tv":1129.74,"id":14833204}]}]}
{"op":"mcm","clk":"1008497375","pt":1580660297737,"mc":[{"id":"1.168237986","rc":[{"batb":[[0,1.27,216.92],[1,1.26,398.28],[2,1.22,535.09]],"batl":[[0,1.3,329.81],[1,1.31,307.72],[2,3,4.54]],"ltp":1.29,"tv":770.13,"id":13181195}]}]}
{"op":"mcm","clk":"1008497672","pt":1580660299091,"mc":[{"id":"1.168237986","rc":[{"batb":[[1,2.52,375.92],[2,1.01,10.51]],"ltp":3.0,"tv":1129.74,"id":14833204}]}]}
{"op":"mcm","clk":"1008498285","pt":1580660301845,"mc":[{"id":"1.168237986","rc":[{"batb":[[0,1.22,535.09],[1,1.15,155.32],[2,1.01,10.51]],"batl":[[0,3,4.54],[1,1.31,0],[2,3,0]],"ltp":1.29,"tv":770.13,"id":13181195}]}]}
{"op":"mcm","clk":"1008498919","pt":1580660304690,"mc":[{"id":"1.168237986","rc":[{"batb":[[1,1.18,187.15],[2,1.17,656.75]],"batl":[[0,1.44,150.33],[1,1.45,194.66],[2,3,4.54]],"ltp":1.29,"tv":770.13,"id":13181195}]}]}
{"op":"mcm","clk":"1008502777","pt":1580660321594,"mc":[{"id":"1.168237986","rc":[{"batb":[[1,1.15,155.32],[2,1.01,10.51]],"ltp":1.29,"tv":770.13,"id":13181195}]}]}
{"op":"mcm","clk":"1008503336","pt":1580660323995,"mc":[{"id":"1.168237986","rc":[{"batb":[[1,1.01,10.51],[2,1.01,0]],"ltp":3.0,"tv":1129.74,"id":14833204},{"batb":[[0,1.15,155.32],[1,1.01,10.51],[2,1.01,0]],"ltp":1.29,"tv":770.13,"id":13181195}]}]}
{"op":"mcm","clk":"1008503558","pt":1580660325016,"mc":[{"id":"1.168237986","rc":[{"batb":[[0,1.4,262.97],[1,1.39,240.25],[2,1.15,155.32]],"ltp":1.29,"tv":770.13,"id":13181195}]}]}
{"op":"mcm","clk":"1008503783","pt":1580660325985,"mc":[{"id":"1.168237986","rc":[{"batb":[[1,2.68,12.43],[2,1.01,10.51]],"ltp":3.0,"tv":1129.74,"id":14833204},{"batb":[[0,1.4,314.9],[2,1.26,85.45]],"ltp":1.29,"tv":770.13,"id":13181195}]}]}
{"op":"mcm","clk":"1008504139","pt":1580660327425,"mc":[{"id":"1.168237986","rc":[{"batb":[[2,2.12,381.97]],"ltp":3.0,"tv":1129.74,"id":14833204},{"batb":[[2,1.31,488.76]],"ltp":1.29,"tv":770.13,"id":13181195}]}]}
{"op":"mcm","clk":"1008508585","pt":1580660347002,"mc":[{"id":"1.168237986","rc":[{"batl":[[0,1.45,194.66],[1,3,4.54],[2,3,0]],"ltp":1.29,"tv":770.13,"id":13181195}]}]}
{"op":"mcm","clk":"1008509050","pt":1580660348958,"mc":[{"id":"1.168237986","rc":[{"batb":[[0,1.4,51.93],[1,1.31,488.76],[2,1.26,85.45]],"batl":[[0,3,4.54],[1,3,0]],"ltp":1.29,"tv":770.13,"id":13181195}]}]}
{"op":"mcm","clk":"1008509321","pt":1580660350034,"mc":[{"id":"1.168237986","rc":[{"batb":[[0,2.68,12.43],[1,2.12,381.97],[2,1.01,10.51]],"ltp":3.0,"tv":1129.74,"id":14833204},{"batb":[[0,1.31,488.76],[1,1.26,85.45],[2,1.01,10.51]],"ltp":1.29,"tv":770.13,"id":13181195}]}]}
{"op":"mcm","clk":"1008509742","pt":1580660351849,"mc":[{"id":"1.168237986","rc":[{"batb":[[1,1.28,399.25],[2,1.27,382.79]],"batl":[[0,1.57,232.25],[1,1.58,138.43],[2,3,4.54]],"ltp":1.29,"tv":770.13,"id":13181195}]}]}
{"op":"mcm","clk":"1008510249","pt":1580660353997,"mc":[{"id":"1.168237986","rc":[{"batb":[[1,1.26,85.45],[2,1.01,10.51]],"batl":[[0,3,4.54],[1,1.58,0],[2,3,0]],"ltp":1.29,"tv":770.13,"id":13181195}]}]}
{"op":"mcm","clk":"1008510724","pt":1580660356009,"mc":[{"id":"1.168237986","rc":[{"batb":[[0,1.38,201.9],[1,1.37,255.55],[2,1.31,488.76]],"batl":[[0,1.42,252.18],[1,1.43,204.68],[2,3,4.54]],"ltp":1.29,"tv":770.13,"id":13181195}]}]}
{"op":"mcm","clk":"1008512077","pt":1580660361851,"mc":[{"id":"1.168237986","rc":[{"batb":[[0,1.31,488.76],[1,1.26,85.45],[2,1.01,10.51]],"batl":[[0,3,4.54],[1,1.43,0],[2,3,0]],"ltp":1.29,"tv":770.13,"id":13181195}]}]}
{"op":"mcm","clk":"1008512726","pt":1580660364974,"mc":[{"id":"1.168237986","rc":[{"batb":[[1,1.28,399.25],[2,1.27,382.79]],"batl":[[0,1.57,232.25],[1,1.58,138.43],[2,3,4.54]],"ltp":1.29,"tv":770.13,"id":13181195}]}]}
{"op":"mcm","clk":"1008513879","pt":1580660369934,"mc":[{"id":"1.168237986","rc":[{"batl":[[0,3,4.54],[1,1.58,0],[2,3,0]],"ltp":1.29,"tv":770.13,"id":13181195}]}]}
{"op":"mcm","clk":"1008514329","pt":1580660372004,"mc":[{"id":"1.168237986","rc":[{"batb":[[1,1.01,10.51],[2,1.01,0]],"ltp":3.0,"tv":1129.74,"id":14833204},{"batb":[[0,1.28,399.25],[1,1.27,382.79],[2,1.26,85.45]],"ltp":1.29,"tv":770.13,"id":13181195}]}]}
{"op":"mcm","clk":"1008514500","pt":1580660372665,"mc":[{"id":"1.168237986","rc":[{"batl":[[0,1.32,417.56],[1,1.33,282.52],[2,3,4.54]],"ltp":1.29,"tv":770.13,"id":13181195}]}]}
{"op":"mcm","clk":"1008514705","pt":1580660373560,"mc":[{"id":"1.168237986","rc":[{"batb":[[0,4.2,20.14],[1,3.05,22.03],[2,1.01,10.51]],"ltp":3.0,"tv":1129.74,"id":14833204}]}]}
{"op":"mcm","clk":"1008515247","pt":1580660375879,"mc":[{"id":"1.168237986","rc":[{"batb":[[2,2.52,375.92]],"ltp":3.0,"tv":1129.74,"id":14833204}]}]}
{"op":"mcm","clk":"1008516923","pt":1580660383265,"mc":[{"id":"1.168237986","rc":[{"trd":[[1.28,4.54]],"batb":[[0,1.28,396.98]],"ltp":1.28,"tv":774.67,"id":13181195}],"tv":1904.42}]}
{"op":"mcm","clk":"1008519851","pt":1580660395903,"mc":[{"id":"1.168237986","rc":[{"batb":[[0,3.05,22.03],[1,2.52,375.92],[2,1.01,10.51]],"ltp":3.0,"tv":1129.74,"id":14833204},{"batb":[[0,1.2,542.93],[1,1.11,211.02],[2,1.01,10.51]],"batl":[[0,3,4.54],[1,1.33,0],[2,3,0]],"ltp":1.28,"tv":774.67,"id":13181195}]}]}
{"op":"mcm","clk":"1008520355","pt":1580660397877,"mc":[{"id":"1.168237986","rc":[{"batb":[[1,1.01,10.51],[2,1.01,0]],"ltp":3.0,"tv":1129.74,"id":14833204},{"batb":[[0,1.11,211.02],[1,1.01,10.51],[2,1.01,0]],"ltp":1.28,"tv":774.67,"id":13181195}]}]}
{"op":"mcm","clk":"1008520574","pt":1580660398889,"mc":[{"id":"1.168237986","rc":[{"batb":[[0,3,22.42]],"ltp":3.0,"tv":1129.74,"id":14833204},{"batb":[[0,1.13,1013.54],[1,1.12,208.35],[2,1.01,10.51]],"batl":[[0,1.47,150.99],[1,1.48,178.45],[2,3,4.54]],"ltp":1.28,"tv":774.67,"id":13181195}]}]}
{"op":"mcm","clk":"1008521022","pt":1580660400795,"mc":[{"id":"1.168237986","rc":[{"batb":[[0,1.12,208.35],[1,1.01,10.51],[2,1.01,0]],"batl":[[0,3,4.54],[1,1.48,0],[2,3,0]],"ltp":1.28,"tv":774.67,"id":13181195}]}]}
{"op":"mcm","clk":"1008521840","pt":1580660403912,"mc":[{"id":"1.168237986","rc":[{"batb":[[0,1.25,336.1],[1,1.24,440.05],[2,1.12,208.35]],"batl":[[0,1.28,301.55],[1,1.29,332.89],[2,3,4.54]],"ltp":1.28,"tv":774.67,"id":13181195}]}]}
{"op":"mcm","clk":"1008522532","pt":1580660406937,"mc":[{"id":"1.168237986","rc":[{"batb":[[1,2.62,373.95],[2,1.01,10.51]],"ltp":3.0,"tv":1129.74,"id":14833204},{"batb":[[2,1.18,561.99]],"ltp":1.28,"tv":774.67,"id":13181195}]}]}
{"op":"mcm","clk":"1008523431","pt":1580660410428,"mc":[{"id":"1.168237986","rc":[{"batb":[[0,1.18,561.99],[1,1.12,208.35],[2,1.01,10.51]],"batl":[[0,3,4.54],[1,1.29,0],[2,3,0]],"ltp":1.28,"tv":774.67,"id":13181195}]}]}
{"op":"mcm","clk":"1008523828","pt":1580660411894,"mc":[{"id":"1.168237986","rc":[{"batb":[[1,1.01,10.51],[2,1.01,0]],"ltp":3.0,"tv":1129.74,"id":14833204},{"batb":[[0,1.12,208.35],[1,1.01,10.51],[2,1.01,0]],"ltp":1.28,"tv":774.67,"id":13181195}]}]}
{"op":"mcm","clk":"1008524084","pt":1580660413033,"mc":[{"id":"1.168237986","rc":[{"batb":[[0,1.13,1028.06],[1,1.12,208.35],[2,1.01,10.51]],"batl":[[0,1.47,140.04],[1,1.48,178.43],[2,3,4.54]],"ltp":1.28,"tv":774.67,"id":13181195}]}]}
{"op":"mcm","clk":"1008524409","pt":1580660414199,"mc":[{"id":"1.168237986","rc":[{"batl":[[0,3,4.54],[1,1.48,0],[2,3,0]],"ltp":1.28,"tv":774.67,"id":13181195}]}]}
{"op":"mcm","clk":"1008525088","pt":1580660417026,"mc":[{"id":"1.168237986","rc":[{"batl":[[0,1.16,740],[1,1.17,361.67],[2,3,4.54]],"ltp":1.28,"tv":774.67,"id":13181195}]}]}
{"op":"mcm","clk":"1008525251","pt":1580660417687,"mc":[{"id":"1.168237986","rc":[{"batb":[[0,7.6,10.23],[1,4.2,20.22],[2,1.01,10.51]],"ltp":3.0,"tv":1129.74,"id":14833204}]}]}
{"op":"mcm","clk":"1008525534","pt":1580660418989,"mc":[{"id":"1.168237986","rc":[{"batb":[[2,3.25,369.08]],"ltp":3.0,"tv":1129.74,"id":14833204},{"batb":[[2,1.08,839.25]],"ltp":1.28,"tv":774.67,"id":13181195}]}]}
{"op":"mcm","clk":"1008528707","pt":1580660432250,"mc":[{"id":"1.168237986","rc":[{"trd":[[1.13,3.42]],"batb":[[0,1.13,1026.35]],"ltp":1.13,"tv":778.1,"id":13181195}],"tv":1907.84}]}
{"op":"mcm","clk":"1008530000","pt":1580660437887,"mc":[{"id":"1.168237986","rc":[{"batb":[[0,1.12,208.35],[1,1.08,839.25],[2,1.01,10.51]],"batl":[[0,3,4.54],[1,1.17,0],[2,3,0]],"ltp":1.13,"tv":778.1,"id":13181195}]}]}
{"op":"mcm","clk":"1008530250","pt":1580660439019,"mc":[{"id":"1.168237986","rc":[{"batb":[[0,4.2,20.22],[1,3.25,369.08],[2,1.01,10.51]],"ltp":3.0,"tv":1129.74,"id":14833204},{"batb":[[0,1.08,839.25],[1,1.01,10.51],[2,1.01,0]],"ltp":1.13,"tv":778.1,"id":13181195}]}]}
{"op":"mcm","clk":"1008530686","pt":1580660440916,"mc":[{"id":"1.168237986","rc":[{"batb":[[1,1.01,10.51],[2,1.01,0]],"ltp":3.0,"tv":1129.74,"id":14833204},{"batb":[[0,1.01,10.51],[1,1.01,0]],"ltp":1.13,"tv":778.1,"id":13181195}]}]}
{"op":"mcm","clk":"1008531364","pt":1580660443887,"mc":[{"id":"1.168237986","rc":[{"batb":[[0,1.1,1165.06],[1,1.01,10.51]],"batl":[[0,1.12,372.57],[1,1.13,764.85],[2,3,4.54]],"ltp":1.13,"tv":778.1,"id":13181195}]}]}
{"op":"mcm","clk":"1008531671","pt":1580660445354,"mc":[{"id":"1.168237986","rc":[{"batb":[[1,3.5,367.23],[2,1.01,10.51]],"ltp":3.0,"tv":1129.74,"id":14833204},{"batb":[[1,1.06,970],[2,1.01,10.51]],"ltp":1.13,"tv":778.1,"id":13181195}]}]}
{"op":"mcm","clk":"1008532528","pt":1580660448905,"mc":[{"id":"1.168237986","rc":[{"batb":[[0,1.06,970],[1,1.01,10.51],[2,1.01,0]],"batl":[[0,3,4.54],[1,1.13,0],[2,3,0]],"ltp":1.13,"tv":778.1,"id":13181195}]}]}
{"op":"mcm","clk":"1008533169","pt":1580660451805,"mc":[{"id":"1.168237986","rc":[{"batb":[[1,1.01,10.51],[2,1.01,0]],"ltp":3.0,"tv":1129.74,"id":14833204},{"batb":[[0,1.01,10.51],[1,1.01,0]],"batl":[[0,1.31,196.18],[1,1.32,296.99],[2,3,4.54]],"ltp":1.13,"tv":778.1,"id":13181195}]}]}
{"op":"mcm","clk":"1008534941","pt":1580660460045,"mc":[{"id":"1.168237986","rc":[{"batl":[[0,3,4.54],[1,1.32,0],[2,3,0]],"ltp":1.13,"tv":778.1,"id":13181195}]}]}
{"op":"mcm","clk":"1008535146","pt":1580660460862,"mc":[{"id":"1.168237986","rc":[{"batb":[[0,1.01,10.51],[1,1.01,0]],"ltp":3.0,"tv":1129.74,"id":14833204}]}]}
{"op":"mcm","clk":"1008535412","pt":1580660461860,"mc":[{"id":"1.168237986","marketDefinition":{"bspMarket":false,"turnInPlayEnabled":true,"persistenceEnabled":true,"marketBaseRate":5.0,"eventId":"29681871","eventTypeId":"2","numberOfWinners":1,"bettingType":"ODDS","marketType":"SET_WINNER","marketTime":"2020-02-02T15:20:00.000Z","suspendTime":"2020-02-02T15:20:00.000Z","bspReconciled":false,"complete":true,"inPlay":true,"crossMatching":true,"runnersVoidable":false,"numberOfActiveRunners":2,"betDelay":3,"status":"SUSPENDED","runners":[{"status":"ACTIVE","sortPriority":1,"id":14833204,"name":"Facundo Diaz Acosta"},{"status":"ACTIVE","sortPriority":2,"id":13181195,"name":"Pedro Martinez"}],"regulators":["MR_INT"],"countryCode":"AR","discountAllowed":true,"timezone":"UTC","openDate":"2020-02-02T15:20:00.000Z","version":3149751180,"name":"Set 1 Winner","eventName":"Diaz Acosta v Martinez"}}]}
{"op":"mcm","clk":"1008542317","pt":1580660491500,"mc":[{"id":"1.168237986","tv":0.0}]}
{"op":"mcm","clk":"1008542598","pt":1580660492592,"mc":[{"id":"1.168237986","marketDefinition":{"bspMarket":false,"turnInPlayEnabled":true,"persistenceEnabled":true,"marketBaseRate":5.0,"eventId":"29681871","eventTypeId":"2","numberOfWinners":1,"bettingType":"ODDS","marketType":"SET_WINNER","marketTime":"2020-02-02T15:20:00.000Z","suspendTime":"2020-02-02T15:20:00.000Z","bspReconciled":false,"complete":true,"inPlay":true,"crossMatching":false,"runnersVoidable":false,"numberOfActiveRunners":0,"betDelay":3,"status":"CLOSED","settledTime":"2020-02-02T16:21:30.000Z","runners":[{"status":"LOSER","sortPriority":1,"id":14833204,"name":"Facundo Diaz Acosta"},{"status":"WINNER","sortPriority":2,"id":13181195,"name":"Pedro Martinez"}],"regulators":["MR_INT"],"countryCode":"AR","discountAllowed":true,"timezone":"UTC","openDate":"2020-02-02T15:20:00.000Z","version":3149754413,"name":"Set 1 Winner","eventName":"Diaz Acosta v Martinez"}}]}
