{"op":"mcm","clk":"998156264","pt":1580585282814,"mc":[{"id":"1.168224581","marketDefinition":{"bspMarket":false,"turnInPlayEnabled":true,"persistenceEnabled":true,"marketBaseRate":5.0,"eventId":"29681732","eventTypeId":"2","numberOfWinners":1,"bettingType":"ODDS","marketType":"SET_WINNER","marketTime":"2020-02-02T09:00:00.000Z","suspendTime":"2020-02-02T09:00:00.000Z","bspReconciled":false,"complete":true,"inPlay":false,"crossMatching":false,"runnersVoidable":false,"numberOfActiveRunners":2,"betDelay":0,"status":"OPEN","runners":[{"status":"ACTIVE","sortPriority":1,"id":2284304,"name":"Sergiy Stakhovsky"},{"status":"ACTIVE","sortPriority":2,"id":7797764,"name":"Alexey Vatutin"}],"regulators":["MR_INT"],"countryCode":"FR","discountAllowed":false,"timezone":"UTC","openDate":"2020-02-02T09:00:00.000Z","version":3147099383,"name":"Set 2 Winner","eventName":"Stakhovsky v Vatutin"},"rc":[{"batb":[[0,1.01,20]],"ltp":0.0,"tv":0.0,"id":7797764},{"batb":[[0,1.01,20]],"ltp":0.0,"tv":0.0,"id":2284304}]}]}
{"op":"mcm","clk":"998156387","pt":1580585283539,"mc":[{"id":"1.168224581","marketDefinition":{"bspMarket":false,"turnInPlayEnabled":true,"persistenceEnabled":true,"marketBaseRate":5.0,"eventId":"29681732","eventTypeId":"2","numberOfWinners":1,"bettingType":"ODDS","marketType":"SET_WINNER","marketTime":"2020-02-02T09:00:00.000Z","suspendTime":"2020-02-02T09:00:00.000Z","bspReconciled":false,"complete":true,"inPlay":false,"crossMatching":false,"runnersVoidable":false,"numberOfActiveRunners":2,"betDelay":0,"status":"OPEN","runners":[{"status":"ACTIVE","sortPriority":1,"id":2284304,"name":"Sergiy Stakhovsky"},{"status":"ACTIVE","sortPriority":2,"id":7797764,"name":"Alexey Vatutin"}],"regulators":["MR_INT"],"countryCode":"FR","discountAllowed":true,"timezone":"UTC","openDate":"2020-02-02T09:00:00.000Z","version":3147099383,"name":"Set 2 Winner","eventName":"Stakhovsky v Vatutin"}}]}
{"op":"mcm","clk":"998179115","pt":1580585420309,"mc":[{"id":"1.168224581","rc":[{"batb":[[0,1.01,15]],"ltp":0.0,"tv":0.0,"id":7797764},{"batb":[[0,1.01,15]],"ltp":0.0,"tv":0.0,"id":2284304}]}]}
{"op":"mcm","clk":"998196992","pt":1580585517440,"mc":[{"id":"1.168224581","marketDefinition":{"bspMarket":false,"turnInPlayEnabled":true,"persistenceEnabled":true,"marketBaseRate":5.0,"eventId":"29681732","eventTypeId":"2","numberOfWinners":1,"bettingType":"ODDS","marketType":"SET_WINNER","marketTime":"2020-02-02T13:30:00.000Z","suspendTime":"2020-02-02T13:30:00.000Z","bspReconciled":false,"complete":true,"inPlay":false,"crossMatching":false,"runnersVoidable":false,"numberOfActiveRunners":2,"betDelay":0,"status":"OPEN","runners":[{"status":"ACTIVE","sortPriority":1,"id":2284304,"name":"Sergiy Stakhovsky"},{"status":"ACTIVE","sortPriority":2,"id":7797764,"name":"Alexey Vatutin"}],"regulators":["MR_INT"],"countryCode":"FR","discountAllowed":true,"timezone":"UTC","openDate":"2020-02-02T09:00:00.000Z","version":3147125177,"name":"Set 2 Winner","eventName":"Stakhovsky v Vatutin"}}]}
{"op":"mcm","clk":"998197631","pt":1580585520453,"mc":[{"id":"1.168224581","marketDefinition":{"bspMarket":false,"turnInPlayEnabled":true,"persistenceEnabled":true,"marketBaseRate":5.0,"eventId":"29681732","eventTypeId":"2","numberOfWinners":1,"bettingType":"ODDS","marketType":"SET_WINNER","marketTime":"2020-02-02T13:30:00.000Z","suspendTime":"2020-02-02T13:30:00.000Z","bspReconciled":false,"complete":true,"inPlay":false,"crossMatching":false,"runnersVoidable":false,"numberOfActiveRunners":2,"betDelay":0,"status":"OPEN","runners":[{"status":"ACTIVE","sortPriority":1,"id":2284304,"name":"Sergiy Stakhovsky"},{"status":"ACTIVE","sortPriority":2,"id":7797764,"name":"Alexey Vatutin"}],"regulators":["MR_INT"],"countryCode":"FR","discountAllowed":true,"timezone":"UTC","openDate":"2020-02-02T13:30:00.000Z","version":3147125177,"name":"Set 2 Winner","eventName":"Stakhovsky v Vatutin"}}]}
{"op":"mcm","clk":"999887494","pt":1580602190419,"mc":[{"id":"1.168224581","rc":[{"batb":[[0,1.01,17.53]],"ltp":0.0,"tv":0.0,"id":7797764},{"batb":[[0,1.01,17.53]],"ltp":0.0,"tv":0.0,"id":2284304}]}]}
{"op":"mcm","clk":"999887546","pt":1580602191151,"mc":[{"id":"1.168224581","rc":[{"batb":[[0,1.01,15.51]],"ltp":0.0,"tv":0.0,"id":7797764},{"batb":[[0,1.01,15.51]],"ltp":0.0,"tv":0.0,"id":2284304}]}]}
{"op":"mcm","clk":"999983515","pt":1580603730486,"mc":[{"id":"1.168224581","rc":[{"batb":[[0,1.01,16.01]],"ltp":0.0,"tv":0.0,"id":7797764},{"batb":[[0,1.01,16.01]],"ltp":0.0,"tv":0.0,"id":2284304}]}]}
{"op":"mcm","clk":"1001426134","pt":1580635614335,"mc":[{"id":"1.168224581","marketDefinition":{"bspMarket":false,"turnInPlayEnabled":true,"persistenceEnabled":true,"marketBaseRate":5.0,"eventId":"29681732","eventTypeId":"2","numberOfWinners":1,"bettingType":"ODDS","marketType":"SET_WINNER","marketTime":"2020-02-02T13:24:00.000Z","suspendTime":"2020-02-02T13:24:00.000Z","bspReconciled":false,"complete":true,"inPlay":false,"crossMatching":false,"runnersVoidable":false,"numberOfActiveRunners":2,"betDelay":0,"status":"OPEN","runners":[{"status":"ACTIVE","sortPriority":1,"id":2284304,"name":"Sergiy Stakhovsky"},{"status":"ACTIVE","sortPriority":2,"id":7797764,"name":"Alexey Vatutin"}],"regulators":["MR_INT"],"countryCode":"FR","discountAllowed":true,"timezone":"UTC","openDate":"2020-02-02T13:30:00.000Z","version":3148345549,"name":"Set 2 Winner","eventName":"Stakhovsky v Vatutin"}}]}
{"op":"mcm","clk":"1001426516","pt":1580635617339,"mc":[{"id":"1.168224581","marketDefinition":{"bspMarket":false,"turnInPlayEnabled":true,"persistenceEnabled":true,"marketBaseRate":5.0,"eventId":"29681732","eventTypeId":"2","numberOfWinners":1,"bettingType":"ODDS","marketType":"SET_WINNER","marketTime":"2020-02-02T13:24:00.000Z","suspendTime":"2020-02-02T13:24:00.000Z","bspReconciled":false,"complete":true,"inPlay":false,"crossMatching":false,"runnersVoidable":false,"numberOfActiveRunners":2,"betDelay":0,"status":"OPEN","runners":[{"status":"ACTIVE","sortPriority":1,"id":2284304,"name":"Sergiy Stakhovsky"},{"status":"ACTIVE","sortPriority":2,"id":7797764,"name":"Alexey Vatutin"}],"regulators":["MR_INT"],"countryCode":"FR","discountAllowed":true,"timezone":"UTC","openDate":"2020-02-02T13:24:00.000Z","version":3148345549,"name":"Set 2 Winner","eventName":"Stakhovsky v Vatutin"}}]}
{"op":"mcm","clk":"1001816438","pt":1580640415425,"mc":[{"id":"1.168224581","marketDefinition":{"bspMarket":false,"turnInPlayEnabled":true,"persistenceEnabled":true,"marketBaseRate":5.0,"eventId":"29681732","eventTypeId":"2","numberOfWinners":1,"bettingType":"ODDS","marketType":"SET_WINNER","marketTime":"2020-02-02T12:51:00.000Z","suspendTime":"2020-02-02T12:51:00.000Z","bspReconciled":false,"complete":true,"inPlay":false,"crossMatching":false,"runnersVoidable":false,"numberOfActiveRunners":2,"betDelay":0,"status":"OPEN","runners":[{"status":"ACTIVE","sortPriority":1,"id":2284304,"name":"Sergiy Stakhovsky"},{"status":"ACTIVE","sortPriority":2,"id":7797764,"name":"Alexey Vatutin"}],"regulators":["MR_INT"],"countryCode":"FR","discountAllowed":true,"timezone":"UTC","openDate":"2020-02-02T13:24:00.000Z","version":3148438477,"name":"Set 2 Winner","eventName":"Stakhovsky v Vatutin"}}]}
{"op":"mcm","clk":"1001817075","pt":1580640420557,"mc":[{"id":"1.168224581","marketDefinition":{"bspMarket":false,"turnInPlayEnabled":true,"persistenceEnabled":true,"marketBaseRate":5.0,"eventId":"29681732","eventTypeId":"2","numberOfWinners":1,"bettingType":"ODDS","marketType":"SET_WINNER","marketTime":"2020-02-02T12:51:00.000Z","suspendTime":"2020-02-02T12:51:00.000Z","bspReconciled":false,"complete":true,"inPlay":false,"crossMatching":false,"runnersVoidable":false,"numberOfActiveRunners":2,"betDelay":0,"status":"OPEN","runners":[{"status":"ACTIVE","sortPriority":1,"id":2284304,"name":"Sergiy Stakhovsky"},{"status":"ACTIVE","sortPriority":2,"id":7797764,"name":"Alexey Vatutin"}],"regulators":["MR_INT"],"countryCode":"FR","discountAllowed":true,"timezone":"UTC","openDate":"2020-02-02T12:51:00.000Z","version":3148438477,"name":"Set 2 Winner","eventName":"Stakhovsky v Vatutin"}}]}
{"op":"mcm","clk":"1001853014","pt":1580640715139,"mc":[{"id":"1.168224581","marketDefinition":{"bspMarket":false,"turnInPlayEnabled":true,"persistenceEnabled":true,"marketBaseRate":5.0,"eventId":"29681732","eventTypeId":"2","numberOfWinners":1,"bettingType":"ODDS","marketType":"SET_WINNER","marketTime":"2020-02-02T12:48:00.000Z","suspendTime":"2020-02-02T12:48:00.000Z","bspReconciled":false,"complete":true,"inPlay":false,"crossMatching":false,"runnersVoidable":false,"numberOfActiveRunners":2,"betDelay":0,"status":"OPEN","runners":[{"status":"ACTIVE","sortPriority":1,"id":2284304,"name":"Sergiy Stakhovsky"},{"status":"ACTIVE","sortPriority":2,"id":7797764,"name":"Alexey Vatutin"}],"regulators":["MR_INT"],"countryCode":"FR","discountAllowed":true,"timezone":"UTC","openDate":"2020-02-02T12:51:00.000Z","version":3148443737,"name":"Set 2 Winner","eventName":"Stakhovsky v Vatutin"}}]}
{"op":"mcm","clk":"1001853277","pt":1580640717181,"mc":[{"id":"1.168224581","marketDefinition":{"bspMarket":false,"turnInPlayEnabled":true,"persistenceEnabled":true,"marketBaseRate":5.0,"eventId":"29681732","eventTypeId":"2","numberOfWinners":1,"bettingType":"ODDS","marketType":"SET_WINNER","marketTime":"2020-02-02T12:48:00.000Z","suspendTime":"2020-02-02T12:48:00.000Z","bspReconciled":false,"complete":true,"inPlay":false,"crossMatching":false,"runnersVoidable":false,"numberOfActiveRunners":2,"betDelay":0,"status":"OPEN","runners":[{"status":"ACTIVE","sortPriority":1,"id":2284304,"name":"Sergiy Stakhovsky"},{"status":"ACTIVE","sortPriority":2,"id":7797764,"name":"Alexey Vatutin"}],"regulators":["MR_INT"],"countryCode":"FR","discountAllowed":true,"timezone":"UTC","openDate":"2020-02-02T12:48:00.000Z","version":3148443737,"name":"Set 2 Winner","eventName":"Stakhovsky v Vatutin"}}]}
{"op":"mcm","clk":"1002676463","pt":1580645815895,"mc":[{"id":"1.168224581","marketDefinition":{"bspMarket":false,"turnInPlayEnabled":true,"persistenceEnabled":true,"marketBaseRate":5.0,"eventId":"29681732","eventTypeId":"2","numberOfWinners":1,"bettingType":"ODDS","marketType":"SET_WINNER","marketTime":"2020-02-02T12:16:00.000Z","suspendTime":"2020-02-02T12:16:00.000Z","bspReconciled":false,"complete":true,"inPlay":false,"crossMatching":false,"runnersVoidable":false,"numberOfActiveRunners":2,"betDelay":0,"status":"OPEN","runners":[{"status":"ACTIVE","sortPriority":1,"id":2284304,"name":"Sergiy Stakhovsky"},{"status":"ACTIVE","sortPriority":2,"id":7797764,"name":"Alexey Vatutin"}],"regulators":["MR_INT"],"countryCode":"FR","discountAllowed":true,"timezone":"UTC","openDate":"2020-02-02T12:48:00.000Z","version":3148684859,"name":"Set 2 Winner","eventName":"Stakhovsky v Vatutin"}}]}
{"op":"mcm","clk":"1002676963","pt":1580645818903,"mc":[{"id":"1.168224581","marketDefinition":{"bspMarket":false,"turnInPlayEnabled":true,"persistenceEnabled":true,"marketBaseRate":5.0,"eventId":"29681732","eventTypeId":"2","numberOfWinners":1,"bettingType":"ODDS","marketType":"SET_WINNER","marketTime":"2020-02-02T12:16:00.000Z","suspendTime":"2020-02-02T12:16:00.000Z","bspReconciled":false,"complete":true,"inPlay":false,"crossMatching":false,"runnersVoidable":false,"numberOfActiveRunners":2,"betDelay":0,"status":"OPEN","runners":[{"status":"ACTIVE","sortPriority":1,"id":2284304,"name":"Sergiy Stakhovsky"},{"status":"ACTIVE","sortPriority":2,"id":7797764,"name":"Alexey Vatutin"}],"regulators":["MR_INT"],"countryCode":"FR","discountAllowed":true,"timezone":"UTC","openDate":"2020-02-02T12:16:00.000Z","version":3148684859,"name":"Set 2 Winner","eventName":"Stakhovsky v Vatutin"}}]}
{"op":"mcm","clk":"1002680995","pt":1580645843375,"mc":[{"id":"1.168224581","rc":[{"batb":[[0,2.06,25.34],[1,1.01,16.01]],"ltp":0.0,"tv":0.0,"id":7797764},{"batb":[[0,1.82,19.04],[1,1.01,16.01]],"ltp":0.0,"tv":0.0,"id":2284304}]}]}
{"op":"mcm","clk":"1002730090","pt":1580646163088,"mc":[{"id":"1.168224581","rc":[{"batb":[[0,2.08,25.1]],"ltp":0.0,"tv":0.0,"id":7797764},{"batb":[[0,1.81,19.2]],"ltp":0.0,"tv":0.0,"id":2284304}]}]}
{"op":"mcm","clk":"1002731680","pt":1580646173193,"mc":[{"id":"1.168224581","rc":[{"batb":[[0,2.08,24.86]],"ltp":0.0,"tv":0.0,"id":7797764}]}]}
{"op":"mcm","clk":"1002742247","pt":1580646240381,"mc":[{"id":"1.168224581","rc":[{"batb":[[0,2.08,24.63]],"ltp":0.0,"tv":0.0,"id":7797764},{"batb":[[0,1.8,19.59]],"ltp":0.0,"tv":0.0,"id":2284304}]}]}
{"op":"mcm","clk":"1002745546","pt":1580646261398,"mc":[{"id":"1.168224581","rc":[{"batb":[[1,1.01,17.21]],"ltp":0.0,"tv":0.0,"id":7797764},{"batb":[[1,1.01,17.41]],"ltp":0.0,"tv":0.0,"id":2284304}]}]}
{"op":"mcm","clk":"1002745595","pt":1580646261671,"mc":[{"id":"1.168224581","rc":[{"batb":[[0,2.1,1.2],[1,2.08,24.63],[2,1.01,16.01]],"ltp":0.0,"tv":0.0,"id":7797764},{"batb":[[0,1.81,1.39],[1,1.8,19.59],[2,1.01,16.01]],"ltp":0.0,"tv":0.0,"id":2284304}]}]}
{"op":"mcm","clk":"1002746145","pt":1580646264879,"mc":[{"id":"1.168224581","rc":[{"batb":[[0,2.1,25.59],[1,1.01,16.01],[2,1.01,0]],"ltp":0.0,"tv":0.0,"id":7797764}]}]}
{"op":"mcm","clk":"1002749112","pt":1580646284183,"mc":[{"id":"1.168224581","marketDefinition":{"bspMarket":false,"turnInPlayEnabled":true,"persistenceEnabled":true,"marketBaseRate":5.0,"eventId":"29681732","eventTypeId":"2","numberOfWinners":1,"bettingType":"ODDS","marketType":"SET_WINNER","marketTime":"2020-02-02T12:16:00.000Z","suspendTime":"2020-02-02T12:16:00.000Z","bspReconciled":false,"complete":true,"inPlay":false,"crossMatching":true,"runnersVoidable":false,"numberOfActiveRunners":2,"betDelay":0,"status":"OPEN","runners":[{"status":"ACTIVE","sortPriority":1,"id":2284304,"name":"Sergiy Stakhovsky"},{"status":"ACTIVE","sortPriority":2,"id":7797764,"name":"Alexey Vatutin"}],"regulators":["MR_INT"],"countryCode":"FR","discountAllowed":true,"timezone":"UTC","openDate":"2020-02-02T12:16:00.000Z","version":3148684859,"name":"Set 2 Winner","eventName":"Stakhovsky v Vatutin"}}]}
{"op":"mcm","clk":"1002749748","pt":1580646288005,"mc":[{"id":"1.168224581","rc":[{"batb":[[1,2.06,39.49],[2,1.01,16.01]],"batl":[[0,2.3,31.93]],"ltp":0.0,"tv":0.0,"id":7797764},{"batb":[[2,1.78,53.77]],"batl":[[0,1.96,42.01]],"ltp":0.0,"tv":0.0,"id":2284304}]}]}
{"op":"mcm","clk":"1002755948","pt":1580646328201,"mc":[{"id":"1.168224581","rc":[{"batb":[[0,2.1,25.44]],"ltp":0.0,"tv":0.0,"id":7797764},{"batb":[[1,1.79,19.91]],"ltp":0.0,"tv":0.0,"id":2284304}]}]}
{"op":"mcm","clk":"1002757590","pt":1580646338259,"mc":[{"id":"1.168224581","rc":[{"batb":[[1,1.8,19.83]],"ltp":0.0,"tv":0.0,"id":2284304}]}]}
{"op":"mcm","clk":"1002787425","pt":1580646527443,"mc":[{"id":"1.168224581","marketDefinition":{"bspMarket":false,"turnInPlayEnabled":true,"persistenceEnabled":true,"marketBaseRate":5.0,"eventId":"29681732","eventTypeId":"2","numberOfWinners":1,"bettingType":"ODDS","marketType":"SET_WINNER","marketTime":"2020-02-02T12:16:00.000Z","suspendTime":"2020-02-02T12:16:00.000Z","bspReconciled":false,"complete":true,"inPlay":false,"crossMatching":true,"runnersVoidable":false,"numberOfActiveRunners":2,"betDelay":0,"status":"OPEN","runners":[{"status":"ACTIVE","sortPriority":1,"id":2284304,"name":"Sergiy Stakhovsky"},{"status":"ACTIVE","sortPriority":2,"id":7797764,"name":"Alexey Vatutin"}],"regulators":["MR_INT"],"countryCode":"FR","discountAllowed":true,"timezone":"UTC","openDate":"2020-02-02T12:16:00.000Z","version":3148684859,"name":"Set 2 Winner","eventName":"Stakhovsky v Vatutin"},"rc":[{"batb":[[0,2.1,1.2],[1,1.01,16.01],[2,1.01,0]],"ltp":0.0,"tv":0.0,"id":7797764},{"batb":[[1,1.01,16.01],[2,1.78,0]],"ltp":0.0,"tv":0.0,"id":2284304}]}]}
{"op":"mcm","clk":"1002787441","pt":1580646527557,"mc":[{"id":"1.168224581","marketDefinition":{"bspMarket":false,"turnInPlayEnabled":true,"persistenceEnabled":true,"marketBaseRate":5.0,"eventId":"29681732","eventTypeId":"2","numberOfWinners":1,"bettingType":"ODDS","marketType":"SET_WINNER","marketTime":"2020-02-02T12:16:00.000Z","suspendTime":"2020-02-02T12:16:00.000Z","bspReconciled":false,"complete":true,"inPlay":true,"crossMatching":true,"runnersVoidable":false,"numberOfActiveRunners":2,"betDelay":3,"status":"OPEN","runners":[{"status":"ACTIVE","sortPriority":1,"id":2284304,"name":"Sergiy Stakhovsky"},{"status":"ACTIVE","sortPriority":2,"id":7797764,"name":"Alexey Vatutin"}],"regulators":["MR_INT"],"countryCode":"FR","discountAllowed":true,"timezone":"UTC","openDate":"2020-02-02T12:16:00.000Z","version":3148715119,"name":"Set 2 Winner","eventName":"Stakhovsky v Vatutin"},"rc":[{"batb":[[0,1.01,15.51],[1,1.01,0]],"ltp":0.0,"tv":0.0,"id":7797764},{"batb":[[0,1.01,15.51],[1,1.01,0]],"ltp":0.0,"tv":0.0,"id":2284304}]}]}
{"op":"mcm","clk":"1002789899","pt":1580646541457,"mc":[{"id":"1.168224581","rc":[{"batb":[[0,2.04,26.04],[1,2.02,27.15],[2,1.01,15.51]],"ltp":0.0,"tv":0.0,"id":7797764},{"batb":[[0,1.83,18.57],[1,1.79,20.14],[2,1.01,15.51]],"ltp":0.0,"tv":0.0,"id":2284304}]}]}
{"op":"mcm","clk":"1002790053","pt":1580646542340,"mc":[{"id":"1.168224581","rc":[{"batb":[[1,2.02,68.31]],"ltp":0.0,"tv":0.0,"id":7797764},{"batl":[[0,1.98,42.01]],"ltp":0.0,"tv":0.0,"id":2284304}]}]}
{"op":"mcm","clk":"1002790393","pt":1580646544277,"mc":[{"id":"1.168224581","rc":[{"batl":[[0,2.26,32.77]],"ltp":0.0,"tv":0.0,"id":7797764},{"batb":[[1,1.79,73.07]],"ltp":0.0,"tv":0.0,"id":2284304}]}]}
{"op":"mcm","clk":"1002792696","pt":1580646557291,"mc":[{"id":"1.168224581","rc":[{"batb":[[0,2.02,27.15],[1,1.01,15.51],[2,1.01,0]],"ltp":0.0,"tv":0.0,"id":7797764},{"batb":[[0,1.79,20.14],[1,1.01,15.51],[2,1.01,0]],"ltp":0.0,"tv":0.0,"id":2284304}]}]}
{"op":"mcm","clk":"1002795295","pt":1580646573256,"mc":[{"id":"1.168224581","rc":[{"batb":[[1,1.99,28.56],[2,1.01,15.51]],"ltp":0.0,"tv":0.0,"id":7797764},{"batb":[[0,1.85,17.86],[1,1.82,19.12],[2,1.01,15.51]],"ltp":0.0,"tv":0.0,"id":2284304}]}]}
{"op":"mcm","clk":"1002795441","pt":1580646574005,"mc":[{"id":"1.168224581","rc":[{"batb":[[1,1.99,70.57]],"batl":[[0,2.24,33.61]],"ltp":0.0,"tv":0.0,"id":7797764},{"batb":[[2,1.81,51.25]],"batl":[[0,2,42.01]],"ltp":0.0,"tv":0.0,"id":2284304}]}]}
{"op":"mcm","clk":"1002797689","pt":1580646589026,"mc":[{"id":"1.168224581","rc":[{"batb":[[0,1.99,28.56],[1,1.01,15.51],[2,1.01,0]],"ltp":0.0,"tv":0.0,"id":7797764},{"batb":[[0,1.82,19.12],[1,1.01,15.51],[2,1.81,0]],"ltp":0.0,"tv":0.0,"id":2284304}]}]}
{"op":"mcm","clk":"1002803962","pt":1580646625488,"mc":[{"id":"1.168224581","rc":[{"batb":[[0,2.08,25.26],[1,2.04,26.59],[2,1.99,28.56]],"ltp":0.0,"tv":0.0,"id":7797764},{"batb":[[1,1.78,20.46],[2,1.01,15.51]],"ltp":0.0,"tv":0.0,"id":2284304}]}]}
{"op":"mcm","clk":"1002804083","pt":1580646626083,"mc":[{"id":"1.168224581","rc":[{"batb":[[1,2.04,66.92],[2,1.01,15.51]],"batl":[[0,2.28,32.77]],"ltp":0.0,"tv":0.0,"id":7797764},{"batb":[[1,1.78,74.23]],"batl":[[0,1.97,42.01]],"ltp":0.0,"tv":0.0,"id":2284304}]}]}
{"op":"mcm","clk":"1002807527","pt":1580646645631,"mc":[{"id":"1.168224581","rc":[{"batb":[[1,2.04,26.59]],"ltp":0.0,"tv":0.0,"id":7797764},{"batb":[[1,1.78,20.46]],"ltp":0.0,"tv":0.0,"id":2284304}]}]}
{"op":"mcm","clk":"1002807916","pt":1580646647921,"mc":[{"id":"1.168224581","rc":[{"batb":[[0,2.04,26.59],[1,1.01,15.51],[2,1.01,0]],"ltp":0.0,"tv":0.0,"id":7797764},{"batb":[[0,1.78,20.46],[1,1.01,15.51],[2,1.01,0]],"ltp":0.0,"tv":0.0,"id":2284304}]}]}
{"op":"mcm","clk":"1002808499","pt":1580646651251,"mc":[{"id":"1.168224581","rc":[{"batb":[[0,2.02,27.07]],"ltp":0.0,"tv":0.0,"id":7797764},{"batb":[[0,1.79,20.14]],"ltp":0.0,"tv":0.0,"id":2284304}]}]}
{"op":"mcm","clk":"1002813002","pt":1580646677393,"mc":[{"id":"1.168224581","rc":[{"batb":[[1,1.99,28.8],[2,1.01,15.51]],"ltp":0.0,"tv":0.0,"id":7797764},{"batb":[[0,1.85,17.86],[1,1.82,18.96],[2,1.01,15.51]],"ltp":0.0,"tv":0.0,"id":2284304}]}]}
{"op":"mcm","clk":"1002813127","pt":1580646678089,"mc":[{"id":"1.168224581","rc":[{"batb":[[1,2,42.01],[2,1.99,28.8]],"batl":[[0,2.24,33.61]],"ltp":0.0,"tv":0.0,"id":7797764},{"batb":[[1,1.82,69.37]],"batl":[[0,2.02,41.17]],"ltp":0.0,"tv":0.0,"id":2284304}]}]}
{"op":"mcm","clk":"1002815659","pt":1580646692295,"mc":[{"id":"1.168224581","rc":[{"batb":[[0,2,42.01],[1,1.99,28.8],[2,1.01,15.51]],"ltp":0.0,"tv":0.0,"id":7797764},{"batb":[[0,1.82,69.37],[1,1.01,15.51],[2,1.01,0]],"ltp":0.0,"tv":0.0,"id":2284304}]}]}
{"op":"mcm","clk":"1002815835","pt":1580646693191,"mc":[{"id":"1.168224581","rc":[{"batb":[[0,1.99,28.8],[1,1.01,15.51],[2,1.01,0]],"ltp":0.0,"tv":0.0,"id":7797764},{"batb":[[0,1.82,18.96]],"ltp":0.0,"tv":0.0,"id":2284304}]}]}
{"op":"mcm","clk":"1002816141","pt":1580646694983,"mc":[{"id":"1.168224581","rc":[{"batb":[[0,1.99,28.48]],"ltp":0.0,"tv":0.0,"id":7797764},{"batb":[[0,1.81,19.2]],"ltp":0.0,"tv":0.0,"id":2284304}]}]}
{"op":"mcm","clk":"1002817407","pt":1580646702314,"mc":[{"id":"1.168224581","rc":[{"batb":[[1,1.96,43.69],[2,1.94,30.76]],"batl":[[0,2.18,35.29]],"ltp":0.0,"tv":0.0,"id":7797764},{"batb":[[0,1.88,17],[1,1.86,48.73],[2,1.85,18.1]],"batl":[[0,2.06,39.49]],"ltp":0.0,"tv":0.0,"id":2284304}]}]}
{"op":"mcm","clk":"1002821649","pt":1580646725000,"mc":[{"id":"1.168224581","rc":[{"batl":[[1,2.6,257.57]],"ltp":0.0,"tv":0.0,"id":7797764},{"batl":[[1,2.6,257.57]],"ltp":0.0,"tv":0.0,"id":2284304}]}]}
{"op":"mcm","clk":"1002826271","pt":1580646749267,"mc":[{"id":"1.168224581","rc":[{"batb":[[0,1.94,30.76],[1,1.01,15.51],[2,1.94,0]],"batl":[[0,2.6,257.57],[1,2.6,0]],"ltp":0.0,"tv":0.0,"id":7797764},{"batb":[[0,1.85,18.1],[1,1.01,15.51],[2,1.85,0]],"batl":[[0,2.6,257.57],[1,2.6,0]],"ltp":0.0,"tv":0.0,"id":2284304}]}]}
{"op":"mcm","clk":"1002826673","pt":1580646751450,"mc":[{"id":"1.168224581","rc":[{"batb":[[0,1.96,30.21],[1,1.94,30.76],[2,1.01,15.51]],"ltp":0.0,"tv":0.0,"id":7797764},{"batb":[[1,1.84,18.41],[2,1.01,15.51]],"ltp":0.0,"tv":0.0,"id":2284304}]}]}
{"op":"mcm","clk":"1002826870","pt":1580646752363,"mc":[{"id":"1.168224581","rc":[{"batb":[[1,1.01,15.51],[2,1.01,0]],"ltp":0.0,"tv":0.0,"id":7797764},{"batb":[[0,1.84,18.41],[1,1.01,15.51],[2,1.01,0]],"ltp":0.0,"tv":0.0,"id":2284304}]}]}
{"op":"mcm","clk":"1002827717","pt":1580646756491,"mc":[{"id":"1.168224581","rc":[{"batb":[[1,1.9,16.44],[2,1.01,15.51]],"ltp":0.0,"tv":0.0,"id":7797764},{"batb":[[0,1.92,16.05],[1,1.89,47.05],[2,1.88,17.15]],"batl":[[0,2.1,37.81],[1,2.6,257.57]],"ltp":0.0,"tv":0.0,"id":2284304}]}]}
{"op":"mcm","clk":"1002828151","pt":1580646758464,"mc":[{"id":"1.168224581","rc":[{"batb":[[1,1.92,45.37],[2,1.9,16.44]],"ltp":0.0,"tv":0.0,"id":7797764}]}]}
{"op":"mcm","clk":"1002828328","pt":1580646759372,"mc":[{"id":"1.168224581","rc":[{"batl":[[0,2.12,36.97],[1,2.6,257.57]],"ltp":0.0,"tv":0.0,"id":7797764}]}]}
{"op":"mcm","clk":"1002830422","pt":1580646769770,"mc":[{"id":"1.168224581","rc":[{"batb":[[0,1.92,45.37],[1,1.9,16.44],[2,1.01,15.51]],"ltp":0.0,"tv":0.0,"id":7797764},{"batb":[[0,1.89,47.05],[1,1.88,17.15],[2,1.01,15.51]],"ltp":0.0,"tv":0.0,"id":2284304}]}]}
{"op":"mcm","clk":"1002830723","pt":1580646771229,"mc":[{"id":"1.168224581","rc":[{"batb":[[0,1.9,16.44],[1,1.01,15.51],[2,1.01,0]],"batl":[[0,2.6,257.57],[1,2.6,0]],"ltp":0.0,"tv":0.0,"id":7797764},{"batb":[[0,1.88,17.15],[1,1.01,15.51],[2,1.01,0]],"batl":[[0,2.6,257.57],[1,2.6,0]],"ltp":0.0,"tv":0.0,"id":2284304}]}]}
{"op":"mcm","clk":"1002831907","pt":1580646777408,"mc":[{"id":"1.168224581","rc":[{"batb":[[1,1.85,17.86],[2,1.01,15.51]],"ltp":0.0,"tv":0.0,"id":7797764},{"batb":[[0,1.97,29.58],[1,1.93,15.66],[2,1.01,15.51]],"ltp":0.0,"tv":0.0,"id":2284304}]}]}
{"op":"mcm","clk":"1002832079","pt":1580646778319,"mc":[{"id":"1.168224581","rc":[{"batb":[[1,1.88,47.05],[2,1.85,17.86]],"batl":[[0,2.08,38.65],[1,2.4,289.78]],"ltp":0.0,"tv":0.0,"id":7797764},{"batb":[[1,1.94,44.53],[2,1.93,15.66]],"batl":[[0,2.16,36.13],[1,2.6,257.57]],"ltp":0.0,"tv":0.0,"id":2284304}]}]}
{"op":"mcm","clk":"1002834251","pt":1580646789545,"mc":[{"id":"1.168224581","rc":[{"batb":[[0,1.88,47.05],[1,1.85,17.86],[2,1.01,15.51]],"ltp":0.0,"tv":0.0,"id":7797764},{"batb":[[0,1.94,44.53],[1,1.93,15.66],[2,1.01,15.51]],"ltp":0.0,"tv":0.0,"id":2284304}]}]}
{"op":"mcm","clk":"1002834577","pt":1580646791250,"mc":[{"id":"1.168224581","rc":[{"batb":[[0,1.85,17.86],[1,1.01,15.51],[2,1.01,0]],"batl":[[0,2.4,289.78],[1,2.4,0]],"ltp":0.0,"tv":0.0,"id":7797764},{"batb":[[0,1.93,15.66],[1,1.01,15.51],[2,1.01,0]],"batl":[[0,2.6,257.57],[1,2.6,0]],"ltp":0.0,"tv":0.0,"id":2284304}]}]}
{"op":"mcm","clk":"1002835841","pt":1580646797452,"mc":[{"id":"1.168224581","rc":[{"batb":[[1,1.8,19.67],[2,1.01,15.51]],"ltp":0.0,"tv":0.0,"id":7797764},{"batb":[[0,2.02,27.15],[1,1.98,29.03],[2,1.01,15.51]],"ltp":0.0,"tv":0.0,"id":2284304}]}]}
{"op":"mcm","clk":"1002836038","pt":1580646798462,"mc":[{"id":"1.168224581","rc":[{"batb":[[0,1.85,66.59]],"batl":[[0,2.04,40.33]],"ltp":0.0,"tv":0.0,"id":7797764},{"batb":[[1,1.98,71.88]],"batl":[[0,2.2,34.45]],"ltp":0.0,"tv":0.0,"id":2284304}]}]}
{"op":"mcm","clk":"1002836242","pt":1580646799457,"mc":[{"id":"1.168224581","rc":[{"batb":[[0,1.85,17.86]],"batl":[[1,2.3,309.75]],"ltp":0.0,"tv":0.0,"id":7797764},{"batl":[[1,3,213.45]],"ltp":0.0,"tv":0.0,"id":2284304}]}]}
{"op":"mcm","clk":"1002836404","pt":1580646800245,"mc":[{"id":"1.168224581","rc":[{"batb":[[1,1.83,50.41],[2,1.8,19.67]],"ltp":0.0,"tv":0.0,"id":7797764}]}]}
{"op":"mcm","clk":"1002838180","pt":1580646809457,"mc":[{"id":"1.168224581","rc":[{"batb":[[0,1.8,19.67],[1,1.01,15.51],[2,1.8,0]],"batl":[[0,2.3,309.75],[1,2.3,0]],"ltp":0.0,"tv":0.0,"id":7797764},{"batb":[[0,1.98,29.03],[1,1.01,15.51],[2,1.01,0]],"batl":[[0,3,213.45],[1,3,0]],"ltp":0.0,"tv":0.0,"id":2284304}]}]}
{"op":"mcm","clk":"1002838636","pt":1580646811830,"mc":[{"id":"1.168224581","rc":[{"batb":[[0,1.79,19.91]],"ltp":0.0,"tv":0.0,"id":7797764},{"batb":[[0,1.99,28.64]],"ltp":0.0,"tv":0.0,"id":2284304}]}]}
{"op":"mcm","clk":"1002840239","pt":1580646820420,"mc":[{"id":"1.168224581","rc":[{"batb":[[1,1.75,55.45],[2,1.01,15.51]],"batl":[[0,1.93,42.01],[1,2.3,309.75]],"ltp":0.0,"tv":0.0,"id":7797764},{"batb":[[0,2.08,38.65],[1,1.99,28.64],[2,1.01,15.51]],"batl":[[0,2.34,31.09],[1,3,213.45]],"ltp":0.0,"tv":0.0,"id":2284304}]}]}
{"op":"mcm","clk":"1002840420","pt":1580646821477,"mc":[{"id":"1.168224581","rc":[{"batb":[[1,1.77,20.93],[2,1.75,55.45]],"ltp":0.0,"tv":0.0,"id":7797764},{"batb":[[0,2.1,24.16],[1,2.08,38.65],[2,2.02,26.83]],"ltp":0.0,"tv":0.0,"id":2284304}]}]}
{"op":"mcm","clk":"1002844499","pt":1580646842252,"mc":[{"id":"1.168224581","rc":[{"batb":[[0,1.77,20.93],[1,1.75,55.45],[2,1.01,15.51]],"ltp":0.0,"tv":0.0,"id":7797764},{"batb":[[0,2.08,38.65],[1,2.02,26.83],[2,1.01,15.51]],"ltp":0.0,"tv":0.0,"id":2284304}]}]}
{"op":"mcm","clk":"1002844688","pt":1580646843309,"mc":[{"id":"1.168224581","rc":[{"batb":[[1,1.01,15.51],[2,1.01,0]],"batl":[[0,2.3,309.75],[1,2.3,0]],"ltp":0.0,"tv":0.0,"id":7797764},{"batb":[[0,2.02,26.83],[1,1.01,15.51],[2,1.01,0]],"batl":[[0,3,213.45],[1,3,0]],"ltp":0.0,"tv":0.0,"id":2284304}]}]}
{"op":"mcm","clk":"1002845066","pt":1580646845306,"mc":[{"id":"1.168224581","rc":[{"batb":[[1,1.76,20.93],[2,1.01,15.51]],"ltp":0.0,"tv":0.0,"id":7797764},{"batb":[[0,2.04,26.83],[1,2.02,26.83],[2,1.01,15.51]],"ltp":0.0,"tv":0.0,"id":2284304}]}]}
{"op":"mcm","clk":"1002845151","pt":1580646845689,"mc":[{"id":"1.168224581","rc":[{"batb":[[0,1.76,20.93],[1,1.01,15.51],[2,1.01,0]],"ltp":0.0,"tv":0.0,"id":7797764},{"batb":[[1,1.01,15.51],[2,1.01,0]],"ltp":0.0,"tv":0.0,"id":2284304}]}]}
{"op":"mcm","clk":"1002845834","pt":1580646849404,"mc":[{"id":"1.168224581","rc":[{"batb":[[0,1.84,18.41],[1,1.8,19.59],[2,1.01,15.51]],"ltp":0.0,"tv":0.0,"id":7797764},{"batb":[[0,2.04,26.28],[1,1.99,28.64],[2,1.01,15.51]],"ltp":0.0,"tv":0.0,"id":2284304}]}]}
{"op":"mcm","clk":"1002846011","pt":1580646850296,"mc":[{"id":"1.168224581","rc":[{"batb":[[2,1.79,52.93]],"batl":[[0,1.97,42.01],[1,2.3,309.75]],"ltp":0.0,"tv":0.0,"id":7797764},{"batb":[[0,2.04,66.61]],"batl":[[0,2.28,32.77],[1,3,213.45]],"ltp":0.0,"tv":0.0,"id":2284304}]}]}
{"op":"mcm","clk":"1002847750","pt":1580646859343,"mc":[{"id":"1.168224581","rc":[{"batb":[[0,1.8,19.59],[1,1.01,15.51],[2,1.79,0]],"batl":[[0,2.3,309.75],[1,2.3,0]],"ltp":0.0,"tv":0.0,"id":7797764},{"batb":[[0,1.99,28.64],[1,1.01,15.51],[2,1.01,0]],"batl":[[0,3,213.45],[1,3,0]],"ltp":0.0,"tv":0.0,"id":2284304}]}]}
{"op":"mcm","clk":"1002851401","pt":1580646877382,"mc":[{"id":"1.168224581","rc":[{"batb":[[0,1.89,16.92],[1,1.85,18.02],[2,1.81,142.29]],"ltp":0.0,"tv":0.0,"id":7797764},{"batb":[[1,1.94,15.58],[2,1.01,15.51]],"ltp":0.0,"tv":0.0,"id":2284304}]}]}
{"op":"mcm","clk":"1002851561","pt":1580646878282,"mc":[{"id":"1.168224581","rc":[{"batb":[[2,1.83,50.41]],"batl":[[0,2.02,41.17],[1,2.3,309.75]],"ltp":0.0,"tv":0.0,"id":7797764},{"batb":[[1,1.98,42.85],[2,1.94,15.58]],"batl":[[0,2.22,33.61]],"ltp":0.0,"tv":0.0,"id":2284304}]}]}
{"op":"mcm","clk":"1002851876","pt":1580646879771,"mc":[{"id":"1.168224581","rc":[{"batl":[[1,2.84,228.62]],"ltp":0.0,"tv":0.0,"id":2284304}]}]}
{"op":"mcm","clk":"1002855370","pt":1580646897412,"mc":[{"id":"1.168224581","rc":[{"batb":[[0,1.85,18.02],[1,1.01,15.51],[2,1.83,0]],"batl":[[0,2.3,309.75],[1,2.3,0]],"ltp":0.0,"tv":0.0,"id":7797764},{"batb":[[0,1.94,15.58],[1,1.01,15.51],[2,1.94,0]],"batl":[[0,2.84,228.62],[1,2.84,0]],"ltp":0.0,"tv":0.0,"id":2284304}]}]}
{"op":"mcm","clk":"1002858371","pt":1580646912464,"mc":[{"id":"1.168224581","rc":[{"batb":[[0,1.86,48.73],[1,1.85,18.02],[2,1.01,15.51]],"batl":[[0,2.06,39.49],[1,2.3,309.75]],"ltp":0.0,"tv":0.0,"id":7797764},{"batb":[[0,1.94,60.11]],"batl":[[0,2.18,35.29]],"ltp":0.0,"tv":0.0,"id":2284304}]}]}
{"op":"mcm","clk":"1002858536","pt":1580646913364,"mc":[{"id":"1.168224581","rc":[{"batb":[[0,1.93,15.58],[1,1.9,16.44],[2,1.86,48.73]],"ltp":0.0,"tv":0.0,"id":7797764},{"batb":[[1,1.89,16.92],[2,1.01,15.51]],"batl":[[0,2.16,36.13]],"ltp":0.0,"tv":0.0,"id":2284304}]}]}
{"op":"mcm","clk":"1002858651","pt":1580646913936,"mc":[{"id":"1.168224581","rc":[{"batl":[[1,2.7,245.56]],"ltp":0.0,"tv":0.0,"id":2284304}]}]}
{"op":"mcm","clk":"1002860868","pt":1580646925357,"mc":[{"id":"1.168224581","rc":[{"batb":[[0,1.9,16.44],[1,1.86,48.73],[2,1.01,15.51]],"ltp":0.0,"tv":0.0,"id":7797764},{"batb":[[0,1.94,44.53]],"ltp":0.0,"tv":0.0,"id":2284304}]}]}
{"op":"mcm","clk":"1002860920","pt":1580646925575,"mc":[{"id":"1.168224581","rc":[{"batb":[[1,1.01,15.51],[2,1.01,0]],"batl":[[0,2.3,309.75],[1,2.3,0]],"ltp":0.0,"tv":0.0,"id":7797764},{"batb":[[0,1.89,16.92],[1,1.01,15.51],[2,1.01,0]],"batl":[[0,2.7,245.56],[1,2.7,0]],"ltp":0.0,"tv":0.0,"id":2284304}]}]}
{"op":"mcm","clk":"1002864164","pt":1580646942348,"mc":[{"id":"1.168224581","rc":[{"batb":[[1,1.86,48.73],[2,1.01,15.51]],"batl":[[0,2.06,39.49],[1,2.3,309.75]],"ltp":0.0,"tv":0.0,"id":7797764},{"batb":[[0,1.94,44.53],[1,1.89,16.92],[2,1.01,15.51]],"batl":[[0,2.18,35.29],[1,2.7,245.56]],"ltp":0.0,"tv":0.0,"id":2284304}]}]}
{"op":"mcm","clk":"1002864385","pt":1580646943464,"mc":[{"id":"1.168224581","rc":[{"batb":[[1,1.87,17.47],[2,1.86,48.73]],"batl":[[0,2.3,309.75],[1,2.3,0]],"ltp":0.0,"tv":0.0,"id":7797764},{"batb":[[0,1.97,29.58],[1,1.92,16.05]],"ltp":0.0,"tv":0.0,"id":2284304}]}]}
{"op":"mcm","clk":"1002864549","pt":1580646944207,"mc":[{"id":"1.168224581","rc":[{"batl":[[0,2.04,40.33],[1,2.3,309.75]],"ltp":0.0,"tv":0.0,"id":7797764},{"batb":[[1,1.95,43.69],[2,1.92,16.05]],"ltp":0.0,"tv":0.0,"id":2284304}]}]}
{"op":"mcm","clk":"1002867170","pt":1580646957361,"mc":[{"id":"1.168224581","rc":[{"batb":[[0,1.87,17.47],[1,1.01,15.51],[2,1.86,0]],"batl":[[0,2.3,309.75],[1,2.3,0]],"ltp":0.0,"tv":0.0,"id":7797764},{"batb":[[0,1.92,16.05],[1,1.01,15.51],[2,1.92,0]],"batl":[[0,2.7,245.56],[1,2.7,0]],"ltp":0.0,"tv":0.0,"id":2284304}]}]}
{"op":"mcm","clk":"1002870845","pt":1580646976414,"mc":[{"id":"1.168224581","rc":[{"batb":[[0,1.96,30.21],[1,1.95,43.69],[2,1.91,16.21]],"batl":[[0,2.2,34.45],[1,2.3,309.75]],"ltp":0.0,"tv":0.0,"id":7797764},{"batb":[[1,1.88,17.15],[2,1.85,48.73]],"batl":[[0,2.04,40.33],[1,2.7,245.56]],"ltp":0.0,"tv":0.0,"id":2284304}]}]}
{"op":"mcm","clk":"1002870988","pt":1580646977090,"mc":[{"id":"1.168224581","rc":[{"batb":[[1,1.91,16.21],[2,1.01,15.51]],"ltp":0.0,"tv":0.0,"id":7797764}]}]}
{"op":"mcm","clk":"1002871248","pt":1580646978408,"mc":[{"id":"1.168224581","rc":[{"batb":[[0,1.96,73.9]],"ltp":0.0,"tv":0.0,"id":7797764}]}]}
{"op":"mcm","clk":"1002872407","pt":1580646984287,"mc":[{"id":"1.168224581","rc":[{"batb":[[0,1.97,29.74],[1,1.96,43.69],[2,1.92,15.97]],"batl":[[0,2.3,309.75],[1,2.3,0]],"ltp":0.0,"tv":0.0,"id":7797764},{"batb":[[0,1.91,16.29],[1,1.87,17.39]],"ltp":0.0,"tv":0.0,"id":2284304}]}]}
{"op":"mcm","clk":"1002872992","pt":1580646987215,"mc":[{"id":"1.168224581","rc":[{"batl":[[0,2.18,35.29],[1,2.3,309.75]],"ltp":0.0,"tv":0.0,"id":7797764}]}]}
{"op":"mcm","clk":"1002873914","pt":1580646991941,"mc":[{"id":"1.168224581","rc":[{"batb":[[0,1.98,29.03],[2,1.94,15.58]],"ltp":0.0,"tv":0.0,"id":7797764},{"batb":[[0,1.89,16.68],[1,1.86,17.78]],"ltp":0.0,"tv":0.0,"id":2284304}]}]}
{"op":"mcm","clk":"1002882573","pt":1580647035404,"mc":[{"id":"1.168224581","rc":[{"batb":[[0,1.99,28.56],[2,1.94,15.42]],"ltp":0.0,"tv":0.0,"id":7797764},{"batb":[[0,1.88,17],[1,1.85,66.75],[2,1.01,15.51]],"ltp":0.0,"tv":0.0,"id":2284304}]}]}
{"op":"mcm","clk":"1002888068","pt":1580647061448,"mc":[{"id":"1.168224581","rc":[{"batb":[[1,1.94,15.42],[2,1.01,15.51]],"batl":[[0,2.3,309.75],[1,2.3,0]],"ltp":0.0,"tv":0.0,"id":7797764},{"batb":[[1,1.85,18.02]],"batl":[[0,2.7,245.56],[1,2.7,0]],"ltp":0.0,"tv":0.0,"id":2284304}]}]}
{"op":"mcm","clk":"1002888086","pt":1580647061553,"mc":[{"id":"1.168224581","rc":[{"batb":[[0,1.94,15.42],[1,1.01,15.51],[2,1.01,0]],"ltp":0.0,"tv":0.0,"id":7797764},{"batb":[[0,1.85,18.02],[1,1.01,15.51],[2,1.01,0]],"ltp":0.0,"tv":0.0,"id":2284304}]}]}
{"op":"mcm","clk":"1002892678","pt":1580647083408,"mc":[{"id":"1.168224581","rc":[{"batb":[[0,2.02,26.83],[1,1.99,28.88],[2,1.94,148.01]],"ltp":0.0,"tv":0.0,"id":7797764},{"batb":[[1,1.82,19.04],[2,1.01,15.51]],"ltp":0.0,"tv":0.0,"id":2284304}]}]}
{"op":"mcm","clk":"1002892879","pt":1580647084374,"mc":[{"id":"1.168224581","rc":[{"batb":[[2,1.98,42.85]],"batl":[[0,2.2,34.45]],"ltp":0.0,"tv":0.0,"id":7797764},{"batb":[[1,1.84,49.57],[2,1.82,19.04]],"batl":[[0,2.02,41.17],[1,2.7,245.56]],"ltp":0.0,"tv":0.0,"id":2284304}]}]}
{"op":"mcm","clk":"1002892984","pt":1580647084883,"mc":[{"id":"1.168224581","rc":[{"batl":[[1,2.6,257.57]],"ltp":0.0,"tv":0.0,"id":7797764}]}]}
{"op":"mcm","clk":"1002895990","pt":1580647099424,"mc":[{"id":"1.168224581","rc":[{"batb":[[0,1.99,28.88],[1,1.01,15.51],[2,1.98,0]],"batl":[[0,2.6,257.57],[1,2.6,0]],"ltp":0.0,"tv":0.0,"id":7797764},{"batb":[[0,1.82,19.04],[1,1.01,15.51],[2,1.82,0]],"batl":[[0,2.7,245.56],[1,2.7,0]],"ltp":0.0,"tv":0.0,"id":2284304}]}]}
{"op":"mcm","clk":"1002896591","pt":1580647102223,"mc":[{"id":"1.168224581","rc":[{"batb":[[0,1.98,29.19]],"ltp":0.0,"tv":0.0,"id":7797764}]}]}
{"op":"mcm","clk":"1002897511","pt":1580647106454,"mc":[{"id":"1.168224581","rc":[{"batb":[[0,2.06,25.34],[1,2.02,27.54],[2,2,42.01]],"batl":[[0,2.24,33.61],[1,2.6,257.57]],"ltp":0.0,"tv":0.0,"id":7797764},{"batb":[[0,1.82,69.45],[1,1.79,19.99],[2,1.01,15.51]],"batl":[[0,2,42.01],[1,2.7,245.56]],"ltp":0.0,"tv":0.0,"id":2284304}]}]}
{"op":"mcm","clk":"1002899933","pt":1580647118223,"mc":[{"id":"1.168224581","rc":[{"batb":[[0,2.02,27.54],[1,2,42.01],[2,1.01,15.51]],"ltp":0.0,"tv":0.0,"id":7797764},{"batb":[[0,1.82,50.41]],"ltp":0.0,"tv":0.0,"id":2284304}]}]}
{"op":"mcm","clk":"1002900171","pt":1580647119411,"mc":[{"id":"1.168224581","rc":[{"batb":[[1,1.01,15.51],[2,1.01,0]],"batl":[[0,2.6,257.57],[1,2.6,0]],"ltp":0.0,"tv":0.0,"id":7797764},{"batb":[[0,1.79,19.99],[1,1.01,15.51],[2,1.01,0]],"batl":[[0,2.7,245.56],[1,2.7,0]],"ltp":0.0,"tv":0.0,"id":2284304}]}]}
{"op":"mcm","clk":"1002901396","pt":1580647125321,"mc":[{"id":"1.168224581","rc":[{"batb":[[0,2.1,24.08],[1,2.06,25.89],[2,2.02,27.54]],"ltp":0.0,"tv":0.0,"id":7797764},{"batb":[[1,1.77,20.93],[2,1.01,15.51]],"ltp":0.0,"tv":0.0,"id":2284304}]}]}
{"op":"mcm","clk":"1002901620","pt":1580647126435,"mc":[{"id":"1.168224581","rc":[{"batb":[[2,2.02,41.17]],"batl":[[0,2.26,32.77],[1,2.6,257.57]],"ltp":0.0,"tv":0.0,"id":7797764},{"batb":[[0,1.8,52.09],[1,1.79,19.99],[2,1.77,20.93]],"batl":[[0,1.99,42.01]],"ltp":0.0,"tv":0.0,"id":2284304}]}]}
{"op":"mcm","clk":"1002901785","pt":1580647127357,"mc":[{"id":"1.168224581","rc":[{"batl":[[1,2.52,270.1]],"ltp":0.0,"tv":0.0,"id":2284304}]}]}
{"op":"mcm","clk":"1002903797","pt":1580647137464,"mc":[{"id":"1.168224581","rc":[{"batb":[[0,2.06,25.89],[1,1.01,15.51],[2,2.02,0]],"batl":[[0,2.6,257.57],[1,2.6,0]],"ltp":0.0,"tv":0.0,"id":7797764},{"batb":[[0,1.77,20.93],[1,1.01,15.51],[2,1.77,0]],"batl":[[0,2.52,270.1],[1,2.52,0]],"ltp":0.0,"tv":0.0,"id":2284304}]}]}
{"op":"mcm","clk":"1002904360","pt":1580647140308,"mc":[{"id":"1.168224581","rc":[{"batb":[[0,2.04,26.28]],"ltp":0.0,"tv":0.0,"id":7797764},{"batb":[[0,1.77,20.61]],"ltp":0.0,"tv":0.0,"id":2284304}]}]}
{"op":"mcm","clk":"1002905198","pt":1580647144393,"mc":[{"id":"1.168224581","rc":[{"batb":[[0,2.12,23.29],[1,2.08,25.1],[2,1.01,15.51]],"ltp":0.0,"tv":0.0,"id":7797764},{"batb":[[1,1.73,22.35],[2,1.01,15.51]],"ltp":0.0,"tv":0.0,"id":2284304}]}]}
{"op":"mcm","clk":"1002905329","pt":1580647144933,"mc":[{"id":"1.168224581","rc":[{"batb":[[2,2.06,39.49]],"batl":[[0,2.3,31.93],[1,2.6,257.57]],"ltp":0.0,"tv":0.0,"id":7797764},{"batb":[[1,1.76,54.61],[2,1.73,22.35]],"batl":[[0,1.96,42.01],[1,2.52,270.1]],"ltp":0.0,"tv":0.0,"id":2284304}]}]}
{"op":"mcm","clk":"1002909950","pt":1580647167752,"mc":[{"id":"1.168224581","rc":[{"batb":[[0,2.08,25.1],[1,2.06,39.49],[2,1.01,15.51]],"ltp":0.0,"tv":0.0,"id":7797764},{"batb":[[0,1.76,54.61],[1,1.73,22.35],[2,1.01,15.51]],"ltp":0.0,"tv":0.0,"id":2284304}]}]}
{"op":"mcm","clk":"1002910309","pt":1580647169454,"mc":[{"id":"1.168224581","rc":[{"batb":[[1,1.01,15.51],[2,1.01,0]],"batl":[[0,2.6,257.57],[1,2.6,0]],"ltp":0.0,"tv":0.0,"id":7797764},{"batb":[[0,1.73,22.35],[1,1.01,15.51],[2,1.01,0]],"batl":[[0,2.52,270.1],[1,2.52,0]],"ltp":0.0,"tv":0.0,"id":2284304}]}]}
{"op":"mcm","clk":"1002910716","pt":1580647171458,"mc":[{"id":"1.168224581","rc":[{"batb":[[0,2.06,25.49]],"ltp":0.0,"tv":0.0,"id":7797764},{"batb":[[0,1.74,22.03]],"ltp":0.0,"tv":0.0,"id":2284304}]}]}
{"op":"mcm","clk":"1002913947","pt":1580647186474,"mc":[{"id":"1.168224581","rc":[{"batb":[[1,2.04,40.33],[2,1.01,15.51]],"batl":[[0,2.28,32.77],[1,2.6,257.57]],"ltp":0.0,"tv":0.0,"id":7797764},{"batb":[[0,1.78,53.77],[1,1.74,22.03],[2,1.01,15.51]],"batl":[[0,1.98,42.01],[1,2.52,270.1]],"ltp":0.0,"tv":0.0,"id":2284304}]}]}
{"op":"mcm","clk":"1002914034","pt":1580647186846,"mc":[{"id":"1.168224581","rc":[{"batb":[[2,2.02,26.83]],"ltp":0.0,"tv":0.0,"id":7797764},{"batb":[[0,1.82,18.96],[1,1.78,53.77],[2,1.77,20.54]],"ltp":0.0,"tv":0.0,"id":2284304}]}]}
{"op":"mcm","clk":"1002917916","pt":1580647205233,"mc":[{"id":"1.168224581","rc":[{"batb":[[0,2.04,40.33],[1,2.02,26.83],[2,1.01,15.51]],"ltp":0.0,"tv":0.0,"id":7797764},{"batb":[[0,1.78,53.77],[1,1.77,20.54],[2,1.01,15.51]],"ltp":0.0,"tv":0.0,"id":2284304}]}]}
{"op":"mcm","clk":"1002917978","pt":1580647205560,"mc":[{"id":"1.168224581","rc":[{"batb":[[0,2.02,26.83],[1,1.01,15.51],[2,1.01,0]],"batl":[[0,2.6,257.57],[1,2.6,0]],"ltp":0.0,"tv":0.0,"id":7797764},{"batb":[[0,1.77,20.54],[1,1.01,15.51],[2,1.01,0]],"batl":[[0,2.52,270.1],[1,2.52,0]],"ltp":0.0,"tv":0.0,"id":2284304}]}]}
{"op":"mcm","clk":"1002920235","pt":1580647216400,"mc":[{"id":"1.168224581","rc":[{"batb":[[0,2.12,23.37],[1,2.08,25.02],[2,2.02,132.41]],"ltp":0.0,"tv":0.0,"id":7797764},{"batb":[[1,1.72,22.66],[2,1.01,15.51]],"ltp":0.0,"tv":0.0,"id":2284304}]}]}
{"op":"mcm","clk":"1002920396","pt":1580647217201,"mc":[{"id":"1.168224581","rc":[{"batb":[[1,2.08,63.67],[2,1.01,15.51]],"batl":[[0,2.32,31.09],[1,2.6,257.57]],"ltp":0.0,"tv":0.0,"id":7797764},{"batb":[[1,1.76,54.61],[2,1.72,22.66]],"batl":[[0,1.94,42.01],[1,2.4,289.78]],"ltp":0.0,"tv":0.0,"id":2284304}]}]}
{"op":"mcm","clk":"1002922332","pt":1580647226073,"mc":[{"id":"1.168224581","rc":[{"batb":[[0,2.08,63.67],[1,1.01,15.51],[2,1.01,0]],"ltp":0.0,"tv":0.0,"id":7797764},{"batb":[[0,1.76,54.61],[1,1.72,22.66],[2,1.01,15.51]],"ltp":0.0,"tv":0.0,"id":2284304}]}]}
{"op":"mcm","clk":"1002922636","pt":1580647227645,"mc":[{"id":"1.168224581","rc":[{"batb":[[0,2.08,25.02]],"batl":[[0,2.6,257.57],[1,2.6,0]],"ltp":0.0,"tv":0.0,"id":7797764},{"batb":[[0,1.72,22.66],[1,1.01,15.51],[2,1.01,0]],"batl":[[0,2.4,289.78],[1,2.4,0]],"ltp":0.0,"tv":0.0,"id":2284304}]}]}
{"op":"mcm","clk":"1002923669","pt":1580647232472,"mc":[{"id":"1.168224581","rc":[{"batb":[[0,2.12,36.97],[1,2.08,25.02],[2,1.01,15.51]],"batl":[[0,2.38,30.25],[1,2.6,257.57]],"ltp":0.0,"tv":0.0,"id":7797764},{"batb":[[0,1.73,57.13],[1,1.72,22.66],[2,1.01,15.51]],"batl":[[0,1.91,42.01],[1,2.4,289.78]],"ltp":0.0,"tv":0.0,"id":2284304}]}]}
{"op":"mcm","clk":"1002923858","pt":1580647233293,"mc":[{"id":"1.168224581","rc":[{"batb":[[0,2.2,21.09],[1,2.14,22.82],[2,2.12,36.97]],"ltp":0.0,"tv":0.0,"id":7797764},{"batb":[[2,1.68,24.94]],"batl":[[0,2.4,289.78],[1,2.4,0]],"ltp":0.0,"tv":0.0,"id":2284304}]}]}
{"op":"mcm","clk":"1002924090","pt":1580647234411,"mc":[{"id":"1.168224581","rc":[{"batl":[[0,1.9,42.01],[1,2.4,289.78]],"ltp":0.0,"tv":0.0,"id":2284304}]}]}
{"op":"mcm","clk":"1002926647","pt":1580647246445,"mc":[{"id":"1.168224581","rc":[{"batb":[[0,2.14,22.82],[1,2.12,36.97],[2,1.01,15.51]],"ltp":0.0,"tv":0.0,"id":7797764},{"batb":[[1,1.68,24.94],[2,1.01,15.51]],"ltp":0.0,"tv":0.0,"id":2284304}]}]}
{"op":"mcm","clk":"1002926882","pt":1580647247506,"mc":[{"id":"1.168224581","rc":[{"batb":[[1,1.01,15.51],[2,1.01,0]],"batl":[[0,2.6,257.57],[1,2.6,0]],"ltp":0.0,"tv":0.0,"id":7797764},{"batb":[[0,1.68,24.94],[1,1.01,15.51],[2,1.01,0]],"batl":[[0,2.4,289.78],[1,2.4,0]],"ltp":0.0,"tv":0.0,"id":2284304}]}]}
{"op":"mcm","clk":"1002928419","pt":1580647254402,"mc":[{"id":"1.168224581","rc":[{"batb":[[0,2.28,18.96],[1,2.22,20.77],[2,1.01,15.51]],"ltp":0.0,"tv":0.0,"id":7797764},{"batb":[[1,1.63,27.62],[2,1.01,15.51]],"ltp":0.0,"tv":0.0,"id":2284304}]}]}
{"op":"mcm","clk":"1002928458","pt":1580647254617,"mc":[{"id":"1.168224581","rc":[{"batb":[[2,2.16,36.13]],"batl":[[0,2.44,28.57]],"ltp":0.0,"tv":0.0,"id":7797764},{"batb":[[0,1.7,59.65],[1,1.68,24.94],[2,1.63,27.62]],"batl":[[0,1.87,42.01]],"ltp":0.0,"tv":0.0,"id":2284304}]}]}
{"op":"mcm","clk":"1002928772","pt":1580647256123,"mc":[{"id":"1.168224581","rc":[{"batl":[[1,3,213.45]],"ltp":0.0,"tv":0.0,"id":7797764},{"batl":[[1,2.3,309.75]],"ltp":0.0,"tv":0.0,"id":2284304}]}]}
{"op":"mcm","clk":"1002930317","pt":1580647263441,"mc":[{"id":"1.168224581","rc":[{"batb":[[0,2.22,20.77],[1,2.16,36.13],[2,1.01,15.51]],"ltp":0.0,"tv":0.0,"id":7797764},{"batb":[[1,1.63,27.62],[2,1.01,15.51]],"ltp":0.0,"tv":0.0,"id":2284304}]}]}
{"op":"mcm","clk":"1002930389","pt":1580647263758,"mc":[{"id":"1.168224581","rc":[{"batb":[[1,1.01,15.51],[2,1.01,0]],"batl":[[0,3,213.45],[1,3,0]],"ltp":0.0,"tv":0.0,"id":7797764},{"batb":[[0,1.63,27.62],[1,1.01,15.51],[2,1.01,0]],"batl":[[0,2.3,309.75],[1,2.3,0]],"ltp":0.0,"tv":0.0,"id":2284304}]}]}
{"op":"mcm","clk":"1002932620","pt":1580647274456,"mc":[{"id":"1.168224581","rc":[{"batb":[[0,2.38,16.92],[1,2.3,18.73],[2,2.26,32.77]],"batl":[[0,2.58,26.05],[1,3,213.45]],"ltp":0.0,"tv":0.0,"id":7797764},{"batb":[[0,1.63,93.99],[1,1.6,29.35],[2,1.01,15.51]],"batl":[[0,1.79,42.01],[1,2.3,309.75]],"ltp":0.0,"tv":0.0,"id":2284304}]}]}
{"op":"mcm","clk":"1002934224","pt":1580647282483,"mc":[{"id":"1.168224581","rc":[{"batb":[[0,2.42,16.29],[1,2.32,18.1]],"ltp":0.0,"tv":0.0,"id":7797764},{"batb":[[0,1.63,66.38],[1,1.61,28.48],[2,1.59,30.21]],"ltp":0.0,"tv":0.0,"id":2284304}]}]}
{"op":"mcm","clk":"1002935043","pt":1580647286442,"mc":[{"id":"1.168224581","rc":[{"trd":[[2.42,20]],"batb":[[0,2.42,6.29]],"ltp":2.42,"tv":20.0,"id":7797764}],"tv":20.0}]}
{"op":"mcm","clk":"1002935199","pt":1580647287306,"mc":[{"id":"1.168224581","rc":[{"trd":[[2.42,32]],"batb":[[0,2.32,18.38],[1,2.26,32.77],[2,1.01,15.51]],"ltp":2.42,"tv":32.0,"id":7797764}],"tv":32.0}]}
{"op":"mcm","clk":"1002935416","pt":1580647288473,"mc":[{"id":"1.168224581","rc":[{"trd":[[2.42,32.58]],"batb":[[0,2.32,18.1]],"ltp":2.42,"tv":32.57,"id":7797764}],"tv":32.57}]}
{"op":"mcm","clk":"1002935759","pt":1580647290489,"mc":[{"id":"1.168224581","rc":[{"batb":[[0,2.4,16.52],[1,2.32,18.1],[2,2.26,32.77]],"batl":[[0,2.42,2],[1,2.58,26.05],[2,3,213.45]],"ltp":2.42,"tv":32.57,"id":7797764},{"batb":[[1,1.62,28.09],[2,1.61,28.48]],"ltp":0.0,"tv":0.0,"id":2284304}]}]}
{"op":"mcm","clk":"1002935855","pt":1580647290973,"mc":[{"id":"1.168224581","rc":[{"batl":[[0,2.58,26.05],[1,3,213.45],[2,3,0]],"ltp":2.42,"tv":32.57,"id":7797764},{"batb":[[2,1.59,29.82]],"ltp":0.0,"tv":0.0,"id":2284304}]}]}
{"op":"mcm","clk":"1002937293","pt":1580647298484,"mc":[{"id":"1.168224581","rc":[{"batb":[[0,1.65,28.01],[1,1.63,66.38],[2,1.62,28.09]],"ltp":0.0,"tv":0.0,"id":2284304}]}]}
{"op":"mcm","clk":"1002939021","pt":1580647306901,"mc":[{"id":"1.168224581","rc":[{"batb":[[0,1.64,28.17],[2,1.61,29.82]],"ltp":0.0,"tv":0.0,"id":2284304}]}]}
{"op":"mcm","clk":"1002943076","pt":1580647326724,"mc":[{"id":"1.168224581","rc":[{"batb":[[2,1.01,15.51]],"ltp":2.42,"tv":32.57,"id":7797764},{"batl":[[0,2.3,309.75],[1,2.3,0]],"ltp":0.0,"tv":0.0,"id":2284304}]}]}
{"op":"mcm","clk":"1002943637","pt":1580647329639,"mc":[{"id":"1.168224581","rc":[{"batb":[[2,2.3,31.93]],"ltp":2.42,"tv":32.57,"id":7797764},{"batl":[[0,1.78,42.01],[1,2.3,309.75]],"ltp":0.0,"tv":0.0,"id":2284304}]}]}
{"op":"mcm","clk":"1002944555","pt":1580647334358,"mc":[{"id":"1.168224581","rc":[{"batb":[[0,2.42,16.44]],"ltp":2.42,"tv":32.57,"id":7797764}]}]}
{"op":"mcm","clk":"1002951133","pt":1580647366854,"mc":[{"id":"1.168224581","rc":[{"batb":[[0,2.32,18.1],[1,2.3,31.93],[2,1.01,15.51]],"ltp":2.42,"tv":32.57,"id":7797764},{"batb":[[0,1.63,66.38],[1,1.61,29.82],[2,1.01,15.51]],"ltp":0.0,"tv":0.0,"id":2284304}]}]}
{"op":"mcm","clk":"1002951291","pt":1580647367549,"mc":[{"id":"1.168224581","rc":[{"batb":[[1,1.01,15.51],[2,1.01,0]],"batl":[[0,3,213.45],[1,3,0]],"ltp":2.42,"tv":32.57,"id":7797764},{"batb":[[0,1.61,29.82],[1,1.01,15.51],[2,1.01,0]],"batl":[[0,2.3,309.75],[1,2.3,0]],"ltp":0.0,"tv":0.0,"id":2284304}]}]}
{"op":"mcm","clk":"1002951678","pt":1580647369367,"mc":[{"id":"1.168224581","rc":[{"batb":[[0,2.34,17.7],[1,2.32,18.1],[2,1.01,15.51]],"ltp":2.42,"tv":32.57,"id":7797764},{"batb":[[1,1.6,30.69],[2,1.01,15.51]],"ltp":0.0,"tv":0.0,"id":2284304}]}]}
{"op":"mcm","clk":"1002951882","pt":1580647370339,"mc":[{"id":"1.168224581","rc":[{"batb":[[1,1.01,15.51],[2,1.01,0]],"ltp":2.42,"tv":32.57,"id":7797764},{"batb":[[0,1.6,30.69],[1,1.01,15.51],[2,1.01,0]],"ltp":0.0,"tv":0.0,"id":2284304}]}]}
{"op":"mcm","clk":"1002953774","pt":1580647379435,"mc":[{"id":"1.168224581","rc":[{"batb":[[1,2.26,52.36],[2,1.01,15.51]],"batl":[[0,2.54,26.89],[1,3,213.45]],"ltp":2.42,"tv":32.57,"id":7797764},{"batb":[[0,1.67,26.52],[1,1.66,63.01],[2,1.64,28.17]],"batl":[[0,1.81,42.01],[1,2.3,309.75]],"ltp":0.0,"tv":0.0,"id":2284304}]}]}
{"op":"mcm","clk":"1002956636","pt":1580647392832,"mc":[{"id":"1.168224581","rc":[{"batb":[[0,2.26,52.36],[1,1.01,15.51],[2,1.01,0]],"ltp":2.42,"tv":32.57,"id":7797764},{"batb":[[0,1.66,63.01],[1,1.64,28.17],[2,1.01,15.51]],"ltp":0.0,"tv":0.0,"id":2284304}]}]}
{"op":"mcm","clk":"1002956805","pt":1580647393655,"mc":[{"id":"1.168224581","rc":[{"batb":[[0,2.26,19.59]],"batl":[[0,3,213.45],[1,3,0]],"ltp":2.42,"tv":32.57,"id":7797764},{"batb":[[0,1.64,28.17],[1,1.01,15.51],[2,1.01,0]],"batl":[[0,2.3,309.75],[1,2.3,0]],"ltp":0.0,"tv":0.0,"id":2284304}]}]}
{"op":"mcm","clk":"1002958342","pt":1580647401295,"mc":[{"id":"1.168224581","rc":[{"batb":[[0,2.42,16.29],[1,2.34,18.02],[2,2.28,32.77]],"batl":[[0,2.58,26.05],[1,3,213.45]],"ltp":2.42,"tv":32.57,"id":7797764},{"batb":[[0,1.64,93.7],[1,1.61,30.14],[2,1.01,15.51]],"batl":[[0,1.79,42.01],[1,2.3,309.75]],"ltp":0.0,"tv":0.0,"id":2284304}]}]}
{"op":"mcm","clk":"1002961180","pt":1580647414951,"mc":[{"id":"1.168224581","rc":[{"batb":[[0,2.34,18.02],[1,2.28,32.77],[2,1.01,15.51]],"ltp":2.42,"tv":32.57,"id":7797764},{"batb":[[0,1.64,65.54]],"ltp":0.0,"tv":0.0,"id":2284304}]}]}
{"op":"mcm","clk":"1002961334","pt":1580647415644,"mc":[{"id":"1.168224581","rc":[{"batb":[[1,1.01,15.51],[2,1.01,0]],"batl":[[0,3,213.45],[1,3,0]],"ltp":2.42,"tv":32.57,"id":7797764},{"batb":[[0,1.61,30.14],[1,1.01,15.51],[2,1.01,0]],"batl":[[0,2.3,309.75],[1,2.3,0]],"ltp":0.0,"tv":0.0,"id":2284304}]}]}
{"op":"mcm","clk":"1002961883","pt":1580647418332,"mc":[{"id":"1.168224581","rc":[{"batb":[[0,2.32,18.41]],"ltp":2.42,"tv":32.57,"id":7797764},{"batb":[[0,1.62,29.66]],"ltp":0.0,"tv":0.0,"id":2284304}]}]}
{"op":"mcm","clk":"1002966035","pt":1580647438307,"mc":[{"id":"1.168224581","rc":[{"batb":[[1,2.22,20.69],[2,1.01,15.51]],"ltp":2.42,"tv":32.57,"id":7797764},{"batb":[[0,1.69,25.57],[1,1.66,27.38],[2,1.01,15.51]],"ltp":0.0,"tv":0.0,"id":2284304}]}]}
{"op":"mcm","clk":"1002966227","pt":1580647439305,"mc":[{"id":"1.168224581","rc":[{"batl":[[0,2.52,26.89],[1,3,213.45]],"ltp":2.42,"tv":32.57,"id":7797764},{"batb":[[1,1.66,90.4]],"batl":[[0,1.82,42.01],[1,2.3,309.75]],"ltp":0.0,"tv":0.0,"id":2284304}]}]}
{"op":"mcm","clk":"1002966365","pt":1580647439979,"mc":[{"id":"1.168224581","rc":[{"batb":[[1,2.22,54.3]],"ltp":2.42,"tv":32.57,"id":7797764}]}]}
{"op":"mcm","clk":"1002969447","pt":1580647454284,"mc":[{"id":"1.168224581","rc":[{"batb":[[0,2.22,54.3],[1,1.01,15.51],[2,1.01,0]],"ltp":2.42,"tv":32.57,"id":7797764},{"batb":[[0,1.66,90.4],[1,1.01,15.51],[2,1.01,0]],"ltp":0.0,"tv":0.0,"id":2284304}]}]}
{"op":"mcm","clk":"1002969730","pt":1580647455720,"mc":[{"id":"1.168224581","rc":[{"batb":[[0,2.22,20.69]],"batl":[[0,3,213.45],[1,3,0]],"ltp":2.42,"tv":32.57,"id":7797764},{"batb":[[0,1.66,27.38]],"batl":[[0,2.3,309.75],[1,2.3,0]],"ltp":0.0,"tv":0.0,"id":2284304}]}]}
{"op":"mcm","clk":"1002973259","pt":1580647472355,"mc":[{"id":"1.168224581","rc":[{"batb":[[0,2.38,17.07],[1,2.28,19.12],[2,2.22,87.53]],"ltp":2.42,"tv":32.57,"id":7797764},{"batb":[[1,1.62,29.35],[2,1.01,15.51]],"ltp":0.0,"tv":0.0,"id":2284304}]}]}
{"op":"mcm","clk":"1002973375","pt":1580647473000,"mc":[{"id":"1.168224581","rc":[{"batb":[[2,2.26,32.77]],"batl":[[0,2.54,26.89],[1,3,213.45]],"ltp":2.42,"tv":32.57,"id":7797764},{"batb":[[0,1.66,90.4]],"batl":[[0,1.81,42.01],[1,2.3,309.75]],"ltp":0.0,"tv":0.0,"id":2284304}]}]}
{"op":"mcm","clk":"1002977121","pt":1580647491397,"mc":[{"id":"1.168224581","rc":[{"batb":[[0,2.28,19.12],[1,2.26,32.77],[2,1.01,15.51]],"ltp":2.42,"tv":32.57,"id":7797764},{"batb":[[0,1.66,63.01]],"ltp":0.0,"tv":0.0,"id":2284304}]}]}
{"op":"mcm","clk":"1002977191","pt":1580647491724,"mc":[{"id":"1.168224581","rc":[{"batb":[[1,1.01,15.51],[2,1.01,0]],"batl":[[0,3,213.45],[1,3,0]],"ltp":2.42,"tv":32.57,"id":7797764},{"batb":[[0,1.62,29.35],[1,1.01,15.51],[2,1.01,0]],"batl":[[0,2.3,309.75],[1,2.3,0]],"ltp":0.0,"tv":0.0,"id":2284304}]}]}
{"op":"mcm","clk":"1002978510","pt":1580647498412,"mc":[{"id":"1.168224581","rc":[{"batb":[[0,2.44,15.74],[1,2.36,17.47],[2,2.28,19.12]],"ltp":2.42,"tv":32.57,"id":7797764},{"batb":[[1,1.6,31],[2,1.01,15.51]],"ltp":0.0,"tv":0.0,"id":2284304}]}]}
{"op":"mcm","clk":"1002978676","pt":1580647499323,"mc":[{"id":"1.168224581","rc":[{"batb":[[2,2.28,32.77]],"batl":[[0,2.58,26.05],[1,3,213.45]],"ltp":2.42,"tv":32.57,"id":7797764},{"batb":[[0,1.64,65.54],[1,1.62,29.35],[2,1.6,31]],"batl":[[0,1.79,42.01],[1,2.3,309.75]],"ltp":0.0,"tv":0.0,"id":2284304}]}]}
{"op":"mcm","clk":"1002981128","pt":1580647510398,"mc":[{"id":"1.168224581","rc":[{"batb":[[0,2.36,17.47],[1,2.28,32.77],[2,1.01,15.51]],"ltp":2.42,"tv":32.57,"id":7797764},{"batb":[[1,1.6,31],[2,1.01,15.51]],"ltp":0.0,"tv":0.0,"id":2284304}]}]}
{"op":"mcm","clk":"1002981391","pt":1580647511683,"mc":[{"id":"1.168224581","rc":[{"batb":[[1,1.01,15.51],[2,1.01,0]],"batl":[[0,3,213.45],[1,3,0]],"ltp":2.42,"tv":32.57,"id":7797764},{"batb":[[0,1.6,31],[1,1.01,15.51],[2,1.01,0]],"batl":[[0,2.3,309.75],[1,2.3,0]],"ltp":0.0,"tv":0.0,"id":2284304}]}]}
{"op":"mcm","clk":"1002985675","pt":1580647533456,"mc":[{"id":"1.168224581","rc":[{"batb":[[0,2.5,14.79],[1,2.44,15.97],[2,2.34,31.09]],"batl":[[0,2.64,25.21],[1,3,213.45]],"ltp":2.42,"tv":32.57,"id":7797764},{"batb":[[0,1.61,68.06],[1,1.6,31],[2,1.56,33.52]],"batl":[[0,1.76,42.01]],"ltp":0.0,"tv":0.0,"id":2284304}]}]}
{"op":"mcm","clk":"1002985794","pt":1580647534096,"mc":[{"id":"1.168224581","rc":[{"batl":[[1,2.16,342.82]],"ltp":0.0,"tv":0.0,"id":2284304}]}]}
{"op":"mcm","clk":"1002988944","pt":1580647550289,"mc":[{"id":"1.168224581","rc":[{"batb":[[0,2.44,15.97],[1,2.34,31.09],[2,1.01,15.51]],"ltp":2.42,"tv":32.57,"id":7797764},{"batb":[[1,1.56,33.52],[2,1.01,15.51]],"ltp":0.0,"tv":0.0,"id":2284304}]}]}
{"op":"mcm","clk":"1002989339","pt":1580647552107,"mc":[{"id":"1.168224581","rc":[{"batb":[[1,1.01,15.51],[2,1.01,0]],"batl":[[0,3,213.45],[1,3,0]],"ltp":2.42,"tv":32.57,"id":7797764},{"batb":[[0,1.56,33.52],[1,1.01,15.51],[2,1.01,0]],"batl":[[0,2.16,342.82],[1,2.16,0]],"ltp":0.0,"tv":0.0,"id":2284304}]}]}
{"op":"mcm","clk":"1002992561","pt":1580647568050,"mc":[{"id":"1.168224581","rc":[{"batb":[[0,2.6,13.45],[1,2.52,14.71],[2,1.01,15.51]],"ltp":2.42,"tv":32.57,"id":7797764},{"batb":[[1,1.52,36.82],[2,1.01,15.51]],"ltp":0.0,"tv":0.0,"id":2284304}]}]}
{"op":"mcm","clk":"1002992801","pt":1580647569248,"mc":[{"id":"1.168224581","rc":[{"batb":[[2,2.38,30.25]],"batl":[[0,2.68,24.37]],"ltp":2.42,"tv":32.57,"id":7797764},{"batb":[[0,1.59,70.58],[1,1.56,33.52],[2,1.52,36.82]],"batl":[[0,1.74,42.01],[1,2.16,342.82]],"ltp":0.0,"tv":0.0,"id":2284304}]}]}
{"op":"mcm","clk":"1002992859","pt":1580647569572,"mc":[{"id":"1.168224581","rc":[{"batl":[[1,3.45,180.4]],"ltp":2.42,"tv":32.57,"id":7797764}]}]}
{"op":"mcm","clk":"1002993421","pt":1580647574186,"mc":[{"id":"1.168224581","rc":[{"batl":[[0,2.16,342.82],[1,2.16,0]],"ltp":0.0,"tv":0.0,"id":2284304}]}]}
{"op":"mcm","clk":"1002993956","pt":1580647575181,"mc":[{"id":"1.168224581","rc":[{"batl":[[0,1.73,42.01],[1,2.16,342.82]],"ltp":0.0,"tv":0.0,"id":2284304}]}]}
{"op":"mcm","clk":"1002994782","pt":1580647579457,"mc":[{"id":"1.168224581","rc":[{"batb":[[0,2.52,14.71],[1,2.38,30.25],[2,1.01,15.51]],"ltp":2.42,"tv":32.57,"id":7797764},{"batb":[[1,1.52,36.82],[2,1.01,15.51]],"ltp":0.0,"tv":0.0,"id":2284304}]}]}
{"op":"mcm","clk":"1002994938","pt":1580647580268,"mc":[{"id":"1.168224581","rc":[{"batb":[[1,1.01,15.51],[2,1.01,0]],"batl":[[0,3.45,180.4],[1,3.45,0]],"ltp":2.42,"tv":32.57,"id":7797764},{"batb":[[0,1.52,36.82],[1,1.01,15.51],[2,1.01,0]],"batl":[[0,2.16,342.82],[1,2.16,0]],"ltp":0.0,"tv":0.0,"id":2284304}]}]}
{"op":"mcm","clk":"1002995405","pt":1580647582476,"mc":[{"id":"1.168224581","rc":[{"batb":[[0,2.48,15.11]],"ltp":2.42,"tv":32.57,"id":7797764},{"batb":[[0,1.53,35.96]],"ltp":0.0,"tv":0.0,"id":2284304}]}]}
{"op":"mcm","clk":"1002995986","pt":1580647585393,"mc":[{"id":"1.168224581","rc":[{"batb":[[1,2.42,16.44],[2,1.01,15.51]],"ltp":2.42,"tv":32.57,"id":7797764},{"batb":[[0,1.61,30.37],[1,1.57,33.28],[2,1.53,35.96]],"ltp":0.0,"tv":0.0,"id":2284304}]}]}
{"op":"mcm","clk":"1002996178","pt":1580647586367,"mc":[{"id":"1.168224581","rc":[{"batb":[[2,1.01,15.51]],"ltp":0.0,"tv":0.0,"id":2284304}]}]}
{"op":"mcm","clk":"1002996320","pt":1580647587093,"mc":[{"id":"1.168224581","rc":[{"batl":[[0,2.68,24.37]],"ltp":2.42,"tv":32.57,"id":7797764},{"batb":[[1,1.59,70.58],[2,1.57,33.28]],"batl":[[0,1.74,42.01],[1,2.16,342.82]],"ltp":0.0,"tv":0.0,"id":2284304}]}]}
{"op":"mcm","clk":"1002996561","pt":1580647588465,"mc":[{"id":"1.168224581","rc":[{"batb":[[2,2.36,30.25]],"batl":[[1,3.3,191.92]],"ltp":2.42,"tv":32.57,"id":7797764}]}]}
{"op":"mcm","clk":"1002997785","pt":1580647594482,"mc":[{"id":"1.168224581","rc":[{"batb":[[0,2.42,16.44],[1,2.36,30.25],[2,1.01,15.51]],"ltp":2.42,"tv":32.57,"id":7797764},{"batb":[[0,1.59,70.58],[1,1.57,33.28],[2,1.01,15.51]],"ltp":0.0,"tv":0.0,"id":2284304}]}]}
{"op":"mcm","clk":"1002998129","pt":1580647596212,"mc":[{"id":"1.168224581","rc":[{"batb":[[1,1.01,15.51],[2,1.01,0]],"batl":[[0,3.3,191.92],[1,3.3,0]],"ltp":2.42,"tv":32.57,"id":7797764},{"batb":[[0,1.57,33.28],[1,1.01,15.51],[2,1.01,0]],"batl":[[0,2.16,342.82],[1,2.16,0]],"ltp":0.0,"tv":0.0,"id":2284304}]}]}
{"op":"mcm","clk":"1002999926","pt":1580647605403,"mc":[{"id":"1.168224581","rc":[{"batb":[[1,2.34,48.79],[2,1.01,15.51]],"batl":[[0,2.66,25.21],[1,3.3,191.92]],"ltp":2.42,"tv":32.57,"id":7797764},{"batb":[[0,1.64,28.4],[1,1.6,100.66],[2,1.01,15.51]],"batl":[[0,1.76,42.01],[1,2.16,342.82]],"ltp":0.0,"tv":0.0,"id":2284304}]}]}
{"op":"mcm","clk":"1003002172","pt":1580647616825,"mc":[{"id":"1.168224581","rc":[{"batb":[[0,2.34,48.79],[1,1.01,15.51],[2,1.01,0]],"ltp":2.42,"tv":32.57,"id":7797764},{"batb":[[0,1.6,100.66],[1,1.01,15.51],[2,1.01,0]],"ltp":0.0,"tv":0.0,"id":2284304}]}]}
{"op":"mcm","clk":"1003002503","pt":1580647618320,"mc":[{"id":"1.168224581","rc":[{"batb":[[0,2.34,17.7]],"batl":[[0,3.3,191.92],[1,3.3,0]],"ltp":2.42,"tv":32.57,"id":7797764},{"batb":[[0,1.6,30.92]],"batl":[[0,2.16,342.82],[1,2.16,0]],"ltp":0.0,"tv":0.0,"id":2284304}]}]}
{"op":"mcm","clk":"1003003572","pt":1580647623472,"mc":[{"id":"1.168224581","rc":[{"batb":[[0,2.34,48.79],[1,2.3,18.73],[2,1.01,15.51]],"batl":[[0,2.66,25.21],[1,3.3,191.92]],"ltp":2.42,"tv":32.57,"id":7797764},{"batb":[[0,1.67,26.52],[1,1.63,28.72],[2,1.61,68.06]],"batl":[[0,1.76,42.01],[1,2.16,342.82]],"ltp":0.0,"tv":0.0,"id":2284304}]}]}
{"op":"mcm","clk":"1003004037","pt":1580647625434,"mc":[{"id":"1.168224581","rc":[{"batb":[[0,2.34,17.7]],"batl":[[0,3.3,191.92],[1,3.3,0]],"ltp":2.42,"tv":32.57,"id":7797764}]}]}
{"op":"mcm","clk":"1003004692","pt":1580647628453,"mc":[{"id":"1.168224581","rc":[{"batb":[[1,2.32,31.09],[2,2.3,18.73]],"batl":[[0,2.62,25.21],[1,3.3,191.92]],"ltp":2.42,"tv":32.57,"id":7797764}]}]}
{"op":"mcm","clk":"1003005653","pt":1580647633054,"mc":[{"id":"1.168224581","rc":[{"batb":[[0,2.32,31.09],[1,2.3,18.73],[2,1.01,15.51]],"ltp":2.42,"tv":32.57,"id":7797764},{"batb":[[0,1.63,28.72],[1,1.61,68.06],[2,1.01,15.51]],"ltp":0.0,"tv":0.0,"id":2284304}]}]}
{"op":"mcm","clk":"1003005958","pt":1580647634342,"mc":[{"id":"1.168224581","rc":[{"batb":[[0,2.3,18.73],[1,1.01,15.51],[2,1.01,0]],"batl":[[0,3.3,191.92],[1,3.3,0]],"ltp":2.42,"tv":32.57,"id":7797764},{"batb":[[1,1.01,15.51],[2,1.01,0]],"batl":[[0,2.16,342.82],[1,2.16,0]],"ltp":0.0,"tv":0.0,"id":2284304}]}]}
{"op":"mcm","clk":"1003006352","pt":1580647636261,"mc":[{"id":"1.168224581","rc":[{"batb":[[0,2.32,18.18]],"ltp":2.42,"tv":32.57,"id":7797764},{"batb":[[0,1.62,29.43]],"ltp":0.0,"tv":0.0,"id":2284304}]}]}
{"op":"mcm","clk":"1003007946","pt":1580647644440,"mc":[{"id":"1.168224581","rc":[{"batb":[[1,2.24,20.14],[2,1.01,15.51]],"ltp":2.42,"tv":32.57,"id":7797764},{"batb":[[0,1.68,25.81],[1,1.65,27.38],[2,1.62,455.26]],"ltp":0.0,"tv":0.0,"id":2284304}]}]}
{"op":"mcm","clk":"1003008022","pt":1580647644850,"mc":[{"id":"1.168224581","rc":[{"batb":[[1,2.28,32.77],[2,2.24,20.14]],"batl":[[0,2.58,26.05]],"ltp":2.42,"tv":32.57,"id":7797764},{"batb":[[2,1.64,65.54]],"batl":[[0,1.79,42.01],[1,2.16,342.82]],"ltp":0.0,"tv":0.0,"id":2284304}]}]}
{"op":"mcm","clk":"1003008474","pt":1580647647180,"mc":[{"id":"1.168224581","rc":[{"batl":[[1,3,213.45]],"ltp":2.42,"tv":32.57,"id":7797764}]}]}
{"op":"mcm","clk":"1003009096","pt":1580647650365,"mc":[{"id":"1.168224581","rc":[{"batb":[[2,2.24,19.99]],"ltp":2.42,"tv":32.57,"id":7797764}]}]}
{"op":"mcm","clk":"1003016554","pt":1580647687998,"mc":[{"id":"1.168224581","rc":[{"batb":[[0,2.34,17.62],[2,2.26,19.51]],"ltp":2.42,"tv":32.57,"id":7797764},{"batb":[[0,1.67,26.59],[1,1.64,93.7],[2,1.01,15.51]],"ltp":0.0,"tv":0.0,"id":2284304}]}]}
{"op":"mcm","clk":"1003018744","pt":1580647699317,"mc":[{"id":"1.168224581","rc":[{"batb":[[0,2.36,17.23],[1,2.28,51.81],[2,1.01,15.51]],"ltp":2.42,"tv":32.57,"id":7797764},{"batb":[[0,1.66,27.15],[1,1.64,65.54],[2,1.63,28.72]],"ltp":0.0,"tv":0.0,"id":2284304}]}]}
{"op":"mcm","clk":"1003023752","pt":1580647725901,"mc":[{"id":"1.168224581","rc":[{"batb":[[0,2.28,19.04],[1,1.01,15.51],[2,1.01,0]],"batl":[[0,3,213.45],[1,3,0]],"ltp":2.42,"tv":32.57,"id":7797764},{"batb":[[0,1.63,28.72],[1,1.01,15.51],[2,1.63,0]],"batl":[[0,2.16,342.82],[1,2.16,0]],"ltp":0.0,"tv":0.0,"id":2284304}]}]}
{"op":"mcm","clk":"1003024734","pt":1580647731292,"mc":[{"id":"1.168224581","rc":[{"batb":[[0,2.42,16.13],[1,2.34,17.94],[2,2.32,31.09]],"batl":[[0,2.62,25.21],[1,3,213.45]],"ltp":2.42,"tv":32.57,"id":7797764},{"batb":[[0,1.63,95.09],[1,1.61,30.21],[2,1.01,15.51]],"batl":[[0,1.77,42.01],[1,2.16,342.82]],"ltp":0.0,"tv":0.0,"id":2284304}]}]}
{"op":"mcm","clk":"1003026872","pt":1580647743334,"mc":[{"id":"1.168224581","rc":[{"batb":[[0,2.34,17.94],[1,2.32,31.09],[2,1.01,15.51]],"ltp":2.42,"tv":32.57,"id":7797764},{"batb":[[0,1.63,66.38]],"ltp":0.0,"tv":0.0,"id":2284304}]}]}
{"op":"mcm","clk":"1003027064","pt":1580647744403,"mc":[{"id":"1.168224581","rc":[{"batb":[[0,2.34,17.7],[1,1.01,15.51],[2,1.01,0]],"batl":[[0,3,213.45],[1,3,0]],"ltp":2.42,"tv":32.57,"id":7797764},{"batb":[[0,1.61,30.21],[1,1.01,15.51],[2,1.01,0]],"batl":[[0,2.16,342.82],[1,2.16,0]],"ltp":0.0,"tv":0.0,"id":2284304}]}]}
{"op":"mcm","clk":"1003031274","pt":1580647767491,"mc":[{"id":"1.168224581","rc":[{"batb":[[0,2.48,15.19],[1,2.4,16.68],[2,2.34,31.09]],"batl":[[0,2.66,25.21],[1,3,213.45]],"ltp":2.42,"tv":32.57,"id":7797764},{"batb":[[0,1.61,98.27],[1,1.58,32.02],[2,1.01,15.51]],"batl":[[0,1.76,42.01],[1,2.16,342.82]],"ltp":0.0,"tv":0.0,"id":2284304}]}]}
{"op":"mcm","clk":"1003034007","pt":1580647782487,"mc":[{"id":"1.168224581","rc":[{"batb":[[0,2.4,16.68],[1,2.34,31.09],[2,1.01,15.51]],"ltp":2.42,"tv":32.57,"id":7797764},{"batb":[[0,1.61,68.06]],"ltp":0.0,"tv":0.0,"id":2284304}]}]}
{"op":"mcm","clk":"1003034326","pt":1580647784184,"mc":[{"id":"1.168224581","rc":[{"batb":[[1,1.01,15.51],[2,1.01,0]],"batl":[[0,3,213.45],[1,3,0]],"ltp":2.42,"tv":32.57,"id":7797764},{"batb":[[0,1.58,32.02],[1,1.01,15.51],[2,1.01,0]],"batl":[[0,2.16,342.82],[1,2.16,0]],"ltp":0.0,"tv":0.0,"id":2284304}]}]}
{"op":"mcm","clk":"1003037503","pt":1580647801322,"mc":[{"id":"1.168224581","rc":[{"batb":[[0,2.54,14.24],[1,2.44,15.97],[2,2.38,30.25]],"batl":[[0,2.7,24.37],[1,3,213.45]],"ltp":2.42,"tv":32.57,"id":7797764},{"batb":[[0,1.59,70.58],[1,1.58,32.02],[2,1.56,33.68]],"batl":[[0,1.74,42.01],[1,2.16,342.82]],"ltp":0.0,"tv":0.0,"id":2284304}]}]}
{"op":"mcm","clk":"1003040283","pt":1580647816483,"mc":[{"id":"1.168224581","rc":[{"batb":[[0,2.44,15.97],[1,1.01,15.51],[2,2.38,0]],"batl":[[0,3,213.45],[1,3,0]],"ltp":2.42,"tv":32.57,"id":7797764},{"batb":[[0,1.56,33.68],[1,1.01,15.51],[2,1.56,0]],"batl":[[0,2.16,342.82],[1,2.16,0]],"ltp":0.0,"tv":0.0,"id":2284304}]}]}
{"op":"mcm","clk":"1003043851","pt":1580647836373,"mc":[{"id":"1.168224581","rc":[{"batb":[[1,2.36,17.47],[2,1.01,15.51]],"ltp":2.42,"tv":32.57,"id":7797764},{"batb":[[0,1.63,29.03],[1,1.6,31],[2,1.01,15.51]],"ltp":0.0,"tv":0.0,"id":2284304}]}]}
{"op":"mcm","clk":"1003043959","pt":1580647836937,"mc":[{"id":"1.168224581","rc":[{"batb":[[2,2.34,31.09]],"batl":[[0,2.64,25.21],[1,3,213.45]],"ltp":2.42,"tv":32.57,"id":7797764},{"batb":[[1,1.61,68.06],[2,1.6,31]],"batl":[[0,1.76,42.01],[1,2.16,342.82]],"ltp":0.0,"tv":0.0,"id":2284304}]}]}
{"op":"mcm","clk":"1003044460","pt":1580647839755,"mc":[{"id":"1.168224581","rc":[{"batb":[[2,1.01,15.51]],"batl":[[0,3,213.45],[1,3,0]],"ltp":2.42,"tv":32.57,"id":7797764}]}]}
{"op":"mcm","clk":"1003044981","pt":1580647842840,"mc":[{"id":"1.168224581","rc":[{"batb":[[2,2.32,31.09]],"batl":[[0,2.62,25.21],[1,3,213.45]],"ltp":2.42,"tv":32.57,"id":7797764}]}]}
{"op":"mcm","clk":"1003047233","pt":1580647855377,"mc":[{"id":"1.168224581","rc":[{"batb":[[0,2.36,17.47],[1,2.32,31.09],[2,1.01,15.51]],"ltp":2.42,"tv":32.57,"id":7797764},{"batb":[[0,1.61,68.06],[1,1.6,31],[2,1.01,15.51]],"ltp":0.0,"tv":0.0,"id":2284304}]}]}
{"op":"mcm","clk":"1003047369","pt":1580647856028,"mc":[{"id":"1.168224581","rc":[{"batb":[[1,1.01,15.51],[2,1.01,0]],"batl":[[0,3,213.45],[1,3,0]],"ltp":2.42,"tv":32.57,"id":7797764},{"batb":[[0,1.6,31],[1,1.01,15.51],[2,1.01,0]],"batl":[[0,2.16,342.82],[1,2.16,0]],"ltp":0.0,"tv":0.0,"id":2284304}]}]}
{"op":"mcm","clk":"1003049051","pt":1580647865323,"mc":[{"id":"1.168224581","rc":[{"batb":[[0,2.5,14.79],[1,2.44,16.05],[2,2.38,30.25]],"batl":[[0,2.68,24.37],[1,3,213.45]],"ltp":2.42,"tv":32.57,"id":7797764},{"batb":[[1,1.59,70.58],[2,1.56,33.6]],"batl":[[0,1.74,42.01],[1,2.16,342.82]],"ltp":0.0,"tv":0.0,"id":2284304}]}]}
{"op":"mcm","clk":"1003052767","pt":1580647887371,"mc":[{"id":"1.168224581","rc":[{"batb":[[0,2.44,16.05],[1,2.38,30.25],[2,1.01,15.51]],"ltp":2.42,"tv":32.57,"id":7797764},{"batb":[[0,1.59,70.58],[1,1.56,33.6],[2,1.01,15.51]],"ltp":0.0,"tv":0.0,"id":2284304}]}]}
{"op":"mcm","clk":"1003052907","pt":1580647888199,"mc":[{"id":"1.168224581","rc":[{"batb":[[1,1.01,15.51],[2,1.01,0]],"batl":[[0,3,213.45],[1,3,0]],"ltp":2.42,"tv":32.57,"id":7797764},{"batb":[[0,1.56,33.6],[1,1.01,15.51],[2,1.01,0]],"batl":[[0,2.16,342.82],[1,2.16,0]],"ltp":0.0,"tv":0.0,"id":2284304}]}]}
{"op":"mcm","clk":"1003055528","pt":1580647903290,"mc":[{"id":"1.168224581","rc":[{"batb":[[0,2.6,13.45],[1,2.5,14.71],[2,2.44,16.05]],"batl":[[0,2.74,23.53],[1,3,213.45]],"ltp":2.42,"tv":32.57,"id":7797764},{"batb":[[0,1.57,73.1],[1,1.56,33.6],[2,1.53,36.51]],"batl":[[0,1.72,42.01],[1,2.16,342.82]],"ltp":0.0,"tv":0.0,"id":2284304}]}]}
{"op":"mcm","clk":"1003055578","pt":1580647903618,"mc":[{"id":"1.168224581","rc":[{"batb":[[2,2.42,29.41]],"ltp":2.42,"tv":32.57,"id":7797764}]}]}
{"op":"mcm","clk":"1003057669","pt":1580647915437,"mc":[{"id":"1.168224581","rc":[{"batb":[[0,2.5,14.71],[1,2.42,29.41],[2,1.01,15.51]],"ltp":2.42,"tv":32.57,"id":7797764},{"batb":[[1,1.53,36.35],[2,1.01,15.51]],"ltp":0.0,"tv":0.0,"id":2284304}]}]}
{"op":"mcm","clk":"1003057760","pt":1580647916033,"mc":[{"id":"1.168224581","rc":[{"batb":[[1,1.01,15.51],[2,1.01,0]],"batl":[[0,3,213.45],[1,3,0]],"ltp":2.42,"tv":32.57,"id":7797764},{"batb":[[0,1.53,36.35],[1,1.01,15.51],[2,1.01,0]],"batl":[[0,2.16,342.82],[1,2.16,0]],"ltp":0.0,"tv":0.0,"id":2284304}]}]}
{"op":"mcm","clk":"1003060728","pt":1580647933354,"mc":[{"id":"1.168224581","rc":[{"batb":[[1,2.44,15.82],[2,1.01,15.51]],"ltp":2.42,"tv":32.57,"id":7797764},{"batb":[[0,1.6,31],[1,1.56,34.07],[2,1.53,36.35]],"ltp":0.0,"tv":0.0,"id":2284304}]}]}
{"op":"mcm","clk":"1003060837","pt":1580647934051,"mc":[{"id":"1.168224581","rc":[{"batb":[[2,1.01,15.51]],"ltp":0.0,"tv":0.0,"id":2284304}]}]}
{"op":"mcm","clk":"1003061089","pt":1580647935472,"mc":[{"id":"1.168224581","rc":[{"batb":[[2,2.4,29.41]],"batl":[[0,2.72,24.37],[1,3,213.45]],"ltp":2.42,"tv":32.57,"id":7797764},{"batb":[[1,1.58,72.26],[2,1.56,34.07]],"ltp":0.0,"tv":0.0,"id":2284304}]}]}
{"op":"mcm","clk":"1003061346","pt":1580647936890,"mc":[{"id":"1.168224581","rc":[{"batl":[[0,1.72,42.01],[1,2.16,342.82]],"ltp":0.0,"tv":0.0,"id":2284304}]}]}
{"op":"mcm","clk":"1003062920","pt":1580647947111,"mc":[{"id":"1.168224581","rc":[{"batb":[[0,2.44,15.82],[1,2.4,29.41],[2,1.01,15.51]],"ltp":2.42,"tv":32.57,"id":7797764},{"batb":[[0,1.58,72.26],[1,1.56,34.07],[2,1.01,15.51]],"ltp":0.0,"tv":0.0,"id":2284304}]}]}
{"op":"mcm","clk":"1003063065","pt":1580647948001,"mc":[{"id":"1.168224581","rc":[{"batb":[[1,1.01,15.51],[2,1.01,0]],"batl":[[0,3,213.45],[1,3,0]],"ltp":2.42,"tv":32.57,"id":7797764},{"batb":[[0,1.56,34.07],[1,1.01,15.51],[2,1.01,0]],"batl":[[0,2.16,342.82],[1,2.16,0]],"ltp":0.0,"tv":0.0,"id":2284304}]}]}
{"op":"mcm","clk":"1003063446","pt":1580647950289,"mc":[{"id":"1.168224581","rc":[{"batb":[[0,1.55,34.23]],"ltp":0.0,"tv":0.0,"id":2284304}]}]}
{"op":"mcm","clk":"1003065049","pt":1580647960010,"mc":[{"id":"1.168224581","rc":[{"batb":[[0,1.01,15.51],[1,1.01,0]],"ltp":2.42,"tv":32.57,"id":7797764}]}]}
{"op":"mcm","clk":"1003065524","pt":1580647962961,"mc":[{"id":"1.168224581","rc":[{"batb":[[0,2.42,16.13],[1,2.38,30.25],[2,2.36,17.23]],"batl":[[0,2.7,24.37],[1,3,213.45]],"ltp":2.42,"tv":32.57,"id":7797764},{"batb":[[0,1.63,28.8],[1,1.59,31.39],[2,1.58,72.26]],"batl":[[0,1.73,42.01],[1,2.16,342.82]],"ltp":0.0,"tv":0.0,"id":2284304}]}]}
{"op":"mcm","clk":"1003067709","pt":1580647976371,"mc":[{"id":"1.168224581","rc":[{"batb":[[0,2.36,17.23],[1,1.01,15.51],[2,2.36,0]],"batl":[[0,3,213.45],[1,3,0]],"ltp":2.42,"tv":32.57,"id":7797764},{"batb":[[0,1.59,31.39],[1,1.01,15.51],[2,1.58,0]],"batl":[[0,2.16,342.82],[1,2.16,0]],"ltp":0.0,"tv":0.0,"id":2284304}]}]}
{"op":"mcm","clk":"1003069780","pt":1580647989004,"mc":[{"id":"1.168224581","rc":[{"batb":[[0,2.52,14.56],[1,2.44,15.89],[2,2.4,29.41]],"batl":[[0,2.76,23.53],[1,3,213.45]],"ltp":2.42,"tv":32.57,"id":7797764},{"batb":[[1,1.57,73.1],[2,1.55,34.15]],"batl":[[0,1.71,42.01],[1,2.16,342.82]],"ltp":0.0,"tv":0.0,"id":2284304}]}]}
{"op":"mcm","clk":"1003070750","pt":1580647994795,"mc":[{"id":"1.168224581","rc":[{"batb":[[2,1.01,15.51]],"ltp":2.42,"tv":32.57,"id":7797764}]}]}
{"op":"mcm","clk":"1003071227","pt":1580647997793,"mc":[{"id":"1.168224581","rc":[{"batb":[[1,2.44,44.46]],"ltp":2.42,"tv":32.57,"id":7797764}]}]}
{"op":"mcm","clk":"1003071901","pt":1580648001956,"mc":[{"id":"1.168224581","rc":[{"batb":[[0,2.44,15.89],[1,1.01,15.51],[2,1.01,0]],"batl":[[0,3,213.45],[1,3,0]],"ltp":2.42,"tv":32.57,"id":7797764},{"batb":[[0,1.55,34.15],[1,1.01,15.51],[2,1.55,0]],"batl":[[0,2.16,342.82],[1,2.16,0]],"ltp":0.0,"tv":0.0,"id":2284304}]}]}
{"op":"mcm","clk":"1003075180","pt":1580648022490,"mc":[{"id":"1.168224581","rc":[{"batb":[[0,2.62,13.22],[1,2.54,14.4],[2,1.01,15.51]],"ltp":2.42,"tv":32.57,"id":7797764},{"batb":[[1,1.51,38.08],[2,1.01,15.51]],"ltp":0.0,"tv":0.0,"id":2284304}]}]}
{"op":"mcm","clk":"1003075255","pt":1580648022932,"mc":[{"id":"1.168224581","rc":[{"batl":[[0,2.82,22.69]],"ltp":2.42,"tv":32.57,"id":7797764},{"batb":[[0,1.55,109.77]],"batl":[[0,1.69,42.01],[1,2.16,342.82]],"ltp":0.0,"tv":0.0,"id":2284304}]}]}
{"op":"mcm","clk":"1003075353","pt":1580648023562,"mc":[{"id":"1.168224581","rc":[{"batl":[[1,3.45,180.4]],"ltp":2.42,"tv":32.57,"id":7797764}]}]}
{"op":"mcm","clk":"1003077256","pt":1580648035386,"mc":[{"id":"1.168224581","rc":[{"batb":[[0,2.54,14.4],[1,1.01,15.51],[2,1.01,0]],"ltp":2.42,"tv":32.57,"id":7797764},{"batb":[[0,1.55,75.62]],"ltp":0.0,"tv":0.0,"id":2284304}]}]}
{"op":"mcm","clk":"1003077350","pt":1580648035969,"mc":[{"id":"1.168224581","rc":[{"batl":[[0,3.45,180.4],[1,3.45,0]],"ltp":2.42,"tv":32.57,"id":7797764},{"batb":[[0,1.51,38.08],[1,1.01,15.51],[2,1.01,0]],"batl":[[0,2.16,342.82],[1,2.16,0]],"ltp":0.0,"tv":0.0,"id":2284304}]}]}
{"op":"mcm","clk":"1003077771","pt":1580648038990,"mc":[{"id":"1.168224581","rc":[{"batb":[[0,2.52,14.48]],"ltp":2.42,"tv":32.57,"id":7797764},{"batb":[[0,1.51,37.77]],"ltp":0.0,"tv":0.0,"id":2284304}]}]}
{"op":"mcm","clk":"1003079852","pt":1580648052408,"mc":[{"id":"1.168224581","rc":[{"batb":[[0,1.51,194.31],[1,1.5,171.42],[2,1.01,15.51]],"batl":[[0,1.56,206.69],[1,1.57,141.55]],"ltp":0.0,"tv":0.0,"id":2284304}]}]}
{"op":"mcm","clk":"1003079961","pt":1580648053179,"mc":[{"id":"1.168224581","rc":[{"batb":[[0,2.74,11.72],[1,2.5,27.73],[2,2.4,16.68]],"batl":[[0,2.86,21.85],[1,3.45,180.4]],"ltp":2.42,"tv":32.57,"id":7797764},{"batb":[[0,1.54,77.3],[1,1.51,194.31],[2,1.5,171.42]],"batl":[[2,1.68,42.01]],"ltp":0.0,"tv":0.0,"id":2284304}]}]}
{"op":"mcm","clk":"1003091756","pt":1580648124035,"mc":[{"id":"1.168224581","rc":[{"trd":[[1.54,154]],"batb":[[0,1.51,194.31],[1,1.5,171.42],[2,1.44,45.64]],"ltp":1.54,"tv":154.0,"id":2284304}],"tv":186.58}]}
{"op":"mcm","clk":"1003092326","pt":1580648127030,"mc":[{"id":"1.168224581","rc":[{"batb":[[0,1.53,78.98],[1,1.51,194.31],[2,1.5,171.42]],"ltp":1.54,"tv":154.0,"id":2284304}]}]}
{"op":"mcm","clk":"1003099054","pt":1580648165106,"mc":[{"id":"1.168224581","rc":[{"trd":[[1.53,43.3]],"batb":[[0,1.53,57.33]],"ltp":1.53,"tv":197.3,"id":2284304}],"tv":229.88}]}
{"op":"mcm","clk":"1003099408","pt":1580648167085,"mc":[{"id":"1.168224581","rc":[{"batb":[[0,2.5,27.73],[1,2.4,16.68],[2,1.01,15.51]],"ltp":2.42,"tv":32.57,"id":7797764},{"batb":[[1,1.44,45.64],[2,1.01,15.51]],"batl":[[0,1.68,42.01],[1,2.04,383.01],[2,1.68,0]],"ltp":1.53,"tv":197.3,"id":2284304}]}]}
{"op":"mcm","clk":"1003099635","pt":1580648168369,"mc":[{"id":"1.168224581","rc":[{"batb":[[0,2.4,16.68],[1,1.01,15.51],[2,1.01,0]],"batl":[[0,3.45,180.4],[1,3.45,0]],"ltp":2.42,"tv":32.57,"id":7797764},{"batb":[[0,1.53,21]],"batl":[[0,2.04,383.01],[1,2.04,0]],"ltp":1.53,"tv":197.3,"id":2284304}]}]}
{"op":"mcm","clk":"1003099820","pt":1580648169438,"mc":[{"id":"1.168224581","rc":[{"batb":[[0,1.44,45.64],[1,1.01,15.51],[2,1.01,0]],"ltp":1.53,"tv":197.3,"id":2284304}]}]}
{"op":"mcm","clk":"1003100124","pt":1580648171304,"mc":[{"id":"1.168224581","rc":[{"trd":[[1.53,76.06]],"batb":[[0,1.53,170.12],[1,1.52,162.74],[2,1.44,45.64]],"batl":[[0,1.58,147.13],[1,1.59,135.42],[2,2.04,383.01]],"ltp":1.53,"tv":230.06,"id":2284304}],"tv":262.64}]}
{"op":"mcm","clk":"1003101219","pt":1580648177966,"mc":[{"id":"1.168224581","rc":[{"batb":[[0,1.44,45.64],[1,1.01,15.51],[2,1.44,0]],"batl":[[0,2.04,383.01],[1,1.59,0],[2,2.04,0]],"ltp":1.53,"tv":230.06,"id":2284304}]}]}
{"op":"mcm","clk":"1003101695","pt":1580648180856,"mc":[{"id":"1.168224581","rc":[{"batb":[[0,1.45,139.08],[1,1.44,249.22],[2,1.01,15.51]],"batl":[[0,1.69,145.72],[1,1.71,210.76],[2,2.04,383.01]],"ltp":1.53,"tv":230.06,"id":2284304}]}]}
{"op":"mcm","clk":"1003103193","pt":1580648190044,"mc":[{"id":"1.168224581","rc":[{"batl":[[0,2.04,383.01],[1,1.71,0],[2,2.04,0]],"ltp":1.53,"tv":230.06,"id":2284304}]}]}
{"op":"mcm","clk":"1003103777","pt":1580648193482,"mc":[{"id":"1.168224581","rc":[{"batl":[[0,1.49,169.83],[1,1.5,169.14],[2,2.04,383.01]],"ltp":1.53,"tv":230.06,"id":2284304}]}]}
{"op":"mcm","clk":"1003103877","pt":1580648193983,"mc":[{"id":"1.168224581","rc":[{"batb":[[0,2.98,23.37],[1,2.64,12.75],[2,1.01,15.51]],"ltp":2.42,"tv":32.57,"id":7797764},{"batb":[[2,1.39,53.35]],"ltp":1.53,"tv":230.06,"id":2284304}]}]}
{"op":"mcm","clk":"1003104041","pt":1580648194971,"mc":[{"id":"1.168224581","rc":[{"batl":[[0,3.1,19.32]],"ltp":2.42,"tv":32.57,"id":7797764},{"batb":[[0,1.47,89.06],[1,1.45,139.08],[2,1.44,249.22]],"batl":[[2,1.57,42.01]],"ltp":1.53,"tv":230.06,"id":2284304}]}]}
{"op":"mcm","clk":"1003104224","pt":1580648196074,"mc":[{"id":"1.168224581","rc":[{"batl":[[1,3.9,158.24]],"ltp":2.42,"tv":32.57,"id":7797764}]}]}
{"op":"mcm","clk":"1003107306","pt":1580648214421,"mc":[{"id":"1.168224581","rc":[{"batb":[[0,2.64,12.75],[1,1.01,15.51],[2,1.01,0]],"ltp":2.42,"tv":32.57,"id":7797764},{"batb":[[1,1.39,53.35],[2,1.01,15.51]],"batl":[[0,1.57,42.01],[1,2.04,383.01],[2,1.57,0]],"ltp":1.53,"tv":230.06,"id":2284304}]}]}
{"op":"mcm","clk":"1003107647","pt":1580648216440,"mc":[{"id":"1.168224581","rc":[{"batl":[[0,3.9,158.24],[1,3.9,0]],"ltp":2.42,"tv":32.57,"id":7797764},{"batb":[[0,1.39,53.35],[1,1.01,15.51],[2,1.01,0]],"batl":[[0,2.04,383.01],[1,2.04,0]],"ltp":1.53,"tv":230.06,"id":2284304}]}]}
{"op":"mcm","clk":"1003107763","pt":1580648217226,"mc":[{"id":"1.168224581","rc":[{"batb":[[0,1.4,305.06],[1,1.39,293.69],[2,1.01,15.51]],"batl":[[0,1.59,232.7],[1,1.6,132.05],[2,2.04,383.01]],"ltp":1.53,"tv":230.06,"id":2284304}]}]}
{"op":"mcm","clk":"1003108220","pt":1580648220490,"mc":[{"id":"1.168224581","rc":[{"batb":[[0,1.39,53.35],[1,1.01,15.51],[2,1.01,0]],"batl":[[0,2.04,383.01],[1,1.6,0],[2,2.04,0]],"ltp":1.53,"tv":230.06,"id":2284304}]}]}
{"op":"mcm","clk":"1003108837","pt":1580648223422,"mc":[{"id":"1.168224581","rc":[{"batb":[[0,1.46,257.11],[1,1.45,198.52],[2,1.39,53.35]],"batl":[[0,1.51,206.61],[1,1.52,160.35],[2,2.04,383.01]],"ltp":1.53,"tv":230.06,"id":2284304}]}]}
{"op":"mcm","clk":"1003109130","pt":1580648225326,"mc":[{"id":"1.168224581","rc":[{"batb":[[0,1.39,53.35],[1,1.01,15.51],[2,1.39,0]],"batl":[[0,2.04,383.01],[1,1.52,0],[2,2.04,0]],"ltp":1.53,"tv":230.06,"id":2284304}]}]}
{"op":"mcm","clk":"1003109606","pt":1580648228035,"mc":[{"id":"1.168224581","rc":[{"batb":[[0,1.4,305.06],[1,1.39,293.69],[2,1.01,15.51]],"batl":[[0,1.59,232.7],[1,1.6,132.05],[2,2.04,383.01]],"ltp":1.53,"tv":230.06,"id":2284304}]}]}
{"op":"mcm","clk":"1003110389","pt":1580648232334,"mc":[{"id":"1.168224581","rc":[{"batl":[[0,2.04,383.01],[1,1.6,0],[2,2.04,0]],"ltp":1.53,"tv":230.06,"id":2284304}]}]}
{"op":"mcm","clk":"1003110940","pt":1580648235364,"mc":[{"id":"1.168224581","rc":[{"batl":[[0,1.45,308.7],[1,1.46,187.73]],"ltp":1.53,"tv":230.06,"id":2284304}]}]}
{"op":"mcm","clk":"1003111094","pt":1580648236230,"mc":[{"id":"1.168224581","rc":[{"batb":[[0,3.2,19.04],[1,2.94,24.39],[2,1.01,15.51]],"ltp":2.42,"tv":32.57,"id":7797764},{"batb":[[2,1.35,60.03]],"ltp":1.53,"tv":230.06,"id":2284304}]}]}
{"op":"mcm","clk":"1003111317","pt":1580648237453,"mc":[{"id":"1.168224581","rc":[{"batl":[[0,3.3,17.64],[1,3.9,158.24]],"ltp":2.42,"tv":32.57,"id":7797764},{"batb":[[0,1.43,97.46],[1,1.4,305.06],[2,1.39,293.69]],"ltp":1.53,"tv":230.06,"id":2284304}]}]}
{"op":"mcm","clk":"1003111480","pt":1580648238402,"mc":[{"id":"1.168224581","rc":[{"batl":[[2,1.89,435.28]],"ltp":1.53,"tv":230.06,"id":2284304}]}]}
{"op":"mcm","clk":"1003113563","pt":1580648250209,"mc":[{"id":"1.168224581","rc":[{"batl":[[0,3.9,158.24],[1,3.9,0]],"ltp":2.42,"tv":32.57,"id":7797764}]}]}
{"op":"mcm","clk":"1003114069","pt":1580648253116,"mc":[{"id":"1.168224581","rc":[{"batl":[[0,3.35,17.64],[1,3.9,158.24]],"ltp":2.42,"tv":32.57,"id":7797764}]}]}
{"op":"mcm","clk":"1003114624","pt":1580648256122,"mc":[{"id":"1.168224581","rc":[{"batb":[[0,2.94,24.39],[1,1.01,15.51],[2,1.01,0]],"batl":[[0,3.9,158.24],[1,3.9,0]],"ltp":2.42,"tv":32.57,"id":7797764},{"batb":[[0,1.35,60.03],[1,1.01,15.51],[2,1.39,0]],"batl":[[0,1.89,435.28],[1,1.46,0],[2,1.89,0]],"ltp":1.53,"tv":230.06,"id":2284304}]}]}
{"op":"mcm","clk":"1003115151","pt":1580648259227,"mc":[{"id":"1.168224581","rc":[{"batb":[[0,2.9,25.41]],"ltp":2.42,"tv":32.57,"id":7797764},{"batb":[[0,1.38,162.7],[1,1.37,255.73],[2,1.36,58.07]],"ltp":1.53,"tv":230.06,"id":2284304}]}]}
{"op":"mcm","clk":"1003115754","pt":1580648262309,"mc":[{"id":"1.168224581","rc":[{"batl":[[0,1.42,295.82],[1,1.43,204.99],[2,1.89,435.28]],"ltp":1.53,"tv":230.06,"id":2284304}]}]}
{"op":"mcm","clk":"1003115950","pt":1580648263247,"mc":[{"id":"1.168224581","rc":[{"batb":[[0,3.4,17],[1,3.15,20.22],[2,1.01,15.51]],"batl":[[0,3.5,16.8]],"ltp":2.42,"tv":32.57,"id":7797764},{"batb":[[0,1.4,105.02],[1,1.38,162.7],[2,1.37,255.73]],"ltp":1.53,"tv":230.06,"id":2284304}]}]}
{"op":"mcm","clk":"1003116476","pt":1580648266157,"mc":[{"id":"1.168224581","rc":[{"batl":[[1,4.6,136.05]],"ltp":2.42,"tv":32.57,"id":7797764}]}]}
{"op":"mcm","clk":"1003118176","pt":1580648276484,"mc":[{"id":"1.168224581","rc":[{"batl":[[1,1.43,391.51]],"ltp":1.53,"tv":230.06,"id":2284304}]}]}
{"op":"mcm","clk":"1003118315","pt":1580648277287,"mc":[{"id":"1.168224581","rc":[{"batb":[[0,3.15,20.22],[1,1.01,15.51],[2,1.01,0]],"ltp":2.42,"tv":32.57,"id":7797764},{"batb":[[1,1.34,62.55],[2,1.01,15.51]],"batl":[[0,1.43,186.52],[1,1.89,435.28],[2,1.89,0]],"ltp":1.53,"tv":230.06,"id":2284304}]}]}
{"op":"mcm","clk":"1003118497","pt":1580648278409,"mc":[{"id":"1.168224581","rc":[{"batl":[[0,4.6,136.05],[1,4.6,0]],"ltp":2.42,"tv":32.57,"id":7797764},{"batb":[[0,1.34,62.55],[1,1.01,15.51],[2,1.01,0]],"batl":[[0,1.89,435.28],[1,1.89,0]],"ltp":1.53,"tv":230.06,"id":2284304}]}]}
{"op":"mcm","clk":"1003119182","pt":1580648282403,"mc":[{"id":"1.168224581","rc":[{"batb":[[0,1.38,296.07],[1,1.37,257.23],[2,1.34,62.55]],"batl":[[0,1.42,171.53],[1,1.43,206.16],[2,1.89,435.28]],"ltp":1.53,"tv":230.06,"id":2284304}]}]}
{"op":"mcm","clk":"1003119824","pt":1580648286212,"mc":[{"id":"1.168224581","rc":[{"batb":[[0,1.34,62.55],[1,1.01,15.51],[2,1.34,0]],"batl":[[0,1.89,435.28],[1,1.43,0],[2,1.89,0]],"ltp":1.53,"tv":230.06,"id":2284304}]}]}
{"op":"mcm","clk":"1003120320","pt":1580648289086,"mc":[{"id":"1.168224581","rc":[{"batb":[[0,1.36,321],[1,1.35,276.79],[2,1.34,62.55]],"ltp":1.53,"tv":230.06,"id":2284304}]}]}
{"op":"mcm","clk":"1003120892","pt":1580648292315,"mc":[{"id":"1.168224581","rc":[{"batl":[[0,1.4,203.3],[1,1.41,219.01]],"ltp":1.53,"tv":230.06,"id":2284304}]}]}
{"op":"mcm","clk":"1003121011","pt":1580648293102,"mc":[{"id":"1.168224581","rc":[{"batb":[[0,3.5,15.42],[1,3.1,20.61],[2,1.01,15.51]],"batl":[[0,3.6,15.96],[1,4.6,136.05]],"ltp":2.42,"tv":32.57,"id":7797764},{"batb":[[0,1.38,110.07],[1,1.36,321],[2,1.35,276.79]],"ltp":1.53,"tv":230.06,"id":2284304}]}]}
{"op":"mcm","clk":"1003121459","pt":1580648295907,"mc":[{"id":"1.168224581","rc":[{"batl":[[2,1.77,500.61]],"ltp":1.53,"tv":230.06,"id":2284304}]}]}
{"op":"mcm","clk":"1003123504","pt":1580648309375,"mc":[{"id":"1.168224581","rc":[{"batl":[[0,1.41,219.01],[1,1.77,500.61],[2,1.77,0]],"ltp":1.53,"tv":230.06,"id":2284304}]}]}
{"op":"mcm","clk":"1003123935","pt":1580648312370,"mc":[{"id":"1.168224581","rc":[{"batb":[[1,1.36,393.77]],"batl":[[0,1.41,350.96],[1,1.42,210.17],[2,1.77,500.61]],"ltp":1.53,"tv":230.06,"id":2284304}]}]}
{"op":"mcm","clk":"1003124000","pt":1580648312795,"mc":[{"id":"1.168224581","rc":[{"trd":[[3.5,30.84]],"batb":[[0,3.1,20.61],[1,1.01,15.51],[2,1.01,0]],"batl":[[0,3.5,22.44],[1,3.6,15.96],[2,4.6,136.05]],"ltp":3.5,"tv":63.41,"id":7797764}],"tv":293.48}]}
{"op":"mcm","clk":"1003126546","pt":1580648329071,"mc":[{"id":"1.168224581","rc":[{"batb":[[1,1.34,62.55],[2,1.27,84.27]],"batl":[[0,1.77,500.61],[1,1.42,0],[2,1.77,0]],"ltp":1.53,"tv":230.06,"id":2284304}]}]}
{"op":"mcm","clk":"1003126945","pt":1580648331879,"mc":[{"id":"1.168224581","rc":[{"batb":[[2,1.29,281.28]],"batl":[[0,1.47,224.67],[1,1.48,177.78],[2,1.77,500.61]],"ltp":1.53,"tv":230.06,"id":2284304}]}]}
{"op":"mcm","clk":"1003127370","pt":1580648334467,"mc":[{"id":"1.168224581","rc":[{"batb":[[1,1.29,281.28],[2,1.28,364.52]],"ltp":1.53,"tv":230.06,"id":2284304}]}]}
{"op":"mcm","clk":"1003127663","pt":1580648336205,"mc":[{"id":"1.168224581","rc":[{"batl":[[1,4.6,136.05],[2,4.6,0]],"ltp":3.5,"tv":63.41,"id":7797764},{"batb":[[0,1.27,84.27],[1,1.01,15.51],[2,1.28,0]],"batl":[[0,1.77,500.61],[1,1.48,0],[2,1.77,0]],"ltp":1.53,"tv":230.06,"id":2284304}]}]}
{"op":"mcm","clk":"1003127918","pt":1580648337983,"mc":[{"id":"1.168224581","rc":[{"batb":[[0,3.05,22.35]],"ltp":3.5,"tv":63.41,"id":7797764},{"batb":[[0,1.28,79.63]],"ltp":1.53,"tv":230.06,"id":2284304}]}]}
{"op":"mcm","clk":"1003128101","pt":1580648339093,"mc":[{"id":"1.168224581","rc":[{"trd":[[3.5,53.28]],"batl":[[0,4.6,136.05],[1,4.6,0]],"ltp":3.5,"tv":85.86,"id":7797764},{"trd":[[1.4,56.11]],"batb":[[0,1.35,244.23],[1,1.34,285.28],[2,1.28,79.63]],"batl":[[0,1.39,244.57],[1,1.4,224.19],[2,1.77,500.61]],"ltp":1.4,"tv":286.17,"id":2284304}],"tv":372.03}]}
{"op":"mcm","clk":"1003128685","pt":1580648342455,"mc":[{"id":"1.168224581","rc":[{"batb":[[0,1.28,79.63],[1,1.01,15.51],[2,1.28,0]],"batl":[[0,1.77,500.61],[1,1.4,0],[2,1.77,0]],"ltp":1.4,"tv":286.17,"id":2284304}]}]}
{"op":"mcm","clk":"1003129118","pt":1580648345106,"mc":[{"id":"1.168224581","rc":[{"batb":[[0,1.29,305.06],[1,1.28,444.21],[2,1.01,15.51]],"batl":[[0,1.47,203.92],[1,1.48,177.76],[2,1.77,500.61]],"ltp":1.4,"tv":286.17,"id":2284304}]}]}
{"op":"mcm","clk":"1003129329","pt":1580648346328,"mc":[{"id":"1.168224581","rc":[{"batl":[[0,1.77,500.61],[1,1.48,0],[2,1.77,0]],"ltp":1.4,"tv":286.17,"id":2284304}]}]}
{"op":"mcm","clk":"1003129836","pt":1580648349383,"mc":[{"id":"1.168224581","rc":[{"batl":[[0,1.32,177.89],[1,1.33,286.95]],"ltp":1.4,"tv":286.17,"id":2284304}]}]}
{"op":"mcm","clk":"1003129923","pt":1580648350016,"mc":[{"id":"1.168224581","rc":[{"batb":[[0,4,22.35],[1,3.45,15.89],[2,1.01,15.51]],"ltp":3.5,"tv":85.86,"id":7797764},{"batb":[[2,1.21,113.62]],"ltp":1.4,"tv":286.17,"id":2284304}]}]}
{"op":"mcm","clk":"1003130138","pt":1580648351407,"mc":[{"id":"1.168224581","rc":[{"trd":[[4.1,13.44]],"ltp":4.1,"tv":99.3,"id":7797764},{"trd":[[1.32,303.9]],"batl":[[0,1.32,5.06]],"ltp":1.32,"tv":590.07,"id":2284304}],"tv":689.38}]}
{"op":"mcm","clk":"1003130295","pt":1580648352416,"mc":[{"id":"1.168224581","rc":[{"batl":[[0,6,106.18]],"ltp":4.1,"tv":99.3,"id":7797764},{"batl":[[0,1.33,286.95],[1,1.66,579.81]],"ltp":1.32,"tv":590.07,"id":2284304}]}]}
{"op":"mcm","clk":"1003130338","pt":1580648352731,"mc":[{"id":"1.168224581","rc":[{"batl":[[0,4.2,12.6],[1,6,106.18]],"ltp":4.1,"tv":99.3,"id":7797764},{"batb":[[0,1.31,135.27],[1,1.29,305.06],[2,1.28,444.21]],"ltp":1.32,"tv":590.07,"id":2284304}]}]}
{"op":"mcm","clk":"1003130794","pt":1580648355436,"mc":[{"id":"1.168224581","rc":[{"batb":[[1,1.29,369.95]],"batl":[[0,1.33,400.69],[1,1.34,272.21],[2,1.66,579.81]],"ltp":1.32,"tv":590.07,"id":2284304}]}]}
{"op":"mcm","clk":"1003131570","pt":1580648360438,"mc":[{"id":"1.168224581","rc":[{"batb":[[0,3.45,15.89],[1,1.01,15.51],[2,1.01,0]],"batl":[[0,6,106.18],[1,6,0]],"ltp":4.1,"tv":99.3,"id":7797764},{"batb":[[0,1.21,113.62],[1,1.01,15.51],[2,1.28,0]],"batl":[[0,1.66,579.81],[1,1.34,0],[2,1.66,0]],"ltp":1.32,"tv":590.07,"id":2284304}]}]}
{"op":"mcm","clk":"1003131615","pt":1580648360756,"mc":[{"id":"1.168224581","rc":[{"batb":[[0,1.21,113.22]],"ltp":1.32,"tv":590.07,"id":2284304}]}]}
{"op":"mcm","clk":"1003132296","pt":1580648365302,"mc":[{"id":"1.168224581","rc":[{"batb":[[0,1.27,518.23],[1,1.26,402.42],[2,1.21,113.22]],"batl":[[0,1.31,362.24],[1,1.32,293.91],[2,1.66,579.81]],"ltp":1.32,"tv":590.07,"id":2284304}]}]}
{"op":"mcm","clk":"1003132929","pt":1580648368998,"mc":[{"id":"1.168224581","rc":[{"batb":[[0,1.21,113.22],[1,1.01,15.51],[2,1.21,0]],"batl":[[0,1.66,579.81],[1,1.32,0],[2,1.66,0]],"ltp":1.32,"tv":590.07,"id":2284304}]}]}
{"op":"mcm","clk":"1003133439","pt":1580648372211,"mc":[{"id":"1.168224581","rc":[{"batb":[[0,1.21,634.06],[1,1.2,531.8],[2,1.01,15.51]],"ltp":1.32,"tv":590.07,"id":2284304}]}]}
{"op":"mcm","clk":"1003133938","pt":1580648375102,"mc":[{"id":"1.168224581","rc":[{"batl":[[0,1.24,358.44],[1,1.25,395.94]],"ltp":1.32,"tv":590.07,"id":2284304}]}]}
{"op":"mcm","clk":"1003134080","pt":1580648375828,"mc":[{"id":"1.168224581","rc":[{"batb":[[0,5,13.3],[1,4.2,20.22],[2,1.01,15.51]],"ltp":4.1,"tv":99.3,"id":7797764},{"batb":[[2,1.15,163.03]],"ltp":1.32,"tv":590.07,"id":2284304}]}]}
{"op":"mcm","clk":"1003134328","pt":1580648377315,"mc":[{"id":"1.168224581","rc":[{"batl":[[0,5.3,9.24]],"ltp":4.1,"tv":99.3,"id":7797764},{"batl":[[2,1.56,675.59]],"ltp":1.32,"tv":590.07,"id":2284304}]}]}
{"op":"mcm","clk":"1003134479","pt":1580648378426,"mc":[{"id":"1.168224581","rc":[{"batl":[[1,7.8,87.91]],"ltp":4.1,"tv":99.3,"id":7797764},{"trd":[[1.24,129.4]],"batb":[[0,1.23,168.04],[1,1.21,634.06],[2,1.2,531.8]],"batl":[[0,1.24,293.74]],"ltp":1.24,"tv":719.47,"id":2284304}],"tv":818.77}]}
{"op":"mcm","clk":"1003135106","pt":1580648382464,"mc":[{"id":"1.168224581","rc":[{"batl":[[0,1.24,334.74]],"ltp":1.24,"tv":719.47,"id":2284304}]}]}
{"op":"mcm","clk":"1003135139","pt":1580648382676,"mc":[{"id":"1.168224581","rc":[{"batb":[[1,1.21,590.78]],"ltp":1.24,"tv":719.47,"id":2284304}]}]}
{"op":"mcm","clk":"1003135749","pt":1580648386159,"mc":[{"id":"1.168224581","rc":[{"batl":[[0,1.24,400.72]],"ltp":1.24,"tv":719.47,"id":2284304}]}]}
{"op":"mcm","clk":"1003136124","pt":1580648388293,"mc":[{"id":"1.168224581","rc":[{"batb":[[0,4.2,20.22],[1,1.01,15.51],[2,1.01,0]],"batl":[[0,7.8,87.91],[1,7.8,0]],"ltp":4.1,"tv":99.3,"id":7797764},{"batb":[[0,1.15,163.03],[1,1.01,15.51],[2,1.2,0]],"batl":[[0,1.56,675.59],[1,1.25,0],[2,1.56,0]],"ltp":1.24,"tv":719.47,"id":2284304}]}]}
{"op":"mcm","clk":"1003137235","pt":1580648395014,"mc":[{"id":"1.168224581","rc":[{"batb":[[0,1.2,269.16],[1,1.19,578.93],[2,1.15,163.03]],"batl":[[0,1.22,214.87],[1,1.23,442.13],[2,1.56,675.59]],"ltp":1.24,"tv":719.47,"id":2284304}]}]}
{"op":"mcm","clk":"1003137473","pt":1580648396405,"mc":[{"id":"1.168224581","rc":[{"batb":[[0,1.15,163.03],[1,1.01,15.51],[2,1.15,0]],"batl":[[0,1.56,675.59],[1,1.23,0],[2,1.56,0]],"ltp":1.24,"tv":719.47,"id":2284304}]}]}
{"op":"mcm","clk":"1003137998","pt":1580648399493,"mc":[{"id":"1.168224581","rc":[{"batl":[[0,1.3,321.21],[1,1.31,307.06],[2,1.56,675.59]],"ltp":1.24,"tv":719.47,"id":2284304}]}]}
{"op":"mcm","clk":"1003138548","pt":1580648402394,"mc":[{"id":"1.168224581","rc":[{"batb":[[0,1.27,228.32],[1,1.26,397.23],[2,1.15,163.03]],"ltp":1.24,"tv":719.47,"id":2284304}]}]}
{"op":"mcm","clk":"1003138767","pt":1580648403220,"mc":[{"id":"1.168224581","rc":[{"batb":[[1,3.5,15.5],[2,1.01,15.51]],"batl":[[0,4.6,10.92]],"ltp":4.1,"tv":99.3,"id":7797764},{"batb":[[0,1.28,149.55],[1,1.27,313.69],[2,1.26,397.23]],"ltp":1.24,"tv":719.47,"id":2284304}]}]}
{"op":"mcm","clk":"1003138915","pt":1580648404052,"mc":[{"id":"1.168224581","rc":[{"batl":[[1,6,106.18]],"ltp":4.1,"tv":99.3,"id":7797764}]}]}
{"op":"mcm","clk":"1003141337","pt":1580648416492,"mc":[{"id":"1.168224581","rc":[{"batb":[[0,3.5,15.5],[1,1.01,15.51],[2,1.01,0]],"batl":[[0,6,106.18],[1,6,0]],"ltp":4.1,"tv":99.3,"id":7797764},{"batb":[[0,1.18,133.6],[1,1.01,15.51],[2,1.26,0]],"batl":[[0,1.56,675.59],[1,1.31,0],[2,1.56,0]],"ltp":1.24,"tv":719.47,"id":2284304}]}]}
{"op":"mcm","clk":"1003141476","pt":1580648417066,"mc":[{"id":"1.168224581","rc":[{"batl":[[0,1.27,66.18],[1,1.56,675.59]],"ltp":1.24,"tv":719.47,"id":2284304}]}]}
{"op":"mcm","clk":"1003141811","pt":1580648419344,"mc":[{"id":"1.168224581","rc":[{"batb":[[0,1.18,329.21],[1,1.17,655.78],[2,1.01,15.51]],"batl":[[1,1.28,186.52],[2,1.38,198.78]],"ltp":1.24,"tv":719.47,"id":2284304}]}]}
{"op":"mcm","clk":"1003141919","pt":1580648419569,"mc":[{"id":"1.168224581","rc":[{"batb":[[0,1.18,133.6],[1,1.01,15.51],[2,1.01,0]],"batl":[[2,1.56,675.59]],"ltp":1.24,"tv":719.47,"id":2284304}]}]}
{"op":"mcm","clk":"1003142279","pt":1580648421452,"mc":[{"id":"1.168224581","rc":[{"batl":[[1,1.56,675.59],[2,1.56,0]],"ltp":1.24,"tv":719.47,"id":2284304}]}]}
{"op":"mcm","clk":"1003142456","pt":1580648422469,"mc":[{"id":"1.168224581","rc":[{"batb":[[0,1.25,258.32],[1,1.24,438.44],[2,1.18,133.6]],"batl":[[1,1.28,378.88],[2,1.29,331.91]],"ltp":1.24,"tv":719.47,"id":2284304}]}]}
{"op":"mcm","clk":"1003142774","pt":1580648424463,"mc":[{"id":"1.168224581","rc":[{"batb":[[0,1.18,133.6],[1,1.01,15.51],[2,1.18,0]],"batl":[[1,1.56,675.59],[2,1.29,0]],"ltp":1.24,"tv":719.47,"id":2284304}]}]}
{"op":"mcm","clk":"1003143303","pt":1580648427479,"mc":[{"id":"1.168224581","rc":[{"batb":[[0,1.18,326.57],[1,1.17,655.78],[2,1.01,15.51]],"batl":[[1,1.38,200.72],[2,1.39,232.2]],"ltp":1.24,"tv":719.47,"id":2284304}]}]}
{"op":"mcm","clk":"1003143862","pt":1580648430986,"mc":[{"id":"1.168224581","rc":[{"trd":[[6,55.96]],"batl":[[0,6,50.22]],"ltp":6.0,"tv":155.26,"id":7797764},{"trd":[[1.2,279.78]],"ltp":1.2,"tv":999.25,"id":2284304}],"tv":1154.51}]}
{"op":"mcm","clk":"1003144281","pt":1580648433471,"mc":[{"id":"1.168224581","rc":[{"batl":[[0,1.38,200.72],[1,1.39,232.2],[2,1.56,675.59]],"ltp":1.2,"tv":999.25,"id":2284304}]}]}
{"op":"mcm","clk":"1003145050","pt":1580648438298,"mc":[{"id":"1.168224581","rc":[{"batl":[[0,1.56,675.59],[1,1.39,0],[2,1.56,0]],"ltp":1.2,"tv":999.25,"id":2284304}]}]}
{"op":"mcm","clk":"1003145439","pt":1580648440392,"mc":[{"id":"1.168224581","rc":[{"batl":[[0,1.2,395.93],[1,1.21,486.07],[2,1.56,675.59]],"ltp":1.2,"tv":999.25,"id":2284304}]}]}
{"op":"mcm","clk":"1003145579","pt":1580648441353,"mc":[{"id":"1.168224581","rc":[{"batb":[[0,5.5,10.46],[1,4.5,16.84],[2,3.5,15.5]],"batl":[[0,6.2,7.56]],"ltp":6.0,"tv":155.26,"id":7797764},{"batb":[[0,1.19,168.04],[1,1.18,326.57],[2,1.17,655.78]],"ltp":1.2,"tv":999.25,"id":2284304}]}]}
{"op":"mcm","clk":"1003145624","pt":1580648441708,"mc":[{"id":"1.168224581","rc":[{"batb":[[2,1.01,15.51]],"ltp":6.0,"tv":155.26,"id":7797764}]}]}
{"op":"mcm","clk":"1003145894","pt":1580648443130,"mc":[{"id":"1.168224581","rc":[{"batl":[[1,8.6,42.45]],"ltp":6.0,"tv":155.26,"id":7797764}]}]}
{"op":"mcm","clk":"1003147053","pt":1580648450022,"mc":[{"id":"1.168224581","rc":[{"batb":[[1,1.18,133.6],[2,1.12,204.73]],"batl":[[0,1.56,675.59],[1,1.21,0],[2,1.56,0]],"ltp":1.2,"tv":999.25,"id":2284304}]}]}
{"op":"mcm","clk":"1003147304","pt":1580648451308,"mc":[{"id":"1.168224581","rc":[{"batb":[[0,4.5,16.84],[1,1.01,15.51],[2,1.01,0]],"ltp":6.0,"tv":155.26,"id":7797764},{"batb":[[1,1.12,204.73],[2,1.01,15.51]],"ltp":1.2,"tv":999.25,"id":2284304}]}]}
{"op":"mcm","clk":"1003147448","pt":1580648452123,"mc":[{"id":"1.168224581","rc":[{"batl":[[0,8.6,42.45],[1,8.6,0]],"ltp":6.0,"tv":155.26,"id":7797764},{"batb":[[0,1.12,204.73],[1,1.01,15.51],[2,1.01,0]],"ltp":1.2,"tv":999.25,"id":2284304}]}]}
{"op":"mcm","clk":"1003147670","pt":1580648453156,"mc":[{"id":"1.168224581","rc":[{"batb":[[1,1.11,364.67],[2,1.1,785.09]],"batl":[[0,1.26,271.9],[1,1.27,364.49],[2,1.56,675.59]],"ltp":1.2,"tv":999.25,"id":2284304}]}]}
{"op":"mcm","clk":"1003147873","pt":1580648454332,"mc":[{"id":"1.168224581","rc":[{"batb":[[1,1.01,15.51],[2,1.1,0]],"ltp":1.2,"tv":999.25,"id":2284304}]}]}
{"op":"mcm","clk":"1003148432","pt":1580648457409,"mc":[{"id":"1.168224581","rc":[{"batb":[[1,3.5,15.66],[2,1.01,15.51]],"batl":[[0,5.2,9.24]],"ltp":6.0,"tv":155.26,"id":7797764},{"trd":[[1.23,154]],"batb":[[0,1.24,264.58],[1,1.23,411.07],[2,1.22,493.42]],"ltp":1.23,"tv":1153.25,"id":2284304}],"tv":1308.51}]}
{"op":"mcm","clk":"1003148760","pt":1580648459457,"mc":[{"id":"1.168224581","rc":[{"batl":[[0,5.1,10.08],[1,7.2,45.41]],"ltp":6.0,"tv":155.26,"id":7797764}]}]}
{"op":"mcm","clk":"1003148919","pt":1580648460577,"mc":[{"id":"1.168224581","rc":[{"batb":[[1,1.23,459.85]],"ltp":1.23,"tv":1153.25,"id":2284304}]}]}
{"op":"mcm","clk":"1003149336","pt":1580648463072,"mc":[{"id":"1.168224581","rc":[{"trd":[[1.24,261.76]],"batb":[[0,1.24,198.4]],"ltp":1.24,"tv":1285.61,"id":2284304}],"tv":1440.88}]}
{"op":"mcm","clk":"1003149672","pt":1580648464856,"mc":[{"id":"1.168224581","rc":[{"batb":[[2,1.22,500.31]],"ltp":1.24,"tv":1285.61,"id":2284304}]}]}
{"op":"mcm","clk":"1003149933","pt":1580648466484,"mc":[{"id":"1.168224581","rc":[{"trd":[[1.24,267.82]],"batb":[[0,1.24,195.37],[2,1.22,493.42]],"ltp":1.24,"tv":1291.67,"id":2284304}],"tv":1446.93}]}
{"op":"mcm","clk":"1003150122","pt":1580648467380,"mc":[{"id":"1.168224581","rc":[{"batb":[[1,1.13,192.38],[2,1.01,15.51]],"batl":[[0,1.56,675.59],[1,1.27,0],[2,1.56,0]],"ltp":1.24,"tv":1291.67,"id":2284304}]}]}
{"op":"mcm","clk":"1003150253","pt":1580648468172,"mc":[{"id":"1.168224581","rc":[{"batb":[[0,3.5,15.66],[1,1.01,15.51],[2,1.01,0]],"batl":[[0,7.2,45.41],[1,7.2,0]],"ltp":6.0,"tv":155.26,"id":7797764},{"batb":[[0,1.13,192.38],[1,1.01,15.51],[2,1.01,0]],"ltp":1.24,"tv":1291.67,"id":2284304}]}]}
{"op":"mcm","clk":"1003150638","pt":1580648470291,"mc":[{"id":"1.168224581","rc":[{"batb":[[1,1.11,690.08],[2,1.1,456.71]],"batl":[[0,1.38,288.21],[1,1.39,231.72]],"ltp":1.24,"tv":1291.67,"id":2284304}]}]}
{"op":"mcm","clk":"1003150795","pt":1580648471308,"mc":[{"id":"1.168224581","rc":[{"batb":[[0,3.55,14.87]],"ltp":6.0,"tv":155.26,"id":7797764},{"batb":[[0,1.12,198.83]],"ltp":1.24,"tv":1291.67,"id":2284304}]}]}
{"op":"mcm","clk":"1003153153","pt":1580648485227,"mc":[{"id":"1.168224581","rc":[{"batb":[[1,1.01,15.51],[2,1.1,0]],"ltp":1.24,"tv":1291.67,"id":2284304}]}]}
{"op":"mcm","clk":"1003153702","pt":1580648488437,"mc":[{"id":"1.168224581","rc":[{"batb":[[0,1.2,699.17],[1,1.19,360.81],[2,1.12,198.83]],"batl":[[0,1.23,275.9],[1,1.24,420.08]],"ltp":1.24,"tv":1291.67,"id":2284304}]}]}
{"op":"mcm","clk":"1003153850","pt":1580648489318,"mc":[{"id":"1.168224581","rc":[{"batb":[[0,1.12,198.83],[1,1.01,15.51],[2,1.12,0]],"ltp":1.24,"tv":1291.67,"id":2284304}]}]}
{"op":"mcm","clk":"1003153933","pt":1580648489798,"mc":[{"id":"1.168224581","rc":[{"batl":[[0,7.8,44.14]],"ltp":6.0,"tv":155.26,"id":7797764},{"batl":[[0,1.56,889.46]],"ltp":1.24,"tv":1291.67,"id":2284304}]}]}
{"op":"mcm","clk":"1003154328","pt":1580648492659,"mc":[{"id":"1.168224581","rc":[{"batb":[[1,1.11,690.08],[2,1.1,456.71]],"batl":[[0,1.38,288.21],[1,1.39,231.72],[2,1.56,889.46]],"ltp":1.24,"tv":1291.67,"id":2284304}]}]}
{"op":"mcm","clk":"1003156846","pt":1580648507247,"mc":[{"id":"1.168224581","rc":[{"batb":[[1,1.01,15.51],[2,1.1,0]],"batl":[[0,1.56,889.46],[1,1.39,0],[2,1.56,0]],"ltp":1.24,"tv":1291.67,"id":2284304}]}]}
{"op":"mcm","clk":"1003157467","pt":1580648510400,"mc":[{"id":"1.168224581","rc":[{"batb":[[1,1.11,685.86],[2,1.1,453.91]],"batl":[[0,1.13,659.38],[1,1.14,452.2]],"ltp":1.24,"tv":1291.67,"id":2284304}]}]}
{"op":"mcm","clk":"1003157627","pt":1580648511184,"mc":[{"id":"1.168224581","rc":[{"batb":[[0,7.2,11.09],[1,5.7,19.75],[2,1.01,15.51]],"batl":[[0,9.6,4.2]],"ltp":6.0,"tv":155.26,"id":7797764}]}]}
{"op":"mcm","clk":"1003157832","pt":1580648512296,"mc":[{"id":"1.168224581","rc":[{"batb":[[0,7.8,43.93],[1,7.2,11.09],[2,5.7,19.75]],"ltp":6.0,"tv":155.26,"id":7797764}]}]}
{"op":"mcm","clk":"1003158035","pt":1580648513471,"mc":[{"id":"1.168224581","rc":[{"batb":[[0,7.2,11.09],[1,5.7,19.75],[2,1.01,15.51]],"ltp":6.0,"tv":155.26,"id":7797764}]}]}
{"op":"mcm","clk":"1003158156","pt":1580648514167,"mc":[{"id":"1.168224581","rc":[{"batl":[[1,14,37.99]],"ltp":6.0,"tv":155.26,"id":7797764},{"batl":[[2,1.43,1105.55]],"ltp":1.24,"tv":1291.67,"id":2284304}]}]}
{"op":"mcm","clk":"1003164170","pt":1580648547455,"mc":[{"id":"1.168224581","rc":[{"batb":[[1,1.09,251.39],[2,1.01,15.51]],"batl":[[0,1.43,1105.55],[1,1.14,0],[2,1.43,0]],"ltp":1.24,"tv":1291.67,"id":2284304}]}]}
{"op":"mcm","clk":"1003164524","pt":1580648549371,"mc":[{"id":"1.168224581","rc":[{"batb":[[0,5.7,19.75],[1,1.01,15.51],[2,1.01,0]],"ltp":6.0,"tv":155.26,"id":7797764},{"batb":[[0,1.09,251.39],[1,1.01,15.51],[2,1.01,0]],"ltp":1.24,"tv":1291.67,"id":2284304}]}]}
{"op":"mcm","clk":"1003164707","pt":1580648550386,"mc":[{"id":"1.168224581","rc":[{"batl":[[0,14,37.99],[1,14,0]],"ltp":6.0,"tv":155.26,"id":7797764},{"batb":[[0,1.09,1022.16],[1,1.08,389.32],[2,1.01,15.51]],"batl":[[0,1.18,704.24],[1,1.19,361],[2,1.43,1105.55]],"ltp":1.24,"tv":1291.67,"id":2284304}]}]}
{"op":"mcm","clk":"1003164897","pt":1580648551404,"mc":[{"id":"1.168224581","rc":[{"batb":[[0,1.09,251.39],[1,1.01,15.51],[2,1.01,0]],"batl":[[0,1.43,1105.55],[1,1.19,0],[2,1.43,0]],"ltp":1.24,"tv":1291.67,"id":2284304}]}]}
{"op":"mcm","clk":"1003165066","pt":1580648552256,"mc":[{"id":"1.168224581","rc":[{"batb":[[0,5.8,19.12]],"ltp":6.0,"tv":155.26,"id":7797764}]}]}
{"op":"mcm","clk":"1003165206","pt":1580648553090,"mc":[{"id":"1.168224581","rc":[{"batb":[[0,1.13,378.62],[1,1.09,251.39],[2,1.01,15.51]],"ltp":1.24,"tv":1291.67,"id":2284304}]}]}
{"op":"mcm","clk":"1003165466","pt":1580648554480,"mc":[{"id":"1.168224581","rc":[{"batb":[[1,1.12,493.12],[2,1.11,638.12]],"batl":[[0,1.14,676.76],[1,1.15,425.3],[2,1.43,1105.55]],"ltp":1.24,"tv":1291.67,"id":2284304}]}]}
{"op":"mcm","clk":"1003166490","pt":1580648559800,"mc":[{"id":"1.168224581","rc":[{"batb":[[1,1.09,251.39],[2,1.01,15.51]],"batl":[[0,1.43,1105.55],[1,1.15,0],[2,1.43,0]],"ltp":1.24,"tv":1291.67,"id":2284304}]}]}
{"op":"mcm","clk":"1003167196","pt":1580648563467,"mc":[{"id":"1.168224581","rc":[{"batb":[[0,1.09,1022.16],[1,1.08,389.32]],"ltp":1.24,"tv":1291.67,"id":2284304}]}]}
{"op":"mcm","clk":"1003167779","pt":1580648566431,"mc":[{"id":"1.168224581","rc":[{"batb":[[0,8.8,7.24],[1,7,12.43],[2,1.01,15.51]],"ltp":6.0,"tv":155.26,"id":7797764},{"batb":[[2,1.07,317.48]],"batl":[[0,1.11,964.82],[1,1.12,169.33],[2,1.43,1105.55]],"ltp":1.24,"tv":1291.67,"id":2284304}]}]}
{"op":"mcm","clk":"1003167907","pt":1580648567169,"mc":[{"id":"1.168224581","rc":[{"batl":[[0,11.5,3.36]],"ltp":6.0,"tv":155.26,"id":7797764},{"batb":[[1,1.08,276.55]],"batl":[[0,1.11,855.37]],"ltp":1.24,"tv":1291.67,"id":2284304}]}]}
{"op":"mcm","clk":"1003168356","pt":1580648569384,"mc":[{"id":"1.168224581","rc":[{"batb":[[0,1.09,1133.9]],"batl":[[1,1.12,277.81]],"ltp":1.24,"tv":1291.67,"id":2284304}]}]}
{"op":"mcm","clk":"1003168404","pt":1580648569701,"mc":[{"id":"1.168224581","rc":[{"batl":[[1,17,37.06]],"ltp":6.0,"tv":155.26,"id":7797764},{"batb":[[1,1.08,225.73]],"batl":[[0,1.11,806.04]],"ltp":1.24,"tv":1291.67,"id":2284304}]}]}
{"op":"mcm","clk":"1003168928","pt":1580648572598,"mc":[{"id":"1.168224581","rc":[{"batb":[[0,1.09,1184.25]],"batl":[[1,1.12,461.12]],"ltp":1.24,"tv":1291.67,"id":2284304}]}]}
{"op":"mcm","clk":"1003169497","pt":1580648575428,"mc":[{"id":"1.168224581","rc":[{"batl":[[1,1.12,326.69]],"ltp":1.24,"tv":1291.67,"id":2284304}]}]}
{"op":"mcm","clk":"1003170561","pt":1580648581035,"mc":[{"id":"1.168224581","rc":[{"batb":[[0,7,12.43],[1,1.01,15.51],[2,1.01,0]],"ltp":6.0,"tv":155.26,"id":7797764},{"batb":[[0,1.08,225.73],[1,1.07,317.48],[2,1.01,15.51]],"batl":[[0,1.43,1105.55],[1,1.12,0],[2,1.43,0]],"ltp":1.24,"tv":1291.67,"id":2284304}]}]}
{"op":"mcm","clk":"1003170800","pt":1580648582314,"mc":[{"id":"1.168224581","rc":[{"batl":[[0,17,37.06],[1,17,0]],"ltp":6.0,"tv":155.26,"id":7797764}]}]}
{"op":"mcm","clk":"1003170862","pt":1580648582677,"mc":[{"id":"1.168224581","rc":[{"batb":[[0,1.11,378.62],[1,1.08,225.73],[2,1.07,317.48]],"ltp":1.24,"tv":1291.67,"id":2284304}]}]}
{"op":"mcm","clk":"1003171048","pt":1580648583590,"mc":[{"id":"1.168224581","rc":[{"batb":[[1,1.08,302.14],[2,1.07,1190.65]],"batl":[[0,1.14,378.58],[1,1.15,705.87],[2,1.43,1105.55]],"ltp":1.24,"tv":1291.67,"id":2284304}]}]}
{"op":"mcm","clk":"1003171698","pt":1580648586987,"mc":[{"id":"1.168224581","rc":[{"batl":[[0,1.43,1105.55],[1,1.15,0],[2,1.43,0]],"ltp":1.24,"tv":1291.67,"id":2284304}]}]}
{"op":"mcm","clk":"1003172316","pt":1580648590118,"mc":[{"id":"1.168224581","rc":[{"trd":[[1.11,757.24]],"batb":[[0,1.08,302.14],[1,1.07,1046.51],[2,1.01,15.51]],"batl":[[0,1.09,99.82],[1,1.1,671.92]],"ltp":1.11,"tv":2048.91,"id":2284304}],"tv":2204.17}]}
{"op":"mcm","clk":"1003172537","pt":1580648591203,"mc":[{"id":"1.168224581","rc":[{"batb":[[0,10,13.06],[1,8.4,8.03],[2,1.01,15.51]],"batl":[[0,13.5,3.36]],"ltp":6.0,"tv":155.26,"id":7797764},{"batb":[[0,1.08,470.18],[2,1.06,381.76]],"batl":[[2,1.11,272.15]],"ltp":1.11,"tv":2048.91,"id":2284304}]}]}
{"op":"mcm","clk":"1003172769","pt":1580648592399,"mc":[{"id":"1.168224581","rc":[{"batl":[[1,24,36.04]],"ltp":6.0,"tv":155.26,"id":7797764},{"batl":[[2,1.11,230.14]],"ltp":1.11,"tv":2048.91,"id":2284304}]}]}
{"op":"mcm","clk":"1003172885","pt":1580648592980,"mc":[{"id":"1.168224581","rc":[{"batb":[[0,1.08,612.99]],"batl":[[0,1.09,337.31],[1,1.1,811.76]],"ltp":1.11,"tv":2048.91,"id":2284304}]}]}
{"op":"mcm","clk":"1003174573","pt":1580648602040,"mc":[{"id":"1.168224581","rc":[{"batl":[[2,1.37,1253.98]],"ltp":1.11,"tv":2048.91,"id":2284304}]}]}
{"op":"mcm","clk":"1003175202","pt":1580648605316,"mc":[{"id":"1.168224581","rc":[{"batb":[[0,1.08,168.04],[1,1.07,968.89]],"batl":[[0,1.37,1253.98],[1,1.1,0],[2,1.37,0]],"ltp":1.11,"tv":2048.91,"id":2284304}]}]}
{"op":"mcm","clk":"1003175377","pt":1580648606298,"mc":[{"id":"1.168224581","rc":[{"batb":[[0,8.4,8.03],[1,1.01,15.51],[2,1.01,0]],"batl":[[0,24,36.04],[1,24,0]],"ltp":6.0,"tv":155.26,"id":7797764},{"batb":[[0,1.07,651.41],[1,1.06,381.76],[2,1.01,15.51]],"ltp":1.11,"tv":2048.91,"id":2284304}]}]}
{"op":"mcm","clk":"1003175714","pt":1580648608198,"mc":[{"id":"1.168224581","rc":[{"batb":[[1,1.06,913.46]],"batl":[[0,1.11,270.8],[1,1.12,857.16],[2,1.37,1253.98]],"ltp":1.11,"tv":2048.91,"id":2284304}]}]}
{"op":"mcm","clk":"1003175970","pt":1580648609432,"mc":[{"id":"1.168224581","rc":[{"batl":[[0,1.37,1253.98],[1,1.12,0],[2,1.37,0]],"ltp":1.11,"tv":2048.91,"id":2284304}]}]}
{"op":"mcm","clk":"1003176606","pt":1580648612485,"mc":[{"id":"1.168224581","rc":[{"batb":[[1,1.06,819.92]],"batl":[[0,1.08,242.85],[1,1.09,825.08],[2,1.37,1253.98]],"ltp":1.11,"tv":2048.91,"id":2284304}]}]}
{"op":"mcm","clk":"1003176724","pt":1580648613121,"mc":[{"id":"1.168224581","rc":[{"batb":[[0,11.5,9.52],[1,10,13.22],[2,1.01,15.51]],"ltp":6.0,"tv":155.26,"id":7797764},{"batb":[[2,1.05,421.34]],"ltp":1.11,"tv":2048.91,"id":2284304}]}]}
{"op":"mcm","clk":"1003177313","pt":1580648616206,"mc":[{"id":"1.168224581","rc":[{"batb":[[0,1.07,744.07]],"batl":[[1,1.09,915.89]],"ltp":1.11,"tv":2048.91,"id":2284304}]}]}
{"op":"mcm","clk":"1003180291","pt":1580648631284,"mc":[{"id":"1.168224581","rc":[{"batb":[[0,10,13.22],[1,1.01,15.51],[2,1.01,0]],"ltp":6.0,"tv":155.26,"id":7797764},{"batb":[[0,1.05,421.34],[1,1.01,15.51],[2,1.05,0]],"batl":[[0,1.37,1253.98],[1,1.09,0],[2,1.37,0]],"ltp":1.11,"tv":2048.91,"id":2284304}]}]}
{"op":"mcm","clk":"1003182264","pt":1580648641165,"mc":[{"id":"1.168224581","rc":[{"batb":[[0,1.07,1034.46],[1,1.05,421.34],[2,1.01,15.51]],"batl":[[0,1.09,1156.52],[1,1.37,1253.98]],"ltp":1.11,"tv":2048.91,"id":2284304}]}]}
{"op":"mcm","clk":"1003182491","pt":1580648642287,"mc":[{"id":"1.168224581","rc":[{"batb":[[0,1.05,421.34],[1,1.01,15.51],[2,1.01,0]],"batl":[[0,1.09,272.98]],"ltp":1.11,"tv":2048.91,"id":2284304}]}]}
{"op":"mcm","clk":"1003182947","pt":1580648644756,"mc":[{"id":"1.168224581","rc":[{"batb":[[0,1.06,1189.26],[1,1.05,421.34],[2,1.01,15.51]],"batl":[[1,1.1,875.51],[2,1.37,1253.98]],"ltp":1.11,"tv":2048.91,"id":2284304}]}]}
{"op":"mcm","clk":"1003184099","pt":1580648650963,"mc":[{"id":"1.168224581","rc":[{"batl":[[1,1.37,1253.98],[2,1.37,0]],"ltp":1.11,"tv":2048.91,"id":2284304}]}]}
{"op":"mcm","clk":"1003184716","pt":1580648654486,"mc":[{"id":"1.168224581","rc":[{"batl":[[0,1.08,912.83],[1,1.09,272.98],[2,1.37,1253.98]],"ltp":1.11,"tv":2048.91,"id":2284304}]}]}
{"op":"mcm","clk":"1003184816","pt":1580648655212,"mc":[{"id":"1.168224581","rc":[{"batb":[[0,12.5,8.03],[1,10.5,11.88],[2,1.01,15.51]],"ltp":6.0,"tv":155.26,"id":7797764},{"batb":[[2,1.04,567.14]],"ltp":1.11,"tv":2048.91,"id":2284304}]}]}
{"op":"mcm","clk":"1003185222","pt":1580648657471,"mc":[{"id":"1.168224581","rc":[{"batl":[[0,30,35.63]],"ltp":6.0,"tv":155.26,"id":7797764}]}]}
{"op":"mcm","clk":"1003187879","pt":1580648672639,"mc":[{"id":"1.168224581","rc":[{"batl":[[1,1.09,223.61]],"ltp":1.11,"tv":2048.91,"id":2284304}]}]}
{"op":"mcm","clk":"1003197155","pt":1580648723293,"mc":[{"id":"1.168224581","rc":[{"batb":[[0,10.5,11.88],[1,1.01,15.51],[2,1.01,0]],"ltp":6.0,"tv":155.26,"id":7797764},{"batb":[[0,1.04,567.14],[1,1.01,15.51],[2,1.04,0]],"batl":[[0,1.09,223.61],[1,1.37,1253.98],[2,1.37,0]],"ltp":1.11,"tv":2048.91,"id":2284304}]}]}
{"op":"mcm","clk":"1003197627","pt":1580648725785,"mc":[{"id":"1.168224581","rc":[{"batb":[[0,1.05,867.1],[1,1.04,903.62],[2,1.01,15.51]],"batl":[[0,1.09,403.4],[1,1.1,746.07],[2,1.37,1253.98]],"ltp":1.11,"tv":2048.91,"id":2284304}]}]}
{"op":"mcm","clk":"1003198483","pt":1580648730760,"mc":[{"id":"1.168224581","rc":[{"batb":[[0,1.04,567.14],[1,1.01,15.51],[2,1.01,0]],"ltp":1.11,"tv":2048.91,"id":2284304}]}]}
{"op":"mcm","clk":"1003199139","pt":1580648734237,"mc":[{"id":"1.168224581","rc":[{"batb":[[1,9.2,15.97],[2,1.01,15.51]],"ltp":6.0,"tv":155.26,"id":7797764},{"batb":[[0,1.08,366.17],[1,1.07,1143.52],[2,1.05,430.31]],"ltp":1.11,"tv":2048.91,"id":2284304}]}]}
{"op":"mcm","clk":"1003199690","pt":1580648737339,"mc":[{"id":"1.168224581","rc":[{"batl":[[0,24,36.04]],"ltp":6.0,"tv":155.26,"id":7797764}]}]}
{"op":"mcm","clk":"1003201591","pt":1580648748163,"mc":[{"id":"1.168224581","rc":[{"batb":[[0,9.2,15.97],[1,1.01,15.51],[2,1.01,0]],"ltp":6.0,"tv":155.26,"id":7797764},{"batb":[[0,1.05,430.31],[1,1.01,15.51],[2,1.05,0]],"batl":[[0,1.37,1253.98],[1,1.1,0],[2,1.37,0]],"ltp":1.11,"tv":2048.91,"id":2284304}]}]}
{"op":"mcm","clk":"1003202692","pt":1580648754153,"mc":[{"id":"1.168224581","rc":[{"batb":[[0,1.07,1177.94],[1,1.05,430.31],[2,1.01,15.51]],"batl":[[0,1.09,799.48],[1,1.1,353.6],[2,1.37,1253.98]],"ltp":1.11,"tv":2048.91,"id":2284304}]}]}
{"op":"mcm","clk":"1003202941","pt":1580648755492,"mc":[{"id":"1.168224581","rc":[{"batb":[[0,1.05,430.31],[1,1.01,15.51],[2,1.01,0]],"batl":[[0,1.37,1253.98],[1,1.1,0],[2,1.37,0]],"ltp":1.11,"tv":2048.91,"id":2284304}]}]}
{"op":"mcm","clk":"1003203427","pt":1580648758312,"mc":[{"id":"1.168224581","rc":[{"batb":[[0,1.06,1189.05],[1,1.05,430.31],[2,1.01,15.51]],"batl":[[0,1.11,1135.49],[1,1.37,1253.98]],"ltp":1.11,"tv":2048.91,"id":2284304}]}]}
{"op":"mcm","clk":"1003205035","pt":1580648767446,"mc":[{"id":"1.168224581","rc":[{"batb":[[0,1.05,430.31],[1,1.01,15.51],[2,1.01,0]],"ltp":1.11,"tv":2048.91,"id":2284304}]}]}
{"op":"mcm","clk":"1003205573","pt":1580648770382,"mc":[{"id":"1.168224581","rc":[{"batb":[[0,1.09,499.13],[1,1.08,663.27],[2,1.05,430.31]],"ltp":1.11,"tv":2048.91,"id":2284304}]}]}
{"op":"mcm","clk":"1003205765","pt":1580648771381,"mc":[{"id":"1.168224581","rc":[{"batb":[[1,8.6,7.47],[2,1.01,15.51]],"batl":[[0,13.5,3.36]],"ltp":6.0,"tv":155.26,"id":7797764},{"batb":[[1,1.08,1113.3],[2,1.07,336.68]],"ltp":1.11,"tv":2048.91,"id":2284304}]}]}
{"op":"mcm","clk":"1003206117","pt":1580648772858,"mc":[{"id":"1.168224581","rc":[{"batl":[[1,21,36.46]],"ltp":6.0,"tv":155.26,"id":7797764}]}]}
{"op":"mcm","clk":"1003208803","pt":1580648787289,"mc":[{"id":"1.168224581","rc":[{"batb":[[0,8.6,7.47],[1,1.01,15.51],[2,1.01,0]],"ltp":6.0,"tv":155.26,"id":7797764},{"batb":[[0,1.08,548.72],[1,1.07,334.48],[2,1.01,15.51]],"batl":[[0,1.11,242.68]],"ltp":1.11,"tv":2048.91,"id":2284304}]}]}
{"op":"mcm","clk":"1003209029","pt":1580648788377,"mc":[{"id":"1.168224581","rc":[{"batl":[[0,21,36.46],[1,21,0]],"ltp":6.0,"tv":155.26,"id":7797764},{"batb":[[0,1.08,380.68]],"ltp":1.11,"tv":2048.91,"id":2284304}]}]}
{"op":"mcm","clk":"1003210000","pt":1580648793457,"mc":[{"id":"1.168224581","rc":[{"batb":[[0,1.09,204.91],[1,1.08,960.21],[2,1.07,334.48]],"batl":[[0,1.1,408.99],[1,1.11,730.17],[2,1.37,1253.98]],"ltp":1.11,"tv":2048.91,"id":2284304}]}]}
{"op":"mcm","clk":"1003210595","pt":1580648796846,"mc":[{"id":"1.168224581","rc":[{"batb":[[0,1.08,380.68],[1,1.07,334.48],[2,1.01,15.51]],"batl":[[0,1.11,242.68],[1,1.37,1253.98],[2,1.37,0]],"ltp":1.11,"tv":2048.91,"id":2284304}]}]}
{"op":"mcm","clk":"1003211030","pt":1580648798892,"mc":[{"id":"1.168224581","rc":[{"batl":[[0,1.37,1253.98],[1,1.37,0]],"ltp":1.11,"tv":2048.91,"id":2284304}]}]}
{"op":"mcm","clk":"1003211336","pt":1580648800384,"mc":[{"id":"1.168224581","rc":[{"batb":[[1,1.07,1128.17]],"ltp":1.11,"tv":2048.91,"id":2284304}]}]}
{"op":"mcm","clk":"1003211699","pt":1580648802279,"mc":[{"id":"1.168224581","rc":[{"batb":[[0,10.5,11.96],[1,9.2,16.44],[2,8.6,7.47]],"ltp":6.0,"tv":155.26,"id":7797764},{"batb":[[2,1.05,444.08]],"batl":[[0,1.09,390.4],[1,1.1,758.95],[2,1.11,230.14]],"ltp":1.11,"tv":2048.91,"id":2284304}]}]}
{"op":"mcm","clk":"1003211760","pt":1580648802596,"mc":[{"id":"1.168224581","rc":[{"batb":[[2,1.01,15.51]],"ltp":6.0,"tv":155.26,"id":7797764}]}]}
{"op":"mcm","clk":"1003212059","pt":1580648804296,"mc":[{"id":"1.168224581","rc":[{"batl":[[0,24,36.04]],"ltp":6.0,"tv":155.26,"id":7797764}]}]}
{"op":"mcm","clk":"1003213973","pt":1580648814456,"mc":[{"id":"1.168224581","rc":[{"batb":[[0,1.07,334.48],[1,1.05,444.08],[2,1.01,15.51]],"batl":[[0,1.37,1253.98],[1,1.1,0],[2,1.11,0]],"ltp":1.11,"tv":2048.91,"id":2284304}]}]}
{"op":"mcm","clk":"1003214032","pt":1580648814772,"mc":[{"id":"1.168224581","rc":[{"batb":[[0,9.2,16.44],[1,1.01,15.51],[2,1.01,0]],"ltp":6.0,"tv":155.26,"id":7797764},{"batb":[[0,1.05,444.08],[1,1.01,15.51],[2,1.01,0]],"ltp":1.11,"tv":2048.91,"id":2284304}]}]}
{"op":"mcm","clk":"1003214484","pt":1580648817253,"mc":[{"id":"1.168224581","rc":[{"batb":[[0,1.06,1098.33],[1,1.05,444.08],[2,1.01,15.51]],"batl":[[0,1.11,933.09],[1,1.12,200.58],[2,1.37,1253.98]],"ltp":1.11,"tv":2048.91,"id":2284304}]}]}
{"op":"mcm","clk":"1003215155","pt":1580648820358,"mc":[{"id":"1.168224581","rc":[{"batb":[[0,1.05,444.08],[1,1.01,15.51],[2,1.01,0]],"ltp":1.11,"tv":2048.91,"id":2284304}]}]}
{"op":"mcm","clk":"1003215764","pt":1580648823467,"mc":[{"id":"1.168224581","rc":[{"batb":[[1,8.6,7.79],[2,1.01,15.51]],"batl":[[0,13,3.36]],"ltp":6.0,"tv":155.26,"id":7797764},{"batb":[[0,1.09,1024.26],[1,1.08,580.93],[2,1.07,323.15]],"ltp":1.11,"tv":2048.91,"id":2284304}]}]}
{"op":"mcm","clk":"1003216120","pt":1580648825461,"mc":[{"id":"1.168224581","rc":[{"batl":[[1,21,36.46]],"ltp":6.0,"tv":155.26,"id":7797764}]}]}
{"op":"mcm","clk":"1003217371","pt":1580648832465,"mc":[{"id":"1.168224581","rc":[{"trd":[[1.11,772.38]],"batl":[[0,1.11,925.52]],"ltp":1.11,"tv":2064.05,"id":2284304}],"tv":2219.31}]}
{"op":"mcm","clk":"1003217491","pt":1580648833226,"mc":[{"id":"1.168224581","rc":[{"batb":[[0,8.6,7.79],[1,1.01,15.51],[2,1.01,0]],"ltp":6.0,"tv":155.26,"id":7797764},{"batb":[[0,1.08,580.93],[1,1.07,323.15],[2,1.01,15.51]],"batl":[[0,1.12,200.58],[1,1.37,1253.98],[2,1.37,0]],"ltp":1.11,"tv":2064.05,"id":2284304}]}]}
{"op":"mcm","clk":"1003217701","pt":1580648834433,"mc":[{"id":"1.168224581","rc":[{"batl":[[0,21,36.46],[1,21,0]],"ltp":6.0,"tv":155.26,"id":7797764},{"batb":[[0,1.08,412.89]],"ltp":1.11,"tv":2064.05,"id":2284304}]}]}
{"op":"mcm","clk":"1003217884","pt":1580648835475,"mc":[{"id":"1.168224581","rc":[{"batb":[[0,1.08,746.28],[1,1.07,747.82]],"batl":[[0,1.12,985.02]],"ltp":1.11,"tv":2064.05,"id":2284304}]}]}
{"op":"mcm","clk":"1003218077","pt":1580648836476,"mc":[{"id":"1.168224581","rc":[{"batb":[[0,1.07,323.15],[1,1.01,15.51],[2,1.01,0]],"ltp":1.11,"tv":2064.05,"id":2284304}]}]}
{"op":"mcm","clk":"1003218625","pt":1580648839366,"mc":[{"id":"1.168224581","rc":[{"batb":[[0,1.1,440.88],[1,1.09,716.11],[2,1.07,323.15]],"ltp":1.11,"tv":2064.05,"id":2284304}]}]}
{"op":"mcm","clk":"1003218802","pt":1580648840298,"mc":[{"id":"1.168224581","rc":[{"batb":[[1,6.2,15.5],[2,1.01,15.51]],"ltp":6.0,"tv":155.26,"id":7797764},{"batb":[[0,1.1,687.31]],"ltp":1.11,"tv":2064.05,"id":2284304}]}]}
{"op":"mcm","clk":"1003218993","pt":1580648841366,"mc":[{"id":"1.168224581","rc":[{"batl":[[0,12.5,3.36]],"ltp":6.0,"tv":155.26,"id":7797764}]}]}
{"op":"mcm","clk":"1003219232","pt":1580648842665,"mc":[{"id":"1.168224581","rc":[{"batl":[[1,17,37.06]],"ltp":6.0,"tv":155.26,"id":7797764}]}]}
{"op":"mcm","clk":"1003223675","pt":1580648867109,"mc":[{"id":"1.168224581","rc":[{"batb":[[0,6.2,15.5],[1,1.01,15.51],[2,1.01,0]],"ltp":6.0,"tv":155.26,"id":7797764},{"batb":[[0,1.07,323.15],[1,1.01,15.51],[2,1.07,0]],"batl":[[0,1.37,1253.98],[1,1.37,0]],"ltp":1.11,"tv":2064.05,"id":2284304}]}]}
{"op":"mcm","clk":"1003223930","pt":1580648868414,"mc":[{"id":"1.168224581","rc":[{"batl":[[0,17,37.06],[1,17,0]],"ltp":6.0,"tv":155.26,"id":7797764}]}]}
{"op":"mcm","clk":"1003224112","pt":1580648869421,"mc":[{"id":"1.168224581","rc":[{"batb":[[0,1.08,294.02],[1,1.07,1209.12],[2,1.01,15.51]],"batl":[[0,1.17,720.11],[1,1.18,358.47],[2,1.37,1253.98]],"ltp":1.11,"tv":2064.05,"id":2284304}]}]}
{"op":"mcm","clk":"1003224965","pt":1580648874239,"mc":[{"id":"1.168224581","rc":[{"batb":[[0,1.07,323.15],[1,1.01,15.51],[2,1.01,0]],"batl":[[0,1.37,1253.98],[1,1.18,0],[2,1.37,0]],"ltp":1.11,"tv":2064.05,"id":2284304}]}]}
{"op":"mcm","clk":"1003225574","pt":1580648877432,"mc":[{"id":"1.168224581","rc":[{"batb":[[0,1.08,294.02],[1,1.07,1377.16],[2,1.01,15.51]],"batl":[[0,1.09,466.34],[1,1.1,688.39],[2,1.37,1253.98]],"ltp":1.11,"tv":2064.05,"id":2284304}]}]}
{"op":"mcm","clk":"1003225723","pt":1580648878231,"mc":[{"id":"1.168224581","rc":[{"batb":[[0,10,12.51],[1,7.8,9.6],[2,1.01,15.51]],"ltp":6.0,"tv":155.26,"id":7797764},{"batb":[[2,1.05,418.12]],"ltp":1.11,"tv":2064.05,"id":2284304}]}]}
{"op":"mcm","clk":"1003226074","pt":1580648880095,"mc":[{"id":"1.168224581","rc":[{"batl":[[0,24,36.04]],"ltp":6.0,"tv":155.26,"id":7797764}]}]}
{"op":"mcm","clk":"1003227836","pt":1580648889212,"mc":[{"id":"1.168224581","rc":[{"batb":[[0,1.07,491.19],[1,1.05,418.12],[2,1.01,15.51]],"batl":[[0,1.37,1253.98],[1,1.1,0],[2,1.37,0]],"ltp":1.11,"tv":2064.05,"id":2284304}]}]}
{"op":"mcm","clk":"1003228050","pt":1580648890437,"mc":[{"id":"1.168224581","rc":[{"batb":[[0,7.8,9.6],[1,1.01,15.51],[2,1.01,0]],"ltp":6.0,"tv":155.26,"id":7797764},{"batb":[[0,1.05,418.12],[1,1.01,15.51],[2,1.01,0]],"ltp":1.11,"tv":2064.05,"id":2284304}]}]}
{"op":"mcm","clk":"1003228458","pt":1580648892451,"mc":[{"id":"1.168224581","rc":[{"batb":[[0,1.06,1193.9],[1,1.05,418.12],[2,1.01,15.51]],"batl":[[0,1.13,786.34],[1,1.14,330.67],[2,1.37,1253.98]],"ltp":1.11,"tv":2064.05,"id":2284304}]}]}
{"op":"mcm","clk":"1003228969","pt":1580648894947,"mc":[{"id":"1.168224581","rc":[{"batb":[[0,1.05,418.12],[1,1.01,15.51],[2,1.01,0]],"batl":[[0,1.37,1253.98],[1,1.14,0],[2,1.37,0]],"ltp":1.11,"tv":2064.05,"id":2284304}]}]}
{"op":"mcm","clk":"1003229625","pt":1580648898334,"mc":[{"id":"1.168224581","rc":[{"batb":[[0,1.08,1171.79],[1,1.05,418.12],[2,1.01,15.51]],"batl":[[0,1.1,787.41],[1,1.11,359.8],[2,1.37,1253.98]],"ltp":1.11,"tv":2064.05,"id":2284304}]}]}
{"op":"mcm","clk":"1003229853","pt":1580648899442,"mc":[{"id":"1.168224581","rc":[{"batl":[[0,1.1,738.7]],"ltp":1.11,"tv":2064.05,"id":2284304}]}]}
{"op":"mcm","clk":"1003230380","pt":1580648902379,"mc":[{"id":"1.168224581","rc":[{"batl":[[1,1.11,408.07]],"ltp":1.11,"tv":2064.05,"id":2284304}]}]}
{"op":"mcm","clk":"1003230875","pt":1580648905036,"mc":[{"id":"1.168224581","rc":[{"batb":[[0,1.05,418.12],[1,1.01,15.51],[2,1.01,0]],"batl":[[0,1.37,1253.98],[1,1.11,0],[2,1.37,0]],"ltp":1.11,"tv":2064.05,"id":2284304}]}]}
{"op":"mcm","clk":"1003231459","pt":1580648908273,"mc":[{"id":"1.168224581","rc":[{"batb":[[0,1.06,1193.9],[1,1.05,418.12],[2,1.01,15.51]],"batl":[[0,1.13,738.72],[1,1.14,377.88],[2,1.37,1253.98]],"ltp":1.11,"tv":2064.05,"id":2284304}]}]}
{"op":"mcm","clk":"1003232731","pt":1580648915245,"mc":[{"id":"1.168224581","rc":[{"batl":[[0,1.37,1253.98],[1,1.14,0],[2,1.37,0]],"ltp":1.11,"tv":2064.05,"id":2284304}]}]}
{"op":"mcm","clk":"1003233261","pt":1580648918336,"mc":[{"id":"1.168224581","rc":[{"batl":[[0,1.08,1171.79],[1,1.37,1253.98]],"ltp":1.11,"tv":2064.05,"id":2284304}]}]}
{"op":"mcm","clk":"1003233440","pt":1580648919306,"mc":[{"id":"1.168224581","rc":[{"batb":[[0,12.5,8.1],[1,9.8,14.16],[2,1.01,15.51]],"ltp":6.0,"tv":155.26,"id":7797764},{"batb":[[2,1.04,509.07]],"ltp":1.11,"tv":2064.05,"id":2284304}]}]}
{"op":"mcm","clk":"1003233797","pt":1580648921294,"mc":[{"id":"1.168224581","rc":[{"batl":[[0,30,35.63]],"ltp":6.0,"tv":155.26,"id":7797764}]}]}
{"op":"mcm","clk":"1003236944","pt":1580648938292,"mc":[{"id":"1.168224581","rc":[{"batb":[[0,1.05,418.12],[1,1.04,509.07],[2,1.01,15.51]],"batl":[[0,1.37,1253.98],[1,1.37,0]],"ltp":1.11,"tv":2064.05,"id":2284304}]}]}
{"op":"mcm","clk":"1003237038","pt":1580648938768,"mc":[{"id":"1.168224581","rc":[{"batb":[[0,9.8,14.16],[1,1.01,15.51],[2,1.01,0]],"ltp":6.0,"tv":155.26,"id":7797764},{"batb":[[0,1.04,509.07],[1,1.01,15.51],[2,1.01,0]],"ltp":1.11,"tv":2064.05,"id":2284304}]}]}
{"op":"mcm","clk":"1003237562","pt":1580648941464,"mc":[{"id":"1.168224581","rc":[{"batb":[[0,1.05,1205.27],[1,1.04,509.07],[2,1.01,15.51]],"ltp":1.11,"tv":2064.05,"id":2284304}]}]}
{"op":"mcm","clk":"1003238096","pt":1580648944490,"mc":[{"id":"1.168224581","rc":[{"batl":[[0,1.07,1182.74],[1,1.37,1253.98]],"ltp":1.11,"tv":2064.05,"id":2284304}]}]}
{"op":"mcm","clk":"1003238250","pt":1580648945286,"mc":[{"id":"1.168224581","rc":[{"batb":[[0,14.5,5.82],[1,12,8.34],[2,1.01,15.51]],"ltp":6.0,"tv":155.26,"id":7797764},{"batb":[[0,1.05,1373.31]],"ltp":1.11,"tv":2064.05,"id":2284304}]}]}
{"op":"mcm","clk":"1003238527","pt":1580648946825,"mc":[{"id":"1.168224581","rc":[{"batl":[[0,42,35.26]],"ltp":6.0,"tv":155.26,"id":7797764}]}]}
{"op":"mcm","clk":"1003240624","pt":1580648958436,"mc":[{"id":"1.168224581","rc":[{"batb":[[0,1.05,1018.23]],"batl":[[0,1.37,1253.98],[1,1.37,0]],"ltp":1.11,"tv":2064.05,"id":2284304}]}]}
{"op":"mcm","clk":"1003240713","pt":1580648958955,"mc":[{"id":"1.168224581","rc":[{"batb":[[0,12,8.34],[1,1.01,15.51],[2,1.01,0]],"ltp":6.0,"tv":155.26,"id":7797764}]}]}
{"op":"mcm","clk":"1003241541","pt":1580648963466,"mc":[{"id":"1.168224581","rc":[{"batb":[[0,1.05,1205.27]],"batl":[[0,1.07,1175.33],[1,1.37,1253.98]],"ltp":1.11,"tv":2064.05,"id":2284304}]}]}
{"op":"mcm","clk":"1003242750","pt":1580648969948,"mc":[{"id":"1.168224581","rc":[{"batb":[[0,1.05,1018.23]],"batl":[[0,1.37,1253.98],[1,1.37,0]],"ltp":1.11,"tv":2064.05,"id":2284304}]}]}
{"op":"mcm","clk":"1003243264","pt":1580648972894,"mc":[{"id":"1.168224581","rc":[{"batb":[[1,1.04,697.9]],"batl":[[0,1.08,1171.79],[1,1.37,1253.98]],"ltp":1.11,"tv":2064.05,"id":2284304}]}]}
{"op":"mcm","clk":"1003243840","pt":1580648975977,"mc":[{"id":"1.168224581","rc":[{"batl":[[0,1.37,1253.98],[1,1.37,0]],"ltp":1.11,"tv":2064.05,"id":2284304}]}]}
{"op":"mcm","clk":"1003244438","pt":1580648979355,"mc":[{"id":"1.168224581","rc":[{"batb":[[1,1.04,509.07]],"batl":[[0,1.06,349.5],[1,1.07,621.46],[2,1.37,1253.98]],"ltp":1.11,"tv":2064.05,"id":2284304}]}]}
{"op":"mcm","clk":"1003244548","pt":1580648980062,"mc":[{"id":"1.168224581","rc":[{"batb":[[0,15.5,4.64],[1,13.5,6.61],[2,1.01,15.51]],"ltp":6.0,"tv":155.26,"id":7797764},{"batb":[[2,1.02,816.95]],"ltp":1.11,"tv":2064.05,"id":2284304}]}]}
{"op":"mcm","clk":"1003244771","pt":1580648981353,"mc":[{"id":"1.168224581","rc":[{"trd":[[1.06,14]],"batl":[[0,1.06,342.5]],"ltp":1.06,"tv":2078.05,"id":2284304}],"tv":2233.31}]}
{"op":"mcm","clk":"1003244952","pt":1580648982372,"mc":[{"id":"1.168224581","rc":[{"batb":[[0,1.05,1205.26]],"batl":[[0,1.06,248.37],[1,1.07,836.49]],"ltp":1.06,"tv":2078.05,"id":2284304}]}]}
{"op":"mcm","clk":"1003245492","pt":1580648985261,"mc":[{"id":"1.168224581","rc":[{"batl":[[1,1.07,936.67]],"ltp":1.06,"tv":2078.05,"id":2284304}]}]}
{"op":"mcm","clk":"1003254298","pt":1580649032239,"mc":[{"id":"1.168224581","rc":[{"trd":[[1.06,510.74]],"batb":[[0,1.06,130.24],[1,1.05,1205.26],[2,1.04,509.07]],"batl":[[0,1.07,936.67],[1,1.37,1253.98],[2,1.4,7]],"ltp":1.06,"tv":2574.79,"id":2284304}],"tv":2730.05}]}
{"op":"mcm","clk":"1003254886","pt":1580649035180,"mc":[{"id":"1.168224581","rc":[{"batl":[[0,1.07,1182.73]],"ltp":1.06,"tv":2574.79,"id":2284304}]}]}
{"op":"mcm","clk":"1003255179","pt":1580649036696,"mc":[{"id":"1.168224581","rc":[{"batl":[[0,65,34.99]],"ltp":6.0,"tv":155.26,"id":7797764}]}]}
{"op":"mcm","clk":"1003255670","pt":1580649039180,"mc":[{"id":"1.168224581","rc":[{"batb":[[0,1.05,1205.26],[1,1.04,509.07],[2,1.02,816.95]],"ltp":1.06,"tv":2574.79,"id":2284304}]}]}
{"op":"mcm","clk":"1003256257","pt":1580649042123,"mc":[{"id":"1.168224581","rc":[{"batl":[[1,1.4,7],[2,1.4,0]],"ltp":1.06,"tv":2574.79,"id":2284304}]}]}
{"op":"mcm","clk":"1003257144","pt":1580649046351,"mc":[{"id":"1.168224581","rc":[{"batl":[[0,95,34.84]],"ltp":6.0,"tv":155.26,"id":7797764},{"batl":[[1,1.31,1447.26],[2,1.4,7]],"ltp":1.06,"tv":2574.79,"id":2284304}]}]}
{"op":"mcm","clk":"1003259233","pt":1580649057450,"mc":[{"id":"1.168224581","rc":[{"batb":[[0,13.5,6.61],[1,1.01,15.51],[2,1.01,0]],"ltp":6.0,"tv":155.26,"id":7797764},{"batb":[[0,1.02,816.95],[1,1.01,15.51],[2,1.02,0]],"batl":[[0,1.31,1447.26],[1,1.4,7],[2,1.4,0]],"ltp":1.06,"tv":2574.79,"id":2284304}]}]}
{"op":"mcm","clk":"1003259764","pt":1580649060074,"mc":[{"id":"1.168224581","rc":[{"batb":[[0,1.04,727.73],[1,1.03,493.86],[2,1.02,816.95]],"batl":[[0,1.08,1171.78],[1,1.31,1447.26],[2,1.4,7]],"ltp":1.06,"tv":2574.79,"id":2284304}]}]}
{"op":"mcm","clk":"1003261896","pt":1580649071011,"mc":[{"id":"1.168224581","rc":[{"trd":[[1.04,100]],"batb":[[0,1.04,677.73]],"batl":[[0,1.31,1447.26],[1,1.4,7],[2,1.4,0]],"ltp":1.04,"tv":2674.79,"id":2284304}],"tv":2830.05}]}
{"op":"mcm","clk":"1003262391","pt":1580649073486,"mc":[{"id":"1.168224581","rc":[{"batl":[[0,1.05,1185.18],[1,1.31,1447.26],[2,1.4,7]],"ltp":1.04,"tv":2674.79,"id":2284304}]}]}
{"op":"mcm","clk":"1003262711","pt":1580649075081,"mc":[{"id":"1.168224581","rc":[{"batb":[[0,20,5.27],[1,16,4.41],[2,1.01,15.51]],"ltp":6.0,"tv":155.26,"id":7797764}]}]}
{"op":"mcm","clk":"1003263367","pt":1580649078385,"mc":[{"id":"1.168224581","rc":[{"batl":[[0,160,34.73]],"ltp":6.0,"tv":155.26,"id":7797764}]}]}
{"op":"mcm","clk":"1003264706","pt":1580649085282,"mc":[{"id":"1.168224581","rc":[{"batb":[[0,16,4.41],[1,1.01,15.51],[2,1.01,0]],"ltp":6.0,"tv":155.26,"id":7797764},{"batb":[[0,1.01,15.51],[1,1.03,0],[2,1.02,0]],"batl":[[0,1.31,1447.26],[1,1.4,7],[2,1.4,0]],"ltp":1.04,"tv":2674.79,"id":2284304}]}]}
{"op":"mcm","clk":"1003265523","pt":1580649089579,"mc":[{"id":"1.168224581","rc":[{"batb":[[0,1.03,1228.66],[1,1.01,15.51]],"batl":[[0,1.05,1205.26],[1,1.31,1447.26],[2,1.4,7]],"ltp":1.04,"tv":2674.79,"id":2284304}]}]}
{"op":"mcm","clk":"1003266274","pt":1580649093118,"mc":[{"id":"1.168224581","rc":[{"batl":[[0,520,34.64]],"ltp":6.0,"tv":155.26,"id":7797764},{"batb":[[0,1.01,15.51],[1,1.01,0]],"batl":[[0,1.31,1447.26],[1,1.4,7],[2,1.4,0]],"ltp":1.04,"tv":2674.79,"id":2284304}]}]}
{"op":"mcm","clk":"1003266858","pt":1580649096037,"mc":[{"id":"1.168224581","rc":[{"batb":[[0,1.02,1240.71],[1,1.01,15.51]],"batl":[[0,1.06,564.84],[1,1.07,623.17],[2,1.31,1447.26]],"ltp":1.04,"tv":2674.79,"id":2284304}]}]}
{"op":"mcm","clk":"1003267082","pt":1580649097118,"mc":[{"id":"1.168224581","rc":[{"batb":[[0,1.01,15.51],[1,1.01,0]],"ltp":1.04,"tv":2674.79,"id":2284304}]}]}
{"op":"mcm","clk":"1003267664","pt":1580649100145,"mc":[{"id":"1.168224581","rc":[{"batb":[[1,13.5,6.53],[2,1.01,15.51]],"ltp":6.0,"tv":155.26,"id":7797764},{"batb":[[0,1.05,955.59],[1,1.04,252.06],[2,1.03,596.09]],"ltp":1.04,"tv":2674.79,"id":2284304}]}]}
{"op":"mcm","clk":"1003268257","pt":1580649103246,"mc":[{"id":"1.168224581","rc":[{"batl":[[0,95,34.84]],"ltp":6.0,"tv":155.26,"id":7797764}]}]}
{"op":"mcm","clk":"1003270651","pt":1580649116077,"mc":[{"id":"1.168224581","rc":[{"batb":[[0,13.5,6.53],[1,1.01,15.51],[2,1.01,0]],"ltp":6.0,"tv":155.26,"id":7797764},{"batb":[[0,1.02,923.17],[1,1.01,15.51],[2,1.03,0]],"batl":[[0,1.31,1447.26],[1,1.4,7],[2,1.31,0]],"ltp":1.04,"tv":2674.79,"id":2284304}]}]}
{"op":"mcm","clk":"1003271150","pt":1580649118468,"mc":[{"id":"1.168224581","rc":[{"batb":[[0,1.03,1228.66],[1,1.02,923.17],[2,1.01,15.51]],"batl":[[0,1.08,1171.78],[1,1.31,1447.26],[2,1.4,7]],"ltp":1.04,"tv":2674.79,"id":2284304}]}]}
{"op":"mcm","clk":"1003271215","pt":1580649118773,"mc":[{"id":"1.168224581","rc":[{"batb":[[0,1.02,923.17],[1,1.01,15.51],[2,1.01,0]],"batl":[[0,1.31,1447.26],[1,1.4,7],[2,1.4,0]],"ltp":1.04,"tv":2674.79,"id":2284304}]}]}
{"op":"mcm","clk":"1003271714","pt":1580649121286,"mc":[{"id":"1.168224581","rc":[{"batb":[[0,1.05,192.09],[1,1.04,1022.91],[2,1.02,923.17]],"batl":[[0,1.06,1193.89],[1,1.31,1447.26],[2,1.4,7]],"ltp":1.04,"tv":2674.79,"id":2284304}]}]}
{"op":"mcm","clk":"1003272096","pt":1580649123392,"mc":[{"id":"1.168224581","rc":[{"batb":[[0,1.02,923.17],[1,1.01,15.51],[2,1.02,0]],"batl":[[0,1.31,1447.26],[1,1.4,7],[2,1.4,0]],"ltp":1.04,"tv":2674.79,"id":2284304}]}]}
{"op":"mcm","clk":"1003272744","pt":1580649126424,"mc":[{"id":"1.168224581","rc":[{"batb":[[0,1.03,1228.66],[1,1.02,923.17],[2,1.01,15.51]],"batl":[[0,1.08,1171.78],[1,1.31,1447.26],[2,1.4,7]],"ltp":1.04,"tv":2674.79,"id":2284304}]}]}
{"op":"mcm","clk":"1003275812","pt":1580649141172,"mc":[{"id":"1.168224581","rc":[{"batb":[[0,1.02,923.17],[1,1.01,15.51],[2,1.01,0]],"batl":[[0,1.31,1447.26],[1,1.4,7],[2,1.4,0]],"ltp":1.04,"tv":2674.79,"id":2284304}]}]}
{"op":"mcm","clk":"1003276449","pt":1580649144445,"mc":[{"id":"1.168224581","rc":[{"batb":[[0,1.06,1192.59],[1,1.02,923.17],[2,1.01,15.51]],"batl":[[0,1.08,1171.78],[1,1.31,1447.26],[2,1.4,7]],"ltp":1.04,"tv":2674.79,"id":2284304}]}]}
{"op":"mcm","clk":"1003276580","pt":1580649145156,"mc":[{"id":"1.168224581","rc":[{"batb":[[1,11.5,9.36],[2,1.01,15.51]],"ltp":6.0,"tv":155.26,"id":7797764},{"batb":[[0,1.06,1108.39],[1,1.05,475.63],[2,1.03,622.85]],"ltp":1.04,"tv":2674.79,"id":2284304}]}]}
{"op":"mcm","clk":"1003277072","pt":1580649147684,"mc":[{"id":"1.168224581","rc":[{"batl":[[0,65,34.99]],"ltp":6.0,"tv":155.26,"id":7797764}]}]}
{"op":"mcm","clk":"1003279961","pt":1580649163112,"mc":[{"id":"1.168224581","rc":[{"batb":[[0,11.5,9.36],[1,1.01,15.51],[2,1.01,0]],"ltp":6.0,"tv":155.26,"id":7797764},{"batb":[[0,1.03,622.85],[1,1.01,15.51],[2,1.03,0]],"batl":[[0,1.31,1447.26],[1,1.4,7],[2,1.4,0]],"ltp":1.04,"tv":2674.79,"id":2284304}]}]}
{"op":"mcm","clk":"1003280416","pt":1580649165481,"mc":[{"id":"1.168224581","rc":[{"batb":[[0,1.05,385.74],[1,1.04,827.4],[2,1.03,622.85]],"batl":[[0,1.09,1161.03],[1,1.31,1447.26],[2,1.4,7]],"ltp":1.04,"tv":2674.79,"id":2284304}]}]}
{"op":"mcm","clk":"1003280665","pt":1580649166815,"mc":[{"id":"1.168224581","rc":[{"batb":[[0,1.03,622.85],[1,1.01,15.51],[2,1.03,0]],"ltp":1.04,"tv":2674.79,"id":2284304}]}]}
{"op":"mcm","clk":"1003281342","pt":1580649170296,"mc":[{"id":"1.168224581","rc":[{"batb":[[1,11,11.02],[2,1.01,15.51]],"ltp":6.0,"tv":155.26,"id":7797764},{"batb":[[0,1.07,948.13],[1,1.06,622.04],[2,1.05,458.48]],"ltp":1.04,"tv":2674.79,"id":2284304}]}]}
{"op":"mcm","clk":"1003281821","pt":1580649172816,"mc":[{"id":"1.168224581","rc":[{"batl":[[0,42,35.26]],"ltp":6.0,"tv":155.26,"id":7797764}]}]}
{"op":"mcm","clk":"1003283331","pt":1580649181242,"mc":[{"id":"1.168224581","rc":[{"batb":[[0,1.06,622.04],[1,1.05,458.48],[2,1.01,15.51]],"batl":[[0,1.09,497.65]],"ltp":1.04,"tv":2674.79,"id":2284304}]}]}
{"op":"mcm","clk":"1003283374","pt":1580649181550,"mc":[{"id":"1.168224581","rc":[{"batb":[[0,11,11.02],[1,1.01,15.51],[2,1.01,0]],"ltp":6.0,"tv":155.26,"id":7797764},{"batb":[[0,1.06,236.81]],"ltp":1.04,"tv":2674.79,"id":2284304}]}]}
{"op":"mcm","clk":"1003283859","pt":1580649184105,"mc":[{"id":"1.168224581","rc":[{"batb":[[0,1.06,1193.89]],"batl":[[1,1.1,657.35],[2,1.31,1447.26]],"ltp":1.04,"tv":2674.79,"id":2284304}]}]}
{"op":"mcm","clk":"1003284150","pt":1580649185544,"mc":[{"id":"1.168224581","rc":[{"batb":[[0,1.05,458.48],[1,1.01,15.51],[2,1.01,0]],"ltp":1.04,"tv":2674.79,"id":2284304}]}]}
{"op":"mcm","clk":"1003284863","pt":1580649189425,"mc":[{"id":"1.168224581","rc":[{"batb":[[0,1.08,224.34],[1,1.07,959.49],[2,1.06,168.04]],"ltp":1.04,"tv":2674.79,"id":2284304}]}]}
{"op":"mcm","clk":"1003284986","pt":1580649190135,"mc":[{"id":"1.168224581","rc":[{"batb":[[1,7.4,10.7],[2,1.01,15.51]],"ltp":6.0,"tv":155.26,"id":7797764},{"batb":[[1,1.07,1310.49]],"ltp":1.04,"tv":2674.79,"id":2284304}]}]}
{"op":"mcm","clk":"1003289801","pt":1580649217074,"mc":[{"id":"1.168224581","rc":[{"batb":[[0,7.4,10.7],[1,1.01,15.51],[2,1.01,0]],"ltp":6.0,"tv":155.26,"id":7797764},{"batb":[[0,1.06,168.04],[1,1.04,499.87],[2,1.01,15.51]],"batl":[[0,1.31,1447.26],[1,1.4,7],[2,1.31,0]],"ltp":1.04,"tv":2674.79,"id":2284304}]}]}
{"op":"mcm","clk":"1003290060","pt":1580649218480,"mc":[{"id":"1.168224581","rc":[{"batb":[[0,1.04,499.87],[1,1.01,15.51],[2,1.01,0]],"ltp":1.04,"tv":2674.79,"id":2284304}]}]}
{"op":"mcm","clk":"1003290265","pt":1580649219594,"mc":[{"id":"1.168224581","rc":[{"batb":[[0,1.05,1208.52],[1,1.04,499.87],[2,1.01,15.51]],"batl":[[0,1.14,178.28],[1,1.15,695.14],[2,1.31,1447.26]],"ltp":1.04,"tv":2674.79,"id":2284304}]}]}
{"op":"mcm","clk":"1003290708","pt":1580649221879,"mc":[{"id":"1.168224581","rc":[{"batl":[[0,1.31,1447.26],[1,1.4,7],[2,1.31,0]],"ltp":1.04,"tv":2674.79,"id":2284304}]}]}
{"op":"mcm","clk":"1003291310","pt":1580649225407,"mc":[{"id":"1.168224581","rc":[{"batb":[[0,14,5.98],[1,9.6,14.48],[2,7.4,10.7]],"ltp":6.0,"tv":155.26,"id":7797764},{"batb":[[2,1.03,727.02]],"batl":[[0,1.07,1185.93],[1,1.31,1447.26],[2,1.4,7]],"ltp":1.04,"tv":2674.79,"id":2284304}]}]}
{"op":"mcm","clk":"1003291371","pt":1580649225679,"mc":[{"id":"1.168224581","rc":[{"batb":[[2,1.01,15.51]],"ltp":6.0,"tv":155.26,"id":7797764}]}]}
{"op":"mcm","clk":"1003291670","pt":1580649227408,"mc":[{"id":"1.168224581","rc":[{"batl":[[0,65,34.99]],"ltp":6.0,"tv":155.26,"id":7797764}]}]}
{"op":"mcm","clk":"1003293690","pt":1580649238417,"mc":[{"id":"1.168224581","rc":[{"batb":[[0,9.6,14.48],[1,1.01,15.51],[2,1.01,0]],"ltp":6.0,"tv":155.26,"id":7797764},{"batb":[[0,1.03,727.02],[1,1.01,15.51],[2,1.03,0]],"batl":[[0,1.31,1447.26],[1,1.4,7],[2,1.4,0]],"ltp":1.04,"tv":2674.79,"id":2284304}]}]}
{"op":"mcm","clk":"1003294219","pt":1580649241441,"mc":[{"id":"1.168224581","rc":[{"batb":[[0,1.04,1211.59],[1,1.03,727.02],[2,1.01,15.51]],"batl":[[0,1.1,266],[1,1.11,879.59],[2,1.31,1447.26]],"ltp":1.04,"tv":2674.79,"id":2284304}]}]}
{"op":"mcm","clk":"1003294502","pt":1580649242865,"mc":[{"id":"1.168224581","rc":[{"batb":[[0,1.03,727.02],[1,1.01,15.51],[2,1.01,0]],"ltp":1.04,"tv":2674.79,"id":2284304}]}]}
{"op":"mcm","clk":"1003295179","pt":1580649246467,"mc":[{"id":"1.168224581","rc":[{"batb":[[1,6.2,15.66],[2,1.01,15.51]],"ltp":6.0,"tv":155.26,"id":7797764},{"batb":[[0,1.09,336.24],[1,1.08,1134.2],[2,1.05,461.55]],"ltp":1.04,"tv":2674.79,"id":2284304}]}]}
{"op":"mcm","clk":"1003295363","pt":1580649247484,"mc":[{"id":"1.168224581","rc":[{"batb":[[2,1.07,168.04]],"ltp":1.04,"tv":2674.79,"id":2284304}]}]}
{"op":"mcm","clk":"1003295812","pt":1580649250005,"mc":[{"id":"1.168224581","rc":[{"batl":[[0,30,35.63]],"ltp":6.0,"tv":155.26,"id":7797764},{"batb":[[0,1.09,246.77]],"batl":[[1,1.11,791.65]],"ltp":1.04,"tv":2674.79,"id":2284304}]}]}
{"op":"mcm","clk":"1003296393","pt":1580649253097,"mc":[{"id":"1.168224581","rc":[{"batb":[[1,1.08,1192.02]],"batl":[[0,1.1,322.89]],"ltp":1.04,"tv":2674.79,"id":2284304}]}]}
{"op":"mcm","clk":"1003296786","pt":1580649255296,"mc":[{"id":"1.168224581","rc":[{"batb":[[0,1.09,279.2]],"batl":[[1,1.11,823.47]],"ltp":1.04,"tv":2674.79,"id":2284304}]}]}
{"op":"mcm","clk":"1003297729","pt":1580649260424,"mc":[{"id":"1.168224581","rc":[{"batb":[[0,6.2,15.66],[1,1.01,15.51],[2,1.01,0]],"ltp":6.0,"tv":155.26,"id":7797764},{"batb":[[0,1.05,461.55],[1,1.01,15.51],[2,1.07,0]],"batl":[[0,1.31,1447.26],[1,1.4,7],[2,1.31,0]],"ltp":1.04,"tv":2674.79,"id":2284304}]}]}
{"op":"mcm","clk":"1003298286","pt":1580649263468,"mc":[{"id":"1.168224581","rc":[{"batb":[[0,1.06,387.96],[1,1.05,1278.42],[2,1.01,15.51]],"batl":[[0,1.09,721.64],[1,1.18,721.96],[2,1.19,350.45]],"ltp":1.04,"tv":2674.79,"id":2284304}]}]}
{"op":"mcm","clk":"1003299633","pt":1580649270993,"mc":[{"id":"1.168224581","rc":[{"batb":[[0,1.05,461.55],[1,1.01,15.51],[2,1.01,0]],"ltp":1.04,"tv":2674.79,"id":2284304}]}]}
{"op":"mcm","clk":"1003300262","pt":1580649274149,"mc":[{"id":"1.168224581","rc":[{"trd":[[1.09,1443.28]],"batb":[[0,1.14,385.7],[1,1.05,461.55],[2,1.01,15.51]],"batl":[[0,1.18,570.13],[1,1.31,1447.26],[2,1.4,7]],"ltp":1.09,"tv":4118.07,"id":2284304}],"tv":4273.34}]}
{"op":"mcm","clk":"1003300477","pt":1580649275402,"mc":[{"id":"1.168224581","rc":[{"batb":[[1,4.1,20.85],[2,1.01,15.51]],"ltp":6.0,"tv":155.26,"id":7797764},{"batb":[[0,1.15,160.83],[1,1.14,385.7],[2,1.09,466.16]],"ltp":1.09,"tv":4118.07,"id":2284304}]}]}
{"op":"mcm","clk":"1003300557","pt":1580649275766,"mc":[{"id":"1.168224581","rc":[{"batb":[[2,1.09,256.11]],"ltp":1.09,"tv":4118.07,"id":2284304}]}]}
{"op":"mcm","clk":"1003300800","pt":1580649277184,"mc":[{"id":"1.168224581","rc":[{"batl":[[0,9.6,4.2],[1,14,37.99]],"ltp":6.0,"tv":155.26,"id":7797764},{"batb":[[0,1.15,568.32],[1,1.14,702.04]],"batl":[[0,1.17,400.88],[1,1.18,570.13],[2,1.31,1447.26]],"ltp":1.09,"tv":4118.07,"id":2284304}]}]}
{"op":"mcm","clk":"1003302845","pt":1580649288360,"mc":[{"id":"1.168224581","rc":[{"batb":[[0,4.1,20.85],[1,1.01,15.51],[2,1.01,0]],"ltp":6.0,"tv":155.26,"id":7797764},{"batb":[[0,1.09,256.11],[1,1.01,15.51],[2,1.09,0]],"batl":[[0,1.31,1447.26],[1,1.4,7],[2,1.31,0]],"ltp":1.09,"tv":4118.07,"id":2284304}]}]}
{"op":"mcm","clk":"1003302885","pt":1580649288530,"mc":[{"id":"1.168224581","rc":[{"batl":[[0,14,37.99],[1,14,0]],"ltp":6.0,"tv":155.26,"id":7797764}]}]}
{"op":"mcm","clk":"1003303205","pt":1580649290270,"mc":[{"id":"1.168224581","rc":[{"batl":[[0,1.31,1447.28]],"ltp":1.09,"tv":4118.07,"id":2284304}]}]}
{"op":"mcm","clk":"1003303290","pt":1580649290649,"mc":[{"id":"1.168224581","rc":[{"batb":[[0,1.1,242.06],[1,1.09,1175.99],[2,1.01,15.51]],"batl":[[0,1.3,245.18],[1,1.31,1750.88],[2,1.4,7]],"ltp":1.09,"tv":4118.07,"id":2284304}]}]}
{"op":"mcm","clk":"1003303516","pt":1580649291755,"mc":[{"id":"1.168224581","rc":[{"batb":[[0,1.09,256.11],[1,1.01,15.51],[2,1.01,0]],"batl":[[0,1.31,1447.28],[1,1.4,7],[2,1.4,0]],"ltp":1.09,"tv":4118.07,"id":2284304}]}]}
{"op":"mcm","clk":"1003303984","pt":1580649294256,"mc":[{"id":"1.168224581","rc":[{"batl":[[0,1.4,7.02],[1,1.4,0]],"ltp":1.09,"tv":4118.07,"id":2284304}]}]}
{"op":"mcm","clk":"1003304173","pt":1580649295343,"mc":[{"id":"1.168224581","rc":[{"trd":[[1.15,0.04]],"batb":[[0,1.17,509.84],[1,1.16,579.67],[2,1.09,256.11]],"batl":[[0,1.2,666.18],[1,1.21,388.04],[2,1.4,7]],"ltp":1.15,"tv":4118.11,"id":2284304}],"tv":4273.37}]}
{"op":"mcm","clk":"1003304766","pt":1580649298250,"mc":[{"id":"1.168224581","rc":[{"batl":[[0,12.5,38.66]],"ltp":6.0,"tv":155.26,"id":7797764}]}]}
{"op":"mcm","clk":"1003304999","pt":1580649299357,"mc":[{"id":"1.168224581","rc":[{"batb":[[0,1.09,256.11],[1,1.01,15.51],[2,1.09,0]],"batl":[[0,1.4,7],[1,1.45,1070.27],[2,1.4,0]],"ltp":1.15,"tv":4118.11,"id":2284304}]}]}
{"op":"mcm","clk":"1003305448","pt":1580649301557,"mc":[{"id":"1.168224581","rc":[{"batb":[[0,1.1,242.06],[1,1.09,1176],[2,1.01,15.51]],"batl":[[0,1.3,245.16],[1,1.31,303.62],[2,1.4,7]],"ltp":1.15,"tv":4118.11,"id":2284304}]}]}
{"op":"mcm","clk":"1003306841","pt":1580649308967,"mc":[{"id":"1.168224581","rc":[{"batl":[[0,11.5,39.54]],"ltp":6.0,"tv":155.26,"id":7797764}]}]}
{"op":"mcm","clk":"1003307578","pt":1580649313167,"mc":[{"id":"1.168224581","rc":[{"batb":[[0,1.09,256.11],[1,1.01,15.51],[2,1.01,0]],"ltp":1.15,"tv":4118.11,"id":2284304}]}]}
{"op":"mcm","clk":"1003308128","pt":1580649316396,"mc":[{"id":"1.168224581","rc":[{"batb":[[0,1.27,294.34],[1,1.26,392.93],[2,1.09,256.11]],"ltp":1.15,"tv":4118.11,"id":2284304}]}]}
{"op":"mcm","clk":"1003308346","pt":1580649317438,"mc":[{"id":"1.168224581","rc":[{"batb":[[1,3.05,22.19],[2,1.01,15.51]],"batl":[[0,5.8,8.4]],"ltp":6.0,"tv":155.26,"id":7797764},{"batb":[[0,1.27,377.82],[2,1.21,168.04]],"ltp":1.15,"tv":4118.11,"id":2284304}]}]}
{"op":"mcm","clk":"1003308629","pt":1580649319068,"mc":[{"id":"1.168224581","rc":[{"batl":[[1,7.2,45.41]],"ltp":6.0,"tv":155.26,"id":7797764}]}]}
{"op":"mcm","clk":"1003311376","pt":1580649336186,"mc":[{"id":"1.168224581","rc":[{"batb":[[0,1.27,83.48],[1,1.21,168.04],[2,1.19,121.33]],"batl":[[0,1.4,7],[1,1.45,1070.27],[2,1.4,0]],"ltp":1.15,"tv":4118.11,"id":2284304}]}]}
{"op":"mcm","clk":"1003311580","pt":1580649337365,"mc":[{"id":"1.168224581","rc":[{"batb":[[0,3.05,21.87],[1,1.01,15.51],[2,1.01,0]],"batl":[[0,7.2,45.41],[1,7.2,0]],"ltp":6.0,"tv":155.26,"id":7797764},{"batb":[[0,1.19,121.33],[1,1.01,15.51],[2,1.19,0]],"ltp":1.15,"tv":4118.11,"id":2284304}]}]}
{"op":"mcm","clk":"1003311894","pt":1580649339391,"mc":[{"id":"1.168224581","rc":[{"batb":[[0,1.19,760.11],[1,1.18,431.18],[2,1.01,15.51]],"batl":[[2,1.49,213.57]],"ltp":1.15,"tv":4118.11,"id":2284304}]}]}
{"op":"mcm","clk":"1003312588","pt":1580649343474,"mc":[{"id":"1.168224581","rc":[{"batb":[[0,1.19,121.33],[1,1.01,15.52],[2,1.01,0]],"ltp":1.15,"tv":4118.11,"id":2284304}]}]}
{"op":"mcm","clk":"1003313048","pt":1580649346286,"mc":[{"id":"1.168224581","rc":[{"batb":[[1,2.7,12.2],[2,1.01,15.51]],"ltp":6.0,"tv":155.26,"id":7797764},{"trd":[[1.4,70.11]],"batb":[[0,1.44,268.72],[1,1.43,208.12],[2,1.42,48]],"batl":[[0,1.49,213.57],[1,1.5,164.66],[2,1.49,0]],"ltp":1.4,"tv":4132.11,"id":2284304}],"tv":4287.37}]}
{"op":"mcm","clk":"1003313582","pt":1580649349490,"mc":[{"id":"1.168224581","rc":[{"batl":[[0,3.7,15.12],[1,4.9,57.83]],"ltp":6.0,"tv":155.26,"id":7797764},{"batl":[[2,1.77,689.49]],"ltp":1.4,"tv":4132.11,"id":2284304}]}]}
{"op":"mcm","clk":"1003313698","pt":1580649350180,"mc":[{"id":"1.168224581","rc":[{"batb":[[0,1.44,237.31]],"ltp":1.4,"tv":4132.11,"id":2284304}]}]}
{"op":"mcm","clk":"1003313840","pt":1580649351112,"mc":[{"id":"1.168224581","rc":[{"batb":[[0,1.44,177.73]],"ltp":1.4,"tv":4132.11,"id":2284304}]}]}
{"op":"mcm","clk":"1003314050","pt":1580649352392,"mc":[{"id":"1.168224581","rc":[{"batl":[[0,3.5,26.36],[1,3.7,15.12],[2,4.9,57.83]],"ltp":6.0,"tv":155.26,"id":7797764}]}]}
{"op":"mcm","clk":"1003314219","pt":1580649353373,"mc":[{"id":"1.168224581","rc":[{"batl":[[0,1.49,281.73]],"ltp":1.4,"tv":4132.11,"id":2284304}]}]}
{"op":"mcm","clk":"1003314359","pt":1580649354190,"mc":[{"id":"1.168224581","rc":[{"batb":[[0,1.44,207.52]],"ltp":1.4,"tv":4132.11,"id":2284304}]}]}
{"op":"mcm","clk":"1003314503","pt":1580649354970,"mc":[{"id":"1.168224581","rc":[{"batb":[[0,1.44,177.73]],"batl":[[0,1.49,172.1],[1,1.77,689.49],[2,1.77,0]],"ltp":1.4,"tv":4132.11,"id":2284304}]}]}
{"op":"mcm","clk":"1003314729","pt":1580649356177,"mc":[{"id":"1.168224581","rc":[{"batb":[[0,1.43,208.12],[1,1.42,48],[2,1.37,113.43]],"ltp":1.4,"tv":4132.11,"id":2284304}]}]}
{"op":"mcm","clk":"1003315097","pt":1580649358493,"mc":[{"id":"1.168224581","rc":[{"batb":[[0,1.43,339.11],[1,1.42,264.53]],"batl":[[0,1.48,185.8],[1,1.49,172.1],[2,1.77,689.49]],"ltp":1.4,"tv":4132.11,"id":2284304}]}]}
{"op":"mcm","clk":"1003315349","pt":1580649359975,"mc":[{"id":"1.168224581","rc":[{"batb":[[0,1.43,307.16]],"ltp":1.4,"tv":4132.11,"id":2284304}]}]}
{"op":"mcm","clk":"1003315951","pt":1580649363315,"mc":[{"id":"1.168224581","rc":[{"batl":[[0,1.48,216.67]],"ltp":1.4,"tv":4132.11,"id":2284304}]}]}
{"op":"mcm","clk":"1003319827","pt":1580649383978,"mc":[{"id":"1.168224581","rc":[{"batb":[[0,1.43,282.62]],"ltp":1.4,"tv":4132.11,"id":2284304}]}]}
{"op":"mcm","clk":"1003320210","pt":1580649386288,"mc":[{"id":"1.168224581","rc":[{"batl":[[0,1.48,240.34]],"ltp":1.4,"tv":4132.11,"id":2284304}]}]}
{"op":"mcm","clk":"1003323464","pt":1580649403482,"mc":[{"id":"1.168224581","rc":[{"batl":[[1,4.9,57.83],[2,4.9,0]],"ltp":6.0,"tv":155.26,"id":7797764},{"batb":[[0,1.43,248.91]],"ltp":1.4,"tv":4132.11,"id":2284304}]}]}
{"op":"mcm","clk":"1003323908","pt":1580649405819,"mc":[{"id":"1.168224581","rc":[{"batl":[[1,3.65,15.12],[2,4.9,57.83]],"ltp":6.0,"tv":155.26,"id":7797764},{"batl":[[0,1.48,273.04]],"ltp":1.4,"tv":4132.11,"id":2284304}]}]}
{"op":"mcm","clk":"1003329178","pt":1580649434400,"mc":[{"id":"1.168224581","rc":[{"batb":[[0,2.7,12.2],[1,1.01,15.51],[2,1.01,0]],"ltp":6.0,"tv":155.26,"id":7797764},{"batb":[[0,1.37,113.43],[1,1.3,72.54],[2,1.01,15.52]],"batl":[[0,1.77,689.49],[1,1.49,0],[2,1.77,0]],"ltp":1.4,"tv":4132.11,"id":2284304}]}]}
{"op":"mcm","clk":"1003329260","pt":1580649434885,"mc":[{"id":"1.168224581","rc":[{"batl":[[1,4.9,57.83],[2,4.9,0]],"ltp":6.0,"tv":155.26,"id":7797764},{"batb":[[0,1.3,72.54],[1,1.01,15.52],[2,1.01,0]],"ltp":1.4,"tv":4132.11,"id":2284304}]}]}
{"op":"mcm","clk":"1003329657","pt":1580649437094,"mc":[{"id":"1.168224581","rc":[{"batb":[[0,1.32,165.31],[1,1.31,318.56],[2,1.3,72.54]],"batl":[[0,1.57,136.29],[1,1.58,138.2],[2,1.77,689.49]],"ltp":1.4,"tv":4132.11,"id":2284304}]}]}
{"op":"mcm","clk":"1003329907","pt":1580649438428,"mc":[{"id":"1.168224581","rc":[{"batl":[[0,1.77,689.49],[1,1.58,0],[2,1.77,0]],"ltp":1.4,"tv":4132.11,"id":2284304}]}]}
{"op":"mcm","clk":"1003330052","pt":1580649439247,"mc":[{"id":"1.168224581","rc":[{"batl":[[1,4.9,0]],"ltp":6.0,"tv":155.26,"id":7797764}]}]}
{"op":"mcm","clk":"1003330419","pt":1580649441382,"mc":[{"id":"1.168224581","rc":[{"trd":[[3.5,79.65]],"batb":[[0,3.8,25.49],[1,3.15,20.54],[2,2.7,12.2]],"ltp":3.5,"tv":181.62,"id":7797764},{"trd":[[1.4,136.04]],"batl":[[0,1.35,143.7],[1,1.36,256.58]],"ltp":1.4,"tv":4198.04,"id":2284304}],"tv":4379.66}]}
{"op":"mcm","clk":"1003330563","pt":1580649442278,"mc":[{"id":"1.168224581","rc":[{"batb":[[2,1.01,15.51]],"batl":[[0,4.4,11.76]],"ltp":3.5,"tv":181.62,"id":7797764}]}]}
{"op":"mcm","clk":"1003330739","pt":1580649443398,"mc":[{"id":"1.168224581","rc":[{"batl":[[1,6,50.06]],"ltp":3.5,"tv":181.62,"id":7797764},{"batl":[[2,1.66,781.21]],"ltp":1.4,"tv":4198.04,"id":2284304}]}]}
{"op":"mcm","clk":"1003330863","pt":1580649444110,"mc":[{"id":"1.168224581","rc":[{"batl":[[0,1.35,184.59]],"ltp":1.4,"tv":4198.04,"id":2284304}]}]}
{"op":"mcm","clk":"1003332379","pt":1580649453200,"mc":[{"id":"1.168224581","rc":[{"batb":[[0,1.3,72.54],[1,1.29,144.51],[2,1.18,126.76]],"batl":[[0,1.66,781.21],[1,1.36,0],[2,1.66,0]],"ltp":1.4,"tv":4198.04,"id":2284304}]}]}
{"op":"mcm","clk":"1003332459","pt":1580649453693,"mc":[{"id":"1.168224581","rc":[{"batb":[[0,3.15,20.54],[1,1.01,15.51],[2,1.01,0]],"ltp":3.5,"tv":181.62,"id":7797764},{"batb":[[0,1.29,144.51],[1,1.18,126.76],[2,1.01,15.52]],"ltp":1.4,"tv":4198.04,"id":2284304}]}]}
{"op":"mcm","clk":"1003332639","pt":1580649454912,"mc":[{"id":"1.168224581","rc":[{"batl":[[0,6,50.06],[1,6,0]],"ltp":3.5,"tv":181.62,"id":7797764},{"batb":[[0,1.18,126.76],[1,1.01,15.52],[2,1.01,0]],"ltp":1.4,"tv":4198.04,"id":2284304}]}]}
{"op":"mcm","clk":"1003332835","pt":1580649456105,"mc":[{"id":"1.168224581","rc":[{"batb":[[0,1.2,393.54],[1,1.19,582.8],[2,1.18,126.76]],"batl":[[0,1.46,281.26],[1,1.47,181.55],[2,1.66,781.21]],"ltp":1.4,"tv":4198.04,"id":2284304}]}]}
{"op":"mcm","clk":"1003334594","pt":1580649466310,"mc":[{"id":"1.168224581","rc":[{"batb":[[0,1.18,126.76],[1,1.01,15.52],[2,1.18,0]],"ltp":1.4,"tv":4198.04,"id":2284304}]}]}
{"op":"mcm","clk":"1003335184","pt":1580649469435,"mc":[{"id":"1.168224581","rc":[{"batb":[[0,1.41,293.52],[1,1.4,231.05],[2,1.18,126.76]],"ltp":1.4,"tv":4198.04,"id":2284304}]}]}
{"op":"mcm","clk":"1003335363","pt":1580649470449,"mc":[{"id":"1.168224581","rc":[{"batb":[[1,2.7,12.27],[2,1.01,15.51]],"batl":[[0,3.8,14.28]],"ltp":3.5,"tv":181.62,"id":7797764},{"batb":[[1,1.4,281.56],[2,1.36,115.95]],"ltp":1.4,"tv":4198.04,"id":2284304}]}]}
{"op":"mcm","clk":"1003335705","pt":1580649472422,"mc":[{"id":"1.168224581","rc":[{"batl":[[1,4.9,57.83]],"ltp":3.5,"tv":181.62,"id":7797764}]}]}
{"op":"mcm","clk":"1003337701","pt":1580649483475,"mc":[{"id":"1.168224581","rc":[{"batb":[[0,2.7,12.27],[1,1.01,15.51],[2,1.01,0]],"ltp":3.5,"tv":181.62,"id":7797764},{"batb":[[0,1.36,115.95],[1,1.27,84.03],[2,1.01,15.52]],"batl":[[0,1.66,781.21],[1,1.47,0],[2,1.66,0]],"ltp":1.4,"tv":4198.04,"id":2284304}]}]}
{"op":"mcm","clk":"1003337972","pt":1580649484976,"mc":[{"id":"1.168224581","rc":[{"batl":[[0,4.9,57.83],[1,4.9,0]],"ltp":3.5,"tv":181.62,"id":7797764},{"batb":[[0,1.27,84.03],[1,1.01,15.52],[2,1.01,0]],"ltp":1.4,"tv":4198.04,"id":2284304}]}]}
{"op":"mcm","clk":"1003338103","pt":1580649485686,"mc":[{"id":"1.168224581","rc":[{"batb":[[0,1.28,267.29],[1,1.27,464.08],[2,1.01,15.52]],"batl":[[0,1.57,159.6],[1,1.58,138.07],[2,1.66,781.21]],"ltp":1.4,"tv":4198.04,"id":2284304}]}]}
{"op":"mcm","clk":"1003338937","pt":1580649490250,"mc":[{"id":"1.168224581","rc":[{"batb":[[0,1.27,84.03],[1,1.01,15.52],[2,1.01,0]],"ltp":1.4,"tv":4198.04,"id":2284304}]}]}
{"op":"mcm","clk":"1003339531","pt":1580649493361,"mc":[{"id":"1.168224581","rc":[{"batb":[[0,1.52,182.82],[1,1.51,166.59],[2,1.27,84.03]],"batl":[[2,1.66,0]],"ltp":1.4,"tv":4198.04,"id":2284304}]}]}
{"op":"mcm","clk":"1003339706","pt":1580649494282,"mc":[{"id":"1.168224581","rc":[{"batb":[[1,2.38,17],[2,1.01,15.51]],"ltp":3.5,"tv":181.62,"id":7797764},{"batb":[[0,1.52,219.09],[2,1.44,94.94]],"ltp":1.4,"tv":4198.04,"id":2284304}]}]}
{"op":"mcm","clk":"1003339895","pt":1580649495291,"mc":[{"id":"1.168224581","rc":[{"batl":[[0,3.25,18.48]],"ltp":3.5,"tv":181.62,"id":7797764}]}]}
{"op":"mcm","clk":"1003340254","pt":1580649497241,"mc":[{"id":"1.168224581","rc":[{"batl":[[1,4.2,67.5]],"ltp":3.5,"tv":181.62,"id":7797764},{"batl":[[2,1.89,611.84]],"ltp":1.4,"tv":4198.04,"id":2284304}]}]}
{"op":"mcm","clk":"1003342134","pt":1580649508381,"mc":[{"id":"1.168224581","rc":[{"batb":[[0,1.52,36.27],[1,1.44,94.94],[2,1.38,53.66]],"batl":[[0,1.89,611.84],[1,1.58,0],[2,1.89,0]],"ltp":1.4,"tv":4198.04,"id":2284304}]}]}
{"op":"mcm","clk":"1003342216","pt":1580649508870,"mc":[{"id":"1.168224581","rc":[{"batb":[[0,2.38,17],[1,1.01,15.51],[2,1.01,0]],"batl":[[0,4.2,67.5],[1,4.2,0]],"ltp":3.5,"tv":181.62,"id":7797764},{"batb":[[0,1.38,53.66],[1,1.01,15.52],[2,1.38,0]],"ltp":1.4,"tv":4198.04,"id":2284304}]}]}
{"op":"mcm","clk":"1003343252","pt":1580649514462,"mc":[{"id":"1.168224581","rc":[{"batb":[[0,1.62,145.02],[1,1.61,130],[2,1.38,53.66]],"batl":[[0,1.68,177.89],[1,1.7,214.32],[2,1.89,611.84]],"ltp":1.4,"tv":4198.04,"id":2284304}]}]}
{"op":"mcm","clk":"1003343364","pt":1580649515097,"mc":[{"id":"1.168224581","rc":[{"batb":[[1,2.24,20.22],[2,1.01,15.51]],"ltp":3.5,"tv":181.62,"id":7797764},{"batb":[[0,1.64,27.46],[1,1.62,145.02],[2,1.61,130]],"ltp":1.4,"tv":4198.04,"id":2284304}]}]}
{"op":"mcm","clk":"1003343715","pt":1580649517186,"mc":[{"id":"1.168224581","rc":[{"batl":[[0,3.65,78.67]],"ltp":3.5,"tv":181.62,"id":7797764}]}]}
{"op":"mcm","clk":"1003344541","pt":1580649521894,"mc":[{"id":"1.168224581","rc":[{"batl":[[0,2.9,21.85],[1,3.65,78.67]],"ltp":3.5,"tv":181.62,"id":7797764},{"batb":[[1,1.62,119]],"ltp":1.4,"tv":4198.04,"id":2284304}]}]}
{"op":"mcm","clk":"1003345099","pt":1580649525205,"mc":[{"id":"1.168224581","rc":[{"batl":[[0,1.68,202.99]],"ltp":1.4,"tv":4198.04,"id":2284304}]}]}
{"op":"mcm","clk":"1003345448","pt":1580649527312,"mc":[{"id":"1.168224581","rc":[{"batb":[[0,2.24,20.22],[1,1.01,15.51],[2,1.01,0]],"ltp":3.5,"tv":181.62,"id":7797764},{"batb":[[0,1.54,34.86],[1,1.01,15.52],[2,1.61,0]],"batl":[[0,1.89,611.84],[1,1.7,0],[2,1.89,0]],"ltp":1.4,"tv":4198.04,"id":2284304}]}]}
{"op":"mcm","clk":"1003345709","pt":1580649528817,"mc":[{"id":"1.168224581","rc":[{"batl":[[0,3.65,78.67],[1,3.65,0]],"ltp":3.5,"tv":181.62,"id":7797764}]}]}
{"op":"mcm","clk":"1003345934","pt":1580649530305,"mc":[{"id":"1.168224581","rc":[{"batb":[[1,1.53,78.98],[2,1.01,15.52]],"batl":[[0,1.64,26.89],[1,1.89,611.84]],"ltp":1.4,"tv":4198.04,"id":2284304}]}]}
{"op":"mcm","clk":"1003346090","pt":1580649531325,"mc":[{"id":"1.168224581","rc":[{"batb":[[0,2.26,19.67]],"ltp":3.5,"tv":181.62,"id":7797764},{"batb":[[0,1.53,35.88],[1,1.01,15.52],[2,1.01,0]],"batl":[[0,1.89,611.84],[1,1.89,0]],"ltp":1.4,"tv":4198.04,"id":2284304}]}]}
{"op":"mcm","clk":"1003346428","pt":1580649533409,"mc":[{"id":"1.168224581","rc":[{"batb":[[0,1.6,160.07],[1,1.59,136.34],[2,1.53,35.88]],"batl":[[0,1.66,190.39],[1,1.68,223.25],[2,1.89,611.84]],"ltp":1.4,"tv":4198.04,"id":2284304}]}]}
{"op":"mcm","clk":"1003346690","pt":1580649535117,"mc":[{"id":"1.168224581","rc":[{"batb":[[0,1.53,35.88],[1,1.01,15.52],[2,1.53,0]],"batl":[[0,1.89,611.84],[1,1.68,0],[2,1.89,0]],"ltp":1.4,"tv":4198.04,"id":2284304}]}]}
{"op":"mcm","clk":"1003347171","pt":1580649538126,"mc":[{"id":"1.168224581","rc":[{"batb":[[0,1.53,295.15],[1,1.52,162.77],[2,1.01,15.52]],"batl":[[0,1.74,161.98],[1,1.76,190.77],[2,1.89,611.84]],"ltp":1.4,"tv":4198.04,"id":2284304}]}]}
{"op":"mcm","clk":"1003347340","pt":1580649539242,"mc":[{"id":"1.168224581","rc":[{"batl":[[0,1.89,611.84],[1,1.76,0],[2,1.89,0]],"ltp":1.4,"tv":4198.04,"id":2284304}]}]}
{"op":"mcm","clk":"1003347836","pt":1580649542155,"mc":[{"id":"1.168224581","rc":[{"batl":[[0,1.59,207.49],[1,1.6,131.74],[2,1.89,611.84]],"ltp":1.4,"tv":4198.04,"id":2284304}]}]}
{"op":"mcm","clk":"1003348037","pt":1580649543346,"mc":[{"id":"1.168224581","rc":[{"batb":[[0,2.68,12.43],[1,2.34,18.25],[2,1.01,15.51]],"ltp":3.5,"tv":181.62,"id":7797764},{"batb":[[2,1.36,57.28]],"ltp":1.4,"tv":4198.04,"id":2284304}]}]}
{"op":"mcm","clk":"1003348166","pt":1580649544143,"mc":[{"id":"1.168224581","rc":[{"batb":[[0,2.76,23.53],[1,2.68,12.43],[2,2.34,18.25]],"batl":[[0,3.1,19.32],[1,3.65,78.67]],"ltp":3.5,"tv":181.62,"id":7797764},{"batb":[[2,1.47,89.06]],"batl":[[0,1.57,42.01],[1,1.59,207.49],[2,1.6,131.74]],"ltp":1.4,"tv":4198.04,"id":2284304}]}]}
{"op":"mcm","clk":"1003351456","pt":1580649564988,"mc":[{"id":"1.168224581","rc":[{"batb":[[1,2.34,18.25],[2,1.01,15.51]],"ltp":3.5,"tv":181.62,"id":7797764},{"batb":[[0,1.53,259.27]],"ltp":1.4,"tv":4198.04,"id":2284304}]}]}
{"op":"mcm","clk":"1003353066","pt":1580649575389,"mc":[{"id":"1.168224581","rc":[{"batb":[[0,2.34,18.25],[1,1.01,15.51],[2,1.01,0]],"batl":[[0,3.65,78.67],[1,3.65,0]],"ltp":3.5,"tv":181.62,"id":7797764},{"batb":[[0,1.36,57.28],[1,1.01,15.52],[2,1.47,0]],"batl":[[0,1.89,611.84],[1,1.59,0],[2,1.6,0]],"ltp":1.4,"tv":4198.04,"id":2284304}]}]}
{"op":"mcm","clk":"1003353436","pt":1580649577881,"mc":[{"id":"1.168224581","rc":[{"batb":[[0,1.38,381.12],[1,1.37,257.23],[2,1.36,57.28]],"batl":[[0,1.72,195.71],[1,1.74,197.97],[2,1.89,611.84]],"ltp":1.4,"tv":4198.04,"id":2284304}]}]}
{"op":"mcm","clk":"1003354958","pt":1580649588122,"mc":[{"id":"1.168224581","rc":[{"batl":[[0,1.89,611.84],[1,1.74,0],[2,1.89,0]],"ltp":1.4,"tv":4198.04,"id":2284304}]}]}
{"op":"mcm","clk":"1003355449","pt":1580649591320,"mc":[{"id":"1.168224581","rc":[{"batl":[[0,1.43,289.69],[1,1.44,198.18]],"ltp":1.4,"tv":4198.04,"id":2284304}]}]}
{"op":"mcm","clk":"1003355526","pt":1580649591835,"mc":[{"id":"1.168224581","rc":[{"batb":[[0,3.35,17.31],[1,3.3,17.64],[2,2.72,12.04]],"batl":[[0,3.75,15.12]],"ltp":3.5,"tv":181.62,"id":7797764},{"batb":[[2,1.36,173.23]],"batl":[[0,1.43,331.7]],"ltp":1.4,"tv":4198.04,"id":2284304}]}]}
{"op":"mcm","clk":"1003356098","pt":1580649595369,"mc":[{"id":"1.168224581","rc":[{"batl":[[1,4.9,57.83]],"ltp":3.5,"tv":181.62,"id":7797764},{"batl":[[2,1.77,689.49]],"ltp":1.4,"tv":4198.04,"id":2284304}]}]}
{"op":"mcm","clk":"1003357853","pt":1580649606345,"mc":[{"id":"1.168224581","rc":[{"batb":[[0,1.36,173.23],[1,1.2,114.09],[2,1.01,15.52]],"batl":[[0,1.43,42.01],[1,1.77,689.49],[2,1.77,0]],"ltp":1.4,"tv":4198.04,"id":2284304}]}]}
{"op":"mcm","clk":"1003357943","pt":1580649606863,"mc":[{"id":"1.168224581","rc":[{"batb":[[0,2.72,12.04],[1,1.01,15.51],[2,2.72,0]],"batl":[[0,4.9,57.83],[1,4.9,0]],"ltp":3.5,"tv":181.62,"id":7797764},{"batb":[[0,1.2,114.09],[1,1.01,15.52],[2,1.01,0]],"batl":[[0,1.77,689.49],[1,1.77,0]],"ltp":1.4,"tv":4198.04,"id":2284304}]}]}
{"op":"mcm","clk":"1003358302","pt":1580649608978,"mc":[{"id":"1.168224581","rc":[{"batb":[[0,1.22,409.85],[1,1.21,519.81],[2,1.2,114.09]],"batl":[[0,1.58,156.64],[1,1.59,135.06],[2,1.77,689.49]],"ltp":1.4,"tv":4198.04,"id":2284304}]}]}
{"op":"mcm","clk":"1003359346","pt":1580649615371,"mc":[{"id":"1.168224581","rc":[{"batb":[[0,1.2,114.09],[1,1.01,15.52],[2,1.2,0]],"ltp":1.4,"tv":4198.04,"id":2284304}]}]}
{"op":"mcm","clk":"1003359594","pt":1580649616971,"mc":[{"id":"1.168224581","rc":[{"batl":[[2,1.77,0]],"ltp":1.4,"tv":4198.04,"id":2284304}]}]}
{"op":"mcm","clk":"1003359813","pt":1580649618294,"mc":[{"id":"1.168224581","rc":[{"batb":[[0,1.53,170.38],[1,1.52,162.33],[2,1.2,114.09]],"ltp":1.4,"tv":4198.04,"id":2284304}]}]}
{"op":"mcm","clk":"1003360001","pt":1580649619488,"mc":[{"id":"1.168224581","rc":[{"batb":[[1,2.36,17.62],[2,1.01,15.51]],"ltp":3.5,"tv":181.62,"id":7797764},{"batb":[[1,1.52,199.07],[2,1.36,58.54]],"ltp":1.4,"tv":4198.04,"id":2284304}]}]}
{"op":"mcm","clk":"1003360066","pt":1580649619897,"mc":[{"id":"1.168224581","rc":[{"batb":[[0,2.78,23.53],[1,2.72,12.04],[2,2.36,17.62]],"batl":[[0,3.15,19.32]],"ltp":3.5,"tv":181.62,"id":7797764},{"batb":[[2,1.47,89.06]],"batl":[[0,1.56,42.01],[1,1.58,156.64],[2,1.59,135.06]],"ltp":1.4,"tv":4198.04,"id":2284304}]}]}
{"op":"mcm","clk":"1003360294","pt":1580649621403,"mc":[{"id":"1.168224581","rc":[{"batl":[[1,3.65,78.67]],"ltp":3.5,"tv":181.62,"id":7797764}]}]}
{"op":"mcm","clk":"1003363176","pt":1580649639441,"mc":[{"id":"1.168224581","rc":[{"batb":[[1,2.36,17.62],[2,1.01,15.51]],"ltp":3.5,"tv":181.62,"id":7797764},{"batb":[[0,1.47,89.06],[1,1.36,58.54],[2,1.01,15.52]],"batl":[[1,2.04,548.04],[2,1.59,0]],"ltp":1.4,"tv":4198.04,"id":2284304}]}]}
{"op":"mcm","clk":"1003363449","pt":1580649641250,"mc":[{"id":"1.168224581","rc":[{"batb":[[0,2.36,17.62],[1,1.01,15.51],[2,1.01,0]],"batl":[[0,3.65,78.67],[1,3.65,0]],"ltp":3.5,"tv":181.62,"id":7797764},{"batb":[[0,1.36,58.54],[1,1.01,15.52],[2,1.01,0]],"batl":[[0,2.04,548.04],[1,2.04,0]],"ltp":1.4,"tv":4198.04,"id":2284304}]}]}
{"op":"mcm","clk":"1003363971","pt":1580649644337,"mc":[{"id":"1.168224581","rc":[{"batb":[[0,1.5,141.72],[1,1.49,175.78],[2,1.36,58.54]],"batl":[[0,1.55,231.89],[1,1.56,144.55],[2,2.04,548.04]],"ltp":1.4,"tv":4198.04,"id":2284304}]}]}
{"op":"mcm","clk":"1003364510","pt":1580649647837,"mc":[{"id":"1.168224581","rc":[{"batb":[[0,1.36,58.54],[1,1.01,15.52],[2,1.36,0]],"batl":[[0,2.04,548.04],[1,1.56,0],[2,2.04,0]],"ltp":1.4,"tv":4198.04,"id":2284304}]}]}
{"op":"mcm","clk":"1003364967","pt":1580649650755,"mc":[{"id":"1.168224581","rc":[{"batb":[[0,1.38,278.27],[1,1.37,256.06],[2,1.36,58.54]],"batl":[[0,1.71,151.78],[1,1.73,202.02],[2,2.04,548.04]],"ltp":1.4,"tv":4198.04,"id":2284304}]}]}
{"op":"mcm","clk":"1003365199","pt":1580649652269,"mc":[{"id":"1.168224581","rc":[{"batb":[[0,1.36,58.54],[1,1.01,15.52],[2,1.36,0]],"ltp":1.4,"tv":4198.04,"id":2284304}]}]}
{"op":"mcm","clk":"1003365629","pt":1580649655043,"mc":[{"id":"1.168224581","rc":[{"batb":[[0,1.65,134.44],[1,1.64,121.58],[2,1.36,58.54]],"ltp":1.4,"tv":4198.04,"id":2284304}]}]}
{"op":"mcm","clk":"1003365769","pt":1580649655891,"mc":[{"id":"1.168224581","rc":[{"batb":[[0,2.5,27.73],[1,2.36,17.62],[2,1.95,15.42]],"batl":[[0,2.8,22.69]],"ltp":3.5,"tv":181.62,"id":7797764},{"batb":[[0,1.66,26.59],[1,1.65,134.44],[2,1.64,121.58]],"batl":[[0,1.67,42.01],[1,1.71,151.78],[2,1.73,202.02]],"ltp":1.4,"tv":4198.04,"id":2284304}]}]}
{"op":"mcm","clk":"1003365991","pt":1580649657464,"mc":[{"id":"1.168224581","rc":[{"batl":[[1,3.3,90.39]],"ltp":3.5,"tv":181.62,"id":7797764}]}]}
{"op":"mcm","clk":"1003369698","pt":1580649682453,"mc":[{"id":"1.168224581","rc":[{"batb":[[1,1.56,74.78],[2,1.53,35.88]],"batl":[[1,2.04,548.04],[2,1.73,0]],"ltp":1.4,"tv":4198.04,"id":2284304}]}]}
{"op":"mcm","clk":"1003369819","pt":1580649683190,"mc":[{"id":"1.168224581","rc":[{"batb":[[0,1.95,15.42],[1,1.01,15.51],[2,1.95,0]],"batl":[[0,3.3,90.39],[1,3.3,0]],"ltp":3.5,"tv":181.62,"id":7797764},{"batb":[[0,1.53,35.88],[1,1.01,15.52],[2,1.53,0]],"batl":[[0,2.04,548.04],[1,2.04,0]],"ltp":1.4,"tv":4198.04,"id":2284304}]}]}
{"op":"mcm","clk":"1003370288","pt":1580649686118,"mc":[{"id":"1.168224581","rc":[{"batb":[[0,1.53,289.63],[1,1.52,162.89],[2,1.01,15.52]],"ltp":1.4,"tv":4198.04,"id":2284304}]}]}
{"op":"mcm","clk":"1003370705","pt":1580649688381,"mc":[{"id":"1.168224581","rc":[{"batl":[[0,1.59,212.78],[1,1.6,131.84],[2,2.04,548.04]],"ltp":1.4,"tv":4198.04,"id":2284304}]}]}
{"op":"mcm","clk":"1003370883","pt":1580649689397,"mc":[{"id":"1.168224581","rc":[{"batb":[[0,2.68,12.43],[1,2.26,19.91],[2,1.01,15.51]],"ltp":3.5,"tv":181.62,"id":7797764},{"batb":[[2,1.44,45.71]],"ltp":1.4,"tv":4198.04,"id":2284304}]}]}
{"op":"mcm","clk":"1003370981","pt":1580649689985,"mc":[{"id":"1.168224581","rc":[{"batb":[[0,2.76,23.53],[1,2.68,12.43],[2,2.26,19.91]],"batl":[[0,3.1,19.32]],"ltp":3.5,"tv":181.62,"id":7797764},{"batb":[[2,1.47,89.06]],"ltp":1.4,"tv":4198.04,"id":2284304}]}]}
{"op":"mcm","clk":"1003371202","pt":1580649691389,"mc":[{"id":"1.168224581","rc":[{"batl":[[1,3.65,78.67]],"ltp":3.5,"tv":181.62,"id":7797764}]}]}
{"op":"mcm","clk":"1003372674","pt":1580649701109,"mc":[{"id":"1.168224581","rc":[{"batb":[[0,1.53,35.88],[1,1.47,89.06],[2,1.44,45.71]],"batl":[[0,2.04,548.04],[1,1.6,0],[2,2.04,0]],"ltp":1.4,"tv":4198.04,"id":2284304}]}]}
{"op":"mcm","clk":"1003372796","pt":1580649701928,"mc":[{"id":"1.168224581","rc":[{"batb":[[1,2.26,19.91],[2,1.01,15.51]],"ltp":3.5,"tv":181.62,"id":7797764},{"batb":[[0,1.47,89.06],[1,1.44,45.71],[2,1.01,15.52]],"ltp":1.4,"tv":4198.04,"id":2284304}]}]}
{"op":"mcm","clk":"1003372948","pt":1580649702929,"mc":[{"id":"1.168224581","rc":[{"batb":[[0,2.26,19.91],[1,1.01,15.51],[2,1.01,0]],"batl":[[0,3.65,78.67],[1,3.65,0]],"ltp":3.5,"tv":181.62,"id":7797764},{"batb":[[0,1.44,45.71],[1,1.01,15.52],[2,1.01,0]],"ltp":1.4,"tv":4198.04,"id":2284304}]}]}
{"op":"mcm","clk":"1003373112","pt":1580649703999,"mc":[{"id":"1.168224581","rc":[{"batb":[[0,1.46,189.8],[1,1.45,197.67],[2,1.44,45.71]],"batl":[[0,1.77,187.7],[1,1.79,180.63],[2,2.04,548.04]],"ltp":1.4,"tv":4198.04,"id":2284304}]}]}
{"op":"mcm","clk":"1003374358","pt":1580649712433,"mc":[{"id":"1.168224581","rc":[{"batl":[[0,2.04,548.04],[1,1.79,0],[2,2.04,0]],"ltp":1.4,"tv":4198.04,"id":2284304}]}]}
{"op":"mcm","clk":"1003374807","pt":1580649715476,"mc":[{"id":"1.168224581","rc":[{"batl":[[0,1.51,262.8],[1,1.52,159.65]],"ltp":1.4,"tv":4198.04,"id":2284304}]}]}
{"op":"mcm","clk":"1003374890","pt":1580649715965,"mc":[{"id":"1.168224581","rc":[{"batb":[[0,3,23.29],[1,2.64,12.98],[2,1.01,15.51]],"batl":[[0,3.45,16.8]],"ltp":3.5,"tv":181.62,"id":7797764},{"batl":[[2,1.92,134.06]],"ltp":1.4,"tv":4198.04,"id":2284304}]}]}
{"op":"mcm","clk":"1003375291","pt":1580649718749,"mc":[{"id":"1.168224581","rc":[{"batl":[[1,4.2,67.5]],"ltp":3.5,"tv":181.62,"id":7797764},{"batl":[[2,1.89,611.84]],"ltp":1.4,"tv":4198.04,"id":2284304}]}]}
{"op":"mcm","clk":"1003377560","pt":1580649733110,"mc":[{"id":"1.168224581","rc":[{"batb":[[0,2.64,12.98],[1,1.01,15.51],[2,1.01,0]],"ltp":3.5,"tv":181.62,"id":7797764},{"batb":[[0,1.41,101.66],[1,1.39,52.95],[2,1.01,15.52]],"batl":[[0,1.89,611.84],[1,1.52,0],[2,1.89,0]],"ltp":1.4,"tv":4198.04,"id":2284304}]}]}
{"op":"mcm","clk":"1003377846","pt":1580649734913,"mc":[{"id":"1.168224581","rc":[{"batl":[[0,4.2,67.5],[1,4.2,0]],"ltp":3.5,"tv":181.62,"id":7797764},{"batb":[[0,1.39,52.95],[1,1.01,15.52],[2,1.01,0]],"ltp":1.4,"tv":4198.04,"id":2284304}]}]}
{"op":"mcm","clk":"1003377946","pt":1580649735531,"mc":[{"id":"1.168224581","rc":[{"batb":[[0,1.42,171.31],[1,1.41,223.46],[2,1.39,52.95]],"batl":[[0,1.6,190.63],[1,1.61,129.01],[2,1.89,611.84]],"ltp":1.4,"tv":4198.04,"id":2284304}]}]}
{"op":"mcm","clk":"1003378537","pt":1580649738943,"mc":[{"id":"1.168224581","rc":[{"batl":[[0,1.89,611.84],[1,1.61,0],[2,1.89,0]],"ltp":1.4,"tv":4198.04,"id":2284304}]}]}
{"op":"mcm","clk":"1003379121","pt":1580649742425,"mc":[{"id":"1.168224581","rc":[{"batb":[[0,3.2,19.28],[1,3,22.82],[2,2.64,12.98]],"ltp":3.5,"tv":181.62,"id":7797764},{"batl":[[0,1.46,189.9],[1,1.47,183.05],[2,1.89,611.84]],"ltp":1.4,"tv":4198.04,"id":2284304}]}]}
{"op":"mcm","clk":"1003379234","pt":1580649743120,"mc":[{"id":"1.168224581","rc":[{"batb":[[2,1.01,15.51]],"ltp":3.5,"tv":181.62,"id":7797764}]}]}
{"op":"mcm","clk":"1003379404","pt":1580649744234,"mc":[{"id":"1.168224581","rc":[{"batb":[[0,3.2,37.76]],"batl":[[0,3.6,15.96],[1,4.2,67.5]],"ltp":3.5,"tv":181.62,"id":7797764},{"batb":[[0,1.41,223.46],[1,1.39,52.95],[2,1.38,110.07]],"batl":[[0,1.46,231.91]],"ltp":1.4,"tv":4198.04,"id":2284304}]}]}
{"op":"mcm","clk":"1003379740","pt":1580649746368,"mc":[{"id":"1.168224581","rc":[{"batb":[[0,1.41,348.41],[1,1.4,232.97],[2,1.39,52.95]],"batl":[[0,1.46,277.98]],"ltp":1.4,"tv":4198.04,"id":2284304}]}]}
{"op":"mcm","clk":"1003381801","pt":1580649760019,"mc":[{"id":"1.168224581","rc":[{"batb":[[0,3.2,18.48]],"ltp":3.5,"tv":181.62,"id":7797764},{"batb":[[0,1.4,232.97],[1,1.38,110.07],[2,1.36,57.44]],"batl":[[0,1.46,42.01],[1,1.89,611.84],[2,1.89,0]],"ltp":1.4,"tv":4198.04,"id":2284304}]}]}
{"op":"mcm","clk":"1003382003","pt":1580649761320,"mc":[{"id":"1.168224581","rc":[{"batb":[[0,3,22.82],[1,1.01,15.51],[2,1.01,0]],"batl":[[0,4.2,67.5],[1,4.2,0]],"ltp":3.5,"tv":181.62,"id":7797764},{"batb":[[0,1.36,57.44],[1,1.01,15.52],[2,1.36,0]],"batl":[[0,1.89,611.84],[1,1.89,0]],"ltp":1.4,"tv":4198.04,"id":2284304}]}]}
{"op":"mcm","clk":"1003382167","pt":1580649762435,"mc":[{"id":"1.168224581","rc":[{"batb":[[0,1.39,239.15],[1,1.36,57.44],[2,1.01,15.52]],"batl":[[0,1.5,278.65],[1,1.51,164.06],[2,1.89,611.84]],"ltp":1.4,"tv":4198.04,"id":2284304}]}]}
{"op":"mcm","clk":"1003382264","pt":1580649763122,"mc":[{"id":"1.168224581","rc":[{"batb":[[0,1.36,57.44],[1,1.01,15.52],[2,1.01,0]],"batl":[[0,1.89,611.84],[1,1.51,0],[2,1.89,0]],"ltp":1.4,"tv":4198.04,"id":2284304}]}]}
{"op":"mcm","clk":"1003382432","pt":1580649764257,"mc":[{"id":"1.168224581","rc":[{"batb":[[0,1.42,275.57],[1,1.41,224.79],[2,1.36,57.44]],"batl":[[0,1.47,276.81],[1,1.48,177.71],[2,1.89,611.84]],"ltp":1.4,"tv":4198.04,"id":2284304}]}]}
{"op":"mcm","clk":"1003382761","pt":1580649766109,"mc":[{"id":"1.168224581","rc":[{"trd":[[1.42,7.58]],"batb":[[0,1.42,271.78]],"ltp":1.42,"tv":4205.62,"id":2284304}],"tv":4387.24}]}
{"op":"mcm","clk":"1003383343","pt":1580649769799,"mc":[{"id":"1.168224581","rc":[{"batb":[[0,1.36,57.44],[1,1.01,15.52],[2,1.36,0]],"batl":[[0,1.89,611.84],[1,1.48,0],[2,1.89,0]],"ltp":1.42,"tv":4205.62,"id":2284304}]}]}
{"op":"mcm","clk":"1003383887","pt":1580649773205,"mc":[{"id":"1.168224581","rc":[{"batb":[[0,1.4,221.19],[1,1.39,239.15],[2,1.36,57.44]],"batl":[[0,1.5,279.97],[1,1.51,164.06],[2,1.89,611.84]],"ltp":1.42,"tv":4205.62,"id":2284304}]}]}
{"op":"mcm","clk":"1003384004","pt":1580649773913,"mc":[{"id":"1.168224581","rc":[{"batl":[[0,1.89,611.84],[1,1.51,0],[2,1.89,0]],"ltp":1.42,"tv":4205.62,"id":2284304}]}]}
{"op":"mcm","clk":"1003384529","pt":1580649777312,"mc":[{"id":"1.168224581","rc":[{"batb":[[0,3,108.39]],"ltp":3.5,"tv":181.62,"id":7797764},{"batl":[[0,1.44,186.79],[1,1.45,194.12],[2,1.89,611.84]],"ltp":1.42,"tv":4205.62,"id":2284304}]}]}
{"op":"mcm","clk":"1003384678","pt":1580649778309,"mc":[{"id":"1.168224581","rc":[{"batb":[[0,3.35,17.31],[1,3,85.57],[2,2.88,10.46]],"batl":[[0,3.75,15.12],[1,4.2,67.5]],"ltp":3.5,"tv":181.62,"id":7797764},{"batb":[[2,1.36,173.38]],"batl":[[0,1.44,228.8]],"ltp":1.42,"tv":4205.62,"id":2284304}]}]}
{"op":"mcm","clk":"1003385597","pt":1580649784322,"mc":[{"id":"1.168224581","rc":[{"trd":[[3.35,34.2]],"batb":[[0,2.88,10.67],[1,1.01,15.51],[2,2.88,0]],"ltp":3.35,"tv":215.82,"id":7797764}],"tv":4421.44}]}
{"op":"mcm","clk":"1003386137","pt":1580649787339,"mc":[{"id":"1.168224581","rc":[{"batb":[[0,3.3,18.07],[1,2.88,10.46],[2,2.86,10.62]],"ltp":3.35,"tv":215.82,"id":7797764},{"batb":[[2,1.37,56.02]],"ltp":1.42,"tv":4205.62,"id":2284304}]}]}
{"op":"mcm","clk":"1003386293","pt":1580649788221,"mc":[{"id":"1.168224581","rc":[{"batb":[[0,3.3,17.86],[1,2.86,10.62],[2,1.01,15.51]],"ltp":3.35,"tv":215.82,"id":7797764}]}]}
{"op":"mcm","clk":"1003387307","pt":1580649794161,"mc":[{"id":"1.168224581","rc":[{"batl":[[0,4.2,67.5],[1,4.2,0]],"ltp":3.35,"tv":215.82,"id":7797764},{"trd":[[1.44,457.34]],"batl":[[0,1.45,194.25],[1,1.89,611.84],[2,1.89,0]],"ltp":1.44,"tv":4662.96,"id":2284304}],"tv":4878.78}]}
{"op":"mcm","clk":"1003387534","pt":1580649795459,"mc":[{"id":"1.168224581","rc":[{"batb":[[1,2.82,10.86]],"ltp":3.35,"tv":215.82,"id":7797764},{"batb":[[2,1.38,55.16]],"ltp":1.44,"tv":4662.96,"id":2284304}]}]}
{"op":"mcm","clk":"1003387842","pt":1580649797430,"mc":[{"id":"1.168224581","rc":[{"batb":[[1,3.25,18.48],[2,2.82,10.86]],"batl":[[0,3.7,15.12],[1,4.2,67.5]],"ltp":3.35,"tv":215.82,"id":7797764},{"batb":[[0,1.4,277.33]],"batl":[[0,1.44,41.3],[1,1.45,325.87],[2,1.46,187.03]],"ltp":1.44,"tv":4662.96,"id":2284304}]}]}
{"op":"mcm","clk":"1003390922","pt":1580649816559,"mc":[{"id":"1.168224581","rc":[{"batl":[[1,1.45,194.15],[2,1.89,611.84]],"ltp":1.44,"tv":4662.96,"id":2284304}]}]}
{"op":"mcm","clk":"1003391408","pt":1580649819458,"mc":[{"id":"1.168224581","rc":[{"batl":[[0,1.44,198.06]],"ltp":1.44,"tv":4662.96,"id":2284304}]}]}
{"op":"mcm","clk":"1003393545","pt":1580649832091,"mc":[{"id":"1.168224581","rc":[{"batb":[[0,3.25,36.9],[1,2.8,10.94],[2,1.01,15.51]],"ltp":3.35,"tv":215.82,"id":7797764},{"batb":[[0,1.4,248.69],[1,1.39,293.91],[2,1.37,113.43]],"ltp":1.44,"tv":4662.96,"id":2284304}]}]}
{"op":"mcm","clk":"1003398481","pt":1580649861449,"mc":[{"id":"1.168224581","rc":[{"trd":[[3.25,44.97]],"batb":[[0,2.8,10.94],[1,1.01,15.51],[2,1.01,0]],"batl":[[0,4.2,67.5],[1,4.2,0]],"ltp":3.25,"tv":260.78,"id":7797764},{"batb":[[0,1.26,89.15],[1,1.01,15.52],[2,1.37,0]],"batl":[[0,1.89,611.84],[1,1.45,0],[2,1.89,0]],"ltp":1.44,"tv":4662.96,"id":2284304}],"tv":4923.75}]}
{"op":"mcm","clk":"1003399359","pt":1580649866363,"mc":[{"id":"1.168224581","rc":[{"batb":[[0,1.37,345.03],[1,1.36,266.79],[2,1.26,89.15]],"batl":[[0,1.41,145.31],[1,1.42,212.45]],"ltp":1.44,"tv":4662.96,"id":2284304}]}]}
{"op":"mcm","clk":"1003399670","pt":1580649868052,"mc":[{"id":"1.168224581","rc":[{"batl":[[0,4.9,57.83]],"ltp":3.25,"tv":260.78,"id":7797764},{"batl":[[2,1.77,689.49]],"ltp":1.44,"tv":4662.96,"id":2284304}]}]}
{"op":"mcm","clk":"1003400212","pt":1580649871472,"mc":[{"id":"1.168224581","rc":[{"batb":[[0,1.26,89.15],[1,1.01,15.52],[2,1.26,0]],"batl":[[0,1.77,689.49],[1,1.42,0],[2,1.77,0]],"ltp":1.44,"tv":4662.96,"id":2284304}]}]}
{"op":"mcm","clk":"1003400712","pt":1580649874484,"mc":[{"id":"1.168224581","rc":[{"batb":[[0,1.28,181.01],[1,1.27,379.95],[2,1.26,89.15]],"batl":[[0,1.55,191.56],[1,1.56,145.14],[2,1.77,689.49]],"ltp":1.44,"tv":4662.96,"id":2284304}]}]}
{"op":"mcm","clk":"1003401211","pt":1580649877383,"mc":[{"id":"1.168224581","rc":[{"batb":[[0,1.26,89.15],[1,1.01,15.52],[2,1.26,0]],"ltp":1.44,"tv":4662.96,"id":2284304}]}]}
{"op":"mcm","clk":"1003401540","pt":1580649879404,"mc":[{"id":"1.168224581","rc":[{"batl":[[2,1.77,0]],"ltp":1.44,"tv":4662.96,"id":2284304}]}]}
{"op":"mcm","clk":"1003401735","pt":1580649880482,"mc":[{"id":"1.168224581","rc":[{"batb":[[0,2.86,21.85],[1,2.8,10.94],[2,2.5,15.03]],"batl":[[0,3.25,18.48]],"ltp":3.25,"tv":260.78,"id":7797764},{"batb":[[0,1.5,225.11],[1,1.49,176.51],[2,1.44,94.94]],"batl":[[0,1.53,42.01],[1,1.55,191.56],[2,1.56,145.14]],"ltp":1.44,"tv":4662.96,"id":2284304}]}]}
{"op":"mcm","clk":"1003402001","pt":1580649882036,"mc":[{"id":"1.168224581","rc":[{"batl":[[1,3.9,72.46]],"ltp":3.25,"tv":260.78,"id":7797764}]}]}
{"op":"mcm","clk":"1003404491","pt":1580649897000,"mc":[{"id":"1.168224581","rc":[{"batb":[[0,2.5,15.03],[1,1.01,15.51],[2,2.5,0]],"batl":[[0,3.9,72.46],[1,3.9,0]],"ltp":3.25,"tv":260.78,"id":7797764},{"batb":[[0,1.36,59.25],[1,1.01,15.52],[2,1.44,0]],"batl":[[0,1.95,581.01],[1,1.55,0],[2,1.56,0]],"ltp":1.44,"tv":4662.96,"id":2284304}]}]}
{"op":"mcm","clk":"1003404896","pt":1580649899598,"mc":[{"id":"1.168224581","rc":[{"batb":[[0,1.38,228.94],[1,1.37,256.18],[2,1.36,59.25]],"batl":[[0,1.65,179.98],[1,1.67,228.6],[2,1.95,581.01]],"ltp":1.44,"tv":4662.96,"id":2284304}]}]}
{"op":"mcm","clk":"1003405508","pt":1580649903213,"mc":[{"id":"1.168224581","rc":[{"batb":[[0,1.36,59.25],[1,1.01,15.52],[2,1.36,0]],"ltp":1.44,"tv":4662.96,"id":2284304}]}]}
{"op":"mcm","clk":"1003406025","pt":1580649906145,"mc":[{"id":"1.168224581","rc":[{"batb":[[0,1.59,186.84],[1,1.58,140.11],[2,1.36,59.25]],"ltp":1.44,"tv":4662.96,"id":2284304}]}]}
{"op":"mcm","clk":"1003406235","pt":1580649907410,"mc":[{"id":"1.168224581","rc":[{"batb":[[1,2.3,18.65],[2,1.01,15.51]],"ltp":3.25,"tv":260.78,"id":7797764},{"batb":[[0,1.61,30.53],[1,1.59,186.84],[2,1.58,140.11]],"ltp":1.44,"tv":4662.96,"id":2284304}]}]}
{"op":"mcm","clk":"1003406446","pt":1580649908489,"mc":[{"id":"1.168224581","rc":[{"batb":[[0,2.62,25.21],[1,2.5,15.03],[2,2.3,18.65]],"batl":[[0,3.45,83.99]],"ltp":3.25,"tv":260.78,"id":7797764},{"trd":[[1.61,61.05]],"batb":[[0,1.59,186.84],[1,1.58,140.11],[2,1.5,40.05]],"ltp":1.61,"tv":4724.01,"id":2284304}],"tv":4984.8}]}
{"op":"mcm","clk":"1003406713","pt":1580649910068,"mc":[{"id":"1.168224581","rc":[{"batl":[[0,2.94,21],[1,3.45,83.99]],"ltp":3.25,"tv":260.78,"id":7797764},{"batl":[[0,1.62,42.01],[1,1.65,179.98],[2,1.67,228.6]],"ltp":1.61,"tv":4724.01,"id":2284304}]}]}
{"op":"mcm","clk":"1003406902","pt":1580649911273,"mc":[{"id":"1.168224581","rc":[{"batb":[[2,1.52,80.66]],"ltp":1.61,"tv":4724.01,"id":2284304}]}]}
{"op":"mcm","clk":"1003408182","pt":1580649919392,"mc":[{"id":"1.168224581","rc":[{"batb":[[1,2.3,18.65],[2,1.01,15.51]],"ltp":3.25,"tv":260.78,"id":7797764},{"batb":[[0,1.52,80.66],[1,1.5,40.05],[2,1.01,15.52]],"batl":[[1,1.95,581.01],[2,1.67,0]],"ltp":1.61,"tv":4724.01,"id":2284304}]}]}
{"op":"mcm","clk":"1003408529","pt":1580649921399,"mc":[{"id":"1.168224581","rc":[{"batb":[[0,2.3,18.65],[1,1.01,15.51],[2,1.01,0]],"batl":[[0,3.45,83.99],[1,3.45,0]],"ltp":3.25,"tv":260.78,"id":7797764},{"batb":[[0,1.5,40.05],[1,1.01,15.52],[2,1.01,0]],"batl":[[0,1.59,3.79]],"ltp":1.61,"tv":4724.01,"id":2284304}]}]}
{"op":"mcm","clk":"1003408637","pt":1580649922000,"mc":[{"id":"1.168224581","rc":[{"batb":[[0,1.5,194.93],[1,1.49,176.31],[2,1.01,15.52]],"batl":[[1,1.72,137.51],[2,1.74,199.08]],"ltp":1.61,"tv":4724.01,"id":2284304}]}]}
{"op":"mcm","clk":"1003408775","pt":1580649922880,"mc":[{"id":"1.168224581","rc":[{"batb":[[0,2.32,18.18]],"ltp":3.25,"tv":260.78,"id":7797764},{"batb":[[0,1.5,154.88],[2,1.48,40.91]],"ltp":1.61,"tv":4724.01,"id":2284304}]}]}
{"op":"mcm","clk":"1003409568","pt":1580649927902,"mc":[{"id":"1.168224581","rc":[{"batl":[[0,1.72,137.51],[1,1.74,199.08],[2,1.95,581.01]],"ltp":1.61,"tv":4724.01,"id":2284304}]}]}
{"op":"mcm","clk":"1003409969","pt":1580649930199,"mc":[{"id":"1.168224581","rc":[{"batl":[[0,1.95,581.01],[1,1.74,0],[2,1.95,0]],"ltp":1.61,"tv":4724.01,"id":2284304}]}]}
{"op":"mcm","clk":"1003410510","pt":1580649933421,"mc":[{"id":"1.168224581","rc":[{"batl":[[0,1.55,220.28],[1,1.56,144.97],[2,1.57,562.93]],"ltp":1.61,"tv":4724.01,"id":2284304}]}]}
{"op":"mcm","clk":"1003410682","pt":1580649934368,"mc":[{"id":"1.168224581","rc":[{"batb":[[0,2.84,33.31],[1,2.5,15.03],[2,1.01,15.51]],"batl":[[0,3.2,18.48]],"ltp":3.25,"tv":260.78,"id":7797764},{"batl":[[0,1.54,42.01],[1,1.55,220.28],[2,1.56,144.97]],"ltp":1.61,"tv":4724.01,"id":2284304}]}]}
{"op":"mcm","clk":"1003411120","pt":1580649936526,"mc":[{"id":"1.168224581","rc":[{"batl":[[1,3.9,72.46]],"ltp":3.25,"tv":260.78,"id":7797764}]}]}
{"op":"mcm","clk":"1003412737","pt":1580649945957,"mc":[{"id":"1.168224581","rc":[{"trd":[[1.5,7.58]],"batb":[[0,1.5,151.09]],"ltp":1.5,"tv":4731.59,"id":2284304}],"tv":4992.38}]}
{"op":"mcm","clk":"1003413278","pt":1580649949326,"mc":[{"id":"1.168224581","rc":[{"batb":[[0,2.84,22.69]],"ltp":3.25,"tv":260.78,"id":7797764},{"batb":[[0,1.45,93.26],[1,1.33,65.23],[2,1.01,15.52]],"batl":[[1,1.95,581.01],[2,1.56,0]],"ltp":1.5,"tv":4731.59,"id":2284304}]}]}
{"op":"mcm","clk":"1003413533","pt":1580649951036,"mc":[{"id":"1.168224581","rc":[{"batb":[[0,2.5,15.03],[1,1.01,15.51],[2,1.01,0]],"batl":[[0,3.9,72.46],[1,3.9,0]],"ltp":3.25,"tv":260.78,"id":7797764},{"batb":[[0,1.33,65.23],[1,1.01,15.52],[2,1.01,0]],"batl":[[0,1.95,581.01],[1,1.95,0]],"ltp":1.5,"tv":4731.59,"id":2284304}]}]}
{"op":"mcm","clk":"1003413606","pt":1580649951559,"mc":[{"id":"1.168224581","rc":[{"batb":[[0,1.36,203.14],[1,1.35,274.79],[2,1.33,65.23]],"batl":[[0,1.67,194.46],[1,1.69,219.31],[2,1.95,581.01]],"ltp":1.5,"tv":4731.59,"id":2284304}]}]}
{"op":"mcm","clk":"1003413845","pt":1580649953169,"mc":[{"id":"1.168224581","rc":[{"batb":[[0,1.33,65.23],[1,1.01,15.52],[2,1.33,0]],"batl":[[0,1.95,581.01],[1,1.69,0],[2,1.95,0]],"ltp":1.5,"tv":4731.59,"id":2284304}]}]}
{"op":"mcm","clk":"1003414284","pt":1580649956374,"mc":[{"id":"1.168224581","rc":[{"batb":[[0,1.47,154.92],[1,1.46,191.92],[2,1.33,65.23]],"batl":[[0,1.52,275.58],[1,1.53,155.75],[2,1.95,581.01]],"ltp":1.5,"tv":4731.59,"id":2284304}]}]}
{"op":"mcm","clk":"1003414408","pt":1580649957156,"mc":[{"id":"1.168224581","rc":[{"batb":[[0,1.33,65.23],[1,1.01,15.52],[2,1.33,0]],"batl":[[0,1.95,581.01],[1,1.53,0],[2,1.95,0]],"ltp":1.5,"tv":4731.59,"id":2284304}]}]}
{"op":"mcm","clk":"1003414789","pt":1580649960057,"mc":[{"id":"1.168224581","rc":[{"batb":[[0,1.36,203.14],[1,1.35,274.79],[2,1.33,65.23]],"batl":[[0,1.67,194.46],[1,1.69,219.31],[2,1.95,581.01]],"ltp":1.5,"tv":4731.59,"id":2284304}]}]}
{"op":"mcm","clk":"1003415791","pt":1580649967155,"mc":[{"id":"1.168224581","rc":[{"batl":[[0,1.95,581.01],[1,1.69,0],[2,1.95,0]],"ltp":1.5,"tv":4731.59,"id":2284304}]}]}
{"op":"mcm","clk":"1003416231","pt":1580649970271,"mc":[{"id":"1.168224581","rc":[{"batl":[[0,1.4,304.62],[1,1.41,217.42],[2,1.43,562.93]],"ltp":1.5,"tv":4731.59,"id":2284304}]}]}
{"op":"mcm","clk":"1003416400","pt":1580649971310,"mc":[{"id":"1.168224581","rc":[{"batb":[[0,3.6,14.56],[1,2.78,11.25],[2,1.01,15.51]],"ltp":3.25,"tv":260.78,"id":7797764}]}]}
{"op":"mcm","clk":"1003416511","pt":1580649971953,"mc":[{"id":"1.168224581","rc":[{"batb":[[1,3.45,16.8],[2,2.78,11.25]],"batl":[[0,3.9,14.28]],"ltp":3.25,"tv":260.78,"id":7797764},{"batb":[[2,1.34,123.51]],"batl":[[1,1.41,259.43]],"ltp":1.5,"tv":4731.59,"id":2284304}]}]}
{"op":"mcm","clk":"1003416655","pt":1580649972962,"mc":[{"id":"1.168224581","rc":[{"batl":[[1,5.3,54.8]],"ltp":3.25,"tv":260.78,"id":7797764},{"batl":[[2,1.73,720.97]],"ltp":1.5,"tv":4731.59,"id":2284304}]}]}
{"op":"mcm","clk":"1003417933","pt":1580649981257,"mc":[{"id":"1.168224581","rc":[{"trd":[[3.6,28.62]],"batb":[[0,3.45,17.05],[1,2.78,11.25],[2,1.01,15.51]],"ltp":3.6,"tv":289.4,"id":7797764}],"tv":5021.0}]}
{"op":"mcm","clk":"1003418327","pt":1580649983285,"mc":[{"id":"1.168224581","rc":[{"batb":[[0,1.34,123.51],[1,1.33,65.23],[2,1.15,155.65]],"batl":[[0,1.41,42.01],[1,1.73,720.97],[2,1.73,0]],"ltp":1.5,"tv":4731.59,"id":2284304}]}]}
{"op":"mcm","clk":"1003418393","pt":1580649983692,"mc":[{"id":"1.168224581","rc":[{"batb":[[0,3.45,16.8]],"ltp":3.6,"tv":289.4,"id":7797764},{"batb":[[1,1.15,155.65],[2,1.01,15.51]],"ltp":1.5,"tv":4731.59,"id":2284304}]}]}
{"op":"mcm","clk":"1003418677","pt":1580649985194,"mc":[{"id":"1.168224581","rc":[{"batb":[[0,2.78,11.25],[1,1.01,15.51],[2,1.01,0]],"ltp":3.6,"tv":289.4,"id":7797764},{"batb":[[0,1.15,155.65],[1,1.01,15.51],[2,1.01,0]],"ltp":1.5,"tv":4731.59,"id":2284304}]}]}
{"op":"mcm","clk":"1003418853","pt":1580649986412,"mc":[{"id":"1.168224581","rc":[{"batb":[[1,2.76,11.57],[2,1.01,15.51]],"ltp":3.6,"tv":289.4,"id":7797764},{"batb":[[0,1.16,152.49],[1,1.15,155.65],[2,1.01,15.51]],"ltp":1.5,"tv":4731.59,"id":2284304}]}]}
{"op":"mcm","clk":"1003418890","pt":1580649986688,"mc":[{"id":"1.168224581","rc":[{"batb":[[0,2.76,11.57],[1,1.01,15.51],[2,1.01,0]],"ltp":3.6,"tv":289.4,"id":7797764},{"batb":[[1,1.01,15.52],[2,1.01,0]],"ltp":1.5,"tv":4731.59,"id":2284304}]}]}
{"op":"mcm","clk":"1003419154","pt":1580649988430,"mc":[{"id":"1.168224581","rc":[{"batb":[[0,1.32,200.52],[1,1.31,320.38],[2,1.16,152.49]],"batl":[[0,1.35,178.66],[1,1.36,258.04]],"ltp":1.5,"tv":4731.59,"id":2284304}]}]}
{"op":"mcm","clk":"1003419410","pt":1580649990219,"mc":[{"id":"1.168224581","rc":[{"batl":[[0,5.5,53.34]],"ltp":3.6,"tv":289.4,"id":7797764},{"batl":[[2,1.71,737.78]],"ltp":1.5,"tv":4731.59,"id":2284304}]}]}
{"op":"mcm","clk":"1003419682","pt":1580649992136,"mc":[{"id":"1.168224581","rc":[{"batb":[[0,1.16,152.49],[1,1.01,15.52],[2,1.16,0]],"batl":[[0,1.71,737.78],[1,1.36,0],[2,1.71,0]],"ltp":1.5,"tv":4731.59,"id":2284304}]}]}
{"op":"mcm","clk":"1003420297","pt":1580649995445,"mc":[{"id":"1.168224581","rc":[{"batb":[[0,1.18,308.49],[1,1.17,664.1],[2,1.16,152.49]],"batl":[[0,1.57,173.47],[1,1.58,138.48]],"ltp":1.5,"tv":4731.59,"id":2284304}]}]}
{"op":"mcm","clk":"1003420692","pt":1580649998145,"mc":[{"id":"1.168224581","rc":[{"batb":[[0,1.16,152.49],[1,1.01,15.52],[2,1.16,0]],"ltp":1.5,"tv":4731.59,"id":2284304}]}]}
{"op":"mcm","clk":"1003421101","pt":1580650001166,"mc":[{"id":"1.168224581","rc":[{"batb":[[0,1.52,169.49],[1,1.51,167.08],[2,1.45,1250.95]],"ltp":1.5,"tv":4731.59,"id":2284304}]}]}
{"op":"mcm","clk":"1003421302","pt":1580650002448,"mc":[{"id":"1.168224581","rc":[{"batb":[[0,2.8,22.69],[1,2.76,11.57],[2,2.36,17.47]],"batl":[[0,3.15,19.32]],"ltp":3.6,"tv":289.4,"id":7797764},{"batb":[[0,1.52,207.65]],"batl":[[0,1.55,42.01],[1,1.57,173.47],[2,1.58,138.48]],"ltp":1.5,"tv":4731.59,"id":2284304}]}]}
{"op":"mcm","clk":"1003421439","pt":1580650003350,"mc":[{"id":"1.168224581","rc":[{"batl":[[1,3.9,72.46]],"ltp":3.6,"tv":289.4,"id":7797764}]}]}
{"op":"mcm","clk":"1003421581","pt":1580650004250,"mc":[{"id":"1.168224581","rc":[{"batb":[[2,1.47,89.06]],"ltp":1.5,"tv":4731.59,"id":2284304}]}]}
{"op":"mcm","clk":"1003422495","pt":1580650010561,"mc":[{"id":"1.168224581","rc":[{"trd":[[1.52,4.54]],"batb":[[0,1.52,205.38]],"ltp":1.52,"tv":4736.13,"id":2284304}],"tv":5025.54}]}
{"op":"mcm","clk":"1003423764","pt":1580650019264,"mc":[{"id":"1.168224581","rc":[{"batb":[[0,1.52,38.16],[1,1.47,89.06],[2,1.33,65.62]],"batl":[[1,1.95,581.01],[2,1.58,0]],"ltp":1.52,"tv":4736.13,"id":2284304}]}]}
{"op":"mcm","clk":"1003423922","pt":1580650020339,"mc":[{"id":"1.168224581","rc":[{"batb":[[1,2.36,17.47],[2,1.01,15.51]],"ltp":3.6,"tv":289.4,"id":7797764},{"batb":[[0,1.47,89.06],[1,1.33,65.62],[2,1.01,15.52]],"ltp":1.52,"tv":4736.13,"id":2284304}]}]}
{"op":"mcm","clk":"1003424094","pt":1580650021353,"mc":[{"id":"1.168224581","rc":[{"batb":[[0,2.36,17.47],[1,1.01,15.51],[2,1.01,0]],"batl":[[0,3.9,72.46],[1,3.9,0]],"ltp":3.6,"tv":289.4,"id":7797764},{"batb":[[0,1.33,65.62],[1,1.01,15.52],[2,1.01,0]],"batl":[[0,1.95,581.01],[1,1.95,0]],"ltp":1.52,"tv":4736.13,"id":2284304}]}]}
{"op":"mcm","clk":"1003424747","pt":1580650025234,"mc":[{"id":"1.168224581","rc":[{"batb":[[0,1.48,247.22],[1,1.47,187.09],[2,1.33,65.62]],"batl":[[0,1.53,169.72],[1,1.54,152.51],[2,1.95,581.01]],"ltp":1.52,"tv":4736.13,"id":2284304}]}]}
{"op":"mcm","clk":"1003425448","pt":1580650029578,"mc":[{"id":"1.168224581","rc":[{"batb":[[0,1.33,65.62],[1,1.01,15.52],[2,1.33,0]],"batl":[[0,1.95,581.01],[1,1.54,0],[2,1.95,0]],"ltp":1.52,"tv":4736.13,"id":2284304}]}]}
{"op":"mcm","clk":"1003425876","pt":1580650032467,"mc":[{"id":"1.168224581","rc":[{"batb":[[0,1.55,3.03],[1,1.33,65.62],[2,1.01,15.52]],"ltp":1.52,"tv":4736.13,"id":2284304}]}]}
{"op":"mcm","clk":"1003425891","pt":1580650032577,"mc":[{"id":"1.168224581","rc":[{"batb":[[1,1.35,371.95],[2,1.34,287.36]],"batl":[[0,1.72,191.28],[1,1.74,198.49],[2,1.95,581.01]],"ltp":1.52,"tv":4736.13,"id":2284304}]}]}
{"op":"mcm","clk":"1003426480","pt":1580650036344,"mc":[{"id":"1.168224581","rc":[{"batb":[[0,1.33,65.62],[1,1.01,15.52],[2,1.34,0]],"ltp":1.52,"tv":4736.13,"id":2284304}]}]}
{"op":"mcm","clk":"1003426802","pt":1580650038465,"mc":[{"id":"1.168224581","rc":[{"batl":[[2,1.95,0]],"ltp":1.52,"tv":4736.13,"id":2284304}]}]}
{"op":"mcm","clk":"1003426951","pt":1580650039363,"mc":[{"id":"1.168224581","rc":[{"batb":[[0,1.65,201.24],[1,1.64,122.05],[2,1.61,922.84]],"ltp":1.52,"tv":4736.13,"id":2284304}]}]}
{"op":"mcm","clk":"1003427107","pt":1580650040476,"mc":[{"id":"1.168224581","rc":[{"batb":[[0,2.46,28.57],[1,2.36,17.47],[2,1.95,30.37]],"batl":[[0,2.76,23.53]],"ltp":3.6,"tv":289.4,"id":7797764},{"batb":[[0,1.67,26.75],[1,1.65,201.24],[2,1.64,122.05]],"batl":[[0,1.68,42.01],[1,1.72,191.28],[2,1.74,198.49]],"ltp":1.52,"tv":4736.13,"id":2284304}]}]}
{"op":"mcm","clk":"1003427385","pt":1580650042441,"mc":[{"id":"1.168224581","rc":[{"batl":[[0,3.3,90.39]],"ltp":3.6,"tv":289.4,"id":7797764}]}]}
{"op":"mcm","clk":"1003427585","pt":1580650043976,"mc":[{"id":"1.168224581","rc":[{"batl":[[0,2.74,23.53],[1,3.3,90.39]],"ltp":3.6,"tv":289.4,"id":7797764},{"trd":[[1.67,52.09]],"batb":[[0,1.65,201.94],[1,1.64,122.05],[2,1.57,73.1]],"ltp":1.67,"tv":4788.22,"id":2284304}],"tv":5077.63}]}
{"op":"mcm","clk":"1003428619","pt":1580650051004,"mc":[{"id":"1.168224581","rc":[{"trd":[[1.65,50.74],[1.67,53.5]],"batb":[[0,1.65,175.87]],"ltp":1.65,"tv":4840.37,"id":2284304}],"tv":5129.78}]}
{"op":"mcm","clk":"1003429255","pt":1580650055323,"mc":[{"id":"1.168224581","rc":[{"trd":[[1.65,82.54]],"batb":[[0,1.65,159.97]],"ltp":1.65,"tv":4872.17,"id":2284304}],"tv":5161.58}]}
{"op":"mcm","clk":"1003429670","pt":1580650058378,"mc":[{"id":"1.168224581","rc":[{"batb":[[0,1.65,186.34]],"ltp":1.65,"tv":4872.17,"id":2284304}]}]}
{"op":"mcm","clk":"1003431164","pt":1580650068427,"mc":[{"id":"1.168224581","rc":[{"batb":[[0,1.65,219.63]],"ltp":1.65,"tv":4872.17,"id":2284304}]}]}
{"op":"mcm","clk":"1003432413","pt":1580650076965,"mc":[{"id":"1.168224581","rc":[{"batb":[[0,1.57,73.1],[1,1.55,34.93],[2,1.01,15.52]],"batl":[[1,2.16,497.72],[2,1.74,0]],"ltp":1.65,"tv":4872.17,"id":2284304}]}]}
{"op":"mcm","clk":"1003432648","pt":1580650078353,"mc":[{"id":"1.168224581","rc":[{"batb":[[1,1.95,30.37],[2,1.01,15.51]],"ltp":3.6,"tv":289.4,"id":7797764}]}]}
{"op":"mcm","clk":"1003432836","pt":1580650079472,"mc":[{"id":"1.168224581","rc":[{"batb":[[0,1.95,30.37],[1,1.01,15.51],[2,1.01,0]],"batl":[[0,3.3,90.39],[1,3.3,0]],"ltp":3.6,"tv":289.4,"id":7797764},{"batb":[[0,1.55,34.93],[1,1.54,270.33],[2,1.53,159.21]],"batl":[[0,2,123.02],[1,2.02,124.53],[2,2.16,497.72]],"ltp":1.65,"tv":4872.17,"id":2284304}]}]}
{"op":"mcm","clk":"1003433104","pt":1580650081355,"mc":[{"id":"1.168224581","rc":[{"batb":[[0,1.97,29.66]],"ltp":3.6,"tv":289.4,"id":7797764},{"batb":[[0,1.53,35.64],[1,1.01,15.52],[2,1.53,0]],"batl":[[0,2.16,497.72],[1,2.02,0],[2,2.16,0]],"ltp":1.65,"tv":4872.17,"id":2284304}]}]}
{"op":"mcm","clk":"1003433539","pt":1580650084372,"mc":[{"id":"1.168224581","rc":[{"batb":[[0,1.7,163.64],[1,1.68,222.21],[2,1.53,35.64]],"batl":[[0,1.77,165.46],[1,1.79,181.1],[2,2.16,497.72]],"ltp":1.65,"tv":4872.17,"id":2284304}]}]}
{"op":"mcm","clk":"1003433982","pt":1580650087086,"mc":[{"id":"1.168224581","rc":[{"batb":[[0,1.53,35.64],[1,1.01,15.52],[2,1.53,0]],"batl":[[0,2.16,497.72],[1,1.79,0],[2,2.16,0]],"ltp":1.65,"tv":4872.17,"id":2284304}]}]}
{"op":"mcm","clk":"1003434504","pt":1580650090309,"mc":[{"id":"1.168224581","rc":[{"batb":[[0,1.54,267.72],[1,1.53,194.85],[2,1.01,15.52]],"batl":[[0,2,125.04],[1,2.02,124.54],[2,2.16,497.72]],"ltp":1.65,"tv":4872.17,"id":2284304}]}]}
{"op":"mcm","clk":"1003435546","pt":1580650096580,"mc":[{"id":"1.168224581","rc":[{"batb":[[0,1.53,35.64],[1,1.01,15.52],[2,1.01,0]],"ltp":1.65,"tv":4872.17,"id":2284304}]}]}
{"op":"mcm","clk":"1003435981","pt":1580650099440,"mc":[{"id":"1.168224581","rc":[{"batb":[[0,1.91,159.58],[1,1.89,149.75],[2,1.84,670.15]],"batl":[[2,2.16,0]],"ltp":1.65,"tv":4872.17,"id":2284304}]}]}
{"op":"mcm","clk":"1003436104","pt":1580650100353,"mc":[{"id":"1.168224581","rc":[{"trd":[[2.08,15.18]],"batb":[[0,2.08,23.47],[1,1.97,29.66],[2,1.6,29.58]],"batl":[[0,2.28,32.77]],"ltp":2.08,"tv":304.59,"id":7797764},{"trd":[[1.93,16.37]],"batl":[[0,1.94,42.01],[1,2,125.04],[2,2.02,124.54]],"ltp":1.93,"tv":4888.54,"id":2284304}],"tv":5193.13}]}
{"op":"mcm","clk":"1003436472","pt":1580650102337,"mc":[{"id":"1.168224581","rc":[{"batl":[[1,2.72,120.53]],"ltp":2.08,"tv":304.59,"id":7797764},{"batb":[[2,1.78,53.77]],"ltp":1.93,"tv":4888.54,"id":2284304}]}]}
{"op":"mcm","clk":"1003436628","pt":1580650103332,"mc":[{"id":"1.168224581","rc":[{"batl":[[0,2.72,120.53],[1,2.72,0]],"ltp":2.08,"tv":304.59,"id":7797764},{"batb":[[2,1.71,24.23]],"ltp":1.93,"tv":4888.54,"id":2284304}]}]}
{"op":"mcm","clk":"1003436778","pt":1580650104399,"mc":[{"id":"1.168224581","rc":[{"batb":[[0,2.08,38.59]],"ltp":2.08,"tv":304.59,"id":7797764}]}]}
{"op":"mcm","clk":"1003437025","pt":1580650106189,"mc":[{"id":"1.168224581","rc":[{"batl":[[0,2.26,32.77],[1,2.72,120.53]],"ltp":2.08,"tv":304.59,"id":7797764},{"batb":[[2,1.79,52.93]],"ltp":1.93,"tv":4888.54,"id":2284304}]}]}
{"op":"mcm","clk":"1003437283","pt":1580650107889,"mc":[{"id":"1.168224581","rc":[{"trd":[[1.91,5.24]],"batb":[[0,1.91,156.96]],"ltp":1.91,"tv":4893.78,"id":2284304}],"tv":5198.37}]}
{"op":"mcm","clk":"1003437752","pt":1580650110975,"mc":[{"id":"1.168224581","rc":[{"trd":[[1.91,17.36]],"batb":[[0,1.91,150.9]],"ltp":1.91,"tv":4905.9,"id":2284304}],"tv":5210.49}]}
{"op":"mcm","clk":"1003438307","pt":1580650114323,"mc":[{"id":"1.168224581","rc":[{"batl":[[1,2,143.7]],"ltp":1.91,"tv":4905.9,"id":2284304}]}]}
{"op":"mcm","clk":"1003439371","pt":1580650121390,"mc":[{"id":"1.168224581","rc":[{"batb":[[0,1.6,29.58],[1,1.01,15.51],[2,1.6,0]],"batl":[[0,2.72,120.53],[1,2.72,0]],"ltp":2.08,"tv":304.59,"id":7797764},{"batb":[[0,1.71,24.23],[1,1.01,15.52],[2,1.79,0]],"batl":[[0,2.5,409.11],[1,2,0],[2,2.02,0]],"ltp":1.91,"tv":4905.9,"id":2284304}]}]}
{"op":"mcm","clk":"1003439800","pt":1580650124335,"mc":[{"id":"1.168224581","rc":[{"batb":[[0,1.61,28.72],[1,1.6,29.58],[2,1.01,15.51]],"ltp":2.08,"tv":304.59,"id":7797764},{"batb":[[1,1.68,25.02],[2,1.01,15.52]],"ltp":1.91,"tv":4905.9,"id":2284304}]}]}
{"op":"mcm","clk":"1003439837","pt":1580650124608,"mc":[{"id":"1.168224581","rc":[{"batb":[[1,1.01,15.51],[2,1.01,0]],"ltp":2.08,"tv":304.59,"id":7797764},{"batb":[[0,1.68,25.02],[1,1.01,15.52],[2,1.01,0]],"ltp":1.91,"tv":4905.9,"id":2284304}]}]}
{"op":"mcm","clk":"1003440109","pt":1580650126308,"mc":[{"id":"1.168224581","rc":[{"batb":[[0,1.91,143.34],[1,1.89,149.63],[2,1.61,28.72]],"batl":[[0,2,139.89],[1,2.02,124.36]],"ltp":2.08,"tv":304.59,"id":7797764}]}]}
{"op":"mcm","clk":"1003440583","pt":1580650129402,"mc":[{"id":"1.168224581","rc":[{"batl":[[2,2.6,131.05]],"ltp":2.08,"tv":304.59,"id":7797764}]}]}
{"op":"mcm","clk":"1003440966","pt":1580650132018,"mc":[{"id":"1.168224581","rc":[{"batb":[[0,1.61,28.72],[1,1.01,15.51],[2,1.61,0]],"batl":[[0,2.6,131.05],[1,2.02,0],[2,2.6,0]],"ltp":2.08,"tv":304.59,"id":7797764}]}]}
{"op":"mcm","clk":"1003441385","pt":1580650134902,"mc":[{"id":"1.168224581","rc":[{"batb":[[0,1.62,120.45],[1,1.61,157.8],[2,1.01,15.51]],"batl":[[0,2.42,91.54],[1,2.46,145.34],[2,2.6,131.05]],"ltp":2.08,"tv":304.59,"id":7797764}]}]}
{"op":"mcm","clk":"1003443321","pt":1580650147407,"mc":[{"id":"1.168224581","rc":[{"batb":[[0,1.61,28.72],[1,1.01,15.51],[2,1.01,0]],"batl":[[0,2.6,131.05],[1,2.46,0],[2,2.6,0]],"ltp":2.08,"tv":304.59,"id":7797764}]}]}
{"op":"mcm","clk":"1003443631","pt":1580650149312,"mc":[{"id":"1.168224581","rc":[{"batl":[[0,1.82,562.93],[1,2.5,409.11]],"ltp":1.91,"tv":4905.9,"id":2284304}]}]}
{"op":"mcm","clk":"1003443822","pt":1580650150488,"mc":[{"id":"1.168224581","rc":[{"batb":[[0,2.34,31.09],[1,2.3,18.88],[2,1.84,18.25]],"batl":[[0,2.6,26.05]],"ltp":2.08,"tv":304.59,"id":7797764},{"batb":[[0,1.7,175.78],[1,1.68,247.37],[2,1.63,66.38]],"batl":[[0,1.75,42.01],[1,1.77,154.22],[2,1.79,181.22]],"ltp":1.91,"tv":4905.9,"id":2284304}]}]}
{"op":"mcm","clk":"1003444265","pt":1580650153628,"mc":[{"id":"1.168224581","rc":[{"batl":[[1,3.15,95.26]],"ltp":2.08,"tv":304.59,"id":7797764}]}]}
{"op":"mcm","clk":"1003445270","pt":1580650160306,"mc":[{"id":"1.168224581","rc":[{"trd":[[1.7,4.54]],"batb":[[0,1.7,173.51]],"ltp":1.7,"tv":4910.44,"id":2284304}],"tv":5215.03}]}
{"op":"mcm","clk":"1003446365","pt":1580650167374,"mc":[{"id":"1.168224581","rc":[{"batb":[[1,1.84,18.25],[2,1.01,15.51]],"ltp":2.08,"tv":304.59,"id":7797764},{"batb":[[0,1.63,66.38],[1,1.52,35.49],[2,1.01,15.52]],"batl":[[1,2.22,480.16],[2,1.79,0]],"ltp":1.7,"tv":4910.44,"id":2284304}]}]}
{"op":"mcm","clk":"1003446657","pt":1580650169198,"mc":[{"id":"1.168224581","rc":[{"batb":[[0,1.84,18.25],[1,1.01,15.51],[2,1.01,0]],"batl":[[0,3.15,95.26],[1,3.15,0]],"ltp":2.08,"tv":304.59,"id":7797764},{"batb":[[0,1.52,35.49],[1,1.01,15.52],[2,1.01,0]],"batl":[[0,2.22,480.16],[1,2.22,0]],"ltp":1.7,"tv":4910.44,"id":2284304}]}]}
{"op":"mcm","clk":"1003447361","pt":1580650173413,"mc":[{"id":"1.168224581","rc":[{"batb":[[0,1.76,188.55],[1,1.74,196.83],[2,1.52,35.49]],"batl":[[0,1.84,162.84],[1,1.86,160.27],[2,2.22,480.16]],"ltp":1.7,"tv":4910.44,"id":2284304}]}]}
{"op":"mcm","clk":"1003448013","pt":1580650177400,"mc":[{"id":"1.168224581","rc":[{"batl":[[0,3,102.97]],"ltp":2.08,"tv":304.59,"id":7797764}]}]}
{"op":"mcm","clk":"1003448163","pt":1580650178506,"mc":[{"id":"1.168224581","rc":[{"batb":[[0,1.52,35.49],[1,1.01,15.52],[2,1.52,0]],"batl":[[0,2.22,480.16],[1,1.86,0],[2,2.22,0]],"ltp":1.7,"tv":4910.44,"id":2284304}]}]}
{"op":"mcm","clk":"1003448585","pt":1580650181396,"mc":[{"id":"1.168224581","rc":[{"batb":[[0,1.55,237.79],[1,1.54,155.13],[2,1.52,35.49]],"batl":[[0,2.18,141.97],[1,2.2,97.34],[2,2.22,480.16]],"ltp":1.7,"tv":4910.44,"id":2284304}]}]}
{"op":"mcm","clk":"1003450093","pt":1580650191476,"mc":[{"id":"1.168224581","rc":[{"batb":[[0,1.52,35.49],[1,1.01,15.52],[2,1.52,0]],"batl":[[0,2.22,480.16],[1,2.2,0],[2,2.22,0]],"ltp":1.7,"tv":4910.44,"id":2284304}]}]}
{"op":"mcm","clk":"1003450577","pt":1580650194465,"mc":[{"id":"1.168224581","rc":[{"batb":[[0,1.85,147.3],[1,1.84,18.25],[2,1.83,165.79]],"batl":[[0,1.93,116.55],[1,1.95,138.07]],"ltp":2.08,"tv":304.59,"id":7797764},{"batb":[[0,1.83,678.22],[1,1.52,35.49],[2,1.01,15.52]],"ltp":1.7,"tv":4910.44,"id":2284304}]}]}
{"op":"mcm","clk":"1003450705","pt":1580650195374,"mc":[{"id":"1.168224581","rc":[{"batb":[[0,2.04,26.52],[1,1.83,678.22],[2,1.74,22.19]],"ltp":1.7,"tv":4910.44,"id":2284304}]}]}
{"op":"mcm","clk":"1003450825","pt":1580650196172,"mc":[{"id":"1.168224581","rc":[{"batb":[[0,1.89,47.05],[1,1.85,147.3],[2,1.84,18.25]],"batl":[[2,2.08,38.65]],"ltp":2.08,"tv":304.59,"id":7797764},{"batb":[[1,1.93,44.53],[2,1.83,678.22]],"batl":[[0,2.12,36.97]],"ltp":1.7,"tv":4910.44,"id":2284304}]}]}
{"op":"mcm","clk":"1003451002","pt":1580650197261,"mc":[{"id":"1.168224581","rc":[{"batb":[[2,1.74,22.19]],"batl":[[1,2.72,364.49]],"ltp":1.7,"tv":4910.44,"id":2284304}]}]}
{"op":"mcm","clk":"1003453467","pt":1580650210429,"mc":[{"id":"1.168224581","rc":[{"batb":[[1,1.43,45.16],[2,1.01,15.51]],"batl":[[0,2.08,38.65],[1,2.5,142.54],[2,2.08,0]],"ltp":2.08,"tv":304.59,"id":7797764},{"batb":[[0,1.93,44.53],[1,1.74,22.19],[2,1.01,15.52]],"ltp":1.7,"tv":4910.44,"id":2284304}]}]}
{"op":"mcm","clk":"1003453604","pt":1580650211322,"mc":[{"id":"1.168224581","rc":[{"batb":[[0,1.43,45.16],[1,1.01,15.51],[2,1.01,0]],"ltp":2.08,"tv":304.59,"id":7797764},{"batb":[[0,1.74,22.19],[1,1.01,15.52],[2,1.01,0]],"ltp":1.7,"tv":4910.44,"id":2284304}]}]}
{"op":"mcm","clk":"1003453818","pt":1580650212451,"mc":[{"id":"1.168224581","rc":[{"batb":[[0,1.43,309.52],[1,1.42,214.16],[2,1.01,15.51]],"batl":[[0,2.32,110.04],[1,2.36,162.44]],"ltp":2.08,"tv":304.59,"id":7797764}]}]}
{"op":"mcm","clk":"1003453957","pt":1580650213250,"mc":[{"id":"1.168224581","rc":[{"batb":[[0,1.43,45.16],[1,1.01,15.51],[2,1.01,0]],"ltp":2.08,"tv":304.59,"id":7797764}]}]}
{"op":"mcm","clk":"1003454301","pt":1580650215444,"mc":[{"id":"1.168224581","rc":[{"batb":[[0,1.75,136.74],[1,1.73,199.49],[2,1.43,45.16]],"batl":[[0,1.82,135.81],[1,1.84,164.86]],"ltp":2.08,"tv":304.59,"id":7797764}]}]}
{"op":"mcm","clk":"1003454538","pt":1580650217044,"mc":[{"id":"1.168224581","rc":[{"batl":[[2,2.36,159.81]],"ltp":2.08,"tv":304.59,"id":7797764},{"batl":[[0,2.92,336.34]],"ltp":1.7,"tv":4910.44,"id":2284304}]}]}
{"op":"mcm","clk":"1003455285","pt":1580650222219,"mc":[{"id":"1.168224581","rc":[{"batb":[[0,1.43,45.16],[1,1.01,15.51],[2,1.43,0]],"batl":[[0,2.36,159.81],[1,1.84,0],[2,2.36,0]],"ltp":2.08,"tv":304.59,"id":7797764}]}]}
{"op":"mcm","clk":"1003455621","pt":1580650224454,"mc":[{"id":"1.168224581","rc":[{"batb":[[0,1.43,313.7],[1,1.42,214.18],[2,1.01,15.51]],"batl":[[0,2.32,107.42],[1,2.36,162.43]],"ltp":2.08,"tv":304.59,"id":7797764}]}]}
{"op":"mcm","clk":"1003456498","pt":1580650230377,"mc":[{"id":"1.168224581","rc":[{"batb":[[0,1.43,45.16],[1,1.01,15.51],[2,1.01,0]],"ltp":2.08,"tv":304.59,"id":7797764}]}]}
{"op":"mcm","clk":"1003456959","pt":1580650233447,"mc":[{"id":"1.168224581","rc":[{"batl":[[0,1.83,147.71],[1,1.85,163.06],[2,1.95,562.93]],"ltp":1.7,"tv":4910.44,"id":2284304}]}]}
{"op":"mcm","clk":"1003457123","pt":1580650234417,"mc":[{"id":"1.168224581","rc":[{"batb":[[0,2.24,33.61],[1,2.2,21.48],[2,1.65,26.36]],"batl":[[0,2.48,27.73]],"ltp":2.08,"tv":304.59,"id":7797764},{"batb":[[1,1.68,61.33],[2,1.51,36.51]],"batl":[[0,1.81,42.01],[1,1.83,147.71],[2,1.85,163.06]],"ltp":1.7,"tv":4910.44,"id":2284304}]}]}
{"op":"mcm","clk":"1003457281","pt":1580650235434,"mc":[{"id":"1.168224581","rc":[{"batl":[[1,3,102.34]],"ltp":2.08,"tv":304.59,"id":7797764}]}]}
{"op":"mcm","clk":"1003457425","pt":1580650236444,"mc":[{"id":"1.168224581","rc":[{"batb":[[0,1.75,186.36],[1,1.74,22.19],[2,1.73,200.86]],"batl":[[1,1.83,176.11]],"ltp":1.7,"tv":4910.44,"id":2284304}]}]}
{"op":"mcm","clk":"1003458458","pt":1580650243023,"mc":[{"id":"1.168224581","rc":[{"trd":[[1.81,6]],"batl":[[0,1.81,39.01]],"ltp":1.81,"tv":4916.44,"id":2284304}],"tv":5221.03}]}
{"op":"mcm","clk":"1003459799","pt":1580650252450,"mc":[{"id":"1.168224581","rc":[{"batb":[[0,1.74,22.19],[1,1.68,61.33],[2,1.51,36.51]],"batl":[[1,2.3,456.2],[2,1.85,0]],"ltp":1.81,"tv":4916.44,"id":2284304}]}]}
{"op":"mcm","clk":"1003459909","pt":1580650253159,"mc":[{"id":"1.168224581","rc":[{"batb":[[0,1.65,26.36],[1,1.01,15.51],[2,1.65,0]],"batl":[[0,3,102.34],[1,3,0]],"ltp":2.08,"tv":304.59,"id":7797764},{"batb":[[0,1.51,36.51],[1,1.01,15.52],[2,1.51,0]],"batl":[[0,2.3,456.2],[1,2.3,0]],"ltp":1.81,"tv":4916.44,"id":2284304}]}]}
{"op":"mcm","clk":"1003460703","pt":1580650258346,"mc":[{"id":"1.168224581","rc":[{"batb":[[0,1.85,146.94],[1,1.83,166.26],[2,1.51,36.51]],"batl":[[0,1.93,118.76],[1,1.95,138.55],[2,2.3,456.2]],"ltp":1.81,"tv":4916.44,"id":2284304}]}]}
{"op":"mcm","clk":"1003461174","pt":1580650261613,"mc":[{"id":"1.168224581","rc":[{"batl":[[0,2.82,113.28]],"ltp":2.08,"tv":304.59,"id":7797764}]}]}
{"op":"mcm","clk":"1003461495","pt":1580650263487,"mc":[{"id":"1.168224581","rc":[{"batb":[[0,1.51,36.51],[1,1.01,15.52],[2,1.51,0]],"batl":[[0,2.3,456.2],[1,1.95,0],[2,2.3,0]],"ltp":1.81,"tv":4916.44,"id":2284304}]}]}
{"op":"mcm","clk":"1003461902","pt":1580650266006,"mc":[{"id":"1.168224581","rc":[{"batb":[[0,1.54,133.11],[1,1.53,158.86],[2,1.51,36.51]],"batl":[[0,2.52,117.01],[1,2.56,129.91]],"ltp":1.81,"tv":4916.44,"id":2284304}]}]}
{"op":"mcm","clk":"1003463448","pt":1580650276094,"mc":[{"id":"1.168224581","rc":[{"batb":[[0,1.51,36.51],[1,1.01,15.52],[2,1.51,0]],"ltp":1.81,"tv":4916.44,"id":2284304}]}]}
{"op":"mcm","clk":"1003464061","pt":1580650279465,"mc":[{"id":"1.168224581","rc":[{"batb":[[0,1.66,153.07],[1,1.65,144.6],[2,1.01,15.51]],"batl":[[0,1.72,117.9],[1,1.74,197.24]],"ltp":2.08,"tv":304.59,"id":7797764},{"batb":[[0,1.88,639.69],[1,1.51,36.51],[2,1.01,15.52]],"ltp":1.81,"tv":4916.44,"id":2284304}]}]}
{"op":"mcm","clk":"1003464209","pt":1580650280389,"mc":[{"id":"1.168224581","rc":[{"batb":[[0,1.69,60.49],[1,1.66,153.07],[2,1.65,144.6]],"batl":[[2,1.83,42.01]],"ltp":2.08,"tv":304.59,"id":7797764},{"batb":[[0,2.34,17.78],[1,2.2,34.45],[2,1.88,639.69]],"batl":[[0,2.44,28.57]],"ltp":1.81,"tv":4916.44,"id":2284304}]}]}
{"op":"mcm","clk":"1003464487","pt":1580650281983,"mc":[{"id":"1.168224581","rc":[{"batb":[[2,1.76,21.24]],"batl":[[1,3.15,307.51]],"ltp":1.81,"tv":4916.44,"id":2284304}]}]}
{"op":"mcm","clk":"1003466199","pt":1580650292208,"mc":[{"id":"1.168224581","rc":[{"batb":[[1,1.65,26.36],[2,1.18,129.12]],"batl":[[0,1.83,42.01],[1,2.22,180.57],[2,1.83,0]],"ltp":2.08,"tv":304.59,"id":7797764}]}]}
{"op":"mcm","clk":"1003466352","pt":1580650293211,"mc":[{"id":"1.168224581","rc":[{"batb":[[0,1.18,129.12],[1,1.01,15.51],[2,1.18,0]],"batl":[[0,2.22,180.57],[1,2.22,0]],"ltp":2.08,"tv":304.59,"id":7797764},{"batb":[[0,1.76,21.24],[1,1.01,15.52],[2,1.76,0]],"batl":[[0,3.15,307.51],[1,3.15,0]],"ltp":1.81,"tv":4916.44,"id":2284304}]}]}
{"op":"mcm","clk":"1003466640","pt":1580650295026,"mc":[{"id":"1.168224581","rc":[{"batb":[[1,1.16,317.38],[2,1.15,748.74]],"batl":[[0,2.3,105.54],[1,2.32,84.4]],"ltp":2.08,"tv":304.59,"id":7797764}]}]}
{"op":"mcm","clk":"1003468859","pt":1580650309451,"mc":[{"id":"1.168224581","rc":[{"trd":[[1.18,258.23]],"batb":[[0,1.16,317.38],[1,1.15,748.74],[2,1.01,15.51]],"batl":[[0,1.18,256.35],[1,1.19,529.05],[2,1.42,562.93]],"ltp":1.18,"tv":562.81,"id":7797764}],"tv":5479.26}]}
{"op":"mcm","clk":"1003469028","pt":1580650310476,"mc":[{"id":"1.168224581","rc":[{"batb":[[1,1.15,916.78],[2,1.09,258.47]],"batl":[[1,1.19,571.06]],"ltp":1.18,"tv":562.81,"id":7797764},{"batb":[[0,6.2,7.56],[1,5.5,10.86],[2,3.55,15.42]],"batl":[[0,7.6,5.88]],"ltp":1.81,"tv":4916.44,"id":2284304}]}]}
{"op":"mcm","clk":"1003469287","pt":1580650312259,"mc":[{"id":"1.168224581","rc":[{"batb":[[0,1.16,383.5]],"batl":[[0,1.18,317.4],[2,1.49,535.96]],"ltp":1.18,"tv":562.81,"id":7797764},{"batl":[[1,9.8,106.89]],"ltp":1.81,"tv":4916.44,"id":2284304}]}]}
{"op":"mcm","clk":"1003469960","pt":1580650316444,"mc":[{"id":"1.168224581","rc":[{"batb":[[1,1.15,886.07]],"ltp":1.18,"tv":562.81,"id":7797764}]}]}
{"op":"mcm","clk":"1003470242","pt":1580650318253,"mc":[{"id":"1.168224581","rc":[{"trd":[[1.16,141.48]],"batb":[[0,1.16,453.52],[2,1.08,280.89]],"ltp":1.16,"tv":704.3,"id":7797764},{"batb":[[1,5.9,19.36],[2,3.8,13.53]],"ltp":1.81,"tv":4916.44,"id":2284304}],"tv":5620.74}]}
{"op":"mcm","clk":"1003470768","pt":1580650321461,"mc":[{"id":"1.168224581","rc":[{"batb":[[0,1.16,501.89]],"ltp":1.16,"tv":704.3,"id":7797764}]}]}
{"op":"mcm","clk":"1003472582","pt":1580650332998,"mc":[{"id":"1.168224581","rc":[{"batb":[[0,1.16,422.45]],"ltp":1.16,"tv":704.3,"id":7797764}]}]}
{"op":"mcm","clk":"1003473047","pt":1580650335905,"mc":[{"id":"1.168224581","rc":[{"trd":[[1.16,159.48]],"batb":[[0,1.16,413.45]],"batl":[[0,1.18,417.84]],"ltp":1.16,"tv":722.3,"id":7797764}],"tv":5638.74}]}
{"op":"mcm","clk":"1003476254","pt":1580650356412,"mc":[{"id":"1.168224581","rc":[{"trd":[[1.16,162.85]],"batb":[[0,1.16,411.77]],"ltp":1.16,"tv":725.66,"id":7797764}],"tv":5642.1}]}
