{"op":"mcm","clk":"998156264","pt":1580585282814,"mc":[{"id":"1.168224575","marketDefinition":{"bspMarket":false,"turnInPlayEnabled":true,"persistenceEnabled":true,"marketBaseRate":5.0,"eventId":"29681732","eventTypeId":"2","numberOfWinners":1,"bettingType":"ODDS","marketType":"SET_BETTING","marketTime":"2020-02-02T09:00:00.000Z","suspendTime":"2020-02-02T09:00:00.000Z","bspReconciled":false,"complete":true,"inPlay":false,"crossMatching":false,"runnersVoidable":false,"numberOfActiveRunners":4,"betDelay":0,"status":"OPEN","runners":[{"status":"ACTIVE","sortPriority":1,"id":13024647,"name":"Stakhovsky 2-0"},{"status":"ACTIVE","sortPriority":2,"id":13024648,"name":"Stakhovsky 2-1"},{"status":"ACTIVE","sortPriority":3,"id":16575844,"name":"Vatutin 2-0"},{"status":"ACTIVE","sortPriority":4,"id":16575845,"name":"Vatutin 2-1"}],"regulators":["MR_INT"],"countryCode":"FR","discountAllowed":false,"timezone":"UTC","openDate":"2020-02-02T09:00:00.000Z","version":3147099366,"name":"Set Betting","eventName":"Stakhovsky v Vatutin"}}]}
{"op":"mcm","clk":"998156387","pt":1580585283539,"mc":[{"id":"1.168224575","marketDefinition":{"bspMarket":false,"turnInPlayEnabled":true,"persistenceEnabled":true,"marketBaseRate":5.0,"eventId":"29681732","eventTypeId":"2","numberOfWinners":1,"bettingType":"ODDS","marketType":"SET_BETTING","marketTime":"2020-02-02T09:00:00.000Z","suspendTime":"2020-02-02T09:00:00.000Z","bspReconciled":false,"complete":true,"inPlay":false,"crossMatching":false,"runnersVoidable":false,"numberOfActiveRunners":4,"betDelay":0,"status":"OPEN","runners":[{"status":"ACTIVE","sortPriority":1,"id":13024647,"name":"Stakhovsky 2-0"},{"status":"ACTIVE","sortPriority":2,"id":13024648,"name":"Stakhovsky 2-1"},{"status":"ACTIVE","sortPriority":3,"id":16575844,"name":"Vatutin 2-0"},{"status":"ACTIVE","sortPriority":4,"id":16575845,"name":"Vatutin 2-1"}],"regulators":["MR_INT"],"countryCode":"FR","discountAllowed":true,"timezone":"UTC","openDate":"2020-02-02T09:00:00.000Z","version":3147099366,"name":"Set Betting","eventName":"Stakhovsky v Vatutin"}}]}
{"op":"mcm","clk":"998196992","pt":1580585517440,"mc":[{"id":"1.168224575","marketDefinition":{"bspMarket":false,"turnInPlayEnabled":true,"persistenceEnabled":true,"marketBaseRate":5.0,"eventId":"29681732","eventTypeId":"2","numberOfWinners":1,"bettingType":"ODDS","marketType":"SET_BETTING","marketTime":"2020-02-02T13:30:00.000Z","suspendTime":"2020-02-02T13:30:00.000Z","bspReconciled":false,"complete":true,"inPlay":false,"crossMatching":false,"runnersVoidable":false,"numberOfActiveRunners":4,"betDelay":0,"status":"OPEN","runners":[{"status":"ACTIVE","sortPriority":1,"id":13024647,"name":"Stakhovsky 2-0"},{"status":"ACTIVE","sortPriority":2,"id":13024648,"name":"Stakhovsky 2-1"},{"status":"ACTIVE","sortPriority":3,"id":16575844,"name":"Vatutin 2-0"},{"status":"ACTIVE","sortPriority":4,"id":16575845,"name":"Vatutin 2-1"}],"regulators":["MR_INT"],"countryCode":"FR","discountAllowed":true,"timezone":"UTC","openDate":"2020-02-02T09:00:00.000Z","version":3147125173,"name":"Set Betting","eventName":"Stakhovsky v Vatutin"}}]}
{"op":"mcm","clk":"998197631","pt":1580585520453,"mc":[{"id":"1.168224575","marketDefinition":{"bspMarket":false,"turnInPlayEnabled":true,"persistenceEnabled":true,"marketBaseRate":5.0,"eventId":"29681732","eventTypeId":"2","numberOfWinners":1,"bettingType":"ODDS","marketType":"SET_BETTING","marketTime":"2020-02-02T13:30:00.000Z","suspendTime":"2020-02-02T13:30:00.000Z","bspReconciled":false,"complete":true,"inPlay":false,"crossMatching":false,"runnersVoidable":false,"numberOfActiveRunners":4,"betDelay":0,"status":"OPEN","runners":[{"status":"ACTIVE","sortPriority":1,"id":13024647,"name":"Stakhovsky 2-0"},{"status":"ACTIVE","sortPriority":2,"id":13024648,"name":"Stakhovsky 2-1"},{"status":"ACTIVE","sortPriority":3,"id":16575844,"name":"Vatutin 2-0"},{"status":"ACTIVE","sortPriority":4,"id":16575845,"name":"Vatutin 2-1"}],"regulators":["MR_INT"],"countryCode":"FR","discountAllowed":true,"timezone":"UTC","openDate":"2020-02-02T13:30:00.000Z","version":3147125173,"name":"Set Betting","eventName":"Stakhovsky v Vatutin"}}]}
{"op":"mcm","clk":"998566262","pt":1580587948531,"mc":[{"id":"1.168224575","rc":[{"batb":[[0,1.02,2]],"ltp":0.0,"tv":0.0,"id":13024648},{"batb":[[0,1.02,2]],"ltp":0.0,"tv":0.0,"id":13024647},{"batb":[[0,1.02,2]],"ltp":0.0,"tv":0.0,"id":16575845},{"batb":[[0,1.02,2]],"ltp":0.0,"tv":0.0,"id":16575844}]}]}
{"op":"mcm","clk":"999887417","pt":1580602189360,"mc":[{"id":"1.168224575","rc":[{"batb":[[1,1.01,2.53]],"ltp":0.0,"tv":0.0,"id":13024648},{"batb":[[1,1.01,2.53]],"ltp":0.0,"tv":0.0,"id":13024647},{"batb":[[1,1.01,2.53]],"ltp":0.0,"tv":0.0,"id":16575845},{"batb":[[1,1.01,2.53]],"ltp":0.0,"tv":0.0,"id":16575844}]}]}
{"op":"mcm","clk":"999887494","pt":1580602190419,"mc":[{"id":"1.168224575","rc":[{"batb":[[1,1.01,0.51]],"ltp":0.0,"tv":0.0,"id":13024648},{"batb":[[1,1.01,0.51]],"ltp":0.0,"tv":0.0,"id":13024647},{"batb":[[1,1.01,0.51]],"ltp":0.0,"tv":0.0,"id":16575845},{"batb":[[1,1.01,0.51]],"ltp":0.0,"tv":0.0,"id":16575844}]}]}
{"op":"mcm","clk":"999983457","pt":1580603729397,"mc":[{"id":"1.168224575","rc":[{"batb":[[1,1.01,1.01]],"ltp":0.0,"tv":0.0,"id":13024648},{"batb":[[1,1.01,1.01]],"ltp":0.0,"tv":0.0,"id":13024647},{"batb":[[1,1.01,1.01]],"ltp":0.0,"tv":0.0,"id":16575845},{"batb":[[1,1.01,1.01]],"ltp":0.0,"tv":0.0,"id":16575844}]}]}
{"op":"mcm","clk":"1001172945","pt":1580630119141,"mc":[{"id":"1.168224575","rc":[{"batb":[[0,2.04,30.29],[1,1.02,2],[2,1.01,1.01]],"ltp":0.0,"tv":0.0,"id":13024647}]}]}
{"op":"mcm","clk":"1001222289","pt":1580631092610,"mc":[{"id":"1.168224575","rc":[{"batb":[[0,2.22,30.29]],"ltp":0.0,"tv":0.0,"id":13024647}]}]}
{"op":"mcm","clk":"1001263364","pt":1580632066924,"mc":[{"id":"1.168224575","rc":[{"batb":[[0,2.34,30.29]],"ltp":0.0,"tv":0.0,"id":13024647}]}]}
{"op":"mcm","clk":"1001426134","pt":1580635614335,"mc":[{"id":"1.168224575","marketDefinition":{"bspMarket":false,"turnInPlayEnabled":true,"persistenceEnabled":true,"marketBaseRate":5.0,"eventId":"29681732","eventTypeId":"2","numberOfWinners":1,"bettingType":"ODDS","marketType":"SET_BETTING","marketTime":"2020-02-02T13:24:00.000Z","suspendTime":"2020-02-02T13:24:00.000Z","bspReconciled":false,"complete":true,"inPlay":false,"crossMatching":false,"runnersVoidable":false,"numberOfActiveRunners":4,"betDelay":0,"status":"OPEN","runners":[{"status":"ACTIVE","sortPriority":1,"id":13024647,"name":"Stakhovsky 2-0"},{"status":"ACTIVE","sortPriority":2,"id":13024648,"name":"Stakhovsky 2-1"},{"status":"ACTIVE","sortPriority":3,"id":16575844,"name":"Vatutin 2-0"},{"status":"ACTIVE","sortPriority":4,"id":16575845,"name":"Vatutin 2-1"}],"regulators":["MR_INT"],"countryCode":"FR","discountAllowed":true,"timezone":"UTC","openDate":"2020-02-02T13:30:00.000Z","version":3148345545,"name":"Set Betting","eventName":"Stakhovsky v Vatutin"}}]}
{"op":"mcm","clk":"1001426516","pt":1580635617339,"mc":[{"id":"1.168224575","marketDefinition":{"bspMarket":false,"turnInPlayEnabled":true,"persistenceEnabled":true,"marketBaseRate":5.0,"eventId":"29681732","eventTypeId":"2","numberOfWinners":1,"bettingType":"ODDS","marketType":"SET_BETTING","marketTime":"2020-02-02T13:24:00.000Z","suspendTime":"2020-02-02T13:24:00.000Z","bspReconciled":false,"complete":true,"inPlay":false,"crossMatching":false,"runnersVoidable":false,"numberOfActiveRunners":4,"betDelay":0,"status":"OPEN","runners":[{"status":"ACTIVE","sortPriority":1,"id":13024647,"name":"Stakhovsky 2-0"},{"status":"ACTIVE","sortPriority":2,"id":13024648,"name":"Stakhovsky 2-1"},{"status":"ACTIVE","sortPriority":3,"id":16575844,"name":"Vatutin 2-0"},{"status":"ACTIVE","sortPriority":4,"id":16575845,"name":"Vatutin 2-1"}],"regulators":["MR_INT"],"countryCode":"FR","discountAllowed":true,"timezone":"UTC","openDate":"2020-02-02T13:24:00.000Z","version":3148345545,"name":"Set Betting","eventName":"Stakhovsky v Vatutin"}}]}
{"op":"mcm","clk":"1001816438","pt":1580640415425,"mc":[{"id":"1.168224575","marketDefinition":{"bspMarket":false,"turnInPlayEnabled":true,"persistenceEnabled":true,"marketBaseRate":5.0,"eventId":"29681732","eventTypeId":"2","numberOfWinners":1,"bettingType":"ODDS","marketType":"SET_BETTING","marketTime":"2020-02-02T12:51:00.000Z","suspendTime":"2020-02-02T12:51:00.000Z","bspReconciled":false,"complete":true,"inPlay":false,"crossMatching":false,"runnersVoidable":false,"numberOfActiveRunners":4,"betDelay":0,"status":"OPEN","runners":[{"status":"ACTIVE","sortPriority":1,"id":13024647,"name":"Stakhovsky 2-0"},{"status":"ACTIVE","sortPriority":2,"id":13024648,"name":"Stakhovsky 2-1"},{"status":"ACTIVE","sortPriority":3,"id":16575844,"name":"Vatutin 2-0"},{"status":"ACTIVE","sortPriority":4,"id":16575845,"name":"Vatutin 2-1"}],"regulators":["MR_INT"],"countryCode":"FR","discountAllowed":true,"timezone":"UTC","openDate":"2020-02-02T13:24:00.000Z","version":3148438473,"name":"Set Betting","eventName":"Stakhovsky v Vatutin"}}]}
{"op":"mcm","clk":"1001817075","pt":1580640420557,"mc":[{"id":"1.168224575","marketDefinition":{"bspMarket":false,"turnInPlayEnabled":true,"persistenceEnabled":true,"marketBaseRate":5.0,"eventId":"29681732","eventTypeId":"2","numberOfWinners":1,"bettingType":"ODDS","marketType":"SET_BETTING","marketTime":"2020-02-02T12:51:00.000Z","suspendTime":"2020-02-02T12:51:00.000Z","bspReconciled":false,"complete":true,"inPlay":false,"crossMatching":false,"runnersVoidable":false,"numberOfActiveRunners":4,"betDelay":0,"status":"OPEN","runners":[{"status":"ACTIVE","sortPriority":1,"id":13024647,"name":"Stakhovsky 2-0"},{"status":"ACTIVE","sortPriority":2,"id":13024648,"name":"Stakhovsky 2-1"},{"status":"ACTIVE","sortPriority":3,"id":16575844,"name":"Vatutin 2-0"},{"status":"ACTIVE","sortPriority":4,"id":16575845,"name":"Vatutin 2-1"}],"regulators":["MR_INT"],"countryCode":"FR","discountAllowed":true,"timezone":"UTC","openDate":"2020-02-02T12:51:00.000Z","version":3148438473,"name":"Set Betting","eventName":"Stakhovsky v Vatutin"}}]}
{"op":"mcm","clk":"1001853014","pt":1580640715139,"mc":[{"id":"1.168224575","marketDefinition":{"bspMarket":false,"turnInPlayEnabled":true,"persistenceEnabled":true,"marketBaseRate":5.0,"eventId":"29681732","eventTypeId":"2","numberOfWinners":1,"bettingType":"ODDS","marketType":"SET_BETTING","marketTime":"2020-02-02T12:48:00.000Z","suspendTime":"2020-02-02T12:48:00.000Z","bspReconciled":false,"complete":true,"inPlay":false,"crossMatching":false,"runnersVoidable":false,"numberOfActiveRunners":4,"betDelay":0,"status":"OPEN","runners":[{"status":"ACTIVE","sortPriority":1,"id":13024647,"name":"Stakhovsky 2-0"},{"status":"ACTIVE","sortPriority":2,"id":13024648,"name":"Stakhovsky 2-1"},{"status":"ACTIVE","sortPriority":3,"id":16575844,"name":"Vatutin 2-0"},{"status":"ACTIVE","sortPriority":4,"id":16575845,"name":"Vatutin 2-1"}],"regulators":["MR_INT"],"countryCode":"FR","discountAllowed":true,"timezone":"UTC","openDate":"2020-02-02T12:51:00.000Z","version":3148443733,"name":"Set Betting","eventName":"Stakhovsky v Vatutin"}}]}
{"op":"mcm","clk":"1001853277","pt":1580640717181,"mc":[{"id":"1.168224575","marketDefinition":{"bspMarket":false,"turnInPlayEnabled":true,"persistenceEnabled":true,"marketBaseRate":5.0,"eventId":"29681732","eventTypeId":"2","numberOfWinners":1,"bettingType":"ODDS","marketType":"SET_BETTING","marketTime":"2020-02-02T12:48:00.000Z","suspendTime":"2020-02-02T12:48:00.000Z","bspReconciled":false,"complete":true,"inPlay":false,"crossMatching":false,"runnersVoidable":false,"numberOfActiveRunners":4,"betDelay":0,"status":"OPEN","runners":[{"status":"ACTIVE","sortPriority":1,"id":13024647,"name":"Stakhovsky 2-0"},{"status":"ACTIVE","sortPriority":2,"id":13024648,"name":"Stakhovsky 2-1"},{"status":"ACTIVE","sortPriority":3,"id":16575844,"name":"Vatutin 2-0"},{"status":"ACTIVE","sortPriority":4,"id":16575845,"name":"Vatutin 2-1"}],"regulators":["MR_INT"],"countryCode":"FR","discountAllowed":true,"timezone":"UTC","openDate":"2020-02-02T12:48:00.000Z","version":3148443733,"name":"Set Betting","eventName":"Stakhovsky v Vatutin"}}]}
{"op":"mcm","clk":"1002081052","pt":1580642171007,"mc":[{"id":"1.168224575","rc":[{"batb":[[0,1.02,2],[1,1.01,1.01],[2,1.01,0]],"ltp":0.0,"tv":0.0,"id":13024647}]}]}
{"op":"mcm","clk":"1002676463","pt":1580645815895,"mc":[{"id":"1.168224575","marketDefinition":{"bspMarket":false,"turnInPlayEnabled":true,"persistenceEnabled":true,"marketBaseRate":5.0,"eventId":"29681732","eventTypeId":"2","numberOfWinners":1,"bettingType":"ODDS","marketType":"SET_BETTING","marketTime":"2020-02-02T12:16:00.000Z","suspendTime":"2020-02-02T12:16:00.000Z","bspReconciled":false,"complete":true,"inPlay":false,"crossMatching":false,"runnersVoidable":false,"numberOfActiveRunners":4,"betDelay":0,"status":"OPEN","runners":[{"status":"ACTIVE","sortPriority":1,"id":13024647,"name":"Stakhovsky 2-0"},{"status":"ACTIVE","sortPriority":2,"id":13024648,"name":"Stakhovsky 2-1"},{"status":"ACTIVE","sortPriority":3,"id":16575844,"name":"Vatutin 2-0"},{"status":"ACTIVE","sortPriority":4,"id":16575845,"name":"Vatutin 2-1"}],"regulators":["MR_INT"],"countryCode":"FR","discountAllowed":true,"timezone":"UTC","openDate":"2020-02-02T12:48:00.000Z","version":3148684855,"name":"Set Betting","eventName":"Stakhovsky v Vatutin"}}]}
{"op":"mcm","clk":"1002676963","pt":1580645818903,"mc":[{"id":"1.168224575","marketDefinition":{"bspMarket":false,"turnInPlayEnabled":true,"persistenceEnabled":true,"marketBaseRate":5.0,"eventId":"29681732","eventTypeId":"2","numberOfWinners":1,"bettingType":"ODDS","marketType":"SET_BETTING","marketTime":"2020-02-02T12:16:00.000Z","suspendTime":"2020-02-02T12:16:00.000Z","bspReconciled":false,"complete":true,"inPlay":false,"crossMatching":false,"runnersVoidable":false,"numberOfActiveRunners":4,"betDelay":0,"status":"OPEN","runners":[{"status":"ACTIVE","sortPriority":1,"id":13024647,"name":"Stakhovsky 2-0"},{"status":"ACTIVE","sortPriority":2,"id":13024648,"name":"Stakhovsky 2-1"},{"status":"ACTIVE","sortPriority":3,"id":16575844,"name":"Vatutin 2-0"},{"status":"ACTIVE","sortPriority":4,"id":16575845,"name":"Vatutin 2-1"}],"regulators":["MR_INT"],"countryCode":"FR","discountAllowed":true,"timezone":"UTC","openDate":"2020-02-02T12:16:00.000Z","version":3148684855,"name":"Set Betting","eventName":"Stakhovsky v Vatutin"}}]}
{"op":"mcm","clk":"1002680995","pt":1580645843375,"mc":[{"id":"1.168224575","rc":[{"batb":[[0,4.4,17.86],[1,1.02,2],[2,1.01,1.01]],"batl":[[0,5.1,17]],"ltp":0.0,"tv":0.0,"id":13024648},{"batb":[[0,2.86,10.46],[1,1.02,2],[2,1.01,1.01]],"batl":[[0,3.15,10.31]],"ltp":0.0,"tv":0.0,"id":13024647},{"batb":[[0,4.9,13.53],[1,1.02,2],[2,1.01,1.01]],"batl":[[0,5.8,12.98]],"ltp":0.0,"tv":0.0,"id":16575845},{"batb":[[0,3.55,15.26],[1,1.02,2],[2,1.01,1.01]],"batl":[[0,3.95,14.79]],"ltp":0.0,"tv":0.0,"id":16575844}]}]}
{"op":"mcm","clk":"1002681431","pt":1580645845985,"mc":[{"id":"1.168224575","rc":[{"batb":[[0,2.88,2],[1,2.86,10.46],[2,1.02,2]],"ltp":0.0,"tv":0.0,"id":13024647},{"batb":[[0,3.6,2],[1,3.55,15.26],[2,1.02,2]],"ltp":0.0,"tv":0.0,"id":16575844}]}]}
{"op":"mcm","clk":"1002684251","pt":1580645864025,"mc":[{"id":"1.168224575","marketDefinition":{"bspMarket":false,"turnInPlayEnabled":true,"persistenceEnabled":true,"marketBaseRate":5.0,"eventId":"29681732","eventTypeId":"2","numberOfWinners":1,"bettingType":"ODDS","marketType":"SET_BETTING","marketTime":"2020-02-02T12:16:00.000Z","suspendTime":"2020-02-02T12:16:00.000Z","bspReconciled":false,"complete":true,"inPlay":false,"crossMatching":true,"runnersVoidable":false,"numberOfActiveRunners":4,"betDelay":0,"status":"OPEN","runners":[{"status":"ACTIVE","sortPriority":1,"id":13024647,"name":"Stakhovsky 2-0"},{"status":"ACTIVE","sortPriority":2,"id":13024648,"name":"Stakhovsky 2-1"},{"status":"ACTIVE","sortPriority":3,"id":16575844,"name":"Vatutin 2-0"},{"status":"ACTIVE","sortPriority":4,"id":16575845,"name":"Vatutin 2-1"}],"regulators":["MR_INT"],"countryCode":"FR","discountAllowed":true,"timezone":"UTC","openDate":"2020-02-02T12:16:00.000Z","version":3148684855,"name":"Set Betting","eventName":"Stakhovsky v Vatutin"}}]}
{"op":"mcm","clk":"1002729975","pt":1580646162288,"mc":[{"id":"1.168224575","rc":[{"trd":[[2.86,62.51],[2.88,4]],"batb":[[0,1.02,2],[1,1.01,1.01],[2,1.02,0]],"batl":[[0,2.86,122.11],[1,3.15,10.31]],"ltp":2.86,"tv":66.51,"id":13024647}],"tv":66.51}]}
{"op":"mcm","clk":"1002730090","pt":1580646163088,"mc":[{"id":"1.168224575","rc":[{"batb":[[0,4.4,17.7]],"ltp":0.0,"tv":0.0,"id":13024648},{"batb":[[0,2.84,10.62],[1,1.02,2],[2,1.01,1.01]],"batl":[[1,3.1,10.46]],"ltp":2.86,"tv":66.51,"id":13024647},{"batb":[[0,5,13.45]],"ltp":0.0,"tv":0.0,"id":16575845},{"batb":[[1,3.55,15.11]],"batl":[[0,4,14.63]],"ltp":0.0,"tv":0.0,"id":16575844}]}]}
{"op":"mcm","clk":"1002731530","pt":1580646172283,"mc":[{"id":"1.168224575","rc":[{"trd":[[2.84,21.24]],"batb":[[0,1.02,2],[1,1.01,1.01],[2,1.01,0]],"batl":[[0,2.84,111.49]],"ltp":2.84,"tv":87.75,"id":13024647}],"tv":87.75}]}
{"op":"mcm","clk":"1002731680","pt":1580646173193,"mc":[{"id":"1.168224575","rc":[{"batb":[[0,4.5,17.55]],"batl":[[0,5.1,16.76]],"ltp":0.0,"tv":0.0,"id":13024648},{"batb":[[0,2.82,10.78],[1,1.02,2],[2,1.01,1.01]],"batl":[[1,3,10.62]],"ltp":2.84,"tv":87.75,"id":13024647},{"batb":[[0,5,13.3]],"batl":[[0,5.8,12.75]],"ltp":0.0,"tv":0.0,"id":16575845},{"batb":[[0,3.6,17.03],[1,1.02,2],[2,1.01,1.01]],"batl":[[0,3.95,14.56]],"ltp":0.0,"tv":0.0,"id":16575844}]}]}
{"op":"mcm","clk":"1002742081","pt":1580646239479,"mc":[{"id":"1.168224575","rc":[{"trd":[[2.82,21.56]],"batb":[[0,1.02,2],[1,1.01,1.01],[2,1.01,0]],"batl":[[0,2.82,100.71]],"ltp":2.82,"tv":109.31,"id":13024647}],"tv":109.31}]}
{"op":"mcm","clk":"1002742247","pt":1580646240381,"mc":[{"id":"1.168224575","rc":[{"batl":[[0,5.1,16.6]],"ltp":0.0,"tv":0.0,"id":13024648},{"trd":[[2.82,29.14]],"batb":[[0,2.8,11.02],[1,1.02,2],[2,1.01,1.01]],"batl":[[0,2.82,96.92],[1,2.98,10.78]],"ltp":2.82,"tv":116.89,"id":13024647},{"batb":[[0,5.1,13.22]],"ltp":0.0,"tv":0.0,"id":16575845},{"batb":[[0,3.6,16.87]],"batl":[[0,4,14.48]],"ltp":0.0,"tv":0.0,"id":16575844}],"tv":116.89}]}
{"op":"mcm","clk":"1002746060","pt":1580646264288,"mc":[{"id":"1.168224575","rc":[{"trd":[[2.8,22.03]],"batb":[[0,1.02,2],[1,1.01,1.01],[2,1.01,0]],"batl":[[0,2.8,85.91]],"ltp":2.8,"tv":138.92,"id":13024647}],"tv":138.92}]}
{"op":"mcm","clk":"1002746145","pt":1580646264879,"mc":[{"id":"1.168224575","rc":[{"batb":[[0,4.5,17.31]],"ltp":0.0,"tv":0.0,"id":13024648},{"batb":[[0,2.78,11.17],[1,1.02,2],[2,1.01,1.01]],"batl":[[1,2.96,11.02]],"ltp":2.8,"tv":138.92,"id":13024647},{"batl":[[0,5.8,12.59]],"ltp":0.0,"tv":0.0,"id":16575845},{"batb":[[0,3.65,14.79],[1,3.6,2],[2,1.02,2]],"batl":[[0,4,14.32]],"ltp":0.0,"tv":0.0,"id":16575844}]}]}
{"op":"mcm","clk":"1002749748","pt":1580646288005,"mc":[{"id":"1.168224575","rc":[{"batb":[[1,4.4,11.76],[2,1.02,2]],"batl":[[1,5.2,9.24]],"ltp":0.0,"tv":0.0,"id":13024648},{"trd":[[2.8,112.77]],"batb":[[0,2.78,34.7]],"batl":[[0,2.8,40.54],[2,3.1,19.32]],"ltp":2.8,"tv":229.66,"id":13024647},{"batb":[[1,4.8,10.92],[2,1.02,2]],"batl":[[0,5.7,8.4],[1,5.8,12.59]],"ltp":0.0,"tv":0.0,"id":16575845},{"batb":[[1,3.6,17.96]],"batl":[[1,4.1,13.44]],"ltp":0.0,"tv":0.0,"id":16575844}],"tv":229.66}]}
{"op":"mcm","clk":"1002755811","pt":1580646327412,"mc":[{"id":"1.168224575","rc":[{"trd":[[2.78,12.58]],"batb":[[0,2.78,28.41]],"ltp":2.78,"tv":242.24,"id":13024647}],"tv":242.24}]}
{"op":"mcm","clk":"1002755948","pt":1580646328201,"mc":[{"id":"1.168224575","rc":[{"batb":[[0,2.78,34.78]],"ltp":2.78,"tv":242.24,"id":13024647}]}]}
{"op":"mcm","clk":"1002756015","pt":1580646328526,"mc":[{"id":"1.168224575","rc":[{"batl":[[0,5.1,16.44]],"ltp":0.0,"tv":0.0,"id":13024648},{"batb":[[0,5.1,13.06]],"ltp":0.0,"tv":0.0,"id":16575845}]}]}
{"op":"mcm","clk":"1002757590","pt":1580646338259,"mc":[{"id":"1.168224575","rc":[{"batb":[[0,4.6,17.15]],"batl":[[0,5.2,25.61],[1,5.2,0]],"ltp":0.0,"tv":0.0,"id":13024648}]}]}
{"op":"mcm","clk":"1002767285","pt":1580646402388,"mc":[{"id":"1.168224575","rc":[{"batl":[[0,2.82,40.54]],"ltp":2.78,"tv":242.24,"id":13024647}]}]}
{"op":"mcm","clk":"1002773137","pt":1580646438269,"mc":[{"id":"1.168224575","rc":[{"batl":[[0,2.8,40.54]],"ltp":2.78,"tv":242.24,"id":13024647}]}]}
{"op":"mcm","clk":"1002774313","pt":1580646445318,"mc":[{"id":"1.168224575","rc":[{"batb":[[1,3.6,15.96]],"ltp":0.0,"tv":0.0,"id":16575844}]}]}
{"op":"mcm","clk":"1002776753","pt":1580646461600,"mc":[{"id":"1.168224575","rc":[{"batb":[[0,3.7,2],[1,3.65,14.79],[2,3.6,15.96]],"ltp":0.0,"tv":0.0,"id":16575844}]}]}
{"op":"mcm","clk":"1002787425","pt":1580646527443,"mc":[{"id":"1.168224575","marketDefinition":{"bspMarket":false,"turnInPlayEnabled":true,"persistenceEnabled":true,"marketBaseRate":5.0,"eventId":"29681732","eventTypeId":"2","numberOfWinners":1,"bettingType":"ODDS","marketType":"SET_BETTING","marketTime":"2020-02-02T12:16:00.000Z","suspendTime":"2020-02-02T12:16:00.000Z","bspReconciled":false,"complete":true,"inPlay":true,"crossMatching":true,"runnersVoidable":false,"numberOfActiveRunners":4,"betDelay":3,"status":"OPEN","runners":[{"status":"ACTIVE","sortPriority":1,"id":13024647,"name":"Stakhovsky 2-0"},{"status":"ACTIVE","sortPriority":2,"id":13024648,"name":"Stakhovsky 2-1"},{"status":"ACTIVE","sortPriority":3,"id":16575844,"name":"Vatutin 2-0"},{"status":"ACTIVE","sortPriority":4,"id":16575845,"name":"Vatutin 2-1"}],"regulators":["MR_INT"],"countryCode":"FR","discountAllowed":true,"timezone":"UTC","openDate":"2020-02-02T12:16:00.000Z","version":3148714994,"name":"Set Betting","eventName":"Stakhovsky v Vatutin"},"rc":[{"batb":[[0,1.01,0.51],[1,4.4,0],[2,1.02,0]],"ltp":0.0,"tv":0.0,"id":13024648},{"batb":[[0,1.01,0.51],[1,1.02,0],[2,1.01,0]],"batl":[[1,2.96,0],[2,3.1,0]],"ltp":2.78,"tv":242.24,"id":13024647},{"batb":[[0,1.01,0.51],[1,4.8,0],[2,1.02,0]],"ltp":0.0,"tv":0.0,"id":16575845},{"batb":[[0,1.01,0.51],[1,3.65,0],[2,3.6,0]],"ltp":0.0,"tv":0.0,"id":16575844}]}]}
{"op":"mcm","clk":"1002788360","pt":1580646532728,"mc":[{"id":"1.168224575","rc":[{"batb":[[0,4.4,40.44],[1,4.3,45.17],[2,1.01,0.51]],"ltp":0.0,"tv":0.0,"id":13024648},{"batb":[[0,2.68,43.88],[1,2.64,60.75],[2,1.01,0.51]],"ltp":2.78,"tv":242.24,"id":13024647},{"batb":[[0,5,28.41],[1,4.9,33.65],[2,1.01,0.51]],"ltp":0.0,"tv":0.0,"id":16575845},{"batb":[[0,3.45,44.66],[1,3.4,39.93],[2,1.01,0.51]],"ltp":0.0,"tv":0.0,"id":16575844}]}]}
{"op":"mcm","clk":"1002789202","pt":1580646537546,"mc":[{"id":"1.168224575","rc":[{"batb":[[0,1.01,0.51],[1,2.64,0],[2,1.01,0]],"ltp":2.78,"tv":242.24,"id":13024647}]}]}
{"op":"mcm","clk":"1002789707","pt":1580646540456,"mc":[{"id":"1.168224575","rc":[{"trd":[[2.8,193.85]],"batb":[[0,3.1,39.26],[1,3.05,51.91],[2,1.01,0.51]],"ltp":2.8,"tv":323.32,"id":13024647}],"tv":323.32}]}
{"op":"mcm","clk":"1002789899","pt":1580646541457,"mc":[{"id":"1.168224575","rc":[{"batb":[[0,4.5,18.02],[1,4.4,40.44],[2,4.3,45.17]],"batl":[[0,5.1,16.44]],"ltp":0.0,"tv":0.0,"id":13024648},{"batb":[[2,2.98,23.45]],"batl":[[0,3.2,22.58],[1,3.45,19.2]],"ltp":2.8,"tv":323.32,"id":13024647},{"batb":[[0,5.1,13.3],[1,5,28.41],[2,4.9,33.65]],"batl":[[0,5.9,12.35]],"ltp":0.0,"tv":0.0,"id":16575845},{"batb":[[2,3.35,18.1]],"batl":[[0,3.65,17.47],[1,4.1,13.61]],"ltp":0.0,"tv":0.0,"id":16575844}]}]}
{"op":"mcm","clk":"1002790053","pt":1580646542340,"mc":[{"id":"1.168224575","rc":[{"batb":[[1,4.4,52.2]],"batl":[[1,5.2,9.24]],"ltp":0.0,"tv":0.0,"id":13024648},{"batl":[[1,3.25,18.48],[2,3.45,19.2]],"ltp":2.8,"tv":323.32,"id":13024647},{"batl":[[0,5.7,8.4],[1,5.9,12.35]],"ltp":0.0,"tv":0.0,"id":16575845},{"batb":[[0,3.45,61.46]],"ltp":0.0,"tv":0.0,"id":16575844}]}]}
{"op":"mcm","clk":"1002790393","pt":1580646544277,"mc":[{"id":"1.168224575","rc":[{"batb":[[0,3.1,72.75]],"ltp":2.8,"tv":323.32,"id":13024647},{"batl":[[1,3.9,14.28],[2,4.1,13.61]],"ltp":0.0,"tv":0.0,"id":16575844}]}]}
{"op":"mcm","clk":"1002792696","pt":1580646557291,"mc":[{"id":"1.168224575","rc":[{"batb":[[1,4.4,40.44]],"batl":[[1,5.2,0]],"ltp":0.0,"tv":0.0,"id":13024648},{"batb":[[0,2.72,11.8],[1,1.01,0.51],[2,2.98,0]],"batl":[[0,3.45,19.2],[1,3.25,0],[2,3.45,0]],"ltp":2.8,"tv":323.32,"id":13024647},{"batb":[[1,5,20.94]],"batl":[[0,5.9,12.35],[1,5.9,0]],"ltp":0.0,"tv":0.0,"id":16575845},{"batb":[[0,3.2,20.77],[1,1.01,0.51],[2,3.35,0]],"batl":[[0,4.1,13.61],[1,3.9,0],[2,4.1,0]],"ltp":0.0,"tv":0.0,"id":16575844}]}]}
{"op":"mcm","clk":"1002793390","pt":1580646561469,"mc":[{"id":"1.168224575","rc":[{"batb":[[1,4.4,49.82]],"ltp":0.0,"tv":0.0,"id":13024648},{"batb":[[0,3.05,77.17],[1,3,54.17],[2,2.72,11.8]],"ltp":2.8,"tv":323.32,"id":13024647},{"batb":[[0,3.5,49.02],[1,3.45,38.46],[2,3.2,20.77]],"ltp":0.0,"tv":0.0,"id":16575844}]}]}
{"op":"mcm","clk":"1002794023","pt":1580646565565,"mc":[{"id":"1.168224575","rc":[{"batb":[[1,4.4,40.44]],"ltp":0.0,"tv":0.0,"id":13024648},{"batb":[[0,2.72,11.8],[1,1.01,0.51],[2,2.72,0]],"ltp":2.8,"tv":323.32,"id":13024647},{"batb":[[0,3.2,20.77],[1,1.01,0.51],[2,3.2,0]],"ltp":0.0,"tv":0.0,"id":16575844}]}]}
{"op":"mcm","clk":"1002794623","pt":1580646569216,"mc":[{"id":"1.168224575","rc":[{"batb":[[0,3.25,68.6],[1,3.2,66.86],[2,1.01,0.51]],"ltp":0.0,"tv":0.0,"id":16575844}]}]}
{"op":"mcm","clk":"1002795126","pt":1580646572208,"mc":[{"id":"1.168224575","rc":[{"batb":[[0,3.3,50.26],[1,3.25,44.56],[2,2.72,11.8]],"ltp":2.8,"tv":323.32,"id":13024647}]}]}
{"op":"mcm","clk":"1002795295","pt":1580646573256,"mc":[{"id":"1.168224575","rc":[{"batb":[[2,3.15,19.91]],"batl":[[1,3.65,16.84]],"ltp":2.8,"tv":323.32,"id":13024647},{"batb":[[0,5,34.47],[1,4.9,33.65],[2,1.01,0.51]],"batl":[[0,5.8,12.59]],"ltp":0.0,"tv":0.0,"id":16575845},{"batb":[[2,3.05,23.37]],"batl":[[0,3.45,20.06],[1,3.75,16.68]],"ltp":0.0,"tv":0.0,"id":16575844}]}]}
{"op":"mcm","clk":"1002795441","pt":1580646574005,"mc":[{"id":"1.168224575","rc":[{"batb":[[1,4.4,52.2]],"batl":[[0,5.1,26.53]],"ltp":0.0,"tv":0.0,"id":13024648},{"batl":[[0,3.4,16.8],[1,3.45,19.2],[2,3.65,16.84]],"ltp":2.8,"tv":323.32,"id":13024647},{"batb":[[2,4.8,10.92]],"batl":[[0,5.7,8.4],[1,5.8,12.59]],"ltp":0.0,"tv":0.0,"id":16575845},{"batb":[[0,3.25,87.08]],"batl":[[1,3.7,15.12],[2,3.75,16.68]],"ltp":0.0,"tv":0.0,"id":16575844}]}]}
{"op":"mcm","clk":"1002797689","pt":1580646589026,"mc":[{"id":"1.168224575","rc":[{"batb":[[1,4.4,40.44]],"batl":[[0,5.1,16.44]],"ltp":0.0,"tv":0.0,"id":13024648},{"batb":[[0,2.94,24.31],[1,1.01,0.51],[2,3.15,0]],"batl":[[0,3.65,16.84],[1,3.45,0],[2,3.65,0]],"ltp":2.8,"tv":323.32,"id":13024647},{"batb":[[0,5,13.53],[2,1.01,0.51]],"batl":[[0,5.8,12.59],[1,5.8,0]],"ltp":0.0,"tv":0.0,"id":16575845},{"batb":[[0,3.05,23.37],[1,1.01,0.51],[2,3.05,0]],"batl":[[0,3.75,16.68],[1,3.7,0],[2,3.75,0]],"ltp":0.0,"tv":0.0,"id":16575844}]}]}
{"op":"mcm","clk":"1002798151","pt":1580646592148,"mc":[{"id":"1.168224575","rc":[{"batb":[[1,4.9,33.7]],"ltp":0.0,"tv":0.0,"id":16575845}]}]}
{"op":"mcm","clk":"1002798521","pt":1580646594427,"mc":[{"id":"1.168224575","rc":[{"batb":[[0,3.25,56.71],[1,3.2,46.24],[2,2.94,24.31]],"ltp":2.8,"tv":323.32,"id":13024647},{"batb":[[0,5,36.32]],"ltp":0.0,"tv":0.0,"id":16575845},{"batb":[[0,3.3,58.83],[1,3.25,44.44],[2,3.05,23.37]],"ltp":0.0,"tv":0.0,"id":16575844}]}]}
{"op":"mcm","clk":"1002799637","pt":1580646601466,"mc":[{"id":"1.168224575","rc":[{"batb":[[0,2.94,24.31],[1,1.01,0.51],[2,2.94,0]],"ltp":2.8,"tv":323.32,"id":13024647},{"batb":[[0,5,13.53]],"ltp":0.0,"tv":0.0,"id":16575845},{"batb":[[0,3.05,23.37],[1,1.01,0.51],[2,3.05,0]],"ltp":0.0,"tv":0.0,"id":16575844}]}]}
{"op":"mcm","clk":"1002800276","pt":1580646604568,"mc":[{"id":"1.168224575","rc":[{"batb":[[0,3.1,46.58],[1,3.05,52.22],[2,2.94,24.31]],"ltp":2.8,"tv":323.32,"id":13024647},{"batb":[[1,4.9,50.24],[2,4.8,34.88]],"ltp":0.0,"tv":0.0,"id":16575845},{"batb":[[0,3.15,59.94],[1,3.1,49.98],[2,3.05,23.37]],"ltp":0.0,"tv":0.0,"id":16575844}]}]}
{"op":"mcm","clk":"1002803332","pt":1580646621868,"mc":[{"id":"1.168224575","rc":[{"batb":[[1,4.9,33.65],[2,1.01,0.51]],"ltp":0.0,"tv":0.0,"id":16575845},{"batb":[[0,3.05,23.37],[1,1.01,0.51],[2,3.05,0]],"ltp":0.0,"tv":0.0,"id":16575844}]}]}
{"op":"mcm","clk":"1002803962","pt":1580646625488,"mc":[{"id":"1.168224575","rc":[{"batl":[[1,5.2,16.13]],"ltp":0.0,"tv":0.0,"id":13024648},{"batl":[[0,3.2,23.29],[1,3.4,19.59],[2,3.65,16.84]],"ltp":2.8,"tv":323.32,"id":13024647},{"batb":[[0,5.1,13.06],[1,5,43.31],[2,4.9,33.65]],"ltp":0.0,"tv":0.0,"id":16575845},{"batb":[[0,3.5,32.62],[1,3.45,55.92],[2,3.2,20.69]],"batl":[[1,4.2,12.9]],"ltp":0.0,"tv":0.0,"id":16575844}]}]}
{"op":"mcm","clk":"1002804083","pt":1580646626083,"mc":[{"id":"1.168224575","rc":[{"batb":[[1,4.4,52.2]],"batl":[[0,5.1,26.53]],"ltp":0.0,"tv":0.0,"id":13024648},{"batl":[[1,3.25,18.48],[2,3.4,19.59]],"ltp":2.8,"tv":323.32,"id":13024647},{"batb":[[1,5,29.78],[2,4.9,43.73]],"batl":[[0,5.7,8.4],[1,5.8,12.59]],"ltp":0.0,"tv":0.0,"id":16575845},{"batb":[[1,3.45,72.72]],"batl":[[1,3.9,14.28],[2,4.2,12.9]],"ltp":0.0,"tv":0.0,"id":16575844}]}]}
{"op":"mcm","clk":"1002804891","pt":1580646630487,"mc":[{"id":"1.168224575","rc":[{"batb":[[2,4.9,33.65]],"ltp":0.0,"tv":0.0,"id":16575845}]}]}
{"op":"mcm","clk":"1002805111","pt":1580646631824,"mc":[{"id":"1.168224575","rc":[{"batb":[[1,5,20.6]],"ltp":0.0,"tv":0.0,"id":16575845},{"batb":[[0,3.45,72.72],[1,3.2,20.69],[2,1.01,0.51]],"ltp":0.0,"tv":0.0,"id":16575844}]}]}
{"op":"mcm","clk":"1002805616","pt":1580646634819,"mc":[{"id":"1.168224575","rc":[{"batb":[[1,4.4,64.75]],"ltp":0.0,"tv":0.0,"id":13024648},{"batb":[[0,3.1,62.13]],"ltp":2.8,"tv":323.32,"id":13024647},{"batb":[[0,3.45,90.96],[1,3.4,39.65],[2,3.2,20.69]],"ltp":0.0,"tv":0.0,"id":16575844}]}]}
{"op":"mcm","clk":"1002806167","pt":1580646638112,"mc":[{"id":"1.168224575","rc":[{"batl":[[0,5.1,16.44]],"ltp":0.0,"tv":0.0,"id":13024648}]}]}
{"op":"mcm","clk":"1002806802","pt":1580646641491,"mc":[{"id":"1.168224575","rc":[{"batl":[[1,5.2,25.37]],"ltp":0.0,"tv":0.0,"id":13024648}]}]}
{"op":"mcm","clk":"1002807527","pt":1580646645631,"mc":[{"id":"1.168224575","rc":[{"batl":[[1,3.4,19.59],[2,3.4,0]],"ltp":2.8,"tv":323.32,"id":13024647},{"batl":[[0,5.8,12.59],[1,5.8,0]],"ltp":0.0,"tv":0.0,"id":16575845},{"batb":[[0,3.45,74.16]],"ltp":0.0,"tv":0.0,"id":16575844}]}]}
{"op":"mcm","clk":"1002807916","pt":1580646647921,"mc":[{"id":"1.168224575","rc":[{"batb":[[1,4.4,52.2]],"batl":[[0,5.2,25.37],[1,5.2,0]],"ltp":0.0,"tv":0.0,"id":13024648},{"batb":[[0,2.9,21.85],[1,2.68,12.43],[2,1.01,0.51]],"batl":[[0,3.4,19.59],[1,3.4,0]],"ltp":2.8,"tv":323.32,"id":13024647},{"batb":[[1,4.9,33.65],[2,4.8,10.92]],"ltp":0.0,"tv":0.0,"id":16575845},{"batb":[[0,3.2,20.69],[1,1.01,0.51],[2,3.2,0]],"batl":[[0,3.9,14.28],[1,4.2,12.9],[2,4.2,0]],"ltp":0.0,"tv":0.0,"id":16575844}]}]}
{"op":"mcm","clk":"1002808151","pt":1580646649150,"mc":[{"id":"1.168224575","rc":[{"batb":[[1,4.4,40.44]],"batl":[[0,5.2,16.13]],"ltp":0.0,"tv":0.0,"id":13024648},{"batb":[[0,2.68,12.43],[1,1.01,0.51],[2,1.01,0]],"ltp":2.8,"tv":323.32,"id":13024647},{"batb":[[2,1.01,0.51]],"ltp":0.0,"tv":0.0,"id":16575845},{"batl":[[0,4.2,12.9],[1,4.2,0]],"ltp":0.0,"tv":0.0,"id":16575844}]}]}
{"op":"mcm","clk":"1002808499","pt":1580646651251,"mc":[{"id":"1.168224575","rc":[{"batb":[[0,4.5,17.62]],"batl":[[0,5.2,15.82]],"ltp":0.0,"tv":0.0,"id":13024648},{"batb":[[0,2.7,12.12]],"batl":[[0,3.45,19.12]],"ltp":2.8,"tv":323.32,"id":13024647},{"batb":[[0,3.15,21.17]],"ltp":0.0,"tv":0.0,"id":16575844}]}]}
{"op":"mcm","clk":"1002808907","pt":1580646653759,"mc":[{"id":"1.168224575","rc":[{"batb":[[1,4.4,52.62]],"ltp":0.0,"tv":0.0,"id":13024648},{"batb":[[0,3.05,43.28],[1,3,54.56],[2,2.7,12.12]],"ltp":2.8,"tv":323.32,"id":13024647},{"batb":[[1,5,26.5],[2,4.9,33.65]],"ltp":0.0,"tv":0.0,"id":16575845},{"batb":[[0,3.55,41.46],[1,3.5,37.15],[2,3.15,21.17]],"ltp":0.0,"tv":0.0,"id":16575844}]}]}
{"op":"mcm","clk":"1002809558","pt":1580646657574,"mc":[{"id":"1.168224575","rc":[{"batb":[[1,4.4,40.44]],"ltp":0.0,"tv":0.0,"id":13024648},{"batb":[[0,2.7,12.12],[1,1.01,0.51],[2,2.7,0]],"ltp":2.8,"tv":323.32,"id":13024647},{"batb":[[1,4.9,33.65],[2,1.01,0.51]],"ltp":0.0,"tv":0.0,"id":16575845},{"batb":[[0,3.15,21.17],[1,1.01,0.51],[2,3.15,0]],"ltp":0.0,"tv":0.0,"id":16575844}]}]}
{"op":"mcm","clk":"1002810065","pt":1580646660501,"mc":[{"id":"1.168224575","rc":[{"batb":[[0,2.82,52.35],[1,2.78,53.12],[2,2.7,12.12]],"ltp":2.8,"tv":323.32,"id":13024647},{"batb":[[1,4.9,53.9],[2,4.8,34.74]],"ltp":0.0,"tv":0.0,"id":16575845},{"batb":[[0,3.25,67.24],[1,3.2,46.03],[2,3.15,21.17]],"ltp":0.0,"tv":0.0,"id":16575844}]}]}
{"op":"mcm","clk":"1002812319","pt":1580646673396,"mc":[{"id":"1.168224575","rc":[{"batb":[[0,2.7,12.12],[1,1.01,0.51],[2,2.7,0]],"ltp":2.8,"tv":323.32,"id":13024647}]}]}
{"op":"mcm","clk":"1002812851","pt":1580646676488,"mc":[{"id":"1.168224575","rc":[{"batb":[[0,3.3,54.33],[1,3.25,44.59],[2,2.7,12.12]],"ltp":2.8,"tv":323.32,"id":13024647}]}]}
{"op":"mcm","clk":"1002813002","pt":1580646677393,"mc":[{"id":"1.168224575","rc":[{"batl":[[0,5.1,16.6]],"ltp":0.0,"tv":0.0,"id":13024648},{"batb":[[2,3.15,19.83]],"batl":[[1,3.65,16.6]],"ltp":2.8,"tv":323.32,"id":13024647},{"batl":[[0,3.45,20.46],[1,3.7,17.15]],"ltp":0.0,"tv":0.0,"id":16575844}]}]}
{"op":"mcm","clk":"1002813127","pt":1580646678089,"mc":[{"id":"1.168224575","rc":[{"batb":[[0,4.5,29.39]],"batl":[[1,5.2,9.24]],"ltp":0.0,"tv":0.0,"id":13024648},{"batl":[[0,3.45,35.92]],"ltp":2.8,"tv":323.32,"id":13024647},{"batl":[[0,5.6,8.4],[1,5.8,12.59]],"ltp":0.0,"tv":0.0,"id":16575845},{"batb":[[0,3.25,85.72]],"batl":[[1,3.7,32.28]],"ltp":0.0,"tv":0.0,"id":16575844}]}]}
{"op":"mcm","clk":"1002815659","pt":1580646692295,"mc":[{"id":"1.168224575","rc":[{"batb":[[0,3.05,20.16],[1,2.98,23.68],[2,1.01,0.51]],"batl":[[0,3.45,16.8]],"ltp":2.8,"tv":323.32,"id":13024647},{"batb":[[0,3.25,18.48],[1,3,23.84],[2,1.01,0.51]],"batl":[[0,3.7,32.28],[1,3.7,0]],"ltp":0.0,"tv":0.0,"id":16575844}]}]}
{"op":"mcm","clk":"1002815835","pt":1580646693191,"mc":[{"id":"1.168224575","rc":[{"batb":[[0,4.5,17.62]],"batl":[[1,5.2,0]],"ltp":0.0,"tv":0.0,"id":13024648},{"batb":[[0,2.98,23.68],[1,1.01,0.51],[2,1.01,0]],"batl":[[0,3.65,16.6],[1,3.65,0]],"ltp":2.8,"tv":323.32,"id":13024647},{"batl":[[0,5.8,12.59],[1,5.8,0]],"ltp":0.0,"tv":0.0,"id":16575845},{"batb":[[0,3,23.84],[1,1.01,0.51],[2,1.01,0]],"batl":[[0,3.7,17.15]],"ltp":0.0,"tv":0.0,"id":16575844}]}]}
{"op":"mcm","clk":"1002816141","pt":1580646694983,"mc":[{"id":"1.168224575","rc":[{"batb":[[0,4.4,58.62],[1,4.3,45.17],[2,1.01,0.51]],"ltp":0.0,"tv":0.0,"id":13024648},{"batb":[[0,3.1,59.44],[1,3.05,52.19],[2,2.96,24]],"ltp":2.8,"tv":323.32,"id":13024647},{"batb":[[0,3.15,62.1],[1,3.1,49.88],[2,3,23.53]],"batl":[[0,3.7,16.92]],"ltp":0.0,"tv":0.0,"id":16575844}]}]}
{"op":"mcm","clk":"1002816793","pt":1580646698787,"mc":[{"id":"1.168224575","rc":[{"batb":[[0,2.96,24],[1,1.01,0.51],[2,2.96,0]],"ltp":2.8,"tv":323.32,"id":13024647}]}]}
{"op":"mcm","clk":"1002817407","pt":1580646702314,"mc":[{"id":"1.168224575","rc":[{"batb":[[0,4.5,11.76],[1,4.4,58.62],[2,4.3,45.17]],"batl":[[0,5,17.15],[1,5.1,16.6],[2,5.2,9.24]],"ltp":0.0,"tv":0.0,"id":13024648},{"batb":[[0,3.45,36.46],[1,3.4,40.07],[2,3.35,17.39]],"batl":[[0,3.65,31.73],[1,4.2,24.47]],"ltp":2.8,"tv":323.32,"id":13024647},{"batb":[[1,5,13.61],[2,4.9,53.9]],"batl":[[0,5.5,9.24],[1,5.8,12.59]],"ltp":0.0,"tv":0.0,"id":16575845},{"batb":[[2,3.05,20.16]],"batl":[[0,3.3,22.66],[1,3.5,16.8],[2,3.55,18.96]],"ltp":0.0,"tv":0.0,"id":16575844}]}]}
{"op":"mcm","clk":"1002817470","pt":1580646702634,"mc":[{"id":"1.168224575","rc":[{"batl":[[1,5.2,9.24],[2,5.2,0]],"ltp":0.0,"tv":0.0,"id":13024648},{"batb":[[0,5,13.61],[1,4.9,53.9],[2,4.8,34.74]],"ltp":0.0,"tv":0.0,"id":16575845}]}]}
{"op":"mcm","clk":"1002823384","pt":1580646734319,"mc":[{"id":"1.168224575","rc":[{"batb":[[1,4.4,18.18]],"ltp":0.0,"tv":0.0,"id":13024648},{"batb":[[0,3.4,40.07],[1,3.35,17.39],[2,3.25,18.48]],"ltp":2.8,"tv":323.32,"id":13024647},{"batb":[[1,4.9,33.76],[2,4.7,10.92]],"ltp":0.0,"tv":0.0,"id":16575845},{"batb":[[0,3.15,48.37],[1,3,23.53],[2,2.76,11.96]],"ltp":0.0,"tv":0.0,"id":16575844}]}]}
{"op":"mcm","clk":"1002823918","pt":1580646737309,"mc":[{"id":"1.168224575","rc":[{"batb":[[2,4.3,54.95]],"ltp":0.0,"tv":0.0,"id":13024648},{"batb":[[0,3.4,43.31],[1,3.35,58.57]],"ltp":2.8,"tv":323.32,"id":13024647},{"batb":[[0,5,38.51]],"ltp":0.0,"tv":0.0,"id":16575845},{"batb":[[0,3.2,32.34],[1,3.15,48.37],[2,3.1,19.32]],"ltp":0.0,"tv":0.0,"id":16575844}]}]}
{"op":"mcm","clk":"1002824298","pt":1580646739326,"mc":[{"id":"1.168224575","rc":[{"batb":[[2,4.3,45.17]],"ltp":0.0,"tv":0.0,"id":13024648},{"batb":[[0,3.35,17.39],[1,3.25,18.48],[2,3.1,20.85]],"ltp":2.8,"tv":323.32,"id":13024647},{"batb":[[0,3.1,19.32],[1,3,23.53],[2,2.76,11.96]],"ltp":0.0,"tv":0.0,"id":16575844}]}]}
{"op":"mcm","clk":"1002824489","pt":1580646740386,"mc":[{"id":"1.168224575","rc":[{"batb":[[0,5,48.86]],"ltp":0.0,"tv":0.0,"id":16575845}]}]}
{"op":"mcm","clk":"1002824822","pt":1580646742069,"mc":[{"id":"1.168224575","rc":[{"batb":[[2,3.15,77.14]],"ltp":2.8,"tv":323.32,"id":13024647},{"batb":[[2,2.9,55.79]],"ltp":0.0,"tv":0.0,"id":16575844}]}]}
{"op":"mcm","clk":"1002826271","pt":1580646749267,"mc":[{"id":"1.168224575","rc":[{"batb":[[0,4.4,18.18],[1,4.3,45.17],[2,4.2,47.25]],"batl":[[1,5.2,0]],"ltp":0.0,"tv":0.0,"id":13024648},{"batb":[[0,3.15,77.14],[1,3.1,70.43],[2,1.01,0.51]],"batl":[[0,4.2,24.47],[1,4.2,0]],"ltp":2.8,"tv":323.32,"id":13024647},{"batb":[[2,1.01,0.51]],"batl":[[0,5.8,12.59],[1,5.8,0]],"ltp":0.0,"tv":0.0,"id":16575845},{"batb":[[0,2.9,55.79],[1,2.86,49.51],[2,2.76,11.96]],"batl":[[0,3.55,18.96],[1,3.5,0],[2,3.55,0]],"ltp":0.0,"tv":0.0,"id":16575844}]}]}
{"op":"mcm","clk":"1002826673","pt":1580646751450,"mc":[{"id":"1.168224575","rc":[{"batl":[[0,4.1,25.49],[1,4.2,24.47]],"ltp":2.8,"tv":323.32,"id":13024647},{"batb":[[0,5.1,13.3],[1,5,48.86],[2,4.9,33.76]],"ltp":0.0,"tv":0.0,"id":16575845},{"batb":[[2,2.8,11.64]],"batl":[[1,3.6,18.49]],"ltp":0.0,"tv":0.0,"id":16575844}]}]}
{"op":"mcm","clk":"1002826870","pt":1580646752363,"mc":[{"id":"1.168224575","rc":[{"batb":[[0,3.1,20.85],[1,1.01,0.51],[2,1.01,0]],"batl":[[1,4.2,0]],"ltp":2.8,"tv":323.32,"id":13024647},{"batb":[[1,5,35.25]],"batl":[[0,5.8,12.43]],"ltp":0.0,"tv":0.0,"id":16575845},{"batl":[[0,3.6,18.49],[1,3.6,0]],"ltp":0.0,"tv":0.0,"id":16575844}]}]}
{"op":"mcm","clk":"1002827510","pt":1580646755470,"mc":[{"id":"1.168224575","rc":[{"batb":[[0,3.85,41.02],[1,3.8,30.38],[2,3.1,20.85]],"ltp":2.8,"tv":323.32,"id":13024647}]}]}
{"op":"mcm","clk":"1002827717","pt":1580646756491,"mc":[{"id":"1.168224575","rc":[{"batb":[[0,4.3,64.84],[1,4.2,47.25],[2,1.01,0.51]],"batl":[[0,4.9,17.94],[1,5,17.15],[2,5.2,9.24]],"ltp":0.0,"tv":0.0,"id":13024648},{"batb":[[2,3.75,13.14]],"batl":[[0,4.1,38.94],[1,5,16.68]],"ltp":2.8,"tv":323.32,"id":13024647},{"batb":[[0,5.1,13.14]],"batl":[[0,5.5,9.24],[1,5.9,12.27]],"ltp":0.0,"tv":0.0,"id":16575845},{"batl":[[0,2.96,11.49],[1,3.2,18.48],[2,3.25,23.13]],"ltp":0.0,"tv":0.0,"id":16575844}]}]}
{"op":"mcm","clk":"1002828151","pt":1580646758464,"mc":[{"id":"1.168224575","rc":[{"batb":[[0,4.5,11.76],[1,4.3,64.84],[2,4.2,47.25]],"ltp":0.0,"tv":0.0,"id":13024648}]}]}
{"op":"mcm","clk":"1002828328","pt":1580646759372,"mc":[{"id":"1.168224575","rc":[{"batb":[[2,2.84,22.69]],"ltp":0.0,"tv":0.0,"id":16575844}]}]}
{"op":"mcm","clk":"1002830422","pt":1580646769770,"mc":[{"id":"1.168224575","rc":[{"batb":[[1,4.3,19.67]],"batl":[[0,5,17.15],[1,5.2,9.24],[2,5.2,0]],"ltp":0.0,"tv":0.0,"id":13024648},{"batb":[[0,3.6,15.96],[1,3.4,16.92],[2,1.01,0.51]],"batl":[[0,4.1,13.44]],"ltp":2.8,"tv":323.32,"id":13024647},{"batb":[[0,2.84,22.69],[1,2.52,15.34],[2,1.01,0.51]],"batl":[[0,3.2,18.48],[1,3.25,23.13],[2,3.25,0]],"ltp":0.0,"tv":0.0,"id":16575844}]}]}
{"op":"mcm","clk":"1002830723","pt":1580646771229,"mc":[{"id":"1.168224575","rc":[{"batb":[[0,4.3,19.67],[1,4.2,47.25],[2,1.01,0.51]],"batl":[[1,5.2,0]],"ltp":0.0,"tv":0.0,"id":13024648},{"batb":[[0,3.4,16.92],[1,1.01,0.51],[2,1.01,0]],"batl":[[0,5,16.68],[1,5,0]],"ltp":2.8,"tv":323.32,"id":13024647},{"batl":[[0,5.9,12.27],[1,5.9,0]],"ltp":0.0,"tv":0.0,"id":16575845},{"batb":[[0,2.52,15.34],[1,1.01,0.51],[2,1.01,0]],"batl":[[0,3.25,23.13],[1,3.25,0]],"ltp":0.0,"tv":0.0,"id":16575844}]}]}
{"op":"mcm","clk":"1002831148","pt":1580646773391,"mc":[{"id":"1.168224575","rc":[{"batb":[[1,4.2,65.03],[2,4.1,49.84]],"ltp":0.0,"tv":0.0,"id":13024648},{"batb":[[0,3.35,17]],"ltp":2.8,"tv":323.32,"id":13024647},{"batb":[[0,2.6,40.26],[1,2.56,66.22],[2,2.52,15.34]],"ltp":0.0,"tv":0.0,"id":16575844}]}]}
{"op":"mcm","clk":"1002831715","pt":1580646776398,"mc":[{"id":"1.168224575","rc":[{"batb":[[0,4.6,56.34],[1,4.5,40.13],[2,3.35,17]],"ltp":2.8,"tv":323.32,"id":13024647}]}]}
{"op":"mcm","clk":"1002831907","pt":1580646777408,"mc":[{"id":"1.168224575","rc":[{"batb":[[0,4.2,85.33],[1,4.1,49.84],[2,1.01,0.51]],"batl":[[0,4.9,18.33]],"ltp":0.0,"tv":0.0,"id":13024648},{"batb":[[2,4.4,17.55]],"batl":[[1,6.2,10.46]],"ltp":2.8,"tv":323.32,"id":13024647},{"batb":[[0,5.2,12.83]],"ltp":0.0,"tv":0.0,"id":16575845},{"batl":[[0,2.66,14.95],[1,2.88,12.35]],"ltp":0.0,"tv":0.0,"id":16575844}]}]}
{"op":"mcm","clk":"1002832079","pt":1580646778319,"mc":[{"id":"1.168224575","rc":[{"batb":[[0,4.4,11.76],[1,4.2,85.33],[2,4.1,49.84]],"batl":[[1,5.1,10.08]],"ltp":0.0,"tv":0.0,"id":13024648},{"batl":[[0,5,26.76]],"ltp":2.8,"tv":323.32,"id":13024647},{"batl":[[0,5.4,9.24],[1,5.9,12.27]],"ltp":0.0,"tv":0.0,"id":16575845},{"batb":[[1,2.56,93.11]],"batl":[[1,2.86,21.85],[2,2.88,12.35]],"ltp":0.0,"tv":0.0,"id":16575844}]}]}
{"op":"mcm","clk":"1002834207","pt":1580646789328,"mc":[{"id":"1.168224575","rc":[{"batb":[[1,4.2,67.55]],"ltp":0.0,"tv":0.0,"id":13024648},{"batb":[[0,4.4,17.55],[1,4.2,12.6],[2,3.9,23.84]],"ltp":2.8,"tv":323.32,"id":13024647},{"batb":[[0,2.56,26.89],[1,2.52,15.34],[2,2.3,19.67]],"ltp":0.0,"tv":0.0,"id":16575844}]}]}
{"op":"mcm","clk":"1002834251","pt":1580646789545,"mc":[{"id":"1.168224575","rc":[{"batb":[[0,4.2,12.6],[1,3.9,23.84],[2,1.01,0.51]],"batl":[[0,5,10.08]],"ltp":2.8,"tv":323.32,"id":13024647},{"batb":[[1,2.3,19.67],[2,1.01,0.51]],"batl":[[0,2.86,21.85],[1,2.88,12.35],[2,2.88,0]],"ltp":0.0,"tv":0.0,"id":16575844}]}]}
{"op":"mcm","clk":"1002834577","pt":1580646791250,"mc":[{"id":"1.168224575","rc":[{"batb":[[0,4.2,67.55],[1,4.1,49.84],[2,1.01,0.51]],"batl":[[1,5.1,0]],"ltp":0.0,"tv":0.0,"id":13024648},{"batb":[[0,3.9,23.84],[1,1.01,0.51],[2,1.01,0]],"batl":[[0,6.2,10.46],[1,6.2,0]],"ltp":2.8,"tv":323.32,"id":13024647},{"batl":[[0,5.9,12.27],[1,5.9,0]],"ltp":0.0,"tv":0.0,"id":16575845},{"batb":[[0,2.3,19.67],[1,1.01,0.51],[2,1.01,0]],"batl":[[0,2.88,12.35],[1,2.88,0]],"ltp":0.0,"tv":0.0,"id":16575844}]}]}
{"op":"mcm","clk":"1002834807","pt":1580646792334,"mc":[{"id":"1.168224575","rc":[{"batb":[[0,4.1,31.07],[1,4,53.3],[2,3.9,23.84]],"ltp":2.8,"tv":323.32,"id":13024647},{"batb":[[0,2.32,55.53],[1,2.3,64.33],[2,1.01,0.51]],"ltp":0.0,"tv":0.0,"id":16575844}]}]}
{"op":"mcm","clk":"1002835043","pt":1580646793453,"mc":[{"id":"1.168224575","rc":[{"batb":[[0,3.9,23.84],[1,1.01,0.51],[2,3.9,0]],"ltp":2.8,"tv":323.32,"id":13024647}]}]}
{"op":"mcm","clk":"1002835629","pt":1580646796424,"mc":[{"id":"1.168224575","rc":[{"batb":[[0,6,32.99],[1,5.9,21.95],[2,3.9,23.84]],"ltp":2.8,"tv":323.32,"id":13024647}]}]}
{"op":"mcm","clk":"1002835841","pt":1580646797452,"mc":[{"id":"1.168224575","rc":[{"batl":[[0,4.8,18.96]],"ltp":0.0,"tv":0.0,"id":13024648},{"batb":[[2,5.4,10.86]],"batl":[[1,7.6,13.69]],"ltp":2.8,"tv":323.32,"id":13024647},{"batb":[[0,5.1,12.98]],"batl":[[1,6,11.88]],"ltp":0.0,"tv":0.0,"id":16575845},{"batb":[[2,2.12,24.23]],"batl":[[0,2.42,19.2],[1,2.56,16.52]],"ltp":0.0,"tv":0.0,"id":16575844}]}]}
{"op":"mcm","clk":"1002836038","pt":1580646798462,"mc":[{"id":"1.168224575","rc":[{"batb":[[0,4.3,12.6],[1,4.2,67.55],[2,4.1,49.84]],"batl":[[1,5,10.08]],"ltp":0.0,"tv":0.0,"id":13024648},{"batl":[[1,6.4,7.56],[2,7.6,13.69]],"ltp":2.8,"tv":323.32,"id":13024647},{"batl":[[0,5.5,9.24],[1,5.9,12.27],[2,6,11.88]],"ltp":0.0,"tv":0.0,"id":16575845},{"batb":[[0,2.32,86.62]],"batl":[[1,2.56,43.41]],"ltp":0.0,"tv":0.0,"id":16575844}]}]}
{"op":"mcm","clk":"1002837999","pt":1580646808447,"mc":[{"id":"1.168224575","rc":[{"batb":[[1,4.2,56.44]],"ltp":0.0,"tv":0.0,"id":13024648},{"batb":[[0,5.4,10.86],[1,5.3,9.24],[2,4.8,14.32]],"ltp":2.8,"tv":323.32,"id":13024647},{"batb":[[0,2.32,31.09],[1,2.3,19.67]],"ltp":0.0,"tv":0.0,"id":16575844}]}]}
{"op":"mcm","clk":"1002838180","pt":1580646809457,"mc":[{"id":"1.168224575","rc":[{"batb":[[0,4.2,56.44],[1,4.1,49.84],[2,1.01,0.51]],"batl":[[1,5,0]],"ltp":0.0,"tv":0.0,"id":13024648},{"batb":[[0,4.8,14.32],[1,1.01,0.51],[2,4.8,0]],"batl":[[0,7.6,13.69],[1,6.4,0],[2,7.6,0]],"ltp":2.8,"tv":323.32,"id":13024647},{"batl":[[0,6,11.88],[1,5.9,0],[2,6,0]],"ltp":0.0,"tv":0.0,"id":16575845},{"batb":[[0,2.12,24.23],[1,1.01,0.51],[2,2.12,0]],"batl":[[0,2.56,16.52],[1,2.56,0]],"ltp":0.0,"tv":0.0,"id":16575844}]}]}
{"op":"mcm","clk":"1002838563","pt":1580646811415,"mc":[{"id":"1.168224575","rc":[{"batb":[[0,5.3,31.06],[1,5.2,29.17],[2,4.8,14.32]],"ltp":2.8,"tv":323.32,"id":13024647},{"batb":[[0,2.14,75.73],[1,2.12,80.57],[2,1.01,0.51]],"ltp":0.0,"tv":0.0,"id":16575844}]}]}
{"op":"mcm","clk":"1002838636","pt":1580646811830,"mc":[{"id":"1.168224575","rc":[{"batb":[[0,4.2,56.13]],"batl":[[0,4.9,18.57]],"ltp":0.0,"tv":0.0,"id":13024648},{"batb":[[2,4.9,14.01]],"batl":[[0,7.8,13.38]],"ltp":2.8,"tv":323.32,"id":13024647},{"batl":[[0,2.54,16.84]],"ltp":0.0,"tv":0.0,"id":16575844}]}]}
{"op":"mcm","clk":"1002839660","pt":1580646817351,"mc":[{"id":"1.168224575","rc":[{"batb":[[0,4.9,14.01],[1,1.01,0.51],[2,4.9,0]],"ltp":2.8,"tv":323.32,"id":13024647}]}]}
{"op":"mcm","clk":"1002840239","pt":1580646820420,"mc":[{"id":"1.168224575","rc":[{"batl":[[1,5.2,9.24]],"ltp":0.0,"tv":0.0,"id":13024648},{"batb":[[0,7.6,35.14],[1,7.4,32.09],[2,4.9,14.01]],"ltp":2.8,"tv":323.32,"id":13024647},{"batl":[[0,5.4,9.24]],"ltp":0.0,"tv":0.0,"id":16575845},{"batl":[[0,2.24,33.61],[1,2.54,16.84]],"ltp":0.0,"tv":0.0,"id":16575844}]}]}
{"op":"mcm","clk":"1002840420","pt":1580646821477,"mc":[{"id":"1.168224575","rc":[{"batb":[[0,4.3,19.75],[1,4.2,36.14],[2,4.1,49.84]],"ltp":0.0,"tv":0.0,"id":13024648},{"trd":[[7.6,20]],"batb":[[0,7.6,25.14],[2,6.4,14.24]],"batl":[[1,9.2,9.6]],"ltp":7.6,"tv":343.32,"id":13024647},{"batl":[[1,5.9,12.04]],"ltp":0.0,"tv":0.0,"id":16575845},{"batb":[[2,2.02,27.93]],"batl":[[0,2.24,57.61],[1,2.42,19.28]],"ltp":0.0,"tv":0.0,"id":16575844}],"tv":343.32}]}
{"op":"mcm","clk":"1002840770","pt":1580646823133,"mc":[{"id":"1.168224575","rc":[{"batb":[[0,4.5,11.76],[1,4.3,19.75],[2,4.2,36.14]],"ltp":0.0,"tv":0.0,"id":13024648},{"batl":[[1,9.2,14.64]],"ltp":7.6,"tv":343.32,"id":13024647},{"batb":[[2,2.04,40.33]],"ltp":0.0,"tv":0.0,"id":16575844}]}]}
{"op":"mcm","clk":"1002841040","pt":1580646824452,"mc":[{"id":"1.168224575","rc":[{"batb":[[0,7.6,33.22]],"ltp":7.6,"tv":343.32,"id":13024647}]}]}
{"op":"mcm","clk":"1002843853","pt":1580646839152,"mc":[{"id":"1.168224575","rc":[{"batb":[[0,7.6,25.32],[1,7.4,5.88]],"ltp":7.6,"tv":343.32,"id":13024647},{"batb":[[0,2.12,80.57],[1,2.04,40.33],[2,2.02,27.93]],"ltp":0.0,"tv":0.0,"id":16575844}]}]}
{"op":"mcm","clk":"1002844499","pt":1580646842252,"mc":[{"id":"1.168224575","rc":[{"batb":[[2,4.2,58.32]],"ltp":0.0,"tv":0.0,"id":13024648},{"trd":[[7.8,26.76]],"batb":[[0,7.4,5.88],[1,5.4,10.94],[2,1.01,0.51]],"batl":[[0,9.2,14.64],[1,9.2,0]],"ltp":7.8,"tv":370.07,"id":13024647},{"batb":[[1,5,26.73]],"ltp":0.0,"tv":0.0,"id":16575845},{"batb":[[0,2.04,40.33],[1,2.02,27.93],[2,1.01,0.51]],"batl":[[0,2.24,33.61]],"ltp":0.0,"tv":0.0,"id":16575844}],"tv":370.07}]}
{"op":"mcm","clk":"1002844688","pt":1580646843309,"mc":[{"id":"1.168224575","rc":[{"batb":[[0,4.3,19.75],[1,4.2,58.32],[2,4.1,49.84]],"batl":[[1,5.2,0]],"ltp":0.0,"tv":0.0,"id":13024648},{"batb":[[0,5.4,10.94],[1,1.01,0.51],[2,1.01,0]],"batl":[[0,9.2,9.6]],"ltp":7.8,"tv":370.07,"id":13024647},{"batl":[[0,5.9,12.04],[1,5.9,0]],"ltp":0.0,"tv":0.0,"id":16575845},{"batb":[[0,2.02,27.93],[1,1.01,0.51],[2,1.01,0]],"batl":[[0,2.42,19.28],[1,2.42,0]],"ltp":0.0,"tv":0.0,"id":16575844}]}]}
{"op":"mcm","clk":"1002845066","pt":1580646845306,"mc":[{"id":"1.168224575","rc":[{"batb":[[0,6.2,31.02],[1,6,41.89],[2,5.4,10.94]],"ltp":7.8,"tv":370.07,"id":13024647},{"batb":[[0,2.06,49.89],[1,2.04,63.16],[2,2.02,27.93]],"ltp":0.0,"tv":0.0,"id":16575844}]}]}
{"op":"mcm","clk":"1002845151","pt":1580646845689,"mc":[{"id":"1.168224575","rc":[{"batb":[[0,2.02,27.93],[1,1.01,0.51],[2,2.02,0]],"ltp":0.0,"tv":0.0,"id":16575844}]}]}
{"op":"mcm","clk":"1002845834","pt":1580646849404,"mc":[{"id":"1.168224575","rc":[{"batb":[[0,4.2,78.54],[1,4.1,49.84],[2,1.01,0.51]],"batl":[[0,4.8,18.73]],"ltp":0.0,"tv":0.0,"id":13024648},{"batb":[[2,5.5,10.39]],"batl":[[0,6.6,19.36],[1,7.8,13.61]],"ltp":7.8,"tv":370.07,"id":13024647},{"batb":[[0,5,40.11],[1,4.9,33.76],[2,1.01,0.51]],"batl":[[0,5.8,12.35]],"ltp":0.0,"tv":0.0,"id":16575845},{"batb":[[0,2.28,80.47],[1,2.26,66.86],[2,2.14,23.6]],"batl":[[0,2.4,19.59],[1,2.64,15.42]],"ltp":0.0,"tv":0.0,"id":16575844}]}]}
{"op":"mcm","clk":"1002846011","pt":1580646850296,"mc":[{"id":"1.168224575","rc":[{"batb":[[0,4.4,11.76],[1,4.2,78.54],[2,4.1,49.84]],"batl":[[1,5.1,10.08]],"ltp":0.0,"tv":0.0,"id":13024648},{"batb":[[0,6.2,38.58]],"batl":[[1,7.4,5.88],[2,7.8,13.61]],"ltp":7.8,"tv":370.07,"id":13024647},{"batb":[[2,4.6,10.92]],"batl":[[0,5.3,9.24],[1,5.8,12.35]],"ltp":0.0,"tv":0.0,"id":16575845},{"batb":[[2,2.18,35.29]],"batl":[[0,2.4,49]],"ltp":0.0,"tv":0.0,"id":16575844}]}]}
{"op":"mcm","clk":"1002847750","pt":1580646859343,"mc":[{"id":"1.168224575","rc":[{"batb":[[0,4.2,69.88],[1,4.1,49.84],[2,1.01,0.51]],"batl":[[1,5.1,0]],"ltp":0.0,"tv":0.0,"id":13024648},{"batb":[[0,4.6,16.05],[1,1.01,0.51],[2,5.5,0]],"batl":[[0,7.8,13.61],[1,7.4,0],[2,7.8,0]],"ltp":7.8,"tv":370.07,"id":13024647},{"batb":[[0,5,38.28],[2,1.01,0.51]],"batl":[[0,5.8,12.35],[1,5.8,0]],"ltp":0.0,"tv":0.0,"id":16575845},{"batb":[[0,2.14,23.6],[1,1.01,0.51],[2,2.18,0]],"batl":[[0,2.64,15.42],[1,2.64,0]],"ltp":0.0,"tv":0.0,"id":16575844}]}]}
{"op":"mcm","clk":"1002848222","pt":1580646861736,"mc":[{"id":"1.168224575","rc":[{"batb":[[0,4.9,33.78],[1,4.8,35.03],[2,4.6,16.05]],"ltp":7.8,"tv":370.07,"id":13024647},{"batb":[[0,2.16,93.35],[1,2.14,78.35],[2,1.01,0.51]],"ltp":0.0,"tv":0.0,"id":16575844}]}]}
{"op":"mcm","clk":"1002850769","pt":1580646874081,"mc":[{"id":"1.168224575","rc":[{"batb":[[1,1.01,0.51],[2,1.01,0]],"ltp":0.0,"tv":0.0,"id":13024648},{"batb":[[0,2.14,23.6],[1,1.01,0.51],[2,1.01,0]],"ltp":0.0,"tv":0.0,"id":16575844}]}]}
{"op":"mcm","clk":"1002851401","pt":1580646877382,"mc":[{"id":"1.168224575","rc":[{"batb":[[0,4.3,23.7],[1,4.2,69.88],[2,1.01,0.51]],"batl":[[1,4.9,18.41]],"ltp":0.0,"tv":0.0,"id":13024648},{"batl":[[0,5.3,15.34],[1,6.2,11.17],[2,7.8,13.61]],"ltp":7.8,"tv":370.07,"id":13024647},{"batb":[[0,2.52,60.57],[1,2.48,87.53],[2,2.32,18.8]],"batl":[[1,2.92,11.88]],"ltp":0.0,"tv":0.0,"id":16575844}]}]}
{"op":"mcm","clk":"1002851561","pt":1580646878282,"mc":[{"id":"1.168224575","rc":[{"batb":[[0,4.4,11.76],[1,4.3,23.7],[2,4.2,69.57]],"batl":[[0,4.9,18.41],[1,5.1,10.08]],"ltp":0.0,"tv":0.0,"id":13024648},{"batb":[[0,4.9,43.86]],"batl":[[1,5.9,8.4],[2,6.2,11.17]],"ltp":7.8,"tv":370.07,"id":13024647},{"batb":[[2,4.5,11.76]],"batl":[[0,5.3,9.24],[1,5.8,12.35]],"ltp":0.0,"tv":0.0,"id":16575845},{"batb":[[2,2.38,30.25]],"batl":[[0,2.64,40.63]],"ltp":0.0,"tv":0.0,"id":16575844}]}]}
{"op":"mcm","clk":"1002855370","pt":1580646897412,"mc":[{"id":"1.168224575","rc":[{"batb":[[0,4.2,69.57],[1,1.01,0.51],[2,4.2,0]],"batl":[[1,5.1,0]],"ltp":0.0,"tv":0.0,"id":13024648},{"batb":[[0,3.9,24],[1,1.01,0.51],[2,4.6,0]],"batl":[[0,6.2,11.17],[1,5.9,0],[2,6.2,0]],"ltp":7.8,"tv":370.07,"id":13024647},{"batb":[[2,1.01,0.51]],"batl":[[0,5.8,12.35],[1,5.8,0]],"ltp":0.0,"tv":0.0,"id":16575845},{"batb":[[0,2.32,18.8],[1,1.01,0.51],[2,2.38,0]],"batl":[[0,2.92,11.88],[1,2.92,0]],"ltp":0.0,"tv":0.0,"id":16575844}]}]}
{"op":"mcm","clk":"1002855922","pt":1580646900434,"mc":[{"id":"1.168224575","rc":[{"batb":[[0,4.2,77.98],[1,4.1,50.35],[2,1.01,0.51]],"ltp":0.0,"tv":0.0,"id":13024648},{"batb":[[0,4,26.04],[1,3.95,27.89],[2,3.9,24]],"ltp":7.8,"tv":370.07,"id":13024647},{"batb":[[0,2.36,67.09],[1,2.32,105.02],[2,1.01,0.51]],"ltp":0.0,"tv":0.0,"id":16575844}]}]}
{"op":"mcm","clk":"1002856036","pt":1580646901017,"mc":[{"id":"1.168224575","rc":[{"batb":[[0,4.2,69.57],[1,1.01,0.51],[2,1.01,0]],"ltp":0.0,"tv":0.0,"id":13024648},{"batb":[[0,3.9,24],[1,1.01,0.51],[2,3.9,0]],"ltp":7.8,"tv":370.07,"id":13024647},{"batb":[[0,2.32,18.8],[1,1.01,0.51],[2,1.01,0]],"ltp":0.0,"tv":0.0,"id":16575844}]}]}
{"op":"mcm","clk":"1002856620","pt":1580646904048,"mc":[{"id":"1.168224575","rc":[{"batb":[[0,4.3,28.41],[1,4.2,69.57],[2,1.01,0.51]],"ltp":0.0,"tv":0.0,"id":13024648},{"batb":[[0,4.7,27.9],[1,4.6,38.7],[2,3.9,24]],"ltp":7.8,"tv":370.07,"id":13024647},{"batb":[[0,2.58,55.15],[1,2.54,67.34],[2,2.32,18.8]],"ltp":0.0,"tv":0.0,"id":16575844}]}]}
{"op":"mcm","clk":"1002856821","pt":1580646905054,"mc":[{"id":"1.168224575","rc":[{"batb":[[0,4.2,69.57],[1,1.01,0.51],[2,1.01,0]],"ltp":0.0,"tv":0.0,"id":13024648},{"batb":[[0,3.9,24],[1,1.01,0.51],[2,3.9,0]],"ltp":7.8,"tv":370.07,"id":13024647},{"batb":[[0,2.32,18.8],[1,1.01,0.51],[2,2.32,0]],"ltp":0.0,"tv":0.0,"id":16575844}]}]}
{"op":"mcm","clk":"1002857426","pt":1580646907939,"mc":[{"id":"1.168224575","rc":[{"batb":[[0,4.2,77.98],[1,4.1,50.35],[2,1.01,0.51]],"ltp":0.0,"tv":0.0,"id":13024648},{"batb":[[0,4,26.04],[1,3.95,27.89],[2,3.9,24]],"ltp":7.8,"tv":370.07,"id":13024647},{"batb":[[0,2.36,67.09],[1,2.32,105.02],[2,1.01,0.51]],"ltp":0.0,"tv":0.0,"id":16575844}]}]}
{"op":"mcm","clk":"1002857745","pt":1580646909429,"mc":[{"id":"1.168224575","rc":[{"batb":[[0,4.2,69.57],[1,1.01,0.51],[2,1.01,0]],"ltp":0.0,"tv":0.0,"id":13024648},{"batb":[[0,2.32,18.8],[1,1.01,0.51],[2,1.01,0]],"ltp":0.0,"tv":0.0,"id":16575844}]}]}
{"op":"mcm","clk":"1002858371","pt":1580646912464,"mc":[{"id":"1.168224575","rc":[{"batb":[[0,4.4,11.76],[1,4.3,47.19],[2,4.2,69.57]],"batl":[[1,5.1,10.08]],"ltp":0.0,"tv":0.0,"id":13024648},{"batb":[[0,4.1,13.44],[1,4,26.04],[2,3.95,27.89]],"batl":[[0,4.8,10.92],[1,6.2,11.17]],"ltp":7.8,"tv":370.07,"id":13024647},{"batb":[[2,4.5,11.76]],"batl":[[0,5.2,9.24],[1,5.8,12.35]],"ltp":0.0,"tv":0.0,"id":16575845},{"batb":[[0,2.84,49.8],[1,2.8,52.12],[2,2.66,25.21]],"batl":[[1,2.96,21]],"ltp":0.0,"tv":0.0,"id":16575844}]}]}
{"op":"mcm","clk":"1002858536","pt":1580646913364,"mc":[{"id":"1.168224575","rc":[{"batb":[[1,4.3,66.62],[2,4.2,49.66]],"ltp":0.0,"tv":0.0,"id":13024648},{"batb":[[0,4,26.04],[1,3.95,27.89],[2,3.9,24]],"batl":[[0,4.4,22.66],[1,4.7,10.92],[2,4.8,18.49]],"ltp":7.8,"tv":370.07,"id":13024647},{"batl":[[1,5.7,12.83]],"ltp":0.0,"tv":0.0,"id":16575845},{"batb":[[2,2.74,12.12]],"batl":[[1,3.2,23.84]],"ltp":0.0,"tv":0.0,"id":16575844}]}]}
{"op":"mcm","clk":"1002859094","pt":1580646916274,"mc":[{"id":"1.168224575","rc":[{"batb":[[0,4,39.48]],"ltp":7.8,"tv":370.07,"id":13024647},{"batl":[[1,3,21],[2,3.2,23.84]],"ltp":0.0,"tv":0.0,"id":16575844}]}]}
{"op":"mcm","clk":"1002860691","pt":1580646924382,"mc":[{"id":"1.168224575","rc":[{"batb":[[0,5,13.38]],"ltp":0.0,"tv":0.0,"id":16575845}]}]}
{"op":"mcm","clk":"1002860868","pt":1580646925357,"mc":[{"id":"1.168224575","rc":[{"batb":[[0,4,13.44],[1,3.5,15.34],[2,1.01,0.51]],"batl":[[0,4.7,10.92],[1,4.8,18.49],[2,4.8,0]],"ltp":7.8,"tv":370.07,"id":13024647},{"batb":[[0,2.68,24.37],[1,2.58,14.08],[2,1.01,0.51]],"batl":[[0,3,21],[1,3.2,23.84],[2,3.2,0]],"ltp":0.0,"tv":0.0,"id":16575844}]}]}
{"op":"mcm","clk":"1002860920","pt":1580646925575,"mc":[{"id":"1.168224575","rc":[{"batb":[[0,4.3,66.62],[1,4.2,49.66],[2,1.01,0.51]],"batl":[[1,5.1,0]],"ltp":0.0,"tv":0.0,"id":13024648},{"batb":[[0,3.5,15.34],[1,1.01,0.51],[2,1.01,0]],"batl":[[0,4.8,18.49],[1,4.8,0]],"ltp":7.8,"tv":370.07,"id":13024647},{"batb":[[2,1.01,0.51]],"batl":[[0,5.7,12.83],[1,5.7,0]],"ltp":0.0,"tv":0.0,"id":16575845},{"batb":[[0,2.58,14.08],[1,1.01,0.51],[2,1.01,0]],"batl":[[0,3.2,23.84],[1,3.2,0]],"ltp":0.0,"tv":0.0,"id":16575844}]}]}
{"op":"mcm","clk":"1002861289","pt":1580646927483,"mc":[{"id":"1.168224575","rc":[{"batb":[[0,3.5,46.98],[1,3.45,38.67],[2,1.01,0.51]],"ltp":7.8,"tv":370.07,"id":13024647},{"batb":[[0,2.68,45.23],[1,2.64,60.76],[2,2.58,14.08]],"ltp":0.0,"tv":0.0,"id":16575844}]}]}
{"op":"mcm","clk":"1002861353","pt":1580646927802,"mc":[{"id":"1.168224575","rc":[{"batb":[[0,3.5,15.34],[1,1.01,0.51],[2,1.01,0]],"ltp":7.8,"tv":370.07,"id":13024647},{"batb":[[0,2.58,14.08],[1,1.01,0.51],[2,2.58,0]],"ltp":0.0,"tv":0.0,"id":16575844}]}]}
{"op":"mcm","clk":"1002861815","pt":1580646930183,"mc":[{"id":"1.168224575","rc":[{"batb":[[0,3.85,54.73],[1,3.8,30.37],[2,3.5,15.34]],"ltp":7.8,"tv":370.07,"id":13024647},{"batb":[[0,5,33.74]],"ltp":0.0,"tv":0.0,"id":16575845},{"batb":[[0,2.9,36.14],[1,2.86,49.39],[2,2.58,14.08]],"ltp":0.0,"tv":0.0,"id":16575844}]}]}
{"op":"mcm","clk":"1002862259","pt":1580646932488,"mc":[{"id":"1.168224575","rc":[{"batb":[[0,3.5,15.34],[1,1.01,0.51],[2,3.5,0]],"ltp":7.8,"tv":370.07,"id":13024647},{"batb":[[0,5,13.38]],"ltp":0.0,"tv":0.0,"id":16575845},{"batb":[[0,2.58,14.08],[1,1.01,0.51],[2,2.58,0]],"ltp":0.0,"tv":0.0,"id":16575844}]}]}
{"op":"mcm","clk":"1002862840","pt":1580646935380,"mc":[{"id":"1.168224575","rc":[{"batb":[[0,3.5,46.98],[1,3.45,38.67],[2,1.01,0.51]],"ltp":7.8,"tv":370.07,"id":13024647},{"batb":[[1,4.9,52.47],[2,4.8,34.87]],"ltp":0.0,"tv":0.0,"id":16575845},{"batb":[[0,2.68,45.23],[1,2.64,60.76],[2,2.58,14.08]],"ltp":0.0,"tv":0.0,"id":16575844}]}]}
{"op":"mcm","clk":"1002863600","pt":1580646939414,"mc":[{"id":"1.168224575","rc":[{"batb":[[0,3.5,15.34],[1,1.01,0.51],[2,1.01,0]],"ltp":7.8,"tv":370.07,"id":13024647}]}]}
{"op":"mcm","clk":"1002864164","pt":1580646942348,"mc":[{"id":"1.168224575","rc":[{"batb":[[0,4.3,79.23]],"batl":[[1,5,10.08]],"ltp":0.0,"tv":0.0,"id":13024648},{"batb":[[0,4.4,27.05],[1,4.3,57.89],[2,3.5,15.34]],"batl":[[1,5.1,10.08]],"ltp":7.8,"tv":370.07,"id":13024647},{"batl":[[0,5.3,9.24],[1,5.7,12.83]],"ltp":0.0,"tv":0.0,"id":16575845},{"batb":[[2,2.58,40.13]],"batl":[[0,2.88,21.85],[1,3.2,23.84]],"ltp":0.0,"tv":0.0,"id":16575844}]}]}
{"op":"mcm","clk":"1002864385","pt":1580646943464,"mc":[{"id":"1.168224575","rc":[{"batl":[[0,4.9,18.02],[1,5,0]],"ltp":0.0,"tv":0.0,"id":13024648},{"batb":[[0,4.4,38.81],[1,4.3,45.29],[2,4.2,19.43]],"batl":[[2,5.6,13.53]],"ltp":7.8,"tv":370.07,"id":13024647},{"batl":[[1,5.8,12.67]],"ltp":0.0,"tv":0.0,"id":16575845},{"batl":[[0,2.76,13.77],[1,3.1,10.39]],"ltp":0.0,"tv":0.0,"id":16575844}]}]}
{"op":"mcm","clk":"1002864549","pt":1580646944207,"mc":[{"id":"1.168224575","rc":[{"batl":[[1,5.1,10.08]],"ltp":0.0,"tv":0.0,"id":13024648},{"batl":[[1,2.86,21.85],[2,3.1,10.39]],"ltp":0.0,"tv":0.0,"id":16575844}]}]}
{"op":"mcm","clk":"1002867170","pt":1580646957361,"mc":[{"id":"1.168224575","rc":[{"batb":[[0,4.3,19.43]],"batl":[[1,5.1,0]],"ltp":0.0,"tv":0.0,"id":13024648},{"batb":[[0,3.65,14.24],[1,1.01,0.51],[2,4.2,0]],"batl":[[0,5.6,13.53],[1,5.1,0],[2,5.6,0]],"ltp":7.8,"tv":370.07,"id":13024647},{"batl":[[0,5.8,12.67],[1,5.8,0]],"ltp":0.0,"tv":0.0,"id":16575845},{"batb":[[0,2.4,17.07],[1,1.01,0.51],[2,2.58,0]],"batl":[[0,3.1,10.39],[1,2.86,0],[2,3.1,0]],"ltp":0.0,"tv":0.0,"id":16575844}]}]}
{"op":"mcm","clk":"1002867691","pt":1580646960142,"mc":[{"id":"1.168224575","rc":[{"batb":[[0,4.2,69.33],[1,1.01,0.51],[2,1.01,0]],"ltp":0.0,"tv":0.0,"id":13024648}]}]}
{"op":"mcm","clk":"1002868105","pt":1580646962332,"mc":[{"id":"1.168224575","rc":[{"batb":[[0,4.3,48.75],[1,4.2,69.33],[2,1.01,0.51]],"ltp":0.0,"tv":0.0,"id":13024648},{"batb":[[0,4.2,28.23],[1,4.1,50.55],[2,3.65,14.24]],"ltp":7.8,"tv":370.07,"id":13024647},{"batb":[[0,2.74,63.42],[1,2.7,57.15],[2,2.4,17.07]],"ltp":0.0,"tv":0.0,"id":16575844}]}]}
{"op":"mcm","clk":"1002868765","pt":1580646965670,"mc":[{"id":"1.168224575","rc":[{"batb":[[0,4.2,69.33],[1,1.01,0.51],[2,1.01,0]],"ltp":0.0,"tv":0.0,"id":13024648},{"batb":[[0,3.65,14.24],[1,1.01,0.51],[2,3.65,0]],"ltp":7.8,"tv":370.07,"id":13024647},{"batb":[[0,2.4,17.07],[1,1.01,0.51],[2,2.4,0]],"ltp":0.0,"tv":0.0,"id":16575844}]}]}
{"op":"mcm","clk":"1002869347","pt":1580646968606,"mc":[{"id":"1.168224575","rc":[{"batb":[[0,4.2,91.43],[1,4.1,50.17],[2,1.01,0.51]],"ltp":0.0,"tv":0.0,"id":13024648},{"batb":[[1,3.55,38.25],[2,3.5,37.28]],"ltp":7.8,"tv":370.07,"id":13024647},{"batb":[[0,2.48,45.04],[1,2.44,75.06],[2,2.4,17.07]],"ltp":0.0,"tv":0.0,"id":16575844}]}]}
{"op":"mcm","clk":"1002870050","pt":1580646972387,"mc":[{"id":"1.168224575","rc":[{"batb":[[0,4.2,19.67],[1,1.01,0.51],[2,1.01,0]],"ltp":0.0,"tv":0.0,"id":13024648},{"batb":[[0,2.4,17.07],[1,1.01,0.51],[2,2.4,0]],"ltp":0.0,"tv":0.0,"id":16575844}]}]}
{"op":"mcm","clk":"1002870631","pt":1580646975490,"mc":[{"id":"1.168224575","rc":[{"batb":[[0,4.4,27.97],[1,4.3,45.53],[2,4.2,19.67]],"ltp":0.0,"tv":0.0,"id":13024648},{"trd":[[3.1,20.78]],"batb":[[0,3.05,52.27],[1,2.4,17.07],[2,1.01,0.51]],"ltp":3.1,"tv":20.77,"id":16575844}],"tv":390.85}]}
{"op":"mcm","clk":"1002870845","pt":1580646976414,"mc":[{"id":"1.168224575","rc":[{"batb":[[1,4.3,64.96],[2,4.2,12.6]],"batl":[[0,4.9,10.08],[1,5,17.62]],"ltp":0.0,"tv":0.0,"id":13024648},{"batl":[[0,3.9,14.28],[1,4.1,13.85],[2,4.7,19.59]],"ltp":7.8,"tv":370.07,"id":13024647},{"batl":[[0,5.4,9.24],[1,5.8,12.67]],"ltp":0.0,"tv":0.0,"id":16575845},{"batb":[[0,3.1,10.08],[1,3.05,52.27],[2,2.88,10.54]],"batl":[[0,3.4,21.01],[1,3.55,15.96]],"ltp":3.1,"tv":20.77,"id":16575844}]}]}
{"op":"mcm","clk":"1002870988","pt":1580646977090,"mc":[{"id":"1.168224575","rc":[{"batl":[[0,5.8,12.67],[1,5.8,0]],"ltp":0.0,"tv":0.0,"id":16575845},{"batb":[[0,3.05,52.27],[1,2.88,10.54],[2,2.62,13.53]],"ltp":3.1,"tv":20.77,"id":16575844}]}]}
{"op":"mcm","clk":"1002871248","pt":1580646978408,"mc":[{"id":"1.168224575","rc":[{"batl":[[0,5.3,9.24],[1,5.8,12.67]],"ltp":0.0,"tv":0.0,"id":16575845},{"batb":[[0,3.15,19.32],[1,3.05,84.22],[2,3,54.01]],"ltp":3.1,"tv":20.77,"id":16575844}]}]}
{"op":"mcm","clk":"1002872407","pt":1580646984287,"mc":[{"id":"1.168224575","rc":[{"batb":[[0,3.6,14.63]],"batl":[[1,3.95,14.16]],"ltp":7.8,"tv":370.07,"id":13024647},{"batl":[[1,5.7,12.9]],"ltp":0.0,"tv":0.0,"id":16575845},{"trd":[[3.15,38.65]],"batb":[[0,3.05,84.22],[1,3,54.01],[2,2.92,10.39]],"batl":[[0,3.15,5.54],[1,3.45,20.38],[2,3.55,15.96]],"ltp":3.15,"tv":59.42,"id":16575844}],"tv":429.5}]}
{"op":"mcm","clk":"1002872992","pt":1580646987215,"mc":[{"id":"1.168224575","rc":[{"trd":[[3.15,45.37]],"batb":[[0,3.1,19.32],[1,3.05,84.22],[2,3,54.01]],"batl":[[0,3.15,2.18]],"ltp":3.15,"tv":66.14,"id":16575844}],"tv":436.22}]}
{"op":"mcm","clk":"1002873914","pt":1580646991941,"mc":[{"id":"1.168224575","rc":[{"batb":[[1,4.3,45.53],[2,4.2,32.51]],"batl":[[0,4.9,28.1],[1,5,0]],"ltp":0.0,"tv":0.0,"id":13024648},{"batb":[[0,3.55,53.12],[1,3.5,37.28],[2,3.4,16.8]],"batl":[[2,4.6,20.54]],"ltp":7.8,"tv":370.07,"id":13024647},{"batb":[[0,4.9,66.55],[1,4.8,34.87],[2,4.6,10.92]],"ltp":0.0,"tv":0.0,"id":16575845},{"batl":[[0,3.25,23.92],[1,3.5,19.59]],"ltp":3.15,"tv":66.14,"id":16575844}]}]}
{"op":"mcm","clk":"1002882573","pt":1580647035404,"mc":[{"id":"1.168224575","rc":[{"batl":[[0,3.9,29],[1,4.6,20.54],[2,4.6,0]],"ltp":7.8,"tv":370.07,"id":13024647},{"batb":[[0,4.9,66.32]],"ltp":0.0,"tv":0.0,"id":16575845},{"batb":[[2,3,78.4]],"batl":[[0,3.25,23.45],[1,3.55,35.08],[2,3.55,0]],"ltp":3.15,"tv":66.14,"id":16575844}]}]}
{"op":"mcm","clk":"1002883836","pt":1580647041334,"mc":[{"id":"1.168224575","rc":[{"batb":[[0,4.9,47.63],[1,4.6,10.92],[2,1.01,0.51]],"ltp":0.0,"tv":0.0,"id":16575845},{"batb":[[1,3.05,52.28],[2,3,24.39]],"ltp":3.15,"tv":66.14,"id":16575844}]}]}
{"op":"mcm","clk":"1002884495","pt":1580647044325,"mc":[{"id":"1.168224575","rc":[{"batb":[[0,5,21.83],[1,4.9,47.63],[2,4.6,10.92]],"ltp":0.0,"tv":0.0,"id":16575845},{"batb":[[0,3.1,56.84]],"ltp":3.15,"tv":66.14,"id":16575844}]}]}
{"op":"mcm","clk":"1002888068","pt":1580647061448,"mc":[{"id":"1.168224575","rc":[{"batb":[[0,4.3,45.53],[1,4.2,19.91],[2,1.01,0.51]],"batl":[[0,4.9,18.02]],"ltp":0.0,"tv":0.0,"id":13024648},{"batb":[[0,3.55,14.87],[1,3.2,19.43],[2,1.01,0.51]],"batl":[[0,3.9,14.71]],"ltp":7.8,"tv":370.07,"id":13024647},{"batb":[[2,1.01,0.51]],"batl":[[0,5.7,12.9],[1,5.7,0]],"ltp":0.0,"tv":0.0,"id":16575845},{"batb":[[0,3,24.39],[1,2.72,12.43],[2,1.01,0.51]],"batl":[[1,3.55,19.12]],"ltp":3.15,"tv":66.14,"id":16575844}]}]}
{"op":"mcm","clk":"1002888086","pt":1580647061553,"mc":[{"id":"1.168224575","rc":[{"batb":[[0,3.2,19.43],[1,1.01,0.51],[2,1.01,0]],"batl":[[0,4.6,20.54],[1,4.6,0]],"ltp":7.8,"tv":370.07,"id":13024647},{"batb":[[0,2.72,12.43],[1,1.01,0.51],[2,1.01,0]],"batl":[[0,3.55,19.12],[1,3.55,0]],"ltp":3.15,"tv":66.14,"id":16575844}]}]}
{"op":"mcm","clk":"1002888688","pt":1580647064381,"mc":[{"id":"1.168224575","rc":[{"batb":[[0,4.3,54.43],[1,4.2,67.42]],"ltp":0.0,"tv":0.0,"id":13024648}]}]}
{"op":"mcm","clk":"1002889129","pt":1580647066353,"mc":[{"id":"1.168224575","rc":[{"batb":[[0,4.3,66.56]],"ltp":0.0,"tv":0.0,"id":13024648},{"batb":[[0,3.65,30.64],[1,3.6,34.75],[2,3.2,19.43]],"ltp":7.8,"tv":370.07,"id":13024647},{"batb":[[0,3,75.72],[1,2.96,44.97],[2,2.72,12.43]],"ltp":3.15,"tv":66.14,"id":16575844}]}]}
{"op":"mcm","clk":"1002890174","pt":1580647071369,"mc":[{"id":"1.168224575","rc":[{"batb":[[0,4.3,54.43]],"ltp":0.0,"tv":0.0,"id":13024648},{"batb":[[0,3.2,19.43],[1,1.01,0.51],[2,3.2,0]],"ltp":7.8,"tv":370.07,"id":13024647},{"batb":[[0,2.72,12.43],[1,1.01,0.51],[2,2.72,0]],"ltp":3.15,"tv":66.14,"id":16575844}]}]}
{"op":"mcm","clk":"1002891037","pt":1580647075475,"mc":[{"id":"1.168224575","rc":[{"batb":[[0,3.25,63.65],[1,3.2,65.45],[2,1.01,0.51]],"ltp":7.8,"tv":370.07,"id":13024647},{"batb":[[0,2.78,62],[1,2.74,54.94],[2,2.72,12.43]],"ltp":3.15,"tv":66.14,"id":16575844}]}]}
{"op":"mcm","clk":"1002891854","pt":1580647079461,"mc":[{"id":"1.168224575","rc":[{"batb":[[0,4.3,45.53],[1,4.2,19.91]],"ltp":0.0,"tv":0.0,"id":13024648},{"batb":[[0,2.72,12.43],[1,1.01,0.51],[2,2.72,0]],"ltp":3.15,"tv":66.14,"id":16575844}]}]}
{"op":"mcm","clk":"1002892499","pt":1580647082478,"mc":[{"id":"1.168224575","rc":[{"batb":[[0,4.4,32.94],[1,4.3,45.53],[2,4.2,19.91]],"ltp":0.0,"tv":0.0,"id":13024648},{"batb":[[0,3.3,58.97],[1,3.25,44.48],[2,2.72,12.43]],"ltp":3.15,"tv":66.14,"id":16575844}]}]}
{"op":"mcm","clk":"1002892678","pt":1580647083408,"mc":[{"id":"1.168224575","rc":[{"batb":[[2,2.98,23.37]],"batl":[[0,3.5,18.73],[1,3.95,14.24],[2,4.6,20.54]],"ltp":7.8,"tv":370.07,"id":13024647},{"batb":[[0,5,35.52]],"ltp":0.0,"tv":0.0,"id":16575845},{"batb":[[1,3.25,64.31],[2,2.96,25.1]],"batl":[[1,3.85,15.74]],"ltp":3.15,"tv":66.14,"id":16575844}]}]}
{"op":"mcm","clk":"1002892879","pt":1580647084374,"mc":[{"id":"1.168224575","rc":[{"batb":[[1,4.3,58.13]],"batl":[[0,4.9,28.1]],"ltp":0.0,"tv":0.0,"id":13024648},{"batb":[[1,3.2,83.94]],"batl":[[1,3.65,15.12],[2,3.95,14.24]],"ltp":7.8,"tv":370.07,"id":13024647},{"batb":[[1,4.9,33.78],[2,4.6,10.92]],"batl":[[0,5.4,9.24],[1,5.7,12.9]],"ltp":0.0,"tv":0.0,"id":16575845},{"batb":[[1,3.25,82.79]],"batl":[[1,3.7,15.12],[2,3.85,15.74]],"ltp":3.15,"tv":66.14,"id":16575844}]}]}
{"op":"mcm","clk":"1002895784","pt":1580647098443,"mc":[{"id":"1.168224575","rc":[{"batb":[[0,4.3,58.13],[1,4.2,19.91],[2,1.01,0.51]],"ltp":0.0,"tv":0.0,"id":13024648},{"batb":[[0,3.2,37.92],[1,2.98,23.37],[2,1.01,0.51]],"ltp":7.8,"tv":370.07,"id":13024647},{"batb":[[0,5,13.69]],"ltp":0.0,"tv":0.0,"id":16575845},{"batb":[[0,3.25,38.31],[1,2.96,25.1],[2,1.01,0.51]],"ltp":3.15,"tv":66.14,"id":16575844}]}]}
{"op":"mcm","clk":"1002895990","pt":1580647099424,"mc":[{"id":"1.168224575","rc":[{"batb":[[0,4.3,45.53]],"batl":[[0,4.9,18.02]],"ltp":0.0,"tv":0.0,"id":13024648},{"batb":[[0,2.98,23.37],[1,1.01,0.51],[2,1.01,0]],"batl":[[0,3.95,14.24],[1,3.65,0],[2,3.95,0]],"ltp":7.8,"tv":370.07,"id":13024647},{"batb":[[2,1.01,0.51]],"batl":[[0,5.7,12.9],[1,5.7,0]],"ltp":0.0,"tv":0.0,"id":16575845},{"batb":[[0,2.96,25.1],[1,1.01,0.51],[2,1.01,0]],"batl":[[0,3.85,15.74],[1,3.7,0],[2,3.85,0]],"ltp":3.15,"tv":66.14,"id":16575844}]}]}
{"op":"mcm","clk":"1002896413","pt":1580647101357,"mc":[{"id":"1.168224575","rc":[{"batb":[[0,4.3,67.42],[1,4.2,67.21]],"ltp":0.0,"tv":0.0,"id":13024648},{"batb":[[0,3.05,77.53],[1,3,53.99],[2,2.98,23.37]],"ltp":7.8,"tv":370.07,"id":13024647},{"batb":[[1,4.9,53.8],[2,4.8,34.9]],"ltp":0.0,"tv":0.0,"id":16575845},{"batb":[[0,3,75.24],[1,2.96,70.09],[2,1.01,0.51]],"ltp":3.15,"tv":66.14,"id":16575844}]}]}
{"op":"mcm","clk":"1002896591","pt":1580647102223,"mc":[{"id":"1.168224575","rc":[{"batb":[[0,4.3,45.53],[1,4.2,19.91]],"batl":[[0,5,18.02]],"ltp":0.0,"tv":0.0,"id":13024648},{"batl":[[0,3.95,14.08]],"ltp":7.8,"tv":370.07,"id":13024647},{"batb":[[0,4.9,47.45],[1,1.01,0.51],[2,4.8,0]],"ltp":0.0,"tv":0.0,"id":16575845},{"batb":[[0,2.94,25.34],[1,1.01,0.51],[2,1.01,0]],"ltp":3.15,"tv":66.14,"id":16575844}]}]}
{"op":"mcm","clk":"1002897208","pt":1580647105157,"mc":[{"id":"1.168224575","rc":[{"batb":[[0,4.4,38.76],[1,4.3,45.53],[2,4.2,19.91]],"ltp":0.0,"tv":0.0,"id":13024648},{"batb":[[0,5,25.51],[1,4.9,47.45],[2,1.01,0.51]],"ltp":0.0,"tv":0.0,"id":16575845},{"batb":[[0,3.5,63.59],[1,3.45,38.4],[2,2.94,25.34]],"ltp":3.15,"tv":66.14,"id":16575844}]}]}
{"op":"mcm","clk":"1002897511","pt":1580647106454,"mc":[{"id":"1.168224575","rc":[{"batb":[[1,4.3,77.57],[2,1.01,0.51]],"batl":[[0,4.9,10.08],[1,5,17.86]],"ltp":0.0,"tv":0.0,"id":13024648},{"batb":[[0,3.05,97.69]],"batl":[[0,3.25,22.74],[1,3.5,16.8],[2,3.55,18.1]],"ltp":7.8,"tv":370.07,"id":13024647},{"batb":[[2,4.6,10.92]],"batl":[[0,5.4,9.24],[1,5.7,12.9]],"ltp":0.0,"tv":0.0,"id":16575845},{"batb":[[0,3.5,80.03],[2,3.4,16.8]],"batl":[[1,3.9,14.28],[2,4.1,13.69]],"ltp":3.15,"tv":66.14,"id":16575844}]}]}
{"op":"mcm","clk":"1002899933","pt":1580647118223,"mc":[{"id":"1.168224575","rc":[{"batb":[[0,3.05,20.16],[1,2.84,10.7],[2,1.01,0.51]],"batl":[[0,3.5,16.8],[1,3.55,18.1],[2,3.55,0]],"ltp":7.8,"tv":370.07,"id":13024647},{"batb":[[0,4.9,47.45],[1,4.6,10.92],[2,1.01,0.51]],"ltp":0.0,"tv":0.0,"id":16575845},{"batb":[[0,3.4,16.8],[1,3.2,20.06],[2,1.01,0.51]],"batl":[[0,3.9,14.28],[1,4.1,13.69],[2,4.1,0]],"ltp":3.15,"tv":66.14,"id":16575844}]}]}
{"op":"mcm","clk":"1002900171","pt":1580647119411,"mc":[{"id":"1.168224575","rc":[{"batb":[[1,4.3,64.96]],"batl":[[0,5,17.86],[1,5,0]],"ltp":0.0,"tv":0.0,"id":13024648},{"batb":[[0,2.84,10.7],[1,1.01,0.51],[2,1.01,0]],"batl":[[0,3.55,18.1],[1,3.55,0]],"ltp":7.8,"tv":370.07,"id":13024647},{"batb":[[1,1.01,0.51],[2,1.01,0]],"batl":[[0,5.7,12.9],[1,5.7,0]],"ltp":0.0,"tv":0.0,"id":16575845},{"batb":[[0,3.2,20.06],[1,1.01,0.51],[2,1.01,0]],"batl":[[0,4.1,13.69],[1,4.1,0]],"ltp":3.15,"tv":66.14,"id":16575844}]}]}
{"op":"mcm","clk":"1002900571","pt":1580647121402,"mc":[{"id":"1.168224575","rc":[{"batb":[[0,2.96,45.56],[1,2.92,46.67],[2,2.84,10.7]],"ltp":7.8,"tv":370.07,"id":13024647},{"batb":[[0,4.9,66.64],[1,4.8,34.93],[2,1.01,0.51]],"ltp":0.0,"tv":0.0,"id":16575845},{"batb":[[0,3.3,31.97],[1,3.25,44.74],[2,3.2,20.06]],"ltp":3.15,"tv":66.14,"id":16575844}]}]}
{"op":"mcm","clk":"1002900766","pt":1580647122459,"mc":[{"id":"1.168224575","rc":[{"batb":[[0,4.9,47.45],[1,1.01,0.51],[2,1.01,0]],"ltp":0.0,"tv":0.0,"id":16575845},{"batb":[[0,3.2,20.06],[1,1.01,0.51],[2,3.2,0]],"ltp":3.15,"tv":66.14,"id":16575844}]}]}
{"op":"mcm","clk":"1002901396","pt":1580647125321,"mc":[{"id":"1.168224575","rc":[{"batl":[[0,3.05,10.46],[1,3.25,22.58],[2,3.55,18.1]],"ltp":7.8,"tv":370.07,"id":13024647},{"batb":[[0,5,29.82],[1,4.9,47.45],[2,1.01,0.51]],"batl":[[1,5.8,12.9]],"ltp":0.0,"tv":0.0,"id":16575845},{"batb":[[0,3.75,14.08],[1,3.7,35.47],[2,3.65,33.75]],"batl":[[1,4.4,24]],"ltp":3.15,"tv":66.14,"id":16575844}]}]}
{"op":"mcm","clk":"1002901620","pt":1580647126435,"mc":[{"id":"1.168224575","rc":[{"batb":[[1,4.3,77.17]],"batl":[[0,5,27.94]],"ltp":0.0,"tv":0.0,"id":13024648},{"batb":[[1,2.94,21],[2,2.92,46.67]],"batl":[[2,3.35,17.64]],"ltp":7.8,"tv":370.07,"id":13024647},{"batb":[[2,4.7,10.92]],"batl":[[0,5.5,9.24]],"ltp":0.0,"tv":0.0,"id":16575845},{"batl":[[0,4.1,27.13]],"ltp":3.15,"tv":66.14,"id":16575844}]}]}
{"op":"mcm","clk":"1002903594","pt":1580647136485,"mc":[{"id":"1.168224575","rc":[{"batb":[[0,2.94,21],[1,2.84,10.7],[2,2.74,11.72]],"ltp":7.8,"tv":370.07,"id":13024647},{"batb":[[0,4.9,47.45],[1,4.7,10.92],[2,1.01,0.51]],"ltp":0.0,"tv":0.0,"id":16575845},{"batb":[[1,3.5,33.01],[2,1.01,0.51]],"ltp":3.15,"tv":66.14,"id":16575844}]}]}
{"op":"mcm","clk":"1002903797","pt":1580647137464,"mc":[{"id":"1.168224575","rc":[{"batb":[[1,4.3,64.57]],"batl":[[0,5,17.86]],"ltp":0.0,"tv":0.0,"id":13024648},{"batb":[[0,2.74,11.72],[1,1.01,0.51],[2,2.74,0]],"batl":[[0,3.25,22.58],[1,3.25,0],[2,3.35,0]],"ltp":7.8,"tv":370.07,"id":13024647},{"batb":[[1,1.01,0.51],[2,1.01,0]],"batl":[[0,5.8,12.9],[1,5.8,0]],"ltp":0.0,"tv":0.0,"id":16575845},{"batb":[[0,3.5,16.21],[1,1.01,0.51],[2,1.01,0]],"batl":[[0,4.4,24],[1,4.4,0]],"ltp":3.15,"tv":66.14,"id":16575844}]}]}
{"op":"mcm","clk":"1002904187","pt":1580647139377,"mc":[{"id":"1.168224575","rc":[{"batb":[[0,2.88,58.37],[1,2.84,49.96],[2,2.74,11.72]],"ltp":7.8,"tv":370.07,"id":13024647},{"batb":[[0,4.9,67.74],[1,4.8,34.93],[2,1.01,0.51]],"ltp":0.0,"tv":0.0,"id":16575845},{"batb":[[0,3.5,78.52],[1,3.45,38.41],[2,1.01,0.51]],"ltp":3.15,"tv":66.14,"id":16575844}]}]}
{"op":"mcm","clk":"1002904360","pt":1580647140308,"mc":[{"id":"1.168224575","rc":[{"batb":[[1,4.3,64.26]],"batl":[[0,5,17.47]],"ltp":0.0,"tv":0.0,"id":13024648},{"batb":[[2,2.76,11.57]],"batl":[[0,3.3,22.19]],"ltp":7.8,"tv":370.07,"id":13024647},{"batb":[[0,4.9,47.34],[1,1.01,0.51],[2,1.01,0]],"batl":[[0,5.7,13.22]],"ltp":0.0,"tv":0.0,"id":16575845},{"batb":[[0,3.5,16.21],[1,1.01,0.51],[2,1.01,0]],"batl":[[0,4.3,24.55]],"ltp":3.15,"tv":66.14,"id":16575844}]}]}
{"op":"mcm","clk":"1002905025","pt":1580647143465,"mc":[{"id":"1.168224575","rc":[{"batb":[[0,5,36.08],[1,4.9,47.34],[2,1.01,0.51]],"ltp":0.0,"tv":0.0,"id":16575845},{"batb":[[0,3.8,40.01],[1,3.75,31.6],[2,3.5,16.21]],"ltp":3.15,"tv":66.14,"id":16575844}]}]}
{"op":"mcm","clk":"1002905198","pt":1580647144393,"mc":[{"id":"1.168224575","rc":[{"batb":[[2,4.2,12.6]],"batl":[[0,4.9,10.08],[1,5,17.47],[2,5.1,16.84]],"ltp":0.0,"tv":0.0,"id":13024648},{"batb":[[1,2.84,72.65]],"batl":[[0,2.94,11.33],[1,3.2,18.48],[2,3.3,22.19]],"ltp":7.8,"tv":370.07,"id":13024647},{"batb":[[2,4.7,10.92]],"batl":[[0,5.6,8.4],[1,5.7,13.22]],"ltp":0.0,"tv":0.0,"id":16575845},{"batb":[[0,3.85,12.98],[1,3.8,40.01],[2,3.75,31.6]],"batl":[[0,4.3,37.15],[1,5,17.47]],"ltp":3.15,"tv":66.14,"id":16575844}]}]}
{"op":"mcm","clk":"1002909950","pt":1580647167752,"mc":[{"id":"1.168224575","rc":[{"batb":[[0,4.3,64.26],[1,4.2,12.6],[2,1.01,0.51]],"batl":[[1,5.1,16.84],[2,5.1,0]],"ltp":0.0,"tv":0.0,"id":13024648},{"batb":[[0,2.84,22.69],[1,2.48,15.26],[2,1.01,0.51]],"batl":[[0,3.2,18.48],[1,3.3,22.19],[2,3.3,0]],"ltp":7.8,"tv":370.07,"id":13024647},{"batb":[[0,5,28.26]],"ltp":0.0,"tv":0.0,"id":16575845},{"batb":[[0,3.65,15.12],[1,3.5,16.21],[2,1.01,0.51]],"batl":[[0,4.3,12.6]],"ltp":3.15,"tv":66.14,"id":16575844}]}]}
{"op":"mcm","clk":"1002910309","pt":1580647169454,"mc":[{"id":"1.168224575","rc":[{"batb":[[1,1.01,0.51],[2,1.01,0]],"batl":[[0,5.1,16.84],[1,5.1,0]],"ltp":0.0,"tv":0.0,"id":13024648},{"batb":[[0,2.48,15.26],[1,1.01,0.51],[2,1.01,0]],"batl":[[0,3.3,22.19],[1,3.3,0]],"ltp":7.8,"tv":370.07,"id":13024647},{"batb":[[2,1.01,0.51]],"batl":[[0,5.7,13.22],[1,5.7,0]],"ltp":0.0,"tv":0.0,"id":16575845},{"batb":[[0,3.5,16.21],[1,1.01,0.51],[2,1.01,0]],"batl":[[0,5,17.47],[1,5,0]],"ltp":3.15,"tv":66.14,"id":16575844}]}]}
{"op":"mcm","clk":"1002910499","pt":1580647170432,"mc":[{"id":"1.168224575","rc":[{"batb":[[0,4.3,84.42],[1,4.2,47.42],[2,1.01,0.51]],"ltp":0.0,"tv":0.0,"id":13024648},{"batb":[[0,2.58,61.14],[1,2.54,66.96],[2,2.48,15.26]],"ltp":7.8,"tv":370.07,"id":13024647},{"batb":[[0,3.5,62.05],[1,3.45,38.61],[2,1.01,0.51]],"ltp":3.15,"tv":66.14,"id":16575844}]}]}
{"op":"mcm","clk":"1002910716","pt":1580647171458,"mc":[{"id":"1.168224575","rc":[{"batb":[[0,4.3,64.26],[1,1.01,0.51],[2,1.01,0]],"batl":[[0,5.1,16.6]],"ltp":0.0,"tv":0.0,"id":13024648},{"batb":[[0,2.5,15.03],[1,1.01,0.51],[2,2.48,0]],"batl":[[0,3.3,21.79]],"ltp":7.8,"tv":370.07,"id":13024647},{"batb":[[0,3.5,16.21],[1,1.01,0.51],[2,1.01,0]],"ltp":3.15,"tv":66.14,"id":16575844}]}]}
{"op":"mcm","clk":"1002911028","pt":1580647172948,"mc":[{"id":"1.168224575","rc":[{"batb":[[0,4.4,45.83],[1,4.3,64.26],[2,1.01,0.51]],"ltp":0.0,"tv":0.0,"id":13024648},{"batb":[[0,2.82,49.63],[1,2.78,52.89],[2,2.5,15.03]],"ltp":7.8,"tv":370.07,"id":13024647},{"batb":[[0,5,38.71]],"ltp":0.0,"tv":0.0,"id":16575845},{"batb":[[0,3.9,44.41],[1,3.85,29.66],[2,3.5,16.21]],"ltp":3.15,"tv":66.14,"id":16575844}]}]}
{"op":"mcm","clk":"1002911966","pt":1580647177222,"mc":[{"id":"1.168224575","rc":[{"batb":[[0,4.3,64.26],[1,1.01,0.51],[2,1.01,0]],"ltp":0.0,"tv":0.0,"id":13024648},{"batb":[[0,2.5,15.03],[1,1.01,0.51],[2,2.5,0]],"ltp":7.8,"tv":370.07,"id":13024647},{"batb":[[0,5,28.26]],"ltp":0.0,"tv":0.0,"id":16575845},{"batb":[[0,3.5,16.21],[1,1.01,0.51],[2,3.5,0]],"ltp":3.15,"tv":66.14,"id":16575844}]}]}
{"op":"mcm","clk":"1002912565","pt":1580647180146,"mc":[{"id":"1.168224575","rc":[{"batb":[[0,4.3,84.42],[1,4.2,47.42],[2,1.01,0.51]],"ltp":0.0,"tv":0.0,"id":13024648},{"batb":[[0,2.58,61.14],[1,2.54,66.96],[2,2.5,15.03]],"ltp":7.8,"tv":370.07,"id":13024647},{"batb":[[0,3.5,62.05],[1,3.45,38.61],[2,1.01,0.51]],"ltp":3.15,"tv":66.14,"id":16575844}]}]}
{"op":"mcm","clk":"1002913175","pt":1580647183039,"mc":[{"id":"1.168224575","rc":[{"batb":[[0,2.5,15.03],[1,1.01,0.51],[2,2.5,0]],"ltp":7.8,"tv":370.07,"id":13024647}]}]}
{"op":"mcm","clk":"1002913947","pt":1580647186474,"mc":[{"id":"1.168224575","rc":[{"batb":[[1,4.2,60.02]],"batl":[[0,4.9,10.08],[1,5.1,16.6]],"ltp":0.0,"tv":0.0,"id":13024648},{"batb":[[0,3.1,62.18],[1,3.05,72.1],[2,2.5,15.03]],"batl":[[1,3.45,16.8]],"ltp":7.8,"tv":370.07,"id":13024647},{"batb":[[2,4.7,10.92]],"batl":[[0,5.6,8.4],[1,5.7,13.22]],"ltp":0.0,"tv":0.0,"id":16575845},{"batb":[[1,3.45,55.41]],"batl":[[0,4,13.44],[1,5,17.47]],"ltp":3.15,"tv":66.14,"id":16575844}]}]}
{"op":"mcm","clk":"1002914034","pt":1580647186846,"mc":[{"id":"1.168224575","rc":[{"batl":[[1,5,17.55]],"ltp":0.0,"tv":0.0,"id":13024648},{"batb":[[2,3,22.66]],"batl":[[2,3.6,17.86]],"ltp":7.8,"tv":370.07,"id":13024647},{"batl":[[0,5.6,21.94],[1,5.7,0]],"ltp":0.0,"tv":0.0,"id":16575845},{"batb":[[2,3.2,20.06]],"batl":[[0,3.85,15.97],[1,4,13.44],[2,4.4,23.84]],"ltp":3.15,"tv":66.14,"id":16575844}]}]}
{"op":"mcm","clk":"1002917916","pt":1580647205233,"mc":[{"id":"1.168224575","rc":[{"batb":[[0,4.3,71.12]],"ltp":0.0,"tv":0.0,"id":13024648},{"batb":[[0,3.05,20.16],[1,2.74,11.72],[2,1.01,0.51]],"batl":[[0,3.45,16.8],[1,3.6,17.86],[2,3.6,0]],"ltp":7.8,"tv":370.07,"id":13024647},{"batb":[[0,5,21.07]],"ltp":0.0,"tv":0.0,"id":16575845},{"batb":[[0,3.45,16.8],[1,3.2,20.06],[2,1.01,0.51]],"batl":[[0,4,13.44],[1,4.4,23.84],[2,4.4,0]],"ltp":3.15,"tv":66.14,"id":16575844}]}]}
{"op":"mcm","clk":"1002917978","pt":1580647205560,"mc":[{"id":"1.168224575","rc":[{"batb":[[1,4.2,47.42]],"batl":[[0,5,17.55],[1,5,0]],"ltp":0.0,"tv":0.0,"id":13024648},{"batb":[[0,2.74,11.72],[1,1.01,0.51],[2,1.01,0]],"batl":[[0,3.6,17.86],[1,3.6,0]],"ltp":7.8,"tv":370.07,"id":13024647},{"batb":[[2,1.01,0.51]],"batl":[[0,5.6,13.53]],"ltp":0.0,"tv":0.0,"id":16575845},{"batb":[[0,3.2,20.06],[1,1.01,0.51],[2,1.01,0]],"batl":[[0,4.4,23.84],[1,4.4,0]],"ltp":3.15,"tv":66.14,"id":16575844}]}]}
{"op":"mcm","clk":"1002918489","pt":1580647208101,"mc":[{"id":"1.168224575","rc":[{"batb":[[0,2.82,51.62],[1,2.78,52.88],[2,2.74,11.72]],"ltp":7.8,"tv":370.07,"id":13024647},{"batb":[[0,3.3,37.24],[1,3.25,44.78],[2,3.2,20.06]],"ltp":3.15,"tv":66.14,"id":16575844}]}]}
{"op":"mcm","clk":"1002919575","pt":1580647213185,"mc":[{"id":"1.168224575","rc":[{"batb":[[0,4.3,64.26],[1,1.01,0.51],[2,1.01,0]],"ltp":0.0,"tv":0.0,"id":13024648},{"batb":[[0,3.2,20.06],[1,1.01,0.51],[2,3.2,0]],"ltp":3.15,"tv":66.14,"id":16575844}]}]}
{"op":"mcm","clk":"1002920235","pt":1580647216400,"mc":[{"id":"1.168224575","rc":[{"batb":[[0,4.4,59.69],[1,4.3,64.26],[2,4.2,12.6]],"batl":[[0,4.9,10.08],[1,5,17.55],[2,5.2,16.44]],"ltp":0.0,"tv":0.0,"id":13024648},{"batb":[[0,2.82,74.31]],"batl":[[0,2.92,11.57],[1,3.15,19.32],[2,3.3,22.11]],"ltp":7.8,"tv":370.07,"id":13024647},{"batb":[[0,5,39.76],[2,4.8,10.92]],"batl":[[0,5.6,21.94],[1,5.7,13.38]],"ltp":0.0,"tv":0.0,"id":16575845},{"batb":[[0,3.9,71.46],[1,3.85,29.64],[2,3.75,15.12]],"batl":[[0,4.4,35.6],[1,5.3,15.74]],"ltp":3.15,"tv":66.14,"id":16575844}]}]}
{"op":"mcm","clk":"1002920396","pt":1580647217201,"mc":[{"id":"1.168224575","rc":[{"batl":[[0,5.6,8.4]],"ltp":0.0,"tv":0.0,"id":16575845}]}]}
{"op":"mcm","clk":"1002922332","pt":1580647226073,"mc":[{"id":"1.168224575","rc":[{"batb":[[0,4.3,64.26],[1,4.2,12.6],[2,1.01,0.51]],"batl":[[1,5.2,16.44],[2,5.2,0]],"ltp":0.0,"tv":0.0,"id":13024648},{"batb":[[0,2.82,22.69],[1,2.42,16.44],[2,1.01,0.51]],"batl":[[0,3.15,19.32],[1,3.3,22.11],[2,3.3,0]],"ltp":7.8,"tv":370.07,"id":13024647},{"batb":[[0,5,31.67]],"ltp":0.0,"tv":0.0,"id":16575845},{"batb":[[0,3.75,15.12],[1,3.5,16.37],[2,1.01,0.51]],"batl":[[0,4.4,11.76]],"ltp":3.15,"tv":66.14,"id":16575844}]}]}
{"op":"mcm","clk":"1002922636","pt":1580647227645,"mc":[{"id":"1.168224575","rc":[{"batb":[[1,1.01,0.51],[2,1.01,0]],"batl":[[0,5.2,16.44],[1,5.2,0]],"ltp":0.0,"tv":0.0,"id":13024648},{"batb":[[0,2.42,16.44],[1,1.01,0.51],[2,1.01,0]],"batl":[[0,3.3,22.11],[1,3.3,0]],"ltp":7.8,"tv":370.07,"id":13024647},{"batb":[[2,1.01,0.51]],"batl":[[0,5.7,13.38],[1,5.7,0]],"ltp":0.0,"tv":0.0,"id":16575845},{"batb":[[0,3.5,16.37],[1,1.01,0.51],[2,1.01,0]],"batl":[[0,5.3,15.74],[1,5.3,0]],"ltp":3.15,"tv":66.14,"id":16575844}]}]}
{"op":"mcm","clk":"1002923037","pt":1580647229472,"mc":[{"id":"1.168224575","rc":[{"batb":[[0,4.3,18.73]],"ltp":0.0,"tv":0.0,"id":13024648}]}]}
{"op":"mcm","clk":"1002923669","pt":1580647232472,"mc":[{"id":"1.168224575","rc":[{"batb":[[0,4.3,31.33]],"batl":[[0,5,10.08],[1,5.2,16.44]],"ltp":0.0,"tv":0.0,"id":13024648},{"batb":[[0,2.5,27.73],[1,2.42,16.44],[2,1.01,0.51]],"batl":[[0,2.82,22.69],[1,3.3,22.11]],"ltp":7.8,"tv":370.07,"id":13024647},{"batb":[[2,4.7,10.92]],"batl":[[0,5.6,8.4],[1,5.7,13.38]],"ltp":0.0,"tv":0.0,"id":16575845},{"batb":[[0,4.4,11.76],[1,3.5,16.37],[2,1.01,0.51]],"batl":[[0,5.2,9.24],[1,5.3,15.74]],"ltp":3.15,"tv":66.14,"id":16575844}]}]}
{"op":"mcm","clk":"1002923858","pt":1580647233293,"mc":[{"id":"1.168224575","rc":[{"batb":[[0,4.5,56.1],[1,4.4,61.08],[2,4.3,12.6]],"batl":[[2,5.4,15.19]],"ltp":0.0,"tv":0.0,"id":13024648},{"batb":[[1,2.48,61.01],[2,2.44,74.62]],"batl":[[0,2.56,16.05],[1,2.86,12.12]],"ltp":7.8,"tv":370.07,"id":13024647},{"batb":[[0,5,52.35]],"batl":[[1,5.7,13.14]],"ltp":0.0,"tv":0.0,"id":16575845},{"batb":[[0,4.7,47.63],[1,4.6,38.85],[2,4.4,11.76]],"batl":[[2,7,17.78]],"ltp":3.15,"tv":66.14,"id":16575844}]}]}
{"op":"mcm","clk":"1002924090","pt":1580647234411,"mc":[{"id":"1.168224575","rc":[{"batl":[[1,2.8,22.69],[2,2.86,12.12]],"ltp":7.8,"tv":370.07,"id":13024647}]}]}
{"op":"mcm","clk":"1002926647","pt":1580647246445,"mc":[{"id":"1.168224575","rc":[{"batb":[[0,4.4,61.08],[1,4.3,12.6],[2,1.01,0.51]],"batl":[[1,5.4,15.19],[2,5.4,0]],"ltp":0.0,"tv":0.0,"id":13024648},{"batb":[[1,2.12,23.45],[2,1.01,0.51]],"batl":[[0,2.8,22.69],[1,2.86,12.12],[2,2.86,0]],"ltp":7.8,"tv":370.07,"id":13024647},{"batb":[[0,5,38]],"ltp":0.0,"tv":0.0,"id":16575845},{"batb":[[0,4.4,11.76],[1,4,23.92],[2,1.01,0.51]],"batl":[[1,7,17.78],[2,7,0]],"ltp":3.15,"tv":66.14,"id":16575844}]}]}
{"op":"mcm","clk":"1002926882","pt":1580647247506,"mc":[{"id":"1.168224575","rc":[{"batb":[[1,1.01,0.51],[2,1.01,0]],"batl":[[0,5.4,15.19],[1,5.4,0]],"ltp":0.0,"tv":0.0,"id":13024648},{"batb":[[0,2.12,23.45],[1,1.01,0.51],[2,1.01,0]],"batl":[[0,2.86,12.12],[1,2.86,0]],"ltp":7.8,"tv":370.07,"id":13024647},{"batb":[[2,1.01,0.51]],"batl":[[0,5.7,13.14],[1,5.7,0]],"ltp":0.0,"tv":0.0,"id":16575845},{"batb":[[0,4,23.92],[1,1.01,0.51],[2,1.01,0]],"batl":[[0,7,17.78],[1,7,0]],"ltp":3.15,"tv":66.14,"id":16575844}]}]}
{"op":"mcm","clk":"1002927297","pt":1580647249437,"mc":[{"id":"1.168224575","rc":[{"batb":[[1,4.3,45.21],[2,1.01,0.51]],"ltp":0.0,"tv":0.0,"id":13024648},{"batb":[[0,2.16,52.55],[1,2.14,54.43],[2,2.12,23.45]],"ltp":7.8,"tv":370.07,"id":13024647},{"batb":[[0,4,68.72],[1,3.95,27.83],[2,1.01,0.51]],"ltp":3.15,"tv":66.14,"id":16575844}]}]}
{"op":"mcm","clk":"1002927438","pt":1580647250040,"mc":[{"id":"1.168224575","rc":[{"batb":[[0,4.4,18.18],[1,1.01,0.51],[2,1.01,0]],"ltp":0.0,"tv":0.0,"id":13024648},{"batb":[[1,4.9,13.69]],"ltp":0.0,"tv":0.0,"id":16575845},{"batb":[[0,4,23.92],[1,1.01,0.51],[2,1.01,0]],"ltp":3.15,"tv":66.14,"id":16575844}]}]}
{"op":"mcm","clk":"1002928101","pt":1580647253001,"mc":[{"id":"1.168224575","rc":[{"batb":[[0,4.6,60.13],[1,4.5,40.39],[2,4.4,18.18]],"ltp":0.0,"tv":0.0,"id":13024648},{"batb":[[0,5.1,28.51],[1,5,38],[2,4.9,13.69]],"ltp":0.0,"tv":0.0,"id":16575845},{"batb":[[0,6.2,42.96],[1,6,41.5],[2,4,23.92]],"ltp":3.15,"tv":66.14,"id":16575844}]}]}
{"op":"mcm","clk":"1002928419","pt":1580647254402,"mc":[{"id":"1.168224575","rc":[{"batb":[[0,4.7,15.82],[1,4.6,76.89],[2,4.5,40.39]],"batl":[[0,5.1,10.08],[1,5.4,15.19],[2,5.6,14.01]],"ltp":0.0,"tv":0.0,"id":13024648},{"batb":[[0,2.18,35.29],[1,2.16,52.55],[2,2.14,54.43]],"batl":[[0,2.26,22.82],[1,2.44,28.57],[2,2.46,17.86]],"ltp":7.8,"tv":370.07,"id":13024647},{"batl":[[0,5.6,8.4],[1,5.8,12.75]],"ltp":0.0,"tv":0.0,"id":16575845},{"batb":[[2,5.9,19.12]],"batl":[[0,7,24.5],[1,9.4,9.76]],"ltp":3.15,"tv":66.14,"id":16575844}]}]}
{"op":"mcm","clk":"1002930317","pt":1580647263441,"mc":[{"id":"1.168224575","rc":[{"batb":[[0,4.6,16.76],[1,4.5,40.39],[2,4.4,11.76]],"batl":[[1,5.6,14.01],[2,5.6,0]],"ltp":0.0,"tv":0.0,"id":13024648},{"batb":[[1,1.93,15.66],[2,1.01,0.51]],"batl":[[0,2.44,28.57],[1,2.46,17.86],[2,2.46,0]],"ltp":7.8,"tv":370.07,"id":13024647},{"batb":[[0,5,38],[1,4.9,13.69],[2,4.7,10.92]],"ltp":0.0,"tv":0.0,"id":16575845},{"batb":[[0,5.7,8.4],[1,5,13.93],[2,1.01,0.51]],"batl":[[0,7,6.72]],"ltp":3.15,"tv":66.14,"id":16575844}]}]}
{"op":"mcm","clk":"1002930389","pt":1580647263758,"mc":[{"id":"1.168224575","rc":[{"batb":[[2,1.01,0.51]],"batl":[[0,5.6,14.01],[1,5.6,0]],"ltp":0.0,"tv":0.0,"id":13024648},{"batb":[[0,1.93,15.66],[1,1.01,0.51],[2,1.01,0]],"batl":[[0,2.46,17.86],[1,2.46,0]],"ltp":7.8,"tv":370.07,"id":13024647},{"batb":[[2,1.01,0.51]],"batl":[[0,5.8,12.75],[1,5.8,0]],"ltp":0.0,"tv":0.0,"id":16575845},{"batb":[[0,5,13.93],[1,1.01,0.51],[2,1.01,0]],"batl":[[0,9.4,9.76],[1,9.4,0]],"ltp":3.15,"tv":66.14,"id":16575844}]}]}
{"op":"mcm","clk":"1002930949","pt":1580647266446,"mc":[{"id":"1.168224575","rc":[{"batb":[[1,4.5,62.65],[2,4.4,42.55]],"ltp":0.0,"tv":0.0,"id":13024648},{"batb":[[1,1.92,60.23],[2,1.9,78.2]],"ltp":7.8,"tv":370.07,"id":13024647},{"batb":[[0,5,48.89],[1,4.9,46.95]],"ltp":0.0,"tv":0.0,"id":16575845},{"batb":[[0,5.2,25.03],[1,5.1,30.73],[2,5,13.93]],"ltp":3.15,"tv":66.14,"id":16575844}]}]}
{"op":"mcm","clk":"1002931973","pt":1580647271264,"mc":[{"id":"1.168224575","rc":[{"batb":[[1,1.01,0.51],[2,4.4,0]],"ltp":0.0,"tv":0.0,"id":13024648},{"batb":[[0,5,38],[1,4.9,13.69]],"ltp":0.0,"tv":0.0,"id":16575845},{"batb":[[0,5,13.93],[1,1.01,0.51],[2,5,0]],"ltp":3.15,"tv":66.14,"id":16575844}]}]}
{"op":"mcm","clk":"1002932620","pt":1580647274456,"mc":[{"id":"1.168224575","rc":[{"batb":[[0,4.8,55.52],[1,4.7,52.52],[2,4.6,16.76]],"batl":[[0,5.2,9.24],[1,5.6,14.01],[2,5.7,13.45]],"ltp":0.0,"tv":0.0,"id":13024648},{"batb":[[2,1.91,45.37]],"batl":[[0,2.04,30.76],[1,2.08,38.65],[2,2.22,23.84]],"ltp":7.8,"tv":370.07,"id":13024647},{"batb":[[0,5.1,46.68],[1,5,51.77],[2,4.9,23.77]],"batl":[[0,5.8,21.15],[1,5.9,12.51]],"ltp":0.0,"tv":0.0,"id":16575845},{"batb":[[0,9.2,19.51],[1,9,22.53],[2,7.8,10.23]],"batl":[[1,11.5,3.36],[2,12,15.34]],"ltp":3.15,"tv":66.14,"id":16575844}]}]}
{"op":"mcm","clk":"1002932675","pt":1580647274766,"mc":[{"id":"1.168224575","rc":[{"batb":[[2,4.4,11.76]],"ltp":0.0,"tv":0.0,"id":13024648},{"batb":[[2,4.9,10.08]],"ltp":0.0,"tv":0.0,"id":16575845},{"batl":[[1,12,15.34],[2,12,0]],"ltp":3.15,"tv":66.14,"id":16575844}]}]}
{"op":"mcm","clk":"1002933189","pt":1580647277265,"mc":[{"id":"1.168224575","rc":[{"batl":[[1,12,18.7]],"ltp":3.15,"tv":66.14,"id":16575844}]}]}
{"op":"mcm","clk":"1002934224","pt":1580647282483,"mc":[{"id":"1.168224575","rc":[{"batl":[[1,5.5,14.24],[2,5.6,13.61]],"ltp":0.0,"tv":0.0,"id":13024648},{"batb":[[0,1.92,60.23],[1,1.91,45.37],[2,1.9,94.64]],"batl":[[0,2,16.21],[2,2.18,25.26]],"ltp":7.8,"tv":370.07,"id":13024647},{"batb":[[0,5.1,59.9],[1,5,38]],"batl":[[0,5.8,8.4],[1,5.9,12.2],[2,6,11.96]],"ltp":0.0,"tv":0.0,"id":16575845},{"batb":[[2,8.2,9.21]],"batl":[[0,9.8,8.81],[1,12,3.36],[2,12.5,13.77]],"ltp":3.15,"tv":66.14,"id":16575844}]}]}
{"op":"mcm","clk":"1002935759","pt":1580647290489,"mc":[{"id":"1.168224575","rc":[{"batb":[[2,4.6,16.05]],"ltp":0.0,"tv":0.0,"id":13024648},{"batb":[[1,1.91,61.58]],"batl":[[1,2.02,15.97],[2,2.08,38.65]],"ltp":7.8,"tv":370.07,"id":13024647},{"batb":[[1,5,51.3]],"ltp":0.0,"tv":0.0,"id":16575845}]}]}
{"op":"mcm","clk":"1002935855","pt":1580647290973,"mc":[{"id":"1.168224575","rc":[{"batb":[[1,4.7,36.78]],"ltp":0.0,"tv":0.0,"id":13024648},{"batb":[[2,1.9,78.2]],"batl":[[0,2.02,15.97],[1,2.08,38.65],[2,2.18,24.94]],"ltp":7.8,"tv":370.07,"id":13024647},{"batb":[[0,5.1,59.51]],"ltp":0.0,"tv":0.0,"id":16575845},{"batb":[[2,8,9.36]],"ltp":3.15,"tv":66.14,"id":16575844}]}]}
{"op":"mcm","clk":"1002936984","pt":1580647296906,"mc":[{"id":"1.168224575","rc":[{"batb":[[0,1.91,61.58],[1,1.82,19.04],[2,1.01,0.51]],"ltp":7.8,"tv":370.07,"id":13024647},{"batb":[[0,5.1,43.63],[1,5,13.3]],"ltp":0.0,"tv":0.0,"id":16575845}]}]}
{"op":"mcm","clk":"1002937427","pt":1580647299189,"mc":[{"id":"1.168224575","rc":[{"batl":[[2,2.2,24.86]],"ltp":7.8,"tv":370.07,"id":13024647}]}]}
{"op":"mcm","clk":"1002937569","pt":1580647299891,"mc":[{"id":"1.168224575","rc":[{"batb":[[0,1.91,152.52],[1,1.89,79.21],[2,1.82,19.04]],"ltp":7.8,"tv":370.07,"id":13024647},{"batb":[[0,5.2,23.34],[1,5.1,43.63],[2,5,13.3]],"ltp":0.0,"tv":0.0,"id":16575845}]}]}
{"op":"mcm","clk":"1002938017","pt":1580647302100,"mc":[{"id":"1.168224575","rc":[{"batl":[[0,1.92,60],[1,2.02,15.97],[2,2.08,38.65]],"ltp":7.8,"tv":370.07,"id":13024647}]}]}
{"op":"mcm","clk":"1002938123","pt":1580647302683,"mc":[{"id":"1.168224575","rc":[{"batl":[[2,2.2,24.86]],"ltp":7.8,"tv":370.07,"id":13024647}]}]}
{"op":"mcm","clk":"1002938577","pt":1580647304821,"mc":[{"id":"1.168224575","rc":[{"batb":[[0,4.8,46.82]],"ltp":0.0,"tv":0.0,"id":13024648},{"batb":[[0,1.91,132.5]],"ltp":7.8,"tv":370.07,"id":13024647}]}]}
{"op":"mcm","clk":"1002938922","pt":1580647306429,"mc":[{"id":"1.168224575","rc":[{"trd":[[1.92,16.8]],"batl":[[0,1.92,51.6],[2,2.06,39.49]],"ltp":1.92,"tv":386.88,"id":13024647}],"tv":453.02}]}
{"op":"mcm","clk":"1002939021","pt":1580647306901,"mc":[{"id":"1.168224575","rc":[{"batb":[[1,4.7,52.75],[2,4.4,11.76]],"ltp":0.0,"tv":0.0,"id":13024648},{"batb":[[0,1.91,116.29],[1,1.9,16.6],[2,1.89,79.21]],"batl":[[1,1.99,16.29]],"ltp":1.92,"tv":386.88,"id":13024647},{"batb":[[2,8.2,8.73]],"batl":[[0,10,8.34],[2,13,13.14]],"ltp":3.15,"tv":66.14,"id":16575844}]}]}
{"op":"mcm","clk":"1002939205","pt":1580647307801,"mc":[{"id":"1.168224575","rc":[{"batb":[[0,5.2,34.25]],"ltp":0.0,"tv":0.0,"id":16575845},{"batb":[[0,9.2,25.85]],"ltp":3.15,"tv":66.14,"id":16575844}]}]}
{"op":"mcm","clk":"1002942299","pt":1580647323226,"mc":[{"id":"1.168224575","rc":[{"batb":[[0,1.91,45.37],[2,1.81,19.36]],"batl":[[0,1.99,16.29],[1,2.06,39.49],[2,2.16,25.57]],"ltp":1.92,"tv":386.88,"id":13024647},{"batb":[[1,5.1,12.83]],"ltp":0.0,"tv":0.0,"id":16575845},{"batb":[[0,9.2,19.51],[1,9,5.04]],"ltp":3.15,"tv":66.14,"id":16575844}]}]}
{"op":"mcm","clk":"1002942991","pt":1580647326343,"mc":[{"id":"1.168224575","rc":[{"trd":[[1.9,12.46],[1.91,90.74]],"batb":[[0,1.9,91.2],[1,1.88,80.57]],"ltp":1.9,"tv":490.08,"id":13024647},{"batb":[[0,5.3,20.19],[1,5.2,34.25],[2,5.1,12.83]],"ltp":0.0,"tv":0.0,"id":16575845},{"batb":[[0,9.4,16.85],[1,9.2,19.51],[2,9,5.04]],"ltp":3.15,"tv":66.14,"id":16575844}],"tv":556.23}]}
{"op":"mcm","clk":"1002943076","pt":1580647326724,"mc":[{"id":"1.168224575","rc":[{"batb":[[2,1.01,0.51]],"ltp":0.0,"tv":0.0,"id":13024648},{"batl":[[1,2.16,25.57],[2,2.16,0]],"ltp":1.9,"tv":490.08,"id":13024647},{"batb":[[2,8.2,8.73]],"ltp":3.15,"tv":66.14,"id":16575844}]}]}
{"op":"mcm","clk":"1002943637","pt":1580647329639,"mc":[{"id":"1.168224575","rc":[{"batb":[[2,4.5,11.76]],"ltp":0.0,"tv":0.0,"id":13024648},{"batb":[[1,1.89,47.05],[2,1.88,80.57]],"batl":[[1,2.04,40.33],[2,2.16,25.57]],"ltp":1.9,"tv":490.08,"id":13024647},{"batb":[[1,9.2,24.55]],"ltp":3.15,"tv":66.14,"id":16575844}]}]}
{"op":"mcm","clk":"1002944555","pt":1580647334358,"mc":[{"id":"1.168224575","rc":[{"batb":[[0,1.9,80.83],[1,1.89,63.73]],"batl":[[0,1.98,16.44]],"ltp":1.9,"tv":490.08,"id":13024647},{"batb":[[2,8.4,8.73]],"ltp":3.15,"tv":66.14,"id":16575844}]}]}
{"op":"mcm","clk":"1002944746","pt":1580647335259,"mc":[{"id":"1.168224575","rc":[{"batb":[[0,4.8,14.63]],"ltp":0.0,"tv":0.0,"id":13024648},{"batb":[[0,1.9,58.98]],"ltp":1.9,"tv":490.08,"id":13024647}]}]}
{"op":"mcm","clk":"1002945333","pt":1580647338254,"mc":[{"id":"1.168224575","rc":[{"batb":[[1,4.7,73.11],[2,4.6,38.02]],"ltp":0.0,"tv":0.0,"id":13024648},{"batb":[[0,5.3,32.1]],"ltp":0.0,"tv":0.0,"id":16575845},{"batb":[[0,9.4,22.99]],"ltp":3.15,"tv":66.14,"id":16575844}]}]}
{"op":"mcm","clk":"1002949821","pt":1580647360454,"mc":[{"id":"1.168224575","rc":[{"batb":[[0,1.89,63.73],[1,1.8,19.51],[2,1.01,0.51]],"ltp":1.9,"tv":490.08,"id":13024647}]}]}
{"op":"mcm","clk":"1002950245","pt":1580647362562,"mc":[{"id":"1.168224575","rc":[{"batb":[[0,1.89,154.77],[1,1.87,81.96],[2,1.8,19.51]],"ltp":1.9,"tv":490.08,"id":13024647}]}]}
{"op":"mcm","clk":"1002951042","pt":1580647366489,"mc":[{"id":"1.168224575","rc":[{"batb":[[1,4.7,15.97]],"ltp":0.0,"tv":0.0,"id":13024648},{"batb":[[0,1.89,63.73],[1,1.8,19.51],[2,1.01,0.51]],"ltp":1.9,"tv":490.08,"id":13024647},{"batb":[[0,5.2,34.25],[1,5.1,12.83],[2,4.9,10.08]],"ltp":0.0,"tv":0.0,"id":16575845},{"batb":[[0,9.2,5.04],[1,8.4,8.73],[2,6.6,14.87]],"ltp":3.15,"tv":66.14,"id":16575844}]}]}
{"op":"mcm","clk":"1002951133","pt":1580647366854,"mc":[{"id":"1.168224575","rc":[{"batb":[[0,4.7,15.97],[1,4.6,38.02],[2,4.5,11.76]],"batl":[[1,5.6,13.61],[2,5.6,0]],"ltp":0.0,"tv":0.0,"id":13024648},{"batb":[[0,1.89,47.05]],"batl":[[0,2.04,40.33],[1,2.16,25.57],[2,2.16,0]],"ltp":1.9,"tv":490.08,"id":13024647},{"batl":[[1,6,11.96],[2,6,0]],"ltp":0.0,"tv":0.0,"id":16575845},{"batb":[[1,6.6,14.87],[2,1.01,0.51]],"batl":[[0,12,3.36],[1,13,13.14],[2,13,0]],"ltp":3.15,"tv":66.14,"id":16575844}]}]}
{"op":"mcm","clk":"1002951291","pt":1580647367549,"mc":[{"id":"1.168224575","rc":[{"batb":[[2,1.01,0.51]],"batl":[[0,5.6,13.61],[1,5.6,0]],"ltp":0.0,"tv":0.0,"id":13024648},{"batb":[[0,1.8,19.51],[1,1.01,0.51],[2,1.01,0]],"batl":[[0,2.16,25.57],[1,2.16,0]],"ltp":1.9,"tv":490.08,"id":13024647},{"batb":[[2,1.01,0.51]],"batl":[[0,6,11.96],[1,6,0]],"ltp":0.0,"tv":0.0,"id":16575845},{"batb":[[0,6.6,14.87],[1,1.01,0.51],[2,1.01,0]],"batl":[[0,13,13.14],[1,13,0]],"ltp":3.15,"tv":66.14,"id":16575844}]}]}
{"op":"mcm","clk":"1002951678","pt":1580647369367,"mc":[{"id":"1.168224575","rc":[{"batb":[[1,4.6,69.51],[2,4.5,39.96]],"ltp":0.0,"tv":0.0,"id":13024648},{"batb":[[0,1.82,66.03],[1,1.8,112.36],[2,1.79,19.99]],"batl":[[0,2.14,26.44],[1,2.16,25.57]],"ltp":1.9,"tv":490.08,"id":13024647},{"batb":[[0,5.2,54.08],[1,5.1,43.97]],"batl":[[1,6.2,11.49]],"ltp":0.0,"tv":0.0,"id":16575845},{"batb":[[0,7.2,34.25],[1,7,30.37],[2,6.6,14.87]],"ltp":3.15,"tv":66.14,"id":16575844}]}]}
{"op":"mcm","clk":"1002951882","pt":1580647370339,"mc":[{"id":"1.168224575","rc":[{"batb":[[0,4.6,69.51],[1,4.5,39.96],[2,1.01,0.51]],"ltp":0.0,"tv":0.0,"id":13024648},{"batb":[[1,1.8,92.85]],"batl":[[1,2.16,0]],"ltp":1.9,"tv":490.08,"id":13024647},{"batb":[[1,5.1,31.14]],"batl":[[0,6.2,11.49],[1,6.2,0]],"ltp":0.0,"tv":0.0,"id":16575845},{"batb":[[2,6.6,14.16]],"batl":[[0,13,12.51]],"ltp":3.15,"tv":66.14,"id":16575844}]}]}
{"op":"mcm","clk":"1002952794","pt":1580647374846,"mc":[{"id":"1.168224575","rc":[{"batb":[[0,1.79,19.99],[1,1.01,0.51],[2,1.79,0]],"ltp":1.9,"tv":490.08,"id":13024647}]}]}
{"op":"mcm","clk":"1002953561","pt":1580647378422,"mc":[{"id":"1.168224575","rc":[{"batb":[[2,4.4,11.76]],"batl":[[0,5.1,10.08],[1,5.6,13.61]],"ltp":0.0,"tv":0.0,"id":13024648},{"batb":[[0,2.04,80.64],[1,2.02,64.34],[2,2,42.01]],"batl":[[1,2.2,34.45]],"ltp":1.9,"tv":490.08,"id":13024647},{"batb":[[2,4.8,10.92]],"batl":[[0,5.7,8.4],[1,6.2,11.49]],"ltp":0.0,"tv":0.0,"id":16575845},{"batb":[[0,7.4,5.88],[1,7.2,34.25],[2,7,30.37]],"batl":[[0,9.4,4.2],[1,13,12.51]],"ltp":3.15,"tv":66.14,"id":16575844}]}]}
{"op":"mcm","clk":"1002953774","pt":1580647379435,"mc":[{"id":"1.168224575","rc":[{"batb":[[1,4.5,57.58]],"batl":[[1,5.3,15.5],[2,5.4,14.87]],"ltp":0.0,"tv":0.0,"id":13024648},{"batb":[[1,2.02,132.73],[2,1.91,16.21]],"batl":[[2,2.38,19.83]],"ltp":1.9,"tv":490.08,"id":13024647},{"batb":[[0,5.2,41.41],[1,5.1,44.2]],"batl":[[1,5.9,12.2],[2,6,12.04]],"ltp":0.0,"tv":0.0,"id":16575845},{"batl":[[0,8,13.3],[1,9.8,8.66]],"ltp":3.15,"tv":66.14,"id":16575844}]}]}
{"op":"mcm","clk":"1002954181","pt":1580647381344,"mc":[{"id":"1.168224575","rc":[{"batl":[[1,9.2,5.04],[2,9.8,8.66]],"ltp":3.15,"tv":66.14,"id":16575844}]}]}
{"op":"mcm","clk":"1002956636","pt":1580647392832,"mc":[{"id":"1.168224575","rc":[{"batb":[[0,4.5,57.58],[1,4.4,11.76],[2,1.01,0.51]],"batl":[[1,5.4,14.87],[2,5.4,0]],"ltp":0.0,"tv":0.0,"id":13024648},{"batb":[[0,2.02,41.17],[1,1.91,16.21],[2,1.01,0.51]],"batl":[[0,2.2,34.45],[1,2.38,19.83],[2,2.38,0]],"ltp":1.9,"tv":490.08,"id":13024647},{"batb":[[0,5.2,23.34]],"batl":[[1,6,12.04],[2,6,0]],"ltp":0.0,"tv":0.0,"id":16575845},{"batb":[[1,5.4,11.72],[2,1.01,0.51]],"batl":[[0,9.2,5.04],[1,9.8,8.66],[2,9.8,0]],"ltp":3.15,"tv":66.14,"id":16575844}]}]}
{"op":"mcm","clk":"1002956805","pt":1580647393655,"mc":[{"id":"1.168224575","rc":[{"batb":[[1,1.01,0.51],[2,1.01,0]],"batl":[[0,5.4,14.87],[1,5.4,0]],"ltp":0.0,"tv":0.0,"id":13024648},{"batb":[[0,1.91,16.21],[1,1.01,0.51],[2,1.01,0]],"batl":[[0,2.38,19.83],[1,2.38,0]],"ltp":1.9,"tv":490.08,"id":13024647},{"batb":[[2,1.01,0.51]],"batl":[[0,6,12.04],[1,6,0]],"ltp":0.0,"tv":0.0,"id":16575845},{"batb":[[0,5.4,11.72],[1,1.01,0.51],[2,1.01,0]],"batl":[[0,9.8,8.66],[1,9.8,0]],"ltp":3.15,"tv":66.14,"id":16575844}]}]}
{"op":"mcm","clk":"1002957329","pt":1580647396431,"mc":[{"id":"1.168224575","rc":[{"batb":[[0,4.5,39.96],[1,4.4,59.94],[2,1.01,0.51]],"ltp":0.0,"tv":0.0,"id":13024648},{"batb":[[0,1.93,62.54],[1,1.91,76.6],[2,1.9,16.37]],"ltp":1.9,"tv":490.08,"id":13024647},{"batl":[[0,6,11.88]],"ltp":0.0,"tv":0.0,"id":16575845},{"batb":[[0,5.5,40.21],[1,5.4,38.8],[2,1.01,0.51]],"batl":[[0,10,8.5]],"ltp":3.15,"tv":66.14,"id":16575844}]}]}
{"op":"mcm","clk":"1002957538","pt":1580647397388,"mc":[{"id":"1.168224575","rc":[{"batb":[[0,4.4,17.78],[1,1.01,0.51],[2,1.01,0]],"ltp":0.0,"tv":0.0,"id":13024648},{"batb":[[1,5.1,13.06]],"ltp":0.0,"tv":0.0,"id":16575845},{"batb":[[0,5.4,11.57],[1,1.01,0.51],[2,1.01,0]],"ltp":3.15,"tv":66.14,"id":16575844}]}]}
{"op":"mcm","clk":"1002958168","pt":1580647400441,"mc":[{"id":"1.168224575","rc":[{"batb":[[0,4.7,43.92],[1,4.6,38.2],[2,4.4,17.78]],"ltp":0.0,"tv":0.0,"id":13024648},{"batb":[[0,5.3,22.81],[1,5.2,30.13],[2,5.1,13.06]],"ltp":0.0,"tv":0.0,"id":16575845},{"batb":[[0,9,13.67],[1,8.8,18.94],[2,5.4,11.57]],"ltp":3.15,"tv":66.14,"id":16575844}]}]}
{"op":"mcm","clk":"1002958342","pt":1580647401295,"mc":[{"id":"1.168224575","rc":[{"batb":[[0,4.7,59.58],[1,4.6,54.96],[2,4.5,11.76]],"batl":[[0,5.2,9.24],[1,5.4,14.87],[2,5.5,14.08]],"ltp":0.0,"tv":0.0,"id":13024648},{"batb":[[0,1.93,107.07]],"batl":[[0,1.99,16.13],[1,2.1,37.81],[2,2.2,24.39]],"ltp":1.9,"tv":490.08,"id":13024647},{"batb":[[2,5.1,12.9]],"batl":[[0,5.7,8.4],[1,6,11.88]],"ltp":0.0,"tv":0.0,"id":16575845},{"batb":[[1,8.8,23.98],[2,8.2,8.89]],"batl":[[1,11.5,3.36],[2,13,12.59]],"ltp":3.15,"tv":66.14,"id":16575844}]}]}
{"op":"mcm","clk":"1002961180","pt":1580647414951,"mc":[{"id":"1.168224575","rc":[{"batb":[[0,4.6,54.96],[1,4.5,11.76],[2,1.01,0.51]],"batl":[[1,5.5,14.08],[2,5.5,0]],"ltp":0.0,"tv":0.0,"id":13024648},{"batb":[[0,1.93,44.53],[1,1.8,19.51],[2,1.01,0.51]],"batl":[[0,2.1,37.81],[1,2.2,24.39],[2,2.2,0]],"ltp":1.9,"tv":490.08,"id":13024647},{"batb":[[0,5.2,30.13],[1,5.1,12.9],[2,4.9,10.08]],"ltp":0.0,"tv":0.0,"id":16575845},{"batb":[[0,8.8,5.04],[1,6.2,16.37],[2,1.01,0.51]],"batl":[[0,11.5,3.36],[1,13,12.59],[2,13,0]],"ltp":3.15,"tv":66.14,"id":16575844}]}]}
{"op":"mcm","clk":"1002961334","pt":1580647415644,"mc":[{"id":"1.168224575","rc":[{"batb":[[1,1.01,0.51],[2,1.01,0]],"batl":[[0,5.5,14.08],[1,5.5,0]],"ltp":0.0,"tv":0.0,"id":13024648},{"batb":[[0,1.8,19.51],[1,1.01,0.51],[2,1.01,0]],"batl":[[0,2.2,24.39],[1,2.2,0]],"ltp":1.9,"tv":490.08,"id":13024647},{"batb":[[2,1.01,0.51]],"batl":[[0,6,11.88],[1,6,0]],"ltp":0.0,"tv":0.0,"id":16575845},{"batb":[[0,6.2,16.37],[1,1.01,0.51],[2,1.01,0]],"batl":[[0,13,12.59],[1,13,0]],"ltp":3.15,"tv":66.14,"id":16575844}]}]}
{"op":"mcm","clk":"1002961883","pt":1580647418332,"mc":[{"id":"1.168224575","rc":[{"batb":[[0,4.6,54.72]],"batl":[[0,5.6,13.93]],"ltp":0.0,"tv":0.0,"id":13024648},{"batb":[[0,1.81,19.2]],"batl":[[0,2.22,23.92]],"ltp":1.9,"tv":490.08,"id":13024647},{"batb":[[1,5.1,31.29],[2,5,13.3]],"batl":[[0,5.9,12.2]],"ltp":0.0,"tv":0.0,"id":16575845}]}]}
{"op":"mcm","clk":"1002962162","pt":1580647419853,"mc":[{"id":"1.168224575","rc":[{"batb":[[0,4.7,34.63],[1,4.6,54.72],[2,1.01,0.51]],"ltp":0.0,"tv":0.0,"id":13024648},{"batb":[[0,1.96,82.31],[1,1.94,72.93],[2,1.81,19.2]],"ltp":1.9,"tv":490.08,"id":13024647},{"batb":[[0,5.2,47.72]],"ltp":0.0,"tv":0.0,"id":16575845},{"batb":[[0,8.4,14.35],[1,8.2,21.98],[2,6.2,16.37]],"ltp":3.15,"tv":66.14,"id":16575844}]}]}
{"op":"mcm","clk":"1002962845","pt":1580647423320,"mc":[{"id":"1.168224575","rc":[{"trd":[[1.96,129.4]],"batb":[[0,1.96,17.61]],"ltp":1.96,"tv":619.47,"id":13024647}],"tv":685.62}]}
{"op":"mcm","clk":"1002963054","pt":1580647424245,"mc":[{"id":"1.168224575","rc":[{"batb":[[0,5.2,30.19],[1,5,13.3],[2,1.01,0.51]],"ltp":0.0,"tv":0.0,"id":16575845}]}]}
{"op":"mcm","clk":"1002963320","pt":1580647425445,"mc":[{"id":"1.168224575","rc":[{"batb":[[0,4.6,54.72],[1,1.01,0.51],[2,1.01,0]],"ltp":0.0,"tv":0.0,"id":13024648},{"batb":[[0,1.81,19.2],[1,1.01,0.51],[2,1.81,0]],"ltp":1.96,"tv":619.47,"id":13024647},{"batb":[[0,6.2,16.37],[1,1.01,0.51],[2,6.2,0]],"ltp":3.15,"tv":66.14,"id":16575844}]}]}
{"op":"mcm","clk":"1002964188","pt":1580647429434,"mc":[{"id":"1.168224575","rc":[{"batb":[[1,4.5,40.25],[2,1.01,0.51]],"ltp":0.0,"tv":0.0,"id":13024648},{"batb":[[0,1.83,70.68],[1,1.81,110.39],[2,1.01,0.51]],"ltp":1.96,"tv":619.47,"id":13024647},{"batb":[[1,5.1,31.3],[2,5,13.3]],"ltp":0.0,"tv":0.0,"id":16575845},{"batb":[[0,6.6,27.38],[1,6.4,37.13],[2,6.2,16.37]],"ltp":3.15,"tv":66.14,"id":16575844}]}]}
{"op":"mcm","clk":"1002965164","pt":1580647434206,"mc":[{"id":"1.168224575","rc":[{"batb":[[0,1.81,19.2],[1,1.01,0.51],[2,1.01,0]],"ltp":1.96,"tv":619.47,"id":13024647}]}]}
{"op":"mcm","clk":"1002965759","pt":1580647437112,"mc":[{"id":"1.168224575","rc":[{"batb":[[0,2.12,49.9],[1,2.1,57.26],[2,1.81,19.2]],"ltp":1.96,"tv":619.47,"id":13024647}]}]}
{"op":"mcm","clk":"1002966035","pt":1580647438307,"mc":[{"id":"1.168224575","rc":[{"batb":[[2,4.4,18.1]],"batl":[[0,5.3,15.74],[1,5.4,14.95]],"ltp":0.0,"tv":0.0,"id":13024648},{"batb":[[1,2.1,81.81],[2,1.94,15.5]],"batl":[[1,2.52,16.76]],"ltp":1.96,"tv":619.47,"id":13024647},{"batl":[[0,5.8,12.59]],"ltp":0.0,"tv":0.0,"id":16575845},{"batl":[[0,7.4,15.82],[1,9.4,9.44]],"ltp":3.15,"tv":66.14,"id":16575844}]}]}
{"op":"mcm","clk":"1002966227","pt":1580647439305,"mc":[{"id":"1.168224575","rc":[{"batl":[[0,5,10.08],[1,5.3,15.74],[2,5.4,14.95]],"ltp":0.0,"tv":0.0,"id":13024648},{"batb":[[2,2.08,38.65]],"batl":[[1,2.28,32.77],[2,2.52,16.76]],"ltp":1.96,"tv":619.47,"id":13024647},{"batl":[[0,5.6,8.4],[1,5.8,12.59]],"ltp":0.0,"tv":0.0,"id":16575845},{"batb":[[0,6.8,6.72],[1,6.6,27.38],[2,6.4,37.13]],"batl":[[1,8.4,5.04],[2,9.4,9.44]],"ltp":3.15,"tv":66.14,"id":16575844}]}]}
{"op":"mcm","clk":"1002968048","pt":1580647447666,"mc":[{"id":"1.168224575","rc":[{"batb":[[0,2.1,81.81],[1,2.08,38.65],[2,1.94,15.5]],"ltp":1.96,"tv":619.47,"id":13024647}]}]}
{"op":"mcm","clk":"1002968660","pt":1580647450605,"mc":[{"id":"1.168224575","rc":[{"batb":[[0,2.1,116.55],[1,2.08,97.47]],"ltp":1.96,"tv":619.47,"id":13024647},{"batb":[[0,5.2,40.18]],"ltp":0.0,"tv":0.0,"id":16575845},{"batb":[[1,6.6,33.93]],"ltp":3.15,"tv":66.14,"id":16575844}]}]}
{"op":"mcm","clk":"1002969447","pt":1580647454284,"mc":[{"id":"1.168224575","rc":[{"batb":[[0,4.4,18.1],[1,4.3,12.6],[2,1.01,0.51]],"batl":[[1,5.4,14.95],[2,5.4,0]],"ltp":0.0,"tv":0.0,"id":13024648},{"batb":[[0,2.08,38.65],[1,1.94,15.5],[2,1.01,0.51]],"batl":[[0,2.28,32.77],[1,2.52,16.76],[2,2.52,0]],"ltp":1.96,"tv":619.47,"id":13024647},{"batb":[[0,5.2,23.34]],"ltp":0.0,"tv":0.0,"id":16575845},{"batb":[[1,4.9,14.95],[2,1.01,0.51]],"batl":[[0,8.4,5.04],[1,9.4,9.44],[2,9.4,0]],"ltp":3.15,"tv":66.14,"id":16575844}]}]}
{"op":"mcm","clk":"1002969730","pt":1580647455720,"mc":[{"id":"1.168224575","rc":[{"batb":[[1,1.01,0.51],[2,1.01,0]],"batl":[[0,5.4,14.95],[1,5.4,0]],"ltp":0.0,"tv":0.0,"id":13024648},{"batb":[[0,1.94,15.5],[1,1.01,0.51],[2,1.01,0]],"batl":[[0,2.52,16.76],[1,2.52,0]],"ltp":1.96,"tv":619.47,"id":13024647},{"batl":[[0,5.8,12.59],[1,5.8,0]],"ltp":0.0,"tv":0.0,"id":16575845},{"batb":[[0,4.9,14.95],[1,1.01,0.51],[2,1.01,0]],"batl":[[0,9.4,9.44],[1,9.4,0]],"ltp":3.15,"tv":66.14,"id":16575844}]}]}
{"op":"mcm","clk":"1002970931","pt":1580647461423,"mc":[{"id":"1.168224575","rc":[{"batb":[[0,4.5,61.31],[1,4.4,59.98],[2,1.01,0.51]],"ltp":0.0,"tv":0.0,"id":13024648},{"batb":[[0,2.16,79.86],[1,2.14,54.05],[2,1.94,15.5]],"ltp":1.96,"tv":619.47,"id":13024647},{"batb":[[0,5.2,36.57]],"ltp":0.0,"tv":0.0,"id":16575845},{"batb":[[0,6.2,26.76],[1,6,42.95],[2,4.9,14.95]],"ltp":3.15,"tv":66.14,"id":16575844}]}]}
{"op":"mcm","clk":"1002971488","pt":1580647464096,"mc":[{"id":"1.168224575","rc":[{"batb":[[0,2.16,62.27]],"ltp":1.96,"tv":619.47,"id":13024647}]}]}
{"op":"mcm","clk":"1002971911","pt":1580647466247,"mc":[{"id":"1.168224575","rc":[{"batb":[[0,4.4,59.98],[1,1.01,0.51],[2,1.01,0]],"ltp":0.0,"tv":0.0,"id":13024648},{"batb":[[0,1.94,15.5],[1,1.01,0.51],[2,1.94,0]],"ltp":1.96,"tv":619.47,"id":13024647},{"batb":[[0,5.2,23.34]],"ltp":0.0,"tv":0.0,"id":16575845},{"batb":[[0,4.9,14.95],[1,1.01,0.51],[2,4.9,0]],"ltp":3.15,"tv":66.14,"id":16575844}]}]}
{"op":"mcm","clk":"1002972394","pt":1580647468393,"mc":[{"id":"1.168224575","rc":[{"batb":[[0,4.4,18.1]],"ltp":0.0,"tv":0.0,"id":13024648},{"batb":[[1,5,13.3],[2,1.01,0.51]],"ltp":0.0,"tv":0.0,"id":16575845}]}]}
{"op":"mcm","clk":"1002972526","pt":1580647468978,"mc":[{"id":"1.168224575","rc":[{"batb":[[0,1.95,74.2],[1,1.94,15.5],[2,1.93,74.02]],"ltp":1.96,"tv":619.47,"id":13024647}]}]}
{"op":"mcm","clk":"1002973036","pt":1580647471397,"mc":[{"id":"1.168224575","rc":[{"batb":[[0,4.7,32.85],[1,4.6,38.32],[2,4.4,18.1]],"ltp":0.0,"tv":0.0,"id":13024648},{"batb":[[0,5.3,20.96],[1,5.2,30.29],[2,5,13.3]],"ltp":0.0,"tv":0.0,"id":16575845},{"batb":[[0,8.6,17.08],[1,8.4,21.1],[2,4.9,14.95]],"ltp":3.15,"tv":66.14,"id":16575844}]}]}
{"op":"mcm","clk":"1002973259","pt":1580647472355,"mc":[{"id":"1.168224575","rc":[{"batb":[[0,4.7,48.51],[2,4.5,17.15]],"batl":[[1,5.6,14.01]],"ltp":0.0,"tv":0.0,"id":13024648},{"batl":[[0,2.06,30.06],[1,2.32,21.24]],"ltp":1.96,"tv":619.47,"id":13024647},{"batl":[[0,5.9,12.51]],"ltp":0.0,"tv":0.0,"id":16575845},{"batb":[[2,7.8,9.91]],"batl":[[1,13.5,11.96]],"ltp":3.15,"tv":66.14,"id":16575844}]}]}
{"op":"mcm","clk":"1002973375","pt":1580647473000,"mc":[{"id":"1.168224575","rc":[{"batl":[[0,5.2,9.24],[1,5.4,14.95],[2,5.6,14.01]],"ltp":0.0,"tv":0.0,"id":13024648},{"batb":[[0,1.95,117.89]],"batl":[[1,2.14,36.13],[2,2.32,21.24]],"ltp":1.96,"tv":619.47,"id":13024647},{"batl":[[0,5.6,8.4],[1,5.9,12.51]],"ltp":0.0,"tv":0.0,"id":16575845},{"batb":[[1,8.4,26.14]],"batl":[[1,10.5,4.2],[2,13.5,11.96]],"ltp":3.15,"tv":66.14,"id":16575844}]}]}
{"op":"mcm","clk":"1002977121","pt":1580647491397,"mc":[{"id":"1.168224575","rc":[{"batb":[[0,4.5,17.15],[1,4.4,11.76],[2,1.01,0.51]],"batl":[[1,5.6,14.01],[2,5.6,0]],"ltp":0.0,"tv":0.0,"id":13024648},{"batb":[[0,1.95,43.69],[1,1.81,19.28],[2,1.01,0.51]],"batl":[[0,2.14,36.13],[1,2.32,21.24],[2,2.32,0]],"ltp":1.96,"tv":619.47,"id":13024647},{"batb":[[0,5.2,30.29],[1,5,13.3],[2,4.8,10.92]],"ltp":0.0,"tv":0.0,"id":16575845},{"batb":[[0,8.4,5.04],[1,5.7,10.39],[2,1.01,0.51]],"batl":[[0,10.5,4.2],[1,13.5,11.96],[2,13.5,0]],"ltp":3.15,"tv":66.14,"id":16575844}]}]}
{"op":"mcm","clk":"1002977191","pt":1580647491724,"mc":[{"id":"1.168224575","rc":[{"batb":[[1,1.01,0.51],[2,1.01,0]],"batl":[[0,5.6,14.01],[1,5.6,0]],"ltp":0.0,"tv":0.0,"id":13024648},{"batb":[[0,1.81,19.28],[1,1.01,0.51],[2,1.01,0]],"batl":[[0,2.32,21.24],[1,2.32,0]],"ltp":1.96,"tv":619.47,"id":13024647},{"batb":[[2,1.01,0.51]],"batl":[[0,5.9,12.51],[1,5.9,0]],"ltp":0.0,"tv":0.0,"id":16575845},{"batb":[[0,5.7,10.39],[1,1.01,0.51],[2,1.01,0]],"batl":[[0,13.5,11.96],[1,13.5,0]],"ltp":3.15,"tv":66.14,"id":16575844}]}]}
{"op":"mcm","clk":"1002977574","pt":1580647493624,"mc":[{"id":"1.168224575","rc":[{"batb":[[0,4.5,65.04],[1,4.4,42.11],[2,1.01,0.51]],"ltp":0.0,"tv":0.0,"id":13024648},{"batb":[[0,1.82,85.79],[1,1.81,19.28],[2,1.8,92.77]],"ltp":1.96,"tv":619.47,"id":13024647},{"batb":[[1,5.1,31.42],[2,5,13.3]],"ltp":0.0,"tv":0.0,"id":16575845},{"batb":[[0,5.9,24.39],[1,5.8,23.71],[2,5.7,10.39]],"ltp":3.15,"tv":66.14,"id":16575844}]}]}
{"op":"mcm","clk":"1002977860","pt":1580647495031,"mc":[{"id":"1.168224575","rc":[{"batb":[[0,4.5,17.15],[1,1.01,0.51],[2,1.01,0]],"ltp":0.0,"tv":0.0,"id":13024648},{"batb":[[1,5,13.3],[2,1.01,0.51]],"ltp":0.0,"tv":0.0,"id":16575845},{"batb":[[0,5.7,10.39],[1,1.01,0.51],[2,5.7,0]],"ltp":3.15,"tv":66.14,"id":16575844}]}]}
{"op":"mcm","clk":"1002978510","pt":1580647498412,"mc":[{"id":"1.168224575","rc":[{"batb":[[0,4.8,33.72],[1,4.7,52.33],[2,4.5,17.15]],"batl":[[1,5.7,13.38]],"ltp":0.0,"tv":0.0,"id":13024648},{"batl":[[0,1.89,18.96],[1,2.08,29.19],[2,2.32,21.24]],"ltp":1.96,"tv":619.47,"id":13024647},{"batb":[[0,5.3,33.26],[1,5.2,30.29],[2,5.1,13.3]],"ltp":0.0,"tv":0.0,"id":16575845},{"batb":[[0,11.5,29.47],[1,11,28.57],[2,10,13.14]],"batl":[[1,18.5,6.53]],"ltp":3.15,"tv":66.14,"id":16575844}]}]}
{"op":"mcm","clk":"1002978676","pt":1580647499323,"mc":[{"id":"1.168224575","rc":[{"batb":[[2,4.5,11.76]],"batl":[[0,5.3,9.24],[1,5.6,14.01],[2,5.7,13.38]],"ltp":0.0,"tv":0.0,"id":13024648},{"batb":[[0,1.84,49.57],[1,1.82,85.79],[2,1.81,19.28]],"batl":[[1,2,42.01],[2,2.08,29.19]],"ltp":1.96,"tv":619.47,"id":13024647},{"batl":[[0,5.6,8.4],[1,5.9,12.12]],"ltp":0.0,"tv":0.0,"id":16575845},{"batb":[[1,11,32.77]],"ltp":3.15,"tv":66.14,"id":16575844}]}]}
{"op":"mcm","clk":"1002981128","pt":1580647510398,"mc":[{"id":"1.168224575","rc":[{"batb":[[0,4.7,43.75],[1,4.5,11.76],[2,1.01,0.51]],"batl":[[1,5.7,13.38],[2,5.7,0]],"ltp":0.0,"tv":0.0,"id":13024648},{"batb":[[1,1.72,22.82],[2,1.01,0.51]],"batl":[[0,2,42.01],[1,2.08,29.19],[2,2.08,0]],"ltp":1.96,"tv":619.47,"id":13024647},{"batb":[[0,5.2,30.29],[1,5.1,13.3],[2,4.8,10.92]],"ltp":0.0,"tv":0.0,"id":16575845},{"batb":[[0,11,4.2],[1,7.6,10.46],[2,1.01,0.51]],"batl":[[0,18.5,6.53],[1,18.5,0]],"ltp":3.15,"tv":66.14,"id":16575844}]}]}
{"op":"mcm","clk":"1002981391","pt":1580647511683,"mc":[{"id":"1.168224575","rc":[{"batb":[[1,1.01,0.51],[2,1.01,0]],"batl":[[0,5.7,13.38],[1,5.7,0]],"ltp":0.0,"tv":0.0,"id":13024648},{"batb":[[0,1.72,22.82],[1,1.01,0.51],[2,1.01,0]],"batl":[[0,2.08,29.19],[1,2.08,0]],"ltp":1.96,"tv":619.47,"id":13024647},{"batb":[[2,1.01,0.51]],"batl":[[0,5.9,12.12],[1,5.9,0]],"ltp":0.0,"tv":0.0,"id":16575845},{"batb":[[0,7.6,10.46],[1,1.01,0.51],[2,1.01,0]],"ltp":3.15,"tv":66.14,"id":16575844}]}]}
{"op":"mcm","clk":"1002981697","pt":1580647513180,"mc":[{"id":"1.168224575","rc":[{"batb":[[1,4.6,38.41],[2,1.01,0.51]],"ltp":0.0,"tv":0.0,"id":13024648},{"batb":[[0,1.75,57.67],[1,1.73,105.71],[2,1.72,22.82]],"ltp":1.96,"tv":619.47,"id":13024647},{"batb":[[0,5.2,38.14],[1,5.1,44.68]],"ltp":0.0,"tv":0.0,"id":16575845},{"batb":[[0,8.4,16.29],[1,8.2,22.24],[2,7.6,10.46]],"ltp":3.15,"tv":66.14,"id":16575844}]}]}
{"op":"mcm","clk":"1002981809","pt":1580647513688,"mc":[{"id":"1.168224575","rc":[{"batb":[[1,1.01,0.51],[2,1.01,0]],"ltp":0.0,"tv":0.0,"id":13024648},{"batb":[[0,1.72,22.82],[1,1.01,0.51],[2,1.72,0]],"ltp":1.96,"tv":619.47,"id":13024647},{"batb":[[0,5.2,30.29],[1,5.1,13.3]],"ltp":0.0,"tv":0.0,"id":16575845},{"batb":[[0,7.6,10.46],[1,1.01,0.51],[2,7.6,0]],"ltp":3.15,"tv":66.14,"id":16575844}]}]}
{"op":"mcm","clk":"1002982569","pt":1580647517448,"mc":[{"id":"1.168224575","rc":[{"batb":[[0,4.8,25.16],[1,4.7,52.46],[2,1.01,0.51]],"ltp":0.0,"tv":0.0,"id":13024648},{"batb":[[0,1.85,74.08],[1,1.83,87.83],[2,1.72,22.82]],"ltp":1.96,"tv":619.47,"id":13024647},{"batb":[[0,5.3,28.13],[1,5.2,30.29],[2,5.1,13.3]],"ltp":0.0,"tv":0.0,"id":16575845},{"batb":[[0,10.5,41.11],[1,10,23.9],[2,7.6,10.46]],"ltp":3.15,"tv":66.14,"id":16575844}]}]}
{"op":"mcm","clk":"1002983240","pt":1580647520989,"mc":[{"id":"1.168224575","rc":[{"batb":[[0,4.7,43.75],[1,1.01,0.51],[2,1.01,0]],"ltp":0.0,"tv":0.0,"id":13024648},{"batb":[[0,1.72,22.82],[1,1.01,0.51],[2,1.72,0]],"ltp":1.96,"tv":619.47,"id":13024647},{"batb":[[0,5.2,30.29],[1,5.1,13.3],[2,1.01,0.51]],"ltp":0.0,"tv":0.0,"id":16575845},{"batb":[[0,7.6,10.46],[1,1.01,0.51],[2,7.6,0]],"ltp":3.15,"tv":66.14,"id":16575844}]}]}
{"op":"mcm","clk":"1002983808","pt":1580647523872,"mc":[{"id":"1.168224575","rc":[{"batb":[[1,4.6,38.41],[2,1.01,0.51]],"ltp":0.0,"tv":0.0,"id":13024648},{"batb":[[0,1.75,57.67],[1,1.73,105.71],[2,1.72,22.82]],"ltp":1.96,"tv":619.47,"id":13024647},{"batb":[[0,5.2,38.14],[1,5.1,44.68]],"ltp":0.0,"tv":0.0,"id":16575845},{"batb":[[0,8.4,16.29],[1,8.2,22.24],[2,7.6,10.46]],"ltp":3.15,"tv":66.14,"id":16575844}]}]}
{"op":"mcm","clk":"1002984879","pt":1580647529386,"mc":[{"id":"1.168224575","rc":[{"batb":[[0,4.7,15.82],[1,1.01,0.51],[2,1.01,0]],"ltp":0.0,"tv":0.0,"id":13024648},{"batb":[[0,5.1,13.3],[1,1.01,0.51],[2,1.01,0]],"ltp":0.0,"tv":0.0,"id":16575845},{"batb":[[0,7.6,10.46],[1,1.01,0.51],[2,7.6,0]],"ltp":3.15,"tv":66.14,"id":16575844}]}]}
{"op":"mcm","clk":"1002985479","pt":1580647532488,"mc":[{"id":"1.168224575","rc":[{"batb":[[0,4.9,23.17],[1,4.8,34.99],[2,4.7,15.82]],"ltp":0.0,"tv":0.0,"id":13024648},{"batb":[[0,5.4,18.69],[1,5.3,29.11],[2,5.1,13.3]],"ltp":0.0,"tv":0.0,"id":16575845},{"batb":[[0,15.5,9.46],[1,15,15.55],[2,7.6,10.46]],"ltp":3.15,"tv":66.14,"id":16575844}]}]}
{"op":"mcm","clk":"1002985675","pt":1580647533456,"mc":[{"id":"1.168224575","rc":[{"batb":[[0,4.9,37.65],[2,4.6,10.92]],"batl":[[0,5.4,9.24],[1,5.7,13.38],[2,5.8,12.59]],"ltp":0.0,"tv":0.0,"id":13024648},{"batb":[[0,1.76,54.61],[1,1.75,57.67],[2,1.73,105.71]],"batl":[[0,1.8,22.42],[1,1.86,19.91],[2,1.91,42.01]],"ltp":1.96,"tv":619.47,"id":13024647},{"batb":[[2,5.2,12.59]],"batl":[[0,5.8,8.4],[1,5.9,12.12],[2,6.2,11.33]],"ltp":0.0,"tv":0.0,"id":16575845},{"batb":[[2,13.5,7]],"batl":[[1,26,7.55]],"ltp":3.15,"tv":66.14,"id":16575844}]}]}
{"op":"mcm","clk":"1002987389","pt":1580647542285,"mc":[{"id":"1.168224575","rc":[{"batb":[[1,1.72,22.82],[2,1.65,26.44]],"ltp":1.96,"tv":619.47,"id":13024647}]}]}
{"op":"mcm","clk":"1002987963","pt":1580647545268,"mc":[{"id":"1.168224575","rc":[{"batb":[[1,1.74,109.29],[2,1.72,131.15]],"ltp":1.96,"tv":619.47,"id":13024647}]}]}
{"op":"mcm","clk":"1002988944","pt":1580647550289,"mc":[{"id":"1.168224575","rc":[{"batb":[[0,4.9,14.48]],"batl":[[1,5.8,12.59],[2,5.8,0]],"ltp":0.0,"tv":0.0,"id":13024648},{"batb":[[1,1.65,26.44],[2,1.01,0.51]],"batl":[[0,1.86,19.91],[1,1.91,42.01],[2,1.91,0]],"ltp":1.96,"tv":619.47,"id":13024647},{"batb":[[0,5.3,29.11],[1,5,13.45],[2,4.9,10.08]],"batl":[[1,6.2,11.33],[2,6.2,0]],"ltp":0.0,"tv":0.0,"id":16575845},{"batb":[[0,11.5,9.99],[1,1.01,0.51],[2,13.5,0]],"batl":[[0,26,7.55],[1,26,0]],"ltp":3.15,"tv":66.14,"id":16575844}]}]}
{"op":"mcm","clk":"1002989339","pt":1580647552107,"mc":[{"id":"1.168224575","rc":[{"batb":[[2,1.01,0.51]],"batl":[[0,5.8,12.59],[1,5.8,0]],"ltp":0.0,"tv":0.0,"id":13024648},{"batb":[[0,1.65,26.44],[1,1.01,0.51],[2,1.01,0]],"batl":[[1,1.91,0]],"ltp":1.96,"tv":619.47,"id":13024647},{"batb":[[2,1.01,0.51]],"batl":[[0,6.2,11.33],[1,6.2,0]],"ltp":0.0,"tv":0.0,"id":16575845}]}]}
{"op":"mcm","clk":"1002989477","pt":1580647552796,"mc":[{"id":"1.168224575","rc":[{"batb":[[2,4.7,36.5]],"ltp":0.0,"tv":0.0,"id":13024648},{"batb":[[0,1.68,106.77],[1,1.66,122.58],[2,1.65,26.44]],"ltp":1.96,"tv":619.47,"id":13024647},{"batb":[[1,5.2,30.34],[2,5,13.45]],"ltp":0.0,"tv":0.0,"id":16575845},{"batb":[[0,13.5,13.76],[1,13,20.79],[2,11.5,9.99]],"ltp":3.15,"tv":66.14,"id":16575844}]}]}
{"op":"mcm","clk":"1002991833","pt":1580647564485,"mc":[{"id":"1.168224575","rc":[{"batb":[[2,1.01,0.51]],"ltp":0.0,"tv":0.0,"id":13024648},{"batb":[[0,5,13.45],[1,1.01,0.51],[2,5,0]],"ltp":0.0,"tv":0.0,"id":16575845},{"batb":[[0,11.5,9.99],[1,1.01,0.51],[2,11.5,0]],"ltp":3.15,"tv":66.14,"id":16575844}]}]}
{"op":"mcm","clk":"1002992412","pt":1580647567358,"mc":[{"id":"1.168224575","rc":[{"batb":[[0,4.9,67.67]],"ltp":0.0,"tv":0.0,"id":13024648},{"batb":[[0,5.5,26.71],[1,5.4,27.78],[2,5,13.45]],"ltp":0.0,"tv":0.0,"id":16575845},{"batb":[[0,19.5,11.97],[1,19,9.52],[2,11.5,9.99]],"ltp":3.15,"tv":66.14,"id":16575844}]}]}
{"op":"mcm","clk":"1002992561","pt":1580647568050,"mc":[{"id":"1.168224575","rc":[{"batb":[[0,5.1,13.14],[1,4.9,67.2],[2,4.8,34.99]],"batl":[[1,6.2,11.72]],"ltp":0.0,"tv":0.0,"id":13024648},{"batl":[[0,1.72,25.89],[1,1.79,22.66]],"ltp":1.96,"tv":619.47,"id":13024647},{"batb":[[2,5.3,11.8]],"batl":[[1,6.4,10.46]],"ltp":0.0,"tv":0.0,"id":16575845},{"batb":[[2,17,4.17]],"ltp":3.15,"tv":66.14,"id":16575844}]}]}
{"op":"mcm","clk":"1002992801","pt":1580647569248,"mc":[{"id":"1.168224575","rc":[{"batl":[[0,5.4,9.24],[1,5.8,12.59],[2,6.2,11.72]],"ltp":0.0,"tv":0.0,"id":13024648},{"batb":[[0,1.71,58.81],[1,1.68,106.77],[2,1.66,122.58]],"batl":[[2,1.84,42.01]],"ltp":1.96,"tv":619.47,"id":13024647},{"batl":[[0,5.9,8.4],[1,6.2,11.33],[2,6.4,10.46]],"ltp":0.0,"tv":0.0,"id":16575845}]}]}
{"op":"mcm","clk":"1002993421","pt":1580647574186,"mc":[{"id":"1.168224575","rc":[{"trd":[[1.72,50.41]],"batl":[[0,1.79,23.34],[1,1.84,42.01],[2,1.84,0]],"ltp":1.72,"tv":669.88,"id":13024647}],"tv":736.03}]}
{"op":"mcm","clk":"1002993956","pt":1580647575181,"mc":[{"id":"1.168224575","rc":[{"trd":[[1.72,51.77]],"batb":[[0,1.72,24.53],[1,1.71,58.81],[2,1.68,75.59]],"batl":[[0,1.79,22.66]],"ltp":1.72,"tv":671.24,"id":13024647},{"batb":[[0,19.5,9.24],[1,17,4.17],[2,14,6.61]],"ltp":3.15,"tv":66.14,"id":16575844}],"tv":737.39}]}
{"op":"mcm","clk":"1002994226","pt":1580647576452,"mc":[{"id":"1.168224575","rc":[{"batb":[[0,1.71,58.81],[1,1.68,75.59],[2,1.66,122.58]],"ltp":1.72,"tv":671.24,"id":13024647}]}]}
{"op":"mcm","clk":"1002994605","pt":1580647578458,"mc":[{"id":"1.168224575","rc":[{"batb":[[0,5.5,43.97]],"ltp":0.0,"tv":0.0,"id":16575845},{"batb":[[0,20,6.81],[1,19.5,9.24],[2,17,4.17]],"ltp":3.15,"tv":66.14,"id":16575844}]}]}
{"op":"mcm","clk":"1002994782","pt":1580647579457,"mc":[{"id":"1.168224575","rc":[{"batb":[[0,4.9,37.11],[1,4.8,34.99],[2,4.6,10.92]],"batl":[[1,6.2,11.72],[2,6.2,0]],"ltp":0.0,"tv":0.0,"id":13024648},{"batb":[[1,1.57,31.39],[2,1.01,0.51]],"ltp":1.72,"tv":671.24,"id":13024647},{"batb":[[0,5.4,27.78],[1,5.2,12.59],[2,5,10.08]],"batl":[[1,6.4,10.46],[2,6.4,0]],"ltp":0.0,"tv":0.0,"id":16575845},{"batb":[[0,14,6.61],[1,1.01,0.51],[2,17,0]],"ltp":3.15,"tv":66.14,"id":16575844}]}]}
{"op":"mcm","clk":"1002994938","pt":1580647580268,"mc":[{"id":"1.168224575","rc":[{"batb":[[2,1.01,0.51]],"batl":[[0,6.2,11.72],[1,6.2,0]],"ltp":0.0,"tv":0.0,"id":13024648},{"batb":[[0,1.57,31.39],[1,1.01,0.51],[2,1.01,0]],"batl":[[1,1.84,0]],"ltp":1.72,"tv":671.24,"id":13024647},{"batb":[[2,1.01,0.51]],"batl":[[0,6.4,10.46],[1,6.4,0]],"ltp":0.0,"tv":0.0,"id":16575845}]}]}
{"op":"mcm","clk":"1002995405","pt":1580647582476,"mc":[{"id":"1.168224575","rc":[{"batl":[[0,6,11.88]],"ltp":0.0,"tv":0.0,"id":13024648},{"batb":[[0,1.59,30.61]],"batl":[[0,1.81,22.03]],"ltp":1.72,"tv":671.24,"id":13024647},{"batb":[[0,5.4,45.6],[1,5.3,28.98],[2,5.1,12.9]],"ltp":0.0,"tv":0.0,"id":16575845},{"batb":[[0,16,17.74],[1,15.5,14.48],[2,14,6.61]],"ltp":3.15,"tv":66.14,"id":16575844}]}]}
{"op":"mcm","clk":"1002995986","pt":1580647585393,"mc":[{"id":"1.168224575","rc":[{"batb":[[1,4.8,49.78]],"batl":[[0,5.6,13.61],[1,5.9,12.51],[2,6,11.88]],"ltp":0.0,"tv":0.0,"id":13024648},{"batb":[[0,1.74,22.42],[1,1.73,66.6],[2,1.71,110.47]],"batl":[[1,1.89,19.28]],"ltp":1.72,"tv":671.24,"id":13024647},{"batl":[[0,5.9,12.43],[1,6,11.72],[2,6.4,10.46]],"ltp":0.0,"tv":0.0,"id":16575845},{"batl":[[0,19,6.37],[1,28,6.53]],"ltp":3.15,"tv":66.14,"id":16575844}]}]}
{"op":"mcm","clk":"1002996178","pt":1580647586367,"mc":[{"id":"1.168224575","rc":[{"batl":[[2,6,0]],"ltp":0.0,"tv":0.0,"id":13024648},{"batl":[[2,6.4,0]],"ltp":0.0,"tv":0.0,"id":16575845}]}]}
{"op":"mcm","clk":"1002996320","pt":1580647587093,"mc":[{"id":"1.168224575","rc":[{"batb":[[2,4.6,10.92]],"batl":[[0,5.4,9.24],[1,5.6,13.61],[2,5.9,12.51]],"ltp":0.0,"tv":0.0,"id":13024648},{"batb":[[1,1.73,123.73]],"ltp":1.72,"tv":671.24,"id":13024647},{"batl":[[0,5.9,20.83]],"ltp":0.0,"tv":0.0,"id":16575845}]}]}
{"op":"mcm","clk":"1002996561","pt":1580647588465,"mc":[{"id":"1.168224575","rc":[{"batl":[[1,1.87,42.01],[2,1.89,19.28]],"ltp":1.72,"tv":671.24,"id":13024647}]}]}
{"op":"mcm","clk":"1002997785","pt":1580647594482,"mc":[{"id":"1.168224575","rc":[{"batb":[[0,4.8,49.78],[1,4.6,10.92],[2,1.01,0.51]],"batl":[[1,5.9,12.51],[2,5.9,0]],"ltp":0.0,"tv":0.0,"id":13024648},{"batb":[[0,1.73,57.13],[1,1.65,26.75],[2,1.01,0.51]],"batl":[[0,1.87,42.01],[1,1.89,19.28],[2,1.89,0]],"ltp":1.72,"tv":671.24,"id":13024647},{"batb":[[0,5.4,20.56],[2,5,24.01]],"batl":[[0,5.9,8.4]],"ltp":0.0,"tv":0.0,"id":16575845},{"batb":[[0,11.5,10.46],[1,1.01,0.51],[2,14,0]],"batl":[[0,28,6.53],[1,28,0]],"ltp":3.15,"tv":66.14,"id":16575844}]}]}
{"op":"mcm","clk":"1002998129","pt":1580647596212,"mc":[{"id":"1.168224575","rc":[{"batb":[[1,1.01,0.51],[2,1.01,0]],"batl":[[0,5.9,12.51],[1,5.9,0]],"ltp":0.0,"tv":0.0,"id":13024648},{"batb":[[0,1.65,26.75],[1,1.01,0.51],[2,1.01,0]],"batl":[[0,1.89,19.28],[1,1.89,0]],"ltp":1.72,"tv":671.24,"id":13024647},{"batb":[[2,5,13.93]],"batl":[[0,6,11.72],[1,6,0]],"ltp":0.0,"tv":0.0,"id":16575845}]}]}
{"op":"mcm","clk":"1002998310","pt":1580647597218,"mc":[{"id":"1.168224575","rc":[{"batb":[[1,4.7,36.45],[2,1.01,0.51]],"ltp":0.0,"tv":0.0,"id":13024648},{"batb":[[0,1.66,79.59],[1,1.65,89.74],[2,1.01,0.51]],"ltp":1.72,"tv":671.24,"id":13024647},{"batb":[[0,13.5,23.44],[1,13,20.68],[2,11.5,10.46]],"ltp":3.15,"tv":66.14,"id":16575844}]}]}
{"op":"mcm","clk":"1002998478","pt":1580647598112,"mc":[{"id":"1.168224575","rc":[{"batl":[[0,5.8,12.59]],"ltp":0.0,"tv":0.0,"id":13024648},{"batl":[[0,6.2,11.64]],"ltp":0.0,"tv":0.0,"id":16575845},{"batb":[[2,11.5,10.31]],"batl":[[0,29,6.37]],"ltp":3.15,"tv":66.14,"id":16575844}]}]}
{"op":"mcm","clk":"1002999107","pt":1580647601293,"mc":[{"id":"1.168224575","rc":[{"batb":[[0,1.65,26.75],[1,1.01,0.51],[2,1.01,0]],"ltp":1.72,"tv":671.24,"id":13024647}]}]}
{"op":"mcm","clk":"1002999597","pt":1580647603699,"mc":[{"id":"1.168224575","rc":[{"batb":[[0,1.78,65.15],[1,1.76,100.21],[2,1.65,26.75]],"ltp":1.72,"tv":671.24,"id":13024647}]}]}
{"op":"mcm","clk":"1002999926","pt":1580647605403,"mc":[{"id":"1.168224575","rc":[{"batb":[[1,4.7,52.03],[2,4.6,10.92]],"batl":[[0,5.3,9.24],[1,5.5,14.24],[2,5.7,13.38]],"ltp":0.0,"tv":0.0,"id":13024648},{"batb":[[0,1.81,19.59],[1,1.78,65.15],[2,1.77,53.77]],"batl":[[1,1.91,42.01],[2,1.97,17]],"ltp":1.72,"tv":671.24,"id":13024647},{"batl":[[0,5.7,13.22],[1,5.8,8.4],[2,5.9,12.43]],"ltp":0.0,"tv":0.0,"id":16575845},{"batb":[[0,13.5,26.8]],"batl":[[0,15.5,9.52],[1,20,5.9]],"ltp":3.15,"tv":66.14,"id":16575844}]}]}
{"op":"mcm","clk":"1003002094","pt":1580647616398,"mc":[{"id":"1.168224575","rc":[{"batb":[[0,4.8,14.79]],"ltp":0.0,"tv":0.0,"id":13024648},{"batb":[[1,1.77,53.77],[2,1.73,22.98]],"ltp":1.72,"tv":671.24,"id":13024647},{"batb":[[0,5.3,28.98],[1,5,13.93],[2,4.9,24.64]],"ltp":0.0,"tv":0.0,"id":16575845},{"batb":[[0,13.5,3.36],[1,11.5,10.31],[2,10,14.32]],"ltp":3.15,"tv":66.14,"id":16575844}]}]}
{"op":"mcm","clk":"1003002172","pt":1580647616825,"mc":[{"id":"1.168224575","rc":[{"batb":[[0,4.7,52.03],[1,4.6,10.92],[2,1.01,0.51]],"batl":[[1,5.7,13.38],[2,5.7,0]],"ltp":0.0,"tv":0.0,"id":13024648},{"batb":[[0,1.77,53.77],[1,1.73,22.98],[2,1.01,0.51]],"batl":[[0,1.91,42.01],[1,1.97,17],[2,1.97,0]],"ltp":1.72,"tv":671.24,"id":13024647},{"batb":[[1,4.9,24.64],[2,1.01,0.51]],"batl":[[0,5.8,8.4],[1,5.9,12.43],[2,5.9,0]],"ltp":0.0,"tv":0.0,"id":16575845},{"batb":[[1,10,14.32],[2,1.01,0.51]],"batl":[[0,20,5.9],[1,20,0]],"ltp":3.15,"tv":66.14,"id":16575844}]}]}
{"op":"mcm","clk":"1003002503","pt":1580647618320,"mc":[{"id":"1.168224575","rc":[{"batb":[[1,1.01,0.51],[2,1.01,0]],"batl":[[0,5.7,13.38],[1,5.7,0]],"ltp":0.0,"tv":0.0,"id":13024648},{"batb":[[0,1.73,22.98],[1,1.01,0.51],[2,1.01,0]],"batl":[[0,1.97,17],[1,1.97,0]],"ltp":1.72,"tv":671.24,"id":13024647},{"batb":[[1,4.9,14.56]],"batl":[[0,5.9,12.43],[1,5.9,0]],"ltp":0.0,"tv":0.0,"id":16575845},{"batb":[[0,10,14.32],[1,1.01,0.51],[2,1.01,0]],"ltp":3.15,"tv":66.14,"id":16575844}]}]}
{"op":"mcm","clk":"1003002772","pt":1580647619491,"mc":[{"id":"1.168224575","rc":[{"batb":[[0,4.7,69.02],[1,4.6,38.04],[2,1.01,0.51]],"ltp":0.0,"tv":0.0,"id":13024648},{"batb":[[1,5.2,30.6],[2,4.9,14.56]],"ltp":0.0,"tv":0.0,"id":16575845},{"batb":[[0,12,25.97],[1,11.5,26.6],[2,10,14.32]],"ltp":3.15,"tv":66.14,"id":16575844}]}]}
{"op":"mcm","clk":"1003003572","pt":1580647623472,"mc":[{"id":"1.168224575","rc":[{"batb":[[1,4.6,54.25],[2,4.5,11.76]],"batl":[[0,5.3,9.24],[1,5.4,14.95],[2,5.5,14.32]],"ltp":0.0,"tv":0.0,"id":13024648},{"batb":[[0,1.89,17.31],[1,1.82,87.88],[2,1.81,19.59]],"batl":[[0,1.93,42.01],[1,1.97,17],[2,2.04,15.5]],"ltp":1.72,"tv":671.24,"id":13024647},{"batb":[[0,5.2,30.6],[1,5,10.08]],"batl":[[0,5.6,13.93],[1,5.7,13.06],[2,5.8,8.4]],"ltp":0.0,"tv":0.0,"id":16575845},{"batb":[[0,12.5,3.36],[1,12,25.97],[2,11.5,26.6]],"batl":[[0,13,13.06],[1,15,9.91]],"ltp":3.15,"tv":66.14,"id":16575844}]}]}
{"op":"mcm","clk":"1003004037","pt":1580647625434,"mc":[{"id":"1.168224575","rc":[{"batl":[[0,1.97,17],[1,2.04,15.5],[2,2.04,0]],"ltp":1.72,"tv":671.24,"id":13024647},{"batb":[[1,4.9,14.56],[2,4.8,15.19]],"ltp":0.0,"tv":0.0,"id":16575845},{"batb":[[0,12,25.97],[1,11.5,26.6],[2,10,14.32]],"ltp":3.15,"tv":66.14,"id":16575844}]}]}
{"op":"mcm","clk":"1003004141","pt":1580647625931,"mc":[{"id":"1.168224575","rc":[{"batb":[[0,5.2,48.75],[1,5.1,31.5],[2,4.9,14.56]],"ltp":0.0,"tv":0.0,"id":16575845}]}]}
{"op":"mcm","clk":"1003004692","pt":1580647628453,"mc":[{"id":"1.168224575","rc":[{"batl":[[0,1.94,42.01],[1,1.97,17],[2,2.04,15.5]],"ltp":1.72,"tv":671.24,"id":13024647},{"batb":[[2,4.9,24.64]],"ltp":0.0,"tv":0.0,"id":16575845},{"batb":[[0,12,29.33]],"ltp":3.15,"tv":66.14,"id":16575844}]}]}
{"op":"mcm","clk":"1003005497","pt":1580647632439,"mc":[{"id":"1.168224575","rc":[{"batb":[[0,4.7,57.67]],"ltp":0.0,"tv":0.0,"id":13024648},{"batb":[[1,1.81,19.59],[2,1.8,52.09]],"ltp":1.72,"tv":671.24,"id":13024647},{"batb":[[0,5.2,30.6]],"ltp":0.0,"tv":0.0,"id":16575845},{"batb":[[0,12,3.36],[1,11.5,11.32]],"ltp":3.15,"tv":66.14,"id":16575844}]}]}
{"op":"mcm","clk":"1003005653","pt":1580647633054,"mc":[{"id":"1.168224575","rc":[{"batb":[[0,4.7,42.09]],"batl":[[1,5.5,14.32],[2,5.5,0]],"ltp":0.0,"tv":0.0,"id":13024648},{"batb":[[0,1.81,19.59],[1,1.8,52.09],[2,1.01,0.51]],"batl":[[1,2.04,15.5],[2,2.04,0]],"ltp":1.72,"tv":671.24,"id":13024647},{"batb":[[2,4.9,10.08]],"batl":[[0,5.7,13.06],[1,5.8,8.4],[2,5.8,0]],"ltp":0.0,"tv":0.0,"id":16575845},{"batb":[[2,9.4,6.92]],"batl":[[0,15,9.91],[1,15,0]],"ltp":3.15,"tv":66.14,"id":16575844}]}]}
{"op":"mcm","clk":"1003005958","pt":1580647634342,"mc":[{"id":"1.168224575","rc":[{"batb":[[2,1.01,0.51]],"batl":[[0,5.5,14.32],[1,5.5,0]],"ltp":0.0,"tv":0.0,"id":13024648},{"batb":[[1,1.01,0.51],[2,1.01,0]],"batl":[[0,2.04,15.5],[1,2.04,0]],"ltp":1.72,"tv":671.24,"id":13024647},{"batb":[[2,4.8,15.19]],"batl":[[1,5.8,0]],"ltp":0.0,"tv":0.0,"id":16575845},{"batb":[[0,11.5,11.32],[1,9.4,6.92],[2,1.01,0.51]],"ltp":3.15,"tv":66.14,"id":16575844}]}]}
{"op":"mcm","clk":"1003006190","pt":1580647635454,"mc":[{"id":"1.168224575","rc":[{"batb":[[1,1.78,74.46],[2,1.76,100.25]],"ltp":1.72,"tv":671.24,"id":13024647},{"batb":[[1,11,29.65],[2,9.4,6.92]],"ltp":3.15,"tv":66.14,"id":16575844}]}]}
{"op":"mcm","clk":"1003006352","pt":1580647636261,"mc":[{"id":"1.168224575","rc":[{"batb":[[0,1.8,20.14]],"batl":[[0,2.02,15.97]],"ltp":1.72,"tv":671.24,"id":13024647},{"batb":[[2,1.01,0.51]],"batl":[[0,5.9,12.35]],"ltp":0.0,"tv":0.0,"id":16575845},{"batb":[[2,9.4,16.37]],"batl":[[0,15.5,9.44]],"ltp":3.15,"tv":66.14,"id":16575844}]}]}
{"op":"mcm","clk":"1003007306","pt":1580647641360,"mc":[{"id":"1.168224575","rc":[{"batb":[[1,1.01,0.51],[2,1.76,0]],"ltp":1.72,"tv":671.24,"id":13024647}]}]}
{"op":"mcm","clk":"1003007946","pt":1580647644440,"mc":[{"id":"1.168224575","rc":[{"batb":[[2,4.5,17.47]],"batl":[[0,5.2,15.82],[1,5.4,14.95],[2,5.5,14.32]],"ltp":0.0,"tv":0.0,"id":13024648},{"batb":[[0,1.93,16.21],[1,1.86,62.12],[2,1.84,86.61]],"batl":[[1,2.22,24.39]],"ltp":1.72,"tv":671.24,"id":13024647},{"batb":[[2,4.8,14.95]],"batl":[[0,5.6,13.61],[1,5.9,12.35]],"ltp":0.0,"tv":0.0,"id":16575845},{"batl":[[0,12,14.79],[1,15.5,9.44],[2,16.5,8.26]],"ltp":3.15,"tv":66.14,"id":16575844}]}]}
{"op":"mcm","clk":"1003008022","pt":1580647644850,"mc":[{"id":"1.168224575","rc":[{"batb":[[2,4.5,29.23]],"batl":[[1,5.3,9.24],[2,5.4,14.95]],"ltp":0.0,"tv":0.0,"id":13024648},{"batb":[[2,1.84,136.18]],"batl":[[0,2,42.01],[1,2.02,15.97],[2,2.22,24.39]],"ltp":1.72,"tv":671.24,"id":13024647},{"batb":[[2,4.8,25.87]],"batl":[[0,5.6,22.01],[1,5.9,0]],"ltp":0.0,"tv":0.0,"id":16575845},{"batb":[[0,11.5,14.68]],"batl":[[1,16.5,8.26],[2,16.5,0]],"ltp":3.15,"tv":66.14,"id":16575844}]}]}
{"op":"mcm","clk":"1003009604","pt":1580647652926,"mc":[{"id":"1.168224575","rc":[{"batl":[[0,5.3,24.98],[1,5.4,14.95],[2,5.4,0]],"ltp":0.0,"tv":0.0,"id":13024648},{"batb":[[0,1.91,16.68]],"batl":[[0,1.99,16.37],[1,2,42.01],[2,2.2,25.26]],"ltp":1.72,"tv":671.24,"id":13024647},{"batb":[[2,9.8,15.03]],"batl":[[0,12.5,13.69],[1,17.5,7.63]],"ltp":3.15,"tv":66.14,"id":16575844}]}]}
{"op":"mcm","clk":"1003015050","pt":1580647680464,"mc":[{"id":"1.168224575","rc":[{"batb":[[0,11.5,3.36]],"ltp":3.15,"tv":66.14,"id":16575844}]}]}
{"op":"mcm","clk":"1003015670","pt":1580647683463,"mc":[{"id":"1.168224575","rc":[{"batb":[[1,11,38.37],[2,10.5,23.96]],"ltp":3.15,"tv":66.14,"id":16575844}]}]}
{"op":"mcm","clk":"1003016554","pt":1580647687998,"mc":[{"id":"1.168224575","rc":[{"batl":[[0,5.2,15.97],[1,5.3,9.24],[2,5.4,14.95]],"ltp":0.0,"tv":0.0,"id":13024648},{"batb":[[0,1.89,17.15]],"batl":[[0,1.97,16.92],[2,2.16,26.12]],"ltp":1.72,"tv":671.24,"id":13024647},{"batb":[[2,4.9,14.4]],"batl":[[0,5.6,8.4],[1,5.7,13.06]],"ltp":0.0,"tv":0.0,"id":16575845},{"batl":[[0,13,12.83],[1,18,7.08]],"ltp":3.15,"tv":66.14,"id":16575844}]}]}
{"op":"mcm","clk":"1003018049","pt":1580647695511,"mc":[{"id":"1.168224575","rc":[{"batb":[[0,4.7,36.45]],"ltp":0.0,"tv":0.0,"id":13024648},{"batb":[[1,1.84,49.57],[2,1.79,20.3]],"ltp":1.72,"tv":671.24,"id":13024647},{"batb":[[1,11,29.69],[2,10,14.01]],"ltp":3.15,"tv":66.14,"id":16575844}]}]}
{"op":"mcm","clk":"1003018744","pt":1580647699317,"mc":[{"id":"1.168224575","rc":[{"batb":[[2,4.5,11.76]],"batl":[[1,5.3,24.59],[2,5.4,0]],"ltp":0.0,"tv":0.0,"id":13024648},{"batb":[[0,1.88,17.55],[1,1.85,82.31],[2,1.84,49.57]],"batl":[[0,1.96,17.23],[2,2.14,26.67]],"ltp":1.72,"tv":671.24,"id":13024647},{"batb":[[0,5.2,42.1],[2,5,13.77]],"batl":[[1,5.8,12.51]],"ltp":0.0,"tv":0.0,"id":16575845},{"batb":[[0,11.5,18.57],[2,10,13.45]],"batl":[[0,13.5,12.27],[1,18.5,6.85]],"ltp":3.15,"tv":66.14,"id":16575844}]}]}
{"op":"mcm","clk":"1003023673","pt":1580647725462,"mc":[{"id":"1.168224575","rc":[{"batb":[[0,4.6,54.25],[1,4.5,11.76],[2,4.4,18.02]],"ltp":0.0,"tv":0.0,"id":13024648},{"batb":[[1,1.84,49.57],[2,1.78,20.77]],"ltp":1.72,"tv":671.24,"id":13024647},{"batb":[[0,5.1,31.5],[1,5,13.77],[2,4.8,10.92]],"ltp":0.0,"tv":0.0,"id":16575845},{"batb":[[0,11.5,3.36],[1,10,13.45],[2,7.8,10.46]],"ltp":3.15,"tv":66.14,"id":16575844}]}]}
{"op":"mcm","clk":"1003023752","pt":1580647725901,"mc":[{"id":"1.168224575","rc":[{"batb":[[0,4.6,38.04],[1,4.4,18.02],[2,1.01,0.51]],"batl":[[0,5.3,15.34],[1,5.3,0]],"ltp":0.0,"tv":0.0,"id":13024648},{"batb":[[0,1.78,20.77],[1,1.01,0.51],[2,1.78,0]],"batl":[[0,2.14,26.67],[1,2,0],[2,2.14,0]],"ltp":1.72,"tv":671.24,"id":13024647},{"batb":[[2,1.01,0.51]],"batl":[[0,5.8,12.51],[1,5.8,0]],"ltp":0.0,"tv":0.0,"id":16575845},{"batb":[[0,7.8,10.46],[1,1.01,0.51],[2,7.8,0]],"batl":[[0,18.5,6.85],[1,18.5,0]],"ltp":3.15,"tv":66.14,"id":16575844}]}]}
{"op":"mcm","clk":"1003024022","pt":1580647727382,"mc":[{"id":"1.168224575","rc":[{"batb":[[0,4.4,18.02],[1,1.01,0.51],[2,1.01,0]],"ltp":0.0,"tv":0.0,"id":13024648},{"batb":[[0,5,13.77],[1,1.01,0.51],[2,1.01,0]],"ltp":0.0,"tv":0.0,"id":16575845}]}]}
{"op":"mcm","clk":"1003024218","pt":1580647728477,"mc":[{"id":"1.168224575","rc":[{"batb":[[0,4.5,40.38],[1,4.4,18.02],[2,1.01,0.51]],"ltp":0.0,"tv":0.0,"id":13024648},{"batb":[[1,1.77,86.76],[2,1.75,102.3]],"ltp":1.72,"tv":671.24,"id":13024647},{"batb":[[0,5.1,19.33],[1,5,47],[2,1.01,0.51]],"ltp":0.0,"tv":0.0,"id":16575845},{"batb":[[0,8,36.19],[1,7.8,35.29],[2,1.01,0.51]],"ltp":3.15,"tv":66.14,"id":16575844}]}]}
{"op":"mcm","clk":"1003024383","pt":1580647729387,"mc":[{"id":"1.168224575","rc":[{"batb":[[0,4.4,18.02],[1,1.01,0.51],[2,1.01,0]],"ltp":0.0,"tv":0.0,"id":13024648},{"batb":[[0,5,13.77],[1,1.01,0.51],[2,1.01,0]],"ltp":0.0,"tv":0.0,"id":16575845},{"batb":[[0,7.8,10.46],[1,1.01,0.51],[2,1.01,0]],"ltp":3.15,"tv":66.14,"id":16575844}]}]}
{"op":"mcm","clk":"1003024578","pt":1580647730447,"mc":[{"id":"1.168224575","rc":[{"batb":[[0,4.8,22.51],[1,4.7,36.64],[2,4.4,18.02]],"ltp":0.0,"tv":0.0,"id":13024648},{"batb":[[0,5.3,25.12],[1,5.2,30.75],[2,5,13.77]],"ltp":0.0,"tv":0.0,"id":16575845},{"batb":[[0,15,15.14],[1,14.5,16.74],[2,7.8,10.46]],"ltp":3.15,"tv":66.14,"id":16575844}]}]}
{"op":"mcm","clk":"1003024734","pt":1580647731292,"mc":[{"id":"1.168224575","rc":[{"batb":[[1,4.7,52.69],[2,4.6,10.92]],"batl":[[0,5.3,24.59],[1,5.4,14.71]],"ltp":0.0,"tv":0.0,"id":13024648},{"batb":[[1,1.77,140.53]],"batl":[[0,1.86,20.38],[1,1.9,42.01],[2,2,16.29]],"ltp":1.72,"tv":671.24,"id":13024647},{"batb":[[2,5.1,13.06]],"batl":[[0,5.6,8.4],[1,5.8,12.51],[2,5.9,12.12]],"ltp":0.0,"tv":0.0,"id":16575845},{"batb":[[2,13.5,7.32]],"batl":[[1,26,7.55]],"ltp":3.15,"tv":66.14,"id":16575844}]}]}
{"op":"mcm","clk":"1003026872","pt":1580647743334,"mc":[{"id":"1.168224575","rc":[{"batb":[[0,4.7,22.06],[1,4.6,10.92],[2,4.5,17.07]],"batl":[[0,5.3,9.24]],"ltp":0.0,"tv":0.0,"id":13024648},{"batb":[[0,1.77,53.77],[1,1.71,23.68],[2,1.01,0.51]],"batl":[[0,1.9,42.01],[1,2,16.29],[2,2,0]],"ltp":1.72,"tv":671.24,"id":13024647},{"batb":[[0,5.2,30.75],[1,5,13.77],[2,4.8,10.92]],"batl":[[1,5.9,12.12],[2,5.9,0]],"ltp":0.0,"tv":0.0,"id":16575845},{"batb":[[0,9.6,15.74],[1,1.01,0.51],[2,13.5,0]],"batl":[[0,26,7.55],[1,26,0]],"ltp":3.15,"tv":66.14,"id":16575844}]}]}
{"op":"mcm","clk":"1003027064","pt":1580647744403,"mc":[{"id":"1.168224575","rc":[{"batb":[[1,4.5,17.07],[2,1.01,0.51]],"batl":[[0,5.4,14.71],[1,5.4,0]],"ltp":0.0,"tv":0.0,"id":13024648},{"batb":[[0,1.71,23.68],[1,1.01,0.51],[2,1.01,0]],"batl":[[0,2,16.29],[1,2,0]],"ltp":1.72,"tv":671.24,"id":13024647},{"batb":[[2,1.01,0.51]],"batl":[[0,5.9,12.12],[1,5.9,0]],"ltp":0.0,"tv":0.0,"id":16575845}]}]}
{"op":"mcm","clk":"1003027447","pt":1580647746401,"mc":[{"id":"1.168224575","rc":[{"batb":[[1,4.6,55.42],[2,4.5,17.07]],"ltp":0.0,"tv":0.0,"id":13024648},{"batb":[[0,1.71,123.06],[1,1.69,115.46],[2,1.01,0.51]],"batl":[[0,1.99,16.52],[1,2,16.29]],"ltp":1.72,"tv":671.24,"id":13024647},{"batb":[[1,5.1,32.11],[2,5,13.77]],"ltp":0.0,"tv":0.0,"id":16575845},{"batb":[[0,10.5,25.71],[1,10,35.71],[2,9.8,15.42]],"batl":[[1,27,7.16]],"ltp":3.15,"tv":66.14,"id":16575844}]}]}
{"op":"mcm","clk":"1003027557","pt":1580647747037,"mc":[{"id":"1.168224575","rc":[{"batb":[[2,1.01,0.51]],"ltp":0.0,"tv":0.0,"id":13024648},{"batl":[[1,2,0]],"ltp":1.72,"tv":671.24,"id":13024647},{"batb":[[2,5,13.61]],"ltp":0.0,"tv":0.0,"id":16575845},{"batl":[[0,27,7.16],[1,27,0]],"ltp":3.15,"tv":66.14,"id":16575844}]}]}
{"op":"mcm","clk":"1003028525","pt":1580647752343,"mc":[{"id":"1.168224575","rc":[{"batb":[[0,1.71,23.68],[1,1.01,0.51],[2,1.01,0]],"ltp":1.72,"tv":671.24,"id":13024647},{"batb":[[1,5,13.61],[2,1.01,0.51]],"ltp":0.0,"tv":0.0,"id":16575845},{"batb":[[0,9.8,15.42],[1,1.01,0.51],[2,9.8,0]],"ltp":3.15,"tv":66.14,"id":16575844}]}]}
{"op":"mcm","clk":"1003029069","pt":1580647755359,"mc":[{"id":"1.168224575","rc":[{"batb":[[0,4.7,52.14]],"ltp":0.0,"tv":0.0,"id":13024648},{"batb":[[0,1.79,95.22],[1,1.77,98.49],[2,1.71,23.68]],"ltp":1.72,"tv":671.24,"id":13024647},{"batb":[[0,5.3,19.15],[1,5.2,30.75],[2,5,13.61]],"ltp":0.0,"tv":0.0,"id":16575845},{"batb":[[0,14,10.17],[1,13.5,19.57],[2,9.8,15.42]],"ltp":3.15,"tv":66.14,"id":16575844}]}]}
{"op":"mcm","clk":"1003029195","pt":1580647756139,"mc":[{"id":"1.168224575","rc":[{"batb":[[0,5.2,30.75],[1,5,13.61],[2,1.01,0.51]],"ltp":0.0,"tv":0.0,"id":16575845}]}]}
{"op":"mcm","clk":"1003029732","pt":1580647759153,"mc":[{"id":"1.168224575","rc":[{"batb":[[0,5.2,49.98],[1,5.1,31.75],[2,5,13.61]],"ltp":0.0,"tv":0.0,"id":16575845}]}]}
{"op":"mcm","clk":"1003029921","pt":1580647760065,"mc":[{"id":"1.168224575","rc":[{"batb":[[0,4.7,22.22]],"ltp":0.0,"tv":0.0,"id":13024648},{"batb":[[0,1.71,23.68],[1,1.01,0.51],[2,1.71,0]],"ltp":1.72,"tv":671.24,"id":13024647},{"batb":[[0,5.2,30.75]],"ltp":0.0,"tv":0.0,"id":16575845},{"batb":[[0,9.8,15.42],[1,1.01,0.51],[2,9.8,0]],"ltp":3.15,"tv":66.14,"id":16575844}]}]}
{"op":"mcm","clk":"1003030543","pt":1580647763479,"mc":[{"id":"1.168224575","rc":[{"batb":[[1,4.6,16.92]],"ltp":0.0,"tv":0.0,"id":13024648},{"batb":[[0,1.71,123.74],[1,1.69,115.46],[2,1.01,0.51]],"ltp":1.72,"tv":671.24,"id":13024647},{"batb":[[1,5,13.61],[2,1.01,0.51]],"ltp":0.0,"tv":0.0,"id":16575845}]}]}
{"op":"mcm","clk":"1003031274","pt":1580647767491,"mc":[{"id":"1.168224575","rc":[{"batb":[[0,4.8,59.09],[1,4.7,36.29],[2,4.6,27.13]],"batl":[[0,5.4,23.96],[1,5.6,14.01]],"ltp":0.0,"tv":0.0,"id":13024648},{"batb":[[0,1.71,182.56],[2,1.66,26.52]],"batl":[[0,1.78,23.37],[1,1.85,42.01],[2,1.88,19.75]],"ltp":1.72,"tv":671.24,"id":13024647},{"batb":[[0,5.3,41.46],[1,5.2,43.42],[2,5,13.61]],"batl":[[0,5.7,8.4],[1,5.9,12.12],[2,6,11.72]],"ltp":0.0,"tv":0.0,"id":16575845},{"batb":[[0,20,5.07],[1,19.5,9.31],[2,17.5,7.95]],"batl":[[0,26,7.24]],"ltp":3.15,"tv":66.14,"id":16575844}]}]}
{"op":"mcm","clk":"1003034007","pt":1580647782487,"mc":[{"id":"1.168224575","rc":[{"batb":[[0,4.7,36.29],[1,4.6,27.13],[2,1.01,0.51]],"batl":[[0,5.4,9.24]],"ltp":0.0,"tv":0.0,"id":13024648},{"batb":[[0,1.71,58.81],[1,1.66,26.52],[2,1.01,0.51]],"batl":[[0,1.85,42.01],[1,1.88,19.75],[2,1.88,0]],"ltp":1.72,"tv":671.24,"id":13024647},{"batb":[[0,5.2,30.75],[1,5,13.61],[2,4.8,10.92]],"batl":[[1,6,11.72],[2,6,0]],"ltp":0.0,"tv":0.0,"id":16575845},{"batb":[[0,13,7.63],[1,1.01,0.51],[2,17.5,0]],"ltp":3.15,"tv":66.14,"id":16575844}]}]}
{"op":"mcm","clk":"1003034326","pt":1580647784184,"mc":[{"id":"1.168224575","rc":[{"batb":[[1,4.6,16.21]],"batl":[[0,5.6,14.01],[1,5.6,0]],"ltp":0.0,"tv":0.0,"id":13024648},{"batb":[[0,1.66,26.52],[1,1.01,0.51],[2,1.01,0]],"batl":[[0,1.88,19.75],[1,1.88,0]],"ltp":1.72,"tv":671.24,"id":13024647},{"batb":[[2,1.01,0.51]],"batl":[[0,6,11.72],[1,6,0]],"ltp":0.0,"tv":0.0,"id":16575845}]}]}
{"op":"mcm","clk":"1003034564","pt":1580647785403,"mc":[{"id":"1.168224575","rc":[{"batb":[[0,4.7,51.18],[1,4.6,54.23]],"ltp":0.0,"tv":0.0,"id":13024648},{"batb":[[0,1.67,113.83],[1,1.66,88.45],[2,1.01,0.51]],"ltp":1.72,"tv":671.24,"id":13024647},{"batb":[[1,5.1,31.95],[2,5,13.61]],"ltp":0.0,"tv":0.0,"id":16575845},{"batb":[[0,14.5,20.83],[1,14,17.81],[2,13,7.63]],"ltp":3.15,"tv":66.14,"id":16575844}]}]}
{"op":"mcm","clk":"1003034758","pt":1580647786434,"mc":[{"id":"1.168224575","rc":[{"batb":[[0,4.7,36.39],[1,4.6,16.21]],"ltp":0.0,"tv":0.0,"id":13024648},{"batb":[[0,1.66,26.52],[1,1.01,0.51],[2,1.01,0]],"ltp":1.72,"tv":671.24,"id":13024647},{"batb":[[1,5,13.61],[2,1.01,0.51]],"ltp":0.0,"tv":0.0,"id":16575845},{"batb":[[0,13,7.63],[1,1.01,0.51],[2,13,0]],"ltp":3.15,"tv":66.14,"id":16575844}]}]}
{"op":"mcm","clk":"1003035283","pt":1580647789451,"mc":[{"id":"1.168224575","rc":[{"batb":[[0,4.8,38.05],[1,4.7,36.39],[2,4.6,16.21]],"ltp":0.0,"tv":0.0,"id":13024648},{"batb":[[0,1.73,64.94],[1,1.71,110.71],[2,1.66,26.52]],"ltp":1.72,"tv":671.24,"id":13024647},{"batb":[[0,5.3,34.42],[1,5.2,30.75],[2,5,13.61]],"ltp":0.0,"tv":0.0,"id":16575845},{"batb":[[0,18.5,10.89],[1,18,10.83],[2,13,7.63]],"ltp":3.15,"tv":66.14,"id":16575844}]}]}
{"op":"mcm","clk":"1003035936","pt":1580647792836,"mc":[{"id":"1.168224575","rc":[{"batb":[[0,4.7,36.39],[1,4.6,16.21],[2,1.01,0.51]],"ltp":0.0,"tv":0.0,"id":13024648},{"batb":[[0,1.66,26.52],[1,1.01,0.51],[2,1.66,0]],"ltp":1.72,"tv":671.24,"id":13024647},{"batb":[[0,5.2,30.75],[1,5,13.61],[2,1.01,0.51]],"ltp":0.0,"tv":0.0,"id":16575845},{"batb":[[0,13,7.63],[1,1.01,0.51],[2,13,0]],"ltp":3.15,"tv":66.14,"id":16575844}]}]}
{"op":"mcm","clk":"1003036583","pt":1580647796343,"mc":[{"id":"1.168224575","rc":[{"batb":[[0,4.7,51.43],[1,4.6,54.23]],"ltp":0.0,"tv":0.0,"id":13024648},{"batb":[[0,1.67,111.71],[1,1.66,88.45],[2,1.01,0.51]],"ltp":1.72,"tv":671.24,"id":13024647},{"batb":[[1,5.1,31.96],[2,5,13.61]],"ltp":0.0,"tv":0.0,"id":16575845},{"batb":[[0,14.5,21.72],[1,14,17.81],[2,13,7.63]],"ltp":3.15,"tv":66.14,"id":16575844}]}]}
{"op":"mcm","clk":"1003036773","pt":1580647797240,"mc":[{"id":"1.168224575","rc":[{"batb":[[0,4.6,16.21],[1,1.01,0.51],[2,1.01,0]],"ltp":0.0,"tv":0.0,"id":13024648},{"batb":[[0,5,13.61],[1,1.01,0.51],[2,5,0]],"ltp":0.0,"tv":0.0,"id":16575845},{"batb":[[0,13,7.63],[1,1.01,0.51],[2,13,0]],"ltp":3.15,"tv":66.14,"id":16575844}]}]}
{"op":"mcm","clk":"1003037323","pt":1580647800354,"mc":[{"id":"1.168224575","rc":[{"batb":[[0,4.9,25.27],[1,4.8,34.88],[2,4.6,16.21]],"ltp":0.0,"tv":0.0,"id":13024648},{"batb":[[0,5.4,31.87],[1,5.3,29.37],[2,5,13.61]],"ltp":0.0,"tv":0.0,"id":16575845},{"batb":[[0,24,13.13],[1,23,12.72],[2,13,7.63]],"ltp":3.15,"tv":66.14,"id":16575844}]}]}
{"op":"mcm","clk":"1003037503","pt":1580647801322,"mc":[{"id":"1.168224575","rc":[{"batb":[[2,4.7,26.58]],"batl":[[0,5.5,9.24],[1,5.6,14.01],[2,5.7,13.45]],"ltp":0.0,"tv":0.0,"id":13024648},{"batb":[[0,1.68,61.33],[1,1.67,111.71],[2,1.66,88.45]],"batl":[[0,1.73,25.97],[1,1.79,22.74],[2,1.81,42.01]],"ltp":1.72,"tv":671.24,"id":13024647},{"batb":[[1,5.3,41.57],[2,5.1,13.3]],"batl":[[0,5.8,8.4],[1,6,11.72],[2,6.2,11.09]],"ltp":0.0,"tv":0.0,"id":16575845},{"batb":[[2,21,4.48]],"ltp":3.15,"tv":66.14,"id":16575844}]}]}
{"op":"mcm","clk":"1003040283","pt":1580647816483,"mc":[{"id":"1.168224575","rc":[{"batb":[[0,4.8,34.88],[1,4.7,15.66],[2,1.01,0.51]],"batl":[[0,5.7,13.45],[1,5.6,0],[2,5.7,0]],"ltp":0.0,"tv":0.0,"id":13024648},{"batb":[[0,1.62,28.56],[1,1.01,0.51],[2,1.66,0]],"batl":[[0,1.79,22.74],[1,1.79,0],[2,1.81,0]],"ltp":1.72,"tv":671.24,"id":13024647},{"batb":[[0,5.3,19.44],[1,5.1,13.3],[2,1.01,0.51]],"batl":[[0,6.2,11.09],[1,6,0],[2,6.2,0]],"ltp":0.0,"tv":0.0,"id":16575845},{"batb":[[0,18,7.55],[1,1.01,0.51],[2,21,0]],"ltp":3.15,"tv":66.14,"id":16575844}]}]}
{"op":"mcm","clk":"1003040762","pt":1580647819317,"mc":[{"id":"1.168224575","rc":[{"batb":[[1,4.7,52.05]],"ltp":0.0,"tv":0.0,"id":13024648},{"batb":[[0,1.65,99.38],[1,1.64,64.59],[2,1.62,28.56]],"batl":[[0,1.8,22.74]],"ltp":1.72,"tv":671.24,"id":13024647},{"batb":[[1,5.2,30.83],[2,5.1,13.3]],"ltp":0.0,"tv":0.0,"id":16575845},{"batb":[[0,20,20.12],[1,19.5,8.97],[2,18,7.55]],"ltp":3.15,"tv":66.14,"id":16575844}]}]}
{"op":"mcm","clk":"1003040970","pt":1580647820654,"mc":[{"id":"1.168224575","rc":[{"batb":[[1,4.7,15.66]],"ltp":0.0,"tv":0.0,"id":13024648},{"batb":[[0,1.62,28.56],[1,1.01,0.51],[2,1.62,0]],"ltp":1.72,"tv":671.24,"id":13024647},{"batb":[[1,5.1,13.3],[2,1.01,0.51]],"ltp":0.0,"tv":0.0,"id":16575845},{"batb":[[0,18,7.55],[1,1.01,0.51],[2,18,0]],"ltp":3.15,"tv":66.14,"id":16575844}]}]}
{"op":"mcm","clk":"1003041622","pt":1580647824101,"mc":[{"id":"1.168224575","rc":[{"batb":[[0,4.9,20.69],[1,4.8,34.88],[2,4.7,15.66]],"ltp":0.0,"tv":0.0,"id":13024648},{"trd":[[1.68,12]],"batb":[[0,1.68,94.29],[1,1.67,60.59],[2,1.62,28.56]],"ltp":1.68,"tv":683.24,"id":13024647},{"batb":[[0,5.4,23.46],[1,5.3,29.49],[2,5.1,13.3]],"ltp":0.0,"tv":0.0,"id":16575845},{"batb":[[0,23,15.66],[1,22,13.82],[2,18,7.55]],"ltp":3.15,"tv":66.14,"id":16575844}],"tv":749.39}]}
{"op":"mcm","clk":"1003042029","pt":1580647826411,"mc":[{"id":"1.168224575","rc":[{"batb":[[0,4.8,34.88],[1,4.7,15.66],[2,1.01,0.51]],"ltp":0.0,"tv":0.0,"id":13024648},{"batb":[[0,1.62,28.56],[1,1.01,0.51],[2,1.62,0]],"ltp":1.68,"tv":683.24,"id":13024647},{"batb":[[0,5.3,19.7],[1,5.1,13.3],[2,1.01,0.51]],"ltp":0.0,"tv":0.0,"id":16575845},{"batb":[[0,18,7.55],[1,1.01,0.51],[2,18,0]],"ltp":3.15,"tv":66.14,"id":16575844}]}]}
{"op":"mcm","clk":"1003042591","pt":1580647829195,"mc":[{"id":"1.168224575","rc":[{"batb":[[1,4.7,52.05]],"ltp":0.0,"tv":0.0,"id":13024648},{"batb":[[0,1.65,98.21],[1,1.64,64.59],[2,1.62,28.56]],"ltp":1.68,"tv":683.24,"id":13024647},{"batb":[[1,5.2,30.83],[2,5.1,13.3]],"ltp":0.0,"tv":0.0,"id":16575845},{"batb":[[0,20,20.18],[1,19.5,8.97],[2,18,7.55]],"ltp":3.15,"tv":66.14,"id":16575844}]}]}
{"op":"mcm","clk":"1003043256","pt":1580647833024,"mc":[{"id":"1.168224575","rc":[{"batb":[[0,1.62,28.56],[1,1.01,0.51],[2,1.62,0]],"ltp":1.68,"tv":683.24,"id":13024647}]}]}
{"op":"mcm","clk":"1003043851","pt":1580647836373,"mc":[{"id":"1.168224575","rc":[{"batb":[[2,4.6,16.37]],"batl":[[0,5.4,14.95],[1,5.5,14.32]],"ltp":0.0,"tv":0.0,"id":13024648},{"batb":[[0,1.72,86.38],[1,1.7,112.99],[2,1.67,25.89]],"batl":[[1,1.89,19.36]],"ltp":1.68,"tv":683.24,"id":13024647},{"batl":[[0,5.8,12.83],[1,5.9,12.27]],"ltp":0.0,"tv":0.0,"id":16575845},{"batl":[[0,27,6.85]],"ltp":3.15,"tv":66.14,"id":16575844}]}]}
{"op":"mcm","clk":"1003043959","pt":1580647836937,"mc":[{"id":"1.168224575","rc":[{"batb":[[2,4.6,27.29]],"batl":[[0,5.4,24.19]],"ltp":0.0,"tv":0.0,"id":13024648},{"batb":[[1,1.71,58.81],[2,1.7,112.99]],"batl":[[1,1.84,42.01],[2,1.89,19.36]],"ltp":1.68,"tv":683.24,"id":13024647},{"batl":[[0,5.6,8.4],[1,5.8,12.83],[2,5.9,12.27]],"ltp":0.0,"tv":0.0,"id":16575845}]}]}
{"op":"mcm","clk":"1003044460","pt":1580647839755,"mc":[{"id":"1.168224575","rc":[{"batb":[[1,1.7,112.99],[2,1.67,25.89]],"batl":[[1,1.89,19.36],[2,1.89,0]],"ltp":1.68,"tv":683.24,"id":13024647}]}]}
{"op":"mcm","clk":"1003044981","pt":1580647842840,"mc":[{"id":"1.168224575","rc":[{"batb":[[0,1.72,144.35]],"batl":[[1,1.85,42.01],[2,1.89,19.36]],"ltp":1.68,"tv":683.24,"id":13024647}]}]}
{"op":"mcm","clk":"1003047233","pt":1580647855377,"mc":[{"id":"1.168224575","rc":[{"batb":[[0,4.7,36.39],[1,4.6,27.29],[2,1.01,0.51]],"batl":[[0,5.4,9.24]],"ltp":0.0,"tv":0.0,"id":13024648},{"batb":[[0,1.72,57.97],[1,1.67,25.89],[2,1.01,0.51]],"batl":[[0,1.85,42.01],[1,1.89,19.36],[2,1.89,0]],"ltp":1.68,"tv":683.24,"id":13024647},{"batb":[[0,4.9,14.32],[1,4.7,10.92],[2,1.01,0.51]],"batl":[[1,5.9,12.27],[2,5.9,0]],"ltp":0.0,"tv":0.0,"id":16575845},{"batb":[[0,13.5,7.08],[1,1.01,0.51],[2,18,0]],"ltp":3.15,"tv":66.14,"id":16575844}]}]}
{"op":"mcm","clk":"1003047369","pt":1580647856028,"mc":[{"id":"1.168224575","rc":[{"batb":[[1,4.6,16.37]],"batl":[[0,5.5,14.32],[1,5.5,0]],"ltp":0.0,"tv":0.0,"id":13024648},{"batb":[[0,1.67,25.89],[1,1.01,0.51],[2,1.01,0]],"batl":[[0,1.89,19.36],[1,1.89,0]],"ltp":1.68,"tv":683.24,"id":13024647},{"batb":[[1,1.01,0.51],[2,1.01,0]],"batl":[[0,5.9,12.27],[1,5.9,0]],"ltp":0.0,"tv":0.0,"id":16575845}]}]}
{"op":"mcm","clk":"1003047814","pt":1580647858399,"mc":[{"id":"1.168224575","rc":[{"batb":[[0,4.7,47.17],[1,4.6,54.46]],"ltp":0.0,"tv":0.0,"id":13024648},{"batb":[[0,1.68,78.18],[1,1.67,25.89],[2,1.66,122.8]],"ltp":1.68,"tv":683.24,"id":13024647},{"batb":[[0,5.1,47.2],[1,5,33.26],[2,4.9,14.32]],"ltp":0.0,"tv":0.0,"id":16575845},{"batb":[[0,15.5,9.67],[1,15,15.81],[2,13.5,7.08]],"ltp":3.15,"tv":66.14,"id":16575844}]}]}
{"op":"mcm","clk":"1003048505","pt":1580647862199,"mc":[{"id":"1.168224575","rc":[{"batb":[[0,4.7,36.39],[1,4.6,16.37]],"ltp":0.0,"tv":0.0,"id":13024648},{"batb":[[0,4.9,14.32],[1,1.01,0.51],[2,4.9,0]],"ltp":0.0,"tv":0.0,"id":16575845},{"batb":[[0,13.5,7.08],[1,1.01,0.51],[2,13.5,0]],"ltp":3.15,"tv":66.14,"id":16575844}]}]}
{"op":"mcm","clk":"1003049051","pt":1580647865323,"mc":[{"id":"1.168224575","rc":[{"batb":[[0,4.8,68.87],[1,4.7,63.05],[2,4.6,16.37]],"batl":[[0,5.5,23.56],[1,5.7,13.53]],"ltp":0.0,"tv":0.0,"id":13024648},{"batb":[[1,1.67,88.06]],"batl":[[0,1.74,25.41],[1,1.79,22.9],[2,1.8,42.01]],"ltp":1.68,"tv":683.24,"id":13024647},{"batb":[[0,5.3,40.65],[1,5.2,43.28],[2,5,13.69]],"batl":[[0,5.7,8.4],[1,5.9,12.27],[2,6.2,11.33]],"ltp":0.0,"tv":0.0,"id":16575845},{"batb":[[0,25,12.86],[1,24,11.68],[2,22,3.82]],"ltp":3.15,"tv":66.14,"id":16575844}]}]}
{"op":"mcm","clk":"1003049084","pt":1580647865541,"mc":[{"id":"1.168224575","rc":[{"batb":[[2,1.01,0.51]],"ltp":0.0,"tv":0.0,"id":13024648}]}]}
{"op":"mcm","clk":"1003051587","pt":1580647880253,"mc":[{"id":"1.168224575","rc":[{"batb":[[0,1.67,88.06],[1,1.66,61.98],[2,1.61,29.35]],"ltp":1.68,"tv":683.24,"id":13024647},{"batb":[[0,5.3,29.68],[1,5.2,12.75]],"ltp":0.0,"tv":0.0,"id":16575845},{"batb":[[0,25,11.17],[1,22,3.82],[2,19,6.45]],"ltp":3.15,"tv":66.14,"id":16575844}]}]}
{"op":"mcm","clk":"1003052136","pt":1580647883458,"mc":[{"id":"1.168224575","rc":[{"batb":[[0,1.67,203.15]],"ltp":1.68,"tv":683.24,"id":13024647},{"batb":[[0,5.4,24.04],[1,5.3,29.68],[2,5.2,12.75]],"ltp":0.0,"tv":0.0,"id":16575845},{"batb":[[0,26,4.63],[1,25,11.17],[2,22,3.82]],"ltp":3.15,"tv":66.14,"id":16575844}]}]}
{"op":"mcm","clk":"1003052767","pt":1580647887371,"mc":[{"id":"1.168224575","rc":[{"batb":[[0,4.8,27.15]],"batl":[[0,5.5,9.24]],"ltp":0.0,"tv":0.0,"id":13024648},{"batb":[[0,1.67,62.17],[1,1.61,29.35],[2,1.01,0.51]],"batl":[[0,1.79,22.9],[1,1.8,42.01],[2,1.8,0]],"ltp":1.68,"tv":683.24,"id":13024647},{"batb":[[0,5.3,22.55],[1,5,13.69],[2,4.9,10.08]],"batl":[[1,6.2,11.33],[2,6.2,0]],"ltp":0.0,"tv":0.0,"id":16575845},{"batb":[[0,19,6.45],[1,1.01,0.51],[2,22,0]],"ltp":3.15,"tv":66.14,"id":16575844}]}]}
{"op":"mcm","clk":"1003052907","pt":1580647888199,"mc":[{"id":"1.168224575","rc":[{"batb":[[1,4.7,52.13]],"batl":[[0,5.7,13.53],[1,5.7,0]],"ltp":0.0,"tv":0.0,"id":13024648},{"batb":[[0,1.61,29.35],[1,1.01,0.51],[2,1.01,0]],"batl":[[1,1.8,0]],"ltp":1.68,"tv":683.24,"id":13024647},{"batb":[[2,1.01,0.51]],"batl":[[0,6.2,11.33],[1,6.2,0]],"ltp":0.0,"tv":0.0,"id":16575845}]}]}
{"op":"mcm","clk":"1003053201","pt":1580647889765,"mc":[{"id":"1.168224575","rc":[{"batb":[[0,1.62,123.65],[1,1.61,98.57],[2,1.01,0.51]],"ltp":1.68,"tv":683.24,"id":13024647},{"batb":[[1,5.2,31.02],[2,5,13.69]],"ltp":0.0,"tv":0.0,"id":16575845},{"batb":[[0,22,12.85],[1,21,15.51],[2,19,6.45]],"ltp":3.15,"tv":66.14,"id":16575844}]}]}
{"op":"mcm","clk":"1003054874","pt":1580647899574,"mc":[{"id":"1.168224575","rc":[{"batb":[[1,4.7,15.74]],"ltp":0.0,"tv":0.0,"id":13024648},{"batb":[[0,5,13.69],[1,1.01,0.51],[2,5,0]],"ltp":0.0,"tv":0.0,"id":16575845},{"batb":[[0,19,6.45],[1,1.01,0.51],[2,19,0]],"ltp":3.15,"tv":66.14,"id":16575844}]}]}
{"op":"mcm","clk":"1003055528","pt":1580647903290,"mc":[{"id":"1.168224575","rc":[{"batb":[[0,4.9,63.71],[1,4.8,42.26],[2,4.7,26.66]],"batl":[[0,5.5,9.24],[1,5.7,13.53],[2,5.9,12.51]],"ltp":0.0,"tv":0.0,"id":13024648},{"batb":[[0,1.64,65.54],[1,1.62,123.65],[2,1.61,98.57]],"batl":[[0,1.68,28.72],[1,1.73,25.57],[2,1.75,42.01]],"ltp":1.68,"tv":683.24,"id":13024647},{"batb":[[0,5.5,41.91],[1,5.4,28.17],[2,5.3,11.8]],"batl":[[0,5.9,8.4],[1,6.2,11.33],[2,6.4,10.46]],"ltp":0.0,"tv":0.0,"id":16575845},{"batb":[[0,34,3.7],[1,32,13.21],[2,29,2.51]],"ltp":3.15,"tv":66.14,"id":16575844}]}]}
{"op":"mcm","clk":"1003055578","pt":1580647903618,"mc":[{"id":"1.168224575","rc":[{"batb":[[2,4.7,10.92]],"ltp":0.0,"tv":0.0,"id":13024648}]}]}
{"op":"mcm","clk":"1003057669","pt":1580647915437,"mc":[{"id":"1.168224575","rc":[{"batb":[[0,4.9,36.91]],"ltp":0.0,"tv":0.0,"id":13024648},{"batb":[[1,1.61,29.35],[2,1.55,33.6]],"ltp":1.68,"tv":683.24,"id":13024647},{"batb":[[0,5.4,28.17],[1,5.3,11.8],[2,5.2,12.51]],"ltp":0.0,"tv":0.0,"id":16575845},{"batb":[[0,29,2.51],[1,23,3.41],[2,1.01,0.51]],"ltp":3.15,"tv":66.14,"id":16575844}]}]}
{"op":"mcm","clk":"1003057760","pt":1580647916033,"mc":[{"id":"1.168224575","rc":[{"batb":[[0,4.9,22.83],[2,1.01,0.51]],"batl":[[0,5.9,12.51],[1,5.7,0],[2,5.9,0]],"ltp":0.0,"tv":0.0,"id":13024648},{"batb":[[0,1.55,33.6],[1,1.01,0.51],[2,1.55,0]],"batl":[[0,1.73,25.57],[1,1.73,0],[2,1.75,0]],"ltp":1.68,"tv":683.24,"id":13024647},{"batb":[[1,5.2,12.51],[2,1.01,0.51]],"batl":[[0,6.4,10.46],[1,6.2,0],[2,6.4,0]],"ltp":0.0,"tv":0.0,"id":16575845},{"batb":[[0,23,3.41],[1,1.01,0.51],[2,1.01,0]],"ltp":3.15,"tv":66.14,"id":16575844}]}]}
{"op":"mcm","clk":"1003058122","pt":1580647918007,"mc":[{"id":"1.168224575","rc":[{"batb":[[1,4.8,49.96]],"ltp":0.0,"tv":0.0,"id":13024648},{"batb":[[0,1.57,103.97],[1,1.56,77.76],[2,1.55,33.6]],"ltp":1.68,"tv":683.24,"id":13024647},{"batb":[[0,5.4,37.34],[1,5.3,29.48],[2,5.2,12.51]],"ltp":0.0,"tv":0.0,"id":16575845},{"batb":[[0,27,5.62],[1,26,10.28],[2,23,3.41]],"ltp":3.15,"tv":66.14,"id":16575844}]}]}
{"op":"mcm","clk":"1003058282","pt":1580647918925,"mc":[{"id":"1.168224575","rc":[{"batb":[[1,4.8,15.11]],"ltp":0.0,"tv":0.0,"id":13024648},{"batb":[[0,1.55,33.6],[1,1.01,0.51],[2,1.55,0]],"ltp":1.68,"tv":683.24,"id":13024647},{"batb":[[0,5.2,12.51],[1,1.01,0.51],[2,5.2,0]],"ltp":0.0,"tv":0.0,"id":16575845},{"batb":[[0,23,3.41],[1,1.01,0.51],[2,23,0]],"ltp":3.15,"tv":66.14,"id":16575844}]}]}
{"op":"mcm","clk":"1003059530","pt":1580647926177,"mc":[{"id":"1.168224575","rc":[{"batb":[[1,4.8,49.96]],"ltp":0.0,"tv":0.0,"id":13024648},{"batb":[[0,1.57,103.97],[1,1.56,77.76],[2,1.55,33.6]],"ltp":1.68,"tv":683.24,"id":13024647},{"batb":[[0,5.4,37.34],[1,5.3,29.48],[2,5.2,12.51]],"ltp":0.0,"tv":0.0,"id":16575845},{"batb":[[0,27,5.62],[1,26,10.28],[2,23,3.41]],"ltp":3.15,"tv":66.14,"id":16575844}]}]}
{"op":"mcm","clk":"1003060192","pt":1580647930229,"mc":[{"id":"1.168224575","rc":[{"batb":[[0,1.55,33.6],[1,1.01,0.51],[2,1.55,0]],"ltp":1.68,"tv":683.24,"id":13024647}]}]}
{"op":"mcm","clk":"1003060728","pt":1580647933354,"mc":[{"id":"1.168224575","rc":[{"batb":[[0,1.66,86.92],[1,1.65,63.32],[2,1.55,33.6]],"ltp":1.68,"tv":683.24,"id":13024647},{"batb":[[1,23,3.41],[2,1.01,0.51]],"ltp":3.15,"tv":66.14,"id":16575844}]}]}
{"op":"mcm","clk":"1003060837","pt":1580647934051,"mc":[{"id":"1.168224575","rc":[{"batb":[[2,4.7,15.58]],"batl":[[0,5.5,14.4],[1,5.7,13.3]],"ltp":0.0,"tv":0.0,"id":13024648},{"batb":[[0,1.66,112.96],[2,1.59,30.29]],"batl":[[1,1.79,23.13]],"ltp":1.68,"tv":683.24,"id":13024647},{"batl":[[0,5.9,12.12],[1,6.2,11.09]],"ltp":0.0,"tv":0.0,"id":16575845},{"batb":[[2,19,6.45]],"ltp":3.15,"tv":66.14,"id":16575844}]}]}
{"op":"mcm","clk":"1003061089","pt":1580647935472,"mc":[{"id":"1.168224575","rc":[{"batb":[[2,4.7,26.5]],"batl":[[0,5.5,23.64]],"ltp":0.0,"tv":0.0,"id":13024648},{"batb":[[0,1.66,175.98]],"batl":[[1,1.78,42.01],[2,1.79,23.13]],"ltp":1.68,"tv":683.24,"id":13024647}]}]}
{"op":"mcm","clk":"1003061246","pt":1580647936262,"mc":[{"id":"1.168224575","rc":[{"batb":[[0,28,4.36],[1,27,9.87],[2,23,3.41]],"ltp":3.15,"tv":66.14,"id":16575844}]}]}
{"op":"mcm","clk":"1003061346","pt":1580647936890,"mc":[{"id":"1.168224575","rc":[{"batl":[[1,6,8.4],[2,6.2,11.09]],"ltp":0.0,"tv":0.0,"id":16575845}]}]}
{"op":"mcm","clk":"1003062823","pt":1580647946404,"mc":[{"id":"1.168224575","rc":[{"batb":[[0,4.8,49.96],[1,4.7,26.5],[2,1.01,0.51]],"ltp":0.0,"tv":0.0,"id":13024648},{"batb":[[0,1.66,89.06],[1,1.59,30.29],[2,1.01,0.51]],"ltp":1.68,"tv":683.24,"id":13024647},{"batb":[[0,5.3,29.48],[1,5.2,12.51],[2,5,23.62]],"ltp":0.0,"tv":0.0,"id":16575845},{"batb":[[0,23,3.41],[1,19,6.45],[2,1.01,0.51]],"ltp":3.15,"tv":66.14,"id":16575844}]}]}
{"op":"mcm","clk":"1003062920","pt":1580647947111,"mc":[{"id":"1.168224575","rc":[{"batb":[[0,4.8,34.85]],"batl":[[0,5.5,9.24]],"ltp":0.0,"tv":0.0,"id":13024648},{"batb":[[0,1.66,63.01]],"batl":[[0,1.78,42.01],[1,1.79,23.13],[2,1.79,0]],"ltp":1.68,"tv":683.24,"id":13024647},{"batb":[[1,5,23.62],[2,1.01,0.51]],"batl":[[0,6,8.4],[1,6.2,11.09],[2,6.2,0]],"ltp":0.0,"tv":0.0,"id":16575845},{"batb":[[0,19,6.45],[1,1.01,0.51],[2,1.01,0]],"ltp":3.15,"tv":66.14,"id":16575844}]}]}
{"op":"mcm","clk":"1003063065","pt":1580647948001,"mc":[{"id":"1.168224575","rc":[{"batb":[[1,4.7,15.58]],"batl":[[0,5.7,13.3],[1,5.7,0]],"ltp":0.0,"tv":0.0,"id":13024648},{"batb":[[0,1.59,30.29],[1,1.01,0.51],[2,1.01,0]],"batl":[[0,1.79,23.13],[1,1.79,0]],"ltp":1.68,"tv":683.24,"id":13024647},{"batb":[[1,5,13.53]],"batl":[[0,6.2,11.09],[1,6.2,0]],"ltp":0.0,"tv":0.0,"id":16575845}]}]}
{"op":"mcm","clk":"1003063309","pt":1580647949491,"mc":[{"id":"1.168224575","rc":[{"batb":[[1,4.7,52.06]],"ltp":0.0,"tv":0.0,"id":13024648},{"batb":[[0,1.6,70.67],[1,1.59,30.29],[2,1.01,0.51]],"ltp":1.68,"tv":683.24,"id":13024647},{"batb":[[1,5.2,30.86],[2,5,13.53]],"ltp":0.0,"tv":0.0,"id":16575845},{"batb":[[0,23,9.41],[1,22,14.65],[2,19,6.45]],"ltp":3.15,"tv":66.14,"id":16575844}]}]}
{"op":"mcm","clk":"1003063446","pt":1580647950289,"mc":[{"id":"1.168224575","rc":[{"batb":[[1,4.7,15.58]],"ltp":0.0,"tv":0.0,"id":13024648},{"batb":[[0,1.59,30.29],[1,1.01,0.51],[2,1.01,0]],"batl":[[0,1.78,23.6]],"ltp":1.68,"tv":683.24,"id":13024647},{"batb":[[1,5,13.53],[2,1.01,0.51]],"ltp":0.0,"tv":0.0,"id":16575845},{"batb":[[0,20,5.51],[1,1.01,0.51],[2,19,0]],"ltp":3.15,"tv":66.14,"id":16575844}]}]}
{"op":"mcm","clk":"1003063983","pt":1580647953475,"mc":[{"id":"1.168224575","rc":[{"batb":[[0,4.9,34.19],[1,4.8,34.85],[2,4.7,15.58]],"ltp":0.0,"tv":0.0,"id":13024648},{"batb":[[0,1.65,94.5],[1,1.64,64.72],[2,1.59,30.29]],"ltp":1.68,"tv":683.24,"id":13024647},{"batb":[[0,5.4,39.15],[1,5.3,29.48],[2,5,13.53]],"ltp":0.0,"tv":0.0,"id":16575845},{"batb":[[0,29,9.89],[1,28,8.95],[2,20,5.51]],"ltp":3.15,"tv":66.14,"id":16575844}]}]}
{"op":"mcm","clk":"1003064414","pt":1580647955926,"mc":[{"id":"1.168224575","rc":[{"batb":[[0,4.8,34.85],[1,4.7,15.58],[2,1.01,0.51]],"ltp":0.0,"tv":0.0,"id":13024648},{"batb":[[0,1.59,30.29],[1,1.01,0.51],[2,1.59,0]],"ltp":1.68,"tv":683.24,"id":13024647},{"batb":[[0,5.3,29.48],[1,5,13.53],[2,1.01,0.51]],"ltp":0.0,"tv":0.0,"id":16575845},{"batb":[[0,20,5.51],[1,1.01,0.51],[2,20,0]],"ltp":3.15,"tv":66.14,"id":16575844}]}]}
{"op":"mcm","clk":"1003064823","pt":1580647958407,"mc":[{"id":"1.168224575","rc":[{"batb":[[1,4.7,52.07]],"ltp":0.0,"tv":0.0,"id":13024648},{"batb":[[0,1.61,76.33],[1,1.6,70.67],[2,1.59,30.29]],"ltp":1.68,"tv":683.24,"id":13024647},{"batb":[[1,5.2,30.86],[2,5,13.53]],"ltp":0.0,"tv":0.0,"id":16575845},{"batb":[[0,23,9.41],[1,22,14.65],[2,20,5.51]],"ltp":3.15,"tv":66.14,"id":16575844}]}]}
{"op":"mcm","clk":"1003064961","pt":1580647959414,"mc":[{"id":"1.168224575","rc":[{"batb":[[0,1.59,30.29],[1,1.01,0.51],[2,1.59,0]],"ltp":1.68,"tv":683.24,"id":13024647}]}]}
{"op":"mcm","clk":"1003065049","pt":1580647960010,"mc":[{"id":"1.168224575","rc":[{"batb":[[2,1.01,0.51]],"ltp":0.0,"tv":0.0,"id":16575845}]}]}
{"op":"mcm","clk":"1003065432","pt":1580647962482,"mc":[{"id":"1.168224575","rc":[{"batb":[[0,1.7,87.04],[1,1.68,118.21],[2,1.59,30.29]],"ltp":1.68,"tv":683.24,"id":13024647}]}]}
{"op":"mcm","clk":"1003065524","pt":1580647962961,"mc":[{"id":"1.168224575","rc":[{"batb":[[0,4.8,50.11],[2,4.6,10.92]],"batl":[[0,5.4,9.24],[1,5.6,13.69]],"ltp":0.0,"tv":0.0,"id":13024648},{"batb":[[0,1.71,23.53],[1,1.7,87.04],[2,1.68,118.21]],"batl":[[0,1.79,23.13],[1,1.8,42.01],[2,1.84,21.09]],"ltp":1.68,"tv":683.24,"id":13024647},{"batb":[[2,5,10.08]],"batl":[[0,5.6,13.61],[1,5.8,12.59],[2,5.9,8.4]],"ltp":0.0,"tv":0.0,"id":16575845}]}]}
{"op":"mcm","clk":"1003067709","pt":1580647976371,"mc":[{"id":"1.168224575","rc":[{"batb":[[0,4.7,52.07],[1,1.01,0.51],[2,4.6,0]],"batl":[[0,5.6,13.69],[1,5.6,0]],"ltp":0.0,"tv":0.0,"id":13024648},{"batb":[[0,1.65,26.83],[1,1.01,0.51],[2,1.68,0]],"batl":[[0,1.84,21.09],[1,1.8,0],[2,1.84,0]],"ltp":1.68,"tv":683.24,"id":13024647},{"batb":[[0,5.2,30.86],[1,4.8,15.11],[2,1.01,0.51]],"batl":[[0,5.8,12.59],[1,5.8,0],[2,5.9,0]],"ltp":0.0,"tv":0.0,"id":16575845},{"batb":[[0,17.5,7.95],[1,1.01,0.51],[2,20,0]],"ltp":3.15,"tv":66.14,"id":16575844}]}]}
{"op":"mcm","clk":"1003068107","pt":1580647978775,"mc":[{"id":"1.168224575","rc":[{"batb":[[0,4.7,67.74],[1,4.6,38.13],[2,1.01,0.51]],"ltp":0.0,"tv":0.0,"id":13024648},{"batb":[[0,1.65,118.67],[1,1.64,64.72],[2,1.01,0.51]],"ltp":1.68,"tv":683.24,"id":13024647},{"batb":[[1,5.1,32.27],[2,4.8,15.11]],"ltp":0.0,"tv":0.0,"id":16575845},{"batb":[[0,20,16.81],[1,19.5,9.42],[2,17.5,7.95]],"ltp":3.15,"tv":66.14,"id":16575844}]}]}
{"op":"mcm","clk":"1003069133","pt":1580647985072,"mc":[{"id":"1.168224575","rc":[{"batb":[[0,4.7,15.58],[1,1.01,0.51],[2,1.01,0]],"ltp":0.0,"tv":0.0,"id":13024648},{"batb":[[0,4.8,15.11],[1,1.01,0.51],[2,4.8,0]],"ltp":0.0,"tv":0.0,"id":16575845},{"batb":[[0,17.5,7.95],[1,1.01,0.51],[2,17.5,0]],"ltp":3.15,"tv":66.14,"id":16575844}]}]}
{"op":"mcm","clk":"1003069633","pt":1580647988045,"mc":[{"id":"1.168224575","rc":[{"batb":[[0,4.9,34.87],[1,4.8,34.73],[2,4.7,15.58]],"ltp":0.0,"tv":0.0,"id":13024648},{"batb":[[0,5.4,44.17],[1,5.3,29.27],[2,4.8,15.11]],"ltp":0.0,"tv":0.0,"id":16575845},{"batb":[[0,29,6.03],[1,28,9.08],[2,17.5,7.95]],"ltp":3.15,"tv":66.14,"id":16575844}]}]}
{"op":"mcm","clk":"1003069780","pt":1580647989004,"mc":[{"id":"1.168224575","rc":[{"batb":[[0,4.9,49.11],[1,4.8,49.92],[2,4.7,10.92]],"batl":[[0,5.5,9.24],[1,5.6,13.69],[2,5.8,12.83]],"ltp":0.0,"tv":0.0,"id":13024648},{"batb":[[1,1.64,130.26],[2,1.58,31.32]],"batl":[[0,1.72,26.28],[1,1.76,42.01],[2,1.78,23.21]],"ltp":1.68,"tv":683.24,"id":13024647},{"batb":[[2,5.1,23.22]],"batl":[[1,6,8.4],[2,6.2,11.64]],"ltp":0.0,"tv":0.0,"id":16575845},{"batb":[[2,24,5.41]],"ltp":3.15,"tv":66.14,"id":16575844}]}]}
{"op":"mcm","clk":"1003071817","pt":1580648001428,"mc":[{"id":"1.168224575","rc":[{"batb":[[0,4.9,14.24]],"ltp":0.0,"tv":0.0,"id":13024648},{"batb":[[0,1.65,26.83],[1,1.64,65.54]],"ltp":1.68,"tv":683.24,"id":13024647},{"batb":[[0,5.3,29.27],[1,5.1,23.22],[2,4.9,14.08]],"ltp":0.0,"tv":0.0,"id":16575845},{"batb":[[0,24,5.41],[1,19.5,5.98],[2,1.01,0.51]],"ltp":3.15,"tv":66.14,"id":16575844}]}]}
{"op":"mcm","clk":"1003071901","pt":1580648001956,"mc":[{"id":"1.168224575","rc":[{"batb":[[0,4.8,49.92],[1,1.01,0.51],[2,4.7,0]],"batl":[[0,5.8,12.83],[1,5.6,0],[2,5.8,0]],"ltp":0.0,"tv":0.0,"id":13024648},{"batb":[[0,1.58,31.32],[1,1.01,0.51],[2,1.58,0]],"batl":[[0,1.78,23.21],[1,1.76,0],[2,1.78,0]],"ltp":1.68,"tv":683.24,"id":13024647},{"batb":[[1,4.9,14.08],[2,1.01,0.51]],"batl":[[0,6.2,11.64],[1,6,0],[2,6.2,0]],"ltp":0.0,"tv":0.0,"id":16575845},{"batb":[[0,19.5,5.98],[1,1.01,0.51],[2,1.01,0]],"ltp":3.15,"tv":66.14,"id":16575844}]}]}
{"op":"mcm","clk":"1003072284","pt":1580648004408,"mc":[{"id":"1.168224575","rc":[{"batb":[[1,4.7,36.44],[2,1.01,0.51]],"ltp":0.0,"tv":0.0,"id":13024648},{"batb":[[0,1.58,168.41],[1,1.57,76.04],[2,1.01,0.51]],"ltp":1.68,"tv":683.24,"id":13024647},{"batb":[[0,5.3,40.22],[1,5.2,30.68],[2,4.9,14.08]],"ltp":0.0,"tv":0.0,"id":16575845},{"batb":[[0,22,18.47],[1,21,12.76],[2,19.5,5.98]],"ltp":3.15,"tv":66.14,"id":16575844}]}]}
{"op":"mcm","clk":"1003074640","pt":1580648019050,"mc":[{"id":"1.168224575","rc":[{"batb":[[0,4.8,15.19],[1,1.01,0.51],[2,1.01,0]],"ltp":0.0,"tv":0.0,"id":13024648},{"batb":[[0,4.9,14.08],[1,1.01,0.51],[2,4.9,0]],"ltp":0.0,"tv":0.0,"id":16575845},{"batb":[[0,19.5,5.98],[1,1.01,0.51],[2,19.5,0]],"ltp":3.15,"tv":66.14,"id":16575844}]}]}
{"op":"mcm","clk":"1003075180","pt":1580648022490,"mc":[{"id":"1.168224575","rc":[{"batb":[[0,5.1,13.38],[1,5,45.5],[2,4.9,47.07]],"batl":[[1,6,11.88]],"ltp":0.0,"tv":0.0,"id":13024648},{"batb":[[2,1.5,38.08]],"batl":[[0,1.65,30.61],[1,1.71,26.59]],"ltp":1.68,"tv":683.24,"id":13024647},{"batb":[[0,5.6,38.07],[1,5.5,26.93],[2,5.3,12.12]],"batl":[[1,6.4,10.31]],"ltp":0.0,"tv":0.0,"id":16575845},{"batb":[[0,50,2.07],[1,48,6.11],[2,30,2.56]],"ltp":3.15,"tv":66.14,"id":16575844}]}]}
{"op":"mcm","clk":"1003075255","pt":1580648022932,"mc":[{"id":"1.168224575","rc":[{"batl":[[0,5.5,9.24],[1,5.8,12.83],[2,6,11.88]],"ltp":0.0,"tv":0.0,"id":13024648},{"batb":[[0,1.59,70.58],[1,1.58,168.41],[2,1.57,76.04]],"batl":[[1,1.71,68.6]],"ltp":1.68,"tv":683.24,"id":13024647},{"batl":[[0,6.2,19.21]],"ltp":0.0,"tv":0.0,"id":16575845}]}]}
{"op":"mcm","clk":"1003077256","pt":1580648035386,"mc":[{"id":"1.168224575","rc":[{"batb":[[0,4.9,47.07],[1,4.7,10.92],[2,1.01,0.51]],"batl":[[1,6,11.88],[2,6,0]],"ltp":0.0,"tv":0.0,"id":13024648},{"batb":[[1,1.5,38.08],[2,1.01,0.51]],"batl":[[0,1.71,68.6],[1,1.71,0]],"ltp":1.68,"tv":683.24,"id":13024647},{"batb":[[0,5.5,26.93],[1,5.2,9.24],[2,5.1,12.98]],"batl":[[0,6.2,7.56]],"ltp":0.0,"tv":0.0,"id":16575845},{"batb":[[0,25,4.89],[1,1.01,0.51],[2,30,0]],"ltp":3.15,"tv":66.14,"id":16575844}]}]}
{"op":"mcm","clk":"1003077350","pt":1580648035969,"mc":[{"id":"1.168224575","rc":[{"batb":[[1,1.01,0.51],[2,1.01,0]],"batl":[[0,6,11.88],[1,6,0]],"ltp":0.0,"tv":0.0,"id":13024648},{"batb":[[0,1.5,38.08],[1,1.01,0.51],[2,1.01,0]],"batl":[[0,1.71,26.59]],"ltp":1.68,"tv":683.24,"id":13024647},{"batb":[[1,5.1,12.98],[2,1.01,0.51]],"batl":[[0,6.4,10.31],[1,6.4,0]],"ltp":0.0,"tv":0.0,"id":16575845}]}]}
{"op":"mcm","clk":"1003077580","pt":1580648037460,"mc":[{"id":"1.168224575","rc":[{"batb":[[0,4.9,14.24]],"ltp":0.0,"tv":0.0,"id":13024648},{"batb":[[0,5.1,12.98],[1,1.01,0.51],[2,1.01,0]],"ltp":0.0,"tv":0.0,"id":16575845}]}]}
{"op":"mcm","clk":"1003077771","pt":1580648038990,"mc":[{"id":"1.168224575","rc":[{"batb":[[0,1.5,37.77]],"batl":[[0,1.72,26.44]],"ltp":1.68,"tv":683.24,"id":13024647}]}]}
{"op":"mcm","clk":"1003077979","pt":1580648040453,"mc":[{"id":"1.168224575","rc":[{"batb":[[0,5.1,24.74],[1,5,31.64],[2,4.9,14.24]],"ltp":0.0,"tv":0.0,"id":13024648},{"batb":[[0,1.57,89.45],[1,1.56,77.64],[2,1.5,37.77]],"ltp":1.68,"tv":683.24,"id":13024647},{"batb":[[0,5.7,23.05],[1,5.6,26.05],[2,5.1,12.98]],"ltp":0.0,"tv":0.0,"id":16575845},{"batb":[[0,60,7.45],[1,55,4.13],[2,25,4.89]],"ltp":3.15,"tv":66.14,"id":16575844}]}]}
{"op":"mcm","clk":"1003078407","pt":1580648043187,"mc":[{"id":"1.168224575","rc":[{"batb":[[0,4.9,14.24],[1,1.01,0.51],[2,4.9,0]],"ltp":0.0,"tv":0.0,"id":13024648},{"batb":[[0,1.5,37.77],[1,1.01,0.51],[2,1.5,0]],"ltp":1.68,"tv":683.24,"id":13024647},{"batb":[[0,5.1,12.98],[1,1.01,0.51],[2,5.1,0]],"ltp":0.0,"tv":0.0,"id":16575845},{"batb":[[0,25,4.89],[1,1.01,0.51],[2,25,0]],"ltp":3.15,"tv":66.14,"id":16575844}]}]}
{"op":"mcm","clk":"1003078793","pt":1580648045713,"mc":[{"id":"1.168224575","rc":[{"batb":[[0,4.9,54.81],[1,4.8,34.64],[2,1.01,0.51]],"ltp":0.0,"tv":0.0,"id":13024648},{"batb":[[0,1.51,85.98],[1,1.5,128.82],[2,1.01,0.51]],"ltp":1.68,"tv":683.24,"id":13024647},{"batb":[[0,5.5,26.84],[1,5.4,28.32],[2,5.1,12.98]],"ltp":0.0,"tv":0.0,"id":16575845},{"batb":[[0,29,10.43],[1,28,8.98],[2,25,4.89]],"ltp":3.15,"tv":66.14,"id":16575844}]}]}
{"op":"mcm","clk":"1003079330","pt":1580648049205,"mc":[{"id":"1.168224575","rc":[{"batb":[[0,4.9,14.24],[1,1.01,0.51],[2,1.01,0]],"ltp":0.0,"tv":0.0,"id":13024648},{"batb":[[0,5.1,12.98],[1,1.01,0.51],[2,5.1,0]],"ltp":0.0,"tv":0.0,"id":16575845},{"batb":[[0,25,4.89],[1,1.01,0.51],[2,25,0]],"ltp":3.15,"tv":66.14,"id":16575844}]}]}
{"op":"mcm","clk":"1003079852","pt":1580648052408,"mc":[{"id":"1.168224575","rc":[{"batb":[[0,5.2,38.8],[1,5.1,29.9],[2,4.9,14.24]],"ltp":0.0,"tv":0.0,"id":13024648},{"batb":[[0,5.9,18.27],[1,5.8,24.06],[2,5.1,12.98]],"ltp":0.0,"tv":0.0,"id":16575845}]}]}
{"op":"mcm","clk":"1003079961","pt":1580648053179,"mc":[{"id":"1.168224575","rc":[{"batb":[[0,5.2,51.23],[2,4.8,10.92]],"batl":[[0,5.6,8.4],[1,6,11.88],[2,6.8,19.12]],"ltp":0.0,"tv":0.0,"id":13024648},{"batb":[[0,1.54,77.3],[1,1.51,85.98],[2,1.5,128.82]],"batl":[[0,1.57,36.82],[1,1.64,42.01],[2,1.7,27.3]],"ltp":1.68,"tv":683.24,"id":13024647},{"batb":[[2,5.5,10.94]],"batl":[[0,6.2,7.56],[1,6.4,10.31],[2,7.2,16.84]],"ltp":0.0,"tv":0.0,"id":16575845},{"batb":[[0,1.01,0.51],[1,1.01,0]],"ltp":3.15,"tv":66.14,"id":16575844}]}]}
{"op":"mcm","clk":"1003086423","pt":1580648094080,"mc":[{"id":"1.168224575","rc":[{"batb":[[0,15,15.12],[1,1.01,0.51]],"ltp":3.15,"tv":66.14,"id":16575844}]}]}
{"op":"mcm","clk":"1003091756","pt":1580648124035,"mc":[{"id":"1.168224575","rc":[{"batb":[[0,1.51,85.98],[1,1.5,128.82],[2,1.43,45.64]],"ltp":1.68,"tv":683.24,"id":13024647}]}]}
{"op":"mcm","clk":"1003092326","pt":1580648127030,"mc":[{"id":"1.168224575","rc":[{"batb":[[0,1.53,78.98],[1,1.51,85.98],[2,1.5,128.82]],"ltp":1.68,"tv":683.24,"id":13024647}]}]}
{"op":"mcm","clk":"1003099408","pt":1580648167085,"mc":[{"id":"1.168224575","rc":[{"batb":[[0,4.8,10.92],[1,4.6,16.76],[2,1.01,0.51]],"batl":[[1,6.8,19.12],[2,6.8,0]],"ltp":0.0,"tv":0.0,"id":13024648},{"batb":[[1,1.43,45.64],[2,1.01,0.51]],"batl":[[0,1.64,42.01],[1,1.7,27.3],[2,1.7,0]],"ltp":1.68,"tv":683.24,"id":13024647},{"batb":[[0,5.2,9.24],[1,4.8,14.95],[2,1.01,0.51]],"batl":[[1,7.2,16.84],[2,7.2,0]],"ltp":0.0,"tv":0.0,"id":16575845}]}]}
{"op":"mcm","clk":"1003099635","pt":1580648168369,"mc":[{"id":"1.168224575","rc":[{"batb":[[0,4.6,16.76],[1,1.01,0.51],[2,1.01,0]],"batl":[[0,6.8,19.12],[1,6.8,0]],"ltp":0.0,"tv":0.0,"id":13024648},{"batb":[[0,1.43,45.64],[1,1.01,0.51],[2,1.01,0]],"batl":[[0,1.7,27.3],[1,1.7,0]],"ltp":1.68,"tv":683.24,"id":13024647},{"batb":[[0,4.8,14.95],[1,1.01,0.51],[2,1.01,0]],"batl":[[0,7.2,16.84],[1,7.2,0]],"ltp":0.0,"tv":0.0,"id":16575845}]}]}
{"op":"mcm","clk":"1003099820","pt":1580648169438,"mc":[{"id":"1.168224575","rc":[{"batb":[[0,4.6,42.63],[1,4.5,40.02],[2,1.01,0.51]],"ltp":0.0,"tv":0.0,"id":13024648},{"batb":[[0,1.45,79.78],[1,1.44,107.08],[2,1.43,45.64]],"ltp":1.68,"tv":683.24,"id":13024647},{"batb":[[0,5.1,38.24],[1,5,33.25],[2,4.8,14.95]],"ltp":0.0,"tv":0.0,"id":16575845}]}]}
{"op":"mcm","clk":"1003099867","pt":1580648169703,"mc":[{"id":"1.168224575","rc":[{"batb":[[0,4.6,16.76],[1,1.01,0.51],[2,1.01,0]],"ltp":0.0,"tv":0.0,"id":13024648},{"batb":[[0,1.43,45.64],[1,1.01,0.51],[2,1.43,0]],"ltp":1.68,"tv":683.24,"id":13024647},{"batb":[[0,4.8,14.95],[1,1.01,0.51],[2,4.8,0]],"ltp":0.0,"tv":0.0,"id":16575845}]}]}
{"op":"mcm","clk":"1003100124","pt":1580648171304,"mc":[{"id":"1.168224575","rc":[{"batb":[[0,5.1,25.4],[1,5,31.47],[2,4.6,16.76]],"ltp":0.0,"tv":0.0,"id":13024648},{"batb":[[0,1.53,101.2],[1,1.52,85.6],[2,1.43,45.64]],"ltp":1.68,"tv":683.24,"id":13024647},{"batb":[[0,5.7,31.75],[1,5.6,25.89],[2,4.8,14.95]],"ltp":0.0,"tv":0.0,"id":16575845}]}]}
{"op":"mcm","clk":"1003101219","pt":1580648177966,"mc":[{"id":"1.168224575","rc":[{"batb":[[0,4.6,16.76],[1,1.01,0.51],[2,4.6,0]],"ltp":0.0,"tv":0.0,"id":13024648},{"batb":[[0,1.43,45.64],[1,1.01,0.51],[2,1.43,0]],"ltp":1.68,"tv":683.24,"id":13024647},{"batb":[[0,4.8,14.95],[1,1.01,0.51],[2,4.8,0]],"ltp":0.0,"tv":0.0,"id":16575845}]}]}
{"op":"mcm","clk":"1003101695","pt":1580648180856,"mc":[{"id":"1.168224575","rc":[{"batb":[[0,4.6,43.45],[1,4.5,40.02],[2,1.01,0.51]],"ltp":0.0,"tv":0.0,"id":13024648},{"batb":[[0,1.45,76.43],[1,1.44,107.07],[2,1.43,45.64]],"ltp":1.68,"tv":683.24,"id":13024647},{"batb":[[0,5.1,38.94],[1,5,33.25],[2,4.8,14.95]],"ltp":0.0,"tv":0.0,"id":16575845}]}]}
{"op":"mcm","clk":"1003103193","pt":1580648190044,"mc":[{"id":"1.168224575","rc":[{"batb":[[0,4.6,16.76],[1,1.01,0.51],[2,1.01,0]],"ltp":0.0,"tv":0.0,"id":13024648},{"batb":[[0,4.8,14.95],[1,1.01,0.51],[2,4.8,0]],"ltp":0.0,"tv":0.0,"id":16575845}]}]}
{"op":"mcm","clk":"1003103777","pt":1580648193482,"mc":[{"id":"1.168224575","rc":[{"batb":[[0,5.7,19.75],[1,5.6,24.47],[2,4.6,16.76]],"ltp":0.0,"tv":0.0,"id":13024648},{"batb":[[0,6.4,27.02],[1,6.2,40.84],[2,4.8,14.95]],"ltp":0.0,"tv":0.0,"id":16575845}]}]}
{"op":"mcm","clk":"1003103877","pt":1580648193983,"mc":[{"id":"1.168224575","rc":[{"batb":[[0,5.7,40.29],[2,5.1,13.3]],"batl":[[1,7.2,16.13]],"ltp":0.0,"tv":0.0,"id":13024648},{"batl":[[0,1.5,44.3],[1,1.6,34.31]],"ltp":1.68,"tv":683.24,"id":13024647},{"batb":[[2,6,18.02]],"batl":[[1,7.8,14.01]],"ltp":0.0,"tv":0.0,"id":16575845}]}]}
{"op":"mcm","clk":"1003104041","pt":1580648194971,"mc":[{"id":"1.168224575","rc":[{"batb":[[2,5.1,23.38]],"batl":[[0,6,8.4],[1,6.8,19.12],[2,7.2,16.13]],"ltp":0.0,"tv":0.0,"id":13024648},{"batb":[[0,1.47,89.06],[1,1.45,76.43],[2,1.44,107.07]],"batl":[[1,1.57,42.01],[2,1.6,34.31]],"ltp":1.68,"tv":683.24,"id":13024647},{"batl":[[0,6.8,6.72],[1,7.2,16.84],[2,7.8,14.01]],"ltp":0.0,"tv":0.0,"id":16575845}]}]}
{"op":"mcm","clk":"1003107080","pt":1580648212929,"mc":[{"id":"1.168224575","rc":[{"batb":[[0,1.01,0.51],[1,1.01,0]],"ltp":3.15,"tv":66.14,"id":16575844}]}]}
{"op":"mcm","clk":"1003107306","pt":1580648214421,"mc":[{"id":"1.168224575","rc":[{"batb":[[0,5.1,23.38],[1,1.01,0.51],[2,5.1,0]],"batl":[[1,7.2,16.13],[2,7.2,0]],"ltp":0.0,"tv":0.0,"id":13024648},{"batb":[[1,1.38,53.35],[2,1.01,0.51]],"batl":[[0,1.57,42.01],[1,1.6,34.31],[2,1.6,0]],"ltp":1.68,"tv":683.24,"id":13024647},{"batb":[[0,5.6,8.4],[1,5.3,11.88],[2,1.01,0.51]],"batl":[[1,7.8,14.01],[2,7.8,0]],"ltp":0.0,"tv":0.0,"id":16575845}]}]}
{"op":"mcm","clk":"1003107647","pt":1580648216440,"mc":[{"id":"1.168224575","rc":[{"batb":[[0,5.1,13.3]],"batl":[[0,7.2,16.13],[1,7.2,0]],"ltp":0.0,"tv":0.0,"id":13024648},{"batb":[[0,1.38,53.35],[1,1.01,0.51],[2,1.01,0]],"batl":[[0,1.6,34.31],[1,1.6,0]],"ltp":1.68,"tv":683.24,"id":13024647},{"batb":[[0,5.3,11.88],[1,1.01,0.51],[2,1.01,0]],"batl":[[0,7.8,14.01],[1,7.8,0]],"ltp":0.0,"tv":0.0,"id":16575845}]}]}
{"op":"mcm","clk":"1003107763","pt":1580648217226,"mc":[{"id":"1.168224575","rc":[{"batb":[[0,5.1,36.02],[1,5,31.53],[2,1.01,0.51]],"ltp":0.0,"tv":0.0,"id":13024648},{"batb":[[0,1.4,163.85],[1,1.39,126.4],[2,1.38,53.35]],"ltp":1.68,"tv":683.24,"id":13024647},{"batb":[[0,5.7,22.47],[1,5.6,26.04],[2,5.3,11.88]],"ltp":0.0,"tv":0.0,"id":16575845}]}]}
{"op":"mcm","clk":"1003108220","pt":1580648220490,"mc":[{"id":"1.168224575","rc":[{"batb":[[0,5.1,13.3],[1,1.01,0.51],[2,1.01,0]],"ltp":0.0,"tv":0.0,"id":13024648},{"batb":[[0,1.38,53.35],[1,1.01,0.51],[2,1.38,0]],"ltp":1.68,"tv":683.24,"id":13024647},{"batb":[[0,5.3,11.88],[1,1.01,0.51],[2,5.3,0]],"ltp":0.0,"tv":0.0,"id":16575845}]}]}
{"op":"mcm","clk":"1003108837","pt":1580648223422,"mc":[{"id":"1.168224575","rc":[{"batb":[[0,5.5,38.99],[1,5.4,26.27],[2,5.1,13.3]],"ltp":0.0,"tv":0.0,"id":13024648},{"batb":[[0,1.46,138.49],[1,1.45,104.41],[2,1.38,53.35]],"ltp":1.68,"tv":683.24,"id":13024647},{"batb":[[0,6.2,36.78],[1,6,43.63],[2,5.3,11.88]],"ltp":0.0,"tv":0.0,"id":16575845}]}]}
{"op":"mcm","clk":"1003109130","pt":1580648225326,"mc":[{"id":"1.168224575","rc":[{"batb":[[0,5.1,13.3],[1,1.01,0.51],[2,5.1,0]],"ltp":0.0,"tv":0.0,"id":13024648},{"batb":[[0,1.38,53.35],[1,1.01,0.51],[2,1.38,0]],"ltp":1.68,"tv":683.24,"id":13024647},{"batb":[[0,5.3,11.88],[1,1.01,0.51],[2,5.3,0]],"ltp":0.0,"tv":0.0,"id":16575845}]}]}
{"op":"mcm","clk":"1003109606","pt":1580648228035,"mc":[{"id":"1.168224575","rc":[{"batb":[[0,5.1,36.02],[1,5,31.53],[2,1.01,0.51]],"ltp":0.0,"tv":0.0,"id":13024648},{"batb":[[0,1.4,163.85],[1,1.39,126.4],[2,1.38,53.35]],"ltp":1.68,"tv":683.24,"id":13024647},{"batb":[[0,5.7,22.47],[1,5.6,26.04],[2,5.3,11.88]],"ltp":0.0,"tv":0.0,"id":16575845}]}]}
{"op":"mcm","clk":"1003110389","pt":1580648232334,"mc":[{"id":"1.168224575","rc":[{"batb":[[0,5.1,13.3],[1,1.01,0.51],[2,1.01,0]],"ltp":0.0,"tv":0.0,"id":13024648},{"batb":[[0,5.3,11.88],[1,1.01,0.51],[2,5.3,0]],"ltp":0.0,"tv":0.0,"id":16575845}]}]}
{"op":"mcm","clk":"1003110940","pt":1580648235364,"mc":[{"id":"1.168224575","rc":[{"batb":[[0,6,37.62],[1,5.9,21.55],[2,5.1,13.3]],"ltp":0.0,"tv":0.0,"id":13024648},{"batb":[[0,6.8,39.29],[1,6.6,35.36],[2,5.3,11.88]],"ltp":0.0,"tv":0.0,"id":16575845}]}]}
{"op":"mcm","clk":"1003111094","pt":1580648236230,"mc":[{"id":"1.168224575","rc":[{"batb":[[0,6,54.85],[2,5.6,10.62]],"batl":[[1,7.8,14.08]],"ltp":0.0,"tv":0.0,"id":13024648},{"batl":[[0,1.44,51.69],[1,1.51,42.96]],"ltp":1.68,"tv":683.24,"id":13024647},{"batb":[[2,6.4,14.87]],"batl":[[1,8.4,12.12]],"ltp":0.0,"tv":0.0,"id":16575845}]}]}
{"op":"mcm","clk":"1003111317","pt":1580648237453,"mc":[{"id":"1.168224575","rc":[{"batb":[[0,1.43,97.46],[1,1.4,163.85],[2,1.39,126.4]],"ltp":1.68,"tv":683.24,"id":13024647},{"batl":[[0,7.2,6.72],[1,7.8,14.01],[2,8.4,12.12]],"ltp":0.0,"tv":0.0,"id":16575845}]}]}
{"op":"mcm","clk":"1003111632","pt":1580648239392,"mc":[{"id":"1.168224575","rc":[{"batl":[[0,6.6,6.72],[1,7.2,16.13],[2,7.8,14.08]],"ltp":0.0,"tv":0.0,"id":13024648},{"trd":[[1.44,102.51]],"batl":[[0,1.51,43.4],[1,1.51,0]],"ltp":1.44,"tv":785.75,"id":13024647}],"tv":851.9}]}
{"op":"mcm","clk":"1003113320","pt":1580648249029,"mc":[{"id":"1.168224575","rc":[{"batb":[[0,22,12.6],[1,1.01,0.51]],"ltp":3.15,"tv":66.14,"id":16575844}]}]}
{"op":"mcm","clk":"1003114624","pt":1580648256122,"mc":[{"id":"1.168224575","rc":[{"batb":[[0,5.6,10.62],[1,1.01,0.51],[2,5.6,0]],"batl":[[0,7.8,14.08],[1,7.2,0],[2,7.8,0]],"ltp":0.0,"tv":0.0,"id":13024648},{"batb":[[0,1.35,60.03],[1,1.01,0.51],[2,1.39,0]],"batl":[[0,1.51,42.96]],"ltp":1.44,"tv":785.75,"id":13024647},{"batb":[[0,5.9,18.73],[1,1.01,0.51],[2,6.4,0]],"batl":[[0,8.4,12.12],[1,7.8,0],[2,8.4,0]],"ltp":0.0,"tv":0.0,"id":16575845}]}]}
{"op":"mcm","clk":"1003115151","pt":1580648259227,"mc":[{"id":"1.168224575","rc":[{"batb":[[0,5.5,10.86]],"batl":[[0,7.6,14.63]],"ltp":0.0,"tv":0.0,"id":13024648},{"batb":[[0,1.38,88.95],[1,1.37,134.5],[2,1.36,58.07]],"batl":[[0,1.53,41.54]],"ltp":1.44,"tv":785.75,"id":13024647},{"batb":[[0,5.7,19.43]],"batl":[[0,8,12.59]],"ltp":0.0,"tv":0.0,"id":16575845}]}]}
{"op":"mcm","clk":"1003115754","pt":1580648262309,"mc":[{"id":"1.168224575","rc":[{"batb":[[0,6.2,48.79],[1,6,40.52],[2,5.5,10.86]],"ltp":0.0,"tv":0.0,"id":13024648},{"batb":[[0,7.2,30.87],[1,7,31.28],[2,5.7,19.43]],"ltp":0.0,"tv":0.0,"id":16575845}]}]}
{"op":"mcm","clk":"1003115950","pt":1580648263247,"mc":[{"id":"1.168224575","rc":[{"batb":[[0,6.2,64.37],[2,5.9,17.86]],"batl":[[0,6.8,6.72],[1,7.6,14.63],[2,7.8,13.69]],"ltp":0.0,"tv":0.0,"id":13024648},{"batb":[[0,1.4,105.02],[1,1.38,88.95],[2,1.37,134.5]],"batl":[[0,1.42,56.18],[1,1.46,49.49]],"ltp":1.44,"tv":785.75,"id":13024647},{"batb":[[2,6.6,13.38]],"batl":[[0,7.8,5.88],[1,8,12.59],[2,8.6,11.25]],"ltp":0.0,"tv":0.0,"id":16575845}]}]}
{"op":"mcm","clk":"1003118315","pt":1580648277287,"mc":[{"id":"1.168224575","rc":[{"batb":[[0,6,40.52],[1,5.9,17.86],[2,5.7,8.4]],"batl":[[1,7.8,13.69],[2,7.8,0]],"ltp":0.0,"tv":0.0,"id":13024648},{"batb":[[1,1.34,62.55],[2,1.01,0.51]],"batl":[[0,1.46,49.49],[1,1.46,0]],"ltp":1.44,"tv":785.75,"id":13024647},{"batb":[[0,6.2,15.97],[1,1.01,0.51],[2,6.6,0]],"batl":[[1,8.6,11.25],[2,8.6,0]],"ltp":0.0,"tv":0.0,"id":16575845},{"batb":[[0,1.01,0.51],[1,1.01,0]],"ltp":3.15,"tv":66.14,"id":16575844}]}]}
{"op":"mcm","clk":"1003118497","pt":1580648278409,"mc":[{"id":"1.168224575","rc":[{"batb":[[2,1.01,0.51]],"batl":[[0,7.8,13.69],[1,7.8,0]],"ltp":0.0,"tv":0.0,"id":13024648},{"batb":[[0,1.34,62.55],[1,1.01,0.51],[2,1.01,0]],"ltp":1.44,"tv":785.75,"id":13024647},{"batl":[[0,8.6,11.25],[1,8.6,0]],"ltp":0.0,"tv":0.0,"id":16575845}]}]}
{"op":"mcm","clk":"1003119182","pt":1580648282403,"mc":[{"id":"1.168224575","rc":[{"batb":[[0,6.2,39.26],[1,6,40.52],[2,5.9,17.86]],"ltp":0.0,"tv":0.0,"id":13024648},{"batb":[[0,1.38,159.07],[1,1.37,135.29],[2,1.34,62.55]],"ltp":1.44,"tv":785.75,"id":13024647},{"batb":[[0,7.2,17.33],[1,7,31.6],[2,6.2,15.97]],"ltp":0.0,"tv":0.0,"id":16575845}]}]}
{"op":"mcm","clk":"1003119824","pt":1580648286212,"mc":[{"id":"1.168224575","rc":[{"batb":[[0,6,40.52],[1,5.9,17.86],[2,1.01,0.51]],"ltp":0.0,"tv":0.0,"id":13024648},{"batb":[[0,1.34,62.55],[1,1.01,0.51],[2,1.34,0]],"ltp":1.44,"tv":785.75,"id":13024647},{"batb":[[0,6.2,15.97],[1,1.01,0.51],[2,6.2,0]],"ltp":0.0,"tv":0.0,"id":16575845}]}]}
{"op":"mcm","clk":"1003120320","pt":1580648289086,"mc":[{"id":"1.168224575","rc":[{"batb":[[0,5.9,17.86],[1,1.01,0.51],[2,1.01,0]],"ltp":0.0,"tv":0.0,"id":13024648},{"batb":[[0,1.36,172.2],[1,1.35,145.58],[2,1.34,62.55]],"ltp":1.44,"tv":785.75,"id":13024647}]}]}
{"op":"mcm","clk":"1003120892","pt":1580648292315,"mc":[{"id":"1.168224575","rc":[{"batb":[[0,6.4,36.21],[1,6.2,38.05],[2,5.9,17.86]],"ltp":0.0,"tv":0.0,"id":13024648},{"batb":[[0,7.4,35.63],[1,7.2,29.34],[2,6.2,15.97]],"ltp":0.0,"tv":0.0,"id":16575845}]}]}
{"op":"mcm","clk":"1003121011","pt":1580648293102,"mc":[{"id":"1.168224575","rc":[{"batb":[[0,6.4,50.77],[2,5.8,27.21]],"batl":[[0,7,6.72],[1,7.8,13.69],[2,9.4,9.36]],"ltp":0.0,"tv":0.0,"id":13024648},{"batb":[[0,1.38,110.07],[1,1.36,172.2],[2,1.35,145.58]],"batl":[[0,1.4,60.43],[1,1.47,48.78]],"ltp":1.44,"tv":785.75,"id":13024647},{"batb":[[2,7,11.96]],"batl":[[0,8.2,5.04],[1,8.6,11.25],[2,10.5,7.79]],"ltp":0.0,"tv":0.0,"id":16575845}]}]}
{"op":"mcm","clk":"1003123040","pt":1580648306575,"mc":[{"id":"1.168224575","rc":[{"trd":[[1.4,100]],"batl":[[0,1.4,10.42]],"ltp":1.4,"tv":885.75,"id":13024647}],"tv":951.9}]}
{"op":"mcm","clk":"1003123504","pt":1580648309375,"mc":[{"id":"1.168224575","rc":[{"batb":[[0,7.4,20.55]],"ltp":0.0,"tv":0.0,"id":16575845}]}]}
{"op":"mcm","clk":"1003123935","pt":1580648312370,"mc":[{"id":"1.168224575","rc":[{"batb":[[1,1.36,209.29]],"ltp":1.4,"tv":885.75,"id":13024647}]}]}
{"op":"mcm","clk":"1003126546","pt":1580648329071,"mc":[{"id":"1.168224575","rc":[{"batb":[[0,6.4,14.56],[1,5.8,27.21],[2,1.01,0.51]],"ltp":0.0,"tv":0.0,"id":13024648},{"batb":[[1,1.34,62.55],[2,1.27,84.27]],"ltp":1.4,"tv":885.75,"id":13024647},{"batb":[[0,7,11.96],[1,6.6,6.72],[2,6.2,15.66]],"ltp":0.0,"tv":0.0,"id":16575845}]}]}
{"op":"mcm","clk":"1003126945","pt":1580648331879,"mc":[{"id":"1.168224575","rc":[{"batb":[[1,5.8,63.03],[2,5.7,23.4]],"ltp":0.0,"tv":0.0,"id":13024648},{"batb":[[2,1.29,150.17]],"ltp":1.4,"tv":885.75,"id":13024647},{"batb":[[1,6.6,39.3],[2,6.4,37.55]],"ltp":0.0,"tv":0.0,"id":16575845}]}]}
{"op":"mcm","clk":"1003127370","pt":1580648334467,"mc":[{"id":"1.168224575","rc":[{"batb":[[0,5.8,63.03],[1,5.7,23.4],[2,1.01,0.51]],"batl":[[1,9.4,9.36],[2,9.4,0]],"ltp":0.0,"tv":0.0,"id":13024648},{"batb":[[1,1.29,150.17],[2,1.28,191.81]],"batl":[[0,1.47,48.78],[1,1.47,0]],"ltp":1.4,"tv":885.75,"id":13024647},{"batb":[[0,6.6,39.3],[1,6.4,37.55],[2,6.2,15.66]],"batl":[[1,10.5,7.79],[2,10.5,0]],"ltp":0.0,"tv":0.0,"id":16575845}]}]}
{"op":"mcm","clk":"1003127663","pt":1580648336205,"mc":[{"id":"1.168224575","rc":[{"batb":[[0,5.8,18.8],[1,1.01,0.51],[2,1.01,0]],"batl":[[0,9.4,9.36],[1,9.4,0]],"ltp":0.0,"tv":0.0,"id":13024648},{"batb":[[0,1.27,84.27],[1,1.01,0.51],[2,1.28,0]],"ltp":1.4,"tv":885.75,"id":13024647},{"batb":[[0,6.2,15.66],[1,1.01,0.51],[2,6.2,0]],"batl":[[0,10.5,7.79],[1,10.5,0]],"ltp":0.0,"tv":0.0,"id":16575845}]}]}
{"op":"mcm","clk":"1003127918","pt":1580648337983,"mc":[{"id":"1.168224575","rc":[{"batb":[[0,5.7,19.99]],"batl":[[0,9,9.91]],"ltp":0.0,"tv":0.0,"id":13024648},{"batb":[[0,1.29,79.63]],"batl":[[0,1.49,45.95]],"ltp":1.4,"tv":885.75,"id":13024647},{"batb":[[0,6,17]],"batl":[[0,9.8,8.5]],"ltp":0.0,"tv":0.0,"id":16575845}]}]}
{"op":"mcm","clk":"1003128101","pt":1580648339093,"mc":[{"id":"1.168224575","rc":[{"batb":[[0,6.6,38.32],[1,6.4,35.49],[2,5.7,19.99]],"ltp":0.0,"tv":0.0,"id":13024648},{"batb":[[0,1.35,130.58],[1,1.34,150.11],[2,1.29,79.63]],"ltp":1.4,"tv":885.75,"id":13024647},{"batb":[[0,7.6,25.17],[1,7.4,27.54],[2,6,17]],"ltp":0.0,"tv":0.0,"id":16575845},{"batb":[[0,19,15.12],[1,1.01,0.51]],"ltp":3.15,"tv":66.14,"id":16575844}]}]}
{"op":"mcm","clk":"1003128685","pt":1580648342455,"mc":[{"id":"1.168224575","rc":[{"batb":[[0,5.7,19.99],[1,1.01,0.51],[2,5.7,0]],"ltp":0.0,"tv":0.0,"id":13024648},{"batb":[[0,1.29,79.63],[1,1.01,0.51],[2,1.29,0]],"ltp":1.4,"tv":885.75,"id":13024647},{"batb":[[0,6,17],[1,1.01,0.51],[2,6,0]],"ltp":0.0,"tv":0.0,"id":16575845}]}]}
{"op":"mcm","clk":"1003129118","pt":1580648345106,"mc":[{"id":"1.168224575","rc":[{"batb":[[0,5.8,33.68],[1,5.7,43.39],[2,1.01,0.51]],"ltp":0.0,"tv":0.0,"id":13024648},{"batb":[[0,1.29,242.3],[1,1.28,191.84],[2,1.01,0.51]],"ltp":1.4,"tv":885.75,"id":13024647},{"batb":[[0,6.6,30.42],[1,6.4,37.55],[2,6,17]],"ltp":0.0,"tv":0.0,"id":16575845}]}]}
{"op":"mcm","clk":"1003129329","pt":1580648346328,"mc":[{"id":"1.168224575","rc":[{"batb":[[0,5.7,19.99],[1,1.01,0.51],[2,1.01,0]],"ltp":0.0,"tv":0.0,"id":13024648},{"batb":[[0,6,17],[1,1.01,0.51],[2,6,0]],"ltp":0.0,"tv":0.0,"id":16575845}]}]}
{"op":"mcm","clk":"1003129836","pt":1580648349383,"mc":[{"id":"1.168224575","rc":[{"batb":[[0,7.6,26.99],[1,7.4,26.02],[2,5.7,19.99]],"ltp":0.0,"tv":0.0,"id":13024648},{"batb":[[0,8.8,14.01],[1,8.6,20.12],[2,6,17]],"ltp":0.0,"tv":0.0,"id":16575845}]}]}
{"op":"mcm","clk":"1003129923","pt":1580648350016,"mc":[{"id":"1.168224575","rc":[{"batb":[[1,7.4,36.48],[2,6.4,14.79]],"batl":[[1,11.5,15.11]],"ltp":0.0,"tv":0.0,"id":13024648},{"batb":[[2,1.21,113.62]],"batl":[[0,1.33,76.48],[1,1.41,59.01]],"ltp":1.4,"tv":885.75,"id":13024647},{"batb":[[2,8,8.89]],"batl":[[1,13,12.59]],"ltp":0.0,"tv":0.0,"id":16575845}]}]}
{"op":"mcm","clk":"1003130138","pt":1580648351407,"mc":[{"id":"1.168224575","rc":[{"batl":[[0,9.2,5.04],[1,9.8,8.5],[2,13,12.59]],"ltp":0.0,"tv":0.0,"id":16575845}]}]}
{"op":"mcm","clk":"1003130295","pt":1580648352416,"mc":[{"id":"1.168224575","rc":[{"batb":[[0,7.6,21.89]],"ltp":0.0,"tv":0.0,"id":13024648},{"batb":[[0,8.6,20.12],[1,8,8.89],[2,7.4,5.88]],"ltp":0.0,"tv":0.0,"id":16575845}]}]}
{"op":"mcm","clk":"1003130338","pt":1580648352731,"mc":[{"id":"1.168224575","rc":[{"batb":[[2,6.8,6.72]],"batl":[[0,8.2,5.04],[1,9,9.91],[2,11.5,15.11]],"ltp":0.0,"tv":0.0,"id":13024648},{"batb":[[0,1.31,135.27],[1,1.29,242.3],[2,1.28,191.84]],"ltp":1.4,"tv":885.75,"id":13024647}]}]}
{"op":"mcm","clk":"1003130794","pt":1580648355436,"mc":[{"id":"1.168224575","rc":[{"batb":[[1,1.29,276.46]],"ltp":1.4,"tv":885.75,"id":13024647},{"batb":[[0,8.6,30.07],[1,8.4,20.73],[2,8,8.89]],"ltp":0.0,"tv":0.0,"id":16575845}]}]}
{"op":"mcm","clk":"1003131570","pt":1580648360438,"mc":[{"id":"1.168224575","rc":[{"batb":[[0,6.4,14.79],[1,1.01,0.51],[2,6.8,0]],"batl":[[0,11.5,15.11],[1,9,0],[2,11.5,0]],"ltp":0.0,"tv":0.0,"id":13024648},{"batb":[[0,1.21,113.62],[1,1.01,0.51],[2,1.28,0]],"batl":[[0,1.41,59.01],[1,1.41,0]],"ltp":1.4,"tv":885.75,"id":13024647},{"batb":[[0,7,12.43],[1,1.01,0.51],[2,8,0]],"batl":[[0,13,12.59],[1,9.8,0],[2,13,0]],"ltp":0.0,"tv":0.0,"id":16575845}]}]}
{"op":"mcm","clk":"1003132009","pt":1580648363490,"mc":[{"id":"1.168224575","rc":[{"batl":[[1,12,14.63]],"ltp":0.0,"tv":0.0,"id":13024648},{"batb":[[1,6.8,12.67],[2,1.01,0.51]],"batl":[[0,12.5,13.22],[1,13,12.59]],"ltp":0.0,"tv":0.0,"id":16575845}]}]}
{"op":"mcm","clk":"1003132056","pt":1580648363813,"mc":[{"id":"1.168224575","rc":[{"batl":[[0,12,14.63],[1,12,0]],"ltp":0.0,"tv":0.0,"id":13024648},{"batb":[[0,1.21,113.22]],"batl":[[0,1.41,58.78]],"ltp":1.4,"tv":885.75,"id":13024647},{"batb":[[0,6.8,12.67],[1,1.01,0.51],[2,1.01,0]],"batl":[[1,13,0]],"ltp":0.0,"tv":0.0,"id":16575845}]}]}
{"op":"mcm","clk":"1003132296","pt":1580648365302,"mc":[{"id":"1.168224575","rc":[{"batb":[[0,8,14.85],[1,7.8,23.38],[2,6.4,14.79]],"ltp":0.0,"tv":0.0,"id":13024648},{"batb":[[0,1.27,274.83],[1,1.26,211.76],[2,1.21,113.22]],"ltp":1.4,"tv":885.75,"id":13024647},{"batb":[[0,9,27.13],[1,8.8,18.8],[2,6.8,12.67]],"ltp":0.0,"tv":0.0,"id":16575845}]}]}
{"op":"mcm","clk":"1003132929","pt":1580648368998,"mc":[{"id":"1.168224575","rc":[{"batb":[[0,6.4,14.79],[1,1.01,0.51],[2,6.4,0]],"ltp":0.0,"tv":0.0,"id":13024648},{"batb":[[0,1.21,113.22],[1,1.01,0.51],[2,1.21,0]],"ltp":1.4,"tv":885.75,"id":13024647},{"batb":[[0,6.8,12.67],[1,1.01,0.51],[2,6.8,0]],"ltp":0.0,"tv":0.0,"id":16575845}]}]}
{"op":"mcm","clk":"1003133439","pt":1580648372211,"mc":[{"id":"1.168224575","rc":[{"batb":[[0,1.21,389.53],[1,1.2,277.94],[2,1.01,0.51]],"ltp":1.4,"tv":885.75,"id":13024647}]}]}
{"op":"mcm","clk":"1003133938","pt":1580648375102,"mc":[{"id":"1.168224575","rc":[{"batb":[[0,9.8,11.04],[1,9.6,15.05],[2,6.4,14.79]],"ltp":0.0,"tv":0.0,"id":13024648},{"batb":[[0,11,21.56],[1,10.5,31.53],[2,6.8,12.67]],"ltp":0.0,"tv":0.0,"id":16575845}]}]}
{"op":"mcm","clk":"1003134080","pt":1580648375828,"mc":[{"id":"1.168224575","rc":[{"batb":[[2,9.2,16.21]],"batl":[[1,15.5,8.5]],"ltp":0.0,"tv":0.0,"id":13024648},{"batb":[[2,1.15,163.03]],"batl":[[0,1.25,107.48],[1,1.32,81.83]],"ltp":1.4,"tv":885.75,"id":13024647},{"batb":[[2,9.6,14.48]],"batl":[[1,16.5,7.95]],"ltp":0.0,"tv":0.0,"id":16575845}]}]}
{"op":"mcm","clk":"1003134328","pt":1580648377315,"mc":[{"id":"1.168224575","rc":[{"batl":[[0,10.5,4.2],[1,12,14.63],[2,15.5,8.5]],"ltp":0.0,"tv":0.0,"id":13024648},{"batl":[[0,11.5,3.36],[1,12.5,13.22],[2,16.5,7.95]],"ltp":0.0,"tv":0.0,"id":16575845}]}]}
{"op":"mcm","clk":"1003134479","pt":1580648378426,"mc":[{"id":"1.168224575","rc":[{"batb":[[0,1.23,168.04],[1,1.21,389.53],[2,1.2,277.94]],"ltp":1.4,"tv":885.75,"id":13024647}]}]}
{"op":"mcm","clk":"1003134524","pt":1580648378710,"mc":[{"id":"1.168224575","rc":[{"batb":[[0,9.6,15.05],[1,9.2,16.21],[2,8.4,5.04]],"ltp":0.0,"tv":0.0,"id":13024648}]}]}
{"op":"mcm","clk":"1003135106","pt":1580648382464,"mc":[{"id":"1.168224575","rc":[{"batb":[[0,9.6,24.87],[1,9.4,15.45],[2,9.2,16.21]],"ltp":0.0,"tv":0.0,"id":13024648}]}]}
{"op":"mcm","clk":"1003135749","pt":1580648386159,"mc":[{"id":"1.168224575","rc":[{"batb":[[0,11,28.71]],"ltp":0.0,"tv":0.0,"id":16575845}]}]}
{"op":"mcm","clk":"1003136124","pt":1580648388293,"mc":[{"id":"1.168224575","rc":[{"batb":[[0,7.8,9.52],[1,1.01,0.51],[2,9.2,0]],"batl":[[0,15.5,8.5],[1,12,0],[2,15.5,0]],"ltp":0.0,"tv":0.0,"id":13024648},{"batb":[[0,1.15,163.03],[1,1.01,0.51],[2,1.2,0]],"batl":[[0,1.32,81.83],[1,1.32,0]],"ltp":1.4,"tv":885.75,"id":13024647},{"batb":[[0,8.4,8.18],[1,1.01,0.51],[2,9.6,0]],"batl":[[0,16.5,7.95],[1,12.5,0],[2,16.5,0]],"ltp":0.0,"tv":0.0,"id":16575845}]}]}
{"op":"mcm","clk":"1003137235","pt":1580648395014,"mc":[{"id":"1.168224575","rc":[{"batb":[[0,10,33.42],[1,9.8,13.95],[2,7.8,9.52]],"ltp":0.0,"tv":0.0,"id":13024648},{"batb":[[0,1.2,145.02],[1,1.19,304.53],[2,1.15,163.03]],"ltp":1.4,"tv":885.75,"id":13024647},{"batb":[[0,11.5,34.03],[1,11,25.12],[2,8.4,8.18]],"ltp":0.0,"tv":0.0,"id":16575845}]}]}
{"op":"mcm","clk":"1003137473","pt":1580648396405,"mc":[{"id":"1.168224575","rc":[{"batb":[[0,7.8,9.52],[1,1.01,0.51],[2,7.8,0]],"ltp":0.0,"tv":0.0,"id":13024648},{"batb":[[0,1.15,163.03],[1,1.01,0.51],[2,1.15,0]],"ltp":1.4,"tv":885.75,"id":13024647},{"batb":[[0,8.4,8.18],[1,1.01,0.51],[2,8.4,0]],"ltp":0.0,"tv":0.0,"id":16575845}]}]}
{"op":"mcm","clk":"1003137998","pt":1580648399493,"mc":[{"id":"1.168224575","rc":[{"batb":[[0,8,28],[1,7.8,32.54],[2,1.01,0.51]],"ltp":0.0,"tv":0.0,"id":13024648},{"batb":[[0,9.4,15.02],[1,9.2,17.49],[2,8.4,8.18]],"ltp":0.0,"tv":0.0,"id":16575845}]}]}
{"op":"mcm","clk":"1003138366","pt":1580648401430,"mc":[{"id":"1.168224575","rc":[{"batl":[[0,10.5,106.05],[1,16.5,7.95]],"ltp":0.0,"tv":0.0,"id":16575845}]}]}
{"op":"mcm","clk":"1003138548","pt":1580648402394,"mc":[{"id":"1.168224575","rc":[{"batb":[[0,1.27,123.34],[1,1.26,208.95],[2,1.15,163.03]],"ltp":1.4,"tv":885.75,"id":13024647},{"batl":[[0,16.5,7.95],[1,16.5,0]],"ltp":0.0,"tv":0.0,"id":16575845}]}]}
{"op":"mcm","clk":"1003138767","pt":1580648403220,"mc":[{"id":"1.168224575","rc":[{"batb":[[2,7.2,6.72]],"batl":[[0,9,5.04],[1,9.4,9.05],[2,13.5,11.49]],"ltp":0.0,"tv":0.0,"id":13024648},{"batb":[[0,1.28,149.55],[1,1.27,208.71],[2,1.26,208.95]],"batl":[[1,1.4,60.03]],"ltp":1.4,"tv":885.75,"id":13024647},{"batl":[[0,10,4.2],[1,10.5,7.79],[2,14,10.54]],"ltp":0.0,"tv":0.0,"id":16575845}]}]}
{"op":"mcm","clk":"1003141337","pt":1580648416492,"mc":[{"id":"1.168224575","rc":[{"batb":[[0,6.4,14.56],[1,1.01,0.51],[2,7.2,0]],"batl":[[0,13.5,11.49],[1,9.4,0],[2,13.5,0]],"ltp":0.0,"tv":0.0,"id":13024648},{"batb":[[0,1.18,133.6],[1,1.01,0.51],[2,1.26,0]],"batl":[[0,1.4,60.03],[1,1.4,0]],"ltp":1.4,"tv":885.75,"id":13024647},{"batb":[[0,7,12.12],[1,1.01,0.51],[2,8.4,0]],"batl":[[0,14,10.54],[1,10.5,0],[2,14,0]],"ltp":0.0,"tv":0.0,"id":16575845}]}]}
{"op":"mcm","clk":"1003141811","pt":1580648419344,"mc":[{"id":"1.168224575","rc":[{"batb":[[0,6.6,39.06],[1,6.4,49.74],[2,1.01,0.51]],"ltp":0.0,"tv":0.0,"id":13024648},{"batb":[[0,1.18,239.99],[1,1.17,344.96],[2,1.01,0.51]],"ltp":1.4,"tv":885.75,"id":13024647},{"batb":[[0,7.8,19.94],[1,7.6,26.19],[2,7,12.12]],"ltp":0.0,"tv":0.0,"id":16575845}]}]}
{"op":"mcm","clk":"1003141919","pt":1580648419569,"mc":[{"id":"1.168224575","rc":[{"batb":[[0,6.4,14.56],[1,1.01,0.51],[2,1.01,0]],"ltp":0.0,"tv":0.0,"id":13024648},{"batb":[[0,1.18,133.6],[1,1.01,0.51],[2,1.01,0]],"ltp":1.4,"tv":885.75,"id":13024647},{"batb":[[0,7,12.12],[1,1.01,0.51],[2,7,0]],"ltp":0.0,"tv":0.0,"id":16575845}]}]}
{"op":"mcm","clk":"1003142456","pt":1580648422469,"mc":[{"id":"1.168224575","rc":[{"batb":[[0,8.6,14.73],[1,8.4,19.88],[2,6.4,14.56]],"ltp":0.0,"tv":0.0,"id":13024648},{"batb":[[0,1.25,139.17],[1,1.24,230.63],[2,1.18,133.6]],"ltp":1.4,"tv":885.75,"id":13024647},{"batb":[[0,10,10.86],[1,9.8,15.37],[2,7,12.12]],"ltp":0.0,"tv":0.0,"id":16575845}]}]}
{"op":"mcm","clk":"1003142774","pt":1580648424463,"mc":[{"id":"1.168224575","rc":[{"batb":[[0,6.4,14.56],[1,1.01,0.51],[2,6.4,0]],"ltp":0.0,"tv":0.0,"id":13024648},{"batb":[[0,1.18,133.6],[1,1.01,0.51],[2,1.18,0]],"ltp":1.4,"tv":885.75,"id":13024647},{"batb":[[0,7,12.12],[1,1.01,0.51],[2,7,0]],"ltp":0.0,"tv":0.0,"id":16575845}]}]}
{"op":"mcm","clk":"1003143303","pt":1580648427479,"mc":[{"id":"1.168224575","rc":[{"batb":[[0,6.6,39.25],[1,6.4,49.74],[2,1.01,0.51]],"ltp":0.0,"tv":0.0,"id":13024648},{"batb":[[0,1.18,238.6],[1,1.17,344.96],[2,1.01,0.51]],"ltp":1.4,"tv":885.75,"id":13024647},{"batb":[[0,7.8,20.09],[1,7.6,26.19],[2,7,12.12]],"ltp":0.0,"tv":0.0,"id":16575845}]}]}
{"op":"mcm","clk":"1003145050","pt":1580648438298,"mc":[{"id":"1.168224575","rc":[{"batb":[[0,6.4,14.56],[1,1.01,0.51],[2,1.01,0]],"ltp":0.0,"tv":0.0,"id":13024648},{"batb":[[0,7,12.12],[1,1.01,0.51],[2,7,0]],"ltp":0.0,"tv":0.0,"id":16575845}]}]}
{"op":"mcm","clk":"1003145439","pt":1580648440392,"mc":[{"id":"1.168224575","rc":[{"batb":[[0,11,30.48],[1,10.5,29.32],[2,6.4,14.56]],"ltp":0.0,"tv":0.0,"id":13024648},{"batb":[[0,13,12.46],[1,12.5,22.43],[2,7,12.12]],"ltp":0.0,"tv":0.0,"id":16575845}]}]}
{"op":"mcm","clk":"1003145579","pt":1580648441353,"mc":[{"id":"1.168224575","rc":[{"batb":[[2,10,12.51]],"batl":[[0,12.5,3.36],[1,13.5,11.49],[2,19,5.98]],"ltp":0.0,"tv":0.0,"id":13024648},{"batb":[[0,1.19,168.04],[1,1.18,238.6],[2,1.17,344.96]],"batl":[[0,1.22,125.97],[1,1.29,92.14],[2,1.4,60.03]],"ltp":1.4,"tv":885.75,"id":13024647},{"batb":[[2,10.5,11.49]],"batl":[[0,13.5,3.36],[1,14,10.54],[2,19.5,5.67]],"ltp":0.0,"tv":0.0,"id":16575845}]}]}
{"op":"mcm","clk":"1003145624","pt":1580648441708,"mc":[{"id":"1.168224575","rc":[{"batl":[[2,1.4,0]],"ltp":1.4,"tv":885.75,"id":13024647}]}]}
{"op":"mcm","clk":"1003146006","pt":1580648443814,"mc":[{"id":"1.168224575","rc":[{"trd":[[13,6.72]],"batb":[[0,13,9.1]],"ltp":13.0,"tv":6.72,"id":16575845}],"tv":958.62}]}
{"op":"mcm","clk":"1003146611","pt":1580648447396,"mc":[{"id":"1.168224575","rc":[{"batb":[[0,13,11.82]],"ltp":13.0,"tv":6.72,"id":16575845}]}]}
{"op":"mcm","clk":"1003147053","pt":1580648450022,"mc":[{"id":"1.168224575","rc":[{"batb":[[0,10,12.51],[1,9.6,4.2],[2,8.6,7.79]],"ltp":0.0,"tv":0.0,"id":13024648},{"batb":[[1,1.18,133.6],[2,1.12,204.73]],"ltp":1.4,"tv":885.75,"id":13024647},{"batb":[[0,10.5,11.49],[1,8.8,7.16],[2,1.01,0.51]],"ltp":13.0,"tv":6.72,"id":16575845}]}]}
{"op":"mcm","clk":"1003147304","pt":1580648451308,"mc":[{"id":"1.168224575","rc":[{"batb":[[0,9.6,4.2],[1,8.6,7.79],[2,1.01,0.51]],"batl":[[1,19,5.98],[2,19,0]],"ltp":0.0,"tv":0.0,"id":13024648},{"batb":[[1,1.12,204.73],[2,1.01,0.51]],"batl":[[0,1.29,92.14],[1,1.29,0]],"ltp":1.4,"tv":885.75,"id":13024647},{"batb":[[0,8.8,7.16],[1,1.01,0.51],[2,1.01,0]],"batl":[[1,19.5,5.67],[2,19.5,0]],"ltp":13.0,"tv":6.72,"id":16575845}]}]}
{"op":"mcm","clk":"1003147448","pt":1580648452123,"mc":[{"id":"1.168224575","rc":[{"batb":[[0,8.6,7.79],[1,1.01,0.51],[2,1.01,0]],"batl":[[0,19,5.98],[1,19,0]],"ltp":0.0,"tv":0.0,"id":13024648},{"batb":[[0,1.12,204.73],[1,1.01,0.51],[2,1.01,0]],"ltp":1.4,"tv":885.75,"id":13024647},{"batl":[[0,19.5,5.67],[1,19.5,0]],"ltp":13.0,"tv":6.72,"id":16575845}]}]}
{"op":"mcm","clk":"1003147670","pt":1580648453156,"mc":[{"id":"1.168224575","rc":[{"batb":[[0,9,17.01],[1,8.8,17.95],[2,8.6,7.79]],"ltp":0.0,"tv":0.0,"id":13024648},{"batb":[[1,1.11,195.87],[2,1.1,409.49]],"ltp":1.4,"tv":885.75,"id":13024647},{"batb":[[0,10.5,11.29],[1,10,35.83],[2,8.8,7.16]],"ltp":13.0,"tv":6.72,"id":16575845}]}]}
{"op":"mcm","clk":"1003147873","pt":1580648454332,"mc":[{"id":"1.168224575","rc":[{"batb":[[1,1.01,0.51],[2,1.1,0]],"ltp":1.4,"tv":885.75,"id":13024647}]}]}
{"op":"mcm","clk":"1003148223","pt":1580648456430,"mc":[{"id":"1.168224575","rc":[{"batl":[[0,11.5,100.21],[1,19.5,5.67]],"ltp":13.0,"tv":6.72,"id":16575845}]}]}
{"op":"mcm","clk":"1003148432","pt":1580648457409,"mc":[{"id":"1.168224575","rc":[{"batl":[[0,10,4.2],[1,10.5,7.47],[2,18.5,6.37]],"ltp":0.0,"tv":0.0,"id":13024648},{"batb":[[0,1.24,264.58],[1,1.23,260.34],[2,1.22,259.53]],"batl":[[1,1.4,59.72]],"ltp":1.4,"tv":885.75,"id":13024647},{"batl":[[0,11,17.07],[1,18.5,6.45]],"ltp":13.0,"tv":6.72,"id":16575845}]}]}
{"op":"mcm","clk":"1003148760","pt":1580648459457,"mc":[{"id":"1.168224575","rc":[{"batl":[[0,11,21.27]],"ltp":13.0,"tv":6.72,"id":16575845}]}]}
{"op":"mcm","clk":"1003150122","pt":1580648467380,"mc":[{"id":"1.168224575","rc":[{"batb":[[0,8.6,7.79],[1,8,5.88],[2,6.4,14.4]],"ltp":0.0,"tv":0.0,"id":13024648},{"batb":[[1,1.13,192.38],[2,1.01,0.51]],"ltp":1.4,"tv":885.75,"id":13024647},{"batb":[[0,8.8,7.16],[1,7,12.35],[2,1.01,0.51]],"ltp":13.0,"tv":6.72,"id":16575845}]}]}
{"op":"mcm","clk":"1003150253","pt":1580648468172,"mc":[{"id":"1.168224575","rc":[{"batb":[[0,6.4,14.4],[1,1.01,0.51],[2,6.4,0]],"batl":[[0,18.5,6.37],[1,10.5,0],[2,18.5,0]],"ltp":0.0,"tv":0.0,"id":13024648},{"batb":[[0,1.13,192.38],[1,1.01,0.51],[2,1.01,0]],"batl":[[0,1.4,59.72],[1,1.4,0]],"ltp":1.4,"tv":885.75,"id":13024647},{"batb":[[0,7,12.35],[1,1.01,0.51],[2,1.01,0]],"batl":[[0,18.5,6.45],[1,18.5,0]],"ltp":13.0,"tv":6.72,"id":16575845}]}]}
{"op":"mcm","clk":"1003150638","pt":1580648470291,"mc":[{"id":"1.168224575","rc":[{"batb":[[0,6.6,44.59],[1,6.4,49.5],[2,1.01,0.51]],"ltp":0.0,"tv":0.0,"id":13024648},{"batb":[[1,1.11,367.04],[2,1.1,236.77]],"ltp":1.4,"tv":885.75,"id":13024647},{"batb":[[0,7.8,29.74],[1,7.6,26.09],[2,7,12.35]],"ltp":13.0,"tv":6.72,"id":16575845}]}]}
{"op":"mcm","clk":"1003150795","pt":1580648471308,"mc":[{"id":"1.168224575","rc":[{"batb":[[0,6.6,58.36],[1,6.4,35.1]],"batl":[[0,19,6.06]],"ltp":0.0,"tv":0.0,"id":13024648},{"batb":[[0,1.12,198.83]],"batl":[[0,1.39,61.92]],"ltp":1.4,"tv":885.75,"id":13024647},{"batb":[[2,7,11.88]],"batl":[[0,19,6.14]],"ltp":13.0,"tv":6.72,"id":16575845}]}]}
{"op":"mcm","clk":"1003153153","pt":1580648485227,"mc":[{"id":"1.168224575","rc":[{"batb":[[0,6.6,13.77],[1,1.01,0.51],[2,1.01,0]],"ltp":0.0,"tv":0.0,"id":13024648},{"batb":[[1,1.01,0.51],[2,1.1,0]],"ltp":1.4,"tv":885.75,"id":13024647},{"batb":[[0,7,11.88],[1,1.01,0.51],[2,7,0]],"ltp":13.0,"tv":6.72,"id":16575845}]}]}
