{"op":"mcm","clk":"998156264","pt":1580585282814,"mc":[{"id":"1.168224571","marketDefinition":{"bspMarket":false,"turnInPlayEnabled":true,"persistenceEnabled":true,"marketBaseRate":5.0,"eventId":"29681732","eventTypeId":"2","numberOfWinners":1,"bettingType":"ODDS","marketType":"MATCH_ODDS","marketTime":"2020-02-02T09:00:00.000Z","suspendTime":"2020-02-02T09:00:00.000Z","bspReconciled":false,"complete":true,"inPlay":false,"crossMatching":false,"runnersVoidable":false,"numberOfActiveRunners":2,"betDelay":0,"status":"OPEN","runners":[{"status":"ACTIVE","sortPriority":1,"id":2284304,"name":"Sergiy Stakhovsky"},{"status":"ACTIVE","sortPriority":2,"id":7797764,"name":"Alexey Vatutin"}],"regulators":["MR_INT"],"countryCode":"FR","discountAllowed":false,"timezone":"UTC","openDate":"2020-02-02T09:00:00.000Z","version":3147099363,"name":"Match Odds","eventName":"Stakhovsky v Vatutin"},"rc":[{"batb":[[0,1.02,3786.16],[1,1.01,4069.07]],"ltp":0.0,"tv":0.0,"id":7797764},{"batb":[[0,1.05,152.2],[1,1.04,168.86],[2,1.03,190.07]],"ltp":0.0,"tv":0.0,"id":2284304}]}]}
{"op":"mcm","clk":"998156387","pt":1580585283539,"mc":[{"id":"1.168224571","marketDefinition":{"bspMarket":false,"turnInPlayEnabled":true,"persistenceEnabled":true,"marketBaseRate":5.0,"eventId":"29681732","eventTypeId":"2","numberOfWinners":1,"bettingType":"ODDS","marketType":"MATCH_ODDS","marketTime":"2020-02-02T09:00:00.000Z","suspendTime":"2020-02-02T09:00:00.000Z","bspReconciled":false,"complete":true,"inPlay":false,"crossMatching":false,"runnersVoidable":false,"numberOfActiveRunners":2,"betDelay":0,"status":"OPEN","runners":[{"status":"ACTIVE","sortPriority":1,"id":2284304,"name":"Sergiy Stakhovsky"},{"status":"ACTIVE","sortPriority":2,"id":7797764,"name":"Alexey Vatutin"}],"regulators":["MR_INT"],"countryCode":"FR","discountAllowed":true,"timezone":"UTC","openDate":"2020-02-02T09:00:00.000Z","version":3147099363,"name":"Match Odds","eventName":"Stakhovsky v Vatutin"}}]}
{"op":"mcm","clk":"998171142","pt":1580585373029,"mc":[{"id":"1.168224571","rc":[{"batb":[[1,1.01,4369.07]],"ltp":0.0,"tv":0.0,"id":7797764}]}]}
{"op":"mcm","clk":"998171821","pt":1580585377026,"mc":[{"id":"1.168224571","rc":[{"batb":[[1,1.01,4069.07]],"ltp":0.0,"tv":0.0,"id":7797764}]}]}
{"op":"mcm","clk":"998179115","pt":1580585420309,"mc":[{"id":"1.168224571","rc":[{"batb":[[1,1.01,4059.07]],"ltp":0.0,"tv":0.0,"id":7797764}]}]}
{"op":"mcm","clk":"998196992","pt":1580585517440,"mc":[{"id":"1.168224571","marketDefinition":{"bspMarket":false,"turnInPlayEnabled":true,"persistenceEnabled":true,"marketBaseRate":5.0,"eventId":"29681732","eventTypeId":"2","numberOfWinners":1,"bettingType":"ODDS","marketType":"MATCH_ODDS","marketTime":"2020-02-02T13:30:00.000Z","suspendTime":"2020-02-02T13:30:00.000Z","bspReconciled":false,"complete":true,"inPlay":false,"crossMatching":false,"runnersVoidable":false,"numberOfActiveRunners":2,"betDelay":0,"status":"OPEN","runners":[{"status":"ACTIVE","sortPriority":1,"id":2284304,"name":"Sergiy Stakhovsky"},{"status":"ACTIVE","sortPriority":2,"id":7797764,"name":"Alexey Vatutin"}],"regulators":["MR_INT"],"countryCode":"FR","discountAllowed":true,"timezone":"UTC","openDate":"2020-02-02T09:00:00.000Z","version":3147125171,"name":"Match Odds","eventName":"Stakhovsky v Vatutin"}}]}
{"op":"mcm","clk":"998197631","pt":1580585520453,"mc":[{"id":"1.168224571","marketDefinition":{"bspMarket":false,"turnInPlayEnabled":true,"persistenceEnabled":true,"marketBaseRate":5.0,"eventId":"29681732","eventTypeId":"2","numberOfWinners":1,"bettingType":"ODDS","marketType":"MATCH_ODDS","marketTime":"2020-02-02T13:30:00.000Z","suspendTime":"2020-02-02T13:30:00.000Z","bspReconciled":false,"complete":true,"inPlay":false,"crossMatching":false,"runnersVoidable":false,"numberOfActiveRunners":2,"betDelay":0,"status":"OPEN","runners":[{"status":"ACTIVE","sortPriority":1,"id":2284304,"name":"Sergiy Stakhovsky"},{"status":"ACTIVE","sortPriority":2,"id":7797764,"name":"Alexey Vatutin"}],"regulators":["MR_INT"],"countryCode":"FR","discountAllowed":true,"timezone":"UTC","openDate":"2020-02-02T13:30:00.000Z","version":3147125171,"name":"Match Odds","eventName":"Stakhovsky v Vatutin"}}]}
{"op":"mcm","clk":"998202128","pt":1580585544699,"mc":[{"id":"1.168224571","rc":[{"batb":[[0,1.03,100.96],[1,1.02,3786.16],[2,1.01,4059.07]],"ltp":0.0,"tv":0.0,"id":7797764},{"batb":[[0,1.06,50.48],[1,1.05,152.2],[2,1.04,168.86]],"ltp":0.0,"tv":0.0,"id":2284304}]}]}
{"op":"mcm","clk":"998203243","pt":1580585550629,"mc":[{"id":"1.168224571","marketDefinition":{"bspMarket":false,"turnInPlayEnabled":true,"persistenceEnabled":true,"marketBaseRate":5.0,"eventId":"29681732","eventTypeId":"2","numberOfWinners":1,"bettingType":"ODDS","marketType":"MATCH_ODDS","marketTime":"2020-02-02T13:30:00.000Z","suspendTime":"2020-02-02T13:30:00.000Z","bspReconciled":false,"complete":true,"inPlay":false,"crossMatching":true,"runnersVoidable":false,"numberOfActiveRunners":2,"betDelay":0,"status":"OPEN","runners":[{"status":"ACTIVE","sortPriority":1,"id":2284304,"name":"Sergiy Stakhovsky"},{"status":"ACTIVE","sortPriority":2,"id":7797764,"name":"Alexey Vatutin"}],"regulators":["MR_INT"],"countryCode":"FR","discountAllowed":true,"timezone":"UTC","openDate":"2020-02-02T13:30:00.000Z","version":3147125171,"name":"Match Odds","eventName":"Stakhovsky v Vatutin"}}]}
{"op":"mcm","clk":"998221621","pt":1580585649814,"mc":[{"id":"1.168224571","rc":[{"batb":[[2,1.01,4122.68]],"ltp":0.0,"tv":0.0,"id":7797764}]}]}
{"op":"mcm","clk":"998268435","pt":1580585919723,"mc":[{"id":"1.168224571","rc":[{"batl":[[0,48,31.05]],"ltp":0.0,"tv":0.0,"id":7797764},{"batl":[[0,48,31.05]],"ltp":0.0,"tv":0.0,"id":2284304}]}]}
{"op":"mcm","clk":"998344350","pt":1580586370245,"mc":[{"id":"1.168224571","rc":[{"batb":[[0,1.03,109.36],[1,1.02,3811.36]],"ltp":0.0,"tv":0.0,"id":7797764}]}]}
{"op":"mcm","clk":"998566225","pt":1580587948198,"mc":[{"id":"1.168224571","rc":[{"batl":[[1,990,2.2]],"ltp":0.0,"tv":0.0,"id":7797764},{"batl":[[1,990,2.2]],"ltp":0.0,"tv":0.0,"id":2284304}]}]}
{"op":"mcm","clk":"998801962","pt":1580589620186,"mc":[{"id":"1.168224571","rc":[{"batb":[[1,1.02,25.21],[2,1.01,336.52]],"ltp":0.0,"tv":0.0,"id":7797764}]}]}
{"op":"mcm","clk":"999008177","pt":1580591340943,"mc":[{"id":"1.168224571","rc":[{"batb":[[0,1.45,681.51],[1,1.06,50.48],[2,1.05,152.2]],"ltp":0.0,"tv":0.0,"id":2284304}]}]}
{"op":"mcm","clk":"999109486","pt":1580592155357,"mc":[{"id":"1.168224571","rc":[{"batb":[[0,1.46,6.02],[1,1.45,681.51],[2,1.06,50.48]],"ltp":0.0,"tv":0.0,"id":2284304}]}]}
{"op":"mcm","clk":"999138375","pt":1580592385901,"mc":[{"id":"1.168224571","rc":[{"batb":[[0,1.48,681.51],[1,1.46,6.02]],"ltp":0.0,"tv":0.0,"id":2284304}]}]}
{"op":"mcm","clk":"999384132","pt":1580594690376,"mc":[{"id":"1.168224571","rc":[{"batb":[[0,1.49,6.02],[1,1.48,681.51]],"ltp":0.0,"tv":0.0,"id":2284304}]}]}
{"op":"mcm","clk":"999858325","pt":1580601582398,"mc":[{"id":"1.168224571","rc":[{"batb":[[2,1.01,338.52]],"batl":[[2,1000,0.02]],"ltp":0.0,"tv":0.0,"id":7797764},{"batl":[[2,1000,0.02]],"ltp":0.0,"tv":0.0,"id":2284304}]}]}
{"op":"mcm","clk":"999858333","pt":1580601582500,"mc":[{"id":"1.168224571","rc":[{"batb":[[0,1.03,109.96]],"ltp":0.0,"tv":0.0,"id":7797764},{"batb":[[2,1.06,50.58]],"ltp":0.0,"tv":0.0,"id":2284304}]}]}
{"op":"mcm","clk":"999860226","pt":1580601626374,"mc":[{"id":"1.168224571","rc":[{"batb":[[0,1.03,110.06]],"ltp":0.0,"tv":0.0,"id":7797764},{"batb":[[2,1.06,50.68]],"ltp":0.0,"tv":0.0,"id":2284304}]}]}
{"op":"mcm","clk":"999887417","pt":1580602189360,"mc":[{"id":"1.168224571","rc":[{"batb":[[2,1.01,341.06]],"ltp":0.0,"tv":0.0,"id":7797764}]}]}
{"op":"mcm","clk":"999887494","pt":1580602190419,"mc":[{"id":"1.168224571","rc":[{"batb":[[2,1.01,339.03]],"ltp":0.0,"tv":0.0,"id":7797764}]}]}
{"op":"mcm","clk":"999983457","pt":1580603729397,"mc":[{"id":"1.168224571","rc":[{"batb":[[2,1.01,341.56]],"ltp":0.0,"tv":0.0,"id":7797764}]}]}
{"op":"mcm","clk":"999983515","pt":1580603730486,"mc":[{"id":"1.168224571","rc":[{"batb":[[2,1.01,339.54]],"ltp":0.0,"tv":0.0,"id":7797764}]}]}
{"op":"mcm","clk":"1000473014","pt":1580615092984,"mc":[{"id":"1.168224571","rc":[{"batl":[[0,990,2.2],[1,1000,0.02],[2,1000,0]],"ltp":0.0,"tv":0.0,"id":7797764},{"batl":[[0,990,2.2],[1,1000,0.02],[2,1000,0]],"ltp":0.0,"tv":0.0,"id":2284304}]}]}
{"op":"mcm","clk":"1000534630","pt":1580616351038,"mc":[{"id":"1.168224571","rc":[{"batl":[[0,95,15.9],[1,990,2.2],[2,1000,0.02]],"ltp":0.0,"tv":0.0,"id":7797764},{"batl":[[0,95,15.9],[1,990,2.2],[2,1000,0.02]],"ltp":0.0,"tv":0.0,"id":2284304}]}]}
{"op":"mcm","clk":"1000544296","pt":1580616562225,"mc":[{"id":"1.168224571","rc":[{"batb":[[0,1.13,75.82],[1,1.03,109.96],[2,1.02,25.21]],"ltp":0.0,"tv":0.0,"id":7797764},{"batb":[[2,1.13,75.82]],"ltp":0.0,"tv":0.0,"id":2284304}]}]}
{"op":"mcm","clk":"1001062555","pt":1580627598957,"mc":[{"id":"1.168224571","rc":[{"batb":[[0,1.14,15.22],[1,1.13,75.72],[2,1.03,109.96]],"batl":[[0,16,3.36],[1,95,15.9],[2,990,2.2]],"ltp":0.0,"tv":0.0,"id":7797764},{"batl":[[0,9.8,3.36],[1,95,15.9],[2,990,2.2]],"ltp":0.0,"tv":0.0,"id":2284304}]}]}
{"op":"mcm","clk":"1001088598","pt":1580628232297,"mc":[{"id":"1.168224571","rc":[{"batb":[[0,2.12,23.04],[1,1.14,15.22],[2,1.13,75.72]],"ltp":0.0,"tv":0.0,"id":7797764},{"batb":[[0,1.5,37.76],[1,1.49,6.02],[2,1.48,681.51]],"ltp":0.0,"tv":0.0,"id":2284304}]}]}
{"op":"mcm","clk":"1001088953","pt":1580628240007,"mc":[{"id":"1.168224571","rc":[{"batb":[[0,1.14,15.22],[1,1.13,75.72],[2,1.03,109.96]],"ltp":0.0,"tv":0.0,"id":7797764},{"batb":[[0,1.49,6.02],[1,1.48,681.51],[2,1.13,75.82]],"ltp":0.0,"tv":0.0,"id":2284304}]}]}
{"op":"mcm","clk":"1001089012","pt":1580628241292,"mc":[{"id":"1.168224571","rc":[{"batb":[[0,1.15,75.82],[1,1.14,15.12]],"ltp":0.0,"tv":0.0,"id":7797764},{"batb":[[0,1.5,37.76],[1,1.49,6.02],[2,1.48,681.51]],"ltp":0.0,"tv":0.0,"id":2284304}]}]}
{"op":"mcm","clk":"1001089434","pt":1580628252518,"mc":[{"id":"1.168224571","rc":[{"batb":[[0,1.79,22.12],[1,1.15,75.82],[2,1.14,15.12]],"ltp":0.0,"tv":0.0,"id":7797764}]}]}
{"op":"mcm","clk":"1001089944","pt":1580628265246,"mc":[{"id":"1.168224571","rc":[{"batb":[[2,1.03,109.96]],"ltp":0.0,"tv":0.0,"id":7797764}]}]}
{"op":"mcm","clk":"1001092392","pt":1580628326941,"mc":[{"id":"1.168224571","rc":[{"batb":[[0,1.95,21.91],[1,1.8,15.12],[2,1.15,75.82]],"ltp":0.0,"tv":0.0,"id":7797764}]}]}
{"op":"mcm","clk":"1001094268","pt":1580628372970,"mc":[{"id":"1.168224571","rc":[{"batb":[[1,1.93,46.95],[2,1.8,15.12]],"ltp":0.0,"tv":0.0,"id":7797764}]}]}
{"op":"mcm","clk":"1001095157","pt":1580628386715,"mc":[{"id":"1.168224571","rc":[{"batb":[[2,1.15,75.82]],"ltp":0.0,"tv":0.0,"id":7797764}]}]}
{"op":"mcm","clk":"1001097491","pt":1580628426133,"mc":[{"id":"1.168224571","rc":[{"batb":[[1,1.87,46.95]],"ltp":0.0,"tv":0.0,"id":7797764},{"batb":[[0,1.53,31.82],[1,1.52,62.09],[2,1.49,6.02]],"ltp":0.0,"tv":0.0,"id":2284304}]}]}
{"op":"mcm","clk":"1001098550","pt":1580628444999,"mc":[{"id":"1.168224571","rc":[{"batb":[[0,2.08,20.56],[1,2.02,46.95]],"ltp":0.0,"tv":0.0,"id":7797764},{"batb":[[0,1.64,29.57],[1,1.62,62.09]],"ltp":0.0,"tv":0.0,"id":2284304}]}]}
{"op":"mcm","clk":"1001099442","pt":1580628461810,"mc":[{"id":"1.168224571","rc":[{"batb":[[1,2,46.95]],"ltp":0.0,"tv":0.0,"id":7797764}]}]}
{"op":"mcm","clk":"1001104507","pt":1580628568067,"mc":[{"id":"1.168224571","rc":[{"batb":[[1,2.02,46.95]],"ltp":0.0,"tv":0.0,"id":7797764}]}]}
{"op":"mcm","clk":"1001105015","pt":1580628578894,"mc":[{"id":"1.168224571","rc":[{"batb":[[1,2,46.95]],"ltp":0.0,"tv":0.0,"id":7797764},{"batb":[[1,1.61,62.09]],"ltp":0.0,"tv":0.0,"id":2284304}]}]}
{"op":"mcm","clk":"1001106633","pt":1580628612447,"mc":[{"id":"1.168224571","rc":[{"batb":[[1,1.15,75.82],[2,1.03,109.96]],"ltp":0.0,"tv":0.0,"id":7797764},{"batb":[[1,1.49,6.02],[2,1.48,681.51]],"ltp":0.0,"tv":0.0,"id":2284304}]}]}
{"op":"mcm","clk":"1001106650","pt":1580628612709,"mc":[{"id":"1.168224571","rc":[{"batb":[[0,2.12,20.29],[1,2.1,46.95],[2,1.15,75.82]],"ltp":0.0,"tv":0.0,"id":7797764},{"batb":[[1,1.6,62.09],[2,1.49,6.02]],"ltp":0.0,"tv":0.0,"id":2284304}]}]}
{"op":"mcm","clk":"1001138575","pt":1580629308905,"mc":[{"id":"1.168224571","rc":[{"batb":[[2,1.31,37.86]],"ltp":0.0,"tv":0.0,"id":7797764}]}]}
{"op":"mcm","clk":"1001138710","pt":1580629310400,"mc":[{"id":"1.168224571","rc":[{"batb":[[2,1.71,37.86]],"ltp":0.0,"tv":0.0,"id":7797764},{"batb":[[2,1.51,37.86]],"ltp":0.0,"tv":0.0,"id":2284304}]}]}
{"op":"mcm","clk":"1001138726","pt":1580629310603,"mc":[{"id":"1.168224571","rc":[{"batb":[[2,1.81,37.86]],"ltp":0.0,"tv":0.0,"id":7797764}]}]}
{"op":"mcm","clk":"1001144411","pt":1580629414009,"mc":[{"id":"1.168224571","rc":[{"batb":[[1,1.59,62.09]],"ltp":0.0,"tv":0.0,"id":2284304}]}]}
{"op":"mcm","clk":"1001154873","pt":1580629664121,"mc":[{"id":"1.168224571","rc":[{"batb":[[1,1.58,62.09]],"ltp":0.0,"tv":0.0,"id":2284304}]}]}
{"op":"mcm","clk":"1001187180","pt":1580630449464,"mc":[{"id":"1.168224571","rc":[{"batb":[[1,1.51,37.86],[2,1.49,6.02]],"ltp":0.0,"tv":0.0,"id":2284304}]}]}
{"op":"mcm","clk":"1001187187","pt":1580630449566,"mc":[{"id":"1.168224571","rc":[{"batb":[[1,1.6,35.59],[2,1.51,37.86]],"ltp":0.0,"tv":0.0,"id":2284304}]}]}
{"op":"mcm","clk":"1001194395","pt":1580630583087,"mc":[{"id":"1.168224571","rc":[{"batb":[[1,1.58,35.59]],"ltp":0.0,"tv":0.0,"id":2284304}]}]}
{"op":"mcm","clk":"1001204145","pt":1580630748241,"mc":[{"id":"1.168224571","rc":[{"batb":[[0,2.1,46.95],[1,2,37.86]],"ltp":0.0,"tv":0.0,"id":7797764},{"batl":[[0,1.66,2.52],[1,9.8,3.36],[2,95,15.9]],"ltp":0.0,"tv":0.0,"id":2284304}]}]}
{"op":"mcm","clk":"1001204185","pt":1580630748756,"mc":[{"id":"1.168224571","rc":[{"batb":[[0,2.22,37.86],[1,2.1,46.95],[2,2,37.86]],"ltp":0.0,"tv":0.0,"id":7797764}]}]}
{"op":"mcm","clk":"1001204250","pt":1580630749847,"mc":[{"id":"1.168224571","rc":[{"batb":[[1,1.58,75.79]],"ltp":0.0,"tv":0.0,"id":2284304}]}]}
{"op":"mcm","clk":"1001206555","pt":1580630786936,"mc":[{"id":"1.168224571","rc":[{"batb":[[1,1.59,35.59],[2,1.58,40.2]],"ltp":0.0,"tv":0.0,"id":2284304}]}]}
{"op":"mcm","clk":"1001207464","pt":1580630802154,"mc":[{"id":"1.168224571","rc":[{"batl":[[1,95,15.9],[2,990,2.2]],"ltp":0.0,"tv":0.0,"id":2284304}]}]}
{"op":"mcm","clk":"1001210910","pt":1580630857829,"mc":[{"id":"1.168224571","rc":[{"batb":[[0,1.61,30.45]],"ltp":0.0,"tv":0.0,"id":2284304}]}]}
{"op":"mcm","clk":"1001211137","pt":1580630861445,"mc":[{"id":"1.168224571","rc":[{"batb":[[1,2.14,46.95]],"ltp":0.0,"tv":0.0,"id":7797764},{"batb":[[0,1.61,66.04],[1,1.58,40.2],[2,1.51,37.86]],"ltp":0.0,"tv":0.0,"id":2284304}]}]}
{"op":"mcm","clk":"1001211335","pt":1580630864239,"mc":[{"id":"1.168224571","rc":[{"batb":[[1,2.12,35.59]],"ltp":0.0,"tv":0.0,"id":7797764},{"batb":[[0,1.61,30.45],[1,1.6,35.59],[2,1.58,40.2]],"ltp":0.0,"tv":0.0,"id":2284304}]}]}
{"op":"mcm","clk":"1001213973","pt":1580630917322,"mc":[{"id":"1.168224571","rc":[{"trd":[[1.66,4.56]],"batb":[[0,1.6,35.59],[1,1.58,40.2],[2,1.51,37.86]],"batl":[[0,95,16.15],[1,990,2.2],[2,1000,0.13]],"ltp":1.66,"tv":4.55,"id":2284304}],"tv":4.55}]}
{"op":"mcm","clk":"1001214121","pt":1580630920409,"mc":[{"id":"1.168224571","rc":[{"batb":[[1,2,37.86],[2,1.81,37.86]],"ltp":0.0,"tv":0.0,"id":7797764},{"batb":[[0,1.58,40.2],[1,1.51,37.86],[2,1.49,6.02]],"ltp":1.66,"tv":4.55,"id":2284304}]}]}
{"op":"mcm","clk":"1001214126","pt":1580630920512,"mc":[{"id":"1.168224571","rc":[{"batb":[[0,1.6,35.59],[1,1.58,40.2],[2,1.51,37.86]],"ltp":1.66,"tv":4.55,"id":2284304}]}]}
{"op":"mcm","clk":"1001214261","pt":1580630923905,"mc":[{"id":"1.168224571","rc":[{"trd":[[2.22,42.31],[2.5,0.16]],"batb":[[0,2.22,16.7]],"ltp":2.22,"tv":42.47,"id":7797764},{"trd":[[1.66,4.8]],"batl":[[0,95,15.9]],"ltp":1.66,"tv":4.8,"id":2284304}],"tv":47.27}]}
{"op":"mcm","clk":"1001214378","pt":1580630926606,"mc":[{"id":"1.168224571","rc":[{"batl":[[0,11,3.36],[1,95,15.9],[2,990,2.2]],"ltp":1.66,"tv":4.8,"id":2284304}]}]}
{"op":"mcm","clk":"1001214504","pt":1580630929230,"mc":[{"id":"1.168224571","rc":[{"batb":[[0,1.58,40.2],[1,1.51,37.86],[2,1.49,6.02]],"ltp":1.66,"tv":4.8,"id":2284304}]}]}
{"op":"mcm","clk":"1001214621","pt":1580630932223,"mc":[{"id":"1.168224571","rc":[{"batb":[[2,1.86,48.46]],"ltp":2.22,"tv":42.47,"id":7797764},{"batb":[[0,1.59,35.59],[1,1.58,40.2],[2,1.51,37.86]],"ltp":1.66,"tv":4.8,"id":2284304}]}]}
{"op":"mcm","clk":"1001214667","pt":1580630933404,"mc":[{"id":"1.168224571","rc":[{"batb":[[2,1.91,48.46]],"ltp":2.22,"tv":42.47,"id":7797764},{"batb":[[0,1.61,27.09]],"ltp":1.66,"tv":4.8,"id":2284304}]}]}
{"op":"mcm","clk":"1001214847","pt":1580630937819,"mc":[{"id":"1.168224571","rc":[{"batb":[[2,1.93,48.46]],"ltp":2.22,"tv":42.47,"id":7797764}]}]}
{"op":"mcm","clk":"1001215347","pt":1580630949330,"mc":[{"id":"1.168224571","rc":[{"batb":[[2,1.93,35.59]],"ltp":2.22,"tv":42.47,"id":7797764}]}]}
{"op":"mcm","clk":"1001215378","pt":1580630949902,"mc":[{"id":"1.168224571","rc":[{"batb":[[2,1.91,35.59]],"ltp":2.22,"tv":42.47,"id":7797764},{"batb":[[1,1.59,35.59],[2,1.58,40.2]],"ltp":1.66,"tv":4.8,"id":2284304}]}]}
{"op":"mcm","clk":"1001216910","pt":1580630983954,"mc":[{"id":"1.168224571","rc":[{"batb":[[2,1.92,35.59]],"ltp":2.22,"tv":42.47,"id":7797764},{"batb":[[1,1.58,75.79],[2,1.51,37.86]],"ltp":1.66,"tv":4.8,"id":2284304}]}]}
{"op":"mcm","clk":"1001217385","pt":1580630993152,"mc":[{"id":"1.168224571","rc":[{"batb":[[1,1.58,40.2]],"ltp":1.66,"tv":4.8,"id":2284304}]}]}
{"op":"mcm","clk":"1001217413","pt":1580630993667,"mc":[{"id":"1.168224571","rc":[{"batb":[[1,2,73.45],[2,1.81,37.86]],"ltp":2.22,"tv":42.47,"id":7797764}]}]}
{"op":"mcm","clk":"1001217747","pt":1580631000898,"mc":[{"id":"1.168224571","rc":[{"batb":[[1,2,37.86],[2,1.98,35.59]],"ltp":2.22,"tv":42.47,"id":7797764},{"batb":[[1,1.58,75.79]],"ltp":1.66,"tv":4.8,"id":2284304}]}]}
{"op":"mcm","clk":"1001218063","pt":1580631006990,"mc":[{"id":"1.168224571","rc":[{"batb":[[2,1.98,46.19]],"ltp":2.22,"tv":42.47,"id":7797764}]}]}
{"op":"mcm","clk":"1001219367","pt":1580631034855,"mc":[{"id":"1.168224571","rc":[{"batb":[[1,1.58,40.2],[2,1.57,35.59]],"ltp":1.66,"tv":4.8,"id":2284304}]}]}
{"op":"mcm","clk":"1001224402","pt":1580631139359,"mc":[{"id":"1.168224571","rc":[{"batb":[[0,1.58,40.2],[1,1.57,35.59],[2,1.51,37.86]],"ltp":1.66,"tv":4.8,"id":2284304}]}]}
{"op":"mcm","clk":"1001227361","pt":1580631209468,"mc":[{"id":"1.168224571","rc":[{"batb":[[0,1.62,28.33],[1,1.58,40.2],[2,1.57,35.59]],"ltp":1.66,"tv":4.8,"id":2284304}]}]}
{"op":"mcm","clk":"1001237445","pt":1580631433852,"mc":[{"id":"1.168224571","rc":[{"batb":[[0,1.58,40.2],[1,1.57,35.59],[2,1.51,37.86]],"ltp":1.66,"tv":4.8,"id":2284304}]}]}
{"op":"mcm","clk":"1001239190","pt":1580631477855,"mc":[{"id":"1.168224571","rc":[{"batb":[[0,1.6,28.64],[1,1.58,40.2],[2,1.57,35.59]],"ltp":1.66,"tv":4.8,"id":2284304}]}]}
{"op":"mcm","clk":"1001251023","pt":1580631803635,"mc":[{"id":"1.168224571","rc":[{"batl":[[0,3,42.01],[1,11,3.36],[2,95,15.9]],"ltp":1.66,"tv":4.8,"id":2284304}]}]}
{"op":"mcm","clk":"1001251211","pt":1580631808457,"mc":[{"id":"1.168224571","rc":[{"batb":[[2,1.81,37.86]],"ltp":2.22,"tv":42.47,"id":7797764}]}]}
{"op":"mcm","clk":"1001251895","pt":1580631827900,"mc":[{"id":"1.168224571","rc":[{"batl":[[1,95,15.9],[2,990,2.2]],"ltp":1.66,"tv":4.8,"id":2284304}]}]}
{"op":"mcm","clk":"1001254502","pt":1580631886511,"mc":[{"id":"1.168224571","rc":[{"batl":[[0,2.98,3.36],[1,3,42.01],[2,95,15.9]],"ltp":1.66,"tv":4.8,"id":2284304}]}]}
{"op":"mcm","clk":"1001254540","pt":1580631887740,"mc":[{"id":"1.168224571","rc":[{"trd":[[2.22,75.72]],"batb":[[0,2,37.86],[1,1.81,37.86],[2,1.71,37.86]],"ltp":2.22,"tv":75.88,"id":7797764},{"batb":[[0,1.58,40.2],[1,1.57,35.59],[2,1.51,37.86]],"ltp":1.66,"tv":4.8,"id":2284304}],"tv":80.68}]}
{"op":"mcm","clk":"1001255544","pt":1580631909477,"mc":[{"id":"1.168224571","rc":[{"batb":[[0,1.66,25.43],[1,1.58,40.2],[2,1.57,57.55]],"ltp":1.66,"tv":4.8,"id":2284304}]}]}
{"op":"mcm","clk":"1001259711","pt":1580631992206,"mc":[{"id":"1.168224571","rc":[{"batl":[[0,2.44,34.45],[1,16,3.36],[2,95,15.9]],"ltp":2.22,"tv":75.88,"id":7797764}]}]}
{"op":"mcm","clk":"1001259773","pt":1580631993093,"mc":[{"id":"1.168224571","rc":[{"batl":[[0,2.4,17.54],[1,2.44,34.45],[2,16,3.36]],"ltp":2.22,"tv":75.88,"id":7797764},{"batb":[[0,1.61,37.86]],"ltp":1.66,"tv":4.8,"id":2284304}]}]}
{"op":"mcm","clk":"1001262154","pt":1580632042479,"mc":[{"id":"1.168224571","rc":[{"batl":[[0,2.44,34.45],[1,16,3.36],[2,95,15.9]],"ltp":2.22,"tv":75.88,"id":7797764}]}]}
{"op":"mcm","clk":"1001262159","pt":1580632042579,"mc":[{"id":"1.168224571","rc":[{"batl":[[0,2.4,26.39],[1,2.44,34.45],[2,16,3.36]],"ltp":2.22,"tv":75.88,"id":7797764}]}]}
{"op":"mcm","clk":"1001262260","pt":1580632044374,"mc":[{"id":"1.168224571","rc":[{"batb":[[2,1.8,35.97]],"ltp":2.22,"tv":75.88,"id":7797764},{"batb":[[0,1.7,41.11],[1,1.61,37.86],[2,1.58,40.2]],"ltp":1.66,"tv":4.8,"id":2284304}]}]}
{"op":"mcm","clk":"1001263364","pt":1580632066924,"mc":[{"id":"1.168224571","rc":[{"batl":[[2,95,15.9]],"ltp":2.22,"tv":75.88,"id":7797764}]}]}
{"op":"mcm","clk":"1001264327","pt":1580632089267,"mc":[{"id":"1.168224571","rc":[{"batb":[[1,1.83,34.67],[2,1.81,37.86]],"ltp":2.22,"tv":75.88,"id":7797764},{"batb":[[0,1.68,42.31]],"ltp":1.66,"tv":4.8,"id":2284304}]}]}
{"op":"mcm","clk":"1001270924","pt":1580632249828,"mc":[{"id":"1.168224571","rc":[{"batl":[[0,2.38,34.45],[1,2.4,26.39]],"ltp":2.22,"tv":75.88,"id":7797764}]}]}
{"op":"mcm","clk":"1001272742","pt":1580632302421,"mc":[{"id":"1.168224571","rc":[{"batb":[[0,1.67,42.95]],"ltp":1.66,"tv":4.8,"id":2284304}]}]}
{"op":"mcm","clk":"1001287038","pt":1580632661142,"mc":[{"id":"1.168224571","rc":[{"batb":[[1,1.81,37.86],[2,1.71,37.86]],"ltp":2.22,"tv":75.88,"id":7797764},{"batb":[[0,1.61,37.86],[1,1.58,40.2],[2,1.51,37.86]],"ltp":1.66,"tv":4.8,"id":2284304}]}]}
{"op":"mcm","clk":"1001287059","pt":1580632661709,"mc":[{"id":"1.168224571","rc":[{"batb":[[1,1.83,34.67],[2,1.81,37.86]],"ltp":2.22,"tv":75.88,"id":7797764},{"batb":[[0,1.68,42.31],[1,1.61,37.86],[2,1.58,40.2]],"ltp":1.66,"tv":4.8,"id":2284304}]}]}
{"op":"mcm","clk":"1001306534","pt":1580633092089,"mc":[{"id":"1.168224571","rc":[{"batl":[[0,3,42.01],[1,95,15.9],[2,990,2.2]],"ltp":1.66,"tv":4.8,"id":2284304}]}]}
{"op":"mcm","clk":"1001306786","pt":1580633096282,"mc":[{"id":"1.168224571","rc":[{"batb":[[0,1.67,42.95]],"ltp":1.66,"tv":4.8,"id":2284304}]}]}
{"op":"mcm","clk":"1001311483","pt":1580633184257,"mc":[{"id":"1.168224571","rc":[{"trd":[[2.38,3.67]],"batl":[[0,2.38,30.78]],"ltp":2.38,"tv":79.54,"id":7797764},{"trd":[[1.72,5.07]],"ltp":1.72,"tv":9.86,"id":2284304}],"tv":89.41}]}
{"op":"mcm","clk":"1001311511","pt":1580633184671,"mc":[{"id":"1.168224571","rc":[{"batl":[[0,2.34,28.06],[1,2.38,30.78]],"ltp":2.38,"tv":79.54,"id":7797764}]}]}
{"op":"mcm","clk":"1001318801","pt":1580633340305,"mc":[{"id":"1.168224571","rc":[{"batb":[[1,1.85,33.86]],"ltp":2.38,"tv":79.54,"id":7797764},{"batb":[[0,1.66,43.6]],"ltp":1.72,"tv":9.86,"id":2284304}]}]}
{"op":"mcm","clk":"1001334370","pt":1580633708144,"mc":[{"id":"1.168224571","rc":[{"batl":[[0,2.38,30.78],[1,95,15.9],[2,990,2.2]],"ltp":2.38,"tv":79.54,"id":7797764},{"batb":[[0,1.85,3.8],[1,1.66,43.6],[2,1.61,37.86]],"ltp":1.72,"tv":9.86,"id":2284304}]}]}
{"op":"mcm","clk":"1001345402","pt":1580634004909,"mc":[{"id":"1.168224571","rc":[{"batb":[[1,1.71,37.86],[2,1.66,43.6]],"ltp":1.72,"tv":9.86,"id":2284304}]}]}
{"op":"mcm","clk":"1001347636","pt":1580634048221,"mc":[{"id":"1.168224571","rc":[{"batb":[[0,2.04,53.49],[1,2,37.86],[2,1.85,33.86]],"ltp":2.38,"tv":79.54,"id":7797764},{"batb":[[1,1.8,66.75],[2,1.71,37.86]],"ltp":1.72,"tv":9.86,"id":2284304}]}]}
{"op":"mcm","clk":"1001350071","pt":1580634106809,"mc":[{"id":"1.168224571","rc":[{"batb":[[2,1.92,46.95]],"ltp":2.38,"tv":79.54,"id":7797764},{"batb":[[2,1.72,53.01]],"ltp":1.72,"tv":9.86,"id":2284304}]}]}
{"op":"mcm","clk":"1001362299","pt":1580634363391,"mc":[{"id":"1.168224571","rc":[{"batb":[[0,2.04,83.11]],"ltp":2.38,"tv":79.54,"id":7797764}]}]}
{"op":"mcm","clk":"1001362419","pt":1580634365459,"mc":[{"id":"1.168224571","rc":[{"batb":[[2,1.71,37.86]],"ltp":1.72,"tv":9.86,"id":2284304}]}]}
{"op":"mcm","clk":"1001362491","pt":1580634366491,"mc":[{"id":"1.168224571","rc":[{"batb":[[1,2,84.81],[2,1.88,32.7]],"ltp":2.38,"tv":79.54,"id":7797764}]}]}
{"op":"mcm","clk":"1001362701","pt":1580634370398,"mc":[{"id":"1.168224571","rc":[{"batb":[[1,2,37.86],[2,1.98,46.95]],"ltp":2.38,"tv":79.54,"id":7797764}]}]}
{"op":"mcm","clk":"1001378412","pt":1580634692090,"mc":[{"id":"1.168224571","rc":[{"batb":[[0,2.04,53.49]],"ltp":2.38,"tv":79.54,"id":7797764},{"batl":[[0,1.92,2.27],[1,3,42.01],[2,95,15.9]],"ltp":1.72,"tv":9.86,"id":2284304}]}]}
{"op":"mcm","clk":"1001415305","pt":1580635424015,"mc":[{"id":"1.168224571","rc":[{"trd":[[1.85,4.06]],"batb":[[0,1.85,1.77]],"ltp":1.85,"tv":13.92,"id":2284304}],"tv":93.47}]}
{"op":"mcm","clk":"1001426134","pt":1580635614335,"mc":[{"id":"1.168224571","marketDefinition":{"bspMarket":false,"turnInPlayEnabled":true,"persistenceEnabled":true,"marketBaseRate":5.0,"eventId":"29681732","eventTypeId":"2","numberOfWinners":1,"bettingType":"ODDS","marketType":"MATCH_ODDS","marketTime":"2020-02-02T13:24:00.000Z","suspendTime":"2020-02-02T13:24:00.000Z","bspReconciled":false,"complete":true,"inPlay":false,"crossMatching":true,"runnersVoidable":false,"numberOfActiveRunners":2,"betDelay":0,"status":"OPEN","runners":[{"status":"ACTIVE","sortPriority":1,"id":2284304,"name":"Sergiy Stakhovsky"},{"status":"ACTIVE","sortPriority":2,"id":7797764,"name":"Alexey Vatutin"}],"regulators":["MR_INT"],"countryCode":"FR","discountAllowed":true,"timezone":"UTC","openDate":"2020-02-02T13:30:00.000Z","version":3148345543,"name":"Match Odds","eventName":"Stakhovsky v Vatutin"}}]}
{"op":"mcm","clk":"1001426516","pt":1580635617339,"mc":[{"id":"1.168224571","marketDefinition":{"bspMarket":false,"turnInPlayEnabled":true,"persistenceEnabled":true,"marketBaseRate":5.0,"eventId":"29681732","eventTypeId":"2","numberOfWinners":1,"bettingType":"ODDS","marketType":"MATCH_ODDS","marketTime":"2020-02-02T13:24:00.000Z","suspendTime":"2020-02-02T13:24:00.000Z","bspReconciled":false,"complete":true,"inPlay":false,"crossMatching":true,"runnersVoidable":false,"numberOfActiveRunners":2,"betDelay":0,"status":"OPEN","runners":[{"status":"ACTIVE","sortPriority":1,"id":2284304,"name":"Sergiy Stakhovsky"},{"status":"ACTIVE","sortPriority":2,"id":7797764,"name":"Alexey Vatutin"}],"regulators":["MR_INT"],"countryCode":"FR","discountAllowed":true,"timezone":"UTC","openDate":"2020-02-02T13:24:00.000Z","version":3148345543,"name":"Match Odds","eventName":"Stakhovsky v Vatutin"}}]}
{"op":"mcm","clk":"1001428623","pt":1580635652996,"mc":[{"id":"1.168224571","rc":[{"batb":[[2,1.88,43.03]],"ltp":2.38,"tv":79.54,"id":7797764}]}]}
{"op":"mcm","clk":"1001446149","pt":1580635972496,"mc":[{"id":"1.168224571","rc":[{"batb":[[0,2.04,53.56]],"ltp":2.38,"tv":79.54,"id":7797764}]}]}
{"op":"mcm","clk":"1001446989","pt":1580635996221,"mc":[{"id":"1.168224571","rc":[{"trd":[[2.08,2]],"ltp":2.08,"tv":81.54,"id":7797764},{"trd":[[1.92,2.17]],"batl":[[0,3,42.12],[1,95,15.9],[2,990,2.2]],"ltp":1.92,"tv":16.09,"id":2284304}],"tv":97.63}]}
{"op":"mcm","clk":"1001447003","pt":1580635996786,"mc":[{"id":"1.168224571","rc":[{"batb":[[0,2.04,93.18]],"ltp":2.08,"tv":81.54,"id":7797764}]}]}
{"op":"mcm","clk":"1001447780","pt":1580636020215,"mc":[{"id":"1.168224571","rc":[{"batl":[[0,1.97,17.75],[1,3,42.01],[2,95,15.9]],"ltp":1.92,"tv":16.09,"id":2284304}]}]}
{"op":"mcm","clk":"1001454968","pt":1580636213247,"mc":[{"id":"1.168224571","rc":[{"batl":[[0,95,15.9],[1,990,2.2],[2,1000,0.13]],"ltp":2.08,"tv":81.54,"id":7797764}]}]}
{"op":"mcm","clk":"1001455397","pt":1580636222237,"mc":[{"id":"1.168224571","rc":[{"batl":[[0,2.24,33.63],[1,95,15.9],[2,990,2.2]],"ltp":2.08,"tv":81.54,"id":7797764}]}]}
{"op":"mcm","clk":"1001457641","pt":1580636272018,"mc":[{"id":"1.168224571","rc":[{"batb":[[1,1.8,66.82]],"ltp":1.92,"tv":16.09,"id":2284304}]}]}
{"op":"mcm","clk":"1001465036","pt":1580636443949,"mc":[{"id":"1.168224571","rc":[{"batl":[[1,2.5,74.21],[2,3,42.01]],"ltp":1.92,"tv":16.09,"id":2284304}]}]}
{"op":"mcm","clk":"1001493490","pt":1580636968350,"mc":[{"id":"1.168224571","rc":[{"batl":[[1,4.2,153.72],[2,95,15.9]],"ltp":2.08,"tv":81.54,"id":7797764}]}]}
{"op":"mcm","clk":"1001504497","pt":1580637162274,"mc":[{"id":"1.168224571","rc":[{"batb":[[0,2.04,53.56]],"ltp":2.08,"tv":81.54,"id":7797764},{"batl":[[0,1.92,7.68],[1,1.97,17.64],[2,2.5,74.21]],"ltp":1.92,"tv":16.09,"id":2284304}]}]}
{"op":"mcm","clk":"1001518061","pt":1580637411005,"mc":[{"id":"1.168224571","rc":[{"batb":[[0,2.04,53.49]],"ltp":2.08,"tv":81.54,"id":7797764}]}]}
{"op":"mcm","clk":"1001522439","pt":1580637470817,"mc":[{"id":"1.168224571","rc":[{"batb":[[0,2.04,53.56]],"ltp":2.08,"tv":81.54,"id":7797764}]}]}
{"op":"mcm","clk":"1001542348","pt":1580637744924,"mc":[{"id":"1.168224571","rc":[{"batb":[[2,1.98,46.19]],"ltp":2.08,"tv":81.54,"id":7797764}]}]}
{"op":"mcm","clk":"1001551120","pt":1580637847574,"mc":[{"id":"1.168224571","rc":[{"batl":[[2,2.4,15.14]],"ltp":1.92,"tv":16.09,"id":2284304}]}]}
{"op":"mcm","clk":"1001640432","pt":1580638777305,"mc":[{"id":"1.168224571","rc":[{"trd":[[2.24,33.57]],"batb":[[0,2.16,48.95],[1,2,37.94]],"batl":[[0,4.2,153.78],[1,95,15.9],[2,990,2.2]],"ltp":2.24,"tv":115.11,"id":7797764},{"trd":[[1.8,175.26],[1.81,0.15],[1.85,7.6]],"batb":[[0,1.72,69.08],[1,1.71,37.86],[2,1.69,54.52]],"ltp":1.8,"tv":195.04,"id":2284304}],"tv":310.16}]}
{"op":"mcm","clk":"1001640661","pt":1580638780017,"mc":[{"id":"1.168224571","rc":[{"batb":[[2,1.61,99.93]],"ltp":1.8,"tv":195.04,"id":2284304}]}]}
{"op":"mcm","clk":"1001640722","pt":1580638780608,"mc":[{"id":"1.168224571","rc":[{"batb":[[1,2.02,46.27],[2,2,37.86]],"ltp":2.24,"tv":115.11,"id":7797764}]}]}
{"op":"mcm","clk":"1001641196","pt":1580638786032,"mc":[{"id":"1.168224571","rc":[{"batl":[[0,4.2,153.72]],"ltp":2.24,"tv":115.11,"id":7797764}]}]}
{"op":"mcm","clk":"1001641484","pt":1580638789225,"mc":[{"id":"1.168224571","rc":[{"trd":[[2.16,0.14]],"batb":[[0,2.16,48.88]],"ltp":2.16,"tv":115.24,"id":7797764}],"tv":310.29}]}
{"op":"mcm","clk":"1001642190","pt":1580638797250,"mc":[{"id":"1.168224571","rc":[{"batb":[[1,2,84.13],[2,1.9,42.07]],"ltp":2.16,"tv":115.24,"id":7797764},{"batb":[[2,1.67,54.52]],"ltp":1.8,"tv":195.04,"id":2284304}]}]}
{"op":"mcm","clk":"1001642984","pt":1580638806454,"mc":[{"id":"1.168224571","rc":[{"batb":[[0,2.26,49.57]],"ltp":2.16,"tv":115.24,"id":7797764},{"batb":[[0,1.71,37.86],[1,1.68,48.09]],"ltp":1.8,"tv":195.04,"id":2284304}]}]}
{"op":"mcm","clk":"1001643066","pt":1580638807349,"mc":[{"id":"1.168224571","rc":[{"batb":[[2,1.81,37.86]],"ltp":2.16,"tv":115.24,"id":7797764},{"batb":[[0,1.68,103.95],[1,1.67,54.52],[2,1.61,37.86]],"ltp":1.8,"tv":195.04,"id":2284304}]}]}
{"op":"mcm","clk":"1001643142","pt":1580638808338,"mc":[{"id":"1.168224571","rc":[{"trd":[[2.26,99.04]],"batb":[[0,2,84.18],[1,1.92,41.16]],"ltp":2.26,"tv":214.28,"id":7797764},{"batb":[[0,1.68,48.09],[1,1.61,37.86],[2,1.59,64.18]],"batl":[[0,1.88,82.29],[1,1.92,7.68],[2,1.97,17.64]],"ltp":1.8,"tv":195.04,"id":2284304}],"tv":409.33}]}
{"op":"mcm","clk":"1001643200","pt":1580638809068,"mc":[{"id":"1.168224571","rc":[{"batb":[[0,2.16,48.41],[1,2,84.13],[2,1.92,41.16]],"ltp":2.26,"tv":214.28,"id":7797764},{"batb":[[0,1.72,69.75]],"batl":[[0,1.92,7.68],[1,1.97,17.64],[2,2.4,15.14]],"ltp":1.8,"tv":195.04,"id":2284304}]}]}
{"op":"mcm","clk":"1001643289","pt":1580638810164,"mc":[{"id":"1.168224571","rc":[{"batb":[[2,1.94,40.28]],"ltp":2.26,"tv":214.28,"id":7797764},{"batb":[[2,1.57,66.42]],"ltp":1.8,"tv":195.04,"id":2284304}]}]}
{"op":"mcm","clk":"1001643594","pt":1580638813765,"mc":[{"id":"1.168224571","rc":[{"batb":[[1,2,37.94],[2,1.98,46.19]],"ltp":2.26,"tv":214.28,"id":7797764},{"batb":[[1,1.63,56.04],[2,1.61,37.86]],"ltp":1.8,"tv":195.04,"id":2284304}]}]}
{"op":"mcm","clk":"1001651542","pt":1580638909087,"mc":[{"id":"1.168224571","rc":[{"batb":[[1,2,37.86]],"ltp":2.26,"tv":214.28,"id":7797764}]}]}
{"op":"mcm","clk":"1001656395","pt":1580638969589,"mc":[{"id":"1.168224571","rc":[{"batb":[[0,2.16,48.49]],"ltp":2.26,"tv":214.28,"id":7797764}]}]}
{"op":"mcm","clk":"1001715790","pt":1580639487858,"mc":[{"id":"1.168224571","rc":[{"batb":[[0,2.16,96.89]],"ltp":2.26,"tv":214.28,"id":7797764},{"batb":[[0,1.72,139.51]],"ltp":1.8,"tv":195.04,"id":2284304}]}]}
{"op":"mcm","clk":"1001765189","pt":1580639979752,"mc":[{"id":"1.168224571","rc":[{"batl":[[0,1.86,7.68],[1,1.92,7.57],[2,1.97,17.64]],"ltp":1.8,"tv":195.04,"id":2284304}]}]}
{"op":"mcm","clk":"1001765544","pt":1580639983780,"mc":[{"id":"1.168224571","rc":[{"batl":[[1,1.97,17.64],[2,2.4,15.14]],"ltp":1.8,"tv":195.04,"id":2284304}]}]}
{"op":"mcm","clk":"1001816438","pt":1580640415425,"mc":[{"id":"1.168224571","marketDefinition":{"bspMarket":false,"turnInPlayEnabled":true,"persistenceEnabled":true,"marketBaseRate":5.0,"eventId":"29681732","eventTypeId":"2","numberOfWinners":1,"bettingType":"ODDS","marketType":"MATCH_ODDS","marketTime":"2020-02-02T12:51:00.000Z","suspendTime":"2020-02-02T12:51:00.000Z","bspReconciled":false,"complete":true,"inPlay":false,"crossMatching":true,"runnersVoidable":false,"numberOfActiveRunners":2,"betDelay":0,"status":"OPEN","runners":[{"status":"ACTIVE","sortPriority":1,"id":2284304,"name":"Sergiy Stakhovsky"},{"status":"ACTIVE","sortPriority":2,"id":7797764,"name":"Alexey Vatutin"}],"regulators":["MR_INT"],"countryCode":"FR","discountAllowed":true,"timezone":"UTC","openDate":"2020-02-02T13:24:00.000Z","version":3148438471,"name":"Match Odds","eventName":"Stakhovsky v Vatutin"}}]}
{"op":"mcm","clk":"1001817075","pt":1580640420557,"mc":[{"id":"1.168224571","marketDefinition":{"bspMarket":false,"turnInPlayEnabled":true,"persistenceEnabled":true,"marketBaseRate":5.0,"eventId":"29681732","eventTypeId":"2","numberOfWinners":1,"bettingType":"ODDS","marketType":"MATCH_ODDS","marketTime":"2020-02-02T12:51:00.000Z","suspendTime":"2020-02-02T12:51:00.000Z","bspReconciled":false,"complete":true,"inPlay":false,"crossMatching":true,"runnersVoidable":false,"numberOfActiveRunners":2,"betDelay":0,"status":"OPEN","runners":[{"status":"ACTIVE","sortPriority":1,"id":2284304,"name":"Sergiy Stakhovsky"},{"status":"ACTIVE","sortPriority":2,"id":7797764,"name":"Alexey Vatutin"}],"regulators":["MR_INT"],"countryCode":"FR","discountAllowed":true,"timezone":"UTC","openDate":"2020-02-02T12:51:00.000Z","version":3148438471,"name":"Match Odds","eventName":"Stakhovsky v Vatutin"}}]}
{"op":"mcm","clk":"1001821997","pt":1580640461592,"mc":[{"id":"1.168224571","rc":[{"batb":[[2,1.94,50.75]],"ltp":2.26,"tv":214.28,"id":7797764},{"batb":[[1,1.61,37.86],[2,1.57,83.7]],"ltp":1.8,"tv":195.04,"id":2284304}]}]}
{"op":"mcm","clk":"1001853014","pt":1580640715139,"mc":[{"id":"1.168224571","marketDefinition":{"bspMarket":false,"turnInPlayEnabled":true,"persistenceEnabled":true,"marketBaseRate":5.0,"eventId":"29681732","eventTypeId":"2","numberOfWinners":1,"bettingType":"ODDS","marketType":"MATCH_ODDS","marketTime":"2020-02-02T12:48:00.000Z","suspendTime":"2020-02-02T12:48:00.000Z","bspReconciled":false,"complete":true,"inPlay":false,"crossMatching":true,"runnersVoidable":false,"numberOfActiveRunners":2,"betDelay":0,"status":"OPEN","runners":[{"status":"ACTIVE","sortPriority":1,"id":2284304,"name":"Sergiy Stakhovsky"},{"status":"ACTIVE","sortPriority":2,"id":7797764,"name":"Alexey Vatutin"}],"regulators":["MR_INT"],"countryCode":"FR","discountAllowed":true,"timezone":"UTC","openDate":"2020-02-02T12:51:00.000Z","version":3148443731,"name":"Match Odds","eventName":"Stakhovsky v Vatutin"}}]}
{"op":"mcm","clk":"1001853277","pt":1580640717181,"mc":[{"id":"1.168224571","marketDefinition":{"bspMarket":false,"turnInPlayEnabled":true,"persistenceEnabled":true,"marketBaseRate":5.0,"eventId":"29681732","eventTypeId":"2","numberOfWinners":1,"bettingType":"ODDS","marketType":"MATCH_ODDS","marketTime":"2020-02-02T12:48:00.000Z","suspendTime":"2020-02-02T12:48:00.000Z","bspReconciled":false,"complete":true,"inPlay":false,"crossMatching":true,"runnersVoidable":false,"numberOfActiveRunners":2,"betDelay":0,"status":"OPEN","runners":[{"status":"ACTIVE","sortPriority":1,"id":2284304,"name":"Sergiy Stakhovsky"},{"status":"ACTIVE","sortPriority":2,"id":7797764,"name":"Alexey Vatutin"}],"regulators":["MR_INT"],"countryCode":"FR","discountAllowed":true,"timezone":"UTC","openDate":"2020-02-02T12:48:00.000Z","version":3148443731,"name":"Match Odds","eventName":"Stakhovsky v Vatutin"}}]}
{"op":"mcm","clk":"1001897529","pt":1580641101912,"mc":[{"id":"1.168224571","rc":[{"batb":[[2,1.81,37.86]],"ltp":2.26,"tv":214.28,"id":7797764},{"batb":[[2,1.52,30.29]],"ltp":1.8,"tv":195.04,"id":2284304}]}]}
{"op":"mcm","clk":"1001897592","pt":1580641102536,"mc":[{"id":"1.168224571","rc":[{"batb":[[2,1.98,87.32]],"ltp":2.26,"tv":214.28,"id":7797764},{"batb":[[2,1.6,142.61]],"ltp":1.8,"tv":195.04,"id":2284304}]}]}
{"op":"mcm","clk":"1001920740","pt":1580641268418,"mc":[{"id":"1.168224571","rc":[{"batb":[[1,1.63,56.04],[2,1.61,37.86]],"ltp":1.8,"tv":195.04,"id":2284304}]}]}
{"op":"mcm","clk":"1001920842","pt":1580641269229,"mc":[{"id":"1.168224571","rc":[{"batb":[[2,1.98,133.51]],"ltp":2.26,"tv":214.28,"id":7797764},{"batl":[[0,1.85,7.57],[1,1.97,17.75]],"ltp":1.8,"tv":195.04,"id":2284304}]}]}
{"op":"mcm","clk":"1002129739","pt":1580642436177,"mc":[{"id":"1.168224571","rc":[{"batb":[[0,1.73,154.6],[1,1.72,139.51],[2,1.63,56.04]],"batl":[[0,1.84,145.35],[1,1.85,7.57],[2,1.97,17.75]],"ltp":1.8,"tv":195.04,"id":2284304}]}]}
{"op":"mcm","clk":"1002145289","pt":1580642526831,"mc":[{"id":"1.168224571","rc":[{"batb":[[0,2.2,56.91],[1,2,37.94]],"ltp":2.26,"tv":214.28,"id":7797764},{"batb":[[0,1.74,98.9],[1,1.73,154.6]],"ltp":1.8,"tv":195.04,"id":2284304}]}]}
{"op":"mcm","clk":"1002168250","pt":1580642660280,"mc":[{"id":"1.168224571","rc":[{"batb":[[1,2.02,115.89],[2,2,37.86]],"ltp":2.26,"tv":214.28,"id":7797764}]}]}
{"op":"mcm","clk":"1002171041","pt":1580642675800,"mc":[{"id":"1.168224571","rc":[{"batl":[[0,1.83,100],[1,1.84,145.35],[2,1.85,7.57]],"ltp":1.8,"tv":195.04,"id":2284304}]}]}
{"op":"mcm","clk":"1002194500","pt":1580642805241,"mc":[{"id":"1.168224571","rc":[{"batb":[[1,2.02,115.81]],"ltp":2.26,"tv":214.28,"id":7797764}]}]}
{"op":"mcm","clk":"1002206672","pt":1580642865758,"mc":[{"id":"1.168224571","rc":[{"batb":[[0,2.2,56.98]],"ltp":2.26,"tv":214.28,"id":7797764}]}]}
{"op":"mcm","clk":"1002243479","pt":1580643066474,"mc":[{"id":"1.168224571","rc":[{"batb":[[1,2,37.86],[2,1.95,124.34]],"ltp":2.26,"tv":214.28,"id":7797764},{"batb":[[2,1.67,176.31]],"ltp":1.8,"tv":195.04,"id":2284304}]}]}
{"op":"mcm","clk":"1002283643","pt":1580643274325,"mc":[{"id":"1.168224571","rc":[{"trd":[[2,75.72],[2.02,17.21],[2.16,6.71],[2.18,122.69],[2.2,139.37],[2.22,75.8]],"batb":[[0,1.95,124.34],[1,1.81,37.86],[2,1.71,37.86]],"ltp":2.0,"tv":575.92,"id":7797764},{"trd":[[1.82,0.09],[1.83,169.27],[1.84,145.35],[1.85,15.17],[1.86,0.11],[1.97,17.64]],"batl":[[0,2.4,15.14],[1,2.5,74.21],[2,3,42.01]],"ltp":1.97,"tv":535.08,"id":2284304}],"tv":1111.01}]}
{"op":"mcm","clk":"1002283856","pt":1580643275413,"mc":[{"id":"1.168224571","rc":[{"batb":[[0,2.02,18.55],[1,1.95,124.34],[2,1.81,37.86]],"ltp":2.0,"tv":575.92,"id":7797764},{"batb":[[0,1.84,7.61],[1,1.74,98.9],[2,1.73,154.6]],"ltp":1.97,"tv":535.08,"id":2284304}]}]}
{"op":"mcm","clk":"1002284039","pt":1580643276414,"mc":[{"id":"1.168224571","rc":[{"batb":[[1,1.81,37.86],[2,1.8,147.66]],"ltp":2.0,"tv":575.92,"id":7797764},{"batb":[[1,1.81,145.84],[2,1.74,98.9]],"ltp":1.97,"tv":535.08,"id":2284304}]}]}
{"op":"mcm","clk":"1002284334","pt":1580643278100,"mc":[{"id":"1.168224571","rc":[{"batb":[[0,2.08,114.04],[1,2.02,53.74],[2,1.81,37.86]],"ltp":2.0,"tv":575.92,"id":7797764},{"batb":[[1,1.82,36.19],[2,1.73,154.6]],"ltp":1.97,"tv":535.08,"id":2284304}]}]}
{"op":"mcm","clk":"1002284501","pt":1580643278996,"mc":[{"id":"1.168224571","rc":[{"batb":[[1,1.93,127.02]],"ltp":2.0,"tv":575.92,"id":7797764}]}]}
{"op":"mcm","clk":"1002284670","pt":1580643280003,"mc":[{"id":"1.168224571","rc":[{"batl":[[0,1.97,7.57],[1,2.4,15.14],[2,2.5,74.21]],"ltp":1.97,"tv":535.08,"id":2284304}]}]}
{"op":"mcm","clk":"1002286811","pt":1580643292031,"mc":[{"id":"1.168224571","rc":[{"batb":[[0,1.82,36.19],[1,1.73,154.6],[2,1.71,37.86]],"batl":[[0,2.4,15.14],[1,2.5,74.21],[2,3,42.01]],"ltp":1.97,"tv":535.08,"id":2284304}]}]}
{"op":"mcm","clk":"1002287035","pt":1580643293207,"mc":[{"id":"1.168224571","rc":[{"batb":[[0,1.83,7.66],[1,1.82,36.19],[2,1.73,154.6]],"ltp":1.97,"tv":535.08,"id":2284304}]}]}
{"op":"mcm","clk":"1002287133","pt":1580643293738,"mc":[{"id":"1.168224571","rc":[{"batl":[[0,1.97,7.57],[1,2.4,15.14],[2,2.5,74.21]],"ltp":1.97,"tv":535.08,"id":2284304}]}]}
{"op":"mcm","clk":"1002287856","pt":1580643297904,"mc":[{"id":"1.168224571","rc":[{"batl":[[0,1.92,7.57],[1,1.97,7.57],[2,2.4,15.14]],"ltp":1.97,"tv":535.08,"id":2284304}]}]}
{"op":"mcm","clk":"1002291054","pt":1580643315334,"mc":[{"id":"1.168224571","rc":[{"batl":[[0,2.2,34.42],[1,4.2,153.72],[2,95,15.9]],"ltp":2.0,"tv":575.92,"id":7797764}]}]}
{"op":"mcm","clk":"1002292848","pt":1580643325442,"mc":[{"id":"1.168224571","rc":[{"batb":[[1,1.77,125.68]],"ltp":1.97,"tv":535.08,"id":2284304}]}]}
{"op":"mcm","clk":"1002296899","pt":1580643347166,"mc":[{"id":"1.168224571","rc":[{"batb":[[1,1.81,37.86],[2,1.71,37.86]],"ltp":2.0,"tv":575.92,"id":7797764}]}]}
{"op":"mcm","clk":"1002297008","pt":1580643347784,"mc":[{"id":"1.168224571","rc":[{"batb":[[1,1.93,127.02],[2,1.81,37.86]],"ltp":2.0,"tv":575.92,"id":7797764}]}]}
{"op":"mcm","clk":"1002299144","pt":1580643358986,"mc":[{"id":"1.168224571","rc":[{"batb":[[0,2.08,108.9]],"ltp":2.0,"tv":575.92,"id":7797764},{"trd":[[1.92,17.31]],"batl":[[0,1.97,7.57],[1,2.4,15.14],[2,2.5,74.21]],"ltp":1.92,"tv":550.22,"id":2284304}],"tv":1126.15}]}
{"op":"mcm","clk":"1002299342","pt":1580643359899,"mc":[{"id":"1.168224571","rc":[{"batb":[[0,1.98,116.93]],"ltp":2.0,"tv":575.92,"id":7797764},{"trd":[[1.91,15.22]],"batb":[[0,1.85,121.09],[1,1.83,7.66]],"ltp":1.91,"tv":565.44,"id":2284304}],"tv":1141.37}]}
{"op":"mcm","clk":"1002299900","pt":1580643362473,"mc":[{"id":"1.168224571","rc":[{"batl":[[0,1.92,7.57],[1,1.97,7.57],[2,2.4,15.14]],"ltp":1.91,"tv":565.44,"id":2284304}]}]}
{"op":"mcm","clk":"1002300807","pt":1580643367198,"mc":[{"id":"1.168224571","rc":[{"batb":[[1,1.73,154.6],[2,1.71,37.86]],"batl":[[0,2.4,15.14],[1,2.5,74.21],[2,3,42.01]],"ltp":1.91,"tv":565.44,"id":2284304}]}]}
{"op":"mcm","clk":"1002301008","pt":1580643367872,"mc":[{"id":"1.168224571","rc":[{"batb":[[0,1.99,124.75],[1,1.98,116.93],[2,1.93,127.02]],"ltp":2.0,"tv":575.92,"id":7797764},{"batl":[[0,1.93,7.57],[1,2.4,15.14],[2,2.5,74.21]],"ltp":1.91,"tv":565.44,"id":2284304}]}]}
{"op":"mcm","clk":"1002301133","pt":1580643368521,"mc":[{"id":"1.168224571","rc":[{"batb":[[0,1.86,7.53],[1,1.85,121.09],[2,1.73,154.6]],"ltp":1.91,"tv":565.44,"id":2284304}]}]}
{"op":"mcm","clk":"1002301480","pt":1580643370503,"mc":[{"id":"1.168224571","rc":[{"batl":[[0,1.92,7.57],[1,1.93,7.57],[2,2.4,15.14]],"ltp":1.91,"tv":565.44,"id":2284304}]}]}
{"op":"mcm","clk":"1002301762","pt":1580643372151,"mc":[{"id":"1.168224571","rc":[{"batl":[[1,1.97,7.57]],"ltp":1.91,"tv":565.44,"id":2284304}]}]}
{"op":"mcm","clk":"1002309708","pt":1580643417344,"mc":[{"id":"1.168224571","rc":[{"batl":[[0,1.97,7.57],[1,2.4,15.14],[2,2.5,74.21]],"ltp":1.91,"tv":565.44,"id":2284304}]}]}
{"op":"mcm","clk":"1002309930","pt":1580643418617,"mc":[{"id":"1.168224571","rc":[{"batl":[[0,1.92,7.57],[1,1.97,7.57],[2,2.4,15.14]],"ltp":1.91,"tv":565.44,"id":2284304}]}]}
{"op":"mcm","clk":"1002314713","pt":1580643446142,"mc":[{"id":"1.168224571","rc":[{"batl":[[0,1.91,7.57],[1,1.92,7.57],[2,1.97,7.57]],"ltp":1.91,"tv":565.44,"id":2284304}]}]}
{"op":"mcm","clk":"1002315220","pt":1580643448533,"mc":[{"id":"1.168224571","rc":[{"batl":[[0,1.92,7.57],[1,1.97,7.57],[2,2.4,15.14]],"ltp":1.91,"tv":565.44,"id":2284304}]}]}
{"op":"mcm","clk":"1002316521","pt":1580643456014,"mc":[{"id":"1.168224571","rc":[{"batb":[[0,2,97.94],[1,1.99,124.75]],"ltp":2.0,"tv":575.92,"id":7797764},{"trd":[[1.92,32.45]],"batb":[[0,1.87,81.35],[1,1.86,7.53]],"batl":[[0,1.97,7.57],[1,2.4,15.14],[2,2.5,74.21]],"ltp":1.92,"tv":580.58,"id":2284304}],"tv":1156.51}]}
{"op":"mcm","clk":"1002317611","pt":1580643461876,"mc":[{"id":"1.168224571","rc":[{"batb":[[0,1.9,7.57],[1,1.87,81.35],[2,1.86,7.53]],"ltp":1.92,"tv":580.58,"id":2284304}]}]}
{"op":"mcm","clk":"1002318516","pt":1580643466817,"mc":[{"id":"1.168224571","rc":[{"batb":[[0,1.91,7.57],[1,1.9,7.57],[2,1.87,81.35]],"ltp":1.92,"tv":580.58,"id":2284304}]}]}
{"op":"mcm","clk":"1002318710","pt":1580643467998,"mc":[{"id":"1.168224571","rc":[{"batb":[[1,1.87,81.35],[2,1.86,7.53]],"ltp":1.92,"tv":580.58,"id":2284304}]}]}
{"op":"mcm","clk":"1002319272","pt":1580643471193,"mc":[{"id":"1.168224571","rc":[{"batb":[[0,1.87,81.35],[1,1.73,154.6],[2,1.71,37.86]],"batl":[[0,2.4,15.14],[1,2.5,74.21],[2,3,42.01]],"ltp":1.92,"tv":580.58,"id":2284304}]}]}
{"op":"mcm","clk":"1002319475","pt":1580643472369,"mc":[{"id":"1.168224571","rc":[{"batb":[[0,1.88,15.19],[1,1.87,81.35],[2,1.73,154.6]],"ltp":1.92,"tv":580.58,"id":2284304}]}]}
{"op":"mcm","clk":"1002319508","pt":1580643472578,"mc":[{"id":"1.168224571","rc":[{"batl":[[0,1.97,7.57],[1,2.4,15.14],[2,2.5,74.21]],"ltp":1.92,"tv":580.58,"id":2284304}]}]}
{"op":"mcm","clk":"1002328071","pt":1580643517109,"mc":[{"id":"1.168224571","rc":[{"batb":[[1,1.93,127.02],[2,1.81,37.86]],"ltp":2.0,"tv":575.92,"id":7797764}]}]}
{"op":"mcm","clk":"1002333954","pt":1580643550246,"mc":[{"id":"1.168224571","rc":[{"batl":[[0,1.92,7.57],[1,1.97,7.57],[2,2.4,15.14]],"ltp":1.92,"tv":580.58,"id":2284304}]}]}
{"op":"mcm","clk":"1002336951","pt":1580643566748,"mc":[{"id":"1.168224571","rc":[{"batl":[[0,1.92,11.36]],"ltp":1.92,"tv":580.58,"id":2284304}]}]}
{"op":"mcm","clk":"1002340097","pt":1580643583389,"mc":[{"id":"1.168224571","rc":[{"batb":[[0,1.93,127.02],[1,1.81,37.86],[2,1.71,37.86]],"ltp":2.0,"tv":575.92,"id":7797764},{"batb":[[1,1.73,154.6],[2,1.71,37.86]],"ltp":1.92,"tv":580.58,"id":2284304}]}]}
{"op":"mcm","clk":"1002340130","pt":1580643583594,"mc":[{"id":"1.168224571","rc":[{"batb":[[0,1.98,124.09],[1,1.93,127.02],[2,1.81,37.86]],"ltp":2.0,"tv":575.92,"id":7797764},{"batb":[[1,1.84,129.89],[2,1.73,154.6]],"ltp":1.92,"tv":580.58,"id":2284304}]}]}
{"op":"mcm","clk":"1002341382","pt":1580643590905,"mc":[{"id":"1.168224571","rc":[{"batb":[[0,1.84,129.89],[1,1.73,154.6],[2,1.71,37.86]],"ltp":1.92,"tv":580.58,"id":2284304}]}]}
{"op":"mcm","clk":"1002341971","pt":1580643594230,"mc":[{"id":"1.168224571","rc":[{"batl":[[0,1.92,3.79],[1,2.4,15.14],[2,2.5,74.21]],"ltp":1.92,"tv":580.58,"id":2284304}]}]}
{"op":"mcm","clk":"1002342190","pt":1580643595417,"mc":[{"id":"1.168224571","rc":[{"batb":[[0,1.85,15.43],[1,1.84,129.89],[2,1.73,154.6]],"ltp":1.92,"tv":580.58,"id":2284304}]}]}
{"op":"mcm","clk":"1002342478","pt":1580643597008,"mc":[{"id":"1.168224571","rc":[{"batl":[[1,1.97,7.57],[2,2.4,15.14]],"ltp":1.92,"tv":580.58,"id":2284304}]}]}
{"op":"mcm","clk":"1002355817","pt":1580643673115,"mc":[{"id":"1.168224571","rc":[{"batb":[[0,2.04,2.12],[1,2.02,2.24],[2,1.98,124.09]],"batl":[[1,2.22,2.03],[2,2.24,2]],"ltp":2.0,"tv":575.92,"id":7797764},{"batb":[[2,1.83,2.03]],"batl":[[1,1.94,2.08],[2,1.95,2.1]],"ltp":1.92,"tv":580.58,"id":2284304}]}]}
{"op":"mcm","clk":"1002363675","pt":1580643714489,"mc":[{"id":"1.168224571","rc":[{"batb":[[1,1.83,2.03],[2,1.82,2.03]],"ltp":1.92,"tv":580.58,"id":2284304}]}]}
{"op":"mcm","clk":"1002363866","pt":1580643715344,"mc":[{"id":"1.168224571","rc":[{"batb":[[1,2.02,2.09]],"batl":[[2,2.24,2.23]],"ltp":2.0,"tv":575.92,"id":7797764},{"batb":[[0,1.86,97.21],[1,1.85,15.43],[2,1.84,2.1]],"batl":[[2,1.95,2.04]],"ltp":1.92,"tv":580.58,"id":2284304}]}]}
{"op":"mcm","clk":"1002364492","pt":1580643718366,"mc":[{"id":"1.168224571","rc":[{"batb":[[1,1.84,2.1],[2,1.83,2.03]],"ltp":1.92,"tv":580.58,"id":2284304}]}]}
{"op":"mcm","clk":"1002364905","pt":1580643720285,"mc":[{"id":"1.168224571","rc":[{"batl":[[0,2.2,36.45],[1,2.22,2.07]],"ltp":2.0,"tv":575.92,"id":7797764},{"batb":[[0,1.87,15.27],[1,1.86,97.21],[2,1.85,2.04]],"ltp":1.92,"tv":580.58,"id":2284304}]}]}
{"op":"mcm","clk":"1002365030","pt":1580643720883,"mc":[{"id":"1.168224571","rc":[{"batb":[[1,2.02,2.2]],"batl":[[2,4.2,153.72]],"ltp":2.0,"tv":575.92,"id":7797764},{"batl":[[2,1.95,2.1]],"ltp":1.92,"tv":580.58,"id":2284304}]}]}
{"op":"mcm","clk":"1002376421","pt":1580643783234,"mc":[{"id":"1.168224571","rc":[{"trd":[[2.04,5.79],[2.06,1.96],[2.08,5.49]],"batb":[[0,1.98,124.09],[1,1.93,127.02],[2,1.81,37.86]],"batl":[[1,2.22,2.16]],"ltp":2.04,"tv":587.16,"id":7797764},{"trd":[[1.92,36.24],[1.94,2.08],[1.95,1.63]],"batl":[[0,2.4,15.14],[1,2.5,74.21],[2,3,42.01]],"ltp":1.95,"tv":588.08,"id":2284304}],"tv":1175.25}]}
{"op":"mcm","clk":"1002376927","pt":1580643785960,"mc":[{"id":"1.168224571","rc":[{"batb":[[0,1.99,124.75],[1,1.98,124.09],[2,1.93,127.02]],"ltp":2.04,"tv":587.16,"id":7797764}]}]}
{"op":"mcm","clk":"1002377288","pt":1580643788081,"mc":[{"id":"1.168224571","rc":[{"batl":[[0,1.97,7.57],[1,2.4,15.14],[2,2.5,74.21]],"ltp":1.95,"tv":588.08,"id":2284304}]}]}
{"op":"mcm","clk":"1002377866","pt":1580643791469,"mc":[{"id":"1.168224571","rc":[{"batb":[[0,1.98,124.09],[1,1.93,127.02],[2,1.81,37.86]],"batl":[[1,4.2,153.72],[2,95,15.9]],"ltp":2.04,"tv":587.16,"id":7797764}]}]}
{"op":"mcm","clk":"1002377894","pt":1580643791644,"mc":[{"id":"1.168224571","rc":[{"batl":[[1,2.22,2.16],[2,4.2,153.72]],"ltp":2.04,"tv":587.16,"id":7797764}]}]}
{"op":"mcm","clk":"1002378415","pt":1580643794472,"mc":[{"id":"1.168224571","rc":[{"batl":[[0,2.16,34.42],[1,2.2,2.03],[2,2.22,2.16]],"ltp":2.04,"tv":587.16,"id":7797764},{"batb":[[0,1.86,97.21],[1,1.84,2.72],[2,1.83,2.68]],"batl":[[0,2.4,15.14],[1,2.5,74.21],[2,3,42.01]],"ltp":1.95,"tv":588.08,"id":2284304}]}]}
{"op":"mcm","clk":"1002378607","pt":1580643795493,"mc":[{"id":"1.168224571","rc":[{"batb":[[0,1.89,15.11],[1,1.86,97.21],[2,1.84,2.72]],"batl":[[0,1.97,7.57],[1,2.4,15.14],[2,2.5,74.21]],"ltp":1.95,"tv":588.08,"id":2284304}]}]}
{"op":"mcm","clk":"1002378644","pt":1580643795672,"mc":[{"id":"1.168224571","rc":[{"batl":[[1,2.18,2.03],[2,2.2,2.03]],"ltp":2.04,"tv":587.16,"id":7797764},{"batb":[[1,1.87,2.35],[2,1.86,100.39]],"ltp":1.95,"tv":588.08,"id":2284304}]}]}
{"op":"mcm","clk":"1002380948","pt":1580643808490,"mc":[{"id":"1.168224571","rc":[{"batl":[[2,2.6,495.23]],"ltp":2.04,"tv":587.16,"id":7797764},{"batb":[[2,1.86,99.89]],"ltp":1.95,"tv":588.08,"id":2284304}]}]}
{"op":"mcm","clk":"1002380967","pt":1580643808552,"mc":[{"id":"1.168224571","rc":[{"batl":[[2,2.2,2.03]],"ltp":2.04,"tv":587.16,"id":7797764}]}]}
{"op":"mcm","clk":"1002424802","pt":1580644061276,"mc":[{"id":"1.168224571","rc":[{"batb":[[0,1.88,15.11],[1,1.86,99.89],[2,1.85,2.57]],"ltp":1.95,"tv":588.08,"id":2284304}]}]}
{"op":"mcm","clk":"1002428399","pt":1580644083204,"mc":[{"id":"1.168224571","rc":[{"batb":[[1,1.81,37.86],[2,1.71,37.86]],"ltp":2.04,"tv":587.16,"id":7797764}]}]}
{"op":"mcm","clk":"1002428475","pt":1580644083689,"mc":[{"id":"1.168224571","rc":[{"batl":[[2,2.2,2.93]],"ltp":2.04,"tv":587.16,"id":7797764},{"batb":[[2,1.85,2.17]],"ltp":1.95,"tv":588.08,"id":2284304}]}]}
{"op":"mcm","clk":"1002428706","pt":1580644085322,"mc":[{"id":"1.168224571","rc":[{"batb":[[0,1.98,149.81]],"ltp":2.04,"tv":587.16,"id":7797764},{"batb":[[1,1.86,129.2]],"ltp":1.95,"tv":588.08,"id":2284304}]}]}
{"op":"mcm","clk":"1002482302","pt":1580644502384,"mc":[{"id":"1.168224571","rc":[{"batl":[[1,2.2,2.63],[2,2.22,2.75]],"ltp":2.04,"tv":587.16,"id":7797764},{"trd":[[1.88,30.22]],"batb":[[0,1.86,126.52],[1,1.84,2.16],[2,1.83,2]],"ltp":1.88,"tv":618.3,"id":2284304}],"tv":1205.46}]}
{"op":"mcm","clk":"1002483173","pt":1580644510422,"mc":[{"id":"1.168224571","rc":[{"batl":[[2,2.22,3.25]],"ltp":2.04,"tv":587.16,"id":7797764},{"batb":[[0,1.86,97.21],[1,1.85,29.65],[2,1.84,2.16]],"batl":[[0,1.92,7.57],[1,1.97,7.57],[2,2.4,15.14]],"ltp":1.88,"tv":618.3,"id":2284304}]}]}
{"op":"mcm","clk":"1002496886","pt":1580644622430,"mc":[{"id":"1.168224571","rc":[{"batl":[[2,2.6,495.23]],"ltp":2.04,"tv":587.16,"id":7797764},{"trd":[[1.86,9.19]],"batb":[[0,1.86,92.67]],"ltp":1.86,"tv":627.39,"id":2284304}],"tv":1214.55}]}
{"op":"mcm","clk":"1002497033","pt":1580644623457,"mc":[{"id":"1.168224571","rc":[{"batb":[[0,2.04,52.37],[1,2,25.21],[2,1.98,25.72]],"batl":[[2,2.22,3.25]],"ltp":2.04,"tv":587.16,"id":7797764},{"batb":[[1,1.84,32.16],[2,1.83,2.03]],"ltp":1.86,"tv":627.39,"id":2284304}]}]}
{"op":"mcm","clk":"1002498587","pt":1580644636353,"mc":[{"id":"1.168224571","rc":[{"batb":[[0,1.86,96.16]],"ltp":1.86,"tv":627.39,"id":2284304}]}]}
{"op":"mcm","clk":"1002498644","pt":1580644636860,"mc":[{"id":"1.168224571","rc":[{"batl":[[2,2.22,2.75]],"ltp":2.04,"tv":587.16,"id":7797764}]}]}
{"op":"mcm","clk":"1002502533","pt":1580644671398,"mc":[{"id":"1.168224571","rc":[{"trd":[[2.08,12.48]],"batl":[[0,2.08,26.62],[1,2.12,2.96],[2,2.14,3.25]],"ltp":2.08,"tv":594.15,"id":7797764},{"trd":[[1.92,43.81]],"batb":[[0,1.9,2.06],[1,1.89,2],[2,1.86,96.16]],"batl":[[0,1.97,7.57],[1,2.4,15.14],[2,2.5,74.21]],"ltp":1.92,"tv":634.96,"id":2284304}],"tv":1229.11}]}
{"op":"mcm","clk":"1002502543","pt":1580644671545,"mc":[{"id":"1.168224571","rc":[{"batb":[[1,1.97,25.99],[2,1.81,37.86]],"ltp":2.08,"tv":594.15,"id":7797764},{"batb":[[2,1.87,28.97]],"ltp":1.92,"tv":634.96,"id":2284304}]}]}
{"op":"mcm","clk":"1002503977","pt":1580644684401,"mc":[{"id":"1.168224571","rc":[{"batl":[[0,2.12,2.96],[1,2.14,3.25],[2,2.16,37.39]],"ltp":2.08,"tv":594.15,"id":7797764},{"batb":[[1,1.87,28.97],[2,1.86,96.16]],"ltp":1.92,"tv":634.96,"id":2284304}]}]}
{"op":"mcm","clk":"1002504094","pt":1580644685389,"mc":[{"id":"1.168224571","rc":[{"batb":[[1,2,25.21],[2,1.97,25.99]],"batl":[[0,2.16,34.42],[1,2.2,2.68],[2,2.22,2.75]],"ltp":2.08,"tv":594.15,"id":7797764},{"batb":[[0,1.86,98.34],[1,1.85,2.17],[2,1.84,32.04]],"ltp":1.92,"tv":634.96,"id":2284304}]}]}
{"op":"mcm","clk":"1002504106","pt":1580644685542,"mc":[{"id":"1.168224571","rc":[{"batb":[[0,1.86,96.16],[1,1.84,32.04],[2,1.83,2]],"ltp":1.92,"tv":634.96,"id":2284304}]}]}
{"op":"mcm","clk":"1002504366","pt":1580644687531,"mc":[{"id":"1.168224571","rc":[{"batl":[[0,2.4,15.14],[1,2.5,74.21],[2,2.6,495.23]],"ltp":1.92,"tv":634.96,"id":2284304}]}]}
{"op":"mcm","clk":"1002504540","pt":1580644688995,"mc":[{"id":"1.168224571","rc":[{"batl":[[1,2.18,3.25],[2,2.2,2.68]],"ltp":2.08,"tv":594.15,"id":7797764},{"batb":[[0,1.89,7.77],[1,1.87,2.04],[2,1.86,98.16]],"batl":[[0,1.96,7.57],[1,2.4,15.14],[2,2.5,74.21]],"ltp":1.92,"tv":634.96,"id":2284304}]}]}
{"op":"mcm","clk":"1002505086","pt":1580644693462,"mc":[{"id":"1.168224571","rc":[{"batb":[[0,1.88,7.77]],"ltp":1.92,"tv":634.96,"id":2284304}]}]}
{"op":"mcm","clk":"1002505153","pt":1580644694047,"mc":[{"id":"1.168224571","rc":[{"batl":[[2,2.2,2.83]],"ltp":2.08,"tv":594.15,"id":7797764},{"batb":[[1,1.86,98.16],[2,1.85,2]],"ltp":1.92,"tv":634.96,"id":2284304}]}]}
{"op":"mcm","clk":"1002505750","pt":1580644699233,"mc":[{"id":"1.168224571","rc":[{"batb":[[1,1.86,94.67]],"ltp":1.92,"tv":634.96,"id":2284304}]}]}
{"op":"mcm","clk":"1002507667","pt":1580644715972,"mc":[{"id":"1.168224571","rc":[{"batl":[[2,2.2,2.78]],"ltp":2.08,"tv":594.15,"id":7797764},{"batb":[[2,1.85,2.04]],"ltp":1.92,"tv":634.96,"id":2284304}]}]}
{"op":"mcm","clk":"1002508112","pt":1580644719509,"mc":[{"id":"1.168224571","rc":[{"batl":[[0,1.94,7.57],[1,1.96,7.57],[2,2.4,15.14]],"ltp":1.92,"tv":634.96,"id":2284304}]}]}
{"op":"mcm","clk":"1002508397","pt":1580644721813,"mc":[{"id":"1.168224571","rc":[{"batl":[[2,2.2,2.73]],"ltp":2.08,"tv":594.15,"id":7797764},{"batb":[[2,1.85,2.17]],"ltp":1.92,"tv":634.96,"id":2284304}]}]}
{"op":"mcm","clk":"1002509929","pt":1580644735230,"mc":[{"id":"1.168224571","rc":[{"batl":[[2,2.2,2.88]],"ltp":2.08,"tv":594.15,"id":7797764},{"batl":[[2,2.4,15.6]],"ltp":1.92,"tv":634.96,"id":2284304}]}]}
{"op":"mcm","clk":"1002514654","pt":1580644774409,"mc":[{"id":"1.168224571","rc":[{"batb":[[0,2,25.21],[1,1.97,25.99],[2,1.81,37.86]],"ltp":2.08,"tv":594.15,"id":7797764}]}]}
{"op":"mcm","clk":"1002514810","pt":1580644775491,"mc":[{"id":"1.168224571","rc":[{"batb":[[0,2.02,76.8],[1,2,25.21],[2,1.97,25.99]],"batl":[[2,2.2,2.73]],"ltp":2.08,"tv":594.15,"id":7797764},{"batb":[[2,1.85,31.65]],"ltp":1.92,"tv":634.96,"id":2284304}]}]}
{"op":"mcm","clk":"1002531490","pt":1580644905197,"mc":[{"id":"1.168224571","rc":[{"batl":[[1,2.2,2.73],[2,2.22,2.75]],"ltp":2.08,"tv":594.15,"id":7797764},{"trd":[[1.88,45.76]],"batb":[[0,1.86,92.67],[1,1.85,29.65],[2,1.84,32.22]],"ltp":1.88,"tv":650.5,"id":2284304}],"tv":1244.66}]}
{"op":"mcm","clk":"1002531578","pt":1580644905887,"mc":[{"id":"1.168224571","rc":[{"trd":[[2.16,75.27]],"batl":[[0,2.22,2.89],[1,2.24,2.98],[2,2.6,495.23]],"ltp":2.16,"tv":662.71,"id":7797764}],"tv":1313.22}]}
{"op":"mcm","clk":"1002532269","pt":1580644911187,"mc":[{"id":"1.168224571","rc":[{"batl":[[1,2.24,2.73]],"ltp":2.16,"tv":662.71,"id":7797764},{"batl":[[0,1.92,15.14],[1,1.94,7.57],[2,1.96,7.57]],"ltp":1.88,"tv":650.5,"id":2284304}]}]}
{"op":"mcm","clk":"1002532319","pt":1580644911604,"mc":[{"id":"1.168224571","rc":[{"batb":[[0,2.02,101.51]],"ltp":2.16,"tv":662.71,"id":7797764},{"batb":[[1,1.84,2.22],[2,1.83,32.39]],"ltp":1.88,"tv":650.5,"id":2284304}]}]}
{"op":"mcm","clk":"1002532512","pt":1580644913214,"mc":[{"id":"1.168224571","rc":[{"batl":[[1,1.96,7.57],[2,2.4,15.6]],"ltp":1.88,"tv":650.5,"id":2284304}]}]}
{"op":"mcm","clk":"1002532567","pt":1580644913692,"mc":[{"id":"1.168224571","rc":[{"batb":[[0,2.02,76.8]],"ltp":2.16,"tv":662.71,"id":7797764},{"batb":[[1,1.84,32.22]],"batl":[[1,2.4,15.6],[2,2.5,74.21]],"ltp":1.88,"tv":650.5,"id":2284304}]}]}
{"op":"mcm","clk":"1002532733","pt":1580644914728,"mc":[{"id":"1.168224571","rc":[{"batb":[[1,1.85,29.65],[2,1.84,32.22]],"batl":[[1,1.97,7.57],[2,2.4,15.6]],"ltp":1.88,"tv":650.5,"id":2284304}]}]}
{"op":"mcm","clk":"1002532890","pt":1580644915624,"mc":[{"id":"1.168224571","rc":[{"batb":[[1,1.84,32.22],[2,1.83,32.39]],"ltp":1.88,"tv":650.5,"id":2284304}]}]}
{"op":"mcm","clk":"1002542383","pt":1580644977488,"mc":[{"id":"1.168224571","rc":[{"batl":[[0,2.22,2.75]],"ltp":2.16,"tv":662.71,"id":7797764}]}]}
{"op":"mcm","clk":"1002542856","pt":1580644979997,"mc":[{"id":"1.168224571","rc":[{"trd":[[2.08,13.28]],"ltp":2.08,"tv":663.51,"id":7797764},{"trd":[[1.92,44.68]],"batl":[[0,1.92,14.27]],"ltp":1.92,"tv":651.37,"id":2284304}],"tv":1314.89}]}
{"op":"mcm","clk":"1002553201","pt":1580645040438,"mc":[{"id":"1.168224571","rc":[{"batb":[[0,2.1,72.68]],"batl":[[0,2.24,2.73],[1,2.26,2.79]],"ltp":2.08,"tv":663.51,"id":7797764},{"batb":[[0,1.84,30],[1,1.83,30.36],[2,1.82,2.03]],"ltp":1.92,"tv":651.37,"id":2284304}]}]}
{"op":"mcm","clk":"1002553380","pt":1580645041304,"mc":[{"id":"1.168224571","rc":[{"batb":[[0,2.1,262.12],[1,2.08,23.34],[2,2,25.21]],"batl":[[0,2.28,2.84],[1,2.3,2.75]],"ltp":2.08,"tv":663.51,"id":7797764},{"batb":[[0,1.78,163.5],[1,1.77,2.11],[2,1.73,154.6]],"ltp":1.92,"tv":651.37,"id":2284304}]}]}
{"op":"mcm","clk":"1002553516","pt":1580645042002,"mc":[{"id":"1.168224571","rc":[{"batl":[[0,2.34,2.75],[1,2.36,2.82]],"ltp":2.08,"tv":663.51,"id":7797764},{"batb":[[0,1.78,129.11],[1,1.77,32.73],[2,1.76,2.23]],"ltp":1.92,"tv":651.37,"id":2284304}]}]}
{"op":"mcm","clk":"1002565311","pt":1580645120438,"mc":[{"id":"1.168224571","rc":[{"batl":[[1,2.6,495.23],[2,4.2,153.72]],"ltp":2.08,"tv":663.51,"id":7797764}]}]}
{"op":"mcm","clk":"1002565482","pt":1580645121463,"mc":[{"id":"1.168224571","rc":[{"batl":[[1,2.36,2.57],[2,2.6,495.23]],"ltp":2.08,"tv":663.51,"id":7797764}]}]}
{"op":"mcm","clk":"1002565496","pt":1580645121550,"mc":[{"id":"1.168224571","rc":[{"batb":[[0,2.12,1.19],[1,2.1,262.12],[2,2.08,23.34]],"ltp":2.08,"tv":663.51,"id":7797764},{"batb":[[0,1.79,1.41],[1,1.78,129.11],[2,1.77,32.73]],"ltp":1.92,"tv":651.37,"id":2284304}]}]}
{"op":"mcm","clk":"1002625490","pt":1580645501096,"mc":[{"id":"1.168224571","rc":[{"batl":[[1,2.36,3.07]],"ltp":2.08,"tv":663.51,"id":7797764},{"batl":[[0,2.4,15.6],[1,2.5,74.21],[2,2.6,495.23]],"ltp":1.92,"tv":651.37,"id":2284304}]}]}
{"op":"mcm","clk":"1002625829","pt":1580645503284,"mc":[{"id":"1.168224571","rc":[{"batb":[[0,1.79,2.39]],"ltp":1.92,"tv":651.37,"id":2284304}]}]}
{"op":"mcm","clk":"1002625958","pt":1580645504180,"mc":[{"id":"1.168224571","rc":[{"batb":[[2,1.77,34.73]],"ltp":1.92,"tv":651.37,"id":2284304}]}]}
{"op":"mcm","clk":"1002676463","pt":1580645815895,"mc":[{"id":"1.168224571","marketDefinition":{"bspMarket":false,"turnInPlayEnabled":true,"persistenceEnabled":true,"marketBaseRate":5.0,"eventId":"29681732","eventTypeId":"2","numberOfWinners":1,"bettingType":"ODDS","marketType":"MATCH_ODDS","marketTime":"2020-02-02T12:16:00.000Z","suspendTime":"2020-02-02T12:16:00.000Z","bspReconciled":false,"complete":true,"inPlay":false,"crossMatching":true,"runnersVoidable":false,"numberOfActiveRunners":2,"betDelay":0,"status":"OPEN","runners":[{"status":"ACTIVE","sortPriority":1,"id":2284304,"name":"Sergiy Stakhovsky"},{"status":"ACTIVE","sortPriority":2,"id":7797764,"name":"Alexey Vatutin"}],"regulators":["MR_INT"],"countryCode":"FR","discountAllowed":true,"timezone":"UTC","openDate":"2020-02-02T12:48:00.000Z","version":3148684853,"name":"Match Odds","eventName":"Stakhovsky v Vatutin"}}]}
{"op":"mcm","clk":"1002676963","pt":1580645818903,"mc":[{"id":"1.168224571","marketDefinition":{"bspMarket":false,"turnInPlayEnabled":true,"persistenceEnabled":true,"marketBaseRate":5.0,"eventId":"29681732","eventTypeId":"2","numberOfWinners":1,"bettingType":"ODDS","marketType":"MATCH_ODDS","marketTime":"2020-02-02T12:16:00.000Z","suspendTime":"2020-02-02T12:16:00.000Z","bspReconciled":false,"complete":true,"inPlay":false,"crossMatching":true,"runnersVoidable":false,"numberOfActiveRunners":2,"betDelay":0,"status":"OPEN","runners":[{"status":"ACTIVE","sortPriority":1,"id":2284304,"name":"Sergiy Stakhovsky"},{"status":"ACTIVE","sortPriority":2,"id":7797764,"name":"Alexey Vatutin"}],"regulators":["MR_INT"],"countryCode":"FR","discountAllowed":true,"timezone":"UTC","openDate":"2020-02-02T12:16:00.000Z","version":3148684853,"name":"Match Odds","eventName":"Stakhovsky v Vatutin"}}]}
{"op":"mcm","clk":"1002680995","pt":1580645843375,"mc":[{"id":"1.168224571","rc":[{"batb":[[0,2.12,95.53]],"ltp":2.08,"tv":663.51,"id":7797764},{"batb":[[0,1.79,83.98]],"ltp":1.92,"tv":651.37,"id":2284304}]}]}
{"op":"mcm","clk":"1002681079","pt":1580645843886,"mc":[{"id":"1.168224571","rc":[{"batb":[[1,2.1,72.68]],"batl":[[0,2.6,495.23],[1,4.2,153.72],[2,95,15.9]],"ltp":2.08,"tv":663.51,"id":7797764},{"batb":[[2,1.77,32.73]],"ltp":1.92,"tv":651.37,"id":2284304}]}]}
{"op":"mcm","clk":"1002681254","pt":1580645844874,"mc":[{"id":"1.168224571","rc":[{"batb":[[1,2.1,95.59]],"ltp":2.08,"tv":663.51,"id":7797764}]}]}
{"op":"mcm","clk":"1002682670","pt":1580645853500,"mc":[{"id":"1.168224571","rc":[{"batl":[[0,1.89,7.57],[1,2.4,15.6],[2,2.5,74.21]],"ltp":1.92,"tv":651.37,"id":2284304}]}]}
{"op":"mcm","clk":"1002685040","pt":1580645869454,"mc":[{"id":"1.168224571","rc":[{"batb":[[0,2.14,29.73],[1,2.12,95.53],[2,2.1,22.91]],"ltp":2.08,"tv":663.51,"id":7797764},{"batb":[[0,1.8,93.81],[1,1.79,83]],"ltp":1.92,"tv":651.37,"id":2284304}]}]}
{"op":"mcm","clk":"1002686640","pt":1580645880329,"mc":[{"id":"1.168224571","rc":[{"batb":[[0,1.8,92.83]],"batl":[[0,2.4,15.6],[1,2.5,74.21],[2,2.6,495.23]],"ltp":1.92,"tv":651.37,"id":2284304}]}]}
{"op":"mcm","clk":"1002687094","pt":1580645883015,"mc":[{"id":"1.168224571","rc":[{"batb":[[0,1.8,93.77]],"ltp":1.92,"tv":651.37,"id":2284304}]}]}
{"op":"mcm","clk":"1002687727","pt":1580645887218,"mc":[{"id":"1.168224571","rc":[{"batb":[[0,1.8,92.83]],"ltp":1.92,"tv":651.37,"id":2284304}]}]}
{"op":"mcm","clk":"1002688127","pt":1580645889822,"mc":[{"id":"1.168224571","rc":[{"trd":[[2.14,0.81]],"batb":[[0,2.14,28.91]],"ltp":2.14,"tv":664.33,"id":7797764},{"trd":[[1.88,46.69]],"ltp":1.88,"tv":652.3,"id":2284304}],"tv":1316.64}]}
{"op":"mcm","clk":"1002690489","pt":1580645905276,"mc":[{"id":"1.168224571","rc":[{"trd":[[2.14,92.48]],"batb":[[0,2.12,95.53],[1,2.1,65.69],[2,2.08,23.34]],"batl":[[0,2.6,496.13]],"ltp":2.14,"tv":755.99,"id":7797764},{"batb":[[0,1.8,127.55]],"ltp":1.88,"tv":652.3,"id":2284304}],"tv":1408.3}]}
{"op":"mcm","clk":"1002690584","pt":1580645905868,"mc":[{"id":"1.168224571","rc":[{"batb":[[1,2.1,42.77]],"ltp":2.14,"tv":755.99,"id":7797764},{"batb":[[2,1.78,32.31]],"ltp":1.88,"tv":652.3,"id":2284304}]}]}
{"op":"mcm","clk":"1002700340","pt":1580645974083,"mc":[{"id":"1.168224571","rc":[{"trd":[[2.12,5.04]],"batb":[[0,2.12,93.01]],"ltp":2.12,"tv":761.03,"id":7797764}],"tv":1413.34}]}
{"op":"mcm","clk":"1002709137","pt":1580646031332,"mc":[{"id":"1.168224571","rc":[{"batl":[[0,1.89,74.21],[1,2.4,15.6],[2,2.5,74.21]],"ltp":1.88,"tv":652.3,"id":2284304}]}]}
{"op":"mcm","clk":"1002723571","pt":1580646120464,"mc":[{"id":"1.168224571","rc":[{"trd":[[2.14,93.38]],"batb":[[1,2.08,23.34],[2,2,25.21]],"batl":[[0,2.6,495.23]],"ltp":2.14,"tv":761.93,"id":7797764},{"trd":[[1.8,257.22],[1.87,1.03]],"batb":[[0,1.8,86.57]],"ltp":1.8,"tv":735.29,"id":2284304}],"tv":1497.23}]}
{"op":"mcm","clk":"1002723648","pt":1580646120882,"mc":[{"id":"1.168224571","rc":[{"batb":[[0,2.14,34.43],[1,2.12,93.01],[2,2.1,22.91]],"ltp":2.14,"tv":761.93,"id":7797764},{"batb":[[2,1.77,32.73]],"ltp":1.8,"tv":735.29,"id":2284304}]}]}
{"op":"mcm","clk":"1002724739","pt":1580646127417,"mc":[{"id":"1.168224571","rc":[{"batb":[[0,2.14,38.64]],"ltp":2.14,"tv":761.93,"id":7797764},{"trd":[[1.8,267.31]],"batb":[[0,1.8,81.52]],"ltp":1.8,"tv":745.38,"id":2284304}],"tv":1507.32}]}
{"op":"mcm","clk":"1002730090","pt":1580646163088,"mc":[{"id":"1.168224571","rc":[{"batb":[[0,2.14,132.19],[1,2.1,22.91],[2,2.08,23.34]],"ltp":2.14,"tv":761.93,"id":7797764},{"batb":[[1,1.79,1.41],[2,1.78,82.22]],"ltp":1.8,"tv":745.38,"id":2284304}]}]}
{"op":"mcm","clk":"1002730994","pt":1580646169184,"mc":[{"id":"1.168224571","rc":[{"batl":[[0,1.87,74.21]],"ltp":1.8,"tv":745.38,"id":2284304}]}]}
{"op":"mcm","clk":"1002731530","pt":1580646172283,"mc":[{"id":"1.168224571","rc":[{"trd":[[1.8,267.35]],"batb":[[0,1.8,81.51]],"ltp":1.8,"tv":745.42,"id":2284304}],"tv":1507.35}]}
{"op":"mcm","clk":"1002731680","pt":1580646173193,"mc":[{"id":"1.168224571","rc":[{"batb":[[0,2.14,131.25]],"ltp":2.14,"tv":761.93,"id":7797764}]}]}
{"op":"mcm","clk":"1002737551","pt":1580646210492,"mc":[{"id":"1.168224571","rc":[{"batl":[[0,1.87,75.09]],"ltp":1.8,"tv":745.42,"id":2284304}]}]}
{"op":"mcm","clk":"1002738154","pt":1580646214081,"mc":[{"id":"1.168224571","rc":[{"batb":[[0,1.81,667.17],[1,1.8,81.51],[2,1.79,1.41]],"ltp":1.8,"tv":745.42,"id":2284304}]}]}
{"op":"mcm","clk":"1002738306","pt":1580646215029,"mc":[{"id":"1.168224571","rc":[{"batb":[[1,2.08,23.34],[2,2,25.21]],"ltp":2.14,"tv":761.93,"id":7797764}]}]}
{"op":"mcm","clk":"1002741761","pt":1580646237368,"mc":[{"id":"1.168224571","rc":[{"batb":[[1,1.8,81.52]],"ltp":1.8,"tv":745.42,"id":2284304}]}]}
{"op":"mcm","clk":"1002742247","pt":1580646240381,"mc":[{"id":"1.168224571","rc":[{"batb":[[0,2.16,91.74],[1,2.14,38.64],[2,2.08,23.34]],"ltp":2.14,"tv":761.93,"id":7797764}]}]}
{"op":"mcm","clk":"1002742355","pt":1580646241013,"mc":[{"id":"1.168224571","rc":[{"batb":[[2,2.1,22.91]],"ltp":2.14,"tv":761.93,"id":7797764}]}]}
{"op":"mcm","clk":"1002743538","pt":1580646248497,"mc":[{"id":"1.168224571","rc":[{"trd":[[1.81,3.51]],"batb":[[0,1.81,665.49]],"ltp":1.81,"tv":748.78,"id":2284304}],"tv":1510.71}]}
{"op":"mcm","clk":"1002746145","pt":1580646264879,"mc":[{"id":"1.168224571","rc":[{"batb":[[0,2.16,90.8]],"ltp":2.14,"tv":761.93,"id":7797764}]}]}
{"op":"mcm","clk":"1002747205","pt":1580646271475,"mc":[{"id":"1.168224571","rc":[{"batb":[[1,2.1,22.91],[2,2.08,23.34]],"ltp":2.14,"tv":761.93,"id":7797764},{"batb":[[1,1.79,1.43],[2,1.77,116.45]],"ltp":1.81,"tv":748.78,"id":2284304}]}]}
{"op":"mcm","clk":"1002747273","pt":1580646272000,"mc":[{"id":"1.168224571","rc":[{"batb":[[1,2.12,59.84],[2,2.1,22.91]],"ltp":2.14,"tv":761.93,"id":7797764},{"batb":[[0,1.82,47.54],[1,1.81,665.49],[2,1.79,1.43]],"ltp":1.81,"tv":748.78,"id":2284304}]}]}
{"op":"mcm","clk":"1002749748","pt":1580646288005,"mc":[{"id":"1.168224571","rc":[{"batb":[[2,2.1,60.72]],"batl":[[0,2.34,31.09],[1,2.6,495.23],[2,4.2,153.72]],"ltp":2.14,"tv":761.93,"id":7797764},{"batl":[[1,1.91,42.01],[2,2.4,15.6]],"ltp":1.81,"tv":748.78,"id":2284304}]}]}
{"op":"mcm","clk":"1002755948","pt":1580646328201,"mc":[{"id":"1.168224571","rc":[{"batb":[[0,2.16,90.33]],"ltp":2.14,"tv":761.93,"id":7797764}]}]}
{"op":"mcm","clk":"1002756632","pt":1580646332221,"mc":[{"id":"1.168224571","rc":[{"trd":[[2.16,125.69]],"batb":[[0,2.16,65.12]],"ltp":2.16,"tv":812.35,"id":7797764}],"tv":1561.13}]}
{"op":"mcm","clk":"1002759117","pt":1580646348371,"mc":[{"id":"1.168224571","rc":[{"batl":[[0,1.91,42.89],[1,2.4,15.6],[2,2.6,495.23]],"ltp":1.81,"tv":748.78,"id":2284304}]}]}
{"op":"mcm","clk":"1002766935","pt":1580646400203,"mc":[{"id":"1.168224571","rc":[{"trd":[[1.82,90.99]],"batb":[[0,1.82,2.09]],"ltp":1.82,"tv":839.67,"id":2284304}],"tv":1652.02}]}
{"op":"mcm","clk":"1002767052","pt":1580646401014,"mc":[{"id":"1.168224571","rc":[{"batb":[[0,2.18,36.03],[1,2.16,65.12]],"ltp":2.16,"tv":812.35,"id":7797764},{"batb":[[0,1.81,665.49],[1,1.79,55.99],[2,1.78,84.43]],"ltp":1.82,"tv":839.67,"id":2284304}]}]}
{"op":"mcm","clk":"1002769091","pt":1580646414295,"mc":[{"id":"1.168224571","rc":[{"batb":[[0,1.82,665.49]],"ltp":1.82,"tv":839.67,"id":2284304}]}]}
{"op":"mcm","clk":"1002771627","pt":1580646430270,"mc":[{"id":"1.168224571","rc":[{"trd":[[1.82,92.76]],"batb":[[0,1.82,664.61]],"ltp":1.82,"tv":841.44,"id":2284304}],"tv":1653.79}]}
{"op":"mcm","clk":"1002772182","pt":1580646432882,"mc":[{"id":"1.168224571","rc":[{"batl":[[0,1.91,42.01]],"ltp":1.82,"tv":841.44,"id":2284304}]}]}
{"op":"mcm","clk":"1002773298","pt":1580646439048,"mc":[{"id":"1.168224571","rc":[{"trd":[[2.18,190.24]],"batb":[[0,2.18,2.25]],"ltp":2.18,"tv":879.9,"id":7797764}],"tv":1721.34}]}
{"op":"mcm","clk":"1002773499","pt":1580646440217,"mc":[{"id":"1.168224571","rc":[{"batb":[[0,2.16,65.12],[1,2.12,64.06]],"ltp":2.18,"tv":879.9,"id":7797764},{"batb":[[0,1.83,25.75],[1,1.82,664.61],[2,1.79,1.43]],"ltp":1.82,"tv":841.44,"id":2284304}]}]}
{"op":"mcm","clk":"1002773631","pt":1580646440964,"mc":[{"id":"1.168224571","rc":[{"batb":[[2,2.1,37.81]],"ltp":2.18,"tv":879.9,"id":7797764}]}]}
{"op":"mcm","clk":"1002778868","pt":1580646475072,"mc":[{"id":"1.168224571","rc":[{"trd":[[1.83,220.77]],"batb":[[0,1.82,664.61],[1,1.79,1.43],[2,1.78,116.74]],"batl":[[0,1.83,480.56],[1,1.91,42.01],[2,2.4,15.6]],"ltp":1.83,"tv":892.95,"id":2284304}],"tv":1772.85}]}
{"op":"mcm","clk":"1002779021","pt":1580646476077,"mc":[{"id":"1.168224571","rc":[{"batb":[[0,2.18,23.95],[1,2.16,65.12],[2,2.12,22.51]],"ltp":2.18,"tv":879.9,"id":7797764},{"batb":[[1,1.79,70.65],[2,1.78,84.43]],"ltp":1.83,"tv":892.95,"id":2284304}]}]}
{"op":"mcm","clk":"1002785944","pt":1580646518290,"mc":[{"id":"1.168224571","rc":[{"trd":[[1.83,1181.89]],"batb":[[0,1.83,184.05]],"batl":[[0,1.91,42.01],[1,2.4,15.6],[2,2.6,495.23]],"ltp":1.83,"tv":1854.06,"id":2284304}],"tv":2733.97}]}
{"op":"mcm","clk":"1002786089","pt":1580646519086,"mc":[{"id":"1.168224571","rc":[{"batb":[[2,2.1,60.72]],"ltp":2.18,"tv":879.9,"id":7797764}]}]}
{"op":"mcm","clk":"1002786400","pt":1580646520882,"mc":[{"id":"1.168224571","rc":[{"batb":[[0,2.16,65.12],[1,2.1,60.72],[2,2.08,23.34]],"ltp":2.18,"tv":879.9,"id":7797764},{"batb":[[1,1.79,1.43]],"ltp":1.83,"tv":1854.06,"id":2284304}]}]}
{"op":"mcm","clk":"1002786573","pt":1580646521991,"mc":[{"id":"1.168224571","rc":[{"batb":[[1,2.1,37.81]],"ltp":2.18,"tv":879.9,"id":7797764},{"batb":[[2,1.78,116.74]],"ltp":1.83,"tv":1854.06,"id":2284304}]}]}
{"op":"mcm","clk":"1002787048","pt":1580646525218,"mc":[{"id":"1.168224571","rc":[{"trd":[[2.16,126.99]],"batb":[[0,2.16,64.47]],"ltp":2.16,"tv":881.2,"id":7797764}],"tv":2735.27}]}
{"op":"mcm","clk":"1002787425","pt":1580646527443,"mc":[{"id":"1.168224571","marketDefinition":{"bspMarket":false,"turnInPlayEnabled":true,"persistenceEnabled":true,"marketBaseRate":5.0,"eventId":"29681732","eventTypeId":"2","numberOfWinners":1,"bettingType":"ODDS","marketType":"MATCH_ODDS","marketTime":"2020-02-02T12:16:00.000Z","suspendTime":"2020-02-02T12:16:00.000Z","bspReconciled":false,"complete":true,"inPlay":false,"crossMatching":true,"runnersVoidable":false,"numberOfActiveRunners":2,"betDelay":0,"status":"OPEN","runners":[{"status":"ACTIVE","sortPriority":1,"id":2284304,"name":"Sergiy Stakhovsky"},{"status":"ACTIVE","sortPriority":2,"id":7797764,"name":"Alexey Vatutin"}],"regulators":["MR_INT"],"countryCode":"FR","discountAllowed":true,"timezone":"UTC","openDate":"2020-02-02T12:16:00.000Z","version":3148684853,"name":"Match Odds","eventName":"Stakhovsky v Vatutin"},"rc":[{"batb":[[0,2.08,23.34],[1,2,25.21],[2,1.97,25.99]],"batl":[[0,2.6,495.23],[1,4.2,153.72],[2,95,15.9]],"ltp":2.16,"tv":881.2,"id":7797764},{"batb":[[2,1.78,32.31]],"batl":[[0,2.4,15.6],[1,2.6,495.23],[2,3,42.01]],"ltp":1.83,"tv":1854.06,"id":2284304}]}]}
{"op":"mcm","clk":"1002787441","pt":1580646527557,"mc":[{"id":"1.168224571","marketDefinition":{"bspMarket":false,"turnInPlayEnabled":true,"persistenceEnabled":true,"marketBaseRate":5.0,"eventId":"29681732","eventTypeId":"2","numberOfWinners":1,"bettingType":"ODDS","marketType":"MATCH_ODDS","marketTime":"2020-02-02T12:16:00.000Z","suspendTime":"2020-02-02T12:16:00.000Z","bspReconciled":false,"complete":true,"inPlay":true,"crossMatching":true,"runnersVoidable":false,"numberOfActiveRunners":2,"betDelay":3,"status":"OPEN","runners":[{"status":"ACTIVE","sortPriority":1,"id":2284304,"name":"Sergiy Stakhovsky"},{"status":"ACTIVE","sortPriority":2,"id":7797764,"name":"Alexey Vatutin"}],"regulators":["MR_INT"],"countryCode":"FR","discountAllowed":true,"timezone":"UTC","openDate":"2020-02-02T12:16:00.000Z","version":3148715123,"name":"Match Odds","eventName":"Stakhovsky v Vatutin"},"rc":[{"batb":[[0,1.11,37.96],[1,1.03,9],[2,1.02,25.41]],"batl":[[0,1000,0.02],[1,4.2,0],[2,95,0]],"ltp":2.16,"tv":881.2,"id":7797764},{"batb":[[1,1.73,154.61],[2,1.11,37.96]],"batl":[[0,3,42.46],[1,1000,0.02],[2,3,0]],"ltp":1.83,"tv":1854.06,"id":2284304}]}]}
{"op":"mcm","clk":"1002788360","pt":1580646532728,"mc":[{"id":"1.168224571","rc":[{"batb":[[2,1.71,231.87]],"batl":[[0,1.93,178.23],[1,1.95,210.7],[2,3,42.46]],"ltp":1.83,"tv":1854.06,"id":2284304}]}]}
{"op":"mcm","clk":"1002789185","pt":1580646537440,"mc":[{"id":"1.168224571","rc":[{"batb":[[2,1.11,37.96]],"ltp":1.83,"tv":1854.06,"id":2284304}]}]}
{"op":"mcm","clk":"1002789512","pt":1580646539354,"mc":[{"id":"1.168224571","rc":[{"batb":[[1,1.03,387.62]],"ltp":2.16,"tv":881.2,"id":7797764}]}]}
{"op":"mcm","clk":"1002789707","pt":1580646540456,"mc":[{"id":"1.168224571","rc":[{"batl":[[0,2.2,495],[1,1000,0.02]],"ltp":2.16,"tv":881.2,"id":7797764},{"batb":[[0,1.86,275.6],[1,1.84,248.34],[2,1.83,184.05]],"batl":[[2,1.96,490]],"ltp":1.83,"tv":1854.06,"id":2284304}]}]}
{"op":"mcm","clk":"1002789899","pt":1580646541457,"mc":[{"id":"1.168224571","rc":[{"batb":[[0,2.06,105.2],[1,1.98,117.39],[2,1.26,3.37]],"ltp":2.16,"tv":881.2,"id":7797764},{"batb":[[0,1.86,329.46]],"ltp":1.83,"tv":1854.06,"id":2284304}]}]}
{"op":"mcm","clk":"1002790053","pt":1580646542340,"mc":[{"id":"1.168224571","rc":[{"batb":[[1,2.02,41.17],[2,1.98,117.39]],"ltp":2.16,"tv":881.2,"id":7797764}]}]}
{"op":"mcm","clk":"1002790393","pt":1580646544277,"mc":[{"id":"1.168224571","rc":[{"batl":[[1,2.26,32.77],[2,1000,0.02]],"ltp":2.16,"tv":881.2,"id":7797764},{"trd":[[1.93,168.04]],"batl":[[0,1.93,113.33]],"ltp":1.93,"tv":2022.1,"id":2284304}],"tv":2903.31}]}
{"op":"mcm","clk":"1002790446","pt":1580646544556,"mc":[{"id":"1.168224571","rc":[{"batb":[[0,1.86,73.57],[1,1.83,184.05],[2,1.8,52.11]],"ltp":1.93,"tv":2022.1,"id":2284304}]}]}
{"op":"mcm","clk":"1002790963","pt":1580646547284,"mc":[{"id":"1.168224571","rc":[{"batb":[[2,1.98,118.04]],"ltp":2.16,"tv":881.2,"id":7797764}]}]}
{"op":"mcm","clk":"1002791022","pt":1580646547559,"mc":[{"id":"1.168224571","rc":[{"batb":[[0,1.87,182.55],[1,1.86,73.57],[2,1.85,243.94]],"batl":[[0,1.93,150.92]],"ltp":1.93,"tv":2022.1,"id":2284304}]}]}
{"op":"mcm","clk":"1002792696","pt":1580646557291,"mc":[{"id":"1.168224571","rc":[{"batb":[[0,1.98,118.04],[1,1.5,113.58],[2,1.4,75.72]],"batl":[[0,1000,0.02],[1,2.26,0],[2,1000,0]],"ltp":2.16,"tv":881.2,"id":7797764},{"batb":[[0,1.83,184.05],[1,1.76,88.22],[2,1.73,154.6]],"batl":[[0,3,42.46],[1,1000,0.02],[2,1.96,0]],"ltp":1.93,"tv":2022.1,"id":2284304}]}]}
{"op":"mcm","clk":"1002793390","pt":1580646561469,"mc":[{"id":"1.168224571","rc":[{"batb":[[0,1.85,213.94],[1,1.83,436.72],[2,1.76,88.22]],"batl":[[0,1.92,248.67],[1,1.94,213.92],[2,3,42.46]],"ltp":1.93,"tv":2022.1,"id":2284304}]}]}
{"op":"mcm","clk":"1002794023","pt":1580646565565,"mc":[{"id":"1.168224571","rc":[{"batb":[[0,1.83,184.05],[1,1.76,88.22],[2,1.73,154.6]],"batl":[[0,3,42.46],[1,1000,0.02],[2,3,0]],"ltp":1.93,"tv":2022.1,"id":2284304}]}]}
{"op":"mcm","clk":"1002794623","pt":1580646569216,"mc":[{"id":"1.168224571","rc":[{"batl":[[0,1.99,162.21],[1,2.02,285.83],[2,3,42.46]],"ltp":1.93,"tv":2022.1,"id":2284304}]}]}
{"op":"mcm","clk":"1002795126","pt":1580646572208,"mc":[{"id":"1.168224571","rc":[{"batl":[[0,2.12,535],[1,1000,0.02]],"ltp":2.16,"tv":881.2,"id":7797764},{"batb":[[0,1.92,228.37],[1,1.9,224.22],[2,1.83,184.05]],"batl":[[2,2.04,581.45]],"ltp":1.93,"tv":2022.1,"id":2284304}]}]}
{"op":"mcm","clk":"1002795295","pt":1580646573256,"mc":[{"id":"1.168224571","rc":[{"batb":[[1,1.93,64.13],[2,1.5,113.58]],"ltp":2.16,"tv":881.2,"id":7797764},{"batb":[[0,1.92,294.46],[2,1.84,76.16]],"ltp":1.93,"tv":2022.1,"id":2284304}]}]}
{"op":"mcm","clk":"1002795441","pt":1580646574005,"mc":[{"id":"1.168224571","rc":[{"batb":[[1,1.95,43.69],[2,1.93,64.13]],"batl":[[1,2.18,35.29],[2,1000,0.02]],"ltp":2.16,"tv":881.2,"id":7797764},{"batb":[[2,1.85,48.73]],"batl":[[2,2.04,621.78]],"ltp":1.93,"tv":2022.1,"id":2284304}]}]}
{"op":"mcm","clk":"1002797253","pt":1580646586036,"mc":[{"id":"1.168224571","rc":[{"trd":[[1.92,50.46]],"batb":[[0,1.92,291.57]],"ltp":1.92,"tv":2027.89,"id":2284304}],"tv":2909.09}]}
{"op":"mcm","clk":"1002797689","pt":1580646589026,"mc":[{"id":"1.168224571","rc":[{"batb":[[0,1.93,64.78],[1,1.5,113.58],[2,1.4,75.72]],"batl":[[0,1000,0.02],[1,2.18,0],[2,1000,0]],"ltp":2.16,"tv":881.2,"id":7797764},{"batb":[[0,1.84,76.16],[1,1.83,184.05],[2,1.73,154.61]],"batl":[[0,3,42.46],[1,1000,0.02],[2,2.04,0]],"ltp":1.92,"tv":2027.89,"id":2284304}]}]}
{"op":"mcm","clk":"1002798521","pt":1580646594427,"mc":[{"id":"1.168224571","rc":[{"batb":[[0,1.91,186.27],[1,1.89,227.95],[2,1.84,76.16]],"batl":[[0,1.98,212.29],[1,2,195.28],[2,3,42.46]],"ltp":1.92,"tv":2027.89,"id":2284304}]}]}
{"op":"mcm","clk":"1002799337","pt":1580646599731,"mc":[{"id":"1.168224571","rc":[{"batl":[[0,2.1,16.8],[1,1000,0.02]],"ltp":2.16,"tv":881.2,"id":7797764}]}]}
{"op":"mcm","clk":"1002799637","pt":1580646601466,"mc":[{"id":"1.168224571","rc":[{"batb":[[0,1.84,76.16],[1,1.83,184.05],[2,1.73,154.61]],"batl":[[0,3,42.46],[1,1000,0.02],[2,3,0]],"ltp":1.92,"tv":2027.89,"id":2284304}]}]}
{"op":"mcm","clk":"1002800276","pt":1580646604568,"mc":[{"id":"1.168224571","rc":[{"batb":[[0,1.85,275.61],[1,1.84,76.16],[2,1.83,436.82]],"batl":[[0,2.04,208.51],[1,2.06,179.03],[2,3,42.01]],"ltp":1.92,"tv":2027.89,"id":2284304}]}]}
{"op":"mcm","clk":"1002803332","pt":1580646621868,"mc":[{"id":"1.168224571","rc":[{"batl":[[0,3,42.46],[1,1000,0.02],[2,3,0]],"ltp":1.92,"tv":2027.89,"id":2284304}]}]}
{"op":"mcm","clk":"1002803962","pt":1580646625488,"mc":[{"id":"1.168224571","rc":[{"trd":[[2.1,16.8]],"batb":[[0,2.08,101.42],[1,1.99,116.47],[2,1.93,64.13]],"batl":[[0,2.22,354]],"ltp":2.1,"tv":898.0,"id":7797764},{"trd":[[1.9,18.57]],"batl":[[0,1.92,189.54],[1,1.93,465],[2,1.94,214]],"ltp":1.9,"tv":2046.46,"id":2284304}],"tv":2944.47}]}
{"op":"mcm","clk":"1002804083","pt":1580646626083,"mc":[{"id":"1.168224571","rc":[{"batb":[[2,1.5,113.58]],"batl":[[1,2.28,32.77],[2,1000,0.02]],"ltp":2.1,"tv":898.0,"id":7797764}]}]}
{"op":"mcm","clk":"1002804411","pt":1580646627871,"mc":[{"id":"1.168224571","rc":[{"batb":[[2,1.75,20.16]],"ltp":2.1,"tv":898.0,"id":7797764}]}]}
{"op":"mcm","clk":"1002805066","pt":1580646631493,"mc":[{"id":"1.168224571","rc":[{"trd":[[2.06,6.18],[2.08,391.08]],"batb":[[0,1.99,116.47],[1,1.75,20.16],[2,1.5,113.58]],"ltp":2.06,"tv":1280.02,"id":7797764},{"trd":[[1.92,240],[1.93,172.55]],"batl":[[0,1.93,460.49],[1,1.94,214],[2,3,42.46]],"ltp":1.93,"tv":2240.51,"id":2284304}],"tv":3520.54}]}
{"op":"mcm","clk":"1002805111","pt":1580646631824,"mc":[{"id":"1.168224571","rc":[{"batb":[[0,1.84,76.16],[1,1.83,184.05],[2,1.79,52.95]],"batl":[[1,3,42.46],[2,1000,0.02]],"ltp":1.93,"tv":2240.51,"id":2284304}]}]}
{"op":"mcm","clk":"1002805616","pt":1580646634819,"mc":[{"id":"1.168224571","rc":[{"batb":[[0,1.86,260.31],[1,1.84,324.38],[2,1.83,184.05]],"batl":[[0,1.93,653.01],[1,1.95,210.57],[2,3,42.46]],"ltp":1.93,"tv":2240.51,"id":2284304}]}]}
{"op":"mcm","clk":"1002806167","pt":1580646638112,"mc":[{"id":"1.168224571","rc":[{"batl":[[1,1000,0.02],[2,1000,0]],"ltp":2.06,"tv":1280.02,"id":7797764}]}]}
{"op":"mcm","clk":"1002806340","pt":1580646638898,"mc":[{"id":"1.168224571","rc":[{"trd":[[1.86,12.56]],"batb":[[0,1.86,258.63]],"ltp":1.86,"tv":2243.87,"id":2284304}],"tv":3523.9}]}
{"op":"mcm","clk":"1002806802","pt":1580646641491,"mc":[{"id":"1.168224571","rc":[{"batl":[[1,2.26,32.77],[2,1000,0.02]],"ltp":2.06,"tv":1280.02,"id":7797764},{"trd":[[1.86,100.99]],"batb":[[0,1.86,214.4]],"ltp":1.86,"tv":2332.3,"id":2284304}],"tv":3612.33}]}
{"op":"mcm","clk":"1002807391","pt":1580646644820,"mc":[{"id":"1.168224571","rc":[{"batb":[[0,1.86,234.94]],"batl":[[0,1.93,677.48]],"ltp":1.86,"tv":2332.3,"id":2284304}]}]}
{"op":"mcm","clk":"1002807527","pt":1580646645631,"mc":[{"id":"1.168224571","rc":[{"batl":[[1,1000,0.02],[2,1000,0]],"ltp":2.06,"tv":1280.02,"id":7797764}]}]}
{"op":"mcm","clk":"1002807796","pt":1580646647232,"mc":[{"id":"1.168224571","rc":[{"batl":[[0,1000,0.02],[1,1000,0]],"ltp":2.06,"tv":1280.02,"id":7797764},{"trd":[[1.86,189.42]],"batb":[[0,1.86,190.71]],"batl":[[0,1.93,216.99]],"ltp":1.86,"tv":2420.73,"id":2284304}],"tv":3700.76}]}
{"op":"mcm","clk":"1002807916","pt":1580646647921,"mc":[{"id":"1.168224571","rc":[{"batb":[[0,1.83,184.05],[1,1.74,90.74],[2,1.73,154.6]],"batl":[[0,3,42.46],[1,1000,0.02],[2,3,0]],"ltp":1.86,"tv":2420.73,"id":2284304}]}]}
{"op":"mcm","clk":"1002808499","pt":1580646651251,"mc":[{"id":"1.168224571","rc":[{"batb":[[0,1.97,119.85]],"ltp":2.06,"tv":1280.02,"id":7797764},{"batb":[[1,1.77,88.3],[2,1.74,90.72]],"ltp":1.86,"tv":2420.73,"id":2284304}]}]}
{"op":"mcm","clk":"1002808907","pt":1580646653759,"mc":[{"id":"1.168224571","rc":[{"batb":[[0,1.84,212.69],[1,1.83,184.05],[2,1.82,257.14]],"batl":[[0,1.91,261.21],[1,1.93,217.23],[2,3,42.46]],"ltp":1.86,"tv":2420.73,"id":2284304}]}]}
{"op":"mcm","clk":"1002809558","pt":1580646657574,"mc":[{"id":"1.168224571","rc":[{"batb":[[0,1.83,184.05],[1,1.77,88.3],[2,1.74,90.72]],"batl":[[0,3,42.46],[1,1000,0.02],[2,3,0]],"ltp":1.86,"tv":2420.73,"id":2284304}]}]}
{"op":"mcm","clk":"1002810065","pt":1580646660501,"mc":[{"id":"1.168224571","rc":[{"batb":[[2,1.76,280.96]],"batl":[[0,1.99,151.9],[1,2.02,285.8],[2,3,42.46]],"ltp":1.86,"tv":2420.73,"id":2284304}]}]}
{"op":"mcm","clk":"1002812319","pt":1580646673396,"mc":[{"id":"1.168224571","rc":[{"batb":[[2,1.74,90.72]],"ltp":1.86,"tv":2420.73,"id":2284304}]}]}
{"op":"mcm","clk":"1002812851","pt":1580646676488,"mc":[{"id":"1.168224571","rc":[{"batl":[[0,2.14,493],[1,2.16,87.66],[2,1000,0.02]],"ltp":2.06,"tv":1280.02,"id":7797764},{"batb":[[0,1.92,239],[1,1.9,224.21],[2,1.84,9.72]],"batl":[[1,2.02,889.8]],"ltp":1.86,"tv":2420.73,"id":2284304}]}]}
{"op":"mcm","clk":"1002813002","pt":1580646677393,"mc":[{"id":"1.168224571","rc":[{"batb":[[1,1.92,64.99],[2,1.75,20.16]],"ltp":2.06,"tv":1280.02,"id":7797764},{"batb":[[0,1.95,65.15],[1,1.92,239],[2,1.9,224.21]],"ltp":1.86,"tv":2420.73,"id":2284304}]}]}
{"op":"mcm","clk":"1002813127","pt":1580646678089,"mc":[{"id":"1.168224571","rc":[{"batb":[[1,1.94,44.53],[2,1.92,64.99]],"batl":[[1,2.16,123.79]],"ltp":2.06,"tv":1280.02,"id":7797764},{"batl":[[2,2.06,39.94]],"ltp":1.86,"tv":2420.73,"id":2284304}]}]}
{"op":"mcm","clk":"1002813676","pt":1580646681165,"mc":[{"id":"1.168224571","rc":[{"trd":[[1.95,35.03]],"batb":[[0,1.95,48.45]],"ltp":1.95,"tv":2454.13,"id":2284304}],"tv":3734.16}]}
{"op":"mcm","clk":"1002814205","pt":1580646684441,"mc":[{"id":"1.168224571","rc":[{"trd":[[1.95,68.43]],"batb":[[0,1.95,31.75]],"ltp":1.95,"tv":2487.53,"id":2284304}],"tv":3767.56}]}
{"op":"mcm","clk":"1002814572","pt":1580646686452,"mc":[{"id":"1.168224571","rc":[{"trd":[[1.95,76.43]],"batb":[[0,1.95,27.75]],"ltp":1.95,"tv":2495.53,"id":2284304}],"tv":3775.56}]}
{"op":"mcm","clk":"1002814628","pt":1580646686723,"mc":[{"id":"1.168224571","rc":[{"trd":[[1.95,80.43]],"batb":[[0,1.95,25.75]],"ltp":1.95,"tv":2499.53,"id":2284304}],"tv":3779.56}]}
{"op":"mcm","clk":"1002814778","pt":1580646687627,"mc":[{"id":"1.168224571","rc":[{"trd":[[1.95,113.83]],"batb":[[0,1.95,9.05]],"ltp":1.95,"tv":2532.93,"id":2284304}],"tv":3812.96}]}
{"op":"mcm","clk":"1002815461","pt":1580646691238,"mc":[{"id":"1.168224571","rc":[{"batl":[[0,2.16,36.13],[1,1000,0.02],[2,1000,0]],"ltp":2.06,"tv":1280.02,"id":7797764},{"trd":[[1.95,131.63]],"batb":[[0,1.92,239.14],[1,1.9,224.21],[2,1.88,73.96]],"batl":[[1,2.02,285.8]],"ltp":1.95,"tv":2550.73,"id":2284304}],"tv":3830.76}]}
{"op":"mcm","clk":"1002815659","pt":1580646692295,"mc":[{"id":"1.168224571","rc":[{"trd":[[2,77.02]],"batb":[[0,1.94,44.53],[1,1.92,64.99],[2,1.75,20.16]],"batl":[[0,2,1.62],[1,2.16,36.13],[2,1000,0.02]],"ltp":2.0,"tv":1281.33,"id":7797764},{"batb":[[0,1.88,73.96],[1,1.87,47.89],[2,1.83,167.66]],"batl":[[0,2.06,39.94],[1,3,42.01],[2,1000,0.02]],"ltp":1.95,"tv":2550.73,"id":2284304}],"tv":3832.06}]}
{"op":"mcm","clk":"1002815835","pt":1580646693191,"mc":[{"id":"1.168224571","rc":[{"batb":[[0,1.92,64.99],[1,1.75,20.16],[2,1.4,75.72]],"batl":[[1,1000,0.02],[2,1000,0]],"ltp":2.0,"tv":1281.33,"id":7797764},{"batb":[[1,1.83,167.66],[2,1.73,154.61]],"batl":[[0,3,42.46],[1,1000,0.02],[2,1000,0]],"ltp":1.95,"tv":2550.73,"id":2284304}]}]}
{"op":"mcm","clk":"1002816141","pt":1580646694983,"mc":[{"id":"1.168224571","rc":[{"batb":[[0,1.93,63.97]],"ltp":2.0,"tv":1281.33,"id":7797764},{"batb":[[0,1.87,75.14],[1,1.86,197.14],[2,1.84,248.2]],"batl":[[0,2.04,209.86],[1,2.06,179.01],[2,3,42.01]],"ltp":1.95,"tv":2550.73,"id":2284304}]}]}
{"op":"mcm","clk":"1002816278","pt":1580646695770,"mc":[{"id":"1.168224571","rc":[{"trd":[[2,80.26]],"batl":[[0,1000,0.02],[1,1000,0]],"ltp":2.0,"tv":1284.57,"id":7797764}],"tv":3835.3}]}
{"op":"mcm","clk":"1002816793","pt":1580646698787,"mc":[{"id":"1.168224571","rc":[{"batb":[[1,1.83,167.66],[2,1.73,154.61]],"batl":[[0,3,42.46],[1,1000,0.02],[2,3,0]],"ltp":1.95,"tv":2550.73,"id":2284304}]}]}
{"op":"mcm","clk":"1002817238","pt":1580646701404,"mc":[{"id":"1.168224571","rc":[{"batl":[[0,2.04,2955.6],[1,2.06,918.83],[2,2.08,501]],"ltp":2.0,"tv":1284.57,"id":7797764},{"batl":[[0,2.06,418.45],[1,3,42.01],[2,1000,0.02]],"ltp":1.95,"tv":2550.73,"id":2284304}]}]}
{"op":"mcm","clk":"1002817407","pt":1580646702314,"mc":[{"id":"1.168224571","rc":[{"batb":[[0,1.96,233.77],[1,1.94,210.11],[2,1.93,63.97]],"batl":[[0,2.04,212.2],[1,2.06,270.91],[2,2.08,539.65]],"ltp":2.0,"tv":1284.57,"id":7797764},{"batb":[[0,1.98,121.48],[1,1.94,44.53],[2,1.92,68.37]],"batl":[[1,2.14,36.13],[2,3,42.01]],"ltp":1.95,"tv":2550.73,"id":2284304}]}]}
{"op":"mcm","clk":"1002818630","pt":1580646708714,"mc":[{"id":"1.168224571","rc":[{"trd":[[1.98,33.44]],"batb":[[0,1.98,104.76]],"ltp":1.98,"tv":2584.17,"id":2284304}],"tv":3868.74}]}
{"op":"mcm","clk":"1002819801","pt":1580646715085,"mc":[{"id":"1.168224571","rc":[{"trd":[[1.98,233.45]],"batb":[[0,1.98,4.76]],"batl":[[0,2.04,1013.08],[1,2.06,418],[2,2.14,36.13]],"ltp":1.98,"tv":2784.18,"id":2284304}],"tv":4068.75}]}
{"op":"mcm","clk":"1002819958","pt":1580646715991,"mc":[{"id":"1.168224571","rc":[{"trd":[[1.98,236.98]],"batb":[[0,1.98,2.99]],"ltp":1.98,"tv":2787.72,"id":2284304}],"tv":4072.29}]}
{"op":"mcm","clk":"1002820755","pt":1580646720298,"mc":[{"id":"1.168224571","rc":[{"trd":[[1.98,242.96]],"batb":[[0,1.94,44.53],[1,1.92,68.37],[2,1.83,167.66]],"batl":[[0,1.98,72.73],[1,2.04,1013.08],[2,2.06,418]],"ltp":1.98,"tv":2793.7,"id":2284304}],"tv":4078.27}]}
{"op":"mcm","clk":"1002821308","pt":1580646723190,"mc":[{"id":"1.168224571","rc":[{"trd":[[2.02,20.99]],"ltp":2.02,"tv":1288.35,"id":7797764},{"trd":[[1.98,246.83]],"batl":[[0,1.98,68.87]],"ltp":1.98,"tv":2797.56,"id":2284304}],"tv":4085.92}]}
{"op":"mcm","clk":"1002821522","pt":1580646724303,"mc":[{"id":"1.168224571","rc":[{"trd":[[2.02,21.64]],"ltp":2.02,"tv":1289.0,"id":7797764},{"trd":[[1.98,247.49]],"batl":[[0,1.98,68.2]],"ltp":1.98,"tv":2798.23,"id":2284304}],"tv":4087.23}]}
{"op":"mcm","clk":"1002822241","pt":1580646728116,"mc":[{"id":"1.168224571","rc":[{"trd":[[2.04,7.71]],"batl":[[0,2.04,210.28]],"ltp":2.04,"tv":1290.92,"id":7797764},{"trd":[[1.96,2]],"ltp":1.96,"tv":2800.23,"id":2284304}],"tv":4091.15}]}
{"op":"mcm","clk":"1002822660","pt":1580646730303,"mc":[{"id":"1.168224571","rc":[{"batl":[[1,2.06,418.45],[2,2.14,36.13]],"ltp":1.96,"tv":2800.23,"id":2284304}]}]}
{"op":"mcm","clk":"1002823234","pt":1580646733442,"mc":[{"id":"1.168224571","rc":[{"trd":[[2.04,217.99]],"batl":[[0,2.06,270.91],[1,2.08,539.65],[2,2.14,89.54]],"ltp":2.04,"tv":1501.2,"id":7797764},{"trd":[[1.96,220.86]],"batl":[[0,1.95,793.77],[1,1.98,68.2],[2,2.06,418.45]],"ltp":1.96,"tv":3019.09,"id":2284304}],"tv":4520.29}]}
{"op":"mcm","clk":"1002823384","pt":1580646734319,"mc":[{"id":"1.168224571","rc":[{"batb":[[0,1.93,63.97],[1,1.88,47.05],[2,1.81,77.97]],"batl":[[0,2.06,91.88]],"ltp":2.04,"tv":1501.2,"id":7797764},{"batl":[[1,1.98,70.45]],"ltp":1.96,"tv":3019.09,"id":2284304}]}]}
{"op":"mcm","clk":"1002823918","pt":1580646737309,"mc":[{"id":"1.168224571","rc":[{"trd":[[1.95,605.3]],"batl":[[0,1.95,556.94],[2,2.02,143.92]],"ltp":1.95,"tv":3492.75,"id":2284304}],"tv":4993.96}]}
{"op":"mcm","clk":"1002824298","pt":1580646739326,"mc":[{"id":"1.168224571","rc":[{"batb":[[1,1.88,47.7]],"ltp":2.04,"tv":1501.2,"id":7797764},{"batl":[[2,2.06,418.45]],"ltp":1.95,"tv":3492.75,"id":2284304}]}]}
{"op":"mcm","clk":"1002824822","pt":1580646742069,"mc":[{"id":"1.168224571","rc":[{"trd":[[2.04,228.07]],"ltp":2.04,"tv":1511.28,"id":7797764},{"trd":[[1.95,615.85]],"batb":[[2,1.87,249.12]],"batl":[[0,1.95,546.39]],"ltp":1.95,"tv":3503.3,"id":2284304}],"tv":5014.59}]}
{"op":"mcm","clk":"1002826017","pt":1580646748145,"mc":[{"id":"1.168224571","rc":[{"batl":[[0,2.08,38.65],[1,1000,0.02],[2,2.14,0]],"ltp":2.04,"tv":1511.28,"id":7797764},{"batl":[[2,2.12,37.42]],"ltp":1.95,"tv":3503.3,"id":2284304}]}]}
{"op":"mcm","clk":"1002826271","pt":1580646749267,"mc":[{"id":"1.168224571","rc":[{"batb":[[0,1.81,78.62],[1,1.75,20.16],[2,1.5,113.58]],"batl":[[0,1000,0.02],[1,1000,0]],"ltp":2.04,"tv":1511.28,"id":7797764},{"batb":[[0,1.92,68.37],[1,1.87,249.12],[2,1.85,244.16]],"batl":[[2,2.16,264.42]],"ltp":1.95,"tv":3503.3,"id":2284304}]}]}
{"op":"mcm","clk":"1002826673","pt":1580646751450,"mc":[{"id":"1.168224571","rc":[{"batb":[[0,1.85,76.26],[1,1.81,77.97],[2,1.75,20.16]],"ltp":2.04,"tv":1511.28,"id":7797764},{"batb":[[1,1.87,319.62]],"ltp":1.95,"tv":3503.3,"id":2284304}]}]}
{"op":"mcm","clk":"1002826870","pt":1580646752363,"mc":[{"id":"1.168224571","rc":[{"batb":[[1,1.75,20.16],[2,1.5,113.58]],"ltp":2.04,"tv":1511.28,"id":7797764},{"batb":[[0,1.87,70.5],[1,1.83,167.66],[2,1.73,154.61]],"batl":[[2,3,42.46]],"ltp":1.95,"tv":3503.3,"id":2284304}]}]}
{"op":"mcm","clk":"1002827266","pt":1580646754242,"mc":[{"id":"1.168224571","rc":[{"batb":[[0,2.06,35.67],[1,1.85,76.26],[2,1.75,20.16]],"ltp":2.04,"tv":1511.28,"id":7797764}]}]}
{"op":"mcm","clk":"1002827510","pt":1580646755470,"mc":[{"id":"1.168224571","rc":[{"trd":[[1.91,1.3],[1.96,0.47],[2.02,90.7],[2.04,750.35],[2.06,77.52]],"batb":[[0,1.87,209.9],[1,1.85,319.59]],"batl":[[0,1.93,488],[1,1.94,230.34],[2,1.96,207.39]],"ltp":1.91,"tv":2175.73,"id":7797764},{"trd":[[1.95,1162.24],[1.98,317.95],[2.04,0.45]],"batb":[[0,2,108.24],[1,1.95,354.31],[2,1.87,70.5]],"batl":[[0,2.24,505],[1,3,42.01],[2,4,2.27]],"ltp":2.04,"tv":4120.6,"id":2284304}],"tv":6296.34}]}
{"op":"mcm","clk":"1002827717","pt":1580646756491,"mc":[{"id":"1.168224571","rc":[{"batb":[[0,2.08,102.21],[1,2,1229.52],[2,1.99,48.76]],"ltp":2.04,"tv":4120.6,"id":2284304}]}]}
{"op":"mcm","clk":"1002827882","pt":1580646757287,"mc":[{"id":"1.168224571","rc":[{"batb":[[1,2,1821.31]],"batl":[[1,3,255.46]],"ltp":2.04,"tv":4120.6,"id":2284304}]}]}
{"op":"mcm","clk":"1002828151","pt":1580646758464,"mc":[{"id":"1.168224571","rc":[{"batb":[[2,1.8,52.09]],"ltp":1.91,"tv":2175.73,"id":7797764},{"batl":[[0,2.24,538.61]],"ltp":2.04,"tv":4120.6,"id":2284304}]}]}
{"op":"mcm","clk":"1002828328","pt":1580646759372,"mc":[{"id":"1.168224571","rc":[{"batb":[[2,1.75,20.16]],"batl":[[2,1.96,249.4]],"ltp":1.91,"tv":2175.73,"id":7797764},{"batb":[[1,2.04,40.33],[2,2,108.24]],"batl":[[0,2.24,505]],"ltp":2.04,"tv":4120.6,"id":2284304}]}]}
{"op":"mcm","clk":"1002828407","pt":1580646759747,"mc":[{"id":"1.168224571","rc":[{"batb":[[2,1.79,52.93]],"ltp":1.91,"tv":2175.73,"id":7797764},{"batl":[[1,2.26,32.77],[2,3,255.46]],"ltp":2.04,"tv":4120.6,"id":2284304}]}]}
{"op":"mcm","clk":"1002828784","pt":1580646761470,"mc":[{"id":"1.168224571","rc":[{"trd":[[2.08,43.92]],"batb":[[0,2.08,80.25]],"ltp":2.08,"tv":4164.52,"id":2284304}],"tv":6340.26}]}
{"op":"mcm","clk":"1002830337","pt":1580646769398,"mc":[{"id":"1.168224571","rc":[{"trd":[[1.93,2.7]],"batl":[[0,1.94,230.34],[1,1.96,249.4],[2,1000,0.02]],"ltp":1.93,"tv":2178.43,"id":7797764},{"batb":[[2,1.97,120.3]],"batl":[[0,2.26,32.77],[1,3,255.46],[2,4,2.27]],"ltp":2.08,"tv":4164.52,"id":2284304}],"tv":6342.96}]}
{"op":"mcm","clk":"1002830422","pt":1580646769770,"mc":[{"id":"1.168224571","rc":[{"batb":[[0,1.79,52.93],[1,1.75,20.16],[2,1.73,94.18]],"batl":[[0,1.96,42.01],[1,1000,0.02],[2,1000,0]],"ltp":1.93,"tv":2178.43,"id":7797764},{"batb":[[0,2.04,40.33],[1,1.97,120.3],[2,1.77,402.28]],"ltp":2.08,"tv":4164.52,"id":2284304}]}]}
{"op":"mcm","clk":"1002830723","pt":1580646771229,"mc":[{"id":"1.168224571","rc":[{"batb":[[0,1.75,20.16],[1,1.73,94.18],[2,1.4,75.72]],"batl":[[0,1000,0.02],[1,1000,0]],"ltp":1.93,"tv":2178.43,"id":7797764},{"batb":[[0,1.97,120.3],[1,1.77,402.28],[2,1.73,154.6]],"batl":[[0,3,255.46],[1,4,2.27],[2,1000,0.02]],"ltp":2.08,"tv":4164.52,"id":2284304}]}]}
{"op":"mcm","clk":"1002831148","pt":1580646773391,"mc":[{"id":"1.168224571","rc":[{"batb":[[1,1.74,303.79],[2,1.72,310.26]],"ltp":1.93,"tv":2178.43,"id":7797764},{"batb":[[0,1.96,120.93]],"ltp":2.08,"tv":4164.52,"id":2284304}]}]}
{"op":"mcm","clk":"1002831433","pt":1580646774916,"mc":[{"id":"1.168224571","rc":[{"batb":[[1,1.73,154.61],[2,1.5,113.58]],"batl":[[0,3,42.01]],"ltp":2.08,"tv":4164.52,"id":2284304}]}]}
{"op":"mcm","clk":"1002831715","pt":1580646776398,"mc":[{"id":"1.168224571","rc":[{"batl":[[0,1.76,113.88],[1,1.78,609],[2,1.8,268.61]],"ltp":1.93,"tv":2178.43,"id":7797764},{"batb":[[0,2.26,106.73],[1,1.96,120.93],[2,1.73,154.61]],"batl":[[0,2.48,400],[1,3,42.01],[2,4,2.27]],"ltp":2.08,"tv":4164.52,"id":2284304}]}]}
{"op":"mcm","clk":"1002831907","pt":1580646777408,"mc":[{"id":"1.168224571","rc":[{"batb":[[1,2.24,81.28],[2,2.12,96.54]],"ltp":2.08,"tv":4164.52,"id":2284304}]}]}
{"op":"mcm","clk":"1002832079","pt":1580646778319,"mc":[{"id":"1.168224571","rc":[{"batb":[[2,2.2,34.45]],"batl":[[0,2.48,427.73],[2,3.45,180.4]],"ltp":2.08,"tv":4164.52,"id":2284304}]}]}
{"op":"mcm","clk":"1002832849","pt":1580646782441,"mc":[{"id":"1.168224571","rc":[{"batl":[[2,1.8,749.2]],"ltp":1.93,"tv":2178.43,"id":7797764}]}]}
{"op":"mcm","clk":"1002832944","pt":1580646782816,"mc":[{"id":"1.168224571","rc":[{"trd":[[1.76,113.88],[1.78,1.1]],"batl":[[0,1.78,607.9],[1,1.8,749.2],[2,1.82,758.04]],"ltp":1.78,"tv":2293.41,"id":7797764},{"trd":[[2.28,0.86],[2.3,87.14]],"ltp":2.28,"tv":4252.52,"id":2284304}],"tv":6545.94}]}
{"op":"mcm","clk":"1002833829","pt":1580646787352,"mc":[{"id":"1.168224571","rc":[{"batb":[[0,1.76,100],[1,1.75,20.16],[2,1.74,303.79]],"ltp":1.78,"tv":2293.41,"id":7797764}]}]}
{"op":"mcm","clk":"1002834207","pt":1580646789328,"mc":[{"id":"1.168224571","rc":[{"batb":[[2,1.74,93.63]],"batl":[[0,1.8,480.59],[1,1.82,497.4],[2,1.83,42.01]],"ltp":1.78,"tv":2293.41,"id":7797764},{"batb":[[0,2.24,81.28],[1,2.2,34.45],[2,2.12,96.54]],"batl":[[0,2.48,27.73]],"ltp":2.28,"tv":4252.52,"id":2284304}]}]}
{"op":"mcm","clk":"1002834251","pt":1580646789545,"mc":[{"id":"1.168224571","rc":[{"batb":[[2,1.71,494.03]],"ltp":1.78,"tv":2293.41,"id":7797764},{"batb":[[0,2.2,34.45],[1,2.12,96.54],[2,1.92,394.91]],"ltp":2.28,"tv":4252.52,"id":2284304}]}]}
{"op":"mcm","clk":"1002834577","pt":1580646791250,"mc":[{"id":"1.168224571","rc":[{"batl":[[2,1000,0.02]],"ltp":1.78,"tv":2293.41,"id":7797764},{"batb":[[0,2.12,96.54],[1,1.92,394.91],[2,1.73,154.61]],"batl":[[0,3,42.01],[1,3.45,180.4],[2,4,2.27]],"ltp":2.28,"tv":4252.52,"id":2284304}]}]}
{"op":"mcm","clk":"1002834807","pt":1580646792334,"mc":[{"id":"1.168224571","rc":[{"batl":[[2,1.89,226.62]],"ltp":1.78,"tv":2293.41,"id":7797764}]}]}
{"op":"mcm","clk":"1002835043","pt":1580646793453,"mc":[{"id":"1.168224571","rc":[{"batl":[[2,1000,0.02]],"ltp":1.78,"tv":2293.41,"id":7797764}]}]}
{"op":"mcm","clk":"1002835132","pt":1580646793832,"mc":[{"id":"1.168224571","rc":[{"batb":[[0,1.75,20.16],[1,1.63,117.08],[2,1.61,367.57]],"ltp":1.78,"tv":2293.41,"id":7797764}]}]}
{"op":"mcm","clk":"1002835629","pt":1580646796424,"mc":[{"id":"1.168224571","rc":[{"trd":[[1.63,234.15],[1.75,40.32]],"batb":[[0,1.61,367.57],[1,1.6,202.27],[2,1.3,113.58]],"batl":[[0,1.63,433.93],[1,1.67,337.73],[2,1.69,506.06]],"ltp":1.63,"tv":2567.89,"id":7797764},{"batb":[[0,2.54,216.68],[1,2.12,96.54]],"batl":[[0,2.82,344],[1,3,42.01]],"ltp":2.28,"tv":4252.52,"id":2284304}],"tv":6820.41}]}
{"op":"mcm","clk":"1002835841","pt":1580646797452,"mc":[{"id":"1.168224571","rc":[{"batb":[[2,1.55,140.37]],"ltp":1.63,"tv":2567.89,"id":7797764},{"batb":[[1,2.46,63.18],[2,2.34,72.86]],"ltp":2.28,"tv":4252.52,"id":2284304}]}]}
{"op":"mcm","clk":"1002836038","pt":1580646798462,"mc":[{"id":"1.168224571","rc":[{"batb":[[2,1.58,72.26]],"ltp":1.63,"tv":2567.89,"id":7797764},{"batl":[[0,2.72,24.37],[1,2.82,344],[2,3,42.01]],"ltp":2.28,"tv":4252.52,"id":2284304}]}]}
{"op":"mcm","clk":"1002836242","pt":1580646799457,"mc":[{"id":"1.168224571","rc":[{"trd":[[1.63,236.85]],"batb":[[2,1.55,140.37]],"batl":[[0,1.63,432.58]],"ltp":1.63,"tv":2570.59,"id":7797764}],"tv":6823.11}]}
{"op":"mcm","clk":"1002836404","pt":1580646800245,"mc":[{"id":"1.168224571","rc":[{"batb":[[2,1.57,73.1]],"ltp":1.63,"tv":2570.59,"id":7797764},{"batb":[[2,2.44,28.57]],"ltp":2.28,"tv":4252.52,"id":2284304}]}]}
{"op":"mcm","clk":"1002836903","pt":1580646802927,"mc":[{"id":"1.168224571","rc":[{"batb":[[2,1.57,567.13]],"batl":[[1,1.67,818.32],[2,1.69,1003.46]],"ltp":1.63,"tv":2570.59,"id":7797764}]}]}
{"op":"mcm","clk":"1002837999","pt":1580646808447,"mc":[{"id":"1.168224571","rc":[{"batb":[[0,1.57,567.13],[1,1.55,651.21],[2,1.3,113.58]],"batl":[[0,1.67,480.59],[1,1.69,497.4],[2,1.7,42.01]],"ltp":1.63,"tv":2570.59,"id":7797764},{"batb":[[0,2.46,63.18],[1,2.44,28.57],[2,2.34,72.86]],"batl":[[1,3,42.01],[2,3.9,158.24]],"ltp":2.28,"tv":4252.52,"id":2284304}]}]}
{"op":"mcm","clk":"1002838180","pt":1580646809457,"mc":[{"id":"1.168224571","rc":[{"batb":[[0,1.63,200],[1,1.57,494.03],[2,1.55,651.21]],"batl":[[2,1000,0.02]],"ltp":1.63,"tv":2570.59,"id":7797764},{"batb":[[0,2.34,72.86],[1,2.04,394.09],[2,1.73,154.61]],"batl":[[0,3,42.01],[1,3.9,158.24],[2,4,2.27]],"ltp":2.28,"tv":4252.52,"id":2284304}]}]}
{"op":"mcm","clk":"1002838563","pt":1580646811415,"mc":[{"id":"1.168224571","rc":[{"batl":[[2,1.73,299.36]],"ltp":1.63,"tv":2570.59,"id":7797764}]}]}
{"op":"mcm","clk":"1002838636","pt":1580646811830,"mc":[{"id":"1.168224571","rc":[{"batb":[[2,1.55,510.84]],"ltp":1.63,"tv":2570.59,"id":7797764},{"batb":[[0,2.36,71.05]],"ltp":2.28,"tv":4252.52,"id":2284304}]}]}
{"op":"mcm","clk":"1002839122","pt":1580646814547,"mc":[{"id":"1.168224571","rc":[{"batb":[[0,1.63,202.52]],"ltp":1.63,"tv":2570.59,"id":7797764}]}]}
{"op":"mcm","clk":"1002839660","pt":1580646817351,"mc":[{"id":"1.168224571","rc":[{"batb":[[1,1.53,337.26],[2,1.52,389.4]],"batl":[[2,1000,0.02]],"ltp":1.63,"tv":2570.59,"id":7797764}]}]}
{"op":"mcm","clk":"1002839999","pt":1580646819136,"mc":[{"id":"1.168224571","rc":[{"batb":[[1,1.73,154.61],[2,1.5,113.58]],"batl":[[1,4,2.27],[2,1000,0.02]],"ltp":2.28,"tv":4252.52,"id":2284304}]}]}
{"op":"mcm","clk":"1002840239","pt":1580646820420,"mc":[{"id":"1.168224571","rc":[{"trd":[[1.63,640.27]],"batb":[[0,1.53,337.26],[1,1.52,389.4],[2,1.45,93.26]],"batl":[[0,1.54,792],[1,1.58,480.85],[2,1.59,204.53]],"ltp":1.63,"tv":2974.01,"id":7797764},{"trd":[[2.6,1.02]],"batb":[[0,2.8,116.13],[1,2.36,71.05],[2,1.73,154.61]],"batl":[[1,3.15,282],[2,3.2,18.48]],"ltp":2.6,"tv":4253.54,"id":2284304}],"tv":7227.55}]}
{"op":"mcm","clk":"1002840420","pt":1580646821477,"mc":[{"id":"1.168224571","rc":[{"batb":[[2,1.48,161.69]],"batl":[[2,1.59,508.23]],"ltp":1.63,"tv":2974.01,"id":7797764},{"batb":[[1,2.72,49.73],[2,2.48,62.39]],"batl":[[2,4,2.27]],"ltp":2.6,"tv":4253.54,"id":2284304}]}]}
{"op":"mcm","clk":"1002840503","pt":1580646821855,"mc":[{"id":"1.168224571","rc":[{"batl":[[2,1.59,919.21]],"ltp":1.63,"tv":2974.01,"id":7797764}]}]}
{"op":"mcm","clk":"1002840770","pt":1580646823133,"mc":[{"id":"1.168224571","rc":[{"batl":[[2,3.25,18.48]],"ltp":2.6,"tv":4253.54,"id":2284304}]}]}
{"op":"mcm","clk":"1002841040","pt":1580646824452,"mc":[{"id":"1.168224571","rc":[{"trd":[[1.53,84.02]],"batb":[[0,1.53,295.25]],"batl":[[2,1.59,282.55]],"ltp":1.53,"tv":3058.03,"id":7797764},{"batl":[[2,3.2,18.48]],"ltp":2.6,"tv":4253.54,"id":2284304}],"tv":7311.57}]}
{"op":"mcm","clk":"1002841077","pt":1580646824654,"mc":[{"id":"1.168224571","rc":[{"batl":[[0,1.54,834.01],[2,1.59,204.53]],"ltp":1.53,"tv":3058.03,"id":7797764},{"batb":[[0,2.82,22.69],[1,2.8,116.13],[2,2.72,49.73]],"ltp":2.6,"tv":4253.54,"id":2284304}]}]}
{"op":"mcm","clk":"1002841580","pt":1580646827371,"mc":[{"id":"1.168224571","rc":[{"batb":[[0,1.53,323.72]],"ltp":1.53,"tv":3058.03,"id":7797764}]}]}
{"op":"mcm","clk":"1002841621","pt":1580646827539,"mc":[{"id":"1.168224571","rc":[{"trd":[[1.53,104.18]],"batb":[[0,1.53,313.64]],"ltp":1.53,"tv":3078.19,"id":7797764}],"tv":7331.73}]}
{"op":"mcm","clk":"1002842572","pt":1580646832874,"mc":[{"id":"1.168224571","rc":[{"trd":[[1.54,3.26]],"batl":[[0,1.54,830.75]],"ltp":1.54,"tv":3081.45,"id":7797764},{"trd":[[2.84,1.77]],"ltp":2.84,"tv":4255.31,"id":2284304}],"tv":7336.76}]}
{"op":"mcm","clk":"1002843853","pt":1580646839152,"mc":[{"id":"1.168224571","rc":[{"trd":[[1.53,731.46]],"batb":[[0,1.52,389.4],[1,1.48,161.69],[2,1.45,93.26]],"batl":[[1,1.58,332.36],[2,1000,0.02]],"ltp":1.53,"tv":3708.73,"id":7797764}],"tv":7964.04}]}
{"op":"mcm","clk":"1002844499","pt":1580646842252,"mc":[{"id":"1.168224571","rc":[{"batb":[[0,1.48,161.69],[1,1.45,93.26],[2,1.26,3.37]],"batl":[[0,1.54,42.01],[1,1000,0.02],[2,1000,0]],"ltp":1.53,"tv":3708.73,"id":7797764},{"batb":[[1,2.48,62.24],[2,2.22,384.52]],"batl":[[1,3.2,18.48],[2,4,2.27]],"ltp":2.84,"tv":4255.31,"id":2284304}]}]}
{"op":"mcm","clk":"1002844688","pt":1580646843309,"mc":[{"id":"1.168224571","rc":[{"batb":[[1,1.26,3.37],[2,1.25,378.62]],"batl":[[0,1000,0.02],[1,1000,0]],"ltp":1.53,"tv":3708.73,"id":7797764},{"batb":[[0,2.48,62.24],[1,2.22,384.52],[2,1.73,154.61]],"batl":[[1,4,2.27],[2,4.6,136.05]],"ltp":2.84,"tv":4255.31,"id":2284304}]}]}
{"op":"mcm","clk":"1002845066","pt":1580646845306,"mc":[{"id":"1.168224571","rc":[{"batb":[[0,1.48,616.05],[1,1.47,283.99],[2,1.26,3.37]],"batl":[[0,1.65,323.25],[1,1.66,176.27],[2,1000,0.02]],"ltp":1.53,"tv":3708.73,"id":7797764}]}]}
{"op":"mcm","clk":"1002845151","pt":1580646845689,"mc":[{"id":"1.168224571","rc":[{"batb":[[0,1.48,161.69],[1,1.26,3.37],[2,1.25,378.62]],"ltp":1.53,"tv":3708.73,"id":7797764}]}]}
{"op":"mcm","clk":"1002845448","pt":1580646847185,"mc":[{"id":"1.168224571","rc":[{"batl":[[2,1000,0.02]],"ltp":2.84,"tv":4255.31,"id":2284304}]}]}
{"op":"mcm","clk":"1002845664","pt":1580646848403,"mc":[{"id":"1.168224571","rc":[{"trd":[[1.53,744.06]],"batb":[[0,1.55,1256.51],[1,1.48,161.69],[2,1.26,3.37]],"batl":[[0,1.62,576],[1,1.65,323.25],[2,1.66,176.27]],"ltp":1.53,"tv":3721.33,"id":7797764},{"trd":[[2.88,6.7]],"batl":[[0,2.66,2321.8],[1,2.78,5.26],[2,2.8,962.87]],"ltp":2.88,"tv":4262.01,"id":2284304}],"tv":7983.34}]}
{"op":"mcm","clk":"1002845834","pt":1580646849404,"mc":[{"id":"1.168224571","rc":[{"batb":[[0,1.6,239.06],[1,1.59,328.29],[2,1.55,125.65]],"ltp":1.53,"tv":3721.33,"id":7797764},{"batb":[[0,2.52,60.74],[1,2.3,76.87],[2,2.22,384.52]],"batl":[[0,2.8,96.96],[1,2.86,374],[2,3,42.01]],"ltp":2.88,"tv":4262.01,"id":2284304}]}]}
{"op":"mcm","clk":"1002846011","pt":1580646850296,"mc":[{"id":"1.168224571","rc":[{"trd":[[1.62,5.32]],"batl":[[0,1.62,615.35]],"ltp":1.62,"tv":3726.65,"id":7797764},{"batb":[[0,2.6,26.05],[1,2.52,60.74],[2,2.36,2.61]],"batl":[[2,2.94,21]],"ltp":2.88,"tv":4262.01,"id":2284304}],"tv":7988.66}]}
{"op":"mcm","clk":"1002846554","pt":1580646853208,"mc":[{"id":"1.168224571","rc":[{"batl":[[2,2.94,21.89]],"ltp":2.88,"tv":4262.01,"id":2284304}]}]}
{"op":"mcm","clk":"1002846887","pt":1580646854917,"mc":[{"id":"1.168224571","rc":[{"batb":[[2,1.56,494.03]],"batl":[[1,1.65,803.84]],"ltp":1.62,"tv":3726.65,"id":7797764}]}]}
{"op":"mcm","clk":"1002847578","pt":1580646858391,"mc":[{"id":"1.168224571","rc":[{"batl":[[0,1.62,42.01]],"ltp":1.62,"tv":3726.65,"id":7797764},{"batl":[[1,2.94,21.89],[2,3,42.01]],"ltp":2.88,"tv":4262.01,"id":2284304}]}]}
{"op":"mcm","clk":"1002847750","pt":1580646859343,"mc":[{"id":"1.168224571","rc":[{"batb":[[0,1.56,494.03],[1,1.54,510.84],[2,1.53,139.58]],"batl":[[0,1.65,480.59],[1,1.67,497.4],[2,1000,0.02]],"ltp":1.62,"tv":3726.65,"id":7797764},{"batb":[[0,2.36,2.61],[1,2.3,76.87],[2,2.22,384.52]],"batl":[[0,3,42.89],[1,3.9,158.24],[2,4,2.27]],"ltp":2.88,"tv":4262.01,"id":2284304}]}]}
{"op":"mcm","clk":"1002847851","pt":1580646859818,"mc":[{"id":"1.168224571","rc":[{"batl":[[0,2.6,100],[1,3,42.89],[2,3.9,158.24]],"ltp":2.88,"tv":4262.01,"id":2284304}]}]}
{"op":"mcm","clk":"1002848222","pt":1580646861736,"mc":[{"id":"1.168224571","rc":[{"batb":[[1,1.54,850.52],[2,1.53,380.21]],"batl":[[2,1.69,24.79]],"ltp":1.62,"tv":3726.65,"id":7797764},{"batb":[[0,2.44,4.42],[1,2.38,3.96],[2,2.36,2.61]],"batl":[[1,3,45.6]],"ltp":2.88,"tv":4262.01,"id":2284304}]}]}
{"op":"mcm","clk":"1002848538","pt":1580646863410,"mc":[{"id":"1.168224571","rc":[{"batl":[[0,3,45.6],[1,3.9,158.24],[2,4,2.27]],"ltp":2.88,"tv":4262.01,"id":2284304}]}]}
{"op":"mcm","clk":"1002850041","pt":1580646870564,"mc":[{"id":"1.168224571","rc":[{"batl":[[0,2.92,1.77],[1,3,44.72],[2,3.9,158.24]],"ltp":2.88,"tv":4262.01,"id":2284304}]}]}
{"op":"mcm","clk":"1002850300","pt":1580646871776,"mc":[{"id":"1.168224571","rc":[{"trd":[[1.65,10]],"batl":[[0,1.65,475.59]],"ltp":1.65,"tv":3736.65,"id":7797764}],"tv":7998.66}]}
{"op":"mcm","clk":"1002850644","pt":1580646873493,"mc":[{"id":"1.168224571","rc":[{"batl":[[0,3,45.6],[1,3.9,158.24],[2,4,2.27]],"ltp":2.88,"tv":4262.01,"id":2284304}]}]}
{"op":"mcm","clk":"1002850769","pt":1580646874081,"mc":[{"id":"1.168224571","rc":[{"batb":[[1,1.54,510.84],[2,1.53,139.58]],"batl":[[0,1.72,22.16],[1,1.76,214.9],[2,1.78,280.56]],"ltp":1.65,"tv":3736.65,"id":7797764},{"batb":[[0,2.38,3.96],[1,2.36,2.61],[2,2.3,76.87]],"ltp":2.88,"tv":4262.01,"id":2284304}]}]}
{"op":"mcm","clk":"1002851195","pt":1580646876379,"mc":[{"id":"1.168224571","rc":[{"batb":[[0,1.7,2179.65],[1,1.56,494.03],[2,1.54,510.84]],"batl":[[1,1.74,483],[2,1.76,214.9]],"ltp":1.65,"tv":3736.65,"id":7797764},{"batl":[[0,2.46,4012.59],[1,2.54,362],[2,2.58,5.62]],"ltp":2.88,"tv":4262.01,"id":2284304}]}]}
{"op":"mcm","clk":"1002851401","pt":1580646877382,"mc":[{"id":"1.168224571","rc":[{"batb":[[0,1.7,545.91],[1,1.69,98.51],[2,1.68,337.53]],"ltp":1.65,"tv":3736.65,"id":7797764},{"batb":[[1,2.3,76.87],[2,2.12,97.01]],"batl":[[0,2.46,152.44],[2,3,45.6]],"ltp":2.88,"tv":4262.01,"id":2284304}]}]}
{"op":"mcm","clk":"1002851561","pt":1580646878282,"mc":[{"id":"1.168224571","rc":[{"batl":[[0,1.72,64.17]],"ltp":1.65,"tv":3736.65,"id":7797764},{"batb":[[0,2.38,34.21]],"batl":[[2,2.62,26.09]],"ltp":2.88,"tv":4262.01,"id":2284304}]}]}
{"op":"mcm","clk":"1002852607","pt":1580646883484,"mc":[{"id":"1.168224571","rc":[{"batl":[[2,1.76,695.49]],"ltp":1.65,"tv":3736.65,"id":7797764},{"batb":[[2,2.16,5.03]],"ltp":2.88,"tv":4262.01,"id":2284304}]}]}
{"op":"mcm","clk":"1002852865","pt":1580646884813,"mc":[{"id":"1.168224571","rc":[{"trd":[[1.72,9.6]],"batl":[[0,1.72,59.37]],"ltp":1.72,"tv":3746.24,"id":7797764}],"tv":8008.26}]}
{"op":"mcm","clk":"1002853141","pt":1580646886105,"mc":[{"id":"1.168224571","rc":[{"trd":[[1.7,400]],"batb":[[0,1.7,345.91]],"ltp":1.7,"tv":4146.24,"id":7797764}],"tv":8408.26}]}
{"op":"mcm","clk":"1002853311","pt":1580646886894,"mc":[{"id":"1.168224571","rc":[{"batl":[[2,2.62,25.21]],"ltp":2.88,"tv":4262.01,"id":2284304}]}]}
{"op":"mcm","clk":"1002853919","pt":1580646889889,"mc":[{"id":"1.168224571","rc":[{"trd":[[1.7,421.2]],"batb":[[0,1.7,335.31]],"ltp":1.7,"tv":4167.45,"id":7797764}],"tv":8429.46}]}
{"op":"mcm","clk":"1002854440","pt":1580646892583,"mc":[{"id":"1.168224571","rc":[{"trd":[[2.38,1.76]],"batb":[[0,2.38,33.33]],"ltp":2.38,"tv":4263.77,"id":2284304}],"tv":8431.22}]}
{"op":"mcm","clk":"1002855191","pt":1580646896487,"mc":[{"id":"1.168224571","rc":[{"batl":[[1,1.76,695.49],[2,1.78,777.96]],"ltp":1.7,"tv":4167.45,"id":7797764},{"batl":[[1,2.62,25.21],[2,2.64,3.18]],"ltp":2.38,"tv":4263.77,"id":2284304}]}]}
{"op":"mcm","clk":"1002855370","pt":1580646897412,"mc":[{"id":"1.168224571","rc":[{"batb":[[0,1.66,494.03],[1,1.64,510.84],[2,1.62,114.72]],"batl":[[0,1.76,480.59],[1,1.78,497.4],[2,1.85,22.3]],"ltp":1.7,"tv":4167.45,"id":7797764},{"batb":[[0,2.12,97.01],[1,2.1,5.74],[2,1.92,394.91]],"batl":[[0,2.64,3.18],[1,2.76,3.02],[2,3,44.72]],"ltp":2.38,"tv":4263.77,"id":2284304}]}]}
{"op":"mcm","clk":"1002855922","pt":1580646900434,"mc":[{"id":"1.168224571","rc":[{"batb":[[2,1.63,320.1]],"ltp":1.7,"tv":4167.45,"id":7797764}]}]}
{"op":"mcm","clk":"1002856036","pt":1580646901017,"mc":[{"id":"1.168224571","rc":[{"batb":[[2,1.62,114.72]],"ltp":1.7,"tv":4167.45,"id":7797764}]}]}
{"op":"mcm","clk":"1002856620","pt":1580646904048,"mc":[{"id":"1.168224571","rc":[{"batb":[[0,1.73,244.93],[1,1.71,316.99],[2,1.66,494.03]],"batl":[[2,1.79,249.97]],"ltp":1.7,"tv":4167.45,"id":7797764}]}]}
{"op":"mcm","clk":"1002856821","pt":1580646905054,"mc":[{"id":"1.168224571","rc":[{"batb":[[0,1.66,494.03],[1,1.64,510.84],[2,1.62,114.72]],"batl":[[2,1.85,22.3]],"ltp":1.7,"tv":4167.45,"id":7797764}]}]}
{"op":"mcm","clk":"1002856971","pt":1580646905850,"mc":[{"id":"1.168224571","rc":[{"trd":[[1.66,4]],"batb":[[0,1.66,492.03]],"ltp":1.66,"tv":4171.45,"id":7797764}],"tv":8435.22}]}
{"op":"mcm","clk":"1002857426","pt":1580646907939,"mc":[{"id":"1.168224571","rc":[{"batb":[[2,1.63,320.1]],"ltp":1.66,"tv":4171.45,"id":7797764}]}]}
{"op":"mcm","clk":"1002857745","pt":1580646909429,"mc":[{"id":"1.168224571","rc":[{"batb":[[0,1.66,497.03],[2,1.62,114.72]],"ltp":1.66,"tv":4171.45,"id":7797764}]}]}
{"op":"mcm","clk":"1002857954","pt":1580646910447,"mc":[{"id":"1.168224571","rc":[{"batl":[[0,1.9,19.45],[1,1.91,260.62],[2,1.93,217.22]],"ltp":1.66,"tv":4171.45,"id":7797764}]}]}
{"op":"mcm","clk":"1002858371","pt":1580646912464,"mc":[{"id":"1.168224571","rc":[{"trd":[[1.84,84.02]],"batb":[[0,1.84,171.24],[1,1.82,257.12],[2,1.81,212.6]],"batl":[[0,1.9,489.45]],"ltp":1.84,"tv":4255.47,"id":7797764},{"batb":[[0,2.16,36.13],[1,2.12,97.01],[2,2.1,5.74]],"batl":[[0,2.22,168.92],[1,2.26,2],[2,2.28,506]],"ltp":2.38,"tv":4263.77,"id":2284304}],"tv":8519.24}]}
{"op":"mcm","clk":"1002858536","pt":1580646913364,"mc":[{"id":"1.168224571","rc":[{"trd":[[1.84,87.12]],"batb":[[0,1.84,168.14]],"batl":[[1,1000,0.02],[2,1.93,0]],"ltp":1.84,"tv":4258.57,"id":7797764},{"trd":[[2.2,2.59]],"ltp":2.2,"tv":4266.36,"id":2284304}],"tv":8524.93}]}
{"op":"mcm","clk":"1002859094","pt":1580646916274,"mc":[{"id":"1.168224571","rc":[{"batb":[[0,1.84,188.32]],"batl":[[0,1.87,42.01],[1,1.9,661.69],[2,1.92,220.86]],"ltp":1.84,"tv":4258.57,"id":7797764}]}]}
{"op":"mcm","clk":"1002859752","pt":1580646919473,"mc":[{"id":"1.168224571","rc":[{"batl":[[2,1.91,480.59]],"ltp":1.84,"tv":4258.57,"id":7797764}]}]}
{"op":"mcm","clk":"1002860116","pt":1580646921352,"mc":[{"id":"1.168224571","rc":[{"trd":[[1.84,90.74]],"batb":[[0,1.84,186.51]],"ltp":1.84,"tv":4262.18,"id":7797764}],"tv":8528.55}]}
{"op":"mcm","clk":"1002860490","pt":1580646923271,"mc":[{"id":"1.168224571","rc":[{"trd":[[1.84,131.09]],"batb":[[0,1.84,146.16]],"ltp":1.84,"tv":4302.53,"id":7797764},{"trd":[[2.2,36.33]],"ltp":2.2,"tv":4300.1,"id":2284304}],"tv":8602.64}]}
{"op":"mcm","clk":"1002860691","pt":1580646924382,"mc":[{"id":"1.168224571","rc":[{"batb":[[2,1.8,577.18]],"batl":[[1,1.9,191.69]],"ltp":1.84,"tv":4302.53,"id":7797764},{"batl":[[0,2.26,2],[1,2.36,30.25],[2,2.38,5.04]],"ltp":2.2,"tv":4300.1,"id":2284304}]}]}
{"op":"mcm","clk":"1002860868","pt":1580646925357,"mc":[{"id":"1.168224571","rc":[{"batb":[[0,1.8,494.03],[1,1.78,510.84],[2,1.74,89.62]],"batl":[[0,1.91,480.59],[1,1.93,497.4],[2,1.96,18.62]],"ltp":1.84,"tv":4302.53,"id":7797764},{"batb":[[0,2.04,5.87],[1,2,134.47],[2,1.92,394.91]],"batl":[[0,2.38,5.04],[1,2.46,4.75],[2,2.64,3.18]],"ltp":2.2,"tv":4300.1,"id":2284304}]}]}
{"op":"mcm","clk":"1002861289","pt":1580646927483,"mc":[{"id":"1.168224571","rc":[{"batb":[[2,1.77,217.73]],"ltp":1.84,"tv":4302.53,"id":7797764},{"batl":[[0,2.16,100],[1,2.38,5.04],[2,2.46,4.75]],"ltp":2.2,"tv":4300.1,"id":2284304}]}]}
{"op":"mcm","clk":"1002861353","pt":1580646927802,"mc":[{"id":"1.168224571","rc":[{"batb":[[2,1.74,89.62]],"ltp":1.84,"tv":4302.53,"id":7797764}]}]}
{"op":"mcm","clk":"1002861501","pt":1580646928602,"mc":[{"id":"1.168224571","rc":[{"batb":[[2,1.73,154.61]],"ltp":2.2,"tv":4300.1,"id":2284304}]}]}
{"op":"mcm","clk":"1002861815","pt":1580646930183,"mc":[{"id":"1.168224571","rc":[{"batb":[[0,1.86,195.74],[1,1.84,248.21],[2,1.8,494.03]],"batl":[[1,1.93,752.17],[2,1.95,210.59]],"ltp":1.84,"tv":4302.53,"id":7797764},{"batl":[[0,2.38,5.04],[1,2.46,4.75],[2,2.64,3.18]],"ltp":2.2,"tv":4300.1,"id":2284304}]}]}
{"op":"mcm","clk":"1002862259","pt":1580646932488,"mc":[{"id":"1.168224571","rc":[{"batb":[[0,1.8,494.03],[1,1.78,510.84],[2,1.74,89.62]],"batl":[[1,1.93,497.4],[2,1.96,18.62]],"ltp":1.84,"tv":4302.53,"id":7797764},{"batb":[[2,1.77,402.28]],"ltp":2.2,"tv":4300.1,"id":2284304}]}]}
{"op":"mcm","clk":"1002862840","pt":1580646935380,"mc":[{"id":"1.168224571","rc":[{"batb":[[2,1.77,217.73]],"ltp":1.84,"tv":4302.53,"id":7797764}]}]}
{"op":"mcm","clk":"1002863600","pt":1580646939414,"mc":[{"id":"1.168224571","rc":[{"batb":[[0,1.77,217.73],[1,1.75,292.95],[2,1.74,89.62]],"ltp":1.84,"tv":4302.53,"id":7797764},{"batl":[[0,2.14,16.8],[1,2.38,5.04],[2,2.46,4.75]],"ltp":2.2,"tv":4300.1,"id":2284304}]}]}
{"op":"mcm","clk":"1002863867","pt":1580646940737,"mc":[{"id":"1.168224571","rc":[{"batb":[[2,1.73,154.61]],"batl":[[0,2.38,5.04],[1,2.46,4.75],[2,2.64,3.18]],"ltp":2.2,"tv":4300.1,"id":2284304}]}]}
{"op":"mcm","clk":"1002864164","pt":1580646942348,"mc":[{"id":"1.168224571","rc":[{"batl":[[0,1.8,23.53],[1,1.82,513],[2,1.83,223.71]],"ltp":1.84,"tv":4302.53,"id":7797764},{"batb":[[0,2.2,92.14],[1,2.14,100.57],[2,2.04,5.87]],"batl":[[1,2.4,424],[2,2.46,33.32]],"ltp":2.2,"tv":4300.1,"id":2284304}]}]}
{"op":"mcm","clk":"1002864385","pt":1580646943464,"mc":[{"id":"1.168224571","rc":[{"batl":[[0,1.82,513],[1,1.83,223.71],[2,1.85,247.93]],"ltp":1.84,"tv":4302.53,"id":7797764},{"batb":[[0,2.22,85.29],[1,2.2,92.14],[2,2.14,109.77]],"ltp":2.2,"tv":4300.1,"id":2284304}]}]}
{"op":"mcm","clk":"1002864549","pt":1580646944207,"mc":[{"id":"1.168224571","rc":[{"batl":[[0,1.82,555.01]],"ltp":1.84,"tv":4302.53,"id":7797764},{"batb":[[0,2.22,118.9],[2,2.14,120.6]],"ltp":2.2,"tv":4300.1,"id":2284304}]}]}
{"op":"mcm","clk":"1002864962","pt":1580646946341,"mc":[{"id":"1.168224571","rc":[{"batb":[[0,2.28,16.87],[1,2.22,118.9],[2,2.2,92.14]],"ltp":2.2,"tv":4300.1,"id":2284304}]}]}
{"op":"mcm","clk":"1002865329","pt":1580646948357,"mc":[{"id":"1.168224571","rc":[{"batb":[[2,1.74,583.65]],"ltp":1.84,"tv":4302.53,"id":7797764},{"trd":[[2.28,13.8]],"batb":[[0,2.28,10.4]],"ltp":2.28,"tv":4313.04,"id":2284304}],"tv":8615.58}]}
{"op":"mcm","clk":"1002865541","pt":1580646949470,"mc":[{"id":"1.168224571","rc":[{"trd":[[2.22,12.8],[2.28,34.6]],"batb":[[0,2.22,112.5],[1,2.2,92.14],[2,2.14,84.61]],"ltp":2.22,"tv":4346.65,"id":2284304}],"tv":8649.19}]}
{"op":"mcm","clk":"1002866407","pt":1580646953828,"mc":[{"id":"1.168224571","rc":[{"batb":[[0,1.77,222.73]],"ltp":1.84,"tv":4302.53,"id":7797764},{"batl":[[0,2.28,100],[1,2.38,5.04],[2,2.4,424]],"ltp":2.22,"tv":4346.65,"id":2284304}]}]}
{"op":"mcm","clk":"1002866941","pt":1580646956247,"mc":[{"id":"1.168224571","rc":[{"batl":[[0,1.82,42.01]],"ltp":1.84,"tv":4302.53,"id":7797764},{"batl":[[2,2.46,33.32]],"ltp":2.22,"tv":4346.65,"id":2284304}]}]}
{"op":"mcm","clk":"1002867170","pt":1580646957361,"mc":[{"id":"1.168224571","rc":[{"batb":[[0,1.77,5],[1,1.74,494.03],[2,1.72,510.84]],"batl":[[0,1.89,480.59],[1,1.91,497.4],[2,1.97,20.5]],"ltp":1.84,"tv":4302.53,"id":7797764},{"batb":[[0,2.04,108.11],[1,2,19.28],[2,1.97,18.17]],"batl":[[1,2.48,4.24],[2,2.54,4.25]],"ltp":2.22,"tv":4346.65,"id":2284304}]}]}
{"op":"mcm","clk":"1002867448","pt":1580646958861,"mc":[{"id":"1.168224571","rc":[{"batl":[[0,2.48,4.24],[1,2.54,4.25],[2,2.58,3.94]],"ltp":2.22,"tv":4346.65,"id":2284304}]}]}
{"op":"mcm","clk":"1002867785","pt":1580646960703,"mc":[{"id":"1.168224571","rc":[{"batb":[[0,1.82,4],[1,1.77,5],[2,1.74,494.03]],"ltp":1.84,"tv":4302.53,"id":7797764}]}]}
{"op":"mcm","clk":"1002868105","pt":1580646962332,"mc":[{"id":"1.168224571","rc":[{"batb":[[1,1.8,223.95],[2,1.78,276.74]],"batl":[[0,1.86,182.27],[1,1.88,235.79],[2,1.89,480.59]],"ltp":1.84,"tv":4302.53,"id":7797764}]}]}
{"op":"mcm","clk":"1002868765","pt":1580646965670,"mc":[{"id":"1.168224571","rc":[{"batb":[[1,1.77,5],[2,1.74,494.03]],"batl":[[0,1.89,480.59],[1,1.91,497.4],[2,1.97,20.5]],"ltp":1.84,"tv":4302.53,"id":7797764}]}]}
{"op":"mcm","clk":"1002869700","pt":1580646970489,"mc":[{"id":"1.168224571","rc":[{"batb":[[1,2.02,6.24],[2,2,19.28]],"ltp":2.22,"tv":4346.65,"id":2284304}]}]}
{"op":"mcm","clk":"1002869793","pt":1580646970986,"mc":[{"id":"1.168224571","rc":[{"trd":[[1.89,280.42]],"batl":[[0,1.89,200.17]],"ltp":1.89,"tv":4582.96,"id":7797764},{"trd":[[2.12,250]],"batb":[[1,2,19.28],[2,1.97,18.17]],"ltp":2.12,"tv":4596.65,"id":2284304}],"tv":9179.61}]}
{"op":"mcm","clk":"1002870050","pt":1580646972387,"mc":[{"id":"1.168224571","rc":[{"batl":[[0,2.02,318.71],[1,2.04,190.73],[2,1000,0.02]],"ltp":1.89,"tv":4582.96,"id":7797764},{"batb":[[1,1.97,18.17],[2,1.86,398.62]],"batl":[[1,2.58,3.94],[2,3,255.46]],"ltp":2.12,"tv":4596.65,"id":2284304}]}]}
{"op":"mcm","clk":"1002870631","pt":1580646975490,"mc":[{"id":"1.168224571","rc":[{"batb":[[0,1.93,253.07],[1,1.91,220.37],[2,1.87,123.13]],"batl":[[0,2.02,809.71]],"ltp":1.89,"tv":4582.96,"id":7797764},{"batl":[[0,2.12,581.89],[1,2.48,4.24],[2,2.58,3.94]],"ltp":2.12,"tv":4596.65,"id":2284304}]}]}
{"op":"mcm","clk":"1002870845","pt":1580646976414,"mc":[{"id":"1.168224571","rc":[{"batb":[[1,1.91,265.74]],"batl":[[2,2.08,38.65]],"ltp":1.89,"tv":4582.96,"id":7797764},{"batb":[[2,1.95,63.1]],"batl":[[0,2.1,37.81],[1,2.12,581.89],[2,2.48,4.24]],"ltp":2.12,"tv":4596.65,"id":2284304}]}]}
{"op":"mcm","clk":"1002872407","pt":1580646984287,"mc":[{"id":"1.168224571","rc":[{"batb":[[0,1.97,269.04],[1,1.93,253.07],[2,1.91,265.74]],"ltp":1.89,"tv":4582.96,"id":7797764},{"batb":[[0,2.02,110.63],[2,1.93,108.89]],"ltp":2.12,"tv":4596.65,"id":2284304}]}]}
{"op":"mcm","clk":"1002872675","pt":1580646985689,"mc":[{"id":"1.168224571","rc":[{"trd":[[1.97,87.78]],"batb":[[0,1.97,181.26]],"ltp":1.97,"tv":4670.73,"id":7797764},{"trd":[[2.04,85.22]],"ltp":2.04,"tv":4681.42,"id":2284304}],"tv":9352.15}]}
{"op":"mcm","clk":"1002873253","pt":1580646988397,"mc":[{"id":"1.168224571","rc":[{"trd":[[1.97,164.1]],"batb":[[0,1.97,143.1]],"ltp":1.97,"tv":4747.05,"id":7797764}],"tv":9428.47}]}
{"op":"mcm","clk":"1002873914","pt":1580646991941,"mc":[{"id":"1.168224571","rc":[{"batb":[[0,2,113.14],[2,1.93,44.53]],"ltp":2.04,"tv":4681.42,"id":2284304}]}]}
{"op":"mcm","clk":"1002875249","pt":1580646998854,"mc":[{"id":"1.168224571","rc":[{"trd":[[1.97,199.04]],"batb":[[0,1.97,108.16]],"ltp":1.97,"tv":4782.0,"id":7797764},{"trd":[[2.04,118.96]],"ltp":2.04,"tv":4715.16,"id":2284304}],"tv":9497.16}]}
{"op":"mcm","clk":"1002877185","pt":1580647008861,"mc":[{"id":"1.168224571","rc":[{"trd":[[1.97,204.08]],"batb":[[0,1.97,105.64]],"ltp":1.97,"tv":4787.04,"id":7797764}],"tv":9502.2}]}
{"op":"mcm","clk":"1002877531","pt":1580647010459,"mc":[{"id":"1.168224571","rc":[{"trd":[[1.97,221.55]],"batb":[[0,1.97,88.17]],"ltp":1.97,"tv":4804.5,"id":7797764},{"trd":[[2.04,135.84]],"ltp":2.04,"tv":4732.03,"id":2284304}],"tv":9536.54}]}
{"op":"mcm","clk":"1002880136","pt":1580647023762,"mc":[{"id":"1.168224571","rc":[{"trd":[[2,81.8]],"ltp":2.0,"tv":4806.04,"id":7797764},{"trd":[[2,4.62]],"batb":[[0,2,110.06]],"ltp":2.0,"tv":4736.65,"id":2284304}],"tv":9542.7}]}
{"op":"mcm","clk":"1002881238","pt":1580647029095,"mc":[{"id":"1.168224571","rc":[{"trd":[[2,204.63]],"batb":[[0,2,10.06]],"ltp":2.0,"tv":4936.66,"id":2284304}],"tv":9742.71}]}
{"op":"mcm","clk":"1002882573","pt":1580647035404,"mc":[{"id":"1.168224571","rc":[{"batb":[[1,1.94,66.8],[2,1.93,253.07]],"ltp":2.0,"tv":4806.04,"id":7797764},{"batb":[[0,1.99,116.13]],"ltp":2.0,"tv":4936.66,"id":2284304}]}]}
{"op":"mcm","clk":"1002883100","pt":1580647037897,"mc":[{"id":"1.168224571","rc":[{"batb":[[0,1.94,66.8],[1,1.93,253.07],[2,1.91,265.74]],"ltp":2.0,"tv":4806.04,"id":7797764}]}]}
{"op":"mcm","clk":"1002883836","pt":1580647041334,"mc":[{"id":"1.168224571","rc":[{"trd":[[2.02,262.68]],"batb":[[1,1.91,45.37],[2,1.87,123.13]],"batl":[[0,2.02,723.72]],"ltp":2.02,"tv":4978.02,"id":7797764}],"tv":9914.69}]}
{"op":"mcm","clk":"1002884495","pt":1580647044325,"mc":[{"id":"1.168224571","rc":[{"batb":[[0,1.94,248.88],[1,1.92,216.8],[2,1.91,45.37]],"batl":[[0,2.02,773.25]],"ltp":2.02,"tv":4978.02,"id":7797764}]}]}
{"op":"mcm","clk":"1002885328","pt":1580647048481,"mc":[{"id":"1.168224571","rc":[{"batb":[[0,1.94,253.88]],"ltp":2.02,"tv":4978.02,"id":7797764}]}]}
{"op":"mcm","clk":"1002885557","pt":1580647049550,"mc":[{"id":"1.168224571","rc":[{"batb":[[0,1.94,248.88]],"ltp":2.02,"tv":4978.02,"id":7797764}]}]}
{"op":"mcm","clk":"1002887138","pt":1580647056950,"mc":[{"id":"1.168224571","rc":[{"batb":[[0,1.94,251.88]],"ltp":2.02,"tv":4978.02,"id":7797764}]}]}
{"op":"mcm","clk":"1002888068","pt":1580647061448,"mc":[{"id":"1.168224571","rc":[{"batb":[[0,1.94,69.8],[1,1.82,81.04],[2,1.68,29.86]],"batl":[[0,1000,0.02],[1,2.04,0],[2,2.08,0]],"ltp":2.02,"tv":4978.02,"id":7797764},{"batb":[[1,1.89,67.51],[2,1.86,398.62]],"batl":[[0,2.48,4.24],[1,3,255.46],[2,4,2.27]],"ltp":2.0,"tv":4936.66,"id":2284304}]}]}
{"op":"mcm","clk":"1002888086","pt":1580647061553,"mc":[{"id":"1.168224571","rc":[{"batb":[[0,1.94,3]],"ltp":2.02,"tv":4978.02,"id":7797764},{"batb":[[0,1.89,67.51],[1,1.86,398.62],[2,1.73,154.61]],"ltp":2.0,"tv":4936.66,"id":2284304}]}]}
{"op":"mcm","clk":"1002888688","pt":1580647064381,"mc":[{"id":"1.168224571","rc":[{"batb":[[2,1.78,20.66]],"batl":[[0,2.06,5.25],[1,2.1,5.95],[2,1000,0.02]],"ltp":2.02,"tv":4978.02,"id":7797764},{"batb":[[0,1.95,19.31],[1,1.91,20.39],[2,1.89,67.51]],"batl":[[0,2.3,4.25],[1,2.42,3.87],[2,2.48,4.24]],"ltp":2.0,"tv":4936.66,"id":2284304}]}]}
{"op":"mcm","clk":"1002888878","pt":1580647065138,"mc":[{"id":"1.168224571","rc":[{"batb":[[2,1.79,24.31]],"batl":[[0,2.1,5.95],[1,1000,0.02],[2,1000,0]],"ltp":2.02,"tv":4978.02,"id":7797764},{"batb":[[0,1.91,20.39],[1,1.89,67.51],[2,1.86,398.62]],"batl":[[0,2.28,4.84],[2,3,255.46]],"ltp":2.0,"tv":4936.66,"id":2284304}]}]}
{"op":"mcm","clk":"1002889129","pt":1580647066353,"mc":[{"id":"1.168224571","rc":[{"batb":[[1,1.91,236.37],[2,1.89,227.76]],"batl":[[0,1.98,164.42],[1,2,195.11],[2,2.1,5.95]],"ltp":2.02,"tv":4978.02,"id":7797764},{"batl":[[0,2.42,3.87],[1,3,255.46],[2,4,2.27]],"ltp":2.0,"tv":4936.66,"id":2284304}]}]}
{"op":"mcm","clk":"1002889536","pt":1580647068146,"mc":[{"id":"1.168224571","rc":[{"batl":[[2,2.06,5.75]],"ltp":2.02,"tv":4978.02,"id":7797764},{"batb":[[0,1.95,17.31],[1,1.91,20.39],[2,1.89,67.51]],"ltp":2.0,"tv":4936.66,"id":2284304}]}]}
{"op":"mcm","clk":"1002890174","pt":1580647071369,"mc":[{"id":"1.168224571","rc":[{"batb":[[1,1.82,81.04],[2,1.78,25.16]],"batl":[[0,2.06,5.75],[1,2.1,5.95],[2,1000,0.02]],"ltp":2.02,"tv":4978.02,"id":7797764},{"batl":[[0,2.3,4.55],[1,2.42,3.87],[2,3,255.46]],"ltp":2.0,"tv":4936.66,"id":2284304}]}]}
{"op":"mcm","clk":"1002890259","pt":1580647071763,"mc":[{"id":"1.168224571","rc":[{"batb":[[2,1.71,25.19]],"batl":[[0,2.1,5.95],[1,1000,0.02],[2,1000,0]],"ltp":2.02,"tv":4978.02,"id":7797764},{"batb":[[0,1.91,20.39],[1,1.89,67.51],[2,1.86,398.62]],"batl":[[0,2.42,3.87],[1,3,255.46],[2,4,2.27]],"ltp":2.0,"tv":4936.66,"id":2284304}]}]}
{"op":"mcm","clk":"1002891037","pt":1580647075475,"mc":[{"id":"1.168224571","rc":[{"batb":[[1,1.82,269.97],[2,1.8,266.22]],"batl":[[0,2.1,186.16],[1,2.12,164.69],[2,1000,0.02]],"ltp":2.02,"tv":4978.02,"id":7797764}]}]}
{"op":"mcm","clk":"1002891633","pt":1580647078472,"mc":[{"id":"1.168224571","rc":[{"batl":[[0,2.06,4.92],[1,2.1,186.16],[2,2.12,164.69]],"ltp":2.02,"tv":4978.02,"id":7797764},{"batb":[[0,1.95,19.91],[1,1.91,20.39],[2,1.89,67.51]],"ltp":2.0,"tv":4936.66,"id":2284304}]}]}
{"op":"mcm","clk":"1002891854","pt":1580647079461,"mc":[{"id":"1.168224571","rc":[{"batb":[[1,1.82,81.04],[2,1.71,25.19]],"batl":[[0,2.1,5.95],[1,1000,0.02],[2,2.12,0]],"ltp":2.02,"tv":4978.02,"id":7797764},{"batb":[[0,1.91,20.39],[1,1.89,67.51],[2,1.86,398.62]],"ltp":2.0,"tv":4936.66,"id":2284304}]}]}
{"op":"mcm","clk":"1002892224","pt":1580647081185,"mc":[{"id":"1.168224571","rc":[{"batb":[[0,1.82,81.04],[1,1.71,25.19],[2,1.4,75.72]],"ltp":2.02,"tv":4978.02,"id":7797764},{"batb":[[2,1.73,154.61]],"batl":[[1,3,42.01]],"ltp":2.0,"tv":4936.66,"id":2284304}]}]}
{"op":"mcm","clk":"1002892499","pt":1580647082478,"mc":[{"id":"1.168224571","rc":[{"batb":[[0,1.98,104.6],[1,1.94,3.42],[2,1.82,81.04]],"batl":[[1,2.12,512],[2,1000,0.02]],"ltp":2.02,"tv":4978.02,"id":7797764},{"batb":[[0,1.91,208.4],[1,1.89,295.36]],"batl":[[0,1.97,106.27],[1,1.98,211.38],[2,2,195.21]],"ltp":2.0,"tv":4936.66,"id":2284304}]}]}
{"op":"mcm","clk":"1002892678","pt":1580647083408,"mc":[{"id":"1.168224571","rc":[{"batb":[[0,2.02,115.03],[1,1.98,104.6],[2,1.94,3.42]],"ltp":2.02,"tv":4978.02,"id":7797764},{"batb":[[2,1.81,77.58]],"ltp":2.0,"tv":4936.66,"id":2284304}]}]}
{"op":"mcm","clk":"1002892879","pt":1580647084374,"mc":[{"id":"1.168224571","rc":[{"batb":[[1,1.99,42.01],[2,1.98,104.6]],"batl":[[2,2.16,36.13]],"ltp":2.02,"tv":4978.02,"id":7797764},{"batb":[[2,1.87,47.89]],"ltp":2.0,"tv":4936.66,"id":2284304}]}]}
{"op":"mcm","clk":"1002894637","pt":1580647092814,"mc":[{"id":"1.168224571","rc":[{"trd":[[1.91,22.54]],"batb":[[0,1.91,204.74]],"ltp":1.91,"tv":4943.98,"id":2284304}],"tv":9922.0}]}
{"op":"mcm","clk":"1002894964","pt":1580647094433,"mc":[{"id":"1.168224571","rc":[{"trd":[[1.97,85.13]],"batl":[[0,1.97,72.53]],"ltp":1.97,"tv":5011.46,"id":2284304}],"tv":9989.49}]}
{"op":"mcm","clk":"1002895307","pt":1580647096017,"mc":[{"id":"1.168224571","rc":[{"batl":[[1,2.12,517.21],[2,2.14,5.25]],"ltp":2.02,"tv":4978.02,"id":7797764},{"trd":[[1.91,90.08]],"batb":[[0,1.91,170.97],[1,1.9,19.36],[2,1.89,295.36]],"ltp":1.91,"tv":5079.01,"id":2284304}],"tv":10057.03}]}
{"op":"mcm","clk":"1002895784","pt":1580647098443,"mc":[{"id":"1.168224571","rc":[{"batb":[[2,1.94,3.42]],"batl":[[1,2.12,5.21]],"ltp":2.02,"tv":4978.02,"id":7797764},{"batb":[[0,1.9,19.36],[1,1.89,67.51],[2,1.88,21.96]],"batl":[[0,2.02,41.17],[1,2.08,2],[2,2.14,4.75]],"ltp":1.91,"tv":5079.01,"id":2284304}]}]}
{"op":"mcm","clk":"1002895990","pt":1580647099424,"mc":[{"id":"1.168224571","rc":[{"batb":[[0,1.93,68.06],[1,1.88,20.96],[2,1.84,20.72]],"batl":[[0,2.14,5.25],[1,1000,0.02],[2,2.14,0]],"ltp":2.02,"tv":4978.02,"id":7797764},{"batb":[[0,1.88,21.96],[1,1.81,77.58],[2,1.73,154.61]],"batl":[[0,2.14,4.75],[1,2.2,5.53],[2,2.28,3.84]],"ltp":1.91,"tv":5079.01,"id":2284304}]}]}
{"op":"mcm","clk":"1002896056","pt":1580647099742,"mc":[{"id":"1.168224571","rc":[{"batb":[[1,1.84,20.72],[2,1.82,81.04]],"ltp":2.02,"tv":4978.02,"id":7797764},{"batl":[[0,2.2,5.53],[1,2.28,3.84],[2,2.42,3.87]],"ltp":1.91,"tv":5079.01,"id":2284304}]}]}
{"op":"mcm","clk":"1002896413","pt":1580647101357,"mc":[{"id":"1.168224571","rc":[{"batb":[[1,1.85,160.72],[2,1.83,252.61]],"batl":[[0,2.1,213.36],[1,2.12,164.62],[2,2.2,5.53]],"ltp":1.91,"tv":5079.01,"id":2284304}]}]}
{"op":"mcm","clk":"1002896591","pt":1580647102223,"mc":[{"id":"1.168224571","rc":[{"batb":[[0,1.92,68.69],[2,1.79,23.31]],"ltp":2.02,"tv":4978.02,"id":7797764},{"batl":[[0,1.91,1.35],[1,2.2,5.53],[2,2.28,3.84]],"ltp":1.91,"tv":5079.01,"id":2284304}]}]}
{"op":"mcm","clk":"1002897208","pt":1580647105157,"mc":[{"id":"1.168224571","rc":[{"batb":[[0,2.12,93.95],[1,2.06,103.62],[2,2,4.87]],"batl":[[1,2.2,421],[2,1000,0.02]],"ltp":2.02,"tv":4978.02,"id":7797764},{"batl":[[0,1.91,193.29],[1,1.93,217.42],[2,1.95,447]],"ltp":1.91,"tv":5079.01,"id":2284304}]}]}
{"op":"mcm","clk":"1002897511","pt":1580647106454,"mc":[{"id":"1.168224571","rc":[{"batb":[[0,2.12,193.95],[2,2.04,40.33]],"batl":[[2,2.24,33.61]],"ltp":2.02,"tv":4978.02,"id":7797764}]}]}
{"op":"mcm","clk":"1002898162","pt":1580647109548,"mc":[{"id":"1.168224571","rc":[{"trd":[[2.12,62.18]],"batb":[[0,2.12,165.38]],"ltp":2.12,"tv":5035.16,"id":7797764}],"tv":10114.17}]}
{"op":"mcm","clk":"1002898836","pt":1580647112784,"mc":[{"id":"1.168224571","rc":[{"batl":[[1,2.18,4.75],[2,2.2,421]],"ltp":2.12,"tv":5035.16,"id":7797764},{"batb":[[1,1.86,19.68],[2,1.85,179.49]],"ltp":1.91,"tv":5079.01,"id":2284304}]}]}
{"op":"mcm","clk":"1002899139","pt":1580647114304,"mc":[{"id":"1.168224571","rc":[{"batb":[[2,1.85,266.91]],"ltp":1.91,"tv":5079.01,"id":2284304}]}]}
{"op":"mcm","clk":"1002899933","pt":1580647118223,"mc":[{"id":"1.168224571","rc":[{"batb":[[0,2.04,40.33],[1,2,117.47],[2,1.97,18.17]],"batl":[[0,2.18,4.75],[1,2.24,33.61],[2,2.66,1.16]],"ltp":2.12,"tv":5035.16,"id":7797764},{"batb":[[0,1.85,106.19],[1,1.82,50.41],[2,1.76,85.31]],"batl":[[0,1.91,1.35],[1,1.98,42.01],[2,2.04,6.13]],"ltp":1.91,"tv":5079.01,"id":2284304}]}]}
{"op":"mcm","clk":"1002900171","pt":1580647119411,"mc":[{"id":"1.168224571","rc":[{"batb":[[0,2,117.47],[1,1.97,18.17],[2,1.91,18.39]],"batl":[[1,2.66,1.16],[2,1000,0.02]],"ltp":2.12,"tv":5035.16,"id":7797764},{"batb":[[1,1.76,85.31],[2,1.73,154.6]],"batl":[[0,2.04,6.13],[1,2.1,5.65],[2,2.2,5.53]],"ltp":1.91,"tv":5079.01,"id":2284304}]}]}
{"op":"mcm","clk":"1002900571","pt":1580647121402,"mc":[{"id":"1.168224571","rc":[{"batb":[[1,1.8,269.95],[2,1.78,276.86]],"batl":[[0,1.99,185.81],[1,2.02,285.73],[2,2.04,6.13]],"ltp":1.91,"tv":5079.01,"id":2284304}]}]}
{"op":"mcm","clk":"1002900766","pt":1580647122459,"mc":[{"id":"1.168224571","rc":[{"batl":[[0,1.88,1.35],[1,2.04,6.13],[2,2.1,5.65]],"ltp":1.91,"tv":5079.01,"id":2284304}]}]}
{"op":"mcm","clk":"1002901197","pt":1580647124425,"mc":[{"id":"1.168224571","rc":[{"batb":[[0,2.1,100.83],[1,2.04,4.87],[2,2,117.47]],"batl":[[1,2.28,477],[2,2.66,1.16]],"ltp":2.12,"tv":5035.16,"id":7797764},{"batl":[[0,1.87,106.01],[1,1.88,4.38],[2,1.9,504]],"ltp":1.91,"tv":5079.01,"id":2284304}]}]}
{"op":"mcm","clk":"1002901396","pt":1580647125321,"mc":[{"id":"1.168224571","rc":[{"trd":[[2.18,284.92]],"batb":[[0,2.12,100.48],[1,2.1,100.83],[2,2.04,4.87]],"batl":[[0,2.28,477],[1,2.66,1.16],[2,1000,0.02]],"ltp":2.18,"tv":5129.84,"id":7797764},{"trd":[[1.85,115.55]],"batb":[[0,1.85,5.81]],"batl":[[0,1.87,363.77],[2,1.89,231.81]],"ltp":1.85,"tv":5179.38,"id":2284304}],"tv":10309.23}]}
{"op":"mcm","clk":"1002901620","pt":1580647126435,"mc":[{"id":"1.168224571","rc":[{"batb":[[1,2.1,138.64]],"batl":[[0,2.28,509.77]],"ltp":2.18,"tv":5129.84,"id":7797764},{"batb":[[2,1.79,52.93]],"ltp":1.85,"tv":5179.38,"id":2284304}]}]}
{"op":"mcm","clk":"1002901927","pt":1580647128047,"mc":[{"id":"1.168224571","rc":[{"trd":[[1.85,127.17]],"batb":[[0,1.8,269.95],[1,1.79,52.93],[2,1.78,276.86]],"ltp":1.85,"tv":5191.01,"id":2284304}],"tv":10320.85}]}
{"op":"mcm","clk":"1002902376","pt":1580647130161,"mc":[{"id":"1.168224571","rc":[{"batl":[[0,1.85,11.36],[1,1.87,363.77],[2,1.88,4.38]],"ltp":1.85,"tv":5191.01,"id":2284304}]}]}
{"op":"mcm","clk":"1002902584","pt":1580647131160,"mc":[{"id":"1.168224571","rc":[{"batl":[[0,2.2,4.78],[1,2.28,509.77],[2,2.66,1.16]],"ltp":2.18,"tv":5129.84,"id":7797764},{"batb":[[0,1.84,23.22],[1,1.8,269.95],[2,1.79,52.93]],"ltp":1.85,"tv":5191.01,"id":2284304}]}]}
{"op":"mcm","clk":"1002903187","pt":1580647134452,"mc":[{"id":"1.168224571","rc":[{"batl":[[0,1.85,11.61]],"ltp":1.85,"tv":5191.01,"id":2284304}]}]}
{"op":"mcm","clk":"1002903594","pt":1580647136485,"mc":[{"id":"1.168224571","rc":[{"batl":[[0,2.28,32.77],[1,2.66,1.16],[2,1000,0.02]],"ltp":2.18,"tv":5129.84,"id":7797764},{"trd":[[1.85,150.38],[1.87,11.57]],"batb":[[0,1.79,52.95],[1,1.78,187.84],[2,1.76,85.29]],"batl":[[0,1.87,100.74],[1,1.88,4.38],[2,1.92,42.01]],"ltp":1.87,"tv":5224.75,"id":2284304}],"tv":10354.6}]}
{"op":"mcm","clk":"1002903797","pt":1580647137464,"mc":[{"id":"1.168224571","rc":[{"batb":[[1,2.04,4.87],[2,2,26.5]],"batl":[[0,2.66,1.16],[1,1000,0.02],[2,1000,0]],"ltp":2.18,"tv":5129.84,"id":7797764},{"trd":[[1.8,267.38]],"batb":[[0,1.78,187.84],[1,1.73,154.6],[2,1.72,92.61]],"batl":[[0,1.8,84.32],[2,1.96,14.87]],"ltp":1.8,"tv":5224.78,"id":2284304}],"tv":10354.63}]}
{"op":"mcm","clk":"1002903866","pt":1580647137733,"mc":[{"id":"1.168224571","rc":[{"trd":[[2.24,38.32]],"batb":[[1,2,26.5],[2,1.97,18.17]],"ltp":2.24,"tv":5134.59,"id":7797764},{"trd":[[1.8,364.63]],"batl":[[0,1.8,32.73],[2,2,26.5]],"ltp":1.8,"tv":5322.04,"id":2284304}],"tv":10456.64}]}
{"op":"mcm","clk":"1002904187","pt":1580647139377,"mc":[{"id":"1.168224571","rc":[{"batb":[[1,1.76,286.94],[2,1.73,154.6]],"batl":[[2,1.91,159.49]],"ltp":1.8,"tv":5322.04,"id":2284304}]}]}
{"op":"mcm","clk":"1002904360","pt":1580647140308,"mc":[{"id":"1.168224571","rc":[{"batb":[[0,2.06,102.99]],"ltp":2.24,"tv":5134.59,"id":7797764},{"batb":[[2,1.74,90.41]],"batl":[[2,2,26.5]],"ltp":1.8,"tv":5322.04,"id":2284304}]}]}
{"op":"mcm","clk":"1002904474","pt":1580647140774,"mc":[{"id":"1.168224571","rc":[{"batb":[[1,2.04,8.87],[2,2,26.5]],"ltp":2.24,"tv":5134.59,"id":7797764},{"trd":[[1.8,430.09]],"batl":[[0,1.88,4.38],[1,1.96,27.37]],"ltp":1.8,"tv":5387.5,"id":2284304}],"tv":10522.09}]}
{"op":"mcm","clk":"1002905025","pt":1580647143465,"mc":[{"id":"1.168224571","rc":[{"batb":[[0,2.12,89.04],[1,2.06,120.57],[2,2.04,8.87]],"batl":[[0,2.32,372],[1,2.66,1.16],[2,1000,0.02]],"ltp":2.24,"tv":5134.59,"id":7797764},{"batl":[[0,1.84,240.67],[1,1.86,802.33],[2,1.88,4.38]],"ltp":1.8,"tv":5387.5,"id":2284304}]}]}
{"op":"mcm","clk":"1002905198","pt":1580647144393,"mc":[{"id":"1.168224571","rc":[{"batb":[[0,2.22,84.43],[1,2.12,89.04],[2,2.08,100.79]],"ltp":2.24,"tv":5134.59,"id":7797764}]}]}
{"op":"mcm","clk":"1002905329","pt":1580647144933,"mc":[{"id":"1.168224571","rc":[{"batb":[[1,2.16,36.13],[2,2.12,89.04]],"batl":[[1,2.36,30.25],[2,2.66,1.16]],"ltp":2.24,"tv":5134.59,"id":7797764},{"batb":[[2,1.75,55.45]],"batl":[[2,1.87,42.01]],"ltp":1.8,"tv":5387.5,"id":2284304}]}]}
{"op":"mcm","clk":"1002906004","pt":1580647148304,"mc":[{"id":"1.168224571","rc":[{"batb":[[1,2.12,89.04],[2,2.08,100.79]],"ltp":2.24,"tv":5134.59,"id":7797764}]}]}
{"op":"mcm","clk":"1002906627","pt":1580647151403,"mc":[{"id":"1.168224571","rc":[{"batb":[[1,2.14,36.13],[2,2.12,89.04]],"batl":[[2,2.46,4.25]],"ltp":2.24,"tv":5134.59,"id":7797764}]}]}
{"op":"mcm","clk":"1002907543","pt":1580647156035,"mc":[{"id":"1.168224571","rc":[{"trd":[[2.22,235.8]],"batb":[[0,2.22,4.42]],"ltp":2.22,"tv":5294.6,"id":7797764}],"tv":10682.1}]}
{"op":"mcm","clk":"1002908582","pt":1580647161024,"mc":[{"id":"1.168224571","rc":[{"batl":[[2,2.46,77.7]],"ltp":2.22,"tv":5294.6,"id":7797764}]}]}
{"op":"mcm","clk":"1002909383","pt":1580647165030,"mc":[{"id":"1.168224571","rc":[{"trd":[[2.22,241.86]],"batb":[[0,2.22,1.39]],"ltp":2.22,"tv":5300.65,"id":7797764}],"tv":10688.16}]}
{"op":"mcm","clk":"1002909634","pt":1580647166250,"mc":[{"id":"1.168224571","rc":[{"trd":[[2.22,243.25]],"batb":[[0,2.14,36.13],[1,2.12,89.04],[2,2.08,100.79]],"ltp":2.22,"tv":5302.05,"id":7797764},{"trd":[[1.82,94.45]],"batb":[[0,1.78,188.18]],"ltp":1.82,"tv":5389.2,"id":2284304}],"tv":10691.25}]}
{"op":"mcm","clk":"1002909882","pt":1580647167440,"mc":[{"id":"1.168224571","rc":[{"batl":[[0,2.36,30.25],[1,2.46,77.7],[2,2.54,3.88]],"ltp":2.22,"tv":5302.05,"id":7797764},{"batl":[[1,1.86,358.33]],"ltp":1.82,"tv":5389.2,"id":2284304}]}]}
{"op":"mcm","clk":"1002909950","pt":1580647167752,"mc":[{"id":"1.168224571","rc":[{"batb":[[1,2.08,100.79],[2,2,26.5]],"ltp":2.22,"tv":5302.05,"id":7797764},{"batb":[[0,1.75,55.8],[1,1.73,154.6],[2,1.69,24.21]],"batl":[[0,1.87,42.01],[1,1.88,1.35],[2,1.97,52.5]],"ltp":1.82,"tv":5389.2,"id":2284304}]}]}
{"op":"mcm","clk":"1002910309","pt":1580647169454,"mc":[{"id":"1.168224571","rc":[{"batb":[[0,2.08,100.79],[1,2,26.5],[2,1.97,18.17]],"batl":[[0,2.46,77.7],[1,2.54,3.88],[2,2.66,1.16]],"ltp":2.22,"tv":5302.05,"id":7797764},{"batb":[[0,1.73,154.94],[1,1.69,24.21],[2,1.65,29.13]],"batl":[[0,1.88,1.35],[1,1.97,52.5],[2,2,26.5]],"ltp":1.82,"tv":5389.2,"id":2284304}]}]}
{"op":"mcm","clk":"1002910499","pt":1580647170432,"mc":[{"id":"1.168224571","rc":[{"batb":[[2,1.67,261.44]],"batl":[[1,1.92,239.91],[2,1.94,214.18]],"ltp":1.82,"tv":5389.2,"id":2284304}]}]}
{"op":"mcm","clk":"1002910716","pt":1580647171458,"mc":[{"id":"1.168224571","rc":[{"batb":[[1,2.06,103.23],[2,2,26.5]],"ltp":2.22,"tv":5302.05,"id":7797764},{"batb":[[2,1.67,108.5]],"batl":[[1,1.97,52.5],[2,2,26.5]],"ltp":1.82,"tv":5389.2,"id":2284304}]}]}
{"op":"mcm","clk":"1002911028","pt":1580647172948,"mc":[{"id":"1.168224571","rc":[{"trd":[[1.82,95.14]],"batb":[[0,1.75,295.24],[1,1.73,459.37],[2,1.69,24.21]],"batl":[[0,1.81,175.43],[1,1.83,256.71],[2,1.88,1.35]],"ltp":1.82,"tv":5389.88,"id":2284304}],"tv":10691.93}]}
{"op":"mcm","clk":"1002911354","pt":1580647174340,"mc":[{"id":"1.168224571","rc":[{"batb":[[2,2.02,17.24]],"ltp":2.22,"tv":5302.05,"id":7797764}]}]}
{"op":"mcm","clk":"1002911411","pt":1580647174600,"mc":[{"id":"1.168224571","rc":[{"batb":[[2,2,26.5]],"ltp":2.22,"tv":5302.05,"id":7797764}]}]}
{"op":"mcm","clk":"1002911966","pt":1580647177222,"mc":[{"id":"1.168224571","rc":[{"batb":[[0,1.73,154.6],[1,1.69,24.21],[2,1.67,108.5]],"batl":[[0,1.88,1.35],[1,1.97,52.5],[2,2,26.5]],"ltp":1.82,"tv":5389.88,"id":2284304}]}]}
{"op":"mcm","clk":"1002912565","pt":1580647180146,"mc":[{"id":"1.168224571","rc":[{"batb":[[2,1.67,369.94]],"batl":[[1,1.92,239.91],[2,1.94,214.18]],"ltp":1.82,"tv":5389.88,"id":2284304}]}]}
{"op":"mcm","clk":"1002912818","pt":1580647181323,"mc":[{"id":"1.168224571","rc":[{"batb":[[2,2.02,17.24]],"ltp":2.22,"tv":5302.05,"id":7797764}]}]}
{"op":"mcm","clk":"1002912881","pt":1580647181639,"mc":[{"id":"1.168224571","rc":[{"batb":[[2,2,26.5]],"ltp":2.22,"tv":5302.05,"id":7797764}]}]}
{"op":"mcm","clk":"1002913175","pt":1580647183039,"mc":[{"id":"1.168224571","rc":[{"batb":[[2,1.67,108.5]],"ltp":1.82,"tv":5389.88,"id":2284304}]}]}
{"op":"mcm","clk":"1002913305","pt":1580647183630,"mc":[{"id":"1.168224571","rc":[{"batb":[[0,2.06,103.23],[1,2,26.5],[2,1.97,18.17]],"ltp":2.22,"tv":5302.05,"id":7797764}]}]}
{"op":"mcm","clk":"1002913691","pt":1580647185391,"mc":[{"id":"1.168224571","rc":[{"batl":[[1,1.91,63],[2,1.92,239.91]],"ltp":1.82,"tv":5389.88,"id":2284304}]}]}
{"op":"mcm","clk":"1002913947","pt":1580647186474,"mc":[{"id":"1.168224571","rc":[{"batb":[[0,2.06,142.72]],"batl":[[0,2.2,387],[1,2.22,91.85],[2,2.26,32.77]],"ltp":2.22,"tv":5302.05,"id":7797764},{"batb":[[0,1.85,224.69],[1,1.83,252.96],[2,1.81,154.61]],"ltp":1.82,"tv":5389.88,"id":2284304}]}]}
{"op":"mcm","clk":"1002914034","pt":1580647186846,"mc":[{"id":"1.168224571","rc":[{"batb":[[2,1.97,136.98]],"ltp":2.22,"tv":5302.05,"id":7797764},{"batb":[[0,1.87,74.91],[1,1.85,224.69],[2,1.83,252.96]],"ltp":1.82,"tv":5389.88,"id":2284304}]}]}
{"op":"mcm","clk":"1002915317","pt":1580647192961,"mc":[{"id":"1.168224571","rc":[{"batl":[[2,2.26,37.79]],"ltp":2.22,"tv":5302.05,"id":7797764},{"batb":[[2,1.84,494.03]],"batl":[[2,1.92,720.5]],"ltp":1.82,"tv":5389.88,"id":2284304}]}]}
{"op":"mcm","clk":"1002915569","pt":1580647194226,"mc":[{"id":"1.168224571","rc":[{"batl":[[1,1.92,720.5],[2,1.94,753.59]],"ltp":1.82,"tv":5389.88,"id":2284304}]}]}
{"op":"mcm","clk":"1002916157","pt":1580647197050,"mc":[{"id":"1.168224571","rc":[{"batl":[[0,1.92,720.5],[1,1.94,753.59],[2,1.95,486]],"ltp":1.82,"tv":5389.88,"id":2284304}]}]}
{"op":"mcm","clk":"1002916429","pt":1580647198437,"mc":[{"id":"1.168224571","rc":[{"trd":[[2.08,393.08]],"ltp":2.08,"tv":5304.05,"id":7797764},{"trd":[[1.92,242.17]],"batl":[[0,1.92,718.33]],"ltp":1.92,"tv":5392.05,"id":2284304}],"tv":10696.1}]}
{"op":"mcm","clk":"1002916830","pt":1580647200273,"mc":[{"id":"1.168224571","rc":[{"trd":[[1.87,14.27]],"batb":[[0,1.87,73.55]],"ltp":1.87,"tv":5394.75,"id":2284304}],"tv":10698.8}]}
{"op":"mcm","clk":"1002916985","pt":1580647200952,"mc":[{"id":"1.168224571","rc":[{"batl":[[1,2.22,97.1]],"ltp":2.08,"tv":5304.05,"id":7797764}]}]}
{"op":"mcm","clk":"1002917916","pt":1580647205233,"mc":[{"id":"1.168224571","rc":[{"batb":[[0,2.06,39.49]],"batl":[[0,2.22,5.25],[1,2.26,37.79],[2,2.28,4.59]],"ltp":2.08,"tv":5304.05,"id":7797764},{"batb":[[0,1.84,494.03],[1,1.82,623.48],[2,1.81,51.25]],"batl":[[0,1.92,480.59],[1,1.94,539.41],[2,2,26.5]],"ltp":1.87,"tv":5394.75,"id":2284304}]}]}
{"op":"mcm","clk":"1002917978","pt":1580647205560,"mc":[{"id":"1.168224571","rc":[{"batb":[[0,2,26.5],[1,1.97,136.98],[2,1.91,18.39]],"batl":[[1,2.26,5.02]],"ltp":2.08,"tv":5304.05,"id":7797764},{"batb":[[2,1.8,23.43]],"batl":[[1,1.94,497.4]],"ltp":1.87,"tv":5394.75,"id":2284304}]}]}
{"op":"mcm","clk":"1002918489","pt":1580647208101,"mc":[{"id":"1.168224571","rc":[{"batl":[[2,1.99,217.35]],"ltp":1.87,"tv":5394.75,"id":2284304}]}]}
{"op":"mcm","clk":"1002919575","pt":1580647213185,"mc":[{"id":"1.168224571","rc":[{"batl":[[0,2.28,4.59],[1,2.46,77.7],[2,2.54,3.88]],"ltp":2.08,"tv":5304.05,"id":7797764},{"batb":[[0,1.82,91],[1,1.79,21.31],[2,1.78,91]],"batl":[[2,2,26.5]],"ltp":1.87,"tv":5394.75,"id":2284304}]}]}
{"op":"mcm","clk":"1002919729","pt":1580647213990,"mc":[{"id":"1.168224571","rc":[{"batb":[[0,1.79,21.31],[1,1.78,91],[2,1.76,91.03]],"ltp":1.87,"tv":5394.75,"id":2284304}]}]}
{"op":"mcm","clk":"1002920018","pt":1580647215398,"mc":[{"id":"1.168224571","rc":[{"batb":[[0,2.16,955.65],[1,2.14,982.36],[2,2,26.5]],"batl":[[1,2.38,408],[2,2.46,77.7]],"ltp":2.08,"tv":5304.05,"id":7797764},{"batb":[[1,1.76,91.03],[2,1.75,280.64]],"batl":[[0,1.81,3345],[1,1.83,507],[2,1.91,7.56]],"ltp":1.87,"tv":5394.75,"id":2284304}]}]}
{"op":"mcm","clk":"1002920235","pt":1580647216400,"mc":[{"id":"1.168224571","rc":[{"batb":[[0,2.22,83.8],[1,2.16,95.56],[2,2.14,116.56]],"ltp":2.08,"tv":5304.05,"id":7797764},{"batl":[[0,1.81,189.44],[1,1.83,763.68],[2,1.87,62.5]],"ltp":1.87,"tv":5394.75,"id":2284304}]}]}
{"op":"mcm","clk":"1002920396","pt":1580647217201,"mc":[{"id":"1.168224571","rc":[{"batb":[[1,2.18,35.29],[2,2.16,95.56]],"batl":[[1,2.38,438.25]],"ltp":2.08,"tv":5304.05,"id":7797764},{"batl":[[2,1.85,42.01]],"ltp":1.87,"tv":5394.75,"id":2284304}]}]}
{"op":"mcm","clk":"1002921337","pt":1580647221808,"mc":[{"id":"1.168224571","rc":[{"batb":[[1,1.76,585.07]],"batl":[[2,1.85,522.6]],"ltp":1.87,"tv":5394.75,"id":2284304}]}]}
{"op":"mcm","clk":"1002922197","pt":1580647225483,"mc":[{"id":"1.168224571","rc":[{"batl":[[1,2.38,30.25]],"ltp":2.08,"tv":5304.05,"id":7797764},{"batl":[[1,1.83,256.68]],"ltp":1.87,"tv":5394.75,"id":2284304}]}]}
{"op":"mcm","clk":"1002922332","pt":1580647226073,"mc":[{"id":"1.168224571","rc":[{"batb":[[0,2.18,35.29],[1,2.14,18.32],[2,2.08,101.89]],"batl":[[0,2.38,30.25],[1,2.46,73.45],[2,2.52,3.76]],"ltp":2.08,"tv":5304.05,"id":7797764},{"batb":[[0,1.76,494.03],[1,1.74,601.84],[2,1.73,154.6]],"batl":[[0,1.85,522.6],[1,1.87,559.9],[2,1.93,54.5]],"ltp":1.87,"tv":5394.75,"id":2284304}]}]}
{"op":"mcm","clk":"1002922636","pt":1580647227645,"mc":[{"id":"1.168224571","rc":[{"batb":[[0,2.14,18.32],[1,2.08,101.89],[2,2.02,17.24]],"batl":[[0,2.46,73.45],[1,2.52,3.76],[2,2.54,3.88]],"ltp":2.08,"tv":5304.05,"id":7797764},{"batl":[[0,1.85,480.59]],"ltp":1.87,"tv":5394.75,"id":2284304}]}]}
{"op":"mcm","clk":"1002923037","pt":1580647229472,"mc":[{"id":"1.168224571","rc":[{"batb":[[0,1.74,91],[1,1.73,154.6],[2,1.7,91]],"ltp":1.87,"tv":5394.75,"id":2284304}]}]}
{"op":"mcm","clk":"1002923079","pt":1580647229689,"mc":[{"id":"1.168224571","rc":[{"batb":[[0,2.08,101.89],[1,2.02,17.24],[2,2,26.5]],"ltp":2.08,"tv":5304.05,"id":7797764},{"batl":[[1,1.87,497.4]],"ltp":1.87,"tv":5394.75,"id":2284304}]}]}
{"op":"mcm","clk":"1002923304","pt":1580647230821,"mc":[{"id":"1.168224571","rc":[{"batb":[[0,1.73,154.6],[1,1.7,91],[2,1.66,24.28]],"ltp":1.87,"tv":5394.75,"id":2284304}]}]}
{"op":"mcm","clk":"1002923669","pt":1580647232472,"mc":[{"id":"1.168224571","rc":[{"batb":[[0,2.44,244.9],[1,2.4,16.86],[2,2.38,157.56]],"ltp":2.08,"tv":5304.05,"id":7797764},{"trd":[[1.7,182],[1.73,309.2]],"batb":[[0,1.66,24.28],[1,1.65,29.13],[2,1.64,116.21]],"batl":[[0,1.69,545],[1,1.71,71.5],[2,1.76,42.01]],"ltp":1.7,"tv":5885.95,"id":2284304}],"tv":11190.0}]}
{"op":"mcm","clk":"1002923858","pt":1580647233293,"mc":[{"id":"1.168224571","rc":[{"trd":[[2.46,73.45]],"batb":[[0,2.46,63.73],[1,2.44,244.9],[2,2.4,16.86]],"batl":[[0,2.64,3.43],[1,2.66,356.16],[2,1000,0.02]],"ltp":2.46,"tv":5377.5,"id":7797764},{"trd":[[1.68,107.55]],"batb":[[0,1.64,116.21],[1,1.63,302.51],[2,1.62,193.1]],"batl":[[2,1.75,341.35]],"ltp":1.68,"tv":5993.5,"id":2284304}],"tv":11371.0}]}
{"op":"mcm","clk":"1002924090","pt":1580647234411,"mc":[{"id":"1.168224571","rc":[{"batl":[[0,2.62,25.21],[1,2.64,3.43],[2,2.66,356.16]],"ltp":2.46,"tv":5377.5,"id":7797764}]}]}
{"op":"mcm","clk":"1002924323","pt":1580647235486,"mc":[{"id":"1.168224571","rc":[{"batl":[[2,1.73,42.01]],"ltp":1.68,"tv":5993.5,"id":2284304}]}]}
{"op":"mcm","clk":"1002924413","pt":1580647235912,"mc":[{"id":"1.168224571","rc":[{"batb":[[1,1.63,363.82]],"batl":[[0,1.69,846.12],[1,1.71,390.81]],"ltp":1.68,"tv":5993.5,"id":2284304}]}]}
{"op":"mcm","clk":"1002924723","pt":1580647237299,"mc":[{"id":"1.168224571","rc":[{"trd":[[1.69,11.7]],"batl":[[0,1.69,840.27]],"ltp":1.69,"tv":6005.2,"id":2284304}],"tv":11382.7}]}
{"op":"mcm","clk":"1002924899","pt":1580647238218,"mc":[{"id":"1.168224571","rc":[{"batl":[[0,1.68,92.08],[1,1.69,840.27],[2,1.71,390.81]],"ltp":1.69,"tv":6005.2,"id":2284304}]}]}
{"op":"mcm","clk":"1002926647","pt":1580647246445,"mc":[{"id":"1.168224571","rc":[{"batb":[[0,2.38,30.25],[1,2.24,80.89],[2,2.14,15.32]],"batl":[[1,2.66,1.16],[2,1000,0.02]],"ltp":2.46,"tv":5377.5,"id":7797764},{"batb":[[0,1.61,562.09],[1,1.6,1.92],[2,1.59,510.84]],"batl":[[1,1.73,522.6],[2,1.75,497.4]],"ltp":1.69,"tv":6005.2,"id":2284304}]}]}
{"op":"mcm","clk":"1002926882","pt":1580647247506,"mc":[{"id":"1.168224571","rc":[{"batb":[[0,2.24,80.89],[1,2.14,15.32],[2,1.7,75.72]],"batl":[[0,2.66,1.16],[1,1000,0.02],[2,1000,0]],"ltp":2.46,"tv":5377.5,"id":7797764},{"batb":[[0,1.61,494.03]],"batl":[[1,1.73,480.59]],"ltp":1.69,"tv":6005.2,"id":2284304}]}]}
{"op":"mcm","clk":"1002927297","pt":1580647249437,"mc":[{"id":"1.168224571","rc":[{"batb":[[1,2.2,15.07],[2,2.14,15.32]],"ltp":2.46,"tv":5377.5,"id":7797764}]}]}
{"op":"mcm","clk":"1002927438","pt":1580647250040,"mc":[{"id":"1.168224571","rc":[{"batb":[[1,2.14,15.32],[2,1.7,75.72]],"ltp":2.46,"tv":5377.5,"id":7797764},{"batb":[[0,1.6,1.92],[1,1.51,153.82],[2,1.5,399.75]],"ltp":1.69,"tv":6005.2,"id":2284304}]}]}
{"op":"mcm","clk":"1002928101","pt":1580647253001,"mc":[{"id":"1.168224571","rc":[{"trd":[[2.66,2.32],[2.68,1.15]],"batb":[[0,2.9,216.29],[1,2.78,15.16],[2,2.24,80.89]],"batl":[[0,3.15,392]],"ltp":2.68,"tv":5380.97,"id":7797764},{"trd":[[1.6,1.92]],"batb":[[0,1.51,153.82],[1,1.5,399.75],[2,1.49,266.48]],"batl":[[0,1.54,577],[1,1.55,592.13],[2,1.56,299.96]],"ltp":1.6,"tv":6007.12,"id":2284304}],"tv":11388.09}]}
{"op":"mcm","clk":"1002928419","pt":1580647254402,"mc":[{"id":"1.168224571","rc":[{"batb":[[1,2.78,60.87],[2,2.54,57.91]],"ltp":2.68,"tv":5380.97,"id":7797764}]}]}
{"op":"mcm","clk":"1002928458","pt":1580647254617,"mc":[{"id":"1.168224571","rc":[{"batl":[[0,3,21],[1,3.15,392],[2,1000,0.02]],"ltp":2.68,"tv":5380.97,"id":7797764},{"batb":[[1,1.5,483.77]],"ltp":1.6,"tv":6007.12,"id":2284304}]}]}
{"op":"mcm","clk":"1002928772","pt":1580647256123,"mc":[{"id":"1.168224571","rc":[{"batb":[[2,2.68,24.37]],"ltp":2.68,"tv":5380.97,"id":7797764}]}]}
{"op":"mcm","clk":"1002930317","pt":1580647263441,"mc":[{"id":"1.168224571","rc":[{"batb":[[0,2.78,15.16],[1,2.68,24.37],[2,2.54,57.91]],"batl":[[1,1000,0.02],[2,1000,0]],"ltp":2.68,"tv":5380.97,"id":7797764},{"batb":[[0,1.5,84.02],[1,1.43,2],[2,1.42,197.96]],"batl":[[0,1.52,20],[1,1.56,80.92],[2,1.59,42.01]],"ltp":1.6,"tv":6007.12,"id":2284304}]}]}
{"op":"mcm","clk":"1002930389","pt":1580647263758,"mc":[{"id":"1.168224571","rc":[{"batb":[[1,2.54,57.91],[2,2.5,14.72]],"batl":[[0,1000,0.02],[1,1000,0]],"ltp":2.68,"tv":5380.97,"id":7797764},{"batb":[[0,1.43,2],[1,1.42,197.96],[2,1.34,465.43]],"batl":[[1,1.54,20],[2,1.56,80.92]],"ltp":1.6,"tv":6007.12,"id":2284304}]}]}
{"op":"mcm","clk":"1002930949","pt":1580647266446,"mc":[{"id":"1.168224571","rc":[{"batb":[[2,1.4,308.49]],"ltp":1.6,"tv":6007.12,"id":2284304}]}]}
{"op":"mcm","clk":"1002931017","pt":1580647266775,"mc":[{"id":"1.168224571","rc":[{"batb":[[0,2.54,57.91],[1,2.5,14.72],[2,2.4,13.01]],"ltp":2.68,"tv":5380.97,"id":7797764},{"batl":[[2,1.63,234.78]],"ltp":1.6,"tv":6007.12,"id":2284304}]}]}
{"op":"mcm","clk":"1002931289","pt":1580647267971,"mc":[{"id":"1.168224571","rc":[{"batl":[[0,1.51,177],[1,1.52,20],[2,1.54,20]],"ltp":1.6,"tv":6007.12,"id":2284304}]}]}
{"op":"mcm","clk":"1002931973","pt":1580647271264,"mc":[{"id":"1.168224571","rc":[{"batl":[[1,1.66,59.25],[2,1.71,55.5]],"ltp":1.6,"tv":6007.12,"id":2284304}]}]}
{"op":"mcm","clk":"1002932378","pt":1580647273403,"mc":[{"id":"1.168224571","rc":[{"batb":[[0,3.25,1153.85],[1,2.82,757.81],[2,2.54,57.91]],"batl":[[0,3.8,332],[1,1000,0.02]],"ltp":2.68,"tv":5380.97,"id":7797764},{"trd":[[1.42,395.91],[1.43,4]],"batb":[[0,1.4,308.49],[1,1.39,359.92],[2,1.23,2]],"batl":[[0,1.42,545.05],[1,1.43,4643.4],[2,1.49,10.55]],"ltp":1.42,"tv":6407.03,"id":2284304}],"tv":11788.0}]}
{"op":"mcm","clk":"1002932620","pt":1580647274456,"mc":[{"id":"1.168224571","rc":[{"batb":[[0,3.3,17.64],[1,3.25,115.39],[2,3.2,12.97]],"batl":[[0,3.75,15.12],[1,3.8,332],[2,1000,0.02]],"ltp":2.68,"tv":5380.97,"id":7797764},{"batb":[[2,1.37,230.38]],"batl":[[1,1.44,343.87],[2,1.45,86.5]],"ltp":1.42,"tv":6407.03,"id":2284304}]}]}
{"op":"mcm","clk":"1002933189","pt":1580647277265,"mc":[{"id":"1.168224571","rc":[{"batl":[[1,1.44,535],[2,1.45,376.99]],"ltp":1.42,"tv":6407.03,"id":2284304}]}]}
{"op":"mcm","clk":"1002934029","pt":1580647281450,"mc":[{"id":"1.168224571","rc":[{"batb":[[0,3.25,115.39],[1,3.2,12.97],[2,3.1,84.11]],"ltp":2.68,"tv":5380.97,"id":7797764},{"batl":[[1,1.44,492.99]],"ltp":1.42,"tv":6407.03,"id":2284304}]}]}
{"op":"mcm","clk":"1002934224","pt":1580647282483,"mc":[{"id":"1.168224571","rc":[{"batb":[[0,3.25,193.21],[2,2.92,101.89]],"ltp":2.68,"tv":5380.97,"id":7797764},{"batb":[[1,1.39,570.08],[2,1.36,115.95]],"ltp":1.42,"tv":6407.03,"id":2284304}]}]}
{"op":"mcm","clk":"1002934547","pt":1580647284086,"mc":[{"id":"1.168224571","rc":[{"batb":[[0,1.4,313.49]],"ltp":1.42,"tv":6407.03,"id":2284304}]}]}
{"op":"mcm","clk":"1002935043","pt":1580647286442,"mc":[{"id":"1.168224571","rc":[{"batl":[[0,1.41,20],[1,1.42,545.05],[2,1.44,492.99]],"ltp":1.42,"tv":6407.03,"id":2284304}]}]}
{"op":"mcm","clk":"1002935416","pt":1580647288473,"mc":[{"id":"1.168224571","rc":[{"batb":[[0,1.4,343.08]],"ltp":1.42,"tv":6407.03,"id":2284304}]}]}
{"op":"mcm","clk":"1002935454","pt":1580647288687,"mc":[{"id":"1.168224571","rc":[{"batb":[[0,3.3,17.64],[1,3.25,193.21],[2,3.2,12.97]],"ltp":2.68,"tv":5380.97,"id":7797764},{"batl":[[2,1.44,535]],"ltp":1.42,"tv":6407.03,"id":2284304}]}]}
{"op":"mcm","clk":"1002935759","pt":1580647290489,"mc":[{"id":"1.168224571","rc":[{"batb":[[0,1.4,338.08]],"ltp":1.42,"tv":6407.03,"id":2284304}]}]}
{"op":"mcm","clk":"1002935855","pt":1580647290973,"mc":[{"id":"1.168224571","rc":[{"batb":[[0,3.25,193.21],[1,3.2,12.97],[2,2.94,41.15]],"ltp":2.68,"tv":5380.97,"id":7797764},{"batb":[[1,1.39,568.27]],"batl":[[2,1.44,492.99]],"ltp":1.42,"tv":6407.03,"id":2284304}]}]}
{"op":"mcm","clk":"1002936128","pt":1580647292391,"mc":[{"id":"1.168224571","rc":[{"trd":[[1.41,10]],"batl":[[0,1.41,15]],"ltp":1.41,"tv":6417.03,"id":2284304}],"tv":11798.0}]}
{"op":"mcm","clk":"1002936272","pt":1580647293092,"mc":[{"id":"1.168224571","rc":[{"trd":[[1.41,40],[1.42,399.69]],"batl":[[0,1.42,543.16],[1,1.44,492.99],[2,1.45,376.99]],"ltp":1.42,"tv":6450.81,"id":2284304}],"tv":11831.78}]}
{"op":"mcm","clk":"1002936362","pt":1580647293569,"mc":[{"id":"1.168224571","rc":[{"batl":[[1,1.43,20],[2,1.44,492.99]],"ltp":1.42,"tv":6450.81,"id":2284304}]}]}
{"op":"mcm","clk":"1002936868","pt":1580647296270,"mc":[{"id":"1.168224571","rc":[{"trd":[[1.4,354]],"batb":[[0,1.4,161.08]],"ltp":1.4,"tv":6804.81,"id":2284304}],"tv":12185.78}]}
{"op":"mcm","clk":"1002936984","pt":1580647296906,"mc":[{"id":"1.168224571","rc":[{"batl":[[2,1.44,301.91]],"ltp":1.4,"tv":6804.81,"id":2284304}]}]}
{"op":"mcm","clk":"1002937293","pt":1580647298484,"mc":[{"id":"1.168224571","rc":[{"batb":[[1,3.2,91.97]],"ltp":2.68,"tv":5380.97,"id":7797764}]}]}
{"op":"mcm","clk":"1002937427","pt":1580647299189,"mc":[{"id":"1.168224571","rc":[{"batb":[[0,3.3,17.64],[1,3.25,115.39],[2,3.2,91.97]],"ltp":2.68,"tv":5380.97,"id":7797764},{"batb":[[1,1.39,567.72]],"batl":[[2,1.44,343.92]],"ltp":1.4,"tv":6804.81,"id":2284304}]}]}
{"op":"mcm","clk":"1002937569","pt":1580647299891,"mc":[{"id":"1.168224571","rc":[{"batb":[[0,1.4,240.27]],"batl":[[1,1.43,302.6]],"ltp":1.4,"tv":6804.81,"id":2284304}]}]}
{"op":"mcm","clk":"1002937706","pt":1580647300611,"mc":[{"id":"1.168224571","rc":[{"batl":[[0,1.41,20],[1,1.42,543.16],[2,1.43,302.6]],"ltp":1.4,"tv":6804.81,"id":2284304}]}]}
{"op":"mcm","clk":"1002938468","pt":1580647304289,"mc":[{"id":"1.168224571","rc":[{"trd":[[1.4,834.55]],"batb":[[0,1.39,567.72],[1,1.36,115.95],[2,1.35,241]],"batl":[[0,1.4,971.29],[1,1.41,20],[2,1.42,543.16]],"ltp":1.4,"tv":7285.35,"id":2284304}],"tv":12666.33}]}
{"op":"mcm","clk":"1002939021","pt":1580647306901,"mc":[{"id":"1.168224571","rc":[{"batb":[[1,3.25,192.1],[2,3.2,12.97]],"ltp":2.68,"tv":5380.97,"id":7797764}]}]}
{"op":"mcm","clk":"1002939205","pt":1580647307801,"mc":[{"id":"1.168224571","rc":[{"batb":[[0,1.39,674.57],[1,1.38,374.63],[2,1.36,115.95]],"batl":[[0,1.4,1315.83]],"ltp":1.4,"tv":7285.35,"id":2284304}]}]}
{"op":"mcm","clk":"1002939507","pt":1580647309327,"mc":[{"id":"1.168224571","rc":[{"trd":[[1.39,40]],"batb":[[0,1.39,654.57]],"ltp":1.39,"tv":7325.35,"id":2284304}],"tv":12706.33}]}
{"op":"mcm","clk":"1002940238","pt":1580647313010,"mc":[{"id":"1.168224571","rc":[{"trd":[[1.4,841.86]],"batl":[[0,1.4,1312.18],[1,1.42,543.16],[2,1.43,454.67]],"ltp":1.4,"tv":7332.67,"id":2284304}],"tv":12713.64}]}
{"op":"mcm","clk":"1002941228","pt":1580647318014,"mc":[{"id":"1.168224571","rc":[{"trd":[[1.4,844.56]],"batl":[[0,1.4,1310.83]],"ltp":1.4,"tv":7335.37,"id":2284304}],"tv":12716.34}]}
{"op":"mcm","clk":"1002941490","pt":1580647319393,"mc":[{"id":"1.168224571","rc":[{"batl":[[0,1.4,966.29]],"ltp":1.4,"tv":7335.37,"id":2284304}]}]}
{"op":"mcm","clk":"1002941613","pt":1580647320032,"mc":[{"id":"1.168224571","rc":[{"batl":[[0,1.42,543.16],[1,1.43,479.87],[2,1.44,301.91]],"ltp":1.4,"tv":7335.37,"id":2284304}]}]}
{"op":"mcm","clk":"1002942094","pt":1580647322325,"mc":[{"id":"1.168224571","rc":[{"trd":[[1.39,726.64],[1.4,847]],"batb":[[0,1.39,311.25]],"ltp":1.39,"tv":8024.45,"id":2284304}],"tv":13405.42}]}
{"op":"mcm","clk":"1002942299","pt":1580647323226,"mc":[{"id":"1.168224571","rc":[{"batl":[[0,1.42,550.72],[1,1.43,356.18],[2,1.45,86.5]],"ltp":1.39,"tv":8024.45,"id":2284304}]}]}
{"op":"mcm","clk":"1002942695","pt":1580647325127,"mc":[{"id":"1.168224571","rc":[{"trd":[[1.39,741.58]],"batb":[[0,1.39,303.78]],"ltp":1.39,"tv":8039.39,"id":2284304}],"tv":13420.36}]}
{"op":"mcm","clk":"1002942991","pt":1580647326343,"mc":[{"id":"1.168224571","rc":[{"batb":[[0,1.39,464.8]],"batl":[[0,1.42,844.8]],"ltp":1.39,"tv":8039.39,"id":2284304}]}]}
{"op":"mcm","clk":"1002943076","pt":1580647326724,"mc":[{"id":"1.168224571","rc":[{"batb":[[0,3.25,192.1],[1,3.2,12.97],[2,2.94,100.16]],"ltp":2.68,"tv":5380.97,"id":7797764}]}]}
{"op":"mcm","clk":"1002943637","pt":1580647329639,"mc":[{"id":"1.168224571","rc":[{"batb":[[0,3.35,17.64],[1,3.25,192.1],[2,3.2,12.97]],"ltp":2.68,"tv":5380.97,"id":7797764},{"batl":[[0,1.41,10],[1,1.42,844.8],[2,1.43,356.18]],"ltp":1.39,"tv":8039.39,"id":2284304}]}]}
{"op":"mcm","clk":"1002944555","pt":1580647334358,"mc":[{"id":"1.168224571","rc":[{"batb":[[1,3.25,191.55]],"ltp":2.68,"tv":5380.97,"id":7797764},{"trd":[[1.41,40.1]],"batl":[[0,1.41,9.95]],"ltp":1.41,"tv":8039.49,"id":2284304}],"tv":13420.46}]}
{"op":"mcm","clk":"1002944746","pt":1580647335259,"mc":[{"id":"1.168224571","rc":[{"trd":[[1.39,1671.17]],"batb":[[0,1.38,374.63],[1,1.36,115.95],[2,1.34,245.88]],"batl":[[0,1.39,519.61],[1,1.41,9.95],[2,1.42,844.8]],"ltp":1.39,"tv":8969.07,"id":2284304}],"tv":14350.05}]}
{"op":"mcm","clk":"1002945333","pt":1580647338254,"mc":[{"id":"1.168224571","rc":[{"batb":[[0,1.38,495.43],[1,1.37,392.03],[2,1.36,115.95]],"batl":[[2,1.42,989.72]],"ltp":1.39,"tv":8969.07,"id":2284304}]}]}
{"op":"mcm","clk":"1002946154","pt":1580647342276,"mc":[{"id":"1.168224571","rc":[{"batl":[[0,1.41,9.95],[1,1.42,989.72],[2,1.43,356.18]],"ltp":1.39,"tv":8969.07,"id":2284304}]}]}
{"op":"mcm","clk":"1002948671","pt":1580647354627,"mc":[{"id":"1.168224571","rc":[{"trd":[[1.41,50]],"batl":[[0,1.41,5]],"ltp":1.41,"tv":8978.98,"id":2284304}],"tv":14359.95}]}
{"op":"mcm","clk":"1002949548","pt":1580647359039,"mc":[{"id":"1.168224571","rc":[{"trd":[[1.38,200]],"batb":[[0,1.38,395.43]],"ltp":1.38,"tv":9178.98,"id":2284304}],"tv":14559.95}]}
{"op":"mcm","clk":"1002949821","pt":1580647360454,"mc":[{"id":"1.168224571","rc":[{"batl":[[1,1000,0.02],[2,1000,0]],"ltp":2.68,"tv":5380.97,"id":7797764},{"batl":[[1,1.42,446.56]],"ltp":1.38,"tv":9178.98,"id":2284304}]}]}
{"op":"mcm","clk":"1002950114","pt":1580647361934,"mc":[{"id":"1.168224571","rc":[{"batb":[[0,1.39,2.18],[1,1.38,395.43],[2,1.37,392.03]],"ltp":1.38,"tv":9178.98,"id":2284304}]}]}
{"op":"mcm","clk":"1002950245","pt":1580647362562,"mc":[{"id":"1.168224571","rc":[{"batb":[[1,1.38,440.17]],"batl":[[1,1.42,500.28]],"ltp":1.38,"tv":9178.98,"id":2284304}]}]}
{"op":"mcm","clk":"1002950606","pt":1580647364442,"mc":[{"id":"1.168224571","rc":[{"batl":[[1,3.8,2.12],[2,3.95,2.05]],"ltp":2.68,"tv":5380.97,"id":7797764}]}]}
{"op":"mcm","clk":"1002951042","pt":1580647366489,"mc":[{"id":"1.168224571","rc":[{"batb":[[1,2.96,99.45],[2,2.12,10.79]],"batl":[[0,3.75,17.22],[2,1000,0.02]],"ltp":2.68,"tv":5380.97,"id":7797764},{"batb":[[1,1.37,46.77],[2,1.36,166.88]],"batl":[[1,1.42,7.56],[2,1.43,42.01]],"ltp":1.38,"tv":9178.98,"id":2284304}]}]}
{"op":"mcm","clk":"1002951133","pt":1580647366854,"mc":[{"id":"1.168224571","rc":[{"batl":[[0,3.75,15.12]],"ltp":2.68,"tv":5380.97,"id":7797764},{"batb":[[1,1.36,166.88],[2,1.34,245.88]],"ltp":1.38,"tv":9178.98,"id":2284304}]}]}
{"op":"mcm","clk":"1002951291","pt":1580647367549,"mc":[{"id":"1.168224571","rc":[{"batb":[[0,2.96,99.45],[1,2.12,10.79],[2,2,75.72]],"batl":[[0,3.8,2.12],[1,1000,0.02],[2,1000,0]],"ltp":2.68,"tv":5380.97,"id":7797764},{"batb":[[1,1.36,50.93]],"batl":[[2,1.5,10]],"ltp":1.38,"tv":9178.98,"id":2284304}]}]}
{"op":"mcm","clk":"1002951678","pt":1580647369367,"mc":[{"id":"1.168224571","rc":[{"batb":[[0,3.05,94.73],[1,2.96,99.45],[2,2.12,10.79]],"ltp":2.68,"tv":5380.97,"id":7797764},{"batb":[[2,1.35,239.49]],"batl":[[2,1.49,413.67]],"ltp":1.38,"tv":9178.98,"id":2284304}]}]}
{"op":"mcm","clk":"1002951882","pt":1580647370339,"mc":[{"id":"1.168224571","rc":[{"batb":[[1,2.12,10.79],[2,2,75.72]],"ltp":2.68,"tv":5380.97,"id":7797764}]}]}
{"op":"mcm","clk":"1002952794","pt":1580647374846,"mc":[{"id":"1.168224571","rc":[{"batb":[[2,1.33,256.27]],"ltp":1.38,"tv":9178.98,"id":2284304}]}]}
{"op":"mcm","clk":"1002953131","pt":1580647376439,"mc":[{"id":"1.168224571","rc":[{"batl":[[0,1.42,7.56],[1,1.49,413.67],[2,1.5,257.87]],"ltp":1.38,"tv":9178.98,"id":2284304}]}]}
{"op":"mcm","clk":"1002953291","pt":1580647377238,"mc":[{"id":"1.168224571","rc":[{"batl":[[0,3.4,3.02],[1,3.8,2.12],[2,1000,0.02]],"ltp":2.68,"tv":5380.97,"id":7797764}]}]}
{"op":"mcm","clk":"1002953561","pt":1580647378422,"mc":[{"id":"1.168224571","rc":[{"trd":[[3.35,3.21]],"batl":[[0,3.3,310],[1,3.4,3.02],[2,3.8,2.12]],"ltp":3.35,"tv":5384.18,"id":7797764},{"trd":[[1.42,407.25]],"batb":[[0,1.45,1820.94],[1,1.44,310.36],[2,1.39,2.18]],"batl":[[0,1.49,1923.74],[1,1.5,818.87],[2,1.77,500.61]],"ltp":1.42,"tv":9186.54,"id":2284304}],"tv":14570.72}]}
{"op":"mcm","clk":"1002953774","pt":1580647379435,"mc":[{"id":"1.168224571","rc":[{"batb":[[0,3.05,114.9],[1,2.76,50.2],[2,2.12,10.79]],"batl":[[2,3.45,16.8]],"ltp":3.35,"tv":5384.18,"id":7797764},{"batb":[[1,1.44,490.86],[2,1.43,26.82]],"batl":[[0,1.49,1965.75]],"ltp":1.42,"tv":9186.54,"id":2284304}]}]}
{"op":"mcm","clk":"1002953953","pt":1580647380230,"mc":[{"id":"1.168224571","rc":[{"batl":[[0,3.3,316.06]],"ltp":3.35,"tv":5384.18,"id":7797764}]}]}
{"op":"mcm","clk":"1002954181","pt":1580647381344,"mc":[{"id":"1.168224571","rc":[{"batl":[[0,3.3,310]],"ltp":3.35,"tv":5384.18,"id":7797764},{"batb":[[2,1.43,17.46]],"ltp":1.42,"tv":9186.54,"id":2284304}]}]}
{"op":"mcm","clk":"1002954308","pt":1580647381823,"mc":[{"id":"1.168224571","rc":[{"batb":[[2,1.41,101.66]],"ltp":1.42,"tv":9186.54,"id":2284304}]}]}
{"op":"mcm","clk":"1002954754","pt":1580647384012,"mc":[{"id":"1.168224571","rc":[{"batb":[[2,1.42,494.03]],"batl":[[2,1.51,480.59]],"ltp":1.42,"tv":9186.54,"id":2284304}]}]}
{"op":"mcm","clk":"1002954875","pt":1580647384647,"mc":[{"id":"1.168224571","rc":[{"batl":[[1,3.4,5.46]],"ltp":3.35,"tv":5384.18,"id":7797764},{"batb":[[2,1.42,533.47]],"batl":[[0,1.48,10],[1,1.49,1965.75],[2,1.5,818.87]],"ltp":1.42,"tv":9186.54,"id":2284304}]}]}
{"op":"mcm","clk":"1002956512","pt":1580647392195,"mc":[{"id":"1.168224571","rc":[{"batl":[[0,3.4,5.46],[1,3.45,16.8],[2,3.5,2.15]],"ltp":3.35,"tv":5384.18,"id":7797764},{"batl":[[2,1.5,257.87]],"ltp":1.42,"tv":9186.54,"id":2284304}]}]}
{"op":"mcm","clk":"1002956636","pt":1580647392832,"mc":[{"id":"1.168224571","rc":[{"batb":[[0,3.05,20.16],[2,2,75.72]],"ltp":3.35,"tv":5384.18,"id":7797764},{"batb":[[0,1.42,533.47],[1,1.41,101.66],[2,1.4,551.45]],"batl":[[1,1.49,42.01],[2,1.51,480.59]],"ltp":1.42,"tv":9186.54,"id":2284304}]}]}
{"op":"mcm","clk":"1002956805","pt":1580647393655,"mc":[{"id":"1.168224571","rc":[{"batb":[[0,2.76,50.2],[1,2,75.72],[2,1.99,36.51]],"batl":[[1,3.5,2.15],[2,3.8,2.12]],"ltp":3.35,"tv":5384.18,"id":7797764},{"batb":[[1,1.4,551.45],[2,1.39,212.52]],"batl":[[1,1.51,480.59],[2,1.53,497.4]],"ltp":1.42,"tv":9186.54,"id":2284304}]}]}
{"op":"mcm","clk":"1002957140","pt":1580647395415,"mc":[{"id":"1.168224571","rc":[{"batb":[[1,1.4,783.81],[2,1.39,576.4]],"ltp":1.42,"tv":9186.54,"id":2284304}]}]}
{"op":"mcm","clk":"1002957329","pt":1580647396431,"mc":[{"id":"1.168224571","rc":[{"batb":[[0,2.76,49.88]],"ltp":3.35,"tv":5384.18,"id":7797764},{"batb":[[2,1.39,363.88]],"ltp":1.42,"tv":9186.54,"id":2284304}]}]}
{"op":"mcm","clk":"1002957650","pt":1580647398023,"mc":[{"id":"1.168224571","rc":[{"batb":[[0,3.25,7],[1,2.76,49.88],[2,2,75.72]],"batl":[[0,3.4,3.02]],"ltp":3.35,"tv":5384.18,"id":7797764},{"batb":[[0,1.4,272.97],[1,1.39,363.88],[2,1.38,215.51]],"ltp":1.42,"tv":9186.54,"id":2284304}]}]}
{"op":"mcm","clk":"1002958168","pt":1580647400441,"mc":[{"id":"1.168224571","rc":[{"batb":[[1,3.2,65.43],[2,3.15,12.23]],"batl":[[2,3.65,363]],"ltp":3.35,"tv":5384.18,"id":7797764},{"batl":[[0,1.43,305.25],[1,1.44,306.57],[2,1.45,1114.09]],"ltp":1.42,"tv":9186.54,"id":2284304}]}]}
{"op":"mcm","clk":"1002958342","pt":1580647401295,"mc":[{"id":"1.168224571","rc":[{"batb":[[0,3.35,75.3],[1,3.25,25.48],[2,3.2,65.43]],"batl":[[2,3.65,378.12]],"ltp":3.35,"tv":5384.18,"id":7797764},{"batl":[[1,1.44,348.58]],"ltp":1.42,"tv":9186.54,"id":2284304}]}]}
{"op":"mcm","clk":"1002958435","pt":1580647401815,"mc":[{"id":"1.168224571","rc":[{"trd":[[3.3,8.73],[3.35,153.8]],"batb":[[0,3.25,25.48],[1,3.2,65.43],[2,3.15,12.23]],"ltp":3.3,"tv":5543.49,"id":7797764},{"trd":[[1.43,24.15]],"batl":[[0,1.43,285.1]],"ltp":1.43,"tv":9206.69,"id":2284304}],"tv":14750.19}]}
{"op":"mcm","clk":"1002958721","pt":1580647403170,"mc":[{"id":"1.168224571","rc":[{"batl":[[0,1.42,10],[1,1.43,285.1],[2,1.44,348.58]],"ltp":1.43,"tv":9206.69,"id":2284304}]}]}
{"op":"mcm","clk":"1002959631","pt":1580647407428,"mc":[{"id":"1.168224571","rc":[{"batb":[[2,1.38,709.54]],"batl":[[2,1.44,829.17]],"ltp":1.43,"tv":9206.69,"id":2284304}]}]}
{"op":"mcm","clk":"1002961072","pt":1580647414422,"mc":[{"id":"1.168224571","rc":[{"batl":[[2,3.65,15.12]],"ltp":3.3,"tv":5543.49,"id":7797764}]}]}
{"op":"mcm","clk":"1002961180","pt":1580647414951,"mc":[{"id":"1.168224571","rc":[{"batb":[[1,2.98,41.15],[2,2,75.72]],"batl":[[1,3.65,15.12],[2,3.75,2.02]],"ltp":3.3,"tv":5543.49,"id":7797764},{"batb":[[0,1.38,494.03],[1,1.37,159.2],[2,1.36,561.77]],"batl":[[1,1.44,522.6],[2,1.46,497.4]],"ltp":1.43,"tv":9206.69,"id":2284304}]}]}
{"op":"mcm","clk":"1002961334","pt":1580647415644,"mc":[{"id":"1.168224571","rc":[{"batb":[[0,3.25,7]],"batl":[[1,3.75,2.02],[2,3.8,2.12]],"ltp":3.3,"tv":5543.49,"id":7797764},{"batb":[[1,1.37,45.77]],"batl":[[1,1.44,480.59]],"ltp":1.43,"tv":9206.69,"id":2284304}]}]}
{"op":"mcm","clk":"1002961883","pt":1580647418332,"mc":[{"id":"1.168224571","rc":[{"batb":[[1,2.9,42.09]],"ltp":3.3,"tv":5543.49,"id":7797764},{"batl":[[0,1.44,480.59],[1,1.46,497.4],[2,1.77,500.61]],"ltp":1.43,"tv":9206.69,"id":2284304}]}]}
{"op":"mcm","clk":"1002962032","pt":1580647419017,"mc":[{"id":"1.168224571","rc":[{"batl":[[0,3.35,1.78],[1,3.4,3.02],[2,3.75,2.02]],"ltp":3.3,"tv":5543.49,"id":7797764}]}]}
{"op":"mcm","clk":"1002962162","pt":1580647419853,"mc":[{"id":"1.168224571","rc":[{"batb":[[0,1.42,2.27],[1,1.41,438.6],[2,1.4,353.77]],"batl":[[1,1.45,380.09],[2,1.46,785.78]],"ltp":1.43,"tv":9206.69,"id":2284304}]}]}
{"op":"mcm","clk":"1002962475","pt":1580647421458,"mc":[{"id":"1.168224571","rc":[{"batb":[[2,2.06,11.58]],"ltp":3.3,"tv":5543.49,"id":7797764}]}]}
{"op":"mcm","clk":"1002962601","pt":1580647422035,"mc":[{"id":"1.168224571","rc":[{"batb":[[2,2,75.72]],"ltp":3.3,"tv":5543.49,"id":7797764},{"batl":[[0,1.43,10],[1,1.44,480.59],[2,1.45,380.09]],"ltp":1.43,"tv":9206.69,"id":2284304}]}]}
{"op":"mcm","clk":"1002963054","pt":1580647424245,"mc":[{"id":"1.168224571","rc":[{"batb":[[1,1.41,403.38]],"ltp":1.43,"tv":9206.69,"id":2284304}]}]}
{"op":"mcm","clk":"1002963320","pt":1580647425445,"mc":[{"id":"1.168224571","rc":[{"batb":[[1,1.38,494.03],[2,1.37,45.77]],"batl":[[2,1.46,497.4]],"ltp":1.43,"tv":9206.69,"id":2284304}]}]}
{"op":"mcm","clk":"1002963948","pt":1580647428332,"mc":[{"id":"1.168224571","rc":[{"batb":[[2,2.06,11.58]],"ltp":3.3,"tv":5543.49,"id":7797764}]}]}
{"op":"mcm","clk":"1002964188","pt":1580647429434,"mc":[{"id":"1.168224571","rc":[{"batb":[[2,2,75.72]],"ltp":3.3,"tv":5543.49,"id":7797764}]}]}
{"op":"mcm","clk":"1002965164","pt":1580647434206,"mc":[{"id":"1.168224571","rc":[{"batl":[[1,1.5,10],[2,1.52,336.07]],"ltp":1.43,"tv":9206.69,"id":2284304}]}]}
{"op":"mcm","clk":"1002965403","pt":1580647435377,"mc":[{"id":"1.168224571","rc":[{"batb":[[2,2.06,11.58]],"ltp":3.3,"tv":5543.49,"id":7797764},{"batl":[[0,1.52,336.07],[1,1.53,239.01],[2,1.77,500.61]],"ltp":1.43,"tv":9206.69,"id":2284304}]}]}
{"op":"mcm","clk":"1002965473","pt":1580647435697,"mc":[{"id":"1.168224571","rc":[{"batb":[[2,2,75.72]],"ltp":3.3,"tv":5543.49,"id":7797764},{"batl":[[2,1.93,36.5]],"ltp":1.43,"tv":9206.69,"id":2284304}]}]}
{"op":"mcm","clk":"1002965759","pt":1580647437112,"mc":[{"id":"1.168224571","rc":[{"trd":[[3.25,7]],"batb":[[0,2.9,42.09],[1,1.99,36.51],[2,1.97,33.17]],"batl":[[0,3.15,367],[1,3.35,1.78],[2,3.4,3.02]],"ltp":3.25,"tv":5550.49,"id":7797764},{"trd":[[1.45,15.69]],"batb":[[0,1.48,267.97],[1,1.47,284.16],[2,1.46,256.85]],"batl":[[2,1.54,626]],"ltp":1.45,"tv":9222.38,"id":2284304}],"tv":14772.88}]}
{"op":"mcm","clk":"1002966035","pt":1580647438307,"mc":[{"id":"1.168224571","rc":[{"batb":[[1,2.56,59.09],[2,1.99,36.51]],"ltp":3.25,"tv":5550.49,"id":7797764},{"batb":[[1,1.47,448.61]],"ltp":1.45,"tv":9222.38,"id":2284304}]}]}
{"op":"mcm","clk":"1002966227","pt":1580647439305,"mc":[{"id":"1.168224571","rc":[{"batl":[[0,1.52,378.08]],"ltp":1.45,"tv":9222.38,"id":2284304}]}]}
{"op":"mcm","clk":"1002966365","pt":1580647439979,"mc":[{"id":"1.168224571","rc":[{"batb":[[0,2.92,21.85],[1,2.9,42.09],[2,2.56,59.09]],"batl":[[1,3.25,18.48],[2,3.35,1.78]],"ltp":3.25,"tv":5550.49,"id":7797764}]}]}
{"op":"mcm","clk":"1002966771","pt":1580647441811,"mc":[{"id":"1.168224571","rc":[{"batl":[[0,1.51,10],[1,1.52,378.08],[2,1.53,239.01]],"ltp":1.45,"tv":9222.38,"id":2284304}]}]}
{"op":"mcm","clk":"1002967465","pt":1580647444995,"mc":[{"id":"1.168224571","rc":[{"batl":[[2,3.4,3.02]],"ltp":3.25,"tv":5550.49,"id":7797764}]}]}
{"op":"mcm","clk":"1002967924","pt":1580647447079,"mc":[{"id":"1.168224571","rc":[{"trd":[[1.48,382.34]],"batb":[[0,1.48,76.8]],"ltp":1.48,"tv":9604.72,"id":2284304}],"tv":15155.22}]}
{"op":"mcm","clk":"1002968048","pt":1580647447666,"mc":[{"id":"1.168224571","rc":[{"batb":[[0,1.47,448.61],[1,1.46,256.85],[2,1.45,720.41]],"batl":[[1,1.52,288.72],[2,1.54,1106.59]],"ltp":1.48,"tv":9604.72,"id":2284304}]}]}
{"op":"mcm","clk":"1002968351","pt":1580647449213,"mc":[{"id":"1.168224571","rc":[{"batl":[[1,1.52,298.72]],"ltp":1.48,"tv":9604.72,"id":2284304}]}]}
{"op":"mcm","clk":"1002968660","pt":1580647450605,"mc":[{"id":"1.168224571","rc":[{"batb":[[0,1.47,612.13],[1,1.46,551.32]],"batl":[[0,1.51,203.49]],"ltp":1.48,"tv":9604.72,"id":2284304}]}]}
{"op":"mcm","clk":"1002969261","pt":1580647453383,"mc":[{"id":"1.168224571","rc":[{"trd":[[1.51,2.48]],"batl":[[0,1.51,202.25]],"ltp":1.51,"tv":9607.2,"id":2284304}],"tv":15157.7}]}
{"op":"mcm","clk":"1002969447","pt":1580647454284,"mc":[{"id":"1.168224571","rc":[{"batb":[[1,2.56,59.09],[2,1.93,37.93]],"batl":[[0,3.25,18.48],[1,3.4,3.02],[2,1000,0.02]],"ltp":3.25,"tv":5550.49,"id":7797764},{"batb":[[0,1.45,494.03],[1,1.44,94.94],[2,1.43,510.84]],"batl":[[0,1.51,8.76],[1,1.52,52.01],[2,1.54,480.59]],"ltp":1.51,"tv":9607.2,"id":2284304}]}]}
{"op":"mcm","clk":"1002969730","pt":1580647455720,"mc":[{"id":"1.168224571","rc":[{"batb":[[0,2.56,59.09],[1,1.93,37.93],[2,1.91,33.39]],"batl":[[0,3.4,3.02],[1,1000,0.02],[2,1000,0]],"ltp":3.25,"tv":5550.49,"id":7797764},{"batb":[[1,1.43,510.84],[2,1.42,2.27]],"batl":[[1,1.52,10]],"ltp":1.51,"tv":9607.2,"id":2284304}]}]}
{"op":"mcm","clk":"1002970703","pt":1580647460295,"mc":[{"id":"1.168224571","rc":[{"batb":[[0,2.92,11.44],[1,2.56,59.09],[2,1.93,37.93]],"batl":[[0,3.05,11.1],[1,3.4,3.02],[2,1000,0.02]],"ltp":3.25,"tv":5550.49,"id":7797764},{"batb":[[0,1.49,11.01],[1,1.45,494.03],[2,1.43,510.84]],"batl":[[1,1.52,11.01]],"ltp":1.51,"tv":9607.2,"id":2284304}]}]}
{"op":"mcm","clk":"1002970931","pt":1580647461423,"mc":[{"id":"1.168224571","rc":[{"trd":[[2.96,0.01]],"batb":[[0,2.56,59.09],[1,1.93,37.93],[2,1.91,33.39]],"batl":[[0,3.4,3.02],[1,1000,0.02],[2,1000,0]],"ltp":2.96,"tv":5550.5,"id":7797764},{"trd":[[1.51,2.5]],"batb":[[0,1.5,257.39],[1,1.49,269.08],[2,1.45,494.03]],"batl":[[0,1.51,8.74],[1,1.54,781.79],[2,1.55,228]],"ltp":1.51,"tv":9607.22,"id":2284304}],"tv":15157.73}]}
{"op":"mcm","clk":"1002971488","pt":1580647464096,"mc":[{"id":"1.168224571","rc":[{"batb":[[0,1.49,269.08],[1,1.45,494.03],[2,1.43,510.84]],"ltp":1.51,"tv":9607.22,"id":2284304}]}]}
{"op":"mcm","clk":"1002971911","pt":1580647466247,"mc":[{"id":"1.168224571","rc":[{"batb":[[0,1.45,494.03],[1,1.43,510.84],[2,1.42,2.27]],"batl":[[1,1.53,10],[2,1.54,480.59]],"ltp":1.51,"tv":9607.22,"id":2284304}]}]}
{"op":"mcm","clk":"1002972526","pt":1580647468978,"mc":[{"id":"1.168224571","rc":[{"batb":[[0,1.42,2.27],[1,1.41,209.46],[2,1.4,554.79]],"ltp":1.51,"tv":9607.22,"id":2284304}]}]}
{"op":"mcm","clk":"1002973036","pt":1580647471397,"mc":[{"id":"1.168224571","rc":[{"batb":[[0,3.2,12.47],[1,3.05,63.14],[2,2.56,59.09]],"batl":[[1,3.5,293],[2,1000,0.02]],"ltp":2.96,"tv":5550.5,"id":7797764},{"batl":[[0,1.44,304.46],[1,1.45,382.35],[2,1.46,153.04]],"ltp":1.51,"tv":9607.22,"id":2284304}]}]}
{"op":"mcm","clk":"1002973259","pt":1580647472355,"mc":[{"id":"1.168224571","rc":[{"batb":[[0,3.2,94.69],[2,2.78,47.21]],"ltp":2.96,"tv":5550.5,"id":7797764}]}]}
{"op":"mcm","clk":"1002973375","pt":1580647473000,"mc":[{"id":"1.168224571","rc":[{"batb":[[1,3.15,19.32],[2,3.05,63.14]],"batl":[[2,3.55,15.96]],"ltp":2.96,"tv":5550.5,"id":7797764},{"batl":[[2,1.46,195.05]],"ltp":1.51,"tv":9607.22,"id":2284304}]}]}
{"op":"mcm","clk":"1002974026","pt":1580647475970,"mc":[{"id":"1.168224571","rc":[{"batl":[[0,1.43,10],[1,1.44,304.46],[2,1.45,382.35]],"ltp":1.51,"tv":9607.22,"id":2284304}]}]}
{"op":"mcm","clk":"1002976519","pt":1580647488188,"mc":[{"id":"1.168224571","rc":[{"trd":[[1.43,28.51]],"batl":[[0,1.43,7.82]],"ltp":1.43,"tv":9611.58,"id":2284304}],"tv":15162.09}]}
{"op":"mcm","clk":"1002976917","pt":1580647490320,"mc":[{"id":"1.168224571","rc":[{"batl":[[1,3.55,15.96],[2,1000,0.02]],"ltp":2.96,"tv":5550.5,"id":7797764}]}]}
{"op":"mcm","clk":"1002977121","pt":1580647491397,"mc":[{"id":"1.168224571","rc":[{"trd":[[3.4,6.99]],"batb":[[0,3.4,3.03],[2,2.78,47.21]],"batl":[[0,3.55,15.96],[1,1000,0.02],[2,1000,0]],"ltp":3.4,"tv":5557.5,"id":7797764},{"trd":[[1.42,409.52]],"batb":[[0,1.39,601.58],[1,1.37,510.84],[2,1.34,712.57]],"batl":[[1,1.46,522.6],[2,1.48,507.4]],"ltp":1.42,"tv":9613.86,"id":2284304}],"tv":15171.36}]}
{"op":"mcm","clk":"1002977191","pt":1580647491724,"mc":[{"id":"1.168224571","rc":[{"batb":[[1,2.78,47.21],[2,2.02,11.74]],"batl":[[0,1000,0.02],[1,1000,0]],"ltp":3.4,"tv":5557.5,"id":7797764},{"batb":[[0,1.39,494.03]],"batl":[[1,1.46,490.59]],"ltp":1.42,"tv":9613.86,"id":2284304}]}]}
{"op":"mcm","clk":"1002977534","pt":1580647493412,"mc":[{"id":"1.168224571","rc":[{"trd":[[3.4,10.02]],"batb":[[0,2.78,47.21],[1,2.02,11.74],[2,2,75.72]],"ltp":3.4,"tv":5560.53,"id":7797764},{"trd":[[1.42,416.77],[1.43,29.61]],"batl":[[0,1.43,7.27],[1,1.46,480.59]],"ltp":1.43,"tv":9622.21,"id":2284304}],"tv":15182.74}]}
{"op":"mcm","clk":"1002977574","pt":1580647493624,"mc":[{"id":"1.168224571","rc":[{"batb":[[2,1.35,267.81]],"ltp":1.43,"tv":9622.21,"id":2284304}]}]}
{"op":"mcm","clk":"1002977860","pt":1580647495031,"mc":[{"id":"1.168224571","rc":[{"batb":[[0,1.35,267.81],[1,1.34,1149.88],[2,1.23,2]],"ltp":1.43,"tv":9622.21,"id":2284304}]}]}
{"op":"mcm","clk":"1002978232","pt":1580647497091,"mc":[{"id":"1.168224571","rc":[{"batb":[[1,1.34,684.45]],"ltp":1.43,"tv":9622.21,"id":2284304}]}]}
{"op":"mcm","clk":"1002978510","pt":1580647498412,"mc":[{"id":"1.168224571","rc":[{"batb":[[0,3.55,181.95],[1,3.15,84.9],[2,2.78,47.21]],"batl":[[0,3.95,288],[1,1000,0.02]],"ltp":3.4,"tv":5560.53,"id":7797764},{"batb":[[2,1.3,291.67]],"batl":[[0,1.38,437.83],[1,1.39,446.67],[2,1.4,1012.39]],"ltp":1.43,"tv":9622.21,"id":2284304}]}]}
{"op":"mcm","clk":"1002978676","pt":1580647499323,"mc":[{"id":"1.168224571","rc":[{"batb":[[2,2.02,11.74]],"batl":[[0,3.95,301.44]],"ltp":3.4,"tv":5560.53,"id":7797764},{"batb":[[1,1.34,807.96]],"ltp":1.43,"tv":9622.21,"id":2284304}]}]}
{"op":"mcm","clk":"1002979512","pt":1580647503034,"mc":[{"id":"1.168224571","rc":[{"batb":[[1,3.45,16.8],[2,3.15,84.9]],"ltp":3.4,"tv":5560.53,"id":7797764},{"batl":[[0,1.37,10],[1,1.38,437.83],[2,1.39,446.67]],"ltp":1.43,"tv":9622.21,"id":2284304}]}]}
{"op":"mcm","clk":"1002979764","pt":1580647504113,"mc":[{"id":"1.168224571","rc":[{"batb":[[2,1.32,494.03]],"ltp":1.43,"tv":9622.21,"id":2284304}]}]}
{"op":"mcm","clk":"1002980234","pt":1580647506224,"mc":[{"id":"1.168224571","rc":[{"batb":[[2,3.25,10.13]],"batl":[[1,4.1,2],[2,4.3,2.05]],"ltp":3.4,"tv":5560.53,"id":7797764},{"batb":[[2,1.33,58.53]],"ltp":1.43,"tv":9622.21,"id":2284304}]}]}
{"op":"mcm","clk":"1002980497","pt":1580647507308,"mc":[{"id":"1.168224571","rc":[{"batl":[[2,4.2,2.03]],"ltp":3.4,"tv":5560.53,"id":7797764}]}]}
{"op":"mcm","clk":"1002981128","pt":1580647510398,"mc":[{"id":"1.168224571","rc":[{"batb":[[0,3.55,11.39]],"batl":[[0,3.95,13.44],[1,4.2,2.03],[2,4.3,2.05]],"ltp":3.4,"tv":5560.53,"id":7797764},{"batb":[[0,1.34,123.51],[1,1.32,545.67],[2,1.31,60.79]],"batl":[[1,1.39,87.5],[2,1.4,522.6]],"ltp":1.43,"tv":9622.21,"id":2284304}]}]}
{"op":"mcm","clk":"1002981230","pt":1580647510830,"mc":[{"id":"1.168224571","rc":[{"batb":[[0,3.45,16.8],[1,3.25,10.13],[2,3.15,84.9]],"ltp":3.4,"tv":5560.53,"id":7797764},{"batl":[[1,1.4,522.6],[2,1.42,497.4]],"ltp":1.43,"tv":9622.21,"id":2284304}]}]}
{"op":"mcm","clk":"1002981391","pt":1580647511683,"mc":[{"id":"1.168224571","rc":[{"batb":[[0,3.25,10.13],[1,3.15,84.9],[2,3.1,10.14]],"batl":[[0,4.2,2.03],[1,4.3,2.05],[2,4.4,2.04]],"ltp":3.4,"tv":5560.53,"id":7797764},{"batb":[[0,1.32,545.67],[1,1.31,60.79],[2,1.3,865.79]],"batl":[[1,1.4,480.59]],"ltp":1.43,"tv":9622.21,"id":2284304}]}]}
{"op":"mcm","clk":"1002981697","pt":1580647513180,"mc":[{"id":"1.168224571","rc":[{"batb":[[1,1.31,498.86],[2,1.3,1379.84]],"ltp":1.43,"tv":9622.21,"id":2284304}]}]}
{"op":"mcm","clk":"1002981809","pt":1580647513688,"mc":[{"id":"1.168224571","rc":[{"batb":[[1,1.31,60.79],[2,1.3,865.79]],"ltp":1.43,"tv":9622.21,"id":2284304}]}]}
{"op":"mcm","clk":"1002982124","pt":1580647515185,"mc":[{"id":"1.168224571","rc":[{"batl":[[0,1.4,480.59],[1,1.42,497.4],[2,1.44,69.33]],"ltp":1.43,"tv":9622.21,"id":2284304}]}]}
{"op":"mcm","clk":"1002982569","pt":1580647517448,"mc":[{"id":"1.168224571","rc":[{"batb":[[0,1.36,383.52],[1,1.35,422.69],[2,1.32,545.67]],"batl":[[0,1.39,292.29],[1,1.4,829.71],[2,1.42,497.4]],"ltp":1.43,"tv":9622.21,"id":2284304}]}]}
{"op":"mcm","clk":"1002982885","pt":1580647519055,"mc":[{"id":"1.168224571","rc":[{"batl":[[0,1.39,302.29]],"ltp":1.43,"tv":9622.21,"id":2284304}]}]}
{"op":"mcm","clk":"1002983240","pt":1580647520989,"mc":[{"id":"1.168224571","rc":[{"batb":[[0,1.32,545.67],[1,1.31,60.79],[2,1.3,865.79]],"batl":[[0,1.39,10],[1,1.4,480.59]],"ltp":1.43,"tv":9622.21,"id":2284304}]}]}
{"op":"mcm","clk":"1002983808","pt":1580647523872,"mc":[{"id":"1.168224571","rc":[{"batb":[[1,1.31,498.86],[2,1.3,1379.84]],"ltp":1.43,"tv":9622.21,"id":2284304}]}]}
{"op":"mcm","clk":"1002984252","pt":1580647526194,"mc":[{"id":"1.168224571","rc":[{"batl":[[0,1.36,1.2],[1,1.39,10],[2,1.4,480.59]],"ltp":1.43,"tv":9622.21,"id":2284304}]}]}
{"op":"mcm","clk":"1002984392","pt":1580647526873,"mc":[{"id":"1.168224571","rc":[{"trd":[[1.32,6.55]],"batb":[[0,1.32,542.4]],"ltp":1.32,"tv":9628.76,"id":2284304}],"tv":15189.29}]}
{"op":"mcm","clk":"1002984879","pt":1580647529386,"mc":[{"id":"1.168224571","rc":[{"batl":[[0,4.3,2.05],[1,4.4,2.04],[2,1000,0.02]],"ltp":3.4,"tv":5560.53,"id":7797764},{"batb":[[0,1.31,498.86],[1,1.3,869],[2,1.25,505.09]],"batl":[[0,1.39,10],[1,1.4,480.59],[2,1.42,497.4]],"ltp":1.32,"tv":9628.76,"id":2284304}]}]}
{"op":"mcm","clk":"1002985051","pt":1580647530287,"mc":[{"id":"1.168224571","rc":[{"trd":[[3.55,1.78]],"ltp":3.55,"tv":5562.31,"id":7797764},{"trd":[[1.39,1675.72]],"batb":[[2,1.23,2]],"batl":[[0,1.39,5.45]],"ltp":1.39,"tv":9633.31,"id":2284304}],"tv":15195.62}]}
{"op":"mcm","clk":"1002985273","pt":1580647531489,"mc":[{"id":"1.168224571","rc":[{"batl":[[0,4.3,257.05]],"ltp":3.55,"tv":5562.31,"id":7797764},{"batb":[[0,1.31,2216.42]],"batl":[[0,1.34,1679.1],[1,1.35,5171.2],[2,1.36,995]],"ltp":1.39,"tv":9633.31,"id":2284304}]}]}
{"op":"mcm","clk":"1002985479","pt":1580647532488,"mc":[{"id":"1.168224571","rc":[{"batb":[[0,3.85,111.35],[1,3.65,58.62],[2,3.25,10.13]],"ltp":3.55,"tv":5562.31,"id":7797764},{"batb":[[2,1.27,334.95]],"batl":[[0,1.34,2124.68],[1,1.35,498.53]],"ltp":1.39,"tv":9633.31,"id":2284304}]}]}
{"op":"mcm","clk":"1002985675","pt":1580647533456,"mc":[{"id":"1.168224571","rc":[{"batl":[[0,4.3,269.65]],"ltp":3.55,"tv":5562.31,"id":7797764},{"trd":[[1.31,27.72]],"batb":[[0,1.31,2202.56],[1,1.3,1008.48]],"ltp":1.31,"tv":9661.03,"id":2284304}],"tv":15223.34}]}
{"op":"mcm","clk":"1002986047","pt":1580647535389,"mc":[{"id":"1.168224571","rc":[{"trd":[[1.34,3.56]],"batl":[[0,1.34,2122.9]],"ltp":1.34,"tv":9664.59,"id":2284304}],"tv":15226.9}]}
{"op":"mcm","clk":"1002986239","pt":1580647536299,"mc":[{"id":"1.168224571","rc":[{"batl":[[0,1.33,10],[1,1.34,2122.9],[2,1.35,498.53]],"ltp":1.34,"tv":9664.59,"id":2284304}]}]}
{"op":"mcm","clk":"1002986642","pt":1580647538377,"mc":[{"id":"1.168224571","rc":[{"batb":[[1,3.75,15.12],[2,3.65,58.62]],"ltp":3.55,"tv":5562.31,"id":7797764}]}]}
{"op":"mcm","clk":"1002986852","pt":1580647539495,"mc":[{"id":"1.168224571","rc":[{"batb":[[1,3.75,25.35]],"batl":[[2,4.5,2]],"ltp":3.55,"tv":5562.31,"id":7797764},{"batb":[[2,1.29,54.81]],"ltp":1.34,"tv":9664.59,"id":2284304}]}]}
{"op":"mcm","clk":"1002987247","pt":1580647541481,"mc":[{"id":"1.168224571","rc":[{"trd":[[1.31,34.32]],"batb":[[0,1.31,2199.26]],"ltp":1.31,"tv":9671.19,"id":2284304}],"tv":15233.5}]}
{"op":"mcm","clk":"1002987389","pt":1580647542285,"mc":[{"id":"1.168224571","rc":[{"trd":[[1.33,0.18]],"batl":[[0,1.33,9.91]],"ltp":1.33,"tv":9671.37,"id":2284304}],"tv":15233.69}]}
{"op":"mcm","clk":"1002987604","pt":1580647543400,"mc":[{"id":"1.168224571","rc":[{"batl":[[2,1.35,498.7]],"ltp":1.33,"tv":9671.37,"id":2284304}]}]}
{"op":"mcm","clk":"1002987963","pt":1580647545268,"mc":[{"id":"1.168224571","rc":[{"batl":[[0,1.34,2122.9],[1,1.35,498.7],[2,1.36,1122.08]],"ltp":1.33,"tv":9671.37,"id":2284304}]}]}
{"op":"mcm","clk":"1002988944","pt":1580647550289,"mc":[{"id":"1.168224571","rc":[{"batb":[[0,3.75,25.35],[1,3.65,58.62],[2,3.6,10.24]],"batl":[[0,4.3,12.6],[1,4.5,2],[2,4.6,2]],"ltp":3.55,"tv":5562.31,"id":7797764},{"batb":[[0,1.3,139.47],[1,1.29,54.81],[2,1.28,60.66]],"batl":[[0,1.36,127.25],[1,1.37,1.76],[2,1.38,80.75]],"ltp":1.33,"tv":9671.37,"id":2284304}]}]}
{"op":"mcm","clk":"1002989013","pt":1580647550609,"mc":[{"id":"1.168224571","rc":[{"batb":[[0,3.75,15.12]],"ltp":3.55,"tv":5562.31,"id":7797764},{"batl":[[0,1.36,42.18]],"ltp":1.33,"tv":9671.37,"id":2284304}]}]}
{"op":"mcm","clk":"1002989339","pt":1580647552107,"mc":[{"id":"1.168224571","rc":[{"batb":[[0,3.65,58.62],[1,3.6,10.24],[2,3.25,10.13]],"batl":[[0,4.8,2],[1,1000,0.02],[2,4.6,0]],"ltp":3.55,"tv":5562.31,"id":7797764},{"batb":[[0,1.27,401.82],[1,1.23,2],[2,1.22,523]],"batl":[[0,1.37,1.93],[1,1.38,80.75],[2,1.44,69.33]],"ltp":1.33,"tv":9671.37,"id":2284304}]}]}
{"op":"mcm","clk":"1002989477","pt":1580647552796,"mc":[{"id":"1.168224571","rc":[{"batb":[[0,1.28,542.07],[1,1.27,991.13],[2,1.23,2]],"batl":[[0,1.36,377.19],[1,1.37,387.57],[2,1.38,80.75]],"ltp":1.33,"tv":9671.37,"id":2284304}]}]}
{"op":"mcm","clk":"1002989749","pt":1580647554200,"mc":[{"id":"1.168224571","rc":[{"batb":[[0,3.75,10.43],[1,3.65,58.62],[2,3.6,10.24]],"ltp":3.55,"tv":5562.31,"id":7797764},{"batl":[[0,1.36,464.01],[1,1.37,385.81]],"ltp":1.33,"tv":9671.37,"id":2284304}]}]}
{"op":"mcm","clk":"1002989954","pt":1580647555222,"mc":[{"id":"1.168224571","rc":[{"batl":[[0,4.5,2.01],[1,4.8,2],[2,1000,0.02]],"ltp":3.55,"tv":5562.31,"id":7797764},{"batb":[[0,1.29,71.81],[1,1.28,542.07],[2,1.27,991.13]],"ltp":1.33,"tv":9671.37,"id":2284304}]}]}
{"op":"mcm","clk":"1002990063","pt":1580647555718,"mc":[{"id":"1.168224571","rc":[{"batl":[[0,4.8,2],[1,1000,0.02],[2,1000,0]],"ltp":3.55,"tv":5562.31,"id":7797764},{"batb":[[0,1.28,542.07],[1,1.27,991.13],[2,1.23,2]],"ltp":1.33,"tv":9671.37,"id":2284304}]}]}
{"op":"mcm","clk":"1002991411","pt":1580647562425,"mc":[{"id":"1.168224571","rc":[{"batl":[[0,4.5,2.01],[1,4.8,2],[2,1000,0.02]],"ltp":3.55,"tv":5562.31,"id":7797764},{"batb":[[0,1.29,52.81],[1,1.28,542.07],[2,1.27,991.13]],"ltp":1.33,"tv":9671.37,"id":2284304}]}]}
{"op":"mcm","clk":"1002991474","pt":1580647562743,"mc":[{"id":"1.168224571","rc":[{"batl":[[0,4.8,2],[1,1000,0.02],[2,1000,0]],"ltp":3.55,"tv":5562.31,"id":7797764},{"batb":[[0,1.28,542.07],[1,1.27,991.13],[2,1.23,2]],"ltp":1.33,"tv":9671.37,"id":2284304}]}]}
{"op":"mcm","clk":"1002991833","pt":1580647564485,"mc":[{"id":"1.168224571","rc":[{"batl":[[0,1.38,80.92],[1,1.44,69.33],[2,1.47,65.5]],"ltp":1.33,"tv":9671.37,"id":2284304}]}]}
{"op":"mcm","clk":"1002991852","pt":1580647564599,"mc":[{"id":"1.168224571","rc":[{"batb":[[0,3.65,58.62],[1,3.6,10.24],[2,3.25,10.13]],"ltp":3.55,"tv":5562.31,"id":7797764}]}]}
{"op":"mcm","clk":"1002992412","pt":1580647567358,"mc":[{"id":"1.168224571","rc":[{"batb":[[0,4.1,10.44],[1,3.65,58.62],[2,3.6,10.24]],"batl":[[0,4.7,259],[1,4.8,2],[2,1000,0.02]],"ltp":3.55,"tv":5562.31,"id":7797764},{"batb":[[0,1.28,2299.88]],"batl":[[0,1.31,2226.75],[1,1.32,1383.83],[2,1.38,80.92]],"ltp":1.33,"tv":9671.37,"id":2284304}]}]}
{"op":"mcm","clk":"1002992561","pt":1580647568050,"mc":[{"id":"1.168224571","rc":[{"batb":[[0,4.2,83.01],[1,4.1,10.44],[2,3.9,99.3]],"ltp":3.55,"tv":5562.31,"id":7797764},{"batb":[[2,1.23,398.32]],"ltp":1.33,"tv":9671.37,"id":2284304}]}]}
{"op":"mcm","clk":"1002992801","pt":1580647569248,"mc":[{"id":"1.168224571","rc":[{"batb":[[2,3.95,13.44]],"batl":[[0,4.6,10.92],[1,4.7,259],[2,4.8,2]],"ltp":3.55,"tv":5562.31,"id":7797764},{"batl":[[2,1.33,42.01]],"ltp":1.33,"tv":9671.37,"id":2284304}]}]}
{"op":"mcm","clk":"1002993421","pt":1580647574186,"mc":[{"id":"1.168224571","rc":[{"batb":[[2,3.9,99.3]],"ltp":3.55,"tv":5562.31,"id":7797764},{"batb":[[1,1.27,1146.56]],"ltp":1.33,"tv":9671.37,"id":2284304}]}]}
{"op":"mcm","clk":"1002993956","pt":1580647575181,"mc":[{"id":"1.168224571","rc":[{"trd":[[4.6,135.08]],"batb":[[2,4,13.44]],"batl":[[0,4.7,259],[1,4.8,2],[2,1000,0.02]],"ltp":4.6,"tv":5697.39,"id":7797764},{"trd":[[1.28,406.93],[1.31,37.88]],"batb":[[0,1.28,1892.95]],"batl":[[0,1.31,2224.97],[1,1.32,923.86]],"ltp":1.28,"tv":10081.86,"id":2284304}],"tv":15779.25}]}
{"op":"mcm","clk":"1002994226","pt":1580647576452,"mc":[{"id":"1.168224571","rc":[{"trd":[[4.2,34]],"batb":[[0,4.2,66.01]],"ltp":4.2,"tv":5731.39,"id":7797764}],"tv":15813.26}]}
{"op":"mcm","clk":"1002994404","pt":1580647577356,"mc":[{"id":"1.168224571","rc":[{"trd":[[4.2,38]],"batb":[[0,4.2,64.01],[2,4,24.16]],"batl":[[2,4.9,2]],"ltp":4.2,"tv":5735.39,"id":7797764},{"batb":[[2,1.26,71.98]],"batl":[[2,1.33,130.51]],"ltp":1.28,"tv":10081.86,"id":2284304}],"tv":15817.26}]}
{"op":"mcm","clk":"1002994605","pt":1580647578458,"mc":[{"id":"1.168224571","rc":[{"batl":[[0,4.6,10.92],[1,4.7,259],[2,4.8,2]],"ltp":4.2,"tv":5735.39,"id":7797764},{"trd":[[1.31,44.68]],"batb":[[0,1.28,2075.01]],"batl":[[0,1.3,244],[1,1.31,2221.57],[2,1.32,923.86]],"ltp":1.31,"tv":10088.67,"id":2284304}],"tv":15824.06}]}
{"op":"mcm","clk":"1002994782","pt":1580647579457,"mc":[{"id":"1.168224571","rc":[{"batb":[[0,4.1,10.44],[1,4,13.44],[2,3.9,99.3]],"batl":[[1,5.2,2],[2,1000,0.02]],"ltp":4.2,"tv":5735.39,"id":7797764},{"trd":[[1.28,415.33]],"batb":[[0,1.27,155.44],[1,1.24,69.77],[2,1.23,398.32]],"batl":[[0,1.32,97.86],[1,1.33,42.01],[2,1.35,83.27]],"ltp":1.28,"tv":10097.07,"id":2284304}],"tv":15832.46}]}
{"op":"mcm","clk":"1002994938","pt":1580647580268,"mc":[{"id":"1.168224571","rc":[{"batb":[[0,3.9,99.3],[1,3.85,9.77],[2,3.6,10.24]],"batl":[[0,5.2,2],[1,1000,0.02],[2,1000,0]],"ltp":4.2,"tv":5735.39,"id":7797764},{"batb":[[0,1.24,69.77],[1,1.23,398.32],[2,1.22,523]],"batl":[[0,1.35,83.27],[1,1.38,80.75],[2,1.44,69.33]],"ltp":1.28,"tv":10097.07,"id":2284304}]}]}
{"op":"mcm","clk":"1002995405","pt":1580647582476,"mc":[{"id":"1.168224571","rc":[{"batb":[[0,3.85,112.29],[1,3.6,10.24],[2,3.25,10.13]],"batl":[[1,5.4,2],[2,1000,0.02]],"ltp":4.2,"tv":5735.39,"id":7797764},{"batb":[[0,1.24,457.36],[1,1.23,81.63]],"batl":[[0,1.28,20],[1,1.33,504.51],[2,1.34,430.34]],"ltp":1.28,"tv":10097.07,"id":2284304}]}]}
{"op":"mcm","clk":"1002995452","pt":1580647582675,"mc":[{"id":"1.168224571","rc":[{"batb":[[0,4,10.72],[1,3.85,112.29],[2,3.6,10.24]],"ltp":4.2,"tv":5735.39,"id":7797764},{"batl":[[1,1.33,593.01]],"ltp":1.28,"tv":10097.07,"id":2284304}]}]}
{"op":"mcm","clk":"1002995814","pt":1580647584482,"mc":[{"id":"1.168224571","rc":[{"trd":[[4.5,5.69]],"batl":[[0,4.3,1641.71],[1,4.4,269],[2,4.5,461.42]],"ltp":4.5,"tv":5741.08,"id":7797764},{"trd":[[1.28,435.33]],"batb":[[0,1.28,1425.47],[1,1.24,457.36],[2,1.23,81.63]],"batl":[[0,1.33,593.01],[1,1.34,430.34],[2,1.35,1044.27]],"ltp":1.28,"tv":10117.07,"id":2284304}],"tv":15858.15}]}
{"op":"mcm","clk":"1002995986","pt":1580647585393,"mc":[{"id":"1.168224571","rc":[{"batb":[[2,3.6,70.9]],"batl":[[0,4.4,269],[1,4.5,46.14],[2,5.2,2]],"ltp":4.5,"tv":5741.08,"id":7797764},{"batb":[[0,1.3,727.8],[1,1.29,542],[2,1.28,142.55]],"ltp":1.28,"tv":10117.07,"id":2284304}]}]}
{"op":"mcm","clk":"1002996178","pt":1580647586367,"mc":[{"id":"1.168224571","rc":[{"batl":[[0,4.4,286.42]],"ltp":4.5,"tv":5741.08,"id":7797764},{"trd":[[1.3,20.24]],"batb":[[0,1.3,717.68],[1,1.29,595.84]],"ltp":1.3,"tv":10137.3,"id":2284304}],"tv":15878.38}]}
{"op":"mcm","clk":"1002996320","pt":1580647587093,"mc":[{"id":"1.168224571","rc":[{"batb":[[1,3.85,126.58]],"batl":[[0,4.4,269]],"ltp":4.5,"tv":5741.08,"id":7797764},{"batb":[[1,1.29,610.76]],"batl":[[2,1.35,1086.28]],"ltp":1.3,"tv":10137.3,"id":2284304}]}]}
{"op":"mcm","clk":"1002996561","pt":1580647588465,"mc":[{"id":"1.168224571","rc":[{"batb":[[0,3.85,126.58],[1,3.6,70.9],[2,3.25,10.13]],"batl":[[0,4.4,280.76]],"ltp":4.5,"tv":5741.08,"id":7797764},{"batb":[[1,1.29,714.41]],"batl":[[0,1.32,10],[1,1.33,504.51],[2,1.34,430.34]],"ltp":1.3,"tv":10137.3,"id":2284304}]}]}
{"op":"mcm","clk":"1002996721","pt":1580647589156,"mc":[{"id":"1.168224571","rc":[{"batb":[[1,1.29,686.51]],"ltp":1.3,"tv":10137.3,"id":2284304}]}]}
{"op":"mcm","clk":"1002997174","pt":1580647591491,"mc":[{"id":"1.168224571","rc":[{"batb":[[1,3.7,10.12],[2,3.6,70.9]],"batl":[[2,4.8,2.02]],"ltp":4.5,"tv":5741.08,"id":7797764},{"batb":[[2,1.28,636.58]],"ltp":1.3,"tv":10137.3,"id":2284304}]}]}
{"op":"mcm","clk":"1002997785","pt":1580647594482,"mc":[{"id":"1.168224571","rc":[{"batb":[[0,3.85,24.05]],"batl":[[0,4.4,11.76],[1,4.8,2.02],[2,5,2]],"ltp":4.5,"tv":5741.08,"id":7797764},{"batb":[[0,1.29,144.51],[1,1.28,494.03],[2,1.27,405.81]],"batl":[[1,1.35,605.87],[2,1.37,578.9]],"ltp":1.3,"tv":10137.3,"id":2284304}]}]}
{"op":"mcm","clk":"1002998129","pt":1580647596212,"mc":[{"id":"1.168224571","rc":[{"batb":[[0,3.85,9.77]],"batl":[[0,4.8,2.02],[1,5,2],[2,5.2,2]],"ltp":4.5,"tv":5741.08,"id":7797764},{"trd":[[1.32,26.33]],"batb":[[0,1.28,494.03],[1,1.27,405.81],[2,1.26,510.84]],"batl":[[0,1.35,563.97],[1,1.37,578.9],[2,1.38,80.75]],"ltp":1.32,"tv":10157.08,"id":2284304}],"tv":15898.16}]}
{"op":"mcm","clk":"1002998310","pt":1580647597218,"mc":[{"id":"1.168224571","rc":[{"batb":[[1,1.27,763.09],[2,1.26,1128.86]],"batl":[[0,1.35,870.15],[1,1.36,403.49],[2,1.37,578.9]],"ltp":1.32,"tv":10157.08,"id":2284304}]}]}
{"op":"mcm","clk":"1002998478","pt":1580647598112,"mc":[{"id":"1.168224571","rc":[{"batb":[[2,3.6,70.43]],"ltp":4.5,"tv":5741.08,"id":7797764},{"batb":[[1,1.27,425.15],[2,1.26,1469]],"ltp":1.32,"tv":10157.08,"id":2284304}]}]}
{"op":"mcm","clk":"1002999107","pt":1580647601293,"mc":[{"id":"1.168224571","rc":[{"batb":[[1,1.27,67.87],[2,1.26,850.98]],"batl":[[0,1.35,389.56],[2,1.37,81.5]],"ltp":1.32,"tv":10157.08,"id":2284304}]}]}
{"op":"mcm","clk":"1002999597","pt":1580647603699,"mc":[{"id":"1.168224571","rc":[{"batl":[[0,4.2,389],[1,4.8,2.02],[2,5,2]],"ltp":4.5,"tv":5741.08,"id":7797764},{"trd":[[1.32,26.55]],"batb":[[0,1.32,2255.23],[1,1.31,500.72],[2,1.28,494.03]],"batl":[[0,1.35,2056.12]],"ltp":1.32,"tv":10157.3,"id":2284304}],"tv":15898.38}]}
{"op":"mcm","clk":"1002999926","pt":1580647605403,"mc":[{"id":"1.168224571","rc":[{"batb":[[1,3.7,25.24]],"batl":[[1,4.3,12.6],[2,4.8,2.02]],"ltp":4.5,"tv":5741.08,"id":7797764},{"batb":[[0,1.34,254.46],[1,1.32,2255.23],[2,1.31,635.99]],"batl":[[2,1.37,123.51]],"ltp":1.32,"tv":10157.3,"id":2284304}]}]}
{"op":"mcm","clk":"1002999990","pt":1580647605813,"mc":[{"id":"1.168224571","rc":[{"trd":[[3.85,2.62]],"batb":[[0,3.85,8.46]],"ltp":3.85,"tv":5743.7,"id":7797764}],"tv":15901.01}]}
{"op":"mcm","clk":"1003000248","pt":1580647607209,"mc":[{"id":"1.168224571","rc":[{"batb":[[0,3.7,25.24],[1,3.6,70.43],[2,3.4,70.03]],"ltp":3.85,"tv":5743.7,"id":7797764},{"batl":[[0,1.35,1973.02]],"ltp":1.32,"tv":10157.3,"id":2284304}]}]}
{"op":"mcm","clk":"1003000882","pt":1580647610425,"mc":[{"id":"1.168224571","rc":[{"batb":[[1,1.32,2749.26]],"ltp":1.32,"tv":10157.3,"id":2284304}]}]}
{"op":"mcm","clk":"1003001029","pt":1580647611121,"mc":[{"id":"1.168224571","rc":[{"batb":[[0,3.75,10.63],[1,3.7,25.24],[2,3.6,70.43]],"batl":[[0,4.2,391.03],[1,4.3,14.65]],"ltp":3.85,"tv":5743.7,"id":7797764},{"trd":[[1.35,34.55]],"batb":[[1,1.32,2804.65],[2,1.31,694.78]],"batl":[[0,1.35,1955.74],[1,1.36,492.06]],"ltp":1.35,"tv":10191.85,"id":2284304}],"tv":15935.55}]}
{"op":"mcm","clk":"1003001367","pt":1580647612940,"mc":[{"id":"1.168224571","rc":[{"trd":[[1.34,6.92]],"batb":[[0,1.34,252.78]],"ltp":1.34,"tv":10195.21,"id":2284304}],"tv":15938.91}]}
{"op":"mcm","clk":"1003001647","pt":1580647614210,"mc":[{"id":"1.168224571","rc":[{"trd":[[1.35,69.09]],"batb":[[1,1.33,8.44],[2,1.32,2804.65]],"batl":[[0,1.35,1938.47]],"ltp":1.35,"tv":10229.75,"id":2284304}],"tv":15973.45}]}
{"op":"mcm","clk":"1003002094","pt":1580647616398,"mc":[{"id":"1.168224571","rc":[{"batl":[[0,4.2,2.03]],"ltp":3.85,"tv":5743.7,"id":7797764},{"batb":[[2,1.32,2253.86]],"batl":[[0,1.35,1666.67],[1,1.36,88.57]],"ltp":1.35,"tv":10229.75,"id":2284304}]}]}
{"op":"mcm","clk":"1003002172","pt":1580647616825,"mc":[{"id":"1.168224571","rc":[{"batb":[[0,3.7,25.24],[1,3.6,10.24],[2,3.4,70.03]],"ltp":3.85,"tv":5743.7,"id":7797764},{"batb":[[0,1.33,8.44],[1,1.32,549.42],[2,1.31,194.06]],"batl":[[0,1.37,126.51],[1,1.38,561.34],[2,1.4,497.4]],"ltp":1.35,"tv":10229.75,"id":2284304}]}]}
{"op":"mcm","clk":"1003002503","pt":1580647618320,"mc":[{"id":"1.168224571","rc":[{"batb":[[0,3.7,10.12]],"batl":[[1,4.3,2.05]],"ltp":3.85,"tv":5743.7,"id":7797764},{"trd":[[1.34,11.29]],"batb":[[2,1.31,58.79]],"batl":[[0,1.37,84.5]],"ltp":1.34,"tv":10234.12,"id":2284304}],"tv":15977.82}]}
{"op":"mcm","clk":"1003002772","pt":1580647619491,"mc":[{"id":"1.168224571","rc":[{"batb":[[1,3.4,70.03],[2,3.25,10.13]],"ltp":3.85,"tv":5743.7,"id":7797764},{"batl":[[0,1.37,313.47],[1,1.38,377.54],[2,1.44,69.33]],"ltp":1.34,"tv":10234.12,"id":2284304}]}]}
{"op":"mcm","clk":"1003002917","pt":1580647620223,"mc":[{"id":"1.168224571","rc":[{"batl":[[0,1.37,310.47]],"ltp":1.34,"tv":10234.12,"id":2284304}]}]}
{"op":"mcm","clk":"1003003572","pt":1580647623472,"mc":[{"id":"1.168224571","rc":[{"batb":[[1,3.65,15.12],[2,3.4,70.03]],"batl":[[0,3.85,193.85],[1,3.95,322],[2,4.2,14.63]],"ltp":3.85,"tv":5743.7,"id":7797764},{"trd":[[1.37,455.24]],"batb":[[0,1.34,795.85],[1,1.33,628.61],[2,1.32,549.42]],"batl":[[0,1.38,419.55],[1,1.4,786]],"ltp":1.37,"tv":10689.35,"id":2284304}],"tv":16433.06}]}
{"op":"mcm","clk":"1003004037","pt":1580647625434,"mc":[{"id":"1.168224571","rc":[{"batb":[[1,3.4,70.03],[2,3.25,87.4]],"batl":[[2,4.2,2.03]],"ltp":3.85,"tv":5743.7,"id":7797764}]}]}
{"op":"mcm","clk":"1003004141","pt":1580647625931,"mc":[{"id":"1.168224571","rc":[{"batb":[[0,1.34,878.58]],"batl":[[0,1.38,566.7],[1,1.39,360.96],[2,1.4,786]],"ltp":1.37,"tv":10689.35,"id":2284304}]}]}
{"op":"mcm","clk":"1003004414","pt":1580647627139,"mc":[{"id":"1.168224571","rc":[{"batb":[[2,1.32,55.39]],"ltp":1.37,"tv":10689.35,"id":2284304}]}]}
{"op":"mcm","clk":"1003004692","pt":1580647628453,"mc":[{"id":"1.168224571","rc":[{"batb":[[1,3.6,21],[2,3.55,5.19]],"batl":[[1,3.95,324.3],[2,4.1,15.44]],"ltp":3.85,"tv":5743.7,"id":7797764},{"batb":[[0,1.34,925.8],[1,1.33,1174.18],[2,1.32,186.46]],"batl":[[0,1.38,610.95],[1,1.39,401.46]],"ltp":1.37,"tv":10689.35,"id":2284304}]}]}
{"op":"mcm","clk":"1003004841","pt":1580647629182,"mc":[{"id":"1.168224571","rc":[{"trd":[[3.7,19.9]],"batb":[[0,3.6,21.17],[1,3.55,5.19],[2,3.4,70.03]],"ltp":3.7,"tv":5763.6,"id":7797764}],"tv":16452.96}]}
{"op":"mcm","clk":"1003005226","pt":1580647631163,"mc":[{"id":"1.168224571","rc":[{"batb":[[1,1.33,1165.73]],"batl":[[0,1.37,3],[1,1.38,610.95],[2,1.39,401.46]],"ltp":1.37,"tv":10689.35,"id":2284304}]}]}
{"op":"mcm","clk":"1003005497","pt":1580647632439,"mc":[{"id":"1.168224571","rc":[{"batl":[[1,3.95,2.3]],"ltp":3.7,"tv":5763.6,"id":7797764},{"batb":[[0,1.34,301.44],[1,1.33,703.3]],"batl":[[0,1.38,86.26],[1,1.39,401.46],[2,1.41,480.59]],"ltp":1.37,"tv":10689.35,"id":2284304}]}]}
{"op":"mcm","clk":"1003005653","pt":1580647633054,"mc":[{"id":"1.168224571","rc":[{"batb":[[0,3.75,6.72],[1,3.6,21],[2,3.55,5.19]],"batl":[[0,3.95,2.3],[1,4.1,15.44],[2,4.2,2.03]],"ltp":3.7,"tv":5763.6,"id":7797764},{"batb":[[1,1.33,545.56]],"ltp":1.37,"tv":10689.35,"id":2284304}]}]}
{"op":"mcm","clk":"1003005958","pt":1580647634342,"mc":[{"id":"1.168224571","rc":[{"trd":[[3.75,3.08]],"batb":[[0,3.75,3.64],[1,3.6,5.04]],"batl":[[1,4.1,2]],"ltp":3.75,"tv":5766.68,"id":7797764},{"trd":[[1.37,463.68]],"batb":[[2,1.32,55.39]],"batl":[[0,1.38,44.25]],"ltp":1.37,"tv":10697.8,"id":2284304}],"tv":16464.48}]}
{"op":"mcm","clk":"1003006190","pt":1580647635454,"mc":[{"id":"1.168224571","rc":[{"trd":[[3.75,4.09]],"batb":[[0,3.75,2.63]],"ltp":3.75,"tv":5767.69,"id":7797764},{"trd":[[1.37,466.45]],"batb":[[2,1.32,699.74]],"batl":[[2,1.4,351.09]],"ltp":1.37,"tv":10700.57,"id":2284304}],"tv":16468.26}]}
{"op":"mcm","clk":"1003006352","pt":1580647636261,"mc":[{"id":"1.168224571","rc":[{"batl":[[0,4.1,2],[1,4.2,2.03],[2,4.3,2.05]],"ltp":3.75,"tv":5767.69,"id":7797764},{"batb":[[0,1.33,545.56],[1,1.32,964.58],[2,1.31,1070.36]],"ltp":1.37,"tv":10700.57,"id":2284304}]}]}
{"op":"mcm","clk":"1003006587","pt":1580647637547,"mc":[{"id":"1.168224571","rc":[{"batb":[[0,1.35,289.87],[1,1.33,545.56],[2,1.32,964.58]],"ltp":1.37,"tv":10700.57,"id":2284304}]}]}
{"op":"mcm","clk":"1003006944","pt":1580647639445,"mc":[{"id":"1.168224571","rc":[{"batl":[[0,3.95,2.1],[1,4.1,2],[2,4.2,2.03]],"ltp":3.75,"tv":5767.69,"id":7797764},{"batb":[[1,1.34,50.72],[2,1.33,545.56]],"ltp":1.37,"tv":10700.57,"id":2284304}]}]}
{"op":"mcm","clk":"1003007306","pt":1580647641360,"mc":[{"id":"1.168224571","rc":[{"batl":[[2,1000,0.02]],"ltp":3.75,"tv":5767.69,"id":7797764},{"batb":[[1,1.34,340.59]],"ltp":1.37,"tv":10700.57,"id":2284304}]}]}
{"op":"mcm","clk":"1003007526","pt":1580647642457,"mc":[{"id":"1.168224571","rc":[{"trd":[[1.35,69.76]],"batb":[[0,1.35,289.53]],"ltp":1.35,"tv":10701.24,"id":2284304}],"tv":16468.93}]}
{"op":"mcm","clk":"1003007946","pt":1580647644440,"mc":[{"id":"1.168224571","rc":[{"trd":[[3.75,9.1]],"batb":[[0,3.6,5.04],[1,3.55,5.19],[2,3.4,73.1]],"batl":[[0,3.8,311],[1,3.95,2.1],[2,4.1,2]],"ltp":3.75,"tv":5772.7,"id":7797764},{"trd":[[1.37,467.14]],"batb":[[0,1.37,219.62],[1,1.36,499.61],[2,1.35,715.12]],"ltp":1.37,"tv":10701.93,"id":2284304}],"tv":16474.63}]}
