{"op":"mcm","clk":"998156264","pt":1580585282814,"mc":[{"id":"1.168224578","marketDefinition":{"bspMarket":false,"turnInPlayEnabled":true,"persistenceEnabled":true,"marketBaseRate":5.0,"eventId":"29681732","eventTypeId":"2","numberOfWinners":1,"bettingType":"ODDS","marketType":"SET_WINNER","marketTime":"2020-02-02T09:00:00.000Z","suspendTime":"2020-02-02T09:00:00.000Z","bspReconciled":false,"complete":true,"inPlay":false,"crossMatching":false,"runnersVoidable":false,"numberOfActiveRunners":2,"betDelay":0,"status":"OPEN","runners":[{"status":"ACTIVE","sortPriority":1,"id":2284304,"name":"Sergiy Stakhovsky"},{"status":"ACTIVE","sortPriority":2,"id":7797764,"name":"Alexey Vatutin"}],"regulators":["MR_INT"],"countryCode":"FR","discountAllowed":false,"timezone":"UTC","openDate":"2020-02-02T09:00:00.000Z","version":3147099378,"name":"Set 1 Winner","eventName":"Stakhovsky v Vatutin"},"rc":[{"batb":[[0,1.01,20]],"ltp":0.0,"tv":0.0,"id":7797764},{"batb":[[0,1.01,20]],"ltp":0.0,"tv":0.0,"id":2284304}]}]}
{"op":"mcm","clk":"998156387","pt":1580585283539,"mc":[{"id":"1.168224578","marketDefinition":{"bspMarket":false,"turnInPlayEnabled":true,"persistenceEnabled":true,"marketBaseRate":5.0,"eventId":"29681732","eventTypeId":"2","numberOfWinners":1,"bettingType":"ODDS","marketType":"SET_WINNER","marketTime":"2020-02-02T09:00:00.000Z","suspendTime":"2020-02-02T09:00:00.000Z","bspReconciled":false,"complete":true,"inPlay":false,"crossMatching":false,"runnersVoidable":false,"numberOfActiveRunners":2,"betDelay":0,"status":"OPEN","runners":[{"status":"ACTIVE","sortPriority":1,"id":2284304,"name":"Sergiy Stakhovsky"},{"status":"ACTIVE","sortPriority":2,"id":7797764,"name":"Alexey Vatutin"}],"regulators":["MR_INT"],"countryCode":"FR","discountAllowed":true,"timezone":"UTC","openDate":"2020-02-02T09:00:00.000Z","version":3147099378,"name":"Set 1 Winner","eventName":"Stakhovsky v Vatutin"}}]}
{"op":"mcm","clk":"998179115","pt":1580585420309,"mc":[{"id":"1.168224578","rc":[{"batb":[[0,1.01,15]],"ltp":0.0,"tv":0.0,"id":7797764},{"batb":[[0,1.01,15]],"ltp":0.0,"tv":0.0,"id":2284304}]}]}
{"op":"mcm","clk":"998196992","pt":1580585517440,"mc":[{"id":"1.168224578","marketDefinition":{"bspMarket":false,"turnInPlayEnabled":true,"persistenceEnabled":true,"marketBaseRate":5.0,"eventId":"29681732","eventTypeId":"2","numberOfWinners":1,"bettingType":"ODDS","marketType":"SET_WINNER","marketTime":"2020-02-02T13:30:00.000Z","suspendTime":"2020-02-02T13:30:00.000Z","bspReconciled":false,"complete":true,"inPlay":false,"crossMatching":false,"runnersVoidable":false,"numberOfActiveRunners":2,"betDelay":0,"status":"OPEN","runners":[{"status":"ACTIVE","sortPriority":1,"id":2284304,"name":"Sergiy Stakhovsky"},{"status":"ACTIVE","sortPriority":2,"id":7797764,"name":"Alexey Vatutin"}],"regulators":["MR_INT"],"countryCode":"FR","discountAllowed":true,"timezone":"UTC","openDate":"2020-02-02T09:00:00.000Z","version":3147125175,"name":"Set 1 Winner","eventName":"Stakhovsky v Vatutin"}}]}
{"op":"mcm","clk":"998197631","pt":1580585520453,"mc":[{"id":"1.168224578","marketDefinition":{"bspMarket":false,"turnInPlayEnabled":true,"persistenceEnabled":true,"marketBaseRate":5.0,"eventId":"29681732","eventTypeId":"2","numberOfWinners":1,"bettingType":"ODDS","marketType":"SET_WINNER","marketTime":"2020-02-02T13:30:00.000Z","suspendTime":"2020-02-02T13:30:00.000Z","bspReconciled":false,"complete":true,"inPlay":false,"crossMatching":false,"runnersVoidable":false,"numberOfActiveRunners":2,"betDelay":0,"status":"OPEN","runners":[{"status":"ACTIVE","sortPriority":1,"id":2284304,"name":"Sergiy Stakhovsky"},{"status":"ACTIVE","sortPriority":2,"id":7797764,"name":"Alexey Vatutin"}],"regulators":["MR_INT"],"countryCode":"FR","discountAllowed":true,"timezone":"UTC","openDate":"2020-02-02T13:30:00.000Z","version":3147125175,"name":"Set 1 Winner","eventName":"Stakhovsky v Vatutin"}}]}
{"op":"mcm","clk":"999887494","pt":1580602190419,"mc":[{"id":"1.168224578","rc":[{"batb":[[0,1.01,15.51]],"ltp":0.0,"tv":0.0,"id":7797764},{"batb":[[0,1.01,15.51]],"ltp":0.0,"tv":0.0,"id":2284304}]}]}
{"op":"mcm","clk":"999983457","pt":1580603729397,"mc":[{"id":"1.168224578","rc":[{"batb":[[0,1.01,18.04]],"ltp":0.0,"tv":0.0,"id":7797764},{"batb":[[0,1.01,18.04]],"ltp":0.0,"tv":0.0,"id":2284304}]}]}
{"op":"mcm","clk":"999983515","pt":1580603730486,"mc":[{"id":"1.168224578","rc":[{"batb":[[0,1.01,15.51]],"ltp":0.0,"tv":0.0,"id":7797764},{"batb":[[0,1.01,15.51]],"ltp":0.0,"tv":0.0,"id":2284304}]}]}
{"op":"mcm","clk":"999983519","pt":1580603730591,"mc":[{"id":"1.168224578","rc":[{"batb":[[0,1.01,16.01]],"ltp":0.0,"tv":0.0,"id":7797764},{"batb":[[0,1.01,16.01]],"ltp":0.0,"tv":0.0,"id":2284304}]}]}
{"op":"mcm","clk":"1001426134","pt":1580635614335,"mc":[{"id":"1.168224578","marketDefinition":{"bspMarket":false,"turnInPlayEnabled":true,"persistenceEnabled":true,"marketBaseRate":5.0,"eventId":"29681732","eventTypeId":"2","numberOfWinners":1,"bettingType":"ODDS","marketType":"SET_WINNER","marketTime":"2020-02-02T13:24:00.000Z","suspendTime":"2020-02-02T13:24:00.000Z","bspReconciled":false,"complete":true,"inPlay":false,"crossMatching":false,"runnersVoidable":false,"numberOfActiveRunners":2,"betDelay":0,"status":"OPEN","runners":[{"status":"ACTIVE","sortPriority":1,"id":2284304,"name":"Sergiy Stakhovsky"},{"status":"ACTIVE","sortPriority":2,"id":7797764,"name":"Alexey Vatutin"}],"regulators":["MR_INT"],"countryCode":"FR","discountAllowed":true,"timezone":"UTC","openDate":"2020-02-02T13:30:00.000Z","version":3148345547,"name":"Set 1 Winner","eventName":"Stakhovsky v Vatutin"}}]}
{"op":"mcm","clk":"1001426516","pt":1580635617339,"mc":[{"id":"1.168224578","marketDefinition":{"bspMarket":false,"turnInPlayEnabled":true,"persistenceEnabled":true,"marketBaseRate":5.0,"eventId":"29681732","eventTypeId":"2","numberOfWinners":1,"bettingType":"ODDS","marketType":"SET_WINNER","marketTime":"2020-02-02T13:24:00.000Z","suspendTime":"2020-02-02T13:24:00.000Z","bspReconciled":false,"complete":true,"inPlay":false,"crossMatching":false,"runnersVoidable":false,"numberOfActiveRunners":2,"betDelay":0,"status":"OPEN","runners":[{"status":"ACTIVE","sortPriority":1,"id":2284304,"name":"Sergiy Stakhovsky"},{"status":"ACTIVE","sortPriority":2,"id":7797764,"name":"Alexey Vatutin"}],"regulators":["MR_INT"],"countryCode":"FR","discountAllowed":true,"timezone":"UTC","openDate":"2020-02-02T13:24:00.000Z","version":3148345547,"name":"Set 1 Winner","eventName":"Stakhovsky v Vatutin"}}]}
{"op":"mcm","clk":"1001816438","pt":1580640415425,"mc":[{"id":"1.168224578","marketDefinition":{"bspMarket":false,"turnInPlayEnabled":true,"persistenceEnabled":true,"marketBaseRate":5.0,"eventId":"29681732","eventTypeId":"2","numberOfWinners":1,"bettingType":"ODDS","marketType":"SET_WINNER","marketTime":"2020-02-02T12:51:00.000Z","suspendTime":"2020-02-02T12:51:00.000Z","bspReconciled":false,"complete":true,"inPlay":false,"crossMatching":false,"runnersVoidable":false,"numberOfActiveRunners":2,"betDelay":0,"status":"OPEN","runners":[{"status":"ACTIVE","sortPriority":1,"id":2284304,"name":"Sergiy Stakhovsky"},{"status":"ACTIVE","sortPriority":2,"id":7797764,"name":"Alexey Vatutin"}],"regulators":["MR_INT"],"countryCode":"FR","discountAllowed":true,"timezone":"UTC","openDate":"2020-02-02T13:24:00.000Z","version":3148438475,"name":"Set 1 Winner","eventName":"Stakhovsky v Vatutin"}}]}
{"op":"mcm","clk":"1001817075","pt":1580640420557,"mc":[{"id":"1.168224578","marketDefinition":{"bspMarket":false,"turnInPlayEnabled":true,"persistenceEnabled":true,"marketBaseRate":5.0,"eventId":"29681732","eventTypeId":"2","numberOfWinners":1,"bettingType":"ODDS","marketType":"SET_WINNER","marketTime":"2020-02-02T12:51:00.000Z","suspendTime":"2020-02-02T12:51:00.000Z","bspReconciled":false,"complete":true,"inPlay":false,"crossMatching":false,"runnersVoidable":false,"numberOfActiveRunners":2,"betDelay":0,"status":"OPEN","runners":[{"status":"ACTIVE","sortPriority":1,"id":2284304,"name":"Sergiy Stakhovsky"},{"status":"ACTIVE","sortPriority":2,"id":7797764,"name":"Alexey Vatutin"}],"regulators":["MR_INT"],"countryCode":"FR","discountAllowed":true,"timezone":"UTC","openDate":"2020-02-02T12:51:00.000Z","version":3148438475,"name":"Set 1 Winner","eventName":"Stakhovsky v Vatutin"}}]}
{"op":"mcm","clk":"1001853014","pt":1580640715139,"mc":[{"id":"1.168224578","marketDefinition":{"bspMarket":false,"turnInPlayEnabled":true,"persistenceEnabled":true,"marketBaseRate":5.0,"eventId":"29681732","eventTypeId":"2","numberOfWinners":1,"bettingType":"ODDS","marketType":"SET_WINNER","marketTime":"2020-02-02T12:48:00.000Z","suspendTime":"2020-02-02T12:48:00.000Z","bspReconciled":false,"complete":true,"inPlay":false,"crossMatching":false,"runnersVoidable":false,"numberOfActiveRunners":2,"betDelay":0,"status":"OPEN","runners":[{"status":"ACTIVE","sortPriority":1,"id":2284304,"name":"Sergiy Stakhovsky"},{"status":"ACTIVE","sortPriority":2,"id":7797764,"name":"Alexey Vatutin"}],"regulators":["MR_INT"],"countryCode":"FR","discountAllowed":true,"timezone":"UTC","openDate":"2020-02-02T12:51:00.000Z","version":3148443735,"name":"Set 1 Winner","eventName":"Stakhovsky v Vatutin"}}]}
{"op":"mcm","clk":"1001853277","pt":1580640717181,"mc":[{"id":"1.168224578","marketDefinition":{"bspMarket":false,"turnInPlayEnabled":true,"persistenceEnabled":true,"marketBaseRate":5.0,"eventId":"29681732","eventTypeId":"2","numberOfWinners":1,"bettingType":"ODDS","marketType":"SET_WINNER","marketTime":"2020-02-02T12:48:00.000Z","suspendTime":"2020-02-02T12:48:00.000Z","bspReconciled":false,"complete":true,"inPlay":false,"crossMatching":false,"runnersVoidable":false,"numberOfActiveRunners":2,"betDelay":0,"status":"OPEN","runners":[{"status":"ACTIVE","sortPriority":1,"id":2284304,"name":"Sergiy Stakhovsky"},{"status":"ACTIVE","sortPriority":2,"id":7797764,"name":"Alexey Vatutin"}],"regulators":["MR_INT"],"countryCode":"FR","discountAllowed":true,"timezone":"UTC","openDate":"2020-02-02T12:48:00.000Z","version":3148443735,"name":"Set 1 Winner","eventName":"Stakhovsky v Vatutin"}}]}
{"op":"mcm","clk":"1002676463","pt":1580645815895,"mc":[{"id":"1.168224578","marketDefinition":{"bspMarket":false,"turnInPlayEnabled":true,"persistenceEnabled":true,"marketBaseRate":5.0,"eventId":"29681732","eventTypeId":"2","numberOfWinners":1,"bettingType":"ODDS","marketType":"SET_WINNER","marketTime":"2020-02-02T12:16:00.000Z","suspendTime":"2020-02-02T12:16:00.000Z","bspReconciled":false,"complete":true,"inPlay":false,"crossMatching":false,"runnersVoidable":false,"numberOfActiveRunners":2,"betDelay":0,"status":"OPEN","runners":[{"status":"ACTIVE","sortPriority":1,"id":2284304,"name":"Sergiy Stakhovsky"},{"status":"ACTIVE","sortPriority":2,"id":7797764,"name":"Alexey Vatutin"}],"regulators":["MR_INT"],"countryCode":"FR","discountAllowed":true,"timezone":"UTC","openDate":"2020-02-02T12:48:00.000Z","version":3148684857,"name":"Set 1 Winner","eventName":"Stakhovsky v Vatutin"}}]}
{"op":"mcm","clk":"1002676963","pt":1580645818903,"mc":[{"id":"1.168224578","marketDefinition":{"bspMarket":false,"turnInPlayEnabled":true,"persistenceEnabled":true,"marketBaseRate":5.0,"eventId":"29681732","eventTypeId":"2","numberOfWinners":1,"bettingType":"ODDS","marketType":"SET_WINNER","marketTime":"2020-02-02T12:16:00.000Z","suspendTime":"2020-02-02T12:16:00.000Z","bspReconciled":false,"complete":true,"inPlay":false,"crossMatching":false,"runnersVoidable":false,"numberOfActiveRunners":2,"betDelay":0,"status":"OPEN","runners":[{"status":"ACTIVE","sortPriority":1,"id":2284304,"name":"Sergiy Stakhovsky"},{"status":"ACTIVE","sortPriority":2,"id":7797764,"name":"Alexey Vatutin"}],"regulators":["MR_INT"],"countryCode":"FR","discountAllowed":true,"timezone":"UTC","openDate":"2020-02-02T12:16:00.000Z","version":3148684857,"name":"Set 1 Winner","eventName":"Stakhovsky v Vatutin"}}]}
{"op":"mcm","clk":"1002680995","pt":1580645843375,"mc":[{"id":"1.168224578","rc":[{"batb":[[0,2.06,25.57],[1,1.01,16.01]],"ltp":0.0,"tv":0.0,"id":7797764},{"batb":[[0,1.82,18.88],[1,1.01,16.01]],"ltp":0.0,"tv":0.0,"id":2284304}]}]}
{"op":"mcm","clk":"1002730090","pt":1580646163088,"mc":[{"id":"1.168224578","rc":[{"batb":[[0,2.06,25.34]],"ltp":0.0,"tv":0.0,"id":7797764}]}]}
{"op":"mcm","clk":"1002731680","pt":1580646173193,"mc":[{"id":"1.168224578","rc":[{"batb":[[0,2.08,25.1]],"ltp":0.0,"tv":0.0,"id":7797764},{"batb":[[0,1.81,19.2]],"ltp":0.0,"tv":0.0,"id":2284304}]}]}
{"op":"mcm","clk":"1002742247","pt":1580646240381,"mc":[{"id":"1.168224578","rc":[{"batb":[[0,2.08,24.86]],"ltp":0.0,"tv":0.0,"id":7797764}]}]}
{"op":"mcm","clk":"1002746145","pt":1580646264879,"mc":[{"id":"1.168224578","rc":[{"batb":[[0,2.08,24.63]],"ltp":0.0,"tv":0.0,"id":7797764},{"batb":[[0,1.8,19.59]],"ltp":0.0,"tv":0.0,"id":2284304}]}]}
{"op":"mcm","clk":"1002749748","pt":1580646288005,"mc":[{"id":"1.168224578","rc":[{"batb":[[1,2.06,39.49],[2,1.01,16.01]],"batl":[[0,2.3,31.93]],"ltp":0.0,"tv":0.0,"id":7797764},{"batb":[[1,1.78,53.77],[2,1.01,16.01]],"batl":[[0,1.96,42.01]],"ltp":0.0,"tv":0.0,"id":2284304}]}]}
{"op":"mcm","clk":"1002750089","pt":1580646290344,"mc":[{"id":"1.168224578","rc":[{"batb":[[2,1.01,17.69]],"ltp":0.0,"tv":0.0,"id":7797764},{"batb":[[2,1.01,17.41]],"ltp":0.0,"tv":0.0,"id":2284304}]}]}
{"op":"mcm","clk":"1002750172","pt":1580646290848,"mc":[{"id":"1.168224578","rc":[{"batb":[[0,2.1,1.2],[1,2.08,24.63],[2,2.06,39.49]],"ltp":0.0,"tv":0.0,"id":7797764},{"batb":[[0,1.81,1.39],[1,1.8,19.59],[2,1.78,53.77]],"ltp":0.0,"tv":0.0,"id":2284304}]}]}
{"op":"mcm","clk":"1002753698","pt":1580646314267,"mc":[{"id":"1.168224578","marketDefinition":{"bspMarket":false,"turnInPlayEnabled":true,"persistenceEnabled":true,"marketBaseRate":5.0,"eventId":"29681732","eventTypeId":"2","numberOfWinners":1,"bettingType":"ODDS","marketType":"SET_WINNER","marketTime":"2020-02-02T12:16:00.000Z","suspendTime":"2020-02-02T12:16:00.000Z","bspReconciled":false,"complete":true,"inPlay":false,"crossMatching":true,"runnersVoidable":false,"numberOfActiveRunners":2,"betDelay":0,"status":"OPEN","runners":[{"status":"ACTIVE","sortPriority":1,"id":2284304,"name":"Sergiy Stakhovsky"},{"status":"ACTIVE","sortPriority":2,"id":7797764,"name":"Alexey Vatutin"}],"regulators":["MR_INT"],"countryCode":"FR","discountAllowed":true,"timezone":"UTC","openDate":"2020-02-02T12:16:00.000Z","version":3148684857,"name":"Set 1 Winner","eventName":"Stakhovsky v Vatutin"}}]}
{"op":"mcm","clk":"1002755948","pt":1580646328201,"mc":[{"id":"1.168224578","rc":[{"batb":[[0,2.1,25.67],[1,2.06,39.49],[2,1.01,16.01]],"ltp":0.0,"tv":0.0,"id":7797764}]}]}
{"op":"mcm","clk":"1002787425","pt":1580646527443,"mc":[{"id":"1.168224578","marketDefinition":{"bspMarket":false,"turnInPlayEnabled":true,"persistenceEnabled":true,"marketBaseRate":5.0,"eventId":"29681732","eventTypeId":"2","numberOfWinners":1,"bettingType":"ODDS","marketType":"SET_WINNER","marketTime":"2020-02-02T12:16:00.000Z","suspendTime":"2020-02-02T12:16:00.000Z","bspReconciled":false,"complete":true,"inPlay":false,"crossMatching":true,"runnersVoidable":false,"numberOfActiveRunners":2,"betDelay":0,"status":"OPEN","runners":[{"status":"ACTIVE","sortPriority":1,"id":2284304,"name":"Sergiy Stakhovsky"},{"status":"ACTIVE","sortPriority":2,"id":7797764,"name":"Alexey Vatutin"}],"regulators":["MR_INT"],"countryCode":"FR","discountAllowed":true,"timezone":"UTC","openDate":"2020-02-02T12:16:00.000Z","version":3148684857,"name":"Set 1 Winner","eventName":"Stakhovsky v Vatutin"},"rc":[{"batb":[[0,2.1,1.2],[1,1.01,16.01],[2,1.01,0]],"ltp":0.0,"tv":0.0,"id":7797764},{"batb":[[1,1.01,16.01],[2,1.78,0]],"ltp":0.0,"tv":0.0,"id":2284304}]}]}
{"op":"mcm","clk":"1002787441","pt":1580646527557,"mc":[{"id":"1.168224578","marketDefinition":{"bspMarket":false,"turnInPlayEnabled":true,"persistenceEnabled":true,"marketBaseRate":5.0,"eventId":"29681732","eventTypeId":"2","numberOfWinners":1,"bettingType":"ODDS","marketType":"SET_WINNER","marketTime":"2020-02-02T12:16:00.000Z","suspendTime":"2020-02-02T12:16:00.000Z","bspReconciled":false,"complete":true,"inPlay":true,"crossMatching":true,"runnersVoidable":false,"numberOfActiveRunners":2,"betDelay":3,"status":"OPEN","runners":[{"status":"ACTIVE","sortPriority":1,"id":2284304,"name":"Sergiy Stakhovsky"},{"status":"ACTIVE","sortPriority":2,"id":7797764,"name":"Alexey Vatutin"}],"regulators":["MR_INT"],"countryCode":"FR","discountAllowed":true,"timezone":"UTC","openDate":"2020-02-02T12:16:00.000Z","version":3148715118,"name":"Set 1 Winner","eventName":"Stakhovsky v Vatutin"},"rc":[{"batb":[[0,1.01,15.51],[1,1.01,0]],"ltp":0.0,"tv":0.0,"id":7797764},{"batb":[[0,1.01,15.51],[1,1.01,0]],"ltp":0.0,"tv":0.0,"id":2284304}]}]}
{"op":"mcm","clk":"1002788360","pt":1580646532728,"mc":[{"id":"1.168224578","rc":[{"batb":[[0,1.68,158.47],[1,1.66,233.19],[2,1.01,15.51]],"batl":[[0,2.04,98.81],[1,2.06,118.63]],"ltp":0.0,"tv":0.0,"id":2284304}]}]}
{"op":"mcm","clk":"1002789202","pt":1580646537546,"mc":[{"id":"1.168224578","rc":[{"batb":[[0,1.01,15.51],[1,1.66,0],[2,1.01,0]],"ltp":0.0,"tv":0.0,"id":2284304}]}]}
{"op":"mcm","clk":"1002789707","pt":1580646540456,"mc":[{"id":"1.168224578","rc":[{"batb":[[0,1.95,163.12],[1,1.93,141.5],[2,1.01,15.51]],"ltp":0.0,"tv":0.0,"id":2284304}]}]}
{"op":"mcm","clk":"1002789899","pt":1580646541457,"mc":[{"id":"1.168224578","rc":[{"batb":[[0,1.94,15.42],[1,1.84,18.41],[2,1.01,15.51]],"ltp":0.0,"tv":0.0,"id":7797764},{"batb":[[1,1.93,157.24],[2,1.77,20.85]],"ltp":0.0,"tv":0.0,"id":2284304}]}]}
{"op":"mcm","clk":"1002790053","pt":1580646542340,"mc":[{"id":"1.168224578","rc":[{"batb":[[0,1.94,59.95]],"ltp":0.0,"tv":0.0,"id":7797764},{"batb":[[2,1.85,48.73]],"ltp":0.0,"tv":0.0,"id":2284304}]}]}
{"op":"mcm","clk":"1002790393","pt":1580646544277,"mc":[{"id":"1.168224578","rc":[{"batl":[[0,2.16,36.13]],"ltp":0.0,"tv":0.0,"id":7797764},{"batl":[[1,2.06,158.12]],"ltp":0.0,"tv":0.0,"id":2284304}]}]}
{"op":"mcm","clk":"1002790446","pt":1580646544556,"mc":[{"id":"1.168224578","rc":[{"batb":[[0,1.93,15.74],[1,1.85,48.73],[2,1.77,20.85]],"ltp":0.0,"tv":0.0,"id":2284304}]}]}
{"op":"mcm","clk":"1002791022","pt":1580646547559,"mc":[{"id":"1.168224578","rc":[{"batb":[[0,1.96,98.49],[1,1.94,139.27],[2,1.93,15.74]],"ltp":0.0,"tv":0.0,"id":2284304}]}]}
{"op":"mcm","clk":"1002792696","pt":1580646557291,"mc":[{"id":"1.168224578","rc":[{"batb":[[0,1.84,18.41],[1,1.01,15.51],[2,1.01,0]],"ltp":0.0,"tv":0.0,"id":7797764},{"batb":[[0,1.77,20.85],[1,1.01,15.51],[2,1.93,0]],"ltp":0.0,"tv":0.0,"id":2284304}]}]}
{"op":"mcm","clk":"1002793390","pt":1580646561469,"mc":[{"id":"1.168224578","rc":[{"batb":[[0,1.92,158.68],[1,1.9,148.65],[2,1.77,20.85]],"batl":[[0,2.02,187.01],[1,2.04,122.07]],"ltp":0.0,"tv":0.0,"id":2284304}]}]}
{"op":"mcm","clk":"1002794023","pt":1580646565565,"mc":[{"id":"1.168224578","rc":[{"batb":[[0,1.77,20.85],[1,1.01,15.51],[2,1.77,0]],"ltp":0.0,"tv":0.0,"id":2284304}]}]}
{"op":"mcm","clk":"1002795126","pt":1580646572208,"mc":[{"id":"1.168224578","rc":[{"batb":[[0,1.86,175.92],[1,1.84,183.11],[2,1.01,15.51]],"batl":[[0,1.95,158.17],[1,1.97,135.36]],"ltp":0.0,"tv":0.0,"id":7797764}]}]}
{"op":"mcm","clk":"1002795295","pt":1580646573256,"mc":[{"id":"1.168224578","rc":[{"batb":[[2,1.76,21.01]],"ltp":0.0,"tv":0.0,"id":7797764},{"batb":[[0,2.04,26.28],[1,1.91,16.21],[2,1.01,15.51]],"ltp":0.0,"tv":0.0,"id":2284304}]}]}
{"op":"mcm","clk":"1002795441","pt":1580646574005,"mc":[{"id":"1.168224578","rc":[{"batb":[[0,1.86,224.65]],"batl":[[2,2.06,39.49]],"ltp":0.0,"tv":0.0,"id":7797764},{"batb":[[1,1.93,44.53],[2,1.91,16.21]],"batl":[[0,2.14,36.13]],"ltp":0.0,"tv":0.0,"id":2284304}]}]}
{"op":"mcm","clk":"1002797689","pt":1580646589026,"mc":[{"id":"1.168224578","rc":[{"batb":[[0,1.76,21.01],[1,1.01,15.51],[2,1.76,0]],"ltp":0.0,"tv":0.0,"id":7797764},{"batb":[[0,1.91,16.21],[1,1.01,15.51],[2,1.91,0]],"ltp":0.0,"tv":0.0,"id":2284304}]}]}
{"op":"mcm","clk":"1002798521","pt":1580646594427,"mc":[{"id":"1.168224578","rc":[{"batb":[[0,1.88,176.51],[1,1.86,159.06],[2,1.76,21.01]],"batl":[[0,1.97,140.2],[1,1.99,131.35]],"ltp":0.0,"tv":0.0,"id":7797764}]}]}
{"op":"mcm","clk":"1002799637","pt":1580646601466,"mc":[{"id":"1.168224578","rc":[{"batb":[[0,1.76,21.01],[1,1.01,15.51],[2,1.76,0]],"ltp":0.0,"tv":0.0,"id":7797764}]}]}
{"op":"mcm","clk":"1002800276","pt":1580646604568,"mc":[{"id":"1.168224578","rc":[{"batb":[[0,1.81,120.03],[1,1.79,180.1],[2,1.76,21.01]],"batl":[[0,2.06,107.75],[1,2.08,115.37]],"ltp":0.0,"tv":0.0,"id":7797764}]}]}
{"op":"mcm","clk":"1002803332","pt":1580646621868,"mc":[{"id":"1.168224578","rc":[{"batb":[[0,1.76,21.01],[1,1.01,15.51],[2,1.76,0]],"ltp":0.0,"tv":0.0,"id":7797764}]}]}
{"op":"mcm","clk":"1002803962","pt":1580646625488,"mc":[{"id":"1.168224578","rc":[{"batb":[[0,1.96,29.98],[1,1.83,18.49],[2,1.76,21.01]],"ltp":0.0,"tv":0.0,"id":7797764},{"batb":[[0,1.94,138.29],[1,1.92,143.84],[2,1.91,16.21]],"batl":[[0,2.04,189.89],[1,2.06,118.66]],"ltp":0.0,"tv":0.0,"id":2284304}]}]}
{"op":"mcm","clk":"1002804083","pt":1580646626083,"mc":[{"id":"1.168224578","rc":[{"batb":[[1,1.95,43.69],[2,1.83,18.49]],"batl":[[0,2.18,35.29]],"ltp":0.0,"tv":0.0,"id":7797764},{"batl":[[1,2.06,158.15]],"ltp":0.0,"tv":0.0,"id":2284304}]}]}
{"op":"mcm","clk":"1002805111","pt":1580646631824,"mc":[{"id":"1.168224578","rc":[{"batb":[[0,1.91,16.21],[1,1.86,48.73],[2,1.74,22.11]],"batl":[[0,2.04,151.52]],"ltp":0.0,"tv":0.0,"id":2284304}]}]}
{"op":"mcm","clk":"1002805616","pt":1580646634819,"mc":[{"id":"1.168224578","rc":[{"batb":[[0,1.95,108.1],[1,1.93,141.53],[2,1.91,16.21]],"ltp":0.0,"tv":0.0,"id":2284304}]}]}
{"op":"mcm","clk":"1002806802","pt":1580646641491,"mc":[{"id":"1.168224578","rc":[{"batl":[[0,2.16,36.13]],"ltp":0.0,"tv":0.0,"id":7797764}]}]}
{"op":"mcm","clk":"1002807916","pt":1580646647921,"mc":[{"id":"1.168224578","rc":[{"batb":[[0,1.95,43.69],[1,1.83,18.49],[2,1.01,15.51]],"ltp":0.0,"tv":0.0,"id":7797764},{"batb":[[0,1.86,48.73],[1,1.74,22.11],[2,1.01,15.51]],"batl":[[0,2.06,39.49],[1,2.06,0]],"ltp":0.0,"tv":0.0,"id":2284304}]}]}
{"op":"mcm","clk":"1002808151","pt":1580646649150,"mc":[{"id":"1.168224578","rc":[{"batb":[[0,1.83,18.49],[1,1.01,15.51],[2,1.01,0]],"ltp":0.0,"tv":0.0,"id":7797764},{"batb":[[0,1.74,22.11],[1,1.01,15.51],[2,1.01,0]],"ltp":0.0,"tv":0.0,"id":2284304}]}]}
{"op":"mcm","clk":"1002808499","pt":1580646651251,"mc":[{"id":"1.168224578","rc":[{"batb":[[0,1.82,18.8]],"ltp":0.0,"tv":0.0,"id":7797764},{"batb":[[0,1.75,21.72]],"ltp":0.0,"tv":0.0,"id":2284304}]}]}
{"op":"mcm","clk":"1002808907","pt":1580646653759,"mc":[{"id":"1.168224578","rc":[{"batb":[[0,1.91,112.53],[1,1.89,151.13],[2,1.75,21.72]],"batl":[[0,1.99,112.94],[1,2.02,189.44]],"ltp":0.0,"tv":0.0,"id":2284304}]}]}
{"op":"mcm","clk":"1002809558","pt":1580646657574,"mc":[{"id":"1.168224578","rc":[{"batb":[[0,1.75,21.72],[1,1.01,15.51],[2,1.75,0]],"ltp":0.0,"tv":0.0,"id":2284304}]}]}
{"op":"mcm","clk":"1002810065","pt":1580646660501,"mc":[{"id":"1.168224578","rc":[{"batb":[[0,1.77,169.08],[1,1.75,216.03],[2,1.01,15.51]],"batl":[[0,2.16,92.6],[1,2.18,100.91]],"ltp":0.0,"tv":0.0,"id":2284304}]}]}
{"op":"mcm","clk":"1002812319","pt":1580646673396,"mc":[{"id":"1.168224578","rc":[{"batb":[[0,1.75,21.72],[1,1.01,15.51],[2,1.01,0]],"ltp":0.0,"tv":0.0,"id":2284304}]}]}
{"op":"mcm","clk":"1002812851","pt":1580646676488,"mc":[{"id":"1.168224578","rc":[{"batb":[[0,1.86,124.15],[1,1.84,164.66],[2,1.82,18.8]],"batl":[[0,1.94,138.66],[1,1.96,137.49]],"ltp":0.0,"tv":0.0,"id":7797764}]}]}
{"op":"mcm","clk":"1002813002","pt":1580646677393,"mc":[{"id":"1.168224578","rc":[{"batb":[[0,2.06,25.73],[1,1.93,15.66],[2,1.01,15.51]],"ltp":0.0,"tv":0.0,"id":2284304}]}]}
{"op":"mcm","clk":"1002813127","pt":1580646678089,"mc":[{"id":"1.168224578","rc":[{"batb":[[1,1.84,214.23]],"batl":[[2,2.04,40.33]],"ltp":0.0,"tv":0.0,"id":7797764},{"batb":[[1,1.95,43.69],[2,1.93,15.66]],"batl":[[0,2.18,35.29]],"ltp":0.0,"tv":0.0,"id":2284304}]}]}
{"op":"mcm","clk":"1002815659","pt":1580646692295,"mc":[{"id":"1.168224578","rc":[{"batb":[[0,1.84,49.57],[1,1.75,21.4],[2,1.01,15.51]],"batl":[[0,2.04,40.33],[1,1.96,0],[2,2.04,0]],"ltp":0.0,"tv":0.0,"id":7797764},{"batb":[[0,1.95,43.69],[1,1.93,15.66],[2,1.01,15.51]],"ltp":0.0,"tv":0.0,"id":2284304}]}]}
{"op":"mcm","clk":"1002815835","pt":1580646693191,"mc":[{"id":"1.168224578","rc":[{"batb":[[0,1.75,21.4],[1,1.01,15.51],[2,1.01,0]],"ltp":0.0,"tv":0.0,"id":7797764},{"batb":[[0,1.93,15.66],[1,1.01,15.51],[2,1.01,0]],"ltp":0.0,"tv":0.0,"id":2284304}]}]}
{"op":"mcm","clk":"1002816141","pt":1580646694983,"mc":[{"id":"1.168224578","rc":[{"batb":[[0,1.8,175.85],[1,1.78,183.64],[2,1.76,21.17]],"batl":[[0,2.06,192.87],[1,2.08,115.41]],"ltp":0.0,"tv":0.0,"id":7797764}]}]}
{"op":"mcm","clk":"1002817407","pt":1580646702314,"mc":[{"id":"1.168224578","rc":[{"batb":[[2,1.77,53.77]],"batl":[[0,1.88,141.19],[1,1.9,151.12],[2,1.95,42.01]],"ltp":0.0,"tv":0.0,"id":7797764},{"batb":[[0,2.16,22.66],[1,2.04,40.33],[2,2,28.01]],"batl":[[0,2.28,32.77]],"ltp":0.0,"tv":0.0,"id":2284304}]}]}
{"op":"mcm","clk":"1002818504","pt":1580646708113,"mc":[{"id":"1.168224578","rc":[{"trd":[[2.16,3.54]],"batb":[[0,2.16,20.89]],"ltp":2.16,"tv":3.53,"id":2284304}],"tv":3.53}]}
{"op":"mcm","clk":"1002819227","pt":1580646712133,"mc":[{"id":"1.168224578","rc":[{"batb":[[0,2.14,22.66]],"ltp":2.16,"tv":3.53,"id":2284304}]}]}
{"op":"mcm","clk":"1002823384","pt":1580646734319,"mc":[{"id":"1.168224578","rc":[{"batb":[[0,1.76,21.17],[1,1.6,29.27],[2,1.01,15.51]],"ltp":0.0,"tv":0.0,"id":7797764}]}]}
{"op":"mcm","clk":"1002823918","pt":1580646737309,"mc":[{"id":"1.168224578","rc":[{"batb":[[0,1.81,137.91],[1,1.79,233.02],[2,1.76,21.17]],"batl":[[0,1.89,119.07],[1,1.91,148.58],[2,1.96,42.01]],"ltp":0.0,"tv":0.0,"id":7797764}]}]}
{"op":"mcm","clk":"1002824298","pt":1580646739326,"mc":[{"id":"1.168224578","rc":[{"batb":[[0,1.79,52.93],[1,1.76,21.17],[2,1.6,29.27]],"batl":[[0,1.96,42.01],[1,1.91,0],[2,1.96,0]],"ltp":0.0,"tv":0.0,"id":7797764}]}]}
{"op":"mcm","clk":"1002824822","pt":1580646742069,"mc":[{"id":"1.168224578","rc":[{"batb":[[2,1.65,215.08]],"batl":[[1,2.02,178.43],[2,2.04,122.01]],"ltp":0.0,"tv":0.0,"id":7797764}]}]}
{"op":"mcm","clk":"1002826271","pt":1580646749267,"mc":[{"id":"1.168224578","rc":[{"batb":[[0,1.65,215.08],[1,1.64,122.57],[2,1.6,29.27]],"batl":[[0,2.02,178.43],[1,2.04,122.01],[2,2.04,0]],"ltp":0.0,"tv":0.0,"id":7797764},{"batb":[[0,2,28.01],[1,1.01,15.51],[2,2,0]],"ltp":2.16,"tv":3.53,"id":2284304}]}]}
{"op":"mcm","clk":"1002826673","pt":1580646751450,"mc":[{"id":"1.168224578","rc":[{"batb":[[2,1.61,28.8]],"ltp":0.0,"tv":0.0,"id":7797764},{"batb":[[1,1.99,28.56],[2,1.01,15.51]],"ltp":2.16,"tv":3.53,"id":2284304}]}]}
{"op":"mcm","clk":"1002826870","pt":1580646752363,"mc":[{"id":"1.168224578","rc":[{"batb":[[0,1.99,28.56],[1,1.01,15.51],[2,1.01,0]],"ltp":2.16,"tv":3.53,"id":2284304}]}]}
{"op":"mcm","clk":"1002827510","pt":1580646755470,"mc":[{"id":"1.168224578","rc":[{"batl":[[0,1.72,182.94],[1,1.74,199.52]],"ltp":0.0,"tv":0.0,"id":7797764}]}]}
{"op":"mcm","clk":"1002827717","pt":1580646756491,"mc":[{"id":"1.168224578","rc":[{"batb":[[0,1.65,278.93]],"ltp":0.0,"tv":0.0,"id":7797764},{"batb":[[0,2.42,16.13],[1,2.18,21.64],[2,1.01,15.51]],"batl":[[0,2.56,26.89]],"ltp":2.16,"tv":3.53,"id":2284304}]}]}
{"op":"mcm","clk":"1002827882","pt":1580646757287,"mc":[{"id":"1.168224578","rc":[{"batb":[[2,1.92,394.91]],"ltp":2.16,"tv":3.53,"id":2284304}]}]}
{"op":"mcm","clk":"1002828151","pt":1580646758464,"mc":[{"id":"1.168224578","rc":[{"batl":[[2,1.8,42.01]],"ltp":0.0,"tv":0.0,"id":7797764}]}]}
{"op":"mcm","clk":"1002828328","pt":1580646759372,"mc":[{"id":"1.168224578","rc":[{"batb":[[1,2.26,32.77],[2,2.18,21.64]],"ltp":2.16,"tv":3.53,"id":2284304}]}]}
{"op":"mcm","clk":"1002830422","pt":1580646769770,"mc":[{"id":"1.168224578","rc":[{"batb":[[0,1.65,63.85],[1,1.46,42.17],[2,1.4,451]],"batl":[[0,1.8,42.01],[1,1.74,0],[2,1.8,0]],"ltp":0.0,"tv":0.0,"id":7797764},{"batb":[[0,2.26,32.77],[1,2.18,21.64],[2,1.92,394.91]],"ltp":2.16,"tv":3.53,"id":2284304}]}]}
{"op":"mcm","clk":"1002830723","pt":1580646771229,"mc":[{"id":"1.168224578","rc":[{"batb":[[0,1.46,42.17],[1,1.4,451],[2,1.01,15.51]],"ltp":0.0,"tv":0.0,"id":7797764},{"batb":[[0,2.18,21.64],[1,1.92,394.91],[2,1.01,15.51]],"ltp":2.16,"tv":3.53,"id":2284304}]}]}
{"op":"mcm","clk":"1002831148","pt":1580646773391,"mc":[{"id":"1.168224578","rc":[{"batb":[[0,1.48,228.56],[1,1.47,187.23],[2,1.46,42.17]],"ltp":0.0,"tv":0.0,"id":7797764}]}]}
{"op":"mcm","clk":"1002831433","pt":1580646774916,"mc":[{"id":"1.168224578","rc":[{"batb":[[1,1.01,15.51],[2,1.01,0]],"ltp":2.16,"tv":3.53,"id":2284304}]}]}
{"op":"mcm","clk":"1002831715","pt":1580646776398,"mc":[{"id":"1.168224578","rc":[{"batl":[[0,1.53,189.38],[1,1.54,152.55]],"ltp":0.0,"tv":0.0,"id":7797764}]}]}
{"op":"mcm","clk":"1002831907","pt":1580646777408,"mc":[{"id":"1.168224578","rc":[{"batb":[[0,2.88,10.39],[1,2.54,14.32],[2,1.01,15.51]],"ltp":2.16,"tv":3.53,"id":2284304}]}]}
{"op":"mcm","clk":"1002832079","pt":1580646778319,"mc":[{"id":"1.168224578","rc":[{"batb":[[0,1.48,315.94]],"batl":[[2,1.6,42.01]],"ltp":0.0,"tv":0.0,"id":7797764},{"batb":[[1,2.66,25.21],[2,2.54,14.32]],"batl":[[0,3.05,20.16]],"ltp":2.16,"tv":3.53,"id":2284304}]}]}
{"op":"mcm","clk":"1002834207","pt":1580646789328,"mc":[{"id":"1.168224578","rc":[{"batb":[[0,1.48,87.38],[1,1.46,42.17],[2,1.33,63.1]],"batl":[[0,1.6,42.01],[1,1.54,0],[2,1.6,0]],"ltp":0.0,"tv":0.0,"id":7797764}]}]}
{"op":"mcm","clk":"1002834251","pt":1580646789545,"mc":[{"id":"1.168224578","rc":[{"batb":[[1,1.33,63.1],[2,1.28,485.89]],"ltp":0.0,"tv":0.0,"id":7797764},{"batb":[[0,2.66,25.21],[1,2.54,14.32],[2,2.22,384.52]],"ltp":2.16,"tv":3.53,"id":2284304}]}]}
{"op":"mcm","clk":"1002834577","pt":1580646791250,"mc":[{"id":"1.168224578","rc":[{"batb":[[0,1.33,63.1],[1,1.28,485.89],[2,1.01,15.51]],"ltp":0.0,"tv":0.0,"id":7797764},{"batb":[[0,2.54,14.32],[1,2.22,384.52],[2,1.01,15.51]],"ltp":2.16,"tv":3.53,"id":2284304}]}]}
{"op":"mcm","clk":"1002834807","pt":1580646792334,"mc":[{"id":"1.168224578","rc":[{"batb":[[0,1.33,335.11],[1,1.32,308.41],[2,1.28,485.89]],"batl":[[0,1.65,150.21],[1,1.66,116.41]],"ltp":0.0,"tv":0.0,"id":7797764}]}]}
{"op":"mcm","clk":"1002835629","pt":1580646796424,"mc":[{"id":"1.168224578","rc":[{"batb":[[2,1.01,15.51]],"batl":[[0,1.37,333.93],[1,1.38,238.58]],"ltp":0.0,"tv":0.0,"id":7797764},{"batb":[[1,1.01,15.51],[2,1.01,0]],"ltp":2.16,"tv":3.53,"id":2284304}]}]}
{"op":"mcm","clk":"1002835841","pt":1580646797452,"mc":[{"id":"1.168224578","rc":[{"batb":[[2,1.26,86.31]],"ltp":0.0,"tv":0.0,"id":7797764},{"batb":[[0,3.55,15.26],[1,3.15,20.38],[2,1.01,15.51]],"ltp":2.16,"tv":3.53,"id":2284304}]}]}
{"op":"mcm","clk":"1002836038","pt":1580646798462,"mc":[{"id":"1.168224578","rc":[{"batb":[[0,1.33,461.98]],"batl":[[2,1.42,42.01]],"ltp":0.0,"tv":0.0,"id":7797764},{"batb":[[1,3.35,17.64],[2,3.15,20.38]],"batl":[[0,4,13.44]],"ltp":2.16,"tv":3.53,"id":2284304}]}]}
{"op":"mcm","clk":"1002836242","pt":1580646799457,"mc":[{"id":"1.168224578","rc":[{"batb":[[1,3.15,20.38],[2,2.52,381.46]],"ltp":2.16,"tv":3.53,"id":2284304}]}]}
{"op":"mcm","clk":"1002836404","pt":1580646800245,"mc":[{"id":"1.168224578","rc":[{"batb":[[1,3.4,16.8],[2,3.15,20.38]],"ltp":2.16,"tv":3.53,"id":2284304}]}]}
{"op":"mcm","clk":"1002837999","pt":1580646808447,"mc":[{"id":"1.168224578","rc":[{"batb":[[0,1.33,189.97],[1,1.26,86.31],[2,1.2,530.86]],"batl":[[0,1.42,42.01],[1,1.38,0],[2,1.42,0]],"ltp":0.0,"tv":0.0,"id":7797764}]}]}
{"op":"mcm","clk":"1002838180","pt":1580646809457,"mc":[{"id":"1.168224578","rc":[{"batb":[[0,1.26,86.31],[1,1.2,530.86],[2,1.01,15.51]],"ltp":0.0,"tv":0.0,"id":7797764},{"batb":[[0,3.15,20.38],[1,2.52,381.46],[2,1.01,15.51]],"ltp":2.16,"tv":3.53,"id":2284304}]}]}
{"op":"mcm","clk":"1002838563","pt":1580646811415,"mc":[{"id":"1.168224578","rc":[{"batb":[[1,1.24,257.82],[2,1.23,461.7]],"batl":[[0,1.44,269.18],[1,1.45,193.03]],"ltp":0.0,"tv":0.0,"id":7797764}]}]}
{"op":"mcm","clk":"1002838636","pt":1580646811830,"mc":[{"id":"1.168224578","rc":[{"batb":[[0,1.25,87.26]],"ltp":0.0,"tv":0.0,"id":7797764},{"batb":[[0,3.15,20.06]],"ltp":2.16,"tv":3.53,"id":2284304}]}]}
{"op":"mcm","clk":"1002839999","pt":1580646819136,"mc":[{"id":"1.168224578","rc":[{"batb":[[1,1.01,15.51],[2,1.01,0]],"ltp":2.16,"tv":3.53,"id":2284304}]}]}
{"op":"mcm","clk":"1002840239","pt":1580646820420,"mc":[{"id":"1.168224578","rc":[{"batl":[[0,1.27,422.45],[1,1.28,387.29]],"ltp":0.0,"tv":0.0,"id":7797764},{"batb":[[0,4.6,10.92],[1,3.15,20.06],[2,1.01,15.51]],"batl":[[0,5.6,8.4]],"ltp":2.16,"tv":3.53,"id":2284304}]}]}
{"op":"mcm","clk":"1002840420","pt":1580646821477,"mc":[{"id":"1.168224578","rc":[{"batb":[[1,4.2,19.51],[2,3.5,15.5]],"ltp":2.16,"tv":3.53,"id":2284304}]}]}
{"op":"mcm","clk":"1002843853","pt":1580646839152,"mc":[{"id":"1.168224578","rc":[{"batb":[[1,1.24,186.71]],"ltp":0.0,"tv":0.0,"id":7797764}]}]}
{"op":"mcm","clk":"1002844499","pt":1580646842252,"mc":[{"id":"1.168224578","rc":[{"batb":[[0,1.2,111.33],[1,1.13,629.97],[2,1.01,15.51]],"batl":[[0,1.28,42.01],[1,1.28,0]],"ltp":0.0,"tv":0.0,"id":7797764},{"batb":[[1,3.5,15.5],[2,2.9,375.84]],"ltp":2.16,"tv":3.53,"id":2284304}]}]}
{"op":"mcm","clk":"1002844688","pt":1580646843309,"mc":[{"id":"1.168224578","rc":[{"batb":[[0,3.5,15.5],[1,2.9,375.84],[2,1.01,15.51]],"ltp":2.16,"tv":3.53,"id":2284304}]}]}
{"op":"mcm","clk":"1002845066","pt":1580646845306,"mc":[{"id":"1.168224578","rc":[{"batb":[[1,1.19,710.04],[2,1.18,370.19]],"batl":[[0,1.35,216.21],[1,1.36,257.77]],"ltp":0.0,"tv":0.0,"id":7797764}]}]}
{"op":"mcm","clk":"1002845151","pt":1580646845689,"mc":[{"id":"1.168224578","rc":[{"batb":[[1,1.13,629.97],[2,1.01,15.51]],"ltp":0.0,"tv":0.0,"id":7797764}]}]}
{"op":"mcm","clk":"1002845448","pt":1580646847185,"mc":[{"id":"1.168224578","rc":[{"batb":[[1,1.01,15.51],[2,1.01,0]],"ltp":0.0,"tv":0.0,"id":7797764}]}]}
{"op":"mcm","clk":"1002845834","pt":1580646849404,"mc":[{"id":"1.168224578","rc":[{"batb":[[0,1.33,64.05],[1,1.32,180.52],[2,1.31,320.12]],"ltp":0.0,"tv":0.0,"id":7797764},{"batb":[[0,3.55,14.87],[1,2.94,24.39],[2,2.9,375.84]],"ltp":2.16,"tv":3.53,"id":2284304}]}]}
{"op":"mcm","clk":"1002846011","pt":1580646850296,"mc":[{"id":"1.168224578","rc":[{"batl":[[1,1.36,299.78]],"ltp":0.0,"tv":0.0,"id":7797764},{"batb":[[0,3.75,15.12],[1,3.55,14.87],[2,2.94,24.39]],"ltp":2.16,"tv":3.53,"id":2284304}]}]}
{"op":"mcm","clk":"1002847750","pt":1580646859343,"mc":[{"id":"1.168224578","rc":[{"batb":[[0,1.26,84.19],[1,1.2,530.86],[2,1.01,15.51]],"ltp":0.0,"tv":0.0,"id":7797764},{"batb":[[0,2.94,24.39],[1,2.9,375.84],[2,1.01,15.51]],"ltp":2.16,"tv":3.53,"id":2284304}]}]}
{"op":"mcm","clk":"1002848222","pt":1580646861736,"mc":[{"id":"1.168224578","rc":[{"batb":[[1,1.25,441.37],[2,1.24,444.51]],"batl":[[0,1.49,210.7],[1,1.5,168.96]],"ltp":0.0,"tv":0.0,"id":7797764}]}]}
{"op":"mcm","clk":"1002850769","pt":1580646874081,"mc":[{"id":"1.168224578","rc":[{"batb":[[1,1.2,530.86],[2,1.01,15.51]],"ltp":0.0,"tv":0.0,"id":7797764}]}]}
{"op":"mcm","clk":"1002851195","pt":1580646876379,"mc":[{"id":"1.168224578","rc":[{"batb":[[1,1.01,15.51],[2,1.01,0]],"ltp":0.0,"tv":0.0,"id":7797764},{"batb":[[1,1.01,15.51],[2,1.01,0]],"ltp":2.16,"tv":3.53,"id":2284304}]}]}
{"op":"mcm","clk":"1002851401","pt":1580646877382,"mc":[{"id":"1.168224578","rc":[{"batb":[[0,1.44,340.02],[1,1.43,211.46],[2,1.36,57.6]],"ltp":0.0,"tv":0.0,"id":7797764},{"batb":[[1,2.5,14.95],[2,1.01,15.51]],"ltp":2.16,"tv":3.53,"id":2284304}]}]}
{"op":"mcm","clk":"1002851561","pt":1580646878282,"mc":[{"id":"1.168224578","rc":[{"batb":[[2,1.39,107.54]],"batl":[[0,1.49,252.71]],"ltp":0.0,"tv":0.0,"id":7797764},{"batb":[[0,3.05,20.16],[1,2.94,24.39],[2,2.5,14.95]],"batl":[[0,3.55,15.96]],"ltp":2.16,"tv":3.53,"id":2284304}]}]}
{"op":"mcm","clk":"1002855370","pt":1580646897412,"mc":[{"id":"1.168224578","rc":[{"batb":[[0,1.36,57.6],[1,1.25,505.09],[2,1.01,15.51]],"ltp":0.0,"tv":0.0,"id":7797764},{"batb":[[0,2.5,14.95],[1,2.3,385.09],[2,1.01,15.51]],"ltp":2.16,"tv":3.53,"id":2284304}]}]}
{"op":"mcm","clk":"1002855922","pt":1580646900434,"mc":[{"id":"1.168224578","rc":[{"batb":[[1,1.35,416.17],[2,1.34,288.22]],"batl":[[0,1.68,178.23],[1,1.7,215.7]],"ltp":0.0,"tv":0.0,"id":7797764}]}]}
{"op":"mcm","clk":"1002856036","pt":1580646901017,"mc":[{"id":"1.168224578","rc":[{"batb":[[1,1.25,505.09],[2,1.01,15.51]],"ltp":0.0,"tv":0.0,"id":7797764}]}]}
{"op":"mcm","clk":"1002856302","pt":1580646902450,"mc":[{"id":"1.168224578","rc":[{"batb":[[1,1.01,15.51],[2,1.01,0]],"ltp":0.0,"tv":0.0,"id":7797764}]}]}
{"op":"mcm","clk":"1002856620","pt":1580646904048,"mc":[{"id":"1.168224578","rc":[{"batb":[[0,1.47,312.79],[1,1.46,193.48],[2,1.36,57.6]],"batl":[[0,1.52,130.76],[1,1.53,156.91]],"ltp":0.0,"tv":0.0,"id":7797764}]}]}
{"op":"mcm","clk":"1002856821","pt":1580646905054,"mc":[{"id":"1.168224578","rc":[{"batb":[[0,1.36,57.6],[1,1.01,15.51],[2,1.36,0]],"ltp":0.0,"tv":0.0,"id":7797764}]}]}
{"op":"mcm","clk":"1002856971","pt":1580646905850,"mc":[{"id":"1.168224578","rc":[{"batb":[[1,1.28,485.89],[2,1.01,15.51]],"ltp":0.0,"tv":0.0,"id":7797764}]}]}
{"op":"mcm","clk":"1002857426","pt":1580646907939,"mc":[{"id":"1.168224578","rc":[{"batb":[[1,1.35,416.17],[2,1.34,288.22]],"batl":[[0,1.68,178.23],[1,1.7,215.7]],"ltp":0.0,"tv":0.0,"id":7797764}]}]}
{"op":"mcm","clk":"1002857745","pt":1580646909429,"mc":[{"id":"1.168224578","rc":[{"batb":[[1,1.28,485.89],[2,1.01,15.51]],"ltp":0.0,"tv":0.0,"id":7797764}]}]}
{"op":"mcm","clk":"1002857954","pt":1580646910447,"mc":[{"id":"1.168224578","rc":[{"batb":[[1,1.01,15.51],[2,1.01,0]],"ltp":0.0,"tv":0.0,"id":7797764},{"batb":[[1,1.01,15.51],[2,1.01,0]],"ltp":2.16,"tv":3.53,"id":2284304}]}]}
{"op":"mcm","clk":"1002858371","pt":1580646912464,"mc":[{"id":"1.168224578","rc":[{"batb":[[0,1.62,149.44],[1,1.61,130.87],[2,1.36,57.6]],"batl":[[0,1.68,220.24]],"ltp":0.0,"tv":0.0,"id":7797764},{"batb":[[1,2.48,27.73],[2,1.01,15.51]],"ltp":2.16,"tv":3.53,"id":2284304}]}]}
{"op":"mcm","clk":"1002858536","pt":1580646913364,"mc":[{"id":"1.168224578","rc":[{"batb":[[2,1.58,30.69]],"batl":[[0,1.68,178.23]],"ltp":0.0,"tv":0.0,"id":7797764},{"batb":[[1,2.24,19.91]],"ltp":2.16,"tv":3.53,"id":2284304}]}]}
{"op":"mcm","clk":"1002858651","pt":1580646913936,"mc":[{"id":"1.168224578","rc":[{"batb":[[2,1.97,394.86]],"ltp":2.16,"tv":3.53,"id":2284304}]}]}
{"op":"mcm","clk":"1002859094","pt":1580646916274,"mc":[{"id":"1.168224578","rc":[{"batl":[[1,1.69,42.01],[2,1.7,215.7]],"ltp":0.0,"tv":0.0,"id":7797764},{"batb":[[1,2.46,28.57],[2,2.24,19.91]],"ltp":2.16,"tv":3.53,"id":2284304}]}]}
{"op":"mcm","clk":"1002860868","pt":1580646925357,"mc":[{"id":"1.168224578","rc":[{"batb":[[0,1.51,37.06],[1,1.38,448.45],[2,1.01,15.51]],"batl":[[0,1.69,42.01],[1,1.69,0],[2,1.7,0]],"ltp":0.0,"tv":0.0,"id":7797764},{"batb":[[0,2.46,28.57],[1,2.24,19.91],[2,1.97,394.86]],"ltp":2.16,"tv":3.53,"id":2284304}]}]}
{"op":"mcm","clk":"1002860920","pt":1580646925575,"mc":[{"id":"1.168224578","rc":[{"batb":[[0,2.24,19.91],[1,1.97,394.86],[2,1.01,15.51]],"ltp":2.16,"tv":3.53,"id":2284304}]}]}
{"op":"mcm","clk":"1002861289","pt":1580646927483,"mc":[{"id":"1.168224578","rc":[{"batb":[[0,1.53,201.73],[1,1.52,163.46],[2,1.51,37.06]],"batl":[[0,1.85,127.41],[1,1.87,159.04]],"ltp":0.0,"tv":0.0,"id":7797764}]}]}
{"op":"mcm","clk":"1002861353","pt":1580646927802,"mc":[{"id":"1.168224578","rc":[{"batb":[[0,1.51,37.06],[1,1.38,448.45],[2,1.01,15.51]],"ltp":0.0,"tv":0.0,"id":7797764}]}]}
{"op":"mcm","clk":"1002861501","pt":1580646928602,"mc":[{"id":"1.168224578","rc":[{"batb":[[1,1.01,15.51],[2,1.01,0]],"ltp":0.0,"tv":0.0,"id":7797764}]}]}
{"op":"mcm","clk":"1002861815","pt":1580646930183,"mc":[{"id":"1.168224578","rc":[{"batb":[[0,1.65,124.26],[1,1.64,122.35],[2,1.51,37.06]],"batl":[[0,1.71,166.5],[1,1.73,203.57]],"ltp":0.0,"tv":0.0,"id":7797764}]}]}
{"op":"mcm","clk":"1002862259","pt":1580646932488,"mc":[{"id":"1.168224578","rc":[{"batb":[[0,1.51,37.06],[1,1.4,451],[2,1.01,15.51]],"ltp":0.0,"tv":0.0,"id":7797764}]}]}
{"op":"mcm","clk":"1002862840","pt":1580646935380,"mc":[{"id":"1.168224578","rc":[{"batb":[[0,1.53,201.73],[1,1.52,163.46],[2,1.51,37.06]],"batl":[[0,1.85,127.41],[1,1.87,159.04]],"ltp":0.0,"tv":0.0,"id":7797764}]}]}
{"op":"mcm","clk":"1002864164","pt":1580646942348,"mc":[{"id":"1.168224578","rc":[{"batl":[[0,1.58,131.16],[1,1.59,135.94]],"ltp":0.0,"tv":0.0,"id":7797764},{"batl":[[0,3.05,20.16]],"ltp":2.16,"tv":3.53,"id":2284304}]}]}
{"op":"mcm","clk":"1002864385","pt":1580646943464,"mc":[{"id":"1.168224578","rc":[{"batb":[[0,2.72,11.96],[1,2.3,18.73],[2,1.97,394.86]],"ltp":2.16,"tv":3.53,"id":2284304}]}]}
{"op":"mcm","clk":"1002864549","pt":1580646944207,"mc":[{"id":"1.168224578","rc":[{"batl":[[2,1.6,42.01]],"ltp":0.0,"tv":0.0,"id":7797764},{"batb":[[1,2.66,25.21],[2,2.3,18.73]],"ltp":2.16,"tv":3.53,"id":2284304}]}]}
{"op":"mcm","clk":"1002867170","pt":1580646957361,"mc":[{"id":"1.168224578","rc":[{"batb":[[0,1.41,49.1],[1,1.34,465.43],[2,1.01,15.51]],"ltp":0.0,"tv":0.0,"id":7797764},{"batb":[[0,2.3,18.73],[1,1.97,394.86],[2,1.01,15.51]],"ltp":2.16,"tv":3.53,"id":2284304}]}]}
{"op":"mcm","clk":"1002868105","pt":1580646962332,"mc":[{"id":"1.168224578","rc":[{"batb":[[0,1.57,208.87],[1,1.56,147.72],[2,1.41,49.1]],"batl":[[0,1.63,192.67],[1,1.64,121.41]],"ltp":0.0,"tv":0.0,"id":7797764}]}]}
{"op":"mcm","clk":"1002868765","pt":1580646965670,"mc":[{"id":"1.168224578","rc":[{"batb":[[0,1.41,49.1],[1,1.34,465.43],[2,1.01,15.51]],"ltp":0.0,"tv":0.0,"id":7797764}]}]}
{"op":"mcm","clk":"1002869347","pt":1580646968606,"mc":[{"id":"1.168224578","rc":[{"batb":[[0,1.42,171.71],[1,1.41,273.22],[2,1.34,465.43]],"batl":[[0,1.83,109.64],[1,1.85,164.53]],"ltp":0.0,"tv":0.0,"id":7797764}]}]}
{"op":"mcm","clk":"1002870050","pt":1580646972387,"mc":[{"id":"1.168224578","rc":[{"batb":[[0,1.41,49.1],[1,1.34,465.43],[2,1.01,15.51]],"ltp":0.0,"tv":0.0,"id":7797764}]}]}
{"op":"mcm","clk":"1002870303","pt":1580646973788,"mc":[{"id":"1.168224578","rc":[{"batb":[[1,1.01,15.51],[2,1.01,0]],"ltp":0.0,"tv":0.0,"id":7797764}]}]}
{"op":"mcm","clk":"1002870631","pt":1580646975490,"mc":[{"id":"1.168224578","rc":[{"batb":[[0,1.76,164.82],[1,1.74,197.89],[2,1.41,49.1]],"ltp":0.0,"tv":0.0,"id":7797764}]}]}
{"op":"mcm","clk":"1002870845","pt":1580646976414,"mc":[{"id":"1.168224578","rc":[{"batb":[[1,1.74,254.18],[2,1.67,25.26]],"batl":[[2,1.9,42.01]],"ltp":0.0,"tv":0.0,"id":7797764},{"trd":[[2.3,31.93]],"batb":[[0,2.3,2.76],[1,2.1,37.81],[2,2.08,24.78]],"batl":[[0,2.34,31.09]],"ltp":2.3,"tv":35.46,"id":2284304}],"tv":35.46}]}
{"op":"mcm","clk":"1002870988","pt":1580646977090,"mc":[{"id":"1.168224578","rc":[{"batb":[[1,1.74,197.89]],"ltp":0.0,"tv":0.0,"id":7797764}]}]}
{"op":"mcm","clk":"1002871248","pt":1580646978408,"mc":[{"id":"1.168224578","rc":[{"batb":[[1,1.75,55.45],[2,1.74,197.89]],"ltp":0.0,"tv":0.0,"id":7797764}]}]}
{"op":"mcm","clk":"1002872407","pt":1580646984287,"mc":[{"id":"1.168224578","rc":[{"batb":[[0,2.28,19.28],[2,2.06,25.49]],"ltp":2.3,"tv":35.46,"id":2284304}]}]}
{"op":"mcm","clk":"1002873914","pt":1580646991941,"mc":[{"id":"1.168224578","rc":[{"batb":[[0,2.26,19.67]],"ltp":2.3,"tv":35.46,"id":2284304}]}]}
{"op":"mcm","clk":"1002882573","pt":1580647035404,"mc":[{"id":"1.168224578","rc":[{"batb":[[0,2.24,19.99],[2,2.04,26.36]],"ltp":2.3,"tv":35.46,"id":2284304}]}]}
{"op":"mcm","clk":"1002883836","pt":1580647041334,"mc":[{"id":"1.168224578","rc":[{"batl":[[0,1.9,42.01],[1,1.85,0],[2,1.9,0]],"ltp":0.0,"tv":0.0,"id":7797764}]}]}
{"op":"mcm","clk":"1002884495","pt":1580647044325,"mc":[{"id":"1.168224578","rc":[{"batl":[[0,1.84,183.34],[1,1.86,161.08],[2,1.9,42.01]],"ltp":0.0,"tv":0.0,"id":7797764}]}]}
{"op":"mcm","clk":"1002888068","pt":1580647061448,"mc":[{"id":"1.168224578","rc":[{"batb":[[0,1.73,23.76],[1,1.57,33.13],[2,1.46,435.7]],"ltp":0.0,"tv":0.0,"id":7797764},{"batb":[[1,2.04,26.36],[2,1.97,394.86]],"ltp":2.3,"tv":35.46,"id":2284304}]}]}
{"op":"mcm","clk":"1002888086","pt":1580647061553,"mc":[{"id":"1.168224578","rc":[{"batb":[[0,1.57,33.13],[1,1.46,435.7],[2,1.01,15.51]],"ltp":0.0,"tv":0.0,"id":7797764},{"batb":[[0,2.04,26.36],[1,1.97,394.86],[2,1.01,15.51]],"ltp":2.3,"tv":35.46,"id":2284304}]}]}
{"op":"mcm","clk":"1002889129","pt":1580647066353,"mc":[{"id":"1.168224578","rc":[{"batb":[[0,1.73,124.86],[1,1.71,209.82],[2,1.57,33.13]],"batl":[[0,1.8,176.2],[1,1.82,172.49]],"ltp":0.0,"tv":0.0,"id":7797764}]}]}
{"op":"mcm","clk":"1002890174","pt":1580647071369,"mc":[{"id":"1.168224578","rc":[{"batb":[[0,1.57,33.13],[1,1.46,435.7],[2,1.01,15.51]],"ltp":0.0,"tv":0.0,"id":7797764}]}]}
{"op":"mcm","clk":"1002891037","pt":1580647075475,"mc":[{"id":"1.168224578","rc":[{"batb":[[0,1.6,164.51],[1,1.59,137.06],[2,1.57,33.13]],"batl":[[0,1.97,157.01],[1,1.99,131.25]],"ltp":0.0,"tv":0.0,"id":7797764}]}]}
{"op":"mcm","clk":"1002891854","pt":1580647079461,"mc":[{"id":"1.168224578","rc":[{"batb":[[0,1.57,33.13],[1,1.46,435.7],[2,1.01,15.51]],"ltp":0.0,"tv":0.0,"id":7797764}]}]}
{"op":"mcm","clk":"1002892224","pt":1580647081185,"mc":[{"id":"1.168224578","rc":[{"batb":[[1,1.01,15.51],[2,1.01,0]],"ltp":0.0,"tv":0.0,"id":7797764},{"batb":[[1,1.01,15.51],[2,1.01,0]],"ltp":2.3,"tv":35.46,"id":2284304}]}]}
{"op":"mcm","clk":"1002892499","pt":1580647082478,"mc":[{"id":"1.168224578","rc":[{"batb":[[0,1.88,159.43],[1,1.86,158.94],[2,1.57,33.13]],"ltp":0.0,"tv":0.0,"id":7797764}]}]}
{"op":"mcm","clk":"1002892678","pt":1580647083408,"mc":[{"id":"1.168224578","rc":[{"batb":[[1,1.87,18.33],[2,1.86,158.94]],"ltp":0.0,"tv":0.0,"id":7797764},{"batb":[[1,1.9,16.44],[2,1.01,15.51]],"ltp":2.3,"tv":35.46,"id":2284304}]}]}
{"op":"mcm","clk":"1002892879","pt":1580647084374,"mc":[{"id":"1.168224578","rc":[{"batl":[[2,2.02,41.17]],"ltp":0.0,"tv":0.0,"id":7797764},{"batb":[[1,1.99,42.01],[2,1.9,16.44]],"ltp":2.3,"tv":35.46,"id":2284304}]}]}
{"op":"mcm","clk":"1002895784","pt":1580647098443,"mc":[{"id":"1.168224578","rc":[{"batb":[[0,1.87,18.33],[1,1.71,24.63],[2,1.55,420.5]],"batl":[[0,2.02,41.17],[1,1.99,0],[2,2.02,0]],"ltp":0.0,"tv":0.0,"id":7797764}]}]}
{"op":"mcm","clk":"1002895990","pt":1580647099424,"mc":[{"id":"1.168224578","rc":[{"batb":[[0,1.71,24.63],[1,1.55,420.5],[2,1.01,15.51]],"ltp":0.0,"tv":0.0,"id":7797764},{"batb":[[0,1.9,16.44],[1,1.7,409.32],[2,1.01,15.51]],"ltp":2.3,"tv":35.46,"id":2284304}]}]}
{"op":"mcm","clk":"1002896413","pt":1580647101357,"mc":[{"id":"1.168224578","rc":[{"batb":[[0,1.73,144.79],[1,1.71,234.53],[2,1.55,420.5]],"batl":[[0,2.1,202.55],[1,2.12,109.24]],"ltp":0.0,"tv":0.0,"id":7797764}]}]}
{"op":"mcm","clk":"1002896591","pt":1580647102223,"mc":[{"id":"1.168224578","rc":[{"batb":[[0,1.71,24.63],[1,1.55,420.5],[2,1.01,15.51]],"ltp":0.0,"tv":0.0,"id":7797764}]}]}
{"op":"mcm","clk":"1002897208","pt":1580647105157,"mc":[{"id":"1.168224578","rc":[{"batb":[[0,1.92,141.73],[1,1.9,165.05],[2,1.7,409.32]],"batl":[[0,2.02,203.93],[1,2.04,122.04]],"ltp":2.3,"tv":35.46,"id":2284304}]}]}
{"op":"mcm","clk":"1002897511","pt":1580647106454,"mc":[{"id":"1.168224578","rc":[{"batb":[[0,2,29.51],[1,1.87,18.49],[2,1.55,420.5]],"batl":[[0,2.1,37.81]],"ltp":0.0,"tv":0.0,"id":7797764},{"batb":[[1,1.9,211.27],[2,1.81,19.28]],"ltp":2.3,"tv":35.46,"id":2284304}]}]}
{"op":"mcm","clk":"1002899933","pt":1580647118223,"mc":[{"id":"1.168224578","rc":[{"batb":[[0,1.87,18.49],[1,1.55,420.5],[2,1.01,15.51]],"ltp":0.0,"tv":0.0,"id":7797764},{"batb":[[0,1.9,46.21],[1,1.81,19.28],[2,1.7,409.32]],"ltp":2.3,"tv":35.46,"id":2284304}]}]}
{"op":"mcm","clk":"1002900171","pt":1580647119411,"mc":[{"id":"1.168224578","rc":[{"batb":[[0,1.81,19.28],[1,1.7,409.32],[2,1.01,15.51]],"ltp":2.3,"tv":35.46,"id":2284304}]}]}
{"op":"mcm","clk":"1002900571","pt":1580647121402,"mc":[{"id":"1.168224578","rc":[{"batb":[[0,1.85,155.94],[1,1.83,167.6],[2,1.81,19.28]],"batl":[[0,2.16,188.76],[1,2.18,100.91]],"ltp":2.3,"tv":35.46,"id":2284304}]}]}
{"op":"mcm","clk":"1002900966","pt":1580647123342,"mc":[{"id":"1.168224578","rc":[{"batb":[[1,1.01,15.51],[2,1.01,0]],"ltp":0.0,"tv":0.0,"id":7797764}]}]}
{"op":"mcm","clk":"1002901396","pt":1580647125321,"mc":[{"id":"1.168224578","rc":[{"batb":[[0,2.12,25.02],[1,2.02,28.8],[2,1.87,18.49]],"ltp":0.0,"tv":0.0,"id":7797764},{"batl":[[0,1.93,117.28],[1,1.95,139.62]],"ltp":2.3,"tv":35.46,"id":2284304}]}]}
{"op":"mcm","clk":"1002901620","pt":1580647126435,"mc":[{"id":"1.168224578","rc":[{"batb":[[2,1.97,42.85]],"batl":[[0,2.18,35.29]],"ltp":0.0,"tv":0.0,"id":7797764},{"batb":[[0,1.85,204.67]],"batl":[[2,2.02,41.17]],"ltp":2.3,"tv":35.46,"id":2284304}]}]}
{"op":"mcm","clk":"1002903594","pt":1580647136485,"mc":[{"id":"1.168224578","rc":[{"batb":[[0,1.85,48.73],[1,1.81,19.28],[2,1.75,21.4]],"batl":[[0,2.02,41.17],[1,1.95,0],[2,2.02,0]],"ltp":2.3,"tv":35.46,"id":2284304}]}]}
{"op":"mcm","clk":"1002903797","pt":1580647137464,"mc":[{"id":"1.168224578","rc":[{"batb":[[0,2.02,28.8],[1,1.67,409.76],[2,1.01,15.51]],"ltp":0.0,"tv":0.0,"id":7797764},{"batb":[[0,1.75,21.4],[1,1.58,416.47],[2,1.01,15.51]],"ltp":2.3,"tv":35.46,"id":2284304}]}]}
{"op":"mcm","clk":"1002904187","pt":1580647139377,"mc":[{"id":"1.168224578","rc":[{"batb":[[0,1.82,110.53],[1,1.8,176.62],[2,1.75,21.4]],"batl":[[0,2,132.8],[1,2.02,125.65]],"ltp":2.3,"tv":35.46,"id":2284304}]}]}
{"op":"mcm","clk":"1002904360","pt":1580647140308,"mc":[{"id":"1.168224578","rc":[{"batb":[[0,2,29.19]],"ltp":0.0,"tv":0.0,"id":7797764},{"batb":[[2,1.76,21.17]],"ltp":2.3,"tv":35.46,"id":2284304}]}]}
{"op":"mcm","clk":"1002905025","pt":1580647143465,"mc":[{"id":"1.168224578","rc":[{"batl":[[0,1.89,110.87],[1,1.91,148.74]],"ltp":2.3,"tv":35.46,"id":2284304}]}]}
{"op":"mcm","clk":"1002905198","pt":1580647144393,"mc":[{"id":"1.168224578","rc":[{"batb":[[0,2.18,22.74],[1,1.99,30.06],[2,1.67,409.76]],"ltp":0.0,"tv":0.0,"id":7797764}]}]}
{"op":"mcm","clk":"1002905329","pt":1580647144933,"mc":[{"id":"1.168224578","rc":[{"batb":[[1,2.04,40.33],[2,1.99,30.06]],"batl":[[0,2.24,33.61]],"ltp":0.0,"tv":0.0,"id":7797764},{"batb":[[2,1.79,52.93]],"batl":[[2,1.96,42.01]],"ltp":2.3,"tv":35.46,"id":2284304}]}]}
{"op":"mcm","clk":"1002907228","pt":1580647154587,"mc":[{"id":"1.168224578","rc":[{"batb":[[0,1.79,52.93],[1,1.76,21.17],[2,1.59,30.21]],"ltp":2.3,"tv":35.46,"id":2284304}]}]}
{"op":"mcm","clk":"1002907839","pt":1580647157433,"mc":[{"id":"1.168224578","rc":[{"batb":[[0,1.81,187.75],[1,1.79,233.23],[2,1.76,21.17]],"ltp":2.3,"tv":35.46,"id":2284304}]}]}
{"op":"mcm","clk":"1002909882","pt":1580647167440,"mc":[{"id":"1.168224578","rc":[{"batb":[[0,1.79,52.93],[1,1.76,21.17],[2,1.59,30.21]],"batl":[[0,1.96,42.01],[1,1.91,0],[2,1.96,0]],"ltp":2.3,"tv":35.46,"id":2284304}]}]}
{"op":"mcm","clk":"1002909950","pt":1580647167752,"mc":[{"id":"1.168224578","rc":[{"batb":[[0,2.04,40.33],[1,1.99,30.06],[2,1.67,409.76]],"ltp":0.0,"tv":0.0,"id":7797764},{"batb":[[1,1.59,30.21],[2,1.58,416.47]],"ltp":2.3,"tv":35.46,"id":2284304}]}]}
{"op":"mcm","clk":"1002910309","pt":1580647169454,"mc":[{"id":"1.168224578","rc":[{"batb":[[0,1.99,30.06],[1,1.67,409.76],[2,1.01,15.51]],"ltp":0.0,"tv":0.0,"id":7797764},{"batb":[[0,1.59,30.21],[1,1.58,416.47],[2,1.01,15.51]],"ltp":2.3,"tv":35.46,"id":2284304}]}]}
{"op":"mcm","clk":"1002910499","pt":1580647170432,"mc":[{"id":"1.168224578","rc":[{"batb":[[0,1.63,210.51],[1,1.62,128.31],[2,1.59,30.21]],"batl":[[0,2.04,112.56],[1,2.06,118.73]],"ltp":2.3,"tv":35.46,"id":2284304}]}]}
{"op":"mcm","clk":"1002910716","pt":1580647171458,"mc":[{"id":"1.168224578","rc":[{"batb":[[0,1.98,30.45]],"ltp":0.0,"tv":0.0,"id":7797764},{"batb":[[0,1.59,29.82],[1,1.58,416.47],[2,1.01,15.51]],"ltp":2.3,"tv":35.46,"id":2284304}]}]}
{"op":"mcm","clk":"1002911028","pt":1580647172948,"mc":[{"id":"1.168224578","rc":[{"batb":[[0,1.77,199.52],[1,1.75,194.47],[2,1.59,29.82]],"batl":[[0,1.85,149],[1,1.87,158.73]],"ltp":2.3,"tv":35.46,"id":2284304}]}]}
{"op":"mcm","clk":"1002911966","pt":1580647177222,"mc":[{"id":"1.168224578","rc":[{"batb":[[0,1.59,29.82],[1,1.58,416.47],[2,1.01,15.51]],"ltp":2.3,"tv":35.46,"id":2284304}]}]}
{"op":"mcm","clk":"1002912565","pt":1580647180146,"mc":[{"id":"1.168224578","rc":[{"batb":[[0,1.63,210.51],[1,1.62,128.31],[2,1.59,29.82]],"batl":[[0,2.04,112.56],[1,2.06,118.73]],"ltp":2.3,"tv":35.46,"id":2284304}]}]}
{"op":"mcm","clk":"1002913175","pt":1580647183039,"mc":[{"id":"1.168224578","rc":[{"batb":[[0,1.59,29.82],[1,1.58,416.47],[2,1.01,15.51]],"ltp":2.3,"tv":35.46,"id":2284304}]}]}
{"op":"mcm","clk":"1002913947","pt":1580647186474,"mc":[{"id":"1.168224578","rc":[{"batb":[[1,1.91,45.37],[2,1.67,409.76]],"batl":[[0,2.1,37.81]],"ltp":0.0,"tv":0.0,"id":7797764},{"batb":[[0,1.95,149.88],[1,1.93,141.62],[2,1.91,45.37]],"batl":[[2,2.1,37.81]],"ltp":2.3,"tv":35.46,"id":2284304}]}]}
{"op":"mcm","clk":"1002914034","pt":1580647186846,"mc":[{"id":"1.168224578","rc":[{"batb":[[2,1.85,19.12]],"ltp":0.0,"tv":0.0,"id":7797764},{"batb":[[2,1.92,15.97]],"ltp":2.3,"tv":35.46,"id":2284304}]}]}
{"op":"mcm","clk":"1002917916","pt":1580647205233,"mc":[{"id":"1.168224578","rc":[{"batb":[[0,1.91,45.37],[1,1.85,19.12],[2,1.67,409.76]],"ltp":0.0,"tv":0.0,"id":7797764},{"batb":[[0,1.91,45.37],[1,1.74,21.95],[2,1.67,409.76]],"batl":[[0,2.1,37.81],[1,2.06,0],[2,2.1,0]],"ltp":2.3,"tv":35.46,"id":2284304}]}]}
{"op":"mcm","clk":"1002917978","pt":1580647205560,"mc":[{"id":"1.168224578","rc":[{"batb":[[0,1.85,19.12],[1,1.67,409.76],[2,1.01,15.51]],"ltp":0.0,"tv":0.0,"id":7797764},{"batb":[[0,1.74,21.95],[1,1.67,409.76],[2,1.01,15.51]],"ltp":2.3,"tv":35.46,"id":2284304}]}]}
{"op":"mcm","clk":"1002918489","pt":1580647208101,"mc":[{"id":"1.168224578","rc":[{"batb":[[0,1.78,135],[1,1.76,190.6],[2,1.74,21.95]],"batl":[[0,2.18,115.53],[1,2.2,98.45]],"ltp":2.3,"tv":35.46,"id":2284304}]}]}
{"op":"mcm","clk":"1002920235","pt":1580647216400,"mc":[{"id":"1.168224578","rc":[{"batb":[[0,2.22,21.79],[1,1.98,30.45],[2,1.85,19.12]],"ltp":0.0,"tv":0.0,"id":7797764},{"batl":[[0,1.85,120.3],[1,1.87,158.8]],"ltp":2.3,"tv":35.46,"id":2284304}]}]}
{"op":"mcm","clk":"1002920396","pt":1580647217201,"mc":[{"id":"1.168224578","rc":[{"batb":[[1,2.08,38.65],[2,1.98,30.45]],"batl":[[0,2.3,31.93]],"ltp":0.0,"tv":0.0,"id":7797764},{"batb":[[1,1.77,53.77],[2,1.76,190.6]],"batl":[[2,1.94,42.01]],"ltp":2.3,"tv":35.46,"id":2284304}]}]}
{"op":"mcm","clk":"1002922332","pt":1580647226073,"mc":[{"id":"1.168224578","rc":[{"batb":[[0,2.08,38.65],[1,1.98,30.45],[2,1.67,409.76]],"ltp":0.0,"tv":0.0,"id":7797764},{"batb":[[0,1.77,53.77],[1,1.55,420.5],[2,1.54,33.52]],"batl":[[0,1.94,42.01],[1,1.87,0],[2,1.94,0]],"ltp":2.3,"tv":35.46,"id":2284304}]}]}
{"op":"mcm","clk":"1002922636","pt":1580647227645,"mc":[{"id":"1.168224578","rc":[{"batb":[[0,1.98,30.45],[1,1.67,409.76],[2,1.01,15.51]],"ltp":0.0,"tv":0.0,"id":7797764},{"batb":[[0,1.55,420.5],[1,1.54,33.52],[2,1.01,15.51]],"ltp":2.3,"tv":35.46,"id":2284304}]}]}
{"op":"mcm","clk":"1002923304","pt":1580647230821,"mc":[{"id":"1.168224578","rc":[{"batb":[[1,1.01,15.51],[2,1.01,0]],"ltp":0.0,"tv":0.0,"id":7797764},{"batb":[[0,1.54,33.52],[1,1.01,15.51],[2,1.01,0]],"ltp":2.3,"tv":35.46,"id":2284304}]}]}
{"op":"mcm","clk":"1002923669","pt":1580647232472,"mc":[{"id":"1.168224578","rc":[{"batl":[[0,2.72,24.37]],"ltp":0.0,"tv":0.0,"id":7797764},{"batb":[[0,1.57,73.1],[1,1.54,33.52],[2,1.01,15.51]],"ltp":2.3,"tv":35.46,"id":2284304}]}]}
{"op":"mcm","clk":"1002923858","pt":1580647233293,"mc":[{"id":"1.168224578","rc":[{"batb":[[0,2.66,13.45],[1,2.42,29.41],[2,2.26,20.69]],"ltp":0.0,"tv":0.0,"id":7797764},{"batb":[[0,1.57,266.8],[1,1.56,147.69],[2,1.54,33.52]],"batl":[[0,1.63,184.24],[1,1.64,121.4]],"ltp":2.3,"tv":35.46,"id":2284304}]}]}
{"op":"mcm","clk":"1002924090","pt":1580647234411,"mc":[{"id":"1.168224578","rc":[{"batl":[[2,1.7,42.01]],"ltp":2.3,"tv":35.46,"id":2284304}]}]}
{"op":"mcm","clk":"1002924413","pt":1580647235912,"mc":[{"id":"1.168224578","rc":[{"batb":[[0,1.57,291.46]],"ltp":2.3,"tv":35.46,"id":2284304}]}]}
{"op":"mcm","clk":"1002926647","pt":1580647246445,"mc":[{"id":"1.168224578","rc":[{"batb":[[0,2.42,29.41],[1,2.26,20.69],[2,1.92,394.91]],"ltp":0.0,"tv":0.0,"id":7797764},{"batb":[[0,1.57,73.1],[1,1.4,451],[2,1.37,55.94]],"batl":[[0,1.7,42.01],[1,1.64,0],[2,1.7,0]],"ltp":2.3,"tv":35.46,"id":2284304}]}]}
{"op":"mcm","clk":"1002926882","pt":1580647247506,"mc":[{"id":"1.168224578","rc":[{"batb":[[0,2.26,20.69],[1,1.92,394.91],[2,1.01,15.51]],"ltp":0.0,"tv":0.0,"id":7797764},{"batb":[[0,1.4,451],[1,1.37,55.94],[2,1.01,15.51]],"ltp":2.3,"tv":35.46,"id":2284304}]}]}
{"op":"mcm","clk":"1002927297","pt":1580647249437,"mc":[{"id":"1.168224578","rc":[{"batb":[[2,1.36,400.28]],"batl":[[0,1.82,162.9],[1,1.84,166.84]],"ltp":2.3,"tv":35.46,"id":2284304}]}]}
{"op":"mcm","clk":"1002927848","pt":1580647251819,"mc":[{"id":"1.168224578","rc":[{"batb":[[1,1.01,15.51],[2,1.01,0]],"ltp":0.0,"tv":0.0,"id":7797764},{"batb":[[0,1.37,55.94],[1,1.36,400.28],[2,1.35,277.15]],"ltp":2.3,"tv":35.46,"id":2284304}]}]}
{"op":"mcm","clk":"1002928101","pt":1580647253001,"mc":[{"id":"1.168224578","rc":[{"batl":[[0,1.41,341.73],[1,1.42,210.26]],"ltp":2.3,"tv":35.46,"id":2284304}]}]}
{"op":"mcm","clk":"1002928419","pt":1580647254402,"mc":[{"id":"1.168224578","rc":[{"batb":[[0,3.4,17.94],[1,2.88,10.94],[2,1.01,15.51]],"ltp":0.0,"tv":0.0,"id":7797764}]}]}
{"op":"mcm","clk":"1002928458","pt":1580647254617,"mc":[{"id":"1.168224578","rc":[{"batl":[[0,3.7,15.12]],"ltp":0.0,"tv":0.0,"id":7797764},{"batb":[[0,1.37,169.37]],"ltp":2.3,"tv":35.46,"id":2284304}]}]}
{"op":"mcm","clk":"1002928772","pt":1580647256123,"mc":[{"id":"1.168224578","rc":[{"batb":[[2,2.3,385.09]],"ltp":0.0,"tv":0.0,"id":7797764}]}]}
{"op":"mcm","clk":"1002929117","pt":1580647257817,"mc":[{"id":"1.168224578","rc":[{"batl":[[2,1.58,279.78]],"ltp":2.3,"tv":35.46,"id":2284304}]}]}
{"op":"mcm","clk":"1002929760","pt":1580647261151,"mc":[{"id":"1.168224578","rc":[{"batl":[[2,1.58,0]],"ltp":2.3,"tv":35.46,"id":2284304}]}]}
{"op":"mcm","clk":"1002930317","pt":1580647263441,"mc":[{"id":"1.168224578","rc":[{"batb":[[0,2.88,10.94],[1,2.3,385.09],[2,1.01,15.51]],"ltp":0.0,"tv":0.0,"id":7797764},{"batb":[[0,1.37,113.43],[1,1.25,594.79],[2,1.01,15.51]],"ltp":2.3,"tv":35.46,"id":2284304}]}]}
{"op":"mcm","clk":"1002930389","pt":1580647263758,"mc":[{"id":"1.168224578","rc":[{"batb":[[0,1.25,594.79],[1,1.01,15.51],[2,1.01,0]],"ltp":2.3,"tv":35.46,"id":2284304}]}]}
{"op":"mcm","clk":"1002930949","pt":1580647266446,"mc":[{"id":"1.168224578","rc":[{"batb":[[1,1.22,286.64],[2,1.21,516.85]],"batl":[[0,1.54,244.68],[1,1.55,148.65]],"ltp":2.3,"tv":35.46,"id":2284304}]}]}
{"op":"mcm","clk":"1002932064","pt":1580647271805,"mc":[{"id":"1.168224578","rc":[{"batb":[[1,1.01,15.51],[2,1.01,0]],"ltp":0.0,"tv":0.0,"id":7797764},{"batb":[[0,1.25,89.7]],"ltp":2.3,"tv":35.46,"id":2284304}]}]}
{"op":"mcm","clk":"1002932620","pt":1580647274456,"mc":[{"id":"1.168224578","rc":[{"batb":[[0,4.4,18.8],[1,3.55,16.05],[2,2.88,10.94]],"batl":[[0,5.9,8.4]],"ltp":0.0,"tv":0.0,"id":7797764},{"trd":[[1.25,179.39]],"batb":[[0,1.22,286.64],[1,1.21,516.85],[2,1.2,168.04]],"batl":[[0,1.25,459.94],[1,1.26,374.87]],"ltp":1.25,"tv":214.85,"id":2284304}],"tv":214.85}]}
{"op":"mcm","clk":"1002932675","pt":1580647274766,"mc":[{"id":"1.168224578","rc":[{"batb":[[2,1.01,15.51]],"ltp":0.0,"tv":0.0,"id":7797764},{"batl":[[0,1.25,417.93]],"ltp":1.25,"tv":214.85,"id":2284304}]}]}
{"op":"mcm","clk":"1002932977","pt":1580647276299,"mc":[{"id":"1.168224578","rc":[{"batb":[[2,2.8,375.33]],"ltp":0.0,"tv":0.0,"id":7797764}]}]}
{"op":"mcm","clk":"1002933189","pt":1580647277265,"mc":[{"id":"1.168224578","rc":[{"batb":[[0,5,10.08],[1,4.4,18.8],[2,3.55,16.05]],"ltp":0.0,"tv":0.0,"id":7797764},{"batb":[[0,1.22,329.21]],"batl":[[0,1.25,507]],"ltp":1.25,"tv":214.85,"id":2284304}]}]}
{"op":"mcm","clk":"1002933431","pt":1580647278492,"mc":[{"id":"1.168224578","rc":[{"batl":[[2,1.37,373.05]],"ltp":1.25,"tv":214.85,"id":2284304}]}]}
{"op":"mcm","clk":"1002933838","pt":1580647280470,"mc":[{"id":"1.168224578","rc":[{"batl":[[2,1.37,0]],"ltp":1.25,"tv":214.85,"id":2284304}]}]}
{"op":"mcm","clk":"1002934224","pt":1580647282483,"mc":[{"id":"1.168224578","rc":[{"batb":[[1,4.6,17.07],[2,3.7,14.63]],"ltp":0.0,"tv":0.0,"id":7797764},{"batb":[[0,1.23,95.76],[1,1.22,329.21],[2,1.21,516.85]],"ltp":1.25,"tv":214.85,"id":2284304}]}]}
{"op":"mcm","clk":"1002935416","pt":1580647288473,"mc":[{"id":"1.168224578","rc":[{"batb":[[0,1.23,95.52]],"ltp":1.25,"tv":214.85,"id":2284304}]}]}
{"op":"mcm","clk":"1002936984","pt":1580647296906,"mc":[{"id":"1.168224578","rc":[{"batb":[[1,1.22,295.41]],"ltp":1.25,"tv":214.85,"id":2284304}]}]}
{"op":"mcm","clk":"1002937569","pt":1580647299891,"mc":[{"id":"1.168224578","rc":[{"batl":[[0,1.25,540.07]],"ltp":1.25,"tv":214.85,"id":2284304}]}]}
{"op":"mcm","clk":"1002938123","pt":1580647302683,"mc":[{"id":"1.168224578","rc":[{"trd":[[1.23,191.04]],"batb":[[0,1.22,295.41],[1,1.21,516.85],[2,1.2,168.04]],"batl":[[0,1.23,61.89],[1,1.25,540.07],[2,1.26,374.87]],"ltp":1.23,"tv":405.89,"id":2284304}],"tv":405.89}]}
{"op":"mcm","clk":"1002938577","pt":1580647304821,"mc":[{"id":"1.168224578","rc":[{"batb":[[0,1.22,235.96]],"batl":[[1,1.25,459.94],[2,1.26,0]],"ltp":1.23,"tv":405.89,"id":2284304}]}]}
{"op":"mcm","clk":"1002938922","pt":1580647306429,"mc":[{"id":"1.168224578","rc":[{"batl":[[0,1.25,459.94],[1,1.25,0]],"ltp":1.23,"tv":405.89,"id":2284304}]}]}
{"op":"mcm","clk":"1002939021","pt":1580647306901,"mc":[{"id":"1.168224578","rc":[{"batb":[[1,4.8,15.97],[2,3.8,13.77]],"ltp":0.0,"tv":0.0,"id":7797764},{"batb":[[0,1.22,336.04]],"ltp":1.23,"tv":405.89,"id":2284304}]}]}
{"op":"mcm","clk":"1002939205","pt":1580647307801,"mc":[{"id":"1.168224578","rc":[{"batl":[[0,1.24,154.43],[1,1.25,459.94]],"ltp":1.23,"tv":405.89,"id":2284304}]}]}
{"op":"mcm","clk":"1002939554","pt":1580647309524,"mc":[{"id":"1.168224578","rc":[{"trd":[[1.22,123.78]],"batb":[[0,1.22,274.15]],"ltp":1.22,"tv":529.67,"id":2284304}],"tv":529.67}]}
{"op":"mcm","clk":"1002940238","pt":1580647313010,"mc":[{"id":"1.168224578","rc":[{"batb":[[0,1.22,308.47]],"ltp":1.22,"tv":529.67,"id":2284304}]}]}
{"op":"mcm","clk":"1002941613","pt":1580647320032,"mc":[{"id":"1.168224578","rc":[{"batl":[[0,1.24,184.51]],"ltp":1.22,"tv":529.67,"id":2284304}]}]}
{"op":"mcm","clk":"1002942299","pt":1580647323226,"mc":[{"id":"1.168224578","rc":[{"batb":[[0,1.22,100.08]],"ltp":1.22,"tv":529.67,"id":2284304}]}]}
{"op":"mcm","clk":"1002942991","pt":1580647326343,"mc":[{"id":"1.168224578","rc":[{"batb":[[1,1.21,663.73],[2,1.2,560.36]],"batl":[[0,1.24,241.5]],"ltp":1.22,"tv":529.67,"id":2284304}]}]}
{"op":"mcm","clk":"1002943076","pt":1580647326724,"mc":[{"id":"1.168224578","rc":[{"batb":[[2,1.2,392.32]],"ltp":1.22,"tv":529.67,"id":2284304}]}]}
{"op":"mcm","clk":"1002943637","pt":1580647329639,"mc":[{"id":"1.168224578","rc":[{"batl":[[0,6,8.4]],"ltp":0.0,"tv":0.0,"id":7797764}]}]}
{"op":"mcm","clk":"1002944746","pt":1580647335259,"mc":[{"id":"1.168224578","rc":[{"batb":[[1,1.21,597.45]],"ltp":1.22,"tv":529.67,"id":2284304}]}]}
{"op":"mcm","clk":"1002945333","pt":1580647338254,"mc":[{"id":"1.168224578","rc":[{"batb":[[2,1.2,459.16]],"batl":[[0,1.24,306.16]],"ltp":1.22,"tv":529.67,"id":2284304}]}]}
{"op":"mcm","clk":"1002951042","pt":1580647366489,"mc":[{"id":"1.168224578","rc":[{"batb":[[1,3.8,13.77],[2,2.8,375.33]],"ltp":0.0,"tv":0.0,"id":7797764},{"batb":[[0,1.17,135.8],[1,1.14,627.92],[2,1.01,15.51]],"batl":[[0,1.25,42.01],[1,1.25,0]],"ltp":1.22,"tv":529.67,"id":2284304}]}]}
{"op":"mcm","clk":"1002951291","pt":1580647367549,"mc":[{"id":"1.168224578","rc":[{"batb":[[0,3.8,13.77],[1,2.8,375.33],[2,1.01,15.51]],"ltp":0.0,"tv":0.0,"id":7797764}]}]}
{"op":"mcm","clk":"1002951678","pt":1580647369367,"mc":[{"id":"1.168224578","rc":[{"batb":[[0,3.85,13.3],[1,3.8,13.77],[2,2.8,375.33]],"ltp":0.0,"tv":0.0,"id":7797764},{"batb":[[0,1.17,487.91],[1,1.16,720.62],[2,1.14,627.92]],"batl":[[0,1.34,411.1],[1,1.35,265.75]],"ltp":1.22,"tv":529.67,"id":2284304}]}]}
{"op":"mcm","clk":"1002951882","pt":1580647370339,"mc":[{"id":"1.168224578","rc":[{"batb":[[1,2.8,375.33],[2,1.01,15.51]],"ltp":0.0,"tv":0.0,"id":7797764}]}]}
{"op":"mcm","clk":"1002952794","pt":1580647374846,"mc":[{"id":"1.168224578","rc":[{"batb":[[0,1.17,135.8],[1,1.14,627.92],[2,1.01,15.51]],"ltp":1.22,"tv":529.67,"id":2284304}]}]}
{"op":"mcm","clk":"1002953131","pt":1580647376439,"mc":[{"id":"1.168224578","rc":[{"batb":[[1,1.01,15.51],[2,1.01,0]],"ltp":1.22,"tv":529.67,"id":2284304}]}]}
{"op":"mcm","clk":"1002953561","pt":1580647378422,"mc":[{"id":"1.168224578","rc":[{"batb":[[0,1.3,324.77],[1,1.29,352.51],[2,1.17,135.8]],"ltp":1.22,"tv":529.67,"id":2284304}]}]}
{"op":"mcm","clk":"1002953774","pt":1580647379435,"mc":[{"id":"1.168224578","rc":[{"batb":[[0,3.95,13.44],[1,3.85,13.3],[2,3.05,23.6]],"batl":[[0,4.6,10.92]],"ltp":0.0,"tv":0.0,"id":7797764},{"batb":[[0,1.31,69.63],[1,1.3,324.77],[2,1.29,352.51]],"batl":[[0,1.34,453.11]],"ltp":1.22,"tv":529.67,"id":2284304}]}]}
{"op":"mcm","clk":"1002956636","pt":1580647392832,"mc":[{"id":"1.168224578","rc":[{"batb":[[1,3.05,23.6],[2,2.8,375.33]],"ltp":0.0,"tv":0.0,"id":7797764},{"batb":[[0,1.27,155.44],[1,1.23,96.07],[2,1.22,523]],"batl":[[0,1.34,42.01],[1,1.35,0]],"ltp":1.22,"tv":529.67,"id":2284304}]}]}
{"op":"mcm","clk":"1002956805","pt":1580647393655,"mc":[{"id":"1.168224578","rc":[{"batb":[[0,3.05,23.6],[1,2.8,375.33],[2,1.01,15.51]],"ltp":0.0,"tv":0.0,"id":7797764},{"batb":[[0,1.23,96.07],[1,1.22,523],[2,1.01,15.51]],"ltp":1.22,"tv":529.67,"id":2284304}]}]}
{"op":"mcm","clk":"1002957140","pt":1580647395415,"mc":[{"id":"1.168224578","rc":[{"batb":[[0,1.23,441.11],[1,1.22,1017.93]],"batl":[[0,1.49,241.71],[1,1.5,169.28]],"ltp":1.22,"tv":529.67,"id":2284304}]}]}
{"op":"mcm","clk":"1002958168","pt":1580647400441,"mc":[{"id":"1.168224578","rc":[{"batb":[[1,1.22,494.93]],"batl":[[0,1.26,412.97],[1,1.27,365.57]],"ltp":1.22,"tv":529.67,"id":2284304}]}]}
{"op":"mcm","clk":"1002958342","pt":1580647401295,"mc":[{"id":"1.168224578","rc":[{"batb":[[0,4.8,10.92],[1,4.7,16.76],[2,3.6,15.89]],"batl":[[0,5.7,8.4]],"ltp":0.0,"tv":0.0,"id":7797764},{"batb":[[2,1.21,168.04]],"batl":[[1,1.27,407.58]],"ltp":1.22,"tv":529.67,"id":2284304}]}]}
{"op":"mcm","clk":"1002961180","pt":1580647414951,"mc":[{"id":"1.168224578","rc":[{"batb":[[1,3.6,15.89],[2,2.8,375.33]],"ltp":0.0,"tv":0.0,"id":7797764},{"batb":[[0,1.21,168.04],[1,1.17,137.38],[2,1.16,576.13]],"batl":[[0,1.27,42.01],[1,1.27,0]],"ltp":1.22,"tv":529.67,"id":2284304}]}]}
{"op":"mcm","clk":"1002961334","pt":1580647415644,"mc":[{"id":"1.168224578","rc":[{"batb":[[0,3.6,15.89],[1,2.8,375.33],[2,1.01,15.51]],"ltp":0.0,"tv":0.0,"id":7797764},{"batb":[[0,1.17,137.38],[1,1.16,576.13],[2,1.01,15.51]],"ltp":1.22,"tv":529.67,"id":2284304}]}]}
{"op":"mcm","clk":"1002961883","pt":1580647418332,"mc":[{"id":"1.168224578","rc":[{"batb":[[0,3.55,16.21]],"ltp":0.0,"tv":0.0,"id":7797764},{"batb":[[0,1.17,135.49]],"ltp":1.22,"tv":529.67,"id":2284304}]}]}
{"op":"mcm","clk":"1002962032","pt":1580647419017,"mc":[{"id":"1.168224578","rc":[{"batb":[[1,1.01,15.51],[2,1.01,0]],"ltp":1.22,"tv":529.67,"id":2284304}]}]}
{"op":"mcm","clk":"1002962162","pt":1580647419853,"mc":[{"id":"1.168224578","rc":[{"batb":[[0,1.25,378.76],[1,1.24,446.21],[2,1.17,135.49]],"batl":[[0,1.28,278.99],[1,1.29,337.7]],"ltp":1.22,"tv":529.67,"id":2284304}]}]}
{"op":"mcm","clk":"1002962601","pt":1580647422035,"mc":[{"id":"1.168224578","rc":[{"batb":[[2,1.18,549.72]],"ltp":1.22,"tv":529.67,"id":2284304}]}]}
{"op":"mcm","clk":"1002963320","pt":1580647425445,"mc":[{"id":"1.168224578","rc":[{"batb":[[0,1.18,549.72],[1,1.17,135.49],[2,1.01,15.51]],"ltp":1.22,"tv":529.67,"id":2284304}]}]}
{"op":"mcm","clk":"1002964188","pt":1580647429434,"mc":[{"id":"1.168224578","rc":[{"batb":[[1,1.17,689.1],[2,1.16,539.8]],"batl":[[0,1.38,236.59],[1,1.39,234.13]],"ltp":1.22,"tv":529.67,"id":2284304}]}]}
{"op":"mcm","clk":"1002965164","pt":1580647434206,"mc":[{"id":"1.168224578","rc":[{"batb":[[1,1.17,135.49],[2,1.01,15.51]],"ltp":1.22,"tv":529.67,"id":2284304}]}]}
{"op":"mcm","clk":"1002965473","pt":1580647435697,"mc":[{"id":"1.168224578","rc":[{"batb":[[1,1.01,15.51],[2,1.01,0]],"ltp":0.0,"tv":0.0,"id":7797764},{"batb":[[0,1.17,135.49],[1,1.01,15.51],[2,1.01,0]],"ltp":1.22,"tv":529.67,"id":2284304}]}]}
{"op":"mcm","clk":"1002965759","pt":1580647437112,"mc":[{"id":"1.168224578","rc":[{"batb":[[0,1.34,354.09],[1,1.33,300.21],[2,1.17,135.49]],"ltp":1.22,"tv":529.67,"id":2284304}]}]}
{"op":"mcm","clk":"1002966035","pt":1580647438307,"mc":[{"id":"1.168224578","rc":[{"batb":[[1,2.76,12.35],[2,1.01,15.51]],"ltp":0.0,"tv":0.0,"id":7797764},{"batb":[[0,1.35,60.27],[1,1.34,354.09],[2,1.33,300.21]],"ltp":1.22,"tv":529.67,"id":2284304}]}]}
{"op":"mcm","clk":"1002966227","pt":1580647439305,"mc":[{"id":"1.168224578","rc":[{"batb":[[0,3.6,15.96],[1,3.55,16.21],[2,2.76,12.35]],"batl":[[0,4.2,12.6]],"ltp":0.0,"tv":0.0,"id":7797764},{"batl":[[0,1.38,278.6]],"ltp":1.22,"tv":529.67,"id":2284304}]}]}
{"op":"mcm","clk":"1002968048","pt":1580647447666,"mc":[{"id":"1.168224578","rc":[{"batb":[[1,1.34,308.89]],"ltp":1.22,"tv":529.67,"id":2284304}]}]}
{"op":"mcm","clk":"1002968660","pt":1580647450605,"mc":[{"id":"1.168224578","rc":[{"batl":[[0,1.38,322.5]],"ltp":1.22,"tv":529.67,"id":2284304}]}]}
{"op":"mcm","clk":"1002969447","pt":1580647454284,"mc":[{"id":"1.168224578","rc":[{"batb":[[1,2.76,12.35],[2,2.3,385.09]],"ltp":0.0,"tv":0.0,"id":7797764},{"batb":[[0,1.31,135.27],[1,1.25,595.34],[2,1.01,15.51]],"batl":[[0,1.38,42.01],[1,1.39,0]],"ltp":1.22,"tv":529.67,"id":2284304}]}]}
{"op":"mcm","clk":"1002969730","pt":1580647455720,"mc":[{"id":"1.168224578","rc":[{"batb":[[0,2.76,12.35],[1,2.3,385.09],[2,1.01,15.51]],"ltp":0.0,"tv":0.0,"id":7797764},{"batb":[[0,1.25,595.34],[1,1.01,15.51],[2,1.01,0]],"ltp":1.22,"tv":529.67,"id":2284304}]}]}
{"op":"mcm","clk":"1002970393","pt":1580647458807,"mc":[{"id":"1.168224578","rc":[{"batb":[[0,1.25,90.25]],"ltp":1.22,"tv":529.67,"id":2284304}]}]}
{"op":"mcm","clk":"1002970931","pt":1580647461423,"mc":[{"id":"1.168224578","rc":[{"batb":[[0,1.38,168.66],[1,1.37,257.56],[2,1.25,90.25]],"batl":[[0,1.42,294.45],[1,1.43,206.4]],"ltp":1.22,"tv":529.67,"id":2284304}]}]}
{"op":"mcm","clk":"1002971140","pt":1580647462382,"mc":[{"id":"1.168224578","rc":[{"batb":[[2,1.28,485.89]],"ltp":1.22,"tv":529.67,"id":2284304}]}]}
{"op":"mcm","clk":"1002971341","pt":1580647463404,"mc":[{"id":"1.168224578","rc":[{"trd":[[1.37,222.24],[1.38,337.32]],"batb":[[0,1.37,146.44],[1,1.28,485.89],[2,1.25,90.25]],"ltp":1.37,"tv":1089.24,"id":2284304}],"tv":1089.24}]}
{"op":"mcm","clk":"1002971488","pt":1580647464096,"mc":[{"id":"1.168224578","rc":[{"batl":[[0,1.42,214.93],[1,1.43,0]],"ltp":1.37,"tv":1089.24,"id":2284304}]}]}
{"op":"mcm","clk":"1002971911","pt":1580647466247,"mc":[{"id":"1.168224578","rc":[{"batb":[[0,1.28,485.89],[1,1.25,90.25],[2,1.01,15.51]],"ltp":1.37,"tv":1089.24,"id":2284304}]}]}
{"op":"mcm","clk":"1002972526","pt":1580647468978,"mc":[{"id":"1.168224578","rc":[{"batb":[[2,1.24,471.75]],"ltp":1.37,"tv":1089.24,"id":2284304}]}]}
{"op":"mcm","clk":"1002973036","pt":1580647471397,"mc":[{"id":"1.168224578","rc":[{"batb":[[1,1.01,15.51],[2,1.01,0]],"ltp":0.0,"tv":0.0,"id":7797764},{"batb":[[0,1.25,90.25],[1,1.24,471.75],[2,1.23,476.43]],"batl":[[0,1.27,254.55],[1,1.28,356.42]],"ltp":1.37,"tv":1089.24,"id":2284304}]}]}
{"op":"mcm","clk":"1002973259","pt":1580647472355,"mc":[{"id":"1.168224578","rc":[{"batb":[[0,4.5,18.65],[1,3.2,20.54],[2,1.01,15.51]],"ltp":0.0,"tv":0.0,"id":7797764}]}]}
{"op":"mcm","clk":"1002973375","pt":1580647473000,"mc":[{"id":"1.168224578","rc":[{"batb":[[0,4.5,30.41]],"batl":[[0,5.3,9.24]],"ltp":0.0,"tv":0.0,"id":7797764}]}]}
{"op":"mcm","clk":"1002973660","pt":1580647474362,"mc":[{"id":"1.168224578","rc":[{"batb":[[2,2.62,379.26]],"ltp":0.0,"tv":0.0,"id":7797764},{"batl":[[1,1.28,398.43]],"ltp":1.37,"tv":1089.24,"id":2284304}]}]}
{"op":"mcm","clk":"1002977121","pt":1580647491397,"mc":[{"id":"1.168224578","rc":[{"batb":[[0,4.5,11.76]],"ltp":0.0,"tv":0.0,"id":7797764},{"batb":[[0,1.22,168.04],[1,1.18,549.72],[2,1.16,143.12]],"batl":[[0,1.28,42.01],[1,1.28,0]],"ltp":1.37,"tv":1089.24,"id":2284304}]}]}
{"op":"mcm","clk":"1002977191","pt":1580647491724,"mc":[{"id":"1.168224578","rc":[{"batb":[[0,3.2,20.54],[1,2.62,379.26],[2,1.01,15.51]],"ltp":0.0,"tv":0.0,"id":7797764},{"batb":[[0,1.18,549.72],[1,1.16,143.12],[2,1.01,15.51]],"ltp":1.37,"tv":1089.24,"id":2284304}]}]}
{"op":"mcm","clk":"1002977574","pt":1580647493624,"mc":[{"id":"1.168224578","rc":[{"batb":[[1,1.16,828.56],[2,1.15,416.34]],"batl":[[0,1.45,222.62],[1,1.46,190.52]],"ltp":1.37,"tv":1089.24,"id":2284304}]}]}
{"op":"mcm","clk":"1002978232","pt":1580647497091,"mc":[{"id":"1.168224578","rc":[{"batb":[[1,1.01,15.51],[2,1.01,0]],"ltp":0.0,"tv":0.0,"id":7797764},{"batb":[[0,1.16,828.56],[1,1.15,416.34],[2,1.01,15.51]],"ltp":1.37,"tv":1089.24,"id":2284304}]}]}
{"op":"mcm","clk":"1002978510","pt":1580647498412,"mc":[{"id":"1.168224578","rc":[{"batb":[[0,6,18.8],[1,4.4,19.51],[2,3.2,20.54]],"ltp":0.0,"tv":0.0,"id":7797764},{"batb":[[2,1.11,216.53]],"batl":[[0,1.19,688.4],[1,1.2,378.92]],"ltp":1.37,"tv":1089.24,"id":2284304}]}]}
{"op":"mcm","clk":"1002978676","pt":1580647499323,"mc":[{"id":"1.168224578","rc":[{"batb":[[0,6,27.21],[2,1.01,15.51]],"batl":[[0,7.4,5.88]],"ltp":0.0,"tv":0.0,"id":7797764},{"batl":[[1,1.2,420.93]],"ltp":1.37,"tv":1089.24,"id":2284304}]}]}
{"op":"mcm","clk":"1002978986","pt":1580647500821,"mc":[{"id":"1.168224578","rc":[{"batb":[[2,3,380.84]],"ltp":0.0,"tv":0.0,"id":7797764},{"batb":[[2,1.11,900.85]],"ltp":1.37,"tv":1089.24,"id":2284304}]}]}
{"op":"mcm","clk":"1002981128","pt":1580647510398,"mc":[{"id":"1.168224578","rc":[{"batb":[[0,6,8.4]],"ltp":0.0,"tv":0.0,"id":7797764},{"batb":[[0,1.11,900.85],[1,1.01,15.51],[2,1.11,0]],"batl":[[0,1.2,42.01],[1,1.2,0]],"ltp":1.37,"tv":1089.24,"id":2284304}]}]}
{"op":"mcm","clk":"1002981391","pt":1580647511683,"mc":[{"id":"1.168224578","rc":[{"batb":[[0,4.4,19.51],[1,3,380.84],[2,1.01,15.51]],"ltp":0.0,"tv":0.0,"id":7797764}]}]}
{"op":"mcm","clk":"1002981697","pt":1580647513180,"mc":[{"id":"1.168224578","rc":[{"batb":[[0,1.12,407.93],[1,1.11,1636.9],[2,1.01,15.51]],"batl":[[0,1.28,366.3],[1,1.29,339.38]],"ltp":1.37,"tv":1089.24,"id":2284304}]}]}
{"op":"mcm","clk":"1002981809","pt":1580647513688,"mc":[{"id":"1.168224578","rc":[{"batb":[[0,1.11,900.85],[1,1.01,15.51],[2,1.01,0]],"ltp":1.37,"tv":1089.24,"id":2284304}]}]}
{"op":"mcm","clk":"1002982124","pt":1580647515185,"mc":[{"id":"1.168224578","rc":[{"batb":[[0,1.11,216.53]],"ltp":1.37,"tv":1089.24,"id":2284304}]}]}
{"op":"mcm","clk":"1002982569","pt":1580647517448,"mc":[{"id":"1.168224578","rc":[{"batb":[[0,1.18,378.19],[1,1.17,679.29],[2,1.11,216.53]],"batl":[[0,1.2,251.48],[1,1.21,503.45]],"ltp":1.37,"tv":1089.24,"id":2284304}]}]}
{"op":"mcm","clk":"1002982885","pt":1580647519055,"mc":[{"id":"1.168224578","rc":[{"batb":[[2,1.13,629.97]],"ltp":1.37,"tv":1089.24,"id":2284304}]}]}
{"op":"mcm","clk":"1002983240","pt":1580647520989,"mc":[{"id":"1.168224578","rc":[{"batb":[[0,1.13,629.97],[1,1.11,216.53],[2,1.01,15.51]],"ltp":1.37,"tv":1089.24,"id":2284304}]}]}
{"op":"mcm","clk":"1002983808","pt":1580647523872,"mc":[{"id":"1.168224578","rc":[{"batb":[[1,1.12,407.93],[2,1.11,952.58]],"batl":[[0,1.28,366.3],[1,1.29,339.38]],"ltp":1.37,"tv":1089.24,"id":2284304}]}]}
{"op":"mcm","clk":"1002985051","pt":1580647530287,"mc":[{"id":"1.168224578","rc":[{"batb":[[1,1.01,15.51],[2,1.01,0]],"ltp":0.0,"tv":0.0,"id":7797764},{"batb":[[0,1.12,407.93],[1,1.11,952.58],[2,1.01,15.51]],"ltp":1.37,"tv":1089.24,"id":2284304}]}]}
{"op":"mcm","clk":"1002985479","pt":1580647532488,"mc":[{"id":"1.168224578","rc":[{"batl":[[0,1.14,795.49],[1,1.15,322.47]],"ltp":1.37,"tv":1089.24,"id":2284304}]}]}
{"op":"mcm","clk":"1002985675","pt":1580647533456,"mc":[{"id":"1.168224578","rc":[{"batb":[[0,8,9.6],[1,7.6,5.88],[2,6.8,13.93]],"batl":[[0,9.8,4.2]],"ltp":0.0,"tv":0.0,"id":7797764},{"batb":[[2,1.08,301.51]],"batl":[[1,1.15,364.48]],"ltp":1.37,"tv":1089.24,"id":2284304}]}]}
{"op":"mcm","clk":"1002987963","pt":1580647545268,"mc":[{"id":"1.168224578","rc":[{"trd":[[1.12,100]],"batb":[[0,1.12,357.93]],"batl":[[1,1.15,332.34]],"ltp":1.12,"tv":1189.24,"id":2284304}],"tv":1189.24}]}
{"op":"mcm","clk":"1002988547","pt":1580647548198,"mc":[{"id":"1.168224578","rc":[{"batb":[[1,1.11,987.98]],"batl":[[0,1.14,827.91]],"ltp":1.12,"tv":1189.24,"id":2284304}]}]}
{"op":"mcm","clk":"1002988944","pt":1580647550289,"mc":[{"id":"1.168224578","rc":[{"batb":[[0,7.6,5.88],[1,6.8,13.93],[2,3.35,371.23]],"ltp":0.0,"tv":0.0,"id":7797764},{"batb":[[0,1.08,301.51],[1,1.07,893.98],[2,1.01,15.51]],"batl":[[0,1.15,42.01],[1,1.15,0]],"ltp":1.12,"tv":1189.24,"id":2284304}]}]}
{"op":"mcm","clk":"1002989339","pt":1580647552107,"mc":[{"id":"1.168224578","rc":[{"batb":[[0,6.8,13.93],[1,3.35,371.23],[2,1.01,15.51]],"ltp":0.0,"tv":0.0,"id":7797764}]}]}
{"op":"mcm","clk":"1002989477","pt":1580647552796,"mc":[{"id":"1.168224578","rc":[{"batb":[[0,1.09,719.87],[1,1.08,758.02],[2,1.07,893.98]],"batl":[[0,1.16,617.71],[1,1.17,479.61]],"ltp":1.12,"tv":1189.24,"id":2284304}]}]}
{"op":"mcm","clk":"1002992067","pt":1580647565654,"mc":[{"id":"1.168224578","rc":[{"batb":[[2,1.01,15.51]],"ltp":1.12,"tv":1189.24,"id":2284304}]}]}
{"op":"mcm","clk":"1002992412","pt":1580647567358,"mc":[{"id":"1.168224578","rc":[{"batl":[[0,1.11,1073.91]],"ltp":1.12,"tv":1189.24,"id":2284304}]}]}
{"op":"mcm","clk":"1002992561","pt":1580647568050,"mc":[{"id":"1.168224578","rc":[{"batb":[[0,10,14.24],[1,8.2,9.21],[2,3.35,371.23]],"ltp":0.0,"tv":0.0,"id":7797764},{"batb":[[2,1.04,491.53]],"ltp":1.12,"tv":1189.24,"id":2284304}]}]}
{"op":"mcm","clk":"1002992801","pt":1580647569248,"mc":[{"id":"1.168224578","rc":[{"batb":[[1,9.2,5.04],[2,8.2,9.21]],"batl":[[0,12,3.36]],"ltp":0.0,"tv":0.0,"id":7797764},{"batb":[[0,1.09,887.91]],"batl":[[1,1.12,42.01]],"ltp":1.12,"tv":1189.24,"id":2284304}]}]}
{"op":"mcm","clk":"1002992859","pt":1580647569572,"mc":[{"id":"1.168224578","rc":[{"batb":[[2,1.06,955.61]],"ltp":1.12,"tv":1189.24,"id":2284304}]}]}
{"op":"mcm","clk":"1002993956","pt":1580647575181,"mc":[{"id":"1.168224578","rc":[{"batb":[[0,1.09,784.4]],"ltp":1.12,"tv":1189.24,"id":2284304}]}]}
{"op":"mcm","clk":"1002994605","pt":1580647578458,"mc":[{"id":"1.168224578","rc":[{"batb":[[1,1.08,862.49]],"batl":[[0,1.11,1151.08]],"ltp":1.12,"tv":1189.24,"id":2284304}]}]}
{"op":"mcm","clk":"1002994782","pt":1580647579457,"mc":[{"id":"1.168224578","rc":[{"batb":[[0,9.2,5.04],[1,8.2,9.21],[2,3.35,371.23]],"ltp":0.0,"tv":0.0,"id":7797764},{"batb":[[0,1.09,168.04],[1,1.06,955.61],[2,1.04,491.53]],"batl":[[0,1.12,42.01],[1,1.12,0]],"ltp":1.12,"tv":1189.24,"id":2284304}]}]}
{"op":"mcm","clk":"1002994938","pt":1580647580268,"mc":[{"id":"1.168224578","rc":[{"batb":[[0,8.2,9.21],[1,3.35,371.23],[2,1.01,15.51]],"ltp":0.0,"tv":0.0,"id":7797764},{"batb":[[0,1.06,955.61],[1,1.04,491.53],[2,1.01,15.51]],"ltp":1.12,"tv":1189.24,"id":2284304}]}]}
{"op":"mcm","clk":"1002995405","pt":1580647582476,"mc":[{"id":"1.168224578","rc":[{"batb":[[0,8,9.44]],"ltp":0.0,"tv":0.0,"id":7797764},{"batb":[[1,1.04,483.97]],"batl":[[0,1.13,532.17],[1,1.14,593.27]],"ltp":1.12,"tv":1189.24,"id":2284304}]}]}
{"op":"mcm","clk":"1002995814","pt":1580647584482,"mc":[{"id":"1.168224578","rc":[{"batb":[[0,1.04,483.97],[1,1.01,15.51],[2,1.01,0]],"ltp":1.12,"tv":1189.24,"id":2284304}]}]}
{"op":"mcm","clk":"1002995986","pt":1580647585393,"mc":[{"id":"1.168224578","rc":[{"batb":[[1,6.6,14.48],[2,3.35,371.23]],"ltp":0.0,"tv":0.0,"id":7797764},{"batb":[[0,1.11,1125.34],[1,1.1,247.48],[2,1.07,330.07]],"ltp":1.12,"tv":1189.24,"id":2284304}]}]}
{"op":"mcm","clk":"1002996320","pt":1580647587093,"mc":[{"id":"1.168224578","rc":[{"batb":[[0,8,15.32]],"batl":[[0,10,4.2]],"ltp":0.0,"tv":0.0,"id":7797764},{"batb":[[0,1.11,1293.38]],"batl":[[1,1.14,635.28]],"ltp":1.12,"tv":1189.24,"id":2284304}]}]}
{"op":"mcm","clk":"1002996561","pt":1580647588465,"mc":[{"id":"1.168224578","rc":[{"batb":[[2,1.07,1224.05]],"ltp":1.12,"tv":1189.24,"id":2284304}]}]}
{"op":"mcm","clk":"1002997785","pt":1580647594482,"mc":[{"id":"1.168224578","rc":[{"batb":[[0,8,5.88]],"ltp":0.0,"tv":0.0,"id":7797764},{"batb":[[0,1.11,168.04],[1,1.07,1224.05],[2,1.01,15.51]],"batl":[[0,1.14,42.01],[1,1.14,0]],"ltp":1.12,"tv":1189.24,"id":2284304}]}]}
{"op":"mcm","clk":"1002998129","pt":1580647596212,"mc":[{"id":"1.168224578","rc":[{"batb":[[0,6.6,14.48],[1,3.35,371.23],[2,1.01,15.51]],"ltp":0.0,"tv":0.0,"id":7797764},{"batb":[[0,1.07,1224.05],[1,1.01,15.51],[2,1.01,0]],"ltp":1.12,"tv":1189.24,"id":2284304}]}]}
{"op":"mcm","clk":"1002998310","pt":1580647597218,"mc":[{"id":"1.168224578","rc":[{"batb":[[0,1.08,718.94],[1,1.07,1692.5],[2,1.01,15.51]],"batl":[[0,1.16,744.81],[1,1.17,353.6]],"ltp":1.12,"tv":1189.24,"id":2284304}]}]}
{"op":"mcm","clk":"1002999107","pt":1580647601293,"mc":[{"id":"1.168224578","rc":[{"batb":[[0,1.07,1224.05],[1,1.01,15.51],[2,1.01,0]],"ltp":1.12,"tv":1189.24,"id":2284304}]}]}
{"op":"mcm","clk":"1002999390","pt":1580647602696,"mc":[{"id":"1.168224578","rc":[{"batb":[[0,1.07,330.07]],"ltp":1.12,"tv":1189.24,"id":2284304}]}]}
{"op":"mcm","clk":"1002999597","pt":1580647603699,"mc":[{"id":"1.168224578","rc":[{"batb":[[0,1.14,211.33],[1,1.13,917.5],[2,1.07,330.07]],"ltp":1.12,"tv":1189.24,"id":2284304}]}]}
{"op":"mcm","clk":"1002999926","pt":1580647605403,"mc":[{"id":"1.168224578","rc":[{"batb":[[0,7,6.72],[1,6.6,14.48],[2,5.8,20.14]],"batl":[[0,8.8,5.04]],"ltp":0.0,"tv":0.0,"id":7797764},{"batb":[[0,1.14,380.26],[2,1.1,229.04]],"ltp":1.12,"tv":1189.24,"id":2284304}]}]}
{"op":"mcm","clk":"1003002094","pt":1580647616398,"mc":[{"id":"1.168224578","rc":[{"batb":[[0,1.14,168.93],[1,1.1,229.04],[2,1.09,779.05]],"ltp":1.12,"tv":1189.24,"id":2284304}]}]}
{"op":"mcm","clk":"1003002172","pt":1580647616825,"mc":[{"id":"1.168224578","rc":[{"batb":[[1,5.8,20.14],[2,3.35,371.23]],"ltp":0.0,"tv":0.0,"id":7797764},{"batb":[[0,1.1,229.04],[1,1.09,779.05],[2,1.01,15.51]],"ltp":1.12,"tv":1189.24,"id":2284304}]}]}
{"op":"mcm","clk":"1003002503","pt":1580647618320,"mc":[{"id":"1.168224578","rc":[{"batb":[[0,5.8,20.14],[1,3.35,371.23],[2,1.01,15.51]],"ltp":0.0,"tv":0.0,"id":7797764}]}]}
{"op":"mcm","clk":"1003002772","pt":1580647619491,"mc":[{"id":"1.168224578","rc":[{"batl":[[0,1.18,557.99],[1,1.19,520.39]],"ltp":1.12,"tv":1189.24,"id":2284304}]}]}
{"op":"mcm","clk":"1003003051","pt":1580647620825,"mc":[{"id":"1.168224578","rc":[{"batb":[[1,1.01,15.51],[2,1.01,0]],"ltp":1.12,"tv":1189.24,"id":2284304}]}]}
{"op":"mcm","clk":"1003003572","pt":1580647623472,"mc":[{"id":"1.168224578","rc":[{"batb":[[0,6.6,6.72],[1,5.8,20.14],[2,5.4,11.96]],"ltp":0.0,"tv":0.0,"id":7797764},{"batb":[[0,1.17,137.3],[1,1.16,214.87],[2,1.15,786.81]],"batl":[[0,1.18,563.62]],"ltp":1.12,"tv":1189.24,"id":2284304}]}]}
{"op":"mcm","clk":"1003004141","pt":1580647625931,"mc":[{"id":"1.168224578","rc":[{"batb":[[1,1.16,251.95]],"batl":[[1,1.19,556.46]],"ltp":1.12,"tv":1189.24,"id":2284304}]}]}
{"op":"mcm","clk":"1003005497","pt":1580647632439,"mc":[{"id":"1.168224578","rc":[{"batb":[[1,1.14,162.4],[2,1.11,684.32]],"batl":[[0,1.18,42.01],[1,1.19,362.21]],"ltp":1.12,"tv":1189.24,"id":2284304}]}]}
{"op":"mcm","clk":"1003005653","pt":1580647633054,"mc":[{"id":"1.168224578","rc":[{"batb":[[1,5.4,11.96],[2,3.35,371.23]],"ltp":0.0,"tv":0.0,"id":7797764},{"batb":[[0,1.14,162.4],[1,1.11,684.32],[2,1.01,15.51]],"ltp":1.12,"tv":1189.24,"id":2284304}]}]}
{"op":"mcm","clk":"1003005958","pt":1580647634342,"mc":[{"id":"1.168224578","rc":[{"batb":[[0,5.4,11.96],[1,3.35,371.23],[2,1.01,15.51]],"ltp":0.0,"tv":0.0,"id":7797764},{"batl":[[0,1.19,362.21],[1,1.19,0]],"ltp":1.12,"tv":1189.24,"id":2284304}]}]}
{"op":"mcm","clk":"1003006190","pt":1580647635454,"mc":[{"id":"1.168224578","rc":[{"batb":[[0,1.14,717.76],[1,1.13,570.42],[2,1.11,684.32]],"batl":[[1,1.2,534.43]],"ltp":1.12,"tv":1189.24,"id":2284304}]}]}
{"op":"mcm","clk":"1003006352","pt":1580647636261,"mc":[{"id":"1.168224578","rc":[{"batb":[[0,5.5,11.57]],"batl":[[0,8,5.88]],"ltp":0.0,"tv":0.0,"id":7797764},{"batb":[[0,1.14,885.8]],"ltp":1.12,"tv":1189.24,"id":2284304}]}]}
{"op":"mcm","clk":"1003006404","pt":1580647636580,"mc":[{"id":"1.168224578","rc":[{"batb":[[0,1.14,717.76]],"ltp":1.12,"tv":1189.24,"id":2284304}]}]}
{"op":"mcm","clk":"1003007306","pt":1580647641360,"mc":[{"id":"1.168224578","rc":[{"batb":[[0,1.14,162.4],[1,1.11,684.32],[2,1.01,15.51]],"ltp":1.12,"tv":1189.24,"id":2284304}]}]}
{"op":"mcm","clk":"1003007946","pt":1580647644440,"mc":[{"id":"1.168224578","rc":[{"batb":[[1,4,23.53],[2,3.35,371.23]],"ltp":0.0,"tv":0.0,"id":7797764},{"trd":[[1.19,247.69]],"batb":[[0,1.17,342.27],[1,1.16,734.74],[2,1.14,162.4]],"batl":[[0,1.19,238.37]],"ltp":1.19,"tv":1436.92,"id":2284304}],"tv":1436.92}]}
{"op":"mcm","clk":"1003008022","pt":1580647644850,"mc":[{"id":"1.168224578","rc":[{"batb":[[0,6.2,7.56],[1,5.5,11.57],[2,4,23.53]],"batl":[[0,7.6,5.88]],"ltp":0.0,"tv":0.0,"id":7797764},{"batb":[[2,1.15,168.04]],"batl":[[0,1.19,280.38]],"ltp":1.19,"tv":1436.92,"id":2284304}]}]}
{"op":"mcm","clk":"1003008630","pt":1580647647953,"mc":[{"id":"1.168224578","rc":[{"batb":[[0,1.17,388.48]],"batl":[[0,1.19,359.34]],"ltp":1.19,"tv":1436.92,"id":2284304}]}]}
{"op":"mcm","clk":"1003009604","pt":1580647652926,"mc":[{"id":"1.168224578","rc":[{"batb":[[1,5.7,10.54],[2,4.2,21.56]],"ltp":0.0,"tv":0.0,"id":7797764},{"batb":[[0,1.18,131.32],[1,1.17,388.48],[2,1.16,734.74]],"ltp":1.19,"tv":1436.92,"id":2284304}]}]}
{"op":"mcm","clk":"1003014258","pt":1580647676443,"mc":[{"id":"1.168224578","rc":[{"trd":[[1.18,85.7]],"batb":[[0,1.18,88.47]],"ltp":1.18,"tv":1522.63,"id":2284304}],"tv":1522.63}]}
{"op":"mcm","clk":"1003015050","pt":1580647680464,"mc":[{"id":"1.168224578","rc":[{"batb":[[2,1.16,695.8]],"ltp":1.18,"tv":1522.63,"id":2284304}]}]}
{"op":"mcm","clk":"1003016554","pt":1580647687998,"mc":[{"id":"1.168224578","rc":[{"batb":[[1,5.8,20.38],[2,4.3,20.46]],"ltp":0.0,"tv":0.0,"id":7797764},{"batb":[[0,1.17,524.6],[1,1.16,695.8],[2,1.15,168.04]],"ltp":1.18,"tv":1522.63,"id":2284304}]}]}
{"op":"mcm","clk":"1003018049","pt":1580647695511,"mc":[{"id":"1.168224578","rc":[{"batb":[[0,1.17,446.41]],"ltp":1.18,"tv":1522.63,"id":2284304}]}]}
{"op":"mcm","clk":"1003018744","pt":1580647699317,"mc":[{"id":"1.168224578","rc":[{"batb":[[1,5.9,19.83],[2,4.3,19.91]],"ltp":0.0,"tv":0.0,"id":7797764},{"batb":[[1,1.16,734.8]],"batl":[[0,1.19,436.26]],"ltp":1.18,"tv":1522.63,"id":2284304}]}]}
{"op":"mcm","clk":"1003023217","pt":1580647722877,"mc":[{"id":"1.168224578","rc":[{"trd":[[1.17,6.06]],"batb":[[0,1.17,443.38]],"ltp":1.17,"tv":1528.69,"id":2284304}],"tv":1528.69}]}
{"op":"mcm","clk":"1003023673","pt":1580647725462,"mc":[{"id":"1.168224578","rc":[{"batb":[[0,1.17,136.12],[1,1.15,168.04],[2,1.11,890.23]],"batl":[[0,1.19,42.01],[1,1.2,0]],"ltp":1.17,"tv":1528.69,"id":2284304}]}]}
{"op":"mcm","clk":"1003023752","pt":1580647725901,"mc":[{"id":"1.168224578","rc":[{"batb":[[0,4.3,19.91],[1,3.35,371.23],[2,1.01,15.51]],"ltp":0.0,"tv":0.0,"id":7797764},{"batb":[[0,1.11,890.23],[1,1.01,15.51],[2,1.11,0]],"ltp":1.17,"tv":1528.69,"id":2284304}]}]}
{"op":"mcm","clk":"1003024218","pt":1580647728477,"mc":[{"id":"1.168224578","rc":[{"batb":[[0,1.12,751.05],[1,1.11,1285.02],[2,1.01,15.51]],"batl":[[0,1.29,338.93],[1,1.3,331.02]],"ltp":1.17,"tv":1528.69,"id":2284304}]}]}
{"op":"mcm","clk":"1003024383","pt":1580647729387,"mc":[{"id":"1.168224578","rc":[{"batb":[[1,1.11,600.7]],"ltp":1.17,"tv":1528.69,"id":2284304}]}]}
{"op":"mcm","clk":"1003024578","pt":1580647730447,"mc":[{"id":"1.168224578","rc":[{"batl":[[0,1.14,500.22],[1,1.15,616.65]],"ltp":1.17,"tv":1528.69,"id":2284304}]}]}
{"op":"mcm","clk":"1003024734","pt":1580647731292,"mc":[{"id":"1.168224578","rc":[{"batb":[[0,7.8,10.46],[1,5.6,11.17],[2,3.35,371.23]],"batl":[[0,10,4.2]],"ltp":0.0,"tv":0.0,"id":7797764},{"batb":[[1,1.11,768.74],[2,1.08,295.61]],"ltp":1.17,"tv":1528.69,"id":2284304}]}]}
{"op":"mcm","clk":"1003024766","pt":1580647731498,"mc":[{"id":"1.168224578","rc":[{"batb":[[0,7.8,16.35]],"ltp":0.0,"tv":0.0,"id":7797764}]}]}
{"op":"mcm","clk":"1003026872","pt":1580647743334,"mc":[{"id":"1.168224578","rc":[{"batb":[[0,7.8,5.88]],"ltp":0.0,"tv":0.0,"id":7797764},{"batb":[[0,1.11,168.04],[1,1.08,295.61],[2,1.07,893.98]],"ltp":1.17,"tv":1528.69,"id":2284304}]}]}
{"op":"mcm","clk":"1003027064","pt":1580647744403,"mc":[{"id":"1.168224578","rc":[{"batb":[[0,5.6,10.94],[1,3.35,371.23],[2,1.01,15.51]],"ltp":0.0,"tv":0.0,"id":7797764},{"batb":[[0,1.08,295.61],[1,1.07,893.98],[2,1.01,15.51]],"ltp":1.17,"tv":1528.69,"id":2284304}]}]}
{"op":"mcm","clk":"1003027447","pt":1580647746401,"mc":[{"id":"1.168224578","rc":[{"batb":[[0,1.09,654.19],[1,1.08,819.99],[2,1.07,893.98]],"batl":[[0,1.21,476.15],[1,1.22,475.97]],"ltp":1.17,"tv":1528.69,"id":2284304}]}]}
{"op":"mcm","clk":"1003028525","pt":1580647752343,"mc":[{"id":"1.168224578","rc":[{"batb":[[0,1.08,295.61],[1,1.07,893.98],[2,1.01,15.51]],"ltp":1.17,"tv":1528.69,"id":2284304}]}]}
{"op":"mcm","clk":"1003028736","pt":1580647753454,"mc":[{"id":"1.168224578","rc":[{"batb":[[1,1.01,15.51],[2,1.01,0]],"ltp":1.17,"tv":1528.69,"id":2284304}]}]}
{"op":"mcm","clk":"1003029069","pt":1580647755359,"mc":[{"id":"1.168224578","rc":[{"batb":[[0,1.13,891.97],[1,1.12,242.38],[2,1.08,295.61]],"batl":[[0,1.15,253.71],[1,1.16,697.9]],"ltp":1.17,"tv":1528.69,"id":2284304}]}]}
{"op":"mcm","clk":"1003029353","pt":1580647757039,"mc":[{"id":"1.168224578","rc":[{"batb":[[2,1.08,1120.28]],"ltp":1.17,"tv":1528.69,"id":2284304}]}]}
{"op":"mcm","clk":"1003029921","pt":1580647760065,"mc":[{"id":"1.168224578","rc":[{"batb":[[0,1.08,1120.28],[1,1.01,15.51],[2,1.08,0]],"ltp":1.17,"tv":1528.69,"id":2284304}]}]}
{"op":"mcm","clk":"1003030543","pt":1580647763479,"mc":[{"id":"1.168224578","rc":[{"batb":[[0,1.09,656.47],[1,1.08,1642.36],[2,1.01,15.51]],"ltp":1.17,"tv":1528.69,"id":2284304}]}]}
{"op":"mcm","clk":"1003030718","pt":1580647764471,"mc":[{"id":"1.168224578","rc":[{"batb":[[1,1.08,817.69]],"ltp":1.17,"tv":1528.69,"id":2284304}]}]}
{"op":"mcm","clk":"1003031274","pt":1580647767491,"mc":[{"id":"1.168224578","rc":[{"batb":[[0,10,14.16],[1,9.8,4.2],[2,7.6,10.86]],"batl":[[0,13,3.36]],"ltp":0.0,"tv":0.0,"id":7797764},{"batb":[[1,1.08,985.73],[2,1.05,411.66]],"batl":[[0,1.11,1186.1]],"ltp":1.17,"tv":1528.69,"id":2284304}]}]}
{"op":"mcm","clk":"1003031390","pt":1580647768176,"mc":[{"id":"1.168224578","rc":[{"batb":[[2,1.05,1481.22]],"ltp":1.17,"tv":1528.69,"id":2284304}]}]}
{"op":"mcm","clk":"1003034007","pt":1580647782487,"mc":[{"id":"1.168224578","rc":[{"batb":[[0,9.8,4.2],[1,7.6,10.86],[2,3.35,371.23]],"ltp":0.0,"tv":0.0,"id":7797764},{"batb":[[0,1.08,168.04],[1,1.05,1481.22],[2,1.01,15.51]],"batl":[[0,1.11,42.01]],"ltp":1.17,"tv":1528.69,"id":2284304}]}]}
{"op":"mcm","clk":"1003034326","pt":1580647784184,"mc":[{"id":"1.168224578","rc":[{"batb":[[0,7.6,10.86],[1,3.35,371.23],[2,1.01,15.51]],"ltp":0.0,"tv":0.0,"id":7797764},{"batb":[[0,1.05,1481.22],[1,1.01,15.51],[2,1.01,0]],"ltp":1.17,"tv":1528.69,"id":2284304}]}]}
{"op":"mcm","clk":"1003034564","pt":1580647785403,"mc":[{"id":"1.168224578","rc":[{"batb":[[0,1.07,1062.89],[1,1.05,1481.22],[2,1.01,15.51]],"batl":[[0,1.14,249.06],[1,1.15,751.24]],"ltp":1.17,"tv":1528.69,"id":2284304}]}]}
{"op":"mcm","clk":"1003034758","pt":1580647786434,"mc":[{"id":"1.168224578","rc":[{"batb":[[0,1.05,1481.22],[1,1.01,15.51],[2,1.01,0]],"ltp":1.17,"tv":1528.69,"id":2284304}]}]}
{"op":"mcm","clk":"1003034792","pt":1580647786620,"mc":[{"id":"1.168224578","rc":[{"batb":[[0,1.05,411.66]],"ltp":1.17,"tv":1528.69,"id":2284304}]}]}
{"op":"mcm","clk":"1003035283","pt":1580647789451,"mc":[{"id":"1.168224578","rc":[{"batb":[[0,1.1,186.95],[1,1.09,985.09],[2,1.05,411.66]],"batl":[[0,1.11,376.59],[1,1.12,769.09]],"ltp":1.17,"tv":1528.69,"id":2284304}]}]}
{"op":"mcm","clk":"1003035477","pt":1580647790420,"mc":[{"id":"1.168224578","rc":[{"batb":[[2,1.06,955.61]],"ltp":1.17,"tv":1528.69,"id":2284304}]}]}
{"op":"mcm","clk":"1003035936","pt":1580647792836,"mc":[{"id":"1.168224578","rc":[{"batb":[[0,1.06,955.61],[1,1.05,411.66],[2,1.01,15.51]],"ltp":1.17,"tv":1528.69,"id":2284304}]}]}
{"op":"mcm","clk":"1003036583","pt":1580647796343,"mc":[{"id":"1.168224578","rc":[{"batb":[[0,1.07,1037.87],[1,1.06,955.61],[2,1.05,411.66]],"batl":[[0,1.14,271.79],[1,1.15,751.31]],"ltp":1.17,"tv":1528.69,"id":2284304}]}]}
{"op":"mcm","clk":"1003037029","pt":1580647798625,"mc":[{"id":"1.168224578","rc":[{"batb":[[1,1.01,15.51],[2,1.01,0]],"ltp":0.0,"tv":0.0,"id":7797764},{"batb":[[1,1.05,411.66],[2,1.01,15.51]],"ltp":1.17,"tv":1528.69,"id":2284304}]}]}
{"op":"mcm","clk":"1003037323","pt":1580647800354,"mc":[{"id":"1.168224578","rc":[{"batl":[[0,1.09,1173.76]],"ltp":1.17,"tv":1528.69,"id":2284304}]}]}
{"op":"mcm","clk":"1003037503","pt":1580647801322,"mc":[{"id":"1.168224578","rc":[{"batb":[[0,12.5,8.34],[1,12,3.36],[2,10.5,12.83]],"ltp":0.0,"tv":0.0,"id":7797764},{"batb":[[2,1.04,491.37]],"batl":[[0,1.09,1215.77]],"ltp":1.17,"tv":1528.69,"id":2284304}]}]}
{"op":"mcm","clk":"1003037717","pt":1580647802433,"mc":[{"id":"1.168224578","rc":[{"batb":[[2,1.04,1754.37]],"ltp":1.17,"tv":1528.69,"id":2284304}]}]}
{"op":"mcm","clk":"1003040283","pt":1580647816483,"mc":[{"id":"1.168224578","rc":[{"batb":[[0,10.5,12.83],[1,3.7,374.33],[2,1.01,15.51]],"ltp":0.0,"tv":0.0,"id":7797764},{"batb":[[0,1.04,1753.97],[1,1.01,15.51],[2,1.04,0]],"ltp":1.17,"tv":1528.69,"id":2284304}]}]}
{"op":"mcm","clk":"1003040762","pt":1580647819317,"mc":[{"id":"1.168224578","rc":[{"batb":[[0,1.06,1206.98],[1,1.04,1753.97],[2,1.01,15.51]],"batl":[[0,1.1,680.44],[1,1.11,478.3]],"ltp":1.17,"tv":1528.69,"id":2284304}]}]}
{"op":"mcm","clk":"1003040970","pt":1580647820654,"mc":[{"id":"1.168224578","rc":[{"batb":[[0,1.04,1753.97],[1,1.01,15.51],[2,1.01,0]],"ltp":1.17,"tv":1528.69,"id":2284304}]}]}
{"op":"mcm","clk":"1003041622","pt":1580647824101,"mc":[{"id":"1.168224578","rc":[{"batb":[[0,1.07,1195.7],[1,1.04,1753.97],[2,1.01,15.51]],"batl":[[0,1.09,1027.49]],"ltp":1.17,"tv":1528.69,"id":2284304}]}]}
{"op":"mcm","clk":"1003042029","pt":1580647826411,"mc":[{"id":"1.168224578","rc":[{"batb":[[0,1.04,1753.97],[1,1.01,15.51],[2,1.01,0]],"ltp":1.17,"tv":1528.69,"id":2284304}]}]}
{"op":"mcm","clk":"1003042591","pt":1580647829195,"mc":[{"id":"1.168224578","rc":[{"batb":[[0,1.06,1206.98],[1,1.04,1753.97],[2,1.01,15.51]],"batl":[[0,1.1,682.54],[1,1.11,476.22]],"ltp":1.17,"tv":1528.69,"id":2284304}]}]}
{"op":"mcm","clk":"1003043256","pt":1580647833024,"mc":[{"id":"1.168224578","rc":[{"batb":[[0,1.04,1753.97],[1,1.01,15.51],[2,1.01,0]],"ltp":1.17,"tv":1528.69,"id":2284304}]}]}
{"op":"mcm","clk":"1003043513","pt":1580647834446,"mc":[{"id":"1.168224578","rc":[{"batb":[[0,1.04,490.98]],"ltp":1.17,"tv":1528.69,"id":2284304}]}]}
{"op":"mcm","clk":"1003043851","pt":1580647836373,"mc":[{"id":"1.168224578","rc":[{"batb":[[1,8,9.76],[2,3.7,374.33]],"ltp":0.0,"tv":0.0,"id":7797764},{"trd":[[1.08,10]],"batb":[[0,1.08,1179.63],[1,1.07,320.16],[2,1.05,437.55]],"ltp":1.08,"tv":1538.69,"id":2284304}],"tv":1538.69}]}
{"op":"mcm","clk":"1003043959","pt":1580647836937,"mc":[{"id":"1.168224578","rc":[{"batb":[[0,10.5,17.03]],"ltp":0.0,"tv":0.0,"id":7797764}]}]}
{"op":"mcm","clk":"1003044209","pt":1580647838211,"mc":[{"id":"1.168224578","rc":[{"batb":[[2,1.05,1507.11]],"ltp":1.08,"tv":1538.69,"id":2284304}]}]}
{"op":"mcm","clk":"1003047233","pt":1580647855377,"mc":[{"id":"1.168224578","rc":[{"batb":[[0,10.5,4.2]],"ltp":0.0,"tv":0.0,"id":7797764},{"batb":[[0,1.05,1507.11],[1,1.01,15.51],[2,1.05,0]],"ltp":1.08,"tv":1538.69,"id":2284304}]}]}
{"op":"mcm","clk":"1003047369","pt":1580647856028,"mc":[{"id":"1.168224578","rc":[{"batb":[[0,8,9.76],[1,3.7,374.33],[2,1.01,15.51]],"ltp":0.0,"tv":0.0,"id":7797764}]}]}
{"op":"mcm","clk":"1003047814","pt":1580647858399,"mc":[{"id":"1.168224578","rc":[{"batb":[[0,1.07,363.98],[1,1.06,839.56],[2,1.05,1507.11]],"batl":[[0,1.14,901.09],[1,1.15,219.26]],"ltp":1.08,"tv":1538.69,"id":2284304}]}]}
{"op":"mcm","clk":"1003048631","pt":1580647862939,"mc":[{"id":"1.168224578","rc":[{"batb":[[2,1.05,437.55]],"ltp":1.08,"tv":1538.69,"id":2284304}]}]}
{"op":"mcm","clk":"1003049051","pt":1580647865323,"mc":[{"id":"1.168224578","rc":[{"batb":[[0,13.5,7.55],[1,12.5,3.36],[2,11,11.17]],"ltp":0.0,"tv":0.0,"id":7797764},{"batb":[[1,1.06,1007.6]],"batl":[[0,1.08,682.04],[1,1.09,499.35]],"ltp":1.08,"tv":1538.69,"id":2284304}]}]}
{"op":"mcm","clk":"1003049425","pt":1580647867415,"mc":[{"id":"1.168224578","rc":[{"trd":[[1.07,168.04]],"batb":[[0,1.07,279.96]],"ltp":1.07,"tv":1706.72,"id":2284304}],"tv":1706.72}]}
{"op":"mcm","clk":"1003050007","pt":1580647870750,"mc":[{"id":"1.168224578","rc":[{"batb":[[0,1.07,333.62]],"ltp":1.07,"tv":1706.72,"id":2284304}]}]}
{"op":"mcm","clk":"1003051587","pt":1580647880253,"mc":[{"id":"1.168224578","rc":[{"batb":[[0,1.07,279.96]],"batl":[[1,1.09,393.13]],"ltp":1.07,"tv":1706.72,"id":2284304}]}]}
{"op":"mcm","clk":"1003052136","pt":1580647883458,"mc":[{"id":"1.168224578","rc":[{"batb":[[1,1.06,1117.74]],"batl":[[0,1.08,789.24]],"ltp":1.07,"tv":1706.72,"id":2284304}]}]}
{"op":"mcm","clk":"1003052767","pt":1580647887371,"mc":[{"id":"1.168224578","rc":[{"batb":[[0,12.5,3.36],[1,11,11.17],[2,3.7,374.33]],"ltp":0.0,"tv":0.0,"id":7797764},{"batb":[[0,1.06,168.04],[1,1.03,2203.54],[2,1.01,15.51]],"batl":[[0,1.09,393.13],[1,1.09,0]],"ltp":1.07,"tv":1706.72,"id":2284304}]}]}
{"op":"mcm","clk":"1003052907","pt":1580647888199,"mc":[{"id":"1.168224578","rc":[{"batb":[[0,11,11.17],[1,3.7,374.33],[2,1.01,15.51]],"ltp":0.0,"tv":0.0,"id":7797764},{"batb":[[0,1.03,2203.54],[1,1.01,15.51],[2,1.01,0]],"ltp":1.07,"tv":1706.72,"id":2284304}]}]}
{"op":"mcm","clk":"1003053201","pt":1580647889765,"mc":[{"id":"1.168224578","rc":[{"batb":[[0,1.05,1021.4],[1,1.04,200.41],[2,1.03,2203.54]],"batl":[[1,1.1,801.98]],"ltp":1.07,"tv":1706.72,"id":2284304}]}]}
{"op":"mcm","clk":"1003055176","pt":1580647901326,"mc":[{"id":"1.168224578","rc":[{"batb":[[2,1.03,631.66]],"ltp":1.07,"tv":1706.72,"id":2284304}]}]}
{"op":"mcm","clk":"1003055403","pt":1580647902491,"mc":[{"id":"1.168224578","rc":[{"batl":[[0,1.06,721.01],[1,1.07,482.83]],"ltp":1.07,"tv":1706.72,"id":2284304}]}]}
{"op":"mcm","clk":"1003055528","pt":1580647903290,"mc":[{"id":"1.168224578","rc":[{"batb":[[0,17,4.09],[1,13.5,7.08],[2,11,11.17]],"ltp":0.0,"tv":0.0,"id":7797764},{"batl":[[1,1.07,524.84]],"ltp":1.07,"tv":1706.72,"id":2284304}]}]}
{"op":"mcm","clk":"1003055578","pt":1580647903618,"mc":[{"id":"1.168224578","rc":[{"batb":[[2,3.7,374.33]],"ltp":0.0,"tv":0.0,"id":7797764}]}]}
{"op":"mcm","clk":"1003057669","pt":1580647915437,"mc":[{"id":"1.168224578","rc":[{"batb":[[0,13.5,7.08],[1,3.7,374.33],[2,1.01,15.51]],"ltp":0.0,"tv":0.0,"id":7797764},{"batb":[[0,1.02,2184.08],[1,1.01,15.51],[2,1.03,0]],"batl":[[0,1.07,42.01],[1,1.07,0]],"ltp":1.07,"tv":1706.72,"id":2284304}]}]}
{"op":"mcm","clk":"1003058122","pt":1580647918007,"mc":[{"id":"1.168224578","rc":[{"batb":[[0,1.03,1243.59],[1,1.02,2184.08],[2,1.01,15.51]],"batl":[[0,1.05,1428.33],[1,1.08,1186.02]],"ltp":1.07,"tv":1706.72,"id":2284304}]}]}
{"op":"mcm","clk":"1003058282","pt":1580647918925,"mc":[{"id":"1.168224578","rc":[{"batb":[[0,1.02,2184.08],[1,1.01,15.51],[2,1.01,0]],"batl":[[1,1.08,0]],"ltp":1.07,"tv":1706.72,"id":2284304}]}]}
{"op":"mcm","clk":"1003059349","pt":1580647925384,"mc":[{"id":"1.168224578","rc":[{"batb":[[1,1.01,15.51],[2,1.01,0]],"ltp":0.0,"tv":0.0,"id":7797764},{"batb":[[0,1.01,15.51],[1,1.01,0]],"ltp":1.07,"tv":1706.72,"id":2284304}]}]}
{"op":"mcm","clk":"1003059530","pt":1580647926177,"mc":[{"id":"1.168224578","rc":[{"batb":[[0,1.03,1243.59],[1,1.01,15.51]],"batl":[[1,1.08,1186.02]],"ltp":1.07,"tv":1706.72,"id":2284304}]}]}
{"op":"mcm","clk":"1003060192","pt":1580647930229,"mc":[{"id":"1.168224578","rc":[{"batb":[[0,1.01,15.51],[1,1.01,0]],"ltp":1.07,"tv":1706.72,"id":2284304}]}]}
{"op":"mcm","clk":"1003060728","pt":1580647933354,"mc":[{"id":"1.168224578","rc":[{"batb":[[1,11,11.33],[2,1.01,15.51]],"ltp":0.0,"tv":0.0,"id":7797764},{"trd":[[1.05,2856.67]],"batb":[[0,1.05,232.23],[1,1.03,730.48],[2,1.01,15.51]],"batl":[[0,1.08,1186.02],[1,1.08,0]],"ltp":1.05,"tv":4563.4,"id":2284304}],"tv":4563.4}]}
{"op":"mcm","clk":"1003061089","pt":1580647935472,"mc":[{"id":"1.168224578","rc":[{"batb":[[0,13.5,10.44],[2,3.85,370.95]],"ltp":0.0,"tv":0.0,"id":7797764},{"trd":[[1.05,2893.28]],"batb":[[0,1.05,213.93]],"batl":[[0,1.08,1228.03]],"ltp":1.05,"tv":4600.0,"id":2284304}],"tv":4600.0}]}
{"op":"mcm","clk":"1003061246","pt":1580647936262,"mc":[{"id":"1.168224578","rc":[{"batb":[[0,1.06,1208.39],[1,1.05,213.93],[2,1.03,2302.36]],"ltp":1.05,"tv":4600.0,"id":2284304}]}]}
{"op":"mcm","clk":"1003062823","pt":1580647946404,"mc":[{"id":"1.168224578","rc":[{"batb":[[0,1.05,213.93],[1,1.03,2302.36],[2,1.01,15.51]],"batl":[[0,1.08,42.01]],"ltp":1.05,"tv":4600.0,"id":2284304}]}]}
{"op":"mcm","clk":"1003062920","pt":1580647947111,"mc":[{"id":"1.168224578","rc":[{"batb":[[0,13.5,3.36]],"ltp":0.0,"tv":0.0,"id":7797764},{"batb":[[0,1.03,2302.36],[1,1.01,15.51],[2,1.01,0]],"ltp":1.05,"tv":4600.0,"id":2284304}]}]}
{"op":"mcm","clk":"1003063065","pt":1580647948001,"mc":[{"id":"1.168224578","rc":[{"batb":[[0,11,11.33],[1,3.85,370.95],[2,1.01,15.51]],"ltp":0.0,"tv":0.0,"id":7797764}]}]}
{"op":"mcm","clk":"1003063309","pt":1580647949491,"mc":[{"id":"1.168224578","rc":[{"batb":[[0,1.04,1231.63],[1,1.03,2302.36],[2,1.01,15.51]],"batl":[[0,1.09,791.75],[1,1.1,328.99]],"ltp":1.05,"tv":4600.0,"id":2284304}]}]}
{"op":"mcm","clk":"1003063446","pt":1580647950289,"mc":[{"id":"1.168224578","rc":[{"batb":[[0,12,9.6]],"ltp":0.0,"tv":0.0,"id":7797764},{"batb":[[0,1.03,1571.88],[1,1.02,804.52]],"ltp":1.05,"tv":4600.0,"id":2284304}]}]}
{"op":"mcm","clk":"1003063983","pt":1580647953475,"mc":[{"id":"1.168224578","rc":[{"batb":[[0,1.06,509.8],[1,1.05,705.24],[2,1.03,1571.88]],"batl":[[0,1.07,868.65],[1,1.08,325.4]],"ltp":1.05,"tv":4600.0,"id":2284304}]}]}
{"op":"mcm","clk":"1003064414","pt":1580647955926,"mc":[{"id":"1.168224578","rc":[{"batb":[[0,1.03,1571.88],[1,1.02,804.52],[2,1.01,15.51]],"ltp":1.05,"tv":4600.0,"id":2284304}]}]}
{"op":"mcm","clk":"1003064823","pt":1580647958407,"mc":[{"id":"1.168224578","rc":[{"batb":[[0,1.04,1231.63],[1,1.03,1571.88],[2,1.02,804.52]],"batl":[[0,1.09,791.75],[1,1.1,379.9]],"ltp":1.05,"tv":4600.0,"id":2284304}]}]}
{"op":"mcm","clk":"1003064961","pt":1580647959414,"mc":[{"id":"1.168224578","rc":[{"batb":[[0,1.03,1571.88],[1,1.02,804.52],[2,1.01,15.51]],"ltp":1.05,"tv":4600.0,"id":2284304}]}]}
{"op":"mcm","clk":"1003065049","pt":1580647960010,"mc":[{"id":"1.168224578","rc":[{"batb":[[0,3.85,370.95],[1,1.01,15.51],[2,1.01,0]],"ltp":0.0,"tv":0.0,"id":7797764}]}]}
{"op":"mcm","clk":"1003065432","pt":1580647962482,"mc":[{"id":"1.168224578","rc":[{"batb":[[0,1.07,1197.1]],"ltp":1.05,"tv":4600.0,"id":2284304}]}]}
{"op":"mcm","clk":"1003065524","pt":1580647962961,"mc":[{"id":"1.168224578","rc":[{"batb":[[0,11.5,13.27],[1,10,13.69],[2,3.85,370.95]],"ltp":0.0,"tv":0.0,"id":7797764},{"batb":[[0,1.07,1365.14],[1,1.06,372.32],[2,1.04,512.61]],"ltp":1.05,"tv":4600.0,"id":2284304}]}]}
{"op":"mcm","clk":"1003065866","pt":1580647965006,"mc":[{"id":"1.168224578","rc":[{"batb":[[2,1.04,1775.61]],"ltp":1.05,"tv":4600.0,"id":2284304}]}]}
{"op":"mcm","clk":"1003066510","pt":1580647968852,"mc":[{"id":"1.168224578","rc":[{"trd":[[1.07,173.08]],"batb":[[0,1.07,1362.62]],"ltp":1.07,"tv":4605.04,"id":2284304}],"tv":4605.04}]}
{"op":"mcm","clk":"1003067709","pt":1580647976371,"mc":[{"id":"1.168224578","rc":[{"batb":[[0,10,13.69],[1,3.85,370.95],[2,1.01,15.51]],"ltp":0.0,"tv":0.0,"id":7797764},{"batb":[[0,1.04,1775.61],[1,1.01,15.51],[2,1.04,0]],"batl":[[0,1.1,379.9],[1,1.1,0]],"ltp":1.07,"tv":4605.04,"id":2284304}]}]}
{"op":"mcm","clk":"1003068107","pt":1580647978775,"mc":[{"id":"1.168224578","rc":[{"batb":[[0,1.06,796.83],[1,1.05,415.48],[2,1.04,1775.61]],"batl":[[0,1.1,477.27],[1,1.11,680.98]],"ltp":1.07,"tv":4605.04,"id":2284304}]}]}
{"op":"mcm","clk":"1003069633","pt":1580647988045,"mc":[{"id":"1.168224578","rc":[{"batb":[[2,1.04,512.61]],"batl":[[0,1.07,620.04],[1,1.08,571.72]],"ltp":1.07,"tv":4605.04,"id":2284304}]}]}
{"op":"mcm","clk":"1003069780","pt":1580647989004,"mc":[{"id":"1.168224578","rc":[{"batb":[[0,15,5.74],[1,13.5,3.36],[2,11.5,10.62]],"ltp":0.0,"tv":0.0,"id":7797764},{"batl":[[1,1.08,613.73]],"ltp":1.07,"tv":4605.04,"id":2284304}]}]}
{"op":"mcm","clk":"1003071817","pt":1580648001428,"mc":[{"id":"1.168224578","rc":[{"batb":[[0,1.04,512.61],[1,1.03,1571.88],[2,1.01,15.51]],"batl":[[0,1.08,42.01],[1,1.08,0]],"ltp":1.07,"tv":4605.04,"id":2284304}]}]}
{"op":"mcm","clk":"1003071901","pt":1580648001956,"mc":[{"id":"1.168224578","rc":[{"batb":[[0,11.5,10.62],[1,3.85,370.95],[2,1.01,15.51]],"ltp":0.0,"tv":0.0,"id":7797764},{"batb":[[0,1.03,1571.88],[1,1.01,15.51],[2,1.01,0]],"ltp":1.07,"tv":4605.04,"id":2284304}]}]}
{"op":"mcm","clk":"1003072019","pt":1580648002706,"mc":[{"id":"1.168224578","rc":[{"batb":[[1,1.01,15.51],[2,1.01,0]],"ltp":0.0,"tv":0.0,"id":7797764},{"batb":[[0,1.01,15.51],[1,1.01,0]],"ltp":1.07,"tv":4605.04,"id":2284304}]}]}
{"op":"mcm","clk":"1003072284","pt":1580648004408,"mc":[{"id":"1.168224578","rc":[{"batb":[[0,1.03,1243.59],[1,1.01,15.51]],"batl":[[0,1.09,475.94],[1,1.1,692.83]],"ltp":1.07,"tv":4605.04,"id":2284304}]}]}
{"op":"mcm","clk":"1003075021","pt":1580648021485,"mc":[{"id":"1.168224578","rc":[{"trd":[[1.03,8.4]],"batb":[[0,1.03,1239.39]],"ltp":1.03,"tv":4613.45,"id":2284304}],"tv":4613.45}]}
{"op":"mcm","clk":"1003075180","pt":1580648022490,"mc":[{"id":"1.168224578","rc":[{"batb":[[0,24,5.54],[1,15,5.59],[2,1.01,15.51]],"ltp":0.0,"tv":0.0,"id":7797764},{"batl":[[0,1.04,630.87],[1,1.05,595.04]],"ltp":1.03,"tv":4613.45,"id":2284304}]}]}
{"op":"mcm","clk":"1003075255","pt":1580648022932,"mc":[{"id":"1.168224578","rc":[{"batl":[[1,1.05,637.05]],"ltp":1.03,"tv":4613.45,"id":2284304}]}]}
{"op":"mcm","clk":"1003075353","pt":1580648023562,"mc":[{"id":"1.168224578","rc":[{"batb":[[2,4.2,372.95]],"ltp":0.0,"tv":0.0,"id":7797764},{"batb":[[1,1.01,3892.94]],"ltp":1.03,"tv":4613.45,"id":2284304}]}]}
{"op":"mcm","clk":"1003076806","pt":1580648032339,"mc":[{"id":"1.168224578","rc":[{"trd":[[1.03,275.8]],"batb":[[0,1.03,1105.69]],"ltp":1.03,"tv":4880.85,"id":2284304}],"tv":4880.85}]}
{"op":"mcm","clk":"1003076852","pt":1580648032767,"mc":[{"id":"1.168224578","rc":[{"batl":[[1,1.05,587.51]],"ltp":1.03,"tv":4880.85,"id":2284304}]}]}
{"op":"mcm","clk":"1003077256","pt":1580648035386,"mc":[{"id":"1.168224578","rc":[{"batb":[[0,15,5.59],[1,4.2,372.95],[2,1.01,15.51]],"ltp":0.0,"tv":0.0,"id":7797764},{"batb":[[0,1.01,3892.94],[1,1.01,0]],"batl":[[0,1.05,42.01],[1,1.05,0]],"ltp":1.03,"tv":4880.85,"id":2284304}]}]}
{"op":"mcm","clk":"1003077350","pt":1580648035969,"mc":[{"id":"1.168224578","rc":[{"batb":[[1,1.01,15.51],[2,1.01,0]],"ltp":0.0,"tv":0.0,"id":7797764},{"batb":[[0,1.01,15.51]],"ltp":1.03,"tv":4880.85,"id":2284304}]}]}
{"op":"mcm","clk":"1003077580","pt":1580648037460,"mc":[{"id":"1.168224578","rc":[{"batl":[[0,1.03,6.17]],"ltp":1.03,"tv":4880.85,"id":2284304}]}]}
{"op":"mcm","clk":"1003077979","pt":1580648040453,"mc":[{"id":"1.168224578","rc":[{"batb":[[0,1.02,1255.78],[1,1.01,15.51]],"batl":[[1,1.04,1231.63]],"ltp":1.03,"tv":4880.85,"id":2284304}]}]}
{"op":"mcm","clk":"1003078407","pt":1580648043187,"mc":[{"id":"1.168224578","rc":[{"batb":[[1,4.3,371.17],[2,1.01,15.51]],"batl":[[0,160,37.1]],"ltp":0.0,"tv":0.0,"id":7797764},{"batb":[[0,1.01,15.51],[1,1.01,0]],"batl":[[1,1.04,0]],"ltp":1.03,"tv":4880.85,"id":2284304}]}]}
{"op":"mcm","clk":"1003078536","pt":1580648044008,"mc":[{"id":"1.168224578","rc":[{"batb":[[1,1.01,15.51],[2,1.01,0]],"ltp":0.0,"tv":0.0,"id":7797764}]}]}
{"op":"mcm","clk":"1003078793","pt":1580648045713,"mc":[{"id":"1.168224578","rc":[{"batl":[[1,1.07,807.11],[2,1.08,386.37]],"ltp":1.03,"tv":4880.85,"id":2284304}]}]}
{"op":"mcm","clk":"1003079330","pt":1580648049205,"mc":[{"id":"1.168224578","rc":[{"batl":[[1,1.07,0],[2,1.08,0]],"ltp":1.03,"tv":4880.85,"id":2284304}]}]}
{"op":"mcm","clk":"1003079535","pt":1580648050490,"mc":[{"id":"1.168224578","marketDefinition":{"bspMarket":false,"turnInPlayEnabled":true,"persistenceEnabled":true,"marketBaseRate":5.0,"eventId":"29681732","eventTypeId":"2","numberOfWinners":1,"bettingType":"ODDS","marketType":"SET_WINNER","marketTime":"2020-02-02T12:16:00.000Z","suspendTime":"2020-02-02T12:16:00.000Z","bspReconciled":false,"complete":true,"inPlay":true,"crossMatching":true,"runnersVoidable":false,"numberOfActiveRunners":2,"betDelay":3,"status":"SUSPENDED","runners":[{"status":"ACTIVE","sortPriority":1,"id":2284304,"name":"Sergiy Stakhovsky"},{"status":"ACTIVE","sortPriority":2,"id":7797764,"name":"Alexey Vatutin"}],"regulators":["MR_INT"],"countryCode":"FR","discountAllowed":true,"timezone":"UTC","openDate":"2020-02-02T12:16:00.000Z","version":3148797436,"name":"Set 1 Winner","eventName":"Stakhovsky v Vatutin"},"rc":[{"batb":[[0,1.01,15.51],[1,1.01,0]],"ltp":0.0,"tv":0.0,"id":7797764}]}]}
{"op":"mcm","clk":"1003097642","pt":1580648156888,"mc":[{"id":"1.168224578","tv":0.0}]}
{"op":"mcm","clk":"1003097802","pt":1580648157728,"mc":[{"id":"1.168224578","marketDefinition":{"bspMarket":false,"turnInPlayEnabled":true,"persistenceEnabled":true,"marketBaseRate":5.0,"eventId":"29681732","eventTypeId":"2","numberOfWinners":1,"bettingType":"ODDS","marketType":"SET_WINNER","marketTime":"2020-02-02T12:16:00.000Z","suspendTime":"2020-02-02T12:16:00.000Z","bspReconciled":false,"complete":true,"inPlay":true,"crossMatching":false,"runnersVoidable":false,"numberOfActiveRunners":0,"betDelay":3,"status":"CLOSED","settledTime":"2020-02-02T12:55:39.000Z","runners":[{"status":"WINNER","sortPriority":1,"id":2284304,"name":"Sergiy Stakhovsky"},{"status":"LOSER","sortPriority":2,"id":7797764,"name":"Alexey Vatutin"}],"regulators":["MR_INT"],"countryCode":"FR","discountAllowed":true,"timezone":"UTC","openDate":"2020-02-02T12:16:00.000Z","version":3148802943,"name":"Set 1 Winner","eventName":"Stakhovsky v Vatutin"}}]}
