{"op":"mcm","clk":"982860992","pt":1580451020414,"mc":[{"id":"1.168119367","marketDefinition":{"bspMarket":false,"turnInPlayEnabled":true,"persistenceEnabled":true,"marketBaseRate":5.0,"eventId":"29678414","eventTypeId":"2","numberOfWinners":1,"bettingType":"ODDS","marketType":"SET_WINNER","marketTime":"2020-02-01T00:00:00.000Z","suspendTime":"2020-02-01T00:00:00.000Z","bspReconciled":false,"complete":true,"inPlay":false,"crossMatching":false,"runnersVoidable":false,"numberOfActiveRunners":2,"betDelay":0,"status":"OPEN","runners":[{"status":"ACTIVE","sortPriority":1,"id":23010367,"name":"Margaroli/Vavassori"},{"status":"ACTIVE","sortPriority":2,"id":27652444,"name":"Heliovaara/Verbeek"}],"regulators":["MR_INT"],"countryCode":"AU","discountAllowed":false,"timezone":"UTC","openDate":"2020-02-01T00:00:00.000Z","version":3142664098,"name":"Set 2 Winner","eventName":"Margaroli/Vavassori v Heliovaara/Verbeek"},"rc":[{"batb":[[0,1.01,20]],"ltp":0.0,"tv":0.0,"id":23010367},{"batb":[[0,1.01,20]],"ltp":0.0,"tv":0.0,"id":27652444}]}]}
{"op":"mcm","clk":"982861023","pt":1580451021746,"mc":[{"id":"1.168119367","marketDefinition":{"bspMarket":false,"turnInPlayEnabled":true,"persistenceEnabled":true,"marketBaseRate":5.0,"eventId":"29678414","eventTypeId":"2","numberOfWinners":1,"bettingType":"ODDS","marketType":"SET_WINNER","marketTime":"2020-02-01T00:00:00.000Z","suspendTime":"2020-02-01T00:00:00.000Z","bspReconciled":false,"complete":true,"inPlay":false,"crossMatching":false,"runnersVoidable":false,"numberOfActiveRunners":2,"betDelay":0,"status":"OPEN","runners":[{"status":"ACTIVE","sortPriority":1,"id":23010367,"name":"Margaroli/Vavassori"},{"status":"ACTIVE","sortPriority":2,"id":27652444,"name":"Heliovaara/Verbeek"}],"regulators":["MR_INT"],"countryCode":"AU","discountAllowed":true,"timezone":"UTC","openDate":"2020-02-01T00:00:00.000Z","version":3142664098,"name":"Set 2 Winner","eventName":"Margaroli/Vavassori v Heliovaara/Verbeek"}}]}
{"op":"mcm","clk":"982867820","pt":1580451313340,"mc":[{"id":"1.168119367","rc":[{"batb":[[0,1.01,10]],"ltp":0.0,"tv":0.0,"id":23010367},{"batb":[[0,1.01,10]],"ltp":0.0,"tv":0.0,"id":27652444}]}]}
{"op":"mcm","clk":"983256060","pt":1580458554475,"mc":[{"id":"1.168119367","rc":[{"batb":[[0,1.01,10.51]],"ltp":0.0,"tv":0.0,"id":23010367},{"batb":[[0,1.01,10.51]],"ltp":0.0,"tv":0.0,"id":27652444}]}]}
{"op":"mcm","clk":"983301084","pt":1580459033468,"mc":[{"id":"1.168119367","rc":[{"batb":[[0,1.01,13.07]],"ltp":0.0,"tv":0.0,"id":23010367},{"batb":[[0,1.01,13.07]],"ltp":0.0,"tv":0.0,"id":27652444}]}]}
{"op":"mcm","clk":"983301168","pt":1580459034545,"mc":[{"id":"1.168119367","rc":[{"batb":[[0,1.01,11.02]],"ltp":0.0,"tv":0.0,"id":23010367},{"batb":[[0,1.01,11.02]],"ltp":0.0,"tv":0.0,"id":27652444}]}]}
{"op":"mcm","clk":"983821051","pt":1580464952089,"mc":[{"id":"1.168119367","rc":[{"batb":[[0,1.01,11.02]],"ltp":0.0,"tv":0.0,"id":23010367},{"batb":[[0,1.01,11.02]],"ltp":0.0,"tv":0.0,"id":27652444}]}]}
{"op":"mcm","clk":"986476131","pt":1580486552114,"mc":[{"id":"1.168119367","rc":[{"batb":[[0,1.01,11.02]],"ltp":0.0,"tv":0.0,"id":23010367},{"batb":[[0,1.01,11.02]],"ltp":0.0,"tv":0.0,"id":27652444}]}]}
{"op":"mcm","clk":"988691838","pt":1580508152091,"mc":[{"id":"1.168119367","rc":[{"batb":[[0,1.01,11.01]],"ltp":0.0,"tv":0.0,"id":23010367},{"batb":[[0,1.01,11.01]],"ltp":0.0,"tv":0.0,"id":27652444}]}]}
{"op":"mcm","clk":"989192787","pt":1580515628586,"mc":[{"id":"1.168119367","marketDefinition":{"bspMarket":false,"turnInPlayEnabled":true,"persistenceEnabled":true,"marketBaseRate":5.0,"eventId":"29678414","eventTypeId":"2","numberOfWinners":1,"bettingType":"ODDS","marketType":"SET_WINNER","marketTime":"2020-02-02T00:00:00.000Z","suspendTime":"2020-02-02T00:00:00.000Z","bspReconciled":false,"complete":true,"inPlay":false,"crossMatching":false,"runnersVoidable":false,"numberOfActiveRunners":2,"betDelay":0,"status":"OPEN","runners":[{"status":"ACTIVE","sortPriority":1,"id":23010367,"name":"Margaroli/Vavassori"},{"status":"ACTIVE","sortPriority":2,"id":27652444,"name":"Heliovaara/Verbeek"}],"regulators":["MR_INT"],"countryCode":"AU","discountAllowed":true,"timezone":"UTC","openDate":"2020-02-01T00:00:00.000Z","version":3144185910,"name":"Set 2 Winner","eventName":"Margaroli/Vavassori v Heliovaara/Verbeek"}}]}
{"op":"mcm","clk":"989193017","pt":1580515631592,"mc":[{"id":"1.168119367","marketDefinition":{"bspMarket":false,"turnInPlayEnabled":true,"persistenceEnabled":true,"marketBaseRate":5.0,"eventId":"29678414","eventTypeId":"2","numberOfWinners":1,"bettingType":"ODDS","marketType":"SET_WINNER","marketTime":"2020-02-02T00:00:00.000Z","suspendTime":"2020-02-02T00:00:00.000Z","bspReconciled":false,"complete":true,"inPlay":false,"crossMatching":false,"runnersVoidable":false,"numberOfActiveRunners":2,"betDelay":0,"status":"OPEN","runners":[{"status":"ACTIVE","sortPriority":1,"id":23010367,"name":"Margaroli/Vavassori"},{"status":"ACTIVE","sortPriority":2,"id":27652444,"name":"Heliovaara/Verbeek"}],"regulators":["MR_INT"],"countryCode":"AU","discountAllowed":true,"timezone":"UTC","openDate":"2020-02-02T00:00:00.000Z","version":3144185910,"name":"Set 2 Winner","eventName":"Margaroli/Vavassori v Heliovaara/Verbeek"}}]}
{"op":"mcm","clk":"999393986","pt":1580594807659,"mc":[{"id":"1.168119367","rc":[{"batb":[[0,1.01,11.02]],"ltp":0.0,"tv":0.0,"id":23010367},{"batb":[[0,1.01,11.02]],"ltp":0.0,"tv":0.0,"id":27652444}]}]}
{"op":"mcm","clk":"999797144","pt":1580600511640,"mc":[{"id":"1.168119367","marketDefinition":{"bspMarket":false,"turnInPlayEnabled":true,"persistenceEnabled":true,"marketBaseRate":5.0,"eventId":"29678414","eventTypeId":"2","numberOfWinners":1,"bettingType":"ODDS","marketType":"SET_WINNER","marketTime":"2020-02-02T00:30:00.000Z","suspendTime":"2020-02-02T00:30:00.000Z","bspReconciled":false,"complete":true,"inPlay":false,"crossMatching":false,"runnersVoidable":false,"numberOfActiveRunners":2,"betDelay":0,"status":"OPEN","runners":[{"status":"ACTIVE","sortPriority":1,"id":23010367,"name":"Margaroli/Vavassori"},{"status":"ACTIVE","sortPriority":2,"id":27652444,"name":"Heliovaara/Verbeek"}],"regulators":["MR_INT"],"countryCode":"AU","discountAllowed":true,"timezone":"UTC","openDate":"2020-02-02T00:00:00.000Z","version":3147850867,"name":"Set 2 Winner","eventName":"Margaroli/Vavassori v Heliovaara/Verbeek"}}]}
{"op":"mcm","clk":"999797210","pt":1580600512641,"mc":[{"id":"1.168119367","marketDefinition":{"bspMarket":false,"turnInPlayEnabled":true,"persistenceEnabled":true,"marketBaseRate":5.0,"eventId":"29678414","eventTypeId":"2","numberOfWinners":1,"bettingType":"ODDS","marketType":"SET_WINNER","marketTime":"2020-02-02T00:30:00.000Z","suspendTime":"2020-02-02T00:30:00.000Z","bspReconciled":false,"complete":true,"inPlay":false,"crossMatching":false,"runnersVoidable":false,"numberOfActiveRunners":2,"betDelay":0,"status":"OPEN","runners":[{"status":"ACTIVE","sortPriority":1,"id":23010367,"name":"Margaroli/Vavassori"},{"status":"ACTIVE","sortPriority":2,"id":27652444,"name":"Heliovaara/Verbeek"}],"regulators":["MR_INT"],"countryCode":"AU","discountAllowed":true,"timezone":"UTC","openDate":"2020-02-02T00:30:00.000Z","version":3147850867,"name":"Set 2 Winner","eventName":"Margaroli/Vavassori v Heliovaara/Verbeek"}}]}
{"op":"mcm","clk":"999916774","pt":1580602611008,"mc":[{"id":"1.168119367","marketDefinition":{"bspMarket":false,"turnInPlayEnabled":true,"persistenceEnabled":true,"marketBaseRate":5.0,"eventId":"29678414","eventTypeId":"2","numberOfWinners":1,"bettingType":"ODDS","marketType":"SET_WINNER","marketTime":"2020-02-02T01:00:00.000Z","suspendTime":"2020-02-02T01:00:00.000Z","bspReconciled":false,"complete":true,"inPlay":false,"crossMatching":false,"runnersVoidable":false,"numberOfActiveRunners":2,"betDelay":0,"status":"OPEN","runners":[{"status":"ACTIVE","sortPriority":1,"id":23010367,"name":"Margaroli/Vavassori"},{"status":"ACTIVE","sortPriority":2,"id":27652444,"name":"Heliovaara/Verbeek"}],"regulators":["MR_INT"],"countryCode":"AU","discountAllowed":true,"timezone":"UTC","openDate":"2020-02-02T00:30:00.000Z","version":3147905859,"name":"Set 2 Winner","eventName":"Margaroli/Vavassori v Heliovaara/Verbeek"}}]}
{"op":"mcm","clk":"999917049","pt":1580602615018,"mc":[{"id":"1.168119367","marketDefinition":{"bspMarket":false,"turnInPlayEnabled":true,"persistenceEnabled":true,"marketBaseRate":5.0,"eventId":"29678414","eventTypeId":"2","numberOfWinners":1,"bettingType":"ODDS","marketType":"SET_WINNER","marketTime":"2020-02-02T01:00:00.000Z","suspendTime":"2020-02-02T01:00:00.000Z","bspReconciled":false,"complete":true,"inPlay":false,"crossMatching":false,"runnersVoidable":false,"numberOfActiveRunners":2,"betDelay":0,"status":"OPEN","runners":[{"status":"ACTIVE","sortPriority":1,"id":23010367,"name":"Margaroli/Vavassori"},{"status":"ACTIVE","sortPriority":2,"id":27652444,"name":"Heliovaara/Verbeek"}],"regulators":["MR_INT"],"countryCode":"AU","discountAllowed":true,"timezone":"UTC","openDate":"2020-02-02T01:00:00.000Z","version":3147905859,"name":"Set 2 Winner","eventName":"Margaroli/Vavassori v Heliovaara/Verbeek"}}]}
{"op":"mcm","clk":"1000039946","pt":1580605014215,"mc":[{"id":"1.168119367","marketDefinition":{"bspMarket":false,"turnInPlayEnabled":true,"persistenceEnabled":true,"marketBaseRate":5.0,"eventId":"29678414","eventTypeId":"2","numberOfWinners":1,"bettingType":"ODDS","marketType":"SET_WINNER","marketTime":"2020-02-02T00:54:00.000Z","suspendTime":"2020-02-02T00:54:00.000Z","bspReconciled":false,"complete":true,"inPlay":false,"crossMatching":false,"runnersVoidable":false,"numberOfActiveRunners":2,"betDelay":0,"status":"OPEN","runners":[{"status":"ACTIVE","sortPriority":1,"id":23010367,"name":"Margaroli/Vavassori"},{"status":"ACTIVE","sortPriority":2,"id":27652444,"name":"Heliovaara/Verbeek"}],"regulators":["MR_INT"],"countryCode":"AU","discountAllowed":true,"timezone":"UTC","openDate":"2020-02-02T01:00:00.000Z","version":3147960886,"name":"Set 2 Winner","eventName":"Margaroli/Vavassori v Heliovaara/Verbeek"}}]}
{"op":"mcm","clk":"1000040019","pt":1580605016258,"mc":[{"id":"1.168119367","marketDefinition":{"bspMarket":false,"turnInPlayEnabled":true,"persistenceEnabled":true,"marketBaseRate":5.0,"eventId":"29678414","eventTypeId":"2","numberOfWinners":1,"bettingType":"ODDS","marketType":"SET_WINNER","marketTime":"2020-02-02T00:54:00.000Z","suspendTime":"2020-02-02T00:54:00.000Z","bspReconciled":false,"complete":true,"inPlay":false,"crossMatching":false,"runnersVoidable":false,"numberOfActiveRunners":2,"betDelay":0,"status":"OPEN","runners":[{"status":"ACTIVE","sortPriority":1,"id":23010367,"name":"Margaroli/Vavassori"},{"status":"ACTIVE","sortPriority":2,"id":27652444,"name":"Heliovaara/Verbeek"}],"regulators":["MR_INT"],"countryCode":"AU","discountAllowed":true,"timezone":"UTC","openDate":"2020-02-02T00:54:00.000Z","version":3147960886,"name":"Set 2 Winner","eventName":"Margaroli/Vavassori v Heliovaara/Verbeek"}}]}
{"op":"mcm","clk":"1000070110","pt":1580606050651,"mc":[{"id":"1.168119367","marketDefinition":{"bspMarket":false,"turnInPlayEnabled":true,"persistenceEnabled":true,"marketBaseRate":5.0,"eventId":"29678414","eventTypeId":"2","numberOfWinners":1,"bettingType":"ODDS","marketType":"SET_WINNER","marketTime":"2020-02-02T00:54:00.000Z","suspendTime":"2020-02-02T00:54:00.000Z","bspReconciled":false,"complete":true,"inPlay":true,"crossMatching":false,"runnersVoidable":false,"numberOfActiveRunners":2,"betDelay":3,"status":"OPEN","runners":[{"status":"ACTIVE","sortPriority":1,"id":23010367,"name":"Margaroli/Vavassori"},{"status":"ACTIVE","sortPriority":2,"id":27652444,"name":"Heliovaara/Verbeek"}],"regulators":["MR_INT"],"countryCode":"AU","discountAllowed":true,"timezone":"UTC","openDate":"2020-02-02T00:54:00.000Z","version":3147986608,"name":"Set 2 Winner","eventName":"Margaroli/Vavassori v Heliovaara/Verbeek"}}]}
{"op":"mcm","clk":"1000070112","pt":1580606050755,"mc":[{"id":"1.168119367","rc":[{"batb":[[0,1.01,10.52]],"ltp":0.0,"tv":0.0,"id":23010367},{"batb":[[0,1.01,10.52]],"ltp":0.0,"tv":0.0,"id":27652444}]}]}
{"op":"mcm","clk":"1000192276","pt":1580609310630,"mc":[{"id":"1.168119367","rc":[{"batl":[[0,2.72,176.58]],"ltp":0.0,"tv":0.0,"id":23010367},{"batl":[[0,2.5,340.03]],"ltp":0.0,"tv":0.0,"id":27652444}]}]}
{"op":"mcm","clk":"1000193036","pt":1580609328265,"mc":[{"id":"1.168119367","marketDefinition":{"bspMarket":false,"turnInPlayEnabled":true,"persistenceEnabled":true,"marketBaseRate":5.0,"eventId":"29678414","eventTypeId":"2","numberOfWinners":1,"bettingType":"ODDS","marketType":"SET_WINNER","marketTime":"2020-02-02T00:54:00.000Z","suspendTime":"2020-02-02T00:54:00.000Z","bspReconciled":false,"complete":true,"inPlay":true,"crossMatching":true,"runnersVoidable":false,"numberOfActiveRunners":2,"betDelay":3,"status":"OPEN","runners":[{"status":"ACTIVE","sortPriority":1,"id":23010367,"name":"Margaroli/Vavassori"},{"status":"ACTIVE","sortPriority":2,"id":27652444,"name":"Heliovaara/Verbeek"}],"regulators":["MR_INT"],"countryCode":"AU","discountAllowed":true,"timezone":"UTC","openDate":"2020-02-02T00:54:00.000Z","version":3147986608,"name":"Set 2 Winner","eventName":"Margaroli/Vavassori v Heliovaara/Verbeek"}}]}
{"op":"mcm","clk":"1000200328","pt":1580609518263,"mc":[{"id":"1.168119367","rc":[{"batl":[[0,2.6,191.6]],"ltp":0.0,"tv":0.0,"id":23010367}]}]}
{"op":"mcm","clk":"1000201333","pt":1580609543520,"mc":[{"id":"1.168119367","rc":[{"batl":[[0,2.5,207.55]],"ltp":0.0,"tv":0.0,"id":23010367}]}]}
{"op":"mcm","clk":"1000202463","pt":1580609570741,"mc":[{"id":"1.168119367","rc":[{"batl":[[0,2.82,290.88]],"ltp":0.0,"tv":0.0,"id":27652444}]}]}
{"op":"mcm","clk":"1000203933","pt":1580609602976,"mc":[{"id":"1.168119367","rc":[{"batl":[[0,2.36,229.47]],"ltp":0.0,"tv":0.0,"id":23010367}]}]}
{"op":"mcm","clk":"1000207625","pt":1580609683395,"mc":[{"id":"1.168119367","rc":[{"batl":[[0,2.6,191.6]],"ltp":0.0,"tv":0.0,"id":23010367},{"batl":[[0,2.6,323.69]],"ltp":0.0,"tv":0.0,"id":27652444}]}]}
{"op":"mcm","clk":"1000208901","pt":1580609708425,"mc":[{"id":"1.168119367","rc":[{"batl":[[0,2.5,344.82]],"ltp":0.0,"tv":0.0,"id":27652444}]}]}
{"op":"mcm","clk":"1000211576","pt":1580609768605,"mc":[{"id":"1.168119367","rc":[{"batl":[[0,2.5,207.55]],"ltp":0.0,"tv":0.0,"id":23010367}]}]}
{"op":"mcm","clk":"1000217261","pt":1580609899480,"mc":[{"id":"1.168119367","rc":[{"batl":[[0,2.36,229.47]],"ltp":0.0,"tv":0.0,"id":23010367},{"batl":[[0,2.92,277.74]],"ltp":0.0,"tv":0.0,"id":27652444}]}]}
{"op":"mcm","clk":"1000218800","pt":1580609938840,"mc":[{"id":"1.168119367","rc":[{"batl":[[0,2.72,302.92]],"ltp":0.0,"tv":0.0,"id":27652444}]}]}
{"op":"mcm","clk":"1000219353","pt":1580609951589,"mc":[{"id":"1.168119367","rc":[{"batl":[[1,1000,0.02]],"ltp":0.0,"tv":0.0,"id":23010367}]}]}
{"op":"mcm","clk":"1000219374","pt":1580609951854,"mc":[{"id":"1.168119367","rc":[{"batl":[[1,1000,0]],"ltp":0.0,"tv":0.0,"id":23010367}]}]}
{"op":"mcm","clk":"1000219476","pt":1580609954946,"mc":[{"id":"1.168119367","rc":[{"trd":[[1.58,0.02]],"ltp":1.58,"tv":0.01,"id":23010367},{"trd":[[2.72,0.01]],"batl":[[0,2.72,302.91]],"ltp":2.72,"tv":0.0,"id":27652444}],"tv":0.02}]}
{"op":"mcm","clk":"1000219770","pt":1580609961679,"mc":[{"id":"1.168119367","rc":[{"batb":[[0,1.01,10.53]],"ltp":1.58,"tv":0.01,"id":23010367}]}]}
{"op":"mcm","clk":"1000219786","pt":1580609962089,"mc":[{"id":"1.168119367","rc":[{"batb":[[0,1.01,10.52]],"ltp":1.58,"tv":0.01,"id":23010367}]}]}
{"op":"mcm","clk":"1000219921","pt":1580609965187,"mc":[{"id":"1.168119367","rc":[{"batb":[[0,1.01,10.53]],"ltp":1.58,"tv":0.01,"id":23010367}]}]}
{"op":"mcm","clk":"1000227051","pt":1580610130474,"mc":[{"id":"1.168119367","rc":[{"batl":[[0,2.1,287.11]],"ltp":1.58,"tv":0.01,"id":23010367},{"batl":[[0,3.45,226.82]],"ltp":2.72,"tv":0.0,"id":27652444}]}]}
{"op":"mcm","clk":"1000228150","pt":1580610155415,"mc":[{"id":"1.168119367","rc":[{"batl":[[0,1.95,330.84]],"ltp":1.58,"tv":0.01,"id":23010367},{"batl":[[0,3.9,198.26]],"ltp":2.72,"tv":0.0,"id":27652444}]}]}
{"op":"mcm","clk":"1000228562","pt":1580610164530,"mc":[{"id":"1.168119367","rc":[{"batl":[[0,2.3,237.57]],"ltp":1.58,"tv":0.01,"id":23010367},{"batl":[[0,3,269.06]],"ltp":2.72,"tv":0.0,"id":27652444}]}]}
{"op":"mcm","clk":"1000229451","pt":1580610183564,"mc":[{"id":"1.168119367","rc":[{"batl":[[0,2.72,302.91]],"ltp":2.72,"tv":0.0,"id":27652444}]}]}
{"op":"mcm","clk":"1000230810","pt":1580610214695,"mc":[{"id":"1.168119367","rc":[{"batl":[[0,3.15,251.81]],"ltp":2.72,"tv":0.0,"id":27652444}]}]}
{"op":"mcm","clk":"1000231721","pt":1580610237730,"mc":[{"id":"1.168119367","rc":[{"batl":[[0,2.72,302.91]],"ltp":2.72,"tv":0.0,"id":27652444}]}]}
{"op":"mcm","clk":"1000232753","pt":1580610259943,"mc":[{"id":"1.168119367","rc":[{"batl":[[0,2.72,177.48]],"ltp":1.58,"tv":0.01,"id":23010367},{"batl":[[0,2.5,344.82]],"ltp":2.72,"tv":0.0,"id":27652444}]}]}
{"op":"mcm","clk":"1000234372","pt":1580610298824,"mc":[{"id":"1.168119367","rc":[{"batl":[[0,2.5,207.56]],"ltp":1.58,"tv":0.01,"id":23010367}]}]}
{"op":"mcm","clk":"1000235694","pt":1580610327863,"mc":[{"id":"1.168119367","rc":[{"batl":[[0,2.82,290.87]],"ltp":2.72,"tv":0.0,"id":27652444}]}]}
{"op":"mcm","clk":"1000237201","pt":1580610360975,"mc":[{"id":"1.168119367","rc":[{"batl":[[0,2.36,229.47]],"ltp":1.58,"tv":0.01,"id":23010367}]}]}
{"op":"mcm","clk":"1000240570","pt":1580610434577,"mc":[{"id":"1.168119367","rc":[{"batl":[[0,2.6,192.35]],"ltp":1.58,"tv":0.01,"id":23010367},{"batl":[[0,2.6,322.95]],"ltp":2.72,"tv":0.0,"id":27652444}]}]}
{"op":"mcm","clk":"1000242015","pt":1580610466724,"mc":[{"id":"1.168119367","rc":[{"batl":[[0,2.42,358.23]],"ltp":2.72,"tv":0.0,"id":27652444}]}]}
{"op":"mcm","clk":"1000242714","pt":1580610484980,"mc":[{"id":"1.168119367","rc":[{"batl":[[0,2.36,229.47]],"ltp":1.58,"tv":0.01,"id":23010367},{"batl":[[0,2.92,277.73]],"ltp":2.72,"tv":0.0,"id":27652444}]}]}
{"op":"mcm","clk":"1000247772","pt":1580610602819,"mc":[{"id":"1.168119367","rc":[{"batl":[[0,2.16,267.07]],"ltp":1.58,"tv":0.01,"id":23010367},{"batl":[[0,3.3,242.23]],"ltp":2.72,"tv":0.0,"id":27652444}]}]}
{"op":"mcm","clk":"1000249251","pt":1580610633643,"mc":[{"id":"1.168119367","rc":[{"batl":[[0,1.82,387.24]],"ltp":1.58,"tv":0.01,"id":23010367},{"batl":[[0,4.6,169.39]],"ltp":2.72,"tv":0.0,"id":27652444}]}]}
{"op":"mcm","clk":"1000249694","pt":1580610642675,"mc":[{"id":"1.168119367","rc":[{"batl":[[1,1000,0.02]],"ltp":1.58,"tv":0.01,"id":23010367}]}]}
{"op":"mcm","clk":"1000249711","pt":1580610643037,"mc":[{"id":"1.168119367","rc":[{"batl":[[1,1000,0]],"ltp":1.58,"tv":0.01,"id":23010367}]}]}
{"op":"mcm","clk":"1000249847","pt":1580610646180,"mc":[{"id":"1.168119367","rc":[{"batb":[[0,1.01,10.52]],"ltp":1.58,"tv":0.01,"id":23010367}]}]}
{"op":"mcm","clk":"1000250338","pt":1580610657376,"mc":[{"id":"1.168119367","rc":[{"batb":[[0,1.01,13.56]],"ltp":1.58,"tv":0.01,"id":23010367}]}]}
{"op":"mcm","clk":"1000250372","pt":1580610658151,"mc":[{"id":"1.168119367","rc":[{"batb":[[0,1.01,10.52]],"ltp":1.58,"tv":0.01,"id":23010367}]}]}
{"op":"mcm","clk":"1000250511","pt":1580610661248,"mc":[{"id":"1.168119367","rc":[{"batb":[[0,1.01,10.53]],"ltp":1.58,"tv":0.01,"id":23010367}]}]}
{"op":"mcm","clk":"1000251429","pt":1580610680417,"mc":[{"id":"1.168119367","rc":[{"batl":[[0,2.04,306.52]],"ltp":1.58,"tv":0.01,"id":23010367},{"batl":[[0,3.65,213.43]],"ltp":2.72,"tv":0.0,"id":27652444}]}]}
{"op":"mcm","clk":"1000253041","pt":1580610710640,"mc":[{"id":"1.168119367","rc":[{"batl":[[0,3.15,251.81]],"ltp":2.72,"tv":0.0,"id":27652444}]}]}
{"op":"mcm","clk":"1000254493","pt":1580610738867,"mc":[{"id":"1.168119367","rc":[{"batl":[[0,2.5,207.56]],"ltp":1.58,"tv":0.01,"id":23010367},{"batl":[[0,2.72,302.91]],"ltp":2.72,"tv":0.0,"id":27652444}]}]}
{"op":"mcm","clk":"1000255503","pt":1580610760980,"mc":[{"id":"1.168119367","rc":[{"batl":[[0,2.5,344.82]],"ltp":2.72,"tv":0.0,"id":27652444}]}]}
{"op":"mcm","clk":"1000278478","pt":1580611307598,"mc":[{"id":"1.168119367","rc":[{"batl":[[0,2.82,153.39]],"ltp":1.58,"tv":0.01,"id":23010367},{"batl":[[0,2.42,377.3]],"ltp":2.72,"tv":0.0,"id":27652444}]}]}
{"op":"mcm","clk":"1000279144","pt":1580611326607,"mc":[{"id":"1.168119367","rc":[{"batl":[[0,3.15,128.16]],"ltp":1.58,"tv":0.01,"id":23010367},{"batl":[[0,2.22,431.84]],"ltp":2.72,"tv":0.0,"id":27652444}]}]}
{"op":"mcm","clk":"1000280197","pt":1580611351655,"mc":[{"id":"1.168119367","rc":[{"batl":[[0,2.1,474.55]],"ltp":2.72,"tv":0.0,"id":27652444}]}]}
{"op":"mcm","clk":"1000281155","pt":1580611374661,"mc":[{"id":"1.168119367","rc":[{"batl":[[0,4.2,89.59]],"ltp":1.58,"tv":0.01,"id":23010367},{"batl":[[0,1.89,562.85]],"ltp":2.72,"tv":0.0,"id":27652444}]}]}
{"op":"mcm","clk":"1000283226","pt":1580611422915,"mc":[{"id":"1.168119367","rc":[{"batl":[[0,6,63.91]],"ltp":1.58,"tv":0.01,"id":23010367},{"batl":[[0,1.66,731.64]],"ltp":2.72,"tv":0.0,"id":27652444}]}]}
{"op":"mcm","clk":"1000285495","pt":1580611481413,"mc":[{"id":"1.168119367","rc":[{"batl":[[0,1.89,821.04]],"ltp":2.72,"tv":0.0,"id":27652444}]}]}
{"op":"mcm","clk":"1000286344","pt":1580611503433,"mc":[{"id":"1.168119367","rc":[{"batl":[[0,2.3,601.64]],"ltp":2.72,"tv":0.0,"id":27652444}]}]}
{"op":"mcm","clk":"1000287801","pt":1580611534665,"mc":[{"id":"1.168119367","rc":[{"batl":[[0,2.22,49.66]],"ltp":1.58,"tv":0.01,"id":23010367},{"batl":[[0,3.15,397.15]],"ltp":2.72,"tv":0.0,"id":27652444}]}]}
{"op":"mcm","clk":"1000291386","pt":1580611619859,"mc":[{"id":"1.168119367","rc":[{"batl":[[0,2.82,454.24]],"ltp":2.72,"tv":0.0,"id":27652444}]}]}
{"op":"mcm","clk":"1000292300","pt":1580611643895,"mc":[{"id":"1.168119367","rc":[{"batl":[[0,3.3,378]],"ltp":2.72,"tv":0.0,"id":27652444}]}]}
{"op":"mcm","clk":"1000293295","pt":1580611669062,"mc":[{"id":"1.168119367","rc":[{"batl":[[0,4.6,259.33]],"ltp":2.72,"tv":0.0,"id":27652444}]}]}
{"op":"mcm","clk":"1000293343","pt":1580611670038,"mc":[{"id":"1.168119367","rc":[{"batl":[[0,1.82,165.57]],"ltp":1.58,"tv":0.01,"id":23010367}]}]}
{"op":"mcm","clk":"1000295006","pt":1580611708110,"mc":[{"id":"1.168119367","rc":[{"batl":[[0,2.1,70.93]],"ltp":1.58,"tv":0.01,"id":23010367},{"batl":[[0,3.45,358.1]],"ltp":2.72,"tv":0.0,"id":27652444}]}]}
{"op":"mcm","clk":"1000296088","pt":1580611737259,"mc":[{"id":"1.168119367","rc":[{"batl":[[0,1.89,131.55]],"ltp":1.58,"tv":0.01,"id":23010367},{"batl":[[0,4.2,287.45]],"ltp":2.72,"tv":0.0,"id":27652444}]}]}
{"op":"mcm","clk":"1000296682","pt":1580611751260,"mc":[{"id":"1.168119367","rc":[{"batl":[[0,2.42,27.35]],"ltp":1.58,"tv":0.01,"id":23010367},{"batl":[[0,2.82,454.24]],"ltp":2.72,"tv":0.0,"id":27652444}]}]}
{"op":"mcm","clk":"1000297596","pt":1580611773269,"mc":[{"id":"1.168119367","rc":[{"batl":[[0,2.72,2.59]],"ltp":1.58,"tv":0.01,"id":23010367},{"batl":[[0,2.5,536.26]],"ltp":2.72,"tv":0.0,"id":27652444}]}]}
{"op":"mcm","clk":"1000299355","pt":1580611816465,"mc":[{"id":"1.168119367","rc":[{"batl":[[0,2.5,17.64]],"ltp":1.58,"tv":0.01,"id":23010367}]}]}
{"op":"mcm","clk":"1000301129","pt":1580611854482,"mc":[{"id":"1.168119367","rc":[{"batl":[[0,2.36,31.81]],"ltp":1.58,"tv":0.01,"id":23010367}]}]}
{"op":"mcm","clk":"1000301165","pt":1580611855310,"mc":[{"id":"1.168119367","rc":[{"batl":[[0,2.92,437.44]],"ltp":2.72,"tv":0.0,"id":27652444}]}]}
{"op":"mcm","clk":"1000308723","pt":1580612030435,"mc":[{"id":"1.168119367","rc":[{"batl":[[0,2.16,62.08]],"ltp":1.58,"tv":0.01,"id":23010367},{"batl":[[0,3.3,378]],"ltp":2.72,"tv":0.0,"id":27652444}]}]}
{"op":"mcm","clk":"1000309390","pt":1580612050476,"mc":[{"id":"1.168119367","rc":[{"batl":[[0,2.42,27.35]],"ltp":1.58,"tv":0.01,"id":23010367},{"batl":[[0,2.82,454.24]],"ltp":2.72,"tv":0.0,"id":27652444}]}]}
{"op":"mcm","clk":"1000310336","pt":1580612076721,"mc":[{"id":"1.168119367","rc":[{"batl":[[0,2.16,62.08]],"ltp":1.58,"tv":0.01,"id":23010367},{"batl":[[0,3.3,378]],"ltp":2.72,"tv":0.0,"id":27652444}]}]}
{"op":"mcm","clk":"1000311501","pt":1580612105859,"mc":[{"id":"1.168119367","rc":[{"batl":[[0,2.42,21.35]],"ltp":1.58,"tv":0.01,"id":23010367},{"batl":[[0,2.82,459.38]],"ltp":2.72,"tv":0.0,"id":27652444}]}]}
{"op":"mcm","clk":"1000312424","pt":1580612130112,"mc":[{"id":"1.168119367","rc":[{"batl":[[0,2.22,57.88]],"ltp":1.58,"tv":0.01,"id":23010367},{"batl":[[0,3.15,391.39]],"ltp":2.72,"tv":0.0,"id":27652444}]}]}
{"op":"mcm","clk":"1000313087","pt":1580612150227,"mc":[{"id":"1.168119367","rc":[{"batl":[[0,2.1,70.93]],"ltp":1.58,"tv":0.01,"id":23010367}]}]}
{"op":"mcm","clk":"1000314872","pt":1580612182467,"mc":[{"id":"1.168119367","rc":[{"batl":[[0,2.42,21.35]],"ltp":1.58,"tv":0.01,"id":23010367},{"batl":[[0,2.82,459.38]],"ltp":2.72,"tv":0.0,"id":27652444}]}]}
{"op":"mcm","clk":"1000316038","pt":1580612208695,"mc":[{"id":"1.168119367","rc":[{"batl":[[0,2.5,543.56]],"ltp":2.72,"tv":0.0,"id":27652444}]}]}
{"op":"mcm","clk":"1000318057","pt":1580612260062,"mc":[{"id":"1.168119367","rc":[{"batl":[[0,2.42,27.35]],"ltp":1.58,"tv":0.01,"id":23010367}]}]}
{"op":"mcm","clk":"1000318089","pt":1580612261041,"mc":[{"id":"1.168119367","rc":[{"batl":[[0,2.82,454.24]],"ltp":2.72,"tv":0.0,"id":27652444}]}]}
{"op":"mcm","clk":"1000319901","pt":1580612312453,"mc":[{"id":"1.168119367","rc":[{"batl":[[0,2.72,2.59]],"ltp":1.58,"tv":0.01,"id":23010367},{"batl":[[0,2.5,536.26]],"ltp":2.72,"tv":0.0,"id":27652444}]}]}
{"op":"mcm","clk":"1000321145","pt":1580612339657,"mc":[{"id":"1.168119367","rc":[{"batl":[[0,2.42,27.35]],"ltp":1.58,"tv":0.01,"id":23010367},{"batl":[[0,2.82,454.24]],"ltp":2.72,"tv":0.0,"id":27652444}]}]}
{"op":"mcm","clk":"1000322305","pt":1580612365801,"mc":[{"id":"1.168119367","rc":[{"batl":[[0,2.36,586.87]],"ltp":2.72,"tv":0.0,"id":27652444}]}]}
{"op":"mcm","clk":"1000323583","pt":1580612391144,"mc":[{"id":"1.168119367","rc":[{"batl":[[0,2.42,27.35]],"ltp":1.58,"tv":0.01,"id":23010367}]}]}
{"op":"mcm","clk":"1000323636","pt":1580612391944,"mc":[{"id":"1.168119367","rc":[{"batl":[[0,2.82,454.24]],"ltp":2.72,"tv":0.0,"id":27652444}]}]}
{"op":"mcm","clk":"1000325445","pt":1580612419983,"mc":[{"id":"1.168119367","rc":[{"batl":[[0,2.1,81.1]],"ltp":1.58,"tv":0.01,"id":23010367},{"batl":[[0,3.45,351.93]],"ltp":2.72,"tv":0.0,"id":27652444}]}]}
{"op":"mcm","clk":"1000330427","pt":1580612501179,"mc":[{"id":"1.168119367","rc":[{"batl":[[0,1.82,165.57]],"ltp":1.58,"tv":0.01,"id":23010367},{"batl":[[0,4.6,259.33]],"ltp":2.72,"tv":0.0,"id":27652444}]}]}
{"op":"mcm","clk":"1000331554","pt":1580612521439,"mc":[{"id":"1.168119367","rc":[{"batl":[[0,2.04,89.44]],"ltp":1.58,"tv":0.01,"id":23010367},{"batl":[[0,3.65,335.09]],"ltp":2.72,"tv":0.0,"id":27652444}]}]}
{"op":"mcm","clk":"1000332985","pt":1580612548260,"mc":[{"id":"1.168119367","rc":[{"batl":[[0,2.36,31.81]],"ltp":1.58,"tv":0.01,"id":23010367},{"batl":[[0,2.92,437.44]],"ltp":2.72,"tv":0.0,"id":27652444}]}]}
{"op":"mcm","clk":"1000333742","pt":1580612567301,"mc":[{"id":"1.168119367","rc":[{"batl":[[0,2.16,62.08]],"ltp":1.58,"tv":0.01,"id":23010367},{"batl":[[0,3.3,378]],"ltp":2.72,"tv":0.0,"id":27652444}]}]}
{"op":"mcm","clk":"1000334286","pt":1580612580428,"mc":[{"id":"1.168119367","rc":[{"batl":[[0,1.95,115.41]],"ltp":1.58,"tv":0.01,"id":23010367},{"batl":[[0,3.9,306.97]],"ltp":2.72,"tv":0.0,"id":27652444}]}]}
{"op":"mcm","clk":"1000335277","pt":1580612605622,"mc":[{"id":"1.168119367","rc":[{"trd":[[1.58,0.05]],"batb":[[0,1.01,10.52]],"batl":[[0,1.58,324.21]],"ltp":1.58,"tv":0.04,"id":23010367},{"batl":[[0,7.2,164.5]],"ltp":2.72,"tv":0.0,"id":27652444}],"tv":0.05}]}
{"op":"mcm","clk":"1000336629","pt":1580612638662,"mc":[{"id":"1.168119367","rc":[{"batl":[[0,1.89,131.53]],"ltp":1.58,"tv":0.04,"id":23010367},{"batl":[[0,4.2,287.46]],"ltp":2.72,"tv":0.0,"id":27652444}]}]}
{"op":"mcm","clk":"1000338391","pt":1580612674100,"mc":[{"id":"1.168119367","rc":[{"batl":[[0,2.5,543.57]],"ltp":2.72,"tv":0.0,"id":27652444}]}]}
{"op":"mcm","clk":"1000342094","pt":1580612740641,"mc":[{"id":"1.168119367","rc":[{"batl":[[0,1.95,775.02]],"ltp":2.72,"tv":0.0,"id":27652444}]}]}
{"op":"mcm","clk":"1000344239","pt":1580612778887,"mc":[{"id":"1.168119367","rc":[{"batl":[[0,2.04,732.31]],"ltp":2.72,"tv":0.0,"id":27652444}]}]}
{"op":"mcm","clk":"1000344999","pt":1580612792983,"mc":[{"id":"1.168119367","rc":[{"batl":[[0,1.71,982.71]],"ltp":2.72,"tv":0.0,"id":27652444}]}]}
{"op":"mcm","clk":"1000347863","pt":1580612834738,"mc":[{"id":"1.168119367","rc":[{"batl":[[0,2.16,667.09]],"ltp":2.72,"tv":0.0,"id":27652444}]}]}
{"op":"mcm","clk":"1000350057","pt":1580612870617,"mc":[{"id":"1.168119367","rc":[{"batl":[[0,1.71,982.71]],"ltp":2.72,"tv":0.0,"id":27652444}]}]}
{"op":"mcm","clk":"1000352331","pt":1580612907639,"mc":[{"id":"1.168119367","rc":[{"batl":[[0,1.62,1093.88]],"ltp":2.72,"tv":0.0,"id":27652444}]}]}
{"op":"mcm","clk":"1000353003","pt":1580612918666,"mc":[{"id":"1.168119367","rc":[{"batl":[[0,14,3.45]],"ltp":1.58,"tv":0.04,"id":23010367},{"trd":[[1.48,0.02]],"batb":[[0,1.01,10.51]],"batl":[[0,1.43,1438.56]],"ltp":1.48,"tv":0.02,"id":27652444}],"tv":0.07}]}
{"op":"mcm","clk":"1000355558","pt":1580612960744,"mc":[{"id":"1.168119367","rc":[{"batl":[[0,65,26.94]],"ltp":1.58,"tv":0.04,"id":23010367},{"batl":[[0,1.32,1797.03]],"ltp":1.48,"tv":0.02,"id":27652444}]}]}
{"op":"mcm","clk":"1000358697","pt":1580613011910,"mc":[{"id":"1.168119367","rc":[{"batl":[[0,14,3.46]],"ltp":1.58,"tv":0.04,"id":23010367},{"batl":[[0,1.43,1438.56]],"ltp":1.48,"tv":0.02,"id":27652444}]}]}
{"op":"mcm","clk":"1000361412","pt":1580613053653,"mc":[{"id":"1.168119367","rc":[{"batl":[[0,1.53,1225.48]],"ltp":1.48,"tv":0.02,"id":27652444}]}]}
{"op":"mcm","clk":"1000363990","pt":1580613091206,"mc":[{"id":"1.168119367","rc":[{"batl":[[0,1.66,1038.91]],"ltp":1.48,"tv":0.02,"id":27652444}]}]}
{"op":"mcm","clk":"1000366539","pt":1580613134371,"mc":[{"id":"1.168119367","rc":[{"batl":[[0,17,7.88]],"ltp":1.58,"tv":0.04,"id":23010367},{"batl":[[0,1.4,1514.16]],"ltp":1.48,"tv":0.02,"id":27652444}]}]}
{"op":"mcm","clk":"1000367822","pt":1580613156388,"mc":[{"id":"1.168119367","rc":[{"batl":[[0,1.47,1348.5]],"ltp":1.48,"tv":0.02,"id":27652444}]}]}
{"op":"mcm","clk":"1000369014","pt":1580613179687,"mc":[{"id":"1.168119367","marketDefinition":{"bspMarket":false,"turnInPlayEnabled":true,"persistenceEnabled":true,"marketBaseRate":5.0,"eventId":"29678414","eventTypeId":"2","numberOfWinners":1,"bettingType":"ODDS","marketType":"SET_WINNER","marketTime":"2020-02-02T00:54:00.000Z","suspendTime":"2020-02-02T00:54:00.000Z","bspReconciled":false,"complete":true,"inPlay":true,"crossMatching":true,"runnersVoidable":false,"numberOfActiveRunners":2,"betDelay":3,"status":"SUSPENDED","runners":[{"status":"ACTIVE","sortPriority":1,"id":23010367,"name":"Margaroli/Vavassori"},{"status":"ACTIVE","sortPriority":2,"id":27652444,"name":"Heliovaara/Verbeek"}],"regulators":["MR_INT"],"countryCode":"AU","discountAllowed":true,"timezone":"UTC","openDate":"2020-02-02T00:54:00.000Z","version":3148100121,"name":"Set 2 Winner","eventName":"Margaroli/Vavassori v Heliovaara/Verbeek"}}]}
{"op":"mcm","clk":"1000370618","pt":1580613211674,"mc":[{"id":"1.168119367","tv":0.0}]}
{"op":"mcm","clk":"1000370690","pt":1580613212768,"mc":[{"id":"1.168119367","marketDefinition":{"bspMarket":false,"turnInPlayEnabled":true,"persistenceEnabled":true,"marketBaseRate":5.0,"eventId":"29678414","eventTypeId":"2","numberOfWinners":1,"bettingType":"ODDS","marketType":"SET_WINNER","marketTime":"2020-02-02T00:54:00.000Z","suspendTime":"2020-02-02T00:54:00.000Z","bspReconciled":false,"complete":true,"inPlay":true,"crossMatching":false,"runnersVoidable":false,"numberOfActiveRunners":0,"betDelay":3,"status":"CLOSED","settledTime":"2020-02-02T03:13:30.000Z","runners":[{"status":"LOSER","sortPriority":1,"id":23010367,"name":"Margaroli/Vavassori"},{"status":"WINNER","sortPriority":2,"id":27652444,"name":"Heliovaara/Verbeek"}],"regulators":["MR_INT"],"countryCode":"AU","discountAllowed":true,"timezone":"UTC","openDate":"2020-02-02T00:54:00.000Z","version":3148100153,"name":"Set 2 Winner","eventName":"Margaroli/Vavassori v Heliovaara/Verbeek"}}]}
