{"op":"mcm","clk":"982860992","pt":1580451020414,"mc":[{"id":"1.168119364","marketDefinition":{"bspMarket":false,"turnInPlayEnabled":true,"persistenceEnabled":true,"marketBaseRate":5.0,"eventId":"29678414","eventTypeId":"2","numberOfWinners":1,"bettingType":"ODDS","marketType":"MATCH_ODDS","marketTime":"2020-02-01T00:00:00.000Z","suspendTime":"2020-02-01T00:00:00.000Z","bspReconciled":false,"complete":true,"inPlay":false,"crossMatching":false,"runnersVoidable":false,"numberOfActiveRunners":2,"betDelay":0,"status":"OPEN","runners":[{"status":"ACTIVE","sortPriority":1,"id":23010367,"name":"Margaroli/Vavassori"},{"status":"ACTIVE","sortPriority":2,"id":27652444,"name":"Heliovaara/Verbeek"}],"regulators":["MR_INT"],"countryCode":"AU","discountAllowed":false,"timezone":"UTC","openDate":"2020-02-01T00:00:00.000Z","version":3142664094,"name":"Match Odds","eventName":"Margaroli/Vavassori v Heliovaara/Verbeek"},"rc":[{"batb":[[0,1.01,30]],"ltp":0.0,"tv":0.0,"id":23010367},{"batb":[[0,1.01,30]],"ltp":0.0,"tv":0.0,"id":27652444}]}]}
{"op":"mcm","clk":"982861023","pt":1580451021746,"mc":[{"id":"1.168119364","marketDefinition":{"bspMarket":false,"turnInPlayEnabled":true,"persistenceEnabled":true,"marketBaseRate":5.0,"eventId":"29678414","eventTypeId":"2","numberOfWinners":1,"bettingType":"ODDS","marketType":"MATCH_ODDS","marketTime":"2020-02-01T00:00:00.000Z","suspendTime":"2020-02-01T00:00:00.000Z","bspReconciled":false,"complete":true,"inPlay":false,"crossMatching":false,"runnersVoidable":false,"numberOfActiveRunners":2,"betDelay":0,"status":"OPEN","runners":[{"status":"ACTIVE","sortPriority":1,"id":23010367,"name":"Margaroli/Vavassori"},{"status":"ACTIVE","sortPriority":2,"id":27652444,"name":"Heliovaara/Verbeek"}],"regulators":["MR_INT"],"countryCode":"AU","discountAllowed":true,"timezone":"UTC","openDate":"2020-02-01T00:00:00.000Z","version":3142664094,"name":"Match Odds","eventName":"Margaroli/Vavassori v Heliovaara/Verbeek"}}]}
{"op":"mcm","clk":"982862475","pt":1580451087107,"mc":[{"id":"1.168119364","rc":[{"batb":[[0,1.01,330]],"ltp":0.0,"tv":0.0,"id":23010367}]}]}
{"op":"mcm","clk":"982862508","pt":1580451088291,"mc":[{"id":"1.168119364","rc":[{"batb":[[0,1.01,330]],"ltp":0.0,"tv":0.0,"id":27652444}]}]}
{"op":"mcm","clk":"982863891","pt":1580451140466,"mc":[{"id":"1.168119364","rc":[{"batl":[[0,990,2.2]],"ltp":0.0,"tv":0.0,"id":23010367},{"batl":[[0,990,2.2]],"ltp":0.0,"tv":0.0,"id":27652444}]}]}
{"op":"mcm","clk":"982867084","pt":1580451283621,"mc":[{"id":"1.168119364","rc":[{"batb":[[0,1.09,76.37],[1,1.01,330]],"ltp":0.0,"tv":0.0,"id":23010367},{"batb":[[0,1.09,76.37],[1,1.01,330]],"ltp":0.0,"tv":0.0,"id":27652444}]}]}
{"op":"mcm","clk":"982867416","pt":1580451298219,"mc":[{"id":"1.168119364","marketDefinition":{"bspMarket":false,"turnInPlayEnabled":true,"persistenceEnabled":true,"marketBaseRate":5.0,"eventId":"29678414","eventTypeId":"2","numberOfWinners":1,"bettingType":"ODDS","marketType":"MATCH_ODDS","marketTime":"2020-02-01T00:00:00.000Z","suspendTime":"2020-02-01T00:00:00.000Z","bspReconciled":false,"complete":true,"inPlay":false,"crossMatching":true,"runnersVoidable":false,"numberOfActiveRunners":2,"betDelay":0,"status":"OPEN","runners":[{"status":"ACTIVE","sortPriority":1,"id":23010367,"name":"Margaroli/Vavassori"},{"status":"ACTIVE","sortPriority":2,"id":27652444,"name":"Heliovaara/Verbeek"}],"regulators":["MR_INT"],"countryCode":"AU","discountAllowed":true,"timezone":"UTC","openDate":"2020-02-01T00:00:00.000Z","version":3142664094,"name":"Match Odds","eventName":"Margaroli/Vavassori v Heliovaara/Verbeek"}}]}
{"op":"mcm","clk":"982867820","pt":1580451313340,"mc":[{"id":"1.168119364","rc":[{"batb":[[1,1.01,310]],"ltp":0.0,"tv":0.0,"id":23010367},{"batb":[[1,1.01,310]],"ltp":0.0,"tv":0.0,"id":27652444}]}]}
{"op":"mcm","clk":"983200178","pt":1580457752126,"mc":[{"id":"1.168119364","rc":[{"batb":[[0,1.09,76.17]],"ltp":0.0,"tv":0.0,"id":23010367},{"batb":[[0,1.09,76.17]],"ltp":0.0,"tv":0.0,"id":27652444}]}]}
{"op":"mcm","clk":"983256176","pt":1580458555506,"mc":[{"id":"1.168119364","rc":[{"batb":[[1,1.01,310.51]],"ltp":0.0,"tv":0.0,"id":23010367},{"batb":[[1,1.01,310.51]],"ltp":0.0,"tv":0.0,"id":27652444}]}]}
{"op":"mcm","clk":"983301168","pt":1580459034545,"mc":[{"id":"1.168119364","rc":[{"batb":[[1,1.01,313.07]],"ltp":0.0,"tv":0.0,"id":23010367},{"batb":[[1,1.01,313.07]],"ltp":0.0,"tv":0.0,"id":27652444}]}]}
{"op":"mcm","clk":"983301256","pt":1580459035577,"mc":[{"id":"1.168119364","rc":[{"batb":[[1,1.01,311.02]],"ltp":0.0,"tv":0.0,"id":23010367},{"batb":[[1,1.01,311.02]],"ltp":0.0,"tv":0.0,"id":27652444}]}]}
{"op":"mcm","clk":"983722572","pt":1580463930587,"mc":[{"id":"1.168119364","rc":[{"batb":[[1,1.02,25.2],[2,1.01,311.02]],"ltp":0.0,"tv":0.0,"id":23010367}]}]}
{"op":"mcm","clk":"983722641","pt":1580463931207,"mc":[{"id":"1.168119364","rc":[{"batb":[[1,1.03,8.4],[2,1.02,25.2]],"ltp":0.0,"tv":0.0,"id":23010367},{"batb":[[1,1.03,8.4],[2,1.02,25.2]],"ltp":0.0,"tv":0.0,"id":27652444}]}]}
{"op":"mcm","clk":"983821051","pt":1580464952089,"mc":[{"id":"1.168119364","rc":[{"batb":[[0,1.09,76.23],[1,1.03,8.41],[2,1.02,25.22]],"ltp":0.0,"tv":0.0,"id":23010367},{"batb":[[0,1.09,76.23],[1,1.03,8.41],[2,1.02,25.22]],"ltp":0.0,"tv":0.0,"id":27652444}]}]}
{"op":"mcm","clk":"983985613","pt":1580466626820,"mc":[{"id":"1.168119364","rc":[{"batb":[[2,1.02,25.42]],"ltp":0.0,"tv":0.0,"id":23010367},{"batb":[[2,1.02,25.42]],"ltp":0.0,"tv":0.0,"id":27652444}]}]}
{"op":"mcm","clk":"984678183","pt":1580472152088,"mc":[{"id":"1.168119364","rc":[{"batb":[[0,1.09,76.18],[1,1.03,8.41],[2,1.02,25.43]],"ltp":0.0,"tv":0.0,"id":23010367},{"batb":[[0,1.09,76.18],[1,1.03,8.41],[2,1.02,25.43]],"ltp":0.0,"tv":0.0,"id":27652444}]}]}
{"op":"mcm","clk":"985397256","pt":1580476970468,"mc":[{"id":"1.168119364","rc":[{"batb":[[0,1.09,76.38]],"ltp":0.0,"tv":0.0,"id":23010367},{"batb":[[0,1.09,76.38]],"ltp":0.0,"tv":0.0,"id":27652444}]}]}
{"op":"mcm","clk":"985397516","pt":1580476972670,"mc":[{"id":"1.168119364","rc":[{"batl":[[1,1000,2]],"ltp":0.0,"tv":0.0,"id":23010367},{"batl":[[1,1000,2]],"ltp":0.0,"tv":0.0,"id":27652444}]}]}
{"op":"mcm","clk":"985397566","pt":1580476973036,"mc":[{"id":"1.168119364","rc":[{"batb":[[0,1.09,76.48],[1,1.03,8.91]],"batl":[[1,1000,0.02]],"ltp":0.0,"tv":0.0,"id":23010367},{"batb":[[0,1.09,76.48],[1,1.03,8.91]],"batl":[[1,1000,0.02]],"ltp":0.0,"tv":0.0,"id":27652444}]}]}
{"op":"mcm","clk":"985716664","pt":1580479352085,"mc":[{"id":"1.168119364","rc":[{"batb":[[0,1.09,76.38],[1,1.03,8.91],[2,1.02,25.43]],"ltp":0.0,"tv":0.0,"id":23010367},{"batb":[[0,1.09,76.38],[1,1.03,8.91],[2,1.02,25.43]],"ltp":0.0,"tv":0.0,"id":27652444}]}]}
{"op":"mcm","clk":"986476131","pt":1580486552114,"mc":[{"id":"1.168119364","rc":[{"batb":[[0,1.09,76.17],[1,1.03,8.91],[2,1.02,25.43]],"ltp":0.0,"tv":0.0,"id":23010367},{"batb":[[0,1.09,76.17],[1,1.03,8.91],[2,1.02,25.43]],"ltp":0.0,"tv":0.0,"id":27652444}]}]}
{"op":"mcm","clk":"987059477","pt":1580493752075,"mc":[{"id":"1.168119364","rc":[{"batb":[[0,1.09,76.08],[1,1.03,8.9],[2,1.02,25.4]],"ltp":0.0,"tv":0.0,"id":23010367},{"batb":[[0,1.09,76.08],[1,1.03,8.9],[2,1.02,25.4]],"ltp":0.0,"tv":0.0,"id":27652444}]}]}
{"op":"mcm","clk":"987928423","pt":1580500952091,"mc":[{"id":"1.168119364","rc":[{"batb":[[0,1.09,76.03],[2,1.02,25.4]],"ltp":0.0,"tv":0.0,"id":23010367},{"batb":[[0,1.09,76.03],[2,1.02,25.4]],"ltp":0.0,"tv":0.0,"id":27652444}]}]}
{"op":"mcm","clk":"988043293","pt":1580501695475,"mc":[{"id":"1.168119364","rc":[{"batb":[[0,1.09,76.04]],"ltp":0.0,"tv":0.0,"id":23010367},{"batb":[[0,1.09,76.04]],"ltp":0.0,"tv":0.0,"id":27652444}]}]}
{"op":"mcm","clk":"988131047","pt":1580502205997,"mc":[{"id":"1.168119364","rc":[{"batb":[[0,1.1,2.31],[1,1.09,75.73],[2,1.03,8.9]],"ltp":0.0,"tv":0.0,"id":23010367}]}]}
{"op":"mcm","clk":"988251293","pt":1580503021507,"mc":[{"id":"1.168119364","rc":[{"batb":[[0,2,44.37],[1,1.1,2.31],[2,1.09,75.73]],"ltp":0.0,"tv":0.0,"id":23010367},{"batb":[[0,1.73,60.78],[1,1.09,76.04],[2,1.03,8.9]],"ltp":0.0,"tv":0.0,"id":27652444}]}]}
{"op":"mcm","clk":"988679010","pt":1580508003810,"mc":[{"id":"1.168119364","rc":[{"batb":[[0,2,59.16]],"ltp":0.0,"tv":0.0,"id":23010367},{"batb":[[0,1.73,81.04]],"ltp":0.0,"tv":0.0,"id":27652444}]}]}
{"op":"mcm","clk":"988679483","pt":1580508013936,"mc":[{"id":"1.168119364","rc":[{"batb":[[0,1.95,62.27],[2,1.09,75.72]],"ltp":0.0,"tv":0.0,"id":23010367},{"batb":[[1,1.09,76.03],[2,1.03,8.9]],"ltp":0.0,"tv":0.0,"id":27652444}]}]}
{"op":"mcm","clk":"988861809","pt":1580510850117,"mc":[{"id":"1.168119364","rc":[{"batb":[[0,2,59.16]],"ltp":0.0,"tv":0.0,"id":23010367},{"batb":[[0,1.7,84.51]],"ltp":0.0,"tv":0.0,"id":27652444}]}]}
{"op":"mcm","clk":"988911598","pt":1580511603694,"mc":[{"id":"1.168119364","rc":[{"batb":[[0,2,84.37]],"ltp":0.0,"tv":0.0,"id":23010367},{"batb":[[0,1.7,120.52]],"ltp":0.0,"tv":0.0,"id":27652444}]}]}
{"op":"mcm","clk":"988912809","pt":1580511624163,"mc":[{"id":"1.168119364","rc":[{"batb":[[0,2.02,2],[1,2,86.37],[2,1.1,2.31]],"ltp":0.0,"tv":0.0,"id":23010367},{"batb":[[0,1.71,2],[1,1.7,122.52],[2,1.09,76.03]],"ltp":0.0,"tv":0.0,"id":27652444}]}]}
{"op":"mcm","clk":"988954921","pt":1580512223654,"mc":[{"id":"1.168119364","rc":[{"batb":[[0,2,84.37],[1,1.1,2.31],[2,1.09,75.72]],"ltp":0.0,"tv":0.0,"id":23010367},{"batb":[[1,1.7,120.52]],"ltp":0.0,"tv":0.0,"id":27652444}]}]}
{"op":"mcm","clk":"988954983","pt":1580512224680,"mc":[{"id":"1.168119364","rc":[{"batb":[[0,1.7,120.52],[1,1.09,76.03],[2,1.03,8.9]],"ltp":0.0,"tv":0.0,"id":27652444}]}]}
{"op":"mcm","clk":"988955475","pt":1580512233679,"mc":[{"id":"1.168119364","rc":[{"batb":[[0,2.02,2],[1,2,86.37],[2,1.1,2.31]],"ltp":0.0,"tv":0.0,"id":23010367},{"batb":[[0,1.71,2],[1,1.7,122.52],[2,1.09,76.03]],"ltp":0.0,"tv":0.0,"id":27652444}]}]}
{"op":"mcm","clk":"988963357","pt":1580512366669,"mc":[{"id":"1.168119364","rc":[{"batb":[[0,2.04,1.24],[1,2.02,2],[2,2,86.37]],"ltp":0.0,"tv":0.0,"id":23010367},{"batb":[[0,1.72,1.46],[1,1.71,2],[2,1.7,122.52]],"ltp":0.0,"tv":0.0,"id":27652444}]}]}
{"op":"mcm","clk":"989003114","pt":1580512834517,"mc":[{"id":"1.168119364","rc":[{"batb":[[1,2,84.37],[2,1.1,2.31]],"ltp":0.0,"tv":0.0,"id":23010367},{"batb":[[1,1.7,120.52],[2,1.09,76.03]],"ltp":0.0,"tv":0.0,"id":27652444}]}]}
{"op":"mcm","clk":"989003540","pt":1580512840722,"mc":[{"id":"1.168119364","rc":[{"batb":[[1,2.02,2],[2,2,86.37]],"ltp":0.0,"tv":0.0,"id":23010367},{"batb":[[1,1.71,2],[2,1.7,122.52]],"ltp":0.0,"tv":0.0,"id":27652444}]}]}
{"op":"mcm","clk":"989041504","pt":1580513402729,"mc":[{"id":"1.168119364","rc":[{"batb":[[2,2,88.37]],"ltp":0.0,"tv":0.0,"id":23010367}]}]}
{"op":"mcm","clk":"989041536","pt":1580513403298,"mc":[{"id":"1.168119364","rc":[{"batb":[[2,2,86.62]],"ltp":0.0,"tv":0.0,"id":23010367},{"batb":[[2,1.7,122.88]],"ltp":0.0,"tv":0.0,"id":27652444}]}]}
{"op":"mcm","clk":"989098092","pt":1580514211770,"mc":[{"id":"1.168119364","rc":[{"batl":[[0,2.16,5.07],[1,990,2.2],[2,1000,0.02]],"ltp":0.0,"tv":0.0,"id":27652444}]}]}
{"op":"mcm","clk":"989160572","pt":1580515183733,"mc":[{"id":"1.168119364","rc":[{"batl":[[2,1000,2.12]],"ltp":0.0,"tv":0.0,"id":27652444}]}]}
{"op":"mcm","clk":"989160598","pt":1580515184247,"mc":[{"id":"1.168119364","rc":[{"trd":[[1.72,0.2]],"batb":[[0,1.72,1.36]],"batl":[[2,1000,0.02]],"ltp":1.72,"tv":0.2,"id":27652444}],"tv":0.2}]}
{"op":"mcm","clk":"989192787","pt":1580515628586,"mc":[{"id":"1.168119364","marketDefinition":{"bspMarket":false,"turnInPlayEnabled":true,"persistenceEnabled":true,"marketBaseRate":5.0,"eventId":"29678414","eventTypeId":"2","numberOfWinners":1,"bettingType":"ODDS","marketType":"MATCH_ODDS","marketTime":"2020-02-02T00:00:00.000Z","suspendTime":"2020-02-02T00:00:00.000Z","bspReconciled":false,"complete":true,"inPlay":false,"crossMatching":true,"runnersVoidable":false,"numberOfActiveRunners":2,"betDelay":0,"status":"OPEN","runners":[{"status":"ACTIVE","sortPriority":1,"id":23010367,"name":"Margaroli/Vavassori"},{"status":"ACTIVE","sortPriority":2,"id":27652444,"name":"Heliovaara/Verbeek"}],"regulators":["MR_INT"],"countryCode":"AU","discountAllowed":true,"timezone":"UTC","openDate":"2020-02-01T00:00:00.000Z","version":3144185904,"name":"Match Odds","eventName":"Margaroli/Vavassori v Heliovaara/Verbeek"}}]}
{"op":"mcm","clk":"989193017","pt":1580515631592,"mc":[{"id":"1.168119364","marketDefinition":{"bspMarket":false,"turnInPlayEnabled":true,"persistenceEnabled":true,"marketBaseRate":5.0,"eventId":"29678414","eventTypeId":"2","numberOfWinners":1,"bettingType":"ODDS","marketType":"MATCH_ODDS","marketTime":"2020-02-02T00:00:00.000Z","suspendTime":"2020-02-02T00:00:00.000Z","bspReconciled":false,"complete":true,"inPlay":false,"crossMatching":true,"runnersVoidable":false,"numberOfActiveRunners":2,"betDelay":0,"status":"OPEN","runners":[{"status":"ACTIVE","sortPriority":1,"id":23010367,"name":"Margaroli/Vavassori"},{"status":"ACTIVE","sortPriority":2,"id":27652444,"name":"Heliovaara/Verbeek"}],"regulators":["MR_INT"],"countryCode":"AU","discountAllowed":true,"timezone":"UTC","openDate":"2020-02-02T00:00:00.000Z","version":3144185904,"name":"Match Odds","eventName":"Margaroli/Vavassori v Heliovaara/Verbeek"}}]}
{"op":"mcm","clk":"989200627","pt":1580515770651,"mc":[{"id":"1.168119364","rc":[{"batb":[[2,2,116.2]],"ltp":0.0,"tv":0.0,"id":23010367},{"batb":[[2,1.7,165.13]],"ltp":1.72,"tv":0.2,"id":27652444}]}]}
{"op":"mcm","clk":"989200631","pt":1580515770755,"mc":[{"id":"1.168119364","rc":[{"batb":[[2,2,57.04]],"ltp":0.0,"tv":0.0,"id":23010367},{"batb":[[2,1.7,80.62]],"ltp":1.72,"tv":0.2,"id":27652444}]}]}
{"op":"mcm","clk":"989212117","pt":1580515978569,"mc":[{"id":"1.168119364","rc":[{"batl":[[1,1000,0.52]],"ltp":0.0,"tv":0.0,"id":23010367},{"batl":[[2,1000,0.52]],"ltp":1.72,"tv":0.2,"id":27652444}]}]}
{"op":"mcm","clk":"989212604","pt":1580515987547,"mc":[{"id":"1.168119364","rc":[{"batl":[[1,1000,2.52]],"ltp":0.0,"tv":0.0,"id":23010367}]}]}
{"op":"mcm","clk":"989212647","pt":1580515988269,"mc":[{"id":"1.168119364","rc":[{"batl":[[0,990,2.5],[1,1000,0.52]],"ltp":0.0,"tv":0.0,"id":23010367}]}]}
{"op":"mcm","clk":"989212846","pt":1580515991356,"mc":[{"id":"1.168119364","rc":[{"batl":[[1,990,2.5]],"ltp":1.72,"tv":0.2,"id":27652444}]}]}
{"op":"mcm","clk":"989213043","pt":1580515994461,"mc":[{"id":"1.168119364","rc":[{"batl":[[0,990,2.7]],"ltp":0.0,"tv":0.0,"id":23010367}]}]}
{"op":"mcm","clk":"989213097","pt":1580515995284,"mc":[{"id":"1.168119364","rc":[{"batb":[[2,2,31.83]],"ltp":0.0,"tv":0.0,"id":23010367},{"batb":[[2,1.7,44.61]],"ltp":1.72,"tv":0.2,"id":27652444}]}]}
{"op":"mcm","clk":"989213239","pt":1580515997664,"mc":[{"id":"1.168119364","rc":[{"batl":[[2,1000,0.72]],"ltp":1.72,"tv":0.2,"id":27652444}]}]}
{"op":"mcm","clk":"989213258","pt":1580515997970,"mc":[{"id":"1.168119364","rc":[{"batl":[[1,990,2.7],[2,1000,0.52]],"ltp":1.72,"tv":0.2,"id":27652444}]}]}
{"op":"mcm","clk":"989321251","pt":1580517361330,"mc":[{"id":"1.168119364","rc":[{"batl":[[0,990,2.7],[1,1000,0.52],[2,1000,0]],"ltp":1.72,"tv":0.2,"id":27652444}]}]}
{"op":"mcm","clk":"989754320","pt":1580523204656,"mc":[{"id":"1.168119364","rc":[{"batb":[[2,2,29.83]],"ltp":0.0,"tv":0.0,"id":23010367},{"batb":[[1,1.7,42.61],[2,1.6,1.5]],"ltp":1.72,"tv":0.2,"id":27652444}]}]}
{"op":"mcm","clk":"989754332","pt":1580523204858,"mc":[{"id":"1.168119364","rc":[{"batb":[[1,2,29.83],[2,1.6,1.5]],"ltp":0.0,"tv":0.0,"id":23010367}]}]}
{"op":"mcm","clk":"990242602","pt":1580531644502,"mc":[{"id":"1.168119364","rc":[{"batb":[[1,2,27.63]],"ltp":0.0,"tv":0.0,"id":23010367},{"batb":[[1,1.7,39.47]],"ltp":1.72,"tv":0.2,"id":27652444}]}]}
{"op":"mcm","clk":"990243494","pt":1580531667568,"mc":[{"id":"1.168119364","rc":[{"batb":[[2,1.1,2.31]],"batl":[[0,990,2.2],[1,1000,0.02]],"ltp":0.0,"tv":0.0,"id":23010367},{"batb":[[2,1.09,76.03]],"batl":[[0,990,2.2],[1,1000,0.02]],"ltp":1.72,"tv":0.2,"id":27652444}]}]}
{"op":"mcm","clk":"990475893","pt":1580535437411,"mc":[{"id":"1.168119364","rc":[{"batb":[[2,1.5,4]],"ltp":1.72,"tv":0.2,"id":27652444}]}]}
{"op":"mcm","clk":"990476141","pt":1580535441095,"mc":[{"id":"1.168119364","rc":[{"batb":[[2,1.5,4]],"ltp":0.0,"tv":0.0,"id":23010367}]}]}
{"op":"mcm","clk":"990490041","pt":1580535671999,"mc":[{"id":"1.168119364","rc":[{"batl":[[0,2.5,3.03],[1,990,2.2],[2,1000,0.02]],"ltp":1.72,"tv":0.2,"id":27652444}]}]}
{"op":"mcm","clk":"991442859","pt":1580550459095,"mc":[{"id":"1.168119364","rc":[{"batl":[[0,95,15.9],[1,990,2.2],[2,1000,0.02]],"ltp":0.0,"tv":0.0,"id":23010367},{"batl":[[1,95,15.9],[2,990,2.2]],"ltp":1.72,"tv":0.2,"id":27652444}]}]}
{"op":"mcm","clk":"992373406","pt":1580556954099,"mc":[{"id":"1.168119364","rc":[{"trd":[[2.04,0.08]],"batb":[[0,2.04,1.16]],"ltp":2.04,"tv":0.07,"id":23010367},{"trd":[[1.97,0.08]],"ltp":1.97,"tv":0.28,"id":27652444}],"tv":0.35}]}
{"op":"mcm","clk":"992713010","pt":1580558828510,"mc":[{"id":"1.168119364","rc":[{"batb":[[2,1.77,15.14]],"ltp":2.04,"tv":0.07,"id":23010367},{"batb":[[2,1.57,16.66]],"ltp":1.97,"tv":0.28,"id":27652444}]}]}
{"op":"mcm","clk":"995971372","pt":1580572816471,"mc":[{"id":"1.168119364","rc":[{"batb":[[0,1.73,37.5],[1,1.72,1.36],[2,1.57,17.02]],"ltp":1.97,"tv":0.28,"id":27652444}]}]}
{"op":"mcm","clk":"995973818","pt":1580572831582,"mc":[{"id":"1.168119364","rc":[{"batb":[[1,1.57,17.02],[2,1.5,4]],"ltp":1.97,"tv":0.28,"id":27652444}]}]}
{"op":"mcm","clk":"995973924","pt":1580572831919,"mc":[{"id":"1.168119364","rc":[{"batb":[[0,1.74,1.45],[1,1.73,37.5],[2,1.57,17.02]],"ltp":1.97,"tv":0.28,"id":27652444}]}]}
{"op":"mcm","clk":"997280787","pt":1580580000399,"mc":[{"id":"1.168119364","rc":[{"batb":[[1,2,41.32]],"ltp":2.04,"tv":0.07,"id":23010367},{"batb":[[1,1.73,56.26]],"ltp":1.97,"tv":0.28,"id":27652444}]}]}
{"op":"mcm","clk":"998000735","pt":1580584376804,"mc":[{"id":"1.168119364","rc":[{"batl":[[0,95,15.9],[1,990,2.2],[2,1000,0.02]],"ltp":1.97,"tv":0.28,"id":27652444}]}]}
{"op":"mcm","clk":"998453684","pt":1580587204716,"mc":[{"id":"1.168119364","rc":[{"batb":[[2,1.56,17.02]],"ltp":1.97,"tv":0.28,"id":27652444}]}]}
{"op":"mcm","clk":"998661966","pt":1580588565703,"mc":[{"id":"1.168119364","rc":[{"batb":[[2,1.55,17.02]],"ltp":1.97,"tv":0.28,"id":27652444}]}]}
{"op":"mcm","clk":"998712452","pt":1580588949085,"mc":[{"id":"1.168119364","rc":[{"batb":[[1,2.02,30.29],[2,2,41.32]],"ltp":2.04,"tv":0.07,"id":23010367}]}]}
{"op":"mcm","clk":"999052708","pt":1580591699249,"mc":[{"id":"1.168119364","rc":[{"batl":[[0,2.36,3.79],[1,95,15.9],[2,990,2.2]],"ltp":2.04,"tv":0.07,"id":23010367},{"batl":[[0,1.98,7.57],[1,95,15.9],[2,990,2.2]],"ltp":1.97,"tv":0.28,"id":27652444}]}]}
{"op":"mcm","clk":"999054760","pt":1580591715623,"mc":[{"id":"1.168119364","rc":[{"batl":[[0,2.76,3.79]],"ltp":2.04,"tv":0.07,"id":23010367}]}]}
{"op":"mcm","clk":"999063102","pt":1580591782195,"mc":[{"id":"1.168119364","rc":[{"batb":[[2,1.58,17.02]],"ltp":1.97,"tv":0.28,"id":27652444}]}]}
{"op":"mcm","clk":"999072138","pt":1580591860245,"mc":[{"id":"1.168119364","rc":[{"batb":[[2,1.58,23.08]],"ltp":1.97,"tv":0.28,"id":27652444}]}]}
{"op":"mcm","clk":"999113947","pt":1580592189467,"mc":[{"id":"1.168119364","rc":[{"trd":[[1.73,17.1],[1.74,2.9]],"batb":[[0,1.73,47.71],[1,1.58,23.08],[2,1.5,4]],"ltp":1.73,"tv":20.27,"id":27652444}],"tv":20.35}]}
{"op":"mcm","clk":"999114411","pt":1580592193179,"mc":[{"id":"1.168119364","rc":[{"batb":[[0,1.73,56.26]],"ltp":1.73,"tv":20.27,"id":27652444}]}]}
{"op":"mcm","clk":"999188916","pt":1580592806063,"mc":[{"id":"1.168119364","rc":[{"batb":[[0,1.74,1.45],[1,1.73,56.26],[2,1.58,23.08]],"ltp":1.73,"tv":20.27,"id":27652444}]}]}
{"op":"mcm","clk":"999360596","pt":1580594403001,"mc":[{"id":"1.168119364","rc":[{"batb":[[2,2,55.01]],"ltp":2.04,"tv":0.07,"id":23010367},{"batb":[[1,1.73,75.01]],"ltp":1.73,"tv":20.27,"id":27652444}]}]}
{"op":"mcm","clk":"999361112","pt":1580594408061,"mc":[{"id":"1.168119364","rc":[{"batb":[[1,1.7,78.59],[2,1.58,22.72]],"ltp":1.73,"tv":20.27,"id":27652444}]}]}
{"op":"mcm","clk":"999362891","pt":1580594427568,"mc":[{"id":"1.168119364","rc":[{"batb":[[1,1.71,30.29],[2,1.7,78.59]],"ltp":1.73,"tv":20.27,"id":27652444}]}]}
{"op":"mcm","clk":"999518684","pt":1580596397847,"mc":[{"id":"1.168119364","rc":[{"batb":[[1,2,55.01],[2,1.8,19.69]],"ltp":2.04,"tv":0.07,"id":23010367}]}]}
{"op":"mcm","clk":"999519294","pt":1580596406756,"mc":[{"id":"1.168119364","rc":[{"batb":[[1,1.7,78.59],[2,1.58,22.72]],"ltp":1.73,"tv":20.27,"id":27652444}]}]}
{"op":"mcm","clk":"999531863","pt":1580596579580,"mc":[{"id":"1.168119364","rc":[{"batb":[[1,2.02,30.29],[2,2,55.01]],"ltp":2.04,"tv":0.07,"id":23010367}]}]}
{"op":"mcm","clk":"999531931","pt":1580596580614,"mc":[{"id":"1.168119364","rc":[{"batb":[[1,1.71,30.29],[2,1.7,78.59]],"ltp":1.73,"tv":20.27,"id":27652444}]}]}
{"op":"mcm","clk":"999624687","pt":1580598004954,"mc":[{"id":"1.168119364","rc":[{"batb":[[1,2.02,55]],"ltp":2.04,"tv":0.07,"id":23010367},{"batb":[[1,1.71,65.79]],"ltp":1.73,"tv":20.27,"id":27652444}]}]}
{"op":"mcm","clk":"999625013","pt":1580598010953,"mc":[{"id":"1.168119364","rc":[{"batb":[[1,1.71,30.29],[2,1.7,114.6]],"ltp":1.73,"tv":20.27,"id":27652444}]}]}
{"op":"mcm","clk":"999625062","pt":1580598011933,"mc":[{"id":"1.168119364","rc":[{"batb":[[1,1.71,65.79]],"ltp":1.73,"tv":20.27,"id":27652444}]}]}
{"op":"mcm","clk":"999625130","pt":1580598013073,"mc":[{"id":"1.168119364","rc":[{"batb":[[1,1.71,30.29]],"ltp":1.73,"tv":20.27,"id":27652444}]}]}
{"op":"mcm","clk":"999625196","pt":1580598014535,"mc":[{"id":"1.168119364","rc":[{"batb":[[1,1.71,65.79]],"ltp":1.73,"tv":20.27,"id":27652444}]}]}
{"op":"mcm","clk":"999625273","pt":1580598015621,"mc":[{"id":"1.168119364","rc":[{"batb":[[1,1.71,30.29]],"ltp":1.73,"tv":20.27,"id":27652444}]}]}
{"op":"mcm","clk":"999625631","pt":1580598019979,"mc":[{"id":"1.168119364","rc":[{"batb":[[1,1.71,65.79]],"ltp":1.73,"tv":20.27,"id":27652444}]}]}
{"op":"mcm","clk":"999625707","pt":1580598021063,"mc":[{"id":"1.168119364","rc":[{"batb":[[1,1.71,30.29]],"ltp":1.73,"tv":20.27,"id":27652444}]}]}
{"op":"mcm","clk":"999625760","pt":1580598021966,"mc":[{"id":"1.168119364","rc":[{"batb":[[1,1.71,65.79]],"ltp":1.73,"tv":20.27,"id":27652444}]}]}
{"op":"mcm","clk":"999625835","pt":1580598022945,"mc":[{"id":"1.168119364","rc":[{"batb":[[1,1.71,30.29]],"ltp":1.73,"tv":20.27,"id":27652444}]}]}
{"op":"mcm","clk":"999625883","pt":1580598023976,"mc":[{"id":"1.168119364","rc":[{"batb":[[1,1.71,65.79]],"ltp":1.73,"tv":20.27,"id":27652444}]}]}
{"op":"mcm","clk":"999625933","pt":1580598024956,"mc":[{"id":"1.168119364","rc":[{"batb":[[1,1.71,30.29]],"ltp":1.73,"tv":20.27,"id":27652444}]}]}
{"op":"mcm","clk":"999625986","pt":1580598025945,"mc":[{"id":"1.168119364","rc":[{"batb":[[1,1.71,65.79]],"ltp":1.73,"tv":20.27,"id":27652444}]}]}
{"op":"mcm","clk":"999626038","pt":1580598027080,"mc":[{"id":"1.168119364","rc":[{"batb":[[1,1.71,30.29]],"ltp":1.73,"tv":20.27,"id":27652444}]}]}
{"op":"mcm","clk":"999626084","pt":1580598027958,"mc":[{"id":"1.168119364","rc":[{"batb":[[1,1.71,65.79]],"ltp":1.73,"tv":20.27,"id":27652444}]}]}
{"op":"mcm","clk":"999626142","pt":1580598028991,"mc":[{"id":"1.168119364","rc":[{"batb":[[1,1.71,30.29]],"ltp":1.73,"tv":20.27,"id":27652444}]}]}
{"op":"mcm","clk":"999626208","pt":1580598029969,"mc":[{"id":"1.168119364","rc":[{"batb":[[1,1.71,65.79]],"ltp":1.73,"tv":20.27,"id":27652444}]}]}
{"op":"mcm","clk":"999626263","pt":1580598030952,"mc":[{"id":"1.168119364","rc":[{"batb":[[1,1.71,30.29]],"ltp":1.73,"tv":20.27,"id":27652444}]}]}
{"op":"mcm","clk":"999626321","pt":1580598031984,"mc":[{"id":"1.168119364","rc":[{"batb":[[1,1.71,65.79]],"ltp":1.73,"tv":20.27,"id":27652444}]}]}
{"op":"mcm","clk":"999626390","pt":1580598033072,"mc":[{"id":"1.168119364","rc":[{"batb":[[1,1.71,30.29]],"ltp":1.73,"tv":20.27,"id":27652444}]}]}
{"op":"mcm","clk":"999626443","pt":1580598034000,"mc":[{"id":"1.168119364","rc":[{"batb":[[1,1.71,65.79]],"ltp":1.73,"tv":20.27,"id":27652444}]}]}
{"op":"mcm","clk":"999626519","pt":1580598034982,"mc":[{"id":"1.168119364","rc":[{"batb":[[1,1.71,30.29]],"ltp":1.73,"tv":20.27,"id":27652444}]}]}
{"op":"mcm","clk":"999626598","pt":1580598035963,"mc":[{"id":"1.168119364","rc":[{"batb":[[1,1.71,65.79]],"ltp":1.73,"tv":20.27,"id":27652444}]}]}
{"op":"mcm","clk":"999626653","pt":1580598036982,"mc":[{"id":"1.168119364","rc":[{"batb":[[1,1.71,30.29]],"ltp":1.73,"tv":20.27,"id":27652444}]}]}
{"op":"mcm","clk":"999626715","pt":1580598037969,"mc":[{"id":"1.168119364","rc":[{"batb":[[1,1.71,65.79]],"ltp":1.73,"tv":20.27,"id":27652444}]}]}
{"op":"mcm","clk":"999626817","pt":1580598039673,"mc":[{"id":"1.168119364","rc":[{"batb":[[1,2.02,24.71]],"ltp":2.04,"tv":0.07,"id":23010367},{"batb":[[1,1.71,30.29]],"ltp":1.73,"tv":20.27,"id":27652444}]}]}
{"op":"mcm","clk":"999626848","pt":1580598040089,"mc":[{"id":"1.168119364","rc":[{"batb":[[0,2.04,31.45],[1,2,80.22],[2,1.5,4]],"ltp":2.04,"tv":0.07,"id":23010367},{"batb":[[1,1.71,65.79]],"ltp":1.73,"tv":20.27,"id":27652444}]}]}
{"op":"mcm","clk":"999626906","pt":1580598040865,"mc":[{"id":"1.168119364","rc":[{"batb":[[0,2.04,55.69]],"ltp":2.04,"tv":0.07,"id":23010367},{"batb":[[1,1.71,30.29]],"ltp":1.73,"tv":20.27,"id":27652444}]}]}
{"op":"mcm","clk":"999626968","pt":1580598042010,"mc":[{"id":"1.168119364","rc":[{"batb":[[1,1.71,65.79]],"ltp":1.73,"tv":20.27,"id":27652444}]}]}
{"op":"mcm","clk":"999627017","pt":1580598042991,"mc":[{"id":"1.168119364","rc":[{"batb":[[1,1.71,30.29]],"ltp":1.73,"tv":20.27,"id":27652444}]}]}
{"op":"mcm","clk":"999627068","pt":1580598043924,"mc":[{"id":"1.168119364","rc":[{"batb":[[1,1.71,65.79]],"ltp":1.73,"tv":20.27,"id":27652444}]}]}
{"op":"mcm","clk":"999627110","pt":1580598045011,"mc":[{"id":"1.168119364","rc":[{"batb":[[1,1.71,30.29]],"ltp":1.73,"tv":20.27,"id":27652444}]}]}
{"op":"mcm","clk":"999627145","pt":1580598045893,"mc":[{"id":"1.168119364","rc":[{"batb":[[1,1.71,65.79]],"ltp":1.73,"tv":20.27,"id":27652444}]}]}
{"op":"mcm","clk":"999627206","pt":1580598047083,"mc":[{"id":"1.168119364","rc":[{"batb":[[1,1.71,30.29]],"ltp":1.73,"tv":20.27,"id":27652444}]}]}
{"op":"mcm","clk":"999627243","pt":1580598047913,"mc":[{"id":"1.168119364","rc":[{"batb":[[1,1.71,65.79]],"ltp":1.73,"tv":20.27,"id":27652444}]}]}
{"op":"mcm","clk":"999627294","pt":1580598048997,"mc":[{"id":"1.168119364","rc":[{"batb":[[1,1.71,30.29]],"ltp":1.73,"tv":20.27,"id":27652444}]}]}
{"op":"mcm","clk":"999627341","pt":1580598049880,"mc":[{"id":"1.168119364","rc":[{"batb":[[1,1.71,65.79]],"ltp":1.73,"tv":20.27,"id":27652444}]}]}
{"op":"mcm","clk":"999627386","pt":1580598050914,"mc":[{"id":"1.168119364","rc":[{"batb":[[1,1.71,30.29]],"ltp":1.73,"tv":20.27,"id":27652444}]}]}
{"op":"mcm","clk":"999627468","pt":1580598051897,"mc":[{"id":"1.168119364","rc":[{"batb":[[1,1.71,65.79]],"ltp":1.73,"tv":20.27,"id":27652444}]}]}
{"op":"mcm","clk":"999627539","pt":1580598052980,"mc":[{"id":"1.168119364","rc":[{"batb":[[1,1.71,30.29]],"ltp":1.73,"tv":20.27,"id":27652444}]}]}
{"op":"mcm","clk":"999627619","pt":1580598053910,"mc":[{"id":"1.168119364","rc":[{"batb":[[1,1.71,65.79]],"ltp":1.73,"tv":20.27,"id":27652444}]}]}
{"op":"mcm","clk":"999627698","pt":1580598055003,"mc":[{"id":"1.168119364","rc":[{"batb":[[1,1.71,30.29]],"ltp":1.73,"tv":20.27,"id":27652444}]}]}
{"op":"mcm","clk":"999627750","pt":1580598055894,"mc":[{"id":"1.168119364","rc":[{"batb":[[1,1.71,65.79]],"ltp":1.73,"tv":20.27,"id":27652444}]}]}
{"op":"mcm","clk":"999627823","pt":1580598056979,"mc":[{"id":"1.168119364","rc":[{"batb":[[1,1.71,30.29]],"ltp":1.73,"tv":20.27,"id":27652444}]}]}
{"op":"mcm","clk":"999627883","pt":1580598057877,"mc":[{"id":"1.168119364","rc":[{"batb":[[1,1.71,65.79]],"ltp":1.73,"tv":20.27,"id":27652444}]}]}
{"op":"mcm","clk":"999627946","pt":1580598059011,"mc":[{"id":"1.168119364","rc":[{"batb":[[1,1.71,30.29]],"ltp":1.73,"tv":20.27,"id":27652444}]}]}
{"op":"mcm","clk":"999628006","pt":1580598059890,"mc":[{"id":"1.168119364","rc":[{"batb":[[1,1.71,65.79]],"ltp":1.73,"tv":20.27,"id":27652444}]}]}
{"op":"mcm","clk":"999628073","pt":1580598061024,"mc":[{"id":"1.168119364","rc":[{"batb":[[1,1.71,30.29]],"ltp":1.73,"tv":20.27,"id":27652444}]}]}
{"op":"mcm","clk":"999628125","pt":1580598061907,"mc":[{"id":"1.168119364","rc":[{"batb":[[1,1.71,65.79]],"ltp":1.73,"tv":20.27,"id":27652444}]}]}
{"op":"mcm","clk":"999628178","pt":1580598063006,"mc":[{"id":"1.168119364","rc":[{"batb":[[1,1.71,30.29]],"ltp":1.73,"tv":20.27,"id":27652444}]}]}
{"op":"mcm","clk":"999628227","pt":1580598063898,"mc":[{"id":"1.168119364","rc":[{"batb":[[1,1.71,65.79]],"ltp":1.73,"tv":20.27,"id":27652444}]}]}
{"op":"mcm","clk":"999628284","pt":1580598064997,"mc":[{"id":"1.168119364","rc":[{"batb":[[1,1.71,30.29]],"ltp":1.73,"tv":20.27,"id":27652444}]}]}
{"op":"mcm","clk":"999628348","pt":1580598065926,"mc":[{"id":"1.168119364","rc":[{"batb":[[1,1.71,65.79]],"ltp":1.73,"tv":20.27,"id":27652444}]}]}
{"op":"mcm","clk":"999628420","pt":1580598067018,"mc":[{"id":"1.168119364","rc":[{"batb":[[1,1.71,30.29]],"ltp":1.73,"tv":20.27,"id":27652444}]}]}
{"op":"mcm","clk":"999628490","pt":1580598067907,"mc":[{"id":"1.168119364","rc":[{"batb":[[1,1.71,65.79]],"ltp":1.73,"tv":20.27,"id":27652444}]}]}
{"op":"mcm","clk":"999634507","pt":1580598161509,"mc":[{"id":"1.168119364","rc":[{"batb":[[0,2.04,25.4]],"ltp":2.04,"tv":0.07,"id":23010367}]}]}
{"op":"mcm","clk":"999634549","pt":1580598162123,"mc":[{"id":"1.168119364","rc":[{"batb":[[0,2.04,1.16]],"ltp":2.04,"tv":0.07,"id":23010367},{"batb":[[1,1.71,35.5]],"ltp":1.73,"tv":20.27,"id":27652444}]}]}
{"op":"mcm","clk":"999634622","pt":1580598163105,"mc":[{"id":"1.168119364","rc":[{"batb":[[1,1.7,114.6],[2,1.5,4]],"ltp":1.73,"tv":20.27,"id":27652444}]}]}
{"op":"mcm","clk":"999643912","pt":1580598283581,"mc":[{"id":"1.168119364","rc":[{"batb":[[1,2.02,30.29],[2,2,80.22]],"ltp":2.04,"tv":0.07,"id":23010367},{"batb":[[1,1.71,30.29],[2,1.7,114.6]],"ltp":1.73,"tv":20.27,"id":27652444}]}]}
{"op":"mcm","clk":"999643946","pt":1580598284050,"mc":[{"id":"1.168119364","rc":[{"batb":[[1,2.02,55]],"ltp":2.04,"tv":0.07,"id":23010367},{"batb":[[1,1.71,65.79]],"ltp":1.73,"tv":20.27,"id":27652444}]}]}
{"op":"mcm","clk":"999652783","pt":1580598404723,"mc":[{"id":"1.168119364","rc":[{"batb":[[1,2.02,24.71]],"ltp":2.04,"tv":0.07,"id":23010367}]}]}
{"op":"mcm","clk":"999652839","pt":1580598405345,"mc":[{"id":"1.168119364","rc":[{"batb":[[0,2.04,55.69]],"ltp":2.04,"tv":0.07,"id":23010367},{"batb":[[1,1.71,35.5]],"ltp":1.73,"tv":20.27,"id":27652444}]}]}
{"op":"mcm","clk":"999652896","pt":1580598406122,"mc":[{"id":"1.168119364","rc":[{"batb":[[1,1.7,114.6],[2,1.5,4]],"ltp":1.73,"tv":20.27,"id":27652444}]}]}
{"op":"mcm","clk":"999662535","pt":1580598526472,"mc":[{"id":"1.168119364","rc":[{"batb":[[0,2.04,25.4]],"ltp":2.04,"tv":0.07,"id":23010367}]}]}
{"op":"mcm","clk":"999662593","pt":1580598527190,"mc":[{"id":"1.168119364","rc":[{"batb":[[0,2.04,1.16],[1,2,80.22],[2,1.5,4]],"ltp":2.04,"tv":0.07,"id":23010367},{"batb":[[1,1.71,30.29],[2,1.7,114.6]],"ltp":1.73,"tv":20.27,"id":27652444}]}]}
{"op":"mcm","clk":"999662665","pt":1580598528075,"mc":[{"id":"1.168119364","rc":[{"batb":[[1,1.71,65.79]],"ltp":1.73,"tv":20.27,"id":27652444}]}]}
{"op":"mcm","clk":"999671378","pt":1580598639595,"mc":[{"id":"1.168119364","rc":[{"batb":[[0,2.04,3.16]],"ltp":2.04,"tv":0.07,"id":23010367},{"batb":[[1,1.72,2],[2,1.71,65.79]],"ltp":1.73,"tv":20.27,"id":27652444}]}]}
{"op":"mcm","clk":"999672221","pt":1580598648631,"mc":[{"id":"1.168119364","rc":[{"batb":[[1,2.02,30.29],[2,2,80.22]],"ltp":2.04,"tv":0.07,"id":23010367},{"batb":[[2,1.71,35.5]],"ltp":1.73,"tv":20.27,"id":27652444}]}]}
{"op":"mcm","clk":"999672282","pt":1580598649203,"mc":[{"id":"1.168119364","rc":[{"batb":[[1,2.02,55]],"ltp":2.04,"tv":0.07,"id":23010367},{"batb":[[2,1.7,114.6]],"ltp":1.73,"tv":20.27,"id":27652444}]}]}
{"op":"mcm","clk":"999672494","pt":1580598651321,"mc":[{"id":"1.168119364","rc":[{"batb":[[0,2.06,2.02],[1,2.04,3.16],[2,2.02,55]],"ltp":2.04,"tv":0.07,"id":23010367},{"batb":[[1,1.73,2.02],[2,1.72,2]],"ltp":1.73,"tv":20.27,"id":27652444}]}]}
{"op":"mcm","clk":"999672852","pt":1580598655714,"mc":[{"id":"1.168119364","rc":[{"batb":[[0,2.08,1.22],[1,2.06,2.02],[2,2.04,2]],"ltp":2.04,"tv":0.07,"id":23010367}]}]}
{"op":"mcm","clk":"999682494","pt":1580598770309,"mc":[{"id":"1.168119364","rc":[{"batb":[[2,2.04,32.29]],"ltp":2.04,"tv":0.07,"id":23010367}]}]}
{"op":"mcm","clk":"999682568","pt":1580598771207,"mc":[{"id":"1.168119364","rc":[{"batb":[[2,2.04,56.53]],"ltp":2.04,"tv":0.07,"id":23010367}]}]}
{"op":"mcm","clk":"999691652","pt":1580598891467,"mc":[{"id":"1.168119364","rc":[{"batb":[[2,2.04,26.24]],"ltp":2.04,"tv":0.07,"id":23010367}]}]}
{"op":"mcm","clk":"999691719","pt":1580598892259,"mc":[{"id":"1.168119364","rc":[{"batb":[[2,2.04,2]],"ltp":2.04,"tv":0.07,"id":23010367}]}]}
{"op":"mcm","clk":"999710317","pt":1580599135501,"mc":[{"id":"1.168119364","rc":[{"batb":[[2,2.04,56.53]],"ltp":2.04,"tv":0.07,"id":23010367}]}]}
{"op":"mcm","clk":"999718722","pt":1580599240592,"mc":[{"id":"1.168119364","rc":[{"batb":[[2,1.7,114.6]],"ltp":1.73,"tv":20.27,"id":27652444}]}]}
{"op":"mcm","clk":"999718739","pt":1580599240800,"mc":[{"id":"1.168119364","rc":[{"batb":[[2,2.04,54.53]],"ltp":2.04,"tv":0.07,"id":23010367}]}]}
{"op":"mcm","clk":"999720002","pt":1580599256604,"mc":[{"id":"1.168119364","rc":[{"batb":[[2,2.04,24.24]],"ltp":2.04,"tv":0.07,"id":23010367}]}]}
{"op":"mcm","clk":"999720067","pt":1580599257287,"mc":[{"id":"1.168119364","rc":[{"batb":[[2,2,80.22]],"ltp":2.04,"tv":0.07,"id":23010367},{"batb":[[2,1.71,30.29]],"ltp":1.73,"tv":20.27,"id":27652444}]}]}
{"op":"mcm","clk":"999720160","pt":1580599258331,"mc":[{"id":"1.168119364","rc":[{"batb":[[2,1.71,65.79]],"ltp":1.73,"tv":20.27,"id":27652444}]}]}
{"op":"mcm","clk":"999728972","pt":1580599378732,"mc":[{"id":"1.168119364","rc":[{"batb":[[2,2.02,55]],"ltp":2.04,"tv":0.07,"id":23010367},{"batb":[[2,1.71,35.5]],"ltp":1.73,"tv":20.27,"id":27652444}]}]}
{"op":"mcm","clk":"999729023","pt":1580599379420,"mc":[{"id":"1.168119364","rc":[{"batb":[[2,1.7,114.6]],"ltp":1.73,"tv":20.27,"id":27652444}]}]}
{"op":"mcm","clk":"999737197","pt":1580599500482,"mc":[{"id":"1.168119364","rc":[{"batb":[[2,2.04,30.29]],"ltp":2.04,"tv":0.07,"id":23010367}]}]}
{"op":"mcm","clk":"999737276","pt":1580599501376,"mc":[{"id":"1.168119364","rc":[{"batb":[[2,2.04,54.53]],"ltp":2.04,"tv":0.07,"id":23010367},{"batb":[[2,1.71,65.79]],"ltp":1.73,"tv":20.27,"id":27652444}]}]}
{"op":"mcm","clk":"999745280","pt":1580599621535,"mc":[{"id":"1.168119364","rc":[{"batb":[[2,2.04,24.24]],"ltp":2.04,"tv":0.07,"id":23010367}]}]}
{"op":"mcm","clk":"999745335","pt":1580599622525,"mc":[{"id":"1.168119364","rc":[{"batb":[[2,2,80.22]],"ltp":2.04,"tv":0.07,"id":23010367},{"batb":[[2,1.7,114.6]],"ltp":1.73,"tv":20.27,"id":27652444}]}]}
{"op":"mcm","clk":"999752134","pt":1580599743637,"mc":[{"id":"1.168119364","rc":[{"batb":[[2,2.02,55]],"ltp":2.04,"tv":0.07,"id":23010367},{"batb":[[2,1.71,30.29]],"ltp":1.73,"tv":20.27,"id":27652444}]}]}
{"op":"mcm","clk":"999752180","pt":1580599744522,"mc":[{"id":"1.168119364","rc":[{"batb":[[2,1.71,65.79]],"ltp":1.73,"tv":20.27,"id":27652444}]}]}
{"op":"mcm","clk":"999756230","pt":1580599809613,"mc":[{"id":"1.168119364","rc":[{"batb":[[2,1.71,30.29]],"ltp":1.73,"tv":20.27,"id":27652444}]}]}
{"op":"mcm","clk":"999756286","pt":1580599810499,"mc":[{"id":"1.168119364","rc":[{"batb":[[2,1.71,65.79]],"ltp":1.73,"tv":20.27,"id":27652444}]}]}
{"op":"mcm","clk":"999756359","pt":1580599811651,"mc":[{"id":"1.168119364","rc":[{"batb":[[2,1.71,30.29]],"ltp":1.73,"tv":20.27,"id":27652444}]}]}
{"op":"mcm","clk":"999756397","pt":1580599812538,"mc":[{"id":"1.168119364","rc":[{"batb":[[2,1.71,65.79]],"ltp":1.73,"tv":20.27,"id":27652444}]}]}
{"op":"mcm","clk":"999756469","pt":1580599813645,"mc":[{"id":"1.168119364","rc":[{"batb":[[2,1.71,30.29]],"ltp":1.73,"tv":20.27,"id":27652444}]}]}
{"op":"mcm","clk":"999756536","pt":1580599814530,"mc":[{"id":"1.168119364","rc":[{"batb":[[2,1.71,65.79]],"ltp":1.73,"tv":20.27,"id":27652444}]}]}
{"op":"mcm","clk":"999756600","pt":1580599815633,"mc":[{"id":"1.168119364","rc":[{"batb":[[2,1.71,30.29]],"ltp":1.73,"tv":20.27,"id":27652444}]}]}
{"op":"mcm","clk":"999756659","pt":1580599816523,"mc":[{"id":"1.168119364","rc":[{"batb":[[2,1.71,65.79]],"ltp":1.73,"tv":20.27,"id":27652444}]}]}
{"op":"mcm","clk":"999756707","pt":1580599817573,"mc":[{"id":"1.168119364","rc":[{"batb":[[2,1.71,30.29]],"ltp":1.73,"tv":20.27,"id":27652444}]}]}
{"op":"mcm","clk":"999756760","pt":1580599818559,"mc":[{"id":"1.168119364","rc":[{"batb":[[2,1.71,65.79]],"ltp":1.73,"tv":20.27,"id":27652444}]}]}
{"op":"mcm","clk":"999756829","pt":1580599819635,"mc":[{"id":"1.168119364","rc":[{"batb":[[2,1.71,30.29]],"ltp":1.73,"tv":20.27,"id":27652444}]}]}
{"op":"mcm","clk":"999756879","pt":1580599820527,"mc":[{"id":"1.168119364","rc":[{"batb":[[2,1.71,65.79]],"ltp":1.73,"tv":20.27,"id":27652444}]}]}
{"op":"mcm","clk":"999756953","pt":1580599821640,"mc":[{"id":"1.168119364","rc":[{"batb":[[2,1.71,30.29]],"ltp":1.73,"tv":20.27,"id":27652444}]}]}
{"op":"mcm","clk":"999757008","pt":1580599822533,"mc":[{"id":"1.168119364","rc":[{"batb":[[2,1.71,65.79]],"ltp":1.73,"tv":20.27,"id":27652444}]}]}
{"op":"mcm","clk":"999757070","pt":1580599823564,"mc":[{"id":"1.168119364","rc":[{"batb":[[2,1.71,30.29]],"ltp":1.73,"tv":20.27,"id":27652444}]}]}
{"op":"mcm","clk":"999757144","pt":1580599824523,"mc":[{"id":"1.168119364","rc":[{"batb":[[2,1.71,65.79]],"ltp":1.73,"tv":20.27,"id":27652444}]}]}
{"op":"mcm","clk":"999757218","pt":1580599825573,"mc":[{"id":"1.168119364","rc":[{"batb":[[2,1.71,30.29]],"ltp":1.73,"tv":20.27,"id":27652444}]}]}
{"op":"mcm","clk":"999757294","pt":1580599826571,"mc":[{"id":"1.168119364","rc":[{"batb":[[2,1.71,65.79]],"ltp":1.73,"tv":20.27,"id":27652444}]}]}
{"op":"mcm","clk":"999757365","pt":1580599827577,"mc":[{"id":"1.168119364","rc":[{"batb":[[2,1.71,30.29]],"ltp":1.73,"tv":20.27,"id":27652444}]}]}
{"op":"mcm","clk":"999757445","pt":1580599828564,"mc":[{"id":"1.168119364","rc":[{"batb":[[2,1.71,65.79]],"ltp":1.73,"tv":20.27,"id":27652444}]}]}
{"op":"mcm","clk":"999757507","pt":1580599829552,"mc":[{"id":"1.168119364","rc":[{"batb":[[2,1.71,30.29]],"ltp":1.73,"tv":20.27,"id":27652444}]}]}
{"op":"mcm","clk":"999757569","pt":1580599830590,"mc":[{"id":"1.168119364","rc":[{"batb":[[2,1.71,65.79]],"ltp":1.73,"tv":20.27,"id":27652444}]}]}
{"op":"mcm","clk":"999757621","pt":1580599831584,"mc":[{"id":"1.168119364","rc":[{"batb":[[2,1.71,30.29]],"ltp":1.73,"tv":20.27,"id":27652444}]}]}
{"op":"mcm","clk":"999757678","pt":1580599832581,"mc":[{"id":"1.168119364","rc":[{"batb":[[2,1.71,65.79]],"ltp":1.73,"tv":20.27,"id":27652444}]}]}
{"op":"mcm","clk":"999757750","pt":1580599833582,"mc":[{"id":"1.168119364","rc":[{"batb":[[2,1.71,30.29]],"ltp":1.73,"tv":20.27,"id":27652444}]}]}
{"op":"mcm","clk":"999757822","pt":1580599834572,"mc":[{"id":"1.168119364","rc":[{"batb":[[2,1.71,65.79]],"ltp":1.73,"tv":20.27,"id":27652444}]}]}
{"op":"mcm","clk":"999757908","pt":1580599835672,"mc":[{"id":"1.168119364","rc":[{"batb":[[2,1.71,30.29]],"ltp":1.73,"tv":20.27,"id":27652444}]}]}
{"op":"mcm","clk":"999757975","pt":1580599836558,"mc":[{"id":"1.168119364","rc":[{"batb":[[2,1.71,65.79]],"ltp":1.73,"tv":20.27,"id":27652444}]}]}
{"op":"mcm","clk":"999758041","pt":1580599837558,"mc":[{"id":"1.168119364","rc":[{"batb":[[2,1.71,30.29]],"ltp":1.73,"tv":20.27,"id":27652444}]}]}
{"op":"mcm","clk":"999758103","pt":1580599838545,"mc":[{"id":"1.168119364","rc":[{"batb":[[2,1.71,65.79]],"ltp":1.73,"tv":20.27,"id":27652444}]}]}
{"op":"mcm","clk":"999758162","pt":1580599839601,"mc":[{"id":"1.168119364","rc":[{"batb":[[2,1.71,30.29]],"ltp":1.73,"tv":20.27,"id":27652444}]}]}
{"op":"mcm","clk":"999758209","pt":1580599840535,"mc":[{"id":"1.168119364","rc":[{"batb":[[2,1.71,65.79]],"ltp":1.73,"tv":20.27,"id":27652444}]}]}
{"op":"mcm","clk":"999758282","pt":1580599841686,"mc":[{"id":"1.168119364","rc":[{"batb":[[2,1.71,30.29]],"ltp":1.73,"tv":20.27,"id":27652444}]}]}
{"op":"mcm","clk":"999758320","pt":1580599842482,"mc":[{"id":"1.168119364","rc":[{"batb":[[2,1.71,65.79]],"ltp":1.73,"tv":20.27,"id":27652444}]}]}
{"op":"mcm","clk":"999758400","pt":1580599843576,"mc":[{"id":"1.168119364","rc":[{"batb":[[2,1.71,30.29]],"ltp":1.73,"tv":20.27,"id":27652444}]}]}
{"op":"mcm","clk":"999758465","pt":1580599844513,"mc":[{"id":"1.168119364","rc":[{"batb":[[2,1.71,65.79]],"ltp":1.73,"tv":20.27,"id":27652444}]}]}
{"op":"mcm","clk":"999758527","pt":1580599845601,"mc":[{"id":"1.168119364","rc":[{"batb":[[2,1.71,30.29]],"ltp":1.73,"tv":20.27,"id":27652444}]}]}
{"op":"mcm","clk":"999758586","pt":1580599846494,"mc":[{"id":"1.168119364","rc":[{"batb":[[2,1.71,65.79]],"ltp":1.73,"tv":20.27,"id":27652444}]}]}
{"op":"mcm","clk":"999758650","pt":1580599847586,"mc":[{"id":"1.168119364","rc":[{"batb":[[2,1.71,30.29]],"ltp":1.73,"tv":20.27,"id":27652444}]}]}
{"op":"mcm","clk":"999758697","pt":1580599848518,"mc":[{"id":"1.168119364","rc":[{"batb":[[2,1.71,65.79]],"ltp":1.73,"tv":20.27,"id":27652444}]}]}
{"op":"mcm","clk":"999758762","pt":1580599849611,"mc":[{"id":"1.168119364","rc":[{"batb":[[2,1.71,30.29]],"ltp":1.73,"tv":20.27,"id":27652444}]}]}
{"op":"mcm","clk":"999758824","pt":1580599850500,"mc":[{"id":"1.168119364","rc":[{"batb":[[2,1.71,65.79]],"ltp":1.73,"tv":20.27,"id":27652444}]}]}
{"op":"mcm","clk":"999758899","pt":1580599851594,"mc":[{"id":"1.168119364","rc":[{"batb":[[2,1.71,30.29]],"ltp":1.73,"tv":20.27,"id":27652444}]}]}
{"op":"mcm","clk":"999758957","pt":1580599852523,"mc":[{"id":"1.168119364","rc":[{"batb":[[2,1.71,65.79]],"ltp":1.73,"tv":20.27,"id":27652444}]}]}
{"op":"mcm","clk":"999759018","pt":1580599853616,"mc":[{"id":"1.168119364","rc":[{"batb":[[2,1.71,30.29]],"ltp":1.73,"tv":20.27,"id":27652444}]}]}
{"op":"mcm","clk":"999759076","pt":1580599854507,"mc":[{"id":"1.168119364","rc":[{"batb":[[2,1.71,65.79]],"ltp":1.73,"tv":20.27,"id":27652444}]}]}
{"op":"mcm","clk":"999759143","pt":1580599855597,"mc":[{"id":"1.168119364","rc":[{"batb":[[2,1.71,30.29]],"ltp":1.73,"tv":20.27,"id":27652444}]}]}
{"op":"mcm","clk":"999759195","pt":1580599856489,"mc":[{"id":"1.168119364","rc":[{"batb":[[2,1.71,65.79]],"ltp":1.73,"tv":20.27,"id":27652444}]}]}
{"op":"mcm","clk":"999759269","pt":1580599857591,"mc":[{"id":"1.168119364","rc":[{"batb":[[2,1.71,30.29]],"ltp":1.73,"tv":20.27,"id":27652444}]}]}
{"op":"mcm","clk":"999759335","pt":1580599858517,"mc":[{"id":"1.168119364","rc":[{"batb":[[2,1.71,65.79]],"ltp":1.73,"tv":20.27,"id":27652444}]}]}
{"op":"mcm","clk":"999759428","pt":1580599859618,"mc":[{"id":"1.168119364","rc":[{"batb":[[2,1.71,30.29]],"ltp":1.73,"tv":20.27,"id":27652444}]}]}
{"op":"mcm","clk":"999759489","pt":1580599860607,"mc":[{"id":"1.168119364","rc":[{"batb":[[2,1.71,65.79]],"ltp":1.73,"tv":20.27,"id":27652444}]}]}
{"op":"mcm","clk":"999759540","pt":1580599861639,"mc":[{"id":"1.168119364","rc":[{"batb":[[2,1.71,30.29]],"ltp":1.73,"tv":20.27,"id":27652444}]}]}
{"op":"mcm","clk":"999759597","pt":1580599862537,"mc":[{"id":"1.168119364","rc":[{"batb":[[2,1.71,65.79]],"ltp":1.73,"tv":20.27,"id":27652444}]}]}
{"op":"mcm","clk":"999759651","pt":1580599863559,"mc":[{"id":"1.168119364","rc":[{"batb":[[2,1.71,30.29]],"ltp":1.73,"tv":20.27,"id":27652444}]}]}
{"op":"mcm","clk":"999759707","pt":1580599864522,"mc":[{"id":"1.168119364","rc":[{"batb":[[2,1.71,65.79]],"ltp":1.73,"tv":20.27,"id":27652444}]}]}
{"op":"mcm","clk":"999759766","pt":1580599865514,"mc":[{"id":"1.168119364","rc":[{"batb":[[2,2.04,54.53]],"ltp":2.04,"tv":0.07,"id":23010367},{"batb":[[2,1.71,30.29]],"ltp":1.73,"tv":20.27,"id":27652444}]}]}
{"op":"mcm","clk":"999759822","pt":1580599866550,"mc":[{"id":"1.168119364","rc":[{"batb":[[2,1.71,65.79]],"ltp":1.73,"tv":20.27,"id":27652444}]}]}
{"op":"mcm","clk":"999767134","pt":1580599986616,"mc":[{"id":"1.168119364","rc":[{"batb":[[2,2.04,24.24]],"ltp":2.04,"tv":0.07,"id":23010367}]}]}
{"op":"mcm","clk":"999767197","pt":1580599987717,"mc":[{"id":"1.168119364","rc":[{"batb":[[2,2,80.22]],"ltp":2.04,"tv":0.07,"id":23010367},{"batb":[[2,1.7,114.6]],"ltp":1.73,"tv":20.27,"id":27652444}]}]}
{"op":"mcm","clk":"999774370","pt":1580600108647,"mc":[{"id":"1.168119364","rc":[{"batb":[[2,2.02,55]],"ltp":2.04,"tv":0.07,"id":23010367},{"batb":[[2,1.71,30.29]],"ltp":1.73,"tv":20.27,"id":27652444}]}]}
{"op":"mcm","clk":"999774449","pt":1580600109624,"mc":[{"id":"1.168119364","rc":[{"batb":[[2,1.71,65.79]],"ltp":1.73,"tv":20.27,"id":27652444}]}]}
{"op":"mcm","clk":"999781409","pt":1580600230681,"mc":[{"id":"1.168119364","rc":[{"batb":[[2,2.04,54.53]],"ltp":2.04,"tv":0.07,"id":23010367}]}]}
{"op":"mcm","clk":"999781430","pt":1580600230991,"mc":[{"id":"1.168119364","rc":[{"batb":[[2,1.71,35.5]],"ltp":1.73,"tv":20.27,"id":27652444}]}]}
{"op":"mcm","clk":"999781483","pt":1580600231770,"mc":[{"id":"1.168119364","rc":[{"batb":[[2,1.7,114.6]],"ltp":1.73,"tv":20.27,"id":27652444}]}]}
{"op":"mcm","clk":"999788043","pt":1580600351621,"mc":[{"id":"1.168119364","rc":[{"batb":[[2,2.04,24.24]],"ltp":2.04,"tv":0.07,"id":23010367}]}]}
{"op":"mcm","clk":"999788065","pt":1580600352088,"mc":[{"id":"1.168119364","rc":[{"batb":[[2,1.71,30.29]],"ltp":1.73,"tv":20.27,"id":27652444}]}]}
{"op":"mcm","clk":"999788098","pt":1580600352814,"mc":[{"id":"1.168119364","rc":[{"batb":[[2,2,80.22]],"ltp":2.04,"tv":0.07,"id":23010367},{"batb":[[2,1.71,65.79]],"ltp":1.73,"tv":20.27,"id":27652444}]}]}
{"op":"mcm","clk":"999795048","pt":1580600473660,"mc":[{"id":"1.168119364","rc":[{"batb":[[2,2.02,30.29]],"ltp":2.04,"tv":0.07,"id":23010367},{"batb":[[2,1.71,35.5]],"ltp":1.73,"tv":20.27,"id":27652444}]}]}
{"op":"mcm","clk":"999795054","pt":1580600473814,"mc":[{"id":"1.168119364","rc":[{"batb":[[2,2.02,55]],"ltp":2.04,"tv":0.07,"id":23010367}]}]}
{"op":"mcm","clk":"999795137","pt":1580600474851,"mc":[{"id":"1.168119364","rc":[{"batb":[[2,1.7,114.6]],"ltp":1.73,"tv":20.27,"id":27652444}]}]}
{"op":"mcm","clk":"999797144","pt":1580600511640,"mc":[{"id":"1.168119364","marketDefinition":{"bspMarket":false,"turnInPlayEnabled":true,"persistenceEnabled":true,"marketBaseRate":5.0,"eventId":"29678414","eventTypeId":"2","numberOfWinners":1,"bettingType":"ODDS","marketType":"MATCH_ODDS","marketTime":"2020-02-02T00:30:00.000Z","suspendTime":"2020-02-02T00:30:00.000Z","bspReconciled":false,"complete":true,"inPlay":false,"crossMatching":true,"runnersVoidable":false,"numberOfActiveRunners":2,"betDelay":0,"status":"OPEN","runners":[{"status":"ACTIVE","sortPriority":1,"id":23010367,"name":"Margaroli/Vavassori"},{"status":"ACTIVE","sortPriority":2,"id":27652444,"name":"Heliovaara/Verbeek"}],"regulators":["MR_INT"],"countryCode":"AU","discountAllowed":true,"timezone":"UTC","openDate":"2020-02-02T00:00:00.000Z","version":3147850861,"name":"Match Odds","eventName":"Margaroli/Vavassori v Heliovaara/Verbeek"}}]}
{"op":"mcm","clk":"999797210","pt":1580600512641,"mc":[{"id":"1.168119364","marketDefinition":{"bspMarket":false,"turnInPlayEnabled":true,"persistenceEnabled":true,"marketBaseRate":5.0,"eventId":"29678414","eventTypeId":"2","numberOfWinners":1,"bettingType":"ODDS","marketType":"MATCH_ODDS","marketTime":"2020-02-02T00:30:00.000Z","suspendTime":"2020-02-02T00:30:00.000Z","bspReconciled":false,"complete":true,"inPlay":false,"crossMatching":true,"runnersVoidable":false,"numberOfActiveRunners":2,"betDelay":0,"status":"OPEN","runners":[{"status":"ACTIVE","sortPriority":1,"id":23010367,"name":"Margaroli/Vavassori"},{"status":"ACTIVE","sortPriority":2,"id":27652444,"name":"Heliovaara/Verbeek"}],"regulators":["MR_INT"],"countryCode":"AU","discountAllowed":true,"timezone":"UTC","openDate":"2020-02-02T00:30:00.000Z","version":3147850861,"name":"Match Odds","eventName":"Margaroli/Vavassori v Heliovaara/Verbeek"}}]}
{"op":"mcm","clk":"999802173","pt":1580600595554,"mc":[{"id":"1.168119364","rc":[{"batb":[[2,2.04,30.29]],"ltp":2.04,"tv":0.07,"id":23010367},{"batb":[[2,1.71,30.29]],"ltp":1.73,"tv":20.27,"id":27652444}]}]}
{"op":"mcm","clk":"999802197","pt":1580600595864,"mc":[{"id":"1.168119364","rc":[{"batb":[[2,2.04,54.53]],"ltp":2.04,"tv":0.07,"id":23010367},{"batb":[[2,1.71,65.79]],"ltp":1.73,"tv":20.27,"id":27652444}]}]}
{"op":"mcm","clk":"999807748","pt":1580600687432,"mc":[{"id":"1.168119364","rc":[{"batl":[[0,1.95,15.14],[1,1.98,7.57],[2,95,15.9]],"ltp":1.73,"tv":20.27,"id":27652444}]}]}
{"op":"mcm","clk":"999807985","pt":1580600691409,"mc":[{"id":"1.168119364","rc":[{"batb":[[1,1.73,11.11]],"ltp":1.73,"tv":20.27,"id":27652444}]}]}
{"op":"mcm","clk":"999809524","pt":1580600716572,"mc":[{"id":"1.168119364","rc":[{"batb":[[2,2.04,24.24]],"ltp":2.04,"tv":0.07,"id":23010367}]}]}
{"op":"mcm","clk":"999809588","pt":1580600717656,"mc":[{"id":"1.168119364","rc":[{"batb":[[2,2,80.22]],"ltp":2.04,"tv":0.07,"id":23010367},{"batb":[[2,1.71,35.5]],"ltp":1.73,"tv":20.27,"id":27652444}]}]}
{"op":"mcm","clk":"999809600","pt":1580600717864,"mc":[{"id":"1.168119364","rc":[{"batb":[[2,2.02,24.71]],"ltp":2.04,"tv":0.07,"id":23010367},{"batb":[[2,1.7,114.6]],"ltp":1.73,"tv":20.27,"id":27652444}]}]}
{"op":"mcm","clk":"999828121","pt":1580601019222,"mc":[{"id":"1.168119364","rc":[{"batb":[[2,2.04,24.24]],"ltp":2.04,"tv":0.07,"id":23010367}]}]}
{"op":"mcm","clk":"999828353","pt":1580601023845,"mc":[{"id":"1.168119364","rc":[{"trd":[[1.74,2.93]],"batb":[[0,1.74,1.43]],"ltp":1.74,"tv":20.3,"id":27652444}],"tv":20.38}]}
{"op":"mcm","clk":"999829740","pt":1580601049437,"mc":[{"id":"1.168119364","rc":[{"batb":[[0,1.74,1.44]],"ltp":1.74,"tv":20.3,"id":27652444}]}]}
{"op":"mcm","clk":"999859446","pt":1580601609200,"mc":[{"id":"1.168119364","rc":[{"batb":[[2,2,80.22]],"ltp":2.04,"tv":0.07,"id":23010367}]}]}
{"op":"mcm","clk":"999859480","pt":1580601610129,"mc":[{"id":"1.168119364","rc":[{"batb":[[2,2.02,24.71]],"ltp":2.04,"tv":0.07,"id":23010367}]}]}
{"op":"mcm","clk":"999872477","pt":1580601911533,"mc":[{"id":"1.168119364","rc":[{"batb":[[2,2.04,24.24]],"ltp":2.04,"tv":0.07,"id":23010367}]}]}
{"op":"mcm","clk":"999875865","pt":1580601993128,"mc":[{"id":"1.168119364","rc":[{"batb":[[0,2.08,3.24]],"ltp":2.04,"tv":0.07,"id":23010367},{"batb":[[0,1.74,3.46]],"ltp":1.74,"tv":20.3,"id":27652444}]}]}
{"op":"mcm","clk":"999909658","pt":1580602508764,"mc":[{"id":"1.168119364","rc":[{"batb":[[2,2,80.22]],"ltp":2.04,"tv":0.07,"id":23010367}]}]}
{"op":"mcm","clk":"999909745","pt":1580602509750,"mc":[{"id":"1.168119364","rc":[{"batb":[[2,2.04,24.24]],"ltp":2.04,"tv":0.07,"id":23010367}]}]}
{"op":"mcm","clk":"999909814","pt":1580602510788,"mc":[{"id":"1.168119364","rc":[{"batb":[[2,2.02,24.71]],"ltp":2.04,"tv":0.07,"id":23010367}]}]}
{"op":"mcm","clk":"999909879","pt":1580602511779,"mc":[{"id":"1.168119364","rc":[{"batb":[[2,2.04,24.24]],"ltp":2.04,"tv":0.07,"id":23010367}]}]}
{"op":"mcm","clk":"999909943","pt":1580602512771,"mc":[{"id":"1.168119364","rc":[{"batb":[[2,2,80.22]],"ltp":2.04,"tv":0.07,"id":23010367}]}]}
{"op":"mcm","clk":"999910015","pt":1580602513760,"mc":[{"id":"1.168119364","rc":[{"batb":[[2,2.04,24.24]],"ltp":2.04,"tv":0.07,"id":23010367}]}]}
{"op":"mcm","clk":"999910081","pt":1580602514791,"mc":[{"id":"1.168119364","rc":[{"batb":[[2,2.02,24.71]],"ltp":2.04,"tv":0.07,"id":23010367}]}]}
{"op":"mcm","clk":"999910162","pt":1580602515757,"mc":[{"id":"1.168119364","rc":[{"batb":[[2,2.04,24.24]],"ltp":2.04,"tv":0.07,"id":23010367}]}]}
{"op":"mcm","clk":"999910231","pt":1580602516792,"mc":[{"id":"1.168119364","rc":[{"batb":[[2,2,80.22]],"ltp":2.04,"tv":0.07,"id":23010367}]}]}
{"op":"mcm","clk":"999910279","pt":1580602517777,"mc":[{"id":"1.168119364","rc":[{"batb":[[2,2.04,24.24]],"ltp":2.04,"tv":0.07,"id":23010367}]}]}
{"op":"mcm","clk":"999910341","pt":1580602518765,"mc":[{"id":"1.168119364","rc":[{"batb":[[2,2.02,24.71]],"ltp":2.04,"tv":0.07,"id":23010367}]}]}
{"op":"mcm","clk":"999910412","pt":1580602519798,"mc":[{"id":"1.168119364","rc":[{"batb":[[2,2.04,24.24]],"ltp":2.04,"tv":0.07,"id":23010367}]}]}
{"op":"mcm","clk":"999910473","pt":1580602520790,"mc":[{"id":"1.168119364","rc":[{"batb":[[2,2,80.22]],"ltp":2.04,"tv":0.07,"id":23010367}]}]}
{"op":"mcm","clk":"999910622","pt":1580602522667,"mc":[{"id":"1.168119364","rc":[{"batb":[[2,2.02,24.71]],"ltp":2.04,"tv":0.07,"id":23010367}]}]}
{"op":"mcm","clk":"999910692","pt":1580602523767,"mc":[{"id":"1.168119364","rc":[{"batb":[[2,2.04,24.24]],"ltp":2.04,"tv":0.07,"id":23010367}]}]}
{"op":"mcm","clk":"999910789","pt":1580602524811,"mc":[{"id":"1.168119364","rc":[{"batb":[[2,2,80.22]],"ltp":2.04,"tv":0.07,"id":23010367}]}]}
{"op":"mcm","clk":"999910930","pt":1580602526688,"mc":[{"id":"1.168119364","rc":[{"batb":[[2,2.04,24.24]],"ltp":2.04,"tv":0.07,"id":23010367}]}]}
{"op":"mcm","clk":"999911067","pt":1580602528811,"mc":[{"id":"1.168119364","rc":[{"batb":[[2,2,80.22]],"ltp":2.04,"tv":0.07,"id":23010367}]}]}
{"op":"mcm","clk":"999911215","pt":1580602530685,"mc":[{"id":"1.168119364","rc":[{"batb":[[2,2.04,24.24]],"ltp":2.04,"tv":0.07,"id":23010367}]}]}
{"op":"mcm","clk":"999911480","pt":1580602534709,"mc":[{"id":"1.168119364","rc":[{"batb":[[2,2.02,24.71]],"ltp":2.04,"tv":0.07,"id":23010367}]}]}
{"op":"mcm","clk":"999911549","pt":1580602535695,"mc":[{"id":"1.168119364","rc":[{"batb":[[2,2.04,24.24]],"ltp":2.04,"tv":0.07,"id":23010367}]}]}
{"op":"mcm","clk":"999911749","pt":1580602538705,"mc":[{"id":"1.168119364","rc":[{"batb":[[2,2.02,24.71]],"ltp":2.04,"tv":0.07,"id":23010367}]}]}
{"op":"mcm","clk":"999911818","pt":1580602539695,"mc":[{"id":"1.168119364","rc":[{"batb":[[2,2.04,24.24]],"ltp":2.04,"tv":0.07,"id":23010367}]}]}
{"op":"mcm","clk":"999911890","pt":1580602540732,"mc":[{"id":"1.168119364","rc":[{"batb":[[2,2,80.22]],"ltp":2.04,"tv":0.07,"id":23010367}]}]}
{"op":"mcm","clk":"999911954","pt":1580602541717,"mc":[{"id":"1.168119364","rc":[{"batb":[[2,2.04,24.24]],"ltp":2.04,"tv":0.07,"id":23010367}]}]}
{"op":"mcm","clk":"999912031","pt":1580602542708,"mc":[{"id":"1.168119364","rc":[{"batb":[[2,2.02,24.71]],"ltp":2.04,"tv":0.07,"id":23010367}]}]}
{"op":"mcm","clk":"999912100","pt":1580602543739,"mc":[{"id":"1.168119364","rc":[{"batb":[[2,2.04,24.24]],"ltp":2.04,"tv":0.07,"id":23010367}]}]}
{"op":"mcm","clk":"999912537","pt":1580602550711,"mc":[{"id":"1.168119364","rc":[{"batb":[[2,2.02,24.71]],"ltp":2.04,"tv":0.07,"id":23010367}]}]}
{"op":"mcm","clk":"999912607","pt":1580602551747,"mc":[{"id":"1.168119364","rc":[{"batb":[[2,2.04,24.24]],"ltp":2.04,"tv":0.07,"id":23010367}]}]}
{"op":"mcm","clk":"999912949","pt":1580602556733,"mc":[{"id":"1.168119364","rc":[{"batb":[[2,2,80.22]],"ltp":2.04,"tv":0.07,"id":23010367}]}]}
{"op":"mcm","clk":"999913025","pt":1580602557724,"mc":[{"id":"1.168119364","rc":[{"batb":[[2,2.04,24.24]],"ltp":2.04,"tv":0.07,"id":23010367}]}]}
{"op":"mcm","clk":"999913236","pt":1580602560736,"mc":[{"id":"1.168119364","rc":[{"batb":[[2,2,80.22]],"ltp":2.04,"tv":0.07,"id":23010367}]}]}
{"op":"mcm","clk":"999913297","pt":1580602561775,"mc":[{"id":"1.168119364","rc":[{"batb":[[2,2.04,24.24]],"ltp":2.04,"tv":0.07,"id":23010367}]}]}
{"op":"mcm","clk":"999913378","pt":1580602562762,"mc":[{"id":"1.168119364","rc":[{"batb":[[2,2.02,24.71]],"ltp":2.04,"tv":0.07,"id":23010367}]}]}
{"op":"mcm","clk":"999913518","pt":1580602564731,"mc":[{"id":"1.168119364","rc":[{"batb":[[2,2,80.22]],"ltp":2.04,"tv":0.07,"id":23010367}]}]}
{"op":"mcm","clk":"999913584","pt":1580602565765,"mc":[{"id":"1.168119364","rc":[{"batb":[[2,2.04,24.24]],"ltp":2.04,"tv":0.07,"id":23010367}]}]}
{"op":"mcm","clk":"999913663","pt":1580602566759,"mc":[{"id":"1.168119364","rc":[{"batb":[[2,2.02,24.71]],"ltp":2.04,"tv":0.07,"id":23010367}]}]}
{"op":"mcm","clk":"999913743","pt":1580602567747,"mc":[{"id":"1.168119364","rc":[{"batb":[[2,2.04,24.24]],"ltp":2.04,"tv":0.07,"id":23010367}]}]}
{"op":"mcm","clk":"999916774","pt":1580602611008,"mc":[{"id":"1.168119364","marketDefinition":{"bspMarket":false,"turnInPlayEnabled":true,"persistenceEnabled":true,"marketBaseRate":5.0,"eventId":"29678414","eventTypeId":"2","numberOfWinners":1,"bettingType":"ODDS","marketType":"MATCH_ODDS","marketTime":"2020-02-02T01:00:00.000Z","suspendTime":"2020-02-02T01:00:00.000Z","bspReconciled":false,"complete":true,"inPlay":false,"crossMatching":true,"runnersVoidable":false,"numberOfActiveRunners":2,"betDelay":0,"status":"OPEN","runners":[{"status":"ACTIVE","sortPriority":1,"id":23010367,"name":"Margaroli/Vavassori"},{"status":"ACTIVE","sortPriority":2,"id":27652444,"name":"Heliovaara/Verbeek"}],"regulators":["MR_INT"],"countryCode":"AU","discountAllowed":true,"timezone":"UTC","openDate":"2020-02-02T00:30:00.000Z","version":3147905853,"name":"Match Odds","eventName":"Margaroli/Vavassori v Heliovaara/Verbeek"}}]}
{"op":"mcm","clk":"999917049","pt":1580602615018,"mc":[{"id":"1.168119364","marketDefinition":{"bspMarket":false,"turnInPlayEnabled":true,"persistenceEnabled":true,"marketBaseRate":5.0,"eventId":"29678414","eventTypeId":"2","numberOfWinners":1,"bettingType":"ODDS","marketType":"MATCH_ODDS","marketTime":"2020-02-02T01:00:00.000Z","suspendTime":"2020-02-02T01:00:00.000Z","bspReconciled":false,"complete":true,"inPlay":false,"crossMatching":true,"runnersVoidable":false,"numberOfActiveRunners":2,"betDelay":0,"status":"OPEN","runners":[{"status":"ACTIVE","sortPriority":1,"id":23010367,"name":"Margaroli/Vavassori"},{"status":"ACTIVE","sortPriority":2,"id":27652444,"name":"Heliovaara/Verbeek"}],"regulators":["MR_INT"],"countryCode":"AU","discountAllowed":true,"timezone":"UTC","openDate":"2020-02-02T01:00:00.000Z","version":3147905853,"name":"Match Odds","eventName":"Margaroli/Vavassori v Heliovaara/Verbeek"}}]}
{"op":"mcm","clk":"999946079","pt":1580603072796,"mc":[{"id":"1.168119364","rc":[{"trd":[[2.08,2.11]],"batb":[[0,2.08,1.13]],"ltp":2.08,"tv":2.18,"id":23010367},{"trd":[[1.93,2.27]],"ltp":1.93,"tv":22.57,"id":27652444}],"tv":24.76}]}
{"op":"mcm","clk":"999965229","pt":1580603409058,"mc":[{"id":"1.168119364","rc":[{"batb":[[2,2,80.22]],"ltp":2.08,"tv":2.18,"id":23010367}]}]}
{"op":"mcm","clk":"999965280","pt":1580603410043,"mc":[{"id":"1.168119364","rc":[{"batb":[[2,2.02,24.71]],"ltp":2.08,"tv":2.18,"id":23010367}]}]}
{"op":"mcm","clk":"999982514","pt":1580603711410,"mc":[{"id":"1.168119364","rc":[{"batb":[[2,2.04,24.24]],"ltp":2.08,"tv":2.18,"id":23010367}]}]}
{"op":"mcm","clk":"999983294","pt":1580603726029,"mc":[{"id":"1.168119364","rc":[{"batb":[[0,2.08,2.34]],"ltp":2.08,"tv":2.18,"id":23010367}]}]}
{"op":"mcm","clk":"1000009461","pt":1580604309493,"mc":[{"id":"1.168119364","rc":[{"batb":[[2,2,80.22]],"ltp":2.08,"tv":2.18,"id":23010367}]}]}
{"op":"mcm","clk":"1000009515","pt":1580604310382,"mc":[{"id":"1.168119364","rc":[{"batb":[[2,2.02,24.71]],"ltp":2.08,"tv":2.18,"id":23010367}]}]}
{"op":"mcm","clk":"1000022777","pt":1580604611734,"mc":[{"id":"1.168119364","rc":[{"batb":[[2,2.04,24.24]],"ltp":2.08,"tv":2.18,"id":23010367}]}]}
{"op":"mcm","clk":"1000039946","pt":1580605014215,"mc":[{"id":"1.168119364","marketDefinition":{"bspMarket":false,"turnInPlayEnabled":true,"persistenceEnabled":true,"marketBaseRate":5.0,"eventId":"29678414","eventTypeId":"2","numberOfWinners":1,"bettingType":"ODDS","marketType":"MATCH_ODDS","marketTime":"2020-02-02T00:54:00.000Z","suspendTime":"2020-02-02T00:54:00.000Z","bspReconciled":false,"complete":true,"inPlay":false,"crossMatching":true,"runnersVoidable":false,"numberOfActiveRunners":2,"betDelay":0,"status":"OPEN","runners":[{"status":"ACTIVE","sortPriority":1,"id":23010367,"name":"Margaroli/Vavassori"},{"status":"ACTIVE","sortPriority":2,"id":27652444,"name":"Heliovaara/Verbeek"}],"regulators":["MR_INT"],"countryCode":"AU","discountAllowed":true,"timezone":"UTC","openDate":"2020-02-02T01:00:00.000Z","version":3147960880,"name":"Match Odds","eventName":"Margaroli/Vavassori v Heliovaara/Verbeek"}}]}
{"op":"mcm","clk":"1000040019","pt":1580605016258,"mc":[{"id":"1.168119364","marketDefinition":{"bspMarket":false,"turnInPlayEnabled":true,"persistenceEnabled":true,"marketBaseRate":5.0,"eventId":"29678414","eventTypeId":"2","numberOfWinners":1,"bettingType":"ODDS","marketType":"MATCH_ODDS","marketTime":"2020-02-02T00:54:00.000Z","suspendTime":"2020-02-02T00:54:00.000Z","bspReconciled":false,"complete":true,"inPlay":false,"crossMatching":true,"runnersVoidable":false,"numberOfActiveRunners":2,"betDelay":0,"status":"OPEN","runners":[{"status":"ACTIVE","sortPriority":1,"id":23010367,"name":"Margaroli/Vavassori"},{"status":"ACTIVE","sortPriority":2,"id":27652444,"name":"Heliovaara/Verbeek"}],"regulators":["MR_INT"],"countryCode":"AU","discountAllowed":true,"timezone":"UTC","openDate":"2020-02-02T00:54:00.000Z","version":3147960880,"name":"Match Odds","eventName":"Margaroli/Vavassori v Heliovaara/Verbeek"}}]}
{"op":"mcm","clk":"1000044642","pt":1580605200721,"mc":[{"id":"1.168119364","rc":[{"batb":[[2,2,55.01]],"ltp":2.08,"tv":2.18,"id":23010367},{"batb":[[2,1.7,78.59]],"ltp":1.93,"tv":22.57,"id":27652444}]}]}
{"op":"mcm","clk":"1000061000","pt":1580605733808,"mc":[{"id":"1.168119364","rc":[{"batb":[[1,1.73,86.12],[2,1.5,4.36]],"ltp":1.93,"tv":22.57,"id":27652444}]}]}
{"op":"mcm","clk":"1000070110","pt":1580606050651,"mc":[{"id":"1.168119364","marketDefinition":{"bspMarket":false,"turnInPlayEnabled":true,"persistenceEnabled":true,"marketBaseRate":5.0,"eventId":"29678414","eventTypeId":"2","numberOfWinners":1,"bettingType":"ODDS","marketType":"MATCH_ODDS","marketTime":"2020-02-02T00:54:00.000Z","suspendTime":"2020-02-02T00:54:00.000Z","bspReconciled":false,"complete":true,"inPlay":true,"crossMatching":true,"runnersVoidable":false,"numberOfActiveRunners":2,"betDelay":3,"status":"OPEN","runners":[{"status":"ACTIVE","sortPriority":1,"id":23010367,"name":"Margaroli/Vavassori"},{"status":"ACTIVE","sortPriority":2,"id":27652444,"name":"Heliovaara/Verbeek"}],"regulators":["MR_INT"],"countryCode":"AU","discountAllowed":true,"timezone":"UTC","openDate":"2020-02-02T00:54:00.000Z","version":3147986614,"name":"Match Odds","eventName":"Margaroli/Vavassori v Heliovaara/Verbeek"}}]}
{"op":"mcm","clk":"1000070112","pt":1580606050755,"mc":[{"id":"1.168119364","rc":[{"batb":[[0,1.03,9.21],[1,1.02,25.41],[2,1.01,312.51]],"batl":[[0,1000,0.02],[1,95,0],[2,990,0]],"ltp":2.08,"tv":2.18,"id":23010367},{"batb":[[0,1.03,9.23],[1,1.02,25.41],[2,1.01,312.51]],"batl":[[0,1000,0.02],[1,1.98,0],[2,95,0]],"ltp":1.93,"tv":22.57,"id":27652444}]}]}
{"op":"mcm","clk":"1000070189","pt":1580606053540,"mc":[{"id":"1.168119364","rc":[{"batb":[[0,1.02,1.01],[1,1.01,312.51],[2,1.01,0]],"ltp":2.08,"tv":2.18,"id":23010367},{"batb":[[0,1.02,1.03],[1,1.01,312.51],[2,1.01,0]],"ltp":1.93,"tv":22.57,"id":27652444}]}]}
{"op":"mcm","clk":"1000070931","pt":1580606079850,"mc":[{"id":"1.168119364","rc":[{"batb":[[0,1.5,37.88],[1,1.02,1.01],[2,1.01,312.51]],"ltp":1.93,"tv":22.57,"id":27652444}]}]}
{"op":"mcm","clk":"1000071018","pt":1580606083187,"mc":[{"id":"1.168119364","rc":[{"batb":[[0,1.53,22.72],[1,1.02,1.01],[2,1.01,312.51]],"ltp":2.08,"tv":2.18,"id":23010367}]}]}
{"op":"mcm","clk":"1000074172","pt":1580606202760,"mc":[{"id":"1.168119364","rc":[{"batb":[[2,1.01,12.51]],"ltp":2.08,"tv":2.18,"id":23010367},{"batb":[[2,1.01,12.51]],"ltp":1.93,"tv":22.57,"id":27652444}]}]}
{"op":"mcm","clk":"1000074364","pt":1580606210727,"mc":[{"id":"1.168119364","rc":[{"trd":[[1.53,45.43]],"batb":[[0,1.02,1.01],[1,1.01,12.51],[2,1.01,0]],"batl":[[0,1.53,1491.75],[1,1000,0.02]],"ltp":1.53,"tv":47.61,"id":23010367}],"tv":70.19}]}
{"op":"mcm","clk":"1000074529","pt":1580606218881,"mc":[{"id":"1.168119364","rc":[{"trd":[[1.48,0.01]],"batb":[[0,1.02,1]],"ltp":1.48,"tv":47.62,"id":23010367},{"trd":[[3.1,0.01]],"batb":[[0,1.5,37.98]],"ltp":3.1,"tv":22.58,"id":27652444}],"tv":70.21}]}
{"op":"mcm","clk":"1000074837","pt":1580606232873,"mc":[{"id":"1.168119364","rc":[{"batl":[[0,1000,0.02],[1,1000,0]],"ltp":1.48,"tv":47.62,"id":23010367}]}]}
{"op":"mcm","clk":"1000075357","pt":1580606251904,"mc":[{"id":"1.168119364","rc":[{"batb":[[0,1.31,60.58],[1,1.02,1],[2,1.01,12.51]],"ltp":1.48,"tv":47.62,"id":23010367}]}]}
{"op":"mcm","clk":"1000075722","pt":1580606263806,"mc":[{"id":"1.168119364","rc":[{"batl":[[0,1.55,22.42],[1,1000,0.02]],"ltp":1.48,"tv":47.62,"id":23010367}]}]}
{"op":"mcm","clk":"1000076003","pt":1580606272536,"mc":[{"id":"1.168119364","rc":[{"batl":[[1,1.95,45.43],[2,1000,0.02]],"ltp":1.48,"tv":47.62,"id":23010367}]}]}
{"op":"mcm","clk":"1000077142","pt":1580606304167,"mc":[{"id":"1.168119364","rc":[{"trd":[[1.4,0.25]],"batl":[[2,2.1,363.31]],"ltp":1.4,"tv":47.87,"id":23010367},{"trd":[[3.5,0.1]],"batb":[[0,1.5,37.88]],"ltp":3.5,"tv":22.68,"id":27652444}],"tv":70.56}]}
{"op":"mcm","clk":"1000078632","pt":1580606347324,"mc":[{"id":"1.168119364","rc":[{"trd":[[1.55,5.33]],"batb":[[0,1.46,435.46],[1,1.31,60.58],[2,1.02,1]],"batl":[[0,1.55,19.76]],"ltp":1.55,"tv":53.2,"id":23010367},{"batb":[[0,2.18,2.55],[1,1.5,37.88],[2,1.02,1.01]],"ltp":3.5,"tv":22.68,"id":27652444}],"tv":75.89}]}
{"op":"mcm","clk":"1000078999","pt":1580606358030,"mc":[{"id":"1.168119364","rc":[{"trd":[[1.55,25.09]],"batl":[[0,1.95,45.43],[1,2.1,363.31],[2,1000,0.02]],"ltp":1.55,"tv":72.96,"id":23010367},{"trd":[[2.8,10.94]],"batl":[[0,1000,0.57]],"ltp":2.8,"tv":33.62,"id":27652444}],"tv":106.59}]}
{"op":"mcm","clk":"1000079199","pt":1580606362848,"mc":[{"id":"1.168119364","rc":[{"batl":[[0,2.8,38.41],[1,1000,0.02]],"ltp":2.8,"tv":33.62,"id":27652444}]}]}
{"op":"mcm","clk":"1000079285","pt":1580606365173,"mc":[{"id":"1.168119364","rc":[{"batl":[[0,2.8,37.86]],"ltp":2.8,"tv":33.62,"id":27652444}]}]}
{"op":"mcm","clk":"1000079357","pt":1580606366831,"mc":[{"id":"1.168119364","rc":[{"batl":[[0,1000,0.02],[1,1000,0]],"ltp":2.8,"tv":33.62,"id":27652444}]}]}
{"op":"mcm","clk":"1000079559","pt":1580606372466,"mc":[{"id":"1.168119364","rc":[{"batb":[[0,1.5,37.88],[1,1.02,1.01],[2,1.01,12.51]],"ltp":2.8,"tv":33.62,"id":27652444}]}]}
{"op":"mcm","clk":"1000079579","pt":1580606372982,"mc":[{"id":"1.168119364","rc":[{"batb":[[0,1.31,60.58],[1,1.02,1],[2,1.01,12.51]],"batl":[[1,1000,0.02],[2,1000,0]],"ltp":1.55,"tv":72.96,"id":23010367}]}]}
{"op":"mcm","clk":"1000079719","pt":1580606376655,"mc":[{"id":"1.168119364","rc":[{"batb":[[0,1.55,420.27],[1,1.31,60.58],[2,1.02,1]],"batl":[[1,2.42,286.67],[2,1000,0.02]],"ltp":1.55,"tv":72.96,"id":23010367}]}]}
{"op":"mcm","clk":"1000079854","pt":1580606380265,"mc":[{"id":"1.168119364","rc":[{"batb":[[1,1.4,45.43],[2,1.31,60.58]],"batl":[[0,2.42,286.67],[1,1000,0.02],[2,1000,0]],"ltp":1.55,"tv":72.96,"id":23010367}]}]}
{"op":"mcm","clk":"1000080000","pt":1580606384902,"mc":[{"id":"1.168119364","rc":[{"batb":[[0,1.59,45.43],[1,1.55,420.27],[2,1.4,45.43]],"ltp":1.55,"tv":72.96,"id":23010367}]}]}
{"op":"mcm","clk":"1000080553","pt":1580606401096,"mc":[{"id":"1.168119364","rc":[{"batl":[[0,1000,0.02],[1,1000,0]],"ltp":1.55,"tv":72.96,"id":23010367}]}]}
{"op":"mcm","clk":"1000080632","pt":1580606403729,"mc":[{"id":"1.168119364","rc":[{"batb":[[0,1.55,420.27],[1,1.4,45.43],[2,1.31,60.58]],"ltp":1.55,"tv":72.96,"id":23010367},{"batb":[[0,2.32,2.56],[1,1.5,37.88],[2,1.02,1.01]],"ltp":2.8,"tv":33.62,"id":27652444}]}]}
{"op":"mcm","clk":"1000080666","pt":1580606404508,"mc":[{"id":"1.168119364","rc":[{"batl":[[0,2.3,309.9],[1,1000,0.02]],"ltp":1.55,"tv":72.96,"id":23010367}]}]}
{"op":"mcm","clk":"1000081567","pt":1580606430967,"mc":[{"id":"1.168119364","rc":[{"batb":[[0,1.5,37.88],[1,1.02,1.01],[2,1.01,12.51]],"ltp":2.8,"tv":33.62,"id":27652444}]}]}
{"op":"mcm","clk":"1000082373","pt":1580606456182,"mc":[{"id":"1.168119364","rc":[{"batb":[[0,1.4,45.43],[1,1.31,60.58],[2,1.02,1]],"batl":[[0,1000,0.02],[1,1000,0]],"ltp":1.55,"tv":72.96,"id":23010367}]}]}
{"op":"mcm","clk":"1000082505","pt":1580606459994,"mc":[{"id":"1.168119364","rc":[{"batb":[[0,1.67,409.55],[1,1.4,45.43],[2,1.31,60.58]],"batl":[[0,2.72,241.68],[1,1000,0.02]],"ltp":1.55,"tv":72.96,"id":23010367},{"batb":[[0,1.85,2.55],[1,1.5,37.88],[2,1.02,1.01]],"ltp":2.8,"tv":33.62,"id":27652444}]}]}
{"op":"mcm","clk":"1000082733","pt":1580606466297,"mc":[{"id":"1.168119364","rc":[{"batb":[[0,1.69,45.43],[1,1.67,409.55],[2,1.4,45.43]],"ltp":1.55,"tv":72.96,"id":23010367}]}]}
{"op":"mcm","clk":"1000083630","pt":1580606487146,"mc":[{"id":"1.168119364","rc":[{"batb":[[0,1.5,37.88],[1,1.02,1.01],[2,1.01,12.51]],"ltp":2.8,"tv":33.62,"id":27652444}]}]}
{"op":"mcm","clk":"1000083990","pt":1580606497074,"mc":[{"id":"1.168119364","rc":[{"batl":[[0,2.2,147.94],[1,1000,0.02]],"ltp":2.8,"tv":33.62,"id":27652444}]}]}
{"op":"mcm","clk":"1000084791","pt":1580606516372,"mc":[{"id":"1.168119364","rc":[{"batb":[[0,1.64,31.06],[1,1.5,37.86],[2,1.02,1.01]],"ltp":2.8,"tv":33.62,"id":27652444}]}]}
{"op":"mcm","clk":"1000084865","pt":1580606519410,"mc":[{"id":"1.168119364","rc":[{"batl":[[0,1000,0.02],[1,1000,0]],"ltp":1.55,"tv":72.96,"id":23010367}]}]}
{"op":"mcm","clk":"1000084973","pt":1580606522603,"mc":[{"id":"1.168119364","rc":[{"batb":[[0,1.93,2.54],[1,1.64,31.06],[2,1.5,37.86]],"ltp":2.8,"tv":33.62,"id":27652444}]}]}
{"op":"mcm","clk":"1000084987","pt":1580606523121,"mc":[{"id":"1.168119364","rc":[{"batl":[[0,2.5,274.68],[1,1000,0.02]],"ltp":1.55,"tv":72.96,"id":23010367}]}]}
{"op":"mcm","clk":"1000085355","pt":1580606533908,"mc":[{"id":"1.168119364","rc":[{"trd":[[2.5,28.99]],"batl":[[0,2.5,245.7]],"ltp":2.5,"tv":101.95,"id":23010367},{"trd":[[1.66,43.66],[1.74,2.96],[1.93,7.35]],"batb":[[0,1.64,31.05],[1,1.5,37.86],[2,1.02,1.01]],"ltp":1.66,"tv":82.38,"id":27652444}],"tv":184.34}]}
{"op":"mcm","clk":"1000085522","pt":1580606539634,"mc":[{"id":"1.168119364","rc":[{"batb":[[0,1.71,31.05],[1,1.64,31.05],[2,1.5,37.86]],"ltp":1.66,"tv":82.38,"id":27652444}]}]}
{"op":"mcm","clk":"1000085536","pt":1580606540102,"mc":[{"id":"1.168119364","rc":[{"batl":[[0,1000,0.02],[1,1000,0]],"ltp":1.66,"tv":82.38,"id":27652444}]}]}
{"op":"mcm","clk":"1000085608","pt":1580606541649,"mc":[{"id":"1.168119364","rc":[{"trd":[[2.42,0.21]],"ltp":2.42,"tv":102.16,"id":23010367},{"trd":[[1.71,0.3]],"batb":[[0,1.71,30.75]],"ltp":1.71,"tv":82.68,"id":27652444}],"tv":184.84}]}
{"op":"mcm","clk":"1000086045","pt":1580606554345,"mc":[{"id":"1.168119364","rc":[{"trd":[[2.42,0.42]],"ltp":2.42,"tv":102.37,"id":23010367},{"trd":[[1.71,0.59]],"batb":[[0,1.71,30.46]],"ltp":1.71,"tv":82.97,"id":27652444}],"tv":185.35}]}
{"op":"mcm","clk":"1000086560","pt":1580606569670,"mc":[{"id":"1.168119364","rc":[{"batl":[[0,1.88,1602.8],[1,2.5,245.7],[2,1000,0.02]],"ltp":2.42,"tv":102.37,"id":23010367}]}]}
{"op":"mcm","clk":"1000086565","pt":1580606569875,"mc":[{"id":"1.168119364","rc":[{"batl":[[0,2.5,245.7],[1,1000,0.02],[2,1000,0]],"ltp":2.42,"tv":102.37,"id":23010367}]}]}
{"op":"mcm","clk":"1000087887","pt":1580606609808,"mc":[{"id":"1.168119364","rc":[{"batl":[[0,1000,0.54]],"ltp":1.71,"tv":82.97,"id":27652444}]}]}
{"op":"mcm","clk":"1000088834","pt":1580606639791,"mc":[{"id":"1.168119364","rc":[{"batb":[[1,1.4,45.43],[2,1.31,60.58]],"batl":[[0,1000,0.02],[1,1000,0]],"ltp":2.42,"tv":102.37,"id":23010367}]}]}
{"op":"mcm","clk":"1000088866","pt":1580606640980,"mc":[{"id":"1.168119364","rc":[{"trd":[[2.06,0.49]],"ltp":2.06,"tv":102.86,"id":23010367},{"trd":[[1.93,7.87]],"batl":[[0,1000,0.02]],"ltp":1.93,"tv":83.5,"id":27652444}],"tv":186.36}]}
{"op":"mcm","clk":"1000088917","pt":1580606643459,"mc":[{"id":"1.168119364","rc":[{"batb":[[1,1.52,473.26],[2,1.4,45.43]],"batl":[[0,2.36,268.5],[1,1000,0.02]],"ltp":2.06,"tv":102.86,"id":23010367}]}]}
{"op":"mcm","clk":"1000089048","pt":1580606648591,"mc":[{"id":"1.168119364","rc":[{"batb":[[0,1.52,473.26],[1,1.4,45.43],[2,1.31,60.58]],"ltp":2.06,"tv":102.86,"id":23010367}]}]}
{"op":"mcm","clk":"1000089268","pt":1580606655914,"mc":[{"id":"1.168119364","rc":[{"batb":[[0,1.55,45.43],[1,1.52,473.26],[2,1.4,45.43]],"ltp":2.06,"tv":102.86,"id":23010367}]}]}
{"op":"mcm","clk":"1000089326","pt":1580606657876,"mc":[{"id":"1.168119364","rc":[{"batb":[[0,1.64,31.05],[1,1.5,37.86],[2,1.02,1.01]],"ltp":1.93,"tv":83.5,"id":27652444}]}]}
{"op":"mcm","clk":"1000089428","pt":1580606660976,"mc":[{"id":"1.168119364","rc":[{"batb":[[0,1.78,30.46],[1,1.64,31.05],[2,1.5,37.86]],"ltp":1.93,"tv":83.5,"id":27652444}]}]}
{"op":"mcm","clk":"1000089765","pt":1580606671598,"mc":[{"id":"1.168119364","rc":[{"batb":[[1,1.4,45.43],[2,1.31,60.58]],"ltp":2.06,"tv":102.86,"id":23010367},{"batl":[[0,2.02,1500.2],[1,2.14,6.71],[2,1000,0.02]],"ltp":1.93,"tv":83.5,"id":27652444}]}]}
{"op":"mcm","clk":"1000089769","pt":1580606671803,"mc":[{"id":"1.168119364","rc":[{"batl":[[0,1000,0.02],[1,2.14,0],[2,1000,0]],"ltp":1.93,"tv":83.5,"id":27652444}]}]}
{"op":"mcm","clk":"1000089829","pt":1580606674593,"mc":[{"id":"1.168119364","rc":[{"batb":[[0,1.58,462.21],[1,1.55,45.43],[2,1.4,45.43]],"ltp":2.06,"tv":102.86,"id":23010367}]}]}
{"op":"mcm","clk":"1000091409","pt":1580606720669,"mc":[{"id":"1.168119364","rc":[{"batb":[[0,1.55,45.43],[1,1.4,45.43],[2,1.31,60.58]],"batl":[[0,1000,0.02],[1,1000,0]],"ltp":2.06,"tv":102.86,"id":23010367},{"batb":[[0,1.64,31.05],[1,1.5,37.86],[2,1.02,1.01]],"batl":[[0,1.88,1605.4],[1,1.95,7.39],[2,1000,0.02]],"ltp":1.93,"tv":83.5,"id":27652444}]}]}
{"op":"mcm","clk":"1000091432","pt":1580606720978,"mc":[{"id":"1.168119364","rc":[{"batl":[[0,1000,0.02],[1,1.95,0],[2,1000,0]],"ltp":1.93,"tv":83.5,"id":27652444}]}]}
{"op":"mcm","clk":"1000091577","pt":1580606723813,"mc":[{"id":"1.168119364","rc":[{"batb":[[0,1.7,452.02],[1,1.55,45.43],[2,1.4,45.43]],"batl":[[0,2.82,205.5],[1,1000,0.02]],"ltp":2.06,"tv":102.86,"id":23010367}]}]}
{"op":"mcm","clk":"1000091978","pt":1580606735602,"mc":[{"id":"1.168119364","rc":[{"batl":[[0,2.34,31.05],[1,1000,0.02]],"ltp":1.93,"tv":83.5,"id":27652444}]}]}
{"op":"mcm","clk":"1000092069","pt":1580606738588,"mc":[{"id":"1.168119364","rc":[{"batb":[[2,1.02,1]],"ltp":2.06,"tv":102.86,"id":23010367}]}]}
{"op":"mcm","clk":"1000092439","pt":1580606749209,"mc":[{"id":"1.168119364","rc":[{"batl":[[0,2,142.53],[1,2.34,31.05],[2,1000,0.02]],"ltp":1.93,"tv":83.5,"id":27652444}]}]}
{"op":"mcm","clk":"1000094039","pt":1580606795302,"mc":[{"id":"1.168119364","rc":[{"batb":[[0,1.55,45.43],[1,1.02,1],[2,1.01,12.51]],"ltp":2.06,"tv":102.86,"id":23010367}]}]}
{"op":"mcm","clk":"1000094085","pt":1580606797003,"mc":[{"id":"1.168119364","rc":[{"batb":[[0,1.5,37.86],[1,1.02,1.01],[2,1.01,12.51]],"ltp":1.93,"tv":83.5,"id":27652444}]}]}
{"op":"mcm","clk":"1000094154","pt":1580606799062,"mc":[{"id":"1.168119364","rc":[{"batb":[[0,1.77,443.08],[1,1.55,45.43],[2,1.02,1]],"ltp":2.06,"tv":102.86,"id":23010367}]}]}
{"op":"mcm","clk":"1000094252","pt":1580606802069,"mc":[{"id":"1.168119364","rc":[{"batl":[[0,1.97,31.05],[1,2,142.53],[2,2.34,31.05]],"ltp":1.93,"tv":83.5,"id":27652444}]}]}
{"op":"mcm","clk":"1000096182","pt":1580606858344,"mc":[{"id":"1.168119364","rc":[{"batl":[[0,2,142.53],[1,2.34,31.05],[2,1000,0.02]],"ltp":1.93,"tv":83.5,"id":27652444}]}]}
{"op":"mcm","clk":"1000097182","pt":1580606884485,"mc":[{"id":"1.168119364","rc":[{"trd":[[2,7]],"ltp":2.0,"tv":109.86,"id":23010367},{"trd":[[2,7]],"batb":[[0,1.65,15.14],[1,1.5,37.86],[2,1.02,1.01]],"batl":[[0,2,135.53]],"ltp":2.0,"tv":90.5,"id":27652444}],"tv":200.36}]}
{"op":"mcm","clk":"1000097604","pt":1580606895443,"mc":[{"id":"1.168119364","rc":[{"batb":[[0,1.5,37.86],[1,1.02,1.01],[2,1.01,12.51]],"ltp":2.0,"tv":90.5,"id":27652444}]}]}
{"op":"mcm","clk":"1000097635","pt":1580606896113,"mc":[{"id":"1.168119364","rc":[{"batl":[[0,2.34,31.05],[1,1000,0.02],[2,1000,0]],"ltp":2.0,"tv":90.5,"id":27652444}]}]}
{"op":"mcm","clk":"1000097888","pt":1580606902227,"mc":[{"id":"1.168119364","rc":[{"batl":[[0,2.2,31.05],[1,2.34,31.05],[2,1000,0.02]],"ltp":2.0,"tv":90.5,"id":27652444}]}]}
{"op":"mcm","clk":"1000098175","pt":1580606909535,"mc":[{"id":"1.168119364","rc":[{"batb":[[0,1.58,31.05],[1,1.5,37.86],[2,1.02,1.01]],"ltp":2.0,"tv":90.5,"id":27652444}]}]}
{"op":"mcm","clk":"1000098326","pt":1580606913034,"mc":[{"id":"1.168119364","rc":[{"batl":[[0,2,135.1],[1,2.2,31.05],[2,2.34,31.05]],"ltp":2.0,"tv":90.5,"id":27652444}]}]}
{"op":"mcm","clk":"1000099210","pt":1580606937179,"mc":[{"id":"1.168119364","rc":[{"batl":[[0,2.2,31.05],[1,2.34,31.05],[2,1000,0.02]],"ltp":2.0,"tv":90.5,"id":27652444}]}]}
{"op":"mcm","clk":"1000100025","pt":1580606960804,"mc":[{"id":"1.168119364","rc":[{"batb":[[0,1.55,45.43],[1,1.02,1],[2,1.01,12.51]],"batl":[[0,1000,0.02],[1,1000,0]],"ltp":2.0,"tv":109.86,"id":23010367}]}]}
{"op":"mcm","clk":"1000100149","pt":1580606964689,"mc":[{"id":"1.168119364","rc":[{"batb":[[0,1.62,460.25],[1,1.55,45.43],[2,1.02,1]],"batl":[[0,2.6,229.75],[1,1000,0.02]],"ltp":2.0,"tv":109.86,"id":23010367}]}]}
{"op":"mcm","clk":"1000101201","pt":1580606991838,"mc":[{"id":"1.168119364","rc":[{"batl":[[0,1000,0.02],[1,1000,0]],"ltp":2.0,"tv":109.86,"id":23010367}]}]}
{"op":"mcm","clk":"1000101357","pt":1580606995861,"mc":[{"id":"1.168119364","rc":[{"batl":[[0,2.5,245.5],[1,1000,0.02]],"ltp":2.0,"tv":109.86,"id":23010367}]}]}
{"op":"mcm","clk":"1000101832","pt":1580607008987,"mc":[{"id":"1.168119364","rc":[{"batb":[[0,1.55,45.43],[1,1.02,1],[2,1.01,12.51]],"ltp":2.0,"tv":109.86,"id":23010367}]}]}
{"op":"mcm","clk":"1000101951","pt":1580607012709,"mc":[{"id":"1.168119364","rc":[{"batb":[[0,1.67,453.11],[1,1.55,45.43],[2,1.02,1]],"ltp":2.0,"tv":109.86,"id":23010367}]}]}
{"op":"mcm","clk":"1000102455","pt":1580607029518,"mc":[{"id":"1.168119364","rc":[{"batb":[[0,1.69,45.43],[1,1.58,31.05],[2,1.5,37.86]],"ltp":2.0,"tv":90.5,"id":27652444}]}]}
{"op":"mcm","clk":"1000102574","pt":1580607033012,"mc":[{"id":"1.168119364","rc":[{"batl":[[0,1000,0.02],[1,1000,0]],"ltp":2.0,"tv":109.86,"id":23010367}]}]}
{"op":"mcm","clk":"1000102723","pt":1580607037405,"mc":[{"id":"1.168119364","rc":[{"batl":[[0,2.82,205.5],[1,1000,0.02]],"ltp":2.0,"tv":109.86,"id":23010367},{"batb":[[0,1.58,31.05],[1,1.5,37.86],[2,1.02,1.01]],"ltp":2.0,"tv":90.5,"id":27652444}]}]}
{"op":"mcm","clk":"1000103685","pt":1580607060063,"mc":[{"id":"1.168119364","rc":[{"trd":[[1.58,62.09]],"batb":[[0,1.5,37.86],[1,1.02,1.01],[2,1.01,12.51]],"batl":[[0,1.58,104.06],[1,2.2,31.05],[2,2.34,31.05]],"ltp":1.58,"tv":152.59,"id":27652444}],"tv":262.45}]}
{"op":"mcm","clk":"1000103799","pt":1580607063149,"mc":[{"id":"1.168119364","rc":[{"trd":[[1.58,270.2]],"batl":[[0,2.2,31.05],[1,2.34,31.05],[2,1000,0.02]],"ltp":1.58,"tv":360.7,"id":27652444}],"tv":470.56}]}
{"op":"mcm","clk":"1000103927","pt":1580607066244,"mc":[{"id":"1.168119364","rc":[{"batb":[[0,1.61,45.43],[1,1.5,37.86],[2,1.02,1.01]],"ltp":1.58,"tv":360.7,"id":27652444}]}]}
{"op":"mcm","clk":"1000103966","pt":1580607067068,"mc":[{"id":"1.168119364","rc":[{"batb":[[0,1.61,90.87]],"ltp":1.58,"tv":360.7,"id":27652444}]}]}
{"op":"mcm","clk":"1000104083","pt":1580607069970,"mc":[{"id":"1.168119364","rc":[{"batb":[[0,1.5,37.86],[1,1.02,1.01],[2,1.01,12.51]],"ltp":1.58,"tv":360.7,"id":27652444}]}]}
{"op":"mcm","clk":"1000104225","pt":1580607073963,"mc":[{"id":"1.168119364","rc":[{"batb":[[0,1.59,45.43],[1,1.5,37.86],[2,1.02,1.01]],"ltp":1.58,"tv":360.7,"id":27652444}]}]}
{"op":"mcm","clk":"1000104445","pt":1580607079768,"mc":[{"id":"1.168119364","rc":[{"batl":[[0,1.8,27.25],[1,2.2,31.05],[2,2.34,31.05]],"ltp":1.58,"tv":360.7,"id":27652444}]}]}
{"op":"mcm","clk":"1000106673","pt":1580607135355,"mc":[{"id":"1.168119364","rc":[{"batb":[[0,1.55,45.43],[1,1.02,1],[2,1.01,12.51]],"ltp":2.0,"tv":109.86,"id":23010367}]}]}
{"op":"mcm","clk":"1000106817","pt":1580607139551,"mc":[{"id":"1.168119364","rc":[{"batb":[[0,1.74,445.82],[1,1.55,45.43],[2,1.02,1]],"ltp":2.0,"tv":109.86,"id":23010367}]}]}
{"op":"mcm","clk":"1000106907","pt":1580607141875,"mc":[{"id":"1.168119364","rc":[{"batb":[[0,1.5,37.86],[1,1.02,1.01],[2,1.01,12.51]],"ltp":1.58,"tv":360.7,"id":27652444}]}]}
{"op":"mcm","clk":"1000107025","pt":1580607144972,"mc":[{"id":"1.168119364","rc":[{"batb":[[0,1.57,45.43],[1,1.5,37.86],[2,1.02,1.01]],"ltp":1.58,"tv":360.7,"id":27652444}]}]}
{"op":"mcm","clk":"1000112759","pt":1580607273785,"mc":[{"id":"1.168119364","rc":[{"batb":[[0,1.55,45.43],[1,1.02,1],[2,1.01,12.51]],"batl":[[0,1000,0.02],[1,1000,0]],"ltp":2.0,"tv":109.86,"id":23010367}]}]}
{"op":"mcm","clk":"1000112881","pt":1580607276354,"mc":[{"id":"1.168119364","rc":[{"batb":[[0,1.5,37.86],[1,1.02,1.01],[2,1.01,12.51]],"ltp":1.58,"tv":360.7,"id":27652444}]}]}
{"op":"mcm","clk":"1000112937","pt":1580607277653,"mc":[{"id":"1.168119364","rc":[{"batb":[[0,1.02,1.01],[1,1.01,12.51],[2,1.01,0]],"ltp":1.58,"tv":360.7,"id":27652444}]}]}
{"op":"mcm","clk":"1000112980","pt":1580607278441,"mc":[{"id":"1.168119364","rc":[{"batb":[[0,1.86,437.5],[1,1.55,45.43],[2,1.02,1]],"batl":[[0,3.3,169.63],[1,1000,0.02]],"ltp":2.0,"tv":109.86,"id":23010367},{"batl":[[0,1.54,31.86],[1,1.8,27.25],[2,2.2,31.05]],"ltp":1.58,"tv":360.7,"id":27652444}]}]}
{"op":"mcm","clk":"1000113107","pt":1580607281074,"mc":[{"id":"1.168119364","rc":[{"batl":[[0,1.8,27.25],[1,2.2,31.05],[2,2.34,31.05]],"ltp":1.58,"tv":360.7,"id":27652444}]}]}
{"op":"mcm","clk":"1000113402","pt":1580607287703,"mc":[{"id":"1.168119364","rc":[{"batl":[[0,1.77,16.89],[1,1.8,27.25],[2,2.2,31.05]],"ltp":1.58,"tv":360.7,"id":27652444}]}]}
{"op":"mcm","clk":"1000113407","pt":1580607287807,"mc":[{"id":"1.168119364","rc":[{"batl":[[0,1.8,27.25],[1,2.2,31.05],[2,2.34,31.05]],"ltp":1.58,"tv":360.7,"id":27652444}]}]}
{"op":"mcm","clk":"1000114191","pt":1580607305382,"mc":[{"id":"1.168119364","rc":[{"batl":[[0,1000,0.02],[1,1000,0]],"ltp":2.0,"tv":109.86,"id":23010367},{"batl":[[0,1.59,30.85],[1,1.8,27.25],[2,2.2,31.05]],"ltp":1.58,"tv":360.7,"id":27652444}]}]}
{"op":"mcm","clk":"1000114344","pt":1580607309014,"mc":[{"id":"1.168119364","rc":[{"batl":[[0,3,189.19],[1,1000,0.02]],"ltp":2.0,"tv":109.86,"id":23010367},{"trd":[[1.59,61.44]],"batl":[[0,1.8,27.38],[1,2.2,31.05],[2,2.34,31.05]],"ltp":1.59,"tv":422.14,"id":27652444}],"tv":532.0}]}
{"op":"mcm","clk":"1000114441","pt":1580607311636,"mc":[{"id":"1.168119364","rc":[{"batb":[[0,1.24,321.78],[1,1.02,1],[2,1.01,12.51]],"ltp":1.59,"tv":422.14,"id":27652444}]}]}
{"op":"mcm","clk":"1000114447","pt":1580607311797,"mc":[{"id":"1.168119364","rc":[{"batb":[[0,1.02,1.01],[1,1.01,12.51],[2,1.01,0]],"ltp":1.59,"tv":422.14,"id":27652444}]}]}
{"op":"mcm","clk":"1000114515","pt":1580607313810,"mc":[{"id":"1.168119364","rc":[{"batl":[[0,1.8,27.25]],"ltp":1.59,"tv":422.14,"id":27652444}]}]}
{"op":"mcm","clk":"1000115026","pt":1580607325528,"mc":[{"id":"1.168119364","rc":[{"batb":[[1,1.02,1],[2,1.01,12.51]],"ltp":2.0,"tv":109.86,"id":23010367}]}]}
{"op":"mcm","clk":"1000115734","pt":1580607341951,"mc":[{"id":"1.168119364","rc":[{"batl":[[0,1000,0.02],[1,1000,0]],"ltp":2.0,"tv":109.86,"id":23010367}]}]}
{"op":"mcm","clk":"1000115868","pt":1580607345138,"mc":[{"id":"1.168119364","rc":[{"batl":[[0,3.45,159.23],[1,1000,0.02]],"ltp":2.0,"tv":109.86,"id":23010367}]}]}
{"op":"mcm","clk":"1000116719","pt":1580607366189,"mc":[{"id":"1.168119364","rc":[{"batb":[[0,1.41,45.44],[1,1.02,1],[2,1.01,12.51]],"ltp":1.59,"tv":422.14,"id":27652444}]}]}
{"op":"mcm","clk":"1000116806","pt":1580607367693,"mc":[{"id":"1.168119364","rc":[{"batb":[[0,1.02,1.01],[1,1.01,12.51],[2,1.01,0]],"ltp":1.59,"tv":422.14,"id":27652444}]}]}
{"op":"mcm","clk":"1000116824","pt":1580607368058,"mc":[{"id":"1.168119364","rc":[{"batb":[[0,1.02,1],[1,1.01,12.51],[2,1.01,0]],"batl":[[0,1000,0.02],[1,1000,0]],"ltp":2.0,"tv":109.86,"id":23010367}]}]}
{"op":"mcm","clk":"1000116962","pt":1580607371571,"mc":[{"id":"1.168119364","rc":[{"batb":[[0,2.22,416.92],[1,1.02,1],[2,1.01,12.51]],"batl":[[0,4.6,119.8],[1,1000,0.02]],"ltp":2.0,"tv":109.86,"id":23010367}]}]}
{"op":"mcm","clk":"1000117026","pt":1580607373682,"mc":[{"id":"1.168119364","rc":[{"batb":[[0,1.3,45.44],[1,1.02,1],[2,1.01,12.51]],"ltp":1.59,"tv":422.14,"id":27652444}]}]}
{"op":"mcm","clk":"1000117120","pt":1580607376004,"mc":[{"id":"1.168119364","rc":[{"batl":[[2,1000,0.02]],"ltp":1.59,"tv":422.14,"id":27652444}]}]}
{"op":"mcm","clk":"1000117154","pt":1580607376784,"mc":[{"id":"1.168119364","rc":[{"batl":[[1,1000,0.02],[2,1000,0]],"ltp":1.59,"tv":422.14,"id":27652444}]}]}
{"op":"mcm","clk":"1000117542","pt":1580607385113,"mc":[{"id":"1.168119364","rc":[{"batl":[[0,1.6,53.76],[1,1.8,27.25],[2,1000,0.02]],"ltp":1.59,"tv":422.14,"id":27652444}]}]}
{"op":"mcm","clk":"1000118554","pt":1580607409245,"mc":[{"id":"1.168119364","rc":[{"batl":[[0,1000,0.02],[1,1000,0]],"ltp":2.0,"tv":109.86,"id":23010367}]}]}
{"op":"mcm","clk":"1000118682","pt":1580607412544,"mc":[{"id":"1.168119364","rc":[{"batl":[[0,3.9,139.42],[1,1000,0.02]],"ltp":2.0,"tv":109.86,"id":23010367}]}]}
{"op":"mcm","clk":"1000119846","pt":1580607443285,"mc":[{"id":"1.168119364","rc":[{"batb":[[0,1.02,1],[1,1.01,12.51],[2,1.01,0]],"batl":[[0,1000,0.02],[1,1000,0]],"ltp":2.0,"tv":109.86,"id":23010367}]}]}
{"op":"mcm","clk":"1000120001","pt":1580607446991,"mc":[{"id":"1.168119364","rc":[{"batb":[[0,1.92,432.48],[1,1.02,1],[2,1.01,12.51]],"batl":[[0,3.45,159.24],[1,1000,0.02]],"ltp":2.0,"tv":109.86,"id":23010367}]}]}
{"op":"mcm","clk":"1000120128","pt":1580607450185,"mc":[{"id":"1.168119364","rc":[{"batl":[[0,1.8,27.25],[1,1000,0.02],[2,1000,0]],"ltp":1.59,"tv":422.14,"id":27652444}]}]}
{"op":"mcm","clk":"1000120591","pt":1580607461789,"mc":[{"id":"1.168119364","rc":[{"batl":[[0,1.73,37.86],[1,1.8,27.25],[2,1000,0.02]],"ltp":1.59,"tv":422.14,"id":27652444}]}]}
{"op":"mcm","clk":"1000121280","pt":1580607479340,"mc":[{"id":"1.168119364","rc":[{"batl":[[0,1000,0.02],[1,1000,0]],"ltp":2.0,"tv":109.86,"id":23010367}]}]}
{"op":"mcm","clk":"1000121331","pt":1580607480321,"mc":[{"id":"1.168119364","rc":[{"batl":[[0,1.8,27.25],[1,1000,0.02],[2,1000,0]],"ltp":1.59,"tv":422.14,"id":27652444}]}]}
{"op":"mcm","clk":"1000121357","pt":1580607481037,"mc":[{"id":"1.168119364","rc":[{"batl":[[0,1000,0.02],[1,1000,0]],"ltp":1.59,"tv":422.14,"id":27652444}]}]}
{"op":"mcm","clk":"1000121442","pt":1580607483317,"mc":[{"id":"1.168119364","rc":[{"batl":[[0,3.15,177.33],[1,1000,0.02]],"ltp":2.0,"tv":109.86,"id":23010367}]}]}
{"op":"mcm","clk":"1000121539","pt":1580607486260,"mc":[{"id":"1.168119364","rc":[{"batl":[[0,1.98,37.86],[1,1000,0.02]],"ltp":1.59,"tv":422.14,"id":27652444}]}]}
{"op":"mcm","clk":"1000121613","pt":1580607488234,"mc":[{"id":"1.168119364","rc":[{"batb":[[0,1.59,37.86],[1,1.3,45.44],[2,1.02,1]],"ltp":1.59,"tv":422.14,"id":27652444}]}]}
{"op":"mcm","clk":"1000121875","pt":1580607495961,"mc":[{"id":"1.168119364","rc":[{"trd":[[1.59,98.44]],"batb":[[0,1.59,19.36]],"ltp":1.59,"tv":459.14,"id":27652444}],"tv":569.0}]}
{"op":"mcm","clk":"1000122026","pt":1580607499932,"mc":[{"id":"1.168119364","rc":[{"trd":[[1.59,131.78]],"batb":[[0,1.59,2.7]],"ltp":1.59,"tv":492.47,"id":27652444}],"tv":602.34}]}
{"op":"mcm","clk":"1000122223","pt":1580607505445,"mc":[{"id":"1.168119364","rc":[{"batb":[[0,1.02,1],[1,1.01,12.51],[2,1.01,0]],"batl":[[0,1000,0.02],[1,1000,0]],"ltp":2.0,"tv":109.86,"id":23010367},{"batb":[[0,1.59,40.56]],"ltp":1.59,"tv":492.47,"id":27652444}]}]}
{"op":"mcm","clk":"1000122367","pt":1580607509466,"mc":[{"id":"1.168119364","rc":[{"batb":[[0,1.77,443.07],[1,1.02,1],[2,1.01,12.51]],"batl":[[0,3,189.2],[1,1000,0.02]],"ltp":2.0,"tv":109.86,"id":23010367}]}]}
{"op":"mcm","clk":"1000122693","pt":1580607518591,"mc":[{"id":"1.168119364","rc":[{"batl":[[0,1000,0.02],[1,1000,0]],"ltp":2.0,"tv":109.86,"id":23010367}]}]}
{"op":"mcm","clk":"1000122846","pt":1580607522572,"mc":[{"id":"1.168119364","rc":[{"batl":[[0,2.82,205.51],[1,1000,0.02]],"ltp":2.0,"tv":109.86,"id":23010367}]}]}
{"op":"mcm","clk":"1000123515","pt":1580607539921,"mc":[{"id":"1.168119364","rc":[{"batl":[[0,1.75,32.07],[1,1.98,37.86],[2,1000,0.02]],"ltp":1.59,"tv":492.47,"id":27652444}]}]}
{"op":"mcm","clk":"1000124078","pt":1580607556932,"mc":[{"id":"1.168119364","rc":[{"trd":[[1.75,63.66]],"batl":[[0,1.98,38.1],[1,1000,0.02],[2,1000,0]],"ltp":1.75,"tv":556.13,"id":27652444}],"tv":665.99}]}
{"op":"mcm","clk":"1000126149","pt":1580607609686,"mc":[{"id":"1.168119364","rc":[{"batl":[[0,1000,0.02],[1,1000,0]],"ltp":2.0,"tv":109.86,"id":23010367},{"batb":[[0,1.3,45.44],[1,1.02,1],[2,1.01,12.51]],"ltp":1.75,"tv":556.13,"id":27652444}]}]}
{"op":"mcm","clk":"1000126240","pt":1580607612263,"mc":[{"id":"1.168119364","rc":[{"batl":[[0,3.15,177.33],[1,1000,0.02]],"ltp":2.0,"tv":109.86,"id":23010367}]}]}
{"op":"mcm","clk":"1000126551","pt":1580607621016,"mc":[{"id":"1.168119364","rc":[{"batl":[[1,1.99,1.2],[2,1000,0.02]],"ltp":1.75,"tv":556.13,"id":27652444}]}]}
{"op":"mcm","clk":"1000127266","pt":1580607642315,"mc":[{"id":"1.168119364","rc":[{"batb":[[0,1.02,1],[1,1.01,12.51],[2,1.01,0]],"batl":[[0,1000,0.02],[1,1000,0]],"ltp":2.0,"tv":109.86,"id":23010367}]}]}
{"op":"mcm","clk":"1000127390","pt":1580607645554,"mc":[{"id":"1.168119364","rc":[{"batb":[[0,1.97,431.57],[1,1.02,1],[2,1.01,12.51]],"batl":[[0,3.65,150.28],[1,1000,0.02]],"ltp":2.0,"tv":109.86,"id":23010367}]}]}
{"op":"mcm","clk":"1000127894","pt":1580607659865,"mc":[{"id":"1.168119364","rc":[{"batb":[[0,1.4,31.06],[1,1.3,45.43],[2,1.02,1]],"ltp":1.75,"tv":556.13,"id":27652444}]}]}
{"op":"mcm","clk":"1000129060","pt":1580607679557,"mc":[{"id":"1.168119364","rc":[{"batb":[[0,1.3,45.44],[1,1.02,1],[2,1.01,12.51]],"ltp":1.75,"tv":556.13,"id":27652444}]}]}
{"op":"mcm","clk":"1000129137","pt":1580607681567,"mc":[{"id":"1.168119364","rc":[{"batb":[[0,1.02,1],[1,1.01,12.51],[2,1.01,0]],"batl":[[0,1000,0.02],[1,1000,0]],"ltp":2.0,"tv":109.86,"id":23010367},{"trd":[[1.48,0.02]],"batb":[[0,1.3,45.43]],"ltp":1.48,"tv":556.15,"id":27652444}],"tv":666.01}]}
{"op":"mcm","clk":"1000129252","pt":1580607684965,"mc":[{"id":"1.168119364","rc":[{"batb":[[0,2.12,422.66],[1,1.02,1],[2,1.01,12.51]],"batl":[[0,4.2,130.36],[1,1000,0.02]],"ltp":2.0,"tv":109.86,"id":23010367},{"batl":[[0,1.6,31.05],[1,1.98,38.1],[2,1.99,1.2]],"ltp":1.48,"tv":556.15,"id":27652444}]}]}
{"op":"mcm","clk":"1000129474","pt":1580607691200,"mc":[{"id":"1.168119364","rc":[{"batb":[[0,1.33,31.05],[1,1.3,45.43],[2,1.02,1]],"ltp":1.48,"tv":556.15,"id":27652444}]}]}
{"op":"mcm","clk":"1000129837","pt":1580607700826,"mc":[{"id":"1.168119364","rc":[{"trd":[[1.33,62.09]],"batb":[[0,1.3,45.43],[1,1.02,1],[2,1.01,12.51]],"batl":[[0,1.33,42.89],[1,1.6,31.05],[2,1.98,38.1]],"ltp":1.33,"tv":618.24,"id":27652444}],"tv":728.1}]}
{"op":"mcm","clk":"1000129947","pt":1580607703912,"mc":[{"id":"1.168119364","rc":[{"trd":[[1.33,147.87]],"batl":[[0,1.6,31.05],[1,1.98,38.1],[2,1.99,1.2]],"ltp":1.33,"tv":704.02,"id":27652444}],"tv":813.89}]}
{"op":"mcm","clk":"1000130334","pt":1580607713941,"mc":[{"id":"1.168119364","rc":[{"batl":[[0,1.41,29.59],[1,1.6,31.05],[2,1.98,38.1]],"ltp":1.33,"tv":704.02,"id":27652444}]}]}
{"op":"mcm","clk":"1000130529","pt":1580607718738,"mc":[{"id":"1.168119364","rc":[{"trd":[[3.4,12.27]],"batl":[[0,3.05,92.77],[1,4,64.17],[2,1000,0.02]],"ltp":3.4,"tv":122.13,"id":23010367},{"trd":[[1.41,29.59]],"batl":[[0,1.6,31.05],[1,1.98,38.1],[2,1.99,1.2]],"ltp":1.41,"tv":733.61,"id":27652444}],"tv":855.74}]}
{"op":"mcm","clk":"1000130542","pt":1580607719048,"mc":[{"id":"1.168119364","rc":[{"batl":[[0,4,64.17],[1,1000,0.02],[2,1000,0]],"ltp":3.4,"tv":122.13,"id":23010367}]}]}
{"op":"mcm","clk":"1000130665","pt":1580607722152,"mc":[{"id":"1.168119364","rc":[{"batl":[[0,3.9,139.42],[1,4,64.17],[2,1000,0.02]],"ltp":3.4,"tv":122.13,"id":23010367}]}]}
{"op":"mcm","clk":"1000131529","pt":1580607743279,"mc":[{"id":"1.168119364","rc":[{"batl":[[0,4,64.17],[1,1000,0.02],[2,1000,0]],"ltp":3.4,"tv":122.13,"id":23010367}]}]}
{"op":"mcm","clk":"1000131713","pt":1580607747360,"mc":[{"id":"1.168119364","rc":[{"batl":[[0,3.65,150.28],[1,4,64.17],[2,1000,0.02]],"ltp":3.4,"tv":122.13,"id":23010367}]}]}
{"op":"mcm","clk":"1000132520","pt":1580607766071,"mc":[{"id":"1.168119364","rc":[{"batl":[[1,1000,0.02],[2,1000,0]],"ltp":3.4,"tv":122.13,"id":23010367}]}]}
{"op":"mcm","clk":"1000133006","pt":1580607780419,"mc":[{"id":"1.168119364","rc":[{"batl":[[0,1.98,38.1],[1,1.99,1.2],[2,1000,0.02]],"ltp":1.41,"tv":733.61,"id":27652444}]}]}
{"op":"mcm","clk":"1000133270","pt":1580607788510,"mc":[{"id":"1.168119364","rc":[{"batl":[[0,1.7,31.05],[1,1.98,38.1],[2,1.99,1.2]],"ltp":1.41,"tv":733.61,"id":27652444}]}]}
{"op":"mcm","clk":"1000134035","pt":1580607809418,"mc":[{"id":"1.168119364","rc":[{"batl":[[0,1000,0.02],[1,1000,0]],"ltp":3.4,"tv":122.13,"id":23010367}]}]}
{"op":"mcm","clk":"1000134162","pt":1580607812622,"mc":[{"id":"1.168119364","rc":[{"batb":[[0,1.02,1],[1,1.01,12.51],[2,1.01,0]],"ltp":1.41,"tv":733.61,"id":27652444}]}]}
{"op":"mcm","clk":"1000134173","pt":1580607812832,"mc":[{"id":"1.168119364","rc":[{"batl":[[0,4.6,119.81],[1,1000,0.02]],"ltp":3.4,"tv":122.13,"id":23010367}]}]}
{"op":"mcm","clk":"1000134374","pt":1580607818237,"mc":[{"id":"1.168119364","rc":[{"batb":[[0,1.27,31.05],[1,1.02,1],[2,1.01,12.51]],"ltp":1.41,"tv":733.61,"id":27652444}]}]}
{"op":"mcm","clk":"1000135176","pt":1580607843062,"mc":[{"id":"1.168119364","rc":[{"batl":[[0,1.5,45.43],[1,1.7,31.05],[2,1.98,38.1]],"ltp":1.41,"tv":733.61,"id":27652444}]}]}
{"op":"mcm","clk":"1000135216","pt":1580607844091,"mc":[{"id":"1.168119364","rc":[{"batl":[[0,4.4,58.77],[1,4.6,119.81],[2,1000,0.02]],"ltp":3.4,"tv":122.13,"id":23010367}]}]}
{"op":"mcm","clk":"1000135879","pt":1580607860611,"mc":[{"id":"1.168119364","rc":[{"batl":[[1,1000,0.02],[2,1000,0]],"ltp":3.4,"tv":122.13,"id":23010367}]}]}
{"op":"mcm","clk":"1000136014","pt":1580607864333,"mc":[{"id":"1.168119364","rc":[{"batl":[[0,4.2,130.36],[1,4.4,58.77],[2,1000,0.02]],"ltp":3.4,"tv":122.13,"id":23010367}]}]}
{"op":"mcm","clk":"1000136321","pt":1580607871997,"mc":[{"id":"1.168119364","rc":[{"batl":[[1,1000,0.02],[2,1000,0]],"ltp":3.4,"tv":122.13,"id":23010367}]}]}
{"op":"mcm","clk":"1000136414","pt":1580607874419,"mc":[{"id":"1.168119364","rc":[{"batl":[[0,1.7,31.05],[1,1.98,38.1],[2,1.99,1.2]],"ltp":1.41,"tv":733.61,"id":27652444}]}]}
{"op":"mcm","clk":"1000136427","pt":1580607874829,"mc":[{"id":"1.168119364","rc":[{"batl":[[0,3,10],[1,4.2,130.36],[2,1000,0.02]],"ltp":3.4,"tv":122.13,"id":23010367}]}]}
{"op":"mcm","clk":"1000136539","pt":1580607877519,"mc":[{"id":"1.168119364","rc":[{"batl":[[0,1.56,45.43],[1,1.7,31.05],[2,1.98,38.1]],"ltp":1.41,"tv":733.61,"id":27652444}]}]}
{"op":"mcm","clk":"1000136634","pt":1580607880046,"mc":[{"id":"1.168119364","rc":[{"trd":[[3,10]],"batl":[[0,4.2,130.36],[1,1000,0.02],[2,1000,0]],"ltp":3.0,"tv":132.13,"id":23010367},{"trd":[[1.5,20]],"batl":[[0,1.5,25.44],[1,1.56,45.43],[2,1.7,31.05]],"ltp":1.5,"tv":753.61,"id":27652444}],"tv":885.74}]}
{"op":"mcm","clk":"1000136969","pt":1580607890156,"mc":[{"id":"1.168119364","rc":[{"batb":[[0,1.34,22.38],[1,1.27,31.05],[2,1.02,1]],"ltp":1.5,"tv":753.61,"id":27652444}]}]}
{"op":"mcm","clk":"1000137065","pt":1580607892845,"mc":[{"id":"1.168119364","rc":[{"batl":[[0,1.56,45.43],[1,1.7,31.05],[2,1.98,38.1]],"ltp":1.5,"tv":753.61,"id":27652444}]}]}
{"op":"mcm","clk":"1000137316","pt":1580607898623,"mc":[{"id":"1.168119364","rc":[{"batl":[[0,1000,0.02],[1,1000,0]],"ltp":3.0,"tv":132.13,"id":23010367}]}]}
{"op":"mcm","clk":"1000137493","pt":1580607902553,"mc":[{"id":"1.168119364","rc":[{"batl":[[0,3.9,139.42],[1,1000,0.02]],"ltp":3.0,"tv":132.13,"id":23010367}]}]}
{"op":"mcm","clk":"1000137674","pt":1580607906636,"mc":[{"id":"1.168119364","rc":[{"batl":[[0,1000,0.02],[1,1000,0]],"ltp":3.0,"tv":132.13,"id":23010367},{"batl":[[0,1.7,31.05],[1,1.98,38.1],[2,1.99,1.2]],"ltp":1.5,"tv":753.61,"id":27652444}]}]}
{"op":"mcm","clk":"1000137850","pt":1580607910656,"mc":[{"id":"1.168119364","rc":[{"batl":[[0,3.65,150.28],[1,1000,0.02]],"ltp":3.0,"tv":132.13,"id":23010367}]}]}
{"op":"mcm","clk":"1000138173","pt":1580607918553,"mc":[{"id":"1.168119364","rc":[{"batb":[[0,1.41,21.27],[1,1.34,22.38],[2,1.27,31.05]],"ltp":1.5,"tv":753.61,"id":27652444}]}]}
{"op":"mcm","clk":"1000138562","pt":1580607929385,"mc":[{"id":"1.168119364","rc":[{"batb":[[0,2.52,5],[1,2.12,422.66],[2,1.02,1]],"ltp":3.0,"tv":132.13,"id":23010367}]}]}
{"op":"mcm","clk":"1000138579","pt":1580607929797,"mc":[{"id":"1.168119364","rc":[{"batb":[[1,1.02,1],[2,1.01,12.51]],"batl":[[0,1000,0.02],[1,1000,0]],"ltp":3.0,"tv":132.13,"id":23010367},{"batl":[[0,1.98,38.1],[1,1.99,1.2],[2,1000,0.02]],"ltp":1.5,"tv":753.61,"id":27652444}]}]}
{"op":"mcm","clk":"1000138647","pt":1580607931661,"mc":[{"id":"1.168119364","rc":[{"batb":[[0,1.02,1],[1,1.01,12.51],[2,1.01,0]],"ltp":3.0,"tv":132.13,"id":23010367}]}]}
{"op":"mcm","clk":"1000138715","pt":1580607933679,"mc":[{"id":"1.168119364","rc":[{"batb":[[0,1.82,441],[1,1.02,1],[2,1.01,12.51]],"batl":[[0,3.15,177.33],[1,1000,0.02]],"ltp":3.0,"tv":132.13,"id":23010367}]}]}
{"op":"mcm","clk":"1000138973","pt":1580607940497,"mc":[{"id":"1.168119364","rc":[{"batb":[[0,1.53,19.6],[1,1.41,21.27],[2,1.34,22.38]],"ltp":1.5,"tv":753.61,"id":27652444}]}]}
{"op":"mcm","clk":"1000139264","pt":1580607947116,"mc":[{"id":"1.168119364","rc":[{"batb":[[0,2.08,5],[1,1.82,441],[2,1.02,1]],"ltp":3.0,"tv":132.13,"id":23010367}]}]}
{"op":"mcm","clk":"1000139496","pt":1580607952590,"mc":[{"id":"1.168119364","rc":[{"batb":[[0,1.82,441],[1,1.02,1],[2,1.01,12.51]],"ltp":3.0,"tv":132.13,"id":23010367}]}]}
{"op":"mcm","clk":"1000139679","pt":1580607957919,"mc":[{"id":"1.168119364","rc":[{"batl":[[0,1000,0.02],[1,1000,0]],"ltp":3.0,"tv":132.13,"id":23010367}]}]}
{"op":"mcm","clk":"1000139820","pt":1580607962009,"mc":[{"id":"1.168119364","rc":[{"batl":[[0,2.82,205.51],[1,1000,0.02]],"ltp":3.0,"tv":132.13,"id":23010367}]}]}
{"op":"mcm","clk":"1000140098","pt":1580607968437,"mc":[{"id":"1.168119364","rc":[{"batl":[[0,1.98,37.86]],"ltp":1.5,"tv":753.61,"id":27652444}]}]}
{"op":"mcm","clk":"1000140297","pt":1580607973138,"mc":[{"id":"1.168119364","rc":[{"batb":[[0,1.59,18.86],[1,1.53,19.6],[2,1.41,21.27]],"ltp":1.5,"tv":753.61,"id":27652444}]}]}
{"op":"mcm","clk":"1000140352","pt":1580607974431,"mc":[{"id":"1.168119364","rc":[{"batb":[[0,2.18,5],[1,1.82,441],[2,1.02,1]],"ltp":3.0,"tv":132.13,"id":23010367}]}]}
{"op":"mcm","clk":"1000140633","pt":1580607982352,"mc":[{"id":"1.168119364","rc":[{"batb":[[0,2.44,5],[1,2.18,5],[2,1.82,441]],"ltp":3.0,"tv":132.13,"id":23010367}]}]}
{"op":"mcm","clk":"1000140830","pt":1580607988459,"mc":[{"id":"1.168119364","rc":[{"batb":[[0,2.18,5],[1,1.82,441],[2,1.02,1]],"ltp":3.0,"tv":132.13,"id":23010367}]}]}
{"op":"mcm","clk":"1000140877","pt":1580607989855,"mc":[{"id":"1.168119364","rc":[{"batb":[[0,1.82,441],[1,1.02,1],[2,1.01,12.51]],"ltp":3.0,"tv":132.13,"id":23010367}]}]}
{"op":"mcm","clk":"1000141674","pt":1580608009678,"mc":[{"id":"1.168119364","rc":[{"batb":[[0,2.22,5],[1,1.82,441],[2,1.02,1]],"ltp":3.0,"tv":132.13,"id":23010367}]}]}
{"op":"mcm","clk":"1000142186","pt":1580608022101,"mc":[{"id":"1.168119364","rc":[{"batl":[[1,1000,0.02],[2,1000,0]],"ltp":1.5,"tv":753.61,"id":27652444}]}]}
{"op":"mcm","clk":"1000142247","pt":1580608023232,"mc":[{"id":"1.168119364","rc":[{"batb":[[0,1.82,441],[1,1.02,1],[2,1.01,12.51]],"ltp":3.0,"tv":132.13,"id":23010367}]}]}
{"op":"mcm","clk":"1000142519","pt":1580608028708,"mc":[{"id":"1.168119364","rc":[{"batl":[[0,1.97,4.16],[1,1.98,37.86],[2,1000,0.02]],"ltp":1.5,"tv":753.61,"id":27652444}]}]}
{"op":"mcm","clk":"1000142535","pt":1580608028918,"mc":[{"id":"1.168119364","rc":[{"batl":[[0,1.98,37.86],[1,1000,0.02],[2,1000,0]],"ltp":1.5,"tv":753.61,"id":27652444}]}]}
{"op":"mcm","clk":"1000142869","pt":1580608037155,"mc":[{"id":"1.168119364","rc":[{"batl":[[0,1000,0.02],[1,1000,0]],"ltp":3.0,"tv":132.13,"id":23010367}]}]}
{"op":"mcm","clk":"1000142992","pt":1580608040660,"mc":[{"id":"1.168119364","rc":[{"batl":[[0,3.15,177.33],[1,1000,0.02]],"ltp":3.0,"tv":132.13,"id":23010367}]}]}
{"op":"mcm","clk":"1000143237","pt":1580608047127,"mc":[{"id":"1.168119364","rc":[{"batl":[[0,1000,0.02],[1,1000,0]],"ltp":3.0,"tv":132.13,"id":23010367}]}]}
{"op":"mcm","clk":"1000143366","pt":1580608050732,"mc":[{"id":"1.168119364","rc":[{"batl":[[0,2.82,205.51],[1,1000,0.02]],"ltp":3.0,"tv":132.13,"id":23010367}]}]}
{"op":"mcm","clk":"1000144731","pt":1580608084819,"mc":[{"id":"1.168119364","rc":[{"batb":[[0,1.71,17.54],[1,1.59,18.86],[2,1.53,19.6]],"ltp":1.5,"tv":753.61,"id":27652444}]}]}
{"op":"mcm","clk":"1000145056","pt":1580608094327,"mc":[{"id":"1.168119364","rc":[{"batb":[[0,1.02,1],[1,1.01,12.51],[2,1.01,0]],"ltp":3.0,"tv":132.13,"id":23010367}]}]}
{"op":"mcm","clk":"1000145092","pt":1580608095513,"mc":[{"id":"1.168119364","rc":[{"batl":[[0,1000,0.02],[1,1000,0]],"ltp":1.5,"tv":753.61,"id":27652444}]}]}
{"op":"mcm","clk":"1000145177","pt":1580608098105,"mc":[{"id":"1.168119364","rc":[{"batb":[[0,1.67,453.09],[1,1.02,1],[2,1.01,12.51]],"ltp":3.0,"tv":132.13,"id":23010367}]}]}
{"op":"mcm","clk":"1000145669","pt":1580608112312,"mc":[{"id":"1.168119364","rc":[{"batb":[[0,1.88,15.95],[1,1.71,17.54],[2,1.59,18.86]],"ltp":1.5,"tv":753.61,"id":27652444}]}]}
{"op":"mcm","clk":"1000146016","pt":1580608123164,"mc":[{"id":"1.168119364","rc":[{"trd":[[1.88,31.9]],"batb":[[0,1.71,17.54],[1,1.59,18.86],[2,1.53,19.6]],"ltp":1.88,"tv":785.51,"id":27652444}],"tv":917.65}]}
{"op":"mcm","clk":"1000146049","pt":1580608124168,"mc":[{"id":"1.168119364","rc":[{"batb":[[0,1.7,45.43],[1,1.67,453.09],[2,1.02,1]],"ltp":3.0,"tv":132.13,"id":23010367}]}]}
{"op":"mcm","clk":"1000146235","pt":1580608129562,"mc":[{"id":"1.168119364","rc":[{"batb":[[0,1.74,13.79],[1,1.7,45.43],[2,1.67,453.09]],"ltp":3.0,"tv":132.13,"id":23010367}]}]}
{"op":"mcm","clk":"1000146244","pt":1580608129767,"mc":[{"id":"1.168119364","rc":[{"batb":[[0,1.7,45.43],[1,1.67,453.09],[2,1.02,1]],"ltp":3.0,"tv":132.13,"id":23010367}]}]}
{"op":"mcm","clk":"1000146432","pt":1580608134036,"mc":[{"id":"1.168119364","rc":[{"batl":[[0,2,1.2],[1,1000,0.02]],"ltp":1.88,"tv":785.51,"id":27652444}]}]}
{"op":"mcm","clk":"1000146861","pt":1580608144078,"mc":[{"id":"1.168119364","rc":[{"trd":[[1.7,4.53],[2,8.2]],"batb":[[0,1.7,43.17]],"ltp":1.7,"tv":137.86,"id":23010367},{"trd":[[2,8.2]],"batl":[[0,1000,0.02],[1,1000,0]],"ltp":2.0,"tv":786.71,"id":27652444}],"tv":924.57}]}
{"op":"mcm","clk":"1000146922","pt":1580608145470,"mc":[{"id":"1.168119364","rc":[{"batb":[[1,1.02,1],[2,1.01,15.54]],"ltp":1.7,"tv":137.86,"id":23010367}]}]}
{"op":"mcm","clk":"1000147089","pt":1580608149592,"mc":[{"id":"1.168119364","rc":[{"batb":[[0,1.74,441.98],[1,1.7,43.17],[2,1.02,1]],"ltp":1.7,"tv":137.86,"id":23010367}]}]}
{"op":"mcm","clk":"1000147164","pt":1580608151698,"mc":[{"id":"1.168119364","rc":[{"trd":[[1.74,0.29]],"batb":[[0,1.74,441.7]],"ltp":1.74,"tv":138.14,"id":23010367},{"trd":[[2.36,0.21]],"ltp":2.36,"tv":786.92,"id":27652444}],"tv":925.07}]}
{"op":"mcm","clk":"1000147364","pt":1580608155786,"mc":[{"id":"1.168119364","rc":[{"batb":[[0,1.76,45.43],[1,1.74,441.7],[2,1.7,43.17]],"ltp":1.74,"tv":138.14,"id":23010367}]}]}
{"op":"mcm","clk":"1000147667","pt":1580608162484,"mc":[{"id":"1.168119364","rc":[{"batb":[[1,1.7,43.17],[2,1.02,1]],"batl":[[0,1000,0.02],[1,1000,0]],"ltp":1.74,"tv":138.14,"id":23010367},{"batb":[[0,1.59,18.86],[1,1.53,19.6],[2,1.41,21.27]],"ltp":2.36,"tv":786.92,"id":27652444}]}]}
{"op":"mcm","clk":"1000147707","pt":1580608163714,"mc":[{"id":"1.168119364","rc":[{"batl":[[0,2.26,1.7],[1,1000,0.02]],"ltp":1.74,"tv":138.14,"id":23010367}]}]}
{"op":"mcm","clk":"1000147808","pt":1580608166608,"mc":[{"id":"1.168119364","rc":[{"batb":[[0,1.82,437.18],[1,1.76,45.43],[2,1.7,43.17]],"batl":[[1,3.15,179.97],[2,1000,0.02]],"ltp":1.74,"tv":138.14,"id":23010367}]}]}
{"op":"mcm","clk":"1000148091","pt":1580608172216,"mc":[{"id":"1.168119364","rc":[{"batb":[[0,1.53,19.6],[1,1.41,21.27],[2,1.34,22.38]],"ltp":2.36,"tv":786.92,"id":27652444}]}]}
{"op":"mcm","clk":"1000148468","pt":1580608180137,"mc":[{"id":"1.168119364","rc":[{"trd":[[2.26,1.7]],"batl":[[0,3.15,179.97],[1,1000,0.02],[2,1000,0]],"ltp":2.26,"tv":139.85,"id":23010367},{"trd":[[1.79,2.15]],"batl":[[0,1.59,81.03],[1,1000,0.02]],"ltp":1.79,"tv":789.07,"id":27652444}],"tv":928.93}]}
{"op":"mcm","clk":"1000148569","pt":1580608182613,"mc":[{"id":"1.168119364","rc":[{"batb":[[0,1.85,45.43],[1,1.82,437.18],[2,1.76,45.43]],"ltp":2.26,"tv":139.85,"id":23010367}]}]}
{"op":"mcm","clk":"1000148818","pt":1580608187512,"mc":[{"id":"1.168119364","rc":[{"trd":[[2.9,0.21]],"ltp":2.9,"tv":140.06,"id":23010367},{"trd":[[1.53,0.4]],"batb":[[0,1.53,19.2]],"batl":[[0,1000,0.02],[1,1000,0]],"ltp":1.53,"tv":789.48,"id":27652444}],"tv":929.54}]}
{"op":"mcm","clk":"1000148922","pt":1580608189934,"mc":[{"id":"1.168119364","rc":[{"trd":[[1.53,38.81]],"batb":[[0,1.41,21.27],[1,1.34,22.38],[2,1.27,31.05]],"batl":[[0,1.52,61.82],[1,1000,0.02]],"ltp":1.53,"tv":827.89,"id":27652444}],"tv":967.95}]}
{"op":"mcm","clk":"1000149157","pt":1580608194529,"mc":[{"id":"1.168119364","rc":[{"batb":[[1,1.76,45.43],[2,1.7,43.17]],"batl":[[0,1000,0.02],[1,1000,0]],"ltp":2.9,"tv":140.06,"id":23010367}]}]}
{"op":"mcm","clk":"1000149281","pt":1580608197160,"mc":[{"id":"1.168119364","rc":[{"batb":[[0,1.34,22.38],[1,1.27,31.05],[2,1.02,1]],"ltp":1.53,"tv":827.89,"id":27652444}]}]}
{"op":"mcm","clk":"1000149322","pt":1580608198139,"mc":[{"id":"1.168119364","rc":[{"batb":[[0,2.04,426.42],[1,1.85,45.43],[2,1.76,45.43]],"batl":[[0,3.9,141.67],[1,1000,0.02]],"ltp":2.9,"tv":140.06,"id":23010367},{"batl":[[0,1.46,20.54],[1,1.52,61.82],[2,1000,0.02]],"ltp":1.53,"tv":827.89,"id":27652444}]}]}
{"op":"mcm","clk":"1000149376","pt":1580608199636,"mc":[{"id":"1.168119364","rc":[{"batb":[[0,2.04,426.63]],"ltp":2.9,"tv":140.06,"id":23010367}]}]}
{"op":"mcm","clk":"1000149502","pt":1580608202446,"mc":[{"id":"1.168119364","rc":[{"batb":[[0,1.27,31.05],[1,1.02,1],[2,1.01,15.54]],"ltp":1.53,"tv":827.89,"id":27652444}]}]}
{"op":"mcm","clk":"1000150056","pt":1580608217582,"mc":[{"id":"1.168119364","rc":[{"batb":[[0,1.85,45.64],[1,1.76,45.43],[2,1.7,43.17]],"batl":[[0,1000,0.02],[1,1000,0]],"ltp":2.9,"tv":140.06,"id":23010367}]}]}
{"op":"mcm","clk":"1000150082","pt":1580608218158,"mc":[{"id":"1.168119364","rc":[{"trd":[[2.92,32.18],[3.15,9.52],[3.5,0.42]],"batb":[[0,1.85,45.43]],"ltp":2.92,"tv":182.18,"id":23010367},{"trd":[[1.46,20.54],[1.52,61.82]],"batl":[[0,1000,0.02],[1,1.52,0],[2,1000,0]],"ltp":1.52,"tv":910.25,"id":27652444}],"tv":1092.43}]}
{"op":"mcm","clk":"1000150211","pt":1580608221098,"mc":[{"id":"1.168119364","rc":[{"batb":[[0,1.86,433.78],[1,1.85,45.43],[2,1.76,45.43]],"batl":[[0,3.3,172.2],[1,1000,0.02]],"ltp":2.92,"tv":182.18,"id":23010367}]}]}
{"op":"mcm","clk":"1000150390","pt":1580608225373,"mc":[{"id":"1.168119364","rc":[{"batb":[[1,1.76,45.43],[2,1.7,43.17]],"ltp":2.92,"tv":182.18,"id":23010367}]}]}
{"op":"mcm","clk":"1000151128","pt":1580608243695,"mc":[{"id":"1.168119364","rc":[{"batb":[[0,1.76,45.43],[1,1.7,43.17],[2,1.02,1]],"batl":[[0,1000,0.02],[1,1000,0]],"ltp":2.92,"tv":182.18,"id":23010367}]}]}
{"op":"mcm","clk":"1000151602","pt":1580608256707,"mc":[{"id":"1.168119364","rc":[{"batb":[[0,1.7,43.17],[1,1.02,1],[2,1.01,15.54]],"ltp":2.92,"tv":182.18,"id":23010367}]}]}
{"op":"mcm","clk":"1000151703","pt":1580608259325,"mc":[{"id":"1.168119364","rc":[{"batb":[[1,1.67,448.52],[2,1.02,1]],"batl":[[0,2.72,217.75],[1,1000,0.02]],"ltp":2.92,"tv":182.18,"id":23010367}]}]}
{"op":"mcm","clk":"1000151856","pt":1580608263544,"mc":[{"id":"1.168119364","rc":[{"batl":[[0,2.56,11.67],[1,2.72,217.75],[2,1000,0.02]],"ltp":2.92,"tv":182.18,"id":23010367},{"batb":[[0,1.5,45.43],[1,1.27,31.05],[2,1.02,1]],"ltp":1.52,"tv":910.25,"id":27652444}]}]}
{"op":"mcm","clk":"1000151867","pt":1580608263755,"mc":[{"id":"1.168119364","rc":[{"batl":[[0,2.72,217.75],[1,1000,0.02],[2,1000,0]],"ltp":2.92,"tv":182.18,"id":23010367}]}]}
{"op":"mcm","clk":"1000151962","pt":1580608265927,"mc":[{"id":"1.168119364","rc":[{"batb":[[0,1.64,45.43],[1,1.5,45.43],[2,1.27,31.05]],"ltp":1.52,"tv":910.25,"id":27652444}]}]}
{"op":"mcm","clk":"1000153353","pt":1580608296786,"mc":[{"id":"1.168119364","rc":[{"batl":[[0,1000,0.02],[1,1000,0]],"ltp":2.92,"tv":182.18,"id":23010367}]}]}
{"op":"mcm","clk":"1000153537","pt":1580608300697,"mc":[{"id":"1.168119364","rc":[{"batl":[[0,2.5,248.49],[1,1000,0.02]],"ltp":2.92,"tv":182.18,"id":23010367}]}]}
{"op":"mcm","clk":"1000153829","pt":1580608307206,"mc":[{"id":"1.168119364","rc":[{"batb":[[0,1.71,45.43],[1,1.64,45.43],[2,1.5,45.43]],"ltp":1.52,"tv":910.25,"id":27652444}]}]}
{"op":"mcm","clk":"1000154069","pt":1580608312597,"mc":[{"id":"1.168119364","rc":[{"batb":[[2,1.27,31.05]],"ltp":1.52,"tv":910.25,"id":27652444}]}]}
{"op":"mcm","clk":"1000154139","pt":1580608314195,"mc":[{"id":"1.168119364","rc":[{"batb":[[2,1.02,1]],"ltp":1.52,"tv":910.25,"id":27652444}]}]}
{"op":"mcm","clk":"1000154300","pt":1580608317586,"mc":[{"id":"1.168119364","rc":[{"batb":[[0,1.79,5],[1,1.7,43.17],[2,1.67,448.52]],"ltp":2.92,"tv":182.18,"id":23010367}]}]}
{"op":"mcm","clk":"1000154659","pt":1580608326017,"mc":[{"id":"1.168119364","rc":[{"trd":[[1.79,10]],"batb":[[0,1.02,1],[1,1.01,15.54],[2,1.67,0]],"batl":[[0,1000,0.02],[1,1000,0]],"ltp":1.79,"tv":192.18,"id":23010367}],"tv":1102.43}]}
{"op":"mcm","clk":"1000154826","pt":1580608329730,"mc":[{"id":"1.168119364","rc":[{"batb":[[0,1.46,480.78],[1,1.02,1],[2,1.01,15.54]],"batl":[[0,1.8,3.36],[1,2.22,299.69],[2,1000,0.02]],"ltp":1.79,"tv":192.18,"id":23010367}]}]}
{"op":"mcm","clk":"1000154956","pt":1580608332519,"mc":[{"id":"1.168119364","rc":[{"batb":[[0,1.51,22.72],[1,1.46,480.78],[2,1.02,1]],"ltp":1.79,"tv":192.18,"id":23010367}]}]}
{"op":"mcm","clk":"1000155035","pt":1580608334632,"mc":[{"id":"1.168119364","rc":[{"batb":[[1,1.02,1],[2,1.01,15.54]],"ltp":1.52,"tv":910.25,"id":27652444}]}]}
{"op":"mcm","clk":"1000155245","pt":1580608339721,"mc":[{"id":"1.168119364","rc":[{"batl":[[1,1.97,37.86],[2,2.22,299.69]],"ltp":1.79,"tv":192.18,"id":23010367}]}]}
{"op":"mcm","clk":"1000155278","pt":1580608340231,"mc":[{"id":"1.168119364","rc":[{"batb":[[0,1.54,5],[1,1.51,22.72],[2,1.46,480.78]],"ltp":1.79,"tv":192.18,"id":23010367}]}]}
{"op":"mcm","clk":"1000155613","pt":1580608349456,"mc":[{"id":"1.168119364","rc":[{"batb":[[0,1.51,22.72],[1,1.46,480.78],[2,1.02,1]],"ltp":1.79,"tv":192.18,"id":23010367}]}]}
{"op":"mcm","clk":"1000155726","pt":1580608352549,"mc":[{"id":"1.168119364","rc":[{"batb":[[0,1.6,5],[1,1.51,22.72],[2,1.46,480.78]],"ltp":1.79,"tv":192.18,"id":23010367}]}]}
{"op":"mcm","clk":"1000156110","pt":1580608362672,"mc":[{"id":"1.168119364","rc":[{"batb":[[0,1.51,22.72],[1,1.46,480.78],[2,1.02,1]],"ltp":1.79,"tv":192.18,"id":23010367}]}]}
{"op":"mcm","clk":"1000156203","pt":1580608365770,"mc":[{"id":"1.168119364","rc":[{"batb":[[0,1.56,5],[1,1.51,22.72],[2,1.46,480.78]],"ltp":1.79,"tv":192.18,"id":23010367}]}]}
{"op":"mcm","clk":"1000156247","pt":1580608367004,"mc":[{"id":"1.168119364","rc":[{"batb":[[2,1.02,1]],"ltp":1.79,"tv":192.18,"id":23010367}]}]}
{"op":"mcm","clk":"1000156397","pt":1580608370574,"mc":[{"id":"1.168119364","rc":[{"batb":[[0,1.51,22.72],[1,1.02,1],[2,1.01,15.54]],"ltp":1.79,"tv":192.18,"id":23010367}]}]}
{"op":"mcm","clk":"1000156409","pt":1580608370984,"mc":[{"id":"1.168119364","rc":[{"batb":[[0,1.55,462.55],[1,1.51,22.72],[2,1.02,1]],"ltp":1.79,"tv":192.18,"id":23010367}]}]}
{"op":"mcm","clk":"1000156487","pt":1580608373666,"mc":[{"id":"1.168119364","rc":[{"trd":[[1.8,6.72]],"batb":[[0,1.8,1.64],[1,1.55,462.55],[2,1.51,22.72]],"batl":[[0,1.97,37.86],[1,2.22,299.69],[2,1000,0.02]],"ltp":1.8,"tv":198.9,"id":23010367}],"tv":1109.15}]}
{"op":"mcm","clk":"1000156760","pt":1580608380316,"mc":[{"id":"1.168119364","rc":[{"batb":[[0,1.59,37.86]],"ltp":1.8,"tv":198.9,"id":23010367}]}]}
{"op":"mcm","clk":"1000156855","pt":1580608383106,"mc":[{"id":"1.168119364","rc":[{"batb":[[0,1.75,1.64],[1,1.59,37.86],[2,1.55,462.55]],"ltp":1.8,"tv":198.9,"id":23010367}]}]}
{"op":"mcm","clk":"1000156936","pt":1580608385011,"mc":[{"id":"1.168119364","rc":[{"batl":[[0,2.22,299.69],[1,1000,0.02],[2,1000,0]],"ltp":1.8,"tv":198.9,"id":23010367}]}]}
{"op":"mcm","clk":"1000157125","pt":1580608389698,"mc":[{"id":"1.168119364","rc":[{"batl":[[0,2.2,21.73],[1,2.22,299.69],[2,1000,0.02]],"ltp":1.8,"tv":198.9,"id":23010367}]}]}
{"op":"mcm","clk":"1000157131","pt":1580608389906,"mc":[{"id":"1.168119364","rc":[{"batl":[[0,2.22,299.69],[1,1000,0.02],[2,1000,0]],"ltp":1.8,"tv":198.9,"id":23010367}]}]}
{"op":"mcm","clk":"1000157188","pt":1580608391504,"mc":[{"id":"1.168119364","rc":[{"batb":[[0,1.59,37.86],[1,1.55,462.55],[2,1.51,22.72]],"batl":[[0,2.14,15.14],[1,2.22,299.69],[2,1000,0.02]],"ltp":1.8,"tv":198.9,"id":23010367}]}]}
{"op":"mcm","clk":"1000157940","pt":1580608409548,"mc":[{"id":"1.168119364","rc":[{"batb":[[1,1.51,22.72],[2,1.02,1]],"batl":[[1,1000,0.02],[2,1000,0]],"ltp":1.8,"tv":198.9,"id":23010367}]}]}
{"op":"mcm","clk":"1000157962","pt":1580608410270,"mc":[{"id":"1.168119364","rc":[{"batl":[[0,1000,0.02],[1,1000,0]],"ltp":1.8,"tv":198.9,"id":23010367}]}]}
{"op":"mcm","clk":"1000158044","pt":1580608412550,"mc":[{"id":"1.168119364","rc":[{"batb":[[0,1.62,455.6],[1,1.59,37.86],[2,1.51,22.72]],"batl":[[0,2.6,232.62],[1,1000,0.02]],"ltp":1.8,"tv":198.9,"id":23010367}]}]}
{"op":"mcm","clk":"1000158061","pt":1580608413159,"mc":[{"id":"1.168119364","rc":[{"batb":[[0,1.83,1.64],[1,1.62,455.6],[2,1.59,37.86]],"ltp":1.8,"tv":198.9,"id":23010367}]}]}
{"op":"mcm","clk":"1000158141","pt":1580608415737,"mc":[{"id":"1.168119364","rc":[{"batb":[[0,1.62,455.6],[1,1.59,37.86],[2,1.51,22.72]],"ltp":1.8,"tv":198.9,"id":23010367}]}]}
{"op":"mcm","clk":"1000158253","pt":1580608418982,"mc":[{"id":"1.168119364","rc":[{"batb":[[0,1.65,15.14],[1,1.62,455.6],[2,1.59,37.86]],"ltp":1.8,"tv":198.9,"id":23010367}]}]}
{"op":"mcm","clk":"1000158627","pt":1580608428375,"mc":[{"id":"1.168119364","rc":[{"trd":[[2.42,2.06]],"ltp":2.42,"tv":200.54,"id":23010367},{"trd":[[1.71,2.92]],"batb":[[0,1.71,43.11]],"ltp":1.71,"tv":912.58,"id":27652444}],"tv":1113.12}]}
{"op":"mcm","clk":"1000158985","pt":1580608439276,"mc":[{"id":"1.168119364","rc":[{"batb":[[1,1.63,45.43],[2,1.02,1]],"batl":[[0,1.92,2.07],[1,1000,0.02]],"ltp":1.71,"tv":912.58,"id":27652444}]}]}
{"op":"mcm","clk":"1000159165","pt":1580608443515,"mc":[{"id":"1.168119364","rc":[{"batb":[[1,1.59,37.86],[2,1.51,22.72]],"ltp":2.42,"tv":200.54,"id":23010367},{"batb":[[0,1.63,45.43],[1,1.02,1],[2,1.01,15.54]],"ltp":1.71,"tv":912.58,"id":27652444}]}]}
{"op":"mcm","clk":"1000159224","pt":1580608444597,"mc":[{"id":"1.168119364","rc":[{"batl":[[1,1.95,385.95],[2,1000,0.02]],"ltp":1.71,"tv":912.58,"id":27652444}]}]}
{"op":"mcm","clk":"1000159230","pt":1580608444808,"mc":[{"id":"1.168119364","rc":[{"batl":[[1,1000,0.02],[2,1000,0]],"ltp":1.71,"tv":912.58,"id":27652444}]}]}
{"op":"mcm","clk":"1000159352","pt":1580608447693,"mc":[{"id":"1.168119364","rc":[{"batb":[[0,1.7,447.61],[1,1.65,15.14],[2,1.59,37.86]],"ltp":2.42,"tv":200.54,"id":23010367}]}]}
{"op":"mcm","clk":"1000159885","pt":1580608459727,"mc":[{"id":"1.168119364","rc":[{"batb":[[1,1.5,45.43],[2,1.02,1]],"ltp":1.71,"tv":912.58,"id":27652444}]}]}
{"op":"mcm","clk":"1000161086","pt":1580608491259,"mc":[{"id":"1.168119364","rc":[{"batb":[[0,1.65,15.14],[1,1.59,37.86],[2,1.51,22.72]],"batl":[[0,1000,0.02],[1,1000,0]],"ltp":2.42,"tv":200.54,"id":23010367}]}]}
{"op":"mcm","clk":"1000161135","pt":1580608492550,"mc":[{"id":"1.168119364","rc":[{"batb":[[0,1.5,45.43],[1,1.02,1],[2,1.01,15.54]],"ltp":1.71,"tv":912.58,"id":27652444}]}]}
{"op":"mcm","clk":"1000161222","pt":1580608495169,"mc":[{"id":"1.168119364","rc":[{"batb":[[0,1.77,438.98],[1,1.65,15.14],[2,1.59,37.86]],"batl":[[0,3,191.87],[1,1000,0.02]],"ltp":2.42,"tv":200.54,"id":23010367}]}]}
{"op":"mcm","clk":"1000161697","pt":1580608509493,"mc":[{"id":"1.168119364","rc":[{"batl":[[1,1000,2.41]],"ltp":1.71,"tv":912.58,"id":27652444}]}]}
{"op":"mcm","clk":"1000161710","pt":1580608509753,"mc":[{"id":"1.168119364","rc":[{"batl":[[1,1000,0.02]],"ltp":1.71,"tv":912.58,"id":27652444}]}]}
{"op":"mcm","clk":"1000161810","pt":1580608512887,"mc":[{"id":"1.168119364","rc":[{"batl":[[0,1.66,2.39],[1,1.88,45.43],[2,1.92,2.07]],"ltp":1.71,"tv":912.58,"id":27652444}]}]}
{"op":"mcm","clk":"1000161927","pt":1580608516479,"mc":[{"id":"1.168119364","rc":[{"trd":[[1.66,48.22]],"batl":[[0,1.88,45.55],[1,1.92,2.07],[2,1000,0.02]],"ltp":1.66,"tv":917.13,"id":27652444}],"tv":1117.68}]}
{"op":"mcm","clk":"1000162259","pt":1580608525110,"mc":[{"id":"1.168119364","rc":[{"trd":[[3,24.25]],"batl":[[0,3,177.62]],"ltp":3.0,"tv":214.79,"id":23010367},{"trd":[[1.5,139.37]],"batb":[[0,1.02,1],[1,1.01,15.54],[2,1.01,0]],"ltp":1.5,"tv":1036.51,"id":27652444}],"tv":1251.3}]}
{"op":"mcm","clk":"1000162493","pt":1580608530983,"mc":[{"id":"1.168119364","rc":[{"batl":[[0,2.8,94.57],[1,3,177.62],[2,1000,0.02]],"ltp":3.0,"tv":214.79,"id":23010367}]}]}
{"op":"mcm","clk":"1000164474","pt":1580608572588,"mc":[{"id":"1.168119364","rc":[{"batl":[[0,1.62,42.19],[1,1.88,45.55],[2,1.92,2.07]],"ltp":1.5,"tv":1036.51,"id":27652444}]}]}
{"op":"mcm","clk":"1000164612","pt":1580608575775,"mc":[{"id":"1.168119364","rc":[{"batl":[[0,1.88,45.55],[1,1.92,2.07],[2,1000,0.02]],"ltp":1.5,"tv":1036.51,"id":27652444}]}]}
{"op":"mcm","clk":"1000164783","pt":1580608579673,"mc":[{"id":"1.168119364","rc":[{"batl":[[0,1.66,41.28],[1,1.88,45.43],[2,1.92,2.07]],"ltp":1.5,"tv":1036.51,"id":27652444}]}]}
{"op":"mcm","clk":"1000164915","pt":1580608582781,"mc":[{"id":"1.168119364","rc":[{"trd":[[1.66,130.78]],"batl":[[0,1.88,45.43],[1,1.92,2.07],[2,1000,0.02]],"ltp":1.66,"tv":1119.07,"id":27652444}],"tv":1333.86}]}
{"op":"mcm","clk":"1000165042","pt":1580608585497,"mc":[{"id":"1.168119364","rc":[{"batb":[[0,1.39,60.58],[1,1.02,1],[2,1.01,15.54]],"ltp":1.66,"tv":1119.07,"id":27652444}]}]}
{"op":"mcm","clk":"1000165072","pt":1580608586273,"mc":[{"id":"1.168119364","rc":[{"batl":[[0,3,177.62],[1,1000,0.02],[2,1000,0]],"ltp":3.0,"tv":214.79,"id":23010367}]}]}
{"op":"mcm","clk":"1000165249","pt":1580608590584,"mc":[{"id":"1.168119364","rc":[{"batl":[[1,1000,0.02],[2,1000,0]],"ltp":1.66,"tv":1119.07,"id":27652444}]}]}
{"op":"mcm","clk":"1000165520","pt":1580608597972,"mc":[{"id":"1.168119364","rc":[{"batb":[[0,1.6,1.2],[1,1.39,60.58],[2,1.02,1]],"ltp":1.66,"tv":1119.07,"id":27652444}]}]}
{"op":"mcm","clk":"1000165679","pt":1580608602383,"mc":[{"id":"1.168119364","rc":[{"batb":[[0,1.65,15.14],[1,1.59,37.86],[2,1.51,22.72]],"batl":[[0,1000,0.02],[1,1000,0]],"ltp":3.0,"tv":214.79,"id":23010367}]}]}
{"op":"mcm","clk":"1000165838","pt":1580608606484,"mc":[{"id":"1.168119364","rc":[{"batb":[[0,1.92,451.16],[1,1.65,15.14],[2,1.59,37.86]],"batl":[[0,3.45,149.31],[1,1000,0.02]],"ltp":3.0,"tv":214.79,"id":23010367}]}]}
{"op":"mcm","clk":"1000166217","pt":1580608616533,"mc":[{"id":"1.168119364","rc":[{"batb":[[2,1.33,60.58]],"ltp":1.66,"tv":1119.07,"id":27652444}]}]}
{"op":"mcm","clk":"1000167096","pt":1580608639547,"mc":[{"id":"1.168119364","rc":[{"batl":[[0,1000,0.02],[1,1000,0]],"ltp":3.0,"tv":214.79,"id":23010367}]}]}
{"op":"mcm","clk":"1000167253","pt":1580608643536,"mc":[{"id":"1.168119364","rc":[{"batl":[[0,3.15,166.38],[1,1000,0.02]],"ltp":3.0,"tv":214.79,"id":23010367}]}]}
{"op":"mcm","clk":"1000167380","pt":1580608646669,"mc":[{"id":"1.168119364","rc":[{"batb":[[1,1.4,280.26],[2,1.39,60.58]],"ltp":1.66,"tv":1119.07,"id":27652444}]}]}
{"op":"mcm","clk":"1000167386","pt":1580608646876,"mc":[{"id":"1.168119364","rc":[{"batb":[[1,1.39,60.58],[2,1.33,60.58]],"ltp":1.66,"tv":1119.07,"id":27652444}]}]}
{"op":"mcm","clk":"1000167963","pt":1580608665570,"mc":[{"id":"1.168119364","rc":[{"batb":[[0,1.65,15.14],[1,1.59,37.86],[2,1.51,22.72]],"batl":[[0,1000,0.02],[1,1000,0]],"ltp":3.0,"tv":214.79,"id":23010367},{"batb":[[1,1.49,31.05],[2,1.39,60.58]],"ltp":1.66,"tv":1119.07,"id":27652444}]}]}
{"op":"mcm","clk":"1000168102","pt":1580608669579,"mc":[{"id":"1.168119364","rc":[{"batb":[[0,1.74,466.15],[1,1.65,15.14],[2,1.59,37.86]],"batl":[[0,2.92,184.46],[1,1000,0.02]],"ltp":3.0,"tv":214.79,"id":23010367}]}]}
{"op":"mcm","clk":"1000168422","pt":1580608678987,"mc":[{"id":"1.168119364","rc":[{"batb":[[1,1.55,37.86],[2,1.49,31.05]],"ltp":1.66,"tv":1119.07,"id":27652444}]}]}
{"op":"mcm","clk":"1000168493","pt":1580608680691,"mc":[{"id":"1.168119364","rc":[{"batl":[[0,1000,0.02],[1,1000,0]],"ltp":1.66,"tv":1119.07,"id":27652444}]}]}
{"op":"mcm","clk":"1000168587","pt":1580608683775,"mc":[{"id":"1.168119364","rc":[{"batl":[[0,1.98,45.43],[1,1000,0.02]],"ltp":1.66,"tv":1119.07,"id":27652444}]}]}
{"op":"mcm","clk":"1000168890","pt":1580608690609,"mc":[{"id":"1.168119364","rc":[{"batl":[[0,1000,0.02],[1,1000,0]],"ltp":3.0,"tv":214.79,"id":23010367}]}]}
{"op":"mcm","clk":"1000168985","pt":1580608693123,"mc":[{"id":"1.168119364","rc":[{"batl":[[0,1000,0.02],[1,1000,0]],"ltp":1.66,"tv":1119.07,"id":27652444}]}]}
{"op":"mcm","clk":"1000169039","pt":1580608694718,"mc":[{"id":"1.168119364","rc":[{"batl":[[0,2.72,202.27],[1,1000,0.02]],"ltp":3.0,"tv":214.79,"id":23010367}]}]}
{"op":"mcm","clk":"1000169140","pt":1580608698106,"mc":[{"id":"1.168119364","rc":[{"batl":[[0,2.28,37.86],[1,1000,0.02]],"ltp":1.66,"tv":1119.07,"id":27652444}]}]}
{"op":"mcm","clk":"1000169208","pt":1580608699904,"mc":[{"id":"1.168119364","rc":[{"batb":[[0,1.62,37.86],[1,1.6,1.2],[2,1.55,37.86]],"ltp":1.66,"tv":1119.07,"id":27652444}]}]}
{"op":"mcm","clk":"1000170129","pt":1580608724137,"mc":[{"id":"1.168119364","rc":[{"batb":[[1,1.55,37.86],[2,1.49,31.05]],"ltp":1.66,"tv":1119.07,"id":27652444}]}]}
{"op":"mcm","clk":"1000170681","pt":1580608739070,"mc":[{"id":"1.168119364","rc":[{"batb":[[0,1.55,37.86],[1,1.49,31.05],[2,1.39,60.58]],"ltp":1.66,"tv":1119.07,"id":27652444}]}]}
{"op":"mcm","clk":"1000171844","pt":1580608774839,"mc":[{"id":"1.168119364","rc":[{"batb":[[0,1.62,37.86],[1,1.55,37.86],[2,1.49,31.05]],"ltp":1.66,"tv":1119.07,"id":27652444}]}]}
{"op":"mcm","clk":"1000172410","pt":1580608793867,"mc":[{"id":"1.168119364","rc":[{"batb":[[0,1.65,15.14],[1,1.59,37.86],[2,1.51,22.72]],"batl":[[0,1000,0.02],[1,1000,0]],"ltp":3.0,"tv":214.79,"id":23010367}]}]}
{"op":"mcm","clk":"1000172488","pt":1580608796233,"mc":[{"id":"1.168119364","rc":[{"batl":[[0,1000,0.02],[1,1000,0]],"ltp":1.66,"tv":1119.07,"id":27652444}]}]}
{"op":"mcm","clk":"1000172552","pt":1580608798133,"mc":[{"id":"1.168119364","rc":[{"batb":[[1,1.62,482.14],[2,1.59,37.86]],"batl":[[0,2.6,216.39],[1,1000,0.02]],"ltp":3.0,"tv":214.79,"id":23010367}]}]}
{"op":"mcm","clk":"1000172911","pt":1580608805857,"mc":[{"id":"1.168119364","rc":[{"batb":[[1,1.59,37.86],[2,1.51,22.72]],"batl":[[0,1000,0.02],[1,1000,0]],"ltp":3.0,"tv":214.79,"id":23010367}]}]}
{"op":"mcm","clk":"1000173014","pt":1580608807865,"mc":[{"id":"1.168119364","rc":[{"batb":[[0,1.59,37.86],[1,1.51,22.72],[2,1.02,1]],"ltp":3.0,"tv":214.79,"id":23010367}]}]}
{"op":"mcm","clk":"1000173080","pt":1580608809260,"mc":[{"id":"1.168119364","rc":[{"batb":[[1,1.52,496.87],[2,1.51,22.72]],"batl":[[0,2.36,253.61],[1,1000,0.02]],"ltp":3.0,"tv":214.79,"id":23010367}]}]}
{"op":"mcm","clk":"1000174198","pt":1580608835872,"mc":[{"id":"1.168119364","rc":[{"batb":[[1,1.51,22.72],[2,1.02,1]],"batl":[[0,1000,0.02],[1,1000,0]],"ltp":3.0,"tv":214.79,"id":23010367}]}]}
{"op":"mcm","clk":"1000174340","pt":1580608839486,"mc":[{"id":"1.168119364","rc":[{"batb":[[0,1.67,474.18],[1,1.59,37.86],[2,1.51,22.72]],"batl":[[0,2.72,202.23],[1,1000,0.02]],"ltp":3.0,"tv":214.79,"id":23010367}]}]}
{"op":"mcm","clk":"1000174813","pt":1580608851834,"mc":[{"id":"1.168119364","rc":[{"batb":[[0,1.7,31.05],[1,1.67,474.18],[2,1.59,37.86]],"ltp":3.0,"tv":214.79,"id":23010367}]}]}
{"op":"mcm","clk":"1000176617","pt":1580608895968,"mc":[{"id":"1.168119364","rc":[{"batb":[[1,1.59,37.86],[2,1.51,22.72]],"batl":[[0,1000,0.02],[1,1000,0]],"ltp":3.0,"tv":214.79,"id":23010367}]}]}
{"op":"mcm","clk":"1000176657","pt":1580608896747,"mc":[{"id":"1.168119364","rc":[{"batb":[[0,1.59,37.86],[1,1.51,22.72],[2,1.02,1]],"ltp":3.0,"tv":214.79,"id":23010367}]}]}
{"op":"mcm","clk":"1000176792","pt":1580608899386,"mc":[{"id":"1.168119364","rc":[{"batb":[[1,1.55,490.12],[2,1.51,22.72]],"batl":[[0,2.42,242.3],[1,1000,0.02]],"ltp":3.0,"tv":214.79,"id":23010367}]}]}
{"op":"mcm","clk":"1000178047","pt":1580608932327,"mc":[{"id":"1.168119364","rc":[{"batb":[[0,1.72,31.05],[1,1.62,37.86],[2,1.55,37.86]],"ltp":1.66,"tv":1119.07,"id":27652444}]}]}
{"op":"mcm","clk":"1000178636","pt":1580608949155,"mc":[{"id":"1.168119364","rc":[{"batb":[[0,1.55,490.12],[1,1.51,22.72],[2,1.02,1]],"ltp":3.0,"tv":214.79,"id":23010367}]}]}
{"op":"mcm","clk":"1000178683","pt":1580608950140,"mc":[{"id":"1.168119364","rc":[{"batb":[[0,1.51,22.72],[1,1.02,1],[2,1.01,15.54]],"batl":[[0,1000,0.02],[1,1000,0]],"ltp":3.0,"tv":214.79,"id":23010367}]}]}
{"op":"mcm","clk":"1000178736","pt":1580608951330,"mc":[{"id":"1.168119364","rc":[{"batb":[[0,1.02,1],[1,1.01,15.54],[2,1.01,0]],"ltp":3.0,"tv":214.79,"id":23010367}]}]}
{"op":"mcm","clk":"1000178828","pt":1580608953522,"mc":[{"id":"1.168119364","rc":[{"batb":[[0,1.4,529.68],[1,1.02,1],[2,1.01,15.54]],"batl":[[0,2.1,312.21],[1,1000,0.02]],"ltp":3.0,"tv":214.79,"id":23010367}]}]}
{"op":"mcm","clk":"1000178976","pt":1580608957449,"mc":[{"id":"1.168119364","rc":[{"batb":[[1,1.38,31.05],[2,1.02,1]],"ltp":3.0,"tv":214.79,"id":23010367}]}]}
{"op":"mcm","clk":"1000179027","pt":1580608958633,"mc":[{"id":"1.168119364","rc":[{"batb":[[0,1.62,37.86],[1,1.55,37.86],[2,1.49,31.05]],"ltp":1.66,"tv":1119.07,"id":27652444}]}]}
{"op":"mcm","clk":"1000179047","pt":1580608959354,"mc":[{"id":"1.168119364","rc":[{"batb":[[0,1.55,37.86],[1,1.49,31.05],[2,1.33,60.58]],"ltp":1.66,"tv":1119.07,"id":27652444}]}]}
{"op":"mcm","clk":"1000179111","pt":1580608961267,"mc":[{"id":"1.168119364","rc":[{"batb":[[0,1.49,31.05],[1,1.33,60.58],[2,1.02,1]],"ltp":1.66,"tv":1119.07,"id":27652444}]}]}
{"op":"mcm","clk":"1000179136","pt":1580608961783,"mc":[{"id":"1.168119364","rc":[{"batb":[[0,1.71,31.05],[1,1.49,31.05],[2,1.33,60.58]],"ltp":1.66,"tv":1119.07,"id":27652444}]}]}
{"op":"mcm","clk":"1000179315","pt":1580608966841,"mc":[{"id":"1.168119364","rc":[{"batl":[[0,1.86,31.05],[1,2.1,312.21],[2,1000,0.02]],"ltp":3.0,"tv":214.79,"id":23010367}]}]}
{"op":"mcm","clk":"1000179826","pt":1580608981261,"mc":[{"id":"1.168119364","rc":[{"batb":[[0,1.42,31.05],[1,1.4,529.68],[2,1.38,31.05]],"ltp":3.0,"tv":214.79,"id":23010367}]}]}
{"op":"mcm","clk":"1000180009","pt":1580608985864,"mc":[{"id":"1.168119364","rc":[{"batl":[[0,1.7,31.05],[1,1.86,31.05],[2,2.1,312.21]],"ltp":3.0,"tv":214.79,"id":23010367}]}]}
{"op":"mcm","clk":"1000180059","pt":1580608987507,"mc":[{"id":"1.168119364","rc":[{"batb":[[1,1.38,31.05],[2,1.02,1]],"batl":[[0,1.86,31.05],[1,2.1,312.21],[2,1000,0.02]],"ltp":3.0,"tv":214.79,"id":23010367}]}]}
{"op":"mcm","clk":"1000180193","pt":1580608990596,"mc":[{"id":"1.168119364","rc":[{"batb":[[0,1.46,510.33],[1,1.42,31.05],[2,1.38,31.05]],"ltp":3.0,"tv":214.79,"id":23010367}]}]}
{"op":"mcm","clk":"1000180452","pt":1580608997019,"mc":[{"id":"1.168119364","rc":[{"batb":[[0,1.6,1.2],[1,1.46,510.33],[2,1.42,31.05]],"ltp":3.0,"tv":214.79,"id":23010367}]}]}
{"op":"mcm","clk":"1000180992","pt":1580609013154,"mc":[{"id":"1.168119364","rc":[{"batl":[[0,2.1,312.21],[1,1000,0.02],[2,1000,0]],"ltp":3.0,"tv":214.79,"id":23010367}]}]}
{"op":"mcm","clk":"1000181845","pt":1580609034249,"mc":[{"id":"1.168119364","rc":[{"batb":[[1,1.42,31.05],[2,1.38,31.05]],"ltp":3.0,"tv":214.79,"id":23010367}]}]}
{"op":"mcm","clk":"1000182012","pt":1580609037750,"mc":[{"id":"1.168119364","rc":[{"batb":[[2,1.38,558.34]],"ltp":3.0,"tv":214.79,"id":23010367}]}]}
{"op":"mcm","clk":"1000182138","pt":1580609041870,"mc":[{"id":"1.168119364","rc":[{"batl":[[0,1.8,37.86],[1,2.1,312.21],[2,1000,0.02]],"ltp":3.0,"tv":214.79,"id":23010367}]}]}
{"op":"mcm","clk":"1000183003","pt":1580609063613,"mc":[{"id":"1.168119364","rc":[{"batl":[[1,1.99,22.72],[2,2.1,312.21]],"ltp":3.0,"tv":214.79,"id":23010367}]}]}
{"op":"mcm","clk":"1000183545","pt":1580609077193,"mc":[{"id":"1.168119364","rc":[{"batl":[[0,1.99,22.72],[1,2.1,312.21],[2,1000,0.02]],"ltp":3.0,"tv":214.79,"id":23010367}]}]}
{"op":"mcm","clk":"1000184798","pt":1580609108448,"mc":[{"id":"1.168119364","rc":[{"batb":[[2,1.38,31.05]],"ltp":3.0,"tv":214.79,"id":23010367}]}]}
{"op":"mcm","clk":"1000185008","pt":1580609112054,"mc":[{"id":"1.168119364","rc":[{"batb":[[2,1.4,529.69]],"ltp":3.0,"tv":214.79,"id":23010367}]}]}
{"op":"mcm","clk":"1000185632","pt":1580609128476,"mc":[{"id":"1.168119364","rc":[{"batb":[[2,1.38,31.05]],"batl":[[0,1000,0.02],[1,2.1,0],[2,1000,0]],"ltp":3.0,"tv":214.79,"id":23010367}]}]}
{"op":"mcm","clk":"1000185765","pt":1580609132176,"mc":[{"id":"1.168119364","rc":[{"batb":[[1,1.52,496.78],[2,1.42,31.05]],"batl":[[0,2.36,253.66],[1,1000,0.02]],"ltp":3.0,"tv":214.79,"id":23010367}]}]}
{"op":"mcm","clk":"1000185859","pt":1580609134594,"mc":[{"id":"1.168119364","rc":[{"batb":[[2,1.45,276.41]],"ltp":3.0,"tv":214.79,"id":23010367}]}]}
{"op":"mcm","clk":"1000185867","pt":1580609134800,"mc":[{"id":"1.168119364","rc":[{"batb":[[2,1.42,31.05]],"ltp":3.0,"tv":214.79,"id":23010367}]}]}
{"op":"mcm","clk":"1000186256","pt":1580609146490,"mc":[{"id":"1.168119364","rc":[{"batb":[[0,1.49,31.05],[1,1.33,60.58],[2,1.02,1]],"ltp":1.66,"tv":1119.07,"id":27652444}]}]}
{"op":"mcm","clk":"1000186338","pt":1580609148504,"mc":[{"id":"1.168119364","rc":[{"batb":[[0,1.74,15.14],[1,1.49,31.05],[2,1.33,60.58]],"ltp":1.66,"tv":1119.07,"id":27652444}]}]}
{"op":"mcm","clk":"1000186516","pt":1580609153805,"mc":[{"id":"1.168119364","rc":[{"batb":[[1,1.61,37.86],[2,1.49,31.05]],"ltp":1.66,"tv":1119.07,"id":27652444}]}]}
{"op":"mcm","clk":"1000186657","pt":1580609159313,"mc":[{"id":"1.168119364","rc":[{"batb":[[1,1.57,22.72],[2,1.52,496.78]],"ltp":3.0,"tv":214.79,"id":23010367}]}]}
{"op":"mcm","clk":"1000186868","pt":1580609166555,"mc":[{"id":"1.168119364","rc":[{"batb":[[2,1.42,31.05]],"batl":[[0,1000,0.02],[1,1000,0]],"ltp":3.0,"tv":214.79,"id":23010367}]}]}
{"op":"mcm","clk":"1000186901","pt":1580609167635,"mc":[{"id":"1.168119364","rc":[{"batb":[[0,1.61,37.86],[1,1.49,31.05],[2,1.33,60.58]],"ltp":1.66,"tv":1119.07,"id":27652444}]}]}
{"op":"mcm","clk":"1000187003","pt":1580609170252,"mc":[{"id":"1.168119364","rc":[{"batb":[[0,1.67,474.18],[1,1.6,1.2],[2,1.57,22.72]],"batl":[[0,2.72,202.23],[1,1000,0.02]],"ltp":3.0,"tv":214.79,"id":23010367}]}]}
{"op":"mcm","clk":"1000187883","pt":1580609196586,"mc":[{"id":"1.168119364","rc":[{"batb":[[0,1.6,1.2],[1,1.57,22.72],[2,1.42,31.05]],"batl":[[0,1000,0.02],[1,1000,0]],"ltp":3.0,"tv":214.79,"id":23010367},{"batb":[[0,1.49,31.05],[1,1.33,60.58],[2,1.02,1]],"ltp":1.66,"tv":1119.07,"id":27652444}]}]}
{"op":"mcm","clk":"1000187983","pt":1580609200290,"mc":[{"id":"1.168119364","rc":[{"batb":[[0,1.82,460.65],[1,1.6,1.2],[2,1.57,22.72]],"batl":[[0,3.15,166.43],[1,1000,0.02]],"ltp":3.0,"tv":214.79,"id":23010367}]}]}
{"op":"mcm","clk":"1000188250","pt":1580609209706,"mc":[{"id":"1.168119364","rc":[{"batl":[[0,1.99,15.14],[1,1000,0.02]],"ltp":1.66,"tv":1119.07,"id":27652444}]}]}
{"op":"mcm","clk":"1000188499","pt":1580609219012,"mc":[{"id":"1.168119364","rc":[{"batb":[[0,1.33,60.58],[1,1.02,1],[2,1.01,15.54]],"ltp":1.66,"tv":1119.07,"id":27652444}]}]}
{"op":"mcm","clk":"1000189145","pt":1580609239728,"mc":[{"id":"1.168119364","rc":[{"batb":[[0,1.6,1.2],[1,1.57,22.72],[2,1.42,31.05]],"batl":[[0,1000,0.02],[1,1000,0]],"ltp":3.0,"tv":214.79,"id":23010367},{"batl":[[0,1.45,2256],[1,1.99,15.14],[2,1000,0.02]],"ltp":1.66,"tv":1119.07,"id":27652444}]}]}
{"op":"mcm","clk":"1000189156","pt":1580609239934,"mc":[{"id":"1.168119364","rc":[{"batl":[[0,1.99,15.14],[1,1000,0.02],[2,1000,0]],"ltp":1.66,"tv":1119.07,"id":27652444}]}]}
{"op":"mcm","clk":"1000189273","pt":1580609242660,"mc":[{"id":"1.168119364","rc":[{"batl":[[0,1.46,31.05],[1,1.99,15.14],[2,1000,0.02]],"ltp":1.66,"tv":1119.07,"id":27652444}]}]}
{"op":"mcm","clk":"1000189310","pt":1580609243430,"mc":[{"id":"1.168119364","rc":[{"batb":[[0,2.22,433.32],[1,1.6,1.2],[2,1.57,22.72]],"batl":[[0,4.6,112.33],[1,1000,0.02]],"ltp":3.0,"tv":214.79,"id":23010367}]}]}
{"op":"mcm","clk":"1000189357","pt":1580609244358,"mc":[{"id":"1.168119364","rc":[{"batl":[[0,1.99,15.14],[1,1000,0.02],[2,1000,0]],"ltp":1.66,"tv":1119.07,"id":27652444}]}]}
{"op":"mcm","clk":"1000189424","pt":1580609245745,"mc":[{"id":"1.168119364","rc":[{"batl":[[0,1.91,326.16],[1,1.99,15.14],[2,1000,0.02]],"ltp":1.66,"tv":1119.07,"id":27652444}]}]}
{"op":"mcm","clk":"1000189431","pt":1580609245955,"mc":[{"id":"1.168119364","rc":[{"batl":[[0,1.99,15.14],[1,1000,0.02],[2,1000,0]],"ltp":1.66,"tv":1119.07,"id":27652444}]}]}
{"op":"mcm","clk":"1000189584","pt":1580609249434,"mc":[{"id":"1.168119364","rc":[{"batl":[[0,1.61,31.05],[1,1.99,15.14],[2,1000,0.02]],"ltp":1.66,"tv":1119.07,"id":27652444}]}]}
{"op":"mcm","clk":"1000189882","pt":1580609256639,"mc":[{"id":"1.168119364","rc":[{"batl":[[0,1.99,15.14],[1,1000,0.02],[2,1000,0]],"ltp":1.66,"tv":1119.07,"id":27652444}]}]}
{"op":"mcm","clk":"1000190019","pt":1580609258834,"mc":[{"id":"1.168119364","rc":[{"batl":[[0,1.74,31.05],[1,1.99,15.14],[2,1000,0.02]],"ltp":1.66,"tv":1119.07,"id":27652444}]}]}
{"op":"mcm","clk":"1000190360","pt":1580609265048,"mc":[{"id":"1.168119364","rc":[{"batb":[[1,1.28,53.76],[2,1.02,1]],"ltp":1.66,"tv":1119.07,"id":27652444}]}]}
{"op":"mcm","clk":"1000190700","pt":1580609272594,"mc":[{"id":"1.168119364","rc":[{"batl":[[0,2.9,1084.4]],"ltp":3.0,"tv":214.79,"id":23010367},{"batb":[[2,1.22,53.76]],"ltp":1.66,"tv":1119.07,"id":27652444}]}]}
{"op":"mcm","clk":"1000190711","pt":1580609272754,"mc":[{"id":"1.168119364","rc":[{"batl":[[0,1000,0.02],[1,1000,0]],"ltp":3.0,"tv":214.79,"id":23010367}]}]}
{"op":"mcm","clk":"1000190799","pt":1580609275381,"mc":[{"id":"1.168119364","rc":[{"batl":[[0,3.9,130.71],[1,1000,0.02]],"ltp":3.0,"tv":214.79,"id":23010367}]}]}
{"op":"mcm","clk":"1000190900","pt":1580609277790,"mc":[{"id":"1.168119364","rc":[{"trd":[[3.9,28.58]],"batl":[[0,3.9,102.13]],"ltp":3.9,"tv":243.37,"id":23010367},{"trd":[[1.34,83.18]],"ltp":1.34,"tv":1202.25,"id":27652444}],"tv":1445.62}]}
{"op":"mcm","clk":"1000190968","pt":1580609279286,"mc":[{"id":"1.168119364","rc":[{"batl":[[0,1.99,15.14],[1,1000,0.02],[2,1000,0]],"ltp":1.34,"tv":1202.25,"id":27652444}]}]}
{"op":"mcm","clk":"1000191865","pt":1580609301095,"mc":[{"id":"1.168119364","rc":[{"batb":[[0,1.28,53.76],[1,1.22,53.76],[2,1.02,1]],"ltp":1.34,"tv":1202.25,"id":27652444}]}]}
{"op":"mcm","clk":"1000192163","pt":1580609308103,"mc":[{"id":"1.168119364","rc":[{"batb":[[0,1.6,1.2],[1,1.57,22.72],[2,1.42,31.05]],"batl":[[0,1000,0.02],[1,1000,0]],"ltp":3.9,"tv":243.37,"id":23010367},{"batb":[[0,1.22,53.76],[1,1.02,1],[2,1.01,15.54]],"ltp":1.34,"tv":1202.25,"id":27652444}]}]}
{"op":"mcm","clk":"1000192324","pt":1580609311612,"mc":[{"id":"1.168119364","rc":[{"batb":[[0,2.52,468.01],[1,1.6,1.2],[2,1.57,22.72]],"batl":[[0,6,66.85],[1,1000,0.02]],"ltp":3.9,"tv":243.37,"id":23010367}]}]}
{"op":"mcm","clk":"1000192350","pt":1580609312234,"mc":[{"id":"1.168119364","rc":[{"batl":[[0,1.46,37.86],[1,1.99,15.14],[2,1000,0.02]],"ltp":1.34,"tv":1202.25,"id":27652444}]}]}
{"op":"mcm","clk":"1000192496","pt":1580609315638,"mc":[{"id":"1.168119364","rc":[{"batb":[[2,1.02,1]],"ltp":3.9,"tv":243.37,"id":23010367}]}]}
{"op":"mcm","clk":"1000192687","pt":1580609320027,"mc":[{"id":"1.168119364","rc":[{"batl":[[0,1.39,53.76],[1,1.46,37.86],[2,1.99,15.14]],"ltp":1.34,"tv":1202.25,"id":27652444}]}]}
{"op":"mcm","clk":"1000193123","pt":1580609330439,"mc":[{"id":"1.168119364","rc":[{"batb":[[2,1.01,18.6]],"ltp":1.34,"tv":1202.25,"id":27652444}]}]}
{"op":"mcm","clk":"1000193161","pt":1580609331521,"mc":[{"id":"1.168119364","rc":[{"trd":[[3.55,16.46]],"ltp":3.55,"tv":259.83,"id":23010367},{"trd":[[1.39,42.03]],"batb":[[2,1.01,15.57]],"batl":[[0,1.39,11.73]],"ltp":1.39,"tv":1244.28,"id":27652444}],"tv":1504.12}]}
{"op":"mcm","clk":"1000193175","pt":1580609331932,"mc":[{"id":"1.168119364","rc":[{"batb":[[2,1.01,15.54]],"ltp":1.39,"tv":1244.28,"id":27652444}]}]}
{"op":"mcm","clk":"1000193217","pt":1580609333218,"mc":[{"id":"1.168119364","rc":[{"batl":[[0,4.5,57.42],[1,6,66.85],[2,1000,0.02]],"ltp":3.55,"tv":259.83,"id":23010367}]}]}
{"op":"mcm","clk":"1000193284","pt":1580609335015,"mc":[{"id":"1.168119364","rc":[{"trd":[[1.39,42.11]],"batl":[[0,1.39,11.69]],"ltp":1.39,"tv":1244.36,"id":27652444}],"tv":1504.2}]}
{"op":"mcm","clk":"1000193407","pt":1580609339025,"mc":[{"id":"1.168119364","rc":[{"batb":[[0,1.3,45.13],[1,1.22,53.76],[2,1.02,1]],"ltp":1.39,"tv":1244.36,"id":27652444}]}]}
{"op":"mcm","clk":"1000193508","pt":1580609341653,"mc":[{"id":"1.168119364","rc":[{"batl":[[0,1.46,37.86],[1,1.99,15.14],[2,1000,0.02]],"ltp":1.39,"tv":1244.36,"id":27652444}]}]}
{"op":"mcm","clk":"1000194003","pt":1580609353376,"mc":[{"id":"1.168119364","rc":[{"batl":[[2,1000,3.86]],"ltp":1.39,"tv":1244.36,"id":27652444}]}]}
{"op":"mcm","clk":"1000194032","pt":1580609354158,"mc":[{"id":"1.168119364","rc":[{"batl":[[2,1000,0.02]],"ltp":1.39,"tv":1244.36,"id":27652444}]}]}
{"op":"mcm","clk":"1000194164","pt":1580609357355,"mc":[{"id":"1.168119364","rc":[{"trd":[[1.3,1.62],[1.46,22.16]],"batb":[[0,1.3,44.32]],"batl":[[0,1.46,37.05]],"ltp":1.46,"tv":1247.6,"id":27652444}],"tv":1507.44}]}
{"op":"mcm","clk":"1000194853","pt":1580609377182,"mc":[{"id":"1.168119364","rc":[{"batl":[[0,6,66.85],[1,1000,0.02],[2,1000,0]],"ltp":3.55,"tv":259.83,"id":23010367}]}]}
{"op":"mcm","clk":"1000195388","pt":1580609389799,"mc":[{"id":"1.168119364","rc":[{"batl":[[0,1.99,15.14],[1,1000,0.02],[2,1000,0]],"ltp":1.46,"tv":1247.6,"id":27652444}]}]}
{"op":"mcm","clk":"1000195594","pt":1580609395134,"mc":[{"id":"1.168119364","rc":[{"batl":[[0,1.51,53.76],[1,1.99,15.14],[2,1000,0.02]],"ltp":1.46,"tv":1247.6,"id":27652444}]}]}
{"op":"mcm","clk":"1000195881","pt":1580609403310,"mc":[{"id":"1.168119364","rc":[{"batb":[[1,1.02,1],[2,1.01,15.54]],"ltp":3.55,"tv":259.83,"id":23010367}]}]}
{"op":"mcm","clk":"1000196159","pt":1580609410747,"mc":[{"id":"1.168119364","rc":[{"trd":[[1.3,90.22]],"batb":[[0,1.22,53.76],[1,1.02,1],[2,1.01,15.54]],"batl":[[0,1.3,57.03],[1,1.51,53.76],[2,1.99,15.14]],"ltp":1.3,"tv":1336.19,"id":27652444}],"tv":1596.03}]}
{"op":"mcm","clk":"1000196504","pt":1580609420542,"mc":[{"id":"1.168119364","rc":[{"trd":[[1.3,92.03]],"batl":[[0,1.3,56.12]],"ltp":1.3,"tv":1338.01,"id":27652444}],"tv":1597.85}]}
{"op":"mcm","clk":"1000197566","pt":1580609449274,"mc":[{"id":"1.168119364","rc":[{"batl":[[1,1.4,37.86],[2,1.51,53.76]],"ltp":1.3,"tv":1338.01,"id":27652444}]}]}
{"op":"mcm","clk":"1000198049","pt":1580609462287,"mc":[{"id":"1.168119364","rc":[{"trd":[[4.3,8.23]],"ltp":4.3,"tv":268.06,"id":23010367},{"trd":[[1.3,119.22]],"batl":[[0,1.3,28.93]],"ltp":1.3,"tv":1365.2,"id":27652444}],"tv":1633.27}]}
{"op":"mcm","clk":"1000199364","pt":1580609495139,"mc":[{"id":"1.168119364","rc":[{"batl":[[0,1000,0.02],[1,1000,0]],"ltp":4.3,"tv":268.06,"id":23010367}]}]}
{"op":"mcm","clk":"1000199514","pt":1580609498955,"mc":[{"id":"1.168119364","rc":[{"batl":[[0,5.5,73.14],[1,1000,0.02]],"ltp":4.3,"tv":268.06,"id":23010367}]}]}
{"op":"mcm","clk":"1000200328","pt":1580609518263,"mc":[{"id":"1.168119364","rc":[{"batb":[[0,3.2,27.98],[1,2.52,468.01],[2,1.02,1]],"ltp":4.3,"tv":268.06,"id":23010367}]}]}
{"op":"mcm","clk":"1000200857","pt":1580609532087,"mc":[{"id":"1.168119364","rc":[{"batb":[[0,1.23,25],[1,1.22,53.76],[2,1.02,1]],"ltp":1.3,"tv":1365.2,"id":27652444}]}]}
{"op":"mcm","clk":"1000201333","pt":1580609543520,"mc":[{"id":"1.168119364","rc":[{"trd":[[1.3,177.12]],"batb":[[0,1.31,8.9],[1,1.23,25],[2,1.22,53.76]],"batl":[[0,1.4,37.86],[1,1.51,53.76],[2,1.99,15.14]],"ltp":1.3,"tv":1423.1,"id":27652444}],"tv":1691.16}]}
{"op":"mcm","clk":"1000201411","pt":1580609545121,"mc":[{"id":"1.168119364","rc":[{"batb":[[0,1.23,25],[1,1.22,53.76],[2,1.02,1]],"ltp":1.3,"tv":1423.1,"id":27652444}]}]}
{"op":"mcm","clk":"1000201875","pt":1580609556100,"mc":[{"id":"1.168119364","rc":[{"batb":[[0,1.25,37.86],[1,1.23,25],[2,1.22,53.76]],"batl":[[0,1.51,53.76],[1,1.99,15.14],[2,1000,0.02]],"ltp":1.3,"tv":1423.1,"id":27652444}]}]}
{"op":"mcm","clk":"1000202064","pt":1580609560235,"mc":[{"id":"1.168119364","rc":[{"batl":[[0,1.45,37.86],[1,1.51,53.76],[2,1.99,15.14]],"ltp":1.3,"tv":1423.1,"id":27652444}]}]}
{"op":"mcm","clk":"1000202286","pt":1580609566006,"mc":[{"id":"1.168119364","rc":[{"batl":[[0,1.35,27.89],[1,1.45,37.86],[2,1.51,53.76]],"ltp":1.3,"tv":1423.1,"id":27652444}]}]}
{"op":"mcm","clk":"1000202330","pt":1580609567344,"mc":[{"id":"1.168119364","rc":[{"batl":[[0,1000,0.02],[1,1000,0]],"ltp":4.3,"tv":268.06,"id":23010367}]}]}
{"op":"mcm","clk":"1000202463","pt":1580609570741,"mc":[{"id":"1.168119364","rc":[{"batl":[[0,4.4,60.8],[1,4.9,79.78],[2,1000,0.02]],"ltp":4.3,"tv":268.06,"id":23010367}]}]}
{"op":"mcm","clk":"1000205313","pt":1580609636133,"mc":[{"id":"1.168119364","rc":[{"batl":[[0,4.9,79.78],[1,1000,0.02],[2,1000,0]],"ltp":4.3,"tv":268.06,"id":23010367}]}]}
{"op":"mcm","clk":"1000205458","pt":1580609639228,"mc":[{"id":"1.168119364","rc":[{"batl":[[0,4.2,60.8],[1,4.9,79.78],[2,1000,0.02]],"ltp":4.3,"tv":268.06,"id":23010367}]}]}
{"op":"mcm","clk":"1000206498","pt":1580609659571,"mc":[{"id":"1.168119364","rc":[{"trd":[[4.2,8.97]],"batl":[[0,4.2,51.83]],"ltp":4.2,"tv":277.03,"id":23010367},{"trd":[[1.31,28.74]],"ltp":1.31,"tv":1451.84,"id":27652444}],"tv":1728.87}]}
{"op":"mcm","clk":"1000206601","pt":1580609661735,"mc":[{"id":"1.168119364","rc":[{"batl":[[0,1.45,37.86],[1,1.51,53.76],[2,1.99,15.14]],"ltp":1.31,"tv":1451.84,"id":27652444}]}]}
{"op":"mcm","clk":"1000206672","pt":1580609663176,"mc":[{"id":"1.168119364","rc":[{"batl":[[0,4.9,79.78],[1,1000,0.02],[2,1000,0]],"ltp":4.2,"tv":277.03,"id":23010367}]}]}
{"op":"mcm","clk":"1000208716","pt":1580609704609,"mc":[{"id":"1.168119364","rc":[{"batl":[[0,1000,0.02],[1,1000,0]],"ltp":4.2,"tv":277.03,"id":23010367}]}]}
{"op":"mcm","clk":"1000208901","pt":1580609708425,"mc":[{"id":"1.168119364","rc":[{"batl":[[0,5.5,73.14],[1,1000,0.02]],"ltp":4.2,"tv":277.03,"id":23010367}]}]}
{"op":"mcm","clk":"1000209742","pt":1580609726452,"mc":[{"id":"1.168119364","rc":[{"batb":[[0,1.23,25],[1,1.22,53.76],[2,1.02,1]],"ltp":1.31,"tv":1451.84,"id":27652444}]}]}
{"op":"mcm","clk":"1000217101","pt":1580609895977,"mc":[{"id":"1.168119364","rc":[{"batl":[[0,1000,0.02],[1,1000,0]],"ltp":4.2,"tv":277.03,"id":23010367}]}]}
{"op":"mcm","clk":"1000217261","pt":1580609899480,"mc":[{"id":"1.168119364","rc":[{"batl":[[0,4.9,79.78],[1,1000,0.02]],"ltp":4.2,"tv":277.03,"id":23010367}]}]}
{"op":"mcm","clk":"1000217390","pt":1580609902681,"mc":[{"id":"1.168119364","rc":[{"batb":[[0,1.23,399.76]],"ltp":1.31,"tv":1451.84,"id":27652444}]}]}
{"op":"mcm","clk":"1000217402","pt":1580609902896,"mc":[{"id":"1.168119364","rc":[{"batb":[[0,1.23,25]],"ltp":1.31,"tv":1451.84,"id":27652444}]}]}
{"op":"mcm","clk":"1000217534","pt":1580609905981,"mc":[{"id":"1.168119364","rc":[{"batb":[[0,1.23,54.41]],"ltp":1.31,"tv":1451.84,"id":27652444}]}]}
{"op":"mcm","clk":"1000217963","pt":1580609916701,"mc":[{"id":"1.168119364","rc":[{"batb":[[0,1.23,25]],"ltp":1.31,"tv":1451.84,"id":27652444}]}]}
{"op":"mcm","clk":"1000222924","pt":1580610032070,"mc":[{"id":"1.168119364","rc":[{"batl":[[0,4.2,52.69],[1,4.9,79.78],[2,1000,0.02]],"ltp":4.2,"tv":277.03,"id":23010367}]}]}
{"op":"mcm","clk":"1000225453","pt":1580610091042,"mc":[{"id":"1.168119364","rc":[{"batl":[[0,4.9,79.78],[1,1000,0.02],[2,1000,0]],"ltp":4.2,"tv":277.03,"id":23010367}]}]}
{"op":"mcm","clk":"1000226871","pt":1580610126507,"mc":[{"id":"1.168119364","rc":[{"batb":[[1,1.02,1],[2,1.01,15.54]],"batl":[[0,1000,0.02],[1,1000,0]],"ltp":4.2,"tv":277.03,"id":23010367}]}]}
{"op":"mcm","clk":"1000226895","pt":1580610127078,"mc":[{"id":"1.168119364","rc":[{"batl":[[0,1.51,53.76],[1,1.99,15.14],[2,1000,0.02]],"ltp":1.31,"tv":1451.84,"id":27652444}]}]}
{"op":"mcm","clk":"1000227051","pt":1580610130474,"mc":[{"id":"1.168119364","rc":[{"batb":[[1,2.12,495],[2,1.02,1]],"batl":[[0,4.2,93.35],[1,1000,0.02]],"ltp":4.2,"tv":277.03,"id":23010367}]}]}
{"op":"mcm","clk":"1000228013","pt":1580610151544,"mc":[{"id":"1.168119364","rc":[{"batl":[[0,1000,0.02],[1,1000,0]],"ltp":4.2,"tv":277.03,"id":23010367}]}]}
{"op":"mcm","clk":"1000228150","pt":1580610155415,"mc":[{"id":"1.168119364","rc":[{"batl":[[0,3.9,99.98],[1,1000,0.02]],"ltp":4.2,"tv":277.03,"id":23010367}]}]}
{"op":"mcm","clk":"1000228312","pt":1580610159120,"mc":[{"id":"1.168119364","rc":[{"trd":[[3.2,35.37]],"batb":[[0,3.2,10.29]],"ltp":3.2,"tv":312.4,"id":23010367}],"tv":1764.25}]}
{"op":"mcm","clk":"1000228373","pt":1580610160514,"mc":[{"id":"1.168119364","rc":[{"batl":[[0,1000,0.02],[1,1000,0]],"ltp":3.2,"tv":312.4,"id":23010367}]}]}
{"op":"mcm","clk":"1000228562","pt":1580610164530,"mc":[{"id":"1.168119364","rc":[{"batl":[[0,4.6,85.78],[1,1000,0.02]],"ltp":3.2,"tv":312.4,"id":23010367}]}]}
{"op":"mcm","clk":"1000229268","pt":1580610179545,"mc":[{"id":"1.168119364","rc":[{"batb":[[1,1.02,1],[2,1.01,15.54]],"batl":[[0,1000,0.02],[1,1000,0]],"ltp":3.2,"tv":312.4,"id":23010367}]}]}
{"op":"mcm","clk":"1000229451","pt":1580610183564,"mc":[{"id":"1.168119364","rc":[{"batb":[[1,2.38,476.85],[2,1.02,1]],"batl":[[0,5.3,75.32],[1,1000,0.02]],"ltp":3.2,"tv":312.4,"id":23010367}]}]}
{"op":"mcm","clk":"1000230047","pt":1580610197563,"mc":[{"id":"1.168119364","rc":[{"batl":[[0,1000,0.02],[1,1000,0]],"ltp":3.2,"tv":312.4,"id":23010367}]}]}
{"op":"mcm","clk":"1000230223","pt":1580610201585,"mc":[{"id":"1.168119364","rc":[{"batl":[[0,4.9,79.79],[1,1000,0.02]],"ltp":3.2,"tv":312.4,"id":23010367}]}]}
{"op":"mcm","clk":"1000230608","pt":1580610209784,"mc":[{"id":"1.168119364","rc":[{"batb":[[2,1.2,50.1]],"ltp":1.31,"tv":1451.84,"id":27652444}]}]}
{"op":"mcm","clk":"1000230645","pt":1580610210892,"mc":[{"id":"1.168119364","rc":[{"batl":[[0,1000,0.02],[1,1000,0]],"ltp":3.2,"tv":312.4,"id":23010367}]}]}
{"op":"mcm","clk":"1000230810","pt":1580610214695,"mc":[{"id":"1.168119364","rc":[{"batl":[[0,4.6,85.78],[1,1000,0.02]],"ltp":3.2,"tv":312.4,"id":23010367}]}]}
{"op":"mcm","clk":"1000231214","pt":1580610224397,"mc":[{"id":"1.168119364","rc":[{"batl":[[1,5.1,97.57],[2,1000,0.02]],"ltp":3.2,"tv":312.4,"id":23010367}]}]}
{"op":"mcm","clk":"1000231320","pt":1580610227122,"mc":[{"id":"1.168119364","rc":[{"batl":[[1,1000,0.02],[2,1000,0]],"ltp":3.2,"tv":312.4,"id":23010367}]}]}
{"op":"mcm","clk":"1000231543","pt":1580610233711,"mc":[{"id":"1.168119364","rc":[{"batl":[[0,1000,0.02],[1,1000,0]],"ltp":3.2,"tv":312.4,"id":23010367}]}]}
{"op":"mcm","clk":"1000231721","pt":1580610237730,"mc":[{"id":"1.168119364","rc":[{"batl":[[0,5.3,75.32],[1,1000,0.02]],"ltp":3.2,"tv":312.4,"id":23010367}]}]}
{"op":"mcm","clk":"1000233316","pt":1580610272664,"mc":[{"id":"1.168119364","rc":[{"batb":[[0,3.25,20.29],[1,3.2,10.29],[2,2.38,476.85]],"ltp":3.2,"tv":312.4,"id":23010367}]}]}
{"op":"mcm","clk":"1000233325","pt":1580610272870,"mc":[{"id":"1.168119364","rc":[{"batb":[[0,3.2,10.29],[1,2.38,476.85],[2,1.02,1]],"ltp":3.2,"tv":312.4,"id":23010367}]}]}
{"op":"mcm","clk":"1000235051","pt":1580610315526,"mc":[{"id":"1.168119364","rc":[{"batl":[[0,1.43,37.86],[1,1.51,53.76],[2,1.99,15.14]],"ltp":1.31,"tv":1451.84,"id":27652444}]}]}
{"op":"mcm","clk":"1000235485","pt":1580610323826,"mc":[{"id":"1.168119364","rc":[{"batl":[[0,1000,0.02],[1,1000,0]],"ltp":3.2,"tv":312.4,"id":23010367}]}]}
{"op":"mcm","clk":"1000235694","pt":1580610327863,"mc":[{"id":"1.168119364","rc":[{"batl":[[0,4.9,79.79],[1,1000,0.02]],"ltp":3.2,"tv":312.4,"id":23010367}]}]}
{"op":"mcm","clk":"1000240406","pt":1580610431112,"mc":[{"id":"1.168119364","rc":[{"batl":[[0,1000,0.02],[1,1000,0]],"ltp":3.2,"tv":312.4,"id":23010367}]}]}
{"op":"mcm","clk":"1000240570","pt":1580610434577,"mc":[{"id":"1.168119364","rc":[{"batl":[[0,5.5,73.15],[1,1000,0.02]],"ltp":3.2,"tv":312.4,"id":23010367}]}]}
{"op":"mcm","clk":"1000240772","pt":1580610438595,"mc":[{"id":"1.168119364","rc":[{"batl":[[0,1.39,107.27],[1,1.43,37.86],[2,1.51,53.76]],"ltp":1.31,"tv":1451.84,"id":27652444}]}]}
{"op":"mcm","clk":"1000240785","pt":1580610438801,"mc":[{"id":"1.168119364","rc":[{"batl":[[0,1.43,37.86],[1,1.51,53.76],[2,1.99,15.14]],"ltp":1.31,"tv":1451.84,"id":27652444}]}]}
{"op":"mcm","clk":"1000241869","pt":1580610463120,"mc":[{"id":"1.168119364","rc":[{"batb":[[1,1.02,1],[2,1.01,15.54]],"ltp":3.2,"tv":312.4,"id":23010367}]}]}
{"op":"mcm","clk":"1000242015","pt":1580610466724,"mc":[{"id":"1.168119364","rc":[{"batb":[[1,2.52,470.85],[2,1.02,1]],"ltp":3.2,"tv":312.4,"id":23010367}]}]}
{"op":"mcm","clk":"1000242530","pt":1580610481161,"mc":[{"id":"1.168119364","rc":[{"batl":[[0,1000,0.02],[1,1000,0]],"ltp":3.2,"tv":312.4,"id":23010367}]}]}
{"op":"mcm","clk":"1000242714","pt":1580610484980,"mc":[{"id":"1.168119364","rc":[{"batl":[[0,4.9,79.79],[1,1000,0.02]],"ltp":3.2,"tv":312.4,"id":23010367}]}]}
{"op":"mcm","clk":"1000244324","pt":1580610521509,"mc":[{"id":"1.168119364","rc":[{"trd":[[3.3,11.45]],"ltp":3.3,"tv":323.86,"id":23010367},{"trd":[[1.43,26.45]],"batl":[[0,1.43,11.41]],"ltp":1.43,"tv":1478.29,"id":27652444}],"tv":1802.15}]}
{"op":"mcm","clk":"1000244850","pt":1580610534321,"mc":[{"id":"1.168119364","rc":[{"batl":[[0,1.4,800],[1,1.43,11.41],[2,1.51,53.76]],"ltp":1.43,"tv":1478.29,"id":27652444}]}]}
{"op":"mcm","clk":"1000246057","pt":1580610563168,"mc":[{"id":"1.168119364","rc":[{"batb":[[0,1.34,28.23],[1,1.23,25],[2,1.22,53.76]],"ltp":1.43,"tv":1478.29,"id":27652444}]}]}
{"op":"mcm","clk":"1000246691","pt":1580610578475,"mc":[{"id":"1.168119364","rc":[{"batb":[[0,2.52,470.85],[1,1.02,1],[2,1.01,15.54]],"ltp":3.3,"tv":323.86,"id":23010367}]}]}
{"op":"mcm","clk":"1000246811","pt":1580610581586,"mc":[{"id":"1.168119364","rc":[{"trd":[[3.95,7.59]],"ltp":3.95,"tv":331.45,"id":23010367},{"trd":[[1.34,105.56]],"batb":[[0,1.34,5.85]],"ltp":1.34,"tv":1500.67,"id":27652444}],"tv":1832.12}]}
{"op":"mcm","clk":"1000247218","pt":1580610590896,"mc":[{"id":"1.168119364","rc":[{"trd":[[1.34,117.1]],"batb":[[0,1.23,25.08],[1,1.22,53.76],[2,1.2,50.1]],"ltp":1.34,"tv":1512.21,"id":27652444}],"tv":1843.67}]}
{"op":"mcm","clk":"1000247464","pt":1580610596983,"mc":[{"id":"1.168119364","rc":[{"trd":[[1.4,0.72]],"batl":[[0,1.4,799.64]],"ltp":1.4,"tv":1512.93,"id":27652444}],"tv":1844.39}]}
{"op":"mcm","clk":"1000247595","pt":1580610599714,"mc":[{"id":"1.168119364","rc":[{"batb":[[0,1.02,1],[1,1.01,15.54],[2,1.01,0]],"batl":[[0,1000,0.02],[1,1000,0]],"ltp":3.95,"tv":331.45,"id":23010367},{"batb":[[0,1.27,37.94],[1,1.23,25],[2,1.22,53.76]],"ltp":1.4,"tv":1512.93,"id":27652444}]}]}
{"op":"mcm","clk":"1000247772","pt":1580610602819,"mc":[{"id":"1.168119364","rc":[{"batb":[[0,2.12,495],[1,1.02,1],[2,1.01,15.54]],"batl":[[0,4.2,93.35],[1,1000,0.02]],"ltp":3.95,"tv":331.45,"id":23010367}]}]}
{"op":"mcm","clk":"1000247827","pt":1580610603825,"mc":[{"id":"1.168119364","rc":[{"batl":[[1,1.51,53.76],[2,1.99,15.14]],"ltp":1.4,"tv":1512.93,"id":27652444}]}]}
{"op":"mcm","clk":"1000248417","pt":1580610615419,"mc":[{"id":"1.168119364","rc":[{"trd":[[1.4,100.72]],"batl":[[0,1.4,749.64]],"ltp":1.4,"tv":1612.93,"id":27652444}],"tv":1944.39}]}
{"op":"mcm","clk":"1000248704","pt":1580610621201,"mc":[{"id":"1.168119364","rc":[{"batb":[[0,1.32,53.85],[1,1.27,37.86],[2,1.23,25]],"ltp":1.4,"tv":1612.93,"id":27652444}]}]}
{"op":"mcm","clk":"1000248737","pt":1580610621820,"mc":[{"id":"1.168119364","rc":[{"batl":[[0,1.51,53.76],[1,1.99,15.14],[2,1000,0.02]],"ltp":1.4,"tv":1612.93,"id":27652444}]}]}
{"op":"mcm","clk":"1000249101","pt":1580610630318,"mc":[{"id":"1.168119364","rc":[{"batl":[[0,1000,0.02],[1,1000,0]],"ltp":3.95,"tv":331.45,"id":23010367},{"batl":[[0,1.99,15.14],[1,1000,0.02],[2,1000,0]],"ltp":1.4,"tv":1612.93,"id":27652444}]}]}
{"op":"mcm","clk":"1000249127","pt":1580610631156,"mc":[{"id":"1.168119364","rc":[{"batb":[[0,1.4,53.76],[1,1.32,53.85],[2,1.27,37.86]],"ltp":1.4,"tv":1612.93,"id":27652444}]}]}
{"op":"mcm","clk":"1000249251","pt":1580610633643,"mc":[{"id":"1.168119364","rc":[{"batl":[[0,1.68,53.76],[1,1.99,15.14],[2,1000,0.02]],"ltp":1.4,"tv":1612.93,"id":27652444}]}]}
{"op":"mcm","clk":"1000249263","pt":1580610633952,"mc":[{"id":"1.168119364","rc":[{"batl":[[0,3.65,108.1],[1,1000,0.02]],"ltp":3.95,"tv":331.45,"id":23010367},{"batb":[[0,1.4,203.76]],"ltp":1.4,"tv":1612.93,"id":27652444}]}]}
{"op":"mcm","clk":"1000249485","pt":1580610638546,"mc":[{"id":"1.168119364","rc":[{"batb":[[0,1.4,53.76]],"ltp":1.4,"tv":1612.93,"id":27652444}]}]}
{"op":"mcm","clk":"1000250041","pt":1580610650672,"mc":[{"id":"1.168119364","rc":[{"trd":[[2.46,36.72]],"batl":[[0,2.42,33.28],[1,3.65,108.1],[2,1000,0.02]],"ltp":2.46,"tv":368.17,"id":23010367},{"trd":[[1.68,53.76]],"batl":[[0,1.99,15.14],[1,1000,0.02],[2,1000,0]],"ltp":1.68,"tv":1666.7,"id":27652444}],"tv":2034.87}]}
{"op":"mcm","clk":"1000250229","pt":1580610654956,"mc":[{"id":"1.168119364","rc":[{"batl":[[1,1000,3.08]],"ltp":1.68,"tv":1666.7,"id":27652444}]}]}
{"op":"mcm","clk":"1000250310","pt":1580610656551,"mc":[{"id":"1.168119364","rc":[{"batl":[[1,1000,0.02]],"ltp":1.68,"tv":1666.7,"id":27652444}]}]}
{"op":"mcm","clk":"1000250338","pt":1580610657376,"mc":[{"id":"1.168119364","rc":[{"trd":[[2.42,35.34]],"batl":[[0,3.65,108.1],[1,1000,0.02],[2,1000,0]],"ltp":2.42,"tv":401.45,"id":23010367},{"trd":[[1.7,47.37]],"batl":[[0,1.7,6.39],[1,1.99,15.14],[2,1000,0.02]],"ltp":1.7,"tv":1714.07,"id":27652444}],"tv":2115.52}]}
{"op":"mcm","clk":"1000250436","pt":1580610659696,"mc":[{"id":"1.168119364","rc":[{"trd":[[2.46,36.74]],"batl":[[0,2.46,18.91],[1,3.65,108.1],[2,1000,0.02]],"ltp":2.46,"tv":401.47,"id":23010367},{"trd":[[1.68,53.79]],"ltp":1.68,"tv":1714.1,"id":27652444}],"tv":2115.58}]}
{"op":"mcm","clk":"1000251060","pt":1580610672682,"mc":[{"id":"1.168119364","rc":[{"trd":[[2.46,53.81]],"batl":[[0,2.46,1.84]],"ltp":2.46,"tv":418.54,"id":23010367},{"trd":[[1.68,78.78]],"ltp":1.68,"tv":1739.09,"id":27652444}],"tv":2157.63}]}
{"op":"mcm","clk":"1000251251","pt":1580610676613,"mc":[{"id":"1.168119364","rc":[{"batl":[[0,1000,0.02],[1,3.65,0],[2,1000,0]],"ltp":2.46,"tv":418.54,"id":23010367}]}]}
{"op":"mcm","clk":"1000251332","pt":1580610678195,"mc":[{"id":"1.168119364","rc":[{"batb":[[0,1.48,53.76],[1,1.4,53.76],[2,1.32,53.85]],"ltp":1.68,"tv":1739.09,"id":27652444}]}]}
{"op":"mcm","clk":"1000251395","pt":1580610679590,"mc":[{"id":"1.168119364","rc":[{"trd":[[2.42,37.18]],"ltp":2.42,"tv":420.38,"id":23010367},{"trd":[[1.7,49.99]],"batl":[[0,1.7,3.77]],"ltp":1.7,"tv":1741.71,"id":27652444}],"tv":2162.09}]}
{"op":"mcm","clk":"1000251429","pt":1580610680417,"mc":[{"id":"1.168119364","rc":[{"batl":[[0,4.2,93.35],[1,1000,0.02]],"ltp":2.42,"tv":420.38,"id":23010367}]}]}
{"op":"mcm","clk":"1000251681","pt":1580610685285,"mc":[{"id":"1.168119364","rc":[{"batl":[[0,1.7,57.53]],"ltp":1.7,"tv":1741.71,"id":27652444}]}]}
{"op":"mcm","clk":"1000251867","pt":1580610688898,"mc":[{"id":"1.168119364","rc":[{"batb":[[0,1.4,53.76],[1,1.32,53.85],[2,1.27,37.86]],"ltp":1.7,"tv":1741.71,"id":27652444}]}]}
{"op":"mcm","clk":"1000251928","pt":1580610690089,"mc":[{"id":"1.168119364","rc":[{"batb":[[0,1.54,53.76],[1,1.4,53.76],[2,1.32,53.85]],"ltp":1.7,"tv":1741.71,"id":27652444}]}]}
{"op":"mcm","clk":"1000252286","pt":1580610696711,"mc":[{"id":"1.168119364","rc":[{"trd":[[1.54,25.75]],"batb":[[0,1.54,40.89]],"ltp":1.54,"tv":1767.45,"id":27652444}],"tv":2187.84}]}
{"op":"mcm","clk":"1000252625","pt":1580610703624,"mc":[{"id":"1.168119364","rc":[{"trd":[[1.54,75.72]],"batb":[[0,1.54,15.9]],"ltp":1.54,"tv":1817.43,"id":27652444}],"tv":2237.82}]}
{"op":"mcm","clk":"1000252692","pt":1580610704616,"mc":[{"id":"1.168119364","rc":[{"trd":[[1.54,107.53]],"batb":[[0,1.4,53.76],[1,1.32,53.85],[2,1.27,37.86]],"batl":[[0,1.48,67.27],[1,1.7,57.53],[2,1.99,15.14]],"ltp":1.54,"tv":1849.24,"id":27652444}],"tv":2269.62}]}
{"op":"mcm","clk":"1000252973","pt":1580610709351,"mc":[{"id":"1.168119364","rc":[{"batb":[[0,1.32,53.85],[1,1.27,37.86],[2,1.23,25]],"ltp":1.54,"tv":1849.24,"id":27652444}]}]}
{"op":"mcm","clk":"1000253041","pt":1580610710640,"mc":[{"id":"1.168119364","rc":[{"trd":[[1.48,125.19]],"batl":[[0,1.48,4.69]],"ltp":1.48,"tv":1974.41,"id":27652444}],"tv":2394.79}]}
{"op":"mcm","clk":"1000253330","pt":1580610716728,"mc":[{"id":"1.168119364","rc":[{"batl":[[0,1.7,57.53],[1,1.99,15.14],[2,1000,0.02]],"ltp":1.48,"tv":1974.41,"id":27652444}]}]}
{"op":"mcm","clk":"1000253410","pt":1580610718540,"mc":[{"id":"1.168119364","rc":[{"batb":[[0,1.32,53.76]],"ltp":1.48,"tv":1974.41,"id":27652444}]}]}
{"op":"mcm","clk":"1000253471","pt":1580610719831,"mc":[{"id":"1.168119364","rc":[{"batl":[[0,1.39,4.69],[1,1.7,57.53],[2,1.99,15.14]],"ltp":1.48,"tv":1974.41,"id":27652444}]}]}
{"op":"mcm","clk":"1000253887","pt":1580610727166,"mc":[{"id":"1.168119364","rc":[{"batl":[[0,1.7,57.53],[1,1.99,15.14],[2,1000,0.02]],"ltp":1.48,"tv":1974.41,"id":27652444}]}]}
{"op":"mcm","clk":"1000254071","pt":1580610730284,"mc":[{"id":"1.168119364","rc":[{"trd":[[1.32,9.38]],"batb":[[0,1.32,49.08]],"ltp":1.32,"tv":1983.78,"id":27652444}],"tv":2404.17}]}
{"op":"mcm","clk":"1000254313","pt":1580610734679,"mc":[{"id":"1.168119364","rc":[{"batb":[[0,1.02,1],[1,1.01,15.54],[2,1.01,0]],"batl":[[0,1000,0.02],[1,1000,0]],"ltp":2.42,"tv":420.38,"id":23010367}]}]}
{"op":"mcm","clk":"1000254410","pt":1580610736955,"mc":[{"id":"1.168119364","rc":[{"batb":[[0,1.27,37.86],[1,1.23,25],[2,1.22,53.76]],"ltp":1.32,"tv":1983.78,"id":27652444}]}]}
{"op":"mcm","clk":"1000254484","pt":1580610738660,"mc":[{"id":"1.168119364","rc":[{"batb":[[0,2.38,476.85],[1,1.02,1],[2,1.01,15.54]],"batl":[[0,5.3,75.32],[1,1000,0.02]],"ltp":2.42,"tv":420.38,"id":23010367}]}]}
{"op":"mcm","clk":"1000254769","pt":1580610745161,"mc":[{"id":"1.168119364","rc":[{"batl":[[0,1.44,53.76],[1,1.7,57.53],[2,1.99,15.14]],"ltp":1.32,"tv":1983.78,"id":27652444}]}]}
{"op":"mcm","clk":"1000255339","pt":1580610757479,"mc":[{"id":"1.168119364","rc":[{"batb":[[0,1.23,25],[1,1.22,53.76],[2,1.2,50.1]],"batl":[[0,1.27,73.94],[1,1.44,53.76],[2,1.7,57.53]],"ltp":1.32,"tv":1983.78,"id":27652444}]}]}
{"op":"mcm","clk":"1000255669","pt":1580610764698,"mc":[{"id":"1.168119364","rc":[{"batl":[[0,1.44,53.76],[1,1.7,57.53],[2,1.99,15.14]],"ltp":1.32,"tv":1983.78,"id":27652444}]}]}
{"op":"mcm","clk":"1000255785","pt":1580610767836,"mc":[{"id":"1.168119364","rc":[{"trd":[[5.3,11.36]],"batl":[[0,5.3,63.96]],"ltp":5.3,"tv":431.74,"id":23010367},{"trd":[[1.23,98.94]],"batb":[[0,1.22,53.76],[1,1.2,50.1],[2,1.01,16.44]],"ltp":1.23,"tv":2082.72,"id":27652444}],"tv":2514.47}]}
{"op":"mcm","clk":"1000255849","pt":1580610769237,"mc":[{"id":"1.168119364","rc":[{"batb":[[0,1.24,53.76],[1,1.22,53.76],[2,1.2,50.1]],"batl":[[1,1.99,15.14],[2,1000,0.02]],"ltp":1.23,"tv":2082.72,"id":27652444}]}]}
{"op":"mcm","clk":"1000256539","pt":1580610785115,"mc":[{"id":"1.168119364","rc":[{"batb":[[0,1.24,107.53]],"ltp":1.23,"tv":2082.72,"id":27652444}]}]}
{"op":"mcm","clk":"1000256782","pt":1580610790732,"mc":[{"id":"1.168119364","rc":[{"batb":[[0,1.02,1],[1,1.01,15.54],[2,1.01,0]],"batl":[[0,1000,0.02],[1,1000,0]],"ltp":5.3,"tv":431.74,"id":23010367}]}]}
{"op":"mcm","clk":"1000256887","pt":1580610793351,"mc":[{"id":"1.168119364","rc":[{"batl":[[1,1.51,45.43],[2,1.99,15.14]],"ltp":1.23,"tv":2082.72,"id":27652444}]}]}
{"op":"mcm","clk":"1000257008","pt":1580610796449,"mc":[{"id":"1.168119364","rc":[{"batb":[[0,1.22,53.76],[1,1.2,50.1],[2,1.01,16.44]],"batl":[[0,1.44,54.78]],"ltp":1.23,"tv":2082.72,"id":27652444}]}]}
{"op":"mcm","clk":"1000257033","pt":1580610796961,"mc":[{"id":"1.168119364","rc":[{"batb":[[0,1.24,1.01],[1,1.22,53.76],[2,1.2,50.1]],"ltp":1.23,"tv":2082.72,"id":27652444}]}]}
{"op":"mcm","clk":"1000257132","pt":1580610799241,"mc":[{"id":"1.168119364","rc":[{"batb":[[1,1.23,107.53]],"ltp":1.23,"tv":2082.72,"id":27652444}]}]}
{"op":"mcm","clk":"1000257235","pt":1580610801865,"mc":[{"id":"1.168119364","rc":[{"batb":[[2,1.2,103.86]],"ltp":1.23,"tv":2082.72,"id":27652444}]}]}
{"op":"mcm","clk":"1000258230","pt":1580610822977,"mc":[{"id":"1.168119364","rc":[{"batb":[[0,1.26,1.91],[1,1.24,1.01],[2,1.23,107.53]],"ltp":1.23,"tv":2082.72,"id":27652444}]}]}
{"op":"mcm","clk":"1000258297","pt":1580610824172,"mc":[{"id":"1.168119364","rc":[{"batl":[[0,1.44,53.76]],"ltp":1.23,"tv":2082.72,"id":27652444}]}]}
{"op":"mcm","clk":"1000258462","pt":1580610827278,"mc":[{"id":"1.168119364","rc":[{"batl":[[0,1.43,1.01],[1,1.44,53.76],[2,1.51,45.43]],"ltp":1.23,"tv":2082.72,"id":27652444}]}]}
{"op":"mcm","clk":"1000260391","pt":1580610863238,"mc":[{"id":"1.168119364","rc":[{"batl":[[0,1.44,53.76],[1,1.51,45.43],[2,1.99,15.14]],"ltp":1.23,"tv":2082.72,"id":27652444}]}]}
{"op":"mcm","clk":"1000260562","pt":1580610866339,"mc":[{"id":"1.168119364","rc":[{"batl":[[0,1.42,1.01],[1,1.44,53.76],[2,1.51,45.43]],"ltp":1.23,"tv":2082.72,"id":27652444}]}]}
{"op":"mcm","clk":"1000261693","pt":1580610891277,"mc":[{"id":"1.168119364","rc":[{"batb":[[1,1.23,107.53],[2,1.2,103.86]],"ltp":1.23,"tv":2082.72,"id":27652444}]}]}
{"op":"mcm","clk":"1000261851","pt":1580610894375,"mc":[{"id":"1.168119364","rc":[{"batb":[[1,1.25,1.01],[2,1.23,107.53]],"ltp":1.23,"tv":2082.72,"id":27652444}]}]}
{"op":"mcm","clk":"1000262761","pt":1580610913696,"mc":[{"id":"1.168119364","rc":[{"trd":[[3.25,23.82],[3.35,0.43]],"batl":[[0,3.15,775.75],[1,1000,0.02]],"ltp":3.25,"tv":455.99,"id":23010367},{"trd":[[1.42,1.01],[1.44,53.76]],"batl":[[0,1.51,45.43],[1,1.99,15.14],[2,1000,0.02]],"ltp":1.44,"tv":2137.5,"id":27652444}],"tv":2593.49}]}
{"op":"mcm","clk":"1000263054","pt":1580610919541,"mc":[{"id":"1.168119364","rc":[{"batl":[[0,1.99,15.14],[1,1000,0.02],[2,1000,0]],"ltp":1.44,"tv":2137.5,"id":27652444}]}]}
{"op":"mcm","clk":"1000263180","pt":1580610922636,"mc":[{"id":"1.168119364","rc":[{"trd":[[3.15,30.58]],"batl":[[0,3.15,754.69]],"ltp":3.15,"tv":477.05,"id":23010367},{"trd":[[1.46,67.6]],"ltp":1.46,"tv":2182.93,"id":27652444}],"tv":2659.99}]}
{"op":"mcm","clk":"1000263331","pt":1580610926342,"mc":[{"id":"1.168119364","rc":[{"trd":[[3.15,48.13]],"batl":[[0,3.15,737.14]],"ltp":3.15,"tv":494.6,"id":23010367},{"trd":[[1.46,105.46]],"ltp":1.46,"tv":2220.79,"id":27652444}],"tv":2715.4}]}
{"op":"mcm","clk":"1000263534","pt":1580610930515,"mc":[{"id":"1.168119364","rc":[{"trd":[[3.15,94.48]],"batl":[[0,3.15,690.79]],"ltp":3.15,"tv":540.95,"id":23010367},{"trd":[[1.46,205.46]],"ltp":1.46,"tv":2320.79,"id":27652444}],"tv":2861.75}]}
{"op":"mcm","clk":"1000263568","pt":1580610931136,"mc":[{"id":"1.168119364","rc":[{"batl":[[0,1.64,60.58],[1,1.99,15.14],[2,1000,0.02]],"ltp":1.46,"tv":2320.79,"id":27652444}]}]}
{"op":"mcm","clk":"1000263960","pt":1580610939628,"mc":[{"id":"1.168119364","rc":[{"batl":[[0,1000,0.02],[1,1000,0]],"ltp":3.15,"tv":540.95,"id":23010367}]}]}
{"op":"mcm","clk":"1000265018","pt":1580610961054,"mc":[{"id":"1.168119364","rc":[{"batl":[[0,1.51,84.44],[1,1.64,60.58],[2,1.99,15.14]],"ltp":1.46,"tv":2320.79,"id":27652444}]}]}
{"op":"mcm","clk":"1000265388","pt":1580610967662,"mc":[{"id":"1.168119364","rc":[{"batl":[[0,1.49,53.76],[1,1.51,84.44],[2,1.64,60.58]],"ltp":1.46,"tv":2320.79,"id":27652444}]}]}
{"op":"mcm","clk":"1000265416","pt":1580610968179,"mc":[{"id":"1.168119364","rc":[{"trd":[[3,26.78]],"ltp":3.0,"tv":543.48,"id":23010367},{"trd":[[1.49,5.1]],"batl":[[0,1.49,48.66]],"ltp":1.49,"tv":2325.9,"id":27652444}],"tv":2869.39}]}
{"op":"mcm","clk":"1000265584","pt":1580610971795,"mc":[{"id":"1.168119364","rc":[{"batl":[[2,1.99,15.14]],"ltp":1.49,"tv":2325.9,"id":27652444}]}]}
{"op":"mcm","clk":"1000265998","pt":1580610979675,"mc":[{"id":"1.168119364","rc":[{"batl":[[0,4,700],[1,1000,0.02]],"ltp":3.0,"tv":543.48,"id":23010367}]}]}
{"op":"mcm","clk":"1000266247","pt":1580610985512,"mc":[{"id":"1.168119364","rc":[{"batb":[[0,1.4,100],[1,1.26,1.91],[2,1.25,1.01]],"ltp":1.49,"tv":2325.9,"id":27652444}]}]}
{"op":"mcm","clk":"1000266589","pt":1580610993296,"mc":[{"id":"1.168119364","rc":[{"trd":[[3,29.31]],"ltp":3.0,"tv":546.02,"id":23010367},{"trd":[[1.49,10.21]],"batl":[[0,1.49,43.56]],"ltp":1.49,"tv":2331.0,"id":27652444}],"tv":2877.02}]}
{"op":"mcm","clk":"1000266665","pt":1580610994833,"mc":[{"id":"1.168119364","rc":[{"batl":[[1,4.4,35.59],[2,1000,0.02]],"ltp":3.0,"tv":546.02,"id":23010367}]}]}
{"op":"mcm","clk":"1000266802","pt":1580610999307,"mc":[{"id":"1.168119364","rc":[{"batl":[[0,1.49,97.32]],"ltp":1.49,"tv":2331.0,"id":27652444}]}]}
{"op":"mcm","clk":"1000266891","pt":1580611001717,"mc":[{"id":"1.168119364","rc":[{"batb":[[0,1.26,1.91],[1,1.25,1.01],[2,1.23,107.53]],"ltp":1.49,"tv":2331.0,"id":27652444}]}]}
{"op":"mcm","clk":"1000267024","pt":1580611004809,"mc":[{"id":"1.168119364","rc":[{"batb":[[0,1.35,100],[1,1.26,1.91],[2,1.25,1.01]],"ltp":1.49,"tv":2331.0,"id":27652444}]}]}
{"op":"mcm","clk":"1000267255","pt":1580611011438,"mc":[{"id":"1.168119364","rc":[{"batl":[[0,1.49,106.41]],"ltp":1.49,"tv":2331.0,"id":27652444}]}]}
{"op":"mcm","clk":"1000267327","pt":1580611012933,"mc":[{"id":"1.168119364","rc":[{"trd":[[3.9,52.18]],"batb":[[0,3.05,71.18],[1,1.02,1],[2,1.01,15.54]],"ltp":3.9,"tv":569.61,"id":23010367},{"trd":[[1.35,68.2]],"batb":[[0,1.35,31.8]],"ltp":1.35,"tv":2399.2,"id":27652444}],"tv":2968.82}]}
{"op":"mcm","clk":"1000267449","pt":1580611015653,"mc":[{"id":"1.168119364","rc":[{"batb":[[2,1.23,107.53]],"ltp":1.35,"tv":2399.2,"id":27652444}]}]}
{"op":"mcm","clk":"1000267587","pt":1580611018752,"mc":[{"id":"1.168119364","rc":[{"batb":[[1,1.26,2.93]],"ltp":1.35,"tv":2399.2,"id":27652444}]}]}
{"op":"mcm","clk":"1000267663","pt":1580611021065,"mc":[{"id":"1.168119364","rc":[{"trd":[[3.9,52.77]],"ltp":3.9,"tv":570.2,"id":23010367},{"trd":[[1.35,69.9]],"batb":[[0,1.35,30.1],[1,1.26,1.91]],"ltp":1.35,"tv":2400.9,"id":27652444}],"tv":2971.1}]}
{"op":"mcm","clk":"1000267737","pt":1580611022729,"mc":[{"id":"1.168119364","rc":[{"batb":[[0,1.35,75.53]],"ltp":1.35,"tv":2400.9,"id":27652444}]}]}
{"op":"mcm","clk":"1000267787","pt":1580611024025,"mc":[{"id":"1.168119364","rc":[{"batb":[[1,1.27,1.01],[2,1.26,1.91]],"ltp":1.35,"tv":2400.9,"id":27652444}]}]}
{"op":"mcm","clk":"1000267892","pt":1580611027037,"mc":[{"id":"1.168119364","rc":[{"batb":[[1,1.26,1.91],[2,1.23,107.53]],"ltp":1.35,"tv":2400.9,"id":27652444}]}]}
{"op":"mcm","clk":"1000268019","pt":1580611030131,"mc":[{"id":"1.168119364","rc":[{"batb":[[1,1.28,1.01],[2,1.26,1.91]],"ltp":1.35,"tv":2400.9,"id":27652444}]}]}
{"op":"mcm","clk":"1000268240","pt":1580611036493,"mc":[{"id":"1.168119364","rc":[{"batl":[[0,4.4,35.59],[1,1000,0.02],[2,1000,0]],"ltp":3.9,"tv":570.2,"id":23010367}]}]}
{"op":"mcm","clk":"1000268736","pt":1580611050553,"mc":[{"id":"1.168119364","rc":[{"batb":[[2,1.01,12.51]],"ltp":3.9,"tv":570.2,"id":23010367}]}]}
{"op":"mcm","clk":"1000269030","pt":1580611059673,"mc":[{"id":"1.168119364","rc":[{"trd":[[3.05,5.07]],"batb":[[0,3.05,68.64]],"ltp":3.05,"tv":575.27,"id":23010367}],"tv":2976.17}]}
{"op":"mcm","clk":"1000269544","pt":1580611073349,"mc":[{"id":"1.168119364","rc":[{"batb":[[1,1.3,37.86],[2,1.28,1.01]],"ltp":1.35,"tv":2400.9,"id":27652444}]}]}
{"op":"mcm","clk":"1000270078","pt":1580611087301,"mc":[{"id":"1.168119364","rc":[{"batb":[[2,1.26,1.91]],"ltp":1.35,"tv":2400.9,"id":27652444}]}]}
{"op":"mcm","clk":"1000270188","pt":1580611090399,"mc":[{"id":"1.168119364","rc":[{"batb":[[2,1.29,1.01]],"ltp":1.35,"tv":2400.9,"id":27652444}]}]}
{"op":"mcm","clk":"1000270668","pt":1580611104036,"mc":[{"id":"1.168119364","rc":[{"batb":[[0,1.35,45.43]],"ltp":1.35,"tv":2400.9,"id":27652444}]}]}
{"op":"mcm","clk":"1000270756","pt":1580611105903,"mc":[{"id":"1.168119364","rc":[{"batb":[[0,3.1,247.52],[1,3.05,68.64],[2,1.02,1]],"ltp":3.05,"tv":575.27,"id":23010367}]}]}
{"op":"mcm","clk":"1000271344","pt":1580611122039,"mc":[{"id":"1.168119364","rc":[{"batb":[[2,1.26,1.91]],"ltp":1.35,"tv":2400.9,"id":27652444}]}]}
{"op":"mcm","clk":"1000271465","pt":1580611125130,"mc":[{"id":"1.168119364","rc":[{"batb":[[0,1.35,46.45]],"ltp":1.35,"tv":2400.9,"id":27652444}]}]}
{"op":"mcm","clk":"1000271573","pt":1580611128224,"mc":[{"id":"1.168119364","rc":[{"batl":[[0,1.51,84.44],[1,1.99,15.14],[2,1000,0.02]],"ltp":1.35,"tv":2400.9,"id":27652444}]}]}
{"op":"mcm","clk":"1000271677","pt":1580611131367,"mc":[{"id":"1.168119364","rc":[{"batl":[[0,1.47,106.41],[1,1.51,84.44],[2,1.99,15.14]],"ltp":1.35,"tv":2400.9,"id":27652444}]}]}
{"op":"mcm","clk":"1000271699","pt":1580611131832,"mc":[{"id":"1.168119364","rc":[{"batb":[[0,1.35,1.01]],"ltp":1.35,"tv":2400.9,"id":27652444}]}]}
{"op":"mcm","clk":"1000272436","pt":1580611149770,"mc":[{"id":"1.168119364","rc":[{"batb":[[0,1.35,31.11]],"ltp":1.35,"tv":2400.9,"id":27652444}]}]}
{"op":"mcm","clk":"1000272674","pt":1580611155973,"mc":[{"id":"1.168119364","rc":[{"batb":[[1,1.02,1],[2,1.01,12.51]],"ltp":3.05,"tv":575.27,"id":23010367}]}]}
{"op":"mcm","clk":"1000272775","pt":1580611159106,"mc":[{"id":"1.168119364","rc":[{"batb":[[0,3.15,68.64],[1,3.1,247.52],[2,1.02,1]],"ltp":3.05,"tv":575.27,"id":23010367}]}]}
{"op":"mcm","clk":"1000273650","pt":1580611181743,"mc":[{"id":"1.168119364","rc":[{"batb":[[1,1.02,1],[2,1.01,12.51]],"ltp":3.05,"tv":575.27,"id":23010367}]}]}
{"op":"mcm","clk":"1000273769","pt":1580611185208,"mc":[{"id":"1.168119364","rc":[{"batb":[[0,3.2,247.52],[1,3.15,68.64],[2,1.02,1]],"ltp":3.05,"tv":575.27,"id":23010367}]}]}
{"op":"mcm","clk":"1000274237","pt":1580611196323,"mc":[{"id":"1.168119364","rc":[{"batb":[[1,1.02,1],[2,1.01,12.51]],"ltp":3.05,"tv":575.27,"id":23010367}]}]}
{"op":"mcm","clk":"1000274356","pt":1580611199464,"mc":[{"id":"1.168119364","rc":[{"batb":[[0,1.02,1],[1,1.01,12.51],[2,1.01,0]],"ltp":3.05,"tv":575.27,"id":23010367}]}]}
{"op":"mcm","clk":"1000274569","pt":1580611205144,"mc":[{"id":"1.168119364","rc":[{"trd":[[1.47,10.24]],"batl":[[0,1.47,101.29]],"ltp":1.47,"tv":2411.14,"id":27652444}],"tv":2986.41}]}
{"op":"mcm","clk":"1000274768","pt":1580611210079,"mc":[{"id":"1.168119364","rc":[{"trd":[[1.47,10.51]],"batl":[[0,1.47,101.15]],"ltp":1.47,"tv":2411.41,"id":27652444}],"tv":2986.68}]}
{"op":"mcm","clk":"1000275199","pt":1580611219876,"mc":[{"id":"1.168119364","rc":[{"batb":[[0,1.35,68.97]],"ltp":1.47,"tv":2411.41,"id":27652444}]}]}
{"op":"mcm","clk":"1000275558","pt":1580611228284,"mc":[{"id":"1.168119364","rc":[{"batb":[[0,3.15,282.88],[1,1.02,1],[2,1.01,12.51]],"ltp":3.05,"tv":575.27,"id":23010367}]}]}
{"op":"mcm","clk":"1000277084","pt":1580611268901,"mc":[{"id":"1.168119364","rc":[{"batb":[[0,3.2,39.73],[1,3.15,282.88],[2,1.02,1]],"ltp":3.05,"tv":575.27,"id":23010367}]}]}
{"op":"mcm","clk":"1000277492","pt":1580611281143,"mc":[{"id":"1.168119364","rc":[{"batb":[[1,1.02,1],[2,1.01,12.51]],"ltp":3.05,"tv":575.27,"id":23010367}]}]}
{"op":"mcm","clk":"1000278295","pt":1580611301857,"mc":[{"id":"1.168119364","rc":[{"batl":[[0,1000,0.02],[1,1000,0]],"ltp":3.05,"tv":575.27,"id":23010367}]}]}
{"op":"mcm","clk":"1000278351","pt":1580611303497,"mc":[{"id":"1.168119364","rc":[{"batb":[[0,1.02,1],[1,1.01,12.51],[2,1.01,0]],"ltp":3.05,"tv":575.27,"id":23010367}]}]}
{"op":"mcm","clk":"1000278478","pt":1580611307598,"mc":[{"id":"1.168119364","rc":[{"batb":[[0,2.52,494.63],[1,1.02,1],[2,1.01,12.51]],"batl":[[0,6,58.17],[1,1000,0.02]],"ltp":3.05,"tv":575.27,"id":23010367}]}]}
{"op":"mcm","clk":"1000279144","pt":1580611326607,"mc":[{"id":"1.168119364","rc":[{"batb":[[0,1.35,31.11]],"ltp":1.47,"tv":2411.41,"id":27652444}]}]}
{"op":"mcm","clk":"1000279185","pt":1580611327684,"mc":[{"id":"1.168119364","rc":[{"batb":[[0,3.25,38.85],[1,2.52,494.63],[2,1.02,1]],"ltp":3.05,"tv":575.27,"id":23010367}]}]}
{"op":"mcm","clk":"1000279258","pt":1580611329694,"mc":[{"id":"1.168119364","rc":[{"batl":[[0,1.51,84.44],[1,1.99,15.14],[2,1000,0.02]],"ltp":1.47,"tv":2411.41,"id":27652444}]}]}
{"op":"mcm","clk":"1000279455","pt":1580611334524,"mc":[{"id":"1.168119364","rc":[{"batl":[[0,1.43,37.86],[1,1.51,84.44],[2,1.99,15.14]],"ltp":1.47,"tv":2411.41,"id":27652444}]}]}
{"op":"mcm","clk":"1000279627","pt":1580611338535,"mc":[{"id":"1.168119364","rc":[{"batb":[[0,2.52,494.63],[1,1.02,1],[2,1.01,12.51]],"ltp":3.05,"tv":575.27,"id":23010367}]}]}
{"op":"mcm","clk":"1000279724","pt":1580611340643,"mc":[{"id":"1.168119364","rc":[{"batb":[[0,3.4,36.42],[1,2.52,494.63],[2,1.02,1]],"ltp":3.05,"tv":575.27,"id":23010367},{"batb":[[0,1.35,1.01]],"ltp":1.47,"tv":2411.41,"id":27652444}]}]}
{"op":"mcm","clk":"1000280039","pt":1580611348917,"mc":[{"id":"1.168119364","rc":[{"batb":[[1,1.02,1],[2,1.01,12.51]],"batl":[[0,1000,0.02],[1,1000,0]],"ltp":3.05,"tv":575.27,"id":23010367}]}]}
{"op":"mcm","clk":"1000281118","pt":1580611373684,"mc":[{"id":"1.168119364","rc":[{"trd":[[3.9,53.12]],"batb":[[0,4,28.79],[1,3.4,36.42],[2,2.9,473.95]],"batl":[[0,8.6,48.14],[1,1000,0.02]],"ltp":3.9,"tv":575.62,"id":23010367},{"trd":[[1.35,70.91]],"batb":[[0,1.3,37.86],[1,1.26,1.91],[2,1.23,107.53]],"ltp":1.35,"tv":2412.42,"id":27652444}],"tv":2988.05}]}
{"op":"mcm","clk":"1000281155","pt":1580611374661,"mc":[{"id":"1.168119364","rc":[{"batb":[[0,1.26,1.91],[1,1.23,107.53],[2,1.2,103.86]],"ltp":1.35,"tv":2412.42,"id":27652444}]}]}
{"op":"mcm","clk":"1000281157","pt":1580611374765,"mc":[{"id":"1.168119364","rc":[{"batb":[[0,4.4,25.71],[1,4,28.79],[2,3.4,36.42]],"ltp":3.9,"tv":575.62,"id":23010367}]}]}
{"op":"mcm","clk":"1000281229","pt":1580611376257,"mc":[{"id":"1.168119364","rc":[{"batb":[[0,4,28.79],[1,3.4,36.42],[2,2.9,473.95]],"ltp":3.9,"tv":575.62,"id":23010367}]}]}
{"op":"mcm","clk":"1000281260","pt":1580611376977,"mc":[{"id":"1.168119364","rc":[{"batb":[[1,1.2,103.86],[2,1.01,13.41]],"ltp":1.35,"tv":2412.42,"id":27652444}]}]}
{"op":"mcm","clk":"1000281439","pt":1580611381296,"mc":[{"id":"1.168119364","rc":[{"batb":[[1,2.9,473.95],[2,1.02,1]],"ltp":3.9,"tv":575.62,"id":23010367},{"batl":[[0,1.3,100],[1,1.43,37.86],[2,1.51,84.44]],"ltp":1.35,"tv":2412.42,"id":27652444}]}]}
{"op":"mcm","clk":"1000281584","pt":1580611384488,"mc":[{"id":"1.168119364","rc":[{"batb":[[0,2.9,473.95],[1,1.02,1],[2,1.01,12.51]],"ltp":3.9,"tv":575.62,"id":23010367}]}]}
{"op":"mcm","clk":"1000281674","pt":1580611386091,"mc":[{"id":"1.168119364","rc":[{"batb":[[0,3.75,31.79],[1,2.9,473.95],[2,1.02,1]],"ltp":3.9,"tv":575.62,"id":23010367}]}]}
{"op":"mcm","clk":"1000282052","pt":1580611395596,"mc":[{"id":"1.168119364","rc":[{"batb":[[1,1.2,50.1]],"ltp":1.35,"tv":2412.42,"id":27652444}]}]}
{"op":"mcm","clk":"1000282153","pt":1580611397806,"mc":[{"id":"1.168119364","rc":[{"trd":[[1.2,100.2],[1.26,3.82]],"batb":[[0,1.01,13.41],[1,1.2,0],[2,1.01,0]],"batl":[[0,1.2,947.99],[1,1.3,100],[2,1.43,37.86]],"ltp":1.2,"tv":2516.45,"id":27652444}],"tv":3092.07}]}
{"op":"mcm","clk":"1000282567","pt":1580611407218,"mc":[{"id":"1.168119364","rc":[{"batb":[[0,1.14,37.86],[1,1.01,13.41]],"ltp":1.2,"tv":2516.45,"id":27652444}]}]}
{"op":"mcm","clk":"1000282622","pt":1580611408298,"mc":[{"id":"1.168119364","rc":[{"batb":[[0,1.14,662.26]],"batl":[[1,1.43,37.86],[2,1.51,84.44]],"ltp":1.2,"tv":2516.45,"id":27652444}]}]}
{"op":"mcm","clk":"1000282997","pt":1580611417517,"mc":[{"id":"1.168119364","rc":[{"batb":[[0,1.14,37.86]],"ltp":1.2,"tv":2516.45,"id":27652444}]}]}
{"op":"mcm","clk":"1000283049","pt":1580611418700,"mc":[{"id":"1.168119364","rc":[{"batl":[[0,1000,0.02],[1,1000,0]],"ltp":3.9,"tv":575.62,"id":23010367},{"batb":[[0,1.01,13.41],[1,1.01,0]],"ltp":1.2,"tv":2516.45,"id":27652444}]}]}
{"op":"mcm","clk":"1000283074","pt":1580611419419,"mc":[{"id":"1.168119364","rc":[{"batb":[[1,1.02,1],[2,1.01,12.51]],"ltp":3.9,"tv":575.62,"id":23010367}]}]}
{"op":"mcm","clk":"1000283163","pt":1580611421526,"mc":[{"id":"1.168119364","rc":[{"batb":[[0,1.02,1],[1,1.01,12.51],[2,1.01,0]],"ltp":3.9,"tv":575.62,"id":23010367}]}]}
{"op":"mcm","clk":"1000283197","pt":1580611422298,"mc":[{"id":"1.168119364","rc":[{"batb":[[0,6.6,15.61],[1,1.02,1],[2,1.01,12.51]],"ltp":3.9,"tv":575.62,"id":23010367}]}]}
{"op":"mcm","clk":"1000283226","pt":1580611422915,"mc":[{"id":"1.168119364","rc":[{"batb":[[1,3.35,455.97],[2,1.02,1]],"batl":[[0,14,41.53],[1,1000,0.02]],"ltp":3.9,"tv":575.62,"id":23010367}]}]}
{"op":"mcm","clk":"1000283368","pt":1580611426301,"mc":[{"id":"1.168119364","rc":[{"batb":[[0,1.03,61.28],[1,1.01,12.71]],"ltp":1.2,"tv":2516.45,"id":27652444}]}]}
{"op":"mcm","clk":"1000283586","pt":1580611431738,"mc":[{"id":"1.168119364","rc":[{"batb":[[0,1.1,38.06],[1,1.08,87.42],[2,1.03,61.08]],"batl":[[0,1.43,37.86],[1,1.51,84.44],[2,1.99,15.14]],"ltp":1.2,"tv":2516.45,"id":27652444}]}]}
{"op":"mcm","clk":"1000283616","pt":1580611432250,"mc":[{"id":"1.168119364","rc":[{"batb":[[1,1.08,174.83]],"ltp":1.2,"tv":2516.45,"id":27652444}]}]}
{"op":"mcm","clk":"1000283682","pt":1580611433937,"mc":[{"id":"1.168119364","rc":[{"trd":[[14,41.53]],"batl":[[0,1000,0.02],[1,1000,0]],"ltp":14.0,"tv":617.15,"id":23010367},{"trd":[[1.07,543.39],[1.08,349.65],[1.1,76.12]],"batb":[[0,1.03,61.08],[1,1.01,12.71],[2,1.03,0]],"batl":[[0,1.05,191.72],[1,1.43,37.86],[2,1.51,84.44]],"ltp":1.07,"tv":3485.61,"id":27652444}],"tv":4102.76}]}
{"op":"mcm","clk":"1000283837","pt":1580611437438,"mc":[{"id":"1.168119364","rc":[{"trd":[[1.05,383.44]],"batl":[[0,1.43,37.86],[1,1.51,84.44],[2,1.99,15.14]],"ltp":1.05,"tv":3869.05,"id":27652444}],"tv":4486.2}]}
{"op":"mcm","clk":"1000283924","pt":1580611439239,"mc":[{"id":"1.168119364","rc":[{"batb":[[0,1.05,37.86],[1,1.03,61.08],[2,1.01,12.71]],"ltp":1.05,"tv":3869.05,"id":27652444}]}]}
{"op":"mcm","clk":"1000283975","pt":1580611440624,"mc":[{"id":"1.168119364","rc":[{"batb":[[0,1.06,174.83],[1,1.05,37.86],[2,1.03,61.08]],"ltp":1.05,"tv":3869.05,"id":27652444}]}]}
{"op":"mcm","clk":"1000284102","pt":1580611443664,"mc":[{"id":"1.168119364","rc":[{"batb":[[0,3.35,455.97],[1,1.02,1],[2,1.01,12.51]],"ltp":14.0,"tv":617.15,"id":23010367}]}]}
{"op":"mcm","clk":"1000284167","pt":1580611445065,"mc":[{"id":"1.168119364","rc":[{"batl":[[0,21,7.57],[1,1000,0.02]],"ltp":14.0,"tv":617.15,"id":23010367}]}]}
{"op":"mcm","clk":"1000284288","pt":1580611447474,"mc":[{"id":"1.168119364","rc":[{"batb":[[0,11,17.04],[1,3.35,455.97],[2,1.02,1]],"batl":[[0,1000,0.02],[1,1000,0]],"ltp":14.0,"tv":617.15,"id":23010367}]}]}
{"op":"mcm","clk":"1000284423","pt":1580611450455,"mc":[{"id":"1.168119364","rc":[{"trd":[[1.06,349.65]],"batb":[[0,1.05,37.86],[1,1.03,61.08],[2,1.01,15.74]],"batl":[[0,1.06,25.18],[1,1.43,37.86],[2,1.51,84.44]],"ltp":1.06,"tv":4218.7,"id":27652444}],"tv":4835.86}]}
{"op":"mcm","clk":"1000284633","pt":1580611456539,"mc":[{"id":"1.168119364","rc":[{"trd":[[1.06,400.01]],"batb":[[0,1.08,62.23],[1,1.06,60.58],[2,1.05,37.86]],"batl":[[0,1.43,37.86],[1,1.51,84.44],[2,1.99,15.14]],"ltp":1.06,"tv":4269.06,"id":27652444}],"tv":4886.22}]}
{"op":"mcm","clk":"1000284642","pt":1580611456947,"mc":[{"id":"1.168119364","rc":[{"batb":[[1,1.07,87.42],[2,1.06,60.58]],"ltp":1.06,"tv":4269.06,"id":27652444}]}]}
{"op":"mcm","clk":"1000284685","pt":1580611458589,"mc":[{"id":"1.168119364","rc":[{"batb":[[0,1.07,87.42],[1,1.06,60.58],[2,1.05,37.86]],"batl":[[0,1.27,60.58],[1,1.43,37.86],[2,1.51,84.44]],"ltp":1.06,"tv":4269.06,"id":27652444}]}]}
{"op":"mcm","clk":"1000284827","pt":1580611462655,"mc":[{"id":"1.168119364","rc":[{"batb":[[0,3.35,455.97],[1,1.02,1],[2,1.01,15.54]],"ltp":14.0,"tv":617.15,"id":23010367}]}]}
{"op":"mcm","clk":"1000284979","pt":1580611467373,"mc":[{"id":"1.168119364","rc":[{"batb":[[0,1.06,60.58],[1,1.05,37.86],[2,1.03,61.08]],"batl":[[0,1.1,363.15],[1,1.27,60.58],[2,1.43,37.86]],"ltp":1.06,"tv":4269.06,"id":27652444}]}]}
{"op":"mcm","clk":"1000285026","pt":1580611468763,"mc":[{"id":"1.168119364","rc":[{"trd":[[11,13.63]],"ltp":11.0,"tv":630.78,"id":23010367},{"trd":[[1.1,212.43]],"batl":[[0,1.1,226.84]],"ltp":1.1,"tv":4405.37,"id":27652444}],"tv":5036.16}]}
{"op":"mcm","clk":"1000285097","pt":1580611470358,"mc":[{"id":"1.168119364","rc":[{"batb":[[0,1.08,207.31],[1,1.06,60.58],[2,1.05,37.86]],"ltp":1.1,"tv":4405.37,"id":27652444}]}]}
{"op":"mcm","clk":"1000285119","pt":1580611470780,"mc":[{"id":"1.168119364","rc":[{"batb":[[0,1.06,60.58],[1,1.05,37.86],[2,1.03,61.08]],"ltp":1.1,"tv":4405.37,"id":27652444}]}]}
{"op":"mcm","clk":"1000285339","pt":1580611477202,"mc":[{"id":"1.168119364","rc":[{"batl":[[0,1.27,60.58],[1,1.43,37.86],[2,1.51,84.44]],"ltp":1.1,"tv":4405.37,"id":27652444}]}]}
{"op":"mcm","clk":"1000285495","pt":1580611481413,"mc":[{"id":"1.168119364","rc":[{"batb":[[0,1.07,87.42],[1,1.06,60.58],[2,1.05,37.86]],"ltp":1.1,"tv":4405.37,"id":27652444}]}]}
{"op":"mcm","clk":"1000285519","pt":1580611481923,"mc":[{"id":"1.168119364","rc":[{"batb":[[0,1.08,87.42],[1,1.07,87.42],[2,1.06,60.58]],"ltp":1.1,"tv":4405.37,"id":27652444}]}]}
{"op":"mcm","clk":"1000285684","pt":1580611485993,"mc":[{"id":"1.168119364","rc":[{"batl":[[0,1.15,216.97],[1,1.27,60.58],[2,1.43,37.86]],"ltp":1.1,"tv":4405.37,"id":27652444}]}]}
{"op":"mcm","clk":"1000285768","pt":1580611488617,"mc":[{"id":"1.168119364","rc":[{"batb":[[0,1.09,154.27]],"ltp":1.1,"tv":4405.37,"id":27652444}]}]}
{"op":"mcm","clk":"1000285781","pt":1580611489029,"mc":[{"id":"1.168119364","rc":[{"batb":[[1,1.06,60.58],[2,1.05,37.86]],"ltp":1.1,"tv":4405.37,"id":27652444}]}]}
{"op":"mcm","clk":"1000285921","pt":1580611493193,"mc":[{"id":"1.168119364","rc":[{"batb":[[2,1.05,125.28]],"ltp":1.1,"tv":4405.37,"id":27652444}]}]}
{"op":"mcm","clk":"1000285977","pt":1580611494533,"mc":[{"id":"1.168119364","rc":[{"batb":[[2,1.05,212.69]],"ltp":1.1,"tv":4405.37,"id":27652444}]}]}
{"op":"mcm","clk":"1000286007","pt":1580611495408,"mc":[{"id":"1.168119364","rc":[{"trd":[[1.15,0.11]],"batb":[[0,1.06,60.58],[1,1.05,212.69],[2,1.03,61.08]],"batl":[[0,1.15,216.92]],"ltp":1.15,"tv":4405.48,"id":27652444}],"tv":5036.27}]}
{"op":"mcm","clk":"1000286067","pt":1580611496906,"mc":[{"id":"1.168119364","rc":[{"batb":[[0,1.02,1],[1,1.01,15.54],[2,1.01,0]],"ltp":11.0,"tv":630.78,"id":23010367}]}]}
{"op":"mcm","clk":"1000286164","pt":1580611500133,"mc":[{"id":"1.168119364","rc":[{"batl":[[0,1.27,60.58],[1,1.43,37.86],[2,1.51,84.44]],"ltp":1.15,"tv":4405.48,"id":27652444}]}]}
{"op":"mcm","clk":"1000286231","pt":1580611501421,"mc":[{"id":"1.168119364","rc":[{"batl":[[0,6.4,318],[1,1000,0.02]],"ltp":11.0,"tv":630.78,"id":23010367}]}]}
{"op":"mcm","clk":"1000286268","pt":1580611502246,"mc":[{"id":"1.168119364","rc":[{"batl":[[0,1000,0.02],[1,1000,0]],"ltp":11.0,"tv":630.78,"id":23010367}]}]}
{"op":"mcm","clk":"1000286344","pt":1580611503433,"mc":[{"id":"1.168119364","rc":[{"batb":[[0,2.62,707.97],[1,1.02,1],[2,1.01,15.54]],"ltp":11.0,"tv":630.78,"id":23010367},{"batl":[[0,1.43,37.86],[1,1.51,84.44],[2,1.99,15.14]],"ltp":1.15,"tv":4405.48,"id":27652444}]}]}
{"op":"mcm","clk":"1000286470","pt":1580611505850,"mc":[{"id":"1.168119364","rc":[{"batl":[[0,1.22,204.47],[1,1.43,37.86],[2,1.51,84.44]],"ltp":1.15,"tv":4405.48,"id":27652444}]}]}
{"op":"mcm","clk":"1000286592","pt":1580611507806,"mc":[{"id":"1.168119364","rc":[{"batb":[[0,1.12,87.42],[1,1.06,60.58],[2,1.05,212.69]],"ltp":1.15,"tv":4405.48,"id":27652444}]}]}
{"op":"mcm","clk":"1000286644","pt":1580611509140,"mc":[{"id":"1.168119364","rc":[{"batb":[[1,1.09,100.05],[2,1.06,60.58]],"ltp":1.15,"tv":4405.48,"id":27652444}]}]}
{"op":"mcm","clk":"1000286691","pt":1580611510417,"mc":[{"id":"1.168119364","rc":[{"batb":[[0,1.06,60.58],[1,1.05,212.69],[2,1.03,61.08]],"ltp":1.15,"tv":4405.48,"id":27652444}]}]}
{"op":"mcm","clk":"1000286837","pt":1580611513451,"mc":[{"id":"1.168119364","rc":[{"batb":[[0,1.13,114.96],[1,1.06,60.58],[2,1.05,212.69]],"ltp":1.15,"tv":4405.48,"id":27652444}]}]}
{"op":"mcm","clk":"1000286859","pt":1580611513815,"mc":[{"id":"1.168119364","rc":[{"trd":[[1.22,60.2]],"batb":[[2,1.05,37.86]],"batl":[[0,1.22,174.37]],"ltp":1.22,"tv":4465.69,"id":27652444}],"tv":5096.47}]}
{"op":"mcm","clk":"1000286998","pt":1580611516655,"mc":[{"id":"1.168119364","rc":[{"trd":[[1.22,68.08]],"batl":[[0,1.22,170.43]],"ltp":1.22,"tv":4473.56,"id":27652444}],"tv":5104.35}]}
{"op":"mcm","clk":"1000287210","pt":1580611521548,"mc":[{"id":"1.168119364","rc":[{"batb":[[0,1.06,60.58],[1,1.05,37.86],[2,1.03,61.08]],"ltp":1.22,"tv":4473.56,"id":27652444}]}]}
{"op":"mcm","clk":"1000287313","pt":1580611523867,"mc":[{"id":"1.168119364","rc":[{"batb":[[0,1.02,1],[1,1.01,15.54],[2,1.01,0]],"ltp":11.0,"tv":630.78,"id":23010367}]}]}
{"op":"mcm","clk":"1000287375","pt":1580611525158,"mc":[{"id":"1.168119364","rc":[{"trd":[[1.22,69.23]],"batl":[[0,1.22,169.86]],"ltp":1.22,"tv":4474.71,"id":27652444}],"tv":5105.5}]}
{"op":"mcm","clk":"1000287643","pt":1580611531479,"mc":[{"id":"1.168119364","rc":[{"batl":[[0,1.43,37.86],[1,1.51,84.44],[2,1.99,15.14]],"ltp":1.22,"tv":4474.71,"id":27652444}]}]}
{"op":"mcm","clk":"1000287736","pt":1580611533482,"mc":[{"id":"1.168119364","rc":[{"batl":[[0,1.51,84.44],[1,1.99,15.14],[2,1000,0.02]],"ltp":1.22,"tv":4474.71,"id":27652444}]}]}
{"op":"mcm","clk":"1000287801","pt":1580611534665,"mc":[{"id":"1.168119364","rc":[{"batb":[[0,2.22,772.29],[1,1.02,1],[2,1.01,15.54]],"ltp":11.0,"tv":630.78,"id":23010367},{"batb":[[0,1.36,242.82],[1,1.06,60.58],[2,1.05,37.86]],"ltp":1.22,"tv":4474.71,"id":27652444}]}]}
{"op":"mcm","clk":"1000287947","pt":1580611537563,"mc":[{"id":"1.168119364","rc":[{"batb":[[0,1.29,301.43],[1,1.27,323.76],[2,1.06,60.58]],"batl":[[0,1.5,37.86],[1,1.51,84.44],[2,1.99,15.14]],"ltp":1.22,"tv":4474.71,"id":27652444}]}]}
{"op":"mcm","clk":"1000288250","pt":1580611543284,"mc":[{"id":"1.168119364","rc":[{"batb":[[0,1.3,60.58],[1,1.29,301.43],[2,1.27,323.76]],"ltp":1.22,"tv":4474.71,"id":27652444}]}]}
{"op":"mcm","clk":"1000288353","pt":1580611545392,"mc":[{"id":"1.168119364","rc":[{"trd":[[3.75,0.03]],"batb":[[0,3.75,55.23],[1,2.22,772.29],[2,1.02,1]],"ltp":3.75,"tv":630.81,"id":23010367},{"trd":[[1.37,0.08]],"ltp":1.37,"tv":4474.8,"id":27652444}],"tv":5105.61}]}
{"op":"mcm","clk":"1000289110","pt":1580611561905,"mc":[{"id":"1.168119364","rc":[{"trd":[[3.75,110.49]],"batb":[[0,2.22,772.29],[1,1.02,1],[2,1.01,15.54]],"ltp":3.75,"tv":741.27,"id":23010367}],"tv":5216.07}]}
{"op":"mcm","clk":"1000289934","pt":1580611581436,"mc":[{"id":"1.168119364","rc":[{"trd":[[1.3,261.12]],"batb":[[0,1.3,18.57]],"ltp":1.3,"tv":4558.8,"id":27652444}],"tv":5300.07}]}
{"op":"mcm","clk":"1000291243","pt":1580611616163,"mc":[{"id":"1.168119364","rc":[{"batb":[[0,1.02,1],[1,1.01,15.54],[2,1.01,0]],"ltp":3.75,"tv":741.27,"id":23010367}]}]}
{"op":"mcm","clk":"1000291303","pt":1580611617650,"mc":[{"id":"1.168119364","rc":[{"batb":[[0,1.06,60.58],[1,1.05,37.86],[2,1.03,61.08]],"ltp":1.3,"tv":4558.8,"id":27652444}]}]}
{"op":"mcm","clk":"1000291358","pt":1580611619187,"mc":[{"id":"1.168119364","rc":[{"batl":[[0,1.37,37.86],[1,1.5,37.86],[2,1.51,84.44]],"ltp":1.3,"tv":4558.8,"id":27652444}]}]}
{"op":"mcm","clk":"1000291386","pt":1580611619859,"mc":[{"id":"1.168119364","rc":[{"batb":[[0,2.38,744.23],[1,1.02,1],[2,1.01,15.54]],"ltp":3.75,"tv":741.27,"id":23010367}]}]}
{"op":"mcm","clk":"1000291506","pt":1580611622386,"mc":[{"id":"1.168119364","rc":[{"batb":[[0,1.25,349.66],[1,1.06,60.58],[2,1.05,37.86]],"ltp":1.3,"tv":4558.8,"id":27652444}]}]}
{"op":"mcm","clk":"1000291778","pt":1580611628874,"mc":[{"id":"1.168119364","rc":[{"batb":[[0,3.25,38.85],[1,2.38,744.23],[2,1.02,1]],"ltp":3.75,"tv":741.27,"id":23010367},{"batb":[[0,1.26,60.58],[1,1.25,349.66],[2,1.06,60.58]],"ltp":1.3,"tv":4558.8,"id":27652444}]}]}
{"op":"mcm","clk":"1000292208","pt":1580611640980,"mc":[{"id":"1.168119364","rc":[{"batl":[[0,1.5,37.86],[1,1.51,84.44],[2,1.99,15.14]],"ltp":1.3,"tv":4558.8,"id":27652444}]}]}
{"op":"mcm","clk":"1000292434","pt":1580611647494,"mc":[{"id":"1.168119364","rc":[{"batb":[[0,1.31,281.99],[1,1.26,60.58],[2,1.25,349.66]],"ltp":1.3,"tv":4558.8,"id":27652444}]}]}
{"op":"mcm","clk":"1000292573","pt":1580611651093,"mc":[{"id":"1.168119364","rc":[{"batl":[[0,1.4,37.86],[1,1.5,37.86],[2,1.51,84.44]],"ltp":1.3,"tv":4558.8,"id":27652444}]}]}
{"op":"mcm","clk":"1000293060","pt":1580611663315,"mc":[{"id":"1.168119364","rc":[{"trd":[[1.31,52.75]],"batb":[[0,1.31,269.99]],"ltp":1.31,"tv":4582.8,"id":27652444}],"tv":5324.08}]}
{"op":"mcm","clk":"1000293116","pt":1580611665216,"mc":[{"id":"1.168119364","rc":[{"batb":[[1,1.02,1],[2,1.01,15.54]],"ltp":3.75,"tv":741.27,"id":23010367}]}]}
{"op":"mcm","clk":"1000293154","pt":1580611665933,"mc":[{"id":"1.168119364","rc":[{"batl":[[0,1.51,84.44],[1,1.99,15.14],[2,1000,0.02]],"ltp":1.31,"tv":4582.8,"id":27652444}]}]}
{"op":"mcm","clk":"1000293295","pt":1580611669062,"mc":[{"id":"1.168119364","rc":[{"batb":[[0,2.04,819.11]],"ltp":3.75,"tv":741.27,"id":23010367}]}]}
{"op":"mcm","clk":"1000293452","pt":1580611672757,"mc":[{"id":"1.168119364","rc":[{"batb":[[0,1.31,350.78]],"ltp":1.31,"tv":4582.8,"id":27652444}]}]}
{"op":"mcm","clk":"1000293581","pt":1580611675659,"mc":[{"id":"1.168119364","rc":[{"batb":[[0,3.25,4.84],[1,2.04,819.11],[2,1.02,1]],"ltp":3.75,"tv":741.27,"id":23010367},{"trd":[[1.31,272.75]],"batb":[[0,1.31,240.77]],"ltp":1.31,"tv":4802.81,"id":27652444}],"tv":5544.08}]}
{"op":"mcm","clk":"1000293688","pt":1580611677824,"mc":[{"id":"1.168119364","rc":[{"batb":[[0,2.04,819.11],[1,1.02,1],[2,1.01,15.54]],"ltp":3.75,"tv":741.27,"id":23010367}]}]}
{"op":"mcm","clk":"1000293777","pt":1580611679365,"mc":[{"id":"1.168119364","rc":[{"batl":[[0,1.47,22.72],[1,1.51,84.44],[2,1.99,15.14]],"ltp":1.31,"tv":4802.81,"id":27652444}]}]}
{"op":"mcm","clk":"1000293863","pt":1580611682032,"mc":[{"id":"1.168119364","rc":[{"batb":[[0,1.33,60.58],[1,1.31,240.77],[2,1.26,60.58]],"ltp":1.31,"tv":4802.81,"id":27652444}]}]}
{"op":"mcm","clk":"1000293946","pt":1580611683630,"mc":[{"id":"1.168119364","rc":[{"batb":[[0,3.5,45.67],[1,2.04,819.11],[2,1.02,1]],"ltp":3.75,"tv":741.27,"id":23010367},{"batb":[[1,1.31,159.98]],"ltp":1.31,"tv":4802.81,"id":27652444}]}]}
{"op":"mcm","clk":"1000294118","pt":1580611687231,"mc":[{"id":"1.168119364","rc":[{"batb":[[1,1.31,160.99]],"batl":[[0,1.45,1.01],[1,1.47,22.72],[2,1.51,84.44]],"ltp":1.31,"tv":4802.81,"id":27652444}]}]}
{"op":"mcm","clk":"1000294575","pt":1580611698062,"mc":[{"id":"1.168119364","rc":[{"trd":[[3.5,91.75]],"batb":[[0,2.04,819.11],[1,1.02,1],[2,1.01,15.54]],"batl":[[0,3.5,13.78],[1,1000,0.02]],"ltp":3.5,"tv":832.6,"id":23010367}],"tv":5635.41}]}
{"op":"mcm","clk":"1000294759","pt":1580611702389,"mc":[{"id":"1.168119364","rc":[{"batl":[[0,1000,0.02],[1,1000,0]],"ltp":3.5,"tv":832.6,"id":23010367}]}]}
{"op":"mcm","clk":"1000294886","pt":1580611705074,"mc":[{"id":"1.168119364","rc":[{"batb":[[0,1.31,160.99],[1,1.26,60.58],[2,1.06,60.58]],"ltp":1.31,"tv":4802.81,"id":27652444}]}]}
{"op":"mcm","clk":"1000295207","pt":1580611713809,"mc":[{"id":"1.168119364","rc":[{"batl":[[0,1.37,37.86],[1,1.45,1.01],[2,1.47,22.72]],"ltp":1.31,"tv":4802.81,"id":27652444}]}]}
{"op":"mcm","clk":"1000295439","pt":1580611719728,"mc":[{"id":"1.168119364","rc":[{"batl":[[0,1.45,1.01],[1,1.47,22.72],[2,1.51,84.44]],"ltp":1.31,"tv":4802.81,"id":27652444}]}]}
{"op":"mcm","clk":"1000295490","pt":1580611720707,"mc":[{"id":"1.168119364","rc":[{"batb":[[0,1.31,241.78]],"batl":[[1,1.51,84.44],[2,1.99,15.14]],"ltp":1.31,"tv":4802.81,"id":27652444}]}]}
{"op":"mcm","clk":"1000295605","pt":1580611723641,"mc":[{"id":"1.168119364","rc":[{"batl":[[0,1.4,37.86],[1,1.45,1.01],[2,1.46,27.75]],"ltp":1.31,"tv":4802.81,"id":27652444}]}]}
{"op":"mcm","clk":"1000295610","pt":1580611723796,"mc":[{"id":"1.168119364","rc":[{"batl":[[2,1.51,84.44]],"ltp":1.31,"tv":4802.81,"id":27652444}]}]}
{"op":"mcm","clk":"1000295705","pt":1580611726619,"mc":[{"id":"1.168119364","rc":[{"batl":[[0,3.7,14.86],[1,1000,0.02]],"ltp":3.5,"tv":832.6,"id":23010367},{"batb":[[0,1.31,160.99]],"ltp":1.31,"tv":4802.81,"id":27652444}]}]}
{"op":"mcm","clk":"1000295951","pt":1580611733144,"mc":[{"id":"1.168119364","rc":[{"batl":[[0,1000,0.02],[1,1000,0]],"ltp":3.5,"tv":832.6,"id":23010367}]}]}
{"op":"mcm","clk":"1000296547","pt":1580611747665,"mc":[{"id":"1.168119364","rc":[{"batb":[[0,1.02,1],[1,1.01,15.54],[2,1.01,0]],"ltp":3.5,"tv":832.6,"id":23010367},{"batb":[[0,1.31,1.01]],"ltp":1.31,"tv":4802.81,"id":27652444}]}]}
{"op":"mcm","clk":"1000296607","pt":1580611749259,"mc":[{"id":"1.168119364","rc":[{"batb":[[1,1.06,60.58],[2,1.05,37.86]],"ltp":1.31,"tv":4802.81,"id":27652444}]}]}
{"op":"mcm","clk":"1000296682","pt":1580611751260,"mc":[{"id":"1.168119364","rc":[{"batb":[[0,2.38,744.23],[1,1.02,1],[2,1.01,15.54]],"ltp":3.5,"tv":832.6,"id":23010367},{"trd":[[1.31,274.78]],"batb":[[0,1.06,60.58],[1,1.05,37.86],[2,1.03,61.08]],"batl":[[0,1.31,36.85],[1,1.4,37.86],[2,1.45,1.01]],"ltp":1.31,"tv":4804.83,"id":27652444}],"tv":5637.44}]}
{"op":"mcm","clk":"1000296788","pt":1580611754387,"mc":[{"id":"1.168119364","rc":[{"batb":[[0,1.25,349.66],[1,1.06,60.58],[2,1.05,37.86]],"ltp":1.31,"tv":4804.83,"id":27652444}]}]}
{"op":"mcm","clk":"1000296822","pt":1580611755360,"mc":[{"id":"1.168119364","rc":[{"batb":[[0,3.55,2.19],[1,3.35,2.67],[2,2.38,744.23]],"batl":[[0,5,2],[1,1000,0.02]],"ltp":3.5,"tv":832.6,"id":23010367},{"batb":[[0,1.25,421.27]],"batl":[[1,1.39,43.5],[2,1.4,37.86]],"ltp":1.31,"tv":4804.83,"id":27652444}]}]}
{"op":"mcm","clk":"1000297068","pt":1580611760965,"mc":[{"id":"1.168119364","rc":[{"trd":[[1.31,348.36]],"batl":[[0,1.39,43.56],[1,1.4,37.86],[2,1.41,37.5]],"ltp":1.31,"tv":4878.41,"id":27652444}],"tv":5711.02}]}
{"op":"mcm","clk":"1000297243","pt":1580611764679,"mc":[{"id":"1.168119364","rc":[{"trd":[[4.2,8.98]],"batb":[[0,2.38,744.23],[1,1.02,1],[2,1.01,15.54]],"batl":[[0,4.2,12.14]],"ltp":4.2,"tv":832.62,"id":23010367},{"trd":[[1.31,348.42]],"batl":[[0,1.37,19.96],[2,1.42,48.75]],"ltp":1.31,"tv":4878.47,"id":27652444}],"tv":5711.09}]}
{"op":"mcm","clk":"1000297255","pt":1580611764884,"mc":[{"id":"1.168119364","rc":[{"batl":[[0,1.4,37.86],[1,1.42,48.75],[2,1.45,1.01]],"ltp":1.31,"tv":4878.47,"id":27652444}]}]}
{"op":"mcm","clk":"1000297440","pt":1580611769196,"mc":[{"id":"1.168119364","rc":[{"batl":[[0,1000,0.02],[1,1000,0]],"ltp":4.2,"tv":832.62,"id":23010367}]}]}
{"op":"mcm","clk":"1000297469","pt":1580611769869,"mc":[{"id":"1.168119364","rc":[{"batb":[[0,1.02,1],[1,1.01,15.54],[2,1.01,0]],"ltp":4.2,"tv":832.62,"id":23010367}]}]}
{"op":"mcm","clk":"1000297596","pt":1580611773269,"mc":[{"id":"1.168119364","rc":[{"batb":[[0,2.52,723.64],[1,1.02,1],[2,1.01,15.54]],"ltp":4.2,"tv":832.62,"id":23010367},{"batb":[[0,1.26,90.35],[1,1.25,71.61],[2,1.06,60.58]],"ltp":1.31,"tv":4878.47,"id":27652444}]}]}
{"op":"mcm","clk":"1000297669","pt":1580611775073,"mc":[{"id":"1.168119364","rc":[{"batb":[[2,1.2,437.08]],"ltp":1.31,"tv":4878.47,"id":27652444}]}]}
{"op":"mcm","clk":"1000299472","pt":1580611819078,"mc":[{"id":"1.168119364","rc":[{"batb":[[0,1.27,323.76],[1,1.26,90.35],[2,1.25,71.61]],"ltp":1.31,"tv":4878.47,"id":27652444}]}]}
{"op":"mcm","clk":"1000299612","pt":1580611822260,"mc":[{"id":"1.168119364","rc":[{"batb":[[0,3.7,2.42],[1,3.55,2.19],[2,2.52,723.64]],"batl":[[0,4.8,2],[1,5,2],[2,1000,0.02]],"ltp":4.2,"tv":832.62,"id":23010367},{"batb":[[0,1.27,383.63]],"batl":[[0,1.37,52.5],[1,1.39,47.5],[2,1.4,37.86]],"ltp":1.31,"tv":4878.47,"id":27652444}]}]}
{"op":"mcm","clk":"1000300004","pt":1580611830580,"mc":[{"id":"1.168119364","rc":[{"batb":[[0,2.52,723.64],[1,1.02,1],[2,1.01,15.54]],"ltp":4.2,"tv":832.62,"id":23010367},{"batb":[[0,1.28,60.58],[1,1.27,383.63],[2,1.26,90.35]],"batl":[[0,1.39,47.5],[1,1.4,37.86],[2,1.45,1.01]],"ltp":1.31,"tv":4878.47,"id":27652444}]}]}
{"op":"mcm","clk":"1000300118","pt":1580611832592,"mc":[{"id":"1.168119364","rc":[{"batl":[[0,5,2],[1,1000,0.02],[2,1000,0]],"ltp":4.2,"tv":832.62,"id":23010367},{"batb":[[1,1.26,90.35],[2,1.25,71.61]],"ltp":1.31,"tv":4878.47,"id":27652444}]}]}
{"op":"mcm","clk":"1000300201","pt":1580611834084,"mc":[{"id":"1.168119364","rc":[{"batb":[[0,3.55,2.59],[1,2.52,723.64],[2,1.02,1]],"ltp":4.2,"tv":832.62,"id":23010367}]}]}
{"op":"mcm","clk":"1000300271","pt":1580611835678,"mc":[{"id":"1.168119364","rc":[{"batl":[[0,4.8,2],[1,5,2],[2,1000,0.02]],"ltp":4.2,"tv":832.62,"id":23010367},{"batb":[[1,1.27,56.87],[2,1.26,90.35]],"ltp":1.31,"tv":4878.47,"id":27652444}]}]}
{"op":"mcm","clk":"1000300281","pt":1580611835888,"mc":[{"id":"1.168119364","rc":[{"batl":[[0,5,2],[1,1000,0.02],[2,1000,0]],"ltp":4.2,"tv":832.62,"id":23010367},{"batb":[[1,1.26,90.35],[2,1.25,71.61]],"ltp":1.31,"tv":4878.47,"id":27652444}]}]}
{"op":"mcm","clk":"1000300535","pt":1580611840572,"mc":[{"id":"1.168119364","rc":[{"batb":[[0,3.7,2.12],[1,3.55,2.59],[2,2.52,723.64]],"ltp":4.2,"tv":832.62,"id":23010367},{"batl":[[0,1.37,49.5],[1,1.39,47.5],[2,1.4,37.86]],"ltp":1.31,"tv":4878.47,"id":27652444}]}]}
{"op":"mcm","clk":"1000300545","pt":1580611840880,"mc":[{"id":"1.168119364","rc":[{"batb":[[0,3.55,2.59],[1,2.52,723.64],[2,1.02,1]],"ltp":4.2,"tv":832.62,"id":23010367},{"batl":[[0,1.39,47.5],[1,1.4,37.86],[2,1.45,1.01]],"ltp":1.31,"tv":4878.47,"id":27652444}]}]}
{"op":"mcm","clk":"1000300606","pt":1580611842576,"mc":[{"id":"1.168119364","rc":[{"batb":[[1,1.27,63.87],[2,1.26,90.35]],"ltp":1.31,"tv":4878.47,"id":27652444}]}]}
{"op":"mcm","clk":"1000300618","pt":1580611843289,"mc":[{"id":"1.168119364","rc":[{"batb":[[1,1.26,90.35],[2,1.25,71.61]],"ltp":1.31,"tv":4878.47,"id":27652444}]}]}
{"op":"mcm","clk":"1000300758","pt":1580611846471,"mc":[{"id":"1.168119364","rc":[{"batb":[[1,1.27,68.87],[2,1.26,90.35]],"ltp":1.31,"tv":4878.47,"id":27652444}]}]}
{"op":"mcm","clk":"1000300796","pt":1580611847597,"mc":[{"id":"1.168119364","rc":[{"batb":[[1,1.26,90.35],[2,1.25,71.61]],"batl":[[0,1.37,43.5],[1,1.39,47.5],[2,1.4,37.86]],"ltp":1.31,"tv":4878.47,"id":27652444}]}]}
{"op":"mcm","clk":"1000300825","pt":1580611848518,"mc":[{"id":"1.168119364","rc":[{"batl":[[0,1.39,47.5],[1,1.4,37.86],[2,1.45,1.01]],"ltp":1.31,"tv":4878.47,"id":27652444}]}]}
{"op":"mcm","clk":"1000301005","pt":1580611851708,"mc":[{"id":"1.168119364","rc":[{"batl":[[0,4,431.3],[1,5,2],[2,1000,0.02]],"ltp":4.2,"tv":832.62,"id":23010367},{"batl":[[1,1.45,1.01],[2,1.46,60.58]],"ltp":1.31,"tv":4878.47,"id":27652444}]}]}
{"op":"mcm","clk":"1000301023","pt":1580611852321,"mc":[{"id":"1.168119364","rc":[{"batl":[[0,5,2],[1,1000,0.02],[2,1000,0]],"ltp":4.2,"tv":832.62,"id":23010367}]}]}
{"op":"mcm","clk":"1000301363","pt":1580611861320,"mc":[{"id":"1.168119364","rc":[{"batb":[[1,3.5,2.64],[2,2.52,723.64]],"batl":[[0,4.2,2.03],[1,4.4,2.04],[2,5,2]],"ltp":4.2,"tv":832.62,"id":23010367},{"batb":[[0,1.32,55.89],[1,1.3,55.08],[2,1.28,60.58]],"batl":[[1,1.4,42.24],[2,1.45,1.01]],"ltp":1.31,"tv":4878.47,"id":27652444}]}]}
{"op":"mcm","clk":"1000301469","pt":1580611863635,"mc":[{"id":"1.168119364","rc":[{"batb":[[2,1.29,301.43]],"ltp":1.31,"tv":4878.47,"id":27652444}]}]}
{"op":"mcm","clk":"1000301488","pt":1580611864100,"mc":[{"id":"1.168119364","rc":[{"batl":[[2,1.46,60.58]],"ltp":1.31,"tv":4878.47,"id":27652444}]}]}
{"op":"mcm","clk":"1000301622","pt":1580611867235,"mc":[{"id":"1.168119364","rc":[{"batl":[[0,1.35,1.01],[1,1.39,47.5],[2,1.4,42.24]],"ltp":1.31,"tv":4878.47,"id":27652444}]}]}
{"op":"mcm","clk":"1000301881","pt":1580611874447,"mc":[{"id":"1.168119364","rc":[{"batb":[[0,3.5,2.64],[1,2.52,723.64],[2,1.02,1]],"batl":[[1,5,2],[2,1000,0.02]],"ltp":4.2,"tv":832.62,"id":23010367},{"batb":[[0,1.33,85.6],[1,1.29,301.43],[2,1.28,60.58]],"ltp":1.31,"tv":4878.47,"id":27652444}]}]}
{"op":"mcm","clk":"1000301922","pt":1580611875790,"mc":[{"id":"1.168119364","rc":[{"batb":[[0,2.52,723.64],[1,1.02,1],[2,1.01,15.54]],"batl":[[0,5,2],[1,1000,0.02],[2,1000,0]],"ltp":4.2,"tv":832.62,"id":23010367},{"batl":[[1,1.46,60.58],[2,1.51,84.44]],"ltp":1.31,"tv":4878.47,"id":27652444}]}]}
{"op":"mcm","clk":"1000301999","pt":1580611877231,"mc":[{"id":"1.168119364","rc":[{"batb":[[0,3.4,2.31],[1,2.52,723.64],[2,1.02,1]],"batl":[[0,4.6,2.01],[1,5,2],[2,1000,0.02]],"ltp":4.2,"tv":832.62,"id":23010367},{"batb":[[2,1.28,124.49]],"batl":[[1,1.41,43.5],[2,1.46,60.58]],"ltp":1.31,"tv":4878.47,"id":27652444}]}]}
{"op":"mcm","clk":"1000302049","pt":1580611878652,"mc":[{"id":"1.168119364","rc":[{"batb":[[0,3.55,2.39],[1,3.4,2.31],[2,2.52,723.64]],"batl":[[0,4.4,2.04],[1,4.6,2.01],[2,5,2]],"ltp":4.2,"tv":832.62,"id":23010367},{"batb":[[1,1.3,59.48],[2,1.29,301.43]],"ltp":1.31,"tv":4878.47,"id":27652444}]}]}
{"op":"mcm","clk":"1000302068","pt":1580611879063,"mc":[{"id":"1.168119364","rc":[{"batb":[[0,3.4,2.31],[1,2.52,723.64],[2,1.02,1]],"batl":[[0,4.6,2.01],[1,5,2],[2,1000,0.02]],"ltp":4.2,"tv":832.62,"id":23010367},{"batb":[[1,1.29,301.43],[2,1.28,124.49]],"batl":[[1,1.39,47.5],[2,1.41,43.5]],"ltp":1.31,"tv":4878.47,"id":27652444}]}]}
{"op":"mcm","clk":"1000302107","pt":1580611880448,"mc":[{"id":"1.168119364","rc":[{"batl":[[1,1.41,43.5],[2,1.46,60.58]],"ltp":1.31,"tv":4878.47,"id":27652444}]}]}
{"op":"mcm","clk":"1000302260","pt":1580611883646,"mc":[{"id":"1.168119364","rc":[{"batb":[[0,3.55,2.19],[1,3.4,2.31],[2,2.52,723.64]],"batl":[[0,3.9,876.2],[1,4.4,2],[2,4.6,2.01]],"ltp":4.2,"tv":832.62,"id":23010367},{"batl":[[1,1.39,46.5],[2,1.41,43.5]],"ltp":1.31,"tv":4878.47,"id":27652444}]}]}
{"op":"mcm","clk":"1000302298","pt":1580611884370,"mc":[{"id":"1.168119364","rc":[{"batb":[[0,3.4,2.31],[1,2.52,723.64],[2,1.02,1]],"batl":[[0,4.6,2.01],[1,5,2],[2,1000,0.02]],"ltp":4.2,"tv":832.62,"id":23010367},{"batl":[[1,1.41,43.5],[2,1.5,60.58]],"ltp":1.31,"tv":4878.47,"id":27652444}]}]}
