{"op":"mcm","clk":"982860992","pt":1580451020414,"mc":[{"id":"1.168119366","marketDefinition":{"bspMarket":false,"turnInPlayEnabled":true,"persistenceEnabled":true,"marketBaseRate":5.0,"eventId":"29678414","eventTypeId":"2","numberOfWinners":1,"bettingType":"ODDS","marketType":"SET_WINNER","marketTime":"2020-02-01T00:00:00.000Z","suspendTime":"2020-02-01T00:00:00.000Z","bspReconciled":false,"complete":true,"inPlay":false,"crossMatching":false,"runnersVoidable":false,"numberOfActiveRunners":2,"betDelay":0,"status":"OPEN","runners":[{"status":"ACTIVE","sortPriority":1,"id":23010367,"name":"Margaroli/Vavassori"},{"status":"ACTIVE","sortPriority":2,"id":27652444,"name":"Heliovaara/Verbeek"}],"regulators":["MR_INT"],"countryCode":"AU","discountAllowed":false,"timezone":"UTC","openDate":"2020-02-01T00:00:00.000Z","version":3142664096,"name":"Set 1 Winner","eventName":"Margaroli/Vavassori v Heliovaara/Verbeek"},"rc":[{"batb":[[0,1.01,20]],"ltp":0.0,"tv":0.0,"id":23010367},{"batb":[[0,1.01,20]],"ltp":0.0,"tv":0.0,"id":27652444}]}]}
{"op":"mcm","clk":"982861023","pt":1580451021746,"mc":[{"id":"1.168119366","marketDefinition":{"bspMarket":false,"turnInPlayEnabled":true,"persistenceEnabled":true,"marketBaseRate":5.0,"eventId":"29678414","eventTypeId":"2","numberOfWinners":1,"bettingType":"ODDS","marketType":"SET_WINNER","marketTime":"2020-02-01T00:00:00.000Z","suspendTime":"2020-02-01T00:00:00.000Z","bspReconciled":false,"complete":true,"inPlay":false,"crossMatching":false,"runnersVoidable":false,"numberOfActiveRunners":2,"betDelay":0,"status":"OPEN","runners":[{"status":"ACTIVE","sortPriority":1,"id":23010367,"name":"Margaroli/Vavassori"},{"status":"ACTIVE","sortPriority":2,"id":27652444,"name":"Heliovaara/Verbeek"}],"regulators":["MR_INT"],"countryCode":"AU","discountAllowed":true,"timezone":"UTC","openDate":"2020-02-01T00:00:00.000Z","version":3142664096,"name":"Set 1 Winner","eventName":"Margaroli/Vavassori v Heliovaara/Verbeek"}}]}
{"op":"mcm","clk":"982867820","pt":1580451313340,"mc":[{"id":"1.168119366","rc":[{"batb":[[0,1.01,10]],"ltp":0.0,"tv":0.0,"id":23010367},{"batb":[[0,1.01,10]],"ltp":0.0,"tv":0.0,"id":27652444}]}]}
{"op":"mcm","clk":"983256176","pt":1580458555506,"mc":[{"id":"1.168119366","rc":[{"batb":[[0,1.01,12.56]],"ltp":0.0,"tv":0.0,"id":23010367},{"batb":[[0,1.01,12.56]],"ltp":0.0,"tv":0.0,"id":27652444}]}]}
{"op":"mcm","clk":"983256278","pt":1580458556383,"mc":[{"id":"1.168119366","rc":[{"batb":[[0,1.01,10.51]],"ltp":0.0,"tv":0.0,"id":23010367},{"batb":[[0,1.01,10.51]],"ltp":0.0,"tv":0.0,"id":27652444}]}]}
{"op":"mcm","clk":"983301256","pt":1580459035577,"mc":[{"id":"1.168119366","rc":[{"batb":[[0,1.01,11.02]],"ltp":0.0,"tv":0.0,"id":23010367},{"batb":[[0,1.01,11.02]],"ltp":0.0,"tv":0.0,"id":27652444}]}]}
{"op":"mcm","clk":"983821051","pt":1580464952089,"mc":[{"id":"1.168119366","rc":[{"batb":[[0,1.01,11.02]],"ltp":0.0,"tv":0.0,"id":23010367},{"batb":[[0,1.01,11.02]],"ltp":0.0,"tv":0.0,"id":27652444}]}]}
{"op":"mcm","clk":"986476131","pt":1580486552114,"mc":[{"id":"1.168119366","rc":[{"batb":[[0,1.01,11.02]],"ltp":0.0,"tv":0.0,"id":23010367},{"batb":[[0,1.01,11.02]],"ltp":0.0,"tv":0.0,"id":27652444}]}]}
{"op":"mcm","clk":"988248301","pt":1580503001711,"mc":[{"id":"1.168119366","rc":[{"batb":[[0,2,40.76],[1,1.01,11.01]],"ltp":0.0,"tv":0.0,"id":23010367},{"batb":[[0,1.73,55.84],[1,1.01,11.01]],"ltp":0.0,"tv":0.0,"id":27652444}]}]}
{"op":"mcm","clk":"988248930","pt":1580503005725,"mc":[{"id":"1.168119366","marketDefinition":{"bspMarket":false,"turnInPlayEnabled":true,"persistenceEnabled":true,"marketBaseRate":5.0,"eventId":"29678414","eventTypeId":"2","numberOfWinners":1,"bettingType":"ODDS","marketType":"SET_WINNER","marketTime":"2020-02-01T00:00:00.000Z","suspendTime":"2020-02-01T00:00:00.000Z","bspReconciled":false,"complete":true,"inPlay":false,"crossMatching":true,"runnersVoidable":false,"numberOfActiveRunners":2,"betDelay":0,"status":"OPEN","runners":[{"status":"ACTIVE","sortPriority":1,"id":23010367,"name":"Margaroli/Vavassori"},{"status":"ACTIVE","sortPriority":2,"id":27652444,"name":"Heliovaara/Verbeek"}],"regulators":["MR_INT"],"countryCode":"AU","discountAllowed":true,"timezone":"UTC","openDate":"2020-02-01T00:00:00.000Z","version":3142664096,"name":"Set 1 Winner","eventName":"Margaroli/Vavassori v Heliovaara/Verbeek"}}]}
{"op":"mcm","clk":"988678971","pt":1580508002931,"mc":[{"id":"1.168119366","rc":[{"batb":[[0,2,54.35]],"ltp":0.0,"tv":0.0,"id":23010367},{"batb":[[0,1.73,74.46]],"ltp":0.0,"tv":0.0,"id":27652444}]}]}
{"op":"mcm","clk":"988691838","pt":1580508152091,"mc":[{"id":"1.168119366","rc":[{"batb":[[1,1.01,11.01]],"ltp":0.0,"tv":0.0,"id":23010367},{"batb":[[1,1.01,11.01]],"ltp":0.0,"tv":0.0,"id":27652444}]}]}
{"op":"mcm","clk":"988912809","pt":1580511624163,"mc":[{"id":"1.168119366","rc":[{"batb":[[0,2.02,2],[1,2,56.35],[2,1.01,11.01]],"ltp":0.0,"tv":0.0,"id":23010367},{"batb":[[0,1.74,2],[1,1.73,76.46],[2,1.01,11.01]],"ltp":0.0,"tv":0.0,"id":27652444}]}]}
{"op":"mcm","clk":"988954983","pt":1580512224680,"mc":[{"id":"1.168119366","rc":[{"batb":[[0,2,56.35],[1,1.01,11.01],[2,1.01,0]],"ltp":0.0,"tv":0.0,"id":23010367},{"batb":[[0,1.73,76.46],[1,1.01,11.01],[2,1.01,0]],"ltp":0.0,"tv":0.0,"id":27652444}]}]}
{"op":"mcm","clk":"988955006","pt":1580512225043,"mc":[{"id":"1.168119366","rc":[{"batb":[[0,2,54.35]],"ltp":0.0,"tv":0.0,"id":23010367},{"batb":[[0,1.73,74.46]],"ltp":0.0,"tv":0.0,"id":27652444}]}]}
{"op":"mcm","clk":"988955475","pt":1580512233679,"mc":[{"id":"1.168119366","rc":[{"batb":[[0,2.02,2],[1,2,56.35],[2,1.01,11.01]],"ltp":0.0,"tv":0.0,"id":23010367},{"batb":[[0,1.74,2],[1,1.73,76.46],[2,1.01,11.01]],"ltp":0.0,"tv":0.0,"id":27652444}]}]}
{"op":"mcm","clk":"988963261","pt":1580512365072,"mc":[{"id":"1.168119366","rc":[{"batb":[[2,1.01,12.69]],"ltp":0.0,"tv":0.0,"id":23010367},{"batb":[[2,1.01,12.69]],"ltp":0.0,"tv":0.0,"id":27652444}]}]}
{"op":"mcm","clk":"988963357","pt":1580512366669,"mc":[{"id":"1.168119366","rc":[{"batb":[[0,2.04,1.24],[1,2.02,2],[2,2,56.35]],"ltp":0.0,"tv":0.0,"id":23010367},{"batb":[[0,1.75,1.44],[1,1.74,2],[2,1.73,76.46]],"ltp":0.0,"tv":0.0,"id":27652444}]}]}
{"op":"mcm","clk":"989003059","pt":1580512833691,"mc":[{"id":"1.168119366","rc":[{"batb":[[1,2,54.35],[2,1.01,11.01]],"ltp":0.0,"tv":0.0,"id":23010367},{"batb":[[1,1.73,74.46],[2,1.01,11.01]],"ltp":0.0,"tv":0.0,"id":27652444}]}]}
{"op":"mcm","clk":"989003540","pt":1580512840722,"mc":[{"id":"1.168119366","rc":[{"batb":[[1,2.02,2],[2,2,56.35]],"ltp":0.0,"tv":0.0,"id":23010367},{"batb":[[1,1.74,2],[2,1.73,76.46]],"ltp":0.0,"tv":0.0,"id":27652444}]}]}
{"op":"mcm","clk":"989192787","pt":1580515628586,"mc":[{"id":"1.168119366","marketDefinition":{"bspMarket":false,"turnInPlayEnabled":true,"persistenceEnabled":true,"marketBaseRate":5.0,"eventId":"29678414","eventTypeId":"2","numberOfWinners":1,"bettingType":"ODDS","marketType":"SET_WINNER","marketTime":"2020-02-02T00:00:00.000Z","suspendTime":"2020-02-02T00:00:00.000Z","bspReconciled":false,"complete":true,"inPlay":false,"crossMatching":true,"runnersVoidable":false,"numberOfActiveRunners":2,"betDelay":0,"status":"OPEN","runners":[{"status":"ACTIVE","sortPriority":1,"id":23010367,"name":"Margaroli/Vavassori"},{"status":"ACTIVE","sortPriority":2,"id":27652444,"name":"Heliovaara/Verbeek"}],"regulators":["MR_INT"],"countryCode":"AU","discountAllowed":true,"timezone":"UTC","openDate":"2020-02-01T00:00:00.000Z","version":3144185908,"name":"Set 1 Winner","eventName":"Margaroli/Vavassori v Heliovaara/Verbeek"}}]}
{"op":"mcm","clk":"989193017","pt":1580515631592,"mc":[{"id":"1.168119366","marketDefinition":{"bspMarket":false,"turnInPlayEnabled":true,"persistenceEnabled":true,"marketBaseRate":5.0,"eventId":"29678414","eventTypeId":"2","numberOfWinners":1,"bettingType":"ODDS","marketType":"SET_WINNER","marketTime":"2020-02-02T00:00:00.000Z","suspendTime":"2020-02-02T00:00:00.000Z","bspReconciled":false,"complete":true,"inPlay":false,"crossMatching":true,"runnersVoidable":false,"numberOfActiveRunners":2,"betDelay":0,"status":"OPEN","runners":[{"status":"ACTIVE","sortPriority":1,"id":23010367,"name":"Margaroli/Vavassori"},{"status":"ACTIVE","sortPriority":2,"id":27652444,"name":"Heliovaara/Verbeek"}],"regulators":["MR_INT"],"countryCode":"AU","discountAllowed":true,"timezone":"UTC","openDate":"2020-02-02T00:00:00.000Z","version":3144185908,"name":"Set 1 Winner","eventName":"Margaroli/Vavassori v Heliovaara/Verbeek"}}]}
{"op":"mcm","clk":"989197917","pt":1580515721114,"mc":[{"id":"1.168119366","rc":[{"batb":[[2,2,29.17]],"ltp":0.0,"tv":0.0,"id":23010367},{"batb":[[2,1.73,39.23]],"ltp":0.0,"tv":0.0,"id":27652444}]}]}
{"op":"mcm","clk":"989290601","pt":1580517060298,"mc":[{"id":"1.168119366","rc":[{"batb":[[2,2,27.17]],"ltp":0.0,"tv":0.0,"id":23010367}]}]}
{"op":"mcm","clk":"989754268","pt":1580523203628,"mc":[{"id":"1.168119366","rc":[{"batb":[[1,1.73,37.23],[2,1.01,11.01]],"ltp":0.0,"tv":0.0,"id":27652444}]}]}
{"op":"mcm","clk":"989754320","pt":1580523204656,"mc":[{"id":"1.168119366","rc":[{"batb":[[1,2,27.17],[2,1.01,11.01]],"ltp":0.0,"tv":0.0,"id":23010367}]}]}
{"op":"mcm","clk":"997278910","pt":1580579986746,"mc":[{"id":"1.168119366","rc":[{"batb":[[1,2,29.52]],"ltp":0.0,"tv":0.0,"id":23010367},{"batb":[[1,1.73,40.44]],"ltp":0.0,"tv":0.0,"id":27652444}]}]}
{"op":"mcm","clk":"997281063","pt":1580580001877,"mc":[{"id":"1.168119366","rc":[{"batb":[[1,2,44.28]],"ltp":0.0,"tv":0.0,"id":23010367},{"batb":[[1,1.73,60.66]],"ltp":0.0,"tv":0.0,"id":27652444}]}]}
{"op":"mcm","clk":"999360442","pt":1580594401784,"mc":[{"id":"1.168119366","rc":[{"batb":[[1,2,59.04]],"ltp":0.0,"tv":0.0,"id":23010367},{"batb":[[1,1.73,80.89]],"ltp":0.0,"tv":0.0,"id":27652444}]}]}
{"op":"mcm","clk":"999393986","pt":1580594807659,"mc":[{"id":"1.168119366","rc":[{"batb":[[2,1.01,11.02]],"ltp":0.0,"tv":0.0,"id":23010367},{"batb":[[2,1.01,11.02]],"ltp":0.0,"tv":0.0,"id":27652444}]}]}
{"op":"mcm","clk":"999671462","pt":1580598640591,"mc":[{"id":"1.168119366","rc":[{"batb":[[1,2.02,2],[2,2,59.04]],"ltp":0.0,"tv":0.0,"id":23010367},{"batb":[[1,1.74,2],[2,1.73,80.89]],"ltp":0.0,"tv":0.0,"id":27652444}]}]}
{"op":"mcm","clk":"999718722","pt":1580599240592,"mc":[{"id":"1.168119366","rc":[{"batb":[[1,2,59.04],[2,1.01,11.02]],"ltp":0.0,"tv":0.0,"id":23010367},{"batb":[[1,1.73,80.89],[2,1.01,11.02]],"ltp":0.0,"tv":0.0,"id":27652444}]}]}
{"op":"mcm","clk":"999719517","pt":1580599250406,"mc":[{"id":"1.168119366","rc":[{"batb":[[1,2.02,2],[2,2,59.04]],"ltp":0.0,"tv":0.0,"id":23010367},{"batb":[[1,1.74,2],[2,1.73,80.89]],"ltp":0.0,"tv":0.0,"id":27652444}]}]}
{"op":"mcm","clk":"999758762","pt":1580599849611,"mc":[{"id":"1.168119366","rc":[{"batb":[[1,2,59.04],[2,1.01,11.02]],"ltp":0.0,"tv":0.0,"id":23010367}]}]}
{"op":"mcm","clk":"999758824","pt":1580599850500,"mc":[{"id":"1.168119366","rc":[{"batb":[[1,2.02,2],[2,2,59.04]],"ltp":0.0,"tv":0.0,"id":23010367}]}]}
{"op":"mcm","clk":"999793530","pt":1580600449616,"mc":[{"id":"1.168119366","rc":[{"batb":[[1,1.73,80.89],[2,1.01,11.02]],"ltp":0.0,"tv":0.0,"id":27652444}]}]}
{"op":"mcm","clk":"999793544","pt":1580600449824,"mc":[{"id":"1.168119366","rc":[{"batb":[[1,2,59.04],[2,1.01,11.02]],"ltp":0.0,"tv":0.0,"id":23010367}]}]}
{"op":"mcm","clk":"999794179","pt":1580600459697,"mc":[{"id":"1.168119366","rc":[{"batb":[[1,2.02,2],[2,2,59.04]],"ltp":0.0,"tv":0.0,"id":23010367},{"batb":[[1,1.74,2],[2,1.73,80.89]],"ltp":0.0,"tv":0.0,"id":27652444}]}]}
{"op":"mcm","clk":"999797144","pt":1580600511640,"mc":[{"id":"1.168119366","marketDefinition":{"bspMarket":false,"turnInPlayEnabled":true,"persistenceEnabled":true,"marketBaseRate":5.0,"eventId":"29678414","eventTypeId":"2","numberOfWinners":1,"bettingType":"ODDS","marketType":"SET_WINNER","marketTime":"2020-02-02T00:30:00.000Z","suspendTime":"2020-02-02T00:30:00.000Z","bspReconciled":false,"complete":true,"inPlay":false,"crossMatching":true,"runnersVoidable":false,"numberOfActiveRunners":2,"betDelay":0,"status":"OPEN","runners":[{"status":"ACTIVE","sortPriority":1,"id":23010367,"name":"Margaroli/Vavassori"},{"status":"ACTIVE","sortPriority":2,"id":27652444,"name":"Heliovaara/Verbeek"}],"regulators":["MR_INT"],"countryCode":"AU","discountAllowed":true,"timezone":"UTC","openDate":"2020-02-02T00:00:00.000Z","version":3147850865,"name":"Set 1 Winner","eventName":"Margaroli/Vavassori v Heliovaara/Verbeek"}}]}
{"op":"mcm","clk":"999797210","pt":1580600512641,"mc":[{"id":"1.168119366","marketDefinition":{"bspMarket":false,"turnInPlayEnabled":true,"persistenceEnabled":true,"marketBaseRate":5.0,"eventId":"29678414","eventTypeId":"2","numberOfWinners":1,"bettingType":"ODDS","marketType":"SET_WINNER","marketTime":"2020-02-02T00:30:00.000Z","suspendTime":"2020-02-02T00:30:00.000Z","bspReconciled":false,"complete":true,"inPlay":false,"crossMatching":true,"runnersVoidable":false,"numberOfActiveRunners":2,"betDelay":0,"status":"OPEN","runners":[{"status":"ACTIVE","sortPriority":1,"id":23010367,"name":"Margaroli/Vavassori"},{"status":"ACTIVE","sortPriority":2,"id":27652444,"name":"Heliovaara/Verbeek"}],"regulators":["MR_INT"],"countryCode":"AU","discountAllowed":true,"timezone":"UTC","openDate":"2020-02-02T00:30:00.000Z","version":3147850865,"name":"Set 1 Winner","eventName":"Margaroli/Vavassori v Heliovaara/Verbeek"}}]}
{"op":"mcm","clk":"999830247","pt":1580601058981,"mc":[{"id":"1.168119366","rc":[{"batb":[[1,1.73,80.89],[2,1.01,11.02]],"ltp":0.0,"tv":0.0,"id":27652444}]}]}
{"op":"mcm","clk":"999830304","pt":1580601059963,"mc":[{"id":"1.168119366","rc":[{"batb":[[1,2,59.04],[2,1.01,11.02]],"ltp":0.0,"tv":0.0,"id":23010367}]}]}
{"op":"mcm","clk":"999830374","pt":1580601061161,"mc":[{"id":"1.168119366","rc":[{"batb":[[1,2.02,2],[2,2,59.04]],"ltp":0.0,"tv":0.0,"id":23010367},{"batb":[[1,1.74,2],[2,1.73,80.89]],"ltp":0.0,"tv":0.0,"id":27652444}]}]}
{"op":"mcm","clk":"999840590","pt":1580601240520,"mc":[{"id":"1.168119366","rc":[{"batb":[[1,1.73,80.89],[2,1.01,11.02]],"ltp":0.0,"tv":0.0,"id":27652444}]}]}
{"op":"mcm","clk":"999840617","pt":1580601240977,"mc":[{"id":"1.168119366","rc":[{"batb":[[1,2,59.04],[2,1.01,11.02]],"ltp":0.0,"tv":0.0,"id":23010367}]}]}
{"op":"mcm","clk":"999840786","pt":1580601243515,"mc":[{"id":"1.168119366","rc":[{"batb":[[1,2.02,2],[2,2,59.04]],"ltp":0.0,"tv":0.0,"id":23010367},{"batb":[[1,1.74,2],[2,1.73,80.89]],"ltp":0.0,"tv":0.0,"id":27652444}]}]}
{"op":"mcm","clk":"999850358","pt":1580601423219,"mc":[{"id":"1.168119366","rc":[{"batb":[[1,2,59.04],[2,1.01,11.02]],"ltp":0.0,"tv":0.0,"id":23010367},{"batb":[[1,1.73,80.89],[2,1.01,11.02]],"ltp":0.0,"tv":0.0,"id":27652444}]}]}
{"op":"mcm","clk":"999850476","pt":1580601425400,"mc":[{"id":"1.168119366","rc":[{"batb":[[1,2.02,2],[2,2,59.04]],"ltp":0.0,"tv":0.0,"id":23010367},{"batb":[[1,1.74,2],[2,1.73,80.89]],"ltp":0.0,"tv":0.0,"id":27652444}]}]}
{"op":"mcm","clk":"999853382","pt":1580601484669,"mc":[{"id":"1.168119366","rc":[{"batb":[[1,1.73,80.89],[2,1.01,11.02]],"ltp":0.0,"tv":0.0,"id":27652444}]}]}
{"op":"mcm","clk":"999853389","pt":1580601484869,"mc":[{"id":"1.168119366","rc":[{"batb":[[1,2,59.04],[2,1.01,11.02]],"ltp":0.0,"tv":0.0,"id":23010367}]}]}
{"op":"mcm","clk":"999853840","pt":1580601494094,"mc":[{"id":"1.168119366","rc":[{"batb":[[1,2.02,2],[2,2,59.04]],"ltp":0.0,"tv":0.0,"id":23010367},{"batb":[[1,1.74,2],[2,1.73,80.89]],"ltp":0.0,"tv":0.0,"id":27652444}]}]}
{"op":"mcm","clk":"999856876","pt":1580601553650,"mc":[{"id":"1.168119366","rc":[{"batb":[[1,2,59.04],[2,1.01,11.02]],"ltp":0.0,"tv":0.0,"id":23010367},{"batb":[[1,1.73,80.89],[2,1.01,11.02]],"ltp":0.0,"tv":0.0,"id":27652444}]}]}
{"op":"mcm","clk":"999857389","pt":1580601563052,"mc":[{"id":"1.168119366","rc":[{"batb":[[1,2.02,2],[2,2,59.04]],"ltp":0.0,"tv":0.0,"id":23010367},{"batb":[[1,1.74,2],[2,1.73,80.89]],"ltp":0.0,"tv":0.0,"id":27652444}]}]}
{"op":"mcm","clk":"999864789","pt":1580601735559,"mc":[{"id":"1.168119366","rc":[{"batb":[[1,2,59.04],[2,1.01,11.02]],"ltp":0.0,"tv":0.0,"id":23010367},{"batb":[[1,1.73,80.89],[2,1.01,11.02]],"ltp":0.0,"tv":0.0,"id":27652444}]}]}
{"op":"mcm","clk":"999865106","pt":1580601743077,"mc":[{"id":"1.168119366","rc":[{"batb":[[1,2.02,2],[2,2,59.04]],"ltp":0.0,"tv":0.0,"id":23010367},{"batb":[[1,1.74,2],[2,1.73,80.89]],"ltp":0.0,"tv":0.0,"id":27652444}]}]}
{"op":"mcm","clk":"999867572","pt":1580601802562,"mc":[{"id":"1.168119366","rc":[{"batb":[[1,2,59.04],[2,1.01,11.02]],"ltp":0.0,"tv":0.0,"id":23010367},{"batb":[[1,1.73,80.89],[2,1.01,11.02]],"ltp":0.0,"tv":0.0,"id":27652444}]}]}
{"op":"mcm","clk":"999867945","pt":1580601810864,"mc":[{"id":"1.168119366","rc":[{"batb":[[1,2.02,2],[2,2,59.04]],"ltp":0.0,"tv":0.0,"id":23010367},{"batb":[[1,1.74,2],[2,1.73,80.89]],"ltp":0.0,"tv":0.0,"id":27652444}]}]}
{"op":"mcm","clk":"999870818","pt":1580601870385,"mc":[{"id":"1.168119366","rc":[{"batb":[[1,2,59.04],[2,1.01,11.02]],"ltp":0.0,"tv":0.0,"id":23010367},{"batb":[[1,1.73,80.89],[2,1.01,11.02]],"ltp":0.0,"tv":0.0,"id":27652444}]}]}
{"op":"mcm","clk":"999871129","pt":1580601878978,"mc":[{"id":"1.168119366","rc":[{"batb":[[1,2.02,2],[2,2,59.04]],"ltp":0.0,"tv":0.0,"id":23010367},{"batb":[[1,1.74,2],[2,1.73,80.89]],"ltp":0.0,"tv":0.0,"id":27652444}]}]}
{"op":"mcm","clk":"999873631","pt":1580601938350,"mc":[{"id":"1.168119366","rc":[{"batb":[[1,2,59.04],[2,1.01,11.02]],"ltp":0.0,"tv":0.0,"id":23010367},{"batb":[[1,1.73,80.89],[2,1.01,11.02]],"ltp":0.0,"tv":0.0,"id":27652444}]}]}
{"op":"mcm","clk":"999916774","pt":1580602611008,"mc":[{"id":"1.168119366","marketDefinition":{"bspMarket":false,"turnInPlayEnabled":true,"persistenceEnabled":true,"marketBaseRate":5.0,"eventId":"29678414","eventTypeId":"2","numberOfWinners":1,"bettingType":"ODDS","marketType":"SET_WINNER","marketTime":"2020-02-02T01:00:00.000Z","suspendTime":"2020-02-02T01:00:00.000Z","bspReconciled":false,"complete":true,"inPlay":false,"crossMatching":true,"runnersVoidable":false,"numberOfActiveRunners":2,"betDelay":0,"status":"OPEN","runners":[{"status":"ACTIVE","sortPriority":1,"id":23010367,"name":"Margaroli/Vavassori"},{"status":"ACTIVE","sortPriority":2,"id":27652444,"name":"Heliovaara/Verbeek"}],"regulators":["MR_INT"],"countryCode":"AU","discountAllowed":true,"timezone":"UTC","openDate":"2020-02-02T00:30:00.000Z","version":3147905857,"name":"Set 1 Winner","eventName":"Margaroli/Vavassori v Heliovaara/Verbeek"}}]}
{"op":"mcm","clk":"999917049","pt":1580602615018,"mc":[{"id":"1.168119366","marketDefinition":{"bspMarket":false,"turnInPlayEnabled":true,"persistenceEnabled":true,"marketBaseRate":5.0,"eventId":"29678414","eventTypeId":"2","numberOfWinners":1,"bettingType":"ODDS","marketType":"SET_WINNER","marketTime":"2020-02-02T01:00:00.000Z","suspendTime":"2020-02-02T01:00:00.000Z","bspReconciled":false,"complete":true,"inPlay":false,"crossMatching":true,"runnersVoidable":false,"numberOfActiveRunners":2,"betDelay":0,"status":"OPEN","runners":[{"status":"ACTIVE","sortPriority":1,"id":23010367,"name":"Margaroli/Vavassori"},{"status":"ACTIVE","sortPriority":2,"id":27652444,"name":"Heliovaara/Verbeek"}],"regulators":["MR_INT"],"countryCode":"AU","discountAllowed":true,"timezone":"UTC","openDate":"2020-02-02T01:00:00.000Z","version":3147905857,"name":"Set 1 Winner","eventName":"Margaroli/Vavassori v Heliovaara/Verbeek"}}]}
{"op":"mcm","clk":"1000039946","pt":1580605014215,"mc":[{"id":"1.168119366","marketDefinition":{"bspMarket":false,"turnInPlayEnabled":true,"persistenceEnabled":true,"marketBaseRate":5.0,"eventId":"29678414","eventTypeId":"2","numberOfWinners":1,"bettingType":"ODDS","marketType":"SET_WINNER","marketTime":"2020-02-02T00:54:00.000Z","suspendTime":"2020-02-02T00:54:00.000Z","bspReconciled":false,"complete":true,"inPlay":false,"crossMatching":true,"runnersVoidable":false,"numberOfActiveRunners":2,"betDelay":0,"status":"OPEN","runners":[{"status":"ACTIVE","sortPriority":1,"id":23010367,"name":"Margaroli/Vavassori"},{"status":"ACTIVE","sortPriority":2,"id":27652444,"name":"Heliovaara/Verbeek"}],"regulators":["MR_INT"],"countryCode":"AU","discountAllowed":true,"timezone":"UTC","openDate":"2020-02-02T01:00:00.000Z","version":3147960884,"name":"Set 1 Winner","eventName":"Margaroli/Vavassori v Heliovaara/Verbeek"}}]}
{"op":"mcm","clk":"1000040019","pt":1580605016258,"mc":[{"id":"1.168119366","marketDefinition":{"bspMarket":false,"turnInPlayEnabled":true,"persistenceEnabled":true,"marketBaseRate":5.0,"eventId":"29678414","eventTypeId":"2","numberOfWinners":1,"bettingType":"ODDS","marketType":"SET_WINNER","marketTime":"2020-02-02T00:54:00.000Z","suspendTime":"2020-02-02T00:54:00.000Z","bspReconciled":false,"complete":true,"inPlay":false,"crossMatching":true,"runnersVoidable":false,"numberOfActiveRunners":2,"betDelay":0,"status":"OPEN","runners":[{"status":"ACTIVE","sortPriority":1,"id":23010367,"name":"Margaroli/Vavassori"},{"status":"ACTIVE","sortPriority":2,"id":27652444,"name":"Heliovaara/Verbeek"}],"regulators":["MR_INT"],"countryCode":"AU","discountAllowed":true,"timezone":"UTC","openDate":"2020-02-02T00:54:00.000Z","version":3147960884,"name":"Set 1 Winner","eventName":"Margaroli/Vavassori v Heliovaara/Verbeek"}}]}
{"op":"mcm","clk":"1000059872","pt":1580605690260,"mc":[{"id":"1.168119366","rc":[{"batb":[[1,1.67,88.13]],"ltp":0.0,"tv":0.0,"id":27652444}]}]}
{"op":"mcm","clk":"1000070110","pt":1580606050651,"mc":[{"id":"1.168119366","marketDefinition":{"bspMarket":false,"turnInPlayEnabled":true,"persistenceEnabled":true,"marketBaseRate":5.0,"eventId":"29678414","eventTypeId":"2","numberOfWinners":1,"bettingType":"ODDS","marketType":"SET_WINNER","marketTime":"2020-02-02T00:54:00.000Z","suspendTime":"2020-02-02T00:54:00.000Z","bspReconciled":false,"complete":true,"inPlay":true,"crossMatching":true,"runnersVoidable":false,"numberOfActiveRunners":2,"betDelay":3,"status":"OPEN","runners":[{"status":"ACTIVE","sortPriority":1,"id":23010367,"name":"Margaroli/Vavassori"},{"status":"ACTIVE","sortPriority":2,"id":27652444,"name":"Heliovaara/Verbeek"}],"regulators":["MR_INT"],"countryCode":"AU","discountAllowed":true,"timezone":"UTC","openDate":"2020-02-02T00:54:00.000Z","version":3147986616,"name":"Set 1 Winner","eventName":"Margaroli/Vavassori v Heliovaara/Verbeek"}}]}
{"op":"mcm","clk":"1000070112","pt":1580606050755,"mc":[{"id":"1.168119366","rc":[{"batb":[[0,1.01,10.52],[1,2,0],[2,1.01,0]],"ltp":0.0,"tv":0.0,"id":23010367},{"batb":[[0,1.01,10.52],[1,1.67,0],[2,1.01,0]],"ltp":0.0,"tv":0.0,"id":27652444}]}]}
{"op":"mcm","clk":"1000076479","pt":1580606287657,"mc":[{"id":"1.168119366","rc":[{"batb":[[0,1.31,477.52],[1,1.01,10.51]],"ltp":0.0,"tv":0.0,"id":23010367},{"batb":[[0,2.12,388.65],[1,1.01,10.52]],"ltp":0.0,"tv":0.0,"id":27652444}]}]}
{"op":"mcm","clk":"1000076993","pt":1580606300752,"mc":[{"id":"1.168119366","rc":[{"batb":[[0,1.01,10.52],[1,1.01,0]],"ltp":0.0,"tv":0.0,"id":23010367},{"batb":[[0,1.01,10.52],[1,1.01,0]],"ltp":0.0,"tv":0.0,"id":27652444}]}]}
{"op":"mcm","clk":"1000077157","pt":1580606304775,"mc":[{"id":"1.168119366","rc":[{"batb":[[0,1.22,523.01],[1,1.01,10.51]],"ltp":0.0,"tv":0.0,"id":23010367},{"batb":[[0,2.42,381.73],[1,1.01,10.52]],"ltp":0.0,"tv":0.0,"id":27652444}]}]}
{"op":"mcm","clk":"1000078542","pt":1580606344900,"mc":[{"id":"1.168119366","rc":[{"batb":[[0,1.01,10.52],[1,1.01,0]],"ltp":0.0,"tv":0.0,"id":23010367}]}]}
{"op":"mcm","clk":"1000078705","pt":1580606349128,"mc":[{"id":"1.168119366","rc":[{"batb":[[0,1.28,485.66],[1,1.01,10.51]],"ltp":0.0,"tv":0.0,"id":23010367}]}]}
{"op":"mcm","clk":"1000079579","pt":1580606372982,"mc":[{"id":"1.168119366","rc":[{"batb":[[0,1.01,10.52],[1,1.01,0]],"ltp":0.0,"tv":0.0,"id":23010367},{"batb":[[0,1.01,10.52],[1,1.01,0]],"ltp":0.0,"tv":0.0,"id":27652444}]}]}
{"op":"mcm","clk":"1000079719","pt":1580606376655,"mc":[{"id":"1.168119366","rc":[{"batb":[[0,1.44,435.96],[1,1.01,10.51]],"ltp":0.0,"tv":0.0,"id":23010367},{"batb":[[0,1.86,398.82],[1,1.01,10.52]],"ltp":0.0,"tv":0.0,"id":27652444}]}]}
{"op":"mcm","clk":"1000080553","pt":1580606401096,"mc":[{"id":"1.168119366","rc":[{"batb":[[0,1.01,10.52],[1,1.01,0]],"ltp":0.0,"tv":0.0,"id":23010367},{"batb":[[0,1.01,10.52],[1,1.01,0]],"ltp":0.0,"tv":0.0,"id":27652444}]}]}
{"op":"mcm","clk":"1000080666","pt":1580606404508,"mc":[{"id":"1.168119366","rc":[{"batb":[[0,1.31,477.27],[1,1.01,10.51]],"ltp":0.0,"tv":0.0,"id":23010367},{"batb":[[0,2.12,388.83],[1,1.01,10.52]],"ltp":0.0,"tv":0.0,"id":27652444}]}]}
{"op":"mcm","clk":"1000081460","pt":1580606427137,"mc":[{"id":"1.168119366","rc":[{"batb":[[0,1.01,10.52],[1,1.01,0]],"ltp":0.0,"tv":0.0,"id":23010367},{"batb":[[0,1.01,10.52],[1,1.01,0]],"ltp":0.0,"tv":0.0,"id":27652444}]}]}
{"op":"mcm","clk":"1000081731","pt":1580606435782,"mc":[{"id":"1.168119366","rc":[{"batb":[[0,1.38,448.22],[1,1.01,10.51]],"ltp":0.0,"tv":0.0,"id":23010367},{"batb":[[0,1.97,395.05],[1,1.01,10.52]],"ltp":0.0,"tv":0.0,"id":27652444}]}]}
{"op":"mcm","clk":"1000082027","pt":1580606446210,"mc":[{"id":"1.168119366","rc":[{"batb":[[0,1.01,10.52],[1,1.01,0]],"ltp":0.0,"tv":0.0,"id":23010367},{"batb":[[0,1.01,10.52],[1,1.01,0]],"ltp":0.0,"tv":0.0,"id":27652444}]}]}
{"op":"mcm","clk":"1000082505","pt":1580606459994,"mc":[{"id":"1.168119366","rc":[{"batb":[[0,1.67,409.54],[1,1.01,10.52]],"ltp":0.0,"tv":0.0,"id":23010367},{"batb":[[0,1.58,416.69],[1,1.01,10.52]],"ltp":0.0,"tv":0.0,"id":27652444}]}]}
{"op":"mcm","clk":"1000084865","pt":1580606519410,"mc":[{"id":"1.168119366","rc":[{"batb":[[0,1.01,10.52],[1,1.01,0]],"ltp":0.0,"tv":0.0,"id":27652444}]}]}
{"op":"mcm","clk":"1000084987","pt":1580606523121,"mc":[{"id":"1.168119366","rc":[{"batb":[[0,1.67,409.97],[1,1.01,10.52]],"ltp":0.0,"tv":0.0,"id":27652444}]}]}
{"op":"mcm","clk":"1000086529","pt":1580606568582,"mc":[{"id":"1.168119366","rc":[{"batb":[[0,1.01,10.52],[1,1.01,0]],"ltp":0.0,"tv":0.0,"id":23010367},{"batb":[[0,1.01,10.52],[1,1.01,0]],"ltp":0.0,"tv":0.0,"id":27652444}]}]}
{"op":"mcm","clk":"1000086623","pt":1580606572196,"mc":[{"id":"1.168119366","rc":[{"batb":[[0,1.5,473.23],[1,1.01,10.52]],"ltp":0.0,"tv":0.0,"id":23010367},{"batb":[[0,1.77,363.13],[1,1.01,10.52]],"ltp":0.0,"tv":0.0,"id":27652444}]}]}
{"op":"mcm","clk":"1000087577","pt":1580606600595,"mc":[{"id":"1.168119366","rc":[{"batb":[[0,1.01,10.52],[1,1.01,0]],"ltp":0.0,"tv":0.0,"id":23010367}]}]}
{"op":"mcm","clk":"1000087708","pt":1580606604342,"mc":[{"id":"1.168119366","rc":[{"batb":[[0,1.58,461.23],[1,1.01,10.52]],"ltp":0.0,"tv":0.0,"id":23010367}]}]}
{"op":"mcm","clk":"1000088834","pt":1580606639791,"mc":[{"id":"1.168119366","rc":[{"batb":[[0,1.01,10.52],[1,1.01,0]],"ltp":0.0,"tv":0.0,"id":23010367},{"batb":[[0,1.01,10.52],[1,1.01,0]],"ltp":0.0,"tv":0.0,"id":27652444}]}]}
{"op":"mcm","clk":"1000088917","pt":1580606643459,"mc":[{"id":"1.168119366","rc":[{"batb":[[0,1.4,500.05],[1,1.01,10.51]],"ltp":0.0,"tv":0.0,"id":23010367},{"batb":[[0,1.92,359.81],[1,1.01,10.52]],"ltp":0.0,"tv":0.0,"id":27652444}]}]}
{"op":"mcm","clk":"1000089765","pt":1580606671598,"mc":[{"id":"1.168119366","rc":[{"batb":[[0,1.01,10.52],[1,1.01,0]],"ltp":0.0,"tv":0.0,"id":23010367},{"batb":[[0,1.01,10.52],[1,1.01,0]],"ltp":0.0,"tv":0.0,"id":27652444}]}]}
{"op":"mcm","clk":"1000089829","pt":1580606674593,"mc":[{"id":"1.168119366","rc":[{"batb":[[0,1.55,466.54],[1,1.01,10.52]],"ltp":0.0,"tv":0.0,"id":23010367},{"batb":[[0,1.7,367.25],[1,1.01,10.52]],"ltp":0.0,"tv":0.0,"id":27652444}]}]}
{"op":"mcm","clk":"1000090597","pt":1580606699859,"mc":[{"id":"1.168119366","rc":[{"batb":[[0,1.01,10.52],[1,1.01,0]],"ltp":0.0,"tv":0.0,"id":23010367},{"batb":[[0,1.01,10.52],[1,1.01,0]],"ltp":0.0,"tv":0.0,"id":27652444}]}]}
{"op":"mcm","clk":"1000090826","pt":1580606706652,"mc":[{"id":"1.168119366","rc":[{"batb":[[0,1.46,483.27],[1,1.01,10.51]],"ltp":0.0,"tv":0.0,"id":23010367},{"batb":[[0,1.82,363.33],[1,1.01,10.52]],"ltp":0.0,"tv":0.0,"id":27652444}]}]}
{"op":"mcm","clk":"1000091077","pt":1580606711965,"mc":[{"id":"1.168119366","rc":[{"batb":[[0,1.01,10.52],[1,1.01,0]],"ltp":0.0,"tv":0.0,"id":23010367},{"batb":[[0,1.01,10.52],[1,1.01,0]],"ltp":0.0,"tv":0.0,"id":27652444}]}]}
{"op":"mcm","clk":"1000091531","pt":1580606722782,"mc":[{"id":"1.168119366","rc":[{"batb":[[0,1.77,444.16],[1,1.01,10.52]],"ltp":0.0,"tv":0.0,"id":23010367},{"batb":[[0,1.5,379.89],[1,1.01,10.52]],"ltp":0.0,"tv":0.0,"id":27652444}]}]}
{"op":"mcm","clk":"1000094039","pt":1580606795302,"mc":[{"id":"1.168119366","rc":[{"batb":[[0,1.01,10.52],[1,1.01,0]],"ltp":0.0,"tv":0.0,"id":23010367},{"batb":[[0,1.01,10.52],[1,1.01,0]],"ltp":0.0,"tv":0.0,"id":27652444}]}]}
{"op":"mcm","clk":"1000094154","pt":1580606799062,"mc":[{"id":"1.168119366","rc":[{"batb":[[0,1.92,434.53],[1,1.01,10.52]],"ltp":0.0,"tv":0.0,"id":23010367},{"batb":[[0,1.4,401.35],[1,1.01,10.51]],"ltp":0.0,"tv":0.0,"id":27652444}]}]}
{"op":"mcm","clk":"1000094685","pt":1580606815295,"mc":[{"id":"1.168119366","rc":[{"batb":[[0,1.01,10.52],[1,1.01,0]],"ltp":0.0,"tv":0.0,"id":23010367},{"batb":[[0,1.01,10.52],[1,1.01,0]],"ltp":0.0,"tv":0.0,"id":27652444}]}]}
{"op":"mcm","clk":"1000094829","pt":1580606819081,"mc":[{"id":"1.168119366","rc":[{"batb":[[0,2.04,432.99],[1,1.01,10.52]],"ltp":0.0,"tv":0.0,"id":23010367},{"batb":[[0,1.34,415.8],[1,1.01,10.51]],"ltp":0.0,"tv":0.0,"id":27652444}]}]}
{"op":"mcm","clk":"1000095172","pt":1580606828325,"mc":[{"id":"1.168119366","rc":[{"batb":[[0,1.01,10.52],[1,1.01,0]],"ltp":0.0,"tv":0.0,"id":23010367},{"batb":[[0,1.01,10.52],[1,1.01,0]],"ltp":0.0,"tv":0.0,"id":27652444}]}]}
{"op":"mcm","clk":"1000095318","pt":1580606832240,"mc":[{"id":"1.168119366","rc":[{"batb":[[0,1.82,442.89],[1,1.01,10.52]],"ltp":0.0,"tv":0.0,"id":23010367},{"batb":[[0,1.46,388.15],[1,1.01,10.51]],"ltp":0.0,"tv":0.0,"id":27652444}]}]}
{"op":"mcm","clk":"1000096047","pt":1580606854468,"mc":[{"id":"1.168119366","rc":[{"batb":[[0,1.01,10.52],[1,1.01,0]],"ltp":0.0,"tv":0.0,"id":27652444}]}]}
{"op":"mcm","clk":"1000096182","pt":1580606858344,"mc":[{"id":"1.168119366","rc":[{"batb":[[0,1.55,374.47],[1,1.01,10.52]],"ltp":0.0,"tv":0.0,"id":27652444}]}]}
{"op":"mcm","clk":"1000097467","pt":1580606891513,"mc":[{"id":"1.168119366","rc":[{"batb":[[0,1.01,10.52],[1,1.01,0]],"ltp":0.0,"tv":0.0,"id":27652444}]}]}
{"op":"mcm","clk":"1000097604","pt":1580606895443,"mc":[{"id":"1.168119366","rc":[{"batb":[[0,1.44,388.19],[1,1.01,10.51]],"ltp":0.0,"tv":0.0,"id":27652444}]}]}
{"op":"mcm","clk":"1000098537","pt":1580606917649,"mc":[{"id":"1.168119366","rc":[{"batb":[[0,1.01,10.52],[1,1.01,0]],"ltp":0.0,"tv":0.0,"id":23010367},{"batb":[[0,1.01,10.52],[1,1.01,0]],"ltp":0.0,"tv":0.0,"id":27652444}]}]}
{"op":"mcm","clk":"1000098665","pt":1580606921574,"mc":[{"id":"1.168119366","rc":[{"batb":[[0,1.97,434.24],[1,1.01,10.52]],"ltp":0.0,"tv":0.0,"id":23010367},{"batb":[[0,1.38,399.7],[1,1.01,10.51]],"ltp":0.0,"tv":0.0,"id":27652444}]}]}
{"op":"mcm","clk":"1000098917","pt":1580606929689,"mc":[{"id":"1.168119366","rc":[{"batb":[[0,1.01,10.52],[1,1.01,0]],"ltp":0.0,"tv":0.0,"id":23010367},{"batb":[[0,1.01,10.52],[1,1.01,0]],"ltp":0.0,"tv":0.0,"id":27652444}]}]}
{"op":"mcm","clk":"1000099078","pt":1580606933571,"mc":[{"id":"1.168119366","rc":[{"batb":[[0,1.7,452.64],[1,1.01,10.52]],"ltp":0.0,"tv":0.0,"id":23010367},{"batb":[[0,1.55,374.47],[1,1.01,10.52]],"ltp":0.0,"tv":0.0,"id":27652444}]}]}
{"op":"mcm","clk":"1000100025","pt":1580606960804,"mc":[{"id":"1.168119366","rc":[{"batb":[[0,1.01,10.52],[1,1.01,0]],"ltp":0.0,"tv":0.0,"id":27652444}]}]}
{"op":"mcm","clk":"1000100149","pt":1580606964689,"mc":[{"id":"1.168119366","rc":[{"batb":[[0,1.62,370.61],[1,1.01,10.52]],"ltp":0.0,"tv":0.0,"id":27652444}]}]}
{"op":"mcm","clk":"1000101201","pt":1580606991838,"mc":[{"id":"1.168119366","rc":[{"batb":[[0,1.01,10.52],[1,1.01,0]],"ltp":0.0,"tv":0.0,"id":23010367},{"batb":[[0,1.01,10.52],[1,1.01,0]],"ltp":0.0,"tv":0.0,"id":27652444}]}]}
{"op":"mcm","clk":"1000101357","pt":1580606995861,"mc":[{"id":"1.168119366","rc":[{"batb":[[0,1.58,462.21],[1,1.01,10.52]],"ltp":0.0,"tv":0.0,"id":23010367},{"batb":[[0,1.67,366.42],[1,1.01,10.52]],"ltp":0.0,"tv":0.0,"id":27652444}]}]}
{"op":"mcm","clk":"1000101832","pt":1580607008987,"mc":[{"id":"1.168119366","rc":[{"batb":[[0,1.01,10.52],[1,1.01,0]],"ltp":0.0,"tv":0.0,"id":23010367},{"batb":[[0,1.01,10.52],[1,1.01,0]],"ltp":0.0,"tv":0.0,"id":27652444}]}]}
{"op":"mcm","clk":"1000101959","pt":1580607012971,"mc":[{"id":"1.168119366","rc":[{"batb":[[0,1.7,452.64],[1,1.01,10.52]],"ltp":0.0,"tv":0.0,"id":23010367},{"batb":[[0,1.55,374.47],[1,1.01,10.52]],"ltp":0.0,"tv":0.0,"id":27652444}]}]}
{"op":"mcm","clk":"1000102574","pt":1580607033012,"mc":[{"id":"1.168119366","rc":[{"batb":[[0,1.01,10.52],[1,1.01,0]],"ltp":0.0,"tv":0.0,"id":23010367}]}]}
{"op":"mcm","clk":"1000102723","pt":1580607037405,"mc":[{"id":"1.168119366","rc":[{"batb":[[0,1.77,444.16],[1,1.01,10.52]],"ltp":0.0,"tv":0.0,"id":23010367}]}]}
{"op":"mcm","clk":"1000106673","pt":1580607135355,"mc":[{"id":"1.168119366","rc":[{"batb":[[0,1.01,10.52],[1,1.01,0]],"ltp":0.0,"tv":0.0,"id":27652444}]}]}
{"op":"mcm","clk":"1000106817","pt":1580607139551,"mc":[{"id":"1.168119366","rc":[{"batb":[[0,1.46,387.42],[1,1.01,10.51]],"ltp":0.0,"tv":0.0,"id":27652444}]}]}
{"op":"mcm","clk":"1000109758","pt":1580607206554,"mc":[{"id":"1.168119366","rc":[{"batb":[[0,1.01,10.52],[1,1.01,0]],"ltp":0.0,"tv":0.0,"id":23010367}]}]}
{"op":"mcm","clk":"1000110081","pt":1580607214197,"mc":[{"id":"1.168119366","rc":[{"batb":[[0,1.82,442.3],[1,1.01,10.52]],"ltp":0.0,"tv":0.0,"id":23010367}]}]}
{"op":"mcm","clk":"1000110740","pt":1580607229599,"mc":[{"id":"1.168119366","rc":[{"batb":[[0,1.01,10.52],[1,1.01,0]],"ltp":0.0,"tv":0.0,"id":27652444}]}]}
{"op":"mcm","clk":"1000110928","pt":1580607233374,"mc":[{"id":"1.168119366","rc":[{"batb":[[0,1.52,379.12],[1,1.01,10.52]],"ltp":0.0,"tv":0.0,"id":27652444}]}]}
{"op":"mcm","clk":"1000111867","pt":1580607252724,"mc":[{"id":"1.168119366","rc":[{"batb":[[0,1.01,10.52],[1,1.01,0]],"ltp":0.0,"tv":0.0,"id":27652444}]}]}
{"op":"mcm","clk":"1000112041","pt":1580607256542,"mc":[{"id":"1.168119366","rc":[{"batb":[[0,1.44,388.19],[1,1.01,10.51]],"ltp":0.0,"tv":0.0,"id":27652444}]}]}
{"op":"mcm","clk":"1000112759","pt":1580607273785,"mc":[{"id":"1.168119366","rc":[{"batb":[[0,1.01,10.52],[1,1.01,0]],"ltp":0.0,"tv":0.0,"id":23010367},{"batb":[[0,1.01,10.52],[1,1.01,0]],"ltp":0.0,"tv":0.0,"id":27652444}]}]}
{"op":"mcm","clk":"1000112937","pt":1580607277653,"mc":[{"id":"1.168119366","rc":[{"batb":[[0,2.12,425.41],[1,1.01,10.52]],"ltp":0.0,"tv":0.0,"id":23010367}]}]}
{"op":"mcm","clk":"1000112980","pt":1580607278441,"mc":[{"id":"1.168119366","rc":[{"batb":[[0,1.31,425.66],[1,1.01,10.51]],"ltp":0.0,"tv":0.0,"id":27652444}]}]}
{"op":"mcm","clk":"1000113707","pt":1580607293798,"mc":[{"id":"1.168119366","rc":[{"batb":[[0,1.01,10.52],[1,1.01,0]],"ltp":0.0,"tv":0.0,"id":23010367},{"batb":[[0,1.01,10.52],[1,1.01,0]],"ltp":0.0,"tv":0.0,"id":27652444}]}]}
{"op":"mcm","clk":"1000113878","pt":1580607297868,"mc":[{"id":"1.168119366","rc":[{"batb":[[0,2.3,419.79],[1,1.01,10.52]],"ltp":0.0,"tv":0.0,"id":23010367},{"batb":[[0,1.25,452.13],[1,1.01,10.51]],"ltp":0.0,"tv":0.0,"id":27652444}]}]}
{"op":"mcm","clk":"1000114191","pt":1580607305382,"mc":[{"id":"1.168119366","rc":[{"batb":[[0,1.01,10.52],[1,1.01,0]],"ltp":0.0,"tv":0.0,"id":23010367},{"batb":[[0,1.01,10.52],[1,1.01,0]],"ltp":0.0,"tv":0.0,"id":27652444}]}]}
{"op":"mcm","clk":"1000114344","pt":1580607309014,"mc":[{"id":"1.168119366","rc":[{"batb":[[0,1.92,434.53],[1,1.01,10.52]],"ltp":0.0,"tv":0.0,"id":23010367},{"batb":[[0,1.4,401.35],[1,1.01,10.51]],"ltp":0.0,"tv":0.0,"id":27652444}]}]}
{"op":"mcm","clk":"1000115734","pt":1580607341951,"mc":[{"id":"1.168119366","rc":[{"batb":[[0,1.01,10.52],[1,1.01,0]],"ltp":0.0,"tv":0.0,"id":23010367},{"batb":[[0,1.01,10.52],[1,1.01,0]],"ltp":0.0,"tv":0.0,"id":27652444}]}]}
{"op":"mcm","clk":"1000115905","pt":1580607346270,"mc":[{"id":"1.168119366","rc":[{"batb":[[0,2.38,416.28],[1,1.01,10.52]],"ltp":0.0,"tv":0.0,"id":23010367},{"batb":[[0,1.23,463.71],[1,1.01,10.51]],"ltp":0.0,"tv":0.0,"id":27652444}]}]}
{"op":"mcm","clk":"1000116467","pt":1580607360090,"mc":[{"id":"1.168119366","rc":[{"batb":[[0,1.01,10.52],[1,1.01,0]],"ltp":0.0,"tv":0.0,"id":23010367},{"batb":[[0,1.01,10.52],[1,1.01,0]],"ltp":0.0,"tv":0.0,"id":27652444}]}]}
{"op":"mcm","clk":"1000116962","pt":1580607371571,"mc":[{"id":"1.168119366","rc":[{"trd":[[3.1,0.01]],"ltp":3.1,"tv":0.0,"id":23010367},{"trd":[[1.48,0.01]],"batb":[[0,1.08,764.36],[1,1.01,10.51]],"ltp":1.48,"tv":0.01,"id":27652444}],"tv":0.01}]}
{"op":"mcm","clk":"1000118554","pt":1580607409245,"mc":[{"id":"1.168119366","rc":[{"batb":[[0,1.01,10.51],[1,1.01,0]],"ltp":1.48,"tv":0.01,"id":27652444}]}]}
{"op":"mcm","clk":"1000118699","pt":1580607412854,"mc":[{"id":"1.168119366","rc":[{"batb":[[0,2.8,405.05],[1,1.01,10.52]],"ltp":3.1,"tv":0.0,"id":23010367},{"batb":[[0,1.14,571.28],[1,1.01,10.51]],"ltp":1.48,"tv":0.01,"id":27652444}]}]}
{"op":"mcm","clk":"1000119846","pt":1580607443285,"mc":[{"id":"1.168119366","rc":[{"batb":[[0,1.01,10.51],[1,1.01,0]],"ltp":1.48,"tv":0.01,"id":27652444}]}]}
{"op":"mcm","clk":"1000120001","pt":1580607446991,"mc":[{"id":"1.168119366","rc":[{"batb":[[0,1.22,470.34],[1,1.01,10.51]],"ltp":1.48,"tv":0.01,"id":27652444}]}]}
{"op":"mcm","clk":"1000121280","pt":1580607479340,"mc":[{"id":"1.168119366","rc":[{"batb":[[0,1.01,10.52],[1,1.01,0]],"ltp":3.1,"tv":0.0,"id":23010367},{"batb":[[0,1.01,10.51],[1,1.01,0]],"ltp":1.48,"tv":0.01,"id":27652444}]}]}
{"op":"mcm","clk":"1000121442","pt":1580607483317,"mc":[{"id":"1.168119366","rc":[{"batb":[[0,2.04,432.26],[1,1.01,10.52]],"ltp":3.1,"tv":0.0,"id":23010367},{"batb":[[0,1.34,414.69],[1,1.01,10.51]],"ltp":1.48,"tv":0.01,"id":27652444}]}]}
{"op":"mcm","clk":"1000122223","pt":1580607505445,"mc":[{"id":"1.168119366","rc":[{"batb":[[0,1.01,10.51],[1,1.01,0]],"ltp":1.48,"tv":0.01,"id":27652444}]}]}
{"op":"mcm","clk":"1000122367","pt":1580607509466,"mc":[{"id":"1.168119366","rc":[{"batb":[[0,1.38,399.71],[1,1.01,10.51]],"ltp":1.48,"tv":0.01,"id":27652444}]}]}
{"op":"mcm","clk":"1000122693","pt":1580607518591,"mc":[{"id":"1.168119366","rc":[{"batb":[[0,1.01,10.52],[1,1.01,0]],"ltp":3.1,"tv":0.0,"id":23010367},{"batb":[[0,1.01,10.51],[1,1.01,0]],"ltp":1.48,"tv":0.01,"id":27652444}]}]}
{"op":"mcm","clk":"1000122846","pt":1580607522572,"mc":[{"id":"1.168119366","rc":[{"batb":[[0,1.82,442.88],[1,1.01,10.52]],"ltp":3.1,"tv":0.0,"id":23010367},{"batb":[[0,1.46,388.15],[1,1.01,10.51]],"ltp":1.48,"tv":0.01,"id":27652444}]}]}
{"op":"mcm","clk":"1000126149","pt":1580607609686,"mc":[{"id":"1.168119366","rc":[{"batb":[[0,1.01,10.52],[1,1.01,0]],"ltp":3.1,"tv":0.0,"id":23010367},{"batb":[[0,1.01,10.51],[1,1.01,0]],"ltp":1.48,"tv":0.01,"id":27652444}]}]}
{"op":"mcm","clk":"1000126240","pt":1580607612263,"mc":[{"id":"1.168119366","rc":[{"batb":[[0,2.04,432.26],[1,1.01,10.52]],"ltp":3.1,"tv":0.0,"id":23010367},{"batb":[[0,1.34,414.69],[1,1.01,10.51]],"ltp":1.48,"tv":0.01,"id":27652444}]}]}
{"op":"mcm","clk":"1000127266","pt":1580607642315,"mc":[{"id":"1.168119366","rc":[{"batb":[[0,1.01,10.52],[1,1.01,0]],"ltp":3.1,"tv":0.0,"id":23010367},{"batb":[[0,1.01,10.51],[1,1.01,0]],"ltp":1.48,"tv":0.01,"id":27652444}]}]}
{"op":"mcm","clk":"1000127390","pt":1580607645554,"mc":[{"id":"1.168119366","rc":[{"batb":[[0,2.42,414.87],[1,1.01,10.52]],"ltp":3.1,"tv":0.0,"id":23010367},{"batb":[[0,1.22,469.27],[1,1.01,10.51]],"ltp":1.48,"tv":0.01,"id":27652444}]}]}
{"op":"mcm","clk":"1000128066","pt":1580607662962,"mc":[{"id":"1.168119366","rc":[{"batb":[[0,1.01,10.52],[1,1.01,0]],"ltp":3.1,"tv":0.0,"id":23010367},{"batb":[[0,1.01,10.51],[1,1.01,0]],"ltp":1.48,"tv":0.01,"id":27652444}]}]}
{"op":"mcm","clk":"1000128341","pt":1580607669776,"mc":[{"id":"1.168119366","rc":[{"batb":[[0,2.62,410.94],[1,1.01,10.52]],"ltp":3.1,"tv":0.0,"id":23010367},{"batb":[[0,1.18,497.58],[1,1.01,10.51]],"ltp":1.48,"tv":0.01,"id":27652444}]}]}
{"op":"mcm","clk":"1000128870","pt":1580607674973,"mc":[{"id":"1.168119366","rc":[{"batb":[[0,1.01,10.52],[1,1.01,0]],"ltp":3.1,"tv":0.0,"id":23010367},{"batb":[[0,1.01,10.51],[1,1.01,0]],"ltp":1.48,"tv":0.01,"id":27652444}]}]}
{"op":"mcm","clk":"1000129215","pt":1580607683884,"mc":[{"id":"1.168119366","rc":[{"batb":[[0,3,409.1],[1,1.01,10.52]],"ltp":3.1,"tv":0.0,"id":23010367},{"batb":[[0,1.11,628.58],[1,1.01,10.51]],"ltp":1.48,"tv":0.01,"id":27652444}]}]}
{"op":"mcm","clk":"1000129917","pt":1580607703092,"mc":[{"id":"1.168119366","rc":[{"batb":[[0,1.01,10.52],[1,1.01,0]],"ltp":3.1,"tv":0.0,"id":23010367},{"batb":[[0,1.01,10.51],[1,1.01,0]],"ltp":1.48,"tv":0.01,"id":27652444}]}]}
{"op":"mcm","clk":"1000130621","pt":1580607721126,"mc":[{"id":"1.168119366","rc":[{"batb":[[0,2.72,408.61],[1,1.01,10.52]],"ltp":3.1,"tv":0.0,"id":23010367},{"batb":[[0,1.16,522.44],[1,1.01,10.51]],"ltp":1.48,"tv":0.01,"id":27652444}]}]}
{"op":"mcm","clk":"1000131355","pt":1580607739260,"mc":[{"id":"1.168119366","rc":[{"batb":[[0,1.01,10.52],[1,1.01,0]],"ltp":3.1,"tv":0.0,"id":23010367},{"batb":[[0,1.01,10.51],[1,1.01,0]],"ltp":1.48,"tv":0.01,"id":27652444}]}]}
{"op":"mcm","clk":"1000131668","pt":1580607746373,"mc":[{"id":"1.168119366","rc":[{"batb":[[0,2.42,414.87],[1,1.01,10.52]],"ltp":3.1,"tv":0.0,"id":23010367},{"batb":[[0,1.22,469.27],[1,1.01,10.51]],"ltp":1.48,"tv":0.01,"id":27652444}]}]}
{"op":"mcm","clk":"1000132462","pt":1580607764403,"mc":[{"id":"1.168119366","rc":[{"batb":[[0,1.01,10.52],[1,1.01,0]],"ltp":3.1,"tv":0.0,"id":23010367},{"batb":[[0,1.01,10.51],[1,1.01,0]],"ltp":1.48,"tv":0.01,"id":27652444}]}]}
{"op":"mcm","clk":"1000133435","pt":1580607793715,"mc":[{"id":"1.168119366","rc":[{"batb":[[0,2.72,408.61],[1,1.01,10.52]],"ltp":3.1,"tv":0.0,"id":23010367},{"batb":[[0,1.16,522.44],[1,1.01,10.51]],"ltp":1.48,"tv":0.01,"id":27652444}]}]}
{"op":"mcm","clk":"1000133619","pt":1580607798409,"mc":[{"id":"1.168119366","rc":[{"batb":[[0,1.01,10.52],[1,1.01,0]],"ltp":3.1,"tv":0.0,"id":23010367},{"batb":[[0,1.01,10.51],[1,1.01,0]],"ltp":1.48,"tv":0.01,"id":27652444}]}]}
{"op":"mcm","clk":"1000134173","pt":1580607812832,"mc":[{"id":"1.168119366","rc":[{"batb":[[0,3.6,398.49],[1,1.01,10.52]],"ltp":3.1,"tv":0.0,"id":23010367},{"batb":[[0,1.05,1012.59],[1,1.01,10.51]],"ltp":1.48,"tv":0.01,"id":27652444}]}]}
{"op":"mcm","clk":"1000135163","pt":1580607842594,"mc":[{"id":"1.168119366","rc":[{"batb":[[0,1.01,10.51],[1,1.01,0]],"ltp":1.48,"tv":0.01,"id":27652444}]}]}
{"op":"mcm","clk":"1000135176","pt":1580607843062,"mc":[{"id":"1.168119366","rc":[{"batb":[[0,1.01,10.52],[1,1.01,0]],"ltp":3.1,"tv":0.0,"id":23010367}]}]}
{"op":"mcm","clk":"1000135663","pt":1580607855191,"mc":[{"id":"1.168119366","rc":[{"batb":[[0,3.35,396.62],[1,1.01,10.52]],"ltp":3.1,"tv":0.0,"id":23010367},{"batb":[[0,1.07,832.79],[1,1.01,10.51]],"ltp":1.48,"tv":0.01,"id":27652444}]}]}
{"op":"mcm","clk":"1000135879","pt":1580607860611,"mc":[{"id":"1.168119366","rc":[{"batb":[[0,1.01,10.51],[1,1.01,0]],"ltp":1.48,"tv":0.01,"id":27652444}]}]}
{"op":"mcm","clk":"1000136014","pt":1580607864333,"mc":[{"id":"1.168119366","rc":[{"batb":[[0,1.11,628.58],[1,1.01,10.51]],"ltp":1.48,"tv":0.01,"id":27652444}]}]}
{"op":"mcm","clk":"1000137316","pt":1580607898623,"mc":[{"id":"1.168119366","rc":[{"batb":[[0,1.01,10.51],[1,1.01,0]],"ltp":1.48,"tv":0.01,"id":27652444}]}]}
{"op":"mcm","clk":"1000137493","pt":1580607902553,"mc":[{"id":"1.168119366","rc":[{"batb":[[0,1.14,571.28],[1,1.01,10.51]],"ltp":1.48,"tv":0.01,"id":27652444}]}]}
{"op":"mcm","clk":"1000137674","pt":1580607906636,"mc":[{"id":"1.168119366","rc":[{"batb":[[0,1.01,10.52],[1,1.01,0]],"ltp":3.1,"tv":0.0,"id":23010367},{"batb":[[0,1.01,10.51],[1,1.01,0]],"ltp":1.48,"tv":0.01,"id":27652444}]}]}
{"op":"mcm","clk":"1000137850","pt":1580607910656,"mc":[{"id":"1.168119366","rc":[{"batb":[[0,2.52,413.92],[1,1.01,10.52]],"ltp":3.1,"tv":0.0,"id":23010367},{"batb":[[0,1.2,478.47],[1,1.01,10.51]],"ltp":1.48,"tv":0.01,"id":27652444}]}]}
{"op":"mcm","clk":"1000138579","pt":1580607929797,"mc":[{"id":"1.168119366","rc":[{"batb":[[0,1.01,10.52],[1,1.01,0]],"ltp":3.1,"tv":0.0,"id":23010367},{"batb":[[0,1.01,10.51],[1,1.01,0]],"ltp":1.48,"tv":0.01,"id":27652444}]}]}
{"op":"mcm","clk":"1000138725","pt":1580607933935,"mc":[{"id":"1.168119366","rc":[{"batb":[[0,2.12,425.88],[1,1.01,10.52]],"ltp":3.1,"tv":0.0,"id":23010367},{"batb":[[0,1.31,426.45],[1,1.01,10.51]],"ltp":1.48,"tv":0.01,"id":27652444}]}]}
{"op":"mcm","clk":"1000139679","pt":1580607957919,"mc":[{"id":"1.168119366","rc":[{"batb":[[0,1.01,10.52],[1,1.01,0]],"ltp":3.1,"tv":0.0,"id":23010367},{"batb":[[0,1.01,10.51],[1,1.01,0]],"ltp":1.48,"tv":0.01,"id":27652444}]}]}
{"op":"mcm","clk":"1000139820","pt":1580607962009,"mc":[{"id":"1.168119366","rc":[{"batb":[[0,1.92,435.52],[1,1.01,10.52]],"ltp":3.1,"tv":0.0,"id":23010367},{"batb":[[0,1.4,402.74],[1,1.01,10.51]],"ltp":1.48,"tv":0.01,"id":27652444}]}]}
{"op":"mcm","clk":"1000142869","pt":1580608037155,"mc":[{"id":"1.168119366","rc":[{"batb":[[0,1.01,10.52],[1,1.01,0]],"ltp":3.1,"tv":0.0,"id":23010367},{"batb":[[0,1.01,10.51],[1,1.01,0]],"ltp":1.48,"tv":0.01,"id":27652444}]}]}
{"op":"mcm","clk":"1000142992","pt":1580608040660,"mc":[{"id":"1.168119366","rc":[{"batb":[[0,2.04,432.26],[1,1.01,10.52]],"ltp":3.1,"tv":0.0,"id":23010367},{"batb":[[0,1.34,414.69],[1,1.01,10.51]],"ltp":1.48,"tv":0.01,"id":27652444}]}]}
{"op":"mcm","clk":"1000143237","pt":1580608047127,"mc":[{"id":"1.168119366","rc":[{"batb":[[0,1.01,10.52],[1,1.01,0]],"ltp":3.1,"tv":0.0,"id":23010367},{"batb":[[0,1.01,10.51],[1,1.01,0]],"ltp":1.48,"tv":0.01,"id":27652444}]}]}
{"op":"mcm","clk":"1000143366","pt":1580608050732,"mc":[{"id":"1.168119366","rc":[{"batb":[[0,1.82,442.88],[1,1.01,10.52]],"ltp":3.1,"tv":0.0,"id":23010367},{"batb":[[0,1.46,388.15],[1,1.01,10.51]],"ltp":1.48,"tv":0.01,"id":27652444}]}]}
{"op":"mcm","clk":"1000145056","pt":1580608094327,"mc":[{"id":"1.168119366","rc":[{"batb":[[0,1.01,10.51],[1,1.01,0]],"ltp":1.48,"tv":0.01,"id":27652444}]}]}
{"op":"mcm","clk":"1000145177","pt":1580608098105,"mc":[{"id":"1.168119366","rc":[{"batb":[[0,1.52,379.14],[1,1.01,10.51]],"ltp":1.48,"tv":0.01,"id":27652444}]}]}
{"op":"mcm","clk":"1000146392","pt":1580608133056,"mc":[{"id":"1.168119366","rc":[{"trd":[[1.82,7.8]],"batb":[[0,1.82,438.98]],"ltp":1.82,"tv":7.8,"id":23010367}],"tv":7.81}]}
{"op":"mcm","clk":"1000146922","pt":1580608145470,"mc":[{"id":"1.168119366","rc":[{"batb":[[0,1.01,10.52],[1,1.01,0]],"ltp":1.82,"tv":7.8,"id":23010367},{"batb":[[0,1.01,10.51],[1,1.01,0]],"ltp":1.48,"tv":0.01,"id":27652444}]}]}
{"op":"mcm","clk":"1000147089","pt":1580608149592,"mc":[{"id":"1.168119366","rc":[{"batb":[[0,1.92,431.28],[1,1.01,10.52]],"ltp":1.82,"tv":7.8,"id":23010367},{"batb":[[0,1.4,407.15],[1,1.01,10.51]],"ltp":1.48,"tv":0.01,"id":27652444}]}]}
{"op":"mcm","clk":"1000147667","pt":1580608162484,"mc":[{"id":"1.168119366","rc":[{"batb":[[0,1.01,10.52],[1,1.01,0]],"ltp":1.82,"tv":7.8,"id":23010367},{"batb":[[0,1.01,10.51],[1,1.01,0]],"ltp":1.48,"tv":0.01,"id":27652444}]}]}
{"op":"mcm","clk":"1000147808","pt":1580608166608,"mc":[{"id":"1.168119366","rc":[{"batb":[[0,2.12,422.34],[1,1.01,10.52]],"ltp":1.82,"tv":7.8,"id":23010367},{"batb":[[0,1.31,432.36],[1,1.01,10.51]],"ltp":1.48,"tv":0.01,"id":27652444}]}]}
{"op":"mcm","clk":"1000148818","pt":1580608187512,"mc":[{"id":"1.168119366","rc":[{"batb":[[0,1.01,10.52],[1,1.01,0]],"ltp":1.82,"tv":7.8,"id":23010367},{"batb":[[0,1.01,10.51],[1,1.01,0]],"ltp":1.48,"tv":0.01,"id":27652444}]}]}
{"op":"mcm","clk":"1000149322","pt":1580608198139,"mc":[{"id":"1.168119366","rc":[{"batb":[[0,2.8,402.44],[1,1.01,10.52]],"ltp":1.82,"tv":7.8,"id":23010367},{"batb":[[0,1.14,578.3],[1,1.01,10.51]],"ltp":1.48,"tv":0.01,"id":27652444}]}]}
{"op":"mcm","clk":"1000149914","pt":1580608213547,"mc":[{"id":"1.168119366","rc":[{"batb":[[0,1.01,10.52],[1,1.01,0]],"ltp":1.82,"tv":7.8,"id":23010367},{"batb":[[0,1.01,10.51],[1,1.01,0]],"ltp":1.48,"tv":0.01,"id":27652444}]}]}
{"op":"mcm","clk":"1000150158","pt":1580608219974,"mc":[{"id":"1.168119366","rc":[{"batb":[[0,2.22,416.96],[1,1.01,10.52]],"ltp":1.82,"tv":7.8,"id":23010367},{"batb":[[0,1.28,440.61],[1,1.01,10.51]],"ltp":1.48,"tv":0.01,"id":27652444}]}]}
{"op":"mcm","clk":"1000151128","pt":1580608243695,"mc":[{"id":"1.168119366","rc":[{"batb":[[0,1.01,10.52],[1,1.01,0]],"ltp":1.82,"tv":7.8,"id":23010367},{"batb":[[0,1.01,10.51],[1,1.01,0]],"ltp":1.48,"tv":0.01,"id":27652444}]}]}
{"op":"mcm","clk":"1000151703","pt":1580608259325,"mc":[{"id":"1.168119366","rc":[{"batb":[[0,1.67,448.5],[1,1.01,10.52]],"ltp":1.82,"tv":7.8,"id":23010367},{"batb":[[0,1.58,375.56],[1,1.01,10.51]],"ltp":1.48,"tv":0.01,"id":27652444}]}]}
{"op":"mcm","clk":"1000153353","pt":1580608296786,"mc":[{"id":"1.168119366","rc":[{"batb":[[0,1.01,10.52],[1,1.01,0]],"ltp":1.82,"tv":7.8,"id":23010367},{"batb":[[0,1.01,10.51],[1,1.01,0]],"ltp":1.48,"tv":0.01,"id":27652444}]}]}
{"op":"mcm","clk":"1000153537","pt":1580608300697,"mc":[{"id":"1.168119366","rc":[{"batb":[[0,1.52,466.79],[1,1.01,10.52]],"ltp":1.82,"tv":7.8,"id":23010367},{"batb":[[0,1.74,368.37],[1,1.01,10.51]],"ltp":1.48,"tv":0.01,"id":27652444}]}]}
{"op":"mcm","clk":"1000154659","pt":1580608326017,"mc":[{"id":"1.168119366","rc":[{"batb":[[0,1.01,10.52],[1,1.01,0]],"ltp":1.82,"tv":7.8,"id":23010367},{"batb":[[0,1.01,10.51],[1,1.01,0]],"ltp":1.48,"tv":0.01,"id":27652444}]}]}
{"op":"mcm","clk":"1000154833","pt":1580608329938,"mc":[{"id":"1.168119366","rc":[{"batb":[[0,1.31,522.58],[1,1.01,10.51]],"ltp":1.82,"tv":7.8,"id":23010367},{"batb":[[0,2.12,361.47],[1,1.01,10.51]],"ltp":1.48,"tv":0.01,"id":27652444}]}]}
{"op":"mcm","clk":"1000155613","pt":1580608349456,"mc":[{"id":"1.168119366","rc":[{"batb":[[0,1.01,10.52],[1,1.01,0]],"ltp":1.82,"tv":7.8,"id":23010367},{"batb":[[0,1.01,10.51],[1,1.01,0]],"ltp":1.48,"tv":0.01,"id":27652444}]}]}
{"op":"mcm","clk":"1000155831","pt":1580608355052,"mc":[{"id":"1.168119366","rc":[{"batb":[[0,1.25,550.6],[1,1.01,10.51]],"ltp":1.82,"tv":7.8,"id":23010367},{"batb":[[0,2.3,361.05],[1,1.01,10.51]],"ltp":1.48,"tv":0.01,"id":27652444}]}]}
{"op":"mcm","clk":"1000156035","pt":1580608360938,"mc":[{"id":"1.168119366","rc":[{"batb":[[0,1.01,10.52],[1,1.01,0]],"ltp":1.82,"tv":7.8,"id":23010367},{"batb":[[0,1.01,10.51],[1,1.01,0]],"ltp":1.48,"tv":0.01,"id":27652444}]}]}
{"op":"mcm","clk":"1000156397","pt":1580608370574,"mc":[{"id":"1.168119366","rc":[{"batb":[[0,1.44,478.11],[1,1.01,10.51]],"ltp":1.82,"tv":7.8,"id":23010367},{"batb":[[0,1.86,366.26],[1,1.01,10.51]],"ltp":1.48,"tv":0.01,"id":27652444}]}]}
{"op":"mcm","clk":"1000157212","pt":1580608392020,"mc":[{"id":"1.168119366","rc":[{"batb":[[0,1.01,10.52],[1,1.01,0]],"ltp":1.82,"tv":7.8,"id":23010367},{"batb":[[0,1.01,10.51],[1,1.01,0]],"ltp":1.48,"tv":0.01,"id":27652444}]}]}
{"op":"mcm","clk":"1000157441","pt":1580608397314,"mc":[{"id":"1.168119366","rc":[{"batb":[[0,1.34,509.24],[1,1.01,10.51]],"ltp":1.82,"tv":7.8,"id":23010367},{"batb":[[0,2.04,365.75],[1,1.01,10.51]],"ltp":1.48,"tv":0.01,"id":27652444}]}]}
{"op":"mcm","clk":"1000157698","pt":1580608403022,"mc":[{"id":"1.168119366","rc":[{"batb":[[0,1.01,10.52],[1,1.01,0]],"ltp":1.82,"tv":7.8,"id":23010367},{"batb":[[0,1.01,10.51],[1,1.01,0]],"ltp":1.48,"tv":0.01,"id":27652444}]}]}
{"op":"mcm","clk":"1000158044","pt":1580608412550,"mc":[{"id":"1.168119366","rc":[{"batb":[[0,1.58,456.37],[1,1.01,10.52]],"ltp":1.82,"tv":7.8,"id":23010367},{"batb":[[0,1.67,371.95],[1,1.01,10.51]],"ltp":1.48,"tv":0.01,"id":27652444}]}]}
{"op":"mcm","clk":"1000159165","pt":1580608443515,"mc":[{"id":"1.168119366","rc":[{"batb":[[0,1.01,10.52],[1,1.01,0]],"ltp":1.82,"tv":7.8,"id":23010367},{"batb":[[0,1.01,10.51],[1,1.01,0]],"ltp":1.48,"tv":0.01,"id":27652444}]}]}
{"op":"mcm","clk":"1000159352","pt":1580608447693,"mc":[{"id":"1.168119366","rc":[{"batb":[[0,1.77,439.85],[1,1.01,10.52]],"ltp":1.82,"tv":7.8,"id":23010367},{"batb":[[0,1.5,384.98],[1,1.01,10.51]],"ltp":1.48,"tv":0.01,"id":27652444}]}]}
{"op":"mcm","clk":"1000160216","pt":1580608468217,"mc":[{"id":"1.168119366","rc":[{"batb":[[0,1.01,10.51],[1,1.01,0]],"ltp":1.48,"tv":0.01,"id":27652444}]}]}
{"op":"mcm","clk":"1000160349","pt":1580608471929,"mc":[{"id":"1.168119366","rc":[{"batb":[[0,1.58,375.56],[1,1.01,10.51]],"ltp":1.48,"tv":0.01,"id":27652444}]}]}
{"op":"mcm","clk":"1000161086","pt":1580608491259,"mc":[{"id":"1.168119366","rc":[{"batb":[[0,1.01,10.52],[1,1.01,0]],"ltp":1.82,"tv":7.8,"id":23010367},{"batb":[[0,1.01,10.51],[1,1.01,0]],"ltp":1.48,"tv":0.01,"id":27652444}]}]}
{"op":"mcm","clk":"1000161222","pt":1580608495169,"mc":[{"id":"1.168119366","rc":[{"batb":[[0,1.92,430.58],[1,1.01,10.52]],"ltp":1.82,"tv":7.8,"id":23010367},{"batb":[[0,1.4,406.87],[1,1.01,10.51]],"ltp":1.48,"tv":0.01,"id":27652444}]}]}
{"op":"mcm","clk":"1000165249","pt":1580608590584,"mc":[{"id":"1.168119366","rc":[{"batb":[[0,1.01,10.52],[1,1.01,0]],"ltp":1.82,"tv":7.8,"id":23010367},{"batb":[[0,1.01,10.51],[1,1.01,0]],"ltp":1.48,"tv":0.01,"id":27652444}]}]}
{"op":"mcm","clk":"1000165402","pt":1580608594383,"mc":[{"id":"1.168119366","rc":[{"batb":[[0,2.04,451.13],[1,1.01,10.52]],"ltp":1.82,"tv":7.8,"id":23010367},{"batb":[[0,1.34,390.38],[1,1.01,10.51]],"ltp":1.48,"tv":0.01,"id":27652444}]}]}
{"op":"mcm","clk":"1000165679","pt":1580608602383,"mc":[{"id":"1.168119366","rc":[{"batb":[[0,1.01,10.52],[1,1.01,0]],"ltp":1.82,"tv":7.8,"id":23010367},{"batb":[[0,1.01,10.51],[1,1.01,0]],"ltp":1.48,"tv":0.01,"id":27652444}]}]}
{"op":"mcm","clk":"1000165838","pt":1580608606484,"mc":[{"id":"1.168119366","rc":[{"batb":[[0,2.3,437.07],[1,1.01,10.52]],"ltp":1.82,"tv":7.8,"id":23010367},{"batb":[[0,1.25,426.97],[1,1.01,10.51]],"ltp":1.48,"tv":0.01,"id":27652444}]}]}
{"op":"mcm","clk":"1000167096","pt":1580608639547,"mc":[{"id":"1.168119366","rc":[{"batb":[[0,1.01,10.52],[1,1.01,0]],"ltp":1.82,"tv":7.8,"id":23010367},{"batb":[[0,1.01,10.51],[1,1.01,0]],"ltp":1.48,"tv":0.01,"id":27652444}]}]}
{"op":"mcm","clk":"1000167253","pt":1580608643536,"mc":[{"id":"1.168119366","rc":[{"batb":[[0,1.97,452.47],[1,1.01,10.52]],"ltp":1.82,"tv":7.8,"id":23010367},{"batb":[[0,1.38,374.65],[1,1.01,10.51]],"ltp":1.48,"tv":0.01,"id":27652444}]}]}
{"op":"mcm","clk":"1000167963","pt":1580608665570,"mc":[{"id":"1.168119366","rc":[{"batb":[[0,1.01,10.51],[1,1.01,0]],"ltp":1.48,"tv":0.01,"id":27652444}]}]}
{"op":"mcm","clk":"1000168102","pt":1580608669579,"mc":[{"id":"1.168119366","rc":[{"batb":[[0,1.46,364.08],[1,1.01,10.51]],"ltp":1.48,"tv":0.01,"id":27652444}]}]}
{"op":"mcm","clk":"1000168890","pt":1580608690609,"mc":[{"id":"1.168119366","rc":[{"batb":[[0,1.01,10.52],[1,1.01,0]],"ltp":1.82,"tv":7.8,"id":23010367},{"batb":[[0,1.01,10.51],[1,1.01,0]],"ltp":1.48,"tv":0.01,"id":27652444}]}]}
{"op":"mcm","clk":"1000169039","pt":1580608694718,"mc":[{"id":"1.168119366","rc":[{"batb":[[0,1.7,473.75],[1,1.01,10.52]],"ltp":1.82,"tv":7.8,"id":23010367},{"batb":[[0,1.55,352.15],[1,1.01,10.51]],"ltp":1.48,"tv":0.01,"id":27652444}]}]}
{"op":"mcm","clk":"1000170218","pt":1580608726650,"mc":[{"id":"1.168119366","rc":[{"batb":[[0,1.01,10.52],[1,1.01,0]],"ltp":1.82,"tv":7.8,"id":23010367},{"batb":[[0,1.01,10.51],[1,1.01,0]],"ltp":1.48,"tv":0.01,"id":27652444}]}]}
{"op":"mcm","clk":"1000170380","pt":1580608730956,"mc":[{"id":"1.168119366","rc":[{"batb":[[0,1.82,462.42],[1,1.01,10.52]],"ltp":1.82,"tv":7.8,"id":23010367},{"batb":[[0,1.46,364.08],[1,1.01,10.51]],"ltp":1.48,"tv":0.01,"id":27652444}]}]}
{"op":"mcm","clk":"1000171441","pt":1580608762720,"mc":[{"id":"1.168119366","rc":[{"batb":[[0,1.01,10.52],[1,1.01,0]],"ltp":1.82,"tv":7.8,"id":23010367},{"batb":[[0,1.01,10.51],[1,1.01,0]],"ltp":1.48,"tv":0.01,"id":27652444}]}]}
{"op":"mcm","clk":"1000171547","pt":1580608766103,"mc":[{"id":"1.168119366","rc":[{"batb":[[0,1.67,474.16],[1,1.01,10.52]],"ltp":1.82,"tv":7.8,"id":23010367},{"batb":[[0,1.58,348.47],[1,1.01,10.51]],"ltp":1.48,"tv":0.01,"id":27652444}]}]}
{"op":"mcm","clk":"1000172410","pt":1580608793867,"mc":[{"id":"1.168119366","rc":[{"batb":[[0,1.01,10.51],[1,1.01,0]],"ltp":1.48,"tv":0.01,"id":27652444}]}]}
{"op":"mcm","clk":"1000172552","pt":1580608798133,"mc":[{"id":"1.168119366","rc":[{"batb":[[0,1.67,346.83],[1,1.01,10.51]],"ltp":1.48,"tv":0.01,"id":27652444}]}]}
{"op":"mcm","clk":"1000172808","pt":1580608803467,"mc":[{"id":"1.168119366","rc":[{"batl":[[0,1000,3.04]],"ltp":1.82,"tv":7.8,"id":23010367}]}]}
{"op":"mcm","clk":"1000172911","pt":1580608805857,"mc":[{"id":"1.168119366","rc":[{"batb":[[0,1.01,10.52],[1,1.01,0]],"ltp":1.82,"tv":7.8,"id":23010367},{"batb":[[0,1.01,10.51],[1,1.01,0]],"ltp":1.48,"tv":0.01,"id":27652444}]}]}
{"op":"mcm","clk":"1000172982","pt":1580608807247,"mc":[{"id":"1.168119366","rc":[{"batl":[[0,1.67,0.02]],"ltp":1.82,"tv":7.8,"id":23010367}]}]}
{"op":"mcm","clk":"1000173080","pt":1580608809260,"mc":[{"id":"1.168119366","rc":[{"batb":[[0,1.38,519.51],[1,1.01,10.51]],"ltp":1.82,"tv":7.8,"id":23010367},{"batb":[[0,1.97,345.22],[1,1.01,10.51]],"ltp":1.48,"tv":0.01,"id":27652444}]}]}
{"op":"mcm","clk":"1000174198","pt":1580608835872,"mc":[{"id":"1.168119366","rc":[{"batb":[[0,1.01,10.52],[1,1.01,0]],"ltp":1.82,"tv":7.8,"id":23010367},{"batb":[[0,1.01,10.51],[1,1.01,0]],"ltp":1.48,"tv":0.01,"id":27652444}]}]}
{"op":"mcm","clk":"1000174340","pt":1580608839486,"mc":[{"id":"1.168119366","rc":[{"trd":[[1.67,0.03]],"ltp":1.67,"tv":7.83,"id":23010367},{"batb":[[0,1.58,348.47],[1,1.01,10.51]],"ltp":1.48,"tv":0.01,"id":27652444}],"tv":7.84}]}
{"op":"mcm","clk":"1000174759","pt":1580608850597,"mc":[{"id":"1.168119366","rc":[{"batb":[[0,1.01,10.53]],"ltp":1.67,"tv":7.83,"id":23010367}]}]}
{"op":"mcm","clk":"1000175691","pt":1580608873945,"mc":[{"id":"1.168119366","rc":[{"batb":[[0,1.01,10.51],[1,1.01,0]],"ltp":1.48,"tv":0.01,"id":27652444}]}]}
{"op":"mcm","clk":"1000176030","pt":1580608882372,"mc":[{"id":"1.168119366","rc":[{"batb":[[0,1.74,467.95],[1,1.01,10.53]],"ltp":1.67,"tv":7.83,"id":23010367},{"batb":[[0,1.52,356.72],[1,1.01,10.51]],"ltp":1.48,"tv":0.01,"id":27652444}]}]}
{"op":"mcm","clk":"1000176399","pt":1580608890949,"mc":[{"id":"1.168119366","rc":[{"batb":[[0,1.01,10.53],[1,1.01,0]],"ltp":1.67,"tv":7.83,"id":23010367},{"batb":[[0,1.01,10.51],[1,1.01,0]],"ltp":1.48,"tv":0.01,"id":27652444}]}]}
{"op":"mcm","clk":"1000176792","pt":1580608899386,"mc":[{"id":"1.168119366","rc":[{"batb":[[0,1.46,506.14],[1,1.01,10.51]],"ltp":1.67,"tv":7.83,"id":23010367},{"batb":[[0,1.82,345.12],[1,1.01,10.51]],"ltp":1.48,"tv":0.01,"id":27652444}]}]}
{"op":"mcm","clk":"1000177666","pt":1580608922006,"mc":[{"id":"1.168119366","rc":[{"batb":[[0,1.01,10.53],[1,1.01,0]],"ltp":1.67,"tv":7.83,"id":23010367},{"batb":[[0,1.01,10.51],[1,1.01,0]],"ltp":1.48,"tv":0.01,"id":27652444}]}]}
{"op":"mcm","clk":"1000178783","pt":1580608952636,"mc":[{"id":"1.168119366","rc":[{"batb":[[0,1.22,600.39],[1,1.01,10.51]],"ltp":1.67,"tv":7.83,"id":23010367},{"batb":[[0,2.42,343.81],[1,1.01,10.51]],"ltp":1.48,"tv":0.01,"id":27652444}]}]}
{"op":"mcm","clk":"1000179534","pt":1580608973145,"mc":[{"id":"1.168119366","rc":[{"batb":[[0,1.01,10.53],[1,1.01,0]],"ltp":1.67,"tv":7.83,"id":23010367},{"batb":[[0,1.01,10.51],[1,1.01,0]],"ltp":1.48,"tv":0.01,"id":27652444}]}]}
{"op":"mcm","clk":"1000179785","pt":1580608979974,"mc":[{"id":"1.168119366","rc":[{"trd":[[1.67,0.05]],"batb":[[0,1.18,626.2],[1,1.01,10.51]],"ltp":1.67,"tv":7.85,"id":23010367},{"trd":[[2.5,0.01]],"ltp":2.5,"tv":0.01,"id":27652444}],"tv":7.86}]}
{"op":"mcm","clk":"1000179901","pt":1580608983160,"mc":[{"id":"1.168119366","rc":[{"batb":[[0,1.01,10.52],[1,1.01,0]],"ltp":1.67,"tv":7.85,"id":23010367}]}]}
{"op":"mcm","clk":"1000180193","pt":1580608990596,"mc":[{"id":"1.168119366","rc":[{"batb":[[0,1.31,552.83],[1,1.01,10.51]],"ltp":1.67,"tv":7.85,"id":23010367},{"batb":[[0,2.12,343.22],[1,1.01,10.51]],"ltp":2.5,"tv":0.01,"id":27652444}]}]}
{"op":"mcm","clk":"1000181292","pt":1580609021238,"mc":[{"id":"1.168119366","rc":[{"batb":[[0,1.01,10.52],[1,1.01,0]],"ltp":1.67,"tv":7.85,"id":23010367},{"batb":[[0,1.01,10.51],[1,1.01,0]],"ltp":2.5,"tv":0.01,"id":27652444}]}]}
{"op":"mcm","clk":"1000181975","pt":1580609037079,"mc":[{"id":"1.168119366","rc":[{"batb":[[0,1.18,626.22],[1,1.01,10.51]],"ltp":1.67,"tv":7.85,"id":23010367},{"batb":[[0,2.62,345.15],[1,1.01,10.51]],"ltp":2.5,"tv":0.01,"id":27652444}]}]}
{"op":"mcm","clk":"1000184682","pt":1580609105463,"mc":[{"id":"1.168119366","rc":[{"batb":[[0,1.01,10.52],[1,1.01,0]],"ltp":1.67,"tv":7.85,"id":23010367},{"batb":[[0,1.01,10.51],[1,1.01,0]],"ltp":2.5,"tv":0.01,"id":27652444}]}]}
{"op":"mcm","clk":"1000184973","pt":1580609111072,"mc":[{"id":"1.168119366","rc":[{"batb":[[0,1.22,600.4],[1,1.01,10.51]],"ltp":1.67,"tv":7.85,"id":23010367},{"batb":[[0,2.42,343.8],[1,1.01,10.51]],"ltp":2.5,"tv":0.01,"id":27652444}]}]}
{"op":"mcm","clk":"1000185110","pt":1580609114469,"mc":[{"id":"1.168119366","rc":[{"batb":[[0,1.01,10.52],[1,1.01,0]],"ltp":1.67,"tv":7.85,"id":23010367},{"batb":[[0,1.01,10.51],[1,1.01,0]],"ltp":2.5,"tv":0.01,"id":27652444}]}]}
{"op":"mcm","clk":"1000185722","pt":1580609131198,"mc":[{"id":"1.168119366","rc":[{"batb":[[0,1.4,523.51],[1,1.01,10.51]],"ltp":1.67,"tv":7.85,"id":23010367},{"batb":[[0,1.92,343.02],[1,1.01,10.51]],"ltp":2.5,"tv":0.01,"id":27652444}]}]}
{"op":"mcm","clk":"1000186463","pt":1580609152518,"mc":[{"id":"1.168119366","rc":[{"batb":[[0,1.01,10.52],[1,1.01,0]],"ltp":1.67,"tv":7.85,"id":23010367},{"batb":[[0,1.01,10.51],[1,1.01,0]],"ltp":2.5,"tv":0.01,"id":27652444}]}]}
{"op":"mcm","clk":"1000186657","pt":1580609159313,"mc":[{"id":"1.168119366","rc":[{"batb":[[0,1.34,538.65],[1,1.01,10.51]],"ltp":1.67,"tv":7.85,"id":23010367},{"batb":[[0,2.04,346.71],[1,1.01,10.51]],"ltp":2.5,"tv":0.01,"id":27652444}]}]}
{"op":"mcm","clk":"1000186752","pt":1580609162541,"mc":[{"id":"1.168119366","rc":[{"batb":[[0,1.01,10.52],[1,1.01,0]],"ltp":1.67,"tv":7.85,"id":23010367},{"batb":[[0,1.01,10.51],[1,1.01,0]],"ltp":2.5,"tv":0.01,"id":27652444}]}]}
{"op":"mcm","clk":"1000186962","pt":1580609169228,"mc":[{"id":"1.168119366","rc":[{"batb":[[0,1.67,474.18],[1,1.01,10.52]],"ltp":1.67,"tv":7.85,"id":23010367},{"batb":[[0,1.58,348.48],[1,1.01,10.51]],"ltp":2.5,"tv":0.01,"id":27652444}]}]}
{"op":"mcm","clk":"1000187593","pt":1580609187559,"mc":[{"id":"1.168119366","rc":[{"batb":[[0,1.01,10.52],[1,1.01,0]],"ltp":1.67,"tv":7.85,"id":23010367},{"batb":[[0,1.01,10.51],[1,1.01,0]],"ltp":2.5,"tv":0.01,"id":27652444}]}]}
{"op":"mcm","clk":"1000187959","pt":1580609199305,"mc":[{"id":"1.168119366","rc":[{"batb":[[0,2.04,451.14],[1,1.01,10.52]],"ltp":1.67,"tv":7.85,"id":23010367},{"batb":[[0,1.34,390.39],[1,1.01,10.51]],"ltp":2.5,"tv":0.01,"id":27652444}]}]}
{"op":"mcm","clk":"1000188553","pt":1580609220606,"mc":[{"id":"1.168119366","rc":[{"batb":[[0,1.01,10.52],[1,1.01,0]],"ltp":1.67,"tv":7.85,"id":23010367},{"batb":[[0,1.01,10.51],[1,1.01,0]],"ltp":2.5,"tv":0.01,"id":27652444}]}]}
{"op":"mcm","clk":"1000189273","pt":1580609242660,"mc":[{"id":"1.168119366","rc":[{"batb":[[0,3.5,408.26],[1,1.01,10.52]],"ltp":1.67,"tv":7.85,"id":23010367},{"batb":[[0,1.06,871.45],[1,1.01,10.51]],"ltp":2.5,"tv":0.01,"id":27652444}]}]}
{"op":"mcm","clk":"1000189882","pt":1580609256639,"mc":[{"id":"1.168119366","rc":[{"batb":[[0,1.01,10.52],[1,1.01,0]],"ltp":1.67,"tv":7.85,"id":23010367},{"batb":[[0,1.01,10.51],[1,1.01,0]],"ltp":2.5,"tv":0.01,"id":27652444}]}]}
{"op":"mcm","clk":"1000190254","pt":1580609263443,"mc":[{"id":"1.168119366","rc":[{"batb":[[0,3.7,410.28],[1,1.01,10.52]],"ltp":1.67,"tv":7.85,"id":23010367},{"batb":[[0,1.04,1175.96],[1,1.01,10.51]],"ltp":2.5,"tv":0.01,"id":27652444}]}]}
{"op":"mcm","clk":"1000190398","pt":1580609265771,"mc":[{"id":"1.168119366","rc":[{"batb":[[0,1.01,10.52],[1,1.01,0]],"ltp":1.67,"tv":7.85,"id":23010367},{"batb":[[0,1.01,10.51],[1,1.01,0]],"ltp":2.5,"tv":0.01,"id":27652444}]}]}
{"op":"mcm","clk":"1000190758","pt":1580609274454,"mc":[{"id":"1.168119366","rc":[{"batb":[[0,2.9,419.69],[1,1.01,10.52]],"ltp":1.67,"tv":7.85,"id":23010367},{"batb":[[0,1.13,551.01],[1,1.01,10.51]],"ltp":2.5,"tv":0.01,"id":27652444}]}]}
{"op":"mcm","clk":"1000191774","pt":1580609298718,"mc":[{"id":"1.168119366","rc":[{"batb":[[0,1.01,10.52],[1,1.01,0]],"ltp":1.67,"tv":7.85,"id":23010367},{"batb":[[0,1.01,10.51],[1,1.01,0]],"ltp":2.5,"tv":0.01,"id":27652444}]}]}
{"op":"mcm","clk":"1000192057","pt":1580609305213,"mc":[{"id":"1.168119366","marketDefinition":{"bspMarket":false,"turnInPlayEnabled":true,"persistenceEnabled":true,"marketBaseRate":5.0,"eventId":"29678414","eventTypeId":"2","numberOfWinners":1,"bettingType":"ODDS","marketType":"SET_WINNER","marketTime":"2020-02-02T00:54:00.000Z","suspendTime":"2020-02-02T00:54:00.000Z","bspReconciled":false,"complete":true,"inPlay":true,"crossMatching":true,"runnersVoidable":false,"numberOfActiveRunners":2,"betDelay":3,"status":"SUSPENDED","runners":[{"status":"ACTIVE","sortPriority":1,"id":23010367,"name":"Margaroli/Vavassori"},{"status":"ACTIVE","sortPriority":2,"id":27652444,"name":"Heliovaara/Verbeek"}],"regulators":["MR_INT"],"countryCode":"AU","discountAllowed":true,"timezone":"UTC","openDate":"2020-02-02T00:54:00.000Z","version":3148036768,"name":"Set 1 Winner","eventName":"Margaroli/Vavassori v Heliovaara/Verbeek"}}]}
{"op":"mcm","clk":"1000193363","pt":1580609337234,"mc":[{"id":"1.168119366","tv":0.0}]}
{"op":"mcm","clk":"1000193384","pt":1580609338291,"mc":[{"id":"1.168119366","marketDefinition":{"bspMarket":false,"turnInPlayEnabled":true,"persistenceEnabled":true,"marketBaseRate":5.0,"eventId":"29678414","eventTypeId":"2","numberOfWinners":1,"bettingType":"ODDS","marketType":"SET_WINNER","marketTime":"2020-02-02T00:54:00.000Z","suspendTime":"2020-02-02T00:54:00.000Z","bspReconciled":false,"complete":true,"inPlay":true,"crossMatching":false,"runnersVoidable":false,"numberOfActiveRunners":0,"betDelay":3,"status":"CLOSED","settledTime":"2020-02-02T02:08:56.000Z","runners":[{"status":"LOSER","sortPriority":1,"id":23010367,"name":"Margaroli/Vavassori"},{"status":"WINNER","sortPriority":2,"id":27652444,"name":"Heliovaara/Verbeek"}],"regulators":["MR_INT"],"countryCode":"AU","discountAllowed":true,"timezone":"UTC","openDate":"2020-02-02T00:54:00.000Z","version":3148036828,"name":"Set 1 Winner","eventName":"Margaroli/Vavassori v Heliovaara/Verbeek"}}]}
