{"op":"mcm","clk":"995732875","pt":1580515645283,"mc":[{"id":"1.168175448","marketDefinition":{"bspMarket":false,"turnInPlayEnabled":true,"persistenceEnabled":true,"marketBaseRate":5.0,"eventId":"29680072","eventTypeId":"2","numberOfWinners":1,"bettingType":"ODDS","marketType":"MATCH_ODDS","marketTime":"2020-02-02T13:00:00.000Z","suspendTime":"2020-02-02T13:00:00.000Z","bspReconciled":false,"complete":true,"inPlay":false,"crossMatching":false,"runnersVoidable":false,"numberOfActiveRunners":2,"betDelay":0,"status":"OPEN","runners":[{"status":"ACTIVE","sortPriority":1,"id":6374165,"name":"Marco Cecchinato"},{"status":"ACTIVE","sortPriority":2,"id":5071877,"name":"Andrej Martin"}],"regulators":["MR_INT"],"countryCode":"UY","discountAllowed":false,"timezone":"UTC","openDate":"2020-02-02T13:00:00.000Z","version":3144186618,"name":"Match Odds","eventName":"Cecchinato v Martin"},"rc":[{"batb":[[0,1.05,152.2],[1,1.04,168.86],[2,1.03,237.77]],"ltp":0.0,"tv":0.0,"id":5071877},{"batb":[[0,1.05,152.2],[1,1.04,168.86],[2,1.03,237.77]],"ltp":0.0,"tv":0.0,"id":6374165}]}]}
{"op":"mcm","clk":"995733031","pt":1580515646599,"mc":[{"id":"1.168175448","marketDefinition":{"bspMarket":false,"turnInPlayEnabled":true,"persistenceEnabled":true,"marketBaseRate":5.0,"eventId":"29680072","eventTypeId":"2","numberOfWinners":1,"bettingType":"ODDS","marketType":"MATCH_ODDS","marketTime":"2020-02-02T13:00:00.000Z","suspendTime":"2020-02-02T13:00:00.000Z","bspReconciled":false,"complete":true,"inPlay":false,"crossMatching":false,"runnersVoidable":false,"numberOfActiveRunners":2,"betDelay":0,"status":"OPEN","runners":[{"status":"ACTIVE","sortPriority":1,"id":6374165,"name":"Marco Cecchinato"},{"status":"ACTIVE","sortPriority":2,"id":5071877,"name":"Andrej Martin"}],"regulators":["MR_INT"],"countryCode":"UY","discountAllowed":false,"timezone":"UTC","openDate":"2020-02-02T13:00:00.000Z","version":3144186618,"name":"Match Odds","eventName":"Cecchinato v Martin"}}]}
{"op":"mcm","clk":"995733303","pt":1580515649573,"mc":[{"id":"1.168175448","marketDefinition":{"bspMarket":false,"turnInPlayEnabled":true,"persistenceEnabled":true,"marketBaseRate":5.0,"eventId":"29680072","eventTypeId":"2","numberOfWinners":1,"bettingType":"ODDS","marketType":"MATCH_ODDS","marketTime":"2020-02-02T13:00:00.000Z","suspendTime":"2020-02-02T13:00:00.000Z","bspReconciled":false,"complete":true,"inPlay":false,"crossMatching":false,"runnersVoidable":false,"numberOfActiveRunners":2,"betDelay":0,"status":"OPEN","runners":[{"status":"ACTIVE","sortPriority":1,"id":6374165,"name":"Marco Cecchinato"},{"status":"ACTIVE","sortPriority":2,"id":5071877,"name":"Andrej Martin"}],"regulators":["MR_INT"],"countryCode":"UY","discountAllowed":true,"timezone":"UTC","openDate":"2020-02-02T13:00:00.000Z","version":3144186618,"name":"Match Odds","eventName":"Cecchinato v Martin"}}]}
{"op":"mcm","clk":"995740939","pt":1580515737797,"mc":[{"id":"1.168175448","marketDefinition":{"bspMarket":false,"turnInPlayEnabled":true,"persistenceEnabled":true,"marketBaseRate":5.0,"eventId":"29680072","eventTypeId":"2","numberOfWinners":1,"bettingType":"ODDS","marketType":"MATCH_ODDS","marketTime":"2020-02-02T13:00:00.000Z","suspendTime":"2020-02-02T13:00:00.000Z","bspReconciled":false,"complete":true,"inPlay":false,"crossMatching":true,"runnersVoidable":false,"numberOfActiveRunners":2,"betDelay":0,"status":"OPEN","runners":[{"status":"ACTIVE","sortPriority":1,"id":6374165,"name":"Marco Cecchinato"},{"status":"ACTIVE","sortPriority":2,"id":5071877,"name":"Andrej Martin"}],"regulators":["MR_INT"],"countryCode":"UY","discountAllowed":true,"timezone":"UTC","openDate":"2020-02-02T13:00:00.000Z","version":3144186618,"name":"Match Odds","eventName":"Cecchinato v Martin"}}]}
{"op":"mcm","clk":"995757865","pt":1580515942552,"mc":[{"id":"1.168175448","rc":[{"batl":[[0,990,2.2]],"ltp":0.0,"tv":0.0,"id":5071877},{"batl":[[0,990,2.2]],"ltp":0.0,"tv":0.0,"id":6374165}]}]}
{"op":"mcm","clk":"995805814","pt":1580516412279,"mc":[{"id":"1.168175448","rc":[{"batb":[[0,1.06,50.48],[1,1.05,152.2],[2,1.04,168.86]],"ltp":0.0,"tv":0.0,"id":5071877},{"batb":[[0,1.06,50.48],[1,1.05,152.2],[2,1.04,168.86]],"ltp":0.0,"tv":0.0,"id":6374165}]}]}
{"op":"mcm","clk":"995889896","pt":1580517337345,"mc":[{"id":"1.168175448","marketDefinition":{"bspMarket":false,"turnInPlayEnabled":true,"persistenceEnabled":true,"marketBaseRate":5.0,"eventId":"29680072","eventTypeId":"2","numberOfWinners":1,"bettingType":"ODDS","marketType":"MATCH_ODDS","marketTime":"2020-02-01T22:00:00.000Z","suspendTime":"2020-02-01T22:00:00.000Z","bspReconciled":false,"complete":true,"inPlay":false,"crossMatching":true,"runnersVoidable":false,"numberOfActiveRunners":2,"betDelay":0,"status":"OPEN","runners":[{"status":"ACTIVE","sortPriority":1,"id":6374165,"name":"Marco Cecchinato"},{"status":"ACTIVE","sortPriority":2,"id":5071877,"name":"Andrej Martin"}],"regulators":["MR_INT"],"countryCode":"UY","discountAllowed":true,"timezone":"UTC","openDate":"2020-02-02T13:00:00.000Z","version":3144220321,"name":"Match Odds","eventName":"Cecchinato v Martin"}}]}
{"op":"mcm","clk":"995890182","pt":1580517341374,"mc":[{"id":"1.168175448","marketDefinition":{"bspMarket":false,"turnInPlayEnabled":true,"persistenceEnabled":true,"marketBaseRate":5.0,"eventId":"29680072","eventTypeId":"2","numberOfWinners":1,"bettingType":"ODDS","marketType":"MATCH_ODDS","marketTime":"2020-02-01T22:00:00.000Z","suspendTime":"2020-02-01T22:00:00.000Z","bspReconciled":false,"complete":true,"inPlay":false,"crossMatching":true,"runnersVoidable":false,"numberOfActiveRunners":2,"betDelay":0,"status":"OPEN","runners":[{"status":"ACTIVE","sortPriority":1,"id":6374165,"name":"Marco Cecchinato"},{"status":"ACTIVE","sortPriority":2,"id":5071877,"name":"Andrej Martin"}],"regulators":["MR_INT"],"countryCode":"UY","discountAllowed":true,"timezone":"UTC","openDate":"2020-02-01T22:00:00.000Z","version":3144220321,"name":"Match Odds","eventName":"Cecchinato v Martin"}}]}
{"op":"mcm","clk":"995909178","pt":1580517588813,"mc":[{"id":"1.168175448","rc":[{"batb":[[0,1.38,3565.79],[1,1.06,50.48],[2,1.05,152.2]],"ltp":0.0,"tv":0.0,"id":5071877}]}]}
{"op":"mcm","clk":"995909443","pt":1580517592222,"mc":[{"id":"1.168175448","rc":[{"batb":[[0,1.4,3565.79]],"ltp":0.0,"tv":0.0,"id":5071877}]}]}
{"op":"mcm","clk":"995909648","pt":1580517594815,"mc":[{"id":"1.168175448","rc":[{"batb":[[0,1.41,8.4],[1,1.4,3565.79],[2,1.06,50.48]],"ltp":0.0,"tv":0.0,"id":5071877}]}]}
{"op":"mcm","clk":"995910160","pt":1580517601220,"mc":[{"id":"1.168175448","rc":[{"batb":[[0,1.18,4546.29],[1,1.06,50.48],[2,1.05,152.2]],"ltp":0.0,"tv":0.0,"id":6374165}]}]}
{"op":"mcm","clk":"995910754","pt":1580517608051,"mc":[{"id":"1.168175448","rc":[{"batb":[[0,1.2,4546.29]],"ltp":0.0,"tv":0.0,"id":6374165}]}]}
{"op":"mcm","clk":"995911401","pt":1580517616273,"mc":[{"id":"1.168175448","rc":[{"batb":[[0,1.21,8.4],[1,1.2,4546.29],[2,1.06,50.48]],"ltp":0.0,"tv":0.0,"id":6374165}]}]}
{"op":"mcm","clk":"995911757","pt":1580517620656,"mc":[{"id":"1.168175448","rc":[{"batb":[[0,1.19,8.4],[1,1.18,4546.29]],"ltp":0.0,"tv":0.0,"id":6374165}]}]}
{"op":"mcm","clk":"995943478","pt":1580517873178,"mc":[{"id":"1.168175448","rc":[{"batl":[[0,3,42.01],[1,990,2.2]],"ltp":0.0,"tv":0.0,"id":6374165}]}]}
{"op":"mcm","clk":"995944711","pt":1580517886207,"mc":[{"id":"1.168175448","rc":[{"batb":[[0,1.5,84.02],[1,1.22,22.84],[2,1.19,8.4]],"ltp":0.0,"tv":0.0,"id":6374165}]}]}
{"op":"mcm","clk":"995954131","pt":1580518004207,"mc":[{"id":"1.168175448","rc":[{"batb":[[0,1.51,907.41],[1,1.41,8.4],[2,1.4,3565.79]],"ltp":0.0,"tv":0.0,"id":5071877}]}]}
{"op":"mcm","clk":"996030636","pt":1580518903376,"mc":[{"id":"1.168175448","rc":[{"batb":[[0,1.52,7.19],[1,1.51,907.41],[2,1.41,8.4]],"ltp":0.0,"tv":0.0,"id":5071877}]}]}
{"op":"mcm","clk":"996030652","pt":1580518903583,"mc":[{"id":"1.168175448","rc":[{"batb":[[1,1.19,8.4],[2,1.18,4546.29]],"ltp":0.0,"tv":0.0,"id":6374165}]}]}
{"op":"mcm","clk":"996953300","pt":1580532595081,"mc":[{"id":"1.168175448","rc":[{"batl":[[0,2.98,3.43],[1,990,2.2]],"ltp":0.0,"tv":0.0,"id":5071877}]}]}
{"op":"mcm","clk":"997115577","pt":1580535230378,"mc":[{"id":"1.168175448","rc":[{"batb":[[0,1.53,75.72],[1,1.52,7.19],[2,1.51,907.41]],"ltp":0.0,"tv":0.0,"id":5071877}]}]}
{"op":"mcm","clk":"997116171","pt":1580535248785,"mc":[{"id":"1.168175448","rc":[{"batb":[[1,1.19,190.14]],"ltp":0.0,"tv":0.0,"id":6374165}]}]}
{"op":"mcm","clk":"997118022","pt":1580535304499,"mc":[{"id":"1.168175448","rc":[{"batl":[[2,1000,0.02]],"ltp":0.0,"tv":0.0,"id":5071877},{"batb":[[1,1.19,190.24]],"batl":[[2,1000,0.02]],"ltp":0.0,"tv":0.0,"id":6374165}]}]}
{"op":"mcm","clk":"997118336","pt":1580535312507,"mc":[{"id":"1.168175448","rc":[{"batb":[[0,2.7,16.1],[1,1.56,69.33],[2,1.53,75.72]],"ltp":0.0,"tv":0.0,"id":5071877},{"batb":[[1,1.4,68.45],[2,1.19,190.24]],"ltp":0.0,"tv":0.0,"id":6374165}]}]}
{"op":"mcm","clk":"997118355","pt":1580535313027,"mc":[{"id":"1.168175448","rc":[{"batb":[[1,1.56,5.83]],"ltp":0.0,"tv":0.0,"id":5071877}]}]}
{"op":"mcm","clk":"997120533","pt":1580535376131,"mc":[{"id":"1.168175448","rc":[{"batb":[[1,1.57,75.72],[2,1.52,7.19]],"ltp":0.0,"tv":0.0,"id":5071877}]}]}
{"op":"mcm","clk":"997122195","pt":1580535422204,"mc":[{"id":"1.168175448","rc":[{"batb":[[0,2.8,15.21]],"ltp":0.0,"tv":0.0,"id":5071877},{"batb":[[1,1.36,76.05]],"ltp":0.0,"tv":0.0,"id":6374165}]}]}
{"op":"mcm","clk":"997128566","pt":1580535584364,"mc":[{"id":"1.168175448","rc":[{"batb":[[2,1.3,4]],"ltp":0.0,"tv":0.0,"id":6374165}]}]}
{"op":"mcm","clk":"997156613","pt":1580536032625,"mc":[{"id":"1.168175448","rc":[{"batb":[[0,2.82,20.14],[1,2.8,15.21],[2,1.57,75.72]],"ltp":0.0,"tv":0.0,"id":5071877}]}]}
{"op":"mcm","clk":"997156777","pt":1580536036645,"mc":[{"id":"1.168175448","rc":[{"batb":[[0,2.8,15.21],[1,1.57,75.72],[2,1.52,7.19]],"ltp":0.0,"tv":0.0,"id":5071877}]}]}
{"op":"mcm","clk":"997156854","pt":1580536038657,"mc":[{"id":"1.168175448","rc":[{"batb":[[0,2.82,20.14],[1,2.8,15.21],[2,1.57,75.72]],"ltp":0.0,"tv":0.0,"id":5071877}]}]}
{"op":"mcm","clk":"997157083","pt":1580536044425,"mc":[{"id":"1.168175448","rc":[{"batb":[[2,2.64,38.62]],"ltp":0.0,"tv":0.0,"id":5071877},{"batb":[[1,1.37,37.86],[2,1.36,76.05]],"ltp":0.0,"tv":0.0,"id":6374165}]}]}
{"op":"mcm","clk":"997158951","pt":1580536089422,"mc":[{"id":"1.168175448","rc":[{"batb":[[0,2.9,14.41],[1,2.64,38.62],[2,1.57,75.72]],"ltp":0.0,"tv":0.0,"id":5071877},{"batb":[[2,1.33,82.97]],"ltp":0.0,"tv":0.0,"id":6374165}]}]}
{"op":"mcm","clk":"997161943","pt":1580536154281,"mc":[{"id":"1.168175448","rc":[{"batb":[[0,2.8,15.21]],"ltp":0.0,"tv":0.0,"id":5071877},{"batb":[[2,1.36,76.05]],"ltp":0.0,"tv":0.0,"id":6374165}]}]}
{"op":"mcm","clk":"997162128","pt":1580536158107,"mc":[{"id":"1.168175448","rc":[{"batb":[[0,2.84,20.22],[1,2.8,15.21],[2,2.64,38.62]],"ltp":0.0,"tv":0.0,"id":5071877},{"batb":[[1,1.37,74.97]],"ltp":0.0,"tv":0.0,"id":6374165}]}]}
{"op":"mcm","clk":"997175676","pt":1580536430518,"mc":[{"id":"1.168175448","rc":[{"batb":[[1,2.82,38.62],[2,2.8,15.21]],"ltp":0.0,"tv":0.0,"id":5071877},{"batb":[[1,1.41,74.97]],"ltp":0.0,"tv":0.0,"id":6374165}]}]}
{"op":"mcm","clk":"997186248","pt":1580536624614,"mc":[{"id":"1.168175448","rc":[{"batl":[[0,2,3.03],[1,3,42.01],[2,990,2.2]],"ltp":0.0,"tv":0.0,"id":6374165}]}]}
{"op":"mcm","clk":"997210813","pt":1580536878532,"mc":[{"id":"1.168175448","rc":[{"batb":[[0,2.82,38.62],[1,2.8,15.21],[2,1.57,75.72]],"batl":[[0,2.96,19.37],[1,2.98,3.43],[2,990,2.2]],"ltp":0.0,"tv":0.0,"id":5071877}]}]}
{"op":"mcm","clk":"997210950","pt":1580536881220,"mc":[{"id":"1.168175448","rc":[{"batl":[[0,2.98,3.43],[1,990,2.2],[2,1000,0.02]],"ltp":0.0,"tv":0.0,"id":5071877}]}]}
{"op":"mcm","clk":"997210975","pt":1580536881731,"mc":[{"id":"1.168175448","rc":[{"batb":[[0,2.8,15.21],[1,1.57,75.72],[2,1.51,907.41]],"ltp":0.0,"tv":0.0,"id":5071877}]}]}
{"op":"mcm","clk":"997211518","pt":1580536887331,"mc":[{"id":"1.168175448","rc":[{"batb":[[1,1.45,74.97]],"ltp":0.0,"tv":0.0,"id":6374165}]}]}
{"op":"mcm","clk":"997211637","pt":1580536888566,"mc":[{"id":"1.168175448","rc":[{"batb":[[1,2.5,40.89],[2,1.57,75.72]],"ltp":0.0,"tv":0.0,"id":5071877},{"batb":[[1,1.36,76.05],[2,1.3,4]],"ltp":0.0,"tv":0.0,"id":6374165}]}]}
{"op":"mcm","clk":"997211658","pt":1580536888671,"mc":[{"id":"1.168175448","rc":[{"batb":[[1,1.43,74.97],[2,1.36,76.05]],"ltp":0.0,"tv":0.0,"id":6374165}]}]}
{"op":"mcm","clk":"997212129","pt":1580536894769,"mc":[{"id":"1.168175448","rc":[{"batb":[[1,2.74,40.89]],"ltp":0.0,"tv":0.0,"id":5071877}]}]}
{"op":"mcm","clk":"997212186","pt":1580536895641,"mc":[{"id":"1.168175448","rc":[{"batl":[[0,2.96,19.37],[1,2.98,3.43],[2,990,2.2]],"ltp":0.0,"tv":0.0,"id":5071877}]}]}
{"op":"mcm","clk":"997212333","pt":1580536898268,"mc":[{"id":"1.168175448","rc":[{"batb":[[1,1.57,75.72],[2,1.51,907.41]],"ltp":0.0,"tv":0.0,"id":5071877},{"batb":[[1,1.45,74.97]],"ltp":0.0,"tv":0.0,"id":6374165}]}]}
{"op":"mcm","clk":"997212491","pt":1580536901141,"mc":[{"id":"1.168175448","rc":[{"batb":[[1,2.46,42.4],[2,1.57,75.72]],"ltp":0.0,"tv":0.0,"id":5071877},{"batb":[[1,1.44,74.97]],"ltp":0.0,"tv":0.0,"id":6374165}]}]}
{"op":"mcm","clk":"997212605","pt":1580536903549,"mc":[{"id":"1.168175448","rc":[{"trd":[[2.8,29.94]],"batb":[[0,2.46,42.64],[1,1.57,75.72],[2,1.51,907.41]],"batl":[[0,2.98,3.43],[1,990,2.2],[2,1000,0.02]],"ltp":2.8,"tv":29.94,"id":5071877}],"tv":29.94}]}
{"op":"mcm","clk":"997212772","pt":1580536906374,"mc":[{"id":"1.168175448","rc":[{"batb":[[0,2.64,16.69]],"ltp":2.8,"tv":29.94,"id":5071877}]}]}
{"op":"mcm","clk":"997212804","pt":1580536906885,"mc":[{"id":"1.168175448","rc":[{"batb":[[1,1.45,74.97]],"ltp":0.0,"tv":0.0,"id":6374165}]}]}
{"op":"mcm","clk":"997212914","pt":1580536909145,"mc":[{"id":"1.168175448","rc":[{"batb":[[1,2.3,43.92],[2,1.57,75.72]],"ltp":2.8,"tv":29.94,"id":5071877},{"batb":[[1,1.44,74.97]],"ltp":0.0,"tv":0.0,"id":6374165}]}]}
{"op":"mcm","clk":"997215624","pt":1580536955730,"mc":[{"id":"1.168175448","rc":[{"batl":[[0,2.88,19.29],[1,2.98,3.43],[2,990,2.2]],"ltp":2.8,"tv":29.94,"id":5071877}]}]}
{"op":"mcm","clk":"997215776","pt":1580536958446,"mc":[{"id":"1.168175448","rc":[{"batb":[[1,1.36,76.05],[2,1.3,4]],"ltp":0.0,"tv":0.0,"id":6374165}]}]}
{"op":"mcm","clk":"997215814","pt":1580536959318,"mc":[{"id":"1.168175448","rc":[{"batb":[[1,2.44,43.92]],"ltp":2.8,"tv":29.94,"id":5071877},{"batb":[[1,1.44,70.42],[2,1.36,76.05]],"ltp":0.0,"tv":0.0,"id":6374165}]}]}
{"op":"mcm","clk":"997216442","pt":1580536971334,"mc":[{"id":"1.168175448","rc":[{"batb":[[0,2.5,18.25]],"ltp":2.8,"tv":29.94,"id":5071877},{"batb":[[1,1.44,132.64],[2,1.3,4]],"ltp":0.0,"tv":0.0,"id":6374165}]}]}
{"op":"mcm","clk":"997217163","pt":1580536985758,"mc":[{"id":"1.168175448","rc":[{"batb":[[1,2.4,43.92]],"ltp":2.8,"tv":29.94,"id":5071877},{"batb":[[0,1.53,70.42],[1,1.5,84.02],[2,1.44,62.22]],"ltp":0.0,"tv":0.0,"id":6374165}]}]}
{"op":"mcm","clk":"997217629","pt":1580536996374,"mc":[{"id":"1.168175448","rc":[{"batb":[[0,2.4,43.92],[1,2.3,21.06]],"ltp":2.8,"tv":29.94,"id":5071877},{"batb":[[0,1.53,122.08],[2,1.3,4]],"ltp":0.0,"tv":0.0,"id":6374165}]}]}
{"op":"mcm","clk":"997218543","pt":1580537016161,"mc":[{"id":"1.168175448","rc":[{"batb":[[0,2.5,20.16],[1,2.4,43.92],[2,2.3,21.06]],"ltp":2.8,"tv":29.94,"id":5071877}]}]}
{"op":"mcm","clk":"997219896","pt":1580537048518,"mc":[{"id":"1.168175448","rc":[{"batb":[[0,2.54,3.36],[1,2.5,20.16],[2,2.4,43.92]],"ltp":2.8,"tv":29.94,"id":5071877}]}]}
{"op":"mcm","clk":"997220007","pt":1580537051495,"mc":[{"id":"1.168175448","rc":[{"batb":[[0,1.53,70.42],[1,1.5,138.78]],"ltp":0.0,"tv":0.0,"id":6374165}]}]}
{"op":"mcm","clk":"997222572","pt":1580537107470,"mc":[{"id":"1.168175448","rc":[{"batb":[[2,2.44,43.92]],"ltp":2.8,"tv":29.94,"id":5071877},{"batb":[[0,1.52,70.42]],"ltp":0.0,"tv":0.0,"id":6374165}]}]}
{"op":"mcm","clk":"997227674","pt":1580537224048,"mc":[{"id":"1.168175448","rc":[{"batb":[[0,1.5,209.2],[1,1.3,4],[2,1.25,12.12]],"ltp":0.0,"tv":0.0,"id":6374165}]}]}
{"op":"mcm","clk":"997228528","pt":1580537245866,"mc":[{"id":"1.168175448","rc":[{"batl":[[0,2.98,3.43],[1,990,2.2],[2,1000,0.02]],"ltp":2.8,"tv":29.94,"id":5071877}]}]}
{"op":"mcm","clk":"997228636","pt":1580537248344,"mc":[{"id":"1.168175448","rc":[{"batb":[[0,1.5,138.78]],"ltp":0.0,"tv":0.0,"id":6374165}]}]}
{"op":"mcm","clk":"997228669","pt":1580537248961,"mc":[{"id":"1.168175448","rc":[{"batb":[[1,2.52,43.92],[2,2.5,20.16]],"ltp":2.8,"tv":29.94,"id":5071877}]}]}
{"op":"mcm","clk":"997229878","pt":1580537280506,"mc":[{"id":"1.168175448","rc":[{"batb":[[0,1.5,206.93]],"ltp":0.0,"tv":0.0,"id":6374165}]}]}
{"op":"mcm","clk":"997234310","pt":1580537386835,"mc":[{"id":"1.168175448","rc":[{"batb":[[0,1.5,138.78],[1,1.49,68.15],[2,1.3,4]],"ltp":0.0,"tv":0.0,"id":6374165}]}]}
{"op":"mcm","clk":"997236415","pt":1580537447427,"mc":[{"id":"1.168175448","rc":[{"batb":[[2,2.5,38.41]],"ltp":2.8,"tv":29.94,"id":5071877},{"batb":[[0,1.5,84.02],[2,1.44,62.22]],"ltp":0.0,"tv":0.0,"id":6374165}]}]}
{"op":"mcm","clk":"997253168","pt":1580537628512,"mc":[{"id":"1.168175448","rc":[{"batb":[[0,2.54,23.35],[1,2.5,82.33],[2,2.02,1.68]],"ltp":2.8,"tv":29.94,"id":5071877},{"batb":[[0,1.5,152.17],[1,1.44,62.22],[2,1.3,4]],"ltp":0.0,"tv":0.0,"id":6374165}]}]}
{"op":"mcm","clk":"997253183","pt":1580537628719,"mc":[{"id":"1.168175448","rc":[{"batl":[[0,2.96,19.37],[1,2.98,3.43],[2,990,2.2]],"ltp":2.8,"tv":29.94,"id":5071877}]}]}
{"op":"mcm","clk":"997253570","pt":1580537638925,"mc":[{"id":"1.168175448","rc":[{"batb":[[0,2.54,3.36]],"batl":[[0,2.98,3.43],[1,990,2.2],[2,1000,0.02]],"ltp":2.8,"tv":29.94,"id":5071877}]}]}
{"op":"mcm","clk":"997253798","pt":1580537645315,"mc":[{"id":"1.168175448","rc":[{"batb":[[0,2.54,23.35]],"batl":[[0,2.96,19.37],[1,2.98,3.43],[2,990,2.2]],"ltp":2.8,"tv":29.94,"id":5071877}]}]}
{"op":"mcm","clk":"997305633","pt":1580538703377,"mc":[{"id":"1.168175448","rc":[{"batb":[[2,2.08,213.5]],"ltp":2.8,"tv":29.94,"id":5071877},{"batb":[[2,1.36,213.5]],"ltp":0.0,"tv":0.0,"id":6374165}]}]}
{"op":"mcm","clk":"997328703","pt":1580539178524,"mc":[{"id":"1.168175448","rc":[{"batb":[[0,2.54,3.36]],"ltp":2.8,"tv":29.94,"id":5071877}]}]}
{"op":"mcm","clk":"997328840","pt":1580539181357,"mc":[{"id":"1.168175448","rc":[{"batb":[[1,2.5,38.41]],"ltp":2.8,"tv":29.94,"id":5071877}]}]}
{"op":"mcm","clk":"997328898","pt":1580539182541,"mc":[{"id":"1.168175448","rc":[{"batb":[[0,1.56,68.15],[1,1.5,84.02],[2,1.44,62.22]],"ltp":0.0,"tv":0.0,"id":6374165}]}]}
{"op":"mcm","clk":"997328943","pt":1580539183466,"mc":[{"id":"1.168175448","rc":[{"batl":[[0,2.98,3.43],[1,990,2.2],[2,1000,0.02]],"ltp":2.8,"tv":29.94,"id":5071877},{"batb":[[0,1.56,34.08],[1,1.55,68.15],[2,1.5,84.02]],"ltp":0.0,"tv":0.0,"id":6374165}]}]}
{"op":"mcm","clk":"997328951","pt":1580539183626,"mc":[{"id":"1.168175448","rc":[{"batb":[[2,2.38,43.16]],"ltp":2.8,"tv":29.94,"id":5071877}]}]}
{"op":"mcm","clk":"997332449","pt":1580539271857,"mc":[{"id":"1.168175448","rc":[{"batb":[[1,2.5,20.16],[2,2.38,63]],"ltp":2.8,"tv":29.94,"id":5071877},{"batb":[[2,1.5,138.78]],"ltp":0.0,"tv":0.0,"id":6374165}]}]}
{"op":"mcm","clk":"997334197","pt":1580539321920,"mc":[{"id":"1.168175448","rc":[{"batb":[[0,1.55,68.15],[1,1.5,138.78],[2,1.36,213.5]],"ltp":0.0,"tv":0.0,"id":6374165}]}]}
{"op":"mcm","clk":"997334487","pt":1580539328924,"mc":[{"id":"1.168175448","rc":[{"batb":[[2,2.4,43.16]],"ltp":2.8,"tv":29.94,"id":5071877},{"batb":[[0,1.55,34.99],[1,1.54,68.15],[2,1.5,138.78]],"ltp":0.0,"tv":0.0,"id":6374165}]}]}
{"op":"mcm","clk":"997356570","pt":1580539702459,"mc":[{"id":"1.168175448","rc":[{"batb":[[0,1.55,51.99]],"ltp":0.0,"tv":0.0,"id":6374165}]}]}
{"op":"mcm","clk":"997449987","pt":1580541286416,"mc":[{"id":"1.168175448","rc":[{"batb":[[0,1.57,48.03],[1,1.55,51.99],[2,1.54,68.15]],"ltp":0.0,"tv":0.0,"id":6374165}]}]}
{"op":"mcm","clk":"997449996","pt":1580541286619,"mc":[{"id":"1.168175448","rc":[{"batb":[[1,1.54,68.15],[2,1.5,84.02]],"ltp":0.0,"tv":0.0,"id":6374165}]}]}
{"op":"mcm","clk":"997460008","pt":1580541507794,"mc":[{"id":"1.168175448","rc":[{"batb":[[1,2.4,43.16],[2,2.2,22.81]],"ltp":2.8,"tv":29.94,"id":5071877}]}]}
{"op":"mcm","clk":"997464108","pt":1580541594497,"mc":[{"id":"1.168175448","rc":[{"batb":[[0,2.4,43.16],[1,2.2,22.81],[2,2.16,24.81]],"ltp":2.8,"tv":29.94,"id":5071877}]}]}
{"op":"mcm","clk":"997495055","pt":1580542156157,"mc":[{"id":"1.168175448","rc":[{"trd":[[1.6,4]],"ltp":1.6,"tv":4.0,"id":6374165}],"tv":33.94}]}
{"op":"mcm","clk":"997541240","pt":1580543037459,"mc":[{"id":"1.168175448","rc":[{"batb":[[2,1.51,6.69]],"ltp":1.6,"tv":4.0,"id":6374165}]}]}
{"op":"mcm","clk":"997556957","pt":1580543522533,"mc":[{"id":"1.168175448","rc":[{"batb":[[0,2.42,39.94],[1,2.4,43.16],[2,2.2,22.81]],"ltp":2.8,"tv":29.94,"id":5071877}]}]}
{"op":"mcm","clk":"997578926","pt":1580543915249,"mc":[{"id":"1.168175448","rc":[{"batb":[[1,2.38,43.16]],"ltp":2.8,"tv":29.94,"id":5071877}]}]}
{"op":"mcm","clk":"997582439","pt":1580544011468,"mc":[{"id":"1.168175448","rc":[{"batb":[[1,2.2,22.81],[2,2.16,32.64]],"ltp":2.8,"tv":29.94,"id":5071877},{"batb":[[1,1.51,6.69],[2,1.5,84.02]],"ltp":1.6,"tv":4.0,"id":6374165}]}]}
{"op":"mcm","clk":"997582447","pt":1580544011571,"mc":[{"id":"1.168175448","rc":[{"batb":[[2,2.18,43.16]],"ltp":2.8,"tv":29.94,"id":5071877}]}]}
{"op":"mcm","clk":"997592924","pt":1580544196500,"mc":[{"id":"1.168175448","rc":[{"batb":[[2,2.16,32.64]],"ltp":2.8,"tv":29.94,"id":5071877}]}]}
{"op":"mcm","clk":"997592929","pt":1580544196600,"mc":[{"id":"1.168175448","rc":[{"batb":[[1,2.4,43.16],[2,2.2,22.81]],"ltp":2.8,"tv":29.94,"id":5071877},{"batb":[[1,1.54,68.15],[2,1.51,6.69]],"ltp":1.6,"tv":4.0,"id":6374165}]}]}
{"op":"mcm","clk":"997782915","pt":1580546689371,"mc":[{"id":"1.168175448","rc":[{"batb":[[0,2.46,4.2],[1,2.42,39.94],[2,2.4,43.16]],"ltp":2.8,"tv":29.94,"id":5071877}]}]}
{"op":"mcm","clk":"997782927","pt":1580546689585,"mc":[{"id":"1.168175448","rc":[{"batb":[[1,2.4,43.16],[2,2.2,22.81]],"ltp":2.8,"tv":29.94,"id":5071877}]}]}
{"op":"mcm","clk":"997901049","pt":1580548199496,"mc":[{"id":"1.168175448","rc":[{"batb":[[0,1.57,132.02]],"ltp":1.6,"tv":4.0,"id":6374165}]}]}
{"op":"mcm","clk":"997901487","pt":1580548204493,"mc":[{"id":"1.168175448","rc":[{"batb":[[1,2.2,22.81],[2,2.12,42.59]],"ltp":2.8,"tv":29.94,"id":5071877},{"batb":[[0,1.57,200.17],[1,1.51,6.69],[2,1.5,84.02]],"ltp":1.6,"tv":4.0,"id":6374165}]}]}
{"op":"mcm","clk":"997901624","pt":1580548206097,"mc":[{"id":"1.168175448","rc":[{"batb":[[1,2.34,43.16],[2,2.2,22.81]],"ltp":2.8,"tv":29.94,"id":5071877},{"batb":[[0,1.57,132.02],[1,1.56,68.15],[2,1.51,6.69]],"ltp":1.6,"tv":4.0,"id":6374165}]}]}
{"op":"mcm","clk":"997908998","pt":1580548297145,"mc":[{"id":"1.168175448","rc":[{"batb":[[0,1.57,83.99],[2,1.53,51.66]],"ltp":1.6,"tv":4.0,"id":6374165}]}]}
{"op":"mcm","clk":"997970647","pt":1580548912103,"mc":[{"id":"1.168175448","rc":[{"batb":[[0,1.57,150.64]],"ltp":1.6,"tv":4.0,"id":6374165}]}]}
{"op":"mcm","clk":"998048744","pt":1580549776695,"mc":[{"id":"1.168175448","rc":[{"batb":[[0,2.48,15.33],[1,2.46,4.2],[2,2.34,43.16]],"ltp":2.8,"tv":29.94,"id":5071877},{"batb":[[0,1.59,47.17],[1,1.57,150.64],[2,1.56,68.15]],"ltp":1.6,"tv":4.0,"id":6374165}]}]}
{"op":"mcm","clk":"998060800","pt":1580549937003,"mc":[{"id":"1.168175448","rc":[{"batb":[[1,1.56,68.15],[2,1.53,51.66]],"ltp":1.6,"tv":4.0,"id":6374165}]}]}
{"op":"mcm","clk":"998126025","pt":1580550561505,"mc":[{"id":"1.168175448","rc":[{"batl":[[1,95,15.9],[2,990,2.2]],"ltp":2.8,"tv":29.94,"id":5071877},{"batl":[[2,95,15.9]],"ltp":1.6,"tv":4.0,"id":6374165}]}]}
{"op":"mcm","clk":"998224300","pt":1580551447046,"mc":[{"id":"1.168175448","rc":[{"batb":[[2,1.53,274.54]],"ltp":1.6,"tv":4.0,"id":6374165}]}]}
{"op":"mcm","clk":"998226710","pt":1580551460664,"mc":[{"id":"1.168175448","rc":[{"batl":[[0,1.64,2.27],[1,2,3.03],[2,3,42.01]],"ltp":1.6,"tv":4.0,"id":6374165}]}]}
{"op":"mcm","clk":"998534004","pt":1580553453408,"mc":[{"id":"1.168175448","rc":[{"trd":[[1.64,4.54]],"batl":[[0,2,3.03],[1,3,42.01],[2,95,15.9]],"ltp":1.64,"tv":8.54,"id":6374165}],"tv":38.48}]}
{"op":"mcm","clk":"998534074","pt":1580553453897,"mc":[{"id":"1.168175448","rc":[{"batb":[[0,2.48,15.21]],"ltp":2.8,"tv":29.94,"id":5071877}]}]}
{"op":"mcm","clk":"998886067","pt":1580555555404,"mc":[{"id":"1.168175448","rc":[{"batb":[[0,2.5,7.56],[1,2.48,15.21]],"ltp":2.8,"tv":29.94,"id":5071877}]}]}
{"op":"mcm","clk":"998915874","pt":1580555710862,"mc":[{"id":"1.168175448","rc":[{"batb":[[1,2.4,34.76]],"ltp":2.8,"tv":29.94,"id":5071877}]}]}
{"op":"mcm","clk":"998961562","pt":1580555938789,"mc":[{"id":"1.168175448","rc":[{"batb":[[1,1.54,68.15]],"ltp":1.64,"tv":8.54,"id":6374165}]}]}
{"op":"mcm","clk":"998965344","pt":1580555958931,"mc":[{"id":"1.168175448","rc":[{"batl":[[0,2.68,3.43]],"ltp":2.8,"tv":29.94,"id":5071877}]}]}
{"op":"mcm","clk":"998968075","pt":1580555973749,"mc":[{"id":"1.168175448","rc":[{"batb":[[1,1.56,68.15]],"ltp":1.64,"tv":8.54,"id":6374165}]}]}
{"op":"mcm","clk":"998975820","pt":1580556014097,"mc":[{"id":"1.168175448","rc":[{"batb":[[0,2.6,1.68],[1,2.54,20.16],[2,2.5,7.56]],"ltp":2.8,"tv":29.94,"id":5071877}]}]}
{"op":"mcm","clk":"998997922","pt":1580556131444,"mc":[{"id":"1.168175448","rc":[{"trd":[[2.6,3.36]],"batb":[[0,2.54,20.16],[1,2.5,7.56],[2,2.34,43.16]],"ltp":2.6,"tv":33.3,"id":5071877}],"tv":41.84}]}
{"op":"mcm","clk":"998997977","pt":1580556131753,"mc":[{"id":"1.168175448","rc":[{"batb":[[2,2.42,31.44]],"ltp":2.6,"tv":33.3,"id":5071877},{"batb":[[0,1.59,44.66]],"ltp":1.64,"tv":8.54,"id":6374165}]}]}
{"op":"mcm","clk":"999121280","pt":1580556747896,"mc":[{"id":"1.168175448","rc":[{"batl":[[0,2.2,3.03]],"ltp":1.64,"tv":8.54,"id":6374165}]}]}
{"op":"mcm","clk":"999313576","pt":1580557728362,"mc":[{"id":"1.168175448","rc":[{"batb":[[0,1.59,44.32]],"ltp":1.64,"tv":8.54,"id":6374165}]}]}
{"op":"mcm","clk":"1000015796","pt":1580561328951,"mc":[{"id":"1.168175448","rc":[{"batb":[[1,1.53,51.66],[2,1.5,84.02]],"ltp":1.64,"tv":8.54,"id":6374165}]}]}
{"op":"mcm","clk":"1000016049","pt":1580561330211,"mc":[{"id":"1.168175448","rc":[{"batb":[[2,1.5,320.28]],"ltp":1.64,"tv":8.54,"id":6374165}]}]}
{"op":"mcm","clk":"1000043689","pt":1580561470638,"mc":[{"id":"1.168175448","rc":[{"batb":[[1,1.5,375.04],[2,1.36,213.5]],"ltp":1.64,"tv":8.54,"id":6374165}]}]}
{"op":"mcm","clk":"1000160221","pt":1580562045112,"mc":[{"id":"1.168175448","rc":[{"batb":[[2,2.42,74.6]],"ltp":2.6,"tv":33.3,"id":5071877},{"batb":[[1,1.53,66.64],[2,1.5,375.04]],"ltp":1.64,"tv":8.54,"id":6374165}]}]}
{"op":"mcm","clk":"1000211801","pt":1580562290348,"mc":[{"id":"1.168175448","rc":[{"batb":[[2,1.5,138.78]],"ltp":1.64,"tv":8.54,"id":6374165}]}]}
{"op":"mcm","clk":"1000211961","pt":1580562290940,"mc":[{"id":"1.168175448","rc":[{"batb":[[2,1.5,499.22]],"ltp":1.64,"tv":8.54,"id":6374165}]}]}
{"op":"mcm","clk":"1000835023","pt":1580564932356,"mc":[{"id":"1.168175448","rc":[{"batb":[[0,1.6,64],[1,1.59,44.32],[2,1.53,66.64]],"ltp":1.64,"tv":8.54,"id":6374165}]}]}
{"op":"mcm","clk":"1000841297","pt":1580564962745,"mc":[{"id":"1.168175448","rc":[{"batb":[[0,1.61,26.59],[1,1.6,64]],"ltp":1.64,"tv":8.54,"id":6374165}]}]}
{"op":"mcm","clk":"1000890871","pt":1580565220281,"mc":[{"id":"1.168175448","rc":[{"batb":[[0,1.61,90.59],[1,1.53,66.64],[2,1.5,499.22]],"ltp":1.64,"tv":8.54,"id":6374165}]}]}
{"op":"mcm","clk":"1000966923","pt":1580565617758,"mc":[{"id":"1.168175448","rc":[{"batb":[[2,2.46,18.75]],"ltp":2.6,"tv":33.3,"id":5071877},{"batb":[[1,1.53,118.3],[2,1.5,444.46]],"ltp":1.64,"tv":8.54,"id":6374165}]}]}
{"op":"mcm","clk":"1000971576","pt":1580565642468,"mc":[{"id":"1.168175448","rc":[{"batb":[[2,2.48,17.17]],"ltp":2.6,"tv":33.3,"id":5071877}]}]}
{"op":"mcm","clk":"1001148020","pt":1580566461520,"mc":[{"id":"1.168175448","rc":[{"batl":[[0,95,15.9],[1,990,2.2],[2,1000,0.02]],"ltp":2.6,"tv":33.3,"id":5071877}]}]}
{"op":"mcm","clk":"1001148028","pt":1580566461631,"mc":[{"id":"1.168175448","rc":[{"batl":[[0,2.62,3.43],[1,95,15.9],[2,990,2.2]],"ltp":2.6,"tv":33.3,"id":5071877}]}]}
{"op":"mcm","clk":"1001170761","pt":1580566554028,"mc":[{"id":"1.168175448","rc":[{"batl":[[0,3,42.01],[1,95,15.9],[2,990,2.2]],"ltp":1.64,"tv":8.54,"id":6374165}]}]}
{"op":"mcm","clk":"1001173415","pt":1580566566878,"mc":[{"id":"1.168175448","rc":[{"batl":[[0,2.2,28.02],[1,3,42.01],[2,95,15.9]],"ltp":1.64,"tv":8.54,"id":6374165}]}]}
{"op":"mcm","clk":"1001267331","pt":1580567000899,"mc":[{"id":"1.168175448","rc":[{"batb":[[2,1.5,84.02]],"ltp":1.64,"tv":8.54,"id":6374165}]}]}
{"op":"mcm","clk":"1001267658","pt":1580567002303,"mc":[{"id":"1.168175448","rc":[{"batb":[[1,1.53,51.66]],"ltp":1.64,"tv":8.54,"id":6374165}]}]}
{"op":"mcm","clk":"1001352298","pt":1580567428914,"mc":[{"id":"1.168175448","rc":[{"trd":[[1.61,3.36]],"batb":[[0,1.61,88.91]],"ltp":1.61,"tv":11.9,"id":6374165}],"tv":45.2}]}
{"op":"mcm","clk":"1001364285","pt":1580567492404,"mc":[{"id":"1.168175448","rc":[{"batb":[[0,2.54,37.93]],"ltp":2.6,"tv":33.3,"id":5071877},{"batb":[[1,1.5,138.78],[2,1.48,375.47]],"ltp":1.61,"tv":11.9,"id":6374165}]}]}
{"op":"mcm","clk":"1001399161","pt":1580567670180,"mc":[{"id":"1.168175448","rc":[{"batb":[[2,2.44,27.79]],"ltp":2.6,"tv":33.3,"id":5071877}]}]}
{"op":"mcm","clk":"1001405063","pt":1580567700530,"mc":[{"id":"1.168175448","rc":[{"batb":[[2,1.37,75.73]],"ltp":1.61,"tv":11.9,"id":6374165}]}]}
{"op":"mcm","clk":"1001405180","pt":1580567701140,"mc":[{"id":"1.168175448","rc":[{"batb":[[2,1.49,367.79]],"ltp":1.61,"tv":11.9,"id":6374165}]}]}
{"op":"mcm","clk":"1001434834","pt":1580567839919,"mc":[{"id":"1.168175448","rc":[{"batb":[[1,1.5,140.78]],"ltp":1.61,"tv":11.9,"id":6374165}]}]}
{"op":"mcm","clk":"1001465311","pt":1580567980284,"mc":[{"id":"1.168175448","rc":[{"batl":[[2,4,3.03]],"ltp":1.61,"tv":11.9,"id":6374165}]}]}
{"op":"mcm","clk":"1001466590","pt":1580567986289,"mc":[{"id":"1.168175448","rc":[{"batl":[[2,4,3.56]],"ltp":1.61,"tv":11.9,"id":6374165}]}]}
{"op":"mcm","clk":"1001469284","pt":1580567998296,"mc":[{"id":"1.168175448","rc":[{"batl":[[0,2.2,28.55],[2,95,15.9]],"ltp":1.61,"tv":11.9,"id":6374165}]}]}
{"op":"mcm","clk":"1001469356","pt":1580567998580,"mc":[{"id":"1.168175448","rc":[{"trd":[[2.54,1.3]],"batb":[[0,2.54,36.63]],"ltp":2.54,"tv":34.6,"id":5071877},{"trd":[[1.65,2]],"ltp":1.65,"tv":13.9,"id":6374165}],"tv":48.5}]}
{"op":"mcm","clk":"1001743031","pt":1580569249223,"mc":[{"id":"1.168175448","rc":[{"batb":[[2,2.46,43.16]],"ltp":2.54,"tv":34.6,"id":5071877},{"batb":[[1,1.52,66.64],[2,1.5,140.78]],"ltp":1.65,"tv":13.9,"id":6374165}]}]}
{"op":"mcm","clk":"1001778301","pt":1580569409473,"mc":[{"id":"1.168175448","rc":[{"batb":[[2,2.48,18.24]],"ltp":2.54,"tv":34.6,"id":5071877}]}]}
{"op":"mcm","clk":"1001993398","pt":1580570285431,"mc":[{"id":"1.168175448","rc":[{"batb":[[1,1.5,140.78],[2,1.46,391.79]],"ltp":1.65,"tv":13.9,"id":6374165}]}]}
{"op":"mcm","clk":"1001999432","pt":1580570311275,"mc":[{"id":"1.168175448","rc":[{"batl":[[0,1.64,3.79],[1,2.2,28.55],[2,3,42.01]],"ltp":1.65,"tv":13.9,"id":6374165}]}]}
{"op":"mcm","clk":"1002000267","pt":1580570314854,"mc":[{"id":"1.168175448","rc":[{"batl":[[0,2.2,28.55],[1,3,42.01],[2,95,15.9]],"ltp":1.65,"tv":13.9,"id":6374165}]}]}
{"op":"mcm","clk":"1002009025","pt":1580570352566,"mc":[{"id":"1.168175448","rc":[{"batb":[[2,2.46,43.16]],"ltp":2.54,"tv":34.6,"id":5071877},{"batb":[[0,1.61,64]],"ltp":1.65,"tv":13.9,"id":6374165}]}]}
{"op":"mcm","clk":"1002009085","pt":1580570352780,"mc":[{"id":"1.168175448","rc":[{"batb":[[0,2.56,14.25],[1,2.54,36.63],[2,2.5,7.56]],"ltp":2.54,"tv":34.6,"id":5071877},{"batb":[[1,1.56,48.83],[2,1.5,140.78]],"ltp":1.65,"tv":13.9,"id":6374165}]}]}
{"op":"mcm","clk":"1002031737","pt":1580570450258,"mc":[{"id":"1.168175448","rc":[{"batb":[[2,1.5,86.02]],"ltp":1.65,"tv":13.9,"id":6374165}]}]}
{"op":"mcm","clk":"1002254646","pt":1580571408465,"mc":[{"id":"1.168175448","rc":[{"trd":[[2.62,6.66]],"batl":[[0,95,16],[1,990,2.2],[2,1000,0.02]],"ltp":2.62,"tv":41.26,"id":5071877},{"trd":[[1.61,131.36]],"batb":[[0,1.56,48.83],[1,1.5,86.02],[2,1.47,58.26]],"ltp":1.61,"tv":141.89,"id":6374165}],"tv":183.16}]}
{"op":"mcm","clk":"1002255599","pt":1580571412481,"mc":[{"id":"1.168175448","rc":[{"batl":[[0,1.64,7.57],[1,2.2,28.55],[2,3,42.01]],"ltp":1.61,"tv":141.89,"id":6374165}]}]}
{"op":"mcm","clk":"1002256200","pt":1580571415025,"mc":[{"id":"1.168175448","rc":[{"batl":[[0,16.5,3.46],[1,95,15.9],[2,990,2.2]],"ltp":2.62,"tv":41.26,"id":5071877}]}]}
{"op":"mcm","clk":"1002257217","pt":1580571419698,"mc":[{"id":"1.168175448","rc":[{"batl":[[0,1.63,301.77],[1,1.64,7.57],[2,2.2,28.55]],"ltp":1.61,"tv":141.89,"id":6374165}]}]}
{"op":"mcm","clk":"1002292067","pt":1580571565877,"mc":[{"id":"1.168175448","rc":[{"batb":[[0,2.6,9.89]],"ltp":2.62,"tv":41.26,"id":5071877},{"batb":[[0,1.55,52.17]],"ltp":1.61,"tv":141.89,"id":6374165}]}]}
{"op":"mcm","clk":"1002292395","pt":1580571567300,"mc":[{"id":"1.168175448","rc":[{"batb":[[0,2.6,198.98]],"ltp":2.62,"tv":41.26,"id":5071877},{"batl":[[0,1.64,7.57],[1,2.2,28.55],[2,3,42.01]],"ltp":1.61,"tv":141.89,"id":6374165}]}]}
{"op":"mcm","clk":"1002340477","pt":1580571772394,"mc":[{"id":"1.168175448","rc":[{"batb":[[0,2.6,189.09],[1,2.58,14.01],[2,2.54,36.63]],"ltp":2.62,"tv":41.26,"id":5071877}]}]}
{"op":"mcm","clk":"1002466628","pt":1580572365868,"mc":[{"id":"1.168175448","rc":[{"batl":[[0,2.2,28.55],[1,3,42.01],[2,95,15.9]],"ltp":1.61,"tv":141.89,"id":6374165}]}]}
{"op":"mcm","clk":"1002467313","pt":1580572370082,"mc":[{"id":"1.168175448","rc":[{"batb":[[1,2.56,18.25]],"ltp":2.62,"tv":41.26,"id":5071877}]}]}
{"op":"mcm","clk":"1002488997","pt":1580572507126,"mc":[{"id":"1.168175448","rc":[{"trd":[[2.62,6.76]],"batb":[[0,2.56,18.25],[1,2.54,36.63],[2,2.5,7.56]],"batl":[[0,16.5,3.36]],"ltp":2.62,"tv":41.36,"id":5071877},{"trd":[[1.61,131.52]],"batl":[[0,1.61,3.63],[1,2.2,28.55],[2,3,42.01]],"ltp":1.61,"tv":142.05,"id":6374165}],"tv":183.42}]}
{"op":"mcm","clk":"1002489422","pt":1580572509837,"mc":[{"id":"1.168175448","rc":[{"trd":[[1.6,4.32]],"ltp":1.6,"tv":142.37,"id":6374165}],"tv":183.74}]}
{"op":"mcm","clk":"1002489618","pt":1580572511163,"mc":[{"id":"1.168175448","rc":[{"batb":[[0,2.58,190.56],[1,2.56,18.25],[2,2.54,36.63]],"ltp":2.62,"tv":41.36,"id":5071877},{"batl":[[0,1.64,3.79]],"ltp":1.6,"tv":142.37,"id":6374165}]}]}
{"op":"mcm","clk":"1002490129","pt":1580572514542,"mc":[{"id":"1.168175448","rc":[{"batb":[[0,2.56,18.25],[1,2.54,36.63],[2,2.5,7.56]],"ltp":2.62,"tv":41.36,"id":5071877},{"batl":[[0,1.61,3.79],[1,1.64,3.79],[2,2.2,28.55]],"ltp":1.6,"tv":142.37,"id":6374165}]}]}
{"op":"mcm","clk":"1002507334","pt":1580572623544,"mc":[{"id":"1.168175448","rc":[{"batl":[[0,1.63,301.77]],"ltp":1.6,"tv":142.37,"id":6374165}]}]}
{"op":"mcm","clk":"1002507399","pt":1580572624028,"mc":[{"id":"1.168175448","rc":[{"batl":[[0,1.61,3.79]],"ltp":1.6,"tv":142.37,"id":6374165}]}]}
{"op":"mcm","clk":"1002537009","pt":1580572801389,"mc":[{"id":"1.168175448","rc":[{"batb":[[1,2.54,45.52]],"ltp":2.62,"tv":41.36,"id":5071877},{"batb":[[2,1.47,87.39]],"ltp":1.6,"tv":142.37,"id":6374165}]}]}
{"op":"mcm","clk":"1002547652","pt":1580572856515,"mc":[{"id":"1.168175448","rc":[{"batb":[[0,2.56,61.41]],"ltp":2.62,"tv":41.36,"id":5071877},{"batb":[[2,1.49,68.15]],"ltp":1.6,"tv":142.37,"id":6374165}]}]}
{"op":"mcm","clk":"1002580956","pt":1580573023385,"mc":[{"id":"1.168175448","rc":[{"batl":[[0,1.61,7.57]],"ltp":1.6,"tv":142.37,"id":6374165}]}]}
{"op":"mcm","clk":"1002608077","pt":1580573143423,"mc":[{"id":"1.168175448","rc":[{"batl":[[0,1.61,11.36]],"ltp":1.6,"tv":142.37,"id":6374165}]}]}
{"op":"mcm","clk":"1002620524","pt":1580573197310,"mc":[{"id":"1.168175448","rc":[{"batl":[[0,1.61,3.79]],"ltp":1.6,"tv":142.37,"id":6374165}]}]}
{"op":"mcm","clk":"1002690456","pt":1580573477348,"mc":[{"id":"1.168175448","rc":[{"batl":[[0,1.61,7.57]],"ltp":1.6,"tv":142.37,"id":6374165}]}]}
{"op":"mcm","clk":"1002691859","pt":1580573482415,"mc":[{"id":"1.168175448","rc":[{"batl":[[0,1.61,15.14]],"ltp":1.6,"tv":142.37,"id":6374165}]}]}
{"op":"mcm","clk":"1002692325","pt":1580573484351,"mc":[{"id":"1.168175448","rc":[{"batl":[[0,1.64,3.79],[1,2.2,28.55],[2,3,42.01]],"ltp":1.6,"tv":142.37,"id":6374165}]}]}
{"op":"mcm","clk":"1002692445","pt":1580573484845,"mc":[{"id":"1.168175448","rc":[{"batl":[[0,1.63,395.77],[1,1.64,3.79],[2,2.2,28.55]],"ltp":1.6,"tv":142.37,"id":6374165}]}]}
{"op":"mcm","clk":"1002693307","pt":1580573488169,"mc":[{"id":"1.168175448","rc":[{"batl":[[0,1.61,7.57]],"ltp":1.6,"tv":142.37,"id":6374165}]}]}
{"op":"mcm","clk":"1002704591","pt":1580573531323,"mc":[{"id":"1.168175448","rc":[{"batl":[[0,1.64,3.79],[1,2.2,28.55],[2,3,42.01]],"ltp":1.6,"tv":142.37,"id":6374165}]}]}
{"op":"mcm","clk":"1002704693","pt":1580573531618,"mc":[{"id":"1.168175448","rc":[{"batl":[[0,1.63,395.77],[1,1.64,3.79],[2,2.2,28.55]],"ltp":1.6,"tv":142.37,"id":6374165}]}]}
{"op":"mcm","clk":"1002720095","pt":1580573593510,"mc":[{"id":"1.168175448","rc":[{"batb":[[0,2.56,43.16]],"ltp":2.62,"tv":41.36,"id":5071877}]}]}
{"op":"mcm","clk":"1002720170","pt":1580573593751,"mc":[{"id":"1.168175448","rc":[{"batb":[[0,2.6,9.89],[1,2.56,43.16],[2,2.54,45.52]],"ltp":2.62,"tv":41.36,"id":5071877}]}]}
{"op":"mcm","clk":"1002720696","pt":1580573595205,"mc":[{"id":"1.168175448","rc":[{"batl":[[0,1.64,3.79],[1,2.2,28.55],[2,3,42.01]],"ltp":1.6,"tv":142.37,"id":6374165}]}]}
{"op":"mcm","clk":"1002728064","pt":1580573620560,"mc":[{"id":"1.168175448","rc":[{"batb":[[0,2.6,257.83]],"ltp":2.62,"tv":41.36,"id":5071877}]}]}
{"op":"mcm","clk":"1002739764","pt":1580573661775,"mc":[{"id":"1.168175448","rc":[{"batl":[[0,1.61,3.79],[1,1.64,3.79],[2,2.2,28.55]],"ltp":1.6,"tv":142.37,"id":6374165}]}]}
{"op":"mcm","clk":"1002740127","pt":1580573662985,"mc":[{"id":"1.168175448","rc":[{"batb":[[0,2.6,9.89]],"ltp":2.62,"tv":41.36,"id":5071877}]}]}
{"op":"mcm","clk":"1002740897","pt":1580573665783,"mc":[{"id":"1.168175448","rc":[{"batl":[[0,1.61,7.57]],"ltp":1.6,"tv":142.37,"id":6374165}]}]}
{"op":"mcm","clk":"1002746670","pt":1580573688180,"mc":[{"id":"1.168175448","rc":[{"batl":[[0,1.61,11.36]],"ltp":1.6,"tv":142.37,"id":6374165}]}]}
{"op":"mcm","clk":"1002747745","pt":1580573692368,"mc":[{"id":"1.168175448","rc":[{"batb":[[0,2.6,257.83]],"ltp":2.62,"tv":41.36,"id":5071877},{"batl":[[0,1.61,3.79]],"ltp":1.6,"tv":142.37,"id":6374165}]}]}
{"op":"mcm","clk":"1002747798","pt":1580573692580,"mc":[{"id":"1.168175448","rc":[{"batb":[[0,2.6,9.89]],"ltp":2.62,"tv":41.36,"id":5071877}]}]}
{"op":"mcm","clk":"1002762432","pt":1580573747315,"mc":[{"id":"1.168175448","rc":[{"batl":[[0,1.61,7.57]],"ltp":1.6,"tv":142.37,"id":6374165}]}]}
{"op":"mcm","clk":"1002774749","pt":1580573793956,"mc":[{"id":"1.168175448","rc":[{"batb":[[0,2.58,14.01]],"ltp":2.62,"tv":41.36,"id":5071877}]}]}
{"op":"mcm","clk":"1002783695","pt":1580573827824,"mc":[{"id":"1.168175448","rc":[{"batl":[[0,1.61,11.36]],"ltp":1.6,"tv":142.37,"id":6374165}]}]}
{"op":"mcm","clk":"1002784347","pt":1580573830232,"mc":[{"id":"1.168175448","rc":[{"batb":[[0,2.6,247.94],[1,2.58,14.01],[2,2.56,43.16]],"ltp":2.62,"tv":41.36,"id":5071877},{"batl":[[0,1.64,3.79],[1,2.2,28.55],[2,3,42.01]],"ltp":1.6,"tv":142.37,"id":6374165}]}]}
{"op":"mcm","clk":"1002784528","pt":1580573830955,"mc":[{"id":"1.168175448","rc":[{"batb":[[0,2.58,14.01],[1,2.56,43.16],[2,2.54,45.52]],"ltp":2.62,"tv":41.36,"id":5071877},{"batl":[[0,1.61,7.57],[1,1.64,3.79],[2,2.2,28.55]],"ltp":1.6,"tv":142.37,"id":6374165}]}]}
{"op":"mcm","clk":"1002936965","pt":1580574403380,"mc":[{"id":"1.168175448","rc":[{"batl":[[0,1.64,3.79],[1,2.2,28.55],[2,3,42.01]],"ltp":1.6,"tv":142.37,"id":6374165}]}]}
{"op":"mcm","clk":"1002937047","pt":1580574403760,"mc":[{"id":"1.168175448","rc":[{"batb":[[0,2.6,247.94],[1,2.58,14.01],[2,2.56,43.16]],"ltp":2.62,"tv":41.36,"id":5071877}]}]}
{"op":"mcm","clk":"1002937755","pt":1580574406414,"mc":[{"id":"1.168175448","rc":[{"batb":[[0,2.58,14.01],[1,2.56,43.16],[2,2.54,45.52]],"ltp":2.62,"tv":41.36,"id":5071877},{"batl":[[0,1.61,7.57],[1,1.64,3.79],[2,2.2,28.55]],"ltp":1.6,"tv":142.37,"id":6374165}]}]}
{"op":"mcm","clk":"1002938514","pt":1580574409468,"mc":[{"id":"1.168175448","rc":[{"batl":[[1,2.2,28.55],[2,3,42.01]],"ltp":1.6,"tv":142.37,"id":6374165}]}]}
{"op":"mcm","clk":"1003079000","pt":1580574999214,"mc":[{"id":"1.168175448","rc":[{"batl":[[0,1.61,11.36]],"ltp":1.6,"tv":142.37,"id":6374165}]}]}
{"op":"mcm","clk":"1003079776","pt":1580575002304,"mc":[{"id":"1.168175448","rc":[{"batb":[[0,2.6,247.94],[1,2.58,14.01],[2,2.56,43.16]],"ltp":2.62,"tv":41.36,"id":5071877},{"batl":[[0,2.2,28.55],[1,3,42.01],[2,95,15.9]],"ltp":1.6,"tv":142.37,"id":6374165}]}]}
{"op":"mcm","clk":"1003079967","pt":1580575003113,"mc":[{"id":"1.168175448","rc":[{"batb":[[0,2.58,14.01],[1,2.56,43.16],[2,2.54,45.52]],"ltp":2.62,"tv":41.36,"id":5071877},{"batl":[[0,1.61,3.79],[1,2.2,28.55],[2,3,42.01]],"ltp":1.6,"tv":142.37,"id":6374165}]}]}
{"op":"mcm","clk":"1003310187","pt":1580575995239,"mc":[{"id":"1.168175448","rc":[{"trd":[[1.55,3.8]],"batb":[[0,1.55,50.27]],"ltp":1.55,"tv":146.17,"id":6374165}],"tv":187.53}]}
{"op":"mcm","clk":"1003409183","pt":1580576591482,"mc":[{"id":"1.168175448","rc":[{"batb":[[0,2.58,16.76]],"ltp":2.62,"tv":41.36,"id":5071877},{"batb":[[0,1.54,57.75]],"ltp":1.55,"tv":146.17,"id":6374165}]}]}
{"op":"mcm","clk":"1003629772","pt":1580577761700,"mc":[{"id":"1.168175448","rc":[{"batb":[[0,2.8,25.53],[1,2.58,16.76],[2,2.56,43.16]],"ltp":2.62,"tv":41.36,"id":5071877}]}]}
{"op":"mcm","clk":"1003630091","pt":1580577763385,"mc":[{"id":"1.168175448","rc":[{"batb":[[2,1.47,87.39]],"ltp":1.55,"tv":146.17,"id":6374165}]}]}
{"op":"mcm","clk":"1003630239","pt":1580577764083,"mc":[{"id":"1.168175448","rc":[{"batb":[[1,2.66,142.78],[2,2.62,43.16]],"ltp":2.62,"tv":41.36,"id":5071877},{"batb":[[2,1.41,578.09]],"ltp":1.55,"tv":146.17,"id":6374165}]}]}
{"op":"mcm","clk":"1003630878","pt":1580577767510,"mc":[{"id":"1.168175448","rc":[{"trd":[[2.8,47.06]],"batb":[[0,2.8,16.97],[1,2.68,24.74],[2,2.66,142.78]],"ltp":2.8,"tv":58.48,"id":5071877},{"batb":[[0,1.51,41.27],[2,1.43,71.19]],"ltp":1.55,"tv":146.17,"id":6374165}],"tv":204.66}]}
{"op":"mcm","clk":"1003631175","pt":1580577769059,"mc":[{"id":"1.168175448","rc":[{"batb":[[2,1.47,87.39]],"ltp":1.55,"tv":146.17,"id":6374165}]}]}
{"op":"mcm","clk":"1003642561","pt":1580577826380,"mc":[{"id":"1.168175448","rc":[{"batb":[[0,1.51,32.23]],"ltp":1.55,"tv":146.17,"id":6374165}]}]}
{"op":"mcm","clk":"1003642689","pt":1580577826959,"mc":[{"id":"1.168175448","rc":[{"batb":[[0,2.8,265.4],[1,2.68,28.52]],"ltp":2.8,"tv":58.48,"id":5071877},{"batb":[[0,1.51,34.46]],"ltp":1.55,"tv":146.17,"id":6374165}]}]}
{"op":"mcm","clk":"1003647387","pt":1580577849203,"mc":[{"id":"1.168175448","rc":[{"batb":[[1,2.7,24.15],[2,2.68,28.52]],"ltp":2.8,"tv":58.48,"id":5071877},{"batb":[[2,1.44,93.35]],"ltp":1.55,"tv":146.17,"id":6374165}]}]}
{"op":"mcm","clk":"1003660089","pt":1580577908921,"mc":[{"id":"1.168175448","rc":[{"batl":[[0,2.2,28.55],[1,3,42.01],[2,95,15.9]],"ltp":1.55,"tv":146.17,"id":6374165}]}]}
{"op":"mcm","clk":"1003675330","pt":1580577986137,"mc":[{"id":"1.168175448","rc":[{"batb":[[1,2.72,21.01],[2,2.7,24.15]],"ltp":2.8,"tv":58.48,"id":5071877}]}]}
{"op":"mcm","clk":"1003714085","pt":1580578203173,"mc":[{"id":"1.168175448","rc":[{"batb":[[0,2.8,16.97]],"ltp":2.8,"tv":58.48,"id":5071877}]}]}
{"op":"mcm","clk":"1003714869","pt":1580578208541,"mc":[{"id":"1.168175448","rc":[{"batb":[[2,1.44,164.53]],"ltp":1.55,"tv":146.17,"id":6374165}]}]}
{"op":"mcm","clk":"1004087485","pt":1580580375127,"mc":[{"id":"1.168175448","rc":[{"batb":[[0,1.52,3.79],[1,1.51,34.46],[2,1.5,86.02]],"ltp":1.55,"tv":146.17,"id":6374165}]}]}
{"op":"mcm","clk":"1004176159","pt":1580580854305,"mc":[{"id":"1.168175448","rc":[{"batb":[[0,1.51,34.46],[1,1.5,86.02],[2,1.44,164.53]],"ltp":1.55,"tv":146.17,"id":6374165}]}]}
{"op":"mcm","clk":"1004181145","pt":1580580880371,"mc":[{"id":"1.168175448","rc":[{"batb":[[0,1.52,3.79],[1,1.51,34.46],[2,1.5,86.02]],"ltp":1.55,"tv":146.17,"id":6374165}]}]}
{"op":"mcm","clk":"1004218595","pt":1580581077410,"mc":[{"id":"1.168175448","rc":[{"batb":[[0,1.51,34.46],[1,1.5,86.02],[2,1.44,164.53]],"ltp":1.55,"tv":146.17,"id":6374165}]}]}
{"op":"mcm","clk":"1004279862","pt":1580581408132,"mc":[{"id":"1.168175448","rc":[{"batb":[[0,2.82,18.86],[1,2.8,16.97],[2,2.72,21.01]],"ltp":2.8,"tv":58.48,"id":5071877}]}]}
{"op":"mcm","clk":"1004545609","pt":1580582939315,"mc":[{"id":"1.168175448","rc":[{"batb":[[0,2.88,18.86]],"ltp":2.8,"tv":58.48,"id":5071877}]}]}
{"op":"mcm","clk":"1004546100","pt":1580582942130,"mc":[{"id":"1.168175448","rc":[{"batb":[[2,1.44,71.19]],"ltp":1.55,"tv":146.17,"id":6374165}]}]}
{"op":"mcm","clk":"1004552370","pt":1580582983545,"mc":[{"id":"1.168175448","rc":[{"trd":[[2.88,9.11]],"batb":[[0,2.88,14.31]],"ltp":2.88,"tv":67.59,"id":5071877},{"trd":[[1.51,5.07]],"batb":[[0,1.51,31.92]],"ltp":1.51,"tv":151.24,"id":6374165}],"tv":218.83}]}
{"op":"mcm","clk":"1004552467","pt":1580582984177,"mc":[{"id":"1.168175448","rc":[{"batb":[[1,2.82,9.61],[2,2.8,16.97]],"ltp":2.88,"tv":67.59,"id":5071877},{"batb":[[0,1.51,23.33]],"ltp":1.51,"tv":151.24,"id":6374165}]}]}
{"op":"mcm","clk":"1004661943","pt":1580583664501,"mc":[{"id":"1.168175448","rc":[{"batb":[[2,1.41,578.09]],"ltp":1.51,"tv":151.24,"id":6374165}]}]}
{"op":"mcm","clk":"1004661958","pt":1580583664694,"mc":[{"id":"1.168175448","rc":[{"batb":[[2,1.43,71.19]],"ltp":1.51,"tv":151.24,"id":6374165}]}]}
{"op":"mcm","clk":"1004776344","pt":1580584274593,"mc":[{"id":"1.168175448","rc":[{"batb":[[2,1.47,2.28]],"ltp":1.51,"tv":151.24,"id":6374165}]}]}
{"op":"mcm","clk":"1004781938","pt":1580584303663,"mc":[{"id":"1.168175448","rc":[{"batb":[[2,1.47,3.8]],"ltp":1.51,"tv":151.24,"id":6374165}]}]}
{"op":"mcm","clk":"1004784026","pt":1580584314921,"mc":[{"id":"1.168175448","rc":[{"batb":[[2,1.47,5.39]],"ltp":1.51,"tv":151.24,"id":6374165}]}]}
{"op":"mcm","clk":"1004785310","pt":1580584321731,"mc":[{"id":"1.168175448","rc":[{"batb":[[2,1.47,1.6]],"ltp":1.51,"tv":151.24,"id":6374165}]}]}
{"op":"mcm","clk":"1004794821","pt":1580584371670,"mc":[{"id":"1.168175448","rc":[{"batl":[[0,3,42.54],[1,95,15.9],[2,990,2.2]],"ltp":1.51,"tv":151.24,"id":6374165}]}]}
{"op":"mcm","clk":"1004800285","pt":1580584399713,"mc":[{"id":"1.168175448","rc":[{"batl":[[0,2.98,3.89],[1,3,42.01],[2,95,15.9]],"ltp":1.51,"tv":151.24,"id":6374165}]}]}
{"op":"mcm","clk":"1004929326","pt":1580585069475,"mc":[{"id":"1.168175448","rc":[{"batb":[[0,1.51,152.72]],"batl":[[0,1.54,126.87],[1,2.98,3.89],[2,3,42.01]],"ltp":1.51,"tv":151.24,"id":6374165}]}]}
{"op":"mcm","clk":"1004929729","pt":1580585071751,"mc":[{"id":"1.168175448","rc":[{"trd":[[1.54,20.14]],"batl":[[0,1.54,116.8]],"ltp":1.54,"tv":171.38,"id":6374165}],"tv":238.98}]}
{"op":"mcm","clk":"1004934720","pt":1580585102355,"mc":[{"id":"1.168175448","rc":[{"batl":[[1,3,42.54],[2,95,15.9]],"ltp":1.54,"tv":171.38,"id":6374165}]}]}
{"op":"mcm","clk":"1004998304","pt":1580585490906,"mc":[{"id":"1.168175448","rc":[{"batl":[[0,2.92,200],[1,16.5,3.36],[2,95,15.9]],"ltp":2.88,"tv":67.59,"id":5071877}]}]}
{"op":"mcm","clk":"1004998450","pt":1580585491776,"mc":[{"id":"1.168175448","rc":[{"batl":[[1,95,15.9],[2,990,2.2]],"ltp":2.88,"tv":67.59,"id":5071877}]}]}
{"op":"mcm","clk":"1005081437","pt":1580585995212,"mc":[{"id":"1.168175448","rc":[{"trd":[[2.92,200]],"batl":[[0,95,15.9],[1,990,2.2],[2,1000,0.02]],"ltp":2.92,"tv":267.59,"id":5071877},{"trd":[[1.5,172.04],[1.51,310.51],[1.52,384.21]],"batb":[[0,1.47,1.6],[1,1.43,71.18],[2,1.41,578.08]],"ltp":1.5,"tv":1033.08,"id":6374165}],"tv":1300.67}]}
{"op":"mcm","clk":"1005081517","pt":1580585995730,"mc":[{"id":"1.168175448","rc":[{"batb":[[1,2.82,21.89]],"ltp":2.92,"tv":267.59,"id":5071877},{"batb":[[1,1.46,58.98],[2,1.43,71.18]],"ltp":1.5,"tv":1033.08,"id":6374165}]}]}
{"op":"mcm","clk":"1005081942","pt":1580585998097,"mc":[{"id":"1.168175448","rc":[{"batb":[[1,2.86,3.92],[2,2.82,21.89]],"batl":[[0,3.15,3.56],[1,95,15.9],[2,990,2.2]],"ltp":2.92,"tv":267.59,"id":5071877},{"batb":[[0,1.47,9.22]],"batl":[[0,1.53,7.32],[1,1.54,116.8],[2,3,42.54]],"ltp":1.5,"tv":1033.08,"id":6374165}]}]}
{"op":"mcm","clk":"1005082094","pt":1580585999141,"mc":[{"id":"1.168175448","rc":[{"batb":[[2,1.44,93.34]],"ltp":1.5,"tv":1033.08,"id":6374165}]}]}
{"op":"mcm","clk":"1005084075","pt":1580586011250,"mc":[{"id":"1.168175448","rc":[{"batb":[[0,2.9,23.06],[1,2.88,14.31],[2,2.86,3.92]],"ltp":2.92,"tv":267.59,"id":5071877},{"batb":[[1,1.45,43.78]],"ltp":1.5,"tv":1033.08,"id":6374165}]}]}
{"op":"mcm","clk":"1005085895","pt":1580586022155,"mc":[{"id":"1.168175448","rc":[{"batl":[[0,3.25,3.56]],"ltp":2.92,"tv":267.59,"id":5071877},{"batb":[[0,1.47,1.6],[1,1.45,51.4]],"ltp":1.5,"tv":1033.08,"id":6374165}]}]}
{"op":"mcm","clk":"1005090294","pt":1580586050060,"mc":[{"id":"1.168175448","rc":[{"trd":[[1.53,11.14]],"batl":[[0,1.53,1.75]],"ltp":1.53,"tv":1044.22,"id":6374165}],"tv":1311.82}]}
{"op":"mcm","clk":"1005090772","pt":1580586053097,"mc":[{"id":"1.168175448","rc":[{"batb":[[1,1.45,49.66]],"ltp":1.53,"tv":1044.22,"id":6374165}]}]}
{"op":"mcm","clk":"1005092246","pt":1580586062540,"mc":[{"id":"1.168175448","rc":[{"batb":[[2,2.86,6.03]],"batl":[[1,3.35,2.1],[2,3.4,2.04]],"ltp":2.92,"tv":267.59,"id":5071877},{"batl":[[2,1.56,2.01]],"ltp":1.53,"tv":1044.22,"id":6374165}]}]}
{"op":"mcm","clk":"1005095358","pt":1580586082545,"mc":[{"id":"1.168175448","rc":[{"batb":[[0,2.92,3.92],[1,2.9,23.06],[2,2.88,16.31]],"batl":[[2,95,15.9]],"ltp":2.92,"tv":267.59,"id":5071877},{"batl":[[2,1.55,2.01]],"ltp":1.53,"tv":1044.22,"id":6374165}]}]}
{"op":"mcm","clk":"1005095417","pt":1580586082961,"mc":[{"id":"1.168175448","rc":[{"batl":[[2,3.4,2.04]],"ltp":2.92,"tv":267.59,"id":5071877}]}]}
{"op":"mcm","clk":"1005096259","pt":1580586088472,"mc":[{"id":"1.168175448","rc":[{"batl":[[1,3.3,2.05],[2,95,15.9]],"ltp":2.92,"tv":267.59,"id":5071877},{"batb":[[1,1.46,129.39],[2,1.45,49.66]],"batl":[[1,1.54,239.46]],"ltp":1.53,"tv":1044.22,"id":6374165}]}]}
{"op":"mcm","clk":"1005096276","pt":1580586088594,"mc":[{"id":"1.168175448","rc":[{"batl":[[2,3.35,2.1]],"ltp":2.92,"tv":267.59,"id":5071877}]}]}
{"op":"mcm","clk":"1005098502","pt":1580586103531,"mc":[{"id":"1.168175448","rc":[{"batb":[[0,2.9,26.98],[1,2.88,14.31],[2,2.86,2.18]],"batl":[[0,3.3,2.05],[1,95,15.9],[2,990,2.2]],"ltp":2.92,"tv":267.59,"id":5071877}]}]}
{"op":"mcm","clk":"1005098537","pt":1580586103764,"mc":[{"id":"1.168175448","rc":[{"batl":[[1,3.35,2.1],[2,95,15.9]],"ltp":2.92,"tv":267.59,"id":5071877}]}]}
{"op":"mcm","clk":"1005101241","pt":1580586121495,"mc":[{"id":"1.168175448","rc":[{"batl":[[1,95,15.9],[2,990,2.2]],"ltp":2.92,"tv":267.59,"id":5071877},{"batb":[[0,1.47,7.48],[2,1.45,43.78]],"ltp":1.53,"tv":1044.22,"id":6374165}]}]}
{"op":"mcm","clk":"1005101341","pt":1580586122078,"mc":[{"id":"1.168175448","rc":[{"batl":[[0,3.25,2.02],[1,3.3,2.02],[2,95,15.9]],"ltp":2.92,"tv":267.59,"id":5071877},{"batb":[[2,1.45,45.79]],"ltp":1.53,"tv":1044.22,"id":6374165}]}]}
{"op":"mcm","clk":"1005102896","pt":1580586132211,"mc":[{"id":"1.168175448","rc":[{"batl":[[1,3.3,2]],"ltp":2.92,"tv":267.59,"id":5071877},{"trd":[[1.53,14.5]],"batl":[[0,1.54,239.53],[1,1.55,2.1],[2,1.56,2.01]],"ltp":1.53,"tv":1047.58,"id":6374165}],"tv":1315.17}]}
{"op":"mcm","clk":"1005103698","pt":1580586137416,"mc":[{"id":"1.168175448","rc":[{"batb":[[0,1.47,26.02],[2,1.45,2.01]],"ltp":1.53,"tv":1047.58,"id":6374165}]}]}
{"op":"mcm","clk":"1005107544","pt":1580586161531,"mc":[{"id":"1.168175448","rc":[{"batl":[[1,95,15.9],[2,990,2.2]],"ltp":2.92,"tv":267.59,"id":5071877},{"batb":[[0,1.47,27.68]],"batl":[[2,3,42.54]],"ltp":1.53,"tv":1047.58,"id":6374165}]}]}
{"op":"mcm","clk":"1005107577","pt":1580586161699,"mc":[{"id":"1.168175448","rc":[{"batl":[[1,3.3,2.05],[2,95,15.9]],"ltp":2.92,"tv":267.59,"id":5071877},{"batl":[[2,1.56,2]],"ltp":1.53,"tv":1047.58,"id":6374165}]}]}
{"op":"mcm","clk":"1005112576","pt":1580586191298,"mc":[{"id":"1.168175448","rc":[{"batl":[[0,3.15,3.56],[1,3.25,2.02],[2,3.3,2.05]],"ltp":2.92,"tv":267.59,"id":5071877}]}]}
{"op":"mcm","clk":"1005112645","pt":1580586191762,"mc":[{"id":"1.168175448","rc":[{"batl":[[2,1.56,2.01]],"ltp":1.53,"tv":1047.58,"id":6374165}]}]}
{"op":"mcm","clk":"1005119414","pt":1580586234258,"mc":[{"id":"1.168175448","rc":[{"batl":[[0,1.53,7.32],[1,1.54,239.46],[2,1.55,2.1]],"ltp":1.53,"tv":1047.58,"id":6374165}]}]}
{"op":"mcm","clk":"1005129033","pt":1580586296532,"mc":[{"id":"1.168175448","rc":[{"batl":[[2,95,15.9]],"ltp":2.92,"tv":267.59,"id":5071877}]}]}
{"op":"mcm","clk":"1005129051","pt":1580586296641,"mc":[{"id":"1.168175448","rc":[{"batl":[[2,3.3,2.02]],"ltp":2.92,"tv":267.59,"id":5071877}]}]}
{"op":"mcm","clk":"1005131312","pt":1580586310201,"mc":[{"id":"1.168175448","rc":[{"batb":[[2,2.84,2.22]],"ltp":2.92,"tv":267.59,"id":5071877},{"batb":[[2,1.44,95.35]],"ltp":1.53,"tv":1047.58,"id":6374165}]}]}
{"op":"mcm","clk":"1005131395","pt":1580586310883,"mc":[{"id":"1.168175448","rc":[{"batl":[[1,3.3,2.02],[2,95,15.9]],"ltp":2.92,"tv":267.59,"id":5071877},{"batl":[[2,1.56,2.01]],"ltp":1.53,"tv":1047.58,"id":6374165}]}]}
{"op":"mcm","clk":"1005131663","pt":1580586312535,"mc":[{"id":"1.168175448","rc":[{"batb":[[2,1.44,93.34]],"ltp":1.53,"tv":1047.58,"id":6374165}]}]}
{"op":"mcm","clk":"1005131744","pt":1580586313105,"mc":[{"id":"1.168175448","rc":[{"batb":[[2,2.8,16.97]],"batl":[[1,95,15.9],[2,990,2.2]],"ltp":2.92,"tv":267.59,"id":5071877},{"batl":[[2,3,42.54]],"ltp":1.53,"tv":1047.58,"id":6374165}]}]}
{"op":"mcm","clk":"1005152187","pt":1580586449205,"mc":[{"id":"1.168175448","rc":[{"batb":[[2,2.86,2.18]],"batl":[[1,3.25,2.02],[2,3.3,2.05]],"ltp":2.92,"tv":267.59,"id":5071877},{"batb":[[2,1.45,2.01]],"batl":[[2,1.55,2.1]],"ltp":1.53,"tv":1047.58,"id":6374165}]}]}
{"op":"mcm","clk":"1005235118","pt":1580587025485,"mc":[{"id":"1.168175448","rc":[{"batb":[[0,2.9,23.06]],"batl":[[0,3.3,2.05],[1,3.35,2.1],[2,95,15.9]],"ltp":2.92,"tv":267.59,"id":5071877},{"batb":[[0,1.47,20.13]],"batl":[[0,1.54,239.46],[1,1.56,2.01],[2,1.57,2.01]],"ltp":1.53,"tv":1047.58,"id":6374165}]}]}
{"op":"mcm","clk":"1005235223","pt":1580587026182,"mc":[{"id":"1.168175448","rc":[{"batl":[[0,3.25,2.02],[1,3.3,2],[2,3.35,2.1]],"ltp":2.92,"tv":267.59,"id":5071877},{"batl":[[1,1.55,2.1],[2,1.56,2.17]],"ltp":1.53,"tv":1047.58,"id":6374165}]}]}
{"op":"mcm","clk":"1005239953","pt":1580587061534,"mc":[{"id":"1.168175448","rc":[{"batb":[[0,2.9,26.92]],"batl":[[0,3.15,3.56],[1,3.25,2.02],[2,95,15.9]],"ltp":2.92,"tv":267.59,"id":5071877},{"batb":[[0,1.47,27.68]],"batl":[[0,1.53,7.32],[1,1.54,239.46],[2,1.55,2.1]],"ltp":1.53,"tv":1047.58,"id":6374165}]}]}
{"op":"mcm","clk":"1005239999","pt":1580587061839,"mc":[{"id":"1.168175448","rc":[{"batl":[[2,3.3,2.05]],"ltp":2.92,"tv":267.59,"id":5071877}]}]}
{"op":"mcm","clk":"1005259092","pt":1580587200491,"mc":[{"id":"1.168175448","rc":[{"batl":[[2,95,15.9]],"ltp":2.92,"tv":267.59,"id":5071877}]}]}
{"op":"mcm","clk":"1005259131","pt":1580587200707,"mc":[{"id":"1.168175448","rc":[{"batl":[[2,3.3,2.05]],"ltp":2.92,"tv":267.59,"id":5071877}]}]}
{"op":"mcm","clk":"1005261757","pt":1580587215523,"mc":[{"id":"1.168175448","rc":[{"batb":[[2,2.84,2.22]],"batl":[[1,3.3,2.05],[2,95,15.9]],"ltp":2.92,"tv":267.59,"id":5071877},{"batb":[[2,1.44,73.35]],"batl":[[2,1.56,2.01]],"ltp":1.53,"tv":1047.58,"id":6374165}]}]}
{"op":"mcm","clk":"1005261877","pt":1580587216240,"mc":[{"id":"1.168175448","rc":[{"batb":[[2,2.8,16.97]],"batl":[[1,95,15.9],[2,990,2.2]],"ltp":2.92,"tv":267.59,"id":5071877},{"batb":[[2,1.44,71.18]],"batl":[[2,3,42.54]],"ltp":1.53,"tv":1047.58,"id":6374165}]}]}
{"op":"mcm","clk":"1005261952","pt":1580587216713,"mc":[{"id":"1.168175448","rc":[{"batl":[[0,1.53,175.36]],"ltp":1.53,"tv":1047.58,"id":6374165}]}]}
{"op":"mcm","clk":"1005271760","pt":1580587289520,"mc":[{"id":"1.168175448","rc":[{"batl":[[0,1.52,7.32],[1,1.53,168.04],[2,1.54,239.46]],"ltp":1.53,"tv":1047.58,"id":6374165}]}]}
{"op":"mcm","clk":"1005275264","pt":1580587314961,"mc":[{"id":"1.168175448","rc":[{"batl":[[0,1.52,9.82]],"ltp":1.53,"tv":1047.58,"id":6374165}]}]}
{"op":"mcm","clk":"1005275389","pt":1580587315872,"mc":[{"id":"1.168175448","rc":[{"trd":[[1.52,398.65]],"batl":[[0,1.52,2.61]],"ltp":1.52,"tv":1062.01,"id":6374165}],"tv":1329.61}]}
{"op":"mcm","clk":"1005275602","pt":1580587317482,"mc":[{"id":"1.168175448","rc":[{"batb":[[0,1.47,35.14]],"ltp":1.52,"tv":1062.01,"id":6374165}]}]}
{"op":"mcm","clk":"1005275656","pt":1580587317858,"mc":[{"id":"1.168175448","rc":[{"batl":[[0,95,15.9],[1,990,2.2],[2,1000,3.58]],"ltp":2.92,"tv":267.59,"id":5071877},{"batl":[[0,1.51,2.5],[1,1.53,168.15]],"ltp":1.52,"tv":1062.01,"id":6374165}]}]}
{"op":"mcm","clk":"1005276185","pt":1580587321484,"mc":[{"id":"1.168175448","rc":[{"batl":[[0,1.5,2.5]],"ltp":1.52,"tv":1062.01,"id":6374165}]}]}
{"op":"mcm","clk":"1005276654","pt":1580587324379,"mc":[{"id":"1.168175448","rc":[{"batl":[[0,1.49,2.5]],"ltp":1.52,"tv":1062.01,"id":6374165}]}]}
{"op":"mcm","clk":"1005277031","pt":1580587326823,"mc":[{"id":"1.168175448","rc":[{"trd":[[1.48,0.02]],"batb":[[0,1.47,35.13]],"batl":[[0,1.48,2.49]],"ltp":1.48,"tv":1062.03,"id":6374165}],"tv":1329.63}]}
{"op":"mcm","clk":"1005277798","pt":1580587331822,"mc":[{"id":"1.168175448","rc":[{"trd":[[1.47,4.98]],"batb":[[0,1.47,32.64]],"batl":[[0,1.53,168.15],[1,1.54,239.46],[2,3,42.54]],"ltp":1.47,"tv":1067.01,"id":6374165}],"tv":1334.6}]}
{"op":"mcm","clk":"1005278141","pt":1580587334333,"mc":[{"id":"1.168175448","rc":[{"batb":[[2,2.86,2.11]],"batl":[[0,3.25,2.02],[1,3.3,2.05],[2,95,15.9]],"ltp":2.92,"tv":267.59,"id":5071877},{"batb":[[0,1.47,39.02],[2,1.45,2.01]],"batl":[[2,1.55,2.1]],"ltp":1.47,"tv":1067.01,"id":6374165}]}]}
{"op":"mcm","clk":"1005286678","pt":1580587392173,"mc":[{"id":"1.168175448","rc":[{"batb":[[0,2.9,23.06]],"ltp":2.92,"tv":267.59,"id":5071877},{"batb":[[0,1.47,24.02]],"batl":[[0,1.53,168.04]],"ltp":1.47,"tv":1067.01,"id":6374165}]}]}
{"op":"mcm","clk":"1005288108","pt":1580587401500,"mc":[{"id":"1.168175448","rc":[{"batb":[[0,2.9,26.92]],"batl":[[0,3.15,3.56],[1,3.25,2.02],[2,3.3,2.05]],"ltp":2.92,"tv":267.59,"id":5071877},{"batb":[[0,1.47,39.02]],"ltp":1.47,"tv":1067.01,"id":6374165}]}]}
{"op":"mcm","clk":"1005288186","pt":1580587401981,"mc":[{"id":"1.168175448","rc":[{"batl":[[0,1.53,168.19]],"ltp":1.47,"tv":1067.01,"id":6374165}]}]}
{"op":"mcm","clk":"1005300249","pt":1580587477384,"mc":[{"id":"1.168175448","rc":[{"batl":[[0,3,61.17],[1,3.1,2.05],[2,3.15,5.6]],"ltp":2.92,"tv":267.59,"id":5071877}]}]}
{"op":"mcm","clk":"1005300349","pt":1580587477987,"mc":[{"id":"1.168175448","rc":[{"batb":[[0,1.48,2.01],[1,1.47,41.03],[2,1.46,129.39]],"batl":[[0,1.53,168.04]],"ltp":1.47,"tv":1067.01,"id":6374165}]}]}
{"op":"mcm","clk":"1005301165","pt":1580587482500,"mc":[{"id":"1.168175448","rc":[{"batl":[[1,3.05,2.1],[2,3.1,2.05]],"ltp":2.92,"tv":267.59,"id":5071877},{"trd":[[1.51,340.54]],"batb":[[1,1.47,26.03]],"ltp":1.51,"tv":1097.03,"id":6374165}],"tv":1364.63}]}
{"op":"mcm","clk":"1005301272","pt":1580587483197,"mc":[{"id":"1.168175448","rc":[{"batl":[[1,3.1,2.05],[2,3.15,2.1]],"ltp":2.92,"tv":267.59,"id":5071877}]}]}
{"op":"mcm","clk":"1005302364","pt":1580587489390,"mc":[{"id":"1.168175448","rc":[{"batl":[[2,95,15.9]],"ltp":2.92,"tv":267.59,"id":5071877},{"batb":[[1,1.47,17.64]],"ltp":1.51,"tv":1097.03,"id":6374165}]}]}
{"op":"mcm","clk":"1005302391","pt":1580587489608,"mc":[{"id":"1.168175448","rc":[{"batl":[[2,3.15,2]],"ltp":2.92,"tv":267.59,"id":5071877},{"batb":[[1,1.47,19.65]],"ltp":1.51,"tv":1097.03,"id":6374165}]}]}
{"op":"mcm","clk":"1005319659","pt":1580587590430,"mc":[{"id":"1.168175448","rc":[{"trd":[[3,8.62]],"batl":[[0,3,52.55],[2,95,15.9]],"ltp":3.0,"tv":276.21,"id":5071877},{"trd":[[1.5,189.27]],"batb":[[1,1.47,17.64]],"ltp":1.5,"tv":1114.27,"id":6374165}],"tv":1390.48}]}
{"op":"mcm","clk":"1005319686","pt":1580587590643,"mc":[{"id":"1.168175448","rc":[{"batl":[[2,3.15,2.1]],"ltp":3.0,"tv":276.21,"id":5071877},{"batb":[[1,1.47,19.65]],"ltp":1.5,"tv":1114.27,"id":6374165}]}]}
{"op":"mcm","clk":"1005320041","pt":1580587592723,"mc":[{"id":"1.168175448","rc":[{"batb":[[0,2.9,18.64]],"ltp":3.0,"tv":276.21,"id":5071877},{"batb":[[1,1.47,37.1]],"ltp":1.5,"tv":1114.27,"id":6374165}]}]}
{"op":"mcm","clk":"1005343898","pt":1580587733495,"mc":[{"id":"1.168175448","rc":[{"trd":[[2.9,33.6]],"batb":[[0,2.9,1.84],[2,2.84,2.22]],"ltp":2.9,"tv":309.81,"id":5071877},{"batb":[[0,1.51,17.23],[1,1.48,2.01],[2,1.47,2.01]],"ltp":1.5,"tv":1114.27,"id":6374165}],"tv":1424.08}]}
{"op":"mcm","clk":"1005344031","pt":1580587734407,"mc":[{"id":"1.168175448","rc":[{"trd":[[1.51,374.95]],"batb":[[0,1.48,2.01],[1,1.47,2.01],[2,1.46,129.39]],"ltp":1.51,"tv":1148.68,"id":6374165}],"tv":1458.5}]}
{"op":"mcm","clk":"1005344168","pt":1580587735326,"mc":[{"id":"1.168175448","rc":[{"batb":[[0,2.9,10.88],[2,2.86,2.18]],"ltp":2.9,"tv":309.81,"id":5071877},{"batb":[[0,1.48,36.32]],"ltp":1.51,"tv":1148.68,"id":6374165}]}]}
{"op":"mcm","clk":"1005344691","pt":1580587738237,"mc":[{"id":"1.168175448","rc":[{"batl":[[0,2.98,1.97],[1,3,52.55],[2,3.1,2.05]],"ltp":2.9,"tv":309.81,"id":5071877}]}]}
{"op":"mcm","clk":"1005379692","pt":1580587942383,"mc":[{"id":"1.168175448","rc":[{"batl":[[2,3.05,2.1]],"ltp":2.9,"tv":309.81,"id":5071877},{"batb":[[0,1.51,74.21],[1,1.49,2.01],[2,1.48,34.31]],"ltp":1.51,"tv":1148.68,"id":6374165}]}]}
{"op":"mcm","clk":"1005379861","pt":1580587943358,"mc":[{"id":"1.168175448","rc":[{"batb":[[0,1.51,81.62],[2,1.48,36.32]],"ltp":1.51,"tv":1148.68,"id":6374165}]}]}
{"op":"mcm","clk":"1005380366","pt":1580587946367,"mc":[{"id":"1.168175448","rc":[{"batl":[[0,2.96,1.97],[2,3.1,2.05]],"ltp":2.9,"tv":309.81,"id":5071877}]}]}
{"op":"mcm","clk":"1005380400","pt":1580587946575,"mc":[{"id":"1.168175448","rc":[{"batl":[[2,3.05,2.1]],"ltp":2.9,"tv":309.81,"id":5071877}]}]}
{"op":"mcm","clk":"1005382575","pt":1580587959434,"mc":[{"id":"1.168175448","rc":[{"batb":[[0,1.51,74.21],[2,1.48,34.31]],"ltp":1.51,"tv":1148.68,"id":6374165}]}]}
{"op":"mcm","clk":"1005382610","pt":1580587959604,"mc":[{"id":"1.168175448","rc":[{"batb":[[2,1.48,36.32]],"ltp":1.51,"tv":1148.68,"id":6374165}]}]}
{"op":"mcm","clk":"1005392267","pt":1580588014459,"mc":[{"id":"1.168175448","rc":[{"batb":[[2,1.48,2.01]],"ltp":1.51,"tv":1148.68,"id":6374165}]}]}
{"op":"mcm","clk":"1005469067","pt":1580588459438,"mc":[{"id":"1.168175448","rc":[{"batb":[[2,1.47,46.45]],"ltp":1.51,"tv":1148.68,"id":6374165}]}]}
{"op":"mcm","clk":"1005469103","pt":1580588459607,"mc":[{"id":"1.168175448","rc":[{"batb":[[2,1.48,2.01]],"ltp":1.51,"tv":1148.68,"id":6374165}]}]}
{"op":"mcm","clk":"1005479284","pt":1580588524514,"mc":[{"id":"1.168175448","rc":[{"batb":[[2,1.47,46.45]],"ltp":1.51,"tv":1148.68,"id":6374165}]}]}
{"op":"mcm","clk":"1005479325","pt":1580588524727,"mc":[{"id":"1.168175448","rc":[{"batb":[[2,1.48,2]],"ltp":1.51,"tv":1148.68,"id":6374165}]}]}
{"op":"mcm","clk":"1005528694","pt":1580588844260,"mc":[{"id":"1.168175448","rc":[{"batl":[[1,3.05,2.1],[2,3.1,2.05]],"ltp":2.9,"tv":309.81,"id":5071877},{"batb":[[2,1.48,2.01]],"ltp":1.51,"tv":1148.68,"id":6374165}]}]}
{"op":"mcm","clk":"1005529930","pt":1580588852482,"mc":[{"id":"1.168175448","rc":[{"batl":[[0,2.96,50.65],[1,3,2],[2,3.05,2.1]],"ltp":2.9,"tv":309.81,"id":5071877},{"batb":[[2,1.47,46.45]],"ltp":1.51,"tv":1148.68,"id":6374165}]}]}
{"op":"mcm","clk":"1005529987","pt":1580588852859,"mc":[{"id":"1.168175448","rc":[{"batb":[[2,1.48,2.01]],"ltp":1.51,"tv":1148.68,"id":6374165}]}]}
{"op":"mcm","clk":"1005535109","pt":1580588884396,"mc":[{"id":"1.168175448","rc":[{"trd":[[1.53,24.64]],"batl":[[0,1.53,162.97]],"ltp":1.53,"tv":1158.82,"id":6374165}],"tv":1468.63}]}
{"op":"mcm","clk":"1005546841","pt":1580588957494,"mc":[{"id":"1.168175448","rc":[{"batb":[[2,1.47,46.45]],"ltp":1.53,"tv":1158.82,"id":6374165}]}]}
{"op":"mcm","clk":"1005546886","pt":1580588957748,"mc":[{"id":"1.168175448","rc":[{"batb":[[2,1.48,2.01]],"ltp":1.53,"tv":1158.82,"id":6374165}]}]}
{"op":"mcm","clk":"1005550161","pt":1580588977894,"mc":[{"id":"1.168175448","rc":[{"batl":[[2,3.05,2]],"ltp":2.9,"tv":309.81,"id":5071877}]}]}
{"op":"mcm","clk":"1005560302","pt":1580589038486,"mc":[{"id":"1.168175448","rc":[{"batl":[[2,95,15.9]],"ltp":2.9,"tv":309.81,"id":5071877},{"batb":[[2,1.47,46.45]],"ltp":1.53,"tv":1158.82,"id":6374165}]}]}
{"op":"mcm","clk":"1005560344","pt":1580589038704,"mc":[{"id":"1.168175448","rc":[{"batl":[[2,3.05,2.1]],"ltp":2.9,"tv":309.81,"id":5071877},{"batb":[[2,1.48,2.01]],"ltp":1.53,"tv":1158.82,"id":6374165}]}]}
{"op":"mcm","clk":"1005612503","pt":1580589365483,"mc":[{"id":"1.168175448","rc":[{"batl":[[2,95,15.9]],"ltp":2.9,"tv":309.81,"id":5071877},{"batb":[[2,1.47,46.45]],"ltp":1.53,"tv":1158.82,"id":6374165}]}]}
{"op":"mcm","clk":"1005612540","pt":1580589365649,"mc":[{"id":"1.168175448","rc":[{"batl":[[2,3.05,2]],"ltp":2.9,"tv":309.81,"id":5071877},{"batb":[[2,1.48,2.01]],"ltp":1.53,"tv":1158.82,"id":6374165}]}]}
{"op":"mcm","clk":"1005620306","pt":1580589419559,"mc":[{"id":"1.168175448","rc":[{"batl":[[2,95,15.9]],"ltp":2.9,"tv":309.81,"id":5071877},{"batb":[[2,1.47,46.45]],"ltp":1.53,"tv":1158.82,"id":6374165}]}]}
{"op":"mcm","clk":"1005620327","pt":1580589419773,"mc":[{"id":"1.168175448","rc":[{"batl":[[2,3.05,2.1]],"ltp":2.9,"tv":309.81,"id":5071877},{"batb":[[2,1.48,2]],"ltp":1.53,"tv":1158.82,"id":6374165}]}]}
{"op":"mcm","clk":"1005628689","pt":1580589476462,"mc":[{"id":"1.168175448","rc":[{"batl":[[2,95,15.9]],"ltp":2.9,"tv":309.81,"id":5071877},{"trd":[[1.53,64.9]],"batb":[[2,1.47,46.45]],"batl":[[0,1.53,142.84]],"ltp":1.53,"tv":1199.08,"id":6374165}],"tv":1508.9}]}
{"op":"mcm","clk":"1005628730","pt":1580589476668,"mc":[{"id":"1.168175448","rc":[{"batl":[[2,3.05,2]],"ltp":2.9,"tv":309.81,"id":5071877},{"batb":[[2,1.48,2.01]],"ltp":1.53,"tv":1199.08,"id":6374165}]}]}
{"op":"mcm","clk":"1005640303","pt":1580589555246,"mc":[{"id":"1.168175448","rc":[{"batl":[[2,3.05,2.1]],"ltp":2.9,"tv":309.81,"id":5071877},{"trd":[[1.53,74.9]],"batl":[[0,1.53,137.84]],"ltp":1.53,"tv":1209.08,"id":6374165}],"tv":1518.9}]}
{"op":"mcm","clk":"1005645231","pt":1580589588458,"mc":[{"id":"1.168175448","rc":[{"batb":[[2,1.48,2]],"ltp":1.53,"tv":1209.08,"id":6374165}]}]}
{"op":"mcm","clk":"1005645456","pt":1580589590147,"mc":[{"id":"1.168175448","rc":[{"trd":[[2.96,13.44]],"batl":[[0,2.96,43.93]],"ltp":2.96,"tv":323.25,"id":5071877}],"tv":1532.34}]}
{"op":"mcm","clk":"1005646008","pt":1580589594372,"mc":[{"id":"1.168175448","rc":[{"batb":[[0,2.92,14.31],[1,2.9,10.88]],"ltp":2.96,"tv":323.25,"id":5071877}]}]}
{"op":"mcm","clk":"1005646153","pt":1580589595270,"mc":[{"id":"1.168175448","rc":[{"batb":[[2,2.88,2.05]],"ltp":2.96,"tv":323.25,"id":5071877},{"batb":[[2,1.48,2.01]],"ltp":1.53,"tv":1209.08,"id":6374165}]}]}
{"op":"mcm","clk":"1005655754","pt":1580589660639,"mc":[{"id":"1.168175448","rc":[{"trd":[[2.92,224.3]],"batb":[[0,2.92,2.16]],"ltp":2.92,"tv":347.55,"id":5071877}],"tv":1556.64}]}
{"op":"mcm","clk":"1005659898","pt":1580589687553,"mc":[{"id":"1.168175448","rc":[{"batl":[[2,95,15.9]],"ltp":2.92,"tv":347.55,"id":5071877},{"batb":[[2,1.47,46.45]],"ltp":1.53,"tv":1209.08,"id":6374165}]}]}
{"op":"mcm","clk":"1005659931","pt":1580589687711,"mc":[{"id":"1.168175448","rc":[{"batl":[[2,3.05,2.1]],"ltp":2.92,"tv":347.55,"id":5071877},{"batb":[[2,1.48,2.01]],"ltp":1.53,"tv":1209.08,"id":6374165}]}]}
{"op":"mcm","clk":"1005661487","pt":1580589698566,"mc":[{"id":"1.168175448","rc":[{"batl":[[2,95,15.9]],"ltp":2.92,"tv":347.55,"id":5071877},{"batb":[[2,1.47,46.45]],"ltp":1.53,"tv":1209.08,"id":6374165}]}]}
{"op":"mcm","clk":"1005661595","pt":1580589699362,"mc":[{"id":"1.168175448","rc":[{"batl":[[2,3.05,2.1]],"ltp":2.92,"tv":347.55,"id":5071877},{"batb":[[2,1.48,2]],"ltp":1.53,"tv":1209.08,"id":6374165}]}]}
{"op":"mcm","clk":"1005662318","pt":1580589704752,"mc":[{"id":"1.168175448","rc":[{"batb":[[2,1.48,2.01]],"ltp":1.53,"tv":1209.08,"id":6374165}]}]}
{"op":"mcm","clk":"1005682398","pt":1580589847524,"mc":[{"id":"1.168175448","rc":[{"batl":[[2,95,15.9]],"ltp":2.92,"tv":347.55,"id":5071877},{"batb":[[2,1.47,46.45]],"ltp":1.53,"tv":1209.08,"id":6374165}]}]}
{"op":"mcm","clk":"1005682425","pt":1580589847724,"mc":[{"id":"1.168175448","rc":[{"batl":[[2,3.05,2]],"ltp":2.92,"tv":347.55,"id":5071877},{"batb":[[2,1.48,2.01]],"ltp":1.53,"tv":1209.08,"id":6374165}]}]}
{"op":"mcm","clk":"1005688370","pt":1580589889479,"mc":[{"id":"1.168175448","rc":[{"batb":[[2,1.48,2]],"ltp":1.53,"tv":1209.08,"id":6374165}]}]}
{"op":"mcm","clk":"1005692171","pt":1580589918443,"mc":[{"id":"1.168175448","rc":[{"trd":[[2.96,17.44]],"batl":[[0,2.96,41.93]],"ltp":2.96,"tv":351.55,"id":5071877}],"tv":1560.64}]}
{"op":"mcm","clk":"1005692236","pt":1580589918923,"mc":[{"id":"1.168175448","rc":[{"batl":[[2,3.05,2.1]],"ltp":2.96,"tv":351.55,"id":5071877},{"batb":[[2,1.48,2.01]],"ltp":1.53,"tv":1209.08,"id":6374165}]}]}
{"op":"mcm","clk":"1005724372","pt":1580590177424,"mc":[{"id":"1.168175448","rc":[{"batl":[[0,1.53,198.62]],"ltp":1.53,"tv":1209.08,"id":6374165}]}]}
{"op":"mcm","clk":"1005727804","pt":1580590208078,"mc":[{"id":"1.168175448","rc":[{"batb":[[1,2.9,9.04]],"batl":[[2,3.05,2]],"ltp":2.96,"tv":351.55,"id":5071877}]}]}
{"op":"mcm","clk":"1005727873","pt":1580590208766,"mc":[{"id":"1.168175448","rc":[{"trd":[[1.53,85.7]],"batl":[[0,1.53,193.22]],"ltp":1.53,"tv":1219.88,"id":6374165}],"tv":1571.44}]}
{"op":"mcm","clk":"1005728857","pt":1580590217273,"mc":[{"id":"1.168175448","rc":[{"batb":[[1,2.9,12.9]],"batl":[[2,3.05,4.1]],"ltp":2.96,"tv":351.55,"id":5071877},{"batb":[[2,1.48,4.02]],"ltp":1.53,"tv":1219.88,"id":6374165}]}]}
{"op":"mcm","clk":"1005730545","pt":1580590230905,"mc":[{"id":"1.168175448","rc":[{"batl":[[2,3.05,2.1]],"ltp":2.96,"tv":351.55,"id":5071877},{"batb":[[2,1.48,2.01]],"ltp":1.53,"tv":1219.88,"id":6374165}]}]}
{"op":"mcm","clk":"1005768551","pt":1580590592464,"mc":[{"id":"1.168175448","rc":[{"batb":[[1,2.9,9.04]],"batl":[[2,95,15.9]],"ltp":2.96,"tv":351.55,"id":5071877},{"batb":[[2,1.47,46.45]],"ltp":1.53,"tv":1219.88,"id":6374165}]}]}
{"op":"mcm","clk":"1005768571","pt":1580590592671,"mc":[{"id":"1.168175448","rc":[{"batl":[[2,3.05,2.1]],"ltp":2.96,"tv":351.55,"id":5071877},{"batb":[[2,1.48,2.01]],"ltp":1.53,"tv":1219.88,"id":6374165}]}]}
{"op":"mcm","clk":"1005769464","pt":1580590602400,"mc":[{"id":"1.168175448","rc":[{"batb":[[1,2.9,12.9]],"batl":[[2,95,15.9]],"ltp":2.96,"tv":351.55,"id":5071877},{"batb":[[2,1.47,46.45]],"ltp":1.53,"tv":1219.88,"id":6374165}]}]}
{"op":"mcm","clk":"1005769478","pt":1580590602606,"mc":[{"id":"1.168175448","rc":[{"batl":[[2,3.05,2.1]],"ltp":2.96,"tv":351.55,"id":5071877},{"batb":[[2,1.48,2.01]],"ltp":1.53,"tv":1219.88,"id":6374165}]}]}
{"op":"mcm","clk":"1005790850","pt":1580590805117,"mc":[{"id":"1.168175448","rc":[{"batb":[[0,1.51,84.01]],"ltp":1.53,"tv":1219.88,"id":6374165}]}]}
{"op":"mcm","clk":"1005791586","pt":1580590810418,"mc":[{"id":"1.168175448","rc":[{"batb":[[1,2.9,21.94]],"ltp":2.96,"tv":351.55,"id":5071877}]}]}
{"op":"mcm","clk":"1005792485","pt":1580590818380,"mc":[{"id":"1.168175448","rc":[{"batb":[[0,1.51,9.8]],"ltp":1.53,"tv":1219.88,"id":6374165}]}]}
{"op":"mcm","clk":"1005794731","pt":1580590836448,"mc":[{"id":"1.168175448","rc":[{"batb":[[1,2.9,18.08]],"ltp":2.96,"tv":351.55,"id":5071877}]}]}
{"op":"mcm","clk":"1005794777","pt":1580590836867,"mc":[{"id":"1.168175448","rc":[{"batl":[[2,3.05,2]],"ltp":2.96,"tv":351.55,"id":5071877}]}]}
{"op":"mcm","clk":"1005795970","pt":1580590847456,"mc":[{"id":"1.168175448","rc":[{"batb":[[1,2.9,21.94]],"ltp":2.96,"tv":351.55,"id":5071877}]}]}
{"op":"mcm","clk":"1005795997","pt":1580590847766,"mc":[{"id":"1.168175448","rc":[{"batl":[[2,3.05,2.1]],"ltp":2.96,"tv":351.55,"id":5071877}]}]}
{"op":"mcm","clk":"1005797072","pt":1580590857500,"mc":[{"id":"1.168175448","rc":[{"batb":[[1,2.9,18.08]],"ltp":2.96,"tv":351.55,"id":5071877}]}]}
{"op":"mcm","clk":"1005797145","pt":1580590858091,"mc":[{"id":"1.168175448","rc":[{"batl":[[2,3.05,4.1]],"ltp":2.96,"tv":351.55,"id":5071877},{"batb":[[2,1.48,4.02]],"ltp":1.53,"tv":1219.88,"id":6374165}]}]}
{"op":"mcm","clk":"1005797870","pt":1580590864506,"mc":[{"id":"1.168175448","rc":[{"batl":[[2,95,15.9]],"ltp":2.96,"tv":351.55,"id":5071877}]}]}
{"op":"mcm","clk":"1005797927","pt":1580590864881,"mc":[{"id":"1.168175448","rc":[{"batl":[[2,3.05,2.1]],"ltp":2.96,"tv":351.55,"id":5071877},{"batb":[[2,1.48,2.01]],"ltp":1.53,"tv":1219.88,"id":6374165}]}]}
{"op":"mcm","clk":"1005802181","pt":1580590906537,"mc":[{"id":"1.168175448","rc":[{"batb":[[0,2.92,25.05]],"batl":[[2,95,15.9]],"ltp":2.96,"tv":351.55,"id":5071877},{"batb":[[2,1.47,92.89]],"ltp":1.53,"tv":1219.88,"id":6374165}]}]}
{"op":"mcm","clk":"1005802231","pt":1580590907013,"mc":[{"id":"1.168175448","rc":[{"trd":[[2.92,269.42]],"batb":[[0,2.92,2.51]],"batl":[[2,3.05,2]],"ltp":2.92,"tv":396.67,"id":5071877},{"batb":[[2,1.48,2.01]],"ltp":1.53,"tv":1219.88,"id":6374165}],"tv":1616.56}]}
{"op":"mcm","clk":"1005803983","pt":1580590923479,"mc":[{"id":"1.168175448","rc":[{"batb":[[2,1.48,2]],"ltp":1.53,"tv":1219.88,"id":6374165}]}]}
{"op":"mcm","clk":"1005807337","pt":1580590953131,"mc":[{"id":"1.168175448","rc":[{"batb":[[2,1.48,2.01]],"ltp":1.53,"tv":1219.88,"id":6374165}]}]}
{"op":"mcm","clk":"1005819638","pt":1580591054214,"mc":[{"id":"1.168175448","rc":[{"batl":[[2,3.05,2.1]],"ltp":2.92,"tv":396.67,"id":5071877}]}]}
{"op":"mcm","clk":"1005822068","pt":1580591073147,"mc":[{"id":"1.168175448","rc":[{"batl":[[0,1.53,193.62]],"ltp":1.53,"tv":1219.88,"id":6374165}]}]}
{"op":"mcm","clk":"1005827835","pt":1580591115506,"mc":[{"id":"1.168175448","rc":[{"batl":[[2,95,15.9]],"ltp":2.92,"tv":396.67,"id":5071877},{"batb":[[2,1.47,92.89]],"batl":[[0,1.53,193.22]],"ltp":1.53,"tv":1219.88,"id":6374165}]}]}
{"op":"mcm","clk":"1005827868","pt":1580591115713,"mc":[{"id":"1.168175448","rc":[{"batl":[[2,3.05,2.1]],"ltp":2.92,"tv":396.67,"id":5071877},{"batb":[[2,1.48,2.01]],"ltp":1.53,"tv":1219.88,"id":6374165}]}]}
{"op":"mcm","clk":"1005828041","pt":1580591117095,"mc":[{"id":"1.168175448","rc":[{"batl":[[0,1.53,193.62]],"ltp":1.53,"tv":1219.88,"id":6374165}]}]}
{"op":"mcm","clk":"1005865294","pt":1580591381468,"mc":[{"id":"1.168175448","rc":[{"batl":[[2,95,15.9]],"ltp":2.92,"tv":396.67,"id":5071877},{"batb":[[2,1.47,92.89]],"batl":[[0,1.53,193.22]],"ltp":1.53,"tv":1219.88,"id":6374165}]}]}
{"op":"mcm","clk":"1005865326","pt":1580591381612,"mc":[{"id":"1.168175448","rc":[{"batl":[[2,3.05,2]],"ltp":2.92,"tv":396.67,"id":5071877},{"batb":[[2,1.48,2.01]],"ltp":1.53,"tv":1219.88,"id":6374165}]}]}
{"op":"mcm","clk":"1005866632","pt":1580591391468,"mc":[{"id":"1.168175448","rc":[{"batl":[[2,3.05,2.1]],"ltp":2.92,"tv":396.67,"id":5071877},{"batl":[[0,1.53,193.62]],"ltp":1.53,"tv":1219.88,"id":6374165}]}]}
{"op":"mcm","clk":"1005867052","pt":1580591394558,"mc":[{"id":"1.168175448","rc":[{"batl":[[0,1.53,61.18]],"ltp":1.53,"tv":1219.88,"id":6374165}]}]}
{"op":"mcm","clk":"1005877625","pt":1580591472378,"mc":[{"id":"1.168175448","rc":[{"batl":[[2,3.05,2]],"ltp":2.92,"tv":396.67,"id":5071877},{"trd":[[1.52,399.44],[1.53,156.07]],"batl":[[0,1.53,25.61]],"ltp":1.53,"tv":1291.04,"id":6374165}],"tv":1687.72}]}
{"op":"mcm","clk":"1005893376","pt":1580591584052,"mc":[{"id":"1.168175448","rc":[{"batl":[[2,3.05,2.1]],"ltp":2.92,"tv":396.67,"id":5071877}]}]}
{"op":"mcm","clk":"1005906547","pt":1580591678529,"mc":[{"id":"1.168175448","rc":[{"trd":[[1.51,375.35]],"batb":[[0,1.51,9.6]],"ltp":1.51,"tv":1291.44,"id":6374165}],"tv":1688.11}]}
{"op":"mcm","clk":"1005953367","pt":1580592014488,"mc":[{"id":"1.168175448","rc":[{"trd":[[2.96,52.72]],"batl":[[0,2.96,24.29]],"ltp":2.96,"tv":431.94,"id":5071877}],"tv":1723.39}]}
{"op":"mcm","clk":"1005953464","pt":1580592015069,"mc":[{"id":"1.168175448","rc":[{"batb":[[1,2.9,18.02]],"ltp":2.96,"tv":431.94,"id":5071877}]}]}
{"op":"mcm","clk":"1005959243","pt":1580592058551,"mc":[{"id":"1.168175448","rc":[{"batl":[[2,95,15.9]],"ltp":2.96,"tv":431.94,"id":5071877},{"batb":[[2,1.47,92.89]],"ltp":1.51,"tv":1291.44,"id":6374165}]}]}
{"op":"mcm","clk":"1005959302","pt":1580592059023,"mc":[{"id":"1.168175448","rc":[{"batl":[[2,3.05,2.1]],"ltp":2.96,"tv":431.94,"id":5071877},{"batb":[[2,1.48,2.01]],"ltp":1.51,"tv":1291.44,"id":6374165}]}]}
{"op":"mcm","clk":"1005979549","pt":1580592206523,"mc":[{"id":"1.168175448","rc":[{"batl":[[0,1.53,67.62]],"ltp":1.51,"tv":1291.44,"id":6374165}]}]}
{"op":"mcm","clk":"1005983746","pt":1580592239381,"mc":[{"id":"1.168175448","rc":[{"batl":[[2,95,15.9]],"ltp":2.96,"tv":431.94,"id":5071877},{"batb":[[2,1.47,92.89]],"ltp":1.51,"tv":1291.44,"id":6374165}]}]}
{"op":"mcm","clk":"1005983780","pt":1580592239588,"mc":[{"id":"1.168175448","rc":[{"batl":[[2,3.05,2]],"ltp":2.96,"tv":431.94,"id":5071877},{"batb":[[2,1.48,2.01]],"ltp":1.51,"tv":1291.44,"id":6374165}]}]}
{"op":"mcm","clk":"1005987690","pt":1580592268541,"mc":[{"id":"1.168175448","rc":[{"trd":[[2.92,274.43]],"batb":[[0,2.9,18.02],[1,2.86,2.18],[2,2.84,2.16]],"batl":[[0,2.92,37.49],[1,2.96,26.41],[2,2.98,2.17]],"ltp":2.92,"tv":436.96,"id":5071877},{"batb":[[1,1.5,2],[2,1.49,2.01]],"ltp":1.51,"tv":1291.44,"id":6374165}],"tv":1728.4}]}
{"op":"mcm","clk":"1005988586","pt":1580592275567,"mc":[{"id":"1.168175448","rc":[{"trd":[[2.9,106.61]],"batb":[[0,2.84,2.1],[1,2.82,2.03],[2,2.8,33.86]],"batl":[[0,2.94,3.07],[1,2.96,24.29],[2,2.98,2.02]],"ltp":2.9,"tv":509.96,"id":5071877}],"tv":1801.41}]}
{"op":"mcm","clk":"1005988644","pt":1580592275984,"mc":[{"id":"1.168175448","rc":[{"batb":[[1,2.82,27.58]],"batl":[[0,2.96,25.28],[1,3,2],[2,3.05,2.1]],"ltp":2.9,"tv":509.96,"id":5071877},{"batb":[[1,1.49,2.01],[2,1.48,105.64]],"ltp":1.51,"tv":1291.44,"id":6374165}]}]}
{"op":"mcm","clk":"1005989376","pt":1580592281562,"mc":[{"id":"1.168175448","rc":[{"batl":[[0,2.96,24.29]],"ltp":2.9,"tv":509.96,"id":5071877}]}]}
{"op":"mcm","clk":"1005989398","pt":1580592281672,"mc":[{"id":"1.168175448","rc":[{"trd":[[2.88,10.1]],"ltp":2.88,"tv":510.95,"id":5071877},{"trd":[[1.53,157.93]],"batl":[[0,1.53,65.76]],"ltp":1.53,"tv":1293.3,"id":6374165}],"tv":1804.26}]}
{"op":"mcm","clk":"1005990573","pt":1580592290275,"mc":[{"id":"1.168175448","rc":[{"trd":[[2.88,20.1]],"ltp":2.88,"tv":520.95,"id":5071877},{"trd":[[1.53,176.74]],"batl":[[0,1.53,46.95]],"ltp":1.53,"tv":1312.11,"id":6374165}],"tv":1833.07}]}
{"op":"mcm","clk":"1005990650","pt":1580592290755,"mc":[{"id":"1.168175448","rc":[{"batl":[[2,3.05,2]],"ltp":2.88,"tv":520.95,"id":5071877}]}]}
{"op":"mcm","clk":"1005990924","pt":1580592293008,"mc":[{"id":"1.168175448","rc":[{"trd":[[2.88,22.76]],"ltp":2.88,"tv":523.61,"id":5071877},{"trd":[[1.53,181.74]],"batl":[[0,1.53,41.95]],"ltp":1.53,"tv":1317.11,"id":6374165}],"tv":1840.73}]}
{"op":"mcm","clk":"1006000638","pt":1580592364566,"mc":[{"id":"1.168175448","rc":[{"batl":[[1,2.98,2],[2,3,2]],"ltp":2.88,"tv":523.61,"id":5071877},{"batb":[[0,1.52,74.21],[1,1.51,9.6],[2,1.5,2]],"ltp":1.53,"tv":1317.11,"id":6374165}]}]}
{"op":"mcm","clk":"1006002663","pt":1580592378512,"mc":[{"id":"1.168175448","rc":[{"batb":[[1,2.82,25.55]],"batl":[[1,3.05,2.1],[2,95,15.9]],"ltp":2.88,"tv":523.61,"id":5071877},{"batb":[[0,1.51,9.6],[1,1.49,2.01],[2,1.48,105.64]],"ltp":1.53,"tv":1317.11,"id":6374165}]}]}
{"op":"mcm","clk":"1006002738","pt":1580592378936,"mc":[{"id":"1.168175448","rc":[{"batb":[[1,2.82,27.58]],"batl":[[1,3,2],[2,3.05,2.1]],"ltp":2.88,"tv":523.61,"id":5071877}]}]}
{"op":"mcm","clk":"1006009405","pt":1580592428544,"mc":[{"id":"1.168175448","rc":[{"trd":[[2.96,77.01]],"batb":[[0,2.92,2.07],[1,2.9,2.06],[2,2.84,2.1]],"batl":[[0,3.15,2.1],[1,3.2,2.03],[2,95,15.9]],"ltp":2.96,"tv":547.91,"id":5071877},{"trd":[[1.51,608.54]],"batb":[[0,1.48,103.63],[1,1.46,186.2],[2,1.45,2.01]],"batl":[[0,1.51,5.76],[1,1.53,43.96],[2,1.54,241.47]],"ltp":1.51,"tv":1550.3,"id":6374165}],"tv":2098.21}]}
{"op":"mcm","clk":"1006009450","pt":1580592428918,"mc":[{"id":"1.168175448","rc":[{"batb":[[2,2.82,39.4]],"batl":[[0,3.2,2.03],[1,3.25,4.02]],"ltp":2.96,"tv":547.91,"id":5071877},{"batb":[[1,1.46,131.4],[2,1.45,58.03]],"ltp":1.51,"tv":1550.3,"id":6374165}]}]}
{"op":"mcm","clk":"1006009876","pt":1580592432244,"mc":[{"id":"1.168175448","rc":[{"batb":[[1,2.9,12.54]],"ltp":2.96,"tv":547.91,"id":5071877},{"batl":[[1,1.52,19.99],[2,1.53,43.96]],"ltp":1.51,"tv":1550.3,"id":6374165}]}]}
{"op":"mcm","clk":"1006009988","pt":1580592433032,"mc":[{"id":"1.168175448","rc":[{"batb":[[2,2.84,13.7]],"ltp":2.96,"tv":547.91,"id":5071877},{"batb":[[2,1.45,2.01]],"ltp":1.51,"tv":1550.3,"id":6374165}]}]}
{"op":"mcm","clk":"1006013480","pt":1580592461488,"mc":[{"id":"1.168175448","rc":[{"batb":[[0,2.9,10.48],[1,2.88,2],[2,2.86,18.64]],"batl":[[1,3.25,2]],"ltp":2.96,"tv":547.91,"id":5071877},{"trd":[[1.51,620.07],[1.52,436.87]],"batb":[[0,1.47,120.47]],"batl":[[0,1.52,1.28],[1,1.53,41.95],[2,1.54,241.47]],"ltp":1.52,"tv":1599.27,"id":6374165}],"tv":2147.18}]}
{"op":"mcm","clk":"1006013518","pt":1580592461785,"mc":[{"id":"1.168175448","rc":[{"batb":[[1,2.86,18.64],[2,2.84,15.7]],"batl":[[0,3.25,2],[1,3.3,2.05]],"ltp":2.96,"tv":547.91,"id":5071877},{"batb":[[1,1.46,129.39]],"batl":[[2,1.54,239.46]],"ltp":1.52,"tv":1599.27,"id":6374165}]}]}
{"op":"mcm","clk":"1006013838","pt":1580592464496,"mc":[{"id":"1.168175448","rc":[{"batl":[[0,3.2,2.03],[1,3.25,2],[2,3.3,2.05]],"ltp":2.96,"tv":547.91,"id":5071877},{"batb":[[0,1.48,19.22],[1,1.47,120.47],[2,1.46,131.4]],"ltp":1.52,"tv":1599.27,"id":6374165}]}]}
{"op":"mcm","clk":"1006014530","pt":1580592469906,"mc":[{"id":"1.168175448","rc":[{"batb":[[2,2.84,15.8]],"batl":[[1,3.25,2.02],[2,95,15.9]],"ltp":2.96,"tv":547.91,"id":5071877}]}]}
{"op":"mcm","clk":"1006016916","pt":1580592489437,"mc":[{"id":"1.168175448","rc":[{"batb":[[0,1.49,74.21],[1,1.48,19.22],[2,1.47,120.47]],"ltp":1.52,"tv":1599.27,"id":6374165}]}]}
{"op":"mcm","clk":"1006017030","pt":1580592490421,"mc":[{"id":"1.168175448","rc":[{"batb":[[2,2.84,2]],"batl":[[0,3.15,2.1],[1,3.2,2]],"ltp":2.96,"tv":547.91,"id":5071877},{"batb":[[2,1.47,122.48]],"ltp":1.52,"tv":1599.27,"id":6374165}]}]}
{"op":"mcm","clk":"1006017293","pt":1580592492407,"mc":[{"id":"1.168175448","rc":[{"batb":[[0,1.5,19.22],[1,1.49,74.21]],"ltp":1.52,"tv":1599.27,"id":6374165}]}]}
{"op":"mcm","clk":"1006017353","pt":1580592493025,"mc":[{"id":"1.168175448","rc":[{"batl":[[0,3.1,2],[1,3.15,2.1],[2,3.2,2]],"ltp":2.96,"tv":547.91,"id":5071877},{"batb":[[2,1.48,2.01]],"ltp":1.52,"tv":1599.27,"id":6374165}]}]}
{"op":"mcm","clk":"1006018106","pt":1580592499358,"mc":[{"id":"1.168175448","rc":[{"batb":[[2,2.84,2.04]],"batl":[[1,3.15,2.04],[2,95,15.9]],"ltp":2.96,"tv":547.91,"id":5071877},{"batb":[[1,1.48,76.22],[2,1.47,122.48]],"ltp":1.52,"tv":1599.27,"id":6374165}]}]}
{"op":"mcm","clk":"1006018196","pt":1580592500047,"mc":[{"id":"1.168175448","rc":[{"batb":[[2,2.84,15.74]],"ltp":2.96,"tv":547.91,"id":5071877}]}]}
{"op":"mcm","clk":"1006018952","pt":1580592506553,"mc":[{"id":"1.168175448","rc":[{"batb":[[0,1.49,19.22]],"ltp":1.52,"tv":1599.27,"id":6374165}]}]}
{"op":"mcm","clk":"1006019028","pt":1580592507074,"mc":[{"id":"1.168175448","rc":[{"batb":[[2,2.84,15.86]],"batl":[[0,3.15,2],[1,3.2,2]],"ltp":2.96,"tv":547.91,"id":5071877},{"batb":[[1,1.48,74.21]],"batl":[[0,1.53,41.95],[1,1.54,239.46],[2,1.55,2.01]],"ltp":1.52,"tv":1599.27,"id":6374165}]}]}
{"op":"mcm","clk":"1006019744","pt":1580592513493,"mc":[{"id":"1.168175448","rc":[{"trd":[[1.48,148.44],[1.49,38.46]],"batb":[[0,1.47,122.48],[1,1.46,131.4],[2,1.45,58.03]],"batl":[[0,1.48,6.55],[1,1.53,41.95],[2,1.54,239.46]],"ltp":1.48,"tv":1786.14,"id":6374165}],"tv":2334.05}]}
{"op":"mcm","clk":"1006019863","pt":1580592514483,"mc":[{"id":"1.168175448","rc":[{"batl":[[0,3.25,2.02],[1,3.3,2.05]],"ltp":2.96,"tv":547.91,"id":5071877},{"trd":[[1.48,161.54]],"batb":[[0,1.47,120.47],[1,1.46,129.39],[2,1.45,2.01]],"batl":[[0,1.53,41.95],[1,1.54,239.46],[2,1.55,2.01]],"ltp":1.48,"tv":1799.24,"id":6374165}],"tv":2347.15}]}
{"op":"mcm","clk":"1006020522","pt":1580592520504,"mc":[{"id":"1.168175448","rc":[{"batl":[[0,1.52,19.99],[1,1.53,41.95],[2,1.54,239.46]],"ltp":1.48,"tv":1799.24,"id":6374165}]}]}
{"op":"mcm","clk":"1006020633","pt":1580592521510,"mc":[{"id":"1.168175448","rc":[{"batb":[[1,2.88,2.13],[2,2.86,32.01]],"ltp":2.96,"tv":547.91,"id":5071877},{"batb":[[0,1.48,1.19],[1,1.47,120.47],[2,1.46,129.39]],"batl":[[2,1.54,241.47]],"ltp":1.48,"tv":1799.24,"id":6374165}]}]}
{"op":"mcm","clk":"1006025204","pt":1580592561372,"mc":[{"id":"1.168175448","rc":[{"batb":[[0,1.48,20.53]],"ltp":1.48,"tv":1799.24,"id":6374165}]}]}
{"op":"mcm","clk":"1006025341","pt":1580592562482,"mc":[{"id":"1.168175448","rc":[{"batb":[[2,2.86,32.12]],"batl":[[0,3.2,2],[1,3.25,2.02]],"ltp":2.96,"tv":547.91,"id":5071877},{"trd":[[1.52,474.79]],"batb":[[2,1.46,131.4]],"batl":[[0,1.52,1.04]],"ltp":1.52,"tv":1837.16,"id":6374165}],"tv":2385.07}]}
{"op":"mcm","clk":"1006025428","pt":1580592563169,"mc":[{"id":"1.168175448","rc":[{"batb":[[1,2.86,18.57],[2,2.84,15.7]],"ltp":2.96,"tv":547.91,"id":5071877},{"batl":[[2,1.54,239.46]],"ltp":1.52,"tv":1837.16,"id":6374165}]}]}
{"op":"mcm","clk":"1006025931","pt":1580592567486,"mc":[{"id":"1.168175448","rc":[{"batb":[[0,1.48,19.33]],"ltp":1.52,"tv":1837.16,"id":6374165}]}]}
{"op":"mcm","clk":"1006028856","pt":1580592592434,"mc":[{"id":"1.168175448","rc":[{"batb":[[2,2.84,15.92]],"batl":[[0,3.15,2.04],[1,3.2,2]],"ltp":2.96,"tv":547.91,"id":5071877},{"batb":[[0,1.49,72.49],[1,1.48,19.33],[2,1.47,2.01]],"ltp":1.52,"tv":1837.16,"id":6374165}]}]}
{"op":"mcm","clk":"1006028929","pt":1580592593010,"mc":[{"id":"1.168175448","rc":[{"batb":[[2,2.84,2.22]],"batl":[[1,3.2,2.03]],"ltp":2.96,"tv":547.91,"id":5071877}]}]}
{"op":"mcm","clk":"1006029329","pt":1580592596445,"mc":[{"id":"1.168175448","rc":[{"batl":[[0,3.1,9.8],[1,3.15,2.04],[2,3.2,2.03]],"ltp":2.96,"tv":547.91,"id":5071877}]}]}
{"op":"mcm","clk":"1006030052","pt":1580592601886,"mc":[{"id":"1.168175448","rc":[{"batb":[[2,2.84,2.16]],"ltp":2.96,"tv":547.91,"id":5071877}]}]}
{"op":"mcm","clk":"1006030559","pt":1580592605552,"mc":[{"id":"1.168175448","rc":[{"trd":[[2.9,127.58],[2.92,274.97]],"batb":[[0,2.86,18.57],[1,2.84,2.16],[2,2.82,13.85]],"batl":[[0,2.9,23.45]],"ltp":2.9,"tv":569.42,"id":5071877},{"trd":[[1.52,475.83]],"batb":[[0,1.5,19.07],[1,1.49,72.49]],"batl":[[0,1.53,41.95],[1,1.54,239.46],[2,1.55,2.1]],"ltp":1.52,"tv":1838.2,"id":6374165}],"tv":2407.63}]}
{"op":"mcm","clk":"1006030669","pt":1580592606444,"mc":[{"id":"1.168175448","rc":[{"trd":[[2.9,172.12]],"batb":[[0,2.86,16.46],[2,2.82,15.88]],"batl":[[0,2.9,1.18],[1,3.05,2.1],[2,3.1,2.05]],"ltp":2.9,"tv":613.95,"id":5071877},{"batb":[[0,1.5,21.07],[1,1.49,74.5],[2,1.48,2.01]],"ltp":1.52,"tv":1838.2,"id":6374165}],"tv":2452.16}]}
{"op":"mcm","clk":"1006030725","pt":1580592606822,"mc":[{"id":"1.168175448","rc":[{"batl":[[1,3.1,2.05],[2,3.15,2]],"ltp":2.9,"tv":613.95,"id":5071877}]}]}
{"op":"mcm","clk":"1006031049","pt":1580592609497,"mc":[{"id":"1.168175448","rc":[{"batb":[[2,2.82,2.03]],"ltp":2.9,"tv":613.95,"id":5071877}]}]}
{"op":"mcm","clk":"1006031817","pt":1580592616420,"mc":[{"id":"1.168175448","rc":[{"batl":[[1,3,10.13],[2,3.1,2.05]],"ltp":2.9,"tv":613.95,"id":5071877},{"batb":[[0,1.5,22.13],[2,1.46,184.19]],"batl":[[0,1.53,116.16]],"ltp":1.52,"tv":1838.2,"id":6374165}]}]}
{"op":"mcm","clk":"1006045245","pt":1580592722497,"mc":[{"id":"1.168175448","rc":[{"batb":[[0,1.51,27.34],[1,1.5,22.13],[2,1.49,2.01]],"ltp":1.52,"tv":1838.2,"id":6374165}]}]}
{"op":"mcm","clk":"1006045331","pt":1580592723236,"mc":[{"id":"1.168175448","rc":[{"batl":[[2,3.05,2.1]],"ltp":2.9,"tv":613.95,"id":5071877}]}]}
{"op":"mcm","clk":"1006046492","pt":1580592732378,"mc":[{"id":"1.168175448","rc":[{"batl":[[1,2.96,10.13],[2,3,2]],"ltp":2.9,"tv":613.95,"id":5071877},{"batb":[[0,1.51,47.34],[1,1.5,2]],"ltp":1.52,"tv":1838.2,"id":6374165}]}]}
{"op":"mcm","clk":"1006048223","pt":1580592746195,"mc":[{"id":"1.168175448","rc":[{"batl":[[1,2.96,10.27]],"ltp":2.9,"tv":613.95,"id":5071877}]}]}
{"op":"mcm","clk":"1006049697","pt":1580592758176,"mc":[{"id":"1.168175448","rc":[{"trd":[[2.9,173.3]],"batl":[[0,2.96,10.27],[1,3,2],[2,3.05,2]],"ltp":2.9,"tv":615.13,"id":5071877},{"trd":[[1.51,625.89],[1.52,478.08]],"batb":[[0,1.51,44.42],[1,1.49,2.01],[2,1.48,76.22]],"ltp":1.51,"tv":1846.28,"id":6374165}],"tv":2461.42}]}
{"op":"mcm","clk":"1006049819","pt":1580592759169,"mc":[{"id":"1.168175448","rc":[{"batb":[[0,1.51,20]],"ltp":1.51,"tv":1846.28,"id":6374165}]}]}
{"op":"mcm","clk":"1006050235","pt":1580592762397,"mc":[{"id":"1.168175448","rc":[{"batb":[[2,2.82,15.88]],"batl":[[0,3.05,9.96],[1,3.15,2],[2,3.2,2.03]],"ltp":2.9,"tv":615.13,"id":5071877},{"batb":[[0,1.51,25.19],[1,1.49,20],[2,1.48,74.21]],"ltp":1.51,"tv":1846.28,"id":6374165}]}]}
{"op":"mcm","clk":"1006050329","pt":1580592763086,"mc":[{"id":"1.168175448","rc":[{"batl":[[0,3.05,12.06],[1,3.1,2.05],[2,3.15,2]],"ltp":2.9,"tv":615.13,"id":5071877},{"batb":[[1,1.49,22.01],[2,1.48,76.22]],"ltp":1.51,"tv":1846.28,"id":6374165}]}]}
{"op":"mcm","clk":"1006052317","pt":1580592779519,"mc":[{"id":"1.168175448","rc":[{"batb":[[2,2.82,2]],"batl":[[0,2.96,9.96],[1,2.98,2.25],[2,3,2]],"ltp":2.9,"tv":615.13,"id":5071877},{"batb":[[0,1.52,20],[1,1.51,25.19],[2,1.5,2]],"ltp":1.51,"tv":1846.28,"id":6374165}]}]}
{"op":"mcm","clk":"1006053800","pt":1580592790145,"mc":[{"id":"1.168175448","rc":[{"batb":[[2,2.82,2.03]],"batl":[[0,2.96,10.27]],"ltp":2.9,"tv":615.13,"id":5071877}]}]}
{"op":"mcm","clk":"1006054093","pt":1580592792150,"mc":[{"id":"1.168175448","rc":[{"batb":[[2,2.82,15.88]],"ltp":2.9,"tv":615.13,"id":5071877},{"trd":[[1.52,517.84]],"batb":[[0,1.51,25.19],[1,1.5,2],[2,1.49,2.01]],"batl":[[0,1.52,80.11],[1,1.53,116.16],[2,1.54,239.46]],"ltp":1.52,"tv":1886.04,"id":6374165}],"tv":2501.17}]}
{"op":"mcm","clk":"1006054247","pt":1580592793122,"mc":[{"id":"1.168175448","rc":[{"batb":[[0,2.88,2.21],[1,2.86,18.64]],"batl":[[1,3,2],[2,3.05,2.1]],"ltp":2.9,"tv":615.13,"id":5071877},{"batb":[[1,1.49,2.01],[2,1.48,76.22]],"batl":[[2,1.54,241.47]],"ltp":1.52,"tv":1886.04,"id":6374165}]}]}
{"op":"mcm","clk":"1006055572","pt":1580592803544,"mc":[{"id":"1.168175448","rc":[{"batb":[[1,2.86,16.46],[2,2.82,13.85]],"batl":[[2,95,15.9]],"ltp":2.9,"tv":615.13,"id":5071877},{"batb":[[2,1.48,74.21]],"batl":[[0,1.53,116.16],[1,1.54,239.46],[2,1.55,2.1]],"ltp":1.52,"tv":1886.04,"id":6374165}]}]}
{"op":"mcm","clk":"1006055653","pt":1580592804126,"mc":[{"id":"1.168175448","rc":[{"batb":[[0,2.86,16.46],[1,2.84,2.22],[2,2.82,2.03]],"batl":[[2,3.05,2.1]],"ltp":2.9,"tv":615.13,"id":5071877},{"batb":[[2,1.48,76.21]],"ltp":1.52,"tv":1886.04,"id":6374165}]}]}
{"op":"mcm","clk":"1006055912","pt":1580592806147,"mc":[{"id":"1.168175448","rc":[{"batb":[[2,2.82,15.88]],"batl":[[0,3.05,12.06],[1,3.1,2],[2,95,15.9]],"ltp":2.9,"tv":615.13,"id":5071877}]}]}
{"op":"mcm","clk":"1006058520","pt":1580592826518,"mc":[{"id":"1.168175448","rc":[{"trd":[[1.51,676.27]],"batb":[[0,1.49,2.01],[1,1.48,76.21],[2,1.46,184.19]],"batl":[[0,1.51,74.81],[1,1.53,116.16],[2,1.54,239.46]],"ltp":1.51,"tv":1936.42,"id":6374165}],"tv":2551.55}]}
{"op":"mcm","clk":"1006058663","pt":1580592827467,"mc":[{"id":"1.168175448","rc":[{"batb":[[0,2.92,2.19],[1,2.9,20.19],[2,2.84,13.7]],"batl":[[0,3.05,9.96],[1,3.15,2.1],[2,3.2,2.03]],"ltp":2.9,"tv":615.13,"id":5071877},{"trd":[[1.51,817.79]],"batb":[[0,1.49,45.02],[1,1.48,74.21],[2,1.46,131.4]],"batl":[[0,1.51,105.35],[1,1.52,18.65],[2,1.53,118.17]],"ltp":1.51,"tv":2077.94,"id":6374165}],"tv":2693.07}]}
{"op":"mcm","clk":"1006058751","pt":1580592828198,"mc":[{"id":"1.168175448","rc":[{"batb":[[2,2.86,13.55]],"ltp":2.9,"tv":615.13,"id":5071877},{"batb":[[2,1.47,2]],"ltp":1.51,"tv":2077.94,"id":6374165}]}]}
{"op":"mcm","clk":"1006061106","pt":1580592846548,"mc":[{"id":"1.168175448","rc":[{"batb":[[2,2.84,13.7]],"ltp":2.9,"tv":615.13,"id":5071877},{"batl":[[0,1.51,4.05]],"ltp":1.51,"tv":2077.94,"id":6374165}]}]}
{"op":"mcm","clk":"1006061252","pt":1580592847558,"mc":[{"id":"1.168175448","rc":[{"batb":[[0,2.9,18.13],[1,2.86,2.04],[2,2.84,15.8]],"ltp":2.9,"tv":615.13,"id":5071877},{"trd":[[1.51,825.43]],"batl":[[0,1.52,18.88],[1,1.53,116.16],[2,1.54,241.47]],"ltp":1.51,"tv":2085.58,"id":6374165}],"tv":2700.71}]}
{"op":"mcm","clk":"1006061311","pt":1580592847818,"mc":[{"id":"1.168175448","rc":[{"batb":[[1,2.88,2.05],[2,2.86,2.04]],"ltp":2.9,"tv":615.13,"id":5071877}]}]}
{"op":"mcm","clk":"1006061660","pt":1580592850401,"mc":[{"id":"1.168175448","rc":[{"batb":[[0,2.92,9.42],[1,2.9,18.13],[2,2.88,2.05]],"batl":[[0,3,9.96],[1,3.1,2.05]],"ltp":2.9,"tv":615.13,"id":5071877},{"batb":[[1,1.48,76.21],[2,1.46,131.4]],"ltp":1.51,"tv":2085.58,"id":6374165}]}]}
{"op":"mcm","clk":"1006061815","pt":1580592851508,"mc":[{"id":"1.168175448","rc":[{"batl":[[2,3.15,2.1]],"ltp":2.9,"tv":615.13,"id":5071877},{"batb":[[2,1.47,2.01]],"ltp":1.51,"tv":2085.58,"id":6374165}]}]}
{"op":"mcm","clk":"1006062298","pt":1580592855406,"mc":[{"id":"1.168175448","rc":[{"batl":[[0,1.52,18.65]],"ltp":1.51,"tv":2085.58,"id":6374165}]}]}
{"op":"mcm","clk":"1006063104","pt":1580592861198,"mc":[{"id":"1.168175448","rc":[{"batl":[[0,3,10.13],[2,3.15,2.04]],"ltp":2.9,"tv":615.13,"id":5071877},{"batb":[[0,1.5,20.26],[1,1.49,45.02],[2,1.48,76.21]],"ltp":1.51,"tv":2085.58,"id":6374165}]}]}
{"op":"mcm","clk":"1006065526","pt":1580592881504,"mc":[{"id":"1.168175448","rc":[{"batl":[[2,3.15,2.1]],"ltp":2.9,"tv":615.13,"id":5071877},{"batl":[[0,1.52,41.1]],"ltp":1.51,"tv":2085.58,"id":6374165}]}]}
{"op":"mcm","clk":"1006065584","pt":1580592881921,"mc":[{"id":"1.168175448","rc":[{"trd":[[1.52,596.37]],"batl":[[0,1.52,1.85],[2,1.54,239.46]],"ltp":1.52,"tv":2164.1,"id":6374165}],"tv":2779.24}]}
{"op":"mcm","clk":"1006065789","pt":1580592883511,"mc":[{"id":"1.168175448","rc":[{"batl":[[0,1.53,116.16],[1,1.54,239.46],[2,1.55,2.01]],"ltp":1.52,"tv":2164.1,"id":6374165}]}]}
{"op":"mcm","clk":"1006066232","pt":1580592887036,"mc":[{"id":"1.168175448","rc":[{"batb":[[0,2.9,18.13],[1,2.86,2],[2,2.84,2]],"ltp":2.9,"tv":615.13,"id":5071877},{"batb":[[0,1.5,18.9]],"ltp":1.52,"tv":2164.1,"id":6374165}]}]}
{"op":"mcm","clk":"1006068986","pt":1580592907517,"mc":[{"id":"1.168175448","rc":[{"batb":[[2,2.84,2.22]],"batl":[[2,3.15,2]],"ltp":2.9,"tv":615.13,"id":5071877},{"batl":[[0,1.52,1.85],[1,1.53,116.16],[2,1.54,239.46]],"ltp":1.52,"tv":2164.1,"id":6374165}]}]}
{"op":"mcm","clk":"1006074604","pt":1580592949487,"mc":[{"id":"1.168175448","rc":[{"batb":[[1,2.88,2.21],[2,2.86,2.11]],"batl":[[2,3.15,2.1]],"ltp":2.9,"tv":615.13,"id":5071877},{"batl":[[0,1.52,76.06],[2,1.54,241.47]],"ltp":1.52,"tv":2164.1,"id":6374165}]}]}
{"op":"mcm","clk":"1006074686","pt":1580592950073,"mc":[{"id":"1.168175448","rc":[{"batb":[[1,2.86,2.11],[2,2.84,2.22]],"ltp":2.9,"tv":615.13,"id":5071877},{"trd":[[1.52,742.23]],"batl":[[0,1.52,3.13]],"ltp":1.52,"tv":2309.96,"id":6374165}],"tv":2925.1}]}
{"op":"mcm","clk":"1006075184","pt":1580592954471,"mc":[{"id":"1.168175448","rc":[{"batl":[[1,3.05,2.1],[2,3.1,2]],"ltp":2.9,"tv":615.13,"id":5071877},{"batb":[[0,1.51,74.21],[1,1.5,18.9],[2,1.49,47.03]],"ltp":1.52,"tv":2309.96,"id":6374165}]}]}
{"op":"mcm","clk":"1006076209","pt":1580592962381,"mc":[{"id":"1.168175448","rc":[{"batb":[[2,2.8,47.86]],"batl":[[2,95,15.9]],"ltp":2.9,"tv":615.13,"id":5071877},{"trd":[[1.51,973.77]],"batb":[[0,1.5,18.9],[1,1.49,45.02],[2,1.48,76.22]],"batl":[[0,1.51,27.17],[1,1.52,3.13],[2,1.53,118.17]],"ltp":1.51,"tv":2458.3,"id":6374165}],"tv":3073.44}]}
{"op":"mcm","clk":"1006076361","pt":1580592963490,"mc":[{"id":"1.168175448","rc":[{"trd":[[2.96,87.28]],"batb":[[0,2.92,10.41],[1,2.9,18.13],[2,2.88,2.21]],"batl":[[0,3.05,2],[1,3.1,2.05],[2,3.15,2.1]],"ltp":2.96,"tv":625.4,"id":5071877},{"trd":[[1.51,1007.99]],"batb":[[0,1.5,4.72],[1,1.49,47.03],[2,1.48,74.21]],"batl":[[0,1.52,3.13],[1,1.53,116.16],[2,1.54,241.47]],"ltp":1.51,"tv":2492.52,"id":6374165}],"tv":3117.92}]}
{"op":"mcm","clk":"1006076394","pt":1580592963697,"mc":[{"id":"1.168175448","rc":[{"batl":[[0,3.1,2.05],[1,3.15,2.1],[2,3.2,2.03]],"ltp":2.96,"tv":625.4,"id":5071877},{"batb":[[1,1.49,45.02],[2,1.48,76.22]],"ltp":1.51,"tv":2492.52,"id":6374165}]}]}
{"op":"mcm","clk":"1006077273","pt":1580592970383,"mc":[{"id":"1.168175448","rc":[{"batl":[[2,95,15.9]],"ltp":2.96,"tv":625.4,"id":5071877},{"batb":[[0,1.5,11.81]],"ltp":1.51,"tv":2492.52,"id":6374165}]}]}
{"op":"mcm","clk":"1006077350","pt":1580592971014,"mc":[{"id":"1.168175448","rc":[{"trd":[[1.52,747.98]],"batl":[[0,1.53,116.41],[1,1.54,239.46],[2,1.55,2.1]],"ltp":1.52,"tv":2498.27,"id":6374165}],"tv":3123.68}]}
{"op":"mcm","clk":"1006078269","pt":1580592978527,"mc":[{"id":"1.168175448","rc":[{"batb":[[0,1.5,4.72]],"ltp":1.52,"tv":2498.27,"id":6374165}]}]}
{"op":"mcm","clk":"1006078845","pt":1580592983047,"mc":[{"id":"1.168175448","rc":[{"batb":[[0,1.5,11.81]],"ltp":1.52,"tv":2498.27,"id":6374165}]}]}
{"op":"mcm","clk":"1006079132","pt":1580592985450,"mc":[{"id":"1.168175448","rc":[{"batl":[[1,3.15,2.04]],"ltp":2.96,"tv":625.4,"id":5071877}]}]}
{"op":"mcm","clk":"1006079508","pt":1580592988361,"mc":[{"id":"1.168175448","rc":[{"batl":[[0,1.52,20.24],[1,1.53,116.16],[2,1.54,241.47]],"ltp":1.52,"tv":2498.27,"id":6374165}]}]}
{"op":"mcm","clk":"1006079586","pt":1580592989044,"mc":[{"id":"1.168175448","rc":[{"trd":[[1.52,786.38]],"batl":[[0,1.52,1.05],[2,1.54,239.46]],"ltp":1.52,"tv":2536.67,"id":6374165}],"tv":3162.08}]}
{"op":"mcm","clk":"1006079851","pt":1580592991046,"mc":[{"id":"1.168175448","rc":[{"batb":[[0,2.92,4.26]],"ltp":2.96,"tv":625.4,"id":5071877},{"batb":[[0,1.5,20.26]],"ltp":1.52,"tv":2536.67,"id":6374165}]}]}
{"op":"mcm","clk":"1006080042","pt":1580592992454,"mc":[{"id":"1.168175448","rc":[{"batl":[[1,95,15.9],[2,990,2.2]],"ltp":2.96,"tv":625.4,"id":5071877}]}]}
{"op":"mcm","clk":"1006080065","pt":1580592992665,"mc":[{"id":"1.168175448","rc":[{"batl":[[1,3.15,2.1],[2,95,15.9]],"ltp":2.96,"tv":625.4,"id":5071877}]}]}
{"op":"mcm","clk":"1006080511","pt":1580592996089,"mc":[{"id":"1.168175448","rc":[{"batl":[[0,1.53,116.16],[1,1.54,239.46],[2,1.55,2.1]],"ltp":1.52,"tv":2536.67,"id":6374165}]}]}
{"op":"mcm","clk":"1006087942","pt":1580593058467,"mc":[{"id":"1.168175448","rc":[{"batl":[[1,95,15.9],[2,990,2.2]],"ltp":2.96,"tv":625.4,"id":5071877},{"batl":[[0,1.52,8.44],[1,1.53,116.16],[2,1.54,241.47]],"ltp":1.52,"tv":2536.67,"id":6374165}]}]}
{"op":"mcm","clk":"1006088017","pt":1580593059046,"mc":[{"id":"1.168175448","rc":[{"batl":[[1,3.15,2.1],[2,95,15.9]],"ltp":2.96,"tv":625.4,"id":5071877},{"trd":[[1.52,801.77]],"batl":[[0,1.53,116.91],[1,1.54,239.46],[2,1.55,2.1]],"ltp":1.52,"tv":2552.07,"id":6374165}],"tv":3177.47}]}
{"op":"mcm","clk":"1006088333","pt":1580593061561,"mc":[{"id":"1.168175448","rc":[{"batb":[[0,2.9,18.39],[1,2.86,2.18],[2,2.84,2.1]],"ltp":2.96,"tv":625.4,"id":5071877}]}]}
{"op":"mcm","clk":"1006088767","pt":1580593065484,"mc":[{"id":"1.168175448","rc":[{"batl":[[0,1.53,116.16]],"ltp":1.52,"tv":2552.07,"id":6374165}]}]}
{"op":"mcm","clk":"1006089019","pt":1580593067501,"mc":[{"id":"1.168175448","rc":[{"trd":[[1.48,236.94],[1.49,128.49],[1.5,229.81]],"batb":[[0,1.48,36.51],[1,1.46,186.2],[2,1.45,58.03]],"ltp":1.48,"tv":2758.05,"id":6374165}],"tv":3383.45}]}
{"op":"mcm","clk":"1006089127","pt":1580593068385,"mc":[{"id":"1.168175448","rc":[{"batb":[[0,2.9,41.13],[1,2.88,2.05],[2,2.86,2.18]],"batl":[[0,3.2,2.03],[1,3.25,2.02],[2,3.3,2.05]],"ltp":2.96,"tv":625.4,"id":5071877},{"batb":[[1,1.47,47.63],[2,1.46,131.4]],"batl":[[0,1.52,74.21],[1,1.53,116.16],[2,1.54,241.47]],"ltp":1.48,"tv":2758.05,"id":6374165}]}]}
{"op":"mcm","clk":"1006089233","pt":1580593069182,"mc":[{"id":"1.168175448","rc":[{"batb":[[2,2.86,2]],"ltp":2.96,"tv":625.4,"id":5071877}]}]}
{"op":"mcm","clk":"1006090404","pt":1580593079524,"mc":[{"id":"1.168175448","rc":[{"batb":[[0,2.94,10.34],[1,2.9,42.94],[2,2.88,2.05]],"batl":[[1,95,15.9],[2,990,2.2]],"ltp":2.96,"tv":625.4,"id":5071877},{"batb":[[0,1.49,18.66],[1,1.48,36.51],[2,1.47,49.64]],"ltp":1.48,"tv":2758.05,"id":6374165}]}]}
{"op":"mcm","clk":"1006090523","pt":1580593080436,"mc":[{"id":"1.168175448","rc":[{"trd":[[2.94,19.25]],"batb":[[0,2.9,41.59],[1,2.88,2.21],[2,2.86,2.18]],"batl":[[0,3.15,2.1],[1,3.2,2.03],[2,95,15.9]],"ltp":2.94,"tv":644.65,"id":5071877}],"tv":3402.7}]}
{"op":"mcm","clk":"1006091180","pt":1580593086487,"mc":[{"id":"1.168175448","rc":[{"batb":[[0,2.9,40.88]],"batl":[[0,3.05,9.28],[1,3.15,2.1],[2,3.2,2.03]],"ltp":2.94,"tv":644.65,"id":5071877}]}]}
{"op":"mcm","clk":"1006094822","pt":1580593119502,"mc":[{"id":"1.168175448","rc":[{"batb":[[2,2.84,13.7]],"batl":[[2,95,15.9]],"ltp":2.94,"tv":644.65,"id":5071877},{"batl":[[0,1.51,2.35],[1,1.52,74.21],[2,1.53,116.16]],"ltp":1.48,"tv":2758.05,"id":6374165}]}]}
{"op":"mcm","clk":"1006094886","pt":1580593120183,"mc":[{"id":"1.168175448","rc":[{"batb":[[2,2.86,2.18]],"batl":[[2,3.2,2.03]],"ltp":2.94,"tv":644.65,"id":5071877},{"batl":[[2,1.53,118.17]],"ltp":1.48,"tv":2758.05,"id":6374165}]}]}
{"op":"mcm","clk":"1006095437","pt":1580593125363,"mc":[{"id":"1.168175448","rc":[{"batb":[[0,2.94,28.64],[1,2.9,2.06],[2,2.88,2.21]],"ltp":2.94,"tv":644.65,"id":5071877},{"batb":[[1,1.48,110.71]],"ltp":1.48,"tv":2758.05,"id":6374165}]}]}
{"op":"mcm","clk":"1006095541","pt":1580593126196,"mc":[{"id":"1.168175448","rc":[{"batb":[[2,2.88,2.05]],"ltp":2.94,"tv":644.65,"id":5071877}]}]}
{"op":"mcm","clk":"1006097879","pt":1580593147528,"mc":[{"id":"1.168175448","rc":[{"batb":[[0,2.96,1.07],[1,2.94,28.64],[2,2.9,2.06]],"batl":[[2,95,15.9]],"ltp":2.94,"tv":644.65,"id":5071877}]}]}
{"op":"mcm","clk":"1006097952","pt":1580593148010,"mc":[{"id":"1.168175448","rc":[{"batb":[[2,2.92,2]],"batl":[[2,3.2,2]],"ltp":2.94,"tv":644.65,"id":5071877}]}]}
{"op":"mcm","clk":"1006101497","pt":1580593178105,"mc":[{"id":"1.168175448","rc":[{"batl":[[2,3.2,2.03]],"ltp":2.94,"tv":644.65,"id":5071877}]}]}
{"op":"mcm","clk":"1006111111","pt":1580593258370,"mc":[{"id":"1.168175448","rc":[{"batb":[[2,2.9,2.06]],"batl":[[2,95,15.9]],"ltp":2.94,"tv":644.65,"id":5071877}]}]}
{"op":"mcm","clk":"1006111136","pt":1580593258586,"mc":[{"id":"1.168175448","rc":[{"batl":[[2,3.2,2.03]],"ltp":2.94,"tv":644.65,"id":5071877}]}]}
{"op":"mcm","clk":"1006113504","pt":1580593278480,"mc":[{"id":"1.168175448","rc":[{"batb":[[2,2.92,2.19]],"ltp":2.94,"tv":644.65,"id":5071877},{"batl":[[0,1.51,57.8]],"ltp":1.48,"tv":2758.05,"id":6374165}]}]}
{"op":"mcm","clk":"1006113649","pt":1580593279426,"mc":[{"id":"1.168175448","rc":[{"batb":[[0,2.94,28.64],[1,2.92,2.19],[2,2.9,2]],"ltp":2.94,"tv":644.65,"id":5071877},{"trd":[[1.51,1118.43]],"batb":[[0,1.49,20.4]],"batl":[[0,1.51,2.58]],"ltp":1.51,"tv":2868.49,"id":6374165}],"tv":3513.14}]}
{"op":"mcm","clk":"1006113747","pt":1580593280213,"mc":[{"id":"1.168175448","rc":[{"batb":[[1,2.9,2],[2,2.88,2.05]],"ltp":2.94,"tv":644.65,"id":5071877}]}]}
{"op":"mcm","clk":"1006114949","pt":1580593290315,"mc":[{"id":"1.168175448","rc":[{"batb":[[2,2.88,2.21]],"batl":[[2,3.2,2]],"ltp":2.94,"tv":644.65,"id":5071877},{"batl":[[1,1.52,158.23]],"ltp":1.51,"tv":2868.49,"id":6374165}]}]}
{"op":"mcm","clk":"1006115379","pt":1580593294053,"mc":[{"id":"1.168175448","rc":[{"batl":[[2,1.53,286.21]],"ltp":1.51,"tv":2868.49,"id":6374165}]}]}
{"op":"mcm","clk":"1006116378","pt":1580593302532,"mc":[{"id":"1.168175448","rc":[{"trd":[[2.94,70.89],[2.96,88.6]],"batb":[[0,2.9,17.12],[1,2.88,2.05],[2,2.84,13.7]],"batl":[[1,3.1,2.05],[2,3.15,2.1]],"ltp":2.94,"tv":697.61,"id":5071877},{"trd":[[1.51,1121.01]],"batb":[[0,1.5,53.77],[1,1.49,71.3],[2,1.48,112.72]],"batl":[[0,1.52,158.23],[1,1.53,284.2],[2,1.54,241.47]],"ltp":1.51,"tv":2871.07,"id":6374165}],"tv":3568.68}]}
{"op":"mcm","clk":"1006116496","pt":1580593303530,"mc":[{"id":"1.168175448","rc":[{"batb":[[0,2.9,15.12],[2,2.86,2]],"ltp":2.94,"tv":697.61,"id":5071877}]}]}
{"op":"mcm","clk":"1006116705","pt":1580593305531,"mc":[{"id":"1.168175448","rc":[{"batl":[[0,3.1,2.05],[1,3.15,2.1],[2,95,15.9]],"ltp":2.94,"tv":697.61,"id":5071877},{"batb":[[0,1.5,74.03],[1,1.49,50.9]],"ltp":1.51,"tv":2871.07,"id":6374165}]}]}
{"op":"mcm","clk":"1006116789","pt":1580593306266,"mc":[{"id":"1.168175448","rc":[{"batl":[[0,2.98,9.28],[1,3.05,2],[2,3.1,2.05]],"ltp":2.94,"tv":697.61,"id":5071877}]}]}
{"op":"mcm","clk":"1006118155","pt":1580593316382,"mc":[{"id":"1.168175448","rc":[{"batl":[[0,2.98,9.5]],"ltp":2.94,"tv":697.61,"id":5071877}]}]}
{"op":"mcm","clk":"1006118205","pt":1580593316863,"mc":[{"id":"1.168175448","rc":[{"batb":[[2,2.86,2.04]],"ltp":2.94,"tv":697.61,"id":5071877}]}]}
{"op":"mcm","clk":"1006118735","pt":1580593321379,"mc":[{"id":"1.168175448","rc":[{"trd":[[2.92,281.97]],"ltp":2.92,"tv":704.61,"id":5071877},{"trd":[[1.52,815.22]],"batl":[[0,1.52,144.78]],"ltp":1.52,"tv":2884.52,"id":6374165}],"tv":3589.13}]}
{"op":"mcm","clk":"1006118874","pt":1580593322479,"mc":[{"id":"1.168175448","rc":[{"trd":[[1.52,1094.58]],"batb":[[0,1.51,20.26],[1,1.5,53.77],[2,1.49,50.9]],"batl":[[0,1.52,5.1]],"ltp":1.52,"tv":3163.88,"id":6374165}],"tv":3868.49}]}
{"op":"mcm","clk":"1006118988","pt":1580593323286,"mc":[{"id":"1.168175448","rc":[{"batb":[[2,2.86,2.18]],"batl":[[2,3.1,2]],"ltp":2.92,"tv":704.61,"id":5071877},{"batb":[[2,1.49,52.91]],"ltp":1.52,"tv":3163.88,"id":6374165}]}]}
{"op":"mcm","clk":"1006119114","pt":1580593324089,"mc":[{"id":"1.168175448","rc":[{"batb":[[0,2.9,18.17]],"ltp":2.92,"tv":704.61,"id":5071877},{"trd":[[1.51,1154.06]],"batb":[[0,1.51,3.74],[2,1.49,46.94]],"ltp":1.51,"tv":3196.93,"id":6374165}],"tv":3901.54}]}
{"op":"mcm","clk":"1006120260","pt":1580593333445,"mc":[{"id":"1.168175448","rc":[{"batb":[[0,1.51,4.24]],"ltp":1.51,"tv":3196.93,"id":6374165}]}]}
{"op":"mcm","clk":"1006120668","pt":1580593336478,"mc":[{"id":"1.168175448","rc":[{"batb":[[1,2.86,2.18],[2,2.84,2.22]],"ltp":2.92,"tv":704.61,"id":5071877},{"trd":[[1.52,1104.28]],"batl":[[0,1.53,284.45],[1,1.54,239.46],[2,1.55,2.1]],"ltp":1.52,"tv":3206.63,"id":6374165}],"tv":3911.24}]}
{"op":"mcm","clk":"1006122090","pt":1580593347368,"mc":[{"id":"1.168175448","rc":[{"batb":[[0,2.92,8.47],[1,2.9,18.17],[2,2.86,2.18]],"ltp":2.92,"tv":704.61,"id":5071877}]}]}
{"op":"mcm","clk":"1006122207","pt":1580593348103,"mc":[{"id":"1.168175448","rc":[{"batb":[[2,2.88,2.21]],"batl":[[2,3.1,2.05]],"ltp":2.92,"tv":704.61,"id":5071877}]}]}
{"op":"mcm","clk":"1006125710","pt":1580593375317,"mc":[{"id":"1.168175448","rc":[{"trd":[[2.92,297.7]],"batb":[[0,2.9,18.79],[1,2.86,2.18],[2,2.84,2.16]],"ltp":2.92,"tv":720.33,"id":5071877}],"tv":3926.96}]}
{"op":"mcm","clk":"1006126120","pt":1580593378489,"mc":[{"id":"1.168175448","rc":[{"batb":[[0,2.9,18.17]],"batl":[[0,2.98,10.2]],"ltp":2.92,"tv":720.33,"id":5071877}]}]}
{"op":"mcm","clk":"1006129748","pt":1580593406410,"mc":[{"id":"1.168175448","rc":[{"batl":[[2,1.55,4.1]],"ltp":1.52,"tv":3206.63,"id":6374165}]}]}
{"op":"mcm","clk":"1006133464","pt":1580593435961,"mc":[{"id":"1.168175448","rc":[{"batb":[[0,2.9,18.79],[2,2.84,2]],"ltp":2.92,"tv":720.33,"id":5071877}]}]}
{"op":"mcm","clk":"1006134596","pt":1580593445060,"mc":[{"id":"1.168175448","rc":[{"batb":[[0,2.9,18.17],[2,2.84,2.22]],"batl":[[2,3.1,2]],"ltp":2.92,"tv":720.33,"id":5071877}]}]}
{"op":"mcm","clk":"1006135543","pt":1580593452479,"mc":[{"id":"1.168175448","rc":[{"batb":[[0,2.92,2],[1,2.9,20.23],[2,2.86,2.18]],"batl":[[2,3.1,2.05]],"ltp":2.92,"tv":720.33,"id":5071877},{"trd":[[1.51,1162.56]],"batb":[[0,1.5,53.77],[1,1.49,44.93],[2,1.48,112.72]],"batl":[[0,1.51,36.71],[1,1.53,286.46],[2,1.54,241.46]],"ltp":1.51,"tv":3215.12,"id":6374165}],"tv":3935.46}]}
{"op":"mcm","clk":"1006135671","pt":1580593453490,"mc":[{"id":"1.168175448","rc":[{"batb":[[2,2.84,13.7]],"ltp":2.92,"tv":720.33,"id":5071877},{"trd":[[1.51,1232.66]],"batl":[[0,1.51,1.66],[1,1.53,284.45],[2,1.54,239.46]],"ltp":1.51,"tv":3285.22,"id":6374165}],"tv":4005.56}]}
{"op":"mcm","clk":"1006135784","pt":1580593454381,"mc":[{"id":"1.168175448","rc":[{"batb":[[0,2.9,18.17],[1,2.86,2.18],[2,2.84,2.1]],"ltp":2.92,"tv":720.33,"id":5071877}]}]}
{"op":"mcm","clk":"1006136422","pt":1580593459184,"mc":[{"id":"1.168175448","rc":[{"batb":[[1,2.88,2],[2,2.86,2.18]],"ltp":2.92,"tv":720.33,"id":5071877},{"batl":[[1,1.52,34.48],[2,1.53,284.2]],"ltp":1.51,"tv":3285.22,"id":6374165}]}]}
{"op":"mcm","clk":"1006138748","pt":1580593477102,"mc":[{"id":"1.168175448","rc":[{"batl":[[2,3.1,2]],"ltp":2.92,"tv":720.33,"id":5071877},{"batb":[[0,1.5,137.79]],"ltp":1.51,"tv":3285.22,"id":6374165}]}]}
{"op":"mcm","clk":"1006139191","pt":1580593480216,"mc":[{"id":"1.168175448","rc":[{"batl":[[1,1.52,68.56]],"ltp":1.51,"tv":3285.22,"id":6374165}]}]}
{"op":"mcm","clk":"1006139302","pt":1580593481019,"mc":[{"id":"1.168175448","rc":[{"batb":[[0,1.5,140.31]],"ltp":1.51,"tv":3285.22,"id":6374165}]}]}
{"op":"mcm","clk":"1006140552","pt":1580593491342,"mc":[{"id":"1.168175448","rc":[{"batb":[[2,2.86,2.04]],"batl":[[2,3.1,2.05]],"ltp":2.92,"tv":720.33,"id":5071877},{"trd":[[1.5,429.81]],"batb":[[0,1.5,40.31]],"ltp":1.5,"tv":3485.22,"id":6374165}],"tv":4205.56}]}
{"op":"mcm","clk":"1006141744","pt":1580593500452,"mc":[{"id":"1.168175448","rc":[{"batb":[[2,2.86,2.18]],"ltp":2.92,"tv":720.33,"id":5071877}]}]}
{"op":"mcm","clk":"1006145231","pt":1580593527430,"mc":[{"id":"1.168175448","rc":[{"trd":[[2.98,10.2]],"batl":[[0,3.05,2],[1,3.1,2.05],[2,95,15.9]],"ltp":2.98,"tv":730.53,"id":5071877},{"trd":[[1.5,530.72]],"batb":[[0,1.49,44.93],[1,1.48,112.72],[2,1.47,2.01]],"batl":[[0,1.5,32.55],[1,1.51,1.66],[2,1.52,68.56]],"ltp":1.5,"tv":3586.13,"id":6374165}],"tv":4316.66}]}
{"op":"mcm","clk":"1006145394","pt":1580593528526,"mc":[{"id":"1.168175448","rc":[{"batb":[[0,2.92,2.19],[1,2.9,20.17],[2,2.88,13.41]],"batl":[[0,3.15,2.1],[1,3.2,2.03]],"ltp":2.98,"tv":730.53,"id":5071877},{"trd":[[1.5,593.16]],"batb":[[1,1.48,110.71]],"batl":[[0,1.5,1.33]],"ltp":1.5,"tv":3648.57,"id":6374165}],"tv":4379.1}]}
{"op":"mcm","clk":"1006145507","pt":1580593529307,"mc":[{"id":"1.168175448","rc":[{"batb":[[0,2.9,18.17],[1,2.88,2.21],[2,2.86,2.18]],"ltp":2.98,"tv":730.53,"id":5071877}]}]}
{"op":"mcm","clk":"1006146638","pt":1580593538424,"mc":[{"id":"1.168175448","rc":[{"trd":[[3,9.28]],"batb":[[2,2.86,2]],"batl":[[0,3,6.3],[1,3.1,2.05],[2,3.15,2.1]],"ltp":3.0,"tv":731.19,"id":5071877},{"trd":[[1.5,594.48]],"batb":[[1,1.48,112.72]],"batl":[[0,1.51,1.66],[1,1.52,68.56],[2,1.53,284.2]],"ltp":1.5,"tv":3649.9,"id":6374165}],"tv":4381.09}]}
{"op":"mcm","clk":"1006147240","pt":1580593543727,"mc":[{"id":"1.168175448","rc":[{"batl":[[0,3,5.63]],"ltp":3.0,"tv":731.19,"id":5071877}]}]}
{"op":"mcm","clk":"1006148296","pt":1580593553119,"mc":[{"id":"1.168175448","rc":[{"batb":[[2,2.86,2.11]],"batl":[[0,3,6.3]],"ltp":3.0,"tv":731.19,"id":5071877}]}]}
{"op":"mcm","clk":"1006148995","pt":1580593559121,"mc":[{"id":"1.168175448","rc":[{"batl":[[0,3,13.87]],"ltp":3.0,"tv":731.19,"id":5071877}]}]}
{"op":"mcm","clk":"1006149666","pt":1580593564259,"mc":[{"id":"1.168175448","rc":[{"trd":[[3,23.15]],"batb":[[2,2.86,2.04]],"batl":[[0,3.15,2.1],[1,3.2,2.03],[2,95,15.9]],"ltp":3.0,"tv":745.06,"id":5071877},{"trd":[[1.5,622.24]],"batb":[[1,1.48,110.71],[2,1.47,2]],"ltp":1.5,"tv":3677.65,"id":6374165}],"tv":4422.71}]}
{"op":"mcm","clk":"1006150317","pt":1580593569557,"mc":[{"id":"1.168175448","rc":[{"batb":[[0,2.92,2.19],[1,2.9,20.23]],"ltp":3.0,"tv":745.06,"id":5071877},{"batl":[[0,1.51,35.89],[1,1.52,34.33],[2,1.53,286.21]],"ltp":1.5,"tv":3677.65,"id":6374165}]}]}
{"op":"mcm","clk":"1006150431","pt":1580593570348,"mc":[{"id":"1.168175448","rc":[{"batb":[[2,2.86,15.59]],"batl":[[1,3.2,2]],"ltp":3.0,"tv":745.06,"id":5071877}]}]}
{"op":"mcm","clk":"1006150686","pt":1580593572545,"mc":[{"id":"1.168175448","rc":[{"batb":[[2,2.86,13.55]],"ltp":3.0,"tv":745.06,"id":5071877},{"trd":[[1.49,217.56]],"batb":[[0,1.48,111.11],[1,1.46,131.4],[2,1.45,2.01]],"ltp":1.49,"tv":3766.71,"id":6374165}],"tv":4511.77}]}
{"op":"mcm","clk":"1006150771","pt":1580593573332,"mc":[{"id":"1.168175448","rc":[{"batb":[[0,2.98,16.7],[1,2.94,2.09],[2,2.92,2.19]],"batl":[[0,3.2,2],[1,3.25,2.02]],"ltp":3.0,"tv":745.06,"id":5071877},{"batb":[[0,1.48,110.71],[1,1.47,48.03],[2,1.46,131.4]],"ltp":1.49,"tv":3766.71,"id":6374165}]}]}
{"op":"mcm","clk":"1006150939","pt":1580593574950,"mc":[{"id":"1.168175448","rc":[{"batb":[[1,2.96,2],[2,2.94,2.09]],"ltp":3.0,"tv":745.06,"id":5071877},{"batl":[[0,1.5,14.49],[1,1.51,35.89],[2,1.52,36.34]],"ltp":1.49,"tv":3766.71,"id":6374165}]}]}
{"op":"mcm","clk":"1006151485","pt":1580593579563,"mc":[{"id":"1.168175448","rc":[{"batb":[[1,2.94,2.09],[2,2.88,13.41]],"batl":[[1,95,15.9],[2,990,2.2]],"ltp":3.0,"tv":745.06,"id":5071877},{"batl":[[0,1.51,35.89],[1,1.52,34.33],[2,1.53,286.21]],"ltp":1.49,"tv":3766.71,"id":6374165}]}]}
{"op":"mcm","clk":"1006151512","pt":1580593579766,"mc":[{"id":"1.168175448","rc":[{"batb":[[2,2.92,2.19]],"batl":[[1,3.25,2.02],[2,95,15.9]],"ltp":3.0,"tv":745.06,"id":5071877}]}]}
{"op":"mcm","clk":"1006153492","pt":1580593595526,"mc":[{"id":"1.168175448","rc":[{"trd":[[2.98,41.47],[3.1,40.87]],"batb":[[0,2.98,1.07],[1,2.92,2.07],[2,2.9,2.06]],"ltp":2.98,"tv":817.2,"id":5071877},{"trd":[[1.48,322.55]],"batb":[[0,1.48,25.11]],"ltp":1.48,"tv":3852.31,"id":6374165}],"tv":4669.52}]}
{"op":"mcm","clk":"1006153634","pt":1580593596310,"mc":[{"id":"1.168175448","rc":[{"batb":[[0,2.94,12.79]],"batl":[[0,3.15,2.1],[1,3.2,2],[2,3.25,2.02]],"ltp":2.98,"tv":817.2,"id":5071877},{"batb":[[0,1.49,31.74],[1,1.48,25.11],[2,1.47,2.01]],"ltp":1.48,"tv":3852.31,"id":6374165}]}]}
{"op":"mcm","clk":"1006153781","pt":1580593597317,"mc":[{"id":"1.168175448","rc":[{"batl":[[1,3.2,2.03]],"ltp":2.98,"tv":817.2,"id":5071877},{"trd":[[1.49,246.54]],"batb":[[0,1.49,17.25]],"ltp":1.49,"tv":3881.3,"id":6374165}],"tv":4698.51}]}
{"op":"mcm","clk":"1006153880","pt":1580593597995,"mc":[{"id":"1.168175448","rc":[{"batb":[[0,2.94,20.06]],"batl":[[0,3.2,2.03],[1,3.25,2.02],[2,95,15.9]],"ltp":2.98,"tv":817.2,"id":5071877},{"batb":[[0,1.48,25.11],[1,1.47,64.9],[2,1.46,131.4]],"ltp":1.49,"tv":3881.3,"id":6374165}]}]}
{"op":"mcm","clk":"1006154181","pt":1580593600411,"mc":[{"id":"1.168175448","rc":[{"batl":[[0,1.5,41.95],[1,1.51,35.89],[2,1.52,34.33]],"ltp":1.49,"tv":3881.3,"id":6374165}]}]}
{"op":"mcm","clk":"1006154297","pt":1580593601407,"mc":[{"id":"1.168175448","rc":[{"batb":[[0,2.96,2],[1,2.94,22.15],[2,2.92,2.07]],"ltp":2.98,"tv":817.2,"id":5071877},{"batl":[[2,1.52,36.34]],"ltp":1.49,"tv":3881.3,"id":6374165}]}]}
{"op":"mcm","clk":"1006154537","pt":1580593603453,"mc":[{"id":"1.168175448","rc":[{"batb":[[2,2.9,13.27]],"ltp":2.98,"tv":817.2,"id":5071877}]}]}
{"op":"mcm","clk":"1006158183","pt":1580593633515,"mc":[{"id":"1.168175448","rc":[{"trd":[[1.5,702.47]],"batl":[[0,1.5,1.83],[1,1.51,110.1],[2,1.52,34.33]],"ltp":1.5,"tv":3961.54,"id":6374165}],"tv":4778.75}]}
{"op":"mcm","clk":"1006158301","pt":1580593634405,"mc":[{"id":"1.168175448","rc":[{"batb":[[0,2.94,20.06],[1,2.92,2.19],[2,2.9,2.06]],"ltp":2.98,"tv":817.2,"id":5071877}]}]}
{"op":"mcm","clk":"1006159911","pt":1580593649342,"mc":[{"id":"1.168175448","rc":[{"batb":[[0,1.48,99.32]],"ltp":1.5,"tv":3961.54,"id":6374165}]}]}
{"op":"mcm","clk":"1006160013","pt":1580593650343,"mc":[{"id":"1.168175448","rc":[{"trd":[[2.96,107.26],[3,24.07]],"ltp":2.96,"tv":836.78,"id":5071877},{"trd":[[1.5,704.31],[1.51,1269.24]],"batl":[[0,1.51,73.52],[1,1.52,34.33],[2,1.53,244.26]],"ltp":1.51,"tv":3999.95,"id":6374165}],"tv":4836.74}]}
{"op":"mcm","clk":"1006162002","pt":1580593668464,"mc":[{"id":"1.168175448","rc":[{"trd":[[2.94,90.95]],"batb":[[0,2.92,2.19],[1,2.88,13.41],[2,2.86,13.55]],"batl":[[1,95,15.9],[2,990,2.2]],"ltp":2.94,"tv":856.85,"id":5071877},{"trd":[[1.51,1416.28],[1.52,1234.21]],"batb":[[0,1.5,2],[1,1.49,2.01],[2,1.48,99.32]],"batl":[[0,1.53,242.25],[1,1.54,239.46],[2,1.55,4.1]],"ltp":1.52,"tv":4276.92,"id":6374165}],"tv":5133.77}]}
{"op":"mcm","clk":"1006162120","pt":1580593669562,"mc":[{"id":"1.168175448","rc":[{"batb":[[0,2.86,24.68],[1,2.84,2.22],[2,2.82,15.88]],"batl":[[0,3.15,2.1],[1,3.2,2.03],[2,3.25,2.02]],"ltp":2.94,"tv":856.85,"id":5071877},{"batb":[[0,1.49,56.67],[1,1.48,99.32],[2,1.47,2.01]],"ltp":1.52,"tv":4276.92,"id":6374165}]}]}
{"op":"mcm","clk":"1006162160","pt":1580593669973,"mc":[{"id":"1.168175448","rc":[{"batb":[[1,2.82,15.88],[2,2.8,35.89]],"ltp":2.94,"tv":856.85,"id":5071877}]}]}
{"op":"mcm","clk":"1006162863","pt":1580593676468,"mc":[{"id":"1.168175448","rc":[{"batb":[[0,2.82,15.88],[1,2.8,35.89],[2,2.74,31.47]],"batl":[[0,3.2,2.03],[1,3.25,2.02],[2,95,15.9]],"ltp":2.94,"tv":856.85,"id":5071877},{"trd":[[1.48,329.21],[1.49,359.88]],"batb":[[0,1.48,95.99],[1,1.46,131.39],[2,1.45,58.03]],"ltp":1.48,"tv":4396.92,"id":6374165}],"tv":5253.77}]}
{"op":"mcm","clk":"1006162979","pt":1580593677358,"mc":[{"id":"1.168175448","rc":[{"batb":[[0,2.98,16.85],[1,2.94,2.09],[2,2.92,2.07]],"ltp":2.94,"tv":856.85,"id":5071877},{"batb":[[1,1.47,47.72],[2,1.46,131.39]],"batl":[[0,1.53,244.26],[1,1.54,241.47],[2,1.55,2]],"ltp":1.48,"tv":4396.92,"id":6374165}]}]}
{"op":"mcm","clk":"1006164555","pt":1580593691471,"mc":[{"id":"1.168175448","rc":[{"trd":[[2.98,72.83]],"batb":[[0,2.98,1.18],[2,2.88,13.41]],"batl":[[1,95,15.9],[2,990,2.2]],"ltp":2.98,"tv":888.21,"id":5071877},{"trd":[[1.48,520.77]],"batb":[[0,1.47,47.93],[1,1.46,129.39],[2,1.45,2.01]],"batl":[[1,1.54,239.46]],"ltp":1.48,"tv":4588.49,"id":6374165}],"tv":5476.7}]}
{"op":"mcm","clk":"1006164692","pt":1580593692567,"mc":[{"id":"1.168175448","rc":[{"batb":[[1,2.84,15.92],[2,2.82,15.88]],"batl":[[0,3.25,2.02],[1,3.3,2.05],[2,95,15.9]],"ltp":2.98,"tv":888.21,"id":5071877},{"batl":[[1,1.54,241.47]],"ltp":1.48,"tv":4588.49,"id":6374165}]}]}
{"op":"mcm","clk":"1006164761","pt":1580593693278,"mc":[{"id":"1.168175448","rc":[{"batb":[[0,2.9,25.01],[1,2.86,2.04],[2,2.84,15.92]],"ltp":2.98,"tv":888.21,"id":5071877},{"batb":[[0,1.47,79.42]],"batl":[[0,1.53,242.25],[1,1.54,239.46],[2,1.55,4.1]],"ltp":1.48,"tv":4588.49,"id":6374165}]}]}
{"op":"mcm","clk":"1006165086","pt":1580593696393,"mc":[{"id":"1.168175448","rc":[{"batb":[[0,1.48,2.2],[1,1.47,79.21],[2,1.46,131.4]],"ltp":1.48,"tv":4588.49,"id":6374165}]}]}
{"op":"mcm","clk":"1006165232","pt":1580593697388,"mc":[{"id":"1.168175448","rc":[{"batl":[[0,3.05,62.08],[1,3.15,2.04],[2,3.2,2.03]],"ltp":2.98,"tv":888.21,"id":5071877}]}]}
{"op":"mcm","clk":"1006165336","pt":1580593698273,"mc":[{"id":"1.168175448","rc":[{"batb":[[1,2.88,2.21],[2,2.86,2.04]],"ltp":2.98,"tv":888.21,"id":5071877},{"batl":[[0,1.52,90.87],[1,1.53,242.25],[2,1.54,241.47]],"ltp":1.48,"tv":4588.49,"id":6374165}]}]}
{"op":"mcm","clk":"1006166436","pt":1580593708428,"mc":[{"id":"1.168175448","rc":[{"batb":[[2,2.86,2.18]],"ltp":2.98,"tv":888.21,"id":5071877},{"trd":[[1.52,1410.75]],"batb":[[0,1.48,76.41]],"batl":[[0,1.52,2.6]],"ltp":1.52,"tv":4765.03,"id":6374165}],"tv":5653.24}]}
{"op":"mcm","clk":"1006166463","pt":1580593708693,"mc":[{"id":"1.168175448","rc":[{"batb":[[1,2.86,2.18],[2,2.84,15.92]],"ltp":2.98,"tv":888.21,"id":5071877}]}]}
{"op":"mcm","clk":"1006166861","pt":1580593712489,"mc":[{"id":"1.168175448","rc":[{"batl":[[0,3.1,62.08],[1,3.2,2.03],[2,3.25,2.02]],"ltp":2.98,"tv":888.21,"id":5071877}]}]}
{"op":"mcm","clk":"1006167215","pt":1580593715523,"mc":[{"id":"1.168175448","rc":[{"trd":[[1.48,673.61]],"batb":[[0,1.47,79.21],[1,1.46,129.39],[2,1.45,2.01]],"ltp":1.48,"tv":4917.86,"id":6374165}],"tv":5806.08}]}
{"op":"mcm","clk":"1006168624","pt":1580593728415,"mc":[{"id":"1.168175448","rc":[{"batb":[[2,2.84,13.7]],"batl":[[2,95,15.9]],"ltp":2.98,"tv":888.21,"id":5071877}]}]}
{"op":"mcm","clk":"1006168661","pt":1580593728792,"mc":[{"id":"1.168175448","rc":[{"batb":[[2,2.84,15.86]],"batl":[[2,3.25,2.02]],"ltp":2.98,"tv":888.21,"id":5071877}]}]}
{"op":"mcm","clk":"1006170351","pt":1580593744409,"mc":[{"id":"1.168175448","rc":[{"batb":[[2,2.84,13.7]],"batl":[[2,95,15.9]],"ltp":2.98,"tv":888.21,"id":5071877},{"batl":[[0,1.52,86.65]],"ltp":1.48,"tv":4917.86,"id":6374165}]}]}
{"op":"mcm","clk":"1006170477","pt":1580593745425,"mc":[{"id":"1.168175448","rc":[{"batb":[[1,2.88,2.13],[2,2.86,15.73]],"batl":[[2,3.25,2.02]],"ltp":2.98,"tv":888.21,"id":5071877},{"trd":[[1.52,1579.6]],"batl":[[0,1.52,2.23]],"ltp":1.52,"tv":5086.72,"id":6374165}],"tv":5974.93}]}
{"op":"mcm","clk":"1006170582","pt":1580593746418,"mc":[{"id":"1.168175448","rc":[{"batb":[[1,2.86,2.18],[2,2.84,15.92]],"ltp":2.98,"tv":888.21,"id":5071877}]}]}
{"op":"mcm","clk":"1006171484","pt":1580593754535,"mc":[{"id":"1.168175448","rc":[{"batb":[[0,1.48,225.66],[1,1.47,79.21],[2,1.46,131.4]],"ltp":1.52,"tv":5086.72,"id":6374165}]}]}
{"op":"mcm","clk":"1006171711","pt":1580593756553,"mc":[{"id":"1.168175448","rc":[{"trd":[[2.92,307.3]],"ltp":2.92,"tv":897.81,"id":5071877},{"trd":[[1.52,1581.83]],"batl":[[0,1.53,242.25],[1,1.54,239.46],[2,1.55,4.1]],"ltp":1.52,"tv":5088.94,"id":6374165}],"tv":5986.76}]}
{"op":"mcm","clk":"1006172370","pt":1580593762458,"mc":[{"id":"1.168175448","rc":[{"batb":[[0,2.96,2.13],[1,2.94,2.09],[2,2.9,25.01]],"ltp":2.92,"tv":897.81,"id":5071877},{"trd":[[1.5,1268.02]],"batl":[[0,1.5,224.79],[1,1.52,2.01],[2,1.53,244.26]],"ltp":1.5,"tv":5652.66,"id":6374165}],"tv":6550.47}]}
{"op":"mcm","clk":"1006173200","pt":1580593770560,"mc":[{"id":"1.168175448","rc":[{"batl":[[0,1.49,2.8],[1,1.5,224.79],[2,1.51,2.01]],"ltp":1.5,"tv":5652.66,"id":6374165}]}]}
{"op":"mcm","clk":"1006174037","pt":1580593779281,"mc":[{"id":"1.168175448","rc":[{"batl":[[1,1.5,1205.79]],"ltp":1.5,"tv":5652.66,"id":6374165}]}]}
{"op":"mcm","clk":"1006174292","pt":1580593781891,"mc":[{"id":"1.168175448","rc":[{"trd":[[1.48,895.42]],"batb":[[0,1.48,114.75]],"ltp":1.48,"tv":5874.47,"id":6374165}],"tv":6772.28}]}
{"op":"mcm","clk":"1006174449","pt":1580593783555,"mc":[{"id":"1.168175448","rc":[{"trd":[[1.49,365.48]],"batl":[[0,1.5,1205.79],[1,1.51,58.81],[2,1.52,170.05]],"ltp":1.49,"tv":5880.07,"id":6374165}],"tv":6777.88}]}
{"op":"mcm","clk":"1006174548","pt":1580593784493,"mc":[{"id":"1.168175448","rc":[{"trd":[[3.05,13.33]],"batb":[[1,2.94,16.39],[2,2.88,13.41]],"ltp":3.05,"tv":911.14,"id":5071877},{"trd":[[1.49,392.78]],"batb":[[0,1.49,1.44],[1,1.48,114.75]],"ltp":1.49,"tv":5907.37,"id":6374165}],"tv":6818.51}]}
{"op":"mcm","clk":"1006174764","pt":1580593786480,"mc":[{"id":"1.168175448","rc":[{"batb":[[0,2.98,16.23],[1,2.96,2.13],[2,2.94,2.09]],"ltp":3.05,"tv":911.14,"id":5071877},{"batb":[[0,1.48,114.75],[1,1.47,48.99]],"ltp":1.49,"tv":5907.37,"id":6374165}]}]}
{"op":"mcm","clk":"1006175300","pt":1580593792189,"mc":[{"id":"1.168175448","rc":[{"batl":[[0,1.49,74.21],[1,1.5,1205.79],[2,1.51,60.82]],"ltp":1.49,"tv":5907.37,"id":6374165}]}]}
{"op":"mcm","clk":"1006176131","pt":1580593800497,"mc":[{"id":"1.168175448","rc":[{"trd":[[1.49,538.3]],"batl":[[0,1.49,1.45]],"ltp":1.49,"tv":6052.89,"id":6374165}],"tv":6964.03}]}
{"op":"mcm","clk":"1006176170","pt":1580593800802,"mc":[{"id":"1.168175448","rc":[{"batl":[[2,1.51,58.81]],"ltp":1.49,"tv":6052.89,"id":6374165}]}]}
{"op":"mcm","clk":"1006176656","pt":1580593805491,"mc":[{"id":"1.168175448","rc":[{"trd":[[2.98,98.04]],"batb":[[0,2.98,3.63],[1,2.94,2.09],[2,2.92,2.19]],"batl":[[0,3.1,64.08],[1,3.15,2.1]],"ltp":2.98,"tv":936.35,"id":5071877},{"trd":[[1.49,541.19],[1.5,3679.88]],"batb":[[0,1.5,1756.35],[1,1.48,116.76],[2,1.47,51]],"batl":[[0,1.51,58.81],[1,1.52,168.04],[2,1.53,244.26]],"ltp":1.5,"tv":8467.64,"id":6374165}],"tv":9403.99}]}
{"op":"mcm","clk":"1006176879","pt":1580593807165,"mc":[{"id":"1.168175448","rc":[{"batb":[[0,2.94,15.35],[1,2.92,2.19],[2,2.9,2.06]],"batl":[[2,95,15.9]],"ltp":2.98,"tv":936.35,"id":5071877},{"trd":[[1.5,3770.75]],"batb":[[0,1.5,1710.92],[1,1.49,26.65],[2,1.48,116.76]],"ltp":1.5,"tv":8558.51,"id":6374165}],"tv":9494.86}]}
{"op":"mcm","clk":"1006177383","pt":1580593812558,"mc":[{"id":"1.168175448","rc":[{"batl":[[1,3.15,2]],"ltp":2.98,"tv":936.35,"id":5071877},{"trd":[[1.5,3944.7]],"batb":[[0,1.5,1623.94]],"batl":[[0,1.52,168.04],[1,1.53,244.26],[2,1.54,241.47]],"ltp":1.5,"tv":8732.46,"id":6374165}],"tv":9668.81}]}
{"op":"mcm","clk":"1006177434","pt":1580593812974,"mc":[{"id":"1.168175448","rc":[{"batb":[[1,2.9,2.06],[2,2.88,2.21]],"ltp":2.98,"tv":936.35,"id":5071877},{"batl":[[1,1.53,301.06]],"ltp":1.5,"tv":8732.46,"id":6374165}]}]}
{"op":"mcm","clk":"1006177681","pt":1580593815413,"mc":[{"id":"1.168175448","rc":[{"batb":[[2,1.48,268.21]],"ltp":1.5,"tv":8732.46,"id":6374165}]}]}
{"op":"mcm","clk":"1006178615","pt":1580593824524,"mc":[{"id":"1.168175448","rc":[{"trd":[[2.94,120.47]],"batb":[[0,2.9,2.65],[1,2.84,13.7],[2,2.82,13.85]],"batl":[[1,95,15.9],[2,990,2.2]],"ltp":2.94,"tv":965.87,"id":5071877},{"batl":[[1,1.53,226.85]],"ltp":1.5,"tv":8732.46,"id":6374165}],"tv":9698.33}]}
{"op":"mcm","clk":"1006178708","pt":1580593825401,"mc":[{"id":"1.168175448","rc":[{"batb":[[0,2.88,2],[1,2.86,2.04]],"batl":[[1,3.15,2.1],[2,95,15.9]],"ltp":2.94,"tv":965.87,"id":5071877}]}]}
{"op":"mcm","clk":"1006178746","pt":1580593825714,"mc":[{"id":"1.168175448","rc":[{"trd":[[1.5,3944.73]],"batb":[[0,1.5,1623.93]],"ltp":1.5,"tv":8732.49,"id":6374165}],"tv":9698.36}]}
{"op":"mcm","clk":"1006178838","pt":1580593826700,"mc":[{"id":"1.168175448","rc":[{"batb":[[1,2.86,27.28]],"ltp":2.94,"tv":965.87,"id":5071877},{"batb":[[1,1.49,55.6]],"ltp":1.5,"tv":8732.49,"id":6374165}]}]}
{"op":"mcm","clk":"1006179499","pt":1580593833539,"mc":[{"id":"1.168175448","rc":[{"batb":[[1,2.86,25.24]],"batl":[[1,95,15.9],[2,990,2.2]],"ltp":2.94,"tv":965.87,"id":5071877}]}]}
{"op":"mcm","clk":"1006179525","pt":1580593833701,"mc":[{"id":"1.168175448","rc":[{"batb":[[1,2.86,27.42]],"batl":[[1,3.15,2.1],[2,95,15.9]],"ltp":2.94,"tv":965.87,"id":5071877}]}]}
{"op":"mcm","clk":"1006180401","pt":1580593842536,"mc":[{"id":"1.168175448","rc":[{"batb":[[1,2.86,25.24]],"batl":[[1,95,15.9],[2,990,2.2]],"ltp":2.94,"tv":965.87,"id":5071877},{"trd":[[1.5,4508.74]],"batb":[[0,1.49,55.6],[1,1.48,266.2],[2,1.47,2.01]],"batl":[[0,1.5,3033.84],[1,1.52,170.05],[2,1.53,228.86]],"ltp":1.5,"tv":9296.5,"id":6374165}],"tv":10262.37}]}
{"op":"mcm","clk":"1006180480","pt":1580593843420,"mc":[{"id":"1.168175448","rc":[{"batb":[[0,2.96,2.13],[1,2.94,2.09],[2,2.88,13.41]],"batl":[[0,3.1,62.08],[1,3.15,2.1],[2,3.2,2]],"ltp":2.94,"tv":965.87,"id":5071877}]}]}
{"op":"mcm","clk":"1006180514","pt":1580593843831,"mc":[{"id":"1.168175448","rc":[{"batl":[[1,1.51,151.45],[2,1.52,170.05]],"ltp":1.5,"tv":9296.5,"id":6374165}]}]}
{"op":"mcm","clk":"1006180896","pt":1580593847521,"mc":[{"id":"1.168175448","rc":[{"batb":[[2,2.92,2.19]],"batl":[[0,3.1,64.13]],"ltp":2.94,"tv":965.87,"id":5071877},{"batb":[[0,1.5,1905.94],[1,1.49,55.6],[2,1.48,268.21]],"batl":[[0,1.51,151.45],[1,1.52,168.04],[2,1.53,228.86]],"ltp":1.5,"tv":9296.5,"id":6374165}]}]}
{"op":"mcm","clk":"1006180988","pt":1580593848458,"mc":[{"id":"1.168175448","rc":[{"batb":[[0,2.92,2.19],[1,2.9,2],[2,2.86,25.24]],"ltp":2.94,"tv":965.87,"id":5071877}]}]}
{"op":"mcm","clk":"1006181100","pt":1580593849552,"mc":[{"id":"1.168175448","rc":[{"batb":[[0,2.88,2.21],[1,2.86,27.42],[2,2.82,13.85]],"batl":[[2,95,15.9]],"ltp":2.94,"tv":965.87,"id":5071877},{"trd":[[1.5,4811.64]],"batb":[[0,1.5,1754.49]],"batl":[[0,1.52,168.04],[1,1.53,226.85],[2,1.54,241.47]],"ltp":1.5,"tv":9599.4,"id":6374165}],"tv":10565.27}]}
{"op":"mcm","clk":"1006181399","pt":1580593852455,"mc":[{"id":"1.168175448","rc":[{"trd":[[1.5,6857.33]],"batb":[[0,1.5,731.1]],"ltp":1.5,"tv":11645.09,"id":6374165}],"tv":12610.96}]}
{"op":"mcm","clk":"1006181876","pt":1580593857149,"mc":[{"id":"1.168175448","rc":[{"batb":[[1,2.86,27.35]],"batl":[[1,3.15,2]],"ltp":2.94,"tv":965.87,"id":5071877}]}]}
{"op":"mcm","clk":"1006182163","pt":1580593860467,"mc":[{"id":"1.168175448","rc":[{"batl":[[0,2.98,62.08],[1,3.05,2.1],[2,3.1,2]],"ltp":2.94,"tv":965.87,"id":5071877}]}]}
{"op":"mcm","clk":"1006182254","pt":1580593861452,"mc":[{"id":"1.168175448","rc":[{"batb":[[0,2.86,25.24],[1,2.84,2.04],[2,2.82,2.03]],"ltp":2.94,"tv":965.87,"id":5071877},{"trd":[[1.52,1912.79]],"batb":[[0,1.5,731.12]],"batl":[[0,1.52,2.56]],"ltp":1.52,"tv":11976.04,"id":6374165}],"tv":12941.92}]}
{"op":"mcm","clk":"1006183499","pt":1580593874381,"mc":[{"id":"1.168175448","rc":[{"batb":[[0,1.51,164.68],[1,1.5,731.12],[2,1.49,55.6]],"ltp":1.52,"tv":11976.04,"id":6374165}]}]}
{"op":"mcm","clk":"1006183629","pt":1580593875473,"mc":[{"id":"1.168175448","rc":[{"batl":[[2,3.1,2.05]],"ltp":2.94,"tv":965.87,"id":5071877},{"trd":[[1.52,1917.64]],"batb":[[2,1.49,57.6]],"batl":[[0,1.53,226.99],[1,1.54,239.46],[2,1.55,4.1]],"ltp":1.52,"tv":11980.9,"id":6374165}],"tv":12946.77}]}
{"op":"mcm","clk":"1006185067","pt":1580593889476,"mc":[{"id":"1.168175448","rc":[{"batl":[[2,3.1,2]],"ltp":2.94,"tv":965.87,"id":5071877},{"batb":[[1,1.49,57.62],[2,1.48,268.21]],"ltp":1.52,"tv":11980.9,"id":6374165}]}]}
{"op":"mcm","clk":"1006185650","pt":1580593895310,"mc":[{"id":"1.168175448","rc":[{"batb":[[0,1.51,168.04]],"ltp":1.52,"tv":11980.9,"id":6374165}]}]}
{"op":"mcm","clk":"1006185774","pt":1580593896504,"mc":[{"id":"1.168175448","rc":[{"trd":[[2.98,160.11]],"batb":[[0,2.96,2.13],[1,2.94,2.09],[2,2.88,13.41]],"batl":[[0,3.15,2.04],[1,3.2,2.03],[2,95,15.9]],"ltp":2.98,"tv":1027.95,"id":5071877},{"trd":[[1.5,6980.69],[1.51,1752.36]],"batb":[[0,1.49,55.6],[1,1.48,266.2],[2,1.47,2.01]],"batl":[[0,1.5,4648.38],[1,1.52,2.14],[2,1.53,228.86]],"ltp":1.5,"tv":12440.35,"id":6374165}],"tv":13468.3}]}
{"op":"mcm","clk":"1006186816","pt":1580593906485,"mc":[{"id":"1.168175448","rc":[{"batb":[[1,1.47,268.21],[2,1.46,131.4]],"batl":[[1,1.52,170.18]],"ltp":1.5,"tv":12440.35,"id":6374165}]}]}
{"op":"mcm","clk":"1006186828","pt":1580593906588,"mc":[{"id":"1.168175448","rc":[{"trd":[[1.5,7544.7]],"batl":[[0,1.5,4366.37]],"ltp":1.5,"tv":13004.36,"id":6374165}],"tv":14032.31}]}
{"op":"mcm","clk":"1006187464","pt":1580593912537,"mc":[{"id":"1.168175448","rc":[{"batb":[[0,1.5,573.4],[1,1.49,55.6],[2,1.47,268.21]],"batl":[[0,1.52,170.18],[1,1.53,228.86],[2,1.54,239.46]],"ltp":1.5,"tv":13004.36,"id":6374165}]}]}
{"op":"mcm","clk":"1006187558","pt":1580593913527,"mc":[{"id":"1.168175448","rc":[{"batb":[[0,2.86,25.24],[1,2.84,2.22],[2,2.82,15.88]],"batl":[[0,3.1,2.05],[1,3.15,2.04]],"ltp":2.98,"tv":1027.95,"id":5071877},{"batb":[[2,1.48,2.01]],"batl":[[0,1.52,168.17],[1,1.53,226.85],[2,1.54,241.47]],"ltp":1.5,"tv":13004.36,"id":6374165}]}]}
{"op":"mcm","clk":"1006187567","pt":1580593913631,"mc":[{"id":"1.168175448","rc":[{"batb":[[0,2.88,2.21],[1,2.86,27.42],[2,2.84,2.22]],"ltp":2.98,"tv":1027.95,"id":5071877}]}]}
{"op":"mcm","clk":"1006187782","pt":1580593915917,"mc":[{"id":"1.168175448","rc":[{"batb":[[1,1.48,81.17],[2,1.47,268.21]],"ltp":1.5,"tv":13004.36,"id":6374165}]}]}
{"op":"mcm","clk":"1006188037","pt":1580593918422,"mc":[{"id":"1.168175448","rc":[{"batb":[[0,2.86,25.24],[1,2.84,2.22],[2,2.82,2.03]],"batl":[[0,2.98,2.03],[1,3,2],[2,3.1,2.05]],"ltp":2.98,"tv":1027.95,"id":5071877},{"trd":[[1.52,2253.99]],"batb":[[0,1.52,325.8],[1,1.5,575.4],[2,1.49,2.01]],"batl":[[0,1.53,226.85],[1,1.54,239.46],[2,1.55,4.1]],"ltp":1.52,"tv":13340.71,"id":6374165}],"tv":14368.66}]}
{"op":"mcm","clk":"1006188306","pt":1580593921331,"mc":[{"id":"1.168175448","rc":[{"batb":[[2,2.82,2]],"batl":[[2,95,15.9]],"ltp":2.98,"tv":1027.95,"id":5071877},{"batb":[[1,1.5,601.26]],"ltp":1.52,"tv":13340.71,"id":6374165}]}]}
{"op":"mcm","clk":"1006188609","pt":1580593924516,"mc":[{"id":"1.168175448","rc":[{"batl":[[1,95,15.9],[2,990,2.2]],"ltp":2.98,"tv":1027.95,"id":5071877},{"trd":[[1.52,2300]],"batb":[[0,1.52,302.8],[2,1.48,79.16]],"ltp":1.52,"tv":13386.71,"id":6374165}],"tv":14414.66}]}
{"op":"mcm","clk":"1006188622","pt":1580593924720,"mc":[{"id":"1.168175448","rc":[{"batl":[[1,3,2],[2,95,15.9]],"ltp":2.98,"tv":1027.95,"id":5071877},{"batb":[[2,1.49,2.01]],"ltp":1.52,"tv":13386.71,"id":6374165}]}]}
{"op":"mcm","clk":"1006188818","pt":1580593926538,"mc":[{"id":"1.168175448","rc":[{"trd":[[1.52,2643.58]],"batb":[[0,1.52,130.98]],"ltp":1.52,"tv":13730.29,"id":6374165}],"tv":14758.25}]}
{"op":"mcm","clk":"1006189418","pt":1580593932409,"mc":[{"id":"1.168175448","rc":[{"batl":[[2,3.7,14.56]],"ltp":2.98,"tv":1027.95,"id":5071877},{"trd":[[1.52,2714.46]],"batb":[[0,1.52,95.54]],"ltp":1.52,"tv":13801.18,"id":6374165}],"tv":14829.13}]}
{"op":"mcm","clk":"1006189469","pt":1580593932842,"mc":[{"id":"1.168175448","rc":[{"batb":[[2,2.82,2.03]],"ltp":2.98,"tv":1027.95,"id":5071877}]}]}
{"op":"mcm","clk":"1006189686","pt":1580593934926,"mc":[{"id":"1.168175448","rc":[{"batb":[[1,1.5,575.4]],"ltp":1.52,"tv":13801.18,"id":6374165}]}]}
{"op":"mcm","clk":"1006190147","pt":1580593939525,"mc":[{"id":"1.168175448","rc":[{"trd":[[2.98,162.14],[3,26.07]],"batl":[[0,3.7,14.56],[1,95,15.9],[2,990,2.2]],"ltp":3.0,"tv":1031.98,"id":5071877},{"trd":[[1.5,7556.74]],"batb":[[0,1.49,2.01],[1,1.48,79.16],[2,1.47,319.83]],"batl":[[0,1.5,9200.58],[1,1.53,226.85],[2,1.54,239.46]],"ltp":1.5,"tv":13813.21,"id":6374165}],"tv":14845.19}]}
{"op":"mcm","clk":"1006190242","pt":1580593940512,"mc":[{"id":"1.168175448","rc":[{"batb":[[0,2.96,2.88],[1,2.94,2.92],[2,2.88,13.41]],"ltp":3.0,"tv":1031.98,"id":5071877},{"trd":[[1.5,7892.82]],"batb":[[0,1.48,79.16],[1,1.47,266.2],[2,1.46,129.39]],"batl":[[0,1.5,9032.53],[1,1.51,2.01],[2,1.52,2.01]],"ltp":1.5,"tv":14149.29,"id":6374165}],"tv":15181.27}]}
{"op":"mcm","clk":"1006190254","pt":1580593940614,"mc":[{"id":"1.168175448","rc":[{"trd":[[1.5,8456.83]],"batl":[[0,1.5,8750.52],[1,1.52,2.01],[2,1.53,228.86]],"ltp":1.5,"tv":14713.3,"id":6374165}],"tv":15745.29}]}
{"op":"mcm","clk":"1006191382","pt":1580593952262,"mc":[{"id":"1.168175448","rc":[{"batb":[[1,2.94,2.59]],"ltp":3.0,"tv":1031.98,"id":5071877},{"batl":[[1,1.52,170.05]],"ltp":1.5,"tv":14713.3,"id":6374165}]}]}
{"op":"mcm","clk":"1006191561","pt":1580593954027,"mc":[{"id":"1.168175448","rc":[{"trd":[[1.5,8508.55]],"batl":[[0,1.5,8724.66]],"ltp":1.5,"tv":14765.03,"id":6374165}],"tv":15797.01}]}
{"op":"mcm","clk":"1006191790","pt":1580593956144,"mc":[{"id":"1.168175448","rc":[{"batl":[[0,1.5,7948.08]],"ltp":1.5,"tv":14765.03,"id":6374165}]}]}
{"op":"mcm","clk":"1006191843","pt":1580593956665,"mc":[{"id":"1.168175448","rc":[{"trd":[[1.5,9026.56]],"batl":[[0,1.5,7689.07]],"ltp":1.5,"tv":15283.04,"id":6374165}],"tv":16315.02}]}
{"op":"mcm","clk":"1006192402","pt":1580593962517,"mc":[{"id":"1.168175448","rc":[{"batb":[[1,2.94,2.92]],"ltp":3.0,"tv":1031.98,"id":5071877},{"batl":[[0,1.5,7787.86]],"ltp":1.5,"tv":15283.04,"id":6374165}]}]}
{"op":"mcm","clk":"1006194135","pt":1580593981356,"mc":[{"id":"1.168175448","rc":[{"batl":[[0,1.49,74.21],[1,1.5,7787.86],[2,1.51,2.01]],"ltp":1.5,"tv":15283.04,"id":6374165}]}]}
{"op":"mcm","clk":"1006194924","pt":1580593990376,"mc":[{"id":"1.168175448","rc":[{"trd":[[3.1,78.66]],"batb":[[0,3.1,16.21],[1,2.96,2.88],[2,2.94,2.92]],"ltp":3.1,"tv":1069.77,"id":5071877},{"trd":[[1.48,974.58]],"batb":[[0,1.47,266.2],[1,1.46,129.39],[2,1.44,29.55]],"ltp":1.48,"tv":15362.2,"id":6374165}],"tv":16431.97}]}
{"op":"mcm","clk":"1006195097","pt":1580593991468,"mc":[{"id":"1.168175448","rc":[{"batb":[[1,3.05,8.64],[2,3,2.96]],"ltp":3.1,"tv":1069.77,"id":5071877},{"batb":[[2,1.45,74.88]],"batl":[[1,1.5,7789.87]],"ltp":1.48,"tv":15362.2,"id":6374165}]}]}
{"op":"mcm","clk":"1006196007","pt":1580594003991,"mc":[{"id":"1.168175448","rc":[{"trd":[[3.1,79.46]],"batb":[[0,3.1,15.41]],"ltp":3.1,"tv":1070.57,"id":5071877},{"trd":[[1.48,976.26]],"ltp":1.48,"tv":15363.88,"id":6374165}],"tv":16434.45}]}
{"op":"mcm","clk":"1006197000","pt":1580594015496,"mc":[{"id":"1.168175448","rc":[{"trd":[[3.1,80.26]],"batb":[[0,3.1,14.61]],"ltp":3.1,"tv":1071.37,"id":5071877},{"trd":[[1.48,977.95]],"ltp":1.48,"tv":15365.56,"id":6374165}],"tv":16436.93}]}
{"op":"mcm","clk":"1006197350","pt":1580594019603,"mc":[{"id":"1.168175448","rc":[{"trd":[[3.1,81.06]],"batb":[[0,3.1,13.81]],"ltp":3.1,"tv":1072.17,"id":5071877},{"trd":[[1.48,979.63]],"ltp":1.48,"tv":15367.24,"id":6374165}],"tv":16439.41}]}
{"op":"mcm","clk":"1006198158","pt":1580594029534,"mc":[{"id":"1.168175448","rc":[{"trd":[[1.47,9.92]],"batb":[[0,1.47,263.73]],"ltp":1.47,"tv":15372.18,"id":6374165}],"tv":16444.35}]}
{"op":"mcm","clk":"1006198591","pt":1580594034128,"mc":[{"id":"1.168175448","rc":[{"trd":[[3.1,87.78]],"batb":[[0,3.1,10.45]],"ltp":3.1,"tv":1078.89,"id":5071877}],"tv":16451.07}]}
{"op":"mcm","clk":"1006199873","pt":1580594047355,"mc":[{"id":"1.168175448","rc":[{"trd":[[3.1,88.58]],"batb":[[0,3.1,9.65]],"ltp":3.1,"tv":1079.69,"id":5071877},{"trd":[[1.48,981.31]],"ltp":1.48,"tv":15373.86,"id":6374165}],"tv":16453.55}]}
{"op":"mcm","clk":"1006200042","pt":1580594048962,"mc":[{"id":"1.168175448","rc":[{"batb":[[0,1.47,306.58]],"ltp":1.48,"tv":15373.86,"id":6374165}]}]}
{"op":"mcm","clk":"1006201236","pt":1580594063517,"mc":[{"id":"1.168175448","rc":[{"trd":[[1.47,376.24]],"batb":[[0,1.47,123.42]],"ltp":1.47,"tv":15740.18,"id":6374165}],"tv":16819.88}]}
{"op":"mcm","clk":"1006201314","pt":1580594064515,"mc":[{"id":"1.168175448","rc":[{"trd":[[3.15,54.69]],"ltp":3.15,"tv":1134.37,"id":5071877},{"trd":[[1.47,493.43]],"batb":[[0,1.47,6.23]],"ltp":1.47,"tv":15857.37,"id":6374165}],"tv":16991.75}]}
{"op":"mcm","clk":"1006201733","pt":1580594068901,"mc":[{"id":"1.168175448","rc":[{"batl":[[0,1.48,74.21],[1,1.49,74.21],[2,1.5,7789.87]],"ltp":1.47,"tv":15857.37,"id":6374165}]}]}
{"op":"mcm","clk":"1006202140","pt":1580594073305,"mc":[{"id":"1.168175448","rc":[{"batl":[[1,1.49,148.42]],"ltp":1.47,"tv":15857.37,"id":6374165}]}]}
{"op":"mcm","clk":"1006202422","pt":1580594076522,"mc":[{"id":"1.168175448","rc":[{"trd":[[3.1,107.88]],"batb":[[0,3.05,8.64],[1,2.98,2.76],[2,2.96,2.63]],"ltp":3.1,"tv":1153.68,"id":5071877},{"trd":[[1.48,1122.93]],"batl":[[0,1.48,3.4]],"ltp":1.48,"tv":15998.99,"id":6374165}],"tv":17152.67}]}
{"op":"mcm","clk":"1006202469","pt":1580594077098,"mc":[{"id":"1.168175448","rc":[{"trd":[[1.48,1129.45]],"batl":[[0,1.49,148.55],[1,1.5,7787.86],[2,1.51,2.01]],"ltp":1.48,"tv":16005.51,"id":6374165}],"tv":17159.2}]}
{"op":"mcm","clk":"1006203191","pt":1580594086487,"mc":[{"id":"1.168175448","rc":[{"batb":[[2,2.96,3.13]],"ltp":3.1,"tv":1153.68,"id":5071877},{"batb":[[1,1.46,131.07]],"ltp":1.48,"tv":16005.51,"id":6374165}]}]}
{"op":"mcm","clk":"1006203454","pt":1580594089702,"mc":[{"id":"1.168175448","rc":[{"batb":[[0,1.47,348.58]],"ltp":1.48,"tv":16005.51,"id":6374165}]}]}
{"op":"mcm","clk":"1006203539","pt":1580594090897,"mc":[{"id":"1.168175448","rc":[{"batb":[[1,1.46,131.91]],"ltp":1.48,"tv":16005.51,"id":6374165}]}]}
{"op":"mcm","clk":"1006204044","pt":1580594097504,"mc":[{"id":"1.168175448","rc":[{"batb":[[2,2.94,12.99]],"ltp":3.1,"tv":1153.68,"id":5071877},{"trd":[[1.48,1205.45]],"batb":[[0,1.48,67.88],[1,1.47,6.23],[2,1.46,131.91]],"batl":[[0,1.49,148.42],[1,1.5,7789.87]],"ltp":1.48,"tv":16081.52,"id":6374165}],"tv":17235.2}]}
{"op":"mcm","clk":"1006204059","pt":1580594097704,"mc":[{"id":"1.168175448","rc":[{"batb":[[2,2.96,3.13]],"ltp":3.1,"tv":1153.68,"id":5071877},{"batb":[[0,1.47,6.23],[1,1.46,131.91],[2,1.45,74.88]],"batl":[[1,1.5,7787.86]],"ltp":1.48,"tv":16081.52,"id":6374165}]}]}
{"op":"mcm","clk":"1006204291","pt":1580594100820,"mc":[{"id":"1.168175448","rc":[{"trd":[[1.47,497.43]],"batb":[[0,1.47,4.23]],"ltp":1.47,"tv":16085.52,"id":6374165}],"tv":17239.2}]}
{"op":"mcm","clk":"1006204636","pt":1580594105195,"mc":[{"id":"1.168175448","rc":[{"batb":[[2,2.96,3.88]],"ltp":3.1,"tv":1153.68,"id":5071877},{"trd":[[1.49,545.3]],"batb":[[2,1.45,76.89]],"batl":[[0,1.49,146.37]],"ltp":1.49,"tv":16089.62,"id":6374165}],"tv":17243.3}]}
{"op":"mcm","clk":"1006204666","pt":1580594105608,"mc":[{"id":"1.168175448","rc":[{"batb":[[0,1.47,229.89]],"ltp":1.49,"tv":16089.62,"id":6374165}]}]}
{"op":"mcm","clk":"1006206693","pt":1580594130924,"mc":[{"id":"1.168175448","rc":[{"batb":[[2,2.96,3.63]],"ltp":3.1,"tv":1153.68,"id":5071877},{"batb":[[0,1.47,541.07]],"ltp":1.49,"tv":16089.62,"id":6374165}]}]}
{"op":"mcm","clk":"1006207036","pt":1580594134955,"mc":[{"id":"1.168175448","rc":[{"trd":[[1.47,500.79]],"batb":[[0,1.47,539.39]],"ltp":1.47,"tv":16092.98,"id":6374165}],"tv":17246.66}]}
{"op":"mcm","clk":"1006207666","pt":1580594143143,"mc":[{"id":"1.168175448","rc":[{"batb":[[2,2.96,3.38]],"ltp":3.1,"tv":1153.68,"id":5071877},{"trd":[[1.47,673.87]],"batb":[[0,1.47,452.85]],"ltp":1.47,"tv":16266.06,"id":6374165}],"tv":17419.74}]}
{"op":"mcm","clk":"1006209650","pt":1580594167471,"mc":[{"id":"1.168175448","rc":[{"batb":[[2,2.94,12.99]],"ltp":3.1,"tv":1153.68,"id":5071877}]}]}
{"op":"mcm","clk":"1006209725","pt":1580594168353,"mc":[{"id":"1.168175448","rc":[{"batb":[[2,2.96,3.88]],"ltp":3.1,"tv":1153.68,"id":5071877},{"trd":[[1.47,675.67]],"batb":[[0,1.47,451.95]],"ltp":1.47,"tv":16267.86,"id":6374165}],"tv":17421.54}]}
{"op":"mcm","clk":"1006211508","pt":1580594187994,"mc":[{"id":"1.168175448","rc":[{"trd":[[1.47,721.04]],"batb":[[0,1.47,429.26]],"ltp":1.47,"tv":16313.23,"id":6374165}],"tv":17466.92}]}
{"op":"mcm","clk":"1006211702","pt":1580594190489,"mc":[{"id":"1.168175448","rc":[{"batl":[[0,1.48,74.21],[1,1.49,146.37],[2,1.5,7787.86]],"ltp":1.47,"tv":16313.23,"id":6374165}]}]}
{"op":"mcm","clk":"1006211768","pt":1580594191325,"mc":[{"id":"1.168175448","rc":[{"trd":[[1.48,1353.86]],"batb":[[0,1.47,118.08]],"batl":[[0,1.49,146.37],[1,1.5,7787.86],[2,1.51,2.01]],"ltp":1.48,"tv":16461.64,"id":6374165}],"tv":17615.33}]}
{"op":"mcm","clk":"1006212800","pt":1580594203559,"mc":[{"id":"1.168175448","rc":[{"batl":[[0,1.48,74.21],[1,1.49,146.37],[2,1.5,7787.86]],"ltp":1.48,"tv":16461.64,"id":6374165}]}]}
{"op":"mcm","clk":"1006212904","pt":1580594204556,"mc":[{"id":"1.168175448","rc":[{"trd":[[1.48,1502.28]],"batb":[[1,1.46,133.92]],"batl":[[0,1.49,146.37],[1,1.5,7787.86],[2,1.51,2.01]],"ltp":1.48,"tv":16610.06,"id":6374165}],"tv":17763.74}]}
{"op":"mcm","clk":"1006212964","pt":1580594205233,"mc":[{"id":"1.168175448","rc":[{"batb":[[0,1.48,8.44],[1,1.47,118.08],[2,1.46,133.92]],"ltp":1.48,"tv":16610.06,"id":6374165}]}]}
{"op":"mcm","clk":"1006214371","pt":1580594220531,"mc":[{"id":"1.168175448","rc":[{"batb":[[2,2.96,3.63]],"ltp":3.1,"tv":1153.68,"id":5071877},{"batb":[[0,1.48,28.44]],"ltp":1.48,"tv":16610.06,"id":6374165}]}]}
{"op":"mcm","clk":"1006216463","pt":1580594243496,"mc":[{"id":"1.168175448","rc":[{"trd":[[3.05,21.45]],"batb":[[0,3.05,4.58],[2,2.96,3.88]],"ltp":3.05,"tv":1161.8,"id":5071877}],"tv":17771.86}]}
{"op":"mcm","clk":"1006216551","pt":1580594244483,"mc":[{"id":"1.168175448","rc":[{"batb":[[0,2.96,33.85],[1,2.94,16.41],[2,2.9,13.27]],"ltp":3.05,"tv":1161.8,"id":5071877},{"trd":[[1.48,1650.68]],"batb":[[0,1.47,150.96],[1,1.46,131.91],[2,1.45,2.01]],"batl":[[0,1.49,146.37],[1,1.5,7789.87]],"ltp":1.48,"tv":16758.46,"id":6374165}],"tv":17920.26}]}
{"op":"mcm","clk":"1006216643","pt":1580594245482,"mc":[{"id":"1.168175448","rc":[{"trd":[[1.48,1650.7]],"batl":[[0,1.49,146.37],[1,1.5,7787.86]],"ltp":1.48,"tv":16758.48,"id":6374165}],"tv":17920.28}]}
{"op":"mcm","clk":"1006216649","pt":1580594245579,"mc":[{"id":"1.168175448","rc":[{"batb":[[1,2.94,3.42]],"ltp":3.05,"tv":1161.8,"id":5071877}]}]}
{"op":"mcm","clk":"1006217307","pt":1580594253510,"mc":[{"id":"1.168175448","rc":[{"trd":[[3.1,119.27]],"batb":[[1,2.94,3.59]],"ltp":3.1,"tv":1173.18,"id":5071877}],"tv":17931.66}]}
{"op":"mcm","clk":"1006217797","pt":1580594259429,"mc":[{"id":"1.168175448","rc":[{"batb":[[0,1.47,374.63]],"ltp":1.48,"tv":16758.48,"id":6374165}]}]}
{"op":"mcm","clk":"1006218300","pt":1580594266436,"mc":[{"id":"1.168175448","rc":[{"trd":[[1.47,724.58]],"batb":[[0,1.47,372.86]],"ltp":1.47,"tv":16762.02,"id":6374165}],"tv":17935.2}]}
{"op":"mcm","clk":"1006218327","pt":1580594266749,"mc":[{"id":"1.168175448","rc":[{"batb":[[1,2.94,3.92]],"ltp":3.1,"tv":1173.18,"id":5071877}]}]}
{"op":"mcm","clk":"1006218429","pt":1580594268157,"mc":[{"id":"1.168175448","rc":[{"batl":[[0,1.49,298.32]],"ltp":1.47,"tv":16762.02,"id":6374165}]}]}
{"op":"mcm","clk":"1006218654","pt":1580594271511,"mc":[{"id":"1.168175448","rc":[{"trd":[[1.47,732.76]],"batb":[[0,1.47,368.77]],"ltp":1.47,"tv":16770.2,"id":6374165}],"tv":17943.38}]}
{"op":"mcm","clk":"1006218785","pt":1580594273248,"mc":[{"id":"1.168175448","rc":[{"batb":[[1,2.94,3.59]],"ltp":3.1,"tv":1173.18,"id":5071877},{"batb":[[0,1.47,594.42]],"ltp":1.47,"tv":16770.2,"id":6374165}]}]}
{"op":"mcm","clk":"1006219616","pt":1580594282363,"mc":[{"id":"1.168175448","rc":[{"batb":[[1,2.94,3.42]],"ltp":3.1,"tv":1173.18,"id":5071877},{"batb":[[0,1.47,668.63]],"ltp":1.47,"tv":16770.2,"id":6374165}]}]}
{"op":"mcm","clk":"1006220259","pt":1580594290459,"mc":[{"id":"1.168175448","rc":[{"trd":[[3.15,67.19]],"ltp":3.15,"tv":1185.68,"id":5071877},{"trd":[[1.47,759.54]],"batb":[[0,1.47,641.85]],"ltp":1.47,"tv":16796.98,"id":6374165}],"tv":17982.66}]}
{"op":"mcm","clk":"1006220294","pt":1580594290874,"mc":[{"id":"1.168175448","rc":[{"batb":[[1,2.94,3.92]],"ltp":3.15,"tv":1185.68,"id":5071877}]}]}
{"op":"mcm","clk":"1006220598","pt":1580594294972,"mc":[{"id":"1.168175448","rc":[{"batb":[[1,1.46,288.93]],"ltp":1.47,"tv":16796.98,"id":6374165}]}]}
{"op":"mcm","clk":"1006220798","pt":1580594297376,"mc":[{"id":"1.168175448","rc":[{"batb":[[1,2.9,13.27],[2,2.88,13.41]],"batl":[[0,3.1,39.86],[1,3.7,14.56],[2,95,15.9]],"ltp":3.15,"tv":1185.68,"id":5071877}]}]}
{"op":"mcm","clk":"1006220808","pt":1580594297575,"mc":[{"id":"1.168175448","rc":[{"batb":[[1,2.94,3.92],[2,2.9,13.27]],"ltp":3.15,"tv":1185.68,"id":5071877}]}]}
{"op":"mcm","clk":"1006221292","pt":1580594302670,"mc":[{"id":"1.168175448","rc":[{"trd":[[1.49,552.6]],"batl":[[0,1.49,294.67]],"ltp":1.49,"tv":16804.28,"id":6374165}],"tv":17989.96}]}
{"op":"mcm","clk":"1006224252","pt":1580594338497,"mc":[{"id":"1.168175448","rc":[{"batb":[[1,2.94,3.59]],"ltp":3.15,"tv":1185.68,"id":5071877}]}]}
{"op":"mcm","clk":"1006224305","pt":1580594339180,"mc":[{"id":"1.168175448","rc":[{"batb":[[0,1.48,337.47],[1,1.47,641.85],[2,1.46,290.94]],"ltp":1.49,"tv":16804.28,"id":6374165}]}]}
{"op":"mcm","clk":"1006224361","pt":1580594339596,"mc":[{"id":"1.168175448","rc":[{"batb":[[2,2.88,99.72]],"ltp":3.15,"tv":1185.68,"id":5071877}]}]}
{"op":"mcm","clk":"1006226521","pt":1580594361532,"mc":[{"id":"1.168175448","rc":[{"batb":[[1,2.88,99.72],[2,2.8,16.89]],"ltp":3.15,"tv":1185.68,"id":5071877}]}]}
{"op":"mcm","clk":"1006226538","pt":1580594361740,"mc":[{"id":"1.168175448","rc":[{"batb":[[1,2.94,3.59],[2,2.88,99.72]],"ltp":3.15,"tv":1185.68,"id":5071877}]}]}
{"op":"mcm","clk":"1006227315","pt":1580594370542,"mc":[{"id":"1.168175448","rc":[{"batb":[[1,2.88,99.72],[2,2.8,16.89]],"ltp":3.15,"tv":1185.68,"id":5071877}]}]}
{"op":"mcm","clk":"1006227325","pt":1580594370644,"mc":[{"id":"1.168175448","rc":[{"batb":[[1,2.94,3.92],[2,2.88,99.72]],"ltp":3.15,"tv":1185.68,"id":5071877}]}]}
{"op":"mcm","clk":"1006228066","pt":1580594378534,"mc":[{"id":"1.168175448","rc":[{"batb":[[1,2.94,3.42]],"batl":[[0,3.05,39.86]],"ltp":3.15,"tv":1185.68,"id":5071877}]}]}
{"op":"mcm","clk":"1006228876","pt":1580594387553,"mc":[{"id":"1.168175448","rc":[{"trd":[[1.49,553.41]],"batl":[[0,1.49,294.26]],"ltp":1.49,"tv":16805.1,"id":6374165}],"tv":17990.78}]}
{"op":"mcm","clk":"1006228915","pt":1580594387969,"mc":[{"id":"1.168175448","rc":[{"batb":[[1,2.94,3.59]],"ltp":3.15,"tv":1185.68,"id":5071877}]}]}
{"op":"mcm","clk":"1006229259","pt":1580594391555,"mc":[{"id":"1.168175448","rc":[{"trd":[[3,405.11]],"ltp":3.0,"tv":1564.72,"id":5071877},{"trd":[[1.49,847.67],[1.5,9492.2]],"batl":[[0,1.5,7322.22],[1,1.52,177.45],[2,1.53,228.86]],"ltp":1.5,"tv":17564.99,"id":6374165}],"tv":19129.72}]}
{"op":"mcm","clk":"1006229323","pt":1580594392174,"mc":[{"id":"1.168175448","rc":[{"batl":[[1,3.25,18.48],[2,3.7,14.56]],"ltp":3.0,"tv":1564.72,"id":5071877}]}]}
{"op":"mcm","clk":"1006229832","pt":1580594397566,"mc":[{"id":"1.168175448","rc":[{"batb":[[1,2.88,99.72],[2,2.86,21.85]],"ltp":3.0,"tv":1564.72,"id":5071877},{"batl":[[0,1.49,8.4],[1,1.5,7322.22],[2,1.51,2.01]],"ltp":1.5,"tv":17564.99,"id":6374165}]}]}
{"op":"mcm","clk":"1006229922","pt":1580594398503,"mc":[{"id":"1.168175448","rc":[{"batb":[[1,2.94,3.92],[2,2.88,99.72]],"ltp":3.0,"tv":1564.72,"id":5071877},{"trd":[[1.48,1651.04]],"batb":[[0,1.48,337.3]],"ltp":1.48,"tv":17565.33,"id":6374165}],"tv":19130.06}]}
{"op":"mcm","clk":"1006230492","pt":1580594403483,"mc":[{"id":"1.168175448","rc":[{"batb":[[1,1.47,418.18]],"ltp":1.48,"tv":17565.33,"id":6374165}]}]}
{"op":"mcm","clk":"1006230516","pt":1580594403698,"mc":[{"id":"1.168175448","rc":[{"batb":[[1,1.47,641.85]],"ltp":1.48,"tv":17565.33,"id":6374165}]}]}
{"op":"mcm","clk":"1006231470","pt":1580594412385,"mc":[{"id":"1.168175448","rc":[{"trd":[[1.49,864.47]],"batb":[[0,1.49,14.6],[1,1.48,337.3],[2,1.47,641.85]],"batl":[[0,1.5,7322.22],[1,1.51,2.01],[2,1.52,177.44]],"ltp":1.49,"tv":17582.14,"id":6374165}],"tv":19146.86}]}
{"op":"mcm","clk":"1006232642","pt":1580594423296,"mc":[{"id":"1.168175448","rc":[{"batb":[[1,1.48,422.74],[2,1.47,556.41]],"ltp":1.49,"tv":17582.14,"id":6374165}]}]}
{"op":"mcm","clk":"1006233094","pt":1580594427309,"mc":[{"id":"1.168175448","rc":[{"trd":[[3,444.96]],"batl":[[0,3.25,18.48],[1,3.7,14.56],[2,95,15.9]],"ltp":3.0,"tv":1604.58,"id":5071877},{"trd":[[1.5,9571.91]],"batl":[[0,1.5,7242.51]],"ltp":1.5,"tv":17661.85,"id":6374165}],"tv":19266.43}]}
{"op":"mcm","clk":"1006233246","pt":1580594428618,"mc":[{"id":"1.168175448","rc":[{"trd":[[1.49,864.55]],"batb":[[0,1.49,14.56]],"ltp":1.49,"tv":17661.93,"id":6374165}],"tv":19266.51}]}
{"op":"mcm","clk":"1006234069","pt":1580594436850,"mc":[{"id":"1.168175448","rc":[{"batb":[[2,1.47,256.55]],"ltp":1.49,"tv":17661.93,"id":6374165}]}]}
{"op":"mcm","clk":"1006234267","pt":1580594438937,"mc":[{"id":"1.168175448","rc":[{"trd":[[1.49,893.68]],"batb":[[0,1.48,422.74],[1,1.47,256.55],[2,1.46,290.94]],"batl":[[0,1.49,8.16],[1,1.5,7242.51],[2,1.51,2.01]],"ltp":1.49,"tv":17691.05,"id":6374165}],"tv":19295.63}]}
{"op":"mcm","clk":"1006235520","pt":1580594451467,"mc":[{"id":"1.168175448","rc":[{"trd":[[1.48,1667.35]],"batb":[[0,1.48,414.58]],"batl":[[0,1.5,7242.51],[1,1.51,2.01],[2,1.52,177.44]],"ltp":1.48,"tv":17707.36,"id":6374165}],"tv":19311.94}]}
{"op":"mcm","clk":"1006236858","pt":1580594464533,"mc":[{"id":"1.168175448","rc":[{"batb":[[0,2.96,29.97]],"ltp":3.0,"tv":1604.58,"id":5071877},{"batl":[[1,1.52,175.44],[2,1.53,226.85]],"ltp":1.48,"tv":17707.36,"id":6374165}]}]}
{"op":"mcm","clk":"1006236868","pt":1580594464633,"mc":[{"id":"1.168175448","rc":[{"batb":[[1,2.88,99.72],[2,2.86,21.85]],"ltp":3.0,"tv":1604.58,"id":5071877},{"batb":[[2,1.46,288.93]],"ltp":1.48,"tv":17707.36,"id":6374165}]}]}
{"op":"mcm","clk":"1006237275","pt":1580594468603,"mc":[{"id":"1.168175448","rc":[{"batl":[[0,1.49,42.01],[1,1.5,7242.51],[2,1.52,175.44]],"ltp":1.48,"tv":17707.36,"id":6374165}]}]}
{"op":"mcm","clk":"1006238138","pt":1580594477306,"mc":[{"id":"1.168175448","rc":[{"batl":[[1,3.3,68.89],[2,3.7,14.56]],"ltp":3.0,"tv":1604.58,"id":5071877}]}]}
{"op":"mcm","clk":"1006239491","pt":1580594490452,"mc":[{"id":"1.168175448","rc":[{"batb":[[2,1.46,131.91]],"ltp":1.48,"tv":17707.36,"id":6374165}]}]}
{"op":"mcm","clk":"1006240055","pt":1580594495541,"mc":[{"id":"1.168175448","rc":[{"batb":[[1,2.9,85.29],[2,2.88,99.72]],"ltp":3.0,"tv":1604.58,"id":5071877},{"batb":[[1,1.47,597.08]],"ltp":1.48,"tv":17707.36,"id":6374165}]}]}
{"op":"mcm","clk":"1006240082","pt":1580594495752,"mc":[{"id":"1.168175448","rc":[{"batb":[[2,2.88,13.41]],"ltp":3.0,"tv":1604.58,"id":5071877},{"batb":[[0,1.48,85.44]],"ltp":1.48,"tv":17707.36,"id":6374165}]}]}
{"op":"mcm","clk":"1006240473","pt":1580594499285,"mc":[{"id":"1.168175448","rc":[{"trd":[[1.48,1742.55]],"batb":[[0,1.48,47.83]],"ltp":1.48,"tv":17782.56,"id":6374165}],"tv":19387.14}]}
{"op":"mcm","clk":"1006240704","pt":1580594501387,"mc":[{"id":"1.168175448","marketDefinition":{"bspMarket":false,"turnInPlayEnabled":true,"persistenceEnabled":true,"marketBaseRate":5.0,"eventId":"29680072","eventTypeId":"2","numberOfWinners":1,"bettingType":"ODDS","marketType":"MATCH_ODDS","marketTime":"2020-02-01T21:57:00.000Z","suspendTime":"2020-02-01T21:57:00.000Z","bspReconciled":false,"complete":true,"inPlay":false,"crossMatching":true,"runnersVoidable":false,"numberOfActiveRunners":2,"betDelay":0,"status":"OPEN","runners":[{"status":"ACTIVE","sortPriority":1,"id":6374165,"name":"Marco Cecchinato"},{"status":"ACTIVE","sortPriority":2,"id":5071877,"name":"Andrej Martin"}],"regulators":["MR_INT"],"countryCode":"UY","discountAllowed":true,"timezone":"UTC","openDate":"2020-02-01T22:00:00.000Z","version":3147667732,"name":"Match Odds","eventName":"Cecchinato v Martin"},"rc":[{"batb":[[1,1.47,373.41]],"ltp":1.48,"tv":17782.56,"id":6374165}]}]}
{"op":"mcm","clk":"1006240857","pt":1580594502939,"mc":[{"id":"1.168175448","marketDefinition":{"bspMarket":false,"turnInPlayEnabled":true,"persistenceEnabled":true,"marketBaseRate":5.0,"eventId":"29680072","eventTypeId":"2","numberOfWinners":1,"bettingType":"ODDS","marketType":"MATCH_ODDS","marketTime":"2020-02-01T21:57:00.000Z","suspendTime":"2020-02-01T21:57:00.000Z","bspReconciled":false,"complete":true,"inPlay":false,"crossMatching":true,"runnersVoidable":false,"numberOfActiveRunners":2,"betDelay":0,"status":"OPEN","runners":[{"status":"ACTIVE","sortPriority":1,"id":6374165,"name":"Marco Cecchinato"},{"status":"ACTIVE","sortPriority":2,"id":5071877,"name":"Andrej Martin"}],"regulators":["MR_INT"],"countryCode":"UY","discountAllowed":true,"timezone":"UTC","openDate":"2020-02-01T21:57:00.000Z","version":3147667732,"name":"Match Odds","eventName":"Cecchinato v Martin"}}]}
{"op":"mcm","clk":"1006242262","pt":1580594516209,"mc":[{"id":"1.168175448","rc":[{"trd":[[1.48,1830.97]],"batb":[[0,1.48,3.61]],"ltp":1.48,"tv":17870.98,"id":6374165}],"tv":19475.57}]}
{"op":"mcm","clk":"1006242351","pt":1580594517103,"mc":[{"id":"1.168175448","rc":[{"batb":[[1,2.9,98.56]],"ltp":3.0,"tv":1604.58,"id":5071877},{"trd":[[1.48,1919.19]],"batb":[[0,1.47,373.41],[1,1.46,131.91],[2,1.44,94.94]],"batl":[[0,1.49,42.11]],"ltp":1.48,"tv":17959.2,"id":6374165}],"tv":19563.78}]}
{"op":"mcm","clk":"1006242514","pt":1580594518895,"mc":[{"id":"1.168175448","rc":[{"batb":[[0,1.47,576.08]],"ltp":1.48,"tv":17959.2,"id":6374165}]}]}
{"op":"mcm","clk":"1006242882","pt":1580594522801,"mc":[{"id":"1.168175448","rc":[{"trd":[[1.48,1919.4],[1.49,895.24]],"batl":[[0,1.49,41.23]],"ltp":1.49,"tv":17960.97,"id":6374165}],"tv":19565.55}]}
{"op":"mcm","clk":"1006243171","pt":1580594525499,"mc":[{"id":"1.168175448","rc":[{"trd":[[1.47,789.54]],"batb":[[0,1.47,561.08]],"ltp":1.47,"tv":17990.97,"id":6374165}],"tv":19595.55}]}
{"op":"mcm","clk":"1006243263","pt":1580594526182,"mc":[{"id":"1.168175448","rc":[{"batb":[[0,3.05,11.79]],"ltp":3.0,"tv":1604.58,"id":5071877},{"batb":[[0,1.47,543.21],[2,1.45,68.27]],"ltp":1.47,"tv":17990.97,"id":6374165}]}]}
{"op":"mcm","clk":"1006243357","pt":1580594527014,"mc":[{"id":"1.168175448","rc":[{"batb":[[1,2.94,12.99],[2,2.9,98.56]],"ltp":3.0,"tv":1604.58,"id":5071877},{"batb":[[0,1.48,337.55]],"ltp":1.47,"tv":17990.97,"id":6374165}]}]}
{"op":"mcm","clk":"1006243478","pt":1580594528180,"mc":[{"id":"1.168175448","rc":[{"batb":[[1,2.92,13.13]],"ltp":3.0,"tv":1604.58,"id":5071877}]}]}
{"op":"mcm","clk":"1006244097","pt":1580594534700,"mc":[{"id":"1.168175448","rc":[{"trd":[[1.48,2119.41]],"batb":[[0,1.48,237.54]],"ltp":1.48,"tv":18190.98,"id":6374165}],"tv":19795.56}]}
{"op":"mcm","clk":"1006244340","pt":1580594536896,"mc":[{"id":"1.168175448","rc":[{"batb":[[1,2.94,86],[2,2.92,13.13]],"ltp":3.0,"tv":1604.58,"id":5071877},{"batb":[[0,1.47,338.41]],"ltp":1.48,"tv":18190.98,"id":6374165}]}]}
{"op":"mcm","clk":"1006244524","pt":1580594538603,"mc":[{"id":"1.168175448","rc":[{"batb":[[1,2.94,98.99]],"ltp":3.0,"tv":1604.58,"id":5071877}]}]}
{"op":"mcm","clk":"1006245520","pt":1580594547532,"mc":[{"id":"1.168175448","rc":[{"batl":[[0,3.3,86.53],[1,3.7,14.56],[2,95,15.9]],"ltp":3.0,"tv":1604.58,"id":5071877}]}]}
{"op":"mcm","clk":"1006245725","pt":1580594549417,"mc":[{"id":"1.168175448","rc":[{"batb":[[1,2.96,85.06],[2,2.94,12.99]],"ltp":3.0,"tv":1604.58,"id":5071877}]}]}
{"op":"mcm","clk":"1006247995","pt":1580594570470,"mc":[{"id":"1.168175448","rc":[{"batb":[[1,2.96,84.58]],"ltp":3.0,"tv":1604.58,"id":5071877}]}]}
{"op":"mcm","clk":"1006248387","pt":1580594574450,"mc":[{"id":"1.168175448","rc":[{"trd":[[1.48,2135.93]],"batl":[[0,1.49,41.41]],"ltp":1.48,"tv":18207.5,"id":6374165}],"tv":19812.08}]}
{"op":"mcm","clk":"1006249033","pt":1580594580554,"mc":[{"id":"1.168175448","rc":[{"batb":[[1,2.96,207.48]],"ltp":3.0,"tv":1604.58,"id":5071877},{"batb":[[0,1.46,483.54],[1,1.45,68.27],[2,1.43,97.46]],"ltp":1.48,"tv":18207.5,"id":6374165}]}]}
{"op":"mcm","clk":"1006249151","pt":1580594581785,"mc":[{"id":"1.168175448","rc":[{"batb":[[1,1.44,94.7]],"ltp":1.48,"tv":18207.5,"id":6374165}]}]}
{"op":"mcm","clk":"1006249536","pt":1580594585245,"mc":[{"id":"1.168175448","rc":[{"trd":[[1.47,790.44],[1.48,2276.05]],"batl":[[0,1.49,41.35]],"ltp":1.48,"tv":18348.52,"id":6374165}],"tv":19953.1}]}
{"op":"mcm","clk":"1006250192","pt":1580594591762,"mc":[{"id":"1.168175448","rc":[{"batb":[[0,1.47,4.46],[1,1.46,483.54],[2,1.44,94.7]],"ltp":1.48,"tv":18348.52,"id":6374165}]}]}
{"op":"mcm","clk":"1006250913","pt":1580594598492,"mc":[{"id":"1.168175448","rc":[{"trd":[[1.48,2276.29],[1.49,903.77]],"batl":[[0,1.49,36.96]],"ltp":1.49,"tv":18357.3,"id":6374165}],"tv":19961.88}]}
{"op":"mcm","clk":"1006250965","pt":1580594599110,"mc":[{"id":"1.168175448","rc":[{"batb":[[0,1.47,166.81]],"batl":[[0,1.49,97.74]],"ltp":1.49,"tv":18357.3,"id":6374165}]}]}
{"op":"mcm","clk":"1006253049","pt":1580594619923,"mc":[{"id":"1.168175448","rc":[{"trd":[[1.47,800.44]],"batb":[[0,1.47,161.81]],"ltp":1.47,"tv":18367.29,"id":6374165}],"tv":19971.87}]}
{"op":"mcm","clk":"1006253764","pt":1580594627039,"mc":[{"id":"1.168175448","rc":[{"batb":[[0,1.47,164.81]],"ltp":1.47,"tv":18367.29,"id":6374165}]}]}
{"op":"mcm","clk":"1006254552","pt":1580594635848,"mc":[{"id":"1.168175448","rc":[{"trd":[[1.48,2284.81]],"batb":[[0,1.47,3]],"batl":[[0,1.49,97.94]],"ltp":1.48,"tv":18375.81,"id":6374165}],"tv":19980.39}]}
{"op":"mcm","clk":"1006255839","pt":1580594649361,"mc":[{"id":"1.168175448","rc":[{"batb":[[1,2.94,221.42],[2,2.92,13.13]],"ltp":3.0,"tv":1604.58,"id":5071877},{"batb":[[0,1.47,162.35],[1,1.46,482.28]],"batl":[[0,1.49,37.16],[1,1.5,7303.29]],"ltp":1.48,"tv":18375.81,"id":6374165}]}]}
{"op":"mcm","clk":"1006257136","pt":1580594663331,"mc":[{"id":"1.168175448","rc":[{"batb":[[1,2.94,221.02]],"ltp":3.0,"tv":1604.58,"id":5071877}]}]}
{"op":"mcm","clk":"1006258622","pt":1580594677111,"mc":[{"id":"1.168175448","rc":[{"batb":[[0,1.47,53.18]],"ltp":1.48,"tv":18375.81,"id":6374165}]}]}
{"op":"mcm","clk":"1006258673","pt":1580594677577,"mc":[{"id":"1.168175448","rc":[{"batb":[[0,1.47,3]],"ltp":1.48,"tv":18375.81,"id":6374165}]}]}
{"op":"mcm","clk":"1006259314","pt":1580594684613,"mc":[{"id":"1.168175448","rc":[{"trd":[[1.49,909.96]],"batl":[[0,1.49,33.87]],"ltp":1.49,"tv":18382.0,"id":6374165}],"tv":19986.58}]}
{"op":"mcm","clk":"1006259737","pt":1580594688453,"mc":[{"id":"1.168175448","marketDefinition":{"bspMarket":false,"turnInPlayEnabled":true,"persistenceEnabled":true,"marketBaseRate":5.0,"eventId":"29680072","eventTypeId":"2","numberOfWinners":1,"bettingType":"ODDS","marketType":"MATCH_ODDS","marketTime":"2020-02-01T21:57:00.000Z","suspendTime":"2020-02-01T21:57:00.000Z","bspReconciled":false,"complete":true,"inPlay":false,"crossMatching":true,"runnersVoidable":false,"numberOfActiveRunners":2,"betDelay":0,"status":"OPEN","runners":[{"status":"ACTIVE","sortPriority":1,"id":6374165,"name":"Marco Cecchinato"},{"status":"ACTIVE","sortPriority":2,"id":5071877,"name":"Andrej Martin"}],"regulators":["MR_INT"],"countryCode":"UY","discountAllowed":true,"timezone":"UTC","openDate":"2020-02-01T21:57:00.000Z","version":3147667732,"name":"Match Odds","eventName":"Cecchinato v Martin"},"rc":[{"batb":[[1,2.94,12.99]],"batl":[[0,3.3,68.89]],"ltp":3.0,"tv":1604.58,"id":5071877},{"batb":[[1,1.46,131.91]],"ltp":1.49,"tv":18382.0,"id":6374165}]}]}
{"op":"mcm","clk":"1006259796","pt":1580594689138,"mc":[{"id":"1.168175448","marketDefinition":{"bspMarket":false,"turnInPlayEnabled":true,"persistenceEnabled":true,"marketBaseRate":5.0,"eventId":"29680072","eventTypeId":"2","numberOfWinners":1,"bettingType":"ODDS","marketType":"MATCH_ODDS","marketTime":"2020-02-01T21:57:00.000Z","suspendTime":"2020-02-01T21:57:00.000Z","bspReconciled":false,"complete":true,"inPlay":true,"crossMatching":true,"runnersVoidable":false,"numberOfActiveRunners":2,"betDelay":3,"status":"OPEN","runners":[{"status":"ACTIVE","sortPriority":1,"id":6374165,"name":"Marco Cecchinato"},{"status":"ACTIVE","sortPriority":2,"id":5071877,"name":"Andrej Martin"}],"regulators":["MR_INT"],"countryCode":"UY","discountAllowed":true,"timezone":"UTC","openDate":"2020-02-01T21:57:00.000Z","version":3147676920,"name":"Match Odds","eventName":"Cecchinato v Martin"},"rc":[{"batb":[[0,1.64,81.37],[1,1.6,2.53],[2,1.26,7.11]],"batl":[[2,1000,0.02]],"ltp":3.0,"tv":1604.58,"id":5071877},{"batb":[[0,1.46,129.39],[1,1.35,30],[2,1.3,2.53]],"batl":[[0,1.5,7242.51],[1,1.54,239.46],[2,1.56,5.3]],"ltp":1.49,"tv":18382.0,"id":6374165}]}]}
{"op":"mcm","clk":"1006261073","pt":1580594702518,"mc":[{"id":"1.168175448","rc":[{"trd":[[1.46,258.78]],"batb":[[0,1.35,30],[1,1.3,2.53],[2,1.05,152.6]],"batl":[[0,1.46,4359.01],[1,1.5,7242.51],[2,1.51,10.32]],"ltp":1.46,"tv":18640.78,"id":6374165}],"tv":20245.36}]}
{"op":"mcm","clk":"1006261163","pt":1580594703448,"mc":[{"id":"1.168175448","rc":[{"batl":[[1,3.4,19],[2,3.5,24]],"ltp":3.0,"tv":1604.58,"id":5071877},{"batl":[[0,1.45,61],[1,1.46,30],[2,1.47,28]],"ltp":1.46,"tv":18640.78,"id":6374165}]}]}
{"op":"mcm","clk":"1006261233","pt":1580594704124,"mc":[{"id":"1.168175448","rc":[{"batb":[[0,3.1,178.77],[1,2.94,86.71],[2,1.64,81.37]],"batl":[[2,3.45,16.8]],"ltp":3.0,"tv":1604.58,"id":5071877},{"batb":[[0,1.42,395.22],[1,1.41,101.66],[2,1.39,438.89]],"ltp":1.46,"tv":18640.78,"id":6374165}]}]}
{"op":"mcm","clk":"1006261441","pt":1580594705941,"mc":[{"id":"1.168175448","rc":[{"batl":[[1,1.46,147.37]],"ltp":1.46,"tv":18640.78,"id":6374165}]}]}
{"op":"mcm","clk":"1006261650","pt":1580594708022,"mc":[{"id":"1.168175448","rc":[{"trd":[[3.2,2.27]],"ltp":3.2,"tv":1606.85,"id":5071877},{"trd":[[1.45,5.01]],"batl":[[0,1.45,55.99]],"ltp":1.45,"tv":18645.79,"id":6374165}],"tv":20252.64}]}
{"op":"mcm","clk":"1006261924","pt":1580594710535,"mc":[{"id":"1.168175448","rc":[{"batb":[[1,2.96,21],[2,2.94,86.71]],"ltp":3.2,"tv":1606.85,"id":5071877}]}]}
{"op":"mcm","clk":"1006261957","pt":1580594710945,"mc":[{"id":"1.168175448","rc":[{"batl":[[0,1.45,57.67]],"ltp":1.45,"tv":18645.79,"id":6374165}]}]}
{"op":"mcm","clk":"1006262064","pt":1580594711830,"mc":[{"id":"1.168175448","rc":[{"batl":[[1,1.46,30]],"ltp":1.45,"tv":18645.79,"id":6374165}]}]}
{"op":"mcm","clk":"1006262567","pt":1580594716451,"mc":[{"id":"1.168175448","rc":[{"trd":[[1.45,6.77]],"batl":[[0,1.45,56.79],[1,1.46,42.6]],"ltp":1.45,"tv":18647.55,"id":6374165}],"tv":20254.4}]}
{"op":"mcm","clk":"1006262673","pt":1580594717441,"mc":[{"id":"1.168175448","rc":[{"batb":[[0,2.96,21],[1,2.94,86.71],[2,1.64,81.37]],"batl":[[1,3.45,16.8],[2,3.7,14.56]],"ltp":3.2,"tv":1606.85,"id":5071877},{"batb":[[0,1.41,101.66],[1,1.39,438.89],[2,1.35,30]],"batl":[[0,1.45,1.68],[1,1.46,12.6],[2,1.48,12.6]],"ltp":1.45,"tv":18647.55,"id":6374165}]}]}
{"op":"mcm","clk":"1006262784","pt":1580594718328,"mc":[{"id":"1.168175448","rc":[{"trd":[[3.3,36.38]],"batb":[[0,2.94,86.71],[1,1.64,81.37],[2,1.6,2.53]],"batl":[[0,3.3,32.5],[1,3.7,14.56],[2,1000,0.02]],"ltp":3.3,"tv":1643.23,"id":5071877},{"trd":[[1.43,84]],"batb":[[0,1.43,3]],"ltp":1.43,"tv":18731.55,"id":6374165}],"tv":20374.78}]}
{"op":"mcm","clk":"1006263039","pt":1580594720465,"mc":[{"id":"1.168175448","rc":[{"batb":[[0,2.9,88.36]],"ltp":3.3,"tv":1643.23,"id":5071877},{"batb":[[1,1.39,432.2]],"ltp":1.43,"tv":18731.55,"id":6374165}]}]}
{"op":"mcm","clk":"1006263423","pt":1580594724168,"mc":[{"id":"1.168175448","rc":[{"trd":[[3.3,68.89]],"batl":[[0,3.7,14.56],[1,1000,0.02],[2,1000,0]],"ltp":3.3,"tv":1675.73,"id":5071877},{"trd":[[1.43,190.28]],"batb":[[0,1.39,432.2],[1,1.35,30],[2,1.3,2.53]],"batl":[[0,1.43,59.35],[1,1.45,1.68],[2,1.46,12.6]],"ltp":1.43,"tv":18837.83,"id":6374165}],"tv":20513.57}]}
{"op":"mcm","clk":"1006263582","pt":1580594725269,"mc":[{"id":"1.168175448","rc":[{"batl":[[0,1.43,68.14]],"ltp":1.43,"tv":18837.83,"id":6374165}]}]}
{"op":"mcm","clk":"1006263628","pt":1580594725631,"mc":[{"id":"1.168175448","rc":[{"batl":[[0,1.43,70.14]],"ltp":1.43,"tv":18837.83,"id":6374165}]}]}
{"op":"mcm","clk":"1006264015","pt":1580594729373,"mc":[{"id":"1.168175448","rc":[{"trd":[[1.4,0.04],[1.43,206.14]],"batl":[[0,1.43,62.2]],"ltp":1.43,"tv":18853.73,"id":6374165}],"tv":20529.47}]}
{"op":"mcm","clk":"1006264043","pt":1580594729683,"mc":[{"id":"1.168175448","rc":[{"batl":[[0,1.43,53.42]],"ltp":1.43,"tv":18853.73,"id":6374165}]}]}
{"op":"mcm","clk":"1006264661","pt":1580594735285,"mc":[{"id":"1.168175448","rc":[{"trd":[[1.43,208.23]],"batl":[[0,1.43,52.38]],"ltp":1.43,"tv":18855.81,"id":6374165}],"tv":20531.55}]}
{"op":"mcm","clk":"1006265382","pt":1580594741179,"mc":[{"id":"1.168175448","rc":[{"batb":[[0,1.42,535.06],[1,1.41,674.31],[2,1.39,432.2]],"ltp":1.43,"tv":18855.81,"id":6374165}]}]}
{"op":"mcm","clk":"1006265912","pt":1580594745909,"mc":[{"id":"1.168175448","rc":[{"batb":[[0,1.39,432.2],[1,1.35,30],[2,1.3,2.53]],"ltp":1.43,"tv":18855.81,"id":6374165}]}]}
{"op":"mcm","clk":"1006266089","pt":1580594747461,"mc":[{"id":"1.168175448","rc":[{"batl":[[1,1.46,12.6],[2,1.48,12.6]],"ltp":1.43,"tv":18855.81,"id":6374165}]}]}
{"op":"mcm","clk":"1006266209","pt":1580594748504,"mc":[{"id":"1.168175448","rc":[{"trd":[[3.3,91.59]],"batl":[[0,3.1,2047.3],[1,3.15,2279],[2,3.35,4.58]],"ltp":3.3,"tv":1698.43,"id":5071877},{"trd":[[1.43,260.61],[1.48,2310.01]],"batb":[[0,1.48,623.93],[1,1.39,432.2],[2,1.35,30]],"batl":[[0,1.49,12.6],[1,1.5,7242.51],[2,1.54,799.75]],"ltp":1.48,"tv":18933.39,"id":6374165}],"tv":20631.83}]}
{"op":"mcm","clk":"1006266321","pt":1580594749482,"mc":[{"id":"1.168175448","rc":[{"trd":[[3,448.3]],"batb":[[1,2.88,10.91],[2,2.82,22.69]],"batl":[[0,3.1,23],[1,3.15,15],[2,3.2,15]],"ltp":3.0,"tv":1701.77,"id":5071877},{"trd":[[1.49,928.44],[1.5,10638.53]],"batb":[[0,1.49,532.84],[1,1.48,955.02],[2,1.47,12.6]],"batl":[[0,1.5,6709.19],[1,1.51,43],[2,1.52,26]],"ltp":1.5,"tv":20018.5,"id":6374165}],"tv":21720.27}]}
{"op":"mcm","clk":"1006266420","pt":1580594750516,"mc":[{"id":"1.168175448","rc":[{"batb":[[2,2.64,111.89]],"batl":[[1,3.15,52.86]],"ltp":3.0,"tv":1701.77,"id":5071877}]}]}
{"op":"mcm","clk":"1006266499","pt":1580594751308,"mc":[{"id":"1.168175448","rc":[{"batl":[[1,3.15,15]],"ltp":3.0,"tv":1701.77,"id":5071877}]}]}
{"op":"mcm","clk":"1006266591","pt":1580594752129,"mc":[{"id":"1.168175448","rc":[{"batb":[[0,1.49,772.73],[1,1.48,1506.38]],"ltp":1.5,"tv":20018.5,"id":6374165}]}]}
{"op":"mcm","clk":"1006266724","pt":1580594753374,"mc":[{"id":"1.168175448","rc":[{"batb":[[2,2.84,22.69]],"ltp":3.0,"tv":1701.77,"id":5071877}]}]}
{"op":"mcm","clk":"1006267158","pt":1580594757118,"mc":[{"id":"1.168175448","rc":[{"trd":[[3.05,21.56]],"ltp":3.05,"tv":1701.88,"id":5071877},{"trd":[[1.49,928.66]],"batb":[[0,1.49,772.51]],"ltp":1.49,"tv":20018.72,"id":6374165}],"tv":21720.6}]}
{"op":"mcm","clk":"1006267355","pt":1580594758791,"mc":[{"id":"1.168175448","rc":[{"batb":[[1,2.84,22.69],[2,2.64,111.89]],"ltp":3.05,"tv":1701.88,"id":5071877}]}]}
{"op":"mcm","clk":"1006267653","pt":1580594761701,"mc":[{"id":"1.168175448","rc":[{"batb":[[0,2.96,5.72],[1,2.9,88.36],[2,2.84,22.69]],"batl":[[0,3.05,6.83],[1,3.1,23],[2,3.15,15]],"ltp":3.05,"tv":1701.88,"id":5071877}]}]}
{"op":"mcm","clk":"1006267816","pt":1580594763297,"mc":[{"id":"1.168175448","rc":[{"trd":[[1.49,929.14],[1.5,10640.29]],"batb":[[0,1.49,772.27]],"batl":[[0,1.5,6708.31]],"ltp":1.49,"tv":20020.95,"id":6374165}],"tv":21722.84}]}
{"op":"mcm","clk":"1006267947","pt":1580594764448,"mc":[{"id":"1.168175448","rc":[{"trd":[[3,848.92]],"ltp":3.0,"tv":2102.5,"id":5071877},{"trd":[[1.5,11441.56]],"batl":[[0,1.5,5907.04]],"ltp":1.5,"tv":20822.22,"id":6374165}],"tv":22924.73}]}
{"op":"mcm","clk":"1006268160","pt":1580594766322,"mc":[{"id":"1.168175448","rc":[{"trd":[[1.49,954.75]],"batb":[[0,1.49,759.47]],"ltp":1.49,"tv":20847.83,"id":6374165}],"tv":22950.33}]}
{"op":"mcm","clk":"1006268689","pt":1580594770540,"mc":[{"id":"1.168175448","rc":[{"trd":[[3,849.19]],"batl":[[1,3.25,18.48],[2,3.7,14.56]],"ltp":3.0,"tv":2102.77,"id":5071877},{"trd":[[1.5,11452.1]],"batl":[[0,1.5,5901.51],[1,1.53,384.22],[2,1.54,704.76]],"ltp":1.5,"tv":20858.36,"id":6374165}],"tv":22961.14}]}
{"op":"mcm","clk":"1006268729","pt":1580594770850,"mc":[{"id":"1.168175448","rc":[{"trd":[[1.49,955.06],[1.5,11458.68]],"batb":[[0,1.49,759.31]],"batl":[[0,1.5,5898.22]],"ltp":1.5,"tv":20865.26,"id":6374165}],"tv":22968.03}]}
{"op":"mcm","clk":"1006268919","pt":1580594772544,"mc":[{"id":"1.168175448","rc":[{"trd":[[1.49,1110.38]],"batb":[[0,1.49,681.65]],"ltp":1.49,"tv":21020.58,"id":6374165}],"tv":23123.35}]}
{"op":"mcm","clk":"1006269043","pt":1580594773534,"mc":[{"id":"1.168175448","rc":[{"batb":[[0,2.9,88.36],[1,2.84,22.69],[2,2.64,111.89]],"batl":[[0,3.25,18.48],[1,3.7,14.56],[2,1000,0.02]],"ltp":3.0,"tv":2102.77,"id":5071877},{"batb":[[1,1.48,882.45]],"ltp":1.49,"tv":21020.58,"id":6374165}]}]}
{"op":"mcm","clk":"1006269168","pt":1580594774412,"mc":[{"id":"1.168175448","rc":[{"batb":[[0,2.64,111.89],[1,1.64,81.37],[2,1.6,2.53]],"batl":[[0,3.7,14.56],[1,1000,0.02],[2,1000,0]],"ltp":3.0,"tv":2102.77,"id":5071877},{"batb":[[0,1.47,12.6],[1,1.46,12.6],[2,1.45,12.6]],"batl":[[1,1.54,239.46],[2,1.56,5.3]],"ltp":1.49,"tv":21020.58,"id":6374165}]}]}
{"op":"mcm","clk":"1006269535","pt":1580594777537,"mc":[{"id":"1.168175448","rc":[{"trd":[[1.47,806.5],[1.5,11460.05]],"batb":[[0,1.47,9.57]],"batl":[[0,1.49,28.52],[1,1.5,5897.53],[2,1.54,239.46]],"ltp":1.5,"tv":21028.02,"id":6374165}],"tv":23130.79}]}
{"op":"mcm","clk":"1006269604","pt":1580594778007,"mc":[{"id":"1.168175448","rc":[{"trd":[[1.47,820.01]],"batb":[[0,1.47,2.81],[2,1.45,496.82]],"ltp":1.47,"tv":21041.53,"id":6374165}],"tv":23144.3}]}
{"op":"mcm","clk":"1006270127","pt":1580594782544,"mc":[{"id":"1.168175448","rc":[{"batb":[[0,1.45,496.82],[1,1.44,995.67],[2,1.43,13.08]],"ltp":1.47,"tv":21041.53,"id":6374165}]}]}
{"op":"mcm","clk":"1006270177","pt":1580594782858,"mc":[{"id":"1.168175448","rc":[{"batb":[[0,1.45,484.22]],"ltp":1.47,"tv":21041.53,"id":6374165}]}]}
{"op":"mcm","clk":"1006270364","pt":1580594784474,"mc":[{"id":"1.168175448","rc":[{"batb":[[0,1.45,3587.67]],"batl":[[0,1.46,3794.74],[1,1.47,4825],[2,1.49,3048.65]],"ltp":1.47,"tv":21041.53,"id":6374165}]}]}
{"op":"mcm","clk":"1006270533","pt":1580594785568,"mc":[{"id":"1.168175448","rc":[{"batb":[[0,3.05,188.99],[1,2.94,21],[2,2.86,91.59]],"batl":[[0,3.35,24],[1,3.4,12],[2,3.45,16.8]],"ltp":3.0,"tv":2102.77,"id":5071877},{"batb":[[1,1.44,1007.86],[2,1.43,737.22]],"batl":[[0,1.46,65.56],[1,1.47,207.6],[2,1.48,39.6]],"ltp":1.47,"tv":21041.53,"id":6374165}]}]}
{"op":"mcm","clk":"1006270620","pt":1580594786251,"mc":[{"id":"1.168175448","rc":[{"batl":[[1,1.47,41.6]],"ltp":1.47,"tv":21041.53,"id":6374165}]}]}
{"op":"mcm","clk":"1006270734","pt":1580594787131,"mc":[{"id":"1.168175448","rc":[{"batl":[[2,1.48,41.6]],"ltp":1.47,"tv":21041.53,"id":6374165}]}]}
{"op":"mcm","clk":"1006270864","pt":1580594788371,"mc":[{"id":"1.168175448","rc":[{"trd":[[1.46,302.8]],"batl":[[0,1.46,43.55]],"ltp":1.46,"tv":21085.55,"id":6374165}],"tv":23188.32}]}
{"op":"mcm","clk":"1006271120","pt":1580594790463,"mc":[{"id":"1.168175448","rc":[{"batb":[[0,1.45,3625.05]],"ltp":1.46,"tv":21085.55,"id":6374165}]}]}
{"op":"mcm","clk":"1006271217","pt":1580594791242,"mc":[{"id":"1.168175448","rc":[{"batb":[[1,1.44,1020.46]],"ltp":1.46,"tv":21085.55,"id":6374165}]}]}
{"op":"mcm","clk":"1006271473","pt":1580594793387,"mc":[{"id":"1.168175448","rc":[{"trd":[[1.45,24.32]],"batb":[[0,1.45,3616.27]],"ltp":1.45,"tv":21103.1,"id":6374165}],"tv":23205.88}]}
{"op":"mcm","clk":"1006271724","pt":1580594795462,"mc":[{"id":"1.168175448","rc":[{"batb":[[0,2.94,21],[1,2.86,91.59],[2,1.64,81.37]],"batl":[[0,3.45,16.8],[1,3.7,14.56],[2,1000,0.02]],"ltp":3.0,"tv":2102.77,"id":5071877},{"batb":[[0,1.45,37.38],[1,1.44,12.6],[2,1.43,13.08]],"batl":[[0,1.47,12.6],[1,1.48,14.6],[2,1.49,12.6]],"ltp":1.45,"tv":21103.1,"id":6374165}]}]}
{"op":"mcm","clk":"1006271854","pt":1580594796441,"mc":[{"id":"1.168175448","rc":[{"batb":[[0,2.86,91.59],[1,1.64,81.37],[2,1.6,2.53]],"batl":[[0,3.7,14.56],[1,1000,0.02],[2,1000,0]],"ltp":3.0,"tv":2102.77,"id":5071877}]}]}
{"op":"mcm","clk":"1006272434","pt":1580594801243,"mc":[{"id":"1.168175448","rc":[{"batl":[[0,3.15,37.86],[1,3.7,14.56],[2,1000,0.02]],"ltp":3.0,"tv":2102.77,"id":5071877},{"trd":[[1.45,81.37]],"batb":[[0,1.45,8.86]],"ltp":1.45,"tv":21160.15,"id":6374165}],"tv":23262.93}]}
{"op":"mcm","clk":"1006272578","pt":1580594802446,"mc":[{"id":"1.168175448","rc":[{"batb":[[2,1.43,14.19]],"ltp":1.45,"tv":21160.15,"id":6374165}]}]}
{"op":"mcm","clk":"1006272697","pt":1580594803500,"mc":[{"id":"1.168175448","rc":[{"batb":[[0,1.43,14.19],[1,1.42,12.6],[2,1.41,962.4]],"ltp":1.45,"tv":21160.15,"id":6374165}]}]}
{"op":"mcm","clk":"1006272722","pt":1580594803692,"mc":[{"id":"1.168175448","rc":[{"batb":[[0,1.43,1.58]],"ltp":1.45,"tv":21160.15,"id":6374165}]}]}
{"op":"mcm","clk":"1006273075","pt":1580594806569,"mc":[{"id":"1.168175448","rc":[{"trd":[[3.15,105.05]],"batb":[[0,3.25,161.06],[1,3.1,803.79],[2,3.05,190.1]],"batl":[[0,3.55,324.55],[1,3.65,21],[2,3.7,25.56]],"ltp":3.15,"tv":2140.63,"id":5071877},{"trd":[[1.42,25.2],[1.43,263.77],[1.46,384.49]],"batb":[[0,1.41,4168],[1,1.4,1144.49],[2,1.37,464.85]],"batl":[[0,1.42,34.4],[1,1.43,45.84],[2,1.44,178.6]],"ltp":1.42,"tv":21270.21,"id":6374165}],"tv":23410.85}]}
{"op":"mcm","clk":"1006273175","pt":1580594807350,"mc":[{"id":"1.168175448","rc":[{"batb":[[1,3.1,823.11]],"batl":[[1,3.65,36.12]],"ltp":3.15,"tv":2140.63,"id":5071877},{"batb":[[2,1.38,110.07]],"ltp":1.42,"tv":21270.21,"id":6374165}]}]}
{"op":"mcm","clk":"1006273379","pt":1580594809067,"mc":[{"id":"1.168175448","rc":[{"trd":[[1.42,94]],"batl":[[0,1.43,45.84],[1,1.44,12.6],[2,1.45,3847.21]],"ltp":1.42,"tv":21339.01,"id":6374165}],"tv":23479.65}]}
{"op":"mcm","clk":"1006273654","pt":1580594811364,"mc":[{"id":"1.168175448","rc":[{"batl":[[0,1.43,58.44]],"ltp":1.42,"tv":21339.01,"id":6374165}]}]}
{"op":"mcm","clk":"1006273892","pt":1580594813593,"mc":[{"id":"1.168175448","rc":[{"batl":[[1,1.44,25.21]],"ltp":1.42,"tv":21339.01,"id":6374165}]}]}
{"op":"mcm","clk":"1006274484","pt":1580594818412,"mc":[{"id":"1.168175448","rc":[{"batb":[[0,3.05,190.1],[1,2.88,39.86],[2,1.64,81.37]],"batl":[[0,3.7,14.56],[1,1000,0.02],[2,3.7,0]],"ltp":3.15,"tv":2140.63,"id":5071877},{"batb":[[0,1.41,12.6],[1,1.4,12.6],[2,1.37,464.85]],"batl":[[0,1.43,12.6],[2,1.45,12.6]],"ltp":1.42,"tv":21339.01,"id":6374165}]}]}
{"op":"mcm","clk":"1006274626","pt":1580594819712,"mc":[{"id":"1.168175448","rc":[{"trd":[[1.41,3.51]],"batb":[[0,1.41,10.85]],"ltp":1.41,"tv":21342.52,"id":6374165}],"tv":23483.16}]}
{"op":"mcm","clk":"1006274791","pt":1580594821079,"mc":[{"id":"1.168175448","rc":[{"batb":[[2,1.39,1035.05]],"ltp":1.41,"tv":21342.52,"id":6374165}]}]}
{"op":"mcm","clk":"1006275273","pt":1580594824374,"mc":[{"id":"1.168175448","rc":[{"trd":[[1.41,4.62]],"batb":[[0,1.41,10.29],[1,1.4,15.95]],"ltp":1.41,"tv":21343.63,"id":6374165}],"tv":23484.27}]}
{"op":"mcm","clk":"1006275533","pt":1580594826404,"mc":[{"id":"1.168175448","rc":[{"batb":[[0,1.4,15.95],[1,1.39,1035.05],[2,1.38,765.75]],"ltp":1.41,"tv":21343.63,"id":6374165}]}]}
{"op":"mcm","clk":"1006275579","pt":1580594826712,"mc":[{"id":"1.168175448","rc":[{"batb":[[0,1.4,3.35]],"ltp":1.41,"tv":21343.63,"id":6374165}]}]}
{"op":"mcm","clk":"1006275871","pt":1580594829566,"mc":[{"id":"1.168175448","rc":[{"trd":[[3.4,4]],"batb":[[0,3.4,238.2],[1,3.05,190.1],[2,2.88,39.86]],"batl":[[0,3.6,5.78],[1,3.65,24],[2,3.7,292.32]],"ltp":3.4,"tv":2144.63,"id":5071877},{"batb":[[0,1.4,5.02],[1,1.39,4272.46]],"batl":[[0,1.41,78.89],[1,1.42,121],[2,1.43,3924.93]],"ltp":1.41,"tv":21343.63,"id":6374165}],"tv":23488.27}]}
{"op":"mcm","clk":"1006276054","pt":1580594830353,"mc":[{"id":"1.168175448","rc":[{"trd":[[3.4,8]],"batb":[[0,3.4,380.66],[1,3.25,18.48],[2,3.2,171.05]],"ltp":3.4,"tv":2148.63,"id":5071877},{"batl":[[0,1.41,91.49],[1,1.42,133.6]],"ltp":1.41,"tv":21343.63,"id":6374165}],"tv":23492.27}]}
{"op":"mcm","clk":"1006276290","pt":1580594832288,"mc":[{"id":"1.168175448","rc":[{"trd":[[3.4,16]],"batb":[[0,3.4,376.66]],"ltp":3.4,"tv":2156.63,"id":5071877},{"trd":[[1.39,13.44],[1.4,10.07]],"batb":[[0,1.39,4265.74],[1,1.38,765.75],[2,1.37,464.85]],"ltp":1.39,"tv":21367.11,"id":6374165}],"tv":23523.74}]}
{"op":"mcm","clk":"1006276673","pt":1580594835361,"mc":[{"id":"1.168175448","rc":[{"trd":[[1.41,104.62]],"batb":[[0,1.4,25.21],[1,1.39,4265.74],[2,1.38,765.75]],"batl":[[0,1.41,41.49]],"ltp":1.41,"tv":21467.11,"id":6374165}],"tv":23623.74}]}
{"op":"mcm","clk":"1006276793","pt":1580594836202,"mc":[{"id":"1.168175448","rc":[{"batb":[[0,1.4,37.81]],"ltp":1.41,"tv":21467.11,"id":6374165}]}]}
{"op":"mcm","clk":"1006276907","pt":1580594836878,"mc":[{"id":"1.168175448","rc":[{"batb":[[0,1.4,50.41]],"ltp":1.41,"tv":21467.11,"id":6374165}]}]}
{"op":"mcm","clk":"1006277113","pt":1580594838288,"mc":[{"id":"1.168175448","rc":[{"trd":[[3.4,16.44]],"batb":[[0,3.4,376.44],[2,3.15,173.49]],"ltp":3.4,"tv":2157.07,"id":5071877},{"batl":[[0,1.41,54.1]],"ltp":1.41,"tv":21467.11,"id":6374165}],"tv":23624.19}]}
{"op":"mcm","clk":"1006277252","pt":1580594839275,"mc":[{"id":"1.168175448","rc":[{"trd":[[1.41,106.41]],"batl":[[0,1.41,65.81]],"ltp":1.41,"tv":21468.89,"id":6374165}],"tv":23625.97}]}
{"op":"mcm","clk":"1006277389","pt":1580594840275,"mc":[{"id":"1.168175448","rc":[{"batb":[[0,1.4,51.12]],"batl":[[0,1.41,78.41]],"ltp":1.41,"tv":21468.89,"id":6374165}]}]}
{"op":"mcm","clk":"1006277508","pt":1580594841210,"mc":[{"id":"1.168175448","rc":[{"trd":[[1.41,126.41]],"batb":[[0,1.4,52.79]],"batl":[[0,1.41,81.01]],"ltp":1.41,"tv":21488.89,"id":6374165}],"tv":23645.97}]}
{"op":"mcm","clk":"1006277607","pt":1580594841880,"mc":[{"id":"1.168175448","rc":[{"trd":[[3.4,20.99]],"batb":[[0,3.4,374.17]],"ltp":3.4,"tv":2161.62,"id":5071877},{"trd":[[1.41,127.35]],"batl":[[0,1.41,80.54]],"ltp":1.41,"tv":21489.83,"id":6374165}],"tv":23651.45}]}
{"op":"mcm","clk":"1006277803","pt":1580594843499,"mc":[{"id":"1.168175448","rc":[{"trd":[[3.4,22.46]],"batb":[[0,3.4,373.43]],"ltp":3.4,"tv":2163.09,"id":5071877},{"batl":[[0,1.41,220.86]],"ltp":1.41,"tv":21489.83,"id":6374165}],"tv":23652.93}]}
{"op":"mcm","clk":"1006277897","pt":1580594844281,"mc":[{"id":"1.168175448","rc":[{"trd":[[1.41,137.39]],"batl":[[0,1.41,215.84]],"ltp":1.41,"tv":21499.87,"id":6374165}],"tv":23662.97}]}
{"op":"mcm","clk":"1006278038","pt":1580594845376,"mc":[{"id":"1.168175448","rc":[{"batl":[[0,3.65,24],[1,3.7,292.32],[2,3.8,34.28]],"ltp":3.4,"tv":2163.09,"id":5071877}]}]}
{"op":"mcm","clk":"1006278081","pt":1580594845702,"mc":[{"id":"1.168175448","rc":[{"trd":[[1.41,137.91]],"batl":[[0,1.41,215.58]],"ltp":1.41,"tv":21500.4,"id":6374165}],"tv":23663.5}]}
{"op":"mcm","clk":"1006278311","pt":1580594847508,"mc":[{"id":"1.168175448","rc":[{"trd":[[1.4,11.82]],"batb":[[0,1.4,51.91]],"ltp":1.4,"tv":21502.15,"id":6374165}],"tv":23665.25}]}
{"op":"mcm","clk":"1006278409","pt":1580594848395,"mc":[{"id":"1.168175448","rc":[{"batl":[[0,3.5,5.81],[1,3.65,24],[2,3.7,292.32]],"ltp":3.4,"tv":2163.09,"id":5071877},{"batl":[[1,1.42,147.44]],"ltp":1.4,"tv":21502.15,"id":6374165}]}]}
{"op":"mcm","clk":"1006278489","pt":1580594849068,"mc":[{"id":"1.168175448","rc":[{"trd":[[3.4,774.51]],"batb":[[0,3.25,18.48],[1,3.15,173.49],[2,2.88,39.86]],"ltp":3.4,"tv":2915.14,"id":5071877},{"trd":[[1.41,150.44]],"batl":[[0,1.41,203.05]],"ltp":1.41,"tv":21514.68,"id":6374165}],"tv":24429.82}]}
{"op":"mcm","clk":"1006278706","pt":1580594850994,"mc":[{"id":"1.168175448","rc":[{"trd":[[3.5,5.81]],"batl":[[0,3.65,24],[1,3.7,292.32],[2,3.8,34.28]],"ltp":3.5,"tv":2920.95,"id":5071877},{"trd":[[1.4,135.53],[1.41,151.65]],"batb":[[0,1.39,4265.74],[1,1.38,765.75],[2,1.37,459.9]],"batl":[[0,1.4,30.88],[1,1.41,202.44],[2,1.42,147.44]],"ltp":1.4,"tv":21639.6,"id":6374165}],"tv":24560.55}]}
{"op":"mcm","clk":"1006278952","pt":1580594853199,"mc":[{"id":"1.168175448","rc":[{"batb":[[0,3.15,173.49],[1,2.88,39.86],[2,1.64,81.37]],"batl":[[2,3.8,20]],"ltp":3.5,"tv":2920.95,"id":5071877},{"trd":[[1.4,141.09]],"batl":[[0,1.4,28.1]],"ltp":1.4,"tv":21645.16,"id":6374165}],"tv":24566.11}]}
{"op":"mcm","clk":"1006279095","pt":1580594854289,"mc":[{"id":"1.168175448","rc":[{"batl":[[1,1.41,215.05]],"ltp":1.4,"tv":21645.16,"id":6374165}]}]}
{"op":"mcm","clk":"1006279158","pt":1580594854912,"mc":[{"id":"1.168175448","rc":[{"batl":[[1,1.41,227.65]],"ltp":1.4,"tv":21645.16,"id":6374165}]}]}
{"op":"mcm","clk":"1006279318","pt":1580594856321,"mc":[{"id":"1.168175448","rc":[{"batb":[[0,3.3,17.64],[1,3.15,173.49],[2,2.88,39.86]],"ltp":3.5,"tv":2920.95,"id":5071877},{"trd":[[1.4,191.94]],"batl":[[0,1.4,2.68]],"ltp":1.4,"tv":21696.0,"id":6374165}],"tv":24616.96}]}
{"op":"mcm","clk":"1006279546","pt":1580594858195,"mc":[{"id":"1.168175448","rc":[{"trd":[[1.4,197.3]],"batb":[[0,1.4,11.02],[1,1.39,4265.74],[2,1.38,765.75]],"batl":[[0,1.41,227.65],[1,1.42,147.44],[2,1.43,3924.93]],"ltp":1.4,"tv":21701.36,"id":6374165}],"tv":24622.32}]}
{"op":"mcm","clk":"1006279904","pt":1580594861330,"mc":[{"id":"1.168175448","rc":[{"batl":[[0,1.41,323.37],[1,1.42,133.6]],"ltp":1.4,"tv":21701.36,"id":6374165}]}]}
{"op":"mcm","clk":"1006280068","pt":1580594862530,"mc":[{"id":"1.168175448","rc":[{"batb":[[0,1.4,11.9]],"batl":[[1,1.42,146.21]],"ltp":1.4,"tv":21701.36,"id":6374165}]}]}
{"op":"mcm","clk":"1006280110","pt":1580594862897,"mc":[{"id":"1.168175448","rc":[{"trd":[[3.4,776.78]],"ltp":3.4,"tv":2923.22,"id":5071877},{"trd":[[1.41,157.13]],"batl":[[0,1.41,317.9],[1,1.42,158.81]],"ltp":1.41,"tv":21706.84,"id":6374165}],"tv":24630.07}]}
{"op":"mcm","clk":"1006280244","pt":1580594864196,"mc":[{"id":"1.168175448","rc":[{"batl":[[0,3.5,1.32],[1,3.55,4.64],[2,3.65,24]],"ltp":3.4,"tv":2923.22,"id":5071877},{"batl":[[0,1.41,332.33]],"ltp":1.41,"tv":21706.84,"id":6374165}]}]}
{"op":"mcm","clk":"1006280393","pt":1580594865506,"mc":[{"id":"1.168175448","rc":[{"batb":[[0,1.4,12.32]],"ltp":1.41,"tv":21706.84,"id":6374165}]}]}
{"op":"mcm","clk":"1006280454","pt":1580594866032,"mc":[{"id":"1.168175448","rc":[{"batb":[[1,1.39,3237.41],[2,1.38,12.6]],"batl":[[2,1.43,3191.45]],"ltp":1.41,"tv":21706.84,"id":6374165}]}]}
{"op":"mcm","clk":"1006280896","pt":1580594869638,"mc":[{"id":"1.168175448","rc":[{"batb":[[0,1.4,11.22]],"ltp":1.41,"tv":21706.84,"id":6374165}]}]}
{"op":"mcm","clk":"1006281298","pt":1580594872924,"mc":[{"id":"1.168175448","rc":[{"trd":[[3.4,779.06]],"ltp":3.4,"tv":2925.5,"id":5071877},{"trd":[[1.41,162.62]],"batl":[[0,1.41,326.83]],"ltp":1.41,"tv":21712.34,"id":6374165}],"tv":24637.84}]}
{"op":"mcm","clk":"1006281410","pt":1580594873921,"mc":[{"id":"1.168175448","rc":[{"trd":[[1.41,164.38]],"batl":[[0,1.41,325.96]],"ltp":1.41,"tv":21714.09,"id":6374165}],"tv":24639.59}]}
{"op":"mcm","clk":"1006281669","pt":1580594876176,"mc":[{"id":"1.168175448","rc":[{"trd":[[1.41,173.84]],"batl":[[0,1.41,321.23]],"ltp":1.41,"tv":21723.55,"id":6374165}],"tv":24649.05}]}
{"op":"mcm","clk":"1006281847","pt":1580594877439,"mc":[{"id":"1.168175448","rc":[{"batl":[[2,3.7,282.32]],"ltp":3.4,"tv":2925.5,"id":5071877},{"batb":[[1,1.38,12.6],[2,1.37,459.9]],"batl":[[1,1.42,125.81],[2,1.43,12.6]],"ltp":1.41,"tv":21723.55,"id":6374165}]}]}
{"op":"mcm","clk":"1006281985","pt":1580594878421,"mc":[{"id":"1.168175448","rc":[{"batb":[[0,3.15,173.49],[1,2.88,39.86],[2,1.64,81.37]],"batl":[[0,3.7,14.56],[1,1000,0.02],[2,3.7,0]],"ltp":3.4,"tv":2925.5,"id":5071877},{"batb":[[2,1.35,500.37]],"batl":[[0,1.41,306.8]],"ltp":1.41,"tv":21723.55,"id":6374165}]}]}
{"op":"mcm","clk":"1006282216","pt":1580594880347,"mc":[{"id":"1.168175448","rc":[{"batb":[[0,3.25,2.77],[1,3.15,176.52],[2,2.88,39.86]],"batl":[[1,3.95,2.1],[2,1000,0.02]],"ltp":3.4,"tv":2925.5,"id":5071877}]}]}
{"op":"mcm","clk":"1006282313","pt":1580594881133,"mc":[{"id":"1.168175448","rc":[{"batb":[[1,3.15,3.03],[2,3.05,181.99]],"ltp":3.4,"tv":2925.5,"id":5071877}]}]}
{"op":"mcm","clk":"1006282807","pt":1580594885156,"mc":[{"id":"1.168175448","rc":[{"batb":[[0,1.4,10.34]],"ltp":1.41,"tv":21723.55,"id":6374165}]}]}
{"op":"mcm","clk":"1006282986","pt":1580594886560,"mc":[{"id":"1.168175448","rc":[{"batb":[[2,1.35,30.88]],"batl":[[1,1.42,37.81],[2,1.44,42.83]],"ltp":1.41,"tv":21723.55,"id":6374165}]}]}
{"op":"mcm","clk":"1006283049","pt":1580594887036,"mc":[{"id":"1.168175448","rc":[{"batl":[[0,1.41,140.31],[1,1.44,42.83],[2,1.45,12.6]],"ltp":1.41,"tv":21723.55,"id":6374165}]}]}
{"op":"mcm","clk":"1006283342","pt":1580594889365,"mc":[{"id":"1.168175448","rc":[{"trd":[[3.4,837.25]],"batb":[[0,3.2,6.06],[1,3.15,22.35]],"batl":[[0,3.3,34.28],[1,3.35,271.19],[2,3.4,13]],"ltp":3.4,"tv":2983.69,"id":5071877},{"trd":[[1.41,314.15]],"batb":[[0,1.43,700.9],[1,1.42,758.9],[2,1.41,12.6]],"batl":[[0,1.45,12.6],[1,1.46,38.27],[2,1.47,883.06]],"ltp":1.41,"tv":21863.86,"id":6374165}],"tv":24847.55}]}
{"op":"mcm","clk":"1006283471","pt":1580594890568,"mc":[{"id":"1.168175448","rc":[{"batl":[[2,3.4,14.32]],"ltp":3.4,"tv":2983.69,"id":5071877},{"batb":[[0,1.44,389.79],[1,1.43,700.9],[2,1.42,758.9]],"ltp":1.41,"tv":21863.86,"id":6374165}]}]}
{"op":"mcm","clk":"1006284018","pt":1580594895257,"mc":[{"id":"1.168175448","rc":[{"batl":[[0,1.45,89.56],[1,1.46,50.87]],"ltp":1.41,"tv":21863.86,"id":6374165}]}]}
{"op":"mcm","clk":"1006284181","pt":1580594896231,"mc":[{"id":"1.168175448","rc":[{"batb":[[2,3.1,2.74]],"ltp":3.4,"tv":2983.69,"id":5071877},{"batl":[[2,1.47,918.56]],"ltp":1.41,"tv":21863.86,"id":6374165}]}]}
{"op":"mcm","clk":"1006284403","pt":1580594898168,"mc":[{"id":"1.168175448","rc":[{"batl":[[2,3.4,13]],"ltp":3.4,"tv":2983.69,"id":5071877},{"batl":[[0,1.45,92.56]],"ltp":1.41,"tv":21863.86,"id":6374165}]}]}
{"op":"mcm","clk":"1006284767","pt":1580594901341,"mc":[{"id":"1.168175448","rc":[{"trd":[[1.45,83.74]],"batl":[[0,1.45,91.38]],"ltp":1.45,"tv":21866.23,"id":6374165}],"tv":24849.92}]}
{"op":"mcm","clk":"1006284869","pt":1580594902484,"mc":[{"id":"1.168175448","rc":[{"trd":[[1.45,146.02]],"batl":[[0,1.45,60.24]],"ltp":1.45,"tv":21928.51,"id":6374165}],"tv":24912.2}]}
{"op":"mcm","clk":"1006285203","pt":1580594905564,"mc":[{"id":"1.168175448","rc":[{"trd":[[1.44,208.37]],"batb":[[0,1.44,285.6]],"ltp":1.44,"tv":22136.88,"id":6374165}],"tv":25120.57}]}
{"op":"mcm","clk":"1006285324","pt":1580594906553,"mc":[{"id":"1.168175448","rc":[{"batb":[[0,3.15,19.32],[1,3.1,2.74],[2,3.05,185.08]],"batl":[[0,3.5,2.23],[1,3.65,17.42],[2,3.7,14.56]],"ltp":3.4,"tv":2983.69,"id":5071877},{"batl":[[1,1.46,13.12],[2,1.47,877.56]],"ltp":1.44,"tv":22136.88,"id":6374165}]}]}
{"op":"mcm","clk":"1006285381","pt":1580594907067,"mc":[{"id":"1.168175448","rc":[{"batb":[[1,3.05,3.09],[2,2.92,208.03]],"ltp":3.4,"tv":2983.69,"id":5071877},{"batb":[[0,1.43,12.6],[1,1.42,100.6],[2,1.41,13.05]],"batl":[[2,1.47,54.61]],"ltp":1.44,"tv":22136.88,"id":6374165}]}]}
{"op":"mcm","clk":"1006285530","pt":1580594908477,"mc":[{"id":"1.168175448","rc":[{"batb":[[0,3.05,3.09],[1,2.92,208.03],[2,2.88,39.86]],"batl":[[0,3.65,2.3],[1,3.7,14.56],[2,3.95,2.1]],"ltp":3.4,"tv":2983.69,"id":5071877},{"batb":[[1,1.42,12.6]],"batl":[[2,1.47,12.6]],"ltp":1.44,"tv":22136.88,"id":6374165}]}]}
{"op":"mcm","clk":"1006285755","pt":1580594910397,"mc":[{"id":"1.168175448","rc":[{"trd":[[1.45,146.91]],"batl":[[0,1.45,59.8]],"ltp":1.45,"tv":22137.77,"id":6374165}],"tv":25121.47}]}
{"op":"mcm","clk":"1006285890","pt":1580594911494,"mc":[{"id":"1.168175448","rc":[{"batb":[[0,3.25,9.81],[1,3.05,3.09],[2,2.92,208.03]],"batl":[[0,3.3,10.35],[1,3.65,2.3],[2,3.7,14.56]],"ltp":3.4,"tv":2983.69,"id":5071877},{"batb":[[0,1.43,24.03],[1,1.42,763.86],[2,1.41,693.04]],"batl":[[0,1.45,70.9],[1,1.46,804.48],[2,1.47,569.56]],"ltp":1.45,"tv":22137.77,"id":6374165}]}]}
{"op":"mcm","clk":"1006285927","pt":1580594911762,"mc":[{"id":"1.168175448","rc":[{"batb":[[0,3.05,3.09],[1,2.92,208.03],[2,2.88,39.86]],"batl":[[0,3.5,2.03]],"ltp":3.4,"tv":2983.69,"id":5071877},{"trd":[[1.45,147.9]],"batb":[[0,1.43,12.6]],"batl":[[0,1.45,59.3]],"ltp":1.45,"tv":22138.76,"id":6374165}],"tv":25122.45}]}
{"op":"mcm","clk":"1006286046","pt":1580594912854,"mc":[{"id":"1.168175448","rc":[{"batb":[[0,1.42,763.86],[1,1.41,693.04],[2,1.4,52.25]],"ltp":1.45,"tv":22138.76,"id":6374165}]}]}
{"op":"mcm","clk":"1006286249","pt":1580594914470,"mc":[{"id":"1.168175448","rc":[{"batb":[[0,3.1,2.64],[1,3.05,3.09],[2,2.92,208.03]],"ltp":3.4,"tv":2983.69,"id":5071877},{"batl":[[0,1.44,18.48],[1,1.45,59.3],[2,1.46,804.48]],"ltp":1.45,"tv":22138.76,"id":6374165}]}]}
{"op":"mcm","clk":"1006286775","pt":1580594918500,"mc":[{"id":"1.168175448","rc":[{"batb":[[0,1.42,12.6],[1,1.41,13.05]],"batl":[[2,1.46,13.12]],"ltp":1.45,"tv":22138.76,"id":6374165}]}]}
{"op":"mcm","clk":"1006286800","pt":1580594918664,"mc":[{"id":"1.168175448","rc":[{"batb":[[0,3.05,3.09],[1,2.92,208.03],[2,2.88,39.86]],"batl":[[0,3.65,2.3],[1,3.7,14.56],[2,3.95,2.1]],"ltp":3.4,"tv":2983.69,"id":5071877},{"batb":[[2,1.4,10.34]],"ltp":1.45,"tv":22138.76,"id":6374165}]}]}
{"op":"mcm","clk":"1006287314","pt":1580594923394,"mc":[{"id":"1.168175448","rc":[{"batb":[[0,1.41,13.05],[1,1.4,10.34],[2,1.38,1644.67]],"ltp":1.45,"tv":22138.76,"id":6374165}]}]}
{"op":"mcm","clk":"1006287345","pt":1580594923706,"mc":[{"id":"1.168175448","rc":[{"batb":[[0,1.4,10.79],[1,1.38,1644.67],[2,1.37,781.07]],"ltp":1.45,"tv":22138.76,"id":6374165}]}]}
{"op":"mcm","clk":"1006287597","pt":1580594926194,"mc":[{"id":"1.168175448","rc":[{"batb":[[0,3.35,317.77],[1,3.05,3.09],[2,2.92,208.03]],"batl":[[0,3.6,21],[1,3.65,2.3],[2,3.7,291.1]],"ltp":3.4,"tv":2983.69,"id":5071877},{"trd":[[1.4,213.92],[1.41,315.04]],"batb":[[0,1.38,4919.85],[1,1.37,781.07],[2,1.35,30.88]],"batl":[[0,1.41,3191.49],[1,1.42,911.99],[2,1.43,683.02]],"ltp":1.4,"tv":22156.28,"id":6374165}],"tv":25139.97}]}
{"op":"mcm","clk":"1006287747","pt":1580594927386,"mc":[{"id":"1.168175448","rc":[{"batb":[[0,3.35,482.16],[1,3.1,177.19],[2,3.05,3.09]],"ltp":3.4,"tv":2983.69,"id":5071877},{"batl":[[1,1.42,954]],"ltp":1.4,"tv":22156.28,"id":6374165}]}]}
{"op":"mcm","clk":"1006287962","pt":1580594929322,"mc":[{"id":"1.168175448","rc":[{"trd":[[1.41,315.48]],"batl":[[0,1.41,3191.27]],"ltp":1.41,"tv":22156.72,"id":6374165}],"tv":25140.41}]}
{"op":"mcm","clk":"1006288111","pt":1580594930415,"mc":[{"id":"1.168175448","rc":[{"trd":[[1.4,214.76]],"batb":[[0,1.38,4919.43]],"batl":[[0,1.4,53.14],[1,1.41,3191.27],[2,1.42,954]],"ltp":1.4,"tv":22157.56,"id":6374165}],"tv":25141.25}]}
{"op":"mcm","clk":"1006288188","pt":1580594931091,"mc":[{"id":"1.168175448","rc":[{"batl":[[0,1.4,65.75]],"ltp":1.4,"tv":22157.56,"id":6374165}]}]}
{"op":"mcm","clk":"1006288387","pt":1580594933218,"mc":[{"id":"1.168175448","rc":[{"batb":[[1,3.25,2.61],[2,3.15,2.43]],"ltp":3.4,"tv":2983.69,"id":5071877}]}]}
{"op":"mcm","clk":"1006288589","pt":1580594934990,"mc":[{"id":"1.168175448","rc":[{"batl":[[1,1.41,3203.87]],"ltp":1.4,"tv":22157.56,"id":6374165}]}]}
{"op":"mcm","clk":"1006288680","pt":1580594936024,"mc":[{"id":"1.168175448","rc":[{"batb":[[0,1.38,4905.54]],"ltp":1.4,"tv":22157.56,"id":6374165}]}]}
{"op":"mcm","clk":"1006288810","pt":1580594937129,"mc":[{"id":"1.168175448","rc":[{"batb":[[2,1.35,30]],"ltp":1.4,"tv":22157.56,"id":6374165}]}]}
{"op":"mcm","clk":"1006288995","pt":1580594938905,"mc":[{"id":"1.168175448","rc":[{"batl":[[0,3.6,26.76]],"ltp":3.4,"tv":2983.69,"id":5071877},{"batl":[[1,1.41,3226.37]],"ltp":1.4,"tv":22157.56,"id":6374165}]}]}
{"op":"mcm","clk":"1006289254","pt":1580594941511,"mc":[{"id":"1.168175448","rc":[{"batb":[[0,3.35,17.64]],"batl":[[0,3.7,14.56],[1,3.9,14.28],[2,4.1,2.05]],"ltp":3.4,"tv":2983.69,"id":5071877},{"batb":[[0,1.38,12.6],[1,1.35,30],[2,1.34,123.51]],"batl":[[1,1.41,12.6],[2,1.42,155.22]],"ltp":1.4,"tv":22157.56,"id":6374165}]}]}
{"op":"mcm","clk":"1006289346","pt":1580594942395,"mc":[{"id":"1.168175448","rc":[{"batb":[[0,3.25,2.61],[1,3.15,2.43],[2,3.1,177.19]],"batl":[[1,4.1,2.05],[2,4.3,2.05]],"ltp":3.4,"tv":2983.69,"id":5071877},{"trd":[[1.4,216.84]],"batb":[[2,1.33,598.38]],"batl":[[0,1.4,64.7],[2,1.42,113.21]],"ltp":1.4,"tv":22159.64,"id":6374165}],"tv":25143.33}]}
{"op":"mcm","clk":"1006289559","pt":1580594944310,"mc":[{"id":"1.168175448","rc":[{"batb":[[2,1.33,1534.81]],"ltp":1.4,"tv":22159.64,"id":6374165}]}]}
{"op":"mcm","clk":"1006290119","pt":1580594949834,"mc":[{"id":"1.168175448","rc":[{"trd":[[1.4,218.6]],"batl":[[0,1.4,63.83]],"ltp":1.4,"tv":22161.39,"id":6374165}],"tv":25145.09}]}
{"op":"mcm","clk":"1006290311","pt":1580594951449,"mc":[{"id":"1.168175448","rc":[{"batb":[[0,3.15,2.43],[1,3.1,177.19],[2,3.05,3.09]],"ltp":3.4,"tv":2983.69,"id":5071877},{"batb":[[2,1.33,598.38]],"batl":[[0,1.42,88],[1,1.44,43.69],[2,1.45,59.3]],"ltp":1.4,"tv":22161.39,"id":6374165}]}]}
{"op":"mcm","clk":"1006290547","pt":1580594953530,"mc":[{"id":"1.168175448","rc":[{"trd":[[3.35,37.3]],"batb":[[0,3.2,6.4],[1,3.15,2.43],[2,3.1,500.69]],"batl":[[0,3.3,24.88],[1,3.35,13],[2,3.45,25]],"ltp":3.35,"tv":3020.99,"id":5071877},{"trd":[[1.42,182]],"batb":[[0,1.42,3169.01],[1,1.41,88],[2,1.38,2428.62]],"batl":[[0,1.44,43.69],[1,1.45,59.3],[2,1.46,3540.83]],"ltp":1.42,"tv":22249.39,"id":6374165}],"tv":25270.39}]}
{"op":"mcm","clk":"1006290620","pt":1580594954258,"mc":[{"id":"1.168175448","rc":[{"batb":[[0,1.43,503.11],[1,1.42,4236.21],[2,1.41,100.6]],"ltp":1.42,"tv":22249.39,"id":6374165}]}]}
{"op":"mcm","clk":"1006290778","pt":1580594955518,"mc":[{"id":"1.168175448","rc":[{"batb":[[1,3.15,21.75]],"ltp":3.35,"tv":3020.99,"id":5071877},{"batl":[[2,1.46,3582.84]],"ltp":1.42,"tv":22249.39,"id":6374165}]}]}
{"op":"mcm","clk":"1006291003","pt":1580594957348,"mc":[{"id":"1.168175448","rc":[{"trd":[[1.43,264.75]],"batb":[[0,1.43,502.62]],"ltp":1.43,"tv":22250.37,"id":6374165}],"tv":25271.37}]}
{"op":"mcm","clk":"1006291165","pt":1580594958760,"mc":[{"id":"1.168175448","rc":[{"trd":[[1.43,269.75]],"batb":[[0,1.43,500.12]],"ltp":1.43,"tv":22255.37,"id":6374165}],"tv":25276.37}]}
{"op":"mcm","clk":"1006291419","pt":1580594960952,"mc":[{"id":"1.168175448","rc":[{"batb":[[2,3.1,503.43]],"ltp":3.35,"tv":3020.99,"id":5071877}]}]}
{"op":"mcm","clk":"1006292525","pt":1580594970446,"mc":[{"id":"1.168175448","rc":[{"batb":[[0,3.15,21.75],[1,3.1,179.93],[2,3.05,3.09]],"batl":[[0,3.6,2.21],[1,3.7,29.68],[2,3.75,2.1]],"ltp":3.35,"tv":3020.99,"id":5071877}]}]}
{"op":"mcm","clk":"1006292622","pt":1580594971170,"mc":[{"id":"1.168175448","rc":[{"batb":[[0,3.15,19.32],[1,3,2.84],[2,2.92,84.27]],"ltp":3.35,"tv":3020.99,"id":5071877},{"batb":[[0,1.42,12.6],[1,1.41,100.6],[2,1.4,12.6]],"batl":[[2,1.46,55.13]],"ltp":1.43,"tv":22255.37,"id":6374165}]}]}
{"op":"mcm","clk":"1006292798","pt":1580594972534,"mc":[{"id":"1.168175448","rc":[{"trd":[[3.25,0.31]],"batb":[[0,3,2.84],[1,2.92,84.27],[2,2.88,39.86]],"batl":[[1,3.7,14.56]],"ltp":3.25,"tv":3021.3,"id":5071877},{"trd":[[1.44,209.07]],"batl":[[0,1.44,42.99],[2,1.46,13.12]],"ltp":1.44,"tv":22256.07,"id":6374165}],"tv":25277.37}]}
{"op":"mcm","clk":"1006293144","pt":1580594975560,"mc":[{"id":"1.168175448","rc":[{"trd":[[1.44,210.11]],"batl":[[0,1.44,42.47],[1,1.45,3],[2,1.48,13.12]],"ltp":1.44,"tv":22257.11,"id":6374165}],"tv":25278.42}]}
{"op":"mcm","clk":"1006293220","pt":1580594976187,"mc":[{"id":"1.168175448","rc":[{"batl":[[0,1.45,3],[1,1.48,13.12],[2,1.49,50.51]],"ltp":1.44,"tv":22257.11,"id":6374165}]}]}
{"op":"mcm","clk":"1006293379","pt":1580594977452,"mc":[{"id":"1.168175448","rc":[{"trd":[[3.2,3.63]],"batb":[[0,3.1,2.94],[1,3,2.84],[2,2.92,84.27]],"batl":[[0,3.15,2607],[1,3.2,2015.44],[2,3.45,4.45]],"ltp":3.2,"tv":3022.66,"id":5071877},{"trd":[[1.45,150.9],[1.46,385.53],[1.47,889.01],[1.48,2333.04]],"batb":[[0,1.47,3026.2],[1,1.46,715.99],[2,1.42,12.6]],"batl":[[0,1.48,1.09],[1,1.49,50.51],[2,1.5,5903.07]],"ltp":1.48,"tv":22353.17,"id":6374165}],"tv":25375.84}]}
{"op":"mcm","clk":"1006293468","pt":1580594978375,"mc":[{"id":"1.168175448","rc":[{"trd":[[3.1,125.15]],"batb":[[0,3,2.84],[1,2.92,84.27],[2,2.88,491.94]],"batl":[[0,3.1,26.06],[1,3.15,15],[2,3.2,15]],"ltp":3.1,"tv":3028.54,"id":5071877},{"batb":[[0,1.47,3373.58],[1,1.46,1692.25],[2,1.45,703.76]],"ltp":1.48,"tv":22353.17,"id":6374165}],"tv":25381.72}]}
{"op":"mcm","clk":"1006293592","pt":1580594979376,"mc":[{"id":"1.168175448","rc":[{"batb":[[0,3,23.84]],"ltp":3.1,"tv":3028.54,"id":5071877},{"batl":[[2,1.5,5945.08]],"ltp":1.48,"tv":22353.17,"id":6374165}]}]}
{"op":"mcm","clk":"1006294229","pt":1580594984561,"mc":[{"id":"1.168175448","rc":[{"batl":[[0,1.48,13.7],[2,1.5,5982.63]],"ltp":1.48,"tv":22353.17,"id":6374165}]}]}
{"op":"mcm","clk":"1006294344","pt":1580594985557,"mc":[{"id":"1.168175448","rc":[{"batl":[[1,1.49,63.11]],"ltp":1.48,"tv":22353.17,"id":6374165}]}]}
{"op":"mcm","clk":"1006294430","pt":1580594986388,"mc":[{"id":"1.168175448","rc":[{"trd":[[3,894.96],[3.05,28.21]],"batb":[[0,2.92,85.23],[1,2.88,491.94],[2,2.8,93.79]],"ltp":3.0,"tv":3080.96,"id":5071877},{"trd":[[1.48,2346.73]],"batb":[[0,1.47,3386.18],[1,1.46,1704.86]],"batl":[[0,1.49,63.11],[1,1.5,5982.63],[2,1.51,3836.42]],"ltp":1.48,"tv":22366.87,"id":6374165}],"tv":25447.83}]}
{"op":"mcm","clk":"1006294609","pt":1580594987690,"mc":[{"id":"1.168175448","rc":[{"batl":[[1,1.5,5977.09]],"ltp":1.48,"tv":22366.87,"id":6374165}]}]}
{"op":"mcm","clk":"1006294826","pt":1580594989676,"mc":[{"id":"1.168175448","rc":[{"batb":[[0,3,23.48],[1,2.92,84.27],[2,2.88,491.94]],"ltp":3.0,"tv":3080.96,"id":5071877},{"batl":[[0,1.49,110.43]],"ltp":1.48,"tv":22366.87,"id":6374165}]}]}
{"op":"mcm","clk":"1006294955","pt":1580594990874,"mc":[{"id":"1.168175448","rc":[{"batb":[[0,3,29.09],[1,2.96,2.88],[2,2.92,84.27]],"ltp":3.0,"tv":3080.96,"id":5071877},{"batb":[[0,1.47,3398.11]],"batl":[[1,1.5,5988.31],[2,1.51,3869.92]],"ltp":1.48,"tv":22366.87,"id":6374165}]}]}
{"op":"mcm","clk":"1006295112","pt":1580594992474,"mc":[{"id":"1.168175448","rc":[{"batb":[[0,3,23.48]],"batl":[[0,3.3,3.65],[1,3.35,17.64],[2,3.4,3.44]],"ltp":3.0,"tv":3080.96,"id":5071877},{"batb":[[0,1.47,3386.18],[1,1.46,988.87]],"batl":[[0,1.49,73.93],[1,1.5,5977.09]],"ltp":1.48,"tv":22366.87,"id":6374165}]}]}
{"op":"mcm","clk":"1006295125","pt":1580594992579,"mc":[{"id":"1.168175448","rc":[{"batb":[[2,2.88,39.86]],"ltp":3.0,"tv":3080.96,"id":5071877},{"batb":[[0,1.47,12.6],[1,1.46,25.21],[2,1.45,100.6]],"batl":[[2,1.51,33.5]],"ltp":1.48,"tv":22366.87,"id":6374165}]}]}
{"op":"mcm","clk":"1006295330","pt":1580594994458,"mc":[{"id":"1.168175448","rc":[{"batb":[[0,3,3.2]],"batl":[[1,3.4,3.44],[2,3.6,2.21]],"ltp":3.0,"tv":3080.96,"id":5071877},{"batl":[[1,1.5,5935.08]],"ltp":1.48,"tv":22366.87,"id":6374165}]}]}
{"op":"mcm","clk":"1006295427","pt":1580594995507,"mc":[{"id":"1.168175448","rc":[{"batl":[[0,1.49,72.53]],"ltp":1.48,"tv":22366.87,"id":6374165}]}]}
{"op":"mcm","clk":"1006295621","pt":1580594997180,"mc":[{"id":"1.168175448","rc":[{"batb":[[1,1.46,564.55],[2,1.45,700.49]],"batl":[[0,1.48,25.21],[1,1.49,72.53],[2,1.5,6691.78]],"ltp":1.48,"tv":22366.87,"id":6374165}]}]}
{"op":"mcm","clk":"1006296193","pt":1580595002202,"mc":[{"id":"1.168175448","rc":[{"trd":[[1.48,2397.15],[1.49,1255.43]],"batb":[[0,1.49,102.27],[1,1.47,12.6],[2,1.46,564.55]],"batl":[[0,1.5,6691.78],[1,1.51,533.91],[2,1.54,239.46]],"ltp":1.49,"tv":22562.33,"id":6374165}],"tv":25643.29}]}
{"op":"mcm","clk":"1006296369","pt":1580595003904,"mc":[{"id":"1.168175448","rc":[{"batb":[[2,1.46,25.21]],"batl":[[0,1.5,5935.08],[1,1.51,33.5]],"ltp":1.49,"tv":22562.33,"id":6374165}]}]}
{"op":"mcm","clk":"1006296484","pt":1580595005127,"mc":[{"id":"1.168175448","rc":[{"trd":[[1.49,1453.57]],"batb":[[0,1.49,3.2]],"ltp":1.49,"tv":22760.47,"id":6374165}],"tv":25841.43}]}
{"op":"mcm","clk":"1006296605","pt":1580595006105,"mc":[{"id":"1.168175448","rc":[{"trd":[[1.46,429.65],[1.47,914.21],[1.49,1459.97]],"batb":[[0,1.46,3.14],[1,1.45,100.6],[2,1.44,56.02]],"ltp":1.46,"tv":22836.2,"id":6374165}],"tv":25917.16}]}
{"op":"mcm","clk":"1006296749","pt":1580595007510,"mc":[{"id":"1.168175448","rc":[{"batl":[[0,1.49,12.6],[1,1.5,5935.08],[2,1.51,33.5]],"ltp":1.46,"tv":22836.2,"id":6374165}]}]}
{"op":"mcm","clk":"1006296820","pt":1580595008091,"mc":[{"id":"1.168175448","rc":[{"batl":[[0,1.49,25.21]],"ltp":1.46,"tv":22836.2,"id":6374165}]}]}
