{"op":"mcm","clk":"995732875","pt":1580515645283,"mc":[{"id":"1.168175453","marketDefinition":{"bspMarket":false,"turnInPlayEnabled":true,"persistenceEnabled":true,"marketBaseRate":5.0,"eventId":"29680072","eventTypeId":"2","numberOfWinners":1,"bettingType":"ODDS","marketType":"SET_WINNER","marketTime":"2020-02-02T13:00:00.000Z","suspendTime":"2020-02-02T13:00:00.000Z","bspReconciled":false,"complete":true,"inPlay":false,"crossMatching":false,"runnersVoidable":false,"numberOfActiveRunners":2,"betDelay":0,"status":"OPEN","runners":[{"status":"ACTIVE","sortPriority":1,"id":6374165,"name":"Marco Cecchinato"},{"status":"ACTIVE","sortPriority":2,"id":5071877,"name":"Andrej Martin"}],"regulators":["MR_INT"],"countryCode":"UY","discountAllowed":false,"timezone":"UTC","openDate":"2020-02-02T13:00:00.000Z","version":3144186607,"name":"Set 1 Winner","eventName":"Cecchinato v Martin"},"rc":[{"batb":[[0,1.01,20]],"ltp":0.0,"tv":0.0,"id":5071877},{"batb":[[0,1.01,20]],"ltp":0.0,"tv":0.0,"id":6374165}]}]}
{"op":"mcm","clk":"995733031","pt":1580515646599,"mc":[{"id":"1.168175453","marketDefinition":{"bspMarket":false,"turnInPlayEnabled":true,"persistenceEnabled":true,"marketBaseRate":5.0,"eventId":"29680072","eventTypeId":"2","numberOfWinners":1,"bettingType":"ODDS","marketType":"SET_WINNER","marketTime":"2020-02-02T13:00:00.000Z","suspendTime":"2020-02-02T13:00:00.000Z","bspReconciled":false,"complete":true,"inPlay":false,"crossMatching":false,"runnersVoidable":false,"numberOfActiveRunners":2,"betDelay":0,"status":"OPEN","runners":[{"status":"ACTIVE","sortPriority":1,"id":6374165,"name":"Marco Cecchinato"},{"status":"ACTIVE","sortPriority":2,"id":5071877,"name":"Andrej Martin"}],"regulators":["MR_INT"],"countryCode":"UY","discountAllowed":false,"timezone":"UTC","openDate":"2020-02-02T13:00:00.000Z","version":3144186607,"name":"Set 1 Winner","eventName":"Cecchinato v Martin"}}]}
{"op":"mcm","clk":"995733303","pt":1580515649573,"mc":[{"id":"1.168175453","marketDefinition":{"bspMarket":false,"turnInPlayEnabled":true,"persistenceEnabled":true,"marketBaseRate":5.0,"eventId":"29680072","eventTypeId":"2","numberOfWinners":1,"bettingType":"ODDS","marketType":"SET_WINNER","marketTime":"2020-02-02T13:00:00.000Z","suspendTime":"2020-02-02T13:00:00.000Z","bspReconciled":false,"complete":true,"inPlay":false,"crossMatching":false,"runnersVoidable":false,"numberOfActiveRunners":2,"betDelay":0,"status":"OPEN","runners":[{"status":"ACTIVE","sortPriority":1,"id":6374165,"name":"Marco Cecchinato"},{"status":"ACTIVE","sortPriority":2,"id":5071877,"name":"Andrej Martin"}],"regulators":["MR_INT"],"countryCode":"UY","discountAllowed":true,"timezone":"UTC","openDate":"2020-02-02T13:00:00.000Z","version":3144186607,"name":"Set 1 Winner","eventName":"Cecchinato v Martin"}}]}
{"op":"mcm","clk":"995782415","pt":1580516116457,"mc":[{"id":"1.168175453","rc":[{"batb":[[0,1.01,15]],"ltp":0.0,"tv":0.0,"id":5071877},{"batb":[[0,1.01,15]],"ltp":0.0,"tv":0.0,"id":6374165}]}]}
{"op":"mcm","clk":"995889896","pt":1580517337345,"mc":[{"id":"1.168175453","marketDefinition":{"bspMarket":false,"turnInPlayEnabled":true,"persistenceEnabled":true,"marketBaseRate":5.0,"eventId":"29680072","eventTypeId":"2","numberOfWinners":1,"bettingType":"ODDS","marketType":"SET_WINNER","marketTime":"2020-02-01T22:00:00.000Z","suspendTime":"2020-02-01T22:00:00.000Z","bspReconciled":false,"complete":true,"inPlay":false,"crossMatching":false,"runnersVoidable":false,"numberOfActiveRunners":2,"betDelay":0,"status":"OPEN","runners":[{"status":"ACTIVE","sortPriority":1,"id":6374165,"name":"Marco Cecchinato"},{"status":"ACTIVE","sortPriority":2,"id":5071877,"name":"Andrej Martin"}],"regulators":["MR_INT"],"countryCode":"UY","discountAllowed":true,"timezone":"UTC","openDate":"2020-02-02T13:00:00.000Z","version":3144220325,"name":"Set 1 Winner","eventName":"Cecchinato v Martin"}}]}
{"op":"mcm","clk":"995890182","pt":1580517341374,"mc":[{"id":"1.168175453","marketDefinition":{"bspMarket":false,"turnInPlayEnabled":true,"persistenceEnabled":true,"marketBaseRate":5.0,"eventId":"29680072","eventTypeId":"2","numberOfWinners":1,"bettingType":"ODDS","marketType":"SET_WINNER","marketTime":"2020-02-01T22:00:00.000Z","suspendTime":"2020-02-01T22:00:00.000Z","bspReconciled":false,"complete":true,"inPlay":false,"crossMatching":false,"runnersVoidable":false,"numberOfActiveRunners":2,"betDelay":0,"status":"OPEN","runners":[{"status":"ACTIVE","sortPriority":1,"id":6374165,"name":"Marco Cecchinato"},{"status":"ACTIVE","sortPriority":2,"id":5071877,"name":"Andrej Martin"}],"regulators":["MR_INT"],"countryCode":"UY","discountAllowed":true,"timezone":"UTC","openDate":"2020-02-01T22:00:00.000Z","version":3144220325,"name":"Set 1 Winner","eventName":"Cecchinato v Martin"}}]}
{"op":"mcm","clk":"996349913","pt":1580523360497,"mc":[{"id":"1.168175453","rc":[{"batb":[[0,1.01,17.53]],"ltp":0.0,"tv":0.0,"id":5071877},{"batb":[[0,1.01,17.53]],"ltp":0.0,"tv":0.0,"id":6374165}]}]}
{"op":"mcm","clk":"996349990","pt":1580523361476,"mc":[{"id":"1.168175453","rc":[{"batb":[[0,1.01,15.51]],"ltp":0.0,"tv":0.0,"id":5071877},{"batb":[[0,1.01,15.51]],"ltp":0.0,"tv":0.0,"id":6374165}]}]}
{"op":"mcm","clk":"996362469","pt":1580523563440,"mc":[{"id":"1.168175453","rc":[{"batb":[[0,1.01,16.01]],"ltp":0.0,"tv":0.0,"id":5071877},{"batb":[[0,1.01,16.01]],"ltp":0.0,"tv":0.0,"id":6374165}]}]}
{"op":"mcm","clk":"997117629","pt":1580535296012,"mc":[{"id":"1.168175453","rc":[{"batb":[[0,2.5,18.11],[1,1.01,16.01]],"ltp":0.0,"tv":0.0,"id":5071877},{"batb":[[0,1.5,54.35],[1,1.01,16.01]],"ltp":0.0,"tv":0.0,"id":6374165}]}]}
{"op":"mcm","clk":"997118124","pt":1580535307442,"mc":[{"id":"1.168175453","marketDefinition":{"bspMarket":false,"turnInPlayEnabled":true,"persistenceEnabled":true,"marketBaseRate":5.0,"eventId":"29680072","eventTypeId":"2","numberOfWinners":1,"bettingType":"ODDS","marketType":"SET_WINNER","marketTime":"2020-02-01T22:00:00.000Z","suspendTime":"2020-02-01T22:00:00.000Z","bspReconciled":false,"complete":true,"inPlay":false,"crossMatching":true,"runnersVoidable":false,"numberOfActiveRunners":2,"betDelay":0,"status":"OPEN","runners":[{"status":"ACTIVE","sortPriority":1,"id":6374165,"name":"Marco Cecchinato"},{"status":"ACTIVE","sortPriority":2,"id":5071877,"name":"Andrej Martin"}],"regulators":["MR_INT"],"countryCode":"UY","discountAllowed":true,"timezone":"UTC","openDate":"2020-02-01T22:00:00.000Z","version":3144220325,"name":"Set 1 Winner","eventName":"Cecchinato v Martin"}}]}
{"op":"mcm","clk":"997159037","pt":1580536091125,"mc":[{"id":"1.168175453","rc":[{"batb":[[0,2.62,16.77]],"ltp":0.0,"tv":0.0,"id":5071877},{"batb":[[0,1.44,61.77]],"ltp":0.0,"tv":0.0,"id":6374165}]}]}
{"op":"mcm","clk":"997161764","pt":1580536151492,"mc":[{"id":"1.168175453","rc":[{"batb":[[0,2.5,18.11]],"ltp":0.0,"tv":0.0,"id":5071877},{"batb":[[0,1.5,54.35]],"ltp":0.0,"tv":0.0,"id":6374165}]}]}
{"op":"mcm","clk":"997216442","pt":1580536971334,"mc":[{"id":"1.168175453","rc":[{"batb":[[0,2.38,19.69]],"ltp":0.0,"tv":0.0,"id":5071877},{"batb":[[0,1.53,51.28]],"ltp":0.0,"tv":0.0,"id":6374165}]}]}
{"op":"mcm","clk":"997217629","pt":1580536996374,"mc":[{"id":"1.168175453","rc":[{"batb":[[0,2.2,22.64]],"ltp":0.0,"tv":0.0,"id":5071877},{"batb":[[0,1.62,43.83]],"ltp":0.0,"tv":0.0,"id":6374165}]}]}
{"op":"mcm","clk":"997220241","pt":1580537056734,"mc":[{"id":"1.168175453","rc":[{"batb":[[0,2.24,21.91]],"ltp":0.0,"tv":0.0,"id":5071877},{"batb":[[0,1.57,47.68]],"ltp":0.0,"tv":0.0,"id":6374165}]}]}
{"op":"mcm","clk":"997255792","pt":1580537701214,"mc":[{"id":"1.168175453","rc":[{"batb":[[0,2.26,20.98],[1,2.24,21.91],[2,1.01,16.01]],"ltp":0.0,"tv":0.0,"id":5071877}]}]}
{"op":"mcm","clk":"997328703","pt":1580539178524,"mc":[{"id":"1.168175453","rc":[{"batb":[[0,1.58,33.06],[1,1.57,47.68],[2,1.01,16.01]],"ltp":0.0,"tv":0.0,"id":6374165}]}]}
{"op":"mcm","clk":"997449866","pt":1580541283530,"mc":[{"id":"1.168175453","rc":[{"batb":[[2,2.2,22.64]],"ltp":0.0,"tv":0.0,"id":5071877},{"batb":[[0,1.62,43.83],[1,1.58,33.06],[2,1.57,47.68]],"ltp":0.0,"tv":0.0,"id":6374165}]}]}
{"op":"mcm","clk":"997449874","pt":1580541283840,"mc":[{"id":"1.168175453","rc":[{"batb":[[1,2.2,22.64],[2,1.01,16.01]],"ltp":0.0,"tv":0.0,"id":5071877},{"batb":[[1,1.01,16.01],[2,1.57,0]],"ltp":0.0,"tv":0.0,"id":6374165}]}]}
{"op":"mcm","clk":"997450643","pt":1580541301220,"mc":[{"id":"1.168175453","rc":[{"batb":[[0,2.2,22.64],[1,1.01,16.01],[2,1.01,0]],"ltp":0.0,"tv":0.0,"id":5071877}]}]}
{"op":"mcm","clk":"997970647","pt":1580548912103,"mc":[{"id":"1.168175453","rc":[{"batb":[[0,2.22,36.34],[1,2.2,22.64],[2,1.01,16.01]],"ltp":0.0,"tv":0.0,"id":5071877}]}]}
{"op":"mcm","clk":"998223881","pt":1580551444509,"mc":[{"id":"1.168175453","rc":[{"batb":[[0,2.2,22.64],[1,1.01,16.01],[2,1.01,0]],"ltp":0.0,"tv":0.0,"id":5071877}]}]}
{"op":"mcm","clk":"998223902","pt":1580551444671,"mc":[{"id":"1.168175453","rc":[{"batb":[[0,2.22,51.61],[1,2.2,22.64],[2,1.01,16.01]],"ltp":0.0,"tv":0.0,"id":5071877}]}]}
{"op":"mcm","clk":"998392921","pt":1580552512508,"mc":[{"id":"1.168175453","rc":[{"batb":[[0,2.22,51.84]],"ltp":0.0,"tv":0.0,"id":5071877}]}]}
{"op":"mcm","clk":"998994678","pt":1580556112650,"mc":[{"id":"1.168175453","rc":[{"batb":[[0,2.2,22.64],[1,1.01,16.01],[2,1.01,0]],"ltp":0.0,"tv":0.0,"id":5071877}]}]}
{"op":"mcm","clk":"1000015501","pt":1580561327405,"mc":[{"id":"1.168175453","rc":[{"batb":[[0,2.28,51.66],[1,2.2,22.64],[2,1.01,16.01]],"ltp":0.0,"tv":0.0,"id":5071877}]}]}
{"op":"mcm","clk":"1000016049","pt":1580561330211,"mc":[{"id":"1.168175453","rc":[{"batb":[[2,2.1,8.67]],"ltp":0.0,"tv":0.0,"id":5071877},{"batb":[[1,1.49,19.47],[2,1.01,16.01]],"ltp":0.0,"tv":0.0,"id":6374165}]}]}
{"op":"mcm","clk":"1000044309","pt":1580561473519,"mc":[{"id":"1.168175453","rc":[{"batb":[[1,2.24,21.91]],"ltp":0.0,"tv":0.0,"id":5071877},{"batb":[[0,1.57,131.67]],"ltp":0.0,"tv":0.0,"id":6374165}]}]}
{"op":"mcm","clk":"1000211471","pt":1580562289024,"mc":[{"id":"1.168175453","rc":[{"batb":[[0,2.28,77.16]],"ltp":0.0,"tv":0.0,"id":5071877},{"batb":[[0,1.57,173.25]],"ltp":0.0,"tv":0.0,"id":6374165}]}]}
{"op":"mcm","clk":"1000834232","pt":1580564928361,"mc":[{"id":"1.168175453","rc":[{"batb":[[0,2.28,77.41]],"ltp":0.0,"tv":0.0,"id":5071877}]}]}
{"op":"mcm","clk":"1000862737","pt":1580565073507,"mc":[{"id":"1.168175453","rc":[{"batb":[[0,1.57,47.68]],"ltp":0.0,"tv":0.0,"id":6374165}]}]}
{"op":"mcm","clk":"1000862838","pt":1580565073928,"mc":[{"id":"1.168175453","rc":[{"batb":[[0,1.57,173.74]],"ltp":0.0,"tv":0.0,"id":6374165}]}]}
{"op":"mcm","clk":"1001267088","pt":1580566999834,"mc":[{"id":"1.168175453","rc":[{"batb":[[0,1.57,47.68]],"ltp":0.0,"tv":0.0,"id":6374165}]}]}
{"op":"mcm","clk":"1001267658","pt":1580567002303,"mc":[{"id":"1.168175453","rc":[{"batb":[[2,1.01,16.01]],"ltp":0.0,"tv":0.0,"id":5071877},{"batb":[[1,1.01,16.01],[2,1.01,0]],"ltp":0.0,"tv":0.0,"id":6374165}]}]}
{"op":"mcm","clk":"1001267781","pt":1580567002912,"mc":[{"id":"1.168175453","rc":[{"batb":[[2,2.18,12.06]],"ltp":0.0,"tv":0.0,"id":5071877},{"batb":[[1,1.49,29.05],[2,1.01,16.01]],"ltp":0.0,"tv":0.0,"id":6374165}]}]}
{"op":"mcm","clk":"1001404719","pt":1580567698598,"mc":[{"id":"1.168175453","rc":[{"batb":[[0,1.57,173.74]],"ltp":0.0,"tv":0.0,"id":6374165}]}]}
{"op":"mcm","clk":"1001405475","pt":1580567702537,"mc":[{"id":"1.168175453","rc":[{"batb":[[1,1.5,28.47]],"ltp":0.0,"tv":0.0,"id":6374165}]}]}
{"op":"mcm","clk":"1001584240","pt":1580568528325,"mc":[{"id":"1.168175453","rc":[{"batb":[[0,2.24,21.91],[1,2.18,12.06],[2,1.01,16.01]],"ltp":0.0,"tv":0.0,"id":5071877}]}]}
{"op":"mcm","clk":"1001584306","pt":1580568528615,"mc":[{"id":"1.168175453","rc":[{"batb":[[0,2.34,76.51],[1,2.24,21.91],[2,2.18,12.06]],"ltp":0.0,"tv":0.0,"id":5071877}]}]}
{"op":"mcm","clk":"1001992810","pt":1580570282901,"mc":[{"id":"1.168175453","rc":[{"batb":[[0,1.57,47.68]],"ltp":0.0,"tv":0.0,"id":6374165}]}]}
{"op":"mcm","clk":"1001993398","pt":1580570285431,"mc":[{"id":"1.168175453","rc":[{"batb":[[2,1.01,16.01]],"ltp":0.0,"tv":0.0,"id":5071877},{"batb":[[1,1.01,16.01],[2,1.01,0]],"ltp":0.0,"tv":0.0,"id":6374165}]}]}
{"op":"mcm","clk":"1001993545","pt":1580570286034,"mc":[{"id":"1.168175453","rc":[{"batb":[[2,2.2,11.87]],"ltp":0.0,"tv":0.0,"id":5071877},{"batb":[[1,1.48,29.66],[2,1.01,16.01]],"ltp":0.0,"tv":0.0,"id":6374165}]}]}
{"op":"mcm","clk":"1002255201","pt":1580571410883,"mc":[{"id":"1.168175453","rc":[{"batb":[[2,1.01,16.01]],"ltp":0.0,"tv":0.0,"id":5071877},{"batb":[[1,1.01,16.01],[2,1.01,0]],"ltp":0.0,"tv":0.0,"id":6374165}]}]}
{"op":"mcm","clk":"1002255599","pt":1580571412481,"mc":[{"id":"1.168175453","rc":[{"batb":[[2,2.2,11.87]],"ltp":0.0,"tv":0.0,"id":5071877},{"batb":[[1,1.49,29.05],[2,1.01,16.01]],"ltp":0.0,"tv":0.0,"id":6374165}]}]}
{"op":"mcm","clk":"1002422063","pt":1580572128616,"mc":[{"id":"1.168175453","rc":[{"batb":[[0,2.24,21.91],[1,2.2,11.87],[2,1.01,16.01]],"ltp":0.0,"tv":0.0,"id":5071877}]}]}
{"op":"mcm","clk":"1002536729","pt":1580572800435,"mc":[{"id":"1.168175453","rc":[{"batb":[[0,2.24,32.87]],"ltp":0.0,"tv":0.0,"id":5071877},{"batb":[[0,1.57,71.52]],"ltp":0.0,"tv":0.0,"id":6374165}]}]}
{"op":"mcm","clk":"1002537256","pt":1580572802512,"mc":[{"id":"1.168175453","rc":[{"batb":[[0,2.28,79.41],[1,2.24,32.87],[2,2.2,11.87]],"ltp":0.0,"tv":0.0,"id":5071877}]}]}
{"op":"mcm","clk":"1002586725","pt":1580573051237,"mc":[{"id":"1.168175453","rc":[{"batb":[[2,1.01,16.01]],"ltp":0.0,"tv":0.0,"id":5071877},{"batb":[[1,1.01,16.01],[2,1.01,0]],"ltp":0.0,"tv":0.0,"id":6374165}]}]}
{"op":"mcm","clk":"1002586854","pt":1580573051831,"mc":[{"id":"1.168175453","rc":[{"batb":[[2,2.2,11.87]],"ltp":0.0,"tv":0.0,"id":5071877},{"batb":[[1,1.49,29.05],[2,1.01,16.01]],"ltp":0.0,"tv":0.0,"id":6374165}]}]}
{"op":"mcm","clk":"1002597691","pt":1580573099553,"mc":[{"id":"1.168175453","rc":[{"batb":[[0,2.24,32.87],[1,2.2,11.87],[2,1.01,16.01]],"ltp":0.0,"tv":0.0,"id":5071877}]}]}
{"op":"mcm","clk":"1002597734","pt":1580573099768,"mc":[{"id":"1.168175453","rc":[{"batb":[[0,2.28,105.41],[1,2.24,32.87],[2,2.2,11.87]],"ltp":0.0,"tv":0.0,"id":5071877}]}]}
{"op":"mcm","clk":"1003374611","pt":1580576403051,"mc":[{"id":"1.168175453","rc":[{"batb":[[0,2.24,32.87],[1,2.2,11.87],[2,1.01,16.01]],"ltp":0.0,"tv":0.0,"id":5071877}]}]}
{"op":"mcm","clk":"1003374785","pt":1580576403663,"mc":[{"id":"1.168175453","rc":[{"batb":[[0,2.32,104.14],[1,2.24,32.87],[2,2.2,11.87]],"ltp":0.0,"tv":0.0,"id":5071877}]}]}
{"op":"mcm","clk":"1003403777","pt":1580576563275,"mc":[{"id":"1.168175453","rc":[{"batb":[[2,1.01,16.01]],"ltp":0.0,"tv":0.0,"id":5071877},{"batb":[[1,1.01,16.01],[2,1.01,0]],"ltp":0.0,"tv":0.0,"id":6374165}]}]}
{"op":"mcm","clk":"1003403896","pt":1580576563907,"mc":[{"id":"1.168175453","rc":[{"batb":[[2,2.2,15.77]],"ltp":0.0,"tv":0.0,"id":5071877},{"batb":[[1,1.49,38.63],[2,1.01,16.01]],"ltp":0.0,"tv":0.0,"id":6374165}]}]}
{"op":"mcm","clk":"1003630505","pt":1580577765406,"mc":[{"id":"1.168175453","rc":[{"batb":[[1,2.28,14.79],[2,2.24,32.87]],"ltp":0.0,"tv":0.0,"id":5071877},{"batb":[[1,1.46,41.16]],"ltp":0.0,"tv":0.0,"id":6374165}]}]}
{"op":"mcm","clk":"1003631175","pt":1580577769059,"mc":[{"id":"1.168175453","rc":[{"batb":[[1,2.24,32.87],[2,1.01,16.01]],"ltp":0.0,"tv":0.0,"id":5071877},{"batb":[[1,1.01,16.01],[2,1.01,0]],"ltp":0.0,"tv":0.0,"id":6374165}]}]}
{"op":"mcm","clk":"1003631273","pt":1580577769695,"mc":[{"id":"1.168175453","rc":[{"batb":[[1,2.24,48.14]],"ltp":0.0,"tv":0.0,"id":5071877},{"batb":[[1,1.47,40.28],[2,1.01,16.01]],"ltp":0.0,"tv":0.0,"id":6374165}]}]}
{"op":"mcm","clk":"1003647829","pt":1580577851406,"mc":[{"id":"1.168175453","rc":[{"batb":[[0,2.4,102.86],[1,2.38,29.54],[2,2.24,15.27]],"ltp":0.0,"tv":0.0,"id":5071877},{"batb":[[0,1.53,258.08]],"ltp":0.0,"tv":0.0,"id":6374165}]}]}
{"op":"mcm","clk":"1004020549","pt":1580579986796,"mc":[{"id":"1.168175453","rc":[{"batb":[[1,2.38,32.09]],"ltp":0.0,"tv":0.0,"id":5071877},{"batb":[[0,1.53,264.72]],"ltp":0.0,"tv":0.0,"id":6374165}]}]}
{"op":"mcm","clk":"1004023345","pt":1580580004229,"mc":[{"id":"1.168175453","rc":[{"batb":[[0,2.42,102.44]],"ltp":0.0,"tv":0.0,"id":5071877}]}]}
{"op":"mcm","clk":"1004286805","pt":1580581451484,"mc":[{"id":"1.168175453","rc":[{"batb":[[0,1.53,83.56]],"ltp":0.0,"tv":0.0,"id":6374165}]}]}
{"op":"mcm","clk":"1004315783","pt":1580581629304,"mc":[{"id":"1.168175453","rc":[{"batb":[[0,1.53,265.89]],"ltp":0.0,"tv":0.0,"id":6374165}]}]}
{"op":"mcm","clk":"1004316472","pt":1580581633319,"mc":[{"id":"1.168175453","rc":[{"batb":[[2,1.01,16.01]],"ltp":0.0,"tv":0.0,"id":5071877},{"batb":[[1,1.01,16.01],[2,1.01,0]],"ltp":0.0,"tv":0.0,"id":6374165}]}]}
{"op":"mcm","clk":"1004316557","pt":1580581633923,"mc":[{"id":"1.168175453","rc":[{"batb":[[2,2.26,15.02]],"ltp":0.0,"tv":0.0,"id":5071877},{"batb":[[1,1.46,41.16],[2,1.01,16.01]],"ltp":0.0,"tv":0.0,"id":6374165}]}]}
{"op":"mcm","clk":"1004651684","pt":1580583604455,"mc":[{"id":"1.168175453","rc":[{"batb":[[0,2.38,32.09],[1,2.26,15.02],[2,1.01,16.01]],"ltp":0.0,"tv":0.0,"id":5071877}]}]}
{"op":"mcm","clk":"1004955858","pt":1580585229412,"mc":[{"id":"1.168175453","rc":[{"batb":[[0,1.53,83.56]],"ltp":0.0,"tv":0.0,"id":6374165}]}]}
{"op":"mcm","clk":"1004955913","pt":1580585229727,"mc":[{"id":"1.168175453","rc":[{"batb":[[0,2.42,103.44],[1,2.38,32.09],[2,2.26,15.02]],"ltp":0.0,"tv":0.0,"id":5071877},{"batb":[[0,1.53,265.89]],"ltp":0.0,"tv":0.0,"id":6374165}]}]}
{"op":"mcm","clk":"1005259556","pt":1580587202599,"mc":[{"id":"1.168175453","rc":[{"batb":[[1,2.38,42.78]],"ltp":0.0,"tv":0.0,"id":5071877},{"batb":[[0,1.53,293.74]],"ltp":0.0,"tv":0.0,"id":6374165}]}]}
{"op":"mcm","clk":"1005389611","pt":1580587999126,"mc":[{"id":"1.168175453","rc":[{"batb":[[1,1.46,41.17]],"ltp":0.0,"tv":0.0,"id":6374165}]}]}
{"op":"mcm","clk":"1005526449","pt":1580588829728,"mc":[{"id":"1.168175453","rc":[{"batb":[[0,2.38,42.78],[1,2.26,15.02],[2,1.01,16.02]],"ltp":0.0,"tv":0.0,"id":5071877},{"batb":[[0,1.53,111.41]],"ltp":0.0,"tv":0.0,"id":6374165}]}]}
{"op":"mcm","clk":"1005792604","pt":1580590819380,"mc":[{"id":"1.168175453","rc":[{"batb":[[0,2.42,103.44],[1,2.38,42.78]],"ltp":0.0,"tv":0.0,"id":5071877},{"batb":[[0,1.53,293.74],[1,1.01,16.02],[2,1.01,0]],"ltp":0.0,"tv":0.0,"id":6374165}]}]}
{"op":"mcm","clk":"1005794731","pt":1580590836448,"mc":[{"id":"1.168175453","rc":[{"batb":[[0,2.44,2],[1,2.42,103.44],[2,2.38,42.78]],"ltp":0.0,"tv":0.0,"id":5071877},{"batb":[[0,1.54,2],[1,1.53,293.74],[2,1.01,16.02]],"ltp":0.0,"tv":0.0,"id":6374165}]}]}
{"op":"mcm","clk":"1005794777","pt":1580590836867,"mc":[{"id":"1.168175453","rc":[{"batb":[[0,2.48,100.76],[1,2.44,2]],"ltp":0.0,"tv":0.0,"id":5071877},{"batb":[[1,1.53,111.41]],"ltp":0.0,"tv":0.0,"id":6374165}]}]}
{"op":"mcm","clk":"1005795970","pt":1580590847456,"mc":[{"id":"1.168175453","rc":[{"batb":[[0,2.5,2.02],[1,2.38,42.78],[2,1.01,16.02]],"ltp":0.0,"tv":0.0,"id":5071877},{"batb":[[0,1.55,2.02],[1,1.54,2],[2,1.53,111.41]],"ltp":0.0,"tv":0.0,"id":6374165}]}]}
{"op":"mcm","clk":"1005795997","pt":1580590847766,"mc":[{"id":"1.168175453","rc":[{"batb":[[0,2.52,99.24],[1,2.5,2.02],[2,2.38,42.78]],"ltp":0.0,"tv":0.0,"id":5071877}]}]}
{"op":"mcm","clk":"1005872839","pt":1580591436293,"mc":[{"id":"1.168175453","rc":[{"batb":[[1,1.53,111.41],[2,1.01,16.02]],"ltp":0.0,"tv":0.0,"id":6374165}]}]}
{"op":"mcm","clk":"1005887113","pt":1580591541800,"mc":[{"id":"1.168175453","rc":[{"batb":[[0,1.56,2],[1,1.55,2.02],[2,1.53,111.41]],"ltp":0.0,"tv":0.0,"id":6374165}]}]}
{"op":"mcm","clk":"1005887664","pt":1580591545337,"mc":[{"id":"1.168175453","rc":[{"batb":[[0,2.52,100.23]],"ltp":0.0,"tv":0.0,"id":5071877},{"batb":[[0,1.57,1.6],[1,1.56,2],[2,1.55,2.02]],"ltp":0.0,"tv":0.0,"id":6374165}]}]}
{"op":"mcm","clk":"1005970454","pt":1580592141152,"mc":[{"id":"1.168175453","rc":[{"batb":[[1,1.55,2.02],[2,1.53,111.41]],"ltp":0.0,"tv":0.0,"id":6374165}]}]}
{"op":"mcm","clk":"1006033560","pt":1580592631146,"mc":[{"id":"1.168175453","rc":[{"batb":[[0,2.54,3.01]],"ltp":0.0,"tv":0.0,"id":5071877},{"batb":[[1,1.56,4.02],[2,1.55,2.02]],"ltp":0.0,"tv":0.0,"id":6374165}]}]}
{"op":"mcm","clk":"1006061815","pt":1580592851508,"mc":[{"id":"1.168175453","rc":[{"trd":[[1.56,8.03],[1.57,3.21]],"batb":[[0,1.55,2.02],[1,1.53,111.41],[2,1.01,16.02]],"batl":[[0,1.56,95.68]],"ltp":1.56,"tv":11.24,"id":6374165}],"tv":11.24}]}
{"op":"mcm","clk":"1006080042","pt":1580592992454,"mc":[{"id":"1.168175453","rc":[{"trd":[[2.78,10.92]],"ltp":2.78,"tv":10.92,"id":5071877},{"trd":[[1.56,27.48]],"batl":[[0,1.56,76.24]],"ltp":1.56,"tv":30.68,"id":6374165}],"tv":41.6}]}
{"op":"mcm","clk":"1006102200","pt":1580593184454,"mc":[{"id":"1.168175453","rc":[{"batb":[[2,2.4,64.29]],"ltp":2.78,"tv":10.92,"id":5071877},{"batb":[[2,1.45,200.01]],"ltp":1.56,"tv":30.68,"id":6374165}]}]}
{"op":"mcm","clk":"1006163632","pt":1580593683005,"mc":[{"id":"1.168175453","rc":[{"trd":[[1.56,180.04]],"batb":[[0,1.56,28.94],[1,1.55,2.02],[2,1.53,111.41]],"ltp":1.56,"tv":183.24,"id":6374165}],"tv":194.16}]}
{"op":"mcm","clk":"1006164692","pt":1580593692567,"mc":[{"id":"1.168175453","rc":[{"batb":[[0,1.6,28.94]],"ltp":1.56,"tv":183.24,"id":6374165}]}]}
{"op":"mcm","clk":"1006169937","pt":1580593740497,"mc":[{"id":"1.168175453","rc":[{"batb":[[0,1.55,2.02],[1,1.53,111.41],[2,1.45,200.01]],"ltp":1.56,"tv":183.24,"id":6374165}]}]}
{"op":"mcm","clk":"1006169956","pt":1580593740714,"mc":[{"id":"1.168175453","rc":[{"trd":[[2.5,2.02],[2.54,3.01]],"batb":[[0,2.4,64.29],[1,2.38,42.78],[2,1.01,16.02]],"ltp":2.5,"tv":15.95,"id":5071877},{"trd":[[1.65,4.64],[1.67,45.1]],"batb":[[0,1.55,2.26]],"ltp":1.67,"tv":232.98,"id":6374165}],"tv":248.94}]}
{"op":"mcm","clk":"1006176753","pt":1580593806176,"mc":[{"id":"1.168175453","rc":[{"batb":[[0,2.46,102.01],[1,2.4,64.29],[2,2.38,42.78]],"ltp":2.5,"tv":15.95,"id":5071877},{"trd":[[1.55,3.06],[1.67,45.58]],"batb":[[0,1.53,111.9],[1,1.45,200.01],[2,1.01,16.01]],"ltp":1.55,"tv":236.52,"id":6374165}],"tv":252.47}]}
{"op":"mcm","clk":"1006184655","pt":1580593885474,"mc":[{"id":"1.168175453","rc":[{"batb":[[2,1.01,17.65]],"ltp":1.55,"tv":236.52,"id":6374165}]}]}
{"op":"mcm","clk":"1006184697","pt":1580593885890,"mc":[{"id":"1.168175453","rc":[{"batb":[[0,1.54,2.13],[1,1.53,111.41],[2,1.45,200.01]],"ltp":1.55,"tv":236.52,"id":6374165}]}]}
{"op":"mcm","clk":"1006210827","pt":1580594180391,"mc":[{"id":"1.168175453","rc":[{"batb":[[0,2.42,103.82]],"ltp":2.5,"tv":15.95,"id":5071877}]}]}
{"op":"mcm","clk":"1006211188","pt":1580594184591,"mc":[{"id":"1.168175453","rc":[{"batb":[[0,2.4,64.29],[1,2.38,42.78],[2,1.01,16.02]],"ltp":2.5,"tv":15.95,"id":5071877}]}]}
{"op":"mcm","clk":"1006211702","pt":1580594190489,"mc":[{"id":"1.168175453","rc":[{"batb":[[0,1.58,84.81],[1,1.54,2.13],[2,1.53,111.41]],"ltp":1.55,"tv":236.52,"id":6374165}]}]}
{"op":"mcm","clk":"1006211825","pt":1580594191900,"mc":[{"id":"1.168175453","rc":[{"batb":[[0,2.44,102.92],[1,2.4,64.29],[2,2.38,42.78]],"ltp":2.5,"tv":15.95,"id":5071877}]}]}
{"op":"mcm","clk":"1006213791","pt":1580594214527,"mc":[{"id":"1.168175453","rc":[{"batb":[[1,1.53,111.9],[2,1.45,200.01]],"ltp":1.55,"tv":236.52,"id":6374165}]}]}
{"op":"mcm","clk":"1006213804","pt":1580594214635,"mc":[{"id":"1.168175453","rc":[{"batb":[[0,1.59,1.59],[1,1.58,84.81],[2,1.53,111.9]],"ltp":1.55,"tv":236.52,"id":6374165}]}]}
{"op":"mcm","clk":"1006217524","pt":1580594256401,"mc":[{"id":"1.168175453","rc":[{"batb":[[0,2.5,39.36],[1,2.44,102.92],[2,2.4,64.29]],"ltp":2.5,"tv":15.95,"id":5071877},{"batb":[[1,1.5,118.58],[2,1.45,200.01]],"ltp":1.55,"tv":236.52,"id":6374165}]}]}
{"op":"mcm","clk":"1006224305","pt":1580594339180,"mc":[{"id":"1.168175453","rc":[{"batb":[[0,2.6,27.93],[1,2.5,39.36],[2,2.44,102.92]],"ltp":2.5,"tv":15.95,"id":5071877},{"batb":[[1,1.55,68.79],[2,1.5,118.09]],"ltp":1.55,"tv":236.52,"id":6374165}]}]}
{"op":"mcm","clk":"1006229323","pt":1580594392174,"mc":[{"id":"1.168175453","rc":[{"batb":[[1,2.58,26.05],[2,2.5,39.36]],"batl":[[0,2.94,21]],"ltp":2.5,"tv":15.95,"id":5071877},{"batb":[[2,1.52,80.66]],"batl":[[0,1.65,42.01]],"ltp":1.55,"tv":236.52,"id":6374165}]}]}
{"op":"mcm","clk":"1006238433","pt":1580594480339,"mc":[{"id":"1.168175453","rc":[{"trd":[[1.59,3.18]],"batb":[[0,1.55,68.79],[1,1.52,80.66],[2,1.5,118.09]],"batl":[[0,1.59,42.61],[1,1.65,42.01]],"ltp":1.59,"tv":239.7,"id":6374165}],"tv":255.65}]}
{"op":"mcm","clk":"1006238465","pt":1580594480651,"mc":[{"id":"1.168175453","rc":[{"batb":[[0,1.55,243.58]],"ltp":1.59,"tv":239.7,"id":6374165}]}]}
{"op":"mcm","clk":"1006239178","pt":1580594487356,"mc":[{"id":"1.168175453","rc":[{"batl":[[0,1.65,42.01],[1,1.65,0]],"ltp":1.59,"tv":239.7,"id":6374165}]}]}
{"op":"mcm","clk":"1006240055","pt":1580594495541,"mc":[{"id":"1.168175453","rc":[{"batb":[[0,2.62,27.38],[1,2.6,27.93],[2,2.58,26.05]],"ltp":2.5,"tv":15.95,"id":5071877},{"trd":[[1.55,91.49]],"batb":[[0,1.55,199.35],[1,1.54,69.32],[2,1.52,80.66]],"ltp":1.55,"tv":328.12,"id":6374165}],"tv":344.08}]}
{"op":"mcm","clk":"1006240082","pt":1580594495752,"mc":[{"id":"1.168175453","rc":[{"batb":[[1,2.58,26.05],[2,2.5,39.36]],"ltp":2.5,"tv":15.95,"id":5071877},{"batb":[[0,1.55,174.79]],"ltp":1.55,"tv":328.12,"id":6374165}]}]}
{"op":"mcm","clk":"1006240224","pt":1580594496960,"mc":[{"id":"1.168175453","rc":[{"batb":[[0,1.59,74.21]],"ltp":1.55,"tv":328.12,"id":6374165}]}]}
{"op":"mcm","clk":"1006240704","pt":1580594501387,"mc":[{"id":"1.168175453","marketDefinition":{"bspMarket":false,"turnInPlayEnabled":true,"persistenceEnabled":true,"marketBaseRate":5.0,"eventId":"29680072","eventTypeId":"2","numberOfWinners":1,"bettingType":"ODDS","marketType":"SET_WINNER","marketTime":"2020-02-01T21:57:00.000Z","suspendTime":"2020-02-01T21:57:00.000Z","bspReconciled":false,"complete":true,"inPlay":false,"crossMatching":true,"runnersVoidable":false,"numberOfActiveRunners":2,"betDelay":0,"status":"OPEN","runners":[{"status":"ACTIVE","sortPriority":1,"id":6374165,"name":"Marco Cecchinato"},{"status":"ACTIVE","sortPriority":2,"id":5071877,"name":"Andrej Martin"}],"regulators":["MR_INT"],"countryCode":"UY","discountAllowed":true,"timezone":"UTC","openDate":"2020-02-01T22:00:00.000Z","version":3147667736,"name":"Set 1 Winner","eventName":"Cecchinato v Martin"}}]}
{"op":"mcm","clk":"1006240857","pt":1580594502939,"mc":[{"id":"1.168175453","marketDefinition":{"bspMarket":false,"turnInPlayEnabled":true,"persistenceEnabled":true,"marketBaseRate":5.0,"eventId":"29680072","eventTypeId":"2","numberOfWinners":1,"bettingType":"ODDS","marketType":"SET_WINNER","marketTime":"2020-02-01T21:57:00.000Z","suspendTime":"2020-02-01T21:57:00.000Z","bspReconciled":false,"complete":true,"inPlay":false,"crossMatching":true,"runnersVoidable":false,"numberOfActiveRunners":2,"betDelay":0,"status":"OPEN","runners":[{"status":"ACTIVE","sortPriority":1,"id":6374165,"name":"Marco Cecchinato"},{"status":"ACTIVE","sortPriority":2,"id":5071877,"name":"Andrej Martin"}],"regulators":["MR_INT"],"countryCode":"UY","discountAllowed":true,"timezone":"UTC","openDate":"2020-02-01T21:57:00.000Z","version":3147667736,"name":"Set 1 Winner","eventName":"Cecchinato v Martin"}}]}
{"op":"mcm","clk":"1006241411","pt":1580594507501,"mc":[{"id":"1.168175453","rc":[{"batb":[[0,1.54,69.32],[1,1.52,80.66],[2,1.5,118.09]],"ltp":1.55,"tv":328.12,"id":6374165}]}]}
{"op":"mcm","clk":"1006241969","pt":1580594513065,"mc":[{"id":"1.168175453","rc":[{"batb":[[0,1.55,174.79],[1,1.54,69.32],[2,1.52,80.66]],"ltp":1.55,"tv":328.12,"id":6374165}]}]}
{"op":"mcm","clk":"1006243263","pt":1580594526182,"mc":[{"id":"1.168175453","rc":[{"trd":[[2.62,27.38]],"batb":[[0,2.58,26.05],[1,2.5,39.36],[2,2.4,171.43]],"ltp":2.62,"tv":43.33,"id":5071877},{"trd":[[1.62,44.28]],"batb":[[0,1.62,26.9]],"ltp":1.62,"tv":372.41,"id":6374165}],"tv":415.74}]}
{"op":"mcm","clk":"1006243357","pt":1580594527014,"mc":[{"id":"1.168175453","rc":[{"trd":[[2.62,44.01]],"batb":[[0,2.66,11.3],[1,2.58,26.05],[2,2.5,39.36]],"ltp":2.62,"tv":59.96,"id":5071877},{"trd":[[1.62,71.18]],"batb":[[0,1.55,243.01],[1,1.52,80.66],[2,1.5,118.09]],"ltp":1.62,"tv":399.3,"id":6374165}],"tv":459.27}]}
{"op":"mcm","clk":"1006244340","pt":1580594536896,"mc":[{"id":"1.168175453","rc":[{"batb":[[0,2.58,54.14],[1,2.5,39.36],[2,2.4,171.43]],"ltp":2.62,"tv":59.96,"id":5071877},{"batb":[[0,1.56,67.9]],"ltp":1.62,"tv":399.3,"id":6374165}]}]}
{"op":"mcm","clk":"1006245520","pt":1580594547532,"mc":[{"id":"1.168175453","rc":[{"batb":[[1,1.51,82.34]],"batl":[[0,1.63,42.01]],"ltp":1.62,"tv":399.3,"id":6374165}]}]}
{"op":"mcm","clk":"1006245725","pt":1580594549417,"mc":[{"id":"1.168175453","rc":[{"batb":[[0,2.6,27.54],[1,2.58,26.05],[2,2.5,39.36]],"ltp":2.62,"tv":59.96,"id":5071877},{"trd":[[1.56,268.46]],"batb":[[0,1.56,68.92]],"ltp":1.56,"tv":487.73,"id":6374165}],"tv":547.7}]}
{"op":"mcm","clk":"1006247995","pt":1580594570470,"mc":[{"id":"1.168175453","rc":[{"batb":[[0,2.64,27.07]],"ltp":2.62,"tv":59.96,"id":5071877},{"batb":[[0,1.54,70.03]],"ltp":1.56,"tv":487.73,"id":6374165}]}]}
{"op":"mcm","clk":"1006248019","pt":1580594570672,"mc":[{"id":"1.168175453","rc":[{"batb":[[0,1.55,174.79],[1,1.54,70.03],[2,1.51,82.34]],"ltp":1.56,"tv":487.73,"id":6374165}]}]}
{"op":"mcm","clk":"1006249033","pt":1580594580554,"mc":[{"id":"1.168175453","rc":[{"batb":[[0,2.66,26.52]],"ltp":2.62,"tv":59.96,"id":5071877},{"batb":[[1,1.53,71.21]],"ltp":1.56,"tv":487.73,"id":6374165}]}]}
{"op":"mcm","clk":"1006254055","pt":1580594630346,"mc":[{"id":"1.168175453","rc":[{"batb":[[0,1.54,176.12]],"ltp":1.56,"tv":487.73,"id":6374165}]}]}
{"op":"mcm","clk":"1006255839","pt":1580594649361,"mc":[{"id":"1.168175453","rc":[{"batb":[[1,1.53,70.89]],"ltp":1.56,"tv":487.73,"id":6374165}]}]}
{"op":"mcm","clk":"1006259737","pt":1580594688453,"mc":[{"id":"1.168175453","marketDefinition":{"bspMarket":false,"turnInPlayEnabled":true,"persistenceEnabled":true,"marketBaseRate":5.0,"eventId":"29680072","eventTypeId":"2","numberOfWinners":1,"bettingType":"ODDS","marketType":"SET_WINNER","marketTime":"2020-02-01T21:57:00.000Z","suspendTime":"2020-02-01T21:57:00.000Z","bspReconciled":false,"complete":true,"inPlay":false,"crossMatching":true,"runnersVoidable":false,"numberOfActiveRunners":2,"betDelay":0,"status":"OPEN","runners":[{"status":"ACTIVE","sortPriority":1,"id":6374165,"name":"Marco Cecchinato"},{"status":"ACTIVE","sortPriority":2,"id":5071877,"name":"Andrej Martin"}],"regulators":["MR_INT"],"countryCode":"UY","discountAllowed":true,"timezone":"UTC","openDate":"2020-02-01T21:57:00.000Z","version":3147667736,"name":"Set 1 Winner","eventName":"Cecchinato v Martin"},"rc":[{"batb":[[0,2.5,39.36],[1,2.4,171.43],[2,1.01,16.02]],"ltp":2.62,"tv":59.96,"id":5071877},{"batb":[[1,1.5,118.09],[2,1.48,312.51]],"ltp":1.56,"tv":487.73,"id":6374165}]}]}
{"op":"mcm","clk":"1006259796","pt":1580594689138,"mc":[{"id":"1.168175453","marketDefinition":{"bspMarket":false,"turnInPlayEnabled":true,"persistenceEnabled":true,"marketBaseRate":5.0,"eventId":"29680072","eventTypeId":"2","numberOfWinners":1,"bettingType":"ODDS","marketType":"SET_WINNER","marketTime":"2020-02-01T21:57:00.000Z","suspendTime":"2020-02-01T21:57:00.000Z","bspReconciled":false,"complete":true,"inPlay":true,"crossMatching":true,"runnersVoidable":false,"numberOfActiveRunners":2,"betDelay":3,"status":"OPEN","runners":[{"status":"ACTIVE","sortPriority":1,"id":6374165,"name":"Marco Cecchinato"},{"status":"ACTIVE","sortPriority":2,"id":5071877,"name":"Andrej Martin"}],"regulators":["MR_INT"],"countryCode":"UY","discountAllowed":true,"timezone":"UTC","openDate":"2020-02-01T21:57:00.000Z","version":3147676943,"name":"Set 1 Winner","eventName":"Cecchinato v Martin"},"rc":[{"batb":[[0,1.01,15.52],[1,2.4,0],[2,1.01,0]],"ltp":2.62,"tv":59.96,"id":5071877},{"batb":[[0,1.01,15.52],[1,1.5,0],[2,1.48,0]],"ltp":1.56,"tv":487.73,"id":6374165}]}]}
{"op":"mcm","clk":"1006261163","pt":1580594703448,"mc":[{"id":"1.168175453","rc":[{"batb":[[0,2.76,23.53],[1,1.01,15.52]],"batl":[[0,3.2,18.48]],"ltp":2.62,"tv":59.96,"id":5071877},{"batb":[[0,1.46,90.75],[1,1.01,15.51]],"batl":[[0,1.57,42.01]],"ltp":1.56,"tv":487.73,"id":6374165}]}]}
{"op":"mcm","clk":"1006261233","pt":1580594704124,"mc":[{"id":"1.168175453","rc":[{"batb":[[0,2.9,21.17],[1,2.76,23.53],[2,2.58,28.8]],"ltp":2.62,"tv":59.96,"id":5071877},{"batb":[[0,1.46,177.22],[1,1.4,102.21],[2,1.01,15.51]],"ltp":1.56,"tv":487.73,"id":6374165}]}]}
{"op":"mcm","clk":"1006262673","pt":1580594717441,"mc":[{"id":"1.168175453","rc":[{"batb":[[0,2.76,23.53],[1,2.58,28.8],[2,1.01,15.52]],"ltp":2.62,"tv":59.96,"id":5071877},{"batb":[[0,1.46,90.75]],"ltp":1.56,"tv":487.73,"id":6374165}]}]}
{"op":"mcm","clk":"1006262784","pt":1580594718328,"mc":[{"id":"1.168175453","rc":[{"batb":[[0,2.58,28.8],[1,1.01,15.52],[2,1.01,0]],"ltp":2.62,"tv":59.96,"id":5071877},{"batb":[[0,1.4,102.22],[1,1.01,15.51],[2,1.01,0]],"ltp":1.56,"tv":487.73,"id":6374165}]}]}
{"op":"mcm","clk":"1006263039","pt":1580594720465,"mc":[{"id":"1.168175453","rc":[{"batb":[[0,2.56,29.35]],"ltp":2.62,"tv":59.96,"id":5071877},{"batb":[[0,1.41,100.64]],"ltp":1.56,"tv":487.73,"id":6374165}]}]}
{"op":"mcm","clk":"1006265382","pt":1580594741179,"mc":[{"id":"1.168175453","rc":[{"batb":[[0,1.44,551.15],[1,1.43,422.89],[2,1.41,100.63]],"batl":[[0,1.65,311.71],[1,1.66,233.11]],"ltp":1.56,"tv":487.73,"id":6374165}]}]}
{"op":"mcm","clk":"1006265912","pt":1580594745909,"mc":[{"id":"1.168175453","rc":[{"batb":[[0,1.41,100.64],[1,1.01,15.51],[2,1.41,0]],"ltp":1.56,"tv":487.73,"id":6374165}]}]}
{"op":"mcm","clk":"1006266321","pt":1580594749482,"mc":[{"id":"1.168175453","rc":[{"batb":[[1,2.54,26.89],[2,2.2,43.83]],"batl":[[0,2.88,21.85]],"ltp":2.62,"tv":59.96,"id":5071877},{"batb":[[0,1.59,328.5],[1,1.58,281.62],[2,1.57,65.31]],"batl":[[0,1.65,353.72]],"ltp":1.56,"tv":487.73,"id":6374165}]}]}
{"op":"mcm","clk":"1006266591","pt":1580594752129,"mc":[{"id":"1.168175453","rc":[{"batl":[[0,1.65,455.06]],"ltp":1.56,"tv":487.73,"id":6374165}]}]}
{"op":"mcm","clk":"1006269168","pt":1580594774412,"mc":[{"id":"1.168175453","rc":[{"batb":[[0,2.54,26.89],[1,2.2,43.83],[2,1.01,15.52]],"ltp":2.62,"tv":59.96,"id":5071877},{"batb":[[0,1.53,78.98],[1,1.47,83.26],[2,1.01,15.51]],"batl":[[0,1.65,42.01],[1,1.66,0]],"ltp":1.56,"tv":487.73,"id":6374165}]}]}
{"op":"mcm","clk":"1006269186","pt":1580594774625,"mc":[{"id":"1.168175453","rc":[{"batb":[[0,2.2,43.83],[1,1.01,15.52],[2,1.01,0]],"ltp":2.62,"tv":59.96,"id":5071877},{"batb":[[0,1.47,83.26],[1,1.01,15.51],[2,1.01,0]],"ltp":1.56,"tv":487.73,"id":6374165}]}]}
{"op":"mcm","clk":"1006269604","pt":1580594778007,"mc":[{"id":"1.168175453","rc":[{"batb":[[0,1.5,352.4],[1,1.49,354.76],[2,1.47,83.26]],"batl":[[0,1.84,348.07],[1,1.86,322.98]],"ltp":1.56,"tv":487.73,"id":6374165}]}]}
{"op":"mcm","clk":"1006270533","pt":1580594785568,"mc":[{"id":"1.168175453","rc":[{"batb":[[0,2.86,21.95],[1,2.74,23.53],[2,2.5,31.16]],"batl":[[0,3.15,19.32]],"ltp":2.62,"tv":59.96,"id":5071877},{"batl":[[0,1.55,411.06],[1,1.56,291.64],[2,1.58,42.01]],"ltp":1.56,"tv":487.73,"id":6374165}]}]}
{"op":"mcm","clk":"1006270864","pt":1580594788371,"mc":[{"id":"1.168175453","rc":[{"trd":[[2.86,4.54]],"batb":[[0,2.86,19.68]],"ltp":2.86,"tv":64.51,"id":5071877}],"tv":552.24}]}
{"op":"mcm","clk":"1006271724","pt":1580594795462,"mc":[{"id":"1.168175453","rc":[{"batb":[[0,2.74,23.53],[1,2.5,31.16],[2,1.01,15.52]],"ltp":2.86,"tv":64.51,"id":5071877},{"batb":[[0,1.46,90.75],[1,1.41,101.34],[2,1.01,15.51]],"batl":[[0,1.58,42.01],[1,1.56,0],[2,1.58,0]],"ltp":1.56,"tv":487.73,"id":6374165}]}]}
{"op":"mcm","clk":"1006271854","pt":1580594796441,"mc":[{"id":"1.168175453","rc":[{"batb":[[0,2.5,31.16],[1,1.01,15.52],[2,1.01,0]],"ltp":2.86,"tv":64.51,"id":5071877},{"batb":[[0,1.41,101.35],[1,1.01,15.51],[2,1.01,0]],"ltp":1.56,"tv":487.73,"id":6374165}]}]}
{"op":"mcm","clk":"1006272096","pt":1580594798477,"mc":[{"id":"1.168175453","rc":[{"batb":[[0,1.44,304.18],[1,1.43,421.73],[2,1.41,101.34]],"batl":[[0,1.68,412.01],[1,1.7,432.37]],"ltp":1.56,"tv":487.73,"id":6374165}]}]}
{"op":"mcm","clk":"1006272578","pt":1580594802446,"mc":[{"id":"1.168175453","rc":[{"batl":[[2,4,4.23]],"ltp":1.56,"tv":487.73,"id":6374165}]}]}
{"op":"mcm","clk":"1006272697","pt":1580594803500,"mc":[{"id":"1.168175453","rc":[{"batl":[[0,4,4.23],[1,1.7,0],[2,4,0]],"ltp":1.56,"tv":487.73,"id":6374165}]}]}
{"op":"mcm","clk":"1006273075","pt":1580594806569,"mc":[{"id":"1.168175453","rc":[{"batb":[[0,3.1,43.2],[1,2.86,21.79],[2,2.5,31.16]],"ltp":2.86,"tv":64.51,"id":5071877},{"trd":[[1.48,0.02]],"batb":[[0,1.44,304.17]],"batl":[[0,1.48,348.14],[1,1.49,348.7],[2,4,4.23]],"ltp":1.48,"tv":487.75,"id":6374165}],"tv":552.26}]}
{"op":"mcm","clk":"1006273175","pt":1580594807350,"mc":[{"id":"1.168175453","rc":[{"batb":[[1,2.94,21],[2,2.86,21.79]],"batl":[[0,3.45,16.8]],"ltp":2.86,"tv":64.51,"id":5071877},{"batb":[[2,1.41,203.01]],"batl":[[2,1.52,42.01]],"ltp":1.48,"tv":487.75,"id":6374165}]}]}
{"op":"mcm","clk":"1006274484","pt":1580594818412,"mc":[{"id":"1.168175453","rc":[{"batb":[[0,2.86,21.79],[1,1.01,15.52],[2,2.86,0]],"ltp":2.86,"tv":64.51,"id":5071877},{"batb":[[0,1.37,115.82],[1,1.01,15.51],[2,1.41,0]],"batl":[[0,4,4.23],[1,1.49,0],[2,1.52,0]],"ltp":1.48,"tv":487.75,"id":6374165}]}]}
{"op":"mcm","clk":"1006274791","pt":1580594821079,"mc":[{"id":"1.168175453","rc":[{"batb":[[0,1.41,273.38],[1,1.4,463.25],[2,1.37,115.82]],"batl":[[0,1.54,293.78],[1,1.55,299.45],[2,4,4.23]],"ltp":1.48,"tv":487.75,"id":6374165}]}]}
{"op":"mcm","clk":"1006275533","pt":1580594826404,"mc":[{"id":"1.168175453","rc":[{"batl":[[0,4,4.23],[1,1.55,0],[2,4,0]],"ltp":1.48,"tv":487.75,"id":6374165}]}]}
{"op":"mcm","clk":"1006275871","pt":1580594829566,"mc":[{"id":"1.168175453","rc":[{"batl":[[0,1.45,494.67],[1,1.46,377.48],[2,4,4.23]],"ltp":1.48,"tv":487.75,"id":6374165}]}]}
{"op":"mcm","clk":"1006276054","pt":1580594830353,"mc":[{"id":"1.168175453","rc":[{"batb":[[0,3.35,36.27],[1,3.1,19.32],[2,2.98,48.55]],"batl":[[0,3.65,15.12]],"ltp":2.86,"tv":64.51,"id":5071877},{"batb":[[0,1.4,463.25],[1,1.38,110.07]],"batl":[[2,1.48,42.01]],"ltp":1.48,"tv":487.75,"id":6374165}]}]}
{"op":"mcm","clk":"1006276350","pt":1580594832758,"mc":[{"id":"1.168175453","rc":[{"batb":[[0,1.4,727.49],[1,1.39,483.59],[2,1.38,110.07]],"ltp":1.48,"tv":487.75,"id":6374165}]}]}
{"op":"mcm","clk":"1006278952","pt":1580594853199,"mc":[{"id":"1.168175453","rc":[{"batb":[[1,2.98,48.55],[2,1.01,15.52]],"ltp":2.86,"tv":64.51,"id":5071877},{"batb":[[2,1.37,114.64]],"batl":[[2,4,4.23]],"ltp":1.48,"tv":487.75,"id":6374165}]}]}
{"op":"mcm","clk":"1006279318","pt":1580594856321,"mc":[{"id":"1.168175453","rc":[{"batb":[[1,3.15,19.32],[2,2.98,48.55]],"ltp":2.86,"tv":64.51,"id":5071877},{"batb":[[2,1.37,228.07]],"batl":[[2,1.47,42.01]],"ltp":1.48,"tv":487.75,"id":6374165}]}]}
{"op":"mcm","clk":"1006279686","pt":1580594859605,"mc":[{"id":"1.168175453","rc":[{"trd":[[3.35,8.18]],"batb":[[0,3.35,32.18]],"ltp":3.35,"tv":72.68,"id":5071877}],"tv":560.44}]}
{"op":"mcm","clk":"1006280454","pt":1580594866032,"mc":[{"id":"1.168175453","rc":[{"batb":[[0,1.37,228.07],[1,1.29,153.35],[2,1.01,15.51]],"batl":[[0,1.47,42.01],[1,4,4.23],[2,1.47,0]],"ltp":1.48,"tv":487.75,"id":6374165}]}]}
{"op":"mcm","clk":"1006280836","pt":1580594869006,"mc":[{"id":"1.168175453","rc":[{"batb":[[1,1.32,717.99],[2,1.31,648.46]],"batl":[[1,1.52,400.76],[2,1.53,314.15]],"ltp":1.48,"tv":487.75,"id":6374165}]}]}
{"op":"mcm","clk":"1006281985","pt":1580594878421,"mc":[{"id":"1.168175453","rc":[{"batb":[[0,2.98,48.55],[1,1.01,15.52],[2,2.98,0]],"ltp":3.35,"tv":72.68,"id":5071877},{"batb":[[0,1.32,717.99],[1,1.31,648.46],[2,1.29,153.35]],"batl":[[0,1.52,400.76],[1,1.53,314.15],[2,4,4.23]],"ltp":1.48,"tv":487.75,"id":6374165}]}]}
{"op":"mcm","clk":"1006282313","pt":1580594881133,"mc":[{"id":"1.168175453","rc":[{"batb":[[0,2.92,50.99]],"ltp":3.35,"tv":72.68,"id":5071877},{"batb":[[2,1.3,149.42]],"ltp":1.48,"tv":487.75,"id":6374165}]}]}
{"op":"mcm","clk":"1006282986","pt":1580594886560,"mc":[{"id":"1.168175453","rc":[{"batb":[[0,1.3,149.42],[1,1.01,15.51],[2,1.3,0]],"ltp":1.48,"tv":487.75,"id":6374165}]}]}
{"op":"mcm","clk":"1006283342","pt":1580594889365,"mc":[{"id":"1.168175453","rc":[{"batb":[[1,2.9,21.85],[2,1.01,15.52]],"batl":[[0,3.35,17.64]],"ltp":3.35,"tv":72.68,"id":5071877},{"batb":[[0,1.47,483.2],[1,1.46,387.25],[2,1.42,99.98]],"batl":[[1,1.53,356.16]],"ltp":1.48,"tv":487.75,"id":6374165}]}]}
{"op":"mcm","clk":"1006283471","pt":1580594890568,"mc":[{"id":"1.168175453","rc":[{"batb":[[2,2.68,25.65]],"ltp":3.35,"tv":72.68,"id":5071877},{"batb":[[2,1.45,89.15]],"ltp":1.48,"tv":487.75,"id":6374165}]}]}
{"op":"mcm","clk":"1006285381","pt":1580594907067,"mc":[{"id":"1.168175453","rc":[{"batb":[[0,2.9,21.85],[1,2.68,25.49],[2,2.12,388.65]],"ltp":3.35,"tv":72.68,"id":5071877},{"batb":[[0,1.42,99.98],[1,1.37,114.8],[2,1.31,477.51]],"batl":[[0,1.53,42.01],[1,4,4.23],[2,4,0]],"ltp":1.48,"tv":487.75,"id":6374165}]}]}
{"op":"mcm","clk":"1006285530","pt":1580594908477,"mc":[{"id":"1.168175453","rc":[{"batb":[[0,2.68,25.49],[1,2.12,388.65],[2,1.01,15.52]],"ltp":3.35,"tv":72.68,"id":5071877},{"batb":[[0,1.37,114.8],[1,1.31,477.51],[2,1.01,15.51]],"batl":[[0,4,4.23],[1,4,0]],"ltp":1.48,"tv":487.75,"id":6374165}]}]}
{"op":"mcm","clk":"1006285890","pt":1580594911494,"mc":[{"id":"1.168175453","rc":[{"batb":[[0,1.45,631.07],[1,1.44,412.02],[2,1.37,114.8]],"batl":[[0,1.5,346.64],[1,1.51,330.96],[2,4,4.23]],"ltp":1.48,"tv":487.75,"id":6374165}]}]}
{"op":"mcm","clk":"1006286775","pt":1580594918500,"mc":[{"id":"1.168175453","rc":[{"batb":[[0,1.37,114.8],[1,1.31,477.51],[2,1.01,15.51]],"batl":[[0,4,4.23],[1,1.51,0],[2,4,0]],"ltp":1.48,"tv":487.75,"id":6374165}]}]}
{"op":"mcm","clk":"1006287117","pt":1580594921518,"mc":[{"id":"1.168175453","rc":[{"batb":[[0,1.39,569.06],[1,1.38,498.61],[2,1.37,114.8]],"batl":[[0,1.59,433.89],[1,1.6,265.73],[2,4,4.23]],"ltp":1.48,"tv":487.75,"id":6374165}]}]}
{"op":"mcm","clk":"1006287314","pt":1580594923394,"mc":[{"id":"1.168175453","rc":[{"batl":[[0,4,4.23],[1,1.6,0],[2,4,0]],"ltp":1.48,"tv":487.75,"id":6374165}]}]}
{"op":"mcm","clk":"1006287459","pt":1580594925016,"mc":[{"id":"1.168175453","rc":[{"batb":[[1,1.01,15.52],[2,1.01,0]],"ltp":3.35,"tv":72.68,"id":5071877}]}]}
{"op":"mcm","clk":"1006287597","pt":1580594926194,"mc":[{"id":"1.168175453","rc":[{"batl":[[0,1.43,311.61],[1,1.44,401.81],[2,4,4.23]],"ltp":1.48,"tv":487.75,"id":6374165}]}]}
{"op":"mcm","clk":"1006287747","pt":1580594927386,"mc":[{"id":"1.168175453","rc":[{"batb":[[0,3.35,36.51],[1,3.2,18.48],[2,2.94,50.2]],"batl":[[0,3.8,14.28]],"ltp":3.35,"tv":72.68,"id":5071877},{"batl":[[2,1.45,42.01]],"ltp":1.48,"tv":487.75,"id":6374165}]}]}
{"op":"mcm","clk":"1006289254","pt":1580594941511,"mc":[{"id":"1.168175453","rc":[{"batb":[[0,3.2,18.48],[1,2.94,50.2],[2,2.3,385.09]],"ltp":3.35,"tv":72.68,"id":5071877},{"batb":[[0,1.36,115.95],[1,1.28,162.95],[2,1.25,505.09]],"batl":[[0,1.45,42.01],[1,4,4.23],[2,1.45,0]],"ltp":1.48,"tv":487.75,"id":6374165}]}]}
{"op":"mcm","clk":"1006289346","pt":1580594942395,"mc":[{"id":"1.168175453","rc":[{"batb":[[0,2.94,50.2],[1,2.3,385.09],[2,1.01,15.52]],"ltp":3.35,"tv":72.68,"id":5071877},{"batb":[[0,1.28,162.95],[1,1.25,505.09],[2,1.01,15.51]],"batl":[[0,4,4.23],[1,4,0]],"ltp":1.48,"tv":487.75,"id":6374165}]}]}
{"op":"mcm","clk":"1006289559","pt":1580594944310,"mc":[{"id":"1.168175453","rc":[{"batb":[[0,1.3,399.17],[1,1.29,699.01],[2,1.28,162.95]],"batl":[[0,1.52,459.74],[1,1.53,313.77],[2,4,4.23]],"ltp":1.48,"tv":487.75,"id":6374165}]}]}
{"op":"mcm","clk":"1006290311","pt":1580594951449,"mc":[{"id":"1.168175453","rc":[{"batb":[[0,1.28,162.95],[1,1.25,505.09],[2,1.01,15.51]],"ltp":1.48,"tv":487.75,"id":6374165}]}]}
{"op":"mcm","clk":"1006290377","pt":1580594952024,"mc":[{"id":"1.168175453","rc":[{"batb":[[1,1.01,15.51],[2,1.01,0]],"ltp":1.48,"tv":487.75,"id":6374165}]}]}
{"op":"mcm","clk":"1006290620","pt":1580594954258,"mc":[{"id":"1.168175453","rc":[{"batb":[[1,2.66,26.36],[2,2.3,385.09]],"ltp":3.35,"tv":72.68,"id":5071877},{"batb":[[0,1.47,420.07],[1,1.46,386.77],[2,1.45,90.17]],"ltp":1.48,"tv":487.75,"id":6374165}]}]}
{"op":"mcm","clk":"1006290778","pt":1580594955518,"mc":[{"id":"1.168175453","rc":[{"batb":[[1,2.92,21.85],[2,2.66,26.36]],"batl":[[0,3.35,17.64]],"ltp":3.35,"tv":72.68,"id":5071877},{"batl":[[1,1.53,355.78]],"ltp":1.48,"tv":487.75,"id":6374165}]}]}
{"op":"mcm","clk":"1006292622","pt":1580594971170,"mc":[{"id":"1.168175453","rc":[{"batb":[[0,2.92,21.85],[1,2.66,26.36],[2,2.3,385.09]],"ltp":3.35,"tv":72.68,"id":5071877},{"batb":[[0,1.42,99.98],[1,1.36,120.15],[2,1.31,477.51]],"batl":[[0,1.53,42.01],[1,4,4.23],[2,4,0]],"ltp":1.48,"tv":487.75,"id":6374165}]}]}
{"op":"mcm","clk":"1006292798","pt":1580594972534,"mc":[{"id":"1.168175453","rc":[{"batb":[[0,2.66,26.36],[1,2.3,385.09],[2,1.01,15.52]],"ltp":3.35,"tv":72.68,"id":5071877},{"batb":[[0,1.36,120.15],[1,1.31,477.51],[2,1.01,15.51]],"batl":[[0,4,4.23],[1,4,0]],"ltp":1.48,"tv":487.75,"id":6374165}]}]}
{"op":"mcm","clk":"1006292909","pt":1580594973672,"mc":[{"id":"1.168175453","rc":[{"batb":[[0,1.38,431.09],[1,1.37,514.46],[2,1.36,120.15]],"batl":[[0,1.6,439.54],[1,1.61,259.8],[2,4,4.23]],"ltp":1.48,"tv":487.75,"id":6374165}]}]}
{"op":"mcm","clk":"1006293144","pt":1580594975560,"mc":[{"id":"1.168175453","rc":[{"batb":[[0,1.36,120.15],[1,1.31,477.51],[2,1.01,15.51]],"ltp":1.48,"tv":487.75,"id":6374165}]}]}
{"op":"mcm","clk":"1006293220","pt":1580594976187,"mc":[{"id":"1.168175453","rc":[{"batb":[[1,1.01,15.52],[2,1.01,0]],"ltp":3.35,"tv":72.68,"id":5071877},{"batb":[[1,1.01,15.51],[2,1.01,0]],"ltp":1.48,"tv":487.75,"id":6374165}]}]}
{"op":"mcm","clk":"1006293468","pt":1580594978375,"mc":[{"id":"1.168175453","rc":[{"batb":[[1,2.5,31.16],[2,1.01,15.52]],"ltp":3.35,"tv":72.68,"id":5071877},{"batb":[[0,1.54,469.96],[1,1.53,391.34],[2,1.46,87.65]],"ltp":1.48,"tv":487.75,"id":6374165}]}]}
{"op":"mcm","clk":"1006293592","pt":1580594979376,"mc":[{"id":"1.168175453","rc":[{"batb":[[0,2.68,24.37],[1,2.66,26.36],[2,2.5,31.16]],"batl":[[0,3.1,19.32]],"ltp":3.35,"tv":72.68,"id":5071877},{"batb":[[2,1.48,87.38]],"batl":[[0,1.6,481.55]],"ltp":1.48,"tv":487.75,"id":6374165}]}]}
{"op":"mcm","clk":"1006295125","pt":1580594992579,"mc":[{"id":"1.168175453","rc":[{"batb":[[1,2.5,31.16],[2,1.97,394.86]],"ltp":3.35,"tv":72.68,"id":5071877},{"batb":[[0,1.48,87.38],[1,1.46,87.65],[2,1.38,448.45]],"batl":[[0,1.6,42.01],[1,4,4.23],[2,4,0]],"ltp":1.48,"tv":487.75,"id":6374165}]}]}
{"op":"mcm","clk":"1006295330","pt":1580594994458,"mc":[{"id":"1.168175453","rc":[{"batb":[[0,2.5,31.16],[1,1.97,394.86],[2,1.01,15.52]],"ltp":3.35,"tv":72.68,"id":5071877},{"batb":[[0,1.46,87.65],[1,1.38,448.45],[2,1.01,15.51]],"batl":[[0,4,4.23],[1,4,0]],"ltp":1.48,"tv":487.75,"id":6374165}]}]}
{"op":"mcm","clk":"1006295427","pt":1580594995507,"mc":[{"id":"1.168175453","rc":[{"batb":[[0,1.48,426.23],[1,1.47,375.86],[2,1.46,87.65]],"batl":[[0,1.65,396.45],[1,1.66,233.39],[2,4,4.23]],"ltp":1.48,"tv":487.75,"id":6374165}]}]}
{"op":"mcm","clk":"1006295453","pt":1580594995666,"mc":[{"id":"1.168175453","rc":[{"batb":[[0,1.46,87.65],[1,1.38,448.45],[2,1.01,15.51]],"batl":[[0,4,4.23],[1,1.66,0],[2,4,0]],"ltp":1.48,"tv":487.75,"id":6374165}]}]}
{"op":"mcm","clk":"1006295621","pt":1580594997180,"mc":[{"id":"1.168175453","rc":[{"batb":[[0,1.53,383.75],[1,1.52,327.69],[2,1.46,87.65]],"batl":[[0,1.58,284.97],[1,1.59,272.55],[2,4,4.23]],"ltp":1.48,"tv":487.75,"id":6374165}]}]}
{"op":"mcm","clk":"1006296369","pt":1580595003904,"mc":[{"id":"1.168175453","rc":[{"batb":[[0,1.46,87.65],[1,1.38,448.45],[2,1.01,15.51]],"batl":[[0,4,4.23],[1,1.59,0],[2,4,0]],"ltp":1.48,"tv":487.75,"id":6374165}]}]}
{"op":"mcm","clk":"1006296749","pt":1580595007510,"mc":[{"id":"1.168175453","rc":[{"batb":[[0,1.48,426.23],[1,1.47,375.86],[2,1.46,87.65]],"batl":[[0,1.65,396.45],[1,1.66,233.39],[2,4,4.23]],"ltp":1.48,"tv":487.75,"id":6374165}]}]}
{"op":"mcm","clk":"1006297890","pt":1580595017404,"mc":[{"id":"1.168175453","rc":[{"batb":[[0,1.46,87.65],[1,1.38,448.45],[2,1.01,15.51]],"ltp":1.48,"tv":487.75,"id":6374165}]}]}
{"op":"mcm","clk":"1006298161","pt":1580595019298,"mc":[{"id":"1.168175453","rc":[{"batb":[[1,1.01,15.51],[2,1.01,0]],"ltp":1.48,"tv":487.75,"id":6374165}]}]}
{"op":"mcm","clk":"1006298301","pt":1580595020499,"mc":[{"id":"1.168175453","rc":[{"batb":[[0,1.59,347.36],[1,1.58,281.89],[2,1.46,87.65]],"ltp":1.48,"tv":487.75,"id":6374165}]}]}
{"op":"mcm","clk":"1006298380","pt":1580595021123,"mc":[{"id":"1.168175453","rc":[{"batb":[[1,2.18,45.56],[2,1.97,394.86]],"ltp":3.35,"tv":72.68,"id":5071877},{"batb":[[0,1.59,409.52],[2,1.51,76.56]],"ltp":1.48,"tv":487.75,"id":6374165}]}]}
{"op":"mcm","clk":"1006298457","pt":1580595021974,"mc":[{"id":"1.168175453","rc":[{"batb":[[0,2.52,26.89],[1,2.5,31.16],[2,2.18,45.56]],"batl":[[0,2.9,21.85]],"ltp":3.35,"tv":72.68,"id":5071877},{"batb":[[2,1.53,78.98]],"batl":[[1,1.66,275.4]],"ltp":1.48,"tv":487.75,"id":6374165}]}]}
{"op":"mcm","clk":"1006300811","pt":1580595044997,"mc":[{"id":"1.168175453","rc":[{"trd":[[1.59,131.6]],"batb":[[0,1.59,345.31]],"ltp":1.59,"tv":616.17,"id":6374165}],"tv":688.86}]}
{"op":"mcm","clk":"1006301906","pt":1580595054511,"mc":[{"id":"1.168175453","rc":[{"batb":[[0,1.59,62.16],[1,1.53,78.98],[2,1.51,76.56]],"batl":[[0,1.66,42.01],[1,4,4.23],[2,4,0]],"ltp":1.59,"tv":616.17,"id":6374165}]}]}
{"op":"mcm","clk":"1006301968","pt":1580595054883,"mc":[{"id":"1.168175453","rc":[{"batb":[[1,2.18,45.56],[2,1.97,394.86]],"ltp":3.35,"tv":72.68,"id":5071877},{"batb":[[0,1.53,78.98],[1,1.51,76.56],[2,1.4,451]],"ltp":1.59,"tv":616.17,"id":6374165}]}]}
{"op":"mcm","clk":"1006302141","pt":1580595056471,"mc":[{"id":"1.168175453","rc":[{"batb":[[0,2.18,45.56],[1,1.97,394.86],[2,1.01,15.52]],"ltp":3.35,"tv":72.68,"id":5071877},{"batb":[[0,1.51,76.56],[1,1.4,451],[2,1.01,15.51]],"batl":[[0,4,4.23],[1,4,0]],"ltp":1.59,"tv":616.17,"id":6374165}]}]}
{"op":"mcm","clk":"1006302262","pt":1580595057491,"mc":[{"id":"1.168175453","rc":[{"batb":[[0,1.51,487.31],[1,1.5,345.89],[2,1.4,451]],"batl":[[0,1.82,382.81],[1,1.84,334.27],[2,4,4.23]],"ltp":1.59,"tv":616.17,"id":6374165}]}]}
{"op":"mcm","clk":"1006302310","pt":1580595057903,"mc":[{"id":"1.168175453","rc":[{"batb":[[0,2.18,44.77]],"ltp":3.35,"tv":72.68,"id":5071877},{"batb":[[0,1.51,410.75],[1,1.5,423.55]],"ltp":1.59,"tv":616.17,"id":6374165}]}]}
{"op":"mcm","clk":"1006303043","pt":1580595064380,"mc":[{"id":"1.168175453","rc":[{"batl":[[0,4,4.23],[1,1.84,0],[2,4,0]],"ltp":1.59,"tv":616.17,"id":6374165}]}]}
{"op":"mcm","clk":"1006303284","pt":1580595066420,"mc":[{"id":"1.168175453","rc":[{"batb":[[2,1.01,15.51]],"ltp":1.59,"tv":616.17,"id":6374165}]}]}
{"op":"mcm","clk":"1006303414","pt":1580595067527,"mc":[{"id":"1.168175453","rc":[{"batl":[[0,1.56,323.75],[1,1.57,285.49],[2,4,4.23]],"ltp":1.59,"tv":616.17,"id":6374165}]}]}
{"op":"mcm","clk":"1006303482","pt":1580595068106,"mc":[{"id":"1.168175453","rc":[{"batb":[[0,2.76,23.92],[1,2.7,24.37],[2,2.42,33.28]],"batl":[[0,3.15,19.32]],"ltp":3.35,"tv":72.68,"id":5071877},{"batb":[[2,1.47,89.06]],"batl":[[2,1.59,42.01]],"ltp":1.59,"tv":616.17,"id":6374165}]}]}
{"op":"mcm","clk":"1006305463","pt":1580595085043,"mc":[{"id":"1.168175453","rc":[{"batb":[[0,2.7,24.37],[1,2.42,33.28],[2,1.97,394.86]],"ltp":3.35,"tv":72.68,"id":5071877},{"batb":[[0,1.47,89.06],[1,1.44,92.92],[2,1.34,465.43]],"batl":[[0,1.59,42.01],[1,4,4.23],[2,1.59,0]],"ltp":1.59,"tv":616.17,"id":6374165}]}]}
{"op":"mcm","clk":"1006305639","pt":1580595086515,"mc":[{"id":"1.168175453","rc":[{"batb":[[0,2.42,33.28],[1,1.97,394.86],[2,1.01,15.52]],"ltp":3.35,"tv":72.68,"id":5071877},{"batb":[[0,1.44,92.92],[1,1.34,465.43],[2,1.01,15.51]],"batl":[[0,4,4.23],[1,4,0]],"ltp":1.59,"tv":616.17,"id":6374165}]}]}
{"op":"mcm","clk":"1006305954","pt":1580595088502,"mc":[{"id":"1.168175453","rc":[{"batb":[[0,1.45,616.73],[1,1.44,504.99],[2,1.34,465.43]],"batl":[[0,1.68,350.85],[1,1.7,433.08],[2,4,4.23]],"ltp":1.59,"tv":616.17,"id":6374165}]}]}
{"op":"mcm","clk":"1006306017","pt":1580595089127,"mc":[{"id":"1.168175453","rc":[{"batl":[[0,4,4.23],[1,1.7,0],[2,4,0]],"ltp":1.59,"tv":616.17,"id":6374165}]}]}
{"op":"mcm","clk":"1006306164","pt":1580595090396,"mc":[{"id":"1.168175453","rc":[{"batb":[[1,1.01,15.52],[2,1.01,0]],"ltp":3.35,"tv":72.68,"id":5071877}]}]}
{"op":"mcm","clk":"1006306424","pt":1580595092337,"mc":[{"id":"1.168175453","rc":[{"batb":[[0,2.98,48.31],[1,2.72,24.71],[2,1.01,15.52]],"ltp":3.35,"tv":72.68,"id":5071877},{"batb":[[2,1.39,106.38]],"batl":[[0,1.5,360.83],[1,1.51,331.02],[2,4,4.23]],"ltp":1.59,"tv":616.17,"id":6374165}]}]}
{"op":"mcm","clk":"1006306563","pt":1580595093537,"mc":[{"id":"1.168175453","rc":[{"batb":[[1,2.88,21.85],[2,2.72,24.71]],"batl":[[0,3.35,17.64]],"ltp":3.35,"tv":72.68,"id":5071877},{"batb":[[2,1.43,97.46]],"batl":[[2,1.53,42.01]],"ltp":1.59,"tv":616.17,"id":6374165}]}]}
{"op":"mcm","clk":"1006308062","pt":1580595106532,"mc":[{"id":"1.168175453","rc":[{"batb":[[0,2.72,24.71],[1,2.12,388.65],[2,1.01,15.52]],"ltp":3.35,"tv":72.68,"id":5071877},{"batb":[[0,1.39,106.38],[1,1.34,465.43],[2,1.01,15.51]],"batl":[[0,4,4.23],[1,1.51,0],[2,1.53,0]],"ltp":1.59,"tv":616.17,"id":6374165}]}]}
{"op":"mcm","clk":"1006308367","pt":1580595109152,"mc":[{"id":"1.168175453","rc":[{"batb":[[0,1.42,463.58],[1,1.41,450.94],[2,1.39,106.38]],"batl":[[0,1.57,342.65],[1,1.58,278.86],[2,4,4.23]],"ltp":1.59,"tv":616.17,"id":6374165}]}]}
{"op":"mcm","clk":"1006308694","pt":1580595112034,"mc":[{"id":"1.168175453","rc":[{"batb":[[0,1.5,9.84],[1,1.42,463.58],[2,1.41,450.94]],"ltp":1.59,"tv":616.17,"id":6374165}]}]}
{"op":"mcm","clk":"1006309056","pt":1580595115194,"mc":[{"id":"1.168175453","rc":[{"batl":[[0,4,4.23],[1,1.58,0],[2,4,0]],"ltp":1.59,"tv":616.17,"id":6374165}]}]}
{"op":"mcm","clk":"1006309436","pt":1580595118493,"mc":[{"id":"1.168175453","rc":[{"trd":[[1.5,19.68]],"batb":[[0,1.42,463.58],[1,1.41,450.94],[2,1.39,106.38]],"batl":[[0,1.46,267.99],[1,1.47,369.31],[2,4,4.23]],"ltp":1.5,"tv":635.85,"id":6374165}],"tv":708.54}]}
{"op":"mcm","clk":"1006309572","pt":1580595119505,"mc":[{"id":"1.168175453","rc":[{"batb":[[0,3.2,40.6],[1,3,21],[2,2.98,48.7]],"batl":[[0,3.5,16.8]],"ltp":3.35,"tv":72.68,"id":5071877},{"batb":[[2,1.4,105.02]],"batl":[[2,1.5,9.24]],"ltp":1.5,"tv":635.85,"id":6374165}]}]}
{"op":"mcm","clk":"1006309637","pt":1580595119855,"mc":[{"id":"1.168175453","rc":[{"batl":[[2,4,4.23]],"ltp":1.5,"tv":635.85,"id":6374165}]}]}
{"op":"mcm","clk":"1006309821","pt":1580595121588,"mc":[{"id":"1.168175453","rc":[{"batl":[[2,1.5,42.01]],"ltp":1.5,"tv":635.85,"id":6374165}]}]}
{"op":"mcm","clk":"1006311231","pt":1580595133300,"mc":[{"id":"1.168175453","rc":[{"batb":[[0,3,21],[1,2.98,48.7],[2,2.12,388.65]],"ltp":3.35,"tv":72.68,"id":5071877},{"batb":[[0,1.4,105.02],[1,1.37,114.4],[2,1.28,485.89]],"batl":[[0,1.5,42.01],[1,4,4.23],[2,1.5,0]],"ltp":1.5,"tv":635.85,"id":6374165}]}]}
{"op":"mcm","clk":"1006311474","pt":1580595135181,"mc":[{"id":"1.168175453","rc":[{"batb":[[0,2.98,48.7],[1,2.12,388.65],[2,1.01,15.52]],"ltp":3.35,"tv":72.68,"id":5071877},{"batb":[[0,1.37,114.4],[1,1.28,485.89],[2,1.01,15.51]],"batl":[[0,4,4.23],[1,4,0]],"ltp":1.5,"tv":635.85,"id":6374165}]}]}
{"op":"mcm","clk":"1006311682","pt":1580595136935,"mc":[{"id":"1.168175453","rc":[{"batb":[[0,1.4,647.76],[1,1.39,483.2],[2,1.37,114.4]],"batl":[[0,1.5,454.46],[1,1.51,330.46],[2,4,4.23]],"ltp":1.5,"tv":635.85,"id":6374165}]}]}
{"op":"mcm","clk":"1006311983","pt":1580595139493,"mc":[{"id":"1.168175453","rc":[{"batl":[[0,4,4.23],[1,1.51,0],[2,4,0]],"ltp":1.5,"tv":635.85,"id":6374165}]}]}
{"op":"mcm","clk":"1006312339","pt":1580595142416,"mc":[{"id":"1.168175453","rc":[{"batl":[[0,1.45,582.31],[1,1.46,377.21],[2,4,4.23]],"ltp":1.5,"tv":635.85,"id":6374165}]}]}
{"op":"mcm","clk":"1006312469","pt":1580595143517,"mc":[{"id":"1.168175453","rc":[{"batb":[[0,3.3,36.9],[1,3.15,19.32],[2,2.98,48.7]],"batl":[[0,3.65,15.12]],"ltp":3.35,"tv":72.68,"id":5071877},{"batb":[[2,1.38,110.07]],"batl":[[2,1.47,42.01]],"ltp":1.5,"tv":635.85,"id":6374165}]}]}
{"op":"mcm","clk":"1006313610","pt":1580595153296,"mc":[{"id":"1.168175453","rc":[{"batb":[[2,2.96,49.1]],"ltp":3.35,"tv":72.68,"id":5071877}]}]}
{"op":"mcm","clk":"1006314528","pt":1580595161336,"mc":[{"id":"1.168175453","rc":[{"batb":[[2,2.94,49.96]],"ltp":3.35,"tv":72.68,"id":5071877}]}]}
{"op":"mcm","clk":"1006315464","pt":1580595168729,"mc":[{"id":"1.168175453","rc":[{"trd":[[3.3,0.99]],"batb":[[0,3.3,35.91]],"ltp":3.3,"tv":73.67,"id":5071877},{"trd":[[1.44,2.27]],"ltp":1.44,"tv":638.13,"id":6374165}],"tv":711.81}]}
{"op":"mcm","clk":"1006315782","pt":1580595171554,"mc":[{"id":"1.168175453","rc":[{"batb":[[1,3.25,38.16],[2,3.15,19.32]],"ltp":3.3,"tv":73.67,"id":5071877},{"batb":[[2,1.38,221.56]],"ltp":1.44,"tv":638.13,"id":6374165}]}]}
{"op":"mcm","clk":"1006315839","pt":1580595172033,"mc":[{"id":"1.168175453","rc":[{"batb":[[0,3.25,38.16],[1,3.15,19.32],[2,2.94,49.96]],"ltp":3.3,"tv":73.67,"id":5071877}]}]}
{"op":"mcm","clk":"1006316787","pt":1580595179930,"mc":[{"id":"1.168175453","rc":[{"batb":[[2,2.92,50.75]],"ltp":3.3,"tv":73.67,"id":5071877}]}]}
{"op":"mcm","clk":"1006318615","pt":1580595196646,"mc":[{"id":"1.168175453","rc":[{"trd":[[1.4,88.43]],"batb":[[0,1.4,603.53]],"ltp":1.4,"tv":726.56,"id":6374165}],"tv":800.24}]}
{"op":"mcm","clk":"1006321220","pt":1580595220467,"mc":[{"id":"1.168175453","rc":[{"batb":[[2,1.38,111.49]],"ltp":1.4,"tv":726.56,"id":6374165}]}]}
{"op":"mcm","clk":"1006321881","pt":1580595226194,"mc":[{"id":"1.168175453","rc":[{"trd":[[3.25,30.29]],"batb":[[0,3.15,19.32],[1,2.92,50.75],[2,2.12,388.65]],"ltp":3.25,"tv":103.96,"id":5071877},{"batb":[[0,1.37,113.43],[1,1.29,152.49],[2,1.28,485.89]],"batl":[[0,1.47,42.01],[1,4,4.23],[2,1.47,0]],"ltp":1.4,"tv":726.56,"id":6374165}],"tv":830.53}]}
{"op":"mcm","clk":"1006321997","pt":1580595227213,"mc":[{"id":"1.168175453","rc":[{"batb":[[0,2.92,50.75],[1,2.12,388.65],[2,1.01,15.52]],"ltp":3.25,"tv":103.96,"id":5071877},{"batb":[[0,1.29,152.49],[1,1.28,485.89],[2,1.01,15.51]],"batl":[[0,4,4.23],[1,4,0]],"ltp":1.4,"tv":726.56,"id":6374165}]}]}
{"op":"mcm","clk":"1006322215","pt":1580595229094,"mc":[{"id":"1.168175453","rc":[{"batb":[[0,1.31,884.35],[1,1.3,679.17],[2,1.29,152.49]],"batl":[[0,1.52,358.52],[1,1.53,314.72],[2,4,4.23]],"ltp":1.4,"tv":726.56,"id":6374165}]}]}
{"op":"mcm","clk":"1006322365","pt":1580595230511,"mc":[{"id":"1.168175453","rc":[{"batl":[[0,4,4.23],[1,1.53,0],[2,4,0]],"ltp":1.4,"tv":726.56,"id":6374165}]}]}
{"op":"mcm","clk":"1006322415","pt":1580595230881,"mc":[{"id":"1.168175453","rc":[{"batb":[[1,1.01,15.52],[2,1.01,0]],"ltp":3.25,"tv":103.96,"id":5071877}]}]}
{"op":"mcm","clk":"1006322704","pt":1580595233493,"mc":[{"id":"1.168175453","rc":[{"batl":[[0,1.35,518.76],[1,1.36,516.66],[2,1.37,220.97]],"ltp":1.4,"tv":726.56,"id":6374165}]}]}
{"op":"mcm","clk":"1006322813","pt":1580595234481,"mc":[{"id":"1.168175453","rc":[{"batb":[[0,3.85,51.22],[1,3.35,35.96],[2,1.01,15.52]],"batl":[[0,4.3,12.6]],"ltp":3.25,"tv":103.96,"id":5071877},{"batb":[[1,1.3,969.55],[2,1.21,226.84]],"ltp":1.4,"tv":726.56,"id":6374165}]}]}
{"op":"mcm","clk":"1006322894","pt":1580595235123,"mc":[{"id":"1.168175453","rc":[{"batb":[[2,2.42,381.73]],"ltp":3.25,"tv":103.96,"id":5071877},{"batb":[[2,1.22,523]],"ltp":1.4,"tv":726.56,"id":6374165}]}]}
{"op":"mcm","clk":"1006323028","pt":1580595236224,"mc":[{"id":"1.168175453","rc":[{"batb":[[1,3.65,15.12],[2,3.35,35.96]],"ltp":3.25,"tv":103.96,"id":5071877},{"batl":[[2,1.38,42.01]],"ltp":1.4,"tv":726.56,"id":6374165}]}]}
{"op":"mcm","clk":"1006324867","pt":1580595252334,"mc":[{"id":"1.168175453","rc":[{"batb":[[0,3.65,15.12],[1,3.35,35.96],[2,2.42,381.73]],"ltp":3.25,"tv":103.96,"id":5071877},{"batb":[[0,1.3,139.47],[1,1.22,523],[2,1.21,226.84]],"batl":[[0,1.38,42.01],[1,4,4.23],[2,1.38,0]],"ltp":1.4,"tv":726.56,"id":6374165}]}]}
{"op":"mcm","clk":"1006325004","pt":1580595253543,"mc":[{"id":"1.168175453","rc":[{"batb":[[0,3.35,35.96],[1,2.42,381.73],[2,1.01,15.52]],"ltp":3.25,"tv":103.96,"id":5071877},{"batb":[[0,1.22,523],[1,1.21,226.84],[2,1.01,15.51]],"batl":[[0,4,4.23],[1,4,0]],"ltp":1.4,"tv":726.56,"id":6374165}]}]}
{"op":"mcm","clk":"1006325379","pt":1580595256393,"mc":[{"id":"1.168175453","rc":[{"batb":[[0,1.3,296.42],[1,1.29,697.98],[2,1.22,523]],"batl":[[0,1.33,585.56],[1,1.34,553.81],[2,4,4.23]],"ltp":1.4,"tv":726.56,"id":6374165}]}]}
{"op":"mcm","clk":"1006326209","pt":1580595263325,"mc":[{"id":"1.168175453","rc":[{"batb":[[0,1.22,523],[1,1.21,226.84],[2,1.01,15.51]],"batl":[[0,4,4.23],[1,1.34,0],[2,4,0]],"ltp":1.4,"tv":726.56,"id":6374165}]}]}
{"op":"mcm","clk":"1006326585","pt":1580595266746,"mc":[{"id":"1.168175453","rc":[{"batb":[[0,1.22,1687.63],[1,1.21,1170.86]],"batl":[[0,1.43,446.38],[1,1.44,401.01],[2,4,4.23]],"ltp":1.4,"tv":726.56,"id":6374165}]}]}
{"op":"mcm","clk":"1006327091","pt":1580595271331,"mc":[{"id":"1.168175453","rc":[{"batb":[[0,1.22,523],[1,1.21,226.84]],"ltp":1.4,"tv":726.56,"id":6374165}]}]}
{"op":"mcm","clk":"1006327161","pt":1580595271910,"mc":[{"id":"1.168175453","rc":[{"batb":[[0,1.21,226.84],[1,1.01,15.51],[2,1.01,0]],"ltp":1.4,"tv":726.56,"id":6374165}]}]}
{"op":"mcm","clk":"1006327387","pt":1580595273542,"mc":[{"id":"1.168175453","rc":[{"batb":[[0,1.39,426.75],[1,1.38,497.55],[2,1.21,226.84]],"ltp":1.4,"tv":726.56,"id":6374165}]}]}
{"op":"mcm","clk":"1006327469","pt":1580595274328,"mc":[{"id":"1.168175453","rc":[{"batb":[[1,3.25,18.48],[2,2.92,51.14]],"batl":[[0,3.8,14.28]],"ltp":3.25,"tv":103.96,"id":5071877},{"batb":[[2,1.37,116.69]],"batl":[[2,1.45,42.01]],"ltp":1.4,"tv":726.56,"id":6374165}]}]}
{"op":"mcm","clk":"1006328037","pt":1580595279520,"mc":[{"id":"1.168175453","rc":[{"batl":[[0,1.43,318.03]],"ltp":1.4,"tv":726.56,"id":6374165}]}]}
{"op":"mcm","clk":"1006328356","pt":1580595282462,"mc":[{"id":"1.168175453","rc":[{"batb":[[0,1.39,559.08]],"ltp":1.4,"tv":726.56,"id":6374165}]}]}
{"op":"mcm","clk":"1006329659","pt":1580595294288,"mc":[{"id":"1.168175453","rc":[{"batb":[[0,3.25,18.48],[1,2.92,51.14],[2,2.42,381.73]],"ltp":3.25,"tv":103.96,"id":5071877},{"batb":[[0,1.36,115.95],[1,1.27,170.43],[2,1.25,505.09]],"batl":[[0,1.45,42.01],[1,4,4.23],[2,1.45,0]],"ltp":1.4,"tv":726.56,"id":6374165}]}]}
{"op":"mcm","clk":"1006329702","pt":1580595294664,"mc":[{"id":"1.168175453","rc":[{"batb":[[0,2.92,51.14],[1,2.42,381.73],[2,1.01,15.52]],"ltp":3.25,"tv":103.96,"id":5071877},{"batb":[[0,1.27,170.43],[1,1.25,505.09],[2,1.01,15.51]],"batl":[[0,4,4.23],[1,4,0]],"ltp":1.4,"tv":726.56,"id":6374165}]}]}
{"op":"mcm","clk":"1006329967","pt":1580595297089,"mc":[{"id":"1.168175453","rc":[{"batb":[[0,1.29,539.1],[1,1.28,731.23],[2,1.27,170.43]],"batl":[[0,1.52,297.75],[1,1.53,314.27],[2,4,4.23]],"ltp":1.4,"tv":726.56,"id":6374165}]}]}
{"op":"mcm","clk":"1006330619","pt":1580595302458,"mc":[{"id":"1.168175453","rc":[{"batl":[[0,4,4.23],[1,1.53,0],[2,4,0]],"ltp":1.4,"tv":726.56,"id":6374165}]}]}
{"op":"mcm","clk":"1006330949","pt":1580595305385,"mc":[{"id":"1.168175453","rc":[{"batb":[[0,4.1,43.04],[1,3.4,34.23],[2,2.42,381.73]],"ltp":3.25,"tv":103.96,"id":5071877},{"batl":[[0,1.32,420.27],[1,1.33,575.37],[2,4,4.23]],"ltp":1.4,"tv":726.56,"id":6374165}]}]}
{"op":"mcm","clk":"1006331025","pt":1580595305963,"mc":[{"id":"1.168175453","rc":[{"batl":[[0,4.6,10.92]],"ltp":3.25,"tv":103.96,"id":5071877},{"batb":[[2,1.27,325.86]],"ltp":1.4,"tv":726.56,"id":6374165}]}]}
{"op":"mcm","clk":"1006332877","pt":1580595322227,"mc":[{"id":"1.168175453","rc":[{"batb":[[0,3.4,34.23],[1,2.42,381.73],[2,1.01,15.52]],"ltp":3.25,"tv":103.96,"id":5071877},{"batb":[[0,1.27,155.44],[1,1.2,530.86],[2,1.17,279.4]],"batl":[[0,4,4.23],[1,1.33,0],[2,4,0]],"ltp":1.4,"tv":726.56,"id":6374165}]}]}
{"op":"mcm","clk":"1006332942","pt":1580595322704,"mc":[{"id":"1.168175453","rc":[{"batb":[[0,1.2,530.86],[1,1.17,279.4],[2,1.01,15.51]],"ltp":1.4,"tv":726.56,"id":6374165}]}]}
{"op":"mcm","clk":"1006333247","pt":1580595325350,"mc":[{"id":"1.168175453","rc":[{"batb":[[0,3.45,33.75]],"ltp":3.25,"tv":103.96,"id":5071877},{"batb":[[1,1.18,1433.04],[2,1.17,1024.81]],"batl":[[0,1.42,554.3],[1,1.43,410.8],[2,4,4.23]],"ltp":1.4,"tv":726.56,"id":6374165}]}]}
{"op":"mcm","clk":"1006334537","pt":1580595337447,"mc":[{"id":"1.168175453","rc":[{"batb":[[1,1.17,279.4],[2,1.01,15.51]],"ltp":1.4,"tv":726.56,"id":6374165}]}]}
{"op":"mcm","clk":"1006334611","pt":1580595338133,"mc":[{"id":"1.168175453","rc":[{"batb":[[0,1.17,279.4],[1,1.01,15.51],[2,1.01,0]],"ltp":1.4,"tv":726.56,"id":6374165}]}]}
{"op":"mcm","clk":"1006334777","pt":1580595339545,"mc":[{"id":"1.168175453","rc":[{"batb":[[0,1.38,358.59],[1,1.37,512.73],[2,1.17,279.4]],"ltp":1.4,"tv":726.56,"id":6374165}]}]}
{"op":"mcm","clk":"1006334879","pt":1580595340491,"mc":[{"id":"1.168175453","rc":[{"batb":[[1,3.35,17.64],[2,2.9,52.32]],"batl":[[0,3.9,14.28]],"ltp":3.25,"tv":103.96,"id":5071877},{"batb":[[2,1.36,122.19]],"batl":[[1,1.43,452.81]],"ltp":1.4,"tv":726.56,"id":6374165}]}]}
{"op":"mcm","clk":"1006337885","pt":1580595366358,"mc":[{"id":"1.168175453","rc":[{"batb":[[0,3.35,17.64],[1,2.9,52.32],[2,2.42,381.73]],"ltp":3.25,"tv":103.96,"id":5071877},{"batb":[[0,1.34,123.51],[1,1.25,505.09],[2,1.23,201.74]],"batl":[[0,1.43,42.01],[1,4,4.23],[2,4,0]],"ltp":1.4,"tv":726.56,"id":6374165}]}]}
{"op":"mcm","clk":"1006337964","pt":1580595366942,"mc":[{"id":"1.168175453","rc":[{"batb":[[0,2.9,52.32],[1,2.42,381.73],[2,1.01,15.52]],"ltp":3.25,"tv":103.96,"id":5071877},{"batb":[[0,1.25,505.09],[1,1.23,201.74],[2,1.01,15.51]],"batl":[[0,4,4.23],[1,4,0]],"ltp":1.4,"tv":726.56,"id":6374165}]}]}
{"op":"mcm","clk":"1006338213","pt":1580595368974,"mc":[{"id":"1.168175453","rc":[{"batb":[[0,1.25,1020.4],[1,1.24,882.57],[2,1.23,201.74]],"batl":[[0,1.54,532.09],[1,1.55,297.97],[2,4,4.23]],"ltp":1.4,"tv":726.56,"id":6374165}]}]}
{"op":"mcm","clk":"1006339368","pt":1580595378563,"mc":[{"id":"1.168175453","rc":[{"batl":[[0,4,4.23],[1,1.55,0],[2,4,0]],"ltp":1.4,"tv":726.56,"id":6374165}]}]}
{"op":"mcm","clk":"1006339447","pt":1580595379293,"mc":[{"id":"1.168175453","rc":[{"batb":[[1,1.01,15.52],[2,1.01,0]],"ltp":3.25,"tv":103.96,"id":5071877},{"batb":[[0,1.25,515.31]],"ltp":1.4,"tv":726.56,"id":6374165}]}]}
{"op":"mcm","clk":"1006339752","pt":1580595381559,"mc":[{"id":"1.168175453","rc":[{"batb":[[0,4.6,33.68],[1,3.5,32.42],[2,1.01,15.52]],"ltp":3.25,"tv":103.96,"id":5071877},{"batl":[[0,1.28,763.1],[1,1.29,667.9],[2,4,4.23]],"ltp":1.4,"tv":726.56,"id":6374165}]}]}
{"op":"mcm","clk":"1006339859","pt":1580595382346,"mc":[{"id":"1.168175453","rc":[{"batb":[[1,4.3,12.6],[2,3.5,32.42]],"batl":[[0,5.2,9.24]],"ltp":3.25,"tv":103.96,"id":5071877},{"batb":[[2,1.23,369.78]],"batl":[[2,1.3,42.01]],"ltp":1.4,"tv":726.56,"id":6374165}]}]}
{"op":"mcm","clk":"1006343006","pt":1580595407003,"mc":[{"id":"1.168175453","rc":[{"batb":[[0,4.3,12.6],[1,3.5,32.42],[2,2.72,378.25]],"ltp":3.25,"tv":103.96,"id":5071877},{"batb":[[0,1.23,168.04],[1,1.16,576.13],[2,1.11,452.81]],"batl":[[0,1.3,42.01],[1,4,4.23],[2,1.3,0]],"ltp":1.4,"tv":726.56,"id":6374165}]}]}
{"op":"mcm","clk":"1006343223","pt":1580595408371,"mc":[{"id":"1.168175453","rc":[{"batb":[[2,1.01,15.52]],"ltp":3.25,"tv":103.96,"id":5071877},{"batb":[[1,1.11,452.81],[2,1.01,15.51]],"ltp":1.4,"tv":726.56,"id":6374165}]}]}
{"op":"mcm","clk":"1006343311","pt":1580595409000,"mc":[{"id":"1.168175453","rc":[{"batb":[[0,3.5,32.42],[1,1.01,15.52],[2,1.01,0]],"ltp":3.25,"tv":103.96,"id":5071877},{"batb":[[0,1.11,452.81],[1,1.01,15.51],[2,1.01,0]],"batl":[[0,4,4.23],[1,4,0]],"ltp":1.4,"tv":726.56,"id":6374165}]}]}
{"op":"mcm","clk":"1006343460","pt":1580595410108,"mc":[{"id":"1.168175453","rc":[{"batb":[[0,1.11,1871.35],[1,1.1,898.67],[2,1.01,15.51]],"batl":[[0,1.41,359.05],[1,1.42,425.74],[2,4,4.23]],"ltp":1.4,"tv":726.56,"id":6374165}]}]}
{"op":"mcm","clk":"1006344032","pt":1580595413988,"mc":[{"id":"1.168175453","rc":[{"batb":[[0,1.11,452.81],[1,1.01,15.51],[2,1.01,0]],"batl":[[0,4,4.23],[1,1.42,0],[2,4,0]],"ltp":1.4,"tv":726.56,"id":6374165}]}]}
{"op":"mcm","clk":"1006344428","pt":1580595416726,"mc":[{"id":"1.168175453","rc":[{"batb":[[0,1.22,538.33],[1,1.21,1035.93],[2,1.11,452.81]],"batl":[[0,1.25,1057.5],[1,1.26,754.58],[2,4,4.23]],"ltp":1.4,"tv":726.56,"id":6374165}]}]}
{"op":"mcm","clk":"1006345350","pt":1580595423717,"mc":[{"id":"1.168175453","rc":[{"batb":[[0,1.11,452.81],[1,1.01,15.51],[2,1.11,0]],"batl":[[0,4,4.23],[1,1.26,0],[2,4,0]],"ltp":1.4,"tv":726.56,"id":6374165}]}]}
{"op":"mcm","clk":"1006345877","pt":1580595427345,"mc":[{"id":"1.168175453","rc":[{"batb":[[0,1.11,1871.35],[1,1.1,898.67],[2,1.01,15.51]],"batl":[[0,1.41,359.05],[1,1.42,425.74],[2,4,4.23]],"ltp":1.4,"tv":726.56,"id":6374165}]}]}
{"op":"mcm","clk":"1006346723","pt":1580595433542,"mc":[{"id":"1.168175453","rc":[{"batb":[[0,1.11,452.81],[1,1.01,15.51],[2,1.01,0]],"ltp":1.4,"tv":726.56,"id":6374165}]}]}
{"op":"mcm","clk":"1006347125","pt":1580595436518,"mc":[{"id":"1.168175453","rc":[{"batb":[[0,1.37,626.31],[1,1.36,534.75],[2,1.11,452.81]],"ltp":1.4,"tv":726.56,"id":6374165}]}]}
{"op":"mcm","clk":"1006347249","pt":1580595437559,"mc":[{"id":"1.168175453","rc":[{"batb":[[1,2.94,50.59],[2,1.01,15.52]],"ltp":3.25,"tv":103.96,"id":5071877},{"batb":[[2,1.35,125.97]],"ltp":1.4,"tv":726.56,"id":6374165}]}]}
{"op":"mcm","clk":"1006347432","pt":1580595439017,"mc":[{"id":"1.168175453","rc":[{"batb":[[2,2.3,385.09]],"ltp":3.25,"tv":103.96,"id":5071877}]}]}
{"op":"mcm","clk":"1006347600","pt":1580595440533,"mc":[{"id":"1.168175453","rc":[{"batb":[[1,3.35,17.64],[2,2.94,50.59]],"ltp":3.25,"tv":103.96,"id":5071877},{"batl":[[2,1.43,42.01]],"ltp":1.4,"tv":726.56,"id":6374165}]}]}
{"op":"mcm","clk":"1006349446","pt":1580595456260,"mc":[{"id":"1.168175453","rc":[{"batb":[[0,3.35,17.64],[1,2.94,50.59],[2,2.3,385.09]],"ltp":3.25,"tv":103.96,"id":5071877},{"batb":[[0,1.25,505.09],[1,1.23,207.96],[2,1.01,15.51]],"batl":[[0,1.43,42.01],[1,4,4.23],[2,1.43,0]],"ltp":1.4,"tv":726.56,"id":6374165}]}]}
{"op":"mcm","clk":"1006349586","pt":1580595457460,"mc":[{"id":"1.168175453","rc":[{"batb":[[0,2.94,50.59],[1,2.3,385.09],[2,1.01,15.52]],"ltp":3.25,"tv":103.96,"id":5071877},{"batl":[[0,4,4.23],[1,4,0]],"ltp":1.4,"tv":726.56,"id":6374165}]}]}
{"op":"mcm","clk":"1006349828","pt":1580595459537,"mc":[{"id":"1.168175453","rc":[{"batb":[[1,1.24,1185.07],[2,1.23,1097.08]],"ltp":1.4,"tv":726.56,"id":6374165}]}]}
{"op":"mcm","clk":"1006349936","pt":1580595460534,"mc":[{"id":"1.168175453","rc":[{"batb":[[1,1.01,15.52],[2,1.01,0]],"ltp":3.25,"tv":103.96,"id":5071877},{"batb":[[0,1.24,1185.07],[1,1.23,1097.08],[2,1.01,15.51]],"ltp":1.4,"tv":726.56,"id":6374165}]}]}
{"op":"mcm","clk":"1006350190","pt":1580595462472,"mc":[{"id":"1.168175453","rc":[{"batl":[[0,1.28,953.55],[1,1.29,663.66],[2,4,4.23]],"ltp":1.4,"tv":726.56,"id":6374165}]}]}
{"op":"mcm","clk":"1006350311","pt":1580595463476,"mc":[{"id":"1.168175453","rc":[{"batb":[[0,4.7,32.18],[1,3.55,31.63],[2,1.01,15.52]],"ltp":3.25,"tv":103.96,"id":5071877},{"batb":[[2,1.11,460.13]],"ltp":1.4,"tv":726.56,"id":6374165}]}]}
{"op":"mcm","clk":"1006350430","pt":1580595464370,"mc":[{"id":"1.168175453","rc":[{"batb":[[2,2.72,378.25]],"batl":[[0,5.3,9.24]],"ltp":3.25,"tv":103.96,"id":5071877},{"batb":[[1,1.23,1265.12],[2,1.16,576.13]],"batl":[[2,1.3,42.01]],"ltp":1.4,"tv":726.56,"id":6374165}]}]}
{"op":"mcm","clk":"1006350543","pt":1580595465260,"mc":[{"id":"1.168175453","rc":[{"batb":[[1,4.4,11.76],[2,3.55,31.63]],"ltp":3.25,"tv":103.96,"id":5071877}]}]}
{"op":"mcm","clk":"1006352123","pt":1580595478492,"mc":[{"id":"1.168175453","rc":[{"batb":[[0,1.24,1034.77]],"batl":[[0,1.28,707.16],[1,1.3,42.01],[2,4,4.23]],"ltp":1.4,"tv":726.56,"id":6374165}]}]}
{"op":"mcm","clk":"1006352424","pt":1580595481071,"mc":[{"id":"1.168175453","rc":[{"batl":[[0,1.27,394.94],[1,1.28,707.16],[2,1.3,42.01]],"ltp":1.4,"tv":726.56,"id":6374165}]}]}
{"op":"mcm","clk":"1006352721","pt":1580595483390,"mc":[{"id":"1.168175453","rc":[{"batb":[[0,4.4,11.76],[1,3.55,31.63],[2,2.72,378.25]],"ltp":3.25,"tv":103.96,"id":5071877},{"batb":[[0,1.23,168.04],[1,1.16,576.13],[2,1.11,460.13]],"batl":[[0,1.3,42.01],[1,4,4.23],[2,1.3,0]],"ltp":1.4,"tv":726.56,"id":6374165}]}]}
{"op":"mcm","clk":"1006352890","pt":1580595484805,"mc":[{"id":"1.168175453","rc":[{"batb":[[0,3.55,31.63],[1,1.01,15.52],[2,2.72,0]],"ltp":3.25,"tv":103.96,"id":5071877},{"batb":[[0,1.11,460.13],[1,1.01,15.51],[2,1.11,0]],"batl":[[0,4,4.23],[1,4,0]],"ltp":1.4,"tv":726.56,"id":6374165}]}]}
{"op":"mcm","clk":"1006353114","pt":1580595486567,"mc":[{"id":"1.168175453","rc":[{"batl":[[0,1.41,660.14],[1,1.42,424.03],[2,4,4.23]],"ltp":1.4,"tv":726.56,"id":6374165}]}]}
{"op":"mcm","clk":"1006353614","pt":1580595490511,"mc":[{"id":"1.168175453","rc":[{"batb":[[1,2.96,49.88],[2,1.01,15.52]],"ltp":3.25,"tv":103.96,"id":5071877},{"batb":[[0,1.37,308.45],[1,1.36,532.5],[2,1.34,128.25]],"batl":[[1,1.42,466.04]],"ltp":1.4,"tv":726.56,"id":6374165}]}]}
{"op":"mcm","clk":"1006353856","pt":1580595492501,"mc":[{"id":"1.168175453","rc":[{"batb":[[1,3.35,17.64],[2,2.96,49.88]],"batl":[[0,3.95,13.44]],"ltp":3.25,"tv":103.96,"id":5071877},{"batb":[[2,1.34,251.76]],"ltp":1.4,"tv":726.56,"id":6374165}]}]}
{"op":"mcm","clk":"1006355318","pt":1580595505333,"mc":[{"id":"1.168175453","rc":[{"batb":[[0,3.35,17.64],[1,2.96,49.88],[2,2.38,382.3]],"ltp":3.25,"tv":103.96,"id":5071877},{"batb":[[0,1.34,123.51],[1,1.23,516.48],[2,1.22,212.28]],"batl":[[0,1.42,42.01],[1,4,4.23],[2,4,0]],"ltp":1.4,"tv":726.56,"id":6374165}]}]}
{"op":"mcm","clk":"1006355553","pt":1580595507432,"mc":[{"id":"1.168175453","rc":[{"batb":[[0,2.96,49.88],[1,2.38,382.3],[2,1.01,15.52]],"ltp":3.25,"tv":103.96,"id":5071877},{"batb":[[0,1.23,516.48],[1,1.22,212.28],[2,1.01,15.51]],"batl":[[0,4,4.23],[1,4,0]],"ltp":1.4,"tv":726.56,"id":6374165}]}]}
{"op":"mcm","clk":"1006355686","pt":1580595508545,"mc":[{"id":"1.168175453","rc":[{"batb":[[0,1.24,782.28],[1,1.23,1455.98],[2,1.22,212.28]],"batl":[[0,1.52,349.76],[1,1.53,315.2],[2,4,4.23]],"ltp":1.4,"tv":726.56,"id":6374165}]}]}
{"op":"mcm","clk":"1006355785","pt":1580595509430,"mc":[{"id":"1.168175453","rc":[{"batb":[[0,1.23,516.48],[1,1.22,212.28],[2,1.01,15.51]],"ltp":1.4,"tv":726.56,"id":6374165}]}]}
{"op":"mcm","clk":"1006356030","pt":1580595511540,"mc":[{"id":"1.168175453","rc":[{"batb":[[0,1.22,212.28],[1,1.01,15.51],[2,1.01,0]],"ltp":1.4,"tv":726.56,"id":6374165}]}]}
{"op":"mcm","clk":"1006356149","pt":1580595512439,"mc":[{"id":"1.168175453","rc":[{"batb":[[1,2.92,21.85],[2,2.62,27.22]],"ltp":3.25,"tv":103.96,"id":5071877},{"batb":[[0,1.47,541.97],[1,1.46,388.54],[2,1.45,90.64]],"batl":[[1,1.53,357.21]],"ltp":1.4,"tv":726.56,"id":6374165}]}]}
{"op":"mcm","clk":"1006357496","pt":1580595523492,"mc":[{"id":"1.168175453","rc":[{"batb":[[1,2.62,27.22],[2,2.38,382.3]],"ltp":3.25,"tv":103.96,"id":5071877}]}]}
{"op":"mcm","clk":"1006357581","pt":1580595524178,"mc":[{"id":"1.168175453","rc":[{"batl":[[1,1.53,315.2]],"ltp":1.4,"tv":726.56,"id":6374165}]}]}
{"op":"mcm","clk":"1006357868","pt":1580595526553,"mc":[{"id":"1.168175453","rc":[{"trd":[[1.47,4.54]],"batb":[[0,1.47,539.7]],"ltp":1.47,"tv":731.1,"id":6374165}],"tv":835.07}]}
{"op":"mcm","clk":"1006357935","pt":1580595527178,"mc":[{"id":"1.168175453","rc":[{"batb":[[0,2.62,27.22],[1,2.38,382.3],[2,1.01,15.52]],"ltp":3.25,"tv":103.96,"id":5071877},{"batb":[[0,1.33,132.89],[1,1.31,477.51],[2,1.01,15.51]],"batl":[[0,4,4.23],[1,1.53,0],[2,4,0]],"ltp":1.47,"tv":731.1,"id":6374165}]}]}
{"op":"mcm","clk":"1006358539","pt":1580595532147,"mc":[{"id":"1.168175453","rc":[{"batb":[[1,1.01,15.52],[2,1.01,0]],"ltp":3.25,"tv":103.96,"id":5071877},{"batb":[[1,1.01,15.51],[2,1.01,0]],"ltp":1.47,"tv":731.1,"id":6374165}]}]}
{"op":"mcm","clk":"1006358684","pt":1580595533510,"mc":[{"id":"1.168175453","rc":[{"batb":[[0,1.56,446.52],[1,1.55,304.48],[2,1.33,132.89]],"batl":[[0,1.62,398.17],[1,1.63,249.37],[2,4,4.23]],"ltp":1.47,"tv":731.1,"id":6374165}]}]}
{"op":"mcm","clk":"1006358802","pt":1580595534370,"mc":[{"id":"1.168175453","rc":[{"batb":[[1,2.24,41.15],[2,1.01,15.52]],"ltp":3.25,"tv":103.96,"id":5071877},{"batb":[[1,1.55,374.19],[2,1.47,86.39]],"batl":[[1,1.63,291.38]],"ltp":1.47,"tv":731.1,"id":6374165}]}]}
{"op":"mcm","clk":"1006358903","pt":1580595535165,"mc":[{"id":"1.168175453","rc":[{"batb":[[2,1.97,394.86]],"ltp":3.25,"tv":103.96,"id":5071877}]}]}
{"op":"mcm","clk":"1006359034","pt":1580595536277,"mc":[{"id":"1.168175453","rc":[{"batb":[[1,2.58,26.05],[2,2.24,41.15]],"batl":[[0,2.94,21]],"ltp":3.25,"tv":103.96,"id":5071877}]}]}
{"op":"mcm","clk":"1006359275","pt":1580595538264,"mc":[{"id":"1.168175453","rc":[{"batb":[[2,1.51,82.34]],"ltp":1.47,"tv":731.1,"id":6374165}]}]}
{"op":"mcm","clk":"1006361173","pt":1580595553523,"mc":[{"id":"1.168175453","rc":[{"batl":[[1,2.96,707.2]],"ltp":3.25,"tv":103.96,"id":5071877}]}]}
{"op":"mcm","clk":"1006361372","pt":1580595555195,"mc":[{"id":"1.168175453","rc":[{"trd":[[1.56,338.77]],"batb":[[0,1.56,411.36]],"ltp":1.56,"tv":801.41,"id":6374165}],"tv":905.38}]}
{"op":"mcm","clk":"1006362621","pt":1580595566028,"mc":[{"id":"1.168175453","rc":[{"trd":[[1.56,342.31]],"batb":[[0,1.56,409.59]],"ltp":1.56,"tv":804.95,"id":6374165}],"tv":908.92}]}
{"op":"mcm","clk":"1006362818","pt":1580595567544,"mc":[{"id":"1.168175453","rc":[{"batb":[[0,2.58,26.05],[1,2.24,41.15],[2,1.97,394.86]],"ltp":3.25,"tv":103.96,"id":5071877},{"batb":[[0,1.51,82.34],[1,1.47,86.39],[2,1.38,448.45]],"batl":[[0,1.63,42.01],[1,4,4.23],[2,4,0]],"ltp":1.56,"tv":804.95,"id":6374165}]}]}
{"op":"mcm","clk":"1006363046","pt":1580595569214,"mc":[{"id":"1.168175453","rc":[{"batb":[[0,2.24,41.15],[1,1.97,394.86],[2,1.01,15.52]],"batl":[[0,2.96,707.2],[1,2.96,0]],"ltp":3.25,"tv":103.96,"id":5071877},{"batb":[[0,1.47,86.39],[1,1.38,448.45],[2,1.01,15.51]],"batl":[[0,1.56,3.03]],"ltp":1.56,"tv":804.95,"id":6374165}]}]}
{"op":"mcm","clk":"1006363303","pt":1580595571403,"mc":[{"id":"1.168175453","rc":[{"trd":[[1.56,348.37]],"batb":[[0,1.59,424.88],[1,1.58,282.9],[2,1.47,86.39]],"batl":[[0,1.65,324.33],[1,1.66,234.21],[2,4,4.23]],"ltp":1.56,"tv":811.01,"id":6374165}],"tv":914.98}]}
{"op":"mcm","clk":"1006363662","pt":1580595574745,"mc":[{"id":"1.168175453","rc":[{"batb":[[0,1.47,86.39],[1,1.38,448.45],[2,1.01,15.51]],"batl":[[0,4,4.23],[1,1.66,0],[2,4,0]],"ltp":1.56,"tv":811.01,"id":6374165}]}]}
{"op":"mcm","clk":"1006363975","pt":1580595577635,"mc":[{"id":"1.168175453","rc":[{"batb":[[0,1.48,488.06],[1,1.47,463.78],[2,1.38,448.45]],"batl":[[0,1.8,356.02],[1,1.82,346.85],[2,4,4.23]],"ltp":1.56,"tv":811.01,"id":6374165}]}]}
{"op":"mcm","clk":"1006364954","pt":1580595586318,"mc":[{"id":"1.168175453","rc":[{"batl":[[0,4,4.23],[1,1.82,0],[2,4,0]],"ltp":1.56,"tv":811.01,"id":6374165}]}]}
{"op":"mcm","clk":"1006365162","pt":1580595588034,"mc":[{"id":"1.168175453","rc":[{"batb":[[1,1.01,15.52],[2,1.01,0]],"ltp":3.25,"tv":103.96,"id":5071877},{"batb":[[2,1.01,15.51]],"ltp":1.56,"tv":811.01,"id":6374165}]}]}
{"op":"mcm","clk":"1006365319","pt":1580595589530,"mc":[{"id":"1.168175453","rc":[{"batb":[[0,2.88,21.24],[1,2.52,30.21],[2,2.24,41.15]],"ltp":3.25,"tv":103.96,"id":5071877},{"batb":[[2,1.41,103.7]],"batl":[[0,1.53,362.26],[1,1.54,307.58],[2,4,4.23]],"ltp":1.56,"tv":811.01,"id":6374165}]}]}
{"op":"mcm","clk":"1006365344","pt":1580595589744,"mc":[{"id":"1.168175453","rc":[{"batb":[[1,2.76,23.53],[2,2.52,30.21]],"batl":[[1,3.2,18.48]],"ltp":3.25,"tv":103.96,"id":5071877},{"batb":[[2,1.45,93.26]],"batl":[[2,1.57,42.01]],"ltp":1.56,"tv":811.01,"id":6374165}]}]}
{"op":"mcm","clk":"1006366907","pt":1580595604561,"mc":[{"id":"1.168175453","rc":[{"batb":[[0,2.76,23.53],[1,2.52,30.21],[2,2.12,388.65]],"ltp":3.25,"tv":103.96,"id":5071877},{"batb":[[0,1.45,93.26],[1,1.41,103.7],[2,1.31,477.51]],"batl":[[0,1.57,42.01],[1,4,4.23],[2,1.57,0]],"ltp":1.56,"tv":811.01,"id":6374165}]}]}
{"op":"mcm","clk":"1006367017","pt":1580595605544,"mc":[{"id":"1.168175453","rc":[{"batb":[[0,2.52,30.21],[1,2.12,388.65],[2,1.01,15.52]],"batl":[[1,3.2,0]],"ltp":3.25,"tv":103.96,"id":5071877},{"batb":[[0,1.41,103.7],[1,1.31,477.51],[2,1.01,15.51]],"batl":[[0,4,4.23],[1,4,0]],"ltp":1.56,"tv":811.01,"id":6374165}]}]}
{"op":"mcm","clk":"1006367175","pt":1580595606952,"mc":[{"id":"1.168175453","rc":[{"batb":[[0,1.43,302.63],[1,1.42,436.5],[2,1.41,103.7]],"batl":[[0,1.65,272.84],[1,1.66,234.43],[2,4,4.23]],"ltp":1.56,"tv":811.01,"id":6374165}]}]}
{"op":"mcm","clk":"1006367566","pt":1580595611053,"mc":[{"id":"1.168175453","rc":[{"batb":[[0,1.41,103.7],[1,1.31,477.51],[2,1.01,15.51]],"ltp":1.56,"tv":811.01,"id":6374165}]}]}
{"op":"mcm","clk":"1006367669","pt":1580595612092,"mc":[{"id":"1.168175453","rc":[{"batb":[[1,1.01,15.52],[2,1.01,0]],"ltp":3.25,"tv":103.96,"id":5071877},{"batb":[[1,1.01,15.51],[2,1.01,0]],"ltp":1.56,"tv":811.01,"id":6374165}]}]}
{"op":"mcm","clk":"1006367847","pt":1580595613494,"mc":[{"id":"1.168175453","rc":[{"batb":[[0,1.59,482.88],[1,1.58,283.17],[2,1.41,103.7]],"ltp":1.56,"tv":811.01,"id":6374165}]}]}
{"op":"mcm","clk":"1006367957","pt":1580595614494,"mc":[{"id":"1.168175453","rc":[{"batb":[[1,2.5,27.73],[2,2.1,49.73]],"batl":[[0,2.84,22.69],[1,2.96,707.2]],"ltp":3.25,"tv":103.96,"id":5071877},{"batb":[[0,1.59,546.61],[2,1.54,77.3]],"batl":[[2,1.67,42.01]],"ltp":1.56,"tv":811.01,"id":6374165}]}]}
{"op":"mcm","clk":"1006369483","pt":1580595630109,"mc":[{"id":"1.168175453","rc":[{"batb":[[0,2.5,27.73],[1,2.1,49.73],[2,1.92,394.91]],"ltp":3.25,"tv":103.96,"id":5071877},{"batb":[[0,1.54,77.3],[1,1.48,83.48],[2,1.4,451]],"batl":[[0,1.67,42.01],[1,4,4.23],[2,1.67,0]],"ltp":1.56,"tv":811.01,"id":6374165}]}]}
{"op":"mcm","clk":"1006369617","pt":1580595631547,"mc":[{"id":"1.168175453","rc":[{"batb":[[0,2.1,49.73],[1,1.92,394.91],[2,1.01,15.52]],"batl":[[0,2.96,707.2],[1,2.96,0]],"ltp":3.25,"tv":103.96,"id":5071877},{"batb":[[0,1.48,83.48],[1,1.4,451],[2,1.01,15.51]],"batl":[[0,4,4.23],[1,4,0]],"ltp":1.56,"tv":811.01,"id":6374165}]}]}
{"op":"mcm","clk":"1006369795","pt":1580595633563,"mc":[{"id":"1.168175453","rc":[{"batb":[[0,1.49,446.61],[1,1.48,450.09],[2,1.4,451]],"ltp":1.56,"tv":811.01,"id":6374165}]}]}
{"op":"mcm","clk":"1006369969","pt":1580595635542,"mc":[{"id":"1.168175453","rc":[{"batb":[[1,1.01,15.52],[2,1.01,0]],"ltp":3.25,"tv":103.96,"id":5071877},{"batb":[[2,1.01,15.51]],"batl":[[0,1.54,363.79],[1,1.55,300.12],[2,4,4.23]],"ltp":1.56,"tv":811.01,"id":6374165}]}]}
{"op":"mcm","clk":"1006370059","pt":1580595636470,"mc":[{"id":"1.168175453","rc":[{"batb":[[0,2.84,21.87],[1,2.72,24.37],[2,2.42,33.75]],"batl":[[1,3.15,19.32]],"ltp":3.25,"tv":103.96,"id":5071877},{"batb":[[2,1.46,90.74]],"batl":[[2,1.58,42.01]],"ltp":1.56,"tv":811.01,"id":6374165}]}]}
{"op":"mcm","clk":"1006371265","pt":1580595649368,"mc":[{"id":"1.168175453","rc":[{"batb":[[0,2.42,33.75],[1,2.04,394.09],[2,1.01,15.52]],"batl":[[1,3.15,0]],"ltp":3.25,"tv":103.96,"id":5071877},{"batb":[[0,1.41,103.78],[1,1.34,465.43],[2,1.01,15.51]],"batl":[[0,4,4.23],[1,1.55,0],[2,1.58,0]],"ltp":1.56,"tv":811.01,"id":6374165}]}]}
{"op":"mcm","clk":"1006371677","pt":1580595653562,"mc":[{"id":"1.168175453","rc":[{"batb":[[0,1.52,312.06],[1,1.51,336.86],[2,1.41,103.78]],"batl":[[0,1.57,387.54],[1,1.58,279.16],[2,4,4.23]],"ltp":1.56,"tv":811.01,"id":6374165}]}]}
{"op":"mcm","clk":"1006371989","pt":1580595656455,"mc":[{"id":"1.168175453","rc":[{"batb":[[0,1.41,103.78],[1,1.34,465.43],[2,1.01,15.51]],"batl":[[0,4,4.23],[1,1.58,0],[2,4,0]],"ltp":1.56,"tv":811.01,"id":6374165}]}]}
{"op":"mcm","clk":"1006372278","pt":1580595659291,"mc":[{"id":"1.168175453","rc":[{"batb":[[1,1.01,15.51],[2,1.01,0]],"ltp":1.56,"tv":811.01,"id":6374165}]}]}
{"op":"mcm","clk":"1006372423","pt":1580595661048,"mc":[{"id":"1.168175453","rc":[{"batl":[[0,1.69,273.19],[1,1.71,425.83],[2,4,4.23]],"ltp":1.56,"tv":811.01,"id":6374165}]}]}
{"op":"mcm","clk":"1006372547","pt":1580595662403,"mc":[{"id":"1.168175453","rc":[{"batb":[[1,1.01,15.52],[2,1.01,0]],"ltp":3.25,"tv":103.96,"id":5071877}]}]}
{"op":"mcm","clk":"1006372654","pt":1580595663377,"mc":[{"id":"1.168175453","rc":[{"batb":[[0,1.63,368.86],[1,1.62,257.51],[2,1.41,103.78]],"ltp":1.56,"tv":811.01,"id":6374165}]}]}
{"op":"mcm","clk":"1006372765","pt":1580595664464,"mc":[{"id":"1.168175453","rc":[{"batb":[[1,2.4,29.41],[2,1.94,31.94]],"batl":[[0,2.74,23.53],[1,2.96,707.2]],"ltp":3.25,"tv":103.96,"id":5071877},{"batb":[[0,1.63,426.77],[2,1.58,72.26]],"batl":[[2,1.72,42.01]],"ltp":1.56,"tv":811.01,"id":6374165}]}]}
{"op":"mcm","clk":"1006374784","pt":1580595684523,"mc":[{"id":"1.168175453","rc":[{"batb":[[0,2.4,29.41],[1,1.94,31.94],[2,1.82,405.44]],"ltp":3.25,"tv":103.96,"id":5071877},{"batb":[[0,1.58,72.26],[1,1.48,83.4],[2,1.46,430.43]],"batl":[[0,1.72,42.01],[1,4,4.23],[2,1.72,0]],"ltp":1.56,"tv":811.01,"id":6374165}]}]}
{"op":"mcm","clk":"1006374821","pt":1580595684892,"mc":[{"id":"1.168175453","rc":[{"batb":[[0,1.94,31.94],[1,1.82,405.44],[2,1.01,15.52]],"batl":[[0,2.96,707.2],[1,2.96,0]],"ltp":3.25,"tv":103.96,"id":5071877},{"batb":[[0,1.48,83.4],[1,1.46,430.43],[2,1.01,15.51]],"batl":[[0,4,4.23],[1,4,0]],"ltp":1.56,"tv":811.01,"id":6374165}]}]}
{"op":"mcm","clk":"1006375072","pt":1580595687419,"mc":[{"id":"1.168175453","rc":[{"batb":[[0,1.95,31.71]],"ltp":3.25,"tv":103.96,"id":5071877},{"batb":[[0,1.48,648.67],[1,1.47,377.81],[2,1.46,430.43]],"batl":[[0,2.06,235.58],[1,2.08,231.39],[2,4,4.23]],"ltp":1.56,"tv":811.01,"id":6374165}]}]}
{"op":"mcm","clk":"1006376705","pt":1580595704346,"mc":[{"id":"1.168175453","rc":[{"batb":[[0,1.48,83.4],[1,1.46,430.43],[2,1.01,15.51]],"batl":[[0,4,4.23],[1,2.08,0],[2,4,0]],"ltp":1.56,"tv":811.01,"id":6374165}]}]}
{"op":"mcm","clk":"1006378130","pt":1580595719449,"mc":[{"id":"1.168175453","rc":[{"batb":[[1,1.01,15.51],[2,1.01,0]],"ltp":1.56,"tv":811.01,"id":6374165}]}]}
{"op":"mcm","clk":"1006378513","pt":1580595723464,"mc":[{"id":"1.168175453","rc":[{"batb":[[0,1.5,421.65],[1,1.48,83.4],[2,1.01,15.51]],"ltp":1.56,"tv":811.01,"id":6374165}]}]}
{"op":"mcm","clk":"1006379975","pt":1580595740453,"mc":[{"id":"1.168175453","rc":[{"batb":[[1,1.01,15.52],[2,1.01,0]],"ltp":3.25,"tv":103.96,"id":5071877},{"batb":[[0,1.48,83.4],[1,1.01,15.51],[2,1.01,0]],"ltp":1.56,"tv":811.01,"id":6374165}]}]}
{"op":"mcm","clk":"1006383890","pt":1580595783329,"mc":[{"id":"1.168175453","rc":[{"batb":[[0,1.01,15.52],[1,1.01,0]],"ltp":3.25,"tv":103.96,"id":5071877}]}]}
{"op":"mcm","clk":"1006384148","pt":1580595786436,"mc":[{"id":"1.168175453","rc":[{"batb":[[0,1.94,76.48],[1,1.5,76.79],[2,1.01,15.52]],"batl":[[0,2.14,36.13],[1,2.8,15.05],[2,2.96,707.2]],"ltp":3.25,"tv":103.96,"id":5071877},{"batb":[[0,1.97,32.02],[1,1.87,47.89],[2,1.65,55.86]],"batl":[[0,2.08,38.65],[1,4,4.23]],"ltp":1.56,"tv":811.01,"id":6374165}]}]}
{"op":"mcm","clk":"1006384223","pt":1580595787117,"mc":[{"id":"1.168175453","rc":[{"batl":[[1,2.96,707.2],[2,2.96,0]],"ltp":3.25,"tv":103.96,"id":5071877}]}]}
{"op":"mcm","clk":"1006384351","pt":1580595788412,"mc":[{"id":"1.168175453","rc":[{"batb":[[0,1.94,44.53]],"ltp":3.25,"tv":103.96,"id":5071877},{"batb":[[0,1.87,47.89],[1,1.65,55.86],[2,1.01,15.51]],"ltp":1.56,"tv":811.01,"id":6374165}]}]}
{"op":"mcm","clk":"1006384437","pt":1580595789241,"mc":[{"id":"1.168175453","rc":[{"batb":[[0,1.5,76.79],[1,1.01,15.52],[2,1.01,0]],"batl":[[0,2.96,707.2],[1,2.96,0]],"ltp":3.25,"tv":103.96,"id":5071877},{"batb":[[0,1.65,55.86],[1,1.01,15.51],[2,1.01,0]],"batl":[[0,4,4.23],[1,4,0]],"ltp":1.56,"tv":811.01,"id":6374165}]}]}
{"op":"mcm","clk":"1006385055","pt":1580595795344,"mc":[{"id":"1.168175453","rc":[{"batb":[[0,2.38,35.17],[1,1.92,32.97],[2,1.01,15.52]],"ltp":3.25,"tv":103.96,"id":5071877},{"batb":[[1,1.49,81.99],[2,1.01,15.51]],"ltp":1.56,"tv":811.01,"id":6374165}]}]}
{"op":"mcm","clk":"1006385148","pt":1580595796338,"mc":[{"id":"1.168175453","rc":[{"batb":[[1,2.36,30.25],[2,1.92,32.97]],"batl":[[0,2.68,24.37],[1,2.96,707.2]],"ltp":3.25,"tv":103.96,"id":5071877},{"batl":[[0,1.74,42.01],[1,4,4.23]],"ltp":1.56,"tv":811.01,"id":6374165}]}]}
{"op":"mcm","clk":"1006385266","pt":1580595797425,"mc":[{"id":"1.168175453","rc":[{"batb":[[2,1.46,430.43]],"ltp":1.56,"tv":811.01,"id":6374165}]}]}
{"op":"mcm","clk":"1006385385","pt":1580595798510,"mc":[{"id":"1.168175453","rc":[{"batb":[[1,1.59,70.58],[2,1.49,81.99]],"ltp":1.56,"tv":811.01,"id":6374165}]}]}
{"op":"mcm","clk":"1006385583","pt":1580595800532,"mc":[{"id":"1.168175453","rc":[{"trd":[[2.38,70.33]],"batb":[[0,2.36,30.25],[1,1.92,32.97],[2,1.82,405.44]],"ltp":2.38,"tv":174.29,"id":5071877}],"tv":985.3}]}
{"op":"mcm","clk":"1006385668","pt":1580595801464,"mc":[{"id":"1.168175453","rc":[{"batb":[[1,1.64,409.01],[2,1.63,251.91]],"batl":[[0,1.71,421.55],[1,1.73,408.79],[2,1.74,42.01]],"ltp":1.56,"tv":811.01,"id":6374165}]}]}
{"op":"mcm","clk":"1006386506","pt":1580595809241,"mc":[{"id":"1.168175453","rc":[{"batb":[[0,1.92,32.97],[1,1.82,405.44],[2,1.01,15.52]],"batl":[[0,2.96,707.2],[1,2.96,0]],"ltp":2.38,"tv":174.29,"id":5071877},{"batb":[[0,1.49,81.99],[1,1.46,430.43],[2,1.01,15.51]],"batl":[[0,4,4.23],[1,1.73,0],[2,1.74,0]],"ltp":1.56,"tv":811.01,"id":6374165}]}]}
{"op":"mcm","clk":"1006386777","pt":1580595812454,"mc":[{"id":"1.168175453","rc":[{"batb":[[0,1.91,33.36]],"ltp":2.38,"tv":174.29,"id":5071877},{"batb":[[0,1.5,81.28]],"ltp":1.56,"tv":811.01,"id":6374165}]}]}
{"op":"mcm","clk":"1006386928","pt":1580595813850,"mc":[{"id":"1.168175453","rc":[{"batb":[[1,1.01,15.52],[2,1.01,0]],"ltp":2.38,"tv":174.29,"id":5071877},{"batb":[[1,1.01,15.51],[2,1.01,0]],"ltp":1.56,"tv":811.01,"id":6374165}]}]}
{"op":"mcm","clk":"1006387119","pt":1580595815454,"mc":[{"id":"1.168175453","rc":[{"batb":[[1,1.49,494.67],[2,1.48,366.82]],"batl":[[0,1.54,318.21],[1,1.55,300.27],[2,4,4.23]],"ltp":1.56,"tv":811.01,"id":6374165}]}]}
{"op":"mcm","clk":"1006387225","pt":1580595816498,"mc":[{"id":"1.168175453","rc":[{"batb":[[0,2.82,22.58],[1,2.7,24.37],[2,2.32,37.92]],"batl":[[1,3.1,19.32]],"ltp":2.38,"tv":174.29,"id":5071877},{"batl":[[2,1.58,42.01]],"ltp":1.56,"tv":811.01,"id":6374165}]}]}
{"op":"mcm","clk":"1006387421","pt":1580595818359,"mc":[{"id":"1.168175453","rc":[{"trd":[[2.8,84.65],[2.82,45.17],[2.84,172.55]],"batb":[[0,2.7,24.37],[1,2.32,37.92],[2,2.04,397.47]],"ltp":2.8,"tv":476.66,"id":5071877},{"trd":[[1.54,318.21],[1.55,244.41]],"batb":[[1,1.49,354.56],[2,1.47,89.06]],"batl":[[0,1.55,147.35],[1,1.58,42.01],[2,4,4.23]],"ltp":1.55,"tv":1282.14,"id":6374165}],"tv":1758.8}]}
{"op":"mcm","clk":"1006387655","pt":1580595820987,"mc":[{"id":"1.168175453","rc":[{"batb":[[0,1.5,398.32]],"batl":[[0,1.55,444.52],[1,1.56,291.47],[2,1.58,42.01]],"ltp":1.55,"tv":1282.14,"id":6374165}]}]}
{"op":"mcm","clk":"1006389345","pt":1580595837306,"mc":[{"id":"1.168175453","rc":[{"batb":[[0,2.32,37.92],[1,2.04,397.47],[2,1.01,15.52]],"batl":[[1,3.1,0]],"ltp":2.8,"tv":476.66,"id":5071877},{"batb":[[0,1.41,103.55],[1,1.34,460.23],[2,1.01,15.51]],"batl":[[0,4,4.23],[1,1.56,0],[2,1.58,0]],"ltp":1.55,"tv":1282.14,"id":6374165}]}]}
{"op":"mcm","clk":"1006389705","pt":1580595840474,"mc":[{"id":"1.168175453","rc":[{"batb":[[0,2.3,38.63]],"ltp":2.8,"tv":476.66,"id":5071877},{"batb":[[0,1.42,441.44],[1,1.41,449.48],[2,1.34,460.23]],"batl":[[0,1.73,418.95],[1,1.75,392.74],[2,4,4.23]],"ltp":1.55,"tv":1282.14,"id":6374165}]}]}
{"op":"mcm","clk":"1006390187","pt":1580595845502,"mc":[{"id":"1.168175453","rc":[{"batb":[[0,1.42,102.05],[1,1.34,460.23],[2,1.01,15.51]],"batl":[[0,4,4.23],[1,1.75,0],[2,4,0]],"ltp":1.55,"tv":1282.14,"id":6374165}]}]}
{"op":"mcm","clk":"1006390328","pt":1580595846908,"mc":[{"id":"1.168175453","rc":[{"batb":[[1,1.01,15.52],[2,1.01,0]],"ltp":2.8,"tv":476.66,"id":5071877},{"batb":[[1,1.01,15.51],[2,1.01,0]],"ltp":1.55,"tv":1282.14,"id":6374165}]}]}
{"op":"mcm","clk":"1006390497","pt":1580595848442,"mc":[{"id":"1.168175453","rc":[{"trd":[[2.96,388.28]],"batl":[[0,2.96,318.92]],"ltp":2.96,"tv":864.94,"id":5071877},{"trd":[[1.51,761.57]],"batb":[[0,1.42,441.44],[1,1.41,449.47],[2,1.01,15.51]],"ltp":1.51,"tv":2043.71,"id":6374165}],"tv":2908.65}]}
{"op":"mcm","clk":"1006390553","pt":1580595848960,"mc":[{"id":"1.168175453","rc":[{"trd":[[2.96,474.02]],"batb":[[0,2.78,23.21]],"batl":[[0,2.96,276.06]],"ltp":2.96,"tv":950.68,"id":5071877},{"batb":[[2,1.31,145.88]],"ltp":1.51,"tv":2043.71,"id":6374165}],"tv":2994.39}]}
{"op":"mcm","clk":"1006390699","pt":1580595850524,"mc":[{"id":"1.168175453","rc":[{"trd":[[2.96,535.32]],"batb":[[1,2.22,380.42],[2,1.01,15.52]],"batl":[[0,2.96,235.77],[1,3.35,17.64]],"ltp":2.96,"tv":1011.98,"id":5071877},{"trd":[[1.51,799.43]],"ltp":1.51,"tv":2081.57,"id":6374165}],"tv":3093.55}]}
{"op":"mcm","clk":"1006390795","pt":1580595851413,"mc":[{"id":"1.168175453","rc":[{"trd":[[2.96,1006.99]],"batl":[[0,3.35,17.64],[1,3.35,0]],"ltp":2.96,"tv":1483.65,"id":5071877}],"tv":3565.22}]}
{"op":"mcm","clk":"1006390900","pt":1580595852356,"mc":[{"id":"1.168175453","rc":[{"batb":[[0,1.42,738.64]],"batl":[[0,1.47,472.84],[1,1.48,355.35],[2,4,4.23]],"ltp":1.51,"tv":2081.57,"id":6374165}]}]}
{"op":"mcm","clk":"1006391009","pt":1580595853438,"mc":[{"id":"1.168175453","rc":[{"batb":[[0,2.96,21],[1,2.78,23.21],[2,2.22,380.42]],"ltp":2.96,"tv":1483.65,"id":5071877},{"batb":[[0,1.42,838.62]],"ltp":1.51,"tv":2081.57,"id":6374165}]}]}
{"op":"mcm","clk":"1006391094","pt":1580595854223,"mc":[{"id":"1.168175453","rc":[{"batb":[[0,2.78,23.21],[1,2.22,380.42],[2,1.01,15.52]],"ltp":2.96,"tv":1483.65,"id":5071877},{"batb":[[0,1.42,738.64]],"ltp":1.51,"tv":2081.57,"id":6374165}]}]}
{"op":"mcm","clk":"1006391166","pt":1580595854741,"mc":[{"id":"1.168175453","rc":[{"batb":[[0,2.98,21],[1,2.78,23.21],[2,2.22,380.42]],"ltp":2.96,"tv":1483.65,"id":5071877},{"batb":[[1,1.41,551.13]],"batl":[[2,1.5,42.01]],"ltp":1.51,"tv":2081.57,"id":6374165}]}]}
{"op":"mcm","clk":"1006391426","pt":1580595857235,"mc":[{"id":"1.168175453","rc":[{"batb":[[0,3.05,44.61],[1,2.98,21],[2,2.74,24.16]],"ltp":2.96,"tv":1483.65,"id":5071877},{"batb":[[0,1.43,98.98],[1,1.42,636.59],[2,1.41,551.13]],"ltp":1.51,"tv":2081.57,"id":6374165}]}]}
{"op":"mcm","clk":"1006391848","pt":1580595861466,"mc":[{"id":"1.168175453","rc":[{"trd":[[1.43,183.21]],"batb":[[0,1.43,7.37]],"ltp":1.43,"tv":2264.78,"id":6374165}],"tv":3748.43}]}
{"op":"mcm","clk":"1006391962","pt":1580595862553,"mc":[{"id":"1.168175453","rc":[{"trd":[[1.47,10.92]],"batl":[[0,1.47,469.65]],"ltp":1.47,"tv":2271.16,"id":6374165}],"tv":3754.81}]}
{"op":"mcm","clk":"1006392218","pt":1580595865445,"mc":[{"id":"1.168175453","rc":[{"batb":[[0,3.1,43.04],[2,2.78,23.29]],"ltp":2.96,"tv":1483.65,"id":5071877},{"batb":[[0,1.42,738.33],[1,1.41,551.13],[2,1.32,141.71]],"ltp":1.47,"tv":2271.16,"id":6374165}]}]}
{"op":"mcm","clk":"1006392330","pt":1580595866440,"mc":[{"id":"1.168175453","rc":[{"trd":[[1.42,56]],"batb":[[0,1.42,710.33]],"ltp":1.42,"tv":2327.16,"id":6374165}],"tv":3810.81}]}
{"op":"mcm","clk":"1006392716","pt":1580595870069,"mc":[{"id":"1.168175453","rc":[{"trd":[[1.47,10.96]],"batl":[[0,1.47,469.63]],"ltp":1.47,"tv":2327.2,"id":6374165}],"tv":3810.85}]}
{"op":"mcm","clk":"1006393069","pt":1580595873367,"mc":[{"id":"1.168175453","rc":[{"batb":[[2,2.76,23.76]],"ltp":2.96,"tv":1483.65,"id":5071877},{"batb":[[0,1.43,100.32],[1,1.42,608.59],[2,1.41,551.13]],"ltp":1.47,"tv":2327.2,"id":6374165}]}]}
{"op":"mcm","clk":"1006398367","pt":1580595929454,"mc":[{"id":"1.168175453","rc":[{"batb":[[0,2.76,23.76],[1,2.22,380.42],[2,1.01,15.52]],"ltp":2.96,"tv":1483.65,"id":5071877},{"batb":[[0,1.32,141.71],[1,1.28,478.65],[2,1.01,15.51]],"batl":[[0,4,4.23],[1,1.48,0],[2,1.5,0]],"ltp":1.47,"tv":2327.2,"id":6374165}]}]}
{"op":"mcm","clk":"1006398544","pt":1580595931499,"mc":[{"id":"1.168175453","rc":[{"batb":[[0,1.32,822.1],[1,1.31,643.8],[2,1.28,478.65]],"batl":[[0,1.56,500.73],[1,1.57,283.17],[2,4,4.23]],"ltp":1.47,"tv":2327.2,"id":6374165}]}]}
{"op":"mcm","clk":"1006402038","pt":1580595969841,"mc":[{"id":"1.168175453","rc":[{"batb":[[0,1.32,141.71],[1,1.28,478.65],[2,1.01,15.51]],"batl":[[0,4,4.23],[1,1.57,0],[2,4,0]],"ltp":1.47,"tv":2327.2,"id":6374165}]}]}
{"op":"mcm","clk":"1006402846","pt":1580595977166,"mc":[{"id":"1.168175453","rc":[{"batb":[[1,1.01,15.52],[2,1.01,0]],"ltp":2.96,"tv":1483.65,"id":5071877},{"batb":[[1,1.01,15.51],[2,1.01,0]],"ltp":1.47,"tv":2327.2,"id":6374165}]}]}
{"op":"mcm","clk":"1006403073","pt":1580595979498,"mc":[{"id":"1.168175453","rc":[{"batb":[[0,3.75,27.15],[1,3.2,40.76],[2,1.01,15.52]],"ltp":2.96,"tv":1483.65,"id":5071877},{"batb":[[1,1.21,230.22],[2,1.01,15.51]],"ltp":1.47,"tv":2327.2,"id":6374165}]}]}
{"op":"mcm","clk":"1006403161","pt":1580595980380,"mc":[{"id":"1.168175453","rc":[{"batb":[[1,3.5,16.8],[2,3.2,40.76]],"batl":[[0,4.1,13.44]],"ltp":2.96,"tv":1483.65,"id":5071877},{"batb":[[0,1.32,272.78]],"batl":[[0,1.4,42.01],[1,4,4.23]],"ltp":1.47,"tv":2327.2,"id":6374165}]}]}
{"op":"mcm","clk":"1006403265","pt":1580595981415,"mc":[{"id":"1.168175453","rc":[{"batb":[[1,1.22,523],[2,1.21,230.22]],"ltp":1.47,"tv":2327.2,"id":6374165}]}]}
{"op":"mcm","clk":"1006403702","pt":1580595985363,"mc":[{"id":"1.168175453","rc":[{"batl":[[1,1.55,21.22],[2,4,4.23]],"ltp":1.47,"tv":2327.2,"id":6374165}]}]}
{"op":"mcm","clk":"1006404070","pt":1580595988502,"mc":[{"id":"1.168175453","rc":[{"batb":[[0,1.32,951.64],[1,1.31,643.8],[2,1.22,523]],"batl":[[0,1.36,613.95],[1,1.37,493.96],[2,1.4,42.01]],"ltp":1.47,"tv":2327.2,"id":6374165}]}]}
{"op":"mcm","clk":"1006404544","pt":1580595993409,"mc":[{"id":"1.168175453","rc":[{"batb":[[0,3.2,40.76],[1,2.42,381.73],[2,1.01,15.52]],"ltp":2.96,"tv":1483.65,"id":5071877},{"batb":[[0,1.22,523],[1,1.21,230.22],[2,1.01,15.51]],"batl":[[0,4,4.23],[1,1.37,0],[2,1.4,0]],"ltp":1.47,"tv":2327.2,"id":6374165}]}]}
{"op":"mcm","clk":"1006404609","pt":1580595994092,"mc":[{"id":"1.168175453","rc":[{"batl":[[0,1.32,17.68],[1,4,4.23]],"ltp":1.47,"tv":2327.2,"id":6374165}]}]}
{"op":"mcm","clk":"1006404865","pt":1580595996521,"mc":[{"id":"1.168175453","rc":[{"batb":[[0,1.22,1189.13],[1,1.21,1263.07]],"batl":[[1,1.45,430.79],[2,1.46,376.14]],"ltp":1.47,"tv":2327.2,"id":6374165}]}]}
{"op":"mcm","clk":"1006405375","pt":1580596001406,"mc":[{"id":"1.168175453","rc":[{"batl":[[1,4,4.23],[2,1.46,0]],"ltp":1.47,"tv":2327.2,"id":6374165}]}]}
{"op":"mcm","clk":"1006405486","pt":1580596002391,"mc":[{"id":"1.168175453","rc":[{"batb":[[1,1.01,15.52],[2,1.01,0]],"ltp":2.96,"tv":1483.65,"id":5071877},{"batb":[[0,1.22,666.13]],"ltp":1.47,"tv":2327.2,"id":6374165}]}]}
{"op":"mcm","clk":"1006405714","pt":1580596004525,"mc":[{"id":"1.168175453","rc":[{"batb":[[0,5,27.62],[1,4.6,10.92],[2,4,45.87]],"batl":[[0,5.4,9.24]],"ltp":2.96,"tv":1483.65,"id":5071877},{"batb":[[0,1.22,834.17],[2,1.13,388.61]],"batl":[[0,1.25,924.81],[1,1.26,752.16],[2,1.28,42.01]],"ltp":1.47,"tv":2327.2,"id":6374165}]}]}
{"op":"mcm","clk":"1006405924","pt":1580596006439,"mc":[{"id":"1.168175453","rc":[{"batb":[[2,1.16,576.13]],"ltp":1.47,"tv":2327.2,"id":6374165}]}]}
{"op":"mcm","clk":"1006408150","pt":1580596027421,"mc":[{"id":"1.168175453","rc":[{"batb":[[0,4,44.77],[1,2.72,378.25],[2,1.01,15.52]],"ltp":2.96,"tv":1483.65,"id":5071877},{"batb":[[0,1.16,576.13],[1,1.13,388.61],[2,1.01,15.51]],"batl":[[0,1.32,17.68],[1,4,4.23],[2,1.28,0]],"ltp":1.47,"tv":2327.2,"id":6374165}]}]}
{"op":"mcm","clk":"1006408488","pt":1580596030556,"mc":[{"id":"1.168175453","rc":[{"batl":[[0,1.32,334.63],[1,1.33,574.06],[2,4,4.23]],"ltp":1.47,"tv":2327.2,"id":6374165}]}]}
{"op":"mcm","clk":"1006408688","pt":1580596032549,"mc":[{"id":"1.168175453","rc":[{"batb":[[0,1.13,388.61],[1,1.01,15.51],[2,1.01,0]],"ltp":1.47,"tv":2327.2,"id":6374165}]}]}
{"op":"mcm","clk":"1006408792","pt":1580596033541,"mc":[{"id":"1.168175453","rc":[{"batb":[[1,3.3,37.22],[2,2.72,378.25]],"ltp":2.96,"tv":1483.65,"id":5071877},{"batb":[[0,1.29,640.58],[1,1.28,895.54],[2,1.18,1602.86]],"ltp":1.47,"tv":2327.2,"id":6374165}]}]}
{"op":"mcm","clk":"1006408884","pt":1580596034430,"mc":[{"id":"1.168175453","rc":[{"batb":[[1,3.85,14.28],[2,3.3,37.22]],"batl":[[0,4.4,11.76]],"ltp":2.96,"tv":1483.65,"id":5071877},{"batb":[[1,1.28,1045.1],[2,1.17,297.73]],"batl":[[2,1.35,42.01]],"ltp":1.47,"tv":2327.2,"id":6374165}]}]}
{"op":"mcm","clk":"1006409144","pt":1580596036571,"mc":[{"id":"1.168175453","rc":[{"batb":[[2,1.2,530.86]],"ltp":1.47,"tv":2327.2,"id":6374165}]}]}
{"op":"mcm","clk":"1006410370","pt":1580596049551,"mc":[{"id":"1.168175453","rc":[{"batb":[[0,3.3,37.22],[1,2.72,378.25],[2,1.01,15.52]],"ltp":2.96,"tv":1483.65,"id":5071877},{"batb":[[0,1.2,530.86],[1,1.17,297.73],[2,1.01,15.51]],"batl":[[0,1.32,17.68],[1,4,4.23],[2,1.35,0]],"ltp":1.47,"tv":2327.2,"id":6374165}]}]}
{"op":"mcm","clk":"1006410567","pt":1580596051793,"mc":[{"id":"1.168175453","rc":[{"batb":[[1,1.17,1595.79],[2,1.16,900.09]],"batl":[[0,1.29,8.84],[1,1.32,17.68],[2,1.43,319.96]],"ltp":1.47,"tv":2327.2,"id":6374165}]}]}
{"op":"mcm","clk":"1006411975","pt":1580596066467,"mc":[{"id":"1.168175453","rc":[{"batl":[[2,4,4.23]],"ltp":1.47,"tv":2327.2,"id":6374165}]}]}
{"op":"mcm","clk":"1006412081","pt":1580596067483,"mc":[{"id":"1.168175453","rc":[{"batb":[[1,1.01,15.52],[2,1.01,0]],"ltp":2.96,"tv":1483.65,"id":5071877},{"batb":[[0,1.17,1595.79],[1,1.16,900.09],[2,1.01,15.51]],"ltp":1.47,"tv":2327.2,"id":6374165}]}]}
{"op":"mcm","clk":"1006412342","pt":1580596069562,"mc":[{"id":"1.168175453","rc":[{"batb":[[0,5.9,37.77],[1,4.6,33.68],[2,1.01,15.52]],"ltp":2.96,"tv":1483.65,"id":5071877},{"batb":[[2,1.09,570.6]],"batl":[[0,1.2,1129.14],[1,1.21,959.54],[2,1.29,8.84]],"ltp":1.47,"tv":2327.2,"id":6374165}]}]}
{"op":"mcm","clk":"1006412478","pt":1580596070496,"mc":[{"id":"1.168175453","rc":[{"batb":[[1,5.5,9.24],[2,4.6,33.68]],"batl":[[0,6.6,6.72]],"ltp":2.96,"tv":1483.65,"id":5071877},{"batb":[[0,1.17,1763.83]],"batl":[[2,1.22,42.01]],"ltp":1.47,"tv":2327.2,"id":6374165}]}]}
{"op":"mcm","clk":"1006412613","pt":1580596071485,"mc":[{"id":"1.168175453","rc":[{"batb":[[2,1.12,650.34]],"ltp":1.47,"tv":2327.2,"id":6374165}]}]}
{"op":"mcm","clk":"1006413725","pt":1580596080393,"mc":[{"id":"1.168175453","rc":[{"batb":[[0,5.5,9.24],[1,4.6,33.68],[2,2.98,374.28]],"ltp":2.96,"tv":1483.65,"id":5071877},{"batb":[[0,1.17,168.04],[1,1.12,650.34],[2,1.09,570.6]],"batl":[[0,1.22,42.01],[1,1.29,8.84],[2,1.32,17.68]],"ltp":1.47,"tv":2327.2,"id":6374165}]}]}
{"op":"mcm","clk":"1006413871","pt":1580596081535,"mc":[{"id":"1.168175453","rc":[{"batb":[[0,4.6,33.68],[1,1.01,15.52],[2,2.98,0]],"ltp":2.96,"tv":1483.65,"id":5071877},{"batb":[[0,1.09,570.6],[1,1.01,15.51],[2,1.09,0]],"batl":[[0,1.29,8.84],[1,1.32,17.68],[2,4,4.23]],"ltp":1.47,"tv":2327.2,"id":6374165}]}]}
{"op":"mcm","clk":"1006414136","pt":1580596083521,"mc":[{"id":"1.168175453","rc":[{"batb":[[0,1.09,1619.69],[1,1.08,1314.19],[2,1.01,15.51]],"batl":[[0,1.27,311.62],[1,1.28,701.58],[2,1.29,8.84]],"ltp":1.47,"tv":2327.2,"id":6374165}]}]}
{"op":"mcm","clk":"1006414441","pt":1580596086418,"mc":[{"id":"1.168175453","rc":[{"batl":[[0,1.29,8.84],[1,1.32,17.68],[2,4,4.23]],"ltp":1.47,"tv":2327.2,"id":6374165}]}]}
{"op":"mcm","clk":"1006414844","pt":1580596089386,"mc":[{"id":"1.168175453","rc":[{"batb":[[0,9.2,33.6],[1,6.6,29.27],[2,1.01,15.52]],"ltp":2.96,"tv":1483.65,"id":5071877},{"batb":[[2,1.06,825.37]],"batl":[[0,1.11,2304.42],[1,1.29,8.84],[2,1.32,17.68]],"ltp":1.47,"tv":2327.2,"id":6374165}]}]}
{"op":"mcm","clk":"1006414943","pt":1580596090434,"mc":[{"id":"1.168175453","rc":[{"batb":[[0,10.5,4.2],[1,9.2,33.6],[2,6.6,29.27]],"batl":[[0,13.5,3.36]],"ltp":2.96,"tv":1483.65,"id":5071877}]}]}
{"op":"mcm","clk":"1006415108","pt":1580596091520,"mc":[{"id":"1.168175453","rc":[{"batb":[[2,1.06,1819.27]],"ltp":1.47,"tv":2327.2,"id":6374165}]}]}
{"op":"mcm","clk":"1006415740","pt":1580596096629,"mc":[{"id":"1.168175453","rc":[{"batb":[[0,1.09,1502.35]],"batl":[[0,1.11,1921.65]],"ltp":1.47,"tv":2327.2,"id":6374165}]}]}
{"op":"mcm","clk":"1006416096","pt":1580596099537,"mc":[{"id":"1.168175453","rc":[{"batb":[[1,1.08,1428.04]],"batl":[[0,1.1,386.24],[1,1.11,1921.65],[2,1.29,8.84]],"ltp":1.47,"tv":2327.2,"id":6374165}]}]}
{"op":"mcm","clk":"1006417131","pt":1580596108425,"mc":[{"id":"1.168175453","rc":[{"batb":[[0,1.09,1421.9]],"batl":[[1,1.11,1842.65]],"ltp":1.47,"tv":2327.2,"id":6374165}]}]}
{"op":"mcm","clk":"1006417448","pt":1580596110931,"mc":[{"id":"1.168175453","rc":[{"batb":[[1,1.08,1509.24]],"batl":[[0,1.1,465.96]],"ltp":1.47,"tv":2327.2,"id":6374165}]}]}
{"op":"mcm","clk":"1006418042","pt":1580596116553,"mc":[{"id":"1.168175453","rc":[{"batb":[[1,6.6,29.27],[2,3.4,376.1]],"ltp":2.96,"tv":1483.65,"id":5071877},{"batb":[[0,1.06,1819.27],[1,1.01,15.51],[2,1.06,0]],"batl":[[0,1.29,8.84],[1,1.32,17.68],[2,4,4.23]],"ltp":1.47,"tv":2327.2,"id":6374165}]}]}
{"op":"mcm","clk":"1006418106","pt":1580596117193,"mc":[{"id":"1.168175453","rc":[{"batb":[[0,6.6,29.27],[1,3.4,376.1],[2,1.01,15.52]],"ltp":2.96,"tv":1483.65,"id":5071877}]}]}
{"op":"mcm","clk":"1006418280","pt":1580596118929,"mc":[{"id":"1.168175453","rc":[{"batb":[[0,1.06,4232.38]],"batl":[[0,1.16,1310.6],[1,1.17,886.84],[2,1.29,8.84]],"ltp":1.47,"tv":2327.2,"id":6374165}]}]}
{"op":"mcm","clk":"1006418877","pt":1580596125360,"mc":[{"id":"1.168175453","rc":[{"batl":[[0,1.29,8.84],[1,1.32,17.68],[2,4,4.23]],"ltp":1.47,"tv":2327.2,"id":6374165}]}]}
{"op":"mcm","clk":"1006419231","pt":1580596128157,"mc":[{"id":"1.168175453","rc":[{"batb":[[0,1.06,3238.48]],"batl":[[0,1.08,2368.43],[1,1.29,8.84],[2,1.32,17.68]],"ltp":1.47,"tv":2327.2,"id":6374165}]}]}
{"op":"mcm","clk":"1006419315","pt":1580596128941,"mc":[{"id":"1.168175453","rc":[{"batb":[[0,13.5,3.36],[1,12,17.78],[2,8.6,15.97]],"ltp":2.96,"tv":1483.65,"id":5071877},{"batb":[[1,1.04,1227.12],[2,1.01,15.51]],"batl":[[0,1.08,2410.44]],"ltp":1.47,"tv":2327.2,"id":6374165}]}]}
{"op":"mcm","clk":"1006419698","pt":1580596132267,"mc":[{"id":"1.168175453","rc":[{"batb":[[1,1.04,2508.24]],"ltp":1.47,"tv":2327.2,"id":6374165}]}]}
{"op":"mcm","clk":"1006420728","pt":1580596142475,"mc":[{"id":"1.168175453","rc":[{"batb":[[1,8.6,15.97],[2,3.4,376.1]],"ltp":2.96,"tv":1483.65,"id":5071877},{"batb":[[0,1.04,2508.24],[1,1.01,15.51],[2,1.01,0]],"batl":[[0,1.08,42.01]],"ltp":1.47,"tv":2327.2,"id":6374165}]}]}
{"op":"mcm","clk":"1006420806","pt":1580596143201,"mc":[{"id":"1.168175453","rc":[{"batb":[[0,8.6,15.97],[1,3.4,376.1],[2,1.01,15.52]],"ltp":2.96,"tv":1483.65,"id":5071877},{"batl":[[0,1.29,8.84],[1,1.32,17.68],[2,4,4.23]],"ltp":1.47,"tv":2327.2,"id":6374165}]}]}
{"op":"mcm","clk":"1006421085","pt":1580596145100,"mc":[{"id":"1.168175453","rc":[{"batb":[[0,1.04,4967.76]],"batl":[[0,1.11,404.48],[1,1.12,1863.7],[2,1.29,8.84]],"ltp":1.47,"tv":2327.2,"id":6374165}]}]}
{"op":"mcm","clk":"1006421821","pt":1580596151308,"mc":[{"id":"1.168175453","rc":[{"batb":[[0,1.04,2508.24]],"ltp":1.47,"tv":2327.2,"id":6374165}]}]}
{"op":"mcm","clk":"1006422014","pt":1580596152476,"mc":[{"id":"1.168175453","rc":[{"batb":[[0,1.04,1227.12]],"ltp":1.47,"tv":2327.2,"id":6374165}]}]}
{"op":"mcm","clk":"1006422303","pt":1580596154497,"mc":[{"id":"1.168175453","rc":[{"batb":[[0,9.6,4.2],[1,8.6,15.97],[2,5.9,38.16]],"batl":[[0,12.5,3.36]],"ltp":2.96,"tv":1483.65,"id":5071877},{"batb":[[0,1.1,1169.91],[1,1.09,1676.13],[2,1.06,797.52]],"ltp":1.47,"tv":2327.2,"id":6374165}]}]}
{"op":"mcm","clk":"1006422516","pt":1580596156008,"mc":[{"id":"1.168175453","rc":[{"batb":[[2,1.06,1791.42]],"ltp":1.47,"tv":2327.2,"id":6374165}]}]}
{"op":"mcm","clk":"1006424243","pt":1580596172520,"mc":[{"id":"1.168175453","rc":[{"batb":[[0,1.1,505.45],[1,1.06,1791.42],[2,1.01,15.51]],"batl":[[0,1.29,8.84],[1,1.32,17.68],[2,4,4.23]],"ltp":1.47,"tv":2327.2,"id":6374165}]}]}
{"op":"mcm","clk":"1006424333","pt":1580596173319,"mc":[{"id":"1.168175453","rc":[{"batb":[[0,5.9,38.16],[1,3.4,376.1],[2,1.01,15.52]],"ltp":2.96,"tv":1483.65,"id":5071877},{"batb":[[0,1.06,1791.42],[1,1.01,15.51],[2,1.01,0]],"ltp":1.47,"tv":2327.2,"id":6374165}]}]}
{"op":"mcm","clk":"1006424568","pt":1580596175548,"mc":[{"id":"1.168175453","rc":[{"batb":[[0,1.06,4204.53]],"batl":[[0,1.18,348.77],[1,1.19,1113.52],[2,1.29,8.84]],"ltp":1.47,"tv":2327.2,"id":6374165}]}]}
{"op":"mcm","clk":"1006425634","pt":1580596186456,"mc":[{"id":"1.168175453","rc":[{"batl":[[0,1.29,8.84],[1,1.32,17.68],[2,4,4.23]],"ltp":1.47,"tv":2327.2,"id":6374165}]}]}
{"op":"mcm","clk":"1006425958","pt":1580596189546,"mc":[{"id":"1.168175453","rc":[{"batb":[[0,12,18.88],[1,8,18.8],[2,5.9,38.16]],"ltp":2.96,"tv":1483.65,"id":5071877},{"batb":[[0,1.06,3210.63],[1,1.03,1279.6],[2,1.01,15.51]],"batl":[[0,1.08,2079.43],[1,1.29,8.84],[2,1.32,17.68]],"ltp":1.47,"tv":2327.2,"id":6374165}]}]}
{"op":"mcm","clk":"1006426065","pt":1580596190539,"mc":[{"id":"1.168175453","rc":[{"batb":[[0,13,3.36],[1,12,18.88],[2,8,18.8]],"ltp":2.96,"tv":1483.65,"id":5071877},{"batl":[[0,1.08,2121.44],[1,1.15,1650.7],[2,1.29,8.84]],"ltp":1.47,"tv":2327.2,"id":6374165}]}]}
{"op":"mcm","clk":"1006426263","pt":1580596192329,"mc":[{"id":"1.168175453","rc":[{"batb":[[1,1.04,1281.12],[2,1.03,1279.6]],"ltp":1.47,"tv":2327.2,"id":6374165}]}]}
{"op":"mcm","clk":"1006426759","pt":1580596197172,"mc":[{"id":"1.168175453","rc":[{"batl":[[2,1.32,17.68]],"ltp":1.47,"tv":2327.2,"id":6374165}]}]}
{"op":"mcm","clk":"1006428475","pt":1580596213443,"mc":[{"id":"1.168175453","rc":[{"batb":[[0,8,18.8],[1,3.4,376.1],[2,1.01,15.52]],"ltp":2.96,"tv":1483.65,"id":5071877},{"batb":[[0,1.04,1281.12],[1,1.03,1279.6],[2,1.01,15.51]],"batl":[[0,1.32,17.68],[1,4,4.23],[2,1.32,0]],"ltp":1.47,"tv":2327.2,"id":6374165}]}]}
{"op":"mcm","clk":"1006428809","pt":1580596216558,"mc":[{"id":"1.168175453","rc":[{"batb":[[0,1.03,1279.6],[1,1.01,15.51],[2,1.01,0]],"ltp":1.47,"tv":2327.2,"id":6374165}]}]}
{"op":"mcm","clk":"1006428902","pt":1580596217391,"mc":[{"id":"1.168175453","rc":[{"batb":[[0,1.07,2390.56],[1,1.03,1279.6],[2,1.01,15.51]],"batl":[[0,1.09,2108.4],[1,1.32,17.68],[2,4,4.23]],"ltp":1.47,"tv":2327.2,"id":6374165}]}]}
{"op":"mcm","clk":"1006429198","pt":1580596220559,"mc":[{"id":"1.168175453","rc":[{"batb":[[1,1.05,1069.58],[2,1.03,1279.6]],"ltp":1.47,"tv":2327.2,"id":6374165}]}]}
{"op":"mcm","clk":"1006429286","pt":1580596221396,"mc":[{"id":"1.168175453","rc":[{"batb":[[0,1.05,1069.58],[1,1.03,1279.6],[2,1.01,15.51]],"batl":[[0,1.32,17.68],[1,4,4.23],[2,4,0]],"ltp":1.47,"tv":2327.2,"id":6374165}]}]}
{"op":"mcm","clk":"1006429581","pt":1580596224165,"mc":[{"id":"1.168175453","rc":[{"batb":[[1,1.04,2459.52],[2,1.03,1279.6]],"batl":[[0,1.13,1878.05],[1,1.14,382.19],[2,1.32,17.68]],"ltp":1.47,"tv":2327.2,"id":6374165}]}]}
{"op":"mcm","clk":"1006430720","pt":1580596234487,"mc":[{"id":"1.168175453","rc":[{"batb":[[1,1.03,1279.6],[2,1.01,15.51]],"ltp":1.47,"tv":2327.2,"id":6374165}]}]}
{"op":"mcm","clk":"1006430922","pt":1580596235885,"mc":[{"id":"1.168175453","rc":[{"batb":[[0,1.03,1279.6],[1,1.01,15.51],[2,1.01,0]],"ltp":1.47,"tv":2327.2,"id":6374165}]}]}
{"op":"mcm","clk":"1006431128","pt":1580596237503,"mc":[{"id":"1.168175453","rc":[{"batb":[[0,1.11,720.99],[1,1.1,1597.82],[2,1.03,1279.6]],"ltp":1.47,"tv":2327.2,"id":6374165}]}]}
{"op":"mcm","clk":"1006431238","pt":1580596238486,"mc":[{"id":"1.168175453","rc":[{"batb":[[0,9,5.04],[1,8,18.8],[2,5,26.99]],"ltp":2.96,"tv":1483.65,"id":5071877},{"batb":[[0,1.11,1178.29],[2,1.06,840.56]],"batl":[[0,1.12,42.01],[1,1.13,1878.05],[2,1.14,382.19]],"ltp":1.47,"tv":2327.2,"id":6374165}]}]}
{"op":"mcm","clk":"1006431345","pt":1580596239525,"mc":[{"id":"1.168175453","rc":[{"batl":[[0,11.5,3.36]],"ltp":2.96,"tv":1483.65,"id":5071877},{"batb":[[2,1.09,168.04]],"batl":[[0,1.13,1878.05],[1,1.14,382.19],[2,1.32,17.68]],"ltp":1.47,"tv":2327.2,"id":6374165}]}]}
{"op":"mcm","clk":"1006432105","pt":1580596245523,"mc":[{"id":"1.168175453","rc":[{"batb":[[1,5,26.99],[2,3.4,376.1]],"ltp":2.96,"tv":1483.65,"id":5071877},{"batb":[[0,1.11,720.99]],"ltp":1.47,"tv":2327.2,"id":6374165}]}]}
{"op":"mcm","clk":"1006432814","pt":1580596251315,"mc":[{"id":"1.168175453","rc":[{"trd":[[1.11,400]],"batb":[[0,1.11,520.99]],"ltp":1.11,"tv":2727.2,"id":6374165}],"tv":4210.85}]}
{"op":"mcm","clk":"1006432875","pt":1580596251833,"mc":[{"id":"1.168175453","rc":[{"batl":[[1,1.32,17.68],[2,4,4.23]],"ltp":1.11,"tv":2727.2,"id":6374165}]}]}
{"op":"mcm","clk":"1006433207","pt":1580596255119,"mc":[{"id":"1.168175453","rc":[{"batb":[[0,1.11,647.74],[1,1.1,1671.73]],"batl":[[0,1.13,1950.13]],"ltp":1.11,"tv":2727.2,"id":6374165}]}]}
{"op":"mcm","clk":"1006433892","pt":1580596261341,"mc":[{"id":"1.168175453","rc":[{"trd":[[1.11,400.32]],"batb":[[0,1.11,647.58]],"ltp":1.11,"tv":2727.52,"id":6374165}],"tv":4211.17}]}
{"op":"mcm","clk":"1006433982","pt":1580596262226,"mc":[{"id":"1.168175453","rc":[{"trd":[[1.11,686.32]],"batb":[[0,1.11,504.58]],"ltp":1.11,"tv":3013.52,"id":6374165}],"tv":4497.17}]}
{"op":"mcm","clk":"1006434246","pt":1580596264532,"mc":[{"id":"1.168175453","rc":[{"batb":[[0,1.09,168.04],[1,1.08,800.96],[2,1.06,840.56]],"batl":[[0,1.32,17.68],[1,4,4.23],[2,4,0]],"ltp":1.11,"tv":3013.52,"id":6374165}]}]}
{"op":"mcm","clk":"1006434339","pt":1580596265413,"mc":[{"id":"1.168175453","rc":[{"batb":[[0,5,26.99],[1,3.4,376.1],[2,1.01,15.52]],"ltp":2.96,"tv":1483.65,"id":5071877},{"batb":[[0,1.08,800.96],[1,1.06,840.56],[2,1.01,15.51]],"ltp":1.11,"tv":3013.52,"id":6374165}]}]}
{"op":"mcm","clk":"1006434495","pt":1580596267141,"mc":[{"id":"1.168175453","rc":[{"batb":[[1,1.06,2976.11]],"batl":[[0,1.23,979.96],[1,1.24,834.36],[2,1.32,17.68]],"ltp":1.11,"tv":3013.52,"id":6374165}]}]}
{"op":"mcm","clk":"1006436255","pt":1580596283530,"mc":[{"id":"1.168175453","rc":[{"batb":[[1,1.06,840.56]],"batl":[[0,1.32,17.68],[1,4,4.23],[2,1.32,0]],"ltp":1.11,"tv":3013.52,"id":6374165}]}]}
{"op":"mcm","clk":"1006436441","pt":1580596285155,"mc":[{"id":"1.168175453","rc":[{"batb":[[0,1.06,840.56],[1,1.01,15.51],[2,1.01,0]],"ltp":1.11,"tv":3013.52,"id":6374165}]}]}
{"op":"mcm","clk":"1006436681","pt":1580596287456,"mc":[{"id":"1.168175453","rc":[{"batb":[[0,12.5,17.23],[1,7.6,20.38],[2,3.4,376.1]],"ltp":2.96,"tv":1483.65,"id":5071877},{"batb":[[0,1.06,2976.11],[1,1.02,1618.02],[2,1.01,15.51]],"batl":[[0,1.07,511.37],[1,1.08,1861.79],[2,1.32,17.68]],"ltp":1.11,"tv":3013.52,"id":6374165}]}]}
{"op":"mcm","clk":"1006436905","pt":1580596289540,"mc":[{"id":"1.168175453","rc":[{"batb":[[1,1.04,1234.55],[2,1.02,1618.02]],"ltp":1.11,"tv":3013.52,"id":6374165}]}]}
{"op":"mcm","clk":"1006439523","pt":1580596313280,"mc":[{"id":"1.168175453","rc":[{"batb":[[0,7.6,20.38],[1,3.4,376.1],[2,1.01,15.52]],"ltp":2.96,"tv":1483.65,"id":5071877},{"batb":[[0,1.04,1234.55],[1,1.02,1618.02],[2,1.01,15.51]],"batl":[[0,1.32,17.68],[1,4,4.23],[2,1.32,0]],"ltp":1.11,"tv":3013.52,"id":6374165}]}]}
{"op":"mcm","clk":"1006439886","pt":1580596316394,"mc":[{"id":"1.168175453","rc":[{"batb":[[1,1.03,2483.4],[2,1.02,1618.02]],"batl":[[0,1.13,1366.55],[1,1.14,889.21],[2,1.32,17.68]],"ltp":1.11,"tv":3013.52,"id":6374165}]}]}
{"op":"mcm","clk":"1006440059","pt":1580596318103,"mc":[{"id":"1.168175453","rc":[{"batl":[[0,1.32,17.68],[1,4,4.23],[2,1.32,0]],"ltp":1.11,"tv":3013.52,"id":6374165}]}]}
{"op":"mcm","clk":"1006440166","pt":1580596319197,"mc":[{"id":"1.168175453","rc":[{"batb":[[1,1.01,15.52],[2,1.01,0]],"ltp":2.96,"tv":1483.65,"id":5071877},{"batb":[[0,1.03,2483.4],[1,1.02,1618.02],[2,1.01,15.51]],"ltp":1.11,"tv":3013.52,"id":6374165}]}]}
{"op":"mcm","clk":"1006440292","pt":1580596320536,"mc":[{"id":"1.168175453","rc":[{"batl":[[0,1.04,25.21],[1,1.32,17.68],[2,4,4.23]],"ltp":1.11,"tv":3013.52,"id":6374165}]}]}
{"op":"mcm","clk":"1006440364","pt":1580596321111,"mc":[{"id":"1.168175453","rc":[{"batl":[[1,1.05,2435.8],[2,1.32,17.68]],"ltp":1.11,"tv":3013.52,"id":6374165}]}]}
{"op":"mcm","clk":"1006440510","pt":1580596322319,"mc":[{"id":"1.168175453","rc":[{"batb":[[0,20,11.49],[1,16.5,8.81],[2,1.01,15.52]],"ltp":2.96,"tv":1483.65,"id":5071877},{"batl":[[1,1.05,2477.81]],"ltp":1.11,"tv":3013.52,"id":6374165}]}]}
{"op":"mcm","clk":"1006440555","pt":1580596322631,"mc":[{"id":"1.168175453","rc":[{"batb":[[2,4,373.79]],"ltp":2.96,"tv":1483.65,"id":5071877},{"batb":[[1,1.02,3765.97]],"ltp":1.11,"tv":3013.52,"id":6374165}]}]}
{"op":"mcm","clk":"1006440937","pt":1580596325931,"mc":[{"id":"1.168175453","rc":[{"batl":[[0,1.05,2477.81],[1,1.32,17.68],[2,4,4.23]],"ltp":1.11,"tv":3013.52,"id":6374165}]}]}
{"op":"mcm","clk":"1006441288","pt":1580596329054,"mc":[{"id":"1.168175453","rc":[{"trd":[[1.03,50.42]],"batb":[[0,1.03,2458.19]],"ltp":1.03,"tv":3063.93,"id":6374165}],"tv":4547.58}]}
{"op":"mcm","clk":"1006442619","pt":1580596341405,"mc":[{"id":"1.168175453","rc":[{"trd":[[1.03,2260.42]],"batb":[[0,1.03,1353.19]],"ltp":1.03,"tv":5273.93,"id":6374165}],"tv":6757.58}]}
{"op":"mcm","clk":"1006442955","pt":1580596344336,"mc":[{"id":"1.168175453","rc":[{"batb":[[2,1.01,15.52]],"ltp":2.96,"tv":1483.65,"id":5071877},{"batb":[[1,1.02,1618.02]],"ltp":1.03,"tv":5273.93,"id":6374165}]}]}
{"op":"mcm","clk":"1006443067","pt":1580596345239,"mc":[{"id":"1.168175453","rc":[{"batb":[[0,1.03,2483.1]],"batl":[[1,1.06,99.14],[2,1.32,17.68]],"ltp":1.03,"tv":5273.93,"id":6374165}]}]}
{"op":"mcm","clk":"1006443455","pt":1580596348425,"mc":[{"id":"1.168175453","rc":[{"batb":[[1,1.02,1617.78]],"ltp":1.03,"tv":5273.93,"id":6374165}]}]}
{"op":"mcm","clk":"1006444240","pt":1580596355534,"mc":[{"id":"1.168175453","rc":[{"trd":[[1.03,2382.42]],"batb":[[0,1.03,2422.1]],"ltp":1.03,"tv":5395.93,"id":6374165}],"tv":6879.58}]}
{"op":"mcm","clk":"1006444709","pt":1580596359475,"mc":[{"id":"1.168175453","rc":[{"batb":[[0,1.03,4037.2]],"ltp":1.03,"tv":5395.93,"id":6374165}]}]}
{"op":"mcm","clk":"1006444732","pt":1580596359633,"mc":[{"id":"1.168175453","rc":[{"batb":[[1,1.01,15.51],[2,1.01,0]],"ltp":1.03,"tv":5395.93,"id":6374165}]}]}
{"op":"mcm","clk":"1006447097","pt":1580596381900,"mc":[{"id":"1.168175453","rc":[{"trd":[[21,10]],"ltp":21.0,"tv":1493.65,"id":5071877},{"trd":[[1.05,200]],"batl":[[0,1.05,2277.81]],"ltp":1.05,"tv":5595.93,"id":6374165}],"tv":7089.58}]}
{"op":"mcm","clk":"1006447461","pt":1580596385190,"mc":[{"id":"1.168175453","rc":[{"batl":[[0,1.05,2477.81]],"ltp":1.05,"tv":5595.93,"id":6374165}]}]}
{"op":"mcm","clk":"1006448964","pt":1580596398275,"mc":[{"id":"1.168175453","rc":[{"batb":[[0,16.5,8.66],[1,1.01,15.52],[2,1.01,0]],"ltp":21.0,"tv":1493.65,"id":5071877},{"batb":[[0,1.01,15.51],[1,1.01,0]],"batl":[[0,1.05,730.39]],"ltp":1.05,"tv":5595.93,"id":6374165}]}]}
{"op":"mcm","clk":"1006449072","pt":1580596399369,"mc":[{"id":"1.168175453","rc":[{"batl":[[0,1.05,688.38]],"ltp":1.05,"tv":5595.93,"id":6374165}]}]}
{"op":"mcm","clk":"1006449234","pt":1580596400971,"mc":[{"id":"1.168175453","rc":[{"batl":[[1,1.06,1830.07]],"ltp":1.05,"tv":5595.93,"id":6374165}]}]}
{"op":"mcm","clk":"1006449486","pt":1580596403293,"mc":[{"id":"1.168175453","rc":[{"batb":[[0,1.04,2459.22],[1,1.01,15.51]],"ltp":1.05,"tv":5595.93,"id":6374165}]}]}
{"op":"mcm","clk":"1006449599","pt":1580596404370,"mc":[{"id":"1.168175453","rc":[{"batb":[[1,14.5,12.12],[2,1.01,15.52]],"ltp":21.0,"tv":1493.65,"id":5071877},{"batb":[[0,1.04,3716.24],[1,1.02,1721.95],[2,1.01,15.51]],"ltp":1.05,"tv":5595.93,"id":6374165}]}]}
{"op":"mcm","clk":"1006449677","pt":1580596405190,"mc":[{"id":"1.168175453","rc":[{"batb":[[1,1.03,1535.84],[2,1.02,1721.95]],"ltp":1.05,"tv":5595.93,"id":6374165}]}]}
{"op":"mcm","clk":"1006450386","pt":1580596411719,"mc":[{"id":"1.168175453","rc":[{"trd":[[1.04,200]],"batb":[[0,1.04,3616.24]],"ltp":1.04,"tv":5795.93,"id":6374165}],"tv":7289.58}]}
{"op":"mcm","clk":"1006450555","pt":1580596413395,"mc":[{"id":"1.168175453","rc":[{"batb":[[0,14.5,12.12],[1,1.01,15.52],[2,1.01,0]],"ltp":21.0,"tv":1493.65,"id":5071877},{"batb":[[0,1.03,1535.84],[1,1.02,1721.95],[2,1.01,15.51]],"batl":[[0,1.06,1830.07],[1,1.32,17.68],[2,4,4.23]],"ltp":1.04,"tv":5795.93,"id":6374165}]}]}
{"op":"mcm","clk":"1006450748","pt":1580596415484,"mc":[{"id":"1.168175453","rc":[{"batb":[[0,1.04,100],[1,1.03,1535.84],[2,1.02,1721.95]],"batl":[[0,1.06,839.83]],"ltp":1.04,"tv":5795.93,"id":6374165}]}]}
{"op":"mcm","clk":"1006450963","pt":1580596417507,"mc":[{"id":"1.168175453","rc":[{"batb":[[1,1.02,1721.95],[2,1.01,15.51]],"ltp":1.04,"tv":5795.93,"id":6374165}]}]}
{"op":"mcm","clk":"1006451019","pt":1580596417980,"mc":[{"id":"1.168175453","rc":[{"trd":[[1.05,275.02]],"batb":[[0,1.04,2459.22]],"batl":[[0,1.05,1499.01],[1,1.06,839.83],[2,1.32,17.68]],"ltp":1.05,"tv":5870.95,"id":6374165}],"tv":7364.6}]}
{"op":"mcm","clk":"1006451331","pt":1580596421005,"mc":[{"id":"1.168175453","rc":[{"batl":[[1,1.06,989.93]],"ltp":1.05,"tv":5870.95,"id":6374165}]}]}
{"op":"mcm","clk":"1006451694","pt":1580596424611,"mc":[{"id":"1.168175453","rc":[{"batb":[[0,1.02,1721.95],[1,1.01,15.51],[2,1.01,0]],"batl":[[0,1.06,989.93],[1,1.32,17.68],[2,4,4.23]],"ltp":1.05,"tv":5870.95,"id":6374165}]}]}
{"op":"mcm","clk":"1006452021","pt":1580596427805,"mc":[{"id":"1.168175453","rc":[{"batb":[[0,1.03,2483.1],[1,1.02,1721.95],[2,1.01,15.51]],"batl":[[0,1.06,1634.83],[1,1.07,868.93],[2,1.32,17.68]],"ltp":1.05,"tv":5870.95,"id":6374165}]}]}
{"op":"mcm","clk":"1006452276","pt":1580596429902,"mc":[{"id":"1.168175453","rc":[{"batl":[[0,1.06,1532.79]],"ltp":1.05,"tv":5870.95,"id":6374165}]}]}
{"op":"mcm","clk":"1006452632","pt":1580596432930,"mc":[{"id":"1.168175453","rc":[{"batl":[[1,1.07,970.01]],"ltp":1.05,"tv":5870.95,"id":6374165}]}]}
{"op":"mcm","clk":"1006452986","pt":1580596435858,"mc":[{"id":"1.168175453","rc":[{"batl":[[0,1.06,99.14],[1,1.32,17.68],[2,4,4.23]],"ltp":1.05,"tv":5870.95,"id":6374165}]}]}
{"op":"mcm","clk":"1006453368","pt":1580596439447,"mc":[{"id":"1.168175453","rc":[{"batb":[[0,20,10.31],[1,16.5,8.66],[2,14.5,12.12]],"ltp":21.0,"tv":1493.65,"id":5071877},{"batl":[[0,1.04,491.4],[1,1.05,1949.07],[2,1.06,99.14]],"ltp":1.05,"tv":5870.95,"id":6374165}]}]}
{"op":"mcm","clk":"1006453465","pt":1580596440431,"mc":[{"id":"1.168175453","rc":[{"batb":[[2,1.01,15.52]],"ltp":21.0,"tv":1493.65,"id":5071877},{"batb":[[0,1.03,2651.14]],"ltp":1.05,"tv":5870.95,"id":6374165}]}]}
{"op":"mcm","clk":"1006453572","pt":1580596441432,"mc":[{"id":"1.168175453","rc":[{"batb":[[1,1.02,3869.91]],"ltp":1.05,"tv":5870.95,"id":6374165}]}]}
{"op":"mcm","clk":"1006453873","pt":1580596444399,"mc":[{"id":"1.168175453","rc":[{"batl":[[0,1.04,502.76]],"ltp":1.05,"tv":5870.95,"id":6374165}]}]}
{"op":"mcm","clk":"1006455460","pt":1580596458466,"mc":[{"id":"1.168175453","rc":[{"batb":[[0,1.03,168.04]],"batl":[[0,1.04,11.36],[1,1.05,397.42]],"ltp":1.05,"tv":5870.95,"id":6374165}]}]}
{"op":"mcm","clk":"1006455564","pt":1580596459368,"mc":[{"id":"1.168175453","rc":[{"batb":[[0,16.5,8.66],[1,1.01,15.52],[2,1.01,0]],"ltp":21.0,"tv":1493.65,"id":5071877},{"batb":[[0,1.02,2147.96],[1,1.01,15.51],[2,1.01,0]],"ltp":1.05,"tv":5870.95,"id":6374165}]}]}
{"op":"mcm","clk":"1006455806","pt":1580596461482,"mc":[{"id":"1.168175453","rc":[{"batb":[[0,1.02,2507.44]],"batl":[[2,1.06,2118.29]],"ltp":1.05,"tv":5870.95,"id":6374165}]}]}
{"op":"mcm","clk":"1006456122","pt":1580596464307,"mc":[{"id":"1.168175453","rc":[{"batb":[[0,1.01,15.51],[1,1.01,0]],"ltp":1.05,"tv":5870.95,"id":6374165}]}]}
{"op":"mcm","clk":"1006456515","pt":1580596467535,"mc":[{"id":"1.168175453","rc":[{"trd":[[1.04,222.72]],"batb":[[0,1.04,2447.86],[1,1.01,15.51]],"batl":[[0,1.05,397.42],[1,1.06,2118.29],[2,1.32,17.68]],"ltp":1.04,"tv":5893.67,"id":6374165}],"tv":7387.32}]}
{"op":"mcm","clk":"1006456631","pt":1580596468532,"mc":[{"id":"1.168175453","rc":[{"batb":[[1,14,13.06],[2,1.01,15.52]],"ltp":21.0,"tv":1493.65,"id":5071877},{"batb":[[0,1.04,3681.51],[1,1.02,1757.6],[2,1.01,15.51]],"ltp":1.04,"tv":5893.67,"id":6374165}]}]}
{"op":"mcm","clk":"1006456886","pt":1580596470537,"mc":[{"id":"1.168175453","rc":[{"batb":[[1,1.03,1535.84],[2,1.02,1757.6]],"ltp":1.04,"tv":5893.67,"id":6374165}]}]}
{"op":"mcm","clk":"1006458016","pt":1580596480544,"mc":[{"id":"1.168175453","rc":[{"batb":[[1,1.02,1757.6],[2,1.01,15.51]],"ltp":1.04,"tv":5893.67,"id":6374165}]}]}
{"op":"mcm","clk":"1006458602","pt":1580596485434,"mc":[{"id":"1.168175453","rc":[{"batb":[[0,14,13.06],[1,1.01,15.52],[2,1.01,0]],"ltp":21.0,"tv":1493.65,"id":5071877},{"batb":[[0,1.02,1757.6],[1,1.01,15.51],[2,1.01,0]],"batl":[[0,1.06,989.32],[1,1.32,17.68],[2,4,4.23]],"ltp":1.04,"tv":5893.67,"id":6374165}]}]}
{"op":"mcm","clk":"1006458918","pt":1580596488177,"mc":[{"id":"1.168175453","rc":[{"batl":[[1,1.07,1508.4],[2,1.32,17.68]],"ltp":1.04,"tv":5893.67,"id":6374165}]}]}
{"op":"mcm","clk":"1006459171","pt":1580596490432,"mc":[{"id":"1.168175453","rc":[{"batb":[[0,1.05,2435.8],[1,1.02,1757.6],[2,1.01,15.51]],"batl":[[1,1.07,1409.1]],"ltp":1.04,"tv":5893.67,"id":6374165}]}]}
{"op":"mcm","clk":"1006459253","pt":1580596491163,"mc":[{"id":"1.168175453","rc":[{"batb":[[1,12.5,16.13],[2,1.01,15.52]],"ltp":21.0,"tv":1493.65,"id":5071877},{"batb":[[1,1.04,1176.69]],"ltp":1.04,"tv":5893.67,"id":6374165}]}]}
{"op":"mcm","clk":"1006459499","pt":1580596493455,"mc":[{"id":"1.168175453","rc":[{"batl":[[0,1.06,1089.56]],"ltp":1.04,"tv":5893.67,"id":6374165}]}]}
{"op":"mcm","clk":"1006460182","pt":1580596499471,"mc":[{"id":"1.168175453","rc":[{"trd":[[1.06,190.82]],"batl":[[0,1.06,994.15]],"ltp":1.06,"tv":6084.49,"id":6374165}],"tv":7578.14}]}
{"op":"mcm","clk":"1006460671","pt":1580596503846,"mc":[{"id":"1.168175453","rc":[{"batb":[[0,12.5,16.13],[1,1.01,15.52],[2,1.01,0]],"ltp":21.0,"tv":1493.65,"id":5071877},{"batb":[[0,1.04,1176.69],[1,1.01,15.51],[2,1.01,0]],"batl":[[0,1.06,3.73]],"ltp":1.06,"tv":6084.49,"id":6374165}]}]}
{"op":"mcm","clk":"1006461267","pt":1580596508986,"mc":[{"id":"1.168175453","rc":[{"trd":[[1.06,192.6]],"batl":[[0,1.06,2.84]],"ltp":1.06,"tv":6086.27,"id":6374165}],"tv":7579.92}]}
{"op":"mcm","clk":"1006461434","pt":1580596510562,"mc":[{"id":"1.168175453","rc":[{"batb":[[0,1.05,2436.27],[1,1.04,1176.69],[2,1.01,15.51]],"batl":[[1,1.07,2390.73]],"ltp":1.06,"tv":6086.27,"id":6374165}]}]}
{"op":"mcm","clk":"1006461529","pt":1580596511501,"mc":[{"id":"1.168175453","rc":[{"batb":[[1,7.6,20.3],[2,1.01,15.52]],"ltp":21.0,"tv":1493.65,"id":5071877},{"batb":[[0,1.05,3309.8],[1,1.02,1729.11]],"ltp":1.06,"tv":6086.27,"id":6374165}]}]}
{"op":"mcm","clk":"1006461627","pt":1580596512390,"mc":[{"id":"1.168175453","rc":[{"batl":[[1,1.07,2432.74]],"ltp":1.06,"tv":6086.27,"id":6374165}]}]}
{"op":"mcm","clk":"1006461775","pt":1580596513806,"mc":[{"id":"1.168175453","rc":[{"batb":[[1,1.04,1234.55],[2,1.02,1729.11]],"ltp":1.06,"tv":6086.27,"id":6374165}]}]}
{"op":"mcm","clk":"1006464745","pt":1580596541526,"mc":[{"id":"1.168175453","rc":[{"batb":[[0,1.05,3392.69]],"ltp":1.06,"tv":6086.27,"id":6374165}]}]}
{"op":"mcm","clk":"1006464791","pt":1580596542040,"mc":[{"id":"1.168175453","rc":[{"batb":[[0,7.6,20.3],[1,1.01,15.52],[2,1.01,0]],"ltp":21.0,"tv":1493.65,"id":5071877},{"batb":[[0,1.04,1234.55],[1,1.02,1729.11],[2,1.01,15.51]],"batl":[[1,1.07,42.01]],"ltp":1.06,"tv":6086.27,"id":6374165}]}]}
{"op":"mcm","clk":"1006464932","pt":1580596543442,"mc":[{"id":"1.168175453","rc":[{"batl":[[1,1.32,17.68],[2,4,4.23]],"ltp":1.06,"tv":6086.27,"id":6374165}]}]}
{"op":"mcm","clk":"1006464965","pt":1580596543851,"mc":[{"id":"1.168175453","rc":[{"batb":[[0,1.02,1729.11],[1,1.01,15.51],[2,1.01,0]],"ltp":1.06,"tv":6086.27,"id":6374165}]}]}
{"op":"mcm","clk":"1006465107","pt":1580596545458,"mc":[{"id":"1.168175453","rc":[{"batb":[[0,7.8,19.36]],"ltp":21.0,"tv":1493.65,"id":5071877}]}]}
{"op":"mcm","clk":"1006465154","pt":1580596545885,"mc":[{"id":"1.168175453","rc":[{"batb":[[0,1.03,2018.8],[1,1.02,2198.45],[2,1.01,15.51]],"ltp":1.06,"tv":6086.27,"id":6374165}]}]}
{"op":"mcm","clk":"1006465437","pt":1580596548439,"mc":[{"id":"1.168175453","rc":[{"batl":[[0,1.04,2459.7],[1,1.06,2.84],[2,1.32,17.68]],"ltp":1.06,"tv":6086.27,"id":6374165}]}]}
{"op":"mcm","clk":"1006465538","pt":1580596549347,"mc":[{"id":"1.168175453","rc":[{"batb":[[0,21,9.27],[1,11.5,19.99],[2,1.01,15.52]],"ltp":21.0,"tv":1493.65,"id":5071877},{"batl":[[0,1.04,2501.71]],"ltp":1.06,"tv":6086.27,"id":6374165}]}]}
{"op":"mcm","clk":"1006465623","pt":1580596550074,"mc":[{"id":"1.168175453","rc":[{"batb":[[2,4.1,372.42]],"ltp":21.0,"tv":1493.65,"id":5071877},{"batb":[[2,1.01,4112.75]],"ltp":1.06,"tv":6086.27,"id":6374165}]}]}
{"op":"mcm","clk":"1006465827","pt":1580596551970,"mc":[{"id":"1.168175453","rc":[{"batb":[[2,1.01,15.51]],"ltp":1.06,"tv":6086.27,"id":6374165}]}]}
{"op":"mcm","clk":"1006466176","pt":1580596555255,"mc":[{"id":"1.168175453","rc":[{"batb":[[2,1.01,4112.75]],"ltp":1.06,"tv":6086.27,"id":6374165}]}]}
{"op":"mcm","clk":"1006466893","pt":1580596561499,"mc":[{"id":"1.168175453","rc":[{"batb":[[0,11.5,19.99],[1,4.1,372.42],[2,1.01,15.52]],"ltp":21.0,"tv":1493.65,"id":5071877},{"batb":[[0,1.01,4112.75],[1,1.02,0],[2,1.01,0]],"batl":[[0,1.06,2.84],[1,1.32,17.68],[2,4,4.23]],"ltp":1.06,"tv":6086.27,"id":6374165}]}]}
{"op":"mcm","clk":"1006467112","pt":1580596563469,"mc":[{"id":"1.168175453","rc":[{"batb":[[1,1.01,15.52],[2,1.01,0]],"ltp":21.0,"tv":1493.65,"id":5071877},{"batb":[[0,1.01,15.51]],"ltp":1.06,"tv":6086.27,"id":6374165}]}]}
{"op":"mcm","clk":"1006467204","pt":1580596564293,"mc":[{"id":"1.168175453","rc":[{"batb":[[0,1.01,2548.27]],"batl":[[1,1.08,2300.89],[2,1.32,17.68]],"ltp":1.06,"tv":6086.27,"id":6374165}]}]}
{"op":"mcm","clk":"1006468187","pt":1580596573497,"mc":[{"id":"1.168175453","rc":[{"batb":[[0,1.01,15.51]],"ltp":1.06,"tv":6086.27,"id":6374165}]}]}
{"op":"mcm","clk":"1006468550","pt":1580596576462,"mc":[{"id":"1.168175453","rc":[{"trd":[[1.06,198.28]],"batb":[[0,1.06,2410.45],[1,1.01,15.51]],"batl":[[0,1.08,2300.89],[1,1.32,17.68],[2,4,4.23]],"ltp":1.06,"tv":6091.95,"id":6374165}],"tv":7585.6}]}
{"op":"mcm","clk":"1006468647","pt":1580596577295,"mc":[{"id":"1.168175453","rc":[{"batb":[[1,6.6,27.77],[2,1.01,15.52]],"ltp":21.0,"tv":1493.65,"id":5071877},{"batb":[[0,1.06,3181.85],[1,1.02,1722.74],[2,1.01,15.51]],"ltp":1.06,"tv":6091.95,"id":6374165}]}]}
{"op":"mcm","clk":"1006468775","pt":1580596578491,"mc":[{"id":"1.168175453","rc":[{"batb":[[0,13.5,3.36],[1,11.5,19.99],[2,6.6,27.77]],"ltp":21.0,"tv":1493.65,"id":5071877},{"batb":[[1,1.04,1281.12],[2,1.02,1722.74]],"batl":[[0,1.08,2342.9]],"ltp":1.06,"tv":6091.95,"id":6374165}]}]}
{"op":"mcm","clk":"1006469145","pt":1580596581919,"mc":[{"id":"1.168175453","rc":[{"batb":[[2,1.02,3356.98]],"ltp":1.06,"tv":6091.95,"id":6374165}]}]}
{"op":"mcm","clk":"1006470667","pt":1580596596476,"mc":[{"id":"1.168175453","rc":[{"batb":[[1,6.6,27.77],[2,3.7,370.81]],"ltp":21.0,"tv":1493.65,"id":5071877},{"batb":[[0,1.04,1281.12],[1,1.02,1722.74],[2,1.01,15.51]],"batl":[[0,1.08,42.01]],"ltp":1.06,"tv":6091.95,"id":6374165}]}]}
{"op":"mcm","clk":"1006470757","pt":1580596597464,"mc":[{"id":"1.168175453","rc":[{"batb":[[0,6.6,27.77],[1,3.7,370.81],[2,1.01,15.52]],"ltp":21.0,"tv":1493.65,"id":5071877},{"batl":[[0,1.32,17.68],[1,4,4.23],[2,4,0]],"ltp":1.06,"tv":6091.95,"id":6374165}]}]}
{"op":"mcm","clk":"1006470823","pt":1580596598088,"mc":[{"id":"1.168175453","rc":[{"batb":[[1,1.01,15.52],[2,1.01,0]],"ltp":21.0,"tv":1493.65,"id":5071877},{"batb":[[0,1.02,1722.74],[1,1.01,15.51],[2,1.01,0]],"ltp":1.06,"tv":6091.95,"id":6374165}]}]}
{"op":"mcm","clk":"1006470962","pt":1580596599392,"mc":[{"id":"1.168175453","rc":[{"batb":[[0,1.03,2483.58],[1,1.02,1722.74],[2,1.01,15.51]],"batl":[[0,1.15,617.42],[1,1.16,1360.49],[2,1.32,17.68]],"ltp":1.06,"tv":6091.95,"id":6374165}]}]}
{"op":"mcm","clk":"1006470986","pt":1580596599602,"mc":[{"id":"1.168175453","rc":[{"batb":[[0,1.02,1722.74],[1,1.01,15.51],[2,1.01,0]],"batl":[[0,1.32,17.68],[1,4,4.23],[2,1.32,0]],"ltp":1.06,"tv":6091.95,"id":6374165}]}]}
{"op":"mcm","clk":"1006471181","pt":1580596601261,"mc":[{"id":"1.168175453","rc":[{"batb":[[0,1.08,639.03],[1,1.07,1745.73],[2,1.02,1722.74]],"batl":[[0,1.09,988.62],[1,1.1,1345.9],[2,1.32,17.68]],"ltp":1.06,"tv":6091.95,"id":6374165}]}]}
{"op":"mcm","clk":"1006471296","pt":1580596602448,"mc":[{"id":"1.168175453","rc":[{"batb":[[1,3.6,374.21],[2,1.01,15.52]],"ltp":21.0,"tv":1493.65,"id":5071877},{"batb":[[2,1.05,1069.58]],"ltp":1.06,"tv":6091.95,"id":6374165}]}]}
{"op":"mcm","clk":"1006471579","pt":1580596605564,"mc":[{"id":"1.168175453","rc":[{"batb":[[0,1.05,1069.58],[1,1.02,1722.74],[2,1.01,15.51]],"batl":[[0,1.32,17.68],[1,4,4.23],[2,1.32,0]],"ltp":1.06,"tv":6091.95,"id":6374165}]}]}
{"op":"mcm","clk":"1006471738","pt":1580596607160,"mc":[{"id":"1.168175453","rc":[{"batb":[[1,1.01,15.52],[2,1.01,0]],"ltp":21.0,"tv":1493.65,"id":5071877},{"batb":[[0,1.02,1722.74],[1,1.01,15.51],[2,1.01,0]],"ltp":1.06,"tv":6091.95,"id":6374165}]}]}
{"op":"mcm","clk":"1006471830","pt":1580596608145,"mc":[{"id":"1.168175453","rc":[{"batb":[[0,1.03,2483.58],[1,1.02,1722.74],[2,1.01,15.51]],"batl":[[0,1.15,622.67],[1,1.16,1360.51],[2,1.32,17.68]],"ltp":1.06,"tv":6091.95,"id":6374165}]}]}
{"op":"mcm","clk":"1006472040","pt":1580596610367,"mc":[{"id":"1.168175453","rc":[{"batb":[[0,13.5,2],[1,6.6,27.77],[2,1.01,15.52]],"ltp":21.0,"tv":1493.65,"id":5071877}]}]}
{"op":"mcm","clk":"1006474156","pt":1580596632394,"mc":[{"id":"1.168175453","rc":[{"batb":[[0,1.02,1722.74],[1,1.01,15.51],[2,1.01,0]],"ltp":1.06,"tv":6091.95,"id":6374165}]}]}
{"op":"mcm","clk":"1006474445","pt":1580596635413,"mc":[{"id":"1.168175453","rc":[{"trd":[[13.5,2]],"batb":[[0,6.6,27.77],[1,1.01,15.52],[2,1.01,0]],"ltp":13.5,"tv":1495.65,"id":5071877},{"trd":[[1.08,25]],"batb":[[0,1.13,1555.32],[1,1.12,689.58],[2,1.02,1722.74]],"ltp":1.08,"tv":6116.95,"id":6374165}],"tv":7612.6}]}
{"op":"mcm","clk":"1006474543","pt":1580596636400,"mc":[{"id":"1.168175453","rc":[{"batb":[[0,7.6,5.88],[1,6.6,27.77],[2,4.2,40.05]],"ltp":13.5,"tv":1495.65,"id":5071877},{"batb":[[0,1.14,360.44],[1,1.13,1555.32],[2,1.12,689.58]],"batl":[[0,1.15,664.68]],"ltp":1.08,"tv":6116.95,"id":6374165}]}]}
{"op":"mcm","clk":"1006474830","pt":1580596639511,"mc":[{"id":"1.168175453","rc":[{"batl":[[0,9.4,4.2]],"ltp":13.5,"tv":1495.65,"id":5071877}]}]}
{"op":"mcm","clk":"1006475154","pt":1580596643300,"mc":[{"id":"1.168175453","rc":[{"trd":[[8.2,5]],"ltp":8.2,"tv":1500.65,"id":5071877},{"trd":[[1.14,35.97]],"batb":[[0,1.14,324.47]],"ltp":1.14,"tv":6152.92,"id":6374165}],"tv":7653.57}]}
{"op":"mcm","clk":"1006475755","pt":1580596650031,"mc":[{"id":"1.168175453","rc":[{"batb":[[1,1.13,1475.91]],"ltp":1.14,"tv":6152.92,"id":6374165}]}]}
{"op":"mcm","clk":"1006476086","pt":1580596653454,"mc":[{"id":"1.168175453","rc":[{"trd":[[1.15,44]],"batb":[[2,1.12,794.91]],"batl":[[0,1.15,745.3]],"ltp":1.15,"tv":6196.92,"id":6374165}],"tv":7697.57}]}
{"op":"mcm","clk":"1006476827","pt":1580596660546,"mc":[{"id":"1.168175453","rc":[{"batb":[[1,1.07,670.61],[2,1.01,15.51]],"batl":[[0,1.15,42.01],[1,1.32,17.68],[2,4,4.23]],"ltp":1.15,"tv":6196.92,"id":6374165}]}]}
{"op":"mcm","clk":"1006476917","pt":1580596661527,"mc":[{"id":"1.168175453","rc":[{"batb":[[0,4.2,40.05],[1,3.2,374.33],[2,1.01,15.52]],"ltp":8.2,"tv":1500.65,"id":5071877},{"batb":[[0,1.07,670.61],[1,1.01,15.51],[2,1.01,0]],"batl":[[0,1.32,17.68],[1,4,4.23],[2,4,0]],"ltp":1.15,"tv":6196.92,"id":6374165}]}]}
{"op":"mcm","clk":"1006477097","pt":1580596663404,"mc":[{"id":"1.168175453","rc":[{"batb":[[0,1.07,3061.34]],"batl":[[0,1.28,535.16],[1,1.29,682.49],[2,1.32,17.68]],"ltp":1.15,"tv":6196.92,"id":6374165}]}]}
{"op":"mcm","clk":"1006477173","pt":1580596664229,"mc":[{"id":"1.168175453","rc":[{"batb":[[0,4.3,38.48]],"ltp":8.2,"tv":1500.65,"id":5071877}]}]}
{"op":"mcm","clk":"1006477275","pt":1580596665320,"mc":[{"id":"1.168175453","rc":[{"batb":[[0,1.07,670.61]],"batl":[[0,1.32,17.68],[1,4,4.23],[2,1.32,0]],"ltp":1.15,"tv":6196.92,"id":6374165}]}]}
{"op":"mcm","clk":"1006477618","pt":1580596668322,"mc":[{"id":"1.168175453","rc":[{"batb":[[0,1.15,1599.84],[1,1.14,630.05],[2,1.07,670.61]],"batl":[[0,1.18,1399.26],[1,1.19,762.15],[2,1.32,17.68]],"ltp":1.15,"tv":6196.92,"id":6374165}]}]}
{"op":"mcm","clk":"1006477844","pt":1580596670399,"mc":[{"id":"1.168175453","rc":[{"batb":[[2,1.12,650.34]],"ltp":1.15,"tv":6196.92,"id":6374165}]}]}
{"op":"mcm","clk":"1006477898","pt":1580596670913,"mc":[{"id":"1.168175453","rc":[{"batb":[[0,1.12,650.34],[1,1.07,670.61],[2,1.01,15.51]],"batl":[[0,1.32,17.68],[1,4,4.23],[2,1.32,0]],"ltp":1.15,"tv":6196.92,"id":6374165}]}]}
{"op":"mcm","clk":"1006478250","pt":1580596674552,"mc":[{"id":"1.168175453","rc":[{"batl":[[0,1.28,535.16],[1,1.29,682.49],[2,1.32,17.68]],"ltp":1.15,"tv":6196.92,"id":6374165}]}]}
{"op":"mcm","clk":"1006478353","pt":1580596675443,"mc":[{"id":"1.168175453","rc":[{"batb":[[1,1.01,15.52],[2,1.01,0]],"ltp":8.2,"tv":1500.65,"id":5071877},{"batb":[[0,1.25,801.47],[1,1.24,901.81],[2,1.07,670.61]],"ltp":1.15,"tv":6196.92,"id":6374165}]}]}
{"op":"mcm","clk":"1006478449","pt":1580596676541,"mc":[{"id":"1.168175453","rc":[{"batb":[[0,4.5,11.76],[1,4.3,38.48],[2,3.2,40.36]],"batl":[[0,5.3,9.24]],"ltp":8.2,"tv":1500.65,"id":5071877},{"batb":[[0,1.26,184.12],[1,1.25,801.47],[2,1.24,901.81]],"batl":[[1,1.29,724.5]],"ltp":1.15,"tv":6196.92,"id":6374165}]}]}
{"op":"mcm","clk":"1006479427","pt":1580596685318,"mc":[{"id":"1.168175453","rc":[{"trd":[[4.9,5]],"ltp":4.9,"tv":1505.65,"id":5071877},{"trd":[[1.26,19.45]],"batb":[[0,1.26,164.67]],"ltp":1.26,"tv":6216.37,"id":6374165}],"tv":7722.02}]}
{"op":"mcm","clk":"1006480152","pt":1580596692271,"mc":[{"id":"1.168175453","rc":[{"trd":[[4.9,7]],"ltp":4.9,"tv":1507.65,"id":5071877},{"trd":[[1.26,27.22]],"batb":[[0,1.26,156.89]],"ltp":1.26,"tv":6224.14,"id":6374165}],"tv":7731.79}]}
{"op":"mcm","clk":"1006480800","pt":1580596698530,"mc":[{"id":"1.168175453","rc":[{"batb":[[1,3.2,39.97],[2,2.62,379.26]],"ltp":4.9,"tv":1507.65,"id":5071877},{"batb":[[0,1.23,168.04],[1,1.18,824.95],[2,1.01,15.51]],"batl":[[0,1.29,42.01],[1,1.32,17.68],[2,4,4.23]],"ltp":1.26,"tv":6224.14,"id":6374165}]}]}
{"op":"mcm","clk":"1006480909","pt":1580596699569,"mc":[{"id":"1.168175453","rc":[{"batb":[[0,3.2,39.97],[1,2.62,379.26],[2,1.01,15.52]],"ltp":4.9,"tv":1507.65,"id":5071877},{"batb":[[0,1.18,824.95],[1,1.01,15.51],[2,1.01,0]],"batl":[[0,1.32,17.68],[1,4,4.23],[2,4,0]],"ltp":1.26,"tv":6224.14,"id":6374165}]}]}
{"op":"mcm","clk":"1006481078","pt":1580596701184,"mc":[{"id":"1.168175453","rc":[{"batb":[[1,1.17,1567.72],[2,1.16,624.01]],"batl":[[1,1.45,441.06],[2,1.46,382.38]],"ltp":1.26,"tv":6224.14,"id":6374165}]}]}
{"op":"mcm","clk":"1006481302","pt":1580596703301,"mc":[{"id":"1.168175453","rc":[{"batl":[[1,4,4.23],[2,1.46,0]],"ltp":1.26,"tv":6224.14,"id":6374165}]}]}
{"op":"mcm","clk":"1006481495","pt":1580596705391,"mc":[{"id":"1.168175453","rc":[{"batb":[[1,1.01,15.52],[2,1.01,0]],"ltp":4.9,"tv":1507.65,"id":5071877},{"batb":[[0,1.18,275.23]],"ltp":1.26,"tv":6224.14,"id":6374165}]}]}
{"op":"mcm","clk":"1006481585","pt":1580596706429,"mc":[{"id":"1.168175453","rc":[{"batl":[[0,7.2,6.72]],"ltp":4.9,"tv":1507.65,"id":5071877},{"batb":[[2,1.16,792.05]],"batl":[[0,1.2,970.97],[1,1.21,988.14],[2,1.32,17.68]],"ltp":1.26,"tv":6224.14,"id":6374165}]}]}
{"op":"mcm","clk":"1006481674","pt":1580596707310,"mc":[{"id":"1.168175453","rc":[{"batb":[[0,5.6,21.17],[1,3.25,38],[2,1.01,15.52]],"ltp":4.9,"tv":1507.65,"id":5071877}]}]}
{"op":"mcm","clk":"1006481902","pt":1580596709504,"mc":[{"id":"1.168175453","rc":[{"batb":[[2,2.84,375.42]],"ltp":4.9,"tv":1507.65,"id":5071877}]}]}
{"op":"mcm","clk":"1006483216","pt":1580596722347,"mc":[{"id":"1.168175453","rc":[{"trd":[[6,42.01]],"ltp":6.0,"tv":1549.66,"id":5071877},{"trd":[[1.2,210.05]],"batb":[[2,1.16,711.99]],"batl":[[0,1.2,760.92]],"ltp":1.2,"tv":6434.19,"id":6374165}],"tv":7983.85}]}
{"op":"mcm","clk":"1006483337","pt":1580596723536,"mc":[{"id":"1.168175453","rc":[{"batb":[[0,3.25,38],[1,2.84,375.42],[2,1.01,15.52]],"ltp":6.0,"tv":1549.66,"id":5071877},{"batb":[[0,1.14,610.45],[1,1.07,668.01],[2,1.01,15.51]],"batl":[[0,1.32,17.68],[1,4,4.23],[2,1.32,0]],"ltp":1.2,"tv":6434.19,"id":6374165}]}]}
{"op":"mcm","clk":"1006483413","pt":1580596724320,"mc":[{"id":"1.168175453","rc":[{"batb":[[1,1.01,15.52],[2,1.01,0]],"ltp":6.0,"tv":1549.66,"id":5071877},{"batb":[[0,1.07,668.01],[1,1.01,15.51],[2,1.01,0]],"ltp":1.2,"tv":6434.19,"id":6374165}]}]}
{"op":"mcm","clk":"1006483644","pt":1580596726544,"mc":[{"id":"1.168175453","rc":[{"batb":[[0,3.3,37.69],[1,3.25,38],[2,1.01,15.52]],"ltp":6.0,"tv":1549.66,"id":5071877}]}]}
{"op":"mcm","clk":"1006483666","pt":1580596726755,"mc":[{"id":"1.168175453","rc":[{"batb":[[1,1.01,15.52],[2,1.01,0]],"ltp":6.0,"tv":1549.66,"id":5071877}]}]}
{"op":"mcm","clk":"1006483858","pt":1580596728562,"mc":[{"id":"1.168175453","rc":[{"batb":[[0,1.21,1232.97],[1,1.2,888.48],[2,1.07,668.01]],"batl":[[0,1.24,594.08],[1,1.25,812.56],[2,1.32,17.68]],"ltp":1.2,"tv":6434.19,"id":6374165}]}]}
{"op":"mcm","clk":"1006484067","pt":1580596730428,"mc":[{"id":"1.168175453","rc":[{"batb":[[1,2.72,378.25],[2,1.01,15.52]],"ltp":6.0,"tv":1549.66,"id":5071877},{"batb":[[2,1.16,576.13]],"ltp":1.2,"tv":6434.19,"id":6374165}]}]}
{"op":"mcm","clk":"1006484262","pt":1580596732442,"mc":[{"id":"1.168175453","rc":[{"batb":[[0,1.16,576.13],[1,1.07,668.01],[2,1.01,15.51]],"batl":[[0,1.32,17.68],[1,4,4.23],[2,1.32,0]],"ltp":1.2,"tv":6434.19,"id":6374165}]}]}
{"op":"mcm","clk":"1006484352","pt":1580596733423,"mc":[{"id":"1.168175453","rc":[{"batb":[[1,1.01,15.52],[2,1.01,0]],"ltp":6.0,"tv":1549.66,"id":5071877},{"batb":[[0,1.07,668.01],[1,1.01,15.51],[2,1.01,0]],"ltp":1.2,"tv":6434.19,"id":6374165}]}]}
{"op":"mcm","clk":"1006484567","pt":1580596735337,"mc":[{"id":"1.168175453","rc":[{"batl":[[1,1.45,655.97],[2,1.46,379.77]],"ltp":1.2,"tv":6434.19,"id":6374165}]}]}
{"op":"mcm","clk":"1006484901","pt":1580596738553,"mc":[{"id":"1.168175453","rc":[{"batb":[[1,3.05,20.16],[2,2.76,23.68]],"ltp":6.0,"tv":1549.66,"id":5071877},{"trd":[[1.32,35.37]],"batb":[[0,1.4,588.91],[1,1.39,599.84],[2,1.25,192.22]],"batl":[[0,1.45,655.97],[1,1.46,379.77],[2,1.49,42.01]],"ltp":1.32,"tv":6469.57,"id":6374165}],"tv":8019.23}]}
{"op":"mcm","clk":"1006484996","pt":1580596739532,"mc":[{"id":"1.168175453","rc":[{"batb":[[1,2.76,23.68],[2,2.22,384.52]],"ltp":6.0,"tv":1549.66,"id":5071877},{"batb":[[2,1.28,485.89]],"ltp":1.32,"tv":6469.57,"id":6374165}]}]}
{"op":"mcm","clk":"1006485076","pt":1580596740559,"mc":[{"id":"1.168175453","rc":[{"batl":[[0,3.55,15.9]],"ltp":6.0,"tv":1549.66,"id":5071877}]}]}
{"op":"mcm","clk":"1006485158","pt":1580596741435,"mc":[{"id":"1.168175453","rc":[{"batb":[[1,3,21],[2,2.76,23.68]],"ltp":6.0,"tv":1549.66,"id":5071877}]}]}
{"op":"mcm","clk":"1006485240","pt":1580596742369,"mc":[{"id":"1.168175453","rc":[{"batl":[[0,3.45,16.8]],"ltp":6.0,"tv":1549.66,"id":5071877},{"batb":[[0,1.4,693.93]],"ltp":1.32,"tv":6469.57,"id":6374165}]}]}
{"op":"mcm","clk":"1006485925","pt":1580596749382,"mc":[{"id":"1.168175453","rc":[{"trd":[[3.45,6]],"batl":[[0,3.45,13.8]],"ltp":3.45,"tv":1555.66,"id":5071877}],"tv":8025.23}]}
{"op":"mcm","clk":"1006486234","pt":1580596752459,"mc":[{"id":"1.168175453","rc":[{"batb":[[1,1.39,599.68]],"ltp":1.32,"tv":6469.57,"id":6374165}]}]}
{"op":"mcm","clk":"1006487014","pt":1580596760374,"mc":[{"id":"1.168175453","rc":[{"batb":[[1,1.39,599.36]],"ltp":1.32,"tv":6469.57,"id":6374165}]}]}
{"op":"mcm","clk":"1006487468","pt":1580596765178,"mc":[{"id":"1.168175453","rc":[{"trd":[[3.3,76.36]],"batb":[[0,3,21],[1,2.76,23.68],[2,2.22,384.52]],"batl":[[0,3.3,46.34],[1,3.45,13.8]],"ltp":3.3,"tv":1631.03,"id":5071877}],"tv":8100.6}]}
{"op":"mcm","clk":"1006488143","pt":1580596771489,"mc":[{"id":"1.168175453","rc":[{"batb":[[0,3.25,39.26],[1,3,21],[2,2.72,24.63]],"ltp":3.3,"tv":1631.03,"id":5071877},{"batb":[[0,1.4,802.99],[1,1.39,487.32]],"ltp":1.32,"tv":6469.57,"id":6374165}]}]}
{"op":"mcm","clk":"1006489307","pt":1580596784112,"mc":[{"id":"1.168175453","rc":[{"batb":[[0,3.2,40.05],[2,2.7,25.1]],"ltp":3.3,"tv":1631.03,"id":5071877},{"batb":[[0,1.4,801.49]],"ltp":1.32,"tv":6469.57,"id":6374165}]}]}
{"op":"mcm","clk":"1006490215","pt":1580596793677,"mc":[{"id":"1.168175453","rc":[{"trd":[[3.3,79.51]],"batl":[[0,3.3,43.19]],"ltp":3.3,"tv":1634.17,"id":5071877},{"trd":[[1.43,190.46]],"ltp":1.43,"tv":6476.82,"id":6374165}],"tv":8110.99}]}
{"op":"mcm","clk":"1006492091","pt":1580596814402,"mc":[{"id":"1.168175453","rc":[{"batb":[[0,3,21],[1,2.7,25.1],[2,2.22,384.52]],"ltp":3.3,"tv":1634.17,"id":5071877},{"batb":[[0,1.4,105.02],[1,1.28,485.89],[2,1.26,183.41]],"batl":[[0,1.49,42.01],[1,4,4.23],[2,1.49,0]],"ltp":1.43,"tv":6476.82,"id":6374165}]}]}
{"op":"mcm","clk":"1006492273","pt":1580596816229,"mc":[{"id":"1.168175453","rc":[{"batb":[[0,2.7,25.1],[1,2.22,384.52],[2,1.01,15.52]],"batl":[[1,3.45,0]],"ltp":3.3,"tv":1634.17,"id":5071877},{"batb":[[0,1.28,485.89],[1,1.26,183.41],[2,1.01,15.51]],"batl":[[0,4,4.23],[1,4,0]],"ltp":1.43,"tv":6476.82,"id":6374165}]}]}
{"op":"mcm","clk":"1006492603","pt":1580596819502,"mc":[{"id":"1.168175453","rc":[{"trd":[[3.3,122.7]],"ltp":3.3,"tv":1677.36,"id":5071877},{"trd":[[1.43,290.14]],"batb":[[0,1.37,708.29],[1,1.36,541.8],[2,1.28,485.89]],"batl":[[0,1.42,431.36],[1,4,4.23]],"ltp":1.43,"tv":6576.5,"id":6374165}],"tv":8253.87}]}
{"op":"mcm","clk":"1006492924","pt":1580596823140,"mc":[{"id":"1.168175453","rc":[{"batl":[[0,1.42,696.9],[1,1.43,414.31],[2,4,4.23]],"ltp":1.43,"tv":6576.5,"id":6374165}]}]}
{"op":"mcm","clk":"1006493205","pt":1580596825950,"mc":[{"id":"1.168175453","rc":[{"batb":[[0,1.28,485.89],[1,1.26,183.41],[2,1.01,15.51]],"batl":[[0,4,4.23],[1,1.43,0],[2,4,0]],"ltp":1.43,"tv":6576.5,"id":6374165}]}]}
{"op":"mcm","clk":"1006493625","pt":1580596829850,"mc":[{"id":"1.168175453","rc":[{"batb":[[1,1.27,743.53],[2,1.26,997.86]],"batl":[[0,1.57,430.01],[1,1.58,280.93],[2,4,4.23]],"ltp":1.43,"tv":6576.5,"id":6374165}]}]}
{"op":"mcm","clk":"1006494350","pt":1580596836472,"mc":[{"id":"1.168175453","rc":[{"batl":[[0,4,4.23],[1,1.58,0],[2,4,0]],"ltp":1.43,"tv":6576.5,"id":6374165}]}]}
{"op":"mcm","clk":"1006494513","pt":1580596837972,"mc":[{"id":"1.168175453","rc":[{"batb":[[1,1.01,15.52],[2,1.01,0]],"ltp":3.3,"tv":1677.36,"id":5071877},{"batb":[[0,1.27,743.53],[1,1.26,997.86],[2,1.01,15.51]],"ltp":1.43,"tv":6576.5,"id":6374165}]}]}
{"op":"mcm","clk":"1006494682","pt":1580596839375,"mc":[{"id":"1.168175453","rc":[{"batl":[[0,1.3,403.87],[1,1.31,629.36],[2,4,4.23]],"ltp":1.43,"tv":6576.5,"id":6374165}]}]}
{"op":"mcm","clk":"1006494794","pt":1580596840564,"mc":[{"id":"1.168175453","rc":[{"batb":[[0,4.3,38.71],[1,3.8,14.28],[2,3.35,36.51]],"batl":[[0,4.5,11.76]],"ltp":3.3,"tv":1677.36,"id":5071877},{"batb":[[0,1.28,149.55],[1,1.27,743.53],[2,1.26,997.86]],"batl":[[2,1.35,42.01]],"ltp":1.43,"tv":6576.5,"id":6374165}]}]}
{"op":"mcm","clk":"1006498882","pt":1580596876847,"mc":[{"id":"1.168175453","rc":[{"batb":[[1,1.26,183.41],[2,1.2,530.86]],"batl":[[0,1.35,42.01],[1,4,4.23],[2,1.35,0]],"ltp":1.43,"tv":6576.5,"id":6374165}]}]}
{"op":"mcm","clk":"1006499154","pt":1580596879560,"mc":[{"id":"1.168175453","rc":[{"batl":[[1,1.42,278.58],[2,1.43,418.35]],"ltp":1.43,"tv":6576.5,"id":6374165}]}]}
{"op":"mcm","clk":"1006499352","pt":1580596881340,"mc":[{"id":"1.168175453","rc":[{"batb":[[0,3.8,14.28],[1,3.35,36.51],[2,2.52,381.46]],"ltp":3.3,"tv":1677.36,"id":5071877},{"batb":[[1,1.2,530.86],[2,1.14,1946.44]],"ltp":1.43,"tv":6576.5,"id":6374165}]}]}
{"op":"mcm","clk":"1006499384","pt":1580596881655,"mc":[{"id":"1.168175453","rc":[{"batb":[[0,3.35,36.51],[1,2.52,381.46],[2,1.01,15.52]],"ltp":3.3,"tv":1677.36,"id":5071877},{"batb":[[0,1.2,530.86],[1,1.14,1946.44],[2,1.13,397.97]],"batl":[[0,1.42,278.58],[1,1.43,418.35],[2,4,4.23]],"ltp":1.43,"tv":6576.5,"id":6374165}]}]}
{"op":"mcm","clk":"1006499478","pt":1580596882842,"mc":[{"id":"1.168175453","rc":[{"batb":[[1,1.01,15.52],[2,1.01,0]],"ltp":3.3,"tv":1677.36,"id":5071877},{"batb":[[0,1.14,1946.44],[1,1.13,397.97],[2,1.01,15.51]],"ltp":1.43,"tv":6576.5,"id":6374165}]}]}
{"op":"mcm","clk":"1006499648","pt":1580596884548,"mc":[{"id":"1.168175453","rc":[{"batb":[[0,3.3,36.9]],"ltp":3.3,"tv":1677.36,"id":5071877},{"batb":[[1,1.13,395.22]],"ltp":1.43,"tv":6576.5,"id":6374165}]}]}
{"op":"mcm","clk":"1006499814","pt":1580596886418,"mc":[{"id":"1.168175453","rc":[{"batb":[[0,1.13,395.22],[1,1.01,15.51],[2,1.01,0]],"ltp":1.43,"tv":6576.5,"id":6374165}]}]}
{"op":"mcm","clk":"1006500103","pt":1580596889428,"mc":[{"id":"1.168175453","rc":[{"batb":[[0,1.38,676.72],[1,1.37,522.2],[2,1.13,395.22]],"ltp":1.43,"tv":6576.5,"id":6374165}]}]}
{"op":"mcm","clk":"1006500204","pt":1580596890568,"mc":[{"id":"1.168175453","rc":[{"batb":[[1,2.68,25.81],[2,1.01,15.52]],"ltp":3.3,"tv":1677.36,"id":5071877},{"batb":[[0,1.39,114.32],[1,1.38,676.72],[2,1.37,522.2]],"ltp":1.43,"tv":6576.5,"id":6374165}]}]}
{"op":"mcm","clk":"1006500279","pt":1580596891346,"mc":[{"id":"1.168175453","rc":[{"batb":[[1,3.15,19.32],[2,2.68,25.81]],"batl":[[0,3.6,15.96]],"ltp":3.3,"tv":1677.36,"id":5071877},{"batb":[[2,1.37,635.63]],"batl":[[2,1.46,42.01]],"ltp":1.43,"tv":6576.5,"id":6374165}]}]}
{"op":"mcm","clk":"1006500415","pt":1580596892542,"mc":[{"id":"1.168175453","rc":[{"batb":[[2,1.37,522.2]],"batl":[[2,4,4.23]],"ltp":1.43,"tv":6576.5,"id":6374165}]}]}
{"op":"mcm","clk":"1006500635","pt":1580596894464,"mc":[{"id":"1.168175453","rc":[{"batb":[[1,1.38,786.79]],"batl":[[2,1.47,42.01]],"ltp":1.43,"tv":6576.5,"id":6374165}]}]}
{"op":"mcm","clk":"1006501940","pt":1580596907549,"mc":[{"id":"1.168175453","rc":[{"batb":[[1,1.38,110.07],[2,1.25,505.09]],"batl":[[0,1.47,42.01],[1,4,4.23],[2,1.47,0]],"ltp":1.43,"tv":6576.5,"id":6374165}]}]}
{"op":"mcm","clk":"1006501980","pt":1580596907967,"mc":[{"id":"1.168175453","rc":[{"batb":[[0,2.68,25.65],[1,2.3,385.09],[2,1.01,15.52]],"ltp":3.3,"tv":1677.36,"id":5071877},{"batb":[[0,1.25,505.09],[1,1.22,220.31],[2,1.01,15.51]],"batl":[[0,4,4.23],[1,4,0]],"ltp":1.43,"tv":6576.5,"id":6374165}]}]}
{"op":"mcm","clk":"1006502234","pt":1580596910360,"mc":[{"id":"1.168175453","rc":[{"batb":[[1,1.23,897.14],[2,1.22,1221.99]],"batl":[[0,1.57,387.23],[1,1.58,281.31],[2,4,4.23]],"ltp":1.43,"tv":6576.5,"id":6374165}]}]}
{"op":"mcm","clk":"1006503895","pt":1580596927466,"mc":[{"id":"1.168175453","rc":[{"batl":[[0,1.39,3.79],[1,1.57,387.23],[2,1.58,281.31]],"ltp":1.43,"tv":6576.5,"id":6374165}]}]}
{"op":"mcm","clk":"1006504246","pt":1580596930991,"mc":[{"id":"1.168175453","rc":[{"batl":[[0,4,4.23],[1,1.57,0],[2,1.58,0]],"ltp":1.43,"tv":6576.5,"id":6374165}]}]}
{"op":"mcm","clk":"1006504463","pt":1580596933305,"mc":[{"id":"1.168175453","rc":[{"batb":[[1,1.01,15.52],[2,1.01,0]],"ltp":3.3,"tv":1677.36,"id":5071877},{"batb":[[0,1.23,897.14],[1,1.22,1221.99],[2,1.01,15.51]],"ltp":1.43,"tv":6576.5,"id":6374165}]}]}
{"op":"mcm","clk":"1006504582","pt":1580596934194,"mc":[{"id":"1.168175453","rc":[{"batl":[[0,1.26,647.69],[1,1.27,739.74],[2,4,4.23]],"ltp":1.43,"tv":6576.5,"id":6374165}]}]}
{"op":"mcm","clk":"1006504710","pt":1580596935493,"mc":[{"id":"1.168175453","rc":[{"batb":[[0,4.9,29.03],[1,3.4,33.99],[2,1.01,15.52]],"batl":[[0,5.1,10.08]],"ltp":3.3,"tv":1677.36,"id":5071877},{"batb":[[0,1.24,168.04],[1,1.23,897.14],[2,1.22,1221.99]],"ltp":1.43,"tv":6576.5,"id":6374165}]}]}
{"op":"mcm","clk":"1006504918","pt":1580596937517,"mc":[{"id":"1.168175453","rc":[{"batb":[[2,2.72,378.25]],"ltp":3.3,"tv":1677.36,"id":5071877}]}]}
{"op":"mcm","clk":"1006506105","pt":1580596949507,"mc":[{"id":"1.168175453","rc":[{"batb":[[0,1.23,897.14],[1,1.22,1221.99],[2,1.16,576.13]],"ltp":1.43,"tv":6576.5,"id":6374165}]}]}
{"op":"mcm","clk":"1006506539","pt":1580596954537,"mc":[{"id":"1.168175453","rc":[{"batb":[[0,3.4,33.99],[1,2.72,378.25],[2,1.01,15.52]],"ltp":3.3,"tv":1677.36,"id":5071877},{"batb":[[0,1.16,576.13],[1,1.07,672.65],[2,1.01,15.51]],"batl":[[0,4,4.23],[1,1.27,0],[2,4,0]],"ltp":1.43,"tv":6576.5,"id":6374165}]}]}
{"op":"mcm","clk":"1006506662","pt":1580596955937,"mc":[{"id":"1.168175453","rc":[{"batb":[[1,1.01,15.52],[2,1.01,0]],"ltp":3.3,"tv":1677.36,"id":5071877},{"batb":[[0,1.07,672.65],[1,1.01,15.51],[2,1.01,0]],"ltp":1.43,"tv":6576.5,"id":6374165}]}]}
{"op":"mcm","clk":"1006506772","pt":1580596957508,"mc":[{"id":"1.168175453","rc":[{"batl":[[0,1.4,356],[1,1.41,444.29],[2,4,4.23]],"ltp":1.43,"tv":6576.5,"id":6374165}]}]}
{"op":"mcm","clk":"1006506860","pt":1580596958498,"mc":[{"id":"1.168175453","rc":[{"batl":[[0,1.24,7.5],[1,1.4,356],[2,1.41,444.29]],"ltp":1.43,"tv":6576.5,"id":6374165}]}]}
{"op":"mcm","clk":"1006506928","pt":1580596959326,"mc":[{"id":"1.168175453","rc":[{"batb":[[1,3.35,2.51],[2,1.01,15.52]],"ltp":3.3,"tv":1677.36,"id":5071877}]}]}
{"op":"mcm","clk":"1006507060","pt":1580596960521,"mc":[{"id":"1.168175453","rc":[{"batb":[[1,1.01,15.52],[2,1.01,0]],"ltp":3.3,"tv":1677.36,"id":5071877},{"trd":[[1.24,15]],"batb":[[0,1.36,705.9],[1,1.35,561.71],[2,1.07,672.65]],"batl":[[0,1.4,356],[1,1.41,444.29],[2,4,4.23]],"ltp":1.24,"tv":6591.5,"id":6374165}],"tv":8268.87}]}
{"op":"mcm","clk":"1006507154","pt":1580596961298,"mc":[{"id":"1.168175453","rc":[{"batb":[[1,2.58,28.01],[2,1.01,15.52]],"ltp":3.3,"tv":1677.36,"id":5071877},{"batb":[[0,1.37,121.56],[1,1.36,705.9],[2,1.35,561.71]],"ltp":1.24,"tv":6591.5,"id":6374165}]}]}
{"op":"mcm","clk":"1006507241","pt":1580596962336,"mc":[{"id":"1.168175453","rc":[{"batb":[[2,2.3,385.09]],"ltp":3.3,"tv":1677.36,"id":5071877}]}]}
{"op":"mcm","clk":"1006507344","pt":1580596963520,"mc":[{"id":"1.168175453","rc":[{"batb":[[1,3.3,17.64],[2,2.58,28.01]],"batl":[[0,3.8,14.28],[1,3.85,6.06]],"ltp":3.3,"tv":1677.36,"id":5071877},{"batb":[[2,1.35,681.02]],"batl":[[2,1.44,42.01]],"ltp":1.24,"tv":6591.5,"id":6374165}]}]}
{"op":"mcm","clk":"1006507397","pt":1580596964401,"mc":[{"id":"1.168175453","rc":[{"batl":[[1,3.85,0]],"ltp":3.3,"tv":1677.36,"id":5071877}]}]}
{"op":"mcm","clk":"1006508453","pt":1580596976562,"mc":[{"id":"1.168175453","rc":[{"batb":[[0,3.3,17.64],[1,2.58,28.01],[2,2.3,385.09]],"ltp":3.3,"tv":1677.36,"id":5071877},{"batb":[[0,1.35,119.31],[1,1.25,505.09],[2,1.16,310.48]],"batl":[[0,1.44,42.01],[1,4,4.23],[2,1.44,0]],"ltp":1.24,"tv":6591.5,"id":6374165}]}]}
{"op":"mcm","clk":"1006508607","pt":1580596978262,"mc":[{"id":"1.168175453","rc":[{"batb":[[0,2.58,28.01],[1,1.01,15.52],[2,2.3,0]],"ltp":3.3,"tv":1677.36,"id":5071877},{"batb":[[0,1.16,310.48],[1,1.01,15.51],[2,1.16,0]],"batl":[[0,4,4.23],[1,4,0]],"ltp":1.24,"tv":6591.5,"id":6374165}]}]}
{"op":"mcm","clk":"1006508722","pt":1580596979555,"mc":[{"id":"1.168175453","rc":[{"batb":[[0,2.6,27.46],[1,2.58,28.01],[2,1.01,15.52]],"ltp":3.3,"tv":1677.36,"id":5071877},{"batb":[[0,1.17,1580.02],[1,1.16,926.14],[2,1.01,15.51]],"batl":[[0,1.6,388.16],[1,1.61,262.67],[2,4,4.23]],"ltp":1.24,"tv":6591.5,"id":6374165}]}]}
{"op":"mcm","clk":"1006508789","pt":1580596980126,"mc":[{"id":"1.168175453","rc":[{"batb":[[1,1.01,15.52],[2,1.01,0]],"ltp":3.3,"tv":1677.36,"id":5071877}]}]}
{"op":"mcm","clk":"1006509791","pt":1580596991794,"mc":[{"id":"1.168175453","rc":[{"batl":[[0,1.37,3.79],[1,1.6,388.16],[2,1.61,262.67]],"ltp":1.24,"tv":6591.5,"id":6374165}]}]}
{"op":"mcm","clk":"1006510160","pt":1580596996187,"mc":[{"id":"1.168175453","rc":[{"batl":[[0,1.6,388.16],[1,1.61,262.67],[2,4,4.23]],"ltp":1.24,"tv":6591.5,"id":6374165}]}]}
{"op":"mcm","clk":"1006513712","pt":1580597036423,"mc":[{"id":"1.168175453","rc":[{"batb":[[0,1.16,310.48],[1,1.01,15.51],[2,1.01,0]],"batl":[[0,4,4.23],[1,1.61,0],[2,4,0]],"ltp":1.24,"tv":6591.5,"id":6374165}]}]}
{"op":"mcm","clk":"1006513967","pt":1580597039421,"mc":[{"id":"1.168175453","rc":[{"batb":[[0,1.32,626.64],[1,1.31,653.75],[2,1.16,310.48]],"batl":[[0,1.36,699.26],[1,1.37,501.75],[2,4,4.23]],"ltp":1.24,"tv":6591.5,"id":6374165}]}]}
{"op":"mcm","clk":"1006514151","pt":1580597041537,"mc":[{"id":"1.168175453","rc":[{"batb":[[1,2.42,381.73],[2,1.01,15.52]],"ltp":3.3,"tv":1677.36,"id":5071877},{"batb":[[2,1.22,523]],"ltp":1.24,"tv":6591.5,"id":6374165}]}]}
{"op":"mcm","clk":"1006514579","pt":1580597046161,"mc":[{"id":"1.168175453","rc":[{"batb":[[0,1.22,523],[1,1.16,310.48],[2,1.01,15.51]],"batl":[[0,4,4.23],[1,1.37,0],[2,4,0]],"ltp":1.24,"tv":6591.5,"id":6374165}]}]}
{"op":"mcm","clk":"1006514796","pt":1580597048227,"mc":[{"id":"1.168175453","rc":[{"batb":[[1,1.01,15.52],[2,1.01,0]],"ltp":3.3,"tv":1677.36,"id":5071877},{"batb":[[0,1.16,310.48],[1,1.01,15.51],[2,1.01,0]],"ltp":1.24,"tv":6591.5,"id":6374165}]}]}
{"op":"mcm","clk":"1006514846","pt":1580597049053,"mc":[{"id":"1.168175453","rc":[{"batb":[[0,1.17,1580.02],[1,1.16,926.14],[2,1.01,15.51]],"batl":[[0,1.6,388.16],[1,1.61,262.67],[2,4,4.23]],"ltp":1.24,"tv":6591.5,"id":6374165}]}]}
{"op":"mcm","clk":"1006515055","pt":1580597051345,"mc":[{"id":"1.168175453","rc":[{"batl":[[0,4,4.23],[1,1.61,0],[2,4,0]],"ltp":1.24,"tv":6591.5,"id":6374165}]}]}
{"op":"mcm","clk":"1006515308","pt":1580597054456,"mc":[{"id":"1.168175453","rc":[{"batl":[[0,1.2,950.11],[1,1.21,986.19],[2,4,4.23]],"ltp":1.24,"tv":6591.5,"id":6374165}]}]}
{"op":"mcm","clk":"1006515361","pt":1580597055176,"mc":[{"id":"1.168175453","rc":[{"batb":[[0,6,34.46],[1,5.3,9.24],[2,3.5,32.34]],"batl":[[0,6.4,7.56]],"ltp":3.3,"tv":1677.36,"id":5071877},{"batb":[[0,1.18,168.04],[1,1.17,1580.02],[2,1.16,926.14]],"batl":[[2,1.23,42.01]],"ltp":1.24,"tv":6591.5,"id":6374165}]}]}
{"op":"mcm","clk":"1006516278","pt":1580597065487,"mc":[{"id":"1.168175453","rc":[{"trd":[[1.18,10]],"batb":[[0,1.18,163.04]],"ltp":1.18,"tv":6601.5,"id":6374165}],"tv":8278.87}]}
{"op":"mcm","clk":"1006516465","pt":1580597067411,"mc":[{"id":"1.168175453","rc":[{"batb":[[1,1.17,1499.95]],"ltp":1.18,"tv":6601.5,"id":6374165}]}]}
{"op":"mcm","clk":"1006516540","pt":1580597068390,"mc":[{"id":"1.168175453","rc":[{"batb":[[0,1.18,167.24]],"ltp":1.18,"tv":6601.5,"id":6374165}]}]}
{"op":"mcm","clk":"1006516736","pt":1580597070509,"mc":[{"id":"1.168175453","rc":[{"trd":[[1.18,55.43]],"batb":[[0,1.18,144.52],[2,1.16,1006.9]],"batl":[[0,1.2,1028.15]],"ltp":1.18,"tv":6646.94,"id":6374165}],"tv":8324.3}]}
{"op":"mcm","clk":"1006516809","pt":1580597071330,"mc":[{"id":"1.168175453","rc":[{"batb":[[1,3.5,32.34],[2,2.98,374.28]],"ltp":3.3,"tv":1677.36,"id":5071877}]}]}
{"op":"mcm","clk":"1006517092","pt":1580597074542,"mc":[{"id":"1.168175453","rc":[{"batb":[[1,5.4,9.24],[2,3.5,32.34]],"batl":[[0,6.6,6.72]],"ltp":3.3,"tv":1677.36,"id":5071877},{"batb":[[0,1.18,167.21]],"ltp":1.18,"tv":6646.94,"id":6374165}]}]}
{"op":"mcm","clk":"1006517156","pt":1580597075225,"mc":[{"id":"1.168175453","rc":[{"batb":[[0,5.4,9.24],[1,3.5,32.34],[2,2.98,374.28]],"ltp":3.3,"tv":1677.36,"id":5071877},{"trd":[[1.18,65.43]],"batb":[[0,1.18,162.21],[1,1.12,650.34],[2,1.01,15.51]],"batl":[[0,1.23,42.01],[1,4,4.23],[2,1.23,0]],"ltp":1.18,"tv":6656.93,"id":6374165}],"tv":8334.3}]}
{"op":"mcm","clk":"1006517281","pt":1580597076525,"mc":[{"id":"1.168175453","rc":[{"batb":[[0,3.5,32.34],[1,1.01,15.52],[2,2.98,0]],"ltp":3.3,"tv":1677.36,"id":5071877},{"batb":[[0,1.01,15.51],[1,1.12,0],[2,1.01,0]],"batl":[[0,4,4.23],[1,4,0]],"ltp":1.18,"tv":6656.93,"id":6374165}]}]}
{"op":"mcm","clk":"1006517369","pt":1580597077515,"mc":[{"id":"1.168175453","rc":[{"batl":[[0,1.4,651.6],[1,1.41,442.16],[2,4,4.23]],"ltp":1.18,"tv":6656.93,"id":6374165}]}]}
{"op":"mcm","clk":"1006517453","pt":1580597078541,"mc":[{"id":"1.168175453","rc":[{"batb":[[0,1.18,5.04],[1,1.01,15.51]],"batl":[[0,4,4.23],[1,1.41,0],[2,4,0]],"ltp":1.18,"tv":6656.93,"id":6374165}]}]}
{"op":"mcm","clk":"1006517461","pt":1580597078646,"mc":[{"id":"1.168175453","rc":[{"batb":[[0,1.01,15.51],[1,1.01,0]],"ltp":1.18,"tv":6656.93,"id":6374165}]}]}
{"op":"mcm","clk":"1006517637","pt":1580597080554,"mc":[{"id":"1.168175453","rc":[{"batb":[[0,1.13,1748.68],[1,1.12,523.91],[2,1.01,15.51]],"batl":[[0,1.15,483.88],[1,1.16,1372.31],[2,4,4.23]],"ltp":1.18,"tv":6656.93,"id":6374165}]}]}
{"op":"mcm","clk":"1006517825","pt":1580597082537,"mc":[{"id":"1.168175453","rc":[{"batb":[[1,3.2,374.33],[2,1.01,15.52]],"ltp":3.3,"tv":1677.36,"id":5071877},{"batb":[[2,1.09,753.06]],"ltp":1.18,"tv":6656.93,"id":6374165}]}]}
{"op":"mcm","clk":"1006518280","pt":1580597087943,"mc":[{"id":"1.168175453","rc":[{"batb":[[0,1.09,753.06],[1,1.01,15.51],[2,1.09,0]],"batl":[[0,4,4.23],[1,1.16,0],[2,4,0]],"ltp":1.18,"tv":6656.93,"id":6374165}]}]}
{"op":"mcm","clk":"1006518488","pt":1580597090542,"mc":[{"id":"1.168175453","rc":[{"batl":[[0,7.6,2]],"ltp":3.3,"tv":1677.36,"id":5071877},{"batl":[[0,1.4,646.62],[1,1.41,442.15],[2,4,4.23]],"ltp":1.18,"tv":6656.93,"id":6374165}]}]}
{"op":"mcm","clk":"1006519114","pt":1580597097459,"mc":[{"id":"1.168175453","rc":[{"batb":[[1,1.01,15.52],[2,1.01,0]],"ltp":3.3,"tv":1677.36,"id":5071877},{"batb":[[0,1.01,15.51],[1,1.01,0]],"ltp":1.18,"tv":6656.93,"id":6374165}]}]}
{"op":"mcm","clk":"1006519303","pt":1580597099543,"mc":[{"id":"1.168175453","rc":[{"batl":[[0,4,4.23],[1,1.41,0],[2,4,0]],"ltp":1.18,"tv":6656.93,"id":6374165}]}]}
{"op":"mcm","clk":"1006519363","pt":1580597100195,"mc":[{"id":"1.168175453","marketDefinition":{"bspMarket":false,"turnInPlayEnabled":true,"persistenceEnabled":true,"marketBaseRate":5.0,"eventId":"29680072","eventTypeId":"2","numberOfWinners":1,"bettingType":"ODDS","marketType":"SET_WINNER","marketTime":"2020-02-01T21:57:00.000Z","suspendTime":"2020-02-01T21:57:00.000Z","bspReconciled":false,"complete":true,"inPlay":true,"crossMatching":true,"runnersVoidable":false,"numberOfActiveRunners":2,"betDelay":3,"status":"SUSPENDED","runners":[{"status":"ACTIVE","sortPriority":1,"id":6374165,"name":"Marco Cecchinato"},{"status":"ACTIVE","sortPriority":2,"id":5071877,"name":"Andrej Martin"}],"regulators":["MR_INT"],"countryCode":"UY","discountAllowed":true,"timezone":"UTC","openDate":"2020-02-01T21:57:00.000Z","version":3147747586,"name":"Set 1 Winner","eventName":"Cecchinato v Martin"},"rc":[{"batb":[[0,1.01,15.52],[1,1.01,0]],"ltp":3.3,"tv":1677.36,"id":5071877}]}]}
{"op":"mcm","clk":"1006522155","pt":1580597132427,"mc":[{"id":"1.168175453","tv":0.0}]}
{"op":"mcm","clk":"1006522247","pt":1580597133309,"mc":[{"id":"1.168175453","marketDefinition":{"bspMarket":false,"turnInPlayEnabled":true,"persistenceEnabled":true,"marketBaseRate":5.0,"eventId":"29680072","eventTypeId":"2","numberOfWinners":1,"bettingType":"ODDS","marketType":"SET_WINNER","marketTime":"2020-02-01T21:57:00.000Z","suspendTime":"2020-02-01T21:57:00.000Z","bspReconciled":false,"complete":true,"inPlay":true,"crossMatching":false,"runnersVoidable":false,"numberOfActiveRunners":0,"betDelay":3,"status":"CLOSED","settledTime":"2020-02-01T22:45:29.000Z","runners":[{"status":"WINNER","sortPriority":1,"id":6374165,"name":"Marco Cecchinato"},{"status":"LOSER","sortPriority":2,"id":5071877,"name":"Andrej Martin"}],"regulators":["MR_INT"],"countryCode":"UY","discountAllowed":true,"timezone":"UTC","openDate":"2020-02-01T21:57:00.000Z","version":3147748437,"name":"Set 1 Winner","eventName":"Cecchinato v Martin"}}]}
