{"op":"mcm","clk":"1006474543","pt":1580596636400,"mc":[{"id":"1.168175449","rc":[{"batb":[[2,6.2,7.56]],"batl":[[0,7.2,31.55],[1,7.6,5.88]],"ltp":7.8,"tv":0.55,"id":13117449},{"batl":[[0,17.5,14.4]],"ltp":50.0,"tv":4.09,"id":13117448},{"batb":[[0,4.8,121.43],[2,4.5,35.88]],"batl":[[0,5.4,29.35],[1,5.6,26.12],[2,5.8,8.4]],"ltp":5.8,"tv":93.9,"id":13117392},{"batb":[[0,1.69,53.5],[1,1.64,194.12],[2,1.63,132.88]],"batl":[[0,1.71,42.01],[1,1.75,52.48],[2,1.82,7.5]],"ltp":1.48,"tv":1744.41,"id":13117391}]}]}
{"op":"mcm","clk":"1006474578","pt":1580596636816,"mc":[{"id":"1.168175449","rc":[{"batb":[[0,4.8,110.51]],"batl":[[2,5.8,0]],"ltp":5.8,"tv":93.9,"id":13117392}]}]}
{"op":"mcm","clk":"1006474830","pt":1580596639511,"mc":[{"id":"1.168175449","rc":[{"batb":[[1,4.7,84.79]],"batl":[[1,5.6,34.52]],"ltp":5.8,"tv":93.9,"id":13117392},{"trd":[[1.69,50.41]],"batb":[[0,1.69,28.3]],"ltp":1.69,"tv":1794.83,"id":13117391}],"tv":1893.37}]}
{"op":"mcm","clk":"1006475080","pt":1580596642520,"mc":[{"id":"1.168175449","rc":[{"batb":[[0,15.5,28.77],[1,13,15.42],[2,8.4,16.84]],"ltp":50.0,"tv":4.09,"id":13117448}]}]}
{"op":"mcm","clk":"1006475334","pt":1580596645136,"mc":[{"id":"1.168175449","rc":[{"batb":[[0,16,12.77],[1,15.5,28.77],[2,13,15.42]],"ltp":50.0,"tv":4.09,"id":13117448}]}]}
{"op":"mcm","clk":"1006476086","pt":1580596653454,"mc":[{"id":"1.168175449","rc":[{"batb":[[0,6.8,48.31]],"ltp":7.8,"tv":0.55,"id":13117449}]}]}
{"op":"mcm","clk":"1006476290","pt":1580596655438,"mc":[{"id":"1.168175449","rc":[{"batb":[[0,16,17.5]],"ltp":50.0,"tv":4.09,"id":13117448}]}]}
{"op":"mcm","clk":"1006476827","pt":1580596660546,"mc":[{"id":"1.168175449","rc":[{"batb":[[0,6.6,34.07],[1,6.2,7.56],[2,6,34.86]],"ltp":7.8,"tv":0.55,"id":13117449},{"batb":[[0,13,15.42],[1,8.4,16.84],[2,1.01,0.51]],"ltp":50.0,"tv":4.09,"id":13117448},{"batb":[[0,4.8,30.61],[1,4.7,10.92]],"ltp":5.8,"tv":93.9,"id":13117392},{"batb":[[1,1.58,139.06],[2,1.01,0.51]],"ltp":1.69,"tv":1794.83,"id":13117391}]}]}
{"op":"mcm","clk":"1006476917","pt":1580596661527,"mc":[{"id":"1.168175449","rc":[{"batb":[[1,6,34.86],[2,1.01,0.51]],"batl":[[1,7.6,0]],"ltp":7.8,"tv":0.55,"id":13117449},{"batb":[[0,8.4,16.84],[1,1.01,0.51],[2,1.01,0]],"ltp":50.0,"tv":4.09,"id":13117448},{"batb":[[0,4.5,35.88],[1,1.01,0.51],[2,4.5,0]],"batl":[[0,5.6,26.12],[1,5.6,0]],"ltp":5.8,"tv":93.9,"id":13117392},{"batb":[[0,1.58,66.8],[1,1.01,0.51],[2,1.01,0]],"batl":[[0,1.82,7.5],[1,1.95,36.98],[2,1.82,0]],"ltp":1.69,"tv":1794.83,"id":13117391}]}]}
{"op":"mcm","clk":"1006477097","pt":1580596663404,"mc":[{"id":"1.168175449","rc":[{"batb":[[1,6.4,75.59],[2,6,34.86]],"ltp":7.8,"tv":0.55,"id":13117449},{"batb":[[0,9.4,40.21],[1,9.2,34.53],[2,8.4,16.84]],"ltp":50.0,"tv":4.09,"id":13117448},{"batb":[[0,4.5,117.89],[1,4.4,85.9],[2,1.01,0.51]],"ltp":5.8,"tv":93.9,"id":13117392},{"batb":[[1,1.55,212.38],[2,1.54,164.74]],"ltp":1.69,"tv":1794.83,"id":13117391}]}]}
{"op":"mcm","clk":"1006477173","pt":1580596664229,"mc":[{"id":"1.168175449","rc":[{"batl":[[0,7.4,30.21]],"ltp":7.8,"tv":0.55,"id":13117449},{"batb":[[2,8.6,15.97]],"ltp":50.0,"tv":4.09,"id":13117448},{"batl":[[0,5.7,26.04]],"ltp":5.8,"tv":93.9,"id":13117392},{"batb":[[0,1.57,68.45]],"batl":[[1,1.93,38.16]],"ltp":1.69,"tv":1794.83,"id":13117391}]}]}
{"op":"mcm","clk":"1006477275","pt":1580596665320,"mc":[{"id":"1.168175449","rc":[{"batb":[[1,6,34.86],[2,1.01,0.51]],"ltp":7.8,"tv":0.55,"id":13117449},{"batb":[[0,8.6,15.97],[1,1.01,0.51],[2,8.6,0]],"ltp":50.0,"tv":4.09,"id":13117448},{"batb":[[0,4.5,35.88],[1,1.01,0.51],[2,1.01,0]],"ltp":5.8,"tv":93.9,"id":13117392},{"batb":[[1,1.01,0.51],[2,1.54,0]],"ltp":1.69,"tv":1794.83,"id":13117391}]}]}
{"op":"mcm","clk":"1006477618","pt":1580596668322,"mc":[{"id":"1.168175449","rc":[{"batb":[[0,6.8,32.38],[1,6.6,70.71],[2,6,34.86]],"ltp":7.8,"tv":0.55,"id":13117449},{"batb":[[0,14,24.07],[1,13.5,38.01],[2,8.6,15.97]],"ltp":50.0,"tv":4.09,"id":13117448},{"batb":[[0,4.7,104.04],[1,4.6,77.12],[2,4.5,35.88]],"ltp":5.8,"tv":93.9,"id":13117392},{"batb":[[0,1.67,190.51],[1,1.66,124.51],[2,1.57,68.45]],"ltp":1.69,"tv":1794.83,"id":13117391}]}]}
{"op":"mcm","clk":"1006477898","pt":1580596670913,"mc":[{"id":"1.168175449","rc":[{"batb":[[0,6.6,34.07],[1,6,34.86],[2,1.01,0.51]],"ltp":7.8,"tv":0.55,"id":13117449},{"batb":[[0,8.6,15.97],[1,1.01,0.51],[2,8.6,0]],"ltp":50.0,"tv":4.09,"id":13117448},{"batb":[[0,4.5,35.88],[1,1.01,0.51],[2,4.5,0]],"ltp":5.8,"tv":93.9,"id":13117392},{"batb":[[0,1.57,68.45],[1,1.01,0.51],[2,1.57,0]],"ltp":1.69,"tv":1794.83,"id":13117391}]}]}
{"op":"mcm","clk":"1006478250","pt":1580596674552,"mc":[{"id":"1.168175449","rc":[{"batb":[[1,6.4,75.59],[2,6,34.86]],"ltp":7.8,"tv":0.55,"id":13117449},{"batb":[[0,9.4,40.21],[1,9.2,34.53],[2,8.6,15.97]],"ltp":50.0,"tv":4.09,"id":13117448},{"batb":[[0,4.5,117.89],[1,4.4,85.9],[2,1.01,0.51]],"ltp":5.8,"tv":93.9,"id":13117392}]}]}
{"op":"mcm","clk":"1006478353","pt":1580596675443,"mc":[{"id":"1.168175449","rc":[{"trd":[[1.82,30]],"batb":[[0,1.82,122.86],[1,1.8,187.51],[2,1.57,68.45]],"batl":[[0,1.93,38.16],[1,1.93,0]],"ltp":1.82,"tv":1809.83,"id":13117391}],"tv":1908.37}]}
{"op":"mcm","clk":"1006478449","pt":1580596676541,"mc":[{"id":"1.168175449","rc":[{"batb":[[2,6,8.4]],"batl":[[0,7,33.44],[1,7.2,39.53]],"ltp":7.8,"tv":0.55,"id":13117449},{"batb":[[0,9.4,44.41]],"batl":[[0,10.5,15.26],[1,12.5,3.36],[2,14.5,21.01]],"ltp":50.0,"tv":4.09,"id":13117448},{"batb":[[1,4.4,97.66],[2,4.2,41.39]],"batl":[[0,5,34.31],[1,5.2,40.48]],"ltp":5.8,"tv":93.9,"id":13117392},{"batb":[[0,1.86,38.79],[1,1.82,122.86],[2,1.8,187.51]],"batl":[[0,1.9,42.01],[1,1.93,38.16],[2,2.18,53.35]],"ltp":1.82,"tv":1809.83,"id":13117391}]}]}
{"op":"mcm","clk":"1006480474","pt":1580596695471,"mc":[{"id":"1.168175449","rc":[{"batl":[[1,14.5,21.01],[2,14.5,0]],"ltp":50.0,"tv":4.09,"id":13117448},{"batl":[[1,5.2,31.24]],"ltp":5.8,"tv":93.9,"id":13117392},{"trd":[[1.9,51.4]],"batl":[[0,1.93,38.16],[1,2.18,53.35],[2,2.18,0]],"ltp":1.9,"tv":1861.23,"id":13117391}],"tv":1959.77}]}
{"op":"mcm","clk":"1006480800","pt":1580596698530,"mc":[{"id":"1.168175449","rc":[{"batb":[[0,6,8.4],[1,5.9,38.63],[2,1.01,0.51]],"batl":[[0,7.2,39.53],[1,7.2,0]],"ltp":7.8,"tv":0.55,"id":13117449},{"batb":[[0,9.4,4.2],[1,6.4,31.94],[2,1.01,0.51]],"batl":[[0,12,3.36],[1,14.5,20.77]],"ltp":50.0,"tv":4.09,"id":13117448},{"batb":[[0,4.4,11.76],[1,4.2,41.39],[2,1.01,0.51]],"batl":[[0,5.1,10.08]],"ltp":5.8,"tv":93.9,"id":13117392},{"batb":[[0,1.77,53.77],[1,1.74,47.76],[2,1.01,0.51]],"batl":[[0,1.91,42.01]],"ltp":1.9,"tv":1861.23,"id":13117391}]}]}
{"op":"mcm","clk":"1006480909","pt":1580596699569,"mc":[{"id":"1.168175449","rc":[{"batb":[[0,5.9,38.63],[1,1.01,0.51],[2,1.01,0]],"batl":[[0,7.2,32.81]],"ltp":7.8,"tv":0.55,"id":13117449},{"batb":[[0,6.4,31.94],[1,1.01,0.51],[2,1.01,0]],"batl":[[0,14.5,20.77],[1,14.5,0]],"ltp":50.0,"tv":4.09,"id":13117448},{"batb":[[0,4.2,41.39],[1,1.01,0.51],[2,1.01,0]],"batl":[[0,5.2,31.24],[1,5.2,0]],"ltp":5.8,"tv":93.9,"id":13117392},{"batb":[[0,1.74,47.76],[1,1.01,0.51],[2,1.01,0]],"batl":[[0,2.18,53.35],[1,2.18,0]],"ltp":1.9,"tv":1861.23,"id":13117391}]}]}
{"op":"mcm","clk":"1006481078","pt":1580596701184,"mc":[{"id":"1.168175449","rc":[{"batb":[[0,6.2,109.8],[1,6,84.85],[2,5.9,38.63]],"ltp":7.8,"tv":0.55,"id":13117449},{"batb":[[0,6.6,51.56],[1,6.4,106.92],[2,1.01,0.51]],"ltp":50.0,"tv":4.09,"id":13117448},{"batb":[[0,4.2,168.27],[1,4.1,100.35],[2,1.01,0.51]],"ltp":5.8,"tv":93.9,"id":13117392},{"batb":[[1,1.7,217],[2,1.68,237.35]],"ltp":1.9,"tv":1861.23,"id":13117391}]}]}
{"op":"mcm","clk":"1006481302","pt":1580596703301,"mc":[{"id":"1.168175449","rc":[{"batb":[[0,5.9,38.63],[1,1.01,0.51],[2,5.9,0]],"ltp":7.8,"tv":0.55,"id":13117449},{"batb":[[0,6.4,31.94],[1,1.01,0.51],[2,1.01,0]],"ltp":50.0,"tv":4.09,"id":13117448},{"batb":[[0,4.2,41.39],[1,1.01,0.51],[2,1.01,0]],"ltp":5.8,"tv":93.9,"id":13117392}]}]}
{"op":"mcm","clk":"1006481585","pt":1580596706429,"mc":[{"id":"1.168175449","rc":[{"batb":[[0,6.6,82.74],[1,6.4,74.3],[2,6,8.4]],"batl":[[0,7.2,39.53]],"ltp":7.8,"tv":0.55,"id":13117449},{"batb":[[0,12.5,42.04],[1,12,47.97],[2,6.4,31.94]],"ltp":50.0,"tv":4.09,"id":13117448},{"batb":[[0,4.7,55.67],[1,4.6,88.85],[2,4.2,41.39]],"batl":[[1,5.4,9.24]],"ltp":5.8,"tv":93.9,"id":13117392},{"batb":[[2,1.68,298.68]],"batl":[[0,1.81,42.01],[1,2.18,53.35]],"ltp":1.9,"tv":1861.23,"id":13117391}]}]}
{"op":"mcm","clk":"1006481674","pt":1580596707310,"mc":[{"id":"1.168175449","rc":[{"batb":[[2,6,44.99]],"batl":[[1,7.4,31.16]],"ltp":7.8,"tv":0.55,"id":13117449},{"batb":[[2,11,22.58]],"ltp":50.0,"tv":4.09,"id":13117448},{"batb":[[0,4.7,88.32],[2,4.2,41.23]],"batl":[[2,5.6,27.07]],"ltp":5.8,"tv":93.9,"id":13117392},{"batb":[[2,1.68,237.35]],"batl":[[0,1.81,46.97],[1,2.14,56.89]],"ltp":1.9,"tv":1861.23,"id":13117391}]}]}
{"op":"mcm","clk":"1006481902","pt":1580596709504,"mc":[{"id":"1.168175449","rc":[{"batl":[[0,1.8,42.01],[1,1.81,46.97],[2,2.14,56.89]],"ltp":1.9,"tv":1861.23,"id":13117391}]}]}
{"op":"mcm","clk":"1006483337","pt":1580596723536,"mc":[{"id":"1.168175449","rc":[{"batb":[[0,6.4,58.17],[1,6,36.59],[2,1.01,0.51]],"batl":[[0,7.4,31.16],[1,7.4,0]],"ltp":7.8,"tv":0.55,"id":13117449},{"batb":[[0,6.6,29.11],[1,1.01,0.51],[2,11,0]],"ltp":50.0,"tv":4.09,"id":13117448},{"batb":[[0,4.2,41.23],[1,1.01,0.51],[2,4.2,0]],"batl":[[0,5.6,27.07],[1,5.4,0],[2,5.6,0]],"ltp":5.8,"tv":93.9,"id":13117392},{"batb":[[0,1.59,65.86],[1,1.01,0.51],[2,1.68,0]],"batl":[[0,2.14,56.89],[1,1.81,0],[2,2.14,0]],"ltp":1.9,"tv":1861.23,"id":13117391}]}]}
{"op":"mcm","clk":"1006483644","pt":1580596726544,"mc":[{"id":"1.168175449","rc":[{"batl":[[0,5.5,27.22],[1,5.6,27.07]],"ltp":5.8,"tv":93.9,"id":13117392},{"batl":[[0,2.12,57.28],[1,2.14,56.89]],"ltp":1.9,"tv":1861.23,"id":13117391}]}]}
{"op":"mcm","clk":"1006483666","pt":1580596726755,"mc":[{"id":"1.168175449","rc":[{"batb":[[1,6,36.12]],"batl":[[0,7.4,30.69]],"ltp":7.8,"tv":0.55,"id":13117449},{"batb":[[0,6.6,28.72]],"ltp":50.0,"tv":4.09,"id":13117448},{"batl":[[1,5.6,0]],"ltp":5.8,"tv":93.9,"id":13117392},{"batl":[[1,2.14,0]],"ltp":1.9,"tv":1861.23,"id":13117391}]}]}
{"op":"mcm","clk":"1006483858","pt":1580596728562,"mc":[{"id":"1.168175449","rc":[{"batb":[[0,6.6,62.3],[1,6.4,74.83],[2,6,36.12]],"ltp":7.8,"tv":0.55,"id":13117449},{"batb":[[0,10.5,61.3],[1,10,69.02],[2,6.6,28.72]],"ltp":50.0,"tv":4.09,"id":13117448},{"batb":[[0,4.6,63.23],[1,4.5,81.83],[2,4.2,41.23]],"ltp":5.8,"tv":93.9,"id":13117392},{"batb":[[0,1.76,167.28],[1,1.74,210.04],[2,1.59,65.86]],"ltp":1.9,"tv":1861.23,"id":13117391}]}]}
{"op":"mcm","clk":"1006484262","pt":1580596732442,"mc":[{"id":"1.168175449","rc":[{"batb":[[0,6.4,58.17],[1,6,36.12],[2,1.01,0.51]],"ltp":7.8,"tv":0.55,"id":13117449},{"batb":[[0,6.6,28.72],[1,1.01,0.51],[2,6.6,0]],"ltp":50.0,"tv":4.09,"id":13117448},{"batb":[[0,4.2,41.23],[1,1.01,0.51],[2,4.2,0]],"ltp":5.8,"tv":93.9,"id":13117392},{"batb":[[0,1.59,65.86],[1,1.01,0.51],[2,1.59,0]],"ltp":1.9,"tv":1861.23,"id":13117391}]}]}
{"op":"mcm","clk":"1006484567","pt":1580596735337,"mc":[{"id":"1.168175449","rc":[{"batb":[[1,6.2,80.2],[2,6,36.12]],"ltp":7.8,"tv":0.55,"id":13117449},{"batb":[[0,6.6,122.94],[1,6.4,73.67],[2,1.01,0.51]],"ltp":50.0,"tv":4.09,"id":13117448},{"batb":[[0,4.2,176.62],[1,4.1,100.12],[2,1.01,0.51]],"ltp":5.8,"tv":93.9,"id":13117392}]}]}
{"op":"mcm","clk":"1006484901","pt":1580596738553,"mc":[{"id":"1.168175449","rc":[{"batl":[[0,6.6,6.72],[1,7.2,32.1],[2,7.4,30.69]],"ltp":7.8,"tv":0.55,"id":13117449},{"batb":[[1,6.4,81.23],[2,5.6,21.64]],"batl":[[0,7.8,32.95],[1,11.5,32.81]],"ltp":50.0,"tv":4.09,"id":13117448},{"batb":[[2,4,59.16]],"batl":[[0,4.7,50.34],[1,5,33.91],[2,5.5,27.22]],"ltp":5.8,"tv":93.9,"id":13117392},{"batb":[[0,2.06,39.49],[1,2.02,243.59],[2,2,134.4]],"batl":[[1,2.26,32.77],[2,2.34,44.38]],"ltp":1.9,"tv":1861.23,"id":13117391}]}]}
{"op":"mcm","clk":"1006484996","pt":1580596739532,"mc":[{"id":"1.168175449","rc":[{"batl":[[2,7.4,0]],"ltp":7.8,"tv":0.55,"id":13117449},{"batl":[[2,5.5,0]],"ltp":5.8,"tv":93.9,"id":13117392}]}]}
{"op":"mcm","clk":"1006485722","pt":1580596747288,"mc":[{"id":"1.168175449","rc":[{"batl":[[1,7,33.83],[2,7.2,32.1]],"ltp":7.8,"tv":0.55,"id":13117449},{"batb":[[2,5.6,21.48]],"ltp":50.0,"tv":4.09,"id":13117448},{"batl":[[0,2.14,57.2],[2,2.34,43.98]],"ltp":1.9,"tv":1861.23,"id":13117391}]}]}
{"op":"mcm","clk":"1006487270","pt":1580596763059,"mc":[{"id":"1.168175449","rc":[{"batl":[[1,11,34.54]],"ltp":50.0,"tv":4.09,"id":13117448},{"batl":[[0,4.7,50.18]],"ltp":5.8,"tv":93.9,"id":13117392},{"batb":[[1,2.04,58.62],[2,2.02,184.66]],"batl":[[0,2.14,56.97],[2,2.34,43.75]],"ltp":1.9,"tv":1861.23,"id":13117391}]}]}
{"op":"mcm","clk":"1006488143","pt":1580596771489,"mc":[{"id":"1.168175449","rc":[{"batb":[[2,5.5,22.35]],"batl":[[0,7.6,28.25],[1,7.8,5.88],[2,11,14.32]],"ltp":50.0,"tv":4.09,"id":13117448},{"batb":[[1,2.04,57.6]],"batl":[[0,2.14,55.94],[2,2.36,42.88]],"ltp":1.9,"tv":1861.23,"id":13117391}]}]}
{"op":"mcm","clk":"1006489307","pt":1580596784112,"mc":[{"id":"1.168175449","rc":[{"batb":[[2,5.9,37.61]],"batl":[[1,7,33.6],[2,7.2,0]],"ltp":7.8,"tv":0.55,"id":13117449},{"batb":[[0,6.6,94.22],[1,6.4,112.23],[2,5.4,23.05]],"batl":[[2,10.5,14.79]],"ltp":50.0,"tv":4.09,"id":13117448},{"batb":[[0,4.2,176.38]],"batl":[[0,4.7,49.87]],"ltp":5.8,"tv":93.9,"id":13117392},{"batb":[[0,2.06,95.98],[1,2.02,184.66],[2,2,134.4]],"batl":[[0,2.16,55],[2,2.38,42.02]],"ltp":1.9,"tv":1861.23,"id":13117391}]}]}
{"op":"mcm","clk":"1006492091","pt":1580596814402,"mc":[{"id":"1.168175449","rc":[{"batb":[[0,6.2,80.2],[1,5.8,39.73],[2,5.6,8.4]],"ltp":7.8,"tv":0.55,"id":13117449},{"batb":[[0,6.4,7.56],[1,5.4,23.05],[2,1.01,0.51]],"batl":[[0,7.8,5.88],[1,10.5,14.79],[2,10.5,0]],"ltp":50.0,"tv":4.09,"id":13117448},{"batb":[[0,4.1,80.28],[1,4,59.16],[2,1.01,0.51]],"batl":[[0,4.7,10.92]],"ltp":5.8,"tv":93.9,"id":13117392},{"batb":[[0,2.06,39.49],[1,1.85,39.34],[2,1.01,0.51]],"batl":[[0,2.26,32.77],[1,2.38,42.02],[2,2.38,0]],"ltp":1.9,"tv":1861.23,"id":13117391}]}]}
{"op":"mcm","clk":"1006492273","pt":1580596816229,"mc":[{"id":"1.168175449","rc":[{"batb":[[2,1.01,0.51]],"batl":[[0,7,33.6],[1,7,0]],"ltp":7.8,"tv":0.55,"id":13117449},{"batb":[[0,5.4,23.05],[1,1.01,0.51],[2,1.01,0]],"batl":[[0,10.5,14.79],[1,10.5,0]],"ltp":50.0,"tv":4.09,"id":13117448},{"batb":[[0,4,45.71],[1,1.01,0.51],[2,1.01,0]],"batl":[[0,5,33.91],[1,5,0]],"ltp":5.8,"tv":93.9,"id":13117392},{"batb":[[0,1.85,39.34],[1,1.01,0.51],[2,1.01,0]],"batl":[[0,2.38,42.02],[1,2.38,0]],"ltp":1.9,"tv":1861.23,"id":13117391}]}]}
{"op":"mcm","clk":"1006492603","pt":1580596819502,"mc":[{"id":"1.168175449","rc":[{"batb":[[0,6.4,76.13],[1,6.2,80.2],[2,5.8,39.73]],"ltp":7.8,"tv":0.55,"id":13117449},{"batb":[[0,7,74.07],[1,6.8,65.08],[2,5.4,23.05]],"ltp":50.0,"tv":4.09,"id":13117448},{"batb":[[0,4.3,81.93],[1,4.2,95.71],[2,4,45.71]],"ltp":5.8,"tv":93.9,"id":13117392}]}]}
{"op":"mcm","clk":"1006492924","pt":1580596823140,"mc":[{"id":"1.168175449","rc":[{"batb":[[0,1.99,102.12],[1,1.97,140.83],[2,1.85,39.34]],"ltp":1.9,"tv":1861.23,"id":13117391}]}]}
{"op":"mcm","clk":"1006493205","pt":1580596825950,"mc":[{"id":"1.168175449","rc":[{"batb":[[0,6.2,80.2],[1,5.8,39.73],[2,1.01,0.51]],"ltp":7.8,"tv":0.55,"id":13117449},{"batb":[[0,5.4,23.05],[1,1.01,0.51],[2,5.4,0]],"ltp":50.0,"tv":4.09,"id":13117448},{"batb":[[0,4,45.71],[1,1.01,0.51],[2,4,0]],"ltp":5.8,"tv":93.9,"id":13117392},{"batb":[[0,1.85,39.34],[1,1.01,0.51],[2,1.85,0]],"ltp":1.9,"tv":1861.23,"id":13117391}]}]}
{"op":"mcm","clk":"1006493625","pt":1580596829850,"mc":[{"id":"1.168175449","rc":[{"batb":[[1,6,85.84],[2,5.8,39.73]],"ltp":7.8,"tv":0.55,"id":13117449},{"batb":[[0,5.7,47.28],[1,5.6,51.12],[2,5.4,23.05]],"ltp":50.0,"tv":4.09,"id":13117448},{"batb":[[0,4.1,79.48],[1,4,153],[2,1.01,0.51]],"ltp":5.8,"tv":93.9,"id":13117392},{"batb":[[1,1.83,124.08],[2,1.81,184.23]],"ltp":1.9,"tv":1861.23,"id":13117391}]}]}
{"op":"mcm","clk":"1006494350","pt":1580596836472,"mc":[{"id":"1.168175449","rc":[{"batb":[[0,5.8,39.73],[1,1.01,0.51],[2,5.8,0]],"ltp":7.8,"tv":0.55,"id":13117449},{"batb":[[0,5.4,23.05],[1,1.01,0.51],[2,5.4,0]],"ltp":50.0,"tv":4.09,"id":13117448},{"batb":[[0,4,45.71],[1,1.01,0.51],[2,1.01,0]],"ltp":5.8,"tv":93.9,"id":13117392}]}]}
{"op":"mcm","clk":"1006494682","pt":1580596839375,"mc":[{"id":"1.168175449","rc":[{"batb":[[0,6.6,70.09],[1,6.4,74.66],[2,5.8,39.73]],"ltp":7.8,"tv":0.55,"id":13117449},{"batb":[[0,9,39.4],[1,8.8,37.82],[2,5.4,23.05]],"ltp":50.0,"tv":4.09,"id":13117448},{"batb":[[0,4.5,75.58],[1,4.4,86.03],[2,4,45.71]],"ltp":5.8,"tv":93.9,"id":13117392}]}]}
{"op":"mcm","clk":"1006494794","pt":1580596840564,"mc":[{"id":"1.168175449","rc":[{"batb":[[2,6,35.96]],"batl":[[0,6.8,6.72],[1,7.4,30.92]],"ltp":7.8,"tv":0.55,"id":13117449},{"batb":[[1,8.8,53.24],[2,8,5.88]],"batl":[[0,10,4.2],[1,10.5,14.79],[2,19.5,11.72]],"ltp":50.0,"tv":4.09,"id":13117448},{"batb":[[0,4.5,111.14],[2,4.3,40.21]],"batl":[[0,4.9,10.08],[1,5,33.91],[2,5.4,28.48]],"ltp":5.8,"tv":93.9,"id":13117392},{"batb":[[0,1.87,47.89],[1,1.85,39.34],[2,1.83,124.08]],"batl":[[0,1.92,38.63],[1,2.06,39.49],[2,2.12,57.75]],"ltp":1.9,"tv":1861.23,"id":13117391}]}]}
{"op":"mcm","clk":"1006497351","pt":1580596864420,"mc":[{"id":"1.168175449","rc":[{"trd":[[1.92,4]],"batl":[[0,1.92,36.63]],"ltp":1.92,"tv":1865.23,"id":13117391}],"tv":1963.77}]}
{"op":"mcm","clk":"1006498836","pt":1580596876431,"mc":[{"id":"1.168175449","rc":[{"batl":[[2,2.1,23.95]],"ltp":1.92,"tv":1865.23,"id":13117391}]}]}
{"op":"mcm","clk":"1006498882","pt":1580596876847,"mc":[{"id":"1.168175449","rc":[{"batb":[[0,6.4,74.66],[1,6,35.96],[2,5.9,37.61]],"ltp":7.8,"tv":0.55,"id":13117449},{"batb":[[0,8.8,15.42],[1,8,5.88],[2,6.6,28.25]],"ltp":50.0,"tv":4.09,"id":13117448},{"batb":[[0,4.5,35.56],[1,4.3,40.21],[2,4.2,12.6]],"ltp":5.8,"tv":93.9,"id":13117392},{"batb":[[2,1.65,57.6]],"ltp":1.92,"tv":1865.23,"id":13117391}]}]}
{"op":"mcm","clk":"1006499154","pt":1580596879560,"mc":[{"id":"1.168175449","rc":[{"batb":[[1,6.2,79.96],[2,6,35.96]],"ltp":7.8,"tv":0.55,"id":13117449},{"batb":[[2,7,43.44]],"ltp":50.0,"tv":4.09,"id":13117448},{"batb":[[1,4.3,100.1],[2,4.2,108.68]],"ltp":5.8,"tv":93.9,"id":13117392}]}]}
{"op":"mcm","clk":"1006499261","pt":1580596880557,"mc":[{"id":"1.168175449","rc":[{"batl":[[2,2.12,57.75]],"ltp":1.92,"tv":1865.23,"id":13117391}]}]}
{"op":"mcm","clk":"1006499352","pt":1580596881340,"mc":[{"id":"1.168175449","rc":[{"batb":[[2,5.9,37.61]],"ltp":7.8,"tv":0.55,"id":13117449},{"batb":[[0,8,5.88],[1,7,43.44],[2,6.8,65.75]],"batl":[[1,19.5,11.72],[2,19.5,0]],"ltp":50.0,"tv":4.09,"id":13117448},{"batb":[[0,4.3,100.1],[1,4.2,108.68],[2,1.01,0.51]],"batl":[[1,5.4,28.48],[2,5.4,0]],"ltp":5.8,"tv":93.9,"id":13117392},{"batb":[[1,1.65,57.6],[2,1.64,138.17]],"batl":[[0,2.06,39.49],[1,2.12,57.75],[2,2.12,0]],"ltp":1.92,"tv":1865.23,"id":13117391}]}]}
{"op":"mcm","clk":"1006499384","pt":1580596881655,"mc":[{"id":"1.168175449","rc":[{"batl":[[0,7.4,30.92],[1,7.4,0]],"ltp":7.8,"tv":0.55,"id":13117449},{"batb":[[0,7,43.44],[1,6.8,65.75],[2,6.6,28.25]],"batl":[[0,19.5,11.72],[1,19.5,0]],"ltp":50.0,"tv":4.09,"id":13117448},{"batb":[[1,4.2,96.08]],"batl":[[0,5.4,28.48],[1,5.4,0]],"ltp":5.8,"tv":93.9,"id":13117392},{"batb":[[0,1.65,57.6],[1,1.64,138.17],[2,1.63,133.01]],"batl":[[0,2.12,57.75],[1,2.12,0]],"ltp":1.92,"tv":1865.23,"id":13117391}]}]}
{"op":"mcm","clk":"1006499648","pt":1580596884548,"mc":[{"id":"1.168175449","rc":[{"batl":[[0,7.2,31.55]],"ltp":7.8,"tv":0.55,"id":13117449},{"batl":[[0,19,11.96]],"ltp":50.0,"tv":4.09,"id":13117448},{"batb":[[0,4.3,99.86]],"ltp":5.8,"tv":93.9,"id":13117392},{"batb":[[0,1.65,57.12]],"batl":[[0,2.14,57.2]],"ltp":1.92,"tv":1865.23,"id":13117391}]}]}
{"op":"mcm","clk":"1006499814","pt":1580596886418,"mc":[{"id":"1.168175449","rc":[{"batb":[[1,1.01,0.51],[2,1.63,0]],"ltp":1.92,"tv":1865.23,"id":13117391}]}]}
{"op":"mcm","clk":"1006500103","pt":1580596889428,"mc":[{"id":"1.168175449","rc":[{"batb":[[0,2,117.58],[1,1.98,138.65],[2,1.65,57.12]],"ltp":1.92,"tv":1865.23,"id":13117391}]}]}
{"op":"mcm","clk":"1006500204","pt":1580596890568,"mc":[{"id":"1.168175449","rc":[{"batl":[[0,6.8,6.72],[1,7,34.23]],"ltp":7.8,"tv":0.55,"id":13117449},{"batb":[[1,6.8,72.47]],"batl":[[0,7.8,27.07],[1,8.2,5.04],[2,12.5,27.62]],"ltp":50.0,"tv":4.09,"id":13117448},{"batb":[[2,4.1,45.48]],"batl":[[0,4.7,10.92],[1,4.8,38],[2,5.1,32.57]],"ltp":5.8,"tv":93.9,"id":13117392},{"batb":[[0,2.02,100.02],[1,2,117.58],[2,1.98,138.65]],"batl":[[1,2.22,33.61],[2,2.4,41.54]],"ltp":1.92,"tv":1865.23,"id":13117391}]}]}
{"op":"mcm","clk":"1006500279","pt":1580596891346,"mc":[{"id":"1.168175449","rc":[{"batl":[[1,8.4,5.04]],"ltp":50.0,"tv":4.09,"id":13117448},{"batl":[[0,4.6,10.92]],"ltp":5.8,"tv":93.9,"id":13117392},{"batl":[[1,2.2,34.45]],"ltp":1.92,"tv":1865.23,"id":13117391}]}]}
{"op":"mcm","clk":"1006500415","pt":1580596892542,"mc":[{"id":"1.168175449","rc":[{"batl":[[1,12.5,27.62],[2,12.5,0]],"ltp":50.0,"tv":4.09,"id":13117448},{"batl":[[1,2.4,41.54],[2,2.4,0]],"ltp":1.92,"tv":1865.23,"id":13117391}]}]}
{"op":"mcm","clk":"1006500635","pt":1580596894464,"mc":[{"id":"1.168175449","rc":[{"batl":[[1,8.2,5.04],[2,12.5,27.62]],"ltp":50.0,"tv":4.09,"id":13117448},{"batl":[[1,2.22,33.61],[2,2.4,41.54]],"ltp":1.92,"tv":1865.23,"id":13117391}]}]}
{"op":"mcm","clk":"1006501940","pt":1580596907549,"mc":[{"id":"1.168175449","rc":[{"batb":[[0,6.2,79.96],[1,5.9,37.61],[2,5.8,39.89]],"ltp":7.8,"tv":0.55,"id":13117449},{"batb":[[0,6.8,6.72],[1,6.6,28.25],[2,5.4,23.68]],"ltp":50.0,"tv":4.09,"id":13117448},{"batb":[[0,4.3,39.97],[1,4.1,45.48],[2,4,13.44]],"ltp":5.8,"tv":93.9,"id":13117392},{"batb":[[1,1.8,42.96],[2,1.01,0.51]],"ltp":1.92,"tv":1865.23,"id":13117391}]}]}
{"op":"mcm","clk":"1006501980","pt":1580596907967,"mc":[{"id":"1.168175449","rc":[{"batb":[[1,5.8,39.89],[2,1.01,0.51]],"batl":[[0,7,34.23],[1,7,0]],"ltp":7.8,"tv":0.55,"id":13117449},{"batb":[[0,5.4,23.68],[1,1.01,0.51],[2,5.4,0]],"batl":[[0,12.5,27.62],[1,8.2,0],[2,12.5,0]],"ltp":50.0,"tv":4.09,"id":13117448},{"batb":[[0,4.1,45.48],[1,1.01,0.51],[2,4,0]],"batl":[[0,5.1,32.57],[1,4.8,0],[2,5.1,0]],"ltp":5.8,"tv":93.9,"id":13117392},{"batb":[[0,1.8,42.96],[1,1.01,0.51],[2,1.01,0]],"batl":[[0,2.4,41.54],[1,2.22,0],[2,2.4,0]],"ltp":1.92,"tv":1865.23,"id":13117391}]}]}
{"op":"mcm","clk":"1006502234","pt":1580596910360,"mc":[{"id":"1.168175449","rc":[{"batb":[[1,6,85.64],[2,5.8,39.89]],"ltp":7.8,"tv":0.55,"id":13117449},{"batb":[[0,5.7,62.5],[1,5.6,51],[2,5.4,23.68]],"ltp":50.0,"tv":4.09,"id":13117448},{"batb":[[0,4.1,109.13],[1,4,107.5],[2,1.01,0.51]],"ltp":5.8,"tv":93.9,"id":13117392},{"batb":[[1,1.77,139.59],[2,1.75,206.13]],"ltp":1.92,"tv":1865.23,"id":13117391}]}]}
{"op":"mcm","clk":"1006502319","pt":1580596911191,"mc":[{"id":"1.168175449","rc":[{"batb":[[2,5.7,40.68]],"batl":[[0,7,33.99]],"ltp":7.8,"tv":0.55,"id":13117449},{"batb":[[2,5.4,23.45]],"batl":[[0,12.5,27.46]],"ltp":50.0,"tv":4.09,"id":13117448},{"batb":[[0,4.1,108.11]],"batl":[[0,5.2,31.55]],"ltp":5.8,"tv":93.9,"id":13117392},{"batb":[[0,1.79,43.83]],"batl":[[0,2.38,42.02]],"ltp":1.92,"tv":1865.23,"id":13117391}]}]}
{"op":"mcm","clk":"1006504246","pt":1580596930991,"mc":[{"id":"1.168175449","rc":[{"batb":[[0,5.7,40.68],[1,1.01,0.51],[2,5.7,0]],"ltp":7.8,"tv":0.55,"id":13117449},{"batb":[[0,5.4,23.45],[1,1.01,0.51],[2,5.4,0]],"ltp":50.0,"tv":4.09,"id":13117448},{"batb":[[0,4.1,44.46],[1,1.01,0.51],[2,1.01,0]],"ltp":5.8,"tv":93.9,"id":13117392}]}]}
{"op":"mcm","clk":"1006504582","pt":1580596934194,"mc":[{"id":"1.168175449","rc":[{"batb":[[0,6.6,100.22],[1,6.4,74.04],[2,5.7,40.68]],"ltp":7.8,"tv":0.55,"id":13117449},{"batb":[[0,10,67.53],[1,9.8,29.62],[2,5.4,23.45]],"ltp":50.0,"tv":4.09,"id":13117448},{"batb":[[0,4.6,56.3],[1,4.5,81.96],[2,4.1,44.46]],"ltp":5.8,"tv":93.9,"id":13117392}]}]}
{"op":"mcm","clk":"1006504710","pt":1580596935493,"mc":[{"id":"1.168175449","rc":[{"batb":[[2,6,36.35]],"batl":[[1,7.2,31.79]],"ltp":7.8,"tv":0.55,"id":13117449},{"batb":[[1,9.8,59.83],[2,9,5.04]],"batl":[[0,11.5,3.36],[1,12.5,27.46]],"ltp":50.0,"tv":4.09,"id":13117448},{"batb":[[0,4.6,89.35],[2,4.3,51.71]],"batl":[[0,5,10.08],[1,5.2,31.55],[2,5.7,25.41]],"ltp":5.8,"tv":93.9,"id":13117392},{"batb":[[0,1.82,50.41],[1,1.79,43.83],[2,1.77,139.59]],"batl":[[0,1.86,43.04],[1,1.99,42.01],[2,2.1,60.19]],"ltp":1.92,"tv":1865.23,"id":13117391}]}]}
{"op":"mcm","clk":"1006504918","pt":1580596937517,"mc":[{"id":"1.168175449","rc":[{"batl":[[0,7,40.71]],"ltp":7.8,"tv":0.55,"id":13117449}]}]}
{"op":"mcm","clk":"1006505409","pt":1580596942408,"mc":[{"id":"1.168175449","rc":[{"batb":[[2,7,26.12]],"ltp":50.0,"tv":4.09,"id":13117448},{"batl":[[1,2.1,60.19],[2,2.1,0]],"ltp":1.92,"tv":1865.23,"id":13117391}]}]}
{"op":"mcm","clk":"1006505600","pt":1580596944530,"mc":[{"id":"1.168175449","rc":[{"batb":[[2,9.2,5.04]],"ltp":50.0,"tv":4.09,"id":13117448},{"batl":[[1,1.98,42.01],[2,2.1,60.19]],"ltp":1.92,"tv":1865.23,"id":13117391}]}]}
{"op":"mcm","clk":"1006506105","pt":1580596949507,"mc":[{"id":"1.168175449","rc":[{"batl":[[0,12.5,27.46],[1,12.5,0]],"ltp":50.0,"tv":4.09,"id":13117448},{"batb":[[2,4.3,39.1]],"ltp":5.8,"tv":93.9,"id":13117392},{"batl":[[1,2.1,60.19],[2,2.1,0]],"ltp":1.92,"tv":1865.23,"id":13117391}]}]}
{"op":"mcm","clk":"1006506266","pt":1580596951515,"mc":[{"id":"1.168175449","rc":[{"batl":[[0,12,3.36],[1,12.5,27.46]],"ltp":50.0,"tv":4.09,"id":13117448}]}]}
{"op":"mcm","clk":"1006506333","pt":1580596952243,"mc":[{"id":"1.168175449","rc":[{"batl":[[1,1.97,42.01],[2,2.1,60.19]],"ltp":1.92,"tv":1865.23,"id":13117391}]}]}
{"op":"mcm","clk":"1006506539","pt":1580596954537,"mc":[{"id":"1.168175449","rc":[{"batb":[[0,6.4,74.04],[1,5.9,37.85],[2,5.8,8.4]],"batl":[[0,7,6.72]],"ltp":7.8,"tv":0.55,"id":13117449},{"batb":[[0,9.2,5.04],[1,7,26.12],[2,1.01,0.51]],"batl":[[1,12.5,0]],"ltp":50.0,"tv":4.09,"id":13117448},{"batb":[[0,4.3,39.1],[1,4.2,12.6],[2,1.01,0.51]],"batl":[[1,5.7,25.41],[2,5.7,0]],"ltp":5.8,"tv":93.9,"id":13117392},{"batb":[[1,1.58,67.9],[2,1.01,0.51]],"batl":[[0,1.97,42.01],[1,2.1,60.19],[2,2.1,0]],"ltp":1.92,"tv":1865.23,"id":13117391}]}]}
{"op":"mcm","clk":"1006506662","pt":1580596955937,"mc":[{"id":"1.168175449","rc":[{"batb":[[2,1.01,0.51]],"batl":[[0,7.2,31.79],[1,7.2,0]],"ltp":7.8,"tv":0.55,"id":13117449},{"batb":[[0,7,26.12],[1,1.01,0.51],[2,1.01,0]],"ltp":50.0,"tv":4.09,"id":13117448},{"batb":[[1,1.01,0.51],[2,1.01,0]],"batl":[[0,5.7,25.41],[1,5.7,0]],"ltp":5.8,"tv":93.9,"id":13117392},{"batb":[[0,1.58,67.9],[1,1.01,0.51],[2,1.01,0]],"batl":[[0,2.1,60.19],[1,2.1,0]],"ltp":1.92,"tv":1865.23,"id":13117391}]}]}
{"op":"mcm","clk":"1006506772","pt":1580596957508,"mc":[{"id":"1.168175449","rc":[{"batb":[[0,6.4,92.8],[1,6.2,79.57],[2,5.9,37.85]],"ltp":7.8,"tv":0.55,"id":13117449},{"batb":[[0,7.2,76.78],[1,7,87.19],[2,1.01,0.51]],"ltp":50.0,"tv":4.09,"id":13117448},{"batb":[[0,4.3,118.38],[1,4.2,95.68],[2,1.01,0.51]],"ltp":5.8,"tv":93.9,"id":13117392}]}]}
{"op":"mcm","clk":"1006506928","pt":1580596959326,"mc":[{"id":"1.168175449","rc":[{"batl":[[0,2.1,84.14]],"ltp":1.92,"tv":1865.23,"id":13117391}]}]}
{"op":"mcm","clk":"1006507060","pt":1580596960521,"mc":[{"id":"1.168175449","rc":[{"batb":[[0,1.96,172.34],[1,1.94,147.64],[2,1.58,67.9]],"ltp":1.92,"tv":1865.23,"id":13117391}]}]}
{"op":"mcm","clk":"1006507154","pt":1580596961298,"mc":[{"id":"1.168175449","rc":[{"batl":[[0,7,40.55]],"ltp":7.8,"tv":0.55,"id":13117449},{"batb":[[0,7.2,83.5],[2,5.3,24.86]],"batl":[[0,8.2,24.71],[1,16,17]],"ltp":50.0,"tv":4.09,"id":13117448},{"batb":[[2,4,59.47]],"batl":[[0,4.6,10.92],[1,4.8,37.22],[2,5.4,29.43]],"ltp":5.8,"tv":93.9,"id":13117392},{"batb":[[0,2,62],[1,1.96,172.34],[2,1.94,147.64]],"batl":[[1,2.42,40.05]],"ltp":1.92,"tv":1865.23,"id":13117391}]}]}
{"op":"mcm","clk":"1006507344","pt":1580596963520,"mc":[{"id":"1.168175449","rc":[{"batl":[[1,8.8,5.04],[2,16,17]],"ltp":50.0,"tv":4.09,"id":13117448},{"batb":[[1,1.97,42.85],[2,1.96,172.34]],"batl":[[1,2.16,36.13],[2,2.42,40.05]],"ltp":1.92,"tv":1865.23,"id":13117391}]}]}
{"op":"mcm","clk":"1006508168","pt":1580596973139,"mc":[{"id":"1.168175449","rc":[{"batl":[[0,2.1,60.19]],"ltp":1.92,"tv":1865.23,"id":13117391}]}]}
{"op":"mcm","clk":"1006508453","pt":1580596976562,"mc":[{"id":"1.168175449","rc":[{"batb":[[0,6.2,79.57],[1,5.8,48.69],[2,1.01,0.51]],"ltp":7.8,"tv":0.55,"id":13117449},{"batb":[[0,7.2,6.72],[1,5.3,24.86],[2,1.01,0.51]],"batl":[[0,8.8,5.04],[1,16,17],[2,16,0]],"ltp":50.0,"tv":4.09,"id":13117448},{"batb":[[0,4,59.47],[1,1.01,0.51],[2,4,0]],"batl":[[1,5.4,29.43],[2,5.4,0]],"ltp":5.8,"tv":93.9,"id":13117392},{"batb":[[0,1.97,42.85],[1,1.71,50.91],[2,1.01,0.51]],"batl":[[0,2.16,36.13],[1,2.42,40.05],[2,2.42,0]],"ltp":1.92,"tv":1865.23,"id":13117391}]}]}
{"op":"mcm","clk":"1006508607","pt":1580596978262,"mc":[{"id":"1.168175449","rc":[{"batb":[[1,5.8,40.29]],"batl":[[0,7,33.83]],"ltp":7.8,"tv":0.55,"id":13117449},{"batb":[[0,5.3,24.86],[1,1.01,0.51],[2,1.01,0]],"batl":[[0,16,17],[1,16,0]],"ltp":50.0,"tv":4.09,"id":13117448},{"batb":[[0,4,46.03]],"batl":[[0,5.4,29.43],[1,5.4,0]],"ltp":5.8,"tv":93.9,"id":13117392},{"batb":[[0,1.71,50.91],[1,1.01,0.51],[2,1.01,0]],"batl":[[0,2.42,40.05],[1,2.42,0]],"ltp":1.92,"tv":1865.23,"id":13117391}]}]}
{"op":"mcm","clk":"1006508722","pt":1580596979555,"mc":[{"id":"1.168175449","rc":[{"batb":[[1,6,85.59],[2,5.8,40.29]],"batl":[[1,7.2,32.42]],"ltp":7.8,"tv":0.55,"id":13117449},{"batb":[[0,5.6,41],[1,5.5,53.41],[2,5.3,24.86]],"batl":[[1,16.5,16.37]],"ltp":50.0,"tv":4.09,"id":13117448},{"batb":[[0,4,176.21],[1,3.95,55.48],[2,1.01,0.51]],"batl":[[0,5.3,29.82],[1,5.4,29.43]],"ltp":5.8,"tv":93.9,"id":13117392},{"batb":[[1,1.7,51.93],[2,1.69,129.74]],"batl":[[0,2.4,40.99],[1,2.42,40.05]],"ltp":1.92,"tv":1865.23,"id":13117391}]}]}
{"op":"mcm","clk":"1006508789","pt":1580596980126,"mc":[{"id":"1.168175449","rc":[{"batb":[[2,1.01,0.51]],"batl":[[0,7.2,32.42],[1,7.2,0]],"ltp":7.8,"tv":0.55,"id":13117449},{"batb":[[2,5.3,23.92]],"batl":[[0,16.5,16.37],[1,16.5,0]],"ltp":50.0,"tv":4.09,"id":13117448},{"batl":[[1,5.4,0]],"ltp":5.8,"tv":93.9,"id":13117392},{"batb":[[0,1.7,51.93],[1,1.69,129.74],[2,1.67,242.29]],"batl":[[1,2.42,0]],"ltp":1.92,"tv":1865.23,"id":13117391}]}]}
{"op":"mcm","clk":"1006513712","pt":1580597036423,"mc":[{"id":"1.168175449","rc":[{"batb":[[0,1.01,0.51],[1,6,0],[2,1.01,0]],"ltp":7.8,"tv":0.55,"id":13117449},{"batb":[[0,5.3,23.92],[1,1.01,0.51],[2,5.3,0]],"ltp":50.0,"tv":4.09,"id":13117448},{"batb":[[0,4,46.03],[1,1.01,0.51],[2,1.01,0]],"ltp":5.8,"tv":93.9,"id":13117392},{"batb":[[1,1.01,0.51],[2,1.67,0]],"ltp":1.92,"tv":1865.23,"id":13117391}]}]}
{"op":"mcm","clk":"1006513967","pt":1580597039421,"mc":[{"id":"1.168175449","rc":[{"batb":[[0,6.6,39.48],[1,6.4,75.59],[2,1.01,0.51]],"ltp":7.8,"tv":0.55,"id":13117449},{"batb":[[0,8,40.57],[1,7.8,49.06],[2,5.3,23.92]],"ltp":50.0,"tv":4.09,"id":13117448},{"batb":[[0,4.4,57.48],[1,4.3,90.97],[2,4,46.03]],"ltp":5.8,"tv":93.9,"id":13117392},{"batb":[[0,1.9,157.54],[1,1.88,162.99],[2,1.7,51.93]],"ltp":1.92,"tv":1865.23,"id":13117391}]}]}
{"op":"mcm","clk":"1006514579","pt":1580597046161,"mc":[{"id":"1.168175449","rc":[{"batb":[[0,1.01,0.51],[1,6.4,0],[2,1.01,0]],"ltp":7.8,"tv":0.55,"id":13117449},{"batb":[[0,5.3,23.92],[1,1.01,0.51],[2,5.3,0]],"ltp":50.0,"tv":4.09,"id":13117448},{"batb":[[0,4,46.03],[1,1.01,0.51],[2,4,0]],"ltp":5.8,"tv":93.9,"id":13117392},{"batb":[[0,1.7,51.93],[1,1.01,0.51],[2,1.7,0]],"ltp":1.92,"tv":1865.23,"id":13117391}]}]}
{"op":"mcm","clk":"1006514846","pt":1580597049053,"mc":[{"id":"1.168175449","rc":[{"batb":[[0,6.2,90.07],[1,6,85.59],[2,1.01,0.51]],"ltp":7.8,"tv":0.55,"id":13117449},{"batb":[[0,5.6,41],[1,5.5,53.41],[2,5.3,23.92]],"ltp":50.0,"tv":4.09,"id":13117448},{"batb":[[0,4,176.21],[1,3.95,55.48],[2,1.01,0.51]],"ltp":5.8,"tv":93.9,"id":13117392},{"batb":[[1,1.69,129.74],[2,1.67,242.29]],"ltp":1.92,"tv":1865.23,"id":13117391}]}]}
{"op":"mcm","clk":"1006515055","pt":1580597051345,"mc":[{"id":"1.168175449","rc":[{"batb":[[0,1.01,0.51],[1,6,0],[2,1.01,0]],"ltp":7.8,"tv":0.55,"id":13117449},{"batb":[[0,5.3,23.92],[1,1.01,0.51],[2,5.3,0]],"ltp":50.0,"tv":4.09,"id":13117448},{"batb":[[0,4,46.03],[1,1.01,0.51],[2,1.01,0]],"ltp":5.8,"tv":93.9,"id":13117392}]}]}
{"op":"mcm","clk":"1006515308","pt":1580597054456,"mc":[{"id":"1.168175449","rc":[{"batb":[[0,6.8,60.26],[1,6.6,70.22],[2,1.01,0.51]],"ltp":7.8,"tv":0.55,"id":13117449},{"batb":[[0,12.5,60.19],[1,12,47.04],[2,5.3,23.92]],"ltp":50.0,"tv":4.09,"id":13117448},{"batb":[[0,4.7,85.24],[1,4.6,77.47],[2,4,46.03]],"ltp":5.8,"tv":93.9,"id":13117392}]}]}
{"op":"mcm","clk":"1006515361","pt":1580597055176,"mc":[{"id":"1.168175449","rc":[{"batb":[[2,6,36.35]],"batl":[[0,7,6.72],[1,7.2,32.42],[2,7.4,30.53]],"ltp":7.8,"tv":0.55,"id":13117449},{"batb":[[0,12.5,77.81],[2,11.5,3.36]],"ltp":50.0,"tv":4.09,"id":13117448},{"batb":[[0,4.8,31.16],[1,4.7,85.24],[2,4.6,77.47]],"batl":[[0,5.1,10.08],[1,5.3,29.82],[2,6.2,22.03]],"ltp":5.8,"tv":93.9,"id":13117392},{"batb":[[0,1.73,57.13],[1,1.7,51.93],[2,1.69,129.74]],"batl":[[0,1.76,50.91],[1,1.88,42.01],[2,2.06,62.71]],"ltp":1.92,"tv":1865.23,"id":13117391}]}]}
{"op":"mcm","clk":"1006516465","pt":1580597067411,"mc":[{"id":"1.168175449","rc":[{"batb":[[0,12.5,62.46],[1,11.5,3.36],[2,7.2,24.31]],"ltp":50.0,"tv":4.09,"id":13117448},{"batb":[[2,1.67,122.17]],"ltp":1.92,"tv":1865.23,"id":13117391}]}]}
{"op":"mcm","clk":"1006516736","pt":1580597070509,"mc":[{"id":"1.168175449","rc":[{"batb":[[0,6.8,72.11]],"ltp":7.8,"tv":0.55,"id":13117449},{"batb":[[0,13,20.53],[1,12.5,62.46],[2,11.5,3.36]],"batl":[[0,16,104.67],[1,16.5,16.37]],"ltp":50.0,"tv":4.09,"id":13117448},{"batb":[[2,1.68,223.46]],"ltp":1.92,"tv":1865.23,"id":13117391}]}]}
{"op":"mcm","clk":"1006517156","pt":1580597075225,"mc":[{"id":"1.168175449","rc":[{"batb":[[0,6.6,43.76],[1,6,36.35],[2,5.8,8.4]],"batl":[[1,7.4,30.53],[2,7.4,0]],"ltp":7.8,"tv":0.55,"id":13117449},{"batb":[[0,11.5,3.36],[1,7.2,24.31],[2,1.01,0.51]],"ltp":50.0,"tv":4.09,"id":13117448},{"batb":[[0,4.4,11.76],[1,4.3,39.73],[2,1.01,0.51]],"batl":[[1,6.2,22.03],[2,6.2,0]],"ltp":5.8,"tv":93.9,"id":13117392},{"batb":[[1,1.45,94.02],[2,1.01,0.51]],"batl":[[0,1.88,42.01],[1,2.06,62.71],[2,2.06,0]],"ltp":1.92,"tv":1865.23,"id":13117391}]}]}
{"op":"mcm","clk":"1006517281","pt":1580597076525,"mc":[{"id":"1.168175449","rc":[{"batb":[[2,1.01,0.51]],"batl":[[0,7.4,30.53],[1,7.4,0]],"ltp":7.8,"tv":0.55,"id":13117449},{"batb":[[0,7.2,24.31],[1,1.01,0.51],[2,1.01,0]],"ltp":50.0,"tv":4.09,"id":13117448},{"batb":[[0,4.3,39.73],[1,1.01,0.51],[2,1.01,0]],"batl":[[0,6.2,22.03],[1,6.2,0]],"ltp":5.8,"tv":93.9,"id":13117392},{"batb":[[0,1.45,94.02],[1,1.01,0.51],[2,1.01,0]],"batl":[[0,2.06,62.71],[1,2.06,0]],"ltp":1.92,"tv":1865.23,"id":13117391}]}]}
{"op":"mcm","clk":"1006517369","pt":1580597077515,"mc":[{"id":"1.168175449","rc":[{"batb":[[0,6.4,75.83]],"ltp":7.8,"tv":0.55,"id":13117449},{"batb":[[0,7.4,55.61],[1,7.2,82.53],[2,1.01,0.51]],"ltp":50.0,"tv":4.09,"id":13117448},{"batb":[[0,4.3,120.29],[1,4.2,95.55],[2,1.01,0.51]],"ltp":5.8,"tv":93.9,"id":13117392},{"batb":[[1,1.42,363.14],[2,1.41,238.39]],"ltp":1.92,"tv":1865.23,"id":13117391}]}]}
{"op":"mcm","clk":"1006517453","pt":1580597078541,"mc":[{"id":"1.168175449","rc":[{"batb":[[0,6,36.35],[1,1.01,0.51],[2,1.01,0]],"ltp":7.8,"tv":0.55,"id":13117449},{"batb":[[0,7.2,24.31],[1,1.01,0.51],[2,1.01,0]],"ltp":50.0,"tv":4.09,"id":13117448},{"batb":[[0,4.3,39.73],[1,1.01,0.51],[2,1.01,0]],"ltp":5.8,"tv":93.9,"id":13117392},{"batb":[[1,1.01,0.51],[2,1.41,0]],"ltp":1.92,"tv":1865.23,"id":13117391}]}]}
{"op":"mcm","clk":"1006517637","pt":1580597080554,"mc":[{"id":"1.168175449","rc":[{"batb":[[0,7,32.92],[1,6.8,66.8],[2,6,36.35]],"ltp":7.8,"tv":0.55,"id":13117449},{"batb":[[0,16,30.79],[1,15.5,28.46],[2,7.2,24.31]],"ltp":50.0,"tv":4.09,"id":13117448},{"batb":[[0,4.8,94.73],[1,4.7,73.51],[2,4.3,39.73]],"ltp":5.8,"tv":93.9,"id":13117392},{"batb":[[0,1.62,249.12],[1,1.61,139.62],[2,1.45,94.02]],"ltp":1.92,"tv":1865.23,"id":13117391}]}]}
{"op":"mcm","clk":"1006518280","pt":1580597087943,"mc":[{"id":"1.168175449","rc":[{"batb":[[0,6,36.35],[1,1.01,0.51],[2,6,0]],"ltp":7.8,"tv":0.55,"id":13117449},{"batb":[[0,7.2,24.31],[1,1.01,0.51],[2,7.2,0]],"ltp":50.0,"tv":4.09,"id":13117448},{"batb":[[0,4.3,39.73],[1,1.01,0.51],[2,4.3,0]],"ltp":5.8,"tv":93.9,"id":13117392},{"batb":[[0,1.45,94.02],[1,1.01,0.51],[2,1.45,0]],"ltp":1.92,"tv":1865.23,"id":13117391}]}]}
{"op":"mcm","clk":"1006518488","pt":1580597090542,"mc":[{"id":"1.168175449","rc":[{"batb":[[0,6.6,42.91],[1,6.4,75.82],[2,6,36.35]],"ltp":7.8,"tv":0.55,"id":13117449},{"batb":[[0,7.4,54.87],[1,7.2,82.53],[2,1.01,0.51]],"ltp":50.0,"tv":4.09,"id":13117448},{"batb":[[0,4.3,120.81],[1,4.2,95.55],[2,1.01,0.51]],"ltp":5.8,"tv":93.9,"id":13117392},{"batb":[[1,1.42,365.07],[2,1.41,238.4]],"ltp":1.92,"tv":1865.23,"id":13117391}]}]}
{"op":"mcm","clk":"1006519303","pt":1580597099543,"mc":[{"id":"1.168175449","rc":[{"batb":[[0,6,36.35],[1,1.01,0.51],[2,6,0]],"ltp":7.8,"tv":0.55,"id":13117449},{"batb":[[0,7.2,24.31],[1,1.01,0.51],[2,1.01,0]],"ltp":50.0,"tv":4.09,"id":13117448},{"batb":[[0,4.3,39.73],[1,1.01,0.51],[2,1.01,0]],"ltp":5.8,"tv":93.9,"id":13117392}]}]}
{"op":"mcm","clk":"1006519554","pt":1580597102348,"mc":[{"id":"1.168175449","rc":[{"batb":[[0,7.2,75.68],[1,7,61.76],[2,6,36.35]],"ltp":7.8,"tv":0.55,"id":13117449},{"batb":[[0,5.4,62.54],[1,5.3,56.43],[2,4.3,39.73]],"ltp":5.8,"tv":93.9,"id":13117392}]}]}
{"op":"mcm","clk":"1006519640","pt":1580597103179,"mc":[{"id":"1.168175449","rc":[{"trd":[[7.2,13.44]],"batb":[[0,7.2,68.96],[2,6.2,32.57]],"batl":[[1,8.2,24.55]],"ltp":7.2,"tv":13.99,"id":13117449},{"batb":[[0,1.01,0.51],[1,1.01,0]],"ltp":50.0,"tv":4.09,"id":13117448},{"batb":[[0,5.4,85.44],[2,4.9,10.08]],"batl":[[1,7,34.7]],"ltp":5.8,"tv":93.9,"id":13117392},{"batl":[[0,1.5,91.43],[1,1.62,68.77]],"ltp":1.92,"tv":1865.23,"id":13117391}],"tv":1977.22}]}
{"op":"mcm","clk":"1006519922","pt":1580597106154,"mc":[{"id":"1.168175449","rc":[{"trd":[[7.2,26.88]],"batb":[[0,7.2,62.24]],"batl":[[0,7.4,36.41]],"ltp":7.2,"tv":27.43,"id":13117449},{"batl":[[0,5.8,8.4],[1,6.2,22.03],[2,7,34.7]],"ltp":5.8,"tv":93.9,"id":13117392},{"batb":[[0,1.46,90.74],[1,1.45,94.02],[2,1.42,365.07]],"batl":[[1,1.56,42.01],[2,1.62,68.77]],"ltp":1.92,"tv":1865.23,"id":13117391}],"tv":1990.66}]}
{"op":"mcm","clk":"1006520278","pt":1580597110494,"mc":[{"id":"1.168175449","rc":[{"trd":[[7.2,40.32]],"batb":[[0,7.2,66.37],[2,6.2,40.14]],"ltp":7.2,"tv":40.87,"id":13117449},{"batb":[[2,1.42,230.91]],"ltp":1.92,"tv":1865.23,"id":13117391}],"tv":2004.1}]}
{"op":"mcm","clk":"1006520457","pt":1580597112886,"mc":[{"id":"1.168175449","rc":[{"batb":[[2,1.43,144.49]],"ltp":1.92,"tv":1865.23,"id":13117391}]}]}
{"op":"mcm","clk":"1006521282","pt":1580597122301,"mc":[{"id":"1.168175449","rc":[{"batb":[[0,1000,4],[1,1.01,0.51]],"ltp":50.0,"tv":4.09,"id":13117448}]}]}
{"op":"mcm","clk":"1006521597","pt":1580597126092,"mc":[{"id":"1.168175449","rc":[{"trd":[[1.46,15.14]],"batb":[[0,1.46,83.17]],"ltp":1.46,"tv":1880.37,"id":13117391}],"tv":2019.24}]}
{"op":"mcm","clk":"1006521859","pt":1580597129302,"mc":[{"id":"1.168175449","rc":[{"batb":[[0,1.46,90.73]],"ltp":1.46,"tv":1880.37,"id":13117391}]}]}
{"op":"mcm","clk":"1006522155","pt":1580597132427,"mc":[{"id":"1.168175449","rc":[{"batb":[[1,6.2,40.14],[2,5.5,21.95]],"ltp":7.2,"tv":40.87,"id":13117449},{"batb":[[2,1.42,230.91]],"ltp":1.46,"tv":1880.37,"id":13117391}]}]}
{"op":"mcm","clk":"1006522455","pt":1580597135509,"mc":[{"id":"1.168175449","rc":[{"trd":[[7.4,72.52]],"batb":[[1,6.6,29.03],[2,6.2,40.14]],"batl":[[0,7.8,27.53],[2,8.6,21.95]],"ltp":7.4,"tv":113.39,"id":13117449},{"batl":[[1,6,22.5],[2,6.2,22.03]],"ltp":5.8,"tv":93.9,"id":13117392},{"batb":[[2,1.44,97.49]],"batl":[[0,1.49,94.73],[1,1.5,91.43],[2,1.56,42.01]],"ltp":1.46,"tv":1880.37,"id":13117391}],"tv":2091.76}]}
{"op":"mcm","clk":"1006522492","pt":1580597135921,"mc":[{"id":"1.168175449","rc":[{"batb":[[2,6.2,7.56]],"batl":[[1,8.6,21.95],[2,8.6,0]],"ltp":7.4,"tv":113.39,"id":13117449},{"batl":[[2,6.8,35.33]],"ltp":5.8,"tv":93.9,"id":13117392},{"batb":[[0,1.44,97.49],[1,1.42,323.93],[2,1.41,240.42]],"batl":[[1,1.6,71.36],[2,1.56,0]],"ltp":1.46,"tv":1880.37,"id":13117391}]}]}
{"op":"mcm","clk":"1006522759","pt":1580597138934,"mc":[{"id":"1.168175449","rc":[{"trd":[[7.4,82.9]],"batb":[[0,7.4,24.08],[1,7.2,66.37],[2,6.6,29.03]],"batl":[[0,7.8,27.38]],"ltp":7.4,"tv":123.77,"id":13117449},{"batb":[[0,1.45,93.26],[1,1.44,97.49],[2,1.42,323.93]],"batl":[[1,1.55,42.01],[2,1.6,71.36]],"ltp":1.46,"tv":1880.37,"id":13117391}],"tv":2102.14}]}
{"op":"mcm","clk":"1006523047","pt":1580597142112,"mc":[{"id":"1.168175449","rc":[{"batl":[[0,7.6,5.88],[1,7.8,27.38],[2,8.6,21.95]],"ltp":7.4,"tv":123.77,"id":13117449}]}]}
{"op":"mcm","clk":"1006523166","pt":1580597143416,"mc":[{"id":"1.168175449","rc":[{"batb":[[2,6.8,27.15]],"batl":[[2,8.2,25.57]],"ltp":7.4,"tv":123.77,"id":13117449},{"batb":[[1,5.3,80.03]],"ltp":5.8,"tv":93.9,"id":13117392},{"batb":[[2,1.42,423.54]],"batl":[[0,1.48,96.7],[1,1.49,94.73],[2,1.55,42.01]],"ltp":1.46,"tv":1880.37,"id":13117391}]}]}
{"op":"mcm","clk":"1006523251","pt":1580597144346,"mc":[{"id":"1.168175449","rc":[{"batl":[[1,8.2,25.57],[2,9,20.54]],"ltp":7.4,"tv":123.77,"id":13117449},{"batb":[[0,5.4,62.54]],"ltp":5.8,"tv":93.9,"id":13117392},{"batb":[[1,1.42,423.54],[2,1.41,240.42]],"batl":[[1,1.55,42.01],[2,1.59,72.94]],"ltp":1.46,"tv":1880.37,"id":13117391}]}]}
{"op":"mcm","clk":"1006523896","pt":1580597152452,"mc":[{"id":"1.168175449","rc":[{"batl":[[1,8,25.73]],"ltp":7.4,"tv":123.77,"id":13117449},{"batb":[[1,1.42,423.31]],"batl":[[0,1.48,96.46],[2,1.59,72.78]],"ltp":1.46,"tv":1880.37,"id":13117391}]}]}
{"op":"mcm","clk":"1006524834","pt":1580597164764,"mc":[{"id":"1.168175449","rc":[{"batb":[[1,1.42,423.15]],"batl":[[0,1.48,96.31],[2,1.59,72.62]],"ltp":1.46,"tv":1880.37,"id":13117391}]}]}
{"op":"mcm","clk":"1006525855","pt":1580597175977,"mc":[{"id":"1.168175449","rc":[{"batb":[[1,1.43,98.82],[2,1.42,323.93]],"batl":[[0,1.48,95.99],[2,1.59,72.39]],"ltp":1.46,"tv":1880.37,"id":13117391}]}]}
{"op":"mcm","clk":"1006526490","pt":1580597184059,"mc":[{"id":"1.168175449","rc":[{"batb":[[2,6.6,28.8]],"batl":[[1,7.8,27.07],[2,8.8,21.79]],"ltp":7.4,"tv":123.77,"id":13117449},{"batb":[[0,5.4,85.91],[1,5.3,56.43]],"ltp":5.8,"tv":93.9,"id":13117392},{"batb":[[1,1.43,97.8]],"batl":[[0,1.48,94.97],[2,1.59,71.52]],"ltp":1.46,"tv":1880.37,"id":13117391}]}]}
{"op":"mcm","clk":"1006528710","pt":1580597210641,"mc":[{"id":"1.168175449","rc":[{"batb":[[0,7.2,66.37],[1,6.6,28.8],[2,6.2,7.56]],"ltp":7.4,"tv":123.77,"id":13117449}]}]}
{"op":"mcm","clk":"1006528979","pt":1580597213550,"mc":[{"id":"1.168175449","rc":[{"batb":[[0,7.2,86.85],[1,7,61.77],[2,6.6,28.8]],"ltp":7.4,"tv":123.77,"id":13117449}]}]}
{"op":"mcm","clk":"1006530244","pt":1580597228072,"mc":[{"id":"1.168175449","rc":[{"batl":[[1,1.59,71.52],[2,1.59,0]],"ltp":1.46,"tv":1880.37,"id":13117391}]}]}
{"op":"mcm","clk":"1006530450","pt":1580597230973,"mc":[{"id":"1.168175449","rc":[{"batl":[[1,1.54,42.01],[2,1.59,71.52]],"ltp":1.46,"tv":1880.37,"id":13117391}]}]}
{"op":"mcm","clk":"1006532221","pt":1580597252385,"mc":[{"id":"1.168175449","rc":[{"batb":[[0,6.2,7.56],[1,5.8,39.5],[2,1.01,0.51]],"batl":[[1,8.8,21.79],[2,8.8,0]],"ltp":7.4,"tv":123.77,"id":13117449},{"batb":[[0,4.9,10.08],[1,4.7,32.18],[2,1.01,0.51]],"batl":[[1,6.8,35.33],[2,6.8,0]],"ltp":5.8,"tv":93.9,"id":13117392},{"batb":[[1,1.37,118.49],[2,1.01,0.51]],"batl":[[0,1.54,42.01],[1,1.59,71.52],[2,1.59,0]],"ltp":1.46,"tv":1880.37,"id":13117391}]}]}
{"op":"mcm","clk":"1006532352","pt":1580597254030,"mc":[{"id":"1.168175449","rc":[{"batb":[[0,5.8,39.5],[1,1.01,0.51],[2,1.01,0]],"batl":[[0,8.8,21.79],[1,8.8,0]],"ltp":7.4,"tv":123.77,"id":13117449},{"batb":[[0,4.7,32.18],[1,1.01,0.51],[2,1.01,0]],"batl":[[0,6.8,35.33],[1,6.8,0]],"ltp":5.8,"tv":93.9,"id":13117392},{"batb":[[0,1.37,118.49],[1,1.01,0.51],[2,1.01,0]],"batl":[[0,1.59,71.52],[1,1.59,0]],"ltp":1.46,"tv":1880.37,"id":13117391}]}]}
{"op":"mcm","clk":"1006532471","pt":1580597255527,"mc":[{"id":"1.168175449","rc":[{"batb":[[0,6.2,100.79],[1,6,86.29],[2,5.8,39.5]],"batl":[[0,8.6,22.9],[1,8.8,21.79]],"ltp":7.4,"tv":123.77,"id":13117449},{"batb":[[0,4.7,83.49],[1,4.6,77.95],[2,1.01,0.51]],"ltp":5.8,"tv":93.9,"id":13117392},{"batb":[[0,1.37,383.01],[1,1.36,283.68],[2,1.01,0.51]],"batl":[[1,1.6,70.42]],"ltp":1.46,"tv":1880.37,"id":13117391}]}]}
{"op":"mcm","clk":"1006532490","pt":1580597255837,"mc":[{"id":"1.168175449","rc":[{"batb":[[2,5.7,41.54]],"batl":[[1,8.8,0]],"ltp":7.4,"tv":123.77,"id":13117449},{"batb":[[0,4.7,83.18]],"batl":[[0,6.8,35.09]],"ltp":5.8,"tv":93.9,"id":13117392},{"batb":[[0,1.37,381.21]],"batl":[[0,1.6,70.42],[1,1.6,0]],"ltp":1.46,"tv":1880.37,"id":13117391}]}]}
{"op":"mcm","clk":"1006532849","pt":1580597260044,"mc":[{"id":"1.168175449","rc":[{"batb":[[0,1.37,116.69],[1,1.01,0.51],[2,1.01,0]],"ltp":1.46,"tv":1880.37,"id":13117391}]}]}
{"op":"mcm","clk":"1006533140","pt":1580597263519,"mc":[{"id":"1.168175449","rc":[{"batl":[[0,6.6,38.71],[1,7.4,30.29],[2,8.6,22.9]],"ltp":7.4,"tv":123.77,"id":13117449},{"batb":[[2,4,45.48]],"batl":[[0,5.2,30.45],[1,5.9,23.84],[2,6.8,35.09]],"ltp":5.8,"tv":93.9,"id":13117392},{"batb":[[0,1.54,72.15],[1,1.53,216.6],[2,1.52,174.1]],"batl":[[1,1.77,49.81]],"ltp":1.46,"tv":1880.37,"id":13117391}]}]}
{"op":"mcm","clk":"1006533160","pt":1580597263727,"mc":[{"id":"1.168175449","rc":[{"batl":[[2,8.6,0]],"ltp":7.4,"tv":123.77,"id":13117449},{"batl":[[2,6.8,0]],"ltp":5.8,"tv":93.9,"id":13117392}]}]}
{"op":"mcm","clk":"1006533307","pt":1580597265543,"mc":[{"id":"1.168175449","rc":[{"batl":[[1,6.8,6.72],[2,7.4,30.29]],"ltp":7.4,"tv":123.77,"id":13117449},{"batb":[[2,4.4,11.76]],"batl":[[0,5.2,39.69]],"ltp":5.8,"tv":93.9,"id":13117392},{"batb":[[0,1.54,149.45]],"batl":[[1,1.65,42.01],[2,1.77,49.81]],"ltp":1.46,"tv":1880.37,"id":13117391}]}]}
{"op":"mcm","clk":"1006533692","pt":1580597270447,"mc":[{"id":"1.168175449","rc":[{"trd":[[1.54,5]],"batb":[[0,1.54,146.95]],"ltp":1.54,"tv":1885.37,"id":13117391}],"tv":2107.14}]}
{"op":"mcm","clk":"1006534365","pt":1580597278242,"mc":[{"id":"1.168175449","rc":[{"batb":[[0,5.6,8.4],[1,5,28.56],[2,1.01,0.51]],"batl":[[0,6.8,6.72],[1,7.4,30.29],[2,7.4,0]],"ltp":7.4,"tv":123.77,"id":13117449},{"batb":[[0,4.4,11.76],[1,4,45.48],[2,1.01,0.51]],"batl":[[0,5.2,9.24]],"ltp":5.8,"tv":93.9,"id":13117392},{"batb":[[0,1.54,77.3],[1,1.45,90.8],[2,1.01,0.51]],"batl":[[0,1.65,42.01],[1,1.77,49.81],[2,1.77,0]],"ltp":1.54,"tv":1885.37,"id":13117391}]}]}
{"op":"mcm","clk":"1006534511","pt":1580597280254,"mc":[{"id":"1.168175449","rc":[{"batb":[[0,5,28.56],[1,1.01,0.51],[2,1.01,0]],"batl":[[0,7.4,30.29],[1,7.4,0]],"ltp":7.4,"tv":123.77,"id":13117449},{"batb":[[0,4,45.48],[1,1.01,0.51],[2,1.01,0]],"batl":[[0,5.9,23.84],[1,5.9,0]],"ltp":5.8,"tv":93.9,"id":13117392},{"batb":[[0,1.45,90.8],[1,1.01,0.51],[2,1.01,0]],"batl":[[0,1.77,49.81],[1,1.77,0]],"ltp":1.54,"tv":1885.37,"id":13117391}]}]}
{"op":"mcm","clk":"1006534622","pt":1580597281552,"mc":[{"id":"1.168175449","rc":[{"batb":[[0,5.3,85.46],[1,5.2,60.72],[2,5,28.56]],"ltp":7.4,"tv":123.77,"id":13117449},{"batb":[[1,3.95,102.29],[2,3.9,57.46]],"ltp":5.8,"tv":93.9,"id":13117392},{"batb":[[1,1.44,354.94],[2,1.43,225.85]],"ltp":1.54,"tv":1885.37,"id":13117391}]}]}
{"op":"mcm","clk":"1006535663","pt":1580597294569,"mc":[{"id":"1.168175449","rc":[{"batb":[[0,5,28.56],[1,1.01,0.51],[2,5,0]],"ltp":7.4,"tv":123.77,"id":13117449},{"batb":[[1,1.01,0.51],[2,3.9,0]],"ltp":5.8,"tv":93.9,"id":13117392}]}]}
{"op":"mcm","clk":"1006535878","pt":1580597297479,"mc":[{"id":"1.168175449","rc":[{"batb":[[0,7,74.45],[1,6.8,66.12],[2,5,28.56]],"ltp":7.4,"tv":123.77,"id":13117449},{"batb":[[0,5.2,83.02],[1,5.1,61.16],[2,4,45.48]],"ltp":5.8,"tv":93.9,"id":13117392}]}]}
{"op":"mcm","clk":"1006535941","pt":1580597298153,"mc":[{"id":"1.168175449","rc":[{"batb":[[2,6.4,32.18]],"batl":[[1,8.4,23.37]],"ltp":7.4,"tv":123.77,"id":13117449},{"batb":[[0,5.2,107.8],[2,4.5,35.64]],"batl":[[1,6.8,35.49]],"ltp":5.8,"tv":93.9,"id":13117392},{"batb":[[1,1.44,217.31],[2,1.38,115.03]],"batl":[[0,1.51,88.44],[1,1.65,63.34]],"ltp":1.54,"tv":1885.37,"id":13117391}]}]}
{"op":"mcm","clk":"1006536003","pt":1580597298882,"mc":[{"id":"1.168175449","rc":[{"batl":[[0,7.4,36.17]],"ltp":7.4,"tv":123.77,"id":13117449},{"batb":[[2,4.8,10.92]],"batl":[[0,5.8,8.4],[1,5.9,23.84],[2,6.8,35.49]],"ltp":5.8,"tv":93.9,"id":13117392},{"batb":[[0,1.46,90.74],[1,1.45,90.8],[2,1.44,217.31]],"batl":[[1,1.57,42.01],[2,1.65,63.34]],"ltp":1.54,"tv":1885.37,"id":13117391}]}]}
{"op":"mcm","clk":"1006536225","pt":1580597301161,"mc":[{"id":"1.168175449","rc":[{"batb":[[1,1.45,232.56]],"ltp":1.54,"tv":1885.37,"id":13117391}]}]}
{"op":"mcm","clk":"1006536987","pt":1580597310306,"mc":[{"id":"1.168175449","rc":[{"batb":[[0,5.5,22.74],[1,1.01,0.51],[2,6.4,0]],"batl":[[0,8.4,23.37],[1,8.4,0]],"ltp":7.4,"tv":123.77,"id":13117449},{"batb":[[0,4.5,35.64],[1,1.01,0.51],[2,4.8,0]],"batl":[[0,6.8,35.49],[1,5.9,0],[2,6.8,0]],"ltp":5.8,"tv":93.9,"id":13117392},{"batb":[[0,1.38,115.03],[1,1.01,0.51],[2,1.44,0]],"batl":[[0,1.65,63.34],[1,1.57,0],[2,1.65,0]],"ltp":1.54,"tv":1885.37,"id":13117391}]}]}
{"op":"mcm","clk":"1006537242","pt":1580597313285,"mc":[{"id":"1.168175449","rc":[{"batb":[[0,5.9,74.85],[1,5.8,47.57],[2,5.5,22.74]],"ltp":7.4,"tv":123.77,"id":13117449},{"batb":[[1,4.4,77.33],[2,4.3,90.38]],"ltp":5.8,"tv":93.9,"id":13117392},{"batb":[[0,1.38,317.15],[1,1.37,272.71],[2,1.01,0.51]],"ltp":1.54,"tv":1885.37,"id":13117391}]}]}
{"op":"mcm","clk":"1006537404","pt":1580597315406,"mc":[{"id":"1.168175449","rc":[{"batb":[[0,5.5,22.74],[1,1.01,0.51],[2,5.5,0]],"ltp":7.4,"tv":123.77,"id":13117449},{"batb":[[1,1.01,0.51],[2,4.3,0]],"ltp":5.8,"tv":93.9,"id":13117392},{"batb":[[0,1.38,115.03],[1,1.01,0.51],[2,1.01,0]],"ltp":1.54,"tv":1885.37,"id":13117391}]}]}
{"op":"mcm","clk":"1006537673","pt":1580597318415,"mc":[{"id":"1.168175449","rc":[{"batb":[[0,8,28.21],[1,7.8,49.96],[2,5.5,22.74]],"ltp":7.4,"tv":123.77,"id":13117449},{"batb":[[0,5.8,81.09],[1,5.7,47.49],[2,4.5,35.64]],"ltp":5.8,"tv":93.9,"id":13117392},{"batb":[[0,1.38,317.15],[1,1.37,272.71],[2,1.01,0.51]],"ltp":1.54,"tv":1885.37,"id":13117391}]}]}
{"op":"mcm","clk":"1006537751","pt":1580597319198,"mc":[{"id":"1.168175449","rc":[{"batb":[[2,7.2,24.71]],"batl":[[0,8.2,5.04],[1,8.4,23.37],[2,9.6,18.33]],"ltp":7.4,"tv":123.77,"id":13117449},{"batb":[[0,5.9,38],[1,5.8,81.09],[2,5.7,47.49]],"batl":[[0,6.4,7.56],[1,6.8,35.49],[2,7.6,28.17]],"ltp":5.8,"tv":93.9,"id":13117392},{"batb":[[0,1.4,105.02],[1,1.38,317.15],[2,1.37,272.71]],"batl":[[0,1.43,111.41],[1,1.53,83.8]],"ltp":1.54,"tv":1885.37,"id":13117391}]}]}
{"op":"mcm","clk":"1006537979","pt":1580597321888,"mc":[{"id":"1.168175449","rc":[{"trd":[[8,11.76]],"batb":[[0,8,22.33]],"ltp":8.0,"tv":135.53,"id":13117449},{"batl":[[1,1.49,42.01],[2,1.53,83.8]],"ltp":1.54,"tv":1885.37,"id":13117391}],"tv":2118.9}]}
{"op":"mcm","clk":"1006539249","pt":1580597337442,"mc":[{"id":"1.168175449","rc":[{"batb":[[0,6.6,6.72],[1,6.2,34.78],[2,1.01,0.51]],"batl":[[1,9.6,18.33],[2,9.6,0]],"ltp":8.0,"tv":135.53,"id":13117449},{"batb":[[0,5.3,9.24],[1,5.1,25.97],[2,1.01,0.51]],"batl":[[1,7.6,28.17],[2,7.6,0]],"ltp":5.8,"tv":93.9,"id":13117392},{"batb":[[1,1.32,139.98],[2,1.01,0.51]],"batl":[[0,1.49,42.01],[1,1.53,83.8],[2,1.53,0]],"ltp":1.54,"tv":1885.37,"id":13117391}]}]}
{"op":"mcm","clk":"1006539292","pt":1580597337915,"mc":[{"id":"1.168175449","rc":[{"batb":[[0,6.2,34.78],[1,1.01,0.51],[2,1.01,0]],"batl":[[0,9.6,18.33],[1,9.6,0]],"ltp":8.0,"tv":135.53,"id":13117449},{"batb":[[0,5.1,25.97],[1,1.01,0.51],[2,1.01,0]],"batl":[[0,7.6,28.17],[1,7.6,0]],"ltp":5.8,"tv":93.9,"id":13117392},{"batb":[[0,1.32,139.98],[1,1.01,0.51],[2,1.01,0]],"batl":[[0,1.53,83.8],[1,1.53,0]],"ltp":1.54,"tv":1885.37,"id":13117391}]}]}
{"op":"mcm","clk":"1006539456","pt":1580597339933,"mc":[{"id":"1.168175449","rc":[{"batb":[[0,6.8,52.2],[1,6.6,70.93],[2,6.2,34.78]],"ltp":8.0,"tv":135.53,"id":13117449},{"batb":[[1,5,102.87],[2,4.9,66.52]],"ltp":5.8,"tv":93.9,"id":13117392},{"batb":[[0,1.33,280.53],[1,1.32,469.13],[2,1.01,0.51]],"ltp":1.54,"tv":1885.37,"id":13117391}]}]}
{"op":"mcm","clk":"1006540008","pt":1580597347347,"mc":[{"id":"1.168175449","rc":[{"batb":[[0,1.32,139.98],[1,1.01,0.51],[2,1.01,0]],"ltp":1.54,"tv":1885.37,"id":13117391}]}]}
{"op":"mcm","clk":"1006540266","pt":1580597350472,"mc":[{"id":"1.168175449","rc":[{"batb":[[0,1.47,236.04],[1,1.46,205.27],[2,1.32,139.98]],"ltp":1.54,"tv":1885.37,"id":13117391}]}]}
{"op":"mcm","clk":"1006540321","pt":1580597351152,"mc":[{"id":"1.168175449","rc":[{"batl":[[0,7.2,39.37],[1,8.4,23.37]],"ltp":8.0,"tv":135.53,"id":13117449},{"batl":[[0,5.6,8.4],[1,5.7,24.94],[2,6.8,34.86]],"ltp":5.8,"tv":93.9,"id":13117392},{"batb":[[0,1.48,87.38],[1,1.47,322.12],[2,1.46,205.27]],"batl":[[1,1.58,42.01],[2,1.72,54.13]],"ltp":1.54,"tv":1885.37,"id":13117391}]}]}
{"op":"mcm","clk":"1006541834","pt":1580597370467,"mc":[{"id":"1.168175449","rc":[{"batb":[[0,6,8.4],[1,5.2,26.2],[2,1.01,0.51]],"batl":[[0,7.2,6.72]],"ltp":8.0,"tv":135.53,"id":13117449},{"batb":[[0,4.7,10.92],[1,4.2,42.09],[2,1.01,0.51]],"batl":[[1,6.8,34.86],[2,6.8,0]],"ltp":5.8,"tv":93.9,"id":13117392},{"batb":[[1,1.37,115.98],[2,1.01,0.51]],"batl":[[0,1.58,42.01],[1,1.72,54.13],[2,1.72,0]],"ltp":1.54,"tv":1885.37,"id":13117391}]}]}
{"op":"mcm","clk":"1006541955","pt":1580597371962,"mc":[{"id":"1.168175449","rc":[{"batb":[[0,5.2,26.2],[1,1.01,0.51],[2,1.01,0]],"batl":[[0,8.4,23.37],[1,8.4,0]],"ltp":8.0,"tv":135.53,"id":13117449},{"batb":[[0,4.2,42.09],[1,1.01,0.51],[2,1.01,0]],"batl":[[0,6.8,34.86],[1,6.8,0]],"ltp":5.8,"tv":93.9,"id":13117392},{"batb":[[0,1.37,115.98],[1,1.01,0.51],[2,1.01,0]],"batl":[[0,1.72,54.13],[1,1.72,0]],"ltp":1.54,"tv":1885.37,"id":13117391}]}]}
{"op":"mcm","clk":"1006542070","pt":1580597373174,"mc":[{"id":"1.168175449","rc":[{"batb":[[0,5.5,49.63],[1,5.4,56.14],[2,5.2,26.2]],"ltp":8.0,"tv":135.53,"id":13117449},{"batb":[[1,4,146.74],[2,3.95,55.22]],"ltp":5.8,"tv":93.9,"id":13117392},{"batb":[[0,1.37,481.92],[1,1.36,284.45],[2,1.01,0.51]],"ltp":1.54,"tv":1885.37,"id":13117391}]}]}
{"op":"mcm","clk":"1006542354","pt":1580597376284,"mc":[{"id":"1.168175449","rc":[{"batb":[[0,5.2,26.2],[1,1.01,0.51],[2,5.2,0]],"ltp":8.0,"tv":135.53,"id":13117449},{"batb":[[1,1.01,0.51],[2,3.95,0]],"ltp":5.8,"tv":93.9,"id":13117392}]}]}
{"op":"mcm","clk":"1006542637","pt":1580597379409,"mc":[{"id":"1.168175449","rc":[{"batb":[[0,8,31.02],[1,7.8,49.87],[2,5.2,26.2]],"ltp":8.0,"tv":135.53,"id":13117449},{"batb":[[0,5.9,66.76],[1,5.8,45.88],[2,4.2,42.09]],"ltp":5.8,"tv":93.9,"id":13117392},{"trd":[[1.72,5.34]],"batl":[[0,1.72,51.46]],"ltp":1.72,"tv":1890.71,"id":13117391}],"tv":2124.25}]}
{"op":"mcm","clk":"1006542689","pt":1580597379980,"mc":[{"id":"1.168175449","rc":[{"batb":[[2,7.2,24.71]],"batl":[[1,9.8,17.55]],"ltp":8.0,"tv":135.53,"id":13117449},{"batb":[[0,5.9,104.06],[2,5,26.91]],"batl":[[1,7.8,26.59]],"ltp":5.8,"tv":93.9,"id":13117392},{"batb":[[2,1.31,145.8]],"batl":[[0,1.43,112.28],[1,1.54,81.44]],"ltp":1.72,"tv":1890.71,"id":13117391}]}]}
{"op":"mcm","clk":"1006542796","pt":1580597381388,"mc":[{"id":"1.168175449","rc":[{"batl":[[0,8.2,5.04],[1,8.4,23.37],[2,9.8,17.55]],"ltp":8.0,"tv":135.53,"id":13117449},{"batb":[[2,5.3,9.24]],"batl":[[0,6.4,7.56],[1,6.8,34.86],[2,7.8,26.59]],"ltp":5.8,"tv":93.9,"id":13117392},{"batb":[[0,1.4,105.02],[1,1.37,481.92],[2,1.36,284.45]],"batl":[[1,1.49,42.01],[2,1.54,81.44]],"ltp":1.72,"tv":1890.71,"id":13117391}]}]}
{"op":"mcm","clk":"1006544041","pt":1580597397521,"mc":[{"id":"1.168175449","rc":[{"batb":[[0,7.2,24.71],[1,6,35.96],[2,1.01,0.51]],"ltp":8.0,"tv":135.53,"id":13117449},{"batb":[[0,5.9,37.3],[1,5.3,9.24],[2,5,26.91]],"ltp":5.8,"tv":93.9,"id":13117392},{"batb":[[1,1.37,115.98],[2,1.31,145.8]],"batl":[[1,1.54,81.44],[2,1.54,0]],"ltp":1.72,"tv":1890.71,"id":13117391}]}]}
{"op":"mcm","clk":"1006544095","pt":1580597398229,"mc":[{"id":"1.168175449","rc":[{"batb":[[0,6,35.96],[1,1.01,0.51],[2,1.01,0]],"batl":[[0,9.8,17.55],[1,8.4,0],[2,9.8,0]],"ltp":8.0,"tv":135.53,"id":13117449},{"batb":[[0,5,26.91],[1,1.01,0.51],[2,5,0]],"batl":[[0,7.8,26.59],[1,6.8,0],[2,7.8,0]],"ltp":5.8,"tv":93.9,"id":13117392},{"batb":[[0,1.31,145.64],[1,1.01,0.51],[2,1.31,0]],"batl":[[0,1.54,81.44],[1,1.54,0]],"ltp":1.72,"tv":1890.71,"id":13117391}]}]}
{"op":"mcm","clk":"1006544250","pt":1580597400442,"mc":[{"id":"1.168175449","rc":[{"batb":[[0,6.8,6.72],[1,6.6,82.21],[2,6.4,75.07]],"ltp":8.0,"tv":135.53,"id":13117449},{"batb":[[0,5,99.48],[1,4.9,67],[2,1.01,0.51]],"ltp":5.8,"tv":93.9,"id":13117392},{"batb":[[0,1.32,249.56],[1,1.31,487.76],[2,1.01,0.51]],"batl":[[0,1.48,42.01],[1,1.54,81.44]],"ltp":1.72,"tv":1890.71,"id":13117391}]}]}
{"op":"mcm","clk":"1006544272","pt":1580597400752,"mc":[{"id":"1.168175449","rc":[{"batb":[[0,6.6,82.21],[1,6.4,75.07],[2,6,35.96]],"ltp":8.0,"tv":135.53,"id":13117449},{"batl":[[0,1.54,81.44],[1,1.54,0]],"ltp":1.72,"tv":1890.71,"id":13117391}]}]}
{"op":"mcm","clk":"1006545338","pt":1580597413807,"mc":[{"id":"1.168175449","rc":[{"batb":[[0,6,35.96],[1,1.01,0.51],[2,6,0]],"ltp":8.0,"tv":135.53,"id":13117449},{"batb":[[0,5,26.91],[1,1.01,0.51],[2,1.01,0]],"ltp":5.8,"tv":93.9,"id":13117392},{"batb":[[0,1.31,145.64],[1,1.01,0.51],[2,1.01,0]],"ltp":1.72,"tv":1890.71,"id":13117391}]}]}
{"op":"mcm","clk":"1006545533","pt":1580597416499,"mc":[{"id":"1.168175449","rc":[{"batb":[[0,7.6,61.42],[1,7.4,55.13],[2,6,35.96]],"ltp":8.0,"tv":135.53,"id":13117449},{"batb":[[0,5.7,65.48],[1,5.6,49.64],[2,5,26.91]],"ltp":5.8,"tv":93.9,"id":13117392},{"batb":[[0,1.39,348.58],[1,1.38,265.08],[2,1.31,145.64]],"ltp":1.72,"tv":1890.71,"id":13117391}]}]}
{"op":"mcm","clk":"1006545813","pt":1580597420523,"mc":[{"id":"1.168175449","rc":[{"batb":[[0,6,35.96],[1,1.01,0.51],[2,6,0]],"ltp":8.0,"tv":135.53,"id":13117449},{"batb":[[0,5,26.91],[1,1.01,0.51],[2,5,0]],"ltp":5.8,"tv":93.9,"id":13117392},{"batb":[[0,1.31,145.64],[1,1.01,0.51],[2,1.31,0]],"ltp":1.72,"tv":1890.71,"id":13117391}]}]}
{"op":"mcm","clk":"1006546058","pt":1580597423488,"mc":[{"id":"1.168175449","rc":[{"batb":[[0,6.6,90.29],[1,6.4,75.08],[2,6,35.96]],"ltp":8.0,"tv":135.53,"id":13117449},{"batb":[[0,5,97.67],[1,4.9,67],[2,1.01,0.51]],"ltp":5.8,"tv":93.9,"id":13117392},{"batb":[[0,1.32,232.77],[1,1.31,487.71],[2,1.01,0.51]],"ltp":1.72,"tv":1890.71,"id":13117391}]}]}
{"op":"mcm","clk":"1006546447","pt":1580597428402,"mc":[{"id":"1.168175449","rc":[{"batb":[[0,1.31,145.64],[1,1.01,0.51],[2,1.01,0]],"ltp":1.72,"tv":1890.71,"id":13117391}]}]}
{"op":"mcm","clk":"1006546728","pt":1580597431505,"mc":[{"id":"1.168175449","rc":[{"batb":[[0,1.48,206.64],[1,1.47,199.36],[2,1.31,145.64]],"ltp":1.72,"tv":1890.71,"id":13117391}]}]}
{"op":"mcm","clk":"1006546786","pt":1580597432124,"mc":[{"id":"1.168175449","rc":[{"batl":[[0,7.2,33.68],[1,8.4,24.16]],"ltp":8.0,"tv":135.53,"id":13117449},{"batb":[[2,4.1,42.57]],"batl":[[0,5.7,25.81],[1,6.8,35.8]],"ltp":5.8,"tv":93.9,"id":13117392},{"batb":[[0,1.49,83.48],[1,1.48,206.64],[2,1.47,199.36]],"batl":[[1,1.74,52.72]],"ltp":1.72,"tv":1890.71,"id":13117391}]}]}
{"op":"mcm","clk":"1006546851","pt":1580597432902,"mc":[{"id":"1.168175449","rc":[{"batb":[[2,6,44.36]],"batl":[[0,7.2,40.4]],"ltp":8.0,"tv":135.53,"id":13117449},{"batb":[[2,4.7,10.92]],"batl":[[0,5.5,9.24],[1,5.7,25.81],[2,6.8,35.8]],"ltp":5.8,"tv":93.9,"id":13117392},{"batb":[[0,1.49,169.18]],"batl":[[1,1.59,42.01],[2,1.74,52.72]],"ltp":1.72,"tv":1890.71,"id":13117391}]}]}
{"op":"mcm","clk":"1006548822","pt":1580597456524,"mc":[{"id":"1.168175449","rc":[{"batb":[[0,6,44.36],[1,5.1,27.38],[2,1.01,0.51]],"ltp":8.0,"tv":135.53,"id":13117449},{"batb":[[0,5,26.91],[1,4.7,10.92],[2,4.1,42.57]],"ltp":5.8,"tv":93.9,"id":13117392},{"batb":[[1,1.38,113.22],[2,1.01,0.51]],"ltp":1.72,"tv":1890.71,"id":13117391}]}]}
{"op":"mcm","clk":"1006548830","pt":1580597456628,"mc":[{"id":"1.168175449","rc":[{"batb":[[0,6,8.4]],"batl":[[0,7.2,6.72]],"ltp":8.0,"tv":135.53,"id":13117449},{"batb":[[0,4.7,10.92],[1,4.1,42.57],[2,1.01,0.51]],"batl":[[1,6.8,35.8],[2,6.8,0]],"ltp":5.8,"tv":93.9,"id":13117392},{"batb":[[0,1.49,85.7]],"batl":[[0,1.59,42.01],[1,1.74,52.72],[2,1.74,0]],"ltp":1.72,"tv":1890.71,"id":13117391}]}]}
{"op":"mcm","clk":"1006548948","pt":1580597458024,"mc":[{"id":"1.168175449","rc":[{"batb":[[0,5.1,27.38],[1,1.01,0.51],[2,1.01,0]],"batl":[[0,8.4,24.16],[1,8.4,0]],"ltp":8.0,"tv":135.53,"id":13117449},{"batb":[[0,4.1,42.57],[1,1.01,0.51],[2,1.01,0]],"batl":[[0,6.8,35.8],[1,6.8,0]],"ltp":5.8,"tv":93.9,"id":13117392},{"batb":[[0,1.38,113.22],[1,1.01,0.51],[2,1.01,0]],"batl":[[0,1.74,52.72],[1,1.74,0]],"ltp":1.72,"tv":1890.71,"id":13117391}]}]}
{"op":"mcm","clk":"1006549292","pt":1580597462517,"mc":[{"id":"1.168175449","rc":[{"batb":[[0,6.4,53.23],[1,6.2,81.5],[2,5.1,27.38]],"ltp":8.0,"tv":135.53,"id":13117449},{"batb":[[0,4.8,50.81],[1,4.7,74.02],[2,4.1,42.57]],"ltp":5.8,"tv":93.9,"id":13117392},{"batb":[[0,1.51,311.38],[1,1.5,184.04],[2,1.38,113.22]],"ltp":1.72,"tv":1890.71,"id":13117391}]}]}
{"op":"mcm","clk":"1006549562","pt":1580597466237,"mc":[{"id":"1.168175449","rc":[{"batb":[[0,5.1,27.38],[1,1.01,0.51],[2,5.1,0]],"ltp":8.0,"tv":135.53,"id":13117449},{"batb":[[0,4.1,42.57],[1,1.01,0.51],[2,4.1,0]],"ltp":5.8,"tv":93.9,"id":13117392},{"batb":[[0,1.38,113.22],[1,1.01,0.51],[2,1.38,0]],"ltp":1.72,"tv":1890.71,"id":13117391}]}]}
{"op":"mcm","clk":"1006549831","pt":1580597469550,"mc":[{"id":"1.168175449","rc":[{"batb":[[0,5.4,68.11],[1,5.3,58.42],[2,5.1,27.38]],"ltp":8.0,"tv":135.53,"id":13117449},{"batb":[[1,4,113.81],[2,3.95,55.5]],"ltp":5.8,"tv":93.9,"id":13117392},{"batb":[[0,1.38,376],[1,1.37,273.58],[2,1.01,0.51]],"ltp":1.72,"tv":1890.71,"id":13117391}]}]}
{"op":"mcm","clk":"1006550637","pt":1580597479721,"mc":[{"id":"1.168175449","rc":[{"batb":[[0,5.1,27.38],[1,1.01,0.51],[2,5.1,0]],"ltp":8.0,"tv":135.53,"id":13117449},{"batb":[[1,1.01,0.51],[2,3.95,0]],"ltp":5.8,"tv":93.9,"id":13117392}]}]}
{"op":"mcm","clk":"1006550864","pt":1580597483437,"mc":[{"id":"1.168175449","rc":[{"batb":[[0,7.8,53.36],[1,7.6,52.38],[2,7,25.49]],"batl":[[0,8.2,5.04],[1,8.4,24.16],[2,9.6,18.33]],"ltp":8.0,"tv":135.53,"id":13117449},{"batb":[[0,5.9,40.37],[1,5.8,84.55],[2,5.3,9.24]],"batl":[[0,6.4,7.56],[1,6.8,35.8],[2,7.8,26.83]],"ltp":5.8,"tv":93.9,"id":13117392},{"batb":[[0,1.4,105.02],[1,1.38,376],[2,1.37,273.58]],"batl":[[0,1.43,109.68],[1,1.49,42.01],[2,1.55,78.84]],"ltp":1.72,"tv":1890.71,"id":13117391}]}]}
{"op":"mcm","clk":"1006551216","pt":1580597488860,"mc":[{"id":"1.168175449","rc":[{"batb":[[0,5.8,84.55],[1,5.3,9.24],[2,5,27.38]],"ltp":5.8,"tv":93.9,"id":13117392}]}]}
{"op":"mcm","clk":"1006551382","pt":1580597491758,"mc":[{"id":"1.168175449","rc":[{"batb":[[0,5.8,118.26],[1,5.7,47.38],[2,5.3,9.24]],"ltp":5.8,"tv":93.9,"id":13117392}]}]}
{"op":"mcm","clk":"1006552265","pt":1580597502560,"mc":[{"id":"1.168175449","rc":[{"batb":[[0,5.9,37.92],[1,1.01,0.51],[2,7,0]],"batl":[[0,9.6,18.33],[1,8.4,0],[2,9.6,0]],"ltp":8.0,"tv":135.53,"id":13117449},{"batb":[[0,5,27.38],[1,1.01,0.51],[2,5.3,0]],"batl":[[0,7.8,26.83],[1,6.8,0],[2,7.8,0]],"ltp":5.8,"tv":93.9,"id":13117392},{"batb":[[0,1.32,142.97],[1,1.01,0.51],[2,1.37,0]],"batl":[[0,1.55,78.84],[1,1.49,0],[2,1.55,0]],"ltp":1.72,"tv":1890.71,"id":13117391}]}]}
{"op":"mcm","clk":"1006552494","pt":1580597505462,"mc":[{"id":"1.168175449","rc":[{"batb":[[0,6.6,42.86],[1,6.4,76.14],[2,5.9,37.92]],"ltp":8.0,"tv":135.53,"id":13117449},{"batb":[[1,4.9,101.43],[2,4.8,69.59]],"ltp":5.8,"tv":93.9,"id":13117392},{"batb":[[0,1.32,586.68],[1,1.31,344.9],[2,1.01,0.51]],"ltp":1.72,"tv":1890.71,"id":13117391}]}]}
{"op":"mcm","clk":"1006553693","pt":1580597521478,"mc":[{"id":"1.168175449","rc":[{"batb":[[0,5.9,37.92],[1,1.01,0.51],[2,5.9,0]],"ltp":8.0,"tv":135.53,"id":13117449},{"batb":[[1,1.01,0.51],[2,4.8,0]],"ltp":5.8,"tv":93.9,"id":13117392},{"batb":[[0,1.32,142.97],[1,1.01,0.51],[2,1.01,0]],"ltp":1.72,"tv":1890.71,"id":13117391}]}]}
{"op":"mcm","clk":"1006553911","pt":1580597524311,"mc":[{"id":"1.168175449","rc":[{"batb":[[0,7.4,55.97],[1,5.9,37.92],[2,1.01,0.51]],"ltp":8.0,"tv":135.53,"id":13117449},{"batb":[[0,5.6,81.32],[1,5.5,51.33],[2,5,27.38]],"ltp":5.8,"tv":93.9,"id":13117392},{"batb":[[0,1.4,297.27],[1,1.39,255.56],[2,1.32,142.97]],"ltp":1.72,"tv":1890.71,"id":13117391}]}]}
{"op":"mcm","clk":"1006554219","pt":1580597527487,"mc":[{"id":"1.168175449","rc":[{"batb":[[0,5.9,37.92],[1,1.01,0.51],[2,1.01,0]],"ltp":8.0,"tv":135.53,"id":13117449},{"batb":[[0,5,27.38],[1,1.01,0.51],[2,5,0]],"ltp":5.8,"tv":93.9,"id":13117392},{"batb":[[0,1.32,142.97],[1,1.01,0.51],[2,1.32,0]],"ltp":1.72,"tv":1890.71,"id":13117391}]}]}
{"op":"mcm","clk":"1006554478","pt":1580597530229,"mc":[{"id":"1.168175449","rc":[{"batb":[[0,6.6,44.99],[1,6.4,76.14],[2,5.9,37.92]],"ltp":8.0,"tv":135.53,"id":13117449},{"batb":[[1,4.9,100.93],[2,4.8,69.59]],"ltp":5.8,"tv":93.9,"id":13117392},{"batb":[[0,1.32,582.22],[1,1.31,344.89],[2,1.01,0.51]],"ltp":1.72,"tv":1890.71,"id":13117391}]}]}
{"op":"mcm","clk":"1006555549","pt":1580597546345,"mc":[{"id":"1.168175449","rc":[{"batb":[[0,5.9,37.92],[1,1.01,0.51],[2,5.9,0]],"ltp":8.0,"tv":135.53,"id":13117449},{"batb":[[1,1.01,0.51],[2,4.8,0]],"ltp":5.8,"tv":93.9,"id":13117392}]}]}
{"op":"mcm","clk":"1006555785","pt":1580597549356,"mc":[{"id":"1.168175449","rc":[{"batb":[[0,8.8,40.04],[1,8.6,40.36],[2,5.9,37.92]],"ltp":8.0,"tv":135.53,"id":13117449},{"batb":[[0,6.6,33.55],[1,6.4,73.23],[2,5,27.38]],"ltp":5.8,"tv":93.9,"id":13117392}]}]}
{"op":"mcm","clk":"1006555833","pt":1580597550187,"mc":[{"id":"1.168175449","rc":[{"batb":[[2,8,19.2]],"batl":[[1,11.5,31.24]],"ltp":8.0,"tv":135.53,"id":13117449},{"batb":[[0,6.6,62.03],[2,5.9,38]],"batl":[[1,9.2,18.96]],"ltp":5.8,"tv":93.9,"id":13117392},{"batb":[[2,1.25,187.34]],"batl":[[0,1.37,137.69],[1,1.43,109.76]],"ltp":1.72,"tv":1890.71,"id":13117391}]}]}
{"op":"mcm","clk":"1006555888","pt":1580597551062,"mc":[{"id":"1.168175449","rc":[{"batl":[[0,9.4,4.2],[1,9.6,18.33],[2,11.5,31.24]],"ltp":8.0,"tv":135.53,"id":13117449},{"batl":[[0,7,6.72],[1,7.8,26.83],[2,9.2,18.96]],"ltp":5.8,"tv":93.9,"id":13117392},{"batb":[[0,1.34,123.51],[1,1.32,582.22],[2,1.31,344.89]],"batl":[[1,1.42,42.01],[2,1.43,109.76]],"ltp":1.72,"tv":1890.71,"id":13117391}]}]}
{"op":"mcm","clk":"1006557336","pt":1580597571081,"mc":[{"id":"1.168175449","rc":[{"batb":[[0,6.6,28.48]],"ltp":5.8,"tv":93.9,"id":13117392},{"batb":[[1,1.32,469.38],[2,1.25,187.34]],"ltp":1.72,"tv":1890.71,"id":13117391}]}]}
{"op":"mcm","clk":"1006557514","pt":1580597574227,"mc":[{"id":"1.168175449","rc":[{"batb":[[1,6.4,97.07],[2,6.2,76.48]],"ltp":5.8,"tv":93.9,"id":13117392},{"batb":[[1,1.33,171.11],[2,1.32,469.38]],"ltp":1.72,"tv":1890.71,"id":13117391}]}]}
{"op":"mcm","clk":"1006558359","pt":1580597586531,"mc":[{"id":"1.168175449","rc":[{"batb":[[0,8,19.2],[1,7.6,5.88],[2,7,25.73]],"ltp":8.0,"tv":135.53,"id":13117449},{"batb":[[1,5.9,38],[2,5.7,8.4]],"ltp":5.8,"tv":93.9,"id":13117392},{"batb":[[1,1.32,142.97],[2,1.25,187.34]],"ltp":1.72,"tv":1890.71,"id":13117391}]}]}
{"op":"mcm","clk":"1006558547","pt":1580597589433,"mc":[{"id":"1.168175449","rc":[{"batb":[[1,7.8,40.76],[2,7.6,58.27]],"ltp":8.0,"tv":135.53,"id":13117449},{"batb":[[2,5.8,61.73]],"ltp":5.8,"tv":93.9,"id":13117392},{"batb":[[2,1.26,275.41]],"ltp":1.72,"tv":1890.71,"id":13117391}]}]}
{"op":"mcm","clk":"1006560019","pt":1580597611350,"mc":[{"id":"1.168175449","rc":[{"batb":[[0,7.8,40.76],[1,7.6,58.27],[2,7,25.73]],"batl":[[1,11.5,31.24],[2,11.5,0]],"ltp":8.0,"tv":135.53,"id":13117449},{"batb":[[0,5.9,38],[1,5.8,61.73],[2,5.7,55.86]],"batl":[[1,9.2,18.96],[2,9.2,0]],"ltp":5.8,"tv":93.9,"id":13117392},{"batb":[[1,1.26,275.41],[2,1.25,632.28]],"batl":[[0,1.42,42.01],[1,1.43,109.76],[2,1.43,0]],"ltp":1.72,"tv":1890.71,"id":13117391}]}]}
{"op":"mcm","clk":"1006560081","pt":1580597612107,"mc":[{"id":"1.168175449","rc":[{"batb":[[1,7.6,52.39]],"batl":[[0,11.5,31.24],[1,11.5,0]],"ltp":8.0,"tv":135.53,"id":13117449},{"batb":[[2,5.7,47.46]],"batl":[[0,9.2,18.96],[1,9.2,0]],"ltp":5.8,"tv":93.9,"id":13117392},{"batb":[[0,1.26,275.41],[1,1.25,632.28],[2,1.01,0.51]],"batl":[[0,1.43,109.76],[1,1.43,0]],"ltp":1.72,"tv":1890.71,"id":13117391}]}]}
{"op":"mcm","clk":"1006560261","pt":1580597614465,"mc":[{"id":"1.168175449","rc":[{"batb":[[2,6.8,27.7]],"batl":[[0,11,34.62]],"ltp":8.0,"tv":135.53,"id":13117449},{"batb":[[0,5.8,100.44],[1,5.7,47.46],[2,1.01,0.51]],"batl":[[0,9,19.43]],"ltp":5.8,"tv":93.9,"id":13117392},{"batb":[[0,1.26,456.46],[1,1.25,444.94]],"batl":[[0,1.45,105.91]],"ltp":1.72,"tv":1890.71,"id":13117391}]}]}
{"op":"mcm","clk":"1006560422","pt":1580597616568,"mc":[{"id":"1.168175449","rc":[{"batb":[[0,1.26,181.05],[1,1.01,0.51],[2,1.01,0]],"ltp":1.72,"tv":1890.71,"id":13117391}]}]}
{"op":"mcm","clk":"1006560560","pt":1580597618478,"mc":[{"id":"1.168175449","rc":[{"batl":[[0,8.4,119.36],[1,11,34.62]],"ltp":8.0,"tv":135.53,"id":13117449}]}]}
{"op":"mcm","clk":"1006560651","pt":1580597619566,"mc":[{"id":"1.168175449","rc":[{"batb":[[2,7,6.72]],"batl":[[0,8,26.12],[1,8.6,5.04],[2,9.4,18.96]],"ltp":8.0,"tv":135.53,"id":13117449},{"batb":[[2,5.3,33]],"batl":[[0,6.4,7.56],[1,6.8,36.12],[2,7.8,26.75]],"ltp":5.8,"tv":93.9,"id":13117392},{"batb":[[0,1.39,216.83],[1,1.38,373.6],[2,1.37,273.79]],"batl":[[1,1.51,87.34]],"ltp":1.72,"tv":1890.71,"id":13117391}]}]}
{"op":"mcm","clk":"1006561486","pt":1580597632507,"mc":[{"id":"1.168175449","rc":[{"batb":[[0,7,6.72],[1,6.8,27.7],[2,6.2,35.01]],"ltp":8.0,"tv":135.53,"id":13117449},{"batb":[[0,5.8,38.71],[1,5.3,33],[2,1.01,0.51]],"ltp":5.8,"tv":93.9,"id":13117392},{"batb":[[1,1.32,141.31],[2,1.01,0.51]],"ltp":1.72,"tv":1890.71,"id":13117391}]}]}
{"op":"mcm","clk":"1006561544","pt":1580597633379,"mc":[{"id":"1.168175449","rc":[{"batb":[[1,6.2,35.01],[2,1.01,0.51]],"batl":[[0,8.6,5.04],[1,9.4,18.96],[2,9.4,0]],"ltp":8.0,"tv":135.53,"id":13117449},{"batb":[[0,5.3,33],[1,1.01,0.51],[2,1.01,0]],"batl":[[1,7.8,26.75],[2,7.8,0]],"ltp":5.8,"tv":93.9,"id":13117392},{"batb":[[0,1.39,107.54]],"batl":[[0,1.51,87.34],[1,1.51,0]],"ltp":1.72,"tv":1890.71,"id":13117391}]}]}
{"op":"mcm","clk":"1006561598","pt":1580597634306,"mc":[{"id":"1.168175449","rc":[{"batb":[[0,6.2,35.01],[1,1.01,0.51],[2,1.01,0]],"batl":[[0,9.4,18.96],[1,9.4,0]],"ltp":8.0,"tv":135.53,"id":13117449},{"batb":[[0,5.3,23.76]],"batl":[[0,7.8,26.75],[1,7.8,0]],"ltp":5.8,"tv":93.9,"id":13117392},{"batb":[[0,1.32,141.31],[1,1.01,0.51],[2,1.01,0]],"ltp":1.72,"tv":1890.71,"id":13117391}]}]}
{"op":"mcm","clk":"1006561695","pt":1580597635500,"mc":[{"id":"1.168175449","rc":[{"batb":[[0,7,73.15],[1,6.8,65.79],[2,6.2,35.01]],"ltp":8.0,"tv":135.53,"id":13117449},{"batb":[[0,5.3,88.85],[1,5.2,58.28],[2,1.01,0.51]],"ltp":5.8,"tv":93.9,"id":13117392},{"batb":[[0,1.32,343.63],[1,1.31,340.15],[2,1.01,0.51]],"ltp":1.72,"tv":1890.71,"id":13117391}]}]}
{"op":"mcm","clk":"1006563121","pt":1580597656143,"mc":[{"id":"1.168175449","rc":[{"batb":[[0,1.32,141.31],[1,1.01,0.51],[2,1.01,0]],"ltp":1.72,"tv":1890.71,"id":13117391}]}]}
{"op":"mcm","clk":"1006563364","pt":1580597659441,"mc":[{"id":"1.168175449","rc":[{"batl":[[0,7.2,32.81],[1,8,5.88],[2,8.2,25.49]],"ltp":8.0,"tv":135.53,"id":13117449},{"batb":[[2,5,10.08]],"batl":[[0,5.9,8.4],[1,6,22.82],[2,6.8,36.04]],"ltp":5.8,"tv":93.9,"id":13117392},{"batb":[[0,1.46,89.78],[1,1.44,239.04],[2,1.43,321.3]],"batl":[[1,1.53,42.01],[2,1.57,75.22]],"ltp":1.72,"tv":1890.71,"id":13117391}]}]}
{"op":"mcm","clk":"1006564529","pt":1580597676483,"mc":[{"id":"1.168175449","rc":[{"batb":[[0,6.2,35.01],[1,5.7,41.23],[2,1.01,0.51]],"ltp":8.0,"tv":135.53,"id":13117449},{"batb":[[0,5.3,23.76],[1,5,10.08],[2,4.9,28.09]],"ltp":5.8,"tv":93.9,"id":13117392},{"batb":[[1,1.43,97.46],[2,1.39,110.39]],"ltp":1.72,"tv":1890.71,"id":13117391}]}]}
{"op":"mcm","clk":"1006564554","pt":1580597676745,"mc":[{"id":"1.168175449","rc":[{"batb":[[0,5.7,41.23],[1,1.01,0.51],[2,1.01,0]],"batl":[[0,8,5.88],[1,8.2,25.49],[2,8.2,0]],"ltp":8.0,"tv":135.53,"id":13117449},{"batb":[[0,5,10.08],[1,4.9,28.09],[2,1.01,0.51]],"batl":[[1,6.8,36.04],[2,6.8,0]],"ltp":5.8,"tv":93.9,"id":13117392},{"batb":[[0,1.43,97.46],[1,1.39,110.39],[2,1.01,0.51]],"batl":[[0,1.53,42.01],[1,1.57,75.22],[2,1.57,0]],"ltp":1.72,"tv":1890.71,"id":13117391}]}]}
{"op":"mcm","clk":"1006564704","pt":1580597678446,"mc":[{"id":"1.168175449","rc":[{"batl":[[0,8.2,25.49],[1,8.2,0]],"ltp":8.0,"tv":135.53,"id":13117449},{"batb":[[0,4.9,28.09],[1,1.01,0.51],[2,1.01,0]],"batl":[[0,6.8,36.04],[1,6.8,0]],"ltp":5.8,"tv":93.9,"id":13117392},{"batb":[[0,1.39,110.39],[1,1.01,0.51],[2,1.01,0]],"batl":[[0,1.57,75.22],[1,1.57,0]],"ltp":1.72,"tv":1890.71,"id":13117391}]}]}
{"op":"mcm","clk":"1006564761","pt":1580597679362,"mc":[{"id":"1.168175449","rc":[{"batb":[[0,6.6,55.23],[1,6.4,75.58],[2,5.7,41.23]],"ltp":8.0,"tv":135.53,"id":13117449},{"batb":[[0,5,61.96],[1,4.9,94.83],[2,1.01,0.51]],"ltp":5.8,"tv":93.9,"id":13117392},{"batb":[[1,1.38,378.57],[2,1.37,273.84]],"ltp":1.72,"tv":1890.71,"id":13117391}]}]}
{"op":"mcm","clk":"1006564920","pt":1580597681539,"mc":[{"id":"1.168175449","rc":[{"batb":[[0,5.7,41.23],[1,1.01,0.51],[2,5.7,0]],"ltp":8.0,"tv":135.53,"id":13117449},{"batb":[[0,4.9,28.09],[1,1.01,0.51],[2,1.01,0]],"ltp":5.8,"tv":93.9,"id":13117392}]}]}
{"op":"mcm","clk":"1006565162","pt":1580597684495,"mc":[{"id":"1.168175449","rc":[{"batb":[[0,7.8,48.28],[1,7.6,52.22],[2,5.7,41.23]],"ltp":8.0,"tv":135.53,"id":13117449},{"batb":[[0,5.8,52.52],[1,5.7,47.59],[2,4.9,28.09]],"ltp":5.8,"tv":93.9,"id":13117392}]}]}
{"op":"mcm","clk":"1006565235","pt":1580597685463,"mc":[{"id":"1.168175449","rc":[{"batb":[[2,7,6.72]],"batl":[[1,8.6,5.04],[2,9.6,17.78]],"ltp":8.0,"tv":135.53,"id":13117449},{"batb":[[0,5.8,91.15],[2,5.3,9.24]],"batl":[[0,6.4,7.56],[1,6.8,36.04],[2,8,25.18]],"ltp":5.8,"tv":93.9,"id":13117392},{"batb":[[0,1.39,217.94]],"batl":[[0,1.44,107.01],[1,1.48,42.01],[2,1.52,84.82]],"ltp":1.72,"tv":1890.71,"id":13117391}]}]}
{"op":"mcm","clk":"1006566419","pt":1580597701415,"mc":[{"id":"1.168175449","rc":[{"batb":[[0,7,6.72],[1,6.8,26.99],[2,6,35.49]],"ltp":8.0,"tv":135.53,"id":13117449},{"batb":[[0,5.8,38.63],[1,5.3,9.24],[2,5.2,24.94]],"ltp":5.8,"tv":93.9,"id":13117392},{"batb":[[1,1.31,148.55],[2,1.01,0.51]],"ltp":1.72,"tv":1890.71,"id":13117391}]}]}
{"op":"mcm","clk":"1006566497","pt":1580597702404,"mc":[{"id":"1.168175449","rc":[{"batb":[[0,6,35.49],[1,1.01,0.51],[2,6,0]],"batl":[[0,9.6,17.78],[1,8.6,0],[2,9.6,0]],"ltp":8.0,"tv":135.53,"id":13117449},{"batb":[[0,5.2,24.94],[1,1.01,0.51],[2,5.2,0]],"batl":[[0,8,25.18],[1,6.8,0],[2,8,0]],"ltp":5.8,"tv":93.9,"id":13117392},{"batb":[[0,1.31,148.55],[1,1.01,0.51],[2,1.01,0]],"batl":[[0,1.52,84.82],[1,1.48,0],[2,1.52,0]],"ltp":1.72,"tv":1890.71,"id":13117391}]}]}
{"op":"mcm","clk":"1006566633","pt":1580597704316,"mc":[{"id":"1.168175449","rc":[{"batb":[[0,7,44.51],[1,6.8,66.31],[2,6,35.49]],"ltp":8.0,"tv":135.53,"id":13117449},{"batb":[[0,5.2,96.77],[1,5.1,60.82],[2,1.01,0.51]],"ltp":5.8,"tv":93.9,"id":13117392},{"batb":[[0,1.31,391.66],[1,1.3,354.82],[2,1.01,0.51]],"ltp":1.72,"tv":1890.71,"id":13117391}]}]}
{"op":"mcm","clk":"1006566903","pt":1580597708395,"mc":[{"id":"1.168175449","rc":[{"batb":[[0,1.31,148.55],[1,1.01,0.51],[2,1.01,0]],"ltp":1.72,"tv":1890.71,"id":13117391}]}]}
{"op":"mcm","clk":"1006567128","pt":1580597711487,"mc":[{"id":"1.168175449","rc":[{"batl":[[0,7.2,33.28],[1,8,32]],"ltp":8.0,"tv":135.53,"id":13117449},{"batb":[[2,4.9,39.12]],"batl":[[0,5.8,8.4],[1,5.9,23.92],[2,6.6,38.32]],"ltp":5.8,"tv":93.9,"id":13117392},{"batb":[[0,1.47,87.18],[1,1.45,239.19],[2,1.44,311.96]],"batl":[[1,1.54,42.01],[2,1.58,73.25]],"ltp":1.72,"tv":1890.71,"id":13117391}]}]}
{"op":"mcm","clk":"1006568277","pt":1580597728411,"mc":[{"id":"1.168175449","rc":[{"batb":[[0,5.7,21.17],[1,1.01,0.51],[2,6,0]],"batl":[[0,8,26.12],[1,8,0]],"ltp":8.0,"tv":135.53,"id":13117449},{"batb":[[0,4.9,29.03],[1,1.01,0.51],[2,4.9,0]],"batl":[[0,6.6,38.32],[1,5.9,0],[2,6.6,0]],"ltp":5.8,"tv":93.9,"id":13117392},{"batb":[[0,1.4,106.3],[1,1.01,0.51],[2,1.44,0]],"batl":[[0,1.58,73.25],[1,1.54,0],[2,1.58,0]],"ltp":1.72,"tv":1890.71,"id":13117391}]}]}
{"op":"mcm","clk":"1006568601","pt":1580597733333,"mc":[{"id":"1.168175449","rc":[{"batb":[[0,7,84.8],[1,6.8,65.31],[2,5.7,21.17]],"ltp":8.0,"tv":135.53,"id":13117449},{"batb":[[0,5.3,60.48],[1,5.2,58.37],[2,4.9,29.03]],"ltp":5.8,"tv":93.9,"id":13117392},{"batb":[[0,1.44,218.48],[1,1.43,223.52],[2,1.4,106.3]],"ltp":1.72,"tv":1890.71,"id":13117391}]}]}
{"op":"mcm","clk":"1006569029","pt":1580597740254,"mc":[{"id":"1.168175449","rc":[{"batb":[[0,5.7,21.17],[1,1.01,0.51],[2,5.7,0]],"ltp":8.0,"tv":135.53,"id":13117449},{"batb":[[0,4.9,29.03],[1,1.01,0.51],[2,4.9,0]],"ltp":5.8,"tv":93.9,"id":13117392},{"batb":[[0,1.4,106.3],[1,1.01,0.51],[2,1.4,0]],"ltp":1.72,"tv":1890.71,"id":13117391}]}]}
{"op":"mcm","clk":"1006569181","pt":1580597743153,"mc":[{"id":"1.168175449","rc":[{"batb":[[0,6.4,106.71],[1,6.2,79.37],[2,5.7,21.17]],"ltp":8.0,"tv":135.53,"id":13117449},{"batb":[[0,4.9,110.88],[1,4.8,69.62],[2,1.01,0.51]],"ltp":5.8,"tv":93.9,"id":13117392},{"batb":[[0,1.4,272.33],[1,1.39,253.29],[2,1.01,0.51]],"ltp":1.72,"tv":1890.71,"id":13117391}]}]}
{"op":"mcm","clk":"1006569694","pt":1580597753083,"mc":[{"id":"1.168175449","rc":[{"batb":[[0,5.7,21.17],[1,1.01,0.51],[2,5.7,0]],"ltp":8.0,"tv":135.53,"id":13117449},{"batb":[[0,4.9,29.03],[1,1.01,0.51],[2,1.01,0]],"ltp":5.8,"tv":93.9,"id":13117392}]}]}
{"op":"mcm","clk":"1006569895","pt":1580597756535,"mc":[{"id":"1.168175449","rc":[{"batb":[[0,7.6,64.4],[1,7.4,54.74],[2,5.7,21.17]],"ltp":8.0,"tv":135.53,"id":13117449},{"batb":[[0,5.7,36.03],[1,5.6,49.74],[2,4.9,29.03]],"ltp":5.8,"tv":93.9,"id":13117392}]}]}
{"op":"mcm","clk":"1006569924","pt":1580597757152,"mc":[{"id":"1.168175449","rc":[{"batb":[[2,7,6.72]],"batl":[[1,8.6,5.04],[2,9.8,17.47]],"ltp":8.0,"tv":135.53,"id":13117449},{"batb":[[0,5.7,77.18],[2,5.2,9.24]],"batl":[[0,6.2,7.56],[1,6.6,38.32],[2,8,25.34]],"ltp":5.8,"tv":93.9,"id":13117392},{"batb":[[0,1.4,377.35],[2,1.3,149.26]],"batl":[[0,1.45,103.07],[1,1.49,42.01],[2,1.55,78.84]],"ltp":1.72,"tv":1890.71,"id":13117391}]}]}
{"op":"mcm","clk":"1006571206","pt":1580597776417,"mc":[{"id":"1.168175449","rc":[{"batb":[[0,6,37.69],[1,1.01,0.51],[2,7,0]],"batl":[[0,9.8,17.47],[1,8.6,0],[2,9.8,0]],"ltp":8.0,"tv":135.53,"id":13117449},{"batb":[[0,5,27.62],[1,1.01,0.51],[2,5.2,0]],"batl":[[0,8,25.34],[1,6.6,0],[2,8,0]],"ltp":5.8,"tv":93.9,"id":13117392},{"batb":[[0,1.3,149.26],[1,1.01,0.51],[2,1.3,0]],"batl":[[0,1.55,78.84],[1,1.49,0],[2,1.55,0]],"ltp":1.72,"tv":1890.71,"id":13117391}]}]}
{"op":"mcm","clk":"1006571363","pt":1580597778905,"mc":[{"id":"1.168175449","rc":[{"batb":[[0,6.8,43.42],[1,6.6,70.73],[2,6,37.69]],"ltp":8.0,"tv":135.53,"id":13117449},{"batb":[[0,5,95.24],[1,4.9,66.64],[2,1.01,0.51]],"ltp":5.8,"tv":93.9,"id":13117392},{"batb":[[0,1.3,638.08],[1,1.29,374.27],[2,1.01,0.51]],"ltp":1.72,"tv":1890.71,"id":13117391}]}]}
{"op":"mcm","clk":"1006572313","pt":1580597790434,"mc":[{"id":"1.168175449","rc":[{"batb":[[0,1.3,149.26],[1,1.01,0.51],[2,1.01,0]],"ltp":1.72,"tv":1890.71,"id":13117391}]}]}
{"op":"mcm","clk":"1006572556","pt":1580597793226,"mc":[{"id":"1.168175449","rc":[{"batb":[[0,1.48,144.71],[1,1.47,198.01],[2,1.3,149.26]],"ltp":1.72,"tv":1890.71,"id":13117391}]}]}
{"op":"mcm","clk":"1006572661","pt":1580597794468,"mc":[{"id":"1.168175449","rc":[{"batl":[[0,7,35.17],[1,7.8,27.62]],"ltp":8.0,"tv":135.53,"id":13117449},{"batb":[[2,4.3,38]],"batl":[[0,5.6,26.44],[1,6.4,42.02]],"ltp":5.8,"tv":93.9,"id":13117392},{"batb":[[0,1.5,80.89],[1,1.48,144.71],[2,1.47,198.01]],"batl":[[1,1.69,57.83]],"ltp":1.72,"tv":1890.71,"id":13117391}]}]}
{"op":"mcm","clk":"1006572715","pt":1580597795139,"mc":[{"id":"1.168175449","rc":[{"batb":[[2,6.2,7.56]],"batl":[[1,7.6,5.88],[2,7.8,27.62]],"ltp":8.0,"tv":135.53,"id":13117449},{"batb":[[2,4.7,10.92]],"batl":[[0,5.6,34.84]],"ltp":5.8,"tv":93.9,"id":13117392},{"batb":[[2,1.47,287.07]],"ltp":1.72,"tv":1890.71,"id":13117391}]}]}
{"op":"mcm","clk":"1006574849","pt":1580597827500,"mc":[{"id":"1.168175449","rc":[{"batb":[[0,6.2,7.56],[1,5.2,25.73],[2,1.01,0.51]],"batl":[[0,7.6,5.88],[1,7.8,27.62],[2,7.8,0]],"ltp":8.0,"tv":135.53,"id":13117449},{"batb":[[0,4.7,10.92],[1,4.3,38],[2,1.01,0.51]],"batl":[[0,5.6,8.4]],"ltp":5.8,"tv":93.9,"id":13117392},{"batb":[[0,1.47,89.06],[1,1.42,100.32],[2,1.01,0.51]],"batl":[[0,1.69,57.83],[1,1.69,0]],"ltp":1.72,"tv":1890.71,"id":13117391}]}]}
{"op":"mcm","clk":"1006574878","pt":1580597828285,"mc":[{"id":"1.168175449","rc":[{"batb":[[0,5.2,25.73],[1,1.01,0.51],[2,1.01,0]],"batl":[[0,7.8,27.62],[1,7.8,0]],"ltp":8.0,"tv":135.53,"id":13117449},{"batb":[[0,4.3,38],[1,1.01,0.51],[2,1.01,0]],"batl":[[0,6.4,42.02],[1,6.4,0]],"ltp":5.8,"tv":93.9,"id":13117392},{"batb":[[0,1.42,100.32],[1,1.01,0.51],[2,1.01,0]],"ltp":1.72,"tv":1890.71,"id":13117391}]}]}
{"op":"mcm","clk":"1006574975","pt":1580597830089,"mc":[{"id":"1.168175449","rc":[{"batb":[[0,5.8,61.3],[1,5.7,49.31],[2,5.2,25.73]],"ltp":8.0,"tv":135.53,"id":13117449},{"batb":[[0,4.3,133.62],[1,4.2,94.53],[2,1.01,0.51]],"ltp":5.8,"tv":93.9,"id":13117392},{"batb":[[1,1.41,260.89],[2,1.4,246.03]],"ltp":1.72,"tv":1890.71,"id":13117391}]}]}
{"op":"mcm","clk":"1006575032","pt":1580597831224,"mc":[{"id":"1.168175449","rc":[{"batb":[[2,5.3,25.18]],"batl":[[0,7.8,27.07]],"ltp":8.0,"tv":135.53,"id":13117449},{"batl":[[0,6.2,21.09]],"ltp":5.8,"tv":93.9,"id":13117392}]}]}
{"op":"mcm","clk":"1006575143","pt":1580597832978,"mc":[{"id":"1.168175449","rc":[{"batb":[[1,1.01,0.51],[2,1.4,0]],"ltp":1.72,"tv":1890.71,"id":13117391}]}]}
{"op":"mcm","clk":"1006575326","pt":1580597836017,"mc":[{"id":"1.168175449","rc":[{"batb":[[0,1.6,251.75],[1,1.59,145.69],[2,1.42,100.32]],"ltp":1.72,"tv":1890.71,"id":13117391}]}]}
{"op":"mcm","clk":"1006575394","pt":1580597837316,"mc":[{"id":"1.168175449","rc":[{"batl":[[0,5.9,24.23],[1,6.6,6.72],[2,6.8,36.98]],"ltp":8.0,"tv":135.53,"id":13117449},{"batb":[[2,4.1,13.44]],"batl":[[0,4.8,47.27],[1,5.5,27.77]],"ltp":5.8,"tv":93.9,"id":13117392},{"batb":[[0,1.63,59.48],[1,1.6,251.75],[2,1.59,145.69]],"batl":[[1,1.9,39.34]],"ltp":1.72,"tv":1890.71,"id":13117391}]}]}
{"op":"mcm","clk":"1006576263","pt":1580597851440,"mc":[{"id":"1.168175449","rc":[{"batb":[[0,4.5,36.43],[1,1.01,0.51],[2,5.3,0]],"batl":[[0,6.6,6.72],[1,6.8,36.98],[2,6.8,0]],"ltp":8.0,"tv":135.53,"id":13117449},{"batb":[[0,4.1,13.44],[1,3.75,26.99],[2,1.01,0.51]],"batl":[[0,4.8,10.92]],"ltp":5.8,"tv":93.9,"id":13117392},{"batb":[[0,1.58,72.26],[1,1.52,77.19],[2,1.01,0.51]],"batl":[[0,1.9,39.34],[1,1.9,0]],"ltp":1.72,"tv":1890.71,"id":13117391}]}]}
{"op":"mcm","clk":"1006576322","pt":1580597852258,"mc":[{"id":"1.168175449","rc":[{"batl":[[0,6.8,36.98],[1,6.8,0]],"ltp":8.0,"tv":135.53,"id":13117449},{"batb":[[0,3.75,26.99],[1,1.01,0.51],[2,1.01,0]],"batl":[[0,5.5,27.77],[1,5.5,0]],"ltp":5.8,"tv":93.9,"id":13117392},{"batb":[[0,1.52,77.19],[1,1.01,0.51],[2,1.01,0]],"ltp":1.72,"tv":1890.71,"id":13117391}]}]}
{"op":"mcm","clk":"1006576485","pt":1580597854536,"mc":[{"id":"1.168175449","rc":[{"batb":[[0,4.7,33.44]],"batl":[[0,7,33.91]],"ltp":8.0,"tv":135.53,"id":13117449},{"batl":[[0,5.4,28.25]],"ltp":5.8,"tv":93.9,"id":13117392},{"batb":[[0,1.5,79.47]],"batl":[[0,1.88,40.52]],"ltp":1.72,"tv":1890.71,"id":13117391}]}]}
{"op":"mcm","clk":"1006576590","pt":1580597856151,"mc":[{"id":"1.168175449","rc":[{"batb":[[0,5.6,57.95],[1,5.5,53.44],[2,4.7,33.44]],"ltp":8.0,"tv":135.53,"id":13117449},{"batb":[[0,4.1,100.87],[1,3.75,26.99],[2,1.01,0.51]],"ltp":5.8,"tv":93.9,"id":13117392},{"batb":[[0,1.64,213.94],[1,1.63,132.78],[2,1.5,79.47]],"ltp":1.72,"tv":1890.71,"id":13117391}]}]}
{"op":"mcm","clk":"1006576833","pt":1580597859345,"mc":[{"id":"1.168175449","rc":[{"batb":[[0,4.7,33.44],[1,1.01,0.51],[2,4.7,0]],"ltp":8.0,"tv":135.53,"id":13117449},{"batb":[[0,3.75,26.99],[1,1.01,0.51],[2,1.01,0]],"ltp":5.8,"tv":93.9,"id":13117392},{"batb":[[0,1.5,79.47],[1,1.01,0.51],[2,1.5,0]],"ltp":1.72,"tv":1890.71,"id":13117391}]}]}
{"op":"mcm","clk":"1006577002","pt":1580597862337,"mc":[{"id":"1.168175449","rc":[{"batb":[[0,4.9,60.12],[1,4.8,72.56],[2,4.7,33.44]],"ltp":8.0,"tv":135.53,"id":13117449},{"batb":[[1,3.65,96.54],[2,3.6,69.11]],"ltp":5.8,"tv":93.9,"id":13117392},{"batb":[[0,1.5,293.92],[1,1.49,187.75],[2,1.01,0.51]],"ltp":1.72,"tv":1890.71,"id":13117391}]}]}
{"op":"mcm","clk":"1006577497","pt":1580597870204,"mc":[{"id":"1.168175449","rc":[{"batb":[[0,4.7,33.44],[1,1.01,0.51],[2,4.7,0]],"ltp":8.0,"tv":135.53,"id":13117449},{"batb":[[1,1.01,0.51],[2,3.6,0]],"ltp":5.8,"tv":93.9,"id":13117392}]}]}
{"op":"mcm","clk":"1006577689","pt":1580597873499,"mc":[{"id":"1.168175449","rc":[{"batb":[[0,6.6,32.24],[1,6.4,75.94],[2,4.7,33.44]],"ltp":8.0,"tv":135.53,"id":13117449},{"batb":[[0,4.8,108.26],[1,4.7,72.65],[2,3.75,26.99]],"ltp":5.8,"tv":93.9,"id":13117392}]}]}
{"op":"mcm","clk":"1006577736","pt":1580597874106,"mc":[{"id":"1.168175449","rc":[{"batb":[[2,6,36.27]],"batl":[[1,8,25.73]],"ltp":8.0,"tv":135.53,"id":13117449},{"batb":[[0,4.8,137.69],[2,4.1,44.53]],"batl":[[1,6.2,21.72]],"ltp":5.8,"tv":93.9,"id":13117392},{"batb":[[2,1.42,101.66]],"batl":[[0,1.56,77.5],[1,1.74,52.56]],"ltp":1.72,"tv":1890.71,"id":13117391}]}]}
{"op":"mcm","clk":"1006577812","pt":1580597875365,"mc":[{"id":"1.168175449","rc":[{"batb":[[2,6,44.67]],"batl":[[1,7.4,5.88],[2,8,25.73]],"ltp":8.0,"tv":135.53,"id":13117449},{"batb":[[2,4.6,10.92]],"batl":[[0,5.4,37.49]],"ltp":5.8,"tv":93.9,"id":13117392},{"batb":[[1,1.49,273.45]],"batl":[[1,1.6,42.01],[2,1.74,52.56]],"ltp":1.72,"tv":1890.71,"id":13117391}]}]}
{"op":"mcm","clk":"1006579114","pt":1580597897512,"mc":[{"id":"1.168175449","rc":[{"batb":[[0,6,8.4],[1,5.2,26.12],[2,1.01,0.51]],"batl":[[0,7.4,5.88],[1,8,25.73],[2,8,0]],"ltp":8.0,"tv":135.53,"id":13117449},{"batb":[[0,4.6,10.92],[1,4.1,44.53],[2,1.01,0.51]],"batl":[[0,5.4,9.24]],"ltp":5.8,"tv":93.9,"id":13117392},{"batb":[[0,1.49,85.7],[1,1.42,101.66],[2,1.01,0.51]],"batl":[[0,1.6,42.01],[1,1.74,52.56],[2,1.74,0]],"ltp":1.72,"tv":1890.71,"id":13117391}]}]}
{"op":"mcm","clk":"1006579169","pt":1580597898287,"mc":[{"id":"1.168175449","rc":[{"batb":[[0,5.2,26.12],[1,1.01,0.51],[2,1.01,0]],"batl":[[0,8,25.73],[1,8,0]],"ltp":8.0,"tv":135.53,"id":13117449},{"batb":[[0,4.1,44.53],[1,1.01,0.51],[2,1.01,0]],"batl":[[0,6.2,21.72],[1,6.2,0]],"ltp":5.8,"tv":93.9,"id":13117392},{"batb":[[0,1.42,101.66],[1,1.01,0.51],[2,1.01,0]],"batl":[[0,1.74,52.56],[1,1.74,0]],"ltp":1.72,"tv":1890.71,"id":13117391}]}]}
{"op":"mcm","clk":"1006579303","pt":1580597900502,"mc":[{"id":"1.168175449","rc":[{"batb":[[0,5.5,58.47],[1,5.4,55.88],[2,5.2,26.12]],"ltp":8.0,"tv":135.53,"id":13117449},{"batb":[[0,4.1,98.87],[1,4,106.73],[2,1.01,0.51]],"ltp":5.8,"tv":93.9,"id":13117392},{"batb":[[0,1.42,247.27],[1,1.41,237.35],[2,1.01,0.51]],"ltp":1.72,"tv":1890.71,"id":13117391}]}]}
{"op":"mcm","clk":"1006579342","pt":1580597901123,"mc":[{"id":"1.168175449","rc":[{"batb":[[2,5.1,26.83]],"ltp":8.0,"tv":135.53,"id":13117449},{"batb":[[0,4.1,97.54]],"batl":[[0,6.2,21.24]],"ltp":5.8,"tv":93.9,"id":13117392},{"batb":[[0,1.42,145.61],[1,1.41,339.87]],"ltp":1.72,"tv":1890.71,"id":13117391}]}]}
{"op":"mcm","clk":"1006579419","pt":1580597902305,"mc":[{"id":"1.168175449","rc":[{"batb":[[0,5.1,26.83],[1,1.01,0.51],[2,5.1,0]],"ltp":8.0,"tv":135.53,"id":13117449},{"batb":[[0,4.1,43.2],[1,1.01,0.51],[2,1.01,0]],"ltp":5.8,"tv":93.9,"id":13117392}]}]}
{"op":"mcm","clk":"1006579647","pt":1580597905555,"mc":[{"id":"1.168175449","rc":[{"batb":[[0,7.4,56.68],[1,7.2,58.5],[2,5.1,26.83]],"ltp":8.0,"tv":135.53,"id":13117449},{"batb":[[0,5.5,43.65],[1,5.4,53.82],[2,4.1,43.2]],"ltp":5.8,"tv":93.9,"id":13117392}]}]}
{"op":"mcm","clk":"1006579687","pt":1580597906226,"mc":[{"id":"1.168175449","rc":[{"batb":[[2,6.8,27.38]],"batl":[[1,9.2,20.14]],"ltp":8.0,"tv":135.53,"id":13117449},{"batb":[[0,5.5,65.68],[2,4.7,31.47]],"batl":[[1,7,32.89]],"ltp":5.8,"tv":93.9,"id":13117392},{"batb":[[2,1.35,126.05]],"batl":[[0,1.47,99.53],[1,1.59,72.07]],"ltp":1.72,"tv":1890.71,"id":13117391}]}]}
{"op":"mcm","clk":"1006579751","pt":1580597907512,"mc":[{"id":"1.168175449","rc":[{"batl":[[0,8,31.61]],"ltp":8.0,"tv":135.53,"id":13117449},{"batb":[[2,5,10.08]],"batl":[[0,6,8.4],[1,6.2,21.24],[2,7,32.89]],"ltp":5.8,"tv":93.9,"id":13117392},{"batb":[[0,1.42,245.59]],"ltp":1.72,"tv":1890.71,"id":13117391}]}]}
{"op":"mcm","clk":"1006579821","pt":1580597908543,"mc":[{"id":"1.168175449","rc":[{"batl":[[1,1.51,42.01],[2,1.59,72.07]],"ltp":1.72,"tv":1890.71,"id":13117391}]}]}
{"op":"mcm","clk":"1006580542","pt":1580597920339,"mc":[{"id":"1.168175449","rc":[{"batl":[[0,8,25.73]],"ltp":8.0,"tv":135.53,"id":13117449},{"batb":[[2,4.7,31.47]],"ltp":5.8,"tv":93.9,"id":13117392}]}]}
{"op":"mcm","clk":"1006580719","pt":1580597923234,"mc":[{"id":"1.168175449","rc":[{"batl":[[1,8.2,5.04],[2,9.2,20.14]],"ltp":8.0,"tv":135.53,"id":13117449},{"batb":[[2,5.1,10.08]],"ltp":5.8,"tv":93.9,"id":13117392}]}]}
{"op":"mcm","clk":"1006580794","pt":1580597924472,"mc":[{"id":"1.168175449","rc":[{"batb":[[0,5.8,39.89],[1,1.01,0.51],[2,6.8,0]],"batl":[[0,9.2,20.14],[1,8.2,0],[2,9.2,0]],"ltp":8.0,"tv":135.53,"id":13117449},{"batb":[[0,4.7,31.47],[1,1.01,0.51],[2,5.1,0]],"batl":[[0,7,32.89],[1,6.2,0],[2,7,0]],"ltp":5.8,"tv":93.9,"id":13117392},{"batb":[[0,1.35,126.05],[1,1.01,0.51],[2,1.35,0]],"batl":[[0,1.59,72.07],[1,1.51,0],[2,1.59,0]],"ltp":1.72,"tv":1890.71,"id":13117391}]}]}
{"op":"mcm","clk":"1006580988","pt":1580597927365,"mc":[{"id":"1.168175449","rc":[{"batb":[[0,6.2,112.06],[1,6,85.53],[2,5.8,39.89]],"batl":[[0,9,20.22],[1,9.2,20.14]],"ltp":8.0,"tv":135.53,"id":13117449},{"batb":[[0,4.7,104.8],[1,4.6,76.88],[2,1.01,0.51]],"ltp":5.8,"tv":93.9,"id":13117392},{"batb":[[0,1.36,253.23],[1,1.35,418.48],[2,1.01,0.51]],"ltp":1.72,"tv":1890.71,"id":13117391}]}]}
{"op":"mcm","clk":"1006580996","pt":1580597927570,"mc":[{"id":"1.168175449","rc":[{"batl":[[1,9.2,0]],"ltp":8.0,"tv":135.53,"id":13117449}]}]}
{"op":"mcm","clk":"1006582120","pt":1580597944860,"mc":[{"id":"1.168175449","rc":[{"batb":[[0,1.35,126.05],[1,1.01,0.51],[2,1.01,0]],"ltp":1.72,"tv":1890.71,"id":13117391}]}]}
{"op":"mcm","clk":"1006582290","pt":1580597947391,"mc":[{"id":"1.168175449","rc":[{"batl":[[0,7,134.03],[1,9,20.22]],"ltp":8.0,"tv":135.53,"id":13117449}]}]}
{"op":"mcm","clk":"1006582365","pt":1580597948474,"mc":[{"id":"1.168175449","rc":[{"batl":[[0,6.8,37.3],[1,8,26.83]],"ltp":8.0,"tv":135.53,"id":13117449},{"batb":[[2,3.85,51.77]],"batl":[[0,5.3,30.14],[1,6.4,41.47]],"ltp":5.8,"tv":93.9,"id":13117392},{"batb":[[0,1.53,73.72],[1,1.52,306.9],[2,1.51,178.48]],"batl":[[1,1.84,43.9]],"ltp":1.72,"tv":1890.71,"id":13117391}]}]}
{"op":"mcm","clk":"1006582428","pt":1580597949558,"mc":[{"id":"1.168175449","rc":[{"batb":[[2,4.5,11.76]],"batl":[[0,5.3,39.38]],"ltp":5.8,"tv":93.9,"id":13117392}]}]}
{"op":"mcm","clk":"1006582524","pt":1580597951105,"mc":[{"id":"1.168175449","rc":[{"batl":[[1,7.2,6.72],[2,8,26.83]],"ltp":8.0,"tv":135.53,"id":13117449}]}]}
{"op":"mcm","clk":"1006583189","pt":1580597962922,"mc":[{"id":"1.168175449","rc":[{"batb":[[1,1.5,84.02],[2,1.41,102.13]],"ltp":1.72,"tv":1890.71,"id":13117391}]}]}
{"op":"mcm","clk":"1006583768","pt":1580597971407,"mc":[{"id":"1.168175449","rc":[{"batb":[[0,5.8,39.89],[1,4.8,31.55],[2,1.01,0.51]],"ltp":8.0,"tv":135.53,"id":13117449},{"batb":[[0,4.7,31.47],[1,4.5,11.76],[2,3.85,51.77]],"ltp":5.8,"tv":93.9,"id":13117392}]}]}
{"op":"mcm","clk":"1006583840","pt":1580597972315,"mc":[{"id":"1.168175449","rc":[{"batb":[[0,4.8,31.55],[1,1.01,0.51],[2,1.01,0]],"batl":[[0,8,26.83],[1,7.2,0],[2,8,0]],"ltp":8.0,"tv":135.53,"id":13117449},{"batb":[[0,3.85,51.77],[1,1.01,0.51],[2,3.85,0]],"batl":[[0,6.4,41.47],[1,6.4,0]],"ltp":5.8,"tv":93.9,"id":13117392},{"batb":[[0,1.41,102.13],[1,1.01,0.51],[2,1.41,0]],"batl":[[0,1.84,43.9],[1,1.84,0]],"ltp":1.72,"tv":1890.71,"id":13117391}]}]}
{"op":"mcm","clk":"1006583942","pt":1580597974431,"mc":[{"id":"1.168175449","rc":[{"batb":[[0,5,66.68],[1,4.8,31.55],[2,1.01,0.51]],"ltp":8.0,"tv":135.53,"id":13117449},{"batb":[[1,3.75,85.48],[2,3.7,64.76]],"ltp":5.8,"tv":93.9,"id":13117392},{"batb":[[0,1.41,339.76],[1,1.4,246.05],[2,1.01,0.51]],"ltp":1.72,"tv":1890.71,"id":13117391}]}]}
{"op":"mcm","clk":"1006583956","pt":1580597974741,"mc":[{"id":"1.168175449","rc":[{"batb":[[0,5,106.12],[1,4.9,68.74],[2,4.8,31.55]],"ltp":8.0,"tv":135.53,"id":13117449}]}]}
{"op":"mcm","clk":"1006584297","pt":1580597980341,"mc":[{"id":"1.168175449","rc":[{"batb":[[0,1.41,102.13],[1,1.01,0.51],[2,1.01,0]],"ltp":1.72,"tv":1890.71,"id":13117391}]}]}
{"op":"mcm","clk":"1006584479","pt":1580597983556,"mc":[{"id":"1.168175449","rc":[{"batl":[[0,5.4,30.14],[1,5.9,8.4],[2,6,8.4]],"ltp":8.0,"tv":135.53,"id":13117449},{"batl":[[0,4.2,12.6],[1,4.3,48.86],[2,5.3,30.29]],"ltp":5.8,"tv":93.9,"id":13117392},{"batb":[[0,1.77,231.35],[1,1.75,205.7],[2,1.72,57.97]],"batl":[[1,2.36,42.33]],"ltp":1.72,"tv":1890.71,"id":13117391}]}]}
{"op":"mcm","clk":"1006584527","pt":1580597984536,"mc":[{"id":"1.168175449","rc":[{"batl":[[2,6.6,38.79]],"ltp":8.0,"tv":135.53,"id":13117449}]}]}
{"op":"mcm","clk":"1006585939","pt":1580598005379,"mc":[{"id":"1.168175449","rc":[{"batb":[[0,3.85,26.99],[1,1.01,0.51],[2,4.8,0]],"batl":[[0,5.9,8.4],[1,6.6,38.79],[2,6.6,0]],"ltp":8.0,"tv":135.53,"id":13117449},{"batb":[[0,3.65,15.12],[1,3,46.26],[2,1.01,0.51]],"batl":[[1,5.3,30.29],[2,5.3,0]],"ltp":5.8,"tv":93.9,"id":13117392},{"batb":[[0,1.72,57.97],[1,1.54,72.23],[2,1.01,0.51]],"batl":[[0,2.36,42.33],[1,2.36,0]],"ltp":1.72,"tv":1890.71,"id":13117391}]}]}
{"op":"mcm","clk":"1006586013","pt":1580598006410,"mc":[{"id":"1.168175449","rc":[{"batl":[[0,6.6,38.79],[1,6.6,0]],"ltp":8.0,"tv":135.53,"id":13117449},{"batb":[[0,3,46.26],[1,1.01,0.51],[2,1.01,0]],"batl":[[0,5.3,30.29],[1,5.3,0]],"ltp":5.8,"tv":93.9,"id":13117392},{"batb":[[0,1.54,72.23],[1,1.01,0.51],[2,1.01,0]],"ltp":1.72,"tv":1890.71,"id":13117391}]}]}
{"op":"mcm","clk":"1006586184","pt":1580598008490,"mc":[{"id":"1.168175449","rc":[{"batb":[[0,3.85,132.62],[1,3.8,62.74],[2,1.01,0.51]],"batl":[[1,6.8,38.32]],"ltp":8.0,"tv":135.53,"id":13117449},{"batb":[[0,3.05,45.79],[1,3,46.26],[2,2.84,106.07]],"ltp":5.8,"tv":93.9,"id":13117392},{"batb":[[1,1.53,297.72],[2,1.52,173.74]],"ltp":1.72,"tv":1890.71,"id":13117391}]}]}
{"op":"mcm","clk":"1006586239","pt":1580598009319,"mc":[{"id":"1.168175449","rc":[{"batb":[[0,3.85,132.3]],"batl":[[0,6.8,38.32],[1,6.8,0]],"ltp":8.0,"tv":135.53,"id":13117449},{"batb":[[1,2.84,106.07],[2,2.8,103.85]],"batl":[[0,5.3,29.9]],"ltp":5.8,"tv":93.9,"id":13117392}]}]}
{"op":"mcm","clk":"1006586995","pt":1580598020446,"mc":[{"id":"1.168175449","rc":[{"batb":[[1,1.01,0.51],[2,1.52,0]],"ltp":1.72,"tv":1890.71,"id":13117391}]}]}
{"op":"mcm","clk":"1006587208","pt":1580598023515,"mc":[{"id":"1.168175449","rc":[{"batl":[[0,4.2,12.6],[1,6.8,38.32]],"ltp":8.0,"tv":135.53,"id":13117449},{"trd":[[2.36,84.66]],"batb":[[0,2.38,67.26],[1,2.36,28.57],[2,2.34,168.67]],"ltp":2.36,"tv":1975.37,"id":13117391}],"tv":2208.91}]}
{"op":"mcm","clk":"1006587269","pt":1580598024445,"mc":[{"id":"1.168175449","rc":[{"batb":[[2,3.55,32.65]],"batl":[[1,4.3,50.44],[2,4.8,38.16]],"ltp":8.0,"tv":135.53,"id":13117449},{"batb":[[1,2.84,128.26]],"batl":[[0,3.3,44.06],[1,3.7,33.52]],"ltp":5.8,"tv":93.9,"id":13117392},{"batb":[[1,2.34,168.67],[2,2.22,43.98]],"batl":[[0,2.66,31]],"ltp":2.36,"tv":1975.37,"id":13117391}]}]}
{"op":"mcm","clk":"1006587389","pt":1580598026320,"mc":[{"id":"1.168175449","rc":[{"trd":[[3.05,40.33]],"batb":[[0,3.05,25.63]],"ltp":3.05,"tv":134.23,"id":13117392},{"batb":[[0,2.38,97.51]],"ltp":2.36,"tv":1975.37,"id":13117391}],"tv":2249.24}]}
{"op":"mcm","clk":"1006587416","pt":1580598026829,"mc":[{"id":"1.168175449","rc":[{"batl":[[0,4.3,50.44],[1,4.8,38.16],[2,4.8,0]],"ltp":8.0,"tv":135.53,"id":13117449}]}]}
{"op":"mcm","clk":"1006587606","pt":1580598030543,"mc":[{"id":"1.168175449","rc":[{"batl":[[0,4.1,13.44],[1,4.3,50.44],[2,4.8,38.16]],"ltp":8.0,"tv":135.53,"id":13117449},{"trd":[[3.05,80.66]],"batb":[[0,3.05,5.46]],"batl":[[0,3.1,19.32],[1,3.3,44.06],[2,3.7,33.52]],"ltp":3.05,"tv":174.56,"id":13117392},{"batl":[[0,2.66,273.25]],"ltp":2.36,"tv":1975.37,"id":13117391}],"tv":2289.57}]}
{"op":"mcm","clk":"1006587653","pt":1580598031526,"mc":[{"id":"1.168175449","rc":[{"batl":[[0,4.3,50.44],[1,4.8,38.16],[2,4.8,0]],"ltp":8.0,"tv":135.53,"id":13117449}]}]}
{"op":"mcm","clk":"1006587695","pt":1580598032456,"mc":[{"id":"1.168175449","rc":[{"batb":[[2,3.5,33.28]],"batl":[[0,4.2,52.24]],"ltp":8.0,"tv":135.53,"id":13117449},{"batb":[[0,3,48],[1,2.84,106.07]],"batl":[[1,3.2,46.19],[2,3.6,35.25]],"ltp":3.05,"tv":174.56,"id":13117392},{"batb":[[2,2.28,41.7]],"batl":[[0,2.4,40.68],[1,2.66,242.25],[2,2.72,29.35]],"ltp":2.36,"tv":1975.37,"id":13117391}]}]}
{"op":"mcm","clk":"1006587768","pt":1580598033540,"mc":[{"id":"1.168175449","rc":[{"batl":[[0,4.2,64.85]],"ltp":8.0,"tv":135.53,"id":13117449}]}]}
{"op":"mcm","clk":"1006587889","pt":1580598035449,"mc":[{"id":"1.168175449","rc":[{"batb":[[2,2.8,126.54]],"ltp":3.05,"tv":174.56,"id":13117392},{"trd":[[2.4,28.57]],"batl":[[0,2.4,26.39],[1,2.72,29.35],[2,2.72,0]],"ltp":2.4,"tv":2003.94,"id":13117391}],"tv":2318.14}]}
{"op":"mcm","clk":"1006588240","pt":1580598040454,"mc":[{"id":"1.168175449","rc":[{"batb":[[0,2.96,49.1]],"batl":[[2,3.55,36.04]],"ltp":3.05,"tv":174.56,"id":13117392},{"batb":[[2,2.3,40.91]],"batl":[[0,2.42,39.97],[1,2.74,28.72]],"ltp":2.4,"tv":2003.94,"id":13117391}]}]}
{"op":"mcm","clk":"1006588752","pt":1580598048171,"mc":[{"id":"1.168175449","rc":[{"batl":[[0,4.2,38.96]],"ltp":8.0,"tv":135.53,"id":13117449},{"batb":[[2,2.3,40.44]],"batl":[[0,2.42,39.5],[1,2.74,28.48]],"ltp":2.4,"tv":2003.94,"id":13117391}]}]}
{"op":"mcm","clk":"1006588784","pt":1580598048849,"mc":[{"id":"1.168175449","rc":[{"batb":[[0,2.38,186.16]],"ltp":2.4,"tv":2003.94,"id":13117391}]}]}
{"op":"mcm","clk":"1006588950","pt":1580598051379,"mc":[{"id":"1.168175449","rc":[{"batb":[[0,2.38,155.91]],"ltp":2.4,"tv":2003.94,"id":13117391}]}]}
{"op":"mcm","clk":"1006589141","pt":1580598054383,"mc":[{"id":"1.168175449","rc":[{"batb":[[1,2.34,199.76]],"ltp":2.4,"tv":2003.94,"id":13117391}]}]}
{"op":"mcm","clk":"1006589297","pt":1580598056362,"mc":[{"id":"1.168175449","rc":[{"batb":[[0,3.85,105.63],[1,3.8,90.04]],"batl":[[1,4.7,39.81]],"ltp":8.0,"tv":135.53,"id":13117449},{"batl":[[1,3.15,47.84]],"ltp":3.05,"tv":174.56,"id":13117392},{"batb":[[2,2.32,40.05]],"batl":[[0,2.44,39.1],[1,2.76,28.17]],"ltp":2.4,"tv":2003.94,"id":13117391}]}]}
{"op":"mcm","clk":"1006589590","pt":1580598061492,"mc":[{"id":"1.168175449","rc":[{"batb":[[1,3.8,62.74]],"batl":[[0,4.2,12.6]],"ltp":8.0,"tv":135.53,"id":13117449},{"batb":[[0,2.84,106.07],[1,2.8,126.54],[2,2.74,24]],"batl":[[1,3.55,36.04],[2,3.55,0]],"ltp":3.05,"tv":174.56,"id":13117392},{"batb":[[2,2.02,59.17]],"batl":[[0,2.76,28.17],[1,2.76,0]],"ltp":2.4,"tv":2003.94,"id":13117391}]}]}
{"op":"mcm","clk":"1006589653","pt":1580598062376,"mc":[{"id":"1.168175449","rc":[{"batl":[[0,4.7,39.81],[1,4.7,0]],"ltp":8.0,"tv":135.53,"id":13117449},{"batb":[[1,2.8,103.85]],"batl":[[0,3.55,36.04],[1,3.55,0]],"ltp":3.05,"tv":174.56,"id":13117392},{"batb":[[1,2.34,168.67]],"ltp":2.4,"tv":2003.94,"id":13117391}]}]}
{"op":"mcm","clk":"1006589884","pt":1580598066187,"mc":[{"id":"1.168175449","rc":[{"batl":[[0,2.72,236.91],[1,2.76,28.17]],"ltp":2.4,"tv":2003.94,"id":13117391}]}]}
{"op":"mcm","clk":"1006590363","pt":1580598073307,"mc":[{"id":"1.168175449","rc":[{"batb":[[0,3.85,82.85]],"ltp":8.0,"tv":135.53,"id":13117449}]}]}
{"op":"mcm","clk":"1006590487","pt":1580598075382,"mc":[{"id":"1.168175449","rc":[{"batb":[[0,2.84,78.61]],"ltp":3.05,"tv":174.56,"id":13117392},{"batb":[[0,2.02,59.17],[1,1.01,0.51],[2,2.02,0]],"ltp":2.4,"tv":2003.94,"id":13117391}]}]}
{"op":"mcm","clk":"1006590564","pt":1580598076410,"mc":[{"id":"1.168175449","rc":[{"batl":[[0,4.6,443.26],[1,4.7,39.81]],"ltp":8.0,"tv":135.53,"id":13117449}]}]}
{"op":"mcm","clk":"1006590632","pt":1580598077394,"mc":[{"id":"1.168175449","rc":[{"batb":[[0,3.8,62.74],[1,3.5,33.28],[2,1.01,0.51]],"ltp":8.0,"tv":135.53,"id":13117449}]}]}
{"op":"mcm","clk":"1006590669","pt":1580598078423,"mc":[{"id":"1.168175449","rc":[{"batl":[[0,3.5,341.41],[1,3.55,36.04]],"ltp":3.05,"tv":174.56,"id":13117392},{"batb":[[0,2.4,91.84],[1,2.36,165.24],[2,2.02,59.17]],"ltp":2.4,"tv":2003.94,"id":13117391}]}]}
{"op":"mcm","clk":"1006590747","pt":1580598079822,"mc":[{"id":"1.168175449","rc":[{"batb":[[0,3.8,113.28],[1,3.75,64.19],[2,3.5,33.28]],"ltp":8.0,"tv":135.53,"id":13117449}]}]}
{"op":"mcm","clk":"1006590954","pt":1580598083213,"mc":[{"id":"1.168175449","rc":[{"batb":[[0,3.8,140.66]],"batl":[[0,4.2,26.59],[1,4.6,443.26],[2,4.7,39.81]],"ltp":8.0,"tv":135.53,"id":13117449},{"batb":[[0,2.94,49.96],[1,2.74,24],[2,1.01,0.51]],"batl":[[0,3.15,48],[1,3.5,341.41],[2,3.55,36.04]],"ltp":3.05,"tv":174.56,"id":13117392},{"batb":[[2,2.32,39.81]],"batl":[[0,2.44,38.87],[1,2.72,236.91],[2,2.76,27.93]],"ltp":2.4,"tv":2003.94,"id":13117391}]}]}
{"op":"mcm","clk":"1006591109","pt":1580598086123,"mc":[{"id":"1.168175449","rc":[{"batb":[[1,2.82,117.15],[2,2.78,105.47]],"batl":[[1,3.55,36.04],[2,3.55,0]],"ltp":3.05,"tv":174.56,"id":13117392},{"batb":[[0,2.4,164.2]],"batl":[[1,2.76,27.93],[2,2.76,0]],"ltp":2.4,"tv":2003.94,"id":13117391}]}]}
{"op":"mcm","clk":"1006591656","pt":1580598096783,"mc":[{"id":"1.168175449","rc":[{"batb":[[0,2.32,39.81],[1,2.02,58.78],[2,1.01,0.51]],"ltp":2.4,"tv":2003.94,"id":13117391}]}]}
{"op":"mcm","clk":"1006591842","pt":1580598100315,"mc":[{"id":"1.168175449","rc":[{"batb":[[0,2.42,84.69],[1,2.38,161.94],[2,2.32,39.81]],"ltp":2.4,"tv":2003.94,"id":13117391}]}]}
{"op":"mcm","clk":"1006592217","pt":1580598107098,"mc":[{"id":"1.168175449","rc":[{"batb":[[0,3.8,115.06]],"batl":[[1,4.7,39.81],[2,4.7,0]],"ltp":8.0,"tv":135.53,"id":13117449}]}]}
{"op":"mcm","clk":"1006593761","pt":1580598132457,"mc":[{"id":"1.168175449","rc":[{"batb":[[0,3.8,27.38],[1,3.5,33.28],[2,1.01,0.51]],"ltp":8.0,"tv":135.53,"id":13117449},{"batb":[[1,2.74,24],[2,1.01,0.51]],"ltp":3.05,"tv":174.56,"id":13117392},{"batb":[[0,2.32,39.81],[1,2.02,58.78],[2,1.01,0.51]],"ltp":2.4,"tv":2003.94,"id":13117391}]}]}
{"op":"mcm","clk":"1006593933","pt":1580598135148,"mc":[{"id":"1.168175449","rc":[{"batb":[[1,3.5,156.08],[2,3.45,78.05]],"ltp":8.0,"tv":135.53,"id":13117449},{"batb":[[2,2.62,136.43]],"ltp":3.05,"tv":174.56,"id":13117392},{"batb":[[1,2.1,103.55],[2,2.08,119.85]],"ltp":2.4,"tv":2003.94,"id":13117391}]}]}
{"op":"mcm","clk":"1006594087","pt":1580598137542,"mc":[{"id":"1.168175449","rc":[{"batb":[[0,3.5,122.8],[1,3.45,78.05],[2,1.01,0.51]],"batl":[[0,4.7,39.81],[1,4.7,0]],"ltp":8.0,"tv":135.53,"id":13117449},{"batb":[[0,2.74,24],[1,2.62,136.43],[2,2.58,128.16]],"batl":[[0,3.55,36.04],[1,3.55,0]],"ltp":3.05,"tv":174.56,"id":13117392},{"batb":[[0,2.02,58.78],[1,1.01,0.51],[2,2.08,0]],"ltp":2.4,"tv":2003.94,"id":13117391}]}]}
{"op":"mcm","clk":"1006594237","pt":1580598140370,"mc":[{"id":"1.168175449","rc":[{"batb":[[1,3.45,113.61],[2,3.2,42.02]],"batl":[[0,3.7,34.38],[1,4.2,26.91],[2,4.7,39.81]],"ltp":8.0,"tv":135.53,"id":13117449},{"batb":[[2,2.58,156.56]],"batl":[[0,2.88,23.84],[1,3.2,47.37],[2,3.55,36.04]],"ltp":3.05,"tv":174.56,"id":13117392},{"batb":[[0,2.72,119.09],[1,2.68,144.9],[2,2.32,39.89]],"batl":[[0,2.82,26.59],[1,3.2,48.39]],"ltp":2.4,"tv":2003.94,"id":13117391}]}]}
{"op":"mcm","clk":"1006594304","pt":1580598141563,"mc":[{"id":"1.168175449","rc":[{"batl":[[1,3.95,13.44],[2,4.2,26.91]],"ltp":8.0,"tv":135.53,"id":13117449},{"batb":[[1,2.64,25.21],[2,2.62,136.43]],"batl":[[1,2.94,21],[2,3.2,47.37]],"ltp":3.05,"tv":174.56,"id":13117392},{"batb":[[2,2.58,26.05]],"ltp":2.4,"tv":2003.94,"id":13117391}]}]}
{"op":"mcm","clk":"1006595126","pt":1580598154474,"mc":[{"id":"1.168175449","rc":[{"batb":[[0,3.45,35.56],[1,3.2,42.02],[2,1.01,0.51]],"ltp":8.0,"tv":135.53,"id":13117449},{"batb":[[2,2.58,28.4]],"ltp":3.05,"tv":174.56,"id":13117392},{"batb":[[0,2.68,27.15],[1,2.58,26.05],[2,2.32,39.89]],"ltp":2.4,"tv":2003.94,"id":13117391}]}]}
{"op":"mcm","clk":"1006595186","pt":1580598155457,"mc":[{"id":"1.168175449","rc":[{"batb":[[0,3.2,42.02],[1,1.01,0.51],[2,1.01,0]],"batl":[[0,4.2,26.91],[1,3.95,0],[2,4.2,0]],"ltp":8.0,"tv":135.53,"id":13117449},{"batb":[[0,2.58,28.4],[1,1.01,0.51],[2,2.58,0]],"batl":[[0,3.2,47.37],[1,2.94,0],[2,3.2,0]],"ltp":3.05,"tv":174.56,"id":13117392},{"batb":[[0,2.32,39.89],[1,1.01,0.51],[2,2.32,0]],"batl":[[0,3.2,48.39],[1,3.2,0]],"ltp":2.4,"tv":2003.94,"id":13117391}]}]}
{"op":"mcm","clk":"1006595307","pt":1580598157498,"mc":[{"id":"1.168175449","rc":[{"batb":[[0,3.3,104.63],[1,3.25,90.42],[2,3.2,42.02]],"batl":[[0,4.1,27.38],[1,4.2,26.91]],"ltp":8.0,"tv":135.53,"id":13117449},{"batb":[[1,2.56,28.8],[2,2.48,143.79]],"batl":[[0,3.15,48.23],[1,3.2,47.37]],"ltp":3.05,"tv":174.56,"id":13117392},{"batb":[[0,2.36,157.41],[1,2.34,38.79],[2,2.32,213.47]],"batl":[[1,3.25,46.97]],"ltp":2.4,"tv":2003.94,"id":13117391}]}]}
{"op":"mcm","clk":"1006595363","pt":1580598158271,"mc":[{"id":"1.168175449","rc":[{"batl":[[1,4.2,0]],"ltp":8.0,"tv":135.53,"id":13117449},{"batb":[[0,2.56,28.8],[1,2.48,143.79],[2,2.44,148.97]],"batl":[[1,3.2,0]],"ltp":3.05,"tv":174.56,"id":13117392},{"batb":[[2,2.32,173.58]],"batl":[[0,3.25,46.97],[1,3.25,0]],"ltp":2.4,"tv":2003.94,"id":13117391}]}]}
{"op":"mcm","clk":"1006597849","pt":1580598191306,"mc":[{"id":"1.168175449","rc":[{"batb":[[0,3.2,42.02],[1,1.01,0.51],[2,3.2,0]],"ltp":8.0,"tv":135.53,"id":13117449},{"batb":[[1,1.01,0.51],[2,2.44,0]],"ltp":3.05,"tv":174.56,"id":13117392}]}]}
{"op":"mcm","clk":"1006598060","pt":1580598194517,"mc":[{"id":"1.168175449","rc":[{"batb":[[0,3.85,109.69],[1,3.8,61.99],[2,3.2,42.02]],"ltp":8.0,"tv":135.53,"id":13117449},{"batb":[[0,2.86,80.37],[1,2.82,101.8],[2,2.56,28.8]],"ltp":3.05,"tv":174.56,"id":13117392},{"batb":[[1,2.32,173.58],[2,1.01,0.51]],"ltp":2.4,"tv":2003.94,"id":13117391}]}]}
{"op":"mcm","clk":"1006598147","pt":1580598195550,"mc":[{"id":"1.168175449","rc":[{"batb":[[2,3.75,28.25]],"batl":[[0,4.3,12.6],[1,4.8,39.66]],"ltp":8.0,"tv":135.53,"id":13117449},{"batb":[[0,2.94,50.2],[1,2.86,80.37],[2,2.82,101.8]],"batl":[[0,3.15,19.32],[1,3.6,35.49]],"ltp":3.05,"tv":174.56,"id":13117392},{"batb":[[1,2.32,204.67],[2,2,60.66]],"batl":[[0,2.46,37.92],[1,2.86,25.49]],"ltp":2.4,"tv":2003.94,"id":13117391}]}]}
{"op":"mcm","clk":"1006598357","pt":1580598198420,"mc":[{"id":"1.168175449","rc":[{"batb":[[0,3.85,91.11],[2,3.4,35.96]],"batl":[[1,4.7,40.29],[2,4.8,39.66]],"ltp":8.0,"tv":135.53,"id":13117449},{"batb":[[0,2.8,22.69],[1,2.7,25.02],[2,1.01,0.51]],"batl":[[1,3.6,35.09]],"ltp":3.05,"tv":174.56,"id":13117392},{"batb":[[0,2.32,31.09],[1,2,60.66],[2,1.01,0.51]],"batl":[[0,2.86,25.49],[1,2.86,0]],"ltp":2.4,"tv":2003.94,"id":13117391}]}]}
{"op":"mcm","clk":"1006598566","pt":1580598201541,"mc":[{"id":"1.168175449","rc":[{"batb":[[0,3.4,35.96],[1,1.01,0.51],[2,3.4,0]],"ltp":8.0,"tv":135.53,"id":13117449}]}]}
{"op":"mcm","clk":"1006598709","pt":1580598203428,"mc":[{"id":"1.168175449","rc":[{"batl":[[0,4.7,40.29],[1,4.8,39.66],[2,4.8,0]],"ltp":8.0,"tv":135.53,"id":13117449},{"batb":[[0,2.7,25.02],[1,1.01,0.51],[2,1.01,0]],"batl":[[0,3.6,35.09],[1,3.6,0]],"ltp":3.05,"tv":174.56,"id":13117392},{"batb":[[0,2,60.66],[1,1.01,0.51],[2,1.01,0]],"ltp":2.4,"tv":2003.94,"id":13117391}]}]}
{"op":"mcm","clk":"1006598904","pt":1580598206262,"mc":[{"id":"1.168175449","rc":[{"batb":[[0,3.95,90.88],[1,3.9,58.3],[2,3.4,35.96]],"ltp":8.0,"tv":135.53,"id":13117449},{"batb":[[0,2.92,78.35],[1,2.88,96.26],[2,2.7,25.02]],"ltp":3.05,"tv":174.56,"id":13117392},{"batb":[[0,2.3,122.51],[1,2.28,92.17],[2,2,60.66]],"ltp":2.4,"tv":2003.94,"id":13117391}]}]}
{"op":"mcm","clk":"1006599303","pt":1580598212039,"mc":[{"id":"1.168175449","rc":[{"batb":[[0,2.7,25.02],[1,1.01,0.51],[2,2.7,0]],"ltp":3.05,"tv":174.56,"id":13117392}]}]}
{"op":"mcm","clk":"1006599411","pt":1580598213546,"mc":[{"id":"1.168175449","rc":[{"batb":[[0,3.4,35.96],[1,1.01,0.51],[2,3.4,0]],"ltp":8.0,"tv":135.53,"id":13117449},{"batb":[[0,2,60.66],[1,1.01,0.51],[2,2,0]],"ltp":2.4,"tv":2003.94,"id":13117391}]}]}
{"op":"mcm","clk":"1006599531","pt":1580598215764,"mc":[{"id":"1.168175449","rc":[{"batb":[[0,3.5,120.65],[1,3.45,77.75],[2,3.4,35.96]],"ltp":8.0,"tv":135.53,"id":13117449},{"batb":[[1,2.6,122.21],[2,2.56,130.57]],"ltp":3.05,"tv":174.56,"id":13117392},{"batb":[[0,2.02,159.76],[1,2,195.62],[2,1.01,0.51]],"ltp":2.4,"tv":2003.94,"id":13117391}]}]}
{"op":"mcm","clk":"1006599626","pt":1580598217269,"mc":[{"id":"1.168175449","rc":[{"batb":[[0,2,60.66],[1,1.01,0.51],[2,1.01,0]],"ltp":2.4,"tv":2003.94,"id":13117391}]}]}
{"op":"mcm","clk":"1006599709","pt":1580598218466,"mc":[{"id":"1.168175449","rc":[{"batb":[[0,2.6,122.21],[1,2.56,130.57],[2,1.01,0.51]],"ltp":3.05,"tv":174.56,"id":13117392}]}]}
{"op":"mcm","clk":"1006599854","pt":1580598220433,"mc":[{"id":"1.168175449","rc":[{"batb":[[0,2.76,85.56],[1,2.72,113.92],[2,2,60.66]],"ltp":2.4,"tv":2003.94,"id":13117391}]}]}
{"op":"mcm","clk":"1006599936","pt":1580598221537,"mc":[{"id":"1.168175449","rc":[{"batl":[[0,3.7,35.25],[1,3.95,13.44],[2,4.1,27.07]],"ltp":8.0,"tv":135.53,"id":13117449},{"batb":[[0,2.68,25.41],[1,2.6,148.26],[2,2.56,130.57]],"batl":[[0,2.84,24.94],[1,2.92,21.85],[2,3.15,47.92]],"ltp":3.05,"tv":174.56,"id":13117392},{"batb":[[1,2.74,25.41],[2,2.72,113.92]],"batl":[[0,2.9,24.94],[1,3.4,42.09]],"ltp":2.4,"tv":2003.94,"id":13117391}]}]}
{"op":"mcm","clk":"1006601541","pt":1580598243404,"mc":[{"id":"1.168175449","rc":[{"batb":[[0,3.15,44.22],[1,1.01,0.51],[2,3.4,0]],"batl":[[0,3.95,13.44],[1,4.1,27.07],[2,4.1,0]],"ltp":8.0,"tv":135.53,"id":13117449},{"batb":[[0,2.6,26.05],[1,2.5,30.84],[2,1.01,0.51]],"batl":[[0,2.92,21.85],[1,3.15,47.92],[2,3.15,0]],"ltp":3.05,"tv":174.56,"id":13117392},{"batb":[[0,2.58,26.05],[1,2.32,39.34],[2,1.01,0.51]],"batl":[[0,3.4,42.09],[1,3.4,0]],"ltp":2.4,"tv":2003.94,"id":13117391}]}]}
{"op":"mcm","clk":"1006601649","pt":1580598244696,"mc":[{"id":"1.168175449","rc":[{"batl":[[0,4.1,27.07],[1,4.1,0]],"ltp":8.0,"tv":135.53,"id":13117449},{"batb":[[0,2.5,30.84],[1,1.01,0.51],[2,1.01,0]],"batl":[[0,3.15,47.92],[1,3.15,0]],"ltp":3.05,"tv":174.56,"id":13117392},{"batb":[[0,2.32,39.34],[1,1.01,0.51],[2,1.01,0]],"ltp":2.4,"tv":2003.94,"id":13117391}]}]}
{"op":"mcm","clk":"1006601896","pt":1580598247432,"mc":[{"id":"1.168175449","rc":[{"batb":[[0,3.1,44.69]],"ltp":8.0,"tv":135.53,"id":13117449},{"batb":[[0,2.5,30.45]],"batl":[[0,3.2,47.6]],"ltp":3.05,"tv":174.56,"id":13117392}]}]}
{"op":"mcm","clk":"1006601966","pt":1580598248105,"mc":[{"id":"1.168175449","rc":[{"batb":[[0,3.6,70.89],[1,3.55,72.93],[2,3.1,44.69]],"ltp":8.0,"tv":135.53,"id":13117449},{"batb":[[0,2.64,134.1],[1,2.6,125.1],[2,2.5,30.45]],"ltp":3.05,"tv":174.56,"id":13117392},{"batb":[[0,2.66,125.53],[1,2.62,125.53],[2,2.32,39.34]],"ltp":2.4,"tv":2003.94,"id":13117391}]}]}
{"op":"mcm","clk":"1006602612","pt":1580598255451,"mc":[{"id":"1.168175449","rc":[{"batb":[[0,3.1,44.69],[1,1.01,0.51],[2,3.1,0]],"ltp":8.0,"tv":135.53,"id":13117449},{"batb":[[0,2.5,30.45],[1,1.01,0.51],[2,2.5,0]],"ltp":3.05,"tv":174.56,"id":13117392},{"batb":[[0,2.32,39.34],[1,1.01,0.51],[2,2.32,0]],"ltp":2.4,"tv":2003.94,"id":13117391}]}]}
{"op":"mcm","clk":"1006602807","pt":1580598257953,"mc":[{"id":"1.168175449","rc":[{"batb":[[0,3.25,138.46],[1,3.2,93.17],[2,3.1,44.69]],"ltp":8.0,"tv":135.53,"id":13117449},{"batb":[[1,2.44,110.63],[2,2.4,155.52]],"ltp":3.05,"tv":174.56,"id":13117392},{"batb":[[0,2.34,141.75],[1,2.32,39.34],[2,2.3,178.51]],"ltp":2.4,"tv":2003.94,"id":13117391}]}]}
{"op":"mcm","clk":"1006603294","pt":1580598263855,"mc":[{"id":"1.168175449","rc":[{"batb":[[0,3.1,44.69],[1,1.01,0.51],[2,3.1,0]],"ltp":8.0,"tv":135.53,"id":13117449},{"batb":[[1,1.01,0.51],[2,2.4,0]],"ltp":3.05,"tv":174.56,"id":13117392}]}]}
{"op":"mcm","clk":"1006603568","pt":1580598267544,"mc":[{"id":"1.168175449","rc":[{"batb":[[0,3.9,101.78],[1,3.85,59.89],[2,3.75,28.17]],"batl":[[1,4.9,36.35]],"ltp":8.0,"tv":135.53,"id":13117449},{"batb":[[0,2.96,49.49],[1,2.86,109.43],[2,2.82,101.23]],"batl":[[1,3.75,31.63]],"ltp":3.05,"tv":174.56,"id":13117392},{"batl":[[0,2.44,38.48],[1,2.98,23.37]],"ltp":2.4,"tv":2003.94,"id":13117391}]}]}
{"op":"mcm","clk":"1006603577","pt":1580598267645,"mc":[{"id":"1.168175449","rc":[{"batl":[[1,4.4,11.76],[2,4.9,36.35]],"ltp":8.0,"tv":135.53,"id":13117449},{"batb":[[2,2.82,123.92]],"batl":[[0,3.2,66.09]],"ltp":3.05,"tv":174.56,"id":13117392}]}]}
{"op":"mcm","clk":"1006605346","pt":1580598291510,"mc":[{"id":"1.168175449","rc":[{"batb":[[0,3.35,37.22],[1,1.01,0.51],[2,3.75,0]],"batl":[[0,4.4,11.76],[1,4.9,36.35],[2,4.9,0]],"ltp":8.0,"tv":135.53,"id":13117449},{"batb":[[0,2.82,22.69],[1,2.64,26.59],[2,1.01,0.51]],"batl":[[0,3.2,18.48]],"ltp":3.05,"tv":174.56,"id":13117392},{"batb":[[0,2.26,32.77],[1,1.92,34.38],[2,1.01,0.51]],"batl":[[0,2.98,23.37],[1,2.98,0]],"ltp":2.4,"tv":2003.94,"id":13117391}]}]}
{"op":"mcm","clk":"1006605478","pt":1580598293183,"mc":[{"id":"1.168175449","rc":[{"batl":[[0,4.9,36.35],[1,4.9,0]],"ltp":8.0,"tv":135.53,"id":13117449},{"batb":[[0,2.64,26.59],[1,1.01,0.51],[2,1.01,0]],"batl":[[0,3.75,31.63],[1,3.75,0]],"ltp":3.05,"tv":174.56,"id":13117392},{"batb":[[0,1.92,34.38],[1,1.01,0.51],[2,1.01,0]],"ltp":2.4,"tv":2003.94,"id":13117391}]}]}
{"op":"mcm","clk":"1006605573","pt":1580598294381,"mc":[{"id":"1.168175449","rc":[{"batb":[[0,3.5,75.14],[1,3.45,78.05],[2,3.35,37.22]],"ltp":8.0,"tv":135.53,"id":13117449},{"batb":[[1,2.56,91.59],[2,2.52,136.31]],"ltp":3.05,"tv":174.56,"id":13117392},{"batb":[[0,1.93,34.23],[1,1.92,34.38],[2,1.9,183.55]],"ltp":2.4,"tv":2003.94,"id":13117391}]}]}
{"op":"mcm","clk":"1006605592","pt":1580598294589,"mc":[{"id":"1.168175449","rc":[{"batb":[[1,1.9,183.55],[2,1.88,163.55]],"batl":[[0,2.98,23.21]],"ltp":2.4,"tv":2003.94,"id":13117391}]}]}
{"op":"mcm","clk":"1006606015","pt":1580598299129,"mc":[{"id":"1.168175449","rc":[{"batb":[[1,1.01,0.51],[2,1.88,0]],"ltp":2.4,"tv":2003.94,"id":13117391}]}]}
{"op":"mcm","clk":"1006606325","pt":1580598302501,"mc":[{"id":"1.168175449","rc":[{"batl":[[0,3.65,36.12],[1,4.2,26.52],[2,4.9,36.35]],"ltp":8.0,"tv":135.53,"id":13117449},{"batl":[[0,2.78,26.2],[1,3.15,47.76],[2,3.75,31.63]],"ltp":3.05,"tv":174.56,"id":13117392},{"batb":[[0,2.84,74.97],[1,2.82,23.68],[2,2.8,105.9]],"batl":[[1,3.65,35.88]],"ltp":2.4,"tv":2003.94,"id":13117391}]}]}
{"op":"mcm","clk":"1006606345","pt":1580598302713,"mc":[{"id":"1.168175449","rc":[{"batl":[[2,4.9,0]],"ltp":8.0,"tv":135.53,"id":13117449},{"batl":[[2,3.75,0]],"ltp":3.05,"tv":174.56,"id":13117392}]}]}
{"op":"mcm","clk":"1006606493","pt":1580598304393,"mc":[{"id":"1.168175449","rc":[{"batl":[[1,3.95,13.44],[2,4.2,26.52]],"ltp":8.0,"tv":135.53,"id":13117449},{"batb":[[1,2.56,118.48]],"batl":[[1,2.86,21.85],[2,3.15,47.76]],"ltp":3.05,"tv":174.56,"id":13117392}]}]}
{"op":"mcm","clk":"1006607324","pt":1580598313423,"mc":[{"id":"1.168175449","rc":[{"batb":[[0,2.82,23.68],[1,2.64,25.21],[2,2.32,40.05]],"ltp":2.4,"tv":2003.94,"id":13117391}]}]}
{"op":"mcm","clk":"1006607507","pt":1580598315448,"mc":[{"id":"1.168175449","rc":[{"batb":[[0,2.82,134.96],[1,2.78,107.52],[2,2.64,25.21]],"ltp":2.4,"tv":2003.94,"id":13117391}]}]}
{"op":"mcm","clk":"1006607749","pt":1580598318519,"mc":[{"id":"1.168175449","rc":[{"batb":[[0,3.35,37.22],[1,3.05,46.82],[2,1.01,0.51]],"ltp":8.0,"tv":135.53,"id":13117449},{"batb":[[1,2.56,26.89],[2,2.42,33.6]],"ltp":3.05,"tv":174.56,"id":13117392},{"batb":[[0,2.82,23.68],[1,2.64,25.21],[2,2.32,40.05]],"ltp":2.4,"tv":2003.94,"id":13117391}]}]}
{"op":"mcm","clk":"1006607789","pt":1580598318936,"mc":[{"id":"1.168175449","rc":[{"batb":[[0,3.05,46.82],[1,1.01,0.51],[2,1.01,0]],"batl":[[0,4.2,26.52],[1,3.95,0],[2,4.2,0]],"ltp":8.0,"tv":135.53,"id":13117449},{"batb":[[0,2.42,33.6],[1,1.01,0.51],[2,2.42,0]],"batl":[[0,3.15,47.76],[1,2.86,0],[2,3.15,0]],"ltp":3.05,"tv":174.56,"id":13117392},{"batb":[[0,2.32,40.05],[1,1.01,0.51],[2,2.32,0]],"batl":[[0,3.65,35.88],[1,3.65,0]],"ltp":2.4,"tv":2003.94,"id":13117391}]}]}
{"op":"mcm","clk":"1006608000","pt":1580598321462,"mc":[{"id":"1.168175449","rc":[{"batb":[[0,3.2,136.05],[1,3.15,97.06],[2,3.05,46.82]],"ltp":8.0,"tv":135.53,"id":13117449},{"batb":[[1,2.36,153.08],[2,2.32,170.9]],"ltp":3.05,"tv":174.56,"id":13117392},{"batb":[[0,2.32,167.36],[1,2.3,90],[2,1.01,0.51]],"ltp":2.4,"tv":2003.94,"id":13117391}]}]}
{"op":"mcm","clk":"1006609047","pt":1580598334169,"mc":[{"id":"1.168175449","rc":[{"batb":[[0,3.05,46.82],[1,1.01,0.51],[2,3.05,0]],"ltp":8.0,"tv":135.53,"id":13117449},{"batb":[[1,1.01,0.51],[2,2.32,0]],"ltp":3.05,"tv":174.56,"id":13117392}]}]}
{"op":"mcm","clk":"1006609354","pt":1580598337450,"mc":[{"id":"1.168175449","rc":[{"batb":[[0,3.95,94.6],[1,3.9,58.19],[2,3.8,27.3]],"batl":[[1,5,35.64]],"ltp":8.0,"tv":135.53,"id":13117449},{"batb":[[0,2.96,49.73],[1,2.88,89.9],[2,2.84,99.6]],"batl":[[1,3.75,31.55]],"ltp":3.05,"tv":174.56,"id":13117392},{"batb":[[2,1.92,34.86]],"batl":[[0,2.44,39.1],[1,2.96,23.76],[2,3.65,35.88]],"ltp":2.4,"tv":2003.94,"id":13117391}]}]}
{"op":"mcm","clk":"1006609395","pt":1580598337964,"mc":[{"id":"1.168175449","rc":[{"batl":[[1,4.4,11.76],[2,5,35.64]],"ltp":8.0,"tv":135.53,"id":13117449},{"batl":[[1,3.2,18.48],[2,3.75,31.55]],"ltp":3.05,"tv":174.56,"id":13117392},{"batb":[[2,2.26,32.77]],"batl":[[2,3.65,0]],"ltp":2.4,"tv":2003.94,"id":13117391}]}]}
{"op":"mcm","clk":"1006611271","pt":1580598363260,"mc":[{"id":"1.168175449","rc":[{"batb":[[0,3.4,36.51],[1,1.01,0.51],[2,3.8,0]],"batl":[[0,5,35.64],[1,4.4,0],[2,5,0]],"ltp":8.0,"tv":135.53,"id":13117449},{"batb":[[0,2.64,26.59],[1,1.01,0.51],[2,2.84,0]],"batl":[[0,3.75,31.55],[1,3.2,0],[2,3.75,0]],"ltp":3.05,"tv":174.56,"id":13117392},{"batb":[[0,1.92,34.86],[1,1.01,0.51],[2,2.26,0]],"batl":[[0,2.96,23.76],[1,2.96,0]],"ltp":2.4,"tv":2003.94,"id":13117391}]}]}
{"op":"mcm","clk":"1006611522","pt":1580598366469,"mc":[{"id":"1.168175449","rc":[{"batb":[[0,3.35,37.14]],"batl":[[0,4.9,36.35]],"ltp":8.0,"tv":135.53,"id":13117449},{"batb":[[0,1.93,34.31]],"batl":[[0,2.98,23.37]],"ltp":2.4,"tv":2003.94,"id":13117391}]}]}
{"op":"mcm","clk":"1006611657","pt":1580598368083,"mc":[{"id":"1.168175449","rc":[{"batb":[[0,4.1,76.21],[1,4,108.59],[2,3.35,37.14]],"ltp":8.0,"tv":135.53,"id":13117449},{"batb":[[0,2.98,83.44],[1,2.94,91.19],[2,2.64,26.59]],"ltp":3.05,"tv":174.56,"id":13117392},{"batb":[[0,2.22,127.94],[1,2.2,102.05],[2,1.93,34.31]],"ltp":2.4,"tv":2003.94,"id":13117391}]}]}
{"op":"mcm","clk":"1006612128","pt":1580598374718,"mc":[{"id":"1.168175449","rc":[{"batb":[[0,3.35,37.14],[1,1.01,0.51],[2,3.35,0]],"ltp":8.0,"tv":135.53,"id":13117449},{"batb":[[0,2.64,26.59],[1,1.01,0.51],[2,2.64,0]],"ltp":3.05,"tv":174.56,"id":13117392},{"batb":[[0,1.93,34.31],[1,1.01,0.51],[2,1.93,0]],"ltp":2.4,"tv":2003.94,"id":13117391}]}]}
{"op":"mcm","clk":"1006612428","pt":1580598378494,"mc":[{"id":"1.168175449","rc":[{"batb":[[0,3.5,126.61],[1,3.45,77.63],[2,3.35,37.14]],"ltp":8.0,"tv":135.53,"id":13117449},{"batb":[[1,2.56,111.39],[2,2.52,136.22]],"ltp":3.05,"tv":174.56,"id":13117392},{"batb":[[1,1.89,151.83],[2,1.87,166.23]],"ltp":2.4,"tv":2003.94,"id":13117391}]}]}
{"op":"mcm","clk":"1006614339","pt":1580598405144,"mc":[{"id":"1.168175449","rc":[{"batb":[[0,3.35,37.14],[1,1.01,0.51],[2,3.35,0]],"ltp":8.0,"tv":135.53,"id":13117449},{"batb":[[1,1.01,0.51],[2,2.52,0]],"ltp":3.05,"tv":174.56,"id":13117392},{"batb":[[1,1.01,0.51],[2,1.87,0]],"ltp":2.4,"tv":2003.94,"id":13117391}]}]}
{"op":"mcm","clk":"1006615717","pt":1580598424511,"mc":[{"id":"1.168175449","rc":[{"batb":[[0,4.4,38.16],[1,3.8,28.01],[2,3.35,37.14]],"batl":[[1,5.2,9.24],[2,6.2,21.79]],"ltp":8.0,"tv":135.53,"id":13117449},{"batb":[[0,3.45,32.81],[1,3.4,16.8],[2,2.96,49.25]],"batl":[[1,3.85,14.28],[2,4.9,35.33]],"ltp":3.05,"tv":174.56,"id":13117392},{"batb":[[1,1.86,48.73],[2,1.6,63.5]],"batl":[[0,2,33.75],[1,2.44,38.79],[2,2.98,23.37]],"ltp":2.4,"tv":2003.94,"id":13117391}]}]}
{"op":"mcm","clk":"1006615738","pt":1580598424714,"mc":[{"id":"1.168175449","rc":[{"batb":[[2,1.01,0.51]],"ltp":8.0,"tv":135.53,"id":13117449},{"batl":[[2,2.98,0]],"ltp":2.4,"tv":2003.94,"id":13117391}]}]}
{"op":"mcm","clk":"1006616404","pt":1580598433428,"mc":[{"id":"1.168175449","rc":[{"batb":[[0,3.8,28.01],[1,1.01,0.51],[2,1.01,0]],"batl":[[0,5.2,9.24],[1,6.2,21.79],[2,6.2,0]],"ltp":8.0,"tv":135.53,"id":13117449},{"batb":[[0,3.4,16.8],[1,2.96,49.25],[2,1.01,0.51]],"batl":[[0,3.85,14.28],[1,4.9,35.33],[2,4.9,0]],"ltp":3.05,"tv":174.56,"id":13117392},{"batb":[[0,1.86,48.73],[1,1.6,63.5],[2,1.01,0.51]],"batl":[[0,2.44,38.79],[1,2.44,0]],"ltp":2.4,"tv":2003.94,"id":13117391}]}]}
{"op":"mcm","clk":"1006616533","pt":1580598435036,"mc":[{"id":"1.168175449","rc":[{"batl":[[0,6.2,21.79],[1,6.2,0]],"ltp":8.0,"tv":135.53,"id":13117449},{"batb":[[0,2.96,49.25],[1,1.01,0.51],[2,1.01,0]],"batl":[[0,4.9,35.33],[1,4.9,0]],"ltp":3.05,"tv":174.56,"id":13117392},{"batb":[[0,1.6,63.5],[1,1.01,0.51],[2,1.01,0]],"ltp":2.4,"tv":2003.94,"id":13117391}]}]}
{"op":"mcm","clk":"1006616662","pt":1580598436548,"mc":[{"id":"1.168175449","rc":[{"batb":[[0,4,74.06],[1,3.95,56.62],[2,3.8,27.54]],"batl":[[0,6.4,21.48]],"ltp":8.0,"tv":135.53,"id":13117449},{"batb":[[1,2.88,103.43],[2,2.84,99.47]],"ltp":3.05,"tv":174.56,"id":13117392},{"batb":[[1,1.53,174.67],[2,1.52,172.78]],"ltp":2.4,"tv":2003.94,"id":13117391}]}]}
{"op":"mcm","clk":"1006617334","pt":1580598444333,"mc":[{"id":"1.168175449","rc":[{"batb":[[1,1.01,0.51],[2,1.52,0]],"ltp":2.4,"tv":2003.94,"id":13117391}]}]}
{"op":"mcm","clk":"1006617578","pt":1580598447552,"mc":[{"id":"1.168175449","rc":[{"batl":[[0,4.2,26.75],[1,5,35.72]],"ltp":8.0,"tv":135.53,"id":13117449},{"batl":[[0,3.2,47.6],[1,3.75,31.63]],"ltp":3.05,"tv":174.56,"id":13117392},{"batb":[[0,2.32,39.89],[1,2.3,153.5],[2,2.28,92.19]],"batl":[[1,2.96,23.76]],"ltp":2.4,"tv":2003.94,"id":13117391}]}]}
{"op":"mcm","clk":"1006617594","pt":1580598447759,"mc":[{"id":"1.168175449","rc":[{"batl":[[1,4.5,11.76],[2,5,35.72]],"ltp":8.0,"tv":135.53,"id":13117449},{"batb":[[2,2.86,21.85]],"batl":[[0,3.2,66.09]],"ltp":3.05,"tv":174.56,"id":13117392}]}]}
{"op":"mcm","clk":"1006618783","pt":1580598462466,"mc":[{"id":"1.168175449","rc":[{"batb":[[0,4,56.09]],"ltp":8.0,"tv":135.53,"id":13117449},{"batb":[[1,2.86,21.85],[2,2.64,26.67]],"ltp":3.05,"tv":174.56,"id":13117392}]}]}
{"op":"mcm","clk":"1006618992","pt":1580598465557,"mc":[{"id":"1.168175449","rc":[{"batb":[[1,2.9,70.64],[2,2.86,119.94]],"ltp":3.05,"tv":174.56,"id":13117392}]}]}
{"op":"mcm","clk":"1006619332","pt":1580598470563,"mc":[{"id":"1.168175449","rc":[{"batb":[[0,3.4,36.35],[1,1.01,0.51],[2,3.8,0]],"batl":[[0,4.5,11.76],[1,5,35.72],[2,5,0]],"ltp":8.0,"tv":135.53,"id":13117449},{"batb":[[0,2.86,21.85],[1,2.64,26.67],[2,1.01,0.51]],"batl":[[0,3.2,18.48]],"ltp":3.05,"tv":174.56,"id":13117392},{"batb":[[0,2.22,33.61],[1,1.92,34.7],[2,1.01,0.51]],"batl":[[0,2.96,23.76],[1,2.96,0]],"ltp":2.4,"tv":2003.94,"id":13117391}]}]}
{"op":"mcm","clk":"1006619422","pt":1580598471557,"mc":[{"id":"1.168175449","rc":[{"batl":[[0,5,35.72],[1,5,0]],"ltp":8.0,"tv":135.53,"id":13117449},{"batb":[[0,2.64,26.67],[1,1.01,0.51],[2,1.01,0]],"batl":[[0,3.75,31.63],[1,3.75,0]],"ltp":3.05,"tv":174.56,"id":13117392},{"batb":[[0,1.92,34.7],[1,1.01,0.51],[2,1.01,0]],"ltp":2.4,"tv":2003.94,"id":13117391}]}]}
{"op":"mcm","clk":"1006619614","pt":1580598473555,"mc":[{"id":"1.168175449","rc":[{"batb":[[0,3.45,35.01]],"batl":[[0,5.1,34.38]],"ltp":8.0,"tv":135.53,"id":13117449},{"batb":[[0,2.62,27.15]],"ltp":3.05,"tv":174.56,"id":13117392},{"batb":[[0,1.91,35.25]],"batl":[[0,2.94,24.16]],"ltp":2.4,"tv":2003.94,"id":13117391}]}]}
{"op":"mcm","clk":"1006619697","pt":1580598474546,"mc":[{"id":"1.168175449","rc":[{"batb":[[0,4.1,90.9],[1,4,107.98],[2,3.45,35.01]],"ltp":8.0,"tv":135.53,"id":13117449},{"batb":[[0,2.98,106.85],[1,2.94,91.11],[2,2.62,27.15]],"ltp":3.05,"tv":174.56,"id":13117392},{"batb":[[0,2.2,181.56],[1,2.18,104.77],[2,1.91,35.25]],"ltp":2.4,"tv":2003.94,"id":13117391}]}]}
{"op":"mcm","clk":"1006620330","pt":1580598481931,"mc":[{"id":"1.168175449","rc":[{"batb":[[0,3.45,35.01],[1,1.01,0.51],[2,3.45,0]],"ltp":8.0,"tv":135.53,"id":13117449},{"batb":[[0,2.62,27.15],[1,1.01,0.51],[2,2.62,0]],"ltp":3.05,"tv":174.56,"id":13117392},{"batb":[[0,1.91,35.25],[1,1.01,0.51],[2,1.91,0]],"ltp":2.4,"tv":2003.94,"id":13117391}]}]}
{"op":"mcm","clk":"1006620633","pt":1580598485364,"mc":[{"id":"1.168175449","rc":[{"batb":[[0,3.55,68.45],[1,3.5,75.3],[2,3.45,35.01]],"ltp":8.0,"tv":135.53,"id":13117449},{"batb":[[1,2.56,134.04],[2,2.52,136.18]],"ltp":3.05,"tv":174.56,"id":13117392},{"batb":[[1,1.88,171.82],[2,1.86,169.22]],"ltp":2.4,"tv":2003.94,"id":13117391}]}]}
{"op":"mcm","clk":"1006620962","pt":1580598489184,"mc":[{"id":"1.168175449","rc":[{"batb":[[1,1.01,0.51],[2,1.86,0]],"ltp":2.4,"tv":2003.94,"id":13117391}]}]}
{"op":"mcm","clk":"1006621213","pt":1580598492370,"mc":[{"id":"1.168175449","rc":[{"batl":[[0,3.75,33.83],[1,4.3,48.94],[2,5.1,34.38]],"ltp":8.0,"tv":135.53,"id":13117449},{"batl":[[0,2.76,26.67],[1,3.15,48],[2,3.75,31.63]],"ltp":3.05,"tv":174.56,"id":13117392},{"batb":[[0,2.78,142.36],[1,2.74,111.73],[2,2.28,41.78]],"batl":[[1,3.6,37.53]],"ltp":2.4,"tv":2003.94,"id":13117391}]}]}
{"op":"mcm","clk":"1006621240","pt":1580598492683,"mc":[{"id":"1.168175449","rc":[{"batl":[[2,5.1,0]],"ltp":8.0,"tv":135.53,"id":13117449},{"batl":[[2,3.75,0]],"ltp":3.05,"tv":174.56,"id":13117392}]}]}
{"op":"mcm","clk":"1006621395","pt":1580598494563,"mc":[{"id":"1.168175449","rc":[{"batl":[[1,4,13.44],[2,4.3,48.94]],"ltp":8.0,"tv":135.53,"id":13117449},{"batb":[[1,2.56,160.93]],"batl":[[1,2.84,22.69],[2,3.15,48]],"ltp":3.05,"tv":174.56,"id":13117392},{"batb":[[2,2.6,26.05]],"ltp":2.4,"tv":2003.94,"id":13117391}]}]}
{"op":"mcm","clk":"1006621904","pt":1580598500956,"mc":[{"id":"1.168175449","rc":[{"batb":[[0,3.5,75.3],[1,3.45,35.01],[2,3.15,43.2]],"ltp":8.0,"tv":135.53,"id":13117449},{"batb":[[1,2.56,26.89],[2,2.4,34.54]],"ltp":3.05,"tv":174.56,"id":13117392},{"batb":[[0,2.78,24.55],[1,2.6,26.05],[2,2.28,41.78]],"ltp":2.4,"tv":2003.94,"id":13117391}]}]}
{"op":"mcm","clk":"1006622247","pt":1580598504569,"mc":[{"id":"1.168175449","rc":[{"batb":[[0,3.5,120.6],[1,3.45,112.29]],"ltp":8.0,"tv":135.53,"id":13117449},{"batb":[[1,2.58,82.07],[2,2.56,26.89]],"ltp":3.05,"tv":174.56,"id":13117392},{"batb":[[0,2.8,75.41],[1,2.78,24.55],[2,2.76,110.02]],"ltp":2.4,"tv":2003.94,"id":13117391}]}]}
{"op":"mcm","clk":"1006622900","pt":1580598512298,"mc":[{"id":"1.168175449","rc":[{"batb":[[0,3.15,43.2],[1,1.01,0.51],[2,3.15,0]],"batl":[[0,4,13.44],[1,4.3,48.94],[2,4.3,0]],"ltp":8.0,"tv":135.53,"id":13117449},{"batb":[[0,2.56,26.89],[1,2.4,34.54],[2,1.01,0.51]],"batl":[[0,2.84,22.69],[1,3.15,48],[2,3.15,0]],"ltp":3.05,"tv":174.56,"id":13117392},{"batb":[[0,2.6,26.05],[1,2.28,41.78],[2,1.01,0.51]],"batl":[[0,3.6,37.53],[1,3.6,0]],"ltp":2.4,"tv":2003.94,"id":13117391}]}]}
{"op":"mcm","clk":"1006622996","pt":1580598513391,"mc":[{"id":"1.168175449","rc":[{"batl":[[0,4.3,48.94],[1,4.3,0]],"ltp":8.0,"tv":135.53,"id":13117449},{"batb":[[0,2.4,34.54],[1,1.01,0.51],[2,1.01,0]],"batl":[[0,3.15,48],[1,3.15,0]],"ltp":3.05,"tv":174.56,"id":13117392},{"batb":[[0,2.28,41.78],[1,1.01,0.51],[2,1.01,0]],"ltp":2.4,"tv":2003.94,"id":13117391}]}]}
{"op":"mcm","clk":"1006623183","pt":1580598515519,"mc":[{"id":"1.168175449","rc":[{"batb":[[0,3.25,75.73],[1,3.2,93.37],[2,3.15,43.2]],"ltp":8.0,"tv":135.53,"id":13117449},{"batb":[[0,2.38,138.75],[1,2.34,167.26],[2,1.01,0.51]],"ltp":3.05,"tv":174.56,"id":13117392},{"batb":[[0,2.3,150.15],[1,2.28,92.43],[2,1.01,0.51]],"batl":[[0,3.65,36.43]],"ltp":2.4,"tv":2003.94,"id":13117391}]}]}
{"op":"mcm","clk":"1006623815","pt":1580598522539,"mc":[{"id":"1.168175449","rc":[{"batb":[[0,2.3,40.6],[1,1.01,0.51],[2,1.01,0]],"ltp":2.4,"tv":2003.94,"id":13117391}]}]}
{"op":"mcm","clk":"1006624074","pt":1580598525474,"mc":[{"id":"1.168175449","rc":[{"batb":[[0,3.3,114.66],[1,3.25,90.56],[2,2.3,40.6]],"ltp":2.4,"tv":2003.94,"id":13117391}]}]}
{"op":"mcm","clk":"1006624162","pt":1580598526461,"mc":[{"id":"1.168175449","rc":[{"batl":[[0,3.4,42.17],[1,3.6,37.14],[2,3.7,15.12]],"ltp":8.0,"tv":135.53,"id":13117449},{"batb":[[0,2.38,169],[2,2.28,40.05]],"batl":[[0,2.5,34.31],[1,2.62,30.76],[2,2.64,25.21]],"ltp":3.05,"tv":174.56,"id":13117392},{"batb":[[0,3.35,37.69],[1,3.3,114.66],[2,3.25,90.56]],"batl":[[1,4.4,48.15]],"ltp":2.4,"tv":2003.94,"id":13117391}]}]}
{"op":"mcm","clk":"1006625484","pt":1580598542075,"mc":[{"id":"1.168175449","rc":[{"trd":[[3.65,5.97]],"batl":[[0,3.65,33.45]],"ltp":3.65,"tv":2009.91,"id":13117391}],"tv":2324.1}]}
{"op":"mcm","clk":"1006625872","pt":1580598547103,"mc":[{"id":"1.168175449","rc":[{"batl":[[1,2.62,33.97]],"ltp":3.05,"tv":174.56,"id":13117392}]}]}
{"op":"mcm","clk":"1006625957","pt":1580598548293,"mc":[{"id":"1.168175449","rc":[{"batl":[[1,2.62,30.76]],"ltp":3.05,"tv":174.56,"id":13117392}]}]}
{"op":"mcm","clk":"1006626111","pt":1580598550392,"mc":[{"id":"1.168175449","rc":[{"trd":[[3.35,2.32]],"batb":[[0,3.35,36.53]],"ltp":3.35,"tv":2012.23,"id":13117391}],"tv":2326.42}]}
{"op":"mcm","clk":"1006626183","pt":1580598551491,"mc":[{"id":"1.168175449","rc":[{"trd":[[3.65,6.04]],"batl":[[0,3.65,33.41]],"ltp":3.65,"tv":2012.3,"id":13117391}],"tv":2326.5}]}
{"op":"mcm","clk":"1006626453","pt":1580598555284,"mc":[{"id":"1.168175449","rc":[{"trd":[[3.65,6.06]],"batl":[[0,3.65,33.4]],"ltp":3.65,"tv":2012.32,"id":13117391}],"tv":2326.52}]}
{"op":"mcm","clk":"1006626546","pt":1580598556488,"mc":[{"id":"1.168175449","rc":[{"trd":[[3.35,32.32]],"batb":[[0,3.35,21.53]],"ltp":3.35,"tv":2042.32,"id":13117391}],"tv":2356.52}]}
{"op":"mcm","clk":"1006627118","pt":1580598563119,"mc":[{"id":"1.168175449","rc":[{"batb":[[0,3.15,43.2],[1,2.94,21.32],[2,1.01,0.51]],"ltp":8.0,"tv":135.53,"id":13117449},{"batb":[[0,2.38,65.34],[1,2.28,40.05],[2,1.01,0.51]],"ltp":3.05,"tv":174.56,"id":13117392},{"batb":[[1,3.05,68.95],[2,1.01,0.51]],"ltp":3.35,"tv":2042.32,"id":13117391}]}]}
{"op":"mcm","clk":"1006627361","pt":1580598566395,"mc":[{"id":"1.168175449","rc":[{"batb":[[0,3,121.07],[1,2.96,90.5],[2,2.94,21.32]],"batl":[[0,3.6,37.14],[1,3.7,15.12],[2,3.7,0]],"ltp":8.0,"tv":135.53,"id":13117449},{"batb":[[0,2.38,30.25],[2,2.26,99.64]],"batl":[[0,2.62,30.76],[1,2.64,25.21],[2,2.64,0]],"ltp":3.05,"tv":174.56,"id":13117392},{"batb":[[0,3.05,68.95],[1,3,162.19],[2,2.96,91.53]],"batl":[[0,4.4,48.15],[1,4.4,0]],"ltp":3.35,"tv":2042.32,"id":13117391}]}]}
{"op":"mcm","clk":"1006627439","pt":1580598567399,"mc":[{"id":"1.168175449","rc":[{"batl":[[1,3.7,0]],"ltp":8.0,"tv":135.53,"id":13117449},{"batb":[[0,2.28,40.05],[1,2.26,99.64],[2,2.24,95.26]],"batl":[[1,2.64,0]],"ltp":3.05,"tv":174.56,"id":13117392},{"batb":[[0,3.05,48.78]],"ltp":3.35,"tv":2042.32,"id":13117391}]}]}
{"op":"mcm","clk":"1006627519","pt":1580598568389,"mc":[{"id":"1.168175449","rc":[{"batb":[[0,2.94,21.32],[1,1.01,0.51],[2,2.94,0]],"ltp":8.0,"tv":135.53,"id":13117449},{"batb":[[1,1.01,0.51],[2,2.24,0]],"ltp":3.05,"tv":174.56,"id":13117392},{"batb":[[1,1.01,0.51],[2,2.96,0]],"ltp":3.35,"tv":2042.32,"id":13117391}]}]}
{"op":"mcm","clk":"1006627610","pt":1580598569532,"mc":[{"id":"1.168175449","rc":[{"batb":[[0,3,50.51]],"batl":[[0,3.7,35.09]],"ltp":8.0,"tv":135.53,"id":13117449},{"batb":[[0,2.26,40.21]],"ltp":3.05,"tv":174.56,"id":13117392},{"batb":[[0,2.98,51.62]],"batl":[[0,4.3,50.99]],"ltp":3.35,"tv":2042.32,"id":13117391}]}]}
{"op":"mcm","clk":"1006627764","pt":1580598571513,"mc":[{"id":"1.168175449","rc":[{"batb":[[0,3.2,73.83],[1,3.15,96.91],[2,3,50.51]],"ltp":8.0,"tv":135.53,"id":13117449},{"batb":[[0,2.34,159.57],[1,2.3,174.93],[2,2.26,40.21]],"ltp":3.05,"tv":174.56,"id":13117392},{"batb":[[0,3.4,130.43],[1,3.35,84.05],[2,2.98,51.62]],"ltp":3.35,"tv":2042.32,"id":13117391}]}]}
{"op":"mcm","clk":"1006628032","pt":1580598574909,"mc":[{"id":"1.168175449","rc":[{"batb":[[0,3,50.51],[1,1.01,0.51],[2,3,0]],"ltp":8.0,"tv":135.53,"id":13117449},{"batb":[[0,2.26,40.21],[1,1.01,0.51],[2,2.26,0]],"ltp":3.05,"tv":174.56,"id":13117392},{"batb":[[0,2.98,51.62],[1,1.01,0.51],[2,2.98,0]],"ltp":3.35,"tv":2042.32,"id":13117391}]}]}
{"op":"mcm","clk":"1006628292","pt":1580598578139,"mc":[{"id":"1.168175449","rc":[{"batb":[[0,3,185.06],[1,2.96,90.51],[2,1.01,0.51]],"ltp":8.0,"tv":135.53,"id":13117449},{"batb":[[1,2.24,185.57],[2,2.22,97.52]],"ltp":3.05,"tv":174.56,"id":13117392},{"batb":[[0,3,156.66],[1,2.98,51.62],[2,2.96,91.53]],"ltp":3.35,"tv":2042.32,"id":13117391}]}]}
{"op":"mcm","clk":"1006628666","pt":1580598582552,"mc":[{"id":"1.168175449","rc":[{"batb":[[0,3,50.51],[1,1.01,0.51],[2,1.01,0]],"ltp":8.0,"tv":135.53,"id":13117449},{"batb":[[1,1.01,0.51],[2,2.22,0]],"ltp":3.05,"tv":174.56,"id":13117392}]}]}
{"op":"mcm","clk":"1006628880","pt":1580598585538,"mc":[{"id":"1.168175449","rc":[{"batb":[[0,3.4,102.62],[1,3.35,83.19],[2,3,50.51]],"ltp":8.0,"tv":135.53,"id":13117449},{"batb":[[0,2.46,94.82],[1,2.42,152.24],[2,2.26,40.21]],"ltp":3.05,"tv":174.56,"id":13117392}]}]}
{"op":"mcm","clk":"1006628942","pt":1580598586420,"mc":[{"id":"1.168175449","rc":[{"batb":[[0,3.4,138.97],[2,3.15,43.35]],"batl":[[1,3.8,14.28],[2,3.9,30.69]],"ltp":8.0,"tv":135.53,"id":13117449},{"batb":[[0,2.48,31.39],[1,2.46,94.82],[2,2.44,28.57]],"batl":[[1,2.7,52.46]],"ltp":3.05,"tv":174.56,"id":13117392},{"batl":[[0,3.2,49.57],[1,3.65,36.04]],"ltp":3.35,"tv":2042.32,"id":13117391}]}]}
{"op":"mcm","clk":"1006629887","pt":1580598598273,"mc":[{"id":"1.168175449","rc":[{"batb":[[0,3.15,43.35],[1,1.01,0.51],[2,3.15,0]],"batl":[[0,3.8,14.28],[1,3.9,30.69],[2,3.9,0]],"ltp":8.0,"tv":135.53,"id":13117449},{"batb":[[0,2.44,28.57],[1,2.36,35.64],[2,1.01,0.51]],"batl":[[0,2.7,52.46],[1,2.7,0]],"ltp":3.05,"tv":174.56,"id":13117392},{"batb":[[0,2.86,21.85],[1,2.74,25.26],[2,1.01,0.51]],"batl":[[0,3.65,36.04],[1,3.65,0]],"ltp":3.35,"tv":2042.32,"id":13117391}]}]}
{"op":"mcm","clk":"1006629981","pt":1580598599396,"mc":[{"id":"1.168175449","rc":[{"batl":[[0,3.9,30.69],[1,3.9,0]],"ltp":8.0,"tv":135.53,"id":13117449},{"batb":[[0,2.36,35.64],[1,1.01,0.51],[2,1.01,0]],"batl":[[0,2.7,28.09]],"ltp":3.05,"tv":174.56,"id":13117392},{"batb":[[0,2.74,25.26],[1,1.01,0.51],[2,1.01,0]],"ltp":3.35,"tv":2042.32,"id":13117391}]}]}
{"op":"mcm","clk":"1006630170","pt":1580598601464,"mc":[{"id":"1.168175449","rc":[{"batb":[[0,3.25,128.44],[1,3.2,77.21],[2,3.15,43.35]],"ltp":8.0,"tv":135.53,"id":13117449},{"batb":[[1,2.32,171.06],[2,2.28,178.78]],"ltp":3.05,"tv":174.56,"id":13117392},{"batb":[[0,2.8,110.16],[1,2.76,109.25],[2,2.74,25.26]],"ltp":3.35,"tv":2042.32,"id":13117391}]}]}
{"op":"mcm","clk":"1006630407","pt":1580598604379,"mc":[{"id":"1.168175449","rc":[{"batb":[[0,3.15,43.35],[1,1.01,0.51],[2,3.15,0]],"ltp":8.0,"tv":135.53,"id":13117449},{"batb":[[1,1.01,0.51],[2,2.28,0]],"ltp":3.05,"tv":174.56,"id":13117392}]}]}
{"op":"mcm","clk":"1006630641","pt":1580598607555,"mc":[{"id":"1.168175449","rc":[{"batb":[[0,3.65,82.85],[1,3.6,71.18],[2,3.15,43.35]],"ltp":8.0,"tv":135.53,"id":13117449},{"batb":[[0,2.5,107.75],[1,2.46,144.92],[2,2.36,35.64]],"ltp":3.05,"tv":174.56,"id":13117392}]}]}
{"op":"mcm","clk":"1006630730","pt":1580598608491,"mc":[{"id":"1.168175449","rc":[{"batb":[[0,3.65,113.14],[2,3.45,35.41]],"batl":[[0,3.9,14.28],[1,4,29.43],[2,4.2,52.17]],"ltp":8.0,"tv":135.53,"id":13117449},{"batb":[[0,2.56,29.19],[1,2.5,107.75],[2,2.48,59.36]],"batl":[[0,2.68,28.56],[1,2.74,27.07],[2,2.76,23.53]],"ltp":3.05,"tv":174.56,"id":13117392},{"batb":[[2,2.74,48.78]],"batl":[[0,2.88,25.18],[1,3.2,50.2]],"ltp":3.35,"tv":2042.32,"id":13117391}]}]}
{"op":"mcm","clk":"1006631518","pt":1580598618548,"mc":[{"id":"1.168175449","rc":[{"batb":[[0,3.65,30.29]],"ltp":8.0,"tv":135.53,"id":13117449},{"batb":[[0,2.74,48.78],[1,2.58,29.82],[2,1.01,0.51]],"ltp":3.35,"tv":2042.32,"id":13117391}]}]}
{"op":"mcm","clk":"1006631564","pt":1580598619130,"mc":[{"id":"1.168175449","rc":[{"batb":[[0,3.45,35.41],[1,1.01,0.51],[2,3.45,0]],"batl":[[0,4.2,52.17],[1,4,0],[2,4.2,0]],"ltp":8.0,"tv":135.53,"id":13117449},{"batb":[[0,2.48,31.63],[1,1.01,0.51],[2,2.48,0]],"batl":[[0,2.74,27.07],[1,2.74,0],[2,2.76,0]],"ltp":3.05,"tv":174.56,"id":13117392},{"batb":[[0,2.58,29.82],[1,1.01,0.51],[2,1.01,0]],"batl":[[0,3.2,50.2],[1,3.2,0]],"ltp":3.35,"tv":2042.32,"id":13117391}]}]}
{"op":"mcm","clk":"1006631758","pt":1580598621534,"mc":[{"id":"1.168175449","rc":[{"batb":[[0,3.55,72.97],[1,3.45,35.41],[2,1.01,0.51]],"ltp":8.0,"tv":135.53,"id":13117449},{"batb":[[0,2.5,34.18],[1,2.48,31.63],[2,1.01,0.51]],"ltp":3.05,"tv":174.56,"id":13117392},{"batb":[[0,2.82,81.71],[1,2.58,29.82],[2,1.01,0.51]],"ltp":3.35,"tv":2042.32,"id":13117391}]}]}
{"op":"mcm","clk":"1006631858","pt":1580598622466,"mc":[{"id":"1.168175449","rc":[{"batb":[[1,3.4,36.51]],"batl":[[0,4.1,27.15]],"ltp":8.0,"tv":135.53,"id":13117449},{"trd":[[2.5,4.24]],"batb":[[0,2.5,32.06],[1,2.48,31.24]],"batl":[[0,2.76,26.59]],"ltp":2.5,"tv":178.8,"id":13117392},{"batb":[[1,2.6,29.35]],"batl":[[0,3.2,49.57]],"ltp":3.35,"tv":2042.32,"id":13117391}],"tv":2360.76}]}
{"op":"mcm","clk":"1006631944","pt":1580598623346,"mc":[{"id":"1.168175449","rc":[{"batb":[[0,3.55,121.23],[1,3.5,75.35],[2,3.4,36.51]],"ltp":8.0,"tv":135.53,"id":13117449},{"batb":[[0,2.5,93.35],[2,2.46,145.26]],"ltp":2.5,"tv":178.8,"id":13117392},{"batb":[[0,2.86,82.93],[1,2.82,81.71],[2,2.6,29.35]],"ltp":3.35,"tv":2042.32,"id":13117391}]}]}
{"op":"mcm","clk":"1006632268","pt":1580598627546,"mc":[{"id":"1.168175449","rc":[{"batb":[[0,3.4,36.51],[1,1.01,0.51],[2,3.4,0]],"ltp":8.0,"tv":135.53,"id":13117449},{"batb":[[0,2.48,31.24],[1,1.01,0.51],[2,2.46,0]],"ltp":2.5,"tv":178.8,"id":13117392},{"batb":[[0,2.6,29.35],[1,1.01,0.51],[2,2.6,0]],"ltp":3.35,"tv":2042.32,"id":13117391}]}]}
{"op":"mcm","clk":"1006632487","pt":1580598630554,"mc":[{"id":"1.168175449","rc":[{"batb":[[0,3.4,171.15],[1,3.35,83.69],[2,1.01,0.51]],"ltp":8.0,"tv":135.53,"id":13117449},{"batb":[[1,2.44,130.04],[2,2.4,155.22]],"ltp":2.5,"tv":178.8,"id":13117392},{"batb":[[0,2.7,92.59],[1,2.66,120.59],[2,2.6,29.35]],"ltp":3.35,"tv":2042.32,"id":13117391}]}]}
{"op":"mcm","clk":"1006632637","pt":1580598632431,"mc":[{"id":"1.168175449","rc":[{"batb":[[0,2.6,29.35],[1,1.01,0.51],[2,2.6,0]],"ltp":3.35,"tv":2042.32,"id":13117391}]}]}
{"op":"mcm","clk":"1006632862","pt":1580598635441,"mc":[{"id":"1.168175449","rc":[{"batb":[[0,3,160.26],[1,2.96,91.22],[2,2.6,29.35]],"ltp":3.35,"tv":2042.32,"id":13117391}]}]}
{"op":"mcm","clk":"1006632960","pt":1580598636428,"mc":[{"id":"1.168175449","rc":[{"batb":[[2,3.1,44.93]],"batl":[[0,3.7,35.25],[1,3.8,14.28],[2,3.9,30.45]],"ltp":8.0,"tv":135.53,"id":13117449},{"batb":[[1,2.44,158.61]],"batl":[[0,2.62,30.61],[1,2.7,24.37],[2,2.74,27.46]],"ltp":2.5,"tv":178.8,"id":13117392},{"batb":[[1,2.98,51.62],[2,2.96,91.22]],"batl":[[1,3.7,34.38]],"ltp":3.35,"tv":2042.32,"id":13117391}]}]}
{"op":"mcm","clk":"1006633991","pt":1580598649472,"mc":[{"id":"1.168175449","rc":[{"batb":[[0,3.4,36.51],[1,3.1,44.93],[2,1.01,0.51]],"ltp":8.0,"tv":135.53,"id":13117449},{"batb":[[1,2.44,28.57],[2,2.36,35.96]],"ltp":2.5,"tv":178.8,"id":13117392},{"batb":[[0,2.98,51.62],[1,2.86,21.85],[2,2.72,25.97]],"ltp":3.35,"tv":2042.32,"id":13117391}]}]}
{"op":"mcm","clk":"1006634027","pt":1580598649947,"mc":[{"id":"1.168175449","rc":[{"batb":[[0,3.1,44.93],[1,1.01,0.51],[2,1.01,0]],"batl":[[0,3.8,14.28],[1,3.9,30.45],[2,3.9,0]],"ltp":8.0,"tv":135.53,"id":13117449},{"batb":[[0,2.44,28.57],[1,2.36,35.96],[2,1.01,0.51]],"batl":[[0,2.7,24.37],[1,2.74,27.46],[2,2.74,0]],"ltp":2.5,"tv":178.8,"id":13117392},{"batb":[[0,2.86,21.85],[1,2.72,25.97],[2,1.01,0.51]],"batl":[[0,3.7,34.38],[1,3.7,0]],"ltp":3.35,"tv":2042.32,"id":13117391}]}]}
{"op":"mcm","clk":"1006634119","pt":1580598651323,"mc":[{"id":"1.168175449","rc":[{"batl":[[0,3.9,30.45],[1,3.9,0]],"ltp":8.0,"tv":135.53,"id":13117449},{"batb":[[0,2.36,35.96],[1,1.01,0.51],[2,1.01,0]],"batl":[[0,2.74,27.46],[1,2.74,0]],"ltp":2.5,"tv":178.8,"id":13117392},{"batb":[[0,2.72,25.97],[1,1.01,0.51],[2,1.01,0]],"ltp":3.35,"tv":2042.32,"id":13117391}]}]}
{"op":"mcm","clk":"1006634386","pt":1580598654448,"mc":[{"id":"1.168175449","rc":[{"batb":[[0,3.35,134.14],[1,3.3,86.83],[2,3.1,44.93]],"ltp":8.0,"tv":135.53,"id":13117449},{"batb":[[0,2.42,108.56],[1,2.38,158.99],[2,2.36,35.96]],"ltp":2.5,"tv":178.8,"id":13117392},{"batb":[[0,3.1,119.38],[1,3.05,105.72],[2,2.72,25.97]],"ltp":3.35,"tv":2042.32,"id":13117391}]}]}
{"op":"mcm","clk":"1006634605","pt":1580598657426,"mc":[{"id":"1.168175449","rc":[{"batb":[[0,3.1,44.93],[1,1.01,0.51],[2,3.1,0]],"ltp":8.0,"tv":135.53,"id":13117449},{"batb":[[0,2.36,35.96],[1,1.01,0.51],[2,2.36,0]],"ltp":2.5,"tv":178.8,"id":13117392},{"batb":[[0,2.72,25.97],[1,1.01,0.51],[2,2.72,0]],"ltp":3.35,"tv":2042.32,"id":13117391}]}]}
{"op":"mcm","clk":"1006634850","pt":1580598660542,"mc":[{"id":"1.168175449","rc":[{"batb":[[0,3.15,159.73],[1,3.1,146.02],[2,1.01,0.51]],"ltp":8.0,"tv":135.53,"id":13117449},{"batb":[[1,2.32,120.83],[2,2.28,179.22]],"ltp":2.5,"tv":178.8,"id":13117392},{"batb":[[0,2.8,85.23],[1,2.76,109.64],[2,2.72,25.97]],"ltp":3.35,"tv":2042.32,"id":13117391}]}]}
{"op":"mcm","clk":"1006634882","pt":1580598660958,"mc":[{"id":"1.168175449","rc":[{"batb":[[0,2.72,25.97],[1,1.01,0.51],[2,2.72,0]],"ltp":3.35,"tv":2042.32,"id":13117391}]}]}
{"op":"mcm","clk":"1006635170","pt":1580598664449,"mc":[{"id":"1.168175449","rc":[{"batb":[[2,2.86,22.9]],"batl":[[0,3.4,43.28],[1,3.7,34.93],[2,3.9,30.45]],"ltp":8.0,"tv":135.53,"id":13117449},{"batl":[[0,2.48,35.17],[1,2.64,29.74],[2,2.74,27.46]],"ltp":2.5,"tv":178.8,"id":13117392},{"batb":[[0,3.5,85.33],[1,3.45,113.88],[2,2.94,21.24]],"batl":[[1,5.1,34.46]],"ltp":3.35,"tv":2042.32,"id":13117391}]}]}
{"op":"mcm","clk":"1006635232","pt":1580598665221,"mc":[{"id":"1.168175449","rc":[{"batl":[[2,3.9,0]],"ltp":8.0,"tv":135.53,"id":13117449},{"batl":[[2,2.74,0]],"ltp":2.5,"tv":178.8,"id":13117392}]}]}
{"op":"mcm","clk":"1006635356","pt":1580598666490,"mc":[{"id":"1.168175449","rc":[{"batl":[[1,3.55,15.96],[2,3.7,34.93]],"ltp":8.0,"tv":135.53,"id":13117449},{"batb":[[1,2.32,151.92]],"batl":[[1,2.58,26.05],[2,2.64,29.74]],"ltp":2.5,"tv":178.8,"id":13117392},{"batb":[[2,3.2,18.48]],"ltp":3.35,"tv":2042.32,"id":13117391}]}]}
{"op":"mcm","clk":"1006635790","pt":1580598672454,"mc":[{"id":"1.168175449","rc":[{"batb":[[0,3.15,98],[1,3.1,44.93]],"ltp":8.0,"tv":135.53,"id":13117449}]}]}
{"op":"mcm","clk":"1006636003","pt":1580598675388,"mc":[{"id":"1.168175449","rc":[{"batb":[[0,3.2,65.39],[1,3.15,98],[2,3.1,44.93]],"ltp":8.0,"tv":135.53,"id":13117449}]}]}
{"op":"mcm","clk":"1006636881","pt":1580598686488,"mc":[{"id":"1.168175449","rc":[{"batb":[[0,2.86,22.9],[1,1.01,0.51],[2,3.1,0]],"batl":[[0,3.55,15.96],[1,3.7,34.93],[2,3.7,0]],"ltp":8.0,"tv":135.53,"id":13117449},{"batb":[[0,2.32,31.09],[1,2.16,46.11],[2,1.01,0.51]],"batl":[[0,2.58,26.05],[1,2.64,29.74],[2,2.64,0]],"ltp":2.5,"tv":178.8,"id":13117392},{"batb":[[0,3.2,18.48],[1,2.94,21.24],[2,1.01,0.51]],"batl":[[0,5.1,34.46],[1,5.1,0]],"ltp":3.35,"tv":2042.32,"id":13117391}]}]}
{"op":"mcm","clk":"1006636915","pt":1580598686909,"mc":[{"id":"1.168175449","rc":[{"batl":[[0,3.7,34.93],[1,3.7,0]],"ltp":8.0,"tv":135.53,"id":13117449},{"batb":[[0,2.16,46.11],[1,1.01,0.51],[2,1.01,0]],"batl":[[0,2.64,29.74],[1,2.64,0]],"ltp":2.5,"tv":178.8,"id":13117392},{"batb":[[0,2.94,21.24],[1,1.01,0.51],[2,1.01,0]],"ltp":3.35,"tv":2042.32,"id":13117391}]}]}
{"op":"mcm","clk":"1006637093","pt":1580598689335,"mc":[{"id":"1.168175449","rc":[{"batb":[[0,2.88,74.84],[1,2.86,22.9],[2,2.84,101.78]],"ltp":8.0,"tv":135.53,"id":13117449},{"batb":[[1,2.12,149.96],[2,2.1,114.78]],"ltp":2.5,"tv":178.8,"id":13117392},{"batb":[[0,2.98,110.63],[1,2.94,93.05],[2,2.92,21.48]],"batl":[[0,5.1,34.31]],"ltp":3.35,"tv":2042.32,"id":13117391}]}]}
{"op":"mcm","clk":"1006637152","pt":1580598690111,"mc":[{"id":"1.168175449","rc":[{"batb":[[0,2.86,22.9],[1,1.01,0.51],[2,2.84,0]],"ltp":8.0,"tv":135.53,"id":13117449},{"batb":[[1,1.01,0.51],[2,2.1,0]],"ltp":2.5,"tv":178.8,"id":13117392},{"batb":[[0,2.92,21.48],[1,1.01,0.51],[2,2.92,0]],"ltp":3.35,"tv":2042.32,"id":13117391}]}]}
{"op":"mcm","clk":"1006637386","pt":1580598693529,"mc":[{"id":"1.168175449","rc":[{"batb":[[0,3.1,102.3],[1,2.86,22.9],[2,1.01,0.51]],"ltp":8.0,"tv":135.53,"id":13117449},{"batb":[[0,2.26,92.76],[1,2.16,46.11],[2,1.01,0.51]],"ltp":2.5,"tv":178.8,"id":13117392},{"batb":[[0,3.65,68.47],[1,2.92,21.48],[2,1.01,0.51]],"ltp":3.35,"tv":2042.32,"id":13117391}]}]}
{"op":"mcm","clk":"1006637449","pt":1580598694520,"mc":[{"id":"1.168175449","rc":[{"batb":[[0,2.86,22.9],[1,1.01,0.51],[2,1.01,0]],"ltp":8.0,"tv":135.53,"id":13117449},{"batb":[[0,2.16,46.11],[1,1.01,0.51],[2,1.01,0]],"ltp":2.5,"tv":178.8,"id":13117392},{"batb":[[0,2.92,21.48],[1,1.01,0.51],[2,1.01,0]],"ltp":3.35,"tv":2042.32,"id":13117391}]}]}
{"op":"mcm","clk":"1006637650","pt":1580598697420,"mc":[{"id":"1.168175449","rc":[{"batb":[[0,2.92,78.6],[1,2.88,98.95],[2,2.86,22.9]],"ltp":8.0,"tv":135.53,"id":13117449},{"batb":[[1,2.1,178.42],[2,2.08,117.96]],"ltp":2.5,"tv":178.8,"id":13117392},{"batb":[[0,2.98,70.46],[1,2.94,92.96],[2,2.92,21.48]],"ltp":3.35,"tv":2042.32,"id":13117391}]}]}
{"op":"mcm","clk":"1006637731","pt":1580598698522,"mc":[{"id":"1.168175449","rc":[{"batb":[[0,2.86,22.9],[1,1.01,0.51],[2,2.86,0]],"ltp":8.0,"tv":135.53,"id":13117449},{"batb":[[1,2.1,139.3]],"ltp":2.5,"tv":178.8,"id":13117392},{"batb":[[0,2.92,21.48],[1,1.01,0.51],[2,2.92,0]],"ltp":3.35,"tv":2042.32,"id":13117391}]}]}
{"op":"mcm","clk":"1006637806","pt":1580598699619,"mc":[{"id":"1.168175449","rc":[{"batb":[[0,2.94,75.87],[1,2.9,97.58],[2,2.86,22.9]],"ltp":8.0,"tv":135.53,"id":13117449},{"batb":[[0,2.96,99.05],[1,2.92,115.69],[2,1.01,0.51]],"ltp":3.35,"tv":2042.32,"id":13117391}]}]}
{"op":"mcm","clk":"1006638122","pt":1580598703537,"mc":[{"id":"1.168175449","rc":[{"batb":[[0,2.86,22.9],[1,1.01,0.51],[2,2.86,0]],"ltp":8.0,"tv":135.53,"id":13117449},{"batb":[[1,1.01,0.51],[2,2.08,0]],"ltp":2.5,"tv":178.8,"id":13117392}]}]}
{"op":"mcm","clk":"1006638487","pt":1580598706533,"mc":[{"id":"1.168175449","rc":[{"batb":[[0,3.5,100.17],[1,3.45,79.27],[2,2.86,22.9]],"ltp":8.0,"tv":135.53,"id":13117449},{"batb":[[0,2.44,150.28],[1,2.4,154.43],[2,2.16,46.11]],"ltp":2.5,"tv":178.8,"id":13117392}]}]}
{"op":"mcm","clk":"1006638540","pt":1580598707152,"mc":[{"id":"1.168175449","rc":[{"batb":[[2,3.4,36.19]],"batl":[[1,3.9,30.29]],"ltp":8.0,"tv":135.53,"id":13117449},{"batb":[[0,2.52,30.37],[1,2.44,150.28],[2,2.4,154.43]],"batl":[[1,2.8,25.97]],"ltp":2.5,"tv":178.8,"id":13117392},{"batb":[[2,2.66,27.62]],"batl":[[0,3.15,51.46],[1,3.75,33.44]],"ltp":3.35,"tv":2042.32,"id":13117391}]}]}
{"op":"mcm","clk":"1006638656","pt":1580598708355,"mc":[{"id":"1.168175449","rc":[{"batl":[[1,3.75,15.12],[2,3.9,30.29]],"ltp":8.0,"tv":135.53,"id":13117449},{"batb":[[1,2.46,28.57],[2,2.44,150.28]],"batl":[[1,2.72,24.37],[2,2.8,25.97]],"ltp":2.5,"tv":178.8,"id":13117392},{"batb":[[2,2.86,21.85]],"ltp":3.35,"tv":2042.32,"id":13117391}]}]}
{"op":"mcm","clk":"1006639445","pt":1580598718420,"mc":[{"id":"1.168175449","rc":[{"batb":[[0,3.1,45.56],[1,1.01,0.51],[2,3.4,0]],"batl":[[0,3.75,15.12],[1,3.9,30.29],[2,3.9,0]],"ltp":8.0,"tv":135.53,"id":13117449},{"batb":[[0,2.46,28.57],[1,2.36,36.27],[2,1.01,0.51]],"batl":[[0,2.72,24.37],[1,2.8,25.97],[2,2.8,0]],"ltp":2.5,"tv":178.8,"id":13117392},{"batb":[[0,2.86,21.85],[1,2.66,27.62],[2,1.01,0.51]],"batl":[[0,3.75,33.44],[1,3.75,0]],"ltp":3.35,"tv":2042.32,"id":13117391}]}]}
{"op":"mcm","clk":"1006639506","pt":1580598719255,"mc":[{"id":"1.168175449","rc":[{"batl":[[0,3.9,30.29],[1,3.9,0]],"ltp":8.0,"tv":135.53,"id":13117449},{"batb":[[0,2.36,36.27],[1,1.01,0.51],[2,1.01,0]],"batl":[[0,2.8,25.97],[1,2.8,0]],"ltp":2.5,"tv":178.8,"id":13117392},{"batb":[[0,2.66,27.62],[1,1.01,0.51],[2,1.01,0]],"ltp":3.35,"tv":2042.32,"id":13117391}]}]}
{"op":"mcm","clk":"1006639669","pt":1580598721467,"mc":[{"id":"1.168175449","rc":[{"batb":[[0,3.2,146.74],[1,3.15,98.5],[2,3.1,45.56]],"ltp":8.0,"tv":135.53,"id":13117449},{"batb":[[1,2.3,125.33],[2,2.28,90.14]],"ltp":2.5,"tv":178.8,"id":13117392},{"batb":[[0,2.7,116.07],[1,2.66,147.32],[2,1.01,0.51]],"ltp":3.35,"tv":2042.32,"id":13117391}]}]}
{"op":"mcm","clk":"1006639917","pt":1580598724465,"mc":[{"id":"1.168175449","rc":[{"batb":[[0,3.1,45.56],[1,1.01,0.51],[2,3.1,0]],"ltp":8.0,"tv":135.53,"id":13117449},{"batb":[[1,1.01,0.51],[2,2.28,0]],"ltp":2.5,"tv":178.8,"id":13117392}]}]}
{"op":"mcm","clk":"1006640174","pt":1580598727403,"mc":[{"id":"1.168175449","rc":[{"batb":[[0,3.7,98.51],[1,3.65,69.29],[2,3.6,31.32]],"batl":[[1,4.5,44.46]],"ltp":8.0,"tv":135.53,"id":13117449},{"batb":[[0,2.64,26.44],[1,2.56,86.98],[2,2.52,135.45]],"batl":[[1,3.15,48.31]],"ltp":2.5,"tv":178.8,"id":13117392},{"batb":[[2,2.22,44.3]],"batl":[[0,2.8,27.15],[1,3.3,44.93]],"ltp":3.35,"tv":2042.32,"id":13117391}]}]}
{"op":"mcm","clk":"1006640207","pt":1580598727771,"mc":[{"id":"1.168175449","rc":[{"batl":[[1,3.95,13.44],[2,4.5,44.46]],"ltp":8.0,"tv":135.53,"id":13117449},{"batb":[[2,2.52,162.34]],"batl":[[0,2.8,48.65]],"ltp":2.5,"tv":178.8,"id":13117392},{"batb":[[1,2.66,172.52]],"ltp":3.35,"tv":2042.32,"id":13117391}]}]}
{"op":"mcm","clk":"1006641111","pt":1580598738374,"mc":[{"id":"1.168175449","rc":[{"trd":[[2.7,27.9]],"batb":[[0,2.7,102.12]],"ltp":2.7,"tv":2070.22,"id":13117391}],"tv":2388.66}]}
{"op":"mcm","clk":"1006642360","pt":1580598752508,"mc":[{"id":"1.168175449","rc":[{"batb":[[0,2.66,26.2]],"batl":[[0,2.8,48.41],[1,3.15,47.92]],"ltp":2.5,"tv":178.8,"id":13117392},{"batb":[[1,2.66,172.29],[2,2.24,43.9]],"batl":[[0,2.82,26.83],[1,3.35,44.46]],"ltp":2.7,"tv":2070.22,"id":13117391}]}]}
{"op":"mcm","clk":"1006643002","pt":1580598760228,"mc":[{"id":"1.168175449","rc":[{"batb":[[0,2.66,26.04]],"batl":[[0,2.8,48.26],[1,3.2,47.68]],"ltp":2.5,"tv":178.8,"id":13117392},{"batl":[[0,2.8,27.07]],"ltp":2.7,"tv":2070.22,"id":13117391}]}]}
{"op":"mcm","clk":"1006645827","pt":1580598794581,"mc":[{"id":"1.168175449","rc":[{"trd":[[2.7,47.9]],"batb":[[0,2.7,92.12]],"ltp":2.7,"tv":2090.22,"id":13117391}],"tv":2408.66}]}
{"op":"mcm","clk":"1006648019","pt":1580598822122,"mc":[{"id":"1.168175449","rc":[{"batb":[[0,3.3,38.63],[1,1.01,0.51],[2,3.6,0]],"batl":[[0,3.95,13.44],[1,4.5,44.46],[2,4.5,0]],"ltp":8.0,"tv":135.53,"id":13117449},{"batb":[[0,2.52,26.89],[1,2.46,32.02],[2,1.01,0.51]],"batl":[[0,2.8,22.69]],"ltp":2.5,"tv":178.8,"id":13117392},{"batb":[[0,2.66,25.21],[1,2.24,43.9],[2,1.01,0.51]],"batl":[[0,3.35,44.46],[1,3.35,0]],"ltp":2.7,"tv":2090.22,"id":13117391}]}]}
{"op":"mcm","clk":"1006648072","pt":1580598823006,"mc":[{"id":"1.168175449","rc":[{"batl":[[0,4.5,44.46],[1,4.5,0]],"ltp":8.0,"tv":135.53,"id":13117449},{"batb":[[0,2.46,32.02],[1,1.01,0.51],[2,1.01,0]],"batl":[[0,3.2,47.68],[1,3.2,0]],"ltp":2.5,"tv":178.8,"id":13117392},{"batb":[[0,2.24,43.9],[1,1.01,0.51],[2,1.01,0]],"ltp":2.7,"tv":2090.22,"id":13117391}]}]}
{"op":"mcm","clk":"1006648224","pt":1580598824639,"mc":[{"id":"1.168175449","rc":[{"batb":[[0,3.4,130.6],[1,3.35,84.85],[2,3.3,38.63]],"ltp":8.0,"tv":135.53,"id":13117449},{"batb":[[1,2.38,88.34],[2,2.34,166.18]],"ltp":2.5,"tv":178.8,"id":13117392},{"batb":[[0,2.26,135.1],[1,2.24,140.16],[2,1.01,0.51]],"ltp":2.7,"tv":2090.22,"id":13117391}]}]}
{"op":"mcm","clk":"1006648924","pt":1580598833407,"mc":[{"id":"1.168175449","rc":[{"batb":[[0,2.24,43.9],[1,1.01,0.51],[2,1.01,0]],"ltp":2.7,"tv":2090.22,"id":13117391}]}]}
{"op":"mcm","clk":"1006649140","pt":1580598836489,"mc":[{"id":"1.168175449","rc":[{"batb":[[0,3.15,90.79],[1,3.1,101.01],[2,2.24,43.9]],"ltp":2.7,"tv":2090.22,"id":13117391}]}]}
{"op":"mcm","clk":"1006649202","pt":1580598837225,"mc":[{"id":"1.168175449","rc":[{"batl":[[0,3.55,38.08],[1,4,29.19]],"ltp":8.0,"tv":135.53,"id":13117449},{"batl":[[0,2.6,31.39],[1,2.82,25.18]],"ltp":2.5,"tv":178.8,"id":13117392},{"batb":[[1,3.1,147.67],[2,2.6,29.35]],"batl":[[1,3.95,30.14]],"ltp":2.7,"tv":2090.22,"id":13117391}]}]}
{"op":"mcm","clk":"1006649252","pt":1580598837901,"mc":[{"id":"1.168175449","rc":[{"batl":[[1,3.7,15.12],[2,4,29.19]],"ltp":8.0,"tv":135.53,"id":13117449},{"batb":[[1,2.38,118.59]],"batl":[[1,2.64,25.21],[2,2.82,25.18]],"ltp":2.5,"tv":178.8,"id":13117392},{"batb":[[2,3,21]],"ltp":2.7,"tv":2090.22,"id":13117391}]}]}
{"op":"mcm","clk":"1006650148","pt":1580598848330,"mc":[{"id":"1.168175449","rc":[{"trd":[[3.4,5.33]],"batb":[[0,3.4,125.27]],"ltp":3.4,"tv":140.86,"id":13117449},{"trd":[[1000,0.02]],"batb":[[0,1000,3.98]],"ltp":1000.0,"tv":4.11,"id":13117448},{"trd":[[2.46,7.36]],"batb":[[0,2.46,24.66]],"ltp":2.46,"tv":186.17,"id":13117392},{"trd":[[3.35,121.23],[3.4,5.33]],"batl":[[0,3.95,30.14],[1,3.95,0]],"ltp":3.4,"tv":2184.46,"id":13117391}],"tv":2515.61}]}
{"op":"mcm","clk":"1006650885","pt":1580598857347,"mc":[{"id":"1.168175449","rc":[{"batb":[[0,3.05,47.21],[1,1.01,0.51],[2,3.3,0]],"batl":[[0,3.7,15.12],[1,4,29.19],[2,4,0]],"ltp":3.4,"tv":140.86,"id":13117449},{"batb":[[0,2.38,30.25],[1,2.32,38.16],[2,1.01,0.51]],"batl":[[0,2.64,25.21],[1,2.82,25.18],[2,2.82,0]],"ltp":2.46,"tv":186.17,"id":13117392},{"batb":[[0,3,21],[1,2.6,29.35],[2,1.01,0.51]],"ltp":3.4,"tv":2184.46,"id":13117391}]}]}
{"op":"mcm","clk":"1006651021","pt":1580598858915,"mc":[{"id":"1.168175449","rc":[{"batl":[[0,4,29.19],[1,4,0]],"ltp":3.4,"tv":140.86,"id":13117449},{"batb":[[0,2.32,38.16],[1,1.01,0.51],[2,1.01,0]],"batl":[[0,2.82,25.18],[1,2.82,0]],"ltp":2.46,"tv":186.17,"id":13117392},{"batb":[[0,2.6,29.35],[1,1.01,0.51],[2,1.01,0]],"ltp":3.4,"tv":2184.46,"id":13117391}]}]}
{"op":"mcm","clk":"1006651141","pt":1580598860440,"mc":[{"id":"1.168175449","rc":[{"batb":[[0,3.2,108.86],[1,3.15,98.79],[2,3.05,47.21]],"ltp":3.4,"tv":140.86,"id":13117449},{"batb":[[1,2.24,142.15],[2,2.22,97.29]],"ltp":2.46,"tv":186.17,"id":13117392},{"batb":[[0,2.64,89.73],[1,2.6,156.61],[2,1.01,0.51]],"ltp":3.4,"tv":2184.46,"id":13117391}]}]}
{"op":"mcm","clk":"1006651190","pt":1580598860851,"mc":[{"id":"1.168175449","rc":[{"batl":[[0,3.95,29.51]],"ltp":3.4,"tv":140.86,"id":13117449},{"batb":[[0,2.3,39.1]],"batl":[[0,2.8,25.97]],"ltp":2.46,"tv":186.17,"id":13117392},{"batb":[[0,2.64,117.98],[1,2.6,127.26]],"batl":[[0,4,28.88]],"ltp":3.4,"tv":2184.46,"id":13117391}]}]}
{"op":"mcm","clk":"1006652802","pt":1580598878510,"mc":[{"id":"1.168175449","rc":[{"batb":[[0,2.64,28.25],[1,1.01,0.51],[2,1.01,0]],"ltp":3.4,"tv":2184.46,"id":13117391}]}]}
{"op":"mcm","clk":"1006653068","pt":1580598881496,"mc":[{"id":"1.168175449","rc":[{"batb":[[0,3.65,95.42],[1,3.6,70.03],[2,2.64,28.25]],"ltp":3.4,"tv":2184.46,"id":13117391}]}]}
{"op":"mcm","clk":"1006653158","pt":1580598882427,"mc":[{"id":"1.168175449","rc":[{"batl":[[0,3.3,45.71],[1,3.5,16.8],[2,3.6,37.45]],"ltp":3.4,"tv":140.86,"id":13117449},{"batb":[[1,2.24,175.76]],"batl":[[0,2.4,38.24],[1,2.5,27.73],[2,2.54,33.05]],"ltp":2.46,"tv":186.17,"id":13117392},{"batb":[[0,3.7,29.82],[1,3.65,95.42],[2,3.6,70.03]],"batl":[[1,4.7,41.23]],"ltp":3.4,"tv":2184.46,"id":13117391}]}]}
{"op":"mcm","clk":"1006654883","pt":1580598901469,"mc":[{"id":"1.168175449","rc":[{"batb":[[0,2.92,21.64],[1,1.01,0.51],[2,3.05,0]],"batl":[[0,3.6,37.45],[1,3.5,0],[2,3.6,0]],"ltp":3.4,"tv":140.86,"id":13117449},{"batb":[[0,2.2,43.35],[1,1.01,0.51],[2,2.22,0]],"batl":[[0,2.54,33.05],[1,2.5,0],[2,2.54,0]],"ltp":2.46,"tv":186.17,"id":13117392},{"batb":[[0,3.15,44.53],[1,1.01,0.51],[2,3.6,0]],"batl":[[0,4.7,41.23],[1,4.7,0]],"ltp":3.4,"tv":2184.46,"id":13117391}]}]}
{"op":"mcm","clk":"1006655119","pt":1580598903480,"mc":[{"id":"1.168175449","rc":[{"batb":[[0,3.05,121.68],[1,3,111.36],[2,2.92,21.64]],"ltp":3.4,"tv":140.86,"id":13117449},{"batb":[[1,2.16,177.15],[2,2.14,108.27]],"ltp":2.46,"tv":186.17,"id":13117392},{"batb":[[0,3.15,146.75],[1,3.1,100.9],[2,1.01,0.51]],"ltp":3.4,"tv":2184.46,"id":13117391}]}]}
{"op":"mcm","clk":"1006655173","pt":1580598904170,"mc":[{"id":"1.168175449","rc":[{"batb":[[0,2.96,21.09],[1,1.01,0.51],[2,2.92,0]],"batl":[[0,3.65,36.12]],"ltp":3.4,"tv":140.86,"id":13117449},{"batb":[[1,1.01,0.51],[2,2.14,0]],"batl":[[0,2.52,33.6]],"ltp":2.46,"tv":186.17,"id":13117392},{"batb":[[0,3.1,45.24],[1,1.01,0.51],[2,1.01,0]],"batl":[[0,4.6,42.02]],"ltp":3.4,"tv":2184.46,"id":13117391}]}]}
{"op":"mcm","clk":"1006655311","pt":1580598905218,"mc":[{"id":"1.168175449","rc":[{"batb":[[0,3.25,97.24],[1,3.2,95.15],[2,2.96,21.09]],"ltp":3.4,"tv":140.86,"id":13117449},{"batb":[[0,2.26,151.99],[1,2.24,94.76],[2,2.2,43.35]],"ltp":2.46,"tv":186.17,"id":13117392},{"batb":[[0,3.55,77.84],[1,3.5,75.1],[2,3.1,45.24]],"ltp":3.4,"tv":2184.46,"id":13117391}]}]}
{"op":"mcm","clk":"1006655968","pt":1580598912380,"mc":[{"id":"1.168175449","rc":[{"batb":[[0,2.96,21.09],[1,1.01,0.51],[2,2.96,0]],"ltp":3.4,"tv":140.86,"id":13117449},{"batb":[[0,2.2,43.35],[1,1.01,0.51],[2,2.2,0]],"ltp":2.46,"tv":186.17,"id":13117392},{"batb":[[0,3.1,45.24],[1,1.01,0.51],[2,3.1,0]],"ltp":3.4,"tv":2184.46,"id":13117391}]}]}
{"op":"mcm","clk":"1006656179","pt":1580598914872,"mc":[{"id":"1.168175449","rc":[{"batb":[[0,3.05,121.68],[1,3,111.36],[2,2.96,21.09]],"ltp":3.4,"tv":140.86,"id":13117449},{"batb":[[1,2.16,177.15],[2,2.14,108.27]],"ltp":2.46,"tv":186.17,"id":13117392},{"batb":[[0,3.15,102.22],[1,3.1,146.14],[2,1.01,0.51]],"ltp":3.4,"tv":2184.46,"id":13117391}]}]}
{"op":"mcm","clk":"1006656566","pt":1580598918477,"mc":[{"id":"1.168175449","rc":[{"batb":[[0,3.1,45.24],[1,1.01,0.51],[2,1.01,0]],"ltp":3.4,"tv":2184.46,"id":13117391}]}]}
{"op":"mcm","clk":"1006656876","pt":1580598921470,"mc":[{"id":"1.168175449","rc":[{"batb":[[0,4.1,97],[1,4,107.57],[2,3.1,45.24]],"ltp":3.4,"tv":2184.46,"id":13117391}]}]}
{"op":"mcm","clk":"1006656963","pt":1580598922262,"mc":[{"id":"1.168175449","rc":[{"batl":[[0,3.15,50.59],[1,3.35,61.47]],"ltp":3.4,"tv":140.86,"id":13117449},{"batb":[[1,2.18,35.29],[2,2.16,223.34]],"batl":[[0,2.3,43.2],[1,2.34,41.23],[2,2.42,29.41]],"ltp":2.46,"tv":186.17,"id":13117392},{"batb":[[0,4.2,44.22],[1,4.1,97],[2,4,107.57]],"batl":[[1,5.2,33.36]],"ltp":3.4,"tv":2184.46,"id":13117391}]}]}
{"op":"mcm","clk":"1006658045","pt":1580598934354,"mc":[{"id":"1.168175449","rc":[{"batl":[[2,2.42,0]],"ltp":2.46,"tv":186.17,"id":13117392}]}]}
{"op":"mcm","clk":"1006658428","pt":1580598937452,"mc":[{"id":"1.168175449","rc":[{"batl":[[2,2.38,30.25]],"ltp":2.46,"tv":186.17,"id":13117392}]}]}
{"op":"mcm","clk":"1006658671","pt":1580598939378,"mc":[{"id":"1.168175449","rc":[{"batb":[[0,2.84,23.37],[1,1.01,0.51],[2,2.96,0]],"batl":[[0,3.35,61.47],[1,3.35,0]],"ltp":3.4,"tv":140.86,"id":13117449},{"batb":[[0,2.18,35.29],[1,2.16,46.19],[2,2.14,108.27]],"batl":[[0,2.34,41.23],[1,2.38,30.25],[2,2.38,0]],"ltp":2.46,"tv":186.17,"id":13117392},{"batb":[[0,3.8,28.17],[1,3.75,15.12],[2,1.01,0.51]],"batl":[[0,5.2,33.36],[1,5.2,0]],"ltp":3.4,"tv":2184.46,"id":13117391}]}]}
{"op":"mcm","clk":"1006658855","pt":1580598941467,"mc":[{"id":"1.168175449","rc":[{"batl":[[0,3.35,43.83]],"ltp":3.4,"tv":140.86,"id":13117449},{"batb":[[0,2.16,46.19],[1,2.14,108.27],[2,1.01,0.51]],"batl":[[1,2.38,0]],"ltp":2.46,"tv":186.17,"id":13117392},{"batb":[[1,1.01,0.51],[2,1.01,0]],"ltp":3.4,"tv":2184.46,"id":13117391}]}]}
{"op":"mcm","clk":"1006658935","pt":1580598942457,"mc":[{"id":"1.168175449","rc":[{"batb":[[0,2.98,86.41],[1,2.94,94.25],[2,2.84,23.37]],"ltp":3.4,"tv":140.86,"id":13117449},{"batb":[[1,2.14,154.11],[2,2.12,111.42]],"ltp":2.46,"tv":186.17,"id":13117392},{"batb":[[1,3.75,113.15],[2,3.7,65.41]],"ltp":3.4,"tv":2184.46,"id":13117391}]}]}
{"op":"mcm","clk":"1006659044","pt":1580598943568,"mc":[{"id":"1.168175449","rc":[{"batb":[[1,1.01,0.51],[2,3.7,0]],"ltp":3.4,"tv":2184.46,"id":13117391}]}]}
{"op":"mcm","clk":"1006659321","pt":1580598946404,"mc":[{"id":"1.168175449","rc":[{"batb":[[0,4.4,64.77],[1,4.3,91.41],[2,3.8,28.17]],"ltp":3.4,"tv":2184.46,"id":13117391}]}]}
{"op":"mcm","clk":"1006659402","pt":1580598947378,"mc":[{"id":"1.168175449","rc":[{"batl":[[0,3,22.98],[1,3.2,49.88]],"ltp":3.4,"tv":140.86,"id":13117449},{"batl":[[0,2.26,45.08],[1,2.32,42.09]],"ltp":2.46,"tv":186.17,"id":13117392},{"batb":[[0,4.6,35.01],[1,4.4,64.77],[2,4.3,91.41]],"batl":[[1,6.4,21.09]],"ltp":3.4,"tv":2184.46,"id":13117391}]}]}
{"op":"mcm","clk":"1006659460","pt":1580598947998,"mc":[{"id":"1.168175449","rc":[{"batl":[[1,3.2,68.37]],"ltp":3.4,"tv":140.86,"id":13117449},{"batb":[[0,2.18,35.29],[1,2.16,46.19],[2,2.14,154.11]],"batl":[[2,2.38,30.25]],"ltp":2.46,"tv":186.17,"id":13117392}]}]}
{"op":"mcm","clk":"1006662376","pt":1580598981798,"mc":[{"id":"1.168175449","rc":[{"batb":[[1,4.4,81.42]],"ltp":3.4,"tv":2184.46,"id":13117391}]}]}
{"op":"mcm","clk":"1006662542","pt":1580598983531,"mc":[{"id":"1.168175449","rc":[{"batb":[[0,2.64,28.01],[1,1.01,0.51],[2,2.84,0]],"batl":[[0,3.2,68.37],[1,3.2,0]],"ltp":3.4,"tv":140.86,"id":13117449},{"batb":[[1,2.1,50.36],[2,1.01,0.51]],"batl":[[0,2.32,42.09],[1,2.38,30.25],[2,2.38,0]],"ltp":2.46,"tv":186.17,"id":13117392},{"batb":[[0,4.1,47.05],[1,4,13.44],[2,1.01,0.51]],"batl":[[0,6.4,21.09],[1,6.4,0]],"ltp":3.4,"tv":2184.46,"id":13117391}]}]}
{"op":"mcm","clk":"1006662713","pt":1580598985311,"mc":[{"id":"1.168175449","rc":[{"batl":[[0,3.2,49.88]],"ltp":3.4,"tv":140.86,"id":13117449},{"batb":[[0,2.1,50.36],[1,1.01,0.51],[2,1.01,0]],"batl":[[1,2.38,0]],"ltp":2.46,"tv":186.17,"id":13117392},{"batb":[[1,1.01,0.51],[2,1.01,0]],"ltp":3.4,"tv":2184.46,"id":13117391}]}]}
{"op":"mcm","clk":"1006662824","pt":1580598986308,"mc":[{"id":"1.168175449","rc":[{"batb":[[0,2.78,124.86],[1,2.74,112.3],[2,2.68,27.07]],"batl":[[1,3.25,48.15]],"ltp":3.4,"tv":140.86,"id":13117449},{"batb":[[1,2.08,51.46],[2,2.06,155.55]],"ltp":2.46,"tv":186.17,"id":13117392},{"batb":[[1,4,47.92],[2,3.95,98.62]],"ltp":3.4,"tv":2184.46,"id":13117391}]}]}
{"op":"mcm","clk":"1006662896","pt":1580598987237,"mc":[{"id":"1.168175449","rc":[{"batl":[[0,3.25,48.15],[1,3.25,0]],"ltp":3.4,"tv":140.86,"id":13117449},{"batb":[[0,2.08,51.46],[1,2.06,155.55],[2,2.04,125.09]],"ltp":2.46,"tv":186.17,"id":13117392},{"batb":[[0,4,47.92],[1,3.95,98.62],[2,3.9,57.99]],"ltp":3.4,"tv":2184.46,"id":13117391}]}]}
{"op":"mcm","clk":"1006663131","pt":1580598990021,"mc":[{"id":"1.168175449","rc":[{"batb":[[0,2.68,27.07],[1,1.01,0.51],[2,2.68,0]],"ltp":3.4,"tv":140.86,"id":13117449},{"batb":[[1,1.01,0.51],[2,2.04,0]],"ltp":2.46,"tv":186.17,"id":13117392}]}]}
{"op":"mcm","clk":"1006663429","pt":1580598993418,"mc":[{"id":"1.168175449","rc":[{"batb":[[0,3.1,93.61],[1,3.05,107.06],[2,2.68,27.07]],"ltp":3.4,"tv":140.86,"id":13117449},{"batb":[[0,2.2,96.67],[1,2.18,102.71],[2,2.08,51.46]],"ltp":2.46,"tv":186.17,"id":13117392}]}]}
{"op":"mcm","clk":"1006663490","pt":1580598994154,"mc":[{"id":"1.168175449","rc":[{"batb":[[2,2.98,50.12]],"batl":[[1,3.3,17.64],[2,3.4,42.17]],"ltp":3.4,"tv":140.86,"id":13117449},{"batb":[[0,2.22,33.61],[1,2.2,140.57],[2,2.18,102.71]],"batl":[[1,2.34,41.07],[2,2.44,28.57]],"ltp":2.46,"tv":186.17,"id":13117392},{"batl":[[0,4.5,45.32],[1,5.3,31.71]],"ltp":3.4,"tv":2184.46,"id":13117391}]}]}
{"op":"mcm","clk":"1006664749","pt":1580599007523,"mc":[{"id":"1.168175449","rc":[{"batb":[[0,2.84,23.29],[1,1.01,0.51],[2,2.98,0]],"batl":[[0,3.3,17.64],[1,3.4,42.17],[2,3.4,0]],"ltp":3.4,"tv":140.86,"id":13117449},{"batb":[[1,2.14,47.76],[2,1.01,0.51]],"batl":[[0,2.34,41.07],[1,2.44,28.57],[2,2.44,0]],"ltp":2.46,"tv":186.17,"id":13117392},{"batb":[[0,3.75,15.12],[1,3.7,29.58],[2,1.01,0.51]],"batl":[[0,5.3,31.71],[1,5.3,0]],"ltp":3.4,"tv":2184.46,"id":13117391}]}]}
{"op":"mcm","clk":"1006664934","pt":1580599009358,"mc":[{"id":"1.168175449","rc":[{"batl":[[0,3.4,42.17],[1,3.4,0]],"ltp":3.4,"tv":140.86,"id":13117449},{"batb":[[0,2.14,47.76],[1,1.01,0.51],[2,1.01,0]],"batl":[[1,2.44,0]],"ltp":2.46,"tv":186.17,"id":13117392},{"batb":[[0,3.7,29.58],[1,1.01,0.51],[2,1.01,0]],"ltp":3.4,"tv":2184.46,"id":13117391}]}]}
{"op":"mcm","clk":"1006665038","pt":1580599010473,"mc":[{"id":"1.168175449","rc":[{"batb":[[0,2.92,117.32],[1,2.88,99],[2,2.86,22.82]],"batl":[[1,3.45,41.39]],"ltp":3.4,"tv":140.86,"id":13117449},{"batb":[[1,2.12,245.64],[2,2.1,114.5]],"ltp":2.46,"tv":186.17,"id":13117392},{"batb":[[1,3.65,120.85],[2,3.6,70.01]],"batl":[[0,5.2,32.1],[1,5.3,31.71]],"ltp":3.4,"tv":2184.46,"id":13117391}]}]}
{"op":"mcm","clk":"1006665056","pt":1580599010677,"mc":[{"id":"1.168175449","rc":[{"batl":[[0,3.45,41.39],[1,3.45,0]],"ltp":3.4,"tv":140.86,"id":13117449},{"batb":[[0,2.12,245.64],[1,2.1,114.5],[2,1.01,0.51]],"ltp":2.46,"tv":186.17,"id":13117392},{"batl":[[1,5.3,0]],"ltp":3.4,"tv":2184.46,"id":13117391}]}]}
{"op":"mcm","clk":"1006666286","pt":1580599023561,"mc":[{"id":"1.168175449","rc":[{"batb":[[1,1.01,0.51],[2,3.6,0]],"ltp":3.4,"tv":2184.46,"id":13117391}]}]}
{"op":"mcm","clk":"1006666536","pt":1580599026360,"mc":[{"id":"1.168175449","rc":[{"batb":[[0,4.5,120.41],[1,4.4,86.06],[2,3.7,29.58]],"ltp":3.4,"tv":2184.46,"id":13117391}]}]}
{"op":"mcm","clk":"1006666622","pt":1580599027096,"mc":[{"id":"1.168175449","rc":[{"batl":[[0,3.05,22.42],[1,3.25,47.6]],"ltp":3.4,"tv":140.86,"id":13117449},{"batb":[[2,2.04,54.21]],"batl":[[0,2.24,46.97],[1,2.3,43.12]],"ltp":2.46,"tv":186.17,"id":13117392},{"batb":[[0,4.7,33.6],[1,4.5,120.41],[2,4.4,86.06]],"batl":[[1,7,35.01]],"ltp":3.4,"tv":2184.46,"id":13117391}]}]}
{"op":"mcm","clk":"1006666758","pt":1580599028557,"mc":[{"id":"1.168175449","rc":[{"batl":[[1,3.15,19.32],[2,3.25,47.6]],"ltp":3.4,"tv":140.86,"id":13117449},{"batb":[[0,2.16,36.13],[1,2.12,245.64],[2,2.1,114.5]],"batl":[[2,2.36,30.25]],"ltp":2.46,"tv":186.17,"id":13117392}]}]}
{"op":"mcm","clk":"1006667852","pt":1580599040072,"mc":[{"id":"1.168175449","rc":[{"trd":[[2.92,25.18]],"batb":[[0,2.92,104.73]],"ltp":2.92,"tv":166.04,"id":13117449}],"tv":2540.79}]}
{"op":"mcm","clk":"1006668216","pt":1580599043400,"mc":[{"id":"1.168175449","rc":[{"batb":[[0,2.64,28.17],[1,1.01,0.51],[2,2.86,0]],"batl":[[0,3.15,19.32],[1,3.25,47.6],[2,3.25,0]],"ltp":2.92,"tv":166.04,"id":13117449},{"batb":[[1,2.04,54.21],[2,1.01,0.51]],"batl":[[0,2.3,43.12],[1,2.36,30.25],[2,2.36,0]],"ltp":2.46,"tv":186.17,"id":13117392},{"batb":[[0,4.1,13.44],[1,4,48.15],[2,1.01,0.51]],"batl":[[0,7,35.01],[1,7,0]],"ltp":3.4,"tv":2184.46,"id":13117391}]}]}
{"op":"mcm","clk":"1006668418","pt":1580599045501,"mc":[{"id":"1.168175449","rc":[{"batl":[[0,3.25,47.6],[1,3.25,0]],"ltp":2.92,"tv":166.04,"id":13117449},{"batb":[[0,2.04,54.21],[1,1.01,0.51],[2,1.01,0]],"batl":[[1,2.36,0]],"ltp":2.46,"tv":186.17,"id":13117392},{"batb":[[0,4,48.15],[1,1.01,0.51],[2,1.01,0]],"ltp":3.4,"tv":2184.46,"id":13117391}]}]}
{"op":"mcm","clk":"1006668483","pt":1580599046285,"mc":[{"id":"1.168175449","rc":[{"batb":[[0,2.72,107.92],[1,2.68,146.17],[2,2.64,28.17]],"batl":[[1,3.3,46.11]],"ltp":2.92,"tv":166.04,"id":13117449},{"batb":[[1,2.02,271.83],[2,2,132.86]],"ltp":2.46,"tv":186.17,"id":13117392},{"batb":[[0,4,113.73],[1,3.95,56.56],[2,1.01,0.51]],"ltp":3.4,"tv":2184.46,"id":13117391}]}]}
{"op":"mcm","clk":"1006668579","pt":1580599047444,"mc":[{"id":"1.168175449","rc":[{"batb":[[2,1.01,0.51]],"batl":[[0,3.3,46.11],[1,3.3,0]],"ltp":2.92,"tv":166.04,"id":13117449},{"batb":[[0,2.02,271.83],[1,2,132.86],[2,1.01,0.51]],"ltp":2.46,"tv":186.17,"id":13117392}]}]}
{"op":"mcm","clk":"1006668668","pt":1580599048443,"mc":[{"id":"1.168175449","rc":[{"batb":[[0,2.68,27.22],[1,1.01,0.51],[2,1.01,0]],"ltp":2.92,"tv":166.04,"id":13117449},{"batb":[[0,2.02,55.39],[1,1.01,0.51],[2,1.01,0]],"ltp":2.46,"tv":186.17,"id":13117392}]}]}
{"op":"mcm","clk":"1006668886","pt":1580599051334,"mc":[{"id":"1.168175449","rc":[{"batb":[[0,3.05,193.81],[1,3,111.12],[2,2.84,23.13]],"batl":[[1,3.45,41.07]],"ltp":2.92,"tv":166.04,"id":13117449},{"batb":[[0,2.2,131.08],[1,2.18,147.56],[2,2.1,49.57]],"batl":[[1,2.36,40.68]],"ltp":2.46,"tv":186.17,"id":13117392},{"batb":[[2,3.65,30.92]],"batl":[[0,4.5,46.19],[1,5.4,30.06],[2,7,35.01]],"ltp":3.4,"tv":2184.46,"id":13117391}]}]}
{"op":"mcm","clk":"1006668940","pt":1580599051963,"mc":[{"id":"1.168175449","rc":[{"batl":[[0,3.25,18.48],[1,3.3,46.11],[2,3.45,41.07]],"ltp":2.92,"tv":166.04,"id":13117449},{"batb":[[0,2.22,33.61],[1,2.2,131.08],[2,2.18,147.56]],"batl":[[2,2.44,28.57]],"ltp":2.46,"tv":186.17,"id":13117392},{"batb":[[2,3.75,15.12]],"batl":[[2,7,0]],"ltp":3.4,"tv":2184.46,"id":13117391}]}]}
{"op":"mcm","clk":"1006669063","pt":1580599053534,"mc":[{"id":"1.168175449","rc":[{"trd":[[2.22,40]],"batb":[[0,2.22,13.61]],"ltp":2.22,"tv":226.16,"id":13117392}],"tv":2580.79}]}
{"op":"mcm","clk":"1006669093","pt":1580599053849,"mc":[{"id":"1.168175449","rc":[{"batb":[[2,2.9,21.85]],"batl":[[0,3.3,46.11],[1,3.45,41.07],[2,3.45,0]],"ltp":2.92,"tv":166.04,"id":13117449}]}]}
{"op":"mcm","clk":"1006669343","pt":1580599056862,"mc":[{"id":"1.168175449","rc":[{"batl":[[0,3.3,63.75]],"ltp":2.92,"tv":166.04,"id":13117449},{"batb":[[0,2.22,32.94]],"ltp":2.22,"tv":226.16,"id":13117392}]}]}
{"op":"mcm","clk":"1006669540","pt":1580599059045,"mc":[{"id":"1.168175449","rc":[{"batb":[[0,3.05,47.92]],"ltp":2.92,"tv":166.04,"id":13117449},{"batb":[[2,2.18,44.93]],"ltp":2.22,"tv":226.16,"id":13117392}]}]}
{"op":"mcm","clk":"1006669842","pt":1580599062368,"mc":[{"id":"1.168175449","rc":[{"batb":[[1,3,122.23],[2,2.96,91.48]],"ltp":2.92,"tv":166.04,"id":13117449},{"batb":[[0,2.22,136.04]],"ltp":2.22,"tv":226.16,"id":13117392},{"batb":[[0,4,142.28]],"ltp":3.4,"tv":2184.46,"id":13117391}]}]}
{"op":"mcm","clk":"1006670104","pt":1580599065346,"mc":[{"id":"1.168175449","rc":[{"batb":[[0,2.84,23.13],[1,1.01,0.51],[2,2.96,0]],"batl":[[0,3.45,41.07],[1,3.45,0]],"ltp":2.92,"tv":166.04,"id":13117449},{"batb":[[0,2.1,49.57],[1,1.01,0.51],[2,2.18,0]],"batl":[[0,2.36,40.68],[1,2.36,0],[2,2.44,0]],"ltp":2.22,"tv":226.16,"id":13117392},{"batb":[[0,3.65,30.92],[1,1.01,0.51],[2,3.75,0]],"batl":[[0,5.4,30.06],[1,5.4,0]],"ltp":3.4,"tv":2184.46,"id":13117391}]}]}
{"op":"mcm","clk":"1006670375","pt":1580599068475,"mc":[{"id":"1.168175449","rc":[{"batb":[[0,2.82,122.34],[1,2.8,24.08],[2,2.78,107.25]],"batl":[[0,3.4,42.72]],"ltp":2.92,"tv":166.04,"id":13117449},{"batb":[[0,2.14,148.35],[1,2.12,160.06],[2,1.01,0.51]],"batl":[[0,2.38,39.89]],"ltp":2.22,"tv":226.16,"id":13117392},{"batb":[[0,3.65,147.06],[1,3.6,70.54],[2,1.01,0.51]],"batl":[[0,5.5,29.51]],"ltp":3.4,"tv":2184.46,"id":13117391}]}]}
{"op":"mcm","clk":"1006670660","pt":1580599071549,"mc":[{"id":"1.168175449","rc":[{"batb":[[0,3.65,30.37],[1,1.01,0.51],[2,1.01,0]],"ltp":3.4,"tv":2184.46,"id":13117391}]}]}
{"op":"mcm","clk":"1006670907","pt":1580599074472,"mc":[{"id":"1.168175449","rc":[{"batb":[[0,4.8,43.6],[1,4.7,75.7],[2,3.65,30.37]],"ltp":3.4,"tv":2184.46,"id":13117391}]}]}
{"op":"mcm","clk":"1006671006","pt":1580599075559,"mc":[{"id":"1.168175449","rc":[{"batl":[[0,2.96,23.6],[1,3.2,48.55]],"ltp":2.92,"tv":166.04,"id":13117449},{"batb":[[2,2,57.83]],"batl":[[0,2.24,47.13],[1,2.34,41.54]],"ltp":2.22,"tv":226.16,"id":13117392},{"batb":[[0,4.9,30.76],[1,4.8,43.6],[2,4.7,75.7]],"batl":[[1,8.2,24.86]],"ltp":3.4,"tv":2184.46,"id":13117391}]}]}
{"op":"mcm","clk":"1006671106","pt":1580599076495,"mc":[{"id":"1.168175449","rc":[{"batl":[[1,3.15,19.32],[2,3.2,48.55]],"ltp":2.92,"tv":166.04,"id":13117449},{"batb":[[1,2.12,197.03]],"batl":[[1,2.34,72.63]],"ltp":2.22,"tv":226.16,"id":13117392}]}]}
{"op":"mcm","clk":"1006672125","pt":1580599087541,"mc":[{"id":"1.168175449","rc":[{"batb":[[0,2.56,30.76],[1,1.01,0.51],[2,2.78,0]],"batl":[[0,3.15,19.32],[1,3.2,48.55],[2,3.2,0]],"ltp":2.92,"tv":166.04,"id":13117449},{"batb":[[0,2.12,36.97],[1,2,57.83],[2,1.01,0.51]],"batl":[[0,2.34,72.63],[1,2.34,0]],"ltp":2.22,"tv":226.16,"id":13117392},{"batb":[[0,4.3,12.6],[1,4,49.73],[2,1.01,0.51]],"batl":[[0,8.2,24.86],[1,8.2,0]],"ltp":3.4,"tv":2184.46,"id":13117391}]}]}
{"op":"mcm","clk":"1006672262","pt":1580599088949,"mc":[{"id":"1.168175449","rc":[{"batl":[[0,3.2,48.55],[1,3.2,0]],"ltp":2.92,"tv":166.04,"id":13117449},{"batb":[[0,2,57.83],[1,1.01,0.51],[2,1.01,0]],"batl":[[0,2.34,41.54]],"ltp":2.22,"tv":226.16,"id":13117392},{"batb":[[0,4,49.73],[1,1.01,0.51],[2,1.01,0]],"ltp":3.4,"tv":2184.46,"id":13117391}]}]}
{"op":"mcm","clk":"1006672380","pt":1580599090166,"mc":[{"id":"1.168175449","rc":[{"batb":[[0,2.58,132.19],[1,2.56,30.76],[2,2.54,135.51]],"ltp":2.92,"tv":166.04,"id":13117449},{"batb":[[0,2,212.45],[1,1.98,137.2],[2,1.01,0.51]],"ltp":2.22,"tv":226.16,"id":13117392},{"batb":[[1,3.95,92.97],[2,3.9,58.47]],"ltp":3.4,"tv":2184.46,"id":13117391}]}]}
{"op":"mcm","clk":"1006672831","pt":1580599095039,"mc":[{"id":"1.168175449","rc":[{"batb":[[1,1.01,0.51],[2,3.9,0]],"ltp":3.4,"tv":2184.46,"id":13117391}]}]}
{"op":"mcm","clk":"1006673140","pt":1580599098470,"mc":[{"id":"1.168175449","rc":[{"batl":[[0,2.7,30.14],[1,2.94,23.92],[2,3.2,48.55]],"ltp":2.92,"tv":166.04,"id":13117449},{"batb":[[2,1.86,36.67]],"batl":[[0,2.1,56.18],[1,2.24,47.13],[2,2.34,41.54]],"ltp":2.22,"tv":226.16,"id":13117392},{"batb":[[0,7,82.67],[1,6.8,65.36],[2,4.9,30.21]],"batl":[[1,27,13.61]],"ltp":3.4,"tv":2184.46,"id":13117391}]}]}
{"op":"mcm","clk":"1006673184","pt":1580599098940,"mc":[{"id":"1.168175449","rc":[{"batl":[[2,3.2,0]],"ltp":2.92,"tv":166.04,"id":13117449},{"batl":[[2,2.34,0]],"ltp":2.22,"tv":226.16,"id":13117392}]}]}
{"op":"mcm","clk":"1006673270","pt":1580599099982,"mc":[{"id":"1.168175449","rc":[{"batb":[[0,2.58,158.24]],"batl":[[1,2.9,21.85],[2,2.94,23.92]],"ltp":2.92,"tv":166.04,"id":13117449},{"batb":[[1,1.99,42.01],[2,1.98,137.2]],"batl":[[1,2.18,35.29],[2,2.24,47.13]],"ltp":2.22,"tv":226.16,"id":13117392},{"batb":[[2,5.9,8.4]],"ltp":3.4,"tv":2184.46,"id":13117391}]}]}
{"op":"mcm","clk":"1006674339","pt":1580599111481,"mc":[{"id":"1.168175449","rc":[{"batb":[[0,2.58,26.05],[2,2.28,41.47]],"ltp":2.92,"tv":166.04,"id":13117449}]}]}
{"op":"mcm","clk":"1006674600","pt":1580599114497,"mc":[{"id":"1.168175449","rc":[{"batb":[[1,2.28,41.47],[2,1.01,0.51]],"batl":[[0,2.9,21.85],[1,2.94,23.92],[2,2.94,0]],"ltp":2.92,"tv":166.04,"id":13117449},{"batb":[[0,1.99,42.01],[1,1.86,36.67],[2,1.01,0.51]],"batl":[[0,2.18,35.29],[1,2.24,47.13],[2,2.24,0]],"ltp":2.22,"tv":226.16,"id":13117392},{"batb":[[0,5.9,8.4],[1,4.9,30.21],[2,1.01,0.51]],"batl":[[0,27,13.61],[1,27,0]],"ltp":3.4,"tv":2184.46,"id":13117391}]}]}
{"op":"mcm","clk":"1006674661","pt":1580599115183,"mc":[{"id":"1.168175449","rc":[{"batb":[[0,2.28,41.47],[1,1.01,0.51],[2,1.01,0]],"batl":[[0,2.94,23.92],[1,2.94,0]],"ltp":2.92,"tv":166.04,"id":13117449},{"batb":[[0,1.86,36.67],[1,1.01,0.51],[2,1.01,0]],"batl":[[0,2.24,47.13],[1,2.24,0]],"ltp":2.22,"tv":226.16,"id":13117392},{"batb":[[0,4.9,30.21],[1,1.01,0.51],[2,1.01,0]],"ltp":3.4,"tv":2184.46,"id":13117391}]}]}
{"op":"mcm","clk":"1006674829","pt":1580599117015,"mc":[{"id":"1.168175449","rc":[{"batb":[[0,2.3,40.91],[1,2.28,176.06],[2,2.26,93.42]],"batl":[[0,2.96,23.6]],"ltp":2.92,"tv":166.04,"id":13117449},{"batb":[[0,1.85,37.06],[1,1.83,115.49],[2,1.81,182.48]],"ltp":2.22,"tv":226.16,"id":13117392},{"batb":[[1,4.8,84.84],[2,4.7,75.33]],"ltp":3.4,"tv":2184.46,"id":13117391}]}]}
{"op":"mcm","clk":"1006675177","pt":1580599121112,"mc":[{"id":"1.168175449","rc":[{"batb":[[1,1.01,0.51],[2,2.26,0]],"ltp":2.92,"tv":166.04,"id":13117449},{"batb":[[1,1.01,0.51],[2,1.81,0]],"ltp":2.22,"tv":226.16,"id":13117392}]}]}
{"op":"mcm","clk":"1006675433","pt":1580599124193,"mc":[{"id":"1.168175449","rc":[{"batb":[[0,2.78,115.72],[1,2.74,111.01],[2,2.3,40.91]],"ltp":2.92,"tv":166.04,"id":13117449},{"batb":[[0,2.16,115.63],[1,2.14,108.86],[2,1.85,37.06]],"ltp":2.22,"tv":226.16,"id":13117392}]}]}
{"op":"mcm","clk":"1006675515","pt":1580599125082,"mc":[{"id":"1.168175449","rc":[{"batb":[[0,2.8,24],[1,2.78,115.72],[2,2.74,111.01]],"batl":[[1,3.2,49.1]],"ltp":2.92,"tv":166.04,"id":13117449},{"batb":[[2,2.12,48.63]],"batl":[[1,2.34,41.23]],"ltp":2.22,"tv":226.16,"id":13117392},{"batl":[[0,5.5,29.35],[1,8.2,24.86]],"ltp":3.4,"tv":2184.46,"id":13117391}]}]}
{"op":"mcm","clk":"1006675637","pt":1580599126084,"mc":[{"id":"1.168175449","rc":[{"batl":[[1,3.1,19.32],[2,3.2,49.1]],"ltp":2.92,"tv":166.04,"id":13117449},{"batb":[[1,2.14,144.99]],"batl":[[2,2.36,30.25]],"ltp":2.22,"tv":226.16,"id":13117392}]}]}
{"op":"mcm","clk":"1006676386","pt":1580599134356,"mc":[{"id":"1.168175449","rc":[{"batb":[[1,2.56,30.69],[2,1.01,0.51]],"ltp":2.92,"tv":166.04,"id":13117449}]}]}
{"op":"mcm","clk":"1006676640","pt":1580599137290,"mc":[{"id":"1.168175449","rc":[{"batb":[[0,2.8,99.15],[1,2.76,109.3],[2,2.56,30.69]],"ltp":2.92,"tv":166.04,"id":13117449}]}]}
{"op":"mcm","clk":"1006676820","pt":1580599139503,"mc":[{"id":"1.168175449","rc":[{"batb":[[0,2.8,24],[1,2.56,30.69],[2,1.01,0.51]],"ltp":2.92,"tv":166.04,"id":13117449},{"batb":[[0,2.14,36.13],[1,2.12,48.63],[2,2,57.83]],"ltp":2.22,"tv":226.16,"id":13117392},{"batb":[[1,4.3,12.6],[2,4,49.57]],"ltp":3.4,"tv":2184.46,"id":13117391}]}]}
{"op":"mcm","clk":"1006676908","pt":1580599140396,"mc":[{"id":"1.168175449","rc":[{"batb":[[0,2.56,30.69],[1,1.01,0.51],[2,1.01,0]],"batl":[[0,3.1,19.32],[1,3.2,49.1],[2,3.2,0]],"ltp":2.92,"tv":166.04,"id":13117449},{"batb":[[1,2,57.83],[2,1.01,0.51]],"batl":[[0,2.34,41.23],[1,2.36,30.25],[2,2.36,0]],"ltp":2.22,"tv":226.16,"id":13117392},{"batb":[[0,4.3,12.6],[1,4,49.57],[2,1.01,0.51]],"batl":[[0,8.2,24.86],[1,8.2,0]],"ltp":3.4,"tv":2184.46,"id":13117391}]}]}
{"op":"mcm","clk":"1006676969","pt":1580599141075,"mc":[{"id":"1.168175449","rc":[{"batl":[[0,3.2,49.1],[1,3.2,0]],"ltp":2.92,"tv":166.04,"id":13117449},{"batb":[[0,2,57.83],[1,1.01,0.51],[2,1.01,0]],"batl":[[1,2.36,0]],"ltp":2.22,"tv":226.16,"id":13117392},{"batb":[[0,4,49.57],[1,1.01,0.51],[2,1.01,0]],"ltp":3.4,"tv":2184.46,"id":13117391}]}]}
{"op":"mcm","clk":"1006677072","pt":1580599142282,"mc":[{"id":"1.168175449","rc":[{"batb":[[0,2.56,120.33],[1,2.52,138.34],[2,1.01,0.51]],"ltp":2.92,"tv":166.04,"id":13117449},{"batb":[[0,2.02,105.92],[1,2,190.99],[2,1.01,0.51]],"ltp":2.22,"tv":226.16,"id":13117392},{"batb":[[0,4,124.72],[1,3.95,57.06],[2,1.01,0.51]],"ltp":3.4,"tv":2184.46,"id":13117391}]}]}
{"op":"mcm","clk":"1006677182","pt":1580599143486,"mc":[{"id":"1.168175449","rc":[{"batb":[[0,2.56,30.69],[1,1.01,0.51],[2,1.01,0]],"ltp":2.92,"tv":166.04,"id":13117449},{"batb":[[0,2,57.83],[1,1.01,0.51],[2,1.01,0]],"ltp":2.22,"tv":226.16,"id":13117392},{"batb":[[0,4,49.57],[1,1.01,0.51],[2,1.01,0]],"ltp":3.4,"tv":2184.46,"id":13117391}]}]}
{"op":"mcm","clk":"1006677372","pt":1580599145482,"mc":[{"id":"1.168175449","rc":[{"batb":[[0,2.74,101.73],[1,2.7,115.48],[2,2.56,30.69]],"ltp":2.92,"tv":166.04,"id":13117449},{"batb":[[0,2.12,162.43],[1,2.1,114.96],[2,2,57.83]],"ltp":2.22,"tv":226.16,"id":13117392},{"batb":[[0,5.1,97.24],[1,5,65.22],[2,4,49.57]],"ltp":3.4,"tv":2184.46,"id":13117391}]}]}
{"op":"mcm","clk":"1006677618","pt":1580599147986,"mc":[{"id":"1.168175449","rc":[{"batb":[[0,2.56,30.69],[1,1.01,0.51],[2,2.56,0]],"ltp":2.92,"tv":166.04,"id":13117449},{"batb":[[0,2,57.83],[1,1.01,0.51],[2,2,0]],"ltp":2.22,"tv":226.16,"id":13117392},{"batb":[[0,4,49.57],[1,1.01,0.51],[2,4,0]],"ltp":3.4,"tv":2184.46,"id":13117391}]}]}
{"op":"mcm","clk":"1006677923","pt":1580599151246,"mc":[{"id":"1.168175449","rc":[{"batb":[[0,4,124.72],[1,3.95,57.06],[2,1.01,0.51]],"ltp":3.4,"tv":2184.46,"id":13117391}]}]}
{"op":"mcm","clk":"1006678224","pt":1580599154488,"mc":[{"id":"1.168175449","rc":[{"batb":[[0,2.96,112.02],[1,2.92,94.51],[2,2.56,30.69]],"ltp":2.92,"tv":166.04,"id":13117449},{"batb":[[0,2.26,105.24],[1,2.24,95.42],[2,2,57.83]],"ltp":2.22,"tv":226.16,"id":13117392}]}]}
{"op":"mcm","clk":"1006678322","pt":1580599155504,"mc":[{"id":"1.168175449","rc":[{"batb":[[0,2.96,163.08],[2,2.78,24.71]],"batl":[[1,3.4,42.41]],"ltp":2.92,"tv":166.04,"id":13117449},{"batb":[[2,2.22,42.25]],"batl":[[1,2.42,38]],"ltp":2.22,"tv":226.16,"id":13117392},{"batb":[[2,3.55,32.73]],"batl":[[0,4.4,46.82],[1,5.5,28.95]],"ltp":3.4,"tv":2184.46,"id":13117391}]}]}
{"op":"mcm","clk":"1006678366","pt":1580599156012,"mc":[{"id":"1.168175449","rc":[{"batl":[[1,3.25,18.48],[2,3.4,42.41]],"ltp":2.92,"tv":166.04,"id":13117449},{"batb":[[2,2.22,75.86]],"batl":[[2,2.46,28.57]],"ltp":2.22,"tv":226.16,"id":13117392},{"batb":[[2,3.75,15.12]],"ltp":3.4,"tv":2184.46,"id":13117391}]}]}
{"op":"mcm","clk":"1006679605","pt":1580599169514,"mc":[{"id":"1.168175449","rc":[{"batb":[[0,2.78,24.71],[1,1.01,0.51],[2,2.78,0]],"batl":[[0,3.25,18.48],[1,3.4,42.41],[2,3.4,0]],"ltp":2.92,"tv":166.04,"id":13117449},{"batb":[[0,2.22,33.61],[1,2.14,47.76],[2,1.01,0.51]],"batl":[[0,2.42,38],[1,2.46,28.57],[2,2.46,0]],"ltp":2.22,"tv":226.16,"id":13117392},{"batb":[[0,3.75,15.12],[1,3.55,32.73],[2,1.01,0.51]],"batl":[[0,5.5,28.95],[1,5.5,0]],"ltp":3.4,"tv":2184.46,"id":13117391}]}]}
{"op":"mcm","clk":"1006679776","pt":1580599171444,"mc":[{"id":"1.168175449","rc":[{"batl":[[0,3.4,42.41],[1,3.4,0]],"ltp":2.92,"tv":166.04,"id":13117449},{"batb":[[0,2.14,47.76],[1,1.01,0.51],[2,1.01,0]],"batl":[[1,2.46,0]],"ltp":2.22,"tv":226.16,"id":13117392},{"batb":[[0,3.55,32.73],[1,1.01,0.51],[2,1.01,0]],"ltp":3.4,"tv":2184.46,"id":13117391}]}]}
{"op":"mcm","clk":"1006679879","pt":1580599172438,"mc":[{"id":"1.168175449","rc":[{"batb":[[0,2.78,98.67],[1,2.74,111.38],[2,1.01,0.51]],"ltp":2.92,"tv":166.04,"id":13117449},{"batb":[[0,2.16,127.39],[1,2.14,156.57],[2,1.01,0.51]],"ltp":2.22,"tv":226.16,"id":13117392},{"batb":[[0,3.6,87.83],[1,3.55,106.14],[2,1.01,0.51]],"ltp":3.4,"tv":2184.46,"id":13117391}]}]}
{"op":"mcm","clk":"1006679973","pt":1580599173537,"mc":[{"id":"1.168175449","rc":[{"batb":[[0,2.78,24.71],[1,1.01,0.51],[2,1.01,0]],"ltp":2.92,"tv":166.04,"id":13117449},{"batb":[[0,2.14,47.76],[1,1.01,0.51],[2,1.01,0]],"ltp":2.22,"tv":226.16,"id":13117392}]}]}
{"op":"mcm","clk":"1006680227","pt":1580599176533,"mc":[{"id":"1.168175449","rc":[{"batb":[[0,3.1,100.9],[1,3.05,105.65],[2,2.78,24.71]],"ltp":2.92,"tv":166.04,"id":13117449},{"batb":[[0,2.32,122.63],[1,2.28,179.78],[2,2.14,47.76]],"ltp":2.22,"tv":226.16,"id":13117392}]}]}
{"op":"mcm","clk":"1006680325","pt":1580599177525,"mc":[{"id":"1.168175449","rc":[{"batb":[[0,3.15,43.98],[1,3.1,100.9],[2,3.05,105.65]],"batl":[[1,3.9,30.76]],"ltp":2.92,"tv":166.04,"id":13117449},{"batb":[[1,2.3,38.79],[2,2.28,179.78]],"batl":[[1,2.7,28.25]],"ltp":2.22,"tv":226.16,"id":13117392},{"batb":[[2,2.76,25.02]],"batl":[[0,3.85,31.79],[1,5,36.35]],"ltp":3.4,"tv":2184.46,"id":13117391}]}]}
{"op":"mcm","clk":"1006680408","pt":1580599178528,"mc":[{"id":"1.168175449","rc":[{"batl":[[0,3.4,59.21]],"ltp":2.92,"tv":166.04,"id":13117449},{"batb":[[2,3.45,16.8]],"ltp":3.4,"tv":2184.46,"id":13117391}]}]}
{"op":"mcm","clk":"1006680584","pt":1580599180567,"mc":[{"id":"1.168175449","rc":[{"batl":[[1,2.52,26.89],[2,2.7,28.25]],"ltp":2.22,"tv":226.16,"id":13117392}]}]}
{"op":"mcm","clk":"1006680913","pt":1580599184173,"mc":[{"id":"1.168175449","rc":[{"batl":[[0,2.42,37.85]],"ltp":2.22,"tv":226.16,"id":13117392}]}]}
{"op":"mcm","clk":"1006681899","pt":1580599195292,"mc":[{"id":"1.168175449","rc":[{"batb":[[1,3.1,146.46]],"batl":[[0,3.35,43.83],[1,3.4,59.21],[2,3.85,31.79]],"ltp":2.92,"tv":166.04,"id":13117449},{"batb":[[0,2.32,160.79]],"batl":[[1,2.44,37.3],[2,2.52,26.89]],"ltp":2.22,"tv":226.16,"id":13117392},{"batb":[[0,3.6,120.17]],"ltp":3.4,"tv":2184.46,"id":13117391}]}]}
{"op":"mcm","clk":"1006681958","pt":1580599196177,"mc":[{"id":"1.168175449","rc":[{"batb":[[0,3.1,146.46],[1,3.05,105.65],[2,3,21]],"batl":[[1,3.4,16.8]],"ltp":2.92,"tv":166.04,"id":13117449},{"batb":[[1,2.28,179.78],[2,2.26,32.77]],"batl":[[0,2.44,37.3],[1,2.52,26.89],[2,2.72,27.85]],"ltp":2.22,"tv":226.16,"id":13117392},{"batb":[[1,3.55,73.41]],"batl":[[0,3.85,31.32],[1,5,35.8]],"ltp":3.4,"tv":2184.46,"id":13117391}]}]}
{"op":"mcm","clk":"1006683379","pt":1580599211388,"mc":[{"id":"1.168175449","rc":[{"batb":[[1,3.05,153.17]],"batl":[[0,3.3,45.71],[1,3.35,43.83],[2,3.4,16.8]],"ltp":2.92,"tv":166.04,"id":13117449},{"batl":[[1,2.46,36.51],[2,2.52,26.89]],"ltp":2.22,"tv":226.16,"id":13117392},{"batl":[[1,3.9,30.76],[2,5,35.8]],"ltp":3.4,"tv":2184.46,"id":13117391}]}]}
{"op":"mcm","clk":"1006683426","pt":1580599211910,"mc":[{"id":"1.168175449","rc":[{"batb":[[0,3.1,100.9]],"batl":[[1,3.4,16.8],[2,3.75,33.2]],"ltp":2.92,"tv":166.04,"id":13117449},{"batb":[[0,2.32,159.93]],"batl":[[0,2.46,36.51],[1,2.52,26.89],[2,2.74,27.38]],"ltp":2.22,"tv":226.16,"id":13117392},{"batb":[[0,3.6,119.62]],"batl":[[0,3.9,30.76],[1,5,35.17],[2,5,0]],"ltp":3.4,"tv":2184.46,"id":13117391}]}]}
{"op":"mcm","clk":"1006684108","pt":1580599219327,"mc":[{"id":"1.168175449","rc":[{"batb":[[0,2.34,37.22],[1,2.32,159.93],[2,2.28,179.78]],"ltp":2.22,"tv":226.16,"id":13117392}]}]}
{"op":"mcm","clk":"1006684190","pt":1580599220270,"mc":[{"id":"1.168175449","rc":[{"batl":[[2,3.8,33.13]],"ltp":2.92,"tv":166.04,"id":13117449},{"batb":[[1,2.32,122.63]],"ltp":2.22,"tv":226.16,"id":13117392}]}]}
{"op":"mcm","clk":"1006684949","pt":1580599228558,"mc":[{"id":"1.168175449","rc":[{"batb":[[1,3.05,105.65],[2,3,70.42]],"batl":[[0,3.25,47.45],[2,3.7,34.54]],"ltp":2.92,"tv":166.04,"id":13117449},{"batb":[[0,2.34,36.51]],"batl":[[0,2.48,35.72],[2,2.76,26.83]],"ltp":2.22,"tv":226.16,"id":13117392},{"batb":[[0,3.6,119.15]],"batl":[[0,3.95,30.37],[1,5.1,34.7]],"ltp":3.4,"tv":2184.46,"id":13117391}]}]}
{"op":"mcm","clk":"1006685599","pt":1580599235548,"mc":[{"id":"1.168175449","rc":[{"batl":[[0,3.9,30.45],[1,3.95,30.37],[2,5.1,34.7]],"ltp":3.4,"tv":2184.46,"id":13117391}]}]}
{"op":"mcm","clk":"1006685654","pt":1580599236280,"mc":[{"id":"1.168175449","rc":[{"batl":[[1,5.1,34.7],[2,5.1,0]],"ltp":3.4,"tv":2184.46,"id":13117391}]}]}
{"op":"mcm","clk":"1006688233","pt":1580599266527,"mc":[{"id":"1.168175449","rc":[{"batb":[[0,3,21],[1,2.82,23.84],[2,1.01,0.51]],"batl":[[0,3.4,16.8],[1,3.7,34.54],[2,3.7,0]],"ltp":2.92,"tv":166.04,"id":13117449},{"batb":[[0,2.26,32.77],[1,2.2,44.3],[2,1.01,0.51]],"batl":[[0,2.52,26.89],[1,2.76,26.83],[2,2.76,0]],"ltp":2.22,"tv":226.16,"id":13117392},{"batb":[[0,3.45,16.8],[1,2.8,24],[2,1.01,0.51]],"batl":[[0,5.1,34.7],[1,5.1,0]],"ltp":3.4,"tv":2184.46,"id":13117391}]}]}
{"op":"mcm","clk":"1006688293","pt":1580599267224,"mc":[{"id":"1.168175449","rc":[{"batb":[[0,2.82,23.84],[1,1.01,0.51],[2,1.01,0]],"batl":[[0,3.7,34.54],[1,3.7,0]],"ltp":2.92,"tv":166.04,"id":13117449},{"batb":[[0,2.2,44.3],[1,1.01,0.51],[2,1.01,0]],"batl":[[0,2.76,26.83],[1,2.76,0]],"ltp":2.22,"tv":226.16,"id":13117392},{"batb":[[0,2.8,24],[1,1.01,0.51],[2,1.01,0]],"ltp":3.4,"tv":2184.46,"id":13117391}]}]}
{"op":"mcm","clk":"1006688457","pt":1580599269197,"mc":[{"id":"1.168175449","rc":[{"batb":[[0,2.88,77.54],[1,2.84,101.61],[2,2.82,23.84]],"ltp":2.92,"tv":166.04,"id":13117449},{"batb":[[1,2.16,158.65],[2,2.14,108.78]],"ltp":2.22,"tv":226.16,"id":13117392},{"batb":[[1,2.78,94.56],[2,2.74,112.21]],"ltp":3.4,"tv":2184.46,"id":13117391}]}]}
{"op":"mcm","clk":"1006689932","pt":1580599286400,"mc":[{"id":"1.168175449","rc":[{"batb":[[1,1.01,0.51],[2,2.74,0]],"ltp":3.4,"tv":2184.46,"id":13117391}]}]}
{"op":"mcm","clk":"1006690197","pt":1580599289543,"mc":[{"id":"1.168175449","rc":[{"batb":[[0,4.5,109.62],[1,4.4,87.23],[2,2.8,24]],"ltp":3.4,"tv":2184.46,"id":13117391}]}]}
{"op":"mcm","clk":"1006690249","pt":1580599290122,"mc":[{"id":"1.168175449","rc":[{"batl":[[0,2.98,23.45],[1,3.2,18.48],[2,3.35,44.06]],"ltp":2.92,"tv":166.04,"id":13117449},{"batb":[[2,2.14,144.91]],"batl":[[0,2.3,43.2],[1,2.36,30.25],[2,2.5,34.93]],"ltp":2.22,"tv":226.16,"id":13117392},{"batb":[[0,4.5,146.13],[2,4.2,12.6]],"batl":[[1,6.8,38.08]],"ltp":3.4,"tv":2184.46,"id":13117391}]}]}
{"op":"mcm","clk":"1006691181","pt":1580599301235,"mc":[{"id":"1.168175449","rc":[{"batb":[[0,2.82,23.84],[1,2.64,28.4],[2,1.01,0.51]],"ltp":2.92,"tv":166.04,"id":13117449},{"batb":[[1,2.14,36.13],[2,2.08,51.77]],"ltp":2.22,"tv":226.16,"id":13117392},{"batb":[[0,4.5,36.51],[1,4.2,12.6],[2,3.45,35.09]],"ltp":3.4,"tv":2184.46,"id":13117391}]}]}
{"op":"mcm","clk":"1006691304","pt":1580599302537,"mc":[{"id":"1.168175449","rc":[{"batb":[[0,2.64,28.4],[1,1.01,0.51],[2,1.01,0]],"batl":[[0,3.2,18.48],[1,3.35,44.06],[2,3.35,0]],"ltp":2.92,"tv":166.04,"id":13117449},{"batb":[[0,2.14,36.13],[1,2.08,51.77],[2,1.01,0.51]],"batl":[[0,2.36,30.25],[1,2.5,34.93],[2,2.5,0]],"ltp":2.22,"tv":226.16,"id":13117392},{"batb":[[0,4.2,12.6],[1,3.45,35.09],[2,1.01,0.51]],"batl":[[0,6.8,38.08],[1,6.8,0]],"ltp":3.4,"tv":2184.46,"id":13117391}]}]}
{"op":"mcm","clk":"1006691376","pt":1580599303225,"mc":[{"id":"1.168175449","rc":[{"batl":[[0,3.35,44.06],[1,3.35,0]],"ltp":2.92,"tv":166.04,"id":13117449},{"batb":[[0,2.08,51.77],[1,1.01,0.51],[2,1.01,0]],"batl":[[0,2.5,34.93],[1,2.5,0]],"ltp":2.22,"tv":226.16,"id":13117392},{"batb":[[0,3.45,35.09],[1,1.01,0.51],[2,1.01,0]],"ltp":3.4,"tv":2184.46,"id":13117391}]}]}
{"op":"mcm","clk":"1006691451","pt":1580599304179,"mc":[{"id":"1.168175449","rc":[{"batb":[[0,2.7,101.63],[1,2.66,120.03],[2,2.64,28.4]],"ltp":2.92,"tv":166.04,"id":13117449},{"batb":[[1,2.06,127.8],[2,2.04,125.46]],"ltp":2.22,"tv":226.16,"id":13117392},{"batb":[[0,3.45,135.71],[1,3.4,81.43],[2,1.01,0.51]],"ltp":3.4,"tv":2184.46,"id":13117391}]}]}
{"op":"mcm","clk":"1006691688","pt":1580599307170,"mc":[{"id":"1.168175449","rc":[{"batb":[[0,3.45,35.09],[1,1.01,0.51],[2,1.01,0]],"ltp":3.4,"tv":2184.46,"id":13117391}]}]}
{"op":"mcm","clk":"1006691961","pt":1580599310554,"mc":[{"id":"1.168175449","rc":[{"batb":[[0,5.8,50.1],[1,5.7,49.23],[2,3.45,35.09]],"ltp":3.4,"tv":2184.46,"id":13117391}]}]}
{"op":"mcm","clk":"1006692003","pt":1580599311072,"mc":[{"id":"1.168175449","rc":[{"batl":[[0,2.78,27.85],[1,3.05,22.42]],"ltp":2.92,"tv":166.04,"id":13117449},{"batl":[[0,2.18,50.44],[1,2.28,44.61]],"ltp":2.22,"tv":226.16,"id":13117392},{"batb":[[0,5.8,90.94],[2,4.5,36.82]],"batl":[[1,8.4,23.68]],"ltp":3.4,"tv":2184.46,"id":13117391}]}]}
{"op":"mcm","clk":"1006692126","pt":1580599312547,"mc":[{"id":"1.168175449","rc":[{"batb":[[1,2.68,24.37],[2,2.66,120.03]],"batl":[[1,3,21],[2,3.05,22.42]],"ltp":2.92,"tv":166.04,"id":13117449},{"batl":[[1,2.22,33.61],[2,2.28,44.61]],"ltp":2.22,"tv":226.16,"id":13117392},{"batb":[[2,5.2,9.24]],"ltp":3.4,"tv":2184.46,"id":13117391}]}]}
{"op":"mcm","clk":"1006693390","pt":1580599327211,"mc":[{"id":"1.168175449","rc":[{"batb":[[0,2.5,32.57],[1,1.01,0.51],[2,2.66,0]],"batl":[[0,3.05,22.42],[1,3,0],[2,3.05,0]],"ltp":2.92,"tv":166.04,"id":13117449},{"batb":[[0,2.02,55.94],[1,1.01,0.51],[2,2.04,0]],"batl":[[0,2.28,44.61],[1,2.22,0],[2,2.28,0]],"ltp":2.22,"tv":226.16,"id":13117392},{"batb":[[0,4.5,36.82],[1,1.01,0.51],[2,5.2,0]],"batl":[[0,8.4,23.68],[1,8.4,0]],"ltp":3.4,"tv":2184.46,"id":13117391}]}]}
{"op":"mcm","clk":"1006693690","pt":1580599330407,"mc":[{"id":"1.168175449","rc":[{"batb":[[0,2.58,120.61],[1,2.54,135.34],[2,2.52,31.63]],"batl":[[0,3.05,21.87]],"ltp":2.92,"tv":166.04,"id":13117449},{"batb":[[0,2,206.4],[1,1.98,137.36],[2,1.01,0.51]],"batl":[[0,2.26,45.32]],"ltp":2.22,"tv":226.16,"id":13117392},{"batb":[[0,4.5,157.6],[1,4.4,87.06],[2,1.01,0.51]],"ltp":3.4,"tv":2184.46,"id":13117391}]}]}
{"op":"mcm","clk":"1006693792","pt":1580599331497,"mc":[{"id":"1.168175449","rc":[{"batb":[[0,2.52,31.63],[1,1.01,0.51],[2,2.52,0]],"ltp":2.92,"tv":166.04,"id":13117449},{"batb":[[0,2,57.04],[1,1.01,0.51],[2,1.01,0]],"ltp":2.22,"tv":226.16,"id":13117392}]}]}
{"op":"mcm","clk":"1006694022","pt":1580599334412,"mc":[{"id":"1.168175449","rc":[{"batb":[[0,2.9,78.77],[1,2.86,99.79],[2,2.52,31.63]],"ltp":2.92,"tv":166.04,"id":13117449},{"batb":[[0,2.14,191.41],[1,2.12,111.77],[2,2,57.04]],"ltp":2.22,"tv":226.16,"id":13117392}]}]}
{"op":"mcm","clk":"1006694113","pt":1580599335420,"mc":[{"id":"1.168175449","rc":[{"batb":[[0,2.9,100.96],[2,2.66,27.46]],"batl":[[1,3.5,39.66]],"ltp":2.92,"tv":166.04,"id":13117449},{"batb":[[0,2.16,46.5],[1,2.14,191.41],[2,2.12,111.77]],"batl":[[1,2.5,34.7]],"ltp":2.22,"tv":226.16,"id":13117392},{"batb":[[2,3.3,39.66]],"batl":[[0,5,35.49],[1,7,34.62]],"ltp":3.4,"tv":2184.46,"id":13117391}]}]}
{"op":"mcm","clk":"1006694204","pt":1580599336354,"mc":[{"id":"1.168175449","rc":[{"batb":[[2,2.84,22.69]],"batl":[[1,3.2,18.48],[2,3.5,39.66]],"ltp":2.92,"tv":166.04,"id":13117449},{"batb":[[2,2.12,148.74]],"batl":[[1,2.34,31.09],[2,2.5,34.7]],"ltp":2.22,"tv":226.16,"id":13117392},{"batb":[[2,4.3,12.6]],"ltp":3.4,"tv":2184.46,"id":13117391}]}]}
{"op":"mcm","clk":"1006696190","pt":1580599358540,"mc":[{"id":"1.168175449","rc":[{"batb":[[0,2.9,22.19],[1,2.84,22.69],[2,2.66,27.46]],"ltp":2.92,"tv":166.04,"id":13117449},{"batb":[[1,2.12,36.97],[2,2.02,55.71]],"ltp":2.22,"tv":226.16,"id":13117392},{"batb":[[0,4.5,36.82],[1,4.3,12.6],[2,3.3,39.66]],"ltp":3.4,"tv":2184.46,"id":13117391}]}]}
{"op":"mcm","clk":"1006696284","pt":1580599359276,"mc":[{"id":"1.168175449","rc":[{"batb":[[0,2.66,27.46],[1,1.01,0.51],[2,2.66,0]],"batl":[[0,3.5,39.66],[1,3.2,0],[2,3.5,0]],"ltp":2.92,"tv":166.04,"id":13117449},{"batb":[[0,2.02,55.71],[1,1.01,0.51],[2,2.02,0]],"batl":[[0,2.5,34.7],[1,2.34,0],[2,2.5,0]],"ltp":2.22,"tv":226.16,"id":13117392},{"batb":[[0,3.3,39.66],[1,1.01,0.51],[2,3.3,0]],"batl":[[0,7,34.62],[1,7,0]],"ltp":3.4,"tv":2184.46,"id":13117391}]}]}
{"op":"mcm","clk":"1006696488","pt":1580599361466,"mc":[{"id":"1.168175449","rc":[{"batb":[[0,2.7,79.8],[1,2.66,147.59],[2,1.01,0.51]],"ltp":2.92,"tv":166.04,"id":13117449},{"batb":[[0,2.02,209.82],[1,2,133.21],[2,1.01,0.51]],"ltp":2.22,"tv":226.16,"id":13117392},{"batb":[[0,3.3,163.12],[1,3.25,90.74],[2,1.01,0.51]],"ltp":3.4,"tv":2184.46,"id":13117391}]}]}
{"op":"mcm","clk":"1006696550","pt":1580599362051,"mc":[{"id":"1.168175449","rc":[{"batb":[[0,2.66,27.46],[1,1.01,0.51],[2,1.01,0]],"ltp":2.92,"tv":166.04,"id":13117449},{"batb":[[0,2.04,55.23],[1,1.01,0.51],[2,1.01,0]],"batl":[[0,2.5,34.46]],"ltp":2.22,"tv":226.16,"id":13117392},{"batb":[[0,3.3,39.42],[1,1.01,0.51],[2,1.01,0]],"batl":[[0,7,34.46]],"ltp":3.4,"tv":2184.46,"id":13117391}]}]}
{"op":"mcm","clk":"1006696765","pt":1580599364046,"mc":[{"id":"1.168175449","rc":[{"batb":[[0,2.96,88.05],[1,2.92,94.63],[2,2.66,27.46]],"ltp":2.92,"tv":166.04,"id":13117449},{"batb":[[0,2.18,189.72],[1,2.16,105.8],[2,2.04,55.23]],"ltp":2.22,"tv":226.16,"id":13117392},{"batb":[[0,4.2,116.38],[1,4.1,102.68],[2,3.3,39.42]],"ltp":3.4,"tv":2184.46,"id":13117391}]}]}
{"op":"mcm","clk":"1006697076","pt":1580599367186,"mc":[{"id":"1.168175449","rc":[{"batb":[[0,4.2,133.44]],"ltp":3.4,"tv":2184.46,"id":13117391}]}]}
{"op":"mcm","clk":"1006697426","pt":1580599371331,"mc":[{"id":"1.168175449","rc":[{"batb":[[0,2.66,27.46],[1,1.01,0.51],[2,2.66,0]],"ltp":2.92,"tv":166.04,"id":13117449},{"batb":[[0,2.04,55.23],[1,1.01,0.51],[2,2.04,0]],"ltp":2.22,"tv":226.16,"id":13117392},{"batb":[[0,3.3,39.42],[1,1.01,0.51],[2,3.3,0]],"ltp":3.4,"tv":2184.46,"id":13117391}]}]}
{"op":"mcm","clk":"1006697743","pt":1580599374403,"mc":[{"id":"1.168175449","rc":[{"batb":[[0,2.68,131.95],[1,2.66,27.46],[2,2.64,122.1]],"ltp":2.92,"tv":166.04,"id":13117449},{"batb":[[1,2.02,144.97],[2,2,133.17]],"ltp":2.22,"tv":226.16,"id":13117392},{"batb":[[0,3.3,184.9],[1,3.25,90.79],[2,1.01,0.51]],"ltp":3.4,"tv":2184.46,"id":13117391}]}]}
{"op":"mcm","clk":"1006697924","pt":1580599376384,"mc":[{"id":"1.168175449","rc":[{"batb":[[0,2.66,27.46],[1,1.01,0.51],[2,2.64,0]],"ltp":2.92,"tv":166.04,"id":13117449},{"batb":[[1,1.01,0.51],[2,2,0]],"ltp":2.22,"tv":226.16,"id":13117392}]}]}
{"op":"mcm","clk":"1006698193","pt":1580599379519,"mc":[{"id":"1.168175449","rc":[{"batb":[[0,3.25,72.86],[1,3.2,93.97],[2,2.66,27.46]],"ltp":2.92,"tv":166.04,"id":13117449},{"batb":[[0,2.36,157.02],[1,2.32,170.99],[2,2.04,55.23]],"ltp":2.22,"tv":226.16,"id":13117392}]}]}
{"op":"mcm","clk":"1006698288","pt":1580599380519,"mc":[{"id":"1.168175449","rc":[{"batb":[[1,3.2,135.67],[2,2.88,22.66]],"batl":[[1,3.55,15.96],[2,4.3,49.88]],"ltp":2.92,"tv":166.04,"id":13117449},{"batb":[[0,2.38,35.25],[1,2.36,157.02],[2,2.32,202.08]],"batl":[[1,2.56,26.89],[2,3.1,51.22]],"ltp":2.22,"tv":226.16,"id":13117392},{"batb":[[2,3.2,18.48]],"batl":[[0,3.55,38.08],[1,5.3,31.08]],"ltp":3.4,"tv":2184.46,"id":13117391}]}]}
{"op":"mcm","clk":"1006700339","pt":1580599401496,"mc":[{"id":"1.168175449","rc":[{"batb":[[0,2.88,22.66],[1,1.01,0.51],[2,2.88,0]],"batl":[[0,4.3,49.88],[1,3.55,0],[2,4.3,0]],"ltp":2.92,"tv":166.04,"id":13117449},{"batb":[[0,2.12,49.41],[1,1.01,0.51],[2,2.32,0]],"batl":[[0,3.1,51.22],[1,2.56,0],[2,3.1,0]],"ltp":2.22,"tv":226.16,"id":13117392},{"batb":[[0,2.34,39.03],[1,1.01,0.51],[2,3.2,0]],"batl":[[0,5.3,31.08],[1,5.3,0]],"ltp":3.4,"tv":2184.46,"id":13117391}]}]}
{"op":"mcm","clk":"1006700628","pt":1580599404432,"mc":[{"id":"1.168175449","rc":[{"batb":[[0,2.82,23.53]],"batl":[[0,4.2,26.36]],"ltp":2.92,"tv":166.04,"id":13117449},{"batb":[[0,2.12,48.39]],"batl":[[0,3.1,50.59]],"ltp":2.22,"tv":226.16,"id":13117392},{"batb":[[0,2.34,38.32]],"batl":[[0,5.4,30.45]],"ltp":3.4,"tv":2184.46,"id":13117391}]}]}
{"op":"mcm","clk":"1006700728","pt":1580599405428,"mc":[{"id":"1.168175449","rc":[{"batb":[[0,3.35,112.83],[1,3.3,86.83],[2,2.82,23.53]],"ltp":2.92,"tv":166.04,"id":13117449},{"batb":[[0,2.46,106.6],[1,2.42,152.39],[2,2.12,48.39]],"ltp":2.22,"tv":226.16,"id":13117392},{"batb":[[0,3.05,115.56],[1,3,111.07],[2,2.34,38.32]],"ltp":3.4,"tv":2184.46,"id":13117391}]}]}
{"op":"mcm","clk":"1006700923","pt":1580599407425,"mc":[{"id":"1.168175449","rc":[{"batb":[[0,3.3,64.33],[1,2.82,23.53],[2,1.01,0.51]],"ltp":2.92,"tv":166.04,"id":13117449},{"batb":[[0,2.12,48.39],[1,1.01,0.51],[2,2.12,0]],"ltp":2.22,"tv":226.16,"id":13117392},{"batb":[[1,2.34,38.32],[2,1.01,0.51]],"ltp":3.4,"tv":2184.46,"id":13117391}]}]}
{"op":"mcm","clk":"1006701164","pt":1580599409645,"mc":[{"id":"1.168175449","rc":[{"batb":[[1,3.25,89.35],[2,2.82,23.53]],"ltp":2.92,"tv":166.04,"id":13117449},{"batb":[[0,2.48,121.81],[1,2.44,149.48],[2,2.12,48.39]],"ltp":2.22,"tv":226.16,"id":13117392},{"batb":[[0,3.1,68.96],[1,3.05,115.56],[2,2.34,38.32]],"ltp":3.4,"tv":2184.46,"id":13117391}]}]}
{"op":"mcm","clk":"1006701453","pt":1580599412329,"mc":[{"id":"1.168175449","rc":[{"batb":[[0,2.82,23.53],[1,1.01,0.51],[2,2.82,0]],"ltp":2.92,"tv":166.04,"id":13117449},{"batb":[[0,2.12,48.39],[1,1.01,0.51],[2,2.12,0]],"ltp":2.22,"tv":226.16,"id":13117392},{"batb":[[0,2.34,38.32],[1,1.01,0.51],[2,2.34,0]],"ltp":3.4,"tv":2184.46,"id":13117391}]}]}
{"op":"mcm","clk":"1006701757","pt":1580599415348,"mc":[{"id":"1.168175449","rc":[{"batb":[[1,2.8,122.56],[2,2.76,107.63]],"ltp":2.92,"tv":166.04,"id":13117449},{"batb":[[0,2.12,223.25],[1,2.1,115.04],[2,1.01,0.51]],"ltp":2.22,"tv":226.16,"id":13117392},{"batb":[[1,2.32,140.92],[2,2.3,90.8]],"ltp":3.4,"tv":2184.46,"id":13117391}]}]}
{"op":"mcm","clk":"1006702876","pt":1580599426314,"mc":[{"id":"1.168175449","rc":[{"batb":[[1,1.01,0.51],[2,2.76,0]],"ltp":2.92,"tv":166.04,"id":13117449},{"batb":[[0,2.12,48.39],[1,1.01,0.51],[2,1.01,0]],"ltp":2.22,"tv":226.16,"id":13117392}]}]}
{"op":"mcm","clk":"1006703152","pt":1580599429392,"mc":[{"id":"1.168175449","rc":[{"batb":[[0,3.85,112.04],[1,3.8,88.01],[2,3.2,42.02]],"batl":[[1,5.8,25.81]],"ltp":2.92,"tv":166.04,"id":13117449},{"batb":[[0,2.92,96.46],[1,2.88,117.78],[2,2.4,34.31]],"batl":[[1,4.4,45.79]],"ltp":2.22,"tv":226.16,"id":13117392},{"batl":[[0,2.48,37.45],[1,3.55,38.95],[2,5.4,30.45]],"ltp":3.4,"tv":2184.46,"id":13117391}]}]}
{"op":"mcm","clk":"1006703259","pt":1580599430487,"mc":[{"id":"1.168175449","rc":[{"batb":[[2,2.84,22.69]],"batl":[[1,3.2,18.48],[2,4.4,45.79]],"ltp":2.22,"tv":226.16,"id":13117392},{"batl":[[2,5.4,0]],"ltp":3.4,"tv":2184.46,"id":13117391}]}]}
{"op":"mcm","clk":"1006703526","pt":1580599433206,"mc":[{"id":"1.168175449","rc":[{"batl":[[1,4.4,11.76],[2,5.8,25.81]],"ltp":2.92,"tv":166.04,"id":13117449}]}]}
{"op":"mcm","clk":"1006703799","pt":1580599436328,"mc":[{"id":"1.168175449","rc":[{"batb":[[0,3.85,59.53],[1,3.8,27.15]],"ltp":2.92,"tv":166.04,"id":13117449}]}]}
{"op":"mcm","clk":"1006704029","pt":1580599439129,"mc":[{"id":"1.168175449","rc":[{"batb":[[0,3.9,52.9],[1,3.85,59.53],[2,3.8,27.15]],"ltp":2.92,"tv":166.04,"id":13117449}]}]}
{"op":"mcm","clk":"1006704231","pt":1580599441497,"mc":[{"id":"1.168175449","rc":[{"batb":[[0,3.8,27.15],[1,3.2,42.02],[2,1.01,0.51]],"ltp":2.92,"tv":166.04,"id":13117449},{"batb":[[0,2.88,21.09],[1,2.84,22.69],[2,2.4,34.31]],"ltp":2.22,"tv":226.16,"id":13117392},{"batb":[[1,2.24,33.61],[2,1.71,50.36]],"ltp":3.4,"tv":2184.46,"id":13117391}]}]}
