{"op":"mcm","clk":"995732875","pt":1580515645283,"mc":[{"id":"1.168175457","marketDefinition":{"bspMarket":false,"turnInPlayEnabled":true,"persistenceEnabled":true,"marketBaseRate":5.0,"eventId":"29680072","eventTypeId":"2","numberOfWinners":1,"bettingType":"ODDS","marketType":"SET_WINNER","marketTime":"2020-02-02T13:00:00.000Z","suspendTime":"2020-02-02T13:00:00.000Z","bspReconciled":false,"complete":true,"inPlay":false,"crossMatching":false,"runnersVoidable":false,"numberOfActiveRunners":2,"betDelay":0,"status":"OPEN","runners":[{"status":"ACTIVE","sortPriority":1,"id":6374165,"name":"Marco Cecchinato"},{"status":"ACTIVE","sortPriority":2,"id":5071877,"name":"Andrej Martin"}],"regulators":["MR_INT"],"countryCode":"UY","discountAllowed":false,"timezone":"UTC","openDate":"2020-02-02T13:00:00.000Z","version":3144186609,"name":"Set 2 Winner","eventName":"Cecchinato v Martin"},"rc":[{"batb":[[0,1.01,20]],"ltp":0.0,"tv":0.0,"id":5071877},{"batb":[[0,1.01,20]],"ltp":0.0,"tv":0.0,"id":6374165}]}]}
{"op":"mcm","clk":"995733031","pt":1580515646599,"mc":[{"id":"1.168175457","marketDefinition":{"bspMarket":false,"turnInPlayEnabled":true,"persistenceEnabled":true,"marketBaseRate":5.0,"eventId":"29680072","eventTypeId":"2","numberOfWinners":1,"bettingType":"ODDS","marketType":"SET_WINNER","marketTime":"2020-02-02T13:00:00.000Z","suspendTime":"2020-02-02T13:00:00.000Z","bspReconciled":false,"complete":true,"inPlay":false,"crossMatching":false,"runnersVoidable":false,"numberOfActiveRunners":2,"betDelay":0,"status":"OPEN","runners":[{"status":"ACTIVE","sortPriority":1,"id":6374165,"name":"Marco Cecchinato"},{"status":"ACTIVE","sortPriority":2,"id":5071877,"name":"Andrej Martin"}],"regulators":["MR_INT"],"countryCode":"UY","discountAllowed":false,"timezone":"UTC","openDate":"2020-02-02T13:00:00.000Z","version":3144186609,"name":"Set 2 Winner","eventName":"Cecchinato v Martin"}}]}
{"op":"mcm","clk":"995733303","pt":1580515649573,"mc":[{"id":"1.168175457","marketDefinition":{"bspMarket":false,"turnInPlayEnabled":true,"persistenceEnabled":true,"marketBaseRate":5.0,"eventId":"29680072","eventTypeId":"2","numberOfWinners":1,"bettingType":"ODDS","marketType":"SET_WINNER","marketTime":"2020-02-02T13:00:00.000Z","suspendTime":"2020-02-02T13:00:00.000Z","bspReconciled":false,"complete":true,"inPlay":false,"crossMatching":false,"runnersVoidable":false,"numberOfActiveRunners":2,"betDelay":0,"status":"OPEN","runners":[{"status":"ACTIVE","sortPriority":1,"id":6374165,"name":"Marco Cecchinato"},{"status":"ACTIVE","sortPriority":2,"id":5071877,"name":"Andrej Martin"}],"regulators":["MR_INT"],"countryCode":"UY","discountAllowed":true,"timezone":"UTC","openDate":"2020-02-02T13:00:00.000Z","version":3144186609,"name":"Set 2 Winner","eventName":"Cecchinato v Martin"}}]}
{"op":"mcm","clk":"995782435","pt":1580516116664,"mc":[{"id":"1.168175457","rc":[{"batb":[[0,1.01,15]],"ltp":0.0,"tv":0.0,"id":5071877},{"batb":[[0,1.01,15]],"ltp":0.0,"tv":0.0,"id":6374165}]}]}
{"op":"mcm","clk":"995889896","pt":1580517337345,"mc":[{"id":"1.168175457","marketDefinition":{"bspMarket":false,"turnInPlayEnabled":true,"persistenceEnabled":true,"marketBaseRate":5.0,"eventId":"29680072","eventTypeId":"2","numberOfWinners":1,"bettingType":"ODDS","marketType":"SET_WINNER","marketTime":"2020-02-01T22:00:00.000Z","suspendTime":"2020-02-01T22:00:00.000Z","bspReconciled":false,"complete":true,"inPlay":false,"crossMatching":false,"runnersVoidable":false,"numberOfActiveRunners":2,"betDelay":0,"status":"OPEN","runners":[{"status":"ACTIVE","sortPriority":1,"id":6374165,"name":"Marco Cecchinato"},{"status":"ACTIVE","sortPriority":2,"id":5071877,"name":"Andrej Martin"}],"regulators":["MR_INT"],"countryCode":"UY","discountAllowed":true,"timezone":"UTC","openDate":"2020-02-02T13:00:00.000Z","version":3144220327,"name":"Set 2 Winner","eventName":"Cecchinato v Martin"}}]}
{"op":"mcm","clk":"995890182","pt":1580517341374,"mc":[{"id":"1.168175457","marketDefinition":{"bspMarket":false,"turnInPlayEnabled":true,"persistenceEnabled":true,"marketBaseRate":5.0,"eventId":"29680072","eventTypeId":"2","numberOfWinners":1,"bettingType":"ODDS","marketType":"SET_WINNER","marketTime":"2020-02-01T22:00:00.000Z","suspendTime":"2020-02-01T22:00:00.000Z","bspReconciled":false,"complete":true,"inPlay":false,"crossMatching":false,"runnersVoidable":false,"numberOfActiveRunners":2,"betDelay":0,"status":"OPEN","runners":[{"status":"ACTIVE","sortPriority":1,"id":6374165,"name":"Marco Cecchinato"},{"status":"ACTIVE","sortPriority":2,"id":5071877,"name":"Andrej Martin"}],"regulators":["MR_INT"],"countryCode":"UY","discountAllowed":true,"timezone":"UTC","openDate":"2020-02-01T22:00:00.000Z","version":3144220327,"name":"Set 2 Winner","eventName":"Cecchinato v Martin"}}]}
{"op":"mcm","clk":"996349835","pt":1580523359464,"mc":[{"id":"1.168175457","rc":[{"batb":[[0,1.01,15.51]],"ltp":0.0,"tv":0.0,"id":5071877},{"batb":[[0,1.01,15.51]],"ltp":0.0,"tv":0.0,"id":6374165}]}]}
{"op":"mcm","clk":"996362264","pt":1580523560402,"mc":[{"id":"1.168175457","rc":[{"batb":[[0,1.01,18.04]],"ltp":0.0,"tv":0.0,"id":5071877},{"batb":[[0,1.01,18.04]],"ltp":0.0,"tv":0.0,"id":6374165}]}]}
{"op":"mcm","clk":"996362335","pt":1580523561533,"mc":[{"id":"1.168175457","rc":[{"batb":[[0,1.01,15.51]],"ltp":0.0,"tv":0.0,"id":5071877},{"batb":[[0,1.01,15.51]],"ltp":0.0,"tv":0.0,"id":6374165}]}]}
{"op":"mcm","clk":"996362376","pt":1580523562102,"mc":[{"id":"1.168175457","rc":[{"batb":[[0,1.01,16.01]],"ltp":0.0,"tv":0.0,"id":5071877},{"batb":[[0,1.01,16.01]],"ltp":0.0,"tv":0.0,"id":6374165}]}]}
{"op":"mcm","clk":"1005389502","pt":1580587998475,"mc":[{"id":"1.168175457","rc":[{"batb":[[0,1.01,18.01]],"ltp":0.0,"tv":0.0,"id":5071877},{"batb":[[0,1.01,18.01]],"ltp":0.0,"tv":0.0,"id":6374165}]}]}
{"op":"mcm","clk":"1005389611","pt":1580587999126,"mc":[{"id":"1.168175457","rc":[{"batb":[[0,1.01,16.02]],"ltp":0.0,"tv":0.0,"id":5071877},{"batb":[[0,1.01,16.02]],"ltp":0.0,"tv":0.0,"id":6374165}]}]}
{"op":"mcm","clk":"1005905394","pt":1580591670521,"mc":[{"id":"1.168175457","rc":[{"batl":[[0,1.92,7.57]],"ltp":0.0,"tv":0.0,"id":6374165}]}]}
{"op":"mcm","clk":"1005905829","pt":1580591673611,"mc":[{"id":"1.168175457","rc":[{"batb":[[0,1.02,2.01],[1,1.01,16.01]],"ltp":0.0,"tv":0.0,"id":6374165}]}]}
{"op":"mcm","clk":"1005910094","pt":1580591704352,"mc":[{"id":"1.168175457","marketDefinition":{"bspMarket":false,"turnInPlayEnabled":true,"persistenceEnabled":true,"marketBaseRate":5.0,"eventId":"29680072","eventTypeId":"2","numberOfWinners":1,"bettingType":"ODDS","marketType":"SET_WINNER","marketTime":"2020-02-01T22:00:00.000Z","suspendTime":"2020-02-01T22:00:00.000Z","bspReconciled":false,"complete":true,"inPlay":false,"crossMatching":true,"runnersVoidable":false,"numberOfActiveRunners":2,"betDelay":0,"status":"OPEN","runners":[{"status":"ACTIVE","sortPriority":1,"id":6374165,"name":"Marco Cecchinato"},{"status":"ACTIVE","sortPriority":2,"id":5071877,"name":"Andrej Martin"}],"regulators":["MR_INT"],"countryCode":"UY","discountAllowed":true,"timezone":"UTC","openDate":"2020-02-01T22:00:00.000Z","version":3144220327,"name":"Set 2 Winner","eventName":"Cecchinato v Martin"}}]}
{"op":"mcm","clk":"1005956189","pt":1580592036174,"mc":[{"id":"1.168175457","rc":[{"batb":[[0,1.03,4.03],[1,1.02,2],[2,1.01,16.01]],"ltp":0.0,"tv":0.0,"id":6374165}]}]}
{"op":"mcm","clk":"1005988235","pt":1580592272870,"mc":[{"id":"1.168175457","rc":[{"batb":[[1,1.01,16.01],[2,1.01,0]],"ltp":0.0,"tv":0.0,"id":6374165}]}]}
{"op":"mcm","clk":"1006034118","pt":1580592635455,"mc":[{"id":"1.168175457","rc":[{"batb":[[0,1.03,2.03]],"ltp":0.0,"tv":0.0,"id":6374165}]}]}
{"op":"mcm","clk":"1006066947","pt":1580592892106,"mc":[{"id":"1.168175457","rc":[{"batl":[[0,1.7,101.3],[1,1.92,7.57]],"ltp":0.0,"tv":0.0,"id":6374165}]}]}
{"op":"mcm","clk":"1006074937","pt":1580592952399,"mc":[{"id":"1.168175457","rc":[{"batl":[[0,1.92,7.57],[1,1.92,0]],"ltp":0.0,"tv":0.0,"id":6374165}]}]}
{"op":"mcm","clk":"1006082756","pt":1580593015066,"mc":[{"id":"1.168175457","rc":[{"batb":[[0,2.1,1.2],[1,1.01,16.02]],"ltp":0.0,"tv":0.0,"id":5071877}]}]}
{"op":"mcm","clk":"1006154324","pt":1580593601676,"mc":[{"id":"1.168175457","rc":[{"batb":[[0,1.04,4.03],[1,1.03,2.02],[2,1.01,16.01]],"ltp":0.0,"tv":0.0,"id":6374165}]}]}
{"op":"mcm","clk":"1006212582","pt":1580594201059,"mc":[{"id":"1.168175457","rc":[{"batb":[[0,1.04,2.03]],"ltp":0.0,"tv":0.0,"id":6374165}]}]}
{"op":"mcm","clk":"1006224252","pt":1580594338497,"mc":[{"id":"1.168175457","rc":[{"batb":[[0,2.62,26.91],[1,2.1,1.2],[2,1.01,16.02]],"ltp":0.0,"tv":0.0,"id":5071877},{"batb":[[0,1.54,70.42],[1,1.04,2.03],[2,1.03,2.02]],"ltp":0.0,"tv":0.0,"id":6374165}]}]}
{"op":"mcm","clk":"1006225347","pt":1580594349428,"mc":[{"id":"1.168175457","rc":[{"batb":[[1,2.42,105.63],[2,2.1,1.2]],"ltp":0.0,"tv":0.0,"id":5071877},{"batb":[[1,1.47,319.16],[2,1.04,2.02]],"ltp":0.0,"tv":0.0,"id":6374165}]}]}
{"op":"mcm","clk":"1006226891","pt":1580594365745,"mc":[{"id":"1.168175457","rc":[{"batb":[[0,1.55,1.63],[1,1.54,70.42],[2,1.47,319.16]],"ltp":0.0,"tv":0.0,"id":6374165}]}]}
{"op":"mcm","clk":"1006229323","pt":1580594392174,"mc":[{"id":"1.168175457","rc":[{"batb":[[1,2.58,26.05],[2,2.42,105.63]],"batl":[[0,2.94,21]],"ltp":0.0,"tv":0.0,"id":5071877},{"batb":[[2,1.52,80.66]],"batl":[[0,1.65,42.01],[1,1.92,7.57]],"ltp":0.0,"tv":0.0,"id":6374165}]}]}
{"op":"mcm","clk":"1006235520","pt":1580594451467,"mc":[{"id":"1.168175457","rc":[{"batb":[[0,2.64,26.83]],"ltp":0.0,"tv":0.0,"id":5071877}]}]}
{"op":"mcm","clk":"1006240704","pt":1580594501387,"mc":[{"id":"1.168175457","marketDefinition":{"bspMarket":false,"turnInPlayEnabled":true,"persistenceEnabled":true,"marketBaseRate":5.0,"eventId":"29680072","eventTypeId":"2","numberOfWinners":1,"bettingType":"ODDS","marketType":"SET_WINNER","marketTime":"2020-02-01T21:57:00.000Z","suspendTime":"2020-02-01T21:57:00.000Z","bspReconciled":false,"complete":true,"inPlay":false,"crossMatching":true,"runnersVoidable":false,"numberOfActiveRunners":2,"betDelay":0,"status":"OPEN","runners":[{"status":"ACTIVE","sortPriority":1,"id":6374165,"name":"Marco Cecchinato"},{"status":"ACTIVE","sortPriority":2,"id":5071877,"name":"Andrej Martin"}],"regulators":["MR_INT"],"countryCode":"UY","discountAllowed":true,"timezone":"UTC","openDate":"2020-02-01T22:00:00.000Z","version":3147667738,"name":"Set 2 Winner","eventName":"Cecchinato v Martin"}}]}
{"op":"mcm","clk":"1006240857","pt":1580594502939,"mc":[{"id":"1.168175457","marketDefinition":{"bspMarket":false,"turnInPlayEnabled":true,"persistenceEnabled":true,"marketBaseRate":5.0,"eventId":"29680072","eventTypeId":"2","numberOfWinners":1,"bettingType":"ODDS","marketType":"SET_WINNER","marketTime":"2020-02-01T21:57:00.000Z","suspendTime":"2020-02-01T21:57:00.000Z","bspReconciled":false,"complete":true,"inPlay":false,"crossMatching":true,"runnersVoidable":false,"numberOfActiveRunners":2,"betDelay":0,"status":"OPEN","runners":[{"status":"ACTIVE","sortPriority":1,"id":6374165,"name":"Marco Cecchinato"},{"status":"ACTIVE","sortPriority":2,"id":5071877,"name":"Andrej Martin"}],"regulators":["MR_INT"],"countryCode":"UY","discountAllowed":true,"timezone":"UTC","openDate":"2020-02-01T21:57:00.000Z","version":3147667738,"name":"Set 2 Winner","eventName":"Cecchinato v Martin"}}]}
{"op":"mcm","clk":"1006245520","pt":1580594547532,"mc":[{"id":"1.168175457","rc":[{"batb":[[2,1.51,82.34]],"batl":[[0,1.63,42.01]],"ltp":0.0,"tv":0.0,"id":6374165}]}]}
{"op":"mcm","clk":"1006245725","pt":1580594549417,"mc":[{"id":"1.168175457","rc":[{"batb":[[0,2.64,26.67]],"ltp":0.0,"tv":0.0,"id":5071877},{"batb":[[1,1.53,70.89]],"ltp":0.0,"tv":0.0,"id":6374165}]}]}
{"op":"mcm","clk":"1006247995","pt":1580594570470,"mc":[{"id":"1.168175457","rc":[{"batb":[[0,2.66,26.2]],"ltp":0.0,"tv":0.0,"id":5071877}]}]}
{"op":"mcm","clk":"1006249033","pt":1580594580554,"mc":[{"id":"1.168175457","rc":[{"batb":[[0,2.68,25.65]],"ltp":0.0,"tv":0.0,"id":5071877},{"batb":[[1,1.52,73.17]],"ltp":0.0,"tv":0.0,"id":6374165}]}]}
{"op":"mcm","clk":"1006255839","pt":1580594649361,"mc":[{"id":"1.168175457","rc":[{"batb":[[1,1.52,72.94]],"ltp":0.0,"tv":0.0,"id":6374165}]}]}
{"op":"mcm","clk":"1006259737","pt":1580594688453,"mc":[{"id":"1.168175457","marketDefinition":{"bspMarket":false,"turnInPlayEnabled":true,"persistenceEnabled":true,"marketBaseRate":5.0,"eventId":"29680072","eventTypeId":"2","numberOfWinners":1,"bettingType":"ODDS","marketType":"SET_WINNER","marketTime":"2020-02-01T21:57:00.000Z","suspendTime":"2020-02-01T21:57:00.000Z","bspReconciled":false,"complete":true,"inPlay":false,"crossMatching":true,"runnersVoidable":false,"numberOfActiveRunners":2,"betDelay":0,"status":"OPEN","runners":[{"status":"ACTIVE","sortPriority":1,"id":6374165,"name":"Marco Cecchinato"},{"status":"ACTIVE","sortPriority":2,"id":5071877,"name":"Andrej Martin"}],"regulators":["MR_INT"],"countryCode":"UY","discountAllowed":true,"timezone":"UTC","openDate":"2020-02-01T21:57:00.000Z","version":3147667738,"name":"Set 2 Winner","eventName":"Cecchinato v Martin"},"rc":[{"batb":[[0,2.42,105.63],[1,2.1,1.2],[2,1.01,16.02]],"ltp":0.0,"tv":0.0,"id":5071877},{"batb":[[1,1.47,319.16],[2,1.04,2.02]],"batl":[[0,1.92,7.57],[1,1.92,0]],"ltp":0.0,"tv":0.0,"id":6374165}]}]}
{"op":"mcm","clk":"1006259796","pt":1580594689138,"mc":[{"id":"1.168175457","marketDefinition":{"bspMarket":false,"turnInPlayEnabled":true,"persistenceEnabled":true,"marketBaseRate":5.0,"eventId":"29680072","eventTypeId":"2","numberOfWinners":1,"bettingType":"ODDS","marketType":"SET_WINNER","marketTime":"2020-02-01T21:57:00.000Z","suspendTime":"2020-02-01T21:57:00.000Z","bspReconciled":false,"complete":true,"inPlay":true,"crossMatching":true,"runnersVoidable":false,"numberOfActiveRunners":2,"betDelay":3,"status":"OPEN","runners":[{"status":"ACTIVE","sortPriority":1,"id":6374165,"name":"Marco Cecchinato"},{"status":"ACTIVE","sortPriority":2,"id":5071877,"name":"Andrej Martin"}],"regulators":["MR_INT"],"countryCode":"UY","discountAllowed":true,"timezone":"UTC","openDate":"2020-02-01T21:57:00.000Z","version":3147676928,"name":"Set 2 Winner","eventName":"Cecchinato v Martin"},"rc":[{"batb":[[0,1.01,15.52],[1,2.1,0],[2,1.01,0]],"ltp":0.0,"tv":0.0,"id":5071877},{"batb":[[0,1.01,15.52],[1,1.47,0],[2,1.04,0]],"ltp":0.0,"tv":0.0,"id":6374165}]}]}
{"op":"mcm","clk":"1006261163","pt":1580594703448,"mc":[{"id":"1.168175457","rc":[{"batb":[[0,2.6,26.05],[1,1.01,15.52]],"batl":[[0,3,21]],"ltp":0.0,"tv":0.0,"id":5071877},{"batb":[[0,1.5,84.02],[1,1.01,15.52]],"batl":[[0,1.62,42.01]],"ltp":0.0,"tv":0.0,"id":6374165}]}]}
{"op":"mcm","clk":"1006261233","pt":1580594704124,"mc":[{"id":"1.168175457","rc":[{"batb":[[0,2.74,24],[1,2.66,26.12],[2,2.6,26.05]],"ltp":0.0,"tv":0.0,"id":5071877},{"batb":[[0,1.5,161.44],[1,1.48,81.76],[2,1.01,15.51]],"ltp":0.0,"tv":0.0,"id":6374165}]}]}
{"op":"mcm","clk":"1006262673","pt":1580594717441,"mc":[{"id":"1.168175457","rc":[{"batb":[[0,2.66,26.12],[1,2.6,26.05],[2,1.01,15.52]],"ltp":0.0,"tv":0.0,"id":5071877},{"batb":[[0,1.5,84.02]],"ltp":0.0,"tv":0.0,"id":6374165}]}]}
{"op":"mcm","clk":"1006262784","pt":1580594718328,"mc":[{"id":"1.168175457","rc":[{"batb":[[1,1.01,15.52],[2,1.01,0]],"ltp":0.0,"tv":0.0,"id":5071877},{"batb":[[0,1.48,81.76],[1,1.01,15.51],[2,1.01,0]],"ltp":0.0,"tv":0.0,"id":6374165}]}]}
{"op":"mcm","clk":"1006263039","pt":1580594720465,"mc":[{"id":"1.168175457","rc":[{"batb":[[0,2.64,26.67]],"ltp":0.0,"tv":0.0,"id":5071877},{"batb":[[0,1.49,80.33],[1,1.01,15.52]],"ltp":0.0,"tv":0.0,"id":6374165}]}]}
{"op":"mcm","clk":"1006266321","pt":1580594749482,"mc":[{"id":"1.168175457","rc":[{"batb":[[1,2.54,56.23],[2,1.01,15.52]],"batl":[[0,2.94,21]],"ltp":0.0,"tv":0.0,"id":5071877},{"batb":[[0,1.53,70.89],[1,1.52,705.6],[2,1.49,80.33]],"batl":[[0,1.65,42.01]],"ltp":0.0,"tv":0.0,"id":6374165}]}]}
{"op":"mcm","clk":"1006266420","pt":1580594750516,"mc":[{"id":"1.168175457","rc":[{"batb":[[1,2.56,26.89],[2,2.54,29.35]],"ltp":0.0,"tv":0.0,"id":5071877},{"batb":[[2,1.01,15.52]],"batl":[[0,1.64,42.01]],"ltp":0.0,"tv":0.0,"id":6374165}]}]}
{"op":"mcm","clk":"1006267605","pt":1580594761328,"mc":[{"id":"1.168175457","rc":[{"batb":[[1,1.52,154.86]],"ltp":0.0,"tv":0.0,"id":6374165}]}]}
{"op":"mcm","clk":"1006267947","pt":1580594764448,"mc":[{"id":"1.168175457","rc":[{"batb":[[1,1.52,324.85]],"ltp":0.0,"tv":0.0,"id":6374165}]}]}
{"op":"mcm","clk":"1006269043","pt":1580594773534,"mc":[{"id":"1.168175457","rc":[{"batb":[[1,1.52,154.86]],"ltp":0.0,"tv":0.0,"id":6374165}]}]}
{"op":"mcm","clk":"1006269168","pt":1580594774412,"mc":[{"id":"1.168175457","rc":[{"batb":[[0,2.54,29.35],[1,1.01,15.52],[2,2.54,0]],"ltp":0.0,"tv":0.0,"id":5071877},{"batb":[[0,1.52,74.2],[1,1.01,15.52],[2,1.01,0]],"ltp":0.0,"tv":0.0,"id":6374165}]}]}
{"op":"mcm","clk":"1006270533","pt":1580594785568,"mc":[{"id":"1.168175457","rc":[{"batb":[[0,2.7,25.26],[1,2.62,52.51],[2,2.54,560.49]],"batl":[[0,3,21]],"ltp":0.0,"tv":0.0,"id":5071877},{"batb":[[1,1.51,82.34],[2,1.49,78.84]],"batl":[[0,1.63,42.01]],"ltp":0.0,"tv":0.0,"id":6374165}]}]}
{"op":"mcm","clk":"1006271724","pt":1580594795462,"mc":[{"id":"1.168175457","rc":[{"batb":[[0,2.62,52.51],[1,1.01,15.52],[2,2.54,0]],"ltp":0.0,"tv":0.0,"id":5071877},{"batb":[[0,1.51,82.34],[1,1.49,78.84],[2,1.01,15.52]],"ltp":0.0,"tv":0.0,"id":6374165}]}]}
{"op":"mcm","clk":"1006271854","pt":1580594796441,"mc":[{"id":"1.168175457","rc":[{"batb":[[0,2.62,27.3]],"ltp":0.0,"tv":0.0,"id":5071877},{"batb":[[0,1.49,78.84],[1,1.01,15.52],[2,1.01,0]],"ltp":0.0,"tv":0.0,"id":6374165}]}]}
{"op":"mcm","clk":"1006273075","pt":1580594806569,"mc":[{"id":"1.168175457","rc":[{"batb":[[0,2.78,23.45],[1,2.68,25.57],[2,2.62,27.3]],"ltp":0.0,"tv":0.0,"id":5071877},{"batb":[[1,1.48,82.23],[2,1.01,15.51]],"ltp":0.0,"tv":0.0,"id":6374165}]}]}
{"op":"mcm","clk":"1006273175","pt":1580594807350,"mc":[{"id":"1.168175457","rc":[{"batb":[[2,2.66,25.21]],"batl":[[0,3.05,20.16]],"ltp":0.0,"tv":0.0,"id":5071877},{"batb":[[0,1.49,164.54]],"batl":[[0,1.61,42.01]],"ltp":0.0,"tv":0.0,"id":6374165}]}]}
{"op":"mcm","clk":"1006274484","pt":1580594818412,"mc":[{"id":"1.168175457","rc":[{"batb":[[0,2.68,25.57],[1,1.01,15.52],[2,2.66,0]],"ltp":0.0,"tv":0.0,"id":5071877},{"batb":[[0,1.48,82.23],[1,1.01,15.51],[2,1.01,0]],"ltp":0.0,"tv":0.0,"id":6374165}]}]}
{"op":"mcm","clk":"1006276054","pt":1580594830353,"mc":[{"id":"1.168175457","rc":[{"batb":[[0,2.82,22.27],[1,2.74,47.44],[2,1.01,15.52]],"batl":[[0,3.15,19.32]],"ltp":0.0,"tv":0.0,"id":5071877},{"batb":[[1,1.46,90.74],[2,1.45,89.07]],"batl":[[0,1.58,42.01]],"ltp":0.0,"tv":0.0,"id":6374165}]}]}
{"op":"mcm","clk":"1006276673","pt":1580594835361,"mc":[{"id":"1.168175457","rc":[{"batb":[[0,1.48,81.29],[2,1.45,87.97]],"ltp":0.0,"tv":0.0,"id":6374165}]}]}
{"op":"mcm","clk":"1006281985","pt":1580594878421,"mc":[{"id":"1.168175457","rc":[{"batb":[[0,2.74,23.92],[1,1.01,15.52],[2,1.01,0]],"ltp":0.0,"tv":0.0,"id":5071877},{"batb":[[0,1.45,87.98],[1,1.01,15.51],[2,1.45,0]],"ltp":0.0,"tv":0.0,"id":6374165}]}]}
{"op":"mcm","clk":"1006282313","pt":1580594881133,"mc":[{"id":"1.168175457","rc":[{"batb":[[0,2.7,25.1]],"ltp":0.0,"tv":0.0,"id":5071877},{"batb":[[0,1.46,85.62]],"ltp":0.0,"tv":0.0,"id":6374165}]}]}
{"op":"mcm","clk":"1006282690","pt":1580594884216,"mc":[{"id":"1.168175457","rc":[{"batl":[[0,3.65,170.41]],"ltp":0.0,"tv":0.0,"id":5071877},{"batl":[[0,2.04,383.01]],"ltp":0.0,"tv":0.0,"id":6374165}]}]}
{"op":"mcm","clk":"1006283342","pt":1580594889365,"mc":[{"id":"1.168175457","rc":[{"batb":[[0,2.72,24.37],[1,2.7,25.1],[2,1.01,15.52]],"batl":[[0,3.1,19.32],[1,3.65,170.41]],"ltp":0.0,"tv":0.0,"id":5071877},{"batb":[[0,1.48,87.39],[1,1.46,85.61],[2,1.01,15.51]],"batl":[[0,1.59,42.01],[1,2.04,383.01]],"ltp":0.0,"tv":0.0,"id":6374165}]}]}
{"op":"mcm","clk":"1006283471","pt":1580594890568,"mc":[{"id":"1.168175457","rc":[{"batb":[[2,2.64,26.75]],"ltp":0.0,"tv":0.0,"id":5071877},{"batb":[[0,1.52,74.59],[1,1.49,80.41],[2,1.48,87.39]],"ltp":0.0,"tv":0.0,"id":6374165}]}]}
{"op":"mcm","clk":"1006285381","pt":1580594907067,"mc":[{"id":"1.168175457","rc":[{"batb":[[1,2.64,26.75],[2,1.01,15.52]],"ltp":0.0,"tv":0.0,"id":5071877},{"batb":[[0,1.49,80.41],[1,1.48,87.39],[2,1.01,15.51]],"ltp":0.0,"tv":0.0,"id":6374165}]}]}
{"op":"mcm","clk":"1006285530","pt":1580594908477,"mc":[{"id":"1.168175457","rc":[{"batb":[[0,2.64,26.75],[1,1.01,15.52],[2,1.01,0]],"batl":[[0,3.65,170.41],[1,3.65,0]],"ltp":0.0,"tv":0.0,"id":5071877},{"batb":[[1,1.01,15.52],[2,1.01,0]],"batl":[[0,2.04,383.01],[1,2.04,0]],"ltp":0.0,"tv":0.0,"id":6374165}]}]}
{"op":"mcm","clk":"1006285755","pt":1580594910397,"mc":[{"id":"1.168175457","rc":[{"batb":[[0,2.64,26.59]],"ltp":0.0,"tv":0.0,"id":5071877},{"batb":[[0,1.48,80.82],[1,1.01,15.51]],"ltp":0.0,"tv":0.0,"id":6374165}]}]}
{"op":"mcm","clk":"1006287747","pt":1580594927386,"mc":[{"id":"1.168175457","rc":[{"batb":[[0,2.8,22.74],[1,2.76,23.53],[2,2.72,24.55]],"batl":[[0,3.2,18.48],[1,3.65,170.41]],"ltp":0.0,"tv":0.0,"id":5071877},{"batb":[[1,1.46,178],[2,1.01,15.51]],"batl":[[0,1.57,42.01],[1,2.04,383.01]],"ltp":0.0,"tv":0.0,"id":6374165}]}]}
{"op":"mcm","clk":"1006289254","pt":1580594941511,"mc":[{"id":"1.168175457","rc":[{"batb":[[0,2.76,23.53],[1,2.72,24.55],[2,1.01,15.52]],"ltp":0.0,"tv":0.0,"id":5071877},{"batb":[[0,1.46,178.01],[1,1.01,15.51],[2,1.01,0]],"ltp":0.0,"tv":0.0,"id":6374165}]}]}
{"op":"mcm","clk":"1006289346","pt":1580594942395,"mc":[{"id":"1.168175457","rc":[{"batb":[[0,2.72,24.55],[1,1.01,15.52],[2,1.01,0]],"batl":[[0,3.65,170.41],[1,3.65,0]],"ltp":0.0,"tv":0.0,"id":5071877},{"batb":[[0,1.46,87.27]],"batl":[[0,2.04,383.01],[1,2.04,0]],"ltp":0.0,"tv":0.0,"id":6374165}]}]}
{"op":"mcm","clk":"1006290620","pt":1580594954258,"mc":[{"id":"1.168175457","rc":[{"batb":[[1,2.64,26.36],[2,1.01,15.52]],"ltp":0.0,"tv":0.0,"id":5071877},{"batb":[[0,1.51,75.85],[1,1.48,82.08],[2,1.01,15.51]],"ltp":0.0,"tv":0.0,"id":6374165}]}]}
{"op":"mcm","clk":"1006290778","pt":1580594955518,"mc":[{"id":"1.168175457","rc":[{"batb":[[1,2.7,24.37],[2,2.64,26.36]],"batl":[[0,3.15,19.32],[1,3.65,170.41]],"ltp":0.0,"tv":0.0,"id":5071877},{"batb":[[2,1.47,89.06]],"batl":[[0,1.59,42.01],[1,2.04,383.01]],"ltp":0.0,"tv":0.0,"id":6374165}]}]}
{"op":"mcm","clk":"1006291003","pt":1580594957348,"mc":[{"id":"1.168175457","rc":[{"batb":[[1,1.49,1079.01],[2,1.48,82.08]],"ltp":0.0,"tv":0.0,"id":6374165}]}]}
{"op":"mcm","clk":"1006292622","pt":1580594971170,"mc":[{"id":"1.168175457","rc":[{"batb":[[0,2.7,24.37],[1,2.64,26.36],[2,1.01,15.52]],"ltp":0.0,"tv":0.0,"id":5071877},{"batb":[[0,1.48,82.08],[1,1.47,89.06],[2,1.01,15.51]],"ltp":0.0,"tv":0.0,"id":6374165}]}]}
{"op":"mcm","clk":"1006292798","pt":1580594972534,"mc":[{"id":"1.168175457","rc":[{"batb":[[0,2.64,26.36],[1,1.01,15.52],[2,1.01,0]],"batl":[[0,3.65,170.41],[1,3.65,0]],"ltp":0.0,"tv":0.0,"id":5071877},{"batb":[[1,1.01,15.51],[2,1.01,0]],"batl":[[0,2.04,383.01],[1,2.04,0]],"ltp":0.0,"tv":0.0,"id":6374165}]}]}
{"op":"mcm","clk":"1006293468","pt":1580594978375,"mc":[{"id":"1.168175457","rc":[{"batb":[[1,2.58,28.4],[2,1.01,15.52]],"ltp":0.0,"tv":0.0,"id":5071877},{"batb":[[0,1.53,71.6],[1,1.5,77.03],[2,1.48,82.08]],"ltp":0.0,"tv":0.0,"id":6374165}]}]}
{"op":"mcm","clk":"1006293592","pt":1580594979376,"mc":[{"id":"1.168175457","rc":[{"batb":[[0,2.66,25.21],[1,2.64,26.36],[2,2.58,28.4]],"batl":[[0,3.05,20.16],[1,3.65,170.41]],"ltp":0.0,"tv":0.0,"id":5071877},{"batb":[[2,1.49,85.7]],"batl":[[0,1.6,42.01],[1,2.04,383.01]],"ltp":0.0,"tv":0.0,"id":6374165}]}]}
{"op":"mcm","clk":"1006295125","pt":1580594992579,"mc":[{"id":"1.168175457","rc":[{"batb":[[1,2.58,28.4],[2,1.01,15.52]],"ltp":0.0,"tv":0.0,"id":5071877},{"batb":[[0,1.5,77.03],[1,1.49,85.7],[2,1.01,15.52]],"ltp":0.0,"tv":0.0,"id":6374165}]}]}
{"op":"mcm","clk":"1006295330","pt":1580594994458,"mc":[{"id":"1.168175457","rc":[{"batb":[[0,2.58,28.4],[1,1.01,15.52],[2,1.01,0]],"batl":[[0,3.65,170.41],[1,3.65,0]],"ltp":0.0,"tv":0.0,"id":5071877},{"batb":[[1,1.01,15.52],[2,1.01,0]],"batl":[[0,2.04,383.01],[1,2.04,0]],"ltp":0.0,"tv":0.0,"id":6374165}]}]}
{"op":"mcm","clk":"1006298380","pt":1580595021123,"mc":[{"id":"1.168175457","rc":[{"batb":[[1,2.48,31.16],[2,1.01,15.52]],"ltp":0.0,"tv":0.0,"id":5071877},{"batb":[[0,1.56,67.19],[1,1.53,72.23],[2,1.5,77.03]],"ltp":0.0,"tv":0.0,"id":6374165}]}]}
{"op":"mcm","clk":"1006298457","pt":1580595021974,"mc":[{"id":"1.168175457","rc":[{"batb":[[1,2.56,26.89],[2,2.48,31.16]],"batl":[[0,2.96,21]],"ltp":0.0,"tv":0.0,"id":5071877},{"batb":[[2,1.52,250.65]],"batl":[[0,1.64,42.01],[1,2.04,383.01]],"ltp":0.0,"tv":0.0,"id":6374165}]}]}
{"op":"mcm","clk":"1006298612","pt":1580595023528,"mc":[{"id":"1.168175457","rc":[{"batl":[[1,3.45,180.4]],"ltp":0.0,"tv":0.0,"id":5071877},{"batb":[[2,1.52,80.66]],"ltp":0.0,"tv":0.0,"id":6374165}]}]}
{"op":"mcm","clk":"1006301968","pt":1580595054883,"mc":[{"id":"1.168175457","rc":[{"batb":[[0,2.56,26.89],[1,2.48,31.16],[2,1.01,15.52]],"ltp":0.0,"tv":0.0,"id":5071877},{"batb":[[0,1.53,72.23],[1,1.52,80.66],[2,1.01,15.52]],"ltp":0.0,"tv":0.0,"id":6374165}]}]}
{"op":"mcm","clk":"1006302141","pt":1580595056471,"mc":[{"id":"1.168175457","rc":[{"batb":[[0,2.48,31.16],[1,1.01,15.52],[2,1.01,0]],"batl":[[0,3.45,180.4],[1,3.45,0]],"ltp":0.0,"tv":0.0,"id":5071877},{"batb":[[1,1.01,15.52],[2,1.01,0]],"batl":[[0,2.04,383.01],[1,2.04,0]],"ltp":0.0,"tv":0.0,"id":6374165}]}]}
{"op":"mcm","clk":"1006302310","pt":1580595057903,"mc":[{"id":"1.168175457","rc":[{"batb":[[0,2.5,30.53]],"ltp":0.0,"tv":0.0,"id":5071877},{"batb":[[0,1.52,73.41]],"ltp":0.0,"tv":0.0,"id":6374165}]}]}
{"op":"mcm","clk":"1006303482","pt":1580595068106,"mc":[{"id":"1.168175457","rc":[{"batb":[[0,2.68,25.57],[1,2.6,26.05],[2,2.58,28.33]],"batl":[[0,3,21],[1,3.45,180.4]],"ltp":0.0,"tv":0.0,"id":5071877},{"batb":[[1,1.5,160.73],[2,1.01,15.52]],"batl":[[0,1.63,42.01],[1,2.04,383.01]],"ltp":0.0,"tv":0.0,"id":6374165}]}]}
{"op":"mcm","clk":"1006305463","pt":1580595085043,"mc":[{"id":"1.168175457","rc":[{"batb":[[0,2.6,26.05],[1,2.58,28.33],[2,1.01,15.52]],"ltp":0.0,"tv":0.0,"id":5071877},{"batb":[[0,1.5,160.73],[1,1.01,15.52],[2,1.01,0]],"ltp":0.0,"tv":0.0,"id":6374165}]}]}
{"op":"mcm","clk":"1006305639","pt":1580595086515,"mc":[{"id":"1.168175457","rc":[{"batb":[[0,2.58,28.33],[1,1.01,15.52],[2,1.01,0]],"batl":[[0,3.45,180.4],[1,3.45,0]],"ltp":0.0,"tv":0.0,"id":5071877},{"batb":[[0,1.5,76.71]],"batl":[[0,2.04,383.01],[1,2.04,0]],"ltp":0.0,"tv":0.0,"id":6374165}]}]}
{"op":"mcm","clk":"1006306424","pt":1580595092337,"mc":[{"id":"1.168175457","rc":[{"batb":[[0,2.74,24.23],[1,2.64,26.44],[2,1.01,15.52]],"ltp":0.0,"tv":0.0,"id":5071877},{"batb":[[1,1.49,79.86],[2,1.01,15.52]],"ltp":0.0,"tv":0.0,"id":6374165}]}]}
{"op":"mcm","clk":"1006306563","pt":1580595093537,"mc":[{"id":"1.168175457","rc":[{"batb":[[1,2.66,25.21],[2,2.64,26.44]],"batl":[[0,3.05,20.16],[1,3.45,180.4]],"ltp":0.0,"tv":0.0,"id":5071877},{"batb":[[1,1.49,165.56]],"batl":[[0,1.61,42.01],[1,2.04,383.01]],"ltp":0.0,"tv":0.0,"id":6374165}]}]}
{"op":"mcm","clk":"1006308062","pt":1580595106532,"mc":[{"id":"1.168175457","rc":[{"batb":[[0,2.64,26.44],[1,1.01,15.52],[2,2.64,0]],"batl":[[0,3.45,180.4],[1,3.45,0]],"ltp":0.0,"tv":0.0,"id":5071877},{"batb":[[0,1.49,79.86],[1,1.01,15.52],[2,1.01,0]],"batl":[[0,2.04,383.01],[1,2.04,0]],"ltp":0.0,"tv":0.0,"id":6374165}]}]}
{"op":"mcm","clk":"1006309572","pt":1580595119505,"mc":[{"id":"1.168175457","rc":[{"batb":[[0,2.78,23.05],[1,2.72,24.37],[2,2.7,25.26]],"batl":[[0,3.1,19.32],[1,3.45,180.4]],"ltp":0.0,"tv":0.0,"id":5071877},{"batb":[[1,1.48,87.39],[2,1.47,83.8]],"batl":[[0,1.59,42.01],[1,2.04,383.01]],"ltp":0.0,"tv":0.0,"id":6374165}]}]}
{"op":"mcm","clk":"1006311231","pt":1580595133300,"mc":[{"id":"1.168175457","rc":[{"batb":[[0,2.72,24.37],[1,2.7,25.26],[2,1.01,15.52]],"ltp":0.0,"tv":0.0,"id":5071877},{"batb":[[0,1.48,87.39],[1,1.47,83.8],[2,1.01,15.51]],"ltp":0.0,"tv":0.0,"id":6374165}]}]}
{"op":"mcm","clk":"1006311474","pt":1580595135181,"mc":[{"id":"1.168175457","rc":[{"batb":[[0,2.7,25.26],[1,1.01,15.52],[2,1.01,0]],"batl":[[0,3.45,180.4],[1,3.45,0]],"ltp":0.0,"tv":0.0,"id":5071877},{"batb":[[0,1.47,83.81],[1,1.01,15.51],[2,1.01,0]],"batl":[[0,2.04,383.01],[1,2.04,0]],"ltp":0.0,"tv":0.0,"id":6374165}]}]}
{"op":"mcm","clk":"1006312469","pt":1580595143517,"mc":[{"id":"1.168175457","rc":[{"batb":[[0,2.86,21.79],[1,2.8,22.69],[2,2.78,23.37]],"batl":[[0,3.2,18.48]],"ltp":0.0,"tv":0.0,"id":5071877},{"batb":[[1,1.46,90.74],[2,1.45,90.17]],"batl":[[0,1.57,42.01],[1,2.04,383.01]],"ltp":0.0,"tv":0.0,"id":6374165}]}]}
{"op":"mcm","clk":"1006312712","pt":1580595145614,"mc":[{"id":"1.168175457","rc":[{"batl":[[1,3.9,158.24]],"ltp":0.0,"tv":0.0,"id":5071877}]}]}
{"op":"mcm","clk":"1006314528","pt":1580595161336,"mc":[{"id":"1.168175457","rc":[{"batb":[[0,2.82,22.19],[2,2.76,23.84]],"ltp":0.0,"tv":0.0,"id":5071877},{"batb":[[0,1.48,82.47],[2,1.45,88.75]],"ltp":0.0,"tv":0.0,"id":6374165}]}]}
{"op":"mcm","clk":"1006315435","pt":1580595168513,"mc":[{"id":"1.168175457","rc":[{"batb":[[1,2.76,23.84],[2,1.01,15.52]],"ltp":0.0,"tv":0.0,"id":5071877}]}]}
{"op":"mcm","clk":"1006315782","pt":1580595171554,"mc":[{"id":"1.168175457","rc":[{"batb":[[1,2.78,23.53],[2,2.76,23.84]],"ltp":0.0,"tv":0.0,"id":5071877},{"batb":[[1,1.46,178.39]],"ltp":0.0,"tv":0.0,"id":6374165}]}]}
{"op":"mcm","clk":"1006315839","pt":1580595172033,"mc":[{"id":"1.168175457","rc":[{"batb":[[2,2.74,24.23]],"ltp":0.0,"tv":0.0,"id":5071877},{"batb":[[0,1.48,81.37],[2,1.01,15.51]],"ltp":0.0,"tv":0.0,"id":6374165}]}]}
{"op":"mcm","clk":"1006321220","pt":1580595220467,"mc":[{"id":"1.168175457","rc":[{"batb":[[1,1.46,87.65]],"ltp":0.0,"tv":0.0,"id":6374165}]}]}
{"op":"mcm","clk":"1006321563","pt":1580595223374,"mc":[{"id":"1.168175457","rc":[{"batb":[[2,1.45,93.26]],"ltp":0.0,"tv":0.0,"id":6374165}]}]}
{"op":"mcm","clk":"1006321881","pt":1580595226194,"mc":[{"id":"1.168175457","rc":[{"batb":[[0,2.78,23.53],[1,2.74,24.23],[2,1.01,15.52]],"ltp":0.0,"tv":0.0,"id":5071877},{"batb":[[0,1.46,87.66],[1,1.45,93.26],[2,1.01,15.51]],"ltp":0.0,"tv":0.0,"id":6374165}]}]}
{"op":"mcm","clk":"1006321997","pt":1580595227213,"mc":[{"id":"1.168175457","rc":[{"batb":[[0,2.74,24.23],[1,1.01,15.52],[2,1.01,0]],"batl":[[0,3.9,158.24],[1,3.9,0]],"ltp":0.0,"tv":0.0,"id":5071877},{"batb":[[1,1.01,15.51],[2,1.01,0]],"batl":[[0,2.04,383.01],[1,2.04,0]],"ltp":0.0,"tv":0.0,"id":6374165}]}]}
{"op":"mcm","clk":"1006322813","pt":1580595234481,"mc":[{"id":"1.168175457","rc":[{"batb":[[0,2.9,52.17],[1,2.86,21.85],[2,2.84,22.19]],"batl":[[0,3.3,17.64],[1,3.9,158.24]],"ltp":0.0,"tv":0.0,"id":5071877},{"batb":[[0,1.46,87.5],[1,1.44,94.94],[2,1.43,95.76]],"batl":[[0,1.54,42.01],[1,2.04,383.01]],"ltp":0.0,"tv":0.0,"id":6374165}]}]}
{"op":"mcm","clk":"1006324867","pt":1580595252334,"mc":[{"id":"1.168175457","rc":[{"batb":[[0,2.86,21.85],[1,2.84,22.19],[2,1.01,15.52]],"ltp":0.0,"tv":0.0,"id":5071877},{"batb":[[0,1.44,94.95],[1,1.43,95.76],[2,1.01,15.51]],"ltp":0.0,"tv":0.0,"id":6374165}]}]}
{"op":"mcm","clk":"1006325004","pt":1580595253543,"mc":[{"id":"1.168175457","rc":[{"batb":[[0,2.84,22.19],[1,1.01,15.52],[2,1.01,0]],"batl":[[0,3.9,158.24],[1,3.9,0]],"ltp":0.0,"tv":0.0,"id":5071877},{"batb":[[0,1.43,95.77],[1,1.01,15.51],[2,1.01,0]],"batl":[[0,2.04,383.01],[1,2.04,0]],"ltp":0.0,"tv":0.0,"id":6374165}]}]}
{"op":"mcm","clk":"1006327469","pt":1580595274328,"mc":[{"id":"1.168175457","rc":[{"batb":[[1,2.8,22.69],[2,2.76,23.84]],"batl":[[0,3.25,18.48],[1,3.9,158.24]],"ltp":0.0,"tv":0.0,"id":5071877},{"batb":[[0,1.48,82.55],[1,1.45,183.35],[2,1.01,15.51]],"batl":[[0,1.56,42.01],[1,2.04,383.01]],"ltp":0.0,"tv":0.0,"id":6374165}]}]}
{"op":"mcm","clk":"1006329659","pt":1580595294288,"mc":[{"id":"1.168175457","rc":[{"batb":[[0,2.8,22.69],[1,2.76,23.84],[2,1.01,15.52]],"ltp":0.0,"tv":0.0,"id":5071877},{"batb":[[0,1.45,183.36],[1,1.01,15.51],[2,1.01,0]],"ltp":0.0,"tv":0.0,"id":6374165}]}]}
{"op":"mcm","clk":"1006329702","pt":1580595294664,"mc":[{"id":"1.168175457","rc":[{"batb":[[0,2.76,23.84],[1,1.01,15.52],[2,1.01,0]],"batl":[[0,3.9,158.24],[1,3.9,0]],"ltp":0.0,"tv":0.0,"id":5071877},{"batb":[[0,1.45,90.1]],"batl":[[0,2.04,383.01],[1,2.04,0]],"ltp":0.0,"tv":0.0,"id":6374165}]}]}
{"op":"mcm","clk":"1006330949","pt":1580595305385,"mc":[{"id":"1.168175457","rc":[{"batb":[[0,2.94,50.28],[1,2.86,21.56],[2,2.76,92.98]],"ltp":0.0,"tv":0.0,"id":5071877},{"batb":[[1,1.42,98.75],[2,1.01,15.51]],"ltp":0.0,"tv":0.0,"id":6374165}]}]}
{"op":"mcm","clk":"1006331025","pt":1580595305963,"mc":[{"id":"1.168175457","rc":[{"batb":[[1,2.9,21.85],[2,2.86,21.56]],"batl":[[0,3.35,17.64],[1,3.9,158.24]],"ltp":0.0,"tv":0.0,"id":5071877},{"batb":[[1,1.43,97.46],[2,1.42,98.75]],"batl":[[0,1.53,42.01],[1,2.04,383.01]],"ltp":0.0,"tv":0.0,"id":6374165}]}]}
{"op":"mcm","clk":"1006332877","pt":1580595322227,"mc":[{"id":"1.168175457","rc":[{"batb":[[0,2.9,21.85],[1,2.86,21.56],[2,1.01,15.52]],"ltp":0.0,"tv":0.0,"id":5071877},{"batb":[[0,1.43,97.47],[1,1.42,98.75],[2,1.01,15.51]],"ltp":0.0,"tv":0.0,"id":6374165}]}]}
{"op":"mcm","clk":"1006332942","pt":1580595322704,"mc":[{"id":"1.168175457","rc":[{"batb":[[0,2.86,21.56],[1,1.01,15.52],[2,1.01,0]],"batl":[[0,3.9,158.24],[1,3.9,0]],"ltp":0.0,"tv":0.0,"id":5071877},{"batb":[[0,1.42,98.76],[1,1.01,15.51],[2,1.01,0]],"batl":[[0,2.04,383.01],[1,2.04,0]],"ltp":0.0,"tv":0.0,"id":6374165}]}]}
{"op":"mcm","clk":"1006333247","pt":1580595325350,"mc":[{"id":"1.168175457","rc":[{"batb":[[0,2.88,21.24]],"ltp":0.0,"tv":0.0,"id":5071877},{"batb":[[0,1.41,99.78]],"ltp":0.0,"tv":0.0,"id":6374165}]}]}
{"op":"mcm","clk":"1006334879","pt":1580595340491,"mc":[{"id":"1.168175457","rc":[{"batb":[[1,2.84,22.69],[2,2.76,23.53]],"batl":[[0,3.25,18.48],[1,3.9,158.24]],"ltp":0.0,"tv":0.0,"id":5071877},{"batb":[[0,1.46,85.3],[1,1.44,94.94],[2,1.43,93.47]],"batl":[[0,1.55,42.01],[1,2.04,383.01]],"ltp":0.0,"tv":0.0,"id":6374165}]}]}
{"op":"mcm","clk":"1006335610","pt":1580595347238,"mc":[{"id":"1.168175457","rc":[{"batb":[[0,1.46,829.31]],"ltp":0.0,"tv":0.0,"id":6374165}]}]}
{"op":"mcm","clk":"1006337885","pt":1580595366358,"mc":[{"id":"1.168175457","rc":[{"batb":[[0,2.84,22.69],[1,2.76,23.53],[2,1.01,15.52]],"ltp":0.0,"tv":0.0,"id":5071877},{"batb":[[0,1.44,94.95],[1,1.43,93.47],[2,1.01,15.51]],"ltp":0.0,"tv":0.0,"id":6374165}]}]}
{"op":"mcm","clk":"1006337964","pt":1580595366942,"mc":[{"id":"1.168175457","rc":[{"batb":[[0,2.76,23.53],[1,1.01,15.52],[2,1.01,0]],"batl":[[0,3.9,158.24],[1,3.9,0]],"ltp":0.0,"tv":0.0,"id":5071877},{"batb":[[0,1.43,93.48],[1,1.01,15.51],[2,1.01,0]],"batl":[[0,2.04,383.01],[1,2.04,0]],"ltp":0.0,"tv":0.0,"id":6374165}]}]}
{"op":"mcm","clk":"1006339752","pt":1580595381559,"mc":[{"id":"1.168175457","rc":[{"batb":[[0,3,48],[1,2.9,52.32],[2,2.78,92.16]],"ltp":0.0,"tv":0.0,"id":5071877},{"batb":[[1,1.4,103.7],[2,1.01,15.51]],"ltp":0.0,"tv":0.0,"id":6374165}]}]}
{"op":"mcm","clk":"1006339859","pt":1580595382346,"mc":[{"id":"1.168175457","rc":[{"batb":[[1,2.9,74.17]],"batl":[[0,3.35,17.64],[1,3.9,158.24]],"ltp":0.0,"tv":0.0,"id":5071877},{"batb":[[1,1.42,99.98],[2,1.4,103.7]],"batl":[[0,1.53,42.01]],"ltp":0.0,"tv":0.0,"id":6374165}]}]}
{"op":"mcm","clk":"1006339917","pt":1580595382868,"mc":[{"id":"1.168175457","rc":[{"batb":[[2,1.01,15.52]],"ltp":0.0,"tv":0.0,"id":5071877},{"batl":[[1,1.89,435.28]],"ltp":0.0,"tv":0.0,"id":6374165}]}]}
{"op":"mcm","clk":"1006343006","pt":1580595407003,"mc":[{"id":"1.168175457","rc":[{"batb":[[0,2.9,74.17],[1,1.01,15.52],[2,1.01,0]],"ltp":0.0,"tv":0.0,"id":5071877},{"batb":[[0,1.42,99.99],[1,1.4,103.7],[2,1.01,15.51]],"ltp":0.0,"tv":0.0,"id":6374165}]}]}
{"op":"mcm","clk":"1006343311","pt":1580595409000,"mc":[{"id":"1.168175457","rc":[{"batb":[[0,2.9,52.32]],"batl":[[0,3.9,158.24],[1,3.9,0]],"ltp":0.0,"tv":0.0,"id":5071877},{"batb":[[0,1.4,103.71],[1,1.01,15.51],[2,1.01,0]],"batl":[[0,1.89,435.28],[1,1.89,0]],"ltp":0.0,"tv":0.0,"id":6374165}]}]}
{"op":"mcm","clk":"1006347249","pt":1580595437559,"mc":[{"id":"1.168175457","rc":[{"batb":[[1,2.8,22.82],[2,1.01,15.52]],"ltp":0.0,"tv":0.0,"id":5071877},{"batb":[[0,1.46,87.27],[1,1.44,179.42],[2,1.43,94.58]],"ltp":0.0,"tv":0.0,"id":6374165}]}]}
{"op":"mcm","clk":"1006347380","pt":1580595438554,"mc":[{"id":"1.168175457","rc":[{"batb":[[1,2.86,21.85],[2,2.8,22.82]],"ltp":0.0,"tv":0.0,"id":5071877}]}]}
{"op":"mcm","clk":"1006347600","pt":1580595440533,"mc":[{"id":"1.168175457","rc":[{"batl":[[0,3.3,17.64],[1,3.9,158.24]],"ltp":0.0,"tv":0.0,"id":5071877},{"batl":[[0,1.54,42.01],[1,1.89,435.28]],"ltp":0.0,"tv":0.0,"id":6374165}]}]}
{"op":"mcm","clk":"1006347703","pt":1580595441372,"mc":[{"id":"1.168175457","rc":[{"batb":[[1,1.44,274.36]],"ltp":0.0,"tv":0.0,"id":6374165}]}]}
{"op":"mcm","clk":"1006349334","pt":1580595455434,"mc":[{"id":"1.168175457","rc":[{"batb":[[1,1.44,94.94]],"ltp":0.0,"tv":0.0,"id":6374165}]}]}
{"op":"mcm","clk":"1006349446","pt":1580595456260,"mc":[{"id":"1.168175457","rc":[{"batb":[[0,2.86,21.85],[1,2.8,22.82],[2,1.01,15.52]],"ltp":0.0,"tv":0.0,"id":5071877},{"batb":[[0,1.44,94.95],[1,1.43,94.58],[2,1.01,15.51]],"ltp":0.0,"tv":0.0,"id":6374165}]}]}
{"op":"mcm","clk":"1006349586","pt":1580595457460,"mc":[{"id":"1.168175457","rc":[{"batb":[[0,2.8,22.82],[1,1.01,15.52],[2,1.01,0]],"batl":[[0,3.9,158.24],[1,3.9,0]],"ltp":0.0,"tv":0.0,"id":5071877},{"batb":[[0,1.43,94.59],[1,1.01,15.51],[2,1.01,0]],"batl":[[0,1.89,435.28],[1,1.89,0]],"ltp":0.0,"tv":0.0,"id":6374165}]}]}
{"op":"mcm","clk":"1006350311","pt":1580595463476,"mc":[{"id":"1.168175457","rc":[{"batb":[[0,3,47.29],[1,2.9,52.24],[2,1.01,15.52]],"ltp":0.0,"tv":0.0,"id":5071877},{"batb":[[1,1.4,104.33],[2,1.01,15.51]],"ltp":0.0,"tv":0.0,"id":6374165}]}]}
{"op":"mcm","clk":"1006350430","pt":1580595464370,"mc":[{"id":"1.168175457","rc":[{"batb":[[1,2.94,21],[2,2.9,52.24]],"batl":[[0,3.4,16.8],[1,3.9,158.24]],"ltp":0.0,"tv":0.0,"id":5071877},{"batb":[[1,1.42,99.98],[2,1.4,104.33]],"ltp":0.0,"tv":0.0,"id":6374165}]}]}
{"op":"mcm","clk":"1006350543","pt":1580595465260,"mc":[{"id":"1.168175457","rc":[{"batl":[[0,1.52,42.01],[1,1.89,435.28]],"ltp":0.0,"tv":0.0,"id":6374165}]}]}
{"op":"mcm","clk":"1006352721","pt":1580595483390,"mc":[{"id":"1.168175457","rc":[{"batb":[[0,2.94,21],[1,2.9,52.24],[2,1.01,15.52]],"ltp":0.0,"tv":0.0,"id":5071877},{"batb":[[0,1.42,99.99],[1,1.4,104.33],[2,1.01,15.51]],"ltp":0.0,"tv":0.0,"id":6374165}]}]}
{"op":"mcm","clk":"1006352890","pt":1580595484805,"mc":[{"id":"1.168175457","rc":[{"batb":[[0,2.9,52.24],[1,1.01,15.52],[2,1.01,0]],"batl":[[0,3.9,158.24],[1,3.9,0]],"ltp":0.0,"tv":0.0,"id":5071877},{"batb":[[0,1.4,104.34],[1,1.01,15.51],[2,1.01,0]],"batl":[[0,1.89,435.28],[1,1.89,0]],"ltp":0.0,"tv":0.0,"id":6374165}]}]}
{"op":"mcm","clk":"1006353614","pt":1580595490511,"mc":[{"id":"1.168175457","rc":[{"batb":[[1,2.82,22.58],[2,1.01,15.52]],"ltp":0.0,"tv":0.0,"id":5071877},{"batb":[[0,1.46,87.43],[1,1.43,193.3],[2,1.01,15.51]],"batl":[[0,1.53,42.01],[1,1.89,435.28]],"ltp":0.0,"tv":0.0,"id":6374165}]}]}
{"op":"mcm","clk":"1006353856","pt":1580595492501,"mc":[{"id":"1.168175457","rc":[{"batb":[[1,2.88,21.85],[2,2.82,22.58]],"batl":[[0,3.3,17.64],[1,3.9,158.24]],"ltp":0.0,"tv":0.0,"id":5071877}]}]}
{"op":"mcm","clk":"1006355318","pt":1580595505333,"mc":[{"id":"1.168175457","rc":[{"batb":[[0,2.88,21.85],[1,2.82,22.58],[2,1.01,15.52]],"ltp":0.0,"tv":0.0,"id":5071877},{"batb":[[0,1.43,193.31],[1,1.01,15.51],[2,1.01,0]],"ltp":0.0,"tv":0.0,"id":6374165}]}]}
{"op":"mcm","clk":"1006355553","pt":1580595507432,"mc":[{"id":"1.168175457","rc":[{"batb":[[0,2.82,22.58],[1,1.01,15.52],[2,1.01,0]],"batl":[[0,3.9,158.24],[1,3.9,0]],"ltp":0.0,"tv":0.0,"id":5071877},{"batb":[[0,1.43,95.84]],"batl":[[0,1.89,435.28],[1,1.89,0]],"ltp":0.0,"tv":0.0,"id":6374165}]}]}
{"op":"mcm","clk":"1006356149","pt":1580595512439,"mc":[{"id":"1.168175457","rc":[{"batb":[[0,2.84,22.69],[1,2.82,22.58],[2,2.72,24.39]],"batl":[[0,3.25,18.48],[1,3.9,158.24]],"ltp":0.0,"tv":0.0,"id":5071877},{"batb":[[0,1.48,81.37],[1,1.45,89.62],[2,1.44,94.94]],"batl":[[0,1.55,42.01],[1,1.89,435.28]],"ltp":0.0,"tv":0.0,"id":6374165}]}]}
{"op":"mcm","clk":"1006357496","pt":1580595523492,"mc":[{"id":"1.168175457","rc":[{"batb":[[0,2.82,22.58],[1,2.72,24.39],[2,1.01,15.52]],"batl":[[0,3.9,158.24],[1,3.9,0]],"ltp":0.0,"tv":0.0,"id":5071877},{"batb":[[2,1.01,15.51]],"batl":[[0,1.89,435.28],[1,1.89,0]],"ltp":0.0,"tv":0.0,"id":6374165}]}]}
{"op":"mcm","clk":"1006357868","pt":1580595526553,"mc":[{"id":"1.168175457","rc":[{"batl":[[0,3.2,18.48],[1,3.9,158.24]],"ltp":0.0,"tv":0.0,"id":5071877},{"batb":[[0,1.48,1193.88],[1,1.45,182.88]],"batl":[[0,1.56,42.01],[1,1.89,435.28]],"ltp":0.0,"tv":0.0,"id":6374165}]}]}
{"op":"mcm","clk":"1006357935","pt":1580595527178,"mc":[{"id":"1.168175457","rc":[{"batb":[[0,2.72,24.39],[1,1.01,15.52],[2,1.01,0]],"batl":[[0,3.9,158.24],[1,3.9,0]],"ltp":0.0,"tv":0.0,"id":5071877},{"batb":[[0,1.45,89.63],[1,1.01,15.51],[2,1.01,0]],"batl":[[0,1.89,435.28],[1,1.89,0]],"ltp":0.0,"tv":0.0,"id":6374165}]}]}
{"op":"mcm","clk":"1006358802","pt":1580595534370,"mc":[{"id":"1.168175457","rc":[{"batb":[[1,2.62,27.38],[2,1.01,15.52]],"batl":[[0,3.1,19.32],[1,3.9,158.24]],"ltp":0.0,"tv":0.0,"id":5071877},{"batb":[[0,1.51,76.32],[1,1.49,80.41],[2,1.01,15.52]],"ltp":0.0,"tv":0.0,"id":6374165}]}]}
{"op":"mcm","clk":"1006359275","pt":1580595538264,"mc":[{"id":"1.168175457","rc":[{"batb":[[1,2.7,24.37],[2,2.62,27.38]],"ltp":0.0,"tv":0.0,"id":5071877},{"batb":[[2,1.48,87.39]],"batl":[[0,1.6,42.01],[1,1.89,435.28]],"ltp":0.0,"tv":0.0,"id":6374165}]}]}
{"op":"mcm","clk":"1006362818","pt":1580595567544,"mc":[{"id":"1.168175457","rc":[{"batb":[[0,2.7,24.37],[1,2.62,27.38],[2,1.01,15.52]],"ltp":0.0,"tv":0.0,"id":5071877},{"batb":[[0,1.49,80.41],[1,1.48,87.39],[2,1.01,15.51]],"ltp":0.0,"tv":0.0,"id":6374165}]}]}
{"op":"mcm","clk":"1006363046","pt":1580595569214,"mc":[{"id":"1.168175457","rc":[{"batb":[[0,2.62,27.38],[1,1.01,15.52],[2,1.01,0]],"batl":[[0,3.9,158.24],[1,3.9,0]],"ltp":0.0,"tv":0.0,"id":5071877},{"batb":[[1,1.01,15.52],[2,1.01,0]],"batl":[[0,1.89,435.28],[1,1.89,0]],"ltp":0.0,"tv":0.0,"id":6374165}]}]}
{"op":"mcm","clk":"1006365319","pt":1580595589530,"mc":[{"id":"1.168175457","rc":[{"batb":[[0,2.8,22.9],[1,2.68,25.65],[2,2.62,27.38]],"ltp":0.0,"tv":0.0,"id":5071877},{"batb":[[1,1.47,84.59],[2,1.01,15.51]],"ltp":0.0,"tv":0.0,"id":6374165}]}]}
{"op":"mcm","clk":"1006365344","pt":1580595589744,"mc":[{"id":"1.168175457","rc":[{"batb":[[1,2.7,24.37],[2,2.68,25.65]],"batl":[[0,3.15,19.32],[1,3.9,158.24]],"ltp":0.0,"tv":0.0,"id":5071877},{"batb":[[1,1.47,173.65]],"batl":[[0,1.59,42.01],[1,1.89,435.28]],"ltp":0.0,"tv":0.0,"id":6374165}]}]}
{"op":"mcm","clk":"1006366907","pt":1580595604561,"mc":[{"id":"1.168175457","rc":[{"batb":[[0,2.7,24.37],[1,2.68,25.65],[2,1.01,15.52]],"ltp":0.0,"tv":0.0,"id":5071877},{"batb":[[0,1.47,173.65],[1,1.01,15.51],[2,1.01,0]],"ltp":0.0,"tv":0.0,"id":6374165}]}]}
{"op":"mcm","clk":"1006367017","pt":1580595605544,"mc":[{"id":"1.168175457","rc":[{"batb":[[0,2.68,25.65],[1,1.01,15.52],[2,1.01,0]],"batl":[[0,3.9,158.24],[1,3.9,0]],"ltp":0.0,"tv":0.0,"id":5071877},{"batb":[[0,1.47,84.59]],"batl":[[0,1.89,435.28],[1,1.89,0]],"ltp":0.0,"tv":0.0,"id":6374165}]}]}
{"op":"mcm","clk":"1006367957","pt":1580595614494,"mc":[{"id":"1.168175457","rc":[{"batb":[[1,2.66,25.21],[2,2.56,29.03]],"batl":[[0,3.05,20.16]],"ltp":0.0,"tv":0.0,"id":5071877},{"batb":[[0,1.52,73.25],[1,1.5,78.37],[2,1.49,85.7]],"batl":[[0,1.61,42.01],[1,1.89,435.28]],"ltp":0.0,"tv":0.0,"id":6374165}]}]}
{"op":"mcm","clk":"1006368147","pt":1580595616164,"mc":[{"id":"1.168175457","rc":[{"batl":[[1,3.65,170.41]],"ltp":0.0,"tv":0.0,"id":5071877}]}]}
{"op":"mcm","clk":"1006369483","pt":1580595630109,"mc":[{"id":"1.168175457","rc":[{"batb":[[0,2.66,25.21],[1,2.56,29.03],[2,1.01,15.52]],"ltp":0.0,"tv":0.0,"id":5071877},{"batb":[[0,1.5,78.37],[1,1.49,85.7],[2,1.01,15.52]],"ltp":0.0,"tv":0.0,"id":6374165}]}]}
{"op":"mcm","clk":"1006369617","pt":1580595631547,"mc":[{"id":"1.168175457","rc":[{"batb":[[0,2.56,29.03],[1,1.01,15.52],[2,1.01,0]],"batl":[[0,3.65,170.41],[1,3.65,0]],"ltp":0.0,"tv":0.0,"id":5071877},{"batb":[[1,1.01,15.52],[2,1.01,0]],"batl":[[0,1.89,435.28],[1,1.89,0]],"ltp":0.0,"tv":0.0,"id":6374165}]}]}
{"op":"mcm","clk":"1006370059","pt":1580595636470,"mc":[{"id":"1.168175457","rc":[{"batb":[[0,2.76,23.6],[1,2.7,24.37],[2,2.64,26.75]],"batl":[[0,3.1,19.32],[1,3.65,170.41]],"ltp":0.0,"tv":0.0,"id":5071877},{"batb":[[1,1.48,87.39],[2,1.47,83.09]],"batl":[[0,1.6,42.01],[1,1.89,435.28]],"ltp":0.0,"tv":0.0,"id":6374165}]}]}
{"op":"mcm","clk":"1006371265","pt":1580595649368,"mc":[{"id":"1.168175457","rc":[{"batb":[[0,2.64,26.75],[1,1.01,15.52],[2,2.64,0]],"batl":[[0,3.65,170.41],[1,3.65,0]],"ltp":0.0,"tv":0.0,"id":5071877},{"batb":[[0,1.47,83.1],[1,1.01,15.51],[2,1.47,0]],"batl":[[0,1.89,435.28],[1,1.89,0]],"ltp":0.0,"tv":0.0,"id":6374165}]}]}
{"op":"mcm","clk":"1006372765","pt":1580595664464,"mc":[{"id":"1.168175457","rc":[{"batb":[[1,2.6,26.05],[2,2.5,30.92]],"batl":[[0,3,21]],"ltp":0.0,"tv":0.0,"id":5071877},{"batb":[[0,1.54,70.74],[1,1.51,76.01],[2,1.5,84.02]],"batl":[[0,1.63,42.01]],"ltp":0.0,"tv":0.0,"id":6374165}]}]}
{"op":"mcm","clk":"1006372924","pt":1580595666078,"mc":[{"id":"1.168175457","rc":[{"batl":[[1,3.45,178.1]],"ltp":0.0,"tv":0.0,"id":5071877},{"batl":[[1,2.1,367.11]],"ltp":0.0,"tv":0.0,"id":6374165}]}]}
{"op":"mcm","clk":"1006374784","pt":1580595684523,"mc":[{"id":"1.168175457","rc":[{"batb":[[0,2.6,26.05],[1,2.5,30.92],[2,1.01,15.52]],"ltp":0.0,"tv":0.0,"id":5071877},{"batb":[[0,1.51,76.01],[1,1.5,84.02],[2,1.01,15.52]],"ltp":0.0,"tv":0.0,"id":6374165}]}]}
{"op":"mcm","clk":"1006374821","pt":1580595684892,"mc":[{"id":"1.168175457","rc":[{"batb":[[0,2.5,30.92],[1,1.01,15.52],[2,1.01,0]],"batl":[[0,3.45,178.1],[1,3.45,0]],"ltp":0.0,"tv":0.0,"id":5071877},{"batb":[[1,1.01,15.52],[2,1.01,0]],"batl":[[0,2.1,367.11],[1,2.1,0]],"ltp":0.0,"tv":0.0,"id":6374165}]}]}
{"op":"mcm","clk":"1006375072","pt":1580595687419,"mc":[{"id":"1.168175457","rc":[{"batb":[[0,2.52,30.29],[1,2.5,30.92],[2,1.01,15.52]],"ltp":0.0,"tv":0.0,"id":5071877},{"batb":[[1,1.5,77.19],[2,1.01,15.52]],"ltp":0.0,"tv":0.0,"id":6374165}]}]}
{"op":"mcm","clk":"1006375093","pt":1580595687627,"mc":[{"id":"1.168175457","rc":[{"batb":[[1,1.01,15.52],[2,1.01,0]],"ltp":0.0,"tv":0.0,"id":5071877},{"batb":[[0,1.5,77.19],[1,1.01,15.52],[2,1.01,0]],"ltp":0.0,"tv":0.0,"id":6374165}]}]}
{"op":"mcm","clk":"1006383890","pt":1580595783329,"mc":[{"id":"1.168175457","rc":[{"batb":[[0,1.01,15.52],[1,1.01,0]],"ltp":0.0,"tv":0.0,"id":5071877}]}]}
{"op":"mcm","clk":"1006384148","pt":1580595786436,"mc":[{"id":"1.168175457","rc":[{"batb":[[0,2.52,26.89],[1,2.5,30.53],[2,2.36,35.56]],"batl":[[0,2.9,21.85]],"ltp":0.0,"tv":0.0,"id":5071877},{"batb":[[0,1.58,63.18],[1,1.55,68.77],[2,1.53,96.14]],"batl":[[0,1.66,42.01]],"ltp":0.0,"tv":0.0,"id":6374165}]}]}
{"op":"mcm","clk":"1006384351","pt":1580595788412,"mc":[{"id":"1.168175457","rc":[{"batb":[[1,2.36,35.56],[2,1.01,15.52]],"ltp":0.0,"tv":0.0,"id":5071877},{"batb":[[0,1.55,68.77],[1,1.53,78.98],[2,1.01,15.52]],"ltp":0.0,"tv":0.0,"id":6374165}]}]}
{"op":"mcm","clk":"1006384437","pt":1580595789241,"mc":[{"id":"1.168175457","rc":[{"batb":[[0,2.36,35.56],[1,1.01,15.52],[2,1.01,0]],"ltp":0.0,"tv":0.0,"id":5071877},{"batb":[[1,1.01,15.52],[2,1.01,0]],"ltp":0.0,"tv":0.0,"id":6374165}]}]}
{"op":"mcm","clk":"1006385055","pt":1580595795344,"mc":[{"id":"1.168175457","rc":[{"batb":[[0,2.6,27.7],[1,2.48,31.63],[2,1.01,15.52]],"ltp":0.0,"tv":0.0,"id":5071877},{"batb":[[1,1.52,74.2],[2,1.01,15.52]],"ltp":0.0,"tv":0.0,"id":6374165}]}]}
{"op":"mcm","clk":"1006385148","pt":1580595796338,"mc":[{"id":"1.168175457","rc":[{"batl":[[0,2.94,21]],"ltp":0.0,"tv":0.0,"id":5071877},{"batb":[[1,1.52,154.86]],"ltp":0.0,"tv":0.0,"id":6374165}]}]}
{"op":"mcm","clk":"1006385266","pt":1580595797425,"mc":[{"id":"1.168175457","rc":[{"batl":[[1,3.45,178.1]],"ltp":0.0,"tv":0.0,"id":5071877},{"batl":[[0,2.1,367.11]],"ltp":0.0,"tv":0.0,"id":6374165}]}]}
{"op":"mcm","clk":"1006385385","pt":1580595798510,"mc":[{"id":"1.168175457","rc":[{"batb":[[1,2.56,26.89],[2,2.48,31.63]],"ltp":0.0,"tv":0.0,"id":5071877},{"batl":[[0,1.64,42.01],[1,2.1,367.11]],"ltp":0.0,"tv":0.0,"id":6374165}]}]}
{"op":"mcm","clk":"1006386506","pt":1580595809241,"mc":[{"id":"1.168175457","rc":[{"batb":[[0,2.48,31.63],[1,1.01,15.52],[2,2.48,0]],"batl":[[0,3.45,178.1],[1,3.45,0]],"ltp":0.0,"tv":0.0,"id":5071877},{"batb":[[0,1.52,74.2],[1,1.01,15.52],[2,1.01,0]],"batl":[[0,2.1,367.11],[1,2.1,0]],"ltp":0.0,"tv":0.0,"id":6374165}]}]}
{"op":"mcm","clk":"1006386777","pt":1580595812454,"mc":[{"id":"1.168175457","rc":[{"batb":[[0,2.48,31.39]],"ltp":0.0,"tv":0.0,"id":5071877},{"batb":[[0,1.51,74.75]],"ltp":0.0,"tv":0.0,"id":6374165}]}]}
{"op":"mcm","clk":"1006387225","pt":1580595816498,"mc":[{"id":"1.168175457","rc":[{"batb":[[0,2.7,25.02],[1,2.6,26.05],[2,2.56,28.72]],"batl":[[0,3,21],[1,3.45,178.1]],"ltp":0.0,"tv":0.0,"id":5071877},{"batb":[[1,1.5,84.02],[2,1.49,79.7]],"batl":[[0,1.63,42.01],[1,2.1,367.11]],"ltp":0.0,"tv":0.0,"id":6374165}]}]}
{"op":"mcm","clk":"1006389345","pt":1580595837306,"mc":[{"id":"1.168175457","rc":[{"batb":[[0,2.56,28.72],[1,1.01,15.52],[2,2.56,0]],"batl":[[0,3.45,178.1],[1,3.45,0]],"ltp":0.0,"tv":0.0,"id":5071877},{"batb":[[0,1.49,79.39],[1,1.01,15.52],[2,1.49,0]],"batl":[[0,2.1,367.11],[1,2.1,0]],"ltp":0.0,"tv":0.0,"id":6374165}]}]}
{"op":"mcm","clk":"1006390553","pt":1580595848960,"mc":[{"id":"1.168175457","rc":[{"batb":[[0,2.78,23.29],[1,2.7,25.26],[2,2.6,98.59]],"ltp":0.0,"tv":0.0,"id":5071877},{"batb":[[1,1.46,86.72],[2,1.01,15.51]],"ltp":0.0,"tv":0.0,"id":6374165}]}]}
{"op":"mcm","clk":"1006390699","pt":1580595850524,"mc":[{"id":"1.168175457","rc":[{"batb":[[1,2.7,49.62],[2,1.01,15.52]],"batl":[[0,3.1,19.32],[1,3.45,178.1]],"ltp":0.0,"tv":0.0,"id":5071877},{"batb":[[1,1.48,87.39],[2,1.46,86.71]],"batl":[[0,1.6,42.01],[1,2.1,367.11]],"ltp":0.0,"tv":0.0,"id":6374165}]}]}
{"op":"mcm","clk":"1006391426","pt":1580595857235,"mc":[{"id":"1.168175457","rc":[{"batb":[[1,2.76,23.53],[2,2.7,24.37]],"ltp":0.0,"tv":0.0,"id":5071877},{"batb":[[0,1.49,78.6],[2,1.46,86]],"ltp":0.0,"tv":0.0,"id":6374165}]}]}
{"op":"mcm","clk":"1006391962","pt":1580595862553,"mc":[{"id":"1.168175457","rc":[{"batb":[[1,2.7,24.37],[2,2.68,25.41]],"ltp":0.0,"tv":0.0,"id":5071877}]}]}
{"op":"mcm","clk":"1006393069","pt":1580595873367,"mc":[{"id":"1.168175457","rc":[{"batb":[[1,2.76,23.84],[2,2.7,24.37]],"ltp":0.0,"tv":0.0,"id":5071877},{"batb":[[0,1.5,77.66],[2,1.47,84.98]],"ltp":0.0,"tv":0.0,"id":6374165}]}]}
{"op":"mcm","clk":"1006398367","pt":1580595929454,"mc":[{"id":"1.168175457","rc":[{"batb":[[0,2.66,25.97],[1,1.01,15.52],[2,2.7,0]],"batl":[[0,3.45,178.1],[1,3.45,0]],"ltp":0.0,"tv":0.0,"id":5071877},{"batb":[[0,1.47,84.99],[1,1.01,15.51],[2,1.47,0]],"batl":[[0,2.1,367.11],[1,2.1,0]],"ltp":0.0,"tv":0.0,"id":6374165}]}]}
{"op":"mcm","clk":"1006403073","pt":1580595979498,"mc":[{"id":"1.168175457","rc":[{"batb":[[0,2.88,21.4],[1,2.78,23.37],[2,1.01,15.52]],"ltp":0.0,"tv":0.0,"id":5071877},{"batb":[[1,1.43,93.24],[2,1.01,15.51]],"ltp":0.0,"tv":0.0,"id":6374165}]}]}
{"op":"mcm","clk":"1006403161","pt":1580595980380,"mc":[{"id":"1.168175457","rc":[{"batb":[[2,2.74,23.53]],"batl":[[0,3.15,19.32]],"ltp":0.0,"tv":0.0,"id":5071877},{"batb":[[1,1.46,90.74],[2,1.43,93.24]],"ltp":0.0,"tv":0.0,"id":6374165}]}]}
{"op":"mcm","clk":"1006403265","pt":1580595981415,"mc":[{"id":"1.168175457","rc":[{"batl":[[1,3.9,158.24]],"ltp":0.0,"tv":0.0,"id":5071877},{"batl":[[0,1.57,42.01],[1,1.95,409.86]],"ltp":0.0,"tv":0.0,"id":6374165}]}]}
{"op":"mcm","clk":"1006404544","pt":1580595993409,"mc":[{"id":"1.168175457","rc":[{"batb":[[0,2.78,23.37],[1,1.01,15.52],[2,2.74,0]],"batl":[[0,3.9,158.24],[1,3.9,0]],"ltp":0.0,"tv":0.0,"id":5071877},{"batb":[[0,1.43,93.25],[1,1.01,15.51],[2,1.43,0]],"batl":[[0,1.95,409.86],[1,1.95,0]],"ltp":0.0,"tv":0.0,"id":6374165}]}]}
{"op":"mcm","clk":"1006405714","pt":1580596004525,"mc":[{"id":"1.168175457","rc":[{"batb":[[0,3,48.15],[1,2.88,21.24],[2,2.84,22.69]],"batl":[[0,3.25,18.48],[1,3.9,158.24]],"ltp":0.0,"tv":0.0,"id":5071877},{"batb":[[0,1.44,94.95],[1,1.43,93.24],[2,1.41,101.74]],"batl":[[0,1.55,42.01],[1,1.95,409.86]],"ltp":0.0,"tv":0.0,"id":6374165}]}]}
{"op":"mcm","clk":"1006408150","pt":1580596027421,"mc":[{"id":"1.168175457","rc":[{"batb":[[0,2.88,21.24],[1,1.01,15.52],[2,2.84,0]],"batl":[[0,3.9,158.24],[1,3.9,0]],"ltp":0.0,"tv":0.0,"id":5071877},{"batb":[[0,1.41,101.75],[1,1.01,15.51],[2,1.41,0]],"batl":[[0,1.95,409.86],[1,1.95,0]],"ltp":0.0,"tv":0.0,"id":6374165}]}]}
{"op":"mcm","clk":"1006408488","pt":1580596030556,"mc":[{"id":"1.168175457","rc":[{"batb":[[0,2.9,51.85]],"ltp":0.0,"tv":0.0,"id":5071877},{"batb":[[0,1.4,103.48]],"ltp":0.0,"tv":0.0,"id":6374165}]}]}
{"op":"mcm","clk":"1006408792","pt":1580596033541,"mc":[{"id":"1.168175457","rc":[{"batb":[[1,2.82,22.5],[2,1.01,15.52]],"ltp":0.0,"tv":0.0,"id":5071877},{"batb":[[0,1.45,87.98],[1,1.42,97.33],[2,1.01,15.51]],"ltp":0.0,"tv":0.0,"id":6374165}]}]}
{"op":"mcm","clk":"1006408884","pt":1580596034430,"mc":[{"id":"1.168175457","rc":[{"batb":[[0,1.45,181.24]],"batl":[[0,1.56,42.01],[1,1.95,409.86]],"ltp":0.0,"tv":0.0,"id":6374165}]}]}
{"op":"mcm","clk":"1006409113","pt":1580596036257,"mc":[{"id":"1.168175457","rc":[{"batb":[[2,2.8,22.69]],"batl":[[0,3.2,18.48],[1,3.9,158.24]],"ltp":0.0,"tv":0.0,"id":5071877}]}]}
{"op":"mcm","clk":"1006409763","pt":1580596043062,"mc":[{"id":"1.168175457","rc":[{"batl":[[0,3.2,551.91]],"ltp":0.0,"tv":0.0,"id":5071877}]}]}
{"op":"mcm","clk":"1006410370","pt":1580596049551,"mc":[{"id":"1.168175457","rc":[{"batb":[[0,2.82,22.5],[1,1.01,15.52],[2,2.8,0]],"batl":[[0,3.9,158.24],[1,3.9,0]],"ltp":0.0,"tv":0.0,"id":5071877},{"batb":[[0,1.42,97.34],[1,1.01,15.51],[2,1.01,0]],"batl":[[0,1.95,409.86],[1,1.95,0]],"ltp":0.0,"tv":0.0,"id":6374165}]}]}
{"op":"mcm","clk":"1006412342","pt":1580596069562,"mc":[{"id":"1.168175457","rc":[{"batb":[[0,3.05,45.56],[1,2.96,49.81],[2,1.01,15.52]],"ltp":0.0,"tv":0.0,"id":5071877},{"batb":[[1,1.39,106.85],[2,1.01,15.51]],"ltp":0.0,"tv":0.0,"id":6374165}]}]}
{"op":"mcm","clk":"1006412478","pt":1580596070496,"mc":[{"id":"1.168175457","rc":[{"batb":[[2,2.88,21.85]],"batl":[[0,3.3,17.64],[1,3.9,158.24]],"ltp":0.0,"tv":0.0,"id":5071877},{"batb":[[0,1.43,97.47],[1,1.42,97.33],[2,1.39,106.85]],"batl":[[0,1.54,42.01],[1,1.95,409.86]],"ltp":0.0,"tv":0.0,"id":6374165}]}]}
{"op":"mcm","clk":"1006413725","pt":1580596080393,"mc":[{"id":"1.168175457","rc":[{"batb":[[0,2.96,49.81],[1,2.88,21.85],[2,1.01,15.52]],"ltp":0.0,"tv":0.0,"id":5071877},{"batb":[[1,1.39,106.85],[2,1.01,15.51]],"ltp":0.0,"tv":0.0,"id":6374165}]}]}
{"op":"mcm","clk":"1006413871","pt":1580596081535,"mc":[{"id":"1.168175457","rc":[{"batb":[[1,1.01,15.52],[2,1.01,0]],"batl":[[0,3.9,158.24],[1,3.9,0]],"ltp":0.0,"tv":0.0,"id":5071877},{"batb":[[0,1.39,106.86],[1,1.01,15.51],[2,1.01,0]],"batl":[[0,1.95,409.86],[1,1.95,0]],"ltp":0.0,"tv":0.0,"id":6374165}]}]}
{"op":"mcm","clk":"1006414844","pt":1580596089386,"mc":[{"id":"1.168175457","rc":[{"trd":[[3.1,0]],"batb":[[0,3.2,40.36],[1,3.05,61.37],[2,1.01,15.52]],"ltp":3.1,"tv":0.0,"id":5071877},{"trd":[[1.48,0.01]],"batb":[[0,1.39,106.85],[1,1.37,113.85],[2,1.01,15.51]],"ltp":1.48,"tv":0.01,"id":6374165}],"tv":0.01}]}
{"op":"mcm","clk":"1006414943","pt":1580596090434,"mc":[{"id":"1.168175457","rc":[{"batl":[[0,3.6,15.96],[1,3.9,158.24]],"ltp":3.1,"tv":0.0,"id":5071877},{"batb":[[1,1.38,110.07],[2,1.37,113.85]],"ltp":1.48,"tv":0.01,"id":6374165}]}]}
{"op":"mcm","clk":"1006415217","pt":1580596092406,"mc":[{"id":"1.168175457","rc":[{"batb":[[1,3.1,19.32],[2,3.05,61.37]],"ltp":3.1,"tv":0.0,"id":5071877},{"batl":[[0,1.48,42.01],[1,1.95,409.86]],"ltp":1.48,"tv":0.01,"id":6374165}]}]}
{"op":"mcm","clk":"1006418042","pt":1580596116553,"mc":[{"id":"1.168175457","rc":[{"batb":[[0,3.1,19.32],[1,3.05,45.48],[2,1.01,15.52]],"ltp":3.1,"tv":0.0,"id":5071877},{"batb":[[0,1.38,110.07],[1,1.37,113.85],[2,1.01,15.51]],"ltp":1.48,"tv":0.01,"id":6374165}]}]}
{"op":"mcm","clk":"1006418106","pt":1580596117193,"mc":[{"id":"1.168175457","rc":[{"batb":[[0,3.05,45.48],[1,1.01,15.52],[2,1.01,0]],"batl":[[0,3.9,158.24],[1,3.9,0]],"ltp":3.1,"tv":0.0,"id":5071877},{"batb":[[0,1.37,113.85],[1,1.01,15.51],[2,1.01,0]],"batl":[[0,1.95,409.86],[1,1.95,0]],"ltp":1.48,"tv":0.01,"id":6374165}]}]}
{"op":"mcm","clk":"1006419231","pt":1580596128157,"mc":[{"id":"1.168175457","rc":[{"batb":[[0,3.15,19.32],[1,3.05,45.48],[2,1.01,15.52]],"batl":[[0,3.7,15.12]],"ltp":3.1,"tv":0.0,"id":5071877},{"batb":[[0,1.37,227.28]],"batl":[[0,1.47,42.01]],"ltp":1.48,"tv":0.01,"id":6374165}]}]}
{"op":"mcm","clk":"1006419315","pt":1580596128941,"mc":[{"id":"1.168175457","rc":[{"batb":[[0,3.3,37.14],[1,3.15,61.81]],"ltp":3.1,"tv":0.0,"id":5071877},{"batb":[[1,1.35,120.3],[2,1.01,15.51]],"ltp":1.48,"tv":0.01,"id":6374165}]}]}
{"op":"mcm","clk":"1006419698","pt":1580596132267,"mc":[{"id":"1.168175457","rc":[{"batl":[[1,4.6,136.05]],"ltp":3.1,"tv":0.0,"id":5071877},{"batl":[[1,1.82,469.11]],"ltp":1.48,"tv":0.01,"id":6374165}]}]}
{"op":"mcm","clk":"1006420728","pt":1580596142475,"mc":[{"id":"1.168175457","rc":[{"batb":[[0,3.15,61.81],[1,1.01,15.52],[2,1.01,0]],"ltp":3.1,"tv":0.0,"id":5071877},{"batb":[[0,1.37,113.43]],"ltp":1.48,"tv":0.01,"id":6374165}]}]}
{"op":"mcm","clk":"1006420806","pt":1580596143201,"mc":[{"id":"1.168175457","rc":[{"batb":[[0,3.15,42.49]],"batl":[[0,4.6,136.05],[1,4.6,0]],"ltp":3.1,"tv":0.0,"id":5071877},{"batb":[[0,1.35,120.3],[1,1.01,15.51],[2,1.01,0]],"batl":[[0,1.82,469.11],[1,1.82,0]],"ltp":1.48,"tv":0.01,"id":6374165}]}]}
{"op":"mcm","clk":"1006422303","pt":1580596154497,"mc":[{"id":"1.168175457","rc":[{"batb":[[1,3.1,19.32],[2,2.98,48.47]],"batl":[[0,3.6,15.96]],"ltp":3.1,"tv":0.0,"id":5071877},{"batb":[[0,1.4,102.68],[1,1.39,107.54],[2,1.38,109.13]],"batl":[[0,1.49,42.01],[1,1.82,469.11]],"ltp":1.48,"tv":0.01,"id":6374165}]}]}
{"op":"mcm","clk":"1006422516","pt":1580596156008,"mc":[{"id":"1.168175457","rc":[{"batl":[[1,4.2,148.03]],"ltp":3.1,"tv":0.0,"id":5071877}]}]}
{"op":"mcm","clk":"1006422994","pt":1580596160516,"mc":[{"id":"1.168175457","rc":[{"batb":[[0,1.4,1421.34]],"ltp":1.48,"tv":0.01,"id":6374165}]}]}
{"op":"mcm","clk":"1006424243","pt":1580596172520,"mc":[{"id":"1.168175457","rc":[{"batb":[[0,1.4,102.68]],"ltp":1.48,"tv":0.01,"id":6374165}]}]}
{"op":"mcm","clk":"1006424333","pt":1580596173319,"mc":[{"id":"1.168175457","rc":[{"batb":[[0,2.98,48.47],[1,1.01,15.52],[2,2.98,0]],"batl":[[0,4.2,148.03],[1,4.2,0]],"ltp":3.1,"tv":0.0,"id":5071877},{"batb":[[0,1.38,109.13],[1,1.01,15.51],[2,1.38,0]],"batl":[[0,1.82,469.11],[1,1.82,0]],"ltp":1.48,"tv":0.01,"id":6374165}]}]}
{"op":"mcm","clk":"1006425958","pt":1580596189546,"mc":[{"id":"1.168175457","rc":[{"batb":[[0,3.25,39.26],[1,3.05,45.01],[2,3,85.57]],"ltp":3.1,"tv":0.0,"id":5071877},{"batb":[[1,1.37,115.82],[2,1.01,15.51]],"ltp":1.48,"tv":0.01,"id":6374165}]}]}
{"op":"mcm","clk":"1006426065","pt":1580596190539,"mc":[{"id":"1.168175457","rc":[{"batb":[[1,3.1,19.32],[2,3.05,45.01]],"batl":[[0,3.65,15.12],[1,4.2,148.03]],"ltp":3.1,"tv":0.0,"id":5071877},{"batb":[[0,1.38,219.2]],"batl":[[0,1.48,42.01],[1,1.82,469.11]],"ltp":1.48,"tv":0.01,"id":6374165}]}]}
{"op":"mcm","clk":"1006428475","pt":1580596213443,"mc":[{"id":"1.168175457","rc":[{"batb":[[0,3.05,45.01],[1,1.01,15.52],[2,3.05,0]],"batl":[[0,4.2,148.03],[1,4.2,0]],"ltp":3.1,"tv":0.0,"id":5071877},{"batb":[[0,1.37,115.82],[1,1.01,15.51],[2,1.01,0]],"batl":[[0,1.82,469.11],[1,1.82,0]],"ltp":1.48,"tv":0.01,"id":6374165}]}]}
{"op":"mcm","clk":"1006431238","pt":1580596238486,"mc":[{"id":"1.168175457","rc":[{"batb":[[1,2.92,51.54],[2,1.01,15.52]],"ltp":3.1,"tv":0.0,"id":5071877},{"batb":[[0,1.42,98.27],[1,1.39,106.22],[2,1.38,1035.38]],"batl":[[0,1.49,42.01],[1,1.82,469.11]],"ltp":1.48,"tv":0.01,"id":6374165}]}]}
{"op":"mcm","clk":"1006431345","pt":1580596239525,"mc":[{"id":"1.168175457","rc":[{"batb":[[2,1.01,15.51]],"ltp":1.48,"tv":0.01,"id":6374165}]}]}
{"op":"mcm","clk":"1006431583","pt":1580596241507,"mc":[{"id":"1.168175457","rc":[{"batb":[[1,3,21],[2,2.92,51.54]],"batl":[[0,3.5,16.8],[1,4.2,148.03]],"ltp":3.1,"tv":0.0,"id":5071877},{"batb":[[1,1.4,105.02],[2,1.39,106.22]],"ltp":1.48,"tv":0.01,"id":6374165}]}]}
{"op":"mcm","clk":"1006432105","pt":1580596245523,"mc":[{"id":"1.168175457","rc":[{"batb":[[0,3,21],[1,2.92,51.54],[2,1.01,15.52]],"ltp":3.1,"tv":0.0,"id":5071877},{"batb":[[0,1.4,105.02],[1,1.39,106.22],[2,1.01,15.51]],"ltp":1.48,"tv":0.01,"id":6374165}]}]}
{"op":"mcm","clk":"1006432554","pt":1580596249016,"mc":[{"id":"1.168175457","rc":[{"batb":[[0,1.41,1297.67],[1,1.4,105.02],[2,1.39,106.22]],"ltp":1.48,"tv":0.01,"id":6374165}]}]}
{"op":"mcm","clk":"1006434246","pt":1580596264532,"mc":[{"id":"1.168175457","rc":[{"batb":[[0,1.4,105.02],[1,1.39,106.22],[2,1.01,15.51]],"ltp":1.48,"tv":0.01,"id":6374165}]}]}
{"op":"mcm","clk":"1006434339","pt":1580596265413,"mc":[{"id":"1.168175457","rc":[{"batb":[[0,2.92,51.54],[1,1.01,15.52],[2,1.01,0]],"batl":[[0,4.2,148.03],[1,4.2,0]],"ltp":3.1,"tv":0.0,"id":5071877},{"batb":[[0,1.39,106.22],[1,1.01,15.51],[2,1.01,0]],"batl":[[0,1.82,469.11],[1,1.82,0]],"ltp":1.48,"tv":0.01,"id":6374165}]}]}
{"op":"mcm","clk":"1006436681","pt":1580596287456,"mc":[{"id":"1.168175457","rc":[{"batb":[[0,3.2,40.68],[1,3,47.21],[2,2.98,19.76]],"ltp":3.1,"tv":0.0,"id":5071877},{"batb":[[1,1.37,113.46],[2,1.01,15.51]],"ltp":1.48,"tv":0.01,"id":6374165}]}]}
{"op":"mcm","clk":"1006436797","pt":1580596288546,"mc":[{"id":"1.168175457","rc":[{"batb":[[1,3.05,20.16],[2,3,47.21]],"batl":[[0,3.55,15.96],[1,4.2,148.03]],"ltp":3.1,"tv":0.0,"id":5071877},{"batb":[[0,1.39,213.77]],"batl":[[0,1.49,42.01],[1,1.82,469.11]],"ltp":1.48,"tv":0.01,"id":6374165}]}]}
{"op":"mcm","clk":"1006439523","pt":1580596313280,"mc":[{"id":"1.168175457","rc":[{"batb":[[0,3,47.21],[1,1.01,15.52],[2,3,0]],"batl":[[0,4.2,148.03],[1,4.2,0]],"ltp":3.1,"tv":0.0,"id":5071877},{"batb":[[0,1.37,113.46],[1,1.01,15.51],[2,1.01,0]],"batl":[[0,1.82,469.11],[1,1.82,0]],"ltp":1.48,"tv":0.01,"id":6374165}]}]}
{"op":"mcm","clk":"1006440510","pt":1580596322319,"mc":[{"id":"1.168175457","rc":[{"batb":[[0,3.3,37.3],[1,3.2,40.6],[2,3.15,19.32]],"batl":[[0,3.7,15.12],[1,4.2,148.03]],"ltp":3.1,"tv":0.0,"id":5071877},{"batb":[[0,1.37,226.89],[1,1.35,122.67],[2,1.01,15.51]],"batl":[[0,1.47,42.01],[1,1.82,469.11]],"ltp":1.48,"tv":0.01,"id":6374165}]}]}
{"op":"mcm","clk":"1006442955","pt":1580596344336,"mc":[{"id":"1.168175457","rc":[{"batl":[[1,4.2,0]],"ltp":3.1,"tv":0.0,"id":5071877},{"batl":[[1,1.82,0]],"ltp":1.48,"tv":0.01,"id":6374165}]}]}
{"op":"mcm","clk":"1006443349","pt":1580596347546,"mc":[{"id":"1.168175457","rc":[{"batl":[[0,3.65,528.5],[1,3.7,15.12]],"ltp":3.1,"tv":0.0,"id":5071877}]}]}
{"op":"mcm","clk":"1006444361","pt":1580596356432,"mc":[{"id":"1.168175457","rc":[{"batb":[[0,1.37,226.73],[1,1.35,122.51]],"ltp":1.48,"tv":0.01,"id":6374165}]}]}
{"op":"mcm","clk":"1006448964","pt":1580596398275,"mc":[{"id":"1.168175457","rc":[{"batb":[[0,3.2,40.6],[1,3.15,19.32],[2,1.01,15.52]],"batl":[[0,3.7,15.12],[1,3.7,0]],"ltp":3.1,"tv":0.0,"id":5071877},{"batb":[[0,1.37,113.43]],"ltp":1.48,"tv":0.01,"id":6374165}]}]}
{"op":"mcm","clk":"1006449072","pt":1580596399369,"mc":[{"id":"1.168175457","rc":[{"batb":[[1,1.01,15.52],[2,1.01,0]],"ltp":3.1,"tv":0.0,"id":5071877},{"batb":[[0,1.35,122.51],[1,1.01,15.51],[2,1.01,0]],"ltp":1.48,"tv":0.01,"id":6374165}]}]}
{"op":"mcm","clk":"1006449599","pt":1580596404370,"mc":[{"id":"1.168175457","rc":[{"batb":[[1,3.1,19.32],[2,3.05,44.69]],"batl":[[0,3.6,15.96]],"ltp":3.1,"tv":0.0,"id":5071877},{"batb":[[0,1.39,106.3],[1,1.38,110.07],[2,1.37,115.03]],"batl":[[0,1.48,42.01]],"ltp":1.48,"tv":0.01,"id":6374165}]}]}
{"op":"mcm","clk":"1006450555","pt":1580596413395,"mc":[{"id":"1.168175457","rc":[{"batb":[[0,3.05,44.69],[1,1.01,15.52],[2,3.05,0]],"ltp":3.1,"tv":0.0,"id":5071877},{"batb":[[0,1.37,115.03],[1,1.01,15.51],[2,1.37,0]],"ltp":1.48,"tv":0.01,"id":6374165}]}]}
{"op":"mcm","clk":"1006453368","pt":1580596439447,"mc":[{"id":"1.168175457","rc":[{"batb":[[0,3.3,36.59],[1,3.2,40.36],[2,3.05,128.78]],"ltp":3.1,"tv":0.0,"id":5071877},{"batb":[[1,1.34,125.34],[2,1.01,15.51]],"ltp":1.48,"tv":0.01,"id":6374165}]}]}
{"op":"mcm","clk":"1006453465","pt":1580596440431,"mc":[{"id":"1.168175457","rc":[{"batb":[[2,3.15,19.32]],"batl":[[0,3.7,15.12]],"ltp":3.1,"tv":0.0,"id":5071877},{"batb":[[0,1.37,228.46]],"batl":[[0,1.46,42.01]],"ltp":1.48,"tv":0.01,"id":6374165}]}]}
{"op":"mcm","clk":"1006455564","pt":1580596459368,"mc":[{"id":"1.168175457","rc":[{"batb":[[0,3.2,40.36],[1,1.01,15.52],[2,3.15,0]],"ltp":3.1,"tv":0.0,"id":5071877},{"batb":[[0,1.34,125.34],[1,1.01,15.51],[2,1.01,0]],"ltp":1.48,"tv":0.01,"id":6374165}]}]}
{"op":"mcm","clk":"1006455806","pt":1580596461482,"mc":[{"id":"1.168175457","rc":[{"batb":[[1,3.15,42.02],[2,1.01,15.52]],"ltp":3.1,"tv":0.0,"id":5071877},{"batb":[[0,1.35,121.56],[1,1.34,125.34],[2,1.01,15.51]],"ltp":1.48,"tv":0.01,"id":6374165}]}]}
{"op":"mcm","clk":"1006455874","pt":1580596462003,"mc":[{"id":"1.168175457","rc":[{"batb":[[0,3.15,42.02],[1,1.01,15.52],[2,1.01,0]],"ltp":3.1,"tv":0.0,"id":5071877},{"batb":[[1,1.01,15.51],[2,1.01,0]],"ltp":1.48,"tv":0.01,"id":6374165}]}]}
{"op":"mcm","clk":"1006456631","pt":1580596468532,"mc":[{"id":"1.168175457","rc":[{"batb":[[0,3.15,61.34],[1,3.05,46.19],[2,1.01,15.52]],"batl":[[0,3.65,15.12]],"ltp":3.1,"tv":0.0,"id":5071877},{"batb":[[0,1.4,103.55],[1,1.38,110.07],[2,1.37,112.91]],"batl":[[0,1.47,42.01]],"ltp":1.48,"tv":0.01,"id":6374165}]}]}
{"op":"mcm","clk":"1006458602","pt":1580596485434,"mc":[{"id":"1.168175457","rc":[{"batb":[[0,3.05,46.19],[1,1.01,15.52],[2,1.01,0]],"ltp":3.1,"tv":0.0,"id":5071877},{"batb":[[0,1.37,112.91],[1,1.01,15.51],[2,1.37,0]],"ltp":1.48,"tv":0.01,"id":6374165}]}]}
{"op":"mcm","clk":"1006459171","pt":1580596490432,"mc":[{"id":"1.168175457","rc":[{"batb":[[0,3.1,19.32],[1,3.05,46.19],[2,1.01,15.52]],"batl":[[0,3.6,15.96]],"ltp":3.1,"tv":0.0,"id":5071877},{"batb":[[0,1.39,107.54],[1,1.37,112.91],[2,1.01,15.51]],"batl":[[0,1.49,42.01]],"ltp":1.48,"tv":0.01,"id":6374165}]}]}
{"op":"mcm","clk":"1006459253","pt":1580596491163,"mc":[{"id":"1.168175457","rc":[{"batb":[[2,2.94,49.96]],"ltp":3.1,"tv":0.0,"id":5071877},{"batb":[[0,1.42,96.31],[1,1.39,212.82]],"ltp":1.48,"tv":0.01,"id":6374165}]}]}
{"op":"mcm","clk":"1006460671","pt":1580596503846,"mc":[{"id":"1.168175457","rc":[{"batb":[[1,2.94,49.96],[2,1.01,15.52]],"ltp":3.1,"tv":0.0,"id":5071877},{"batb":[[0,1.39,212.82],[1,1.01,15.51],[2,1.01,0]],"ltp":1.48,"tv":0.01,"id":6374165}]}]}
{"op":"mcm","clk":"1006460852","pt":1580596505378,"mc":[{"id":"1.168175457","rc":[{"batb":[[0,2.94,49.96],[1,1.01,15.52],[2,1.01,0]],"ltp":3.1,"tv":0.0,"id":5071877},{"batb":[[0,1.39,105.28]],"ltp":1.48,"tv":0.01,"id":6374165}]}]}
{"op":"mcm","clk":"1006461529","pt":1580596511501,"mc":[{"id":"1.168175457","rc":[{"batb":[[1,2.82,22.58],[2,1.01,15.52]],"ltp":3.1,"tv":0.0,"id":5071877},{"batb":[[0,1.44,90.56],[1,1.42,96.31],[2,1.01,15.51]],"ltp":1.48,"tv":0.01,"id":6374165}]}]}
{"op":"mcm","clk":"1006461627","pt":1580596512390,"mc":[{"id":"1.168175457","rc":[{"batb":[[0,2.94,70.97]],"batl":[[0,3.45,16.8]],"ltp":3.1,"tv":0.0,"id":5071877},{"batb":[[2,1.41,101.66]],"batl":[[0,1.51,42.01]],"ltp":1.48,"tv":0.01,"id":6374165}]}]}
{"op":"mcm","clk":"1006464791","pt":1580596542040,"mc":[{"id":"1.168175457","rc":[{"batb":[[0,2.94,21]],"ltp":3.1,"tv":0.0,"id":5071877},{"batb":[[0,1.42,96.31],[1,1.41,101.66],[2,1.01,15.51]],"ltp":1.48,"tv":0.01,"id":6374165}]}]}
{"op":"mcm","clk":"1006464932","pt":1580596543442,"mc":[{"id":"1.168175457","rc":[{"batb":[[0,2.82,22.58],[1,1.01,15.52],[2,1.01,0]],"ltp":3.1,"tv":0.0,"id":5071877},{"batb":[[1,1.01,15.51],[2,1.01,0]],"ltp":1.48,"tv":0.01,"id":6374165}]}]}
{"op":"mcm","clk":"1006465107","pt":1580596545458,"mc":[{"id":"1.168175457","rc":[{"batb":[[0,2.86,21.64]],"ltp":3.1,"tv":0.0,"id":5071877},{"batb":[[0,1.41,99.22]],"ltp":1.48,"tv":0.01,"id":6374165}]}]}
{"op":"mcm","clk":"1006465437","pt":1580596548439,"mc":[{"id":"1.168175457","rc":[{"batb":[[0,2.98,21],[1,2.86,21.64],[2,1.01,15.52]],"batl":[[0,3.5,16.8]],"ltp":3.1,"tv":0.0,"id":5071877},{"batb":[[1,1.4,105.02],[2,1.01,15.51]],"batl":[[0,1.5,42.01]],"ltp":1.48,"tv":0.01,"id":6374165}]}]}
{"op":"mcm","clk":"1006465538","pt":1580596549347,"mc":[{"id":"1.168175457","rc":[{"batb":[[0,3.05,44.46],[1,3,21],[2,2.92,50.91]],"ltp":3.1,"tv":0.0,"id":5071877},{"batb":[[2,1.39,105.83]],"batl":[[1,1.51,30.5]],"ltp":1.48,"tv":0.01,"id":6374165}]}]}
{"op":"mcm","clk":"1006466893","pt":1580596561499,"mc":[{"id":"1.168175457","rc":[{"batb":[[0,2.92,50.91],[1,1.01,15.52],[2,2.92,0]],"ltp":3.1,"tv":0.0,"id":5071877},{"batb":[[0,1.39,105.83],[1,1.01,15.51],[2,1.39,0]],"ltp":1.48,"tv":0.01,"id":6374165}]}]}
{"op":"mcm","clk":"1006468647","pt":1580596577295,"mc":[{"id":"1.168175457","rc":[{"batb":[[1,2.8,22.74],[2,1.01,15.52]],"ltp":3.1,"tv":0.0,"id":5071877},{"batb":[[0,1.45,89.15],[1,1.43,95.76],[2,1.01,15.51]],"ltp":1.48,"tv":0.01,"id":6374165}]}]}
{"op":"mcm","clk":"1006468775","pt":1580596578491,"mc":[{"id":"1.168175457","rc":[{"batb":[[1,2.9,21.85],[2,2.8,22.74]],"batl":[[0,3.4,16.8]],"ltp":3.1,"tv":0.0,"id":5071877},{"batb":[[2,1.42,99.98]],"batl":[[0,1.52,42.01]],"ltp":1.48,"tv":0.01,"id":6374165}]}]}
{"op":"mcm","clk":"1006468993","pt":1580596580514,"mc":[{"id":"1.168175457","rc":[{"batl":[[1,3.9,158.24]],"ltp":3.1,"tv":0.0,"id":5071877}]}]}
{"op":"mcm","clk":"1006470667","pt":1580596596476,"mc":[{"id":"1.168175457","rc":[{"batb":[[0,2.9,21.85],[1,2.8,22.74],[2,1.01,15.52]],"ltp":3.1,"tv":0.0,"id":5071877},{"batb":[[0,1.43,95.76],[1,1.42,99.98],[2,1.01,15.51]],"ltp":1.48,"tv":0.01,"id":6374165}]}]}
{"op":"mcm","clk":"1006470757","pt":1580596597464,"mc":[{"id":"1.168175457","rc":[{"batb":[[0,2.8,22.74],[1,1.01,15.52],[2,1.01,0]],"batl":[[0,3.9,158.24],[1,3.9,0]],"ltp":3.1,"tv":0.0,"id":5071877},{"batb":[[1,1.01,15.51],[2,1.01,0]],"ltp":1.48,"tv":0.01,"id":6374165}]}]}
{"op":"mcm","clk":"1006474543","pt":1580596636400,"mc":[{"id":"1.168175457","rc":[{"batb":[[0,2.82,22.69],[1,2.8,22.74],[2,2.66,25.89]],"batl":[[0,3.3,17.64],[1,3.9,158.24]],"ltp":3.1,"tv":0.0,"id":5071877},{"batb":[[0,1.48,80.81],[1,1.46,86.31],[2,1.44,94.94]],"batl":[[0,1.55,42.01]],"ltp":1.48,"tv":0.01,"id":6374165}]}]}
{"op":"mcm","clk":"1006475620","pt":1580596648539,"mc":[{"id":"1.168175457","rc":[{"batl":[[1,3.9,0]],"ltp":3.1,"tv":0.0,"id":5071877}]}]}
{"op":"mcm","clk":"1006476086","pt":1580596653454,"mc":[{"id":"1.168175457","rc":[{"batl":[[1,3.9,158.24]],"ltp":3.1,"tv":0.0,"id":5071877},{"batl":[[1,1.95,409.86]],"ltp":1.48,"tv":0.01,"id":6374165}]}]}
{"op":"mcm","clk":"1006476170","pt":1580596654240,"mc":[{"id":"1.168175457","rc":[{"batl":[[1,3.9,0]],"ltp":3.1,"tv":0.0,"id":5071877}]}]}
{"op":"mcm","clk":"1006476604","pt":1580596658476,"mc":[{"id":"1.168175457","rc":[{"batl":[[1,3.65,170.41]],"ltp":3.1,"tv":0.0,"id":5071877}]}]}
{"op":"mcm","clk":"1006476917","pt":1580596661527,"mc":[{"id":"1.168175457","rc":[{"batb":[[0,2.66,25.89],[1,1.01,15.52],[2,2.66,0]],"batl":[[0,3.65,170.41],[1,3.65,0]],"ltp":3.1,"tv":0.0,"id":5071877},{"batb":[[0,1.46,86.31],[1,1.01,15.51],[2,1.44,0]],"batl":[[0,1.95,409.86],[1,1.95,0]],"ltp":1.48,"tv":0.01,"id":6374165}]}]}
{"op":"mcm","clk":"1006477173","pt":1580596664229,"mc":[{"id":"1.168175457","rc":[{"batb":[[0,2.7,25.18]],"ltp":3.1,"tv":0.0,"id":5071877},{"batb":[[0,1.45,88.28]],"ltp":1.48,"tv":0.01,"id":6374165}]}]}
{"op":"mcm","clk":"1006478449","pt":1580596676541,"mc":[{"id":"1.168175457","rc":[{"batb":[[0,2.74,23.53],[1,2.7,25.18],[2,2.58,28.56]],"batl":[[0,3.15,19.32],[1,3.65,170.41]],"ltp":3.1,"tv":0.0,"id":5071877},{"batb":[[0,1.52,74.43],[1,1.49,78.92],[2,1.46,90.74]],"batl":[[0,1.58,42.01],[1,1.95,409.86]],"ltp":1.48,"tv":0.01,"id":6374165}]}]}
{"op":"mcm","clk":"1006479870","pt":1580596689465,"mc":[{"id":"1.168175457","rc":[{"batl":[[1,3.65,0]],"ltp":3.1,"tv":0.0,"id":5071877}]}]}
{"op":"mcm","clk":"1006480262","pt":1580596693143,"mc":[{"id":"1.168175457","rc":[{"batl":[[1,3.45,180.4]],"ltp":3.1,"tv":0.0,"id":5071877}]}]}
{"op":"mcm","clk":"1006480800","pt":1580596698530,"mc":[{"id":"1.168175457","rc":[{"batb":[[1,2.58,28.56],[2,1.01,15.52]],"ltp":3.1,"tv":0.0,"id":5071877},{"batb":[[0,1.49,78.92],[1,1.46,90.74],[2,1.01,15.51]],"ltp":1.48,"tv":0.01,"id":6374165}]}]}
{"op":"mcm","clk":"1006480909","pt":1580596699569,"mc":[{"id":"1.168175457","rc":[{"batb":[[0,2.58,28.56],[1,1.01,15.52],[2,1.01,0]],"batl":[[0,3.45,180.4],[1,3.45,0]],"ltp":3.1,"tv":0.0,"id":5071877},{"batb":[[1,1.01,15.51],[2,1.01,0]],"batl":[[0,1.95,409.86],[1,1.95,0]],"ltp":1.48,"tv":0.01,"id":6374165}]}]}
{"op":"mcm","clk":"1006481585","pt":1580596706429,"mc":[{"id":"1.168175457","rc":[{"batb":[[0,2.76,23.53],[1,2.58,28.56],[2,1.01,15.52]],"batl":[[0,3.2,18.48],[1,3.45,180.4]],"ltp":3.1,"tv":0.0,"id":5071877},{"batb":[[1,1.46,90.74],[2,1.01,15.51]],"batl":[[0,1.57,42.01],[1,1.95,409.86]],"ltp":1.48,"tv":0.01,"id":6374165}]}]}
{"op":"mcm","clk":"1006481674","pt":1580596707310,"mc":[{"id":"1.168175457","rc":[{"batb":[[0,2.78,23.37],[1,2.76,23.53],[2,2.64,26.59]],"ltp":3.1,"tv":0.0,"id":5071877},{"batb":[[1,1.47,85.13]],"ltp":1.48,"tv":0.01,"id":6374165}]}]}
{"op":"mcm","clk":"1006481902","pt":1580596709504,"mc":[{"id":"1.168175457","rc":[{"batb":[[2,1.45,93.26]],"ltp":1.48,"tv":0.01,"id":6374165}]}]}
{"op":"mcm","clk":"1006483337","pt":1580596723536,"mc":[{"id":"1.168175457","rc":[{"batb":[[0,2.64,26.59],[1,1.01,15.52],[2,2.64,0]],"batl":[[0,3.45,180.4],[1,3.45,0]],"ltp":3.1,"tv":0.0,"id":5071877},{"batb":[[0,1.47,85.13],[1,1.01,15.51],[2,1.45,0]],"batl":[[0,1.95,409.86],[1,1.95,0]],"ltp":1.48,"tv":0.01,"id":6374165}]}]}
{"op":"mcm","clk":"1006483644","pt":1580596726544,"mc":[{"id":"1.168175457","rc":[{"batb":[[1,1.46,85.61],[2,1.01,15.51]],"ltp":1.48,"tv":0.01,"id":6374165}]}]}
{"op":"mcm","clk":"1006483666","pt":1580596726755,"mc":[{"id":"1.168175457","rc":[{"batb":[[0,2.64,26.44]],"ltp":3.1,"tv":0.0,"id":5071877},{"batb":[[0,1.46,85.61],[1,1.01,15.51],[2,1.01,0]],"ltp":1.48,"tv":0.01,"id":6374165}]}]}
{"op":"mcm","clk":"1006484901","pt":1580596738553,"mc":[{"id":"1.168175457","rc":[{"batb":[[1,2.58,26.05],[2,2.56,28.72]],"batl":[[0,2.96,21],[1,3.45,180.4]],"ltp":3.1,"tv":0.0,"id":5071877},{"batb":[[0,1.53,71.44],[1,1.52,80.66],[2,1.49,79]],"batl":[[0,1.64,42.01],[1,1.95,409.86]],"ltp":1.48,"tv":0.01,"id":6374165}]}]}
{"op":"mcm","clk":"1006484996","pt":1580596739532,"mc":[{"id":"1.168175457","rc":[{"batl":[[0,3.45,180.4],[1,3.45,0]],"ltp":3.1,"tv":0.0,"id":5071877}]}]}
{"op":"mcm","clk":"1006485158","pt":1580596741435,"mc":[{"id":"1.168175457","rc":[{"batl":[[0,2.94,21],[1,3.45,180.4]],"ltp":3.1,"tv":0.0,"id":5071877}]}]}
{"op":"mcm","clk":"1006485722","pt":1580596747288,"mc":[{"id":"1.168175457","rc":[{"batb":[[2,1.5,78.29]],"ltp":1.48,"tv":0.01,"id":6374165}]}]}
{"op":"mcm","clk":"1006487014","pt":1580596760374,"mc":[{"id":"1.168175457","rc":[{"batb":[[0,1.53,71.13],[2,1.5,77.97]],"ltp":1.48,"tv":0.01,"id":6374165}]}]}
{"op":"mcm","clk":"1006488143","pt":1580596771489,"mc":[{"id":"1.168175457","rc":[{"batb":[[2,2.54,29.19]],"ltp":3.1,"tv":0.0,"id":5071877},{"batb":[[0,1.54,70.74],[2,1.5,77.66]],"ltp":1.48,"tv":0.01,"id":6374165}]}]}
{"op":"mcm","clk":"1006489307","pt":1580596784112,"mc":[{"id":"1.168175457","rc":[{"batb":[[0,2.62,27.3],[2,2.52,29.82]],"ltp":3.1,"tv":0.0,"id":5071877},{"batb":[[0,1.54,69.55],[2,1.51,76.48]],"ltp":1.48,"tv":0.01,"id":6374165}]}]}
{"op":"mcm","clk":"1006492091","pt":1580596814402,"mc":[{"id":"1.168175457","rc":[{"batb":[[0,2.58,26.05],[1,2.52,29.82],[2,1.01,15.52]],"ltp":3.1,"tv":0.0,"id":5071877},{"batb":[[0,1.52,80.66],[1,1.51,76.48],[2,1.01,15.51]],"ltp":1.48,"tv":0.01,"id":6374165}]}]}
{"op":"mcm","clk":"1006492273","pt":1580596816229,"mc":[{"id":"1.168175457","rc":[{"batb":[[0,2.52,29.82],[1,1.01,15.52],[2,1.01,0]],"batl":[[0,3.45,180.4],[1,3.45,0]],"ltp":3.1,"tv":0.0,"id":5071877},{"batb":[[0,1.51,76.48],[1,1.01,15.51],[2,1.01,0]],"batl":[[0,1.95,409.86],[1,1.95,0]],"ltp":1.48,"tv":0.01,"id":6374165}]}]}
{"op":"mcm","clk":"1006494794","pt":1580596840564,"mc":[{"id":"1.168175457","rc":[{"batb":[[0,2.74,24.31],[1,2.64,26.67],[2,2.62,25.21]],"batl":[[0,3,21],[1,3.45,180.4]],"ltp":3.1,"tv":0.0,"id":5071877},{"batb":[[1,1.5,84.02],[2,1.47,85.29]],"batl":[[0,1.62,42.01],[1,1.95,409.86]],"ltp":1.48,"tv":0.01,"id":6374165}]}]}
{"op":"mcm","clk":"1006499352","pt":1580596881340,"mc":[{"id":"1.168175457","rc":[{"batb":[[0,2.64,26.67],[1,2.62,25.21],[2,1.01,15.52]],"ltp":3.1,"tv":0.0,"id":5071877},{"batb":[[0,1.5,84.02],[1,1.47,85.29],[2,1.01,15.51]],"ltp":1.48,"tv":0.01,"id":6374165}]}]}
{"op":"mcm","clk":"1006499384","pt":1580596881655,"mc":[{"id":"1.168175457","rc":[{"batb":[[1,1.01,15.52],[2,1.01,0]],"batl":[[0,3.45,180.4],[1,3.45,0]],"ltp":3.1,"tv":0.0,"id":5071877},{"batb":[[0,1.47,85.29],[1,1.01,15.51],[2,1.01,0]],"batl":[[0,1.95,409.86],[1,1.95,0]],"ltp":1.48,"tv":0.01,"id":6374165}]}]}
{"op":"mcm","clk":"1006499648","pt":1580596884548,"mc":[{"id":"1.168175457","rc":[{"batb":[[0,2.62,26.91]],"ltp":3.1,"tv":0.0,"id":5071877},{"batb":[[0,1.47,84.58]],"ltp":1.48,"tv":0.01,"id":6374165}]}]}
{"op":"mcm","clk":"1006500204","pt":1580596890568,"mc":[{"id":"1.168175457","rc":[{"batb":[[1,2.52,29.82],[2,1.01,15.52]],"ltp":3.1,"tv":0.0,"id":5071877},{"batb":[[0,1.54,70.34],[1,1.5,77.74],[2,1.01,15.51]],"ltp":1.48,"tv":0.01,"id":6374165}]}]}
{"op":"mcm","clk":"1006500279","pt":1580596891346,"mc":[{"id":"1.168175457","rc":[{"batb":[[1,2.6,26.05],[2,2.52,29.82]],"batl":[[0,2.98,21],[1,3.45,180.4]],"ltp":3.1,"tv":0.0,"id":5071877},{"batb":[[1,1.5,161.76]],"batl":[[0,1.62,42.01],[1,1.95,409.86]],"ltp":1.48,"tv":0.01,"id":6374165}]}]}
{"op":"mcm","clk":"1006501980","pt":1580596907967,"mc":[{"id":"1.168175457","rc":[{"batb":[[0,2.52,29.82],[1,1.01,15.52],[2,2.52,0]],"batl":[[0,3.45,180.4],[1,3.45,0]],"ltp":3.1,"tv":0.0,"id":5071877},{"batb":[[0,1.5,77.74],[1,1.01,15.51],[2,1.01,0]],"batl":[[0,1.95,409.86],[1,1.95,0]],"ltp":1.48,"tv":0.01,"id":6374165}]}]}
{"op":"mcm","clk":"1006502319","pt":1580596911191,"mc":[{"id":"1.168175457","rc":[{"batb":[[0,2.54,29.51]],"ltp":3.1,"tv":0.0,"id":5071877},{"batb":[[0,1.49,79]],"ltp":1.48,"tv":0.01,"id":6374165}]}]}
{"op":"mcm","clk":"1006504710","pt":1580596935493,"mc":[{"id":"1.168175457","rc":[{"batb":[[0,2.78,23.37],[1,2.66,26.04],[2,2.64,25.21]],"batl":[[0,3.05,20.16],[1,3.45,180.4]],"ltp":3.1,"tv":0.0,"id":5071877},{"batb":[[0,1.49,164.7],[1,1.45,88.2],[2,1.01,15.51]],"batl":[[0,1.61,42.01],[1,1.95,409.86]],"ltp":1.48,"tv":0.01,"id":6374165}]}]}
{"op":"mcm","clk":"1006506105","pt":1580596949507,"mc":[{"id":"1.168175457","rc":[{"batb":[[2,2.6,7.89]],"ltp":3.1,"tv":0.0,"id":5071877},{"batb":[[0,1.49,79]],"batl":[[0,1.95,409.86],[1,1.95,0]],"ltp":1.48,"tv":0.01,"id":6374165}]}]}
{"op":"mcm","clk":"1006506266","pt":1580596951515,"mc":[{"id":"1.168175457","rc":[{"batb":[[1,2.7,24.37],[2,2.66,26.04]],"ltp":3.1,"tv":0.0,"id":5071877},{"batb":[[1,1.48,87.38],[2,1.45,88.2]],"batl":[[0,1.6,42.01],[1,1.95,409.86]],"ltp":1.48,"tv":0.01,"id":6374165}]}]}
{"op":"mcm","clk":"1006506539","pt":1580596954537,"mc":[{"id":"1.168175457","rc":[{"batb":[[0,2.7,24.37],[1,2.66,26.04],[2,1.01,15.52]],"ltp":3.1,"tv":0.0,"id":5071877},{"batb":[[0,1.48,87.38],[1,1.45,88.2],[2,1.01,15.51]],"ltp":1.48,"tv":0.01,"id":6374165}]}]}
{"op":"mcm","clk":"1006506662","pt":1580596955937,"mc":[{"id":"1.168175457","rc":[{"batb":[[0,2.66,26.04],[1,1.01,15.52],[2,1.01,0]],"batl":[[0,3.45,180.4],[1,3.45,0]],"ltp":3.1,"tv":0.0,"id":5071877},{"batb":[[0,1.45,88.2],[1,1.01,15.51],[2,1.01,0]],"batl":[[0,1.95,409.86],[1,1.95,0]],"ltp":1.48,"tv":0.01,"id":6374165}]}]}
{"op":"mcm","clk":"1006507154","pt":1580596961298,"mc":[{"id":"1.168175457","rc":[{"batb":[[1,2.54,29.43],[2,1.01,15.52]],"batl":[[0,3.05,20.16],[1,3.45,180.4]],"ltp":3.1,"tv":0.0,"id":5071877},{"batb":[[0,1.53,72.31],[1,1.5,1064.58],[2,1.49,85.7]],"batl":[[0,1.61,42.01],[1,1.95,409.86]],"ltp":1.48,"tv":0.01,"id":6374165}]}]}
{"op":"mcm","clk":"1006507344","pt":1580596963520,"mc":[{"id":"1.168175457","rc":[{"batb":[[0,2.66,51.25]],"ltp":3.1,"tv":0.0,"id":5071877}]}]}
{"op":"mcm","clk":"1006508453","pt":1580596976562,"mc":[{"id":"1.168175457","rc":[{"batb":[[0,2.66,25.21]],"ltp":3.1,"tv":0.0,"id":5071877},{"batb":[[0,1.49,85.7],[1,1.48,81.44],[2,1.01,15.51]],"ltp":1.48,"tv":0.01,"id":6374165}]}]}
{"op":"mcm","clk":"1006508607","pt":1580596978262,"mc":[{"id":"1.168175457","rc":[{"batb":[[0,2.54,29.43],[1,1.01,15.52],[2,1.01,0]],"batl":[[0,3.45,180.4],[1,3.45,0]],"ltp":3.1,"tv":0.0,"id":5071877},{"batb":[[0,1.48,81.44],[1,1.01,15.51],[2,1.01,0]],"batl":[[0,1.95,409.86],[1,1.95,0]],"ltp":1.48,"tv":0.01,"id":6374165}]}]}
{"op":"mcm","clk":"1006508722","pt":1580596979555,"mc":[{"id":"1.168175457","rc":[{"batb":[[0,2.56,28.64],[1,2.54,29.43],[2,1.01,15.52]],"ltp":3.1,"tv":0.0,"id":5071877}]}]}
{"op":"mcm","clk":"1006508789","pt":1580596980126,"mc":[{"id":"1.168175457","rc":[{"batb":[[1,1.01,15.52],[2,1.01,0]],"ltp":3.1,"tv":0.0,"id":5071877}]}]}
{"op":"mcm","clk":"1006515361","pt":1580597055176,"mc":[{"id":"1.168175457","rc":[{"batb":[[0,2.84,22.03],[1,2.7,25.26],[2,2.68,24.37]],"batl":[[0,3.1,19.32],[1,3.45,180.4]],"ltp":3.1,"tv":0.0,"id":5071877},{"batb":[[1,1.47,89.06],[2,1.43,94.02]],"batl":[[0,1.59,42.01],[1,1.95,409.86]],"ltp":1.48,"tv":0.01,"id":6374165}]}]}
{"op":"mcm","clk":"1006515618","pt":1580597058184,"mc":[{"id":"1.168175457","rc":[{"batl":[[0,1.58,162.44],[1,1.59,42.01],[2,1.95,409.86]],"ltp":1.48,"tv":0.01,"id":6374165}]}]}
{"op":"mcm","clk":"1006517156","pt":1580597075225,"mc":[{"id":"1.168175457","rc":[{"batb":[[0,2.7,25.26],[1,2.68,24.37],[2,1.01,15.52]],"ltp":3.1,"tv":0.0,"id":5071877},{"batb":[[0,1.47,89.06],[1,1.43,94.02],[2,1.01,15.51]],"batl":[[0,1.59,42.01],[1,1.95,409.86],[2,1.95,0]],"ltp":1.48,"tv":0.01,"id":6374165}]}]}
{"op":"mcm","clk":"1006517281","pt":1580597076525,"mc":[{"id":"1.168175457","rc":[{"batb":[[1,1.01,15.52],[2,1.01,0]],"batl":[[0,3.45,180.4],[1,3.45,0]],"ltp":3.1,"tv":0.0,"id":5071877},{"batb":[[0,1.43,94.02],[1,1.01,15.51],[2,1.01,0]],"batl":[[0,1.95,409.86],[1,1.95,0]],"ltp":1.48,"tv":0.01,"id":6374165}]}]}
{"op":"mcm","clk":"1006519554","pt":1580597102348,"mc":[{"id":"1.168175457","rc":[{"batb":[[1,1.42,696.37],[2,1.41,456.82]],"batl":[[0,1.47,438.73],[1,1.48,361.06],[2,1.95,409.86]],"ltp":1.48,"tv":0.01,"id":6374165}]}]}
{"op":"mcm","clk":"1006519640","pt":1580597103179,"mc":[{"id":"1.168175457","rc":[{"batb":[[0,3,47.6],[1,2.78,23.53],[2,2.62,26.91]],"batl":[[0,3.2,18.48],[1,3.45,180.4]],"ltp":3.1,"tv":0.0,"id":5071877},{"batb":[[0,1.46,90.74],[1,1.43,94.02],[2,1.42,696.37]],"batl":[[2,1.57,42.01]],"ltp":1.48,"tv":0.01,"id":6374165}]}]}
{"op":"mcm","clk":"1006520030","pt":1580597107394,"mc":[{"id":"1.168175457","rc":[{"batb":[[0,1.43,94.02],[1,1.42,696.37],[2,1.41,456.82]],"batl":[[2,1.95,409.86]],"ltp":1.48,"tv":0.01,"id":6374165}]}]}
{"op":"mcm","clk":"1006520278","pt":1580597110494,"mc":[{"id":"1.168175457","rc":[{"batb":[[0,1.45,93.26],[1,1.43,94.02],[2,1.42,438.65]],"batl":[[2,1.56,42.01]],"ltp":1.48,"tv":0.01,"id":6374165}]}]}
{"op":"mcm","clk":"1006520457","pt":1580597112886,"mc":[{"id":"1.168175457","rc":[{"batb":[[1,1.43,365.67]],"ltp":1.48,"tv":0.01,"id":6374165}]}]}
{"op":"mcm","clk":"1006522155","pt":1580597132427,"mc":[{"id":"1.168175457","rc":[{"batb":[[1,1.43,94.02]],"ltp":1.48,"tv":0.01,"id":6374165}]}]}
{"op":"mcm","clk":"1006522455","pt":1580597135509,"mc":[{"id":"1.168175457","rc":[{"batb":[[0,3.05,45.48],[1,3,47.6],[2,2.78,23.53]],"ltp":3.1,"tv":0.0,"id":5071877},{"batb":[[2,1.42,707.73]],"batl":[[0,1.47,521.89]],"ltp":1.48,"tv":0.01,"id":6374165}]}]}
{"op":"mcm","clk":"1006522492","pt":1580597135921,"mc":[{"id":"1.168175457","rc":[{"batb":[[1,2.78,23.53],[2,2.68,25.73]],"ltp":3.1,"tv":0.0,"id":5071877},{"batb":[[1,1.42,707.73],[2,1.41,456.8]],"ltp":1.48,"tv":0.01,"id":6374165}]}]}
{"op":"mcm","clk":"1006523166","pt":1580597143416,"mc":[{"id":"1.168175457","rc":[{"batb":[[0,3.1,44.22],[1,3.05,45.48],[2,2.78,23.53]],"ltp":3.1,"tv":0.0,"id":5071877},{"batb":[[2,1.41,556.41]],"ltp":1.48,"tv":0.01,"id":6374165}]}]}
{"op":"mcm","clk":"1006523251","pt":1580597144346,"mc":[{"id":"1.168175457","rc":[{"batb":[[1,2.78,23.53],[2,2.7,25.02]],"ltp":3.1,"tv":0.0,"id":5071877},{"batb":[[1,1.42,610.24]],"ltp":1.48,"tv":0.01,"id":6374165}]}]}
{"op":"mcm","clk":"1006523896","pt":1580597152452,"mc":[{"id":"1.168175457","rc":[{"batb":[[0,3.05,44.38]],"ltp":3.1,"tv":0.0,"id":5071877},{"batb":[[2,1.41,556.18]],"ltp":1.48,"tv":0.01,"id":6374165}]}]}
{"op":"mcm","clk":"1006524834","pt":1580597164764,"mc":[{"id":"1.168175457","rc":[{"batb":[[2,1.41,556.02]],"ltp":1.48,"tv":0.01,"id":6374165}]}]}
{"op":"mcm","clk":"1006525855","pt":1580597175977,"mc":[{"id":"1.168175457","rc":[{"batb":[[2,1.41,555.62]],"ltp":1.48,"tv":0.01,"id":6374165}]}]}
{"op":"mcm","clk":"1006526490","pt":1580597184059,"mc":[{"id":"1.168175457","rc":[{"batb":[[2,2.68,25.65]],"ltp":3.1,"tv":0.0,"id":5071877},{"batb":[[1,1.42,708.04],[2,1.41,456.8]],"ltp":1.48,"tv":0.01,"id":6374165}]}]}
{"op":"mcm","clk":"1006528683","pt":1580597210332,"mc":[{"id":"1.168175457","rc":[{"trd":[[1.47,118.1]],"batl":[[0,1.47,462.84]],"ltp":1.47,"tv":118.11,"id":6374165}],"tv":118.11}]}
{"op":"mcm","clk":"1006528979","pt":1580597213550,"mc":[{"id":"1.168175457","rc":[{"batb":[[1,1.42,762.29]],"ltp":1.47,"tv":118.11,"id":6374165}]}]}
{"op":"mcm","clk":"1006530244","pt":1580597228072,"mc":[{"id":"1.168175457","rc":[{"batb":[[1,2.68,25.65],[2,1.01,15.52]],"batl":[[0,3.45,180.4],[1,3.45,0]],"ltp":3.1,"tv":0.0,"id":5071877},{"trd":[[1.45,123.79]],"batb":[[0,1.42,762.29],[1,1.41,456.8],[2,1.36,118.49]],"batl":[[2,1.95,409.86]],"ltp":1.45,"tv":241.9,"id":6374165}],"tv":241.91}]}
{"op":"mcm","clk":"1006530450","pt":1580597230973,"mc":[{"id":"1.168175457","rc":[{"batb":[[1,2.92,21.85],[2,2.68,25.65]],"batl":[[0,3.25,18.48],[1,3.45,180.4]],"ltp":3.1,"tv":0.0,"id":5071877},{"batb":[[0,1.44,94.94],[1,1.42,762.29],[2,1.41,456.8]],"batl":[[2,1.52,42.01]],"ltp":1.45,"tv":241.9,"id":6374165}]}]}
{"op":"mcm","clk":"1006532221","pt":1580597252385,"mc":[{"id":"1.168175457","rc":[{"batb":[[0,2.92,21.85],[1,2.68,25.65],[2,1.01,15.52]],"ltp":3.1,"tv":0.0,"id":5071877},{"batb":[[1,1.36,118.49],[2,1.01,15.51]],"batl":[[0,1.52,42.01],[1,1.95,409.86],[2,1.52,0]],"ltp":1.45,"tv":241.9,"id":6374165}]}]}
{"op":"mcm","clk":"1006532352","pt":1580597254030,"mc":[{"id":"1.168175457","rc":[{"batb":[[0,2.68,25.65],[1,1.01,15.52],[2,1.01,0]],"batl":[[0,3.45,180.4],[1,3.45,0]],"ltp":3.1,"tv":0.0,"id":5071877},{"batb":[[0,1.36,118.49],[1,1.01,15.51],[2,1.01,0]],"batl":[[0,1.95,409.86],[1,1.95,0]],"ltp":1.45,"tv":241.9,"id":6374165}]}]}
{"op":"mcm","clk":"1006532471","pt":1580597255527,"mc":[{"id":"1.168175457","rc":[{"batb":[[0,2.66,26.12]],"ltp":3.1,"tv":0.0,"id":5071877},{"batb":[[0,1.37,498.02],[1,1.36,655.66],[2,1.01,15.51]],"batl":[[0,1.44,1.77],[1,1.58,269.13],[2,1.59,275.15]],"ltp":1.45,"tv":241.9,"id":6374165}]}]}
{"op":"mcm","clk":"1006532849","pt":1580597260044,"mc":[{"id":"1.168175457","rc":[{"batb":[[0,1.36,116.69],[1,1.01,15.51],[2,1.01,0]],"ltp":1.45,"tv":241.9,"id":6374165}]}]}
{"op":"mcm","clk":"1006533140","pt":1580597263519,"mc":[{"id":"1.168175457","rc":[{"batb":[[1,2.28,39.18],[2,1.01,15.52]],"ltp":3.1,"tv":0.0,"id":5071877},{"trd":[[1.44,3.54]],"batb":[[0,1.53,477.82],[1,1.52,330.77],[2,1.44,90.8]],"batl":[[0,1.58,269.13],[1,1.59,275.15],[2,1.59,0]],"ltp":1.44,"tv":245.44,"id":6374165}],"tv":245.44}]}
{"op":"mcm","clk":"1006533307","pt":1580597265543,"mc":[{"id":"1.168175457","rc":[{"batb":[[1,2.6,26.05],[2,2.28,39.18]],"ltp":3.1,"tv":0.0,"id":5071877},{"batl":[[2,1.63,42.01]],"ltp":1.44,"tv":245.44,"id":6374165}]}]}
{"op":"mcm","clk":"1006533387","pt":1580597266529,"mc":[{"id":"1.168175457","rc":[{"batl":[[0,2.88,21.85],[1,3.15,200.42]],"ltp":3.1,"tv":0.0,"id":5071877},{"batb":[[0,1.53,556.8]],"ltp":1.44,"tv":245.44,"id":6374165}]}]}
{"op":"mcm","clk":"1006534365","pt":1580597278242,"mc":[{"id":"1.168175457","rc":[{"batb":[[0,2.6,26.05],[1,2.28,39.18],[2,1.01,15.52]],"ltp":3.1,"tv":0.0,"id":5071877},{"batb":[[0,1.53,78.98],[1,1.44,90.8],[2,1.01,15.51]],"batl":[[0,1.63,42.01],[1,2.22,329.01],[2,1.63,0]],"ltp":1.44,"tv":245.44,"id":6374165}]}]}
{"op":"mcm","clk":"1006534511","pt":1580597280254,"mc":[{"id":"1.168175457","rc":[{"batb":[[0,2.28,39.18],[1,1.01,15.52],[2,1.01,0]],"batl":[[0,3.15,200.42],[1,3.15,0]],"ltp":3.1,"tv":0.0,"id":5071877},{"batb":[[0,1.44,90.8],[1,1.01,15.51],[2,1.01,0]],"batl":[[0,2.22,329.01],[1,2.22,0]],"ltp":1.44,"tv":245.44,"id":6374165}]}]}
{"op":"mcm","clk":"1006534622","pt":1580597281552,"mc":[{"id":"1.168175457","rc":[{"batb":[[0,1.44,760.83],[1,1.43,429.09],[2,1.01,15.51]],"batl":[[0,1.77,367.62],[1,1.79,367.97],[2,2.22,329.01]],"ltp":1.44,"tv":245.44,"id":6374165}]}]}
{"op":"mcm","clk":"1006534941","pt":1580597285237,"mc":[{"id":"1.168175457","rc":[{"batl":[[0,1.5,50],[1,1.77,367.62],[2,1.79,367.97]],"ltp":1.44,"tv":245.44,"id":6374165}]}]}
{"op":"mcm","clk":"1006535273","pt":1580597289858,"mc":[{"id":"1.168175457","rc":[{"trd":[[3,25]],"batl":[[0,3,12.86],[1,3.15,200.42]],"ltp":3.0,"tv":25.0,"id":5071877},{"trd":[[1.5,50]],"batl":[[0,1.77,367.62],[1,1.79,367.97],[2,2.22,329.01]],"ltp":1.5,"tv":295.44,"id":6374165}],"tv":320.45}]}
{"op":"mcm","clk":"1006535663","pt":1580597294569,"mc":[{"id":"1.168175457","rc":[{"batl":[[0,2.22,329.01],[1,1.79,0],[2,2.22,0]],"ltp":1.5,"tv":295.44,"id":6374165}]}]}
{"op":"mcm","clk":"1006535878","pt":1580597297479,"mc":[{"id":"1.168175457","rc":[{"trd":[[3,37.86]],"ltp":3.0,"tv":37.86,"id":5071877},{"trd":[[1.5,75.72]],"batl":[[0,1.49,340.38],[1,1.5,342.95]],"ltp":1.5,"tv":321.16,"id":6374165}],"tv":359.03}]}
{"op":"mcm","clk":"1006535941","pt":1580597298153,"mc":[{"id":"1.168175457","rc":[{"batb":[[0,2.96,49.73],[1,2.54,29.66],[2,1.01,15.52]],"ltp":3.0,"tv":37.86,"id":5071877},{"batb":[[2,1.37,115.03]],"ltp":1.5,"tv":321.16,"id":6374165}]}]}
{"op":"mcm","clk":"1006536003","pt":1580597298882,"mc":[{"id":"1.168175457","rc":[{"batb":[[1,2.8,22.69],[2,2.54,29.66]],"batl":[[0,3.15,19.32]],"ltp":3.0,"tv":37.86,"id":5071877},{"batb":[[0,1.46,90.74],[1,1.44,760.83],[2,1.43,429.09]],"batl":[[2,1.55,42.01]],"ltp":1.5,"tv":321.16,"id":6374165}]}]}
{"op":"mcm","clk":"1006536225","pt":1580597301161,"mc":[{"id":"1.168175457","rc":[{"batl":[[1,3.65,170.41]],"ltp":3.0,"tv":37.86,"id":5071877}]}]}
{"op":"mcm","clk":"1006536528","pt":1580597304487,"mc":[{"id":"1.168175457","rc":[{"trd":[[1.49,372.56]],"batb":[[1,1.44,503.7],[2,1.37,115.03]],"batl":[[0,1.49,154.1]],"ltp":1.49,"tv":693.72,"id":6374165}],"tv":731.59}]}
{"op":"mcm","clk":"1006536747","pt":1580597307091,"mc":[{"id":"1.168175457","rc":[{"batb":[[1,1.45,335.24],[2,1.44,503.7]],"batl":[[0,1.49,288.39]],"ltp":1.49,"tv":693.72,"id":6374165}]}]}
{"op":"mcm","clk":"1006536987","pt":1580597310306,"mc":[{"id":"1.168175457","rc":[{"batb":[[0,2.54,29.66],[1,1.01,15.52],[2,2.54,0]],"batl":[[0,3.65,170.41],[1,3.65,0]],"ltp":3.0,"tv":37.86,"id":5071877},{"batb":[[0,1.37,115.03],[1,1.01,15.51],[2,1.44,0]],"batl":[[0,2.04,383.01],[1,1.5,0],[2,1.55,0]],"ltp":1.49,"tv":693.72,"id":6374165}]}]}
{"op":"mcm","clk":"1006537242","pt":1580597313285,"mc":[{"id":"1.168175457","rc":[{"batb":[[0,1.38,379.49],[1,1.37,633.16],[2,1.01,15.51]],"batl":[[0,1.64,286.69],[1,1.65,240.55],[2,2.04,383.01]],"ltp":1.49,"tv":693.72,"id":6374165}]}]}
{"op":"mcm","clk":"1006537404","pt":1580597315406,"mc":[{"id":"1.168175457","rc":[{"batb":[[0,1.37,115.03],[1,1.01,15.51],[2,1.01,0]],"batl":[[0,2.04,383.01],[1,1.65,0],[2,2.04,0]],"ltp":1.49,"tv":693.72,"id":6374165}]}]}
{"op":"mcm","clk":"1006537673","pt":1580597318415,"mc":[{"id":"1.168175457","rc":[{"batb":[[0,1.38,379.49],[1,1.37,633.16],[2,1.01,15.51]],"batl":[[0,1.42,545.33],[1,1.43,415.18]],"ltp":1.49,"tv":693.72,"id":6374165}]}]}
{"op":"mcm","clk":"1006537751","pt":1580597319198,"mc":[{"id":"1.168175457","rc":[{"batb":[[0,3.3,36.59],[1,3.1,19.32],[2,2.88,21.32]],"batl":[[0,3.5,16.8]],"ltp":3.0,"tv":37.86,"id":5071877},{"batb":[[0,1.4,105.02],[1,1.38,379.49],[2,1.37,633.16]],"batl":[[2,1.48,42.01]],"ltp":1.49,"tv":693.72,"id":6374165}]}]}
{"op":"mcm","clk":"1006537979","pt":1580597321888,"mc":[{"id":"1.168175457","rc":[{"batl":[[1,4.2,148.03]],"ltp":3.0,"tv":37.86,"id":5071877}]}]}
{"op":"mcm","clk":"1006539249","pt":1580597337442,"mc":[{"id":"1.168175457","rc":[{"batb":[[0,3.1,19.32],[1,2.88,21.32],[2,1.01,15.52]],"ltp":3.0,"tv":37.86,"id":5071877},{"batb":[[1,1.31,139.98],[2,1.01,15.51]],"batl":[[0,1.48,42.01],[1,1.89,435.28],[2,1.48,0]],"ltp":1.49,"tv":693.72,"id":6374165}]}]}
{"op":"mcm","clk":"1006539292","pt":1580597337915,"mc":[{"id":"1.168175457","rc":[{"batb":[[0,2.88,21.32],[1,1.01,15.52],[2,1.01,0]],"batl":[[0,4.2,148.03],[1,4.2,0]],"ltp":3.0,"tv":37.86,"id":5071877},{"batb":[[0,1.31,139.98],[1,1.01,15.51],[2,1.01,0]],"batl":[[0,1.89,435.28],[1,1.89,0]],"ltp":1.49,"tv":693.72,"id":6374165}]}]}
{"op":"mcm","clk":"1006539456","pt":1580597339933,"mc":[{"id":"1.168175457","rc":[{"batb":[[0,1.33,528.43],[1,1.32,625.35],[2,1.31,139.98]],"batl":[[0,1.52,443.5],[1,1.53,316.42],[2,1.89,435.28]],"ltp":1.49,"tv":693.72,"id":6374165}]}]}
{"op":"mcm","clk":"1006540008","pt":1580597347347,"mc":[{"id":"1.168175457","rc":[{"batb":[[0,1.31,139.98],[1,1.01,15.51],[2,1.31,0]],"ltp":1.49,"tv":693.72,"id":6374165}]}]}
{"op":"mcm","clk":"1006540266","pt":1580597350472,"mc":[{"id":"1.168175457","rc":[{"batb":[[0,1.47,444.31],[1,1.46,389.99],[2,1.31,139.98]],"batl":[[2,1.89,0]],"ltp":1.49,"tv":693.72,"id":6374165}]}]}
{"op":"mcm","clk":"1006540321","pt":1580597351152,"mc":[{"id":"1.168175457","rc":[{"batb":[[1,2.76,23.53],[2,2.36,35.64]],"batl":[[0,3.1,19.32]],"ltp":3.0,"tv":37.86,"id":5071877},{"batb":[[0,1.48,87.38],[1,1.47,444.31],[2,1.46,476.07]],"batl":[[2,1.57,42.01]],"ltp":1.49,"tv":693.72,"id":6374165}]}]}
{"op":"mcm","clk":"1006540619","pt":1580597354538,"mc":[{"id":"1.168175457","rc":[{"batl":[[1,3.45,180.4]],"ltp":3.0,"tv":37.86,"id":5071877}]}]}
{"op":"mcm","clk":"1006541834","pt":1580597370467,"mc":[{"id":"1.168175457","rc":[{"batb":[[0,2.76,23.53],[1,2.36,35.64],[2,1.01,15.52]],"ltp":3.0,"tv":37.86,"id":5071877},{"batb":[[1,1.37,142.97],[2,1.01,15.51]],"batl":[[0,1.57,42.01],[1,2.1,363.31],[2,1.57,0]],"ltp":1.49,"tv":693.72,"id":6374165}]}]}
{"op":"mcm","clk":"1006541955","pt":1580597371962,"mc":[{"id":"1.168175457","rc":[{"batb":[[0,2.36,35.64],[1,1.01,15.52],[2,1.01,0]],"batl":[[0,3.45,180.4],[1,3.45,0]],"ltp":3.0,"tv":37.86,"id":5071877},{"batb":[[0,1.37,142.97],[1,1.01,15.51],[2,1.01,0]],"batl":[[0,2.1,363.31],[1,2.1,0]],"ltp":1.49,"tv":693.72,"id":6374165}]}]}
{"op":"mcm","clk":"1006542070","pt":1580597373174,"mc":[{"id":"1.168175457","rc":[{"batb":[[0,1.37,833.77],[1,1.36,540.42],[2,1.01,15.51]],"batl":[[0,1.74,415.2],[1,1.76,388.15],[2,2.1,363.31]],"ltp":1.49,"tv":693.72,"id":6374165}]}]}
{"op":"mcm","clk":"1006542354","pt":1580597376284,"mc":[{"id":"1.168175457","rc":[{"batl":[[0,2.1,363.31],[1,1.76,0],[2,2.1,0]],"ltp":1.49,"tv":693.72,"id":6374165}]}]}
{"op":"mcm","clk":"1006542637","pt":1580597379409,"mc":[{"id":"1.168175457","rc":[{"batl":[[0,1.41,308.67],[1,1.42,430.29]],"ltp":1.49,"tv":693.72,"id":6374165}]}]}
{"op":"mcm","clk":"1006542689","pt":1580597379980,"mc":[{"id":"1.168175457","rc":[{"batb":[[0,3.35,36.19],[1,2.84,21.79],[2,1.01,15.52]],"ltp":3.0,"tv":37.86,"id":5071877},{"batb":[[2,1.3,145.8]],"ltp":1.49,"tv":693.72,"id":6374165}]}]}
{"op":"mcm","clk":"1006542796","pt":1580597381388,"mc":[{"id":"1.168175457","rc":[{"batb":[[1,3.1,19.32],[2,2.84,21.79]],"batl":[[0,3.5,16.8],[1,4.2,148.03]],"ltp":3.0,"tv":37.86,"id":5071877},{"batl":[[2,1.48,42.01]],"ltp":1.49,"tv":693.72,"id":6374165}]}]}
{"op":"mcm","clk":"1006542871","pt":1580597382385,"mc":[{"id":"1.168175457","rc":[{"batb":[[0,1.4,105.02],[1,1.37,833.77],[2,1.36,540.42]],"ltp":1.49,"tv":693.72,"id":6374165}]}]}
{"op":"mcm","clk":"1006544041","pt":1580597397521,"mc":[{"id":"1.168175457","rc":[{"batb":[[0,3.1,19.32],[1,2.84,21.79],[2,1.01,15.52]],"ltp":3.0,"tv":37.86,"id":5071877},{"batb":[[0,1.37,27],[1,1.3,145.64],[2,1.01,15.51]],"batl":[[0,1.89,435.28],[1,1.42,0],[2,1.48,0]],"ltp":1.49,"tv":693.72,"id":6374165}]}]}
{"op":"mcm","clk":"1006544095","pt":1580597398229,"mc":[{"id":"1.168175457","rc":[{"batb":[[0,2.84,21.79],[1,1.01,15.52],[2,1.01,0]],"batl":[[0,4.2,148.03],[1,4.2,0]],"ltp":3.0,"tv":37.86,"id":5071877}]}]}
{"op":"mcm","clk":"1006544250","pt":1580597400442,"mc":[{"id":"1.168175457","rc":[{"batb":[[0,1.39,107.54],[1,1.37,27],[2,1.32,469.55]],"batl":[[0,1.47,42.01],[1,1.53,429.96],[2,1.54,308.72]],"ltp":1.49,"tv":693.72,"id":6374165}]}]}
{"op":"mcm","clk":"1006544272","pt":1580597400752,"mc":[{"id":"1.168175457","rc":[{"batb":[[0,1.37,27],[1,1.32,469.55],[2,1.31,649.99]],"batl":[[0,1.53,429.96],[1,1.54,308.72],[2,1.89,435.28]],"ltp":1.49,"tv":693.72,"id":6374165}]}]}
{"op":"mcm","clk":"1006545338","pt":1580597413807,"mc":[{"id":"1.168175457","rc":[{"batb":[[1,1.3,145.64],[2,1.01,15.51]],"batl":[[0,1.89,435.28],[1,1.54,0],[2,1.89,0]],"ltp":1.49,"tv":693.72,"id":6374165}]}]}
{"op":"mcm","clk":"1006545444","pt":1580597415201,"mc":[{"id":"1.168175457","rc":[{"trd":[[1.37,0.03]],"batb":[[0,1.37,26.98]],"ltp":1.37,"tv":693.75,"id":6374165}],"tv":731.62}]}
{"op":"mcm","clk":"1006545533","pt":1580597416499,"mc":[{"id":"1.168175457","rc":[{"batb":[[0,1.39,657.89],[1,1.38,503.62],[2,1.37,26.98]],"batl":[[0,1.44,639.9],[1,1.45,390.65],[2,1.89,435.28]],"ltp":1.37,"tv":693.75,"id":6374165}]}]}
{"op":"mcm","clk":"1006545715","pt":1580597419075,"mc":[{"id":"1.168175457","rc":[{"batl":[[0,3.9,158.24]],"ltp":3.0,"tv":37.86,"id":5071877},{"batl":[[2,1.89,0]],"ltp":1.37,"tv":693.75,"id":6374165}]}]}
{"op":"mcm","clk":"1006545853","pt":1580597420891,"mc":[{"id":"1.168175457","rc":[{"batb":[[0,1.37,26.98],[1,1.3,145.64],[2,1.01,15.51]],"ltp":1.37,"tv":693.75,"id":6374165}]}]}
{"op":"mcm","clk":"1006546058","pt":1580597423488,"mc":[{"id":"1.168175457","rc":[{"batb":[[1,1.32,436.85],[2,1.31,649.93]],"batl":[[0,1.53,458.28],[1,1.54,308.76]],"ltp":1.37,"tv":693.75,"id":6374165}]}]}
{"op":"mcm","clk":"1006546447","pt":1580597428402,"mc":[{"id":"1.168175457","rc":[{"batb":[[1,1.3,145.64],[2,1.01,15.51]],"ltp":1.37,"tv":693.75,"id":6374165}]}]}
{"op":"mcm","clk":"1006546728","pt":1580597431505,"mc":[{"id":"1.168175457","rc":[{"batb":[[0,1.48,387.78],[1,1.47,378.78],[2,1.37,26.98]],"ltp":1.37,"tv":693.75,"id":6374165}]}]}
{"op":"mcm","clk":"1006546786","pt":1580597432124,"mc":[{"id":"1.168175457","rc":[{"batb":[[1,2.34,36.74],[2,1.01,15.52]],"ltp":3.0,"tv":37.86,"id":5071877},{"batb":[[1,1.47,462.26],[2,1.37,140.2]],"ltp":1.37,"tv":693.75,"id":6374165}]}]}
{"op":"mcm","clk":"1006546851","pt":1580597432902,"mc":[{"id":"1.168175457","rc":[{"batb":[[1,2.76,23.53],[2,2.34,36.74]],"batl":[[0,3.05,20.16]],"ltp":3.0,"tv":37.86,"id":5071877},{"batb":[[0,1.48,475.16]],"batl":[[2,1.57,42.01]],"ltp":1.37,"tv":693.75,"id":6374165}]}]}
{"op":"mcm","clk":"1006546910","pt":1580597433623,"mc":[{"id":"1.168175457","rc":[{"batl":[[1,3.45,180.4]],"ltp":3.0,"tv":37.86,"id":5071877}]}]}
{"op":"mcm","clk":"1006547045","pt":1580597435139,"mc":[{"id":"1.168175457","rc":[{"batb":[[2,1.37,1381.97]],"ltp":1.37,"tv":693.75,"id":6374165}]}]}
{"op":"mcm","clk":"1006548119","pt":1580597448223,"mc":[{"id":"1.168175457","rc":[{"batb":[[2,1.37,1381.99]],"ltp":1.37,"tv":693.75,"id":6374165}]}]}
{"op":"mcm","clk":"1006548410","pt":1580597451515,"mc":[{"id":"1.168175457","rc":[{"batl":[[1,3.45,0]],"ltp":3.0,"tv":37.86,"id":5071877}]}]}
{"op":"mcm","clk":"1006548822","pt":1580597456524,"mc":[{"id":"1.168175457","rc":[{"batb":[[0,1.48,87.38],[1,1.47,83.48],[2,1.37,140.22]],"batl":[[0,1.57,42.01],[1,1.54,0],[2,1.57,0]],"ltp":1.37,"tv":693.75,"id":6374165}]}]}
{"op":"mcm","clk":"1006548830","pt":1580597456628,"mc":[{"id":"1.168175457","rc":[{"batb":[[0,2.76,23.53],[1,2.34,36.74],[2,1.01,15.52]],"ltp":3.0,"tv":37.86,"id":5071877},{"batb":[[1,1.37,140.22],[2,1.01,15.51]],"ltp":1.37,"tv":693.75,"id":6374165}]}]}
{"op":"mcm","clk":"1006548948","pt":1580597458024,"mc":[{"id":"1.168175457","rc":[{"batb":[[0,2.34,36.74],[1,1.01,15.52],[2,1.01,0]],"ltp":3.0,"tv":37.86,"id":5071877},{"batb":[[0,1.37,140.22],[1,1.01,15.51],[2,1.01,0]],"ltp":1.37,"tv":693.75,"id":6374165}]}]}
{"op":"mcm","clk":"1006549292","pt":1580597462517,"mc":[{"id":"1.168175457","rc":[{"batb":[[0,1.51,586.88],[1,1.5,349.68],[2,1.37,140.22]],"batl":[[0,1.57,450.93],[1,1.58,280.51]],"ltp":1.37,"tv":693.75,"id":6374165}]}]}
{"op":"mcm","clk":"1006549460","pt":1580597464797,"mc":[{"id":"1.168175457","rc":[{"batl":[[0,3.3,191.92]],"ltp":3.0,"tv":37.86,"id":5071877}]}]}
{"op":"mcm","clk":"1006549562","pt":1580597466237,"mc":[{"id":"1.168175457","rc":[{"batb":[[0,1.37,140.22],[1,1.01,15.51],[2,1.37,0]],"ltp":1.37,"tv":693.75,"id":6374165}]}]}
{"op":"mcm","clk":"1006549831","pt":1580597469550,"mc":[{"id":"1.168175457","rc":[{"batb":[[0,1.38,494.1],[1,1.37,660.02],[2,1.01,15.51]],"batl":[[0,1.75,363.33],[1,1.77,381.43]],"ltp":1.37,"tv":693.75,"id":6374165}]}]}
{"op":"mcm","clk":"1006550864","pt":1580597483437,"mc":[{"id":"1.168175457","rc":[{"batb":[[0,3.3,37.37],[1,3.1,19.32],[2,2.8,22.74]],"batl":[[0,3.5,16.8]],"ltp":3.0,"tv":37.86,"id":5071877},{"batb":[[0,1.4,105.02],[1,1.38,494.1],[2,1.37,660.02]],"batl":[[0,1.42,439.86],[1,1.43,416.5],[2,1.48,42.01]],"ltp":1.37,"tv":693.75,"id":6374165}]}]}
{"op":"mcm","clk":"1006551078","pt":1580597486539,"mc":[{"id":"1.168175457","rc":[{"batl":[[1,3.9,158.24]],"ltp":3.0,"tv":37.86,"id":5071877}]}]}
{"op":"mcm","clk":"1006551196","pt":1580597488441,"mc":[{"id":"1.168175457","rc":[{"trd":[[1.42,363.48]],"batl":[[0,1.42,258.12]],"ltp":1.42,"tv":1057.23,"id":6374165}],"tv":1095.09}]}
{"op":"mcm","clk":"1006551356","pt":1580597491235,"mc":[{"id":"1.168175457","rc":[{"batl":[[2,1.95,409.86]],"ltp":1.42,"tv":1057.23,"id":6374165}]}]}
{"op":"mcm","clk":"1006551382","pt":1580597491758,"mc":[{"id":"1.168175457","rc":[{"batb":[[1,1.38,562.7]],"batl":[[0,1.42,373.29]],"ltp":1.42,"tv":1057.23,"id":6374165}]}]}
{"op":"mcm","clk":"1006551566","pt":1580597494187,"mc":[{"id":"1.168175457","rc":[{"batl":[[2,1.47,42.01]],"ltp":1.42,"tv":1057.23,"id":6374165}]}]}
{"op":"mcm","clk":"1006551857","pt":1580597497643,"mc":[{"id":"1.168175457","rc":[{"batl":[[1,3.9,0]],"ltp":3.0,"tv":37.86,"id":5071877}]}]}
{"op":"mcm","clk":"1006552265","pt":1580597502560,"mc":[{"id":"1.168175457","rc":[{"batb":[[0,2.8,22.74],[1,1.01,15.52],[2,2.8,0]],"ltp":3.0,"tv":37.86,"id":5071877},{"batb":[[0,1.37,27],[1,1.31,142.97],[2,1.01,15.51]],"ltp":1.42,"tv":1057.23,"id":6374165}]}]}
{"op":"mcm","clk":"1006552494","pt":1580597505462,"mc":[{"id":"1.168175457","rc":[{"batb":[[1,1.32,837.6],[2,1.31,798.29]],"batl":[[0,1.54,388.48],[1,1.55,301.27]],"ltp":1.42,"tv":1057.23,"id":6374165}]}]}
{"op":"mcm","clk":"1006553693","pt":1580597521478,"mc":[{"id":"1.168175457","rc":[{"batb":[[1,1.31,142.97],[2,1.01,15.51]],"ltp":1.42,"tv":1057.23,"id":6374165}]}]}
{"op":"mcm","clk":"1006553911","pt":1580597524311,"mc":[{"id":"1.168175457","rc":[{"batb":[[0,1.4,559.67],[1,1.39,485.57],[2,1.37,27]],"batl":[[0,1.44,278.56],[1,1.45,393.55]],"ltp":1.42,"tv":1057.23,"id":6374165}]}]}
{"op":"mcm","clk":"1006554219","pt":1580597527487,"mc":[{"id":"1.168175457","rc":[{"batb":[[0,1.37,27],[1,1.31,142.97],[2,1.01,15.51]],"ltp":1.42,"tv":1057.23,"id":6374165}]}]}
{"op":"mcm","clk":"1006554478","pt":1580597530229,"mc":[{"id":"1.168175457","rc":[{"batb":[[1,1.32,828.92],[2,1.31,798.28]],"batl":[[0,1.54,395.95],[1,1.55,301.28]],"ltp":1.42,"tv":1057.23,"id":6374165}]}]}
{"op":"mcm","clk":"1006555674","pt":1580597548062,"mc":[{"id":"1.168175457","rc":[{"trd":[[1.37,7.6]],"batb":[[0,1.37,23.21]],"ltp":1.37,"tv":1064.8,"id":6374165}],"tv":1102.66}]}
{"op":"mcm","clk":"1006555785","pt":1580597549356,"mc":[{"id":"1.168175457","rc":[{"trd":[[1.37,54.02]],"batb":[[0,1.32,828.92],[1,1.31,798.28],[2,1.01,15.51]],"batl":[[0,1.36,476.85],[1,1.37,502.85]],"ltp":1.37,"tv":1111.22,"id":6374165}],"tv":1149.08}]}
{"op":"mcm","clk":"1006555833","pt":1580597550187,"mc":[{"id":"1.168175457","rc":[{"batb":[[0,3.75,27.22],[1,3.3,37.37],[2,1.01,15.52]],"ltp":3.0,"tv":37.86,"id":5071877},{"batb":[[2,1.24,187.34]],"ltp":1.37,"tv":1111.22,"id":6374165}]}]}
{"op":"mcm","clk":"1006555888","pt":1580597551062,"mc":[{"id":"1.168175457","rc":[{"batb":[[1,3.4,16.8],[2,3.3,37.37]],"batl":[[0,3.95,13.44]],"ltp":3.0,"tv":37.86,"id":5071877},{"batb":[[0,1.34,123.51],[1,1.32,828.92],[2,1.31,798.28]],"batl":[[2,1.41,42.01]],"ltp":1.37,"tv":1111.22,"id":6374165}]}]}
{"op":"mcm","clk":"1006556005","pt":1580597552670,"mc":[{"id":"1.168175457","rc":[{"batl":[[1,4.6,136.05]],"ltp":3.0,"tv":37.86,"id":5071877}]}]}
{"op":"mcm","clk":"1006556218","pt":1580597555566,"mc":[{"id":"1.168175457","rc":[{"batl":[[1,4.6,0]],"ltp":3.0,"tv":37.86,"id":5071877}]}]}
{"op":"mcm","clk":"1006556896","pt":1580597564787,"mc":[{"id":"1.168175457","rc":[{"trd":[[1.36,8.44]],"batl":[[0,1.36,472.63]],"ltp":1.36,"tv":1119.65,"id":6374165}],"tv":1157.52}]}
{"op":"mcm","clk":"1006557336","pt":1580597571081,"mc":[{"id":"1.168175457","rc":[{"trd":[[3.75,153.25]],"batb":[[0,3.4,16.8],[1,3.3,37.37],[2,1.01,15.52]],"ltp":3.75,"tv":191.11,"id":5071877},{"trd":[[1.36,280.89]],"batb":[[1,1.32,620.21],[2,1.31,142.97]],"batl":[[0,1.36,200.18]],"ltp":1.36,"tv":1392.1,"id":6374165}],"tv":1583.22}]}
{"op":"mcm","clk":"1006557514","pt":1580597574227,"mc":[{"id":"1.168175457","rc":[{"batb":[[1,1.33,319.47],[2,1.32,620.21]],"batl":[[0,1.36,390.15]],"ltp":1.36,"tv":1392.1,"id":6374165}]}]}
{"op":"mcm","clk":"1006558359","pt":1580597586531,"mc":[{"id":"1.168175457","rc":[{"batb":[[1,1.31,142.97],[2,1.24,187.34]],"batl":[[0,1.41,42.01],[1,1.37,0],[2,1.41,0]],"ltp":1.36,"tv":1392.1,"id":6374165}]}]}
{"op":"mcm","clk":"1006558547","pt":1580597589433,"mc":[{"id":"1.168175457","rc":[{"batb":[[2,1.26,517.33]],"batl":[[1,1.43,652.16],[2,1.44,400.68]],"ltp":1.36,"tv":1392.1,"id":6374165}]}]}
{"op":"mcm","clk":"1006558812","pt":1580597593540,"mc":[{"id":"1.168175457","rc":[{"batl":[[0,1.4,23.34],[1,1.41,42.01],[2,1.43,652.16]],"ltp":1.36,"tv":1392.1,"id":6374165}]}]}
{"op":"mcm","clk":"1006560019","pt":1580597611350,"mc":[{"id":"1.168175457","rc":[{"batb":[[1,1.26,517.33],[2,1.25,845.4]],"batl":[[0,1.41,42.01],[1,1.43,652.16],[2,1.44,400.68]],"ltp":1.36,"tv":1392.1,"id":6374165}]}]}
{"op":"mcm","clk":"1006560081","pt":1580597612107,"mc":[{"id":"1.168175457","rc":[{"batb":[[0,3.3,37.37],[1,1.01,15.52],[2,1.01,0]],"ltp":3.75,"tv":191.11,"id":5071877},{"batb":[[0,1.26,517.33],[1,1.25,845.4],[2,1.24,187.34]],"batl":[[0,1.43,652.16],[1,1.44,400.68],[2,1.44,0]],"ltp":1.36,"tv":1392.1,"id":6374165}]}]}
{"op":"mcm","clk":"1006560261","pt":1580597614465,"mc":[{"id":"1.168175457","rc":[{"batb":[[0,3.25,39.18]],"ltp":3.75,"tv":191.11,"id":5071877},{"batb":[[0,1.26,698.38],[2,1.01,15.51]],"ltp":1.36,"tv":1392.1,"id":6374165}]}]}
{"op":"mcm","clk":"1006560422","pt":1580597616568,"mc":[{"id":"1.168175457","rc":[{"batb":[[0,1.26,181.05],[1,1.01,15.51],[2,1.01,0]],"ltp":1.36,"tv":1392.1,"id":6374165}]}]}
{"op":"mcm","clk":"1006560651","pt":1580597619566,"mc":[{"id":"1.168175457","rc":[{"batb":[[1,3.15,19.32],[2,2.94,50.51]],"batl":[[0,3.6,15.96]],"ltp":3.75,"tv":191.11,"id":5071877},{"batb":[[0,1.39,216.83],[1,1.38,704.41],[2,1.37,520.22]],"ltp":1.36,"tv":1392.1,"id":6374165}]}]}
{"op":"mcm","clk":"1006560834","pt":1580597622401,"mc":[{"id":"1.168175457","rc":[{"batl":[[1,4.2,148.03]],"ltp":3.75,"tv":191.11,"id":5071877}]}]}
{"op":"mcm","clk":"1006561486","pt":1580597632507,"mc":[{"id":"1.168175457","rc":[{"batb":[[1,1.32,141.31],[2,1.01,15.51]],"ltp":1.36,"tv":1392.1,"id":6374165}]}]}
{"op":"mcm","clk":"1006561544","pt":1580597633379,"mc":[{"id":"1.168175457","rc":[{"batb":[[0,3.15,19.32],[1,2.94,50.51],[2,1.01,15.52]],"ltp":3.75,"tv":191.11,"id":5071877},{"batb":[[0,1.39,107.54]],"ltp":1.36,"tv":1392.1,"id":6374165}]}]}
{"op":"mcm","clk":"1006561598","pt":1580597634306,"mc":[{"id":"1.168175457","rc":[{"batb":[[0,2.94,50.51],[1,1.01,15.52],[2,1.01,0]],"batl":[[0,4.2,148.03],[1,4.2,0]],"ltp":3.75,"tv":191.11,"id":5071877},{"batb":[[0,1.32,141.31],[1,1.01,15.51],[2,1.01,0]],"ltp":1.36,"tv":1392.1,"id":6374165}]}]}
{"op":"mcm","clk":"1006561763","pt":1580597636418,"mc":[{"id":"1.168175457","rc":[{"batb":[[0,1.32,520.04],[1,1.31,646.3],[2,1.01,15.51]],"batl":[[0,1.49,563.16],[1,1.5,339.91]],"ltp":1.36,"tv":1392.1,"id":6374165}]}]}
{"op":"mcm","clk":"1006563121","pt":1580597656143,"mc":[{"id":"1.168175457","rc":[{"batb":[[0,1.32,141.31],[1,1.01,15.51],[2,1.01,0]],"ltp":1.36,"tv":1392.1,"id":6374165}]}]}
{"op":"mcm","clk":"1006563364","pt":1580597659441,"mc":[{"id":"1.168175457","rc":[{"batb":[[0,2.94,71.52],[1,2.74,24.08],[2,1.01,15.52]],"batl":[[0,3.3,17.64]],"ltp":3.75,"tv":191.11,"id":5071877},{"batb":[[0,1.46,89.78],[1,1.44,448.97],[2,1.43,522.77]],"batl":[[2,1.52,42.01]],"ltp":1.36,"tv":1392.1,"id":6374165}]}]}
{"op":"mcm","clk":"1006563515","pt":1580597661353,"mc":[{"id":"1.168175457","rc":[{"batl":[[1,3.9,158.24]],"ltp":3.75,"tv":191.11,"id":5071877}]}]}
{"op":"mcm","clk":"1006564529","pt":1580597676483,"mc":[{"id":"1.168175457","rc":[{"batb":[[1,1.43,97.46],[2,1.39,110.39]],"batl":[[0,1.52,42.01],[1,1.5,0],[2,1.52,0]],"ltp":1.36,"tv":1392.1,"id":6374165}]}]}
{"op":"mcm","clk":"1006564554","pt":1580597676745,"mc":[{"id":"1.168175457","rc":[{"batb":[[0,2.94,21]],"ltp":3.75,"tv":191.11,"id":5071877},{"batb":[[0,1.43,97.46],[1,1.39,110.39],[2,1.01,15.51]],"ltp":1.36,"tv":1392.1,"id":6374165}]}]}
{"op":"mcm","clk":"1006564704","pt":1580597678446,"mc":[{"id":"1.168175457","rc":[{"batb":[[0,2.74,24.08],[1,1.01,15.52],[2,1.01,0]],"batl":[[0,3.9,158.24],[1,3.9,0]],"ltp":3.75,"tv":191.11,"id":5071877},{"batb":[[0,1.39,110.39],[1,1.01,15.51],[2,1.01,0]],"ltp":1.36,"tv":1392.1,"id":6374165}]}]}
{"op":"mcm","clk":"1006564761","pt":1580597679362,"mc":[{"id":"1.168175457","rc":[{"batb":[[1,1.38,713.86],[2,1.37,520.31]],"batl":[[0,1.53,264.2],[1,1.54,308.77]],"ltp":1.36,"tv":1392.1,"id":6374165}]}]}
{"op":"mcm","clk":"1006565162","pt":1580597684495,"mc":[{"id":"1.168175457","rc":[{"batl":[[0,1.43,643.42],[1,1.44,400.76]],"ltp":1.36,"tv":1392.1,"id":6374165}]}]}
{"op":"mcm","clk":"1006565235","pt":1580597685463,"mc":[{"id":"1.168175457","rc":[{"batb":[[0,3.25,38.63],[1,3.15,19.32],[2,2.9,52.4]],"batl":[[0,3.6,15.96],[1,3.9,158.24]],"ltp":3.75,"tv":191.11,"id":5071877},{"batb":[[0,1.39,217.94]],"batl":[[2,1.45,5.8]],"ltp":1.36,"tv":1392.1,"id":6374165}]}]}
{"op":"mcm","clk":"1006565314","pt":1580597686494,"mc":[{"id":"1.168175457","rc":[{"batl":[[2,1.46,42.01]],"ltp":1.36,"tv":1392.1,"id":6374165}]}]}
{"op":"mcm","clk":"1006566419","pt":1580597701415,"mc":[{"id":"1.168175457","rc":[{"batb":[[1,1.31,148.55],[2,1.01,15.51]],"batl":[[0,1.46,42.01],[1,1.44,0],[2,1.46,0]],"ltp":1.36,"tv":1392.1,"id":6374165}]}]}
{"op":"mcm","clk":"1006566497","pt":1580597702404,"mc":[{"id":"1.168175457","rc":[{"batb":[[0,2.9,52.4],[1,1.01,15.52],[2,2.9,0]],"batl":[[0,3.9,158.24],[1,3.9,0]],"ltp":3.75,"tv":191.11,"id":5071877},{"batb":[[0,1.31,148.55],[1,1.01,15.51],[2,1.01,0]],"ltp":1.36,"tv":1392.1,"id":6374165}]}]}
{"op":"mcm","clk":"1006566633","pt":1580597704316,"mc":[{"id":"1.168175457","rc":[{"batb":[[0,1.31,605.56],[1,1.3,674.14],[2,1.01,15.51]],"batl":[[0,1.5,516.01],[1,1.51,331.26]],"ltp":1.36,"tv":1392.1,"id":6374165}]}]}
{"op":"mcm","clk":"1006566828","pt":1580597707408,"mc":[{"id":"1.168175457","rc":[{"batl":[[0,3.3,24.84],[1,3.9,158.24]],"ltp":3.75,"tv":191.11,"id":5071877}]}]}
{"op":"mcm","clk":"1006566903","pt":1580597708395,"mc":[{"id":"1.168175457","rc":[{"batb":[[0,1.31,148.55],[1,1.01,15.51],[2,1.01,0]],"ltp":1.36,"tv":1392.1,"id":6374165}]}]}
{"op":"mcm","clk":"1006566970","pt":1580597709429,"mc":[{"id":"1.168175457","rc":[{"batl":[[0,3.9,158.24],[1,3.9,0]],"ltp":3.75,"tv":191.11,"id":5071877}]}]}
{"op":"mcm","clk":"1006567128","pt":1580597711487,"mc":[{"id":"1.168175457","rc":[{"batb":[[0,2.9,74.25],[1,2.7,24.94],[2,1.01,15.52]],"batl":[[0,3.3,17.64]],"ltp":3.75,"tv":191.11,"id":5071877},{"batb":[[0,1.47,87.18],[1,1.45,450],[2,1.44,412.33]],"batl":[[2,1.52,42.01]],"ltp":1.36,"tv":1392.1,"id":6374165}]}]}
{"op":"mcm","clk":"1006567294","pt":1580597713903,"mc":[{"id":"1.168175457","rc":[{"batl":[[1,3.65,170.41]],"ltp":3.75,"tv":191.11,"id":5071877}]}]}
{"op":"mcm","clk":"1006567710","pt":1580597719520,"mc":[{"id":"1.168175457","rc":[{"trd":[[3,43.48]],"ltp":3.0,"tv":196.74,"id":5071877},{"trd":[[1.5,86.96]],"batl":[[0,1.5,504.77]],"ltp":1.5,"tv":1403.34,"id":6374165}],"tv":1600.09}]}
{"op":"mcm","clk":"1006568277","pt":1580597728411,"mc":[{"id":"1.168175457","rc":[{"batb":[[0,2.7,24.94],[1,1.01,15.52],[2,1.01,0]],"batl":[[0,3.65,170.41],[1,3.65,0]],"ltp":3.0,"tv":196.74,"id":5071877},{"batb":[[0,1.4,106.3],[1,1.01,15.51],[2,1.44,0]],"batl":[[0,2.04,383.01],[1,1.51,0],[2,1.52,0]],"ltp":1.5,"tv":1403.34,"id":6374165}]}]}
{"op":"mcm","clk":"1006568505","pt":1580597731934,"mc":[{"id":"1.168175457","rc":[{"batl":[[0,3,24.84],[1,3.65,170.41]],"ltp":3.0,"tv":196.74,"id":5071877}]}]}
{"op":"mcm","clk":"1006568601","pt":1580597733333,"mc":[{"id":"1.168175457","rc":[{"trd":[[3,68.32]],"batl":[[0,3.65,170.41],[1,3.65,0]],"ltp":3.0,"tv":221.58,"id":5071877},{"trd":[[1.5,136.64]],"batb":[[0,1.44,410.64],[1,1.43,424.68],[2,1.4,106.3]],"batl":[[0,1.49,547.77],[1,1.5,339.42],[2,2.04,383.01]],"ltp":1.5,"tv":1453.02,"id":6374165}],"tv":1674.61}]}
{"op":"mcm","clk":"1006569029","pt":1580597740254,"mc":[{"id":"1.168175457","rc":[{"batb":[[0,1.4,106.3],[1,1.01,15.51],[2,1.4,0]],"batl":[[0,2.04,383.01],[1,1.5,0],[2,2.04,0]],"ltp":1.5,"tv":1453.02,"id":6374165}]}]}
{"op":"mcm","clk":"1006569181","pt":1580597743153,"mc":[{"id":"1.168175457","rc":[{"batb":[[0,1.4,417.16],[1,1.39,481.24],[2,1.01,15.51]],"batl":[[0,1.55,546.27],[1,1.56,292.22],[2,2.04,383.01]],"ltp":1.5,"tv":1453.02,"id":6374165}]}]}
{"op":"mcm","clk":"1006569694","pt":1580597753083,"mc":[{"id":"1.168175457","rc":[{"batl":[[0,2.04,383.01],[1,1.56,0],[2,2.04,0]],"ltp":1.5,"tv":1453.02,"id":6374165}]}]}
{"op":"mcm","clk":"1006569895","pt":1580597756535,"mc":[{"id":"1.168175457","rc":[{"batl":[[0,1.44,505.22],[1,1.45,390.06]],"ltp":1.5,"tv":1453.02,"id":6374165}]}]}
{"op":"mcm","clk":"1006569924","pt":1580597757152,"mc":[{"id":"1.168175457","rc":[{"batb":[[0,3.2,40.6],[1,3.1,19.32],[2,2.8,22.74]],"batl":[[0,3.55,15.96]],"ltp":3.0,"tv":221.58,"id":5071877},{"batb":[[1,1.39,588.78],[2,1.3,149.26]],"batl":[[2,1.47,42.01]],"ltp":1.5,"tv":1453.02,"id":6374165}]}]}
{"op":"mcm","clk":"1006570015","pt":1580597759157,"mc":[{"id":"1.168175457","rc":[{"batl":[[1,4.2,148.03]],"ltp":3.0,"tv":221.58,"id":5071877}]}]}
{"op":"mcm","clk":"1006571206","pt":1580597776417,"mc":[{"id":"1.168175457","rc":[{"batb":[[0,2.8,22.74],[1,1.01,15.52],[2,2.8,0]],"batl":[[0,4.2,148.03],[1,4.2,0]],"ltp":3.0,"tv":221.58,"id":5071877},{"batb":[[0,1.3,149.26],[1,1.01,15.51],[2,1.3,0]],"batl":[[0,1.89,435.28],[1,1.45,0],[2,1.47,0]],"ltp":1.5,"tv":1453.02,"id":6374165}]}]}
{"op":"mcm","clk":"1006571363","pt":1580597778905,"mc":[{"id":"1.168175457","rc":[{"batl":[[0,3.25,25],[1,4.2,148.03]],"ltp":3.0,"tv":221.58,"id":5071877},{"batb":[[0,1.3,1073.04],[1,1.29,711.09],[2,1.01,15.51]],"batl":[[0,1.53,563.15],[1,1.54,306.62],[2,1.89,435.28]],"ltp":1.5,"tv":1453.02,"id":6374165}]}]}
{"op":"mcm","clk":"1006571497","pt":1580597780202,"mc":[{"id":"1.168175457","rc":[{"batl":[[0,4.2,148.03],[1,4.2,0]],"ltp":3.0,"tv":221.58,"id":5071877}]}]}
{"op":"mcm","clk":"1006572313","pt":1580597790434,"mc":[{"id":"1.168175457","rc":[{"batb":[[0,1.3,149.26],[1,1.01,15.51],[2,1.01,0]],"ltp":1.5,"tv":1453.02,"id":6374165}]}]}
{"op":"mcm","clk":"1006572556","pt":1580597793226,"mc":[{"id":"1.168175457","rc":[{"batb":[[0,1.48,270.6],[1,1.47,376.19],[2,1.3,149.26]],"ltp":1.5,"tv":1453.02,"id":6374165}]}]}
{"op":"mcm","clk":"1006572661","pt":1580597794468,"mc":[{"id":"1.168175457","rc":[{"batb":[[1,2.44,33.05],[2,1.01,15.52]],"ltp":3.0,"tv":221.58,"id":5071877},{"batb":[[0,1.5,80.89],[1,1.48,270.6],[2,1.47,376.19]],"ltp":1.5,"tv":1453.02,"id":6374165}]}]}
{"op":"mcm","clk":"1006572715","pt":1580597795139,"mc":[{"id":"1.168175457","rc":[{"batb":[[0,2.8,45.42]],"batl":[[0,3.15,19.32]],"ltp":3.0,"tv":221.58,"id":5071877},{"batl":[[2,1.55,42.01]],"ltp":1.5,"tv":1453.02,"id":6374165}]}]}
{"op":"mcm","clk":"1006572797","pt":1580597796269,"mc":[{"id":"1.168175457","rc":[{"batl":[[1,3.65,170.41]],"ltp":3.0,"tv":221.58,"id":5071877}]}]}
{"op":"mcm","clk":"1006574849","pt":1580597827500,"mc":[{"id":"1.168175457","rc":[{"batb":[[0,2.8,22.69],[1,2.44,32.73]],"ltp":3.0,"tv":221.58,"id":5071877},{"batb":[[0,1.46,90.74],[1,1.42,100.32],[2,1.01,15.51]],"batl":[[0,1.55,42.01],[1,1.89,435.28],[2,1.55,0]],"ltp":1.5,"tv":1453.02,"id":6374165}]}]}
{"op":"mcm","clk":"1006574878","pt":1580597828285,"mc":[{"id":"1.168175457","rc":[{"batb":[[0,2.44,32.73],[1,1.01,15.52],[2,1.01,0]],"batl":[[0,3.65,170.41],[1,3.65,0]],"ltp":3.0,"tv":221.58,"id":5071877},{"batb":[[0,1.42,100.32],[1,1.01,15.51],[2,1.01,0]],"batl":[[0,1.89,435.28],[1,1.89,0]],"ltp":1.5,"tv":1453.02,"id":6374165}]}]}
{"op":"mcm","clk":"1006574975","pt":1580597830089,"mc":[{"id":"1.168175457","rc":[{"batb":[[1,1.41,491.12],[2,1.4,467.44]],"batl":[[0,1.66,247.74],[1,1.68,453.1],[2,1.89,435.28]],"ltp":1.5,"tv":1453.02,"id":6374165}]}]}
{"op":"mcm","clk":"1006575143","pt":1580597832978,"mc":[{"id":"1.168175457","rc":[{"batb":[[1,1.01,15.51],[2,1.4,0]],"ltp":1.5,"tv":1453.02,"id":6374165}]}]}
{"op":"mcm","clk":"1006575276","pt":1580597835140,"mc":[{"id":"1.168175457","rc":[{"batl":[[2,1.89,0]],"ltp":1.5,"tv":1453.02,"id":6374165}]}]}
{"op":"mcm","clk":"1006575326","pt":1580597836017,"mc":[{"id":"1.168175457","rc":[{"batb":[[0,1.6,474.28],[1,1.59,276.8],[2,1.42,100.32]],"ltp":1.5,"tv":1453.02,"id":6374165}]}]}
{"op":"mcm","clk":"1006575394","pt":1580597837316,"mc":[{"id":"1.168175457","rc":[{"batb":[[0,2.46,28.57],[1,2.44,32.73],[2,2.1,50.75]],"batl":[[0,2.76,23.53]],"ltp":3.0,"tv":221.58,"id":5071877},{"batb":[[0,1.63,59.48],[1,1.6,474.28],[2,1.59,276.8]],"ltp":1.5,"tv":1453.02,"id":6374165}]}]}
{"op":"mcm","clk":"1006575465","pt":1580597839326,"mc":[{"id":"1.168175457","rc":[{"batl":[[1,3.15,200.42]],"ltp":3.0,"tv":221.58,"id":5071877},{"batl":[[2,2.22,329.01]],"ltp":1.5,"tv":1453.02,"id":6374165}]}]}
{"op":"mcm","clk":"1006576263","pt":1580597851440,"mc":[{"id":"1.168175457","rc":[{"batb":[[1,2.1,50.75],[2,1.01,15.52]],"ltp":3.0,"tv":221.58,"id":5071877},{"batb":[[0,1.57,73.1],[1,1.52,77.19],[2,1.01,15.51]],"batl":[[0,2.22,329.01],[1,1.68,0],[2,2.22,0]],"ltp":1.5,"tv":1453.02,"id":6374165}]}]}
{"op":"mcm","clk":"1006576322","pt":1580597852258,"mc":[{"id":"1.168175457","rc":[{"batb":[[0,2.1,50.75],[1,1.01,15.52],[2,1.01,0]],"batl":[[0,3.15,200.42],[1,3.15,0]],"ltp":3.0,"tv":221.58,"id":5071877},{"batb":[[0,1.52,77.19],[1,1.01,15.51],[2,1.01,0]],"ltp":1.5,"tv":1453.02,"id":6374165}]}]}
{"op":"mcm","clk":"1006576485","pt":1580597854536,"mc":[{"id":"1.168175457","rc":[{"batb":[[0,2.12,49.1]],"ltp":3.0,"tv":221.58,"id":5071877},{"batb":[[0,1.51,79.47]],"ltp":1.5,"tv":1453.02,"id":6374165}]}]}
{"op":"mcm","clk":"1006576590","pt":1580597856151,"mc":[{"id":"1.168175457","rc":[{"trd":[[2.58,24.84]],"ltp":2.58,"tv":246.42,"id":5071877},{"trd":[[1.64,39.08]],"batb":[[0,1.64,363.47],[1,1.63,252.26],[2,1.51,79.47]],"batl":[[0,1.71,423.53],[1,1.73,409.34],[2,2.22,329.01]],"ltp":1.64,"tv":1492.1,"id":6374165}],"tv":1738.53}]}
{"op":"mcm","clk":"1006576833","pt":1580597859345,"mc":[{"id":"1.168175457","rc":[{"batl":[[0,3,213.45]],"ltp":2.58,"tv":246.42,"id":5071877},{"batb":[[0,1.51,79.47],[1,1.01,15.51],[2,1.51,0]],"batl":[[0,2.22,329.01],[1,1.73,0],[2,2.22,0]],"ltp":1.64,"tv":1492.1,"id":6374165}]}]}
{"op":"mcm","clk":"1006577002","pt":1580597862337,"mc":[{"id":"1.168175457","rc":[{"batb":[[1,1.5,403.16],[2,1.49,356.7]],"batl":[[0,1.89,237.75],[1,1.91,298.95],[2,2.22,329.01]],"ltp":1.64,"tv":1492.1,"id":6374165}]}]}
{"op":"mcm","clk":"1006577497","pt":1580597870204,"mc":[{"id":"1.168175457","rc":[{"batl":[[0,2.22,329.01],[1,1.91,0],[2,2.22,0]],"ltp":1.64,"tv":1492.1,"id":6374165}]}]}
{"op":"mcm","clk":"1006577689","pt":1580597873499,"mc":[{"id":"1.168175457","rc":[{"batl":[[0,1.55,363.71],[1,1.56,293.23],[2,1.84,700.28]],"ltp":1.64,"tv":1492.1,"id":6374165}]}]}
{"op":"mcm","clk":"1006577736","pt":1580597874106,"mc":[{"id":"1.168175457","rc":[{"batb":[[0,2.78,23.21],[1,2.34,36.82],[2,1.01,15.52]],"ltp":2.58,"tv":246.42,"id":5071877}]}]}
{"op":"mcm","clk":"1006577812","pt":1580597875365,"mc":[{"id":"1.168175457","rc":[{"batb":[[1,2.72,24.37],[2,2.34,36.82]],"batl":[[0,3.05,20.16]],"ltp":2.58,"tv":246.42,"id":5071877},{"batb":[[2,1.49,442.4]],"batl":[[2,1.58,42.01]],"ltp":1.64,"tv":1492.1,"id":6374165}]}]}
{"op":"mcm","clk":"1006577926","pt":1580597877469,"mc":[{"id":"1.168175457","rc":[{"batl":[[1,3.45,180.4]],"ltp":2.58,"tv":246.42,"id":5071877}]}]}
{"op":"mcm","clk":"1006579114","pt":1580597897512,"mc":[{"id":"1.168175457","rc":[{"batb":[[0,2.72,24.37],[1,2.34,36.82],[2,1.01,15.52]],"ltp":2.58,"tv":246.42,"id":5071877},{"batb":[[0,1.49,85.7],[1,1.42,101.66],[2,1.01,15.51]],"batl":[[0,1.58,42.01],[1,2.1,363.31],[2,1.58,0]],"ltp":1.64,"tv":1492.1,"id":6374165}]}]}
{"op":"mcm","clk":"1006579169","pt":1580597898287,"mc":[{"id":"1.168175457","rc":[{"batb":[[0,2.34,36.82],[1,1.01,15.52],[2,1.01,0]],"batl":[[0,3.45,180.4],[1,3.45,0]],"ltp":2.58,"tv":246.42,"id":5071877},{"batb":[[0,1.42,101.66],[1,1.01,15.51],[2,1.01,0]],"batl":[[0,2.1,363.31],[1,2.1,0]],"ltp":1.64,"tv":1492.1,"id":6374165}]}]}
{"op":"mcm","clk":"1006579303","pt":1580597900502,"mc":[{"id":"1.168175457","rc":[{"batb":[[1,1.41,724.17],[2,1.4,470.22]],"batl":[[0,1.51,24.84],[1,1.73,306.46],[2,1.75,394.86]],"ltp":1.64,"tv":1492.1,"id":6374165}]}]}
{"op":"mcm","clk":"1006579342","pt":1580597901123,"mc":[{"id":"1.168175457","rc":[{"batb":[[0,2.34,36.67]],"ltp":2.58,"tv":246.42,"id":5071877},{"batb":[[0,1.41,826.69],[1,1.4,470.22],[2,1.01,15.51]],"ltp":1.64,"tv":1492.1,"id":6374165}]}]}
{"op":"mcm","clk":"1006579419","pt":1580597902305,"mc":[{"id":"1.168175457","rc":[{"batl":[[1,2.1,363.31],[2,1.75,0]],"ltp":1.64,"tv":1492.1,"id":6374165}]}]}
{"op":"mcm","clk":"1006579511","pt":1580597903439,"mc":[{"id":"1.168175457","rc":[{"batl":[[0,2.1,363.31],[1,2.1,0]],"ltp":1.64,"tv":1492.1,"id":6374165}]}]}
{"op":"mcm","clk":"1006579647","pt":1580597905555,"mc":[{"id":"1.168175457","rc":[{"batl":[[0,1.46,457.79],[1,1.47,369.38]],"ltp":1.64,"tv":1492.1,"id":6374165}]}]}
{"op":"mcm","clk":"1006579687","pt":1580597906226,"mc":[{"id":"1.168175457","rc":[{"batb":[[0,3.15,42.57],[1,2.68,25.41],[2,1.01,15.52]],"ltp":2.58,"tv":246.42,"id":5071877},{"batb":[[2,1.35,126.05]],"ltp":1.64,"tv":1492.1,"id":6374165}]}]}
{"op":"mcm","clk":"1006579751","pt":1580597907512,"mc":[{"id":"1.168175457","rc":[{"batb":[[1,2.98,21],[2,2.68,25.41]],"batl":[[0,3.4,16.8]],"ltp":2.58,"tv":246.42,"id":5071877},{"batb":[[0,1.42,99.98],[1,1.41,826.69],[2,1.4,470.22]],"batl":[[2,1.5,42.01]],"ltp":1.64,"tv":1492.1,"id":6374165}]}]}
{"op":"mcm","clk":"1006579821","pt":1580597908543,"mc":[{"id":"1.168175457","rc":[{"batl":[[1,3.9,158.24]],"ltp":2.58,"tv":246.42,"id":5071877}]}]}
{"op":"mcm","clk":"1006580542","pt":1580597920339,"mc":[{"id":"1.168175457","rc":[{"trd":[[1.42,494.55]],"batb":[[0,1.41,826.69],[1,1.4,470.22],[2,1.35,126.05]],"ltp":1.42,"tv":1623.18,"id":6374165}],"tv":1869.6}]}
{"op":"mcm","clk":"1006580719","pt":1580597923234,"mc":[{"id":"1.168175457","rc":[{"batb":[[0,1.41,928.36]],"ltp":1.42,"tv":1623.18,"id":6374165}]}]}
{"op":"mcm","clk":"1006580794","pt":1580597924472,"mc":[{"id":"1.168175457","rc":[{"batb":[[0,2.68,25.41],[1,1.01,15.52],[2,2.68,0]],"batl":[[0,3.9,158.24],[1,3.9,0]],"ltp":2.58,"tv":246.42,"id":5071877},{"batb":[[0,1.35,126.05],[1,1.01,15.51],[2,1.35,0]],"batl":[[0,1.95,409.86],[1,1.47,0],[2,1.5,0]],"ltp":1.42,"tv":1623.18,"id":6374165}]}]}
{"op":"mcm","clk":"1006580988","pt":1580597927365,"mc":[{"id":"1.168175457","rc":[{"batb":[[0,1.36,475.42],[1,1.35,681.7],[2,1.01,15.51]],"batl":[[0,1.58,413.44],[1,1.59,273.24],[2,1.95,409.86]],"ltp":1.42,"tv":1623.18,"id":6374165}]}]}
{"op":"mcm","clk":"1006582120","pt":1580597944860,"mc":[{"id":"1.168175457","rc":[{"batb":[[0,1.35,126.05],[1,1.01,15.51],[2,1.01,0]],"ltp":1.42,"tv":1623.18,"id":6374165}]}]}
{"op":"mcm","clk":"1006582365","pt":1580597948474,"mc":[{"id":"1.168175457","rc":[{"batb":[[1,2.18,45.08],[2,1.01,15.52]],"batl":[[0,2.96,2.84]],"ltp":2.58,"tv":246.42,"id":5071877},{"batb":[[0,1.54,73.72],[1,1.52,577.98],[2,1.51,339.13]],"ltp":1.42,"tv":1623.18,"id":6374165}]}]}
{"op":"mcm","clk":"1006582428","pt":1580597949558,"mc":[{"id":"1.168175457","rc":[{"batl":[[0,3,21]],"ltp":2.58,"tv":246.42,"id":5071877}]}]}
{"op":"mcm","clk":"1006582524","pt":1580597951105,"mc":[{"id":"1.168175457","rc":[{"batl":[[1,3.45,180.4]],"ltp":2.58,"tv":246.42,"id":5071877}]}]}
{"op":"mcm","clk":"1006583768","pt":1580597971407,"mc":[{"id":"1.168175457","rc":[{"trd":[[2.72,24.84]],"ltp":2.72,"tv":271.26,"id":5071877},{"trd":[[1.58,42.76]],"batb":[[1,1.5,84.02],[2,1.42,102.13]],"batl":[[0,1.95,409.86],[1,1.59,0],[2,1.95,0]],"ltp":1.58,"tv":1665.94,"id":6374165}],"tv":1937.2}]}
{"op":"mcm","clk":"1006583840","pt":1580597972315,"mc":[{"id":"1.168175457","rc":[{"batb":[[0,2.18,45.08],[1,1.01,15.52],[2,1.01,0]],"batl":[[0,3.45,180.4],[1,3.45,0]],"ltp":2.72,"tv":271.26,"id":5071877},{"batb":[[0,1.42,102.13],[1,1.01,15.51],[2,1.42,0]],"ltp":1.58,"tv":1665.94,"id":6374165}]}]}
{"op":"mcm","clk":"1006583942","pt":1580597974431,"mc":[{"id":"1.168175457","rc":[{"batb":[[1,1.41,445.97],[2,1.4,467.51]],"batl":[[0,1.85,357.81],[1,1.87,319.08],[2,1.95,409.86]],"ltp":1.58,"tv":1665.94,"id":6374165}]}]}
{"op":"mcm","clk":"1006584297","pt":1580597980341,"mc":[{"id":"1.168175457","rc":[{"batb":[[1,1.01,15.51],[2,1.4,0]],"ltp":1.58,"tv":1665.94,"id":6374165}]}]}
{"op":"mcm","clk":"1006584416","pt":1580597982419,"mc":[{"id":"1.168175457","rc":[{"batl":[[2,1.95,0]],"ltp":1.58,"tv":1665.94,"id":6374165}]}]}
{"op":"mcm","clk":"1006584479","pt":1580597983556,"mc":[{"id":"1.168175457","rc":[{"batb":[[1,1.73,46.34],[2,1.01,15.52]],"ltp":2.72,"tv":271.26,"id":5071877},{"batb":[[0,1.78,44.69],[1,1.77,350.24],[2,1.75,390.83]],"ltp":1.58,"tv":1665.94,"id":6374165}]}]}
{"op":"mcm","clk":"1006584630","pt":1580597986339,"mc":[{"id":"1.168175457","rc":[{"batl":[[0,2.72,241.55]],"ltp":2.72,"tv":271.26,"id":5071877},{"batl":[[2,2.5,274.54]],"ltp":1.58,"tv":1665.94,"id":6374165}]}]}
{"op":"mcm","clk":"1006585423","pt":1580597999236,"mc":[{"id":"1.168175457","rc":[{"trd":[[2.3,24.84]],"ltp":2.3,"tv":296.1,"id":5071877},{"trd":[[1.78,32.1]],"batb":[[0,1.78,12.59]],"ltp":1.78,"tv":1698.03,"id":6374165}],"tv":1994.13}]}
{"op":"mcm","clk":"1006585939","pt":1580598005379,"mc":[{"id":"1.168175457","rc":[{"batb":[[0,1.73,46.34],[1,1.01,15.52],[2,1.01,0]],"ltp":2.3,"tv":296.1,"id":5071877},{"batb":[[0,1.55,72.23],[1,1.01,15.51],[2,1.75,0]],"batl":[[0,2.5,274.54],[1,1.87,0],[2,2.5,0]],"ltp":1.78,"tv":1698.03,"id":6374165}]}]}
{"op":"mcm","clk":"1006586061","pt":1580598006984,"mc":[{"id":"1.168175457","rc":[{"batl":[[0,2.18,8.4],[1,2.72,241.55]],"ltp":2.3,"tv":296.1,"id":5071877}]}]}
{"op":"mcm","clk":"1006586184","pt":1580598008490,"mc":[{"id":"1.168175457","rc":[{"batb":[[0,1.74,45.71],[1,1.73,46.34],[2,1.01,15.52]],"ltp":2.3,"tv":296.1,"id":5071877},{"batb":[[1,1.53,633.72],[2,1.52,330.12]],"batl":[[1,2.52,281.56],[2,2.56,264.69]],"ltp":1.78,"tv":1698.03,"id":6374165}]}]}
{"op":"mcm","clk":"1006586239","pt":1580598009319,"mc":[{"id":"1.168175457","rc":[{"batb":[[1,1.01,15.52],[2,1.01,0]],"batl":[[0,2.72,241.55],[1,2.72,0]],"ltp":2.3,"tv":296.1,"id":5071877},{"batb":[[0,1.53,633.72],[1,1.52,330.12],[2,1.01,15.51]],"ltp":1.78,"tv":1698.03,"id":6374165}]}]}
{"op":"mcm","clk":"1006586995","pt":1580598020446,"mc":[{"id":"1.168175457","rc":[{"batb":[[0,1.53,73.17],[1,1.01,15.51],[2,1.01,0]],"batl":[[1,2.52,0],[2,2.56,0]],"ltp":1.78,"tv":1698.03,"id":6374165}]}]}
{"op":"mcm","clk":"1006587208","pt":1580598023515,"mc":[{"id":"1.168175457","rc":[{"trd":[[1.74,91.42]],"batb":[[0,1.66,377.34],[1,1.65,240.88],[2,1.01,15.52]],"batl":[[0,1.73,345.06],[1,1.75,393.4]],"ltp":1.74,"tv":387.52,"id":5071877}],"tv":2085.56}]}
{"op":"mcm","clk":"1006587269","pt":1580598024445,"mc":[{"id":"1.168175457","rc":[{"batb":[[2,1.6,61.37]],"ltp":1.74,"tv":387.52,"id":5071877},{"batb":[[0,2.22,43.98],[1,1.96,32.1],[2,1.01,15.51]],"ltp":1.78,"tv":1698.03,"id":6374165}]}]}
{"op":"mcm","clk":"1006587389","pt":1580598026320,"mc":[{"id":"1.168175457","rc":[{"batl":[[0,1.73,387.07],[2,2.16,342.82]],"ltp":1.74,"tv":387.52,"id":5071877},{"batb":[[0,2.38,30.25],[1,2.22,43.98],[2,1.96,32.1]],"batl":[[0,3.3,191.92]],"ltp":1.78,"tv":1698.03,"id":6374165}]}]}
{"op":"mcm","clk":"1006587695","pt":1580598032456,"mc":[{"id":"1.168175457","rc":[{"batb":[[0,1.71,48],[1,1.66,377.34],[2,1.65,240.88]],"ltp":1.74,"tv":387.52,"id":5071877},{"batb":[[1,2.28,41.7],[2,2,61.45]],"ltp":1.78,"tv":1698.03,"id":6374165}]}]}
{"op":"mcm","clk":"1006587768","pt":1580598033540,"mc":[{"id":"1.168175457","rc":[{"batl":[[1,1.74,35.15],[2,1.75,393.4]],"ltp":1.74,"tv":387.52,"id":5071877}]}]}
{"op":"mcm","clk":"1006588240","pt":1580598040454,"mc":[{"id":"1.168175457","rc":[{"batb":[[0,1.7,48.86]],"ltp":1.74,"tv":387.52,"id":5071877},{"batb":[[1,2.3,40.91],[2,2,60.35]],"ltp":1.78,"tv":1698.03,"id":6374165}]}]}
{"op":"mcm","clk":"1006588382","pt":1580598042531,"mc":[{"id":"1.168175457","rc":[{"trd":[[1.7,49.68]],"batb":[[0,1.7,24.02]],"ltp":1.7,"tv":437.2,"id":5071877}],"tv":2135.24}]}
{"op":"mcm","clk":"1006588615","pt":1580598046051,"mc":[{"id":"1.168175457","rc":[{"trd":[[1.65,150.06],[1.66,754.68],[1.7,97.72]],"batb":[[0,1.65,165.85],[1,1.57,64.36],[2,1.01,15.52]],"batl":[[0,1.73,42.01],[2,2.16,342.82]],"ltp":1.65,"tv":1389.98,"id":5071877}],"tv":3088.02}]}
{"op":"mcm","clk":"1006588752","pt":1580598048171,"mc":[{"id":"1.168175457","rc":[{"batb":[[0,1.7,25.34],[1,1.65,165.85],[2,1.56,66.01]],"ltp":1.65,"tv":1389.98,"id":5071877},{"batb":[[1,2.32,40.44],[2,2.02,59.72]],"ltp":1.78,"tv":1698.03,"id":6374165}]}]}
{"op":"mcm","clk":"1006588784","pt":1580598048849,"mc":[{"id":"1.168175457","rc":[{"batb":[[1,1.66,251.46],[2,1.65,240.9]],"batl":[[0,1.72,309.85],[1,1.73,42.01],[2,1.74,437.14]],"ltp":1.65,"tv":1389.98,"id":5071877}]}]}
{"op":"mcm","clk":"1006588950","pt":1580598051379,"mc":[{"id":"1.168175457","rc":[{"batl":[[1,1.74,437.14],[2,2.16,342.82]],"ltp":1.65,"tv":1389.98,"id":5071877},{"trd":[[2.38,53.05]],"batb":[[0,2.32,40.44],[1,2.02,59.72],[2,1.01,15.51]],"ltp":2.38,"tv":1751.09,"id":6374165}],"tv":3141.07}]}
{"op":"mcm","clk":"1006589141","pt":1580598054383,"mc":[{"id":"1.168175457","rc":[{"trd":[[1.72,2.45]],"batl":[[0,1.72,307.4],[2,1.75,42.01]],"ltp":1.72,"tv":1392.43,"id":5071877},{"trd":[[2.38,54.82]],"batb":[[0,2.34,31.09],[1,2.32,40.44],[2,2.02,59.72]],"ltp":2.38,"tv":1752.85,"id":6374165}],"tv":3145.29}]}
{"op":"mcm","clk":"1006589297","pt":1580598056362,"mc":[{"id":"1.168175457","rc":[{"batb":[[0,1.69,49.81]],"ltp":1.72,"tv":1392.43,"id":5071877},{"batb":[[1,2.32,40.05],[2,2.02,59.17]],"ltp":2.38,"tv":1752.85,"id":6374165}]}]}
{"op":"mcm","clk":"1006589377","pt":1580598057568,"mc":[{"id":"1.168175457","rc":[{"batl":[[0,1.7,270.98],[1,1.72,307.4],[2,1.74,437.14]],"ltp":1.72,"tv":1392.43,"id":5071877}]}]}
{"op":"mcm","clk":"1006589590","pt":1580598061492,"mc":[{"id":"1.168175457","rc":[{"batb":[[0,1.66,251.46],[1,1.65,240.9],[2,1.56,66.01]],"ltp":1.72,"tv":1392.43,"id":5071877},{"batb":[[1,2.02,59.17],[2,1.01,15.51]],"ltp":2.38,"tv":1752.85,"id":6374165}]}]}
{"op":"mcm","clk":"1006589653","pt":1580598062376,"mc":[{"id":"1.168175457","rc":[{"batb":[[0,2.02,59.17],[1,1.01,15.51],[2,1.01,0]],"ltp":2.38,"tv":1752.85,"id":6374165}]}]}
{"op":"mcm","clk":"1006589836","pt":1580598065511,"mc":[{"id":"1.168175457","rc":[{"batl":[[0,1.69,100],[1,1.7,270.98],[2,1.72,307.4]],"ltp":1.72,"tv":1392.43,"id":5071877}]}]}
{"op":"mcm","clk":"1006590257","pt":1580598071485,"mc":[{"id":"1.168175457","rc":[{"batl":[[0,1.7,270.98],[1,1.72,307.4],[2,1.74,437.14]],"ltp":1.72,"tv":1392.43,"id":5071877}]}]}
{"op":"mcm","clk":"1006590487","pt":1580598075382,"mc":[{"id":"1.168175457","rc":[{"trd":[[1.66,954.68]],"batb":[[0,1.65,240.9],[1,1.56,66.01],[2,1.01,15.52]],"ltp":1.66,"tv":1592.43,"id":5071877}],"tv":3345.29}]}
{"op":"mcm","clk":"1006590669","pt":1580598078423,"mc":[{"id":"1.168175457","rc":[{"batb":[[0,1.65,388.65],[1,1.64,246.96],[2,1.56,66.01]],"batl":[[1,1.72,357.83]],"ltp":1.66,"tv":1592.43,"id":5071877}]}]}
{"op":"mcm","clk":"1006590747","pt":1580598079822,"mc":[{"id":"1.168175457","rc":[{"batl":[[1,1.72,409.24]],"ltp":1.66,"tv":1592.43,"id":5071877}]}]}
{"op":"mcm","clk":"1006590889","pt":1580598082323,"mc":[{"id":"1.168175457","rc":[{"trd":[[1.65,927.36]],"batb":[[0,1.64,246.96],[1,1.56,66.01],[2,1.01,15.52]],"ltp":1.65,"tv":2369.73,"id":5071877}],"tv":4122.59}]}
{"op":"mcm","clk":"1006590954","pt":1580598083213,"mc":[{"id":"1.168175457","rc":[{"batb":[[0,1.69,50.12],[1,1.64,246.96],[2,1.56,66.01]],"batl":[[1,1.74,35.15],[2,2.16,342.82]],"ltp":1.65,"tv":2369.73,"id":5071877},{"batb":[[0,2.34,39.81],[1,2.04,58.78],[2,1.01,15.51]],"ltp":2.38,"tv":1752.85,"id":6374165}]}]}
{"op":"mcm","clk":"1006591109","pt":1580598086123,"mc":[{"id":"1.168175457","rc":[{"batb":[[1,1.65,243],[2,1.64,246.96]],"batl":[[1,1.71,344.54],[2,1.73,410.96]],"ltp":1.65,"tv":2369.73,"id":5071877}]}]}
{"op":"mcm","clk":"1006591347","pt":1580598090060,"mc":[{"id":"1.168175457","rc":[{"batl":[[0,1.71,344.54],[1,1.73,410.96],[2,1.74,35.15]],"ltp":1.65,"tv":2369.73,"id":5071877}]}]}
{"op":"mcm","clk":"1006591507","pt":1580598094090,"mc":[{"id":"1.168175457","rc":[{"trd":[[1.71,53]],"batl":[[0,1.71,318.04]],"ltp":1.71,"tv":2422.74,"id":5071877}],"tv":4175.6}]}
{"op":"mcm","clk":"1006592016","pt":1580598103284,"mc":[{"id":"1.168175457","rc":[{"trd":[[1.69,100.24]],"batb":[[0,1.65,243],[1,1.64,246.96],[2,1.56,66.01]],"batl":[[0,1.69,4.96],[1,1.71,318.04],[2,1.73,410.96]],"ltp":1.69,"tv":2522.98,"id":5071877}],"tv":4275.84}]}
{"op":"mcm","clk":"1006592150","pt":1580598105808,"mc":[{"id":"1.168175457","rc":[{"batl":[[0,1.71,318.04],[1,1.73,410.96],[2,1.74,35.15]],"ltp":1.69,"tv":2522.98,"id":5071877}]}]}
{"op":"mcm","clk":"1006592217","pt":1580598107098,"mc":[{"id":"1.168175457","rc":[{"trd":[[1.65,1250.86]],"batb":[[0,1.64,246.96],[1,1.56,66.01],[2,1.01,15.52]],"ltp":1.65,"tv":2846.48,"id":5071877}],"tv":4599.34}]}
{"op":"mcm","clk":"1006592371","pt":1580598110207,"mc":[{"id":"1.168175457","rc":[{"batb":[[0,1.64,429.1],[1,1.63,253.27],[2,1.56,66.01]],"batl":[[0,1.71,404.47]],"ltp":1.65,"tv":2846.48,"id":5071877}]}]}
{"op":"mcm","clk":"1006592520","pt":1580598113409,"mc":[{"id":"1.168175457","rc":[{"batb":[[0,1.65,18.73],[1,1.64,429.1],[2,1.63,253.27]],"ltp":1.65,"tv":2846.48,"id":5071877}]}]}
{"op":"mcm","clk":"1006592910","pt":1580598119422,"mc":[{"id":"1.168175457","rc":[{"trd":[[1.64,12.54],[1.65,1288.32]],"batb":[[0,1.64,422.83],[1,1.63,253.27],[2,1.56,66.01]],"ltp":1.64,"tv":2896.48,"id":5071877}],"tv":4649.34}]}
{"op":"mcm","clk":"1006593711","pt":1580598131525,"mc":[{"id":"1.168175457","rc":[{"trd":[[1.65,1288.64]],"batb":[[0,1.65,8.97],[1,1.64,422.83],[2,1.63,253.27]],"ltp":1.65,"tv":2896.79,"id":5071877}],"tv":4649.65}]}
{"op":"mcm","clk":"1006593761","pt":1580598132457,"mc":[{"id":"1.168175457","rc":[{"batb":[[0,1.56,66.01],[1,1.01,15.52],[2,1.63,0]],"batl":[[0,1.74,35.15],[1,2.16,342.82],[2,1.74,0]],"ltp":1.65,"tv":2896.79,"id":5071877}]}]}
{"op":"mcm","clk":"1006593804","pt":1580598133237,"mc":[{"id":"1.168175457","rc":[{"batl":[[0,1.64,126.03],[1,1.74,35.15],[2,2.16,342.82]],"ltp":1.65,"tv":2896.79,"id":5071877}]}]}
{"op":"mcm","clk":"1006593933","pt":1580598135148,"mc":[{"id":"1.168175457","rc":[{"batb":[[1,1.53,322.14],[2,1.52,329.75]],"batl":[[1,1.65,143.67],[2,1.74,35.15]],"ltp":1.65,"tv":2896.79,"id":5071877}]}]}
{"op":"mcm","clk":"1006594000","pt":1580598136137,"mc":[{"id":"1.168175457","rc":[{"batl":[[0,1.65,143.67],[1,1.74,35.15],[2,1.91,227.1]],"ltp":1.65,"tv":2896.79,"id":5071877}]}]}
{"op":"mcm","clk":"1006594087","pt":1580598137542,"mc":[{"id":"1.168175457","rc":[{"batl":[[2,2.16,342.82]],"ltp":1.65,"tv":2896.79,"id":5071877},{"batb":[[0,2.04,58.78],[1,1.01,15.51],[2,1.01,0]],"ltp":2.38,"tv":1752.85,"id":6374165}]}]}
{"op":"mcm","clk":"1006594097","pt":1580598137635,"mc":[{"id":"1.168175457","rc":[{"batb":[[0,1.53,322.14],[1,1.52,329.75],[2,1.01,15.52]],"ltp":1.65,"tv":2896.79,"id":5071877}]}]}
{"op":"mcm","clk":"1006594237","pt":1580598140370,"mc":[{"id":"1.168175457","rc":[{"batb":[[0,1.54,69.95],[1,1.53,322.14],[2,1.52,329.75]],"batl":[[0,1.58,347.29],[1,1.59,274.3],[2,1.64,156.68]],"ltp":1.65,"tv":2896.79,"id":5071877},{"batb":[[0,2.68,27.15],[1,2.32,39.89],[2,2.04,58.78]],"ltp":2.38,"tv":1752.85,"id":6374165}]}]}
{"op":"mcm","clk":"1006594304","pt":1580598141563,"mc":[{"id":"1.168175457","rc":[{"batl":[[2,1.63,42.01]],"ltp":1.65,"tv":2896.79,"id":5071877},{"batb":[[1,2.58,26.05],[2,2.32,39.89]],"ltp":2.38,"tv":1752.85,"id":6374165}]}]}
{"op":"mcm","clk":"1006594349","pt":1580598142238,"mc":[{"id":"1.168175457","rc":[{"batl":[[0,1.56,126.03],[1,1.58,347.29],[2,1.59,274.3]],"ltp":1.65,"tv":2896.79,"id":5071877}]}]}
{"op":"mcm","clk":"1006594423","pt":1580598143472,"mc":[{"id":"1.168175457","rc":[{"batl":[[0,3.9,158.24]],"ltp":2.38,"tv":1752.85,"id":6374165}]}]}
{"op":"mcm","clk":"1006594457","pt":1580598144144,"mc":[{"id":"1.168175457","rc":[{"batl":[[0,1.58,347.29],[1,1.59,274.3],[2,1.63,42.01]],"ltp":1.65,"tv":2896.79,"id":5071877}]}]}
{"op":"mcm","clk":"1006595126","pt":1580598154474,"mc":[{"id":"1.168175457","rc":[{"trd":[[1.53,112.16],[1.54,139.89]],"batb":[[0,1.45,90.02],[1,1.01,15.51],[2,1.52,0]],"batl":[[0,1.63,42.01],[1,1.74,35.15],[2,1.95,409.86]],"ltp":1.53,"tv":3148.85,"id":5071877}],"tv":4901.71}]}
{"op":"mcm","clk":"1006595186","pt":1580598155457,"mc":[{"id":"1.168175457","rc":[{"batl":[[0,1.74,35.15],[1,1.95,409.86],[2,1.95,0]],"ltp":1.53,"tv":3148.85,"id":5071877},{"batb":[[0,2.32,39.89],[1,1.01,15.51],[2,2.32,0]],"ltp":2.38,"tv":1752.85,"id":6374165}]}]}
{"op":"mcm","clk":"1006595307","pt":1580598157498,"mc":[{"id":"1.168175457","rc":[{"batb":[[1,1.44,599.65],[2,1.43,426.85]],"batl":[[0,1.73,297.61],[1,1.74,35.15],[2,1.75,396.25]],"ltp":1.53,"tv":3148.85,"id":5071877},{"batb":[[0,2.36,38.79],[1,2.32,39.89],[2,1.01,15.51]],"ltp":2.38,"tv":1752.85,"id":6374165}]}]}
{"op":"mcm","clk":"1006595363","pt":1580598158271,"mc":[{"id":"1.168175457","rc":[{"batb":[[0,1.44,599.66],[1,1.43,426.85],[2,1.01,15.51]],"ltp":1.53,"tv":3148.85,"id":5071877},{"batb":[[1,1.01,15.51],[2,1.01,0]],"ltp":2.38,"tv":1752.85,"id":6374165}]}]}
{"op":"mcm","clk":"1006597253","pt":1580598182409,"mc":[{"id":"1.168175457","rc":[{"trd":[[1.44,6.7],[1.48,0.02]],"batb":[[0,1.44,596.3]],"ltp":1.44,"tv":3155.57,"id":5071877}],"tv":4908.43}]}
{"op":"mcm","clk":"1006597767","pt":1580598190231,"mc":[{"id":"1.168175457","rc":[{"trd":[[1.44,13.42]],"batb":[[0,1.44,592.94]],"ltp":1.44,"tv":3162.29,"id":5071877}],"tv":4915.15}]}
{"op":"mcm","clk":"1006597849","pt":1580598191306,"mc":[{"id":"1.168175457","rc":[{"batb":[[0,1.44,92.14],[1,1.01,15.51],[2,1.01,0]],"ltp":1.44,"tv":3162.29,"id":5071877}]}]}
{"op":"mcm","clk":"1006598060","pt":1580598194517,"mc":[{"id":"1.168175457","rc":[{"batb":[[0,1.67,245.21],[1,1.66,236.74],[2,1.44,92.14]],"ltp":1.44,"tv":3162.29,"id":5071877},{"batb":[[0,1.01,15.51],[1,1.01,0]],"ltp":2.38,"tv":1752.85,"id":6374165}]}]}
{"op":"mcm","clk":"1006598147","pt":1580598195550,"mc":[{"id":"1.168175457","rc":[{"batb":[[0,1.68,51.22],[1,1.67,245.21],[2,1.66,236.74]],"ltp":1.44,"tv":3162.29,"id":5071877},{"batb":[[0,2.32,31.09],[1,2,60.66],[2,1.01,15.51]],"ltp":2.38,"tv":1752.85,"id":6374165}]}]}
{"op":"mcm","clk":"1006598288","pt":1580598197334,"mc":[{"id":"1.168175457","rc":[{"trd":[[1.66,1294.44],[1.67,490.42],[1.68,102.44]],"batb":[[0,1.66,66.86],[1,1.53,72.54],[2,1.01,15.51]],"ltp":1.66,"tv":4094.91,"id":5071877}],"tv":5847.77}]}
{"op":"mcm","clk":"1006598357","pt":1580598198420,"mc":[{"id":"1.168175457","rc":[{"batb":[[1,1.53,72.39]],"batl":[[0,1.74,35.15],[1,1.76,42.01],[2,1.75,0]],"ltp":1.66,"tv":4094.91,"id":5071877},{"batb":[[1,2.02,60.59],[2,2,60.66]],"ltp":2.38,"tv":1752.85,"id":6374165}]}]}
{"op":"mcm","clk":"1006598417","pt":1580598199411,"mc":[{"id":"1.168175457","rc":[{"batl":[[2,2.22,329.01]],"ltp":1.66,"tv":4094.91,"id":5071877},{"batl":[[0,3.15,200.42]],"ltp":2.38,"tv":1752.85,"id":6374165}]}]}
{"op":"mcm","clk":"1006598566","pt":1580598201541,"mc":[{"id":"1.168175457","rc":[{"batb":[[0,1.53,72.39],[1,1.01,15.51],[2,1.01,0]],"ltp":1.66,"tv":4094.91,"id":5071877}]}]}
{"op":"mcm","clk":"1006598709","pt":1580598203428,"mc":[{"id":"1.168175457","rc":[{"batl":[[0,1.68,3.36],[1,1.74,35.15]],"ltp":1.66,"tv":4094.91,"id":5071877},{"batb":[[0,2.02,60.59],[1,2,60.66],[2,1.01,15.51]],"ltp":2.38,"tv":1752.85,"id":6374165}]}]}
{"op":"mcm","clk":"1006598837","pt":1580598205318,"mc":[{"id":"1.168175457","rc":[{"batl":[[0,1.74,35.15],[1,2.22,329.01],[2,2.22,0]],"ltp":1.66,"tv":4094.91,"id":5071877}]}]}
{"op":"mcm","clk":"1006598904","pt":1580598206262,"mc":[{"id":"1.168175457","rc":[{"batb":[[0,1.7,367.38],[1,1.68,452.34],[2,1.53,72.39]],"batl":[[1,1.77,314.02],[2,1.79,368.64]],"ltp":1.66,"tv":4094.91,"id":5071877}]}]}
{"op":"mcm","clk":"1006599266","pt":1580598211565,"mc":[{"id":"1.168175457","rc":[{"trd":[[1.7,385.07]],"batb":[[0,1.7,223.71]],"ltp":1.7,"tv":4382.26,"id":5071877}],"tv":6135.12}]}
{"op":"mcm","clk":"1006599411","pt":1580598213546,"mc":[{"id":"1.168175457","rc":[{"batb":[[0,1.53,72.39],[1,1.01,15.51],[2,1.53,0]],"batl":[[1,2.22,329.01],[2,1.79,0]],"ltp":1.7,"tv":4382.26,"id":5071877}]}]}
{"op":"mcm","clk":"1006599504","pt":1580598215144,"mc":[{"id":"1.168175457","rc":[{"trd":[[1.7,422.03]],"ltp":1.7,"tv":4419.22,"id":5071877}],"tv":6172.08}]}
{"op":"mcm","clk":"1006599531","pt":1580598215764,"mc":[{"id":"1.168175457","rc":[{"batb":[[1,1.52,381.91],[2,1.51,340.03]],"batl":[[1,1.98,301.77],[2,2,261.57]],"ltp":1.7,"tv":4419.22,"id":5071877}]}]}
{"op":"mcm","clk":"1006599626","pt":1580598217269,"mc":[{"id":"1.168175457","rc":[{"batl":[[1,2.22,329.01],[2,2,0]],"ltp":1.7,"tv":4419.22,"id":5071877}]}]}
{"op":"mcm","clk":"1006599709","pt":1580598218466,"mc":[{"id":"1.168175457","rc":[{"batb":[[0,1.52,381.91],[1,1.51,340.03],[2,1.01,15.51]],"ltp":1.7,"tv":4419.22,"id":5071877}]}]}
{"op":"mcm","clk":"1006599747","pt":1580598219034,"mc":[{"id":"1.168175457","rc":[{"batl":[[1,2.22,0]],"ltp":1.7,"tv":4419.22,"id":5071877}]}]}
{"op":"mcm","clk":"1006599854","pt":1580598220433,"mc":[{"id":"1.168175457","rc":[{"batl":[[0,1.57,334.63],[1,1.58,281.81],[2,1.74,35.15]],"ltp":1.7,"tv":4419.22,"id":5071877}]}]}
{"op":"mcm","clk":"1006599936","pt":1580598221537,"mc":[{"id":"1.168175457","rc":[{"batb":[[0,1.52,455.71],[2,1.41,100.56]],"batl":[[2,1.63,42.01]],"ltp":1.7,"tv":4419.22,"id":5071877},{"batb":[[0,2.76,25.41],[1,2.58,26.05],[2,2.34,39.34]],"ltp":2.38,"tv":1752.85,"id":6374165}]}]}
{"op":"mcm","clk":"1006599990","pt":1580598222477,"mc":[{"id":"1.168175457","rc":[{"batl":[[0,3.9,158.24]],"ltp":2.38,"tv":1752.85,"id":6374165}]}]}
{"op":"mcm","clk":"1006600341","pt":1580598227344,"mc":[{"id":"1.168175457","rc":[{"trd":[[1.52,6.72]],"batb":[[0,1.52,452.35]],"ltp":1.52,"tv":4425.94,"id":5071877}],"tv":6178.8}]}
{"op":"mcm","clk":"1006600608","pt":1580598230562,"mc":[{"id":"1.168175457","rc":[{"trd":[[1.52,361.28]],"batb":[[0,1.52,275.07]],"ltp":1.52,"tv":4780.5,"id":5071877}],"tv":6533.36}]}
{"op":"mcm","clk":"1006600881","pt":1580598234356,"mc":[{"id":"1.168175457","rc":[{"trd":[[1.52,368]],"batb":[[0,1.52,378.58]],"batl":[[0,1.57,398.71]],"ltp":1.52,"tv":4787.22,"id":5071877}],"tv":6540.08}]}
{"op":"mcm","clk":"1006601541","pt":1580598243404,"mc":[{"id":"1.168175457","rc":[{"batb":[[0,1.41,100.56],[1,1.01,15.51],[2,1.41,0]],"batl":[[0,1.63,42.01],[1,1.74,35.15],[2,1.95,409.86]],"ltp":1.52,"tv":4787.22,"id":5071877},{"batb":[[0,2.58,26.05],[1,2.34,39.34],[2,1.01,15.51]],"ltp":2.38,"tv":1752.85,"id":6374165}]}]}
{"op":"mcm","clk":"1006601584","pt":1580598244023,"mc":[{"id":"1.168175457","rc":[{"batb":[[0,1.41,100.4]],"ltp":1.52,"tv":4787.22,"id":5071877}]}]}
{"op":"mcm","clk":"1006601649","pt":1580598244696,"mc":[{"id":"1.168175457","rc":[{"batl":[[0,1.74,35.15],[1,1.95,409.86],[2,1.95,0]],"ltp":1.52,"tv":4787.22,"id":5071877},{"batb":[[0,2.34,39.34],[1,1.01,15.51],[2,1.01,0]],"ltp":2.38,"tv":1752.85,"id":6374165}]}]}
{"op":"mcm","clk":"1006601896","pt":1580598247432,"mc":[{"id":"1.168175457","rc":[{"batl":[[0,1.52,12.6],[1,1.74,35.15],[2,1.95,409.86]],"ltp":1.52,"tv":4787.22,"id":5071877}]}]}
{"op":"mcm","clk":"1006601966","pt":1580598248105,"mc":[{"id":"1.168175457","rc":[{"trd":[[1.52,393.21]],"batb":[[0,1.55,273.86],[1,1.54,314.4],[2,1.41,100.4]],"batl":[[0,1.6,328.77],[1,1.61,263.44],[2,1.74,35.15]],"ltp":1.52,"tv":4812.43,"id":5071877}],"tv":6565.29}]}
{"op":"mcm","clk":"1006602391","pt":1580598252651,"mc":[{"id":"1.168175457","rc":[{"batl":[[0,3.65,170.41]],"ltp":2.38,"tv":1752.85,"id":6374165}]}]}
{"op":"mcm","clk":"1006602612","pt":1580598255451,"mc":[{"id":"1.168175457","rc":[{"batb":[[0,1.41,100.4],[1,1.01,15.51],[2,1.41,0]],"batl":[[0,1.74,35.15],[1,1.95,409.86],[2,1.74,0]],"ltp":1.52,"tv":4812.43,"id":5071877}]}]}
{"op":"mcm","clk":"1006602807","pt":1580598257953,"mc":[{"id":"1.168175457","rc":[{"batb":[[0,1.42,435.13],[1,1.41,556.42],[2,1.01,15.51]],"batl":[[0,1.74,269.19],[1,1.76,390.47],[2,1.95,409.86]],"ltp":1.52,"tv":4812.43,"id":5071877}]}]}
{"op":"mcm","clk":"1006603294","pt":1580598263855,"mc":[{"id":"1.168175457","rc":[{"batb":[[0,1.41,100.4],[1,1.01,15.51],[2,1.01,0]],"ltp":1.52,"tv":4812.43,"id":5071877}]}]}
{"op":"mcm","clk":"1006603484","pt":1580598266554,"mc":[{"id":"1.168175457","rc":[{"batl":[[2,1.95,0]],"ltp":1.52,"tv":4812.43,"id":5071877}]}]}
{"op":"mcm","clk":"1006603568","pt":1580598267544,"mc":[{"id":"1.168175457","rc":[{"batb":[[0,1.68,346.97],[1,1.67,232.61],[2,1.5,77.9]],"ltp":1.52,"tv":4812.43,"id":5071877},{"batb":[[1,1.93,34.38],[2,1.01,15.51]],"ltp":2.38,"tv":1752.85,"id":6374165}]}]}
{"op":"mcm","clk":"1006603577","pt":1580598267645,"mc":[{"id":"1.168175457","rc":[{"batl":[[2,1.79,42.01]],"ltp":1.52,"tv":4812.43,"id":5071877},{"batb":[[1,2.26,32.77],[2,1.93,34.38]],"ltp":2.38,"tv":1752.85,"id":6374165}]}]}
{"op":"mcm","clk":"1006603754","pt":1580598269870,"mc":[{"id":"1.168175457","rc":[{"batl":[[0,3.15,200.42]],"ltp":2.38,"tv":1752.85,"id":6374165}]}]}
{"op":"mcm","clk":"1006604502","pt":1580598279961,"mc":[{"id":"1.168175457","rc":[{"trd":[[1.74,97.5]],"batl":[[0,1.74,266.15]],"ltp":1.74,"tv":4818.51,"id":5071877}],"tv":6571.37}]}
{"op":"mcm","clk":"1006605346","pt":1580598291510,"mc":[{"id":"1.168175457","rc":[{"batb":[[0,1.5,77.9],[1,1.01,15.51],[2,1.5,0]],"batl":[[0,1.74,32.11],[1,1.79,42.01],[2,2.22,329.01]],"ltp":1.74,"tv":4818.51,"id":5071877},{"batb":[[0,2.26,32.77],[1,1.93,34.38],[2,1.01,15.51]],"ltp":2.38,"tv":1752.85,"id":6374165}]}]}
{"op":"mcm","clk":"1006605478","pt":1580598293183,"mc":[{"id":"1.168175457","rc":[{"batl":[[1,2.22,329.01],[2,2.22,0]],"ltp":1.74,"tv":4818.51,"id":5071877},{"batb":[[0,1.93,34.38],[1,1.01,15.51],[2,1.01,0]],"ltp":2.38,"tv":1752.85,"id":6374165}]}]}
{"op":"mcm","clk":"1006605573","pt":1580598294381,"mc":[{"id":"1.168175457","rc":[{"batb":[[0,1.5,397.51],[1,1.49,359],[2,1.01,15.51]],"batl":[[1,2.1,188.73],[2,2.12,220.73]],"ltp":1.74,"tv":4818.51,"id":5071877},{"batb":[[0,1.94,34.23],[1,1.93,34.38],[2,1.01,15.51]],"ltp":2.38,"tv":1752.85,"id":6374165}]}]}
{"op":"mcm","clk":"1006605592","pt":1580598294589,"mc":[{"id":"1.168175457","rc":[{"batb":[[1,1.01,15.51],[2,1.01,0]],"ltp":2.38,"tv":1752.85,"id":6374165}]}]}
{"op":"mcm","clk":"1006606015","pt":1580598299129,"mc":[{"id":"1.168175457","rc":[{"batl":[[1,2.22,329.01],[2,2.12,0]],"ltp":1.74,"tv":4818.51,"id":5071877}]}]}
{"op":"mcm","clk":"1006606325","pt":1580598302501,"mc":[{"id":"1.168175457","rc":[{"batb":[[2,1.37,113.85]],"batl":[[0,1.55,455.08],[1,1.56,295.22],[2,1.74,32.11]],"ltp":1.74,"tv":4818.51,"id":5071877},{"batb":[[0,2.84,23.68],[1,2.32,40.05],[2,1.94,34.23]],"ltp":2.38,"tv":1752.85,"id":6374165}]}]}
{"op":"mcm","clk":"1006606345","pt":1580598302713,"mc":[{"id":"1.168175457","rc":[{"batb":[[2,1.01,15.51]],"ltp":2.38,"tv":1752.85,"id":6374165}]}]}
{"op":"mcm","clk":"1006606493","pt":1580598304393,"mc":[{"id":"1.168175457","rc":[{"batl":[[2,1.61,42.01]],"ltp":1.74,"tv":4818.51,"id":5071877},{"batb":[[1,2.64,25.21],[2,2.32,40.05]],"ltp":2.38,"tv":1752.85,"id":6374165}]}]}
{"op":"mcm","clk":"1006606658","pt":1580598306008,"mc":[{"id":"1.168175457","rc":[{"batl":[[0,3.9,158.24]],"ltp":2.38,"tv":1752.85,"id":6374165}]}]}
{"op":"mcm","clk":"1006607265","pt":1580598312537,"mc":[{"id":"1.168175457","rc":[{"trd":[[1.55,313.12]],"batl":[[0,1.55,298.52]],"ltp":1.55,"tv":5131.63,"id":5071877}],"tv":6884.49}]}
{"op":"mcm","clk":"1006607507","pt":1580598315448,"mc":[{"id":"1.168175457","rc":[{"batb":[[0,1.5,456.86]],"batl":[[0,1.55,397.74]],"ltp":1.55,"tv":5131.63,"id":5071877}]}]}
{"op":"mcm","clk":"1006607749","pt":1580598318519,"mc":[{"id":"1.168175457","rc":[{"batb":[[0,1.5,77.9],[1,1.37,113.85],[2,1.01,15.51]],"batl":[[0,1.61,42.01],[1,1.74,32.11],[2,1.95,409.86]],"ltp":1.55,"tv":5131.63,"id":5071877}]}]}
{"op":"mcm","clk":"1006607789","pt":1580598318936,"mc":[{"id":"1.168175457","rc":[{"batb":[[0,1.37,113.85],[1,1.01,15.51],[2,1.01,0]],"batl":[[0,1.74,32.11],[1,1.95,409.86],[2,1.95,0]],"ltp":1.55,"tv":5131.63,"id":5071877},{"batb":[[0,2.32,40.05],[1,1.01,15.51],[2,2.32,0]],"ltp":2.38,"tv":1752.85,"id":6374165}]}]}
{"op":"mcm","clk":"1006608000","pt":1580598321462,"mc":[{"id":"1.168175457","rc":[{"batb":[[0,1.39,297.22],[1,1.38,501.86],[2,1.37,113.85]],"batl":[[1,1.76,362.61],[2,1.78,375.51]],"ltp":1.55,"tv":5131.63,"id":5071877}]}]}
{"op":"mcm","clk":"1006609047","pt":1580598334169,"mc":[{"id":"1.168175457","rc":[{"batb":[[0,1.37,113.85],[1,1.01,15.51],[2,1.37,0]],"ltp":1.55,"tv":5131.63,"id":5071877}]}]}
{"op":"mcm","clk":"1006609354","pt":1580598337450,"mc":[{"id":"1.168175457","rc":[{"batb":[[0,1.69,391.44],[1,1.67,462.19],[2,1.5,76.87]],"ltp":1.55,"tv":5131.63,"id":5071877},{"batb":[[1,1.92,34.86],[2,1.01,15.51]],"ltp":2.38,"tv":1752.85,"id":6374165}]}]}
{"op":"mcm","clk":"1006609395","pt":1580598337964,"mc":[{"id":"1.168175457","rc":[{"batb":[[1,2.26,32.77],[2,1.92,34.86]],"ltp":2.38,"tv":1752.85,"id":6374165}]}]}
{"op":"mcm","clk":"1006609584","pt":1580598340153,"mc":[{"id":"1.168175457","rc":[{"batl":[[0,3.15,200.42]],"ltp":2.38,"tv":1752.85,"id":6374165}]}]}
{"op":"mcm","clk":"1006610812","pt":1580598356810,"mc":[{"id":"1.168175457","rc":[{"trd":[[1.69,130.53]],"batb":[[0,1.69,376.3]],"ltp":1.69,"tv":5161.91,"id":5071877}],"tv":6914.77}]}
{"op":"mcm","clk":"1006611271","pt":1580598363260,"mc":[{"id":"1.168175457","rc":[{"batb":[[0,1.5,76.87],[1,1.01,15.51],[2,1.5,0]],"batl":[[1,2.22,329.01],[2,1.78,0]],"ltp":1.69,"tv":5161.91,"id":5071877},{"batb":[[0,1.92,34.86],[1,1.01,15.51],[2,1.92,0]],"ltp":2.38,"tv":1752.85,"id":6374165}]}]}
{"op":"mcm","clk":"1006611522","pt":1580598366469,"mc":[{"id":"1.168175457","rc":[{"batb":[[0,1.93,34.31]],"ltp":2.38,"tv":1752.85,"id":6374165}]}]}
{"op":"mcm","clk":"1006611657","pt":1580598368083,"mc":[{"id":"1.168175457","rc":[{"trd":[[1.74,161.73]],"batb":[[0,1.75,241.05],[1,1.73,408.52],[2,1.5,76.87]],"batl":[[0,1.82,299.25],[1,1.84,337.82],[2,2.22,329.01]],"ltp":1.74,"tv":5226.14,"id":5071877}],"tv":6979.0}]}
{"op":"mcm","clk":"1006611817","pt":1580598370362,"mc":[{"id":"1.168175457","rc":[{"batl":[[0,3,213.45]],"ltp":2.38,"tv":1752.85,"id":6374165}]}]}
{"op":"mcm","clk":"1006612128","pt":1580598374718,"mc":[{"id":"1.168175457","rc":[{"batb":[[0,1.5,76.87],[1,1.01,15.51],[2,1.5,0]],"batl":[[0,2.22,329.01],[1,1.84,0],[2,2.22,0]],"ltp":1.74,"tv":5226.14,"id":5071877}]}]}
{"op":"mcm","clk":"1006612428","pt":1580598378494,"mc":[{"id":"1.168175457","rc":[{"batb":[[0,1.5,675.51],[1,1.49,360.46],[2,1.01,15.51]],"batl":[[0,2.12,215.44],[1,2.14,214.8],[2,2.22,329.01]],"ltp":1.74,"tv":5226.14,"id":5071877}]}]}
{"op":"mcm","clk":"1006614339","pt":1580598405144,"mc":[{"id":"1.168175457","rc":[{"batb":[[0,1.5,76.87],[1,1.01,15.51],[2,1.01,0]],"batl":[[0,2.22,329.01],[1,2.14,0],[2,2.22,0]],"ltp":1.74,"tv":5226.14,"id":5071877}]}]}
{"op":"mcm","clk":"1006615717","pt":1580598424511,"mc":[{"id":"1.168175457","rc":[{"batb":[[0,1.99,59.48],[1,1.69,50.2],[2,1.5,76.87]],"batl":[[0,2.18,35.29]],"ltp":1.74,"tv":5226.14,"id":5071877},{"batb":[[1,1.86,48.73],[2,1.61,63.5]],"ltp":2.38,"tv":1752.85,"id":6374165}]}]}
{"op":"mcm","clk":"1006615738","pt":1580598424714,"mc":[{"id":"1.168175457","rc":[{"batb":[[2,1.52,25.24]],"ltp":1.74,"tv":5226.14,"id":5071877}]}]}
{"op":"mcm","clk":"1006615873","pt":1580598426447,"mc":[{"id":"1.168175457","rc":[{"batl":[[1,2.6,257.57]],"ltp":1.74,"tv":5226.14,"id":5071877},{"batl":[[0,2.6,257.57]],"ltp":2.38,"tv":1752.85,"id":6374165}]}]}
{"op":"mcm","clk":"1006616404","pt":1580598433428,"mc":[{"id":"1.168175457","rc":[{"batb":[[0,1.69,50.2],[1,1.01,15.51],[2,1.52,0]],"ltp":1.74,"tv":5226.14,"id":5071877},{"batb":[[0,1.86,48.73],[1,1.61,63.5],[2,1.01,15.51]],"ltp":2.38,"tv":1752.85,"id":6374165}]}]}
{"op":"mcm","clk":"1006616533","pt":1580598435036,"mc":[{"id":"1.168175457","rc":[{"batl":[[0,2.6,257.57],[1,2.6,0]],"ltp":1.74,"tv":5226.14,"id":5071877},{"batb":[[0,1.61,63.5],[1,1.01,15.51],[2,1.01,0]],"ltp":2.38,"tv":1752.85,"id":6374165}]}]}
{"op":"mcm","clk":"1006616662","pt":1580598436548,"mc":[{"id":"1.168175457","rc":[{"batb":[[0,1.69,49.96]],"ltp":1.74,"tv":5226.14,"id":5071877},{"batb":[[0,1.6,63.81],[1,1.53,328.47],[2,1.52,328.23]],"batl":[[0,2.44,285.99],[1,2.48,290.01],[2,2.6,257.57]],"ltp":2.38,"tv":1752.85,"id":6374165}]}]}
{"op":"mcm","clk":"1006616871","pt":1580598439054,"mc":[{"id":"1.168175457","rc":[{"batl":[[0,1.93,2.36],[1,2.44,285.99],[2,2.48,290.01]],"ltp":2.38,"tv":1752.85,"id":6374165}]}]}
{"op":"mcm","clk":"1006617334","pt":1580598444333,"mc":[{"id":"1.168175457","rc":[{"batb":[[1,1.01,15.51],[2,1.52,0]],"batl":[[1,2.6,257.57],[2,2.48,0]],"ltp":2.38,"tv":1752.85,"id":6374165}]}]}
{"op":"mcm","clk":"1006617425","pt":1580598445529,"mc":[{"id":"1.168175457","rc":[{"batl":[[1,2.6,0]],"ltp":2.38,"tv":1752.85,"id":6374165}]}]}
{"op":"mcm","clk":"1006617493","pt":1580598446562,"mc":[{"id":"1.168175457","rc":[{"batl":[[0,1.62,75.72],[1,1.93,2.36]],"ltp":2.38,"tv":1752.85,"id":6374165}]}]}
{"op":"mcm","clk":"1006617578","pt":1580598447552,"mc":[{"id":"1.168175457","rc":[{"trd":[[2.06,2.21],[2.6,47.18]],"batb":[[0,1.7,287.81],[1,1.69,49.96],[2,1.68,452.35]],"batl":[[0,1.77,341.12],[1,1.79,368.69]],"ltp":2.06,"tv":5275.53,"id":5071877},{"trd":[[1.62,75.72],[1.93,2.36]],"batb":[[0,2.32,39.89],[1,1.93,34.7],[2,1.01,15.51]],"ltp":1.93,"tv":1830.94,"id":6374165}],"tv":7106.48}]}
{"op":"mcm","clk":"1006617728","pt":1580598449544,"mc":[{"id":"1.168175457","rc":[{"batl":[[2,2.22,329.01]],"ltp":2.06,"tv":5275.53,"id":5071877},{"batl":[[0,3.15,200.42]],"ltp":1.93,"tv":1830.94,"id":6374165}]}]}
{"op":"mcm","clk":"1006617791","pt":1580598450385,"mc":[{"id":"1.168175457","rc":[{"batl":[[2,1.82,42.01]],"ltp":2.06,"tv":5275.53,"id":5071877},{"batb":[[1,2.22,33.61],[2,1.93,34.7]],"ltp":1.93,"tv":1830.94,"id":6374165}]}]}
{"op":"mcm","clk":"1006618629","pt":1580598460481,"mc":[{"id":"1.168175457","rc":[{"trd":[[1.7,427.01]],"batb":[[0,1.7,285.32]],"ltp":1.7,"tv":5280.51,"id":5071877}],"tv":7111.46}]}
{"op":"mcm","clk":"1006618833","pt":1580598463251,"mc":[{"id":"1.168175457","rc":[{"batl":[[0,1.77,396.64]],"ltp":1.7,"tv":5280.51,"id":5071877}]}]}
{"op":"mcm","clk":"1006619253","pt":1580598469562,"mc":[{"id":"1.168175457","rc":[{"trd":[[1.7,617.57]],"batb":[[0,1.7,190.04]],"ltp":1.7,"tv":5471.08,"id":5071877}],"tv":7302.02}]}
{"op":"mcm","clk":"1006619332","pt":1580598470563,"mc":[{"id":"1.168175457","rc":[{"batb":[[0,1.5,76.87],[1,1.01,15.51],[2,1.68,0]],"batl":[[0,1.7,2.5],[1,1.82,42.01],[2,2.22,329.01]],"ltp":1.7,"tv":5471.08,"id":5071877},{"batb":[[0,2.22,33.61],[1,1.93,34.7],[2,1.01,15.51]],"ltp":1.93,"tv":1830.94,"id":6374165}]}]}
{"op":"mcm","clk":"1006619422","pt":1580598471557,"mc":[{"id":"1.168175457","rc":[{"batl":[[1,2.22,329.01],[2,2.22,0]],"ltp":1.7,"tv":5471.08,"id":5071877},{"batb":[[0,1.93,34.7],[1,1.01,15.51],[2,1.01,0]],"ltp":1.93,"tv":1830.94,"id":6374165}]}]}
{"op":"mcm","clk":"1006619614","pt":1580598473555,"mc":[{"id":"1.168175457","rc":[{"batb":[[0,1.51,75.85]],"batl":[[0,2.22,329.01],[1,2.22,0]],"ltp":1.7,"tv":5471.08,"id":5071877},{"batb":[[0,1.92,35.25]],"ltp":1.93,"tv":1830.94,"id":6374165}]}]}
{"op":"mcm","clk":"1006619697","pt":1580598474546,"mc":[{"id":"1.168175457","rc":[{"batb":[[0,1.75,393.59],[1,1.73,409.24],[2,1.51,75.85]],"batl":[[0,1.83,355.96],[1,1.85,332.25],[2,2.22,329.01]],"ltp":1.7,"tv":5471.08,"id":5071877}]}]}
{"op":"mcm","clk":"1006619911","pt":1580598477262,"mc":[{"id":"1.168175457","rc":[{"batl":[[0,3,213.45]],"ltp":1.93,"tv":1830.94,"id":6374165}]}]}
{"op":"mcm","clk":"1006620330","pt":1580598481931,"mc":[{"id":"1.168175457","rc":[{"trd":[[1.51,5]],"batb":[[0,1.51,73.35],[1,1.01,15.51],[2,1.51,0]],"batl":[[0,2.22,329.01],[1,1.85,0],[2,2.22,0]],"ltp":1.51,"tv":5476.08,"id":5071877}],"tv":7307.02}]}
{"op":"mcm","clk":"1006620633","pt":1580598485364,"mc":[{"id":"1.168175457","rc":[{"batb":[[0,1.51,475.37],[1,1.5,349.9],[2,1.01,15.51]],"batl":[[0,2.14,323.71],[1,2.16,209.41],[2,2.22,329.01]],"ltp":1.51,"tv":5476.08,"id":5071877}]}]}
{"op":"mcm","clk":"1006620962","pt":1580598489184,"mc":[{"id":"1.168175457","rc":[{"batl":[[0,2.22,329.01],[1,2.16,0],[2,2.22,0]],"ltp":1.51,"tv":5476.08,"id":5071877}]}]}
{"op":"mcm","clk":"1006621213","pt":1580598492370,"mc":[{"id":"1.168175457","rc":[{"batb":[[2,1.38,109.92]],"batl":[[0,1.56,343.54],[1,1.57,288.88]],"ltp":1.51,"tv":5476.08,"id":5071877},{"batb":[[0,2.8,24.55],[1,2.28,41.78],[2,1.92,35.25]],"ltp":1.93,"tv":1830.94,"id":6374165}]}]}
{"op":"mcm","clk":"1006621240","pt":1580598492683,"mc":[{"id":"1.168175457","rc":[{"batb":[[2,1.01,15.51]],"ltp":1.93,"tv":1830.94,"id":6374165}]}]}
{"op":"mcm","clk":"1006621395","pt":1580598494563,"mc":[{"id":"1.168175457","rc":[{"batl":[[2,1.62,42.01]],"ltp":1.51,"tv":5476.08,"id":5071877},{"batb":[[1,2.6,26.05],[2,2.28,41.78]],"batl":[[0,3.9,158.24]],"ltp":1.93,"tv":1830.94,"id":6374165}]}]}
{"op":"mcm","clk":"1006622396","pt":1580598506503,"mc":[{"id":"1.168175457","rc":[{"trd":[[1.51,35]],"batb":[[0,1.51,460.37]],"ltp":1.51,"tv":5506.08,"id":5071877}],"tv":7337.02}]}
{"op":"mcm","clk":"1006622547","pt":1580598508375,"mc":[{"id":"1.168175457","rc":[{"trd":[[1.51,115.7]],"batb":[[0,1.51,379.67]],"ltp":1.51,"tv":5586.78,"id":5071877},{"trd":[[2.98,40.89]],"ltp":2.98,"tv":1871.83,"id":6374165}],"tv":7458.61}]}
{"op":"mcm","clk":"1006622900","pt":1580598512298,"mc":[{"id":"1.168175457","rc":[{"batb":[[0,1.38,109.92],[1,1.01,15.51],[2,1.38,0]],"batl":[[0,1.62,42.01],[1,1.95,409.86],[2,1.62,0]],"ltp":1.51,"tv":5586.78,"id":5071877},{"batb":[[0,2.6,26.05],[1,2.28,41.78],[2,1.01,15.51]],"ltp":2.98,"tv":1871.83,"id":6374165}]}]}
{"op":"mcm","clk":"1006622996","pt":1580598513391,"mc":[{"id":"1.168175457","rc":[{"batl":[[0,1.95,409.86],[1,1.95,0]],"ltp":1.51,"tv":5586.78,"id":5071877},{"batb":[[0,2.28,41.78],[1,1.01,15.51],[2,1.01,0]],"ltp":2.98,"tv":1871.83,"id":6374165}]}]}
{"op":"mcm","clk":"1006623183","pt":1580598515519,"mc":[{"id":"1.168175457","rc":[{"batb":[[0,1.39,598.92],[1,1.38,506.4],[2,1.37,112.44]],"batl":[[0,1.51,15],[1,1.77,283.48],[2,1.79,369.63]],"ltp":1.51,"tv":5586.78,"id":5071877},{"batb":[[0,2.32,40.6]],"ltp":2.98,"tv":1871.83,"id":6374165}]}]}
{"op":"mcm","clk":"1006623815","pt":1580598522539,"mc":[{"id":"1.168175457","rc":[{"batl":[[1,1.95,409.86],[2,1.79,0]],"ltp":1.51,"tv":5586.78,"id":5071877}]}]}
{"op":"mcm","clk":"1006624074","pt":1580598525474,"mc":[{"id":"1.168175457","rc":[{"trd":[[1.39,1.18]],"batb":[[0,1.39,598.33]],"batl":[[0,1.43,302.73],[1,1.44,407.71],[2,1.51,15]],"ltp":1.39,"tv":5587.96,"id":5071877}],"tv":7459.79}]}
{"op":"mcm","clk":"1006624162","pt":1580598526461,"mc":[{"id":"1.168175457","rc":[{"batl":[[2,1.49,42.01]],"ltp":1.39,"tv":5587.96,"id":5071877},{"batb":[[0,3.4,37.69],[1,3.05,68.95],[2,1.01,15.51]],"ltp":2.98,"tv":1871.83,"id":6374165}]}]}
{"op":"mcm","clk":"1006624406","pt":1580598529059,"mc":[{"id":"1.168175457","rc":[{"batl":[[0,4.6,136.05]],"ltp":2.98,"tv":1871.83,"id":6374165}]}]}
{"op":"mcm","clk":"1006625425","pt":1580598541496,"mc":[{"id":"1.168175457","rc":[{"trd":[[1.39,288.52],[1.42,49.84]],"batb":[[0,1.39,454.66]],"ltp":1.42,"tv":5925.14,"id":5071877},{"trd":[[3.4,20.82]],"batb":[[0,3.4,16.87]],"ltp":3.4,"tv":1892.65,"id":6374165}],"tv":7817.79}]}
{"op":"mcm","clk":"1006625589","pt":1580598543490,"mc":[{"id":"1.168175457","rc":[{"trd":[[1.39,313.52]],"batb":[[0,1.39,442.16]],"ltp":1.39,"tv":5950.14,"id":5071877}],"tv":7842.79}]}
{"op":"mcm","clk":"1006625677","pt":1580598544486,"mc":[{"id":"1.168175457","rc":[{"batb":[[0,1.39,532.87]],"batl":[[0,1.43,354.09]],"ltp":1.39,"tv":5950.14,"id":5071877}]}]}
{"op":"mcm","clk":"1006626277","pt":1580598552585,"mc":[{"id":"1.168175457","rc":[{"trd":[[3.4,38.5]],"batb":[[0,3.4,8.03]],"ltp":3.4,"tv":1910.33,"id":6374165}],"tv":7860.48}]}
{"op":"mcm","clk":"1006627118","pt":1580598563119,"mc":[{"id":"1.168175457","rc":[{"batb":[[0,1.37,112.44],[1,1.29,151.46],[2,1.01,15.51]],"batl":[[0,1.49,42.01],[1,1.82,469.11],[2,1.49,0]],"ltp":1.39,"tv":5950.14,"id":5071877}]}]}
{"op":"mcm","clk":"1006627361","pt":1580598566395,"mc":[{"id":"1.168175457","rc":[{"batb":[[0,1.31,557.15],[1,1.3,683.96],[2,1.29,151.46]],"batl":[[0,1.49,312.84],[1,1.5,345.31],[2,1.82,469.11]],"ltp":1.39,"tv":5950.14,"id":5071877},{"batb":[[0,3.05,68.95],[1,1.01,15.51],[2,1.01,0]],"ltp":3.4,"tv":1910.33,"id":6374165}]}]}
{"op":"mcm","clk":"1006627439","pt":1580598567399,"mc":[{"id":"1.168175457","rc":[{"batl":[[0,1.49,270.83]],"ltp":1.39,"tv":5950.14,"id":5071877},{"batb":[[0,3.05,48.78]],"ltp":3.4,"tv":1910.33,"id":6374165}]}]}
{"op":"mcm","clk":"1006627519","pt":1580598568389,"mc":[{"id":"1.168175457","rc":[{"batb":[[0,1.29,151.46],[1,1.01,15.51],[2,1.29,0]],"batl":[[0,1.82,469.11],[1,1.5,0],[2,1.82,0]],"ltp":1.39,"tv":5950.14,"id":5071877}]}]}
{"op":"mcm","clk":"1006627610","pt":1580598569532,"mc":[{"id":"1.168175457","rc":[{"batb":[[0,1.3,145.25]],"ltp":1.39,"tv":5950.14,"id":5071877},{"batb":[[0,3,51.62]],"ltp":3.4,"tv":1910.33,"id":6374165}]}]}
{"op":"mcm","clk":"1006627764","pt":1580598571513,"mc":[{"id":"1.168175457","rc":[{"batb":[[0,1.37,713.24],[1,1.36,544.47],[2,1.3,145.25]],"batl":[[0,1.41,302.71],[1,1.42,433.61],[2,1.82,469.11]],"ltp":1.39,"tv":5950.14,"id":5071877}]}]}
{"op":"mcm","clk":"1006628032","pt":1580598574909,"mc":[{"id":"1.168175457","rc":[{"batb":[[0,1.3,145.25],[1,1.01,15.51],[2,1.3,0]],"batl":[[0,1.82,469.11],[1,1.42,0],[2,1.82,0]],"ltp":1.39,"tv":5950.14,"id":5071877}]}]}
{"op":"mcm","clk":"1006628292","pt":1580598578139,"mc":[{"id":"1.168175457","rc":[{"batb":[[0,1.31,582.3],[1,1.3,829.27],[2,1.01,15.51]],"batl":[[0,1.5,593],[1,1.51,334.08],[2,1.82,469.11]],"ltp":1.39,"tv":5950.14,"id":5071877}]}]}
{"op":"mcm","clk":"1006628666","pt":1580598582552,"mc":[{"id":"1.168175457","rc":[{"batb":[[0,1.3,145.25],[1,1.01,15.51],[2,1.01,0]],"ltp":1.39,"tv":5950.14,"id":5071877}]}]}
{"op":"mcm","clk":"1006628880","pt":1580598585538,"mc":[{"id":"1.168175457","rc":[{"batb":[[0,1.45,387.03],[1,1.44,415.68],[2,1.3,145.25]],"ltp":1.39,"tv":5950.14,"id":5071877}]}]}
{"op":"mcm","clk":"1006628942","pt":1580598586420,"mc":[{"id":"1.168175457","rc":[{"batb":[[0,1.45,475.31],[2,1.37,113.38]],"batl":[[2,1.54,42.01]],"ltp":1.39,"tv":5950.14,"id":5071877},{"batb":[[1,2.86,21.85],[2,2.76,25.26]],"ltp":3.4,"tv":1910.33,"id":6374165}]}]}
{"op":"mcm","clk":"1006629097","pt":1580598588568,"mc":[{"id":"1.168175457","rc":[{"batl":[[0,4.2,148.03]],"ltp":3.4,"tv":1910.33,"id":6374165}]}]}
{"op":"mcm","clk":"1006629887","pt":1580598598273,"mc":[{"id":"1.168175457","rc":[{"batb":[[0,1.37,113.38],[1,1.01,15.51],[2,1.37,0]],"batl":[[0,1.54,42.01],[1,1.82,469.11],[2,1.54,0]],"ltp":1.39,"tv":5950.14,"id":5071877},{"batb":[[0,2.86,21.85],[1,2.76,25.26],[2,1.01,15.51]],"ltp":3.4,"tv":1910.33,"id":6374165}]}]}
{"op":"mcm","clk":"1006629981","pt":1580598599396,"mc":[{"id":"1.168175457","rc":[{"batl":[[0,1.82,469.11],[1,1.82,0]],"ltp":1.39,"tv":5950.14,"id":5071877},{"batb":[[0,2.76,25.26],[1,1.01,15.51],[2,1.01,0]],"ltp":3.4,"tv":1910.33,"id":6374165}]}]}
{"op":"mcm","clk":"1006630170","pt":1580598601464,"mc":[{"id":"1.168175457","rc":[{"batb":[[0,1.38,552.05],[1,1.37,634.31],[2,1.01,15.51]],"batl":[[0,1.56,497.48],[1,1.57,287.06],[2,1.82,469.11]],"ltp":1.39,"tv":5950.14,"id":5071877}]}]}
{"op":"mcm","clk":"1006630407","pt":1580598604379,"mc":[{"id":"1.168175457","rc":[{"batb":[[0,1.37,113.38],[1,1.01,15.51],[2,1.01,0]],"ltp":1.39,"tv":5950.14,"id":5071877}]}]}
{"op":"mcm","clk":"1006630475","pt":1580598605258,"mc":[{"id":"1.168175457","rc":[{"batb":[[0,1.01,15.51],[1,1.01,0]],"ltp":3.4,"tv":1910.33,"id":6374165}]}]}
{"op":"mcm","clk":"1006630641","pt":1580598607555,"mc":[{"id":"1.168175457","rc":[{"batb":[[0,1.5,583.09],[1,1.49,359.48],[2,1.37,113.38]],"ltp":1.39,"tv":5950.14,"id":5071877}]}]}
{"op":"mcm","clk":"1006630730","pt":1580598608491,"mc":[{"id":"1.168175457","rc":[{"batb":[[0,1.52,73.17],[1,1.5,583.09],[2,1.49,359.48]],"batl":[[2,1.59,42.01]],"ltp":1.39,"tv":5950.14,"id":5071877},{"batb":[[0,2.74,49.18],[1,2.6,29.82],[2,1.01,15.51]],"ltp":3.4,"tv":1910.33,"id":6374165}]}]}
{"op":"mcm","clk":"1006630914","pt":1580598610696,"mc":[{"id":"1.168175457","rc":[{"batl":[[0,3.9,158.24]],"ltp":3.4,"tv":1910.33,"id":6374165}]}]}
{"op":"mcm","clk":"1006631518","pt":1580598618548,"mc":[{"id":"1.168175457","rc":[{"batb":[[1,1.5,490.03]],"batl":[[0,1.56,295.62],[1,1.59,42.01],[2,1.82,469.11]],"ltp":1.39,"tv":5950.14,"id":5071877}]}]}
{"op":"mcm","clk":"1006631564","pt":1580598619130,"mc":[{"id":"1.168175457","rc":[{"batb":[[0,1.46,87.34],[1,1.01,15.51],[2,1.49,0]],"batl":[[0,1.82,469.11],[1,1.59,0],[2,1.82,0]],"ltp":1.39,"tv":5950.14,"id":5071877},{"batb":[[0,2.6,29.82],[1,1.01,15.51],[2,1.01,0]],"ltp":3.4,"tv":1910.33,"id":6374165}]}]}
{"op":"mcm","clk":"1006631758","pt":1580598621534,"mc":[{"id":"1.168175457","rc":[{"batl":[[0,1.55,293.42],[1,1.82,469.11]],"ltp":1.39,"tv":5950.14,"id":5071877}]}]}
{"op":"mcm","clk":"1006631858","pt":1580598622466,"mc":[{"id":"1.168175457","rc":[{"batb":[[0,1.45,88.28]],"ltp":1.39,"tv":5950.14,"id":5071877},{"batb":[[0,2.6,29.35]],"ltp":3.4,"tv":1910.33,"id":6374165}]}]}
{"op":"mcm","clk":"1006631944","pt":1580598623346,"mc":[{"id":"1.168175457","rc":[{"batb":[[0,1.49,457.54],[1,1.48,369.47],[2,1.45,88.28]],"batl":[[0,1.54,360.1],[1,1.55,293.42],[2,1.82,469.11]],"ltp":1.39,"tv":5950.14,"id":5071877}]}]}
{"op":"mcm","clk":"1006632268","pt":1580598627546,"mc":[{"id":"1.168175457","rc":[{"batb":[[0,1.45,88.28],[1,1.01,15.51],[2,1.45,0]],"batl":[[0,1.82,469.11],[1,1.55,0],[2,1.82,0]],"ltp":1.39,"tv":5950.14,"id":5071877}]}]}
{"op":"mcm","clk":"1006632487","pt":1580598630554,"mc":[{"id":"1.168175457","rc":[{"batb":[[0,1.45,459.12],[1,1.44,414.45],[2,1.01,15.51]],"batl":[[0,1.59,341.67],[1,1.6,268.92],[2,1.82,469.11]],"ltp":1.39,"tv":5950.14,"id":5071877}]}]}
{"op":"mcm","clk":"1006632637","pt":1580598632431,"mc":[{"id":"1.168175457","rc":[{"batl":[[0,1.82,469.11],[1,1.6,0],[2,1.82,0]],"ltp":1.39,"tv":5950.14,"id":5071877}]}]}
{"op":"mcm","clk":"1006632862","pt":1580598635441,"mc":[{"id":"1.168175457","rc":[{"batl":[[0,1.49,260.61],[1,1.5,344.26],[2,1.82,469.11]],"ltp":1.39,"tv":5950.14,"id":5071877}]}]}
{"op":"mcm","clk":"1006632960","pt":1580598636428,"mc":[{"id":"1.168175457","rc":[{"batb":[[2,1.36,117.63]],"batl":[[2,1.54,42.01]],"ltp":1.39,"tv":5950.14,"id":5071877},{"batb":[[0,3,51.62],[1,2.86,21.85],[2,2.74,25.97]],"ltp":3.4,"tv":1910.33,"id":6374165}]}]}
{"op":"mcm","clk":"1006633991","pt":1580598649472,"mc":[{"id":"1.168175457","rc":[{"batb":[[0,1.45,88.28],[1,1.36,117.63],[2,1.01,15.51]],"batl":[[0,1.54,42.01],[1,1.82,469.11],[2,1.54,0]],"ltp":1.39,"tv":5950.14,"id":5071877}]}]}
{"op":"mcm","clk":"1006634027","pt":1580598649947,"mc":[{"id":"1.168175457","rc":[{"batb":[[0,1.36,117.63],[1,1.01,15.51],[2,1.01,0]],"ltp":1.39,"tv":5950.14,"id":5071877},{"batb":[[0,2.86,21.85],[1,2.74,25.97],[2,1.01,15.51]],"ltp":3.4,"tv":1910.33,"id":6374165}]}]}
{"op":"mcm","clk":"1006634119","pt":1580598651323,"mc":[{"id":"1.168175457","rc":[{"batl":[[0,1.82,469.11],[1,1.82,0]],"ltp":1.39,"tv":5950.14,"id":5071877},{"batb":[[0,2.74,25.97],[1,1.01,15.51],[2,1.01,0]],"ltp":3.4,"tv":1910.33,"id":6374165}]}]}
{"op":"mcm","clk":"1006634246","pt":1580598653138,"mc":[{"id":"1.168175457","rc":[{"batb":[[0,1.45,2],[1,1.36,117.63],[2,1.01,15.51]],"ltp":1.39,"tv":5950.14,"id":5071877}]}]}
{"op":"mcm","clk":"1006634386","pt":1580598654448,"mc":[{"id":"1.168175457","rc":[{"batb":[[1,1.43,467.52],[2,1.42,441.58]],"batl":[[0,1.48,606.5],[1,1.49,351.1],[2,1.82,469.11]],"ltp":1.39,"tv":5950.14,"id":5071877}]}]}
{"op":"mcm","clk":"1006634605","pt":1580598657426,"mc":[{"id":"1.168175457","rc":[{"batb":[[1,1.36,117.63],[2,1.01,15.51]],"batl":[[0,1.82,469.11],[1,1.49,0],[2,1.82,0]],"ltp":1.39,"tv":5950.14,"id":5071877}]}]}
{"op":"mcm","clk":"1006634850","pt":1580598660542,"mc":[{"id":"1.168175457","rc":[{"batb":[[1,1.36,781.23],[2,1.35,562.03]],"batl":[[0,1.56,416.03],[1,1.57,288],[2,1.82,469.11]],"ltp":1.39,"tv":5950.14,"id":5071877}]}]}
{"op":"mcm","clk":"1006634882","pt":1580598660958,"mc":[{"id":"1.168175457","rc":[{"batb":[[0,1.36,781.23],[1,1.35,562.03],[2,1.01,15.51]],"batl":[[0,1.82,469.11],[1,1.57,0],[2,1.82,0]],"ltp":1.39,"tv":5950.14,"id":5071877}]}]}
{"op":"mcm","clk":"1006635170","pt":1580598664449,"mc":[{"id":"1.168175457","rc":[{"batb":[[2,1.24,192.22]],"batl":[[0,1.4,399.06],[1,1.41,444.63],[2,1.82,469.11]],"ltp":1.39,"tv":5950.14,"id":5071877},{"batb":[[0,3.45,35.56],[1,2.96,21.24],[2,2.74,25.97]],"ltp":3.4,"tv":1910.33,"id":6374165}]}]}
{"op":"mcm","clk":"1006635232","pt":1580598665221,"mc":[{"id":"1.168175457","rc":[{"batb":[[2,1.01,15.51]],"ltp":3.4,"tv":1910.33,"id":6374165}]}]}
{"op":"mcm","clk":"1006635356","pt":1580598666490,"mc":[{"id":"1.168175457","rc":[{"batl":[[2,1.45,42.01]],"ltp":1.39,"tv":5950.14,"id":5071877},{"batb":[[1,3.2,18.48],[2,2.96,21.24]],"ltp":3.4,"tv":1910.33,"id":6374165}]}]}
{"op":"mcm","clk":"1006635433","pt":1580598667461,"mc":[{"id":"1.168175457","rc":[{"batl":[[0,4.9,147.5]],"ltp":3.4,"tv":1910.33,"id":6374165}]}]}
{"op":"mcm","clk":"1006635790","pt":1580598672454,"mc":[{"id":"1.168175457","rc":[{"trd":[[1.4,285.5]],"batl":[[0,1.4,256.31]],"ltp":1.4,"tv":6235.64,"id":5071877}],"tv":8145.97}]}
{"op":"mcm","clk":"1006636003","pt":1580598675388,"mc":[{"id":"1.168175457","rc":[{"batb":[[0,1.36,835.16]],"batl":[[0,1.4,346.78]],"ltp":1.4,"tv":6235.64,"id":5071877}]}]}
{"op":"mcm","clk":"1006636109","pt":1580598676559,"mc":[{"id":"1.168175457","rc":[{"batb":[[0,1.37,2],[1,1.36,835.16],[2,1.35,562.03]],"ltp":1.4,"tv":6235.64,"id":5071877}]}]}
{"op":"mcm","clk":"1006636413","pt":1580598680561,"mc":[{"id":"1.168175457","rc":[{"trd":[[1.4,287.52]],"batl":[[0,1.4,345.77]],"ltp":1.4,"tv":6237.66,"id":5071877}],"tv":8147.99}]}
{"op":"mcm","clk":"1006636485","pt":1580598681502,"mc":[{"id":"1.168175457","rc":[{"trd":[[1.36,21],[1.37,4]],"batb":[[0,1.36,824.66],[1,1.35,562.03],[2,1.24,192.22]],"ltp":1.36,"tv":6262.66,"id":5071877}],"tv":8172.99}]}
{"op":"mcm","clk":"1006636881","pt":1580598686488,"mc":[{"id":"1.168175457","rc":[{"batb":[[0,1.24,192.22],[1,1.01,15.51],[2,1.24,0]],"batl":[[0,1.45,42.01],[1,1.82,469.11],[2,1.45,0]],"ltp":1.36,"tv":6262.66,"id":5071877},{"batb":[[0,3.2,18.48],[1,2.96,21.24],[2,1.01,15.51]],"ltp":3.4,"tv":1910.33,"id":6374165}]}]}
{"op":"mcm","clk":"1006636915","pt":1580598686909,"mc":[{"id":"1.168175457","rc":[{"batl":[[0,1.82,469.11],[1,1.82,0]],"ltp":1.36,"tv":6262.66,"id":5071877},{"batb":[[0,2.96,21.24],[1,1.01,15.51],[2,1.01,0]],"ltp":3.4,"tv":1910.33,"id":6374165}]}]}
{"op":"mcm","clk":"1006637093","pt":1580598689335,"mc":[{"id":"1.168175457","rc":[{"batb":[[0,1.24,885.42],[1,1.23,945.81],[2,1.01,15.51]],"batl":[[0,1.51,573.84],[1,1.52,324.43],[2,1.82,469.11]],"ltp":1.36,"tv":6262.66,"id":5071877},{"batb":[[0,2.94,21.48]],"ltp":3.4,"tv":1910.33,"id":6374165}]}]}
{"op":"mcm","clk":"1006637152","pt":1580598690111,"mc":[{"id":"1.168175457","rc":[{"batb":[[0,1.24,192.22],[1,1.01,15.51],[2,1.01,0]],"batl":[[0,1.82,469.11],[1,1.52,0],[2,1.82,0]],"ltp":1.36,"tv":6262.66,"id":5071877}]}]}
{"op":"mcm","clk":"1006637386","pt":1580598693529,"mc":[{"id":"1.168175457","rc":[{"batb":[[0,1.34,362.71],[1,1.33,600.86],[2,1.24,192.22]],"batl":[[0,1.38,490.32]],"ltp":1.36,"tv":6262.66,"id":5071877}]}]}
{"op":"mcm","clk":"1006637449","pt":1580598694520,"mc":[{"id":"1.168175457","rc":[{"batb":[[0,1.24,192.22],[1,1.01,15.51],[2,1.24,0]],"ltp":1.36,"tv":6262.66,"id":5071877}]}]}
{"op":"mcm","clk":"1006637589","pt":1580598696540,"mc":[{"id":"1.168175457","rc":[{"batl":[[0,1.73,462.51]],"ltp":1.36,"tv":6262.66,"id":5071877}]}]}
{"op":"mcm","clk":"1006637650","pt":1580598697420,"mc":[{"id":"1.168175457","rc":[{"batb":[[0,1.24,1079.82],[1,1.23,946.63],[2,1.01,15.51]],"batl":[[0,1.51,417.59],[1,1.52,324.25],[2,1.73,462.51]],"ltp":1.36,"tv":6262.66,"id":5071877}]}]}
{"op":"mcm","clk":"1006637731","pt":1580598698522,"mc":[{"id":"1.168175457","rc":[{"batl":[[0,1.51,347.85]],"ltp":1.36,"tv":6262.66,"id":5071877}]}]}
{"op":"mcm","clk":"1006637806","pt":1580598699619,"mc":[{"id":"1.168175457","rc":[{"batb":[[0,1.24,1166.52]],"ltp":1.36,"tv":6262.66,"id":5071877}]}]}
{"op":"mcm","clk":"1006638122","pt":1580598703537,"mc":[{"id":"1.168175457","rc":[{"batb":[[0,1.24,192.22],[1,1.01,15.51],[2,1.01,0]],"ltp":1.36,"tv":6262.66,"id":5071877}]}]}
{"op":"mcm","clk":"1006638487","pt":1580598706533,"mc":[{"id":"1.168175457","rc":[{"batb":[[0,1.46,586.57],[1,1.45,401.5],[2,1.24,192.22]],"ltp":1.36,"tv":6262.66,"id":5071877}]}]}
{"op":"mcm","clk":"1006638540","pt":1580598707152,"mc":[{"id":"1.168175457","rc":[{"batb":[[0,1.46,672.18],[2,1.36,119.99]],"ltp":1.36,"tv":6262.66,"id":5071877},{"batb":[[1,2.66,27.62],[2,1.01,15.51]],"ltp":3.4,"tv":1910.33,"id":6374165}]}]}
{"op":"mcm","clk":"1006638656","pt":1580598708355,"mc":[{"id":"1.168175457","rc":[{"batl":[[2,1.54,42.01]],"ltp":1.36,"tv":6262.66,"id":5071877},{"batb":[[1,2.86,21.85],[2,2.66,27.62]],"batl":[[0,4.2,167.23]],"ltp":3.4,"tv":1910.33,"id":6374165}]}]}
{"op":"mcm","clk":"1006639445","pt":1580598718420,"mc":[{"id":"1.168175457","rc":[{"batb":[[0,1.36,119.99],[1,1.01,15.51],[2,1.36,0]],"batl":[[0,1.54,42.01],[1,1.73,462.51],[2,1.54,0]],"ltp":1.36,"tv":6262.66,"id":5071877},{"batb":[[0,2.86,21.85],[1,2.66,27.62],[2,1.01,15.51]],"ltp":3.4,"tv":1910.33,"id":6374165}]}]}
{"op":"mcm","clk":"1006639506","pt":1580598719255,"mc":[{"id":"1.168175457","rc":[{"batl":[[0,1.73,462.51],[1,1.73,0]],"ltp":1.36,"tv":6262.66,"id":5071877},{"batb":[[0,2.66,27.62],[1,1.01,15.51],[2,1.01,0]],"ltp":3.4,"tv":1910.33,"id":6374165}]}]}
{"op":"mcm","clk":"1006639669","pt":1580598721467,"mc":[{"id":"1.168175457","rc":[{"batb":[[0,1.36,846.28],[1,1.35,559.1],[2,1.01,15.51]],"batl":[[0,1.59,408.99],[1,1.6,267.1],[2,1.73,462.51]],"ltp":1.36,"tv":6262.66,"id":5071877}]}]}
{"op":"mcm","clk":"1006639917","pt":1580598724465,"mc":[{"id":"1.168175457","rc":[{"batb":[[0,1.36,119.99],[1,1.01,15.51],[2,1.01,0]],"ltp":1.36,"tv":6262.66,"id":5071877}]}]}
{"op":"mcm","clk":"1006640098","pt":1580598726468,"mc":[{"id":"1.168175457","rc":[{"batl":[[2,1.73,0]],"ltp":1.36,"tv":6262.66,"id":5071877}]}]}
{"op":"mcm","clk":"1006640174","pt":1580598727403,"mc":[{"id":"1.168175457","rc":[{"batb":[[0,1.55,68.77],[1,1.53,543.61],[2,1.52,330.08]],"ltp":1.36,"tv":6262.66,"id":5071877},{"batb":[[1,2.24,44.3],[2,1.01,15.51]],"ltp":3.4,"tv":1910.33,"id":6374165}]}]}
{"op":"mcm","clk":"1006640207","pt":1580598727771,"mc":[{"id":"1.168175457","rc":[{"batl":[[1,1.6,309.11]],"ltp":1.36,"tv":6262.66,"id":5071877},{"batb":[[0,2.66,52.82]],"ltp":3.4,"tv":1910.33,"id":6374165}]}]}
{"op":"mcm","clk":"1006640377","pt":1580598729757,"mc":[{"id":"1.168175457","rc":[{"batl":[[2,2.04,294.51]],"ltp":1.36,"tv":6262.66,"id":5071877},{"batl":[[0,3.65,120.81]],"ltp":3.4,"tv":1910.33,"id":6374165}]}]}
{"op":"mcm","clk":"1006642360","pt":1580598752508,"mc":[{"id":"1.168175457","rc":[{"batb":[[0,1.54,69.4]],"ltp":1.36,"tv":6262.66,"id":5071877},{"batb":[[0,2.68,27.38],[1,2.66,25.21],[2,2.24,43.9]],"ltp":3.4,"tv":1910.33,"id":6374165}]}]}
{"op":"mcm","clk":"1006642501","pt":1580598754236,"mc":[{"id":"1.168175457","rc":[{"trd":[[2.68,23.55]],"batb":[[0,2.68,15.61]],"ltp":2.68,"tv":1933.88,"id":6374165}],"tv":8196.54}]}
{"op":"mcm","clk":"1006643002","pt":1580598760228,"mc":[{"id":"1.168175457","rc":[{"batb":[[0,1.55,68.93]],"ltp":1.36,"tv":6262.66,"id":5071877}]}]}
{"op":"mcm","clk":"1006645687","pt":1580598792892,"mc":[{"id":"1.168175457","rc":[{"trd":[[2.68,27.09]],"batb":[[0,2.68,13.84]],"ltp":2.68,"tv":1937.42,"id":6374165}],"tv":8200.08}]}
{"op":"mcm","clk":"1006648019","pt":1580598822122,"mc":[{"id":"1.168175457","rc":[{"batb":[[0,1.43,95.6],[1,1.01,15.51],[2,1.52,0]],"batl":[[0,1.6,42.01],[1,2.04,294.51],[2,2.04,0]],"ltp":1.36,"tv":6262.66,"id":5071877},{"batb":[[0,2.66,25.21],[1,2.24,43.9],[2,1.01,15.51]],"ltp":2.68,"tv":1937.42,"id":6374165}]}]}
{"op":"mcm","clk":"1006648072","pt":1580598823006,"mc":[{"id":"1.168175457","rc":[{"batl":[[0,2.04,294.51],[1,2.04,0]],"ltp":1.36,"tv":6262.66,"id":5071877},{"batb":[[0,2.24,43.9],[1,1.01,15.51],[2,1.01,0]],"ltp":2.68,"tv":1937.42,"id":6374165}]}]}
{"op":"mcm","clk":"1006648224","pt":1580598824639,"mc":[{"id":"1.168175457","rc":[{"batb":[[1,1.42,584.73],[2,1.41,453.95]],"batl":[[0,1.79,246.08],[1,1.81,353.97],[2,2.04,294.51]],"ltp":1.36,"tv":6262.66,"id":5071877}]}]}
{"op":"mcm","clk":"1006648924","pt":1580598833407,"mc":[{"id":"1.168175457","rc":[{"batl":[[0,2.04,294.51],[1,1.81,0],[2,2.04,0]],"ltp":1.36,"tv":6262.66,"id":5071877}]}]}
{"op":"mcm","clk":"1006649140","pt":1580598836489,"mc":[{"id":"1.168175457","rc":[{"batl":[[0,1.47,535.19],[1,1.48,358.77]],"ltp":1.36,"tv":6262.66,"id":5071877}]}]}
{"op":"mcm","clk":"1006649202","pt":1580598837225,"mc":[{"id":"1.168175457","rc":[{"batb":[[0,3.1,46.66],[1,2.6,29.35],[2,1.01,15.51]],"ltp":2.68,"tv":1937.42,"id":6374165}]}]}
{"op":"mcm","clk":"1006649252","pt":1580598837901,"mc":[{"id":"1.168175457","rc":[{"batl":[[2,1.5,42.01]],"ltp":1.36,"tv":6262.66,"id":5071877},{"batb":[[1,3,21],[2,2.6,29.35]],"ltp":2.68,"tv":1937.42,"id":6374165}]}]}
{"op":"mcm","clk":"1006649381","pt":1580598839509,"mc":[{"id":"1.168175457","rc":[{"batl":[[0,4.6,136.05]],"ltp":2.68,"tv":1937.42,"id":6374165}]}]}
{"op":"mcm","clk":"1006650885","pt":1580598857347,"mc":[{"id":"1.168175457","rc":[{"batb":[[0,1.33,129.83],[1,1.01,15.51],[2,1.41,0]],"batl":[[0,1.5,42.01],[1,1.82,469.11],[2,1.5,0]],"ltp":1.36,"tv":6262.66,"id":5071877},{"batb":[[0,3,21],[1,2.6,29.35],[2,1.01,15.51]],"ltp":2.68,"tv":1937.42,"id":6374165}]}]}
{"op":"mcm","clk":"1006651021","pt":1580598858915,"mc":[{"id":"1.168175457","rc":[{"batl":[[0,1.82,469.11],[1,1.82,0]],"ltp":1.36,"tv":6262.66,"id":5071877},{"batb":[[0,2.6,29.35],[1,1.01,15.51],[2,1.01,0]],"ltp":2.68,"tv":1937.42,"id":6374165}]}]}
{"op":"mcm","clk":"1006651141","pt":1580598860440,"mc":[{"id":"1.168175457","rc":[{"batb":[[0,1.34,572.99],[1,1.33,730.07],[2,1.01,15.51]],"batl":[[0,1.61,272.6],[1,1.62,255.94],[2,1.82,469.11]],"ltp":1.36,"tv":6262.66,"id":5071877},{"batb":[[0,2.64,28.25],[1,2.6,29.35],[2,1.01,15.51]],"ltp":2.68,"tv":1937.42,"id":6374165}]}]}
{"op":"mcm","clk":"1006651190","pt":1580598860851,"mc":[{"id":"1.168175457","rc":[{"batb":[[1,1.01,15.51],[2,1.01,0]],"ltp":2.68,"tv":1937.42,"id":6374165}]}]}
{"op":"mcm","clk":"1006652802","pt":1580598878510,"mc":[{"id":"1.168175457","rc":[{"batl":[[0,1.82,469.11],[1,1.62,0],[2,1.82,0]],"ltp":1.36,"tv":6262.66,"id":5071877}]}]}
{"op":"mcm","clk":"1006653068","pt":1580598881496,"mc":[{"id":"1.168175457","rc":[{"batl":[[0,1.38,591.51],[1,1.39,468.1]],"ltp":1.36,"tv":6262.66,"id":5071877}]}]}
{"op":"mcm","clk":"1006653158","pt":1580598882427,"mc":[{"id":"1.168175457","rc":[{"batb":[[2,1.27,169.32]],"ltp":1.36,"tv":6262.66,"id":5071877},{"batb":[[0,3.75,29.82],[1,3.15,44.53],[2,1.01,15.51]],"ltp":2.68,"tv":1937.42,"id":6374165}]}]}
{"op":"mcm","clk":"1006653315","pt":1580598884431,"mc":[{"id":"1.168175457","rc":[{"batl":[[2,1.73,527.57]],"ltp":1.36,"tv":6262.66,"id":5071877},{"batl":[[0,5.3,118.79]],"ltp":2.68,"tv":1937.42,"id":6374165}]}]}
{"op":"mcm","clk":"1006654092","pt":1580598893034,"mc":[{"id":"1.168175457","rc":[{"trd":[[1.37,6]],"ltp":1.37,"tv":6264.66,"id":5071877},{"trd":[[3.75,0.73]],"batb":[[0,3.75,29.09]],"ltp":3.75,"tv":1938.15,"id":6374165}],"tv":8202.81}]}
{"op":"mcm","clk":"1006654883","pt":1580598901469,"mc":[{"id":"1.168175457","rc":[{"batb":[[0,1.27,167.28],[1,1.01,15.51],[2,1.27,0]],"batl":[[0,1.73,527.57],[1,1.39,0],[2,1.73,0]],"ltp":1.37,"tv":6264.66,"id":5071877},{"batb":[[0,3.15,44.53],[1,1.01,15.51],[2,1.01,0]],"ltp":3.75,"tv":1938.15,"id":6374165}]}]}
{"op":"mcm","clk":"1006655119","pt":1580598903480,"mc":[{"id":"1.168175457","rc":[{"batb":[[0,1.29,565.05],[1,1.28,736.84],[2,1.27,167.28]],"batl":[[0,1.47,581.67],[1,1.48,358.38],[2,1.73,527.57]],"ltp":1.37,"tv":6264.66,"id":5071877}]}]}
{"op":"mcm","clk":"1006655173","pt":1580598904170,"mc":[{"id":"1.168175457","rc":[{"batb":[[0,1.27,167.28],[1,1.01,15.51],[2,1.27,0]],"batl":[[0,1.73,527.57],[1,1.48,0],[2,1.73,0]],"ltp":1.37,"tv":6264.66,"id":5071877}]}]}
{"op":"mcm","clk":"1006655311","pt":1580598905218,"mc":[{"id":"1.168175457","rc":[{"batb":[[0,1.36,305.82],[1,1.35,553.5],[2,1.27,167.28]],"batl":[[0,1.4,716.7],[1,1.41,437.88],[2,1.73,527.57]],"ltp":1.37,"tv":6264.66,"id":5071877}]}]}
{"op":"mcm","clk":"1006655968","pt":1580598912380,"mc":[{"id":"1.168175457","rc":[{"batb":[[0,1.27,167.28],[1,1.01,15.51],[2,1.27,0]],"batl":[[0,1.73,527.57],[1,1.41,0],[2,1.73,0]],"ltp":1.37,"tv":6264.66,"id":5071877}]}]}
{"op":"mcm","clk":"1006656179","pt":1580598914872,"mc":[{"id":"1.168175457","rc":[{"batb":[[0,1.29,565.05],[1,1.28,736.84],[2,1.27,167.28]],"batl":[[0,1.47,581.67],[1,1.48,358.38],[2,1.73,527.57]],"ltp":1.37,"tv":6264.66,"id":5071877}]}]}
{"op":"mcm","clk":"1006656566","pt":1580598918477,"mc":[{"id":"1.168175457","rc":[{"batl":[[0,1.73,527.57],[1,1.48,0],[2,1.73,0]],"ltp":1.37,"tv":6264.66,"id":5071877}]}]}
{"op":"mcm","clk":"1006656876","pt":1580598921470,"mc":[{"id":"1.168175457","rc":[{"batl":[[0,1.32,402.81],[1,1.33,579.83]],"ltp":1.37,"tv":6264.66,"id":5071877}]}]}
{"op":"mcm","clk":"1006656963","pt":1580598922262,"mc":[{"id":"1.168175457","rc":[{"batl":[[2,1.36,42.01]],"ltp":1.37,"tv":6264.66,"id":5071877},{"batb":[[0,4.2,44.22],[1,3.8,28.17],[2,3.75,15.12]],"ltp":3.75,"tv":1938.15,"id":6374165}]}]}
{"op":"mcm","clk":"1006657071","pt":1580598923430,"mc":[{"id":"1.168175457","rc":[{"batl":[[0,6,106.18]],"ltp":3.75,"tv":1938.15,"id":6374165}]}]}
{"op":"mcm","clk":"1006657694","pt":1580598930248,"mc":[{"id":"1.168175457","rc":[{"trd":[[1.32,4]],"batl":[[0,1.32,400.81]],"ltp":1.32,"tv":6268.66,"id":5071877}],"tv":8206.81}]}
{"op":"mcm","clk":"1006658045","pt":1580598934354,"mc":[{"id":"1.168175457","rc":[{"trd":[[1.29,5]],"batb":[[0,1.29,562.55]],"ltp":1.29,"tv":6273.66,"id":5071877}],"tv":8211.81}]}
{"op":"mcm","clk":"1006658570","pt":1580598938274,"mc":[{"id":"1.168175457","rc":[{"trd":[[1.32,4.04]],"batl":[[0,1.32,400.79]],"ltp":1.32,"tv":6273.69,"id":5071877}],"tv":8211.85}]}
{"op":"mcm","clk":"1006658671","pt":1580598939378,"mc":[{"id":"1.168175457","rc":[{"batb":[[0,1.23,196.47],[1,1.01,15.51],[2,1.27,0]],"batl":[[0,1.36,42.01],[1,1.66,579.81],[2,1.36,0]],"ltp":1.32,"tv":6273.69,"id":5071877},{"batb":[[0,3.8,28.17],[1,3.75,15.12],[2,1.01,15.51]],"ltp":3.75,"tv":1938.15,"id":6374165}]}]}
{"op":"mcm","clk":"1006658855","pt":1580598941467,"mc":[{"id":"1.168175457","rc":[{"batl":[[0,1.66,579.81],[1,1.66,0]],"ltp":1.32,"tv":6273.69,"id":5071877},{"batb":[[1,1.01,15.51],[2,1.01,0]],"ltp":3.75,"tv":1938.15,"id":6374165}]}]}
{"op":"mcm","clk":"1006658935","pt":1580598942457,"mc":[{"id":"1.168175457","rc":[{"batb":[[0,1.27,315.29],[1,1.26,801.8],[2,1.23,196.47]],"batl":[[0,1.36,390.55],[1,1.37,502.78],[2,1.66,579.81]],"ltp":1.32,"tv":6273.69,"id":5071877}]}]}
{"op":"mcm","clk":"1006659044","pt":1580598943568,"mc":[{"id":"1.168175457","rc":[{"batl":[[0,1.66,579.81],[1,1.37,0],[2,1.66,0]],"ltp":1.32,"tv":6273.69,"id":5071877}]}]}
{"op":"mcm","clk":"1006659321","pt":1580598946404,"mc":[{"id":"1.168175457","rc":[{"batl":[[0,1.3,782.22],[1,1.31,619.62],[2,1.66,579.81]],"ltp":1.32,"tv":6273.69,"id":5071877}]}]}
{"op":"mcm","clk":"1006659402","pt":1580598947378,"mc":[{"id":"1.168175457","rc":[{"batb":[[0,4.6,35.01],[1,4.1,47.05],[2,1.01,15.51]],"ltp":3.75,"tv":1938.15,"id":6374165}]}]}
{"op":"mcm","clk":"1006659460","pt":1580598947998,"mc":[{"id":"1.168175457","rc":[{"batl":[[2,1.33,42.01]],"ltp":1.32,"tv":6273.69,"id":5071877},{"batb":[[2,4,13.44]],"ltp":3.75,"tv":1938.15,"id":6374165}]}]}
{"op":"mcm","clk":"1006659969","pt":1580598954204,"mc":[{"id":"1.168175457","rc":[{"trd":[[1.28,2]],"ltp":1.28,"tv":6275.69,"id":5071877},{"trd":[[4.6,0.56]],"batb":[[0,4.6,34.46]],"ltp":4.6,"tv":1938.71,"id":6374165}],"tv":8214.41}]}
{"op":"mcm","clk":"1006660086","pt":1580598955497,"mc":[{"id":"1.168175457","rc":[{"trd":[[1.27,559.56]],"batb":[[0,1.26,801.8],[1,1.23,196.47],[2,1.18,267.99]],"ltp":1.27,"tv":6835.26,"id":5071877}],"tv":8773.97}]}
{"op":"mcm","clk":"1006660319","pt":1580598958210,"mc":[{"id":"1.168175457","rc":[{"batb":[[0,1.26,1016.77],[1,1.25,859.05],[2,1.23,196.47]],"batl":[[0,1.3,881.98]],"ltp":1.27,"tv":6835.26,"id":5071877}]}]}
{"op":"mcm","clk":"1006661336","pt":1580598970320,"mc":[{"id":"1.168175457","rc":[{"trd":[[1.28,4]],"ltp":1.28,"tv":6837.26,"id":5071877},{"trd":[[4.6,1.11]],"batb":[[0,4.6,33.9]],"ltp":4.6,"tv":1939.26,"id":6374165}],"tv":8776.53}]}
{"op":"mcm","clk":"1006662542","pt":1580598983531,"mc":[{"id":"1.168175457","rc":[{"batb":[[0,1.18,264.76],[1,1.01,15.51],[2,1.23,0]],"batl":[[0,1.33,42.01],[1,1.66,579.81],[2,1.33,0]],"ltp":1.28,"tv":6837.26,"id":5071877},{"batb":[[0,4.1,47.05],[1,4,13.44],[2,1.01,15.51]],"ltp":4.6,"tv":1939.26,"id":6374165}]}]}
{"op":"mcm","clk":"1006662713","pt":1580598985311,"mc":[{"id":"1.168175457","rc":[{"batl":[[0,1.66,579.81],[1,1.66,0]],"ltp":1.28,"tv":6837.26,"id":5071877},{"batb":[[1,1.01,15.51],[2,1.01,0]],"ltp":4.6,"tv":1939.26,"id":6374165}]}]}
{"op":"mcm","clk":"1006662824","pt":1580598986308,"mc":[{"id":"1.168175457","rc":[{"batb":[[0,1.2,1345.33],[1,1.19,812.3],[2,1.18,264.76]],"batl":[[0,1.34,592.63],[1,1.35,537.86],[2,1.66,579.81]],"ltp":1.28,"tv":6837.26,"id":5071877}]}]}
{"op":"mcm","clk":"1006662896","pt":1580598987237,"mc":[{"id":"1.168175457","rc":[{"batb":[[0,1.28,10],[1,1.2,1345.33],[2,1.19,812.3]],"ltp":1.28,"tv":6837.26,"id":5071877}]}]}
{"op":"mcm","clk":"1006663131","pt":1580598990021,"mc":[{"id":"1.168175457","rc":[{"batb":[[1,1.18,264.76],[2,1.01,15.51]],"ltp":1.28,"tv":6837.26,"id":5071877}]}]}
{"op":"mcm","clk":"1006663429","pt":1580598993418,"mc":[{"id":"1.168175457","rc":[{"batb":[[0,1.3,903.33],[1,1.29,713.56],[2,1.28,10]],"ltp":1.28,"tv":6837.26,"id":5071877}]}]}
{"op":"mcm","clk":"1006663490","pt":1580598994154,"mc":[{"id":"1.168175457","rc":[{"batb":[[2,1.28,168.31]],"batl":[[2,1.37,42.01]],"ltp":1.28,"tv":6837.26,"id":5071877},{"batb":[[1,3.75,44.71],[2,1.01,15.51]],"ltp":4.6,"tv":1939.26,"id":6374165}]}]}
{"op":"mcm","clk":"1006663983","pt":1580598999468,"mc":[{"id":"1.168175457","rc":[{"trd":[[1.3,17.69]],"batb":[[0,1.3,894.48],[2,1.28,158.31]],"ltp":1.3,"tv":6854.95,"id":5071877}],"tv":8794.22}]}
{"op":"mcm","clk":"1006664650","pt":1580599006530,"mc":[{"id":"1.168175457","rc":[{"trd":[[1.33,10]],"ltp":1.33,"tv":6864.95,"id":5071877},{"trd":[[4.1,3.24]],"batb":[[0,4.1,43.81]],"ltp":4.1,"tv":1942.51,"id":6374165}],"tv":8807.46}]}
{"op":"mcm","clk":"1006664749","pt":1580599007523,"mc":[{"id":"1.168175457","rc":[{"batb":[[0,1.23,203.63],[1,1.01,15.51],[2,1.28,0]],"batl":[[0,1.37,42.01],[1,1.66,579.81],[2,1.37,0]],"ltp":1.33,"tv":6864.95,"id":5071877},{"batb":[[0,3.75,44.71],[1,1.01,15.51],[2,1.01,0]],"batl":[[0,4.2,4.5],[1,6,106.18]],"ltp":4.1,"tv":1942.51,"id":6374165}]}]}
{"op":"mcm","clk":"1006664934","pt":1580599009358,"mc":[{"id":"1.168175457","rc":[{"batl":[[0,1.66,579.81],[1,1.66,0]],"ltp":1.33,"tv":6864.95,"id":5071877},{"batb":[[0,3.75,29.58]],"ltp":4.1,"tv":1942.51,"id":6374165}]}]}
{"op":"mcm","clk":"1006665038","pt":1580599010473,"mc":[{"id":"1.168175457","rc":[{"batb":[[0,1.25,939.22],[1,1.24,901.2],[2,1.23,201.9]],"batl":[[0,1.38,719.3],[1,1.39,467.96],[2,1.66,579.81]],"ltp":1.33,"tv":6864.95,"id":5071877},{"batb":[[0,3.7,29.9]],"ltp":4.1,"tv":1942.51,"id":6374165}]}]}
{"op":"mcm","clk":"1006666286","pt":1580599023561,"mc":[{"id":"1.168175457","rc":[{"batl":[[0,1.66,579.81],[1,1.39,0],[2,1.66,0]],"ltp":1.33,"tv":6864.95,"id":5071877}]}]}
{"op":"mcm","clk":"1006666536","pt":1580599026360,"mc":[{"id":"1.168175457","rc":[{"trd":[[1.31,14.42]],"batl":[[0,1.28,375.67],[1,1.29,681.98],[2,1.66,579.81]],"ltp":1.31,"tv":6879.37,"id":5071877},{"trd":[[4.2,4.5]],"batb":[[0,3.7,593.72]],"batl":[[0,6,106.18],[1,6,0]],"ltp":4.2,"tv":1947.0,"id":6374165}],"tv":8826.38}]}
{"op":"mcm","clk":"1006666622","pt":1580599027096,"mc":[{"id":"1.168175457","rc":[{"batb":[[0,4.7,33.6],[1,4.1,48.15],[2,1.01,15.51]],"ltp":4.2,"tv":1947.0,"id":6374165}]}]}
{"op":"mcm","clk":"1006666758","pt":1580599028557,"mc":[{"id":"1.168175457","rc":[{"batl":[[2,1.31,3.79]],"ltp":1.31,"tv":6879.37,"id":5071877},{"batb":[[1,4.1,61.6]],"ltp":4.2,"tv":1947.0,"id":6374165}]}]}
{"op":"mcm","clk":"1006666801","pt":1580599029083,"mc":[{"id":"1.168175457","rc":[{"batl":[[2,1.32,42.01]],"ltp":1.31,"tv":6879.37,"id":5071877}]}]}
{"op":"mcm","clk":"1006667654","pt":1580599038142,"mc":[{"id":"1.168175457","rc":[{"trd":[[1.28,10]],"batl":[[0,1.28,372.67]],"ltp":1.28,"tv":6885.37,"id":5071877}],"tv":8832.38}]}
{"op":"mcm","clk":"1006668216","pt":1580599043400,"mc":[{"id":"1.168175457","rc":[{"batb":[[0,1.16,299.07],[1,1.01,15.51],[2,1.23,0]],"batl":[[0,1.32,42.01],[1,1.66,579.81],[2,1.32,0]],"ltp":1.28,"tv":6885.37,"id":5071877},{"batb":[[0,4.1,61.6],[1,1.01,15.51],[2,1.01,0]],"ltp":4.2,"tv":1947.0,"id":6374165}]}]}
{"op":"mcm","clk":"1006668418","pt":1580599045501,"mc":[{"id":"1.168175457","rc":[{"batl":[[0,1.66,579.81],[1,1.66,0]],"ltp":1.28,"tv":6885.37,"id":5071877},{"batb":[[0,4.1,48.15]],"ltp":4.2,"tv":1947.0,"id":6374165}]}]}
{"op":"mcm","clk":"1006668483","pt":1580599046285,"mc":[{"id":"1.168175457","rc":[{"batb":[[0,1.18,1162.68],[1,1.17,1033.4],[2,1.16,299.07]],"batl":[[0,1.34,729.14],[1,1.35,535.95],[2,1.66,579.81]],"ltp":1.28,"tv":6885.37,"id":5071877},{"batb":[[1,4,48.86],[2,1.01,15.51]],"ltp":4.2,"tv":1947.0,"id":6374165}]}]}
{"op":"mcm","clk":"1006668579","pt":1580599047444,"mc":[{"id":"1.168175457","rc":[{"batb":[[2,1.16,296.16]],"ltp":1.28,"tv":6885.37,"id":5071877},{"batb":[[0,4,48.86],[1,1.01,15.51],[2,1.01,0]],"ltp":4.2,"tv":1947.0,"id":6374165}]}]}
{"op":"mcm","clk":"1006668668","pt":1580599048443,"mc":[{"id":"1.168175457","rc":[{"batb":[[0,1.16,296.16],[1,1.01,15.51],[2,1.16,0]],"ltp":1.28,"tv":6885.37,"id":5071877}]}]}
{"op":"mcm","clk":"1006668886","pt":1580599051334,"mc":[{"id":"1.168175457","rc":[{"batb":[[0,1.3,753.56],[1,1.29,867.09],[2,1.22,211.42]],"ltp":1.28,"tv":6885.37,"id":5071877},{"batb":[[1,3.65,30.92],[2,1.01,15.51]],"ltp":4.2,"tv":1947.0,"id":6374165}]}]}
{"op":"mcm","clk":"1006668940","pt":1580599051963,"mc":[{"id":"1.168175457","rc":[{"batl":[[2,1.37,42.01]],"ltp":1.28,"tv":6885.37,"id":5071877},{"batb":[[1,3.75,15.12],[2,3.65,30.92]],"ltp":4.2,"tv":1947.0,"id":6374165}]}]}
{"op":"mcm","clk":"1006669093","pt":1580599053849,"mc":[{"id":"1.168175457","rc":[{"batl":[[2,1.66,579.81]],"ltp":1.28,"tv":6885.37,"id":5071877}]}]}
{"op":"mcm","clk":"1006669343","pt":1580599056862,"mc":[{"id":"1.168175457","rc":[{"batl":[[2,1.36,42.01]],"ltp":1.28,"tv":6885.37,"id":5071877}]}]}
{"op":"mcm","clk":"1006669540","pt":1580599059045,"mc":[{"id":"1.168175457","rc":[{"batb":[[0,1.3,579.86]],"batl":[[0,1.34,564.19],[1,1.36,42.01],[2,1.66,579.81]],"ltp":1.28,"tv":6885.37,"id":5071877}]}]}
{"op":"mcm","clk":"1006669842","pt":1580599062368,"mc":[{"id":"1.168175457","rc":[{"batb":[[0,1.3,501.47]],"batl":[[0,1.33,336.31],[1,1.34,564.19],[2,1.36,42.01]],"ltp":1.28,"tv":6885.37,"id":5071877}]}]}
{"op":"mcm","clk":"1006670104","pt":1580599065346,"mc":[{"id":"1.168175457","rc":[{"batb":[[0,1.22,211.42],[1,1.01,15.51],[2,1.22,0]],"batl":[[0,1.66,579.81],[1,1.34,0],[2,1.36,0]],"ltp":1.28,"tv":6885.37,"id":5071877},{"batb":[[0,3.65,30.92],[1,1.01,15.51],[2,3.65,0]],"ltp":4.2,"tv":1947.0,"id":6374165}]}]}
{"op":"mcm","clk":"1006670375","pt":1580599068475,"mc":[{"id":"1.168175457","rc":[{"batb":[[0,1.24,596.05],[1,1.23,946.36],[2,1.22,211.42]],"batl":[[0,1.38,708.28],[1,1.39,471.26],[2,1.66,579.81]],"ltp":1.28,"tv":6885.37,"id":5071877},{"batb":[[0,3.7,30.37]],"ltp":4.2,"tv":1947.0,"id":6374165}]}]}
{"op":"mcm","clk":"1006670660","pt":1580599071549,"mc":[{"id":"1.168175457","rc":[{"batl":[[0,1.66,579.81],[1,1.39,0],[2,1.66,0]],"ltp":1.28,"tv":6885.37,"id":5071877}]}]}
{"op":"mcm","clk":"1006670907","pt":1580599074472,"mc":[{"id":"1.168175457","rc":[{"batl":[[0,1.27,818.48],[1,1.28,708.01]],"ltp":1.28,"tv":6885.37,"id":5071877}]}]}
{"op":"mcm","clk":"1006671006","pt":1580599075559,"mc":[{"id":"1.168175457","rc":[{"batb":[[0,4.9,30.76],[1,4,49.73],[2,1.01,15.51]],"ltp":4.2,"tv":1947.0,"id":6374165}]}]}
{"op":"mcm","clk":"1006671106","pt":1580599076495,"mc":[{"id":"1.168175457","rc":[{"batb":[[0,1.24,764.09]],"batl":[[2,1.3,42.01]],"ltp":1.28,"tv":6885.37,"id":5071877},{"batb":[[1,4.3,12.6],[2,4,49.73]],"ltp":4.2,"tv":1947.0,"id":6374165}]}]}
{"op":"mcm","clk":"1006671175","pt":1580599077186,"mc":[{"id":"1.168175457","rc":[{"batl":[[0,7.2,92.18]],"ltp":4.2,"tv":1947.0,"id":6374165}]}]}
{"op":"mcm","clk":"1006671491","pt":1580599080533,"mc":[{"id":"1.168175457","rc":[{"batb":[[2,4,62]],"ltp":4.2,"tv":1947.0,"id":6374165}]}]}
{"op":"mcm","clk":"1006671582","pt":1580599081417,"mc":[{"id":"1.168175457","rc":[{"batb":[[0,1.25,5],[1,1.24,764.09],[2,1.23,946.36]],"ltp":1.28,"tv":6885.37,"id":5071877}]}]}
{"op":"mcm","clk":"1006671846","pt":1580599084343,"mc":[{"id":"1.168175457","rc":[{"batb":[[0,1.24,764.09],[1,1.23,946.36],[2,1.22,211.42]],"ltp":1.28,"tv":6885.37,"id":5071877}]}]}
{"op":"mcm","clk":"1006672125","pt":1580599087541,"mc":[{"id":"1.168175457","rc":[{"batb":[[0,1.26,5],[1,1.24,168.04],[2,1.13,373.19]],"batl":[[0,1.3,42.01],[1,1.58,650.58],[2,1.3,0]],"ltp":1.28,"tv":6885.37,"id":5071877},{"batb":[[0,4.3,12.6],[1,4,49.73],[2,1.01,15.51]],"ltp":4.2,"tv":1947.0,"id":6374165}]}]}
{"op":"mcm","clk":"1006672262","pt":1580599088949,"mc":[{"id":"1.168175457","rc":[{"batb":[[1,1.13,373.19],[2,1.01,15.51]],"batl":[[0,1.58,650.58],[1,1.58,0]],"ltp":1.28,"tv":6885.37,"id":5071877},{"batb":[[0,4,49.73],[1,1.01,15.51],[2,1.01,0]],"ltp":4.2,"tv":1947.0,"id":6374165}]}]}
{"op":"mcm","clk":"1006672380","pt":1580599090166,"mc":[{"id":"1.168175457","rc":[{"batb":[[1,1.15,632.93],[2,1.14,1625.58]],"batl":[[0,1.34,570.79],[1,1.35,541.98],[2,1.58,650.58]],"ltp":1.28,"tv":6885.37,"id":5071877}]}]}
{"op":"mcm","clk":"1006672450","pt":1580599090971,"mc":[{"id":"1.168175457","rc":[{"batb":[[0,1.26,32.73]],"ltp":1.28,"tv":6885.37,"id":5071877}]}]}
{"op":"mcm","clk":"1006672573","pt":1580599092473,"mc":[{"id":"1.168175457","rc":[{"batb":[[0,1.26,5]],"ltp":1.28,"tv":6885.37,"id":5071877}]}]}
{"op":"mcm","clk":"1006672831","pt":1580599095039,"mc":[{"id":"1.168175457","rc":[{"batl":[[0,1.58,650.58],[1,1.35,0],[2,1.58,0]],"ltp":1.28,"tv":6885.37,"id":5071877}]}]}
{"op":"mcm","clk":"1006672947","pt":1580599096338,"mc":[{"id":"1.168175457","rc":[{"batb":[[0,1.15,632.93],[1,1.14,1625.58],[2,1.13,373.19]],"ltp":1.28,"tv":6885.37,"id":5071877}]}]}
{"op":"mcm","clk":"1006673140","pt":1580599098470,"mc":[{"id":"1.168175457","rc":[{"batl":[[0,1.17,1056.89],[1,1.18,1139.38]],"ltp":1.28,"tv":6885.37,"id":5071877},{"batb":[[0,7.2,26.28],[1,5,30.21],[2,4,49.73]],"ltp":4.2,"tv":1947.0,"id":6374165}]}]}
{"op":"mcm","clk":"1006673184","pt":1580599098940,"mc":[{"id":"1.168175457","rc":[{"batb":[[2,1.01,15.51]],"ltp":4.2,"tv":1947.0,"id":6374165}]}]}
{"op":"mcm","clk":"1006673270","pt":1580599099982,"mc":[{"id":"1.168175457","rc":[{"batl":[[2,1.2,42.01]],"ltp":1.28,"tv":6885.37,"id":5071877},{"batb":[[1,5.9,8.4],[2,5,30.21]],"ltp":4.2,"tv":1947.0,"id":6374165}]}]}
{"op":"mcm","clk":"1006673385","pt":1580599101082,"mc":[{"id":"1.168175457","rc":[{"batl":[[0,10.5,72.32]],"ltp":4.2,"tv":1947.0,"id":6374165}]}]}
{"op":"mcm","clk":"1006673888","pt":1580599106360,"mc":[{"id":"1.168175457","rc":[{"trd":[[1.17,10]],"batl":[[0,1.17,1051.89]],"ltp":1.17,"tv":6895.37,"id":5071877}],"tv":8842.38}]}
{"op":"mcm","clk":"1006674234","pt":1580599110056,"mc":[{"id":"1.168175457","rc":[{"trd":[[7.2,9]],"batb":[[0,7.2,21.78]],"ltp":7.2,"tv":1956.0,"id":6374165}],"tv":8851.37}]}
{"op":"mcm","clk":"1006674339","pt":1580599111481,"mc":[{"id":"1.168175457","rc":[{"batb":[[0,1.15,505.47]],"batl":[[1,1.18,1014.83]],"ltp":1.17,"tv":6895.37,"id":5071877}]}]}
{"op":"mcm","clk":"1006674513","pt":1580599113452,"mc":[{"id":"1.168175457","rc":[{"trd":[[1.17,67.14]],"batl":[[0,1.17,1023.32]],"ltp":1.17,"tv":6952.51,"id":5071877}],"tv":8908.51}]}
{"op":"mcm","clk":"1006674600","pt":1580599114497,"mc":[{"id":"1.168175457","rc":[{"batb":[[0,1.03,1385.59],[1,1.01,15.51],[2,1.13,0]],"batl":[[0,1.2,42.01],[1,1.48,784.94],[2,1.2,0]],"ltp":1.17,"tv":6952.51,"id":5071877},{"batb":[[0,5.9,8.4],[1,5,30.21],[2,1.01,15.51]],"ltp":7.2,"tv":1956.0,"id":6374165}]}]}
{"op":"mcm","clk":"1006674661","pt":1580599115183,"mc":[{"id":"1.168175457","rc":[{"batb":[[0,5,30.21],[1,1.01,15.51],[2,1.01,0]],"ltp":7.2,"tv":1956.0,"id":6374165}]}]}
{"op":"mcm","clk":"1006674753","pt":1580599116276,"mc":[{"id":"1.168175457","rc":[{"batb":[[0,1.17,5],[1,1.03,1385.59],[2,1.01,15.51]],"ltp":1.17,"tv":6952.51,"id":5071877}]}]}
{"op":"mcm","clk":"1006674829","pt":1580599117015,"mc":[{"id":"1.168175457","rc":[{"batb":[[1,1.03,3877.37]],"batl":[[0,1.26,365.45],[1,1.27,752.37]],"ltp":1.17,"tv":6952.51,"id":5071877},{"batb":[[0,4.9,30.69]],"ltp":7.2,"tv":1956.0,"id":6374165}]}]}
{"op":"mcm","clk":"1006675177","pt":1580599121112,"mc":[{"id":"1.168175457","rc":[{"batb":[[1,1.03,1371.5]],"ltp":1.17,"tv":6952.51,"id":5071877}]}]}
{"op":"mcm","clk":"1006675433","pt":1580599124193,"mc":[{"id":"1.168175457","rc":[{"batb":[[0,1.23,1223.47],[1,1.22,882.1],[2,1.17,5]],"ltp":1.17,"tv":6952.51,"id":5071877}]}]}
{"op":"mcm","clk":"1006675515","pt":1580599125082,"mc":[{"id":"1.168175457","rc":[{"trd":[[1.23,48.12]],"batb":[[0,1.23,1199.41],[1,1.22,1096.74]],"ltp":1.23,"tv":7000.63,"id":5071877},{"batb":[[1,4,49.57],[2,1.01,15.51]],"ltp":7.2,"tv":1956.0,"id":6374165}],"tv":8956.64}]}
{"op":"mcm","clk":"1006675637","pt":1580599126084,"mc":[{"id":"1.168175457","rc":[{"batl":[[2,1.3,42.01]],"ltp":1.23,"tv":7000.63,"id":5071877},{"batb":[[1,4.3,12.6],[2,4,49.57]],"batl":[[0,7.2,92.18]],"ltp":7.2,"tv":1956.0,"id":6374165}]}]}
{"op":"mcm","clk":"1006675932","pt":1580599129378,"mc":[{"id":"1.168175457","rc":[{"batb":[[2,1.13,373.03]],"ltp":1.23,"tv":7000.63,"id":5071877}]}]}
{"op":"mcm","clk":"1006676187","pt":1580599132214,"mc":[{"id":"1.168175457","rc":[{"trd":[[1.26,6.72]],"batl":[[0,1.26,362.09]],"ltp":1.26,"tv":7007.35,"id":5071877}],"tv":8963.36}]}
{"op":"mcm","clk":"1006676457","pt":1580599135291,"mc":[{"id":"1.168175457","rc":[{"trd":[[1.26,48.73]],"batl":[[0,1.26,341.09]],"ltp":1.26,"tv":7049.36,"id":5071877}],"tv":9005.36}]}
{"op":"mcm","clk":"1006676640","pt":1580599137290,"mc":[{"id":"1.168175457","rc":[{"trd":[[1.23,67.86]],"batb":[[0,1.23,1179.67]],"ltp":1.23,"tv":7069.1,"id":5071877},{"trd":[[5.4,4.5]],"ltp":5.4,"tv":1960.5,"id":6374165}],"tv":9029.6}]}
{"op":"mcm","clk":"1006676820","pt":1580599139503,"mc":[{"id":"1.168175457","rc":[{"batb":[[0,1.22,214.64],[1,1.13,373.03],[2,1.01,15.51]],"batl":[[0,1.3,42.01],[1,1.58,650.58],[2,1.3,0]],"ltp":1.23,"tv":7069.1,"id":5071877}]}]}
{"op":"mcm","clk":"1006676908","pt":1580599140396,"mc":[{"id":"1.168175457","rc":[{"batb":[[0,1.13,373.03],[1,1.01,15.51],[2,1.01,0]],"ltp":1.23,"tv":7069.1,"id":5071877},{"batb":[[0,4.3,12.6],[1,4,49.57],[2,1.01,15.51]],"ltp":5.4,"tv":1960.5,"id":6374165}]}]}
