{"op":"mcm","clk":"995732875","pt":1580515645283,"mc":[{"id":"1.168175449","marketDefinition":{"bspMarket":false,"turnInPlayEnabled":true,"persistenceEnabled":true,"marketBaseRate":5.0,"eventId":"29680072","eventTypeId":"2","numberOfWinners":1,"bettingType":"ODDS","marketType":"SET_BETTING","marketTime":"2020-02-02T13:00:00.000Z","suspendTime":"2020-02-02T13:00:00.000Z","bspReconciled":false,"complete":true,"inPlay":false,"crossMatching":false,"runnersVoidable":false,"numberOfActiveRunners":4,"betDelay":0,"status":"OPEN","runners":[{"status":"ACTIVE","sortPriority":1,"id":13117391,"name":"Cecchinato 2-0"},{"status":"ACTIVE","sortPriority":2,"id":13117392,"name":"Cecchinato 2-1"},{"status":"ACTIVE","sortPriority":3,"id":13117448,"name":"Martin 2-0"},{"status":"ACTIVE","sortPriority":4,"id":13117449,"name":"Martin 2-1"}],"regulators":["MR_INT"],"countryCode":"UY","discountAllowed":false,"timezone":"UTC","openDate":"2020-02-02T13:00:00.000Z","version":3144186613,"name":"Set Betting","eventName":"Cecchinato v Martin"}}]}
{"op":"mcm","clk":"995733031","pt":1580515646599,"mc":[{"id":"1.168175449","marketDefinition":{"bspMarket":false,"turnInPlayEnabled":true,"persistenceEnabled":true,"marketBaseRate":5.0,"eventId":"29680072","eventTypeId":"2","numberOfWinners":1,"bettingType":"ODDS","marketType":"SET_BETTING","marketTime":"2020-02-02T13:00:00.000Z","suspendTime":"2020-02-02T13:00:00.000Z","bspReconciled":false,"complete":true,"inPlay":false,"crossMatching":false,"runnersVoidable":false,"numberOfActiveRunners":4,"betDelay":0,"status":"OPEN","runners":[{"status":"ACTIVE","sortPriority":1,"id":13117391,"name":"Cecchinato 2-0"},{"status":"ACTIVE","sortPriority":2,"id":13117392,"name":"Cecchinato 2-1"},{"status":"ACTIVE","sortPriority":3,"id":13117448,"name":"Martin 2-0"},{"status":"ACTIVE","sortPriority":4,"id":13117449,"name":"Martin 2-1"}],"regulators":["MR_INT"],"countryCode":"UY","discountAllowed":false,"timezone":"UTC","openDate":"2020-02-02T13:00:00.000Z","version":3144186613,"name":"Set Betting","eventName":"Cecchinato v Martin"}}]}
{"op":"mcm","clk":"995733303","pt":1580515649573,"mc":[{"id":"1.168175449","marketDefinition":{"bspMarket":false,"turnInPlayEnabled":true,"persistenceEnabled":true,"marketBaseRate":5.0,"eventId":"29680072","eventTypeId":"2","numberOfWinners":1,"bettingType":"ODDS","marketType":"SET_BETTING","marketTime":"2020-02-02T13:00:00.000Z","suspendTime":"2020-02-02T13:00:00.000Z","bspReconciled":false,"complete":true,"inPlay":false,"crossMatching":false,"runnersVoidable":false,"numberOfActiveRunners":4,"betDelay":0,"status":"OPEN","runners":[{"status":"ACTIVE","sortPriority":1,"id":13117391,"name":"Cecchinato 2-0"},{"status":"ACTIVE","sortPriority":2,"id":13117392,"name":"Cecchinato 2-1"},{"status":"ACTIVE","sortPriority":3,"id":13117448,"name":"Martin 2-0"},{"status":"ACTIVE","sortPriority":4,"id":13117449,"name":"Martin 2-1"}],"regulators":["MR_INT"],"countryCode":"UY","discountAllowed":true,"timezone":"UTC","openDate":"2020-02-02T13:00:00.000Z","version":3144186613,"name":"Set Betting","eventName":"Cecchinato v Martin"}}]}
{"op":"mcm","clk":"995757893","pt":1580515942918,"mc":[{"id":"1.168175449","rc":[{"batb":[[0,1.02,2]],"ltp":0.0,"tv":0.0,"id":13117449},{"batb":[[0,1.02,2]],"ltp":0.0,"tv":0.0,"id":13117448},{"batb":[[0,1.02,2]],"ltp":0.0,"tv":0.0,"id":13117392},{"batb":[[0,1.02,2]],"ltp":0.0,"tv":0.0,"id":13117391}]}]}
{"op":"mcm","clk":"995889896","pt":1580517337345,"mc":[{"id":"1.168175449","marketDefinition":{"bspMarket":false,"turnInPlayEnabled":true,"persistenceEnabled":true,"marketBaseRate":5.0,"eventId":"29680072","eventTypeId":"2","numberOfWinners":1,"bettingType":"ODDS","marketType":"SET_BETTING","marketTime":"2020-02-01T22:00:00.000Z","suspendTime":"2020-02-01T22:00:00.000Z","bspReconciled":false,"complete":true,"inPlay":false,"crossMatching":false,"runnersVoidable":false,"numberOfActiveRunners":4,"betDelay":0,"status":"OPEN","runners":[{"status":"ACTIVE","sortPriority":1,"id":13117391,"name":"Cecchinato 2-0"},{"status":"ACTIVE","sortPriority":2,"id":13117392,"name":"Cecchinato 2-1"},{"status":"ACTIVE","sortPriority":3,"id":13117448,"name":"Martin 2-0"},{"status":"ACTIVE","sortPriority":4,"id":13117449,"name":"Martin 2-1"}],"regulators":["MR_INT"],"countryCode":"UY","discountAllowed":true,"timezone":"UTC","openDate":"2020-02-02T13:00:00.000Z","version":3144220323,"name":"Set Betting","eventName":"Cecchinato v Martin"}}]}
{"op":"mcm","clk":"995890182","pt":1580517341374,"mc":[{"id":"1.168175449","marketDefinition":{"bspMarket":false,"turnInPlayEnabled":true,"persistenceEnabled":true,"marketBaseRate":5.0,"eventId":"29680072","eventTypeId":"2","numberOfWinners":1,"bettingType":"ODDS","marketType":"SET_BETTING","marketTime":"2020-02-01T22:00:00.000Z","suspendTime":"2020-02-01T22:00:00.000Z","bspReconciled":false,"complete":true,"inPlay":false,"crossMatching":false,"runnersVoidable":false,"numberOfActiveRunners":4,"betDelay":0,"status":"OPEN","runners":[{"status":"ACTIVE","sortPriority":1,"id":13117391,"name":"Cecchinato 2-0"},{"status":"ACTIVE","sortPriority":2,"id":13117392,"name":"Cecchinato 2-1"},{"status":"ACTIVE","sortPriority":3,"id":13117448,"name":"Martin 2-0"},{"status":"ACTIVE","sortPriority":4,"id":13117449,"name":"Martin 2-1"}],"regulators":["MR_INT"],"countryCode":"UY","discountAllowed":true,"timezone":"UTC","openDate":"2020-02-01T22:00:00.000Z","version":3144220323,"name":"Set Betting","eventName":"Cecchinato v Martin"}}]}
{"op":"mcm","clk":"996349835","pt":1580523359464,"mc":[{"id":"1.168175449","rc":[{"batb":[[1,1.01,2.53]],"ltp":0.0,"tv":0.0,"id":13117449},{"batb":[[1,1.01,2.53]],"ltp":0.0,"tv":0.0,"id":13117448},{"batb":[[1,1.01,2.53]],"ltp":0.0,"tv":0.0,"id":13117392},{"batb":[[1,1.01,2.53]],"ltp":0.0,"tv":0.0,"id":13117391}]}]}
{"op":"mcm","clk":"996349913","pt":1580523360497,"mc":[{"id":"1.168175449","rc":[{"batb":[[1,1.01,0]],"ltp":0.0,"tv":0.0,"id":13117449},{"batb":[[1,1.01,0]],"ltp":0.0,"tv":0.0,"id":13117448},{"batb":[[1,1.01,0]],"ltp":0.0,"tv":0.0,"id":13117392},{"batb":[[1,1.01,0]],"ltp":0.0,"tv":0.0,"id":13117391}]}]}
{"op":"mcm","clk":"996349990","pt":1580523361476,"mc":[{"id":"1.168175449","rc":[{"batb":[[1,1.01,0.51]],"ltp":0.0,"tv":0.0,"id":13117449},{"batb":[[1,1.01,0.51]],"ltp":0.0,"tv":0.0,"id":13117448},{"batb":[[1,1.01,0.51]],"ltp":0.0,"tv":0.0,"id":13117392},{"batb":[[1,1.01,0.51]],"ltp":0.0,"tv":0.0,"id":13117391}]}]}
{"op":"mcm","clk":"996362376","pt":1580523562102,"mc":[{"id":"1.168175449","rc":[{"batb":[[1,1.01,3.04]],"ltp":0.0,"tv":0.0,"id":13117449},{"batb":[[1,1.01,3.04]],"ltp":0.0,"tv":0.0,"id":13117448},{"batb":[[1,1.01,3.04]],"ltp":0.0,"tv":0.0,"id":13117392},{"batb":[[1,1.01,3.04]],"ltp":0.0,"tv":0.0,"id":13117391}]}]}
{"op":"mcm","clk":"996362469","pt":1580523563440,"mc":[{"id":"1.168175449","rc":[{"batb":[[1,1.01,1.01]],"ltp":0.0,"tv":0.0,"id":13117449},{"batb":[[1,1.01,1.01]],"ltp":0.0,"tv":0.0,"id":13117448},{"batb":[[1,1.01,1.01]],"ltp":0.0,"tv":0.0,"id":13117392},{"batb":[[1,1.01,1.01]],"ltp":0.0,"tv":0.0,"id":13117391}]}]}
{"op":"mcm","clk":"997117629","pt":1580535296012,"mc":[{"id":"1.168175449","rc":[{"batb":[[0,5,10],[1,1.02,2],[2,1.01,1.01]],"ltp":0.0,"tv":0.0,"id":13117449},{"batb":[[0,4.5,10],[1,1.02,2],[2,1.01,1.01]],"ltp":0.0,"tv":0.0,"id":13117448},{"batb":[[0,3.75,10],[1,1.02,2],[2,1.01,1.01]],"ltp":0.0,"tv":0.0,"id":13117392},{"batb":[[0,2.1,24.7],[1,1.02,2],[2,1.01,1.01]],"ltp":0.0,"tv":0.0,"id":13117391}]}]}
{"op":"mcm","clk":"997118124","pt":1580535307442,"mc":[{"id":"1.168175449","marketDefinition":{"bspMarket":false,"turnInPlayEnabled":true,"persistenceEnabled":true,"marketBaseRate":5.0,"eventId":"29680072","eventTypeId":"2","numberOfWinners":1,"bettingType":"ODDS","marketType":"SET_BETTING","marketTime":"2020-02-01T22:00:00.000Z","suspendTime":"2020-02-01T22:00:00.000Z","bspReconciled":false,"complete":true,"inPlay":false,"crossMatching":true,"runnersVoidable":false,"numberOfActiveRunners":4,"betDelay":0,"status":"OPEN","runners":[{"status":"ACTIVE","sortPriority":1,"id":13117391,"name":"Cecchinato 2-0"},{"status":"ACTIVE","sortPriority":2,"id":13117392,"name":"Cecchinato 2-1"},{"status":"ACTIVE","sortPriority":3,"id":13117448,"name":"Martin 2-0"},{"status":"ACTIVE","sortPriority":4,"id":13117449,"name":"Martin 2-1"}],"regulators":["MR_INT"],"countryCode":"UY","discountAllowed":true,"timezone":"UTC","openDate":"2020-02-01T22:00:00.000Z","version":3144220323,"name":"Set Betting","eventName":"Cecchinato v Martin"}}]}
{"op":"mcm","clk":"997122376","pt":1580535426895,"mc":[{"id":"1.168175449","rc":[{"batb":[[0,5,10]],"ltp":0.0,"tv":0.0,"id":13117448},{"batb":[[0,2,27.17]],"ltp":0.0,"tv":0.0,"id":13117391}]}]}
{"op":"mcm","clk":"997216442","pt":1580536971334,"mc":[{"id":"1.168175449","rc":[{"batb":[[0,4.5,10]],"ltp":0.0,"tv":0.0,"id":13117448},{"batb":[[0,2.2,22.64]],"ltp":0.0,"tv":0.0,"id":13117391}]}]}
{"op":"mcm","clk":"997217629","pt":1580536996374,"mc":[{"id":"1.168175449","rc":[{"batb":[[0,4.5,10]],"ltp":0.0,"tv":0.0,"id":13117449},{"batb":[[0,4,10]],"ltp":0.0,"tv":0.0,"id":13117448},{"batb":[[0,2.4,19.41]],"ltp":0.0,"tv":0.0,"id":13117391}]}]}
{"op":"mcm","clk":"997220241","pt":1580537056734,"mc":[{"id":"1.168175449","rc":[{"batb":[[0,5,10]],"ltp":0.0,"tv":0.0,"id":13117449},{"batb":[[0,4.2,10]],"ltp":0.0,"tv":0.0,"id":13117448},{"batb":[[0,2.3,20.9]],"ltp":0.0,"tv":0.0,"id":13117391}]}]}
{"op":"mcm","clk":"997236463","pt":1580537449231,"mc":[{"id":"1.168175449","rc":[{"batb":[[0,4.5,10]],"ltp":0.0,"tv":0.0,"id":13117448},{"batb":[[0,2.2,22.64]],"ltp":0.0,"tv":0.0,"id":13117391}]}]}
{"op":"mcm","clk":"997252133","pt":1580537601567,"mc":[{"id":"1.168175449","rc":[{"batb":[[0,5.1,50.04],[1,5,10],[2,1.02,2]],"ltp":0.0,"tv":0.0,"id":13117449},{"batb":[[1,4.3,59.38],[2,1.02,2]],"ltp":0.0,"tv":0.0,"id":13117448},{"batb":[[0,3.8,67.23],[1,3.75,10],[2,1.02,2]],"batl":[[0,14,186.54]],"ltp":0.0,"tv":0.0,"id":13117392}]}]}
{"op":"mcm","clk":"997252148","pt":1580537601883,"mc":[{"id":"1.168175449","rc":[{"batl":[[0,60,40.28]],"ltp":0.0,"tv":0.0,"id":13117449},{"batb":[[1,1.02,2],[2,1.01,1.01]],"batl":[[0,22,114.65]],"ltp":0.0,"tv":0.0,"id":13117448}]}]}
{"op":"mcm","clk":"997260815","pt":1580537848221,"mc":[{"id":"1.168175449","rc":[{"batb":[[1,3.55,30.29],[2,1.02,2]],"ltp":0.0,"tv":0.0,"id":13117448}]}]}
{"op":"mcm","clk":"997332402","pt":1580539270767,"mc":[{"id":"1.168175449","rc":[{"batb":[[0,4.2,10]],"ltp":0.0,"tv":0.0,"id":13117448},{"batb":[[0,2.3,20.9]],"ltp":0.0,"tv":0.0,"id":13117391}]}]}
{"op":"mcm","clk":"997333733","pt":1580539309702,"mc":[{"id":"1.168175449","rc":[{"batb":[[1,3.4,30.29]],"ltp":0.0,"tv":0.0,"id":13117448}]}]}
{"op":"mcm","clk":"997347649","pt":1580539431360,"mc":[{"id":"1.168175449","rc":[{"batb":[[1,3.45,30.29]],"ltp":0.0,"tv":0.0,"id":13117448}]}]}
{"op":"mcm","clk":"997446411","pt":1580541201524,"mc":[{"id":"1.168175449","rc":[{"batb":[[0,5,10],[1,1.02,2],[2,1.01,1.01]],"ltp":0.0,"tv":0.0,"id":13117449},{"batb":[[0,3.75,10],[1,1.02,2],[2,1.01,1.01]],"ltp":0.0,"tv":0.0,"id":13117392}]}]}
{"op":"mcm","clk":"997446442","pt":1580541202144,"mc":[{"id":"1.168175449","rc":[{"batb":[[0,5.3,48.08],[1,5,10],[2,1.02,2]],"batl":[[0,42,57.53]],"ltp":0.0,"tv":0.0,"id":13117449},{"batb":[[0,4.3,59.38],[1,4.2,10],[2,3.45,30.29]],"batl":[[0,23,109.67]],"ltp":0.0,"tv":0.0,"id":13117448},{"batb":[[0,3.85,66.37],[1,3.75,10],[2,1.02,2]],"batl":[[0,13,200.87]],"ltp":0.0,"tv":0.0,"id":13117392}]}]}
{"op":"mcm","clk":"997448682","pt":1580541256570,"mc":[{"id":"1.168175449","rc":[{"batb":[[2,1.02,2]],"ltp":0.0,"tv":0.0,"id":13117448}]}]}
{"op":"mcm","clk":"997449866","pt":1580541283530,"mc":[{"id":"1.168175449","rc":[{"batb":[[2,4.5,10]],"ltp":0.0,"tv":0.0,"id":13117449},{"batb":[[2,3.75,10]],"ltp":0.0,"tv":0.0,"id":13117448},{"batb":[[0,2.4,19.41],[1,2.3,20.9],[2,1.02,2]],"ltp":0.0,"tv":0.0,"id":13117391}]}]}
{"op":"mcm","clk":"997449874","pt":1580541283840,"mc":[{"id":"1.168175449","rc":[{"batb":[[1,4.5,10],[2,1.02,2]],"ltp":0.0,"tv":0.0,"id":13117449},{"batb":[[1,3.75,10],[2,1.02,2]],"ltp":0.0,"tv":0.0,"id":13117448},{"batb":[[1,1.02,2],[2,1.01,1.01]],"ltp":0.0,"tv":0.0,"id":13117391}]}]}
{"op":"mcm","clk":"997637819","pt":1580544802396,"mc":[{"id":"1.168175449","rc":[{"batb":[[0,5,51.21]],"batl":[[0,75,32.22]],"ltp":0.0,"tv":0.0,"id":13117449},{"batb":[[0,3.8,67.23]],"ltp":0.0,"tv":0.0,"id":13117448},{"batb":[[0,3.75,10],[1,1.02,2],[2,1.01,1.01]],"batl":[[0,12,217.58]],"ltp":0.0,"tv":0.0,"id":13117392}]}]}
{"op":"mcm","clk":"997643953","pt":1580544908795,"mc":[{"id":"1.168175449","rc":[{"batb":[[0,3.85,30.29],[1,3.8,67.23],[2,3.75,10]],"ltp":0.0,"tv":0.0,"id":13117448}]}]}
{"op":"mcm","clk":"997760842","pt":1580546471999,"mc":[{"id":"1.168175449","rc":[{"batb":[[0,4.2,60.77],[1,3.85,30.29]],"batl":[[0,14.5,173.61]],"ltp":0.0,"tv":0.0,"id":13117448}]}]}
{"op":"mcm","clk":"997762470","pt":1580546493014,"mc":[{"id":"1.168175449","rc":[{"batb":[[1,3.75,10],[2,1.02,2]],"ltp":0.0,"tv":0.0,"id":13117448}]}]}
{"op":"mcm","clk":"997909603","pt":1580548304145,"mc":[{"id":"1.168175449","rc":[{"batl":[[0,14.5,17.67]],"ltp":0.0,"tv":0.0,"id":13117448}]}]}
{"op":"mcm","clk":"997928779","pt":1580548402397,"mc":[{"id":"1.168175449","rc":[{"batb":[[0,4.5,10],[1,1.02,2],[2,1.01,1.01]],"ltp":0.0,"tv":0.0,"id":13117449},{"batb":[[0,3.75,10],[1,1.02,2],[2,1.01,1.01]],"ltp":0.0,"tv":0.0,"id":13117448},{"batb":[[0,3.8,67.23],[1,3.75,10],[2,1.02,2]],"ltp":0.0,"tv":0.0,"id":13117392}]}]}
{"op":"mcm","clk":"997928796","pt":1580548402608,"mc":[{"id":"1.168175449","rc":[{"batb":[[0,3.8,67.23],[1,3.75,10],[2,1.02,2]],"ltp":0.0,"tv":0.0,"id":13117448}]}]}
{"op":"mcm","clk":"997931807","pt":1580548439829,"mc":[{"id":"1.168175449","rc":[{"batb":[[0,3.85,30.29],[1,3.8,67.23],[2,3.75,10]],"ltp":0.0,"tv":0.0,"id":13117448}]}]}
{"op":"mcm","clk":"997937578","pt":1580548510479,"mc":[{"id":"1.168175449","rc":[{"batb":[[1,3.75,10],[2,1.02,2]],"batl":[[0,14.5,174.27]],"ltp":0.0,"tv":0.0,"id":13117448}]}]}
{"op":"mcm","clk":"997937588","pt":1580548510583,"mc":[{"id":"1.168175449","rc":[{"batb":[[0,3.9,65.56],[1,3.85,30.29],[2,3.75,10]],"ltp":0.0,"tv":0.0,"id":13117448}]}]}
{"op":"mcm","clk":"997941746","pt":1580548561554,"mc":[{"id":"1.168175449","rc":[{"batb":[[1,3.75,10],[2,1.02,2]],"ltp":0.0,"tv":0.0,"id":13117448}]}]}
{"op":"mcm","clk":"997941795","pt":1580548561925,"mc":[{"id":"1.168175449","rc":[{"batb":[[0,4,64.07],[1,3.95,30.29],[2,3.75,10]],"ltp":0.0,"tv":0.0,"id":13117448}]}]}
{"op":"mcm","clk":"997953358","pt":1580548684321,"mc":[{"id":"1.168175449","rc":[{"batb":[[1,3.75,10],[2,1.02,2]],"ltp":0.0,"tv":0.0,"id":13117448}]}]}
{"op":"mcm","clk":"998049009","pt":1580549780413,"mc":[{"id":"1.168175449","rc":[{"batb":[[0,4.8,53.13],[1,4.5,10],[2,1.02,2]],"ltp":0.0,"tv":0.0,"id":13117449}]}]}
{"op":"mcm","clk":"998049022","pt":1580549780576,"mc":[{"id":"1.168175449","rc":[{"batl":[[0,40,60.68]],"ltp":0.0,"tv":0.0,"id":13117449}]}]}
{"op":"mcm","clk":"998071528","pt":1580550072290,"mc":[{"id":"1.168175449","rc":[{"batl":[[0,18.5,136.59]],"ltp":0.0,"tv":0.0,"id":13117448}]}]}
{"op":"mcm","clk":"998318932","pt":1580552003263,"mc":[{"id":"1.168175449","rc":[{"batb":[[0,3.9,65.56]],"ltp":0.0,"tv":0.0,"id":13117448},{"batl":[[0,12.5,208.65]],"ltp":0.0,"tv":0.0,"id":13117392}]}]}
{"op":"mcm","clk":"998331647","pt":1580552092643,"mc":[{"id":"1.168175449","rc":[{"batb":[[0,3.95,30.29],[1,3.9,65.56],[2,3.75,10]],"ltp":0.0,"tv":0.0,"id":13117448}]}]}
{"op":"mcm","clk":"998524271","pt":1580553380447,"mc":[{"id":"1.168175449","rc":[{"batb":[[0,4.5,10],[1,1.02,2],[2,1.01,1.01]],"ltp":0.0,"tv":0.0,"id":13117449}]}]}
{"op":"mcm","clk":"998524343","pt":1580553380983,"mc":[{"id":"1.168175449","rc":[{"batb":[[0,5.1,50.04],[1,4.5,10],[2,1.02,2]],"batl":[[0,46,52.77]],"ltp":0.0,"tv":0.0,"id":13117449}]}]}
{"op":"mcm","clk":"998566291","pt":1580553672516,"mc":[{"id":"1.168175449","rc":[{"batb":[[1,3.75,10],[2,1.02,2]],"batl":[[0,14.5,174.27]],"ltp":0.0,"tv":0.0,"id":13117448}]}]}
{"op":"mcm","clk":"998566305","pt":1580553672625,"mc":[{"id":"1.168175449","rc":[{"batb":[[0,4,64.07],[1,3.95,30.29],[2,3.75,10]],"ltp":0.0,"tv":0.0,"id":13117448}]}]}
{"op":"mcm","clk":"998566686","pt":1580553675602,"mc":[{"id":"1.168175449","rc":[{"batb":[[1,3.75,10],[2,1.02,2]],"ltp":0.0,"tv":0.0,"id":13117448}]}]}
{"op":"mcm","clk":"998895120","pt":1580555602404,"mc":[{"id":"1.168175449","rc":[{"batb":[[0,3.75,10],[1,1.02,2],[2,1.01,1.01]],"ltp":0.0,"tv":0.0,"id":13117392}]}]}
{"op":"mcm","clk":"998895377","pt":1580555603877,"mc":[{"id":"1.168175449","rc":[{"batb":[[0,4.3,59.38]],"ltp":0.0,"tv":0.0,"id":13117448}]}]}
{"op":"mcm","clk":"999168859","pt":1580556981376,"mc":[{"id":"1.168175449","rc":[{"batb":[[0,5.2,49.02]],"ltp":0.0,"tv":0.0,"id":13117449},{"batb":[[0,3.85,66.37],[1,3.75,10],[2,1.02,2]],"ltp":0.0,"tv":0.0,"id":13117392}]}]}
{"op":"mcm","clk":"999168897","pt":1580556981593,"mc":[{"id":"1.168175449","rc":[{"batl":[[0,11.5,226.77]],"ltp":0.0,"tv":0.0,"id":13117392}]}]}
{"op":"mcm","clk":"999227428","pt":1580557294254,"mc":[{"id":"1.168175449","rc":[{"batl":[[0,7.2,350.73]],"ltp":0.0,"tv":0.0,"id":13117448}]}]}
{"op":"mcm","clk":"999579633","pt":1580559203922,"mc":[{"id":"1.168175449","rc":[{"batb":[[0,3.75,10],[1,1.02,2],[2,1.01,1.01]],"ltp":0.0,"tv":0.0,"id":13117448}]}]}
{"op":"mcm","clk":"999594425","pt":1580559277090,"mc":[{"id":"1.168175449","rc":[{"batb":[[0,4,64.07],[1,3.75,10],[2,3.4,30.29]],"ltp":0.0,"tv":0.0,"id":13117448}]}]}
{"op":"mcm","clk":"999617451","pt":1580559398587,"mc":[{"id":"1.168175449","rc":[{"batb":[[2,1.02,2]],"ltp":0.0,"tv":0.0,"id":13117448}]}]}
{"op":"mcm","clk":"999853598","pt":1580560581451,"mc":[{"id":"1.168175449","rc":[{"batb":[[0,4.5,10],[1,1.02,2],[2,1.01,1.01]],"ltp":0.0,"tv":0.0,"id":13117449},{"batb":[[0,3.75,10],[1,1.02,2],[2,1.01,1.01]],"ltp":0.0,"tv":0.0,"id":13117392}]}]}
{"op":"mcm","clk":"999917758","pt":1580560894564,"mc":[{"id":"1.168175449","rc":[{"batl":[[0,17.5,144.39]],"ltp":0.0,"tv":0.0,"id":13117448}]}]}
{"op":"mcm","clk":"1000043239","pt":1580561468286,"mc":[{"id":"1.168175449","rc":[{"batb":[[0,4.2,60.77],[1,4.1,29.3],[2,3.75,10]],"ltp":0.0,"tv":0.0,"id":13117448}]}]}
{"op":"mcm","clk":"1000044309","pt":1580561473519,"mc":[{"id":"1.168175449","rc":[{"batb":[[0,5.1,50.04],[1,5,10],[2,1.02,2]],"batl":[[0,60,40.46]],"ltp":0.0,"tv":0.0,"id":13117449},{"batb":[[0,4.2,70.77],[2,1.02,2]],"ltp":0.0,"tv":0.0,"id":13117448},{"batb":[[0,2.3,20.9]],"ltp":0.0,"tv":0.0,"id":13117391}]}]}
{"op":"mcm","clk":"1000066944","pt":1580561589975,"mc":[{"id":"1.168175449","rc":[{"batb":[[1,1.02,2],[2,1.01,1.01]],"ltp":0.0,"tv":0.0,"id":13117448}]}]}
{"op":"mcm","clk":"1000354093","pt":1580562877968,"mc":[{"id":"1.168175449","rc":[{"batb":[[0,4.3,59.38],[1,4.2,10],[2,1.02,2]],"ltp":0.0,"tv":0.0,"id":13117448}]}]}
{"op":"mcm","clk":"1000652959","pt":1580564182548,"mc":[{"id":"1.168175449","rc":[{"batb":[[0,3.8,67.23],[1,3.75,10],[2,1.02,2]],"ltp":0.0,"tv":0.0,"id":13117392}]}]}
{"op":"mcm","clk":"1000653066","pt":1580564182926,"mc":[{"id":"1.168175449","rc":[{"batl":[[0,12.5,208.65]],"ltp":0.0,"tv":0.0,"id":13117392}]}]}
{"op":"mcm","clk":"1000728163","pt":1580564495072,"mc":[{"id":"1.168175449","rc":[{"batl":[[0,13.5,187.19]],"ltp":0.0,"tv":0.0,"id":13117448}]}]}
{"op":"mcm","clk":"1000835387","pt":1580564934274,"mc":[{"id":"1.168175449","rc":[{"batb":[[0,4.2,10],[1,1.02,2],[2,1.01,1.01]],"ltp":0.0,"tv":0.0,"id":13117448}]}]}
{"op":"mcm","clk":"1000848242","pt":1580564997967,"mc":[{"id":"1.168175449","rc":[{"batb":[[1,3.45,30.29],[2,1.02,2]],"ltp":0.0,"tv":0.0,"id":13117448}]}]}
{"op":"mcm","clk":"1000855979","pt":1580565038312,"mc":[{"id":"1.168175449","rc":[{"batl":[[0,13.5,19.01]],"ltp":0.0,"tv":0.0,"id":13117448},{"batl":[[0,12.5,20.53]],"ltp":0.0,"tv":0.0,"id":13117392}]}]}
{"op":"mcm","clk":"1000856105","pt":1580565038689,"mc":[{"id":"1.168175449","rc":[{"batb":[[0,4.2,70.77]],"ltp":0.0,"tv":0.0,"id":13117448}]}]}
{"op":"mcm","clk":"1000862737","pt":1580565073507,"mc":[{"id":"1.168175449","rc":[{"batb":[[0,5,10],[1,1.02,2],[2,1.01,1.01]],"ltp":0.0,"tv":0.0,"id":13117449}]}]}
{"op":"mcm","clk":"1000862838","pt":1580565073928,"mc":[{"id":"1.168175449","rc":[{"batl":[[0,13.5,187.93]],"ltp":0.0,"tv":0.0,"id":13117448}]}]}
{"op":"mcm","clk":"1000864574","pt":1580565082316,"mc":[{"id":"1.168175449","rc":[{"batl":[[0,12.5,207.57]],"ltp":0.0,"tv":0.0,"id":13117392}]}]}
{"op":"mcm","clk":"1000871752","pt":1580565119627,"mc":[{"id":"1.168175449","rc":[{"batb":[[1,1.02,2],[2,1.01,1.01]],"ltp":0.0,"tv":0.0,"id":13117448}]}]}
{"op":"mcm","clk":"1000891347","pt":1580565222527,"mc":[{"id":"1.168175449","rc":[{"batb":[[0,5.1,50.04],[1,5,10],[2,1.02,2]],"batl":[[0,80,30.35]],"ltp":0.0,"tv":0.0,"id":13117449}]}]}
{"op":"mcm","clk":"1001422269","pt":1580567782306,"mc":[{"id":"1.168175449","rc":[{"batb":[[0,3.75,10],[1,1.02,2],[2,1.01,1.01]],"ltp":0.0,"tv":0.0,"id":13117392}]}]}
{"op":"mcm","clk":"1001422357","pt":1580567782691,"mc":[{"id":"1.168175449","rc":[{"batb":[[0,3.85,66.37],[1,3.75,10],[2,1.02,2]],"ltp":0.0,"tv":0.0,"id":13117392}]}]}
{"op":"mcm","clk":"1001422592","pt":1580567784001,"mc":[{"id":"1.168175449","rc":[{"batl":[[0,7.4,350.44]],"ltp":0.0,"tv":0.0,"id":13117392}]}]}
{"op":"mcm","clk":"1001490669","pt":1580568095852,"mc":[{"id":"1.168175449","rc":[{"batl":[[0,9.4,269.84]],"ltp":0.0,"tv":0.0,"id":13117448}]}]}
{"op":"mcm","clk":"1001647280","pt":1580568822259,"mc":[{"id":"1.168175449","rc":[{"batb":[[0,5,10],[1,1.02,2],[2,1.01,1.01]],"ltp":0.0,"tv":0.0,"id":13117449}]}]}
{"op":"mcm","clk":"1001647352","pt":1580568822574,"mc":[{"id":"1.168175449","rc":[{"batb":[[0,5.2,49.02],[1,5,10],[2,1.02,2]],"ltp":0.0,"tv":0.0,"id":13117449}]}]}
{"op":"mcm","clk":"1002010152","pt":1580570357312,"mc":[{"id":"1.168175449","rc":[{"batb":[[0,4.3,27.53],[1,4.2,10],[2,1.02,2]],"ltp":0.0,"tv":0.0,"id":13117448}]}]}
{"op":"mcm","clk":"1002023904","pt":1580570417869,"mc":[{"id":"1.168175449","rc":[{"batb":[[0,4.3,37.53],[1,1.02,2],[2,1.01,1.01]],"ltp":0.0,"tv":0.0,"id":13117448},{"batb":[[0,2.24,21.91]],"ltp":0.0,"tv":0.0,"id":13117391}]}]}
{"op":"mcm","clk":"1002032519","pt":1580570453435,"mc":[{"id":"1.168175449","rc":[{"batb":[[0,2.2,139.36]],"ltp":0.0,"tv":0.0,"id":13117391}]}]}
{"op":"mcm","clk":"1002032641","pt":1580570453976,"mc":[{"id":"1.168175449","rc":[{"batl":[[0,4.1,165.55]],"ltp":0.0,"tv":0.0,"id":13117391}]}]}
{"op":"mcm","clk":"1002038580","pt":1580570478375,"mc":[{"id":"1.168175449","rc":[{"batb":[[0,2.22,30.29],[1,2.2,139.36],[2,1.02,2]],"ltp":0.0,"tv":0.0,"id":13117391}]}]}
{"op":"mcm","clk":"1002038846","pt":1580570479563,"mc":[{"id":"1.168175449","rc":[{"batb":[[0,4.3,10],[1,3.6,30.29],[2,1.02,2]],"ltp":0.0,"tv":0.0,"id":13117448},{"batb":[[1,2.2,22.64]],"ltp":0.0,"tv":0.0,"id":13117391}]}]}
{"op":"mcm","clk":"1002248310","pt":1580571383215,"mc":[{"id":"1.168175449","rc":[{"batb":[[0,3.8,67.23]],"ltp":0.0,"tv":0.0,"id":13117392}]}]}
{"op":"mcm","clk":"1002293941","pt":1580571574031,"mc":[{"id":"1.168175449","rc":[{"batb":[[0,2.2,139.36],[1,1.02,2],[2,1.01,1.01]],"ltp":0.0,"tv":0.0,"id":13117391}]}]}
{"op":"mcm","clk":"1002322562","pt":1580571696126,"mc":[{"id":"1.168175449","rc":[{"batl":[[0,18.5,137.13]],"ltp":0.0,"tv":0.0,"id":13117448}]}]}
{"op":"mcm","clk":"1002475847","pt":1580572422591,"mc":[{"id":"1.168175449","rc":[{"batb":[[0,5,10],[1,1.02,2],[2,1.01,1.01]],"ltp":0.0,"tv":0.0,"id":13117449}]}]}
{"op":"mcm","clk":"1002536729","pt":1580572800435,"mc":[{"id":"1.168175449","rc":[{"batb":[[0,5,10.19]],"ltp":0.0,"tv":0.0,"id":13117449},{"batb":[[0,4.3,12.35]],"ltp":0.0,"tv":0.0,"id":13117448},{"batb":[[1,3.75,14.82]],"ltp":0.0,"tv":0.0,"id":13117392},{"batb":[[0,2.2,150.69]],"ltp":0.0,"tv":0.0,"id":13117391}]}]}
{"op":"mcm","clk":"1002537009","pt":1580572801389,"mc":[{"id":"1.168175449","rc":[{"batb":[[0,5.1,50.04],[1,5,10.19],[2,1.02,2]],"ltp":0.0,"tv":0.0,"id":13117449},{"batl":[[0,14,185.59]],"ltp":0.0,"tv":0.0,"id":13117392}]}]}
{"op":"mcm","clk":"1002537256","pt":1580572802512,"mc":[{"id":"1.168175449","rc":[{"batl":[[0,36,67.42]],"ltp":0.0,"tv":0.0,"id":13117449}]}]}
{"op":"mcm","clk":"1003075154","pt":1580574983188,"mc":[{"id":"1.168175449","rc":[{"batb":[[0,3.75,14.82],[1,1.02,2],[2,1.01,1.01]],"ltp":0.0,"tv":0.0,"id":13117392}]}]}
{"op":"mcm","clk":"1003075251","pt":1580574983588,"mc":[{"id":"1.168175449","rc":[{"batb":[[0,3.85,66.37],[1,3.75,14.82],[2,1.02,2]],"ltp":0.0,"tv":0.0,"id":13117392}]}]}
{"op":"mcm","clk":"1003123172","pt":1580575174451,"mc":[{"id":"1.168175449","rc":[{"batl":[[0,3.6,188.41]],"ltp":0.0,"tv":0.0,"id":13117391}]}]}
{"op":"mcm","clk":"1003314496","pt":1580576023006,"mc":[{"id":"1.168175449","rc":[{"batb":[[0,5.1,12],[1,4.3,12.35],[2,3.6,30.29]],"batl":[[0,8.2,309.28]],"ltp":0.0,"tv":0.0,"id":13117448}]}]}
{"op":"mcm","clk":"1003314962","pt":1580576026042,"mc":[{"id":"1.168175449","rc":[{"trd":[[2.2,2.54]],"batb":[[0,2.2,149.42]],"ltp":2.2,"tv":2.53,"id":13117391}],"tv":2.53}]}
{"op":"mcm","clk":"1003315263","pt":1580576027992,"mc":[{"id":"1.168175449","rc":[{"batb":[[0,2.2,150.69]],"ltp":2.2,"tv":2.53,"id":13117391}]}]}
{"op":"mcm","clk":"1003316496","pt":1580576035165,"mc":[{"id":"1.168175449","rc":[{"batb":[[2,1.02,2]],"ltp":0.0,"tv":0.0,"id":13117448}]}]}
{"op":"mcm","clk":"1003374236","pt":1580576401367,"mc":[{"id":"1.168175449","rc":[{"batb":[[0,5,10.19],[1,1.02,2],[2,1.01,1.01]],"ltp":0.0,"tv":0.0,"id":13117449}]}]}
{"op":"mcm","clk":"1003374489","pt":1580576402552,"mc":[{"id":"1.168175449","rc":[{"batb":[[0,5.1,50.04],[1,5,10.19],[2,1.02,2]],"ltp":0.0,"tv":0.0,"id":13117449}]}]}
{"op":"mcm","clk":"1003374611","pt":1580576403051,"mc":[{"id":"1.168175449","rc":[{"batl":[[0,22,110.29]],"ltp":0.0,"tv":0.0,"id":13117449}]}]}
{"op":"mcm","clk":"1003630505","pt":1580577765406,"mc":[{"id":"1.168175449","rc":[{"batl":[[0,8.2,31.43]],"ltp":0.0,"tv":0.0,"id":13117448},{"batl":[[0,12,217.58]],"ltp":0.0,"tv":0.0,"id":13117392},{"batl":[[0,3.6,183.76]],"ltp":2.2,"tv":2.53,"id":13117391}]}]}
{"op":"mcm","clk":"1003641908","pt":1580577823160,"mc":[{"id":"1.168175449","rc":[{"batl":[[0,8.2,308.03]],"ltp":0.0,"tv":0.0,"id":13117448}]}]}
{"op":"mcm","clk":"1003643593","pt":1580577831271,"mc":[{"id":"1.168175449","rc":[{"batl":[[0,22,11.82]],"ltp":0.0,"tv":0.0,"id":13117449},{"batl":[[0,8.2,306.88]],"ltp":0.0,"tv":0.0,"id":13117448},{"batb":[[0,2.2,33.97]],"batl":[[0,3.6,71.66]],"ltp":2.2,"tv":2.53,"id":13117391}]}]}
{"op":"mcm","clk":"1003647829","pt":1580577851406,"mc":[{"id":"1.168175449","rc":[{"batb":[[1,4.5,11.64]],"ltp":0.0,"tv":0.0,"id":13117448},{"batb":[[0,2.12,121.29],[1,2.1,37.06],[2,1.02,2]],"ltp":2.2,"tv":2.53,"id":13117391}]}]}
{"op":"mcm","clk":"1003652856","pt":1580577874690,"mc":[{"id":"1.168175449","rc":[{"batl":[[0,3.6,174.66]],"ltp":2.2,"tv":2.53,"id":13117391}]}]}
{"op":"mcm","clk":"1003658543","pt":1580577902012,"mc":[{"id":"1.168175449","rc":[{"batl":[[0,22,109.78]],"ltp":0.0,"tv":0.0,"id":13117449}]}]}
{"op":"mcm","clk":"1003764407","pt":1580578475442,"mc":[{"id":"1.168175449","rc":[{"batb":[[0,2.14,30.29]],"ltp":2.2,"tv":2.53,"id":13117391}]}]}
{"op":"mcm","clk":"1003764429","pt":1580578475645,"mc":[{"id":"1.168175449","rc":[{"batb":[[0,2.16,119.03],[1,2.14,30.29],[2,2.1,37.06]],"ltp":2.2,"tv":2.53,"id":13117391}]}]}
{"op":"mcm","clk":"1003784136","pt":1580578584109,"mc":[{"id":"1.168175449","rc":[{"batb":[[0,3.8,67.23]],"ltp":0.0,"tv":0.0,"id":13117392}]}]}
{"op":"mcm","clk":"1003786423","pt":1580578596804,"mc":[{"id":"1.168175449","rc":[{"batb":[[1,2.1,37.06],[2,1.02,2]],"ltp":2.2,"tv":2.53,"id":13117391}]}]}
{"op":"mcm","clk":"1003818503","pt":1580578775770,"mc":[{"id":"1.168175449","rc":[{"batl":[[0,3.55,177.1]],"ltp":2.2,"tv":2.53,"id":13117391}]}]}
{"op":"mcm","clk":"1004020549","pt":1580579986796,"mc":[{"id":"1.168175449","rc":[{"batb":[[1,5,11.07]],"ltp":0.0,"tv":0.0,"id":13117449},{"batb":[[1,4.5,12.65]],"ltp":0.0,"tv":0.0,"id":13117448},{"batb":[[1,3.75,16.1]],"ltp":0.0,"tv":0.0,"id":13117392},{"batb":[[1,2.1,40.26]],"ltp":2.2,"tv":2.53,"id":13117391}]}]}
{"op":"mcm","clk":"1004022916","pt":1580580001830,"mc":[{"id":"1.168175449","rc":[{"batb":[[0,5,11.07],[1,1.02,2],[2,1.01,1.01]],"ltp":0.0,"tv":0.0,"id":13117449}]}]}
{"op":"mcm","clk":"1004023345","pt":1580580004229,"mc":[{"id":"1.168175449","rc":[{"batl":[[0,21,115]],"ltp":0.0,"tv":0.0,"id":13117449}]}]}
{"op":"mcm","clk":"1004286995","pt":1580581452378,"mc":[{"id":"1.168175449","rc":[{"batb":[[0,2.1,40.26],[1,1.02,2],[2,1.01,1.01]],"ltp":2.2,"tv":2.53,"id":13117391}]}]}
{"op":"mcm","clk":"1004287056","pt":1580581452759,"mc":[{"id":"1.168175449","rc":[{"batb":[[0,2.16,119.03],[1,2.1,40.26],[2,1.02,2]],"ltp":2.2,"tv":2.53,"id":13117391}]}]}
{"op":"mcm","clk":"1004412276","pt":1580582184050,"mc":[{"id":"1.168175449","rc":[{"batb":[[0,3.75,16.1],[1,1.02,2],[2,1.01,1.01]],"ltp":0.0,"tv":0.0,"id":13117392}]}]}
{"op":"mcm","clk":"1004412487","pt":1580582185030,"mc":[{"id":"1.168175449","rc":[{"batb":[[0,3.85,66.37],[1,3.75,16.1],[2,1.02,2]],"batl":[[0,13.5,193.44]],"ltp":0.0,"tv":0.0,"id":13117392}]}]}
{"op":"mcm","clk":"1004546239","pt":1580582943015,"mc":[{"id":"1.168175449","rc":[{"batb":[[0,5.1,50.04],[1,5,11.07],[2,1.02,2]],"ltp":0.0,"tv":0.0,"id":13117449}]}]}
{"op":"mcm","clk":"1004926511","pt":1580585052762,"mc":[{"id":"1.168175449","rc":[{"batb":[[0,2.1,40.26],[1,1.02,2],[2,1.01,1.01]],"ltp":2.2,"tv":2.53,"id":13117391}]}]}
{"op":"mcm","clk":"1004926968","pt":1580585055326,"mc":[{"id":"1.168175449","rc":[{"batb":[[0,2.12,30.29],[1,2.1,40.26],[2,1.02,2]],"ltp":2.2,"tv":2.53,"id":13117391}]}]}
{"op":"mcm","clk":"1005048097","pt":1580585785098,"mc":[{"id":"1.168175449","rc":[{"batb":[[0,3.75,16.1],[1,1.02,2],[2,1.01,1.01]],"ltp":0.0,"tv":0.0,"id":13117392}]}]}
{"op":"mcm","clk":"1005048162","pt":1580585785611,"mc":[{"id":"1.168175449","rc":[{"batl":[[0,7.8,334.22]],"ltp":0.0,"tv":0.0,"id":13117392}]}]}
{"op":"mcm","clk":"1005084782","pt":1580586015483,"mc":[{"id":"1.168175449","rc":[{"batb":[[0,3.8,67.23],[1,3.75,16.1],[2,1.02,2]],"batl":[[0,7.8,336.02]],"ltp":0.0,"tv":0.0,"id":13117392},{"batb":[[0,2.14,120.03],[1,2.12,30.29],[2,2.1,40.26]],"batl":[[0,2.88,212.54]],"ltp":2.2,"tv":2.53,"id":13117391}]}]}
{"op":"mcm","clk":"1005087212","pt":1580586030397,"mc":[{"id":"1.168175449","rc":[{"batb":[[1,2.1,40.26],[2,1.02,2]],"ltp":2.2,"tv":2.53,"id":13117391}]}]}
{"op":"mcm","clk":"1005166620","pt":1580586543491,"mc":[{"id":"1.168175449","rc":[{"batb":[[0,5.3,48.08]],"batl":[[0,85,28.43]],"ltp":0.0,"tv":0.0,"id":13117449}]}]}
{"op":"mcm","clk":"1005259556","pt":1580587202599,"mc":[{"id":"1.168175449","rc":[{"batb":[[1,5,14.76]],"ltp":0.0,"tv":0.0,"id":13117449},{"batb":[[1,4.5,16.87]],"ltp":0.0,"tv":0.0,"id":13117448},{"batb":[[1,3.75,21.47]],"ltp":0.0,"tv":0.0,"id":13117392},{"batb":[[1,2.1,53.68]],"ltp":2.2,"tv":2.53,"id":13117391}]}]}
{"op":"mcm","clk":"1005268028","pt":1580587261178,"mc":[{"id":"1.168175449","rc":[{"batb":[[0,5.4,12]],"ltp":0.0,"tv":0.0,"id":13117448}]}]}
{"op":"mcm","clk":"1005615565","pt":1580589386083,"mc":[{"id":"1.168175449","rc":[{"batl":[[0,7.6,344.81]],"ltp":0.0,"tv":0.0,"id":13117392}]}]}
{"op":"mcm","clk":"1005648990","pt":1580589615102,"mc":[{"id":"1.168175449","rc":[{"batb":[[0,3.75,21.47],[1,1.02,2],[2,1.01,1.01]],"ltp":0.0,"tv":0.0,"id":13117392},{"batb":[[0,2.1,53.68],[1,1.02,2],[2,1.01,1.01]],"ltp":2.2,"tv":2.53,"id":13117391}]}]}
{"op":"mcm","clk":"1005659076","pt":1580589682352,"mc":[{"id":"1.168175449","rc":[{"batb":[[0,2.12,30.29],[1,2.1,53.68],[2,1.02,2]],"ltp":2.2,"tv":2.53,"id":13117391}]}]}
{"op":"mcm","clk":"1005659144","pt":1580589682718,"mc":[{"id":"1.168175449","rc":[{"batb":[[0,2.14,120.03],[1,2.12,30.29],[2,2.1,53.68]],"batl":[[0,2.74,223.48]],"ltp":2.2,"tv":2.53,"id":13117391}]}]}
{"op":"mcm","clk":"1005676199","pt":1580589803958,"mc":[{"id":"1.168175449","rc":[{"batb":[[1,2.1,53.68],[2,1.02,2]],"ltp":2.2,"tv":2.53,"id":13117391}]}]}
{"op":"mcm","clk":"1005720276","pt":1580590143504,"mc":[{"id":"1.168175449","rc":[{"batb":[[0,5.4,47.16]],"ltp":0.0,"tv":0.0,"id":13117449}]}]}
{"op":"mcm","clk":"1005720293","pt":1580590143611,"mc":[{"id":"1.168175449","rc":[{"batl":[[0,70,34.52]],"ltp":0.0,"tv":0.0,"id":13117449}]}]}
{"op":"mcm","clk":"1005727479","pt":1580590205087,"mc":[{"id":"1.168175449","rc":[{"batl":[[0,2.62,42.22],[1,2.74,223.48]],"ltp":2.2,"tv":2.53,"id":13117391}]}]}
{"op":"mcm","clk":"1005729916","pt":1580590225992,"mc":[{"id":"1.168175449","rc":[{"batl":[[0,7.8,29.55]],"ltp":0.0,"tv":0.0,"id":13117448}]}]}
{"op":"mcm","clk":"1005751801","pt":1580590425749,"mc":[{"id":"1.168175449","rc":[{"batl":[[0,6.4,391.77],[1,7.8,29.55]],"ltp":0.0,"tv":0.0,"id":13117448}]}]}
{"op":"mcm","clk":"1005795086","pt":1580590839462,"mc":[{"id":"1.168175449","rc":[{"batb":[[0,5.5,2],[1,5.4,47.16],[2,5,14.76]],"ltp":0.0,"tv":0.0,"id":13117449},{"batb":[[0,5.5,2],[1,5.4,12],[2,4.5,16.87]],"ltp":0.0,"tv":0.0,"id":13117448},{"batb":[[0,3.8,2],[1,3.75,21.47],[2,1.02,2]],"ltp":0.0,"tv":0.0,"id":13117392},{"batb":[[0,2.16,2],[1,2.14,120.03],[2,2.1,53.68]],"ltp":2.2,"tv":2.53,"id":13117391}]}]}
{"op":"mcm","clk":"1005795130","pt":1580590839890,"mc":[{"id":"1.168175449","rc":[{"batb":[[0,3.8,69.23]],"ltp":0.0,"tv":0.0,"id":13117392},{"batb":[[1,2.1,53.68],[2,1.02,2]],"batl":[[0,2.6,235.5],[1,2.62,42.22]],"ltp":2.2,"tv":2.53,"id":13117391}]}]}
{"op":"mcm","clk":"1005856967","pt":1580591323969,"mc":[{"id":"1.168175449","rc":[{"batb":[[0,5.6,2.02],[1,5.5,2],[2,5.4,47.16]],"ltp":0.0,"tv":0.0,"id":13117449},{"batb":[[0,3.85,2.02],[1,3.8,69.23],[2,3.75,21.47]],"ltp":0.0,"tv":0.0,"id":13117392},{"batb":[[0,2.18,2.02],[1,2.16,2],[2,2.1,53.68]],"ltp":2.2,"tv":2.53,"id":13117391}]}]}
{"op":"mcm","clk":"1005868118","pt":1580591402562,"mc":[{"id":"1.168175449","rc":[{"trd":[[3.85,32.32]],"batb":[[0,3.8,69.23],[1,3.75,21.47],[2,1.02,2]],"batl":[[0,3.85,5.79]],"ltp":3.85,"tv":32.32,"id":13117392}],"tv":34.85}]}
{"op":"mcm","clk":"1005870639","pt":1580591420074,"mc":[{"id":"1.168175449","rc":[{"trd":[[3.8,11.58]],"batb":[[0,3.75,21.47],[1,1.02,2],[2,1.01,1.01]],"batl":[[0,9.4,278.89]],"ltp":3.8,"tv":43.9,"id":13117392}],"tv":46.43}]}
{"op":"mcm","clk":"1005873260","pt":1580591439093,"mc":[{"id":"1.168175449","rc":[{"batb":[[0,5.6,47.51],[1,5,14.76],[2,1.02,2]],"ltp":0.0,"tv":0.0,"id":13117449},{"batb":[[0,5.4,12],[1,4.5,16.87],[2,1.02,2]],"ltp":0.0,"tv":0.0,"id":13117448},{"batb":[[1,2.1,53.68],[2,1.02,2]],"ltp":2.2,"tv":2.53,"id":13117391}]}]}
{"op":"mcm","clk":"1005875037","pt":1580591452455,"mc":[{"id":"1.168175449","rc":[{"trd":[[2.18,4.04]],"batb":[[0,2.12,121.29]],"batl":[[0,2.18,16.13]],"ltp":2.18,"tv":6.57,"id":13117391}],"tv":50.47}]}
{"op":"mcm","clk":"1005876663","pt":1580591465373,"mc":[{"id":"1.168175449","rc":[{"trd":[[2.12,32.28]],"batb":[[0,2.12,105.15]],"batl":[[0,2.62,42.22],[1,2.62,0]],"ltp":2.12,"tv":38.85,"id":13117391}],"tv":82.75}]}
{"op":"mcm","clk":"1005876715","pt":1580591465701,"mc":[{"id":"1.168175449","rc":[{"batb":[[0,2.1,53.68],[1,1.02,2],[2,1.01,1.01]],"batl":[[0,2.6,235.31],[1,2.62,42.22]],"ltp":2.12,"tv":38.85,"id":13117391}]}]}
{"op":"mcm","clk":"1005877232","pt":1580591469484,"mc":[{"id":"1.168175449","rc":[{"batl":[[0,2.62,42.22],[1,2.62,0]],"ltp":2.12,"tv":38.85,"id":13117391}]}]}
{"op":"mcm","clk":"1005877323","pt":1580591470066,"mc":[{"id":"1.168175449","rc":[{"batl":[[0,70,3.72]],"ltp":0.0,"tv":0.0,"id":13117449},{"batb":[[0,2.12,121.79],[1,2.1,53.68],[2,1.02,2]],"batl":[[0,2.6,228.71],[1,2.62,42.22]],"ltp":2.12,"tv":38.85,"id":13117391}]}]}
{"op":"mcm","clk":"1005901927","pt":1580591646662,"mc":[{"id":"1.168175449","rc":[{"batl":[[0,70,34.37]],"ltp":0.0,"tv":0.0,"id":13117449}]}]}
{"op":"mcm","clk":"1005943754","pt":1580591943021,"mc":[{"id":"1.168175449","rc":[{"batb":[[0,5.5,2],[1,5.4,12],[2,4.5,16.87]],"ltp":0.0,"tv":0.0,"id":13117448},{"batb":[[0,2.14,2],[1,2.12,121.79],[2,2.1,53.68]],"ltp":2.12,"tv":38.85,"id":13117391}]}]}
{"op":"mcm","clk":"1005974938","pt":1580592172363,"mc":[{"id":"1.168175449","rc":[{"batb":[[0,2.14,122.82],[1,2.1,53.68],[2,1.02,2]],"ltp":2.12,"tv":38.85,"id":13117391}]}]}
{"op":"mcm","clk":"1005978930","pt":1580592202025,"mc":[{"id":"1.168175449","rc":[{"trd":[[2.14,5.06]],"batb":[[0,2.14,120.29]],"ltp":2.14,"tv":43.91,"id":13117391}],"tv":87.81}]}
{"op":"mcm","clk":"1006022982","pt":1580592542338,"mc":[{"id":"1.168175449","rc":[{"batb":[[0,5.4,12],[1,4.5,16.87],[2,1.02,2]],"ltp":0.0,"tv":0.0,"id":13117448}]}]}
{"op":"mcm","clk":"1006058663","pt":1580592827467,"mc":[{"id":"1.168175449","rc":[{"batl":[[0,7.8,29.55],[1,7.8,0]],"ltp":0.0,"tv":0.0,"id":13117448}]}]}
{"op":"mcm","clk":"1006058751","pt":1580592828198,"mc":[{"id":"1.168175449","rc":[{"batl":[[0,6.4,390.57],[1,7.8,29.55]],"ltp":0.0,"tv":0.0,"id":13117448}]}]}
{"op":"mcm","clk":"1006060623","pt":1580592842509,"mc":[{"id":"1.168175449","rc":[{"trd":[[2.14,106.41]],"batb":[[0,2.14,69.59]],"ltp":2.14,"tv":145.26,"id":13117391}],"tv":189.16}]}
{"op":"mcm","clk":"1006060657","pt":1580592842727,"mc":[{"id":"1.168175449","rc":[{"batb":[[0,2.1,53.68],[1,1.02,2],[2,1.01,1.01]],"ltp":2.14,"tv":145.26,"id":13117391}]}]}
{"op":"mcm","clk":"1006061106","pt":1580592846548,"mc":[{"id":"1.168175449","rc":[{"batb":[[0,3.8,67.33],[1,3.75,21.47],[2,1.02,2]],"batl":[[0,9.4,27.34]],"ltp":3.8,"tv":43.9,"id":13117392},{"batb":[[0,2.1,177.02]],"batl":[[0,2.6,98.31]],"ltp":2.14,"tv":145.26,"id":13117391}]}]}
{"op":"mcm","clk":"1006070662","pt":1580592919786,"mc":[{"id":"1.168175449","rc":[{"batl":[[0,9.4,277.58]],"ltp":3.8,"tv":43.9,"id":13117392}]}]}
{"op":"mcm","clk":"1006076620","pt":1580592965493,"mc":[{"id":"1.168175449","rc":[{"batl":[[0,2.62,42.22],[1,2.62,0]],"ltp":2.14,"tv":145.26,"id":13117391}]}]}
{"op":"mcm","clk":"1006076635","pt":1580592965600,"mc":[{"id":"1.168175449","rc":[{"batl":[[0,2.6,216.51],[1,2.62,42.22]],"ltp":2.14,"tv":145.26,"id":13117391}]}]}
{"op":"mcm","clk":"1006102997","pt":1580593191183,"mc":[{"id":"1.168175449","rc":[{"batb":[[0,6,18],[1,5.6,47.51],[2,5,14.76]],"ltp":0.0,"tv":0.0,"id":13117449},{"batb":[[1,4.5,42.58]],"ltp":0.0,"tv":0.0,"id":13117448},{"batb":[[0,4,30],[1,3.8,67.33],[2,3.75,21.47]],"ltp":3.8,"tv":43.9,"id":13117392},{"batb":[[0,2.1,258.84]],"ltp":2.14,"tv":145.26,"id":13117391}]}]}
{"op":"mcm","clk":"1006116007","pt":1580593299751,"mc":[{"id":"1.168175449","rc":[{"trd":[[2.1,469.4]],"batb":[[0,2.1,24.02]],"ltp":2.1,"tv":614.66,"id":13117391}],"tv":658.56}]}
{"op":"mcm","clk":"1006116496","pt":1580593303530,"mc":[{"id":"1.168175449","rc":[{"batb":[[1,1.96,61.51],[2,1.02,2]],"ltp":2.1,"tv":614.66,"id":13117391}]}]}
{"op":"mcm","clk":"1006116584","pt":1580593304317,"mc":[{"id":"1.168175449","rc":[{"batb":[[1,5.6,2.02]],"batl":[[0,70,3.72]],"ltp":0.0,"tv":0.0,"id":13117449},{"batl":[[0,6.4,40.29]],"ltp":0.0,"tv":0.0,"id":13117448},{"batb":[[1,3.75,21.47],[2,1.02,2]],"batl":[[0,9.4,27.34]],"ltp":3.8,"tv":43.9,"id":13117392},{"batl":[[0,2.6,98.68]],"ltp":2.1,"tv":614.66,"id":13117391}]}]}
{"op":"mcm","clk":"1006125346","pt":1580593372302,"mc":[{"id":"1.168175449","rc":[{"batl":[[0,2.6,193.76]],"ltp":2.1,"tv":614.66,"id":13117391}]}]}
{"op":"mcm","clk":"1006132126","pt":1580593425855,"mc":[{"id":"1.168175449","rc":[{"batl":[[0,6.4,386.34]],"ltp":0.0,"tv":0.0,"id":13117448}]}]}
{"op":"mcm","clk":"1006134729","pt":1580593446054,"mc":[{"id":"1.168175449","rc":[{"batl":[[0,70,34.23]],"ltp":0.0,"tv":0.0,"id":13117449}]}]}
{"op":"mcm","clk":"1006144277","pt":1580593519783,"mc":[{"id":"1.168175449","rc":[{"batl":[[0,9.4,275.94]],"ltp":3.8,"tv":43.9,"id":13117392}]}]}
{"op":"mcm","clk":"1006154537","pt":1580593603453,"mc":[{"id":"1.168175449","rc":[{"batl":[[0,2.6,98.46]],"ltp":2.1,"tv":614.66,"id":13117391}]}]}
{"op":"mcm","clk":"1006162425","pt":1580593672365,"mc":[{"id":"1.168175449","rc":[{"batl":[[0,2.6,188.26]],"ltp":2.1,"tv":614.66,"id":13117391}]}]}
{"op":"mcm","clk":"1006170477","pt":1580593745425,"mc":[{"id":"1.168175449","rc":[{"batl":[[0,65,36.87]],"ltp":0.0,"tv":0.0,"id":13117449}]}]}
{"op":"mcm","clk":"1006175439","pt":1580593793484,"mc":[{"id":"1.168175449","rc":[{"batl":[[0,65,36.72]],"ltp":0.0,"tv":0.0,"id":13117449}]}]}
{"op":"mcm","clk":"1006177017","pt":1580593808660,"mc":[{"id":"1.168175449","rc":[{"batl":[[0,65,36.87]],"ltp":0.0,"tv":0.0,"id":13117449}]}]}
{"op":"mcm","clk":"1006183795","pt":1580593877093,"mc":[{"id":"1.168175449","rc":[{"batl":[[0,2.6,98.68]],"ltp":2.1,"tv":614.66,"id":13117391}]}]}
{"op":"mcm","clk":"1006186670","pt":1580593905071,"mc":[{"id":"1.168175449","rc":[{"batb":[[0,6.2,4],[1,6,18],[2,5.6,2.02]],"ltp":0.0,"tv":0.0,"id":13117449},{"batb":[[1,5,5],[2,4.5,42.58]],"ltp":0.0,"tv":0.0,"id":13117448},{"batb":[[0,4.1,5],[1,4,30],[2,3.75,21.47]],"ltp":3.8,"tv":43.9,"id":13117392},{"batb":[[0,2.12,7],[1,2.1,24.02],[2,1.96,61.51]],"ltp":2.1,"tv":614.66,"id":13117391}]}]}
{"op":"mcm","clk":"1006192710","pt":1580593965843,"mc":[{"id":"1.168175449","rc":[{"batl":[[0,60,6],[1,65,36.87]],"ltp":0.0,"tv":0.0,"id":13117449},{"batl":[[0,6.2,4],[1,6.4,386.34],[2,7.8,29.55]],"ltp":0.0,"tv":0.0,"id":13117448},{"batl":[[0,9.2,6],[1,9.4,275.94]],"ltp":3.8,"tv":43.9,"id":13117392},{"batl":[[0,2.58,6],[1,2.6,98.68],[2,2.62,42.22]],"ltp":2.1,"tv":614.66,"id":13117391}]}]}
{"op":"mcm","clk":"1006193353","pt":1580593972371,"mc":[{"id":"1.168175449","rc":[{"trd":[[4.1,10]],"batb":[[0,4,30],[1,3.75,21.47],[2,1.02,2]],"batl":[[0,4.1,10.15],[1,9.2,6],[2,9.4,275.94]],"ltp":4.1,"tv":53.9,"id":13117392},{"batl":[[1,2.6,188.26]],"ltp":2.1,"tv":614.66,"id":13117391}],"tv":668.56}]}
{"op":"mcm","clk":"1006194258","pt":1580593982450,"mc":[{"id":"1.168175449","rc":[{"batl":[[1,65,4]],"ltp":0.0,"tv":0.0,"id":13117449}]}]}
{"op":"mcm","clk":"1006194300","pt":1580593982871,"mc":[{"id":"1.168175449","rc":[{"batl":[[1,65,36.72]],"ltp":0.0,"tv":0.0,"id":13117449}]}]}
{"op":"mcm","clk":"1006197898","pt":1580594026463,"mc":[{"id":"1.168175449","rc":[{"batl":[[1,4.9,6]],"ltp":4.1,"tv":53.9,"id":13117392}]}]}
{"op":"mcm","clk":"1006200231","pt":1580594051344,"mc":[{"id":"1.168175449","rc":[{"batl":[[0,40,59.66],[1,60,6]],"ltp":0.0,"tv":0.0,"id":13117449}]}]}
{"op":"mcm","clk":"1006202140","pt":1580594073305,"mc":[{"id":"1.168175449","rc":[{"batl":[[0,2.56,100.17],[1,2.58,6]],"ltp":2.1,"tv":614.66,"id":13117391}]}]}
{"op":"mcm","clk":"1006207036","pt":1580594134955,"mc":[{"id":"1.168175449","rc":[{"trd":[[4,20.3]],"batb":[[0,4,19.85]],"batl":[[0,4.9,6],[1,4.9,0],[2,9.4,0]],"ltp":4.0,"tv":74.19,"id":13117392}],"tv":688.86}]}
{"op":"mcm","clk":"1006209505","pt":1580594165753,"mc":[{"id":"1.168175449","rc":[{"batl":[[0,2.56,185.67]],"ltp":2.1,"tv":614.66,"id":13117391}]}]}
{"op":"mcm","clk":"1006216763","pt":1580594247000,"mc":[{"id":"1.168175449","rc":[{"batl":[[0,60,6],[1,60,0]],"ltp":0.0,"tv":0.0,"id":13117449},{"batl":[[1,7.8,29.55],[2,7.8,0]],"ltp":0.0,"tv":0.0,"id":13117448},{"batl":[[0,2.58,6],[1,2.62,42.22],[2,2.62,0]],"ltp":2.1,"tv":614.66,"id":13117391}]}]}
{"op":"mcm","clk":"1006224305","pt":1580594339180,"mc":[{"id":"1.168175449","rc":[{"batb":[[1,6,52.38]],"batl":[[0,7.4,32.26],[1,60,6]],"ltp":0.0,"tv":0.0,"id":13117449},{"batb":[[1,5,32.3]],"batl":[[0,5.8,26.2],[1,6.2,4],[2,7.8,29.55]],"ltp":0.0,"tv":0.0,"id":13117448},{"batb":[[0,4.3,38.24],[1,4,19.85],[2,3.75,21.47]],"batl":[[1,5,36.43]],"ltp":4.0,"tv":74.19,"id":13117392},{"batb":[[0,2.14,46.97],[1,2.12,7],[2,2.1,24.02]],"batl":[[0,2.3,45.79],[1,2.58,6],[2,2.62,42.22]],"ltp":2.1,"tv":614.66,"id":13117391}]}]}
{"op":"mcm","clk":"1006225347","pt":1580594349428,"mc":[{"id":"1.168175449","rc":[{"batb":[[2,5.7,31.91]],"ltp":0.0,"tv":0.0,"id":13117449},{"batb":[[1,5,69.8]],"ltp":0.0,"tv":0.0,"id":13117448},{"batb":[[1,4,69.85]],"ltp":4.0,"tv":74.19,"id":13117392}]}]}
{"op":"mcm","clk":"1006229046","pt":1580594389380,"mc":[{"id":"1.168175449","rc":[{"batb":[[0,6,52.38],[1,5.7,31.91],[2,5.6,2.02]],"ltp":0.0,"tv":0.0,"id":13117449},{"batb":[[1,5,64.8]],"ltp":0.0,"tv":0.0,"id":13117448},{"batb":[[1,2.1,24.02],[2,2.08,138.89]],"ltp":2.1,"tv":614.66,"id":13117391}]}]}
{"op":"mcm","clk":"1006229098","pt":1580594389882,"mc":[{"id":"1.168175449","rc":[{"batb":[[0,6.2,4],[1,6,52.38],[2,5.7,31.91]],"ltp":0.0,"tv":0.0,"id":13117449},{"batb":[[1,5,69.8]],"ltp":0.0,"tv":0.0,"id":13117448},{"batb":[[0,4.4,5],[1,4.3,38.24],[2,4,69.85]],"ltp":4.0,"tv":74.19,"id":13117392},{"batb":[[1,2.12,7],[2,2.1,24.02]],"ltp":2.1,"tv":614.66,"id":13117391}]}]}
{"op":"mcm","clk":"1006229323","pt":1580594392174,"mc":[{"id":"1.168175449","rc":[{"batb":[[1,6,60.79]],"batl":[[0,7.4,38.14]],"ltp":0.0,"tv":0.0,"id":13117449},{"batb":[[1,5.1,10.08],[2,5,69.8]],"batl":[[1,6.2,11.56]],"ltp":0.0,"tv":0.0,"id":13117448},{"batb":[[2,4.1,13.44]],"batl":[[0,4.9,16.08]],"ltp":4.0,"tv":74.19,"id":13117392},{"batb":[[1,2.12,43.97]],"batl":[[1,2.36,30.25],[2,2.58,6]],"ltp":2.1,"tv":614.66,"id":13117391}]}]}
{"op":"mcm","clk":"1006234267","pt":1580594438937,"mc":[{"id":"1.168175449","rc":[{"trd":[[4.4,10]],"batb":[[0,4.3,38.24],[1,4.1,13.44],[2,4,69.85]],"batl":[[0,4.4,44.22],[1,4.9,16.08],[2,5,36.43]],"ltp":4.4,"tv":84.19,"id":13117392}],"tv":698.86}]}
{"op":"mcm","clk":"1006236588","pt":1580594462100,"mc":[{"id":"1.168175449","rc":[{"batl":[[2,7.8,0]],"ltp":0.0,"tv":0.0,"id":13117448},{"batl":[[0,4.9,16.08],[1,5,36.43],[2,5,0]],"ltp":4.4,"tv":84.19,"id":13117392}]}]}
{"op":"mcm","clk":"1006240082","pt":1580594495752,"mc":[{"id":"1.168175449","rc":[{"batb":[[2,5,69.41]],"batl":[[0,5.8,25.81]],"ltp":0.0,"tv":0.0,"id":13117448},{"batb":[[0,4.3,38.08]],"batl":[[1,5,36.27]],"ltp":4.4,"tv":84.19,"id":13117392}]}]}
{"op":"mcm","clk":"1006240704","pt":1580594501387,"mc":[{"id":"1.168175449","marketDefinition":{"bspMarket":false,"turnInPlayEnabled":true,"persistenceEnabled":true,"marketBaseRate":5.0,"eventId":"29680072","eventTypeId":"2","numberOfWinners":1,"bettingType":"ODDS","marketType":"SET_BETTING","marketTime":"2020-02-01T21:57:00.000Z","suspendTime":"2020-02-01T21:57:00.000Z","bspReconciled":false,"complete":true,"inPlay":false,"crossMatching":true,"runnersVoidable":false,"numberOfActiveRunners":4,"betDelay":0,"status":"OPEN","runners":[{"status":"ACTIVE","sortPriority":1,"id":13117391,"name":"Cecchinato 2-0"},{"status":"ACTIVE","sortPriority":2,"id":13117392,"name":"Cecchinato 2-1"},{"status":"ACTIVE","sortPriority":3,"id":13117448,"name":"Martin 2-0"},{"status":"ACTIVE","sortPriority":4,"id":13117449,"name":"Martin 2-1"}],"regulators":["MR_INT"],"countryCode":"UY","discountAllowed":true,"timezone":"UTC","openDate":"2020-02-01T22:00:00.000Z","version":3147667734,"name":"Set Betting","eventName":"Cecchinato v Martin"}}]}
{"op":"mcm","clk":"1006240857","pt":1580594502939,"mc":[{"id":"1.168175449","marketDefinition":{"bspMarket":false,"turnInPlayEnabled":true,"persistenceEnabled":true,"marketBaseRate":5.0,"eventId":"29680072","eventTypeId":"2","numberOfWinners":1,"bettingType":"ODDS","marketType":"SET_BETTING","marketTime":"2020-02-01T21:57:00.000Z","suspendTime":"2020-02-01T21:57:00.000Z","bspReconciled":false,"complete":true,"inPlay":false,"crossMatching":true,"runnersVoidable":false,"numberOfActiveRunners":4,"betDelay":0,"status":"OPEN","runners":[{"status":"ACTIVE","sortPriority":1,"id":13117391,"name":"Cecchinato 2-0"},{"status":"ACTIVE","sortPriority":2,"id":13117392,"name":"Cecchinato 2-1"},{"status":"ACTIVE","sortPriority":3,"id":13117448,"name":"Martin 2-0"},{"status":"ACTIVE","sortPriority":4,"id":13117449,"name":"Martin 2-1"}],"regulators":["MR_INT"],"countryCode":"UY","discountAllowed":true,"timezone":"UTC","openDate":"2020-02-01T21:57:00.000Z","version":3147667734,"name":"Set Betting","eventName":"Cecchinato v Martin"}}]}
{"op":"mcm","clk":"1006244340","pt":1580594536896,"mc":[{"id":"1.168175449","rc":[{"batb":[[0,6.2,38.15],[1,6,26.4]],"batl":[[0,7.4,37.9]],"ltp":0.0,"tv":0.0,"id":13117449}]}]}
{"op":"mcm","clk":"1006245520","pt":1580594547532,"mc":[{"id":"1.168175449","rc":[{"batb":[[1,2.12,7]],"ltp":2.1,"tv":614.66,"id":13117391}]}]}
{"op":"mcm","clk":"1006247901","pt":1580594569540,"mc":[{"id":"1.168175449","rc":[{"trd":[[2.1,517.44],[2.12,46.27],[2.14,200.35]],"batb":[[0,2.08,138.89],[1,1.96,61.51],[2,1.02,2]],"ltp":2.1,"tv":770.64,"id":13117391}],"tv":854.84}]}
{"op":"mcm","clk":"1006247995","pt":1580594570470,"mc":[{"id":"1.168175449","rc":[{"batb":[[0,6.2,37.52]],"batl":[[0,7.4,37.28]],"ltp":0.0,"tv":0.0,"id":13117449},{"batb":[[1,5.1,36.6],[2,5,42.5]],"batl":[[0,5.9,25.41]],"ltp":0.0,"tv":0.0,"id":13117448},{"batb":[[0,4.4,37.77]],"batl":[[1,5,35.96]],"ltp":4.4,"tv":84.19,"id":13117392},{"trd":[[2.12,143.52]],"batb":[[0,2.12,48.62],[1,2.08,138.89],[2,1.96,61.51]],"batl":[[0,2.28,47.37]],"ltp":2.12,"tv":867.89,"id":13117391}],"tv":952.08}]}
{"op":"mcm","clk":"1006248547","pt":1580594575660,"mc":[{"id":"1.168175449","rc":[{"batb":[[1,2.1,37.81],[2,2.08,138.89]],"ltp":2.12,"tv":867.89,"id":13117391}]}]}
{"op":"mcm","clk":"1006249033","pt":1580594580554,"mc":[{"id":"1.168175449","rc":[{"batb":[[0,6.4,32.97],[1,6.2,4],[2,6,26.4]],"batl":[[0,7.4,36.8]],"ltp":0.0,"tv":0.0,"id":13117449},{"batb":[[1,5.2,26.04],[2,5.1,10.08]],"batl":[[0,5.9,25.02]],"ltp":0.0,"tv":0.0,"id":13117448},{"batb":[[0,4.5,37.14]],"batl":[[1,5,35.33]],"ltp":4.4,"tv":84.19,"id":13117392},{"batb":[[1,2.1,87.69]],"batl":[[0,2.2,48.63]],"ltp":2.12,"tv":867.89,"id":13117391}]}]}
{"op":"mcm","clk":"1006255755","pt":1580594648241,"mc":[{"id":"1.168175449","rc":[{"trd":[[2.2,24.54]],"batl":[[0,2.2,37.62]],"ltp":2.2,"tv":889.89,"id":13117391}],"tv":974.08}]}
{"op":"mcm","clk":"1006255839","pt":1580594649361,"mc":[{"id":"1.168175449","rc":[{"batb":[[1,2.1,87.38]],"batl":[[0,2.22,48.31]],"ltp":2.2,"tv":889.89,"id":13117391}]}]}
{"op":"mcm","clk":"1006257062","pt":1580594662560,"mc":[{"id":"1.168175449","rc":[{"trd":[[5.9,4]],"batl":[[0,5.9,23.02]],"ltp":5.9,"tv":4.0,"id":13117448}],"tv":978.08}]}
{"op":"mcm","clk":"1006257136","pt":1580594663331,"mc":[{"id":"1.168175449","rc":[{"batb":[[0,6.2,37.13],[1,6,26.4],[2,5.7,31.91]],"ltp":0.0,"tv":0.0,"id":13117449}]}]}
{"op":"mcm","clk":"1006259737","pt":1580594688453,"mc":[{"id":"1.168175449","marketDefinition":{"bspMarket":false,"turnInPlayEnabled":true,"persistenceEnabled":true,"marketBaseRate":5.0,"eventId":"29680072","eventTypeId":"2","numberOfWinners":1,"bettingType":"ODDS","marketType":"SET_BETTING","marketTime":"2020-02-01T21:57:00.000Z","suspendTime":"2020-02-01T21:57:00.000Z","bspReconciled":false,"complete":true,"inPlay":false,"crossMatching":true,"runnersVoidable":false,"numberOfActiveRunners":4,"betDelay":0,"status":"OPEN","runners":[{"status":"ACTIVE","sortPriority":1,"id":13117391,"name":"Cecchinato 2-0"},{"status":"ACTIVE","sortPriority":2,"id":13117392,"name":"Cecchinato 2-1"},{"status":"ACTIVE","sortPriority":3,"id":13117448,"name":"Martin 2-0"},{"status":"ACTIVE","sortPriority":4,"id":13117449,"name":"Martin 2-1"}],"regulators":["MR_INT"],"countryCode":"UY","discountAllowed":true,"timezone":"UTC","openDate":"2020-02-01T21:57:00.000Z","version":3147667734,"name":"Set Betting","eventName":"Cecchinato v Martin"},"rc":[{"batb":[[0,6.2,4],[1,6,18]],"batl":[[0,60,6],[1,60,0]],"ltp":0.0,"tv":0.0,"id":13117449},{"batb":[[1,5,42.5],[2,4.5,42.58]],"batl":[[0,6.2,4],[1,6.2,0]],"ltp":5.9,"tv":4.0,"id":13117448},{"batb":[[0,4,69.85],[1,3.75,21.47],[2,1.02,2]],"batl":[[0,4.9,6],[1,5,0]],"ltp":4.4,"tv":84.19,"id":13117392},{"batb":[[1,2.08,138.89],[2,1.96,61.51]],"batl":[[0,2.58,6],[1,2.36,0],[2,2.58,0]],"ltp":2.2,"tv":889.89,"id":13117391}]}]}
{"op":"mcm","clk":"1006259796","pt":1580594689138,"mc":[{"id":"1.168175449","marketDefinition":{"bspMarket":false,"turnInPlayEnabled":true,"persistenceEnabled":true,"marketBaseRate":5.0,"eventId":"29680072","eventTypeId":"2","numberOfWinners":1,"bettingType":"ODDS","marketType":"SET_BETTING","marketTime":"2020-02-01T21:57:00.000Z","suspendTime":"2020-02-01T21:57:00.000Z","bspReconciled":false,"complete":true,"inPlay":true,"crossMatching":true,"runnersVoidable":false,"numberOfActiveRunners":4,"betDelay":3,"status":"OPEN","runners":[{"status":"ACTIVE","sortPriority":1,"id":13117391,"name":"Cecchinato 2-0"},{"status":"ACTIVE","sortPriority":2,"id":13117392,"name":"Cecchinato 2-1"},{"status":"ACTIVE","sortPriority":3,"id":13117448,"name":"Martin 2-0"},{"status":"ACTIVE","sortPriority":4,"id":13117449,"name":"Martin 2-1"}],"regulators":["MR_INT"],"countryCode":"UY","discountAllowed":true,"timezone":"UTC","openDate":"2020-02-01T21:57:00.000Z","version":3147676934,"name":"Set Betting","eventName":"Cecchinato v Martin"},"rc":[{"batb":[[0,1.01,0.51],[1,6,0],[2,5.7,0]],"ltp":0.0,"tv":0.0,"id":13117449},{"batb":[[0,1.01,0.51],[1,5,0],[2,4.5,0]],"ltp":5.9,"tv":4.0,"id":13117448},{"batb":[[0,1.01,0.51],[1,3.75,0],[2,1.02,0]],"ltp":4.4,"tv":84.19,"id":13117392},{"batb":[[1,1.01,0.51],[2,1.96,0]],"ltp":2.2,"tv":889.89,"id":13117391}]}]}
{"op":"mcm","clk":"1006261163","pt":1580594703448,"mc":[{"id":"1.168175449","rc":[{"batb":[[0,6,8.4],[1,1.01,0.51]],"batl":[[0,7.6,5.88]],"ltp":0.0,"tv":0.0,"id":13117449},{"batb":[[0,5.5,9.24],[1,1.01,0.51]],"batl":[[0,6.8,6.72]],"ltp":5.9,"tv":4.0,"id":13117448},{"batb":[[0,4.2,12.6],[1,1.01,0.51]],"batl":[[0,5,10.08]],"ltp":4.4,"tv":84.19,"id":13117392},{"batb":[[1,2.02,41.17],[2,1.01,0.51]],"batl":[[0,2.24,33.61]],"ltp":2.2,"tv":889.89,"id":13117391}]}]}
{"op":"mcm","clk":"1006261233","pt":1580594704124,"mc":[{"id":"1.168175449","rc":[{"batb":[[0,6.4,32.1],[1,6.2,33.68],[2,6,8.4]],"batl":[[0,7.6,34.84]],"ltp":0.0,"tv":0.0,"id":13117449},{"batb":[[0,5.7,21.24],[1,5.5,9.24],[2,5.1,28.01]],"batl":[[0,6.6,39.5],[1,6.8,6.72],[2,7.2,32.57]],"ltp":5.9,"tv":4.0,"id":13117448},{"batb":[[0,4.6,34.93],[1,4.5,37.45],[2,4.2,12.6]],"batl":[[1,5.2,33.36],[2,5.3,31.47]],"ltp":4.4,"tv":84.19,"id":13117392},{"trd":[[2.12,240.77]],"batb":[[0,2.02,41.17],[1,2,58.07],[2,1.92,32.97]],"batl":[[0,2.1,7.79],[1,2.24,79.72]],"ltp":2.12,"tv":987.14,"id":13117391}],"tv":1075.33}]}
{"op":"mcm","clk":"1006262673","pt":1580594717441,"mc":[{"id":"1.168175449","rc":[{"batb":[[0,6.2,33.68],[1,6,8.4],[2,1.01,0.51]],"ltp":0.0,"tv":0.0,"id":13117449},{"batb":[[0,5.5,9.24],[1,5.1,28.01],[2,1.01,0.51]],"batl":[[0,6.8,6.72],[1,7.2,32.57],[2,7.2,0]],"ltp":5.9,"tv":4.0,"id":13117448},{"batb":[[0,4.5,37.45],[1,4.2,12.6],[2,1.01,0.51]],"batl":[[1,5.3,31.47],[2,5.3,0]],"ltp":4.4,"tv":84.19,"id":13117392},{"batb":[[1,1.92,32.97],[2,1.01,0.51]],"batl":[[0,2.24,79.72],[1,2.24,0]],"ltp":2.12,"tv":987.14,"id":13117391}]}]}
{"op":"mcm","clk":"1006262784","pt":1580594718328,"mc":[{"id":"1.168175449","rc":[{"batb":[[1,1.01,0.51],[2,1.01,0]],"batl":[[0,7.6,28.95]],"ltp":0.0,"tv":0.0,"id":13117449},{"batb":[[0,5.1,28.01],[1,1.01,0.51],[2,1.01,0]],"batl":[[0,7.2,32.57],[1,7.2,0]],"ltp":5.9,"tv":4.0,"id":13117448},{"batb":[[1,1.01,0.51],[2,1.01,0]],"batl":[[0,5.3,31.47],[1,5.3,0]],"ltp":4.4,"tv":84.19,"id":13117392},{"batb":[[0,1.92,32.97],[1,1.01,0.51],[2,1.01,0]],"batl":[[0,2.24,46.11]],"ltp":2.12,"tv":987.14,"id":13117391}]}]}
{"op":"mcm","clk":"1006263039","pt":1580594720465,"mc":[{"id":"1.168175449","rc":[{"batb":[[1,5,28.48],[2,1.01,0.51]],"ltp":5.9,"tv":4.0,"id":13117448},{"batb":[[1,4.4,38.08],[2,1.01,0.51]],"ltp":4.4,"tv":84.19,"id":13117392},{"batb":[[0,1.94,32.18],[1,1.92,32.97],[2,1.01,0.51]],"batl":[[1,2.28,45.01]],"ltp":2.12,"tv":987.14,"id":13117391}]}]}
{"op":"mcm","clk":"1006263049","pt":1580594720572,"mc":[{"id":"1.168175449","rc":[{"batb":[[0,5,28.48],[1,1.01,0.51],[2,1.01,0]],"ltp":5.9,"tv":4.0,"id":13117448},{"batb":[[0,4.4,38.08],[1,1.01,0.51],[2,1.01,0]],"ltp":4.4,"tv":84.19,"id":13117392},{"batb":[[1,1.01,0.51],[2,1.01,0]],"batl":[[0,2.28,45.01],[1,2.28,0]],"ltp":2.12,"tv":987.14,"id":13117391}]}]}
{"op":"mcm","clk":"1006265382","pt":1580594741179,"mc":[{"id":"1.168175449","rc":[{"batb":[[0,6.4,32.02],[1,6.2,112.55],[2,1.01,0.51]],"ltp":0.0,"tv":0.0,"id":13117449},{"batb":[[0,5.1,76.77],[1,5,92.46],[2,1.01,0.51]],"ltp":5.9,"tv":4.0,"id":13117448},{"batb":[[1,4.1,148.67],[2,4,105.74]],"ltp":4.4,"tv":84.19,"id":13117392},{"batb":[[0,2.04,120.78],[1,2.02,129.61],[2,1.94,32.18]],"ltp":2.12,"tv":987.14,"id":13117391}]}]}
{"op":"mcm","clk":"1006265912","pt":1580594745909,"mc":[{"id":"1.168175449","rc":[{"batb":[[0,1.94,32.18],[1,1.01,0.51],[2,1.94,0]],"ltp":2.12,"tv":987.14,"id":13117391}]}]}
{"op":"mcm","clk":"1006266321","pt":1580594749482,"mc":[{"id":"1.168175449","rc":[{"batb":[[2,6,35.72]],"batl":[[0,7.4,37.2],[1,7.6,28.95]],"ltp":0.0,"tv":0.0,"id":13117449},{"batb":[[1,5,102.55],[2,4.3,39.81]],"batl":[[0,5.6,27.3],[1,6.4,21.32],[2,7.2,32.57]],"ltp":5.9,"tv":4.0,"id":13117448},{"batb":[[1,4.2,43.04],[2,4.1,162.11]],"batl":[[0,4.9,10.08],[1,5,36.27],[2,5.1,34.07]],"ltp":4.4,"tv":84.19,"id":13117392},{"batb":[[0,2.26,99.88],[1,2.24,95.77],[2,2.16,46.11]],"batl":[[1,2.38,30.25],[2,2.52,33.83]],"ltp":2.12,"tv":987.14,"id":13117391}]}]}
{"op":"mcm","clk":"1006266420","pt":1580594750516,"mc":[{"id":"1.168175449","rc":[{"batb":[[1,6.2,78.87]],"batl":[[1,7.6,0]],"ltp":0.0,"tv":0.0,"id":13117449},{"batl":[[1,6.2,7.56],[2,6.4,21.32]],"ltp":5.9,"tv":4.0,"id":13117448}]}]}
{"op":"mcm","clk":"1006266591","pt":1580594752129,"mc":[{"id":"1.168175449","rc":[{"batb":[[0,6.4,50.82]],"ltp":0.0,"tv":0.0,"id":13117449},{"batb":[[0,5.1,101.42]],"ltp":5.9,"tv":4.0,"id":13117448}]}]}
{"op":"mcm","clk":"1006268195","pt":1580594766632,"mc":[{"id":"1.168175449","rc":[{"batb":[[0,5.1,62.13],[1,5,38.57]],"ltp":5.9,"tv":4.0,"id":13117448}]}]}
{"op":"mcm","clk":"1006268689","pt":1580594770540,"mc":[{"id":"1.168175449","rc":[{"batb":[[0,5.2,39.12],[1,5.1,62.13],[2,5,38.57]],"ltp":5.9,"tv":4.0,"id":13117448}]}]}
{"op":"mcm","clk":"1006269043","pt":1580594773534,"mc":[{"id":"1.168175449","rc":[{"batb":[[2,4.1,142.9]],"ltp":4.4,"tv":84.19,"id":13117392}]}]}
{"op":"mcm","clk":"1006269168","pt":1580594774412,"mc":[{"id":"1.168175449","rc":[{"batb":[[0,6.2,67.35],[1,6,35.72],[2,1.01,0.51]],"batl":[[0,7.4,31.32]],"ltp":0.0,"tv":0.0,"id":13117449},{"batb":[[0,4.3,39.81],[1,1.01,0.51],[2,5,0]],"batl":[[0,6.4,21.32],[1,6.2,0],[2,6.4,0]],"ltp":5.9,"tv":4.0,"id":13117448},{"batb":[[0,4.2,43.04],[1,4,68.36],[2,1.01,0.51]],"batl":[[0,5.1,34.07],[1,5,0],[2,5.1,0]],"ltp":4.4,"tv":84.19,"id":13117392},{"batb":[[0,2.04,55],[1,1.01,0.51],[2,2.16,0]],"batl":[[0,2.52,33.83],[1,2.38,0],[2,2.52,0]],"ltp":2.12,"tv":987.14,"id":13117391}]}]}
{"op":"mcm","clk":"1006269604","pt":1580594778007,"mc":[{"id":"1.168175449","rc":[{"batb":[[1,6,120.13]],"ltp":0.0,"tv":0.0,"id":13117449},{"batb":[[0,4.4,103.96],[1,4.3,130.37],[2,1.01,0.51]],"ltp":5.9,"tv":4.0,"id":13117448},{"batb":[[2,3.95,55.72]],"ltp":4.4,"tv":84.19,"id":13117392},{"batb":[[0,2.12,152.47],[1,2.1,115.31],[2,2.04,55]],"ltp":2.12,"tv":987.14,"id":13117391}]}]}
{"op":"mcm","clk":"1006270127","pt":1580594782544,"mc":[{"id":"1.168175449","rc":[{"batb":[[1,6,35.72]],"ltp":0.0,"tv":0.0,"id":13117449},{"batb":[[0,4.3,39.81],[1,1.01,0.51],[2,1.01,0]],"ltp":5.9,"tv":4.0,"id":13117448},{"batb":[[1,1.01,0.51],[2,3.95,0]],"ltp":4.4,"tv":84.19,"id":13117392}]}]}
{"op":"mcm","clk":"1006270533","pt":1580594785568,"mc":[{"id":"1.168175449","rc":[{"batb":[[0,6.4,94.49],[1,6.2,101.97],[2,6,8.4]],"batl":[[1,7.6,36.02]],"ltp":0.0,"tv":0.0,"id":13117449},{"batb":[[0,5.7,77.71],[1,5.6,72.01],[2,5.4,9.24]],"batl":[[1,6.8,6.72],[2,7.2,33.13]],"ltp":5.9,"tv":4.0,"id":13117448},{"batb":[[0,4.5,35.72],[1,4.3,39.34],[2,4.2,141.18]],"batl":[[0,5,10.08],[1,5.1,34.07],[2,5.2,32.18]],"ltp":4.4,"tv":84.19,"id":13117392},{"batl":[[0,2.16,53.5],[1,2.26,32.77],[2,2.32,42.8]],"ltp":2.12,"tv":987.14,"id":13117391}]}]}
{"op":"mcm","clk":"1006271724","pt":1580594795462,"mc":[{"id":"1.168175449","rc":[{"batb":[[0,6.4,35.17]],"batl":[[0,7.6,36.02],[1,7.6,0]],"ltp":0.0,"tv":0.0,"id":13117449},{"batb":[[0,5.4,9.24],[1,4.9,29.9],[2,1.01,0.51]],"batl":[[0,6.8,6.72],[1,7.2,33.13],[2,7.2,0]],"ltp":5.9,"tv":4.0,"id":13117448},{"batb":[[0,4.3,39.34],[1,4.2,12.6],[2,4.1,99.76]],"batl":[[1,5.2,32.18],[2,5.2,0]],"ltp":4.4,"tv":84.19,"id":13117392},{"batb":[[0,2.02,41.17],[1,1.94,32.02],[2,1.01,0.51]],"batl":[[0,2.26,32.77],[1,2.32,42.8],[2,2.32,0]],"ltp":2.12,"tv":987.14,"id":13117391}]}]}
{"op":"mcm","clk":"1006271854","pt":1580594796441,"mc":[{"id":"1.168175449","rc":[{"batb":[[2,1.01,0.51]],"batl":[[0,7.6,30.14]],"ltp":0.0,"tv":0.0,"id":13117449},{"batb":[[0,4.9,29.9],[1,1.01,0.51],[2,1.01,0]],"batl":[[0,7.2,33.13],[1,7.2,0]],"ltp":5.9,"tv":4.0,"id":13117448},{"batb":[[1,4.1,99.76],[2,1.01,0.51]],"batl":[[0,5.2,32.18],[1,5.2,0]],"ltp":4.4,"tv":84.19,"id":13117392},{"batb":[[0,1.94,32.02],[1,1.01,0.51],[2,1.01,0]],"batl":[[0,2.32,42.8],[1,2.32,0]],"ltp":2.12,"tv":987.14,"id":13117391}]}]}
{"op":"mcm","clk":"1006272096","pt":1580594798477,"mc":[{"id":"1.168175449","rc":[{"batb":[[1,6.2,114.02]],"ltp":0.0,"tv":0.0,"id":13117449},{"batb":[[0,5,73.93],[1,4.9,97.41],[2,1.01,0.51]],"ltp":5.9,"tv":4.0,"id":13117448},{"batb":[[2,4,106.27]],"ltp":4.4,"tv":84.19,"id":13117392},{"batb":[[0,2.02,216.88],[1,2,133.4],[2,1.94,32.02]],"ltp":2.12,"tv":987.14,"id":13117391}]}]}
{"op":"mcm","clk":"1006272697","pt":1580594803500,"mc":[{"id":"1.168175449","rc":[{"batb":[[1,6.2,34.62]],"ltp":0.0,"tv":0.0,"id":13117449},{"batb":[[0,4.9,29.9],[1,1.01,0.51],[2,1.01,0]],"ltp":5.9,"tv":4.0,"id":13117448},{"batb":[[1,1.01,0.51],[2,4,0]],"ltp":4.4,"tv":84.19,"id":13117392}]}]}
{"op":"mcm","clk":"1006273075","pt":1580594806569,"mc":[{"id":"1.168175449","rc":[{"batb":[[0,6.6,54.84],[1,6.4,73.56],[2,6.2,34.62]],"ltp":0.0,"tv":0.0,"id":13117449},{"batb":[[0,6.2,87.15],[1,6,119.28],[2,5.6,22.19]],"batl":[[1,7.8,28.4]],"ltp":5.9,"tv":4.0,"id":13117448},{"batb":[[0,4.6,33.68],[1,4.5,35.72],[2,4.3,148.28]],"batl":[[1,5.4,30.61]],"ltp":4.4,"tv":84.19,"id":13117392},{"batl":[[0,2.04,62.16],[1,2.16,53.19],[2,2.32,42.8]],"ltp":2.12,"tv":987.14,"id":13117391}]}]}
{"op":"mcm","clk":"1006273175","pt":1580594807350,"mc":[{"id":"1.168175449","rc":[{"batb":[[2,6.2,41.08]],"batl":[[0,7.6,34.99]],"ltp":0.0,"tv":0.0,"id":13117449},{"batb":[[2,5.8,8.4]],"batl":[[0,7.2,39.85]],"ltp":5.9,"tv":4.0,"id":13117448},{"batb":[[2,4.3,108.94]],"batl":[[0,5.1,10.08],[1,5.2,32.18],[2,5.4,30.61]],"ltp":4.4,"tv":84.19,"id":13117392},{"batb":[[2,1.97,42.85]],"batl":[[2,2.18,35.29]],"ltp":2.12,"tv":987.14,"id":13117391}]}]}
{"op":"mcm","clk":"1006274484","pt":1580594818412,"mc":[{"id":"1.168175449","rc":[{"batb":[[0,6.4,73.56],[1,6.2,33.52],[2,1.01,0.51]],"batl":[[0,7.6,29.11]],"ltp":0.0,"tv":0.0,"id":13117449},{"batb":[[0,5.6,22.19],[1,1.01,0.51],[2,5.8,0]],"batl":[[0,7.8,28.4],[1,7.8,0]],"ltp":5.9,"tv":4.0,"id":13117448},{"batb":[[0,4.5,35.72],[1,4.2,94.6],[2,1.01,0.51]],"batl":[[0,5.4,30.61],[1,5.2,0],[2,5.4,0]],"ltp":4.4,"tv":84.19,"id":13117392},{"batb":[[0,1.88,35.33],[1,1.01,0.51],[2,1.97,0]],"batl":[[0,2.16,53.19],[1,2.16,0],[2,2.18,0]],"ltp":2.12,"tv":987.14,"id":13117391}]}]}
{"op":"mcm","clk":"1006274791","pt":1580594821079,"mc":[{"id":"1.168175449","rc":[{"batb":[[1,6.2,111.62]],"ltp":0.0,"tv":0.0,"id":13117449},{"batb":[[0,5.7,83.39],[1,5.6,72.01],[2,1.01,0.51]],"ltp":5.9,"tv":4.0,"id":13117448},{"batb":[[1,4.2,136.57],[2,4.1,99.62]],"ltp":4.4,"tv":84.19,"id":13117392},{"batb":[[0,1.98,158.65],[1,1.96,141.95],[2,1.88,35.33]],"ltp":2.12,"tv":987.14,"id":13117391}]}]}
{"op":"mcm","clk":"1006275533","pt":1580594826404,"mc":[{"id":"1.168175449","rc":[{"batb":[[1,6.2,33.52]],"ltp":0.0,"tv":0.0,"id":13117449},{"batb":[[0,5.6,22.19],[1,1.01,0.51],[2,1.01,0]],"ltp":5.9,"tv":4.0,"id":13117448},{"batb":[[1,1.01,0.51],[2,4.1,0]],"ltp":4.4,"tv":84.19,"id":13117392}]}]}
{"op":"mcm","clk":"1006275871","pt":1580594829566,"mc":[{"id":"1.168175449","rc":[{"batb":[[0,6.6,82.01],[1,6.4,73.56],[2,6.2,33.52]],"ltp":0.0,"tv":0.0,"id":13117449},{"batb":[[0,6.6,64.71],[1,6.4,73.3],[2,5.6,22.19]],"ltp":5.9,"tv":4.0,"id":13117448},{"batb":[[1,4.4,57.84],[2,4.3,90.41]],"ltp":4.4,"tv":84.19,"id":13117392}]}]}
{"op":"mcm","clk":"1006276054","pt":1580594830353,"mc":[{"id":"1.168175449","rc":[{"batb":[[1,6.4,113.46],[2,1.01,0.51]],"batl":[[0,7.8,5.88],[1,8,27.15]],"ltp":0.0,"tv":0.0,"id":13117449},{"batb":[[0,6.6,94.92],[2,6.2,7.56]],"batl":[[0,7.8,34.29],[1,9.2,19.83]],"ltp":5.9,"tv":4.0,"id":13117448},{"batb":[[0,4.7,31.94],[1,4.6,34.93],[2,4.4,57.84]],"batl":[[0,5.1,10.08],[1,5.4,30.61],[2,5.6,27.7]],"ltp":4.4,"tv":84.19,"id":13117392},{"trd":[[1.98,69.56]],"batb":[[0,1.98,123.87],[2,1.9,46.21]],"batl":[[0,2.08,58.3],[1,2.1,37.81]],"ltp":1.98,"tv":1056.69,"id":13117391}],"tv":1144.89}]}
{"op":"mcm","clk":"1006277113","pt":1580594838288,"mc":[{"id":"1.168175449","rc":[{"batb":[[1,6.4,112.44],[2,6.2,32.81]],"ltp":0.0,"tv":0.0,"id":13117449},{"batb":[[0,6.6,64.71],[1,6.4,103.91]],"ltp":5.9,"tv":4.0,"id":13117448},{"batb":[[1,4.5,35.33]],"ltp":4.4,"tv":84.19,"id":13117392},{"batl":[[0,1.99,34.15],[2,2.12,57.36]],"ltp":1.98,"tv":1056.69,"id":13117391}]}]}
{"op":"mcm","clk":"1006278489","pt":1580594849068,"mc":[{"id":"1.168175449","rc":[{"trd":[[1.99,63.29]],"batl":[[0,1.99,2.5]],"ltp":1.99,"tv":1119.98,"id":13117391}],"tv":1208.17}]}
{"op":"mcm","clk":"1006278952","pt":1580594853199,"mc":[{"id":"1.168175449","rc":[{"batl":[[0,8,27.15],[1,8,0]],"ltp":0.0,"tv":0.0,"id":13117449},{"batb":[[2,5.8,39.58]],"ltp":5.9,"tv":4.0,"id":13117448},{"batb":[[2,1.89,34.7]],"ltp":1.99,"tv":1119.98,"id":13117391}]}]}
{"op":"mcm","clk":"1006279318","pt":1580594856321,"mc":[{"id":"1.168175449","rc":[{"batl":[[0,8,33.03]],"ltp":0.0,"tv":0.0,"id":13117449},{"batb":[[1,6.4,111.47]],"ltp":5.9,"tv":4.0,"id":13117448},{"batb":[[2,1.89,81.75]],"ltp":1.99,"tv":1119.98,"id":13117391}]}]}
{"op":"mcm","clk":"1006279546","pt":1580594858195,"mc":[{"id":"1.168175449","rc":[{"trd":[[1.98,145.28]],"batb":[[0,1.98,86.01]],"ltp":1.98,"tv":1195.7,"id":13117391}],"tv":1283.9}]}
{"op":"mcm","clk":"1006279904","pt":1580594861330,"mc":[{"id":"1.168175449","rc":[{"batb":[[0,1.98,144.46]],"ltp":1.98,"tv":1195.7,"id":13117391}]}]}
{"op":"mcm","clk":"1006280454","pt":1580594866032,"mc":[{"id":"1.168175449","rc":[{"batb":[[0,6.6,38.05]],"ltp":0.0,"tv":0.0,"id":13117449},{"batb":[[0,6.4,38.17],[1,5.8,39.58],[2,1.01,0.51]],"ltp":5.9,"tv":4.0,"id":13117448},{"batb":[[2,4.3,67.33]],"ltp":4.4,"tv":84.19,"id":13117392},{"batb":[[0,1.89,81.75],[1,1.77,42.8],[2,1.01,0.51]],"ltp":1.98,"tv":1195.7,"id":13117391}]}]}
{"op":"mcm","clk":"1006280836","pt":1580594869006,"mc":[{"id":"1.168175449","rc":[{"batb":[[1,6,52.55],[2,5.9,44.8]],"ltp":5.9,"tv":4.0,"id":13117448},{"batb":[[1,1.86,119.47],[2,1.84,173.23]],"ltp":1.98,"tv":1195.7,"id":13117391}]}]}
{"op":"mcm","clk":"1006281985","pt":1580594878421,"mc":[{"id":"1.168175449","rc":[{"batb":[[1,6.4,73.56]],"batl":[[0,8,27.15]],"ltp":0.0,"tv":0.0,"id":13117449},{"batb":[[0,6,52.55],[1,5.9,44.8],[2,5.8,39.58]],"batl":[[0,9.2,19.83],[1,9.2,0]],"ltp":5.9,"tv":4.0,"id":13117448},{"batb":[[0,4.5,35.33],[1,4.3,54.73],[2,4.2,95.6]],"batl":[[0,5.6,27.7],[1,5.4,0],[2,5.6,0]],"ltp":4.4,"tv":84.19,"id":13117392},{"batb":[[0,1.86,119.47],[1,1.84,173.23],[2,1.77,42.8]],"batl":[[0,2.12,57.36],[1,2.1,0],[2,2.12,0]],"ltp":1.98,"tv":1195.7,"id":13117391}]}]}
{"op":"mcm","clk":"1006282313","pt":1580594881133,"mc":[{"id":"1.168175449","rc":[{"batl":[[0,7.6,28.72]],"ltp":0.0,"tv":0.0,"id":13117449},{"batb":[[2,5.7,41.39]],"batl":[[0,9,21.09]],"ltp":5.9,"tv":4.0,"id":13117448},{"batl":[[0,5.5,28.09]],"ltp":4.4,"tv":84.19,"id":13117392},{"batb":[[2,1.81,41.39]],"batl":[[0,2.16,55.39]],"ltp":1.98,"tv":1195.7,"id":13117391}]}]}
{"op":"mcm","clk":"1006282986","pt":1580594886560,"mc":[{"id":"1.168175449","rc":[{"batb":[[0,1.81,41.39],[1,1.01,0.51],[2,1.81,0]],"ltp":1.98,"tv":1195.7,"id":13117391}]}]}
{"op":"mcm","clk":"1006283342","pt":1580594889365,"mc":[{"id":"1.168175449","rc":[{"batb":[[2,6.2,40.37]],"batl":[[1,7.8,5.88]],"ltp":0.0,"tv":0.0,"id":13117449},{"batb":[[1,5.9,53.2]],"batl":[[0,7.2,6.72],[1,9,21.09]],"ltp":5.9,"tv":4.0,"id":13117448},{"batb":[[2,4.2,108.2]],"batl":[[0,5.1,10.08],[1,5.5,28.09]],"ltp":4.4,"tv":84.19,"id":13117392},{"batb":[[0,2.08,141.43],[1,2.06,122.07],[2,1.97,42.85]],"batl":[[1,2.18,35.29]],"ltp":1.98,"tv":1195.7,"id":13117391}]}]}
{"op":"mcm","clk":"1006283471","pt":1580594890568,"mc":[{"id":"1.168175449","rc":[{"batl":[[0,7.4,32.02],[1,7.6,28.72],[2,7.8,5.88]],"ltp":0.0,"tv":0.0,"id":13117449},{"batl":[[0,6.8,38.55],[1,7.2,6.72],[2,7.8,28.64]],"ltp":5.9,"tv":4.0,"id":13117448},{"batb":[[1,4.4,37.85],[2,4.3,54.73]],"batl":[[0,5.1,43.76],[1,5.3,31.08]],"ltp":4.4,"tv":84.19,"id":13117392},{"batb":[[2,2.02,56.97]],"batl":[[2,2.28,47.6]],"ltp":1.98,"tv":1195.7,"id":13117391}]}]}
{"op":"mcm","clk":"1006285381","pt":1580594907067,"mc":[{"id":"1.168175449","rc":[{"batb":[[0,6.4,73.56],[1,6.2,7.56],[2,6,34.7]],"batl":[[0,7.6,28.72],[1,7.8,5.88],[2,7.8,0]],"ltp":0.0,"tv":0.0,"id":13117449},{"batb":[[0,5.9,8.4],[1,5.2,25.1],[2,1.01,0.51]],"batl":[[0,7.2,6.72],[1,7.8,28.4],[2,7.8,0]],"ltp":5.9,"tv":4.0,"id":13117448},{"batb":[[0,4.4,37.85],[1,4.2,81.11],[2,1.01,0.51]],"batl":[[0,5.1,10.08]],"ltp":4.4,"tv":84.19,"id":13117392},{"batb":[[0,1.97,42.85],[1,1.92,34.38],[2,1.01,0.51]],"batl":[[0,2.18,35.29],[1,2.28,47.6],[2,2.28,0]],"ltp":1.98,"tv":1195.7,"id":13117391}]}]}
{"op":"mcm","clk":"1006285530","pt":1580594908477,"mc":[{"id":"1.168175449","rc":[{"batb":[[1,6,34.7],[2,1.01,0.51]],"batl":[[1,7.8,0]],"ltp":0.0,"tv":0.0,"id":13117449},{"batb":[[0,5.2,25.1],[1,1.01,0.51],[2,1.01,0]],"batl":[[0,7.8,28.4],[1,7.8,0]],"ltp":5.9,"tv":4.0,"id":13117448},{"batb":[[1,4.2,68.51]],"batl":[[0,5.3,31.08],[1,5.3,0]],"ltp":4.4,"tv":84.19,"id":13117392},{"batb":[[0,1.92,34.38],[1,1.01,0.51],[2,1.01,0]],"batl":[[0,2.28,47.6],[1,2.28,0]],"ltp":1.98,"tv":1195.7,"id":13117391}]}]}
{"op":"mcm","clk":"1006285890","pt":1580594911494,"mc":[{"id":"1.168175449","rc":[{"batb":[[0,6.6,49.87],[1,6.4,73.56],[2,6,34.7]],"ltp":0.0,"tv":0.0,"id":13117449},{"batb":[[0,6,116.54],[1,5.9,43.91],[2,5.2,25.1]],"ltp":5.9,"tv":4.0,"id":13117448},{"batb":[[1,4.3,78.08],[2,4.2,95.2]],"ltp":4.4,"tv":84.19,"id":13117392},{"batb":[[0,2.06,108.05],[1,2.04,125.72],[2,1.92,34.38]],"ltp":1.98,"tv":1195.7,"id":13117391}]}]}
{"op":"mcm","clk":"1006286775","pt":1580594918500,"mc":[{"id":"1.168175449","rc":[{"batb":[[0,6.4,73.56],[1,6,34.7],[2,1.01,0.51]],"ltp":0.0,"tv":0.0,"id":13117449},{"batb":[[0,5.2,25.1],[1,1.01,0.51],[2,5.2,0]],"ltp":5.9,"tv":4.0,"id":13117448},{"batb":[[1,4.2,68.51],[2,1.01,0.51]],"ltp":4.4,"tv":84.19,"id":13117392},{"batb":[[0,1.92,34.38],[1,1.01,0.51],[2,1.92,0]],"ltp":1.98,"tv":1195.7,"id":13117391}]}]}
{"op":"mcm","clk":"1006287117","pt":1580594921518,"mc":[{"id":"1.168175449","rc":[{"batb":[[1,6.2,78.5],[2,6,34.7]],"ltp":0.0,"tv":0.0,"id":13117449},{"batb":[[0,5.5,70.75],[1,5.4,54.3],[2,5.2,25.1]],"ltp":5.9,"tv":4.0,"id":13117448},{"batb":[[2,4.1,100.88]],"ltp":4.4,"tv":84.19,"id":13117392},{"batb":[[0,1.96,134.89],[1,1.94,146.53],[2,1.92,34.38]],"ltp":1.98,"tv":1195.7,"id":13117391}]}]}
{"op":"mcm","clk":"1006287314","pt":1580594923394,"mc":[{"id":"1.168175449","rc":[{"batb":[[1,6,34.7],[2,1.01,0.51]],"ltp":0.0,"tv":0.0,"id":13117449},{"batb":[[0,5.2,25.1],[1,1.01,0.51],[2,5.2,0]],"ltp":5.9,"tv":4.0,"id":13117448},{"batb":[[1,1.01,0.51],[2,4.1,0]],"ltp":4.4,"tv":84.19,"id":13117392}]}]}
{"op":"mcm","clk":"1006287597","pt":1580594926194,"mc":[{"id":"1.168175449","rc":[{"batb":[[0,6.6,97.29],[1,6.4,73.56],[2,6,34.7]],"ltp":0.0,"tv":0.0,"id":13117449},{"batb":[[0,6.8,56.75],[1,6.6,68.8],[2,5.2,25.1]],"ltp":5.9,"tv":4.0,"id":13117448},{"batb":[[0,4.4,117.6],[1,4.3,90.1],[2,1.01,0.51]],"ltp":4.4,"tv":84.19,"id":13117392}]}]}
{"op":"mcm","clk":"1006287747","pt":1580594927386,"mc":[{"id":"1.168175449","rc":[{"batb":[[1,6.4,81.12],[2,6.2,33.6]],"batl":[[1,8,5.88]],"ltp":0.0,"tv":0.0,"id":13117449},{"batb":[[1,6.6,75.52],[2,6.4,30.14]],"batl":[[1,8.2,5.04],[2,9.4,18.65]],"ltp":5.9,"tv":4.0,"id":13117448},{"batb":[[0,4.7,32.65],[1,4.5,35.64],[2,4.4,79.75]],"batl":[[0,5.2,9.24],[1,5.3,31.08],[2,5.6,27.46]],"ltp":4.4,"tv":84.19,"id":13117392},{"batl":[[0,2,33.99],[1,2.06,39.49],[2,2.14,56.18]],"ltp":1.98,"tv":1195.7,"id":13117391}]}]}
{"op":"mcm","clk":"1006289254","pt":1580594941511,"mc":[{"id":"1.168175449","rc":[{"batb":[[0,6.6,45.75]],"ltp":0.0,"tv":0.0,"id":13117449},{"batb":[[0,6.6,6.72],[1,5.8,40.05],[2,1.01,0.51]],"batl":[[0,8.2,5.04],[1,9.4,18.65],[2,9.4,0]],"ltp":5.9,"tv":4.0,"id":13117448},{"batb":[[0,4.5,35.64],[1,4.3,66.7],[2,1.01,0.51]],"batl":[[1,5.6,27.46],[2,5.6,0]],"ltp":4.4,"tv":84.19,"id":13117392},{"batb":[[0,1.87,47.89],[1,1.78,43.59],[2,1.01,0.51]],"batl":[[0,2.06,39.49],[1,2.14,56.18],[2,2.14,0]],"ltp":1.98,"tv":1195.7,"id":13117391}]}]}
{"op":"mcm","clk":"1006289346","pt":1580594942395,"mc":[{"id":"1.168175449","rc":[{"batb":[[1,6.4,73.56]],"batl":[[1,8,0]],"ltp":0.0,"tv":0.0,"id":13117449},{"batb":[[0,5.8,40.05],[1,1.01,0.51],[2,1.01,0]],"batl":[[0,9.4,18.65],[1,9.4,0]],"ltp":5.9,"tv":4.0,"id":13117448},{"batb":[[1,4.3,54.1]],"batl":[[0,5.6,27.46],[1,5.6,0]],"ltp":4.4,"tv":84.19,"id":13117392},{"batb":[[0,1.78,43.59],[1,1.01,0.51],[2,1.01,0]],"batl":[[0,2.14,56.18],[1,2.14,0]],"ltp":1.98,"tv":1195.7,"id":13117391}]}]}
{"op":"mcm","clk":"1006289559","pt":1580594944310,"mc":[{"id":"1.168175449","rc":[{"batb":[[0,6,68.54],[1,5.9,44.58],[2,5.8,40.05]],"ltp":5.9,"tv":4.0,"id":13117448},{"batb":[[2,4.2,95.62]],"ltp":4.4,"tv":84.19,"id":13117392},{"batb":[[0,1.82,147.63],[1,1.8,186.13],[2,1.78,43.59]],"ltp":1.98,"tv":1195.7,"id":13117391}]}]}
{"op":"mcm","clk":"1006290311","pt":1580594951449,"mc":[{"id":"1.168175449","rc":[{"batb":[[0,1.78,43.59],[1,1.01,0.51],[2,1.78,0]],"ltp":1.98,"tv":1195.7,"id":13117391}]}]}
{"op":"mcm","clk":"1006290620","pt":1580594954258,"mc":[{"id":"1.168175449","rc":[{"batl":[[0,7.4,31.55],[1,7.6,28.72]],"ltp":0.0,"tv":0.0,"id":13117449},{"batl":[[0,6.8,37.37],[1,8,26.75]],"ltp":5.9,"tv":4.0,"id":13117448},{"batb":[[1,4.3,92.42]],"batl":[[0,5.1,33.99],[1,5.3,30.84]],"ltp":4.4,"tv":84.19,"id":13117392},{"batb":[[0,2.08,104.45],[1,2.06,122.11],[2,2.02,57.83]],"batl":[[1,2.28,47.13]],"ltp":1.98,"tv":1195.7,"id":13117391}]}]}
{"op":"mcm","clk":"1006290778","pt":1580594955518,"mc":[{"id":"1.168175449","rc":[{"batb":[[1,6.4,81.12]],"batl":[[2,7.8,5.88]],"ltp":0.0,"tv":0.0,"id":13117449},{"batb":[[0,6,76.94]],"batl":[[1,7.4,5.88],[2,8,26.75]],"ltp":5.9,"tv":4.0,"id":13117448},{"batb":[[2,4.2,108.22]],"batl":[[0,5,10.08],[1,5.1,33.99],[2,5.3,30.84]],"ltp":4.4,"tv":84.19,"id":13117392},{"batl":[[1,2.16,36.13],[2,2.28,47.13]],"ltp":1.98,"tv":1195.7,"id":13117391}]}]}
{"op":"mcm","clk":"1006292622","pt":1580594971170,"mc":[{"id":"1.168175449","rc":[{"batb":[[0,6.4,81.12],[1,6,35.01],[2,1.01,0.51]],"batl":[[0,7.6,28.72],[1,7.8,5.88],[2,7.8,0]],"ltp":0.0,"tv":0.0,"id":13117449},{"batb":[[0,6,8.4],[1,5.2,25.41],[2,1.01,0.51]],"batl":[[0,7.4,5.88],[1,8,26.75],[2,8,0]],"ltp":5.9,"tv":4.0,"id":13117448},{"batb":[[0,4.3,38.32],[1,4.2,66.16],[2,1.01,0.51]],"batl":[[1,5.3,30.84],[2,5.3,0]],"ltp":4.4,"tv":84.19,"id":13117392},{"batb":[[0,1.94,44.53],[1,1.9,35.64],[2,1.01,0.51]],"batl":[[0,2.16,36.13],[1,2.28,47.13],[2,2.28,0]],"ltp":1.98,"tv":1195.7,"id":13117391}]}]}
{"op":"mcm","clk":"1006292798","pt":1580594972534,"mc":[{"id":"1.168175449","rc":[{"batb":[[0,6.4,73.56]],"batl":[[1,7.8,0]],"ltp":0.0,"tv":0.0,"id":13117449},{"batb":[[0,5.2,25.41],[1,1.01,0.51],[2,1.01,0]],"batl":[[0,8,26.75],[1,8,0]],"ltp":5.9,"tv":4.0,"id":13117448},{"batb":[[1,4.2,53.56]],"batl":[[0,5.3,30.84],[1,5.3,0]],"ltp":4.4,"tv":84.19,"id":13117392},{"batb":[[0,1.9,35.64],[1,1.01,0.51],[2,1.01,0]],"batl":[[0,2.28,47.13],[1,2.28,0]],"ltp":1.98,"tv":1195.7,"id":13117391}]}]}
{"op":"mcm","clk":"1006292909","pt":1580594973672,"mc":[{"id":"1.168175449","rc":[{"batb":[[1,6.2,78.39],[2,6,35.01]],"ltp":0.0,"tv":0.0,"id":13117449},{"batb":[[0,5.5,53.17],[1,5.4,54.56],[2,5.2,25.41]],"ltp":5.9,"tv":4.0,"id":13117448},{"batb":[[2,4.1,101.14]],"ltp":4.4,"tv":84.19,"id":13117392},{"batb":[[0,1.94,129.51],[1,1.92,151.33],[2,1.9,35.64]],"ltp":1.98,"tv":1195.7,"id":13117391}]}]}
{"op":"mcm","clk":"1006293144","pt":1580594975560,"mc":[{"id":"1.168175449","rc":[{"batb":[[0,1.9,35.64],[1,1.01,0.51],[2,1.9,0]],"ltp":1.98,"tv":1195.7,"id":13117391}]}]}
{"op":"mcm","clk":"1006293468","pt":1580594978375,"mc":[{"id":"1.168175449","rc":[{"batl":[[0,7.4,31.55],[1,7.6,28.72]],"ltp":0.0,"tv":0.0,"id":13117449},{"batl":[[0,5.9,24.39],[1,6.8,37.85],[2,8,26.75]],"ltp":5.9,"tv":4.0,"id":13117448},{"batl":[[0,4.9,36.43],[1,5.1,34.07],[2,5.3,30.84]],"ltp":4.4,"tv":84.19,"id":13117392},{"batb":[[0,2.18,155.8],[1,2.16,106.15],[2,2.14,48.39]],"batl":[[1,2.4,41.39]],"ltp":1.98,"tv":1195.7,"id":13117391}]}]}
{"op":"mcm","clk":"1006293592","pt":1580594979376,"mc":[{"id":"1.168175449","rc":[{"batb":[[1,6.2,85.95]],"batl":[[1,7.6,5.88]],"ltp":0.0,"tv":0.0,"id":13117449},{"batb":[[0,5.5,62.41]],"batl":[[1,6.8,44.57],[2,8,0]],"ltp":5.9,"tv":4.0,"id":13117448},{"batb":[[2,4.1,114.58]],"batl":[[0,4.9,46.51],[2,5.3,0]],"ltp":4.4,"tv":84.19,"id":13117392},{"batl":[[0,2.26,32.77],[1,2.28,47.13],[2,2.4,41.39]],"ltp":1.98,"tv":1195.7,"id":13117391}]}]}
{"op":"mcm","clk":"1006295125","pt":1580594992579,"mc":[{"id":"1.168175449","rc":[{"batb":[[0,6.4,40.36]],"ltp":0.0,"tv":0.0,"id":13117449},{"batb":[[0,5.5,9.24],[1,4.9,29.9],[2,1.01,0.51]],"batl":[[0,6.8,44.57],[1,6.8,0]],"ltp":5.9,"tv":4.0,"id":13117448},{"batb":[[1,4.1,114.58],[2,1.01,0.51]],"batl":[[0,4.9,10.08]],"ltp":4.4,"tv":84.19,"id":13117392},{"batb":[[0,2.04,40.33],[1,2.02,57.44],[2,1.01,0.51]],"batl":[[1,2.4,41.39],[2,2.4,0]],"ltp":1.98,"tv":1195.7,"id":13117391}]}]}
{"op":"mcm","clk":"1006295330","pt":1580594994458,"mc":[{"id":"1.168175449","rc":[{"batb":[[1,6.2,78.39]],"batl":[[1,7.6,0]],"ltp":0.0,"tv":0.0,"id":13117449},{"batb":[[0,4.9,29.9],[1,1.01,0.51],[2,1.01,0]],"batl":[[0,6.8,37.85]],"ltp":5.9,"tv":4.0,"id":13117448},{"batb":[[1,4.1,101.14]],"batl":[[0,5.1,34.07],[1,5.1,0]],"ltp":4.4,"tv":84.19,"id":13117392},{"batb":[[0,2.02,57.44],[1,1.01,0.51],[2,1.01,0]],"batl":[[0,2.4,41.39],[1,2.4,0]],"ltp":1.98,"tv":1195.7,"id":13117391}]}]}
{"op":"mcm","clk":"1006295427","pt":1580594995507,"mc":[{"id":"1.168175449","rc":[{"batb":[[0,5.2,58.96],[1,5.1,61.94],[2,4.9,29.9]],"ltp":5.9,"tv":4.0,"id":13117448},{"batb":[[2,4,106.34]],"ltp":4.4,"tv":84.19,"id":13117392},{"batb":[[0,2.08,161.26],[1,2.06,122.05],[2,2.02,57.44]],"ltp":1.98,"tv":1195.7,"id":13117391}]}]}
{"op":"mcm","clk":"1006295453","pt":1580594995666,"mc":[{"id":"1.168175449","rc":[{"batb":[[0,4.9,29.9],[1,1.01,0.51],[2,4.9,0]],"ltp":5.9,"tv":4.0,"id":13117448},{"batb":[[2,1.01,0.51]],"ltp":4.4,"tv":84.19,"id":13117392},{"batb":[[0,2.02,57.44],[1,1.01,0.51],[2,2.02,0]],"ltp":1.98,"tv":1195.7,"id":13117391}]}]}
{"op":"mcm","clk":"1006295621","pt":1580594997180,"mc":[{"id":"1.168175449","rc":[{"batb":[[0,6.4,85.46]],"ltp":0.0,"tv":0.0,"id":13117449},{"batb":[[0,5.6,47.77],[1,5.5,52.44],[2,4.9,29.9]],"ltp":5.9,"tv":4.0,"id":13117448},{"batb":[[1,4.2,69.59],[2,4.1,101.14]],"ltp":4.4,"tv":84.19,"id":13117392},{"batb":[[0,2.16,152.68],[1,2.14,109.07],[2,2.02,57.44]],"ltp":1.98,"tv":1195.7,"id":13117391}]}]}
{"op":"mcm","clk":"1006296369","pt":1580595003904,"mc":[{"id":"1.168175449","rc":[{"batb":[[0,6.4,40.36]],"ltp":0.0,"tv":0.0,"id":13117449},{"batb":[[0,4.9,29.9],[1,1.01,0.51],[2,4.9,0]],"ltp":5.9,"tv":4.0,"id":13117448},{"batb":[[1,4.1,101.14],[2,1.01,0.51]],"ltp":4.4,"tv":84.19,"id":13117392},{"batb":[[0,2.02,57.44],[1,1.01,0.51],[2,2.02,0]],"ltp":1.98,"tv":1195.7,"id":13117391}]}]}
{"op":"mcm","clk":"1006296749","pt":1580595007510,"mc":[{"id":"1.168175449","rc":[{"batb":[[0,5.2,58.96],[1,5.1,61.94],[2,4.9,29.9]],"ltp":5.9,"tv":4.0,"id":13117448},{"batb":[[2,4,106.34]],"ltp":4.4,"tv":84.19,"id":13117392},{"batb":[[0,2.08,161.26],[1,2.06,122.05],[2,2.02,57.44]],"ltp":1.98,"tv":1195.7,"id":13117391}]}]}
{"op":"mcm","clk":"1006297890","pt":1580595017404,"mc":[{"id":"1.168175449","rc":[{"batb":[[0,2.02,57.44],[1,1.01,0.51],[2,2.02,0]],"ltp":1.98,"tv":1195.7,"id":13117391}]}]}
{"op":"mcm","clk":"1006298301","pt":1580595020499,"mc":[{"id":"1.168175449","rc":[{"batb":[[0,2.26,130.43],[1,2.24,95.66],[2,2.02,57.44]],"ltp":1.98,"tv":1195.7,"id":13117391}]}]}
{"op":"mcm","clk":"1006298380","pt":1580595021123,"mc":[{"id":"1.168175449","rc":[{"batl":[[0,7.2,33.05],[1,7.4,31.55]],"ltp":0.0,"tv":0.0,"id":13117449},{"batl":[[0,5.5,28.64],[1,6.2,22.66],[2,6.8,37.85]],"ltp":5.9,"tv":4.0,"id":13117448},{"batb":[[1,4.1,145.12]],"batl":[[0,4.8,38.32],[1,5,35.96],[2,5.1,34.07]],"ltp":4.4,"tv":84.19,"id":13117392},{"batb":[[0,2.26,172.76],[2,2.12,50.44]],"batl":[[1,2.66,31.39]],"ltp":1.98,"tv":1195.7,"id":13117391}]}]}
{"op":"mcm","clk":"1006298457","pt":1580595021974,"mc":[{"id":"1.168175449","rc":[{"batb":[[2,5.9,8.4]],"batl":[[0,7.2,39.77],[1,7.4,0]],"ltp":0.0,"tv":0.0,"id":13117449},{"batb":[[1,5.1,72.02]],"batl":[[1,6.2,30.22],[2,6.8,0]],"ltp":5.9,"tv":4.0,"id":13117448},{"batb":[[1,4.1,158.57]],"batl":[[1,4.9,10.08],[2,5,35.96]],"ltp":4.4,"tv":84.19,"id":13117392},{"batb":[[2,2.12,87.4]],"batl":[[0,2.4,70.79]],"ltp":1.98,"tv":1195.7,"id":13117391}]}]}
{"op":"mcm","clk":"1006301906","pt":1580595054511,"mc":[{"id":"1.168175449","rc":[{"batb":[[0,6.2,56.88],[1,5.9,8.4],[2,5.8,39.1]],"ltp":0.0,"tv":0.0,"id":13117449},{"batb":[[0,5.1,10.08],[1,4.9,29.9],[2,4.2,41.07]],"ltp":5.9,"tv":4.0,"id":13117448},{"batb":[[1,4.1,57.43],[2,4,60.7]],"ltp":4.4,"tv":84.19,"id":13117392},{"batb":[[0,2.26,42.33],[1,2.12,87.4],[2,1.01,0.51]],"ltp":1.98,"tv":1195.7,"id":13117391}]}]}
{"op":"mcm","clk":"1006301968","pt":1580595054883,"mc":[{"id":"1.168175449","rc":[{"batb":[[1,4.2,41.07],[2,1.01,0.51]],"batl":[[0,6.2,30.22],[1,6.2,0]],"ltp":5.9,"tv":4.0,"id":13117448},{"batb":[[0,4.1,57.43],[1,4,60.7],[2,1.01,0.51]],"batl":[[0,4.9,10.08],[1,5,35.96],[2,5,0]],"ltp":4.4,"tv":84.19,"id":13117392},{"batb":[[0,2.12,87.4],[1,1.01,0.51],[2,1.01,0]],"batl":[[0,2.4,29.41]],"ltp":1.98,"tv":1195.7,"id":13117391}]}]}
{"op":"mcm","clk":"1006302141","pt":1580595056471,"mc":[{"id":"1.168175449","rc":[{"batb":[[1,5.8,39.1],[2,1.01,0.51]],"batl":[[0,7.2,33.05]],"ltp":0.0,"tv":0.0,"id":13117449},{"batb":[[0,4.2,41.07],[1,1.01,0.51],[2,1.01,0]],"batl":[[0,6.2,22.66]],"ltp":5.9,"tv":4.0,"id":13117448},{"trd":[[4.9,8.97]],"batb":[[0,4.1,43.98]],"batl":[[0,5,35.96],[1,5,0]],"ltp":4.9,"tv":93.16,"id":13117392},{"batb":[[0,2.12,50.44]],"batl":[[0,2.66,31.39],[1,2.66,0]],"ltp":1.98,"tv":1195.7,"id":13117391}],"tv":1292.87}]}
{"op":"mcm","clk":"1006302262","pt":1580595057491,"mc":[{"id":"1.168175449","rc":[{"batb":[[1,6,84.81],[2,5.8,39.1]],"ltp":0.0,"tv":0.0,"id":13117449},{"batb":[[0,4.5,86.91],[1,4.4,86.29],[2,4.2,41.07]],"ltp":5.9,"tv":4.0,"id":13117448},{"batb":[[2,3.95,55.84]],"ltp":4.9,"tv":93.16,"id":13117392},{"batb":[[0,2.14,157.21],[1,2.12,162.53],[2,1.01,0.51]],"ltp":1.98,"tv":1195.7,"id":13117391}]}]}
{"op":"mcm","clk":"1006302310","pt":1580595057903,"mc":[{"id":"1.168175449","rc":[{"batb":[[2,5.9,38.16]],"batl":[[0,7.2,32.18]],"ltp":0.0,"tv":0.0,"id":13117449},{"batb":[[2,4.3,39.97]],"batl":[[0,6.2,22.03]],"ltp":5.9,"tv":4.0,"id":13117448},{"batl":[[0,4.9,36.43]],"ltp":4.9,"tv":93.16,"id":13117392},{"batb":[[1,2.12,112.09],[2,2.1,51.38]],"batl":[[0,2.64,31.94]],"ltp":1.98,"tv":1195.7,"id":13117391}]}]}
{"op":"mcm","clk":"1006303043","pt":1580595064380,"mc":[{"id":"1.168175449","rc":[{"batb":[[1,5.9,38.16],[2,1.01,0.51]],"ltp":0.0,"tv":0.0,"id":13117449},{"batb":[[0,4.3,39.97],[1,1.01,0.51],[2,4.3,0]],"ltp":5.9,"tv":4.0,"id":13117448},{"batb":[[1,1.01,0.51],[2,3.95,0]],"ltp":4.9,"tv":93.16,"id":13117392}]}]}
{"op":"mcm","clk":"1006303414","pt":1580595067527,"mc":[{"id":"1.168175449","rc":[{"batb":[[0,6.4,78.48],[1,6.2,78.32],[2,6,8.4]],"batl":[[1,7.4,5.88]],"ltp":0.0,"tv":0.0,"id":13117449},{"batb":[[0,5.7,58.75],[1,5.6,50.26],[2,5.4,9.24]],"batl":[[1,6.6,6.72]],"ltp":5.9,"tv":4.0,"id":13117448},{"batb":[[0,4.2,97.55],[1,4.1,144.58],[2,1.01,0.51]],"batl":[[1,5,10.08]],"ltp":4.9,"tv":93.16,"id":13117392},{"batl":[[0,2.28,32.77],[1,2.64,31.94]],"ltp":1.98,"tv":1195.7,"id":13117391}]}]}
{"op":"mcm","clk":"1006303482","pt":1580595068106,"mc":[{"id":"1.168175449","rc":[{"batb":[[2,6,44.44]],"batl":[[0,7.4,36.72],[1,7.4,0]],"ltp":0.0,"tv":0.0,"id":13117449},{"batb":[[2,5.5,22.82]],"batl":[[2,7,35.96]],"ltp":5.9,"tv":4.0,"id":13117448},{"batb":[[0,4.3,38.32],[1,4.2,138.94],[2,4.1,100.6]],"batl":[[2,5.1,34.23]],"ltp":4.9,"tv":93.16,"id":13117392},{"batl":[[0,2.24,50.04],[1,2.28,32.77],[2,2.42,39.89]],"ltp":1.98,"tv":1195.7,"id":13117391}]}]}
{"op":"mcm","clk":"1006305463","pt":1580595085043,"mc":[{"id":"1.168175449","rc":[{"batb":[[0,6.2,78.32],[1,6,44.44],[2,1.01,0.51]],"ltp":0.0,"tv":0.0,"id":13117449},{"batb":[[0,5.4,9.24],[1,4.8,31.24],[2,1.01,0.51]],"batl":[[0,6.6,6.72],[1,7,35.96],[2,7,0]],"ltp":5.9,"tv":4.0,"id":13117448},{"batb":[[0,4.2,53.99],[1,4.1,68.95],[2,1.01,0.51]],"batl":[[0,5,10.08],[1,5.1,34.23],[2,5.1,0]],"ltp":4.9,"tv":93.16,"id":13117392},{"batb":[[0,2.06,39.49],[1,2,59.17],[2,1.01,0.51]],"batl":[[0,2.28,32.77],[1,2.42,39.89],[2,2.42,0]],"ltp":1.98,"tv":1195.7,"id":13117391}]}]}
{"op":"mcm","clk":"1006305639","pt":1580595086515,"mc":[{"id":"1.168175449","rc":[{"batb":[[1,6,36.04]],"batl":[[0,7.4,30.84]],"ltp":0.0,"tv":0.0,"id":13117449},{"batb":[[0,4.8,31.24],[1,1.01,0.51],[2,1.01,0]],"batl":[[0,7,35.96],[1,7,0]],"ltp":5.9,"tv":4.0,"id":13117448},{"batb":[[0,4.2,41.39]],"batl":[[0,5.1,34.23],[1,5.1,0]],"ltp":4.9,"tv":93.16,"id":13117392},{"batb":[[0,2,59.17],[1,1.01,0.51],[2,1.01,0]],"batl":[[0,2.42,39.89],[1,2.42,0]],"ltp":1.98,"tv":1195.7,"id":13117391}]}]}
{"op":"mcm","clk":"1006305954","pt":1580595088502,"mc":[{"id":"1.168175449","rc":[{"batb":[[0,6.2,100.37],[1,6,119.66]],"ltp":0.0,"tv":0.0,"id":13117449},{"batb":[[0,5,85.22],[1,4.9,67.45],[2,4.8,31.24]],"ltp":5.9,"tv":4.0,"id":13117448},{"batb":[[2,4,106.89]],"ltp":4.9,"tv":93.16,"id":13117392},{"batb":[[0,2.06,139.51],[1,2.04,125.66],[2,2,59.17]],"ltp":1.98,"tv":1195.7,"id":13117391}]}]}
{"op":"mcm","clk":"1006306017","pt":1580595089127,"mc":[{"id":"1.168175449","rc":[{"batb":[[0,6,36.04],[1,1.01,0.51],[2,1.01,0]],"ltp":0.0,"tv":0.0,"id":13117449},{"batb":[[0,4.8,31.24],[1,1.01,0.51],[2,4.8,0]],"ltp":5.9,"tv":4.0,"id":13117448},{"batb":[[1,1.01,0.51],[2,4,0]],"ltp":4.9,"tv":93.16,"id":13117392}]}]}
{"op":"mcm","clk":"1006306424","pt":1580595092337,"mc":[{"id":"1.168175449","rc":[{"batb":[[0,6.6,37.57],[1,6.4,74.1],[2,6,34.78]],"batl":[[0,7.4,30.53]],"ltp":0.0,"tv":0.0,"id":13117449},{"batb":[[0,6.2,44.09],[1,6,85.2],[2,5.9,38.48]],"batl":[[1,7.6,30.14]],"ltp":5.9,"tv":4.0,"id":13117448},{"batb":[[0,4.3,94.52],[1,4.2,95.59],[2,1.01,0.51]],"batl":[[1,5.2,33.05]],"ltp":4.9,"tv":93.16,"id":13117392},{"batl":[[0,2.12,57.52],[1,2.26,48.15]],"ltp":1.98,"tv":1195.7,"id":13117391}]}]}
{"op":"mcm","clk":"1006306563","pt":1580595093537,"mc":[{"id":"1.168175449","rc":[{"batb":[[2,6,43.18]],"batl":[[1,7.6,5.88]],"ltp":0.0,"tv":0.0,"id":13117449},{"batl":[[1,7.2,6.72],[2,7.6,30.14]],"ltp":5.9,"tv":4.0,"id":13117448},{"batb":[[0,4.3,107.13]],"batl":[[0,5,10.08],[1,5.1,34.23],[2,5.2,33.05]],"ltp":4.9,"tv":93.16,"id":13117392},{"batl":[[1,2.2,34.45],[2,2.26,48.15]],"ltp":1.98,"tv":1195.7,"id":13117391}]}]}
{"op":"mcm","clk":"1006308062","pt":1580595106532,"mc":[{"id":"1.168175449","rc":[{"batb":[[0,6.4,74.1],[1,6,34.78],[2,1.01,0.51]],"batl":[[1,7.6,0]],"ltp":0.0,"tv":0.0,"id":13117449},{"batb":[[0,5.4,23.84],[1,1.01,0.51],[2,5.9,0]],"batl":[[0,7.6,30.14],[1,7.2,0],[2,7.6,0]],"ltp":5.9,"tv":4.0,"id":13117448},{"batb":[[0,4.3,39.18],[1,4.2,73]],"batl":[[0,5.2,33.05],[1,5.1,0],[2,5.2,0]],"ltp":4.9,"tv":93.16,"id":13117392},{"batb":[[0,1.96,32.42],[1,1.01,0.51],[2,2,0]],"batl":[[0,2.26,48.15],[1,2.2,0],[2,2.26,0]],"ltp":1.98,"tv":1195.7,"id":13117391}]}]}
{"op":"mcm","clk":"1006308367","pt":1580595109152,"mc":[{"id":"1.168175449","rc":[{"batb":[[1,6.2,78.79],[2,6,34.78]],"ltp":0.0,"tv":0.0,"id":13117449},{"batb":[[0,5.6,67.96],[1,5.5,52.23],[2,5.4,23.84]],"ltp":5.9,"tv":4.0,"id":13117448},{"batb":[[2,4.1,100.78]],"ltp":4.9,"tv":93.16,"id":13117392},{"batb":[[0,2,175.05],[1,1.98,137.54],[2,1.96,32.42]],"ltp":1.98,"tv":1195.7,"id":13117391}]}]}
{"op":"mcm","clk":"1006309056","pt":1580595115194,"mc":[{"id":"1.168175449","rc":[{"batb":[[1,6,34.78],[2,1.01,0.51]],"ltp":0.0,"tv":0.0,"id":13117449},{"batb":[[0,5.4,23.84],[1,1.01,0.51],[2,5.4,0]],"ltp":5.9,"tv":4.0,"id":13117448},{"batb":[[2,1.01,0.51]],"ltp":4.9,"tv":93.16,"id":13117392}]}]}
{"op":"mcm","clk":"1006309436","pt":1580595118493,"mc":[{"id":"1.168175449","rc":[{"batb":[[0,6.6,68.78],[1,6.4,74.1],[2,6,34.78]],"ltp":0.0,"tv":0.0,"id":13117449},{"batb":[[0,6.6,34.18],[1,6.4,74.29],[2,5.4,23.84]],"ltp":5.9,"tv":4.0,"id":13117448},{"batb":[[0,4.3,137.11],[1,4.2,94.82]],"ltp":4.9,"tv":93.16,"id":13117392}]}]}
{"op":"mcm","clk":"1006309572","pt":1580595119505,"mc":[{"id":"1.168175449","rc":[{"batb":[[2,6.2,41.55]],"batl":[[0,7.6,34.91]],"ltp":0.0,"tv":0.0,"id":13117449},{"batb":[[1,6.4,106.39],[2,6.2,7.56]],"batl":[[0,7.6,36.02],[1,7.8,27.22]],"ltp":5.9,"tv":4.0,"id":13117448},{"batb":[[0,4.5,36.27],[1,4.3,110.53],[2,4.2,94.82]],"batl":[[0,5.1,10.08],[1,5.2,32.18]],"ltp":4.9,"tv":93.16,"id":13117392},{"batl":[[0,2.06,31.94],[1,2.14,91.91]],"ltp":1.98,"tv":1195.7,"id":13117391}]}]}
{"op":"mcm","clk":"1006311231","pt":1580595133300,"mc":[{"id":"1.168175449","rc":[{"batb":[[0,6.4,74.1],[1,6.2,41.55],[2,1.01,0.51]],"ltp":0.0,"tv":0.0,"id":13117449},{"batb":[[0,6.2,7.56],[1,5.8,39.42],[2,1.01,0.51]],"batl":[[0,7.6,5.88]],"ltp":5.9,"tv":4.0,"id":13117448},{"batb":[[1,4.3,69.75]],"ltp":4.9,"tv":93.16,"id":13117392},{"batb":[[0,1.98,137.54],[1,1.94,44.53],[2,1.91,34.93]],"batl":[[0,2.14,91.91],[1,2.14,0]],"ltp":1.98,"tv":1195.7,"id":13117391}]}]}
{"op":"mcm","clk":"1006311474","pt":1580595135181,"mc":[{"id":"1.168175449","rc":[{"batb":[[1,6.2,33.99]],"batl":[[0,7.6,29.03]],"ltp":0.0,"tv":0.0,"id":13117449},{"batb":[[0,5.8,39.42],[1,1.01,0.51],[2,1.01,0]],"batl":[[0,7.8,27.22],[1,7.8,0]],"ltp":5.9,"tv":4.0,"id":13117448},{"batb":[[1,4.3,57.15]],"batl":[[0,5.2,32.18],[1,5.2,0]],"ltp":4.9,"tv":93.16,"id":13117392},{"batb":[[1,1.91,34.93],[2,1.01,0.51]],"batl":[[0,2.14,55.79]],"ltp":1.98,"tv":1195.7,"id":13117391}]}]}
{"op":"mcm","clk":"1006311614","pt":1580595136403,"mc":[{"id":"1.168175449","rc":[{"batl":[[0,2,40],[1,2.14,55.79]],"ltp":1.98,"tv":1195.7,"id":13117391}]}]}
{"op":"mcm","clk":"1006311682","pt":1580595136935,"mc":[{"id":"1.168175449","rc":[{"batb":[[0,6.4,99.4],[1,6.2,111.8]],"ltp":0.0,"tv":0.0,"id":13117449},{"batb":[[0,6.2,39.28],[1,6,85.38],[2,5.8,39.42]],"ltp":5.9,"tv":4.0,"id":13117448},{"batb":[[1,1.96,141.92],[2,1.91,34.93]],"ltp":1.98,"tv":1195.7,"id":13117391}]}]}
{"op":"mcm","clk":"1006311983","pt":1580595139493,"mc":[{"id":"1.168175449","rc":[{"batb":[[0,6.4,74.1],[1,6.2,33.99]],"ltp":0.0,"tv":0.0,"id":13117449},{"batb":[[0,5.8,39.42],[1,1.01,0.51],[2,5.8,0]],"ltp":5.9,"tv":4.0,"id":13117448}]}]}
{"op":"mcm","clk":"1006312089","pt":1580595140485,"mc":[{"id":"1.168175449","rc":[{"batl":[[0,2.14,55.79],[1,2.14,0]],"ltp":1.98,"tv":1195.7,"id":13117391}]}]}
{"op":"mcm","clk":"1006312339","pt":1580595142416,"mc":[{"id":"1.168175449","rc":[{"batb":[[0,6.6,93.4],[1,6.4,74.1],[2,6.2,33.99]],"ltp":0.0,"tv":0.0,"id":13117449},{"batb":[[0,6.8,43.28],[1,6.6,69.24],[2,5.8,39.42]],"ltp":5.9,"tv":4.0,"id":13117448},{"batb":[[1,4.3,120.27]],"ltp":4.9,"tv":93.16,"id":13117392}]}]}
{"op":"mcm","clk":"1006312469","pt":1580595143517,"mc":[{"id":"1.168175449","rc":[{"batb":[[1,6.4,112.58],[2,6.2,32.89]],"batl":[[1,7.8,33.18]],"ltp":0.0,"tv":0.0,"id":13117449},{"batb":[[1,6.6,104.84],[2,6,37.3]],"batl":[[1,8,5.88],[2,9.6,18.49]],"ltp":5.9,"tv":4.0,"id":13117448},{"batb":[[0,4.6,33.68],[1,4.5,36.27],[2,4.3,132.87]],"batl":[[0,5.1,10.08],[1,5.2,32.18],[2,5.5,29.03]],"ltp":4.9,"tv":93.16,"id":13117392},{"batl":[[0,2,34.38],[1,2.08,38.65],[2,2.12,57.91]],"ltp":1.98,"tv":1195.7,"id":13117391}]}]}
{"op":"mcm","clk":"1006313290","pt":1580595150319,"mc":[{"id":"1.168175449","rc":[{"trd":[[1.98,165.92]],"batb":[[0,1.91,34.93],[1,1.89,47.05],[2,1.78,43.35]],"ltp":1.98,"tv":1216.34,"id":13117391}],"tv":1313.51}]}
{"op":"mcm","clk":"1006313610","pt":1580595153296,"mc":[{"id":"1.168175449","rc":[{"batb":[[0,1.97,172.05],[1,1.95,144.16],[2,1.91,34.93]],"ltp":1.98,"tv":1216.34,"id":13117391}]}]}
{"op":"mcm","clk":"1006314528","pt":1580595161336,"mc":[{"id":"1.168175449","rc":[{"batb":[[2,5.9,38.48]],"batl":[[2,9.4,19.04]],"ltp":5.9,"tv":4.0,"id":13117448},{"batb":[[0,4.6,33.28],[1,4.5,35.8]],"batl":[[1,5.2,31.79],[2,5.5,28.72]],"ltp":4.9,"tv":93.16,"id":13117392},{"batb":[[2,1.92,34.38]],"batl":[[0,2.02,33.83],[2,2.14,56.89]],"ltp":1.98,"tv":1216.34,"id":13117391}]}]}
{"op":"mcm","clk":"1006315435","pt":1580595168513,"mc":[{"id":"1.168175449","rc":[{"batb":[[0,2,3.42],[1,1.97,172.05],[2,1.95,144.16]],"ltp":1.98,"tv":1216.34,"id":13117391}]}]}
{"op":"mcm","clk":"1006315782","pt":1580595171554,"mc":[{"id":"1.168175449","rc":[{"batl":[[0,7.4,30.69],[1,7.6,29.03],[2,7.8,33.18]],"ltp":0.0,"tv":0.0,"id":13117449},{"batb":[[2,6.4,30.61]],"batl":[[0,7.6,28.8],[1,7.8,27.22],[2,8,5.88]],"ltp":5.9,"tv":4.0,"id":13117448},{"batl":[[2,5.3,31.47]],"ltp":4.9,"tv":93.16,"id":13117392}]}]}
{"op":"mcm","clk":"1006315839","pt":1580595172033,"mc":[{"id":"1.168175449","rc":[{"batb":[[1,6.4,81.66],[2,6.2,32.73]],"batl":[[2,7.8,5.88]],"ltp":0.0,"tv":0.0,"id":13117449},{"batb":[[1,6.6,75.96]],"batl":[[1,8,5.88],[2,9.2,19.59]],"ltp":5.9,"tv":4.0,"id":13117448},{"batb":[[0,4.6,32.89],[1,4.5,35.33]],"batl":[[1,5.3,31.47],[2,5.5,28.48]],"ltp":4.9,"tv":93.16,"id":13117392},{"batl":[[0,2.02,33.36],[2,2.14,56.02]],"ltp":1.98,"tv":1216.34,"id":13117391}]}]}
{"op":"mcm","clk":"1006319264","pt":1580595202242,"mc":[{"id":"1.168175449","rc":[{"trd":[[2,6.84]],"batb":[[0,1.97,172.05],[1,1.95,144.16],[2,1.93,33.83]],"batl":[[0,2,37.58],[1,2.02,33.36],[2,2.08,38.65]],"ltp":2.0,"tv":1223.18,"id":13117391}],"tv":1320.35}]}
{"op":"mcm","clk":"1006321220","pt":1580595220467,"mc":[{"id":"1.168175449","rc":[{"batl":[[1,9.2,19.59],[2,9.2,0]],"ltp":5.9,"tv":4.0,"id":13117448}]}]}
{"op":"mcm","clk":"1006321563","pt":1580595223374,"mc":[{"id":"1.168175449","rc":[{"batl":[[1,8.2,5.04],[2,9.2,19.59]],"ltp":5.9,"tv":4.0,"id":13117448}]}]}
{"op":"mcm","clk":"1006321881","pt":1580595226194,"mc":[{"id":"1.168175449","rc":[{"batb":[[0,6.6,43.43],[2,6,34.78]],"batl":[[0,7.6,29.03],[1,7.8,5.88],[2,7.8,0]],"ltp":0.0,"tv":0.0,"id":13117449},{"batb":[[0,6.6,6.72],[1,5.8,39.42],[2,1.01,0.51]],"batl":[[0,8.2,5.04],[1,9.2,19.59],[2,9.2,0]],"ltp":5.9,"tv":4.0,"id":13117448},{"batb":[[0,4.5,35.33],[1,4.3,12.6],[2,4.2,94.82]],"batl":[[1,5.5,28.48],[2,5.5,0]],"ltp":4.9,"tv":93.16,"id":13117392},{"batb":[[0,1.89,47.05],[1,1.8,42.02],[2,1.01,0.51]],"batl":[[1,2.08,38.65],[2,2.14,56.02]],"ltp":2.0,"tv":1223.18,"id":13117391}]}]}
{"op":"mcm","clk":"1006321997","pt":1580595227213,"mc":[{"id":"1.168175449","rc":[{"batb":[[1,6.4,74.1]],"batl":[[1,7.8,0]],"ltp":0.0,"tv":0.0,"id":13117449},{"batb":[[0,5.8,39.42],[1,1.01,0.51],[2,1.01,0]],"batl":[[0,9.2,19.59],[1,9.2,0]],"ltp":5.9,"tv":4.0,"id":13117448},{"batb":[[1,4.2,94.82],[2,1.01,0.51]],"batl":[[0,5.5,28.48],[1,5.5,0]],"ltp":4.9,"tv":93.16,"id":13117392},{"batb":[[0,1.8,42.02],[1,1.01,0.51],[2,1.01,0]],"batl":[[1,2.14,56.02],[2,2.14,0]],"ltp":2.0,"tv":1223.18,"id":13117391}]}]}
{"op":"mcm","clk":"1006322215","pt":1580595229094,"mc":[{"id":"1.168175449","rc":[{"batb":[[0,6,93.73],[1,5.9,44.33],[2,5.8,39.42]],"ltp":5.9,"tv":4.0,"id":13117448},{"batb":[[2,4.1,100.13]],"ltp":4.9,"tv":93.16,"id":13117392},{"batb":[[0,1.84,158.08],[1,1.82,179.48],[2,1.8,42.02]],"ltp":2.0,"tv":1223.18,"id":13117391}]}]}
{"op":"mcm","clk":"1006322365","pt":1580595230511,"mc":[{"id":"1.168175449","rc":[{"batb":[[0,6,34.78],[1,1.01,0.51],[2,6,0]],"ltp":0.0,"tv":0.0,"id":13117449},{"batb":[[0,5.8,39.42],[1,1.01,0.51],[2,5.8,0]],"ltp":5.9,"tv":4.0,"id":13117448},{"batb":[[1,1.01,0.51],[2,4.1,0]],"ltp":4.9,"tv":93.16,"id":13117392}]}]}
{"op":"mcm","clk":"1006322704","pt":1580595233493,"mc":[{"id":"1.168175449","rc":[{"batb":[[0,7,30.1],[1,6.8,65.19],[2,6.6,6.72]],"batl":[[1,8.2,5.04]],"ltp":0.0,"tv":0.0,"id":13117449},{"batb":[[0,8,70.88],[1,7.8,47.66],[2,7.6,5.88]],"batl":[[1,9.4,4.2]],"ltp":5.9,"tv":4.0,"id":13117448},{"batb":[[0,4.5,142.04],[1,4.4,85.14],[2,1.01,0.51]],"batl":[[0,5.3,9.24],[1,5.5,28.48]],"ltp":4.9,"tv":93.16,"id":13117392},{"batl":[[0,1.96,42.01],[1,2,37.58],[2,2.14,56.02]],"ltp":2.0,"tv":1223.18,"id":13117391}]}]}
{"op":"mcm","clk":"1006322813","pt":1580595234481,"mc":[{"id":"1.168175449","rc":[{"batl":[[1,8,26.75],[2,8.2,5.04]],"ltp":0.0,"tv":0.0,"id":13117449},{"batb":[[2,7.6,26.73]],"batl":[[1,12.5,27.85]],"ltp":5.9,"tv":4.0,"id":13117448},{"batb":[[0,4.8,29.82],[1,4.6,32.89],[2,4.5,106.71]],"batl":[[2,5.8,25.26]],"ltp":4.9,"tv":93.16,"id":13117392},{"batb":[[2,1.81,41.78]],"batl":[[0,1.88,41.07],[1,2,71.96],[2,2.14,0]],"ltp":2.0,"tv":1223.18,"id":13117391}]}]}
{"op":"mcm","clk":"1006323028","pt":1580595236224,"mc":[{"id":"1.168175449","rc":[{"batl":[[1,9.6,4.2],[2,12.5,27.85]],"ltp":5.9,"tv":4.0,"id":13117448},{"batl":[[1,1.95,42.01],[2,2,71.96]],"ltp":2.0,"tv":1223.18,"id":13117391}]}]}
{"op":"mcm","clk":"1006324867","pt":1580595252334,"mc":[{"id":"1.168175449","rc":[{"batb":[[0,6.8,37.67],[1,6.6,6.72],[2,6.2,32.42]],"batl":[[0,8,26.75],[1,8.2,5.04],[2,8.2,0]],"ltp":0.0,"tv":0.0,"id":13117449},{"batb":[[0,7.6,5.88],[1,6.6,28.56],[2,1.01,0.51]],"batl":[[0,9.6,4.2],[1,12.5,27.85],[2,12.5,0]],"ltp":5.9,"tv":4.0,"id":13117448},{"batb":[[0,4.6,32.89],[1,4.5,11.76],[2,4.4,49.57]],"batl":[[1,5.8,25.26],[2,5.8,0]],"ltp":4.9,"tv":93.16,"id":13117392},{"batb":[[0,1.78,53.77],[1,1.67,53.82],[2,1.01,0.51]],"batl":[[0,1.95,42.01],[1,2,71.96],[2,2,0]],"ltp":2.0,"tv":1223.18,"id":13117391}]}]}
{"op":"mcm","clk":"1006325004","pt":1580595253543,"mc":[{"id":"1.168175449","rc":[{"batb":[[1,6.2,32.42],[2,1.01,0.51]],"batl":[[1,8.2,0]],"ltp":0.0,"tv":0.0,"id":13117449},{"batb":[[0,6.6,28.56],[1,1.01,0.51],[2,1.01,0]],"batl":[[0,12.5,27.85],[1,12.5,0]],"ltp":5.9,"tv":4.0,"id":13117448},{"batb":[[1,1.01,0.51],[2,4.4,0]],"batl":[[0,5.8,25.26],[1,5.8,0]],"ltp":4.9,"tv":93.16,"id":13117392},{"batb":[[0,1.67,53.82],[1,1.01,0.51],[2,1.01,0]],"batl":[[0,2,71.96],[1,2,0]],"ltp":2.0,"tv":1223.18,"id":13117391}]}]}
{"op":"mcm","clk":"1006325379","pt":1580595256393,"mc":[{"id":"1.168175449","rc":[{"batb":[[0,7,46.34],[1,6.8,64.79],[2,6.2,32.42]],"ltp":0.0,"tv":0.0,"id":13117449},{"batb":[[0,8.4,63.54],[1,8.2,42.92],[2,6.6,28.56]],"ltp":5.9,"tv":4.0,"id":13117448},{"batb":[[0,4.6,81.9],[1,4.5,81.58],[2,1.01,0.51]],"ltp":4.9,"tv":93.16,"id":13117392},{"batb":[[0,1.81,175.91],[1,1.79,189.58],[2,1.67,53.82]],"ltp":2.0,"tv":1223.18,"id":13117391}]}]}
{"op":"mcm","clk":"1006326209","pt":1580595263325,"mc":[{"id":"1.168175449","rc":[{"batb":[[0,6.8,37.67],[1,6.2,32.42],[2,1.01,0.51]],"ltp":0.0,"tv":0.0,"id":13117449},{"batb":[[0,6.6,28.56],[1,1.01,0.51],[2,6.6,0]],"ltp":5.9,"tv":4.0,"id":13117448},{"batb":[[0,4.6,32.89],[1,1.01,0.51],[2,1.01,0]],"ltp":4.9,"tv":93.16,"id":13117392},{"batb":[[0,1.67,53.82],[1,1.01,0.51],[2,1.67,0]],"ltp":2.0,"tv":1223.18,"id":13117391}]}]}
{"op":"mcm","clk":"1006326585","pt":1580595266746,"mc":[{"id":"1.168175449","rc":[{"batb":[[1,6.6,69.36],[2,6.2,32.42]],"ltp":0.0,"tv":0.0,"id":13117449},{"batb":[[0,7,43.12],[1,6.8,64.94],[2,6.6,28.56]],"ltp":5.9,"tv":4.0,"id":13117448},{"batb":[[1,4.4,49.57],[2,4.3,90.59]],"ltp":4.9,"tv":93.16,"id":13117392},{"batb":[[0,1.71,131.94],[1,1.69,230.29],[2,1.67,53.82]],"ltp":2.0,"tv":1223.18,"id":13117391}]}]}
{"op":"mcm","clk":"1006327091","pt":1580595271331,"mc":[{"id":"1.168175449","rc":[{"batb":[[0,1.67,53.82],[1,1.01,0.51],[2,1.67,0]],"ltp":2.0,"tv":1223.18,"id":13117391}]}]}
{"op":"mcm","clk":"1006327387","pt":1580595273542,"mc":[{"id":"1.168175449","rc":[{"batb":[[1,6.6,76.08]],"batl":[[0,8,32.63]],"ltp":0.0,"tv":0.0,"id":13117449},{"batb":[[1,6.8,71.66]],"batl":[[0,8.6,5.04],[1,12.5,27.85]],"ltp":5.9,"tv":4.0,"id":13117448},{"batb":[[2,4.3,103.19]],"batl":[[0,5.1,10.08],[1,5.8,25.26]],"ltp":4.9,"tv":93.16,"id":13117392},{"batb":[[0,1.95,146.82],[1,1.93,148.86],[2,1.85,48.73]],"batl":[[1,2.04,40.33]],"ltp":2.0,"tv":1223.18,"id":13117391}]}]}
{"op":"mcm","clk":"1006327469","pt":1580595274328,"mc":[{"id":"1.168175449","rc":[{"batb":[[1,6.6,69.36],[2,6.4,7.56]],"batl":[[0,7.4,30.37],[1,7.6,28.64],[2,8,5.88]],"ltp":0.0,"tv":0.0,"id":13117449},{"batl":[[0,8,26.91],[1,8.4,5.04],[2,10,16.68]],"ltp":5.9,"tv":4.0,"id":13117448},{"batb":[[1,4.4,85.84]],"batl":[[1,5.3,31.39],[2,5.6,27.77]],"ltp":4.9,"tv":93.16,"id":13117392},{"batb":[[2,1.91,34.93]],"batl":[[2,2.14,55.94]],"ltp":2.0,"tv":1223.18,"id":13117391}]}]}
{"op":"mcm","clk":"1006328037","pt":1580595279520,"mc":[{"id":"1.168175449","rc":[{"batb":[[0,6.6,69.36],[1,6.4,7.56],[2,6.2,32.42]],"ltp":0.0,"tv":0.0,"id":13117449},{"batb":[[0,6.8,71.66],[1,6.6,28.56],[2,5.9,38.71]],"ltp":5.9,"tv":4.0,"id":13117448},{"batb":[[0,1.91,34.93],[1,1.85,48.73],[2,1.76,45.01]],"ltp":2.0,"tv":1223.18,"id":13117391}]}]}
{"op":"mcm","clk":"1006328356","pt":1580595282462,"mc":[{"id":"1.168175449","rc":[{"batb":[[0,6.6,86.27],[1,6.4,79.89]],"ltp":0.0,"tv":0.0,"id":13117449},{"batb":[[0,6.8,94.96],[1,6.6,96.17]],"ltp":5.9,"tv":4.0,"id":13117448},{"batb":[[0,1.96,122.91],[1,1.94,146.52],[2,1.91,34.93]],"ltp":2.0,"tv":1223.18,"id":13117391}]}]}
{"op":"mcm","clk":"1006329246","pt":1580595290450,"mc":[{"id":"1.168175449","rc":[{"trd":[[1.96,5]],"batb":[[0,1.96,120.41]],"ltp":1.96,"tv":1228.18,"id":13117391}],"tv":1325.35}]}
{"op":"mcm","clk":"1006329659","pt":1580595294288,"mc":[{"id":"1.168175449","rc":[{"batb":[[0,6.4,79.89],[1,6.2,32.42],[2,1.01,0.51]],"batl":[[0,7.6,28.64],[1,8,5.88],[2,8,0]],"ltp":0.0,"tv":0.0,"id":13117449},{"batb":[[0,6.8,6.72],[1,5.9,38.71],[2,1.01,0.51]],"batl":[[0,8.4,5.04],[1,10,16.68],[2,10,0]],"ltp":5.9,"tv":4.0,"id":13117448},{"batb":[[0,4.4,36.27],[1,4.3,12.6],[2,1.01,0.51]],"batl":[[1,5.6,27.77],[2,5.6,0]],"ltp":4.9,"tv":93.16,"id":13117392},{"batb":[[0,1.85,48.73],[1,1.76,45.01],[2,1.01,0.51]],"batl":[[0,2,37.58]],"ltp":1.96,"tv":1228.18,"id":13117391}]}]}
{"op":"mcm","clk":"1006329702","pt":1580595294664,"mc":[{"id":"1.168175449","rc":[{"batb":[[0,6.4,72.33]],"batl":[[1,8,0]],"ltp":0.0,"tv":0.0,"id":13117449},{"batb":[[0,5.9,38.71],[1,1.01,0.51],[2,1.01,0]],"batl":[[0,10,16.68],[1,10,0]],"ltp":5.9,"tv":4.0,"id":13117448},{"batb":[[1,1.01,0.51],[2,1.01,0]],"batl":[[0,5.6,27.77],[1,5.6,0]],"ltp":4.9,"tv":93.16,"id":13117392},{"batb":[[0,1.76,45.01],[1,1.01,0.51],[2,1.01,0]],"batl":[[1,2.14,55.94],[2,2.14,0]],"ltp":1.96,"tv":1228.18,"id":13117391}]}]}
{"op":"mcm","clk":"1006329967","pt":1580595297089,"mc":[{"id":"1.168175449","rc":[{"batb":[[0,6.4,105.06],[1,6.2,109.51]],"ltp":0.0,"tv":0.0,"id":13117449},{"batb":[[0,6,86.93],[1,5.9,82.79],[2,1.01,0.51]],"ltp":5.9,"tv":4.0,"id":13117448},{"batb":[[1,4.2,124.84],[2,4.1,100.15]],"ltp":4.9,"tv":93.16,"id":13117392},{"batb":[[0,1.81,116.88],[1,1.79,189.47],[2,1.76,45.01]],"ltp":1.96,"tv":1228.18,"id":13117391}]}]}
{"op":"mcm","clk":"1006330619","pt":1580595302458,"mc":[{"id":"1.168175449","rc":[{"batb":[[0,6.2,32.42],[1,1.01,0.51],[2,1.01,0]],"ltp":0.0,"tv":0.0,"id":13117449},{"batb":[[0,5.9,38.71],[1,1.01,0.51],[2,1.01,0]],"ltp":5.9,"tv":4.0,"id":13117448},{"batb":[[1,1.01,0.51],[2,4.1,0]],"ltp":4.9,"tv":93.16,"id":13117392}]}]}
{"op":"mcm","clk":"1006330949","pt":1580595305385,"mc":[{"id":"1.168175449","rc":[{"batb":[[0,7,29.73],[1,6.8,64.7],[2,6.4,30.45]],"batl":[[1,8,26.2]],"ltp":0.0,"tv":0.0,"id":13117449},{"batb":[[0,8.6,45.51],[1,8.4,40.79],[2,8.2,17.47]],"batl":[[1,14.5,21.17]],"ltp":5.9,"tv":4.0,"id":13117448},{"batb":[[0,4.9,28.95],[1,4.7,32.34],[2,4.6,72.86]],"batl":[[1,6,23.53]],"ltp":4.9,"tv":93.16,"id":13117392},{"batl":[[0,1.84,44.22],[1,1.98,35.49],[2,2,37.58]],"ltp":1.96,"tv":1228.18,"id":13117391}]}]}
{"op":"mcm","clk":"1006331025","pt":1580595305963,"mc":[{"id":"1.168175449","rc":[{"batb":[[2,6.6,6.72]],"batl":[[2,8.2,5.04]],"ltp":0.0,"tv":0.0,"id":13117449},{"batl":[[1,10.5,4.2],[2,14.5,21.17]],"ltp":5.9,"tv":4.0,"id":13117448},{"batl":[[0,5.4,9.24],[1,5.6,27.77],[2,6,23.53]],"ltp":4.9,"tv":93.16,"id":13117392},{"batl":[[1,1.91,42.01],[2,1.98,35.49]],"ltp":1.96,"tv":1228.18,"id":13117391}]}]}
{"op":"mcm","clk":"1006332877","pt":1580595322227,"mc":[{"id":"1.168175449","rc":[{"batb":[[0,6.6,6.72],[1,6.2,32.26],[2,1.01,0.51]],"batl":[[0,8,26.2],[1,8.2,5.04],[2,8.2,0]],"ltp":0.0,"tv":0.0,"id":13117449},{"batb":[[0,8,5.88],[1,6.8,26.83],[2,1.01,0.51]],"batl":[[0,10.5,4.2],[1,14.5,21.17],[2,14.5,0]],"ltp":5.9,"tv":4.0,"id":13117448},{"batb":[[0,4.7,32.34],[1,4.5,11.76],[2,1.01,0.51]],"batl":[[1,6,23.53],[2,6,0]],"ltp":4.9,"tv":93.16,"id":13117392},{"batb":[[0,1.74,56.29],[1,1.62,59.96],[2,1.01,0.51]],"batl":[[0,1.91,42.01],[1,1.98,35.49],[2,2,37.58]],"ltp":1.96,"tv":1228.18,"id":13117391}]}]}
{"op":"mcm","clk":"1006332942","pt":1580595322704,"mc":[{"id":"1.168175449","rc":[{"batb":[[0,6.2,32.26],[1,1.01,0.51],[2,1.01,0]],"batl":[[1,8.2,0]],"ltp":0.0,"tv":0.0,"id":13117449},{"batb":[[0,6.8,26.83],[1,1.01,0.51],[2,1.01,0]],"batl":[[0,14.5,21.17],[1,14.5,0]],"ltp":5.9,"tv":4.0,"id":13117448},{"batb":[[1,1.01,0.51],[2,1.01,0]],"batl":[[0,6,23.53],[1,6,0]],"ltp":4.9,"tv":93.16,"id":13117392},{"batb":[[0,1.62,59.96],[1,1.01,0.51],[2,1.01,0]],"batl":[[0,1.98,35.49],[1,2,37.58],[2,2,0]],"ltp":1.96,"tv":1228.18,"id":13117391}]}]}
{"op":"mcm","clk":"1006333247","pt":1580595325350,"mc":[{"id":"1.168175449","rc":[{"batb":[[0,6.6,99.7],[1,6.4,71.98],[2,1.01,0.51]],"batl":[[0,8,25.57]],"ltp":0.0,"tv":0.0,"id":13117449},{"batb":[[0,7,112.21],[1,6.8,63.37],[2,1.01,0.51]],"batl":[[0,14.5,20.69]],"ltp":5.9,"tv":4.0,"id":13117448},{"batb":[[1,4.4,83.79],[2,4.3,90.26]],"ltp":4.9,"tv":93.16,"id":13117392},{"batb":[[0,1.65,225.04],[1,1.64,129.14],[2,1.61,60.66]],"batl":[[0,1.97,35.96]],"ltp":1.96,"tv":1228.18,"id":13117391}]}]}
{"op":"mcm","clk":"1006334537","pt":1580595337447,"mc":[{"id":"1.168175449","rc":[{"batb":[[0,1.61,60.66],[1,1.01,0.51],[2,1.61,0]],"ltp":1.96,"tv":1228.18,"id":13117391}]}]}
{"op":"mcm","clk":"1006334777","pt":1580595339545,"mc":[{"id":"1.168175449","rc":[{"batb":[[0,1.93,178.87],[1,1.91,153.83],[2,1.61,60.66]],"ltp":1.96,"tv":1228.18,"id":13117391}]}]}
{"op":"mcm","clk":"1006334879","pt":1580595340491,"mc":[{"id":"1.168175449","rc":[{"batb":[[0,6.6,106.42],[1,6.4,103.53],[2,6.2,33.83]],"batl":[[0,7.6,29.66],[1,7.8,27.15],[2,8,25.57]],"ltp":0.0,"tv":0.0,"id":13117449},{"batb":[[0,7,118.93],[2,5.8,39.1]],"batl":[[0,8.2,24.78],[1,8.8,5.04],[2,11.5,32.42]],"ltp":5.9,"tv":4.0,"id":13117448},{"batb":[[1,4.4,120.46],[2,4.3,102.86]],"batl":[[0,5.1,10.08],[1,5.3,31.16],[2,5.7,26.52]],"ltp":4.9,"tv":93.16,"id":13117392},{"batb":[[2,1.89,36.51]],"batl":[[2,2.02,41.17]],"ltp":1.96,"tv":1228.18,"id":13117391}]}]}
{"op":"mcm","clk":"1006334892","pt":1580595340646,"mc":[{"id":"1.168175449","rc":[{"batl":[[2,8.2,5.04]],"ltp":0.0,"tv":0.0,"id":13117449}]}]}
{"op":"mcm","clk":"1006337042","pt":1580595359551,"mc":[{"id":"1.168175449","rc":[{"batb":[[0,6.6,75.76],[1,6.4,31.55]],"ltp":0.0,"tv":0.0,"id":13117449},{"trd":[[1.93,183.16]],"batb":[[0,1.93,87.29]],"ltp":1.93,"tv":1411.34,"id":13117391}],"tv":1508.51}]}
{"op":"mcm","clk":"1006337379","pt":1580595362334,"mc":[{"id":"1.168175449","rc":[{"batb":[[0,6.8,32.71],[1,6.6,75.76],[2,6.4,31.55]],"ltp":0.0,"tv":0.0,"id":13117449},{"batb":[[0,1.93,161.21]],"ltp":1.93,"tv":1411.34,"id":13117391}]}]}
{"op":"mcm","clk":"1006337885","pt":1580595366358,"mc":[{"id":"1.168175449","rc":[{"batb":[[0,6.6,43.14],[1,6.2,33.83],[2,1.01,0.51]],"batl":[[0,7.8,27.15],[1,8.2,5.04],[2,8.2,0]],"ltp":0.0,"tv":0.0,"id":13117449},{"batb":[[0,7,6.72],[1,5.8,39.1],[2,1.01,0.51]],"batl":[[0,8.8,5.04],[1,11.5,32.42],[2,11.5,0]],"ltp":5.9,"tv":4.0,"id":13117448},{"batb":[[0,4.4,36.67],[1,4.3,12.6],[2,1.01,0.51]],"batl":[[1,5.7,26.52],[2,5.7,0]],"ltp":4.9,"tv":93.16,"id":13117392},{"batb":[[0,1.83,50.41],[1,1.71,50.12],[2,1.01,0.51]],"batl":[[0,2,37.58],[1,2.02,41.17],[2,2.14,55.79]],"ltp":1.93,"tv":1411.34,"id":13117391}]}]}
{"op":"mcm","clk":"1006337964","pt":1580595366942,"mc":[{"id":"1.168175449","rc":[{"batb":[[0,6.6,36.42]],"batl":[[1,8.2,0]],"ltp":0.0,"tv":0.0,"id":13117449},{"batb":[[0,5.8,39.1],[1,1.01,0.51],[2,1.01,0]],"batl":[[0,11.5,32.42],[1,11.5,0]],"ltp":5.9,"tv":4.0,"id":13117448},{"batb":[[1,1.01,0.51],[2,1.01,0]],"batl":[[0,5.7,26.52],[1,5.7,0]],"ltp":4.9,"tv":93.16,"id":13117392},{"batb":[[0,1.71,50.12],[1,1.01,0.51],[2,1.01,0]],"batl":[[1,2.14,55.79],[2,2.14,0]],"ltp":1.93,"tv":1411.34,"id":13117391}]}]}
{"op":"mcm","clk":"1006338213","pt":1580595368974,"mc":[{"id":"1.168175449","rc":[{"batb":[[1,6.4,73.73],[2,6.2,33.83]],"ltp":0.0,"tv":0.0,"id":13117449},{"batb":[[0,6,60.13],[1,5.9,44.51],[2,5.8,39.1]],"ltp":5.9,"tv":4.0,"id":13117448},{"batb":[[1,4.2,109.47],[2,4.1,100.52]],"ltp":4.9,"tv":93.16,"id":13117392},{"batb":[[0,1.75,132.2],[1,1.73,212.49],[2,1.71,50.12]],"ltp":1.93,"tv":1411.34,"id":13117391}]}]}
{"op":"mcm","clk":"1006339368","pt":1580595378563,"mc":[{"id":"1.168175449","rc":[{"batb":[[0,6.2,33.83],[1,1.01,0.51],[2,6.2,0]],"ltp":0.0,"tv":0.0,"id":13117449},{"batb":[[0,5.8,39.1],[1,1.01,0.51],[2,5.8,0]],"ltp":5.9,"tv":4.0,"id":13117448},{"batb":[[1,1.01,0.51],[2,4.1,0]],"ltp":4.9,"tv":93.16,"id":13117392}]}]}
{"op":"mcm","clk":"1006339752","pt":1580595381559,"mc":[{"id":"1.168175449","rc":[{"batb":[[0,7,59.61],[1,6.8,64.03],[2,6.6,28.8]],"batl":[[1,8.2,25.1]],"ltp":0.0,"tv":0.0,"id":13117449},{"batb":[[0,9.6,49.65],[1,9.4,32.02],[2,9,14.4]],"batl":[[1,21,10.46]],"ltp":5.9,"tv":4.0,"id":13117448},{"batb":[[0,5,27.62],[1,4.7,106],[2,4.6,77.48]],"batl":[[1,6.4,21.48]],"ltp":4.9,"tv":93.16,"id":13117392},{"batl":[[0,1.78,49.18],[1,1.95,37.14],[2,2,37.58]],"ltp":1.93,"tv":1411.34,"id":13117391}]}]}
{"op":"mcm","clk":"1006339859","pt":1580595382346,"mc":[{"id":"1.168175449","rc":[{"batb":[[1,6.8,70.75]],"batl":[[2,8.4,5.04]],"ltp":0.0,"tv":0.0,"id":13117449},{"batb":[[2,9,19.44]],"batl":[[0,11.5,35.78]],"ltp":5.9,"tv":4.0,"id":13117448},{"batb":[[2,4.6,88.4]],"batl":[[0,5.5,9.24],[1,5.7,26.52],[2,6.4,21.48]],"ltp":4.9,"tv":93.16,"id":13117392},{"batl":[[1,1.85,42.01],[2,1.95,37.14]],"ltp":1.93,"tv":1411.34,"id":13117391}]}]}
{"op":"mcm","clk":"1006343006","pt":1580595407003,"mc":[{"id":"1.168175449","rc":[{"batb":[[0,6.8,50.07],[1,6.4,30.45],[2,1.01,0.51]],"batl":[[0,8.2,25.1],[1,8.4,5.04],[2,8.4,0]],"ltp":0.0,"tv":0.0,"id":13117449},{"batb":[[0,9,5.04],[1,7,25.02],[2,1.01,0.51]],"batl":[[0,11.5,3.36]],"ltp":5.9,"tv":4.0,"id":13117448},{"batb":[[0,4.7,32.57],[1,4.6,10.92],[2,1.01,0.51]],"batl":[[1,6.4,21.48],[2,6.4,0]],"ltp":4.9,"tv":93.16,"id":13117392},{"batb":[[0,1.69,60.49],[1,1.53,73.02],[2,1.01,0.51]],"batl":[[0,1.85,42.01],[1,1.95,37.14],[2,2,37.58]],"ltp":1.93,"tv":1411.34,"id":13117391}]}]}
{"op":"mcm","clk":"1006343311","pt":1580595409000,"mc":[{"id":"1.168175449","rc":[{"batb":[[0,6.8,43.35]],"batl":[[1,8.4,0]],"ltp":0.0,"tv":0.0,"id":13117449},{"batb":[[0,7,25.02],[1,1.01,0.51],[2,1.01,0]],"batl":[[0,21,10.46],[1,21,0]],"ltp":5.9,"tv":4.0,"id":13117448},{"batb":[[1,1.01,0.51],[2,1.01,0]],"batl":[[0,6.4,21.48],[1,6.4,0]],"ltp":4.9,"tv":93.16,"id":13117392},{"batb":[[0,1.53,73.02],[1,1.01,0.51],[2,1.01,0]],"batl":[[0,1.95,37.14],[1,2,37.58],[2,2,0]],"ltp":1.93,"tv":1411.34,"id":13117391}]}]}
{"op":"mcm","clk":"1006343460","pt":1580595410108,"mc":[{"id":"1.168175449","rc":[{"batb":[[1,6.6,68.77],[2,6.4,30.45]],"ltp":0.0,"tv":0.0,"id":13117449},{"batb":[[0,7.2,49.28],[1,7,85.45],[2,1.01,0.51]],"ltp":5.9,"tv":4.0,"id":13117448},{"batb":[[1,4.4,97.49],[2,4.3,90.12]],"ltp":4.9,"tv":93.16,"id":13117392},{"batb":[[0,1.55,235.96],[1,1.54,163.61],[2,1.53,73.02]],"ltp":1.93,"tv":1411.34,"id":13117391}]}]}
{"op":"mcm","clk":"1006344032","pt":1580595413988,"mc":[{"id":"1.168175449","rc":[{"batb":[[1,6.4,30.45],[2,1.01,0.51]],"ltp":0.0,"tv":0.0,"id":13117449},{"batb":[[0,7,25.02],[1,1.01,0.51],[2,1.01,0]],"ltp":5.9,"tv":4.0,"id":13117448},{"batb":[[1,1.01,0.51],[2,4.3,0]],"ltp":4.9,"tv":93.16,"id":13117392},{"batb":[[0,1.53,73.02],[1,1.01,0.51],[2,1.53,0]],"ltp":1.93,"tv":1411.34,"id":13117391}]}]}
{"op":"mcm","clk":"1006344428","pt":1580595416726,"mc":[{"id":"1.168175449","rc":[{"batb":[[0,7,82.06],[1,6.8,63.46],[2,6.4,30.45]],"ltp":0.0,"tv":0.0,"id":13117449},{"batb":[[0,10.5,58.86],[1,10,67.64],[2,7,25.02]],"ltp":5.9,"tv":4.0,"id":13117448},{"batb":[[0,4.8,59.53],[1,4.7,106.55],[2,1.01,0.51]],"ltp":4.9,"tv":93.16,"id":13117392},{"batb":[[0,1.7,218.78],[1,1.68,235.56],[2,1.53,73.02]],"ltp":1.93,"tv":1411.34,"id":13117391}]}]}
{"op":"mcm","clk":"1006345350","pt":1580595423717,"mc":[{"id":"1.168175449","rc":[{"batb":[[0,6.8,43.35],[1,6.4,30.45],[2,1.01,0.51]],"ltp":0.0,"tv":0.0,"id":13117449},{"batb":[[0,7,25.02],[1,1.01,0.51],[2,7,0]],"ltp":5.9,"tv":4.0,"id":13117448},{"batb":[[0,4.7,32.57],[1,1.01,0.51],[2,1.01,0]],"ltp":4.9,"tv":93.16,"id":13117392},{"batb":[[0,1.53,73.02],[1,1.01,0.51],[2,1.53,0]],"ltp":1.93,"tv":1411.34,"id":13117391}]}]}
{"op":"mcm","clk":"1006345877","pt":1580595427345,"mc":[{"id":"1.168175449","rc":[{"batb":[[1,6.6,68.77],[2,6.4,30.45]],"ltp":0.0,"tv":0.0,"id":13117449},{"batb":[[0,7.2,49.28],[1,7,85.45],[2,1.01,0.51]],"ltp":5.9,"tv":4.0,"id":13117448},{"batb":[[1,4.4,97.49],[2,4.3,90.12]],"ltp":4.9,"tv":93.16,"id":13117392},{"batb":[[0,1.55,235.96],[1,1.54,163.61],[2,1.53,73.02]],"ltp":1.93,"tv":1411.34,"id":13117391}]}]}
{"op":"mcm","clk":"1006346723","pt":1580595433542,"mc":[{"id":"1.168175449","rc":[{"batb":[[0,1.53,73.02],[1,1.01,0.51],[2,1.53,0]],"ltp":1.93,"tv":1411.34,"id":13117391}]}]}
{"op":"mcm","clk":"1006347125","pt":1580595436518,"mc":[{"id":"1.168175449","rc":[{"batb":[[0,1.92,165.55],[1,1.9,156.39],[2,1.53,73.02]],"ltp":1.93,"tv":1411.34,"id":13117391}]}]}
{"op":"mcm","clk":"1006347249","pt":1580595437559,"mc":[{"id":"1.168175449","rc":[{"batl":[[0,7.6,28.64],[1,8,26.83]],"ltp":0.0,"tv":0.0,"id":13117449},{"batb":[[2,5.9,37.37]],"batl":[[0,8.4,23.6],[1,12,30.76]],"ltp":5.9,"tv":4.0,"id":13117448},{"batb":[[1,4.4,134]],"batl":[[0,5.3,31.08],[1,5.7,26.44]],"ltp":4.9,"tv":93.16,"id":13117392},{"batb":[[2,1.87,37.77]],"batl":[[2,2.12,57.6]],"ltp":1.93,"tv":1411.34,"id":13117391}]}]}
{"op":"mcm","clk":"1006347380","pt":1580595438554,"mc":[{"id":"1.168175449","rc":[{"batb":[[1,6.6,75.49]],"batl":[[2,8.2,5.04]],"ltp":0.0,"tv":0.0,"id":13117449},{"batb":[[2,4.3,102.72]],"batl":[[0,5.1,10.08],[1,5.3,31.08],[2,5.7,26.44]],"ltp":4.9,"tv":93.16,"id":13117392}]}]}
{"op":"mcm","clk":"1006347600","pt":1580595440533,"mc":[{"id":"1.168175449","rc":[{"batb":[[1,7,92.17]],"ltp":5.9,"tv":4.0,"id":13117448}]}]}
{"op":"mcm","clk":"1006347703","pt":1580595441372,"mc":[{"id":"1.168175449","rc":[{"batl":[[1,8.8,5.04],[2,12,30.76]],"ltp":5.9,"tv":4.0,"id":13117448},{"batl":[[1,2,79.59]],"ltp":1.93,"tv":1411.34,"id":13117391}]}]}
{"op":"mcm","clk":"1006349446","pt":1580595456260,"mc":[{"id":"1.168175449","rc":[{"batb":[[0,6.6,48.99],[1,6.2,32.89],[2,1.01,0.51]],"batl":[[0,8,26.83],[1,8.2,5.04],[2,8.2,0]],"ltp":0.0,"tv":0.0,"id":13117449},{"batb":[[0,7,6.72],[1,5.9,37.37],[2,1.01,0.51]],"batl":[[0,8.8,5.04],[1,12,30.76],[2,12,0]],"ltp":5.9,"tv":4.0,"id":13117448},{"batb":[[0,4.4,36.51],[1,4.3,12.6],[2,1.01,0.51]],"batl":[[1,5.7,26.44],[2,5.7,0]],"ltp":4.9,"tv":93.16,"id":13117392},{"batb":[[0,1.82,50.41],[1,1.7,51.14],[2,1.01,0.51]],"batl":[[0,2,79.59],[1,2.12,57.6],[2,2.12,0]],"ltp":1.93,"tv":1411.34,"id":13117391}]}]}
{"op":"mcm","clk":"1006349586","pt":1580595457460,"mc":[{"id":"1.168175449","rc":[{"batb":[[0,6.6,42.27]],"batl":[[1,8.2,0]],"ltp":0.0,"tv":0.0,"id":13117449},{"batb":[[0,5.9,37.37],[1,1.01,0.51],[2,1.01,0]],"batl":[[0,12,30.76],[1,12,0]],"ltp":5.9,"tv":4.0,"id":13117448},{"batb":[[1,1.01,0.51],[2,1.01,0]],"batl":[[0,5.7,26.44],[1,5.7,0]],"ltp":4.9,"tv":93.16,"id":13117392},{"batb":[[0,1.7,51.14],[1,1.01,0.51],[2,1.01,0]],"batl":[[0,2,37.58]],"ltp":1.93,"tv":1411.34,"id":13117391}]}]}
{"op":"mcm","clk":"1006349828","pt":1580595459537,"mc":[{"id":"1.168175449","rc":[{"batb":[[0,6.2,32.89],[1,1.01,0.51],[2,1.01,0]],"ltp":0.0,"tv":0.0,"id":13117449},{"batb":[[0,1.74,170.1],[1,1.72,216.88],[2,1.7,51.14]],"ltp":1.93,"tv":1411.34,"id":13117391}]}]}
{"op":"mcm","clk":"1006350190","pt":1580595462472,"mc":[{"id":"1.168175449","rc":[{"batb":[[0,7,67.31],[1,6.8,63.75],[2,6.2,32.89]],"ltp":0.0,"tv":0.0,"id":13117449},{"batb":[[0,9.8,32.26],[1,9.6,30.89],[2,5.9,37.37]],"ltp":5.9,"tv":4.0,"id":13117448},{"batb":[[0,4.7,85.34],[1,4.6,77.33],[2,4.4,36.51]],"ltp":4.9,"tv":93.16,"id":13117392}]}]}
{"op":"mcm","clk":"1006350311","pt":1580595463476,"mc":[{"id":"1.168175449","rc":[{"batb":[[2,6.6,28.4]],"batl":[[1,8.2,24.71]],"ltp":0.0,"tv":0.0,"id":13117449},{"batb":[[2,9.2,34.07]],"batl":[[1,21,10.31]],"ltp":5.9,"tv":4.0,"id":13117448},{"batb":[[0,5,27.62],[1,4.7,117.44],[2,4.6,77.33]],"batl":[[1,6.4,21.32]],"ltp":4.9,"tv":93.16,"id":13117392},{"batl":[[0,1.77,50.12],[1,1.94,37.45],[2,2,37.58]],"ltp":1.93,"tv":1411.34,"id":13117391}]}]}
{"op":"mcm","clk":"1006350430","pt":1580595464370,"mc":[{"id":"1.168175449","rc":[{"batb":[[1,6.8,70.47]],"ltp":0.0,"tv":0.0,"id":13117449},{"batl":[[0,11.5,3.36],[1,12,30.76],[2,21,10.31]],"ltp":5.9,"tv":4.0,"id":13117448},{"batb":[[2,4.6,88.25]],"batl":[[0,5.5,9.24],[1,5.7,26.44],[2,6.4,21.32]],"ltp":4.9,"tv":93.16,"id":13117392}]}]}
{"op":"mcm","clk":"1006350543","pt":1580595465260,"mc":[{"id":"1.168175449","rc":[{"batl":[[2,8.4,5.04]],"ltp":0.0,"tv":0.0,"id":13117449},{"batl":[[1,1.84,42.01],[2,1.94,37.45]],"ltp":1.93,"tv":1411.34,"id":13117391}]}]}
{"op":"mcm","clk":"1006352123","pt":1580595478492,"mc":[{"id":"1.168175449","rc":[{"trd":[[1.74,5]],"batb":[[0,1.74,114.86]],"ltp":1.74,"tv":1416.34,"id":13117391}],"tv":1513.51}]}
{"op":"mcm","clk":"1006352424","pt":1580595481071,"mc":[{"id":"1.168175449","rc":[{"batb":[[0,7,89.28]],"ltp":0.0,"tv":0.0,"id":13117449},{"batb":[[0,9.8,47.3]],"ltp":5.9,"tv":4.0,"id":13117448}]}]}
{"op":"mcm","clk":"1006352721","pt":1580595483390,"mc":[{"id":"1.168175449","rc":[{"batb":[[0,6.8,70.47],[1,6.4,31],[2,1.01,0.51]],"batl":[[0,8.2,24.71],[1,8.4,5.04],[2,8.4,0]],"ltp":0.0,"tv":0.0,"id":13117449},{"batb":[[0,9,5.04],[1,7.2,24.39],[2,1.01,0.51]],"batl":[[1,21,10.31],[2,21,0]],"ltp":5.9,"tv":4.0,"id":13117448},{"batb":[[0,4.7,32.1],[1,4.6,10.92],[2,1.01,0.51]],"batl":[[1,6.4,21.32],[2,6.4,0]],"ltp":4.9,"tv":93.16,"id":13117392},{"batb":[[0,1.69,60.49],[1,1.53,73.96],[2,1.01,0.51]],"batl":[[0,1.84,42.01],[1,1.94,37.45],[2,2,37.58]],"ltp":1.74,"tv":1416.34,"id":13117391}]}]}
{"op":"mcm","clk":"1006352890","pt":1580595484805,"mc":[{"id":"1.168175449","rc":[{"batb":[[0,6.8,63.75]],"batl":[[1,8.4,0]],"ltp":0.0,"tv":0.0,"id":13117449},{"batb":[[0,7.2,24.39],[1,1.01,0.51],[2,1.01,0]],"batl":[[0,21,10.31],[1,21,0]],"ltp":5.9,"tv":4.0,"id":13117448},{"batb":[[1,1.01,0.51],[2,1.01,0]],"batl":[[0,6.4,21.32],[1,6.4,0]],"ltp":4.9,"tv":93.16,"id":13117392},{"batb":[[0,1.53,73.96],[1,1.01,0.51],[2,1.01,0]],"batl":[[0,1.94,37.45],[1,2,37.58],[2,2,0]],"ltp":1.74,"tv":1416.34,"id":13117391}]}]}
{"op":"mcm","clk":"1006353114","pt":1580595486567,"mc":[{"id":"1.168175449","rc":[{"batb":[[1,6.6,68.54],[2,6.4,31]],"ltp":0.0,"tv":0.0,"id":13117449},{"batb":[[0,7.4,28.82],[1,7.2,82.14],[2,1.01,0.51]],"ltp":5.9,"tv":4.0,"id":13117448},{"batb":[[1,4.4,95.05],[2,4.3,90.02]],"ltp":4.9,"tv":93.16,"id":13117392}]}]}
{"op":"mcm","clk":"1006353614","pt":1580595490511,"mc":[{"id":"1.168175449","rc":[{"batl":[[0,7.6,29.11],[1,8,26.52]],"ltp":0.0,"tv":0.0,"id":13117449},{"batb":[[2,6,36.74]],"batl":[[0,8.6,23.05],[1,12,30.37]],"ltp":5.9,"tv":4.0,"id":13117448},{"batb":[[1,4.5,36.19],[2,4.4,95.05]],"batl":[[0,5.1,10.08],[1,5.3,30.76],[2,5.8,25.57]],"ltp":4.9,"tv":93.16,"id":13117392},{"batb":[[0,1.91,131.82],[1,1.89,159.1],[2,1.86,38.08]],"batl":[[2,2.12,58.38]],"ltp":1.74,"tv":1416.34,"id":13117391}]}]}
{"op":"mcm","clk":"1006353856","pt":1580595492501,"mc":[{"id":"1.168175449","rc":[{"batb":[[1,6.6,75.26]],"batl":[[2,8.2,5.04]],"ltp":0.0,"tv":0.0,"id":13117449},{"batb":[[1,7.2,88.86]],"batl":[[1,9,5.04],[2,12,30.37]],"ltp":5.9,"tv":4.0,"id":13117448},{"batl":[[1,1.99,42.01],[2,2,37.58]],"ltp":1.74,"tv":1416.34,"id":13117391}]}]}
{"op":"mcm","clk":"1006354296","pt":1580595496407,"mc":[{"id":"1.168175449","rc":[{"batb":[[0,6.8,74.05]],"ltp":0.0,"tv":0.0,"id":13117449}]}]}
{"op":"mcm","clk":"1006355318","pt":1580595505333,"mc":[{"id":"1.168175449","rc":[{"batb":[[0,6.6,75.26],[1,6.2,32.89],[2,1.01,0.51]],"batl":[[0,8,26.52],[1,8.2,5.04],[2,8.2,0]],"ltp":0.0,"tv":0.0,"id":13117449},{"batb":[[0,7.2,6.72],[1,6,36.74],[2,1.01,0.51]],"batl":[[0,9,5.04],[1,12,30.37],[2,12,0]],"ltp":5.9,"tv":4.0,"id":13117448},{"batb":[[0,4.5,36.19],[1,4.3,12.6],[2,1.01,0.51]],"batl":[[1,5.8,25.57],[2,5.8,0]],"ltp":4.9,"tv":93.16,"id":13117392},{"batb":[[0,1.81,51.25],[1,1.68,52.4],[2,1.01,0.51]],"batl":[[0,1.99,42.01],[1,2,37.58],[2,2.12,58.38]],"ltp":1.74,"tv":1416.34,"id":13117391}]}]}
{"op":"mcm","clk":"1006355553","pt":1580595507432,"mc":[{"id":"1.168175449","rc":[{"batb":[[0,6.6,68.54]],"batl":[[1,8.2,0]],"ltp":0.0,"tv":0.0,"id":13117449},{"batb":[[0,6,36.74],[1,1.01,0.51],[2,1.01,0]],"batl":[[0,12,30.37],[1,12,0]],"ltp":5.9,"tv":4.0,"id":13117448},{"batb":[[1,1.01,0.51],[2,1.01,0]],"batl":[[0,5.8,25.57],[1,5.8,0]],"ltp":4.9,"tv":93.16,"id":13117392},{"batb":[[0,1.68,52.4],[1,1.01,0.51],[2,1.01,0]],"batl":[[0,2,37.58],[1,2.12,58.38],[2,2.12,0]],"ltp":1.74,"tv":1416.34,"id":13117391}]}]}
{"op":"mcm","clk":"1006355686","pt":1580595508545,"mc":[{"id":"1.168175449","rc":[{"batb":[[1,6.4,73.31],[2,6.2,32.89]],"ltp":0.0,"tv":0.0,"id":13117449},{"batb":[[0,6.2,42.71],[1,6,122.23],[2,1.01,0.51]],"ltp":5.9,"tv":4.0,"id":13117448},{"batb":[[1,4.2,107.83],[2,4.1,100.37]],"ltp":4.9,"tv":93.16,"id":13117392},{"batb":[[0,1.73,143.62],[1,1.71,221.36],[2,1.68,52.4]],"ltp":1.74,"tv":1416.34,"id":13117391}]}]}
{"op":"mcm","clk":"1006355785","pt":1580595509430,"mc":[{"id":"1.168175449","rc":[{"batb":[[0,1.68,52.4],[1,1.01,0.51],[2,1.68,0]],"ltp":1.74,"tv":1416.34,"id":13117391}]}]}
{"op":"mcm","clk":"1006356149","pt":1580595512439,"mc":[{"id":"1.168175449","rc":[{"batb":[[1,6.4,80.87]],"batl":[[0,7.4,30.84],[1,7.8,28.17],[2,8,32.4]],"ltp":0.0,"tv":0.0,"id":13117449},{"batb":[[0,6.2,50.27],[2,5.3,23.92]],"batl":[[0,7,34.38],[1,7.8,5.88],[2,8.8,21.95]],"ltp":5.9,"tv":4.0,"id":13117448},{"batb":[[1,4.3,40.05],[2,4.2,107.83]],"batl":[[0,4.9,10.08],[1,5.1,34.46],[2,5.4,30.14]],"ltp":4.9,"tv":93.16,"id":13117392},{"trd":[[2,82]],"batb":[[0,2.06,109.47],[1,2.04,125.74],[2,2,60.11]],"batl":[[0,2.12,58.38],[1,2.14,36.13],[2,2.28,47.52]],"ltp":2.0,"tv":1491.5,"id":13117391}],"tv":1588.67}]}
{"op":"mcm","clk":"1006356170","pt":1580595512646,"mc":[{"id":"1.168175449","rc":[{"batl":[[2,8,5.88]],"ltp":0.0,"tv":0.0,"id":13117449}]}]}
{"op":"mcm","clk":"1006357496","pt":1580595523492,"mc":[{"id":"1.168175449","rc":[{"batl":[[2,8,0]],"ltp":0.0,"tv":0.0,"id":13117449},{"batl":[[1,8.8,21.95],[2,8.8,0]],"ltp":5.9,"tv":4.0,"id":13117448}]}]}
{"op":"mcm","clk":"1006357581","pt":1580595524178,"mc":[{"id":"1.168175449","rc":[{"batb":[[1,6.4,73.31]],"ltp":0.0,"tv":0.0,"id":13117449},{"batb":[[0,6.2,42.71]],"ltp":5.9,"tv":4.0,"id":13117448},{"batl":[[1,2.28,47.52],[2,2.28,0]],"ltp":2.0,"tv":1491.5,"id":13117391}]}]}
{"op":"mcm","clk":"1006357868","pt":1580595526553,"mc":[{"id":"1.168175449","rc":[{"batl":[[1,7.8,34.05]],"ltp":0.0,"tv":0.0,"id":13117449},{"batl":[[1,7.6,5.88],[2,8.8,21.95]],"ltp":5.9,"tv":4.0,"id":13117448}]}]}
{"op":"mcm","clk":"1006357935","pt":1580595527178,"mc":[{"id":"1.168175449","rc":[{"batb":[[0,6.4,73.31],[1,6.2,32.89],[2,1.01,0.51]],"batl":[[0,7.8,28.17],[1,7.8,0]],"ltp":0.0,"tv":0.0,"id":13117449},{"batb":[[0,5.3,23.92],[1,1.01,0.51],[2,5.3,0]],"batl":[[0,8.8,21.95],[1,7.6,0],[2,8.8,0]],"ltp":5.9,"tv":4.0,"id":13117448},{"batb":[[0,4.3,40.05],[1,4.1,82.34],[2,1.01,0.51]],"batl":[[0,5.4,30.14],[1,5.1,0],[2,5.4,0]],"ltp":4.9,"tv":93.16,"id":13117392},{"batb":[[0,1.84,39.66],[1,1.01,0.51],[2,2,0]],"batl":[[0,2.28,47.52],[1,2.28,0]],"ltp":2.0,"tv":1491.5,"id":13117391}]}]}
{"op":"mcm","clk":"1006358684","pt":1580595533510,"mc":[{"id":"1.168175449","rc":[{"batb":[[0,6.4,95.82],[1,6.2,111.01]],"ltp":0.0,"tv":0.0,"id":13117449},{"batb":[[0,5.5,73.33],[1,5.4,54.49],[2,5.3,23.92]],"ltp":5.9,"tv":4.0,"id":13117448},{"batb":[[2,4,106.88]],"ltp":4.9,"tv":93.16,"id":13117392},{"batb":[[0,2.2,95.01],[1,2.18,103.49],[2,1.84,39.66]],"ltp":2.0,"tv":1491.5,"id":13117391}]}]}
{"op":"mcm","clk":"1006358802","pt":1580595534370,"mc":[{"id":"1.168175449","rc":[{"batb":[[1,6.2,78.12],[2,6,36.98]],"batl":[[0,7.2,32.42],[1,7.4,31.32]],"ltp":0.0,"tv":0.0,"id":13117449},{"batl":[[0,6.2,22.98],[1,7,35.96]],"ltp":5.9,"tv":4.0,"id":13117448},{"batb":[[1,4.1,127.35],[2,4,120.32]],"batl":[[0,4.7,10.92],[1,4.8,38.08],[2,5,35.33]],"ltp":4.9,"tv":93.16,"id":13117392},{"batb":[[2,2.14,48.78]],"batl":[[1,2.54,35.33]],"ltp":2.0,"tv":1491.5,"id":13117391}]}]}
{"op":"mcm","clk":"1006359034","pt":1580595536277,"mc":[{"id":"1.168175449","rc":[{"batb":[[2,6,45.38]],"ltp":0.0,"tv":0.0,"id":13117449},{"batl":[[1,6.6,6.72],[2,7,35.96]],"ltp":5.9,"tv":4.0,"id":13117448},{"batl":[[1,2.32,31.09],[2,2.54,35.33]],"ltp":2.0,"tv":1491.5,"id":13117391}]}]}
{"op":"mcm","clk":"1006359167","pt":1580595537373,"mc":[{"id":"1.168175449","rc":[{"batl":[[1,7.4,37.2]],"ltp":0.0,"tv":0.0,"id":13117449},{"batb":[[1,5.4,63.73]],"ltp":5.9,"tv":4.0,"id":13117448}]}]}
{"op":"mcm","clk":"1006361424","pt":1580595555611,"mc":[{"id":"1.168175449","rc":[{"batb":[[0,2.18,103.49],[1,2.14,48.78],[2,2.08,38.65]],"ltp":2.0,"tv":1491.5,"id":13117391}]}]}
{"op":"mcm","clk":"1006361794","pt":1580595558604,"mc":[{"id":"1.168175449","rc":[{"batb":[[0,2.18,196.18],[1,2.16,106.09],[2,2.14,48.78]],"ltp":2.0,"tv":1491.5,"id":13117391}]}]}
{"op":"mcm","clk":"1006362818","pt":1580595567544,"mc":[{"id":"1.168175449","rc":[{"batb":[[0,6.2,78.12],[1,6,45.38],[2,1.01,0.51]],"batl":[[0,7.4,37.2],[1,7.4,0]],"ltp":0.0,"tv":0.0,"id":13117449},{"batb":[[0,5.4,9.24],[1,4.6,34.46],[2,1.01,0.51]],"batl":[[0,6.6,6.72],[1,7,35.96],[2,7,0]],"ltp":5.9,"tv":4.0,"id":13117448},{"batb":[[0,4.1,45.01],[1,4,13.44],[2,1.01,0.51]],"batl":[[1,5,35.33],[2,5,0]],"ltp":4.9,"tv":93.16,"id":13117392},{"batb":[[0,2.08,38.65],[1,2.02,57.67],[2,1.01,0.51]],"batl":[[0,2.32,31.09],[1,2.54,35.33],[2,2.54,0]],"ltp":2.0,"tv":1491.5,"id":13117391}]}]}
{"op":"mcm","clk":"1006363046","pt":1580595569214,"mc":[{"id":"1.168175449","rc":[{"batb":[[1,6,36.98]],"batl":[[0,7.4,31.32]],"ltp":0.0,"tv":0.0,"id":13117449},{"batb":[[0,4.6,34.46],[1,1.01,0.51],[2,1.01,0]],"batl":[[0,7,35.96],[1,7,0]],"ltp":5.9,"tv":4.0,"id":13117448},{"batb":[[1,1.01,0.51],[2,1.01,0]],"batl":[[0,5,35.33],[1,5,0]],"ltp":4.9,"tv":93.16,"id":13117392},{"batb":[[0,2.02,57.67],[1,1.01,0.51],[2,1.01,0]],"batl":[[0,2.54,35.33],[1,2.54,0]],"ltp":2.0,"tv":1491.5,"id":13117391}]}]}
{"op":"mcm","clk":"1006363187","pt":1580595570412,"mc":[{"id":"1.168175449","rc":[{"batb":[[0,6.2,78.56]],"ltp":0.0,"tv":0.0,"id":13117449},{"batb":[[1,3.95,61.15],[2,1.01,0.51]],"ltp":4.9,"tv":93.16,"id":13117392}]}]}
{"op":"mcm","clk":"1006363303","pt":1580595571403,"mc":[{"id":"1.168175449","rc":[{"batb":[[0,6.4,79.98],[1,6.2,78.56],[2,6,36.98]],"ltp":0.0,"tv":0.0,"id":13117449},{"batb":[[0,5.3,88.83],[1,5.2,59.12],[2,4.6,34.46]],"ltp":5.9,"tv":4.0,"id":13117448},{"batb":[[1,4,154.47],[2,3.95,61.15]],"ltp":4.9,"tv":93.16,"id":13117392},{"batb":[[0,2.24,113.3],[1,2.22,98.19],[2,2.02,57.67]],"ltp":2.0,"tv":1491.5,"id":13117391}]}]}
{"op":"mcm","clk":"1006363662","pt":1580595574745,"mc":[{"id":"1.168175449","rc":[{"batb":[[0,6.2,78.56],[1,6,36.98],[2,1.01,0.51]],"ltp":0.0,"tv":0.0,"id":13117449},{"batb":[[0,4.6,34.46],[1,1.01,0.51],[2,4.6,0]],"ltp":5.9,"tv":4.0,"id":13117448},{"batb":[[1,3.95,61.15],[2,1.01,0.51]],"ltp":4.9,"tv":93.16,"id":13117392},{"batb":[[0,2.02,57.67],[1,1.01,0.51],[2,2.02,0]],"ltp":2.0,"tv":1491.5,"id":13117391}]}]}
{"op":"mcm","clk":"1006363975","pt":1580595577635,"mc":[{"id":"1.168175449","rc":[{"batb":[[0,6.2,98.12],[1,6,121.02]],"ltp":0.0,"tv":0.0,"id":13117449},{"batb":[[0,4.7,91.73],[1,4.6,112.63],[2,1.01,0.51]],"ltp":5.9,"tv":4.0,"id":13117448},{"batb":[[2,3.9,57.68]],"ltp":4.9,"tv":93.16,"id":13117392},{"batb":[[0,2.08,110.43],[1,2.06,122.13],[2,2.02,57.67]],"ltp":2.0,"tv":1491.5,"id":13117391}]}]}
{"op":"mcm","clk":"1006364954","pt":1580595586318,"mc":[{"id":"1.168175449","rc":[{"batb":[[0,6,36.98],[1,1.01,0.51],[2,1.01,0]],"ltp":0.0,"tv":0.0,"id":13117449},{"batb":[[0,4.6,34.46],[1,1.01,0.51],[2,1.01,0]],"ltp":5.9,"tv":4.0,"id":13117448},{"batb":[[1,1.01,0.51],[2,3.9,0]],"ltp":4.9,"tv":93.16,"id":13117392}]}]}
{"op":"mcm","clk":"1006365319","pt":1580595589530,"mc":[{"id":"1.168175449","rc":[{"batb":[[0,6.6,67.91],[1,6.4,73.6],[2,6.2,33.44]],"batl":[[1,7.6,29.82]],"ltp":0.0,"tv":0.0,"id":13117449},{"batb":[[0,6,106.69],[1,5.9,82.77],[2,5.1,26.59]],"batl":[[1,7.6,28.88]],"ltp":5.9,"tv":4.0,"id":13117448},{"batb":[[0,4.4,37.14],[1,4.2,124.67],[2,4.1,145.83]],"batl":[[1,5.1,33.75]],"ltp":4.9,"tv":93.16,"id":13117392},{"batl":[[0,2.14,56.1],[1,2.34,43.75],[2,2.54,35.33]],"ltp":2.0,"tv":1491.5,"id":13117391}]}]}
{"op":"mcm","clk":"1006365344","pt":1580595589744,"mc":[{"id":"1.168175449","rc":[{"batl":[[1,7.6,35.7]],"ltp":0.0,"tv":0.0,"id":13117449},{"batb":[[2,5.8,8.4]],"batl":[[1,7.2,6.72],[2,7.6,28.88]],"ltp":5.9,"tv":4.0,"id":13117448},{"batb":[[2,4.1,114.26]],"batl":[[0,4.9,10.08],[1,5,35.33],[2,5.1,33.75]],"ltp":4.9,"tv":93.16,"id":13117392},{"batl":[[1,2.24,33.61],[2,2.34,43.75]],"ltp":2.0,"tv":1491.5,"id":13117391}]}]}
{"op":"mcm","clk":"1006366907","pt":1580595604561,"mc":[{"id":"1.168175449","rc":[{"batb":[[0,6.4,73.6],[1,6,43.65],[2,1.01,0.51]],"batl":[[0,7.6,35.7],[1,7.6,0]],"ltp":0.0,"tv":0.0,"id":13117449},{"batb":[[0,5.8,8.4],[1,5.1,26.59],[2,1.01,0.51]],"batl":[[0,7.2,6.72],[1,7.6,28.88],[2,7.6,0]],"ltp":5.9,"tv":4.0,"id":13117448},{"batb":[[0,4.2,41.54],[1,4.1,13.44],[2,1.01,0.51]],"batl":[[1,5.1,33.75],[2,5.1,0]],"ltp":4.9,"tv":93.16,"id":13117392},{"batb":[[0,2,42.01],[1,1.95,32.89],[2,1.01,0.51]],"batl":[[0,2.24,33.61],[1,2.34,43.75],[2,2.34,0]],"ltp":2.0,"tv":1491.5,"id":13117391}]}]}
{"op":"mcm","clk":"1006367017","pt":1580595605544,"mc":[{"id":"1.168175449","rc":[{"batb":[[1,6,35.25]],"batl":[[0,7.6,29.82]],"ltp":0.0,"tv":0.0,"id":13117449},{"batb":[[0,5.1,26.59],[1,1.01,0.51],[2,1.01,0]],"batl":[[0,7.6,28.88],[1,7.6,0]],"ltp":5.9,"tv":4.0,"id":13117448},{"batb":[[1,1.01,0.51],[2,1.01,0]],"batl":[[0,5.1,33.75],[1,5.1,0]],"ltp":4.9,"tv":93.16,"id":13117392},{"batb":[[0,1.95,32.89],[1,1.01,0.51],[2,1.01,0]],"batl":[[0,2.34,43.75],[1,2.34,0]],"ltp":2.0,"tv":1491.5,"id":13117391}]}]}
{"op":"mcm","clk":"1006367175","pt":1580595606952,"mc":[{"id":"1.168175449","rc":[{"batb":[[1,6.2,78.86],[2,6,35.25]],"ltp":0.0,"tv":0.0,"id":13117449},{"batb":[[0,5.3,75.53],[1,5.2,59.36],[2,5.1,26.59]],"ltp":5.9,"tv":4.0,"id":13117448},{"batb":[[1,4,148.89],[2,3.95,55.16]],"ltp":4.9,"tv":93.16,"id":13117392},{"batb":[[0,1.99,160.7],[1,1.97,139.77],[2,1.95,32.89]],"ltp":2.0,"tv":1491.5,"id":13117391}]}]}
{"op":"mcm","clk":"1006367566","pt":1580595611053,"mc":[{"id":"1.168175449","rc":[{"batb":[[0,1.95,32.89],[1,1.01,0.51],[2,1.95,0]],"ltp":2.0,"tv":1491.5,"id":13117391}]}]}
{"op":"mcm","clk":"1006367847","pt":1580595613494,"mc":[{"id":"1.168175449","rc":[{"batb":[[0,2.24,153.92],[1,2.22,98.09],[2,1.95,32.89]],"ltp":2.0,"tv":1491.5,"id":13117391}]}]}
{"op":"mcm","clk":"1006367957","pt":1580595614494,"mc":[{"id":"1.168175449","rc":[{"batb":[[2,6,43.65]],"batl":[[0,7.2,39.77],[1,7.4,31.63]],"ltp":0.0,"tv":0.0,"id":13117449},{"batb":[[0,5.3,84.77]],"batl":[[0,5.8,25.57],[1,6.4,7.56],[2,6.8,37.77]],"ltp":5.9,"tv":4.0,"id":13117448},{"batb":[[1,4,210.17]],"batl":[[0,4.7,10.92],[1,4.8,39.42],[2,5,36.04]],"ltp":4.9,"tv":93.16,"id":13117392},{"batb":[[2,2.2,44.85]],"batl":[[1,2.38,30.25],[2,2.7,30.29]],"ltp":2.0,"tv":1491.5,"id":13117391}]}]}
{"op":"mcm","clk":"1006369483","pt":1580595630109,"mc":[{"id":"1.168175449","rc":[{"batb":[[0,6.2,59.6],[1,6,8.4],[2,5.9,38.08]],"batl":[[0,7.2,6.72]],"ltp":0.0,"tv":0.0,"id":13117449},{"batb":[[0,5.3,9.24],[1,4.3,40.52],[2,1.01,0.51]],"batl":[[0,6.4,7.56],[1,6.8,37.77],[2,6.8,0]],"ltp":5.9,"tv":4.0,"id":13117448},{"batb":[[0,4,61.28],[1,1.01,0.51],[2,3.95,0]],"batl":[[1,5,36.04],[2,5,0]],"ltp":4.9,"tv":93.16,"id":13117392},{"batb":[[0,2.14,36.13],[1,2.04,55.55],[2,1.01,0.51]],"batl":[[0,2.38,30.25],[1,2.7,30.29],[2,2.7,0]],"ltp":2.0,"tv":1491.5,"id":13117391}]}]}
{"op":"mcm","clk":"1006369617","pt":1580595631547,"mc":[{"id":"1.168175449","rc":[{"batb":[[1,5.9,38.08],[2,1.01,0.51]],"batl":[[0,7.4,31.63],[1,7.4,0]],"ltp":0.0,"tv":0.0,"id":13117449},{"batb":[[0,4.3,40.52],[1,1.01,0.51],[2,1.01,0]],"batl":[[0,6.8,37.77],[1,6.8,0]],"ltp":5.9,"tv":4.0,"id":13117448},{"batb":[[0,4,47.84]],"batl":[[0,5,36.04],[1,5,0]],"ltp":4.9,"tv":93.16,"id":13117392},{"batb":[[0,2.04,55.55],[1,1.01,0.51],[2,1.01,0]],"batl":[[0,2.7,30.29],[1,2.7,0]],"ltp":2.0,"tv":1491.5,"id":13117391}]}]}
{"op":"mcm","clk":"1006369714","pt":1580595632531,"mc":[{"id":"1.168175449","rc":[{"batb":[[0,5.9,38.08],[1,1.01,0.51],[2,1.01,0]],"ltp":0.0,"tv":0.0,"id":13117449}]}]}
{"op":"mcm","clk":"1006369795","pt":1580595633563,"mc":[{"id":"1.168175449","rc":[{"batb":[[0,2.1,114.96],[1,2.08,118.66],[2,2.04,55.55]],"ltp":2.0,"tv":1491.5,"id":13117391}]}]}
{"op":"mcm","clk":"1006369969","pt":1580595635542,"mc":[{"id":"1.168175449","rc":[{"batb":[[0,6.6,47.61],[1,6.4,74.13],[2,5.9,38.08]],"ltp":0.0,"tv":0.0,"id":13117449},{"batb":[[0,6,60.62],[1,5.9,44.93],[2,4.3,40.52]],"ltp":5.9,"tv":4.0,"id":13117448},{"batb":[[0,4.2,70.38],[1,4.1,101.04],[2,4,47.84]],"ltp":4.9,"tv":93.16,"id":13117392}]}]}
{"op":"mcm","clk":"1006370059","pt":1580595636470,"mc":[{"id":"1.168175449","rc":[{"batb":[[2,6,45.38]],"batl":[[0,7.4,36.57]],"ltp":0.0,"tv":0.0,"id":13117449},{"batb":[[2,5.7,48.92]],"batl":[[1,7,6.72],[2,7.6,29.35]],"ltp":5.9,"tv":4.0,"id":13117448},{"batb":[[0,4.4,37.85],[1,4.2,112.4],[2,4.1,114.48]],"batl":[[0,4.9,10.08],[1,5,36.04],[2,5.1,33.28]],"ltp":4.9,"tv":93.16,"id":13117392},{"batb":[[2,2.04,95.88]],"batl":[[0,2.18,54.05],[1,2.26,32.77],[2,2.42,40.21]],"ltp":2.0,"tv":1491.5,"id":13117391}]}]}
{"op":"mcm","clk":"1006371265","pt":1580595649368,"mc":[{"id":"1.168175449","rc":[{"batb":[[0,6.4,39.75],[1,6,36.98],[2,1.01,0.51]],"batl":[[0,7.4,30.69]],"ltp":0.0,"tv":0.0,"id":13117449},{"batb":[[0,4.9,29.58],[1,1.01,0.51],[2,5.7,0]],"batl":[[0,7.6,29.35],[1,7,0],[2,7.6,0]],"ltp":5.9,"tv":4.0,"id":13117448},{"batb":[[0,4.2,42.02],[1,1.01,0.51],[2,4.1,0]],"batl":[[0,5.1,33.28],[1,5,0],[2,5.1,0]],"ltp":4.9,"tv":93.16,"id":13117392},{"batb":[[0,1.96,32.57],[1,1.01,0.51],[2,2.04,0]],"batl":[[0,2.42,40.21],[1,2.26,0],[2,2.42,0]],"ltp":2.0,"tv":1491.5,"id":13117391}]}]}
{"op":"mcm","clk":"1006371527","pt":1580595652267,"mc":[{"id":"1.168175449","rc":[{"batb":[[1,6.2,79.58],[2,6,36.98]],"ltp":0.0,"tv":0.0,"id":13117449},{"batb":[[1,4,109.94],[2,1.01,0.51]],"ltp":4.9,"tv":93.16,"id":13117392}]}]}
{"op":"mcm","clk":"1006371677","pt":1580595653562,"mc":[{"id":"1.168175449","rc":[{"batb":[[0,6.4,103.27]],"ltp":0.0,"tv":0.0,"id":13117449},{"batb":[[0,5.8,57.43],[1,5.7,48.49],[2,4.9,29.58]],"ltp":5.9,"tv":4.0,"id":13117448},{"batb":[[1,4.1,141.37],[2,4,109.94]],"ltp":4.9,"tv":93.16,"id":13117392},{"batb":[[0,2.14,112.7],[1,2.12,112.21],[2,1.96,32.57]],"ltp":2.0,"tv":1491.5,"id":13117391}]}]}
{"op":"mcm","clk":"1006371989","pt":1580595656455,"mc":[{"id":"1.168175449","rc":[{"batb":[[0,6.4,39.91]],"ltp":0.0,"tv":0.0,"id":13117449},{"batb":[[0,4.9,29.58],[1,1.01,0.51],[2,4.9,0]],"ltp":5.9,"tv":4.0,"id":13117448},{"batb":[[1,4,109.94],[2,1.01,0.51]],"ltp":4.9,"tv":93.16,"id":13117392},{"batb":[[0,1.96,32.57],[1,1.01,0.51],[2,1.96,0]],"ltp":2.0,"tv":1491.5,"id":13117391}]}]}
{"op":"mcm","clk":"1006372423","pt":1580595661048,"mc":[{"id":"1.168175449","rc":[{"batb":[[0,5.1,73.57],[1,5,64.81],[2,4.9,29.58]],"ltp":5.9,"tv":4.0,"id":13117448},{"batb":[[2,3.95,55.54]],"ltp":4.9,"tv":93.16,"id":13117392}]}]}
{"op":"mcm","clk":"1006372654","pt":1580595663377,"mc":[{"id":"1.168175449","rc":[{"batb":[[0,2.3,148.47],[1,2.28,90.95],[2,1.96,32.57]],"ltp":2.0,"tv":1491.5,"id":13117391}]}]}
{"op":"mcm","clk":"1006372765","pt":1580595664464,"mc":[{"id":"1.168175449","rc":[{"batb":[[2,5.8,47.9]],"batl":[[0,7,34.54],[1,7.2,39.53]],"ltp":0.0,"tv":0.0,"id":13117449},{"batb":[[1,5,74.89]],"batl":[[0,5.5,28.33],[1,6,8.4],[2,6.6,38.71]],"ltp":5.9,"tv":4.0,"id":13117448},{"batb":[[1,4,123.38]],"batl":[[0,4.7,50.89],[1,5,35.64]],"ltp":4.9,"tv":93.16,"id":13117392},{"batb":[[1,2.28,132.18],[2,2.2,34.45]],"batl":[[1,2.46,28.57],[2,2.94,24.39]],"ltp":2.0,"tv":1491.5,"id":13117391}]}]}
{"op":"mcm","clk":"1006374784","pt":1580595684523,"mc":[{"id":"1.168175449","rc":[{"batb":[[0,5.8,47.9],[1,1.01,0.51],[2,5.8,0]],"batl":[[0,7.2,39.53],[1,7.2,0]],"ltp":0.0,"tv":0.0,"id":13117449},{"batb":[[0,5,10.08],[1,3.9,49.65],[2,1.01,0.51]],"batl":[[0,6,8.4],[1,6.6,38.71],[2,6.6,0]],"ltp":5.9,"tv":4.0,"id":13117448},{"batb":[[0,4,13.44],[1,3.85,51.85],[2,1.01,0.51]],"batl":[[0,4.7,10.92]],"ltp":4.9,"tv":93.16,"id":13117392},{"batb":[[0,2.2,34.45],[1,2.06,54.37],[2,1.01,0.51]],"batl":[[0,2.46,28.57],[1,2.94,24.39],[2,2.94,0]],"ltp":2.0,"tv":1491.5,"id":13117391}]}]}
{"op":"mcm","clk":"1006374821","pt":1580595684892,"mc":[{"id":"1.168175449","rc":[{"batb":[[0,5.8,39.5]],"batl":[[0,7.2,32.81]],"ltp":0.0,"tv":0.0,"id":13117449},{"batb":[[0,3.9,49.65],[1,1.01,0.51],[2,1.01,0]],"batl":[[0,6.6,38.71],[1,6.6,0]],"ltp":5.9,"tv":4.0,"id":13117448},{"batb":[[0,3.85,51.85],[1,1.01,0.51],[2,1.01,0]],"batl":[[0,5,35.64],[1,5,0]],"ltp":4.9,"tv":93.16,"id":13117392},{"batb":[[0,2.06,54.37],[1,1.01,0.51],[2,1.01,0]],"batl":[[0,2.94,24.39],[1,2.94,0]],"ltp":2.0,"tv":1491.5,"id":13117391}]}]}
{"op":"mcm","clk":"1006375072","pt":1580595687419,"mc":[{"id":"1.168175449","rc":[{"batb":[[0,6,93.54],[1,5.9,82.88],[2,5.8,39.5]],"batl":[[1,7.4,31.87]],"ltp":0.0,"tv":0.0,"id":13117449},{"batb":[[0,4,147.2],[1,3.95,104.16],[2,3.9,49.65]],"batl":[[1,6.8,37.69]],"ltp":5.9,"tv":4.0,"id":13117448},{"batb":[[1,3.75,81.43],[2,3.7,65.24]],"ltp":4.9,"tv":93.16,"id":13117392},{"batb":[[0,2.1,114.7],[1,2.08,118.68],[2,2.06,54.37]],"batl":[[0,2.92,24.86],[1,2.94,24.39]],"ltp":2.0,"tv":1491.5,"id":13117391}]}]}
{"op":"mcm","clk":"1006375093","pt":1580595687627,"mc":[{"id":"1.168175449","rc":[{"batb":[[2,1.01,0.51]],"batl":[[0,7.4,31.87],[1,7.4,0]],"ltp":0.0,"tv":0.0,"id":13117449},{"batb":[[2,1.01,0.51]],"batl":[[0,6.8,37.69],[1,6.8,0]],"ltp":5.9,"tv":4.0,"id":13117448},{"batb":[[0,3.85,26.44]],"ltp":4.9,"tv":93.16,"id":13117392},{"batb":[[2,2.04,55.39]],"batl":[[1,2.94,0]],"ltp":2.0,"tv":1491.5,"id":13117391}]}]}
{"op":"mcm","clk":"1006376705","pt":1580595704346,"mc":[{"id":"1.168175449","rc":[{"batb":[[0,5.9,38.48],[1,1.01,0.51],[2,1.01,0]],"ltp":0.0,"tv":0.0,"id":13117449},{"batb":[[0,3.95,48.31],[1,1.01,0.51],[2,1.01,0]],"ltp":5.9,"tv":4.0,"id":13117448},{"batb":[[1,1.01,0.51],[2,3.7,0]],"ltp":4.9,"tv":93.16,"id":13117392},{"batb":[[0,2.04,55.39],[1,1.01,0.51],[2,2.04,0]],"ltp":2.0,"tv":1491.5,"id":13117391}]}]}
{"op":"mcm","clk":"1006383890","pt":1580595783329,"mc":[{"id":"1.168175449","rc":[{"batb":[[0,1.01,0.51],[1,1.01,0]],"ltp":0.0,"tv":0.0,"id":13117449}]}]}
{"op":"mcm","clk":"1006384148","pt":1580595786436,"mc":[{"id":"1.168175449","rc":[{"batb":[[0,5.8,38.95],[1,5.6,29.88],[2,1.01,0.51]],"batl":[[0,6.8,43.07],[1,7,34.86]],"ltp":0.0,"tv":0.0,"id":13117449},{"batb":[[0,4.1,13.44],[1,3.95,48.31],[2,3.1,44.14]],"batl":[[0,4.5,46.26],[1,4.9,10.08],[2,5.4,29.58]],"ltp":5.9,"tv":4.0,"id":13117448},{"batb":[[1,3.7,15.12],[2,3.5,33.28]],"batl":[[0,4.3,62.09],[1,4.7,40.99]],"ltp":4.9,"tv":93.16,"id":13117392},{"batb":[[0,2.76,25.1],[1,2.6,26.05],[2,2.32,39.34]],"batl":[[0,2.92,24.71],[1,2.94,21],[2,4.2,26.59]],"ltp":2.0,"tv":1491.5,"id":13117391}]}]}
{"op":"mcm","clk":"1006384351","pt":1580595788412,"mc":[{"id":"1.168175449","rc":[{"batb":[[0,5.6,29.88],[1,1.01,0.51],[2,1.01,0]],"batl":[[0,6.8,6.72]],"ltp":0.0,"tv":0.0,"id":13117449},{"batb":[[1,3.1,44.14],[2,1.01,0.51]],"batl":[[0,4.9,10.08],[1,5.4,29.58],[2,5.4,0]],"ltp":5.9,"tv":4.0,"id":13117448},{"batb":[[0,3.7,15.12],[1,3.5,33.28],[2,1.01,0.51]],"batl":[[0,4.3,12.6]],"ltp":4.9,"tv":93.16,"id":13117392},{"batb":[[0,2.6,26.05],[1,2.32,39.34],[2,1.01,0.51]],"batl":[[0,2.94,21],[1,4.2,26.59],[2,4.2,0]],"ltp":2.0,"tv":1491.5,"id":13117391}]}]}
{"op":"mcm","clk":"1006384437","pt":1580595789241,"mc":[{"id":"1.168175449","rc":[{"batb":[[0,5.6,21.48]],"batl":[[0,7,34.86],[1,7,0]],"ltp":0.0,"tv":0.0,"id":13117449},{"batb":[[0,3.1,44.14],[1,1.01,0.51],[2,1.01,0]],"batl":[[0,5.4,29.58],[1,5.4,0]],"ltp":5.9,"tv":4.0,"id":13117448},{"batb":[[0,3.5,33.28],[1,1.01,0.51],[2,1.01,0]],"batl":[[0,4.7,40.99],[1,4.7,0]],"ltp":4.9,"tv":93.16,"id":13117392},{"batb":[[0,2.32,39.34],[1,1.01,0.51],[2,1.01,0]],"batl":[[0,4.2,26.59],[1,4.2,0]],"ltp":2.0,"tv":1491.5,"id":13117391}]}]}
{"op":"mcm","clk":"1006385055","pt":1580595795344,"mc":[{"id":"1.168175449","rc":[{"batb":[[0,5.8,39.73]],"batl":[[1,7.2,32.65]],"ltp":0.0,"tv":0.0,"id":13117449},{"batb":[[0,4.8,30.92],[1,3.85,51.46],[2,1.01,0.51]],"batl":[[1,6.6,39.89]],"ltp":5.9,"tv":4.0,"id":13117448},{"batb":[[0,4.1,43.2],[1,3.85,52.32],[2,1.01,0.51]],"batl":[[1,4.9,36.59]],"ltp":4.9,"tv":93.16,"id":13117392},{"batb":[[1,2.08,52.87],[2,1.01,0.51]],"batl":[[0,2.46,38.48],[1,2.98,23.53]],"ltp":2.0,"tv":1491.5,"id":13117391}]}]}
{"op":"mcm","clk":"1006385148","pt":1580595796338,"mc":[{"id":"1.168175449","rc":[{"batl":[[0,7,41.58]],"ltp":0.0,"tv":0.0,"id":13117449},{"batb":[[0,4.9,10.08],[1,4.8,30.92],[2,3.85,51.46]],"batl":[[1,5.9,8.4],[2,6.6,39.89]],"ltp":5.9,"tv":4.0,"id":13117448},{"batb":[[1,3.95,13.44],[2,3.85,52.32]],"batl":[[0,4.7,51.92]],"ltp":4.9,"tv":93.16,"id":13117392},{"batb":[[1,2.24,33.61],[2,2.08,52.87]],"batl":[[1,2.52,26.89],[2,2.98,23.53]],"ltp":2.0,"tv":1491.5,"id":13117391}]}]}
{"op":"mcm","clk":"1006385385","pt":1580595798510,"mc":[{"id":"1.168175449","rc":[{"batb":[[1,5.7,8.4],[2,1.01,0.51]],"ltp":0.0,"tv":0.0,"id":13117449}]}]}
{"op":"mcm","clk":"1006385668","pt":1580595801464,"mc":[{"id":"1.168175449","rc":[{"batb":[[0,6.2,104.93],[1,6,83.72],[2,5.8,39.73]],"ltp":0.0,"tv":0.0,"id":13117449},{"batb":[[0,5,84.64],[1,4.9,77.76],[2,4.8,30.92]],"ltp":5.9,"tv":4.0,"id":13117448},{"batb":[[1,4,104.04],[2,3.95,69.04]],"ltp":4.9,"tv":93.16,"id":13117392},{"batb":[[0,2.32,205.67],[1,2.3,88.7],[2,2.24,33.61]],"ltp":2.0,"tv":1491.5,"id":13117391}]}]}
{"op":"mcm","clk":"1006386506","pt":1580595809241,"mc":[{"id":"1.168175449","rc":[{"batb":[[0,6,83.72],[1,5.8,39.73],[2,1.01,0.51]],"batl":[[0,7.2,32.65],[1,7.2,0]],"ltp":0.0,"tv":0.0,"id":13117449},{"batb":[[0,3.85,51.46],[1,1.01,0.51],[2,4.8,0]],"batl":[[0,6.6,39.89],[1,5.9,0],[2,6.6,0]],"ltp":5.9,"tv":4.0,"id":13117448},{"batb":[[0,3.85,52.32],[1,1.01,0.51],[2,3.95,0]],"batl":[[0,4.9,36.59],[1,4.9,0]],"ltp":4.9,"tv":93.16,"id":13117392},{"batb":[[0,2.08,52.87],[1,1.01,0.51],[2,2.24,0]],"batl":[[0,2.98,23.53],[1,2.52,0],[2,2.98,0]],"ltp":2.0,"tv":1491.5,"id":13117391}]}]}
{"op":"mcm","clk":"1006386777","pt":1580595812454,"mc":[{"id":"1.168175449","rc":[{"batb":[[0,5.8,39.18],[1,1.01,0.51],[2,1.01,0]],"batl":[[0,7.2,32.1]],"ltp":0.0,"tv":0.0,"id":13117449},{"batb":[[0,3.8,26.67]],"ltp":4.9,"tv":93.16,"id":13117392}]}]}
{"op":"mcm","clk":"1006387119","pt":1580595815454,"mc":[{"id":"1.168175449","rc":[{"batb":[[0,6.4,88.06],[1,6.2,78.27],[2,5.8,39.18]],"ltp":0.0,"tv":0.0,"id":13117449},{"batb":[[0,5.9,65.56],[1,5.8,46.54],[2,3.85,51.46]],"ltp":5.9,"tv":4.0,"id":13117448},{"batb":[[0,4.2,77.61],[1,4.1,100.97],[2,3.8,26.67]],"ltp":4.9,"tv":93.16,"id":13117392},{"batb":[[0,2.12,107.67],[1,2.1,115.38],[2,2.08,52.87]],"ltp":2.0,"tv":1491.5,"id":13117391}]}]}
{"op":"mcm","clk":"1006387225","pt":1580595816498,"mc":[{"id":"1.168175449","rc":[{"batb":[[2,5.9,45.78]],"batl":[[0,7.2,38.82],[1,7.4,30.76]],"ltp":0.0,"tv":0.0,"id":13117449},{"batb":[[2,5.6,29.88]],"batl":[[1,6.8,6.72],[2,7.6,30.14]],"ltp":5.9,"tv":4.0,"id":13117448},{"batb":[[0,4.3,39.03],[1,4.2,77.61],[2,4.1,159.18]],"batl":[[0,4.9,46.67],[1,5.1,34.54]],"ltp":4.9,"tv":93.16,"id":13117392},{"batl":[[0,2.22,51.38],[1,2.3,31.93],[2,2.52,35.96]],"ltp":2.0,"tv":1491.5,"id":13117391}]}]}
{"op":"mcm","clk":"1006387421","pt":1580595818359,"mc":[{"id":"1.168175449","rc":[{"batb":[[0,5.9,46.84]],"ltp":5.9,"tv":4.0,"id":13117448}]}]}
{"op":"mcm","clk":"1006387655","pt":1580595820987,"mc":[{"id":"1.168175449","rc":[{"batb":[[0,2.12,149.62]],"ltp":2.0,"tv":1491.5,"id":13117391}]}]}
{"op":"mcm","clk":"1006387927","pt":1580595823278,"mc":[{"id":"1.168175449","rc":[{"trd":[[2.22,8.1]],"batl":[[0,2.22,47.33]],"ltp":2.22,"tv":1499.6,"id":13117391}],"tv":1596.77}]}
{"op":"mcm","clk":"1006389345","pt":1580595837306,"mc":[{"id":"1.168175449","rc":[{"batb":[[0,6.2,78.27],[1,5.9,37.37],[2,1.01,0.51]],"batl":[[0,7.4,30.76],[1,7.4,0]],"ltp":0.0,"tv":0.0,"id":13117449},{"batb":[[0,4.6,33.36],[1,1.01,0.51],[2,5.6,0]],"batl":[[0,7.6,30.14],[1,6.8,0],[2,7.6,0]],"ltp":5.9,"tv":4.0,"id":13117448},{"batb":[[0,4.1,44.77],[1,1.01,0.51],[2,4.1,0]],"batl":[[0,5.1,34.54],[1,5.1,0]],"ltp":4.9,"tv":93.16,"id":13117392},{"batb":[[0,1.98,31.79],[1,1.01,0.51],[2,2.08,0]],"batl":[[0,2.52,35.96],[1,2.3,0],[2,2.52,0]],"ltp":2.22,"tv":1499.6,"id":13117391}]}]}
{"op":"mcm","clk":"1006389705","pt":1580595840474,"mc":[{"id":"1.168175449","rc":[{"batb":[[0,6.2,90.65],[1,6,84.13],[2,5.9,37.37]],"ltp":0.0,"tv":0.0,"id":13117449},{"batb":[[0,4.9,82.41],[1,4.8,70.72],[2,4.6,33.36]],"batl":[[0,7.4,30.69]],"ltp":5.9,"tv":4.0,"id":13117448},{"batb":[[1,4,87.13],[2,3.95,55.62]],"batl":[[0,5,34.7]],"ltp":4.9,"tv":93.16,"id":13117392},{"batb":[[0,2,171.45],[1,1.98,137.71],[2,1.97,62.79]],"batl":[[0,2.54,35.49]],"ltp":2.22,"tv":1499.6,"id":13117391}]}]}
{"op":"mcm","clk":"1006390187","pt":1580595845502,"mc":[{"id":"1.168175449","rc":[{"batb":[[0,5.9,37.37],[1,1.01,0.51],[2,5.9,0]],"ltp":0.0,"tv":0.0,"id":13117449},{"batb":[[0,4.6,33.36],[1,1.01,0.51],[2,4.6,0]],"ltp":5.9,"tv":4.0,"id":13117448},{"batb":[[1,1.01,0.51],[2,3.95,0]],"ltp":4.9,"tv":93.16,"id":13117392},{"batb":[[0,1.97,62.79],[1,1.01,0.51],[2,1.97,0]],"ltp":2.22,"tv":1499.6,"id":13117391}]}]}
{"op":"mcm","clk":"1006390497","pt":1580595848442,"mc":[{"id":"1.168175449","rc":[{"batb":[[0,6.6,60.15],[1,6.4,73.79],[2,5.9,37.37]],"ltp":0.0,"tv":0.0,"id":13117449},{"batb":[[0,6.6,63.94],[1,6.4,73.43],[2,4.6,33.36]],"ltp":5.9,"tv":4.0,"id":13117448},{"batb":[[0,4.3,77.97],[1,4.2,95.31],[2,4.1,44.77]],"ltp":4.9,"tv":93.16,"id":13117392},{"batb":[[0,2,171.44],[1,1.98,137.71],[2,1.97,62.79]],"ltp":2.22,"tv":1499.6,"id":13117391}]}]}
{"op":"mcm","clk":"1006390553","pt":1580595848960,"mc":[{"id":"1.168175449","rc":[{"batb":[[2,6.2,32.89]],"batl":[[1,7.6,29.03]],"ltp":0.0,"tv":0.0,"id":13117449},{"batb":[[0,6.6,36.71],[2,6.2,32.65]],"batl":[[1,9.2,19.75]],"ltp":5.9,"tv":4.0,"id":13117448},{"batb":[[0,4.4,36.43],[1,4.3,117.55],[2,4.2,95.31]],"batl":[[1,5.3,30.76]],"ltp":4.9,"tv":93.16,"id":13117392},{"batb":[[0,2,133.7],[1,1.97,62.79],[2,1.83,40.21]],"batl":[[0,2.08,60.9],[1,2.24,50.2]],"ltp":2.22,"tv":1499.6,"id":13117391}]}]}
{"op":"mcm","clk":"1006390699","pt":1580595850524,"mc":[{"id":"1.168175449","rc":[{"batl":[[0,7.4,36.65]],"ltp":0.0,"tv":0.0,"id":13117449},{"batb":[[2,6.2,40.21]],"batl":[[1,7.8,5.88],[2,9.2,19.75]],"ltp":5.9,"tv":4.0,"id":13117448},{"batb":[[2,4.2,107.91]],"batl":[[0,5,44.78]],"ltp":4.9,"tv":93.16,"id":13117392},{"batb":[[1,1.97,105.64]],"batl":[[1,2.18,35.29],[2,2.24,50.2]],"ltp":2.22,"tv":1499.6,"id":13117391}]}]}
{"op":"mcm","clk":"1006390900","pt":1580595852356,"mc":[{"id":"1.168175449","rc":[{"batb":[[0,2.02,103.09],[1,2,133.7],[2,1.97,105.64]],"ltp":2.22,"tv":1499.6,"id":13117391}]}]}
{"op":"mcm","clk":"1006391426","pt":1580595857235,"mc":[{"id":"1.168175449","rc":[{"batl":[[2,9,20.61]],"ltp":5.9,"tv":4.0,"id":13117448},{"batb":[[2,1.99,61.29]],"batl":[[0,2.1,59.56],[2,2.26,48.94]],"ltp":2.22,"tv":1499.6,"id":13117391}]}]}
{"op":"mcm","clk":"1006392218","pt":1580595865445,"mc":[{"id":"1.168175449","rc":[{"batl":[[2,9.2,19.91]],"ltp":5.9,"tv":4.0,"id":13117448},{"batb":[[0,4.5,36.27],[1,4.3,117.39]],"batl":[[1,5.3,30.61]],"ltp":4.9,"tv":93.16,"id":13117392},{"batb":[[2,1.97,105.4]],"batl":[[0,2.08,60.74],[2,2.24,49.96]],"ltp":2.22,"tv":1499.6,"id":13117391}]}]}
{"op":"mcm","clk":"1006392545","pt":1580595868422,"mc":[{"id":"1.168175449","rc":[{"batl":[[0,5,437.59]],"ltp":4.9,"tv":93.16,"id":13117392}]}]}
{"op":"mcm","clk":"1006393069","pt":1580595873367,"mc":[{"id":"1.168175449","rc":[{"batl":[[0,7.2,32.1],[1,7.4,36.1]],"ltp":0.0,"tv":0.0,"id":13117449},{"batl":[[2,9,20.61]],"ltp":5.9,"tv":4.0,"id":13117448},{"batb":[[0,4.5,35.8],[1,4.3,116.76]],"batl":[[0,5,402.89],[1,5.1,34.15],[2,5.3,30.29]],"ltp":4.9,"tv":93.16,"id":13117392},{"batb":[[2,1.99,61.37]],"batl":[[0,2.1,59.56],[2,2.26,49.02]],"ltp":2.22,"tv":1499.6,"id":13117391}]}]}
{"op":"mcm","clk":"1006394854","pt":1580595891472,"mc":[{"id":"1.168175449","rc":[{"batb":[[0,2,133.7],[1,1.99,61.37],[2,1.97,42.85]],"ltp":2.22,"tv":1499.6,"id":13117391}]}]}
{"op":"mcm","clk":"1006395076","pt":1580595893808,"mc":[{"id":"1.168175449","rc":[{"batb":[[0,2,234.69],[2,1.98,137.8]],"ltp":2.22,"tv":1499.6,"id":13117391}]}]}
{"op":"mcm","clk":"1006398261","pt":1580595928480,"mc":[{"id":"1.168175449","rc":[{"batl":[[0,5,10.08]],"ltp":4.9,"tv":93.16,"id":13117392}]}]}
{"op":"mcm","clk":"1006398367","pt":1580595929454,"mc":[{"id":"1.168175449","rc":[{"batb":[[0,6.4,73.79],[1,6,35.09],[2,1.01,0.51]],"batl":[[0,7.4,30.21],[1,7.4,0]],"ltp":0.0,"tv":0.0,"id":13117449},{"batb":[[0,5.5,22.19],[1,1.01,0.51],[2,6.2,0]],"batl":[[0,9,20.61],[1,7.8,0],[2,9,0]],"ltp":5.9,"tv":4.0,"id":13117448},{"batb":[[0,4.3,38.79],[1,1.01,0.51],[2,4.2,0]],"batl":[[0,5.3,30.29],[1,5.1,0],[2,5.3,0]],"ltp":4.9,"tv":93.16,"id":13117392},{"batb":[[0,1.85,39.34],[1,1.01,0.51],[2,1.98,0]],"batl":[[0,2.26,49.02],[1,2.18,0],[2,2.26,0]],"ltp":2.22,"tv":1499.6,"id":13117391}]}]}
{"op":"mcm","clk":"1006398544","pt":1580595931499,"mc":[{"id":"1.168175449","rc":[{"batb":[[1,6.2,78.55],[2,6,35.09]],"ltp":0.0,"tv":0.0,"id":13117449},{"batb":[[0,5.8,74.81],[1,5.7,47.68],[2,5.5,22.19]],"ltp":5.9,"tv":4.0,"id":13117448},{"batb":[[1,4.1,149.73],[2,4,105.4]],"ltp":4.9,"tv":93.16,"id":13117392},{"batb":[[0,1.86,156.22],[1,1.85,39.34],[2,1.84,173.57]],"ltp":2.22,"tv":1499.6,"id":13117391}]}]}
{"op":"mcm","clk":"1006402038","pt":1580595969841,"mc":[{"id":"1.168175449","rc":[{"batb":[[0,6,35.09],[1,1.01,0.51],[2,6,0]],"ltp":0.0,"tv":0.0,"id":13117449},{"batb":[[0,5.5,22.19],[1,1.01,0.51],[2,5.5,0]],"ltp":5.9,"tv":4.0,"id":13117448},{"batb":[[1,1.01,0.51],[2,4,0]],"ltp":4.9,"tv":93.16,"id":13117392},{"batb":[[0,1.85,39.34],[1,1.01,0.51],[2,1.84,0]],"ltp":2.22,"tv":1499.6,"id":13117391}]}]}
{"op":"mcm","clk":"1006403073","pt":1580595979498,"mc":[{"id":"1.168175449","rc":[{"batb":[[0,6.2,33.99]],"batl":[[1,7.8,28.01]],"ltp":0.0,"tv":0.0,"id":13117449},{"batb":[[0,7.6,21.72],[1,6.4,31.47],[2,1.01,0.51]],"batl":[[1,12.5,26.83]],"ltp":5.9,"tv":4.0,"id":13117448},{"batb":[[0,4.7,31.63],[1,4.5,35.25],[2,1.01,0.51]],"batl":[[1,5.7,26.12]],"ltp":4.9,"tv":93.16,"id":13117392},{"batb":[[1,1.69,52.56],[2,1.01,0.51]],"batl":[[0,1.92,38.71],[1,2.08,62.08]],"ltp":2.22,"tv":1499.6,"id":13117391}]}]}
{"op":"mcm","clk":"1006403161","pt":1580595980380,"mc":[{"id":"1.168175449","rc":[{"batb":[[0,6.2,41.55]],"batl":[[1,7.6,5.88],[2,7.8,28.01]],"ltp":0.0,"tv":0.0,"id":13117449},{"batb":[[1,7.4,5.88],[2,6.4,31.47]],"batl":[[1,9.2,5.04],[2,12.5,26.83]],"ltp":5.9,"tv":4.0,"id":13117448},{"batb":[[2,4.4,11.76]],"batl":[[0,5.2,9.24],[1,5.3,30.29],[2,5.7,26.12]],"ltp":4.9,"tv":93.16,"id":13117392},{"batl":[[1,2.02,41.17],[2,2.08,62.08]],"ltp":2.22,"tv":1499.6,"id":13117391}]}]}
{"op":"mcm","clk":"1006403265","pt":1580595981415,"mc":[{"id":"1.168175449","rc":[{"batb":[[1,1.83,50.41],[2,1.69,52.56]],"ltp":2.22,"tv":1499.6,"id":13117391}]}]}
{"op":"mcm","clk":"1006404070","pt":1580595988502,"mc":[{"id":"1.168175449","rc":[{"batb":[[0,6.8,62.94],[1,6.6,68.89],[2,6.2,41.55]],"ltp":0.0,"tv":0.0,"id":13117449},{"batb":[[0,8,42.88],[1,7.8,47.76],[2,7.6,21.72]],"ltp":5.9,"tv":4.0,"id":13117448},{"batb":[[1,4.5,96],[2,4.4,97.59]],"ltp":4.9,"tv":93.16,"id":13117392},{"batb":[[0,1.86,155.92],[1,1.85,39.34],[2,1.84,173.57]],"ltp":2.22,"tv":1499.6,"id":13117391}]}]}
{"op":"mcm","clk":"1006404544","pt":1580595993409,"mc":[{"id":"1.168175449","rc":[{"batb":[[0,6.2,33.99],[1,1.01,0.51],[2,6.2,0]],"batl":[[0,7.8,28.01],[1,7.6,0],[2,7.8,0]],"ltp":0.0,"tv":0.0,"id":13117449},{"batb":[[0,6.4,31.47],[1,1.01,0.51],[2,7.6,0]],"batl":[[0,12.5,26.83],[1,9.2,0],[2,12.5,0]],"ltp":5.9,"tv":4.0,"id":13117448},{"batb":[[0,4.5,35.25],[1,1.01,0.51],[2,4.4,0]],"batl":[[0,5.7,26.12],[1,5.3,0],[2,5.7,0]],"ltp":4.9,"tv":93.16,"id":13117392},{"batb":[[0,1.69,52.56],[1,1.01,0.51],[2,1.84,0]],"batl":[[0,2.08,62.08],[1,2.02,0],[2,2.08,0]],"ltp":2.22,"tv":1499.6,"id":13117391}]}]}
{"op":"mcm","clk":"1006404865","pt":1580595996521,"mc":[{"id":"1.168175449","rc":[{"batb":[[0,6.6,70.16],[1,6.4,73.45],[2,6.2,33.99]],"ltp":0.0,"tv":0.0,"id":13117449},{"batb":[[0,6.8,40.55],[1,6.6,68.66],[2,6.4,31.47]],"ltp":5.9,"tv":4.0,"id":13117448},{"batb":[[1,4.3,91.29],[2,4.2,95]],"ltp":4.9,"tv":93.16,"id":13117392},{"batb":[[0,1.71,150.48],[1,1.69,283.46],[2,1.01,0.51]],"ltp":2.22,"tv":1499.6,"id":13117391}]}]}
{"op":"mcm","clk":"1006405375","pt":1580596001406,"mc":[{"id":"1.168175449","rc":[{"batb":[[0,6.2,33.99],[1,1.01,0.51],[2,6.2,0]],"ltp":0.0,"tv":0.0,"id":13117449},{"batb":[[0,6.4,31.47],[1,1.01,0.51],[2,6.4,0]],"ltp":5.9,"tv":4.0,"id":13117448},{"batb":[[1,1.01,0.51],[2,4.2,0]],"ltp":4.9,"tv":93.16,"id":13117392}]}]}
{"op":"mcm","clk":"1006405714","pt":1580596004525,"mc":[{"id":"1.168175449","rc":[{"batb":[[0,7,85.05],[1,6.8,64.07],[2,6.6,29.74]],"batl":[[0,7.8,33.89],[1,8,26.04]],"ltp":0.0,"tv":0.0,"id":13117449},{"batb":[[0,10.5,62.71],[1,10,67.14],[2,9.8,29.51]],"batl":[[0,12.5,30.19],[1,19,12.59]],"ltp":5.9,"tv":4.0,"id":13117448},{"batb":[[0,5,27.22],[1,4.8,30.53],[2,4.7,104.12]],"batl":[[0,5.5,9.24],[1,5.7,26.12],[2,6.2,22.66]],"ltp":4.9,"tv":93.16,"id":13117392},{"batb":[[1,1.7,59.65],[2,1.69,283.46]],"batl":[[0,1.76,51.46],[1,1.85,42.01],[2,1.88,41.62]],"ltp":2.22,"tv":1499.6,"id":13117391}]}]}
{"op":"mcm","clk":"1006408053","pt":1580596026433,"mc":[{"id":"1.168175449","rc":[{"batl":[[0,7.8,28.01]],"ltp":0.0,"tv":0.0,"id":13117449},{"batb":[[1,1.69,283.46],[2,1.57,68.14]],"ltp":2.22,"tv":1499.6,"id":13117391}]}]}
{"op":"mcm","clk":"1006408150","pt":1580596027421,"mc":[{"id":"1.168175449","rc":[{"batb":[[0,6.8,64.07],[1,6.4,31.94],[2,1.01,0.51]],"batl":[[0,8,26.04],[1,8,0]],"ltp":0.0,"tv":0.0,"id":13117449},{"batb":[[0,8,18.41],[1,1.01,0.51],[2,9.8,0]],"batl":[[0,19,12.59],[1,19,0]],"ltp":5.9,"tv":4.0,"id":13117448},{"batb":[[0,4.8,30.53],[1,1.01,0.51],[2,4.7,0]],"batl":[[0,6.2,22.66],[1,5.7,0],[2,6.2,0]],"ltp":4.9,"tv":93.16,"id":13117392},{"batb":[[0,1.57,68.14],[1,1.01,0.51],[2,1.57,0]],"batl":[[0,1.88,41.62],[1,1.85,0],[2,1.88,0]],"ltp":2.22,"tv":1499.6,"id":13117391}]}]}
{"op":"mcm","clk":"1006408488","pt":1580596030556,"mc":[{"id":"1.168175449","rc":[{"batb":[[0,6.8,84.29],[1,6.6,68.37],[2,6.4,30.69]],"batl":[[0,8.2,24.94]],"ltp":0.0,"tv":0.0,"id":13117449},{"batb":[[0,8.6,49.38],[1,8.4,40.59],[2,8.2,17.7]],"batl":[[0,19,12.12]],"ltp":5.9,"tv":4.0,"id":13117448},{"batb":[[1,4.5,113.9],[2,4.4,84.97]],"ltp":4.9,"tv":93.16,"id":13117392},{"batb":[[0,1.56,69.4]],"batl":[[0,1.86,42.49]],"ltp":2.22,"tv":1499.6,"id":13117391}]}]}
{"op":"mcm","clk":"1006408792","pt":1580596033541,"mc":[{"id":"1.168175449","rc":[{"batb":[[0,1.82,113.17],[1,1.8,186.39],[2,1.56,69.4]],"ltp":2.22,"tv":1499.6,"id":13117391}]}]}
{"op":"mcm","clk":"1006408884","pt":1580596034430,"mc":[{"id":"1.168175449","rc":[{"batl":[[0,7.6,28.8],[1,7.8,5.88],[2,8,26.2]],"ltp":0.0,"tv":0.0,"id":13117449},{"batl":[[0,10,16.92],[1,15.5,18.49]],"ltp":5.9,"tv":4.0,"id":13117448},{"batb":[[1,4.5,149.23],[2,4.4,96.73]],"batl":[[0,5.3,9.24],[1,5.4,29.58],[2,5.8,25.18]],"ltp":4.9,"tv":93.16,"id":13117392},{"batb":[[2,1.79,43.2]],"batl":[[1,1.94,42.01],[2,2.02,33.05]],"ltp":2.22,"tv":1499.6,"id":13117391}]}]}
{"op":"mcm","clk":"1006409113","pt":1580596036257,"mc":[{"id":"1.168175449","rc":[{"batl":[[0,10,21.12]],"ltp":5.9,"tv":4.0,"id":13117448},{"trd":[[1.82,15]],"batb":[[0,1.82,105.67]],"ltp":1.82,"tv":1514.6,"id":13117391}],"tv":1611.77}]}
{"op":"mcm","clk":"1006410370","pt":1580596049551,"mc":[{"id":"1.168175449","rc":[{"batb":[[0,6.6,68.37],[1,6.2,32.73],[2,1.01,0.51]],"batl":[[0,8,26.2],[1,7.8,0],[2,8,0]],"ltp":0.0,"tv":0.0,"id":13117449},{"batb":[[0,6.6,28.33],[1,1.01,0.51],[2,8.2,0]],"batl":[[0,15.5,18.49],[1,15.5,0]],"ltp":5.9,"tv":4.0,"id":13117448},{"batb":[[0,4.5,35.33],[1,1.01,0.51],[2,4.4,0]],"batl":[[0,5.8,25.18],[1,5.4,0],[2,5.8,0]],"ltp":4.9,"tv":93.16,"id":13117392},{"batb":[[0,1.62,59.88],[1,1.01,0.51],[2,1.79,0]],"batl":[[0,2.02,33.05],[1,1.94,0],[2,2.02,0]],"ltp":1.82,"tv":1514.6,"id":13117391}]}]}
{"op":"mcm","clk":"1006410567","pt":1580596051793,"mc":[{"id":"1.168175449","rc":[{"batb":[[0,6.6,83.49],[1,6.4,73.12],[2,6.2,32.73]],"ltp":0.0,"tv":0.0,"id":13117449},{"batb":[[0,7,43.16],[1,6.8,64.28],[2,6.6,28.33]],"ltp":5.9,"tv":4.0,"id":13117448},{"batb":[[1,4.3,112.26],[2,4.2,94.66]],"ltp":4.9,"tv":93.16,"id":13117392},{"batb":[[0,1.64,232.52],[1,1.63,132.42],[2,1.62,59.88]],"ltp":1.82,"tv":1514.6,"id":13117391}]}]}
{"op":"mcm","clk":"1006411975","pt":1580596066467,"mc":[{"id":"1.168175449","rc":[{"batb":[[0,6.2,32.73],[1,1.01,0.51],[2,6.2,0]],"ltp":0.0,"tv":0.0,"id":13117449},{"batb":[[0,6.6,28.33],[1,1.01,0.51],[2,6.6,0]],"ltp":5.9,"tv":4.0,"id":13117448},{"batb":[[1,1.01,0.51],[2,4.2,0]],"ltp":4.9,"tv":93.16,"id":13117392}]}]}
{"op":"mcm","clk":"1006412342","pt":1580596069562,"mc":[{"id":"1.168175449","rc":[{"batb":[[0,7.2,54.87],[1,7,60.9],[2,6.8,27.77]],"batl":[[1,8.4,23.92]],"ltp":0.0,"tv":0.0,"id":13117449},{"batb":[[0,13,23.61],[1,12.5,43.31],[2,11.5,19.99]],"batl":[[1,26,13.93]],"ltp":5.9,"tv":4.0,"id":13117448},{"batb":[[0,5.1,26.2],[1,4.9,82.86],[2,4.8,70.56]],"batl":[[1,6.4,21.24]],"ltp":4.9,"tv":93.16,"id":13117392},{"batl":[[0,1.69,58.62],[1,1.8,47.37]],"ltp":1.82,"tv":1514.6,"id":13117391}]}]}
{"op":"mcm","clk":"1006412478","pt":1580596070496,"mc":[{"id":"1.168175449","rc":[{"batl":[[0,8,32.08]],"ltp":0.0,"tv":0.0,"id":13117449},{"batb":[[2,11.5,23.35]],"ltp":5.9,"tv":4.0,"id":13117448},{"batl":[[0,5.7,8.4],[1,5.8,25.18],[2,6.4,21.24]],"ltp":4.9,"tv":93.16,"id":13117392}]}]}
{"op":"mcm","clk":"1006412673","pt":1580596072118,"mc":[{"id":"1.168175449","rc":[{"batb":[[1,1.63,198.8]],"batl":[[1,1.77,42.01],[2,1.8,47.37]],"ltp":1.82,"tv":1514.6,"id":13117391}]}]}
{"op":"mcm","clk":"1006413725","pt":1580596080393,"mc":[{"id":"1.168175449","rc":[{"batb":[[0,7,46.22],[1,6.4,37.7],[2,1.01,0.51]],"batl":[[0,8,5.88]],"ltp":0.0,"tv":0.0,"id":13117449},{"batb":[[0,11.5,3.36],[1,9.2,34.78],[2,1.01,0.51]],"batl":[[0,26,13.93],[1,26,0]],"ltp":5.9,"tv":4.0,"id":13117448},{"batb":[[0,4.9,29.35],[1,4.7,10.92],[2,1.01,0.51]],"batl":[[1,6.4,21.24],[2,6.4,0]],"ltp":4.9,"tv":93.16,"id":13117392},{"batb":[[0,1.63,66.38],[1,1.5,79.31],[2,1.01,0.51]],"batl":[[0,1.77,42.01],[1,1.8,47.37],[2,1.8,0]],"ltp":1.82,"tv":1514.6,"id":13117391}]}]}
{"op":"mcm","clk":"1006413871","pt":1580596081535,"mc":[{"id":"1.168175449","rc":[{"batb":[[1,6.4,30.14]],"batl":[[0,8.4,23.92],[1,8.4,0]],"ltp":0.0,"tv":0.0,"id":13117449},{"batb":[[0,9.2,34.78],[1,1.01,0.51],[2,1.01,0]],"ltp":5.9,"tv":4.0,"id":13117448},{"batb":[[1,1.01,0.51],[2,1.01,0]],"batl":[[0,6.4,21.24],[1,6.4,0]],"ltp":4.9,"tv":93.16,"id":13117392},{"batb":[[0,1.5,79.31],[1,1.01,0.51],[2,1.01,0]],"batl":[[0,1.8,47.37],[1,1.8,0]],"ltp":1.82,"tv":1514.6,"id":13117391}]}]}
{"op":"mcm","clk":"1006414136","pt":1580596083521,"mc":[{"id":"1.168175449","rc":[{"batb":[[1,6.8,65.02],[2,6.4,30.14]],"ltp":0.0,"tv":0.0,"id":13117449},{"batb":[[0,9.8,43.23],[1,9.6,30.6],[2,9.2,34.78]],"ltp":5.9,"tv":4.0,"id":13117448},{"batb":[[1,4.6,115.23],[2,4.5,80.67]],"ltp":4.9,"tv":93.16,"id":13117392},{"batb":[[0,1.52,174.54],[1,1.51,177.51],[2,1.5,79.31]],"ltp":1.82,"tv":1514.6,"id":13117391}]}]}
{"op":"mcm","clk":"1006414441","pt":1580596086418,"mc":[{"id":"1.168175449","rc":[{"batb":[[0,6.4,30.14],[1,1.01,0.51],[2,6.4,0]],"ltp":0.0,"tv":0.0,"id":13117449},{"batb":[[0,9.2,34.78],[1,1.01,0.51],[2,9.2,0]],"ltp":5.9,"tv":4.0,"id":13117448},{"batb":[[1,1.01,0.51],[2,4.5,0]],"ltp":4.9,"tv":93.16,"id":13117392}]}]}
{"op":"mcm","clk":"1006414844","pt":1580596089386,"mc":[{"id":"1.168175449","rc":[{"batb":[[0,7.6,36.61],[1,7.4,54.49],[2,7,25.26]],"batl":[[1,8.6,22.66]],"ltp":0.0,"tv":0.0,"id":13117449},{"batb":[[0,23,8.84],[1,22,26.88],[2,17.5,15.26]],"ltp":5.9,"tv":4.0,"id":13117448},{"batb":[[0,5.5,22.03],[1,5.2,101.97],[2,5.1,61.23]],"batl":[[1,6.6,38.63]],"ltp":4.9,"tv":93.16,"id":13117392},{"batl":[[0,1.57,77.34],[1,1.66,62.08]],"ltp":1.82,"tv":1514.6,"id":13117391}]}]}
{"op":"mcm","clk":"1006414943","pt":1580596090434,"mc":[{"id":"1.168175449","rc":[{"batb":[[2,5.1,71.31]],"batl":[[0,6.2,7.56],[1,6.4,21.24],[2,6.6,38.63]],"ltp":4.9,"tv":93.16,"id":13117392},{"batl":[[1,1.58,42.01],[2,1.66,62.08]],"ltp":1.82,"tv":1514.6,"id":13117391}]}]}
{"op":"mcm","clk":"1006415217","pt":1580596092406,"mc":[{"id":"1.168175449","rc":[{"batb":[[2,7.2,6.72]],"batl":[[2,9,5.04]],"ltp":0.0,"tv":0.0,"id":13117449}]}]}
{"op":"mcm","clk":"1006416096","pt":1580596099537,"mc":[{"id":"1.168175449","rc":[{"batb":[[0,7.6,51.11]],"ltp":0.0,"tv":0.0,"id":13117449},{"batb":[[0,23,13.22]],"ltp":5.9,"tv":4.0,"id":13117448}]}]}
{"op":"mcm","clk":"1006416671","pt":1580596104514,"mc":[{"id":"1.168175449","rc":[{"batb":[[0,1.51,177.51],[1,1.5,79.31],[2,1.47,89.06]],"ltp":1.82,"tv":1514.6,"id":13117391}]}]}
{"op":"mcm","clk":"1006417027","pt":1580596107441,"mc":[{"id":"1.168175449","rc":[{"batb":[[0,1.51,304.06],[1,1.5,262.34]],"ltp":1.82,"tv":1514.6,"id":13117391}]}]}
{"op":"mcm","clk":"1006417448","pt":1580596110931,"mc":[{"id":"1.168175449","rc":[{"batb":[[0,7.6,61.24]],"ltp":0.0,"tv":0.0,"id":13117449},{"batb":[[0,23,16.29]],"ltp":5.9,"tv":4.0,"id":13117448}]}]}
{"op":"mcm","clk":"1006418042","pt":1580596116553,"mc":[{"id":"1.168175449","rc":[{"batb":[[0,7.4,35.01],[1,7.2,6.72],[2,6.6,28.25]],"batl":[[0,8.6,22.66],[1,9,5.04],[2,9,0]],"ltp":0.0,"tv":0.0,"id":13117449},{"batb":[[0,13,16.05],[1,1.01,0.51],[2,17.5,0]],"ltp":5.9,"tv":4.0,"id":13117448},{"batb":[[0,5.2,25.02],[1,5.1,10.08],[2,1.01,0.51]],"batl":[[1,6.6,38.63],[2,6.6,0]],"ltp":4.9,"tv":93.16,"id":13117392},{"batb":[[0,1.47,89.06],[1,1.45,90.48],[2,1.01,0.51]],"batl":[[0,1.58,42.01],[1,1.66,62.08],[2,1.82,7.5]],"ltp":1.82,"tv":1514.6,"id":13117391}]}]}
{"op":"mcm","clk":"1006418106","pt":1580596117193,"mc":[{"id":"1.168175449","rc":[{"batb":[[1,6.6,28.25],[2,1.01,0.51]],"batl":[[1,9,0]],"ltp":0.0,"tv":0.0,"id":13117449},{"batb":[[1,1.01,0.51],[2,1.01,0]],"batl":[[0,6.6,38.63],[1,6.6,0]],"ltp":4.9,"tv":93.16,"id":13117392},{"batb":[[0,1.45,90.48],[1,1.01,0.51],[2,1.01,0]],"batl":[[0,1.51,7.5]],"ltp":1.82,"tv":1514.6,"id":13117391}]}]}
{"op":"mcm","clk":"1006418239","pt":1580596118516,"mc":[{"id":"1.168175449","rc":[{"batl":[[0,1.66,62.08],[1,1.82,7.5],[2,1.82,0]],"ltp":1.82,"tv":1514.6,"id":13117391}]}]}
{"op":"mcm","clk":"1006418280","pt":1580596118929,"mc":[{"id":"1.168175449","rc":[{"batb":[[1,7.2,58.5],[2,6.6,28.25]],"ltp":0.0,"tv":0.0,"id":13117449},{"batb":[[0,15.5,35.89],[1,15,29.68],[2,13,16.05]],"ltp":5.9,"tv":4.0,"id":13117448},{"batb":[[1,5,45.82],[2,4.9,67.32]],"ltp":4.9,"tv":93.16,"id":13117392},{"batb":[[0,1.47,282.4],[1,1.46,204.86],[2,1.45,90.48]],"ltp":1.82,"tv":1514.6,"id":13117391}]}]}
{"op":"mcm","clk":"1006418877","pt":1580596125360,"mc":[{"id":"1.168175449","rc":[{"batb":[[0,6.6,28.25],[1,1.01,0.51],[2,6.6,0]],"ltp":0.0,"tv":0.0,"id":13117449},{"batb":[[0,13,16.05],[1,1.01,0.51],[2,13,0]],"ltp":5.9,"tv":4.0,"id":13117448},{"batb":[[1,1.01,0.51],[2,4.9,0]],"ltp":4.9,"tv":93.16,"id":13117392}]}]}
{"op":"mcm","clk":"1006419103","pt":1580596127058,"mc":[{"id":"1.168175449","rc":[{"trd":[[1.47,15]],"batb":[[0,1.47,274.9]],"ltp":1.47,"tv":1529.6,"id":13117391}],"tv":1626.77}]}
{"op":"mcm","clk":"1006419231","pt":1580596128157,"mc":[{"id":"1.168175449","rc":[{"batb":[[0,7.8,60.11],[1,7.6,51.6],[2,7.4,5.88]],"batl":[[1,9.2,5.04]],"ltp":0.0,"tv":0.0,"id":13117449},{"batb":[[0,30,27.59],[1,29,14.97],[2,13,16.05]],"ltp":5.9,"tv":4.0,"id":13117448},{"batb":[[0,5.3,99],[1,5.2,83.32],[2,1.01,0.51]],"batl":[[0,6.4,7.56],[1,6.6,38.63]],"ltp":4.9,"tv":93.16,"id":13117392},{"batl":[[0,1.54,42.01],[1,1.66,62.08],[2,1.82,7.5]],"ltp":1.47,"tv":1529.6,"id":13117391}]}]}
{"op":"mcm","clk":"1006419315","pt":1580596128941,"mc":[{"id":"1.168175449","rc":[{"batl":[[1,8.8,21.48],[2,9.2,5.04]],"ltp":0.0,"tv":0.0,"id":13117449},{"batb":[[2,23,6.75]],"ltp":5.9,"tv":4.0,"id":13117448},{"batb":[[0,5.7,41.54],[1,5.4,22.9],[2,5.3,99]],"batl":[[2,7,35.33]],"ltp":4.9,"tv":93.16,"id":13117392},{"batl":[[0,1.51,88.05],[1,1.54,42.01],[2,1.59,72.39]],"ltp":1.47,"tv":1529.6,"id":13117391}]}]}
{"op":"mcm","clk":"1006420458","pt":1580596139873,"mc":[{"id":"1.168175449","rc":[{"trd":[[1.47,30]],"batb":[[0,1.47,267.4]],"ltp":1.47,"tv":1544.6,"id":13117391}],"tv":1641.77}]}
{"op":"mcm","clk":"1006420728","pt":1580596142475,"mc":[{"id":"1.168175449","rc":[{"batb":[[0,7.6,29.28],[1,7.4,5.88],[2,6.8,26.83]],"batl":[[0,8.8,21.48],[1,9.2,5.04],[2,9.2,0]],"ltp":0.0,"tv":0.0,"id":13117449},{"batb":[[0,16.5,9.13],[1,1.01,0.51],[2,23,0]],"ltp":5.9,"tv":4.0,"id":13117448},{"batb":[[0,5.4,22.9],[1,5.3,9.24],[2,1.01,0.51]],"batl":[[1,7,35.33],[2,7,0]],"ltp":4.9,"tv":93.16,"id":13117392},{"batb":[[0,1.44,94.94],[1,1.41,101.81],[2,1.01,0.51]],"batl":[[0,1.54,42.01],[1,1.59,72.39],[2,1.82,7.5]],"ltp":1.47,"tv":1544.6,"id":13117391}]}]}
{"op":"mcm","clk":"1006420806","pt":1580596143201,"mc":[{"id":"1.168175449","rc":[{"batb":[[1,6.8,26.83],[2,1.01,0.51]],"batl":[[1,9.2,0]],"ltp":0.0,"tv":0.0,"id":13117449},{"batb":[[1,1.01,0.51],[2,1.01,0]],"batl":[[0,7,35.33],[1,7,0]],"ltp":4.9,"tv":93.16,"id":13117392},{"batb":[[0,1.41,101.81],[1,1.01,0.51],[2,1.01,0]],"batl":[[0,1.59,72.39],[1,1.82,7.5],[2,1.82,0]],"ltp":1.47,"tv":1544.6,"id":13117391}]}]}
{"op":"mcm","clk":"1006421085","pt":1580596145100,"mc":[{"id":"1.168175449","rc":[{"batb":[[1,7.4,55.34],[2,6.8,26.83]],"ltp":0.0,"tv":0.0,"id":13117449},{"batb":[[0,21,18.97],[1,20,32.58],[2,16.5,9.13]],"ltp":5.9,"tv":4.0,"id":13117448},{"batb":[[1,5.1,86.76],[2,5,63.74]],"ltp":4.9,"tv":93.16,"id":13117392},{"batb":[[0,1.44,274.05],[1,1.43,224.1],[2,1.41,101.81]],"ltp":1.47,"tv":1544.6,"id":13117391}]}]}
{"op":"mcm","clk":"1006421821","pt":1580596151308,"mc":[{"id":"1.168175449","rc":[{"batb":[[0,1.41,101.81],[1,1.01,0.51],[2,1.41,0]],"ltp":1.47,"tv":1544.6,"id":13117391}]}]}
{"op":"mcm","clk":"1006422303","pt":1580596154497,"mc":[{"id":"1.168175449","rc":[{"batl":[[0,8.2,25.34],[1,8.4,23.92],[2,8.8,5.04]],"ltp":0.0,"tv":0.0,"id":13117449},{"batl":[[0,23,8.66]],"ltp":5.9,"tv":4.0,"id":13117448},{"batb":[[1,5.1,123.36]],"batl":[[0,6,8.4],[1,6.2,22.11],[2,6.6,39.97]],"ltp":4.9,"tv":93.16,"id":13117392},{"batb":[[0,1.53,352.29],[1,1.52,173.49],[2,1.49,85.7]],"batl":[[1,1.6,42.01],[2,1.71,56.34]],"ltp":1.47,"tv":1544.6,"id":13117391}]}]}
{"op":"mcm","clk":"1006422607","pt":1580596156896,"mc":[{"id":"1.168175449","rc":[{"batb":[[2,7,6.72]],"ltp":0.0,"tv":0.0,"id":13117449}]}]}
{"op":"mcm","clk":"1006424243","pt":1580596172520,"mc":[{"id":"1.168175449","rc":[{"batb":[[0,7,6.72],[1,6.8,26.83],[2,6.6,29.74]],"ltp":0.0,"tv":0.0,"id":13117449},{"batb":[[0,16.5,9.13],[1,11.5,20.93],[2,1.01,0.51]],"ltp":5.9,"tv":4.0,"id":13117448},{"batb":[[1,5.1,36.6],[2,1.01,0.51]],"ltp":4.9,"tv":93.16,"id":13117392},{"batb":[[0,1.53,74.2],[1,1.49,85.7],[2,1.47,86.55]],"ltp":1.47,"tv":1544.6,"id":13117391}]}]}
{"op":"mcm","clk":"1006424333","pt":1580596173319,"mc":[{"id":"1.168175449","rc":[{"batb":[[0,6.6,29.74],[1,1.01,0.51],[2,6.6,0]],"batl":[[0,8.4,23.92],[1,8.4,0],[2,8.8,0]],"ltp":0.0,"tv":0.0,"id":13117449},{"batb":[[0,11.5,20.93],[1,1.01,0.51],[2,1.01,0]],"ltp":5.9,"tv":4.0,"id":13117448},{"batb":[[0,5.1,26.52],[1,1.01,0.51],[2,1.01,0]],"batl":[[0,6.6,39.97],[1,6.2,0],[2,6.6,0]],"ltp":4.9,"tv":93.16,"id":13117392},{"batb":[[0,1.47,86.55],[1,1.01,0.51],[2,1.47,0]],"batl":[[0,1.71,56.34],[1,1.82,7.5],[2,1.71,0]],"ltp":1.47,"tv":1544.6,"id":13117391}]}]}
{"op":"mcm","clk":"1006424568","pt":1580596175548,"mc":[{"id":"1.168175449","rc":[{"batb":[[0,7.2,52.19],[1,7,61.73],[2,6.6,29.74]],"ltp":0.0,"tv":0.0,"id":13117449},{"batb":[[0,13.5,40.07],[1,13,39.85],[2,11.5,20.93]],"ltp":5.9,"tv":4.0,"id":13117448},{"batb":[[1,4.9,41.82],[2,4.8,70.59]],"ltp":4.9,"tv":93.16,"id":13117392},{"batb":[[0,1.48,277.38],[1,1.47,285.58],[2,1.01,0.51]],"ltp":1.47,"tv":1544.6,"id":13117391}]}]}
{"op":"mcm","clk":"1006425634","pt":1580596186456,"mc":[{"id":"1.168175449","rc":[{"batb":[[0,6.6,29.74],[1,1.01,0.51],[2,6.6,0]],"ltp":0.0,"tv":0.0,"id":13117449},{"batb":[[0,11.5,20.93],[1,1.01,0.51],[2,11.5,0]],"ltp":5.9,"tv":4.0,"id":13117448},{"batb":[[1,1.01,0.51],[2,4.8,0]],"ltp":4.9,"tv":93.16,"id":13117392}]}]}
{"op":"mcm","clk":"1006425958","pt":1580596189546,"mc":[{"id":"1.168175449","rc":[{"batb":[[0,7.8,27.36],[1,7.6,52.35],[2,7,25.34]],"batl":[[1,8.6,22.66]],"ltp":0.0,"tv":0.0,"id":13117449},{"batb":[[0,30,14.24],[1,29,15.42],[2,22,7.72]],"ltp":5.9,"tv":4.0,"id":13117448},{"batb":[[0,5.6,21.48],[1,5.3,87.18],[2,5.2,58.71]],"batl":[[1,6.8,36.59]],"ltp":4.9,"tv":93.16,"id":13117392},{"batb":[[2,1.42,98.67]],"batl":[[0,1.53,84.27],[1,1.62,67.59],[2,1.71,56.34]],"ltp":1.47,"tv":1544.6,"id":13117391}]}]}
{"op":"mcm","clk":"1006426065","pt":1580596190539,"mc":[{"id":"1.168175449","rc":[{"batb":[[2,7.2,6.72]],"ltp":0.0,"tv":0.0,"id":13117449},{"batb":[[2,5.2,67.95]],"batl":[[0,6.2,7.56],[1,6.6,39.97],[2,6.8,36.59]],"ltp":4.9,"tv":93.16,"id":13117392},{"batb":[[2,1.45,93.26]],"batl":[[1,1.55,42.01],[2,1.62,67.59]],"ltp":1.47,"tv":1544.6,"id":13117391}]}]}
{"op":"mcm","clk":"1006426263","pt":1580596192329,"mc":[{"id":"1.168175449","rc":[{"batl":[[2,9,5.04]],"ltp":0.0,"tv":0.0,"id":13117449}]}]}
{"op":"mcm","clk":"1006428475","pt":1580596213443,"mc":[{"id":"1.168175449","rc":[{"batb":[[0,6.6,28.48],[1,1.01,0.51],[2,7.2,0]],"batl":[[0,8.6,22.66],[1,8.6,0],[2,9,0]],"ltp":0.0,"tv":0.0,"id":13117449},{"batb":[[0,15.5,10.54],[1,1.01,0.51],[2,22,0]],"ltp":5.9,"tv":4.0,"id":13117448},{"batb":[[0,5.3,24.16],[1,1.01,0.51],[2,5.2,0]],"batl":[[0,6.8,36.59],[1,6.6,0],[2,6.8,0]],"ltp":4.9,"tv":93.16,"id":13117392},{"batb":[[0,1.42,98.67],[1,1.01,0.51],[2,1.45,0]],"batl":[[0,1.62,67.59],[1,1.82,7.5],[2,1.62,0]],"ltp":1.47,"tv":1544.6,"id":13117391}]}]}
{"op":"mcm","clk":"1006428809","pt":1580596216558,"mc":[{"id":"1.168175449","rc":[{"batb":[[0,7.4,48.39],[1,6.6,28.48],[2,1.01,0.51]],"ltp":0.0,"tv":0.0,"id":13117449},{"batb":[[1,5.1,41.77],[2,1.01,0.51]],"ltp":4.9,"tv":93.16,"id":13117392}]}]}
{"op":"mcm","clk":"1006428902","pt":1580596217391,"mc":[{"id":"1.168175449","rc":[{"batb":[[0,7.6,62.94],[1,7.4,48.39],[2,6.6,28.48]],"ltp":0.0,"tv":0.0,"id":13117449},{"batb":[[0,27,15],[1,26,19.22],[2,15.5,10.54]],"ltp":5.9,"tv":4.0,"id":13117448},{"batb":[[1,5.2,94.31],[2,5.1,60.85]],"ltp":4.9,"tv":93.16,"id":13117392},{"batb":[[0,1.5,159.3],[1,1.49,187.4],[2,1.42,98.67]],"ltp":1.47,"tv":1544.6,"id":13117391}]}]}
{"op":"mcm","clk":"1006429286","pt":1580596221396,"mc":[{"id":"1.168175449","rc":[{"batb":[[0,7.4,48.39],[1,6.6,28.48],[2,1.01,0.51]],"ltp":0.0,"tv":0.0,"id":13117449},{"batb":[[0,15.5,10.54],[1,1.01,0.51],[2,15.5,0]],"ltp":5.9,"tv":4.0,"id":13117448},{"batb":[[1,5.1,41.77],[2,1.01,0.51]],"ltp":4.9,"tv":93.16,"id":13117392},{"batb":[[0,1.42,98.67],[1,1.01,0.51],[2,1.42,0]],"ltp":1.47,"tv":1544.6,"id":13117391}]}]}
{"op":"mcm","clk":"1006429581","pt":1580596224165,"mc":[{"id":"1.168175449","rc":[{"batb":[[1,7.2,58.23],[2,6.6,28.48]],"ltp":0.0,"tv":0.0,"id":13117449},{"batb":[[0,19,28.8],[1,18.5,19.35],[2,15.5,10.54]],"ltp":5.9,"tv":4.0,"id":13117448},{"batb":[[2,5,64.43]],"ltp":4.9,"tv":93.16,"id":13117392},{"batb":[[0,1.45,143.06],[1,1.44,216.34],[2,1.42,98.67]],"ltp":1.47,"tv":1544.6,"id":13117391}]}]}
{"op":"mcm","clk":"1006430720","pt":1580596234487,"mc":[{"id":"1.168175449","rc":[{"batb":[[0,1.42,98.67],[1,1.01,0.51],[2,1.42,0]],"ltp":1.47,"tv":1544.6,"id":13117391}]}]}
{"op":"mcm","clk":"1006431128","pt":1580596237503,"mc":[{"id":"1.168175449","rc":[{"batb":[[0,1.56,137.96],[1,1.55,159.97],[2,1.42,98.67]],"ltp":1.47,"tv":1544.6,"id":13117391}]}]}
{"op":"mcm","clk":"1006431238","pt":1580596238486,"mc":[{"id":"1.168175449","rc":[{"batb":[[2,7,6.72]],"batl":[[0,7.8,26.83],[1,8.2,25.02],[2,8.8,5.04]],"ltp":0.0,"tv":0.0,"id":13117449},{"batl":[[0,22,9.99]],"ltp":5.9,"tv":4.0,"id":13117448},{"batb":[[2,5,74.51]],"batl":[[0,6,31.61],[1,6.6,40.13]],"ltp":4.9,"tv":93.16,"id":13117392},{"batb":[[0,1.56,207.2],[2,1.5,84.02]],"batl":[[0,1.61,42.01],[1,1.62,67.59],[2,1.78,49.25]],"ltp":1.47,"tv":1544.6,"id":13117391}]}]}
{"op":"mcm","clk":"1006431345","pt":1580596239525,"mc":[{"id":"1.168175449","rc":[{"batb":[[2,6.6,28.48]],"batl":[[2,8.8,0]],"ltp":0.0,"tv":0.0,"id":13117449},{"batl":[[0,1.62,67.59],[1,1.78,49.25],[2,1.82,7.5]],"ltp":1.47,"tv":1544.6,"id":13117391}]}]}
{"op":"mcm","clk":"1006431583","pt":1580596241507,"mc":[{"id":"1.168175449","rc":[{"batb":[[2,6.8,6.72]],"batl":[[2,8.6,5.04]],"ltp":0.0,"tv":0.0,"id":13117449},{"batl":[[1,1.63,42.01],[2,1.78,49.25]],"ltp":1.47,"tv":1544.6,"id":13117391}]}]}
{"op":"mcm","clk":"1006432105","pt":1580596245523,"mc":[{"id":"1.168175449","rc":[{"batl":[[0,8.2,25.02],[1,8.6,5.04],[2,8.6,0]],"ltp":0.0,"tv":0.0,"id":13117449},{"batb":[[2,10,29.11]],"ltp":5.9,"tv":4.0,"id":13117448},{"batb":[[0,5.1,41.77],[1,5,74.51],[2,4.9,28.95]],"batl":[[0,6,8.4]],"ltp":4.9,"tv":93.16,"id":13117392},{"batb":[[0,1.56,137.96]],"batl":[[0,1.63,42.01],[1,1.78,49.25],[2,1.82,7.5]],"ltp":1.47,"tv":1544.6,"id":13117391}]}]}
{"op":"mcm","clk":"1006432875","pt":1580596251833,"mc":[{"id":"1.168175449","rc":[{"batb":[[0,19,18.79],[1,10,29.11],[2,1.01,0.51]],"ltp":5.9,"tv":4.0,"id":13117448}]}]}
{"op":"mcm","clk":"1006433207","pt":1580596255119,"mc":[{"id":"1.168175449","rc":[{"batb":[[0,19.5,11.82],[1,19,18.79],[2,10,29.11]],"ltp":5.9,"tv":4.0,"id":13117448}]}]}
{"op":"mcm","clk":"1006434055","pt":1580596262977,"mc":[{"id":"1.168175449","rc":[{"batb":[[0,1.55,159.97],[1,1.5,84.02],[2,1.47,85.45]],"ltp":1.47,"tv":1544.6,"id":13117391}]}]}
{"op":"mcm","clk":"1006434246","pt":1580596264532,"mc":[{"id":"1.168175449","rc":[{"batb":[[0,6.8,6.72],[1,6.4,31.16],[2,1.01,0.51]],"ltp":0.0,"tv":0.0,"id":13117449},{"batb":[[0,10,29.11],[1,1.01,0.51],[2,10,0]],"ltp":5.9,"tv":4.0,"id":13117448},{"batb":[[0,5,10.08],[1,4.9,28.95],[2,1.01,0.51]],"ltp":4.9,"tv":93.16,"id":13117392},{"batb":[[0,1.5,84.02],[1,1.47,85.45],[2,1.01,0.51]],"ltp":1.47,"tv":1544.6,"id":13117391}]}]}
{"op":"mcm","clk":"1006434339","pt":1580596265413,"mc":[{"id":"1.168175449","rc":[{"batb":[[0,6.4,31.16],[1,1.01,0.51],[2,1.01,0]],"batl":[[1,8.6,0]],"ltp":0.0,"tv":0.0,"id":13117449},{"batb":[[0,4.9,28.95],[1,1.01,0.51],[2,1.01,0]],"batl":[[0,6.6,40.13],[1,6.6,0]],"ltp":4.9,"tv":93.16,"id":13117392},{"batb":[[0,1.47,85.45],[1,1.01,0.51],[2,1.01,0]],"batl":[[0,1.78,49.25],[1,1.82,7.5],[2,1.82,0]],"ltp":1.47,"tv":1544.6,"id":13117391}]}]}
{"op":"mcm","clk":"1006434495","pt":1580596267141,"mc":[{"id":"1.168175449","rc":[{"batb":[[0,7,69.16],[1,6.8,65.34],[2,6.4,31.16]],"ltp":0.0,"tv":0.0,"id":13117449},{"batb":[[0,11.5,28.08],[1,11,57.29],[2,10,29.11]],"ltp":5.9,"tv":4.0,"id":13117448},{"batb":[[1,4.7,89.95],[2,4.6,77]],"ltp":4.9,"tv":93.16,"id":13117392},{"batb":[[0,1.48,321.27],[1,1.47,284.84],[2,1.01,0.51]],"ltp":1.47,"tv":1544.6,"id":13117391}]}]}
{"op":"mcm","clk":"1006436255","pt":1580596283530,"mc":[{"id":"1.168175449","rc":[{"batb":[[0,6.4,31.16],[1,1.01,0.51],[2,6.4,0]],"ltp":0.0,"tv":0.0,"id":13117449},{"batb":[[0,10,29.11],[1,1.01,0.51],[2,10,0]],"ltp":5.9,"tv":4.0,"id":13117448},{"batb":[[1,1.01,0.51],[2,4.6,0]],"ltp":4.9,"tv":93.16,"id":13117392},{"batb":[[0,1.47,85.45],[1,1.01,0.51],[2,1.01,0]],"ltp":1.47,"tv":1544.6,"id":13117391}]}]}
{"op":"mcm","clk":"1006436681","pt":1580596287456,"mc":[{"id":"1.168175449","rc":[{"batb":[[0,7.6,50.58],[1,7.4,54.9],[2,6.8,26.52]],"batl":[[1,8.4,23.37]],"ltp":0.0,"tv":0.0,"id":13117449},{"batb":[[0,32,7.6],[1,30,28.42],[2,23,6.89]],"ltp":5.9,"tv":4.0,"id":13117448},{"batb":[[0,5.6,21.56],[1,5.3,50.76],[2,5.2,83.69]],"batl":[[1,6.8,37.06]],"ltp":4.9,"tv":93.16,"id":13117392},{"batb":[[0,1.48,321.27],[1,1.47,284.84],[2,1.42,99.45]],"batl":[[0,1.54,83.25],[1,1.64,64.68],[2,1.82,7.5]],"ltp":1.47,"tv":1544.6,"id":13117391}]}]}
{"op":"mcm","clk":"1006436797","pt":1580596288546,"mc":[{"id":"1.168175449","rc":[{"batb":[[2,7,6.72]],"batl":[[2,8.6,5.04]],"ltp":0.0,"tv":0.0,"id":13117449},{"batb":[[2,5.2,92.94]],"batl":[[0,6.2,7.56],[1,6.6,40.13],[2,6.8,37.06]],"ltp":4.9,"tv":93.16,"id":13117392},{"batb":[[2,1.45,93.26]],"batl":[[1,1.56,42.01],[2,1.64,64.68]],"ltp":1.47,"tv":1544.6,"id":13117391}]}]}
{"op":"mcm","clk":"1006439523","pt":1580596313280,"mc":[{"id":"1.168175449","rc":[{"batb":[[0,6.6,29.82],[1,1.01,0.51],[2,7,0]],"batl":[[0,8.4,23.37],[1,8.4,0],[2,8.6,0]],"ltp":0.0,"tv":0.0,"id":13117449},{"batb":[[0,14.5,11.64],[1,1.01,0.51],[2,23,0]],"ltp":5.9,"tv":4.0,"id":13117448},{"batb":[[0,5.2,24.78],[1,1.01,0.51],[2,5.2,0]],"batl":[[0,6.8,37.06],[1,6.6,0],[2,6.8,0]],"ltp":4.9,"tv":93.16,"id":13117392},{"batb":[[0,1.42,99.45],[1,1.01,0.51],[2,1.45,0]],"batl":[[0,1.64,64.68],[1,1.82,7.5],[2,1.64,0]],"ltp":1.47,"tv":1544.6,"id":13117391}]}]}
{"op":"mcm","clk":"1006439886","pt":1580596316394,"mc":[{"id":"1.168175449","rc":[{"batb":[[0,7.2,76.66],[1,7,61.23],[2,6.6,29.82]],"ltp":0.0,"tv":0.0,"id":13117449},{"batb":[[0,18.5,28.06],[1,18,20.61],[2,14.5,11.64]],"ltp":5.9,"tv":4.0,"id":13117448},{"batb":[[1,5,83.3],[2,4.9,66.8]],"ltp":4.9,"tv":93.16,"id":13117392},{"batb":[[0,1.44,305.09],[1,1.43,224.45],[2,1.42,99.45]],"ltp":1.47,"tv":1544.6,"id":13117391}]}]}
{"op":"mcm","clk":"1006440059","pt":1580596318103,"mc":[{"id":"1.168175449","rc":[{"batb":[[0,6.6,29.82],[1,1.01,0.51],[2,6.6,0]],"ltp":0.0,"tv":0.0,"id":13117449},{"batb":[[0,14.5,11.64],[1,1.01,0.51],[2,14.5,0]],"ltp":5.9,"tv":4.0,"id":13117448},{"batb":[[1,1.01,0.51],[2,4.9,0]],"ltp":4.9,"tv":93.16,"id":13117392}]}]}
{"op":"mcm","clk":"1006440364","pt":1580596321111,"mc":[{"id":"1.168175449","rc":[{"batb":[[0,7.8,46.49],[1,7.6,51.95],[2,6.6,29.82]],"ltp":0.0,"tv":0.0,"id":13117449},{"batb":[[0,50,15.64],[1,48,10.76],[2,14.5,11.64]],"ltp":5.9,"tv":4.0,"id":13117448},{"batb":[[0,5.4,78.53],[1,5.3,56.05],[2,5.2,24.78]],"ltp":4.9,"tv":93.16,"id":13117392}]}]}
{"op":"mcm","clk":"1006440510","pt":1580596322319,"mc":[{"id":"1.168175449","rc":[{"batb":[[2,7.2,6.72]],"batl":[[1,8.8,21.09],[2,9,5.04]],"ltp":0.0,"tv":0.0,"id":13117449},{"batb":[[2,30,4.29]],"ltp":5.9,"tv":4.0,"id":13117448},{"batb":[[0,5.8,39.81],[1,5.6,21.17],[2,5.4,87.77]],"batl":[[0,6.4,7.56],[1,6.8,37.06],[2,7,33.83]],"ltp":4.9,"tv":93.16,"id":13117392},{"batl":[[0,1.48,96.62],[1,1.51,130.29],[2,1.82,7.5]],"ltp":1.47,"tv":1544.6,"id":13117391}]}]}
{"op":"mcm","clk":"1006442698","pt":1580596342135,"mc":[{"id":"1.168175449","rc":[{"batb":[[1,48,7.17]],"ltp":5.9,"tv":4.0,"id":13117448}]}]}
{"op":"mcm","clk":"1006443067","pt":1580596345239,"mc":[{"id":"1.168175449","rc":[{"batb":[[0,50,20.04]],"ltp":5.9,"tv":4.0,"id":13117448}]}]}
{"op":"mcm","clk":"1006444732","pt":1580596359633,"mc":[{"id":"1.168175449","rc":[{"batb":[[2,30,2.83]],"ltp":5.9,"tv":4.0,"id":13117448},{"batb":[[2,1.42,99.3]],"batl":[[0,1.48,96.46],[1,1.51,130.13]],"ltp":1.47,"tv":1544.6,"id":13117391}]}]}
{"op":"mcm","clk":"1006448964","pt":1580596398275,"mc":[{"id":"1.168175449","rc":[{"batb":[[0,7.6,39.7],[1,7.2,6.72],[2,6.8,26.99]],"batl":[[0,8.8,21.09],[1,9,5.04],[2,9,0]],"ltp":0.0,"tv":0.0,"id":13117449},{"batb":[[0,1.01,0.51],[1,48,0],[2,30,0]],"ltp":5.9,"tv":4.0,"id":13117448},{"batb":[[0,5.6,21.17],[1,5.4,9.24],[2,5.3,56.05]],"batl":[[1,7,33.83],[2,7,0]],"ltp":4.9,"tv":93.16,"id":13117392},{"batb":[[0,1.41,101.66],[1,1.38,111.41],[2,1.01,0.51]],"batl":[[0,1.51,130.13],[1,1.82,7.5],[2,1.82,0]],"ltp":1.47,"tv":1544.6,"id":13117391}]}]}
{"op":"mcm","clk":"1006449072","pt":1580596399369,"mc":[{"id":"1.168175449","rc":[{"batb":[[1,6.8,26.99],[2,1.01,0.51]],"batl":[[1,9,0]],"ltp":0.0,"tv":0.0,"id":13117449},{"batb":[[1,5.3,56.05],[2,1.01,0.51]],"batl":[[0,7,33.83],[1,7,0]],"ltp":4.9,"tv":93.16,"id":13117392},{"batb":[[0,1.38,111.41],[1,1.01,0.51],[2,1.01,0]],"batl":[[0,1.51,88.12]],"ltp":1.47,"tv":1544.6,"id":13117391}]}]}
{"op":"mcm","clk":"1006449234","pt":1580596400971,"mc":[{"id":"1.168175449","rc":[{"batb":[[1,7.4,55.22],[2,6.8,26.99]],"ltp":0.0,"tv":0.0,"id":13117449},{"batb":[[0,44,5.88],[1,42,14.79],[2,1.01,0.51]],"ltp":5.9,"tv":4.0,"id":13117448},{"batb":[[1,5.3,69.69],[2,5.2,58.69]],"ltp":4.9,"tv":93.16,"id":13117392}]}]}
{"op":"mcm","clk":"1006449486","pt":1580596403293,"mc":[{"id":"1.168175449","rc":[{"batb":[[0,1.47,156.43],[1,1.46,204.27],[2,1.38,111.41]],"ltp":1.47,"tv":1544.6,"id":13117391}]}]}
{"op":"mcm","clk":"1006449599","pt":1580596404370,"mc":[{"id":"1.168175449","rc":[{"batb":[[2,7,6.72]],"batl":[[0,8,25.65],[1,8.6,22.98],[2,8.8,5.04]],"ltp":0.0,"tv":0.0,"id":13117449},{"batb":[[2,26,8.43]],"ltp":5.9,"tv":4.0,"id":13117448},{"batb":[[1,5.5,22.35],[2,5.3,78.93]],"batl":[[0,6.4,7.56],[1,6.6,39.26],[2,6.8,36.51]],"ltp":4.9,"tv":93.16,"id":13117392},{"batb":[[2,1.45,90.8]],"batl":[[1,1.52,42.01],[2,1.55,80.33]],"ltp":1.47,"tv":1544.6,"id":13117391}]}]}
{"op":"mcm","clk":"1006450555","pt":1580596413395,"mc":[{"id":"1.168175449","rc":[{"batb":[[0,7.4,37.65],[1,6.6,29.74],[2,1.01,0.51]],"batl":[[0,8.6,22.98],[1,8.6,0],[2,8.8,0]],"ltp":0.0,"tv":0.0,"id":13117449},{"batb":[[0,26,8.43],[1,1.01,0.51],[2,26,0]],"ltp":5.9,"tv":4.0,"id":13117448},{"batb":[[0,5.5,22.35],[1,5.2,58.69],[2,1.01,0.51]],"batl":[[0,6.8,36.51],[1,6.6,0],[2,6.8,0]],"ltp":4.9,"tv":93.16,"id":13117392},{"batb":[[0,1.41,101.5],[1,1.01,0.51],[2,1.45,0]],"batl":[[0,1.55,80.33],[1,1.82,7.5],[2,1.55,0]],"ltp":1.47,"tv":1544.6,"id":13117391}]}]}
{"op":"mcm","clk":"1006451019","pt":1580596417980,"mc":[{"id":"1.168175449","rc":[{"batb":[[0,7.6,32.89],[1,7.4,54.85],[2,6.6,29.74]],"ltp":0.0,"tv":0.0,"id":13117449},{"batb":[[0,44,13.54],[1,26,8.43],[2,1.01,0.51]],"ltp":5.9,"tv":4.0,"id":13117448},{"batb":[[1,5.3,86.69],[2,5.2,58.69]],"ltp":4.9,"tv":93.16,"id":13117392},{"batb":[[0,1.46,236.21],[1,1.45,210.96],[2,1.41,101.5]],"ltp":1.47,"tv":1544.6,"id":13117391}]}]}
{"op":"mcm","clk":"1006451331","pt":1580596421005,"mc":[{"id":"1.168175449","rc":[{"batb":[[0,44,15.56],[1,42,14.22],[2,26,8.43]],"ltp":5.9,"tv":4.0,"id":13117448},{"batb":[[0,1.46,288.76]],"ltp":1.47,"tv":1544.6,"id":13117391}]}]}
{"op":"mcm","clk":"1006451694","pt":1580596424611,"mc":[{"id":"1.168175449","rc":[{"batb":[[0,6.6,29.74],[1,1.01,0.51],[2,6.6,0]],"ltp":0.0,"tv":0.0,"id":13117449},{"batb":[[0,26,8.43],[1,1.01,0.51],[2,26,0]],"ltp":5.9,"tv":4.0,"id":13117448},{"batb":[[1,5.2,58.69],[2,1.01,0.51]],"ltp":4.9,"tv":93.16,"id":13117392},{"batb":[[0,1.41,101.5],[1,1.01,0.51],[2,1.41,0]],"ltp":1.47,"tv":1544.6,"id":13117391}]}]}
{"op":"mcm","clk":"1006452021","pt":1580596427805,"mc":[{"id":"1.168175449","rc":[{"batb":[[0,7.2,73.32],[1,7,60.86],[2,6.6,29.74]],"ltp":0.0,"tv":0.0,"id":13117449},{"batb":[[0,38,7.18],[1,36,19.88],[2,26,8.43]],"ltp":5.9,"tv":4.0,"id":13117448},{"batb":[[1,5.2,74.3],[2,5.1,61.36]],"ltp":4.9,"tv":93.16,"id":13117392},{"batb":[[0,1.44,213.87],[1,1.43,223.48],[2,1.41,101.5]],"ltp":1.47,"tv":1544.6,"id":13117391}]}]}
{"op":"mcm","clk":"1006452276","pt":1580596429902,"mc":[{"id":"1.168175449","rc":[{"batb":[[0,7.2,59.94]],"ltp":0.0,"tv":0.0,"id":13117449},{"batb":[[0,36,19.88],[1,26,8.43],[2,1.01,0.51]],"ltp":5.9,"tv":4.0,"id":13117448}]}]}
{"op":"mcm","clk":"1006452632","pt":1580596432930,"mc":[{"id":"1.168175449","rc":[{"batb":[[0,36,25.07],[1,34,13.05],[2,26,8.43]],"ltp":5.9,"tv":4.0,"id":13117448}]}]}
{"op":"mcm","clk":"1006452986","pt":1580596435858,"mc":[{"id":"1.168175449","rc":[{"batb":[[0,6.6,29.74],[1,1.01,0.51],[2,6.6,0]],"ltp":0.0,"tv":0.0,"id":13117449},{"batb":[[0,26,8.43],[1,1.01,0.51],[2,26,0]],"ltp":5.9,"tv":4.0,"id":13117448},{"batb":[[1,1.01,0.51],[2,5.1,0]],"ltp":4.9,"tv":93.16,"id":13117392}]}]}
{"op":"mcm","clk":"1006453368","pt":1580596439447,"mc":[{"id":"1.168175449","rc":[{"batb":[[0,7.8,30.64],[1,7.6,51.57],[2,7.2,24.23]],"batl":[[1,9,20.61]],"ltp":0.0,"tv":0.0,"id":13117449},{"batb":[[0,50,25.36],[1,30,4.21],[2,26,8.43]],"ltp":5.9,"tv":4.0,"id":13117448},{"batb":[[0,5.8,39.1],[1,5.6,21.17],[2,5.5,72.3]],"batl":[[1,7.2,32.89]],"ltp":4.9,"tv":93.16,"id":13117392},{"batl":[[0,1.47,98.51],[1,1.51,88.75],[2,1.55,80.33]],"ltp":1.47,"tv":1544.6,"id":13117391}]}]}
{"op":"mcm","clk":"1006453465","pt":1580596440431,"mc":[{"id":"1.168175449","rc":[{"batb":[[2,7.4,5.88]],"batl":[[2,9.2,5.04]],"ltp":0.0,"tv":0.0,"id":13117449},{"batb":[[2,1.01,0.51]],"ltp":5.9,"tv":4.0,"id":13117448},{"batb":[[2,5.5,49.95]],"batl":[[0,6.4,7.56],[1,6.8,36.51],[2,7.2,32.89]],"ltp":4.9,"tv":93.16,"id":13117392},{"batl":[[1,1.5,42.01],[2,1.51,88.75]],"ltp":1.47,"tv":1544.6,"id":13117391}]}]}
{"op":"mcm","clk":"1006454105","pt":1580596446648,"mc":[{"id":"1.168175449","rc":[{"trd":[[7.8,0.55]],"batb":[[0,7.8,30.09]],"ltp":7.8,"tv":0.55,"id":13117449},{"trd":[[50,0.09]],"batb":[[0,50,25.27]],"ltp":50.0,"tv":4.09,"id":13117448},{"trd":[[5.8,0.74]],"batb":[[0,5.8,38.36]],"ltp":5.8,"tv":93.9,"id":13117392},{"trd":[[1.47,226.91],[1.48,2.9]],"batl":[[0,1.5,42.01],[1,1.51,88.75],[2,1.82,7.5]],"ltp":1.48,"tv":1744.41,"id":13117391}],"tv":1842.96}]}
{"op":"mcm","clk":"1006455460","pt":1580596458466,"mc":[{"id":"1.168175449","rc":[{"batb":[[0,7.4,5.88],[1,7.2,24.23],[2,6.8,26.67]],"ltp":7.8,"tv":0.55,"id":13117449},{"batb":[[0,30,4.21],[1,1.01,0.51],[2,1.01,0]],"ltp":50.0,"tv":4.09,"id":13117448},{"batb":[[2,5.4,9.24]],"ltp":5.8,"tv":93.9,"id":13117392},{"batb":[[0,1.41,101.5],[1,1.4,105.02],[2,1.37,115.35]],"ltp":1.48,"tv":1744.41,"id":13117391}]}]}
{"op":"mcm","clk":"1006455564","pt":1580596459368,"mc":[{"id":"1.168175449","rc":[{"batb":[[0,6.8,26.67],[1,1.01,0.51],[2,6.8,0]],"batl":[[0,9,20.61],[1,9,0],[2,9.2,0]],"ltp":7.8,"tv":0.55,"id":13117449},{"batb":[[0,5.6,21.17],[1,1.01,0.51],[2,5.4,0]],"batl":[[0,7.2,32.89],[1,6.8,0],[2,7.2,0]],"ltp":5.8,"tv":93.9,"id":13117392},{"batb":[[0,1.37,115.35],[1,1.01,0.51],[2,1.37,0]],"batl":[[0,1.51,88.75],[1,1.82,7.5],[2,1.82,0]],"ltp":1.48,"tv":1744.41,"id":13117391}]}]}
{"op":"mcm","clk":"1006455806","pt":1580596461482,"mc":[{"id":"1.168175449","rc":[{"batb":[[0,7.4,74.76],[1,7.2,56.89],[2,6.8,26.67]],"ltp":7.8,"tv":0.55,"id":13117449},{"batb":[[0,42,16.69],[1,40,15.54],[2,30,4.21]],"ltp":50.0,"tv":4.09,"id":13117448},{"batb":[[1,5.3,89.38],[2,5.2,58.56]],"ltp":5.8,"tv":93.9,"id":13117392},{"batb":[[0,1.41,161.17],[1,1.4,244.9],[2,1.37,115.35]],"ltp":1.48,"tv":1744.41,"id":13117391}]}]}
{"op":"mcm","clk":"1006455874","pt":1580596462003,"mc":[{"id":"1.168175449","rc":[{"batl":[[0,8.8,21.4]],"ltp":7.8,"tv":0.55,"id":13117449},{"batb":[[2,29,4.8]],"ltp":50.0,"tv":4.09,"id":13117448},{"batl":[[0,7,34.15]],"ltp":5.8,"tv":93.9,"id":13117392},{"batb":[[2,1.39,111.81]],"batl":[[0,1.52,86]],"ltp":1.48,"tv":1744.41,"id":13117391}]}]}
{"op":"mcm","clk":"1006456122","pt":1580596464307,"mc":[{"id":"1.168175449","rc":[{"batb":[[0,1.39,111.81],[1,1.01,0.51],[2,1.39,0]],"ltp":1.48,"tv":1744.41,"id":13117391}]}]}
{"op":"mcm","clk":"1006456515","pt":1580596467535,"mc":[{"id":"1.168175449","rc":[{"batb":[[0,1.47,169.56],[1,1.46,203.88],[2,1.39,111.81]],"ltp":1.48,"tv":1744.41,"id":13117391}]}]}
{"op":"mcm","clk":"1006456631","pt":1580596468532,"mc":[{"id":"1.168175449","rc":[{"batb":[[1,7.2,63.61]],"batl":[[0,8,26.04],[1,8.2,23.76],[2,8.8,5.04]],"ltp":7.8,"tv":0.55,"id":13117449},{"batb":[[1,5.4,23.13],[2,5.3,98.62]],"batl":[[0,6.4,49.11],[1,6.8,36.98]],"ltp":5.8,"tv":93.9,"id":13117392},{"batb":[[0,1.47,257.92],[2,1.43,99.85]],"batl":[[0,1.52,128.01],[1,1.56,77.9],[2,1.82,7.5]],"ltp":1.48,"tv":1744.41,"id":13117391}]}]}
{"op":"mcm","clk":"1006458602","pt":1580596485434,"mc":[{"id":"1.168175449","rc":[{"batb":[[0,7.2,56.89],[1,6.4,30.53],[2,1.01,0.51]],"batl":[[0,8.2,23.76],[1,8.2,0],[2,8.8,0]],"ltp":7.8,"tv":0.55,"id":13117449},{"batb":[[0,25,9.68],[1,1.01,0.51],[2,29,0]],"ltp":50.0,"tv":4.09,"id":13117448},{"batb":[[0,5.4,23.13],[1,5.2,58.56],[2,1.01,0.51]],"batl":[[0,6.8,36.98],[1,6.8,0]],"ltp":5.8,"tv":93.9,"id":13117392},{"batb":[[0,1.43,99.85],[1,1.01,0.51],[2,1.43,0]],"batl":[[0,1.56,77.9],[1,1.82,7.5],[2,1.82,0]],"ltp":1.48,"tv":1744.41,"id":13117391}]}]}
{"op":"mcm","clk":"1006458918","pt":1580596488177,"mc":[{"id":"1.168175449","rc":[{"batb":[[0,7.2,73.33],[1,7,60.54],[2,6.4,30.53]],"ltp":7.8,"tv":0.55,"id":13117449},{"batb":[[0,36,18.86],[1,34,19.62],[2,25,9.68]],"ltp":50.0,"tv":4.09,"id":13117448},{"batb":[[1,5.2,83.39],[2,5.1,61.29]],"ltp":5.8,"tv":93.9,"id":13117392}]}]}
{"op":"mcm","clk":"1006459171","pt":1580596490432,"mc":[{"id":"1.168175449","rc":[{"batb":[[0,7.2,58.32],[1,7,6.72]],"batl":[[1,8.6,5.04]],"ltp":7.8,"tv":0.55,"id":13117449},{"batb":[[1,34,17.14]],"ltp":50.0,"tv":4.09,"id":13117448},{"batb":[[1,5.2,92.63]],"batl":[[0,6.2,7.56],[1,6.8,36.98]],"ltp":5.8,"tv":93.9,"id":13117392},{"batb":[[0,1.49,258.49],[1,1.48,193.22],[2,1.44,94.94]],"batl":[[0,1.54,42.01],[1,1.56,77.9],[2,1.82,7.5]],"ltp":1.48,"tv":1744.41,"id":13117391}]}]}
{"op":"mcm","clk":"1006459253","pt":1580596491163,"mc":[{"id":"1.168175449","rc":[{"batl":[[0,7.6,28.72],[1,8,25.65],[2,8.6,5.04]],"ltp":7.8,"tv":0.55,"id":13117449},{"batb":[[1,5.3,24.63],[2,5.2,92.63]],"batl":[[0,6.2,29.83],[1,6.4,40.29]],"ltp":5.8,"tv":93.9,"id":13117392},{"batb":[[0,1.51,79.86],[1,1.49,258.49],[2,1.48,193.22]],"batl":[[2,1.6,72.07]],"ltp":1.48,"tv":1744.41,"id":13117391}]}]}
{"op":"mcm","clk":"1006459499","pt":1580596493455,"mc":[{"id":"1.168175449","rc":[{"batb":[[0,7.4,27.39],[1,7.2,58.32],[2,7,6.72]],"ltp":7.8,"tv":0.55,"id":13117449},{"batb":[[0,36,21.21]],"ltp":50.0,"tv":4.09,"id":13117448}]}]}
{"op":"mcm","clk":"1006460671","pt":1580596503846,"mc":[{"id":"1.168175449","rc":[{"batb":[[0,7.2,31.39],[1,7,6.72],[2,6.2,32.73]],"batl":[[0,8,25.65],[1,8.6,5.04],[2,8.6,0]],"ltp":7.8,"tv":0.55,"id":13117449},{"batb":[[0,34,12.61],[1,23,6.63],[2,1.01,0.51]],"ltp":50.0,"tv":4.09,"id":13117448},{"batb":[[0,5.3,24.63],[1,5.2,9.24],[2,5.1,61.29]],"batl":[[0,6.2,7.56]],"ltp":5.8,"tv":93.9,"id":13117392},{"batb":[[0,1.47,89.07],[1,1.44,94.94],[2,1.01,0.51]],"batl":[[1,1.6,72.07],[2,1.82,7.5]],"ltp":1.48,"tv":1744.41,"id":13117391}]}]}
{"op":"mcm","clk":"1006460852","pt":1580596505378,"mc":[{"id":"1.168175449","rc":[{"batb":[[1,6.2,32.73],[2,1.01,0.51]],"batl":[[1,8.6,0]],"ltp":7.8,"tv":0.55,"id":13117449},{"batb":[[1,5.1,61.29],[2,1.01,0.51]],"batl":[[0,6.4,40.29],[1,6.4,0]],"ltp":5.8,"tv":93.9,"id":13117392},{"batb":[[1,1.01,0.51],[2,1.01,0]],"batl":[[0,1.6,72.07],[1,1.82,7.5],[2,1.82,0]],"ltp":1.48,"tv":1744.41,"id":13117391}]}]}
{"op":"mcm","clk":"1006461434","pt":1580596510562,"mc":[{"id":"1.168175449","rc":[{"batb":[[1,7,61.88],[2,6.2,32.73]],"ltp":7.8,"tv":0.55,"id":13117449},{"batb":[[1,32,24.82],[2,23,6.63]],"ltp":50.0,"tv":4.09,"id":13117448},{"batb":[[1,5.1,90.94],[2,5,63.94]],"ltp":5.8,"tv":93.9,"id":13117392},{"batb":[[0,1.51,212.94],[1,1.5,182.78],[2,1.47,89.07]],"ltp":1.48,"tv":1744.41,"id":13117391}]}]}
{"op":"mcm","clk":"1006461529","pt":1580596511501,"mc":[{"id":"1.168175449","rc":[{"batl":[[0,7.4,29.74]],"ltp":7.8,"tv":0.55,"id":13117449},{"batb":[[2,5,92.11]],"batl":[[0,5.9,23.68],[1,6.2,21.64]],"ltp":5.8,"tv":93.9,"id":13117392},{"batb":[[0,1.54,73.88],[1,1.51,212.94],[2,1.5,182.78]],"batl":[[1,1.71,56.18],[2,1.82,7.5]],"ltp":1.48,"tv":1744.41,"id":13117391}]}]}
{"op":"mcm","clk":"1006461627","pt":1580596512390,"mc":[{"id":"1.168175449","rc":[{"batb":[[2,6.6,6.72]],"batl":[[1,8.2,5.04]],"ltp":7.8,"tv":0.55,"id":13117449},{"batb":[[1,5.1,101.02]],"batl":[[1,6.2,29.2]],"ltp":5.8,"tv":93.9,"id":13117392},{"batl":[[0,1.58,42.01],[1,1.6,72.07],[2,1.71,56.18]],"ltp":1.48,"tv":1744.41,"id":13117391}]}]}
{"op":"mcm","clk":"1006464791","pt":1580596542040,"mc":[{"id":"1.168175449","rc":[{"batb":[[0,6.6,6.72],[1,6,36.43],[2,1.01,0.51]],"ltp":7.8,"tv":0.55,"id":13117449},{"batb":[[0,14.5,11.8],[1,1.01,0.51],[2,23,0]],"ltp":50.0,"tv":4.09,"id":13117448},{"batb":[[0,5.1,10.08],[1,5,28.17],[2,1.01,0.51]],"batl":[[0,6.2,29.2],[1,6.2,0]],"ltp":5.8,"tv":93.9,"id":13117392},{"batb":[[0,1.48,85.45],[1,1.47,89.06],[2,1.01,0.51]],"batl":[[1,1.71,56.18],[2,1.82,7.5]],"ltp":1.48,"tv":1744.41,"id":13117391}]}]}
{"op":"mcm","clk":"1006464932","pt":1580596543442,"mc":[{"id":"1.168175449","rc":[{"batb":[[0,6,36.43],[1,1.01,0.51],[2,1.01,0]],"batl":[[1,8.2,0]],"ltp":7.8,"tv":0.55,"id":13117449},{"batb":[[0,5,28.17],[1,1.01,0.51],[2,1.01,0]],"batl":[[0,6.2,21.64]],"ltp":5.8,"tv":93.9,"id":13117392},{"batb":[[1,1.01,0.51],[2,1.01,0]],"batl":[[0,1.71,56.18],[1,1.82,7.5],[2,1.82,0]],"ltp":1.48,"tv":1744.41,"id":13117391}]}]}
{"op":"mcm","clk":"1006465107","pt":1580596545458,"mc":[{"id":"1.168175449","rc":[{"batb":[[0,1.01,0.51],[1,1.01,0]],"batl":[[0,7.8,27.3]],"ltp":7.8,"tv":0.55,"id":13117449},{"batb":[[0,15,10.94]],"ltp":50.0,"tv":4.09,"id":13117448},{"batb":[[0,4.9,28.8]],"ltp":5.8,"tv":93.9,"id":13117392},{"batb":[[0,1.47,88.05]],"batl":[[0,1.69,58.15]],"ltp":1.48,"tv":1744.41,"id":13117391}]}]}
{"op":"mcm","clk":"1006465154","pt":1580596545885,"mc":[{"id":"1.168175449","rc":[{"batb":[[0,1.47,235.72],[1,1.46,203.89],[2,1.01,0.51]],"ltp":1.48,"tv":1744.41,"id":13117391}]}]}
{"op":"mcm","clk":"1006465437","pt":1580596548439,"mc":[{"id":"1.168175449","rc":[{"batb":[[0,7.2,78.14],[1,7,60.74],[2,6.6,6.72]],"batl":[[1,8.2,5.04]],"ltp":7.8,"tv":0.55,"id":13117449},{"batb":[[0,60,10.08],[1,55,13.49],[2,15,10.94]],"ltp":50.0,"tv":4.09,"id":13117448},{"batb":[[0,5.3,57.67],[1,5.2,59.12],[2,4.9,28.8]],"batl":[[1,6.4,7.56]],"ltp":5.8,"tv":93.9,"id":13117392},{"batb":[[2,1.43,97.46]],"batl":[[0,1.53,42.01],[1,1.69,58.15],[2,1.82,7.5]],"ltp":1.48,"tv":1744.41,"id":13117391}]}]}
{"op":"mcm","clk":"1006465538","pt":1580596549347,"mc":[{"id":"1.168175449","rc":[{"batb":[[2,6.6,35.76]],"batl":[[1,8,25.1],[2,8.2,5.04]],"ltp":7.8,"tv":0.55,"id":13117449},{"batb":[[2,30,5.98]],"ltp":50.0,"tv":4.09,"id":13117448},{"batb":[[0,5.4,22.82],[1,5.3,57.67],[2,5.2,59.12]],"batl":[[1,6.4,47.69]],"ltp":5.8,"tv":93.9,"id":13117392},{"batb":[[2,1.43,197.86]],"batl":[[0,1.52,85.68],[1,1.53,42.01],[2,1.61,69.16]],"ltp":1.48,"tv":1744.41,"id":13117391}]}]}
{"op":"mcm","clk":"1006466893","pt":1580596561499,"mc":[{"id":"1.168175449","rc":[{"batb":[[0,7,60.74],[1,6.2,32.1],[2,1.01,0.51]],"batl":[[0,8,25.1],[1,8,0],[2,8.2,0]],"ltp":7.8,"tv":0.55,"id":13117449},{"batb":[[0,22,8.21],[1,1.01,0.51],[2,30,0]],"ltp":50.0,"tv":4.09,"id":13117448},{"batb":[[0,5.1,26.44],[1,1.01,0.51],[2,5.2,0]],"batl":[[0,6.4,40.13],[1,6.4,0]],"ltp":5.8,"tv":93.9,"id":13117392},{"batb":[[0,1.43,100.4],[1,1.01,0.51],[2,1.43,0]],"batl":[[0,1.61,69.16],[1,1.82,7.5],[2,1.61,0]],"ltp":1.48,"tv":1744.41,"id":13117391}]}]}
{"op":"mcm","clk":"1006467204","pt":1580596564293,"mc":[{"id":"1.168175449","rc":[{"batb":[[1,6.8,65.33],[2,6.2,32.1]],"ltp":7.8,"tv":0.55,"id":13117449},{"batb":[[0,30,9.19],[1,29,15.75],[2,22,8.21]],"ltp":50.0,"tv":4.09,"id":13117448},{"batb":[[0,5.1,73.36],[1,5,64.63],[2,1.01,0.51]],"ltp":5.8,"tv":93.9,"id":13117392},{"batb":[[0,1.43,410.86],[1,1.42,231.34],[2,1.01,0.51]],"ltp":1.48,"tv":1744.41,"id":13117391}]}]}
{"op":"mcm","clk":"1006468187","pt":1580596573497,"mc":[{"id":"1.168175449","rc":[{"batb":[[0,1.43,100.4],[1,1.01,0.51],[2,1.01,0]],"ltp":1.48,"tv":1744.41,"id":13117391}]}]}
{"op":"mcm","clk":"1006468550","pt":1580596576462,"mc":[{"id":"1.168175449","rc":[{"batb":[[0,1.53,226.47],[1,1.52,173.39],[2,1.43,100.4]],"ltp":1.48,"tv":1744.41,"id":13117391}]}]}
{"op":"mcm","clk":"1006468647","pt":1580596577295,"mc":[{"id":"1.168175449","rc":[{"batl":[[0,7.4,30.14],[1,7.6,28.48]],"ltp":7.8,"tv":0.55,"id":13117449},{"batb":[[2,4.8,30.61]],"batl":[[0,5.7,25.41],[1,6,22.66]],"ltp":5.8,"tv":93.9,"id":13117392},{"batb":[[0,1.56,70.81],[1,1.53,226.47],[2,1.52,173.39]],"batl":[[1,1.75,52.48],[2,1.82,7.5]],"ltp":1.48,"tv":1744.41,"id":13117391}]}]}
{"op":"mcm","clk":"1006468775","pt":1580596578491,"mc":[{"id":"1.168175449","rc":[{"batb":[[2,6.4,7.56]],"batl":[[2,8,5.88]],"ltp":7.8,"tv":0.55,"id":13117449},{"batb":[[1,5,74.71]],"batl":[[1,6,31.06]],"ltp":5.8,"tv":93.9,"id":13117392},{"batl":[[0,1.6,42.01],[1,1.61,69.16],[2,1.75,52.48]],"ltp":1.48,"tv":1744.41,"id":13117391}]}]}
{"op":"mcm","clk":"1006470667","pt":1580596596476,"mc":[{"id":"1.168175449","rc":[{"batb":[[0,6.8,33.74],[1,6.4,7.56],[2,6,34.86]],"batl":[[0,7.6,28.48],[1,8,5.88],[2,8,0]],"ltp":7.8,"tv":0.55,"id":13117449},{"batb":[[0,13,15.42],[1,1.01,0.51],[2,22,0]],"ltp":50.0,"tv":4.09,"id":13117448},{"batb":[[0,5,10.08],[1,4.8,30.61],[2,1.01,0.51]],"batl":[[0,6,31.06],[1,6,0]],"ltp":5.8,"tv":93.9,"id":13117392},{"batb":[[0,1.49,170.68],[1,1.01,0.51],[2,1.52,0]],"batl":[[1,1.75,52.48],[2,1.82,7.5]],"ltp":1.48,"tv":1744.41,"id":13117391}]}]}
{"op":"mcm","clk":"1006470757","pt":1580596597464,"mc":[{"id":"1.168175449","rc":[{"batb":[[1,6,34.86],[2,1.01,0.51]],"batl":[[1,8,0]],"ltp":7.8,"tv":0.55,"id":13117449},{"batb":[[0,4.8,30.61],[1,1.01,0.51],[2,1.01,0]],"batl":[[0,6,22.66]],"ltp":5.8,"tv":93.9,"id":13117392},{"batb":[[0,1.49,84.98]],"batl":[[0,1.75,52.48],[1,1.82,7.5],[2,1.82,0]],"ltp":1.48,"tv":1744.41,"id":13117391}]}]}
{"op":"mcm","clk":"1006470962","pt":1580596599392,"mc":[{"id":"1.168175449","rc":[{"batb":[[1,6.6,70.26],[2,6,34.86]],"ltp":7.8,"tv":0.55,"id":13117449},{"batb":[[0,15.5,40.22],[1,15,29.86],[2,13,15.42]],"ltp":50.0,"tv":4.09,"id":13117448},{"batb":[[0,4.8,110.8],[1,4.7,73.86],[2,1.01,0.51]],"ltp":5.8,"tv":93.9,"id":13117392},{"batb":[[1,1.48,141.36],[2,1.47,198.09]],"ltp":1.48,"tv":1744.41,"id":13117391}]}]}
{"op":"mcm","clk":"1006470986","pt":1580596599602,"mc":[{"id":"1.168175449","rc":[{"batb":[[1,6,34.86],[2,1.01,0.51]],"ltp":7.8,"tv":0.55,"id":13117449},{"batb":[[0,13,15.42],[1,1.01,0.51],[2,13,0]],"ltp":50.0,"tv":4.09,"id":13117448},{"batb":[[0,4.8,30.61],[1,1.01,0.51],[2,1.01,0]],"ltp":5.8,"tv":93.9,"id":13117392},{"batb":[[1,1.01,0.51],[2,1.47,0]],"ltp":1.48,"tv":1744.41,"id":13117391}]}]}
{"op":"mcm","clk":"1006471181","pt":1580596601261,"mc":[{"id":"1.168175449","rc":[{"batb":[[0,7,36.55],[1,6.8,65.76],[2,6,34.86]],"ltp":7.8,"tv":0.55,"id":13117449},{"batb":[[0,25,21.33],[1,24,22.61],[2,13,15.42]],"ltp":50.0,"tv":4.09,"id":13117448},{"batb":[[0,5,78.11],[1,4.9,67.17],[2,4.8,30.61]],"ltp":5.8,"tv":93.9,"id":13117392},{"batb":[[0,1.55,232.06],[1,1.54,164.72],[2,1.49,84.98]],"ltp":1.48,"tv":1744.41,"id":13117391}]}]}
{"op":"mcm","clk":"1006471579","pt":1580596605564,"mc":[{"id":"1.168175449","rc":[{"batb":[[0,6.8,34.5],[1,6,34.86],[2,1.01,0.51]],"ltp":7.8,"tv":0.55,"id":13117449},{"batb":[[0,13,15.42],[1,1.01,0.51],[2,13,0]],"ltp":50.0,"tv":4.09,"id":13117448},{"batb":[[0,4.8,30.61],[1,1.01,0.51],[2,4.8,0]],"ltp":5.8,"tv":93.9,"id":13117392},{"batb":[[0,1.49,84.98],[1,1.01,0.51],[2,1.49,0]],"ltp":1.48,"tv":1744.41,"id":13117391}]}]}
{"op":"mcm","clk":"1006471830","pt":1580596608145,"mc":[{"id":"1.168175449","rc":[{"batb":[[1,6.6,70.26],[2,6,34.86]],"ltp":7.8,"tv":0.55,"id":13117449},{"batb":[[0,15.5,40.53],[1,15,29.86],[2,13,15.42]],"ltp":50.0,"tv":4.09,"id":13117448},{"batb":[[0,4.8,110.51],[1,4.7,73.87],[2,1.01,0.51]],"ltp":5.8,"tv":93.9,"id":13117392},{"batb":[[1,1.48,139.67],[2,1.47,198.08]],"ltp":1.48,"tv":1744.41,"id":13117391}]}]}
{"op":"mcm","clk":"1006474156","pt":1580596632394,"mc":[{"id":"1.168175449","rc":[{"batb":[[1,1.01,0.51],[2,1.47,0]],"ltp":1.48,"tv":1744.41,"id":13117391}]}]}
{"op":"mcm","clk":"1006474445","pt":1580596635413,"mc":[{"id":"1.168175449","rc":[{"batb":[[0,1.64,194.12],[1,1.63,132.88],[2,1.49,84.98]],"ltp":1.48,"tv":1744.41,"id":13117391}]}]}
