{"op":"mcm","clk":"1002483925","pt":1580594279657,"mc":[{"id":"1.168238842","marketDefinition":{"bspMarket":false,"turnInPlayEnabled":true,"persistenceEnabled":true,"marketBaseRate":5.0,"eventId":"29681898","eventTypeId":"2","numberOfWinners":1,"bettingType":"ODDS","marketType":"SET_WINNER","marketTime":"2020-02-02T18:00:00.000Z","suspendTime":"2020-02-02T18:00:00.000Z","bspReconciled":false,"complete":true,"inPlay":false,"crossMatching":false,"runnersVoidable":false,"numberOfActiveRunners":2,"betDelay":0,"status":"OPEN","runners":[{"status":"ACTIVE","sortPriority":1,"id":8860646,"name":"Daniel Elahi Galan"},{"status":"ACTIVE","sortPriority":2,"id":8258569,"name":"Thai-Son Kwiatkowski"}],"regulators":["MR_INT"],"countryCode":"US","discountAllowed":false,"timezone":"UTC","openDate":"2020-02-02T18:00:00.000Z","version":3147660987,"name":"Set 1 Winner","eventName":"Galan v Kwiatkowski"},"rc":[{"batb":[[0,1.01,20]],"ltp":0.0,"tv":0.0,"id":8860646},{"batb":[[0,1.01,20]],"ltp":0.0,"tv":0.0,"id":8258569}]}]}
{"op":"mcm","clk":"1002483973","pt":1580594280292,"mc":[{"id":"1.168238842","marketDefinition":{"bspMarket":false,"turnInPlayEnabled":true,"persistenceEnabled":true,"marketBaseRate":5.0,"eventId":"29681898","eventTypeId":"2","numberOfWinners":1,"bettingType":"ODDS","marketType":"SET_WINNER","marketTime":"2020-02-02T18:00:00.000Z","suspendTime":"2020-02-02T18:00:00.000Z","bspReconciled":false,"complete":true,"inPlay":false,"crossMatching":false,"runnersVoidable":false,"numberOfActiveRunners":2,"betDelay":0,"status":"OPEN","runners":[{"status":"ACTIVE","sortPriority":1,"id":8860646,"name":"Daniel Elahi Galan"},{"status":"ACTIVE","sortPriority":2,"id":8258569,"name":"Thai-Son Kwiatkowski"}],"regulators":["MR_INT"],"countryCode":"US","discountAllowed":false,"timezone":"UTC","openDate":"2020-02-02T18:00:00.000Z","version":3147660987,"name":"Set 1 Winner","eventName":"Galan v Kwiatkowski"}}]}
{"op":"mcm","clk":"1002484254","pt":1580594284306,"mc":[{"id":"1.168238842","marketDefinition":{"bspMarket":false,"turnInPlayEnabled":true,"persistenceEnabled":true,"marketBaseRate":5.0,"eventId":"29681898","eventTypeId":"2","numberOfWinners":1,"bettingType":"ODDS","marketType":"SET_WINNER","marketTime":"2020-02-02T18:00:00.000Z","suspendTime":"2020-02-02T18:00:00.000Z","bspReconciled":false,"complete":true,"inPlay":false,"crossMatching":false,"runnersVoidable":false,"numberOfActiveRunners":2,"betDelay":0,"status":"OPEN","runners":[{"status":"ACTIVE","sortPriority":1,"id":8860646,"name":"Daniel Elahi Galan"},{"status":"ACTIVE","sortPriority":2,"id":8258569,"name":"Thai-Son Kwiatkowski"}],"regulators":["MR_INT"],"countryCode":"US","discountAllowed":true,"timezone":"UTC","openDate":"2020-02-02T18:00:00.000Z","version":3147660987,"name":"Set 1 Winner","eventName":"Galan v Kwiatkowski"}}]}
{"op":"mcm","clk":"1002493227","pt":1580594420604,"mc":[{"id":"1.168238842","rc":[{"batb":[[0,1.01,15]],"ltp":0.0,"tv":0.0,"id":8860646},{"batb":[[0,1.01,15]],"ltp":0.0,"tv":0.0,"id":8258569}]}]}
{"op":"mcm","clk":"1002629161","pt":1580596307111,"mc":[{"id":"1.168238842","marketDefinition":{"bspMarket":false,"turnInPlayEnabled":true,"persistenceEnabled":true,"marketBaseRate":5.0,"eventId":"29681898","eventTypeId":"2","numberOfWinners":1,"bettingType":"ODDS","marketType":"SET_WINNER","marketTime":"2020-02-02T19:00:00.000Z","suspendTime":"2020-02-02T19:00:00.000Z","bspReconciled":false,"complete":true,"inPlay":false,"crossMatching":false,"runnersVoidable":false,"numberOfActiveRunners":2,"betDelay":0,"status":"OPEN","runners":[{"status":"ACTIVE","sortPriority":1,"id":8860646,"name":"Daniel Elahi Galan"},{"status":"ACTIVE","sortPriority":2,"id":8258569,"name":"Thai-Son Kwiatkowski"}],"regulators":["MR_INT"],"countryCode":"US","discountAllowed":true,"timezone":"UTC","openDate":"2020-02-02T18:00:00.000Z","version":3147732914,"name":"Set 1 Winner","eventName":"Galan v Kwiatkowski"}}]}
{"op":"mcm","clk":"1002629419","pt":1580596310123,"mc":[{"id":"1.168238842","marketDefinition":{"bspMarket":false,"turnInPlayEnabled":true,"persistenceEnabled":true,"marketBaseRate":5.0,"eventId":"29681898","eventTypeId":"2","numberOfWinners":1,"bettingType":"ODDS","marketType":"SET_WINNER","marketTime":"2020-02-02T19:00:00.000Z","suspendTime":"2020-02-02T19:00:00.000Z","bspReconciled":false,"complete":true,"inPlay":false,"crossMatching":false,"runnersVoidable":false,"numberOfActiveRunners":2,"betDelay":0,"status":"OPEN","runners":[{"status":"ACTIVE","sortPriority":1,"id":8860646,"name":"Daniel Elahi Galan"},{"status":"ACTIVE","sortPriority":2,"id":8258569,"name":"Thai-Son Kwiatkowski"}],"regulators":["MR_INT"],"countryCode":"US","discountAllowed":true,"timezone":"UTC","openDate":"2020-02-02T19:00:00.000Z","version":3147732914,"name":"Set 1 Winner","eventName":"Galan v Kwiatkowski"}}]}
{"op":"mcm","clk":"1003066340","pt":1580602554037,"mc":[{"id":"1.168238842","rc":[{"batb":[[0,1.01,15.51]],"ltp":0.0,"tv":0.0,"id":8860646},{"batb":[[0,1.01,15.51]],"ltp":0.0,"tv":0.0,"id":8258569}]}]}
{"op":"mcm","clk":"1003185382","pt":1580604083272,"mc":[{"id":"1.168238842","rc":[{"batb":[[0,1.01,16.01]],"ltp":0.0,"tv":0.0,"id":8860646},{"batb":[[0,1.01,16.01]],"ltp":0.0,"tv":0.0,"id":8258569}]}]}
{"op":"mcm","clk":"1003442328","pt":1580607794440,"mc":[{"id":"1.168238842","rc":[{"batb":[[0,1.77,22.37],[1,1.01,16.01]],"ltp":0.0,"tv":0.0,"id":8860646},{"batb":[[0,1.54,27.12],[1,1.01,16.01]],"ltp":0.0,"tv":0.0,"id":8258569}]}]}
{"op":"mcm","clk":"1003695891","pt":1580611395134,"mc":[{"id":"1.168238842","rc":[{"batb":[[0,1.82,21.92]],"ltp":0.0,"tv":0.0,"id":8860646},{"batb":[[0,1.58,26.56]],"ltp":0.0,"tv":0.0,"id":8258569}]}]}
{"op":"mcm","clk":"1003878454","pt":1580614995167,"mc":[{"id":"1.168238842","rc":[{"batb":[[0,1.01,16.01],[1,1.01,0]],"ltp":0.0,"tv":0.0,"id":8860646},{"batb":[[0,1.01,16.01],[1,1.01,0]],"ltp":0.0,"tv":0.0,"id":8258569}]}]}
{"op":"mcm","clk":"1004083838","pt":1580619900099,"mc":[{"id":"1.168238842","rc":[{"batb":[[0,1.59,25.11],[1,1.01,16.01]],"ltp":0.0,"tv":0.0,"id":8860646},{"batb":[[0,1.6,26.04],[1,1.01,16.01]],"ltp":0.0,"tv":0.0,"id":8258569}]}]}
{"op":"mcm","clk":"1004218125","pt":1580623500088,"mc":[{"id":"1.168238842","rc":[{"batb":[[0,1.01,16.01],[1,1.01,0]],"ltp":0.0,"tv":0.0,"id":8860646},{"batb":[[0,1.01,16.01],[1,1.01,0]],"ltp":0.0,"tv":0.0,"id":8258569}]}]}
{"op":"mcm","clk":"1004245185","pt":1580624400170,"mc":[{"id":"1.168238842","rc":[{"batb":[[0,1.61,24.68],[1,1.01,16.01]],"ltp":0.0,"tv":0.0,"id":8860646},{"batb":[[0,1.73,24.13],[1,1.01,16.01]],"ltp":0.0,"tv":0.0,"id":8258569}]}]}
{"op":"mcm","clk":"1004260273","pt":1580624870165,"mc":[{"id":"1.168238842","rc":[{"batb":[[0,1.01,16.01],[1,1.01,0]],"ltp":0.0,"tv":0.0,"id":8860646},{"batb":[[0,1.01,16.01],[1,1.01,0]],"ltp":0.0,"tv":0.0,"id":8258569}]}]}
{"op":"mcm","clk":"1004260516","pt":1580624879767,"mc":[{"id":"1.168238842","rc":[{"batb":[[0,1.56,25.58],[1,1.01,16.01]],"ltp":0.0,"tv":0.0,"id":8860646},{"batb":[[0,1.64,25.57],[1,1.01,16.01]],"ltp":0.0,"tv":0.0,"id":8258569}]}]}
{"op":"mcm","clk":"1004266840","pt":1580625108491,"mc":[{"id":"1.168238842","rc":[{"batb":[[0,1.56,44.58]],"ltp":0.0,"tv":0.0,"id":8860646},{"batb":[[0,1.64,44.57]],"ltp":0.0,"tv":0.0,"id":8258569}]}]}
{"op":"mcm","clk":"1004381990","pt":1580628480120,"mc":[{"id":"1.168238842","rc":[{"batb":[[0,1.68,41.61]],"ltp":0.0,"tv":0.0,"id":8860646},{"batb":[[0,1.01,16.01],[1,1.01,0]],"ltp":0.0,"tv":0.0,"id":8258569}]}]}
{"op":"mcm","clk":"1004382003","pt":1580628480326,"mc":[{"id":"1.168238842","rc":[{"batb":[[0,1.51,48.77],[1,1.01,16.01]],"ltp":0.0,"tv":0.0,"id":8258569}]}]}
{"op":"mcm","clk":"1004478042","pt":1580630709992,"mc":[{"id":"1.168238842","rc":[{"batb":[[0,1.68,59.11]],"ltp":0.0,"tv":0.0,"id":8860646},{"batb":[[0,1.51,69.36]],"ltp":0.0,"tv":0.0,"id":8258569}]}]}
{"op":"mcm","clk":"1004530748","pt":1580631916265,"mc":[{"id":"1.168238842","rc":[{"batb":[[0,1.79,12.08],[1,1.68,59.11],[2,1.01,16.01]],"ltp":0.0,"tv":0.0,"id":8860646},{"batb":[[0,1.71,13.44],[1,1.51,69.36],[2,1.01,16.01]],"ltp":0.0,"tv":0.0,"id":8258569}]}]}
{"op":"mcm","clk":"1004530759","pt":1580631916472,"mc":[{"id":"1.168238842","rc":[{"batb":[[0,1.86,53.54],[1,1.79,12.08]],"ltp":0.0,"tv":0.0,"id":8860646},{"batb":[[0,1.75,59.51],[1,1.71,13.44]],"ltp":0.0,"tv":0.0,"id":8258569}]}]}
{"op":"mcm","clk":"1004531585","pt":1580631933566,"mc":[{"id":"1.168238842","marketDefinition":{"bspMarket":false,"turnInPlayEnabled":true,"persistenceEnabled":true,"marketBaseRate":5.0,"eventId":"29681898","eventTypeId":"2","numberOfWinners":1,"bettingType":"ODDS","marketType":"SET_WINNER","marketTime":"2020-02-02T19:00:00.000Z","suspendTime":"2020-02-02T19:00:00.000Z","bspReconciled":false,"complete":true,"inPlay":false,"crossMatching":true,"runnersVoidable":false,"numberOfActiveRunners":2,"betDelay":0,"status":"OPEN","runners":[{"status":"ACTIVE","sortPriority":1,"id":8860646,"name":"Daniel Elahi Galan"},{"status":"ACTIVE","sortPriority":2,"id":8258569,"name":"Thai-Son Kwiatkowski"}],"regulators":["MR_INT"],"countryCode":"US","discountAllowed":true,"timezone":"UTC","openDate":"2020-02-02T19:00:00.000Z","version":3147732914,"name":"Set 1 Winner","eventName":"Galan v Kwiatkowski"}}]}
{"op":"mcm","clk":"1004538325","pt":1580632080767,"mc":[{"id":"1.168238842","rc":[{"batb":[[0,1.89,52.41]],"ltp":0.0,"tv":0.0,"id":8860646},{"batb":[[0,1.72,60.84]],"ltp":0.0,"tv":0.0,"id":8258569}]}]}
{"op":"mcm","clk":"1004589359","pt":1580633214991,"mc":[{"id":"1.168238842","rc":[{"batb":[[1,1.01,16.01],[2,1.01,0]],"ltp":0.0,"tv":0.0,"id":8860646},{"batb":[[1,1.01,16.01],[2,1.01,0]],"ltp":0.0,"tv":0.0,"id":8258569}]}]}
{"op":"mcm","clk":"1004589382","pt":1580633215604,"mc":[{"id":"1.168238842","rc":[{"batb":[[1,1.79,12.08],[2,1.01,16.01]],"ltp":0.0,"tv":0.0,"id":8860646},{"batb":[[0,1.72,74.09]],"ltp":0.0,"tv":0.0,"id":8258569}]}]}
{"op":"mcm","clk":"1004707180","pt":1580635680819,"mc":[{"id":"1.168238842","rc":[{"batb":[[0,1.79,12.08],[1,1.01,16.01],[2,1.01,0]],"ltp":0.0,"tv":0.0,"id":8860646},{"batb":[[0,1.72,13.25]],"ltp":0.0,"tv":0.0,"id":8258569}]}]}
{"op":"mcm","clk":"1005082659","pt":1580640612797,"mc":[{"id":"1.168238842","rc":[{"batb":[[0,1.86,52.68],[1,1.79,12.08],[2,1.01,16.01]],"ltp":0.0,"tv":0.0,"id":8860646}]}]}
{"op":"mcm","clk":"1005082972","pt":1580640614986,"mc":[{"id":"1.168238842","rc":[{"batb":[[1,1.01,16.01],[2,1.01,0]],"ltp":0.0,"tv":0.0,"id":8860646},{"batb":[[0,1.01,16.01],[1,1.01,0]],"ltp":0.0,"tv":0.0,"id":8258569}]}]}
{"op":"mcm","clk":"1005083097","pt":1580640615775,"mc":[{"id":"1.168238842","rc":[{"batb":[[1,1.81,11.78],[2,1.01,16.01]],"ltp":0.0,"tv":0.0,"id":8860646},{"batb":[[0,1.7,13.63],[1,1.01,16.01]],"ltp":0.0,"tv":0.0,"id":8258569}]}]}
{"op":"mcm","clk":"1005083794","pt":1580640620572,"mc":[{"id":"1.168238842","rc":[{"batb":[[0,1.73,76.02],[1,1.7,13.63],[2,1.01,16.01]],"ltp":0.0,"tv":0.0,"id":8258569}]}]}
{"op":"mcm","clk":"1005156278","pt":1580641201144,"mc":[{"id":"1.168238842","rc":[{"batb":[[0,1.7,13.63],[1,1.01,16.01],[2,1.01,0]],"ltp":0.0,"tv":0.0,"id":8258569}]}]}
{"op":"mcm","clk":"1005156561","pt":1580641202554,"mc":[{"id":"1.168238842","rc":[{"batb":[[0,1.72,67.84],[1,1.7,13.63],[2,1.01,16.01]],"ltp":0.0,"tv":0.0,"id":8258569}]}]}
{"op":"mcm","clk":"1005171889","pt":1580641288682,"mc":[{"id":"1.168238842","rc":[{"batb":[[0,1.86,79.11]],"ltp":0.0,"tv":0.0,"id":8860646}]}]}
{"op":"mcm","clk":"1005273281","pt":1580641797573,"mc":[{"id":"1.168238842","rc":[{"batb":[[0,1.7,13.63],[1,1.01,16.01],[2,1.01,0]],"ltp":0.0,"tv":0.0,"id":8258569}]}]}
{"op":"mcm","clk":"1005273457","pt":1580641798578,"mc":[{"id":"1.168238842","rc":[{"batb":[[0,1.75,74.91],[1,1.7,13.63],[2,1.01,16.01]],"ltp":0.0,"tv":0.0,"id":8258569}]}]}
{"op":"mcm","clk":"1005329550","pt":1580642108187,"mc":[{"id":"1.168238842","rc":[{"batb":[[0,1.71,76.88]],"ltp":0.0,"tv":0.0,"id":8258569}]}]}
{"op":"mcm","clk":"1005444483","pt":1580642722481,"mc":[{"id":"1.168238842","rc":[{"batb":[[0,1.7,13.63],[1,1.01,16.01],[2,1.01,0]],"ltp":0.0,"tv":0.0,"id":8258569}]}]}
{"op":"mcm","clk":"1005444673","pt":1580642723675,"mc":[{"id":"1.168238842","rc":[{"batb":[[0,1.71,76.88],[1,1.7,13.63],[2,1.01,16.01]],"ltp":0.0,"tv":0.0,"id":8258569}]}]}
{"op":"mcm","clk":"1005449245","pt":1580642748527,"mc":[{"id":"1.168238842","rc":[{"batb":[[0,1.7,13.63],[1,1.01,16.01],[2,1.01,0]],"ltp":0.0,"tv":0.0,"id":8258569}]}]}
{"op":"mcm","clk":"1005449581","pt":1580642750238,"mc":[{"id":"1.168238842","rc":[{"batb":[[0,1.72,67.84],[1,1.7,13.63],[2,1.01,16.01]],"ltp":0.0,"tv":0.0,"id":8258569}]}]}
{"op":"mcm","clk":"1005453547","pt":1580642771264,"mc":[{"id":"1.168238842","rc":[{"batb":[[0,1.7,13.63],[1,1.01,16.01],[2,1.01,0]],"ltp":0.0,"tv":0.0,"id":8258569}]}]}
{"op":"mcm","clk":"1005453709","pt":1580642772165,"mc":[{"id":"1.168238842","rc":[{"batb":[[0,1.76,74.48],[1,1.7,13.63],[2,1.01,16.01]],"ltp":0.0,"tv":0.0,"id":8258569}]}]}
{"op":"mcm","clk":"1005487912","pt":1580642957207,"mc":[{"id":"1.168238842","rc":[{"batb":[[1,1.82,17.36]],"ltp":0.0,"tv":0.0,"id":8860646},{"batb":[[1,1.74,19.24]],"ltp":0.0,"tv":0.0,"id":8258569}]}]}
{"op":"mcm","clk":"1005494715","pt":1580642994663,"mc":[{"id":"1.168238842","rc":[{"batb":[[1,1.01,16.01],[2,1.01,0]],"ltp":0.0,"tv":0.0,"id":8860646},{"batb":[[1,1.01,16.01],[2,1.01,0]],"ltp":0.0,"tv":0.0,"id":8258569}]}]}
{"op":"mcm","clk":"1005494846","pt":1580642995427,"mc":[{"id":"1.168238842","rc":[{"batb":[[1,1.81,17.58],[2,1.01,16.01]],"ltp":0.0,"tv":0.0,"id":8860646},{"batb":[[1,1.74,19.24],[2,1.01,16.01]],"ltp":0.0,"tv":0.0,"id":8258569}]}]}
{"op":"mcm","clk":"1005569747","pt":1580643382016,"mc":[{"id":"1.168238842","rc":[{"batb":[[0,1.78,88.07]],"ltp":0.0,"tv":0.0,"id":8258569}]}]}
{"op":"mcm","clk":"1005722654","pt":1580644214028,"mc":[{"id":"1.168238842","rc":[{"batb":[[0,1.82,82.03]],"ltp":0.0,"tv":0.0,"id":8860646}]}]}
{"op":"mcm","clk":"1005795874","pt":1580644771824,"mc":[{"id":"1.168238842","rc":[{"batb":[[1,1.01,16.01],[2,1.01,0]],"ltp":0.0,"tv":0.0,"id":8860646},{"batb":[[1,1.01,16.01],[2,1.01,0]],"ltp":0.0,"tv":0.0,"id":8258569}]}]}
{"op":"mcm","clk":"1005795947","pt":1580644772417,"mc":[{"id":"1.168238842","rc":[{"batb":[[0,1.82,99.39]],"ltp":0.0,"tv":0.0,"id":8860646},{"batb":[[1,1.73,19.5],[2,1.01,16.01]],"ltp":0.0,"tv":0.0,"id":8258569}]}]}
{"op":"mcm","clk":"1005892811","pt":1580645315255,"mc":[{"id":"1.168238842","rc":[{"batb":[[0,1.82,82.03]],"ltp":0.0,"tv":0.0,"id":8860646},{"batb":[[1,1.01,16.01],[2,1.01,0]],"ltp":0.0,"tv":0.0,"id":8258569}]}]}
{"op":"mcm","clk":"1005892980","pt":1580645315950,"mc":[{"id":"1.168238842","rc":[{"batb":[[1,1.81,17.58],[2,1.01,16.01]],"ltp":0.0,"tv":0.0,"id":8860646},{"batb":[[1,1.75,18.98],[2,1.01,16.01]],"ltp":0.0,"tv":0.0,"id":8258569}]}]}
{"op":"mcm","clk":"1005904690","pt":1580645374790,"mc":[{"id":"1.168238842","rc":[{"batb":[[1,1.01,16.01],[2,1.01,0]],"ltp":0.0,"tv":0.0,"id":8860646},{"batb":[[1,1.01,16.01],[2,1.01,0]],"ltp":0.0,"tv":0.0,"id":8258569}]}]}
{"op":"mcm","clk":"1005904890","pt":1580645375897,"mc":[{"id":"1.168238842","rc":[{"batb":[[0,1.88,78.21],[1,1.85,16.75],[2,1.01,16.01]],"ltp":0.0,"tv":0.0,"id":8860646},{"batb":[[1,1.7,20.34],[2,1.01,16.01]],"ltp":0.0,"tv":0.0,"id":8258569}]}]}
{"op":"mcm","clk":"1006124120","pt":1580646623189,"mc":[{"id":"1.168238842","rc":[{"batb":[[1,1.86,16.55]],"ltp":0.0,"tv":0.0,"id":8860646}]}]}
{"op":"mcm","clk":"1006189857","pt":1580646982008,"mc":[{"id":"1.168238842","rc":[{"batb":[[0,1.7,20.34],[1,1.01,16.01],[2,1.01,0]],"ltp":0.0,"tv":0.0,"id":8258569}]}]}
{"op":"mcm","clk":"1006344602","pt":1580647815000,"mc":[{"id":"1.168238842","rc":[{"batb":[[0,1.87,79.27]],"ltp":0.0,"tv":0.0,"id":8860646}]}]}
{"op":"mcm","clk":"1006344694","pt":1580647815477,"mc":[{"id":"1.168238842","rc":[{"batb":[[0,1.8,72.78],[1,1.7,20.34],[2,1.01,16.01]],"ltp":0.0,"tv":0.0,"id":8258569}]}]}
{"op":"mcm","clk":"1006389000","pt":1580648124951,"mc":[{"id":"1.168238842","rc":[{"batb":[[0,1.7,20.34],[1,1.01,16.01],[2,1.01,0]],"ltp":0.0,"tv":0.0,"id":8258569}]}]}
{"op":"mcm","clk":"1006389074","pt":1580648125531,"mc":[{"id":"1.168238842","rc":[{"batb":[[0,1.8,72.78],[1,1.7,20.34],[2,1.01,16.01]],"ltp":0.0,"tv":0.0,"id":8258569}]}]}
{"op":"mcm","clk":"1006430579","pt":1580648435818,"mc":[{"id":"1.168238842","rc":[{"batb":[[0,1.72,76.34]],"ltp":0.0,"tv":0.0,"id":8258569}]}]}
{"op":"mcm","clk":"1006472006","pt":1580648746220,"mc":[{"id":"1.168238842","rc":[{"batb":[[0,1.76,74.48]],"ltp":0.0,"tv":0.0,"id":8258569}]}]}
{"op":"mcm","clk":"1006517187","pt":1580649057179,"mc":[{"id":"1.168238842","rc":[{"batb":[[0,1.71,76.88]],"ltp":0.0,"tv":0.0,"id":8258569}]}]}
{"op":"mcm","clk":"1006564804","pt":1580649366845,"mc":[{"id":"1.168238842","rc":[{"batb":[[0,1.7,20.34],[1,1.01,16.01],[2,1.01,0]],"ltp":0.0,"tv":0.0,"id":8258569}]}]}
{"op":"mcm","clk":"1006564909","pt":1580649367546,"mc":[{"id":"1.168238842","rc":[{"batb":[[0,1.73,76.02],[1,1.7,20.34],[2,1.01,16.01]],"ltp":0.0,"tv":0.0,"id":8258569}]}]}
{"op":"mcm","clk":"1006609760","pt":1580649677248,"mc":[{"id":"1.168238842","rc":[{"batb":[[0,1.7,20.34],[1,1.01,16.01],[2,1.01,0]],"ltp":0.0,"tv":0.0,"id":8258569}]}]}
{"op":"mcm","clk":"1006609861","pt":1580649677839,"mc":[{"id":"1.168238842","rc":[{"batb":[[0,1.73,76.02],[1,1.7,20.34],[2,1.01,16.01]],"ltp":0.0,"tv":0.0,"id":8258569}]}]}
{"op":"mcm","clk":"1006654791","pt":1580649987841,"mc":[{"id":"1.168238842","rc":[{"batb":[[0,1.72,76.34]],"ltp":0.0,"tv":0.0,"id":8258569}]}]}
{"op":"mcm","clk":"1006698912","pt":1580650297742,"mc":[{"id":"1.168238842","rc":[{"batb":[[0,1.7,20.34],[1,1.01,16.01],[2,1.01,0]],"ltp":0.0,"tv":0.0,"id":8258569}]}]}
{"op":"mcm","clk":"1006699086","pt":1580650298954,"mc":[{"id":"1.168238842","rc":[{"batb":[[0,1.76,74.48],[1,1.7,20.34],[2,1.01,16.01]],"ltp":0.0,"tv":0.0,"id":8258569}]}]}
{"op":"mcm","clk":"1006862487","pt":1580651414973,"mc":[{"id":"1.168238842","rc":[{"batb":[[0,1.86,16.55],[1,1.01,16.01],[2,1.01,0]],"ltp":0.0,"tv":0.0,"id":8860646}]}]}
{"op":"mcm","clk":"1006914004","pt":1580651813222,"mc":[{"id":"1.168238842","rc":[{"batb":[[0,1.89,78.41],[1,1.86,16.55],[2,1.01,16.01]],"ltp":0.0,"tv":0.0,"id":8860646},{"batb":[[0,1.74,75.52]],"ltp":0.0,"tv":0.0,"id":8258569}]}]}
{"op":"mcm","clk":"1006928806","pt":1580651919270,"mc":[{"id":"1.168238842","rc":[{"batb":[[0,1.71,68.19]],"ltp":0.0,"tv":0.0,"id":8258569}]}]}
{"op":"mcm","clk":"1006980095","pt":1580652259042,"mc":[{"id":"1.168238842","rc":[{"batb":[[0,1.89,104.78]],"ltp":0.0,"tv":0.0,"id":8860646}]}]}
{"op":"mcm","clk":"1007028551","pt":1580652529007,"mc":[{"id":"1.168238842","rc":[{"batb":[[0,1.7,20.34],[1,1.01,16.01],[2,1.01,0]],"ltp":0.0,"tv":0.0,"id":8258569}]}]}
{"op":"mcm","clk":"1007028811","pt":1580652530204,"mc":[{"id":"1.168238842","rc":[{"batb":[[0,1.75,66.55],[1,1.7,20.34],[2,1.01,16.01]],"ltp":0.0,"tv":0.0,"id":8258569}]}]}
{"op":"mcm","clk":"1007089651","pt":1580652871033,"mc":[{"id":"1.168238842","rc":[{"batb":[[0,1.7,20.34],[1,1.01,16.01],[2,1.01,0]],"ltp":0.0,"tv":0.0,"id":8258569}]}]}
{"op":"mcm","clk":"1007407202","pt":1580654828167,"mc":[{"id":"1.168238842","rc":[{"batb":[[0,1.86,16.55],[1,1.01,16.01],[2,1.01,0]],"ltp":0.0,"tv":0.0,"id":8860646}]}]}
{"op":"mcm","clk":"1007418620","pt":1580654916832,"mc":[{"id":"1.168238842","rc":[{"batb":[[0,1.01,16.01],[1,1.01,0]],"ltp":0.0,"tv":0.0,"id":8860646},{"batb":[[0,1.01,16.01],[1,1.01,0]],"ltp":0.0,"tv":0.0,"id":8258569}]}]}
{"op":"mcm","clk":"1007418770","pt":1580654918130,"mc":[{"id":"1.168238842","rc":[{"batb":[[0,1.86,61.11],[1,1.85,22.27],[2,1.01,16.01]],"ltp":0.0,"tv":0.0,"id":8860646},{"batb":[[0,1.77,65.98],[1,1.72,26.29],[2,1.01,16.01]],"ltp":0.0,"tv":0.0,"id":8258569}]}]}
{"op":"mcm","clk":"1007496062","pt":1580655540165,"mc":[{"id":"1.168238842","rc":[{"batb":[[0,1.86,104.97]],"ltp":0.0,"tv":0.0,"id":8860646}]}]}
{"op":"mcm","clk":"1007497979","pt":1580655554881,"mc":[{"id":"1.168238842","rc":[{"batb":[[0,1.72,26.29],[1,1.01,16.01],[2,1.01,0]],"ltp":0.0,"tv":0.0,"id":8258569}]}]}
{"op":"mcm","clk":"1007498122","pt":1580655556175,"mc":[{"id":"1.168238842","rc":[{"batb":[[0,1.8,72.78],[1,1.72,26.29],[2,1.01,16.01]],"ltp":0.0,"tv":0.0,"id":8258569}]}]}
{"op":"mcm","clk":"1007616398","pt":1580656172410,"mc":[{"id":"1.168238842","rc":[{"batb":[[0,1.72,26.29],[1,1.01,16.01],[2,1.01,0]],"ltp":0.0,"tv":0.0,"id":8258569}]}]}
{"op":"mcm","clk":"1007678207","pt":1580656429274,"mc":[{"id":"1.168238842","rc":[{"batl":[[0,2.38,3.79]],"ltp":0.0,"tv":0.0,"id":8860646},{"batl":[[0,2.16,5.3]],"ltp":0.0,"tv":0.0,"id":8258569}]}]}
{"op":"mcm","clk":"1007678429","pt":1580656430067,"mc":[{"id":"1.168238842","rc":[{"batl":[[0,2.36,55.57],[1,2.38,3.79]],"ltp":0.0,"tv":0.0,"id":8860646}]}]}
{"op":"mcm","clk":"1007681096","pt":1580656440909,"mc":[{"id":"1.168238842","rc":[{"batl":[[0,2.32,56.61],[1,2.34,3.79]],"ltp":0.0,"tv":0.0,"id":8860646}]}]}
{"op":"mcm","clk":"1007682910","pt":1580656448285,"mc":[{"id":"1.168238842","rc":[{"batl":[[1,2.34,0]],"ltp":0.0,"tv":0.0,"id":8860646}]}]}
{"op":"mcm","clk":"1007683064","pt":1580656448912,"mc":[{"id":"1.168238842","rc":[{"batl":[[0,2.28,57.59],[1,2.3,3.79]],"ltp":0.0,"tv":0.0,"id":8860646}]}]}
{"op":"mcm","clk":"1007685081","pt":1580656457021,"mc":[{"id":"1.168238842","rc":[{"batl":[[1,2.38,3.79]],"ltp":0.0,"tv":0.0,"id":8860646}]}]}
{"op":"mcm","clk":"1007872347","pt":1580657277568,"mc":[{"id":"1.168238842","rc":[{"batl":[[0,2.38,3.79],[1,2.38,0]],"ltp":0.0,"tv":0.0,"id":8860646}]}]}
{"op":"mcm","clk":"1007872543","pt":1580657278521,"mc":[{"id":"1.168238842","rc":[{"batl":[[0,2.34,49.75],[1,2.38,3.79]],"ltp":0.0,"tv":0.0,"id":8860646}]}]}
{"op":"mcm","clk":"1008008711","pt":1580657888080,"mc":[{"id":"1.168238842","rc":[{"batl":[[0,2.38,3.79],[1,2.38,0]],"ltp":0.0,"tv":0.0,"id":8860646}]}]}
{"op":"mcm","clk":"1008252297","pt":1580659140210,"mc":[{"id":"1.168238842","rc":[{"batb":[[0,1.85,22.27],[1,1.01,16.01],[2,1.01,0]],"ltp":0.0,"tv":0.0,"id":8860646}]}]}
{"op":"mcm","clk":"1008252375","pt":1580659140861,"mc":[{"id":"1.168238842","rc":[{"batl":[[0,2.3,50.65],[1,2.38,3.79]],"ltp":0.0,"tv":0.0,"id":8860646}]}]}
{"op":"mcm","clk":"1008371059","pt":1580659751225,"mc":[{"id":"1.168238842","rc":[{"batl":[[0,2.38,3.79],[1,2.38,0]],"ltp":0.0,"tv":0.0,"id":8860646},{"batl":[[0,2.14,91.18],[1,2.16,5.3]],"ltp":0.0,"tv":0.0,"id":8258569}]}]}
{"op":"mcm","clk":"1008371230","pt":1580659751975,"mc":[{"id":"1.168238842","rc":[{"batl":[[0,2.26,51.52],[1,2.38,3.79]],"ltp":0.0,"tv":0.0,"id":8860646}]}]}
{"op":"mcm","clk":"1008441656","pt":1580660061195,"mc":[{"id":"1.168238842","rc":[{"batl":[[0,2.38,3.79],[1,2.38,0]],"ltp":0.0,"tv":0.0,"id":8860646}]}]}
{"op":"mcm","clk":"1008441945","pt":1580660062525,"mc":[{"id":"1.168238842","rc":[{"batl":[[0,2.36,49.32],[1,2.38,3.79]],"ltp":0.0,"tv":0.0,"id":8860646}]}]}
{"op":"mcm","clk":"1008454823","pt":1580660117202,"mc":[{"id":"1.168238842","rc":[{"batl":[[0,2.36,55.57]],"ltp":0.0,"tv":0.0,"id":8860646}]}]}
{"op":"mcm","clk":"1008527499","pt":1580660426884,"mc":[{"id":"1.168238842","rc":[{"batl":[[0,2.38,3.79],[1,2.38,0]],"ltp":0.0,"tv":0.0,"id":8860646}]}]}
{"op":"mcm","clk":"1008527781","pt":1580660428181,"mc":[{"id":"1.168238842","rc":[{"batl":[[0,2.34,55.96],[1,2.38,3.79]],"ltp":0.0,"tv":0.0,"id":8860646}]}]}
{"op":"mcm","clk":"1008562296","pt":1580660579630,"mc":[{"id":"1.168238842","rc":[{"batl":[[0,2.38,3.79],[1,2.38,0]],"ltp":0.0,"tv":0.0,"id":8860646}]}]}
{"op":"mcm","clk":"1008562457","pt":1580660580318,"mc":[{"id":"1.168238842","rc":[{"batl":[[0,2.3,50.65],[1,2.38,3.79]],"ltp":0.0,"tv":0.0,"id":8860646}]}]}
{"op":"mcm","clk":"1008629737","pt":1580660891243,"mc":[{"id":"1.168238842","rc":[{"batl":[[0,2.36,49.32]],"ltp":0.0,"tv":0.0,"id":8860646}]}]}
{"op":"mcm","clk":"1008761946","pt":1580661500935,"mc":[{"id":"1.168238842","rc":[{"batl":[[0,2.38,3.79],[1,2.38,0]],"ltp":0.0,"tv":0.0,"id":8860646}]}]}
{"op":"mcm","clk":"1008762239","pt":1580661502233,"mc":[{"id":"1.168238842","rc":[{"batl":[[0,2.36,49.32],[1,2.38,3.79]],"ltp":0.0,"tv":0.0,"id":8860646}]}]}
{"op":"mcm","clk":"1008963462","pt":1580662668951,"mc":[{"id":"1.168238842","rc":[{"batl":[[0,2.38,3.79],[1,2.38,0]],"ltp":0.0,"tv":0.0,"id":8860646}]}]}
{"op":"mcm","clk":"1008963554","pt":1580662669737,"mc":[{"id":"1.168238842","rc":[{"batl":[[0,2.32,56.61],[1,2.38,3.79]],"ltp":0.0,"tv":0.0,"id":8860646}]}]}
{"op":"mcm","clk":"1009070980","pt":1580663351158,"mc":[{"id":"1.168238842","rc":[{"batl":[[0,2.16,5.3],[1,2.16,0]],"ltp":0.0,"tv":0.0,"id":8258569}]}]}
{"op":"mcm","clk":"1009092139","pt":1580663484602,"mc":[{"id":"1.168238842","rc":[{"batl":[[0,2.12,92.46],[1,2.16,5.3]],"ltp":0.0,"tv":0.0,"id":8258569}]}]}
{"op":"mcm","clk":"1009092498","pt":1580663486935,"mc":[{"id":"1.168238842","rc":[{"batb":[[0,1.01,16.01],[1,1.01,0]],"ltp":0.0,"tv":0.0,"id":8860646},{"batb":[[0,1.01,16.01],[1,1.01,0]],"ltp":0.0,"tv":0.0,"id":8258569}]}]}
{"op":"mcm","clk":"1009092693","pt":1580663488255,"mc":[{"id":"1.168238842","rc":[{"batb":[[0,1.85,22.27],[1,1.01,16.01]],"ltp":0.0,"tv":0.0,"id":8860646},{"batb":[[0,1.72,26.29],[1,1.01,16.01]],"ltp":0.0,"tv":0.0,"id":8258569}]}]}
{"op":"mcm","clk":"1009108212","pt":1580663579240,"mc":[{"id":"1.168238842","rc":[{"batl":[[0,2.38,3.79],[1,2.38,0]],"ltp":0.0,"tv":0.0,"id":8860646}]}]}
{"op":"mcm","clk":"1009455419","pt":1580665901104,"mc":[{"id":"1.168238842","rc":[{"batl":[[0,2.08,94.19],[1,2.1,5.3]],"ltp":0.0,"tv":0.0,"id":8258569}]}]}
{"op":"mcm","clk":"1009455444","pt":1580665901312,"mc":[{"id":"1.168238842","rc":[{"batl":[[0,2.24,58.48],[1,2.38,3.79]],"ltp":0.0,"tv":0.0,"id":8860646}]}]}
{"op":"mcm","clk":"1009456506","pt":1580665911820,"mc":[{"id":"1.168238842","rc":[{"batl":[[1,2.16,5.3]],"ltp":0.0,"tv":0.0,"id":8258569}]}]}
{"op":"mcm","clk":"1009505845","pt":1580666409214,"mc":[{"id":"1.168238842","rc":[{"batb":[[0,1.01,16.01],[1,1.01,0]],"ltp":0.0,"tv":0.0,"id":8860646},{"batb":[[0,1.01,16.01],[1,1.01,0]],"ltp":0.0,"tv":0.0,"id":8258569}]}]}
{"op":"mcm","clk":"1009522818","pt":1580666586397,"mc":[{"id":"1.168238842","rc":[{"batl":[[0,2.38,3.79],[1,2.38,0]],"ltp":0.0,"tv":0.0,"id":8860646}]}]}
{"op":"mcm","clk":"1009574414","pt":1580667085129,"mc":[{"id":"1.168238842","rc":[{"batl":[[0,2.16,5.3],[1,2.16,0]],"ltp":0.0,"tv":0.0,"id":8258569}]}]}
{"op":"mcm","clk":"1009574481","pt":1580667085917,"mc":[{"id":"1.168238842","rc":[{"batl":[[0,2.24,51.98],[1,2.38,3.79]],"ltp":0.0,"tv":0.0,"id":8860646},{"batl":[[0,2.08,93.69],[1,2.16,5.3]],"ltp":0.0,"tv":0.0,"id":8258569}]}]}
{"op":"mcm","clk":"1009686141","pt":1580668350880,"mc":[{"id":"1.168238842","rc":[{"batl":[[0,2.38,3.79],[1,2.38,0]],"ltp":0.0,"tv":0.0,"id":8860646}]}]}
{"op":"mcm","clk":"1009686226","pt":1580668351821,"mc":[{"id":"1.168238842","rc":[{"batl":[[0,2.3,56.95],[1,2.38,3.79]],"ltp":0.0,"tv":0.0,"id":8860646}]}]}
{"op":"mcm","clk":"1009754033","pt":1580669066203,"mc":[{"id":"1.168238842","rc":[{"batl":[[0,2.34,88.51]],"ltp":0.0,"tv":0.0,"id":8860646}]}]}
{"op":"mcm","clk":"1009755189","pt":1580669079062,"mc":[{"id":"1.168238842","rc":[{"batb":[[0,1.01,17.32]],"ltp":0.0,"tv":0.0,"id":8860646},{"batb":[[0,1.01,17.69]],"ltp":0.0,"tv":0.0,"id":8258569}]}]}
{"op":"mcm","clk":"1009755258","pt":1580669079885,"mc":[{"id":"1.168238842","rc":[{"batb":[[0,1.93,1.3],[1,1.01,16.01]],"batl":[[0,2.38,3.79],[1,2.38,0]],"ltp":0.0,"tv":0.0,"id":8860646},{"batb":[[0,1.78,116.16],[1,1.75,1.44],[2,1.01,16.01]],"batl":[[0,2.16,5.3],[1,2.16,0]],"ltp":0.0,"tv":0.0,"id":8258569}]}]}
{"op":"mcm","clk":"1009757791","pt":1580669109129,"mc":[{"id":"1.168238842","rc":[{"batb":[[1,1.01,17.69],[2,1.01,0]],"ltp":0.0,"tv":0.0,"id":8258569}]}]}
{"op":"mcm","clk":"1009757919","pt":1580669110081,"mc":[{"id":"1.168238842","rc":[{"batb":[[0,1.85,111.77],[1,1.79,1.41],[2,1.01,16.01]],"ltp":0.0,"tv":0.0,"id":8258569}]}]}
{"op":"mcm","clk":"1009760461","pt":1580669140045,"mc":[{"id":"1.168238842","rc":[{"batb":[[1,1.01,17.37],[2,1.01,0]],"ltp":0.0,"tv":0.0,"id":8258569}]}]}
{"op":"mcm","clk":"1009760538","pt":1580669140728,"mc":[{"id":"1.168238842","rc":[{"batb":[[0,1.86,112.53],[1,1.01,16.01]],"ltp":0.0,"tv":0.0,"id":8258569}]}]}
{"op":"mcm","clk":"1009805087","pt":1580669626250,"mc":[{"id":"1.168238842","rc":[{"batb":[[0,1.86,1.35]],"ltp":0.0,"tv":0.0,"id":8258569}]}]}
{"op":"mcm","clk":"1009805163","pt":1580669627081,"mc":[{"id":"1.168238842","rc":[{"batb":[[0,1.94,100.92],[1,1.93,1.3],[2,1.01,16.01]],"ltp":0.0,"tv":0.0,"id":8860646}]}]}
{"op":"mcm","clk":"1009807353","pt":1580669649101,"mc":[{"id":"1.168238842","rc":[{"batb":[[0,1.95,1.29],[1,1.94,100.92]],"ltp":0.0,"tv":0.0,"id":8860646}]}]}
{"op":"mcm","clk":"1009807405","pt":1580669649508,"mc":[{"id":"1.168238842","rc":[{"batb":[[0,1.95,101.8],[1,1.01,16.01],[2,1.01,0]],"ltp":0.0,"tv":0.0,"id":8860646}]}]}
{"op":"mcm","clk":"1009851683","pt":1580670107906,"mc":[{"id":"1.168238842","marketDefinition":{"bspMarket":false,"turnInPlayEnabled":true,"persistenceEnabled":true,"marketBaseRate":5.0,"eventId":"29681898","eventTypeId":"2","numberOfWinners":1,"bettingType":"ODDS","marketType":"SET_WINNER","marketTime":"2020-02-02T19:15:00.000Z","suspendTime":"2020-02-02T19:15:00.000Z","bspReconciled":false,"complete":true,"inPlay":false,"crossMatching":true,"runnersVoidable":false,"numberOfActiveRunners":2,"betDelay":0,"status":"OPEN","runners":[{"status":"ACTIVE","sortPriority":1,"id":8860646,"name":"Daniel Elahi Galan"},{"status":"ACTIVE","sortPriority":2,"id":8258569,"name":"Thai-Son Kwiatkowski"}],"regulators":["MR_INT"],"countryCode":"US","discountAllowed":true,"timezone":"UTC","openDate":"2020-02-02T19:00:00.000Z","version":3150309945,"name":"Set 1 Winner","eventName":"Galan v Kwiatkowski"}}]}
{"op":"mcm","clk":"1009851975","pt":1580670109936,"mc":[{"id":"1.168238842","marketDefinition":{"bspMarket":false,"turnInPlayEnabled":true,"persistenceEnabled":true,"marketBaseRate":5.0,"eventId":"29681898","eventTypeId":"2","numberOfWinners":1,"bettingType":"ODDS","marketType":"SET_WINNER","marketTime":"2020-02-02T19:15:00.000Z","suspendTime":"2020-02-02T19:15:00.000Z","bspReconciled":false,"complete":true,"inPlay":false,"crossMatching":true,"runnersVoidable":false,"numberOfActiveRunners":2,"betDelay":0,"status":"OPEN","runners":[{"status":"ACTIVE","sortPriority":1,"id":8860646,"name":"Daniel Elahi Galan"},{"status":"ACTIVE","sortPriority":2,"id":8258569,"name":"Thai-Son Kwiatkowski"}],"regulators":["MR_INT"],"countryCode":"US","discountAllowed":true,"timezone":"UTC","openDate":"2020-02-02T19:15:00.000Z","version":3150309945,"name":"Set 1 Winner","eventName":"Galan v Kwiatkowski"}}]}
{"op":"mcm","clk":"1009859411","pt":1580670172592,"mc":[{"id":"1.168238842","rc":[{"batb":[[0,1.95,1.29]],"ltp":0.0,"tv":0.0,"id":8860646}]}]}
{"op":"mcm","clk":"1009861629","pt":1580670191103,"mc":[{"id":"1.168238842","rc":[{"batb":[[0,1.96,102.38],[1,1.95,1.29],[2,1.01,16.01]],"ltp":0.0,"tv":0.0,"id":8860646}]}]}
{"op":"mcm","clk":"1009865076","pt":1580670220215,"mc":[{"id":"1.168238842","rc":[{"batb":[[1,1.01,16.01],[2,1.01,0]],"ltp":0.0,"tv":0.0,"id":8860646}]}]}
{"op":"mcm","clk":"1009865146","pt":1580670220692,"mc":[{"id":"1.168238842","rc":[{"batb":[[0,1.98,101.26],[1,1.97,1.28],[2,1.01,16.01]],"ltp":0.0,"tv":0.0,"id":8860646}]}]}
{"op":"mcm","clk":"1009868792","pt":1580670252250,"mc":[{"id":"1.168238842","rc":[{"batb":[[1,1.01,17.69],[2,1.01,0]],"ltp":0.0,"tv":0.0,"id":8860646}]}]}
{"op":"mcm","clk":"1009868903","pt":1580670253252,"mc":[{"id":"1.168238842","rc":[{"batb":[[0,2,100.48],[1,1.99,1.27],[2,1.01,16.01]],"ltp":0.0,"tv":0.0,"id":8860646}]}]}
{"op":"mcm","clk":"1009871566","pt":1580670277196,"mc":[{"id":"1.168238842","rc":[{"batb":[[1,1.01,17.69],[2,1.01,0]],"ltp":0.0,"tv":0.0,"id":8860646}]}]}
{"op":"mcm","clk":"1009871657","pt":1580670277994,"mc":[{"id":"1.168238842","rc":[{"batb":[[0,2.02,1.25],[1,2,100.48],[2,1.01,16.01]],"ltp":0.0,"tv":0.0,"id":8860646}]}]}
{"op":"mcm","clk":"1009871704","pt":1580670278398,"mc":[{"id":"1.168238842","rc":[{"batb":[[0,2.02,100.49],[1,1.01,16.01],[2,1.01,0]],"ltp":0.0,"tv":0.0,"id":8860646}]}]}
{"op":"mcm","clk":"1009895195","pt":1580670472272,"mc":[{"id":"1.168238842","rc":[{"batb":[[0,2.02,1.25]],"ltp":0.0,"tv":0.0,"id":8860646}]}]}
{"op":"mcm","clk":"1009919727","pt":1580670669259,"mc":[{"id":"1.168238842","rc":[{"batb":[[1,1.01,16.02]],"ltp":0.0,"tv":0.0,"id":8860646},{"batb":[[1,1.01,16.02]],"ltp":0.0,"tv":0.0,"id":8258569}]}]}
{"op":"mcm","clk":"1009963861","pt":1580671008639,"mc":[{"id":"1.168238842","marketDefinition":{"bspMarket":false,"turnInPlayEnabled":true,"persistenceEnabled":true,"marketBaseRate":5.0,"eventId":"29681898","eventTypeId":"2","numberOfWinners":1,"bettingType":"ODDS","marketType":"SET_WINNER","marketTime":"2020-02-02T19:30:00.000Z","suspendTime":"2020-02-02T19:30:00.000Z","bspReconciled":false,"complete":true,"inPlay":false,"crossMatching":true,"runnersVoidable":false,"numberOfActiveRunners":2,"betDelay":0,"status":"OPEN","runners":[{"status":"ACTIVE","sortPriority":1,"id":8860646,"name":"Daniel Elahi Galan"},{"status":"ACTIVE","sortPriority":2,"id":8258569,"name":"Thai-Son Kwiatkowski"}],"regulators":["MR_INT"],"countryCode":"US","discountAllowed":true,"timezone":"UTC","openDate":"2020-02-02T19:15:00.000Z","version":3150350849,"name":"Set 1 Winner","eventName":"Galan v Kwiatkowski"}}]}
{"op":"mcm","clk":"1009964241","pt":1580671011646,"mc":[{"id":"1.168238842","marketDefinition":{"bspMarket":false,"turnInPlayEnabled":true,"persistenceEnabled":true,"marketBaseRate":5.0,"eventId":"29681898","eventTypeId":"2","numberOfWinners":1,"bettingType":"ODDS","marketType":"SET_WINNER","marketTime":"2020-02-02T19:30:00.000Z","suspendTime":"2020-02-02T19:30:00.000Z","bspReconciled":false,"complete":true,"inPlay":false,"crossMatching":true,"runnersVoidable":false,"numberOfActiveRunners":2,"betDelay":0,"status":"OPEN","runners":[{"status":"ACTIVE","sortPriority":1,"id":8860646,"name":"Daniel Elahi Galan"},{"status":"ACTIVE","sortPriority":2,"id":8258569,"name":"Thai-Son Kwiatkowski"}],"regulators":["MR_INT"],"countryCode":"US","discountAllowed":true,"timezone":"UTC","openDate":"2020-02-02T19:30:00.000Z","version":3150350849,"name":"Set 1 Winner","eventName":"Galan v Kwiatkowski"}}]}
{"op":"mcm","clk":"1010073708","pt":1580671908035,"mc":[{"id":"1.168238842","marketDefinition":{"bspMarket":false,"turnInPlayEnabled":true,"persistenceEnabled":true,"marketBaseRate":5.0,"eventId":"29681898","eventTypeId":"2","numberOfWinners":1,"bettingType":"ODDS","marketType":"SET_WINNER","marketTime":"2020-02-02T19:45:00.000Z","suspendTime":"2020-02-02T19:45:00.000Z","bspReconciled":false,"complete":true,"inPlay":false,"crossMatching":true,"runnersVoidable":false,"numberOfActiveRunners":2,"betDelay":0,"status":"OPEN","runners":[{"status":"ACTIVE","sortPriority":1,"id":8860646,"name":"Daniel Elahi Galan"},{"status":"ACTIVE","sortPriority":2,"id":8258569,"name":"Thai-Son Kwiatkowski"}],"regulators":["MR_INT"],"countryCode":"US","discountAllowed":true,"timezone":"UTC","openDate":"2020-02-02T19:30:00.000Z","version":3150384453,"name":"Set 1 Winner","eventName":"Galan v Kwiatkowski"}}]}
{"op":"mcm","clk":"1010074096","pt":1580671911042,"mc":[{"id":"1.168238842","marketDefinition":{"bspMarket":false,"turnInPlayEnabled":true,"persistenceEnabled":true,"marketBaseRate":5.0,"eventId":"29681898","eventTypeId":"2","numberOfWinners":1,"bettingType":"ODDS","marketType":"SET_WINNER","marketTime":"2020-02-02T19:45:00.000Z","suspendTime":"2020-02-02T19:45:00.000Z","bspReconciled":false,"complete":true,"inPlay":false,"crossMatching":true,"runnersVoidable":false,"numberOfActiveRunners":2,"betDelay":0,"status":"OPEN","runners":[{"status":"ACTIVE","sortPriority":1,"id":8860646,"name":"Daniel Elahi Galan"},{"status":"ACTIVE","sortPriority":2,"id":8258569,"name":"Thai-Son Kwiatkowski"}],"regulators":["MR_INT"],"countryCode":"US","discountAllowed":true,"timezone":"UTC","openDate":"2020-02-02T19:45:00.000Z","version":3150384453,"name":"Set 1 Winner","eventName":"Galan v Kwiatkowski"}}]}
{"op":"mcm","clk":"1010101563","pt":1580672139122,"mc":[{"id":"1.168238842","rc":[{"batb":[[0,2.04,99.37],[1,2.02,1.25],[2,1.01,16.02]],"ltp":0.0,"tv":0.0,"id":8860646}]}]}
{"op":"mcm","clk":"1010181430","pt":1580672808353,"mc":[{"id":"1.168238842","marketDefinition":{"bspMarket":false,"turnInPlayEnabled":true,"persistenceEnabled":true,"marketBaseRate":5.0,"eventId":"29681898","eventTypeId":"2","numberOfWinners":1,"bettingType":"ODDS","marketType":"SET_WINNER","marketTime":"2020-02-02T20:00:00.000Z","suspendTime":"2020-02-02T20:00:00.000Z","bspReconciled":false,"complete":true,"inPlay":false,"crossMatching":true,"runnersVoidable":false,"numberOfActiveRunners":2,"betDelay":0,"status":"OPEN","runners":[{"status":"ACTIVE","sortPriority":1,"id":8860646,"name":"Daniel Elahi Galan"},{"status":"ACTIVE","sortPriority":2,"id":8258569,"name":"Thai-Son Kwiatkowski"}],"regulators":["MR_INT"],"countryCode":"US","discountAllowed":true,"timezone":"UTC","openDate":"2020-02-02T19:45:00.000Z","version":3150416836,"name":"Set 1 Winner","eventName":"Galan v Kwiatkowski"}}]}
{"op":"mcm","clk":"1010183449","pt":1580672828399,"mc":[{"id":"1.168238842","marketDefinition":{"bspMarket":false,"turnInPlayEnabled":true,"persistenceEnabled":true,"marketBaseRate":5.0,"eventId":"29681898","eventTypeId":"2","numberOfWinners":1,"bettingType":"ODDS","marketType":"SET_WINNER","marketTime":"2020-02-02T20:00:00.000Z","suspendTime":"2020-02-02T20:00:00.000Z","bspReconciled":false,"complete":true,"inPlay":false,"crossMatching":true,"runnersVoidable":false,"numberOfActiveRunners":2,"betDelay":0,"status":"OPEN","runners":[{"status":"ACTIVE","sortPriority":1,"id":8860646,"name":"Daniel Elahi Galan"},{"status":"ACTIVE","sortPriority":2,"id":8258569,"name":"Thai-Son Kwiatkowski"}],"regulators":["MR_INT"],"countryCode":"US","discountAllowed":true,"timezone":"UTC","openDate":"2020-02-02T20:00:00.000Z","version":3150416836,"name":"Set 1 Winner","eventName":"Galan v Kwiatkowski"}}]}
{"op":"mcm","clk":"1010230814","pt":1580673380172,"mc":[{"id":"1.168238842","rc":[{"batb":[[0,2.02,1.25],[1,1.01,16.02],[2,1.01,0]],"ltp":0.0,"tv":0.0,"id":8860646}]}]}
{"op":"mcm","clk":"1010231529","pt":1580673390208,"mc":[{"id":"1.168238842","rc":[{"batb":[[0,2.04,102.62],[1,2.02,1.25],[2,1.01,16.02]],"ltp":0.0,"tv":0.0,"id":8860646}]}]}
{"op":"mcm","clk":"1010231645","pt":1580673391423,"mc":[{"id":"1.168238842","rc":[{"batb":[[0,2.02,1.25],[1,1.01,16.02],[2,1.01,0]],"ltp":0.0,"tv":0.0,"id":8860646}]}]}
{"op":"mcm","clk":"1010231808","pt":1580673393527,"mc":[{"id":"1.168238842","rc":[{"batb":[[0,2.08,100.56],[1,2.02,1.25],[2,1.01,16.02]],"ltp":0.0,"tv":0.0,"id":8860646}]}]}
{"op":"mcm","clk":"1010256348","pt":1580673709097,"mc":[{"id":"1.168238842","marketDefinition":{"bspMarket":false,"turnInPlayEnabled":true,"persistenceEnabled":true,"marketBaseRate":5.0,"eventId":"29681898","eventTypeId":"2","numberOfWinners":1,"bettingType":"ODDS","marketType":"SET_WINNER","marketTime":"2020-02-02T20:15:00.000Z","suspendTime":"2020-02-02T20:15:00.000Z","bspReconciled":false,"complete":true,"inPlay":false,"crossMatching":true,"runnersVoidable":false,"numberOfActiveRunners":2,"betDelay":0,"status":"OPEN","runners":[{"status":"ACTIVE","sortPriority":1,"id":8860646,"name":"Daniel Elahi Galan"},{"status":"ACTIVE","sortPriority":2,"id":8258569,"name":"Thai-Son Kwiatkowski"}],"regulators":["MR_INT"],"countryCode":"US","discountAllowed":true,"timezone":"UTC","openDate":"2020-02-02T20:00:00.000Z","version":3150445148,"name":"Set 1 Winner","eventName":"Galan v Kwiatkowski"}}]}
{"op":"mcm","clk":"1010256461","pt":1580673710634,"mc":[{"id":"1.168238842","marketDefinition":{"bspMarket":false,"turnInPlayEnabled":true,"persistenceEnabled":true,"marketBaseRate":5.0,"eventId":"29681898","eventTypeId":"2","numberOfWinners":1,"bettingType":"ODDS","marketType":"SET_WINNER","marketTime":"2020-02-02T20:15:00.000Z","suspendTime":"2020-02-02T20:15:00.000Z","bspReconciled":false,"complete":true,"inPlay":false,"crossMatching":true,"runnersVoidable":false,"numberOfActiveRunners":2,"betDelay":0,"status":"OPEN","runners":[{"status":"ACTIVE","sortPriority":1,"id":8860646,"name":"Daniel Elahi Galan"},{"status":"ACTIVE","sortPriority":2,"id":8258569,"name":"Thai-Son Kwiatkowski"}],"regulators":["MR_INT"],"countryCode":"US","discountAllowed":true,"timezone":"UTC","openDate":"2020-02-02T20:15:00.000Z","version":3150445148,"name":"Set 1 Winner","eventName":"Galan v Kwiatkowski"}}]}
{"op":"mcm","clk":"1010257579","pt":1580673725625,"mc":[{"id":"1.168238842","rc":[{"batb":[[0,2.02,1.25],[1,1.01,16.02],[2,1.01,0]],"ltp":0.0,"tv":0.0,"id":8860646}]}]}
{"op":"mcm","clk":"1010260584","pt":1580673766832,"mc":[{"id":"1.168238842","rc":[{"batb":[[0,2.04,101.12],[1,2.02,1.25],[2,1.01,16.02]],"ltp":0.0,"tv":0.0,"id":8860646}]}]}
{"op":"mcm","clk":"1010292193","pt":1580674118436,"mc":[{"id":"1.168238842","rc":[{"batb":[[0,2.02,1.25],[1,1.01,16.02],[2,1.01,0]],"ltp":0.0,"tv":0.0,"id":8860646}]}]}
{"op":"mcm","clk":"1010292313","pt":1580674119921,"mc":[{"id":"1.168238842","rc":[{"batb":[[0,2.04,99.37],[1,2.02,1.25],[2,1.01,16.02]],"ltp":0.0,"tv":0.0,"id":8860646}]}]}
{"op":"mcm","clk":"1010300630","pt":1580674210083,"mc":[{"id":"1.168238842","rc":[{"trd":[[2.38,3.79]],"ltp":2.38,"tv":3.78,"id":8860646},{"trd":[[1.72,5.24],[1.86,2.71]],"batb":[[0,1.01,16.02],[1,1.01,0]],"batl":[[0,2.16,6.28]],"ltp":1.72,"tv":7.94,"id":8258569}],"tv":11.73}]}
{"op":"mcm","clk":"1010300677","pt":1580674210494,"mc":[{"id":"1.168238842","rc":[{"batb":[[0,1.56,141.58],[1,1.01,16.02]],"ltp":1.72,"tv":7.94,"id":8258569}]}]}
{"op":"mcm","clk":"1010307014","pt":1580674273174,"mc":[{"id":"1.168238842","rc":[{"batb":[[1,1.01,17.7],[2,1.01,0]],"ltp":2.38,"tv":3.78,"id":8860646}]}]}
{"op":"mcm","clk":"1010307155","pt":1580674274196,"mc":[{"id":"1.168238842","rc":[{"batb":[[1,1.01,16.02]],"ltp":2.38,"tv":3.78,"id":8860646}]}]}
{"op":"mcm","clk":"1010307276","pt":1580674274554,"mc":[{"id":"1.168238842","rc":[{"batb":[[0,2.06,1.23]],"ltp":2.38,"tv":3.78,"id":8860646}]}]}
{"op":"mcm","clk":"1010307845","pt":1580674280062,"mc":[{"id":"1.168238842","rc":[{"batb":[[0,1.01,16.02],[1,1.01,0]],"ltp":1.72,"tv":7.94,"id":8258569}]}]}
{"op":"mcm","clk":"1010307880","pt":1580674280375,"mc":[{"id":"1.168238842","rc":[{"batb":[[0,1.6,137.89],[1,1.01,16.02]],"ltp":1.72,"tv":7.94,"id":8258569}]}]}
{"op":"mcm","clk":"1010308788","pt":1580674289315,"mc":[{"id":"1.168238842","rc":[{"batb":[[0,1.01,16.02],[1,1.01,0]],"ltp":1.72,"tv":7.94,"id":8258569}]}]}
{"op":"mcm","clk":"1010308898","pt":1580674290369,"mc":[{"id":"1.168238842","rc":[{"batb":[[0,1.46,151.39],[1,1.01,16.01]],"ltp":1.72,"tv":7.94,"id":8258569}]}]}
{"op":"mcm","clk":"1010323454","pt":1580674430728,"mc":[{"id":"1.168238842","rc":[{"batb":[[0,2.08,100.31],[1,2.06,1.23],[2,1.01,16.02]],"ltp":2.38,"tv":3.78,"id":8860646}]}]}
{"op":"mcm","clk":"1010325705","pt":1580674451082,"mc":[{"id":"1.168238842","rc":[{"batb":[[1,1.01,17.22],[2,1.01,0]],"ltp":2.38,"tv":3.78,"id":8860646}]}]}
{"op":"mcm","clk":"1010325791","pt":1580674451874,"mc":[{"id":"1.168238842","rc":[{"batb":[[0,2.1,100.34],[1,1.01,16.02]],"ltp":2.38,"tv":3.78,"id":8860646}]}]}
{"op":"mcm","clk":"1010329425","pt":1580674484614,"mc":[{"id":"1.168238842","rc":[{"batb":[[0,2.1,1.2]],"ltp":2.38,"tv":3.78,"id":8860646}]}]}
{"op":"mcm","clk":"1010342736","pt":1580674608256,"mc":[{"id":"1.168238842","marketDefinition":{"bspMarket":false,"turnInPlayEnabled":true,"persistenceEnabled":true,"marketBaseRate":5.0,"eventId":"29681898","eventTypeId":"2","numberOfWinners":1,"bettingType":"ODDS","marketType":"SET_WINNER","marketTime":"2020-02-02T20:30:00.000Z","suspendTime":"2020-02-02T20:30:00.000Z","bspReconciled":false,"complete":true,"inPlay":false,"crossMatching":true,"runnersVoidable":false,"numberOfActiveRunners":2,"betDelay":0,"status":"OPEN","runners":[{"status":"ACTIVE","sortPriority":1,"id":8860646,"name":"Daniel Elahi Galan"},{"status":"ACTIVE","sortPriority":2,"id":8258569,"name":"Thai-Son Kwiatkowski"}],"regulators":["MR_INT"],"countryCode":"US","discountAllowed":true,"timezone":"UTC","openDate":"2020-02-02T20:15:00.000Z","version":3150491535,"name":"Set 1 Winner","eventName":"Galan v Kwiatkowski"}}]}
{"op":"mcm","clk":"1010343011","pt":1580674611262,"mc":[{"id":"1.168238842","marketDefinition":{"bspMarket":false,"turnInPlayEnabled":true,"persistenceEnabled":true,"marketBaseRate":5.0,"eventId":"29681898","eventTypeId":"2","numberOfWinners":1,"bettingType":"ODDS","marketType":"SET_WINNER","marketTime":"2020-02-02T20:30:00.000Z","suspendTime":"2020-02-02T20:30:00.000Z","bspReconciled":false,"complete":true,"inPlay":false,"crossMatching":true,"runnersVoidable":false,"numberOfActiveRunners":2,"betDelay":0,"status":"OPEN","runners":[{"status":"ACTIVE","sortPriority":1,"id":8860646,"name":"Daniel Elahi Galan"},{"status":"ACTIVE","sortPriority":2,"id":8258569,"name":"Thai-Son Kwiatkowski"}],"regulators":["MR_INT"],"countryCode":"US","discountAllowed":true,"timezone":"UTC","openDate":"2020-02-02T20:30:00.000Z","version":3150491535,"name":"Set 1 Winner","eventName":"Galan v Kwiatkowski"}}]}
{"op":"mcm","clk":"1010362586","pt":1580674796127,"mc":[{"id":"1.168238842","rc":[{"batb":[[0,2.1,50.77]],"ltp":2.38,"tv":3.78,"id":8860646},{"trd":[[1.72,7.19]],"batb":[[0,1.8,39.86],[1,1.46,151.39],[2,1.01,16.01]],"batl":[[0,2.16,5.3]],"ltp":1.72,"tv":9.9,"id":8258569}],"tv":13.68}]}
{"op":"mcm","clk":"1010362663","pt":1580674796831,"mc":[{"id":"1.168238842","rc":[{"batb":[[0,1.82,113.14],[1,1.8,39.86],[2,1.01,16.02]],"ltp":1.72,"tv":9.9,"id":8258569}]}]}
{"op":"mcm","clk":"1010363393","pt":1580674804051,"mc":[{"id":"1.168238842","rc":[{"batb":[[1,1.79,40.91]],"ltp":1.72,"tv":9.9,"id":8258569}]}]}
{"op":"mcm","clk":"1010365036","pt":1580674821267,"mc":[{"id":"1.168238842","rc":[{"batb":[[0,1.8,114.23]],"ltp":1.72,"tv":9.9,"id":8258569}]}]}
{"op":"mcm","clk":"1010365158","pt":1580674822607,"mc":[{"id":"1.168238842","rc":[{"batb":[[0,2.12,49.1],[1,2.1,1.2],[2,1.01,16.02]],"ltp":2.38,"tv":3.78,"id":8860646},{"batb":[[0,1.79,40.91],[1,1.01,16.02],[2,1.01,0]],"ltp":1.72,"tv":9.9,"id":8258569}]}]}
{"op":"mcm","clk":"1010370162","pt":1580674872251,"mc":[{"id":"1.168238842","rc":[{"batb":[[0,2.14,1.18],[1,2.12,49.1]],"ltp":2.38,"tv":3.78,"id":8860646},{"batb":[[0,1.8,1.4],[1,1.79,40.91],[2,1.01,16.02]],"ltp":1.72,"tv":9.9,"id":8258569}]}]}
{"op":"mcm","clk":"1010371598","pt":1580674886215,"mc":[{"id":"1.168238842","rc":[{"batb":[[2,2.1,49.81]],"ltp":2.38,"tv":3.78,"id":8860646},{"batb":[[0,1.8,42.08]],"ltp":1.72,"tv":9.9,"id":8258569}]}]}
{"op":"mcm","clk":"1010371643","pt":1580674886574,"mc":[{"id":"1.168238842","rc":[{"batb":[[1,2.1,49.81],[2,1.01,16.02]],"ltp":2.38,"tv":3.78,"id":8860646},{"batb":[[1,1.01,16.02],[2,1.01,0]],"ltp":1.72,"tv":9.9,"id":8258569}]}]}
{"op":"mcm","clk":"1010373865","pt":1580674908202,"mc":[{"id":"1.168238842","marketDefinition":{"bspMarket":false,"turnInPlayEnabled":true,"persistenceEnabled":true,"marketBaseRate":5.0,"eventId":"29681898","eventTypeId":"2","numberOfWinners":1,"bettingType":"ODDS","marketType":"SET_WINNER","marketTime":"2020-02-02T20:18:00.000Z","suspendTime":"2020-02-02T20:18:00.000Z","bspReconciled":false,"complete":true,"inPlay":false,"crossMatching":true,"runnersVoidable":false,"numberOfActiveRunners":2,"betDelay":0,"status":"OPEN","runners":[{"status":"ACTIVE","sortPriority":1,"id":8860646,"name":"Daniel Elahi Galan"},{"status":"ACTIVE","sortPriority":2,"id":8258569,"name":"Thai-Son Kwiatkowski"}],"regulators":["MR_INT"],"countryCode":"US","discountAllowed":true,"timezone":"UTC","openDate":"2020-02-02T20:30:00.000Z","version":3150502607,"name":"Set 1 Winner","eventName":"Galan v Kwiatkowski"}}]}
{"op":"mcm","clk":"1010374305","pt":1580674912182,"mc":[{"id":"1.168238842","marketDefinition":{"bspMarket":false,"turnInPlayEnabled":true,"persistenceEnabled":true,"marketBaseRate":5.0,"eventId":"29681898","eventTypeId":"2","numberOfWinners":1,"bettingType":"ODDS","marketType":"SET_WINNER","marketTime":"2020-02-02T20:18:00.000Z","suspendTime":"2020-02-02T20:18:00.000Z","bspReconciled":false,"complete":true,"inPlay":false,"crossMatching":true,"runnersVoidable":false,"numberOfActiveRunners":2,"betDelay":0,"status":"OPEN","runners":[{"status":"ACTIVE","sortPriority":1,"id":8860646,"name":"Daniel Elahi Galan"},{"status":"ACTIVE","sortPriority":2,"id":8258569,"name":"Thai-Son Kwiatkowski"}],"regulators":["MR_INT"],"countryCode":"US","discountAllowed":true,"timezone":"UTC","openDate":"2020-02-02T20:18:00.000Z","version":3150502607,"name":"Set 1 Winner","eventName":"Galan v Kwiatkowski"}}]}
{"op":"mcm","clk":"1010380978","pt":1580674976034,"mc":[{"id":"1.168238842","rc":[{"batb":[[1,1.01,16.02],[2,1.01,0]],"ltp":2.38,"tv":3.78,"id":8860646},{"batb":[[0,1.8,1.4]],"ltp":1.72,"tv":9.9,"id":8258569}]}]}
{"op":"mcm","clk":"1010381004","pt":1580674976326,"mc":[{"id":"1.168238842","marketDefinition":{"bspMarket":false,"turnInPlayEnabled":true,"persistenceEnabled":true,"marketBaseRate":5.0,"eventId":"29681898","eventTypeId":"2","numberOfWinners":1,"bettingType":"ODDS","marketType":"SET_WINNER","marketTime":"2020-02-02T20:18:00.000Z","suspendTime":"2020-02-02T20:18:00.000Z","bspReconciled":false,"complete":true,"inPlay":true,"crossMatching":true,"runnersVoidable":false,"numberOfActiveRunners":2,"betDelay":3,"status":"OPEN","runners":[{"status":"ACTIVE","sortPriority":1,"id":8860646,"name":"Daniel Elahi Galan"},{"status":"ACTIVE","sortPriority":2,"id":8258569,"name":"Thai-Son Kwiatkowski"}],"regulators":["MR_INT"],"countryCode":"US","discountAllowed":true,"timezone":"UTC","openDate":"2020-02-02T20:18:00.000Z","version":3150503832,"name":"Set 1 Winner","eventName":"Galan v Kwiatkowski"},"rc":[{"batb":[[0,1.01,15.52],[1,1.01,0]],"ltp":2.38,"tv":3.78,"id":8860646},{"batb":[[0,1.01,15.52],[1,1.01,0]],"ltp":1.72,"tv":9.9,"id":8258569}]}]}
{"op":"mcm","clk":"1010381720","pt":1580674982028,"mc":[{"id":"1.168238842","rc":[{"batb":[[0,1.97,61.37],[1,1.86,36.27],[2,1.01,15.52]],"ltp":2.38,"tv":3.78,"id":8860646},{"batb":[[0,1.91,33.28],[1,1.76,43.35],[2,1.01,15.52]],"ltp":1.72,"tv":9.9,"id":8258569}]}]}
{"op":"mcm","clk":"1010382385","pt":1580674987735,"mc":[{"id":"1.168238842","rc":[{"batb":[[0,1.86,36.27],[1,1.01,15.52],[2,1.01,0]],"ltp":2.38,"tv":3.78,"id":8860646},{"batb":[[0,1.76,43.35],[1,1.01,15.52],[2,1.01,0]],"ltp":1.72,"tv":9.9,"id":8258569}]}]}
{"op":"mcm","clk":"1010384358","pt":1580675004262,"mc":[{"id":"1.168238842","rc":[{"batb":[[0,2.16,46.58],[1,1.98,59.96],[2,1.93,13.36]],"ltp":2.38,"tv":3.78,"id":8860646},{"batb":[[1,1.58,63.02],[2,1.01,15.52]],"ltp":1.72,"tv":9.9,"id":8258569}]}]}
{"op":"mcm","clk":"1010385533","pt":1580675015103,"mc":[{"id":"1.168238842","rc":[{"batb":[[0,1.98,59.96],[1,1.01,15.52],[2,1.93,0]],"ltp":2.38,"tv":3.78,"id":8860646},{"batb":[[0,1.58,63.02],[1,1.01,15.52],[2,1.01,0]],"ltp":1.72,"tv":9.9,"id":8258569}]}]}
{"op":"mcm","clk":"1010385876","pt":1580675018190,"mc":[{"id":"1.168238842","rc":[{"batl":[[0,2.02,347.89],[1,2.04,366.19]],"ltp":1.72,"tv":9.9,"id":8258569}]}]}
{"op":"mcm","clk":"1010386210","pt":1580675021280,"mc":[{"id":"1.168238842","rc":[{"batb":[[1,1.87,36.12],[2,1.01,15.52]],"ltp":2.38,"tv":3.78,"id":8860646},{"batb":[[0,1.93,480.81],[1,1.91,438.58],[2,1.9,33.99]],"ltp":1.72,"tv":9.9,"id":8258569}]}]}
{"op":"mcm","clk":"1010387213","pt":1580675029905,"mc":[{"id":"1.168238842","rc":[{"batb":[[0,1.87,36.12],[1,1.01,15.52],[2,1.01,0]],"ltp":2.38,"tv":3.78,"id":8860646},{"batb":[[0,1.73,46.34],[1,1.01,15.52],[2,1.9,0]],"ltp":1.72,"tv":9.9,"id":8258569}]}]}
{"op":"mcm","clk":"1010387560","pt":1580675032818,"mc":[{"id":"1.168238842","rc":[{"batb":[[0,1.77,377.69],[1,1.75,582.48],[2,1.73,46.34]],"batl":[[0,2.14,278.69],[1,2.16,310.6]],"ltp":1.72,"tv":9.9,"id":8258569}]}]}
{"op":"mcm","clk":"1010388188","pt":1580675039082,"mc":[{"id":"1.168238842","rc":[{"batb":[[0,1.73,46.34],[1,1.01,15.52],[2,1.73,0]],"ltp":1.72,"tv":9.9,"id":8258569}]}]}
{"op":"mcm","clk":"1010388526","pt":1580675042203,"mc":[{"id":"1.168238842","rc":[{"batb":[[0,2.2,43.51],[1,1.97,60.66],[2,1.01,15.52]],"ltp":2.38,"tv":3.78,"id":8860646},{"batb":[[0,1.73,46.11],[1,1.52,74.43],[2,1.01,15.52]],"batl":[[0,1.85,430.13],[1,1.87,475.9]],"ltp":1.72,"tv":9.9,"id":8258569}]}]}
{"op":"mcm","clk":"1010388825","pt":1580675045005,"mc":[{"id":"1.168238842","rc":[{"batb":[[0,1.77,604.71],[1,1.75,583.16],[2,1.73,46.11]],"ltp":1.72,"tv":9.9,"id":8258569}]}]}
{"op":"mcm","clk":"1010389849","pt":1580675053821,"mc":[{"id":"1.168238842","rc":[{"batb":[[0,1.73,46.11],[1,1.52,74.43],[2,1.01,15.52]],"ltp":1.72,"tv":9.9,"id":8258569}]}]}
{"op":"mcm","clk":"1010389984","pt":1580675055023,"mc":[{"id":"1.168238842","rc":[{"batb":[[0,1.97,60.66],[1,1.01,15.52],[2,1.01,0]],"ltp":2.38,"tv":3.78,"id":8860646},{"batb":[[0,1.52,73.57],[1,1.01,15.52],[2,1.01,0]],"ltp":1.72,"tv":9.9,"id":8258569}]}]}
{"op":"mcm","clk":"1010390346","pt":1580675058350,"mc":[{"id":"1.168238842","rc":[{"batb":[[0,1.72,570.82],[1,1.7,643.75],[2,1.52,73.57]],"batl":[[0,1.79,371.75],[1,1.81,527.58]],"ltp":1.72,"tv":9.9,"id":8258569}]}]}
{"op":"mcm","clk":"1010390890","pt":1580675063217,"mc":[{"id":"1.168238842","rc":[{"batb":[[0,1.52,73.57],[1,1.01,15.52],[2,1.52,0]],"ltp":1.72,"tv":9.9,"id":8258569}]}]}
{"op":"mcm","clk":"1010391146","pt":1580675065654,"mc":[{"id":"1.168238842","rc":[{"batb":[[0,1.54,666.22],[1,1.53,477.83],[2,1.52,73.57]],"batl":[[0,2.04,314.77],[1,2.06,356.05]],"ltp":1.72,"tv":9.9,"id":8258569}]}]}
{"op":"mcm","clk":"1010391656","pt":1580675070275,"mc":[{"id":"1.168238842","rc":[{"batl":[[0,1.72,56.29],[1,2.04,314.77],[2,2.06,356.05]],"ltp":1.72,"tv":9.9,"id":8258569}]}]}
{"op":"mcm","clk":"1010392383","pt":1580675076455,"mc":[{"id":"1.168238842","rc":[{"batl":[[1,2.04,0],[2,2.06,0]],"ltp":1.72,"tv":9.9,"id":8258569}]}]}
{"op":"mcm","clk":"1010392843","pt":1580675080262,"mc":[{"id":"1.168238842","rc":[{"batb":[[0,2.68,25.49],[1,2.22,42.65],[2,1.01,15.52]],"ltp":2.38,"tv":3.78,"id":8860646},{"batl":[[0,1.6,686.85],[1,1.61,388.16],[2,1.72,56.29]],"ltp":1.72,"tv":9.9,"id":8258569}]}]}
{"op":"mcm","clk":"1010394331","pt":1580675093202,"mc":[{"id":"1.168238842","rc":[{"batl":[[2,1.71,98.18]],"ltp":1.72,"tv":9.9,"id":8258569}]}]}
{"op":"mcm","clk":"1010394792","pt":1580675096992,"mc":[{"id":"1.168238842","rc":[{"batb":[[0,1.54,498.72]],"batl":[[0,1.6,398.84],[1,1.71,98.18],[2,1.71,0]],"ltp":1.72,"tv":9.9,"id":8258569}]}]}
{"op":"mcm","clk":"1010394910","pt":1580675098096,"mc":[{"id":"1.168238842","rc":[{"trd":[[1.54,112.58]],"batb":[[0,1.54,442.43]],"ltp":1.54,"tv":122.48,"id":8258569}],"tv":126.27}]}
{"op":"mcm","clk":"1010395180","pt":1580675100175,"mc":[{"id":"1.168238842","rc":[{"batl":[[0,1.59,452.2],[1,1.6,398.84]],"ltp":1.54,"tv":122.48,"id":8258569}]}]}
{"op":"mcm","clk":"1010395318","pt":1580675101281,"mc":[{"id":"1.168238842","rc":[{"batb":[[0,2.22,42.65],[1,1.01,15.52],[2,1.01,0]],"ltp":2.38,"tv":3.78,"id":8860646},{"batb":[[0,1.3,150.29],[1,1.01,15.51],[2,1.52,0]],"ltp":1.54,"tv":122.48,"id":8258569}]}]}
{"op":"mcm","clk":"1010395648","pt":1580675104203,"mc":[{"id":"1.168238842","rc":[{"batb":[[1,1.28,817.06],[2,1.27,1146.01]],"batl":[[0,1.83,411.08],[1,1.85,493.01]],"ltp":1.54,"tv":122.48,"id":8258569}]}]}
{"op":"mcm","clk":"1010396299","pt":1580675109586,"mc":[{"id":"1.168238842","rc":[{"batb":[[1,1.01,15.51],[2,1.27,0]],"ltp":1.54,"tv":122.48,"id":8258569}]}]}
{"op":"mcm","clk":"1010396605","pt":1580675112283,"mc":[{"id":"1.168238842","rc":[{"batb":[[0,1.76,408.34],[1,1.74,594.81],[2,1.3,150.29]],"ltp":1.54,"tv":122.48,"id":8258569}]}]}
{"op":"mcm","clk":"1010396674","pt":1580675112912,"mc":[{"id":"1.168238842","rc":[{"batb":[[1,1.98,59.8],[2,1.01,15.52]],"ltp":2.38,"tv":3.78,"id":8860646},{"batb":[[2,1.72,46.97]],"ltp":1.54,"tv":122.48,"id":8258569}]}]}
{"op":"mcm","clk":"1010398126","pt":1580675126937,"mc":[{"id":"1.168238842","rc":[{"batb":[[0,1.98,59.8],[1,1.01,15.52],[2,1.01,0]],"ltp":2.38,"tv":3.78,"id":8860646},{"batb":[[0,1.51,75.22],[1,1.01,15.52],[2,1.72,0]],"ltp":1.54,"tv":122.48,"id":8258569}]}]}
{"op":"mcm","clk":"1010398924","pt":1580675133930,"mc":[{"id":"1.168238842","rc":[{"batb":[[0,1.71,391.41],[1,1.69,657.36],[2,1.51,75.22]],"batl":[[0,1.78,577.17],[1,1.8,537.22]],"ltp":1.54,"tv":122.48,"id":8258569}]}]}
{"op":"mcm","clk":"1010399072","pt":1580675135266,"mc":[{"id":"1.168238842","rc":[{"batb":[[0,1.51,75.22],[1,1.01,15.52],[2,1.51,0]],"batl":[[0,1.76,28.57],[1,1.8,0]],"ltp":1.54,"tv":122.48,"id":8258569}]}]}
{"op":"mcm","clk":"1010399388","pt":1580675138261,"mc":[{"id":"1.168238842","rc":[{"batb":[[0,1.53,587.78],[1,1.52,490.98],[2,1.51,75.22]],"batl":[[1,2.02,348.15],[2,2.04,366.76]],"ltp":1.54,"tv":122.48,"id":8258569}]}]}
{"op":"mcm","clk":"1010400340","pt":1580675147153,"mc":[{"id":"1.168238842","rc":[{"batb":[[0,1.51,75.22],[1,1.01,15.52],[2,1.51,0]],"ltp":1.54,"tv":122.48,"id":8258569}]}]}
{"op":"mcm","clk":"1010400659","pt":1580675150181,"mc":[{"id":"1.168238842","rc":[{"trd":[[1.76,57.14]],"batb":[[0,1.93,454.86],[1,1.91,439.27],[2,1.51,75.22]],"batl":[[0,2.02,348.15],[1,2.04,366.76],[2,2.04,0]],"ltp":1.76,"tv":179.62,"id":8258569}],"tv":183.4}]}
{"op":"mcm","clk":"1010400795","pt":1580675151254,"mc":[{"id":"1.168238842","rc":[{"batb":[[1,1.85,37.3],[2,1.01,15.52]],"ltp":2.38,"tv":3.78,"id":8860646},{"batb":[[2,1.9,34.15]],"ltp":1.76,"tv":179.62,"id":8258569}]}]}
{"op":"mcm","clk":"1010401675","pt":1580675159124,"mc":[{"id":"1.168238842","rc":[{"batb":[[0,1.85,37.3],[1,1.01,15.52],[2,1.01,0]],"ltp":2.38,"tv":3.78,"id":8860646},{"batb":[[0,1.71,48.23],[1,1.01,15.52],[2,1.9,0]],"ltp":1.76,"tv":179.62,"id":8258569}]}]}
{"op":"mcm","clk":"1010401990","pt":1580675162215,"mc":[{"id":"1.168238842","rc":[{"batb":[[0,1.75,353.32],[1,1.73,606.41],[2,1.71,48.23]],"batl":[[0,2.16,269.72],[1,2.18,303.11]],"ltp":1.76,"tv":179.62,"id":8258569}]}]}
{"op":"mcm","clk":"1010402092","pt":1580675163179,"mc":[{"id":"1.168238842","rc":[{"batb":[[0,1.71,48.23],[1,1.01,15.52],[2,1.71,0]],"ltp":1.76,"tv":179.62,"id":8258569}]}]}
{"op":"mcm","clk":"1010402390","pt":1580675166120,"mc":[{"id":"1.168238842","rc":[{"batb":[[0,1.89,477.1],[1,1.87,469.69],[2,1.71,48.23]],"batl":[[0,1.98,448.02],[1,2,388.76]],"ltp":1.76,"tv":179.62,"id":8258569}]}]}
{"op":"mcm","clk":"1010402690","pt":1580675168838,"mc":[{"id":"1.168238842","rc":[{"batb":[[0,1.71,48.23],[1,1.01,15.52],[2,1.71,0]],"ltp":1.76,"tv":179.62,"id":8258569}]}]}
{"op":"mcm","clk":"1010402968","pt":1580675171616,"mc":[{"id":"1.168238842","rc":[{"batb":[[0,1.75,353.32],[1,1.73,606.41],[2,1.71,48.23]],"batl":[[0,2.16,269.72],[1,2.18,303.11]],"ltp":1.76,"tv":179.62,"id":8258569}]}]}
{"op":"mcm","clk":"1010403335","pt":1580675175222,"mc":[{"id":"1.168238842","rc":[{"batb":[[0,1.71,48.23],[1,1.01,15.52],[2,1.71,0]],"ltp":1.76,"tv":179.62,"id":8258569}]}]}
{"op":"mcm","clk":"1010403631","pt":1580675178236,"mc":[{"id":"1.168238842","rc":[{"batb":[[0,1.86,363.13],[1,1.85,37.3],[2,1.84,494.59]],"batl":[[0,1.94,427.15],[1,1.96,412.98]],"ltp":2.38,"tv":3.78,"id":8860646}]}]}
{"op":"mcm","clk":"1010403723","pt":1580675179245,"mc":[{"id":"1.168238842","rc":[{"batb":[[0,2.04,54.68],[1,1.92,33.2],[2,1.01,15.52]],"ltp":1.76,"tv":179.62,"id":8258569}]}]}
{"op":"mcm","clk":"1010404015","pt":1580675181966,"mc":[{"id":"1.168238842","rc":[{"batb":[[0,1.85,37.3],[1,1.67,51.85],[2,1.01,15.52]],"ltp":2.38,"tv":3.78,"id":8860646}]}]}
{"op":"mcm","clk":"1010404353","pt":1580675185129,"mc":[{"id":"1.168238842","rc":[{"batb":[[0,1.85,486.71],[1,1.83,503.76],[2,1.67,51.85]],"batl":[[0,1.93,369.86],[1,1.95,419.69]],"ltp":2.38,"tv":3.78,"id":8860646}]}]}
{"op":"mcm","clk":"1010405631","pt":1580675197253,"mc":[{"id":"1.168238842","rc":[{"trd":[[1.93,30.49]],"batl":[[0,1.93,339.37]],"ltp":1.93,"tv":34.27,"id":8860646},{"trd":[[2.06,28.57]],"ltp":2.06,"tv":208.18,"id":8258569}],"tv":242.46}]}
{"op":"mcm","clk":"1010407445","pt":1580675215166,"mc":[{"id":"1.168238842","rc":[{"batb":[[0,1.85,37.3],[1,1.67,51.85],[2,1.01,15.52]],"ltp":1.93,"tv":34.27,"id":8860646}]}]}
{"op":"mcm","clk":"1010407770","pt":1580675218258,"mc":[{"id":"1.168238842","rc":[{"batb":[[1,1.69,344],[2,1.67,737.88]],"batl":[[0,2.06,527.6],[1,2.08,346.79]],"ltp":1.93,"tv":34.27,"id":8860646}]}]}
{"op":"mcm","clk":"1010408423","pt":1580675225269,"mc":[{"id":"1.168238842","rc":[{"batb":[[0,1.69,344],[1,1.67,737.88],[2,1.01,15.52]],"ltp":1.93,"tv":34.27,"id":8860646},{"batb":[[0,1.92,33.2],[1,1.01,15.52],[2,1.01,0]],"ltp":2.06,"tv":208.18,"id":8258569}]}]}
{"op":"mcm","clk":"1010409113","pt":1580675232225,"mc":[{"id":"1.168238842","rc":[{"batb":[[0,1.67,51.85],[1,1.01,15.52],[2,1.01,0]],"ltp":1.93,"tv":34.27,"id":8860646}]}]}
{"op":"mcm","clk":"1010409360","pt":1580675235170,"mc":[{"id":"1.168238842","rc":[{"batb":[[0,1.95,419.37],[1,1.93,425.34],[2,1.92,33.2]],"batl":[[0,2.04,366.6],[1,2.06,356.57]],"ltp":2.06,"tv":208.18,"id":8258569}]}]}
{"op":"mcm","clk":"1010409445","pt":1580675236159,"mc":[{"id":"1.168238842","rc":[{"batb":[[0,1.97,61.45],[1,1.8,40.21],[2,1.01,15.52]],"ltp":1.93,"tv":34.27,"id":8860646}]}]}
{"op":"mcm","clk":"1010410386","pt":1580675246052,"mc":[{"id":"1.168238842","rc":[{"batb":[[0,1.8,40.21],[1,1.01,15.52],[2,1.01,0]],"ltp":1.93,"tv":34.27,"id":8860646},{"batb":[[0,1.82,39.03],[1,1.01,15.52],[2,1.92,0]],"ltp":2.06,"tv":208.18,"id":8258569}]}]}
{"op":"mcm","clk":"1010410683","pt":1580675249161,"mc":[{"id":"1.168238842","rc":[{"batb":[[0,1.87,322.22],[1,1.85,486.01],[2,1.82,39.03]],"ltp":2.06,"tv":208.18,"id":8258569}]}]}
{"op":"mcm","clk":"1010410955","pt":1580675252195,"mc":[{"id":"1.168238842","rc":[{"batb":[[0,1.84,131.72],[1,1.8,40.21],[2,1.01,15.52]],"ltp":1.93,"tv":34.27,"id":8860646},{"batl":[[0,1.95,442.87],[1,1.97,406.68]],"ltp":2.06,"tv":208.18,"id":8258569}]}]}
{"op":"mcm","clk":"1010411034","pt":1580675253190,"mc":[{"id":"1.168238842","rc":[{"batb":[[0,2.08,52.09],[1,1.94,32.02]],"ltp":1.93,"tv":34.27,"id":8860646}]}]}
{"op":"mcm","clk":"1010411799","pt":1580675262271,"mc":[{"id":"1.168238842","rc":[{"batb":[[0,1.94,32.02],[1,1.01,15.52],[2,1.01,0]],"ltp":1.93,"tv":34.27,"id":8860646},{"batb":[[0,1.76,43.59],[1,1.01,15.52],[2,1.82,0]],"ltp":2.06,"tv":208.18,"id":8258569}]}]}
{"op":"mcm","clk":"1010411964","pt":1580675264275,"mc":[{"id":"1.168238842","rc":[{"batb":[[0,1.81,544.05],[1,1.79,541.45],[2,1.76,43.59]],"batl":[[0,2.06,379.74],[1,2.08,346.72]],"ltp":2.06,"tv":208.18,"id":8258569}]}]}
{"op":"mcm","clk":"1010412052","pt":1580675265169,"mc":[{"id":"1.168238842","rc":[{"batb":[[0,1.76,43.59],[1,1.01,15.52],[2,1.76,0]],"ltp":2.06,"tv":208.18,"id":8258569}]}]}
{"op":"mcm","clk":"1010412205","pt":1580675267207,"mc":[{"id":"1.168238842","rc":[{"batb":[[0,1.89,311.87],[1,1.87,469.61],[2,1.76,43.59]],"batl":[[0,1.97,408.15],[1,1.99,394.65]],"ltp":2.06,"tv":208.18,"id":8258569}]}]}
{"op":"mcm","clk":"1010412379","pt":1580675269211,"mc":[{"id":"1.168238842","rc":[{"batb":[[0,1.76,43.59],[1,1.01,15.52],[2,1.76,0]],"ltp":2.06,"tv":208.18,"id":8258569}]}]}
{"op":"mcm","clk":"1010412608","pt":1580675271892,"mc":[{"id":"1.168238842","rc":[{"batb":[[0,1.81,544.46],[1,1.79,541.45],[2,1.76,43.59]],"batl":[[0,2.06,379.38],[1,2.08,346.72]],"ltp":2.06,"tv":208.18,"id":8258569}]}]}
{"op":"mcm","clk":"1010413316","pt":1580675280081,"mc":[{"id":"1.168238842","rc":[{"batb":[[0,2.16,46.26],[1,2.06,52.8],[2,1.94,32.02]],"ltp":1.93,"tv":34.27,"id":8860646},{"batl":[[0,1.89,381.75],[1,1.91,446.63],[2,2.06,799.59]],"ltp":2.06,"tv":208.18,"id":8258569}]}]}
{"op":"mcm","clk":"1010413403","pt":1580675281009,"mc":[{"id":"1.168238842","rc":[{"batb":[[2,1.01,15.52]],"ltp":1.93,"tv":34.27,"id":8860646},{"batl":[[2,2.06,0]],"ltp":2.06,"tv":208.18,"id":8258569}]}]}
{"op":"mcm","clk":"1010414898","pt":1580675296944,"mc":[{"id":"1.168238842","rc":[{"batb":[[0,2.06,52.8],[1,1.01,15.52],[2,1.01,0]],"ltp":1.93,"tv":34.27,"id":8860646},{"batb":[[0,1.79,384.06],[1,1.71,47.68],[2,1.01,15.52]],"ltp":2.06,"tv":208.18,"id":8258569}]}]}
{"op":"mcm","clk":"1010415178","pt":1580675299922,"mc":[{"id":"1.168238842","rc":[{"batb":[[0,1.71,47.68],[1,1.01,15.52],[2,1.01,0]],"ltp":2.06,"tv":208.18,"id":8258569}]}]}
{"op":"mcm","clk":"1010415423","pt":1580675302656,"mc":[{"id":"1.168238842","rc":[{"batb":[[0,1.82,541.2],[1,1.8,531.59],[2,1.71,47.68]],"batl":[[0,1.9,357.81],[1,1.92,439.6]],"ltp":2.06,"tv":208.18,"id":8258569}]}]}
{"op":"mcm","clk":"1010415585","pt":1580675304442,"mc":[{"id":"1.168238842","rc":[{"batb":[[0,1.71,47.68],[1,1.01,15.52],[2,1.71,0]],"ltp":2.06,"tv":208.18,"id":8258569}]}]}
{"op":"mcm","clk":"1010415955","pt":1580675308237,"mc":[{"id":"1.168238842","rc":[{"batb":[[0,1.79,384.06],[1,1.77,561.63],[2,1.71,47.68]],"batl":[[0,1.95,447.84],[1,1.97,406.66]],"ltp":2.06,"tv":208.18,"id":8258569}]}]}
{"op":"mcm","clk":"1010416633","pt":1580675315234,"mc":[{"id":"1.168238842","rc":[{"batl":[[0,1.86,355.12],[1,1.88,469.01]],"ltp":2.06,"tv":208.18,"id":8258569}]}]}
{"op":"mcm","clk":"1010416729","pt":1580675316244,"mc":[{"id":"1.168238842","rc":[{"batb":[[0,2.24,42.02],[1,2.06,52.8],[2,1.01,15.52]],"ltp":1.93,"tv":34.27,"id":8860646},{"batb":[[0,1.71,47.68],[1,1.56,66.01],[2,1.01,15.52]],"ltp":2.06,"tv":208.18,"id":8258569}]}]}
{"op":"mcm","clk":"1010416799","pt":1580675316979,"mc":[{"id":"1.168238842","rc":[{"batb":[[2,1.77,402.27]],"ltp":1.93,"tv":34.27,"id":8860646},{"batb":[[2,1.5,426.9]],"ltp":2.06,"tv":208.18,"id":8258569}]}]}
{"op":"mcm","clk":"1010416938","pt":1580675318252,"mc":[{"id":"1.168238842","rc":[{"batl":[[0,1.82,78.5],[1,1.86,355.12],[2,1.88,469.01]],"ltp":2.06,"tv":208.18,"id":8258569}]}]}
{"op":"mcm","clk":"1010417011","pt":1580675318985,"mc":[{"id":"1.168238842","rc":[{"batb":[[0,1.78,592.26],[1,1.76,573.13],[2,1.71,47.68]],"batl":[[1,1.86,423.31]],"ltp":2.06,"tv":208.18,"id":8258569}]}]}
{"op":"mcm","clk":"1010418940","pt":1580675338106,"mc":[{"id":"1.168238842","rc":[{"batb":[[0,2.06,52.8],[1,1.77,402.27],[2,1.01,15.52]],"ltp":1.93,"tv":34.27,"id":8860646},{"batb":[[0,1.56,66.01],[1,1.5,426.9],[2,1.01,15.52]],"batl":[[1,1.86,0],[2,1.88,0]],"ltp":2.06,"tv":208.18,"id":8258569}]}]}
{"op":"mcm","clk":"1010419228","pt":1580675341169,"mc":[{"id":"1.168238842","rc":[{"batb":[[1,2.04,54.76],[2,1.77,402.27]],"ltp":1.93,"tv":34.27,"id":8860646},{"batb":[[0,1.63,371.41],[1,1.62,384.6],[2,1.57,64.44]],"batl":[[1,1.98,413.49],[2,2,388.97]],"ltp":2.06,"tv":208.18,"id":8258569}]}]}
{"op":"mcm","clk":"1010419321","pt":1580675342125,"mc":[{"id":"1.168238842","rc":[{"batb":[[0,2.04,54.76],[1,1.77,402.27],[2,1.01,15.52]],"ltp":1.93,"tv":34.27,"id":8860646}]}]}
{"op":"mcm","clk":"1010420234","pt":1580675351194,"mc":[{"id":"1.168238842","rc":[{"batb":[[0,1.57,64.44],[1,1.5,426.9],[2,1.01,15.52]],"ltp":2.06,"tv":208.18,"id":8258569}]}]}
{"op":"mcm","clk":"1010420490","pt":1580675353992,"mc":[{"id":"1.168238842","rc":[{"trd":[[1.82,157.03]],"batb":[[0,1.89,435.9],[1,1.87,469.97],[2,1.57,64.44]],"batl":[[0,1.98,413.49],[1,2,388.97],[2,2,0]],"ltp":1.82,"tv":365.21,"id":8258569}],"tv":399.49}]}
{"op":"mcm","clk":"1010420585","pt":1580675354903,"mc":[{"id":"1.168238842","rc":[{"batb":[[1,1.94,32.1],[2,1.77,402.27]],"ltp":1.93,"tv":34.27,"id":8860646},{"batb":[[2,1.85,37.22]],"ltp":1.82,"tv":365.21,"id":8258569}]}]}
{"op":"mcm","clk":"1010420712","pt":1580675356205,"mc":[{"id":"1.168238842","rc":[{"batl":[[0,2.2,37.86]],"ltp":1.93,"tv":34.27,"id":8860646}]}]}
{"op":"mcm","clk":"1010421878","pt":1580675367719,"mc":[{"id":"1.168238842","rc":[{"batb":[[0,1.94,32.1],[1,1.77,402.27],[2,1.01,15.52]],"ltp":1.93,"tv":34.27,"id":8860646},{"batb":[[0,1.69,49.96],[1,1.58,416.47],[2,1.01,15.52]],"ltp":1.82,"tv":365.21,"id":8258569}]}]}
{"op":"mcm","clk":"1010422203","pt":1580675371227,"mc":[{"id":"1.168238842","rc":[{"batb":[[1,1.93,32.5],[2,1.77,402.27]],"ltp":1.93,"tv":34.27,"id":8860646},{"batb":[[0,1.75,425],[1,1.73,606.99],[2,1.7,49.1]],"batl":[[0,2.08,338.38],[1,2.1,337.4]],"ltp":1.82,"tv":365.21,"id":8258569}]}]}
{"op":"mcm","clk":"1010422308","pt":1580675372225,"mc":[{"id":"1.168238842","rc":[{"batb":[[0,1.93,32.5],[1,1.77,402.27],[2,1.01,15.52]],"ltp":1.93,"tv":34.27,"id":8860646},{"batb":[[0,1.7,49.1],[1,1.58,416.47],[2,1.01,15.52]],"ltp":1.82,"tv":365.21,"id":8258569}]}]}
{"op":"mcm","clk":"1010422384","pt":1580675372957,"mc":[{"id":"1.168238842","rc":[{"batb":[[1,1.01,15.52],[2,1.01,0]],"ltp":1.93,"tv":34.27,"id":8860646},{"batb":[[1,1.01,15.52],[2,1.01,0]],"ltp":1.82,"tv":365.21,"id":8258569}]}]}
{"op":"mcm","clk":"1010422543","pt":1580675374539,"mc":[{"id":"1.168238842","rc":[{"batb":[[1,1.92,495.7],[2,1.9,446.89]],"batl":[[0,2.02,546.54],[1,2.04,367.01]],"ltp":1.93,"tv":34.27,"id":8860646}]}]}
{"op":"mcm","clk":"1010422691","pt":1580675376089,"mc":[{"id":"1.168238842","rc":[{"batb":[[0,1.95,62.87],[1,1.83,38.24],[2,1.01,15.52]],"ltp":1.82,"tv":365.21,"id":8258569}]}]}
{"op":"mcm","clk":"1010422782","pt":1580675376867,"mc":[{"id":"1.168238842","rc":[{"batb":[[2,1.62,415.43]],"ltp":1.82,"tv":365.21,"id":8258569}]}]}
{"op":"mcm","clk":"1010423429","pt":1580675383584,"mc":[{"id":"1.168238842","rc":[{"batb":[[0,1.85,37.06],[1,1.62,415.43],[2,1.01,15.52]],"ltp":1.93,"tv":34.27,"id":8860646},{"batb":[[0,1.83,38.24],[1,1.62,415.43],[2,1.01,15.52]],"ltp":1.82,"tv":365.21,"id":8258569}]}]}
{"op":"mcm","clk":"1010423746","pt":1580675386838,"mc":[{"id":"1.168238842","rc":[{"batb":[[0,1.86,36.67]],"ltp":1.93,"tv":34.27,"id":8860646}]}]}
{"op":"mcm","clk":"1010423873","pt":1580675388253,"mc":[{"id":"1.168238842","rc":[{"batb":[[0,1.95,310.9],[1,1.93,425.44],[2,1.86,36.67]],"batl":[[0,2.04,470.9],[1,2.06,356.73]],"ltp":1.93,"tv":34.27,"id":8860646}]}]}
{"op":"mcm","clk":"1010424236","pt":1580675391878,"mc":[{"id":"1.168238842","rc":[{"batb":[[0,1.86,36.67],[1,1.62,415.43],[2,1.01,15.52]],"ltp":1.93,"tv":34.27,"id":8860646}]}]}
{"op":"mcm","clk":"1010424498","pt":1580675394767,"mc":[{"id":"1.168238842","rc":[{"batb":[[0,1.86,567.78],[1,1.84,495.13],[2,1.62,415.43]],"batl":[[0,2.14,433.86],[1,2.16,311.41]],"ltp":1.93,"tv":34.27,"id":8860646}]}]}
{"op":"mcm","clk":"1010426009","pt":1580675409206,"mc":[{"id":"1.168238842","rc":[{"batb":[[0,1.86,36.67],[1,1.62,415.43],[2,1.01,15.52]],"ltp":1.93,"tv":34.27,"id":8860646}]}]}
{"op":"mcm","clk":"1010426360","pt":1580675412123,"mc":[{"id":"1.168238842","rc":[{"batb":[[1,1.01,15.52],[2,1.01,0]],"ltp":1.93,"tv":34.27,"id":8860646},{"batb":[[0,1.88,428.18],[1,1.86,478.04],[2,1.83,38.24]],"batl":[[0,1.96,319.86],[1,1.98,400.88]],"ltp":1.82,"tv":365.21,"id":8258569}]}]}
{"op":"mcm","clk":"1010426473","pt":1580675413216,"mc":[{"id":"1.168238842","rc":[{"batb":[[0,2.06,52.64],[1,1.93,32.34],[2,1.87,135.04]],"ltp":1.93,"tv":34.27,"id":8860646}]}]}
{"op":"mcm","clk":"1010427327","pt":1580675421251,"mc":[{"id":"1.168238842","rc":[{"batb":[[2,1.7,409.32]],"ltp":1.93,"tv":34.27,"id":8860646}]}]}
{"op":"mcm","clk":"1010427416","pt":1580675422020,"mc":[{"id":"1.168238842","rc":[{"batb":[[0,1.93,32.34],[1,1.7,409.32],[2,1.01,15.52]],"ltp":1.93,"tv":34.27,"id":8860646},{"batb":[[0,1.65,53.82],[1,1.62,415.43],[2,1.01,15.52]],"ltp":1.82,"tv":365.21,"id":8258569}]}]}
{"op":"mcm","clk":"1010428048","pt":1580675428155,"mc":[{"id":"1.168238842","rc":[{"batb":[[1,1.92,368.06],[2,1.9,446.83]],"batl":[[0,2,292.7],[1,2.02,377.84]],"ltp":1.93,"tv":34.27,"id":8860646},{"batb":[[0,1.95,31.63],[1,1.83,38.71],[2,1.65,53.82]],"ltp":1.82,"tv":365.21,"id":8258569}]}]}
{"op":"mcm","clk":"1010428147","pt":1580675429253,"mc":[{"id":"1.168238842","rc":[{"batb":[[2,1.62,415.43]],"ltp":1.82,"tv":365.21,"id":8258569}]}]}
{"op":"mcm","clk":"1010428951","pt":1580675437044,"mc":[{"id":"1.168238842","rc":[{"batb":[[0,1.86,36.27],[1,1.7,409.32],[2,1.01,15.52]],"ltp":1.93,"tv":34.27,"id":8860646},{"batb":[[0,1.83,38.71],[1,1.62,415.43],[2,1.01,15.52]],"ltp":1.82,"tv":365.21,"id":8258569}]}]}
{"op":"mcm","clk":"1010429272","pt":1580675440260,"mc":[{"id":"1.168238842","rc":[{"batb":[[0,1.86,525.35],[1,1.84,495.1],[2,1.7,409.32]],"batl":[[0,2.12,356.72],[1,2.14,319.69]],"ltp":1.93,"tv":34.27,"id":8860646}]}]}
{"op":"mcm","clk":"1010430207","pt":1580675449779,"mc":[{"id":"1.168238842","rc":[{"batb":[[2,1.01,15.52]],"ltp":1.93,"tv":34.27,"id":8860646},{"batb":[[1,1.01,15.52],[2,1.01,0]],"ltp":1.82,"tv":365.21,"id":8258569}]}]}
{"op":"mcm","clk":"1010430342","pt":1580675450999,"mc":[{"id":"1.168238842","rc":[{"batl":[[0,1.94,308.22],[1,1.96,413.37]],"ltp":1.93,"tv":34.27,"id":8860646}]}]}
{"op":"mcm","clk":"1010430454","pt":1580675451961,"mc":[{"id":"1.168238842","rc":[{"batb":[[2,1.67,52.17]],"ltp":1.93,"tv":34.27,"id":8860646},{"batb":[[0,2.02,56.18],[1,1.9,33.99],[2,1.01,15.52]],"ltp":1.82,"tv":365.21,"id":8258569}]}]}
{"op":"mcm","clk":"1010430621","pt":1580675453797,"mc":[{"id":"1.168238842","rc":[{"batb":[[2,1.67,409.76]],"ltp":1.82,"tv":365.21,"id":8258569}]}]}
{"op":"mcm","clk":"1010432069","pt":1580675467904,"mc":[{"id":"1.168238842","rc":[{"batb":[[0,1.87,36.19],[1,1.86,489.08],[2,1.84,495.1]],"ltp":1.93,"tv":34.27,"id":8860646}]}]}
{"op":"mcm","clk":"1010435864","pt":1580675504846,"mc":[{"id":"1.168238842","rc":[{"batb":[[0,1.87,35.8]],"ltp":1.93,"tv":34.27,"id":8860646},{"batb":[[1,1.89,34.46]],"ltp":1.82,"tv":365.21,"id":8258569}]}]}
{"op":"mcm","clk":"1010439599","pt":1580675537117,"mc":[{"id":"1.168238842","rc":[{"batb":[[0,1.68,51.54],[1,1.58,416.47],[2,1.01,15.52]],"ltp":1.93,"tv":34.27,"id":8860646},{"batb":[[0,1.89,34.46],[1,1.67,409.76],[2,1.01,15.52]],"ltp":1.82,"tv":365.21,"id":8258569}]}]}
{"op":"mcm","clk":"1010440292","pt":1580675542718,"mc":[{"id":"1.168238842","rc":[{"batb":[[0,1.82,532.71],[1,1.8,531.97],[2,1.68,51.54]],"batl":[[0,1.9,367.53],[1,1.92,439.98]],"ltp":1.93,"tv":34.27,"id":8860646}]}]}
{"op":"mcm","clk":"1010440495","pt":1580675544132,"mc":[{"id":"1.168238842","rc":[{"batb":[[0,1.68,51.54],[1,1.58,416.47],[2,1.01,15.52]],"ltp":1.93,"tv":34.27,"id":8860646}]}]}
{"op":"mcm","clk":"1010441058","pt":1580675548856,"mc":[{"id":"1.168238842","rc":[{"batb":[[0,1.69,353.31],[1,1.68,51.54],[2,1.67,685.72]],"batl":[[0,2.08,458.35],[1,2.1,337.42]],"ltp":1.93,"tv":34.27,"id":8860646}]}]}
{"op":"mcm","clk":"1010442587","pt":1580675563264,"mc":[{"id":"1.168238842","rc":[{"batb":[[1,1.01,15.52],[2,1.01,0]],"ltp":1.82,"tv":365.21,"id":8258569}]}]}
{"op":"mcm","clk":"1010442705","pt":1580675564171,"mc":[{"id":"1.168238842","rc":[{"batl":[[0,1.75,396.44],[1,1.77,568.42]],"ltp":1.93,"tv":34.27,"id":8860646}]}]}
{"op":"mcm","clk":"1010442828","pt":1580675565244,"mc":[{"id":"1.168238842","rc":[{"batb":[[0,2.3,38.55],[1,2.08,51.85],[2,1.01,15.52]],"ltp":1.82,"tv":365.21,"id":8258569}]}]}
{"op":"mcm","clk":"1010442952","pt":1580675566647,"mc":[{"id":"1.168238842","rc":[{"batb":[[2,1.77,402.27]],"ltp":1.82,"tv":365.21,"id":8258569}]}]}
{"op":"mcm","clk":"1010444058","pt":1580675577207,"mc":[{"id":"1.168238842","rc":[{"trd":[[1.69,456.81]],"batb":[[0,1.69,124.91]],"ltp":1.69,"tv":491.08,"id":8860646}],"tv":856.3}]}
{"op":"mcm","clk":"1010444140","pt":1580675577983,"mc":[{"id":"1.168238842","rc":[{"batb":[[0,1.68,51.54],[1,1.67,345.83],[2,1.48,82.23]],"ltp":1.69,"tv":491.08,"id":8860646}]}]}
{"op":"mcm","clk":"1010444451","pt":1580675580989,"mc":[{"id":"1.168238842","rc":[{"batb":[[0,1.68,660.66]],"batl":[[0,1.75,416.42]],"ltp":1.69,"tv":491.08,"id":8860646}]}]}
{"op":"mcm","clk":"1010444578","pt":1580675582086,"mc":[{"id":"1.168238842","rc":[{"batb":[[0,1.48,82.23],[1,1.46,435.7],[2,1.01,15.51]],"ltp":1.69,"tv":491.08,"id":8860646},{"batb":[[0,2.08,51.85],[1,1.01,15.52],[2,1.77,0]],"ltp":1.82,"tv":365.21,"id":8258569}]}]}
{"op":"mcm","clk":"1010445040","pt":1580675585969,"mc":[{"id":"1.168238842","rc":[{"batb":[[1,1.86,398.62],[2,1.01,15.52]],"ltp":1.82,"tv":365.21,"id":8258569}]}]}
{"op":"mcm","clk":"1010445172","pt":1580675587085,"mc":[{"id":"1.168238842","rc":[{"batb":[[0,1.64,567.43],[1,1.63,377],[2,1.48,82.23]],"batl":[[0,1.7,355.84],[1,1.72,625.3]],"ltp":1.69,"tv":491.08,"id":8860646}]}]}
{"op":"mcm","clk":"1010445508","pt":1580675590069,"mc":[{"id":"1.168238842","rc":[{"batb":[[0,1.48,82.23],[1,1.46,435.7],[2,1.01,15.51]],"ltp":1.69,"tv":491.08,"id":8860646}]}]}
{"op":"mcm","clk":"1010445889","pt":1580675593123,"mc":[{"id":"1.168238842","rc":[{"batb":[[0,1.49,450.66],[1,1.48,628.99],[2,1.46,435.7]],"batl":[[0,1.9,417.93],[1,1.92,439.88]],"ltp":1.69,"tv":491.08,"id":8860646}]}]}
{"op":"mcm","clk":"1010446448","pt":1580675598212,"mc":[{"id":"1.168238842","rc":[{"batb":[[0,1.48,82.23],[1,1.46,435.7],[2,1.01,15.51]],"ltp":1.69,"tv":491.08,"id":8860646}]}]}
{"op":"mcm","clk":"1010446541","pt":1580675599130,"mc":[{"id":"1.168238842","rc":[{"batb":[[1,1.01,15.51],[2,1.01,0]],"ltp":1.69,"tv":491.08,"id":8860646}]}]}
{"op":"mcm","clk":"1010446758","pt":1580675601035,"mc":[{"id":"1.168238842","rc":[{"batb":[[0,1.82,479.6],[1,1.8,531.84],[2,1.48,82.23]],"ltp":1.69,"tv":491.08,"id":8860646}]}]}
{"op":"mcm","clk":"1010446919","pt":1580675602212,"mc":[{"id":"1.168238842","rc":[{"batb":[[0,1.82,518.78],[2,1.6,60.82]],"ltp":1.69,"tv":491.08,"id":8860646},{"batb":[[1,1.92,33.28],[2,1.86,398.62]],"ltp":1.82,"tv":365.21,"id":8258569}]}]}
{"op":"mcm","clk":"1010448509","pt":1580675615635,"mc":[{"id":"1.168238842","rc":[{"batb":[[0,1.6,60.82],[1,1.52,425.49],[2,1.01,15.52]],"ltp":1.69,"tv":491.08,"id":8860646},{"batb":[[0,1.92,33.28],[1,1.86,398.62],[2,1.01,15.52]],"ltp":1.82,"tv":365.21,"id":8258569}]}]}
{"op":"mcm","clk":"1010448887","pt":1580675618938,"mc":[{"id":"1.168238842","rc":[{"batb":[[0,1.91,33.28]],"ltp":1.82,"tv":365.21,"id":8258569}]}]}
{"op":"mcm","clk":"1010449140","pt":1580675621264,"mc":[{"id":"1.168238842","rc":[{"batb":[[0,1.77,600.54],[1,1.75,584.52],[2,1.6,60.82]],"batl":[[0,1.85,447.06],[1,1.87,477.08]],"ltp":1.69,"tv":491.08,"id":8860646}]}]}
{"op":"mcm","clk":"1010449457","pt":1580675624072,"mc":[{"id":"1.168238842","rc":[{"batb":[[0,1.6,60.82],[1,1.52,425.49],[2,1.01,15.52]],"ltp":1.69,"tv":491.08,"id":8860646}]}]}
{"op":"mcm","clk":"1010449757","pt":1580675626777,"mc":[{"id":"1.168238842","rc":[{"batb":[[0,1.61,570.98],[1,1.6,464.48],[2,1.52,425.49]],"batl":[[0,2.06,470.24],[1,2.08,346.89]],"ltp":1.69,"tv":491.08,"id":8860646}]}]}
{"op":"mcm","clk":"1010450473","pt":1580675633266,"mc":[{"id":"1.168238842","rc":[{"batb":[[0,1.6,60.82],[1,1.52,425.49],[2,1.01,15.52]],"ltp":1.69,"tv":491.08,"id":8860646}]}]}
{"op":"mcm","clk":"1010450695","pt":1580675635267,"mc":[{"id":"1.168238842","rc":[{"batb":[[1,1.01,15.52],[2,1.01,0]],"ltp":1.69,"tv":491.08,"id":8860646},{"batb":[[1,1.01,15.52],[2,1.01,0]],"ltp":1.82,"tv":365.21,"id":8258569}]}]}
{"op":"mcm","clk":"1010450807","pt":1580675636277,"mc":[{"id":"1.168238842","rc":[{"batb":[[0,1.95,358.72],[1,1.93,425.48],[2,1.91,33.28]],"batl":[[0,2.04,425.29],[1,2.06,356.73]],"ltp":1.82,"tv":365.21,"id":8258569}]}]}
{"op":"mcm","clk":"1010450909","pt":1580675637178,"mc":[{"id":"1.168238842","rc":[{"batb":[[0,1.97,61.37],[1,1.76,43.28],[2,1.01,15.52]],"ltp":1.69,"tv":491.08,"id":8860646}]}]}
{"op":"mcm","clk":"1010451119","pt":1580675639063,"mc":[{"id":"1.168238842","rc":[{"batb":[[2,1.62,415.43]],"ltp":1.69,"tv":491.08,"id":8860646}]}]}
{"op":"mcm","clk":"1010452267","pt":1580675648199,"mc":[{"id":"1.168238842","rc":[{"batb":[[0,1.76,43.28],[1,1.62,415.43],[2,1.01,15.52]],"ltp":1.69,"tv":491.08,"id":8860646},{"batb":[[0,1.81,39.97],[1,1.62,415.43],[2,1.01,15.52]],"ltp":1.82,"tv":365.21,"id":8258569}]}]}
{"op":"mcm","clk":"1010452600","pt":1580675651078,"mc":[{"id":"1.168238842","rc":[{"batb":[[0,1.84,517.14],[1,1.82,512.97],[2,1.81,39.97]],"batl":[[0,2.28,256.71],[1,2.3,261.33]],"ltp":1.82,"tv":365.21,"id":8258569}]}]}
{"op":"mcm","clk":"1010452790","pt":1580675652796,"mc":[{"id":"1.168238842","rc":[{"batb":[[0,1.81,39.97],[1,1.62,415.43],[2,1.01,15.52]],"ltp":1.82,"tv":365.21,"id":8258569}]}]}
{"op":"mcm","clk":"1010453623","pt":1580675659791,"mc":[{"id":"1.168238842","rc":[{"batb":[[0,1.78,363.66],[1,1.76,616.02],[2,1.62,415.43]],"batl":[[0,2.18,279.63],[1,2.2,295.61]],"ltp":1.69,"tv":491.08,"id":8860646}]}]}
{"op":"mcm","clk":"1010454315","pt":1580675665111,"mc":[{"id":"1.168238842","rc":[{"batb":[[0,1.76,43.28],[1,1.62,415.43],[2,1.01,15.52]],"ltp":1.69,"tv":491.08,"id":8860646}]}]}
{"op":"mcm","clk":"1010454485","pt":1580675666313,"mc":[{"id":"1.168238842","rc":[{"batb":[[1,1.01,15.52],[2,1.01,0]],"ltp":1.69,"tv":491.08,"id":8860646}]}]}
{"op":"mcm","clk":"1010454663","pt":1580675667999,"mc":[{"id":"1.168238842","rc":[{"batb":[[0,1.84,517.14],[1,1.82,512.97],[2,1.81,39.97]],"batl":[[0,1.92,330.23],[1,1.94,426.31]],"ltp":1.82,"tv":365.21,"id":8258569}]}]}
{"op":"mcm","clk":"1010454749","pt":1580675668680,"mc":[{"id":"1.168238842","rc":[{"batb":[[0,2.1,50.75],[1,1.95,62.95],[2,1.01,15.52]],"ltp":1.69,"tv":491.08,"id":8860646}]}]}
{"op":"mcm","clk":"1010454894","pt":1580675669793,"mc":[{"id":"1.168238842","rc":[{"batb":[[2,1.7,409.32]],"ltp":1.69,"tv":491.08,"id":8860646}]}]}
{"op":"mcm","clk":"1010456394","pt":1580675681772,"mc":[{"id":"1.168238842","rc":[{"batb":[[0,1.95,62.95],[1,1.7,409.32],[2,1.01,15.52]],"ltp":1.69,"tv":491.08,"id":8860646},{"batb":[[0,1.75,44.53],[1,1.62,415.43],[2,1.01,15.52]],"ltp":1.82,"tv":365.21,"id":8258569}]}]}
{"op":"mcm","clk":"1010457097","pt":1580675687114,"mc":[{"id":"1.168238842","rc":[{"batb":[[0,1.86,476.82],[1,1.84,495.04],[2,1.75,44.53]],"batl":[[0,1.94,319.76],[1,1.96,413.31]],"ltp":1.82,"tv":365.21,"id":8258569}]}]}
{"op":"mcm","clk":"1010457579","pt":1580675690815,"mc":[{"id":"1.168238842","rc":[{"batb":[[0,1.75,44.53],[1,1.62,415.43],[2,1.01,15.52]],"ltp":1.82,"tv":365.21,"id":8258569}]}]}
{"op":"mcm","clk":"1010457990","pt":1580675693995,"mc":[{"id":"1.168238842","rc":[{"batb":[[0,1.8,345.79],[1,1.78,551.48],[2,1.75,44.53]],"batl":[[0,2.04,565.05],[1,2.06,356.72]],"ltp":1.82,"tv":365.21,"id":8258569}]}]}
{"op":"mcm","clk":"1010459227","pt":1580675703157,"mc":[{"id":"1.168238842","rc":[{"batl":[[0,1.87,368.15],[1,1.89,461.71]],"ltp":1.82,"tv":365.21,"id":8258569}]}]}
{"op":"mcm","clk":"1010459363","pt":1580675704065,"mc":[{"id":"1.168238842","rc":[{"batb":[[0,2.18,45.32],[1,2.02,56.57],[2,1.7,409.32]],"ltp":1.69,"tv":491.08,"id":8860646}]}]}
{"op":"mcm","clk":"1010462332","pt":1580675725212,"mc":[{"id":"1.168238842","rc":[{"batb":[[0,2.02,56.57],[1,1.7,409.32],[2,1.01,15.52]],"ltp":1.69,"tv":491.08,"id":8860646},{"batb":[[0,1.57,64.52],[1,1.52,425.49],[2,1.01,15.52]],"ltp":1.82,"tv":365.21,"id":8258569}]}]}
{"op":"mcm","clk":"1010463175","pt":1580675731133,"mc":[{"id":"1.168238842","rc":[{"batb":[[0,1.76,419.37],[1,1.74,595.32],[2,1.57,64.52]],"batl":[[0,1.83,402.17],[1,1.85,493.44]],"ltp":1.82,"tv":365.21,"id":8258569}]}]}
{"op":"mcm","clk":"1010463492","pt":1580675733227,"mc":[{"id":"1.168238842","rc":[{"batb":[[0,1.57,64.52],[1,1.52,425.49],[2,1.01,15.52]],"ltp":1.82,"tv":365.21,"id":8258569}]}]}
{"op":"mcm","clk":"1010463888","pt":1580675736204,"mc":[{"id":"1.168238842","rc":[{"batb":[[0,1.62,625],[1,1.61,394.55],[2,1.57,64.52]],"batl":[[0,2,347.4],[1,2.02,377.81]],"ltp":1.82,"tv":365.21,"id":8258569}]}]}
{"op":"mcm","clk":"1010464925","pt":1580675743836,"mc":[{"id":"1.168238842","rc":[{"batb":[[1,1.01,15.52],[2,1.01,0]],"ltp":1.69,"tv":491.08,"id":8860646}]}]}
{"op":"mcm","clk":"1010465089","pt":1580675745058,"mc":[{"id":"1.168238842","rc":[{"batl":[[0,1.68,374.73],[1,1.7,650.21]],"ltp":1.82,"tv":365.21,"id":8258569}]}]}
{"op":"mcm","clk":"1010465247","pt":1580675746013,"mc":[{"id":"1.168238842","rc":[{"batb":[[0,2.54,29.82],[1,2.24,41.54],[2,1.01,15.52]],"ltp":1.69,"tv":491.08,"id":8860646}]}]}
{"op":"mcm","clk":"1010465503","pt":1580675748025,"mc":[{"id":"1.168238842","rc":[{"batb":[[2,1.92,394.91]],"ltp":1.69,"tv":491.08,"id":8860646}]}]}
{"op":"mcm","clk":"1010466974","pt":1580675758263,"mc":[{"id":"1.168238842","rc":[{"trd":[[2.54,2.18]],"batb":[[0,2.54,27.64]],"ltp":2.54,"tv":493.27,"id":8860646},{"trd":[[1.65,3.36]],"ltp":1.65,"tv":368.57,"id":8258569}],"tv":861.85}]}
{"op":"mcm","clk":"1010467824","pt":1580675764275,"mc":[{"id":"1.168238842","rc":[{"batb":[[0,2.24,41.54],[1,1.92,394.91],[2,1.01,15.52]],"ltp":2.54,"tv":493.27,"id":8860646},{"batb":[[0,1.4,554.32],[1,1.01,15.51],[2,1.57,0]],"ltp":1.65,"tv":368.57,"id":8258569}]}]}
{"op":"mcm","clk":"1010468250","pt":1580675767169,"mc":[{"id":"1.168238842","rc":[{"batb":[[1,2.22,42.33],[2,1.92,394.91]],"ltp":2.54,"tv":493.27,"id":8860646},{"batb":[[0,1.41,101.67],[1,1.4,554.31],[2,1.01,15.51]],"ltp":1.65,"tv":368.57,"id":8258569}]}]}
{"op":"mcm","clk":"1010468363","pt":1580675767864,"mc":[{"id":"1.168238842","rc":[{"batb":[[0,2.22,42.33],[1,1.92,394.91],[2,1.01,15.52]],"ltp":2.54,"tv":493.27,"id":8860646},{"batb":[[1,1.4,451]],"ltp":1.65,"tv":368.57,"id":8258569}]}]}
{"op":"mcm","clk":"1010468833","pt":1580675771177,"mc":[{"id":"1.168238842","rc":[{"batb":[[0,1.58,607.92],[1,1.57,433.5],[2,1.41,101.67]],"batl":[[0,1.64,556.42],[1,1.65,357.58]],"ltp":1.65,"tv":368.57,"id":8258569}]}]}
{"op":"mcm","clk":"1010469054","pt":1580675772582,"mc":[{"id":"1.168238842","rc":[{"batb":[[0,1.41,101.67],[1,1.4,451],[2,1.01,15.51]],"ltp":1.65,"tv":368.57,"id":8258569}]}]}
{"op":"mcm","clk":"1010469407","pt":1580675775175,"mc":[{"id":"1.168238842","rc":[{"batb":[[0,1.44,441.37],[1,1.43,632.35],[2,1.41,101.66]],"batl":[[0,1.83,416.7],[1,1.85,493.42]],"ltp":1.65,"tv":368.57,"id":8258569}]}]}
{"op":"mcm","clk":"1010471538","pt":1580675790239,"mc":[{"id":"1.168238842","rc":[{"batb":[[1,1.01,15.52],[2,1.01,0]],"ltp":2.54,"tv":493.27,"id":8860646}]}]}
{"op":"mcm","clk":"1010471688","pt":1580675791215,"mc":[{"id":"1.168238842","rc":[{"batb":[[0,3.1,43.04],[1,2.68,25.41],[2,2.24,913.27]],"ltp":2.54,"tv":493.27,"id":8860646},{"trd":[[1.48,0.02]],"batb":[[0,1.44,441.36]],"batl":[[0,1.48,535.87],[1,1.49,522.82]],"ltp":1.48,"tv":368.59,"id":8258569}],"tv":861.87}]}
{"op":"mcm","clk":"1010471701","pt":1580675791321,"mc":[{"id":"1.168238842","rc":[{"batb":[[2,1.01,15.52]],"ltp":2.54,"tv":493.27,"id":8860646}]}]}
{"op":"mcm","clk":"1010472037","pt":1580675793506,"mc":[{"id":"1.168238842","rc":[{"batb":[[2,2.22,384.52]],"ltp":2.54,"tv":493.27,"id":8860646}]}]}
{"op":"mcm","clk":"1010473042","pt":1580675800940,"mc":[{"id":"1.168238842","rc":[{"trd":[[1.48,6.74]],"batl":[[0,1.48,532.51]],"ltp":1.48,"tv":375.32,"id":8258569}],"tv":868.59}]}
{"op":"mcm","clk":"1010474138","pt":1580675809104,"mc":[{"id":"1.168238842","rc":[{"batb":[[0,2.68,25.41],[1,2.22,384.52],[2,1.01,15.52]],"ltp":2.54,"tv":493.27,"id":8860646},{"batb":[[0,1.28,485.89],[1,1.26,175.62],[2,1.01,15.51]],"ltp":1.48,"tv":375.32,"id":8258569}]}]}
{"op":"mcm","clk":"1010474496","pt":1580675811810,"mc":[{"id":"1.168238842","rc":[{"batb":[[1,1.27,1584.05],[2,1.26,1393.68]],"batl":[[0,1.61,456.5],[1,1.62,381.9]],"ltp":1.48,"tv":375.32,"id":8258569}]}]}
{"op":"mcm","clk":"1010474834","pt":1580675814167,"mc":[{"id":"1.168238842","rc":[{"batb":[[1,1.26,175.62],[2,1.01,15.51]],"ltp":1.48,"tv":375.32,"id":8258569}]}]}
{"op":"mcm","clk":"1010475050","pt":1580675815865,"mc":[{"id":"1.168238842","rc":[{"batb":[[1,1.01,15.52],[2,1.01,0]],"ltp":2.54,"tv":493.27,"id":8860646},{"batb":[[0,1.26,175.62],[1,1.01,15.51],[2,1.01,0]],"ltp":1.48,"tv":375.32,"id":8258569}]}]}
{"op":"mcm","clk":"1010475233","pt":1580675817241,"mc":[{"id":"1.168238842","rc":[{"batb":[[0,1.56,409.01],[1,1.55,454.38],[2,1.26,175.62]],"ltp":1.48,"tv":375.32,"id":8258569}]}]}
{"op":"mcm","clk":"1010475356","pt":1580675818147,"mc":[{"id":"1.168238842","rc":[{"batb":[[1,2.3,39.03],[2,1.01,15.52]],"ltp":2.54,"tv":493.27,"id":8860646},{"batb":[[2,1.52,73.49]],"ltp":1.48,"tv":375.32,"id":8258569}]}]}
{"op":"mcm","clk":"1010475595","pt":1580675819959,"mc":[{"id":"1.168238842","rc":[{"batb":[[2,1.97,394.86]],"ltp":2.54,"tv":493.27,"id":8860646}]}]}
{"op":"mcm","clk":"1010477095","pt":1580675830989,"mc":[{"id":"1.168238842","rc":[{"batb":[[0,2.3,39.03],[1,1.97,394.86],[2,1.01,15.52]],"ltp":2.54,"tv":493.27,"id":8860646},{"batb":[[0,1.38,448.45],[1,1.32,136.59],[2,1.01,15.51]],"ltp":1.48,"tv":375.32,"id":8258569}]}]}
{"op":"mcm","clk":"1010477527","pt":1580675834054,"mc":[{"id":"1.168238842","rc":[{"batb":[[0,2.28,39.1]],"ltp":2.54,"tv":493.27,"id":8860646},{"batb":[[1,1.34,1082.79],[2,1.33,898.01]],"batl":[[0,1.79,432.3],[1,1.81,528.76]],"ltp":1.48,"tv":375.32,"id":8258569}]}]}
{"op":"mcm","clk":"1010481918","pt":1580675869058,"mc":[{"id":"1.168238842","rc":[{"batb":[[1,1.32,136.28],[2,1.01,15.51]],"ltp":1.48,"tv":375.32,"id":8258569}]}]}
{"op":"mcm","clk":"1010482076","pt":1580675870236,"mc":[{"id":"1.168238842","rc":[{"batb":[[0,1.32,136.28],[1,1.01,15.51],[2,1.01,0]],"ltp":1.48,"tv":375.32,"id":8258569}]}]}
{"op":"mcm","clk":"1010482400","pt":1580675872220,"mc":[{"id":"1.168238842","rc":[{"batb":[[0,1.72,488.58],[1,1.7,645.15],[2,1.32,136.28]],"ltp":1.48,"tv":375.32,"id":8258569}]}]}
{"op":"mcm","clk":"1010482538","pt":1580675873227,"mc":[{"id":"1.168238842","rc":[{"batb":[[1,2,57.36],[2,1.97,394.86]],"ltp":2.54,"tv":493.27,"id":8860646},{"batb":[[2,1.68,50.83]],"ltp":1.48,"tv":375.32,"id":8258569}]}]}
{"op":"mcm","clk":"1010483949","pt":1580675884261,"mc":[{"id":"1.168238842","rc":[{"trd":[[1.72,17.28]],"batb":[[0,1.72,483.54]],"ltp":1.72,"tv":385.4,"id":8258569}],"tv":878.67}]}
{"op":"mcm","clk":"1010484560","pt":1580675889285,"mc":[{"id":"1.168238842","rc":[{"batb":[[0,2,57.36],[1,1.97,394.86],[2,1.01,15.52]],"ltp":2.54,"tv":493.27,"id":8860646},{"batb":[[0,1.46,435.7],[1,1.44,92.84],[2,1.01,15.51]],"ltp":1.72,"tv":385.4,"id":8258569}]}]}
{"op":"mcm","clk":"1010484915","pt":1580675892075,"mc":[{"id":"1.168238842","rc":[{"batb":[[0,1.46,1357.72],[1,1.45,599.63],[2,1.44,92.84]],"batl":[[0,2.02,652.55],[1,2.04,367.04]],"ltp":1.72,"tv":385.4,"id":8258569}]}]}
{"op":"mcm","clk":"1010485832","pt":1580675899033,"mc":[{"id":"1.168238842","rc":[{"batb":[[0,1.46,435.7],[1,1.44,92.84],[2,1.01,15.51]],"ltp":1.72,"tv":385.4,"id":8258569}]}]}
{"op":"mcm","clk":"1010485964","pt":1580675900214,"mc":[{"id":"1.168238842","rc":[{"batb":[[1,1.01,15.52],[2,1.01,0]],"ltp":2.54,"tv":493.27,"id":8860646},{"batb":[[0,1.44,92.84],[1,1.01,15.51],[2,1.01,0]],"ltp":1.72,"tv":385.4,"id":8258569}]}]}
{"op":"mcm","clk":"1010486284","pt":1580675902289,"mc":[{"id":"1.168238842","rc":[{"batb":[[1,1.86,36.59],[2,1.01,15.52]],"ltp":2.54,"tv":493.27,"id":8860646},{"batb":[[0,1.92,384.41],[1,1.9,446.92],[2,1.88,35.56]],"ltp":1.72,"tv":385.4,"id":8258569}]}]}
{"op":"mcm","clk":"1010486509","pt":1580675904020,"mc":[{"id":"1.168238842","rc":[{"batb":[[2,1.67,409.76]],"ltp":2.54,"tv":493.27,"id":8860646}]}]}
{"op":"mcm","clk":"1010487490","pt":1580675911900,"mc":[{"id":"1.168238842","rc":[{"trd":[[1.92,3.36]],"batb":[[0,1.92,382.73]],"ltp":1.92,"tv":388.76,"id":8258569}],"tv":882.03}]}
{"op":"mcm","clk":"1010488062","pt":1580675916229,"mc":[{"id":"1.168238842","rc":[{"batl":[[0,2.02,377.9],[1,2.04,0]],"ltp":1.92,"tv":388.76,"id":8258569}]}]}
{"op":"mcm","clk":"1010488158","pt":1580675917016,"mc":[{"id":"1.168238842","rc":[{"batb":[[0,1.86,36.59],[1,1.67,409.76],[2,1.01,15.52]],"ltp":2.54,"tv":493.27,"id":8860646},{"batb":[[0,1.66,53.35],[1,1.58,416.47],[2,1.01,15.51]],"ltp":1.92,"tv":388.76,"id":8258569}]}]}
{"op":"mcm","clk":"1010488933","pt":1580675923242,"mc":[{"id":"1.168238842","rc":[{"batb":[[0,1.87,468.98],[1,1.85,486.58],[2,1.66,53.35]],"batl":[[0,1.95,304.28],[1,1.97,407.17]],"ltp":1.92,"tv":388.76,"id":8258569}]}]}
{"op":"mcm","clk":"1010489571","pt":1580675928651,"mc":[{"id":"1.168238842","rc":[{"batb":[[0,1.66,53.35],[1,1.58,416.47],[2,1.01,15.51]],"ltp":1.92,"tv":388.76,"id":8258569}]}]}
{"op":"mcm","clk":"1010489974","pt":1580675931962,"mc":[{"id":"1.168238842","rc":[{"batb":[[0,1.71,440.73],[1,1.69,658.4],[2,1.66,53.35]],"batl":[[0,2.16,306.36],[1,2.18,303.36]],"ltp":1.92,"tv":388.76,"id":8258569}]}]}
{"op":"mcm","clk":"1010490365","pt":1580675935243,"mc":[{"id":"1.168238842","rc":[{"batb":[[1,1.01,15.52],[2,1.01,0]],"ltp":2.54,"tv":493.27,"id":8860646}]}]}
{"op":"mcm","clk":"1010490489","pt":1580675936250,"mc":[{"id":"1.168238842","rc":[{"batb":[[0,2.34,37.06],[1,2.04,55.23],[2,1.86,36.59]],"ltp":2.54,"tv":493.27,"id":8860646},{"batl":[[0,1.78,533.28],[1,1.8,538.1]],"ltp":1.92,"tv":388.76,"id":8258569}]}]}
{"op":"mcm","clk":"1010490608","pt":1580675937151,"mc":[{"id":"1.168238842","rc":[{"batb":[[2,1.01,15.52]],"ltp":2.54,"tv":493.27,"id":8860646}]}]}
{"op":"mcm","clk":"1010490823","pt":1580675939008,"mc":[{"id":"1.168238842","rc":[{"batb":[[2,1.82,401.24]],"ltp":2.54,"tv":493.27,"id":8860646}]}]}
{"op":"mcm","clk":"1010492384","pt":1580675950993,"mc":[{"id":"1.168238842","rc":[{"batb":[[0,2.04,55.23],[1,1.82,401.24],[2,1.01,15.52]],"ltp":2.54,"tv":493.27,"id":8860646},{"batb":[[0,1.46,435.7],[1,1.42,96.23],[2,1.01,15.51]],"ltp":1.92,"tv":388.76,"id":8258569}]}]}
{"op":"mcm","clk":"1010492771","pt":1580675954097,"mc":[{"id":"1.168238842","rc":[{"batb":[[0,1.46,931.25],[1,1.45,596.43],[2,1.42,96.23]],"batl":[[0,1.99,358.52],[1,2.02,569.6]],"ltp":1.92,"tv":388.76,"id":8258569}]}]}
{"op":"mcm","clk":"1010493016","pt":1580675956018,"mc":[{"id":"1.168238842","rc":[{"batb":[[0,1.46,435.7],[1,1.42,96.23],[2,1.01,15.51]],"ltp":1.92,"tv":388.76,"id":8258569}]}]}
{"op":"mcm","clk":"1010493426","pt":1580675959285,"mc":[{"id":"1.168238842","rc":[{"batb":[[0,1.65,568.41],[1,1.64,368.85],[2,1.46,435.7]],"batl":[[0,1.72,629.83],[1,1.74,600.51]],"ltp":1.92,"tv":388.76,"id":8258569}]}]}
{"op":"mcm","clk":"1010493525","pt":1580675960016,"mc":[{"id":"1.168238842","rc":[{"batb":[[0,1.65,489.87]],"ltp":1.92,"tv":388.76,"id":8258569}]}]}
{"op":"mcm","clk":"1010493634","pt":1580675960801,"mc":[{"id":"1.168238842","rc":[{"batl":[[0,1.71,2.27]],"ltp":1.92,"tv":388.76,"id":8258569}]}]}
{"op":"mcm","clk":"1010493773","pt":1580675961918,"mc":[{"id":"1.168238842","rc":[{"batb":[[0,1.46,435.7],[1,1.42,96.23],[2,1.01,15.51]],"ltp":1.92,"tv":388.76,"id":8258569}]}]}
{"op":"mcm","clk":"1010494209","pt":1580675964928,"mc":[{"id":"1.168238842","rc":[{"batb":[[0,1.46,842.03],[1,1.45,596.28],[2,1.42,96.23]],"batl":[[1,1.99,423.85],[2,2.02,569.8]],"ltp":1.92,"tv":388.76,"id":8258569}]}]}
{"op":"mcm","clk":"1010494295","pt":1580675965542,"mc":[{"id":"1.168238842","rc":[{"batl":[[0,1.99,423.85],[1,2.02,569.8],[2,2.02,0]],"ltp":1.92,"tv":388.76,"id":8258569}]}]}
{"op":"mcm","clk":"1010494803","pt":1580675969620,"mc":[{"id":"1.168238842","rc":[{"batb":[[0,1.46,435.7],[1,1.42,96.23],[2,1.01,15.51]],"ltp":1.92,"tv":388.76,"id":8258569}]}]}
{"op":"mcm","clk":"1010495044","pt":1580675971417,"mc":[{"id":"1.168238842","rc":[{"batb":[[1,1.01,15.52],[2,1.01,0]],"ltp":2.54,"tv":493.27,"id":8860646},{"batb":[[0,1.42,96.23],[1,1.01,15.51],[2,1.01,0]],"ltp":1.92,"tv":388.76,"id":8258569}]}]}
{"op":"mcm","clk":"1010495275","pt":1580675973245,"mc":[{"id":"1.168238842","rc":[{"batb":[[1,1.88,35.25],[2,1.01,15.52]],"ltp":2.54,"tv":493.27,"id":8860646},{"batb":[[0,1.9,479.51],[1,1.88,462.37],[2,1.86,36.82]],"ltp":1.92,"tv":388.76,"id":8258569}]}]}
{"op":"mcm","clk":"1010495492","pt":1580675975029,"mc":[{"id":"1.168238842","rc":[{"batb":[[2,1.67,409.76]],"ltp":2.54,"tv":493.27,"id":8860646}]}]}
{"op":"mcm","clk":"1010497662","pt":1580675991282,"mc":[{"id":"1.168238842","rc":[{"trd":[[1.9,44.98]],"batb":[[0,1.9,457.02]],"ltp":1.9,"tv":433.73,"id":8258569}],"tv":927.01}]}
{"op":"mcm","clk":"1010497699","pt":1580675991549,"mc":[{"id":"1.168238842","rc":[{"batb":[[0,1.88,35.25],[1,1.67,409.76],[2,1.01,15.52]],"ltp":2.54,"tv":493.27,"id":8860646},{"batb":[[0,1.64,55.47],[1,1.58,416.47],[2,1.01,15.51]],"ltp":1.9,"tv":433.73,"id":8258569}]}]}
{"op":"mcm","clk":"1010498578","pt":1580675998046,"mc":[{"id":"1.168238842","rc":[{"batb":[[1,1.01,15.51],[2,1.01,0]],"ltp":1.9,"tv":433.73,"id":8258569}]}]}
{"op":"mcm","clk":"1010498859","pt":1580676000258,"mc":[{"id":"1.168238842","rc":[{"batb":[[1,1.87,468.6],[2,1.85,486.68]],"batl":[[0,1.95,304.9],[1,1.97,407.22]],"ltp":2.54,"tv":493.27,"id":8860646},{"batb":[[0,2,57.83],[1,1.87,35.72],[2,1.01,15.51]],"ltp":1.9,"tv":433.73,"id":8258569}]}]}
{"op":"mcm","clk":"1010498999","pt":1580676001295,"mc":[{"id":"1.168238842","rc":[{"batb":[[2,1.67,409.76]],"ltp":1.9,"tv":433.73,"id":8258569}]}]}
{"op":"mcm","clk":"1010499561","pt":1580676005269,"mc":[{"id":"1.168238842","rc":[{"batb":[[0,1.88,35.01]],"ltp":2.54,"tv":493.27,"id":8860646}]}]}
{"op":"mcm","clk":"1010499824","pt":1580676007171,"mc":[{"id":"1.168238842","rc":[{"batl":[[0,2.04,1.68]],"ltp":1.9,"tv":433.73,"id":8258569}]}]}
{"op":"mcm","clk":"1010500095","pt":1580676009283,"mc":[{"id":"1.168238842","rc":[{"trd":[[1.96,1.75]],"batl":[[0,1.96,460.05],[1,1.98,400.93]],"ltp":1.96,"tv":495.02,"id":8860646},{"trd":[[2.04,1.68]],"ltp":2.04,"tv":435.42,"id":8258569}],"tv":930.44}]}
{"op":"mcm","clk":"1010501004","pt":1580676016203,"mc":[{"id":"1.168238842","rc":[{"batb":[[0,1.89,34.7]],"ltp":1.96,"tv":495.02,"id":8860646},{"batb":[[0,1.99,58.85],[1,1.86,36.35]],"ltp":2.04,"tv":435.42,"id":8258569}]}]}
{"op":"mcm","clk":"1010501423","pt":1580676019220,"mc":[{"id":"1.168238842","rc":[{"batb":[[1,1.67,461.38],[2,1.01,15.52]],"ltp":1.96,"tv":495.02,"id":8860646}]}]}
{"op":"mcm","clk":"1010501703","pt":1580676021192,"mc":[{"id":"1.168238842","rc":[{"batl":[[0,1.96,398.38]],"ltp":1.96,"tv":495.02,"id":8860646}]}]}
{"op":"mcm","clk":"1010501998","pt":1580676023217,"mc":[{"id":"1.168238842","rc":[{"batb":[[1,1.88,306.95],[2,1.86,478.1]],"ltp":1.96,"tv":495.02,"id":8860646}]}]}
{"op":"mcm","clk":"1010502258","pt":1580676025220,"mc":[{"id":"1.168238842","rc":[{"batb":[[1,1.88,372.22]],"ltp":1.96,"tv":495.02,"id":8860646}]}]}
{"op":"mcm","clk":"1010506443","pt":1580676056264,"mc":[{"id":"1.168238842","rc":[{"batl":[[0,1.96,344.33]],"ltp":1.96,"tv":495.02,"id":8860646}]}]}
{"op":"mcm","clk":"1010506839","pt":1580676059152,"mc":[{"id":"1.168238842","rc":[{"trd":[[1.96,3.5]],"batl":[[0,1.96,342.58]],"ltp":1.96,"tv":496.77,"id":8860646},{"trd":[[2.04,3.36]],"ltp":2.04,"tv":437.1,"id":8258569}],"tv":933.87}]}
{"op":"mcm","clk":"1010508952","pt":1580676075800,"mc":[{"id":"1.168238842","rc":[{"trd":[[1.96,5.86]],"batl":[[0,1.96,340.22]],"ltp":1.96,"tv":499.13,"id":8860646},{"trd":[[2.04,5.63]],"ltp":2.04,"tv":439.37,"id":8258569}],"tv":938.5}]}
{"op":"mcm","clk":"1010510750","pt":1580676089220,"mc":[{"id":"1.168238842","rc":[{"batb":[[0,1.75,1.68],[1,1.67,461.38],[2,1.01,15.52]],"ltp":1.96,"tv":499.13,"id":8860646},{"batb":[[0,1.86,36.35],[1,1.67,409.76],[2,1.01,15.51]],"ltp":2.04,"tv":439.37,"id":8258569}]}]}
{"op":"mcm","clk":"1010511166","pt":1580676092242,"mc":[{"id":"1.168238842","rc":[{"batb":[[1,1.68,575.8],[2,1.67,806.75]],"batl":[[0,2.1,317.94],[1,2.12,328.42]],"ltp":1.96,"tv":499.13,"id":8860646}]}]}
{"op":"mcm","clk":"1010511202","pt":1580676092514,"mc":[{"id":"1.168238842","rc":[{"batb":[[2,1.67,755.13]],"ltp":1.96,"tv":499.13,"id":8860646}]}]}
{"op":"mcm","clk":"1010511451","pt":1580676094528,"mc":[{"id":"1.168238842","rc":[{"batb":[[1,1.68,51.3],[2,1.67,409.76]],"ltp":1.96,"tv":499.13,"id":8860646}]}]}
{"op":"mcm","clk":"1010511974","pt":1580676098164,"mc":[{"id":"1.168238842","rc":[{"batb":[[0,2.02,55.55],[1,1.83,38.08],[2,1.75,1.68]],"ltp":1.96,"tv":499.13,"id":8860646},{"batb":[[0,1.91,329.36],[1,1.89,454.38],[2,1.86,36.35]],"batl":[[0,1.99,350.51],[1,2.02,569.65]],"ltp":2.04,"tv":439.37,"id":8258569}]}]}
{"op":"mcm","clk":"1010513373","pt":1580676108255,"mc":[{"id":"1.168238842","rc":[{"batb":[[0,1.83,38.08],[1,1.75,1.68],[2,1.67,409.76]],"ltp":1.96,"tv":499.13,"id":8860646},{"batb":[[0,1.77,43.12],[1,1.67,409.76],[2,1.01,15.51]],"ltp":2.04,"tv":439.37,"id":8258569}]}]}
{"op":"mcm","clk":"1010513768","pt":1580676111176,"mc":[{"id":"1.168238842","rc":[{"batb":[[0,1.82,389.7],[1,1.8,531.77],[2,1.77,43.12]],"ltp":2.04,"tv":439.37,"id":8258569}]}]}
{"op":"mcm","clk":"1010514284","pt":1580676115061,"mc":[{"id":"1.168238842","rc":[{"batb":[[0,2.14,46.89],[1,1.99,59.48],[2,1.75,1.68]],"ltp":1.96,"tv":499.13,"id":8860646},{"batl":[[0,1.9,503.94],[1,1.92,439.9]],"ltp":2.04,"tv":439.37,"id":8258569}]}]}
{"op":"mcm","clk":"1010515641","pt":1580676125184,"mc":[{"id":"1.168238842","rc":[{"batb":[[0,1.99,59.48],[1,1.75,1.68],[2,1.67,409.76]],"ltp":1.96,"tv":499.13,"id":8860646},{"batb":[[0,1.71,48.31],[1,1.55,420.5],[2,1.01,15.51]],"ltp":2.04,"tv":439.37,"id":8258569}]}]}
{"op":"mcm","clk":"1010516012","pt":1580676128100,"mc":[{"id":"1.168238842","rc":[{"batb":[[0,1.77,362.59],[1,1.75,583.93],[2,1.71,48.31]],"batl":[[0,2.02,508.19],[1,2.04,367.13]],"ltp":2.04,"tv":439.37,"id":8258569}]}]}
{"op":"mcm","clk":"1010516578","pt":1580676132266,"mc":[{"id":"1.168238842","rc":[{"batb":[[0,1.71,48.31],[1,1.55,420.5],[2,1.01,15.51]],"ltp":2.04,"tv":439.37,"id":8258569}]}]}
{"op":"mcm","clk":"1010516940","pt":1580676135182,"mc":[{"id":"1.168238842","rc":[{"batb":[[1,1.76,43.2],[2,1.75,1.68]],"ltp":1.96,"tv":499.13,"id":8860646},{"batb":[[0,1.93,317.54],[1,1.91,439.59],[2,1.9,34.31]],"ltp":2.04,"tv":439.37,"id":8258569}]}]}
{"op":"mcm","clk":"1010517125","pt":1580676136600,"mc":[{"id":"1.168238842","rc":[{"batb":[[2,1.67,409.76]],"ltp":1.96,"tv":499.13,"id":8860646}]}]}
{"op":"mcm","clk":"1010518113","pt":1580676144006,"mc":[{"id":"1.168238842","rc":[{"batb":[[0,1.76,43.2],[1,1.67,409.76],[2,1.01,15.52]],"ltp":1.96,"tv":499.13,"id":8860646},{"batb":[[0,1.79,41.78],[1,1.55,420.5],[2,1.01,15.51]],"ltp":2.04,"tv":439.37,"id":8258569}]}]}
{"op":"mcm","clk":"1010518621","pt":1580676147931,"mc":[{"id":"1.168238842","rc":[{"batb":[[1,1.01,15.51],[2,1.01,0]],"ltp":2.04,"tv":439.37,"id":8258569}]}]}
{"op":"mcm","clk":"1010518859","pt":1580676149740,"mc":[{"id":"1.168238842","rc":[{"batb":[[0,1.94,444.04],[1,1.92,432.55],[2,1.76,43.2]],"batl":[[0,2.04,546.4],[1,2.06,356.76]],"ltp":1.96,"tv":499.13,"id":8860646}]}]}
{"op":"mcm","clk":"1010519065","pt":1580676151231,"mc":[{"id":"1.168238842","rc":[{"batb":[[0,1.76,43.2],[1,1.67,409.76],[2,1.01,15.52]],"ltp":1.96,"tv":499.13,"id":8860646},{"batb":[[1,1.62,415.43],[2,1.01,15.51]],"ltp":2.04,"tv":439.37,"id":8258569}]}]}
{"op":"mcm","clk":"1010519421","pt":1580676153927,"mc":[{"id":"1.168238842","rc":[{"batb":[[0,1.78,446.08],[1,1.76,616.13],[2,1.67,409.76]],"batl":[[0,2.22,280.62],[1,2.24,281.21]],"ltp":1.96,"tv":499.13,"id":8860646}]}]}
{"op":"mcm","clk":"1010521103","pt":1580676166844,"mc":[{"id":"1.168238842","rc":[{"batb":[[0,1.76,43.2],[1,1.67,409.76],[2,1.01,15.52]],"ltp":1.96,"tv":499.13,"id":8860646}]}]}
{"op":"mcm","clk":"1010521530","pt":1580676170263,"mc":[{"id":"1.168238842","rc":[{"batb":[[0,2.12,48.47],[1,1.98,60.43],[2,1.76,43.2]],"ltp":1.96,"tv":499.13,"id":8860646},{"batb":[[0,1.82,333.8],[1,1.8,531.67],[2,1.79,41.78]],"batl":[[0,1.89,332.81],[1,1.91,447.26]],"ltp":2.04,"tv":439.37,"id":8258569}]}]}
{"op":"mcm","clk":"1010521547","pt":1580676170371,"mc":[{"id":"1.168238842","rc":[{"batb":[[2,1.67,409.76]],"ltp":1.96,"tv":499.13,"id":8860646}]}]}
{"op":"mcm","clk":"1010523452","pt":1580676185171,"mc":[{"id":"1.168238842","rc":[{"batb":[[0,1.98,60.43],[1,1.67,409.76],[2,1.01,15.52]],"ltp":1.96,"tv":499.13,"id":8860646},{"batb":[[0,1.72,47.13],[1,1.62,415.43],[2,1.01,15.51]],"ltp":2.04,"tv":439.37,"id":8258569}]}]}
{"op":"mcm","clk":"1010523856","pt":1580676188290,"mc":[{"id":"1.168238842","rc":[{"batb":[[0,1.77,420.86],[1,1.75,584.57],[2,1.72,47.13]],"batl":[[0,2,324.17],[1,2.02,377.94]],"ltp":2.04,"tv":439.37,"id":8258569}]}]}
{"op":"mcm","clk":"1010524496","pt":1580676193258,"mc":[{"id":"1.168238842","rc":[{"batb":[[1,1.01,15.52],[2,1.01,0]],"ltp":1.96,"tv":499.13,"id":8860646}]}]}
{"op":"mcm","clk":"1010524726","pt":1580676195166,"mc":[{"id":"1.168238842","rc":[{"batb":[[0,2.22,42.49],[1,2.02,55.39],[2,1.98,60.43]],"ltp":1.96,"tv":499.13,"id":8860646},{"batl":[[0,1.84,375.31],[1,1.86,485.48]],"ltp":2.04,"tv":439.37,"id":8258569}]}]}
{"op":"mcm","clk":"1010524863","pt":1580676196074,"mc":[{"id":"1.168238842","rc":[{"batb":[[2,1.01,15.52]],"ltp":1.96,"tv":499.13,"id":8860646}]}]}
{"op":"mcm","clk":"1010524920","pt":1580676196565,"mc":[{"id":"1.168238842","rc":[{"batb":[[2,1.74,404.28]],"ltp":1.96,"tv":499.13,"id":8860646}]}]}
{"op":"mcm","clk":"1010525126","pt":1580676198066,"mc":[{"id":"1.168238842","rc":[{"batb":[[0,1.79,2.52],[1,1.77,420.86],[2,1.75,584.57]],"ltp":2.04,"tv":439.37,"id":8258569}]}]}
{"op":"mcm","clk":"1010525823","pt":1580676203194,"mc":[{"id":"1.168238842","rc":[{"batb":[[0,1.77,420.86],[1,1.75,584.57],[2,1.72,47.13]],"ltp":2.04,"tv":439.37,"id":8258569}]}]}
{"op":"mcm","clk":"1010526214","pt":1580676206278,"mc":[{"id":"1.168238842","rc":[{"trd":[[2.22,2.07]],"batb":[[0,2.22,40.42]],"ltp":2.22,"tv":501.19,"id":8860646},{"trd":[[1.82,159.55]],"ltp":1.82,"tv":441.89,"id":8258569}],"tv":943.09}]}
{"op":"mcm","clk":"1010528110","pt":1580676220781,"mc":[{"id":"1.168238842","rc":[{"batb":[[0,2.02,55.39],[1,1.74,404.28],[2,1.01,15.52]],"ltp":2.22,"tv":501.19,"id":8860646},{"batb":[[0,1.54,70.66],[1,1.52,425.49],[2,1.01,15.51]],"ltp":1.82,"tv":441.89,"id":8258569}]}]}
{"op":"mcm","clk":"1010528556","pt":1580676224198,"mc":[{"id":"1.168238842","rc":[{"batb":[[0,1.58,716.71],[1,1.57,434.44],[2,1.54,70.66]],"batl":[[0,1.98,325.96],[1,2,389.1]],"ltp":1.82,"tv":441.89,"id":8258569}]}]}
{"op":"mcm","clk":"1010528677","pt":1580676225167,"mc":[{"id":"1.168238842","rc":[{"batb":[[0,1.54,70.66],[1,1.52,425.49],[2,1.01,15.51]],"ltp":1.82,"tv":441.89,"id":8258569}]}]}
{"op":"mcm","clk":"1010529083","pt":1580676228213,"mc":[{"id":"1.168238842","rc":[{"batb":[[0,1.73,420.58],[1,1.71,632.08],[2,1.54,70.66]],"batl":[[0,1.8,490.26],[1,1.82,519.7]],"ltp":1.82,"tv":441.89,"id":8258569}]}]}
{"op":"mcm","clk":"1010529491","pt":1580676231140,"mc":[{"id":"1.168238842","rc":[{"batb":[[0,1.54,70.66],[1,1.52,425.49],[2,1.01,15.51]],"batl":[[0,1.77,1.77],[1,1.82,0]],"ltp":1.82,"tv":441.89,"id":8258569}]}]}
{"op":"mcm","clk":"1010529886","pt":1580676234204,"mc":[{"id":"1.168238842","rc":[{"batb":[[0,1.58,716.98],[1,1.57,434.45],[2,1.54,70.66]],"batl":[[1,1.98,325.74],[2,2,389.1]],"ltp":1.82,"tv":441.89,"id":8258569}]}]}
{"op":"mcm","clk":"1010530139","pt":1580676236262,"mc":[{"id":"1.168238842","rc":[{"batb":[[0,1.54,70.66],[1,1.52,425.49],[2,1.01,15.51]],"batl":[[1,1.98,0],[2,2,0]],"ltp":1.82,"tv":441.89,"id":8258569}]}]}
{"op":"mcm","clk":"1010530400","pt":1580676238242,"mc":[{"id":"1.168238842","rc":[{"batb":[[1,1.01,15.52],[2,1.01,0]],"ltp":2.22,"tv":501.19,"id":8860646},{"batb":[[1,1.01,15.51],[2,1.01,0]],"ltp":1.82,"tv":441.89,"id":8258569}]}]}
{"op":"mcm","clk":"1010530648","pt":1580676240163,"mc":[{"id":"1.168238842","rc":[{"batb":[[0,2.64,26.83],[1,2.3,38.32],[2,1.01,15.52]],"ltp":2.22,"tv":501.19,"id":8860646},{"batb":[[0,1.58,716.98],[1,1.57,434.45],[2,1.54,70.66]],"batl":[[0,1.64,457.48],[1,1.65,358.41],[2,1.77,1.77]],"ltp":1.82,"tv":441.89,"id":8258569}]}]}
{"op":"mcm","clk":"1010530926","pt":1580676242247,"mc":[{"id":"1.168238842","rc":[{"batb":[[2,1.97,394.86]],"ltp":2.22,"tv":501.19,"id":8860646}]}]}
{"op":"mcm","clk":"1010532605","pt":1580676255975,"mc":[{"id":"1.168238842","rc":[{"batb":[[0,2.3,38.32],[1,1.97,394.86],[2,1.01,15.52]],"ltp":2.22,"tv":501.19,"id":8860646},{"batb":[[0,1.38,448.45],[1,1.35,120.93],[2,1.01,15.51]],"batl":[[0,1.77,1.77],[1,1.65,0],[2,1.77,0]],"ltp":1.82,"tv":441.89,"id":8258569}]}]}
{"op":"mcm","clk":"1010532962","pt":1580676259182,"mc":[{"id":"1.168238842","rc":[{"batb":[[1,1.36,119.91]],"ltp":1.82,"tv":441.89,"id":8258569}]}]}
{"op":"mcm","clk":"1010533236","pt":1580676261251,"mc":[{"id":"1.168238842","rc":[{"batb":[[0,1.54,572.81],[1,1.53,479.68],[2,1.38,448.45]],"batl":[[0,1.59,389.95],[1,1.6,400.44],[2,1.77,1.77]],"ltp":1.82,"tv":441.89,"id":8258569}]}]}
{"op":"mcm","clk":"1010533601","pt":1580676264168,"mc":[{"id":"1.168238842","rc":[{"batb":[[0,1.38,448.45],[1,1.36,119.91],[2,1.01,15.51]],"batl":[[0,1.77,1.77],[1,1.6,0],[2,1.77,0]],"ltp":1.82,"tv":441.89,"id":8258569}]}]}
{"op":"mcm","clk":"1010533942","pt":1580676267031,"mc":[{"id":"1.168238842","rc":[{"batb":[[0,1.39,634.07],[1,1.38,1195.43],[2,1.36,119.91]],"batl":[[1,1.8,488.28],[2,1.82,519.82]],"ltp":1.82,"tv":441.89,"id":8258569}]}]}
{"op":"mcm","clk":"1010534231","pt":1580676269262,"mc":[{"id":"1.168238842","rc":[{"batl":[[1,1.8,0],[2,1.82,0]],"ltp":1.82,"tv":441.89,"id":8258569}]}]}
{"op":"mcm","clk":"1010534604","pt":1580676272182,"mc":[{"id":"1.168238842","rc":[{"batb":[[1,1.01,15.52],[2,1.01,0]],"ltp":2.22,"tv":501.19,"id":8860646},{"batb":[[1,1.38,746.98]],"batl":[[0,1.43,678.78],[1,1.44,602.06],[2,1.77,1.77]],"ltp":1.82,"tv":441.89,"id":8258569}]}]}
{"op":"mcm","clk":"1010534746","pt":1580676273197,"mc":[{"id":"1.168238842","rc":[{"batb":[[0,3.4,34.62],[1,2.84,22.03],[2,1.01,15.52]],"ltp":2.22,"tv":501.19,"id":8860646}]}]}
{"op":"mcm","clk":"1010535150","pt":1580676276214,"mc":[{"id":"1.168238842","rc":[{"batb":[[2,2.3,385.09]],"ltp":2.22,"tv":501.19,"id":8860646}]}]}
{"op":"mcm","clk":"1010536914","pt":1580676290249,"mc":[{"id":"1.168238842","rc":[{"batb":[[0,2.84,22.03],[1,2.3,385.09],[2,1.01,15.52]],"ltp":2.22,"tv":501.19,"id":8860646},{"batb":[[0,1.25,505.09],[1,1.2,231.17],[2,1.01,15.51]],"batl":[[0,1.77,1.77],[1,1.44,0],[2,1.77,0]],"ltp":1.82,"tv":441.89,"id":8258569}]}]}
{"op":"mcm","clk":"1010537291","pt":1580676293159,"mc":[{"id":"1.168238842","rc":[{"batl":[[0,1.57,728.94],[1,1.58,417.67],[2,1.77,1.77]],"ltp":1.82,"tv":441.89,"id":8258569}]}]}
{"op":"mcm","clk":"1010537680","pt":1580676296229,"mc":[{"id":"1.168238842","rc":[{"batb":[[1,1.01,15.52],[2,1.01,0]],"ltp":2.22,"tv":501.19,"id":8860646},{"batb":[[0,1.3,1649.78]],"ltp":1.82,"tv":441.89,"id":8258569}]}]}
{"op":"mcm","clk":"1010537792","pt":1580676297147,"mc":[{"id":"1.168238842","rc":[{"batb":[[1,2.36,35.64],[2,1.01,15.52]],"ltp":2.22,"tv":501.19,"id":8860646},{"batb":[[0,1.51,816.42],[1,1.5,520.69],[2,1.48,82.77]],"ltp":1.82,"tv":441.89,"id":8258569}]}]}
{"op":"mcm","clk":"1010538047","pt":1580676299273,"mc":[{"id":"1.168238842","rc":[{"batb":[[2,2.04,394.09]],"ltp":2.22,"tv":501.19,"id":8860646}]}]}
{"op":"mcm","clk":"1010538639","pt":1580676304145,"mc":[{"id":"1.168238842","rc":[{"batb":[[0,2.36,35.64],[1,2.04,394.09],[2,1.01,15.52]],"ltp":2.22,"tv":501.19,"id":8860646},{"batb":[[0,1.34,465.43],[1,1.27,169.09],[2,1.01,15.51]],"batl":[[0,1.77,1.77],[1,1.58,0],[2,1.77,0]],"ltp":1.82,"tv":441.89,"id":8258569}]}]}
{"op":"mcm","clk":"1010539175","pt":1580676308247,"mc":[{"id":"1.168238842","rc":[{"batb":[[0,1.46,872.44],[1,1.45,600.32],[2,1.34,465.43]],"batl":[[0,1.51,530.41],[1,1.52,484.69],[2,1.77,1.77]],"ltp":1.82,"tv":441.89,"id":8258569}]}]}
{"op":"mcm","clk":"1010539708","pt":1580676312674,"mc":[{"id":"1.168238842","rc":[{"batb":[[0,1.34,465.43],[1,1.27,169.09],[2,1.01,15.51]],"batl":[[0,1.77,1.77],[1,1.52,0],[2,1.77,0]],"ltp":1.82,"tv":441.89,"id":8258569}]}]}
{"op":"mcm","clk":"1010540038","pt":1580676315770,"mc":[{"id":"1.168238842","rc":[{"batb":[[1,1.29,1198.03],[2,1.28,1108.89]],"batl":[[0,1.76,552.12],[1,1.77,1.77],[2,1.78,558.12]],"ltp":1.82,"tv":441.89,"id":8258569}]}]}
{"op":"mcm","clk":"1010540939","pt":1580676324010,"mc":[{"id":"1.168238842","rc":[{"batb":[[1,1.27,169.09],[2,1.01,15.51]],"ltp":1.82,"tv":441.89,"id":8258569}]}]}
{"op":"mcm","clk":"1010541300","pt":1580676327228,"mc":[{"id":"1.168238842","rc":[{"batb":[[1,2.04,55.16]],"ltp":2.22,"tv":501.19,"id":8860646},{"batb":[[0,1.69,494.06],[1,1.67,687.07],[2,1.64,55.31]],"ltp":1.82,"tv":441.89,"id":8258569}]}]}
{"op":"mcm","clk":"1010541673","pt":1580676330244,"mc":[{"id":"1.168238842","rc":[{"batb":[[2,1.82,401.24]],"ltp":2.22,"tv":501.19,"id":8860646}]}]}
{"op":"mcm","clk":"1010543832","pt":1580676348209,"mc":[{"id":"1.168238842","rc":[{"batb":[[0,2.04,55.16],[1,1.82,401.24],[2,1.01,15.52]],"ltp":2.22,"tv":501.19,"id":8860646},{"batb":[[0,1.46,435.7],[1,1.38,109.13],[2,1.01,15.51]],"batl":[[0,1.77,1.77],[1,1.77,0],[2,1.78,0]],"ltp":1.82,"tv":441.89,"id":8258569}]}]}
{"op":"mcm","clk":"1010544154","pt":1580676350679,"mc":[{"id":"1.168238842","rc":[{"batb":[[1,1.42,635.13],[2,1.41,676.7]],"batl":[[1,1.99,312.63],[2,2.02,569.5]],"ltp":1.82,"tv":441.89,"id":8258569}]}]}
{"op":"mcm","clk":"1010544415","pt":1580676352921,"mc":[{"id":"1.168238842","rc":[{"batl":[[1,1.99,0],[2,2.02,0]],"ltp":1.82,"tv":441.89,"id":8258569}]}]}
{"op":"mcm","clk":"1010544679","pt":1580676355145,"mc":[{"id":"1.168238842","rc":[{"batb":[[1,1.01,15.52],[2,1.01,0]],"ltp":2.22,"tv":501.19,"id":8860646},{"batb":[[0,1.42,635.13],[1,1.41,676.7],[2,1.38,109.13]],"ltp":1.82,"tv":441.89,"id":8258569}]}]}
{"op":"mcm","clk":"1010544790","pt":1580676355936,"mc":[{"id":"1.168238842","rc":[{"batl":[[0,1.46,477.37],[1,1.47,554.23],[2,1.77,1.77]],"ltp":1.82,"tv":441.89,"id":8258569}]}]}
{"op":"mcm","clk":"1010544962","pt":1580676357205,"mc":[{"id":"1.168238842","rc":[{"batb":[[0,3.25,39.26],[1,2.4,34.62],[2,1.01,15.52]],"ltp":2.22,"tv":501.19,"id":8860646}]}]}
{"op":"mcm","clk":"1010545132","pt":1580676358637,"mc":[{"id":"1.168238842","rc":[{"batb":[[2,2.22,384.52]],"ltp":2.22,"tv":501.19,"id":8860646}]}]}
{"op":"mcm","clk":"1010546446","pt":1580676369868,"mc":[{"id":"1.168238842","rc":[{"trd":[[1.42,3.36]],"batb":[[0,1.42,633.45]],"ltp":1.42,"tv":445.25,"id":8258569}],"tv":946.45}]}
{"op":"mcm","clk":"1010546820","pt":1580676373193,"mc":[{"id":"1.168238842","rc":[{"batb":[[0,2.4,34.62],[1,2.22,384.52],[2,1.01,15.52]],"ltp":2.22,"tv":501.19,"id":8860646},{"batb":[[0,1.28,485.89],[1,1.12,390.58],[2,1.01,15.51]],"batl":[[0,1.77,1.77],[1,1.47,0],[2,1.77,0]],"ltp":1.42,"tv":445.25,"id":8258569}]}]}
{"op":"mcm","clk":"1010547032","pt":1580676375190,"mc":[{"id":"1.168238842","rc":[{"batb":[[1,1.01,15.52],[2,1.01,0]],"ltp":2.22,"tv":501.19,"id":8860646},{"batb":[[0,1.12,390.58],[1,1.01,15.51],[2,1.01,0]],"ltp":1.42,"tv":445.25,"id":8258569}]}]}
{"op":"mcm","clk":"1010547131","pt":1580676376087,"mc":[{"id":"1.168238842","rc":[{"batb":[[1,2.38,34.86],[2,1.01,15.52]],"ltp":2.22,"tv":501.19,"id":8860646},{"batb":[[0,1.13,2700.97],[1,1.12,1488.12],[2,1.01,15.51]],"batl":[[0,1.75,542.9],[1,1.77,570.25]],"ltp":1.42,"tv":445.25,"id":8258569}]}]}
{"op":"mcm","clk":"1010547217","pt":1580676376781,"mc":[{"id":"1.168238842","rc":[{"batb":[[0,2.38,34.86],[1,1.01,15.52],[2,1.01,0]],"ltp":2.22,"tv":501.19,"id":8860646},{"batb":[[0,1.13,388.85],[1,1.01,15.51],[2,1.01,0]],"batl":[[0,1.77,1.77],[1,1.77,0]],"ltp":1.42,"tv":445.25,"id":8258569}]}]}
{"op":"mcm","clk":"1010547386","pt":1580676378205,"mc":[{"id":"1.168238842","rc":[{"batb":[[0,1.35,816.67],[1,1.34,863.88],[2,1.13,388.85]],"batl":[[0,1.39,834.72],[1,1.4,678.66],[2,1.77,1.77]],"ltp":1.42,"tv":445.25,"id":8258569}]}]}
{"op":"mcm","clk":"1010547479","pt":1580676378995,"mc":[{"id":"1.168238842","rc":[{"batb":[[0,2.38,417.15]],"ltp":2.22,"tv":501.19,"id":8860646},{"batb":[[2,1.23,516.48]],"ltp":1.42,"tv":445.25,"id":8258569}]}]}
{"op":"mcm","clk":"1010547871","pt":1580676382449,"mc":[{"id":"1.168238842","rc":[{"batb":[[0,1.23,516.48],[1,1.13,388.85],[2,1.01,15.51]],"batl":[[0,1.77,1.77],[1,1.4,0],[2,1.77,0]],"ltp":1.42,"tv":445.25,"id":8258569}]}]}
{"op":"mcm","clk":"1010548069","pt":1580676384177,"mc":[{"id":"1.168238842","rc":[{"batb":[[0,2.38,34.86]],"ltp":2.22,"tv":501.19,"id":8860646},{"batb":[[0,1.13,388.85],[1,1.01,15.51],[2,1.01,0]],"ltp":1.42,"tv":445.25,"id":8258569}]}]}
{"op":"mcm","clk":"1010548287","pt":1580676386134,"mc":[{"id":"1.168238842","rc":[{"batb":[[0,1.13,2698.54],[1,1.12,1099.98],[2,1.01,15.51]],"batl":[[0,1.75,543.71],[1,1.77,570.25]],"ltp":1.42,"tv":445.25,"id":8258569}]}]}
{"op":"mcm","clk":"1010549275","pt":1580676394227,"mc":[{"id":"1.168238842","rc":[{"batl":[[0,1.77,1.77],[1,1.77,0]],"ltp":1.42,"tv":445.25,"id":8258569}]}]}
{"op":"mcm","clk":"1010549601","pt":1580676397131,"mc":[{"id":"1.168238842","rc":[{"batl":[[0,1.15,957.16],[1,1.16,2024.76],[2,1.77,1.77]],"ltp":1.42,"tv":445.25,"id":8258569}]}]}
{"op":"mcm","clk":"1010549727","pt":1580676398236,"mc":[{"id":"1.168238842","rc":[{"batb":[[0,7,24.55],[1,4.9,28.48],[2,1.01,15.52]],"ltp":2.22,"tv":501.19,"id":8860646},{"batb":[[2,1.09,565.72]],"ltp":1.42,"tv":445.25,"id":8258569}]}]}
{"op":"mcm","clk":"1010549850","pt":1580676399239,"mc":[{"id":"1.168238842","rc":[{"batb":[[2,3.2,374.33]],"ltp":2.22,"tv":501.19,"id":8860646},{"batb":[[2,1.09,1318.78]],"ltp":1.42,"tv":445.25,"id":8258569}]}]}
{"op":"mcm","clk":"1010550594","pt":1580676405620,"mc":[{"id":"1.168238842","rc":[{"trd":[[1.13,3.36]],"batb":[[0,1.13,2696.86]],"ltp":1.13,"tv":448.61,"id":8258569}],"tv":949.81}]}
{"op":"mcm","clk":"1010551955","pt":1580676416981,"mc":[{"id":"1.168238842","rc":[{"batb":[[0,1.13,2386.02]],"ltp":1.13,"tv":448.61,"id":8258569}]}]}
{"op":"mcm","clk":"1010552301","pt":1580676419797,"mc":[{"id":"1.168238842","rc":[{"batb":[[0,7.2,23.76],[1,5,27.62]],"ltp":2.22,"tv":501.19,"id":8860646},{"trd":[[1.13,78.98]],"batb":[[0,1.13,1998.85],[1,1.12,1806.68],[2,1.09,753.06]],"batl":[[0,1.15,1260.16]],"ltp":1.13,"tv":524.23,"id":8258569}],"tv":1025.43}]}
{"op":"mcm","clk":"1010552983","pt":1580676425232,"mc":[{"id":"1.168238842","rc":[{"batb":[[0,7.2,23.45],[1,5,27.22]],"ltp":2.22,"tv":501.19,"id":8860646}]}]}
{"op":"mcm","clk":"1010554367","pt":1580676437144,"mc":[{"id":"1.168238842","rc":[{"trd":[[1.15,1.7]],"batl":[[0,1.15,1259.31]],"ltp":1.15,"tv":525.93,"id":8258569}],"tv":1027.13}]}
{"op":"mcm","clk":"1010556095","pt":1580676452289,"mc":[{"id":"1.168238842","rc":[{"trd":[[1.15,4.5]],"batl":[[0,1.15,1257.91]],"ltp":1.15,"tv":528.73,"id":8258569}],"tv":1029.93}]}
{"op":"mcm","clk":"1010557959","pt":1580676469000,"mc":[{"id":"1.168238842","rc":[{"batl":[[2,1.2,2.52]],"ltp":1.15,"tv":528.73,"id":8258569}]}]}
{"op":"mcm","clk":"1010559175","pt":1580676479977,"mc":[{"id":"1.168238842","rc":[{"batb":[[0,5,27.22],[1,3.2,374.33],[2,1.01,15.52]],"ltp":2.22,"tv":501.19,"id":8860646},{"batb":[[0,1.09,753.06],[1,1.08,577.21],[2,1.01,15.51]],"batl":[[0,1.2,2.52],[1,1.77,1.77],[2,1.2,0]],"ltp":1.15,"tv":528.73,"id":8258569}]}]}
{"op":"mcm","clk":"1010559565","pt":1580676483241,"mc":[{"id":"1.168238842","rc":[{"batb":[[0,1.09,4273.96]],"batl":[[1,1.24,1613.72],[2,1.25,1199.66]],"ltp":1.15,"tv":528.73,"id":8258569}]}]}
{"op":"mcm","clk":"1010560120","pt":1580676488179,"mc":[{"id":"1.168238842","rc":[{"batl":[[0,1.18,2.52],[1,1.2,2.52],[2,1.24,1613.72]],"ltp":1.15,"tv":528.73,"id":8258569}]}]}
{"op":"mcm","clk":"1010560517","pt":1580676491275,"mc":[{"id":"1.168238842","rc":[{"batb":[[0,1.09,753.06]],"ltp":1.15,"tv":528.73,"id":8258569}]}]}
{"op":"mcm","clk":"1010560618","pt":1580676492159,"mc":[{"id":"1.168238842","rc":[{"batb":[[0,1.08,577.21],[1,1.01,15.51],[2,1.01,0]],"ltp":1.15,"tv":528.73,"id":8258569}]}]}
{"op":"mcm","clk":"1010560857","pt":1580676494196,"mc":[{"id":"1.168238842","rc":[{"batb":[[1,3.5,33.28],[2,3.2,374.33]],"ltp":2.22,"tv":501.19,"id":8860646},{"trd":[[1.18,5.04],[1.2,5.04]],"batb":[[0,1.21,1034.13],[1,1.2,1903.69],[2,1.14,351.47]],"batl":[[0,1.24,1613.72],[1,1.25,1199.66],[2,1.77,1.77]],"ltp":1.2,"tv":538.81,"id":8258569}],"tv":1040.01}]}
{"op":"mcm","clk":"1010561128","pt":1580676496286,"mc":[{"id":"1.168238842","rc":[{"trd":[[1.21,15.12]],"batb":[[0,1.21,1026.57],[2,1.16,576.13]],"ltp":1.21,"tv":553.93,"id":8258569}],"tv":1055.13}]}
{"op":"mcm","clk":"1010562426","pt":1580676507020,"mc":[{"id":"1.168238842","rc":[{"batb":[[0,3.5,33.28],[1,3.2,374.33],[2,1.01,15.52]],"ltp":2.22,"tv":501.19,"id":8860646},{"batb":[[0,1.16,576.13],[1,1.14,351.47],[2,1.01,15.51]],"batl":[[0,1.77,1.77],[1,1.25,0],[2,1.77,0]],"ltp":1.21,"tv":553.93,"id":8258569}]}]}
{"op":"mcm","clk":"1010563173","pt":1580676513107,"mc":[{"id":"1.168238842","rc":[{"batb":[[0,1.23,1726.66],[1,1.22,1404.91],[2,1.16,576.13]],"batl":[[0,1.26,626.08],[1,1.27,1116.48],[2,1.77,1.77]],"ltp":1.21,"tv":553.93,"id":8258569}]}]}
{"op":"mcm","clk":"1010563451","pt":1580676515212,"mc":[{"id":"1.168238842","rc":[{"batb":[[0,1.16,576.13],[1,1.14,351.47],[2,1.01,15.51]],"batl":[[0,1.77,1.77],[1,1.27,0],[2,1.77,0]],"ltp":1.21,"tv":553.93,"id":8258569}]}]}
{"op":"mcm","clk":"1010563806","pt":1580676518137,"mc":[{"id":"1.168238842","rc":[{"batb":[[1,1.15,802.12],[2,1.14,2862.63]],"batl":[[0,1.39,969.66],[1,1.4,682.37],[2,1.77,1.77]],"ltp":1.21,"tv":553.93,"id":8258569}]}]}
{"op":"mcm","clk":"1010564383","pt":1580676523034,"mc":[{"id":"1.168238842","rc":[{"batl":[[0,1.77,1.77],[1,1.4,0],[2,1.77,0]],"ltp":1.21,"tv":553.93,"id":8258569}]}]}
{"op":"mcm","clk":"1010564517","pt":1580676524135,"mc":[{"id":"1.168238842","rc":[{"batb":[[0,1.15,802.12],[1,1.14,2862.63],[2,1.01,15.51]],"ltp":1.21,"tv":553.93,"id":8258569}]}]}
{"op":"mcm","clk":"1010564745","pt":1580676526032,"mc":[{"id":"1.168238842","rc":[{"batl":[[0,1.17,1704.72],[1,1.18,1562.07],[2,1.77,1.77]],"ltp":1.21,"tv":553.93,"id":8258569}]}]}
{"op":"mcm","clk":"1010564877","pt":1580676527149,"mc":[{"id":"1.168238842","rc":[{"batb":[[0,6.6,28.95],[1,4.3,39.26],[2,3.2,374.33]],"ltp":2.22,"tv":501.19,"id":8860646},{"batb":[[2,1.09,553.37]],"ltp":1.21,"tv":553.93,"id":8258569}]}]}
{"op":"mcm","clk":"1010564999","pt":1580676528134,"mc":[{"id":"1.168238842","rc":[{"batb":[[2,1.1,723.21]],"ltp":1.21,"tv":553.93,"id":8258569}]}]}
{"op":"mcm","clk":"1010566448","pt":1580676540848,"mc":[{"id":"1.168238842","rc":[{"trd":[[1.15,10.5]],"batb":[[0,1.15,799.12]],"ltp":1.15,"tv":559.93,"id":8258569}],"tv":1061.13}]}
{"op":"mcm","clk":"1010566854","pt":1580676544248,"mc":[{"id":"1.168238842","rc":[{"batb":[[0,1.14,351.47],[1,1.1,723.21],[2,1.09,553.37]],"batl":[[0,1.77,1.77],[1,1.18,0],[2,1.77,0]],"ltp":1.15,"tv":559.93,"id":8258569}]}]}
{"op":"mcm","clk":"1010566950","pt":1580676545041,"mc":[{"id":"1.168238842","rc":[{"batb":[[0,4.3,39.26],[1,3.2,374.33],[2,1.01,15.52]],"ltp":2.22,"tv":501.19,"id":8860646},{"batb":[[0,1.1,723.21],[1,1.09,553.37],[2,1.01,15.51]],"ltp":1.15,"tv":559.93,"id":8258569}]}]}
{"op":"mcm","clk":"1010567040","pt":1580676545863,"mc":[{"id":"1.168238842","rc":[{"batb":[[0,1.17,2],[1,1.1,723.21],[2,1.09,553.37]],"ltp":1.15,"tv":559.93,"id":8258569}]}]}
{"op":"mcm","clk":"1010567208","pt":1580676547276,"mc":[{"id":"1.168238842","rc":[{"batb":[[1,1.1,2259.78],[2,1.09,2523.59]],"batl":[[0,1.28,540.36],[1,1.29,1025.68],[2,1.77,1.77]],"ltp":1.15,"tv":559.93,"id":8258569}]}]}
{"op":"mcm","clk":"1010567313","pt":1580676548155,"mc":[{"id":"1.168238842","rc":[{"batb":[[1,1.09,553.37],[2,1.01,15.51]],"batl":[[0,1.77,1.77],[1,1.29,0],[2,1.77,0]],"ltp":1.15,"tv":559.93,"id":8258569}]}]}
{"op":"mcm","clk":"1010567545","pt":1580676550144,"mc":[{"id":"1.168238842","rc":[{"batb":[[0,1.17,709.7],[1,1.16,2152.86],[2,1.09,553.37]],"batl":[[0,1.19,1315.27],[1,1.2,1567.81],[2,1.77,1.77]],"ltp":1.15,"tv":559.93,"id":8258569}]}]}
{"op":"mcm","clk":"1010567758","pt":1580676552177,"mc":[{"id":"1.168238842","rc":[{"batb":[[2,1.12,650.34]],"ltp":1.15,"tv":559.93,"id":8258569}]}]}
{"op":"mcm","clk":"1010567878","pt":1580676553071,"mc":[{"id":"1.168238842","rc":[{"batb":[[0,1.17,2],[1,1.12,650.34],[2,1.09,553.37]],"batl":[[0,1.77,1.77],[1,1.2,0],[2,1.77,0]],"ltp":1.15,"tv":559.93,"id":8258569}]}]}
{"op":"mcm","clk":"1010568223","pt":1580676556269,"mc":[{"id":"1.168238842","rc":[{"batl":[[0,1.28,540.36],[1,1.29,1025.68],[2,1.77,1.77]],"ltp":1.15,"tv":559.93,"id":8258569}]}]}
{"op":"mcm","clk":"1010568339","pt":1580676557263,"mc":[{"id":"1.168238842","rc":[{"batb":[[1,1.01,15.52],[2,1.01,0]],"ltp":2.22,"tv":501.19,"id":8860646},{"batb":[[1,1.09,553.37],[2,1.01,15.51]],"ltp":1.15,"tv":559.93,"id":8258569}]}]}
{"op":"mcm","clk":"1010568520","pt":1580676558892,"mc":[{"id":"1.168238842","rc":[{"batb":[[0,1.25,1477.64],[1,1.24,1355.29],[2,1.17,2]],"ltp":1.15,"tv":559.93,"id":8258569}]}]}
{"op":"mcm","clk":"1010568693","pt":1580676560204,"mc":[{"id":"1.168238842","rc":[{"batb":[[1,2.92,21.24],[2,1.01,15.52]],"ltp":2.22,"tv":501.19,"id":8860646},{"batb":[[0,1.25,1659.16]],"ltp":1.15,"tv":559.93,"id":8258569}]}]}
{"op":"mcm","clk":"1010568832","pt":1580676561207,"mc":[{"id":"1.168238842","rc":[{"batb":[[2,2.62,379.26]],"ltp":2.22,"tv":501.19,"id":8860646},{"batb":[[2,1.18,549.72]],"ltp":1.15,"tv":559.93,"id":8258569}]}]}
{"op":"mcm","clk":"1010570697","pt":1580676577055,"mc":[{"id":"1.168238842","rc":[{"trd":[[1.25,67.22]],"batb":[[0,1.25,1625.55]],"ltp":1.25,"tv":627.15,"id":8258569}],"tv":1128.35}]}
{"op":"mcm","clk":"1010571046","pt":1580676580257,"mc":[{"id":"1.168238842","rc":[{"batb":[[0,1.25,181.52],[1,1.18,549.72],[2,1.17,2]],"batl":[[0,1.77,1.77],[1,1.29,0],[2,1.77,0]],"ltp":1.25,"tv":627.15,"id":8258569}]}]}
{"op":"mcm","clk":"1010571076","pt":1580676580473,"mc":[{"id":"1.168238842","rc":[{"batb":[[0,2.92,21.24],[1,2.62,379.26],[2,1.01,15.52]],"ltp":2.22,"tv":501.19,"id":8860646},{"batb":[[0,1.18,549.72],[1,1.17,2],[2,1.16,300.96]],"ltp":1.25,"tv":627.15,"id":8258569}]}]}
{"op":"mcm","clk":"1010571402","pt":1580676583244,"mc":[{"id":"1.168238842","rc":[{"batb":[[2,1.16,2715.89]],"batl":[[0,1.51,523.43],[1,1.52,488.46],[2,1.77,1.77]],"ltp":1.25,"tv":627.15,"id":8258569}]}]}
{"op":"mcm","clk":"1010572277","pt":1580676591198,"mc":[{"id":"1.168238842","rc":[{"batb":[[2,1.16,300.96]],"batl":[[0,1.77,1.77],[1,1.52,0],[2,1.77,0]],"ltp":1.25,"tv":627.15,"id":8258569}]}]}
{"op":"mcm","clk":"1010572507","pt":1580676593279,"mc":[{"id":"1.168238842","rc":[{"batb":[[1,1.01,15.52],[2,1.01,0]],"ltp":2.22,"tv":501.19,"id":8860646},{"batb":[[0,1.17,2],[1,1.16,300.96],[2,1.1,5.88]],"ltp":1.25,"tv":627.15,"id":8258569}]}]}
{"op":"mcm","clk":"1010572612","pt":1580676594288,"mc":[{"id":"1.168238842","rc":[{"batb":[[1,2.14,47.92],[2,1.01,15.52]],"ltp":2.22,"tv":501.19,"id":8860646},{"batb":[[0,1.46,988.68],[1,1.45,604.92],[2,1.33,133.37]],"batl":[[0,1.51,523.43],[1,1.52,488.46],[2,1.77,1.77]],"ltp":1.25,"tv":627.15,"id":8258569}]}]}
{"op":"mcm","clk":"1010572825","pt":1580676596115,"mc":[{"id":"1.168238842","rc":[{"batb":[[2,2.12,388.65]],"ltp":2.22,"tv":501.19,"id":8860646}]}]}
{"op":"mcm","clk":"1010574375","pt":1580676609163,"mc":[{"id":"1.168238842","rc":[{"batb":[[0,2.14,47.92],[1,2.12,388.65],[2,1.01,15.52]],"ltp":2.22,"tv":501.19,"id":8860646},{"trd":[[1.51,6.08]],"batb":[[0,1.33,133.37],[1,1.31,477.51],[2,1.17,2]],"batl":[[0,1.77,1.77],[1,1.52,0],[2,1.77,0]],"ltp":1.51,"tv":633.24,"id":8258569}],"tv":1134.44}]}
{"op":"mcm","clk":"1010574903","pt":1580676613210,"mc":[{"id":"1.168238842","rc":[{"batb":[[0,1.33,889.59],[1,1.32,938.75],[2,1.31,477.51]],"batl":[[1,1.88,490.11],[2,1.9,455.47]],"ltp":1.51,"tv":633.24,"id":8258569}]}]}
{"op":"mcm","clk":"1010575131","pt":1580676615141,"mc":[{"id":"1.168238842","rc":[{"batl":[[1,1.88,0],[2,1.9,0]],"ltp":1.51,"tv":633.24,"id":8258569}]}]}
{"op":"mcm","clk":"1010575277","pt":1580676616428,"mc":[{"id":"1.168238842","rc":[{"batb":[[1,1.01,15.52],[2,1.01,0]],"ltp":2.22,"tv":501.19,"id":8860646},{"batb":[[2,1.17,2]],"ltp":1.51,"tv":633.24,"id":8258569}]}]}
{"op":"mcm","clk":"1010575441","pt":1580676617939,"mc":[{"id":"1.168238842","rc":[{"batl":[[0,1.37,1110],[1,1.38,726.57],[2,1.77,1.77]],"ltp":1.51,"tv":633.24,"id":8258569}]}]}
{"op":"mcm","clk":"1010575547","pt":1580676618902,"mc":[{"id":"1.168238842","rc":[{"batb":[[0,3.65,29.98],[1,2.18,45.64],[2,1.01,15.52]],"ltp":2.22,"tv":501.19,"id":8860646},{"batb":[[2,1.17,286.91]],"ltp":1.51,"tv":633.24,"id":8258569}]}]}
{"op":"mcm","clk":"1010575675","pt":1580676620117,"mc":[{"id":"1.168238842","rc":[{"batb":[[1,2.42,381.73],[2,2.18,45.64]],"ltp":2.22,"tv":501.19,"id":8860646},{"batb":[[2,1.22,523]],"ltp":1.51,"tv":633.24,"id":8258569}]}]}
{"op":"mcm","clk":"1010576481","pt":1580676627125,"mc":[{"id":"1.168238842","rc":[{"trd":[[1.37,0.04]],"batl":[[0,1.37,1109.98]],"ltp":1.37,"tv":633.28,"id":8258569}],"tv":1134.48}]}
{"op":"mcm","clk":"1010576728","pt":1580676629247,"mc":[{"id":"1.168238842","rc":[{"trd":[[1.37,2.38]],"batl":[[0,1.37,1108.81]],"ltp":1.37,"tv":635.62,"id":8258569}],"tv":1136.82}]}
{"op":"mcm","clk":"1010577735","pt":1580676638264,"mc":[{"id":"1.168238842","rc":[{"batb":[[0,1.33,133.37],[1,1.22,523],[2,1.17,284.91]],"batl":[[0,1.77,1.77],[1,1.38,0],[2,1.77,0]],"ltp":1.37,"tv":635.62,"id":8258569}]}]}
{"op":"mcm","clk":"1010577845","pt":1580676639243,"mc":[{"id":"1.168238842","rc":[{"batb":[[0,2.42,381.73],[1,2.18,45.64],[2,1.01,15.52]],"ltp":2.22,"tv":501.19,"id":8860646},{"batb":[[0,1.22,523],[1,1.17,284.91],[2,1.1,5.88]],"ltp":1.37,"tv":635.62,"id":8258569}]}]}
{"op":"mcm","clk":"1010578064","pt":1580676641254,"mc":[{"id":"1.168238842","rc":[{"batb":[[0,2.18,45.64],[1,1.01,15.52],[2,1.01,0]],"ltp":2.22,"tv":501.19,"id":8860646},{"batb":[[0,1.17,1545.72],[1,1.16,2036.75]],"batl":[[1,1.86,351.23],[2,1.88,470.86]],"ltp":1.37,"tv":635.62,"id":8258569}]}]}
{"op":"mcm","clk":"1010578286","pt":1580676643252,"mc":[{"id":"1.168238842","rc":[{"batl":[[1,1.86,0],[2,1.88,0]],"ltp":1.37,"tv":635.62,"id":8258569}]}]}
{"op":"mcm","clk":"1010578637","pt":1580676646144,"mc":[{"id":"1.168238842","rc":[{"batb":[[0,5.7,40.44],[1,3.5,32.34],[2,1.01,15.52]],"ltp":2.22,"tv":501.19,"id":8860646},{"batl":[[0,1.19,812.43],[1,1.2,1585.38],[2,1.77,1.77]],"ltp":1.37,"tv":635.62,"id":8258569}]}]}
{"op":"mcm","clk":"1010578954","pt":1580676648290,"mc":[{"id":"1.168238842","rc":[{"batb":[[2,2.98,374.28]],"ltp":2.22,"tv":501.19,"id":8860646},{"batb":[[2,1.12,650.34]],"ltp":1.37,"tv":635.62,"id":8258569}]}]}
{"op":"mcm","clk":"1010580165","pt":1580676660112,"mc":[{"id":"1.168238842","rc":[{"batb":[[0,3.5,32.34],[1,2.98,374.28],[2,1.01,15.52]],"ltp":2.22,"tv":501.19,"id":8860646},{"batb":[[0,1.12,650.34],[1,1.1,5.88],[2,1.09,539.52]],"batl":[[0,1.77,1.77],[1,1.2,0],[2,1.77,0]],"ltp":1.37,"tv":635.62,"id":8258569}]}]}
{"op":"mcm","clk":"1010580261","pt":1580676661011,"mc":[{"id":"1.168238842","rc":[{"batb":[[0,1.19,1.68],[1,1.12,650.34],[2,1.1,5.88]],"ltp":1.37,"tv":635.62,"id":8258569}]}]}
{"op":"mcm","clk":"1010580511","pt":1580676663264,"mc":[{"id":"1.168238842","rc":[{"batb":[[0,3.55,31.94],[1,3.5,32.34],[2,2.98,374.28]],"ltp":2.22,"tv":501.19,"id":8860646},{"batb":[[2,1.1,698.86]],"ltp":1.37,"tv":635.62,"id":8258569}]}]}
{"op":"mcm","clk":"1010580605","pt":1580676664149,"mc":[{"id":"1.168238842","rc":[{"batb":[[1,2.98,374.28],[2,1.01,15.52]],"ltp":2.22,"tv":501.19,"id":8860646}]}]}
{"op":"mcm","clk":"1010580699","pt":1580676665241,"mc":[{"id":"1.168238842","rc":[{"batb":[[1,1.01,15.52],[2,1.01,0]],"ltp":2.22,"tv":501.19,"id":8860646},{"batb":[[0,1.1,698.86],[1,1.09,3361.08],[2,1.01,15.51]],"ltp":1.37,"tv":635.62,"id":8258569}]}]}
{"op":"mcm","clk":"1010580811","pt":1580676666142,"mc":[{"id":"1.168238842","rc":[{"batl":[[0,1.11,930.83],[1,1.12,2504.07],[2,1.77,1.77]],"ltp":1.37,"tv":635.62,"id":8258569}]}]}
{"op":"mcm","clk":"1010580927","pt":1580676667259,"mc":[{"id":"1.168238842","rc":[{"batb":[[0,9,14.56],[1,5.6,21.48],[2,1.01,15.52]],"ltp":2.22,"tv":501.19,"id":8860646},{"batb":[[2,1.05,949.61]],"ltp":1.37,"tv":635.62,"id":8258569}]}]}
{"op":"mcm","clk":"1010581121","pt":1580676669126,"mc":[{"id":"1.168238842","rc":[{"batb":[[2,3.4,376.1]],"ltp":2.22,"tv":501.19,"id":8860646},{"trd":[[1.11,4]],"batb":[[2,1.06,993.9]],"batl":[[0,1.11,928.83]],"ltp":1.11,"tv":639.62,"id":8258569}],"tv":1140.82}]}
{"op":"mcm","clk":"1010581675","pt":1580676674255,"mc":[{"id":"1.168238842","rc":[{"batb":[[0,1.1,692.98]],"ltp":1.11,"tv":639.62,"id":8258569}]}]}
{"op":"mcm","clk":"1010582463","pt":1580676682250,"mc":[{"id":"1.168238842","rc":[{"trd":[[1.11,15.76]],"batl":[[0,1.11,922.95]],"ltp":1.11,"tv":651.38,"id":8258569}],"tv":1152.58}]}
{"op":"mcm","clk":"1010582567","pt":1580676683245,"mc":[{"id":"1.168238842","rc":[{"batb":[[0,5.6,21.48],[1,3.4,376.1],[2,1.01,15.52]],"ltp":2.22,"tv":501.19,"id":8860646},{"batb":[[0,1.06,993.9],[1,1.05,949.61],[2,1.01,15.51]],"batl":[[0,1.77,1.77],[1,1.12,0],[2,1.77,0]],"ltp":1.11,"tv":651.38,"id":8258569}]}]}
{"op":"mcm","clk":"1010582878","pt":1580676686172,"mc":[{"id":"1.168238842","rc":[{"batb":[[0,1.06,3693.63],[1,1.05,1879.19]],"batl":[[0,1.2,1512.36],[1,1.21,1477.51],[2,1.77,1.77]],"ltp":1.11,"tv":651.38,"id":8258569}]}]}
{"op":"mcm","clk":"1010582967","pt":1580676687064,"mc":[{"id":"1.168238842","rc":[{"batl":[[0,1.77,1.77],[1,1.21,0],[2,1.77,0]],"ltp":1.11,"tv":651.38,"id":8258569}]}]}
{"op":"mcm","clk":"1010583156","pt":1580676689180,"mc":[{"id":"1.168238842","rc":[{"batb":[[0,1.06,2699.73]],"ltp":1.11,"tv":651.38,"id":8258569}]}]}
{"op":"mcm","clk":"1010583261","pt":1580676690277,"mc":[{"id":"1.168238842","rc":[{"batb":[[0,13.5,14.01],[1,11.5,19.2],[2,3.4,376.1]],"ltp":2.22,"tv":501.19,"id":8860646},{"batb":[[2,1.03,1309.5]],"batl":[[0,1.07,1250.31],[1,1.08,2311.44],[2,1.77,1.77]],"ltp":1.11,"tv":651.38,"id":8258569}]}]}
{"op":"mcm","clk":"1010583430","pt":1580676691958,"mc":[{"id":"1.168238842","rc":[{"batb":[[2,1.04,1234.55]],"ltp":1.11,"tv":651.38,"id":8258569}]}]}
{"op":"mcm","clk":"1010585276","pt":1580676712213,"mc":[{"id":"1.168238842","rc":[{"batb":[[0,1.05,949.61],[1,1.04,1234.55],[2,1.03,1309.5]],"batl":[[0,1.08,1183.43],[1,1.77,1.77],[2,1.77,0]],"ltp":1.11,"tv":651.38,"id":8258569}]}]}
{"op":"mcm","clk":"1010585350","pt":1580676713024,"mc":[{"id":"1.168238842","rc":[{"batb":[[0,11.5,19.2],[1,3.4,376.1],[2,1.01,15.52]],"ltp":2.22,"tv":501.19,"id":8860646},{"batb":[[0,1.04,1234.55],[1,1.03,1309.5],[2,1.01,15.51]],"ltp":1.11,"tv":651.38,"id":8258569}]}]}
{"op":"mcm","clk":"1010585532","pt":1580676715113,"mc":[{"id":"1.168238842","rc":[{"batb":[[0,1.04,4921.28],[2,1.02,7.87]],"batl":[[1,1.09,2345.04],[2,1.77,1.77]],"ltp":1.11,"tv":651.38,"id":8258569}]}]}
{"op":"mcm","clk":"1010586072","pt":1580676720935,"mc":[{"id":"1.168238842","rc":[{"batb":[[0,1.04,1234.55]],"ltp":1.11,"tv":651.38,"id":8258569}]}]}
{"op":"mcm","clk":"1010586264","pt":1580676722812,"mc":[{"id":"1.168238842","rc":[{"batb":[[0,1.03,1309.5],[1,1.02,7.87],[2,1.01,15.51]],"ltp":1.11,"tv":651.38,"id":8258569}]}]}
{"op":"mcm","clk":"1010586395","pt":1580676724234,"mc":[{"id":"1.168238842","rc":[{"batb":[[1,10.5,23.53],[2,3.4,376.1]],"ltp":2.22,"tv":501.19,"id":8860646},{"batb":[[0,1.07,1924.98],[1,1.06,2463.68],[2,1.05,1004.93]],"ltp":1.11,"tv":651.38,"id":8258569}]}]}
{"op":"mcm","clk":"1010587522","pt":1580676735056,"mc":[{"id":"1.168238842","rc":[{"batb":[[0,10.5,23.53],[1,3.4,376.1],[2,1.01,15.52]],"ltp":2.22,"tv":501.19,"id":8860646},{"trd":[[1.07,2856.66]],"batb":[[0,1.06,1038.46],[1,1.05,1004.93],[2,1.04,1281.12]],"batl":[[0,1.09,1897.92],[1,1.77,1.77],[2,1.77,0]],"ltp":1.07,"tv":3508.04,"id":8258569}],"tv":4009.24}]}
{"op":"mcm","clk":"1010587547","pt":1580676735363,"mc":[{"id":"1.168238842","rc":[{"batb":[[0,1.05,1004.93],[1,1.04,1281.12],[2,1.02,7.87]],"ltp":1.07,"tv":3508.04,"id":8258569}]}]}
{"op":"mcm","clk":"1010587780","pt":1580676737975,"mc":[{"id":"1.168238842","rc":[{"batb":[[0,1.05,3608.2]],"batl":[[1,1.1,1095.64],[2,1.77,1.77]],"ltp":1.07,"tv":3508.04,"id":8258569}]}]}
{"op":"mcm","clk":"1010587837","pt":1580676738564,"mc":[{"id":"1.168238842","rc":[{"batb":[[0,1.05,1004.93]],"batl":[[0,1.09,710.94],[1,1.77,1.77],[2,1.77,0]],"ltp":1.07,"tv":3508.04,"id":8258569}]}]}
{"op":"mcm","clk":"1010588573","pt":1580676746187,"mc":[{"id":"1.168238842","rc":[{"batl":[[0,1.09,2411.92],[1,1.1,1095.64],[2,1.77,1.77]],"ltp":1.07,"tv":3508.04,"id":8258569}]}]}
{"op":"mcm","clk":"1010588625","pt":1580676746806,"mc":[{"id":"1.168238842","rc":[{"batb":[[1,1.02,7.87],[2,1.01,23.37]],"ltp":1.07,"tv":3508.04,"id":8258569}]}]}
{"op":"mcm","clk":"1010588767","pt":1580676748287,"mc":[{"id":"1.168238842","rc":[{"batb":[[0,1.07,3583.36],[1,1.05,1004.93],[2,1.02,7.87]],"ltp":1.07,"tv":3508.04,"id":8258569}]}]}
{"op":"mcm","clk":"1010588800","pt":1580676748596,"mc":[{"id":"1.168238842","rc":[{"batb":[[1,10,27.46],[2,3.4,376.1]],"ltp":2.22,"tv":501.19,"id":8860646},{"batb":[[0,1.07,4286.23],[1,1.06,813.73]],"ltp":1.07,"tv":3508.04,"id":8258569}]}]}
{"op":"mcm","clk":"1010589064","pt":1580676751117,"mc":[{"id":"1.168238842","rc":[{"batb":[[2,1.05,1069.58]],"ltp":1.07,"tv":3508.04,"id":8258569}]}]}
{"op":"mcm","clk":"1010589387","pt":1580676754110,"mc":[{"id":"1.168238842","rc":[{"batb":[[1,1.06,1035.73]],"ltp":1.07,"tv":3508.04,"id":8258569}]}]}
{"op":"mcm","clk":"1010589961","pt":1580676759818,"mc":[{"id":"1.168238842","rc":[{"trd":[[1.09,0.78]],"batl":[[0,1.09,2411.53]],"ltp":1.09,"tv":3508.82,"id":8258569}],"tv":4010.02}]}
{"op":"mcm","clk":"1010590287","pt":1580676762752,"mc":[{"id":"1.168238842","rc":[{"batb":[[0,10,27.46],[1,3.4,376.1],[2,1.01,15.52]],"ltp":2.22,"tv":501.19,"id":8860646},{"batb":[[0,1.07,1174.07]],"batl":[[0,1.1,1095.64],[1,1.77,1.77],[2,1.77,0]],"ltp":1.09,"tv":3508.82,"id":8258569}]}]}
{"op":"mcm","clk":"1010590670","pt":1580676766248,"mc":[{"id":"1.168238842","rc":[{"batb":[[1,1.06,3467.74]],"batl":[[0,1.1,3485.64]],"ltp":1.09,"tv":3508.82,"id":8258569}]}]}
{"op":"mcm","clk":"1010591166","pt":1580676771047,"mc":[{"id":"1.168238842","rc":[{"batb":[[1,1.06,1035.73]],"batl":[[0,1.77,1.77],[1,1.77,0]],"ltp":1.09,"tv":3508.82,"id":8258569}]}]}
{"op":"mcm","clk":"1010591494","pt":1580676773933,"mc":[{"id":"1.168238842","rc":[{"batb":[[1,1.06,3467.74]],"batl":[[0,1.08,1902.37],[1,1.09,1632.69],[2,1.77,1.77]],"ltp":1.09,"tv":3508.82,"id":8258569}]}]}
{"op":"mcm","clk":"1010591579","pt":1580676774768,"mc":[{"id":"1.168238842","rc":[{"batb":[[0,12,18.25],[1,10.5,24.55],[2,3.4,376.1]],"ltp":2.22,"tv":501.19,"id":8860646}]}]}
{"op":"mcm","clk":"1010592449","pt":1580676783075,"mc":[{"id":"1.168238842","rc":[{"batb":[[0,1.07,970.68]],"batl":[[1,1.09,1432.76]],"ltp":1.09,"tv":3508.82,"id":8258569}]}]}
{"op":"mcm","clk":"1010592786","pt":1580676786061,"mc":[{"id":"1.168238842","rc":[{"batb":[[1,1.06,3673.06]],"batl":[[0,1.08,2104.15]],"ltp":1.09,"tv":3508.82,"id":8258569}]}]}
{"op":"mcm","clk":"1010592908","pt":1580676787160,"mc":[{"id":"1.168238842","rc":[{"batb":[[0,1.06,1035.73],[1,1.05,1069.58],[2,1.04,1058.35]],"batl":[[0,1.09,1432.76],[1,1.77,1.77],[2,1.77,0]],"ltp":1.09,"tv":3508.82,"id":8258569}]}]}
{"op":"mcm","clk":"1010592925","pt":1580676787371,"mc":[{"id":"1.168238842","rc":[{"batb":[[0,10.5,24.55],[1,3.4,376.1],[2,1.01,15.52]],"ltp":2.22,"tv":501.19,"id":8860646},{"batb":[[0,1.06,222]],"ltp":1.09,"tv":3508.82,"id":8258569}]}]}
{"op":"mcm","clk":"1010593226","pt":1580676790154,"mc":[{"id":"1.168238842","rc":[{"batb":[[1,1.05,4721.2]],"batl":[[0,1.09,2153.85],[1,1.1,1351.36],[2,1.77,1.77]],"ltp":1.09,"tv":3508.82,"id":8258569}]}]}
{"op":"mcm","clk":"1010593413","pt":1580676791983,"mc":[{"id":"1.168238842","rc":[{"batb":[[1,1.05,1069.58]],"ltp":1.09,"tv":3508.82,"id":8258569}]}]}
{"op":"mcm","clk":"1010593721","pt":1580676794974,"mc":[{"id":"1.168238842","rc":[{"batb":[[0,1.07,3583.36],[1,1.06,222],[2,1.05,1069.58]],"ltp":1.09,"tv":3508.82,"id":8258569}]}]}
{"op":"mcm","clk":"1010593804","pt":1580676795720,"mc":[{"id":"1.168238842","rc":[{"batb":[[1,10,28.01],[2,3.4,376.1]],"ltp":2.22,"tv":501.19,"id":8860646},{"batb":[[0,1.07,4268.52],[1,1.06,1014.01]],"ltp":1.09,"tv":3508.82,"id":8258569}]}]}
{"op":"mcm","clk":"1010593960","pt":1580676797283,"mc":[{"id":"1.168238842","rc":[{"batl":[[0,1.09,1976.24]],"ltp":1.09,"tv":3508.82,"id":8258569}]}]}
{"op":"mcm","clk":"1010594287","pt":1580676800282,"mc":[{"id":"1.168238842","rc":[{"batl":[[1,1.1,1527.35]],"ltp":1.09,"tv":3508.82,"id":8258569}]}]}
{"op":"mcm","clk":"1010594891","pt":1580676806174,"mc":[{"id":"1.168238842","rc":[{"batb":[[0,10,28.01],[1,3.4,376.1],[2,1.01,15.52]],"ltp":2.22,"tv":501.19,"id":8860646},{"batb":[[0,1.07,2013.25]],"batl":[[0,1.1,1527.35],[1,1.77,1.77],[2,1.77,0]],"ltp":1.09,"tv":3508.82,"id":8258569}]}]}
{"op":"mcm","clk":"1010595171","pt":1580676809189,"mc":[{"id":"1.168238842","rc":[{"batb":[[1,1.06,2598.93]],"batl":[[0,1.1,3485.64]],"ltp":1.09,"tv":3508.82,"id":8258569}]}]}
{"op":"mcm","clk":"1010595548","pt":1580676813108,"mc":[{"id":"1.168238842","rc":[{"batl":[[0,1.08,294.07],[1,1.1,3485.64],[2,1.77,1.77]],"ltp":1.09,"tv":3508.82,"id":8258569}]}]}
{"op":"mcm","clk":"1010596168","pt":1580676819218,"mc":[{"id":"1.168238842","rc":[{"batb":[[0,1.07,1115.73],[1,1.06,1014.01]],"ltp":1.09,"tv":3508.82,"id":8258569}]}]}
{"op":"mcm","clk":"1010596481","pt":1580676822228,"mc":[{"id":"1.168238842","rc":[{"trd":[[1.08,588.14]],"batb":[[0,1.08,2151.12],[1,1.07,1115.73],[2,1.06,1014.01]],"batl":[[0,1.1,3485.64],[1,1.77,1.77],[2,1.77,0]],"ltp":1.08,"tv":4096.96,"id":8258569}],"tv":4598.16}]}
{"op":"mcm","clk":"1010596563","pt":1580676823132,"mc":[{"id":"1.168238842","rc":[{"batb":[[1,5.7,40.44],[2,3.4,376.1]],"ltp":2.22,"tv":501.19,"id":8860646},{"batb":[[0,1.08,2785.53]],"ltp":1.08,"tv":4096.96,"id":8258569}]}]}
{"op":"mcm","clk":"1010596662","pt":1580676824144,"mc":[{"id":"1.168238842","rc":[{"batb":[[2,1.06,222]],"ltp":1.08,"tv":4096.96,"id":8258569}]}]}
{"op":"mcm","clk":"1010596817","pt":1580676825667,"mc":[{"id":"1.168238842","rc":[{"trd":[[1.08,597.89]],"batb":[[0,1.08,2965.86],[1,1.07,1225.62]],"ltp":1.08,"tv":4106.72,"id":8258569}],"tv":4607.92}]}
{"op":"mcm","clk":"1010600825","pt":1580676867894,"mc":[{"id":"1.168238842","rc":[{"trd":[[1.08,1186.03]],"batb":[[0,1.08,2671.79]],"ltp":1.08,"tv":4694.86,"id":8258569}],"tv":5196.06}]}
{"op":"mcm","clk":"1010601119","pt":1580676871108,"mc":[{"id":"1.168238842","rc":[{"batb":[[0,1.08,2859.11],[1,1.07,1338.29]],"ltp":1.08,"tv":4694.86,"id":8258569}]}]}
{"op":"mcm","clk":"1010604275","pt":1580676905853,"mc":[{"id":"1.168238842","rc":[{"batb":[[0,5.7,40.44],[1,3.4,376.1],[2,1.01,15.52]],"ltp":2.22,"tv":501.19,"id":8860646},{"batb":[[0,1.06,222],[1,1.05,1069.58],[2,1.03,1304.86]],"batl":[[0,1.77,1.77],[1,1.77,0]],"ltp":1.08,"tv":4694.86,"id":8258569}]}]}
{"op":"mcm","clk":"1010604421","pt":1580676907365,"mc":[{"id":"1.168238842","rc":[{"batb":[[1,1.01,15.52],[2,1.01,0]],"ltp":2.22,"tv":501.19,"id":8860646},{"batb":[[1,1.03,1304.86],[2,1.02,7.87]],"ltp":1.08,"tv":4694.86,"id":8258569}]}]}
{"op":"mcm","clk":"1010604612","pt":1580676909255,"mc":[{"id":"1.168238842","rc":[{"batb":[[1,1.04,3687.16],[2,1.03,1304.86]],"batl":[[0,1.19,2032.88],[1,1.2,1179.6],[2,1.77,1.77]],"ltp":1.08,"tv":4694.86,"id":8258569}]}]}
{"op":"mcm","clk":"1010605086","pt":1580676914194,"mc":[{"id":"1.168238842","rc":[{"batl":[[0,1.77,1.77],[1,1.2,0],[2,1.77,0]],"ltp":1.08,"tv":4694.86,"id":8258569}]}]}
{"op":"mcm","clk":"1010605377","pt":1580676917263,"mc":[{"id":"1.168238842","rc":[{"trd":[[1.06,444]],"batb":[[0,1.04,3687.16],[1,1.03,1304.86],[2,1.02,7.87]],"batl":[[0,1.05,1896.27],[1,1.06,1519.3],[2,1.77,1.77]],"ltp":1.06,"tv":5138.86,"id":8258569}],"tv":5640.06}]}
{"op":"mcm","clk":"1010605466","pt":1580676918072,"mc":[{"id":"1.168238842","rc":[{"batb":[[0,17,16.6],[1,8.8,15.11],[2,1.01,15.52]],"ltp":2.22,"tv":501.19,"id":8860646}]}]}
{"op":"mcm","clk":"1010605525","pt":1580676918791,"mc":[{"id":"1.168238842","rc":[{"batb":[[2,4,373.79]],"ltp":2.22,"tv":501.19,"id":8860646},{"batb":[[2,1.02,2155.83]],"ltp":1.06,"tv":5138.86,"id":8258569}]}]}
{"op":"mcm","clk":"1010605658","pt":1580676920273,"mc":[{"id":"1.168238842","rc":[{"batl":[[0,1.05,2036.22]],"ltp":1.06,"tv":5138.86,"id":8258569}]}]}
{"op":"mcm","clk":"1010607095","pt":1580676934997,"mc":[{"id":"1.168238842","rc":[{"batb":[[0,8.8,15.11],[1,4,373.79],[2,1.01,15.52]],"ltp":2.22,"tv":501.19,"id":8860646},{"batb":[[0,1.02,2155.83],[1,1.01,23.37],[2,1.02,0]],"batl":[[0,1.04,2],[1,1.77,1.77],[2,1.77,0]],"ltp":1.06,"tv":5138.86,"id":8258569}]}]}
{"op":"mcm","clk":"1010607286","pt":1580676936927,"mc":[{"id":"1.168238842","rc":[{"batb":[[1,1.01,15.52],[2,1.01,0]],"ltp":2.22,"tv":501.19,"id":8860646},{"batb":[[0,1.02,7.87]],"ltp":1.06,"tv":5138.86,"id":8258569}]}]}
{"op":"mcm","clk":"1010607564","pt":1580676940150,"mc":[{"id":"1.168238842","rc":[{"trd":[[1.04,4]],"batb":[[0,1.05,3650.05],[1,1.02,7.87],[2,1.01,23.37]],"batl":[[0,1.06,978.13],[1,1.07,2614.79],[2,1.77,1.77]],"ltp":1.04,"tv":5142.86,"id":8258569}],"tv":5644.06}]}
{"op":"mcm","clk":"1010607752","pt":1580676942125,"mc":[{"id":"1.168238842","rc":[{"batb":[[1,3.9,370.01],[2,1.01,15.52]],"ltp":2.22,"tv":501.19,"id":8860646},{"batb":[[0,1.03,1535.84]],"batl":[[0,1.77,1.77],[1,1.07,0],[2,1.77,0]],"ltp":1.04,"tv":5142.86,"id":8258569}]}]}
{"op":"mcm","clk":"1010607942","pt":1580676944218,"mc":[{"id":"1.168238842","rc":[{"batb":[[1,1.01,15.52],[2,1.01,0]],"ltp":2.22,"tv":501.19,"id":8860646},{"batb":[[0,1.02,7.87],[1,1.01,23.37],[2,1.01,0]],"ltp":1.04,"tv":5142.86,"id":8258569}]}]}
{"op":"mcm","clk":"1010607995","pt":1580676944837,"mc":[{"id":"1.168238842","rc":[{"batb":[[1,1.01,3820.05]],"batl":[[0,1.11,1407.06],[1,1.12,2029.29],[2,1.77,1.77]],"ltp":1.04,"tv":5142.86,"id":8258569}]}]}
{"op":"mcm","clk":"1010608438","pt":1580676949839,"mc":[{"id":"1.168238842","rc":[{"batl":[[0,1.77,1.77],[1,1.12,0],[2,1.77,0]],"ltp":1.04,"tv":5142.86,"id":8258569}]}]}
{"op":"mcm","clk":"1010608717","pt":1580676952938,"mc":[{"id":"1.168238842","rc":[{"trd":[[1.02,15.74]],"batb":[[0,1.01,3820.05],[1,1.01,0]],"batl":[[0,1.02,1235.5],[1,1.03,2491.66],[2,1.77,1.77]],"ltp":1.02,"tv":5158.6,"id":8258569}],"tv":5659.8}]}
{"op":"mcm","clk":"1010608816","pt":1580676954037,"mc":[{"id":"1.168238842","rc":[{"batb":[[0,30,2.91],[1,16.5,8.97],[2,1.01,15.52]],"ltp":2.22,"tv":501.19,"id":8860646}]}]}
{"op":"mcm","clk":"1010608939","pt":1580676955240,"mc":[{"id":"1.168238842","rc":[{"batb":[[2,4.4,373.53]],"ltp":2.22,"tv":501.19,"id":8860646}]}]}
{"op":"mcm","clk":"1010609909","pt":1580676965882,"mc":[{"id":"1.168238842","rc":[{"trd":[[1.02,19.1]],"batl":[[0,1.02,1233.82]],"ltp":1.02,"tv":5161.96,"id":8258569}],"tv":5663.16}]}
{"op":"mcm","clk":"1010610196","pt":1580676969061,"mc":[{"id":"1.168238842","rc":[{"batb":[[0,16.5,8.97],[1,4.4,373.53],[2,1.01,15.52]],"ltp":2.22,"tv":501.19,"id":8860646},{"batb":[[0,1.01,23.37]],"batl":[[0,1.77,1.77],[1,1.03,0],[2,1.77,0]],"ltp":1.02,"tv":5161.96,"id":8258569}]}]}
{"op":"mcm","clk":"1010610307","pt":1580676970102,"mc":[{"id":"1.168238842","rc":[{"trd":[[1.01,46.74]],"batl":[[0,1.01,564.77],[1,1.77,1.77]],"ltp":1.01,"tv":5208.7,"id":8258569}],"tv":5709.9}]}
{"op":"mcm","clk":"1010610354","pt":1580676970574,"mc":[{"id":"1.168238842","rc":[{"batb":[[1,1.01,15.52],[2,1.01,0]],"ltp":2.22,"tv":501.19,"id":8860646}]}]}
{"op":"mcm","clk":"1010610498","pt":1580676972094,"mc":[{"id":"1.168238842","rc":[{"batl":[[1,1.06,3617.59],[2,1.77,1.77]],"ltp":1.01,"tv":5208.7,"id":8258569}]}]}
{"op":"mcm","clk":"1010610559","pt":1580676972772,"mc":[{"id":"1.168238842","rc":[{"batl":[[1,1.77,1.77],[2,1.77,0]],"ltp":1.01,"tv":5208.7,"id":8258569}]}]}
{"op":"mcm","clk":"1010610772","pt":1580676975161,"mc":[{"id":"1.168238842","rc":[{"batl":[[0,1.77,1.77],[1,1.77,0]],"ltp":1.01,"tv":5208.7,"id":8258569}]}]}
{"op":"mcm","clk":"1010610878","pt":1580676976204,"mc":[{"id":"1.168238842","rc":[{"trd":[[1.02,102.4]],"batb":[[0,1.02,3717.81]],"batl":[[0,1.03,3722.96],[1,1.77,1.77]],"ltp":1.02,"tv":5291.99,"id":8258569}],"tv":5793.19}]}
{"op":"mcm","clk":"1010611058","pt":1580676978114,"mc":[{"id":"1.168238842","rc":[{"batb":[[1,4.4,367.24],[2,1.01,15.52]],"batl":[[0,340,35.88]],"ltp":2.22,"tv":501.19,"id":8860646},{"batl":[[0,1.77,1.77],[1,1.77,0]],"ltp":1.02,"tv":5291.99,"id":8258569}]}]}
{"op":"mcm","clk":"1010611250","pt":1580676979640,"mc":[{"id":"1.168238842","rc":[{"batb":[[1,1.01,15.52],[2,1.01,0]],"ltp":2.22,"tv":501.19,"id":8860646}]}]}
{"op":"mcm","clk":"1010611374","pt":1580676981003,"mc":[{"id":"1.168238842","rc":[{"batl":[[0,1.06,3617.59],[1,1.77,1.77]],"ltp":1.02,"tv":5291.99,"id":8258569}]}]}
{"op":"mcm","clk":"1010612568","pt":1580676994147,"mc":[{"id":"1.168238842","rc":[{"batb":[[0,1.01,15.52],[1,1.01,0]],"ltp":2.22,"tv":501.19,"id":8860646},{"batl":[[0,1.77,1.77],[1,1.77,0]],"ltp":1.02,"tv":5291.99,"id":8258569}]}]}
{"op":"mcm","clk":"1010612822","pt":1580676997169,"mc":[{"id":"1.168238842","rc":[{"batl":[[0,1.01,3796.68],[1,1.77,1.77]],"ltp":1.02,"tv":5291.99,"id":8258569}]}]}
{"op":"mcm","clk":"1010613007","pt":1580676999262,"mc":[{"id":"1.168238842","rc":[{"batb":[[0,4.8,366.76],[1,1.01,15.52]],"ltp":2.22,"tv":501.19,"id":8860646}]}]}
{"op":"mcm","clk":"1010613324","pt":1580677002948,"mc":[{"id":"1.168238842","rc":[{"batl":[[0,1.01,4583.5]],"ltp":1.02,"tv":5291.99,"id":8258569}]}]}
{"op":"mcm","clk":"1010613577","pt":1580677005966,"mc":[{"id":"1.168238842","rc":[{"batl":[[0,1.01,4688.6]],"ltp":1.02,"tv":5291.99,"id":8258569}]}]}
{"op":"mcm","clk":"1010614292","pt":1580677014196,"mc":[{"id":"1.168238842","rc":[{"batl":[[0,1.01,3901.78]],"ltp":1.02,"tv":5291.99,"id":8258569}]}]}
{"op":"mcm","clk":"1010614632","pt":1580677018202,"mc":[{"id":"1.168238842","rc":[{"batl":[[0,1.01,105.1]],"ltp":1.02,"tv":5291.99,"id":8258569}]}]}
{"op":"mcm","clk":"1010614762","pt":1580677019702,"mc":[{"id":"1.168238842","rc":[{"batb":[[0,1.01,15.52],[1,1.01,0]],"ltp":2.22,"tv":501.19,"id":8860646}]}]}
{"op":"mcm","clk":"1010614896","pt":1580677021222,"mc":[{"id":"1.168238842","rc":[{"batl":[[1,1.02,3759.46],[2,1.77,1.77]],"ltp":1.02,"tv":5291.99,"id":8258569}]}]}
{"op":"mcm","clk":"1010615119","pt":1580677023885,"mc":[{"id":"1.168238842","rc":[{"batl":[[1,1.77,1.77],[2,1.77,0]],"ltp":1.02,"tv":5291.99,"id":8258569}]}]}
{"op":"mcm","clk":"1010615222","pt":1580677025234,"mc":[{"id":"1.168238842","marketDefinition":{"bspMarket":false,"turnInPlayEnabled":true,"persistenceEnabled":true,"marketBaseRate":5.0,"eventId":"29681898","eventTypeId":"2","numberOfWinners":1,"bettingType":"ODDS","marketType":"SET_WINNER","marketTime":"2020-02-02T20:18:00.000Z","suspendTime":"2020-02-02T20:18:00.000Z","bspReconciled":false,"complete":true,"inPlay":true,"crossMatching":true,"runnersVoidable":false,"numberOfActiveRunners":2,"betDelay":3,"status":"SUSPENDED","runners":[{"status":"ACTIVE","sortPriority":1,"id":8860646,"name":"Daniel Elahi Galan"},{"status":"ACTIVE","sortPriority":2,"id":8258569,"name":"Thai-Son Kwiatkowski"}],"regulators":["MR_INT"],"countryCode":"US","discountAllowed":true,"timezone":"UTC","openDate":"2020-02-02T20:18:00.000Z","version":3150578394,"name":"Set 1 Winner","eventName":"Galan v Kwiatkowski"}}]}
{"op":"mcm","clk":"1010622865","pt":1580677113283,"mc":[{"id":"1.168238842","tv":0.0}]}
{"op":"mcm","clk":"1010622923","pt":1580677114011,"mc":[{"id":"1.168238842","marketDefinition":{"bspMarket":false,"turnInPlayEnabled":true,"persistenceEnabled":true,"marketBaseRate":5.0,"eventId":"29681898","eventTypeId":"2","numberOfWinners":1,"bettingType":"ODDS","marketType":"SET_WINNER","marketTime":"2020-02-02T20:18:00.000Z","suspendTime":"2020-02-02T20:18:00.000Z","bspReconciled":false,"complete":true,"inPlay":true,"crossMatching":false,"runnersVoidable":false,"numberOfActiveRunners":0,"betDelay":3,"status":"CLOSED","settledTime":"2020-02-02T20:58:23.000Z","runners":[{"status":"LOSER","sortPriority":1,"id":8860646,"name":"Daniel Elahi Galan"},{"status":"WINNER","sortPriority":2,"id":8258569,"name":"Thai-Son Kwiatkowski"}],"regulators":["MR_INT"],"countryCode":"US","discountAllowed":true,"timezone":"UTC","openDate":"2020-02-02T20:18:00.000Z","version":3150582912,"name":"Set 1 Winner","eventName":"Galan v Kwiatkowski"}}]}
