{"op":"mcm","clk":"1002483925","pt":1580594279657,"mc":[{"id":"1.168238841","marketDefinition":{"bspMarket":false,"turnInPlayEnabled":true,"persistenceEnabled":true,"marketBaseRate":5.0,"eventId":"29681898","eventTypeId":"2","numberOfWinners":1,"bettingType":"ODDS","marketType":"SET_BETTING","marketTime":"2020-02-02T18:00:00.000Z","suspendTime":"2020-02-02T18:00:00.000Z","bspReconciled":false,"complete":true,"inPlay":false,"crossMatching":false,"runnersVoidable":false,"numberOfActiveRunners":4,"betDelay":0,"status":"OPEN","runners":[{"status":"ACTIVE","sortPriority":1,"id":16858291,"name":"Galan 2-0"},{"status":"ACTIVE","sortPriority":2,"id":16858293,"name":"Galan 2-1"},{"status":"ACTIVE","sortPriority":3,"id":13460814,"name":"Kwiatkowski 2-0"},{"status":"ACTIVE","sortPriority":4,"id":13460817,"name":"Kwiatkowski 2-1"}],"regulators":["MR_INT"],"countryCode":"US","discountAllowed":false,"timezone":"UTC","openDate":"2020-02-02T18:00:00.000Z","version":3147660989,"name":"Set Betting","eventName":"Galan v Kwiatkowski"}}]}
{"op":"mcm","clk":"1002483973","pt":1580594280292,"mc":[{"id":"1.168238841","marketDefinition":{"bspMarket":false,"turnInPlayEnabled":true,"persistenceEnabled":true,"marketBaseRate":5.0,"eventId":"29681898","eventTypeId":"2","numberOfWinners":1,"bettingType":"ODDS","marketType":"SET_BETTING","marketTime":"2020-02-02T18:00:00.000Z","suspendTime":"2020-02-02T18:00:00.000Z","bspReconciled":false,"complete":true,"inPlay":false,"crossMatching":false,"runnersVoidable":false,"numberOfActiveRunners":4,"betDelay":0,"status":"OPEN","runners":[{"status":"ACTIVE","sortPriority":1,"id":16858291,"name":"Galan 2-0"},{"status":"ACTIVE","sortPriority":2,"id":16858293,"name":"Galan 2-1"},{"status":"ACTIVE","sortPriority":3,"id":13460814,"name":"Kwiatkowski 2-0"},{"status":"ACTIVE","sortPriority":4,"id":13460817,"name":"Kwiatkowski 2-1"}],"regulators":["MR_INT"],"countryCode":"US","discountAllowed":false,"timezone":"UTC","openDate":"2020-02-02T18:00:00.000Z","version":3147660989,"name":"Set Betting","eventName":"Galan v Kwiatkowski"}}]}
{"op":"mcm","clk":"1002484254","pt":1580594284306,"mc":[{"id":"1.168238841","marketDefinition":{"bspMarket":false,"turnInPlayEnabled":true,"persistenceEnabled":true,"marketBaseRate":5.0,"eventId":"29681898","eventTypeId":"2","numberOfWinners":1,"bettingType":"ODDS","marketType":"SET_BETTING","marketTime":"2020-02-02T18:00:00.000Z","suspendTime":"2020-02-02T18:00:00.000Z","bspReconciled":false,"complete":true,"inPlay":false,"crossMatching":false,"runnersVoidable":false,"numberOfActiveRunners":4,"betDelay":0,"status":"OPEN","runners":[{"status":"ACTIVE","sortPriority":1,"id":16858291,"name":"Galan 2-0"},{"status":"ACTIVE","sortPriority":2,"id":16858293,"name":"Galan 2-1"},{"status":"ACTIVE","sortPriority":3,"id":13460814,"name":"Kwiatkowski 2-0"},{"status":"ACTIVE","sortPriority":4,"id":13460817,"name":"Kwiatkowski 2-1"}],"regulators":["MR_INT"],"countryCode":"US","discountAllowed":true,"timezone":"UTC","openDate":"2020-02-02T18:00:00.000Z","version":3147660989,"name":"Set Betting","eventName":"Galan v Kwiatkowski"}}]}
{"op":"mcm","clk":"1002629161","pt":1580596307111,"mc":[{"id":"1.168238841","marketDefinition":{"bspMarket":false,"turnInPlayEnabled":true,"persistenceEnabled":true,"marketBaseRate":5.0,"eventId":"29681898","eventTypeId":"2","numberOfWinners":1,"bettingType":"ODDS","marketType":"SET_BETTING","marketTime":"2020-02-02T19:00:00.000Z","suspendTime":"2020-02-02T19:00:00.000Z","bspReconciled":false,"complete":true,"inPlay":false,"crossMatching":false,"runnersVoidable":false,"numberOfActiveRunners":4,"betDelay":0,"status":"OPEN","runners":[{"status":"ACTIVE","sortPriority":1,"id":16858291,"name":"Galan 2-0"},{"status":"ACTIVE","sortPriority":2,"id":16858293,"name":"Galan 2-1"},{"status":"ACTIVE","sortPriority":3,"id":13460814,"name":"Kwiatkowski 2-0"},{"status":"ACTIVE","sortPriority":4,"id":13460817,"name":"Kwiatkowski 2-1"}],"regulators":["MR_INT"],"countryCode":"US","discountAllowed":true,"timezone":"UTC","openDate":"2020-02-02T18:00:00.000Z","version":3147732908,"name":"Set Betting","eventName":"Galan v Kwiatkowski"}}]}
{"op":"mcm","clk":"1002629419","pt":1580596310123,"mc":[{"id":"1.168238841","marketDefinition":{"bspMarket":false,"turnInPlayEnabled":true,"persistenceEnabled":true,"marketBaseRate":5.0,"eventId":"29681898","eventTypeId":"2","numberOfWinners":1,"bettingType":"ODDS","marketType":"SET_BETTING","marketTime":"2020-02-02T19:00:00.000Z","suspendTime":"2020-02-02T19:00:00.000Z","bspReconciled":false,"complete":true,"inPlay":false,"crossMatching":false,"runnersVoidable":false,"numberOfActiveRunners":4,"betDelay":0,"status":"OPEN","runners":[{"status":"ACTIVE","sortPriority":1,"id":16858291,"name":"Galan 2-0"},{"status":"ACTIVE","sortPriority":2,"id":16858293,"name":"Galan 2-1"},{"status":"ACTIVE","sortPriority":3,"id":13460814,"name":"Kwiatkowski 2-0"},{"status":"ACTIVE","sortPriority":4,"id":13460817,"name":"Kwiatkowski 2-1"}],"regulators":["MR_INT"],"countryCode":"US","discountAllowed":true,"timezone":"UTC","openDate":"2020-02-02T19:00:00.000Z","version":3147732908,"name":"Set Betting","eventName":"Galan v Kwiatkowski"}}]}
{"op":"mcm","clk":"1003051149","pt":1580602390700,"mc":[{"id":"1.168238841","rc":[{"batb":[[0,1.02,2]],"ltp":0.0,"tv":0.0,"id":16858291},{"batb":[[0,1.02,2]],"ltp":0.0,"tv":0.0,"id":16858293},{"batb":[[0,1.02,2]],"ltp":0.0,"tv":0.0,"id":13460814},{"batb":[[0,1.02,2]],"ltp":0.0,"tv":0.0,"id":13460817}]}]}
{"op":"mcm","clk":"1003066265","pt":1580602553207,"mc":[{"id":"1.168238841","rc":[{"batb":[[1,1.01,2.53]],"ltp":0.0,"tv":0.0,"id":16858291},{"batb":[[1,1.01,2.53]],"ltp":0.0,"tv":0.0,"id":16858293},{"batb":[[1,1.01,2.53]],"ltp":0.0,"tv":0.0,"id":13460814},{"batb":[[1,1.01,2.53]],"ltp":0.0,"tv":0.0,"id":13460817}]}]}
{"op":"mcm","clk":"1003066340","pt":1580602554037,"mc":[{"id":"1.168238841","rc":[{"batb":[[1,1.01,0.51]],"ltp":0.0,"tv":0.0,"id":16858291},{"batb":[[1,1.01,0.51]],"ltp":0.0,"tv":0.0,"id":16858293},{"batb":[[1,1.01,0.51]],"ltp":0.0,"tv":0.0,"id":13460814},{"batb":[[1,1.01,0.51]],"ltp":0.0,"tv":0.0,"id":13460817}]}]}
{"op":"mcm","clk":"1003185308","pt":1580604082082,"mc":[{"id":"1.168238841","rc":[{"batb":[[1,1.01,3.04]],"ltp":0.0,"tv":0.0,"id":16858291},{"batb":[[1,1.01,3.04]],"ltp":0.0,"tv":0.0,"id":16858293},{"batb":[[1,1.01,3.04]],"ltp":0.0,"tv":0.0,"id":13460814},{"batb":[[1,1.01,3.04]],"ltp":0.0,"tv":0.0,"id":13460817}]}]}
{"op":"mcm","clk":"1003185382","pt":1580604083272,"mc":[{"id":"1.168238841","rc":[{"batb":[[1,1.01,1.01]],"ltp":0.0,"tv":0.0,"id":16858291},{"batb":[[1,1.01,1.01]],"ltp":0.0,"tv":0.0,"id":16858293},{"batb":[[1,1.01,1.01]],"ltp":0.0,"tv":0.0,"id":13460814},{"batb":[[1,1.01,1.01]],"ltp":0.0,"tv":0.0,"id":13460817}]}]}
{"op":"mcm","clk":"1003453315","pt":1580607941948,"mc":[{"id":"1.168238841","rc":[{"batb":[[0,2.72,30.29],[1,1.02,2],[2,1.01,1.01]],"ltp":0.0,"tv":0.0,"id":16858291}]}]}
{"op":"mcm","clk":"1003453343","pt":1580607942459,"mc":[{"id":"1.168238841","rc":[{"batb":[[0,2.52,30.29],[1,1.02,2],[2,1.01,1.01]],"ltp":0.0,"tv":0.0,"id":13460814}]}]}
{"op":"mcm","clk":"1003975778","pt":1580617402048,"mc":[{"id":"1.168238841","rc":[{"batb":[[0,2.9,88.36],[1,2.72,30.29],[2,1.02,2]],"batl":[[0,8.2,265.98]],"ltp":0.0,"tv":0.0,"id":16858291},{"batb":[[0,3.6,70.99],[1,1.02,2],[2,1.01,1.01]],"batl":[[0,12.5,203.81]],"ltp":0.0,"tv":0.0,"id":16858293},{"batb":[[0,2.82,91.03],[1,2.52,30.29],[2,1.02,2]],"batl":[[0,6.6,265.46]],"ltp":0.0,"tv":0.0,"id":13460814},{"batb":[[0,2.72,94.34],[1,1.02,2],[2,1.01,1.01]],"batl":[[0,13.5,191.27]],"ltp":0.0,"tv":0.0,"id":13460817}]}]}
{"op":"mcm","clk":"1003976180","pt":1580617409926,"mc":[{"id":"1.168238841","marketDefinition":{"bspMarket":false,"turnInPlayEnabled":true,"persistenceEnabled":true,"marketBaseRate":5.0,"eventId":"29681898","eventTypeId":"2","numberOfWinners":1,"bettingType":"ODDS","marketType":"SET_BETTING","marketTime":"2020-02-02T19:00:00.000Z","suspendTime":"2020-02-02T19:00:00.000Z","bspReconciled":false,"complete":true,"inPlay":false,"crossMatching":true,"runnersVoidable":false,"numberOfActiveRunners":4,"betDelay":0,"status":"OPEN","runners":[{"status":"ACTIVE","sortPriority":1,"id":16858291,"name":"Galan 2-0"},{"status":"ACTIVE","sortPriority":2,"id":16858293,"name":"Galan 2-1"},{"status":"ACTIVE","sortPriority":3,"id":13460814,"name":"Kwiatkowski 2-0"},{"status":"ACTIVE","sortPriority":4,"id":13460817,"name":"Kwiatkowski 2-1"}],"regulators":["MR_INT"],"countryCode":"US","discountAllowed":true,"timezone":"UTC","openDate":"2020-02-02T19:00:00.000Z","version":3147732908,"name":"Set Betting","eventName":"Galan v Kwiatkowski"}}]}
{"op":"mcm","clk":"1003977481","pt":1580617436271,"mc":[{"id":"1.168238841","rc":[{"batb":[[0,2.94,87.09],[1,2.92,30.29]],"ltp":0.0,"tv":0.0,"id":16858291},{"batb":[[0,2.84,30.29],[1,2.82,91.03]],"ltp":0.0,"tv":0.0,"id":13460814}]}]}
{"op":"mcm","clk":"1003977500","pt":1580617436582,"mc":[{"id":"1.168238841","rc":[{"batb":[[0,2.86,89.68],[1,2.84,30.29]],"ltp":0.0,"tv":0.0,"id":13460814}]}]}
{"op":"mcm","clk":"1003983132","pt":1580617557922,"mc":[{"id":"1.168238841","rc":[{"batb":[[0,3.1,82.54],[1,2.96,30.29]],"ltp":0.0,"tv":0.0,"id":16858291},{"batb":[[1,1.02,2],[2,1.01,1.01]],"ltp":0.0,"tv":0.0,"id":13460814}]}]}
{"op":"mcm","clk":"1003983167","pt":1580617558747,"mc":[{"id":"1.168238841","rc":[{"batb":[[0,2.9,88.36],[1,2.88,30.28],[2,1.02,2]],"ltp":0.0,"tv":0.0,"id":13460814}]}]}
{"op":"mcm","clk":"1003988540","pt":1580617679102,"mc":[{"id":"1.168238841","rc":[{"batb":[[0,3.15,30.29],[1,3.1,82.54]],"ltp":0.0,"tv":0.0,"id":16858291}]}]}
{"op":"mcm","clk":"1003988584","pt":1580617680182,"mc":[{"id":"1.168238841","rc":[{"batb":[[0,3.2,79.97],[1,3.15,30.29]],"ltp":0.0,"tv":0.0,"id":16858291},{"batb":[[0,2.92,30.29],[1,2.9,88.36]],"ltp":0.0,"tv":0.0,"id":13460814}]}]}
{"op":"mcm","clk":"1003988598","pt":1580617680494,"mc":[{"id":"1.168238841","rc":[{"batb":[[0,2.94,87.09],[1,2.92,30.29]],"ltp":0.0,"tv":0.0,"id":13460814}]}]}
{"op":"mcm","clk":"1003993756","pt":1580617801216,"mc":[{"id":"1.168238841","rc":[{"batb":[[1,1.02,2],[2,1.01,1.01]],"ltp":0.0,"tv":0.0,"id":16858291},{"batb":[[1,1.02,2],[2,1.01,1.01]],"ltp":0.0,"tv":0.0,"id":13460814}]}]}
{"op":"mcm","clk":"1004131835","pt":1580621002091,"mc":[{"id":"1.168238841","rc":[{"batb":[[0,1.02,2],[1,1.01,1.01],[2,1.01,0]],"ltp":0.0,"tv":0.0,"id":16858291},{"batb":[[0,1.02,2],[1,1.01,1.01],[2,1.01,0]],"ltp":0.0,"tv":0.0,"id":16858293},{"batb":[[0,2.74,93.52]],"ltp":0.0,"tv":0.0,"id":13460814},{"batb":[[0,1.02,2],[1,1.01,1.01],[2,1.01,0]],"ltp":0.0,"tv":0.0,"id":13460817}]}]}
{"op":"mcm","clk":"1004131863","pt":1580621002605,"mc":[{"id":"1.168238841","rc":[{"batb":[[0,2.4,106.91],[1,1.02,2],[2,1.01,1.01]],"batl":[[0,6.8,320.62]],"ltp":0.0,"tv":0.0,"id":16858291},{"batl":[[0,16,161.63]],"ltp":0.0,"tv":0.0,"id":13460817}]}]}
{"op":"mcm","clk":"1004136239","pt":1580621086189,"mc":[{"id":"1.168238841","rc":[{"batb":[[0,2.94,87.09],[1,2.72,30.29],[2,1.02,2]],"ltp":0.0,"tv":0.0,"id":16858291}]}]}
{"op":"mcm","clk":"1004136259","pt":1580621086599,"mc":[{"id":"1.168238841","rc":[{"batb":[[0,2.82,91.03],[1,2.76,30.29],[2,1.02,2]],"batl":[[0,6.4,273.74]],"ltp":0.0,"tv":0.0,"id":13460814}]}]}
{"op":"mcm","clk":"1004141585","pt":1580621208195,"mc":[{"id":"1.168238841","rc":[{"batb":[[0,2.98,85.9],[1,2.96,30.29]],"ltp":0.0,"tv":0.0,"id":16858291}]}]}
{"op":"mcm","clk":"1004141611","pt":1580621208660,"mc":[{"id":"1.168238841","rc":[{"batb":[[0,2.9,88.36],[1,2.84,30.29]],"ltp":0.0,"tv":0.0,"id":13460814}]}]}
{"op":"mcm","clk":"1004145822","pt":1580621329262,"mc":[{"id":"1.168238841","rc":[{"batb":[[1,1.02,2],[2,1.01,1.01]],"ltp":0.0,"tv":0.0,"id":16858291}]}]}
{"op":"mcm","clk":"1004145860","pt":1580621330236,"mc":[{"id":"1.168238841","rc":[{"batb":[[0,3.05,84.09],[1,3,30.29],[2,1.02,2]],"ltp":0.0,"tv":0.0,"id":16858291},{"batb":[[0,2.94,87.09],[1,2.92,30.29]],"ltp":0.0,"tv":0.0,"id":13460814}]}]}
{"op":"mcm","clk":"1004149707","pt":1580621451227,"mc":[{"id":"1.168238841","rc":[{"batb":[[0,3.1,30.29],[1,1.02,2],[2,1.01,1.01]],"ltp":0.0,"tv":0.0,"id":16858291}]}]}
{"op":"mcm","clk":"1004149718","pt":1580621451637,"mc":[{"id":"1.168238841","rc":[{"batb":[[0,3.15,81.23],[1,3.1,30.29],[2,1.02,2]],"ltp":0.0,"tv":0.0,"id":16858291},{"batb":[[1,1.02,2],[2,1.01,1.01]],"ltp":0.0,"tv":0.0,"id":13460814}]}]}
{"op":"mcm","clk":"1004154542","pt":1580621572558,"mc":[{"id":"1.168238841","rc":[{"batb":[[1,1.02,2],[2,1.01,1.01]],"ltp":0.0,"tv":0.0,"id":16858291}]}]}
{"op":"mcm","clk":"1004214776","pt":1580623399250,"mc":[{"id":"1.168238841","rc":[{"batb":[[0,2.96,30.29],[1,2.94,87.09],[2,1.02,2]],"ltp":0.0,"tv":0.0,"id":13460814}]}]}
{"op":"mcm","clk":"1004214793","pt":1580623399612,"mc":[{"id":"1.168238841","rc":[{"batb":[[0,2.96,116.92],[1,1.02,2],[2,1.01,1.01]],"ltp":0.0,"tv":0.0,"id":13460814}]}]}
{"op":"mcm","clk":"1004218832","pt":1580623520450,"mc":[{"id":"1.168238841","rc":[{"batb":[[0,2.96,86.63]],"ltp":0.0,"tv":0.0,"id":13460814}]}]}
{"op":"mcm","clk":"1004252122","pt":1580624603125,"mc":[{"id":"1.168238841","rc":[{"batb":[[0,1.02,2],[1,1.01,1.01],[2,1.01,0]],"ltp":0.0,"tv":0.0,"id":16858291},{"batb":[[0,1.02,2],[1,1.01,1.01],[2,1.01,0]],"ltp":0.0,"tv":0.0,"id":13460814},{"batb":[[0,2.76,92.98],[1,1.02,2],[2,1.01,1.01]],"batl":[[0,15.5,166.59]],"ltp":0.0,"tv":0.0,"id":13460817}]}]}
{"op":"mcm","clk":"1004252138","pt":1580624603433,"mc":[{"id":"1.168238841","rc":[{"batb":[[0,2.28,112.66],[1,1.02,2],[2,1.01,1.01]],"batl":[[0,8,272.85]],"ltp":0.0,"tv":0.0,"id":16858291},{"batb":[[0,2.18,117.86],[1,1.02,2],[2,1.01,1.01]],"ltp":0.0,"tv":0.0,"id":13460814}]}]}
{"op":"mcm","clk":"1004252517","pt":1580624616141,"mc":[{"id":"1.168238841","rc":[{"batb":[[0,2.84,90.22],[1,2.72,30.29],[2,1.02,2]],"ltp":0.0,"tv":0.0,"id":16858291},{"batb":[[0,2.62,98.04],[1,2.54,30.29],[2,1.02,2]],"ltp":0.0,"tv":0.0,"id":13460814}]}]}
{"op":"mcm","clk":"1004256047","pt":1580624738238,"mc":[{"id":"1.168238841","rc":[{"batb":[[1,1.02,2],[2,1.01,1.01]],"ltp":0.0,"tv":0.0,"id":16858291}]}]}
{"op":"mcm","clk":"1004256089","pt":1580624739162,"mc":[{"id":"1.168238841","rc":[{"batb":[[0,2.9,88.36],[1,2.86,30.29],[2,1.02,2]],"ltp":0.0,"tv":0.0,"id":16858291},{"batb":[[0,2.64,30.29],[1,1.02,2],[2,1.01,1.01]],"batl":[[0,6.2,282.53]],"ltp":0.0,"tv":0.0,"id":13460814}]}]}
{"op":"mcm","clk":"1004256097","pt":1580624739325,"mc":[{"id":"1.168238841","rc":[{"batb":[[0,2.92,87.69],[1,2.64,30.29],[2,1.02,2]],"ltp":0.0,"tv":0.0,"id":13460814}]}]}
{"op":"mcm","clk":"1004260018","pt":1580624861269,"mc":[{"id":"1.168238841","rc":[{"batb":[[0,3.05,84.09],[1,2.92,30.29]],"ltp":0.0,"tv":0.0,"id":16858291},{"batb":[[0,2.94,30.29],[1,2.92,87.69]],"ltp":0.0,"tv":0.0,"id":13460814}]}]}
{"op":"mcm","clk":"1004260029","pt":1580624861576,"mc":[{"id":"1.168238841","rc":[{"batb":[[0,2.96,86.63],[1,2.94,30.29]],"ltp":0.0,"tv":0.0,"id":13460814}]}]}
{"op":"mcm","clk":"1004263139","pt":1580624982047,"mc":[{"id":"1.168238841","rc":[{"batb":[[0,3.15,81.23],[1,3.1,30.29]],"ltp":0.0,"tv":0.0,"id":16858291}]}]}
{"op":"mcm","clk":"1004263145","pt":1580624982351,"mc":[{"id":"1.168238841","rc":[{"batb":[[1,1.02,2],[2,1.01,1.01]],"ltp":0.0,"tv":0.0,"id":13460814}]}]}
{"op":"mcm","clk":"1004266726","pt":1580625104175,"mc":[{"id":"1.168238841","rc":[{"batb":[[1,1.02,2],[2,1.01,1.01]],"ltp":0.0,"tv":0.0,"id":16858291}]}]}
{"op":"mcm","clk":"1004343652","pt":1580627538023,"mc":[{"id":"1.168238841","rc":[{"batb":[[0,3.2,110.26]],"ltp":0.0,"tv":0.0,"id":16858291}]}]}
{"op":"mcm","clk":"1004348107","pt":1580627659271,"mc":[{"id":"1.168238841","rc":[{"batb":[[0,3.2,79.97]],"ltp":0.0,"tv":0.0,"id":16858291}]}]}
{"op":"mcm","clk":"1004348125","pt":1580627659576,"mc":[{"id":"1.168238841","rc":[{"batb":[[0,3.25,30.29]],"ltp":0.0,"tv":0.0,"id":16858291}]}]}
{"op":"mcm","clk":"1004353006","pt":1580627781286,"mc":[{"id":"1.168238841","rc":[{"batb":[[0,2.84,30.29],[1,2.28,112.66],[2,1.02,2]],"ltp":0.0,"tv":0.0,"id":16858291}]}]}
{"op":"mcm","clk":"1004353017","pt":1580627781544,"mc":[{"id":"1.168238841","rc":[{"batb":[[0,2.94,87.09],[1,2.84,30.29]],"ltp":0.0,"tv":0.0,"id":16858291}]}]}
{"op":"mcm","clk":"1004357663","pt":1580627903232,"mc":[{"id":"1.168238841","rc":[{"batb":[[1,1.02,2],[2,1.01,1.01]],"ltp":0.0,"tv":0.0,"id":16858291}]}]}
{"op":"mcm","clk":"1004357682","pt":1580627903641,"mc":[{"id":"1.168238841","rc":[{"batb":[[0,3,85.57],[1,2.96,30.29],[2,1.02,2]],"ltp":0.0,"tv":0.0,"id":16858291}]}]}
{"op":"mcm","clk":"1004363256","pt":1580628024788,"mc":[{"id":"1.168238841","rc":[{"batb":[[0,3.1,82.54],[1,3.05,30.29]],"ltp":0.0,"tv":0.0,"id":16858291}]}]}
{"op":"mcm","clk":"1004369010","pt":1580628146138,"mc":[{"id":"1.168238841","rc":[{"batb":[[0,3.15,30.29],[1,3.1,82.54]],"ltp":0.0,"tv":0.0,"id":16858291}]}]}
{"op":"mcm","clk":"1004369019","pt":1580628146444,"mc":[{"id":"1.168238841","rc":[{"batb":[[0,3.2,79.97],[1,3.15,30.29]],"ltp":0.0,"tv":0.0,"id":16858291}]}]}
{"op":"mcm","clk":"1004371429","pt":1580628203043,"mc":[{"id":"1.168238841","rc":[{"batb":[[0,1.02,2],[1,1.01,1.01],[2,1.01,0]],"ltp":0.0,"tv":0.0,"id":13460817}]}]}
{"op":"mcm","clk":"1004371472","pt":1580628204431,"mc":[{"id":"1.168238841","rc":[{"batb":[[0,1.02,2],[1,1.01,1.01],[2,1.01,0]],"ltp":0.0,"tv":0.0,"id":13460814}]}]}
{"op":"mcm","clk":"1004373664","pt":1580628268222,"mc":[{"id":"1.168238841","rc":[{"batb":[[0,3.25,30.29],[1,1.02,2],[2,1.01,1.01]],"batl":[[0,7.6,286.96]],"ltp":0.0,"tv":0.0,"id":16858291},{"batb":[[0,2.54,30.29],[1,1.02,2],[2,1.01,1.01]],"ltp":0.0,"tv":0.0,"id":13460814}]}]}
{"op":"mcm","clk":"1004373674","pt":1580628268632,"mc":[{"id":"1.168238841","rc":[{"batb":[[0,2.6,98.59],[1,2.54,30.29],[2,1.02,2]],"ltp":0.0,"tv":0.0,"id":13460814}]}]}
{"op":"mcm","clk":"1004378487","pt":1580628390155,"mc":[{"id":"1.168238841","rc":[{"batb":[[0,2.94,87.09],[1,2.84,30.29],[2,1.02,2]],"ltp":0.0,"tv":0.0,"id":16858291},{"batb":[[0,2.62,30.29],[1,2.6,98.59]],"ltp":0.0,"tv":0.0,"id":13460814}]}]}
{"op":"mcm","clk":"1004378511","pt":1580628390467,"mc":[{"id":"1.168238841","rc":[{"batb":[[0,2.76,92.98],[1,2.62,30.29]],"batl":[[0,6.4,273.74]],"ltp":0.0,"tv":0.0,"id":13460814}]}]}
{"op":"mcm","clk":"1004383227","pt":1580628511221,"mc":[{"id":"1.168238841","rc":[{"batb":[[0,2.96,30.29],[1,1.02,2],[2,1.01,1.01]],"ltp":0.0,"tv":0.0,"id":16858291}]}]}
{"op":"mcm","clk":"1004383282","pt":1580628512146,"mc":[{"id":"1.168238841","rc":[{"batb":[[0,2.98,85.9],[1,2.96,30.29],[2,1.02,2]],"ltp":0.0,"tv":0.0,"id":16858291},{"batb":[[0,2.82,91.03],[1,2.78,30.29]],"ltp":0.0,"tv":0.0,"id":13460814}]}]}
{"op":"mcm","clk":"1004387921","pt":1580628634287,"mc":[{"id":"1.168238841","rc":[{"batb":[[0,3.05,84.09],[1,3,30.29]],"ltp":0.0,"tv":0.0,"id":16858291},{"batb":[[0,2.84,30.29],[1,1.02,2],[2,1.01,1.01]],"ltp":0.0,"tv":0.0,"id":13460814}]}]}
{"op":"mcm","clk":"1004387928","pt":1580628634390,"mc":[{"id":"1.168238841","rc":[{"batb":[[0,2.86,89.68],[1,2.84,30.29],[2,1.02,2]],"ltp":0.0,"tv":0.0,"id":13460814}]}]}
{"op":"mcm","clk":"1004393085","pt":1580628755020,"mc":[{"id":"1.168238841","rc":[{"batb":[[0,3.15,81.23],[1,3.1,30.29]],"ltp":0.0,"tv":0.0,"id":16858291},{"batb":[[1,1.02,2],[2,1.01,1.01]],"ltp":0.0,"tv":0.0,"id":13460814}]}]}
{"op":"mcm","clk":"1004393123","pt":1580628755844,"mc":[{"id":"1.168238841","rc":[{"batb":[[0,2.92,87.69],[1,2.88,30.28],[2,1.02,2]],"ltp":0.0,"tv":0.0,"id":13460814}]}]}
{"op":"mcm","clk":"1004397874","pt":1580628876280,"mc":[{"id":"1.168238841","rc":[{"batb":[[0,3.2,30.29],[1,1.02,2],[2,1.01,1.01]],"ltp":0.0,"tv":0.0,"id":16858291}]}]}
{"op":"mcm","clk":"1004397898","pt":1580628877203,"mc":[{"id":"1.168238841","rc":[{"batb":[[0,3.2,110.26]],"ltp":0.0,"tv":0.0,"id":16858291},{"batb":[[0,2.94,30.29],[1,1.02,2],[2,1.01,1.01]],"ltp":0.0,"tv":0.0,"id":13460814}]}]}
{"op":"mcm","clk":"1004397902","pt":1580628877305,"mc":[{"id":"1.168238841","rc":[{"batb":[[0,2.96,86.63],[1,2.94,30.29],[2,1.02,2]],"ltp":0.0,"tv":0.0,"id":13460814}]}]}
{"op":"mcm","clk":"1004402197","pt":1580628998052,"mc":[{"id":"1.168238841","rc":[{"batb":[[0,3.25,30.29]],"ltp":0.0,"tv":0.0,"id":16858291}]}]}
{"op":"mcm","clk":"1004402211","pt":1580628998464,"mc":[{"id":"1.168238841","rc":[{"batb":[[1,1.02,2],[2,1.01,1.01]],"ltp":0.0,"tv":0.0,"id":13460814}]}]}
{"op":"mcm","clk":"1004407098","pt":1580629119759,"mc":[{"id":"1.168238841","rc":[{"batb":[[0,3,85.57],[1,2.84,30.29],[2,1.02,2]],"ltp":0.0,"tv":0.0,"id":16858291}]}]}
{"op":"mcm","clk":"1004412101","pt":1580629241221,"mc":[{"id":"1.168238841","rc":[{"batb":[[0,3.05,30.29],[1,3,85.57]],"ltp":0.0,"tv":0.0,"id":16858291}]}]}
{"op":"mcm","clk":"1004412112","pt":1580629241529,"mc":[{"id":"1.168238841","rc":[{"batb":[[0,3.1,82.54],[1,3.05,30.29]],"ltp":0.0,"tv":0.0,"id":16858291}]}]}
{"op":"mcm","clk":"1004417139","pt":1580629363168,"mc":[{"id":"1.168238841","rc":[{"batb":[[0,3.2,79.97],[1,3.15,30.29]],"ltp":0.0,"tv":0.0,"id":16858291}]}]}
{"op":"mcm","clk":"1004421946","pt":1580629484720,"mc":[{"id":"1.168238841","rc":[{"batb":[[0,3.25,30.29],[1,1.02,2],[2,1.01,1.01]],"ltp":0.0,"tv":0.0,"id":16858291}]}]}
{"op":"mcm","clk":"1004427254","pt":1580629606266,"mc":[{"id":"1.168238841","rc":[{"batb":[[0,2.84,30.29]],"ltp":0.0,"tv":0.0,"id":16858291}]}]}
{"op":"mcm","clk":"1004427277","pt":1580629606778,"mc":[{"id":"1.168238841","rc":[{"batb":[[0,2.96,86.63],[1,2.84,30.29],[2,1.02,2]],"ltp":0.0,"tv":0.0,"id":16858291}]}]}
{"op":"mcm","clk":"1004432738","pt":1580629728263,"mc":[{"id":"1.168238841","rc":[{"batb":[[0,3,85.57],[1,2.98,30.29]],"ltp":0.0,"tv":0.0,"id":16858291}]}]}
{"op":"mcm","clk":"1004438529","pt":1580629849816,"mc":[{"id":"1.168238841","rc":[{"batb":[[0,3.15,81.23],[1,3.05,30.29]],"ltp":0.0,"tv":0.0,"id":16858291}]}]}
{"op":"mcm","clk":"1004443610","pt":1580629972229,"mc":[{"id":"1.168238841","rc":[{"batb":[[0,3.2,30.29],[1,3.15,81.23]],"ltp":0.0,"tv":0.0,"id":16858291}]}]}
{"op":"mcm","clk":"1004443632","pt":1580629972851,"mc":[{"id":"1.168238841","rc":[{"batb":[[0,3.2,110.26],[1,1.02,2],[2,1.01,1.01]],"ltp":0.0,"tv":0.0,"id":16858291}]}]}
{"op":"mcm","clk":"1004448668","pt":1580630094915,"mc":[{"id":"1.168238841","rc":[{"batb":[[0,3.25,30.29]],"ltp":0.0,"tv":0.0,"id":16858291}]}]}
{"op":"mcm","clk":"1004454592","pt":1580630216062,"mc":[{"id":"1.168238841","rc":[{"batb":[[0,3,85.57],[1,2.84,30.29],[2,1.02,2]],"ltp":0.0,"tv":0.0,"id":16858291}]}]}
{"op":"mcm","clk":"1004460345","pt":1580630337238,"mc":[{"id":"1.168238841","rc":[{"batb":[[0,3.05,30.29],[1,3,85.57]],"ltp":0.0,"tv":0.0,"id":16858291}]}]}
{"op":"mcm","clk":"1004460359","pt":1580630337550,"mc":[{"id":"1.168238841","rc":[{"batb":[[0,3.1,82.54],[1,3.05,30.29]],"ltp":0.0,"tv":0.0,"id":16858291}]}]}
{"op":"mcm","clk":"1004463704","pt":1580630406070,"mc":[{"id":"1.168238841","rc":[{"batb":[[0,2.84,90.22],[1,1.02,2],[2,1.01,1.01]],"batl":[[0,12.5,203.81]],"ltp":0.0,"tv":0.0,"id":16858293},{"batb":[[0,2.88,88.96],[1,1.02,2],[2,1.01,1.01]],"batl":[[0,16,161.63]],"ltp":0.0,"tv":0.0,"id":13460817}]}]}
{"op":"mcm","clk":"1004466580","pt":1580630459214,"mc":[{"id":"1.168238841","rc":[{"batb":[[0,3.15,30.29],[1,1.02,2],[2,1.01,1.01]],"ltp":0.0,"tv":0.0,"id":16858291}]}]}
{"op":"mcm","clk":"1004466585","pt":1580630459317,"mc":[{"id":"1.168238841","rc":[{"batb":[[0,3.2,79.97],[1,3.15,30.29],[2,1.02,2]],"ltp":0.0,"tv":0.0,"id":16858291}]}]}
{"op":"mcm","clk":"1004472237","pt":1580630580825,"mc":[{"id":"1.168238841","rc":[{"batb":[[0,3.25,30.29],[1,1.02,2],[2,1.01,1.01]],"ltp":0.0,"tv":0.0,"id":16858291}]}]}
{"op":"mcm","clk":"1004477724","pt":1580630702285,"mc":[{"id":"1.168238841","rc":[{"batb":[[0,2.84,30.29]],"ltp":0.0,"tv":0.0,"id":16858291}]}]}
{"op":"mcm","clk":"1004477756","pt":1580630702831,"mc":[{"id":"1.168238841","rc":[{"batb":[[0,2.88,88.96],[1,2.84,30.29],[2,1.02,2]],"ltp":0.0,"tv":0.0,"id":16858291}]}]}
{"op":"mcm","clk":"1004482848","pt":1580630824220,"mc":[{"id":"1.168238841","rc":[{"batb":[[0,2.9,30.29],[1,1.02,2],[2,1.01,1.01]],"ltp":0.0,"tv":0.0,"id":16858291}]}]}
{"op":"mcm","clk":"1004482852","pt":1580630824323,"mc":[{"id":"1.168238841","rc":[{"batb":[[0,3.1,82.54],[1,2.9,30.29],[2,1.02,2]],"ltp":0.0,"tv":0.0,"id":16858291}]}]}
{"op":"mcm","clk":"1004487731","pt":1580630946132,"mc":[{"id":"1.168238841","rc":[{"batb":[[0,3.2,79.97],[1,3.15,30.29]],"ltp":0.0,"tv":0.0,"id":16858291}]}]}
{"op":"mcm","clk":"1004493621","pt":1580631067225,"mc":[{"id":"1.168238841","rc":[{"batb":[[1,1.02,2],[2,1.01,1.01]],"ltp":0.0,"tv":0.0,"id":16858291}]}]}
{"op":"mcm","clk":"1004493641","pt":1580631067541,"mc":[{"id":"1.168238841","rc":[{"batb":[[0,3.25,30.29]],"ltp":0.0,"tv":0.0,"id":16858291}]}]}
{"op":"mcm","clk":"1004498984","pt":1580631189178,"mc":[{"id":"1.168238841","rc":[{"batb":[[0,2.84,30.29],[1,2.42,106.13],[2,1.02,2]],"ltp":0.0,"tv":0.0,"id":16858291}]}]}
{"op":"mcm","clk":"1004499000","pt":1580631189485,"mc":[{"id":"1.168238841","rc":[{"batb":[[0,2.94,87.09],[1,2.84,30.29]],"ltp":0.0,"tv":0.0,"id":16858291}]}]}
{"op":"mcm","clk":"1004503990","pt":1580631310976,"mc":[{"id":"1.168238841","rc":[{"batb":[[0,3,85.57],[1,2.96,30.29]],"ltp":0.0,"tv":0.0,"id":16858291}]}]}
{"op":"mcm","clk":"1004509323","pt":1580631432712,"mc":[{"id":"1.168238841","rc":[{"batb":[[0,3.1,82.54],[1,3.05,30.29]],"ltp":0.0,"tv":0.0,"id":16858291}]}]}
{"op":"mcm","clk":"1004514370","pt":1580631554280,"mc":[{"id":"1.168238841","rc":[{"batb":[[0,3.2,79.97],[1,3.15,30.29]],"ltp":0.0,"tv":0.0,"id":16858291}]}]}
{"op":"mcm","clk":"1004520147","pt":1580631676603,"mc":[{"id":"1.168238841","rc":[{"batb":[[0,3.25,30.29],[1,1.02,2],[2,1.01,1.01]],"ltp":0.0,"tv":0.0,"id":16858291}]}]}
{"op":"mcm","clk":"1004525110","pt":1580631797949,"mc":[{"id":"1.168238841","rc":[{"batb":[[0,3,85.57],[1,2.84,30.29],[2,1.02,2]],"ltp":0.0,"tv":0.0,"id":16858291}]}]}
{"op":"mcm","clk":"1004528312","pt":1580631869828,"mc":[{"id":"1.168238841","rc":[{"batb":[[0,2.16,119.03]],"ltp":0.0,"tv":0.0,"id":13460814}]}]}
{"op":"mcm","clk":"1004530867","pt":1580631919085,"mc":[{"id":"1.168238841","rc":[{"batb":[[0,3.05,30.29],[1,3,85.57]],"ltp":0.0,"tv":0.0,"id":16858291}]}]}
{"op":"mcm","clk":"1004530897","pt":1580631919802,"mc":[{"id":"1.168238841","rc":[{"batb":[[0,3.15,81.23],[1,3.05,30.29]],"batl":[[0,7.4,294.69]],"ltp":0.0,"tv":0.0,"id":16858291},{"batb":[[0,2.92,87.69],[1,2.54,30.29],[2,1.02,2]],"ltp":0.0,"tv":0.0,"id":13460814}]}]}
{"op":"mcm","clk":"1004536867","pt":1580632041048,"mc":[{"id":"1.168238841","rc":[{"batb":[[0,3.2,110.26],[1,1.02,2],[2,1.01,1.01]],"ltp":0.0,"tv":0.0,"id":16858291}]}]}
{"op":"mcm","clk":"1004536905","pt":1580632041708,"mc":[{"id":"1.168238841","rc":[{"batb":[[0,2.96,86.63],[1,2.94,30.29]],"batl":[[0,6.8,257.67]],"ltp":0.0,"tv":0.0,"id":13460814}]}]}
{"op":"mcm","clk":"1004541525","pt":1580632162995,"mc":[{"id":"1.168238841","rc":[{"batb":[[0,3.25,30.29]],"ltp":0.0,"tv":0.0,"id":16858291},{"batb":[[1,1.02,2],[2,1.01,1.01]],"ltp":0.0,"tv":0.0,"id":13460814}]}]}
{"op":"mcm","clk":"1004546821","pt":1580632284225,"mc":[{"id":"1.168238841","rc":[{"batb":[[0,2.96,86.63],[1,2.86,30.29],[2,1.02,2]],"ltp":0.0,"tv":0.0,"id":16858291}]}]}
{"op":"mcm","clk":"1004552632","pt":1580632407203,"mc":[{"id":"1.168238841","rc":[{"batb":[[0,2.98,30.29],[1,1.02,2],[2,1.01,1.01]],"ltp":0.0,"tv":0.0,"id":16858291}]}]}
{"op":"mcm","clk":"1004552641","pt":1580632407307,"mc":[{"id":"1.168238841","rc":[{"batb":[[0,3.1,82.54],[1,2.98,30.29],[2,1.02,2]],"ltp":0.0,"tv":0.0,"id":16858291}]}]}
{"op":"mcm","clk":"1004557572","pt":1580632528649,"mc":[{"id":"1.168238841","rc":[{"batb":[[0,3.2,79.97],[1,3.15,30.29]],"ltp":0.0,"tv":0.0,"id":16858291}]}]}
{"op":"mcm","clk":"1004562521","pt":1580632650180,"mc":[{"id":"1.168238841","rc":[{"batb":[[0,3.25,30.29],[1,3.2,79.97]],"ltp":0.0,"tv":0.0,"id":16858291}]}]}
{"op":"mcm","clk":"1004562530","pt":1580632650387,"mc":[{"id":"1.168238841","rc":[{"batb":[[1,1.02,2],[2,1.01,1.01]],"ltp":0.0,"tv":0.0,"id":16858291}]}]}
{"op":"mcm","clk":"1004567617","pt":1580632772184,"mc":[{"id":"1.168238841","rc":[{"batb":[[0,2.96,86.63],[1,2.86,30.29],[2,1.02,2]],"ltp":0.0,"tv":0.0,"id":16858291}]}]}
{"op":"mcm","clk":"1004573325","pt":1580632893803,"mc":[{"id":"1.168238841","rc":[{"batb":[[0,3,85.57],[1,2.98,30.29]],"ltp":0.0,"tv":0.0,"id":16858291}]}]}
{"op":"mcm","clk":"1004579904","pt":1580633015274,"mc":[{"id":"1.168238841","rc":[{"batb":[[0,3.05,30.29],[1,1.02,2],[2,1.01,1.01]],"ltp":0.0,"tv":0.0,"id":16858291}]}]}
{"op":"mcm","clk":"1004579909","pt":1580633015378,"mc":[{"id":"1.168238841","rc":[{"batb":[[0,3.1,82.54],[1,3.05,30.29],[2,1.02,2]],"ltp":0.0,"tv":0.0,"id":16858291}]}]}
{"op":"mcm","clk":"1004585650","pt":1580633137288,"mc":[{"id":"1.168238841","rc":[{"batb":[[1,1.02,2],[2,1.01,1.01]],"ltp":0.0,"tv":0.0,"id":16858291}]}]}
{"op":"mcm","clk":"1004585672","pt":1580633137696,"mc":[{"id":"1.168238841","rc":[{"batb":[[0,3.2,79.97],[1,3.15,30.29],[2,1.02,2]],"ltp":0.0,"tv":0.0,"id":16858291}]}]}
{"op":"mcm","clk":"1004591214","pt":1580633258733,"mc":[{"id":"1.168238841","rc":[{"batb":[[0,3.25,30.29],[1,1.02,2],[2,1.01,1.01]],"ltp":0.0,"tv":0.0,"id":16858291}]}]}
{"op":"mcm","clk":"1004592153","pt":1580633283097,"mc":[{"id":"1.168238841","rc":[{"batl":[[0,7.4,34.84]],"ltp":0.0,"tv":0.0,"id":16858291},{"batl":[[0,12.5,20.53]],"ltp":0.0,"tv":0.0,"id":16858293}]}]}
{"op":"mcm","clk":"1004596690","pt":1580633380246,"mc":[{"id":"1.168238841","rc":[{"batb":[[0,2.84,30.29]],"ltp":0.0,"tv":0.0,"id":16858291}]}]}
{"op":"mcm","clk":"1004596728","pt":1580633380814,"mc":[{"id":"1.168238841","rc":[{"batb":[[0,2.96,86.63],[1,2.84,30.29],[2,1.02,2]],"ltp":0.0,"tv":0.0,"id":16858291},{"batb":[[0,2.98,30.29]],"ltp":0.0,"tv":0.0,"id":13460814}]}]}
{"op":"mcm","clk":"1004597914","pt":1580633405963,"mc":[{"id":"1.168238841","rc":[{"batl":[[0,12.5,204.67]],"ltp":0.0,"tv":0.0,"id":16858293}]}]}
{"op":"mcm","clk":"1004598583","pt":1580633419243,"mc":[{"id":"1.168238841","rc":[{"batl":[[0,7.4,284.59]],"ltp":0.0,"tv":0.0,"id":16858291}]}]}
{"op":"mcm","clk":"1004602063","pt":1580633502236,"mc":[{"id":"1.168238841","rc":[{"batb":[[0,3.05,84.09],[1,2.98,30.29]],"ltp":0.0,"tv":0.0,"id":16858291}]}]}
{"op":"mcm","clk":"1004602101","pt":1580633502952,"mc":[{"id":"1.168238841","rc":[{"batb":[[0,2.8,91.48],[1,2.56,30.29],[2,1.02,2]],"ltp":0.0,"tv":0.0,"id":13460814}]}]}
{"op":"mcm","clk":"1004606940","pt":1580633624208,"mc":[{"id":"1.168238841","rc":[{"batb":[[0,3.15,81.23],[1,3.1,30.29]],"ltp":0.0,"tv":0.0,"id":16858291},{"batb":[[0,2.82,30.29],[1,2.8,91.48]],"ltp":0.0,"tv":0.0,"id":13460814}]}]}
{"op":"mcm","clk":"1004606951","pt":1580633624516,"mc":[{"id":"1.168238841","rc":[{"batb":[[0,2.9,88.36],[1,2.82,30.29]],"ltp":0.0,"tv":0.0,"id":13460814}]}]}
{"op":"mcm","clk":"1004612556","pt":1580633745166,"mc":[{"id":"1.168238841","rc":[{"batb":[[0,3.2,30.29],[1,3.15,81.23]],"ltp":0.0,"tv":0.0,"id":16858291}]}]}
{"op":"mcm","clk":"1004612608","pt":1580633746192,"mc":[{"id":"1.168238841","rc":[{"batb":[[0,3.2,110.26],[1,1.02,2],[2,1.01,1.01]],"ltp":0.0,"tv":0.0,"id":16858291},{"batb":[[0,2.94,87.09],[1,2.92,30.29]],"ltp":0.0,"tv":0.0,"id":13460814}]}]}
{"op":"mcm","clk":"1004618998","pt":1580633868223,"mc":[{"id":"1.168238841","rc":[{"batb":[[0,3.25,30.29]],"ltp":0.0,"tv":0.0,"id":16858291},{"batb":[[0,2.96,30.29],[1,2.94,87.09]],"ltp":0.0,"tv":0.0,"id":13460814}]}]}
{"op":"mcm","clk":"1004619018","pt":1580633868531,"mc":[{"id":"1.168238841","rc":[{"batb":[[0,2.96,116.92],[1,1.02,2],[2,1.01,1.01]],"ltp":0.0,"tv":0.0,"id":13460814}]}]}
{"op":"mcm","clk":"1004625722","pt":1580633989120,"mc":[{"id":"1.168238841","rc":[{"batb":[[0,2.98,85.9],[1,2.84,30.29],[2,1.02,2]],"ltp":0.0,"tv":0.0,"id":16858291},{"batb":[[0,2.98,30.29],[1,2.96,86.63],[2,1.02,2]],"ltp":0.0,"tv":0.0,"id":13460814}]}]}
{"op":"mcm","clk":"1004625739","pt":1580633989326,"mc":[{"id":"1.168238841","rc":[{"batb":[[1,1.02,2],[2,1.01,1.01]],"ltp":0.0,"tv":0.0,"id":13460814}]}]}
{"op":"mcm","clk":"1004626818","pt":1580634006215,"mc":[{"id":"1.168238841","rc":[{"batb":[[0,1.02,2],[1,1.01,1.01],[2,1.01,0]],"batl":[[0,15.5,165.07]],"ltp":0.0,"tv":0.0,"id":16858293},{"batb":[[0,1.02,2],[1,1.01,1.01],[2,1.01,0]],"ltp":0.0,"tv":0.0,"id":13460817}]}]}
{"op":"mcm","clk":"1004626831","pt":1580634006418,"mc":[{"id":"1.168238841","rc":[{"batb":[[0,3.85,66.37],[1,1.02,2],[2,1.01,1.01]],"ltp":0.0,"tv":0.0,"id":16858293}]}]}
{"op":"mcm","clk":"1004633167","pt":1580634110288,"mc":[{"id":"1.168238841","rc":[{"batb":[[0,3,30.29],[1,2.98,85.9]],"ltp":0.0,"tv":0.0,"id":16858291}]}]}
{"op":"mcm","clk":"1004633213","pt":1580634111263,"mc":[{"id":"1.168238841","rc":[{"batb":[[0,3.1,82.54],[1,3,30.29]],"ltp":0.0,"tv":0.0,"id":16858291},{"batb":[[0,2.56,30.29]],"ltp":0.0,"tv":0.0,"id":13460814}]}]}
{"op":"mcm","clk":"1004633220","pt":1580634111366,"mc":[{"id":"1.168238841","rc":[{"batb":[[0,2.72,94.34],[1,2.56,30.29],[2,1.02,2]],"ltp":0.0,"tv":0.0,"id":13460814}]}]}
{"op":"mcm","clk":"1004638820","pt":1580634232248,"mc":[{"id":"1.168238841","rc":[{"batb":[[0,3.15,30.29],[1,1.02,2],[2,1.01,1.01]],"ltp":0.0,"tv":0.0,"id":16858291}]}]}
{"op":"mcm","clk":"1004638859","pt":1580634232963,"mc":[{"id":"1.168238841","rc":[{"batb":[[0,3.2,79.97],[1,3.15,30.29],[2,1.02,2]],"ltp":0.0,"tv":0.0,"id":16858291},{"batb":[[0,2.92,87.69],[1,2.74,30.29]],"ltp":0.0,"tv":0.0,"id":13460814}]}]}
{"op":"mcm","clk":"1004644475","pt":1580634354196,"mc":[{"id":"1.168238841","rc":[{"batb":[[0,3.25,30.29],[1,1.02,2],[2,1.01,1.01]],"ltp":0.0,"tv":0.0,"id":16858291},{"batb":[[1,1.02,2],[2,1.01,1.01]],"ltp":0.0,"tv":0.0,"id":13460814}]}]}
{"op":"mcm","clk":"1004644500","pt":1580634354718,"mc":[{"id":"1.168238841","rc":[{"batb":[[0,2.96,86.63],[1,2.94,30.29],[2,1.02,2]],"ltp":0.0,"tv":0.0,"id":13460814}]}]}
{"op":"mcm","clk":"1004650633","pt":1580634478256,"mc":[{"id":"1.168238841","rc":[{"batb":[[0,2.84,30.29],[1,2.54,101.12],[2,1.02,2]],"ltp":0.0,"tv":0.0,"id":16858291}]}]}
{"op":"mcm","clk":"1004650670","pt":1580634478869,"mc":[{"id":"1.168238841","rc":[{"batb":[[0,2.9,88.36],[1,2.84,30.29]],"ltp":0.0,"tv":0.0,"id":16858291},{"batb":[[0,2.98,30.29],[1,1.02,2],[2,1.01,1.01]],"ltp":0.0,"tv":0.0,"id":13460814}]}]}
{"op":"mcm","clk":"1004655883","pt":1580634599244,"mc":[{"id":"1.168238841","rc":[{"batb":[[0,2.94,87.09],[1,2.92,30.29]],"ltp":0.0,"tv":0.0,"id":16858291}]}]}
{"op":"mcm","clk":"1004655923","pt":1580634600171,"mc":[{"id":"1.168238841","rc":[{"batb":[[0,2.76,92.98],[1,2.56,30.29],[2,1.02,2]],"ltp":0.0,"tv":0.0,"id":13460814}]}]}
{"op":"mcm","clk":"1004661594","pt":1580634721235,"mc":[{"id":"1.168238841","rc":[{"batb":[[0,2.98,85.9],[1,2.96,30.29]],"ltp":0.0,"tv":0.0,"id":16858291},{"batb":[[0,2.78,30.29],[1,2.76,92.98]],"ltp":0.0,"tv":0.0,"id":13460814}]}]}
{"op":"mcm","clk":"1004661609","pt":1580634721391,"mc":[{"id":"1.168238841","rc":[{"batb":[[0,2.8,91.48],[1,2.78,30.29]],"ltp":0.0,"tv":0.0,"id":13460814}]}]}
{"op":"mcm","clk":"1004667852","pt":1580634842256,"mc":[{"id":"1.168238841","rc":[{"batb":[[1,1.02,2],[2,1.01,1.01]],"ltp":0.0,"tv":0.0,"id":16858291}]}]}
{"op":"mcm","clk":"1004667903","pt":1580634843030,"mc":[{"id":"1.168238841","rc":[{"batb":[[0,3.05,84.09],[1,3,30.29],[2,1.02,2]],"ltp":0.0,"tv":0.0,"id":16858291},{"batb":[[0,2.82,30.29],[1,2.8,91.48]],"ltp":0.0,"tv":0.0,"id":13460814}]}]}
{"op":"mcm","clk":"1004667926","pt":1580634843444,"mc":[{"id":"1.168238841","rc":[{"batb":[[0,2.9,88.36],[1,2.82,30.29]],"ltp":0.0,"tv":0.0,"id":13460814}]}]}
{"op":"mcm","clk":"1004674347","pt":1580634964231,"mc":[{"id":"1.168238841","rc":[{"batb":[[0,3.15,81.23],[1,3.1,30.29]],"ltp":0.0,"tv":0.0,"id":16858291}]}]}
{"op":"mcm","clk":"1004674383","pt":1580634964896,"mc":[{"id":"1.168238841","rc":[{"batb":[[0,2.94,87.09],[1,2.92,30.29]],"ltp":0.0,"tv":0.0,"id":13460814}]}]}
{"op":"mcm","clk":"1004680669","pt":1580635086193,"mc":[{"id":"1.168238841","rc":[{"batb":[[0,3.2,110.26],[1,1.02,2],[2,1.01,1.01]],"ltp":0.0,"tv":0.0,"id":16858291},{"batb":[[1,1.02,2],[2,1.01,1.01]],"ltp":0.0,"tv":0.0,"id":13460814}]}]}
{"op":"mcm","clk":"1004680702","pt":1580635086565,"mc":[{"id":"1.168238841","rc":[{"batb":[[0,2.96,116.92]],"ltp":0.0,"tv":0.0,"id":13460814}]}]}
{"op":"mcm","clk":"1004686876","pt":1580635207193,"mc":[{"id":"1.168238841","rc":[{"batb":[[0,3.2,79.97]],"ltp":0.0,"tv":0.0,"id":16858291}]}]}
{"op":"mcm","clk":"1004686887","pt":1580635207400,"mc":[{"id":"1.168238841","rc":[{"batb":[[0,3.25,30.29]],"ltp":0.0,"tv":0.0,"id":16858291}]}]}
{"op":"mcm","clk":"1004686945","pt":1580635208893,"mc":[{"id":"1.168238841","rc":[{"batb":[[0,2.98,30.29]],"ltp":0.0,"tv":0.0,"id":13460814}]}]}
{"op":"mcm","clk":"1004692461","pt":1580635329148,"mc":[{"id":"1.168238841","rc":[{"batb":[[0,2.84,30.29]],"ltp":0.0,"tv":0.0,"id":16858291}]}]}
{"op":"mcm","clk":"1004692503","pt":1580635330240,"mc":[{"id":"1.168238841","rc":[{"batb":[[0,2.92,87.69],[1,2.84,30.29],[2,1.02,2]],"ltp":0.0,"tv":0.0,"id":16858291},{"batb":[[0,2.56,30.29]],"ltp":0.0,"tv":0.0,"id":13460814}]}]}
{"op":"mcm","clk":"1004692507","pt":1580635330339,"mc":[{"id":"1.168238841","rc":[{"batb":[[0,2.84,90.22],[1,2.56,30.29],[2,1.02,2]],"ltp":0.0,"tv":0.0,"id":13460814}]}]}
{"op":"mcm","clk":"1004697029","pt":1580635451004,"mc":[{"id":"1.168238841","rc":[{"batb":[[0,2.96,86.63],[1,2.94,30.29]],"ltp":0.0,"tv":0.0,"id":16858291}]}]}
{"op":"mcm","clk":"1004697065","pt":1580635451828,"mc":[{"id":"1.168238841","rc":[{"batb":[[0,2.88,88.96],[1,2.86,30.29]],"ltp":0.0,"tv":0.0,"id":13460814}]}]}
{"op":"mcm","clk":"1004702208","pt":1580635572290,"mc":[{"id":"1.168238841","rc":[{"batb":[[1,1.02,2],[2,1.01,1.01]],"ltp":0.0,"tv":0.0,"id":16858291}]}]}
{"op":"mcm","clk":"1004702254","pt":1580635573272,"mc":[{"id":"1.168238841","rc":[{"batb":[[0,3,85.57],[1,2.98,30.29],[2,1.02,2]],"ltp":0.0,"tv":0.0,"id":16858291},{"batb":[[0,2.92,87.69],[1,2.9,30.29]],"ltp":0.0,"tv":0.0,"id":13460814}]}]}
{"op":"mcm","clk":"1004707714","pt":1580635694135,"mc":[{"id":"1.168238841","rc":[{"batb":[[0,3.15,81.23],[1,3.05,30.29]],"ltp":0.0,"tv":0.0,"id":16858291}]}]}
{"op":"mcm","clk":"1004707745","pt":1580635694908,"mc":[{"id":"1.168238841","rc":[{"batb":[[0,2.96,86.63],[1,2.94,30.29]],"batl":[[0,5.6,312.97]],"ltp":0.0,"tv":0.0,"id":13460814}]}]}
{"op":"mcm","clk":"1004712725","pt":1580635816281,"mc":[{"id":"1.168238841","rc":[{"batb":[[0,3.2,110.26],[1,1.02,2],[2,1.01,1.01]],"ltp":0.0,"tv":0.0,"id":16858291},{"batb":[[0,2.98,30.29],[1,2.96,86.63]],"ltp":0.0,"tv":0.0,"id":13460814}]}]}
{"op":"mcm","clk":"1004712732","pt":1580635816485,"mc":[{"id":"1.168238841","rc":[{"batb":[[1,1.02,2],[2,1.01,1.01]],"ltp":0.0,"tv":0.0,"id":13460814}]}]}
{"op":"mcm","clk":"1004717656","pt":1580635937284,"mc":[{"id":"1.168238841","rc":[{"batb":[[0,3.25,30.29],[1,3.2,79.97],[2,1.02,2]],"ltp":0.0,"tv":0.0,"id":16858291}]}]}
{"op":"mcm","clk":"1004717697","pt":1580635938107,"mc":[{"id":"1.168238841","rc":[{"batb":[[1,1.02,2],[2,1.01,1.01]],"ltp":0.0,"tv":0.0,"id":16858291},{"batb":[[0,2.56,30.29],[1,2.16,119.03],[2,1.02,2]],"ltp":0.0,"tv":0.0,"id":13460814}]}]}
{"op":"mcm","clk":"1004717713","pt":1580635938529,"mc":[{"id":"1.168238841","rc":[{"batb":[[0,2.58,99.56],[1,2.56,30.29]],"ltp":0.0,"tv":0.0,"id":13460814}]}]}
{"op":"mcm","clk":"1004723127","pt":1580636060192,"mc":[{"id":"1.168238841","rc":[{"batb":[[0,2.92,87.69],[1,2.84,30.29],[2,1.02,2]],"ltp":0.0,"tv":0.0,"id":16858291},{"batb":[[1,1.02,2],[2,1.01,1.01]],"ltp":0.0,"tv":0.0,"id":13460814}]}]}
{"op":"mcm","clk":"1004723150","pt":1580636060756,"mc":[{"id":"1.168238841","rc":[{"batb":[[0,2.66,96.34],[1,2.6,30.29],[2,1.02,2]],"ltp":0.0,"tv":0.0,"id":13460814}]}]}
{"op":"mcm","clk":"1004728162","pt":1580636180982,"mc":[{"id":"1.168238841","rc":[{"batb":[[0,3,85.57],[1,2.94,30.29]],"ltp":0.0,"tv":0.0,"id":16858291}]}]}
{"op":"mcm","clk":"1004728194","pt":1580636181655,"mc":[{"id":"1.168238841","rc":[{"batb":[[0,2.84,90.22],[1,2.68,30.29]],"ltp":0.0,"tv":0.0,"id":13460814}]}]}
{"op":"mcm","clk":"1004733146","pt":1580636303275,"mc":[{"id":"1.168238841","rc":[{"batb":[[0,3.1,82.54],[1,3.05,30.29]],"ltp":0.0,"tv":0.0,"id":16858291},{"batb":[[0,2.86,30.29],[1,2.84,90.22]],"ltp":0.0,"tv":0.0,"id":13460814}]}]}
{"op":"mcm","clk":"1004733161","pt":1580636303583,"mc":[{"id":"1.168238841","rc":[{"batb":[[0,2.88,88.96],[1,2.86,30.29]],"ltp":0.0,"tv":0.0,"id":13460814}]}]}
{"op":"mcm","clk":"1004738823","pt":1580636424097,"mc":[{"id":"1.168238841","rc":[{"batb":[[0,3.15,30.29],[1,3.1,82.54]],"ltp":0.0,"tv":0.0,"id":16858291}]}]}
{"op":"mcm","clk":"1004738905","pt":1580636425132,"mc":[{"id":"1.168238841","rc":[{"batb":[[0,3.2,79.97],[1,3.15,30.29]],"ltp":0.0,"tv":0.0,"id":16858291},{"batb":[[0,2.94,87.09],[1,2.9,30.29]],"ltp":0.0,"tv":0.0,"id":13460814}]}]}
{"op":"mcm","clk":"1004745852","pt":1580636546001,"mc":[{"id":"1.168238841","rc":[{"batb":[[0,3.25,30.29],[1,1.02,2],[2,1.01,1.01]],"ltp":0.0,"tv":0.0,"id":16858291}]}]}
{"op":"mcm","clk":"1004745892","pt":1580636546675,"mc":[{"id":"1.168238841","rc":[{"batb":[[0,2.96,116.92],[1,1.02,2],[2,1.01,1.01]],"ltp":0.0,"tv":0.0,"id":13460814}]}]}
{"op":"mcm","clk":"1004751456","pt":1580636667280,"mc":[{"id":"1.168238841","rc":[{"batb":[[0,1.02,2],[1,1.01,1.01],[2,1.01,0]],"ltp":0.0,"tv":0.0,"id":16858291}]}]}
{"op":"mcm","clk":"1004751487","pt":1580636668101,"mc":[{"id":"1.168238841","rc":[{"batb":[[0,2.92,87.69],[1,2.84,30.29],[2,1.02,2]],"ltp":0.0,"tv":0.0,"id":16858291},{"batb":[[0,2.98,30.29],[1,2.96,86.63],[2,1.02,2]],"ltp":0.0,"tv":0.0,"id":13460814}]}]}
{"op":"mcm","clk":"1004751496","pt":1580636668308,"mc":[{"id":"1.168238841","rc":[{"batb":[[1,1.02,2],[2,1.01,1.01]],"ltp":0.0,"tv":0.0,"id":13460814}]}]}
{"op":"mcm","clk":"1004756995","pt":1580636790257,"mc":[{"id":"1.168238841","rc":[{"batb":[[0,3,85.57],[1,2.94,30.29]],"ltp":0.0,"tv":0.0,"id":16858291}]}]}
{"op":"mcm","clk":"1004757048","pt":1580636791242,"mc":[{"id":"1.168238841","rc":[{"batb":[[0,2.7,94.92],[1,2.56,30.29],[2,1.02,2]],"ltp":0.0,"tv":0.0,"id":13460814}]}]}
{"op":"mcm","clk":"1004762855","pt":1580636911158,"mc":[{"id":"1.168238841","rc":[{"batb":[[0,3.1,82.54],[1,3.05,30.29]],"ltp":0.0,"tv":0.0,"id":16858291}]}]}
{"op":"mcm","clk":"1004762882","pt":1580636911673,"mc":[{"id":"1.168238841","rc":[{"batb":[[0,2.8,91.48],[1,2.72,30.29]],"ltp":0.0,"tv":0.0,"id":13460814}]}]}
{"op":"mcm","clk":"1004769775","pt":1580637033266,"mc":[{"id":"1.168238841","rc":[{"batb":[[0,3.2,79.97],[1,3.15,30.29]],"ltp":0.0,"tv":0.0,"id":16858291},{"batb":[[0,2.82,30.29],[1,1.02,2],[2,1.01,1.01]],"ltp":0.0,"tv":0.0,"id":13460814}]}]}
{"op":"mcm","clk":"1004769782","pt":1580637033364,"mc":[{"id":"1.168238841","rc":[{"batb":[[0,2.88,88.96],[1,2.82,30.29],[2,1.02,2]],"ltp":0.0,"tv":0.0,"id":13460814}]}]}
{"op":"mcm","clk":"1004776405","pt":1580637155069,"mc":[{"id":"1.168238841","rc":[{"batb":[[0,3.25,30.29],[1,3.2,79.97]],"ltp":0.0,"tv":0.0,"id":16858291}]}]}
{"op":"mcm","clk":"1004776443","pt":1580637155784,"mc":[{"id":"1.168238841","rc":[{"batb":[[1,1.02,2],[2,1.01,1.01]],"ltp":0.0,"tv":0.0,"id":16858291},{"batb":[[0,2.9,30.29],[1,2.88,88.96]],"ltp":0.0,"tv":0.0,"id":13460814}]}]}
{"op":"mcm","clk":"1004776637","pt":1580637159286,"mc":[{"id":"1.168238841","rc":[{"batb":[[1,1.02,2],[2,1.01,1.01]],"ltp":0.0,"tv":0.0,"id":13460814}]}]}
{"op":"mcm","clk":"1004776651","pt":1580637159443,"mc":[{"id":"1.168238841","rc":[{"batb":[[0,2.92,87.69],[1,2.9,30.29],[2,1.02,2]],"ltp":0.0,"tv":0.0,"id":13460814}]}]}
{"op":"mcm","clk":"1004782522","pt":1580637277253,"mc":[{"id":"1.168238841","rc":[{"batb":[[0,2.84,30.29]],"ltp":0.0,"tv":0.0,"id":16858291}]}]}
{"op":"mcm","clk":"1004782550","pt":1580637277764,"mc":[{"id":"1.168238841","rc":[{"batb":[[0,2.96,86.63],[1,2.84,30.29],[2,1.02,2]],"ltp":0.0,"tv":0.0,"id":16858291},{"batb":[[0,2.96,86.63],[1,2.94,30.29]],"ltp":0.0,"tv":0.0,"id":13460814}]}]}
{"op":"mcm","clk":"1004789030","pt":1580637399162,"mc":[{"id":"1.168238841","rc":[{"batb":[[0,3,85.57],[1,2.98,30.29]],"ltp":0.0,"tv":0.0,"id":16858291},{"batb":[[0,2.98,30.29],[1,2.96,86.63]],"ltp":0.0,"tv":0.0,"id":13460814}]}]}
{"op":"mcm","clk":"1004789042","pt":1580637399369,"mc":[{"id":"1.168238841","rc":[{"batb":[[1,1.02,2],[2,1.01,1.01]],"ltp":0.0,"tv":0.0,"id":13460814}]}]}
{"op":"mcm","clk":"1004796107","pt":1580637521251,"mc":[{"id":"1.168238841","rc":[{"batb":[[0,3.1,82.54],[1,3.05,30.29]],"ltp":0.0,"tv":0.0,"id":16858291}]}]}
{"op":"mcm","clk":"1004796152","pt":1580637522074,"mc":[{"id":"1.168238841","rc":[{"batb":[[0,2.66,96.34],[1,2.56,30.29],[2,1.02,2]],"ltp":0.0,"tv":0.0,"id":13460814}]}]}
{"op":"mcm","clk":"1004801442","pt":1580637606812,"mc":[{"id":"1.168238841","rc":[{"batb":[[0,2.94,87.09]],"batl":[[0,7.6,336.46]],"ltp":0.0,"tv":0.0,"id":16858293}]}]}
{"op":"mcm","clk":"1004803912","pt":1580637642175,"mc":[{"id":"1.168238841","rc":[{"batb":[[0,3.2,79.97],[1,3.15,30.29]],"ltp":0.0,"tv":0.0,"id":16858291}]}]}
{"op":"mcm","clk":"1004803965","pt":1580637642956,"mc":[{"id":"1.168238841","rc":[{"batb":[[0,2.8,91.48],[1,2.68,30.29]],"ltp":0.0,"tv":0.0,"id":13460814}]}]}
{"op":"mcm","clk":"1004813383","pt":1580637763283,"mc":[{"id":"1.168238841","rc":[{"batb":[[1,1.02,2],[2,1.01,1.01]],"ltp":0.0,"tv":0.0,"id":16858291}]}]}
{"op":"mcm","clk":"1004813454","pt":1580637764278,"mc":[{"id":"1.168238841","rc":[{"batb":[[0,3.25,30.29]],"ltp":0.0,"tv":0.0,"id":16858291},{"batb":[[0,2.84,90.22],[1,2.82,30.29]],"ltp":0.0,"tv":0.0,"id":13460814}]}]}
{"op":"mcm","clk":"1004821368","pt":1580637885210,"mc":[{"id":"1.168238841","rc":[{"batb":[[0,2.84,30.29]],"ltp":0.0,"tv":0.0,"id":16858291}]}]}
{"op":"mcm","clk":"1004821435","pt":1580637886237,"mc":[{"id":"1.168238841","rc":[{"batb":[[0,2.94,87.09],[1,2.84,30.29],[2,1.02,2]],"ltp":0.0,"tv":0.0,"id":16858291},{"batb":[[0,2.92,87.69],[1,2.86,30.29]],"ltp":0.0,"tv":0.0,"id":13460814}]}]}
{"op":"mcm","clk":"1004829126","pt":1580638007119,"mc":[{"id":"1.168238841","rc":[{"batb":[[0,2.96,30.29],[1,1.02,2],[2,1.01,1.01]],"ltp":0.0,"tv":0.0,"id":16858291}]}]}
{"op":"mcm","clk":"1004829185","pt":1580638007899,"mc":[{"id":"1.168238841","rc":[{"batb":[[0,3,85.57],[1,2.96,30.29],[2,1.02,2]],"ltp":0.0,"tv":0.0,"id":16858291},{"batb":[[0,2.96,86.63],[1,2.94,30.29]],"ltp":0.0,"tv":0.0,"id":13460814}]}]}
{"op":"mcm","clk":"1004837181","pt":1580638129228,"mc":[{"id":"1.168238841","rc":[{"batb":[[0,3.1,82.54],[1,3.05,30.29]],"ltp":0.0,"tv":0.0,"id":16858291},{"batb":[[0,2.98,30.29],[1,2.96,86.63]],"ltp":0.0,"tv":0.0,"id":13460814}]}]}
{"op":"mcm","clk":"1004837206","pt":1580638129535,"mc":[{"id":"1.168238841","rc":[{"batb":[[1,1.02,2],[2,1.01,1.01]],"ltp":0.0,"tv":0.0,"id":13460814}]}]}
{"op":"mcm","clk":"1004845762","pt":1580638251192,"mc":[{"id":"1.168238841","rc":[{"batb":[[0,3.15,30.29],[1,1.02,2],[2,1.01,1.01]],"ltp":0.0,"tv":0.0,"id":16858291}]}]}
{"op":"mcm","clk":"1004845842","pt":1580638252074,"mc":[{"id":"1.168238841","rc":[{"batb":[[0,3.2,79.97],[1,3.15,30.29],[2,1.02,2]],"ltp":0.0,"tv":0.0,"id":16858291},{"batb":[[0,2.68,95.61],[1,2.56,30.29],[2,1.02,2]],"ltp":0.0,"tv":0.0,"id":13460814}]}]}
{"op":"mcm","clk":"1004855118","pt":1580638372126,"mc":[{"id":"1.168238841","rc":[{"batb":[[0,3.25,30.29],[1,1.02,2],[2,1.01,1.01]],"ltp":0.0,"tv":0.0,"id":16858291}]}]}
{"op":"mcm","clk":"1004855218","pt":1580638373270,"mc":[{"id":"1.168238841","rc":[{"batb":[[0,2.88,88.96],[1,2.7,30.28]],"ltp":0.0,"tv":0.0,"id":13460814}]}]}
{"op":"mcm","clk":"1004864971","pt":1580638494072,"mc":[{"id":"1.168238841","rc":[{"batb":[[0,2.98,85.9],[1,2.84,30.29],[2,1.02,2]],"ltp":0.0,"tv":0.0,"id":16858291},{"batb":[[1,1.02,2],[2,1.01,1.01]],"ltp":0.0,"tv":0.0,"id":13460814}]}]}
{"op":"mcm","clk":"1004865042","pt":1580638494917,"mc":[{"id":"1.168238841","rc":[{"batb":[[0,2.92,87.69],[1,2.9,30.29],[2,1.02,2]],"ltp":0.0,"tv":0.0,"id":13460814}]}]}
{"op":"mcm","clk":"1004874509","pt":1580638615125,"mc":[{"id":"1.168238841","rc":[{"batb":[[0,3,30.29],[1,2.98,85.9]],"ltp":0.0,"tv":0.0,"id":16858291}]}]}
{"op":"mcm","clk":"1004874583","pt":1580638616014,"mc":[{"id":"1.168238841","rc":[{"batb":[[0,3.1,82.54],[1,3,30.29]],"ltp":0.0,"tv":0.0,"id":16858291},{"batb":[[0,2.96,86.63],[1,2.94,30.29]],"ltp":0.0,"tv":0.0,"id":13460814}]}]}
{"op":"mcm","clk":"1004884064","pt":1580638737170,"mc":[{"id":"1.168238841","rc":[{"batb":[[0,3.2,79.97],[1,3.15,30.29]],"ltp":0.0,"tv":0.0,"id":16858291}]}]}
{"op":"mcm","clk":"1004884117","pt":1580638737791,"mc":[{"id":"1.168238841","rc":[{"batb":[[0,2.98,30.29],[1,1.02,2],[2,1.01,1.01]],"ltp":0.0,"tv":0.0,"id":13460814}]}]}
{"op":"mcm","clk":"1004894081","pt":1580638859132,"mc":[{"id":"1.168238841","rc":[{"batb":[[0,3.25,30.29],[1,1.02,2],[2,1.01,1.01]],"ltp":0.0,"tv":0.0,"id":16858291},{"batb":[[0,2.56,30.29]],"ltp":0.0,"tv":0.0,"id":13460814}]}]}
{"op":"mcm","clk":"1004894126","pt":1580638859548,"mc":[{"id":"1.168238841","rc":[{"batb":[[0,2.64,97.32],[1,2.56,30.29],[2,1.02,2]],"ltp":0.0,"tv":0.0,"id":13460814}]}]}
{"op":"mcm","clk":"1004904241","pt":1580638980237,"mc":[{"id":"1.168238841","rc":[{"batb":[[0,2.84,30.29]],"ltp":0.0,"tv":0.0,"id":16858291}]}]}
{"op":"mcm","clk":"1004904280","pt":1580638980711,"mc":[{"id":"1.168238841","rc":[{"batb":[[0,2.96,86.63],[1,2.84,30.29],[2,1.02,2]],"ltp":0.0,"tv":0.0,"id":16858291}]}]}
{"op":"mcm","clk":"1004904418","pt":1580638982232,"mc":[{"id":"1.168238841","rc":[{"batb":[[0,2.84,90.22],[1,2.66,30.29]],"ltp":0.0,"tv":0.0,"id":13460814}]}]}
{"op":"mcm","clk":"1004917310","pt":1580639102255,"mc":[{"id":"1.168238841","rc":[{"batb":[[0,2.98,30.29],[1,1.02,2],[2,1.01,1.01]],"ltp":0.0,"tv":0.0,"id":16858291}]}]}
{"op":"mcm","clk":"1004917402","pt":1580639103143,"mc":[{"id":"1.168238841","rc":[{"batb":[[0,3.15,81.23],[1,2.98,30.29],[2,1.02,2]],"ltp":0.0,"tv":0.0,"id":16858291},{"batb":[[0,2.88,88.96],[1,2.86,30.29]],"ltp":0.0,"tv":0.0,"id":13460814}]}]}
{"op":"mcm","clk":"1004919187","pt":1580639122583,"mc":[{"id":"1.168238841","rc":[{"batl":[[0,7.8,270.02]],"ltp":0.0,"tv":0.0,"id":16858291}]}]}
{"op":"mcm","clk":"1004930211","pt":1580639223932,"mc":[{"id":"1.168238841","rc":[{"batb":[[0,3.2,110.26],[1,1.02,2],[2,1.01,1.01]],"ltp":0.0,"tv":0.0,"id":16858291}]}]}
{"op":"mcm","clk":"1004930297","pt":1580639224715,"mc":[{"id":"1.168238841","rc":[{"batb":[[0,2.94,87.09],[1,2.9,30.29]],"ltp":0.0,"tv":0.0,"id":13460814}]}]}
{"op":"mcm","clk":"1004937969","pt":1580639295101,"mc":[{"id":"1.168238841","rc":[{"batl":[[0,6.8,257.67]],"ltp":0.0,"tv":0.0,"id":13460814}]}]}
{"op":"mcm","clk":"1004943016","pt":1580639345186,"mc":[{"id":"1.168238841","rc":[{"batb":[[0,3.25,30.29],[1,3.2,79.97],[2,1.02,2]],"ltp":0.0,"tv":0.0,"id":16858291}]}]}
{"op":"mcm","clk":"1004943138","pt":1580639346188,"mc":[{"id":"1.168238841","rc":[{"batb":[[1,1.02,2],[2,1.01,1.01]],"ltp":0.0,"tv":0.0,"id":16858291},{"batb":[[0,2.96,116.92],[1,1.02,2],[2,1.01,1.01]],"ltp":0.0,"tv":0.0,"id":13460814}]}]}
{"op":"mcm","clk":"1004955422","pt":1580639467267,"mc":[{"id":"1.168238841","rc":[{"batb":[[0,2.88,88.96],[1,2.84,30.29],[2,1.02,2]],"ltp":0.0,"tv":0.0,"id":16858291}]}]}
{"op":"mcm","clk":"1004955468","pt":1580639467684,"mc":[{"id":"1.168238841","rc":[{"batb":[[0,2.98,30.29]],"ltp":0.0,"tv":0.0,"id":13460814}]}]}
{"op":"mcm","clk":"1004968049","pt":1580639590025,"mc":[{"id":"1.168238841","rc":[{"batb":[[0,3.1,82.54],[1,2.9,30.29]],"ltp":0.0,"tv":0.0,"id":16858291}]}]}
{"op":"mcm","clk":"1004968141","pt":1580639590977,"mc":[{"id":"1.168238841","rc":[{"batb":[[0,2.66,96.34],[1,2.56,30.29],[2,1.02,2]],"ltp":0.0,"tv":0.0,"id":13460814}]}]}
{"op":"mcm","clk":"1004978741","pt":1580639711238,"mc":[{"id":"1.168238841","rc":[{"batb":[[0,3.15,30.29],[1,3.1,82.54]],"ltp":0.0,"tv":0.0,"id":16858291}]}]}
{"op":"mcm","clk":"1004978841","pt":1580639712127,"mc":[{"id":"1.168238841","rc":[{"batb":[[0,3.2,79.97],[1,3.15,30.29]],"ltp":0.0,"tv":0.0,"id":16858291},{"batb":[[0,2.68,30.29],[1,2.66,96.34]],"ltp":0.0,"tv":0.0,"id":13460814}]}]}
{"op":"mcm","clk":"1004978891","pt":1580639712548,"mc":[{"id":"1.168238841","rc":[{"batb":[[0,2.88,88.96],[1,2.68,30.29]],"ltp":0.0,"tv":0.0,"id":13460814}]}]}
{"op":"mcm","clk":"1004990718","pt":1580639833277,"mc":[{"id":"1.168238841","rc":[{"batb":[[0,3.25,30.29],[1,1.02,2],[2,1.01,1.01]],"ltp":0.0,"tv":0.0,"id":16858291}]}]}
{"op":"mcm","clk":"1004990781","pt":1580639834003,"mc":[{"id":"1.168238841","rc":[{"batb":[[0,2.92,87.69],[1,2.9,30.29]],"ltp":0.0,"tv":0.0,"id":13460814}]}]}
{"op":"mcm","clk":"1005002338","pt":1580639955185,"mc":[{"id":"1.168238841","rc":[{"batb":[[0,2.92,87.69],[1,2.84,30.29],[2,1.02,2]],"ltp":0.0,"tv":0.0,"id":16858291},{"batb":[[0,2.94,30.29],[1,2.92,87.69]],"ltp":0.0,"tv":0.0,"id":13460814}]}]}
{"op":"mcm","clk":"1005002379","pt":1580639955604,"mc":[{"id":"1.168238841","rc":[{"batb":[[0,2.96,86.63],[1,2.94,30.29]],"ltp":0.0,"tv":0.0,"id":13460814}]}]}
{"op":"mcm","clk":"1005013641","pt":1580640076272,"mc":[{"id":"1.168238841","rc":[{"batb":[[0,2.94,30.29],[1,2.92,87.69]],"ltp":0.0,"tv":0.0,"id":16858291}]}]}
{"op":"mcm","clk":"1005013717","pt":1580640077058,"mc":[{"id":"1.168238841","rc":[{"batb":[[0,2.98,85.9],[1,2.94,30.29]],"ltp":0.0,"tv":0.0,"id":16858291},{"batb":[[0,2.98,30.29],[1,1.02,2],[2,1.01,1.01]],"ltp":0.0,"tv":0.0,"id":13460814}]}]}
{"op":"mcm","clk":"1005028471","pt":1580640198215,"mc":[{"id":"1.168238841","rc":[{"batb":[[0,3,30.29],[1,1.02,2],[2,1.01,1.01]],"ltp":0.0,"tv":0.0,"id":16858291}]}]}
{"op":"mcm","clk":"1005028681","pt":1580640199182,"mc":[{"id":"1.168238841","rc":[{"batb":[[0,3.1,82.54],[1,3,30.29],[2,1.02,2]],"ltp":0.0,"tv":0.0,"id":16858291},{"batb":[[0,2.56,30.29]],"ltp":0.0,"tv":0.0,"id":13460814}]}]}
{"op":"mcm","clk":"1005028711","pt":1580640199353,"mc":[{"id":"1.168238841","rc":[{"batb":[[0,2.6,98.59],[1,2.56,30.29],[2,1.02,2]],"ltp":0.0,"tv":0.0,"id":13460814}]}]}
{"op":"mcm","clk":"1005157490","pt":1580641207138,"mc":[{"id":"1.168238841","rc":[{"batb":[[0,2.84,90.22]],"ltp":0.0,"tv":0.0,"id":16858293}]}]}
{"op":"mcm","clk":"1005157530","pt":1580641207352,"mc":[{"id":"1.168238841","rc":[{"batl":[[0,14,183]],"ltp":0.0,"tv":0.0,"id":16858293}]}]}
{"op":"mcm","clk":"1005172843","pt":1580641294181,"mc":[{"id":"1.168238841","rc":[{"batb":[[0,3.2,79.97],[1,3.15,30.29]],"ltp":0.0,"tv":0.0,"id":16858291}]}]}
{"op":"mcm","clk":"1005172927","pt":1580641294702,"mc":[{"id":"1.168238841","rc":[{"batb":[[0,2.7,94.92],[1,2.62,30.29]],"ltp":0.0,"tv":0.0,"id":13460814}]}]}
{"op":"mcm","clk":"1005195979","pt":1580641415264,"mc":[{"id":"1.168238841","rc":[{"batb":[[0,3.25,30.29],[1,1.02,2],[2,1.01,1.01]],"ltp":0.0,"tv":0.0,"id":16858291},{"batb":[[0,2.72,30.29],[1,2.7,94.92]],"ltp":0.0,"tv":0.0,"id":13460814}]}]}
{"op":"mcm","clk":"1005196071","pt":1580641415635,"mc":[{"id":"1.168238841","rc":[{"batb":[[0,2.78,92.16],[1,2.72,30.29]],"ltp":0.0,"tv":0.0,"id":13460814}]}]}
{"op":"mcm","clk":"1005220743","pt":1580641537188,"mc":[{"id":"1.168238841","rc":[{"batb":[[0,2.94,87.09],[1,2.88,30.28],[2,1.02,2]],"ltp":0.0,"tv":0.0,"id":16858291},{"batb":[[1,1.02,2],[2,1.01,1.01]],"ltp":0.0,"tv":0.0,"id":13460814}]}]}
{"op":"mcm","clk":"1005220838","pt":1580641537715,"mc":[{"id":"1.168238841","rc":[{"batb":[[0,2.82,91.03],[1,2.8,30.29],[2,1.02,2]],"ltp":0.0,"tv":0.0,"id":13460814}]}]}
{"op":"mcm","clk":"1005245869","pt":1580641657966,"mc":[{"id":"1.168238841","rc":[{"batb":[[1,1.02,2],[2,1.01,1.01]],"ltp":0.0,"tv":0.0,"id":16858291}]}]}
{"op":"mcm","clk":"1005246100","pt":1580641659085,"mc":[{"id":"1.168238841","rc":[{"batb":[[0,3,85.57],[1,2.96,30.29],[2,1.02,2]],"ltp":0.0,"tv":0.0,"id":16858291},{"batb":[[0,2.84,30.29],[1,2.82,91.03]],"ltp":0.0,"tv":0.0,"id":13460814}]}]}
{"op":"mcm","clk":"1005246182","pt":1580641659460,"mc":[{"id":"1.168238841","rc":[{"batb":[[0,2.88,88.96],[1,2.84,30.29]],"ltp":0.0,"tv":0.0,"id":13460814}]}]}
{"op":"mcm","clk":"1005270017","pt":1580641780253,"mc":[{"id":"1.168238841","rc":[{"batb":[[0,3.1,82.54],[1,3.05,30.29]],"ltp":0.0,"tv":0.0,"id":16858291}]}]}
{"op":"mcm","clk":"1005270139","pt":1580641780835,"mc":[{"id":"1.168238841","rc":[{"batb":[[0,2.92,87.69],[1,2.9,30.29]],"ltp":0.0,"tv":0.0,"id":13460814}]}]}
{"op":"mcm","clk":"1005292826","pt":1580641902031,"mc":[{"id":"1.168238841","rc":[{"batb":[[0,3.2,79.97],[1,3.15,30.29]],"ltp":0.0,"tv":0.0,"id":16858291},{"batb":[[1,1.02,2],[2,1.01,1.01]],"ltp":0.0,"tv":0.0,"id":13460814}]}]}
{"op":"mcm","clk":"1005314396","pt":1580642024886,"mc":[{"id":"1.168238841","rc":[{"batb":[[0,3.25,30.29],[1,1.02,2],[2,1.01,1.01]],"ltp":0.0,"tv":0.0,"id":16858291}]}]}
{"op":"mcm","clk":"1005336272","pt":1580642146236,"mc":[{"id":"1.168238841","rc":[{"batb":[[0,2.88,30.28]],"ltp":0.0,"tv":0.0,"id":16858291}]}]}
{"op":"mcm","clk":"1005336371","pt":1580642146870,"mc":[{"id":"1.168238841","rc":[{"batb":[[0,2.94,87.09],[1,2.88,30.28],[2,1.02,2]],"ltp":0.0,"tv":0.0,"id":16858291}]}]}
{"op":"mcm","clk":"1005358482","pt":1580642267280,"mc":[{"id":"1.168238841","rc":[{"batb":[[1,1.02,2],[2,1.01,1.01]],"ltp":0.0,"tv":0.0,"id":16858291}]}]}
{"op":"mcm","clk":"1005358654","pt":1580642268184,"mc":[{"id":"1.168238841","rc":[{"batb":[[0,3.1,82.54],[1,2.96,30.29],[2,1.02,2]],"ltp":0.0,"tv":0.0,"id":16858291}]}]}
{"op":"mcm","clk":"1005381863","pt":1580642389181,"mc":[{"id":"1.168238841","rc":[{"batb":[[0,3.15,30.29],[1,3.1,82.54]],"ltp":0.0,"tv":0.0,"id":16858291}]}]}
{"op":"mcm","clk":"1005381927","pt":1580642389584,"mc":[{"id":"1.168238841","rc":[{"batb":[[0,3.2,79.97],[1,3.15,30.29]],"ltp":0.0,"tv":0.0,"id":16858291}]}]}
{"op":"mcm","clk":"1005403840","pt":1580642511054,"mc":[{"id":"1.168238841","rc":[{"batb":[[0,3.25,30.29],[1,1.02,2],[2,1.01,1.01]],"ltp":0.0,"tv":0.0,"id":16858291}]}]}
{"op":"mcm","clk":"1005427515","pt":1580642633135,"mc":[{"id":"1.168238841","rc":[{"batb":[[0,2.88,30.28]],"ltp":0.0,"tv":0.0,"id":16858291}]}]}
{"op":"mcm","clk":"1005427570","pt":1580642633343,"mc":[{"id":"1.168238841","rc":[{"batb":[[0,2.9,88.36],[1,2.88,30.28],[2,1.02,2]],"ltp":0.0,"tv":0.0,"id":16858291}]}]}
{"op":"mcm","clk":"1005449581","pt":1580642750238,"mc":[{"id":"1.168238841","rc":[{"batl":[[0,4.5,467.31]],"ltp":0.0,"tv":0.0,"id":16858291}]}]}
{"op":"mcm","clk":"1005450384","pt":1580642754844,"mc":[{"id":"1.168238841","rc":[{"batb":[[1,1.02,2],[2,1.01,1.01]],"ltp":0.0,"tv":0.0,"id":16858291}]}]}
{"op":"mcm","clk":"1005450569","pt":1580642755712,"mc":[{"id":"1.168238841","rc":[{"batb":[[0,2.98,85.9],[1,2.92,30.29],[2,1.02,2]],"ltp":0.0,"tv":0.0,"id":16858291}]}]}
{"op":"mcm","clk":"1005473747","pt":1580642876106,"mc":[{"id":"1.168238841","rc":[{"batb":[[0,3,30.29],[1,1.02,2],[2,1.01,1.01]],"ltp":0.0,"tv":0.0,"id":16858291}]}]}
{"op":"mcm","clk":"1005473778","pt":1580642876314,"mc":[{"id":"1.168238841","rc":[{"batb":[[0,3.1,82.54],[1,3,30.29],[2,1.02,2]],"ltp":0.0,"tv":0.0,"id":16858291}]}]}
{"op":"mcm","clk":"1005480367","pt":1580642914248,"mc":[{"id":"1.168238841","rc":[{"batb":[[0,3.1,82.54],[1,1.02,2],[2,1.01,1.01]],"batl":[[0,16,160.87]],"ltp":0.0,"tv":0.0,"id":13460817}]}]}
{"op":"mcm","clk":"1005495372","pt":1580642998101,"mc":[{"id":"1.168238841","rc":[{"batb":[[0,3.15,111.52],[1,1.02,2],[2,1.01,1.01]],"ltp":0.0,"tv":0.0,"id":16858291},{"batb":[[0,2.94,30.29],[1,2.92,87.69],[2,1.02,2]],"ltp":0.0,"tv":0.0,"id":13460814}]}]}
{"op":"mcm","clk":"1005495446","pt":1580642998473,"mc":[{"id":"1.168238841","rc":[{"batb":[[0,2.96,86.63],[1,2.94,30.29]],"batl":[[0,5.8,301.97]],"ltp":0.0,"tv":0.0,"id":13460814}]}]}
{"op":"mcm","clk":"1005518057","pt":1580643119258,"mc":[{"id":"1.168238841","rc":[{"batb":[[0,3.2,30.29],[1,3.15,81.23],[2,1.02,2]],"ltp":0.0,"tv":0.0,"id":16858291}]}]}
{"op":"mcm","clk":"1005518247","pt":1580643120269,"mc":[{"id":"1.168238841","rc":[{"batb":[[1,1.02,2],[2,1.01,1.01]],"ltp":0.0,"tv":0.0,"id":16858291},{"batb":[[0,2.98,30.29],[1,1.02,2],[2,1.01,1.01]],"ltp":0.0,"tv":0.0,"id":13460814}]}]}
{"op":"mcm","clk":"1005541791","pt":1580643241272,"mc":[{"id":"1.168238841","rc":[{"batb":[[0,2.82,30.29],[1,2.3,111.68],[2,1.02,2]],"ltp":0.0,"tv":0.0,"id":16858291}]}]}
{"op":"mcm","clk":"1005541899","pt":1580643241869,"mc":[{"id":"1.168238841","rc":[{"batb":[[0,2.96,86.63],[1,2.82,30.29]],"ltp":0.0,"tv":0.0,"id":16858291},{"batb":[[0,2.6,98.59],[1,2.56,30.29],[2,1.02,2]],"ltp":0.0,"tv":0.0,"id":13460814}]}]}
{"op":"mcm","clk":"1005565880","pt":1580643363099,"mc":[{"id":"1.168238841","rc":[{"batb":[[0,3,85.57],[1,2.98,30.29]],"ltp":0.0,"tv":0.0,"id":16858291},{"batb":[[0,2.62,30.29],[1,2.6,98.59]],"ltp":0.0,"tv":0.0,"id":13460814}]}]}
{"op":"mcm","clk":"1005565940","pt":1580643363418,"mc":[{"id":"1.168238841","rc":[{"batb":[[0,2.72,94.34],[1,2.62,30.29]],"ltp":0.0,"tv":0.0,"id":13460814}]}]}
{"op":"mcm","clk":"1005566937","pt":1580643368028,"mc":[{"id":"1.168238841","rc":[{"batl":[[0,4.5,57.31]],"ltp":0.0,"tv":0.0,"id":16858291},{"batl":[[0,14,183.82]],"ltp":0.0,"tv":0.0,"id":16858293},{"batl":[[0,5.8,44.71]],"ltp":0.0,"tv":0.0,"id":13460814},{"batl":[[0,16,16.24]],"ltp":0.0,"tv":0.0,"id":13460817}]}]}
{"op":"mcm","clk":"1005597117","pt":1580643514330,"mc":[{"id":"1.168238841","rc":[{"batl":[[0,16,161.63]],"ltp":0.0,"tv":0.0,"id":13460817}]}]}
{"op":"mcm","clk":"1005600832","pt":1580643531060,"mc":[{"id":"1.168238841","rc":[{"batl":[[0,5.8,325.67]],"ltp":0.0,"tv":0.0,"id":13460814}]}]}
{"op":"mcm","clk":"1005614795","pt":1580643597954,"mc":[{"id":"1.168238841","rc":[{"batl":[[0,4.5,483.87]],"ltp":0.0,"tv":0.0,"id":16858291}]}]}
{"op":"mcm","clk":"1005800925","pt":1580644807145,"mc":[{"id":"1.168238841","rc":[{"batb":[[0,1.02,2],[1,1.01,1.01],[2,1.01,0]],"ltp":0.0,"tv":0.0,"id":16858293}]}]}
{"op":"mcm","clk":"1005801080","pt":1580644808170,"mc":[{"id":"1.168238841","rc":[{"batb":[[0,2.92,87.69],[1,1.02,2],[2,1.01,1.01]],"batl":[[0,12,214.41]],"ltp":0.0,"tv":0.0,"id":16858293}]}]}
{"op":"mcm","clk":"1005803179","pt":1580644823256,"mc":[{"id":"1.168238841","rc":[{"batb":[[0,3.1,82.54],[1,3.05,30.29]],"ltp":0.0,"tv":0.0,"id":16858291},{"batb":[[0,2.74,30.29],[1,2.72,94.34]],"ltp":0.0,"tv":0.0,"id":13460814}]}]}
{"op":"mcm","clk":"1005803220","pt":1580644823575,"mc":[{"id":"1.168238841","rc":[{"batb":[[0,2.96,86.63],[1,2.74,30.29]],"ltp":0.0,"tv":0.0,"id":13460814}]}]}
{"op":"mcm","clk":"1005821819","pt":1580644944255,"mc":[{"id":"1.168238841","rc":[{"batb":[[1,1.02,2],[2,1.01,1.01]],"ltp":0.0,"tv":0.0,"id":16858291}]}]}
{"op":"mcm","clk":"1005821957","pt":1580644945089,"mc":[{"id":"1.168238841","rc":[{"batb":[[0,3.2,79.97],[1,3.15,30.29],[2,1.02,2]],"ltp":0.0,"tv":0.0,"id":16858291},{"batb":[[1,1.02,2],[2,1.01,1.01]],"ltp":0.0,"tv":0.0,"id":13460814}]}]}
{"op":"mcm","clk":"1005844056","pt":1580645066918,"mc":[{"id":"1.168238841","rc":[{"batb":[[0,3.25,30.29],[1,1.02,2],[2,1.01,1.01]],"ltp":0.0,"tv":0.0,"id":16858291}]}]}
{"op":"mcm","clk":"1005867715","pt":1580645188116,"mc":[{"id":"1.168238841","rc":[{"batb":[[0,2.84,30.29]],"ltp":0.0,"tv":0.0,"id":16858291}]}]}
{"op":"mcm","clk":"1005867756","pt":1580645188367,"mc":[{"id":"1.168238841","rc":[{"batb":[[0,2.92,87.69],[1,2.84,30.29],[2,1.02,2]],"ltp":0.0,"tv":0.0,"id":16858291}]}]}
{"op":"mcm","clk":"1005891515","pt":1580645309257,"mc":[{"id":"1.168238841","rc":[{"batb":[[0,2.94,30.29],[1,2.92,87.69]],"ltp":0.0,"tv":0.0,"id":16858291}]}]}
{"op":"mcm","clk":"1005891577","pt":1580645309574,"mc":[{"id":"1.168238841","rc":[{"batb":[[0,3.15,81.23],[1,2.94,30.29]],"ltp":0.0,"tv":0.0,"id":16858291}]}]}
{"op":"mcm","clk":"1005915135","pt":1580645431064,"mc":[{"id":"1.168238841","rc":[{"batb":[[0,3.2,30.29],[1,3.15,81.23]],"ltp":0.0,"tv":0.0,"id":16858291}]}]}
{"op":"mcm","clk":"1005915228","pt":1580645431437,"mc":[{"id":"1.168238841","rc":[{"batb":[[0,3.2,110.26],[1,1.02,2],[2,1.01,1.01]],"ltp":0.0,"tv":0.0,"id":16858291}]}]}
{"op":"mcm","clk":"1005937033","pt":1580645553012,"mc":[{"id":"1.168238841","rc":[{"batb":[[0,3.25,30.29]],"ltp":0.0,"tv":0.0,"id":16858291}]}]}
{"op":"mcm","clk":"1005958968","pt":1580645674267,"mc":[{"id":"1.168238841","rc":[{"batb":[[0,1.02,2],[1,1.01,1.01],[2,1.01,0]],"ltp":0.0,"tv":0.0,"id":16858291}]}]}
{"op":"mcm","clk":"1005959027","pt":1580645674587,"mc":[{"id":"1.168238841","rc":[{"batb":[[0,2.96,86.63],[1,2.92,30.29],[2,1.02,2]],"ltp":0.0,"tv":0.0,"id":16858291}]}]}
{"op":"mcm","clk":"1005980578","pt":1580645796099,"mc":[{"id":"1.168238841","rc":[{"batb":[[0,2.98,30.29],[1,2.96,86.63]],"ltp":0.0,"tv":0.0,"id":16858291}]}]}
{"op":"mcm","clk":"1005980652","pt":1580645796617,"mc":[{"id":"1.168238841","rc":[{"batb":[[0,3.1,82.54],[1,2.98,30.29]],"ltp":0.0,"tv":0.0,"id":16858291}]}]}
{"op":"mcm","clk":"1006001595","pt":1580645918270,"mc":[{"id":"1.168238841","rc":[{"batb":[[0,3.2,79.97],[1,3.15,30.29]],"ltp":0.0,"tv":0.0,"id":16858291}]}]}
{"op":"mcm","clk":"1006022359","pt":1580646039227,"mc":[{"id":"1.168238841","rc":[{"batb":[[1,1.02,2],[2,1.01,1.01]],"ltp":0.0,"tv":0.0,"id":16858291}]}]}
{"op":"mcm","clk":"1006022407","pt":1580646039499,"mc":[{"id":"1.168238841","rc":[{"batb":[[0,3.25,30.29]],"ltp":0.0,"tv":0.0,"id":16858291}]}]}
{"op":"mcm","clk":"1006044283","pt":1580646161078,"mc":[{"id":"1.168238841","rc":[{"batb":[[0,2.92,30.29]],"ltp":0.0,"tv":0.0,"id":16858291}]}]}
{"op":"mcm","clk":"1006044367","pt":1580646161551,"mc":[{"id":"1.168238841","rc":[{"batb":[[0,2.98,85.9],[1,2.92,30.29],[2,1.02,2]],"ltp":0.0,"tv":0.0,"id":16858291}]}]}
{"op":"mcm","clk":"1006065381","pt":1580646283248,"mc":[{"id":"1.168238841","rc":[{"batb":[[0,3.1,82.54],[1,3,30.29]],"ltp":0.0,"tv":0.0,"id":16858291}]}]}
{"op":"mcm","clk":"1006077103","pt":1580646350742,"mc":[{"id":"1.168238841","rc":[{"batl":[[0,5.5,396.17]],"ltp":0.0,"tv":0.0,"id":16858291}]}]}
{"op":"mcm","clk":"1006086661","pt":1580646404758,"mc":[{"id":"1.168238841","rc":[{"batb":[[0,3.2,79.97],[1,3.15,30.29]],"ltp":0.0,"tv":0.0,"id":16858291}]}]}
{"op":"mcm","clk":"1006086809","pt":1580646405557,"mc":[{"id":"1.168238841","rc":[{"batl":[[0,5.8,44.47]],"ltp":0.0,"tv":0.0,"id":13460814},{"batl":[[0,16,16.24]],"ltp":0.0,"tv":0.0,"id":13460817}]}]}
{"op":"mcm","clk":"1006105097","pt":1580646514424,"mc":[{"id":"1.168238841","rc":[{"batb":[[0,1.02,2],[1,1.01,1.01],[2,1.01,0]],"batl":[[0,16,162.42]],"ltp":0.0,"tv":0.0,"id":13460817}]}]}
{"op":"mcm","clk":"1006105301","pt":1580646515632,"mc":[{"id":"1.168238841","rc":[{"batl":[[0,12.5,207.57]],"ltp":0.0,"tv":0.0,"id":13460817}]}]}
{"op":"mcm","clk":"1006107132","pt":1580646526175,"mc":[{"id":"1.168238841","rc":[{"batb":[[0,3.25,30.29],[1,3.2,79.97]],"ltp":0.0,"tv":0.0,"id":16858291}]}]}
{"op":"mcm","clk":"1006107182","pt":1580646526448,"mc":[{"id":"1.168238841","rc":[{"batb":[[1,1.02,2],[2,1.01,1.01]],"ltp":0.0,"tv":0.0,"id":16858291}]}]}
{"op":"mcm","clk":"1006108105","pt":1580646531645,"mc":[{"id":"1.168238841","rc":[{"batl":[[0,5.8,313.72]],"ltp":0.0,"tv":0.0,"id":13460814}]}]}
{"op":"mcm","clk":"1006119758","pt":1580646599620,"mc":[{"id":"1.168238841","rc":[{"batl":[[0,6.8,267.67]],"ltp":0.0,"tv":0.0,"id":13460814}]}]}
{"op":"mcm","clk":"1006128484","pt":1580646648019,"mc":[{"id":"1.168238841","rc":[{"batb":[[0,2.92,30.29]],"ltp":0.0,"tv":0.0,"id":16858291}]}]}
{"op":"mcm","clk":"1006128600","pt":1580646648614,"mc":[{"id":"1.168238841","rc":[{"batb":[[0,2.96,86.63],[1,2.92,30.29],[2,1.02,2]],"ltp":0.0,"tv":0.0,"id":16858291}]}]}
{"op":"mcm","clk":"1006150136","pt":1580646770855,"mc":[{"id":"1.168238841","rc":[{"batb":[[0,3.05,84.09],[1,2.98,30.29]],"ltp":0.0,"tv":0.0,"id":16858291}]}]}
{"op":"mcm","clk":"1006162981","pt":1580646843071,"mc":[{"id":"1.168238841","rc":[{"batb":[[0,2.28,112.66]],"ltp":0.0,"tv":0.0,"id":13460814}]}]}
{"op":"mcm","clk":"1006172659","pt":1580646892105,"mc":[{"id":"1.168238841","rc":[{"batb":[[0,3.1,30.29],[1,3.05,84.09]],"ltp":0.0,"tv":0.0,"id":16858291}]}]}
{"op":"mcm","clk":"1006172832","pt":1580646893002,"mc":[{"id":"1.168238841","rc":[{"batb":[[0,3.15,81.23],[1,3.1,30.29]],"ltp":0.0,"tv":0.0,"id":16858291},{"batb":[[0,2.82,91.03],[1,2.48,30.29],[2,1.02,2]],"ltp":0.0,"tv":0.0,"id":13460814}]}]}
{"op":"mcm","clk":"1006196094","pt":1580647014286,"mc":[{"id":"1.168238841","rc":[{"batb":[[0,3.2,110.26],[1,1.02,2],[2,1.01,1.01]],"ltp":0.0,"tv":0.0,"id":16858291},{"batb":[[1,1.02,2],[2,1.01,1.01]],"ltp":0.0,"tv":0.0,"id":13460814}]}]}
{"op":"mcm","clk":"1006196186","pt":1580647014708,"mc":[{"id":"1.168238841","rc":[{"batb":[[0,2.9,88.36],[1,2.84,30.29],[2,1.02,2]],"ltp":0.0,"tv":0.0,"id":13460814}]}]}
{"op":"mcm","clk":"1006220456","pt":1580647135947,"mc":[{"id":"1.168238841","rc":[{"batb":[[0,3.25,30.29]],"ltp":0.0,"tv":0.0,"id":16858291},{"batb":[[1,1.02,2],[2,1.01,1.01]],"ltp":0.0,"tv":0.0,"id":13460814}]}]}
{"op":"mcm","clk":"1006245248","pt":1580647257066,"mc":[{"id":"1.168238841","rc":[{"batb":[[0,2.94,30.29]],"ltp":0.0,"tv":0.0,"id":16858291}]}]}
{"op":"mcm","clk":"1006245410","pt":1580647257784,"mc":[{"id":"1.168238841","rc":[{"batb":[[0,2.96,86.63],[1,2.94,30.29],[2,1.02,2]],"ltp":0.0,"tv":0.0,"id":16858291}]}]}
{"op":"mcm","clk":"1006269452","pt":1580647379216,"mc":[{"id":"1.168238841","rc":[{"batb":[[0,2.98,30.29],[1,1.02,2],[2,1.01,1.01]],"ltp":0.0,"tv":0.0,"id":16858291}]}]}
{"op":"mcm","clk":"1006269517","pt":1580647379375,"mc":[{"id":"1.168238841","rc":[{"batb":[[0,3,85.57],[1,2.98,30.29],[2,1.02,2]],"ltp":0.0,"tv":0.0,"id":16858291}]}]}
{"op":"mcm","clk":"1006426936","pt":1580648408246,"mc":[{"id":"1.168238841","rc":[{"batb":[[0,2.96,86.63]],"ltp":0.0,"tv":0.0,"id":16858293}]}]}
{"op":"mcm","clk":"1006426979","pt":1580648408561,"mc":[{"id":"1.168238841","rc":[{"batl":[[0,16.5,155.75]],"ltp":0.0,"tv":0.0,"id":16858293}]}]}
{"op":"mcm","clk":"1006435755","pt":1580648474232,"mc":[{"id":"1.168238841","rc":[{"batb":[[0,3.05,30.29],[1,1.02,2],[2,1.01,1.01]],"ltp":0.0,"tv":0.0,"id":16858291}]}]}
{"op":"mcm","clk":"1006435773","pt":1580648474362,"mc":[{"id":"1.168238841","rc":[{"batb":[[0,3.15,81.23],[1,3.05,30.29],[2,1.02,2]],"ltp":0.0,"tv":0.0,"id":16858291}]}]}
{"op":"mcm","clk":"1006451787","pt":1580648596010,"mc":[{"id":"1.168238841","rc":[{"batb":[[0,3.2,110.26],[1,1.02,2],[2,1.01,1.01]],"ltp":0.0,"tv":0.0,"id":16858291}]}]}
{"op":"mcm","clk":"1006468046","pt":1580648717126,"mc":[{"id":"1.168238841","rc":[{"batb":[[0,3.2,79.97]],"ltp":0.0,"tv":0.0,"id":16858291}]}]}
{"op":"mcm","clk":"1006468109","pt":1580648717502,"mc":[{"id":"1.168238841","rc":[{"batb":[[0,3.25,30.29]],"ltp":0.0,"tv":0.0,"id":16858291}]}]}
{"op":"mcm","clk":"1006486014","pt":1580648840285,"mc":[{"id":"1.168238841","rc":[{"batb":[[0,2.94,30.29]],"ltp":0.0,"tv":0.0,"id":16858291}]}]}
{"op":"mcm","clk":"1006486026","pt":1580648840363,"mc":[{"id":"1.168238841","rc":[{"batb":[[0,3.1,82.54],[1,2.94,30.29],[2,1.02,2]],"ltp":0.0,"tv":0.0,"id":16858291}]}]}
{"op":"mcm","clk":"1006503194","pt":1580648961223,"mc":[{"id":"1.168238841","rc":[{"batb":[[0,3.2,79.97],[1,3.15,30.29]],"ltp":0.0,"tv":0.0,"id":16858291}]}]}
{"op":"mcm","clk":"1006520961","pt":1580649082221,"mc":[{"id":"1.168238841","rc":[{"batb":[[0,3.25,30.29],[1,3.2,79.97]],"ltp":0.0,"tv":0.0,"id":16858291}]}]}
{"op":"mcm","clk":"1006520999","pt":1580649082503,"mc":[{"id":"1.168238841","rc":[{"batb":[[1,1.02,2],[2,1.01,1.01]],"ltp":0.0,"tv":0.0,"id":16858291}]}]}
{"op":"mcm","clk":"1006539682","pt":1580649204231,"mc":[{"id":"1.168238841","rc":[{"batb":[[0,2.94,30.29],[1,2.42,106.13],[2,1.02,2]],"ltp":0.0,"tv":0.0,"id":16858291}]}]}
{"op":"mcm","clk":"1006539764","pt":1580649204653,"mc":[{"id":"1.168238841","rc":[{"batb":[[0,3,85.57],[1,2.94,30.29]],"ltp":0.0,"tv":0.0,"id":16858291}]}]}
{"op":"mcm","clk":"1006558899","pt":1580649326266,"mc":[{"id":"1.168238841","rc":[{"batb":[[0,3.05,30.29],[1,1.02,2],[2,1.01,1.01]],"ltp":0.0,"tv":0.0,"id":16858291}]}]}
{"op":"mcm","clk":"1006558940","pt":1580649326393,"mc":[{"id":"1.168238841","rc":[{"batb":[[0,3.1,82.54],[1,3.05,30.29],[2,1.02,2]],"ltp":0.0,"tv":0.0,"id":16858291}]}]}
{"op":"mcm","clk":"1006576846","pt":1580649447214,"mc":[{"id":"1.168238841","rc":[{"batb":[[0,3.15,30.29],[1,3.1,82.54]],"ltp":0.0,"tv":0.0,"id":16858291}]}]}
{"op":"mcm","clk":"1006576907","pt":1580649447631,"mc":[{"id":"1.168238841","rc":[{"batb":[[0,3.2,79.97],[1,3.15,30.29]],"ltp":0.0,"tv":0.0,"id":16858291}]}]}
{"op":"mcm","clk":"1006594298","pt":1580649569085,"mc":[{"id":"1.168238841","rc":[{"batb":[[0,3.25,30.29],[1,1.02,2],[2,1.01,1.01]],"ltp":0.0,"tv":0.0,"id":16858291}]}]}
{"op":"mcm","clk":"1006611825","pt":1580649691229,"mc":[{"id":"1.168238841","rc":[{"batb":[[0,2.94,30.29]],"ltp":0.0,"tv":0.0,"id":16858291}]}]}
{"op":"mcm","clk":"1006611841","pt":1580649691328,"mc":[{"id":"1.168238841","rc":[{"batb":[[0,2.96,86.63],[1,2.94,30.29],[2,1.02,2]],"ltp":0.0,"tv":0.0,"id":16858291}]}]}
{"op":"mcm","clk":"1006628671","pt":1580649812197,"mc":[{"id":"1.168238841","rc":[{"batb":[[1,1.02,2],[2,1.01,1.01]],"ltp":0.0,"tv":0.0,"id":16858291}]}]}
{"op":"mcm","clk":"1006628741","pt":1580649812724,"mc":[{"id":"1.168238841","rc":[{"batb":[[0,3.05,84.09],[1,2.98,30.29],[2,1.02,2]],"ltp":0.0,"tv":0.0,"id":16858291}]}]}
{"op":"mcm","clk":"1006646878","pt":1580649934198,"mc":[{"id":"1.168238841","rc":[{"batb":[[0,3.1,30.29],[1,1.02,2],[2,1.01,1.01]],"ltp":0.0,"tv":0.0,"id":16858291}]}]}
{"op":"mcm","clk":"1006646897","pt":1580649934305,"mc":[{"id":"1.168238841","rc":[{"batb":[[0,3.15,81.23],[1,3.1,30.29],[2,1.02,2]],"ltp":0.0,"tv":0.0,"id":16858291}]}]}
{"op":"mcm","clk":"1006649249","pt":1580649951089,"mc":[{"id":"1.168238841","rc":[{"batl":[[0,8.2,265.98]],"ltp":0.0,"tv":0.0,"id":16858291}]}]}
{"op":"mcm","clk":"1006664654","pt":1580650056024,"mc":[{"id":"1.168238841","rc":[{"batb":[[0,3.2,110.26],[1,1.02,2],[2,1.01,1.01]],"ltp":0.0,"tv":0.0,"id":16858291}]}]}
{"op":"mcm","clk":"1006673202","pt":1580650115913,"mc":[{"id":"1.168238841","rc":[{"batb":[[0,2.94,87.09],[1,1.02,2],[2,1.01,1.01]],"ltp":0.0,"tv":0.0,"id":13460817}]}]}
{"op":"mcm","clk":"1006681400","pt":1580650177283,"mc":[{"id":"1.168238841","rc":[{"batb":[[0,3.2,79.97]],"ltp":0.0,"tv":0.0,"id":16858291}]}]}
{"op":"mcm","clk":"1006681447","pt":1580650177659,"mc":[{"id":"1.168238841","rc":[{"batb":[[0,3.25,30.29]],"ltp":0.0,"tv":0.0,"id":16858291}]}]}
{"op":"mcm","clk":"1006699086","pt":1580650298954,"mc":[{"id":"1.168238841","rc":[{"batb":[[0,2.94,30.29]],"ltp":0.0,"tv":0.0,"id":16858291}]}]}
{"op":"mcm","clk":"1006699216","pt":1580650299630,"mc":[{"id":"1.168238841","rc":[{"batb":[[0,3.05,84.09],[1,2.94,30.29],[2,1.02,2]],"ltp":0.0,"tv":0.0,"id":16858291}]}]}
{"op":"mcm","clk":"1006716775","pt":1580650421286,"mc":[{"id":"1.168238841","rc":[{"batb":[[0,3.1,30.29],[1,1.02,2],[2,1.01,1.01]],"ltp":0.0,"tv":0.0,"id":16858291}]}]}
{"op":"mcm","clk":"1006716797","pt":1580650421360,"mc":[{"id":"1.168238841","rc":[{"batb":[[0,3.15,81.23],[1,3.1,30.29],[2,1.02,2]],"ltp":0.0,"tv":0.0,"id":16858291}]}]}
{"op":"mcm","clk":"1006720111","pt":1580650443973,"mc":[{"id":"1.168238841","rc":[{"batb":[[0,1.02,2],[1,1.01,1.01],[2,1.01,0]],"ltp":0.0,"tv":0.0,"id":13460814}]}]}
{"op":"mcm","clk":"1006720169","pt":1580650444505,"mc":[{"id":"1.168238841","rc":[{"batb":[[0,2.46,104.38],[1,1.02,2],[2,1.01,1.01]],"batl":[[0,5.7,319.25]],"ltp":0.0,"tv":0.0,"id":13460814}]}]}
{"op":"mcm","clk":"1006733828","pt":1580650542224,"mc":[{"id":"1.168238841","rc":[{"batb":[[1,1.02,2],[2,1.01,1.01]],"ltp":0.0,"tv":0.0,"id":16858291}]}]}
{"op":"mcm","clk":"1006734014","pt":1580650543209,"mc":[{"id":"1.168238841","rc":[{"batb":[[0,3.2,110.26]],"ltp":0.0,"tv":0.0,"id":16858291},{"batb":[[0,2.48,30.29]],"ltp":0.0,"tv":0.0,"id":13460814}]}]}
{"op":"mcm","clk":"1006734044","pt":1580650543417,"mc":[{"id":"1.168238841","rc":[{"batb":[[0,2.62,98.04],[1,2.48,30.29],[2,1.02,2]],"ltp":0.0,"tv":0.0,"id":13460814}]}]}
{"op":"mcm","clk":"1006751563","pt":1580650664103,"mc":[{"id":"1.168238841","rc":[{"batb":[[0,3.25,30.29],[1,3.2,79.97],[2,1.02,2]],"ltp":0.0,"tv":0.0,"id":16858291}]}]}
{"op":"mcm","clk":"1006751723","pt":1580650665087,"mc":[{"id":"1.168238841","rc":[{"batb":[[1,1.02,2],[2,1.01,1.01]],"ltp":0.0,"tv":0.0,"id":16858291},{"batb":[[0,2.72,94.34],[1,2.64,30.29]],"ltp":0.0,"tv":0.0,"id":13460814}]}]}
{"op":"mcm","clk":"1006769904","pt":1580650786264,"mc":[{"id":"1.168238841","rc":[{"batb":[[0,3,85.57],[1,2.94,30.29],[2,1.02,2]],"ltp":0.0,"tv":0.0,"id":16858291},{"batb":[[0,2.74,30.29],[1,2.72,94.34]],"ltp":0.0,"tv":0.0,"id":13460814}]}]}
{"op":"mcm","clk":"1006769980","pt":1580650786749,"mc":[{"id":"1.168238841","rc":[{"batb":[[0,2.88,88.96],[1,2.74,30.29]],"ltp":0.0,"tv":0.0,"id":13460814}]}]}
{"op":"mcm","clk":"1006788226","pt":1580650907203,"mc":[{"id":"1.168238841","rc":[{"batb":[[1,1.02,2],[2,1.01,1.01]],"ltp":0.0,"tv":0.0,"id":16858291}]}]}
{"op":"mcm","clk":"1006788299","pt":1580650907781,"mc":[{"id":"1.168238841","rc":[{"batb":[[0,3.15,81.23],[1,3.05,30.29],[2,1.02,2]],"ltp":0.0,"tv":0.0,"id":16858291},{"batb":[[1,1.02,2],[2,1.01,1.01]],"ltp":0.0,"tv":0.0,"id":13460814}]}]}
{"op":"mcm","clk":"1006807679","pt":1580651029055,"mc":[{"id":"1.168238841","rc":[{"batb":[[0,3.2,30.29],[1,3.15,81.23]],"ltp":0.0,"tv":0.0,"id":16858291}]}]}
{"op":"mcm","clk":"1006807795","pt":1580651029764,"mc":[{"id":"1.168238841","rc":[{"batb":[[0,3.2,110.26],[1,1.02,2],[2,1.01,1.01]],"ltp":0.0,"tv":0.0,"id":16858291}]}]}
{"op":"mcm","clk":"1006940412","pt":1580652003526,"mc":[{"id":"1.168238841","rc":[{"batb":[[0,3.25,30.29],[1,3.2,79.97],[2,1.02,2]],"ltp":0.0,"tv":0.0,"id":16858291}]}]}
{"op":"mcm","clk":"1006940664","pt":1580652005324,"mc":[{"id":"1.168238841","rc":[{"batb":[[1,1.02,2],[2,1.01,1.01]],"ltp":0.0,"tv":0.0,"id":16858291}]}]}
{"op":"mcm","clk":"1006941299","pt":1580652007935,"mc":[{"id":"1.168238841","rc":[{"batb":[[0,1.02,2],[1,1.01,1.01],[2,1.01,0]],"ltp":0.0,"tv":0.0,"id":16858293}]}]}
{"op":"mcm","clk":"1006941908","pt":1580652011974,"mc":[{"id":"1.168238841","rc":[{"batb":[[0,2.78,92.16],[1,1.02,2],[2,1.01,1.01]],"ltp":0.0,"tv":0.0,"id":16858293}]}]}
{"op":"mcm","clk":"1006941966","pt":1580652012355,"mc":[{"id":"1.168238841","rc":[{"batl":[[0,9.2,279.28]],"ltp":0.0,"tv":0.0,"id":16858293}]}]}
{"op":"mcm","clk":"1006958486","pt":1580652125134,"mc":[{"id":"1.168238841","rc":[{"batb":[[0,2.94,30.29]],"ltp":0.0,"tv":0.0,"id":16858291}]}]}
{"op":"mcm","clk":"1006958592","pt":1580652125831,"mc":[{"id":"1.168238841","rc":[{"batb":[[0,3.15,81.23],[1,2.94,30.29],[2,1.02,2]],"ltp":0.0,"tv":0.0,"id":16858291}]}]}
{"op":"mcm","clk":"1006978022","pt":1580652246838,"mc":[{"id":"1.168238841","rc":[{"batb":[[0,3.2,30.29],[1,3.15,81.23]],"ltp":0.0,"tv":0.0,"id":16858291}]}]}
{"op":"mcm","clk":"1006978239","pt":1580652248053,"mc":[{"id":"1.168238841","rc":[{"batb":[[0,3.2,110.26],[1,1.02,2],[2,1.01,1.01]],"ltp":0.0,"tv":0.0,"id":16858291}]}]}
{"op":"mcm","clk":"1006998795","pt":1580652369043,"mc":[{"id":"1.168238841","rc":[{"batb":[[0,3.25,30.29]],"ltp":0.0,"tv":0.0,"id":16858291}]}]}
{"op":"mcm","clk":"1007020825","pt":1580652490249,"mc":[{"id":"1.168238841","rc":[{"batb":[[0,2.94,30.29]],"ltp":0.0,"tv":0.0,"id":16858291}]}]}
{"op":"mcm","clk":"1007020978","pt":1580652490972,"mc":[{"id":"1.168238841","rc":[{"batb":[[0,3.05,84.09],[1,2.94,30.29],[2,1.02,2]],"ltp":0.0,"tv":0.0,"id":16858291}]}]}
{"op":"mcm","clk":"1007043226","pt":1580652613004,"mc":[{"id":"1.168238841","rc":[{"batb":[[0,3.15,81.23],[1,3.1,30.29]],"ltp":0.0,"tv":0.0,"id":16858291}]}]}
{"op":"mcm","clk":"1007064588","pt":1580652734234,"mc":[{"id":"1.168238841","rc":[{"batb":[[0,3.2,110.26],[1,1.02,2],[2,1.01,1.01]],"ltp":0.0,"tv":0.0,"id":16858291}]}]}
{"op":"mcm","clk":"1007086844","pt":1580652855131,"mc":[{"id":"1.168238841","rc":[{"batb":[[0,3.2,79.97]],"ltp":0.0,"tv":0.0,"id":16858291}]}]}
{"op":"mcm","clk":"1007086939","pt":1580652855628,"mc":[{"id":"1.168238841","rc":[{"batb":[[0,3.25,30.29]],"ltp":0.0,"tv":0.0,"id":16858291}]}]}
{"op":"mcm","clk":"1007108517","pt":1580652977255,"mc":[{"id":"1.168238841","rc":[{"batb":[[0,2.94,30.29],[1,2.4,106.91],[2,1.02,2]],"ltp":0.0,"tv":0.0,"id":16858291}]}]}
{"op":"mcm","clk":"1007108593","pt":1580652977635,"mc":[{"id":"1.168238841","rc":[{"batb":[[0,3,85.57],[1,2.94,30.29]],"ltp":0.0,"tv":0.0,"id":16858291}]}]}
{"op":"mcm","clk":"1007129189","pt":1580653099165,"mc":[{"id":"1.168238841","rc":[{"batb":[[0,3.1,82.54],[1,3.05,30.29]],"ltp":0.0,"tv":0.0,"id":16858291}]}]}
{"op":"mcm","clk":"1007148081","pt":1580653220232,"mc":[{"id":"1.168238841","rc":[{"batb":[[0,3.15,30.29],[1,3.1,82.54]],"ltp":0.0,"tv":0.0,"id":16858291}]}]}
{"op":"mcm","clk":"1007148156","pt":1580653220722,"mc":[{"id":"1.168238841","rc":[{"batb":[[0,3.2,79.97],[1,3.15,30.29]],"ltp":0.0,"tv":0.0,"id":16858291}]}]}
{"op":"mcm","clk":"1007168791","pt":1580653342177,"mc":[{"id":"1.168238841","rc":[{"batb":[[0,3.25,30.29],[1,1.02,2],[2,1.01,1.01]],"ltp":0.0,"tv":0.0,"id":16858291}]}]}
{"op":"mcm","clk":"1007187755","pt":1580653464142,"mc":[{"id":"1.168238841","rc":[{"batb":[[0,2.96,86.63],[1,2.94,30.29],[2,1.02,2]],"ltp":0.0,"tv":0.0,"id":16858291}]}]}
{"op":"mcm","clk":"1007201101","pt":1580653551463,"mc":[{"id":"1.168238841","rc":[{"batl":[[0,5.9,369.45]],"ltp":0.0,"tv":0.0,"id":16858291}]}]}
{"op":"mcm","clk":"1007205958","pt":1580653585164,"mc":[{"id":"1.168238841","rc":[{"batb":[[0,2.98,30.29],[1,2.96,86.63]],"ltp":0.0,"tv":0.0,"id":16858291}]}]}
{"op":"mcm","clk":"1007206043","pt":1580653585600,"mc":[{"id":"1.168238841","rc":[{"batb":[[0,3,85.57],[1,2.98,30.29]],"ltp":0.0,"tv":0.0,"id":16858291}]}]}
{"op":"mcm","clk":"1007225663","pt":1580653706863,"mc":[{"id":"1.168238841","rc":[{"batb":[[0,3.05,30.29],[1,3,85.57]],"ltp":0.0,"tv":0.0,"id":16858291}]}]}
{"op":"mcm","clk":"1007225765","pt":1580653707489,"mc":[{"id":"1.168238841","rc":[{"batb":[[0,3.1,82.54],[1,3.05,30.29]],"ltp":0.0,"tv":0.0,"id":16858291}]}]}
{"op":"mcm","clk":"1007227083","pt":1580653716010,"mc":[{"id":"1.168238841","rc":[{"batb":[[0,1.02,2],[1,1.01,1.01],[2,1.01,0]],"ltp":0.0,"tv":0.0,"id":13460817}]}]}
{"op":"mcm","clk":"1007227172","pt":1580653716489,"mc":[{"id":"1.168238841","rc":[{"batl":[[0,15,173.23]],"ltp":0.0,"tv":0.0,"id":13460817}]}]}
{"op":"mcm","clk":"1007245622","pt":1580653828624,"mc":[{"id":"1.168238841","rc":[{"batb":[[0,3.15,30.29],[1,3.1,82.54]],"ltp":0.0,"tv":0.0,"id":16858291}]}]}
{"op":"mcm","clk":"1007246041","pt":1580653831248,"mc":[{"id":"1.168238841","rc":[{"batb":[[0,3.2,79.97],[1,3.15,30.29]],"ltp":0.0,"tv":0.0,"id":16858291}]}]}
{"op":"mcm","clk":"1007265079","pt":1580653950190,"mc":[{"id":"1.168238841","rc":[{"batb":[[0,3.25,30.29],[1,3.2,79.97]],"ltp":0.0,"tv":0.0,"id":16858291}]}]}
{"op":"mcm","clk":"1007265125","pt":1580653950510,"mc":[{"id":"1.168238841","rc":[{"batb":[[1,1.02,2],[2,1.01,1.01]],"ltp":0.0,"tv":0.0,"id":16858291}]}]}
{"op":"mcm","clk":"1007280639","pt":1580654045199,"mc":[{"id":"1.168238841","rc":[{"batb":[[0,1.02,2],[1,1.01,1.01],[2,1.01,0]],"batl":[[0,6.8,267.67]],"ltp":0.0,"tv":0.0,"id":13460814}]}]}
{"op":"mcm","clk":"1007280694","pt":1580654045515,"mc":[{"id":"1.168238841","rc":[{"batb":[[0,2.64,97.32],[1,1.02,2],[2,1.01,1.01]],"ltp":0.0,"tv":0.0,"id":13460814}]}]}
{"op":"mcm","clk":"1007285393","pt":1580654072246,"mc":[{"id":"1.168238841","rc":[{"batb":[[0,2.94,30.29],[1,2.56,100.33],[2,1.02,2]],"ltp":0.0,"tv":0.0,"id":16858291}]}]}
{"op":"mcm","clk":"1007285507","pt":1580654072933,"mc":[{"id":"1.168238841","rc":[{"batb":[[0,3.05,84.09],[1,2.94,30.29]],"ltp":0.0,"tv":0.0,"id":16858291},{"batb":[[0,2.74,93.52],[1,2.66,30.29],[2,1.02,2]],"ltp":0.0,"tv":0.0,"id":13460814}]}]}
{"op":"mcm","clk":"1007306410","pt":1580654194284,"mc":[{"id":"1.168238841","rc":[{"batb":[[0,3.1,30.29],[1,1.02,2],[2,1.01,1.01]],"ltp":0.0,"tv":0.0,"id":16858291}]}]}
{"op":"mcm","clk":"1007306499","pt":1580654194769,"mc":[{"id":"1.168238841","rc":[{"batb":[[0,3.15,81.23],[1,3.1,30.29],[2,1.02,2]],"ltp":0.0,"tv":0.0,"id":16858291},{"batb":[[0,2.8,91.48],[1,2.76,30.29]],"ltp":0.0,"tv":0.0,"id":13460814}]}]}
{"op":"mcm","clk":"1007327535","pt":1580654315224,"mc":[{"id":"1.168238841","rc":[{"batb":[[1,1.02,2],[2,1.01,1.01]],"ltp":0.0,"tv":0.0,"id":16858291}]}]}
{"op":"mcm","clk":"1007327693","pt":1580654316126,"mc":[{"id":"1.168238841","rc":[{"batb":[[0,3.2,110.26]],"ltp":0.0,"tv":0.0,"id":16858291},{"batb":[[0,2.82,30.29],[1,2.8,91.48]],"ltp":0.0,"tv":0.0,"id":13460814}]}]}
{"op":"mcm","clk":"1007327766","pt":1580654316607,"mc":[{"id":"1.168238841","rc":[{"batb":[[0,2.9,88.36],[1,2.82,30.29]],"ltp":0.0,"tv":0.0,"id":13460814}]}]}
{"op":"mcm","clk":"1007346441","pt":1580654436983,"mc":[{"id":"1.168238841","rc":[{"batb":[[0,3.25,30.29],[1,3.2,79.97],[2,1.02,2]],"ltp":0.0,"tv":0.0,"id":16858291}]}]}
{"op":"mcm","clk":"1007346532","pt":1580654437595,"mc":[{"id":"1.168238841","rc":[{"batb":[[1,1.02,2],[2,1.01,1.01]],"ltp":0.0,"tv":0.0,"id":16858291},{"batb":[[1,1.02,2],[2,1.01,1.01]],"ltp":0.0,"tv":0.0,"id":13460814}]}]}
{"op":"mcm","clk":"1007365901","pt":1580654559180,"mc":[{"id":"1.168238841","rc":[{"batb":[[0,2.94,30.29]],"ltp":0.0,"tv":0.0,"id":16858291}]}]}
{"op":"mcm","clk":"1007365934","pt":1580654559394,"mc":[{"id":"1.168238841","rc":[{"batb":[[0,3.05,84.09],[1,2.94,30.29],[2,1.02,2]],"ltp":0.0,"tv":0.0,"id":16858291}]}]}
{"op":"mcm","clk":"1007385048","pt":1580654680219,"mc":[{"id":"1.168238841","rc":[{"batb":[[1,1.02,2],[2,1.01,1.01]],"ltp":0.0,"tv":0.0,"id":16858291}]}]}
{"op":"mcm","clk":"1007385152","pt":1580654680921,"mc":[{"id":"1.168238841","rc":[{"batb":[[0,3.15,81.23],[1,3.1,30.29],[2,1.02,2]],"ltp":0.0,"tv":0.0,"id":16858291}]}]}
{"op":"mcm","clk":"1007403905","pt":1580654802127,"mc":[{"id":"1.168238841","rc":[{"batb":[[0,3.2,30.29],[1,1.02,2],[2,1.01,1.01]],"ltp":0.0,"tv":0.0,"id":16858291}]}]}
{"op":"mcm","clk":"1007403925","pt":1580654802339,"mc":[{"id":"1.168238841","rc":[{"batb":[[0,3.2,110.26]],"ltp":0.0,"tv":0.0,"id":16858291}]}]}
{"op":"mcm","clk":"1007419505","pt":1580654924067,"mc":[{"id":"1.168238841","rc":[{"batb":[[0,3.25,30.29],[1,3.2,79.97],[2,1.02,2]],"ltp":0.0,"tv":0.0,"id":16858291}]}]}
{"op":"mcm","clk":"1007419549","pt":1580654924343,"mc":[{"id":"1.168238841","rc":[{"batb":[[1,1.02,2],[2,1.01,1.01]],"ltp":0.0,"tv":0.0,"id":16858291}]}]}
{"op":"mcm","clk":"1007435144","pt":1580655046189,"mc":[{"id":"1.168238841","rc":[{"batb":[[0,3.05,84.09],[1,3,30.29],[2,1.02,2]],"ltp":0.0,"tv":0.0,"id":16858291},{"batb":[[0,2.92,30.29]],"ltp":0.0,"tv":0.0,"id":13460814}]}]}
{"op":"mcm","clk":"1007435168","pt":1580655046406,"mc":[{"id":"1.168238841","rc":[{"batb":[[0,2.94,87.09],[1,2.92,30.29],[2,1.02,2]],"ltp":0.0,"tv":0.0,"id":13460814}]}]}
{"op":"mcm","clk":"1007449492","pt":1580655167034,"mc":[{"id":"1.168238841","rc":[{"batb":[[0,3.1,30.29],[1,3.05,84.09]],"ltp":0.0,"tv":0.0,"id":16858291}]}]}
{"op":"mcm","clk":"1007449613","pt":1580655168032,"mc":[{"id":"1.168238841","rc":[{"batb":[[0,3.15,81.23],[1,3.1,30.29]],"ltp":0.0,"tv":0.0,"id":16858291},{"batb":[[0,3,85.57],[1,2.96,30.29]],"ltp":0.0,"tv":0.0,"id":13460814}]}]}
{"op":"mcm","clk":"1007464888","pt":1580655289112,"mc":[{"id":"1.168238841","rc":[{"batb":[[0,3.2,30.29],[1,1.02,2],[2,1.01,1.01]],"ltp":0.0,"tv":0.0,"id":16858291}]}]}
{"op":"mcm","clk":"1007464965","pt":1580655289742,"mc":[{"id":"1.168238841","rc":[{"batb":[[0,3.2,110.26]],"ltp":0.0,"tv":0.0,"id":16858291},{"batb":[[0,3.05,114.38],[1,1.02,2],[2,1.01,1.01]],"ltp":0.0,"tv":0.0,"id":13460814}]}]}
{"op":"mcm","clk":"1007480642","pt":1580655410259,"mc":[{"id":"1.168238841","rc":[{"batb":[[0,3.25,30.29],[1,3.2,79.97],[2,1.02,2]],"ltp":0.0,"tv":0.0,"id":16858291}]}]}
{"op":"mcm","clk":"1007480717","pt":1580655411057,"mc":[{"id":"1.168238841","rc":[{"batb":[[1,1.02,2],[2,1.01,1.01]],"ltp":0.0,"tv":0.0,"id":16858291},{"batb":[[0,3.1,30.29],[1,3.05,84.09],[2,1.02,2]],"ltp":0.0,"tv":0.0,"id":13460814}]}]}
{"op":"mcm","clk":"1007480745","pt":1580655411371,"mc":[{"id":"1.168238841","rc":[{"batb":[[1,1.02,2],[2,1.01,1.01]],"ltp":0.0,"tv":0.0,"id":13460814}]}]}
{"op":"mcm","clk":"1007495116","pt":1580655532230,"mc":[{"id":"1.168238841","rc":[{"batb":[[0,3,30.29],[1,2.3,111.68],[2,1.02,2]],"ltp":0.0,"tv":0.0,"id":16858291}]}]}
{"op":"mcm","clk":"1007495232","pt":1580655533230,"mc":[{"id":"1.168238841","rc":[{"batb":[[0,3.1,82.54],[1,3,30.29]],"ltp":0.0,"tv":0.0,"id":16858291},{"batb":[[0,2.86,89.68],[1,2.68,30.29],[2,1.02,2]],"ltp":0.0,"tv":0.0,"id":13460814}]}]}
{"op":"mcm","clk":"1007505480","pt":1580655612024,"mc":[{"id":"1.168238841","rc":[{"batb":[[0,1.02,2],[1,1.01,1.01],[2,1.01,0]],"ltp":0.0,"tv":0.0,"id":16858293}]}]}
{"op":"mcm","clk":"1007511452","pt":1580655653996,"mc":[{"id":"1.168238841","rc":[{"batb":[[0,3.2,79.97],[1,3.15,30.29]],"ltp":0.0,"tv":0.0,"id":16858291}]}]}
{"op":"mcm","clk":"1007511627","pt":1580655655274,"mc":[{"id":"1.168238841","rc":[{"batb":[[0,2.88,30.28],[1,1.02,2],[2,1.01,1.01]],"ltp":0.0,"tv":0.0,"id":13460814}]}]}
{"op":"mcm","clk":"1007511649","pt":1580655655486,"mc":[{"id":"1.168238841","rc":[{"batb":[[0,2.98,85.9],[1,2.88,30.28],[2,1.02,2]],"ltp":0.0,"tv":0.0,"id":13460814}]}]}
{"op":"mcm","clk":"1007532320","pt":1580655775271,"mc":[{"id":"1.168238841","rc":[{"batb":[[1,1.02,2],[2,1.01,1.01]],"ltp":0.0,"tv":0.0,"id":16858291}]}]}
{"op":"mcm","clk":"1007532435","pt":1580655775977,"mc":[{"id":"1.168238841","rc":[{"batb":[[0,3.25,30.29]],"ltp":0.0,"tv":0.0,"id":16858291},{"batb":[[1,1.02,2],[2,1.01,1.01]],"ltp":0.0,"tv":0.0,"id":13460814}]}]}
{"op":"mcm","clk":"1007532591","pt":1580655776786,"mc":[{"id":"1.168238841","rc":[{"batb":[[0,3.05,84.09],[1,3,30.29],[2,1.02,2]],"ltp":0.0,"tv":0.0,"id":13460814}]}]}
{"op":"mcm","clk":"1007556101","pt":1580655897135,"mc":[{"id":"1.168238841","rc":[{"batb":[[0,3,30.29]],"ltp":0.0,"tv":0.0,"id":16858291}]}]}
{"op":"mcm","clk":"1007556307","pt":1580655898230,"mc":[{"id":"1.168238841","rc":[{"batb":[[0,3.05,84.09],[1,3,30.29],[2,1.02,2]],"ltp":0.0,"tv":0.0,"id":16858291},{"batb":[[0,3.1,30.29],[1,1.02,2],[2,1.01,1.01]],"ltp":0.0,"tv":0.0,"id":13460814}]}]}
{"op":"mcm","clk":"1007581354","pt":1580656019212,"mc":[{"id":"1.168238841","rc":[{"batb":[[0,3.15,81.23],[1,3.1,30.29]],"ltp":0.0,"tv":0.0,"id":16858291}]}]}
{"op":"mcm","clk":"1007581537","pt":1580656020029,"mc":[{"id":"1.168238841","rc":[{"batb":[[0,2.84,90.22],[1,2.68,30.29],[2,1.02,2]],"ltp":0.0,"tv":0.0,"id":13460814}]}]}
{"op":"mcm","clk":"1007608778","pt":1580656140288,"mc":[{"id":"1.168238841","rc":[{"batb":[[1,1.02,2],[2,1.01,1.01]],"ltp":0.0,"tv":0.0,"id":16858291}]}]}
{"op":"mcm","clk":"1007608970","pt":1580656141130,"mc":[{"id":"1.168238841","rc":[{"batb":[[0,3.2,110.26]],"ltp":0.0,"tv":0.0,"id":16858291},{"batb":[[0,2.86,30.29],[1,2.84,90.22]],"ltp":0.0,"tv":0.0,"id":13460814}]}]}
{"op":"mcm","clk":"1007609109","pt":1580656141725,"mc":[{"id":"1.168238841","rc":[{"batb":[[0,3,85.57],[1,2.86,30.29]],"ltp":0.0,"tv":0.0,"id":13460814}]}]}
{"op":"mcm","clk":"1007638778","pt":1580656262062,"mc":[{"id":"1.168238841","rc":[{"batb":[[0,3.25,30.29],[1,3.2,79.97],[2,1.02,2]],"ltp":0.0,"tv":0.0,"id":16858291}]}]}
{"op":"mcm","clk":"1007639083","pt":1580656263268,"mc":[{"id":"1.168238841","rc":[{"batb":[[1,1.02,2],[2,1.01,1.01]],"ltp":0.0,"tv":0.0,"id":16858291},{"batb":[[0,3.05,114.38],[1,1.02,2],[2,1.01,1.01]],"ltp":0.0,"tv":0.0,"id":13460814}]}]}
{"op":"mcm","clk":"1007668028","pt":1580656385185,"mc":[{"id":"1.168238841","rc":[{"batb":[[0,3,30.29]],"ltp":0.0,"tv":0.0,"id":16858291}]}]}
{"op":"mcm","clk":"1007668211","pt":1580656385985,"mc":[{"id":"1.168238841","rc":[{"batb":[[0,3.05,84.09],[1,3,30.29],[2,1.02,2]],"ltp":0.0,"tv":0.0,"id":16858291},{"batb":[[0,3.1,30.29]],"ltp":0.0,"tv":0.0,"id":13460814}]}]}
{"op":"mcm","clk":"1007697050","pt":1580656506270,"mc":[{"id":"1.168238841","rc":[{"batb":[[1,1.02,2],[2,1.01,1.01]],"ltp":0.0,"tv":0.0,"id":16858291}]}]}
{"op":"mcm","clk":"1007697335","pt":1580656507285,"mc":[{"id":"1.168238841","rc":[{"batb":[[0,3.15,81.23],[1,3.1,30.29],[2,1.02,2]],"ltp":0.0,"tv":0.0,"id":16858291},{"batb":[[0,2.68,30.29]],"ltp":0.0,"tv":0.0,"id":13460814}]}]}
{"op":"mcm","clk":"1007697466","pt":1580656507803,"mc":[{"id":"1.168238841","rc":[{"batb":[[0,2.78,92.16],[1,2.68,30.29],[2,1.02,2]],"ltp":0.0,"tv":0.0,"id":13460814}]}]}
{"op":"mcm","clk":"1007724547","pt":1580656628059,"mc":[{"id":"1.168238841","rc":[{"batb":[[0,3.2,30.29],[1,3.15,81.23]],"ltp":0.0,"tv":0.0,"id":16858291}]}]}
{"op":"mcm","clk":"1007724807","pt":1580656629161,"mc":[{"id":"1.168238841","rc":[{"batb":[[0,3.2,110.26],[1,1.02,2],[2,1.01,1.01]],"ltp":0.0,"tv":0.0,"id":16858291},{"batb":[[0,2.92,87.69],[1,2.8,30.29]],"ltp":0.0,"tv":0.0,"id":13460814}]}]}
{"op":"mcm","clk":"1007752876","pt":1580656750234,"mc":[{"id":"1.168238841","rc":[{"batb":[[0,3.25,30.29]],"ltp":0.0,"tv":0.0,"id":16858291},{"batb":[[1,1.02,2],[2,1.01,1.01]],"ltp":0.0,"tv":0.0,"id":13460814}]}]}
{"op":"mcm","clk":"1007753032","pt":1580656750845,"mc":[{"id":"1.168238841","rc":[{"batb":[[0,3,85.57],[1,2.94,30.29],[2,1.02,2]],"ltp":0.0,"tv":0.0,"id":13460814}]}]}
{"op":"mcm","clk":"1007780655","pt":1580656872274,"mc":[{"id":"1.168238841","rc":[{"batb":[[0,3.05,84.09],[1,3,30.29],[2,1.02,2]],"ltp":0.0,"tv":0.0,"id":16858291},{"batb":[[0,3.05,30.29],[1,3,85.57]],"ltp":0.0,"tv":0.0,"id":13460814}]}]}
{"op":"mcm","clk":"1007780761","pt":1580656872662,"mc":[{"id":"1.168238841","rc":[{"batb":[[0,3.05,114.38],[1,1.02,2],[2,1.01,1.01]],"ltp":0.0,"tv":0.0,"id":13460814}]}]}
{"op":"mcm","clk":"1007807722","pt":1580656993200,"mc":[{"id":"1.168238841","rc":[{"batb":[[0,3.1,30.29],[1,3.05,84.09]],"ltp":0.0,"tv":0.0,"id":16858291}]}]}
{"op":"mcm","clk":"1007807937","pt":1580656994005,"mc":[{"id":"1.168238841","rc":[{"batb":[[0,3.15,81.23],[1,3.1,30.29]],"ltp":0.0,"tv":0.0,"id":16858291},{"batb":[[0,3.1,30.29],[1,3.05,84.09],[2,1.02,2]],"ltp":0.0,"tv":0.0,"id":13460814}]}]}
{"op":"mcm","clk":"1007807992","pt":1580656994320,"mc":[{"id":"1.168238841","rc":[{"batb":[[1,1.02,2],[2,1.01,1.01]],"ltp":0.0,"tv":0.0,"id":13460814}]}]}
{"op":"mcm","clk":"1007835112","pt":1580657115189,"mc":[{"id":"1.168238841","rc":[{"batb":[[0,3.2,30.29],[1,1.02,2],[2,1.01,1.01]],"ltp":0.0,"tv":0.0,"id":16858291}]}]}
{"op":"mcm","clk":"1007835350","pt":1580657116281,"mc":[{"id":"1.168238841","rc":[{"batb":[[0,3.2,110.26]],"ltp":0.0,"tv":0.0,"id":16858291},{"batb":[[0,2.68,30.29],[1,2.62,98.04],[2,1.02,2]],"ltp":0.0,"tv":0.0,"id":13460814}]}]}
{"op":"mcm","clk":"1007835420","pt":1580657116587,"mc":[{"id":"1.168238841","rc":[{"batb":[[0,2.78,92.16],[1,2.68,30.29]],"ltp":0.0,"tv":0.0,"id":13460814}]}]}
{"op":"mcm","clk":"1007862917","pt":1580657237062,"mc":[{"id":"1.168238841","rc":[{"batb":[[0,3.25,30.29]],"batl":[[0,7,311.72]],"ltp":0.0,"tv":0.0,"id":16858291},{"batb":[[0,2.8,30.29],[1,2.78,92.16]],"ltp":0.0,"tv":0.0,"id":13460814}]}]}
{"op":"mcm","clk":"1007863049","pt":1580657237556,"mc":[{"id":"1.168238841","rc":[{"batb":[[0,2.82,91.03],[1,2.8,30.29]],"ltp":0.0,"tv":0.0,"id":13460814}]}]}
{"op":"mcm","clk":"1007881443","pt":1580657316938,"mc":[{"id":"1.168238841","rc":[{"batb":[[0,2.76,92.98],[1,1.02,2],[2,1.01,1.01]],"ltp":0.0,"tv":0.0,"id":13460817}]}]}
{"op":"mcm","clk":"1007890900","pt":1580657358227,"mc":[{"id":"1.168238841","rc":[{"batb":[[0,3,30.29]],"ltp":0.0,"tv":0.0,"id":16858291}]}]}
{"op":"mcm","clk":"1007891122","pt":1580657359183,"mc":[{"id":"1.168238841","rc":[{"batb":[[0,3.1,82.54],[1,3,30.29],[2,1.02,2]],"ltp":0.0,"tv":0.0,"id":16858291},{"batb":[[0,2.84,30.29],[1,1.02,2],[2,1.01,1.01]],"ltp":0.0,"tv":0.0,"id":13460814}]}]}
{"op":"mcm","clk":"1007891173","pt":1580657359388,"mc":[{"id":"1.168238841","rc":[{"batb":[[0,2.92,87.69],[1,2.84,30.29],[2,1.02,2]],"ltp":0.0,"tv":0.0,"id":13460814}]}]}
{"op":"mcm","clk":"1007917917","pt":1580657480224,"mc":[{"id":"1.168238841","rc":[{"batb":[[0,3.2,79.97],[1,3.15,30.29]],"ltp":0.0,"tv":0.0,"id":16858291}]}]}
{"op":"mcm","clk":"1007918098","pt":1580657481035,"mc":[{"id":"1.168238841","rc":[{"batb":[[0,2.96,86.63],[1,2.94,30.29]],"ltp":0.0,"tv":0.0,"id":13460814}]}]}
{"op":"mcm","clk":"1007945126","pt":1580657602174,"mc":[{"id":"1.168238841","rc":[{"batb":[[0,3.25,30.29],[1,1.02,2],[2,1.01,1.01]],"ltp":0.0,"tv":0.0,"id":16858291},{"batb":[[1,1.02,2],[2,1.01,1.01]],"ltp":0.0,"tv":0.0,"id":13460814}]}]}
{"op":"mcm","clk":"1007945268","pt":1580657602781,"mc":[{"id":"1.168238841","rc":[{"batb":[[0,3,85.57],[1,2.98,30.29],[2,1.02,2]],"ltp":0.0,"tv":0.0,"id":13460814}]}]}
{"op":"mcm","clk":"1007972666","pt":1580657723150,"mc":[{"id":"1.168238841","rc":[{"batb":[[0,3,30.29]],"ltp":0.0,"tv":0.0,"id":16858291}]}]}
{"op":"mcm","clk":"1007972841","pt":1580657724036,"mc":[{"id":"1.168238841","rc":[{"batb":[[0,3.05,84.09],[1,3,30.29],[2,1.02,2]],"ltp":0.0,"tv":0.0,"id":16858291},{"batb":[[0,3.05,30.29],[1,1.02,2],[2,1.01,1.01]],"batl":[[0,7,260.29]],"ltp":0.0,"tv":0.0,"id":13460814}]}]}
{"op":"mcm","clk":"1007999089","pt":1580657845125,"mc":[{"id":"1.168238841","rc":[{"batb":[[0,3.1,30.29],[1,1.02,2],[2,1.01,1.01]],"ltp":0.0,"tv":0.0,"id":16858291}]}]}
{"op":"mcm","clk":"1007999313","pt":1580657846091,"mc":[{"id":"1.168238841","rc":[{"batb":[[0,3.15,81.23],[1,3.1,30.29],[2,1.02,2]],"ltp":0.0,"tv":0.0,"id":16858291},{"batb":[[0,2.66,30.29]],"ltp":0.0,"tv":0.0,"id":13460814}]}]}
{"op":"mcm","clk":"1007999393","pt":1580657846454,"mc":[{"id":"1.168238841","rc":[{"batb":[[0,2.78,92.16],[1,2.66,30.29],[2,1.02,2]],"ltp":0.0,"tv":0.0,"id":13460814}]}]}
{"op":"mcm","clk":"1008027015","pt":1580657968136,"mc":[{"id":"1.168238841","rc":[{"batb":[[0,3.2,110.26],[1,1.02,2],[2,1.01,1.01]],"ltp":0.0,"tv":0.0,"id":16858291},{"batb":[[0,2.8,30.29],[1,2.78,92.16]],"ltp":0.0,"tv":0.0,"id":13460814}]}]}
{"op":"mcm","clk":"1008027125","pt":1580657968620,"mc":[{"id":"1.168238841","rc":[{"batb":[[0,2.86,89.68],[1,2.8,30.29]],"ltp":0.0,"tv":0.0,"id":13460814}]}]}
{"op":"mcm","clk":"1008055795","pt":1580658089214,"mc":[{"id":"1.168238841","rc":[{"batb":[[0,3.25,30.29],[1,3.2,79.97],[2,1.02,2]],"ltp":0.0,"tv":0.0,"id":16858291}]}]}
{"op":"mcm","clk":"1008056025","pt":1580658090290,"mc":[{"id":"1.168238841","rc":[{"batb":[[1,1.02,2],[2,1.01,1.01]],"ltp":0.0,"tv":0.0,"id":16858291},{"batb":[[0,2.88,30.28],[1,2.86,89.68]],"ltp":0.0,"tv":0.0,"id":13460814}]}]}
{"op":"mcm","clk":"1008056118","pt":1580658090669,"mc":[{"id":"1.168238841","rc":[{"batb":[[0,2.9,88.36],[1,2.88,30.28]],"ltp":0.0,"tv":0.0,"id":13460814}]}]}
{"op":"mcm","clk":"1008084741","pt":1580658211153,"mc":[{"id":"1.168238841","rc":[{"batb":[[0,3,30.29],[1,2.94,87.09],[2,1.02,2]],"ltp":0.0,"tv":0.0,"id":16858291}]}]}
{"op":"mcm","clk":"1008084888","pt":1580658211875,"mc":[{"id":"1.168238841","rc":[{"batb":[[0,3.05,84.09],[1,3,30.29]],"ltp":0.0,"tv":0.0,"id":16858291},{"batb":[[0,2.92,30.29],[1,2.9,88.36]],"ltp":0.0,"tv":0.0,"id":13460814}]}]}
{"op":"mcm","clk":"1008085027","pt":1580658212496,"mc":[{"id":"1.168238841","rc":[{"batb":[[0,2.94,87.09],[1,2.92,30.29]],"ltp":0.0,"tv":0.0,"id":13460814}]}]}
{"op":"mcm","clk":"1008112816","pt":1580658333170,"mc":[{"id":"1.168238841","rc":[{"batb":[[0,3.15,81.23],[1,3.1,30.29]],"ltp":0.0,"tv":0.0,"id":16858291},{"batb":[[0,2.96,30.29],[1,2.94,87.09]],"ltp":0.0,"tv":0.0,"id":13460814}]}]}
{"op":"mcm","clk":"1008112907","pt":1580658333581,"mc":[{"id":"1.168238841","rc":[{"batb":[[0,2.98,85.9],[1,2.96,30.29]],"ltp":0.0,"tv":0.0,"id":13460814}]}]}
{"op":"mcm","clk":"1008137664","pt":1580658454210,"mc":[{"id":"1.168238841","rc":[{"batb":[[0,3.2,30.29],[1,3.15,81.23]],"ltp":0.0,"tv":0.0,"id":16858291}]}]}
{"op":"mcm","clk":"1008137808","pt":1580658454947,"mc":[{"id":"1.168238841","rc":[{"batb":[[0,3.2,110.26],[1,1.02,2],[2,1.01,1.01]],"ltp":0.0,"tv":0.0,"id":16858291},{"batb":[[0,3,30.29],[1,2.98,85.9]],"ltp":0.0,"tv":0.0,"id":13460814}]}]}
{"op":"mcm","clk":"1008137915","pt":1580658455429,"mc":[{"id":"1.168238841","rc":[{"batb":[[0,3,115.86],[1,1.02,2],[2,1.01,1.01]],"ltp":0.0,"tv":0.0,"id":13460814}]}]}
{"op":"mcm","clk":"1008159683","pt":1580658567693,"mc":[{"id":"1.168238841","rc":[{"batl":[[0,7,37.06]],"ltp":0.0,"tv":0.0,"id":16858291},{"batl":[[0,14,185.59]],"ltp":0.0,"tv":0.0,"id":13460817}]}]}
{"op":"mcm","clk":"1008161221","pt":1580658576008,"mc":[{"id":"1.168238841","rc":[{"batb":[[0,3.25,30.29],[1,3.2,79.97],[2,1.02,2]],"ltp":0.0,"tv":0.0,"id":16858291}]}]}
{"op":"mcm","clk":"1008161440","pt":1580658577277,"mc":[{"id":"1.168238841","rc":[{"batb":[[1,1.02,2],[2,1.01,1.01]],"ltp":0.0,"tv":0.0,"id":16858291},{"batb":[[0,3.05,30.29]],"ltp":0.0,"tv":0.0,"id":13460814}]}]}
{"op":"mcm","clk":"1008179378","pt":1580658680233,"mc":[{"id":"1.168238841","rc":[{"batl":[[0,7,322.54]],"ltp":0.0,"tv":0.0,"id":16858291}]}]}
{"op":"mcm","clk":"1008182168","pt":1580658698231,"mc":[{"id":"1.168238841","rc":[{"batb":[[0,3.1,82.54],[1,3,30.29],[2,1.02,2]],"ltp":0.0,"tv":0.0,"id":16858291},{"batb":[[0,1.02,2],[1,1.01,1.01],[2,1.01,0]],"ltp":0.0,"tv":0.0,"id":13460814}]}]}
{"op":"mcm","clk":"1008182261","pt":1580658698815,"mc":[{"id":"1.168238841","rc":[{"batb":[[0,2.86,89.68],[1,2.66,30.29],[2,1.02,2]],"ltp":0.0,"tv":0.0,"id":13460814}]}]}
{"op":"mcm","clk":"1008201419","pt":1580658819210,"mc":[{"id":"1.168238841","rc":[{"batb":[[1,1.02,2],[2,1.01,1.01]],"ltp":0.0,"tv":0.0,"id":16858291}]}]}
{"op":"mcm","clk":"1008201611","pt":1580658820271,"mc":[{"id":"1.168238841","rc":[{"batb":[[0,3.2,79.97],[1,3.15,30.29],[2,1.02,2]],"ltp":0.0,"tv":0.0,"id":16858291},{"batb":[[0,2.88,30.28],[1,2.86,89.68]],"ltp":0.0,"tv":0.0,"id":13460814}]}]}
{"op":"mcm","clk":"1008201677","pt":1580658820693,"mc":[{"id":"1.168238841","rc":[{"batb":[[0,2.94,87.09],[1,2.88,30.28]],"ltp":0.0,"tv":0.0,"id":13460814}]}]}
{"op":"mcm","clk":"1008220994","pt":1580658941154,"mc":[{"id":"1.168238841","rc":[{"batb":[[0,3.25,30.29],[1,1.02,2],[2,1.01,1.01]],"ltp":0.0,"tv":0.0,"id":16858291}]}]}
{"op":"mcm","clk":"1008221158","pt":1580658942198,"mc":[{"id":"1.168238841","rc":[{"batb":[[0,2.96,30.29],[1,1.02,2],[2,1.01,1.01]],"ltp":0.0,"tv":0.0,"id":13460814}]}]}
{"op":"mcm","clk":"1008221192","pt":1580658942406,"mc":[{"id":"1.168238841","rc":[{"batb":[[0,2.98,85.9],[1,2.96,30.29],[2,1.02,2]],"ltp":0.0,"tv":0.0,"id":13460814}]}]}
{"op":"mcm","clk":"1008240971","pt":1580659063208,"mc":[{"id":"1.168238841","rc":[{"batb":[[0,3,30.29]],"ltp":0.0,"tv":0.0,"id":16858291},{"batb":[[0,3,30.29],[1,2.98,85.9]],"ltp":0.0,"tv":0.0,"id":13460814}]}]}
{"op":"mcm","clk":"1008241045","pt":1580659063624,"mc":[{"id":"1.168238841","rc":[{"batb":[[0,3.1,82.54],[1,3,30.29],[2,1.02,2]],"ltp":0.0,"tv":0.0,"id":16858291},{"batb":[[0,3,115.86],[1,1.02,2],[2,1.01,1.01]],"ltp":0.0,"tv":0.0,"id":13460814}]}]}
{"op":"mcm","clk":"1008259138","pt":1580659184225,"mc":[{"id":"1.168238841","rc":[{"batb":[[1,1.02,2],[2,1.01,1.01]],"ltp":0.0,"tv":0.0,"id":16858291}]}]}
{"op":"mcm","clk":"1008259279","pt":1580659185033,"mc":[{"id":"1.168238841","rc":[{"batb":[[0,3.2,79.97],[1,3.15,30.29],[2,1.02,2]],"ltp":0.0,"tv":0.0,"id":16858291},{"batb":[[0,3.05,30.29],[1,3,85.57],[2,1.02,2]],"ltp":0.0,"tv":0.0,"id":13460814}]}]}
{"op":"mcm","clk":"1008259369","pt":1580659185639,"mc":[{"id":"1.168238841","rc":[{"batb":[[1,1.02,2],[2,1.01,1.01]],"ltp":0.0,"tv":0.0,"id":13460814}]}]}
{"op":"mcm","clk":"1008264399","pt":1580659213179,"mc":[{"id":"1.168238841","rc":[{"batb":[[0,3.1,82.54],[1,1.02,2],[2,1.01,1.01]],"batl":[[0,8.4,305.84]],"ltp":0.0,"tv":0.0,"id":16858293}]}]}
{"op":"mcm","clk":"1008281225","pt":1580659306061,"mc":[{"id":"1.168238841","rc":[{"batb":[[0,3.25,30.29],[1,3.2,79.97]],"ltp":0.0,"tv":0.0,"id":16858291}]}]}
{"op":"mcm","clk":"1008281479","pt":1580659307234,"mc":[{"id":"1.168238841","rc":[{"batb":[[1,1.02,2],[2,1.01,1.01]],"ltp":0.0,"tv":0.0,"id":16858291},{"batb":[[0,2.66,30.29]],"ltp":0.0,"tv":0.0,"id":13460814}]}]}
{"op":"mcm","clk":"1008281513","pt":1580659307444,"mc":[{"id":"1.168238841","rc":[{"batb":[[0,2.7,94.92],[1,2.66,30.29],[2,1.02,2]],"ltp":0.0,"tv":0.0,"id":13460814}]}]}
{"op":"mcm","clk":"1008304346","pt":1580659428048,"mc":[{"id":"1.168238841","rc":[{"batb":[[0,3,30.29]],"ltp":0.0,"tv":0.0,"id":16858291}]}]}
{"op":"mcm","clk":"1008304516","pt":1580659428957,"mc":[{"id":"1.168238841","rc":[{"batb":[[0,3.1,82.54],[1,3,30.29],[2,1.02,2]],"ltp":0.0,"tv":0.0,"id":16858291},{"batb":[[0,2.72,30.29],[1,2.7,94.92]],"ltp":0.0,"tv":0.0,"id":13460814}]}]}
{"op":"mcm","clk":"1008304634","pt":1580659429595,"mc":[{"id":"1.168238841","rc":[{"batb":[[0,2.94,87.09],[1,2.72,30.29]],"ltp":0.0,"tv":0.0,"id":13460814}]}]}
{"op":"mcm","clk":"1008327528","pt":1580659549270,"mc":[{"id":"1.168238841","rc":[{"batb":[[1,1.02,2],[2,1.01,1.01]],"ltp":0.0,"tv":0.0,"id":16858291}]}]}
{"op":"mcm","clk":"1008327720","pt":1580659550108,"mc":[{"id":"1.168238841","rc":[{"batb":[[0,3.2,79.97],[1,3.15,30.29],[2,1.02,2]],"ltp":0.0,"tv":0.0,"id":16858291},{"batb":[[0,2.96,30.29],[1,2.94,87.09]],"ltp":0.0,"tv":0.0,"id":13460814}]}]}
{"op":"mcm","clk":"1008327854","pt":1580659550661,"mc":[{"id":"1.168238841","rc":[{"batb":[[0,2.98,85.9],[1,2.96,30.29]],"ltp":0.0,"tv":0.0,"id":13460814}]}]}
{"op":"mcm","clk":"1008353371","pt":1580659671262,"mc":[{"id":"1.168238841","rc":[{"batb":[[0,3.25,30.29],[1,1.02,2],[2,1.01,1.01]],"ltp":0.0,"tv":0.0,"id":16858291}]}]}
{"op":"mcm","clk":"1008353571","pt":1580659672130,"mc":[{"id":"1.168238841","rc":[{"batb":[[0,3,30.29],[1,1.02,2],[2,1.01,1.01]],"ltp":0.0,"tv":0.0,"id":13460814}]}]}
{"op":"mcm","clk":"1008353621","pt":1580659672339,"mc":[{"id":"1.168238841","rc":[{"batb":[[0,3,115.86]],"ltp":0.0,"tv":0.0,"id":13460814}]}]}
{"op":"mcm","clk":"1008380510","pt":1580659793041,"mc":[{"id":"1.168238841","rc":[{"batb":[[0,3,30.29],[1,2.64,97.32],[2,1.02,2]],"ltp":0.0,"tv":0.0,"id":16858291}]}]}
{"op":"mcm","clk":"1008380659","pt":1580659793646,"mc":[{"id":"1.168238841","rc":[{"batb":[[0,3.05,84.09],[1,3,30.29]],"ltp":0.0,"tv":0.0,"id":16858291},{"batb":[[0,3.05,30.29]],"ltp":0.0,"tv":0.0,"id":13460814}]}]}
{"op":"mcm","clk":"1008407761","pt":1580659914192,"mc":[{"id":"1.168238841","rc":[{"batb":[[1,1.02,2],[2,1.01,1.01]],"ltp":0.0,"tv":0.0,"id":16858291}]}]}
{"op":"mcm","clk":"1008407999","pt":1580659915062,"mc":[{"id":"1.168238841","rc":[{"batb":[[0,3.15,81.23],[1,3.1,30.29],[2,1.02,2]],"ltp":0.0,"tv":0.0,"id":16858291},{"batb":[[0,2.66,30.29]],"ltp":0.0,"tv":0.0,"id":13460814}]}]}
{"op":"mcm","clk":"1008408221","pt":1580659916003,"mc":[{"id":"1.168238841","rc":[{"batb":[[0,2.92,87.69],[1,2.66,30.29],[2,1.02,2]],"ltp":0.0,"tv":0.0,"id":13460814}]}]}
{"op":"mcm","clk":"1008435670","pt":1580660036018,"mc":[{"id":"1.168238841","rc":[{"batb":[[0,3.2,30.29],[1,3.15,81.23]],"ltp":0.0,"tv":0.0,"id":16858291}]}]}
{"op":"mcm","clk":"1008435922","pt":1580660037074,"mc":[{"id":"1.168238841","rc":[{"batb":[[0,3.2,110.26],[1,1.02,2],[2,1.01,1.01]],"ltp":0.0,"tv":0.0,"id":16858291},{"batb":[[0,2.96,86.63],[1,2.94,30.29]],"ltp":0.0,"tv":0.0,"id":13460814}]}]}
{"op":"mcm","clk":"1008464312","pt":1580660158251,"mc":[{"id":"1.168238841","rc":[{"batb":[[0,3.25,30.29],[1,3.2,79.97],[2,1.02,2]],"ltp":0.0,"tv":0.0,"id":16858291}]}]}
{"op":"mcm","clk":"1008464512","pt":1580660159166,"mc":[{"id":"1.168238841","rc":[{"batb":[[1,1.02,2],[2,1.01,1.01]],"ltp":0.0,"tv":0.0,"id":16858291},{"batb":[[0,2.98,30.29],[1,1.02,2],[2,1.01,1.01]],"ltp":0.0,"tv":0.0,"id":13460814}]}]}
{"op":"mcm","clk":"1008464549","pt":1580660159368,"mc":[{"id":"1.168238841","rc":[{"batb":[[0,3,85.57],[1,2.98,30.29],[2,1.02,2]],"ltp":0.0,"tv":0.0,"id":13460814}]}]}
{"op":"mcm","clk":"1008493250","pt":1580660280261,"mc":[{"id":"1.168238841","rc":[{"batb":[[0,3.05,84.09],[1,3,30.29],[2,1.02,2]],"ltp":0.0,"tv":0.0,"id":16858291},{"batb":[[0,3.05,30.29],[1,3,85.57]],"ltp":0.0,"tv":0.0,"id":13460814}]}]}
{"op":"mcm","clk":"1008493334","pt":1580660280539,"mc":[{"id":"1.168238841","rc":[{"batb":[[1,1.02,2],[2,1.01,1.01]],"ltp":0.0,"tv":0.0,"id":13460814}]}]}
{"op":"mcm","clk":"1008496453","pt":1580660294048,"mc":[{"id":"1.168238841","rc":[{"batl":[[0,8.4,30.69]],"ltp":0.0,"tv":0.0,"id":16858293}]}]}
{"op":"mcm","clk":"1008521093","pt":1580660401119,"mc":[{"id":"1.168238841","rc":[{"batb":[[0,3.1,30.29],[1,3.05,84.09]],"ltp":0.0,"tv":0.0,"id":16858291}]}]}
{"op":"mcm","clk":"1008521388","pt":1580660402241,"mc":[{"id":"1.168238841","rc":[{"batb":[[0,3.15,81.23],[1,3.1,30.29]],"ltp":0.0,"tv":0.0,"id":16858291},{"batb":[[0,2.76,92.98],[1,2.66,30.29],[2,1.02,2]],"ltp":0.0,"tv":0.0,"id":13460814}]}]}
{"op":"mcm","clk":"1008524172","pt":1580660413303,"mc":[{"id":"1.168238841","rc":[{"batl":[[0,8.4,304.49]],"ltp":0.0,"tv":0.0,"id":16858293}]}]}
{"op":"mcm","clk":"1008549560","pt":1580660523179,"mc":[{"id":"1.168238841","rc":[{"batb":[[0,3.2,110.26],[1,1.02,2],[2,1.01,1.01]],"ltp":0.0,"tv":0.0,"id":16858291},{"batb":[[1,1.02,2],[2,1.01,1.01]],"ltp":0.0,"tv":0.0,"id":13460814}]}]}
{"op":"mcm","clk":"1008549716","pt":1580660523820,"mc":[{"id":"1.168238841","rc":[{"batb":[[0,2.88,88.96],[1,2.78,30.29],[2,1.02,2]],"ltp":0.0,"tv":0.0,"id":13460814}]}]}
{"op":"mcm","clk":"1008576785","pt":1580660645252,"mc":[{"id":"1.168238841","rc":[{"batb":[[0,3.25,30.29]],"ltp":0.0,"tv":0.0,"id":16858291},{"batb":[[0,2.9,30.29],[1,2.88,88.96]],"ltp":0.0,"tv":0.0,"id":13460814}]}]}
{"op":"mcm","clk":"1008576874","pt":1580660645678,"mc":[{"id":"1.168238841","rc":[{"batb":[[0,2.96,86.63],[1,2.9,30.29]],"ltp":0.0,"tv":0.0,"id":13460814}]}]}
{"op":"mcm","clk":"1008589787","pt":1580660703970,"mc":[{"id":"1.168238841","rc":[{"batb":[[0,3.25,109.02]],"batl":[[0,7,37.06]],"ltp":0.0,"tv":0.0,"id":16858291},{"batl":[[0,7,37.06]],"ltp":0.0,"tv":0.0,"id":13460814}]}]}
{"op":"mcm","clk":"1008594278","pt":1580660724333,"mc":[{"id":"1.168238841","rc":[{"batl":[[0,7,250.56]],"ltp":0.0,"tv":0.0,"id":13460814}]}]}
{"op":"mcm","clk":"1008602897","pt":1580660766159,"mc":[{"id":"1.168238841","rc":[{"batb":[[0,3.3,30.29],[1,3.25,78.73],[2,1.02,2]],"ltp":0.0,"tv":0.0,"id":16858291}]}]}
{"op":"mcm","clk":"1008603053","pt":1580660766998,"mc":[{"id":"1.168238841","rc":[{"batb":[[1,1.02,2],[2,1.01,1.01]],"ltp":0.0,"tv":0.0,"id":16858291},{"batb":[[0,2.98,30.29],[1,2.96,86.63]],"ltp":0.0,"tv":0.0,"id":13460814}]}]}
{"op":"mcm","clk":"1008603170","pt":1580660767400,"mc":[{"id":"1.168238841","rc":[{"batb":[[0,3,85.57],[1,2.98,30.29]],"ltp":0.0,"tv":0.0,"id":13460814}]}]}
{"op":"mcm","clk":"1008605958","pt":1580660780601,"mc":[{"id":"1.168238841","rc":[{"batl":[[0,7,333.58]],"ltp":0.0,"tv":0.0,"id":16858291}]}]}
{"op":"mcm","clk":"1008618241","pt":1580660838086,"mc":[{"id":"1.168238841","rc":[{"batl":[[0,7.2,324.34]],"ltp":0.0,"tv":0.0,"id":16858291}]}]}
{"op":"mcm","clk":"1008629073","pt":1580660888063,"mc":[{"id":"1.168238841","rc":[{"batb":[[0,3,30.29],[1,2.54,101.12],[2,1.02,2]],"ltp":0.0,"tv":0.0,"id":16858291}]}]}
{"op":"mcm","clk":"1008629269","pt":1580660888939,"mc":[{"id":"1.168238841","rc":[{"batb":[[0,3.2,79.97],[1,3,30.29]],"ltp":0.0,"tv":0.0,"id":16858291},{"batb":[[0,3.05,30.29],[1,3,85.57]],"ltp":0.0,"tv":0.0,"id":13460814}]}]}
{"op":"mcm","clk":"1008629310","pt":1580660889311,"mc":[{"id":"1.168238841","rc":[{"batb":[[1,1.02,2],[2,1.01,1.01]],"ltp":0.0,"tv":0.0,"id":13460814}]}]}
{"op":"mcm","clk":"1008635558","pt":1580660917010,"mc":[{"id":"1.168238841","rc":[{"batb":[[0,1.02,2],[1,1.01,1.01],[2,1.01,0]],"ltp":0.0,"tv":0.0,"id":13460817}]}]}
{"op":"mcm","clk":"1008636835","pt":1580660923212,"mc":[{"id":"1.168238841","rc":[{"batb":[[0,2.76,92.98],[1,1.02,2],[2,1.01,1.01]],"ltp":0.0,"tv":0.0,"id":13460817}]}]}
{"op":"mcm","clk":"1008654915","pt":1580661010283,"mc":[{"id":"1.168238841","rc":[{"batb":[[0,3.25,109.02],[1,1.02,2],[2,1.01,1.01]],"ltp":0.0,"tv":0.0,"id":16858291},{"batb":[[0,2.66,30.29],[1,2.2,116.72],[2,1.02,2]],"ltp":0.0,"tv":0.0,"id":13460814}]}]}
{"op":"mcm","clk":"1008655013","pt":1580661010670,"mc":[{"id":"1.168238841","rc":[{"batb":[[0,2.82,91.03],[1,2.66,30.29]],"ltp":0.0,"tv":0.0,"id":13460814}]}]}
{"op":"mcm","clk":"1008681282","pt":1580661131166,"mc":[{"id":"1.168238841","rc":[{"batb":[[0,3.3,30.29],[1,3.25,78.73],[2,1.02,2]],"ltp":0.0,"tv":0.0,"id":16858291}]}]}
{"op":"mcm","clk":"1008681500","pt":1580661132162,"mc":[{"id":"1.168238841","rc":[{"batb":[[1,1.02,2],[2,1.01,1.01]],"ltp":0.0,"tv":0.0,"id":16858291},{"batb":[[0,2.86,89.68],[1,2.84,30.29]],"ltp":0.0,"tv":0.0,"id":13460814}]}]}
{"op":"mcm","clk":"1008707686","pt":1580661253197,"mc":[{"id":"1.168238841","rc":[{"batb":[[0,3,30.29]],"ltp":0.0,"tv":0.0,"id":16858291},{"batb":[[1,1.02,2],[2,1.01,1.01]],"ltp":0.0,"tv":0.0,"id":13460814}]}]}
{"op":"mcm","clk":"1008707882","pt":1580661254189,"mc":[{"id":"1.168238841","rc":[{"batb":[[0,3.05,84.09],[1,3,30.29],[2,1.02,2]],"ltp":0.0,"tv":0.0,"id":16858291},{"batb":[[0,2.9,88.36],[1,2.88,30.28],[2,1.02,2]],"ltp":0.0,"tv":0.0,"id":13460814}]}]}
{"op":"mcm","clk":"1008722770","pt":1580661324589,"mc":[{"id":"1.168238841","rc":[{"batl":[[0,5.8,301.97]],"ltp":0.0,"tv":0.0,"id":13460814}]}]}
{"op":"mcm","clk":"1008733607","pt":1580661375058,"mc":[{"id":"1.168238841","rc":[{"batb":[[0,3.2,79.97],[1,3.1,30.29]],"ltp":0.0,"tv":0.0,"id":16858291},{"batb":[[1,1.02,2],[2,1.01,1.01]],"ltp":0.0,"tv":0.0,"id":13460814}]}]}
{"op":"mcm","clk":"1008733807","pt":1580661375970,"mc":[{"id":"1.168238841","rc":[{"batb":[[0,2.94,87.09],[1,2.92,30.29],[2,1.02,2]],"ltp":0.0,"tv":0.0,"id":13460814}]}]}
{"op":"mcm","clk":"1008760904","pt":1580661496105,"mc":[{"id":"1.168238841","rc":[{"batb":[[0,3.25,30.29],[1,3.2,79.97]],"ltp":0.0,"tv":0.0,"id":16858291}]}]}
{"op":"mcm","clk":"1008761159","pt":1580661497229,"mc":[{"id":"1.168238841","rc":[{"batb":[[0,3.25,109.02],[1,1.02,2],[2,1.01,1.01]],"ltp":0.0,"tv":0.0,"id":16858291},{"batb":[[0,2.96,116.92],[1,1.02,2],[2,1.01,1.01]],"ltp":0.0,"tv":0.0,"id":13460814}]}]}
{"op":"mcm","clk":"1008787566","pt":1580661618284,"mc":[{"id":"1.168238841","rc":[{"batb":[[0,3.25,78.73]],"ltp":0.0,"tv":0.0,"id":16858291}]}]}
{"op":"mcm","clk":"1008787861","pt":1580661619218,"mc":[{"id":"1.168238841","rc":[{"batb":[[0,3.3,30.29]],"ltp":0.0,"tv":0.0,"id":16858291},{"batb":[[0,2.98,30.29]],"ltp":0.0,"tv":0.0,"id":13460814}]}]}
{"op":"mcm","clk":"1008813561","pt":1580661740238,"mc":[{"id":"1.168238841","rc":[{"batb":[[0,3,30.29],[1,2.54,101.12],[2,1.02,2]],"ltp":0.0,"tv":0.0,"id":16858291}]}]}
{"op":"mcm","clk":"1008813765","pt":1580661741162,"mc":[{"id":"1.168238841","rc":[{"batb":[[0,3.1,82.54],[1,3,30.29]],"ltp":0.0,"tv":0.0,"id":16858291},{"batb":[[0,2.76,92.98],[1,2.66,30.29],[2,1.02,2]],"ltp":0.0,"tv":0.0,"id":13460814}]}]}
{"op":"mcm","clk":"1008838255","pt":1580661861185,"mc":[{"id":"1.168238841","rc":[{"batb":[[0,3.15,30.29],[1,3.1,82.54]],"ltp":0.0,"tv":0.0,"id":16858291}]}]}
{"op":"mcm","clk":"1008838463","pt":1580661862097,"mc":[{"id":"1.168238841","rc":[{"batb":[[0,3.2,79.97],[1,3.15,30.29]],"ltp":0.0,"tv":0.0,"id":16858291},{"batb":[[0,2.78,30.29],[1,1.02,2],[2,1.01,1.01]],"ltp":0.0,"tv":0.0,"id":13460814}]}]}
{"op":"mcm","clk":"1008838503","pt":1580661862315,"mc":[{"id":"1.168238841","rc":[{"batb":[[0,2.8,91.48],[1,2.78,30.29],[2,1.02,2]],"ltp":0.0,"tv":0.0,"id":13460814}]}]}
{"op":"mcm","clk":"1008863500","pt":1580661983232,"mc":[{"id":"1.168238841","rc":[{"batb":[[0,3.25,109.02],[1,1.02,2],[2,1.01,1.01]],"ltp":0.0,"tv":0.0,"id":16858291}]}]}
{"op":"mcm","clk":"1008863640","pt":1580661983852,"mc":[{"id":"1.168238841","rc":[{"batb":[[0,2.84,90.22],[1,2.82,30.29]],"ltp":0.0,"tv":0.0,"id":13460814}]}]}
{"op":"mcm","clk":"1008885299","pt":1580662105084,"mc":[{"id":"1.168238841","rc":[{"batb":[[0,3.3,30.29]],"ltp":0.0,"tv":0.0,"id":16858291},{"batb":[[0,2.86,30.29],[1,2.84,90.22]],"ltp":0.0,"tv":0.0,"id":13460814}]}]}
{"op":"mcm","clk":"1008885363","pt":1580662105497,"mc":[{"id":"1.168238841","rc":[{"batb":[[0,2.88,88.96],[1,2.86,30.29]],"ltp":0.0,"tv":0.0,"id":13460814}]}]}
{"op":"mcm","clk":"1008895358","pt":1580662167938,"mc":[{"id":"1.168238841","rc":[{"batl":[[0,11,236.11]],"ltp":0.0,"tv":0.0,"id":13460817}]}]}
{"op":"mcm","clk":"1008904192","pt":1580662226189,"mc":[{"id":"1.168238841","rc":[{"batb":[[0,3,30.29]],"ltp":0.0,"tv":0.0,"id":16858291}]}]}
{"op":"mcm","clk":"1008904340","pt":1580662227094,"mc":[{"id":"1.168238841","rc":[{"batb":[[0,3.05,84.09],[1,3,30.29],[2,1.02,2]],"ltp":0.0,"tv":0.0,"id":16858291},{"batb":[[0,2.92,87.69],[1,2.9,30.29]],"ltp":0.0,"tv":0.0,"id":13460814}]}]}
{"op":"mcm","clk":"1008921482","pt":1580662348219,"mc":[{"id":"1.168238841","rc":[{"batb":[[0,3.15,81.23],[1,3.1,30.29]],"ltp":0.0,"tv":0.0,"id":16858291}]}]}
{"op":"mcm","clk":"1008921602","pt":1580662349013,"mc":[{"id":"1.168238841","rc":[{"batb":[[0,2.96,86.63],[1,2.94,30.29]],"ltp":0.0,"tv":0.0,"id":13460814}]}]}
{"op":"mcm","clk":"1008937786","pt":1580662470083,"mc":[{"id":"1.168238841","rc":[{"batb":[[0,3.2,30.29],[1,3.15,81.23]],"ltp":0.0,"tv":0.0,"id":16858291}]}]}
{"op":"mcm","clk":"1008937928","pt":1580662471055,"mc":[{"id":"1.168238841","rc":[{"batb":[[0,3.25,78.73],[1,3.2,30.29]],"ltp":0.0,"tv":0.0,"id":16858291},{"batb":[[0,2.98,30.29],[1,1.02,2],[2,1.01,1.01]],"ltp":0.0,"tv":0.0,"id":13460814}]}]}
{"op":"mcm","clk":"1008953722","pt":1580662591215,"mc":[{"id":"1.168238841","rc":[{"batb":[[0,3.3,30.29],[1,3.25,78.73]],"ltp":0.0,"tv":0.0,"id":16858291}]}]}
{"op":"mcm","clk":"1008953856","pt":1580662592238,"mc":[{"id":"1.168238841","rc":[{"batb":[[1,1.02,2],[2,1.01,1.01]],"ltp":0.0,"tv":0.0,"id":16858291},{"batb":[[0,2.66,30.29]],"ltp":0.0,"tv":0.0,"id":13460814}]}]}
{"op":"mcm","clk":"1008953905","pt":1580662592438,"mc":[{"id":"1.168238841","rc":[{"batb":[[0,2.68,95.61],[1,2.66,30.29],[2,1.02,2]],"ltp":0.0,"tv":0.0,"id":13460814}]}]}
{"op":"mcm","clk":"1008969193","pt":1580662713204,"mc":[{"id":"1.168238841","rc":[{"batb":[[0,3,30.29]],"ltp":0.0,"tv":0.0,"id":16858291}]}]}
{"op":"mcm","clk":"1008969334","pt":1580662714196,"mc":[{"id":"1.168238841","rc":[{"batb":[[0,3.05,84.09],[1,3,30.29],[2,1.02,2]],"ltp":0.0,"tv":0.0,"id":16858291},{"batb":[[0,2.76,92.98],[1,2.7,30.28]],"ltp":0.0,"tv":0.0,"id":13460814}]}]}
{"op":"mcm","clk":"1008981511","pt":1580662813206,"mc":[{"id":"1.168238841","rc":[{"batb":[[0,1.02,2],[1,1.01,1.01],[2,1.01,0]],"ltp":0.0,"tv":0.0,"id":16858293}]}]}
{"op":"mcm","clk":"1008981657","pt":1580662814340,"mc":[{"id":"1.168238841","rc":[{"batl":[[0,11,232.82]],"ltp":0.0,"tv":0.0,"id":16858293}]}]}
{"op":"mcm","clk":"1008984171","pt":1580662835143,"mc":[{"id":"1.168238841","rc":[{"batb":[[0,3.2,79.97],[1,3.1,30.29]],"ltp":0.0,"tv":0.0,"id":16858291},{"batb":[[1,1.02,2],[2,1.01,1.01]],"ltp":0.0,"tv":0.0,"id":13460814}]}]}
{"op":"mcm","clk":"1008984265","pt":1580662835928,"mc":[{"id":"1.168238841","rc":[{"batb":[[0,2.8,91.48],[1,2.78,30.29],[2,1.02,2]],"ltp":0.0,"tv":0.0,"id":13460814}]}]}
{"op":"mcm","clk":"1009001758","pt":1580662956085,"mc":[{"id":"1.168238841","rc":[{"batb":[[0,3.25,30.29],[1,3.2,79.97]],"ltp":0.0,"tv":0.0,"id":16858291}]}]}
{"op":"mcm","clk":"1009001942","pt":1580662957202,"mc":[{"id":"1.168238841","rc":[{"batb":[[0,3.25,109.02],[1,1.02,2],[2,1.01,1.01]],"ltp":0.0,"tv":0.0,"id":16858291},{"batb":[[0,2.92,87.69],[1,2.82,30.29]],"ltp":0.0,"tv":0.0,"id":13460814}]}]}
{"op":"mcm","clk":"1009022424","pt":1580663078119,"mc":[{"id":"1.168238841","rc":[{"batb":[[0,3.3,30.29]],"ltp":0.0,"tv":0.0,"id":16858291}]}]}
{"op":"mcm","clk":"1009022586","pt":1580663078915,"mc":[{"id":"1.168238841","rc":[{"batb":[[0,2.96,86.63],[1,2.94,30.29]],"ltp":0.0,"tv":0.0,"id":13460814}]}]}
{"op":"mcm","clk":"1009044245","pt":1580663200100,"mc":[{"id":"1.168238841","rc":[{"batb":[[0,3,30.29]],"ltp":0.0,"tv":0.0,"id":16858291}]}]}
{"op":"mcm","clk":"1009044424","pt":1580663201007,"mc":[{"id":"1.168238841","rc":[{"batb":[[0,3.15,81.23],[1,3,30.29],[2,1.02,2]],"ltp":0.0,"tv":0.0,"id":16858291},{"batb":[[0,2.98,30.29],[1,1.02,2],[2,1.01,1.01]],"ltp":0.0,"tv":0.0,"id":13460814}]}]}
{"op":"mcm","clk":"1009066074","pt":1580663321171,"mc":[{"id":"1.168238841","rc":[{"batb":[[0,3.2,30.29],[1,3.15,81.23]],"ltp":0.0,"tv":0.0,"id":16858291}]}]}
{"op":"mcm","clk":"1009066247","pt":1580663322209,"mc":[{"id":"1.168238841","rc":[{"batb":[[0,3.25,78.73],[1,3.2,30.29]],"ltp":0.0,"tv":0.0,"id":16858291},{"batb":[[0,2.66,30.29],[1,2.34,109.72],[2,1.02,2]],"ltp":0.0,"tv":0.0,"id":13460814}]}]}
{"op":"mcm","clk":"1009066306","pt":1580663322582,"mc":[{"id":"1.168238841","rc":[{"batb":[[0,2.7,94.92],[1,2.66,30.29]],"ltp":0.0,"tv":0.0,"id":13460814}]}]}
{"op":"mcm","clk":"1009086011","pt":1580663443264,"mc":[{"id":"1.168238841","rc":[{"batb":[[0,3.3,30.29],[1,1.02,2],[2,1.01,1.01]],"ltp":0.0,"tv":0.0,"id":16858291}]}]}
{"op":"mcm","clk":"1009086098","pt":1580663443900,"mc":[{"id":"1.168238841","rc":[{"batb":[[0,2.78,92.16],[1,2.72,30.29]],"ltp":0.0,"tv":0.0,"id":13460814}]}]}
{"op":"mcm","clk":"1009105926","pt":1580663566223,"mc":[{"id":"1.168238841","rc":[{"batb":[[0,3.05,84.09],[1,3,30.29],[2,1.02,2]],"ltp":0.0,"tv":0.0,"id":16858291},{"batb":[[1,1.02,2],[2,1.01,1.01]],"ltp":0.0,"tv":0.0,"id":13460814}]}]}
{"op":"mcm","clk":"1009106045","pt":1580663566833,"mc":[{"id":"1.168238841","rc":[{"batb":[[0,2.9,88.36],[1,2.8,30.29],[2,1.02,2]],"ltp":0.0,"tv":0.0,"id":13460814}]}]}
{"op":"mcm","clk":"1009126111","pt":1580663687195,"mc":[{"id":"1.168238841","rc":[{"batb":[[0,3.1,30.29],[1,3.05,84.09]],"ltp":0.0,"tv":0.0,"id":16858291}]}]}
{"op":"mcm","clk":"1009126282","pt":1580663688158,"mc":[{"id":"1.168238841","rc":[{"batb":[[0,3.2,79.97],[1,3.1,30.29]],"ltp":0.0,"tv":0.0,"id":16858291},{"batb":[[0,2.94,87.09],[1,2.92,30.29]],"ltp":0.0,"tv":0.0,"id":13460814}]}]}
{"op":"mcm","clk":"1009146830","pt":1580663808985,"mc":[{"id":"1.168238841","rc":[{"batb":[[0,3.25,30.29],[1,3.2,79.97]],"ltp":0.0,"tv":0.0,"id":16858291}]}]}
{"op":"mcm","clk":"1009146977","pt":1580663810005,"mc":[{"id":"1.168238841","rc":[{"batb":[[0,3.25,109.02],[1,1.02,2],[2,1.01,1.01]],"ltp":0.0,"tv":0.0,"id":16858291},{"batb":[[0,2.96,116.92],[1,1.02,2],[2,1.01,1.01]],"ltp":0.0,"tv":0.0,"id":13460814}]}]}
{"op":"mcm","clk":"1009166738","pt":1580663931267,"mc":[{"id":"1.168238841","rc":[{"batb":[[0,3.3,30.29],[1,3.25,78.73],[2,1.02,2]],"ltp":0.0,"tv":0.0,"id":16858291}]}]}
{"op":"mcm","clk":"1009166894","pt":1580663932170,"mc":[{"id":"1.168238841","rc":[{"batb":[[1,1.02,2],[2,1.01,1.01]],"ltp":0.0,"tv":0.0,"id":16858291},{"batb":[[0,2.98,30.29]],"ltp":0.0,"tv":0.0,"id":13460814}]}]}
{"op":"mcm","clk":"1009185445","pt":1580664053095,"mc":[{"id":"1.168238841","rc":[{"batb":[[0,3.15,81.23],[1,3,30.29],[2,1.02,2]],"ltp":0.0,"tv":0.0,"id":16858291}]}]}
{"op":"mcm","clk":"1009185732","pt":1580664055098,"mc":[{"id":"1.168238841","rc":[{"batb":[[0,2.82,91.03],[1,2.66,30.29],[2,1.02,2]],"ltp":0.0,"tv":0.0,"id":13460814}]}]}
{"op":"mcm","clk":"1009204507","pt":1580664179263,"mc":[{"id":"1.168238841","rc":[{"batb":[[0,3.2,30.29],[1,1.02,2],[2,1.01,1.01]],"ltp":0.0,"tv":0.0,"id":16858291}]}]}
{"op":"mcm","clk":"1009204646","pt":1580664180099,"mc":[{"id":"1.168238841","rc":[{"batb":[[0,3.25,78.73],[1,3.2,30.29],[2,1.02,2]],"ltp":0.0,"tv":0.0,"id":16858291},{"batb":[[0,2.84,30.29],[1,1.02,2],[2,1.01,1.01]],"ltp":0.0,"tv":0.0,"id":13460814}]}]}
{"op":"mcm","clk":"1009204704","pt":1580664180395,"mc":[{"id":"1.168238841","rc":[{"batb":[[0,2.86,89.68],[1,2.84,30.29],[2,1.02,2]],"ltp":0.0,"tv":0.0,"id":13460814}]}]}
{"op":"mcm","clk":"1009225183","pt":1580664310068,"mc":[{"id":"1.168238841","rc":[{"batb":[[0,3.3,30.29],[1,1.02,2],[2,1.01,1.01]],"ltp":0.0,"tv":0.0,"id":16858291}]}]}
{"op":"mcm","clk":"1009225225","pt":1580664310345,"mc":[{"id":"1.168238841","rc":[{"batb":[[1,1.02,2],[2,1.01,1.01]],"ltp":0.0,"tv":0.0,"id":13460814}]}]}
{"op":"mcm","clk":"1009225482","pt":1580664312021,"mc":[{"id":"1.168238841","rc":[{"batb":[[0,2.88,30.28],[1,2.86,89.68],[2,1.02,2]],"ltp":0.0,"tv":0.0,"id":13460814}]}]}
{"op":"mcm","clk":"1009225577","pt":1580664312557,"mc":[{"id":"1.168238841","rc":[{"batb":[[0,2.9,88.36],[1,2.88,30.28]],"ltp":0.0,"tv":0.0,"id":13460814}]}]}
{"op":"mcm","clk":"1009243932","pt":1580664441159,"mc":[{"id":"1.168238841","rc":[{"batb":[[0,3.05,84.09],[1,3,30.29],[2,1.02,2]],"ltp":0.0,"tv":0.0,"id":16858291}]}]}
{"op":"mcm","clk":"1009244096","pt":1580664442171,"mc":[{"id":"1.168238841","rc":[{"batb":[[1,1.02,2],[2,1.01,1.01]],"ltp":0.0,"tv":0.0,"id":13460814}]}]}
{"op":"mcm","clk":"1009244243","pt":1580664443135,"mc":[{"id":"1.168238841","rc":[{"batb":[[0,2.94,87.09],[1,2.92,30.29],[2,1.02,2]],"ltp":0.0,"tv":0.0,"id":13460814}]}]}
{"op":"mcm","clk":"1009256285","pt":1580664523152,"mc":[{"id":"1.168238841","rc":[{"batb":[[0,1.02,2],[1,1.01,1.01],[2,1.01,0]],"ltp":0.0,"tv":0.0,"id":13460817}]}]}
{"op":"mcm","clk":"1009262804","pt":1580664567233,"mc":[{"id":"1.168238841","rc":[{"batb":[[1,1.02,2],[2,1.01,1.01]],"ltp":0.0,"tv":0.0,"id":16858291}]}]}
{"op":"mcm","clk":"1009262957","pt":1580664568124,"mc":[{"id":"1.168238841","rc":[{"batb":[[0,3.15,81.23],[1,3.1,30.29],[2,1.02,2]],"batl":[[0,6.4,364.54]],"ltp":0.0,"tv":0.0,"id":16858291},{"batb":[[0,2.96,30.29],[1,2.94,87.09]],"ltp":0.0,"tv":0.0,"id":13460814}]}]}
{"op":"mcm","clk":"1009263030","pt":1580664568610,"mc":[{"id":"1.168238841","rc":[{"batb":[[0,2.96,116.92],[1,1.02,2],[2,1.01,1.01]],"ltp":0.0,"tv":0.0,"id":13460814}]}]}
{"op":"mcm","clk":"1009281650","pt":1580664689104,"mc":[{"id":"1.168238841","rc":[{"batb":[[0,3.2,30.29],[1,3.15,81.23]],"ltp":0.0,"tv":0.0,"id":16858291}]}]}
{"op":"mcm","clk":"1009281773","pt":1580664689905,"mc":[{"id":"1.168238841","rc":[{"batb":[[0,3.25,78.73],[1,3.2,30.29]],"ltp":0.0,"tv":0.0,"id":16858291},{"batb":[[0,2.98,30.29]],"ltp":0.0,"tv":0.0,"id":13460814}]}]}
{"op":"mcm","clk":"1009300179","pt":1580664811027,"mc":[{"id":"1.168238841","rc":[{"batb":[[0,3.3,30.29],[1,1.02,2],[2,1.01,1.01]],"ltp":0.0,"tv":0.0,"id":16858291}]}]}
{"op":"mcm","clk":"1009300346","pt":1580664812143,"mc":[{"id":"1.168238841","rc":[{"batb":[[0,2.66,30.29],[1,2.5,102.82],[2,1.02,2]],"ltp":0.0,"tv":0.0,"id":13460814}]}]}
{"op":"mcm","clk":"1009300395","pt":1580664812499,"mc":[{"id":"1.168238841","rc":[{"batb":[[0,2.72,94.34],[1,2.66,30.29]],"ltp":0.0,"tv":0.0,"id":13460814}]}]}
{"op":"mcm","clk":"1009319979","pt":1580664933286,"mc":[{"id":"1.168238841","rc":[{"batb":[[0,3.05,84.09],[1,3,30.29],[2,1.02,2]],"ltp":0.0,"tv":0.0,"id":16858291},{"batb":[[0,2.74,30.29],[1,2.72,94.34]],"ltp":0.0,"tv":0.0,"id":13460814}]}]}
{"op":"mcm","clk":"1009320027","pt":1580664933612,"mc":[{"id":"1.168238841","rc":[{"batb":[[0,2.82,91.03],[1,2.74,30.29]],"ltp":0.0,"tv":0.0,"id":13460814}]}]}
{"op":"mcm","clk":"1009340152","pt":1580665054026,"mc":[{"id":"1.168238841","rc":[{"batb":[[0,3.1,30.29],[1,3.05,84.09]],"ltp":0.0,"tv":0.0,"id":16858291}]}]}
{"op":"mcm","clk":"1009340306","pt":1580665055115,"mc":[{"id":"1.168238841","rc":[{"batb":[[0,3.15,81.23],[1,3.1,30.29]],"ltp":0.0,"tv":0.0,"id":16858291},{"batb":[[0,2.84,30.29],[1,1.02,2],[2,1.01,1.01]],"batl":[[0,5.8,301.97]],"ltp":0.0,"tv":0.0,"id":13460814}]}]}
{"op":"mcm","clk":"1009340337","pt":1580665055315,"mc":[{"id":"1.168238841","rc":[{"batb":[[0,2.92,87.69],[1,2.84,30.29],[2,1.02,2]],"ltp":0.0,"tv":0.0,"id":13460814}]}]}
{"op":"mcm","clk":"1009361226","pt":1580665176192,"mc":[{"id":"1.168238841","rc":[{"batb":[[0,3.2,30.29],[1,1.02,2],[2,1.01,1.01]],"ltp":0.0,"tv":0.0,"id":16858291}]}]}
{"op":"mcm","clk":"1009361356","pt":1580665176993,"mc":[{"id":"1.168238841","rc":[{"batb":[[0,3.25,78.73],[1,3.2,30.29],[2,1.02,2]],"ltp":0.0,"tv":0.0,"id":16858291},{"batb":[[0,2.96,86.63],[1,2.94,30.29]],"ltp":0.0,"tv":0.0,"id":13460814}]}]}
{"op":"mcm","clk":"1009381481","pt":1580665298184,"mc":[{"id":"1.168238841","rc":[{"batb":[[0,3.3,30.29],[1,1.02,2],[2,1.01,1.01]],"ltp":0.0,"tv":0.0,"id":16858291},{"batb":[[0,2.98,30.29],[1,2.96,86.63]],"ltp":0.0,"tv":0.0,"id":13460814}]}]}
{"op":"mcm","clk":"1009381613","pt":1580665298868,"mc":[{"id":"1.168238841","rc":[{"batb":[[0,3,85.57],[1,2.98,30.29]],"ltp":0.0,"tv":0.0,"id":13460814}]}]}
{"op":"mcm","clk":"1009399794","pt":1580665419018,"mc":[{"id":"1.168238841","rc":[{"batb":[[0,3,30.29]],"ltp":0.0,"tv":0.0,"id":16858291}]}]}
{"op":"mcm","clk":"1009399944","pt":1580665419920,"mc":[{"id":"1.168238841","rc":[{"batb":[[0,3.15,81.23],[1,3,30.29],[2,1.02,2]],"ltp":0.0,"tv":0.0,"id":16858291},{"batb":[[0,3.05,30.29],[1,1.02,2],[2,1.01,1.01]],"ltp":0.0,"tv":0.0,"id":13460814}]}]}
{"op":"mcm","clk":"1009416073","pt":1580665541191,"mc":[{"id":"1.168238841","rc":[{"batb":[[0,3.25,78.73],[1,3.2,30.29]],"ltp":0.0,"tv":0.0,"id":16858291},{"batb":[[0,1.02,2],[1,1.01,1.01],[2,1.01,0]],"ltp":0.0,"tv":0.0,"id":13460814}]}]}
{"op":"mcm","clk":"1009416161","pt":1580665541937,"mc":[{"id":"1.168238841","rc":[{"batb":[[0,2.78,92.16],[1,2.66,30.29],[2,1.02,2]],"ltp":0.0,"tv":0.0,"id":13460814}]}]}
{"op":"mcm","clk":"1009430551","pt":1580665663049,"mc":[{"id":"1.168238841","rc":[{"batb":[[0,3.3,30.29],[1,3.25,78.73]],"ltp":0.0,"tv":0.0,"id":16858291}]}]}
{"op":"mcm","clk":"1009430672","pt":1580665664090,"mc":[{"id":"1.168238841","rc":[{"batb":[[1,1.02,2],[2,1.01,1.01]],"ltp":0.0,"tv":0.0,"id":16858291},{"batb":[[0,2.82,91.03],[1,2.8,30.29]],"ltp":0.0,"tv":0.0,"id":13460814}]}]}
{"op":"mcm","clk":"1009442293","pt":1580665768186,"mc":[{"id":"1.168238841","rc":[{"batb":[[0,2.72,94.34],[1,1.02,2],[2,1.01,1.01]],"ltp":0.0,"tv":0.0,"id":13460817}]}]}
{"op":"mcm","clk":"1009443937","pt":1580665784282,"mc":[{"id":"1.168238841","rc":[{"batb":[[0,3,30.29],[1,2.48,103.51],[2,1.02,2]],"ltp":0.0,"tv":0.0,"id":16858291}]}]}
{"op":"mcm","clk":"1009444019","pt":1580665785234,"mc":[{"id":"1.168238841","rc":[{"batb":[[0,3.05,84.09],[1,3,30.29]],"ltp":0.0,"tv":0.0,"id":16858291},{"batb":[[0,2.94,87.09],[1,2.84,30.29]],"ltp":0.0,"tv":0.0,"id":13460814}]}]}
{"op":"mcm","clk":"1009455922","pt":1580665906101,"mc":[{"id":"1.168238841","rc":[{"batb":[[0,3.1,30.29],[1,1.02,2],[2,1.01,1.01]],"ltp":0.0,"tv":0.0,"id":16858291}]}]}
{"op":"mcm","clk":"1009456009","pt":1580665906886,"mc":[{"id":"1.168238841","rc":[{"batb":[[0,3.15,81.23],[1,3.1,30.29],[2,1.02,2]],"ltp":0.0,"tv":0.0,"id":16858291},{"batb":[[0,2.98,85.9],[1,2.96,30.29]],"ltp":0.0,"tv":0.0,"id":13460814}]}]}
{"op":"mcm","clk":"1009467957","pt":1580666028193,"mc":[{"id":"1.168238841","rc":[{"batb":[[0,3.25,78.73],[1,3.2,30.29]],"ltp":0.0,"tv":0.0,"id":16858291}]}]}
{"op":"mcm","clk":"1009468037","pt":1580666028983,"mc":[{"id":"1.168238841","rc":[{"batb":[[0,3,115.86],[1,1.02,2],[2,1.01,1.01]],"ltp":0.0,"tv":0.0,"id":13460814}]}]}
{"op":"mcm","clk":"1009479762","pt":1580666149110,"mc":[{"id":"1.168238841","rc":[{"batb":[[0,3.3,30.29],[1,3.25,78.73]],"ltp":0.0,"tv":0.0,"id":16858291}]}]}
{"op":"mcm","clk":"1009479885","pt":1580666150009,"mc":[{"id":"1.168238841","rc":[{"batb":[[1,1.02,2],[2,1.01,1.01]],"ltp":0.0,"tv":0.0,"id":16858291},{"batb":[[0,3.05,30.29]],"ltp":0.0,"tv":0.0,"id":13460814}]}]}
{"op":"mcm","clk":"1009492085","pt":1580666272178,"mc":[{"id":"1.168238841","rc":[{"batb":[[0,3,30.29]],"ltp":0.0,"tv":0.0,"id":16858291}]}]}
{"op":"mcm","clk":"1009492188","pt":1580666273177,"mc":[{"id":"1.168238841","rc":[{"batb":[[0,3.1,82.54],[1,3,30.29],[2,1.02,2]],"ltp":0.0,"tv":0.0,"id":16858291},{"batb":[[0,1.02,2],[1,1.01,1.01],[2,1.01,0]],"ltp":0.0,"tv":0.0,"id":13460814}]}]}
{"op":"mcm","clk":"1009492252","pt":1580666273753,"mc":[{"id":"1.168238841","rc":[{"batb":[[0,2.72,94.34],[1,2.66,30.29],[2,1.02,2]],"ltp":0.0,"tv":0.0,"id":13460814}]}]}
{"op":"mcm","clk":"1009504252","pt":1580666394283,"mc":[{"id":"1.168238841","rc":[{"batb":[[0,3.2,79.97],[1,3.15,30.29]],"ltp":0.0,"tv":0.0,"id":16858291},{"batb":[[0,2.74,30.29],[1,2.72,94.34]],"ltp":0.0,"tv":0.0,"id":13460814}]}]}
{"op":"mcm","clk":"1009504285","pt":1580666394694,"mc":[{"id":"1.168238841","rc":[{"batb":[[0,2.78,92.16],[1,2.74,30.29]],"ltp":0.0,"tv":0.0,"id":13460814}]}]}
{"op":"mcm","clk":"1009506261","pt":1580666414108,"mc":[{"id":"1.168238841","rc":[{"batb":[[0,2.74,93.52],[1,1.02,2],[2,1.01,1.01]],"ltp":0.0,"tv":0.0,"id":16858293}]}]}
{"op":"mcm","clk":"1009506298","pt":1580666414528,"mc":[{"id":"1.168238841","rc":[{"batl":[[0,12.5,204.67]],"ltp":0.0,"tv":0.0,"id":16858293}]}]}
{"op":"mcm","clk":"1009515376","pt":1580666510006,"mc":[{"id":"1.168238841","rc":[{"batl":[[0,6.4,40.53]],"ltp":0.0,"tv":0.0,"id":16858291},{"batl":[[0,5.8,44.47]],"ltp":0.0,"tv":0.0,"id":13460814}]}]}
{"op":"mcm","clk":"1009515900","pt":1580666515145,"mc":[{"id":"1.168238841","rc":[{"batb":[[0,3.25,30.29],[1,3.2,79.97]],"ltp":0.0,"tv":0.0,"id":16858291}]}]}
{"op":"mcm","clk":"1009515991","pt":1580666516113,"mc":[{"id":"1.168238841","rc":[{"batb":[[1,1.02,2],[2,1.01,1.01]],"ltp":0.0,"tv":0.0,"id":16858291},{"batb":[[0,2.8,30.29],[1,1.02,2],[2,1.01,1.01]],"ltp":0.0,"tv":0.0,"id":13460814}]}]}
{"op":"mcm","clk":"1009516008","pt":1580666516314,"mc":[{"id":"1.168238841","rc":[{"batb":[[0,2.86,89.68],[1,2.8,30.29],[2,1.02,2]],"ltp":0.0,"tv":0.0,"id":13460814}]}]}
{"op":"mcm","clk":"1009519710","pt":1580666555287,"mc":[{"id":"1.168238841","rc":[{"batl":[[0,5.8,313.72]],"ltp":0.0,"tv":0.0,"id":13460814}]}]}
{"op":"mcm","clk":"1009528291","pt":1580666637260,"mc":[{"id":"1.168238841","rc":[{"batb":[[0,3,30.29]],"ltp":0.0,"tv":0.0,"id":16858291},{"batb":[[1,1.02,2],[2,1.01,1.01]],"ltp":0.0,"tv":0.0,"id":13460814}]}]}
{"op":"mcm","clk":"1009528384","pt":1580666638145,"mc":[{"id":"1.168238841","rc":[{"batb":[[0,3.05,84.09],[1,3,30.29],[2,1.02,2]],"ltp":0.0,"tv":0.0,"id":16858291},{"batb":[[0,2.9,88.36],[1,2.88,30.28],[2,1.02,2]],"ltp":0.0,"tv":0.0,"id":13460814}]}]}
{"op":"mcm","clk":"1009532047","pt":1580666671654,"mc":[{"id":"1.168238841","rc":[{"batl":[[0,6.4,352.44]],"ltp":0.0,"tv":0.0,"id":16858291}]}]}
{"op":"mcm","clk":"1009540585","pt":1580666759071,"mc":[{"id":"1.168238841","rc":[{"batb":[[0,3.15,81.23],[1,3.1,30.29]],"ltp":0.0,"tv":0.0,"id":16858291},{"batb":[[1,1.02,2],[2,1.01,1.01]],"ltp":0.0,"tv":0.0,"id":13460814}]}]}
{"op":"mcm","clk":"1009540669","pt":1580666759875,"mc":[{"id":"1.168238841","rc":[{"batb":[[0,2.96,86.63],[1,2.92,30.29],[2,1.02,2]],"ltp":0.0,"tv":0.0,"id":13460814}]}]}
{"op":"mcm","clk":"1009553658","pt":1580666880132,"mc":[{"id":"1.168238841","rc":[{"batb":[[0,3.2,30.29],[1,3.15,81.23]],"ltp":0.0,"tv":0.0,"id":16858291}]}]}
{"op":"mcm","clk":"1009553757","pt":1580666881036,"mc":[{"id":"1.168238841","rc":[{"batb":[[0,3.2,110.26],[1,1.02,2],[2,1.01,1.01]],"ltp":0.0,"tv":0.0,"id":16858291},{"batb":[[0,2.98,30.29],[1,1.02,2],[2,1.01,1.01]],"ltp":0.0,"tv":0.0,"id":13460814}]}]}
{"op":"mcm","clk":"1009553799","pt":1580666881330,"mc":[{"id":"1.168238841","rc":[{"batb":[[0,3,85.57],[1,2.98,30.29],[2,1.02,2]],"ltp":0.0,"tv":0.0,"id":13460814}]}]}
{"op":"mcm","clk":"1009566264","pt":1580667002030,"mc":[{"id":"1.168238841","rc":[{"batb":[[0,3.25,30.29]],"ltp":0.0,"tv":0.0,"id":16858291}]}]}
{"op":"mcm","clk":"1009566329","pt":1580667002623,"mc":[{"id":"1.168238841","rc":[{"batb":[[0,3.05,30.29],[1,1.02,2],[2,1.01,1.01]],"ltp":0.0,"tv":0.0,"id":13460814}]}]}
{"op":"mcm","clk":"1009578220","pt":1580667125290,"mc":[{"id":"1.168238841","rc":[{"batb":[[0,1.02,2],[1,1.01,1.01],[2,1.01,0]],"ltp":0.0,"tv":0.0,"id":16858291}]}]}
{"op":"mcm","clk":"1009578294","pt":1580667126080,"mc":[{"id":"1.168238841","rc":[{"batb":[[0,3.1,82.54],[1,3,30.29],[2,1.02,2]],"ltp":0.0,"tv":0.0,"id":16858291},{"batb":[[0,2.68,30.29]],"ltp":0.0,"tv":0.0,"id":13460814}]}]}
{"op":"mcm","clk":"1009578353","pt":1580667126656,"mc":[{"id":"1.168238841","rc":[{"batb":[[0,2.84,90.22],[1,2.68,30.29],[2,1.02,2]],"ltp":0.0,"tv":0.0,"id":13460814}]}]}
{"op":"mcm","clk":"1009589538","pt":1580667233186,"mc":[{"id":"1.168238841","rc":[{"batl":[[0,12.5,20.53]],"ltp":0.0,"tv":0.0,"id":16858293}]}]}
{"op":"mcm","clk":"1009589962","pt":1580667237059,"mc":[{"id":"1.168238841","rc":[{"batl":[[0,6.4,40.29]],"ltp":0.0,"tv":0.0,"id":16858291},{"batl":[[0,5.8,44.47]],"ltp":0.0,"tv":0.0,"id":13460814}]}]}
{"op":"mcm","clk":"1009590830","pt":1580667245167,"mc":[{"id":"1.168238841","rc":[{"batb":[[0,3.15,30.29],[1,3.1,82.54]],"ltp":0.0,"tv":0.0,"id":16858291}]}]}
{"op":"mcm","clk":"1009590923","pt":1580667246066,"mc":[{"id":"1.168238841","rc":[{"batb":[[0,3.2,79.97],[1,3.15,30.29]],"ltp":0.0,"tv":0.0,"id":16858291},{"batb":[[0,2.92,87.69],[1,2.86,30.29]],"ltp":0.0,"tv":0.0,"id":13460814}]}]}
{"op":"mcm","clk":"1009593703","pt":1580667271371,"mc":[{"id":"1.168238841","rc":[{"batl":[[0,6.4,364.54]],"ltp":0.0,"tv":0.0,"id":16858291}]}]}
{"op":"mcm","clk":"1009597952","pt":1580667311326,"mc":[{"id":"1.168238841","rc":[{"batl":[[0,5.8,301.97]],"ltp":0.0,"tv":0.0,"id":13460814}]}]}
{"op":"mcm","clk":"1009598238","pt":1580667314033,"mc":[{"id":"1.168238841","rc":[{"batl":[[0,12.5,204.67]],"ltp":0.0,"tv":0.0,"id":16858293}]}]}
{"op":"mcm","clk":"1009603584","pt":1580667367280,"mc":[{"id":"1.168238841","rc":[{"batb":[[0,3.25,109.02],[1,1.02,2],[2,1.01,1.01]],"ltp":0.0,"tv":0.0,"id":16858291}]}]}
{"op":"mcm","clk":"1009603648","pt":1580667368074,"mc":[{"id":"1.168238841","rc":[{"batb":[[0,2.96,86.63],[1,2.94,30.29]],"ltp":0.0,"tv":0.0,"id":13460814}]}]}
{"op":"mcm","clk":"1009614607","pt":1580667489132,"mc":[{"id":"1.168238841","rc":[{"batb":[[0,3.3,30.29]],"ltp":0.0,"tv":0.0,"id":16858291},{"batb":[[0,2.98,30.29],[1,2.96,86.63]],"ltp":0.0,"tv":0.0,"id":13460814}]}]}
{"op":"mcm","clk":"1009614623","pt":1580667489340,"mc":[{"id":"1.168238841","rc":[{"batb":[[1,1.02,2],[2,1.01,1.01]],"ltp":0.0,"tv":0.0,"id":13460814}]}]}
{"op":"mcm","clk":"1009625373","pt":1580667610190,"mc":[{"id":"1.168238841","rc":[{"batb":[[0,3,30.29]],"ltp":0.0,"tv":0.0,"id":16858291}]}]}
{"op":"mcm","clk":"1009625470","pt":1580667611289,"mc":[{"id":"1.168238841","rc":[{"batb":[[0,3.05,84.09],[1,3,30.29],[2,1.02,2]],"ltp":0.0,"tv":0.0,"id":16858291},{"batb":[[0,2.72,94.34],[1,2.68,30.29],[2,1.02,2]],"ltp":0.0,"tv":0.0,"id":13460814}]}]}
{"op":"mcm","clk":"1009635951","pt":1580667732214,"mc":[{"id":"1.168238841","rc":[{"batb":[[0,3.15,81.23],[1,3.1,30.29]],"ltp":0.0,"tv":0.0,"id":16858291}]}]}
{"op":"mcm","clk":"1009636010","pt":1580667732944,"mc":[{"id":"1.168238841","rc":[{"batb":[[0,2.9,88.36],[1,2.74,30.29]],"ltp":0.0,"tv":0.0,"id":13460814}]}]}
{"op":"mcm","clk":"1009646592","pt":1580667854212,"mc":[{"id":"1.168238841","rc":[{"batb":[[1,1.02,2],[2,1.01,1.01]],"ltp":0.0,"tv":0.0,"id":16858291}]}]}
{"op":"mcm","clk":"1009646682","pt":1580667855238,"mc":[{"id":"1.168238841","rc":[{"batb":[[0,3.25,78.73],[1,3.2,30.29],[2,1.02,2]],"ltp":0.0,"tv":0.0,"id":16858291},{"batb":[[0,2.96,86.63],[1,2.92,30.29]],"ltp":0.0,"tv":0.0,"id":13460814}]}]}
{"op":"mcm","clk":"1009656095","pt":1580667975211,"mc":[{"id":"1.168238841","rc":[{"batb":[[0,3.3,30.29],[1,3.25,78.73]],"ltp":0.0,"tv":0.0,"id":16858291}]}]}
{"op":"mcm","clk":"1009656167","pt":1580667976212,"mc":[{"id":"1.168238841","rc":[{"batb":[[1,1.02,2],[2,1.01,1.01]],"ltp":0.0,"tv":0.0,"id":16858291},{"batb":[[0,3,85.57],[1,2.98,30.29]],"ltp":0.0,"tv":0.0,"id":13460814}]}]}
{"op":"mcm","clk":"1009665568","pt":1580668097245,"mc":[{"id":"1.168238841","rc":[{"batb":[[0,3,30.29],[1,2.64,97.32],[2,1.02,2]],"ltp":0.0,"tv":0.0,"id":16858291}]}]}
{"op":"mcm","clk":"1009665609","pt":1580668097969,"mc":[{"id":"1.168238841","rc":[{"batb":[[0,3.1,82.54],[1,3,30.29]],"ltp":0.0,"tv":0.0,"id":16858291},{"batb":[[0,3.05,30.29],[1,1.02,2],[2,1.01,1.01]],"ltp":0.0,"tv":0.0,"id":13460814}]}]}
{"op":"mcm","clk":"1009671377","pt":1580668169024,"mc":[{"id":"1.168238841","rc":[{"batl":[[0,8,291.98]],"ltp":0.0,"tv":0.0,"id":16858291}]}]}
{"op":"mcm","clk":"1009675304","pt":1580668216385,"mc":[{"id":"1.168238841","rc":[{"batl":[[0,8,282.33]],"ltp":0.0,"tv":0.0,"id":16858291}]}]}
{"op":"mcm","clk":"1009675560","pt":1580668219289,"mc":[{"id":"1.168238841","rc":[{"batb":[[0,3.2,79.97],[1,3.15,30.29]],"ltp":0.0,"tv":0.0,"id":16858291},{"batb":[[0,2.68,30.29]],"ltp":0.0,"tv":0.0,"id":13460814}]}]}
{"op":"mcm","clk":"1009675615","pt":1580668219762,"mc":[{"id":"1.168238841","rc":[{"batb":[[0,2.7,94.92],[1,2.68,30.29],[2,1.02,2]],"ltp":0.0,"tv":0.0,"id":13460814}]}]}
{"op":"mcm","clk":"1009685099","pt":1580668340289,"mc":[{"id":"1.168238841","rc":[{"batb":[[0,3.25,30.29],[1,3.2,79.97]],"ltp":0.0,"tv":0.0,"id":16858291}]}]}
{"op":"mcm","clk":"1009685201","pt":1580668341183,"mc":[{"id":"1.168238841","rc":[{"batb":[[1,1.02,2],[2,1.01,1.01]],"ltp":0.0,"tv":0.0,"id":16858291},{"batb":[[0,2.96,86.63],[1,2.72,30.29]],"ltp":0.0,"tv":0.0,"id":13460814}]}]}
{"op":"mcm","clk":"1009696641","pt":1580668462162,"mc":[{"id":"1.168238841","rc":[{"batb":[[0,3,30.29],[1,2.68,95.61],[2,1.02,2]],"ltp":0.0,"tv":0.0,"id":16858291}]}]}
{"op":"mcm","clk":"1009696721","pt":1580668462835,"mc":[{"id":"1.168238841","rc":[{"batb":[[0,3.05,84.09],[1,3,30.29]],"ltp":0.0,"tv":0.0,"id":16858291},{"batb":[[0,3,85.57],[1,2.98,30.29]],"ltp":0.0,"tv":0.0,"id":13460814}]}]}
{"op":"mcm","clk":"1009707925","pt":1580668583932,"mc":[{"id":"1.168238841","rc":[{"batb":[[0,3.15,81.23],[1,3.1,30.29]],"ltp":0.0,"tv":0.0,"id":16858291}]}]}
{"op":"mcm","clk":"1009708074","pt":1580668585240,"mc":[{"id":"1.168238841","rc":[{"batb":[[0,3.05,30.29],[1,1.02,2],[2,1.01,1.01]],"ltp":0.0,"tv":0.0,"id":13460814}]}]}
{"op":"mcm","clk":"1009710084","pt":1580668604767,"mc":[{"id":"1.168238841","rc":[{"batl":[[0,7.8,327.87],[1,9,2.27]],"ltp":0.0,"tv":0.0,"id":16858293}]}]}
{"op":"mcm","clk":"1009711195","pt":1580668615252,"mc":[{"id":"1.168238841","rc":[{"batl":[[0,7.4,2.27],[1,7.8,327.87]],"ltp":0.0,"tv":0.0,"id":16858293}]}]}
{"op":"mcm","clk":"1009711233","pt":1580668615671,"mc":[{"id":"1.168238841","rc":[{"batl":[[0,7.2,355.13],[1,7.4,2.27]],"ltp":0.0,"tv":0.0,"id":16858293}]}]}
{"op":"mcm","clk":"1009711845","pt":1580668621783,"mc":[{"id":"1.168238841","rc":[{"batl":[[0,7,2.27],[1,7.2,355.13]],"ltp":0.0,"tv":0.0,"id":16858293}]}]}
{"op":"mcm","clk":"1009715001","pt":1580668655895,"mc":[{"id":"1.168238841","rc":[{"batl":[[0,5.9,297.11]],"ltp":0.0,"tv":0.0,"id":13460814}]}]}
{"op":"mcm","clk":"1009719246","pt":1580668706235,"mc":[{"id":"1.168238841","rc":[{"batb":[[0,3.2,110.26],[1,1.02,2],[2,1.01,1.01]],"ltp":0.0,"tv":0.0,"id":16858291},{"batb":[[0,2.68,30.29],[1,2.22,115.84],[2,1.02,2]],"ltp":0.0,"tv":0.0,"id":13460814}]}]}
{"op":"mcm","clk":"1009719278","pt":1580668706643,"mc":[{"id":"1.168238841","rc":[{"batb":[[0,2.76,92.98],[1,2.68,30.29]],"ltp":0.0,"tv":0.0,"id":13460814}]}]}
{"op":"mcm","clk":"1009727675","pt":1580668797524,"mc":[{"id":"1.168238841","rc":[{"batl":[[0,8,32.44]],"ltp":0.0,"tv":0.0,"id":16858291}]}]}
{"op":"mcm","clk":"1009728869","pt":1580668810645,"mc":[{"id":"1.168238841","rc":[{"batl":[[0,8,291.98]],"ltp":0.0,"tv":0.0,"id":16858291}]}]}
{"op":"mcm","clk":"1009730253","pt":1580668827187,"mc":[{"id":"1.168238841","rc":[{"batb":[[0,3.25,109.02]],"ltp":0.0,"tv":0.0,"id":16858291}]}]}
{"op":"mcm","clk":"1009730338","pt":1580668827972,"mc":[{"id":"1.168238841","rc":[{"batb":[[0,2.84,90.22],[1,2.78,30.29]],"ltp":0.0,"tv":0.0,"id":13460814}]}]}
{"op":"mcm","clk":"1009742027","pt":1580668949268,"mc":[{"id":"1.168238841","rc":[{"batb":[[0,3.3,30.29]],"ltp":0.0,"tv":0.0,"id":16858291},{"batb":[[0,2.86,30.29],[1,2.84,90.22]],"ltp":0.0,"tv":0.0,"id":13460814}]}]}
{"op":"mcm","clk":"1009742060","pt":1580668949583,"mc":[{"id":"1.168238841","rc":[{"batb":[[0,2.92,87.69],[1,2.86,30.29]],"ltp":0.0,"tv":0.0,"id":13460814}]}]}
{"op":"mcm","clk":"1009749651","pt":1580669024514,"mc":[{"id":"1.168238841","rc":[{"batl":[[0,7.2,355.13],[1,7.2,0]],"ltp":0.0,"tv":0.0,"id":16858293}]}]}
{"op":"mcm","clk":"1009751043","pt":1580669037214,"mc":[{"id":"1.168238841","rc":[{"batl":[[0,6,2.27]],"ltp":0.0,"tv":0.0,"id":16858291}]}]}
{"op":"mcm","clk":"1009751055","pt":1580669037328,"mc":[{"id":"1.168238841","rc":[{"batl":[[0,4.9,475.75],[1,6,2.27]],"ltp":0.0,"tv":0.0,"id":16858291}]}]}
{"op":"mcm","clk":"1009752408","pt":1580669050256,"mc":[{"id":"1.168238841","rc":[{"batl":[[0,4.7,495.95],[1,4.8,2.27]],"ltp":0.0,"tv":0.0,"id":16858291}]}]}
{"op":"mcm","clk":"1009753482","pt":1580669060056,"mc":[{"id":"1.168238841","rc":[{"batl":[[0,4.6,2.27],[1,4.7,495.95]],"ltp":0.0,"tv":0.0,"id":16858291}]}]}
{"op":"mcm","clk":"1009753519","pt":1580669060514,"mc":[{"id":"1.168238841","rc":[{"batl":[[0,4.4,529.54],[1,4.6,2.27]],"ltp":0.0,"tv":0.0,"id":16858291}]}]}
{"op":"mcm","clk":"1009754403","pt":1580669070248,"mc":[{"id":"1.168238841","rc":[{"batb":[[0,2.94,30.29]],"ltp":0.0,"tv":0.0,"id":16858291}]}]}
{"op":"mcm","clk":"1009754503","pt":1580669071141,"mc":[{"id":"1.168238841","rc":[{"batb":[[0,3.05,84.09],[1,2.94,30.29],[2,1.02,2]],"batl":[[0,4.3,2.27],[1,4.4,529.54]],"ltp":0.0,"tv":0.0,"id":16858291},{"batb":[[0,2.96,86.63],[1,2.94,30.29]],"ltp":0.0,"tv":0.0,"id":13460814}]}]}
{"op":"mcm","clk":"1009754532","pt":1580669071461,"mc":[{"id":"1.168238841","rc":[{"batl":[[0,4.2,554.63],[1,4.3,2.27]],"ltp":0.0,"tv":0.0,"id":16858291}]}]}
{"op":"mcm","clk":"1009755510","pt":1580669082664,"mc":[{"id":"1.168238841","rc":[{"batl":[[0,4.1,2.27],[1,4.3,0]],"ltp":0.0,"tv":0.0,"id":16858291}]}]}
{"op":"mcm","clk":"1009764925","pt":1580669191860,"mc":[{"id":"1.168238841","rc":[{"batb":[[1,1.02,2],[2,1.01,1.01]],"ltp":0.0,"tv":0.0,"id":16858291}]}]}
{"op":"mcm","clk":"1009764972","pt":1580669192482,"mc":[{"id":"1.168238841","rc":[{"batb":[[1,1.02,2],[2,1.01,1.01]],"ltp":0.0,"tv":0.0,"id":13460814}]}]}
{"op":"mcm","clk":"1009781102","pt":1580669368197,"mc":[{"id":"1.168238841","rc":[{"batb":[[0,1.02,2],[1,1.01,1.01],[2,1.01,0]],"ltp":0.0,"tv":0.0,"id":13460817}]}]}
{"op":"mcm","clk":"1009781133","pt":1580669368510,"mc":[{"id":"1.168238841","rc":[{"batl":[[0,14,185.59]],"ltp":0.0,"tv":0.0,"id":13460817}]}]}
{"op":"mcm","clk":"1009797692","pt":1580669543670,"mc":[{"id":"1.168238841","rc":[{"batl":[[0,6.8,343.36]],"ltp":0.0,"tv":0.0,"id":16858291}]}]}
{"op":"mcm","clk":"1009799357","pt":1580669562105,"mc":[{"id":"1.168238841","rc":[{"batl":[[0,5,2.27],[1,7.2,355.13]],"ltp":0.0,"tv":0.0,"id":16858293}]}]}
{"op":"mcm","clk":"1009799376","pt":1580669562305,"mc":[{"id":"1.168238841","rc":[{"batl":[[1,7.2,0]],"ltp":0.0,"tv":0.0,"id":16858293}]}]}
{"op":"mcm","clk":"1009826496","pt":1580669860739,"mc":[{"id":"1.168238841","rc":[{"batl":[[0,17.5,146.19]],"ltp":0.0,"tv":0.0,"id":16858293}]}]}
{"op":"mcm","clk":"1009840992","pt":1580670013922,"mc":[{"id":"1.168238841","rc":[{"batb":[[0,1.02,2],[1,1.01,1.01],[2,1.01,0]],"ltp":0.0,"tv":0.0,"id":16858293}]}]}
{"op":"mcm","clk":"1009842273","pt":1580670025925,"mc":[{"id":"1.168238841","rc":[{"batb":[[0,2.86,89.68],[1,1.02,2],[2,1.01,1.01]],"batl":[[0,5.9,433.15],[1,6,2.27]],"ltp":0.0,"tv":0.0,"id":16858293}]}]}
{"op":"mcm","clk":"1009843035","pt":1580670033257,"mc":[{"id":"1.168238841","rc":[{"batl":[[1,6,0]],"ltp":0.0,"tv":0.0,"id":16858293}]}]}
{"op":"mcm","clk":"1009843072","pt":1580670033630,"mc":[{"id":"1.168238841","rc":[{"batl":[[0,5.6,456.26],[1,5.7,2.27]],"ltp":0.0,"tv":0.0,"id":16858293}]}]}
{"op":"mcm","clk":"1009844463","pt":1580670046866,"mc":[{"id":"1.168238841","rc":[{"batl":[[0,5.5,2.27],[1,5.6,456.26]],"ltp":0.0,"tv":0.0,"id":16858293}]}]}
{"op":"mcm","clk":"1009850845","pt":1580670101219,"mc":[{"id":"1.168238841","rc":[{"batl":[[0,5.6,456.26],[1,5.6,0]],"ltp":0.0,"tv":0.0,"id":16858293}]}]}
{"op":"mcm","clk":"1009851683","pt":1580670107906,"mc":[{"id":"1.168238841","marketDefinition":{"bspMarket":false,"turnInPlayEnabled":true,"persistenceEnabled":true,"marketBaseRate":5.0,"eventId":"29681898","eventTypeId":"2","numberOfWinners":1,"bettingType":"ODDS","marketType":"SET_BETTING","marketTime":"2020-02-02T19:15:00.000Z","suspendTime":"2020-02-02T19:15:00.000Z","bspReconciled":false,"complete":true,"inPlay":false,"crossMatching":true,"runnersVoidable":false,"numberOfActiveRunners":4,"betDelay":0,"status":"OPEN","runners":[{"status":"ACTIVE","sortPriority":1,"id":16858291,"name":"Galan 2-0"},{"status":"ACTIVE","sortPriority":2,"id":16858293,"name":"Galan 2-1"},{"status":"ACTIVE","sortPriority":3,"id":13460814,"name":"Kwiatkowski 2-0"},{"status":"ACTIVE","sortPriority":4,"id":13460817,"name":"Kwiatkowski 2-1"}],"regulators":["MR_INT"],"countryCode":"US","discountAllowed":true,"timezone":"UTC","openDate":"2020-02-02T19:00:00.000Z","version":3150309943,"name":"Set Betting","eventName":"Galan v Kwiatkowski"}}]}
{"op":"mcm","clk":"1009851975","pt":1580670109936,"mc":[{"id":"1.168238841","marketDefinition":{"bspMarket":false,"turnInPlayEnabled":true,"persistenceEnabled":true,"marketBaseRate":5.0,"eventId":"29681898","eventTypeId":"2","numberOfWinners":1,"bettingType":"ODDS","marketType":"SET_BETTING","marketTime":"2020-02-02T19:15:00.000Z","suspendTime":"2020-02-02T19:15:00.000Z","bspReconciled":false,"complete":true,"inPlay":false,"crossMatching":true,"runnersVoidable":false,"numberOfActiveRunners":4,"betDelay":0,"status":"OPEN","runners":[{"status":"ACTIVE","sortPriority":1,"id":16858291,"name":"Galan 2-0"},{"status":"ACTIVE","sortPriority":2,"id":16858293,"name":"Galan 2-1"},{"status":"ACTIVE","sortPriority":3,"id":13460814,"name":"Kwiatkowski 2-0"},{"status":"ACTIVE","sortPriority":4,"id":13460817,"name":"Kwiatkowski 2-1"}],"regulators":["MR_INT"],"countryCode":"US","discountAllowed":true,"timezone":"UTC","openDate":"2020-02-02T19:15:00.000Z","version":3150309943,"name":"Set Betting","eventName":"Galan v Kwiatkowski"}}]}
{"op":"mcm","clk":"1009854954","pt":1580670134250,"mc":[{"id":"1.168238841","rc":[{"batl":[[0,5,2.27],[1,14,185.59]],"ltp":0.0,"tv":0.0,"id":13460817}]}]}
{"op":"mcm","clk":"1009861629","pt":1580670191103,"mc":[{"id":"1.168238841","rc":[{"batb":[[0,3.25,78.73],[1,1.02,2],[2,1.01,1.01]],"batl":[[1,14,0]],"ltp":0.0,"tv":0.0,"id":13460817}]}]}
{"op":"mcm","clk":"1009868036","pt":1580670245538,"mc":[{"id":"1.168238841","rc":[{"batl":[[0,14.5,179.2]],"ltp":0.0,"tv":0.0,"id":13460817}]}]}
{"op":"mcm","clk":"1009877897","pt":1580670331154,"mc":[{"id":"1.168238841","rc":[{"batb":[[0,3,2.27],[1,2.96,86.63],[2,1.02,2]],"ltp":0.0,"tv":0.0,"id":13460814}]}]}
{"op":"mcm","clk":"1009877918","pt":1580670331323,"mc":[{"id":"1.168238841","rc":[{"batb":[[1,1.02,2],[2,1.01,1.01]],"ltp":0.0,"tv":0.0,"id":13460814}]}]}
{"op":"mcm","clk":"1009879824","pt":1580670347258,"mc":[{"id":"1.168238841","rc":[{"batb":[[0,1.02,2],[1,1.01,1.01],[2,1.01,0]],"ltp":0.0,"tv":0.0,"id":13460814}]}]}
{"op":"mcm","clk":"1009879851","pt":1580670347564,"mc":[{"id":"1.168238841","rc":[{"batb":[[0,2.38,107.96],[1,1.02,2],[2,1.01,1.01]],"ltp":0.0,"tv":0.0,"id":13460814}]}]}
{"op":"mcm","clk":"1009954989","pt":1580670935991,"mc":[{"id":"1.168238841","rc":[{"batl":[[0,14.5,17.67]],"ltp":0.0,"tv":0.0,"id":13460817}]}]}
{"op":"mcm","clk":"1009955061","pt":1580670936521,"mc":[{"id":"1.168238841","rc":[{"batl":[[0,9,277.21]],"ltp":0.0,"tv":0.0,"id":16858291}]}]}
{"op":"mcm","clk":"1009963861","pt":1580671008639,"mc":[{"id":"1.168238841","marketDefinition":{"bspMarket":false,"turnInPlayEnabled":true,"persistenceEnabled":true,"marketBaseRate":5.0,"eventId":"29681898","eventTypeId":"2","numberOfWinners":1,"bettingType":"ODDS","marketType":"SET_BETTING","marketTime":"2020-02-02T19:30:00.000Z","suspendTime":"2020-02-02T19:30:00.000Z","bspReconciled":false,"complete":true,"inPlay":false,"crossMatching":true,"runnersVoidable":false,"numberOfActiveRunners":4,"betDelay":0,"status":"OPEN","runners":[{"status":"ACTIVE","sortPriority":1,"id":16858291,"name":"Galan 2-0"},{"status":"ACTIVE","sortPriority":2,"id":16858293,"name":"Galan 2-1"},{"status":"ACTIVE","sortPriority":3,"id":13460814,"name":"Kwiatkowski 2-0"},{"status":"ACTIVE","sortPriority":4,"id":13460817,"name":"Kwiatkowski 2-1"}],"regulators":["MR_INT"],"countryCode":"US","discountAllowed":true,"timezone":"UTC","openDate":"2020-02-02T19:15:00.000Z","version":3150350847,"name":"Set Betting","eventName":"Galan v Kwiatkowski"}}]}
{"op":"mcm","clk":"1009964241","pt":1580671011646,"mc":[{"id":"1.168238841","marketDefinition":{"bspMarket":false,"turnInPlayEnabled":true,"persistenceEnabled":true,"marketBaseRate":5.0,"eventId":"29681898","eventTypeId":"2","numberOfWinners":1,"bettingType":"ODDS","marketType":"SET_BETTING","marketTime":"2020-02-02T19:30:00.000Z","suspendTime":"2020-02-02T19:30:00.000Z","bspReconciled":false,"complete":true,"inPlay":false,"crossMatching":true,"runnersVoidable":false,"numberOfActiveRunners":4,"betDelay":0,"status":"OPEN","runners":[{"status":"ACTIVE","sortPriority":1,"id":16858291,"name":"Galan 2-0"},{"status":"ACTIVE","sortPriority":2,"id":16858293,"name":"Galan 2-1"},{"status":"ACTIVE","sortPriority":3,"id":13460814,"name":"Kwiatkowski 2-0"},{"status":"ACTIVE","sortPriority":4,"id":13460817,"name":"Kwiatkowski 2-1"}],"regulators":["MR_INT"],"countryCode":"US","discountAllowed":true,"timezone":"UTC","openDate":"2020-02-02T19:30:00.000Z","version":3150350847,"name":"Set Betting","eventName":"Galan v Kwiatkowski"}}]}
{"op":"mcm","clk":"1009981149","pt":1580671145852,"mc":[{"id":"1.168238841","rc":[{"batl":[[0,14,186.54]],"ltp":0.0,"tv":0.0,"id":13460817}]}]}
{"op":"mcm","clk":"1010073708","pt":1580671908035,"mc":[{"id":"1.168238841","marketDefinition":{"bspMarket":false,"turnInPlayEnabled":true,"persistenceEnabled":true,"marketBaseRate":5.0,"eventId":"29681898","eventTypeId":"2","numberOfWinners":1,"bettingType":"ODDS","marketType":"SET_BETTING","marketTime":"2020-02-02T19:45:00.000Z","suspendTime":"2020-02-02T19:45:00.000Z","bspReconciled":false,"complete":true,"inPlay":false,"crossMatching":true,"runnersVoidable":false,"numberOfActiveRunners":4,"betDelay":0,"status":"OPEN","runners":[{"status":"ACTIVE","sortPriority":1,"id":16858291,"name":"Galan 2-0"},{"status":"ACTIVE","sortPriority":2,"id":16858293,"name":"Galan 2-1"},{"status":"ACTIVE","sortPriority":3,"id":13460814,"name":"Kwiatkowski 2-0"},{"status":"ACTIVE","sortPriority":4,"id":13460817,"name":"Kwiatkowski 2-1"}],"regulators":["MR_INT"],"countryCode":"US","discountAllowed":true,"timezone":"UTC","openDate":"2020-02-02T19:30:00.000Z","version":3150384451,"name":"Set Betting","eventName":"Galan v Kwiatkowski"}}]}
{"op":"mcm","clk":"1010074096","pt":1580671911042,"mc":[{"id":"1.168238841","marketDefinition":{"bspMarket":false,"turnInPlayEnabled":true,"persistenceEnabled":true,"marketBaseRate":5.0,"eventId":"29681898","eventTypeId":"2","numberOfWinners":1,"bettingType":"ODDS","marketType":"SET_BETTING","marketTime":"2020-02-02T19:45:00.000Z","suspendTime":"2020-02-02T19:45:00.000Z","bspReconciled":false,"complete":true,"inPlay":false,"crossMatching":true,"runnersVoidable":false,"numberOfActiveRunners":4,"betDelay":0,"status":"OPEN","runners":[{"status":"ACTIVE","sortPriority":1,"id":16858291,"name":"Galan 2-0"},{"status":"ACTIVE","sortPriority":2,"id":16858293,"name":"Galan 2-1"},{"status":"ACTIVE","sortPriority":3,"id":13460814,"name":"Kwiatkowski 2-0"},{"status":"ACTIVE","sortPriority":4,"id":13460817,"name":"Kwiatkowski 2-1"}],"regulators":["MR_INT"],"countryCode":"US","discountAllowed":true,"timezone":"UTC","openDate":"2020-02-02T19:45:00.000Z","version":3150384451,"name":"Set Betting","eventName":"Galan v Kwiatkowski"}}]}
{"op":"mcm","clk":"1010103984","pt":1580672158455,"mc":[{"id":"1.168238841","rc":[{"batl":[[0,16,16.24]],"ltp":0.0,"tv":0.0,"id":16858293},{"batl":[[0,6.2,271.78]],"ltp":0.0,"tv":0.0,"id":13460814}]}]}
{"op":"mcm","clk":"1010110779","pt":1580672216334,"mc":[{"id":"1.168238841","rc":[{"batl":[[0,16,159.47]],"ltp":0.0,"tv":0.0,"id":16858293}]}]}
{"op":"mcm","clk":"1010152463","pt":1580672576773,"mc":[{"id":"1.168238841","rc":[{"batb":[[0,3.2,79.97],[1,3.1,5],[2,1.02,2]],"ltp":0.0,"tv":0.0,"id":16858291},{"batb":[[0,3.1,82.54],[1,2.88,6],[2,1.02,2]],"ltp":0.0,"tv":0.0,"id":16858293},{"batb":[[0,2.62,98.04],[1,2.4,6],[2,1.02,2]],"ltp":0.0,"tv":0.0,"id":13460814},{"batb":[[0,3.4,75.21],[1,3.3,5],[2,1.02,2]],"ltp":0.0,"tv":0.0,"id":13460817}]}]}
{"op":"mcm","clk":"1010160122","pt":1580672637177,"mc":[{"id":"1.168238841","rc":[{"batb":[[0,3.25,5],[1,1.02,2],[2,1.01,1.01]],"ltp":0.0,"tv":0.0,"id":16858291},{"batb":[[0,3.15,6],[1,3.1,82.54]],"ltp":0.0,"tv":0.0,"id":16858293}]}]}
{"op":"mcm","clk":"1010160250","pt":1580672638149,"mc":[{"id":"1.168238841","rc":[{"batb":[[0,3.3,77.58],[1,3.25,5],[2,1.02,2]],"ltp":0.0,"tv":0.0,"id":16858291},{"batb":[[0,3.85,66.37],[1,3.15,6]],"ltp":0.0,"tv":0.0,"id":16858293},{"batb":[[0,2.8,91.48],[1,2.64,6]],"ltp":0.0,"tv":0.0,"id":13460814},{"batb":[[0,3.6,70.99],[1,3.45,5]],"ltp":0.0,"tv":0.0,"id":13460817}]}]}
{"op":"mcm","clk":"1010168184","pt":1580672698260,"mc":[{"id":"1.168238841","rc":[{"batb":[[1,1.02,2],[2,1.01,1.01]],"ltp":0.0,"tv":0.0,"id":16858291}]}]}
{"op":"mcm","clk":"1010168298","pt":1580672699156,"mc":[{"id":"1.168238841","rc":[{"batb":[[0,3.35,5]],"ltp":0.0,"tv":0.0,"id":16858291},{"batb":[[0,3.95,64.71],[1,3.9,6]],"ltp":0.0,"tv":0.0,"id":16858293},{"batb":[[1,2.76,6]],"ltp":0.0,"tv":0.0,"id":13460814},{"batb":[[0,3.65,5],[1,3.6,70.99]],"ltp":0.0,"tv":0.0,"id":13460817}]}]}
{"op":"mcm","clk":"1010168455","pt":1580672700263,"mc":[{"id":"1.168238841","rc":[{"batb":[[0,3.75,68.11],[1,3.65,5]],"ltp":0.0,"tv":0.0,"id":13460817}]}]}
{"op":"mcm","clk":"1010176064","pt":1580672760104,"mc":[{"id":"1.168238841","rc":[{"batb":[[0,4.1,62.34],[1,4,6]],"ltp":0.0,"tv":0.0,"id":16858293},{"batb":[[0,3.8,5],[1,1.02,2],[2,1.01,1.01]],"ltp":0.0,"tv":0.0,"id":13460817}]}]}
{"op":"mcm","clk":"1010176084","pt":1580672760317,"mc":[{"id":"1.168238841","rc":[{"batb":[[0,3.85,66.37],[1,3.8,5],[2,1.02,2]],"ltp":0.0,"tv":0.0,"id":13460817}]}]}
{"op":"mcm","clk":"1010181430","pt":1580672808353,"mc":[{"id":"1.168238841","marketDefinition":{"bspMarket":false,"turnInPlayEnabled":true,"persistenceEnabled":true,"marketBaseRate":5.0,"eventId":"29681898","eventTypeId":"2","numberOfWinners":1,"bettingType":"ODDS","marketType":"SET_BETTING","marketTime":"2020-02-02T20:00:00.000Z","suspendTime":"2020-02-02T20:00:00.000Z","bspReconciled":false,"complete":true,"inPlay":false,"crossMatching":true,"runnersVoidable":false,"numberOfActiveRunners":4,"betDelay":0,"status":"OPEN","runners":[{"status":"ACTIVE","sortPriority":1,"id":16858291,"name":"Galan 2-0"},{"status":"ACTIVE","sortPriority":2,"id":16858293,"name":"Galan 2-1"},{"status":"ACTIVE","sortPriority":3,"id":13460814,"name":"Kwiatkowski 2-0"},{"status":"ACTIVE","sortPriority":4,"id":13460817,"name":"Kwiatkowski 2-1"}],"regulators":["MR_INT"],"countryCode":"US","discountAllowed":true,"timezone":"UTC","openDate":"2020-02-02T19:45:00.000Z","version":3150416834,"name":"Set Betting","eventName":"Galan v Kwiatkowski"}}]}
{"op":"mcm","clk":"1010182718","pt":1580672820987,"mc":[{"id":"1.168238841","rc":[{"batb":[[0,4.2,66.77],[1,1.02,2],[2,1.01,1.01]],"ltp":0.0,"tv":0.0,"id":16858293},{"batb":[[0,3.9,5],[1,1.02,2],[2,1.01,1.01]],"ltp":0.0,"tv":0.0,"id":13460817}]}]}
{"op":"mcm","clk":"1010183449","pt":1580672828399,"mc":[{"id":"1.168238841","marketDefinition":{"bspMarket":false,"turnInPlayEnabled":true,"persistenceEnabled":true,"marketBaseRate":5.0,"eventId":"29681898","eventTypeId":"2","numberOfWinners":1,"bettingType":"ODDS","marketType":"SET_BETTING","marketTime":"2020-02-02T20:00:00.000Z","suspendTime":"2020-02-02T20:00:00.000Z","bspReconciled":false,"complete":true,"inPlay":false,"crossMatching":true,"runnersVoidable":false,"numberOfActiveRunners":4,"betDelay":0,"status":"OPEN","runners":[{"status":"ACTIVE","sortPriority":1,"id":16858291,"name":"Galan 2-0"},{"status":"ACTIVE","sortPriority":2,"id":16858293,"name":"Galan 2-1"},{"status":"ACTIVE","sortPriority":3,"id":13460814,"name":"Kwiatkowski 2-0"},{"status":"ACTIVE","sortPriority":4,"id":13460817,"name":"Kwiatkowski 2-1"}],"regulators":["MR_INT"],"countryCode":"US","discountAllowed":true,"timezone":"UTC","openDate":"2020-02-02T20:00:00.000Z","version":3150416834,"name":"Set Betting","eventName":"Galan v Kwiatkowski"}}]}
{"op":"mcm","clk":"1010201218","pt":1580673016159,"mc":[{"id":"1.168238841","rc":[{"batl":[[0,4.7,3.79]],"ltp":0.0,"tv":0.0,"id":16858293}]}]}
{"op":"mcm","clk":"1010202736","pt":1580673033290,"mc":[{"id":"1.168238841","rc":[{"batl":[[0,4.3,3.79]],"ltp":0.0,"tv":0.0,"id":16858293}]}]}
{"op":"mcm","clk":"1010202753","pt":1580673033462,"mc":[{"id":"1.168238841","rc":[{"batb":[[0,4.2,6]],"ltp":0.0,"tv":0.0,"id":16858293}]}]}
{"op":"mcm","clk":"1010203743","pt":1580673044689,"mc":[{"id":"1.168238841","rc":[{"batb":[[0,4.2,66.77]],"batl":[[0,14,182.22]],"ltp":0.0,"tv":0.0,"id":16858293}]}]}
{"op":"mcm","clk":"1010206885","pt":1580673079132,"mc":[{"id":"1.168238841","rc":[{"trd":[[4.2,9.08]],"batb":[[0,4.2,62.23]],"ltp":4.2,"tv":9.08,"id":16858293}],"tv":9.08}]}
{"op":"mcm","clk":"1010207221","pt":1580673083020,"mc":[{"id":"1.168238841","rc":[{"batb":[[0,3.35,81.47]],"batl":[[0,5.4,491.34]],"ltp":0.0,"tv":0.0,"id":16858291},{"batl":[[0,14,18.56]],"ltp":4.2,"tv":9.08,"id":16858293},{"batl":[[0,5.5,294.35]],"ltp":0.0,"tv":0.0,"id":13460814}]}]}
{"op":"mcm","clk":"1010207251","pt":1580673083331,"mc":[{"id":"1.168238841","rc":[{"batl":[[0,12,218.75]],"ltp":0.0,"tv":0.0,"id":13460817}]}]}
{"op":"mcm","clk":"1010207486","pt":1580673086266,"mc":[{"id":"1.168238841","rc":[{"batl":[[0,5.5,282.69]],"ltp":0.0,"tv":0.0,"id":13460814}]}]}
{"op":"mcm","clk":"1010208803","pt":1580673100555,"mc":[{"id":"1.168238841","rc":[{"batl":[[0,12,21.65]],"ltp":0.0,"tv":0.0,"id":13460817}]}]}
{"op":"mcm","clk":"1010210620","pt":1580673120983,"mc":[{"id":"1.168238841","rc":[{"batl":[[0,12,219.98]],"ltp":0.0,"tv":0.0,"id":13460817}]}]}
{"op":"mcm","clk":"1010211206","pt":1580673127395,"mc":[{"id":"1.168238841","rc":[{"batl":[[0,5.4,47.79]],"ltp":0.0,"tv":0.0,"id":16858291}]}]}
{"op":"mcm","clk":"1010212880","pt":1580673145224,"mc":[{"id":"1.168238841","rc":[{"batl":[[0,5.5,47.14]],"ltp":0.0,"tv":0.0,"id":13460814}]}]}
{"op":"mcm","clk":"1010220520","pt":1580673242079,"mc":[{"id":"1.168238841","rc":[{"batl":[[0,12,21.65]],"ltp":0.0,"tv":0.0,"id":13460817}]}]}
{"op":"mcm","clk":"1010228217","pt":1580673345833,"mc":[{"id":"1.168238841","rc":[{"batl":[[0,14,179.4]],"ltp":4.2,"tv":9.08,"id":16858293}]}]}
{"op":"mcm","clk":"1010230269","pt":1580673371969,"mc":[{"id":"1.168238841","rc":[{"batl":[[0,14,18.56]],"ltp":4.2,"tv":9.08,"id":16858293}]}]}
{"op":"mcm","clk":"1010231043","pt":1580673383200,"mc":[{"id":"1.168238841","rc":[{"batl":[[0,5.4,496.74]],"ltp":0.0,"tv":0.0,"id":16858291},{"batl":[[0,5.5,271.25]],"ltp":0.0,"tv":0.0,"id":13460814},{"batl":[[0,12,221.28]],"ltp":0.0,"tv":0.0,"id":13460817}]}]}
{"op":"mcm","clk":"1010236363","pt":1580673458215,"mc":[{"id":"1.168238841","rc":[{"batl":[[0,5.4,47.79]],"ltp":0.0,"tv":0.0,"id":16858291}]}]}
{"op":"mcm","clk":"1010239073","pt":1580673492155,"mc":[{"id":"1.168238841","rc":[{"batl":[[0,12,21.65]],"ltp":0.0,"tv":0.0,"id":13460817}]}]}
{"op":"mcm","clk":"1010243744","pt":1580673549284,"mc":[{"id":"1.168238841","rc":[{"batl":[[0,5.3,4]],"ltp":0.0,"tv":0.0,"id":16858291},{"batl":[[0,13.5,6]],"ltp":4.2,"tv":9.08,"id":16858293},{"batl":[[0,5.4,4]],"ltp":0.0,"tv":0.0,"id":13460814},{"batl":[[0,11.5,6]],"ltp":0.0,"tv":0.0,"id":13460817}]}]}
{"op":"mcm","clk":"1010243823","pt":1580673550268,"mc":[{"id":"1.168238841","rc":[{"batl":[[0,4.8,53.77],[1,5.3,4]],"ltp":0.0,"tv":0.0,"id":16858291},{"batl":[[0,9.6,27.05],[1,13.5,6]],"ltp":4.2,"tv":9.08,"id":16858293},{"batl":[[0,5.2,286.88],[1,5.4,4]],"ltp":0.0,"tv":0.0,"id":13460814},{"batl":[[0,8.2,31.43],[1,11.5,6]],"ltp":0.0,"tv":0.0,"id":13460817}]}]}
{"op":"mcm","clk":"1010246136","pt":1580673581941,"mc":[{"id":"1.168238841","rc":[{"batl":[[0,5.2,49.63]],"ltp":0.0,"tv":0.0,"id":13460814}]}]}
{"op":"mcm","clk":"1010248401","pt":1580673610106,"mc":[{"id":"1.168238841","rc":[{"batl":[[0,4.5,57.31],[1,4.7,4]],"ltp":0.0,"tv":0.0,"id":16858291},{"batl":[[0,9.4,6],[1,9.6,27.05]],"ltp":4.2,"tv":9.08,"id":16858293},{"batl":[[0,5.1,4],[1,5.2,49.63]],"ltp":0.0,"tv":0.0,"id":13460814}]}]}
{"op":"mcm","clk":"1010248423","pt":1580673610412,"mc":[{"id":"1.168238841","rc":[{"batl":[[0,4.4,58.64],[1,5.1,4]],"ltp":0.0,"tv":0.0,"id":13460814},{"batl":[[0,8,6],[1,8.2,31.43]],"ltp":0.0,"tv":0.0,"id":13460817}]}]}
{"op":"mcm","clk":"1010251234","pt":1580673645277,"mc":[{"id":"1.168238841","rc":[{"batl":[[1,9.6,264.21]],"ltp":4.2,"tv":9.08,"id":16858293}]}]}
{"op":"mcm","clk":"1010251728","pt":1580673650984,"mc":[{"id":"1.168238841","rc":[{"batl":[[0,7.4,342.64],[1,9.4,6]],"ltp":4.2,"tv":9.08,"id":16858293}]}]}
{"op":"mcm","clk":"1010253339","pt":1580673671197,"mc":[{"id":"1.168238841","rc":[{"batl":[[0,7.2,6],[1,7.4,342.64]],"ltp":4.2,"tv":9.08,"id":16858293},{"batl":[[1,5.1,0]],"ltp":0.0,"tv":0.0,"id":13460814}]}]}
{"op":"mcm","clk":"1010253379","pt":1580673671744,"mc":[{"id":"1.168238841","rc":[{"batl":[[0,3.85,67.1],[1,4.3,4]],"ltp":0.0,"tv":0.0,"id":13460814}]}]}
{"op":"mcm","clk":"1010254329","pt":1580673683242,"mc":[{"id":"1.168238841","rc":[{"batl":[[0,4.5,589.21]],"ltp":0.0,"tv":0.0,"id":16858291},{"batl":[[0,3.85,420.1]],"ltp":0.0,"tv":0.0,"id":13460814},{"batl":[[1,8.2,0]],"ltp":0.0,"tv":0.0,"id":13460817}]}]}
{"op":"mcm","clk":"1010254341","pt":1580673683344,"mc":[{"id":"1.168238841","rc":[{"batl":[[1,8.2,319.63]],"ltp":0.0,"tv":0.0,"id":13460817}]}]}
{"op":"mcm","clk":"1010256348","pt":1580673709097,"mc":[{"id":"1.168238841","marketDefinition":{"bspMarket":false,"turnInPlayEnabled":true,"persistenceEnabled":true,"marketBaseRate":5.0,"eventId":"29681898","eventTypeId":"2","numberOfWinners":1,"bettingType":"ODDS","marketType":"SET_BETTING","marketTime":"2020-02-02T20:15:00.000Z","suspendTime":"2020-02-02T20:15:00.000Z","bspReconciled":false,"complete":true,"inPlay":false,"crossMatching":true,"runnersVoidable":false,"numberOfActiveRunners":4,"betDelay":0,"status":"OPEN","runners":[{"status":"ACTIVE","sortPriority":1,"id":16858291,"name":"Galan 2-0"},{"status":"ACTIVE","sortPriority":2,"id":16858293,"name":"Galan 2-1"},{"status":"ACTIVE","sortPriority":3,"id":13460814,"name":"Kwiatkowski 2-0"},{"status":"ACTIVE","sortPriority":4,"id":13460817,"name":"Kwiatkowski 2-1"}],"regulators":["MR_INT"],"countryCode":"US","discountAllowed":true,"timezone":"UTC","openDate":"2020-02-02T20:00:00.000Z","version":3150445146,"name":"Set Betting","eventName":"Galan v Kwiatkowski"}}]}
{"op":"mcm","clk":"1010256461","pt":1580673710634,"mc":[{"id":"1.168238841","marketDefinition":{"bspMarket":false,"turnInPlayEnabled":true,"persistenceEnabled":true,"marketBaseRate":5.0,"eventId":"29681898","eventTypeId":"2","numberOfWinners":1,"bettingType":"ODDS","marketType":"SET_BETTING","marketTime":"2020-02-02T20:15:00.000Z","suspendTime":"2020-02-02T20:15:00.000Z","bspReconciled":false,"complete":true,"inPlay":false,"crossMatching":true,"runnersVoidable":false,"numberOfActiveRunners":4,"betDelay":0,"status":"OPEN","runners":[{"status":"ACTIVE","sortPriority":1,"id":16858291,"name":"Galan 2-0"},{"status":"ACTIVE","sortPriority":2,"id":16858293,"name":"Galan 2-1"},{"status":"ACTIVE","sortPriority":3,"id":13460814,"name":"Kwiatkowski 2-0"},{"status":"ACTIVE","sortPriority":4,"id":13460817,"name":"Kwiatkowski 2-1"}],"regulators":["MR_INT"],"countryCode":"US","discountAllowed":true,"timezone":"UTC","openDate":"2020-02-02T20:15:00.000Z","version":3150445146,"name":"Set Betting","eventName":"Galan v Kwiatkowski"}}]}
{"op":"mcm","clk":"1010256879","pt":1580673715903,"mc":[{"id":"1.168238841","rc":[{"batb":[[0,2.82,151.45],[1,2.8,91.48],[2,2.76,6]],"ltp":0.0,"tv":0.0,"id":13460814}]}]}
{"op":"mcm","clk":"1010258086","pt":1580673731856,"mc":[{"id":"1.168238841","rc":[{"batl":[[0,3.8,4],[1,3.85,420.1]],"ltp":0.0,"tv":0.0,"id":13460814}]}]}
{"op":"mcm","clk":"1010258149","pt":1580673732752,"mc":[{"id":"1.168238841","rc":[{"batb":[[1,2.76,6],[2,1.02,2]],"batl":[[1,3.85,0]],"ltp":0.0,"tv":0.0,"id":13460814}]}]}
{"op":"mcm","clk":"1010260584","pt":1580673766832,"mc":[{"id":"1.168238841","rc":[{"batb":[[0,2.88,88.96],[1,2.82,151.45],[2,2.76,6]],"batl":[[0,3.75,431.1],[1,3.8,4]],"ltp":0.0,"tv":0.0,"id":13460814},{"batl":[[0,7.4,354.14],[1,8,6]],"ltp":0.0,"tv":0.0,"id":13460817}]}]}
{"op":"mcm","clk":"1010262645","pt":1580673793109,"mc":[{"id":"1.168238841","rc":[{"batl":[[0,3.7,4],[1,3.75,431.1]],"ltp":0.0,"tv":0.0,"id":13460814},{"batl":[[0,7.2,6],[1,7.4,354.14]],"ltp":0.0,"tv":0.0,"id":13460817}]}]}
{"op":"mcm","clk":"1010263570","pt":1580673804733,"mc":[{"id":"1.168238841","rc":[{"batl":[[0,4.5,552.93]],"ltp":0.0,"tv":0.0,"id":16858291}]}]}
{"op":"mcm","clk":"1010289787","pt":1580674094105,"mc":[{"id":"1.168238841","rc":[{"batl":[[1,7.4,0]],"ltp":4.2,"tv":9.08,"id":16858293}]}]}
{"op":"mcm","clk":"1010289808","pt":1580674094322,"mc":[{"id":"1.168238841","rc":[{"batl":[[0,6.4,397.91],[1,7.2,6]],"ltp":4.2,"tv":9.08,"id":16858293}]}]}
{"op":"mcm","clk":"1010295950","pt":1580674156658,"mc":[{"id":"1.168238841","rc":[{"batb":[[0,3.35,5]],"ltp":0.0,"tv":0.0,"id":16858291},{"batl":[[1,3.75,68.78]],"ltp":0.0,"tv":0.0,"id":13460814},{"batl":[[1,7.4,34.84]],"ltp":0.0,"tv":0.0,"id":13460817}]}]}
{"op":"mcm","clk":"1010296083","pt":1580674158205,"mc":[{"id":"1.168238841","rc":[{"batl":[[1,3.75,0]],"ltp":0.0,"tv":0.0,"id":13460814},{"batl":[[1,7.4,0]],"ltp":0.0,"tv":0.0,"id":13460817}]}]}
{"op":"mcm","clk":"1010296138","pt":1580674158996,"mc":[{"id":"1.168238841","rc":[{"batl":[[0,3.7,73.75]],"ltp":0.0,"tv":0.0,"id":13460814},{"batl":[[0,5.9,43.75],[1,7.2,6]],"ltp":0.0,"tv":0.0,"id":13460817}]}]}
{"op":"mcm","clk":"1010308162","pt":1580674283286,"mc":[{"id":"1.168238841","rc":[{"batl":[[0,7.2,6],[1,7.2,0]],"ltp":0.0,"tv":0.0,"id":13460817}]}]}
{"op":"mcm","clk":"1010308176","pt":1580674283393,"mc":[{"id":"1.168238841","rc":[{"batl":[[0,5.9,441.76],[1,7.2,6]],"ltp":0.0,"tv":0.0,"id":13460817}]}]}
{"op":"mcm","clk":"1010312193","pt":1580674323127,"mc":[{"id":"1.168238841","rc":[{"batb":[[0,3.35,81.47]],"batl":[[0,4.5,57.31]],"ltp":0.0,"tv":0.0,"id":16858291},{"batl":[[0,6.4,40.29]],"ltp":4.2,"tv":9.08,"id":16858293},{"batl":[[0,5.9,43.75]],"ltp":0.0,"tv":0.0,"id":13460817}]}]}
{"op":"mcm","clk":"1010315761","pt":1580674359063,"mc":[{"id":"1.168238841","rc":[{"batb":[[0,2.84,90.22]],"ltp":0.0,"tv":0.0,"id":13460814}]}]}
{"op":"mcm","clk":"1010316570","pt":1580674366859,"mc":[{"id":"1.168238841","rc":[{"batl":[[0,4.5,589.21]],"ltp":0.0,"tv":0.0,"id":16858291},{"batl":[[0,3.7,423.65]],"ltp":0.0,"tv":0.0,"id":13460814},{"batl":[[0,5.9,446.45]],"ltp":0.0,"tv":0.0,"id":13460817}]}]}
{"op":"mcm","clk":"1010319477","pt":1580674394082,"mc":[{"id":"1.168238841","rc":[{"batl":[[0,6.4,394.49]],"ltp":4.2,"tv":9.08,"id":16858293}]}]}
{"op":"mcm","clk":"1010320555","pt":1580674403996,"mc":[{"id":"1.168238841","rc":[{"batl":[[0,4.5,57.31]],"ltp":0.0,"tv":0.0,"id":16858291}]}]}
{"op":"mcm","clk":"1010320673","pt":1580674405209,"mc":[{"id":"1.168238841","rc":[{"batl":[[0,4.5,599.79]],"ltp":0.0,"tv":0.0,"id":16858291}]}]}
{"op":"mcm","clk":"1010321183","pt":1580674409955,"mc":[{"id":"1.168238841","rc":[{"batl":[[0,6.4,40.53]],"ltp":4.2,"tv":9.08,"id":16858293},{"batl":[[0,3.7,73.75]],"ltp":0.0,"tv":0.0,"id":13460814}]}]}
{"op":"mcm","clk":"1010330792","pt":1580674497228,"mc":[{"id":"1.168238841","rc":[{"batl":[[0,4.7,4],[1,4.7,0]],"ltp":0.0,"tv":0.0,"id":16858291}]}]}
{"op":"mcm","clk":"1010330805","pt":1580674497323,"mc":[{"id":"1.168238841","rc":[{"batl":[[0,4.5,57.31],[1,4.7,4]],"ltp":0.0,"tv":0.0,"id":16858291}]}]}
{"op":"mcm","clk":"1010334784","pt":1580674533216,"mc":[{"id":"1.168238841","rc":[{"batl":[[0,7.2,6],[1,7.2,0]],"ltp":0.0,"tv":0.0,"id":13460817}]}]}
{"op":"mcm","clk":"1010334805","pt":1580674533426,"mc":[{"id":"1.168238841","rc":[{"batl":[[0,5.9,43.75],[1,7.2,6]],"ltp":0.0,"tv":0.0,"id":13460817}]}]}
{"op":"mcm","clk":"1010340229","pt":1580674583183,"mc":[{"id":"1.168238841","rc":[{"batl":[[0,5.9,443.95]],"ltp":0.0,"tv":0.0,"id":13460817}]}]}
{"op":"mcm","clk":"1010342736","pt":1580674608256,"mc":[{"id":"1.168238841","marketDefinition":{"bspMarket":false,"turnInPlayEnabled":true,"persistenceEnabled":true,"marketBaseRate":5.0,"eventId":"29681898","eventTypeId":"2","numberOfWinners":1,"bettingType":"ODDS","marketType":"SET_BETTING","marketTime":"2020-02-02T20:30:00.000Z","suspendTime":"2020-02-02T20:30:00.000Z","bspReconciled":false,"complete":true,"inPlay":false,"crossMatching":true,"runnersVoidable":false,"numberOfActiveRunners":4,"betDelay":0,"status":"OPEN","runners":[{"status":"ACTIVE","sortPriority":1,"id":16858291,"name":"Galan 2-0"},{"status":"ACTIVE","sortPriority":2,"id":16858293,"name":"Galan 2-1"},{"status":"ACTIVE","sortPriority":3,"id":13460814,"name":"Kwiatkowski 2-0"},{"status":"ACTIVE","sortPriority":4,"id":13460817,"name":"Kwiatkowski 2-1"}],"regulators":["MR_INT"],"countryCode":"US","discountAllowed":true,"timezone":"UTC","openDate":"2020-02-02T20:15:00.000Z","version":3150491533,"name":"Set Betting","eventName":"Galan v Kwiatkowski"}}]}
{"op":"mcm","clk":"1010343011","pt":1580674611262,"mc":[{"id":"1.168238841","marketDefinition":{"bspMarket":false,"turnInPlayEnabled":true,"persistenceEnabled":true,"marketBaseRate":5.0,"eventId":"29681898","eventTypeId":"2","numberOfWinners":1,"bettingType":"ODDS","marketType":"SET_BETTING","marketTime":"2020-02-02T20:30:00.000Z","suspendTime":"2020-02-02T20:30:00.000Z","bspReconciled":false,"complete":true,"inPlay":false,"crossMatching":true,"runnersVoidable":false,"numberOfActiveRunners":4,"betDelay":0,"status":"OPEN","runners":[{"status":"ACTIVE","sortPriority":1,"id":16858291,"name":"Galan 2-0"},{"status":"ACTIVE","sortPriority":2,"id":16858293,"name":"Galan 2-1"},{"status":"ACTIVE","sortPriority":3,"id":13460814,"name":"Kwiatkowski 2-0"},{"status":"ACTIVE","sortPriority":4,"id":13460817,"name":"Kwiatkowski 2-1"}],"regulators":["MR_INT"],"countryCode":"US","discountAllowed":true,"timezone":"UTC","openDate":"2020-02-02T20:30:00.000Z","version":3150491533,"name":"Set Betting","eventName":"Galan v Kwiatkowski"}}]}
{"op":"mcm","clk":"1010343764","pt":1580674619254,"mc":[{"id":"1.168238841","rc":[{"batl":[[0,6.6,384.06]],"ltp":4.2,"tv":9.08,"id":16858293},{"batl":[[0,3.65,425.54],[1,3.7,4]],"ltp":0.0,"tv":0.0,"id":13460814}]}]}
{"op":"mcm","clk":"1010350796","pt":1580674684101,"mc":[{"id":"1.168238841","rc":[{"batb":[[1,2.76,6],[2,1.02,2]],"ltp":0.0,"tv":0.0,"id":13460814}]}]}
{"op":"mcm","clk":"1010351012","pt":1580674686328,"mc":[{"id":"1.168238841","rc":[{"batb":[[0,3.35,5]],"batl":[[0,4.7,4],[1,4.7,0]],"ltp":0.0,"tv":0.0,"id":16858291},{"batb":[[0,4.2,1.46]],"batl":[[0,7.2,6],[1,7.2,0]],"ltp":4.2,"tv":9.08,"id":16858293},{"batb":[[0,2.76,6],[1,1.02,2],[2,1.01,1.01]],"batl":[[0,3.7,4],[1,3.7,0]],"ltp":0.0,"tv":0.0,"id":13460814},{"batl":[[0,7.2,6],[1,7.2,0]],"ltp":0.0,"tv":0.0,"id":13460817}]}]}
{"op":"mcm","clk":"1010362586","pt":1580674796127,"mc":[{"id":"1.168238841","rc":[{"batb":[[0,3.65,28.8],[1,3.35,5],[2,1.02,2]],"batl":[[0,4.1,27.93],[1,4.7,4]],"ltp":0.0,"tv":0.0,"id":16858291},{"batb":[[0,5.1,26.36],[1,4.2,1.46],[2,1.02,2]],"batl":[[0,5.9,25.26],[1,7.2,6]],"ltp":4.2,"tv":9.08,"id":16858293},{"batb":[[0,2.78,23.21],[1,2.76,6],[2,1.02,2]],"batl":[[0,3.05,22.82],[1,3.7,4]],"ltp":0.0,"tv":0.0,"id":13460814},{"batb":[[0,4.4,37.85],[1,3.9,5],[2,1.02,2]],"batl":[[0,5,36.04],[1,7.2,6]],"ltp":0.0,"tv":0.0,"id":13460817}]}]}
{"op":"mcm","clk":"1010362663","pt":1580674796831,"mc":[{"id":"1.168238841","rc":[{"batb":[[2,2.2,12.92]],"ltp":4.2,"tv":9.08,"id":16858293}]}]}
{"op":"mcm","clk":"1010365118","pt":1580674822058,"mc":[{"id":"1.168238841","rc":[{"trd":[[2.76,11.58],[2.78,46.42]],"batb":[[0,1.02,2.21],[1,1.01,1.01],[2,1.02,0]],"ltp":2.76,"tv":58.0,"id":13460814}],"tv":67.08}]}
{"op":"mcm","clk":"1010365158","pt":1580674822607,"mc":[{"id":"1.168238841","rc":[{"batb":[[0,3.7,28.48]],"batl":[[0,4.1,27.7]],"ltp":0.0,"tv":0.0,"id":16858291},{"batb":[[0,5.1,26.12]],"batl":[[0,5.9,25.1]],"ltp":4.2,"tv":9.08,"id":16858293},{"batb":[[0,2.76,23.81],[1,1.02,2],[2,1.01,1.01]],"batl":[[0,3,23.21]],"ltp":2.76,"tv":58.0,"id":13460814},{"batb":[[0,4.4,37.53]],"batl":[[0,5,35.72]],"ltp":0.0,"tv":0.0,"id":13460817}]}]}
{"op":"mcm","clk":"1010370566","pt":1580674876230,"mc":[{"id":"1.168238841","rc":[{"batl":[[0,5.8,25.26],[1,5.9,25.1],[2,7.2,6]],"ltp":4.2,"tv":9.08,"id":16858293},{"batl":[[0,2.92,23.05],[1,3,23.21],[2,3.7,4]],"ltp":2.76,"tv":58.0,"id":13460814}]}]}
{"op":"mcm","clk":"1010370614","pt":1580674876654,"mc":[{"id":"1.168238841","rc":[{"batb":[[2,1.02,2]],"batl":[[1,7.2,6],[2,7.2,0]],"ltp":4.2,"tv":9.08,"id":16858293},{"trd":[[2.92,45.88]],"batb":[[0,2.76,23.66]],"batl":[[0,3.7,4.11],[1,3,0],[2,3.7,0]],"ltp":2.92,"tv":103.88,"id":13460814},{"batb":[[0,4.4,37.3]],"batl":[[0,5,35.56]],"ltp":0.0,"tv":0.0,"id":13460817}],"tv":112.96}]}
{"op":"mcm","clk":"1010371598","pt":1580674886215,"mc":[{"id":"1.168238841","rc":[{"batb":[[1,3.65,28.95],[2,3.35,5]],"ltp":0.0,"tv":0.0,"id":16858291},{"batl":[[1,5.9,25.49],[2,7.2,6]],"ltp":4.2,"tv":9.08,"id":16858293},{"batb":[[0,2.8,23.05],[1,2.76,23.66],[2,1.02,2]],"batl":[[0,3.05,22.77],[1,3.7,4]],"ltp":2.92,"tv":103.88,"id":13460814}]}]}
{"op":"mcm","clk":"1010371643","pt":1580674886574,"mc":[{"id":"1.168238841","rc":[{"batb":[[0,3.65,28.95],[1,3.35,5],[2,1.02,2]],"ltp":0.0,"tv":0.0,"id":16858291},{"batl":[[0,5.9,25.49],[1,7.2,6],[2,7.2,0]],"ltp":4.2,"tv":9.08,"id":16858293},{"batb":[[1,1.02,2.21],[2,1.01,1.01]],"batl":[[0,3.05,22.66]],"ltp":2.92,"tv":103.88,"id":13460814}]}]}
{"op":"mcm","clk":"1010373865","pt":1580674908202,"mc":[{"id":"1.168238841","marketDefinition":{"bspMarket":false,"turnInPlayEnabled":true,"persistenceEnabled":true,"marketBaseRate":5.0,"eventId":"29681898","eventTypeId":"2","numberOfWinners":1,"bettingType":"ODDS","marketType":"SET_BETTING","marketTime":"2020-02-02T20:18:00.000Z","suspendTime":"2020-02-02T20:18:00.000Z","bspReconciled":false,"complete":true,"inPlay":false,"crossMatching":true,"runnersVoidable":false,"numberOfActiveRunners":4,"betDelay":0,"status":"OPEN","runners":[{"status":"ACTIVE","sortPriority":1,"id":16858291,"name":"Galan 2-0"},{"status":"ACTIVE","sortPriority":2,"id":16858293,"name":"Galan 2-1"},{"status":"ACTIVE","sortPriority":3,"id":13460814,"name":"Kwiatkowski 2-0"},{"status":"ACTIVE","sortPriority":4,"id":13460817,"name":"Kwiatkowski 2-1"}],"regulators":["MR_INT"],"countryCode":"US","discountAllowed":true,"timezone":"UTC","openDate":"2020-02-02T20:30:00.000Z","version":3150502604,"name":"Set Betting","eventName":"Galan v Kwiatkowski"}}]}
{"op":"mcm","clk":"1010374305","pt":1580674912182,"mc":[{"id":"1.168238841","marketDefinition":{"bspMarket":false,"turnInPlayEnabled":true,"persistenceEnabled":true,"marketBaseRate":5.0,"eventId":"29681898","eventTypeId":"2","numberOfWinners":1,"bettingType":"ODDS","marketType":"SET_BETTING","marketTime":"2020-02-02T20:18:00.000Z","suspendTime":"2020-02-02T20:18:00.000Z","bspReconciled":false,"complete":true,"inPlay":false,"crossMatching":true,"runnersVoidable":false,"numberOfActiveRunners":4,"betDelay":0,"status":"OPEN","runners":[{"status":"ACTIVE","sortPriority":1,"id":16858291,"name":"Galan 2-0"},{"status":"ACTIVE","sortPriority":2,"id":16858293,"name":"Galan 2-1"},{"status":"ACTIVE","sortPriority":3,"id":13460814,"name":"Kwiatkowski 2-0"},{"status":"ACTIVE","sortPriority":4,"id":13460817,"name":"Kwiatkowski 2-1"}],"regulators":["MR_INT"],"countryCode":"US","discountAllowed":true,"timezone":"UTC","openDate":"2020-02-02T20:18:00.000Z","version":3150502604,"name":"Set Betting","eventName":"Galan v Kwiatkowski"}}]}
{"op":"mcm","clk":"1010380978","pt":1580674976034,"mc":[{"id":"1.168238841","marketDefinition":{"bspMarket":false,"turnInPlayEnabled":true,"persistenceEnabled":true,"marketBaseRate":5.0,"eventId":"29681898","eventTypeId":"2","numberOfWinners":1,"bettingType":"ODDS","marketType":"SET_BETTING","marketTime":"2020-02-02T20:18:00.000Z","suspendTime":"2020-02-02T20:18:00.000Z","bspReconciled":false,"complete":true,"inPlay":true,"crossMatching":true,"runnersVoidable":false,"numberOfActiveRunners":4,"betDelay":3,"status":"OPEN","runners":[{"status":"ACTIVE","sortPriority":1,"id":16858291,"name":"Galan 2-0"},{"status":"ACTIVE","sortPriority":2,"id":16858293,"name":"Galan 2-1"},{"status":"ACTIVE","sortPriority":3,"id":13460814,"name":"Kwiatkowski 2-0"},{"status":"ACTIVE","sortPriority":4,"id":13460817,"name":"Kwiatkowski 2-1"}],"regulators":["MR_INT"],"countryCode":"US","discountAllowed":true,"timezone":"UTC","openDate":"2020-02-02T20:18:00.000Z","version":3150503664,"name":"Set Betting","eventName":"Galan v Kwiatkowski"},"rc":[{"batb":[[0,1.01,0.51],[1,3.35,0],[2,1.02,0]],"ltp":0.0,"tv":0.0,"id":16858291},{"batb":[[0,1.01,0.51],[1,4.2,0],[2,1.02,0]],"ltp":4.2,"tv":9.08,"id":16858293},{"batb":[[0,1.01,0.51],[1,1.02,0],[2,1.01,0]],"ltp":2.92,"tv":103.88,"id":13460814},{"batb":[[0,1.01,0.51],[1,3.9,0],[2,1.02,0]],"ltp":0.0,"tv":0.0,"id":13460817}]}]}
{"op":"mcm","clk":"1010381720","pt":1580674982028,"mc":[{"id":"1.168238841","rc":[{"batb":[[0,3.4,34.54],[1,3.2,39.97],[2,1.01,0.51]],"batl":[[0,3.8,33.44],[1,4.2,26.36]],"ltp":0.0,"tv":0.0,"id":16858291},{"batb":[[0,5,27.22],[1,1.01,0.51]],"batl":[[0,5.8,25.73]],"ltp":4.2,"tv":9.08,"id":16858293},{"batb":[[0,2.98,48.78],[1,2.74,24.16],[2,1.01,0.51]],"batl":[[0,3.3,46.89],[1,3.5,40.21]],"ltp":2.92,"tv":103.88,"id":13460814},{"batb":[[0,4.3,39.34],[1,1.01,0.51]],"batl":[[0,5,35.88]],"ltp":0.0,"tv":0.0,"id":13460817}]}]}
{"op":"mcm","clk":"1010382385","pt":1580674987735,"mc":[{"id":"1.168238841","rc":[{"batb":[[0,3.2,39.97],[1,1.01,0.51],[2,1.01,0]],"batl":[[0,4.2,26.36],[1,4.2,0]],"ltp":0.0,"tv":0.0,"id":16858291},{"batb":[[0,2.74,24.16],[1,1.01,0.51],[2,1.01,0]],"batl":[[0,3.5,40.21],[1,3.5,0]],"ltp":2.92,"tv":103.88,"id":13460814}]}]}
{"op":"mcm","clk":"1010384358","pt":1580675004262,"mc":[{"id":"1.168238841","rc":[{"batb":[[0,3.75,27.15],[1,3.45,33.6],[2,1.01,0.51]],"batl":[[1,5,36.74]],"ltp":0.0,"tv":0.0,"id":16858291},{"batb":[[0,5,26.83]],"batl":[[0,5.9,25.41]],"ltp":4.2,"tv":9.08,"id":16858293},{"batb":[[1,2.46,32.34],[2,1.01,0.51]],"batl":[[0,2.98,23.68],[1,3.25,47.92]],"ltp":2.92,"tv":103.88,"id":13460814},{"batb":[[0,4.4,37.69],[1,4.3,38.95],[2,1.01,0.51]],"batl":[[1,5.1,33.99]],"ltp":0.0,"tv":0.0,"id":13460817}]}]}
{"op":"mcm","clk":"1010385533","pt":1580675015103,"mc":[{"id":"1.168238841","rc":[{"batb":[[0,3.45,33.6],[1,1.01,0.51],[2,1.01,0]],"batl":[[0,5,36.74],[1,5,0]],"ltp":0.0,"tv":0.0,"id":16858291},{"batb":[[0,2.46,32.34],[1,1.01,0.51],[2,1.01,0]],"batl":[[0,3.25,47.92],[1,3.25,0]],"ltp":2.92,"tv":103.88,"id":13460814},{"batb":[[0,4.3,38.95],[1,1.01,0.51],[2,1.01,0]],"batl":[[0,5.1,33.99],[1,5.1,0]],"ltp":0.0,"tv":0.0,"id":13460817}]}]}
{"op":"mcm","clk":"1010385730","pt":1580675016798,"mc":[{"id":"1.168238841","rc":[{"batb":[[1,4.9,130.02],[2,4.8,105.08]],"ltp":4.2,"tv":9.08,"id":16858293},{"batb":[[0,4.3,166.67],[1,4.2,142.1],[2,1.01,0.51]],"ltp":0.0,"tv":0.0,"id":13460817}]}]}
{"op":"mcm","clk":"1010385876","pt":1580675018190,"mc":[{"id":"1.168238841","rc":[{"batb":[[0,3.55,150.6],[1,3.5,111.48],[2,3.45,33.6]],"ltp":0.0,"tv":0.0,"id":16858291}]}]}
{"op":"mcm","clk":"1010386210","pt":1580675021280,"mc":[{"id":"1.168238841","rc":[{"batl":[[0,3.85,32.57],[1,4.4,48.7],[2,5,36.74]],"ltp":0.0,"tv":0.0,"id":16858291},{"batb":[[0,3.1,216.87],[1,3.05,155.96],[2,2.96,49.81]],"batl":[[1,3.5,40.84]],"ltp":2.92,"tv":103.88,"id":13460814}]}]}
{"op":"mcm","clk":"1010386231","pt":1580675021493,"mc":[{"id":"1.168238841","rc":[{"batl":[[2,5,0]],"ltp":0.0,"tv":0.0,"id":16858291}]}]}
{"op":"mcm","clk":"1010387213","pt":1580675029905,"mc":[{"id":"1.168238841","rc":[{"batb":[[0,3.25,39.26],[1,1.01,0.51],[2,3.45,0]],"batl":[[0,4.4,48.7],[1,4.4,0]],"ltp":0.0,"tv":0.0,"id":16858291},{"batb":[[1,4.9,96.39]],"ltp":4.2,"tv":9.08,"id":16858293},{"batb":[[0,2.68,25.73],[1,1.01,0.51],[2,2.96,0]],"batl":[[0,3.5,40.84],[1,3.5,0]],"ltp":2.92,"tv":103.88,"id":13460814},{"batb":[[0,4.3,131.43]],"ltp":0.0,"tv":0.0,"id":13460817}]}]}
{"op":"mcm","clk":"1010387560","pt":1580675032818,"mc":[{"id":"1.168238841","rc":[{"batb":[[0,3.35,166.87],[1,3.3,128.57],[2,3.25,39.26]],"ltp":0.0,"tv":0.0,"id":16858291},{"batb":[[0,2.84,170.96],[1,2.8,156.1],[2,2.68,25.73]],"ltp":2.92,"tv":103.88,"id":13460814}]}]}
{"op":"mcm","clk":"1010388188","pt":1580675039082,"mc":[{"id":"1.168238841","rc":[{"batb":[[0,3.25,39.26],[1,1.01,0.51],[2,3.25,0]],"ltp":0.0,"tv":0.0,"id":16858291},{"batb":[[1,2.68,25.73],[2,1.01,0.51]],"ltp":2.92,"tv":103.88,"id":13460814},{"batb":[[1,1.01,0.51],[2,1.01,0]],"ltp":0.0,"tv":0.0,"id":13460817}]}]}
{"op":"mcm","clk":"1010388526","pt":1580675042203,"mc":[{"id":"1.168238841","rc":[{"batb":[[0,3.9,147.73],[1,3.85,88.12],[2,3.8,52.01]],"batl":[[1,5.3,31.16]],"ltp":0.0,"tv":0.0,"id":16858291},{"batb":[[0,2.68,25.57],[1,2.34,36.67]],"batl":[[0,2.9,25.1],[1,3.25,48]],"ltp":2.92,"tv":103.88,"id":13460814},{"batb":[[0,4.4,135.73],[1,4.3,175.8],[2,1.01,0.51]],"batl":[[1,5.2,32.73]],"ltp":0.0,"tv":0.0,"id":13460817}]}]}
{"op":"mcm","clk":"1010388825","pt":1580675045005,"mc":[{"id":"1.168238841","rc":[{"batb":[[0,2.86,179.62],[1,2.82,153.96],[2,2.68,25.57]],"ltp":2.92,"tv":103.88,"id":13460814}]}]}
{"op":"mcm","clk":"1010389849","pt":1580675053821,"mc":[{"id":"1.168238841","rc":[{"batb":[[0,3.8,52.01],[1,3.45,33.6],[2,1.01,0.51]],"ltp":0.0,"tv":0.0,"id":16858291},{"batb":[[1,4.9,74.66]],"ltp":4.2,"tv":9.08,"id":16858293},{"batb":[[0,2.68,25.57],[1,2.34,36.67],[2,1.01,0.51]],"ltp":2.92,"tv":103.88,"id":13460814},{"batb":[[0,4.4,36.74]],"ltp":0.0,"tv":0.0,"id":13460817}]}]}
{"op":"mcm","clk":"1010389984","pt":1580675055023,"mc":[{"id":"1.168238841","rc":[{"batb":[[0,3.45,33.6],[1,1.01,0.51],[2,1.01,0]],"batl":[[0,5.3,31.16],[1,5.3,0]],"ltp":0.0,"tv":0.0,"id":16858291},{"batb":[[0,2.34,36.67],[1,1.01,0.51],[2,1.01,0]],"batl":[[0,3.25,48],[1,3.25,0]],"ltp":2.92,"tv":103.88,"id":13460814},{"batb":[[0,4.3,175.8],[1,1.01,0.51],[2,1.01,0]],"batl":[[0,5.2,32.73],[1,5.2,0]],"ltp":0.0,"tv":0.0,"id":13460817}]}]}
{"op":"mcm","clk":"1010390306","pt":1580675058034,"mc":[{"id":"1.168238841","rc":[{"batb":[[0,3.4,34.23]],"ltp":0.0,"tv":0.0,"id":16858291},{"batl":[[0,5.8,25.89]],"ltp":4.2,"tv":9.08,"id":16858293},{"batb":[[0,2.36,36.12]],"batl":[[0,3.3,47.13]],"ltp":2.92,"tv":103.88,"id":13460814},{"batb":[[0,4.3,175.09]],"batl":[[0,5.3,32.34]],"ltp":0.0,"tv":0.0,"id":13460817}]}]}
{"op":"mcm","clk":"1010390346","pt":1580675058350,"mc":[{"id":"1.168238841","rc":[{"batb":[[0,4,230.56],[1,3.95,82.2],[2,3.4,34.23]],"ltp":0.0,"tv":0.0,"id":16858291},{"batb":[[0,2.78,165.61],[1,2.74,165.96],[2,2.36,36.12]],"ltp":2.92,"tv":103.88,"id":13460814},{"batb":[[0,4.4,122.39],[1,4.3,175.09],[2,1.01,0.51]],"ltp":0.0,"tv":0.0,"id":13460817}]}]}
{"op":"mcm","clk":"1010390890","pt":1580675063217,"mc":[{"id":"1.168238841","rc":[{"batb":[[0,3.4,34.23],[1,1.01,0.51],[2,3.4,0]],"ltp":0.0,"tv":0.0,"id":16858291},{"batb":[[0,2.36,36.12],[1,1.01,0.51],[2,2.36,0]],"ltp":2.92,"tv":103.88,"id":13460814},{"batb":[[0,4.3,175.09],[1,1.01,0.51],[2,1.01,0]],"ltp":0.0,"tv":0.0,"id":13460817}]}]}
{"op":"mcm","clk":"1010391146","pt":1580675065654,"mc":[{"id":"1.168238841","rc":[{"batb":[[0,3.5,179.56],[1,3.45,114.53],[2,3.4,34.23]],"ltp":0.0,"tv":0.0,"id":16858291},{"batb":[[0,2.48,216.9],[1,2.44,225.47],[2,2.36,36.12]],"ltp":2.92,"tv":103.88,"id":13460814},{"batb":[[1,4.2,143.42],[2,1.01,0.51]],"ltp":0.0,"tv":0.0,"id":13460817}]}]}
{"op":"mcm","clk":"1010392383","pt":1580675076455,"mc":[{"id":"1.168238841","rc":[{"batb":[[0,3.4,34.23],[1,1.01,0.51],[2,3.4,0]],"ltp":0.0,"tv":0.0,"id":16858291},{"batb":[[0,4.3,38.24],[1,1.01,0.51],[2,1.01,0]],"ltp":0.0,"tv":0.0,"id":13460817}]}]}
{"op":"mcm","clk":"1010392843","pt":1580675080262,"mc":[{"id":"1.168238841","rc":[{"batb":[[0,4.8,127.06],[1,4.7,109.58],[2,4.6,33.28]],"batl":[[1,7.8,28.01]],"ltp":0.0,"tv":0.0,"id":16858291},{"batb":[[1,4.9,113.81]],"ltp":4.2,"tv":9.08,"id":16858293},{"batl":[[0,2.54,35.33],[1,2.88,25.49]],"ltp":2.92,"tv":103.88,"id":13460814},{"batb":[[0,4.6,33.83],[1,4.5,91.11],[2,4.4,166.27]],"batl":[[1,5.5,29.66]],"ltp":0.0,"tv":0.0,"id":13460817}]}]}
{"op":"mcm","clk":"1010394792","pt":1580675096992,"mc":[{"id":"1.168238841","rc":[{"batb":[[0,2.48,155.54]],"ltp":2.92,"tv":103.88,"id":13460814},{"batb":[[1,4.4,166.27],[2,1.01,0.51]],"ltp":0.0,"tv":0.0,"id":13460817}]}]}
{"op":"mcm","clk":"1010395180","pt":1580675100175,"mc":[{"id":"1.168238841","rc":[{"batb":[[0,4.8,163.97]],"ltp":0.0,"tv":0.0,"id":16858291},{"batb":[[1,4.9,149.79]],"ltp":4.2,"tv":9.08,"id":16858293},{"batb":[[1,4.4,232.66],[2,4.3,134.77]],"ltp":0.0,"tv":0.0,"id":13460817}]}]}
{"op":"mcm","clk":"1010395318","pt":1580675101281,"mc":[{"id":"1.168238841","rc":[{"batb":[[0,3.85,51.38],[1,1.01,0.51],[2,4.6,0]],"batl":[[0,7.8,28.01],[1,7.8,0]],"ltp":0.0,"tv":0.0,"id":16858291},{"batb":[[0,2.02,55.86],[1,1.01,0.51],[2,2.36,0]],"batl":[[0,2.88,25.49],[1,2.88,0]],"ltp":2.92,"tv":103.88,"id":13460814},{"batb":[[0,4.4,36.35],[1,4.3,134.77],[2,1.01,0.51]],"batl":[[0,5.5,29.66],[1,5.5,0]],"ltp":0.0,"tv":0.0,"id":13460817}]}]}
{"op":"mcm","clk":"1010395648","pt":1580675104203,"mc":[{"id":"1.168238841","rc":[{"batb":[[0,4,97.79],[1,3.95,83.84],[2,3.85,51.38]],"ltp":0.0,"tv":0.0,"id":16858291},{"batb":[[0,2.06,232.01],[1,2.04,189.19],[2,2.02,55.86]],"ltp":2.92,"tv":103.88,"id":13460814},{"batb":[[1,4.3,204.91],[2,4.2,142.25]],"ltp":0.0,"tv":0.0,"id":13460817}]}]}
{"op":"mcm","clk":"1010396299","pt":1580675109586,"mc":[{"id":"1.168238841","rc":[{"batb":[[0,2.02,55.86],[1,1.01,0.51],[2,2.02,0]],"ltp":2.92,"tv":103.88,"id":13460814}]}]}
{"op":"mcm","clk":"1010396605","pt":1580675112283,"mc":[{"id":"1.168238841","rc":[{"batb":[[0,2.82,177.41],[1,2.78,159.45],[2,2.02,55.86]],"ltp":2.92,"tv":103.88,"id":13460814}]}]}
{"op":"mcm","clk":"1010396674","pt":1580675112912,"mc":[{"id":"1.168238841","rc":[{"batl":[[0,4.4,48.63],[1,5.4,30.84]],"ltp":0.0,"tv":0.0,"id":16858291},{"batl":[[0,5.8,25.73]],"ltp":4.2,"tv":9.08,"id":16858293},{"batb":[[2,2.66,25.89]],"batl":[[1,3.25,48.7]],"ltp":2.92,"tv":103.88,"id":13460814},{"batl":[[0,5.1,34.62],[1,5.3,32.42]],"ltp":0.0,"tv":0.0,"id":13460817}]}]}
{"op":"mcm","clk":"1010398126","pt":1580675126937,"mc":[{"id":"1.168238841","rc":[{"batb":[[0,3.45,33.2],[1,1.01,0.51],[2,3.85,0]],"batl":[[0,5.4,30.84],[1,5.4,0]],"ltp":0.0,"tv":0.0,"id":16858291},{"batb":[[1,4.9,117.14]],"ltp":4.2,"tv":9.08,"id":16858293},{"batb":[[0,2.36,36.43],[1,1.01,0.51],[2,2.66,0]],"batl":[[0,3.25,48.7],[1,3.25,0]],"ltp":2.92,"tv":103.88,"id":13460814},{"batb":[[1,4.3,134.77]],"batl":[[0,5.3,32.42],[1,5.3,0]],"ltp":0.0,"tv":0.0,"id":13460817}]}]}
{"op":"mcm","clk":"1010398498","pt":1580675130249,"mc":[{"id":"1.168238841","rc":[{"batb":[[2,1.01,0.51]],"ltp":0.0,"tv":0.0,"id":13460817}]}]}
{"op":"mcm","clk":"1010398924","pt":1580675133930,"mc":[{"id":"1.168238841","rc":[{"batb":[[0,4.1,184.09],[1,4,159.23],[2,3.45,33.2]],"ltp":0.0,"tv":0.0,"id":16858291},{"batb":[[1,4.9,142]],"ltp":4.2,"tv":9.08,"id":16858293},{"batb":[[0,2.74,172.27],[1,2.7,172.07],[2,2.36,36.43]],"ltp":2.92,"tv":103.88,"id":13460814},{"batb":[[0,4.4,129.4]],"ltp":0.0,"tv":0.0,"id":13460817}]}]}
{"op":"mcm","clk":"1010399072","pt":1580675135266,"mc":[{"id":"1.168238841","rc":[{"batb":[[0,3.45,33.2],[1,1.01,0.51],[2,3.45,0]],"ltp":0.0,"tv":0.0,"id":16858291},{"batb":[[1,4.9,117.14]],"ltp":4.2,"tv":9.08,"id":16858293},{"batb":[[0,2.36,36.43],[1,1.01,0.51],[2,2.36,0]],"ltp":2.92,"tv":103.88,"id":13460814},{"batb":[[0,4.4,36.35]],"ltp":0.0,"tv":0.0,"id":13460817}]}]}
{"op":"mcm","clk":"1010399388","pt":1580675138261,"mc":[{"id":"1.168238841","rc":[{"batb":[[0,3.55,192.58],[1,3.5,111.06],[2,3.45,33.2]],"ltp":0.0,"tv":0.0,"id":16858291},{"batb":[[0,2.46,155.94],[1,2.42,230.56],[2,2.36,36.43]],"ltp":2.92,"tv":103.88,"id":13460814},{"batb":[[2,4.2,143.64]],"ltp":0.0,"tv":0.0,"id":13460817}]}]}
{"op":"mcm","clk":"1010400340","pt":1580675147153,"mc":[{"id":"1.168238841","rc":[{"batb":[[0,2.36,36.43],[1,1.01,0.51],[2,2.36,0]],"ltp":2.92,"tv":103.88,"id":13460814}]}]}
{"op":"mcm","clk":"1010400659","pt":1580675150181,"mc":[{"id":"1.168238841","rc":[{"batb":[[0,3.1,173.27],[1,3.05,156.84],[2,2.36,36.43]],"ltp":2.92,"tv":103.88,"id":13460814}]}]}
{"op":"mcm","clk":"1010400795","pt":1580675151254,"mc":[{"id":"1.168238841","rc":[{"batb":[[0,3.55,108.29],[1,3.45,33.2],[2,3.2,39.97]],"batl":[[0,3.85,32.1],[1,4.4,47.13]],"ltp":0.0,"tv":0.0,"id":16858291},{"batb":[[2,2.94,50.75]],"batl":[[1,3.5,40.21]],"ltp":2.92,"tv":103.88,"id":13460814},{"batb":[[0,4.3,173.8],[1,4.2,143.64],[2,1.01,0.51]],"batl":[[0,5,35.96],[1,5.1,34.7]],"ltp":0.0,"tv":0.0,"id":13460817}]}]}
{"op":"mcm","clk":"1010401119","pt":1580675154282,"mc":[{"id":"1.168238841","rc":[{"batb":[[0,3.6,84.98],[1,3.55,108.29],[2,3.45,33.2]],"ltp":0.0,"tv":0.0,"id":16858291}]}]}
{"op":"mcm","clk":"1010401675","pt":1580675159124,"mc":[{"id":"1.168238841","rc":[{"batb":[[0,3.2,39.97],[1,1.01,0.51],[2,3.45,0]],"batl":[[0,4.4,47.13],[1,4.4,0]],"ltp":0.0,"tv":0.0,"id":16858291},{"batb":[[1,4.9,113.81]],"ltp":4.2,"tv":9.08,"id":16858293},{"batb":[[0,2.64,26.44],[1,1.01,0.51],[2,2.94,0]],"batl":[[0,3.5,40.21],[1,3.5,0]],"ltp":2.92,"tv":103.88,"id":13460814},{"batb":[[0,4.3,114.78]],"batl":[[0,5.1,34.7],[1,5.1,0]],"ltp":0.0,"tv":0.0,"id":13460817}]}]}
{"op":"mcm","clk":"1010401990","pt":1580675162215,"mc":[{"id":"1.168238841","rc":[{"batb":[[0,3.35,147.84],[1,3.3,128.74],[2,3.2,39.97]],"ltp":0.0,"tv":0.0,"id":16858291},{"batb":[[0,2.8,150.78],[1,2.76,162.63],[2,2.64,26.44]],"ltp":2.92,"tv":103.88,"id":13460814}]}]}
{"op":"mcm","clk":"1010402092","pt":1580675163179,"mc":[{"id":"1.168238841","rc":[{"batb":[[0,3.2,39.97],[1,1.01,0.51],[2,3.2,0]],"ltp":0.0,"tv":0.0,"id":16858291},{"batb":[[0,2.64,26.44],[1,1.01,0.51],[2,2.64,0]],"ltp":2.92,"tv":103.88,"id":13460814}]}]}
{"op":"mcm","clk":"1010402390","pt":1580675166120,"mc":[{"id":"1.168238841","rc":[{"batb":[[0,3.65,151.73],[1,3.6,104.11],[2,3.2,39.97]],"ltp":0.0,"tv":0.0,"id":16858291},{"batb":[[0,3.05,118.17],[1,3,163.98],[2,2.64,26.44]],"ltp":2.92,"tv":103.88,"id":13460814},{"batb":[[0,4.3,178.92]],"ltp":0.0,"tv":0.0,"id":13460817}]}]}
{"op":"mcm","clk":"1010402690","pt":1580675168838,"mc":[{"id":"1.168238841","rc":[{"batb":[[0,3.2,39.97],[1,1.01,0.51],[2,3.2,0]],"ltp":0.0,"tv":0.0,"id":16858291},{"batb":[[0,2.64,26.44],[1,1.01,0.51],[2,2.64,0]],"ltp":2.92,"tv":103.88,"id":13460814},{"batb":[[0,4.3,114.78]],"ltp":0.0,"tv":0.0,"id":13460817}]}]}
{"op":"mcm","clk":"1010402968","pt":1580675171616,"mc":[{"id":"1.168238841","rc":[{"batb":[[0,3.35,147.84],[1,3.3,128.74],[2,3.2,39.97]],"ltp":0.0,"tv":0.0,"id":16858291},{"batb":[[0,2.8,150.78],[1,2.76,162.63],[2,2.64,26.44]],"ltp":2.92,"tv":103.88,"id":13460814}]}]}
{"op":"mcm","clk":"1010403335","pt":1580675175222,"mc":[{"id":"1.168238841","rc":[{"batb":[[0,2.64,26.44],[1,1.01,0.51],[2,2.64,0]],"ltp":2.92,"tv":103.88,"id":13460814}]}]}
{"op":"mcm","clk":"1010403631","pt":1580675178236,"mc":[{"id":"1.168238841","rc":[{"batb":[[0,3.3,213.64],[1,3.25,133.49],[2,2.64,26.44]],"ltp":2.92,"tv":103.88,"id":13460814}]}]}
{"op":"mcm","clk":"1010403723","pt":1580675179245,"mc":[{"id":"1.168238841","rc":[{"batl":[[0,3.55,38.55],[1,3.85,32.5]],"ltp":0.0,"tv":0.0,"id":16858291},{"batb":[[2,3.15,41.7]],"batl":[[1,4,29.58]],"ltp":2.92,"tv":103.88,"id":13460814},{"batb":[[0,4.3,75.75],[1,4.2,184.24]],"batl":[[0,5,36.43]],"ltp":0.0,"tv":0.0,"id":13460817}]}]}
{"op":"mcm","clk":"1010404015","pt":1580675181966,"mc":[{"id":"1.168238841","rc":[{"batb":[[0,3.3,128.74],[1,3.2,39.97],[2,2.9,51.77]],"ltp":0.0,"tv":0.0,"id":16858291},{"batb":[[1,4.9,74.66]],"ltp":4.2,"tv":9.08,"id":16858293},{"batb":[[0,3.3,129.75],[1,3.15,41.7],[2,2.96,49.49]],"ltp":2.92,"tv":103.88,"id":13460814}]}]}
{"op":"mcm","clk":"1010404353","pt":1580675185129,"mc":[{"id":"1.168238841","rc":[{"batb":[[0,3.3,219.72],[1,3.25,132.46],[2,3.2,39.97]],"ltp":0.0,"tv":0.0,"id":16858291},{"batb":[[0,3.35,138.14],[1,3.3,129.75],[2,3.15,41.7]],"ltp":2.92,"tv":103.88,"id":13460814},{"batb":[[0,4.3,115.59]],"ltp":0.0,"tv":0.0,"id":13460817}]}]}
{"op":"mcm","clk":"1010405631","pt":1580675197253,"mc":[{"id":"1.168238841","rc":[{"batb":[[0,3.3,128.74],[1,3.2,39.97],[2,2.9,51.77]],"ltp":0.0,"tv":0.0,"id":16858291}]}]}
{"op":"mcm","clk":"1010405937","pt":1580675200272,"mc":[{"id":"1.168238841","rc":[{"batb":[[0,3.35,91.83],[1,3.3,128.74],[2,3.2,39.97]],"ltp":0.0,"tv":0.0,"id":16858291}]}]}
{"op":"mcm","clk":"1010407445","pt":1580675215166,"mc":[{"id":"1.168238841","rc":[{"batb":[[0,3.2,39.97],[1,2.9,51.77],[2,1.01,0.51]],"ltp":0.0,"tv":0.0,"id":16858291},{"batb":[[1,4.8,105.08],[2,1.01,0.51]],"ltp":4.2,"tv":9.08,"id":16858293},{"batb":[[0,3.15,41.7],[1,2.96,49.49],[2,1.01,0.51]],"ltp":2.92,"tv":103.88,"id":13460814},{"batb":[[0,4.2,184.24],[1,1.01,0.51],[2,1.01,0]],"ltp":0.0,"tv":0.0,"id":13460817}]}]}
{"op":"mcm","clk":"1010407770","pt":1580675218258,"mc":[{"id":"1.168238841","rc":[{"batb":[[1,3,212.68],[2,2.96,134.6]],"ltp":0.0,"tv":0.0,"id":16858291},{"batb":[[1,4.8,151.93],[2,4.7,109.22]],"ltp":4.2,"tv":9.08,"id":16858293},{"batb":[[0,3.15,177.18],[1,3.1,151.45],[2,2.96,49.49]],"ltp":2.92,"tv":103.88,"id":13460814},{"batb":[[0,4.2,249.89],[1,4.1,151.2],[2,1.01,0.51]],"ltp":0.0,"tv":0.0,"id":13460817}]}]}
{"op":"mcm","clk":"1010408423","pt":1580675225269,"mc":[{"id":"1.168238841","rc":[{"batb":[[0,3,212.68],[1,2.96,134.6],[2,2.9,51.77]],"batl":[[0,3.85,32.5],[1,3.85,0]],"ltp":0.0,"tv":0.0,"id":16858291},{"batb":[[0,3.15,135.48]],"batl":[[0,4,29.58],[1,4,0]],"ltp":2.92,"tv":103.88,"id":13460814}]}]}
{"op":"mcm","clk":"1010409113","pt":1580675232225,"mc":[{"id":"1.168238841","rc":[{"batb":[[0,2.9,51.77],[1,1.01,0.51],[2,2.9,0]],"ltp":0.0,"tv":0.0,"id":16858291},{"batb":[[1,4.8,105.33],[2,1.01,0.51]],"ltp":4.2,"tv":9.08,"id":16858293},{"batb":[[0,4.2,184.58],[1,1.01,0.51],[2,1.01,0]],"ltp":0.0,"tv":0.0,"id":13460817}]}]}
{"op":"mcm","clk":"1010409360","pt":1580675235170,"mc":[{"id":"1.168238841","rc":[{"batb":[[0,3.55,110.01],[1,3.5,111.37],[2,2.9,51.77]],"ltp":0.0,"tv":0.0,"id":16858291},{"batb":[[1,4.9,72.71],[2,4.8,105.33]],"ltp":4.2,"tv":9.08,"id":16858293},{"batb":[[0,4.3,145.99],[1,4.2,184.58],[2,1.01,0.51]],"ltp":0.0,"tv":0.0,"id":13460817}]}]}
{"op":"mcm","clk":"1010409445","pt":1580675236159,"mc":[{"id":"1.168238841","rc":[{"batb":[[2,3.45,33.6]],"batl":[[1,4.1,28.17]],"ltp":0.0,"tv":0.0,"id":16858291},{"batl":[[0,5.7,26.67],[1,5.8,25.73]],"ltp":4.2,"tv":9.08,"id":16858293},{"batl":[[0,3.25,47.52],[1,3.65,37.06]],"ltp":2.92,"tv":103.88,"id":13460814},{"batb":[[0,4.3,185.65],[1,4.2,143.98]],"batl":[[0,5,35.96]],"ltp":0.0,"tv":0.0,"id":13460817}]}]}
{"op":"mcm","clk":"1010410386","pt":1580675246052,"mc":[{"id":"1.168238841","rc":[{"batb":[[0,3.1,42.65],[1,1.01,0.51],[2,3.45,0]],"batl":[[0,4.1,28.17],[1,4.1,0]],"ltp":0.0,"tv":0.0,"id":16858291},{"batb":[[1,4.8,105.33],[2,1.01,0.51]],"batl":[[0,5.8,25.73],[1,5.8,0]],"ltp":4.2,"tv":9.08,"id":16858293},{"batb":[[0,2.82,22.42],[1,1.01,0.51],[2,2.96,0]],"batl":[[0,3.65,37.06],[1,3.65,0]],"ltp":2.92,"tv":103.88,"id":13460814},{"batb":[[0,4.3,149.3]],"ltp":0.0,"tv":0.0,"id":13460817}]}]}
{"op":"mcm","clk":"1010410683","pt":1580675249161,"mc":[{"id":"1.168238841","rc":[{"batb":[[0,3,160.69],[1,2.96,136.35],[2,2.82,22.42]],"ltp":2.92,"tv":103.88,"id":13460814},{"batb":[[1,4.2,143.64]],"ltp":0.0,"tv":0.0,"id":13460817}]}]}
{"op":"mcm","clk":"1010410955","pt":1580675252195,"mc":[{"id":"1.168238841","rc":[{"batb":[[0,3.7,176.2],[1,3.65,100.05],[2,3.1,42.65]],"ltp":0.0,"tv":0.0,"id":16858291},{"batb":[[1,4.9,85.05],[2,4.8,105.33]],"ltp":4.2,"tv":9.08,"id":16858293},{"batb":[[0,4.3,206.29]],"ltp":0.0,"tv":0.0,"id":13460817}]}]}
{"op":"mcm","clk":"1010411034","pt":1580675253190,"mc":[{"id":"1.168238841","rc":[{"batb":[[1,3.65,129.08],[2,3.4,35.25]],"batl":[[1,4.3,49.81]],"ltp":0.0,"tv":0.0,"id":16858291},{"batl":[[0,3.05,22.03],[1,3.35,45.48]],"ltp":2.92,"tv":103.88,"id":13460814},{"batb":[[0,4.3,205.11]],"ltp":0.0,"tv":0.0,"id":13460817}]}]}
{"op":"mcm","clk":"1010411799","pt":1580675262271,"mc":[{"id":"1.168238841","rc":[{"batb":[[0,3.4,35.25],[1,1.01,0.51],[2,3.4,0]],"batl":[[0,4.3,49.81],[1,4.3,0]],"ltp":0.0,"tv":0.0,"id":16858291},{"batb":[[1,4.8,105.33],[2,1.01,0.51]],"ltp":4.2,"tv":9.08,"id":16858293},{"batb":[[0,2.72,24.47],[1,1.01,0.51],[2,2.82,0]],"batl":[[0,3.35,45.48],[1,3.35,0]],"ltp":2.92,"tv":103.88,"id":13460814}]}]}
{"op":"mcm","clk":"1010411964","pt":1580675264275,"mc":[{"id":"1.168238841","rc":[{"batb":[[0,3.5,121.91],[1,3.45,115.22],[2,3.4,35.25]],"ltp":0.0,"tv":0.0,"id":16858291},{"batb":[[1,4.8,165.71],[2,4.7,108.99]],"ltp":4.2,"tv":9.08,"id":16858293},{"batb":[[0,2.92,121.55],[1,2.88,146.47],[2,2.72,24.47]],"ltp":2.92,"tv":103.88,"id":13460814}]}]}
{"op":"mcm","clk":"1010412052","pt":1580675265169,"mc":[{"id":"1.168238841","rc":[{"batb":[[0,3.4,35.25],[1,1.01,0.51],[2,3.4,0]],"ltp":0.0,"tv":0.0,"id":16858291},{"batb":[[1,4.8,105.33],[2,1.01,0.51]],"ltp":4.2,"tv":9.08,"id":16858293},{"batb":[[0,2.72,24.47],[1,1.01,0.51],[2,2.72,0]],"ltp":2.92,"tv":103.88,"id":13460814}]}]}
{"op":"mcm","clk":"1010412205","pt":1580675267207,"mc":[{"id":"1.168238841","rc":[{"batb":[[0,3.65,182.52],[1,3.6,103.38],[2,3.4,35.25]],"ltp":0.0,"tv":0.0,"id":16858291},{"batb":[[1,4.9,79.73],[2,4.8,105.33]],"ltp":4.2,"tv":9.08,"id":16858293},{"batb":[[0,3.05,109.86],[1,3,164.65],[2,2.72,24.47]],"ltp":2.92,"tv":103.88,"id":13460814}]}]}
{"op":"mcm","clk":"1010412379","pt":1580675269211,"mc":[{"id":"1.168238841","rc":[{"batb":[[0,3.4,35.25],[1,1.01,0.51],[2,3.4,0]],"ltp":0.0,"tv":0.0,"id":16858291},{"batb":[[1,4.8,105.33],[2,1.01,0.51]],"ltp":4.2,"tv":9.08,"id":16858293},{"batb":[[0,2.72,24.47],[1,1.01,0.51],[2,2.72,0]],"ltp":2.92,"tv":103.88,"id":13460814}]}]}
