{"op":"mcm","clk":"1002483925","pt":1580594279657,"mc":[{"id":"1.168238840","marketDefinition":{"bspMarket":false,"turnInPlayEnabled":true,"persistenceEnabled":true,"marketBaseRate":5.0,"eventId":"29681898","eventTypeId":"2","numberOfWinners":1,"bettingType":"ODDS","marketType":"MATCH_ODDS","marketTime":"2020-02-02T18:00:00.000Z","suspendTime":"2020-02-02T18:00:00.000Z","bspReconciled":false,"complete":true,"inPlay":false,"crossMatching":false,"runnersVoidable":false,"numberOfActiveRunners":2,"betDelay":0,"status":"OPEN","runners":[{"status":"ACTIVE","sortPriority":1,"id":8860646,"name":"Daniel Elahi Galan"},{"status":"ACTIVE","sortPriority":2,"id":8258569,"name":"Thai-Son Kwiatkowski"}],"regulators":["MR_INT"],"countryCode":"US","discountAllowed":false,"timezone":"UTC","openDate":"2020-02-02T18:00:00.000Z","version":3147660993,"name":"Match Odds","eventName":"Galan v Kwiatkowski"},"rc":[{"batb":[[0,1.05,152.2],[1,1.04,168.86],[2,1.03,237.77]],"ltp":0.0,"tv":0.0,"id":8860646},{"batb":[[0,1.01,346.52]],"ltp":0.0,"tv":0.0,"id":8258569}]}]}
{"op":"mcm","clk":"1002483973","pt":1580594280292,"mc":[{"id":"1.168238840","marketDefinition":{"bspMarket":false,"turnInPlayEnabled":true,"persistenceEnabled":true,"marketBaseRate":5.0,"eventId":"29681898","eventTypeId":"2","numberOfWinners":1,"bettingType":"ODDS","marketType":"MATCH_ODDS","marketTime":"2020-02-02T18:00:00.000Z","suspendTime":"2020-02-02T18:00:00.000Z","bspReconciled":false,"complete":true,"inPlay":false,"crossMatching":false,"runnersVoidable":false,"numberOfActiveRunners":2,"betDelay":0,"status":"OPEN","runners":[{"status":"ACTIVE","sortPriority":1,"id":8860646,"name":"Daniel Elahi Galan"},{"status":"ACTIVE","sortPriority":2,"id":8258569,"name":"Thai-Son Kwiatkowski"}],"regulators":["MR_INT"],"countryCode":"US","discountAllowed":false,"timezone":"UTC","openDate":"2020-02-02T18:00:00.000Z","version":3147660993,"name":"Match Odds","eventName":"Galan v Kwiatkowski"}}]}
{"op":"mcm","clk":"1002484254","pt":1580594284306,"mc":[{"id":"1.168238840","marketDefinition":{"bspMarket":false,"turnInPlayEnabled":true,"persistenceEnabled":true,"marketBaseRate":5.0,"eventId":"29681898","eventTypeId":"2","numberOfWinners":1,"bettingType":"ODDS","marketType":"MATCH_ODDS","marketTime":"2020-02-02T18:00:00.000Z","suspendTime":"2020-02-02T18:00:00.000Z","bspReconciled":false,"complete":true,"inPlay":false,"crossMatching":false,"runnersVoidable":false,"numberOfActiveRunners":2,"betDelay":0,"status":"OPEN","runners":[{"status":"ACTIVE","sortPriority":1,"id":8860646,"name":"Daniel Elahi Galan"},{"status":"ACTIVE","sortPriority":2,"id":8258569,"name":"Thai-Son Kwiatkowski"}],"regulators":["MR_INT"],"countryCode":"US","discountAllowed":true,"timezone":"UTC","openDate":"2020-02-02T18:00:00.000Z","version":3147660993,"name":"Match Odds","eventName":"Galan v Kwiatkowski"}}]}
{"op":"mcm","clk":"1002486827","pt":1580594323598,"mc":[{"id":"1.168238840","rc":[{"batb":[[0,1.01,646.52]],"ltp":0.0,"tv":0.0,"id":8258569}]}]}
{"op":"mcm","clk":"1002487084","pt":1580594327383,"mc":[{"id":"1.168238840","rc":[{"batb":[[0,1.01,346.52]],"ltp":0.0,"tv":0.0,"id":8258569}]}]}
{"op":"mcm","clk":"1002493200","pt":1580594420134,"mc":[{"id":"1.168238840","rc":[{"batb":[[0,1.01,336.52]],"ltp":0.0,"tv":0.0,"id":8258569}]}]}
{"op":"mcm","clk":"1002524953","pt":1580594901242,"mc":[{"id":"1.168238840","rc":[{"batb":[[0,1.06,50.48],[1,1.05,152.2],[2,1.04,168.86]],"ltp":0.0,"tv":0.0,"id":8860646},{"batb":[[0,1.02,151.45],[1,1.01,336.52]],"ltp":0.0,"tv":0.0,"id":8258569}]}]}
{"op":"mcm","clk":"1002525799","pt":1580594914125,"mc":[{"id":"1.168238840","marketDefinition":{"bspMarket":false,"turnInPlayEnabled":true,"persistenceEnabled":true,"marketBaseRate":5.0,"eventId":"29681898","eventTypeId":"2","numberOfWinners":1,"bettingType":"ODDS","marketType":"MATCH_ODDS","marketTime":"2020-02-02T18:00:00.000Z","suspendTime":"2020-02-02T18:00:00.000Z","bspReconciled":false,"complete":true,"inPlay":false,"crossMatching":true,"runnersVoidable":false,"numberOfActiveRunners":2,"betDelay":0,"status":"OPEN","runners":[{"status":"ACTIVE","sortPriority":1,"id":8860646,"name":"Daniel Elahi Galan"},{"status":"ACTIVE","sortPriority":2,"id":8258569,"name":"Thai-Son Kwiatkowski"}],"regulators":["MR_INT"],"countryCode":"US","discountAllowed":true,"timezone":"UTC","openDate":"2020-02-02T18:00:00.000Z","version":3147660993,"name":"Match Odds","eventName":"Galan v Kwiatkowski"}}]}
{"op":"mcm","clk":"1002629161","pt":1580596307111,"mc":[{"id":"1.168238840","marketDefinition":{"bspMarket":false,"turnInPlayEnabled":true,"persistenceEnabled":true,"marketBaseRate":5.0,"eventId":"29681898","eventTypeId":"2","numberOfWinners":1,"bettingType":"ODDS","marketType":"MATCH_ODDS","marketTime":"2020-02-02T19:00:00.000Z","suspendTime":"2020-02-02T19:00:00.000Z","bspReconciled":false,"complete":true,"inPlay":false,"crossMatching":true,"runnersVoidable":false,"numberOfActiveRunners":2,"betDelay":0,"status":"OPEN","runners":[{"status":"ACTIVE","sortPriority":1,"id":8860646,"name":"Daniel Elahi Galan"},{"status":"ACTIVE","sortPriority":2,"id":8258569,"name":"Thai-Son Kwiatkowski"}],"regulators":["MR_INT"],"countryCode":"US","discountAllowed":true,"timezone":"UTC","openDate":"2020-02-02T18:00:00.000Z","version":3147732904,"name":"Match Odds","eventName":"Galan v Kwiatkowski"}}]}
{"op":"mcm","clk":"1002629419","pt":1580596310123,"mc":[{"id":"1.168238840","marketDefinition":{"bspMarket":false,"turnInPlayEnabled":true,"persistenceEnabled":true,"marketBaseRate":5.0,"eventId":"29681898","eventTypeId":"2","numberOfWinners":1,"bettingType":"ODDS","marketType":"MATCH_ODDS","marketTime":"2020-02-02T19:00:00.000Z","suspendTime":"2020-02-02T19:00:00.000Z","bspReconciled":false,"complete":true,"inPlay":false,"crossMatching":true,"runnersVoidable":false,"numberOfActiveRunners":2,"betDelay":0,"status":"OPEN","runners":[{"status":"ACTIVE","sortPriority":1,"id":8860646,"name":"Daniel Elahi Galan"},{"status":"ACTIVE","sortPriority":2,"id":8258569,"name":"Thai-Son Kwiatkowski"}],"regulators":["MR_INT"],"countryCode":"US","discountAllowed":true,"timezone":"UTC","openDate":"2020-02-02T19:00:00.000Z","version":3147732904,"name":"Match Odds","eventName":"Galan v Kwiatkowski"}}]}
{"op":"mcm","clk":"1002809066","pt":1580599058320,"mc":[{"id":"1.168238840","rc":[{"batb":[[0,1.67,24.44],[1,1.06,50.48],[2,1.05,152.2]],"ltp":0.0,"tv":0.0,"id":8860646},{"batb":[[0,1.57,25.85],[1,1.02,151.45],[2,1.01,336.52]],"ltp":0.0,"tv":0.0,"id":8258569}]}]}
{"op":"mcm","clk":"1002809789","pt":1580599069259,"mc":[{"id":"1.168238840","rc":[{"batb":[[0,1.82,22.53],[1,1.79,37.86],[2,1.06,50.48]],"ltp":0.0,"tv":0.0,"id":8860646},{"batb":[[0,1.85,21.97],[1,1.79,37.86],[2,1.02,151.45]],"ltp":0.0,"tv":0.0,"id":8258569}]}]}
{"op":"mcm","clk":"1002842535","pt":1580599519000,"mc":[{"id":"1.168238840","rc":[{"batb":[[0,1.88,37.86],[1,1.82,22.53]],"ltp":0.0,"tv":0.0,"id":8860646},{"batb":[[0,1.88,37.86],[1,1.85,21.97]],"ltp":0.0,"tv":0.0,"id":8258569}]}]}
{"op":"mcm","clk":"1002872538","pt":1580599897253,"mc":[{"id":"1.168238840","rc":[{"batb":[[1,1.06,50.48],[2,1.05,152.2]],"batl":[[0,2.28,18.48]],"ltp":0.0,"tv":0.0,"id":8860646},{"batb":[[1,1.02,151.45],[2,1.01,336.52]],"ltp":0.0,"tv":0.0,"id":8258569}]}]}
{"op":"mcm","clk":"1002872544","pt":1580599897355,"mc":[{"id":"1.168238840","rc":[{"batb":[[0,1.89,21.69],[1,1.88,37.86],[2,1.06,50.48]],"ltp":0.0,"tv":0.0,"id":8860646},{"batb":[[0,1.89,21.69],[1,1.88,37.86],[2,1.02,151.45]],"ltp":0.0,"tv":0.0,"id":8258569}]}]}
{"op":"mcm","clk":"1002874850","pt":1580599928090,"mc":[{"id":"1.168238840","rc":[{"batl":[[0,2.28,18.48]],"ltp":0.0,"tv":0.0,"id":8258569}]}]}
{"op":"mcm","clk":"1002985541","pt":1580601563833,"mc":[{"id":"1.168238840","rc":[{"batb":[[2,1.06,50.58]],"ltp":0.0,"tv":0.0,"id":8860646},{"batb":[[2,1.02,151.55]],"ltp":0.0,"tv":0.0,"id":8258569}]}]}
{"op":"mcm","clk":"1002985611","pt":1580601564555,"mc":[{"id":"1.168238840","rc":[{"batl":[[1,1000,0.02]],"ltp":0.0,"tv":0.0,"id":8860646},{"batb":[[2,1.02,152.05]],"batl":[[1,1000,0.02]],"ltp":0.0,"tv":0.0,"id":8258569}]}]}
{"op":"mcm","clk":"1002989736","pt":1580601621616,"mc":[{"id":"1.168238840","rc":[{"batb":[[2,1.06,50.68]],"ltp":0.0,"tv":0.0,"id":8860646},{"batb":[[2,1.02,152.15]],"ltp":0.0,"tv":0.0,"id":8258569}]}]}
{"op":"mcm","clk":"1002991875","pt":1580601653648,"mc":[{"id":"1.168238840","rc":[{"batb":[[0,1.88,59.57],[1,1.06,50.68],[2,1.05,152.2]],"ltp":0.0,"tv":0.0,"id":8860646},{"batb":[[0,1.88,59.57],[1,1.02,152.15],[2,1.01,338.52]],"ltp":0.0,"tv":0.0,"id":8258569}]}]}
{"op":"mcm","clk":"1002992239","pt":1580601659676,"mc":[{"id":"1.168238840","rc":[{"batb":[[0,1.88,37.86]],"ltp":0.0,"tv":0.0,"id":8860646},{"batb":[[0,1.88,37.86]],"ltp":0.0,"tv":0.0,"id":8258569}]}]}
{"op":"mcm","clk":"1002992282","pt":1580601660559,"mc":[{"id":"1.168238840","rc":[{"batb":[[0,1.88,59.57]],"ltp":0.0,"tv":0.0,"id":8860646},{"batb":[[0,1.88,59.57]],"ltp":0.0,"tv":0.0,"id":8258569}]}]}
{"op":"mcm","clk":"1002998913","pt":1580601764070,"mc":[{"id":"1.168238840","rc":[{"batb":[[0,1.88,21.71],[1,1.87,37.86],[2,1.06,50.68]],"ltp":0.0,"tv":0.0,"id":8860646},{"batb":[[0,1.88,21.71],[1,1.87,37.86],[2,1.02,152.15]],"ltp":0.0,"tv":0.0,"id":8258569}]}]}
{"op":"mcm","clk":"1003020722","pt":1580602060894,"mc":[{"id":"1.168238840","rc":[{"batl":[[0,2.06,15.14],[1,2.28,18.48],[2,1000,0.02]],"ltp":0.0,"tv":0.0,"id":8258569}]}]}
{"op":"mcm","clk":"1003021128","pt":1580602064893,"mc":[{"id":"1.168238840","rc":[{"batl":[[0,2.28,18.48],[1,1000,0.02],[2,1000,0]],"ltp":0.0,"tv":0.0,"id":8258569}]}]}
{"op":"mcm","clk":"1003027829","pt":1580602133704,"mc":[{"id":"1.168238840","rc":[{"batl":[[0,2,15.14],[1,2.28,18.48],[2,1000,0.02]],"ltp":0.0,"tv":0.0,"id":8258569}]}]}
{"op":"mcm","clk":"1003028535","pt":1580602142206,"mc":[{"id":"1.168238840","rc":[{"batl":[[0,2.28,18.48],[1,1000,0.02],[2,1000,0]],"ltp":0.0,"tv":0.0,"id":8258569}]}]}
{"op":"mcm","clk":"1003029894","pt":1580602157935,"mc":[{"id":"1.168238840","rc":[{"batb":[[0,1.87,37.86],[1,1.02,152.15],[2,1.01,338.52]],"ltp":0.0,"tv":0.0,"id":8258569}]}]}
{"op":"mcm","clk":"1003030083","pt":1580602160014,"mc":[{"id":"1.168238840","rc":[{"batb":[[0,1.02,152.15],[1,1.01,338.52],[2,1.01,0]],"ltp":0.0,"tv":0.0,"id":8258569}]}]}
{"op":"mcm","clk":"1003030135","pt":1580602160640,"mc":[{"id":"1.168238840","rc":[{"batb":[[0,1.93,37.86],[1,1.88,21.71]],"ltp":0.0,"tv":0.0,"id":8860646}]}]}
{"op":"mcm","clk":"1003030749","pt":1580602167138,"mc":[{"id":"1.168238840","rc":[{"batb":[[0,1.92,37.86]],"ltp":0.0,"tv":0.0,"id":8860646},{"batb":[[0,1.82,38.62],[1,1.02,152.15],[2,1.01,338.52]],"ltp":0.0,"tv":0.0,"id":8258569}]}]}
{"op":"mcm","clk":"1003051108","pt":1580602390230,"mc":[{"id":"1.168238840","rc":[{"batl":[[1,990,2.2],[2,1000,0.02]],"ltp":0.0,"tv":0.0,"id":8860646},{"batl":[[1,990,2.2],[2,1000,0.02]],"ltp":0.0,"tv":0.0,"id":8258569}]}]}
{"op":"mcm","clk":"1003051149","pt":1580602390700,"mc":[{"id":"1.168238840","rc":[{"batb":[[0,1.93,20.51],[1,1.92,37.86]],"ltp":0.0,"tv":0.0,"id":8860646},{"batb":[[0,1.83,23.03],[1,1.82,38.62],[2,1.02,152.15]],"ltp":0.0,"tv":0.0,"id":8258569}]}]}
{"op":"mcm","clk":"1003081094","pt":1580602720932,"mc":[{"id":"1.168238840","rc":[{"batb":[[0,1.93,30.79]],"ltp":0.0,"tv":0.0,"id":8860646},{"batb":[[0,1.83,34.56]],"ltp":0.0,"tv":0.0,"id":8258569}]}]}
{"op":"mcm","clk":"1003178642","pt":1580603975267,"mc":[{"id":"1.168238840","rc":[{"batb":[[2,1.81,35.52]],"ltp":0.0,"tv":0.0,"id":8860646},{"batb":[[2,1.72,39.97]],"ltp":0.0,"tv":0.0,"id":8258569}]}]}
{"op":"mcm","clk":"1003256034","pt":1580605261467,"mc":[{"id":"1.168238840","rc":[{"batb":[[0,1.92,37.86],[1,1.81,35.52],[2,1.06,50.68]],"ltp":0.0,"tv":0.0,"id":8860646}]}]}
{"op":"mcm","clk":"1003291111","pt":1580605761635,"mc":[{"id":"1.168238840","rc":[{"batb":[[0,1.93,30.93],[1,1.92,37.86],[2,1.81,35.52]],"ltp":0.0,"tv":0.0,"id":8860646}]}]}
{"op":"mcm","clk":"1003306878","pt":1580605991279,"mc":[{"id":"1.168238840","rc":[{"batb":[[0,1.82,38.62],[1,1.72,39.97],[2,1.02,152.15]],"ltp":0.0,"tv":0.0,"id":8258569}]}]}
{"op":"mcm","clk":"1003306920","pt":1580605991792,"mc":[{"id":"1.168238840","rc":[{"batb":[[0,1.83,34.56],[1,1.82,38.62],[2,1.72,39.97]],"ltp":0.0,"tv":0.0,"id":8258569}]}]}
{"op":"mcm","clk":"1003313755","pt":1580606089228,"mc":[{"id":"1.168238840","rc":[{"batb":[[1,1.92,60.58]],"ltp":0.0,"tv":0.0,"id":8860646}]}]}
{"op":"mcm","clk":"1003313795","pt":1580606089744,"mc":[{"id":"1.168238840","rc":[{"batb":[[1,1.82,64.36]],"ltp":0.0,"tv":0.0,"id":8258569}]}]}
{"op":"mcm","clk":"1003341384","pt":1580606452108,"mc":[{"id":"1.168238840","rc":[{"batb":[[0,1.92,60.58],[1,1.81,35.52],[2,1.06,50.68]],"ltp":0.0,"tv":0.0,"id":8860646},{"batb":[[0,1.82,64.36],[1,1.72,39.97],[2,1.03,9.1]],"ltp":0.0,"tv":0.0,"id":8258569}]}]}
{"op":"mcm","clk":"1003341401","pt":1580606452313,"mc":[{"id":"1.168238840","rc":[{"batb":[[0,1.93,40.93],[1,1.92,60.58],[2,1.81,35.52]],"ltp":0.0,"tv":0.0,"id":8860646},{"batb":[[0,1.83,46.03],[1,1.82,64.36],[2,1.72,39.97]],"ltp":0.0,"tv":0.0,"id":8258569}]}]}
{"op":"mcm","clk":"1003341495","pt":1580606453717,"mc":[{"id":"1.168238840","rc":[{"batb":[[2,1.06,50.68]],"ltp":0.0,"tv":0.0,"id":8860646},{"batb":[[2,1.03,9.1]],"ltp":0.0,"tv":0.0,"id":8258569}]}]}
{"op":"mcm","clk":"1003341541","pt":1580606454329,"mc":[{"id":"1.168238840","rc":[{"batb":[[2,1.81,46.74]],"ltp":0.0,"tv":0.0,"id":8860646},{"batb":[[2,1.72,52.58]],"ltp":0.0,"tv":0.0,"id":8258569}]}]}
{"op":"mcm","clk":"1003549010","pt":1580609362756,"mc":[{"id":"1.168238840","rc":[{"batb":[[0,1.93,41.22]],"ltp":0.0,"tv":0.0,"id":8860646}]}]}
{"op":"mcm","clk":"1003566022","pt":1580609592056,"mc":[{"id":"1.168238840","rc":[{"batb":[[0,1.83,46.09]],"ltp":0.0,"tv":0.0,"id":8258569}]}]}
{"op":"mcm","clk":"1003607748","pt":1580610168241,"mc":[{"id":"1.168238840","rc":[{"batb":[[0,1.93,51.22]],"ltp":0.0,"tv":0.0,"id":8860646},{"batb":[[0,1.83,57.56]],"ltp":0.0,"tv":0.0,"id":8258569}]}]}
{"op":"mcm","clk":"1003607876","pt":1580610170046,"mc":[{"id":"1.168238840","rc":[{"batb":[[2,1.06,50.68]],"ltp":0.0,"tv":0.0,"id":8860646},{"batb":[[2,1.03,9.1]],"ltp":0.0,"tv":0.0,"id":8258569}]}]}
{"op":"mcm","clk":"1003607915","pt":1580610170716,"mc":[{"id":"1.168238840","rc":[{"batb":[[2,1.81,58.9]],"ltp":0.0,"tv":0.0,"id":8860646},{"batb":[[2,1.72,66.26]],"ltp":0.0,"tv":0.0,"id":8258569}]}]}
{"op":"mcm","clk":"1003786903","pt":1580612963998,"mc":[{"id":"1.168238840","rc":[{"batb":[[0,1.92,60.58],[1,1.81,58.9],[2,1.06,50.68]],"ltp":0.0,"tv":0.0,"id":8860646},{"batl":[[0,2.08,47.69],[1,2.28,18.48],[2,990,2.2]],"ltp":0.0,"tv":0.0,"id":8258569}]}]}
{"op":"mcm","clk":"1003795525","pt":1580613193250,"mc":[{"id":"1.168238840","rc":[{"batl":[[0,2.22,47.66],[1,2.28,18.48],[2,990,2.2]],"ltp":0.0,"tv":0.0,"id":8860646},{"batb":[[0,1.82,64.36],[1,1.72,66.26],[2,1.03,9.1]],"ltp":0.0,"tv":0.0,"id":8258569}]}]}
{"op":"mcm","clk":"1003795539","pt":1580613193613,"mc":[{"id":"1.168238840","rc":[{"batl":[[0,2.28,18.48],[1,990,2.2],[2,1000,0.02]],"ltp":0.0,"tv":0.0,"id":8860646},{"batb":[[0,1.83,57.68],[1,1.82,64.36],[2,1.72,66.26]],"ltp":0.0,"tv":0.0,"id":8258569}]}]}
{"op":"mcm","clk":"1003935084","pt":1580616564014,"mc":[{"id":"1.168238840","rc":[{"batl":[[0,2.28,18.48],[1,990,2.2],[2,1000,0.02]],"ltp":0.0,"tv":0.0,"id":8258569}]}]}
{"op":"mcm","clk":"1003946269","pt":1580616794064,"mc":[{"id":"1.168238840","rc":[{"batb":[[0,1.93,51.36],[1,1.92,60.58],[2,1.81,58.9]],"ltp":0.0,"tv":0.0,"id":8860646},{"batb":[[0,1.82,64.36],[1,1.72,66.26],[2,1.03,9.1]],"ltp":0.0,"tv":0.0,"id":8258569}]}]}
{"op":"mcm","clk":"1003985428","pt":1580617605084,"mc":[{"id":"1.168238840","rc":[{"batl":[[1,95,15.9],[2,990,2.2]],"ltp":0.0,"tv":0.0,"id":8860646},{"batl":[[1,95,15.9],[2,990,2.2]],"ltp":0.0,"tv":0.0,"id":8258569}]}]}
{"op":"mcm","clk":"1003985440","pt":1580617605389,"mc":[{"id":"1.168238840","rc":[{"batb":[[0,1.83,57.68],[1,1.82,64.36],[2,1.72,66.26]],"ltp":0.0,"tv":0.0,"id":8258569}]}]}
{"op":"mcm","clk":"1004102022","pt":1580620394112,"mc":[{"id":"1.168238840","rc":[{"batb":[[0,1.92,60.58],[1,1.81,58.9],[2,1.51,6.06]],"ltp":0.0,"tv":0.0,"id":8860646}]}]}
{"op":"mcm","clk":"1004102028","pt":1580620394316,"mc":[{"id":"1.168238840","rc":[{"batb":[[0,1.93,51.36],[1,1.92,60.58],[2,1.81,58.9]],"ltp":0.0,"tv":0.0,"id":8860646}]}]}
{"op":"mcm","clk":"1004141470","pt":1580621205462,"mc":[{"id":"1.168238840","rc":[{"batb":[[0,1.82,64.36],[1,1.72,66.26],[2,1.41,7.57]],"ltp":0.0,"tv":0.0,"id":8258569}]}]}
{"op":"mcm","clk":"1004218125","pt":1580623500088,"mc":[{"id":"1.168238840","rc":[{"batb":[[0,1.83,57.68],[1,1.82,64.36],[2,1.72,66.26]],"ltp":0.0,"tv":0.0,"id":8258569}]}]}
{"op":"mcm","clk":"1004232484","pt":1580623994342,"mc":[{"id":"1.168238840","rc":[{"batb":[[0,1.92,60.58],[1,1.81,58.9],[2,1.51,6.06]],"ltp":0.0,"tv":0.0,"id":8860646}]}]}
{"op":"mcm","clk":"1004236381","pt":1580624121437,"mc":[{"id":"1.168238840","rc":[{"batb":[[0,1.93,51.36],[1,1.92,60.58],[2,1.81,58.9]],"ltp":0.0,"tv":0.0,"id":8860646}]}]}
{"op":"mcm","clk":"1004240469","pt":1580624257780,"mc":[{"id":"1.168238840","rc":[{"batb":[[0,1.83,122.04],[1,1.72,66.26],[2,1.41,7.57]],"ltp":0.0,"tv":0.0,"id":8258569}]}]}
{"op":"mcm","clk":"1004260273","pt":1580624870165,"mc":[{"id":"1.168238840","rc":[{"batb":[[0,1.83,64.36]],"ltp":0.0,"tv":0.0,"id":8258569}]}]}
{"op":"mcm","clk":"1004260281","pt":1580624870371,"mc":[{"id":"1.168238840","rc":[{"batb":[[0,1.83,121.92]],"ltp":0.0,"tv":0.0,"id":8258569}]}]}
{"op":"mcm","clk":"1004260497","pt":1580624879201,"mc":[{"id":"1.168238840","rc":[{"batb":[[0,1.92,60.58],[1,1.81,58.9],[2,1.51,6.06]],"ltp":0.0,"tv":0.0,"id":8860646},{"batb":[[0,1.83,64.36]],"ltp":0.0,"tv":0.0,"id":8258569}]}]}
{"op":"mcm","clk":"1004260516","pt":1580624879767,"mc":[{"id":"1.168238840","rc":[{"batb":[[0,1.93,51.36],[1,1.92,60.58],[2,1.81,58.9]],"ltp":0.0,"tv":0.0,"id":8860646},{"batb":[[0,1.83,121.92]],"ltp":0.0,"tv":0.0,"id":8258569}]}]}
{"op":"mcm","clk":"1004266840","pt":1580625108491,"mc":[{"id":"1.168238840","rc":[{"batb":[[0,1.93,92.36]],"ltp":0.0,"tv":0.0,"id":8860646},{"batb":[[0,1.83,167.39]],"ltp":0.0,"tv":0.0,"id":8258569}]}]}
{"op":"mcm","clk":"1004266936","pt":1580625111163,"mc":[{"id":"1.168238840","rc":[{"batb":[[2,1.84,101.86]],"ltp":0.0,"tv":0.0,"id":8860646},{"batb":[[1,1.75,114.09]],"ltp":0.0,"tv":0.0,"id":8258569}]}]}
{"op":"mcm","clk":"1004343326","pt":1580627528416,"mc":[{"id":"1.168238840","rc":[{"batb":[[0,1.94,6.8],[1,1.93,92.36],[2,1.92,60.58]],"ltp":0.0,"tv":0.0,"id":8860646}]}]}
{"op":"mcm","clk":"1004343361","pt":1580627529339,"mc":[{"id":"1.168238840","rc":[{"batb":[[0,1.84,7.23],[1,1.83,167.39],[2,1.75,114.09]],"ltp":0.0,"tv":0.0,"id":8258569}]}]}
{"op":"mcm","clk":"1004360076","pt":1580627956007,"mc":[{"id":"1.168238840","rc":[{"batb":[[0,1.96,40.73],[1,1.94,6.8]],"ltp":0.0,"tv":0.0,"id":8860646},{"batb":[[0,1.86,42.66],[1,1.84,7.23],[2,1.83,64.36]],"ltp":0.0,"tv":0.0,"id":8258569}]}]}
{"op":"mcm","clk":"1004450441","pt":1580630133074,"mc":[{"id":"1.168238840","rc":[{"batb":[[1,1.92,60.58],[2,1.85,6.8]],"ltp":0.0,"tv":0.0,"id":8860646}]}]}
{"op":"mcm","clk":"1004450473","pt":1580630133743,"mc":[{"id":"1.168238840","rc":[{"batb":[[1,1.83,64.36],[2,1.76,7.23]],"ltp":0.0,"tv":0.0,"id":8258569}]}]}
{"op":"mcm","clk":"1004466980","pt":1580630468064,"mc":[{"id":"1.168238840","rc":[{"batb":[[1,1.85,6.8],[2,1.84,101.86]],"ltp":0.0,"tv":0.0,"id":8860646},{"batb":[[1,1.76,7.23],[2,1.75,114.09]],"ltp":0.0,"tv":0.0,"id":8258569}]}]}
{"op":"mcm","clk":"1004473593","pt":1580630615553,"mc":[{"id":"1.168238840","rc":[{"batb":[[1,1.92,60.58],[2,1.85,6.8]],"ltp":0.0,"tv":0.0,"id":8860646},{"batb":[[1,1.83,64.36],[2,1.76,7.23]],"ltp":0.0,"tv":0.0,"id":8258569}]}]}
{"op":"mcm","clk":"1004478114","pt":1580630711691,"mc":[{"id":"1.168238840","rc":[{"batb":[[2,1.87,135.78]],"ltp":0.0,"tv":0.0,"id":8860646},{"batb":[[2,1.78,151.45]],"ltp":0.0,"tv":0.0,"id":8258569}]}]}
{"op":"mcm","clk":"1004530656","pt":1580631914257,"mc":[{"id":"1.168238840","rc":[{"batb":[[2,1.88,134.23]],"ltp":0.0,"tv":0.0,"id":8860646},{"batb":[[2,1.77,153.42]],"ltp":0.0,"tv":0.0,"id":8258569}]}]}
{"op":"mcm","clk":"1004571453","pt":1580632858076,"mc":[{"id":"1.168238840","rc":[{"batb":[[0,1.97,40.88]],"ltp":0.0,"tv":0.0,"id":8860646},{"trd":[[1.86,10.13]],"batb":[[0,1.85,43.11]],"ltp":1.86,"tv":10.13,"id":8258569}],"tv":10.13}]}
{"op":"mcm","clk":"1004589098","pt":1580633207992,"mc":[{"id":"1.168238840","rc":[{"trd":[[1.97,81.75]],"batb":[[0,1.92,60.58],[1,1.88,134.23],[2,1.71,37.86]],"batl":[[0,1.97,55.75],[1,2.28,18.48],[2,95,15.9]],"ltp":1.97,"tv":81.75,"id":8860646}],"tv":91.88}]}
{"op":"mcm","clk":"1004589141","pt":1580633209167,"mc":[{"id":"1.168238840","rc":[{"trd":[[1.97,115.43]],"batb":[[0,1.93,18.74],[1,1.92,60.58],[2,1.89,38.37]],"batl":[[0,1.97,38.91]],"ltp":1.97,"tv":115.42,"id":8860646},{"batb":[[0,1.94,39.05]],"ltp":1.86,"tv":10.13,"id":8258569}],"tv":125.55}]}
{"op":"mcm","clk":"1004589214","pt":1580633211157,"mc":[{"id":"1.168238840","rc":[{"trd":[[1.97,193.11]],"batl":[[0,2.28,18.55],[1,95,15.9],[2,990,2.2]],"ltp":1.97,"tv":193.11,"id":8860646}],"tv":203.24}]}
{"op":"mcm","clk":"1004589316","pt":1580633213765,"mc":[{"id":"1.168238840","rc":[{"batb":[[2,1.71,37.86]],"ltp":1.86,"tv":10.13,"id":8258569}]}]}
{"op":"mcm","clk":"1004589359","pt":1580633214991,"mc":[{"id":"1.168238840","rc":[{"batb":[[2,1.78,151.45]],"ltp":1.86,"tv":10.13,"id":8258569}]}]}
{"op":"mcm","clk":"1004626818","pt":1580634006215,"mc":[{"id":"1.168238840","rc":[{"batb":[[2,1.81,37.86]],"ltp":1.86,"tv":10.13,"id":8258569}]}]}
{"op":"mcm","clk":"1004630548","pt":1580634065019,"mc":[{"id":"1.168238840","rc":[{"batb":[[1,1.9,6.33],[2,1.83,64.36]],"ltp":1.86,"tv":10.13,"id":8258569}]}]}
{"op":"mcm","clk":"1004630648","pt":1580634066623,"mc":[{"id":"1.168238840","rc":[{"batb":[[1,1.91,60.58]],"ltp":1.97,"tv":193.11,"id":8860646}]}]}
{"op":"mcm","clk":"1004631382","pt":1580634078130,"mc":[{"id":"1.168238840","rc":[{"batb":[[0,1.92,152.96]],"ltp":1.97,"tv":193.11,"id":8860646}]}]}
{"op":"mcm","clk":"1004762329","pt":1580636901046,"mc":[{"id":"1.168238840","rc":[{"batl":[[1,2.7,74.21],[2,95,15.9]],"ltp":1.97,"tv":193.11,"id":8860646}]}]}
{"op":"mcm","clk":"1004806551","pt":1580637678230,"mc":[{"id":"1.168238840","rc":[{"batb":[[0,1.92,23.52]],"ltp":1.97,"tv":193.11,"id":8860646}]}]}
{"op":"mcm","clk":"1004867290","pt":1580638521720,"mc":[{"id":"1.168238840","rc":[{"batb":[[0,1.92,152.96]],"ltp":1.97,"tv":193.11,"id":8860646}]}]}
{"op":"mcm","clk":"1004972822","pt":1580639643441,"mc":[{"id":"1.168238840","rc":[{"batb":[[1,1.9,60.58]],"ltp":1.97,"tv":193.11,"id":8860646}]}]}
{"op":"mcm","clk":"1005083097","pt":1580640615775,"mc":[{"id":"1.168238840","rc":[{"batb":[[2,1.81,37.86]],"ltp":1.86,"tv":10.13,"id":8258569}]}]}
{"op":"mcm","clk":"1005100427","pt":1580640759276,"mc":[{"id":"1.168238840","rc":[{"batb":[[0,1.93,8.26],[1,1.92,152.96],[2,1.9,60.58]],"ltp":1.97,"tv":193.11,"id":8860646},{"batb":[[0,1.92,40.46]],"ltp":1.86,"tv":10.13,"id":8258569}]}]}
{"op":"mcm","clk":"1005100460","pt":1580640759585,"mc":[{"id":"1.168238840","rc":[{"batb":[[0,1.94,126.26],[1,1.93,8.26],[2,1.92,23.52]],"ltp":1.97,"tv":193.11,"id":8860646}]}]}
{"op":"mcm","clk":"1005115566","pt":1580640887258,"mc":[{"id":"1.168238840","rc":[{"batb":[[0,1.95,17.64],[1,1.9,60.58],[2,1.89,38.37]],"ltp":1.97,"tv":193.11,"id":8860646}]}]}
{"op":"mcm","clk":"1005115579","pt":1580640887313,"mc":[{"id":"1.168238840","rc":[{"batb":[[0,1.95,143.15]],"ltp":1.97,"tv":193.11,"id":8860646}]}]}
{"op":"mcm","clk":"1005166930","pt":1580641260230,"mc":[{"id":"1.168238840","rc":[{"batb":[[1,1.89,38.37],[2,1.88,134.23]],"ltp":1.97,"tv":193.11,"id":8860646}]}]}
{"op":"mcm","clk":"1005166987","pt":1580641260652,"mc":[{"id":"1.168238840","rc":[{"batb":[[1,1.94,60.58],[2,1.89,38.37]],"ltp":1.97,"tv":193.11,"id":8860646},{"batb":[[2,1.81,102.23]],"ltp":1.86,"tv":10.13,"id":8258569}]}]}
{"op":"mcm","clk":"1005171889","pt":1580641288682,"mc":[{"id":"1.168238840","rc":[{"batb":[[0,1.95,208.55]],"ltp":1.97,"tv":193.11,"id":8860646}]}]}
{"op":"mcm","clk":"1005436151","pt":1580642677218,"mc":[{"id":"1.168238840","rc":[{"trd":[[2.04,15.14]],"ltp":2.04,"tv":25.27,"id":8258569}],"tv":218.38}]}
{"op":"mcm","clk":"1005436166","pt":1580642677326,"mc":[{"id":"1.168238840","rc":[{"batb":[[0,2.02,7.65],[1,1.92,40.46],[2,1.9,6.33]],"ltp":2.04,"tv":25.27,"id":8258569}]}]}
{"op":"mcm","clk":"1005437469","pt":1580642683942,"mc":[{"id":"1.168238840","rc":[{"batb":[[0,1.92,40.46],[1,1.9,6.33],[2,1.81,102.23]],"ltp":2.04,"tv":25.27,"id":8258569}]}]}
{"op":"mcm","clk":"1005437655","pt":1580642685111,"mc":[{"id":"1.168238840","rc":[{"trd":[[2.04,30.28]],"ltp":2.04,"tv":40.41,"id":8258569}],"tv":233.52}]}
{"op":"mcm","clk":"1005437699","pt":1580642685422,"mc":[{"id":"1.168238840","rc":[{"batb":[[0,2.02,7.65],[1,1.92,40.46],[2,1.9,6.33]],"ltp":2.04,"tv":40.41,"id":8258569}]}]}
{"op":"mcm","clk":"1005438004","pt":1580642687229,"mc":[{"id":"1.168238840","rc":[{"batl":[[0,2.04,7.57],[1,2.28,18.48],[2,95,15.9]],"ltp":2.04,"tv":40.41,"id":8258569}]}]}
{"op":"mcm","clk":"1005438064","pt":1580642687544,"mc":[{"id":"1.168238840","rc":[{"batb":[[0,1.95,17.64]],"ltp":1.97,"tv":193.11,"id":8860646}]}]}
{"op":"mcm","clk":"1005438826","pt":1580642691764,"mc":[{"id":"1.168238840","rc":[{"batb":[[0,1.93,7.65]],"ltp":2.04,"tv":40.41,"id":8258569}]}]}
{"op":"mcm","clk":"1005439245","pt":1580642693935,"mc":[{"id":"1.168238840","rc":[{"batb":[[0,1.95,208.55]],"ltp":1.97,"tv":193.11,"id":8860646},{"batb":[[0,1.92,40.46],[1,1.9,6.33],[2,1.81,102.23]],"batl":[[0,2.28,18.48],[1,95,15.9],[2,990,2.2]],"ltp":2.04,"tv":40.41,"id":8258569}]}]}
{"op":"mcm","clk":"1005439419","pt":1580642694944,"mc":[{"id":"1.168238840","rc":[{"batb":[[0,1.95,17.64]],"ltp":1.97,"tv":193.11,"id":8860646},{"trd":[[2.04,38.95]],"batb":[[0,1.93,16.01],[1,1.92,40.46],[2,1.9,6.33]],"batl":[[0,2.04,3.24],[1,2.28,18.48],[2,95,15.9]],"ltp":2.04,"tv":49.07,"id":8258569}],"tv":242.18}]}
{"op":"mcm","clk":"1005439522","pt":1580642695531,"mc":[{"id":"1.168238840","rc":[{"batb":[[0,2.02,4.38],[1,1.93,16.01],[2,1.92,40.46]],"ltp":2.04,"tv":49.07,"id":8258569}]}]}
{"op":"mcm","clk":"1005439854","pt":1580642697443,"mc":[{"id":"1.168238840","rc":[{"batl":[[0,2.04,10.81]],"ltp":2.04,"tv":49.07,"id":8258569}]}]}
{"op":"mcm","clk":"1005448926","pt":1580642746924,"mc":[{"id":"1.168238840","rc":[{"batb":[[0,1.98,4.38]],"ltp":2.04,"tv":49.07,"id":8258569}]}]}
{"op":"mcm","clk":"1005452294","pt":1580642764433,"mc":[{"id":"1.168238840","rc":[{"batb":[[1,1.94,30.91],[2,1.93,16.01]],"ltp":2.04,"tv":49.07,"id":8258569}]}]}
{"op":"mcm","clk":"1005463667","pt":1580642822219,"mc":[{"id":"1.168238840","rc":[{"batb":[[0,1.95,208.55]],"ltp":1.97,"tv":193.11,"id":8860646},{"batl":[[0,2.04,7.57]],"ltp":2.04,"tv":49.07,"id":8258569}]}]}
{"op":"mcm","clk":"1005463763","pt":1580642822602,"mc":[{"id":"1.168238840","rc":[{"batb":[[0,1.95,17.64]],"ltp":1.97,"tv":193.11,"id":8860646}]}]}
{"op":"mcm","clk":"1005469857","pt":1580642855135,"mc":[{"id":"1.168238840","rc":[{"trd":[[1.97,193.18]],"batl":[[0,2.28,18.48]],"ltp":1.97,"tv":193.17,"id":8860646},{"trd":[[2.02,0.07]],"batb":[[1,1.95,16.01],[2,1.94,30.91]],"batl":[[0,2.02,4.39],[1,2.04,7.57],[2,2.28,18.48]],"ltp":2.02,"tv":49.14,"id":8258569}],"tv":242.32}]}
{"op":"mcm","clk":"1005477019","pt":1580642895102,"mc":[{"id":"1.168238840","rc":[{"batb":[[1,1.96,21.7],[2,1.95,16.01]],"ltp":2.02,"tv":49.14,"id":8258569}]}]}
{"op":"mcm","clk":"1005488123","pt":1580642958494,"mc":[{"id":"1.168238840","rc":[{"batb":[[1,1.89,38.37],[2,1.86,209.56]],"ltp":1.97,"tv":193.17,"id":8860646}]}]}
{"op":"mcm","clk":"1005489158","pt":1580642964290,"mc":[{"id":"1.168238840","rc":[{"trd":[[2.02,8.82]],"batb":[[0,1.96,21.7],[1,1.95,16.01],[2,1.9,6.33]],"batl":[[0,2.04,7.58],[1,2.28,18.48],[2,95,15.9]],"ltp":2.02,"tv":57.89,"id":8258569}],"tv":251.07}]}
{"op":"mcm","clk":"1005489785","pt":1580642967671,"mc":[{"id":"1.168238840","rc":[{"batb":[[1,1.9,6.33],[2,1.81,102.23]],"batl":[[0,2.28,18.49],[1,95,15.9],[2,990,2.2]],"ltp":2.02,"tv":57.89,"id":8258569}]}]}
{"op":"mcm","clk":"1005490037","pt":1580642968961,"mc":[{"id":"1.168238840","rc":[{"batb":[[0,1.97,15.68],[1,1.96,21.7],[2,1.9,6.33]],"batl":[[0,2.04,7.58],[1,2.28,18.48],[2,95,15.9]],"ltp":2.02,"tv":57.89,"id":8258569}]}]}
{"op":"mcm","clk":"1005493685","pt":1580642989285,"mc":[{"id":"1.168238840","rc":[{"batb":[[0,1.96,21.7],[1,1.9,6.33],[2,1.81,102.23]],"batl":[[0,2.28,18.49],[1,95,15.9],[2,990,2.2]],"ltp":2.02,"tv":57.89,"id":8258569}]}]}
{"op":"mcm","clk":"1005493916","pt":1580642990453,"mc":[{"id":"1.168238840","rc":[{"batb":[[0,1.97,15.68],[1,1.96,21.7],[2,1.9,6.33]],"batl":[[0,2.04,7.58],[1,2.28,18.48],[2,95,15.9]],"ltp":2.02,"tv":57.89,"id":8258569}]}]}
{"op":"mcm","clk":"1005494587","pt":1580642993974,"mc":[{"id":"1.168238840","rc":[{"batb":[[2,1.84,214.55]],"ltp":1.97,"tv":193.17,"id":8860646}]}]}
{"op":"mcm","clk":"1005500609","pt":1580643025146,"mc":[{"id":"1.168238840","rc":[{"batb":[[0,1.89,38.37],[1,1.84,214.55],[2,1.71,37.86]],"ltp":1.97,"tv":193.17,"id":8860646},{"batb":[[1,1.9,6.33],[2,1.81,102.23]],"ltp":2.02,"tv":57.89,"id":8258569}]}]}
{"op":"mcm","clk":"1005500643","pt":1580643025317,"mc":[{"id":"1.168238840","rc":[{"batb":[[0,1.9,41.64],[1,1.89,38.37],[2,1.84,214.55]],"ltp":1.97,"tv":193.17,"id":8860646},{"batb":[[1,1.92,40.46],[2,1.9,6.33]],"ltp":2.02,"tv":57.89,"id":8258569}]}]}
{"op":"mcm","clk":"1005509400","pt":1580643073009,"mc":[{"id":"1.168238840","rc":[{"batl":[[0,2.02,10.56],[1,2.28,18.48],[2,2.7,74.21]],"ltp":1.97,"tv":193.17,"id":8860646}]}]}
{"op":"mcm","clk":"1005527608","pt":1580643170763,"mc":[{"id":"1.168238840","rc":[{"batl":[[0,2.04,7.57]],"ltp":2.02,"tv":57.89,"id":8258569}]}]}
{"op":"mcm","clk":"1005540189","pt":1580643233136,"mc":[{"id":"1.168238840","rc":[{"batl":[[0,2.1,7.57]],"ltp":2.02,"tv":57.89,"id":8258569}]}]}
{"op":"mcm","clk":"1005540635","pt":1580643235541,"mc":[{"id":"1.168238840","rc":[{"batb":[[0,2.02,7.57],[1,1.97,15.68],[2,1.92,40.46]],"ltp":2.02,"tv":57.89,"id":8258569}]}]}
{"op":"mcm","clk":"1005541279","pt":1580643238563,"mc":[{"id":"1.168238840","rc":[{"batb":[[1,1.92,40.46],[2,1.9,6.33]],"ltp":2.02,"tv":57.89,"id":8258569}]}]}
{"op":"mcm","clk":"1005541899","pt":1580643241869,"mc":[{"id":"1.168238840","rc":[{"batb":[[0,1.99,7.57]],"ltp":2.02,"tv":57.89,"id":8258569}]}]}
{"op":"mcm","clk":"1005542534","pt":1580643245042,"mc":[{"id":"1.168238840","rc":[{"batl":[[0,2.06,7.57],[1,2.1,7.57],[2,2.28,18.48]],"ltp":2.02,"tv":57.89,"id":8258569}]}]}
{"op":"mcm","clk":"1005543026","pt":1580643247564,"mc":[{"id":"1.168238840","rc":[{"batl":[[1,2.28,18.48],[2,95,15.9]],"ltp":2.02,"tv":57.89,"id":8258569}]}]}
{"op":"mcm","clk":"1005545371","pt":1580643259487,"mc":[{"id":"1.168238840","rc":[{"batl":[[0,2.04,7.57]],"ltp":2.02,"tv":57.89,"id":8258569}]}]}
{"op":"mcm","clk":"1005606129","pt":1580643555800,"mc":[{"id":"1.168238840","rc":[{"trd":[[1.99,10.39]],"batb":[[0,1.99,2.38]],"ltp":1.99,"tv":68.28,"id":8258569}],"tv":261.46}]}
{"op":"mcm","clk":"1005611490","pt":1580643582233,"mc":[{"id":"1.168238840","rc":[{"batb":[[0,1.92,40.46],[1,1.9,6.33],[2,1.81,102.23]],"batl":[[0,2.28,18.48],[1,95,15.9],[2,990,2.2]],"ltp":1.99,"tv":68.28,"id":8258569}]}]}
{"op":"mcm","clk":"1005611695","pt":1580643583116,"mc":[{"id":"1.168238840","rc":[{"batb":[[0,1.91,199.95],[1,1.9,41.64],[2,1.89,38.37]],"ltp":1.97,"tv":193.17,"id":8860646}]}]}
{"op":"mcm","clk":"1005611806","pt":1580643583747,"mc":[{"id":"1.168238840","rc":[{"batb":[[0,1.99,10.33],[1,1.92,40.46],[2,1.9,6.33]],"batl":[[0,2.04,7.57],[1,2.28,18.48],[2,95,15.9]],"ltp":1.99,"tv":68.28,"id":8258569}]}]}
{"op":"mcm","clk":"1005631752","pt":1580643684147,"mc":[{"id":"1.168238840","rc":[{"batb":[[0,1.92,31.78],[1,1.89,38.37],[2,1.84,214.55]],"ltp":1.97,"tv":193.17,"id":8860646}]}]}
{"op":"mcm","clk":"1005657986","pt":1580643816856,"mc":[{"id":"1.168238840","rc":[{"batb":[[0,1.9,41.64]],"ltp":1.97,"tv":193.17,"id":8860646}]}]}
{"op":"mcm","clk":"1005795563","pt":1580644769209,"mc":[{"id":"1.168238840","rc":[{"batb":[[2,1.71,37.86]],"ltp":1.97,"tv":193.17,"id":8860646}]}]}
{"op":"mcm","clk":"1005795657","pt":1580644769931,"mc":[{"id":"1.168238840","rc":[{"batb":[[2,1.86,209.56]],"ltp":1.97,"tv":193.17,"id":8860646}]}]}
{"op":"mcm","clk":"1005833189","pt":1580645010047,"mc":[{"id":"1.168238840","rc":[{"batb":[[0,1.91,60.58],[1,1.9,41.64],[2,1.89,38.37]],"ltp":1.97,"tv":193.17,"id":8860646}]}]}
{"op":"mcm","clk":"1005893149","pt":1580645316854,"mc":[{"id":"1.168238840","rc":[{"batb":[[0,1.9,41.64],[1,1.89,38.37],[2,1.83,217.14]],"ltp":1.97,"tv":193.17,"id":8860646}]}]}
{"op":"mcm","clk":"1005893985","pt":1580645320902,"mc":[{"id":"1.168238840","rc":[{"batb":[[1,1.89,100.46]],"ltp":1.97,"tv":193.17,"id":8860646}]}]}
{"op":"mcm","clk":"1005904112","pt":1580645372166,"mc":[{"id":"1.168238840","rc":[{"trd":[[2.02,10.56]],"batl":[[0,2.28,18.48],[1,2.7,74.21],[2,95,15.9]],"ltp":2.02,"tv":203.73,"id":8860646},{"trd":[[1.98,10.77],[1.99,31.04]],"batb":[[0,1.92,40.46],[1,1.9,6.33],[2,1.86,64.36]],"batl":[[0,2.02,185.25],[1,2.04,7.57],[2,2.28,18.48]],"ltp":1.98,"tv":99.71,"id":8258569}],"tv":303.44}]}
{"op":"mcm","clk":"1005904528","pt":1580645374077,"mc":[{"id":"1.168238840","rc":[{"batb":[[0,2,38.78],[1,1.91,198.05],[2,1.89,100.46]],"ltp":2.02,"tv":203.73,"id":8860646},{"batb":[[0,1.9,6.33],[1,1.87,20.49]],"ltp":1.98,"tv":99.71,"id":8258569}]}]}
{"op":"mcm","clk":"1005904890","pt":1580645375897,"mc":[{"id":"1.168238840","rc":[{"batl":[[0,2.04,7.57],[1,2.28,18.48],[2,95,15.9]],"ltp":1.98,"tv":99.71,"id":8258569}]}]}
{"op":"mcm","clk":"1005905145","pt":1580645376962,"mc":[{"id":"1.168238840","rc":[{"batb":[[1,1.98,62.09],[2,1.91,198.05]],"ltp":2.02,"tv":203.73,"id":8860646},{"batb":[[2,1.81,37.86]],"ltp":1.98,"tv":99.71,"id":8258569}]}]}
{"op":"mcm","clk":"1005906453","pt":1580645383899,"mc":[{"id":"1.168238840","rc":[{"batl":[[0,2.28,18.48],[1,95,15.9],[2,990,2.2]],"ltp":1.98,"tv":99.71,"id":8258569}]}]}
{"op":"mcm","clk":"1005906875","pt":1580645386165,"mc":[{"id":"1.168238840","rc":[{"batb":[[1,1.97,62.09]],"ltp":2.02,"tv":203.73,"id":8860646}]}]}
{"op":"mcm","clk":"1005912202","pt":1580645415218,"mc":[{"id":"1.168238840","rc":[{"batb":[[1,1.83,42.21]],"ltp":1.98,"tv":99.71,"id":8258569}]}]}
{"op":"mcm","clk":"1006031843","pt":1580646091868,"mc":[{"id":"1.168238840","rc":[{"batl":[[0,1.99,7.57],[1,2.28,18.48],[2,95,15.9]],"ltp":1.98,"tv":99.71,"id":8258569}]}]}
{"op":"mcm","clk":"1006032686","pt":1580646096488,"mc":[{"id":"1.168238840","rc":[{"batl":[[0,1.99,15.14]],"ltp":1.98,"tv":99.71,"id":8258569}]}]}
{"op":"mcm","clk":"1006060129","pt":1580646252597,"mc":[{"id":"1.168238840","rc":[{"batl":[[0,2.1,6.06],[1,2.28,18.48],[2,2.7,74.21]],"ltp":2.02,"tv":203.73,"id":8860646}]}]}
{"op":"mcm","clk":"1006072601","pt":1580646323595,"mc":[{"id":"1.168238840","rc":[{"batl":[[0,1.97,7.04],[1,1.99,15.14],[2,2.28,18.48]],"ltp":1.98,"tv":99.71,"id":8258569}]}]}
{"op":"mcm","clk":"1006080500","pt":1580646371261,"mc":[{"id":"1.168238840","rc":[{"batb":[[0,2.04,22.16]],"ltp":2.02,"tv":203.73,"id":8860646}]}]}
{"op":"mcm","clk":"1006123751","pt":1580646621182,"mc":[{"id":"1.168238840","rc":[{"batb":[[2,1.89,38.37]],"ltp":2.02,"tv":203.73,"id":8860646}]}]}
{"op":"mcm","clk":"1006123862","pt":1580646621760,"mc":[{"id":"1.168238840","rc":[{"batb":[[2,1.92,195.9]],"ltp":2.02,"tv":203.73,"id":8860646}]}]}
{"op":"mcm","clk":"1006125242","pt":1580646629594,"mc":[{"id":"1.168238840","rc":[{"batb":[[1,1.98,62.09]],"ltp":2.02,"tv":203.73,"id":8860646}]}]}
{"op":"mcm","clk":"1006162755","pt":1580646841663,"mc":[{"id":"1.168238840","rc":[{"batl":[[1,2.28,18.48],[2,95,15.9]],"ltp":1.98,"tv":99.71,"id":8258569}]}]}
{"op":"mcm","clk":"1006319948","pt":1580647655862,"mc":[{"id":"1.168238840","rc":[{"batl":[[2,4.2,153.72]],"ltp":1.98,"tv":99.71,"id":8258569}]}]}
{"op":"mcm","clk":"1006340456","pt":1580647789310,"mc":[{"id":"1.168238840","rc":[{"batl":[[2,4,3.03]],"ltp":1.98,"tv":99.71,"id":8258569}]}]}
{"op":"mcm","clk":"1006342312","pt":1580647800949,"mc":[{"id":"1.168238840","rc":[{"batl":[[2,4,3.45]],"ltp":1.98,"tv":99.71,"id":8258569}]}]}
{"op":"mcm","clk":"1006350476","pt":1580647854843,"mc":[{"id":"1.168238840","rc":[{"batl":[[0,1.97,7.46],[2,4.2,153.72]],"ltp":1.98,"tv":99.71,"id":8258569}]}]}
{"op":"mcm","clk":"1006351726","pt":1580647863259,"mc":[{"id":"1.168238840","rc":[{"batl":[[0,1.97,7.04]],"ltp":1.98,"tv":99.71,"id":8258569}]}]}
{"op":"mcm","clk":"1006351788","pt":1580647863648,"mc":[{"id":"1.168238840","rc":[{"trd":[[1.92,0.84]],"ltp":1.92,"tv":100.54,"id":8258569}],"tv":304.28}]}
{"op":"mcm","clk":"1006353883","pt":1580647876696,"mc":[{"id":"1.168238840","rc":[{"batl":[[2,3,3.03]],"ltp":1.92,"tv":100.54,"id":8258569}]}]}
{"op":"mcm","clk":"1006355389","pt":1580647887009,"mc":[{"id":"1.168238840","rc":[{"batl":[[2,3,3.33]],"ltp":1.92,"tv":100.54,"id":8258569}]}]}
{"op":"mcm","clk":"1006356761","pt":1580647896610,"mc":[{"id":"1.168238840","rc":[{"batl":[[1,2.28,18.79],[2,4.2,153.72]],"ltp":1.92,"tv":100.54,"id":8258569}]}]}
{"op":"mcm","clk":"1006444232","pt":1580648538364,"mc":[{"id":"1.168238840","rc":[{"batb":[[1,1.88,4.45],[2,1.83,42.21]],"ltp":1.92,"tv":100.54,"id":8258569}]}]}
{"op":"mcm","clk":"1006461759","pt":1580648671046,"mc":[{"id":"1.168238840","rc":[{"batl":[[0,2.08,50],[1,2.1,6.06],[2,2.28,18.48]],"ltp":2.02,"tv":203.73,"id":8860646}]}]}
{"op":"mcm","clk":"1006481139","pt":1580648809025,"mc":[{"id":"1.168238840","rc":[{"trd":[[2.08,13.26]],"batb":[[0,1.99,36.36]],"batl":[[0,2.08,43.37]],"ltp":2.08,"tv":216.99,"id":8860646},{"batb":[[2,1.84,43.96]],"ltp":1.92,"tv":100.54,"id":8258569}],"tv":317.54}]}
{"op":"mcm","clk":"1006482163","pt":1580648815904,"mc":[{"id":"1.168238840","rc":[{"batl":[[0,2.04,5],[1,2.08,43.37],[2,2.1,6.06]],"ltp":2.08,"tv":216.99,"id":8860646}]}]}
{"op":"mcm","clk":"1006484172","pt":1580648827926,"mc":[{"id":"1.168238840","rc":[{"trd":[[2.02,15.56]],"batl":[[0,2.08,43.37],[1,2.1,6.06],[2,2.28,18.48]],"ltp":2.02,"tv":221.99,"id":8860646},{"trd":[[1.97,5.13]],"batl":[[0,1.97,1.92]],"ltp":1.97,"tv":105.67,"id":8258569}],"tv":327.66}]}
{"op":"mcm","clk":"1006502580","pt":1580648956930,"mc":[{"id":"1.168238840","rc":[{"batl":[[0,2.06,10],[1,2.08,43.37],[2,2.1,6.06]],"ltp":2.02,"tv":221.99,"id":8860646}]}]}
{"op":"mcm","clk":"1006514257","pt":1580649037546,"mc":[{"id":"1.168238840","rc":[{"trd":[[2.06,1.58]],"batl":[[0,2.06,8.42]],"ltp":2.06,"tv":223.57,"id":8860646},{"trd":[[1.94,1.68]],"ltp":1.94,"tv":107.35,"id":8258569}],"tv":330.92}]}
{"op":"mcm","clk":"1006521246","pt":1580649084210,"mc":[{"id":"1.168238840","rc":[{"trd":[[2.06,16.82]],"batl":[[0,2.08,44.17],[1,2.1,6.06],[2,2.28,18.48]],"ltp":2.06,"tv":238.81,"id":8860646}],"tv":346.16}]}
{"op":"mcm","clk":"1006521333","pt":1580649084792,"mc":[{"id":"1.168238840","rc":[{"batb":[[0,1.99,28.62]],"ltp":2.06,"tv":238.81,"id":8860646},{"batb":[[2,1.86,41.34]],"ltp":1.94,"tv":107.35,"id":8258569}]}]}
{"op":"mcm","clk":"1006532090","pt":1580649152862,"mc":[{"id":"1.168238840","rc":[{"batl":[[0,1.96,2],[1,1.97,1.92],[2,2.28,18.79]],"ltp":1.94,"tv":107.35,"id":8258569}]}]}
{"op":"mcm","clk":"1006883752","pt":1580651581972,"mc":[{"id":"1.168238840","rc":[{"trd":[[2.04,1.92]],"batl":[[0,2.04,4.38],[1,2.08,44.17],[2,2.1,6.06]],"ltp":2.04,"tv":240.73,"id":8860646},{"trd":[[1.96,2]],"batl":[[0,1.97,1.92],[1,2.28,18.79],[2,4.2,153.72]],"ltp":1.96,"tv":109.35,"id":8258569}],"tv":350.09}]}
{"op":"mcm","clk":"1006884886","pt":1580651591019,"mc":[{"id":"1.168238840","rc":[{"trd":[[2.04,10.68]],"batb":[[0,1.99,24.21]],"batl":[[0,2.08,44.17],[1,2.1,6.06],[2,2.28,18.48]],"ltp":2.04,"tv":249.49,"id":8860646},{"batb":[[0,1.93,10.8],[1,1.9,6.33],[2,1.88,4.45]],"ltp":1.96,"tv":109.35,"id":8258569}],"tv":358.84}]}
{"op":"mcm","clk":"1006980533","pt":1580652261868,"mc":[{"id":"1.168238840","rc":[{"batb":[[2,1.89,38.37]],"ltp":2.04,"tv":249.49,"id":8860646}]}]}
{"op":"mcm","clk":"1006980631","pt":1580652262472,"mc":[{"id":"1.168238840","rc":[{"batb":[[2,1.93,254.85]],"ltp":2.04,"tv":249.49,"id":8860646}]}]}
{"op":"mcm","clk":"1007042895","pt":1580652611104,"mc":[{"id":"1.168238840","rc":[{"batl":[[0,1.97,9.49]],"ltp":1.96,"tv":109.35,"id":8258569}]}]}
{"op":"mcm","clk":"1007162004","pt":1580653301649,"mc":[{"id":"1.168238840","rc":[{"batl":[[2,4.2,154.56]],"ltp":1.96,"tv":109.35,"id":8258569}]}]}
{"op":"mcm","clk":"1007207784","pt":1580653596363,"mc":[{"id":"1.168238840","rc":[{"batl":[[0,1.97,17.06]],"ltp":1.96,"tv":109.35,"id":8258569}]}]}
{"op":"mcm","clk":"1007208001","pt":1580653597929,"mc":[{"id":"1.168238840","rc":[{"batl":[[0,1.97,1.92]],"ltp":1.96,"tv":109.35,"id":8258569}]}]}
{"op":"mcm","clk":"1007263460","pt":1580653938878,"mc":[{"id":"1.168238840","rc":[{"trd":[[2.06,18.42],[2.08,40.4]],"batl":[[0,2.08,29.8]],"ltp":2.08,"tv":278.22,"id":8860646}],"tv":387.58}]}
{"op":"mcm","clk":"1007263557","pt":1580653939593,"mc":[{"id":"1.168238840","rc":[{"batb":[[0,1.99,36.42]],"ltp":2.08,"tv":278.22,"id":8860646},{"batb":[[0,1.9,6.33],[1,1.88,4.45],[2,1.84,43.89]],"ltp":1.96,"tv":109.35,"id":8258569}]}]}
{"op":"mcm","clk":"1007272252","pt":1580653996551,"mc":[{"id":"1.168238840","rc":[{"trd":[[2,0.13],[2.02,17.43]],"ltp":2.0,"tv":280.22,"id":8860646},{"trd":[[1.97,7.04],[1.99,31.17]],"batl":[[0,2.28,18.66],[1,4.2,154.56],[2,95,15.9]],"ltp":1.99,"tv":111.39,"id":8258569}],"tv":391.62}]}
{"op":"mcm","clk":"1007272808","pt":1580654000040,"mc":[{"id":"1.168238840","rc":[{"batb":[[0,1.99,284.95]],"ltp":2.0,"tv":280.22,"id":8860646},{"batl":[[0,1.99,7.75],[1,2.28,18.48],[2,4.2,154.56]],"ltp":1.99,"tv":111.39,"id":8258569}]}]}
{"op":"mcm","clk":"1007272992","pt":1580654001131,"mc":[{"id":"1.168238840","rc":[{"batb":[[0,1.99,36.42]],"ltp":2.0,"tv":280.22,"id":8860646},{"batl":[[0,1.98,7.57],[1,1.99,7.75],[2,2.28,18.48]],"ltp":1.99,"tv":111.39,"id":8258569}]}]}
{"op":"mcm","clk":"1007273405","pt":1580654003562,"mc":[{"id":"1.168238840","rc":[{"batl":[[1,1.99,15.32]],"ltp":1.99,"tv":111.39,"id":8258569}]}]}
{"op":"mcm","clk":"1007274820","pt":1580654012081,"mc":[{"id":"1.168238840","rc":[{"batl":[[0,1.99,15.32],[1,2.28,18.48],[2,4.2,154.56]],"ltp":1.99,"tv":111.39,"id":8258569}]}]}
{"op":"mcm","clk":"1007275164","pt":1580654013988,"mc":[{"id":"1.168238840","rc":[{"batb":[[0,2.02,23.69]],"ltp":2.0,"tv":280.22,"id":8860646}]}]}
{"op":"mcm","clk":"1007280386","pt":1580654043834,"mc":[{"id":"1.168238840","rc":[{"batl":[[0,1.99,22.89]],"ltp":1.99,"tv":111.39,"id":8258569}]}]}
{"op":"mcm","clk":"1007280639","pt":1580654045199,"mc":[{"id":"1.168238840","rc":[{"batl":[[0,1.98,7.57],[1,1.99,22.89],[2,2.28,18.48]],"ltp":1.99,"tv":111.39,"id":8258569}]}]}
{"op":"mcm","clk":"1007280981","pt":1580654047184,"mc":[{"id":"1.168238840","rc":[{"batl":[[0,1.99,22.89],[1,2.28,18.48],[2,4.2,154.56]],"ltp":1.99,"tv":111.39,"id":8258569}]}]}
{"op":"mcm","clk":"1007295363","pt":1580654130626,"mc":[{"id":"1.168238840","rc":[{"batl":[[0,1.98,22.72],[1,1.99,22.89],[2,2.28,18.48]],"ltp":1.99,"tv":111.39,"id":8258569}]}]}
{"op":"mcm","clk":"1007298222","pt":1580654146600,"mc":[{"id":"1.168238840","rc":[{"trd":[[2.02,37.59]],"batb":[[0,2.02,13.6]],"ltp":2.02,"tv":300.39,"id":8860646}],"tv":411.79}]}
{"op":"mcm","clk":"1007298358","pt":1580654147425,"mc":[{"id":"1.168238840","rc":[{"batb":[[0,1.91,18.12],[1,1.9,6.33],[2,1.88,4.45]],"ltp":1.99,"tv":111.39,"id":8258569}]}]}
{"op":"mcm","clk":"1007299180","pt":1580654152233,"mc":[{"id":"1.168238840","rc":[{"batl":[[1,2.28,18.66],[2,4.2,154.56]],"ltp":1.99,"tv":111.39,"id":8258569}]}]}
{"op":"mcm","clk":"1007310886","pt":1580654219281,"mc":[{"id":"1.168238840","rc":[{"batl":[[2,2.2,22.72]],"ltp":2.02,"tv":300.39,"id":8860646}]}]}
{"op":"mcm","clk":"1007325114","pt":1580654300226,"mc":[{"id":"1.168238840","rc":[{"batb":[[0,1.99,26.37]],"ltp":2.02,"tv":300.39,"id":8860646}]}]}
{"op":"mcm","clk":"1007410834","pt":1580654856248,"mc":[{"id":"1.168238840","rc":[{"batb":[[2,1.94,252.14]],"ltp":2.02,"tv":300.39,"id":8860646}]}]}
{"op":"mcm","clk":"1007410940","pt":1580654856962,"mc":[{"id":"1.168238840","rc":[{"batl":[[0,1.97,7.57],[1,1.98,22.72],[2,2.28,18.66]],"ltp":1.99,"tv":111.39,"id":8258569}]}]}
{"op":"mcm","clk":"1007411992","pt":1580654865422,"mc":[{"id":"1.168238840","rc":[{"batl":[[0,1.98,22.72],[1,2.28,18.66],[2,4.2,154.56]],"ltp":1.99,"tv":111.39,"id":8258569}]}]}
{"op":"mcm","clk":"1007421371","pt":1580654938068,"mc":[{"id":"1.168238840","rc":[{"batb":[[0,1.99,88.47],[1,1.94,252.14],[2,1.89,38.37]],"ltp":2.02,"tv":300.39,"id":8860646}]}]}
{"op":"mcm","clk":"1007824568","pt":1580657067219,"mc":[{"id":"1.168238840","rc":[{"batb":[[0,2.04,17.2],[1,1.99,62.09],[2,1.94,252.14]],"ltp":2.02,"tv":300.39,"id":8860646},{"batb":[[0,1.9,6.33],[1,1.88,4.45],[2,1.84,42.09]],"ltp":1.99,"tv":111.39,"id":8258569}]}]}
{"op":"mcm","clk":"1007830628","pt":1580657093779,"mc":[{"id":"1.168238840","rc":[{"trd":[[2.08,80.94]],"batl":[[0,2.08,9.53]],"ltp":2.08,"tv":340.93,"id":8860646}],"tv":452.33}]}
{"op":"mcm","clk":"1008022886","pt":1580657950245,"mc":[{"id":"1.168238840","rc":[{"trd":[[2.04,19.48]],"batb":[[0,2.04,12.8]],"ltp":2.04,"tv":349.74,"id":8860646},{"batb":[[1,1.84,42.09],[2,1.81,37.86]],"ltp":1.99,"tv":111.39,"id":8258569}],"tv":461.13}]}
{"op":"mcm","clk":"1008023036","pt":1580657950839,"mc":[{"id":"1.168238840","rc":[{"batb":[[1,1.85,41.35]],"ltp":1.99,"tv":111.39,"id":8258569}]}]}
{"op":"mcm","clk":"1008050865","pt":1580658067057,"mc":[{"id":"1.168238840","rc":[{"trd":[[2.08,82.69]],"batl":[[0,2.08,7.78]],"ltp":2.08,"tv":351.49,"id":8860646},{"trd":[[1.92,2.74]],"ltp":1.92,"tv":113.29,"id":8258569}],"tv":464.78}]}
{"op":"mcm","clk":"1008159231","pt":1580658565062,"mc":[{"id":"1.168238840","rc":[{"trd":[[2.08,98.25]],"batb":[[0,2.08,29.37],[1,2.04,12.8],[2,1.99,62.09]],"batl":[[0,2.1,6.06],[1,2.2,22.72],[2,2.28,18.48]],"ltp":2.08,"tv":367.05,"id":8860646}],"tv":480.34}]}
{"op":"mcm","clk":"1008166939","pt":1580658608535,"mc":[{"id":"1.168238840","rc":[{"trd":[[2.1,12.12]],"batb":[[0,2.1,23.31]],"batl":[[0,2.2,22.72],[1,2.28,18.48],[2,2.7,74.21]],"ltp":2.1,"tv":379.16,"id":8860646}],"tv":492.46}]}
{"op":"mcm","clk":"1008167893","pt":1580658614147,"mc":[{"id":"1.168238840","rc":[{"batb":[[0,2.04,12.8],[1,1.99,62.09],[2,1.94,252.14]],"ltp":2.1,"tv":379.16,"id":8860646}]}]}
{"op":"mcm","clk":"1008167932","pt":1580658614339,"mc":[{"id":"1.168238840","rc":[{"batb":[[0,2.06,23.31],[1,2.04,12.8],[2,1.99,62.09]],"ltp":2.1,"tv":379.16,"id":8860646}]}]}
{"op":"mcm","clk":"1008170804","pt":1580658631153,"mc":[{"id":"1.168238840","rc":[{"batb":[[0,2.04,12.8],[1,1.99,62.09],[2,1.94,252.14]],"ltp":2.1,"tv":379.16,"id":8860646}]}]}
{"op":"mcm","clk":"1008177304","pt":1580658668097,"mc":[{"id":"1.168238840","rc":[{"batb":[[0,2.06,26.19],[1,2.04,12.8],[2,1.99,62.09]],"ltp":2.1,"tv":379.16,"id":8860646}]}]}
{"op":"mcm","clk":"1008178322","pt":1580658674228,"mc":[{"id":"1.168238840","rc":[{"batb":[[0,2.04,12.8],[1,1.99,62.09],[2,1.94,252.14]],"ltp":2.1,"tv":379.16,"id":8860646}]}]}
{"op":"mcm","clk":"1008178366","pt":1580658674400,"mc":[{"id":"1.168238840","rc":[{"batb":[[0,2.06,26.19],[1,2.04,12.8],[2,1.99,62.09]],"ltp":2.1,"tv":379.16,"id":8860646}]}]}
{"op":"mcm","clk":"1008201419","pt":1580658819210,"mc":[{"id":"1.168238840","rc":[{"trd":[[1.9,12.67]],"batb":[[0,1.85,41.35],[1,1.81,37.86],[2,1.79,64.36]],"batl":[[0,1.9,8.79],[1,1.98,22.72],[2,2.28,18.66]],"ltp":1.9,"tv":125.96,"id":8258569}],"tv":505.13}]}
{"op":"mcm","clk":"1008201611","pt":1580658820271,"mc":[{"id":"1.168238840","rc":[{"batb":[[1,1.79,64.36],[2,1.75,316.02]],"ltp":1.9,"tv":125.96,"id":8258569}]}]}
{"op":"mcm","clk":"1008218676","pt":1580658926249,"mc":[{"id":"1.168238840","rc":[{"trd":[[1.9,30.25]],"batl":[[0,1.98,22.72],[1,2.28,18.66],[2,4.2,154.56]],"ltp":1.9,"tv":143.54,"id":8258569}],"tv":522.71}]}
{"op":"mcm","clk":"1008219074","pt":1580658928656,"mc":[{"id":"1.168238840","rc":[{"batb":[[1,2.04,20.94]],"ltp":2.1,"tv":379.16,"id":8860646},{"batb":[[0,1.84,37.97]],"ltp":1.9,"tv":143.54,"id":8258569}]}]}
{"op":"mcm","clk":"1008267699","pt":1580659230499,"mc":[{"id":"1.168238840","rc":[{"batb":[[2,2,62.09]],"ltp":2.1,"tv":379.16,"id":8860646},{"batb":[[1,1.78,64.36]],"ltp":1.9,"tv":143.54,"id":8258569}]}]}
{"op":"mcm","clk":"1008303299","pt":1580659422764,"mc":[{"id":"1.168238840","rc":[{"batl":[[0,2.18,9.09],[1,2.2,22.72],[2,2.28,18.48]],"ltp":2.1,"tv":379.16,"id":8860646}]}]}
{"op":"mcm","clk":"1008310419","pt":1580659461250,"mc":[{"id":"1.168238840","rc":[{"batl":[[0,1.96,15.14],[1,1.98,22.72],[2,2.28,18.66]],"ltp":1.9,"tv":143.54,"id":8258569}]}]}
{"op":"mcm","clk":"1008469406","pt":1580660180225,"mc":[{"id":"1.168238840","rc":[{"batb":[[2,1.75,316.35]],"ltp":1.9,"tv":143.54,"id":8258569}]}]}
{"op":"mcm","clk":"1008495988","pt":1580660292143,"mc":[{"id":"1.168238840","rc":[{"trd":[[2.18,9.09]],"batb":[[0,2.08,38.52],[1,2.06,26.19]],"batl":[[0,2.2,22.72],[1,2.28,18.48],[2,2.7,74.21]],"ltp":2.18,"tv":388.25,"id":8860646},{"trd":[[1.84,114.11]],"batb":[[0,1.79,28.99]],"batl":[[0,1.84,37.56],[1,1.96,15.14],[2,1.98,22.72]],"ltp":1.84,"tv":257.65,"id":8258569}],"tv":645.9}]}
{"op":"mcm","clk":"1008496087","pt":1580660292641,"mc":[{"id":"1.168238840","rc":[{"trd":[[2.18,12.94]],"batb":[[2,2,99.95]],"ltp":2.18,"tv":392.11,"id":8860646},{"trd":[[1.84,164.32]],"batl":[[0,1.84,10.17]],"ltp":1.84,"tv":307.86,"id":8258569}],"tv":699.97}]}
{"op":"mcm","clk":"1008497110","pt":1580660296681,"mc":[{"id":"1.168238840","rc":[{"trd":[[1.84,177.2]],"batl":[[0,1.84,3.73]],"ltp":1.84,"tv":320.74,"id":8258569}],"tv":712.85}]}
{"op":"mcm","clk":"1008499735","pt":1580660308167,"mc":[{"id":"1.168238840","rc":[{"trd":[[2.18,14.94]],"ltp":2.18,"tv":394.11,"id":8860646},{"trd":[[1.84,179.57]],"batl":[[0,1.84,1.36]],"ltp":1.84,"tv":323.11,"id":8258569}],"tv":717.22}]}
{"op":"mcm","clk":"1008499791","pt":1580660308506,"mc":[{"id":"1.168238840","rc":[{"trd":[[2.18,16.09]],"batl":[[0,2.2,23.57]],"ltp":2.18,"tv":395.26,"id":8860646},{"trd":[[1.84,180.93]],"batl":[[0,1.96,15.14],[1,1.98,22.72],[2,2.28,18.66]],"ltp":1.84,"tv":324.47,"id":8258569}],"tv":719.73}]}
{"op":"mcm","clk":"1008500117","pt":1580660309890,"mc":[{"id":"1.168238840","rc":[{"batl":[[0,2.18,2.85],[1,2.2,22.72],[2,2.28,18.48]],"ltp":2.18,"tv":395.26,"id":8860646}]}]}
{"op":"mcm","clk":"1008500389","pt":1580660311033,"mc":[{"id":"1.168238840","rc":[{"batl":[[0,2.2,22.72],[1,2.28,18.48],[2,2.7,74.21]],"ltp":2.18,"tv":395.26,"id":8860646}]}]}
{"op":"mcm","clk":"1008559168","pt":1580660565544,"mc":[{"id":"1.168238840","rc":[{"batl":[[0,1.92,15.14],[1,1.96,15.14],[2,1.98,22.72]],"ltp":1.84,"tv":324.47,"id":8258569}]}]}
{"op":"mcm","clk":"1008588996","pt":1580660700382,"mc":[{"id":"1.168238840","rc":[{"batb":[[0,1.84,160.48],[1,1.79,28.99],[2,1.78,64.36]],"batl":[[0,1.91,154.6],[1,1.92,15.14],[2,1.96,15.14]],"ltp":1.84,"tv":324.47,"id":8258569}]}]}
{"op":"mcm","clk":"1008642767","pt":1580660951244,"mc":[{"id":"1.168238840","rc":[{"batb":[[1,2,99.95],[2,1.94,252.4]],"ltp":2.18,"tv":395.26,"id":8860646}]}]}
{"op":"mcm","clk":"1008644227","pt":1580660958076,"mc":[{"id":"1.168238840","rc":[{"batb":[[0,2.1,25.69],[1,2.08,38.52],[2,2,99.95]],"ltp":2.18,"tv":395.26,"id":8860646}]}]}
{"op":"mcm","clk":"1008645098","pt":1580660962155,"mc":[{"id":"1.168238840","rc":[{"batb":[[0,2.08,38.52],[1,2,99.95],[2,1.94,252.4]],"ltp":2.18,"tv":395.26,"id":8860646}]}]}
{"op":"mcm","clk":"1008645152","pt":1580660962363,"mc":[{"id":"1.168238840","rc":[{"batb":[[0,2.1,25.69],[1,2.08,38.52],[2,2,99.95]],"ltp":2.18,"tv":395.26,"id":8860646}]}]}
{"op":"mcm","clk":"1008667836","pt":1580661070068,"mc":[{"id":"1.168238840","rc":[{"batb":[[0,2.12,23.68],[1,2.1,25.69]],"ltp":2.18,"tv":395.26,"id":8860646}]}]}
{"op":"mcm","clk":"1008695951","pt":1580661197142,"mc":[{"id":"1.168238840","rc":[{"trd":[[2.12,12]],"batb":[[0,2.12,17.68]],"ltp":2.12,"tv":407.25,"id":8860646},{"batb":[[1,1.79,35.99]],"ltp":1.84,"tv":324.47,"id":8258569}],"tv":731.73}]}
{"op":"mcm","clk":"1008779824","pt":1580661582256,"mc":[{"id":"1.168238840","rc":[{"batl":[[0,2.28,18.48],[1,2.7,74.21],[2,4.2,153.72]],"ltp":2.12,"tv":407.25,"id":8860646}]}]}
{"op":"mcm","clk":"1008786918","pt":1580661614832,"mc":[{"id":"1.168238840","rc":[{"batl":[[2,1.98,22.72]],"ltp":1.84,"tv":324.47,"id":8258569}]}]}
{"op":"mcm","clk":"1009002518","pt":1580662960693,"mc":[{"id":"1.168238840","rc":[{"batl":[[2,95,15.9]],"ltp":2.12,"tv":407.25,"id":8860646}]}]}
{"op":"mcm","clk":"1009048437","pt":1580663222780,"mc":[{"id":"1.168238840","rc":[{"trd":[[2.12,47.36]],"batb":[[0,2.1,25.69],[1,2,99.95],[2,1.94,252.4]],"batl":[[0,2.12,637.9],[1,2.28,18.48],[2,2.7,74.21]],"ltp":2.12,"tv":442.61,"id":8860646}],"tv":767.08}]}
{"op":"mcm","clk":"1009048634","pt":1580663223750,"mc":[{"id":"1.168238840","rc":[{"batb":[[1,2.04,30.42],[2,2,62.09]],"ltp":2.12,"tv":442.61,"id":8860646},{"batb":[[0,1.85,22],[1,1.84,170.7]],"ltp":1.84,"tv":324.47,"id":8258569}]}]}
{"op":"mcm","clk":"1009080342","pt":1580663408591,"mc":[{"id":"1.168238840","rc":[{"batb":[[1,1.84,160.48]],"ltp":1.84,"tv":324.47,"id":8258569}]}]}
{"op":"mcm","clk":"1009087492","pt":1580663452815,"mc":[{"id":"1.168238840","rc":[{"trd":[[2.12,90.08]],"batl":[[0,2.12,595.17]],"ltp":2.12,"tv":485.34,"id":8860646},{"trd":[[1.89,47.9]],"ltp":1.89,"tv":372.37,"id":8258569}],"tv":857.71}]}
{"op":"mcm","clk":"1009087712","pt":1580663454259,"mc":[{"id":"1.168238840","rc":[{"batb":[[1,2.08,5.38],[2,2.04,30.42]],"ltp":2.12,"tv":485.34,"id":8860646}]}]}
{"op":"mcm","clk":"1009092693","pt":1580663488255,"mc":[{"id":"1.168238840","rc":[{"batb":[[2,1.74,320.62]],"ltp":1.89,"tv":372.37,"id":8258569}]}]}
{"op":"mcm","clk":"1009092709","pt":1580663488360,"mc":[{"id":"1.168238840","rc":[{"batb":[[2,1.77,64.36]],"ltp":1.89,"tv":372.37,"id":8258569}]}]}
{"op":"mcm","clk":"1009174105","pt":1580663976843,"mc":[{"id":"1.168238840","rc":[{"batb":[[1,2.04,30.42],[2,2,62.09]],"ltp":2.12,"tv":485.34,"id":8860646}]}]}
{"op":"mcm","clk":"1009174440","pt":1580663978912,"mc":[{"id":"1.168238840","rc":[{"batb":[[1,2.08,5.38],[2,2.04,30.42]],"ltp":2.12,"tv":485.34,"id":8860646}]}]}
{"op":"mcm","clk":"1009250373","pt":1580664484861,"mc":[{"id":"1.168238840","rc":[{"batb":[[1,2.04,30.42],[2,2,62.09]],"ltp":2.12,"tv":485.34,"id":8860646}]}]}
{"op":"mcm","clk":"1009250996","pt":1580664488972,"mc":[{"id":"1.168238840","rc":[{"batb":[[1,2.08,5.38],[2,2.04,30.42]],"ltp":2.12,"tv":485.34,"id":8860646}]}]}
{"op":"mcm","clk":"1009264556","pt":1580664578919,"mc":[{"id":"1.168238840","rc":[{"trd":[[2.1,62.53]],"batb":[[0,2.08,5.86],[1,2.04,30.42],[2,2,62.09]],"ltp":2.1,"tv":535.75,"id":8860646}],"tv":908.12}]}
{"op":"mcm","clk":"1009264664","pt":1580664579714,"mc":[{"id":"1.168238840","rc":[{"trd":[[1.9,117.82]],"batl":[[0,1.9,2.33],[1,1.91,154.6],[2,1.92,15.14]],"ltp":1.9,"tv":459.94,"id":8258569}],"tv":995.69}]}
{"op":"mcm","clk":"1009265976","pt":1580664588434,"mc":[{"id":"1.168238840","rc":[{"batl":[[2,2.3,16.8]],"ltp":2.1,"tv":535.75,"id":8860646}]}]}
{"op":"mcm","clk":"1009277745","pt":1580664664161,"mc":[{"id":"1.168238840","rc":[{"trd":[[2.12,205.98]],"batl":[[0,2.12,479.27]],"ltp":2.12,"tv":651.65,"id":8860646},{"trd":[[1.89,177.9]],"ltp":1.89,"tv":589.94,"id":8258569}],"tv":1241.59}]}
{"op":"mcm","clk":"1009282321","pt":1580664693525,"mc":[{"id":"1.168238840","rc":[{"trd":[[1.89,184.64]],"ltp":1.89,"tv":596.68,"id":8258569}],"tv":1248.33}]}
{"op":"mcm","clk":"1009286746","pt":1580664723827,"mc":[{"id":"1.168238840","rc":[{"batl":[[1,1.91,157.93]],"ltp":1.89,"tv":596.68,"id":8258569}]}]}
{"op":"mcm","clk":"1009291204","pt":1580664753164,"mc":[{"id":"1.168238840","rc":[{"trd":[[2.1,70.96]],"batb":[[0,2.08,5.38]],"batl":[[0,2.1,471.32],[1,2.12,5.28],[2,2.28,18.48]],"ltp":2.1,"tv":660.09,"id":8860646},{"trd":[[1.9,126.08]],"batb":[[0,1.89,5.93],[1,1.85,22],[2,1.84,160.48]],"batl":[[0,1.91,157.93],[1,1.92,15.14],[2,1.98,22.72]],"ltp":1.9,"tv":604.94,"id":8258569}],"tv":1265.03}]}
{"op":"mcm","clk":"1009293498","pt":1580664768100,"mc":[{"id":"1.168238840","rc":[{"batl":[[1,2.28,18.48],[2,2.3,16.8]],"ltp":2.1,"tv":660.09,"id":8860646},{"batb":[[0,1.85,22],[1,1.84,160.48],[2,1.77,64.36]],"ltp":1.9,"tv":604.94,"id":8258569}]}]}
{"op":"mcm","clk":"1009296851","pt":1580664789242,"mc":[{"id":"1.168238840","rc":[{"trd":[[2.1,85.7]],"batb":[[1,2.04,22.96]],"batl":[[0,2.1,463.95]],"ltp":2.1,"tv":674.82,"id":8860646},{"batb":[[0,1.85,30.26]],"ltp":1.9,"tv":604.94,"id":8258569}],"tv":1279.77}]}
{"op":"mcm","clk":"1009352386","pt":1580665125224,"mc":[{"id":"1.168238840","rc":[{"batl":[[0,2.1,488.95]],"ltp":2.1,"tv":674.82,"id":8860646}]}]}
{"op":"mcm","clk":"1009369128","pt":1580665223358,"mc":[{"id":"1.168238840","rc":[{"trd":[[2.08,118.9]],"batb":[[0,2.04,22.96],[1,2,62.09],[2,1.95,249.75]],"ltp":2.08,"tv":695.47,"id":8860646},{"trd":[[1.91,10.75]],"batl":[[0,1.91,147.17]],"ltp":1.91,"tv":615.69,"id":8258569}],"tv":1311.17}]}
{"op":"mcm","clk":"1009371124","pt":1580665235370,"mc":[{"id":"1.168238840","rc":[{"batl":[[0,2.1,494.28]],"ltp":2.08,"tv":695.47,"id":8860646}]}]}
{"op":"mcm","clk":"1009376628","pt":1580665269089,"mc":[{"id":"1.168238840","rc":[{"batb":[[0,2.04,24.96],[1,2.02,2.02],[2,2,62.09]],"batl":[[1,2.14,2.18],[2,2.16,2.1]],"ltp":2.08,"tv":695.47,"id":8860646},{"batb":[[0,1.88,2.21],[1,1.87,2.04],[2,1.85,30.26]],"batl":[[2,1.93,2.07]],"ltp":1.91,"tv":615.69,"id":8258569}]}]}
{"op":"mcm","clk":"1009384765","pt":1580665318193,"mc":[{"id":"1.168238840","rc":[{"trd":[[2.08,125.85]],"batb":[[0,2.08,1.91],[1,2.04,24.96],[2,2.02,2.06]],"batl":[[2,2.16,2.22]],"ltp":2.08,"tv":702.43,"id":8860646}],"tv":1318.12}]}
{"op":"mcm","clk":"1009385588","pt":1580665323194,"mc":[{"id":"1.168238840","rc":[{"trd":[[2.08,129.76]],"batb":[[0,2.04,25.08],[1,2.02,2.06],[2,2,64.09]],"batl":[[0,2.1,497.72]],"ltp":2.08,"tv":706.34,"id":8860646},{"trd":[[1.91,10.86]],"batl":[[0,1.91,147.07]],"ltp":1.91,"tv":615.79,"id":8258569}],"tv":1322.14}]}
{"op":"mcm","clk":"1009389500","pt":1580665349941,"mc":[{"id":"1.168238840","rc":[{"batb":[[1,2,62.09],[2,1.95,249.75]],"batl":[[0,2.1,499.61],[2,2.28,18.48]],"ltp":2.08,"tv":706.34,"id":8860646},{"batb":[[1,1.85,30.26],[2,1.84,160.48]],"ltp":1.91,"tv":615.79,"id":8258569}]}]}
{"op":"mcm","clk":"1009389558","pt":1580665350331,"mc":[{"id":"1.168238840","rc":[{"batb":[[1,2.02,2.2],[2,2,62.09]],"batl":[[2,2.16,2.1]],"ltp":2.08,"tv":706.34,"id":8860646},{"batb":[[1,1.87,2.04],[2,1.85,30.26]],"ltp":1.91,"tv":615.79,"id":8258569}]}]}
{"op":"mcm","clk":"1009399341","pt":1580665416213,"mc":[{"id":"1.168238840","rc":[{"batb":[[0,2.08,5.38],[1,2.04,25.08],[2,2.02,2.2]],"ltp":2.08,"tv":706.34,"id":8860646}]}]}
{"op":"mcm","clk":"1009399415","pt":1580665416721,"mc":[{"id":"1.168238840","rc":[{"trd":[[2.08,136.72]],"batb":[[0,2.08,1.91],[2,2.02,2.24]],"batl":[[2,2.16,2.22]],"ltp":2.08,"tv":713.29,"id":8860646}],"tv":1329.09}]}
{"op":"mcm","clk":"1009400140","pt":1580665421110,"mc":[{"id":"1.168238840","rc":[{"batl":[[0,2.1,503.05]],"ltp":2.08,"tv":713.29,"id":8860646}]}]}
{"op":"mcm","clk":"1009404746","pt":1580665454285,"mc":[{"id":"1.168238840","rc":[{"batb":[[2,2.02,2.11]],"batl":[[2,2.16,2]],"ltp":2.08,"tv":713.29,"id":8860646},{"trd":[[1.91,105.67]],"batl":[[0,1.91,99.65]],"ltp":1.91,"tv":710.61,"id":8258569}],"tv":1423.91}]}
{"op":"mcm","clk":"1009413186","pt":1580665519253,"mc":[{"id":"1.168238840","rc":[{"batb":[[0,2.08,5.38],[2,2,62.09]],"batl":[[2,2.28,18.48]],"ltp":2.08,"tv":713.29,"id":8860646},{"batb":[[1,1.85,30.26],[2,1.84,160.48]],"ltp":1.91,"tv":710.61,"id":8258569}]}]}
{"op":"mcm","clk":"1009413211","pt":1580665519466,"mc":[{"id":"1.168238840","rc":[{"batb":[[2,2.02,2.24]],"batl":[[2,2.16,2.1]],"ltp":2.08,"tv":713.29,"id":8860646},{"batb":[[1,1.87,2.04],[2,1.85,30.26]],"ltp":1.91,"tv":710.61,"id":8258569}]}]}
{"op":"mcm","clk":"1009415771","pt":1580665539111,"mc":[{"id":"1.168238840","rc":[{"batl":[[2,2.16,2.22]],"ltp":2.08,"tv":713.29,"id":8860646}]}]}
{"op":"mcm","clk":"1009453999","pt":1580665887182,"mc":[{"id":"1.168238840","rc":[{"trd":[[2.08,140.72]],"batb":[[0,2.08,3.38],[2,2,62.09]],"batl":[[0,2.1,503.42],[2,2.28,18.48]],"ltp":2.08,"tv":717.29,"id":8860646},{"batb":[[1,1.85,30.26],[2,1.84,160.48]],"ltp":1.91,"tv":710.61,"id":8258569}],"tv":1427.91}]}
{"op":"mcm","clk":"1009454006","pt":1580665887291,"mc":[{"id":"1.168238840","rc":[{"batb":[[2,2.02,2.24]],"batl":[[2,2.16,2.22]],"ltp":2.08,"tv":717.29,"id":8860646},{"batb":[[1,1.87,2.04],[2,1.85,30.26]],"ltp":1.91,"tv":710.61,"id":8258569}]}]}
{"op":"mcm","clk":"1009463186","pt":1580665981238,"mc":[{"id":"1.168238840","rc":[{"batb":[[0,2.08,5.38],[2,2.02,2.2]],"ltp":2.08,"tv":717.29,"id":8860646}]}]}
{"op":"mcm","clk":"1009466682","pt":1580666015246,"mc":[{"id":"1.168238840","rc":[{"trd":[[2.08,161.25]],"batb":[[0,2.04,22.96],[1,2.02,2.2],[2,2,64.09]],"batl":[[2,2.28,18.48]],"ltp":2.08,"tv":737.82,"id":8860646},{"trd":[[1.91,116.3]],"batb":[[1,1.85,30.26],[2,1.84,160.48]],"batl":[[0,1.91,89.02]],"ltp":1.91,"tv":721.24,"id":8258569}],"tv":1459.07}]}
{"op":"mcm","clk":"1009466753","pt":1580666015980,"mc":[{"id":"1.168238840","rc":[{"batb":[[0,2.04,24.99],[1,2.02,2.23]],"batl":[[2,2.16,2.04]],"ltp":2.08,"tv":737.82,"id":8860646},{"batb":[[1,1.87,2.04],[2,1.85,30.26]],"ltp":1.91,"tv":721.24,"id":8258569}]}]}
{"op":"mcm","clk":"1009476675","pt":1580666116191,"mc":[{"id":"1.168238840","rc":[{"batb":[[0,2.08,5.38],[1,2.04,24.99],[2,2.02,2.23]],"ltp":2.08,"tv":737.82,"id":8860646}]}]}
{"op":"mcm","clk":"1009476729","pt":1580666116785,"mc":[{"id":"1.168238840","rc":[{"batb":[[2,2.02,2.01]],"batl":[[2,2.16,2]],"ltp":2.08,"tv":737.82,"id":8860646}]}]}
{"op":"mcm","clk":"1009501717","pt":1580666368176,"mc":[{"id":"1.168238840","rc":[{"batb":[[1,2.04,47.96],[2,2.02,2.21]],"ltp":2.08,"tv":737.82,"id":8860646},{"batb":[[1,1.87,2],[2,1.85,60.51]],"ltp":1.91,"tv":721.24,"id":8258569}]}]}
{"op":"mcm","clk":"1009505147","pt":1580666403185,"mc":[{"id":"1.168238840","rc":[{"batb":[[0,1.9,5.56],[1,1.88,2.21],[2,1.87,2]],"ltp":1.91,"tv":721.24,"id":8258569}]}]}
{"op":"mcm","clk":"1009505197","pt":1580666403625,"mc":[{"id":"1.168238840","rc":[{"batb":[[2,2.02,2.24]],"ltp":2.08,"tv":737.82,"id":8860646},{"trd":[[1.9,137.2],[1.91,250.73]],"batb":[[0,1.88,2.21],[1,1.87,2],[2,1.85,60.51]],"batl":[[0,1.91,21.81]],"ltp":1.91,"tv":866.79,"id":8258569}],"tv":1604.62}]}
{"op":"mcm","clk":"1009505845","pt":1580666409214,"mc":[{"id":"1.168238840","rc":[{"trd":[[2.08,206.02]],"batb":[[0,2.04,45.93],[1,2.02,2.24],[2,2,89.3]],"batl":[[0,2.08,44.63],[1,2.1,503.42],[2,2.12,2.21]],"ltp":2.08,"tv":782.59,"id":8860646},{"trd":[[1.91,272.54],[1.92,17.88]],"batb":[[0,1.9,2.06],[1,1.89,2.05],[2,1.88,2.21]],"batl":[[0,1.95,2.1],[1,1.96,2.11],[2,1.98,22.72]],"ltp":1.92,"tv":903.74,"id":8258569}],"tv":1686.34}]}
{"op":"mcm","clk":"1009505897","pt":1580666409732,"mc":[{"id":"1.168238840","rc":[{"batb":[[2,2,64.09]],"ltp":2.08,"tv":782.59,"id":8860646},{"batb":[[2,1.87,28.97]],"batl":[[0,1.97,2.16],[1,1.98,24.97],[2,2.28,18.66]],"ltp":1.92,"tv":903.74,"id":8258569}]}]}
{"op":"mcm","clk":"1009506004","pt":1580666410930,"mc":[{"id":"1.168238840","rc":[{"batb":[[1,2,64.09],[2,1.99,2]],"batl":[[1,2.1,488.95]],"ltp":2.08,"tv":782.59,"id":8860646},{"batl":[[0,1.98,22.72],[1,1.99,2.54],[2,2,2]],"ltp":1.92,"tv":903.74,"id":8258569}]}]}
{"op":"mcm","clk":"1009506180","pt":1580666413118,"mc":[{"id":"1.168238840","rc":[{"batl":[[0,2.1,488.95],[1,2.12,2.21],[2,2.14,2.04]],"ltp":2.08,"tv":782.59,"id":8860646}]}]}
{"op":"mcm","clk":"1009506261","pt":1580666414108,"mc":[{"id":"1.168238840","rc":[{"batb":[[2,1.99,27.46]],"batl":[[1,2.14,2.04],[2,2.16,2.22]],"ltp":2.08,"tv":782.59,"id":8860646},{"batb":[[0,1.88,4.34],[1,1.87,4.04],[2,1.86,31.49]],"ltp":1.92,"tv":903.74,"id":8258569}]}]}
{"op":"mcm","clk":"1009507217","pt":1580666425259,"mc":[{"id":"1.168238840","rc":[{"batb":[[1,2,2]],"ltp":2.08,"tv":782.59,"id":8860646}]}]}
{"op":"mcm","clk":"1009507274","pt":1580666425828,"mc":[{"id":"1.168238840","rc":[{"batl":[[2,2.16,2.04]],"ltp":2.08,"tv":782.59,"id":8860646},{"batb":[[0,1.88,2.21],[1,1.87,2.04],[2,1.86,29.31]],"ltp":1.92,"tv":903.74,"id":8258569}]}]}
{"op":"mcm","clk":"1009507389","pt":1580666426926,"mc":[{"id":"1.168238840","rc":[{"batb":[[1,2,59.55]],"ltp":2.08,"tv":782.59,"id":8860646}]}]}
{"op":"mcm","clk":"1009508177","pt":1580666435268,"mc":[{"id":"1.168238840","rc":[{"batl":[[0,2.08,14.61],[1,2.1,488.95],[2,2.14,2.04]],"ltp":2.08,"tv":782.59,"id":8860646}]}]}
{"op":"mcm","clk":"1009508263","pt":1580666435957,"mc":[{"id":"1.168238840","rc":[{"batl":[[2,2.12,2.21]],"ltp":2.08,"tv":782.59,"id":8860646},{"batb":[[0,1.9,2.06],[1,1.89,2.05]],"ltp":1.92,"tv":903.74,"id":8258569}]}]}
{"op":"mcm","clk":"1009508569","pt":1580666439161,"mc":[{"id":"1.168238840","rc":[{"batl":[[0,1.96,8.1],[1,1.98,24.8],[2,1.99,2.54]],"ltp":1.92,"tv":903.74,"id":8258569}]}]}
{"op":"mcm","clk":"1009508617","pt":1580666439538,"mc":[{"id":"1.168238840","rc":[{"batl":[[2,1.99,2.22]],"ltp":1.92,"tv":903.74,"id":8258569}]}]}
{"op":"mcm","clk":"1009510163","pt":1580666456161,"mc":[{"id":"1.168238840","rc":[{"trd":[[2.08,235.26],[2.1,134.74]],"batl":[[0,2.1,464.43],[1,2.14,2],[2,2.16,2.04]],"ltp":2.1,"tv":860.87,"id":8860646},{"batb":[[0,1.88,2.21],[1,1.87,2]],"ltp":1.92,"tv":903.74,"id":8258569}],"tv":1764.62}]}
{"op":"mcm","clk":"1009510222","pt":1580666456636,"mc":[{"id":"1.168238840","rc":[{"batb":[[0,1.88,2.13],[1,1.87,2.04],[2,1.86,31.49]],"ltp":1.92,"tv":903.74,"id":8258569}]}]}
{"op":"mcm","clk":"1009510487","pt":1580666459266,"mc":[{"id":"1.168238840","rc":[{"trd":[[2.1,134.75]],"batl":[[0,2.1,464.42]],"ltp":2.1,"tv":860.88,"id":8860646},{"trd":[[1.9,137.2]],"batb":[[0,1.91,15.91],[1,1.89,2.05],[2,1.88,2.13]],"ltp":1.9,"tv":903.75,"id":8258569}],"tv":1764.63}]}
{"op":"mcm","clk":"1009511318","pt":1580666467187,"mc":[{"id":"1.168238840","rc":[{"batb":[[2,1.99,25.46]],"batl":[[2,2.28,18.48]],"ltp":2.1,"tv":860.88,"id":8860646},{"batb":[[2,1.86,29.31]],"batl":[[2,2.28,18.66]],"ltp":1.9,"tv":903.75,"id":8258569}]}]}
{"op":"mcm","clk":"1009511341","pt":1580666467396,"mc":[{"id":"1.168238840","rc":[{"batb":[[2,1.99,27.46]],"batl":[[2,2.16,2.16]],"ltp":2.1,"tv":860.88,"id":8860646},{"batb":[[2,1.88,2.21]],"batl":[[2,1.99,2.4]],"ltp":1.9,"tv":903.75,"id":8258569}]}]}
{"op":"mcm","clk":"1009512553","pt":1580666480118,"mc":[{"id":"1.168238840","rc":[{"batl":[[0,2.08,12.4],[1,2.1,464.42],[2,2.14,2]],"ltp":2.1,"tv":860.88,"id":8860646}]}]}
{"op":"mcm","clk":"1009512675","pt":1580666481285,"mc":[{"id":"1.168238840","rc":[{"trd":[[2.08,260.07]],"batb":[[0,2.04,33.43],[2,1.99,2]],"batl":[[0,2.1,464.42],[1,2.14,2.18],[2,2.16,2.22]],"ltp":2.08,"tv":885.69,"id":8860646},{"batb":[[0,1.91,28.46],[2,1.88,2]],"batl":[[2,1.99,2.2]],"ltp":1.9,"tv":903.75,"id":8258569}],"tv":1789.44}]}
{"op":"mcm","clk":"1009513077","pt":1580666485485,"mc":[{"id":"1.168238840","rc":[{"batb":[[1,2,2]],"ltp":2.08,"tv":885.69,"id":8860646}]}]}
{"op":"mcm","clk":"1009513447","pt":1580666489206,"mc":[{"id":"1.168238840","rc":[{"batb":[[1,2,59.55],[2,1.98,25.72]],"batl":[[2,2.28,18.48]],"ltp":2.08,"tv":885.69,"id":8860646},{"batb":[[2,1.87,28.97]],"batl":[[2,2.28,18.66]],"ltp":1.9,"tv":903.75,"id":8258569}]}]}
{"op":"mcm","clk":"1009513461","pt":1580666489312,"mc":[{"id":"1.168238840","rc":[{"batb":[[2,1.99,2]],"batl":[[2,2.16,2.22]],"ltp":2.08,"tv":885.69,"id":8860646},{"batb":[[2,1.88,2]],"batl":[[2,1.99,2.46]],"ltp":1.9,"tv":903.75,"id":8258569}]}]}
{"op":"mcm","clk":"1009515562","pt":1580666511527,"mc":[{"id":"1.168238840","rc":[{"batl":[[2,2.16,2.1]],"ltp":2.08,"tv":885.69,"id":8860646},{"batb":[[2,1.88,2.21]],"batl":[[2,1.99,2.23]],"ltp":1.9,"tv":903.75,"id":8258569}]}]}
{"op":"mcm","clk":"1009518402","pt":1580666541290,"mc":[{"id":"1.168238840","rc":[{"batb":[[2,1.98,25.72]],"batl":[[0,2.1,478.89],[2,2.28,18.48]],"ltp":2.08,"tv":885.69,"id":8860646},{"batb":[[2,1.87,28.97]],"batl":[[2,2.28,18.66]],"ltp":1.9,"tv":903.75,"id":8258569}]}]}
{"op":"mcm","clk":"1009518421","pt":1580666541462,"mc":[{"id":"1.168238840","rc":[{"batb":[[2,1.99,2]],"batl":[[2,2.16,2.22]],"ltp":2.08,"tv":885.69,"id":8860646},{"batb":[[2,1.88,2.05]],"batl":[[2,1.99,2.53]],"ltp":1.9,"tv":903.75,"id":8258569}]}]}
{"op":"mcm","clk":"1009518802","pt":1580666545764,"mc":[{"id":"1.168238840","rc":[{"batb":[[1,2,2]],"ltp":2.08,"tv":885.69,"id":8860646}]}]}
{"op":"mcm","clk":"1009521702","pt":1580666574789,"mc":[{"id":"1.168238840","rc":[{"batl":[[2,2.16,2.04]],"ltp":2.08,"tv":885.69,"id":8860646},{"batb":[[2,1.88,2.21]],"batl":[[2,1.99,2.41]],"ltp":1.9,"tv":903.75,"id":8258569}]}]}
{"op":"mcm","clk":"1009527093","pt":1580666626128,"mc":[{"id":"1.168238840","rc":[{"batb":[[1,2,59.55],[2,1.98,25.72]],"batl":[[2,2.18,9.09]],"ltp":2.08,"tv":885.69,"id":8860646},{"batb":[[2,1.87,28.97]],"batl":[[2,2.28,18.66]],"ltp":1.9,"tv":903.75,"id":8258569}]}]}
{"op":"mcm","clk":"1009527119","pt":1580666626342,"mc":[{"id":"1.168238840","rc":[{"batb":[[2,1.99,2]],"batl":[[2,2.16,2.16]],"ltp":2.08,"tv":885.69,"id":8860646},{"batb":[[2,1.88,2.05]],"batl":[[2,1.99,2.23]],"ltp":1.9,"tv":903.75,"id":8258569}]}]}
{"op":"mcm","clk":"1009529006","pt":1580666644157,"mc":[{"id":"1.168238840","rc":[{"batb":[[2,1.98,25.72]],"batl":[[2,2.18,9.09]],"ltp":2.08,"tv":885.69,"id":8860646},{"trd":[[1.91,297.74]],"batb":[[0,1.91,15.87],[2,1.87,28.97]],"batl":[[2,2.28,18.66]],"ltp":1.91,"tv":928.95,"id":8258569}],"tv":1814.64}]}
{"op":"mcm","clk":"1009529070","pt":1580666644790,"mc":[{"id":"1.168238840","rc":[{"batb":[[2,1.99,27.46]],"batl":[[2,2.16,2]],"ltp":2.08,"tv":885.69,"id":8860646},{"batb":[[2,1.88,2.13]],"batl":[[0,1.96,12.27],[2,1.99,2.48]],"ltp":1.91,"tv":928.95,"id":8258569}]}]}
{"op":"mcm","clk":"1009529190","pt":1580666645777,"mc":[{"id":"1.168238840","rc":[{"batb":[[0,1.91,19.17]],"ltp":1.91,"tv":928.95,"id":8258569}]}]}
{"op":"mcm","clk":"1009529287","pt":1580666646762,"mc":[{"id":"1.168238840","rc":[{"batb":[[2,1.99,2]],"ltp":2.08,"tv":885.69,"id":8860646}]}]}
{"op":"mcm","clk":"1009531403","pt":1580666666090,"mc":[{"id":"1.168238840","rc":[{"batb":[[1,2,2]],"ltp":2.08,"tv":885.69,"id":8860646}]}]}
{"op":"mcm","clk":"1009531470","pt":1580666666565,"mc":[{"id":"1.168238840","rc":[{"batb":[[2,1.88,2.21]],"batl":[[2,1.99,2.27]],"ltp":1.91,"tv":928.95,"id":8258569}]}]}
{"op":"mcm","clk":"1009536714","pt":1580666717215,"mc":[{"id":"1.168238840","rc":[{"batb":[[1,2,59.55]],"batl":[[2,2.16,2.16]],"ltp":2.08,"tv":885.69,"id":8860646},{"batb":[[2,1.88,2]],"batl":[[2,1.99,2.44]],"ltp":1.91,"tv":928.95,"id":8258569}]}]}
{"op":"mcm","clk":"1009537568","pt":1580666726238,"mc":[{"id":"1.168238840","rc":[{"batb":[[0,1.91,31.76]],"ltp":1.91,"tv":928.95,"id":8258569}]}]}
{"op":"mcm","clk":"1009537611","pt":1580666726719,"mc":[{"id":"1.168238840","rc":[{"batb":[[1,2,2]],"batl":[[2,2.16,2.04]],"ltp":2.08,"tv":885.69,"id":8860646},{"batb":[[2,1.88,2.13]],"batl":[[2,1.99,2.38]],"ltp":1.91,"tv":928.95,"id":8258569}]}]}
{"op":"mcm","clk":"1009538197","pt":1580666733168,"mc":[{"id":"1.168238840","rc":[{"batb":[[1,2,59.55],[2,1.98,25.72]],"batl":[[2,2.18,9.09]],"ltp":2.08,"tv":885.69,"id":8860646},{"batb":[[2,1.87,28.97]],"batl":[[2,2.28,18.66]],"ltp":1.91,"tv":928.95,"id":8258569}]}]}
{"op":"mcm","clk":"1009538218","pt":1580666733437,"mc":[{"id":"1.168238840","rc":[{"batb":[[2,1.99,2]],"batl":[[2,2.16,2.22]],"ltp":2.08,"tv":885.69,"id":8860646},{"batb":[[2,1.88,2.21]],"batl":[[2,1.99,2.17]],"ltp":1.91,"tv":928.95,"id":8258569}]}]}
{"op":"mcm","clk":"1009543628","pt":1580666787247,"mc":[{"id":"1.168238840","rc":[{"batb":[[1,2,2]],"batl":[[2,2.16,2.1]],"ltp":2.08,"tv":885.69,"id":8860646},{"batb":[[2,1.88,2.05]],"batl":[[2,2.28,18.66]],"ltp":1.91,"tv":928.95,"id":8258569}]}]}
{"op":"mcm","clk":"1009543639","pt":1580666787304,"mc":[{"id":"1.168238840","rc":[{"batl":[[2,1.99,2.27]],"ltp":1.91,"tv":928.95,"id":8258569}]}]}
{"op":"mcm","clk":"1009544430","pt":1580666794122,"mc":[{"id":"1.168238840","rc":[{"batb":[[1,2,59.55]],"ltp":2.08,"tv":885.69,"id":8860646},{"batb":[[2,1.88,2.21]],"batl":[[2,1.99,2.21]],"ltp":1.91,"tv":928.95,"id":8258569}]}]}
{"op":"mcm","clk":"1009550208","pt":1580666847287,"mc":[{"id":"1.168238840","rc":[{"batb":[[1,2,2],[2,1.98,25.72]],"batl":[[2,2.18,9.09]],"ltp":2.08,"tv":885.69,"id":8860646},{"batb":[[2,1.87,28.97]],"batl":[[2,2.28,18.66]],"ltp":1.91,"tv":928.95,"id":8258569}]}]}
{"op":"mcm","clk":"1009550234","pt":1580666847498,"mc":[{"id":"1.168238840","rc":[{"batb":[[2,1.99,2]],"batl":[[2,2.16,2.1]],"ltp":2.08,"tv":885.69,"id":8860646},{"batb":[[2,1.88,2.21]],"batl":[[2,1.99,2.29]],"ltp":1.91,"tv":928.95,"id":8258569}]}]}
{"op":"mcm","clk":"1009550991","pt":1580666855181,"mc":[{"id":"1.168238840","rc":[{"batb":[[1,2,59.55],[2,1.98,25.72]],"batl":[[2,2.18,9.09]],"ltp":2.08,"tv":885.69,"id":8860646},{"batb":[[2,1.87,28.97]],"batl":[[2,2.28,18.66]],"ltp":1.91,"tv":928.95,"id":8258569}]}]}
{"op":"mcm","clk":"1009551015","pt":1580666855385,"mc":[{"id":"1.168238840","rc":[{"batb":[[2,1.99,2]],"batl":[[2,2.16,2.1]],"ltp":2.08,"tv":885.69,"id":8860646},{"batb":[[2,1.88,2.21]],"batl":[[2,1.99,2.38]],"ltp":1.91,"tv":928.95,"id":8258569}]}]}
{"op":"mcm","clk":"1009553564","pt":1580666879133,"mc":[{"id":"1.168238840","rc":[{"batl":[[2,2.16,2.16]],"ltp":2.08,"tv":885.69,"id":8860646},{"batb":[[2,1.88,2]],"batl":[[2,1.99,2.58]],"ltp":1.91,"tv":928.95,"id":8258569}]}]}
{"op":"mcm","clk":"1009554441","pt":1580666887722,"mc":[{"id":"1.168238840","rc":[{"batb":[[1,2,2],[2,1.99,59.55]],"batl":[[2,2.16,2.04]],"ltp":2.08,"tv":885.69,"id":8860646},{"batb":[[2,1.88,2.21]],"batl":[[2,1.99,2.36]],"ltp":1.91,"tv":928.95,"id":8258569}]}]}
{"op":"mcm","clk":"1009556448","pt":1580666907242,"mc":[{"id":"1.168238840","rc":[{"batb":[[2,1.99,2]],"ltp":2.08,"tv":885.69,"id":8860646}]}]}
{"op":"mcm","clk":"1009556497","pt":1580666907720,"mc":[{"id":"1.168238840","rc":[{"batl":[[2,2.16,2]],"ltp":2.08,"tv":885.69,"id":8860646},{"batl":[[2,1.99,2.44]],"ltp":1.91,"tv":928.95,"id":8258569}]}]}
{"op":"mcm","clk":"1009557818","pt":1580666920254,"mc":[{"id":"1.168238840","rc":[{"batb":[[2,1.99,57.55]],"batl":[[2,2.18,9.09]],"ltp":2.08,"tv":885.69,"id":8860646},{"batb":[[2,1.87,28.97]],"batl":[[2,2.28,18.66]],"ltp":1.91,"tv":928.95,"id":8258569}]}]}
{"op":"mcm","clk":"1009557834","pt":1580666920424,"mc":[{"id":"1.168238840","rc":[{"batb":[[2,1.99,59.55]],"batl":[[2,2.16,2.1]],"ltp":2.08,"tv":885.69,"id":8860646},{"batb":[[2,1.88,2.21]],"batl":[[2,1.99,2.46]],"ltp":1.91,"tv":928.95,"id":8258569}]}]}
{"op":"mcm","clk":"1009558527","pt":1580666927252,"mc":[{"id":"1.168238840","rc":[{"batb":[[0,2.02,15.04],[1,2,34.79]],"batl":[[2,2.16,2.04]],"ltp":2.08,"tv":885.69,"id":8860646},{"batb":[[0,1.92,35.6],[1,1.91,31.76],[2,1.9,2.06]],"batl":[[0,1.96,8.1],[1,1.97,12.21],[2,1.98,24.8]],"ltp":1.91,"tv":928.95,"id":8258569}]}]}
{"op":"mcm","clk":"1009558641","pt":1580666928153,"mc":[{"id":"1.168238840","rc":[{"batb":[[1,2,32.79]],"batl":[[0,2.08,14.47],[1,2.1,464.42],[2,2.12,2.05]],"ltp":2.08,"tv":885.69,"id":8860646},{"batl":[[0,1.98,22.72],[1,2,2.17],[2,2.02,2.25]],"ltp":1.91,"tv":928.95,"id":8258569}]}]}
{"op":"mcm","clk":"1009558896","pt":1580666930751,"mc":[{"id":"1.168238840","rc":[{"batb":[[1,1.91,15.85]],"ltp":1.91,"tv":928.95,"id":8258569}]}]}
{"op":"mcm","clk":"1009560528","pt":1580666945280,"mc":[{"id":"1.168238840","rc":[{"batl":[[0,1.97,12.21],[1,1.98,22.72],[2,2,2.17]],"ltp":1.91,"tv":928.95,"id":8258569}]}]}
{"op":"mcm","clk":"1009560616","pt":1580666945957,"mc":[{"id":"1.168238840","rc":[{"batl":[[2,1.99,2.32]],"ltp":1.91,"tv":928.95,"id":8258569}]}]}
{"op":"mcm","clk":"1009561804","pt":1580666956084,"mc":[{"id":"1.168238840","rc":[{"batb":[[1,1.91,12.55]],"ltp":1.91,"tv":928.95,"id":8258569}]}]}
{"op":"mcm","clk":"1009562031","pt":1580666957985,"mc":[{"id":"1.168238840","rc":[{"batb":[[0,1.93,15.75],[1,1.92,35.6],[2,1.91,14.61]],"ltp":1.91,"tv":928.95,"id":8258569}]}]}
{"op":"mcm","clk":"1009563032","pt":1580666968196,"mc":[{"id":"1.168238840","rc":[{"batb":[[2,1.99,2]],"ltp":2.08,"tv":885.69,"id":8860646}]}]}
{"op":"mcm","clk":"1009564297","pt":1580666981882,"mc":[{"id":"1.168238840","rc":[{"batb":[[2,1.99,59.55]],"ltp":2.08,"tv":885.69,"id":8860646}]}]}
{"op":"mcm","clk":"1009568902","pt":1580667027950,"mc":[{"id":"1.168238840","rc":[{"batb":[[2,1.99,2]],"ltp":2.08,"tv":885.69,"id":8860646}]}]}
{"op":"mcm","clk":"1009569904","pt":1580667037160,"mc":[{"id":"1.168238840","rc":[{"batb":[[1,1.99,2],[2,1.98,50.06]],"ltp":2.08,"tv":885.69,"id":8860646},{"batb":[[1,1.91,50.21],[2,1.88,28.64]],"ltp":1.91,"tv":928.95,"id":8258569}]}]}
{"op":"mcm","clk":"1009569922","pt":1580667037366,"mc":[{"id":"1.168238840","rc":[{"batb":[[2,1.98,52.06]],"ltp":2.08,"tv":885.69,"id":8860646},{"batb":[[2,1.9,2]],"ltp":1.91,"tv":928.95,"id":8258569}]}]}
{"op":"mcm","clk":"1009570180","pt":1580667040040,"mc":[{"id":"1.168238840","rc":[{"batb":[[0,2.04,15.04],[1,2,2],[2,1.99,2]],"ltp":2.08,"tv":885.69,"id":8860646},{"batb":[[0,1.92,15.75],[1,1.91,48.15]],"ltp":1.91,"tv":928.95,"id":8258569}]}]}
{"op":"mcm","clk":"1009570403","pt":1580667042260,"mc":[{"id":"1.168238840","rc":[{"batb":[[2,1.99,59.55]],"ltp":2.08,"tv":885.69,"id":8860646}]}]}
{"op":"mcm","clk":"1009574751","pt":1580667088820,"mc":[{"id":"1.168238840","rc":[{"batb":[[2,1.99,2]],"ltp":2.08,"tv":885.69,"id":8860646}]}]}
{"op":"mcm","clk":"1009576168","pt":1580667102908,"mc":[{"id":"1.168238840","rc":[{"batb":[[2,1.99,59.55]],"ltp":2.08,"tv":885.69,"id":8860646}]}]}
{"op":"mcm","clk":"1009580434","pt":1580667148273,"mc":[{"id":"1.168238840","rc":[{"batb":[[1,2,34.79]],"ltp":2.08,"tv":885.69,"id":8860646},{"batb":[[0,1.93,28.92],[1,1.92,15.75],[2,1.91,2.06]],"ltp":1.91,"tv":928.95,"id":8258569}]}]}
{"op":"mcm","clk":"1009580499","pt":1580667148898,"mc":[{"id":"1.168238840","rc":[{"batb":[[2,1.99,2]],"ltp":2.08,"tv":885.69,"id":8860646}]}]}
{"op":"mcm","clk":"1009581304","pt":1580667156900,"mc":[{"id":"1.168238840","rc":[{"batb":[[0,2.02,15.04],[1,2,32.79]],"ltp":2.08,"tv":885.69,"id":8860646}]}]}
{"op":"mcm","clk":"1009581741","pt":1580667161279,"mc":[{"id":"1.168238840","rc":[{"batb":[[0,1.94,15.75],[1,1.93,28.92],[2,1.92,2.19]],"ltp":1.91,"tv":928.95,"id":8258569}]}]}
{"op":"mcm","clk":"1009581946","pt":1580667163180,"mc":[{"id":"1.168238840","rc":[{"batb":[[2,1.99,59.55]],"ltp":2.08,"tv":885.69,"id":8860646}]}]}
{"op":"mcm","clk":"1009586918","pt":1580667209229,"mc":[{"id":"1.168238840","rc":[{"batb":[[2,1.99,2]],"ltp":2.08,"tv":885.69,"id":8860646}]}]}
{"op":"mcm","clk":"1009589538","pt":1580667233186,"mc":[{"id":"1.168238840","rc":[{"trd":[[2.08,274.54],[2.1,599.17]],"batl":[[0,2.12,2.05],[1,2.14,2.11],[2,2.18,9.09]],"ltp":2.1,"tv":1364.58,"id":8860646},{"trd":[[1.9,650.48],[1.91,301.85],[1.92,37.96],[1.93,57.84],[1.94,33.19]],"batb":[[0,1.88,28.64],[1,1.87,28.97],[2,1.86,29.31]],"batl":[[0,1.9,3623.07],[1,1.97,12.21],[2,1.98,22.72]],"ltp":1.9,"tv":1555.77,"id":8258569}],"tv":2920.35}]}
{"op":"mcm","clk":"1009589660","pt":1580667234261,"mc":[{"id":"1.168238840","rc":[{"trd":[[2.1,599.22],[2.12,209.88]],"batb":[[0,2.06,2.08],[1,2.04,2],[2,2.02,39.75]],"batl":[[0,2.18,9.09],[1,2.22,2.03],[2,2.24,2.19]],"ltp":2.1,"tv":1368.53,"id":8860646},{"trd":[[1.9,1452.84]],"batb":[[0,1.84,160.48],[1,1.81,31.12],[2,1.71,38.19]],"batl":[[0,1.9,3221.86],[1,1.92,2.81],[2,1.93,2.64]],"ltp":1.9,"tv":2358.13,"id":8258569}],"tv":3726.66}]}
{"op":"mcm","clk":"1009589743","pt":1580667234947,"mc":[{"id":"1.168238840","rc":[{"batb":[[1,2.04,80.15]],"ltp":2.1,"tv":1368.53,"id":8860646},{"batb":[[0,1.85,51.69],[1,1.84,160.48],[2,1.8,31.51]],"ltp":1.9,"tv":2358.13,"id":8258569}]}]}
{"op":"mcm","clk":"1009589845","pt":1580667235953,"mc":[{"id":"1.168238840","rc":[{"batb":[[2,1.81,31.12]],"ltp":1.9,"tv":2358.13,"id":8258569}]}]}
{"op":"mcm","clk":"1009590053","pt":1580667237748,"mc":[{"id":"1.168238840","rc":[{"batb":[[0,1.86,7.54],[1,1.85,51.69],[2,1.84,160.48]],"ltp":1.9,"tv":2358.13,"id":8258569}]}]}
{"op":"mcm","clk":"1009590205","pt":1580667239282,"mc":[{"id":"1.168238840","rc":[{"batb":[[0,2.04,78.15],[1,2.02,41.99],[2,1.96,26.26]],"ltp":2.1,"tv":1368.53,"id":8860646},{"batl":[[0,1.94,3.08],[1,1.95,3.1],[2,1.97,12.21]],"ltp":1.9,"tv":2358.13,"id":8258569}]}]}
{"op":"mcm","clk":"1009590309","pt":1580667240266,"mc":[{"id":"1.168238840","rc":[{"batb":[[0,2.04,53.92],[1,2.02,39.75],[2,2,2]],"batl":[[2,2.24,2.23]],"ltp":2.1,"tv":1368.53,"id":8860646},{"batb":[[2,1.84,190.48]],"batl":[[0,1.97,12.21],[1,1.98,22.72],[2,1.99,3.6]],"ltp":1.9,"tv":2358.13,"id":8258569}]}]}
{"op":"mcm","clk":"1009590394","pt":1580667241097,"mc":[{"id":"1.168238840","rc":[{"batb":[[0,2.04,68.96],[1,2.02,24.71]],"ltp":2.1,"tv":1368.53,"id":8860646},{"batl":[[0,1.97,15.43]],"ltp":1.9,"tv":2358.13,"id":8258569}]}]}
{"op":"mcm","clk":"1009590830","pt":1580667245167,"mc":[{"id":"1.168238840","rc":[{"batb":[[0,1.85,51.69],[1,1.84,190.48],[2,1.81,31.12]],"ltp":1.9,"tv":2358.13,"id":8258569}]}]}
{"op":"mcm","clk":"1009591009","pt":1580667246970,"mc":[{"id":"1.168238840","rc":[{"batb":[[0,2.06,1.23],[1,2.04,68.96],[2,2.02,24.71]],"ltp":2.1,"tv":1368.53,"id":8860646},{"batb":[[0,1.86,1.35],[1,1.85,51.69],[2,1.84,190.48]],"ltp":1.9,"tv":2358.13,"id":8258569}]}]}
{"op":"mcm","clk":"1009593427","pt":1580667269197,"mc":[{"id":"1.168238840","rc":[{"batb":[[0,2.06,16.27],[1,2.04,53.92]],"ltp":2.1,"tv":1368.53,"id":8860646},{"batl":[[0,1.96,15.5],[1,1.98,25.47]],"ltp":1.9,"tv":2358.13,"id":8258569}]}]}
{"op":"mcm","clk":"1009593526","pt":1580667269985,"mc":[{"id":"1.168238840","rc":[{"batb":[[2,2.02,26.78]],"ltp":2.1,"tv":1368.53,"id":8860646},{"batb":[[2,1.84,160.48]],"batl":[[1,1.97,3.16],[2,1.98,25.47]],"ltp":1.9,"tv":2358.13,"id":8258569}]}]}
{"op":"mcm","clk":"1009595172","pt":1580667285230,"mc":[{"id":"1.168238840","rc":[{"batb":[[0,2.06,15.84]],"batl":[[2,2.28,18.48]],"ltp":2.1,"tv":1368.53,"id":8860646},{"batl":[[2,1.98,22.72]],"ltp":1.9,"tv":2358.13,"id":8258569}]}]}
{"op":"mcm","clk":"1009595191","pt":1580667285362,"mc":[{"id":"1.168238840","rc":[{"batl":[[2,2.24,2.23]],"ltp":2.1,"tv":1368.53,"id":8860646},{"batl":[[2,1.98,25.97]],"ltp":1.9,"tv":2358.13,"id":8258569}]}]}
{"op":"mcm","clk":"1009598795","pt":1580667319229,"mc":[{"id":"1.168238840","rc":[{"batl":[[0,2.16,3.79],[1,2.18,9.09],[2,2.2,2.03]],"ltp":2.1,"tv":1368.53,"id":8860646}]}]}
{"op":"mcm","clk":"1009598867","pt":1580667319753,"mc":[{"id":"1.168238840","rc":[{"batl":[[2,1.98,25.47]],"ltp":1.9,"tv":2358.13,"id":8258569}]}]}
{"op":"mcm","clk":"1009599898","pt":1580667329245,"mc":[{"id":"1.168238840","rc":[{"trd":[[2.16,3.79]],"batl":[[0,2.18,9.09],[1,2.2,2.03],[2,2.22,2.07]],"ltp":2.16,"tv":1372.31,"id":8860646},{"trd":[[1.86,17.23]],"batb":[[0,1.85,51.69],[1,1.84,160.48],[2,1.83,30.36]],"ltp":1.86,"tv":2365.23,"id":8258569}],"tv":3737.55}]}
{"op":"mcm","clk":"1009599941","pt":1580667329662,"mc":[{"id":"1.168238840","rc":[{"batl":[[1,2.22,2.07],[2,2.24,2.23]],"ltp":2.16,"tv":1372.31,"id":8860646},{"batl":[[2,1.98,25.97]],"ltp":1.86,"tv":2365.23,"id":8258569}]}]}
{"op":"mcm","clk":"1009600017","pt":1580667330347,"mc":[{"id":"1.168238840","rc":[{"batb":[[0,1.85,51.09]],"ltp":1.86,"tv":2365.23,"id":8258569}]}]}
{"op":"mcm","clk":"1009600498","pt":1580667335254,"mc":[{"id":"1.168238840","rc":[{"batl":[[2,2.28,18.48]],"ltp":2.16,"tv":1372.31,"id":8860646},{"batl":[[2,1.98,22.72]],"ltp":1.86,"tv":2365.23,"id":8258569}]}]}
{"op":"mcm","clk":"1009600520","pt":1580667335459,"mc":[{"id":"1.168238840","rc":[{"batl":[[2,2.24,2.19]],"ltp":2.16,"tv":1372.31,"id":8860646},{"batl":[[2,1.98,25.47]],"ltp":1.86,"tv":2365.23,"id":8258569}]}]}
{"op":"mcm","clk":"1009601384","pt":1580667344174,"mc":[{"id":"1.168238840","rc":[{"batb":[[0,2.08,3.79],[1,2.06,15.84],[2,2.04,53.92]],"ltp":2.16,"tv":1372.31,"id":8860646}]}]}
{"op":"mcm","clk":"1009601453","pt":1580667344863,"mc":[{"id":"1.168238840","rc":[{"batb":[[2,2.04,55.97]],"batl":[[2,2.24,2.23]],"ltp":2.16,"tv":1372.31,"id":8860646},{"batl":[[0,1.95,3.1],[1,1.96,18.37],[2,1.98,22.72]],"ltp":1.86,"tv":2365.23,"id":8258569}]}]}
{"op":"mcm","clk":"1009624705","pt":1580667601961,"mc":[{"id":"1.168238840","rc":[{"trd":[[2.08,276.1]],"batb":[[0,2.08,2.23]],"batl":[[2,2.24,2]],"ltp":2.08,"tv":1373.87,"id":8860646},{"trd":[[1.93,59.52]],"batl":[[1,1.96,18.62]],"ltp":1.93,"tv":2366.91,"id":8258569}],"tv":3740.79}]}
{"op":"mcm","clk":"1009625470","pt":1580667611289,"mc":[{"id":"1.168238840","rc":[{"trd":[[2.08,280.55]],"batb":[[0,2.06,15.84],[1,2.04,53.92],[2,2.02,26.74]],"batl":[[0,2.08,17.37],[1,2.12,2.13],[2,2.14,2.11]],"ltp":2.08,"tv":1378.32,"id":8860646},{"batl":[[1,1.96,15.5]],"ltp":1.93,"tv":2366.91,"id":8258569}],"tv":3745.24}]}
{"op":"mcm","clk":"1009625543","pt":1580667612083,"mc":[{"id":"1.168238840","rc":[{"batb":[[2,2.02,2.03]],"ltp":2.08,"tv":1378.32,"id":8860646},{"batb":[[0,1.87,28.97],[1,1.85,51.09],[2,1.84,160.48]],"batl":[[0,1.96,15.5],[1,1.97,2.83],[2,1.98,25.97]],"ltp":1.93,"tv":2366.91,"id":8258569}]}]}
{"op":"mcm","clk":"1009625758","pt":1580667614280,"mc":[{"id":"1.168238840","rc":[{"batb":[[0,2.06,1.23]],"ltp":2.08,"tv":1378.32,"id":8860646}]}]}
{"op":"mcm","clk":"1009625837","pt":1580667615216,"mc":[{"id":"1.168238840","rc":[{"batb":[[1,2.04,68.53],[2,2,2]],"ltp":2.08,"tv":1378.32,"id":8860646},{"batl":[[1,1.98,25.97],[2,1.99,3.67]],"ltp":1.93,"tv":2366.91,"id":8258569}]}]}
{"op":"mcm","clk":"1009625891","pt":1580667615797,"mc":[{"id":"1.168238840","rc":[{"batb":[[0,1.87,34.55]],"ltp":1.93,"tv":2366.91,"id":8258569}]}]}
{"op":"mcm","clk":"1009625943","pt":1580667616322,"mc":[{"id":"1.168238840","rc":[{"batb":[[0,1.87,28.97]],"ltp":1.93,"tv":2366.91,"id":8258569}]}]}
{"op":"mcm","clk":"1009626243","pt":1580667619986,"mc":[{"id":"1.168238840","rc":[{"trd":[[2.06,20.87]],"batb":[[0,2.04,68.53],[1,2,2],[2,1.99,2]],"batl":[[0,2.06,16.15]],"ltp":2.06,"tv":1380.78,"id":8860646}],"tv":3747.69}]}
{"op":"mcm","clk":"1009626349","pt":1580667621089,"mc":[{"id":"1.168238840","rc":[{"batl":[[1,2.1,2.05],[2,2.12,2.21]],"ltp":2.06,"tv":1380.78,"id":8860646},{"batb":[[0,1.86,29.31]],"ltp":1.93,"tv":2366.91,"id":8258569}]}]}
{"op":"mcm","clk":"1009627063","pt":1580667630221,"mc":[{"id":"1.168238840","rc":[{"batb":[[0,2.04,68.67]],"ltp":2.06,"tv":1380.78,"id":8860646}]}]}
{"op":"mcm","clk":"1009627114","pt":1580667630811,"mc":[{"id":"1.168238840","rc":[{"batl":[[2,2.12,2.13]],"ltp":2.06,"tv":1380.78,"id":8860646}]}]}
{"op":"mcm","clk":"1009627160","pt":1580667631344,"mc":[{"id":"1.168238840","rc":[{"batb":[[0,1.87,6.58],[1,1.86,29.31],[2,1.85,51.09]],"ltp":1.93,"tv":2366.91,"id":8258569}]}]}
{"op":"mcm","clk":"1009627972","pt":1580667641248,"mc":[{"id":"1.168238840","rc":[{"trd":[[2.04,51.8]],"batb":[[0,2.04,52.5],[2,1.97,25.99]],"batl":[[0,2.14,2.04],[1,2.16,2.22],[2,2.18,9.09]],"ltp":2.04,"tv":1413.09,"id":8860646},{"batb":[[0,1.86,29.31],[1,1.85,51.09],[2,1.84,160.48]],"batl":[[2,2.28,18.66]],"ltp":1.93,"tv":2366.91,"id":8258569}],"tv":3780.0}]}
{"op":"mcm","clk":"1009628031","pt":1580667642035,"mc":[{"id":"1.168238840","rc":[{"batb":[[1,2,27.21],[2,1.99,2]],"batl":[[0,2.18,11.12],[1,2.2,2.03],[2,2.22,2.16]],"ltp":2.04,"tv":1413.09,"id":8860646},{"batb":[[0,1.88,36.97],[1,1.85,29.65]],"batl":[[2,1.99,3.67]],"ltp":1.93,"tv":2366.91,"id":8258569}]}]}
{"op":"mcm","clk":"1009628824","pt":1580667652256,"mc":[{"id":"1.168238840","rc":[{"batb":[[0,2.04,37.75],[1,2.02,2.1],[2,2,27.21]],"batl":[[2,2.28,18.48]],"ltp":2.04,"tv":1413.09,"id":8860646}]}]}
{"op":"mcm","clk":"1009628879","pt":1580667652734,"mc":[{"id":"1.168238840","rc":[{"batb":[[1,2,27.21],[2,1.99,2]],"ltp":2.04,"tv":1413.09,"id":8860646},{"batl":[[2,1.99,3.54]],"ltp":1.93,"tv":2366.91,"id":8258569}]}]}
{"op":"mcm","clk":"1009630235","pt":1580667667247,"mc":[{"id":"1.168238840","rc":[{"batb":[[0,2.06,14.61],[1,2.04,37.75],[2,2.02,2.05]],"batl":[[1,2.28,18.48],[2,2.3,16.8]],"ltp":2.04,"tv":1413.09,"id":8860646},{"batl":[[2,2.28,18.66]],"ltp":1.93,"tv":2366.91,"id":8258569}]}]}
{"op":"mcm","clk":"1009630319","pt":1580667668146,"mc":[{"id":"1.168238840","rc":[{"batl":[[0,2.12,3.79],[1,2.16,2.22],[2,2.18,9.09]],"ltp":2.04,"tv":1413.09,"id":8860646},{"batl":[[1,1.97,2.83],[2,1.98,25.47]],"ltp":1.93,"tv":2366.91,"id":8258569}]}]}
{"op":"mcm","clk":"1009630356","pt":1580667668456,"mc":[{"id":"1.168238840","rc":[{"batl":[[2,2.18,11.12]],"ltp":2.04,"tv":1413.09,"id":8860646}]}]}
{"op":"mcm","clk":"1009633167","pt":1580667699199,"mc":[{"id":"1.168238840","rc":[{"batl":[[2,2.18,9.09]],"ltp":2.04,"tv":1413.09,"id":8860646},{"batb":[[0,1.86,57.88],[1,1.84,190.48],[2,1.83,30.36]],"batl":[[0,1.94,133.96],[1,1.96,18.12],[2,1.98,22.72]],"ltp":1.93,"tv":2366.91,"id":8258569}]}]}
{"op":"mcm","clk":"1009633246","pt":1580667700099,"mc":[{"id":"1.168238840","rc":[{"batb":[[2,2.02,26.76]],"batl":[[2,2.18,11.12]],"ltp":2.04,"tv":1413.09,"id":8860646},{"batb":[[1,1.84,160.48]],"batl":[[2,1.97,2.83]],"ltp":1.93,"tv":2366.91,"id":8258569}]}]}
{"op":"mcm","clk":"1009633455","pt":1580667702267,"mc":[{"id":"1.168238840","rc":[{"batb":[[0,2.08,14.61]],"ltp":2.04,"tv":1413.09,"id":8860646},{"batl":[[0,1.93,15.5],[1,1.94,133.96],[2,1.95,3.1]],"ltp":1.93,"tv":2366.91,"id":8258569}]}]}
{"op":"mcm","clk":"1009633488","pt":1580667702580,"mc":[{"id":"1.168238840","rc":[{"batb":[[1,2.04,39.75],[2,2.02,26.93]],"ltp":2.04,"tv":1413.09,"id":8860646}]}]}
{"op":"mcm","clk":"1009634606","pt":1580667716121,"mc":[{"id":"1.168238840","rc":[{"batb":[[2,2.02,26.95]],"ltp":2.04,"tv":1413.09,"id":8860646},{"batl":[[0,1.93,15.75]],"ltp":1.93,"tv":2366.91,"id":8258569}]}]}
{"op":"mcm","clk":"1009634801","pt":1580667718418,"mc":[{"id":"1.168238840","rc":[{"batb":[[0,2.08,14.47]],"ltp":2.04,"tv":1413.09,"id":8860646}]}]}
{"op":"mcm","clk":"1009642475","pt":1580667809168,"mc":[{"id":"1.168238840","rc":[{"batb":[[2,2.02,24.71]],"batl":[[2,2.18,9.09]],"ltp":2.04,"tv":1413.09,"id":8860646},{"batb":[[0,1.85,68.64]],"ltp":1.93,"tv":2366.91,"id":8258569}]}]}
{"op":"mcm","clk":"1009642559","pt":1580667810203,"mc":[{"id":"1.168238840","rc":[{"batb":[[2,2.02,26.73]],"batl":[[2,2.18,11.12]],"ltp":2.04,"tv":1413.09,"id":8860646},{"batb":[[2,1.82,30.74]],"ltp":1.93,"tv":2366.91,"id":8258569}]}]}
{"op":"mcm","clk":"1009645281","pt":1580667838917,"mc":[{"id":"1.168238840","rc":[{"trd":[[2.08,305.26]],"batb":[[0,2.08,2.12]],"ltp":2.08,"tv":1437.8,"id":8860646}],"tv":3804.71}]}
{"op":"mcm","clk":"1009645581","pt":1580667842200,"mc":[{"id":"1.168238840","rc":[{"batb":[[0,2.04,37.75],[1,2.02,26.73],[2,2,27.21]],"batl":[[0,2.18,9.09],[1,2.22,2.07],[2,2.24,2.15]],"ltp":2.08,"tv":1437.8,"id":8860646}]}]}
{"op":"mcm","clk":"1009646314","pt":1580667850910,"mc":[{"id":"1.168238840","rc":[{"trd":[[2.18,16.37]],"batl":[[0,2.18,8.95],[2,2.24,2.23]],"ltp":2.18,"tv":1438.07,"id":8860646}],"tv":3804.99}]}
{"op":"mcm","clk":"1009646491","pt":1580667853118,"mc":[{"id":"1.168238840","rc":[{"batb":[[0,2.08,2.12],[1,2.04,37.75],[2,2.02,26.73]],"ltp":2.18,"tv":1438.07,"id":8860646}]}]}
{"op":"mcm","clk":"1009646592","pt":1580667854212,"mc":[{"id":"1.168238840","rc":[{"batb":[[1,2.04,39.82],[2,2.02,26.89]],"ltp":2.18,"tv":1438.07,"id":8860646}]}]}
{"op":"mcm","clk":"1009661281","pt":1580668040069,"mc":[{"id":"1.168238840","rc":[{"trd":[[2.06,21.11],[2.08,309.51]],"batb":[[0,2.04,39.82],[1,2.02,26.89],[2,2,27.21]],"ltp":2.06,"tv":1442.55,"id":8860646},{"trd":[[1.93,59.77]],"batl":[[0,1.93,15.49]],"ltp":1.93,"tv":2367.16,"id":8258569}],"tv":3809.72}]}
{"op":"mcm","clk":"1009661324","pt":1580668040583,"mc":[{"id":"1.168238840","rc":[{"batb":[[0,2.04,37.75]],"ltp":2.06,"tv":1442.55,"id":8860646}]}]}
{"op":"mcm","clk":"1009662403","pt":1580668056196,"mc":[{"id":"1.168238840","rc":[{"batl":[[0,1.93,15.75]],"ltp":1.93,"tv":2367.16,"id":8258569}]}]}
{"op":"mcm","clk":"1009662430","pt":1580668056570,"mc":[{"id":"1.168238840","rc":[{"batl":[[2,2.24,2.19]],"ltp":2.06,"tv":1442.55,"id":8860646}]}]}
{"op":"mcm","clk":"1009663457","pt":1580668070203,"mc":[{"id":"1.168238840","rc":[{"batb":[[0,1.9,5.62],[1,1.85,68.64],[2,1.84,160.48]],"ltp":1.93,"tv":2367.16,"id":8258569}]}]}
{"op":"mcm","clk":"1009663492","pt":1580668070627,"mc":[{"id":"1.168238840","rc":[{"batl":[[2,2.24,2.23]],"ltp":2.06,"tv":1442.55,"id":8860646},{"trd":[[1.9,1464.09]],"batb":[[0,1.85,68.64],[1,1.84,160.48],[2,1.82,30.74]],"ltp":1.9,"tv":2378.41,"id":8258569}],"tv":3820.96}]}
{"op":"mcm","clk":"1009664599","pt":1580668084214,"mc":[{"id":"1.168238840","rc":[{"batb":[[0,2.08,2.12],[1,2.04,37.75],[2,2.02,26.89]],"batl":[[2,2.24,2.15]],"ltp":2.06,"tv":1442.55,"id":8860646}]}]}
{"op":"mcm","clk":"1009664650","pt":1580668084724,"mc":[{"id":"1.168238840","rc":[{"batb":[[1,2.04,39.87],[2,2.02,26.95]],"ltp":2.06,"tv":1442.55,"id":8860646}]}]}
{"op":"mcm","clk":"1009672241","pt":1580668180251,"mc":[{"id":"1.168238840","rc":[{"batb":[[2,2.02,26.82]],"batl":[[2,2.24,2.19]],"ltp":2.06,"tv":1442.55,"id":8860646},{"batl":[[0,1.92,2.27],[1,1.93,15.75],[2,1.94,136.87]],"ltp":1.9,"tv":2378.41,"id":8258569}]}]}
{"op":"mcm","clk":"1009674937","pt":1580668212258,"mc":[{"id":"1.168238840","rc":[{"trd":[[2.08,315.85]],"batb":[[0,2.04,37.75],[1,2.02,26.82],[2,2,27.21]],"batl":[[0,2.08,43.86],[1,2.12,2.21],[2,2.14,2.25]],"ltp":2.08,"tv":1448.89,"id":8860646},{"trd":[[1.92,40.23]],"batl":[[0,1.93,15.75],[1,1.94,133.96],[2,1.95,2.7]],"ltp":1.92,"tv":2380.68,"id":8258569}],"tv":3829.58}]}
{"op":"mcm","clk":"1009675027","pt":1580668213261,"mc":[{"id":"1.168238840","rc":[{"batb":[[1,2.02,2.11],[2,2,2]],"ltp":2.08,"tv":1448.89,"id":8860646},{"batb":[[0,1.86,29.31],[1,1.85,88.21],[2,1.84,160.48]],"ltp":1.92,"tv":2380.68,"id":8258569}]}]}
{"op":"mcm","clk":"1009675206","pt":1580668215261,"mc":[{"id":"1.168238840","rc":[{"batl":[[0,1.94,149.63],[1,1.95,2.7],[2,1.96,3.12]],"ltp":1.92,"tv":2380.68,"id":8258569}]}]}
{"op":"mcm","clk":"1009675295","pt":1580668216267,"mc":[{"id":"1.168238840","rc":[{"trd":[[2.08,399.13]],"batl":[[0,2.08,4.34]],"ltp":2.08,"tv":1532.17,"id":8860646},{"batb":[[0,1.87,9.9],[1,1.85,68.64]],"batl":[[1,1.96,3.12],[2,1.97,2.83]],"ltp":1.92,"tv":2380.68,"id":8258569}],"tv":3912.86}]}
{"op":"mcm","clk":"1009675560","pt":1580668219289,"mc":[{"id":"1.168238840","rc":[{"batl":[[0,2.08,2.22],[1,2.12,4.33],[2,2.14,2.11]],"ltp":2.08,"tv":1532.17,"id":8860646}]}]}
{"op":"mcm","clk":"1009676231","pt":1580668228281,"mc":[{"id":"1.168238840","rc":[{"batb":[[2,1.99,25.46]],"batl":[[2,2.18,8.95]],"ltp":2.08,"tv":1532.17,"id":8860646},{"batb":[[0,1.88,2.27],[1,1.87,9.9],[2,1.85,68.64]],"batl":[[2,1.98,22.72]],"ltp":1.92,"tv":2380.68,"id":8258569}]}]}
{"op":"mcm","clk":"1009676290","pt":1580668229063,"mc":[{"id":"1.168238840","rc":[{"batb":[[2,2,2]],"batl":[[2,2.14,2]],"ltp":2.08,"tv":1532.17,"id":8860646},{"trd":[[1.92,46.75]],"batb":[[1,1.86,9.9]],"batl":[[2,1.97,2.83]],"ltp":1.92,"tv":2387.2,"id":8258569}],"tv":3919.38}]}
{"op":"mcm","clk":"1009676552","pt":1580668232203,"mc":[{"id":"1.168238840","rc":[{"batl":[[0,1.93,15.67],[1,1.94,133.96],[2,1.95,2.9]],"ltp":1.92,"tv":2387.2,"id":8258569}]}]}
{"op":"mcm","clk":"1009677246","pt":1580668242205,"mc":[{"id":"1.168238840","rc":[{"batb":[[2,1.99,25.46]],"batl":[[2,2.18,8.95]],"ltp":2.08,"tv":1532.17,"id":8860646},{"batb":[[0,1.89,2.27]],"ltp":1.92,"tv":2387.2,"id":8258569}]}]}
{"op":"mcm","clk":"1009677260","pt":1580668242411,"mc":[{"id":"1.168238840","rc":[{"batb":[[2,2,2]],"batl":[[2,2.14,2.11]],"ltp":2.08,"tv":1532.17,"id":8860646}]}]}
{"op":"mcm","clk":"1009677391","pt":1580668244189,"mc":[{"id":"1.168238840","rc":[{"trd":[[2.08,403.57]],"batb":[[0,2.08,7.63],[1,2.04,39.86],[2,2.02,2.11]],"batl":[[0,2.12,2.12],[1,2.16,2],[2,2.18,10.98]],"ltp":2.08,"tv":1536.61,"id":8860646}],"tv":3923.82}]}
{"op":"mcm","clk":"1009677458","pt":1580668245016,"mc":[{"id":"1.168238840","rc":[{"batb":[[2,2.02,26.87]],"batl":[[0,2.16,2.04],[1,2.18,10.98],[2,2.2,2.03]],"ltp":2.08,"tv":1536.61,"id":8860646},{"batl":[[0,1.93,15.75]],"ltp":1.92,"tv":2387.2,"id":8258569}]}]}
{"op":"mcm","clk":"1009677782","pt":1580668249227,"mc":[{"id":"1.168238840","rc":[{"batb":[[1,1.87,47.32],[2,1.86,9.9]],"ltp":1.92,"tv":2387.2,"id":8258569}]}]}
{"op":"mcm","clk":"1009677924","pt":1580668251246,"mc":[{"id":"1.168238840","rc":[{"batb":[[0,2.08,20.12],[2,2.02,26.95]],"ltp":2.08,"tv":1536.61,"id":8860646}]}]}
{"op":"mcm","clk":"1009678166","pt":1580668254126,"mc":[{"id":"1.168238840","rc":[{"batl":[[0,2.14,2.04]],"ltp":2.08,"tv":1536.61,"id":8860646}]}]}
{"op":"mcm","clk":"1009678263","pt":1580668255254,"mc":[{"id":"1.168238840","rc":[{"batb":[[0,1.88,2.27]],"ltp":1.92,"tv":2387.2,"id":8258569}]}]}
{"op":"mcm","clk":"1009678886","pt":1580668263229,"mc":[{"id":"1.168238840","rc":[{"batb":[[0,2.08,22.24]],"ltp":2.08,"tv":1536.61,"id":8860646},{"batb":[[2,1.84,160.48]],"batl":[[1,1.94,137.19]],"ltp":1.92,"tv":2387.2,"id":8258569}]}]}
{"op":"mcm","clk":"1009678958","pt":1580668264208,"mc":[{"id":"1.168238840","rc":[{"batb":[[2,2.02,26.86]],"ltp":2.08,"tv":1536.61,"id":8860646},{"trd":[[1.88,24.36]],"batb":[[0,1.87,47.32],[1,1.84,160.48],[2,1.81,31.12]],"batl":[[0,1.88,1.45],[1,1.93,15.75],[2,1.94,137.19]],"ltp":1.88,"tv":2411.56,"id":8258569}],"tv":3948.17}]}
{"op":"mcm","clk":"1009679488","pt":1580668271212,"mc":[{"id":"1.168238840","rc":[{"trd":[[1.88,24.45]],"batl":[[0,1.88,1.4]],"ltp":1.88,"tv":2411.65,"id":8258569}],"tv":3948.27}]}
{"op":"mcm","clk":"1009679522","pt":1580668271623,"mc":[{"id":"1.168238840","rc":[{"batb":[[2,2.02,26.95]],"batl":[[2,2.2,2]],"ltp":2.08,"tv":1536.61,"id":8860646}]}]}
{"op":"mcm","clk":"1009680220","pt":1580668280249,"mc":[{"id":"1.168238840","rc":[{"batb":[[0,2.1,1.68],[1,2.08,22.24],[2,2.04,39.86]],"batl":[[2,2.2,2.03]],"ltp":2.08,"tv":1536.61,"id":8860646}]}]}
{"op":"mcm","clk":"1009682992","pt":1580668315175,"mc":[{"id":"1.168238840","rc":[{"trd":[[2.1,601.8],[2.12,211.12]],"batb":[[0,2.08,22.63],[1,2.04,39.86],[2,2.02,26.8]],"ltp":2.1,"tv":1540.44,"id":8860646},{"trd":[[1.88,25.85]],"batl":[[0,1.93,15.75],[1,1.94,137.19],[2,1.95,2.9]],"ltp":1.88,"tv":2413.05,"id":8258569}],"tv":3953.49}]}
{"op":"mcm","clk":"1009683039","pt":1580668315652,"mc":[{"id":"1.168238840","rc":[{"batb":[[2,2.02,26.92]],"ltp":2.1,"tv":1540.44,"id":8860646}]}]}
{"op":"mcm","clk":"1009683092","pt":1580668316306,"mc":[{"id":"1.168238840","rc":[{"batb":[[2,1.83,30.36]],"ltp":1.88,"tv":2413.05,"id":8258569}]}]}
{"op":"mcm","clk":"1009683816","pt":1580668325187,"mc":[{"id":"1.168238840","rc":[{"batb":[[2,2.02,26.39]],"batl":[[2,2.28,18.48]],"ltp":2.1,"tv":1540.44,"id":8860646}]}]}
{"op":"mcm","clk":"1009683827","pt":1580668325291,"mc":[{"id":"1.168238840","rc":[{"batb":[[2,2.02,28.63]],"batl":[[2,2.2,2.03]],"ltp":2.1,"tv":1540.44,"id":8860646}]}]}
{"op":"mcm","clk":"1009685383","pt":1580668343076,"mc":[{"id":"1.168238840","rc":[{"trd":[[2.08,412.52],[2.1,602.57]],"batb":[[0,2.08,17.76]],"batl":[[1,2.18,2.03]],"ltp":2.08,"tv":1550.17,"id":8860646}],"tv":3963.22}]}
{"op":"mcm","clk":"1009687092","pt":1580668360816,"mc":[{"id":"1.168238840","rc":[{"batb":[[0,1.85,68.64]],"ltp":1.88,"tv":2413.05,"id":8258569}]}]}
{"op":"mcm","clk":"1009687148","pt":1580668361335,"mc":[{"id":"1.168238840","rc":[{"batb":[[2,1.82,30.74]],"ltp":1.88,"tv":2413.05,"id":8258569}]}]}
{"op":"mcm","clk":"1009687257","pt":1580668362324,"mc":[{"id":"1.168238840","rc":[{"batb":[[1,2.04,64.1]],"ltp":2.08,"tv":1550.17,"id":8860646}]}]}
{"op":"mcm","clk":"1009687451","pt":1580668364214,"mc":[{"id":"1.168238840","rc":[{"batl":[[0,2.16,2.04],[1,2.2,2.03],[2,2.22,2.16]],"ltp":2.08,"tv":1550.17,"id":8860646}]}]}
{"op":"mcm","clk":"1009701087","pt":1580668509126,"mc":[{"id":"1.168238840","rc":[{"trd":[[2.08,433.74]],"batb":[[0,2.08,7.16]],"ltp":2.08,"tv":1571.38,"id":8860646}],"tv":3984.43}]}
{"op":"mcm","clk":"1009701131","pt":1580668509651,"mc":[{"id":"1.168238840","rc":[{"batb":[[2,2.02,28.46]],"ltp":2.08,"tv":1571.38,"id":8860646}]}]}
{"op":"mcm","clk":"1009701190","pt":1580668510333,"mc":[{"id":"1.168238840","rc":[{"batb":[[1,2.04,39.86]],"ltp":2.08,"tv":1571.38,"id":8860646}]}]}
{"op":"mcm","clk":"1009701562","pt":1580668514458,"mc":[{"id":"1.168238840","rc":[{"batl":[[0,2.16,9.22]],"ltp":2.08,"tv":1571.38,"id":8860646}]}]}
{"op":"mcm","clk":"1009703000","pt":1580668529978,"mc":[{"id":"1.168238840","rc":[{"trd":[[2.08,438.01]],"batb":[[0,2.08,5.02],[2,2.02,28.61]],"batl":[[2,2.22,2.07]],"ltp":2.08,"tv":1575.66,"id":8860646},{"trd":[[1.93,64.05]],"batl":[[0,1.93,13.61]],"ltp":1.93,"tv":2417.32,"id":8258569}],"tv":3992.99}]}
{"op":"mcm","clk":"1009703305","pt":1580668533397,"mc":[{"id":"1.168238840","rc":[{"batl":[[0,2.16,11.28]],"ltp":2.08,"tv":1575.66,"id":8860646}]}]}
{"op":"mcm","clk":"1009704439","pt":1580668545963,"mc":[{"id":"1.168238840","rc":[{"batb":[[2,2.02,28.52]],"batl":[[2,2.22,2.16]],"ltp":2.08,"tv":1575.66,"id":8860646},{"batl":[[0,1.93,15.75]],"ltp":1.93,"tv":2417.32,"id":8258569}]}]}
{"op":"mcm","clk":"1009706599","pt":1580668569213,"mc":[{"id":"1.168238840","rc":[{"batb":[[0,2.08,12.48]],"ltp":2.08,"tv":1575.66,"id":8860646}]}]}
{"op":"mcm","clk":"1009706642","pt":1580668569696,"mc":[{"id":"1.168238840","rc":[{"batb":[[2,2.02,28.63]],"batl":[[2,2.22,2.07]],"ltp":2.08,"tv":1575.66,"id":8860646}]}]}
{"op":"mcm","clk":"1009708074","pt":1580668585240,"mc":[{"id":"1.168238840","rc":[{"batb":[[0,1.84,160.48],[1,1.82,30.74],[2,1.81,31.12]],"ltp":1.93,"tv":2417.32,"id":8258569}]}]}
{"op":"mcm","clk":"1009708119","pt":1580668585616,"mc":[{"id":"1.168238840","rc":[{"batb":[[2,2.02,28.48]],"batl":[[2,2.22,2.16]],"ltp":2.08,"tv":1575.66,"id":8860646},{"batb":[[0,1.87,47.32],[1,1.84,160.48],[2,1.82,30.74]],"ltp":1.93,"tv":2417.32,"id":8258569}]}]}
{"op":"mcm","clk":"1009708200","pt":1580668586356,"mc":[{"id":"1.168238840","rc":[{"batb":[[2,1.83,30.36]],"ltp":1.93,"tv":2417.32,"id":8258569}]}]}
{"op":"mcm","clk":"1009708702","pt":1580668591156,"mc":[{"id":"1.168238840","rc":[{"batb":[[0,2.08,14.61],[2,2.02,26.39]],"batl":[[2,2.28,18.48]],"ltp":2.08,"tv":1575.66,"id":8860646}]}]}
{"op":"mcm","clk":"1009708730","pt":1580668591365,"mc":[{"id":"1.168238840","rc":[{"batb":[[2,2.02,28.4]],"batl":[[2,2.22,2]],"ltp":2.08,"tv":1575.66,"id":8860646}]}]}
{"op":"mcm","clk":"1009709254","pt":1580668596244,"mc":[{"id":"1.168238840","rc":[{"batl":[[0,2.14,11.39]],"ltp":2.08,"tv":1575.66,"id":8860646}]}]}
{"op":"mcm","clk":"1009709350","pt":1580668597136,"mc":[{"id":"1.168238840","rc":[{"batb":[[2,2.02,28.48]],"batl":[[1,2.18,2.03],[2,2.2,2.03]],"ltp":2.08,"tv":1575.66,"id":8860646},{"batb":[[0,1.88,2.14],[1,1.87,47.32],[2,1.84,160.48]],"ltp":1.93,"tv":2417.32,"id":8258569}]}]}
{"op":"mcm","clk":"1009720213","pt":1580668717156,"mc":[{"id":"1.168238840","rc":[{"batb":[[2,2.02,26.39]],"batl":[[2,2.28,18.48]],"ltp":2.08,"tv":1575.66,"id":8860646}]}]}
{"op":"mcm","clk":"1009720234","pt":1580668717367,"mc":[{"id":"1.168238840","rc":[{"batb":[[2,2.02,28.5]],"batl":[[2,2.2,2.03]],"ltp":2.08,"tv":1575.66,"id":8860646}]}]}
{"op":"mcm","clk":"1009722893","pt":1580668745282,"mc":[{"id":"1.168238840","rc":[{"batl":[[0,1.91,540.41],[1,1.93,18.82],[2,1.94,140.27]],"ltp":1.93,"tv":2417.32,"id":8258569}]}]}
{"op":"mcm","clk":"1009722978","pt":1580668746288,"mc":[{"id":"1.168238840","rc":[{"batb":[[2,2.02,28.63]],"ltp":2.08,"tv":1575.66,"id":8860646},{"batb":[[0,1.87,47.32],[1,1.84,160.48],[2,1.82,30.74]],"ltp":1.93,"tv":2417.32,"id":8258569}]}]}
{"op":"mcm","clk":"1009722989","pt":1580668746393,"mc":[{"id":"1.168238840","rc":[{"batb":[[0,1.87,49.46]],"ltp":1.93,"tv":2417.32,"id":8258569}]}]}
{"op":"mcm","clk":"1009723327","pt":1580668750206,"mc":[{"id":"1.168238840","rc":[{"batb":[[1,2.06,2.08],[2,2.04,39.87]],"ltp":2.08,"tv":1575.66,"id":8860646},{"batl":[[0,1.9,16],[1,1.91,540.41],[2,1.92,2.81]],"ltp":1.93,"tv":2417.32,"id":8258569}]}]}
{"op":"mcm","clk":"1009730137","pt":1580668825885,"mc":[{"id":"1.168238840","rc":[{"batb":[[0,2.08,36.68],[1,2.04,2.12],[2,2.02,28.6]],"ltp":2.08,"tv":1575.66,"id":8860646},{"trd":[[1.9,1496.08]],"batb":[[0,1.87,2.14],[1,1.85,52.46],[2,1.84,160.48]],"batl":[[0,1.91,540.42],[1,1.93,3.07],[2,1.94,140.27]],"ltp":1.9,"tv":2449.32,"id":8258569}],"tv":4024.99}]}
{"op":"mcm","clk":"1009730253","pt":1580668827187,"mc":[{"id":"1.168238840","rc":[{"batb":[[1,2.04,26.36]],"ltp":2.08,"tv":1575.66,"id":8860646}]}]}
{"op":"mcm","clk":"1009730338","pt":1580668827972,"mc":[{"id":"1.168238840","rc":[{"batl":[[0,2.16,11.39],[1,2.2,2.03],[2,2.22,2.07]],"ltp":2.08,"tv":1575.66,"id":8860646},{"batb":[[0,1.86,16.34]],"ltp":1.9,"tv":2449.32,"id":8258569}]}]}
{"op":"mcm","clk":"1009730373","pt":1580668828492,"mc":[{"id":"1.168238840","rc":[{"batb":[[1,2.04,2.12]],"ltp":2.08,"tv":1575.66,"id":8860646}]}]}
{"op":"mcm","clk":"1009730766","pt":1580668833192,"mc":[{"id":"1.168238840","rc":[{"trd":[[1.9,1496.09],[1.91,531.22]],"batl":[[0,1.91,425.74]],"ltp":1.91,"tv":2678.69,"id":8258569}],"tv":4254.36}]}
{"op":"mcm","clk":"1009730802","pt":1580668833562,"mc":[{"id":"1.168238840","rc":[{"batb":[[2,2.02,28.63]],"batl":[[2,2.22,2.16]],"ltp":2.08,"tv":1575.66,"id":8860646}]}]}
{"op":"mcm","clk":"1009730955","pt":1580668835178,"mc":[{"id":"1.168238840","rc":[{"batl":[[0,1.9,15.99],[1,1.91,425.74],[2,1.92,3.06]],"ltp":1.91,"tv":2678.69,"id":8258569}]}]}
{"op":"mcm","clk":"1009731018","pt":1580668835854,"mc":[{"id":"1.168238840","rc":[{"batb":[[1,2.06,2.08],[2,2.04,2.06]],"ltp":2.08,"tv":1575.66,"id":8860646}]}]}
{"op":"mcm","clk":"1009731620","pt":1580668842103,"mc":[{"id":"1.168238840","rc":[{"batb":[[2,2.04,2.12]],"batl":[[0,2.16,11.28],[2,2.22,2.03]],"ltp":2.08,"tv":1575.66,"id":8860646}]}]}
{"op":"mcm","clk":"1009734302","pt":1580668868917,"mc":[{"id":"1.168238840","rc":[{"batb":[[2,2.04,2]],"batl":[[2,2.22,2.16]],"ltp":2.08,"tv":1575.66,"id":8860646}]}]}
{"op":"mcm","clk":"1009741599","pt":1580668945285,"mc":[{"id":"1.168238840","rc":[{"batb":[[1,1.84,160.48],[2,1.82,30.74]],"ltp":1.91,"tv":2678.69,"id":8258569}]}]}
{"op":"mcm","clk":"1009741648","pt":1580668945655,"mc":[{"id":"1.168238840","rc":[{"batb":[[2,2.04,2.12]],"ltp":2.08,"tv":1575.66,"id":8860646},{"batb":[[0,1.87,31.22],[1,1.86,16.34],[2,1.84,160.48]],"ltp":1.91,"tv":2678.69,"id":8258569}]}]}
{"op":"mcm","clk":"1009742492","pt":1580668954247,"mc":[{"id":"1.168238840","rc":[{"batl":[[0,2.2,2.03],[1,2.22,2.16],[2,2.28,18.48]],"ltp":2.08,"tv":1575.66,"id":8860646},{"batb":[[0,1.87,47.56],[1,1.84,160.48],[2,1.82,30.74]],"ltp":1.91,"tv":2678.69,"id":8258569}]}]}
{"op":"mcm","clk":"1009742565","pt":1580668954974,"mc":[{"id":"1.168238840","rc":[{"batl":[[0,2.14,11.28],[1,2.18,2.03],[2,2.2,2]],"ltp":2.08,"tv":1575.66,"id":8860646}]}]}
{"op":"mcm","clk":"1009744422","pt":1580668972870,"mc":[{"id":"1.168238840","rc":[{"batl":[[0,2.14,11.39]],"ltp":2.08,"tv":1575.66,"id":8860646}]}]}
{"op":"mcm","clk":"1009751334","pt":1580669040048,"mc":[{"id":"1.168238840","rc":[{"batb":[[0,2.08,22.06]],"batl":[[2,2.2,2.03]],"ltp":2.08,"tv":1575.66,"id":8860646},{"batb":[[0,1.87,31.22]],"ltp":1.91,"tv":2678.69,"id":8258569}]}]}
{"op":"mcm","clk":"1009751765","pt":1580669044258,"mc":[{"id":"1.168238840","rc":[{"batb":[[0,2.08,21.58]],"ltp":2.08,"tv":1575.66,"id":8860646},{"batb":[[0,1.84,160.48],[1,1.82,30.74],[2,1.81,31.12]],"ltp":1.91,"tv":2678.69,"id":8258569}]}]}
{"op":"mcm","clk":"1009751799","pt":1580669044534,"mc":[{"id":"1.168238840","rc":[{"batb":[[2,2.04,26.36]],"ltp":2.08,"tv":1575.66,"id":8860646},{"batb":[[0,1.85,53.02],[1,1.84,160.48]],"ltp":1.91,"tv":2678.69,"id":8258569}]}]}
{"op":"mcm","clk":"1009752408","pt":1580669050256,"mc":[{"id":"1.168238840","rc":[{"batl":[[0,2.16,11.28]],"ltp":2.08,"tv":1575.66,"id":8860646}]}]}
{"op":"mcm","clk":"1009752445","pt":1580669050648,"mc":[{"id":"1.168238840","rc":[{"batb":[[2,2.04,26.34]],"batl":[[1,2.2,2.03],[2,2.22,2.07]],"ltp":2.08,"tv":1575.66,"id":8860646}]}]}
{"op":"mcm","clk":"1009762170","pt":1580669160136,"mc":[{"id":"1.168238840","rc":[{"batb":[[2,2.04,24.24]],"batl":[[0,2.16,28.08],[2,2.28,18.48]],"ltp":2.08,"tv":1575.66,"id":8860646}]}]}
{"op":"mcm","clk":"1009762203","pt":1580669160547,"mc":[{"id":"1.168238840","rc":[{"batb":[[2,2.04,2.12]],"batl":[[2,2.22,2.16]],"ltp":2.08,"tv":1575.66,"id":8860646},{"batb":[[2,1.82,30.74]],"ltp":1.91,"tv":2678.69,"id":8258569}]}]}
{"op":"mcm","clk":"1009764613","pt":1580669188257,"mc":[{"id":"1.168238840","rc":[{"batl":[[0,2.14,3.79],[1,2.16,28.08],[2,2.18,2.03]],"ltp":2.08,"tv":1575.66,"id":8860646}]}]}
{"op":"mcm","clk":"1009765064","pt":1580669193574,"mc":[{"id":"1.168238840","rc":[{"batb":[[0,1.87,31.78]],"ltp":1.91,"tv":2678.69,"id":8258569}]}]}
{"op":"mcm","clk":"1009771072","pt":1580669264222,"mc":[{"id":"1.168238840","rc":[{"batb":[[2,2.02,26.39]],"batl":[[0,2.16,28.08],[1,2.2,2.03],[2,2.22,2.16]],"ltp":2.08,"tv":1575.66,"id":8860646}]}]}
{"op":"mcm","clk":"1009771089","pt":1580669264438,"mc":[{"id":"1.168238840","rc":[{"batb":[[2,2.04,2.11]],"ltp":2.08,"tv":1575.66,"id":8860646}]}]}
{"op":"mcm","clk":"1009776389","pt":1580669321186,"mc":[{"id":"1.168238840","rc":[{"batb":[[0,2.1,15.75],[1,2.08,21.58],[2,2.06,2.08]],"ltp":2.08,"tv":1575.66,"id":8860646},{"trd":[[1.87,35.37]],"batb":[[0,1.85,35.34]],"ltp":1.87,"tv":2714.06,"id":8258569}],"tv":4289.72}]}
{"op":"mcm","clk":"1009784345","pt":1580669403061,"mc":[{"id":"1.168238840","rc":[{"batl":[[2,2.22,2]],"ltp":2.08,"tv":1575.66,"id":8860646}]}]}
{"op":"mcm","clk":"1009786470","pt":1580669423274,"mc":[{"id":"1.168238840","rc":[{"trd":[[2.16,3.8]],"batl":[[0,2.16,28.07],[2,2.22,2.07]],"ltp":2.16,"tv":1575.68,"id":8860646},{"trd":[[1.86,17.25]],"ltp":1.86,"tv":2714.07,"id":8258569}],"tv":4289.75}]}
{"op":"mcm","clk":"1009788347","pt":1580669441978,"mc":[{"id":"1.168238840","rc":[{"trd":[[2.16,6.7]],"batl":[[0,2.16,25.17],[2,2.22,2.16]],"ltp":2.16,"tv":1578.57,"id":8860646},{"trd":[[1.86,20.62]],"ltp":1.86,"tv":2717.44,"id":8258569}],"tv":4296.02}]}
{"op":"mcm","clk":"1009788660","pt":1580669445108,"mc":[{"id":"1.168238840","rc":[{"batl":[[0,2.16,22.27]],"ltp":2.16,"tv":1578.57,"id":8860646}]}]}
{"op":"mcm","clk":"1009789307","pt":1580669452216,"mc":[{"id":"1.168238840","rc":[{"batl":[[0,2.16,25.17]],"ltp":2.16,"tv":1578.57,"id":8860646}]}]}
{"op":"mcm","clk":"1009790883","pt":1580669468239,"mc":[{"id":"1.168238840","rc":[{"batl":[[2,2.28,18.48]],"ltp":2.16,"tv":1578.57,"id":8860646}]}]}
{"op":"mcm","clk":"1009790952","pt":1580669468920,"mc":[{"id":"1.168238840","rc":[{"batl":[[2,2.22,2.16]],"ltp":2.16,"tv":1578.57,"id":8860646},{"batb":[[0,1.85,35.35]],"ltp":1.86,"tv":2717.44,"id":8258569}]}]}
{"op":"mcm","clk":"1009801504","pt":1580669586852,"mc":[{"id":"1.168238840","rc":[{"batl":[[2,1.92,137.02]],"ltp":1.86,"tv":2717.44,"id":8258569}]}]}
{"op":"mcm","clk":"1009804780","pt":1580669623270,"mc":[{"id":"1.168238840","rc":[{"trd":[[1.9,1528.1],[1.91,569.38]],"batl":[[0,1.91,406.65],[1,1.92,137.02],[2,1.93,2.78]],"ltp":1.91,"tv":2787.61,"id":8258569}],"tv":4366.19}]}
{"op":"mcm","clk":"1009804894","pt":1580669624261,"mc":[{"id":"1.168238840","rc":[{"trd":[[2.08,459.45],[2.1,618.32]],"batb":[[0,2.06,36.89],[1,2.04,2.12],[2,2.02,28.56]],"ltp":2.08,"tv":1615.76,"id":8860646},{"trd":[[1.91,1884.6]],"batb":[[0,1.87,31.77],[1,1.84,160.49]],"batl":[[0,1.91,169.96],[1,1.92,133.96],[2,1.93,3.07]],"ltp":1.91,"tv":4102.83,"id":8258569}],"tv":5718.59}]}
{"op":"mcm","clk":"1009804993","pt":1580669625259,"mc":[{"id":"1.168238840","rc":[{"trd":[[1.91,2224.52],[1.92,52.15]],"batb":[[0,1.91,153.8],[1,1.87,31.77],[2,1.84,160.49]],"batl":[[0,1.92,131.26],[1,1.93,3.07],[2,1.94,2.75]],"ltp":1.92,"tv":4448.16,"id":8258569}],"tv":6063.92}]}
{"op":"mcm","clk":"1009805087","pt":1580669626250,"mc":[{"id":"1.168238840","rc":[{"batb":[[2,2.02,3.85]],"batl":[[0,2.14,2.18],[1,2.16,27.17]],"ltp":2.08,"tv":1615.76,"id":8860646},{"trd":[[1.91,2241.16]],"batb":[[0,1.91,145.48],[2,1.85,29.67]],"batl":[[1,1.94,2.75],[2,1.95,2.9]],"ltp":1.91,"tv":4464.8,"id":8258569}],"tv":6080.56}]}
{"op":"mcm","clk":"1009805354","pt":1580669629169,"mc":[{"id":"1.168238840","rc":[{"batb":[[2,2.02,3.92]],"batl":[[2,2.28,18.48]],"ltp":2.08,"tv":1615.76,"id":8860646},{"batl":[[0,1.92,135.34],[2,1.95,3.1]],"ltp":1.91,"tv":4464.8,"id":8258569}]}]}
{"op":"mcm","clk":"1009805450","pt":1580669630060,"mc":[{"id":"1.168238840","rc":[{"batl":[[0,2.16,25.17],[1,2.18,2.03],[2,2.2,2]],"ltp":2.08,"tv":1615.76,"id":8860646},{"trd":[[1.91,2371.65]],"batb":[[0,1.87,31.77],[1,1.85,29.67],[2,1.84,160.48]],"batl":[[0,1.91,19.51],[1,1.92,135.34],[2,1.93,2.64]],"ltp":1.91,"tv":4595.29,"id":8258569}],"tv":6211.05}]}
{"op":"mcm","clk":"1009805576","pt":1580669631269,"mc":[{"id":"1.168238840","rc":[{"batb":[[2,2.02,28.63]],"batl":[[0,2.14,52.01],[1,2.16,25.17],[2,2.18,2]],"ltp":2.08,"tv":1615.76,"id":8860646},{"batb":[[1,1.84,160.49],[2,1.82,30.74]],"ltp":1.91,"tv":4595.29,"id":8258569}]}]}
{"op":"mcm","clk":"1009805623","pt":1580669631677,"mc":[{"id":"1.168238840","rc":[{"batb":[[2,1.83,30.36]],"ltp":1.91,"tv":4595.29,"id":8258569}]}]}
{"op":"mcm","clk":"1009805875","pt":1580669634289,"mc":[{"id":"1.168238840","rc":[{"trd":[[2.14,104.03]],"batb":[[0,2.14,13.52],[1,2.1,2],[2,2.08,2.06]],"batl":[[0,2.16,25.17],[1,2.2,2],[2,2.22,2.16]],"ltp":2.14,"tv":1719.79,"id":8860646},{"batl":[[0,1.9,2.75],[1,1.91,22.56],[2,1.92,135.34]],"ltp":1.91,"tv":4595.29,"id":8258569}],"tv":6315.08}]}
{"op":"mcm","clk":"1009805941","pt":1580669634975,"mc":[{"id":"1.168238840","rc":[{"batb":[[2,1.81,31.12]],"ltp":1.91,"tv":4595.29,"id":8258569}]}]}
{"op":"mcm","clk":"1009806074","pt":1580669636067,"mc":[{"id":"1.168238840","rc":[{"batl":[[0,1.9,6.83],[2,1.92,131.26]],"ltp":1.91,"tv":4595.29,"id":8258569}]}]}
{"op":"mcm","clk":"1009806319","pt":1580669638898,"mc":[{"id":"1.168238840","rc":[{"trd":[[2.14,117.42]],"batb":[[0,2.06,39.03],[1,2.04,26.36],[2,2.02,26.39]],"ltp":2.14,"tv":1733.18,"id":8860646},{"trd":[[1.88,41.09]],"batl":[[0,1.9,4.08],[1,1.91,19.51],[2,1.92,134.32]],"ltp":1.88,"tv":4610.53,"id":8258569}],"tv":6343.71}]}
{"op":"mcm","clk":"1009806408","pt":1580669639683,"mc":[{"id":"1.168238840","rc":[{"batb":[[1,2.04,2.12]],"ltp":2.14,"tv":1733.18,"id":8860646},{"batb":[[2,1.82,30.74]],"ltp":1.88,"tv":4610.53,"id":8258569}]}]}
{"op":"mcm","clk":"1009806653","pt":1580669642189,"mc":[{"id":"1.168238840","rc":[{"trd":[[1.87,75.35]],"batb":[[0,1.87,11.78]],"batl":[[1,1.92,134.32],[2,1.93,2.64]],"ltp":1.87,"tv":4650.51,"id":8258569}],"tv":6383.69}]}
{"op":"mcm","clk":"1009806716","pt":1580669642803,"mc":[{"id":"1.168238840","rc":[{"batb":[[0,2.1,24.6],[1,2.06,2],[2,2.04,2.12]],"ltp":2.14,"tv":1733.18,"id":8860646},{"batb":[[0,1.85,33.04],[1,1.84,160.48]],"ltp":1.87,"tv":4650.51,"id":8258569}]}]}
{"op":"mcm","clk":"1009806856","pt":1580669644116,"mc":[{"id":"1.168238840","rc":[{"batb":[[2,2.04,26.36]],"ltp":2.14,"tv":1733.18,"id":8860646},{"batl":[[2,1.93,3.07]],"ltp":1.87,"tv":4650.51,"id":8258569}]}]}
{"op":"mcm","clk":"1009806969","pt":1580669645213,"mc":[{"id":"1.168238840","rc":[{"batb":[[0,2.1,24.47]],"ltp":2.14,"tv":1733.18,"id":8860646}]}]}
{"op":"mcm","clk":"1009807076","pt":1580669646210,"mc":[{"id":"1.168238840","rc":[{"batl":[[0,1.91,4.08],[1,1.92,131.26]],"ltp":1.87,"tv":4650.51,"id":8258569}]}]}
{"op":"mcm","clk":"1009808088","pt":1580669657130,"mc":[{"id":"1.168238840","rc":[{"batb":[[2,2.04,78.37]],"ltp":2.14,"tv":1733.18,"id":8860646}]}]}
{"op":"mcm","clk":"1009810078","pt":1580669677120,"mc":[{"id":"1.168238840","rc":[{"batb":[[2,2.04,26.36]],"ltp":2.14,"tv":1733.18,"id":8860646}]}]}
{"op":"mcm","clk":"1009810128","pt":1580669677631,"mc":[{"id":"1.168238840","rc":[{"batb":[[2,2.04,78.37]],"ltp":2.14,"tv":1733.18,"id":8860646}]}]}
{"op":"mcm","clk":"1009811713","pt":1580669694051,"mc":[{"id":"1.168238840","rc":[{"batb":[[2,2.04,78.36]],"ltp":2.14,"tv":1733.18,"id":8860646}]}]}
{"op":"mcm","clk":"1009811796","pt":1580669694939,"mc":[{"id":"1.168238840","rc":[{"trd":[[2.1,621.88]],"batb":[[0,2.1,22.69]],"ltp":2.1,"tv":1736.73,"id":8860646}],"tv":6387.25}]}
{"op":"mcm","clk":"1009811852","pt":1580669695556,"mc":[{"id":"1.168238840","rc":[{"batb":[[0,1.85,35.04]],"ltp":1.87,"tv":4650.51,"id":8258569}]}]}
{"op":"mcm","clk":"1009812282","pt":1580669700264,"mc":[{"id":"1.168238840","rc":[{"trd":[[2.16,12.26]],"batl":[[0,2.16,19.61]],"ltp":2.16,"tv":1742.3,"id":8860646},{"trd":[[1.86,27.12]],"batb":[[0,1.85,35.03]],"ltp":1.86,"tv":4657.02,"id":8258569}],"tv":6399.32}]}
{"op":"mcm","clk":"1009812375","pt":1580669701267,"mc":[{"id":"1.168238840","rc":[{"batb":[[2,2.04,78.37]],"batl":[[2,2.22,2.07]],"ltp":2.16,"tv":1742.3,"id":8860646}]}]}
{"op":"mcm","clk":"1009812644","pt":1580669703747,"mc":[{"id":"1.168238840","rc":[{"batl":[[0,2.16,16.71]],"ltp":2.16,"tv":1742.3,"id":8860646},{"batb":[[2,1.81,31.12]],"ltp":1.86,"tv":4657.02,"id":8258569}]}]}
{"op":"mcm","clk":"1009812868","pt":1580669706058,"mc":[{"id":"1.168238840","rc":[{"trd":[[2.16,14.1]],"batl":[[0,2.16,14.87],[2,2.22,2.16]],"ltp":2.16,"tv":1744.14,"id":8860646},{"trd":[[1.86,29.26]],"ltp":1.86,"tv":4659.16,"id":8258569}],"tv":6403.3}]}
{"op":"mcm","clk":"1009812965","pt":1580669707101,"mc":[{"id":"1.168238840","rc":[{"batl":[[0,2.14,2.93],[1,2.16,14.87],[2,2.18,2.03]],"ltp":2.16,"tv":1744.14,"id":8860646}]}]}
{"op":"mcm","clk":"1009813032","pt":1580669707759,"mc":[{"id":"1.168238840","rc":[{"batb":[[2,1.82,30.74]],"ltp":1.86,"tv":4659.16,"id":8258569}]}]}
{"op":"mcm","clk":"1009817622","pt":1580669759290,"mc":[{"id":"1.168238840","rc":[{"batb":[[0,2.12,6.75],[1,2.1,22.69],[2,2.06,2]],"ltp":2.16,"tv":1744.14,"id":8860646}]}]}
{"op":"mcm","clk":"1009817691","pt":1580669760017,"mc":[{"id":"1.168238840","rc":[{"batb":[[2,2.08,2.06]],"ltp":2.16,"tv":1744.14,"id":8860646},{"batl":[[1,1.92,134.07]],"ltp":1.86,"tv":4659.16,"id":8258569}]}]}
{"op":"mcm","clk":"1009817882","pt":1580669762214,"mc":[{"id":"1.168238840","rc":[{"trd":[[2.14,120.35]],"batl":[[0,2.16,14.87],[1,2.2,2.03],[2,2.22,2.16]],"ltp":2.14,"tv":1747.06,"id":8860646},{"trd":[[1.87,78.7]],"batl":[[0,1.91,4.74]],"ltp":1.87,"tv":4662.51,"id":8258569}],"tv":6409.58}]}
{"op":"mcm","clk":"1009817940","pt":1580669762837,"mc":[{"id":"1.168238840","rc":[{"batb":[[2,1.81,31.12]],"batl":[[0,1.9,4.74]],"ltp":1.87,"tv":4662.51,"id":8258569}]}]}
{"op":"mcm","clk":"1009826496","pt":1580669860739,"mc":[{"id":"1.168238840","rc":[{"batl":[[2,2.22,2]],"ltp":2.14,"tv":1747.06,"id":8860646}]}]}
{"op":"mcm","clk":"1009827655","pt":1580669874021,"mc":[{"id":"1.168238840","rc":[{"trd":[[2.16,15.41]],"batl":[[0,2.16,13.56]],"ltp":2.16,"tv":1748.38,"id":8860646},{"trd":[[1.86,30.78]],"ltp":1.86,"tv":4664.03,"id":8258569}],"tv":6412.41}]}
{"op":"mcm","clk":"1009827739","pt":1580669874955,"mc":[{"id":"1.168238840","rc":[{"batl":[[2,1.93,2.64]],"ltp":1.86,"tv":4664.03,"id":8258569}]}]}
{"op":"mcm","clk":"1009828412","pt":1580669882648,"mc":[{"id":"1.168238840","rc":[{"batl":[[2,1.93,3.07]],"ltp":1.86,"tv":4664.03,"id":8258569}]}]}
{"op":"mcm","clk":"1009833920","pt":1580669945524,"mc":[{"id":"1.168238840","rc":[{"batl":[[2,2.22,2.07]],"ltp":2.16,"tv":1748.38,"id":8860646},{"batl":[[2,1.93,2.64]],"ltp":1.86,"tv":4664.03,"id":8258569}]}]}
{"op":"mcm","clk":"1009834453","pt":1580669951244,"mc":[{"id":"1.168238840","rc":[{"batl":[[0,1.91,4.74],[1,1.92,134.57],[2,1.93,3.07]],"ltp":1.86,"tv":4664.03,"id":8258569}]}]}
{"op":"mcm","clk":"1009835010","pt":1580669957244,"mc":[{"id":"1.168238840","rc":[{"batl":[[2,2.28,18.48]],"ltp":2.16,"tv":1748.38,"id":8860646},{"batl":[[2,2.1,17.85]],"ltp":1.86,"tv":4664.03,"id":8258569}]}]}
{"op":"mcm","clk":"1009835023","pt":1580669957349,"mc":[{"id":"1.168238840","rc":[{"batl":[[2,2.22,2.16]],"ltp":2.16,"tv":1748.38,"id":8860646},{"trd":[[1.87,79.02]],"batl":[[0,1.91,4.58],[2,1.93,2.78]],"ltp":1.87,"tv":4664.35,"id":8258569}],"tv":6412.73}]}
{"op":"mcm","clk":"1009836505","pt":1580669971961,"mc":[{"id":"1.168238840","rc":[{"batl":[[0,1.92,135.07],[1,1.93,3.07],[2,2.1,17.85]],"ltp":1.87,"tv":4664.35,"id":8258569}]}]}
{"op":"mcm","clk":"1009838442","pt":1580669991194,"mc":[{"id":"1.168238840","rc":[{"trd":[[2.16,16.32]],"batl":[[0,2.16,12.65],[2,2.22,2]],"ltp":2.16,"tv":1749.28,"id":8860646},{"trd":[[1.86,31.83]],"batl":[[1,1.93,2.64]],"ltp":1.86,"tv":4665.4,"id":8258569}],"tv":6414.68}]}
{"op":"mcm","clk":"1009838629","pt":1580669992998,"mc":[{"id":"1.168238840","rc":[{"trd":[[2.16,17.63]],"batl":[[0,2.16,11.34]],"ltp":2.16,"tv":1750.59,"id":8860646},{"trd":[[1.86,33.35]],"ltp":1.86,"tv":4666.92,"id":8258569}],"tv":6417.51}]}
{"op":"mcm","clk":"1009839602","pt":1580670002117,"mc":[{"id":"1.168238840","rc":[{"trd":[[2.16,17.78]],"batl":[[0,2.16,11.19]],"ltp":2.16,"tv":1750.75,"id":8860646},{"trd":[[1.86,33.53]],"ltp":1.86,"tv":4667.1,"id":8258569}],"tv":6417.85}]}
{"op":"mcm","clk":"1009840867","pt":1580670013068,"mc":[{"id":"1.168238840","rc":[{"trd":[[2.16,18.2]],"batl":[[0,2.16,10.77]],"ltp":2.16,"tv":1751.17,"id":8860646},{"trd":[[1.86,34.02]],"ltp":1.86,"tv":4667.59,"id":8258569}],"tv":6418.76}]}
{"op":"mcm","clk":"1009841313","pt":1580670016717,"mc":[{"id":"1.168238840","rc":[{"batb":[[0,1.86,3],[1,1.85,35.03],[2,1.84,160.48]],"ltp":1.86,"tv":4667.59,"id":8258569}]}]}
{"op":"mcm","clk":"1009841649","pt":1580670019610,"mc":[{"id":"1.168238840","rc":[{"trd":[[1.86,37.2]],"batb":[[0,1.86,1.41]],"ltp":1.86,"tv":4670.77,"id":8258569}],"tv":6421.94}]}
{"op":"mcm","clk":"1009849786","pt":1580670092814,"mc":[{"id":"1.168238840","rc":[{"trd":[[2.16,28.97]],"batb":[[2,2.04,24.24]],"batl":[[0,2.28,18.48],[1,2.3,16.8],[2,2.5,12.6]],"ltp":2.16,"tv":1761.94,"id":8860646},{"trd":[[1.86,52.53]],"batb":[[0,1.85,35.03],[1,1.84,160.48],[2,1.79,31.9]],"batl":[[0,1.86,9.08],[1,1.92,131.76]],"ltp":1.86,"tv":4686.1,"id":8258569}],"tv":6448.04}]}
{"op":"mcm","clk":"1009849937","pt":1580670093825,"mc":[{"id":"1.168238840","rc":[{"batb":[[2,2.06,23.78]],"ltp":2.16,"tv":1761.94,"id":8860646}]}]}
{"op":"mcm","clk":"1009851683","pt":1580670107906,"mc":[{"id":"1.168238840","marketDefinition":{"bspMarket":false,"turnInPlayEnabled":true,"persistenceEnabled":true,"marketBaseRate":5.0,"eventId":"29681898","eventTypeId":"2","numberOfWinners":1,"bettingType":"ODDS","marketType":"MATCH_ODDS","marketTime":"2020-02-02T19:15:00.000Z","suspendTime":"2020-02-02T19:15:00.000Z","bspReconciled":false,"complete":true,"inPlay":false,"crossMatching":true,"runnersVoidable":false,"numberOfActiveRunners":2,"betDelay":0,"status":"OPEN","runners":[{"status":"ACTIVE","sortPriority":1,"id":8860646,"name":"Daniel Elahi Galan"},{"status":"ACTIVE","sortPriority":2,"id":8258569,"name":"Thai-Son Kwiatkowski"}],"regulators":["MR_INT"],"countryCode":"US","discountAllowed":true,"timezone":"UTC","openDate":"2020-02-02T19:00:00.000Z","version":3150309941,"name":"Match Odds","eventName":"Galan v Kwiatkowski"}}]}
{"op":"mcm","clk":"1009851975","pt":1580670109936,"mc":[{"id":"1.168238840","marketDefinition":{"bspMarket":false,"turnInPlayEnabled":true,"persistenceEnabled":true,"marketBaseRate":5.0,"eventId":"29681898","eventTypeId":"2","numberOfWinners":1,"bettingType":"ODDS","marketType":"MATCH_ODDS","marketTime":"2020-02-02T19:15:00.000Z","suspendTime":"2020-02-02T19:15:00.000Z","bspReconciled":false,"complete":true,"inPlay":false,"crossMatching":true,"runnersVoidable":false,"numberOfActiveRunners":2,"betDelay":0,"status":"OPEN","runners":[{"status":"ACTIVE","sortPriority":1,"id":8860646,"name":"Daniel Elahi Galan"},{"status":"ACTIVE","sortPriority":2,"id":8258569,"name":"Thai-Son Kwiatkowski"}],"regulators":["MR_INT"],"countryCode":"US","discountAllowed":true,"timezone":"UTC","openDate":"2020-02-02T19:15:00.000Z","version":3150309941,"name":"Match Odds","eventName":"Galan v Kwiatkowski"}}]}
{"op":"mcm","clk":"1009857305","pt":1580670154268,"mc":[{"id":"1.168238840","rc":[{"trd":[[1.86,70.69]],"batb":[[0,1.85,33.03]],"batl":[[0,1.92,131.76],[1,2.1,17.85],[2,2.28,18.48]],"ltp":1.86,"tv":4704.26,"id":8258569}],"tv":6466.2}]}
{"op":"mcm","clk":"1009857404","pt":1580670155264,"mc":[{"id":"1.168238840","rc":[{"batb":[[1,2.1,30.67],[2,2.04,24.24]],"ltp":2.16,"tv":1761.94,"id":8860646},{"batb":[[0,1.85,25.97],[2,1.81,31.12]],"ltp":1.86,"tv":4704.26,"id":8258569}]}]}
{"op":"mcm","clk":"1009857418","pt":1580670155372,"mc":[{"id":"1.168238840","rc":[{"trd":[[2.12,211.76],[2.14,120.78]],"batb":[[0,2.12,6.44]],"ltp":2.12,"tv":1763.01,"id":8860646},{"trd":[[1.87,79.52]],"batl":[[0,1.92,131.26]],"ltp":1.87,"tv":4704.76,"id":8258569}],"tv":6467.78}]}
{"op":"mcm","clk":"1009860694","pt":1580670183593,"mc":[{"id":"1.168238840","rc":[{"batl":[[0,2.16,2.36],[1,2.28,18.48],[2,2.3,16.8]],"ltp":2.12,"tv":1763.01,"id":8860646}]}]}
{"op":"mcm","clk":"1009861159","pt":1580670187193,"mc":[{"id":"1.168238840","rc":[{"batl":[[0,1.9,3],[1,1.92,131.26],[2,2.1,17.85]],"ltp":1.87,"tv":4704.76,"id":8258569}]}]}
{"op":"mcm","clk":"1009866218","pt":1580670230247,"mc":[{"id":"1.168238840","rc":[{"trd":[[2.12,214.04]],"batb":[[0,2.12,5.3]],"ltp":2.12,"tv":1765.29,"id":8860646}],"tv":6470.06}]}
{"op":"mcm","clk":"1009898859","pt":1580670500521,"mc":[{"id":"1.168238840","rc":[{"batl":[[0,2.28,18.48],[1,2.3,16.8],[2,2.5,12.6]],"ltp":2.12,"tv":1765.29,"id":8860646}]}]}
{"op":"mcm","clk":"1009931057","pt":1580670749217,"mc":[{"id":"1.168238840","rc":[{"batl":[[0,2.18,3.79],[1,2.28,18.48],[2,2.3,16.8]],"ltp":2.12,"tv":1765.29,"id":8860646}]}]}
{"op":"mcm","clk":"1009954682","pt":1580670933289,"mc":[{"id":"1.168238840","rc":[{"batb":[[1,2.1,53.23],[2,2.08,23.34]],"ltp":2.12,"tv":1765.29,"id":8860646},{"trd":[[1.84,182.47],[1.85,198.62]],"batb":[[0,1.84,159.7],[1,1.82,33.13],[2,1.78,32.31]],"batl":[[0,1.85,73.65],[1,1.9,3],[2,1.92,131.26]],"ltp":1.84,"tv":4904.93,"id":8258569}],"tv":6670.23}]}
{"op":"mcm","clk":"1009956648","pt":1580670949136,"mc":[{"id":"1.168238840","rc":[{"batb":[[2,2.04,24.24]],"ltp":2.12,"tv":1765.29,"id":8860646},{"trd":[[1.84,329.8]],"batb":[[0,1.84,86.03],[2,1.8,31.51]],"batl":[[0,1.9,3],[1,1.92,131.26],[2,2.1,17.85]],"ltp":1.84,"tv":5052.26,"id":8258569}],"tv":6817.56}]}
{"op":"mcm","clk":"1009961884","pt":1580670992558,"mc":[{"id":"1.168238840","rc":[{"batl":[[2,2,2.45]],"ltp":1.84,"tv":5052.26,"id":8258569}]}]}
{"op":"mcm","clk":"1009963861","pt":1580671008639,"mc":[{"id":"1.168238840","marketDefinition":{"bspMarket":false,"turnInPlayEnabled":true,"persistenceEnabled":true,"marketBaseRate":5.0,"eventId":"29681898","eventTypeId":"2","numberOfWinners":1,"bettingType":"ODDS","marketType":"MATCH_ODDS","marketTime":"2020-02-02T19:30:00.000Z","suspendTime":"2020-02-02T19:30:00.000Z","bspReconciled":false,"complete":true,"inPlay":false,"crossMatching":true,"runnersVoidable":false,"numberOfActiveRunners":2,"betDelay":0,"status":"OPEN","runners":[{"status":"ACTIVE","sortPriority":1,"id":8860646,"name":"Daniel Elahi Galan"},{"status":"ACTIVE","sortPriority":2,"id":8258569,"name":"Thai-Son Kwiatkowski"}],"regulators":["MR_INT"],"countryCode":"US","discountAllowed":true,"timezone":"UTC","openDate":"2020-02-02T19:15:00.000Z","version":3150350845,"name":"Match Odds","eventName":"Galan v Kwiatkowski"}}]}
{"op":"mcm","clk":"1009964241","pt":1580671011646,"mc":[{"id":"1.168238840","marketDefinition":{"bspMarket":false,"turnInPlayEnabled":true,"persistenceEnabled":true,"marketBaseRate":5.0,"eventId":"29681898","eventTypeId":"2","numberOfWinners":1,"bettingType":"ODDS","marketType":"MATCH_ODDS","marketTime":"2020-02-02T19:30:00.000Z","suspendTime":"2020-02-02T19:30:00.000Z","bspReconciled":false,"complete":true,"inPlay":false,"crossMatching":true,"runnersVoidable":false,"numberOfActiveRunners":2,"betDelay":0,"status":"OPEN","runners":[{"status":"ACTIVE","sortPriority":1,"id":8860646,"name":"Daniel Elahi Galan"},{"status":"ACTIVE","sortPriority":2,"id":8258569,"name":"Thai-Son Kwiatkowski"}],"regulators":["MR_INT"],"countryCode":"US","discountAllowed":true,"timezone":"UTC","openDate":"2020-02-02T19:30:00.000Z","version":3150350845,"name":"Match Odds","eventName":"Galan v Kwiatkowski"}}]}
{"op":"mcm","clk":"1009969950","pt":1580671055750,"mc":[{"id":"1.168238840","rc":[{"batb":[[1,1.81,44.6]],"ltp":1.84,"tv":5052.26,"id":8258569}]}]}
{"op":"mcm","clk":"1009987303","pt":1580671198148,"mc":[{"id":"1.168238840","rc":[{"batl":[[0,2.16,48.69],[1,2.18,3.79],[2,2.28,18.48]],"ltp":2.12,"tv":1765.29,"id":8860646},{"batb":[[1,1.82,30.74],[2,1.81,44.6]],"ltp":1.84,"tv":5052.26,"id":8258569}]}]}
{"op":"mcm","clk":"1009995399","pt":1580671267022,"mc":[{"id":"1.168238840","rc":[{"batb":[[2,2.08,2.06]],"batl":[[2,2.2,2.03]],"ltp":2.12,"tv":1765.29,"id":8860646},{"batb":[[0,1.84,88.25],[1,1.83,2.03],[2,1.82,30.74]],"batl":[[1,1.92,133.32],[2,1.93,2.07]],"ltp":1.84,"tv":5052.26,"id":8258569}]}]}
{"op":"mcm","clk":"1009996083","pt":1580671273232,"mc":[{"id":"1.168238840","rc":[{"trd":[[2.16,50.72]],"batb":[[1,2.1,42.23]],"batl":[[0,2.16,37.81]],"ltp":2.16,"tv":1787.04,"id":8860646}],"tv":6839.3}]}
{"op":"mcm","clk":"1009996096","pt":1580671273355,"mc":[{"id":"1.168238840","rc":[{"batb":[[1,1.83,36.66]],"ltp":1.84,"tv":5052.26,"id":8258569}]}]}
{"op":"mcm","clk":"1010026837","pt":1580671520159,"mc":[{"id":"1.168238840","rc":[{"batl":[[0,2.14,252.06],[1,2.16,37.81],[2,2.18,5.82]],"ltp":2.16,"tv":1787.04,"id":8860646},{"batb":[[0,1.85,2.17],[1,1.84,86.03],[2,1.83,34.63]],"ltp":1.84,"tv":5052.26,"id":8258569}]}]}
{"op":"mcm","clk":"1010026861","pt":1580671520374,"mc":[{"id":"1.168238840","rc":[{"batb":[[1,1.84,88.25]],"ltp":1.84,"tv":5052.26,"id":8258569}]}]}
{"op":"mcm","clk":"1010027726","pt":1580671527248,"mc":[{"id":"1.168238840","rc":[{"batl":[[2,2.18,2.03]],"ltp":2.16,"tv":1787.04,"id":8860646}]}]}
{"op":"mcm","clk":"1010037217","pt":1580671602183,"mc":[{"id":"1.168238840","rc":[{"trd":[[2.14,148.06]],"batb":[[1,2.1,28.49]],"batl":[[0,2.14,238.42]],"ltp":2.14,"tv":1814.31,"id":8860646},{"batb":[[0,1.85,30.62],[2,1.82,30.74]],"batl":[[2,1.93,2]],"ltp":1.84,"tv":5052.26,"id":8258569}],"tv":6866.57}]}
{"op":"mcm","clk":"1010059930","pt":1580671793172,"mc":[{"id":"1.168238840","rc":[{"batb":[[1,1.84,86.03]],"batl":[[2,2,2.45]],"ltp":1.84,"tv":5052.26,"id":8258569}]}]}
{"op":"mcm","clk":"1010059952","pt":1580671793382,"mc":[{"id":"1.168238840","rc":[{"batb":[[1,1.84,88.07]],"batl":[[2,1.93,2.07]],"ltp":1.84,"tv":5052.26,"id":8258569}]}]}
{"op":"mcm","clk":"1010066278","pt":1580671847053,"mc":[{"id":"1.168238840","rc":[{"trd":[[2.14,624.9]],"batb":[[0,2.14,1.1],[1,2.12,5.3],[2,2.1,28.49]],"batl":[[0,2.16,37.81],[1,2.18,2.03],[2,2.2,2.03]],"ltp":2.14,"tv":2291.15,"id":8860646}],"tv":7343.42}]}
{"op":"mcm","clk":"1010066321","pt":1580671847472,"mc":[{"id":"1.168238840","rc":[{"batb":[[2,1.81,31.12]],"ltp":1.84,"tv":5052.26,"id":8258569}]}]}
{"op":"mcm","clk":"1010068294","pt":1580671863560,"mc":[{"id":"1.168238840","rc":[{"batl":[[1,2.28,18.48],[2,2.3,16.8]],"ltp":2.14,"tv":2291.15,"id":8860646},{"batb":[[0,1.85,28.45],[1,1.84,86.03]],"batl":[[1,1.92,131.26],[2,2,2.45]],"ltp":1.84,"tv":5052.26,"id":8258569}]}]}
{"op":"mcm","clk":"1010070420","pt":1580671880786,"mc":[{"id":"1.168238840","rc":[{"trd":[[2.16,72.42]],"batl":[[0,2.16,16.11]],"ltp":2.16,"tv":2312.86,"id":8860646},{"trd":[[1.86,95.9]],"ltp":1.86,"tv":5077.47,"id":8258569}],"tv":7390.33}]}
{"op":"mcm","clk":"1010073708","pt":1580671908035,"mc":[{"id":"1.168238840","marketDefinition":{"bspMarket":false,"turnInPlayEnabled":true,"persistenceEnabled":true,"marketBaseRate":5.0,"eventId":"29681898","eventTypeId":"2","numberOfWinners":1,"bettingType":"ODDS","marketType":"MATCH_ODDS","marketTime":"2020-02-02T19:45:00.000Z","suspendTime":"2020-02-02T19:45:00.000Z","bspReconciled":false,"complete":true,"inPlay":false,"crossMatching":true,"runnersVoidable":false,"numberOfActiveRunners":2,"betDelay":0,"status":"OPEN","runners":[{"status":"ACTIVE","sortPriority":1,"id":8860646,"name":"Daniel Elahi Galan"},{"status":"ACTIVE","sortPriority":2,"id":8258569,"name":"Thai-Son Kwiatkowski"}],"regulators":["MR_INT"],"countryCode":"US","discountAllowed":true,"timezone":"UTC","openDate":"2020-02-02T19:30:00.000Z","version":3150384449,"name":"Match Odds","eventName":"Galan v Kwiatkowski"}}]}
{"op":"mcm","clk":"1010074096","pt":1580671911042,"mc":[{"id":"1.168238840","marketDefinition":{"bspMarket":false,"turnInPlayEnabled":true,"persistenceEnabled":true,"marketBaseRate":5.0,"eventId":"29681898","eventTypeId":"2","numberOfWinners":1,"bettingType":"ODDS","marketType":"MATCH_ODDS","marketTime":"2020-02-02T19:45:00.000Z","suspendTime":"2020-02-02T19:45:00.000Z","bspReconciled":false,"complete":true,"inPlay":false,"crossMatching":true,"runnersVoidable":false,"numberOfActiveRunners":2,"betDelay":0,"status":"OPEN","runners":[{"status":"ACTIVE","sortPriority":1,"id":8860646,"name":"Daniel Elahi Galan"},{"status":"ACTIVE","sortPriority":2,"id":8258569,"name":"Thai-Son Kwiatkowski"}],"regulators":["MR_INT"],"countryCode":"US","discountAllowed":true,"timezone":"UTC","openDate":"2020-02-02T19:45:00.000Z","version":3150384449,"name":"Match Odds","eventName":"Galan v Kwiatkowski"}}]}
{"op":"mcm","clk":"1010077480","pt":1580671940868,"mc":[{"id":"1.168238840","rc":[{"batb":[[2,1.82,280.63]],"ltp":1.86,"tv":5077.47,"id":8258569}]}]}
{"op":"mcm","clk":"1010098169","pt":1580672111972,"mc":[{"id":"1.168238840","rc":[{"trd":[[2.16,88.53]],"batl":[[0,2.28,18.48],[1,2.3,16.8],[2,2.5,12.6]],"ltp":2.16,"tv":2328.97,"id":8860646},{"trd":[[1.84,501.86],[1.85,255.52],[1.86,114.6]],"batb":[[0,1.82,280.63],[1,1.81,31.12],[2,1.8,31.51]],"ltp":1.84,"tv":5325.12,"id":8258569}],"tv":7654.09}]}
{"op":"mcm","clk":"1010098274","pt":1580672112783,"mc":[{"id":"1.168238840","rc":[{"batb":[[0,2.14,35.88],[2,2.06,23.78]],"ltp":2.16,"tv":2328.97,"id":8860646},{"batb":[[0,1.82,301.68],[1,1.8,31.51],[2,1.78,32.31]],"ltp":1.84,"tv":5325.12,"id":8258569}]}]}
{"op":"mcm","clk":"1010098352","pt":1580672113470,"mc":[{"id":"1.168238840","rc":[{"batb":[[1,1.78,32.31],[2,1.73,205.81]],"ltp":1.84,"tv":5325.12,"id":8258569}]}]}
{"op":"mcm","clk":"1010098473","pt":1580672114492,"mc":[{"id":"1.168238840","rc":[{"batb":[[2,2.08,23.34]],"ltp":2.16,"tv":2328.97,"id":8860646}]}]}
{"op":"mcm","clk":"1010100683","pt":1580672132119,"mc":[{"id":"1.168238840","rc":[{"trd":[[1.82,603.26]],"batb":[[0,1.78,32.36],[1,1.73,205.81],[2,1.72,125]],"ltp":1.82,"tv":5928.38,"id":8258569}],"tv":8257.35}]}
{"op":"mcm","clk":"1010100767","pt":1580672132711,"mc":[{"id":"1.168238840","rc":[{"batb":[[0,2.14,53.48]],"ltp":2.16,"tv":2328.97,"id":8860646},{"batb":[[0,1.79,34.95],[1,1.76,33.16],[2,1.73,205.81]],"ltp":1.82,"tv":5928.38,"id":8258569}]}]}
{"op":"mcm","clk":"1010100850","pt":1580672133403,"mc":[{"id":"1.168238840","rc":[{"batb":[[2,2.1,22.91]],"ltp":2.16,"tv":2328.97,"id":8860646}]}]}
{"op":"mcm","clk":"1010101563","pt":1580672139122,"mc":[{"id":"1.168238840","rc":[{"trd":[[1.79,69.9]],"batb":[[0,1.76,33.16],[1,1.73,205.81],[2,1.72,125]],"ltp":1.79,"tv":5998.29,"id":8258569}],"tv":8327.26}]}
{"op":"mcm","clk":"1010102215","pt":1580672144210,"mc":[{"id":"1.168238840","rc":[{"batb":[[0,2.16,67.01],[1,2.14,1.1],[2,2.12,5.3]],"ltp":2.16,"tv":2328.97,"id":8860646},{"batb":[[0,1.77,24.42],[1,1.76,33.16],[2,1.73,205.81]],"ltp":1.79,"tv":5998.29,"id":8258569}]}]}
{"op":"mcm","clk":"1010102319","pt":1580672145015,"mc":[{"id":"1.168238840","rc":[{"trd":[[1.78,47.05]],"batb":[[0,1.78,8.79],[1,1.77,24.42],[2,1.76,33.16]],"ltp":1.78,"tv":6045.34,"id":8258569}],"tv":8374.31}]}
{"op":"mcm","clk":"1010102373","pt":1580672145435,"mc":[{"id":"1.168238840","rc":[{"batb":[[2,2.12,27.8]],"ltp":2.16,"tv":2328.97,"id":8860646},{"batb":[[0,1.77,24.42],[1,1.75,33.94],[2,1.73,205.48]],"ltp":1.78,"tv":6045.34,"id":8258569}]}]}
{"op":"mcm","clk":"1010102503","pt":1580672146448,"mc":[{"id":"1.168238840","rc":[{"batb":[[1,1.76,33.16],[2,1.75,33.94]],"ltp":1.78,"tv":6045.34,"id":8258569}]}]}
{"op":"mcm","clk":"1010102935","pt":1580672149854,"mc":[{"id":"1.168238840","rc":[{"trd":[[2.28,18.48]],"batl":[[0,2.3,16.8],[1,2.5,12.6],[2,2.7,74.21]],"ltp":2.28,"tv":2347.45,"id":8860646},{"trd":[[1.78,70.73]],"ltp":1.78,"tv":6069.01,"id":8258569}],"tv":8416.47}]}
{"op":"mcm","clk":"1010103007","pt":1580672150439,"mc":[{"id":"1.168238840","rc":[{"batb":[[1,1.75,33.94],[2,1.73,205.48]],"ltp":1.78,"tv":6069.01,"id":8258569}]}]}
{"op":"mcm","clk":"1010103535","pt":1580672154815,"mc":[{"id":"1.168238840","rc":[{"trd":[[1.77,48.73]],"batb":[[0,1.75,33.94],[1,1.73,205.48],[2,1.72,125]],"ltp":1.77,"tv":6117.74,"id":8258569}],"tv":8465.2}]}
{"op":"mcm","clk":"1010103597","pt":1580672155457,"mc":[{"id":"1.168238840","rc":[{"batb":[[0,1.74,34.39]],"ltp":1.77,"tv":6117.74,"id":8258569}]}]}
{"op":"mcm","clk":"1010103770","pt":1580672156843,"mc":[{"id":"1.168238840","rc":[{"batb":[[0,2.18,63.24],[1,2.14,23.21]],"ltp":2.28,"tv":2347.45,"id":8860646},{"batb":[[0,1.75,25.65],[1,1.74,34.06],[2,1.73,205.48]],"ltp":1.77,"tv":6117.74,"id":8258569}]}]}
{"op":"mcm","clk":"1010104128","pt":1580672159567,"mc":[{"id":"1.168238840","rc":[{"batb":[[0,2.18,72.83]],"ltp":2.28,"tv":2347.45,"id":8860646}]}]}
{"op":"mcm","clk":"1010105101","pt":1580672167550,"mc":[{"id":"1.168238840","rc":[{"trd":[[2.3,1.22]],"batl":[[0,2.3,15.59]],"ltp":2.3,"tv":2348.67,"id":8860646},{"trd":[[1.76,1.59]],"ltp":1.76,"tv":6119.33,"id":8258569}],"tv":8468.01}]}
{"op":"mcm","clk":"1010113544","pt":1580672242467,"mc":[{"id":"1.168238840","rc":[{"batb":[[1,2.14,22.11]],"ltp":2.3,"tv":2348.67,"id":8860646}]}]}
{"op":"mcm","clk":"1010114319","pt":1580672250237,"mc":[{"id":"1.168238840","rc":[{"trd":[[2.3,1.66]],"batl":[[0,2.3,15.37]],"ltp":2.3,"tv":2349.11,"id":8860646}],"tv":8468.45}]}
{"op":"mcm","clk":"1010117070","pt":1580672276404,"mc":[{"id":"1.168238840","rc":[{"batb":[[1,2.14,269.13]],"ltp":2.3,"tv":2349.11,"id":8860646}]}]}
{"op":"mcm","clk":"1010118886","pt":1580672293696,"mc":[{"id":"1.168238840","rc":[{"trd":[[2.3,2.94]],"batl":[[0,2.3,14.08]],"ltp":2.3,"tv":2350.39,"id":8860646},{"trd":[[1.76,3.27]],"ltp":1.76,"tv":6121.01,"id":8258569}],"tv":8471.41}]}
{"op":"mcm","clk":"1010119718","pt":1580672300993,"mc":[{"id":"1.168238840","rc":[{"batb":[[1,2.14,22.11]],"ltp":2.3,"tv":2350.39,"id":8860646}]}]}
{"op":"mcm","clk":"1010121648","pt":1580672317597,"mc":[{"id":"1.168238840","rc":[{"batl":[[0,1.9,284.6]],"ltp":1.76,"tv":6121.01,"id":8258569}]}]}
{"op":"mcm","clk":"1010139197","pt":1580672466945,"mc":[{"id":"1.168238840","rc":[{"batb":[[1,2.14,24.14],[2,2.12,29.84]],"batl":[[1,2.34,2.02],[2,2.36,2.07]],"ltp":2.3,"tv":2350.39,"id":8860646},{"batb":[[1,1.74,36.06],[2,1.73,207.61]],"batl":[[0,1.87,2.19],[1,1.88,2.04],[2,1.9,284.6]],"ltp":1.76,"tv":6121.01,"id":8258569}]}]}
{"op":"mcm","clk":"1010142462","pt":1580672495166,"mc":[{"id":"1.168238840","rc":[{"batl":[[0,1.84,17.37],[1,1.86,2.25],[2,1.87,2.11]],"ltp":1.76,"tv":6121.01,"id":8258569}]}]}
{"op":"mcm","clk":"1010142535","pt":1580672495798,"mc":[{"id":"1.168238840","rc":[{"trd":[[1.84,535.65]],"batl":[[0,1.87,2.58],[1,1.88,2.04],[2,1.9,284.6]],"ltp":1.84,"tv":6154.81,"id":8258569}],"tv":8505.21}]}
{"op":"mcm","clk":"1010148245","pt":1580672544138,"mc":[{"id":"1.168238840","rc":[{"batl":[[2,2.36,2.02]],"ltp":2.3,"tv":2350.39,"id":8860646},{"batb":[[0,1.77,154.6],[1,1.75,25.65],[2,1.74,36.06]],"batl":[[0,1.84,149.19],[1,1.86,2.25],[2,1.87,2.02]],"ltp":1.84,"tv":6154.81,"id":8258569}]}]}
{"op":"mcm","clk":"1010148352","pt":1580672544982,"mc":[{"id":"1.168238840","rc":[{"trd":[[1.84,832.36]],"batl":[[0,1.87,2.85],[1,1.88,2.04],[2,1.9,284.6]],"ltp":1.84,"tv":6451.51,"id":8258569}],"tv":8801.91}]}
{"op":"mcm","clk":"1010153490","pt":1580672585286,"mc":[{"id":"1.168238840","rc":[{"batl":[[0,2.28,3.79],[1,2.3,14.08],[2,2.34,2.02]],"ltp":2.3,"tv":2350.39,"id":8860646}]}]}
{"op":"mcm","clk":"1010153588","pt":1580672586019,"mc":[{"id":"1.168238840","rc":[{"batb":[[2,2.12,29.82]],"batl":[[2,2.32,2.02]],"ltp":2.3,"tv":2350.39,"id":8860646}]}]}
{"op":"mcm","clk":"1010156508","pt":1580672608221,"mc":[{"id":"1.168238840","rc":[{"batl":[[0,2.24,42.39],[1,2.28,3.79],[2,2.3,14.08]],"ltp":2.3,"tv":2350.39,"id":8860646}]}]}
{"op":"mcm","clk":"1010156586","pt":1580672608801,"mc":[{"id":"1.168238840","rc":[{"batb":[[1,2.14,2.03],[2,2.12,29.84]],"batl":[[1,2.28,5.88],[2,2.3,16.13]],"ltp":2.3,"tv":2350.39,"id":8860646},{"batb":[[0,1.78,2],[1,1.77,156.71],[2,1.76,33.16]],"ltp":1.84,"tv":6451.51,"id":8258569}]}]}
{"op":"mcm","clk":"1010159744","pt":1580672634232,"mc":[{"id":"1.168238840","rc":[{"trd":[[2.24,68.77]],"batl":[[0,2.24,8.01]],"ltp":2.24,"tv":2419.16,"id":8860646}],"tv":8870.68}]}
{"op":"mcm","clk":"1010159874","pt":1580672635230,"mc":[{"id":"1.168238840","rc":[{"batb":[[0,2.14,87.62],[1,2.12,27.8],[2,2.1,2.04]],"ltp":2.24,"tv":2419.16,"id":8860646},{"batb":[[0,1.78,33.1],[2,1.75,33.94]],"batl":[[0,1.9,287.48],[1,1.91,2.05],[2,1.92,133.32]],"ltp":1.84,"tv":6451.51,"id":8258569}]}]}
{"op":"mcm","clk":"1010159925","pt":1580672635651,"mc":[{"id":"1.168238840","rc":[{"batb":[[0,2.14,65.51],[1,2.12,5.3],[2,2.1,24.95]],"ltp":2.24,"tv":2419.16,"id":8860646},{"batb":[[2,1.76,33.16]],"ltp":1.84,"tv":6451.51,"id":8258569}]}]}
{"op":"mcm","clk":"1010163481","pt":1580672663000,"mc":[{"id":"1.168238840","rc":[{"batl":[[1,2.28,2.09]],"ltp":2.24,"tv":2419.16,"id":8860646}]}]}
{"op":"mcm","clk":"1010163567","pt":1580672663584,"mc":[{"id":"1.168238840","rc":[{"batb":[[1,1.77,156.6]],"batl":[[1,1.91,2.04],[2,1.92,131.26]],"ltp":1.84,"tv":6451.51,"id":8258569}]}]}
{"op":"mcm","clk":"1010165939","pt":1580672681242,"mc":[{"id":"1.168238840","rc":[{"batl":[[0,2.22,3.79],[1,2.24,8.01],[2,2.26,2.02]],"ltp":2.24,"tv":2419.16,"id":8860646},{"batb":[[0,1.79,2],[1,1.78,33.1],[2,1.77,154.6]],"batl":[[1,1.91,2.05]],"ltp":1.84,"tv":6451.51,"id":8258569}]}]}
{"op":"mcm","clk":"1010165984","pt":1580672681505,"mc":[{"id":"1.168238840","rc":[{"batb":[[1,1.78,33.17]],"ltp":1.84,"tv":6451.51,"id":8258569}]}]}
{"op":"mcm","clk":"1010168455","pt":1580672700263,"mc":[{"id":"1.168238840","rc":[{"batl":[[1,2.26,2.02],[2,2.3,14.08]],"ltp":2.24,"tv":2419.16,"id":8860646},{"batb":[[1,1.78,31.1]],"ltp":1.84,"tv":6451.51,"id":8258569}]}]}
{"op":"mcm","clk":"1010168528","pt":1580672700748,"mc":[{"id":"1.168238840","rc":[{"batl":[[2,2.28,2.09]],"ltp":2.24,"tv":2419.16,"id":8860646},{"batb":[[1,1.78,33.17]],"batl":[[1,1.91,2.01]],"ltp":1.84,"tv":6451.51,"id":8258569}]}]}
{"op":"mcm","clk":"1010174846","pt":1580672750106,"mc":[{"id":"1.168238840","rc":[{"trd":[[2.22,7.58]],"batb":[[0,2.14,61.66]],"batl":[[0,2.26,2.02],[1,2.28,2.09],[2,2.3,14.08]],"ltp":2.22,"tv":2426.73,"id":8860646},{"batb":[[1,1.78,37.85]],"ltp":1.84,"tv":6451.51,"id":8258569}],"tv":8878.25}]}
{"op":"mcm","clk":"1010176489","pt":1580672763642,"mc":[{"id":"1.168238840","rc":[{"batb":[[2,2.1,22.91]],"batl":[[0,2.3,14.08],[1,2.5,12.6],[2,2.7,74.21]],"ltp":2.22,"tv":2426.73,"id":8860646},{"batb":[[0,1.78,35.78],[1,1.77,154.6],[2,1.76,33.16]],"batl":[[0,1.9,285.43],[1,1.92,131.26],[2,2,2.45]],"ltp":1.84,"tv":6451.51,"id":8258569}]}]}
{"op":"mcm","clk":"1010180670","pt":1580672801080,"mc":[{"id":"1.168238840","rc":[{"batb":[[0,2.16,3.79],[1,2.14,61.66],[2,2.12,5.3]],"ltp":2.22,"tv":2426.73,"id":8860646}]}]}
{"op":"mcm","clk":"1010181430","pt":1580672808353,"mc":[{"id":"1.168238840","marketDefinition":{"bspMarket":false,"turnInPlayEnabled":true,"persistenceEnabled":true,"marketBaseRate":5.0,"eventId":"29681898","eventTypeId":"2","numberOfWinners":1,"bettingType":"ODDS","marketType":"MATCH_ODDS","marketTime":"2020-02-02T20:00:00.000Z","suspendTime":"2020-02-02T20:00:00.000Z","bspReconciled":false,"complete":true,"inPlay":false,"crossMatching":true,"runnersVoidable":false,"numberOfActiveRunners":2,"betDelay":0,"status":"OPEN","runners":[{"status":"ACTIVE","sortPriority":1,"id":8860646,"name":"Daniel Elahi Galan"},{"status":"ACTIVE","sortPriority":2,"id":8258569,"name":"Thai-Son Kwiatkowski"}],"regulators":["MR_INT"],"countryCode":"US","discountAllowed":true,"timezone":"UTC","openDate":"2020-02-02T19:45:00.000Z","version":3150416832,"name":"Match Odds","eventName":"Galan v Kwiatkowski"}}]}
{"op":"mcm","clk":"1010183449","pt":1580672828399,"mc":[{"id":"1.168238840","marketDefinition":{"bspMarket":false,"turnInPlayEnabled":true,"persistenceEnabled":true,"marketBaseRate":5.0,"eventId":"29681898","eventTypeId":"2","numberOfWinners":1,"bettingType":"ODDS","marketType":"MATCH_ODDS","marketTime":"2020-02-02T20:00:00.000Z","suspendTime":"2020-02-02T20:00:00.000Z","bspReconciled":false,"complete":true,"inPlay":false,"crossMatching":true,"runnersVoidable":false,"numberOfActiveRunners":2,"betDelay":0,"status":"OPEN","runners":[{"status":"ACTIVE","sortPriority":1,"id":8860646,"name":"Daniel Elahi Galan"},{"status":"ACTIVE","sortPriority":2,"id":8258569,"name":"Thai-Son Kwiatkowski"}],"regulators":["MR_INT"],"countryCode":"US","discountAllowed":true,"timezone":"UTC","openDate":"2020-02-02T20:00:00.000Z","version":3150416832,"name":"Match Odds","eventName":"Galan v Kwiatkowski"}}]}
{"op":"mcm","clk":"1010184847","pt":1580672842490,"mc":[{"id":"1.168238840","rc":[{"batl":[[0,2.28,7.87],[1,2.3,14.08],[2,2.5,12.6]],"ltp":2.22,"tv":2426.73,"id":8860646}]}]}
{"op":"mcm","clk":"1010189098","pt":1580672888025,"mc":[{"id":"1.168238840","rc":[{"trd":[[2.28,34.22]],"batb":[[0,2.28,1.42],[1,2.16,3.79],[2,2.14,61.66]],"batl":[[0,2.3,14.08],[1,2.5,12.6],[2,2.7,74.21]],"ltp":2.28,"tv":2442.47,"id":8860646}],"tv":8893.99}]}
{"op":"mcm","clk":"1010189161","pt":1580672888755,"mc":[{"id":"1.168238840","rc":[{"batb":[[2,1.73,205.81]],"ltp":1.84,"tv":6451.51,"id":8258569}]}]}
{"op":"mcm","clk":"1010189812","pt":1580672895256,"mc":[{"id":"1.168238840","rc":[{"batl":[[0,1.86,12.99],[1,1.9,284.6],[2,1.92,131.26]],"ltp":1.84,"tv":6451.51,"id":8258569}]}]}
{"op":"mcm","clk":"1010189945","pt":1580672896468,"mc":[{"id":"1.168238840","rc":[{"batb":[[0,2.16,3.79],[1,2.14,61.66],[2,2.12,27.8]],"ltp":2.28,"tv":2442.47,"id":8860646}]}]}
{"op":"mcm","clk":"1010190077","pt":1580672897762,"mc":[{"id":"1.168238840","rc":[{"batb":[[2,1.75,33.94]],"ltp":1.84,"tv":6451.51,"id":8258569}]}]}
{"op":"mcm","clk":"1010191763","pt":1580672914844,"mc":[{"id":"1.168238840","rc":[{"trd":[[2.3,21.36]],"batl":[[0,2.3,4.87]],"ltp":2.3,"tv":2460.89,"id":8860646}],"tv":8912.41}]}
{"op":"mcm","clk":"1010196399","pt":1580672964120,"mc":[{"id":"1.168238840","rc":[{"trd":[[1.82,625.26]],"batl":[[0,1.84,1.19],[1,1.86,12.16],[2,1.9,284.6]],"ltp":1.82,"tv":6473.52,"id":8258569}],"tv":8934.41}]}
{"op":"mcm","clk":"1010198055","pt":1580672981608,"mc":[{"id":"1.168238840","rc":[{"batl":[[0,1.86,12.99],[1,1.9,284.6],[2,1.92,131.26]],"ltp":1.82,"tv":6473.52,"id":8258569}]}]}
{"op":"mcm","clk":"1010199169","pt":1580672993839,"mc":[{"id":"1.168238840","rc":[{"batb":[[0,2.18,34.39],[1,2.16,3.79]],"ltp":2.3,"tv":2460.89,"id":8860646}]}]}
{"op":"mcm","clk":"1010199250","pt":1580672994728,"mc":[{"id":"1.168238840","rc":[{"batb":[[2,1.74,34.39]],"ltp":1.82,"tv":6473.52,"id":8258569}]}]}
{"op":"mcm","clk":"1010206431","pt":1580673074118,"mc":[{"id":"1.168238840","rc":[{"trd":[[1.78,142.3]],"batb":[[0,1.77,154.6],[1,1.74,34.39],[2,1.73,205.48]],"batl":[[0,1.78,87.71],[1,1.86,12.99],[2,1.9,284.6]],"ltp":1.78,"tv":6545.09,"id":8258569}],"tv":9005.98}]}
{"op":"mcm","clk":"1010206548","pt":1580673075220,"mc":[{"id":"1.168238840","rc":[{"batb":[[0,2.18,63.1]],"ltp":2.3,"tv":2460.89,"id":8860646},{"trd":[[1.78,313.76]],"batb":[[1,1.75,37.99]],"batl":[[0,1.78,1.98]],"ltp":1.78,"tv":6716.55,"id":8258569}],"tv":9177.44}]}
{"op":"mcm","clk":"1010206608","pt":1580673075730,"mc":[{"id":"1.168238840","rc":[{"batb":[[2,2.14,22.11]],"ltp":2.3,"tv":2460.89,"id":8860646}]}]}
{"op":"mcm","clk":"1010206939","pt":1580673079832,"mc":[{"id":"1.168238840","rc":[{"trd":[[2.3,30.6]],"batl":[[0,2.5,12.85],[1,2.7,74.21],[2,95,15.9]],"ltp":2.3,"tv":2470.13,"id":8860646},{"trd":[[1.77,357.93]],"batb":[[0,1.75,37.99],[1,1.73,205.48],[2,1.72,125]],"batl":[[0,1.77,141.78],[1,1.78,1.98],[2,1.86,12.99]],"ltp":1.77,"tv":7025.75,"id":8258569}],"tv":9495.88}]}
{"op":"mcm","clk":"1010207098","pt":1580673081719,"mc":[{"id":"1.168238840","rc":[{"batb":[[0,2.2,21],[1,2.18,63.1],[2,2.16,3.79]],"ltp":2.3,"tv":2470.13,"id":8860646}]}]}
{"op":"mcm","clk":"1010207221","pt":1580673083020,"mc":[{"id":"1.168238840","rc":[{"trd":[[2.3,30.85]],"batl":[[0,2.5,12.6]],"ltp":2.3,"tv":2470.38,"id":8860646},{"trd":[[1.75,75.98],[1.76,3.6]],"batb":[[0,1.73,205.48],[1,1.72,125],[2,1.71,37.86]],"batl":[[0,1.75,208.67],[1,1.77,141.78],[2,1.78,1.98]],"ltp":1.75,"tv":7102.05,"id":8258569}],"tv":9572.44}]}
{"op":"mcm","clk":"1010207359","pt":1580673084746,"mc":[{"id":"1.168238840","rc":[{"batb":[[0,2.24,20.32],[1,2.2,21],[2,2.18,63.1]],"ltp":2.3,"tv":2470.38,"id":8860646}]}]}
{"op":"mcm","clk":"1010207486","pt":1580673086266,"mc":[{"id":"1.168238840","rc":[{"batl":[[0,1.74,246.99],[1,1.75,208.67],[2,1.77,141.78]],"ltp":1.75,"tv":7102.05,"id":8258569}]}]}
{"op":"mcm","clk":"1010207550","pt":1580673086842,"mc":[{"id":"1.168238840","rc":[{"batb":[[0,2.3,18.31],[1,2.24,20.32],[2,2.2,21]],"ltp":2.3,"tv":2470.38,"id":8860646},{"batb":[[0,1.73,231.82]],"ltp":1.75,"tv":7102.05,"id":8258569}]}]}
{"op":"mcm","clk":"1010207635","pt":1580673087729,"mc":[{"id":"1.168238840","rc":[{"batb":[[1,2.26,20.01],[2,2.24,20.32]],"ltp":2.3,"tv":2470.38,"id":8860646}]}]}
{"op":"mcm","clk":"1010208465","pt":1580673097256,"mc":[{"id":"1.168238840","rc":[{"trd":[[1.72,25.2],[1.73,931.66]],"batb":[[0,1.72,112.4],[1,1.71,37.86],[2,1.67,37.62]],"batl":[[0,1.73,28.14],[1,1.74,246.99],[2,1.75,208.67]],"ltp":1.73,"tv":8058.91,"id":8258569}],"tv":10529.3}]}
{"op":"mcm","clk":"1010208565","pt":1580673098249,"mc":[{"id":"1.168238840","rc":[{"batb":[[0,2.34,15.73]],"ltp":2.3,"tv":2470.38,"id":8860646},{"batb":[[2,1.69,55.78]],"ltp":1.73,"tv":8058.91,"id":8258569}]}]}
{"op":"mcm","clk":"1010208615","pt":1580673098768,"mc":[{"id":"1.168238840","rc":[{"batb":[[1,2.28,19.69],[2,2.26,20.01]],"ltp":2.3,"tv":2470.38,"id":8860646}]}]}
{"op":"mcm","clk":"1010209836","pt":1580673112362,"mc":[{"id":"1.168238840","rc":[{"trd":[[1.72,28.76]],"batb":[[0,1.72,110.62]],"ltp":1.72,"tv":8062.48,"id":8258569}],"tv":10532.86}]}
{"op":"mcm","clk":"1010210709","pt":1580673121882,"mc":[{"id":"1.168238840","rc":[{"trd":[[1.73,942.81]],"batl":[[0,1.73,22.56]],"ltp":1.73,"tv":8073.62,"id":8258569}],"tv":10544.01}]}
{"op":"mcm","clk":"1010210788","pt":1580673122783,"mc":[{"id":"1.168238840","rc":[{"batb":[[1,2.26,20.01],[2,2.24,20.32]],"ltp":2.3,"tv":2470.38,"id":8860646},{"trd":[[1.73,986.21]],"batl":[[0,1.74,247.85],[1,1.75,208.67],[2,1.77,141.78]],"ltp":1.73,"tv":8117.03,"id":8258569}],"tv":10587.41}]}
{"op":"mcm","clk":"1010210882","pt":1580673123885,"mc":[{"id":"1.168238840","rc":[{"batl":[[0,1.73,31.06],[1,1.74,246.99],[2,1.75,208.67]],"ltp":1.73,"tv":8117.03,"id":8258569}]}]}
{"op":"mcm","clk":"1010210964","pt":1580673124781,"mc":[{"id":"1.168238840","rc":[{"batb":[[1,2.28,19.69],[2,2.26,20.01]],"ltp":2.3,"tv":2470.38,"id":8860646}]}]}
{"op":"mcm","clk":"1010211059","pt":1580673125821,"mc":[{"id":"1.168238840","rc":[{"trd":[[1.71,25.2],[1.72,250.01]],"batb":[[0,1.71,25.26],[1,1.69,55.78],[2,1.65,38.77]],"batl":[[0,1.72,136.36],[1,1.73,31.06],[2,1.74,246.99]],"ltp":1.71,"tv":8363.47,"id":8258569}],"tv":10833.86}]}
{"op":"mcm","clk":"1010211727","pt":1580673133185,"mc":[{"id":"1.168238840","rc":[{"trd":[[1.7,1431.38],[1.71,75.73],[1.72,522.73],[1.73,1048.32]],"batb":[[0,1.69,55.78],[1,1.65,38.77],[2,1.64,59.16]],"batl":[[0,1.74,246.99],[1,1.75,208.67],[2,1.77,141.78]],"ltp":1.73,"tv":10180.21,"id":8258569}],"tv":12650.6}]}
{"op":"mcm","clk":"1010211830","pt":1580673134284,"mc":[{"id":"1.168238840","rc":[{"trd":[[1.69,25.21]],"batb":[[0,1.65,38.77],[1,1.64,59.16],[2,1.63,217.89]],"ltp":1.69,"tv":10205.42,"id":8258569}],"tv":12675.81}]}
{"op":"mcm","clk":"1010211881","pt":1580673134807,"mc":[{"id":"1.168238840","rc":[{"batb":[[0,2.34,24.75]],"ltp":2.3,"tv":2470.38,"id":8860646},{"batb":[[0,1.67,73.08],[1,1.64,98.55]],"ltp":1.69,"tv":10205.42,"id":8258569}]}]}
{"op":"mcm","clk":"1010211995","pt":1580673135810,"mc":[{"id":"1.168238840","rc":[{"batb":[[1,2.3,19.39],[2,2.28,19.69]],"ltp":2.3,"tv":2470.38,"id":8860646}]}]}
{"op":"mcm","clk":"1010212319","pt":1580673138928,"mc":[{"id":"1.168238840","rc":[{"batl":[[0,1.7,246.99],[1,1.74,246.99],[2,1.75,208.67]],"ltp":1.69,"tv":10205.42,"id":8258569}]}]}
{"op":"mcm","clk":"1010212397","pt":1580673139821,"mc":[{"id":"1.168238840","rc":[{"trd":[[1.7,1909.39]],"batb":[[1,1.64,59.16]],"batl":[[0,1.7,7.98]],"ltp":1.7,"tv":10683.43,"id":8258569}],"tv":13153.82}]}
{"op":"mcm","clk":"1010212479","pt":1580673140826,"mc":[{"id":"1.168238840","rc":[{"batb":[[1,1.64,98.55]],"ltp":1.7,"tv":10683.43,"id":8258569}]}]}
{"op":"mcm","clk":"1010212679","pt":1580673142921,"mc":[{"id":"1.168238840","rc":[{"batl":[[0,1.7,254.97]],"ltp":1.7,"tv":10683.43,"id":8258569}]}]}
{"op":"mcm","clk":"1010212751","pt":1580673143702,"mc":[{"id":"1.168238840","rc":[{"batb":[[0,2.34,43.56]],"ltp":2.3,"tv":2470.38,"id":8860646},{"batb":[[1,1.64,59.16]],"ltp":1.7,"tv":10683.43,"id":8258569}]}]}
{"op":"mcm","clk":"1010212880","pt":1580673145224,"mc":[{"id":"1.168238840","rc":[{"trd":[[2.42,5]],"ltp":2.42,"tv":2475.38,"id":8860646},{"trd":[[1.7,1916.51]],"batl":[[0,1.7,247.85]],"ltp":1.7,"tv":10690.55,"id":8258569}],"tv":13165.94}]}
{"op":"mcm","clk":"1010213050","pt":1580673147037,"mc":[{"id":"1.168238840","rc":[{"trd":[[2.42,10]],"ltp":2.42,"tv":2480.38,"id":8860646},{"trd":[[1.7,2011.39]],"batl":[[0,1.7,196.85]],"ltp":1.7,"tv":10785.43,"id":8258569}],"tv":13265.82}]}
{"op":"mcm","clk":"1010213273","pt":1580673149816,"mc":[{"id":"1.168238840","rc":[{"trd":[[1.7,2055.27]],"batl":[[0,1.7,174.91]],"ltp":1.7,"tv":10829.31,"id":8258569}],"tv":13309.7}]}
{"op":"mcm","clk":"1010214066","pt":1580673159046,"mc":[{"id":"1.168238840","rc":[{"batb":[[0,1.7,1940.54],[1,1.67,73.08],[2,1.64,59.16]],"batl":[[0,1.74,246.99],[1,1.75,208.67],[2,1.77,141.78]],"ltp":1.7,"tv":10829.31,"id":8258569}]}]}
{"op":"mcm","clk":"1010214173","pt":1580673160151,"mc":[{"id":"1.168238840","rc":[{"batb":[[0,2.34,24.75],[1,2.28,19.69],[2,2.26,20.01]],"ltp":2.42,"tv":2480.38,"id":8860646},{"trd":[[1.74,464.01]],"batb":[[2,1.66,38.19]],"batl":[[0,1.74,14.98]],"ltp":1.74,"tv":11293.32,"id":8258569}],"tv":13773.71}]}
{"op":"mcm","clk":"1010215457","pt":1580673176051,"mc":[{"id":"1.168238840","rc":[{"trd":[[2.34,0.67]],"batb":[[0,2.34,24.42]],"ltp":2.34,"tv":2481.05,"id":8860646}],"tv":13774.38}]}
{"op":"mcm","clk":"1010215546","pt":1580673177057,"mc":[{"id":"1.168238840","rc":[{"trd":[[2.34,7.96]],"batb":[[0,2.34,20.77]],"ltp":2.34,"tv":2488.35,"id":8860646},{"trd":[[1.74,491.67]],"batl":[[0,1.74,1.15]],"ltp":1.74,"tv":11320.98,"id":8258569}],"tv":13809.33}]}
{"op":"mcm","clk":"1010215610","pt":1580673177689,"mc":[{"id":"1.168238840","rc":[{"batb":[[1,1.67,78.58]],"ltp":1.74,"tv":11320.98,"id":8258569}]}]}
{"op":"mcm","clk":"1010215736","pt":1580673179163,"mc":[{"id":"1.168238840","rc":[{"batb":[[0,2.36,16.9],[1,2.34,20.77],[2,2.28,19.69]],"ltp":2.34,"tv":2488.35,"id":8860646},{"batb":[[1,1.67,54.99]],"ltp":1.74,"tv":11320.98,"id":8258569}]}]}
{"op":"mcm","clk":"1010215787","pt":1580673179747,"mc":[{"id":"1.168238840","rc":[{"trd":[[1.7,2055.33]],"batb":[[0,1.7,1940.51],[2,1.65,38.77]],"ltp":1.7,"tv":11321.04,"id":8258569}],"tv":13809.39}]}
{"op":"mcm","clk":"1010216226","pt":1580673185079,"mc":[{"id":"1.168238840","rc":[{"batb":[[0,1.71,31.99],[1,1.7,1940.51],[2,1.67,54.99]],"ltp":1.7,"tv":11321.04,"id":8258569}]}]}
{"op":"mcm","clk":"1010216471","pt":1580673188081,"mc":[{"id":"1.168238840","rc":[{"batb":[[2,1.68,33.41]],"ltp":1.7,"tv":11321.04,"id":8258569}]}]}
{"op":"mcm","clk":"1010216680","pt":1580673190895,"mc":[{"id":"1.168238840","rc":[{"trd":[[1.71,81.94]],"batb":[[0,1.71,28.89]],"ltp":1.71,"tv":11327.24,"id":8258569}],"tv":13815.6}]}
{"op":"mcm","clk":"1010217188","pt":1580673197185,"mc":[{"id":"1.168238840","rc":[{"batl":[[0,1.73,3.07],[1,1.74,1.15],[2,1.75,208.67]],"ltp":1.71,"tv":11327.24,"id":8258569}]}]}
{"op":"mcm","clk":"1010217271","pt":1580673198281,"mc":[{"id":"1.168238840","rc":[{"trd":[[1.73,1054.24]],"batl":[[0,1.73,2.11],[1,1.74,3.42]],"ltp":1.73,"tv":11333.16,"id":8258569}],"tv":13821.52}]}
{"op":"mcm","clk":"1010219440","pt":1580673226620,"mc":[{"id":"1.168238840","rc":[{"trd":[[2.36,16.9]],"batb":[[0,2.34,20.77],[1,2.28,19.69],[2,2.26,20.01]],"ltp":2.36,"tv":2505.24,"id":8860646},{"trd":[[1.73,1058.46],[1.74,521.42],[1.75,384.33]],"batl":[[0,1.75,54.46],[1,1.77,141.78],[2,1.78,1.98]],"ltp":1.75,"tv":11675.48,"id":8258569}],"tv":14180.73}]}
{"op":"mcm","clk":"1010219542","pt":1580673227815,"mc":[{"id":"1.168238840","rc":[{"batb":[[1,2.26,20.01],[2,2.12,5.3]],"ltp":2.36,"tv":2505.24,"id":8860646},{"trd":[[1.75,491.21]],"batb":[[0,1.71,49.19]],"batl":[[0,1.75,1.02]],"ltp":1.75,"tv":11782.36,"id":8258569}],"tv":14287.61}]}
{"op":"mcm","clk":"1010219988","pt":1580673234447,"mc":[{"id":"1.168238840","rc":[{"trd":[[1.71,107.14]],"batb":[[0,1.71,36.59]],"ltp":1.71,"tv":11807.56,"id":8258569}],"tv":14312.81}]}
{"op":"mcm","clk":"1010220265","pt":1580673238241,"mc":[{"id":"1.168238840","rc":[{"trd":[[2.5,12.6]],"batl":[[0,2.7,74.21],[1,95,15.9],[2,990,2.2]],"ltp":2.5,"tv":2517.85,"id":8860646},{"trd":[[1.66,472.7],[1.68,66.82],[1.7,5936.28],[1.71,180.32]],"batb":[[0,1.65,38.77],[1,1.64,59.16],[2,1.63,217.89]],"batl":[[0,1.66,965.87],[1,1.75,1.02],[2,1.77,141.78]],"ltp":1.66,"tv":16301.2,"id":8258569}],"tv":18819.06}]}
{"op":"mcm","clk":"1010220306","pt":1580673238737,"mc":[{"id":"1.168238840","rc":[{"batb":[[0,2.42,17.75],[1,2.34,35.49],[2,2.26,20.01]],"ltp":2.5,"tv":2517.85,"id":8860646},{"trd":[[1.66,529.43]],"batb":[[0,1.64,59.16],[1,1.63,217.89],[2,1.61,37.86]],"batl":[[0,1.66,937.51]],"ltp":1.66,"tv":16357.93,"id":8258569}],"tv":18875.79}]}
{"op":"mcm","clk":"1010220423","pt":1580673240669,"mc":[{"id":"1.168238840","rc":[{"batl":[[0,1.75,1.02],[1,1.77,141.78],[2,1.78,1.98]],"ltp":1.66,"tv":16357.93,"id":8258569}]}]}
{"op":"mcm","clk":"1010220520","pt":1580673242079,"mc":[{"id":"1.168238840","rc":[{"batb":[[0,2.34,35.49],[1,2.32,19.1]],"ltp":2.5,"tv":2517.85,"id":8860646},{"batb":[[2,1.62,40.66]],"ltp":1.66,"tv":16357.93,"id":8258569}]}]}
{"op":"mcm","clk":"1010220661","pt":1580673243967,"mc":[{"id":"1.168238840","rc":[{"batb":[[1,1.63,257.9]],"batl":[[0,1.74,60.65],[1,1.75,1.02],[2,1.77,141.78]],"ltp":1.66,"tv":16357.93,"id":8258569}]}]}
{"op":"mcm","clk":"1010220901","pt":1580673246995,"mc":[{"id":"1.168238840","rc":[{"batb":[[0,2.36,19.76],[1,2.34,35.49],[2,2.32,19.1]],"ltp":2.5,"tv":2517.85,"id":8860646},{"batb":[[0,1.65,61.06],[1,1.64,59.16],[2,1.63,257.9]],"ltp":1.66,"tv":16357.93,"id":8258569}]}]}
{"op":"mcm","clk":"1010220992","pt":1580673248148,"mc":[{"id":"1.168238840","rc":[{"trd":[[2.42,15]],"batb":[[0,2.36,14.7]],"ltp":2.42,"tv":2522.85,"id":8860646},{"trd":[[1.7,5943.4]],"batb":[[0,1.65,68.3]],"ltp":1.7,"tv":16365.05,"id":8258569}],"tv":18887.9}]}
{"op":"mcm","clk":"1010221064","pt":1580673249197,"mc":[{"id":"1.168238840","rc":[{"batb":[[0,1.66,34.42],[1,1.65,68.3],[2,1.64,59.16]],"ltp":1.7,"tv":16365.05,"id":8258569}]}]}
{"op":"mcm","clk":"1010221259","pt":1580673251798,"mc":[{"id":"1.168238840","rc":[{"trd":[[1.66,550.39]],"batb":[[0,1.66,23.94]],"ltp":1.66,"tv":16386.01,"id":8258569}],"tv":18908.86}]}
{"op":"mcm","clk":"1010221449","pt":1580673254305,"mc":[{"id":"1.168238840","rc":[{"batl":[[0,1.75,1.02],[1,1.77,141.78],[2,1.78,1.98]],"ltp":1.66,"tv":16386.01,"id":8258569}]}]}
{"op":"mcm","clk":"1010221574","pt":1580673255666,"mc":[{"id":"1.168238840","rc":[{"batl":[[0,1.73,71.06],[1,1.75,1.02],[2,1.77,141.78]],"ltp":1.66,"tv":16386.01,"id":8258569}]}]}
{"op":"mcm","clk":"1010221664","pt":1580673256913,"mc":[{"id":"1.168238840","rc":[{"batb":[[0,2.36,12.79]],"ltp":2.42,"tv":2522.85,"id":8860646},{"batb":[[1,1.65,71.02]],"batl":[[0,1.7,10],[1,1.73,71.06],[2,1.75,1.02]],"ltp":1.66,"tv":16386.01,"id":8258569}]}]}
{"op":"mcm","clk":"1010221889","pt":1580673259784,"mc":[{"id":"1.168238840","rc":[{"batb":[[0,2.36,31.32]],"ltp":2.42,"tv":2522.85,"id":8860646},{"batl":[[0,1.7,32.72]],"ltp":1.66,"tv":16386.01,"id":8258569}]}]}
{"op":"mcm","clk":"1010221985","pt":1580673261117,"mc":[{"id":"1.168238840","rc":[{"batb":[[0,2.36,12.79]],"ltp":2.42,"tv":2522.85,"id":8860646},{"trd":[[1.7,6006.77]],"batl":[[0,1.7,1.03],[1,1.75,1.02],[2,1.77,141.78]],"ltp":1.7,"tv":16449.39,"id":8258569}],"tv":18972.24}]}
{"op":"mcm","clk":"1010222015","pt":1580673261581,"mc":[{"id":"1.168238840","rc":[{"batl":[[0,2.7,74.6]],"ltp":2.42,"tv":2522.85,"id":8860646},{"trd":[[1.66,561.91]],"batb":[[0,1.66,18.17]],"ltp":1.66,"tv":16460.91,"id":8258569}],"tv":18983.76}]}
{"op":"mcm","clk":"1010222058","pt":1580673262309,"mc":[{"id":"1.168238840","rc":[{"batl":[[1,1.73,45.43],[2,1.75,1.02]],"ltp":1.66,"tv":16460.91,"id":8258569}]}]}
{"op":"mcm","clk":"1010222210","pt":1580673264385,"mc":[{"id":"1.168238840","rc":[{"batl":[[0,1.73,45.43],[1,1.75,1.02],[2,1.77,141.78]],"ltp":1.66,"tv":16460.91,"id":8258569}]}]}
{"op":"mcm","clk":"1010222589","pt":1580673269729,"mc":[{"id":"1.168238840","rc":[{"batl":[[0,1.75,1.02],[1,1.77,141.78],[2,1.78,1.98]],"ltp":1.66,"tv":16460.91,"id":8258569}]}]}
{"op":"mcm","clk":"1010222786","pt":1580673272720,"mc":[{"id":"1.168238840","rc":[{"batl":[[0,1.73,55.28],[1,1.75,1.02],[2,1.77,141.78]],"ltp":1.66,"tv":16460.91,"id":8258569}]}]}
{"op":"mcm","clk":"1010223061","pt":1580673276727,"mc":[{"id":"1.168238840","rc":[{"batb":[[0,1.68,1.14],[1,1.66,18.17],[2,1.65,71.02]],"ltp":1.66,"tv":16460.91,"id":8258569}]}]}
{"op":"mcm","clk":"1010223109","pt":1580673277459,"mc":[{"id":"1.168238840","rc":[{"trd":[[1.73,1167.45]],"batl":[[0,1.75,1.8],[1,1.77,141.78],[2,1.78,1.98]],"ltp":1.73,"tv":16569.91,"id":8258569}],"tv":19092.76}]}
{"op":"mcm","clk":"1010223310","pt":1580673279851,"mc":[{"id":"1.168238840","rc":[{"batb":[[1,1.66,52.59]],"ltp":1.73,"tv":16569.91,"id":8258569}]}]}
{"op":"mcm","clk":"1010223479","pt":1580673282146,"mc":[{"id":"1.168238840","rc":[{"batl":[[0,2.5,299.11],[1,2.7,74.6],[2,95,15.9]],"ltp":2.42,"tv":2522.85,"id":8860646}]}]}
{"op":"mcm","clk":"1010223664","pt":1580673284339,"mc":[{"id":"1.168238840","rc":[{"batb":[[1,1.67,33.91],[2,1.66,52.59]],"ltp":1.73,"tv":16569.91,"id":8258569}]}]}
{"op":"mcm","clk":"1010223901","pt":1580673287051,"mc":[{"id":"1.168238840","rc":[{"batl":[[2,90,1.68]],"ltp":2.42,"tv":2522.85,"id":8860646}]}]}
{"op":"mcm","clk":"1010224048","pt":1580673289264,"mc":[{"id":"1.168238840","rc":[{"batl":[[0,2.5,308.47]],"ltp":2.42,"tv":2522.85,"id":8860646}]}]}
{"op":"mcm","clk":"1010224122","pt":1580673290358,"mc":[{"id":"1.168238840","rc":[{"batb":[[1,1.67,71.77]],"ltp":1.73,"tv":16569.91,"id":8258569}]}]}
{"op":"mcm","clk":"1010224300","pt":1580673292848,"mc":[{"id":"1.168238840","rc":[{"batl":[[0,1.73,1.45],[1,1.75,1.02],[2,1.77,141.78]],"ltp":1.73,"tv":16569.91,"id":8258569}]}]}
{"op":"mcm","clk":"1010224363","pt":1580673293783,"mc":[{"id":"1.168238840","rc":[{"batl":[[2,90,2.42]],"ltp":2.42,"tv":2522.85,"id":8860646}]}]}
{"op":"mcm","clk":"1010224803","pt":1580673299975,"mc":[{"id":"1.168238840","rc":[{"batl":[[0,2.5,309.21],[2,90,1.68]],"ltp":2.42,"tv":2522.85,"id":8860646}]}]}
{"op":"mcm","clk":"1010225190","pt":1580673305669,"mc":[{"id":"1.168238840","rc":[{"batb":[[0,1.68,39],[1,1.67,33.91]],"ltp":1.73,"tv":16569.91,"id":8258569}]}]}
{"op":"mcm","clk":"1010225295","pt":1580673307174,"mc":[{"id":"1.168238840","rc":[{"trd":[[2.48,0.74]],"batb":[[0,2.38,7.46],[1,2.36,12.79],[2,2.34,35.49]],"batl":[[0,2.5,308.47]],"ltp":2.48,"tv":2523.59,"id":8860646},{"trd":[[1.67,68.92],[1.68,144.81]],"batb":[[0,1.66,52.59],[1,1.65,71.02],[2,1.64,134.05]],"batl":[[0,1.67,862.81],[1,1.73,1.45],[2,1.75,1.02]],"ltp":1.67,"tv":16716.82,"id":8258569}],"tv":19240.41}]}
{"op":"mcm","clk":"1010225366","pt":1580673308101,"mc":[{"id":"1.168238840","rc":[{"batb":[[0,2.38,18.27]],"batl":[[2,95,15.9]],"ltp":2.48,"tv":2523.59,"id":8860646},{"batb":[[2,1.64,94.66]],"ltp":1.67,"tv":16716.82,"id":8258569}]}]}
{"op":"mcm","clk":"1010225441","pt":1580673309085,"mc":[{"id":"1.168238840","rc":[{"batb":[[0,1.67,33.91],[1,1.66,52.59],[2,1.65,71.02]],"batl":[[0,1.73,1.45],[1,1.75,1.02],[2,1.77,141.78]],"ltp":1.67,"tv":16716.82,"id":8258569}]}]}
{"op":"mcm","clk":"1010225521","pt":1580673310083,"mc":[{"id":"1.168238840","rc":[{"batb":[[0,2.36,12.79],[1,2.34,35.49],[2,2.32,19.1]],"batl":[[0,2.5,299.11]],"ltp":2.48,"tv":2523.59,"id":8860646}]}]}
{"op":"mcm","clk":"1010225569","pt":1580673310699,"mc":[{"id":"1.168238840","rc":[{"batl":[[0,1.75,1.69],[1,1.77,141.78],[2,1.78,1.98]],"ltp":1.67,"tv":16716.82,"id":8258569}]}]}
{"op":"mcm","clk":"1010225686","pt":1580673312308,"mc":[{"id":"1.168238840","rc":[{"batl":[[0,1.73,34.18],[1,1.75,1.02],[2,1.77,141.78]],"ltp":1.67,"tv":16716.82,"id":8258569}]}]}
{"op":"mcm","clk":"1010226108","pt":1580673318089,"mc":[{"id":"1.168238840","rc":[{"batb":[[1,2.34,54.3]],"ltp":2.48,"tv":2523.59,"id":8860646},{"trd":[[1.67,136.74]],"batb":[[0,1.66,52.59],[1,1.65,71.02],[2,1.64,94.66]],"batl":[[0,1.67,828.97],[1,1.7,28.94],[2,1.73,34.18]],"ltp":1.67,"tv":16784.64,"id":8258569}],"tv":19308.23}]}
{"op":"mcm","clk":"1010226174","pt":1580673318881,"mc":[{"id":"1.168238840","rc":[{"batb":[[0,2.38,18.27],[1,2.36,12.79],[2,2.34,54.3]],"ltp":2.48,"tv":2523.59,"id":8860646},{"batl":[[2,1.72,9.33]],"ltp":1.67,"tv":16784.64,"id":8258569}]}]}
{"op":"mcm","clk":"1010226308","pt":1580673321012,"mc":[{"id":"1.168238840","rc":[{"batl":[[2,1.72,75.96]],"ltp":1.67,"tv":16784.64,"id":8258569}]}]}
{"op":"mcm","clk":"1010226325","pt":1580673321322,"mc":[{"id":"1.168238840","rc":[{"batl":[[2,1.72,84.21]],"ltp":1.67,"tv":16784.64,"id":8258569}]}]}
{"op":"mcm","clk":"1010226460","pt":1580673323108,"mc":[{"id":"1.168238840","rc":[{"batl":[[0,2.7,74.6],[1,95,15.9],[2,990,2.2]],"ltp":2.48,"tv":2523.59,"id":8860646},{"batl":[[0,1.7,28.94],[1,1.72,75.55],[2,1.75,1.02]],"ltp":1.67,"tv":16784.64,"id":8258569}]}]}
{"op":"mcm","clk":"1010226516","pt":1580673323889,"mc":[{"id":"1.168238840","rc":[{"batb":[[0,2.36,31.32],[1,2.34,54.3],[2,2.32,19.1]],"ltp":2.48,"tv":2523.59,"id":8860646}]}]}
{"op":"mcm","clk":"1010226609","pt":1580673324988,"mc":[{"id":"1.168238840","rc":[{"batl":[[1,1.72,8.93]],"ltp":1.67,"tv":16784.64,"id":8258569}]}]}
{"op":"mcm","clk":"1010226669","pt":1580673325811,"mc":[{"id":"1.168238840","rc":[{"batb":[[0,2.36,12.79],[1,2.34,35.49]],"ltp":2.48,"tv":2523.59,"id":8860646},{"trd":[[1.7,6062.33]],"batl":[[0,1.7,68.57]],"ltp":1.7,"tv":16840.2,"id":8258569}],"tv":19363.79}]}
{"op":"mcm","clk":"1010226742","pt":1580673326799,"mc":[{"id":"1.168238840","rc":[{"batb":[[0,2.36,31.32]],"ltp":2.48,"tv":2523.59,"id":8860646}]}]}
{"op":"mcm","clk":"1010226832","pt":1580673328118,"mc":[{"id":"1.168238840","rc":[{"batl":[[0,1.7,1.16]],"ltp":1.7,"tv":16840.2,"id":8258569}]}]}
{"op":"mcm","clk":"1010226884","pt":1580673328805,"mc":[{"id":"1.168238840","rc":[{"batb":[[0,2.36,12.79],[1,2.34,54.3]],"ltp":2.48,"tv":2523.59,"id":8860646},{"batl":[[1,1.72,75.55]],"ltp":1.7,"tv":16840.2,"id":8258569}]}]}
{"op":"mcm","clk":"1010227031","pt":1580673331128,"mc":[{"id":"1.168238840","rc":[{"trd":[[1.66,667.09]],"batb":[[0,1.65,71.02],[1,1.64,94.66],[2,1.63,257.9]],"batl":[[0,1.66,777.1],[1,1.7,1.16],[2,1.72,75.55]],"ltp":1.66,"tv":16945.38,"id":8258569}],"tv":19468.97}]}
{"op":"mcm","clk":"1010227085","pt":1580673331804,"mc":[{"id":"1.168238840","rc":[{"batb":[[0,2.4,18.01],[1,2.36,12.79],[2,2.34,54.3]],"ltp":2.48,"tv":2523.59,"id":8860646},{"trd":[[1.65,25.21],[1.66,668.94]],"batb":[[0,1.65,58.42],[2,1.63,217.89]],"batl":[[0,1.66,776.17],[2,1.72,86.21]],"ltp":1.66,"tv":16972.43,"id":8258569}],"tv":19496.02}]}
{"op":"mcm","clk":"1010227184","pt":1580673333008,"mc":[{"id":"1.168238840","rc":[{"batb":[[0,2.42,44.49],[1,2.4,18.01],[2,2.34,18.81]],"ltp":2.48,"tv":2523.59,"id":8860646},{"trd":[[1.66,754.79]],"batb":[[0,1.65,69.89],[1,1.64,126.28]],"batl":[[0,1.66,733.25]],"ltp":1.66,"tv":17058.28,"id":8258569}],"tv":19581.87}]}
{"op":"mcm","clk":"1010227270","pt":1580673334237,"mc":[{"id":"1.168238840","rc":[{"batl":[[0,1.7,119.93],[1,1.72,19.59],[2,1.75,1.02]],"ltp":1.66,"tv":17058.28,"id":8258569}]}]}
{"op":"mcm","clk":"1010227321","pt":1580673334813,"mc":[{"id":"1.168238840","rc":[{"batb":[[1,2.36,18.53]],"ltp":2.48,"tv":2523.59,"id":8860646},{"batl":[[1,1.72,8.93]],"ltp":1.66,"tv":17058.28,"id":8258569}]}]}
{"op":"mcm","clk":"1010227428","pt":1580673336219,"mc":[{"id":"1.168238840","rc":[{"trd":[[1.66,832.59]],"batb":[[0,1.64,126.28],[1,1.63,217.89],[2,1.61,79.18]],"batl":[[0,1.66,119.12],[1,1.7,119.93],[2,1.75,1.69]],"ltp":1.66,"tv":17136.09,"id":8258569}],"tv":19659.68}]}
{"op":"mcm","clk":"1010227480","pt":1580673336842,"mc":[{"id":"1.168238840","rc":[{"batb":[[0,2.42,62.24]],"ltp":2.48,"tv":2523.59,"id":8860646},{"batb":[[2,1.61,37.86]],"batl":[[2,1.72,11.58]],"ltp":1.66,"tv":17136.09,"id":8258569}]}]}
{"op":"mcm","clk":"1010227827","pt":1580673341529,"mc":[{"id":"1.168238840","rc":[{"trd":[[1.66,901.42]],"batl":[[0,1.66,84.7]],"ltp":1.66,"tv":17204.92,"id":8258569}],"tv":19728.51}]}
{"op":"mcm","clk":"1010227958","pt":1580673342929,"mc":[{"id":"1.168238840","rc":[{"batb":[[0,2.42,44.49],[1,2.38,18.27],[2,2.36,18.53]],"ltp":2.48,"tv":2523.59,"id":8860646},{"trd":[[1.64,3.76],[1.66,1068.21]],"batb":[[0,1.64,124.4]],"batl":[[0,1.66,1.31],[1,1.7,165.36],[2,1.75,1.69]],"ltp":1.66,"tv":17375.46,"id":8258569}],"tv":19899.05}]}
{"op":"mcm","clk":"1010228058","pt":1580673344120,"mc":[{"id":"1.168238840","rc":[{"trd":[[1.65,40.88]],"batl":[[0,1.66,1.73]],"ltp":1.65,"tv":17391.14,"id":8258569}],"tv":19914.73}]}
{"op":"mcm","clk":"1010228111","pt":1580673344859,"mc":[{"id":"1.168238840","rc":[{"trd":[[2.5,13.47],[2.52,0.27]],"batl":[[0,2.5,112.44],[1,2.7,74.21],[2,95,15.9]],"ltp":2.5,"tv":2524.73,"id":8860646},{"trd":[[1.64,74.44],[1.65,41.3],[1.66,1069.52]],"batb":[[0,1.64,89.06]],"batl":[[0,1.7,165.36],[1,1.75,1.69],[2,1.77,141.78]],"ltp":1.66,"tv":17463.54,"id":8258569}],"tv":19988.28}]}
{"op":"mcm","clk":"1010228217","pt":1580673345833,"mc":[{"id":"1.168238840","rc":[{"batb":[[1,2.36,18.53],[2,2.34,18.81]],"ltp":2.5,"tv":2524.73,"id":8860646}]}]}
{"op":"mcm","clk":"1010228299","pt":1580673346826,"mc":[{"id":"1.168238840","rc":[{"batb":[[2,1.62,40.66]],"ltp":1.66,"tv":17463.54,"id":8258569}]}]}
{"op":"mcm","clk":"1010228635","pt":1580673351855,"mc":[{"id":"1.168238840","rc":[{"batb":[[0,1.67,56.79],[1,1.64,89.06],[2,1.63,217.89]],"ltp":1.66,"tv":17463.54,"id":8258569}]}]}
{"op":"mcm","clk":"1010228718","pt":1580673352835,"mc":[{"id":"1.168238840","rc":[{"batb":[[1,2.34,18.81],[2,2.32,19.1]],"ltp":2.5,"tv":2524.73,"id":8860646}]}]}
{"op":"mcm","clk":"1010228900","pt":1580673355340,"mc":[{"id":"1.168238840","rc":[{"batb":[[1,1.64,89.44]],"ltp":1.66,"tv":17463.54,"id":8258569}]}]}
{"op":"mcm","clk":"1010229074","pt":1580673357568,"mc":[{"id":"1.168238840","rc":[{"batl":[[1,1.75,184.58]],"ltp":1.66,"tv":17463.54,"id":8258569}]}]}
{"op":"mcm","clk":"1010229203","pt":1580673359285,"mc":[{"id":"1.168238840","rc":[{"trd":[[1.7,6390.11]],"batl":[[0,1.7,24.19],[1,1.75,1.69]],"ltp":1.7,"tv":17791.32,"id":8258569}],"tv":20316.06}]}
{"op":"mcm","clk":"1010229250","pt":1580673359855,"mc":[{"id":"1.168238840","rc":[{"trd":[[1.67,141.16]],"batb":[[0,1.67,54.58]],"ltp":1.67,"tv":17795.74,"id":8258569}],"tv":20320.48}]}
{"op":"mcm","clk":"1010229296","pt":1580673360640,"mc":[{"id":"1.168238840","rc":[{"batb":[[0,1.67,88.49]],"ltp":1.67,"tv":17795.74,"id":8258569}]}]}
{"op":"mcm","clk":"1010229458","pt":1580673362771,"mc":[{"id":"1.168238840","rc":[{"trd":[[1.7,6394.17]],"batb":[[1,1.64,124.94]],"batl":[[0,1.7,22.16]],"ltp":1.7,"tv":17799.8,"id":8258569}],"tv":20324.54}]}
{"op":"mcm","clk":"1010229535","pt":1580673363865,"mc":[{"id":"1.168238840","rc":[{"batl":[[0,1.75,1.69],[1,1.77,141.78],[2,1.78,1.98]],"ltp":1.7,"tv":17799.8,"id":8258569}]}]}
{"op":"mcm","clk":"1010229590","pt":1580673364700,"mc":[{"id":"1.168238840","rc":[{"batl":[[0,1.7,23.51],[1,1.75,1.69],[2,1.77,141.78]],"ltp":1.7,"tv":17799.8,"id":8258569}]}]}
{"op":"mcm","clk":"1010229992","pt":1580673368603,"mc":[{"id":"1.168238840","rc":[{"trd":[[1.7,6439.88]],"batl":[[0,1.72,1.33],[1,1.75,1.02]],"ltp":1.7,"tv":17845.51,"id":8258569}],"tv":20370.24}]}
{"op":"mcm","clk":"1010230329","pt":1580673372697,"mc":[{"id":"1.168238840","rc":[{"batb":[[1,1.66,34.79],[2,1.64,124.56]],"ltp":1.7,"tv":17845.51,"id":8258569}]}]}
{"op":"mcm","clk":"1010230427","pt":1580673374160,"mc":[{"id":"1.168238840","rc":[{"batb":[[0,2.34,18.81],[1,2.32,19.1],[2,2.3,19.39]],"batl":[[1,2.7,74.6]],"ltp":2.5,"tv":2524.73,"id":8860646},{"trd":[[1.67,170.98]],"batb":[[0,1.67,73.58]],"ltp":1.67,"tv":17875.33,"id":8258569}],"tv":20400.07}]}
{"op":"mcm","clk":"1010230469","pt":1580673374975,"mc":[{"id":"1.168238840","rc":[{"batb":[[0,2.36,65.36]],"ltp":2.5,"tv":2524.73,"id":8860646},{"batb":[[2,1.65,15.07]],"ltp":1.67,"tv":17875.33,"id":8258569}]}]}
{"op":"mcm","clk":"1010230756","pt":1580673379286,"mc":[{"id":"1.168238840","rc":[{"batl":[[1,1.73,22.72],[2,1.75,1.02]],"ltp":1.67,"tv":17875.33,"id":8258569}]}]}
{"op":"mcm","clk":"1010230814","pt":1580673380172,"mc":[{"id":"1.168238840","rc":[{"trd":[[2.5,125.92]],"batb":[[0,2.42,17.75],[1,2.36,65.36],[2,2.32,19.1]],"batl":[[0,2.7,74.6],[1,95,15.9],[2,990,2.2]],"ltp":2.5,"tv":2637.17,"id":8860646},{"trd":[[1.66,1308.44],[1.67,318.15]],"batb":[[0,1.65,15.07],[1,1.64,124.56],[2,1.63,217.89]],"batl":[[0,1.66,455.77],[1,1.72,1.33],[2,1.73,22.72]],"ltp":1.66,"tv":18261.42,"id":8258569}],"tv":20898.6}]}
{"op":"mcm","clk":"1010230957","pt":1580673382105,"mc":[{"id":"1.168238840","rc":[{"trd":[[1.66,1377.27]],"batl":[[0,1.72,1.33],[1,1.73,22.72],[2,1.75,1.02]],"ltp":1.66,"tv":18330.25,"id":8258569}],"tv":20967.43}]}
{"op":"mcm","clk":"1010231043","pt":1580673383200,"mc":[{"id":"1.168238840","rc":[{"batb":[[0,2.36,65.36],[1,2.34,18.81]],"ltp":2.5,"tv":2637.17,"id":8860646},{"batl":[[0,1.71,100.59],[1,1.73,23.39]],"ltp":1.66,"tv":18330.25,"id":8258569}]}]}
{"op":"mcm","clk":"1010231105","pt":1580673383881,"mc":[{"id":"1.168238840","rc":[{"batb":[[0,2.36,83.89]],"ltp":2.5,"tv":2637.17,"id":8860646}]}]}
{"op":"mcm","clk":"1010231150","pt":1580673384583,"mc":[{"id":"1.168238840","rc":[{"trd":[[1.71,379.12]],"batl":[[0,1.71,1.19]],"ltp":1.71,"tv":18529.06,"id":8258569}],"tv":21166.23}]}
{"op":"mcm","clk":"1010231244","pt":1580673386183,"mc":[{"id":"1.168238840","rc":[{"batb":[[0,2.36,65.36]],"ltp":2.5,"tv":2637.17,"id":8860646},{"batb":[[0,1.65,50.02]],"ltp":1.71,"tv":18529.06,"id":8258569}]}]}
{"op":"mcm","clk":"1010231304","pt":1580673386894,"mc":[{"id":"1.168238840","rc":[{"batb":[[1,2.32,19.1],[2,2.3,19.39]],"ltp":2.5,"tv":2637.17,"id":8860646},{"batb":[[0,1.65,119.91],[2,1.63,257.9]],"ltp":1.71,"tv":18529.06,"id":8258569}]}]}
{"op":"mcm","clk":"1010231529","pt":1580673390208,"mc":[{"id":"1.168238840","rc":[{"batl":[[0,2.54,308.46],[1,2.7,74.6],[2,95,15.9]],"ltp":2.5,"tv":2637.17,"id":8860646}]}]}
{"op":"mcm","clk":"1010231808","pt":1580673393527,"mc":[{"id":"1.168238840","rc":[{"batb":[[0,1.65,174.8]],"batl":[[0,1.73,23.39],[1,1.75,1.02],[2,1.77,141.78]],"ltp":1.71,"tv":18529.06,"id":8258569}]}]}
{"op":"mcm","clk":"1010231995","pt":1580673396033,"mc":[{"id":"1.168238840","rc":[{"trd":[[2.54,78.51]],"batl":[[0,2.54,229.95]],"ltp":2.54,"tv":2715.68,"id":8860646},{"trd":[[1.64,445.15],[1.65,390.88]],"batb":[[0,1.63,257.9],[1,1.61,79.18],[2,1.59,38.51]],"ltp":1.64,"tv":19249.35,"id":8258569}],"tv":21965.03}]}
{"op":"mcm","clk":"1010232058","pt":1580673397120,"mc":[{"id":"1.168238840","rc":[{"batb":[[1,2.34,18.81],[2,2.32,19.1]],"ltp":2.54,"tv":2715.68,"id":8860646}]}]}
{"op":"mcm","clk":"1010232124","pt":1580673398106,"mc":[{"id":"1.168238840","rc":[{"batl":[[0,1.7,192.62],[1,1.73,23.39],[2,1.75,1.02]],"ltp":1.64,"tv":19249.35,"id":8258569}]}]}
{"op":"mcm","clk":"1010232178","pt":1580673398826,"mc":[{"id":"1.168238840","rc":[{"batb":[[0,2.38,18.27],[1,2.36,65.36],[2,2.34,18.81]],"ltp":2.54,"tv":2715.68,"id":8860646},{"batb":[[0,1.63,217.89]],"batl":[[0,1.7,194.38]],"ltp":1.64,"tv":19249.35,"id":8258569}]}]}
{"op":"mcm","clk":"1010232431","pt":1580673402833,"mc":[{"id":"1.168238840","rc":[{"batb":[[0,2.44,44.13],[1,2.38,18.27]],"ltp":2.54,"tv":2715.68,"id":8860646},{"batb":[[1,1.62,50.28],[2,1.61,79.18]],"ltp":1.64,"tv":19249.35,"id":8258569}]}]}
{"op":"mcm","clk":"1010232498","pt":1580673403620,"mc":[{"id":"1.168238840","rc":[{"trd":[[1.7,6825.75]],"batl":[[0,1.7,1.45]],"ltp":1.7,"tv":19635.23,"id":8258569}],"tv":22350.91}]}
{"op":"mcm","clk":"1010232620","pt":1580673405222,"mc":[{"id":"1.168238840","rc":[{"batb":[[0,1.65,69.89],[1,1.63,217.89],[2,1.62,50.28]],"ltp":1.7,"tv":19635.23,"id":8258569}]}]}
{"op":"mcm","clk":"1010232656","pt":1580673405627,"mc":[{"id":"1.168238840","rc":[{"batb":[[0,1.65,139.78]],"ltp":1.7,"tv":19635.23,"id":8258569}]}]}
{"op":"mcm","clk":"1010232899","pt":1580673409144,"mc":[{"id":"1.168238840","rc":[{"batb":[[2,1.62,1513.06]],"batl":[[0,1.69,1.77],[1,1.7,1.45],[2,1.73,23.39]],"ltp":1.7,"tv":19635.23,"id":8258569}]}]}
{"op":"mcm","clk":"1010233483","pt":1580673418043,"mc":[{"id":"1.168238840","rc":[{"batl":[[0,1.69,55.35]],"ltp":1.7,"tv":19635.23,"id":8258569}]}]}
{"op":"mcm","clk":"1010233562","pt":1580673419241,"mc":[{"id":"1.168238840","rc":[{"trd":[[2.44,1.96]],"batb":[[0,2.44,42.17]],"ltp":2.44,"tv":2717.64,"id":8860646},{"trd":[[1.69,135.91],[1.7,6831.45]],"batb":[[2,1.62,1515.98]],"batl":[[0,1.73,23.39],[1,1.74,162.8],[2,1.75,1.02]],"ltp":1.7,"tv":19751.63,"id":8258569}],"tv":22469.27}]}
{"op":"mcm","clk":"1010233622","pt":1580673420053,"mc":[{"id":"1.168238840","rc":[{"batb":[[0,1.66,1.77],[1,1.65,139.78],[2,1.63,326.07]],"ltp":1.7,"tv":19751.63,"id":8258569}]}]}
{"op":"mcm","clk":"1010233692","pt":1580673421043,"mc":[{"id":"1.168238840","rc":[{"batb":[[0,1.66,3.54]],"ltp":1.7,"tv":19751.63,"id":8258569}]}]}
{"op":"mcm","clk":"1010233788","pt":1580673422437,"mc":[{"id":"1.168238840","rc":[{"batb":[[0,2.46,81.5],[1,2.44,42.17],[2,2.38,18.27]],"ltp":2.44,"tv":2717.64,"id":8860646}]}]}
{"op":"mcm","clk":"1010234556","pt":1580673433059,"mc":[{"id":"1.168238840","rc":[{"batb":[[1,1.65,203.11]],"ltp":1.7,"tv":19751.63,"id":8258569}]}]}
{"op":"mcm","clk":"1010234597","pt":1580673433670,"mc":[{"id":"1.168238840","rc":[{"batl":[[1,2.7,74.21]],"ltp":2.44,"tv":2717.64,"id":8860646}]}]}
{"op":"mcm","clk":"1010234663","pt":1580673434564,"mc":[{"id":"1.168238840","rc":[{"trd":[[2.46,161.24]],"batb":[[0,2.44,43.05],[1,2.38,18.27],[2,2.34,18.81]],"ltp":2.46,"tv":2878.87,"id":8860646}],"tv":22630.51}]}
{"op":"mcm","clk":"1010235034","pt":1580673439474,"mc":[{"id":"1.168238840","rc":[{"batb":[[0,2.44,42.17]],"batl":[[0,2.7,74.21],[1,95,15.9],[2,990,2.2]],"ltp":2.46,"tv":2878.87,"id":8860646}]}]}
{"op":"mcm","clk":"1010235228","pt":1580673442153,"mc":[{"id":"1.168238840","rc":[{"trd":[[2.52,0.7]],"ltp":2.52,"tv":2879.3,"id":8860646},{"trd":[[1.66,1377.92]],"batb":[[0,1.66,2.89]],"ltp":1.66,"tv":19752.28,"id":8258569}],"tv":22631.59}]}
{"op":"mcm","clk":"1010235370","pt":1580673444379,"mc":[{"id":"1.168238840","rc":[{"trd":[[2.52,0.71]],"ltp":2.52,"tv":2879.31,"id":8860646},{"trd":[[1.66,1377.94]],"batb":[[0,1.66,2.87]],"ltp":1.66,"tv":19752.29,"id":8258569}],"tv":22631.61}]}
{"op":"mcm","clk":"1010235492","pt":1580673446079,"mc":[{"id":"1.168238840","rc":[{"trd":[[2.34,149.21],[2.36,33.55],[2.38,37.02],[2.44,86.3]],"batb":[[0,2.32,19.1],[1,2.3,19.39],[2,2.26,20.01]],"ltp":2.34,"tv":3158.56,"id":8860646},{"trd":[[1.72,523.4],[1.73,1190.17],[1.74,660.77]],"batl":[[0,1.74,23.45],[1,1.75,1.02],[2,1.77,141.78]],"ltp":1.74,"tv":19915.03,"id":8258569}],"tv":23073.6}]}
{"op":"mcm","clk":"1010235556","pt":1580673446893,"mc":[{"id":"1.168238840","rc":[{"batb":[[2,1.63,366.08]],"ltp":1.74,"tv":19915.03,"id":8258569}]}]}
{"op":"mcm","clk":"1010235604","pt":1580673447575,"mc":[{"id":"1.168238840","rc":[{"batb":[[0,2.36,40.8],[1,2.32,19.1],[2,2.3,19.39]],"ltp":2.34,"tv":3158.56,"id":8860646},{"batb":[[0,1.66,53.49]],"ltp":1.74,"tv":19915.03,"id":8258569}]}]}
{"op":"mcm","clk":"1010235719","pt":1580673449076,"mc":[{"id":"1.168238840","rc":[{"batb":[[0,1.67,23.53],[1,1.66,53.49],[2,1.65,203.11]],"batl":[[0,1.72,1.77],[1,1.74,23.45],[2,1.75,1.02]],"ltp":1.74,"tv":19915.03,"id":8258569}]}]}
{"op":"mcm","clk":"1010235794","pt":1580673450210,"mc":[{"id":"1.168238840","rc":[{"trd":[[2.36,110.64],[2.38,38.3]],"batb":[[0,2.32,24.14],[1,2.3,19.39],[2,2.26,20.01]],"ltp":2.36,"tv":3236.94,"id":8860646},{"trd":[[1.72,525.17]],"batb":[[0,1.67,112.64],[1,1.66,2.87]],"batl":[[0,1.74,23.45],[1,1.75,1.02],[2,1.77,141.78]],"ltp":1.72,"tv":19916.8,"id":8258569}],"tv":23153.74}]}
{"op":"mcm","clk":"1010235880","pt":1580673451201,"mc":[{"id":"1.168238840","rc":[{"batb":[[0,1.68,1.77],[1,1.67,112.64],[2,1.66,37.29]],"ltp":1.72,"tv":19916.8,"id":8258569}]}]}
{"op":"mcm","clk":"1010236132","pt":1580673455216,"mc":[{"id":"1.168238840","rc":[{"batb":[[0,1.68,4.64],[2,1.66,34.42]],"ltp":1.72,"tv":19916.8,"id":8258569}]}]}
{"op":"mcm","clk":"1010236245","pt":1580673456715,"mc":[{"id":"1.168238840","rc":[{"batb":[[0,1.68,28.03]],"ltp":1.72,"tv":19916.8,"id":8258569}]}]}
{"op":"mcm","clk":"1010236691","pt":1580673462909,"mc":[{"id":"1.168238840","rc":[{"batb":[[2,1.65,263.39]],"ltp":1.72,"tv":19916.8,"id":8258569}]}]}
{"op":"mcm","clk":"1010236858","pt":1580673465213,"mc":[{"id":"1.168238840","rc":[{"batl":[[0,1.74,23.9]],"ltp":1.72,"tv":19916.8,"id":8258569}]}]}
{"op":"mcm","clk":"1010236890","pt":1580673465624,"mc":[{"id":"1.168238840","rc":[{"trd":[[1.73,1191.07],[1.74,705.69]],"batl":[[0,1.75,2.01],[1,1.77,141.78],[2,1.78,1.98]],"ltp":1.74,"tv":19962.62,"id":8258569}],"tv":23199.56}]}
{"op":"mcm","clk":"1010236999","pt":1580673466935,"mc":[{"id":"1.168238840","rc":[{"trd":[[2.48,15.74]],"batb":[[1,2.28,19.69]],"ltp":2.48,"tv":3251.94,"id":8860646},{"trd":[[1.68,166.95]],"batb":[[0,1.68,5.89]],"ltp":1.68,"tv":19984.76,"id":8258569}],"tv":23236.7}]}
{"op":"mcm","clk":"1010237213","pt":1580673469510,"mc":[{"id":"1.168238840","rc":[{"batl":[[0,1.75,24.73]],"ltp":1.68,"tv":19984.76,"id":8258569}]}]}
{"op":"mcm","clk":"1010237336","pt":1580673471012,"mc":[{"id":"1.168238840","rc":[{"batl":[[0,1.73,1.77],[1,1.75,24.73],[2,1.77,141.78]],"ltp":1.68,"tv":19984.76,"id":8258569}]}]}
{"op":"mcm","clk":"1010237495","pt":1580673473028,"mc":[{"id":"1.168238840","rc":[{"batl":[[0,1.73,3.54]],"ltp":1.68,"tv":19984.76,"id":8258569}]}]}
{"op":"mcm","clk":"1010237996","pt":1580673479760,"mc":[{"id":"1.168238840","rc":[{"batl":[[0,2.42,6.4],[1,2.7,74.21],[2,95,15.9]],"ltp":2.48,"tv":3251.94,"id":8860646}]}]}
{"op":"mcm","clk":"1010238120","pt":1580673481161,"mc":[{"id":"1.168238840","rc":[{"batb":[[0,1.68,28.16]],"ltp":1.68,"tv":19984.76,"id":8258569}]}]}
{"op":"mcm","clk":"1010238156","pt":1580673481625,"mc":[{"id":"1.168238840","rc":[{"trd":[[1.73,1197.04]],"batl":[[0,1.74,1.54],[1,1.75,23.73]],"ltp":1.73,"tv":19990.74,"id":8258569}],"tv":23242.68}]}
{"op":"mcm","clk":"1010238245","pt":1580673482624,"mc":[{"id":"1.168238840","rc":[{"trd":[[1.73,1198.14]],"batb":[[0,1.68,28.27]],"batl":[[0,1.75,2.01],[1,1.77,141.78],[2,1.78,1.98]],"ltp":1.73,"tv":19991.83,"id":8258569}],"tv":23243.77}]}
{"op":"mcm","clk":"1010238352","pt":1580673483772,"mc":[{"id":"1.168238840","rc":[{"batb":[[0,1.71,1.88],[1,1.7,5.82],[2,1.68,28.16]],"ltp":1.73,"tv":19991.83,"id":8258569}]}]}
{"op":"mcm","clk":"1010238538","pt":1580673486059,"mc":[{"id":"1.168238840","rc":[{"batb":[[1,1.68,28.16],[2,1.67,112.64]],"ltp":1.73,"tv":19991.83,"id":8258569}]}]}
{"op":"mcm","clk":"1010238606","pt":1580673486852,"mc":[{"id":"1.168238840","rc":[{"batb":[[0,1.71,7.67]],"ltp":1.73,"tv":19991.83,"id":8258569}]}]}
{"op":"mcm","clk":"1010238719","pt":1580673488150,"mc":[{"id":"1.168238840","rc":[{"trd":[[1.71,393.03],[1.73,1198.36]],"batb":[[0,1.68,28.77],[1,1.67,112.64],[2,1.65,263.39]],"ltp":1.71,"tv":20005.97,"id":8258569}],"tv":23257.91}]}
{"op":"mcm","clk":"1010238748","pt":1580673488463,"mc":[{"id":"1.168238840","rc":[{"batb":[[0,1.67,113.24],[1,1.65,263.39],[2,1.64,39.39]],"ltp":1.71,"tv":20005.97,"id":8258569}]}]}
{"op":"mcm","clk":"1010238939","pt":1580673490545,"mc":[{"id":"1.168238840","rc":[{"batb":[[0,1.71,2.37],[1,1.67,112.64],[2,1.65,263.39]],"ltp":1.71,"tv":20005.97,"id":8258569}]}]}
{"op":"mcm","clk":"1010239073","pt":1580673492155,"mc":[{"id":"1.168238840","rc":[{"batl":[[0,1.75,24.73]],"ltp":1.71,"tv":20005.97,"id":8258569}]}]}
{"op":"mcm","clk":"1010239161","pt":1580673492985,"mc":[{"id":"1.168238840","rc":[{"batl":[[0,2.7,74.21],[1,95,15.9],[2,990,2.2]],"ltp":2.48,"tv":3251.94,"id":8860646}]}]}
{"op":"mcm","clk":"1010239281","pt":1580673494492,"mc":[{"id":"1.168238840","rc":[{"batb":[[1,1.68,33.41],[2,1.67,112.64]],"ltp":1.71,"tv":20005.97,"id":8258569}]}]}
{"op":"mcm","clk":"1010239618","pt":1580673497985,"mc":[{"id":"1.168238840","rc":[{"batb":[[0,1.7,2.37]],"ltp":1.71,"tv":20005.97,"id":8258569}]}]}
{"op":"mcm","clk":"1010239680","pt":1580673498714,"mc":[{"id":"1.168238840","rc":[{"trd":[[1.74,707.67],[1.75,537.09]],"batl":[[0,1.77,142.58],[1,1.78,1.98],[2,1.9,3.83]],"ltp":1.75,"tv":20053.83,"id":8258569}],"tv":23305.77}]}
{"op":"mcm","clk":"1010239971","pt":1580673501975,"mc":[{"id":"1.168238840","rc":[{"batb":[[0,1.7,24.94]],"ltp":1.75,"tv":20053.83,"id":8258569}]}]}
{"op":"mcm","clk":"1010240086","pt":1580673503285,"mc":[{"id":"1.168238840","rc":[{"batb":[[0,2.3,35.38],[1,2.24,20.32],[2,2.12,5.3]],"ltp":2.48,"tv":3251.94,"id":8860646},{"batb":[[0,1.71,30.73],[1,1.7,24.94],[2,1.68,33.41]],"batl":[[0,1.74,1.77],[1,1.77,142.58],[2,1.78,1.98]],"ltp":1.75,"tv":20053.83,"id":8258569}]}]}
{"op":"mcm","clk":"1010240229","pt":1580673504891,"mc":[{"id":"1.168238840","rc":[{"batb":[[0,1.72,22.91],[1,1.71,30.73],[2,1.7,24.94]],"ltp":1.75,"tv":20053.83,"id":8258569}]}]}
{"op":"mcm","clk":"1010240304","pt":1580673505872,"mc":[{"id":"1.168238840","rc":[{"batb":[[2,1.7,1.77]],"ltp":1.75,"tv":20053.83,"id":8258569}]}]}
{"op":"mcm","clk":"1010240398","pt":1580673507113,"mc":[{"id":"1.168238840","rc":[{"batl":[[1,1.77,141.78]],"ltp":1.75,"tv":20053.83,"id":8258569}]}]}
{"op":"mcm","clk":"1010240492","pt":1580673508097,"mc":[{"id":"1.168238840","rc":[{"batl":[[0,1.76,1.77]],"ltp":1.75,"tv":20053.83,"id":8258569}]}]}
{"op":"mcm","clk":"1010240837","pt":1580673512506,"mc":[{"id":"1.168238840","rc":[{"trd":[[2.3,33.26]],"batb":[[0,2.3,34.18]],"ltp":2.3,"tv":3254.34,"id":8860646}],"tv":23308.17}]}
{"op":"mcm","clk":"1010241183","pt":1580673516902,"mc":[{"id":"1.168238840","rc":[{"batb":[[2,1.7,34.22]],"ltp":1.75,"tv":20053.83,"id":8258569}]}]}
{"op":"mcm","clk":"1010241270","pt":1580673517904,"mc":[{"id":"1.168238840","rc":[{"trd":[[2.3,101.1]],"batb":[[0,2.24,20.58],[1,2.12,5.3],[2,1.96,78.87]],"ltp":2.3,"tv":3322.18,"id":8860646},{"batb":[[2,1.7,1.77]],"ltp":1.75,"tv":20053.83,"id":8258569}],"tv":23376.01}]}
{"op":"mcm","clk":"1010241382","pt":1580673519189,"mc":[{"id":"1.168238840","rc":[{"batb":[[0,2.26,25.01],[1,2.24,20.32],[2,2.12,5.3]],"ltp":2.3,"tv":3322.18,"id":8860646},{"trd":[[1.72,540.31],[1.76,7.14]],"batb":[[0,1.73,48.12],[1,1.72,15.33]],"batl":[[0,1.77,141.78],[1,1.78,1.98],[2,1.9,3.83]],"ltp":1.76,"tv":20072.51,"id":8258569}],"tv":23394.7}]}
{"op":"mcm","clk":"1010241441","pt":1580673519912,"mc":[{"id":"1.168238840","rc":[{"batb":[[1,2.22,20.66]],"ltp":2.3,"tv":3322.18,"id":8860646},{"batb":[[0,1.73,49.89],[2,1.68,70.48]],"ltp":1.76,"tv":20072.51,"id":8258569}]}]}
{"op":"mcm","clk":"1010241518","pt":1580673520902,"mc":[{"id":"1.168238840","rc":[{"batb":[[0,1.74,15.15],[1,1.73,49.89],[2,1.72,15.33]],"ltp":1.76,"tv":20072.51,"id":8258569}]}]}
{"op":"mcm","clk":"1010241565","pt":1580673521412,"mc":[{"id":"1.168238840","rc":[{"batb":[[2,1.69,36.53]],"ltp":1.76,"tv":20072.51,"id":8258569}]}]}
{"op":"mcm","clk":"1010241762","pt":1580673523911,"mc":[{"id":"1.168238840","rc":[{"trd":[[1.74,712.88]],"batb":[[0,1.74,12.55]],"ltp":1.74,"tv":20077.73,"id":8258569}],"tv":23399.91}]}
{"op":"mcm","clk":"1010241961","pt":1580673526535,"mc":[{"id":"1.168238840","rc":[{"batb":[[1,1.73,48.12],[2,1.71,1.77]],"ltp":1.74,"tv":20077.73,"id":8258569}]}]}
{"op":"mcm","clk":"1010242232","pt":1580673530024,"mc":[{"id":"1.168238840","rc":[{"batb":[[2,1.69,36.53]],"ltp":1.74,"tv":20077.73,"id":8258569}]}]}
{"op":"mcm","clk":"1010242255","pt":1580673530323,"mc":[{"id":"1.168238840","rc":[{"batb":[[2,1.7,3.73]],"ltp":1.74,"tv":20077.73,"id":8258569}]}]}
{"op":"mcm","clk":"1010242719","pt":1580673535733,"mc":[{"id":"1.168238840","rc":[{"trd":[[1.74,715.96],[1.77,639.41]],"batb":[[0,1.74,11.01]],"batl":[[0,1.77,1.04]],"ltp":1.77,"tv":20362.28,"id":8258569}],"tv":23684.47}]}
{"op":"mcm","clk":"1010242828","pt":1580673536927,"mc":[{"id":"1.168238840","rc":[{"batb":[[1,2.2,21]],"ltp":2.3,"tv":3322.18,"id":8860646}]}]}
{"op":"mcm","clk":"1010242898","pt":1580673537954,"mc":[{"id":"1.168238840","rc":[{"batb":[[2,1.7,39.74]],"ltp":1.77,"tv":20362.28,"id":8258569}]}]}
{"op":"mcm","clk":"1010242971","pt":1580673538940,"mc":[{"id":"1.168238840","rc":[{"batb":[[0,1.75,10.95],[1,1.74,11.01],[2,1.73,48.12]],"ltp":1.77,"tv":20362.28,"id":8258569}]}]}
{"op":"mcm","clk":"1010243110","pt":1580673540855,"mc":[{"id":"1.168238840","rc":[{"batb":[[0,1.76,10.89]],"ltp":1.77,"tv":20362.28,"id":8258569}]}]}
{"op":"mcm","clk":"1010243237","pt":1580673542754,"mc":[{"id":"1.168238840","rc":[{"batb":[[0,1.74,11.01],[1,1.73,48.12],[2,1.7,39.74]],"ltp":1.77,"tv":20362.28,"id":8258569}]}]}
{"op":"mcm","clk":"1010243282","pt":1580673543374,"mc":[{"id":"1.168238840","rc":[{"trd":[[1.77,641.49]],"batb":[[0,1.77,9.79],[1,1.74,11.01],[2,1.73,48.12]],"batl":[[0,1.78,1.98],[1,1.9,3.83],[2,1.92,131.26]],"ltp":1.77,"tv":20364.36,"id":8258569}],"tv":23686.54}]}
{"op":"mcm","clk":"1010243399","pt":1580673544778,"mc":[{"id":"1.168238840","rc":[{"batb":[[0,1.74,11.01],[1,1.73,48.12],[2,1.7,39.74]],"ltp":1.77,"tv":20364.36,"id":8258569}]}]}
{"op":"mcm","clk":"1010243450","pt":1580673545347,"mc":[{"id":"1.168238840","rc":[{"trd":[[1.78,317.71]],"batb":[[0,1.78,7.76],[1,1.74,11.01],[2,1.73,48.12]],"batl":[[0,1.9,3.83],[1,1.92,131.26],[2,1.98,136.3]],"ltp":1.78,"tv":20368.31,"id":8258569}],"tv":23690.5}]}
{"op":"mcm","clk":"1010243558","pt":1580673546751,"mc":[{"id":"1.168238840","rc":[{"batb":[[0,1.74,11.01],[1,1.73,48.12],[2,1.7,39.74]],"ltp":1.78,"tv":20368.31,"id":8258569}]}]}
{"op":"mcm","clk":"1010243626","pt":1580673547676,"mc":[{"id":"1.168238840","rc":[{"batl":[[0,1.84,1.28],[1,1.9,3],[2,1.92,131.26]],"ltp":1.78,"tv":20368.31,"id":8258569}]}]}
{"op":"mcm","clk":"1010243823","pt":1580673550268,"mc":[{"id":"1.168238840","rc":[{"batb":[[0,1.75,3.62],[1,1.74,11.01],[2,1.73,48.12]],"ltp":1.78,"tv":20368.31,"id":8258569}]}]}
{"op":"mcm","clk":"1010245219","pt":1580673569116,"mc":[{"id":"1.168238840","rc":[{"batl":[[0,2.5,5],[1,2.7,74.21],[2,95,15.9]],"ltp":2.3,"tv":3322.18,"id":8860646}]}]}
{"op":"mcm","clk":"1010245289","pt":1580673570098,"mc":[{"id":"1.168238840","rc":[{"trd":[[2.26,49.24],[2.28,34.57],[2.34,151.92]],"batb":[[0,2.34,17.29]],"ltp":2.34,"tv":3374.48,"id":8860646},{"trd":[[1.75,540.72],[1.77,641.94]],"batb":[[0,1.74,11.01],[1,1.73,48.12],[2,1.7,36.01]],"batl":[[0,1.9,3.83],[1,1.92,131.26],[2,2,93.31]],"ltp":1.75,"tv":20372.38,"id":8258569}],"tv":23746.87}]}
{"op":"mcm","clk":"1010245374","pt":1580673571190,"mc":[{"id":"1.168238840","rc":[{"trd":[[2.34,169.21]],"batb":[[0,2.22,24.83],[1,2.18,21.36]],"ltp":2.34,"tv":3391.77,"id":8860646},{"trd":[[1.75,563.84]],"batb":[[1,1.7,36.01],[2,1.69,36.53]],"ltp":1.75,"tv":20395.51,"id":8258569}],"tv":23787.28}]}
{"op":"mcm","clk":"1010245438","pt":1580673572019,"mc":[{"id":"1.168238840","rc":[{"batb":[[0,2.22,42.83],[1,2.2,21],[2,2.18,21.36]],"ltp":2.34,"tv":3391.77,"id":8860646},{"batb":[[1,1.71,84.34],[2,1.7,36.01]],"ltp":1.75,"tv":20395.51,"id":8258569}]}]}
{"op":"mcm","clk":"1010245494","pt":1580673572799,"mc":[{"id":"1.168238840","rc":[{"batb":[[0,1.71,84.34],[1,1.7,36.01],[2,1.69,36.53]],"ltp":1.75,"tv":20395.51,"id":8258569}]}]}
{"op":"mcm","clk":"1010245585","pt":1580673574228,"mc":[{"id":"1.168238840","rc":[{"batb":[[0,1.72,31.55],[1,1.71,84.34],[2,1.7,36.01]],"ltp":1.75,"tv":20395.51,"id":8258569}]}]}
{"op":"mcm","clk":"1010245901","pt":1580673578929,"mc":[{"id":"1.168238840","rc":[{"batl":[[0,2.38,20],[1,2.5,5],[2,2.7,74.21]],"ltp":2.34,"tv":3391.77,"id":8860646}]}]}
{"op":"mcm","clk":"1010246496","pt":1580673586828,"mc":[{"id":"1.168238840","rc":[{"trd":[[2.22,8.05]],"batb":[[0,2.22,42.6]],"ltp":2.22,"tv":3392.24,"id":8860646}],"tv":23787.75}]}
{"op":"mcm","clk":"1010246559","pt":1580673587738,"mc":[{"id":"1.168238840","rc":[{"trd":[[2.22,92.01]],"batb":[[0,2.2,21.62],[1,2.18,21.36],[2,2.12,5.3]],"ltp":2.22,"tv":3476.2,"id":8860646}],"tv":23871.72}]}
{"op":"mcm","clk":"1010246643","pt":1580673588928,"mc":[{"id":"1.168238840","rc":[{"batb":[[0,2.12,5.91],[1,2.08,23.34],[2,1.96,78.87]],"ltp":2.22,"tv":3476.2,"id":8860646},{"batb":[[0,1.72,66.56]],"ltp":1.75,"tv":20395.51,"id":8258569}]}]}
{"op":"mcm","clk":"1010246729","pt":1580673590028,"mc":[{"id":"1.168238840","rc":[{"batb":[[0,2.16,252.53],[1,2.14,65.26],[2,2.12,5.3]],"ltp":2.22,"tv":3476.2,"id":8860646},{"batb":[[0,1.75,69.17],[1,1.72,66.56]],"ltp":1.75,"tv":20395.51,"id":8258569}]}]}
{"op":"mcm","clk":"1010246810","pt":1580673590970,"mc":[{"id":"1.168238840","rc":[{"batb":[[1,2.14,87.37]],"ltp":2.22,"tv":3476.2,"id":8860646}]}]}
{"op":"mcm","clk":"1010246892","pt":1580673591952,"mc":[{"id":"1.168238840","rc":[{"batb":[[0,1.76,7.84],[1,1.75,69.17],[2,1.74,34.06]],"ltp":1.75,"tv":20395.51,"id":8258569}]}]}
{"op":"mcm","clk":"1010247047","pt":1580673594034,"mc":[{"id":"1.168238840","rc":[{"batl":[[0,2.5,5],[1,2.7,74.21],[2,95,15.9]],"ltp":2.22,"tv":3476.2,"id":8860646}]}]}
{"op":"mcm","clk":"1010247129","pt":1580673595076,"mc":[{"id":"1.168238840","rc":[{"batl":[[0,2.3,20],[1,2.5,5],[2,2.7,74.21]],"ltp":2.22,"tv":3476.2,"id":8860646},{"batb":[[0,1.76,27.78]],"ltp":1.75,"tv":20395.51,"id":8258569}]}]}
{"op":"mcm","clk":"1010247263","pt":1580673596848,"mc":[{"id":"1.168238840","rc":[{"batb":[[1,1.75,102.78]],"ltp":1.75,"tv":20395.51,"id":8258569}]}]}
{"op":"mcm","clk":"1010248042","pt":1580673606062,"mc":[{"id":"1.168238840","rc":[{"batb":[[2,1.74,64.76]],"ltp":1.75,"tv":20395.51,"id":8258569}]}]}
{"op":"mcm","clk":"1010248123","pt":1580673607071,"mc":[{"id":"1.168238840","rc":[{"batb":[[2,1.74,34.06]],"ltp":1.75,"tv":20395.51,"id":8258569}]}]}
{"op":"mcm","clk":"1010248564","pt":1580673611413,"mc":[{"id":"1.168238840","rc":[{"batl":[[0,2.28,15],[1,2.3,20],[2,2.5,5]],"ltp":2.22,"tv":3476.2,"id":8860646}]}]}
{"op":"mcm","clk":"1010248758","pt":1580673613903,"mc":[{"id":"1.168238840","rc":[{"batb":[[1,2.14,65.26],[2,2.12,27.8]],"ltp":2.22,"tv":3476.2,"id":8860646},{"batb":[[0,1.79,7.72],[1,1.76,27.78],[2,1.75,102.78]],"ltp":1.75,"tv":20395.51,"id":8258569}]}]}
{"op":"mcm","clk":"1010248849","pt":1580673614906,"mc":[{"id":"1.168238840","rc":[{"batb":[[1,1.76,60.94]],"ltp":1.75,"tv":20395.51,"id":8258569}]}]}
{"op":"mcm","clk":"1010249173","pt":1580673619022,"mc":[{"id":"1.168238840","rc":[{"batl":[[0,1.86,152.28],[1,1.9,3],[2,1.92,131.26]],"ltp":1.75,"tv":20395.51,"id":8258569}]}]}
{"op":"mcm","clk":"1010249242","pt":1580673619913,"mc":[{"id":"1.168238840","rc":[{"batb":[[1,1.76,27.78]],"ltp":1.75,"tv":20395.51,"id":8258569}]}]}
{"op":"mcm","clk":"1010249483","pt":1580673623440,"mc":[{"id":"1.168238840","rc":[{"trd":[[1.79,71.99]],"batb":[[0,1.79,6.67]],"ltp":1.79,"tv":20397.59,"id":8258569}],"tv":23873.8}]}
{"op":"mcm","clk":"1010249782","pt":1580673627034,"mc":[{"id":"1.168238840","rc":[{"batb":[[0,2.14,65.26],[1,2.12,27.8],[2,2.08,23.34]],"ltp":2.22,"tv":3476.2,"id":8860646},{"batl":[[0,1.84,297.36],[1,1.86,151.45],[2,1.9,3]],"ltp":1.79,"tv":20397.59,"id":8258569}]}]}
{"op":"mcm","clk":"1010250104","pt":1580673631019,"mc":[{"id":"1.168238840","rc":[{"batb":[[0,2.2,24.9]],"ltp":2.22,"tv":3476.2,"id":8860646},{"trd":[[1.84,1268.36]],"batb":[[1,1.77,43.72],[2,1.76,27.78]],"batl":[[0,1.86,151.45],[1,1.9,3],[2,1.92,131.26]],"ltp":1.84,"tv":20833.6,"id":8258569}],"tv":24309.8}]}
{"op":"mcm","clk":"1010250268","pt":1580673633258,"mc":[{"id":"1.168238840","rc":[{"batb":[[1,2.14,27.41],[2,2.12,22.51]],"ltp":2.22,"tv":3476.2,"id":8860646}]}]}
{"op":"mcm","clk":"1010250671","pt":1580673638533,"mc":[{"id":"1.168238840","rc":[{"batl":[[0,1.86,151.8]],"ltp":1.84,"tv":20833.6,"id":8258569}]}]}
{"op":"mcm","clk":"1010250822","pt":1580673640455,"mc":[{"id":"1.168238840","rc":[{"batb":[[0,1.8,2.23],[1,1.79,6.67],[2,1.77,43.72]],"ltp":1.84,"tv":20833.6,"id":8258569}]}]}
{"op":"mcm","clk":"1010251091","pt":1580673643564,"mc":[{"id":"1.168238840","rc":[{"batl":[[1,2.5,5],[2,2.7,74.21]],"ltp":2.22,"tv":3476.2,"id":8860646}]}]}
{"op":"mcm","clk":"1010251234","pt":1580673645277,"mc":[{"id":"1.168238840","rc":[{"batl":[[0,1.9,3.36],[1,1.92,131.26],[2,2,2.45]],"ltp":1.84,"tv":20833.6,"id":8258569}]}]}
{"op":"mcm","clk":"1010251329","pt":1580673646167,"mc":[{"id":"1.168238840","rc":[{"trd":[[2.2,48]],"batb":[[0,2.16,250.19]],"ltp":2.2,"tv":3524.2,"id":8860646},{"batl":[[0,1.89,151.8],[1,1.9,3],[2,1.92,131.26]],"ltp":1.84,"tv":20833.6,"id":8258569}],"tv":24357.8}]}
{"op":"mcm","clk":"1010251423","pt":1580673647261,"mc":[{"id":"1.168238840","rc":[{"batb":[[0,2.16,249.28],[1,2.14,5.3]],"ltp":2.2,"tv":3524.2,"id":8860646},{"batb":[[2,1.76,60.94]],"ltp":1.84,"tv":20833.6,"id":8258569}]}]}
{"op":"mcm","clk":"1010251438","pt":1580673647369,"mc":[{"id":"1.168238840","rc":[{"batb":[[1,2.14,46.33]],"ltp":2.2,"tv":3524.2,"id":8860646},{"batb":[[1,1.79,55.27]],"ltp":1.84,"tv":20833.6,"id":8258569}]}]}
{"op":"mcm","clk":"1010251589","pt":1580673649070,"mc":[{"id":"1.168238840","rc":[{"batb":[[1,1.79,48.6]],"ltp":1.84,"tv":20833.6,"id":8258569}]}]}
{"op":"mcm","clk":"1010251938","pt":1580673653583,"mc":[{"id":"1.168238840","rc":[{"batb":[[0,1.8,8.86]],"ltp":1.84,"tv":20833.6,"id":8258569}]}]}
{"op":"mcm","clk":"1010253062","pt":1580673668012,"mc":[{"id":"1.168238840","rc":[{"trd":[[2.16,134.99],[2.2,48.29]],"batb":[[0,2.14,46.33],[1,2.12,22.51],[2,2.08,23.34]],"ltp":2.16,"tv":3570.96,"id":8860646},{"trd":[[1.82,625.62]],"batl":[[0,1.87,2.23],[1,1.89,151.45],[2,1.9,3]],"ltp":1.82,"tv":20833.95,"id":8258569}],"tv":24404.91}]}
{"op":"mcm","clk":"1010253131","pt":1580673668629,"mc":[{"id":"1.168238840","rc":[{"batb":[[0,2.16,249.28],[1,2.14,46.33],[2,2.12,22.51]],"ltp":2.16,"tv":3570.96,"id":8860646}]}]}
{"op":"mcm","clk":"1010253908","pt":1580673678021,"mc":[{"id":"1.168238840","rc":[{"batb":[[0,2.18,54.89],[1,2.16,249.28],[2,2.14,46.33]],"ltp":2.16,"tv":3570.96,"id":8860646}]}]}
{"op":"mcm","clk":"1010253991","pt":1580673678961,"mc":[{"id":"1.168238840","rc":[{"batb":[[2,1.76,27.78]],"ltp":1.82,"tv":20833.95,"id":8258569}]}]}
{"op":"mcm","clk":"1010254700","pt":1580673688045,"mc":[{"id":"1.168238840","rc":[{"trd":[[2.26,49.54]],"batl":[[1,2.38,151.95],[2,2.5,5]],"ltp":2.26,"tv":3571.26,"id":8860646},{"trd":[[1.8,0.38]],"batb":[[0,1.8,8.48]],"ltp":1.8,"tv":20834.33,"id":8258569}],"tv":24405.6}]}
{"op":"mcm","clk":"1010255211","pt":1580673694690,"mc":[{"id":"1.168238840","rc":[{"batb":[[0,1.8,8.62]],"ltp":1.8,"tv":20834.33,"id":8258569}]}]}
{"op":"mcm","clk":"1010255566","pt":1580673699406,"mc":[{"id":"1.168238840","rc":[{"batl":[[0,1.87,449.03]],"ltp":1.8,"tv":20834.33,"id":8258569}]}]}
{"op":"mcm","clk":"1010255657","pt":1580673700463,"mc":[{"id":"1.168238840","rc":[{"batb":[[2,2.14,41.04]],"ltp":2.26,"tv":3571.26,"id":8860646}]}]}
{"op":"mcm","clk":"1010256154","pt":1580673706906,"mc":[{"id":"1.168238840","rc":[{"batb":[[0,2.18,304.25],[1,2.14,41.04],[2,2.12,22.51]],"ltp":2.26,"tv":3571.26,"id":8860646}]}]}
{"op":"mcm","clk":"1010256348","pt":1580673709097,"mc":[{"id":"1.168238840","marketDefinition":{"bspMarket":false,"turnInPlayEnabled":true,"persistenceEnabled":true,"marketBaseRate":5.0,"eventId":"29681898","eventTypeId":"2","numberOfWinners":1,"bettingType":"ODDS","marketType":"MATCH_ODDS","marketTime":"2020-02-02T20:15:00.000Z","suspendTime":"2020-02-02T20:15:00.000Z","bspReconciled":false,"complete":true,"inPlay":false,"crossMatching":true,"runnersVoidable":false,"numberOfActiveRunners":2,"betDelay":0,"status":"OPEN","runners":[{"status":"ACTIVE","sortPriority":1,"id":8860646,"name":"Daniel Elahi Galan"},{"status":"ACTIVE","sortPriority":2,"id":8258569,"name":"Thai-Son Kwiatkowski"}],"regulators":["MR_INT"],"countryCode":"US","discountAllowed":true,"timezone":"UTC","openDate":"2020-02-02T20:00:00.000Z","version":3150445144,"name":"Match Odds","eventName":"Galan v Kwiatkowski"},"rc":[{"batb":[[0,2.18,54.89]],"ltp":2.26,"tv":3571.26,"id":8860646}]}]}
