{"op":"mcm","clk":"1002483925","pt":1580594279657,"mc":[{"id":"1.168238843","marketDefinition":{"bspMarket":false,"turnInPlayEnabled":true,"persistenceEnabled":true,"marketBaseRate":5.0,"eventId":"29681898","eventTypeId":"2","numberOfWinners":1,"bettingType":"ODDS","marketType":"SET_WINNER","marketTime":"2020-02-02T18:00:00.000Z","suspendTime":"2020-02-02T18:00:00.000Z","bspReconciled":false,"complete":true,"inPlay":false,"crossMatching":false,"runnersVoidable":false,"numberOfActiveRunners":2,"betDelay":0,"status":"OPEN","runners":[{"status":"ACTIVE","sortPriority":1,"id":8860646,"name":"Daniel Elahi Galan"},{"status":"ACTIVE","sortPriority":2,"id":8258569,"name":"Thai-Son Kwiatkowski"}],"regulators":["MR_INT"],"countryCode":"US","discountAllowed":false,"timezone":"UTC","openDate":"2020-02-02T18:00:00.000Z","version":3147660986,"name":"Set 2 Winner","eventName":"Galan v Kwiatkowski"},"rc":[{"batb":[[0,1.01,20]],"ltp":0.0,"tv":0.0,"id":8860646},{"batb":[[0,1.01,20]],"ltp":0.0,"tv":0.0,"id":8258569}]}]}
{"op":"mcm","clk":"1002483973","pt":1580594280292,"mc":[{"id":"1.168238843","marketDefinition":{"bspMarket":false,"turnInPlayEnabled":true,"persistenceEnabled":true,"marketBaseRate":5.0,"eventId":"29681898","eventTypeId":"2","numberOfWinners":1,"bettingType":"ODDS","marketType":"SET_WINNER","marketTime":"2020-02-02T18:00:00.000Z","suspendTime":"2020-02-02T18:00:00.000Z","bspReconciled":false,"complete":true,"inPlay":false,"crossMatching":false,"runnersVoidable":false,"numberOfActiveRunners":2,"betDelay":0,"status":"OPEN","runners":[{"status":"ACTIVE","sortPriority":1,"id":8860646,"name":"Daniel Elahi Galan"},{"status":"ACTIVE","sortPriority":2,"id":8258569,"name":"Thai-Son Kwiatkowski"}],"regulators":["MR_INT"],"countryCode":"US","discountAllowed":false,"timezone":"UTC","openDate":"2020-02-02T18:00:00.000Z","version":3147660986,"name":"Set 2 Winner","eventName":"Galan v Kwiatkowski"}}]}
{"op":"mcm","clk":"1002484254","pt":1580594284306,"mc":[{"id":"1.168238843","marketDefinition":{"bspMarket":false,"turnInPlayEnabled":true,"persistenceEnabled":true,"marketBaseRate":5.0,"eventId":"29681898","eventTypeId":"2","numberOfWinners":1,"bettingType":"ODDS","marketType":"SET_WINNER","marketTime":"2020-02-02T18:00:00.000Z","suspendTime":"2020-02-02T18:00:00.000Z","bspReconciled":false,"complete":true,"inPlay":false,"crossMatching":false,"runnersVoidable":false,"numberOfActiveRunners":2,"betDelay":0,"status":"OPEN","runners":[{"status":"ACTIVE","sortPriority":1,"id":8860646,"name":"Daniel Elahi Galan"},{"status":"ACTIVE","sortPriority":2,"id":8258569,"name":"Thai-Son Kwiatkowski"}],"regulators":["MR_INT"],"countryCode":"US","discountAllowed":true,"timezone":"UTC","openDate":"2020-02-02T18:00:00.000Z","version":3147660986,"name":"Set 2 Winner","eventName":"Galan v Kwiatkowski"}}]}
{"op":"mcm","clk":"1002493227","pt":1580594420604,"mc":[{"id":"1.168238843","rc":[{"batb":[[0,1.01,15]],"ltp":0.0,"tv":0.0,"id":8860646},{"batb":[[0,1.01,15]],"ltp":0.0,"tv":0.0,"id":8258569}]}]}
{"op":"mcm","clk":"1002629161","pt":1580596307111,"mc":[{"id":"1.168238843","marketDefinition":{"bspMarket":false,"turnInPlayEnabled":true,"persistenceEnabled":true,"marketBaseRate":5.0,"eventId":"29681898","eventTypeId":"2","numberOfWinners":1,"bettingType":"ODDS","marketType":"SET_WINNER","marketTime":"2020-02-02T19:00:00.000Z","suspendTime":"2020-02-02T19:00:00.000Z","bspReconciled":false,"complete":true,"inPlay":false,"crossMatching":false,"runnersVoidable":false,"numberOfActiveRunners":2,"betDelay":0,"status":"OPEN","runners":[{"status":"ACTIVE","sortPriority":1,"id":8860646,"name":"Daniel Elahi Galan"},{"status":"ACTIVE","sortPriority":2,"id":8258569,"name":"Thai-Son Kwiatkowski"}],"regulators":["MR_INT"],"countryCode":"US","discountAllowed":true,"timezone":"UTC","openDate":"2020-02-02T18:00:00.000Z","version":3147732916,"name":"Set 2 Winner","eventName":"Galan v Kwiatkowski"}}]}
{"op":"mcm","clk":"1002629419","pt":1580596310123,"mc":[{"id":"1.168238843","marketDefinition":{"bspMarket":false,"turnInPlayEnabled":true,"persistenceEnabled":true,"marketBaseRate":5.0,"eventId":"29681898","eventTypeId":"2","numberOfWinners":1,"bettingType":"ODDS","marketType":"SET_WINNER","marketTime":"2020-02-02T19:00:00.000Z","suspendTime":"2020-02-02T19:00:00.000Z","bspReconciled":false,"complete":true,"inPlay":false,"crossMatching":false,"runnersVoidable":false,"numberOfActiveRunners":2,"betDelay":0,"status":"OPEN","runners":[{"status":"ACTIVE","sortPriority":1,"id":8860646,"name":"Daniel Elahi Galan"},{"status":"ACTIVE","sortPriority":2,"id":8258569,"name":"Thai-Son Kwiatkowski"}],"regulators":["MR_INT"],"countryCode":"US","discountAllowed":true,"timezone":"UTC","openDate":"2020-02-02T19:00:00.000Z","version":3147732916,"name":"Set 2 Winner","eventName":"Galan v Kwiatkowski"}}]}
{"op":"mcm","clk":"1003066265","pt":1580602553207,"mc":[{"id":"1.168238843","rc":[{"batb":[[0,1.01,15.51]],"ltp":0.0,"tv":0.0,"id":8860646},{"batb":[[0,1.01,15.51]],"ltp":0.0,"tv":0.0,"id":8258569}]}]}
{"op":"mcm","clk":"1003185308","pt":1580604082082,"mc":[{"id":"1.168238843","rc":[{"batb":[[0,1.01,18.04]],"ltp":0.0,"tv":0.0,"id":8860646},{"batb":[[0,1.01,18.04]],"ltp":0.0,"tv":0.0,"id":8258569}]}]}
{"op":"mcm","clk":"1003185382","pt":1580604083272,"mc":[{"id":"1.168238843","rc":[{"batb":[[0,1.01,16.01]],"ltp":0.0,"tv":0.0,"id":8860646},{"batb":[[0,1.01,16.01]],"ltp":0.0,"tv":0.0,"id":8258569}]}]}
{"op":"mcm","clk":"1009851683","pt":1580670107906,"mc":[{"id":"1.168238843","marketDefinition":{"bspMarket":false,"turnInPlayEnabled":true,"persistenceEnabled":true,"marketBaseRate":5.0,"eventId":"29681898","eventTypeId":"2","numberOfWinners":1,"bettingType":"ODDS","marketType":"SET_WINNER","marketTime":"2020-02-02T19:15:00.000Z","suspendTime":"2020-02-02T19:15:00.000Z","bspReconciled":false,"complete":true,"inPlay":false,"crossMatching":false,"runnersVoidable":false,"numberOfActiveRunners":2,"betDelay":0,"status":"OPEN","runners":[{"status":"ACTIVE","sortPriority":1,"id":8860646,"name":"Daniel Elahi Galan"},{"status":"ACTIVE","sortPriority":2,"id":8258569,"name":"Thai-Son Kwiatkowski"}],"regulators":["MR_INT"],"countryCode":"US","discountAllowed":true,"timezone":"UTC","openDate":"2020-02-02T19:00:00.000Z","version":3150309947,"name":"Set 2 Winner","eventName":"Galan v Kwiatkowski"}}]}
{"op":"mcm","clk":"1009851975","pt":1580670109936,"mc":[{"id":"1.168238843","marketDefinition":{"bspMarket":false,"turnInPlayEnabled":true,"persistenceEnabled":true,"marketBaseRate":5.0,"eventId":"29681898","eventTypeId":"2","numberOfWinners":1,"bettingType":"ODDS","marketType":"SET_WINNER","marketTime":"2020-02-02T19:15:00.000Z","suspendTime":"2020-02-02T19:15:00.000Z","bspReconciled":false,"complete":true,"inPlay":false,"crossMatching":false,"runnersVoidable":false,"numberOfActiveRunners":2,"betDelay":0,"status":"OPEN","runners":[{"status":"ACTIVE","sortPriority":1,"id":8860646,"name":"Daniel Elahi Galan"},{"status":"ACTIVE","sortPriority":2,"id":8258569,"name":"Thai-Son Kwiatkowski"}],"regulators":["MR_INT"],"countryCode":"US","discountAllowed":true,"timezone":"UTC","openDate":"2020-02-02T19:15:00.000Z","version":3150309947,"name":"Set 2 Winner","eventName":"Galan v Kwiatkowski"}}]}
{"op":"mcm","clk":"1009919727","pt":1580670669259,"mc":[{"id":"1.168238843","rc":[{"batb":[[0,1.01,16.02]],"ltp":0.0,"tv":0.0,"id":8860646},{"batb":[[0,1.01,18.01]],"ltp":0.0,"tv":0.0,"id":8258569}]}]}
{"op":"mcm","clk":"1009919796","pt":1580670669746,"mc":[{"id":"1.168238843","rc":[{"batb":[[0,1.01,16.02]],"ltp":0.0,"tv":0.0,"id":8258569}]}]}
{"op":"mcm","clk":"1009963861","pt":1580671008639,"mc":[{"id":"1.168238843","marketDefinition":{"bspMarket":false,"turnInPlayEnabled":true,"persistenceEnabled":true,"marketBaseRate":5.0,"eventId":"29681898","eventTypeId":"2","numberOfWinners":1,"bettingType":"ODDS","marketType":"SET_WINNER","marketTime":"2020-02-02T19:30:00.000Z","suspendTime":"2020-02-02T19:30:00.000Z","bspReconciled":false,"complete":true,"inPlay":false,"crossMatching":false,"runnersVoidable":false,"numberOfActiveRunners":2,"betDelay":0,"status":"OPEN","runners":[{"status":"ACTIVE","sortPriority":1,"id":8860646,"name":"Daniel Elahi Galan"},{"status":"ACTIVE","sortPriority":2,"id":8258569,"name":"Thai-Son Kwiatkowski"}],"regulators":["MR_INT"],"countryCode":"US","discountAllowed":true,"timezone":"UTC","openDate":"2020-02-02T19:15:00.000Z","version":3150350851,"name":"Set 2 Winner","eventName":"Galan v Kwiatkowski"}}]}
{"op":"mcm","clk":"1009964241","pt":1580671011646,"mc":[{"id":"1.168238843","marketDefinition":{"bspMarket":false,"turnInPlayEnabled":true,"persistenceEnabled":true,"marketBaseRate":5.0,"eventId":"29681898","eventTypeId":"2","numberOfWinners":1,"bettingType":"ODDS","marketType":"SET_WINNER","marketTime":"2020-02-02T19:30:00.000Z","suspendTime":"2020-02-02T19:30:00.000Z","bspReconciled":false,"complete":true,"inPlay":false,"crossMatching":false,"runnersVoidable":false,"numberOfActiveRunners":2,"betDelay":0,"status":"OPEN","runners":[{"status":"ACTIVE","sortPriority":1,"id":8860646,"name":"Daniel Elahi Galan"},{"status":"ACTIVE","sortPriority":2,"id":8258569,"name":"Thai-Son Kwiatkowski"}],"regulators":["MR_INT"],"countryCode":"US","discountAllowed":true,"timezone":"UTC","openDate":"2020-02-02T19:30:00.000Z","version":3150350851,"name":"Set 2 Winner","eventName":"Galan v Kwiatkowski"}}]}
{"op":"mcm","clk":"1010073708","pt":1580671908035,"mc":[{"id":"1.168238843","marketDefinition":{"bspMarket":false,"turnInPlayEnabled":true,"persistenceEnabled":true,"marketBaseRate":5.0,"eventId":"29681898","eventTypeId":"2","numberOfWinners":1,"bettingType":"ODDS","marketType":"SET_WINNER","marketTime":"2020-02-02T19:45:00.000Z","suspendTime":"2020-02-02T19:45:00.000Z","bspReconciled":false,"complete":true,"inPlay":false,"crossMatching":false,"runnersVoidable":false,"numberOfActiveRunners":2,"betDelay":0,"status":"OPEN","runners":[{"status":"ACTIVE","sortPriority":1,"id":8860646,"name":"Daniel Elahi Galan"},{"status":"ACTIVE","sortPriority":2,"id":8258569,"name":"Thai-Son Kwiatkowski"}],"regulators":["MR_INT"],"countryCode":"US","discountAllowed":true,"timezone":"UTC","openDate":"2020-02-02T19:30:00.000Z","version":3150384455,"name":"Set 2 Winner","eventName":"Galan v Kwiatkowski"}}]}
{"op":"mcm","clk":"1010074096","pt":1580671911042,"mc":[{"id":"1.168238843","marketDefinition":{"bspMarket":false,"turnInPlayEnabled":true,"persistenceEnabled":true,"marketBaseRate":5.0,"eventId":"29681898","eventTypeId":"2","numberOfWinners":1,"bettingType":"ODDS","marketType":"SET_WINNER","marketTime":"2020-02-02T19:45:00.000Z","suspendTime":"2020-02-02T19:45:00.000Z","bspReconciled":false,"complete":true,"inPlay":false,"crossMatching":false,"runnersVoidable":false,"numberOfActiveRunners":2,"betDelay":0,"status":"OPEN","runners":[{"status":"ACTIVE","sortPriority":1,"id":8860646,"name":"Daniel Elahi Galan"},{"status":"ACTIVE","sortPriority":2,"id":8258569,"name":"Thai-Son Kwiatkowski"}],"regulators":["MR_INT"],"countryCode":"US","discountAllowed":true,"timezone":"UTC","openDate":"2020-02-02T19:45:00.000Z","version":3150384455,"name":"Set 2 Winner","eventName":"Galan v Kwiatkowski"}}]}
{"op":"mcm","clk":"1010181430","pt":1580672808353,"mc":[{"id":"1.168238843","marketDefinition":{"bspMarket":false,"turnInPlayEnabled":true,"persistenceEnabled":true,"marketBaseRate":5.0,"eventId":"29681898","eventTypeId":"2","numberOfWinners":1,"bettingType":"ODDS","marketType":"SET_WINNER","marketTime":"2020-02-02T20:00:00.000Z","suspendTime":"2020-02-02T20:00:00.000Z","bspReconciled":false,"complete":true,"inPlay":false,"crossMatching":false,"runnersVoidable":false,"numberOfActiveRunners":2,"betDelay":0,"status":"OPEN","runners":[{"status":"ACTIVE","sortPriority":1,"id":8860646,"name":"Daniel Elahi Galan"},{"status":"ACTIVE","sortPriority":2,"id":8258569,"name":"Thai-Son Kwiatkowski"}],"regulators":["MR_INT"],"countryCode":"US","discountAllowed":true,"timezone":"UTC","openDate":"2020-02-02T19:45:00.000Z","version":3150416838,"name":"Set 2 Winner","eventName":"Galan v Kwiatkowski"}}]}
{"op":"mcm","clk":"1010183449","pt":1580672828399,"mc":[{"id":"1.168238843","marketDefinition":{"bspMarket":false,"turnInPlayEnabled":true,"persistenceEnabled":true,"marketBaseRate":5.0,"eventId":"29681898","eventTypeId":"2","numberOfWinners":1,"bettingType":"ODDS","marketType":"SET_WINNER","marketTime":"2020-02-02T20:00:00.000Z","suspendTime":"2020-02-02T20:00:00.000Z","bspReconciled":false,"complete":true,"inPlay":false,"crossMatching":false,"runnersVoidable":false,"numberOfActiveRunners":2,"betDelay":0,"status":"OPEN","runners":[{"status":"ACTIVE","sortPriority":1,"id":8860646,"name":"Daniel Elahi Galan"},{"status":"ACTIVE","sortPriority":2,"id":8258569,"name":"Thai-Son Kwiatkowski"}],"regulators":["MR_INT"],"countryCode":"US","discountAllowed":true,"timezone":"UTC","openDate":"2020-02-02T20:00:00.000Z","version":3150416838,"name":"Set 2 Winner","eventName":"Galan v Kwiatkowski"}}]}
{"op":"mcm","clk":"1010256348","pt":1580673709097,"mc":[{"id":"1.168238843","marketDefinition":{"bspMarket":false,"turnInPlayEnabled":true,"persistenceEnabled":true,"marketBaseRate":5.0,"eventId":"29681898","eventTypeId":"2","numberOfWinners":1,"bettingType":"ODDS","marketType":"SET_WINNER","marketTime":"2020-02-02T20:15:00.000Z","suspendTime":"2020-02-02T20:15:00.000Z","bspReconciled":false,"complete":true,"inPlay":false,"crossMatching":false,"runnersVoidable":false,"numberOfActiveRunners":2,"betDelay":0,"status":"OPEN","runners":[{"status":"ACTIVE","sortPriority":1,"id":8860646,"name":"Daniel Elahi Galan"},{"status":"ACTIVE","sortPriority":2,"id":8258569,"name":"Thai-Son Kwiatkowski"}],"regulators":["MR_INT"],"countryCode":"US","discountAllowed":true,"timezone":"UTC","openDate":"2020-02-02T20:00:00.000Z","version":3150445150,"name":"Set 2 Winner","eventName":"Galan v Kwiatkowski"}}]}
{"op":"mcm","clk":"1010256461","pt":1580673710634,"mc":[{"id":"1.168238843","marketDefinition":{"bspMarket":false,"turnInPlayEnabled":true,"persistenceEnabled":true,"marketBaseRate":5.0,"eventId":"29681898","eventTypeId":"2","numberOfWinners":1,"bettingType":"ODDS","marketType":"SET_WINNER","marketTime":"2020-02-02T20:15:00.000Z","suspendTime":"2020-02-02T20:15:00.000Z","bspReconciled":false,"complete":true,"inPlay":false,"crossMatching":false,"runnersVoidable":false,"numberOfActiveRunners":2,"betDelay":0,"status":"OPEN","runners":[{"status":"ACTIVE","sortPriority":1,"id":8860646,"name":"Daniel Elahi Galan"},{"status":"ACTIVE","sortPriority":2,"id":8258569,"name":"Thai-Son Kwiatkowski"}],"regulators":["MR_INT"],"countryCode":"US","discountAllowed":true,"timezone":"UTC","openDate":"2020-02-02T20:15:00.000Z","version":3150445150,"name":"Set 2 Winner","eventName":"Galan v Kwiatkowski"}}]}
{"op":"mcm","clk":"1010342736","pt":1580674608256,"mc":[{"id":"1.168238843","marketDefinition":{"bspMarket":false,"turnInPlayEnabled":true,"persistenceEnabled":true,"marketBaseRate":5.0,"eventId":"29681898","eventTypeId":"2","numberOfWinners":1,"bettingType":"ODDS","marketType":"SET_WINNER","marketTime":"2020-02-02T20:30:00.000Z","suspendTime":"2020-02-02T20:30:00.000Z","bspReconciled":false,"complete":true,"inPlay":false,"crossMatching":false,"runnersVoidable":false,"numberOfActiveRunners":2,"betDelay":0,"status":"OPEN","runners":[{"status":"ACTIVE","sortPriority":1,"id":8860646,"name":"Daniel Elahi Galan"},{"status":"ACTIVE","sortPriority":2,"id":8258569,"name":"Thai-Son Kwiatkowski"}],"regulators":["MR_INT"],"countryCode":"US","discountAllowed":true,"timezone":"UTC","openDate":"2020-02-02T20:15:00.000Z","version":3150491537,"name":"Set 2 Winner","eventName":"Galan v Kwiatkowski"}}]}
{"op":"mcm","clk":"1010343011","pt":1580674611262,"mc":[{"id":"1.168238843","marketDefinition":{"bspMarket":false,"turnInPlayEnabled":true,"persistenceEnabled":true,"marketBaseRate":5.0,"eventId":"29681898","eventTypeId":"2","numberOfWinners":1,"bettingType":"ODDS","marketType":"SET_WINNER","marketTime":"2020-02-02T20:30:00.000Z","suspendTime":"2020-02-02T20:30:00.000Z","bspReconciled":false,"complete":true,"inPlay":false,"crossMatching":false,"runnersVoidable":false,"numberOfActiveRunners":2,"betDelay":0,"status":"OPEN","runners":[{"status":"ACTIVE","sortPriority":1,"id":8860646,"name":"Daniel Elahi Galan"},{"status":"ACTIVE","sortPriority":2,"id":8258569,"name":"Thai-Son Kwiatkowski"}],"regulators":["MR_INT"],"countryCode":"US","discountAllowed":true,"timezone":"UTC","openDate":"2020-02-02T20:30:00.000Z","version":3150491537,"name":"Set 2 Winner","eventName":"Galan v Kwiatkowski"}}]}
{"op":"mcm","clk":"1010362586","pt":1580674796127,"mc":[{"id":"1.168238843","rc":[{"batb":[[0,2.12,48.55],[1,1.79,13.93],[2,1.01,16.02]],"ltp":0.0,"tv":0.0,"id":8860646},{"batb":[[0,1.78,41.7],[1,1.48,23.77],[2,1.01,16.01]],"ltp":0.0,"tv":0.0,"id":8258569}]}]}
{"op":"mcm","clk":"1010362663","pt":1580674796831,"mc":[{"id":"1.168238843","rc":[{"batb":[[1,1.01,16.02],[2,1.01,0]],"ltp":0.0,"tv":0.0,"id":8860646},{"batb":[[1,1.01,16.02],[2,1.01,0]],"ltp":0.0,"tv":0.0,"id":8258569}]}]}
{"op":"mcm","clk":"1010365036","pt":1580674821267,"mc":[{"id":"1.168238843","marketDefinition":{"bspMarket":false,"turnInPlayEnabled":true,"persistenceEnabled":true,"marketBaseRate":5.0,"eventId":"29681898","eventTypeId":"2","numberOfWinners":1,"bettingType":"ODDS","marketType":"SET_WINNER","marketTime":"2020-02-02T20:30:00.000Z","suspendTime":"2020-02-02T20:30:00.000Z","bspReconciled":false,"complete":true,"inPlay":false,"crossMatching":true,"runnersVoidable":false,"numberOfActiveRunners":2,"betDelay":0,"status":"OPEN","runners":[{"status":"ACTIVE","sortPriority":1,"id":8860646,"name":"Daniel Elahi Galan"},{"status":"ACTIVE","sortPriority":2,"id":8258569,"name":"Thai-Son Kwiatkowski"}],"regulators":["MR_INT"],"countryCode":"US","discountAllowed":true,"timezone":"UTC","openDate":"2020-02-02T20:30:00.000Z","version":3150491537,"name":"Set 2 Winner","eventName":"Galan v Kwiatkowski"}}]}
{"op":"mcm","clk":"1010365158","pt":1580674822607,"mc":[{"id":"1.168238843","rc":[{"batb":[[0,2.12,48.07]],"ltp":0.0,"tv":0.0,"id":8860646}]}]}
{"op":"mcm","clk":"1010371598","pt":1580674886215,"mc":[{"id":"1.168238843","rc":[{"batb":[[0,1.79,41.47],[1,1.78,41.7],[2,1.01,16.02]],"ltp":0.0,"tv":0.0,"id":8258569}]}]}
{"op":"mcm","clk":"1010371643","pt":1580674886574,"mc":[{"id":"1.168238843","rc":[{"batb":[[1,1.01,16.02],[2,1.01,0]],"ltp":0.0,"tv":0.0,"id":8258569}]}]}
{"op":"mcm","clk":"1010373865","pt":1580674908202,"mc":[{"id":"1.168238843","marketDefinition":{"bspMarket":false,"turnInPlayEnabled":true,"persistenceEnabled":true,"marketBaseRate":5.0,"eventId":"29681898","eventTypeId":"2","numberOfWinners":1,"bettingType":"ODDS","marketType":"SET_WINNER","marketTime":"2020-02-02T20:18:00.000Z","suspendTime":"2020-02-02T20:18:00.000Z","bspReconciled":false,"complete":true,"inPlay":false,"crossMatching":true,"runnersVoidable":false,"numberOfActiveRunners":2,"betDelay":0,"status":"OPEN","runners":[{"status":"ACTIVE","sortPriority":1,"id":8860646,"name":"Daniel Elahi Galan"},{"status":"ACTIVE","sortPriority":2,"id":8258569,"name":"Thai-Son Kwiatkowski"}],"regulators":["MR_INT"],"countryCode":"US","discountAllowed":true,"timezone":"UTC","openDate":"2020-02-02T20:30:00.000Z","version":3150502609,"name":"Set 2 Winner","eventName":"Galan v Kwiatkowski"}}]}
{"op":"mcm","clk":"1010374305","pt":1580674912182,"mc":[{"id":"1.168238843","marketDefinition":{"bspMarket":false,"turnInPlayEnabled":true,"persistenceEnabled":true,"marketBaseRate":5.0,"eventId":"29681898","eventTypeId":"2","numberOfWinners":1,"bettingType":"ODDS","marketType":"SET_WINNER","marketTime":"2020-02-02T20:18:00.000Z","suspendTime":"2020-02-02T20:18:00.000Z","bspReconciled":false,"complete":true,"inPlay":false,"crossMatching":true,"runnersVoidable":false,"numberOfActiveRunners":2,"betDelay":0,"status":"OPEN","runners":[{"status":"ACTIVE","sortPriority":1,"id":8860646,"name":"Daniel Elahi Galan"},{"status":"ACTIVE","sortPriority":2,"id":8258569,"name":"Thai-Son Kwiatkowski"}],"regulators":["MR_INT"],"countryCode":"US","discountAllowed":true,"timezone":"UTC","openDate":"2020-02-02T20:18:00.000Z","version":3150502609,"name":"Set 2 Winner","eventName":"Galan v Kwiatkowski"}}]}
{"op":"mcm","clk":"1010380978","pt":1580674976034,"mc":[{"id":"1.168238843","rc":[{"batb":[[0,1.01,16.02],[1,1.01,0]],"ltp":0.0,"tv":0.0,"id":8860646},{"batb":[[0,1.01,16.02],[1,1.01,0]],"ltp":0.0,"tv":0.0,"id":8258569}]}]}
{"op":"mcm","clk":"1010381004","pt":1580674976326,"mc":[{"id":"1.168238843","marketDefinition":{"bspMarket":false,"turnInPlayEnabled":true,"persistenceEnabled":true,"marketBaseRate":5.0,"eventId":"29681898","eventTypeId":"2","numberOfWinners":1,"bettingType":"ODDS","marketType":"SET_WINNER","marketTime":"2020-02-02T20:18:00.000Z","suspendTime":"2020-02-02T20:18:00.000Z","bspReconciled":false,"complete":true,"inPlay":true,"crossMatching":true,"runnersVoidable":false,"numberOfActiveRunners":2,"betDelay":3,"status":"OPEN","runners":[{"status":"ACTIVE","sortPriority":1,"id":8860646,"name":"Daniel Elahi Galan"},{"status":"ACTIVE","sortPriority":2,"id":8258569,"name":"Thai-Son Kwiatkowski"}],"regulators":["MR_INT"],"countryCode":"US","discountAllowed":true,"timezone":"UTC","openDate":"2020-02-02T20:18:00.000Z","version":3150503842,"name":"Set 2 Winner","eventName":"Galan v Kwiatkowski"},"rc":[{"batb":[[0,1.01,15.52]],"ltp":0.0,"tv":0.0,"id":8860646},{"batb":[[0,1.01,15.52]],"ltp":0.0,"tv":0.0,"id":8258569}]}]}
{"op":"mcm","clk":"1010381720","pt":1580674982028,"mc":[{"id":"1.168238843","rc":[{"batb":[[0,2.08,51.85],[1,2.04,54.45],[2,1.01,15.52]],"ltp":0.0,"tv":0.0,"id":8860646},{"batb":[[0,1.82,39.18],[1,1.78,42.17],[2,1.01,15.52]],"ltp":0.0,"tv":0.0,"id":8258569}]}]}
{"op":"mcm","clk":"1010382385","pt":1580674987735,"mc":[{"id":"1.168238843","rc":[{"batb":[[0,2.04,54.45],[1,1.01,15.52],[2,1.01,0]],"ltp":0.0,"tv":0.0,"id":8860646},{"batb":[[0,1.78,42.17],[1,1.01,15.52],[2,1.01,0]],"ltp":0.0,"tv":0.0,"id":8258569}]}]}
{"op":"mcm","clk":"1010384358","pt":1580675004262,"mc":[{"id":"1.168238843","rc":[{"batb":[[0,2.14,48],[1,2.08,51.14],[2,2.04,12.37]],"ltp":0.0,"tv":0.0,"id":8860646},{"batb":[[1,1.74,45.64],[2,1.01,15.52]],"ltp":0.0,"tv":0.0,"id":8258569}]}]}
{"op":"mcm","clk":"1010385533","pt":1580675015103,"mc":[{"id":"1.168238843","rc":[{"batb":[[0,2.08,51.14],[1,1.01,15.52],[2,2.04,0]],"ltp":0.0,"tv":0.0,"id":8860646},{"batb":[[0,1.74,45.64],[1,1.01,15.52],[2,1.01,0]],"ltp":0.0,"tv":0.0,"id":8258569}]}]}
{"op":"mcm","clk":"1010386210","pt":1580675021280,"mc":[{"id":"1.168238843","rc":[{"batb":[[1,2.06,53.27],[2,1.01,15.52]],"ltp":0.0,"tv":0.0,"id":8860646},{"batb":[[0,1.81,39.66],[1,1.76,43.2],[2,1.74,45.64]],"ltp":0.0,"tv":0.0,"id":8258569}]}]}
{"op":"mcm","clk":"1010386231","pt":1580675021493,"mc":[{"id":"1.168238843","rc":[{"batb":[[2,1.01,15.52]],"ltp":0.0,"tv":0.0,"id":8258569}]}]}
{"op":"mcm","clk":"1010387213","pt":1580675029905,"mc":[{"id":"1.168238843","rc":[{"batb":[[0,2.06,53.27],[1,1.01,15.52],[2,1.01,0]],"ltp":0.0,"tv":0.0,"id":8860646},{"batb":[[0,1.76,43.2],[1,1.01,15.52],[2,1.01,0]],"ltp":0.0,"tv":0.0,"id":8258569}]}]}
{"op":"mcm","clk":"1010388526","pt":1580675042203,"mc":[{"id":"1.168238843","rc":[{"batb":[[0,2.14,46.97],[1,2.1,50.44],[2,1.01,15.52]],"ltp":0.0,"tv":0.0,"id":8860646},{"batb":[[0,1.77,42.96],[1,1.72,47.29],[2,1.01,15.52]],"ltp":0.0,"tv":0.0,"id":8258569}]}]}
{"op":"mcm","clk":"1010389984","pt":1580675055023,"mc":[{"id":"1.168238843","rc":[{"batb":[[0,2.1,50.44],[1,1.01,15.52],[2,1.01,0]],"ltp":0.0,"tv":0.0,"id":8860646},{"batb":[[0,1.72,47.29],[1,1.01,15.52],[2,1.01,0]],"ltp":0.0,"tv":0.0,"id":8258569}]}]}
{"op":"mcm","clk":"1010390306","pt":1580675058034,"mc":[{"id":"1.168238843","rc":[{"batb":[[0,2.08,51.22]],"ltp":0.0,"tv":0.0,"id":8860646},{"batb":[[0,1.73,46.66]],"ltp":0.0,"tv":0.0,"id":8258569}]}]}
{"op":"mcm","clk":"1010392843","pt":1580675080262,"mc":[{"id":"1.168238843","rc":[{"batb":[[0,2.22,43.04],[1,2.14,46.97],[2,1.01,15.52]],"ltp":0.0,"tv":0.0,"id":8860646},{"batb":[[1,1.67,51.62],[2,1.01,15.52]],"ltp":0.0,"tv":0.0,"id":8258569}]}]}
{"op":"mcm","clk":"1010395318","pt":1580675101281,"mc":[{"id":"1.168238843","rc":[{"batb":[[0,2.14,46.97],[1,1.01,15.52],[2,1.01,0]],"ltp":0.0,"tv":0.0,"id":8860646},{"batb":[[0,1.67,51.62],[1,1.01,15.52],[2,1.01,0]],"ltp":0.0,"tv":0.0,"id":8258569}]}]}
{"op":"mcm","clk":"1010395648","pt":1580675104203,"mc":[{"id":"1.168238843","rc":[{"batb":[[0,1.68,51.54]],"ltp":0.0,"tv":0.0,"id":8258569}]}]}
{"op":"mcm","clk":"1010396674","pt":1580675112912,"mc":[{"id":"1.168238843","rc":[{"batb":[[1,2.1,50.2],[2,1.01,15.52]],"ltp":0.0,"tv":0.0,"id":8860646},{"batb":[[0,1.77,42.96],[1,1.72,46.74],[2,1.01,15.52]],"ltp":0.0,"tv":0.0,"id":8258569}]}]}
{"op":"mcm","clk":"1010398126","pt":1580675126937,"mc":[{"id":"1.168238843","rc":[{"batb":[[0,2.1,50.2],[1,1.01,15.52],[2,1.01,0]],"ltp":0.0,"tv":0.0,"id":8860646},{"batb":[[0,1.72,46.74],[1,1.01,15.52],[2,1.01,0]],"ltp":0.0,"tv":0.0,"id":8258569}]}]}
{"op":"mcm","clk":"1010400795","pt":1580675151254,"mc":[{"id":"1.168238843","rc":[{"batb":[[1,2.06,52.87],[2,1.01,15.52]],"ltp":0.0,"tv":0.0,"id":8860646},{"batb":[[0,1.8,40.44],[1,1.76,43.35],[2,1.74,148.02]],"ltp":0.0,"tv":0.0,"id":8258569}]}]}
{"op":"mcm","clk":"1010401675","pt":1580675159124,"mc":[{"id":"1.168238843","rc":[{"batb":[[0,2.06,52.87],[1,1.01,15.52],[2,1.01,0]],"ltp":0.0,"tv":0.0,"id":8860646},{"batb":[[0,1.76,43.35],[1,1.01,15.52],[2,1.74,0]],"ltp":0.0,"tv":0.0,"id":8258569}]}]}
{"op":"mcm","clk":"1010403723","pt":1580675179245,"mc":[{"id":"1.168238843","rc":[{"batb":[[1,2,57.36],[2,1.01,15.52]],"ltp":0.0,"tv":0.0,"id":8860646},{"batb":[[0,1.83,38.48],[1,1.8,40.44],[2,1.74,148.02]],"ltp":0.0,"tv":0.0,"id":8258569}]}]}
{"op":"mcm","clk":"1010408423","pt":1580675225269,"mc":[{"id":"1.168238843","rc":[{"batb":[[0,2,57.36],[1,1.01,15.52],[2,1.01,0]],"ltp":0.0,"tv":0.0,"id":8860646},{"batb":[[0,1.8,40.44],[1,1.01,15.52],[2,1.74,0]],"ltp":0.0,"tv":0.0,"id":8258569}]}]}
{"op":"mcm","clk":"1010409445","pt":1580675236159,"mc":[{"id":"1.168238843","rc":[{"batb":[[0,2.1,50.12],[1,2.04,54.61],[2,1.01,15.52]],"ltp":0.0,"tv":0.0,"id":8860646},{"batb":[[1,1.78,42.25],[2,1.01,15.52]],"ltp":0.0,"tv":0.0,"id":8258569}]}]}
{"op":"mcm","clk":"1010410386","pt":1580675246052,"mc":[{"id":"1.168238843","rc":[{"batb":[[0,2.04,54.61],[1,1.01,15.52],[2,1.01,0]],"ltp":0.0,"tv":0.0,"id":8860646},{"batb":[[0,1.78,42.25],[1,1.01,15.52],[2,1.01,0]],"ltp":0.0,"tv":0.0,"id":8258569}]}]}
{"op":"mcm","clk":"1010411034","pt":1580675253190,"mc":[{"id":"1.168238843","rc":[{"batb":[[0,2.14,47.92],[1,2.08,51.62],[2,1.01,15.52]],"ltp":0.0,"tv":0.0,"id":8860646},{"batb":[[1,1.76,43.51],[2,1.01,15.52]],"ltp":0.0,"tv":0.0,"id":8258569}]}]}
{"op":"mcm","clk":"1010411799","pt":1580675262271,"mc":[{"id":"1.168238843","rc":[{"batb":[[0,2.08,51.62],[1,1.01,15.52],[2,1.01,0]],"ltp":0.0,"tv":0.0,"id":8860646},{"batb":[[0,1.76,43.51],[1,1.01,15.52],[2,1.01,0]],"ltp":0.0,"tv":0.0,"id":8258569}]}]}
{"op":"mcm","clk":"1010413316","pt":1580675280081,"mc":[{"id":"1.168238843","rc":[{"batb":[[0,2.16,46.42],[1,2.12,49.18],[2,2.08,51.62]],"ltp":0.0,"tv":0.0,"id":8860646},{"batb":[[1,1.74,45.56],[2,1.01,15.52]],"ltp":0.0,"tv":0.0,"id":8258569}]}]}
{"op":"mcm","clk":"1010413403","pt":1580675281009,"mc":[{"id":"1.168238843","rc":[{"batb":[[2,1.01,15.52]],"ltp":0.0,"tv":0.0,"id":8860646}]}]}
{"op":"mcm","clk":"1010413681","pt":1580675284011,"mc":[{"id":"1.168238843","rc":[{"batl":[[0,3,213.45]],"ltp":0.0,"tv":0.0,"id":8860646},{"batl":[[0,2.3,309.75]],"ltp":0.0,"tv":0.0,"id":8258569}]}]}
{"op":"mcm","clk":"1010414898","pt":1580675296944,"mc":[{"id":"1.168238843","rc":[{"batb":[[0,2.12,49.18],[1,1.01,15.52],[2,1.01,0]],"ltp":0.0,"tv":0.0,"id":8860646},{"batb":[[0,1.74,45.56],[1,1.01,15.52],[2,1.01,0]],"ltp":0.0,"tv":0.0,"id":8258569}]}]}
{"op":"mcm","clk":"1010416729","pt":1580675316244,"mc":[{"id":"1.168238843","rc":[{"batb":[[0,2.2,44.14],[1,2.14,46.97],[2,2.12,12.54]],"ltp":0.0,"tv":0.0,"id":8860646},{"batb":[[1,1.7,49.1],[2,1.01,15.52]],"ltp":0.0,"tv":0.0,"id":8258569}]}]}
{"op":"mcm","clk":"1010418940","pt":1580675338106,"mc":[{"id":"1.168238843","rc":[{"batb":[[0,2.14,46.97],[1,1.01,15.52],[2,2.12,0]],"ltp":0.0,"tv":0.0,"id":8860646},{"batb":[[0,1.7,49.1],[1,1.01,15.52],[2,1.01,0]],"ltp":0.0,"tv":0.0,"id":8258569}]}]}
{"op":"mcm","clk":"1010419228","pt":1580675341169,"mc":[{"id":"1.168238843","rc":[{"batb":[[1,2.12,48.31],[2,1.01,15.52]],"ltp":0.0,"tv":0.0,"id":8860646},{"batb":[[0,1.71,47.76],[1,1.7,49.1],[2,1.01,15.52]],"ltp":0.0,"tv":0.0,"id":8258569}]}]}
{"op":"mcm","clk":"1010419321","pt":1580675342125,"mc":[{"id":"1.168238843","rc":[{"batb":[[0,2.12,48.31],[1,1.01,15.52],[2,1.01,0]],"ltp":0.0,"tv":0.0,"id":8860646},{"batb":[[1,1.01,15.52],[2,1.01,0]],"ltp":0.0,"tv":0.0,"id":8258569}]}]}
{"op":"mcm","clk":"1010420585","pt":1580675354903,"mc":[{"id":"1.168238843","rc":[{"batb":[[1,2.1,50.36],[2,1.01,15.52]],"ltp":0.0,"tv":0.0,"id":8860646},{"batb":[[0,1.78,41.86],[1,1.73,289.84],[2,1.01,15.52]],"ltp":0.0,"tv":0.0,"id":8258569}]}]}
{"op":"mcm","clk":"1010421878","pt":1580675367719,"mc":[{"id":"1.168238843","rc":[{"batb":[[0,2.1,50.36],[1,1.01,15.52],[2,1.01,0]],"ltp":0.0,"tv":0.0,"id":8860646},{"batb":[[0,1.73,45.71],[1,1.01,15.52],[2,1.01,0]],"ltp":0.0,"tv":0.0,"id":8258569}]}]}
{"op":"mcm","clk":"1010422203","pt":1580675371227,"mc":[{"id":"1.168238843","rc":[{"batb":[[1,2.08,50.99],[2,1.01,15.52]],"ltp":0.0,"tv":0.0,"id":8860646},{"batb":[[0,1.74,45.16],[1,1.73,45.71],[2,1.01,15.52]],"ltp":0.0,"tv":0.0,"id":8258569}]}]}
{"op":"mcm","clk":"1010422308","pt":1580675372225,"mc":[{"id":"1.168238843","rc":[{"batb":[[0,2.08,50.99],[1,1.01,15.52],[2,1.01,0]],"ltp":0.0,"tv":0.0,"id":8860646},{"batb":[[1,1.01,15.52],[2,1.01,0]],"ltp":0.0,"tv":0.0,"id":8258569}]}]}
{"op":"mcm","clk":"1010422691","pt":1580675376089,"mc":[{"id":"1.168238843","rc":[{"batb":[[1,2.06,52.95],[2,1.01,15.52]],"ltp":0.0,"tv":0.0,"id":8860646},{"batb":[[0,1.81,39.81],[1,1.77,42.8],[2,1.01,15.52]],"ltp":0.0,"tv":0.0,"id":8258569}]}]}
{"op":"mcm","clk":"1010422782","pt":1580675376867,"mc":[{"id":"1.168238843","rc":[{"batl":[[0,2.84,228.62]],"ltp":0.0,"tv":0.0,"id":8860646}]}]}
{"op":"mcm","clk":"1010423429","pt":1580675383584,"mc":[{"id":"1.168238843","rc":[{"batb":[[0,2.06,52.95],[1,1.01,15.52],[2,1.01,0]],"ltp":0.0,"tv":0.0,"id":8860646},{"batb":[[0,1.77,42.8],[1,1.01,15.52],[2,1.01,0]],"ltp":0.0,"tv":0.0,"id":8258569}]}]}
{"op":"mcm","clk":"1010423746","pt":1580675386838,"mc":[{"id":"1.168238843","rc":[{"batb":[[0,2.06,52.4]],"ltp":0.0,"tv":0.0,"id":8860646},{"batb":[[0,1.76,43.28]],"ltp":0.0,"tv":0.0,"id":8258569}]}]}
{"op":"mcm","clk":"1010426473","pt":1580675413216,"mc":[{"id":"1.168238843","rc":[{"batb":[[0,2.16,46.66],[1,2.1,49.41],[2,1.01,15.52]],"ltp":0.0,"tv":0.0,"id":8860646},{"batb":[[1,1.72,47.13],[2,1.01,15.52]],"ltp":0.0,"tv":0.0,"id":8258569}]}]}
{"op":"mcm","clk":"1010427416","pt":1580675422020,"mc":[{"id":"1.168238843","rc":[{"batb":[[0,2.1,49.41],[1,1.01,15.52],[2,1.01,0]],"ltp":0.0,"tv":0.0,"id":8860646},{"batb":[[0,1.72,47.13],[1,1.01,15.52],[2,1.01,0]],"ltp":0.0,"tv":0.0,"id":8258569}]}]}
{"op":"mcm","clk":"1010428048","pt":1580675428155,"mc":[{"id":"1.168238843","rc":[{"batb":[[1,2.08,51.85],[2,1.01,15.52]],"ltp":0.0,"tv":0.0,"id":8860646},{"batb":[[0,1.79,40.99],[1,1.75,44.61],[2,1.72,47.13]],"ltp":0.0,"tv":0.0,"id":8258569}]}]}
{"op":"mcm","clk":"1010428147","pt":1580675429253,"mc":[{"id":"1.168238843","rc":[{"batb":[[2,1.01,15.52]],"ltp":0.0,"tv":0.0,"id":8258569}]}]}
{"op":"mcm","clk":"1010428951","pt":1580675437044,"mc":[{"id":"1.168238843","rc":[{"batb":[[0,2.08,51.85],[1,1.01,15.52],[2,1.01,0]],"ltp":0.0,"tv":0.0,"id":8860646},{"batb":[[0,1.75,44.61],[1,1.01,15.52],[2,1.01,0]],"ltp":0.0,"tv":0.0,"id":8258569}]}]}
{"op":"mcm","clk":"1010430454","pt":1580675451961,"mc":[{"id":"1.168238843","rc":[{"batb":[[1,2.02,56.89],[2,1.01,15.52]],"ltp":0.0,"tv":0.0,"id":8860646},{"batb":[[0,1.82,39.18],[1,1.79,41.31],[2,1.73,149.02]],"ltp":0.0,"tv":0.0,"id":8258569}]}]}
{"op":"mcm","clk":"1010431715","pt":1580675464821,"mc":[{"id":"1.168238843","rc":[{"batb":[[0,2.08,51.69],[1,2.02,56.65]],"ltp":0.0,"tv":0.0,"id":8860646}]}]}
{"op":"mcm","clk":"1010435864","pt":1580675504846,"mc":[{"id":"1.168238843","rc":[{"batb":[[0,2.08,51.06],[1,2.02,56.02]],"ltp":0.0,"tv":0.0,"id":8860646},{"batb":[[0,1.81,39.73],[1,1.78,41.94]],"ltp":0.0,"tv":0.0,"id":8258569}]}]}
{"op":"mcm","clk":"1010439599","pt":1580675537117,"mc":[{"id":"1.168238843","rc":[{"batb":[[0,2.02,56.02],[1,1.01,15.52],[2,1.01,0]],"ltp":0.0,"tv":0.0,"id":8860646},{"batb":[[0,1.78,41.94],[1,1.01,15.52],[2,1.73,0]],"ltp":0.0,"tv":0.0,"id":8258569}]}]}
{"op":"mcm","clk":"1010442828","pt":1580675565244,"mc":[{"id":"1.168238843","rc":[{"batb":[[1,1.96,61.61],[2,1.01,15.52]],"ltp":0.0,"tv":0.0,"id":8860646},{"batb":[[0,1.86,36.43],[1,1.83,38.55],[2,1.73,149.02]],"ltp":0.0,"tv":0.0,"id":8258569}]}]}
{"op":"mcm","clk":"1010442952","pt":1580675566647,"mc":[{"id":"1.168238843","rc":[{"batl":[[0,2.7,245.56]],"ltp":0.0,"tv":0.0,"id":8860646}]}]}
{"op":"mcm","clk":"1010444578","pt":1580675582086,"mc":[{"id":"1.168238843","rc":[{"batb":[[0,1.96,61.61],[1,1.01,15.52],[2,1.01,0]],"ltp":0.0,"tv":0.0,"id":8860646},{"batb":[[0,1.83,38.55],[1,1.01,15.52],[2,1.73,0]],"ltp":0.0,"tv":0.0,"id":8258569}]}]}
{"op":"mcm","clk":"1010445040","pt":1580675585969,"mc":[{"id":"1.168238843","rc":[{"batl":[[0,2.6,257.57]],"ltp":0.0,"tv":0.0,"id":8258569}]}]}
{"op":"mcm","clk":"1010446919","pt":1580675602212,"mc":[{"id":"1.168238843","rc":[{"batb":[[0,2.06,52.8],[1,2,57.91],[2,1.01,15.52]],"ltp":0.0,"tv":0.0,"id":8860646},{"batb":[[1,1.8,40.76],[2,1.01,15.52]],"ltp":0.0,"tv":0.0,"id":8258569}]}]}
{"op":"mcm","clk":"1010448509","pt":1580675615635,"mc":[{"id":"1.168238843","rc":[{"batb":[[0,2,57.91],[1,1.01,15.52],[2,1.01,0]],"ltp":0.0,"tv":0.0,"id":8860646},{"batb":[[0,1.8,40.76],[1,1.01,15.52],[2,1.01,0]],"ltp":0.0,"tv":0.0,"id":8258569}]}]}
{"op":"mcm","clk":"1010449609","pt":1580675625507,"mc":[{"id":"1.168238843","rc":[{"batl":[[0,2.4,289.78]],"ltp":0.0,"tv":0.0,"id":8258569}]}]}
{"op":"mcm","clk":"1010450909","pt":1580675637178,"mc":[{"id":"1.168238843","rc":[{"batb":[[0,2.1,49.73],[1,2.04,54.92],[2,1.01,15.52]],"ltp":0.0,"tv":0.0,"id":8860646},{"batb":[[1,1.77,42.49],[2,1.01,15.52]],"ltp":0.0,"tv":0.0,"id":8258569}]}]}
{"op":"mcm","clk":"1010452267","pt":1580675648199,"mc":[{"id":"1.168238843","rc":[{"batb":[[0,2.04,54.92],[1,1.01,15.52],[2,1.01,0]],"ltp":0.0,"tv":0.0,"id":8860646},{"batb":[[0,1.77,42.49],[1,1.01,15.52],[2,1.01,0]],"ltp":0.0,"tv":0.0,"id":8258569}]}]}
{"op":"mcm","clk":"1010454749","pt":1580675668680,"mc":[{"id":"1.168238843","rc":[{"batb":[[0,2.14,47.6],[1,2.08,51.54],[2,1.01,15.52]],"ltp":0.0,"tv":0.0,"id":8860646},{"batb":[[1,1.75,44.38],[2,1.01,15.52]],"ltp":0.0,"tv":0.0,"id":8258569}]}]}
{"op":"mcm","clk":"1010456394","pt":1580675681772,"mc":[{"id":"1.168238843","rc":[{"batb":[[0,2.08,51.54],[1,1.01,15.52],[2,1.01,0]],"ltp":0.0,"tv":0.0,"id":8860646},{"batb":[[0,1.75,44.38],[1,1.01,15.52],[2,1.01,0]],"ltp":0.0,"tv":0.0,"id":8258569}]}]}
{"op":"mcm","clk":"1010459363","pt":1580675704065,"mc":[{"id":"1.168238843","rc":[{"batb":[[0,2.18,45.48],[1,2.14,48],[2,2.1,15.14]],"ltp":0.0,"tv":0.0,"id":8860646},{"batb":[[1,1.7,48.86],[2,1.01,15.52]],"ltp":0.0,"tv":0.0,"id":8258569}]}]}
{"op":"mcm","clk":"1010459653","pt":1580675706166,"mc":[{"id":"1.168238843","rc":[{"batl":[[0,3,213.45]],"ltp":0.0,"tv":0.0,"id":8860646},{"batl":[[0,2.3,309.75]],"ltp":0.0,"tv":0.0,"id":8258569}]}]}
{"op":"mcm","clk":"1010462332","pt":1580675725212,"mc":[{"id":"1.168238843","rc":[{"batb":[[0,2.14,48],[1,1.01,15.52],[2,2.1,0]],"ltp":0.0,"tv":0.0,"id":8860646},{"batb":[[0,1.7,48.86],[1,1.01,15.52],[2,1.01,0]],"ltp":0.0,"tv":0.0,"id":8258569}]}]}
{"op":"mcm","clk":"1010462756","pt":1580675728198,"mc":[{"id":"1.168238843","rc":[{"batb":[[0,2.12,48.07]],"ltp":0.0,"tv":0.0,"id":8860646}]}]}
{"op":"mcm","clk":"1010465247","pt":1580675746013,"mc":[{"id":"1.168238843","rc":[{"batb":[[0,2.26,40.99],[1,2.2,43.75],[2,1.01,15.52]],"ltp":0.0,"tv":0.0,"id":8860646},{"batb":[[1,1.66,53.66],[2,1.01,15.52]],"ltp":0.0,"tv":0.0,"id":8258569}]}]}
{"op":"mcm","clk":"1010467824","pt":1580675764275,"mc":[{"id":"1.168238843","rc":[{"batb":[[0,2.2,43.75],[1,1.01,15.52],[2,1.01,0]],"ltp":0.0,"tv":0.0,"id":8860646},{"batb":[[0,1.66,53.66],[1,1.01,15.52],[2,1.01,0]],"ltp":0.0,"tv":0.0,"id":8258569}]}]}
{"op":"mcm","clk":"1010468250","pt":1580675767169,"mc":[{"id":"1.168238843","rc":[{"batb":[[1,2.18,44.61],[2,1.01,15.52]],"ltp":0.0,"tv":0.0,"id":8860646}]}]}
{"op":"mcm","clk":"1010468363","pt":1580675767864,"mc":[{"id":"1.168238843","rc":[{"batb":[[0,2.18,44.61],[1,1.01,15.52],[2,1.01,0]],"ltp":0.0,"tv":0.0,"id":8860646},{"batb":[[0,1.66,52.72]],"ltp":0.0,"tv":0.0,"id":8258569}]}]}
{"op":"mcm","clk":"1010471688","pt":1580675791215,"mc":[{"id":"1.168238843","rc":[{"batb":[[0,2.32,37.61],[1,2.26,40.44],[2,2.18,844.86]],"ltp":0.0,"tv":0.0,"id":8860646},{"batb":[[1,1.61,58.7],[2,1.01,15.52]],"ltp":0.0,"tv":0.0,"id":8258569}]}]}
{"op":"mcm","clk":"1010471701","pt":1580675791321,"mc":[{"id":"1.168238843","rc":[{"batb":[[2,1.01,15.52]],"ltp":0.0,"tv":0.0,"id":8860646}]}]}
{"op":"mcm","clk":"1010474138","pt":1580675809104,"mc":[{"id":"1.168238843","rc":[{"batb":[[0,2.26,40.44],[1,1.01,15.52],[2,1.01,0]],"ltp":0.0,"tv":0.0,"id":8860646},{"batb":[[0,1.61,58.7],[1,1.01,15.52],[2,1.01,0]],"ltp":0.0,"tv":0.0,"id":8258569}]}]}
{"op":"mcm","clk":"1010474496","pt":1580675811810,"mc":[{"id":"1.168238843","rc":[{"batb":[[0,1.62,58.46]],"ltp":0.0,"tv":0.0,"id":8258569}]}]}
{"op":"mcm","clk":"1010475356","pt":1580675818147,"mc":[{"id":"1.168238843","rc":[{"batb":[[1,2.2,43.43],[2,1.01,15.52]],"ltp":0.0,"tv":0.0,"id":8860646},{"batb":[[0,1.7,49.18],[1,1.64,55.16],[2,1.01,15.52]],"ltp":0.0,"tv":0.0,"id":8258569}]}]}
{"op":"mcm","clk":"1010477095","pt":1580675830989,"mc":[{"id":"1.168238843","rc":[{"batb":[[0,2.2,43.43],[1,1.01,15.52],[2,1.01,0]],"ltp":0.0,"tv":0.0,"id":8860646},{"batb":[[0,1.64,55],[1,1.01,15.52],[2,1.01,0]],"ltp":0.0,"tv":0.0,"id":8258569}]}]}
{"op":"mcm","clk":"1010482538","pt":1580675873227,"mc":[{"id":"1.168238843","rc":[{"batb":[[1,2.14,47.05],[2,1.01,15.52]],"ltp":0.0,"tv":0.0,"id":8860646},{"batb":[[0,1.73,46.11],[1,1.68,51.46],[2,1.01,15.52]],"ltp":0.0,"tv":0.0,"id":8258569}]}]}
{"op":"mcm","clk":"1010484560","pt":1580675889285,"mc":[{"id":"1.168238843","rc":[{"batb":[[0,2.14,47.05],[1,1.01,15.52],[2,1.01,0]],"ltp":0.0,"tv":0.0,"id":8860646},{"batb":[[0,1.68,51.46],[1,1.01,15.52],[2,1.01,0]],"ltp":0.0,"tv":0.0,"id":8258569}]}]}
{"op":"mcm","clk":"1010486284","pt":1580675902289,"mc":[{"id":"1.168238843","rc":[{"batb":[[1,2.1,49.96],[2,1.01,15.52]],"ltp":0.0,"tv":0.0,"id":8860646},{"batb":[[0,1.77,42.96],[1,1.72,47.29],[2,1.68,51.46]],"ltp":0.0,"tv":0.0,"id":8258569}]}]}
{"op":"mcm","clk":"1010486348","pt":1580675902802,"mc":[{"id":"1.168238843","rc":[{"batb":[[2,1.01,15.52]],"ltp":0.0,"tv":0.0,"id":8258569}]}]}
{"op":"mcm","clk":"1010488158","pt":1580675917016,"mc":[{"id":"1.168238843","rc":[{"batb":[[0,2.1,49.96],[1,1.01,15.52],[2,1.01,0]],"ltp":0.0,"tv":0.0,"id":8860646},{"batb":[[0,1.72,47.29],[1,1.01,15.52],[2,1.01,0]],"ltp":0.0,"tv":0.0,"id":8258569}]}]}
{"op":"mcm","clk":"1010490489","pt":1580675936250,"mc":[{"id":"1.168238843","rc":[{"batb":[[0,2.22,42.41],[1,2.16,45.56],[2,2.1,122.44]],"ltp":0.0,"tv":0.0,"id":8860646},{"batb":[[1,1.66,53.27],[2,1.01,15.52]],"ltp":0.0,"tv":0.0,"id":8258569}]}]}
{"op":"mcm","clk":"1010490608","pt":1580675937151,"mc":[{"id":"1.168238843","rc":[{"batb":[[2,1.01,15.52]],"ltp":0.0,"tv":0.0,"id":8860646}]}]}
{"op":"mcm","clk":"1010492384","pt":1580675950993,"mc":[{"id":"1.168238843","rc":[{"batb":[[0,2.16,45.56],[1,1.01,15.52],[2,1.01,0]],"ltp":0.0,"tv":0.0,"id":8860646},{"batb":[[0,1.66,53.27],[1,1.01,15.52],[2,1.01,0]],"ltp":0.0,"tv":0.0,"id":8258569}]}]}
{"op":"mcm","clk":"1010495275","pt":1580675973245,"mc":[{"id":"1.168238843","rc":[{"batb":[[1,2.12,48.63],[2,1.01,15.52]],"ltp":0.0,"tv":0.0,"id":8860646},{"batb":[[0,1.75,44.14],[1,1.7,48.55],[2,1.66,53.27]],"ltp":0.0,"tv":0.0,"id":8258569}]}]}
{"op":"mcm","clk":"1010495397","pt":1580675974238,"mc":[{"id":"1.168238843","rc":[{"batb":[[2,1.01,15.52]],"ltp":0.0,"tv":0.0,"id":8258569}]}]}
{"op":"mcm","clk":"1010497699","pt":1580675991549,"mc":[{"id":"1.168238843","rc":[{"batb":[[0,2.12,48.63],[1,1.01,15.52],[2,1.01,0]],"ltp":0.0,"tv":0.0,"id":8860646},{"batb":[[0,1.7,48.55],[1,1.01,15.52],[2,1.01,0]],"ltp":0.0,"tv":0.0,"id":8258569}]}]}
{"op":"mcm","clk":"1010498859","pt":1580676000258,"mc":[{"id":"1.168238843","rc":[{"batb":[[1,2.06,53.66],[2,1.01,15.52]],"ltp":0.0,"tv":0.0,"id":8860646},{"batb":[[0,1.78,41.62],[1,1.76,43.9],[2,1.01,15.52]],"ltp":0.0,"tv":0.0,"id":8258569}]}]}
{"op":"mcm","clk":"1010499945","pt":1580676008075,"mc":[{"id":"1.168238843","rc":[{"batb":[[0,2.12,48.15],[1,2.06,53.11]],"ltp":0.0,"tv":0.0,"id":8860646},{"batb":[[1,1.75,44.3]],"ltp":0.0,"tv":0.0,"id":8258569}]}]}
{"op":"mcm","clk":"1010501004","pt":1580676016203,"mc":[{"id":"1.168238843","rc":[{"batb":[[0,2.14,47.6],[1,2.06,52.56]],"ltp":0.0,"tv":0.0,"id":8860646},{"batb":[[0,1.77,42.49]],"ltp":0.0,"tv":0.0,"id":8258569}]}]}
{"op":"mcm","clk":"1010510750","pt":1580676089220,"mc":[{"id":"1.168238843","rc":[{"batb":[[0,2.06,52.56],[1,1.01,15.52],[2,1.01,0]],"ltp":0.0,"tv":0.0,"id":8860646},{"batb":[[0,1.75,44.3],[1,1.01,15.52],[2,1.01,0]],"ltp":0.0,"tv":0.0,"id":8258569}]}]}
{"op":"mcm","clk":"1010511166","pt":1580676092242,"mc":[{"id":"1.168238843","rc":[{"batb":[[0,2.08,52.01]],"ltp":0.0,"tv":0.0,"id":8860646},{"batb":[[0,1.74,45.08]],"ltp":0.0,"tv":0.0,"id":8258569}]}]}
{"op":"mcm","clk":"1010511974","pt":1580676098164,"mc":[{"id":"1.168238843","rc":[{"batb":[[0,2.18,44.61],[1,2.12,49.02],[2,2.08,52.01]],"ltp":0.0,"tv":0.0,"id":8860646},{"batb":[[1,1.72,47.29],[2,1.01,15.52]],"ltp":0.0,"tv":0.0,"id":8258569}]}]}
{"op":"mcm","clk":"1010512122","pt":1580676099128,"mc":[{"id":"1.168238843","rc":[{"batb":[[2,2.1,12.44]],"ltp":0.0,"tv":0.0,"id":8860646}]}]}
{"op":"mcm","clk":"1010513373","pt":1580676108255,"mc":[{"id":"1.168238843","rc":[{"batb":[[0,2.12,49.02],[1,1.01,15.52],[2,2.1,0]],"ltp":0.0,"tv":0.0,"id":8860646},{"batb":[[0,1.72,47.29],[1,1.01,15.52],[2,1.01,0]],"ltp":0.0,"tv":0.0,"id":8258569}]}]}
{"op":"mcm","clk":"1010514284","pt":1580676115061,"mc":[{"id":"1.168238843","rc":[{"batb":[[0,2.22,42.41],[1,2.14,59.5],[2,1.01,15.52]],"ltp":0.0,"tv":0.0,"id":8860646},{"batb":[[1,1.7,49.1],[2,1.01,15.52]],"ltp":0.0,"tv":0.0,"id":8258569}]}]}
{"op":"mcm","clk":"1010514396","pt":1580676116056,"mc":[{"id":"1.168238843","rc":[{"batb":[[1,2.14,46.97]],"ltp":0.0,"tv":0.0,"id":8860646}]}]}
{"op":"mcm","clk":"1010515641","pt":1580676125184,"mc":[{"id":"1.168238843","rc":[{"batb":[[0,2.14,46.97],[1,1.01,15.52],[2,1.01,0]],"ltp":0.0,"tv":0.0,"id":8860646},{"batb":[[0,1.7,49.1],[1,1.01,15.52],[2,1.01,0]],"ltp":0.0,"tv":0.0,"id":8258569}]}]}
{"op":"mcm","clk":"1010516940","pt":1580676135182,"mc":[{"id":"1.168238843","rc":[{"batb":[[1,2.08,51.85],[2,1.01,15.52]],"ltp":0.0,"tv":0.0,"id":8860646},{"batb":[[0,1.77,42.96],[1,1.74,45.56],[2,1.71,150.88]],"ltp":0.0,"tv":0.0,"id":8258569}]}]}
{"op":"mcm","clk":"1010517063","pt":1580676136118,"mc":[{"id":"1.168238843","rc":[{"batb":[[2,1.01,15.52]],"ltp":0.0,"tv":0.0,"id":8258569}]}]}
{"op":"mcm","clk":"1010518113","pt":1580676144006,"mc":[{"id":"1.168238843","rc":[{"batb":[[0,2.08,51.85],[1,1.01,15.52],[2,1.01,0]],"ltp":0.0,"tv":0.0,"id":8860646},{"batb":[[0,1.74,45.56],[1,1.01,15.52],[2,1.01,0]],"ltp":0.0,"tv":0.0,"id":8258569}]}]}
{"op":"mcm","clk":"1010521530","pt":1580676170263,"mc":[{"id":"1.168238843","rc":[{"batb":[[0,2.2,44.14],[1,2.12,48.39],[2,2.08,145.41]],"ltp":0.0,"tv":0.0,"id":8860646},{"batb":[[1,1.71,47.92],[2,1.01,15.52]],"ltp":0.0,"tv":0.0,"id":8258569}]}]}
{"op":"mcm","clk":"1010521547","pt":1580676170371,"mc":[{"id":"1.168238843","rc":[{"batb":[[2,2.08,93.56]],"ltp":0.0,"tv":0.0,"id":8860646}]}]}
{"op":"mcm","clk":"1010523452","pt":1580676185171,"mc":[{"id":"1.168238843","rc":[{"batb":[[0,2.12,48.39],[1,1.01,15.52],[2,2.08,0]],"ltp":0.0,"tv":0.0,"id":8860646},{"batb":[[0,1.71,47.92],[1,1.01,15.52],[2,1.01,0]],"ltp":0.0,"tv":0.0,"id":8258569}]}]}
{"op":"mcm","clk":"1010524726","pt":1580676195166,"mc":[{"id":"1.168238843","rc":[{"batb":[[0,2.24,41.78],[1,2.18,44.53],[2,2.12,48.39]],"ltp":0.0,"tv":0.0,"id":8860646},{"batb":[[1,1.66,52.87],[2,1.01,15.52]],"ltp":0.0,"tv":0.0,"id":8258569}]}]}
{"op":"mcm","clk":"1010524863","pt":1580676196074,"mc":[{"id":"1.168238843","rc":[{"batb":[[2,2.14,12.82]],"ltp":0.0,"tv":0.0,"id":8860646}]}]}
{"op":"mcm","clk":"1010528110","pt":1580676220781,"mc":[{"id":"1.168238843","rc":[{"batb":[[0,2.18,44.53],[1,1.01,15.52],[2,2.14,0]],"ltp":0.0,"tv":0.0,"id":8860646},{"batb":[[0,1.66,52.87],[1,1.01,15.52],[2,1.01,0]],"ltp":0.0,"tv":0.0,"id":8258569}]}]}
{"op":"mcm","clk":"1010530648","pt":1580676240163,"mc":[{"id":"1.168238843","rc":[{"batb":[[0,2.32,37.45],[1,2.26,40.29],[2,1.01,15.52]],"ltp":0.0,"tv":0.0,"id":8860646},{"batb":[[1,1.62,58.38],[2,1.01,15.52]],"ltp":0.0,"tv":0.0,"id":8258569}]}]}
{"op":"mcm","clk":"1010530796","pt":1580676241247,"mc":[{"id":"1.168238843","rc":[{"batb":[[2,2.2,13.17]],"ltp":0.0,"tv":0.0,"id":8860646}]}]}
{"op":"mcm","clk":"1010532605","pt":1580676255975,"mc":[{"id":"1.168238843","rc":[{"batb":[[0,2.26,40.29],[1,1.01,15.52],[2,2.2,0]],"ltp":0.0,"tv":0.0,"id":8860646},{"batb":[[0,1.62,57.83],[1,1.01,15.52],[2,1.01,0]],"ltp":0.0,"tv":0.0,"id":8258569}]}]}
{"op":"mcm","clk":"1010534746","pt":1580676273197,"mc":[{"id":"1.168238843","rc":[{"batb":[[0,2.42,33.83],[1,2.34,36.67],[2,2.3,13.48]],"ltp":0.0,"tv":0.0,"id":8860646},{"batb":[[1,1.57,64.76],[2,1.01,15.52]],"ltp":0.0,"tv":0.0,"id":8258569}]}]}
{"op":"mcm","clk":"1010535150","pt":1580676276214,"mc":[{"id":"1.168238843","rc":[{"batb":[[2,1.01,15.52]],"ltp":0.0,"tv":0.0,"id":8860646},{"batl":[[0,2.16,342.82]],"ltp":0.0,"tv":0.0,"id":8258569}]}]}
{"op":"mcm","clk":"1010536914","pt":1580676290249,"mc":[{"id":"1.168238843","rc":[{"batb":[[0,2.34,36.67],[1,1.01,15.52],[2,1.01,0]],"ltp":0.0,"tv":0.0,"id":8860646},{"batb":[[0,1.57,64.76],[1,1.01,15.52],[2,1.01,0]],"ltp":0.0,"tv":0.0,"id":8258569}]}]}
{"op":"mcm","clk":"1010537792","pt":1580676297147,"mc":[{"id":"1.168238843","rc":[{"batb":[[1,2.28,39.89],[2,1.01,15.52]],"ltp":0.0,"tv":0.0,"id":8860646},{"batb":[[0,1.65,53.82],[1,1.63,337.42],[2,1.6,60.59]],"ltp":0.0,"tv":0.0,"id":8258569}]}]}
{"op":"mcm","clk":"1010538639","pt":1580676304145,"mc":[{"id":"1.168238843","rc":[{"batb":[[0,2.28,39.89],[1,1.01,15.52],[2,1.01,0]],"ltp":0.0,"tv":0.0,"id":8860646},{"batb":[[0,1.6,60.59],[1,1.01,15.52],[2,1.6,0]],"ltp":0.0,"tv":0.0,"id":8258569}]}]}
{"op":"mcm","clk":"1010541300","pt":1580676327228,"mc":[{"id":"1.168238843","rc":[{"batb":[[1,2.22,43.04],[2,1.01,15.52]],"ltp":0.0,"tv":0.0,"id":8860646},{"batb":[[0,1.69,49.96],[1,1.64,308.32],[2,1.63,57.2]],"ltp":0.0,"tv":0.0,"id":8258569}]}]}
{"op":"mcm","clk":"1010543832","pt":1580676348209,"mc":[{"id":"1.168238843","rc":[{"batb":[[0,2.22,43.04],[1,1.01,15.52],[2,1.01,0]],"ltp":0.0,"tv":0.0,"id":8860646},{"batb":[[0,1.63,57.2],[1,1.01,15.52],[2,1.63,0]],"ltp":0.0,"tv":0.0,"id":8258569}]}]}
{"op":"mcm","clk":"1010544962","pt":1580676357205,"mc":[{"id":"1.168238843","rc":[{"batb":[[0,2.4,34.31],[1,2.3,38.79],[2,2.22,115.84]],"ltp":0.0,"tv":0.0,"id":8860646},{"batb":[[1,1.57,65.7],[2,1.01,15.52]],"ltp":0.0,"tv":0.0,"id":8258569}]}]}
{"op":"mcm","clk":"1010546820","pt":1580676373193,"mc":[{"id":"1.168238843","rc":[{"batb":[[2,1.01,15.52]],"ltp":0.0,"tv":0.0,"id":8860646}]}]}
{"op":"mcm","clk":"1010546910","pt":1580676374085,"mc":[{"id":"1.168238843","rc":[{"batb":[[0,2.3,38.79],[1,1.01,15.52],[2,1.01,0]],"ltp":0.0,"tv":0.0,"id":8860646},{"batb":[[0,1.57,65.38],[1,1.01,15.52],[2,1.01,0]],"ltp":0.0,"tv":0.0,"id":8258569}]}]}
{"op":"mcm","clk":"1010549727","pt":1580676398236,"mc":[{"id":"1.168238843","rc":[{"batb":[[0,2.54,29.35],[1,2.42,33.28],[2,2.32,110.64]],"ltp":0.0,"tv":0.0,"id":8860646},{"batb":[[1,1.55,68.77],[2,1.01,15.52]],"ltp":0.0,"tv":0.0,"id":8258569}]}]}
{"op":"mcm","clk":"1010549850","pt":1580676399239,"mc":[{"id":"1.168238843","rc":[{"batl":[[0,3.45,180.4]],"ltp":0.0,"tv":0.0,"id":8860646}]}]}
{"op":"mcm","clk":"1010549958","pt":1580676400129,"mc":[{"id":"1.168238843","rc":[{"batb":[[2,1.01,15.52]],"ltp":0.0,"tv":0.0,"id":8860646}]}]}
{"op":"mcm","clk":"1010552301","pt":1580676419797,"mc":[{"id":"1.168238843","rc":[{"batb":[[0,2.58,28.56],[1,2.46,32.34]],"ltp":0.0,"tv":0.0,"id":8860646},{"batb":[[0,1.56,66.96],[1,1.54,70.34]],"ltp":0.0,"tv":0.0,"id":8258569}]}]}
{"op":"mcm","clk":"1010559175","pt":1580676479977,"mc":[{"id":"1.168238843","rc":[{"batb":[[0,2.46,32.34],[1,1.01,15.52],[2,1.01,0]],"ltp":0.0,"tv":0.0,"id":8860646},{"batb":[[0,1.54,70.34],[1,1.01,15.52],[2,1.01,0]],"ltp":0.0,"tv":0.0,"id":8258569}]}]}
{"op":"mcm","clk":"1010560857","pt":1580676494196,"mc":[{"id":"1.168238843","rc":[{"batb":[[1,2.34,36.74],[2,1.01,15.52]],"ltp":0.0,"tv":0.0,"id":8860646},{"batb":[[0,1.6,60.27],[1,1.59,405.33],[2,1.58,63.89]],"ltp":0.0,"tv":0.0,"id":8258569}]}]}
{"op":"mcm","clk":"1010561128","pt":1580676496286,"mc":[{"id":"1.168238843","rc":[{"batl":[[0,3.3,191.92]],"ltp":0.0,"tv":0.0,"id":8860646},{"batb":[[1,1.58,63.89],[2,1.01,15.52]],"ltp":0.0,"tv":0.0,"id":8258569}]}]}
{"op":"mcm","clk":"1010562426","pt":1580676507020,"mc":[{"id":"1.168238843","rc":[{"batb":[[0,2.34,36.74],[1,1.01,15.52],[2,1.01,0]],"ltp":0.0,"tv":0.0,"id":8860646},{"batb":[[0,1.58,63.89],[1,1.01,15.52],[2,1.01,0]],"ltp":0.0,"tv":0.0,"id":8258569}]}]}
{"op":"mcm","clk":"1010564877","pt":1580676527149,"mc":[{"id":"1.168238843","rc":[{"batb":[[0,2.52,30.21],[1,2.4,34.46],[2,1.01,15.52]],"ltp":0.0,"tv":0.0,"id":8860646},{"batb":[[1,1.55,67.98],[2,1.01,15.52]],"ltp":0.0,"tv":0.0,"id":8258569}]}]}
{"op":"mcm","clk":"1010566950","pt":1580676545041,"mc":[{"id":"1.168238843","rc":[{"batb":[[0,2.4,34.46],[1,1.01,15.52],[2,1.01,0]],"ltp":0.0,"tv":0.0,"id":8860646},{"batb":[[0,1.55,67.98],[1,1.01,15.52],[2,1.01,0]],"ltp":0.0,"tv":0.0,"id":8258569}]}]}
{"op":"mcm","clk":"1010568693","pt":1580676560204,"mc":[{"id":"1.168238843","rc":[{"batb":[[1,2.28,39.42],[2,1.01,15.52]],"ltp":0.0,"tv":0.0,"id":8860646},{"batb":[[0,1.63,56.97],[1,1.6,60.51],[2,1.01,15.52]],"ltp":0.0,"tv":0.0,"id":8258569}]}]}
{"op":"mcm","clk":"1010571076","pt":1580676580473,"mc":[{"id":"1.168238843","rc":[{"batb":[[0,2.28,39.42],[1,1.01,15.52],[2,1.01,0]],"ltp":0.0,"tv":0.0,"id":8860646},{"batb":[[0,1.6,60.51],[1,1.01,15.52],[2,1.01,0]],"ltp":0.0,"tv":0.0,"id":8258569}]}]}
{"op":"mcm","clk":"1010572612","pt":1580676594288,"mc":[{"id":"1.168238843","rc":[{"batb":[[1,2.18,45.24],[2,1.01,15.52]],"ltp":0.0,"tv":0.0,"id":8860646},{"batb":[[0,1.69,50.51],[1,1.65,54.05],[2,1.6,60.51]],"ltp":0.0,"tv":0.0,"id":8258569}]}]}
{"op":"mcm","clk":"1010572653","pt":1580676594657,"mc":[{"id":"1.168238843","rc":[{"batb":[[2,1.01,15.52]],"ltp":0.0,"tv":0.0,"id":8258569}]}]}
{"op":"mcm","clk":"1010574375","pt":1580676609163,"mc":[{"id":"1.168238843","rc":[{"batb":[[0,2.18,45.24],[1,1.01,15.52],[2,1.01,0]],"ltp":0.0,"tv":0.0,"id":8860646},{"batb":[[0,1.65,54.05],[1,1.01,15.52],[2,1.01,0]],"ltp":0.0,"tv":0.0,"id":8258569}]}]}
{"op":"mcm","clk":"1010575547","pt":1580676618902,"mc":[{"id":"1.168238843","rc":[{"batb":[[0,2.34,36.51],[1,2.22,42.96],[2,2.2,70.92]],"ltp":0.0,"tv":0.0,"id":8860646},{"batb":[[1,1.61,59.01],[2,1.01,15.52]],"ltp":0.0,"tv":0.0,"id":8258569}]}]}
{"op":"mcm","clk":"1010576232","pt":1580676624933,"mc":[{"id":"1.168238843","rc":[{"batb":[[2,1.01,15.52]],"ltp":0.0,"tv":0.0,"id":8860646}]}]}
{"op":"mcm","clk":"1010577845","pt":1580676639243,"mc":[{"id":"1.168238843","rc":[{"batb":[[0,2.22,42.96],[1,1.01,15.52],[2,1.01,0]],"ltp":0.0,"tv":0.0,"id":8860646},{"batb":[[0,1.61,59.01],[1,1.01,15.52],[2,1.01,0]],"ltp":0.0,"tv":0.0,"id":8258569}]}]}
{"op":"mcm","clk":"1010578637","pt":1580676646144,"mc":[{"id":"1.168238843","rc":[{"batb":[[0,2.44,33.13],[1,2.3,38.32],[2,2.26,113.71]],"ltp":0.0,"tv":0.0,"id":8860646},{"batb":[[1,1.59,62.87],[2,1.01,15.52]],"ltp":0.0,"tv":0.0,"id":8258569}]}]}
{"op":"mcm","clk":"1010580165","pt":1580676660112,"mc":[{"id":"1.168238843","rc":[{"batb":[[0,2.3,38.32],[1,1.01,15.52],[2,2.26,0]],"ltp":0.0,"tv":0.0,"id":8860646},{"batb":[[0,1.59,62.87],[1,1.01,15.52],[2,1.01,0]],"ltp":0.0,"tv":0.0,"id":8258569}]}]}
{"op":"mcm","clk":"1010580511","pt":1580676663264,"mc":[{"id":"1.168238843","rc":[{"batb":[[0,1.01,15.52],[1,1.01,0]],"ltp":0.0,"tv":0.0,"id":8258569}]}]}
{"op":"mcm","clk":"1010580605","pt":1580676664149,"mc":[{"id":"1.168238843","rc":[{"batb":[[0,2.32,37.77]],"ltp":0.0,"tv":0.0,"id":8860646},{"batb":[[0,1.58,63.73],[1,1.01,15.52]],"ltp":0.0,"tv":0.0,"id":8258569}]}]}
{"op":"mcm","clk":"1010580927","pt":1580676667259,"mc":[{"id":"1.168238843","rc":[{"batb":[[0,2.52,30.21],[1,2.4,34.54],[2,1.01,15.52]],"ltp":0.0,"tv":0.0,"id":8860646},{"batb":[[1,1.55,67.59],[2,1.01,15.52]],"ltp":0.0,"tv":0.0,"id":8258569}]}]}
{"op":"mcm","clk":"1010582567","pt":1580676683245,"mc":[{"id":"1.168238843","rc":[{"batb":[[0,2.4,34.54],[1,1.01,15.52],[2,1.01,0]],"ltp":0.0,"tv":0.0,"id":8860646},{"batb":[[0,1.55,67.59],[1,1.01,15.52],[2,1.01,0]],"ltp":0.0,"tv":0.0,"id":8258569}]}]}
{"op":"mcm","clk":"1010583261","pt":1580676690277,"mc":[{"id":"1.168238843","rc":[{"batb":[[0,2.58,28.25],[1,2.5,30.53],[2,1.01,15.52]],"ltp":0.0,"tv":0.0,"id":8860646},{"batb":[[1,1.52,74.51],[2,1.01,15.52]],"ltp":0.0,"tv":0.0,"id":8258569}]}]}
{"op":"mcm","clk":"1010585350","pt":1580676713024,"mc":[{"id":"1.168238843","rc":[{"batb":[[0,2.5,30.53],[1,1.01,15.52],[2,1.01,0]],"ltp":0.0,"tv":0.0,"id":8860646},{"batb":[[0,1.52,74.51],[1,1.01,15.52],[2,1.01,0]],"ltp":0.0,"tv":0.0,"id":8258569}]}]}
{"op":"mcm","clk":"1010586395","pt":1580676724234,"mc":[{"id":"1.168238843","rc":[{"batb":[[1,2.46,32.1],[2,1.01,15.52]],"ltp":0.0,"tv":0.0,"id":8860646},{"batb":[[0,1.58,63.26],[1,1.54,69.87],[2,1.52,74.51]],"ltp":0.0,"tv":0.0,"id":8258569}]}]}
{"op":"mcm","clk":"1010586502","pt":1580676725223,"mc":[{"id":"1.168238843","rc":[{"batb":[[2,1.01,15.52]],"ltp":0.0,"tv":0.0,"id":8258569}]}]}
{"op":"mcm","clk":"1010587522","pt":1580676735056,"mc":[{"id":"1.168238843","rc":[{"batb":[[0,2.46,32.1],[1,1.01,15.52],[2,1.01,0]],"ltp":0.0,"tv":0.0,"id":8860646},{"batb":[[0,1.54,69.87],[1,1.01,15.52],[2,1.01,0]],"ltp":0.0,"tv":0.0,"id":8258569}]}]}
{"op":"mcm","clk":"1010588800","pt":1580676748596,"mc":[{"id":"1.168238843","rc":[{"batb":[[1,2.4,34.15],[2,1.01,15.52]],"ltp":0.0,"tv":0.0,"id":8860646},{"batb":[[0,1.6,60.59],[1,1.57,65.7],[2,1.01,15.52]],"ltp":0.0,"tv":0.0,"id":8258569}]}]}
{"op":"mcm","clk":"1010590287","pt":1580676762752,"mc":[{"id":"1.168238843","rc":[{"batb":[[0,2.4,34.15],[1,1.01,15.52],[2,1.01,0]],"ltp":0.0,"tv":0.0,"id":8860646},{"batb":[[0,1.57,65.7],[1,1.01,15.52],[2,1.01,0]],"ltp":0.0,"tv":0.0,"id":8258569}]}]}
{"op":"mcm","clk":"1010591579","pt":1580676774768,"mc":[{"id":"1.168238843","rc":[{"batb":[[0,2.54,29.19],[1,2.48,31.16],[2,1.01,15.52]],"ltp":0.0,"tv":0.0,"id":8860646},{"batb":[[1,1.53,72.23],[2,1.01,15.52]],"ltp":0.0,"tv":0.0,"id":8258569}]}]}
{"op":"mcm","clk":"1010592925","pt":1580676787371,"mc":[{"id":"1.168238843","rc":[{"batb":[[0,2.48,31.16],[1,1.01,15.52],[2,1.01,0]],"ltp":0.0,"tv":0.0,"id":8860646},{"batb":[[0,1.53,72.23],[1,1.01,15.52],[2,1.01,0]],"ltp":0.0,"tv":0.0,"id":8258569}]}]}
{"op":"mcm","clk":"1010593804","pt":1580676795720,"mc":[{"id":"1.168238843","rc":[{"batb":[[1,2.42,33.44],[2,1.01,15.52]],"ltp":0.0,"tv":0.0,"id":8860646},{"batb":[[0,1.59,62.08],[1,1.55,68.06],[2,1.01,15.52]],"ltp":0.0,"tv":0.0,"id":8258569}]}]}
{"op":"mcm","clk":"1010594891","pt":1580676806174,"mc":[{"id":"1.168238843","rc":[{"batb":[[0,2.42,33.44],[1,1.01,15.52],[2,1.01,0]],"ltp":0.0,"tv":0.0,"id":8860646},{"batb":[[0,1.55,68.06],[1,1.01,15.52],[2,1.01,0]],"ltp":0.0,"tv":0.0,"id":8258569}]}]}
{"op":"mcm","clk":"1010596563","pt":1580676823132,"mc":[{"id":"1.168238843","rc":[{"batb":[[1,2.32,37.77],[2,1.01,15.52]],"ltp":0.0,"tv":0.0,"id":8860646},{"batb":[[0,1.62,58.38],[1,1.59,62.63],[2,1.55,484.05]],"ltp":0.0,"tv":0.0,"id":8258569}]}]}
{"op":"mcm","clk":"1010596662","pt":1580676824144,"mc":[{"id":"1.168238843","rc":[{"batb":[[2,1.55,415.99]],"ltp":0.0,"tv":0.0,"id":8258569}]}]}
{"op":"mcm","clk":"1010604275","pt":1580676905853,"mc":[{"id":"1.168238843","rc":[{"batb":[[0,2.32,37.77],[1,1.01,15.52],[2,1.01,0]],"ltp":0.0,"tv":0.0,"id":8860646},{"batb":[[0,1.59,62.63],[1,1.01,15.52],[2,1.55,0]],"ltp":0.0,"tv":0.0,"id":8258569}]}]}
{"op":"mcm","clk":"1010605466","pt":1580676918072,"mc":[{"id":"1.168238843","rc":[{"batb":[[0,2.5,30.84],[1,2.38,35.33],[2,2.32,55.64]],"ltp":0.0,"tv":0.0,"id":8860646},{"batb":[[1,1.57,65.86],[2,1.01,15.52]],"ltp":0.0,"tv":0.0,"id":8258569}]}]}
{"op":"mcm","clk":"1010607095","pt":1580676934997,"mc":[{"id":"1.168238843","rc":[{"batb":[[0,2.38,35.33],[1,1.01,15.52],[2,2.32,0]],"ltp":0.0,"tv":0.0,"id":8860646},{"batb":[[0,1.57,65.86],[1,1.01,15.52],[2,1.01,0]],"ltp":0.0,"tv":0.0,"id":8258569}]}]}
{"op":"mcm","clk":"1010608816","pt":1580676954037,"mc":[{"id":"1.168238843","rc":[{"batb":[[0,2.56,29.11],[1,2.44,32.97],[2,1.01,15.52]],"ltp":0.0,"tv":0.0,"id":8860646},{"batb":[[1,1.54,70.11],[2,1.01,15.52]],"ltp":0.0,"tv":0.0,"id":8258569}]}]}
{"op":"mcm","clk":"1010610196","pt":1580676969061,"mc":[{"id":"1.168238843","rc":[{"batb":[[0,2.44,32.97],[1,1.01,15.52],[2,1.01,0]],"ltp":0.0,"tv":0.0,"id":8860646},{"batb":[[0,1.54,70.11],[1,1.01,15.52],[2,1.01,0]],"ltp":0.0,"tv":0.0,"id":8258569}]}]}
{"op":"mcm","clk":"1010612822","pt":1580676997169,"mc":[{"id":"1.168238843","rc":[{"batb":[[0,2.62,27.07],[1,2.5,30.69],[2,2.44,32.97]],"ltp":0.0,"tv":0.0,"id":8860646},{"batb":[[1,1.51,74.75],[2,1.01,15.52]],"ltp":0.0,"tv":0.0,"id":8258569}]}]}
{"op":"mcm","clk":"1010612904","pt":1580676998054,"mc":[{"id":"1.168238843","rc":[{"batb":[[2,1.01,15.52]],"ltp":0.0,"tv":0.0,"id":8860646}]}]}
{"op":"mcm","clk":"1010614714","pt":1580677019183,"mc":[{"id":"1.168238843","rc":[{"batb":[[0,2.5,30.69],[1,1.01,15.52],[2,1.01,0]],"ltp":0.0,"tv":0.0,"id":8860646},{"batb":[[0,1.51,74.75],[1,1.01,15.52],[2,1.01,0]],"ltp":0.0,"tv":0.0,"id":8258569}]}]}
{"op":"mcm","clk":"1010615409","pt":1580677027114,"mc":[{"id":"1.168238843","rc":[{"batb":[[0,2.7,25.02],[1,2.48,31.63],[2,1.01,15.52]],"ltp":0.0,"tv":0.0,"id":8860646},{"batb":[[0,1.58,477.44],[1,1.57,429.62],[2,1.51,74.75]],"batl":[[0,1.64,667.01],[1,1.65,354.49],[2,2.16,342.82]],"ltp":0.0,"tv":0.0,"id":8258569}]}]}
{"op":"mcm","clk":"1010616281","pt":1580677037247,"mc":[{"id":"1.168238843","rc":[{"batb":[[1,2.68,25.41],[2,2.48,31.63]],"ltp":0.0,"tv":0.0,"id":8860646},{"batb":[[2,1.52,73.72]],"ltp":0.0,"tv":0.0,"id":8258569}]}]}
{"op":"mcm","clk":"1010616310","pt":1580677037663,"mc":[{"id":"1.168238843","rc":[{"batb":[[0,2.68,25.41],[1,2.46,32.1],[2,1.01,15.52]],"ltp":0.0,"tv":0.0,"id":8860646}]}]}
{"op":"mcm","clk":"1010617847","pt":1580677055902,"mc":[{"id":"1.168238843","rc":[{"batb":[[0,2.66,25.89],[1,2.44,32.73]],"ltp":0.0,"tv":0.0,"id":8860646},{"batb":[[2,1.53,72.62]],"ltp":0.0,"tv":0.0,"id":8258569}]}]}
{"op":"mcm","clk":"1010618495","pt":1580677063088,"mc":[{"id":"1.168238843","rc":[{"batl":[[2,2.16,0]],"ltp":0.0,"tv":0.0,"id":8258569}]}]}
{"op":"mcm","clk":"1010618923","pt":1580677067284,"mc":[{"id":"1.168238843","rc":[{"batl":[[0,3.65,170.41]],"ltp":0.0,"tv":0.0,"id":8860646},{"batl":[[2,2.04,383.01]],"ltp":0.0,"tv":0.0,"id":8258569}]}]}
{"op":"mcm","clk":"1010625744","pt":1580677150253,"mc":[{"id":"1.168238843","rc":[{"batb":[[0,1.53,72.62],[1,1.42,96.63],[2,1.01,15.51]],"batl":[[0,2.04,383.01],[1,1.65,0],[2,2.04,0]],"ltp":0.0,"tv":0.0,"id":8258569}]}]}
{"op":"mcm","clk":"1010625812","pt":1580677151138,"mc":[{"id":"1.168238843","rc":[{"batb":[[0,2.44,32.73],[1,1.01,15.52],[2,1.01,0]],"ltp":0.0,"tv":0.0,"id":8860646},{"batb":[[0,1.42,96.63],[1,1.01,15.51],[2,1.01,0]],"ltp":0.0,"tv":0.0,"id":8258569}]}]}
{"op":"mcm","clk":"1010625983","pt":1580677153250,"mc":[{"id":"1.168238843","rc":[{"batb":[[0,1.47,438],[1,1.46,574.55],[2,1.42,96.62]],"batl":[[0,1.72,456.02],[1,1.74,596.18],[2,2.04,383.01]],"ltp":0.0,"tv":0.0,"id":8258569}]}]}
{"op":"mcm","clk":"1010626174","pt":1580677155851,"mc":[{"id":"1.168238843","rc":[{"batb":[[0,1.42,96.63],[1,1.01,15.51],[2,1.42,0]],"ltp":0.0,"tv":0.0,"id":8258569}]}]}
{"op":"mcm","clk":"1010626437","pt":1580677159055,"mc":[{"id":"1.168238843","rc":[{"batb":[[0,1.66,378.01],[1,1.65,357.2],[2,1.42,96.63]],"ltp":0.0,"tv":0.0,"id":8258569}]}]}
{"op":"mcm","clk":"1010626484","pt":1580677159675,"mc":[{"id":"1.168238843","rc":[{"batb":[[1,2.3,39.1],[2,1.01,15.52]],"ltp":0.0,"tv":0.0,"id":8860646},{"batb":[[2,1.61,59.56]],"ltp":0.0,"tv":0.0,"id":8258569}]}]}
{"op":"mcm","clk":"1010626698","pt":1580677162266,"mc":[{"id":"1.168238843","rc":[{"batl":[[0,3.3,191.92]],"ltp":0.0,"tv":0.0,"id":8860646}]}]}
{"op":"mcm","clk":"1010626788","pt":1580677163266,"mc":[{"id":"1.168238843","rc":[{"batb":[[0,1.61,59.56],[1,1.5,76.71],[2,1.01,15.52]],"batl":[[0,2.04,383.01],[1,1.74,0],[2,2.04,0]],"ltp":0.0,"tv":0.0,"id":8258569}]}]}
{"op":"mcm","clk":"1010626812","pt":1580677163669,"mc":[{"id":"1.168238843","rc":[{"batb":[[0,2.3,39.1],[1,1.01,15.52],[2,1.01,0]],"ltp":0.0,"tv":0.0,"id":8860646},{"batb":[[0,1.5,76.71],[1,1.01,15.52],[2,1.01,0]],"ltp":0.0,"tv":0.0,"id":8258569}]}]}
{"op":"mcm","clk":"1010627015","pt":1580677166182,"mc":[{"id":"1.168238843","rc":[{"batb":[[0,1.55,793.21],[1,1.54,464.37],[2,1.5,76.71]],"batl":[[0,1.8,579.38],[1,1.82,514.66],[2,2.04,383.01]],"ltp":0.0,"tv":0.0,"id":8258569}]}]}
{"op":"mcm","clk":"1010627085","pt":1580677167081,"mc":[{"id":"1.168238843","rc":[{"batb":[[0,1.5,76.71],[1,1.01,15.52],[2,1.5,0]],"batl":[[0,2.04,383.01],[1,1.82,0],[2,2.04,0]],"ltp":0.0,"tv":0.0,"id":8258569}]}]}
{"op":"mcm","clk":"1010627238","pt":1580677169280,"mc":[{"id":"1.168238843","rc":[{"batb":[[0,1.63,708.87],[1,1.62,382.86],[2,1.5,76.71]],"batl":[[0,1.7,566.08],[1,1.72,619.11],[2,2.04,383.01]],"ltp":0.0,"tv":0.0,"id":8258569}]}]}
{"op":"mcm","clk":"1010627444","pt":1580677172100,"mc":[{"id":"1.168238843","rc":[{"batb":[[0,1.5,76.71],[1,1.01,15.52],[2,1.5,0]],"batl":[[0,2.04,383.01],[1,1.72,0],[2,2.04,0]],"ltp":0.0,"tv":0.0,"id":8258569}]}]}
{"op":"mcm","clk":"1010627639","pt":1580677174575,"mc":[{"id":"1.168238843","rc":[{"batb":[[0,1.55,793.21],[1,1.54,464.37],[2,1.5,76.71]],"batl":[[0,1.8,579.38],[1,1.82,514.66],[2,2.04,383.01]],"ltp":0.0,"tv":0.0,"id":8258569}]}]}
{"op":"mcm","clk":"1010627921","pt":1580677178242,"mc":[{"id":"1.168238843","rc":[{"batb":[[0,1.5,76.71],[1,1.01,15.52],[2,1.5,0]],"ltp":0.0,"tv":0.0,"id":8258569}]}]}
{"op":"mcm","clk":"1010628060","pt":1580677180125,"mc":[{"id":"1.168238843","rc":[{"batl":[[2,2.04,0]],"ltp":0.0,"tv":0.0,"id":8258569}]}]}
{"op":"mcm","clk":"1010628134","pt":1580677181124,"mc":[{"id":"1.168238843","rc":[{"batb":[[0,1.72,622.61],[1,1.7,639.95],[2,1.5,76.71]],"ltp":0.0,"tv":0.0,"id":8258569}]}]}
{"op":"mcm","clk":"1010628215","pt":1580677182111,"mc":[{"id":"1.168238843","rc":[{"batb":[[1,2.2,44.22],[2,1.01,15.52]],"ltp":0.0,"tv":0.0,"id":8860646},{"batb":[[2,1.68,50.91]],"ltp":0.0,"tv":0.0,"id":8258569}]}]}
{"op":"mcm","clk":"1010628303","pt":1580677183208,"mc":[{"id":"1.168238843","rc":[{"batl":[[0,3,213.45]],"ltp":0.0,"tv":0.0,"id":8860646}]}]}
{"op":"mcm","clk":"1010628381","pt":1580677184252,"mc":[{"id":"1.168238843","rc":[{"batl":[[2,2.3,309.75]],"ltp":0.0,"tv":0.0,"id":8258569}]}]}
{"op":"mcm","clk":"1010628913","pt":1580677191240,"mc":[{"id":"1.168238843","rc":[{"batb":[[0,2.2,44.22],[1,1.01,15.52],[2,1.01,0]],"ltp":0.0,"tv":0.0,"id":8860646},{"batb":[[0,1.6,61.14],[1,1.01,15.52],[2,1.68,0]],"batl":[[0,2.3,309.75],[1,1.82,0],[2,2.3,0]],"ltp":0.0,"tv":0.0,"id":8258569}]}]}
{"op":"mcm","clk":"1010629141","pt":1580677194249,"mc":[{"id":"1.168238843","rc":[{"batb":[[0,1.65,449.29],[1,1.64,365.31],[2,1.6,61.14]],"batl":[[0,1.85,464.63],[1,1.87,472.8],[2,2.3,309.75]],"ltp":0.0,"tv":0.0,"id":8258569}]}]}
{"op":"mcm","clk":"1010629350","pt":1580677196852,"mc":[{"id":"1.168238843","rc":[{"batl":[[0,2.3,309.75],[1,1.87,0],[2,2.3,0]],"ltp":0.0,"tv":0.0,"id":8258569}]}]}
{"op":"mcm","clk":"1010629631","pt":1580677200220,"mc":[{"id":"1.168238843","rc":[{"batb":[[0,2.48,31.79],[1,2.3,38.55],[2,2.2,44.22]],"ltp":0.0,"tv":0.0,"id":8860646},{"batl":[[0,1.71,421.65],[1,1.73,607.9]],"ltp":0.0,"tv":0.0,"id":8258569}]}]}
{"op":"mcm","clk":"1010629666","pt":1580677200491,"mc":[{"id":"1.168238843","rc":[{"batb":[[2,1.01,15.52]],"ltp":0.0,"tv":0.0,"id":8860646}]}]}
{"op":"mcm","clk":"1010630004","pt":1580677203286,"mc":[{"id":"1.168238843","rc":[{"batl":[[2,2.16,342.82]],"ltp":0.0,"tv":0.0,"id":8258569}]}]}
{"op":"mcm","clk":"1010630580","pt":1580677209217,"mc":[{"id":"1.168238843","rc":[{"batb":[[0,2.48,31.85],[1,2.3,38.63],[2,1.01,15.52]],"batl":[[0,3,213.68]],"ltp":0.0,"tv":0.0,"id":8860646},{"batb":[[0,1.6,61.25],[1,1.47,83.18],[2,1.01,15.51]],"batl":[[0,2.16,343.19],[1,1.73,0],[2,2.16,0]],"ltp":0.0,"tv":0.0,"id":8258569}]}]}
{"op":"mcm","clk":"1010630645","pt":1580677209841,"mc":[{"id":"1.168238843","rc":[{"batb":[[0,2.3,38.63],[1,1.01,15.52],[2,1.01,0]],"ltp":0.0,"tv":0.0,"id":8860646},{"batb":[[0,1.47,83.18],[1,1.01,15.51],[2,1.01,0]],"ltp":0.0,"tv":0.0,"id":8258569}]}]}
{"op":"mcm","clk":"1010630918","pt":1580677212243,"mc":[{"id":"1.168238843","rc":[{"batb":[[0,1.53,649.74],[1,1.52,488.23],[2,1.47,83.18]],"batl":[[0,1.8,444.2],[1,1.82,515.04],[2,2.16,343.19]],"ltp":0.0,"tv":0.0,"id":8258569}]}]}
{"op":"mcm","clk":"1010631004","pt":1580677213221,"mc":[{"id":"1.168238843","rc":[{"batb":[[0,1.47,83.18],[1,1.01,15.51],[2,1.47,0]],"ltp":0.0,"tv":0.0,"id":8258569}]}]}
{"op":"mcm","clk":"1010631260","pt":1580677216245,"mc":[{"id":"1.168238843","rc":[{"batb":[[0,1.73,454.39],[1,1.71,626.41],[2,1.47,83.18]],"ltp":0.0,"tv":0.0,"id":8258569}]}]}
{"op":"mcm","clk":"1010631344","pt":1580677217141,"mc":[{"id":"1.168238843","rc":[{"batb":[[1,2.2,43.6],[2,1.01,15.52]],"ltp":0.0,"tv":0.0,"id":8860646},{"batb":[[2,1.68,51.64]],"ltp":0.0,"tv":0.0,"id":8258569}]}]}
{"op":"mcm","clk":"1010632148","pt":1580677226166,"mc":[{"id":"1.168238843","rc":[{"batb":[[0,2.2,43.6],[1,1.01,15.52],[2,1.01,0]],"ltp":0.0,"tv":0.0,"id":8860646},{"batb":[[0,1.59,62.12],[1,1.01,15.52],[2,1.68,0]],"batl":[[0,2.16,343.19],[1,1.82,0],[2,2.16,0]],"ltp":0.0,"tv":0.0,"id":8258569}]}]}
{"op":"mcm","clk":"1010632588","pt":1580677230934,"mc":[{"id":"1.168238843","rc":[{"batb":[[0,1.71,619.17],[1,1.69,653.24],[2,1.59,62.12]],"batl":[[0,1.78,350.78],[1,1.8,533.92],[2,2.16,343.19]],"ltp":0.0,"tv":0.0,"id":8258569}]}]}
{"op":"mcm","clk":"1010633011","pt":1580677235179,"mc":[{"id":"1.168238843","rc":[{"batb":[[0,1.59,62.12],[1,1.01,15.52],[2,1.59,0]],"batl":[[0,2.16,343.19],[1,1.8,0],[2,2.16,0]],"ltp":0.0,"tv":0.0,"id":8258569}]}]}
{"op":"mcm","clk":"1010633310","pt":1580677238153,"mc":[{"id":"1.168238843","rc":[{"batb":[[0,1.66,395.85],[1,1.65,357.23],[2,1.59,62.12]],"ltp":0.0,"tv":0.0,"id":8258569}]}]}
{"op":"mcm","clk":"1010633572","pt":1580677241081,"mc":[{"id":"1.168238843","rc":[{"batl":[[0,1.72,438.39],[1,1.74,596.22],[2,2.16,343.19]],"ltp":0.0,"tv":0.0,"id":8258569}]}]}
{"op":"mcm","clk":"1010633689","pt":1580677242284,"mc":[{"id":"1.168238843","rc":[{"batb":[[0,2.48,31.3],[1,2.28,39.34],[2,1.01,15.52]],"ltp":0.0,"tv":0.0,"id":8860646}]}]}
{"op":"mcm","clk":"1010634834","pt":1580677254208,"mc":[{"id":"1.168238843","rc":[{"batb":[[0,2.28,39.34],[1,1.01,15.52],[2,1.01,0]],"ltp":0.0,"tv":0.0,"id":8860646},{"batb":[[0,1.46,86.41],[1,1.01,15.51],[2,1.59,0]],"batl":[[0,2.16,343.19],[1,1.74,0],[2,2.16,0]],"ltp":0.0,"tv":0.0,"id":8258569}]}]}
{"op":"mcm","clk":"1010635118","pt":1580677257285,"mc":[{"id":"1.168238843","rc":[{"batb":[[0,1.52,807.92],[1,1.51,502.16],[2,1.46,86.41]],"batl":[[0,1.82,327.43],[1,1.84,497.7],[2,2.16,343.19]],"ltp":0.0,"tv":0.0,"id":8258569}]}]}
{"op":"mcm","clk":"1010635259","pt":1580677258918,"mc":[{"id":"1.168238843","rc":[{"batb":[[0,1.46,86.41],[1,1.01,15.51],[2,1.46,0]],"ltp":0.0,"tv":0.0,"id":8258569}]}]}
{"op":"mcm","clk":"1010635561","pt":1580677262195,"mc":[{"id":"1.168238843","rc":[{"batb":[[1,2.02,56.52],[2,1.01,15.52]],"ltp":0.0,"tv":0.0,"id":8860646},{"batb":[[0,1.75,515.07],[1,1.73,602],[2,1.68,50.61]],"ltp":0.0,"tv":0.0,"id":8258569}]}]}
{"op":"mcm","clk":"1010636432","pt":1580677271206,"mc":[{"id":"1.168238843","rc":[{"trd":[[1.75,277.58]],"batb":[[0,1.75,376.28]],"ltp":1.75,"tv":277.58,"id":8258569}],"tv":277.58}]}
{"op":"mcm","clk":"1010636732","pt":1580677275019,"mc":[{"id":"1.168238843","rc":[{"batb":[[0,1.75,464.42]],"ltp":1.75,"tv":277.58,"id":8258569}]}]}
{"op":"mcm","clk":"1010638681","pt":1580677299167,"mc":[{"id":"1.168238843","rc":[{"batb":[[0,1.68,50.61],[1,1.61,59.2],[2,1.01,15.52]],"batl":[[0,2.16,343.19],[1,1.84,0],[2,2.16,0]],"ltp":1.75,"tv":277.58,"id":8258569}]}]}
{"op":"mcm","clk":"1010638774","pt":1580677300162,"mc":[{"id":"1.168238843","rc":[{"batb":[[0,2.02,56.52],[1,1.01,15.52],[2,1.01,0]],"ltp":0.0,"tv":0.0,"id":8860646},{"batb":[[0,1.61,59.2],[1,1.01,15.52],[2,1.01,0]],"ltp":1.75,"tv":277.58,"id":8258569}]}]}
{"op":"mcm","clk":"1010638917","pt":1580677301881,"mc":[{"id":"1.168238843","rc":[{"batb":[[0,1.67,566.22],[1,1.66,350.13],[2,1.61,59.2]],"batl":[[0,2.02,406],[1,2.04,363.5],[2,2.16,343.19]],"ltp":1.75,"tv":277.58,"id":8258569}]}]}
{"op":"mcm","clk":"1010639457","pt":1580677308183,"mc":[{"id":"1.168238843","rc":[{"batl":[[0,2.16,343.19],[1,2.04,0],[2,2.16,0]],"ltp":1.75,"tv":277.58,"id":8258569}]}]}
{"op":"mcm","clk":"1010639697","pt":1580677311198,"mc":[{"id":"1.168238843","rc":[{"batb":[[0,2.44,33.03],[1,2.18,44.54],[2,2.02,56.52]],"ltp":0.0,"tv":0.0,"id":8860646},{"batl":[[0,1.74,540.79],[1,1.76,573.87],[2,2.16,343.19]],"ltp":1.75,"tv":277.58,"id":8258569}]}]}
{"op":"mcm","clk":"1010639778","pt":1580677312214,"mc":[{"id":"1.168238843","rc":[{"batb":[[2,1.01,15.52]],"ltp":0.0,"tv":0.0,"id":8860646}]}]}
{"op":"mcm","clk":"1010640596","pt":1580677322614,"mc":[{"id":"1.168238843","rc":[{"trd":[[1.67,20]],"batb":[[0,1.67,556.22]],"ltp":1.67,"tv":297.58,"id":8258569}],"tv":297.58}]}
{"op":"mcm","clk":"1010640772","pt":1580677324925,"mc":[{"id":"1.168238843","rc":[{"batb":[[0,2.18,44.54],[1,1.01,15.52],[2,1.01,0]],"ltp":0.0,"tv":0.0,"id":8860646},{"batb":[[0,1.56,67.01],[1,1.01,15.52],[2,1.61,0]],"batl":[[0,2.16,343.19],[1,1.76,0],[2,2.16,0]],"ltp":1.67,"tv":297.58,"id":8258569}]}]}
{"op":"mcm","clk":"1010641175","pt":1580677330120,"mc":[{"id":"1.168238843","rc":[{"batb":[[0,1.69,643.09],[1,1.67,681.53],[2,1.56,67.01]],"batl":[[0,1.76,396.12],[1,1.78,553.61],[2,2.16,343.19]],"ltp":1.67,"tv":297.58,"id":8258569}]}]}
{"op":"mcm","clk":"1010641326","pt":1580677332103,"mc":[{"id":"1.168238843","rc":[{"batb":[[0,1.56,67.01],[1,1.01,15.52],[2,1.56,0]],"batl":[[0,2.16,343.19],[1,1.78,0],[2,2.16,0]],"ltp":1.67,"tv":297.58,"id":8258569}]}]}
{"op":"mcm","clk":"1010641535","pt":1580677334742,"mc":[{"id":"1.168238843","rc":[{"batb":[[0,1.62,448.87],[1,1.61,390.93],[2,1.56,67.01]],"batl":[[0,1.87,439.64],[1,1.89,457.54],[2,2.16,343.19]],"ltp":1.67,"tv":297.58,"id":8258569}]}]}
{"op":"mcm","clk":"1010642043","pt":1580677341232,"mc":[{"id":"1.168238843","rc":[{"batl":[[0,2.16,343.19],[1,1.89,0],[2,2.16,0]],"ltp":1.67,"tv":297.58,"id":8258569}]}]}
{"op":"mcm","clk":"1010642291","pt":1580677344264,"mc":[{"id":"1.168238843","rc":[{"batl":[[0,1.68,530.56],[1,1.7,644.43],[2,2.16,343.19]],"ltp":1.67,"tv":297.58,"id":8258569}]}]}
{"op":"mcm","clk":"1010642352","pt":1580677344926,"mc":[{"id":"1.168238843","rc":[{"batb":[[0,2.56,28.62],[1,2.36,35.87],[2,1.01,15.52]],"ltp":0.0,"tv":0.0,"id":8860646}]}]}
{"op":"mcm","clk":"1010642493","pt":1580677346783,"mc":[{"id":"1.168238843","rc":[{"batl":[[0,3.45,180.6]],"ltp":0.0,"tv":0.0,"id":8860646}]}]}
{"op":"mcm","clk":"1010643211","pt":1580677355188,"mc":[{"id":"1.168238843","rc":[{"trd":[[1.62,83.26]],"batb":[[0,1.62,407.24]],"ltp":1.62,"tv":380.83,"id":8258569}],"tv":380.83}]}
{"op":"mcm","clk":"1010643986","pt":1580677364289,"mc":[{"id":"1.168238843","rc":[{"batb":[[0,2.36,35.87],[1,1.01,15.52],[2,1.01,0]],"ltp":0.0,"tv":0.0,"id":8860646},{"batb":[[0,1.52,73.95],[1,1.01,15.52],[2,1.56,0]],"batl":[[0,2.16,343.19],[1,1.7,0],[2,2.16,0]],"ltp":1.62,"tv":380.83,"id":8258569}]}]}
{"op":"mcm","clk":"1010644199","pt":1580677366894,"mc":[{"id":"1.168238843","rc":[{"batb":[[0,1.58,765.13],[1,1.57,431],[2,1.52,73.95]],"batl":[[0,1.76,581.21],[1,1.78,553.01],[2,2.16,343.19]],"ltp":1.62,"tv":380.83,"id":8258569}]}]}
{"op":"mcm","clk":"1010644271","pt":1580677367725,"mc":[{"id":"1.168238843","rc":[{"batl":[[0,2.16,343.19],[1,1.78,0],[2,2.16,0]],"ltp":1.62,"tv":380.83,"id":8258569}]}]}
{"op":"mcm","clk":"1010644605","pt":1580677371224,"mc":[{"id":"1.168238843","rc":[{"batb":[[0,2.68,25.46],[1,2.52,30.11],[2,2.4,106.91]],"ltp":0.0,"tv":0.0,"id":8860646},{"batl":[[0,1.64,397.2],[1,1.65,355.58]],"ltp":1.62,"tv":380.83,"id":8258569}]}]}
{"op":"mcm","clk":"1010644621","pt":1580677371427,"mc":[{"id":"1.168238843","rc":[{"batb":[[2,1.01,15.52]],"ltp":0.0,"tv":0.0,"id":8860646}]}]}
{"op":"mcm","clk":"1010644797","pt":1580677373246,"mc":[{"id":"1.168238843","rc":[{"batl":[[2,2.04,383.43]],"ltp":1.62,"tv":380.83,"id":8258569}]}]}
{"op":"mcm","clk":"1010645207","pt":1580677378135,"mc":[{"id":"1.168238843","rc":[{"batb":[[0,1.57,431],[1,1.52,73.95],[2,1.5,78.52]],"batl":[[0,2.04,383.43],[1,1.65,0],[2,2.04,0]],"ltp":1.62,"tv":380.83,"id":8258569}]}]}
{"op":"mcm","clk":"1010645255","pt":1580677378749,"mc":[{"id":"1.168238843","rc":[{"batb":[[0,2.52,30.11],[1,1.01,15.52],[2,1.01,0]],"ltp":0.0,"tv":0.0,"id":8860646},{"batb":[[1,1.5,78.52],[2,1.01,15.52]],"ltp":1.62,"tv":380.83,"id":8258569}]}]}
{"op":"mcm","clk":"1010645458","pt":1580677380937,"mc":[{"id":"1.168238843","rc":[{"batb":[[1,1.56,440.46],[2,1.5,78.52]],"batl":[[0,1.68,395.9],[1,1.7,645.31],[2,2.04,383.43]],"ltp":1.62,"tv":380.83,"id":8258569}]}]}
{"op":"mcm","clk":"1010645939","pt":1580677385284,"mc":[{"id":"1.168238843","rc":[{"batl":[[0,2.04,383.43],[1,1.7,0],[2,2.04,0]],"ltp":1.62,"tv":380.83,"id":8258569}]}]}
{"op":"mcm","clk":"1010646171","pt":1580677388165,"mc":[{"id":"1.168238843","rc":[{"trd":[[2.76,23.65]],"ltp":2.76,"tv":23.65,"id":8860646},{"trd":[[1.57,41.58]],"batb":[[0,1.57,389.42]],"batl":[[0,1.63,700.49],[1,1.64,362.15],[2,2.04,383.43]],"ltp":1.57,"tv":422.41,"id":8258569}],"tv":446.06}]}
{"op":"mcm","clk":"1010646237","pt":1580677388984,"mc":[{"id":"1.168238843","rc":[{"batb":[[0,2.52,29.96]],"ltp":2.76,"tv":23.65,"id":8860646},{"batl":[[0,1.63,371.49],[1,2.04,383.43],[2,2.04,0]],"ltp":1.57,"tv":422.41,"id":8258569}]}]}
{"op":"mcm","clk":"1010646461","pt":1580677391995,"mc":[{"id":"1.168238843","rc":[{"batl":[[0,1.62,385.9],[1,1.63,371.49],[2,2.04,383.43]],"ltp":1.57,"tv":422.41,"id":8258569}]}]}
{"op":"mcm","clk":"1010647668","pt":1580677405994,"mc":[{"id":"1.168238843","rc":[{"batb":[[0,1.39,107.46],[1,1.01,15.51],[2,1.5,0]],"batl":[[0,2.04,383.43],[1,1.63,0],[2,2.04,0]],"ltp":1.57,"tv":422.41,"id":8258569}]}]}
{"op":"mcm","clk":"1010647842","pt":1580677408185,"mc":[{"id":"1.168238843","rc":[{"batb":[[0,1.45,697.02],[1,1.44,612.23],[2,1.39,107.45]],"batl":[[0,1.71,394.83],[1,1.73,608.47],[2,2.04,383.43]],"ltp":1.57,"tv":422.41,"id":8258569}]}]}
{"op":"mcm","clk":"1010647913","pt":1580677409012,"mc":[{"id":"1.168238843","rc":[{"batb":[[0,2.48,31.61]],"ltp":2.76,"tv":23.65,"id":8860646},{"batb":[[2,1.41,102.72]],"ltp":1.57,"tv":422.41,"id":8258569}]}]}
{"op":"mcm","clk":"1010648666","pt":1580677419127,"mc":[{"id":"1.168238843","rc":[{"batl":[[0,2.04,383.43],[1,1.73,0],[2,2.04,0]],"ltp":1.57,"tv":422.41,"id":8258569}]}]}
{"op":"mcm","clk":"1010648934","pt":1580677422254,"mc":[{"id":"1.168238843","rc":[{"batl":[[0,1.5,741.84],[1,1.51,491.92]],"ltp":1.57,"tv":422.41,"id":8258569}]}]}
{"op":"mcm","clk":"1010648996","pt":1580677423131,"mc":[{"id":"1.168238843","rc":[{"trd":[[3.1,0]],"batb":[[0,3.15,42.64],[1,2.78,23.18],[2,1.01,15.52]],"ltp":3.1,"tv":23.65,"id":8860646},{"trd":[[1.48,0.01]],"batb":[[0,1.45,697.01]],"ltp":1.48,"tv":422.42,"id":8258569}],"tv":446.08}]}
{"op":"mcm","clk":"1010649146","pt":1580677425151,"mc":[{"id":"1.168238843","rc":[{"batl":[[0,4.6,136.2]],"ltp":3.1,"tv":23.65,"id":8860646},{"batl":[[2,1.82,469.62]],"ltp":1.48,"tv":422.42,"id":8258569}]}]}
{"op":"mcm","clk":"1010650239","pt":1580677437858,"mc":[{"id":"1.168238843","rc":[{"batb":[[0,2.78,23.18],[1,1.01,15.52],[2,1.01,0]],"ltp":3.1,"tv":23.65,"id":8860646},{"batb":[[0,1.29,157.9],[1,1.01,15.51],[2,1.41,0]],"batl":[[0,1.82,469.62],[1,1.51,0],[2,1.82,0]],"ltp":1.48,"tv":422.42,"id":8258569}]}]}
{"op":"mcm","clk":"1010650492","pt":1580677441201,"mc":[{"id":"1.168238843","rc":[{"batb":[[0,1.32,1179.5],[1,1.31,969.25],[2,1.29,157.9]],"batl":[[0,1.6,594.01],[1,1.61,387.37],[2,1.82,469.62]],"ltp":1.48,"tv":422.42,"id":8258569}]}]}
{"op":"mcm","clk":"1010650657","pt":1580677443275,"mc":[{"id":"1.168238843","rc":[{"batb":[[0,1.29,157.9],[1,1.01,15.51],[2,1.29,0]],"ltp":1.48,"tv":422.42,"id":8258569}]}]}
{"op":"mcm","clk":"1010650886","pt":1580677445989,"mc":[{"id":"1.168238843","rc":[{"batb":[[0,1.54,762.62],[1,1.53,476.68],[2,1.29,157.9]],"ltp":1.48,"tv":422.42,"id":8258569}]}]}
{"op":"mcm","clk":"1010650993","pt":1580677447286,"mc":[{"id":"1.168238843","rc":[{"batb":[[1,2.5,30.75],[2,1.01,15.52]],"ltp":3.1,"tv":23.65,"id":8860646},{"batb":[[2,1.5,79.39]],"ltp":1.48,"tv":422.42,"id":8258569}]}]}
{"op":"mcm","clk":"1010651064","pt":1580677448116,"mc":[{"id":"1.168238843","rc":[{"batl":[[0,3.9,158.42]],"ltp":3.1,"tv":23.65,"id":8860646}]}]}
{"op":"mcm","clk":"1010651538","pt":1580677454196,"mc":[{"id":"1.168238843","rc":[{"batb":[[0,2.5,30.75],[1,1.01,15.52],[2,1.01,0]],"ltp":3.1,"tv":23.65,"id":8860646},{"batb":[[0,1.37,117.3],[1,1.01,15.51],[2,1.5,0]],"batl":[[0,1.82,469.62],[1,1.61,0],[2,1.82,0]],"ltp":1.48,"tv":422.42,"id":8258569}]}]}
{"op":"mcm","clk":"1010652053","pt":1580677460130,"mc":[{"id":"1.168238843","rc":[{"batb":[[0,1.51,829.51],[1,1.5,516.52],[2,1.37,117.3]],"batl":[[0,1.57,699.13],[1,1.58,414.36],[2,1.82,469.62]],"ltp":1.48,"tv":422.42,"id":8258569}]}]}
{"op":"mcm","clk":"1010652280","pt":1580677463235,"mc":[{"id":"1.168238843","rc":[{"batb":[[0,1.37,117.3],[1,1.01,15.51],[2,1.37,0]],"batl":[[0,1.82,469.62],[1,1.58,0],[2,1.82,0]],"ltp":1.48,"tv":422.42,"id":8258569}]}]}
{"op":"mcm","clk":"1010652513","pt":1580677466221,"mc":[{"id":"1.168238843","rc":[{"batb":[[0,1.41,542.38],[1,1.4,692.53],[2,1.37,117.3]],"batl":[[0,1.71,612.26],[1,1.73,607.4],[2,1.82,469.62]],"ltp":1.48,"tv":422.42,"id":8258569}]}]}
{"op":"mcm","clk":"1010652574","pt":1580677466938,"mc":[{"id":"1.168238843","rc":[{"batl":[[0,1.82,469.62],[1,1.73,0],[2,1.82,0]],"ltp":1.48,"tv":422.42,"id":8258569}]}]}
{"op":"mcm","clk":"1010652809","pt":1580677469960,"mc":[{"id":"1.168238843","rc":[{"batl":[[0,1.45,613.3],[1,1.46,564.37],[2,1.82,469.62]],"ltp":1.48,"tv":422.42,"id":8258569}]}]}
{"op":"mcm","clk":"1010652930","pt":1580677471251,"mc":[{"id":"1.168238843","rc":[{"batb":[[0,3.35,35.87],[1,2.88,21.36],[2,1.01,15.52]],"ltp":3.1,"tv":23.65,"id":8860646}]}]}
{"op":"mcm","clk":"1010653078","pt":1580677472927,"mc":[{"id":"1.168238843","rc":[{"batl":[[0,4.9,126.41]],"ltp":3.1,"tv":23.65,"id":8860646}]}]}
{"op":"mcm","clk":"1010654378","pt":1580677489283,"mc":[{"id":"1.168238843","rc":[{"batb":[[0,2.88,21.36],[1,1.01,15.52],[2,1.01,0]],"ltp":3.1,"tv":23.65,"id":8860646},{"batb":[[0,1.23,204.18],[1,1.01,15.51],[2,1.37,0]],"batl":[[0,1.82,469.62],[1,1.46,0],[2,1.82,0]],"ltp":1.48,"tv":422.42,"id":8258569}]}]}
{"op":"mcm","clk":"1010654628","pt":1580677492193,"mc":[{"id":"1.168238843","rc":[{"batb":[[1,2.86,21.52],[2,1.01,15.52]],"ltp":3.1,"tv":23.65,"id":8860646},{"batb":[[0,1.26,1014.59],[1,1.25,1261.14],[2,1.23,204.18]],"batl":[[0,1.57,413.95],[1,1.58,415.73],[2,1.82,469.62]],"ltp":1.48,"tv":422.42,"id":8258569}]}]}
{"op":"mcm","clk":"1010654722","pt":1580677493181,"mc":[{"id":"1.168238843","rc":[{"batb":[[0,2.86,21.52],[1,1.01,15.52],[2,1.01,0]],"ltp":3.1,"tv":23.65,"id":8860646},{"batb":[[2,1.23,203.23]],"ltp":1.48,"tv":422.42,"id":8258569}]}]}
{"op":"mcm","clk":"1010656021","pt":1580677507112,"mc":[{"id":"1.168238843","rc":[{"batl":[[0,1.82,469.62],[1,1.58,0],[2,1.82,0]],"ltp":1.48,"tv":422.42,"id":8258569}]}]}
{"op":"mcm","clk":"1010656333","pt":1580677510141,"mc":[{"id":"1.168238843","rc":[{"batl":[[0,1.29,785.15],[1,1.3,964.89]],"ltp":1.48,"tv":422.42,"id":8258569}]}]}
{"op":"mcm","clk":"1010656416","pt":1580677510922,"mc":[{"id":"1.168238843","rc":[{"batb":[[0,4.6,33.43],[1,3.75,27.12],[2,1.01,15.52]],"ltp":3.1,"tv":23.65,"id":8860646}]}]}
{"op":"mcm","clk":"1010656671","pt":1580677513241,"mc":[{"id":"1.168238843","rc":[{"batl":[[0,6.6,99.06]],"ltp":3.1,"tv":23.65,"id":8860646},{"batl":[[2,1.62,615.07]],"ltp":1.48,"tv":422.42,"id":8258569}]}]}
{"op":"mcm","clk":"1010657107","pt":1580677517239,"mc":[{"id":"1.168238843","rc":[{"batb":[[0,1.26,802.84]],"ltp":1.48,"tv":422.42,"id":8258569}]}]}
{"op":"mcm","clk":"1010657336","pt":1580677519231,"mc":[{"id":"1.168238843","rc":[{"batl":[[0,1.29,991.32]],"ltp":1.48,"tv":422.42,"id":8258569}]}]}
{"op":"mcm","clk":"1010657440","pt":1580677520222,"mc":[{"id":"1.168238843","rc":[{"batb":[[0,1.26,652.94]],"ltp":1.48,"tv":422.42,"id":8258569}]}]}
{"op":"mcm","clk":"1010657717","pt":1580677523040,"mc":[{"id":"1.168238843","rc":[{"batl":[[0,1.29,1137.7]],"ltp":1.48,"tv":422.42,"id":8258569}]}]}
{"op":"mcm","clk":"1010658321","pt":1580677529158,"mc":[{"id":"1.168238843","rc":[{"trd":[[1.26,16.82]],"batb":[[0,1.26,644.53]],"ltp":1.26,"tv":439.24,"id":8258569}],"tv":462.9}]}
{"op":"mcm","clk":"1010658514","pt":1580677531241,"mc":[{"id":"1.168238843","rc":[{"batb":[[0,3.75,27.12],[1,1.01,15.52],[2,1.01,0]],"ltp":3.1,"tv":23.65,"id":8860646},{"batb":[[0,1.13,384.95],[1,1.01,15.51],[2,1.23,0]],"batl":[[0,1.62,615.07],[1,1.3,0],[2,1.62,0]],"ltp":1.26,"tv":439.24,"id":8258569}]}]}
{"op":"mcm","clk":"1010659132","pt":1580677537181,"mc":[{"id":"1.168238843","rc":[{"batb":[[0,1.23,1461.74],[1,1.22,1493.63],[2,1.13,384.95]],"batl":[[0,1.26,842.88],[1,1.27,1103.27],[2,1.62,615.07]],"ltp":1.26,"tv":439.24,"id":8258569}]}]}
{"op":"mcm","clk":"1010659525","pt":1580677541249,"mc":[{"id":"1.168238843","rc":[{"batb":[[0,1.13,384.95],[1,1.01,15.51],[2,1.13,0]],"batl":[[0,1.62,615.07],[1,1.27,0],[2,1.62,0]],"ltp":1.26,"tv":439.24,"id":8258569}]}]}
{"op":"mcm","clk":"1010659823","pt":1580677544278,"mc":[{"id":"1.168238843","rc":[{"batb":[[0,1.14,2644.16],[1,1.13,1104.64],[2,1.01,15.51]],"batl":[[0,1.38,663.96],[1,1.39,701.92],[2,1.62,615.07]],"ltp":1.26,"tv":439.24,"id":8258569}]}]}
{"op":"mcm","clk":"1010662446","pt":1580677570944,"mc":[{"id":"1.168238843","rc":[{"batb":[[0,1.13,384.95],[1,1.01,15.51],[2,1.01,0]],"ltp":1.26,"tv":439.24,"id":8258569}]}]}
{"op":"mcm","clk":"1010662792","pt":1580677574080,"mc":[{"id":"1.168238843","rc":[{"batb":[[0,1.34,1103.79],[1,1.33,899.92],[2,1.13,384.95]],"ltp":1.26,"tv":439.24,"id":8258569}]}]}
{"op":"mcm","clk":"1010662880","pt":1580677574753,"mc":[{"id":"1.168238843","rc":[{"batb":[[1,2.9,52.66],[2,1.01,15.52]],"ltp":3.1,"tv":23.65,"id":8860646},{"batb":[[2,1.31,143.95]],"ltp":1.26,"tv":439.24,"id":8258569}]}]}
{"op":"mcm","clk":"1010663168","pt":1580677577241,"mc":[{"id":"1.168238843","rc":[{"batl":[[0,5.5,115.18]],"ltp":3.1,"tv":23.65,"id":8860646}]}]}
{"op":"mcm","clk":"1010665100","pt":1580677595273,"mc":[{"id":"1.168238843","rc":[{"batb":[[0,2.9,52.66],[1,1.01,15.52],[2,1.01,0]],"ltp":3.1,"tv":23.65,"id":8860646},{"batb":[[0,1.14,365.24],[1,1.01,15.51],[2,1.31,0]],"batl":[[0,1.62,615.07],[1,1.39,0],[2,1.62,0]],"ltp":1.26,"tv":439.24,"id":8258569}]}]}
{"op":"mcm","clk":"1010665385","pt":1580677597977,"mc":[{"id":"1.168238843","rc":[{"batb":[[0,1.15,908.94],[1,1.14,2805.86],[2,1.01,15.51]],"batl":[[0,1.56,521.74],[1,1.57,427.39]],"ltp":1.26,"tv":439.24,"id":8258569}]}]}
{"op":"mcm","clk":"1010666334","pt":1580677607288,"mc":[{"id":"1.168238843","rc":[{"batl":[[0,1.17,1590.99],[1,1.18,1667.34]],"ltp":1.26,"tv":439.24,"id":8258569}]}]}
{"op":"mcm","clk":"1010666419","pt":1580677608078,"mc":[{"id":"1.168238843","rc":[{"batb":[[0,6.8,27.36],[1,5.2,25.62],[2,2.9,52.66]],"ltp":3.1,"tv":23.65,"id":8860646},{"batb":[[2,1.11,451.4]],"ltp":1.26,"tv":439.24,"id":8258569}]}]}
{"op":"mcm","clk":"1010666439","pt":1580677608291,"mc":[{"id":"1.168238843","rc":[{"batb":[[2,1.01,15.52]],"ltp":3.1,"tv":23.65,"id":8860646}]}]}
{"op":"mcm","clk":"1010666639","pt":1580677610290,"mc":[{"id":"1.168238843","rc":[{"batb":[[2,3.35,822.07]],"batl":[[0,10.5,72.4]],"ltp":3.1,"tv":23.65,"id":8860646},{"batl":[[2,1.48,785.79]],"ltp":1.26,"tv":439.24,"id":8258569}]}]}
{"op":"mcm","clk":"1010668556","pt":1580677628729,"mc":[{"id":"1.168238843","rc":[{"batb":[[1,1.14,2688.38]],"batl":[[0,1.17,1475.4]],"ltp":1.26,"tv":439.24,"id":8258569}]}]}
{"op":"mcm","clk":"1010668925","pt":1580677632019,"mc":[{"id":"1.168238843","rc":[{"batb":[[0,1.15,916.13]],"ltp":1.26,"tv":439.24,"id":8258569}]}]}
{"op":"mcm","clk":"1010669241","pt":1580677634837,"mc":[{"id":"1.168238843","rc":[{"batb":[[1,1.14,2799.77]],"batl":[[0,1.17,1583.87]],"ltp":1.26,"tv":439.24,"id":8258569}]}]}
{"op":"mcm","clk":"1010669347","pt":1580677635939,"mc":[{"id":"1.168238843","rc":[{"batl":[[0,12,67.85]],"ltp":3.1,"tv":23.65,"id":8860646}]}]}
{"op":"mcm","clk":"1010669596","pt":1580677638251,"mc":[{"id":"1.168238843","rc":[{"batb":[[0,6.8,27.04],[1,5.2,25.38]],"ltp":3.1,"tv":23.65,"id":8860646},{"batb":[[1,1.14,2434.53],[2,1.13,367.52]],"ltp":1.26,"tv":439.24,"id":8258569}]}]}
{"op":"mcm","clk":"1010672113","pt":1580677661995,"mc":[{"id":"1.168238843","rc":[{"batb":[[0,7,24.91],[1,5.4,23.41]],"ltp":3.1,"tv":23.65,"id":8860646}]}]}
{"op":"mcm","clk":"1010677092","pt":1580677712177,"mc":[{"id":"1.168238843","rc":[{"batb":[[1,1.14,2324.99]],"batl":[[0,1.17,1477.45]],"ltp":1.26,"tv":439.24,"id":8258569}]}]}
{"op":"mcm","clk":"1010677291","pt":1580677714073,"mc":[{"id":"1.168238843","rc":[{"batb":[[0,5.4,23.41],[1,1.01,15.52],[2,3.35,0]],"ltp":3.1,"tv":23.65,"id":8860646},{"batb":[[0,1.1,477.65],[1,1.01,15.51],[2,1.13,0]],"batl":[[0,1.48,785.79],[1,1.18,0],[2,1.48,0]],"ltp":1.26,"tv":439.24,"id":8258569}]}]}
{"op":"mcm","clk":"1010677414","pt":1580677715170,"mc":[{"id":"1.168238843","rc":[{"batb":[[0,1.15,108.6],[1,1.1,477.65],[2,1.01,15.51]],"ltp":1.26,"tv":439.24,"id":8258569}]}]}
{"op":"mcm","clk":"1010677489","pt":1580677716009,"mc":[{"id":"1.168238843","rc":[{"batb":[[0,1.1,477.65],[1,1.01,15.51],[2,1.01,0]],"ltp":1.26,"tv":439.24,"id":8258569}]}]}
{"op":"mcm","clk":"1010677563","pt":1580677716796,"mc":[{"id":"1.168238843","rc":[{"batb":[[0,1.12,2592.37],[1,1.11,833.75],[2,1.1,477.65]],"batl":[[0,1.23,896.61],[1,1.24,1266.89],[2,1.48,785.79]],"ltp":1.26,"tv":439.24,"id":8258569}]}]}
{"op":"mcm","clk":"1010677799","pt":1580677719284,"mc":[{"id":"1.168238843","rc":[{"batb":[[0,1.1,477.65],[1,1.01,15.51],[2,1.1,0]],"batl":[[0,1.48,785.79],[1,1.24,0],[2,1.48,0]],"ltp":1.26,"tv":439.24,"id":8258569}]}]}
{"op":"mcm","clk":"1010678093","pt":1580677722173,"mc":[{"id":"1.168238843","rc":[{"batb":[[0,1.16,1192.11],[1,1.15,2127.02],[2,1.1,477.65]],"batl":[[0,1.18,1074.06],[1,1.19,1658.44],[2,1.48,785.79]],"ltp":1.26,"tv":439.24,"id":8258569}]}]}
{"op":"mcm","clk":"1010678478","pt":1580677726200,"mc":[{"id":"1.168238843","rc":[{"batb":[[0,1.1,477.65],[1,1.01,15.51],[2,1.1,0]],"batl":[[0,1.48,785.81],[1,1.19,0],[2,1.48,0]],"ltp":1.26,"tv":439.24,"id":8258569}]}]}
{"op":"mcm","clk":"1010678779","pt":1580677729112,"mc":[{"id":"1.168238843","rc":[{"trd":[[1.12,0.04]],"batb":[[0,1.12,2592.35],[1,1.11,833.75],[2,1.1,477.65]],"batl":[[0,1.48,785.79]],"ltp":1.12,"tv":439.28,"id":8258569}],"tv":462.93}]}
{"op":"mcm","clk":"1010678980","pt":1580677731202,"mc":[{"id":"1.168238843","rc":[{"batl":[[0,1.14,1096.6],[1,1.15,2169.41]],"ltp":1.12,"tv":439.28,"id":8258569}]}]}
{"op":"mcm","clk":"1010679060","pt":1580677731930,"mc":[{"id":"1.168238843","rc":[{"batb":[[0,8.2,17.58],[1,6.4,31.22],[2,1.01,15.52]],"ltp":3.1,"tv":23.65,"id":8860646}]}]}
{"op":"mcm","clk":"1010679297","pt":1580677734135,"mc":[{"id":"1.168238843","rc":[{"batl":[[0,15.5,59.7]],"ltp":3.1,"tv":23.65,"id":8860646},{"batl":[[2,1.41,903.63]],"ltp":1.12,"tv":439.28,"id":8258569}]}]}
{"op":"mcm","clk":"1010680166","pt":1580677742845,"mc":[{"id":"1.168238843","rc":[{"batb":[[0,6.4,31.22],[1,1.01,15.52],[2,1.01,0]],"ltp":3.1,"tv":23.65,"id":8860646},{"batb":[[0,1.08,584.63],[1,1.01,15.51],[2,1.1,0]],"batl":[[0,1.41,903.63],[1,1.15,0],[2,1.41,0]],"ltp":1.12,"tv":439.28,"id":8258569}]}]}
{"op":"mcm","clk":"1010680832","pt":1580677749241,"mc":[{"id":"1.168238843","rc":[{"batb":[[0,1.13,1776.29],[1,1.12,1626.52],[2,1.08,584.63]],"batl":[[0,1.15,1426.24],[1,1.16,1886.85],[2,1.41,903.63]],"ltp":1.12,"tv":439.28,"id":8258569}]}]}
{"op":"mcm","clk":"1010681010","pt":1580677751034,"mc":[{"id":"1.168238843","rc":[{"batb":[[0,1.08,584.63],[1,1.01,15.51],[2,1.08,0]],"batl":[[0,1.41,903.63],[1,1.16,0],[2,1.41,0]],"ltp":1.12,"tv":439.28,"id":8258569}]}]}
{"op":"mcm","clk":"1010681307","pt":1580677754069,"mc":[{"id":"1.168238843","rc":[{"batb":[[0,1.1,3480.84],[1,1.08,584.63],[2,1.01,15.51]],"batl":[[0,1.19,2123.42],[1,1.2,1085.05],[2,1.41,903.63]],"ltp":1.12,"tv":439.28,"id":8258569}]}]}
{"op":"mcm","clk":"1010681423","pt":1580677755281,"mc":[{"id":"1.168238843","rc":[{"batl":[[0,1.41,903.63],[1,1.2,0],[2,1.41,0]],"ltp":1.12,"tv":439.28,"id":8258569}]}]}
{"op":"mcm","clk":"1010681701","pt":1580677758272,"mc":[{"id":"1.168238843","rc":[{"batl":[[0,1.12,923.53],[1,1.13,2473.07],[2,1.41,903.63]],"ltp":1.12,"tv":439.28,"id":8258569}]}]}
{"op":"mcm","clk":"1010681776","pt":1580677758964,"mc":[{"id":"1.168238843","rc":[{"batb":[[0,9.4,32.4],[1,7.8,19.79],[2,1.01,15.52]],"ltp":3.1,"tv":23.65,"id":8860646},{"batb":[[0,1.1,3375.9],[2,1.07,666.38]],"batl":[[1,1.13,1907.62]],"ltp":1.12,"tv":439.28,"id":8258569}]}]}
{"op":"mcm","clk":"1010682001","pt":1580677761289,"mc":[{"id":"1.168238843","rc":[{"batb":[[2,7,13.95]],"batl":[[0,18,56.27]],"ltp":3.1,"tv":23.65,"id":8860646}]}]}
{"op":"mcm","clk":"1010682086","pt":1580677761993,"mc":[{"id":"1.168238843","rc":[{"batb":[[0,1.1,3118.74]],"batl":[[0,1.12,1494.02],[1,1.13,1657.84]],"ltp":1.12,"tv":439.28,"id":8258569}]}]}
{"op":"mcm","clk":"1010682372","pt":1580677765063,"mc":[{"id":"1.168238843","rc":[{"trd":[[1.12,0.07]],"batl":[[0,1.12,1746.01]],"ltp":1.12,"tv":439.31,"id":8258569}],"tv":462.97}]}
{"op":"mcm","clk":"1010682802","pt":1580677769202,"mc":[{"id":"1.168238843","rc":[{"batb":[[0,7.8,19.79],[1,1.01,15.52],[2,7,0]],"ltp":3.1,"tv":23.65,"id":8860646},{"batb":[[0,1.07,666.38],[1,1.01,15.51],[2,1.07,0]],"batl":[[0,1.41,903.63],[1,1.13,0],[2,1.41,0]],"ltp":1.12,"tv":439.31,"id":8258569}]}]}
{"op":"mcm","clk":"1010683395","pt":1580677775104,"mc":[{"id":"1.168238843","rc":[{"batb":[[0,1.11,649.05],[1,1.1,2473.38],[2,1.07,666.38]],"batl":[[0,1.13,2638.29],[1,1.41,903.63]],"ltp":1.12,"tv":439.31,"id":8258569}]}]}
{"op":"mcm","clk":"1010683633","pt":1580677777269,"mc":[{"id":"1.168238843","rc":[{"batb":[[0,1.07,666.38],[1,1.01,15.51],[2,1.07,0]],"batl":[[0,1.41,903.63],[1,1.41,0]],"ltp":1.12,"tv":439.31,"id":8258569}]}]}
{"op":"mcm","clk":"1010683780","pt":1580677778780,"mc":[{"id":"1.168238843","rc":[{"batl":[[0,1.12,2.28],[1,1.41,903.63]],"ltp":1.12,"tv":439.31,"id":8258569}]}]}
{"op":"mcm","clk":"1010683902","pt":1580677780093,"mc":[{"id":"1.168238843","rc":[{"batb":[[0,1.09,3067.07],[1,1.07,666.38],[2,1.01,15.51]],"batl":[[1,1.14,866.16],[2,1.15,2240.95]],"ltp":1.12,"tv":439.31,"id":8258569}]}]}
{"op":"mcm","clk":"1010684208","pt":1580677783196,"mc":[{"id":"1.168238843","rc":[{"batl":[[0,1.14,866.16],[1,1.15,2240.95],[2,1.41,903.63]],"ltp":1.12,"tv":439.31,"id":8258569}]}]}
{"op":"mcm","clk":"1010684664","pt":1580677788221,"mc":[{"id":"1.168238843","rc":[{"batb":[[0,1.07,666.38],[1,1.01,15.51],[2,1.01,0]],"ltp":1.12,"tv":439.31,"id":8258569}]}]}
{"op":"mcm","clk":"1010684958","pt":1580677791113,"mc":[{"id":"1.168238843","rc":[{"batb":[[1,5.8,39.1],[2,1.01,15.52]],"ltp":3.1,"tv":23.65,"id":8860646},{"batb":[[0,1.12,2981.9],[1,1.11,444.7],[2,1.09,554.99]],"ltp":1.12,"tv":439.31,"id":8258569}]}]}
{"op":"mcm","clk":"1010685286","pt":1580677794116,"mc":[{"id":"1.168238843","rc":[{"batl":[[0,15.5,59.7]],"ltp":3.1,"tv":23.65,"id":8860646}]}]}
{"op":"mcm","clk":"1010686747","pt":1580677808151,"mc":[{"id":"1.168238843","rc":[{"batb":[[0,5.8,39.1],[1,1.01,15.52],[2,1.01,0]],"ltp":3.1,"tv":23.65,"id":8860646},{"batb":[[0,1.09,554.99],[1,1.01,15.51],[2,1.09,0]],"batl":[[0,1.41,903.63],[1,1.15,0],[2,1.41,0]],"ltp":1.12,"tv":439.31,"id":8258569}]}]}
{"op":"mcm","clk":"1010686788","pt":1580677808517,"mc":[{"id":"1.168238843","rc":[{"batl":[[0,1.12,3.8],[1,1.41,903.63]],"ltp":1.12,"tv":439.31,"id":8258569}]}]}
{"op":"mcm","clk":"1010687277","pt":1580677813231,"mc":[{"id":"1.168238843","rc":[{"batb":[[0,1.13,2589.98],[1,1.12,805.57],[2,1.09,554.99]],"batl":[[0,1.15,829.84],[1,1.16,2085.64],[2,1.41,903.63]],"ltp":1.12,"tv":439.31,"id":8258569}]}]}
{"op":"mcm","clk":"1010687450","pt":1580677815149,"mc":[{"id":"1.168238843","rc":[{"batb":[[0,1.09,554.99],[1,1.01,15.51],[2,1.09,0]],"batl":[[0,1.41,903.63],[1,1.16,0],[2,1.41,0]],"ltp":1.12,"tv":439.31,"id":8258569}]}]}
{"op":"mcm","clk":"1010687662","pt":1580677817124,"mc":[{"id":"1.168238843","rc":[{"batl":[[0,13.5,64.14]],"ltp":3.1,"tv":23.65,"id":8860646}]}]}
{"op":"mcm","clk":"1010687771","pt":1580677818176,"mc":[{"id":"1.168238843","rc":[{"batb":[[0,1.1,2899.6],[1,1.09,1141.56],[2,1.01,15.51]],"batl":[[0,1.2,1937.93],[1,1.21,1242.48],[2,1.41,903.63]],"ltp":1.12,"tv":439.31,"id":8258569}]}]}
{"op":"mcm","clk":"1010688310","pt":1580677823253,"mc":[{"id":"1.168238843","rc":[{"batl":[[0,1.41,903.63],[1,1.21,0],[2,1.41,0]],"ltp":1.12,"tv":439.31,"id":8258569}]}]}
{"op":"mcm","clk":"1010688635","pt":1580677826248,"mc":[{"id":"1.168238843","rc":[{"batl":[[0,1.12,1988.78],[1,1.13,1417.25],[2,1.41,903.63]],"ltp":1.12,"tv":439.31,"id":8258569}]}]}
{"op":"mcm","clk":"1010688737","pt":1580677827189,"mc":[{"id":"1.168238843","rc":[{"batb":[[0,9,14.19],[1,7.6,21.44],[2,1.01,15.52]],"ltp":3.1,"tv":23.65,"id":8860646},{"batb":[[2,1.08,638.32]],"ltp":1.12,"tv":439.31,"id":8258569}]}]}
{"op":"mcm","clk":"1010689062","pt":1580677830251,"mc":[{"id":"1.168238843","rc":[{"batl":[[0,18,56.27]],"ltp":3.1,"tv":23.65,"id":8860646}]}]}
{"op":"mcm","clk":"1010691098","pt":1580677850213,"mc":[{"id":"1.168238843","rc":[{"batb":[[0,1.09,1141.56],[1,1.08,638.32],[2,1.01,15.51]],"batl":[[0,1.41,903.63],[1,1.13,0],[2,1.41,0]],"ltp":1.12,"tv":439.31,"id":8258569}]}]}
{"op":"mcm","clk":"1010691172","pt":1580677850912,"mc":[{"id":"1.168238843","rc":[{"batb":[[0,7.6,21.44],[1,1.01,15.52],[2,1.01,0]],"ltp":3.1,"tv":23.65,"id":8860646},{"batb":[[0,1.09,586.57]],"ltp":1.12,"tv":439.31,"id":8258569}]}]}
{"op":"mcm","clk":"1010691404","pt":1580677853216,"mc":[{"id":"1.168238843","rc":[{"batb":[[0,1.09,3324.62]],"batl":[[0,1.14,1036.99],[1,1.15,2234.73],[2,1.41,903.63]],"ltp":1.12,"tv":439.31,"id":8258569}]}]}
{"op":"mcm","clk":"1010693063","pt":1580677870084,"mc":[{"id":"1.168238843","rc":[{"batb":[[0,1.08,638.32],[1,1.01,15.51],[2,1.01,0]],"ltp":1.12,"tv":439.31,"id":8258569}]}]}
{"op":"mcm","clk":"1010693319","pt":1580677872621,"mc":[{"id":"1.168238843","rc":[{"batb":[[0,1.12,2815.97],[1,1.11,608.14],[2,1.08,638.32]],"ltp":1.12,"tv":439.31,"id":8258569}]}]}
{"op":"mcm","clk":"1010693469","pt":1580677874053,"mc":[{"id":"1.168238843","rc":[{"batb":[[1,5.5,22.31],[2,1.01,15.52]],"ltp":3.1,"tv":23.65,"id":8860646},{"batb":[[0,1.12,3239.7],[2,1.09,554.28]],"ltp":1.12,"tv":439.31,"id":8258569}]}]}
{"op":"mcm","clk":"1010693580","pt":1580677875175,"mc":[{"id":"1.168238843","rc":[{"batl":[[0,15.5,59.7]],"ltp":3.1,"tv":23.65,"id":8860646}]}]}
{"op":"mcm","clk":"1010695396","pt":1580677895253,"mc":[{"id":"1.168238843","rc":[{"batb":[[0,5.5,22.31],[1,1.01,15.52],[2,1.01,0]],"ltp":3.1,"tv":23.65,"id":8860646},{"batb":[[0,1.09,553.18],[1,1.01,15.51],[2,1.09,0]],"batl":[[0,1.41,903.63],[1,1.15,0],[2,1.41,0]],"ltp":1.12,"tv":439.31,"id":8258569}]}]}
{"op":"mcm","clk":"1010695663","pt":1580677898285,"mc":[{"id":"1.168238843","rc":[{"batb":[[0,1.1,1407.75],[1,1.09,2645.28],[2,1.01,15.51]],"batl":[[0,1.2,755.99],[1,1.21,1526.68],[2,1.41,903.63]],"ltp":1.12,"tv":439.31,"id":8258569}]}]}
{"op":"mcm","clk":"1010695936","pt":1580677901076,"mc":[{"id":"1.168238843","rc":[{"batl":[[0,1.41,903.63],[1,1.21,0],[2,1.41,0]],"ltp":1.12,"tv":439.31,"id":8258569}]}]}
{"op":"mcm","clk":"1010696215","pt":1580677904221,"mc":[{"id":"1.168238843","rc":[{"batl":[[0,1.12,3253.78],[1,1.41,903.63]],"ltp":1.12,"tv":439.31,"id":8258569}]}]}
{"op":"mcm","clk":"1010696256","pt":1580677904633,"mc":[{"id":"1.168238843","rc":[{"batb":[[0,9,14.19],[1,8,18.21],[2,1.01,15.52]],"ltp":3.1,"tv":23.65,"id":8860646},{"batb":[[2,1.07,726.85]],"ltp":1.12,"tv":439.31,"id":8258569}]}]}
{"op":"mcm","clk":"1010696605","pt":1580677908262,"mc":[{"id":"1.168238843","rc":[{"batl":[[0,18,31.47]],"ltp":3.1,"tv":23.65,"id":8860646}]}]}
{"op":"mcm","clk":"1010698516","pt":1580677928265,"mc":[{"id":"1.168238843","rc":[{"batb":[[0,1.09,553.18],[1,1.07,726.85],[2,1.01,15.51]],"batl":[[0,1.41,903.63],[1,1.41,0]],"ltp":1.12,"tv":439.31,"id":8258569}]}]}
{"op":"mcm","clk":"1010698567","pt":1580677928750,"mc":[{"id":"1.168238843","rc":[{"batb":[[0,8,18.21],[1,1.01,15.52],[2,1.01,0]],"ltp":3.1,"tv":23.65,"id":8860646},{"batb":[[0,1.07,726.85],[1,1.01,15.51],[2,1.01,0]],"ltp":1.12,"tv":439.31,"id":8258569}]}]}
{"op":"mcm","clk":"1010698823","pt":1580677931151,"mc":[{"id":"1.168238843","rc":[{"batb":[[0,1.08,970.77],[1,1.07,3325.29],[2,1.01,15.51]],"batl":[[0,1.13,1302.67],[1,1.14,2067.32],[2,1.41,903.63]],"ltp":1.12,"tv":439.31,"id":8258569}]}]}
{"op":"mcm","clk":"1010699436","pt":1580677937979,"mc":[{"id":"1.168238843","rc":[{"batb":[[0,1.07,726.85],[1,1.01,15.51],[2,1.01,0]],"batl":[[0,1.41,903.63],[1,1.14,0],[2,1.41,0]],"ltp":1.12,"tv":439.31,"id":8258569}]}]}
{"op":"mcm","clk":"1010699607","pt":1580677939921,"mc":[{"id":"1.168238843","rc":[{"batl":[[0,1.1,1.77],[1,1.41,903.63]],"ltp":1.12,"tv":439.31,"id":8258569}]}]}
{"op":"mcm","clk":"1010699710","pt":1580677941093,"mc":[{"id":"1.168238843","rc":[{"trd":[[1.1,3.54]],"batb":[[0,1.11,3055.27],[1,1.07,726.85],[2,1.01,15.51]],"batl":[[0,1.13,1286.86],[1,1.14,2082.98],[2,1.41,903.63]],"ltp":1.1,"tv":442.85,"id":8258569}],"tv":466.51}]}
{"op":"mcm","clk":"1010699774","pt":1580677941719,"mc":[{"id":"1.168238843","rc":[{"batb":[[1,7.4,22.55],[2,1.01,15.52]],"ltp":3.1,"tv":23.65,"id":8860646},{"batb":[[0,1.11,3523.39],[1,1.08,586.45]],"ltp":1.1,"tv":442.85,"id":8258569}]}]}
{"op":"mcm","clk":"1010699923","pt":1580677943193,"mc":[{"id":"1.168238843","rc":[{"batl":[[0,15.5,31.2]],"ltp":3.1,"tv":23.65,"id":8860646}]}]}
{"op":"mcm","clk":"1010700706","pt":1580677951092,"mc":[{"id":"1.168238843","rc":[{"batb":[[0,1.11,468.12]],"batl":[[0,1.41,903.63],[1,1.14,0],[2,1.41,0]],"ltp":1.1,"tv":442.85,"id":8258569}]}]}
{"op":"mcm","clk":"1010700785","pt":1580677951924,"mc":[{"id":"1.168238843","rc":[{"batb":[[0,7.4,22.55],[1,1.01,15.52],[2,1.01,0]],"ltp":3.1,"tv":23.65,"id":8860646},{"batb":[[0,1.08,586.45],[1,1.01,15.51],[2,1.01,0]],"ltp":1.1,"tv":442.85,"id":8258569}]}]}
{"op":"mcm","clk":"1010701006","pt":1580677954129,"mc":[{"id":"1.168238843","rc":[{"batb":[[0,1.09,3512.62],[1,1.08,586.45],[2,1.01,15.51]],"batl":[[0,1.15,2580.16],[1,1.16,742.73],[2,1.41,903.63]],"ltp":1.1,"tv":442.85,"id":8258569}]}]}
{"op":"mcm","clk":"1010701364","pt":1580677958036,"mc":[{"id":"1.168238843","rc":[{"batl":[[0,1.41,903.63],[1,1.16,0],[2,1.41,0]],"ltp":1.1,"tv":442.85,"id":8258569}]}]}
{"op":"mcm","clk":"1010701696","pt":1580677961210,"mc":[{"id":"1.168238843","rc":[{"batb":[[0,9.4,32.24],[1,8.2,17.9],[2,7.4,22.55]],"ltp":3.1,"tv":23.65,"id":8860646},{"batb":[[2,1.06,825.15]],"batl":[[0,1.11,1467.42],[1,1.12,1964.21],[2,1.41,903.63]],"ltp":1.1,"tv":442.85,"id":8258569}]}]}
{"op":"mcm","clk":"1010701807","pt":1580677962210,"mc":[{"id":"1.168238843","rc":[{"batb":[[2,1.01,15.52]],"ltp":3.1,"tv":23.65,"id":8860646}]}]}
{"op":"mcm","clk":"1010701869","pt":1580677962837,"mc":[{"id":"1.168238843","rc":[{"batl":[[0,21,53.54]],"ltp":3.1,"tv":23.65,"id":8860646}]}]}
{"op":"mcm","clk":"1010702040","pt":1580677964433,"mc":[{"id":"1.168238843","rc":[{"batl":[[0,1.11,1341.25]],"ltp":1.1,"tv":442.85,"id":8258569}]}]}
{"op":"mcm","clk":"1010702362","pt":1580677967535,"mc":[{"id":"1.168238843","rc":[{"batl":[[1,1.12,2089.26]],"ltp":1.1,"tv":442.85,"id":8258569}]}]}
{"op":"mcm","clk":"1010702838","pt":1580677971953,"mc":[{"id":"1.168238843","rc":[{"batb":[[0,8.2,17.9],[1,1.01,15.52],[2,1.01,0]],"ltp":3.1,"tv":23.65,"id":8860646},{"batb":[[0,1.06,825.15],[1,1.01,15.51],[2,1.06,0]],"batl":[[0,1.41,903.63],[1,1.12,0],[2,1.41,0]],"ltp":1.1,"tv":442.85,"id":8258569}]}]}
{"op":"mcm","clk":"1010703114","pt":1580677974647,"mc":[{"id":"1.168238843","rc":[{"batb":[[0,1.07,2373.87],[1,1.06,2040.91],[2,1.01,15.51]],"batl":[[0,1.13,1277.56],[1,1.14,2092.2],[2,1.41,903.63]],"ltp":1.1,"tv":442.85,"id":8258569}]}]}
{"op":"mcm","clk":"1010703243","pt":1580677975835,"mc":[{"id":"1.168238843","rc":[{"batb":[[0,1.06,825.15],[1,1.01,15.51],[2,1.01,0]],"batl":[[0,1.41,903.63],[1,1.14,0],[2,1.41,0]],"ltp":1.1,"tv":442.85,"id":8258569}]}]}
{"op":"mcm","clk":"1010703565","pt":1580677979059,"mc":[{"id":"1.168238843","rc":[{"batb":[[0,1.09,2225.18],[1,1.08,1299.36],[2,1.06,825.15]],"batl":[[0,1.11,3165.6],[1,1.41,903.63]],"ltp":1.1,"tv":442.85,"id":8258569}]}]}
{"op":"mcm","clk":"1010703777","pt":1580677981216,"mc":[{"id":"1.168238843","rc":[{"batb":[[0,1.06,825.15],[1,1.01,15.51],[2,1.06,0]],"batl":[[0,1.41,903.63],[1,1.41,0]],"ltp":1.1,"tv":442.85,"id":8258569}]}]}
{"op":"mcm","clk":"1010704068","pt":1580677984167,"mc":[{"id":"1.168238843","rc":[{"batb":[[0,1.07,2373.87],[1,1.06,2040.91],[2,1.01,15.51]],"batl":[[0,1.13,1277.56],[1,1.14,2092.2],[2,1.41,903.63]],"ltp":1.1,"tv":442.85,"id":8258569}]}]}
{"op":"mcm","clk":"1010705132","pt":1580677995074,"mc":[{"id":"1.168238843","rc":[{"batl":[[0,1.41,903.63],[1,1.14,0],[2,1.41,0]],"ltp":1.1,"tv":442.85,"id":8258569}]}]}
{"op":"mcm","clk":"1010705430","pt":1580677998087,"mc":[{"id":"1.168238843","rc":[{"batl":[[0,1.08,863.23],[1,1.09,2657.31],[2,1.41,903.63]],"ltp":1.1,"tv":442.85,"id":8258569}]}]}
{"op":"mcm","clk":"1010705515","pt":1580677998875,"mc":[{"id":"1.168238843","rc":[{"batb":[[0,12,17.9],[1,9.6,30.19],[2,1.01,15.52]],"ltp":3.1,"tv":23.65,"id":8860646},{"batb":[[2,1.03,1538.13]],"ltp":1.1,"tv":442.85,"id":8258569}]}]}
{"op":"mcm","clk":"1010705745","pt":1580678001246,"mc":[{"id":"1.168238843","rc":[{"batl":[[0,26,49.43]],"ltp":3.1,"tv":23.65,"id":8860646}]}]}
{"op":"mcm","clk":"1010706604","pt":1580678010077,"mc":[{"id":"1.168238843","rc":[{"trd":[[13.5,2.52]],"ltp":13.5,"tv":26.17,"id":8860646},{"trd":[[1.08,31.54]],"batl":[[0,1.08,831.69]],"ltp":1.08,"tv":474.39,"id":8258569}],"tv":500.57}]}
{"op":"mcm","clk":"1010707392","pt":1580678018212,"mc":[{"id":"1.168238843","rc":[{"batb":[[0,9.6,30.19],[1,1.01,15.52],[2,1.01,0]],"ltp":13.5,"tv":26.17,"id":8860646},{"batb":[[0,1.03,1538.13],[1,1.01,15.51],[2,1.03,0]],"batl":[[0,1.41,903.63],[1,1.09,0],[2,1.41,0]],"ltp":1.08,"tv":474.39,"id":8258569}]}]}
{"op":"mcm","clk":"1010707666","pt":1580678021176,"mc":[{"id":"1.168238843","rc":[{"batb":[[0,1.04,2841.7],[1,1.03,2386.08],[2,1.01,15.51]],"batl":[[0,1.11,2566.26],[1,1.12,875.18],[2,1.41,903.63]],"ltp":1.08,"tv":474.39,"id":8258569}]}]}
{"op":"mcm","clk":"1010708209","pt":1580678027211,"mc":[{"id":"1.168238843","rc":[{"batl":[[0,1.41,903.63],[1,1.12,0],[2,1.41,0]],"ltp":1.08,"tv":474.39,"id":8258569}]}]}
{"op":"mcm","clk":"1010708498","pt":1580678030121,"mc":[{"id":"1.168238843","rc":[{"batb":[[0,19,12.61],[1,14,12.38],[2,9.6,30.19]],"ltp":13.5,"tv":26.17,"id":8860646},{"batl":[[0,1.05,3646.44]],"ltp":1.08,"tv":474.39,"id":8258569}]}]}
{"op":"mcm","clk":"1010708532","pt":1580678030384,"mc":[{"id":"1.168238843","rc":[{"batb":[[2,1.01,15.52]],"ltp":13.5,"tv":26.17,"id":8860646}]}]}
{"op":"mcm","clk":"1010708779","pt":1580678033012,"mc":[{"id":"1.168238843","rc":[{"batl":[[0,60,41.02]],"ltp":13.5,"tv":26.17,"id":8860646},{"batl":[[1,1.32,1155.76]],"ltp":1.08,"tv":474.39,"id":8258569}]}]}
{"op":"mcm","clk":"1010710502","pt":1580678049682,"mc":[{"id":"1.168238843","rc":[{"batb":[[0,1.04,2686.98]],"ltp":1.08,"tv":474.39,"id":8258569}]}]}
{"op":"mcm","clk":"1010710781","pt":1580678052627,"mc":[{"id":"1.168238843","rc":[{"batb":[[1,1.03,2542.31]],"ltp":1.08,"tv":474.39,"id":8258569}]}]}
{"op":"mcm","clk":"1010710925","pt":1580678054254,"mc":[{"id":"1.168238843","rc":[{"batb":[[0,1.03,1538.13],[1,1.01,15.51],[2,1.01,0]],"batl":[[0,1.32,1155.76],[1,1.32,0]],"ltp":1.08,"tv":474.39,"id":8258569}]}]}
{"op":"mcm","clk":"1010711014","pt":1580678055166,"mc":[{"id":"1.168238843","rc":[{"batb":[[0,14,12.38],[1,1.01,15.52],[2,1.01,0]],"ltp":13.5,"tv":26.17,"id":8860646},{"batb":[[0,1.01,15.51],[1,1.01,0]],"ltp":1.08,"tv":474.39,"id":8258569}]}]}
{"op":"mcm","clk":"1010711231","pt":1580678057145,"mc":[{"id":"1.168238843","rc":[{"batb":[[0,1.01,3806.36]],"batl":[[0,1.07,2471.49],[1,1.08,1096.54]],"ltp":1.08,"tv":474.39,"id":8258569}]}]}
{"op":"mcm","clk":"1010711287","pt":1580678057775,"mc":[{"id":"1.168238843","rc":[{"batb":[[0,1.01,15.51]],"ltp":1.08,"tv":474.39,"id":8258569}]}]}
{"op":"mcm","clk":"1010711490","pt":1580678060094,"mc":[{"id":"1.168238843","rc":[{"batb":[[0,1.03,3717.24],[1,1.01,15.51]],"batl":[[0,1.04,795.82],[1,1.05,2858.19]],"ltp":1.08,"tv":474.39,"id":8258569}]}]}
{"op":"mcm","clk":"1010711668","pt":1580678061956,"mc":[{"id":"1.168238843","rc":[{"batl":[[0,85,39.17]],"ltp":13.5,"tv":26.17,"id":8860646},{"batl":[[2,1.31,1188.32]],"ltp":1.08,"tv":474.39,"id":8258569}]}]}
{"op":"mcm","clk":"1010711850","pt":1580678063950,"mc":[{"id":"1.168238843","rc":[{"batb":[[0,1.01,15.51],[1,1.01,0]],"batl":[[0,1.31,1188.32],[1,1.05,0],[2,1.31,0]],"ltp":1.08,"tv":474.39,"id":8258569}]}]}
{"op":"mcm","clk":"1010712085","pt":1580678066384,"mc":[{"id":"1.168238843","rc":[{"batb":[[0,1.01,3806.36]],"batl":[[0,1.07,2471.49],[1,1.08,1096.54]],"ltp":1.08,"tv":474.39,"id":8258569}]}]}
{"op":"mcm","clk":"1010712941","pt":1580678075286,"mc":[{"id":"1.168238843","rc":[{"batl":[[0,1.02,3749.19]],"ltp":1.08,"tv":474.39,"id":8258569}]}]}
{"op":"mcm","clk":"1010712997","pt":1580678075922,"mc":[{"id":"1.168238843","rc":[{"batb":[[0,30,6.27],[1,24,11.48],[2,1.01,15.52]],"ltp":13.5,"tv":26.17,"id":8860646}]}]}
{"op":"mcm","clk":"1010713125","pt":1580678077189,"mc":[{"id":"1.168238843","rc":[{"batl":[[1,1.28,1310.54]],"ltp":1.08,"tv":474.39,"id":8258569}]}]}
{"op":"mcm","clk":"1010715092","pt":1580678098228,"mc":[{"id":"1.168238843","rc":[{"trd":[[1.01,1980.58]],"batb":[[0,1.01,2816.07]],"ltp":1.01,"tv":2454.97,"id":8258569}],"tv":2481.15}]}
{"op":"mcm","clk":"1010715416","pt":1580678101826,"mc":[{"id":"1.168238843","rc":[{"batb":[[0,1.01,3786.31]],"ltp":1.01,"tv":2454.97,"id":8258569}]}]}
{"op":"mcm","clk":"1010720818","pt":1580678165271,"mc":[{"id":"1.168238843","rc":[{"batl":[[0,1.28,1310.54],[1,1.28,0]],"ltp":1.01,"tv":2454.97,"id":8258569}]}]}
{"op":"mcm","clk":"1010720845","pt":1580678165539,"mc":[{"id":"1.168238843","rc":[{"batb":[[0,24,11.48],[1,1.01,15.52],[2,1.01,0]],"ltp":13.5,"tv":26.17,"id":8860646}]}]}
{"op":"mcm","clk":"1010721324","pt":1580678170781,"mc":[{"id":"1.168238843","rc":[{"batl":[[0,1.03,3712.79],[1,1.28,1310.54]],"ltp":1.01,"tv":2454.97,"id":8258569}]}]}
{"op":"mcm","clk":"1010721628","pt":1580678174147,"mc":[{"id":"1.168238843","rc":[{"batl":[[0,1.28,1310.54],[1,1.28,0]],"ltp":1.01,"tv":2454.97,"id":8258569}]}]}
{"op":"mcm","clk":"1010721888","pt":1580678177009,"mc":[{"id":"1.168238843","rc":[{"batl":[[0,1.04,3677.09],[1,1.28,1310.54]],"ltp":1.01,"tv":2454.97,"id":8258569}]}]}
{"op":"mcm","clk":"1010721964","pt":1580678177704,"mc":[{"id":"1.168238843","rc":[{"batl":[[0,1.28,1310.54],[1,1.28,0]],"ltp":1.01,"tv":2454.97,"id":8258569}]}]}
{"op":"mcm","clk":"1010722266","pt":1580678181226,"mc":[{"id":"1.168238843","rc":[{"batb":[[0,30,3.39],[1,24,11.48],[2,1.01,15.52]],"ltp":13.5,"tv":26.17,"id":8860646},{"batl":[[0,1.02,3749.19],[1,1.28,1310.54]],"ltp":1.01,"tv":2454.97,"id":8258569}]}]}
{"op":"mcm","clk":"1010722282","pt":1580678181448,"mc":[{"id":"1.168238843","rc":[{"batb":[[1,1.01,15.52],[2,1.01,0]],"ltp":13.5,"tv":26.17,"id":8860646}]}]}
{"op":"mcm","clk":"1010723688","pt":1580678197021,"mc":[{"id":"1.168238843","rc":[{"batl":[[0,1.28,1310.54],[1,1.28,0]],"ltp":1.01,"tv":2454.97,"id":8258569}]}]}
{"op":"mcm","clk":"1010724097","pt":1580678201139,"mc":[{"id":"1.168238843","rc":[{"batb":[[0,1.01,15.52],[1,1.01,0]],"ltp":13.5,"tv":26.17,"id":8860646}]}]}
{"op":"mcm","clk":"1010724272","pt":1580678202946,"mc":[{"id":"1.168238843","rc":[{"batl":[[0,1.01,3786.31],[1,1.28,1310.54]],"ltp":1.01,"tv":2454.97,"id":8258569}]}]}
{"op":"mcm","clk":"1010725344","pt":1580678215166,"mc":[{"id":"1.168238843","rc":[{"batl":[[0,1.28,1310.54],[1,1.28,0]],"ltp":1.01,"tv":2454.97,"id":8258569}]}]}
{"op":"mcm","clk":"1010725627","pt":1580678218259,"mc":[{"id":"1.168238843","rc":[{"batl":[[0,1.02,733.93],[1,1.28,1310.54]],"ltp":1.01,"tv":2454.97,"id":8258569}]}]}
{"op":"mcm","clk":"1010725775","pt":1580678220046,"mc":[{"id":"1.168238843","rc":[{"batl":[[0,1.01,3038.86],[1,1.02,733.93],[2,1.28,1310.54]],"ltp":1.01,"tv":2454.97,"id":8258569}]}]}
{"op":"mcm","clk":"1010726016","pt":1580678222753,"mc":[{"id":"1.168238843","rc":[{"batl":[[0,1.02,733.93],[1,1.28,1310.54],[2,1.28,0]],"ltp":1.01,"tv":2454.97,"id":8258569}]}]}
{"op":"mcm","clk":"1010726290","pt":1580678225755,"mc":[{"id":"1.168238843","rc":[{"batl":[[0,1.02,3749.19]],"ltp":1.01,"tv":2454.97,"id":8258569}]}]}
{"op":"mcm","clk":"1010726843","pt":1580678232841,"mc":[{"id":"1.168238843","rc":[{"batb":[[0,28,5.82],[1,1.01,15.52]],"ltp":13.5,"tv":26.17,"id":8860646},{"batb":[[0,1.01,3786.31]],"ltp":1.01,"tv":2454.97,"id":8258569}]}]}
{"op":"mcm","clk":"1010727951","pt":1580678248095,"mc":[{"id":"1.168238843","rc":[{"batl":[[0,1.28,1310.54],[1,1.28,0]],"ltp":1.01,"tv":2454.97,"id":8258569}]}]}
{"op":"mcm","clk":"1010728192","pt":1580678250993,"mc":[{"id":"1.168238843","rc":[{"batl":[[0,1.03,3712.79]],"ltp":1.01,"tv":2454.97,"id":8258569}]}]}
{"op":"mcm","clk":"1010728301","pt":1580678252454,"mc":[{"id":"1.168238843","rc":[{"batb":[[0,1.01,15.52],[1,1.01,0]],"ltp":13.5,"tv":26.17,"id":8860646}]}]}
{"op":"mcm","clk":"1010728472","pt":1580678254853,"mc":[{"id":"1.168238843","rc":[{"batl":[[0,1.01,3786.31]],"ltp":1.01,"tv":2454.97,"id":8258569}]}]}
{"op":"mcm","clk":"1010728660","pt":1580678257163,"mc":[{"id":"1.168238843","rc":[{"batl":[[1,1.27,1376.36]],"ltp":1.01,"tv":2454.97,"id":8258569}]}]}
{"op":"mcm","clk":"1010729327","pt":1580678266086,"mc":[{"id":"1.168238843","rc":[{"batl":[[0,1.27,1376.36],[1,1.27,0]],"ltp":1.01,"tv":2454.97,"id":8258569}]}]}
{"op":"mcm","clk":"1010729555","pt":1580678268976,"mc":[{"id":"1.168238843","rc":[{"batl":[[0,1.02,3749.19],[1,1.27,1376.36]],"ltp":1.01,"tv":2454.97,"id":8258569}]}]}
{"op":"mcm","clk":"1010729681","pt":1580678270708,"mc":[{"id":"1.168238843","rc":[{"batl":[[0,1.27,1376.36],[1,1.27,0]],"ltp":1.01,"tv":2454.97,"id":8258569}]}]}
{"op":"mcm","clk":"1010729881","pt":1580678273611,"mc":[{"id":"1.168238843","rc":[{"batl":[[0,1.01,3786.31],[1,1.27,1376.36]],"ltp":1.01,"tv":2454.97,"id":8258569}]}]}
{"op":"mcm","clk":"1010729974","pt":1580678274710,"mc":[{"id":"1.168238843","rc":[{"batl":[[0,1.27,1376.36],[1,1.27,0]],"ltp":1.01,"tv":2454.97,"id":8258569}]}]}
{"op":"mcm","clk":"1010730186","pt":1580678277606,"mc":[{"id":"1.168238843","rc":[{"batl":[[0,1.02,3749.19],[1,1.27,1376.36]],"ltp":1.01,"tv":2454.97,"id":8258569}]}]}
{"op":"mcm","clk":"1010730733","pt":1580678284828,"mc":[{"id":"1.168238843","rc":[{"batl":[[0,1.27,1376.36],[1,1.27,0]],"ltp":1.01,"tv":2454.97,"id":8258569}]}]}
{"op":"mcm","clk":"1010730977","pt":1580678287689,"mc":[{"id":"1.168238843","rc":[{"batl":[[0,1.01,3785.87],[1,1.27,1376.36]],"ltp":1.01,"tv":2454.97,"id":8258569}]}]}
{"op":"mcm","clk":"1010735388","pt":1580678348222,"mc":[{"id":"1.168238843","rc":[{"batl":[[1,1.27,0]],"ltp":1.01,"tv":2454.97,"id":8258569}]}]}
{"op":"mcm","clk":"1010741696","pt":1580678436029,"mc":[{"id":"1.168238843","marketDefinition":{"bspMarket":false,"turnInPlayEnabled":true,"persistenceEnabled":true,"marketBaseRate":5.0,"eventId":"29681898","eventTypeId":"2","numberOfWinners":1,"bettingType":"ODDS","marketType":"SET_WINNER","marketTime":"2020-02-02T20:18:00.000Z","suspendTime":"2020-02-02T20:18:00.000Z","bspReconciled":false,"complete":true,"inPlay":true,"crossMatching":true,"runnersVoidable":false,"numberOfActiveRunners":2,"betDelay":3,"status":"SUSPENDED","runners":[{"status":"ACTIVE","sortPriority":1,"id":8860646,"name":"Daniel Elahi Galan"},{"status":"ACTIVE","sortPriority":2,"id":8258569,"name":"Thai-Son Kwiatkowski"}],"regulators":["MR_INT"],"countryCode":"US","discountAllowed":true,"timezone":"UTC","openDate":"2020-02-02T20:18:00.000Z","version":3150650793,"name":"Set 2 Winner","eventName":"Galan v Kwiatkowski"}}]}
{"op":"mcm","clk":"1010744976","pt":1580678482997,"mc":[{"id":"1.168238843","tv":0.0}]}
{"op":"mcm","clk":"1010745063","pt":1580678484029,"mc":[{"id":"1.168238843","marketDefinition":{"bspMarket":false,"turnInPlayEnabled":true,"persistenceEnabled":true,"marketBaseRate":5.0,"eventId":"29681898","eventTypeId":"2","numberOfWinners":1,"bettingType":"ODDS","marketType":"SET_WINNER","marketTime":"2020-02-02T20:18:00.000Z","suspendTime":"2020-02-02T20:18:00.000Z","bspReconciled":false,"complete":true,"inPlay":true,"crossMatching":false,"runnersVoidable":false,"numberOfActiveRunners":0,"betDelay":3,"status":"CLOSED","settledTime":"2020-02-02T21:21:19.000Z","runners":[{"status":"LOSER","sortPriority":1,"id":8860646,"name":"Daniel Elahi Galan"},{"status":"WINNER","sortPriority":2,"id":8258569,"name":"Thai-Son Kwiatkowski"}],"regulators":["MR_INT"],"countryCode":"US","discountAllowed":true,"timezone":"UTC","openDate":"2020-02-02T20:18:00.000Z","version":3150653446,"name":"Set 2 Winner","eventName":"Galan v Kwiatkowski"}}]}
