{"op":"mcm","clk":"998176899","pt":1580569848193,"mc":[{"id":"1.168219389","marketDefinition":{"bspMarket":false,"turnInPlayEnabled":true,"persistenceEnabled":true,"marketBaseRate":5.0,"eventId":"29681328","eventTypeId":"2","numberOfWinners":1,"bettingType":"ODDS","marketType":"SET_WINNER","marketTime":"2020-02-02T11:30:00.000Z","suspendTime":"2020-02-02T11:30:00.000Z","bspReconciled":false,"complete":true,"inPlay":false,"crossMatching":false,"runnersVoidable":false,"numberOfActiveRunners":2,"betDelay":0,"status":"OPEN","runners":[{"status":"ACTIVE","sortPriority":1,"id":8535963,"name":"Nikola Milojevic"},{"status":"ACTIVE","sortPriority":2,"id":2309796,"name":"Robin Haase"}],"regulators":["MR_INT"],"countryCode":"IN","discountAllowed":false,"timezone":"UTC","openDate":"2020-02-02T11:30:00.000Z","version":3145750584,"name":"Set 1 Winner","eventName":"Milojevic v Haase"}}]}
{"op":"mcm","clk":"998177333","pt":1580569849772,"mc":[{"id":"1.168219389","marketDefinition":{"bspMarket":false,"turnInPlayEnabled":true,"persistenceEnabled":true,"marketBaseRate":5.0,"eventId":"29681328","eventTypeId":"2","numberOfWinners":1,"bettingType":"ODDS","marketType":"SET_WINNER","marketTime":"2020-02-02T11:30:00.000Z","suspendTime":"2020-02-02T11:30:00.000Z","bspReconciled":false,"complete":true,"inPlay":false,"crossMatching":false,"runnersVoidable":false,"numberOfActiveRunners":2,"betDelay":0,"status":"OPEN","runners":[{"status":"ACTIVE","sortPriority":1,"id":8535963,"name":"Nikola Milojevic"},{"status":"ACTIVE","sortPriority":2,"id":2309796,"name":"Robin Haase"}],"regulators":["MR_INT"],"countryCode":"IN","discountAllowed":false,"timezone":"UTC","openDate":"2020-02-02T11:30:00.000Z","version":3145750584,"name":"Set 1 Winner","eventName":"Milojevic v Haase"}}]}
{"op":"mcm","clk":"998177617","pt":1580569850776,"mc":[{"id":"1.168219389","marketDefinition":{"bspMarket":false,"turnInPlayEnabled":true,"persistenceEnabled":true,"marketBaseRate":5.0,"eventId":"29681328","eventTypeId":"2","numberOfWinners":1,"bettingType":"ODDS","marketType":"SET_WINNER","marketTime":"2020-02-02T11:30:00.000Z","suspendTime":"2020-02-02T11:30:00.000Z","bspReconciled":false,"complete":true,"inPlay":false,"crossMatching":false,"runnersVoidable":false,"numberOfActiveRunners":2,"betDelay":0,"status":"OPEN","runners":[{"status":"ACTIVE","sortPriority":1,"id":8535963,"name":"Nikola Milojevic"},{"status":"ACTIVE","sortPriority":2,"id":2309796,"name":"Robin Haase"}],"regulators":["MR_INT"],"countryCode":"IN","discountAllowed":true,"timezone":"UTC","openDate":"2020-02-02T11:30:00.000Z","version":3145750584,"name":"Set 1 Winner","eventName":"Milojevic v Haase"}}]}
{"op":"mcm","clk":"998189144","pt":1580569893697,"mc":[{"id":"1.168219389","rc":[{"batb":[[0,1.01,20]],"ltp":0.0,"tv":0.0,"id":8535963},{"batb":[[0,1.01,20]],"ltp":0.0,"tv":0.0,"id":2309796}]}]}
{"op":"mcm","clk":"998246771","pt":1580570113734,"mc":[{"id":"1.168219389","rc":[{"batb":[[0,1.01,10]],"ltp":0.0,"tv":0.0,"id":8535963},{"batb":[[0,1.01,10]],"ltp":0.0,"tv":0.0,"id":2309796}]}]}
{"op":"mcm","clk":"1003058525","pt":1580602467518,"mc":[{"id":"1.168219389","rc":[{"batb":[[0,1.01,10.51]],"ltp":0.0,"tv":0.0,"id":8535963},{"batb":[[0,1.01,10.51]],"ltp":0.0,"tv":0.0,"id":2309796}]}]}
{"op":"mcm","clk":"1003180170","pt":1580604001642,"mc":[{"id":"1.168219389","rc":[{"batb":[[0,1.01,11.01]],"ltp":0.0,"tv":0.0,"id":8535963},{"batb":[[0,1.01,11.01]],"ltp":0.0,"tv":0.0,"id":2309796}]}]}
{"op":"mcm","clk":"1003389712","pt":1580607092754,"mc":[{"id":"1.168219389","rc":[{"batb":[[0,1.01,11.02]],"ltp":0.0,"tv":0.0,"id":8535963},{"batb":[[0,1.01,13.01]],"ltp":0.0,"tv":0.0,"id":2309796}]}]}
{"op":"mcm","clk":"1003389751","pt":1580607093169,"mc":[{"id":"1.168219389","rc":[{"batb":[[0,1.01,11.02]],"ltp":0.0,"tv":0.0,"id":2309796}]}]}
{"op":"mcm","clk":"1004334260","pt":1580627284068,"mc":[{"id":"1.168219389","rc":[{"batl":[[0,3.3,3.03]],"ltp":0.0,"tv":0.0,"id":8535963},{"batl":[[0,2.16,7.57]],"ltp":0.0,"tv":0.0,"id":2309796}]}]}
{"op":"mcm","clk":"1004334693","pt":1580627293368,"mc":[{"id":"1.168219389","rc":[{"batl":[[0,2.22,7.57]],"ltp":0.0,"tv":0.0,"id":2309796}]}]}
{"op":"mcm","clk":"1004335356","pt":1580627312146,"mc":[{"id":"1.168219389","marketDefinition":{"bspMarket":false,"turnInPlayEnabled":true,"persistenceEnabled":true,"marketBaseRate":5.0,"eventId":"29681328","eventTypeId":"2","numberOfWinners":1,"bettingType":"ODDS","marketType":"SET_WINNER","marketTime":"2020-02-02T11:30:00.000Z","suspendTime":"2020-02-02T11:30:00.000Z","bspReconciled":false,"complete":true,"inPlay":false,"crossMatching":true,"runnersVoidable":false,"numberOfActiveRunners":2,"betDelay":0,"status":"OPEN","runners":[{"status":"ACTIVE","sortPriority":1,"id":8535963,"name":"Nikola Milojevic"},{"status":"ACTIVE","sortPriority":2,"id":2309796,"name":"Robin Haase"}],"regulators":["MR_INT"],"countryCode":"IN","discountAllowed":true,"timezone":"UTC","openDate":"2020-02-02T11:30:00.000Z","version":3146887819,"name":"Set 1 Winner","eventName":"Milojevic v Haase"}}]}
{"op":"mcm","clk":"1004704063","pt":1580635607319,"mc":[{"id":"1.168219389","marketDefinition":{"bspMarket":false,"turnInPlayEnabled":true,"persistenceEnabled":true,"marketBaseRate":5.0,"eventId":"29681328","eventTypeId":"2","numberOfWinners":1,"bettingType":"ODDS","marketType":"SET_WINNER","marketTime":"2020-02-02T11:23:00.000Z","suspendTime":"2020-02-02T11:23:00.000Z","bspReconciled":false,"complete":true,"inPlay":false,"crossMatching":true,"runnersVoidable":false,"numberOfActiveRunners":2,"betDelay":0,"status":"OPEN","runners":[{"status":"ACTIVE","sortPriority":1,"id":8535963,"name":"Nikola Milojevic"},{"status":"ACTIVE","sortPriority":2,"id":2309796,"name":"Robin Haase"}],"regulators":["MR_INT"],"countryCode":"IN","discountAllowed":true,"timezone":"UTC","openDate":"2020-02-02T11:30:00.000Z","version":3148345185,"name":"Set 1 Winner","eventName":"Milojevic v Haase"}}]}
{"op":"mcm","clk":"1004704272","pt":1580635610363,"mc":[{"id":"1.168219389","marketDefinition":{"bspMarket":false,"turnInPlayEnabled":true,"persistenceEnabled":true,"marketBaseRate":5.0,"eventId":"29681328","eventTypeId":"2","numberOfWinners":1,"bettingType":"ODDS","marketType":"SET_WINNER","marketTime":"2020-02-02T11:23:00.000Z","suspendTime":"2020-02-02T11:23:00.000Z","bspReconciled":false,"complete":true,"inPlay":false,"crossMatching":true,"runnersVoidable":false,"numberOfActiveRunners":2,"betDelay":0,"status":"OPEN","runners":[{"status":"ACTIVE","sortPriority":1,"id":8535963,"name":"Nikola Milojevic"},{"status":"ACTIVE","sortPriority":2,"id":2309796,"name":"Robin Haase"}],"regulators":["MR_INT"],"countryCode":"IN","discountAllowed":true,"timezone":"UTC","openDate":"2020-02-02T11:23:00.000Z","version":3148345185,"name":"Set 1 Winner","eventName":"Milojevic v Haase"}}]}
{"op":"mcm","clk":"1005053389","pt":1580640381602,"mc":[{"id":"1.168219389","rc":[{"batb":[[0,2.12,23.92],[1,1.01,11.02]],"ltp":0.0,"tv":0.0,"id":8535963},{"batb":[[0,1.79,20.14],[1,1.01,11.02]],"ltp":0.0,"tv":0.0,"id":2309796}]}]}
{"op":"mcm","clk":"1005056582","pt":1580640406412,"mc":[{"id":"1.168219389","marketDefinition":{"bspMarket":false,"turnInPlayEnabled":true,"persistenceEnabled":true,"marketBaseRate":5.0,"eventId":"29681328","eventTypeId":"2","numberOfWinners":1,"bettingType":"ODDS","marketType":"SET_WINNER","marketTime":"2020-02-02T10:45:00.000Z","suspendTime":"2020-02-02T10:45:00.000Z","bspReconciled":false,"complete":true,"inPlay":false,"crossMatching":true,"runnersVoidable":false,"numberOfActiveRunners":2,"betDelay":0,"status":"OPEN","runners":[{"status":"ACTIVE","sortPriority":1,"id":8535963,"name":"Nikola Milojevic"},{"status":"ACTIVE","sortPriority":2,"id":2309796,"name":"Robin Haase"}],"regulators":["MR_INT"],"countryCode":"IN","discountAllowed":true,"timezone":"UTC","openDate":"2020-02-02T11:23:00.000Z","version":3148437221,"name":"Set 1 Winner","eventName":"Milojevic v Haase"}}]}
{"op":"mcm","clk":"1005058517","pt":1580640420442,"mc":[{"id":"1.168219389","marketDefinition":{"bspMarket":false,"turnInPlayEnabled":true,"persistenceEnabled":true,"marketBaseRate":5.0,"eventId":"29681328","eventTypeId":"2","numberOfWinners":1,"bettingType":"ODDS","marketType":"SET_WINNER","marketTime":"2020-02-02T10:45:00.000Z","suspendTime":"2020-02-02T10:45:00.000Z","bspReconciled":false,"complete":true,"inPlay":false,"crossMatching":true,"runnersVoidable":false,"numberOfActiveRunners":2,"betDelay":0,"status":"OPEN","runners":[{"status":"ACTIVE","sortPriority":1,"id":8535963,"name":"Nikola Milojevic"},{"status":"ACTIVE","sortPriority":2,"id":2309796,"name":"Robin Haase"}],"regulators":["MR_INT"],"countryCode":"IN","discountAllowed":true,"timezone":"UTC","openDate":"2020-02-02T10:45:00.000Z","version":3148437221,"name":"Set 1 Winner","eventName":"Milojevic v Haase"}}]}
{"op":"mcm","clk":"1005078888","pt":1580640585070,"mc":[{"id":"1.168219389","rc":[{"batb":[[0,1.78,20.22]],"ltp":0.0,"tv":0.0,"id":2309796}]}]}
{"op":"mcm","clk":"1005082938","pt":1580640614685,"mc":[{"id":"1.168219389","rc":[{"batb":[[1,1.01,12.2]],"ltp":0.0,"tv":0.0,"id":8535963},{"batb":[[1,1.01,12.43]],"ltp":0.0,"tv":0.0,"id":2309796}]}]}
{"op":"mcm","clk":"1005082978","pt":1580640614988,"mc":[{"id":"1.168219389","rc":[{"batb":[[0,2.14,1.18],[1,2.12,23.92],[2,1.01,11.02]],"ltp":0.0,"tv":0.0,"id":8535963},{"batb":[[0,1.79,1.41],[1,1.78,20.22],[2,1.01,11.02]],"ltp":0.0,"tv":0.0,"id":2309796}]}]}
{"op":"mcm","clk":"1005094206","pt":1580640705750,"mc":[{"id":"1.168219389","rc":[{"batb":[[1,2.12,23.76]],"ltp":0.0,"tv":0.0,"id":8535963}]}]}
{"op":"mcm","clk":"1005106695","pt":1580640813138,"mc":[{"id":"1.168219389","rc":[{"batb":[[2,2.08,38.65]],"batl":[[0,2.34,31.09],[1,3.3,3.03]],"ltp":0.0,"tv":0.0,"id":8535963},{"batb":[[2,1.76,54.61]],"batl":[[0,1.94,42.01],[1,2.22,7.57]],"ltp":0.0,"tv":0.0,"id":2309796}]}]}
{"op":"mcm","clk":"1005125574","pt":1580640967534,"mc":[{"id":"1.168219389","rc":[{"batl":[[2,4,2.53]],"ltp":0.0,"tv":0.0,"id":8535963}]}]}
{"op":"mcm","clk":"1005126150","pt":1580640972830,"mc":[{"id":"1.168219389","rc":[{"batl":[[2,4,0]],"ltp":0.0,"tv":0.0,"id":8535963}]}]}
{"op":"mcm","clk":"1005129150","pt":1580640996448,"mc":[{"id":"1.168219389","rc":[{"batl":[[1,2.4,3.04],[2,3.3,3.03]],"ltp":0.0,"tv":0.0,"id":8535963}]}]}
{"op":"mcm","clk":"1005129360","pt":1580640998365,"mc":[{"id":"1.168219389","rc":[{"batl":[[1,3.3,3.03],[2,3.3,0]],"ltp":0.0,"tv":0.0,"id":8535963}]}]}
{"op":"mcm","clk":"1005131325","pt":1580641014755,"mc":[{"id":"1.168219389","rc":[{"batl":[[0,2.16,2.53],[1,2.34,31.09],[2,3.3,3.03]],"ltp":0.0,"tv":0.0,"id":8535963}]}]}
{"op":"mcm","clk":"1005131547","pt":1580641016644,"mc":[{"id":"1.168219389","rc":[{"batl":[[0,2.34,31.09],[1,3.3,3.03],[2,3.3,0]],"ltp":0.0,"tv":0.0,"id":8535963}]}]}
{"op":"mcm","clk":"1005132725","pt":1580641025254,"mc":[{"id":"1.168219389","rc":[{"trd":[[2.12,2.72],[2.14,2.35]],"batb":[[0,2.12,22.4],[1,2.08,38.65],[2,1.01,11.02]],"ltp":2.12,"tv":5.06,"id":8535963}],"tv":5.06}]}
{"op":"mcm","clk":"1005134252","pt":1580641036391,"mc":[{"id":"1.168219389","rc":[{"batb":[[0,2.1,24.16]],"ltp":2.12,"tv":5.06,"id":8535963},{"batb":[[0,1.79,21.32],[1,1.76,54.61],[2,1.01,11.02]],"ltp":0.0,"tv":0.0,"id":2309796}]}]}
{"op":"mcm","clk":"1005137469","pt":1580641060220,"mc":[{"id":"1.168219389","rc":[{"batb":[[0,2.08,38.65],[1,1.01,11.02],[2,1.01,0]],"ltp":2.12,"tv":5.06,"id":8535963},{"batb":[[0,1.79,1.41]],"ltp":0.0,"tv":0.0,"id":2309796}]}]}
{"op":"mcm","clk":"1005137575","pt":1580641060914,"mc":[{"id":"1.168219389","marketDefinition":{"bspMarket":false,"turnInPlayEnabled":true,"persistenceEnabled":true,"marketBaseRate":5.0,"eventId":"29681328","eventTypeId":"2","numberOfWinners":1,"bettingType":"ODDS","marketType":"SET_WINNER","marketTime":"2020-02-02T10:45:00.000Z","suspendTime":"2020-02-02T10:45:00.000Z","bspReconciled":false,"complete":true,"inPlay":true,"crossMatching":true,"runnersVoidable":false,"numberOfActiveRunners":2,"betDelay":3,"status":"OPEN","runners":[{"status":"ACTIVE","sortPriority":1,"id":8535963,"name":"Nikola Milojevic"},{"status":"ACTIVE","sortPriority":2,"id":2309796,"name":"Robin Haase"}],"regulators":["MR_INT"],"countryCode":"IN","discountAllowed":true,"timezone":"UTC","openDate":"2020-02-02T10:45:00.000Z","version":3148446538,"name":"Set 1 Winner","eventName":"Milojevic v Haase"},"rc":[{"batb":[[0,1.01,10.52],[1,1.01,0]],"ltp":2.12,"tv":5.06,"id":8535963},{"batb":[[0,1.01,10.52],[1,1.76,0],[2,1.01,0]],"ltp":0.0,"tv":0.0,"id":2309796}]}]}
{"op":"mcm","clk":"1005138919","pt":1580641072720,"mc":[{"id":"1.168219389","rc":[{"batl":[[0,2.62,25.21]],"ltp":2.12,"tv":5.06,"id":8535963},{"batb":[[0,1.61,68.06],[1,1.01,10.52]],"ltp":0.0,"tv":0.0,"id":2309796}]}]}
{"op":"mcm","clk":"1005139029","pt":1580641073507,"mc":[{"id":"1.168219389","rc":[{"batb":[[0,2.38,17],[1,2.3,31.93],[2,2.16,22.11]],"ltp":2.12,"tv":5.06,"id":8535963},{"batb":[[0,1.63,27.46],[1,1.61,68.06],[2,1.47,40.92]],"batl":[[0,1.77,42.01]],"ltp":0.0,"tv":0.0,"id":2309796}]}]}
{"op":"mcm","clk":"1005140661","pt":1580641086732,"mc":[{"id":"1.168219389","rc":[{"batb":[[0,2.3,31.93],[1,2.16,22.11],[2,1.01,10.52]],"ltp":2.12,"tv":5.06,"id":8535963},{"batb":[[0,1.61,68.06],[1,1.47,40.92],[2,1.01,10.51]],"ltp":0.0,"tv":0.0,"id":2309796}]}]}
{"op":"mcm","clk":"1005140772","pt":1580641087625,"mc":[{"id":"1.168219389","rc":[{"batb":[[0,2.16,22.11],[1,1.01,10.52],[2,1.01,0]],"ltp":2.12,"tv":5.06,"id":8535963},{"batb":[[0,1.47,40.92],[1,1.01,10.51],[2,1.01,0]],"ltp":0.0,"tv":0.0,"id":2309796}]}]}
{"op":"mcm","clk":"1005141267","pt":1580641091332,"mc":[{"id":"1.168219389","rc":[{"batb":[[0,1.5,264.77],[1,1.49,177.58],[2,1.47,40.92]],"batl":[[0,1.88,169.27],[1,1.9,150.99]],"ltp":0.0,"tv":0.0,"id":2309796}]}]}
{"op":"mcm","clk":"1005142102","pt":1580641098016,"mc":[{"id":"1.168219389","rc":[{"batb":[[0,1.47,40.92],[1,1.01,10.51],[2,1.47,0]],"ltp":0.0,"tv":0.0,"id":2309796}]}]}
{"op":"mcm","clk":"1005142554","pt":1580641101647,"mc":[{"id":"1.168219389","rc":[{"batb":[[1,2,28.09],[2,1.01,10.52]],"ltp":2.12,"tv":5.06,"id":8535963},{"batb":[[0,1.8,145.95],[1,1.78,183.48],[2,1.75,21.72]],"ltp":0.0,"tv":0.0,"id":2309796}]}]}
{"op":"mcm","clk":"1005142678","pt":1580641102636,"mc":[{"id":"1.168219389","rc":[{"batb":[[1,2.14,36.13],[2,2,28.09]],"batl":[[0,2.4,29.41]],"ltp":2.12,"tv":5.06,"id":8535963},{"batl":[[0,1.88,211.28]],"ltp":0.0,"tv":0.0,"id":2309796}]}]}
{"op":"mcm","clk":"1005144510","pt":1580641116685,"mc":[{"id":"1.168219389","rc":[{"batb":[[0,2.14,36.13],[1,2,28.09],[2,1.01,10.52]],"ltp":2.12,"tv":5.06,"id":8535963},{"batb":[[0,1.71,58.81],[1,1.57,31.47],[2,1.01,10.52]],"batl":[[0,1.88,42.01],[1,1.9,0]],"ltp":0.0,"tv":0.0,"id":2309796}]}]}
{"op":"mcm","clk":"1005144651","pt":1580641117731,"mc":[{"id":"1.168219389","rc":[{"batb":[[0,2,28.09],[1,1.01,10.52],[2,1.01,0]],"ltp":2.12,"tv":5.06,"id":8535963},{"batb":[[0,1.57,31.47],[1,1.01,10.52],[2,1.01,0]],"ltp":0.0,"tv":0.0,"id":2309796}]}]}
{"op":"mcm","clk":"1005145009","pt":1580641120298,"mc":[{"id":"1.168219389","rc":[{"batb":[[0,1.76,145.12],[1,1.74,198.01],[2,1.57,31.47]],"batl":[[0,1.83,127.58],[1,1.85,164.13]],"ltp":0.0,"tv":0.0,"id":2309796}]}]}
{"op":"mcm","clk":"1005145506","pt":1580641123999,"mc":[{"id":"1.168219389","rc":[{"batb":[[0,1.57,31.47],[1,1.01,10.52],[2,1.57,0]],"ltp":0.0,"tv":0.0,"id":2309796}]}]}
{"op":"mcm","clk":"1005145829","pt":1580641126696,"mc":[{"id":"1.168219389","rc":[{"batb":[[0,1.61,231.15],[1,1.6,134.39],[2,1.57,31.47]],"batl":[[0,2.02,130.82],[1,2.04,122.06]],"ltp":0.0,"tv":0.0,"id":2309796}]}]}
{"op":"mcm","clk":"1005146424","pt":1580641131430,"mc":[{"id":"1.168219389","rc":[{"batb":[[0,1.57,31.47],[1,1.01,10.52],[2,1.57,0]],"ltp":0.0,"tv":0.0,"id":2309796}]}]}
{"op":"mcm","clk":"1005146851","pt":1580641134715,"mc":[{"id":"1.168219389","rc":[{"batb":[[1,1.99,42.01],[2,1.01,10.52]],"batl":[[0,2.22,33.61]],"ltp":2.12,"tv":5.06,"id":8535963},{"batb":[[0,1.93,144.69],[1,1.91,146.18],[2,1.82,50.41]],"batl":[[0,2.02,171.99]],"ltp":0.0,"tv":0.0,"id":2309796}]}]}
{"op":"mcm","clk":"1005146977","pt":1580641135506,"mc":[{"id":"1.168219389","rc":[{"batb":[[2,1.89,16.76]],"ltp":2.12,"tv":5.06,"id":8535963},{"batb":[[2,1.88,17.23]],"ltp":0.0,"tv":0.0,"id":2309796}]}]}
{"op":"mcm","clk":"1005147804","pt":1580641141646,"mc":[{"id":"1.168219389","rc":[{"batb":[[0,1.88,17.23],[1,1.82,50.41],[2,1.71,23.37]],"batl":[[1,2.04,0]],"ltp":0.0,"tv":0.0,"id":2309796}]}]}
{"op":"mcm","clk":"1005148262","pt":1580641144656,"mc":[{"id":"1.168219389","rc":[{"batb":[[0,1.92,109.12],[1,1.9,148.66],[2,1.88,17.23]],"batl":[[0,2,109.59],[1,2.02,171.99]],"ltp":0.0,"tv":0.0,"id":2309796}]}]}
{"op":"mcm","clk":"1005149077","pt":1580641149730,"mc":[{"id":"1.168219389","rc":[{"batb":[[0,1.89,16.76],[1,1.01,10.52],[2,1.89,0]],"ltp":2.12,"tv":5.06,"id":8535963},{"batb":[[0,1.71,23.37],[1,1.01,10.52],[2,1.88,0]],"ltp":0.0,"tv":0.0,"id":2309796}]}]}
{"op":"mcm","clk":"1005149467","pt":1580641152707,"mc":[{"id":"1.168219389","rc":[{"batb":[[0,1.9,16.6]],"ltp":2.12,"tv":5.06,"id":8535963},{"batb":[[0,1.75,155.02],[1,1.73,202.21],[2,1.7,23.6]],"batl":[[0,2.14,195.94],[1,2.16,103.63]],"ltp":0.0,"tv":0.0,"id":2309796}]}]}
{"op":"mcm","clk":"1005150155","pt":1580641158225,"mc":[{"id":"1.168219389","rc":[{"batb":[[0,1.7,23.6],[1,1.01,10.52],[2,1.7,0]],"ltp":0.0,"tv":0.0,"id":2309796}]}]}
{"op":"mcm","clk":"1005150552","pt":1580641161176,"mc":[{"id":"1.168219389","rc":[{"batb":[[0,1.92,109.12],[1,1.9,148.66],[2,1.7,23.6]],"batl":[[0,2,109.59],[1,2.02,125.72]],"ltp":0.0,"tv":0.0,"id":2309796}]}]}
{"op":"mcm","clk":"1005153760","pt":1580641184596,"mc":[{"id":"1.168219389","rc":[{"batb":[[0,1.7,23.6],[1,1.01,10.52],[2,1.7,0]],"ltp":0.0,"tv":0.0,"id":2309796}]}]}
{"op":"mcm","clk":"1005154113","pt":1580641187577,"mc":[{"id":"1.168219389","rc":[{"batb":[[0,1.75,155.02],[1,1.73,202.21],[2,1.7,23.6]],"batl":[[0,2.14,195.94],[1,2.16,103.63]],"ltp":0.0,"tv":0.0,"id":2309796}]}]}
{"op":"mcm","clk":"1005154749","pt":1580641191692,"mc":[{"id":"1.168219389","rc":[{"batb":[[0,2.24,20.14],[1,2,27.85],[2,1.01,10.52]],"ltp":2.12,"tv":5.06,"id":8535963},{"batl":[[0,1.82,128.34],[1,1.84,167.18]],"ltp":0.0,"tv":0.0,"id":2309796}]}]}
{"op":"mcm","clk":"1005154866","pt":1580641192730,"mc":[{"id":"1.168219389","rc":[{"batb":[[1,2.18,35.29],[2,2,27.85]],"batl":[[0,2.46,28.57]],"ltp":2.12,"tv":5.06,"id":8535963},{"batl":[[2,1.86,42.01]],"ltp":0.0,"tv":0.0,"id":2309796}]}]}
{"op":"mcm","clk":"1005156710","pt":1580641203257,"mc":[{"id":"1.168219389","rc":[{"batb":[[0,1.7,23.6],[1,1.69,60.49],[2,1.49,38.71]],"ltp":0.0,"tv":0.0,"id":2309796}]}]}
{"op":"mcm","clk":"1005157287","pt":1580641206118,"mc":[{"id":"1.168219389","rc":[{"batb":[[0,1.74,190.72],[1,1.72,206.6],[2,1.7,23.6]],"batl":[[0,1.82,190.49]],"ltp":0.0,"tv":0.0,"id":2309796}]}]}
{"op":"mcm","clk":"1005157687","pt":1580641208235,"mc":[{"id":"1.168219389","rc":[{"batb":[[0,2.18,35.29],[1,2,27.85],[2,1.01,10.52]],"ltp":2.12,"tv":5.06,"id":8535963},{"batb":[[0,1.69,60.49],[1,1.49,38.71],[2,1.01,10.52]],"batl":[[0,1.86,42.01],[1,1.84,0],[2,1.86,0]],"ltp":0.0,"tv":0.0,"id":2309796}]}]}
{"op":"mcm","clk":"1005157952","pt":1580641209776,"mc":[{"id":"1.168219389","rc":[{"batb":[[0,2,27.85],[1,1.01,10.52],[2,1.01,0]],"ltp":2.12,"tv":5.06,"id":8535963},{"batb":[[0,1.49,38.71],[1,1.01,10.52],[2,1.01,0]],"ltp":0.0,"tv":0.0,"id":2309796}]}]}
{"op":"mcm","clk":"1005158244","pt":1580641211252,"mc":[{"id":"1.168219389","rc":[{"batb":[[0,1.52,151.08],[1,1.51,168.33],[2,1.49,38.71]],"batl":[[0,2,113.09],[1,2.02,125.8]],"ltp":0.0,"tv":0.0,"id":2309796}]}]}
{"op":"mcm","clk":"1005161303","pt":1580641228749,"mc":[{"id":"1.168219389","rc":[{"batb":[[0,1.49,38.71],[1,1.01,10.52],[2,1.49,0]],"ltp":0.0,"tv":0.0,"id":2309796}]}]}
{"op":"mcm","clk":"1005161750","pt":1580641231563,"mc":[{"id":"1.168219389","rc":[{"batb":[[0,1.92,105.8],[1,1.9,148.74],[2,1.49,38.71]],"ltp":0.0,"tv":0.0,"id":2309796}]}]}
{"op":"mcm","clk":"1005161946","pt":1580641232679,"mc":[{"id":"1.168219389","rc":[{"batb":[[1,1.99,42.01],[2,1.89,16.84]],"batl":[[0,2.22,33.61]],"ltp":2.12,"tv":5.06,"id":8535963},{"batb":[[2,1.87,17.39]],"batl":[[1,2.02,166.97]],"ltp":0.0,"tv":0.0,"id":2309796}]}]}
{"op":"mcm","clk":"1005165386","pt":1580641251743,"mc":[{"id":"1.168219389","rc":[{"batb":[[0,1.89,16.84],[1,1.01,10.52],[2,1.89,0]],"ltp":2.12,"tv":5.06,"id":8535963},{"batb":[[0,1.69,24.39],[1,1.01,10.52],[2,1.87,0]],"ltp":0.0,"tv":0.0,"id":2309796}]}]}
{"op":"mcm","clk":"1005165879","pt":1580641254115,"mc":[{"id":"1.168219389","rc":[{"batb":[[0,1.73,158.35],[1,1.71,210.68],[2,1.69,24.39]],"batl":[[0,2.14,97.94],[1,2.16,103.57]],"ltp":0.0,"tv":0.0,"id":2309796}]}]}
{"op":"mcm","clk":"1005166246","pt":1580641256314,"mc":[{"id":"1.168219389","rc":[{"batb":[[0,1.69,24.39],[1,1.01,10.52],[2,1.69,0]],"ltp":0.0,"tv":0.0,"id":2309796}]}]}
{"op":"mcm","clk":"1005166815","pt":1580641259632,"mc":[{"id":"1.168219389","rc":[{"batb":[[1,1.87,168.71],[2,1.85,161.87]],"batl":[[0,1.96,156.24],[1,1.98,133.32]],"ltp":2.12,"tv":5.06,"id":8535963}]}]}
{"op":"mcm","clk":"1005166993","pt":1580641260755,"mc":[{"id":"1.168219389","rc":[{"batb":[[2,1.86,48.73]],"batl":[[2,2.06,39.49]],"ltp":2.12,"tv":5.06,"id":8535963},{"batb":[[0,1.99,28.8],[1,1.94,44.53],[2,1.88,17.15]],"batl":[[0,2.18,35.29]],"ltp":0.0,"tv":0.0,"id":2309796}]}]}
{"op":"mcm","clk":"1005173213","pt":1580641296400,"mc":[{"id":"1.168219389","rc":[{"batb":[[1,1.86,48.73],[2,1.7,23.84]],"batl":[[0,2.06,39.49],[1,1.98,0],[2,2.06,0]],"ltp":2.12,"tv":5.06,"id":8535963}]}]}
{"op":"mcm","clk":"1005173738","pt":1580641299370,"mc":[{"id":"1.168219389","rc":[{"batb":[[2,1.7,196.39]],"batl":[[1,2.08,114.23],[2,2.1,112.31]],"ltp":2.12,"tv":5.06,"id":8535963}]}]}
{"op":"mcm","clk":"1005175517","pt":1580641308318,"mc":[{"id":"1.168219389","rc":[{"batb":[[0,1.86,48.73],[1,1.7,196.39],[2,1.68,223.38]],"ltp":2.12,"tv":5.06,"id":8535963},{"batb":[[0,1.94,44.53],[1,1.88,17.15],[2,1.01,10.52]],"ltp":0.0,"tv":0.0,"id":2309796}]}]}
{"op":"mcm","clk":"1005175794","pt":1580641309913,"mc":[{"id":"1.168219389","rc":[{"batb":[[0,1.7,196.39],[1,1.68,223.38],[2,1.01,10.52]],"batl":[[0,2.08,114.23],[1,2.1,112.31],[2,2.1,0]],"ltp":2.12,"tv":5.06,"id":8535963},{"batb":[[0,1.88,17.15],[1,1.01,10.52],[2,1.01,0]],"ltp":0.0,"tv":0.0,"id":2309796}]}]}
{"op":"mcm","clk":"1005177567","pt":1580641319418,"mc":[{"id":"1.168219389","rc":[{"batb":[[0,1.7,23.84],[1,1.01,10.52],[2,1.01,0]],"ltp":2.12,"tv":5.06,"id":8535963}]}]}
{"op":"mcm","clk":"1005178168","pt":1580641322731,"mc":[{"id":"1.168219389","rc":[{"batb":[[0,1.94,44.53],[1,1.7,23.84],[2,1.01,10.52]],"batl":[[0,2.18,35.29]],"ltp":2.12,"tv":5.06,"id":8535963},{"batb":[[0,1.92,166.74],[1,1.9,148.76],[2,1.88,17.15]],"batl":[[0,2.02,179.91],[1,2.04,122.2],[2,2.06,39.49]],"ltp":0.0,"tv":0.0,"id":2309796}]}]}
{"op":"mcm","clk":"1005178286","pt":1580641323321,"mc":[{"id":"1.168219389","rc":[{"batb":[[0,2,28.33],[1,1.94,44.53],[2,1.83,18.65]],"ltp":2.12,"tv":5.06,"id":8535963}]}]}
{"op":"mcm","clk":"1005180603","pt":1580641336061,"mc":[{"id":"1.168219389","rc":[{"batb":[[0,1.94,44.53],[1,1.83,18.65],[2,1.67,409.76]],"ltp":2.12,"tv":5.06,"id":8535963},{"batb":[[0,1.86,48.73],[1,1.8,19.83],[2,1.58,416.47]],"batl":[[0,2.06,39.49],[1,2.04,0],[2,2.06,0]],"ltp":0.0,"tv":0.0,"id":2309796}]}]}
{"op":"mcm","clk":"1005180923","pt":1580641337765,"mc":[{"id":"1.168219389","rc":[{"batb":[[0,1.83,18.65],[1,1.67,409.76],[2,1.01,10.52]],"ltp":2.12,"tv":5.06,"id":8535963},{"batb":[[0,1.8,19.83],[1,1.58,416.47],[2,1.01,10.52]],"ltp":0.0,"tv":0.0,"id":2309796}]}]}
{"op":"mcm","clk":"1005181111","pt":1580641338882,"mc":[{"id":"1.168219389","rc":[{"batb":[[0,1.84,146.32],[1,1.82,170.8],[2,1.8,19.83]],"batl":[[0,2.2,107.46],[1,2.22,95.88]],"ltp":0.0,"tv":0.0,"id":2309796}]}]}
{"op":"mcm","clk":"1005182555","pt":1580641346882,"mc":[{"id":"1.168219389","rc":[{"batb":[[0,1.84,113.65]],"ltp":0.0,"tv":0.0,"id":2309796}]}]}
{"op":"mcm","clk":"1005183188","pt":1580641350430,"mc":[{"id":"1.168219389","rc":[{"batb":[[0,1.8,19.83],[1,1.58,416.47],[2,1.01,10.52]],"batl":[[0,2.2,134.66]],"ltp":0.0,"tv":0.0,"id":2309796}]}]}
{"op":"mcm","clk":"1005183618","pt":1580641352689,"mc":[{"id":"1.168219389","rc":[{"batb":[[1,1.01,10.52],[2,1.01,0]],"ltp":2.12,"tv":5.06,"id":8535963}]}]}
{"op":"mcm","clk":"1005184002","pt":1580641354697,"mc":[{"id":"1.168219389","rc":[{"batb":[[0,2.02,41.17],[1,1.83,18.65],[2,1.01,10.52]],"batl":[[0,2.28,32.77]],"ltp":2.12,"tv":5.06,"id":8535963},{"batb":[[0,1.83,175.73],[1,1.81,174.07],[2,1.8,19.83]],"batl":[[0,1.91,115.37],[1,1.93,144.36],[2,1.98,42.01]],"ltp":0.0,"tv":0.0,"id":2309796}]}]}
{"op":"mcm","clk":"1005184184","pt":1580641355595,"mc":[{"id":"1.168219389","rc":[{"batb":[[0,2.1,24.31],[1,2.02,41.17],[2,1.96,29.9]],"ltp":2.12,"tv":5.06,"id":8535963}]}]}
{"op":"mcm","clk":"1005187757","pt":1580641374649,"mc":[{"id":"1.168219389","rc":[{"batb":[[0,1.8,19.83],[1,1.79,52.93],[2,1.74,21.87]],"batl":[[0,1.98,42.01],[1,1.93,0],[2,1.98,0]],"ltp":0.0,"tv":0.0,"id":2309796}]}]}
{"op":"mcm","clk":"1005187974","pt":1580641375722,"mc":[{"id":"1.168219389","rc":[{"batb":[[0,1.96,29.9],[1,1.74,404.28],[2,1.01,10.52]],"ltp":2.12,"tv":5.06,"id":8535963},{"batb":[[0,1.74,21.87],[1,1.58,416.47],[2,1.01,10.52]],"ltp":0.0,"tv":0.0,"id":2309796}]}]}
{"op":"mcm","clk":"1005188337","pt":1580641377524,"mc":[{"id":"1.168219389","rc":[{"batb":[[0,1.78,173.66],[1,1.76,191.09],[2,1.74,21.87]],"batl":[[0,2.02,99.23],[1,2.04,122.25]],"ltp":0.0,"tv":0.0,"id":2309796}]}]}
{"op":"mcm","clk":"1005189117","pt":1580641381645,"mc":[{"id":"1.168219389","rc":[{"batl":[[0,1.86,164.17],[1,1.88,156.46]],"ltp":0.0,"tv":0.0,"id":2309796}]}]}
{"op":"mcm","clk":"1005189340","pt":1580641382736,"mc":[{"id":"1.168219389","rc":[{"batb":[[0,2.18,21.87],[1,2.1,37.81],[2,2.08,25.1]],"batl":[[0,2.36,30.25]],"ltp":2.12,"tv":5.06,"id":8535963},{"batb":[[2,1.75,55.45]],"batl":[[2,1.9,42.01]],"ltp":0.0,"tv":0.0,"id":2309796}]}]}
{"op":"mcm","clk":"1005190710","pt":1580641389968,"mc":[{"id":"1.168219389","rc":[{"batb":[[0,2.1,37.81],[1,2.08,25.1],[2,1.74,404.28]],"ltp":2.12,"tv":5.06,"id":8535963},{"batb":[[0,1.76,113.28],[1,1.75,55.45],[2,1.7,23.68]],"batl":[[0,1.9,42.01],[1,1.88,0],[2,1.9,0]],"ltp":0.0,"tv":0.0,"id":2309796}]}]}
{"op":"mcm","clk":"1005191258","pt":1580641392757,"mc":[{"id":"1.168219389","rc":[{"batb":[[0,2.08,25.1],[1,1.74,404.28],[2,1.01,10.52]],"ltp":2.12,"tv":5.06,"id":8535963},{"batb":[[1,1.7,23.68],[2,1.58,416.47]],"ltp":0.0,"tv":0.0,"id":2309796}]}]}
{"op":"mcm","clk":"1005191279","pt":1580641392862,"mc":[{"id":"1.168219389","rc":[{"batb":[[1,1.74,198.45],[2,1.7,23.68]],"batl":[[0,1.92,172.4],[1,1.94,142.06]],"ltp":0.0,"tv":0.0,"id":2309796}]}]}
{"op":"mcm","clk":"1005192118","pt":1580641396458,"mc":[{"id":"1.168219389","rc":[{"batb":[[0,1.7,23.68],[1,1.58,416.47],[2,1.01,10.52]],"ltp":0.0,"tv":0.0,"id":2309796}]}]}
{"op":"mcm","clk":"1005192680","pt":1580641399274,"mc":[{"id":"1.168219389","rc":[{"batb":[[0,1.84,106.98],[1,1.82,170.87],[2,1.7,23.68]],"ltp":0.0,"tv":0.0,"id":2309796}]}]}
{"op":"mcm","clk":"1005192938","pt":1580641400766,"mc":[{"id":"1.168219389","rc":[{"batb":[[1,2.02,41.17],[2,1.95,30.69]],"batl":[[0,2.28,32.77]],"ltp":2.12,"tv":5.06,"id":8535963},{"batb":[[2,1.81,19.2]],"batl":[[2,1.96,42.01]],"ltp":0.0,"tv":0.0,"id":2309796}]}]}
{"op":"mcm","clk":"1005194314","pt":1580641407684,"mc":[{"id":"1.168219389","rc":[{"batb":[[0,2.02,41.17],[1,1.95,30.69],[2,1.74,404.28]],"ltp":2.12,"tv":5.06,"id":8535963},{"batb":[[0,1.8,52.09],[1,1.76,21.24],[2,1.58,416.47]],"batl":[[0,1.96,42.01],[1,1.94,0],[2,1.96,0]],"ltp":0.0,"tv":0.0,"id":2309796}]}]}
{"op":"mcm","clk":"1005194353","pt":1580641407900,"mc":[{"id":"1.168219389","rc":[{"batb":[[0,1.95,30.69],[1,1.74,404.28],[2,1.01,10.52]],"ltp":2.12,"tv":5.06,"id":8535963},{"batb":[[0,1.76,21.24],[1,1.58,416.47],[2,1.01,10.52]],"ltp":0.0,"tv":0.0,"id":2309796}]}]}
{"op":"mcm","clk":"1005194995","pt":1580641410600,"mc":[{"id":"1.168219389","rc":[{"batb":[[0,1.79,120.27],[1,1.77,187.38],[2,1.76,21.24]],"batl":[[0,2.02,124.09],[1,2.04,122.27]],"ltp":0.0,"tv":0.0,"id":2309796}]}]}
{"op":"mcm","clk":"1005196411","pt":1580641417332,"mc":[{"id":"1.168219389","rc":[{"batl":[[0,1.86,126.49],[1,1.88,156.55]],"ltp":0.0,"tv":0.0,"id":2309796}]}]}
{"op":"mcm","clk":"1005196680","pt":1580641418697,"mc":[{"id":"1.168219389","rc":[{"batb":[[0,2.16,22.58],[1,2.1,37.81],[2,2.02,27.54]],"batl":[[0,2.38,30.25]],"ltp":2.12,"tv":5.06,"id":8535963},{"batl":[[2,1.89,42.01]],"ltp":0.0,"tv":0.0,"id":2309796}]}]}
{"op":"mcm","clk":"1005202649","pt":1580641448209,"mc":[{"id":"1.168219389","rc":[{"batb":[[0,2.1,37.81],[1,2.02,27.54],[2,1.74,404.28]],"ltp":2.12,"tv":5.06,"id":8535963},{"batb":[[0,1.74,56.29],[1,1.6,29.74],[2,1.58,416.47]],"batl":[[0,1.89,42.01],[1,1.88,0],[2,1.89,0]],"ltp":0.0,"tv":0.0,"id":2309796}]}]}
{"op":"mcm","clk":"1005202957","pt":1580641449824,"mc":[{"id":"1.168219389","rc":[{"batb":[[0,2.02,27.54],[1,1.74,404.28],[2,1.01,10.52]],"ltp":2.12,"tv":5.06,"id":8535963},{"batb":[[0,1.6,29.74],[1,1.58,416.47],[2,1.01,10.52]],"ltp":0.0,"tv":0.0,"id":2309796}]}]}
{"op":"mcm","clk":"1005203646","pt":1580641453097,"mc":[{"id":"1.168219389","rc":[{"batb":[[0,1.75,173.08],[1,1.73,202.62],[2,1.6,29.74]],"batl":[[0,1.82,112.31],[1,1.84,167.54]],"ltp":0.0,"tv":0.0,"id":2309796}]}]}
{"op":"mcm","clk":"1005204388","pt":1580641456719,"mc":[{"id":"1.168219389","rc":[{"batb":[[0,1.6,29.74],[1,1.58,416.47],[2,1.01,10.52]],"ltp":0.0,"tv":0.0,"id":2309796}]}]}
{"op":"mcm","clk":"1005205211","pt":1580641460734,"mc":[{"id":"1.168219389","rc":[{"batb":[[0,1.63,137.9],[1,1.62,128.56],[2,1.6,29.74]],"batl":[[0,1.99,159.84],[1,2.02,189.69]],"ltp":0.0,"tv":0.0,"id":2309796}]}]}
{"op":"mcm","clk":"1005207519","pt":1580641471365,"mc":[{"id":"1.168219389","rc":[{"batb":[[1,1.01,10.52],[2,1.01,0]],"ltp":2.12,"tv":5.06,"id":8535963}]}]}
{"op":"mcm","clk":"1005207817","pt":1580641472741,"mc":[{"id":"1.168219389","rc":[{"batl":[[0,2.7,24.37]],"ltp":2.12,"tv":5.06,"id":8535963},{"batb":[[2,1.6,99.48]],"batl":[[0,1.69,180.41],[1,1.71,212.65]],"ltp":0.0,"tv":0.0,"id":2309796}]}]}
{"op":"mcm","clk":"1005208025","pt":1580641473753,"mc":[{"id":"1.168219389","rc":[{"batb":[[0,2.46,15.5],[1,2.36,30.25],[2,2.22,20.77]],"ltp":2.12,"tv":5.06,"id":8535963},{"batl":[[2,1.74,42.01]],"ltp":0.0,"tv":0.0,"id":2309796}]}]}
{"op":"mcm","clk":"1005211144","pt":1580641490136,"mc":[{"id":"1.168219389","rc":[{"batb":[[0,2.22,20.77],[1,1.92,394.91],[2,1.01,10.52]],"ltp":2.12,"tv":5.06,"id":8535963},{"batb":[[0,1.43,46.35],[1,1.4,451],[2,1.01,10.51]],"ltp":0.0,"tv":0.0,"id":2309796}]}]}
{"op":"mcm","clk":"1005212047","pt":1580641494747,"mc":[{"id":"1.168219389","rc":[{"batb":[[1,1.01,10.51],[2,1.01,0]],"ltp":0.0,"tv":0.0,"id":2309796}]}]}
{"op":"mcm","clk":"1005212335","pt":1580641496386,"mc":[{"id":"1.168219389","rc":[{"batb":[[0,1.75,167.12],[1,1.73,202.61],[2,1.43,46.35]],"batl":[[0,1.82,117.99],[1,1.84,167.53]],"ltp":0.0,"tv":0.0,"id":2309796}]}]}
{"op":"mcm","clk":"1005212496","pt":1580641497177,"mc":[{"id":"1.168219389","rc":[{"batb":[[1,2.16,36.13],[2,2.02,26.83]],"batl":[[0,2.44,28.57]],"ltp":2.12,"tv":5.06,"id":8535963},{"batb":[[2,1.72,22.98]],"batl":[[2,1.87,42.01]],"ltp":0.0,"tv":0.0,"id":2309796}]}]}
{"op":"mcm","clk":"1005214847","pt":1580641508997,"mc":[{"id":"1.168219389","rc":[{"batb":[[0,2.16,36.13],[1,2.02,26.83],[2,1.92,394.91]],"ltp":2.12,"tv":5.06,"id":8535963},{"batb":[[0,1.69,60.49],[1,1.53,34.62],[2,1.46,435.71]],"batl":[[0,1.87,42.01],[1,1.84,0],[2,1.87,0]],"ltp":0.0,"tv":0.0,"id":2309796}]}]}
{"op":"mcm","clk":"1005215033","pt":1580641509907,"mc":[{"id":"1.168219389","rc":[{"batb":[[0,2.02,26.83],[1,1.92,394.91],[2,1.01,10.52]],"ltp":2.12,"tv":5.06,"id":8535963},{"batb":[[0,1.53,34.62],[1,1.46,435.71],[2,1.01,10.51]],"ltp":0.0,"tv":0.0,"id":2309796}]}]}
{"op":"mcm","clk":"1005215415","pt":1580641511912,"mc":[{"id":"1.168219389","rc":[{"batb":[[0,1.56,254.01],[1,1.55,152.48],[2,1.53,34.62]],"batl":[[0,1.97,138.46],[1,1.99,131.58]],"ltp":0.0,"tv":0.0,"id":2309796}]}]}
{"op":"mcm","clk":"1005217192","pt":1580641519993,"mc":[{"id":"1.168219389","rc":[{"batb":[[0,1.53,34.62],[1,1.46,435.71],[2,1.01,10.51]],"ltp":0.0,"tv":0.0,"id":2309796}]}]}
{"op":"mcm","clk":"1005217749","pt":1580641522700,"mc":[{"id":"1.168219389","rc":[{"batb":[[1,1.01,10.52],[2,1.01,0]],"ltp":2.12,"tv":5.06,"id":8535963},{"batb":[[0,1.88,179.37],[1,1.86,159.28],[2,1.53,34.62]],"ltp":0.0,"tv":0.0,"id":2309796}]}]}
{"op":"mcm","clk":"1005217903","pt":1580641523508,"mc":[{"id":"1.168219389","rc":[{"batb":[[1,1.92,16.05],[2,1.01,10.52]],"ltp":2.12,"tv":5.06,"id":8535963},{"batb":[[2,1.85,18.02]],"ltp":0.0,"tv":0.0,"id":2309796}]}]}
{"op":"mcm","clk":"1005218179","pt":1580641524881,"mc":[{"id":"1.168219389","rc":[{"batb":[[1,2,42.01],[2,1.92,16.05]],"batl":[[0,2.24,33.61]],"ltp":2.12,"tv":5.06,"id":8535963},{"batl":[[1,1.99,173.59]],"ltp":0.0,"tv":0.0,"id":2309796}]}]}
{"op":"mcm","clk":"1005221248","pt":1580641539750,"mc":[{"id":"1.168219389","rc":[{"batb":[[0,2,42.01],[1,1.92,16.05],[2,1.7,409.32]],"ltp":2.12,"tv":5.06,"id":8535963},{"batb":[[2,1.8,52.09]],"ltp":0.0,"tv":0.0,"id":2309796}]}]}
{"op":"mcm","clk":"1005221331","pt":1580641540138,"mc":[{"id":"1.168219389","rc":[{"batb":[[0,1.92,16.05],[1,1.7,409.32],[2,1.01,10.52]],"ltp":2.12,"tv":5.06,"id":8535963},{"batb":[[0,1.67,25.18],[1,1.55,420.5],[2,1.01,10.52]],"ltp":0.0,"tv":0.0,"id":2309796}]}]}
{"op":"mcm","clk":"1005222103","pt":1580641543532,"mc":[{"id":"1.168219389","rc":[{"batb":[[0,1.71,207.59],[1,1.69,219.88],[2,1.67,25.18]],"batl":[[0,2.1,146.4],[1,2.12,109.32]],"ltp":0.0,"tv":0.0,"id":2309796}]}]}
{"op":"mcm","clk":"1005222946","pt":1580641547369,"mc":[{"id":"1.168219389","rc":[{"batb":[[0,1.67,25.18],[1,1.55,420.5],[2,1.01,10.52]],"ltp":0.0,"tv":0.0,"id":2309796}]}]}
{"op":"mcm","clk":"1005223603","pt":1580641550360,"mc":[{"id":"1.168219389","rc":[{"batb":[[1,1.91,154.23],[2,1.89,151.26]],"batl":[[0,2,137.34],[1,2.02,125.71]],"ltp":2.12,"tv":5.06,"id":8535963}]}]}
{"op":"mcm","clk":"1005223761","pt":1580641551146,"mc":[{"id":"1.168219389","rc":[{"batb":[[2,1.9,46.21]],"batl":[[2,2.1,37.81]],"ltp":2.12,"tv":5.06,"id":8535963},{"batb":[[0,1.96,30.21],[1,1.9,46.21],[2,1.85,18.18]],"batl":[[0,2.12,36.97]],"ltp":0.0,"tv":0.0,"id":2309796}]}]}
{"op":"mcm","clk":"1005226309","pt":1580641562755,"mc":[{"id":"1.168219389","rc":[{"batb":[[0,1.9,46.21],[1,1.85,18.02],[2,1.7,409.32]],"batl":[[0,2.1,37.81],[1,2.02,0],[2,2.1,0]],"ltp":2.12,"tv":5.06,"id":8535963},{"batb":[[0,1.9,46.21],[1,1.85,18.18],[2,1.55,420.5]],"ltp":0.0,"tv":0.0,"id":2309796}]}]}
{"op":"mcm","clk":"1005226563","pt":1580641563991,"mc":[{"id":"1.168219389","rc":[{"batb":[[0,1.85,18.02],[1,1.7,409.32],[2,1.01,10.52]],"ltp":2.12,"tv":5.06,"id":8535963},{"batb":[[0,1.85,18.18],[1,1.55,420.5],[2,1.01,10.52]],"ltp":0.0,"tv":0.0,"id":2309796}]}]}
{"op":"mcm","clk":"1005227131","pt":1580641566700,"mc":[{"id":"1.168219389","rc":[{"batb":[[0,1.86,109.82],[1,1.85,18.02],[2,1.84,164.63]],"ltp":2.12,"tv":5.06,"id":8535963}]}]}
{"op":"mcm","clk":"1005227399","pt":1580641567815,"mc":[{"id":"1.168219389","rc":[{"batb":[[1,1.01,10.52],[2,1.01,0]],"ltp":0.0,"tv":0.0,"id":2309796}]}]}
{"op":"mcm","clk":"1005227809","pt":1580641569478,"mc":[{"id":"1.168219389","rc":[{"batl":[[0,1.94,152.25],[1,1.96,137.42]],"ltp":2.12,"tv":5.06,"id":8535963}]}]}
{"op":"mcm","clk":"1005227937","pt":1580641570098,"mc":[{"id":"1.168219389","rc":[{"batb":[[0,2.02,26.91],[1,1.91,16.29],[2,1.01,10.52]],"ltp":0.0,"tv":0.0,"id":2309796}]}]}
{"op":"mcm","clk":"1005228124","pt":1580641570999,"mc":[{"id":"1.168219389","rc":[{"batl":[[2,2.02,41.17]],"ltp":2.12,"tv":5.06,"id":8535963},{"batb":[[1,1.97,42.85],[2,1.91,16.29]],"batl":[[0,2.22,33.61]],"ltp":0.0,"tv":0.0,"id":2309796}]}]}
{"op":"mcm","clk":"1005244787","pt":1580641652631,"mc":[{"id":"1.168219389","rc":[{"batb":[[0,1.66,25.73],[1,1.58,416.47],[2,1.01,10.52]],"ltp":2.12,"tv":5.06,"id":8535963},{"batb":[[0,1.91,16.29],[1,1.67,409.76],[2,1.01,10.52]],"ltp":0.0,"tv":0.0,"id":2309796}]}]}
{"op":"mcm","clk":"1005245605","pt":1580641656729,"mc":[{"id":"1.168219389","rc":[{"batb":[[0,1.82,118.58],[1,1.8,176.83],[2,1.66,25.73]],"batl":[[0,1.89,102.51],[1,1.91,148.69]],"ltp":2.12,"tv":5.06,"id":8535963}]}]}
{"op":"mcm","clk":"1005246215","pt":1580641659617,"mc":[{"id":"1.168219389","rc":[{"batb":[[0,1.66,25.73],[1,1.58,416.47],[2,1.01,10.52]],"ltp":2.12,"tv":5.06,"id":8535963}]}]}
{"op":"mcm","clk":"1005246846","pt":1580641662558,"mc":[{"id":"1.168219389","rc":[{"batb":[[0,1.68,118.94],[1,1.66,258.58],[2,1.58,416.47]],"batl":[[0,2.08,203.72],[1,2.1,112.28]],"ltp":2.12,"tv":5.06,"id":8535963}]}]}
{"op":"mcm","clk":"1005249493","pt":1580641675686,"mc":[{"id":"1.168219389","rc":[{"batb":[[0,1.66,25.73],[1,1.58,416.47],[2,1.01,10.52]],"ltp":2.12,"tv":5.06,"id":8535963}]}]}
{"op":"mcm","clk":"1005249808","pt":1580641677382,"mc":[{"id":"1.168219389","rc":[{"batb":[[1,1.01,10.52],[2,1.01,0]],"ltp":2.12,"tv":5.06,"id":8535963}]}]}
{"op":"mcm","clk":"1005250072","pt":1580641678676,"mc":[{"id":"1.168219389","rc":[{"batb":[[0,1.94,118.52],[1,1.92,143.87],[2,1.91,16.29]],"batl":[[0,2.04,208.95],[1,2.06,118.74]],"ltp":0.0,"tv":0.0,"id":2309796}]}]}
{"op":"mcm","clk":"1005250231","pt":1580641679465,"mc":[{"id":"1.168219389","rc":[{"batb":[[0,1.96,29.82],[1,1.92,45.37],[2,1.79,19.99]],"batl":[[0,2.14,36.13]],"ltp":2.12,"tv":5.06,"id":8535963},{"batl":[[2,2.08,38.65]],"ltp":0.0,"tv":0.0,"id":2309796}]}]}
{"op":"mcm","clk":"1005252933","pt":1580641693564,"mc":[{"id":"1.168219389","rc":[{"batb":[[0,1.92,45.37],[1,1.79,19.99],[2,1.67,409.76]],"ltp":2.12,"tv":5.06,"id":8535963},{"batb":[[0,1.89,47.05],[1,1.83,18.73],[2,1.67,409.76]],"batl":[[0,2.08,38.65],[1,2.06,0],[2,2.08,0]],"ltp":0.0,"tv":0.0,"id":2309796}]}]}
{"op":"mcm","clk":"1005253024","pt":1580641694102,"mc":[{"id":"1.168219389","rc":[{"batb":[[0,1.79,19.99],[1,1.67,409.76],[2,1.01,10.52]],"ltp":2.12,"tv":5.06,"id":8535963},{"batb":[[0,1.83,18.73],[1,1.67,409.76],[2,1.01,10.52]],"ltp":0.0,"tv":0.0,"id":2309796}]}]}
{"op":"mcm","clk":"1005254299","pt":1580641700574,"mc":[{"id":"1.168219389","rc":[{"batb":[[0,1.94,130.27],[1,1.92,143.91],[2,1.79,19.99]],"batl":[[0,2.04,197.71],[1,2.06,118.66]],"ltp":2.12,"tv":5.06,"id":8535963}]}]}
{"op":"mcm","clk":"1005254917","pt":1580641703700,"mc":[{"id":"1.168219389","rc":[{"batb":[[0,1.79,19.99],[1,1.67,409.76],[2,1.01,10.52]],"ltp":2.12,"tv":5.06,"id":8535963}]}]}
{"op":"mcm","clk":"1005255504","pt":1580641706720,"mc":[{"id":"1.168219389","rc":[{"batb":[[0,1.81,161.5],[1,1.79,200.18],[2,1.67,409.76]],"batl":[[0,2.18,139.7],[1,2.2,98.43]],"ltp":2.12,"tv":5.06,"id":8535963}]}]}
{"op":"mcm","clk":"1005255693","pt":1580641707580,"mc":[{"id":"1.168219389","rc":[{"batb":[[0,1.79,19.99],[1,1.67,409.76],[2,1.01,10.52]],"ltp":2.12,"tv":5.06,"id":8535963}]}]}
{"op":"mcm","clk":"1005255968","pt":1580641708803,"mc":[{"id":"1.168219389","rc":[{"batb":[[1,1.01,10.52],[2,1.01,0]],"ltp":2.12,"tv":5.06,"id":8535963},{"batb":[[1,1.01,10.52],[2,1.01,0]],"ltp":0.0,"tv":0.0,"id":2309796}]}]}
{"op":"mcm","clk":"1005256340","pt":1580641710685,"mc":[{"id":"1.168219389","rc":[{"batb":[[0,1.85,143.77],[1,1.83,186.39],[2,1.01,10.52]],"batl":[[0,1.93,128.22],[1,1.95,139.71]],"ltp":0.0,"tv":0.0,"id":2309796}]}]}
{"op":"mcm","clk":"1005256536","pt":1580641711698,"mc":[{"id":"1.168219389","rc":[{"batb":[[0,2.06,25.73],[1,2,42.01],[2,1.93,15.66]],"batl":[[0,2.24,33.61]],"ltp":2.12,"tv":5.06,"id":8535963},{"batb":[[2,1.8,52.09]],"batl":[[2,1.98,42.01]],"ltp":0.0,"tv":0.0,"id":2309796}]}]}
{"op":"mcm","clk":"1005258762","pt":1580641722627,"mc":[{"id":"1.168219389","rc":[{"batb":[[0,2,42.01],[1,1.93,15.66],[2,1.74,404.28]],"ltp":2.12,"tv":5.06,"id":8535963},{"batb":[[0,1.8,52.09],[1,1.77,20.85],[2,1.52,425.49]],"batl":[[0,1.98,42.01],[1,1.95,0],[2,1.98,0]],"ltp":0.0,"tv":0.0,"id":2309796}]}]}
{"op":"mcm","clk":"1005259036","pt":1580641724110,"mc":[{"id":"1.168219389","rc":[{"batb":[[0,1.93,15.66],[1,1.74,404.28],[2,1.01,10.52]],"ltp":2.12,"tv":5.06,"id":8535963},{"batb":[[0,1.77,20.85],[1,1.52,425.49],[2,1.01,10.52]],"ltp":0.0,"tv":0.0,"id":2309796}]}]}
{"op":"mcm","clk":"1005259348","pt":1580641725712,"mc":[{"id":"1.168219389","rc":[{"batb":[[0,1.8,125.02],[1,1.78,183.59],[2,1.77,20.85]],"batl":[[0,2.06,190.67],[1,2.08,115.46]],"ltp":0.0,"tv":0.0,"id":2309796}]}]}
{"op":"mcm","clk":"1005262758","pt":1580641743694,"mc":[{"id":"1.168219389","rc":[{"batl":[[0,1.87,112.64],[1,1.89,153.75]],"ltp":0.0,"tv":0.0,"id":2309796}]}]}
{"op":"mcm","clk":"1005262942","pt":1580641744587,"mc":[{"id":"1.168219389","rc":[{"batb":[[0,2.14,22.98],[1,2.04,26.44],[2,1.93,15.66]],"ltp":2.12,"tv":5.06,"id":8535963}]}]}
{"op":"mcm","clk":"1005263098","pt":1580641745335,"mc":[{"id":"1.168219389","rc":[{"batb":[[1,2.06,39.49],[2,2.04,26.44]],"batl":[[0,2.32,31.09]],"ltp":2.12,"tv":5.06,"id":8535963},{"batl":[[2,1.94,42.01]],"ltp":0.0,"tv":0.0,"id":2309796}]}]}
{"op":"mcm","clk":"1005265143","pt":1580641755701,"mc":[{"id":"1.168219389","rc":[{"batb":[[0,1.77,20.85],[1,1.76,54.61],[2,1.73,22.5]],"batl":[[0,1.94,42.01],[1,1.89,0],[2,1.94,0]],"ltp":0.0,"tv":0.0,"id":2309796}]}]}
{"op":"mcm","clk":"1005265311","pt":1580641756606,"mc":[{"id":"1.168219389","rc":[{"batb":[[0,2.04,26.44],[1,1.74,404.28],[2,1.01,10.52]],"ltp":2.12,"tv":5.06,"id":8535963},{"batb":[[0,1.73,22.5],[1,1.52,425.49],[2,1.01,10.52]],"ltp":0.0,"tv":0.0,"id":2309796}]}]}
{"op":"mcm","clk":"1005265703","pt":1580641758719,"mc":[{"id":"1.168219389","rc":[{"batb":[[0,1.77,167.86],[1,1.75,194.74],[2,1.73,22.5]],"batl":[[0,1.93,115.71],[1,1.95,139.72]],"ltp":0.0,"tv":0.0,"id":2309796}]}]}
{"op":"mcm","clk":"1005266778","pt":1580641764241,"mc":[{"id":"1.168219389","rc":[{"batb":[[1,1.01,10.52],[2,1.01,0]],"ltp":2.12,"tv":5.06,"id":8535963}]}]}
{"op":"mcm","clk":"1005267074","pt":1580641765723,"mc":[{"id":"1.168219389","rc":[{"batl":[[0,1.85,179.45],[1,1.87,158.77]],"ltp":0.0,"tv":0.0,"id":2309796}]}]}
{"op":"mcm","clk":"1005267266","pt":1580641766632,"mc":[{"id":"1.168219389","rc":[{"batb":[[0,2.2,21.24],[1,2.04,26.44],[2,1.01,10.52]],"ltp":2.12,"tv":5.06,"id":8535963}]}]}
{"op":"mcm","clk":"1005267464","pt":1580641767425,"mc":[{"id":"1.168219389","rc":[{"batb":[[1,2.12,36.97],[2,2.04,26.44]],"batl":[[0,2.38,30.25]],"ltp":2.12,"tv":5.06,"id":8535963},{"batl":[[2,1.88,42.01]],"ltp":0.0,"tv":0.0,"id":2309796}]}]}
{"op":"mcm","clk":"1005272140","pt":1580641791646,"mc":[{"id":"1.168219389","rc":[{"batb":[[0,2.12,36.97],[1,2.04,26.44],[2,1.82,401.24]],"ltp":2.12,"tv":5.06,"id":8535963},{"batb":[[0,1.72,57.97],[1,1.56,32.1],[2,1.52,425.49]],"batl":[[0,1.88,42.01],[1,1.87,0],[2,1.88,0]],"ltp":0.0,"tv":0.0,"id":2309796}]}]}
{"op":"mcm","clk":"1005272259","pt":1580641792209,"mc":[{"id":"1.168219389","rc":[{"batb":[[0,2.04,26.44],[1,1.82,401.24],[2,1.01,10.52]],"ltp":2.12,"tv":5.06,"id":8535963},{"batb":[[0,1.56,32.1],[1,1.52,425.49],[2,1.01,10.52]],"ltp":0.0,"tv":0.0,"id":2309796}]}]}
{"op":"mcm","clk":"1005273039","pt":1580641796403,"mc":[{"id":"1.168219389","rc":[{"batb":[[0,1.73,204.72],[1,1.71,210.62],[2,1.56,32.1]],"batl":[[0,1.81,188.58],[1,1.83,169.95]],"ltp":0.0,"tv":0.0,"id":2309796}]}]}
{"op":"mcm","clk":"1005273404","pt":1580641798316,"mc":[{"id":"1.168219389","rc":[{"trd":[[2.22,21.03]],"ltp":2.22,"tv":26.09,"id":8535963},{"trd":[[1.81,25.79]],"batl":[[0,1.81,162.79]],"ltp":1.81,"tv":25.79,"id":2309796}],"tv":51.88}]}
{"op":"mcm","clk":"1005273667","pt":1580641799698,"mc":[{"id":"1.168219389","rc":[{"batb":[[0,1.56,32.1],[1,1.52,425.49],[2,1.01,10.52]],"ltp":1.81,"tv":25.79,"id":2309796}]}]}
{"op":"mcm","clk":"1005274346","pt":1580641803451,"mc":[{"id":"1.168219389","rc":[{"batb":[[0,1.6,209.96],[1,1.59,137.82],[2,1.56,32.1]],"batl":[[0,1.97,114.5],[1,1.99,131.34]],"ltp":1.81,"tv":25.79,"id":2309796}]}]}
{"op":"mcm","clk":"1005274612","pt":1580641804836,"mc":[{"id":"1.168219389","rc":[{"batb":[[0,1.56,32.1],[1,1.52,425.49],[2,1.01,10.52]],"ltp":1.81,"tv":25.79,"id":2309796}]}]}
{"op":"mcm","clk":"1005275332","pt":1580641808755,"mc":[{"id":"1.168219389","rc":[{"batb":[[1,1.94,15.5],[2,1.82,401.24]],"ltp":2.22,"tv":26.09,"id":8535963},{"batb":[[0,1.89,125.91],[1,1.87,156.24],[2,1.85,18.18]],"ltp":1.81,"tv":25.79,"id":2309796}]}]}
{"op":"mcm","clk":"1005275393","pt":1580641809178,"mc":[{"id":"1.168219389","rc":[{"batb":[[1,2,42.01],[2,1.94,15.5]],"batl":[[0,2.24,33.61]],"ltp":2.22,"tv":26.09,"id":8535963},{"batl":[[1,1.99,173.35]],"ltp":1.81,"tv":25.79,"id":2309796}]}]}
{"op":"mcm","clk":"1005278060","pt":1580641823453,"mc":[{"id":"1.168219389","rc":[{"batb":[[0,2,42.01],[1,1.94,15.5],[2,1.82,401.24]],"ltp":2.22,"tv":26.09,"id":8535963},{"batb":[[0,1.81,51.25],[1,1.68,24.78],[2,1.52,425.49]],"batl":[[0,1.99,42.01],[1,1.99,0]],"ltp":1.81,"tv":25.79,"id":2309796}]}]}
{"op":"mcm","clk":"1005278185","pt":1580641824180,"mc":[{"id":"1.168219389","rc":[{"batb":[[0,1.94,15.5],[1,1.82,401.24],[2,1.01,10.52]],"ltp":2.22,"tv":26.09,"id":8535963},{"batb":[[0,1.68,24.78],[1,1.52,425.49],[2,1.01,10.52]],"ltp":1.81,"tv":25.79,"id":2309796}]}]}
{"op":"mcm","clk":"1005278644","pt":1580641826685,"mc":[{"id":"1.168219389","rc":[{"batb":[[0,1.73,188.95],[1,1.71,210.53],[2,1.68,24.78]],"batl":[[0,2.08,112.11],[1,2.1,112.13]],"ltp":1.81,"tv":25.79,"id":2309796}]}]}
{"op":"mcm","clk":"1005279156","pt":1580641829593,"mc":[{"id":"1.168219389","rc":[{"batb":[[0,1.68,24.78],[1,1.52,425.49],[2,1.01,10.52]],"ltp":1.81,"tv":25.79,"id":2309796}]}]}
{"op":"mcm","clk":"1005279364","pt":1580641830679,"mc":[{"id":"1.168219389","rc":[{"batb":[[1,1.01,10.52],[2,1.01,0]],"ltp":2.22,"tv":26.09,"id":8535963},{"batb":[[1,1.01,10.52],[2,1.01,0]],"ltp":1.81,"tv":25.79,"id":2309796}]}]}
{"op":"mcm","clk":"1005279715","pt":1580641832549,"mc":[{"id":"1.168219389","rc":[{"batb":[[1,1.92,164.36],[2,1.9,148.52]],"batl":[[0,2.02,181.4],[1,2.04,121.91]],"ltp":2.22,"tv":26.09,"id":8535963}]}]}
{"op":"mcm","clk":"1005279820","pt":1580641833130,"mc":[{"id":"1.168219389","rc":[{"batb":[[2,1.91,45.37]],"batl":[[2,2.12,36.97]],"ltp":2.22,"tv":26.09,"id":8535963},{"batb":[[0,1.94,15.66],[1,1.89,47.05],[2,1.82,19.12]],"batl":[[0,2.1,37.81]],"ltp":1.81,"tv":25.79,"id":2309796}]}]}
{"op":"mcm","clk":"1005282777","pt":1580641848674,"mc":[{"id":"1.168219389","rc":[{"batb":[[1,1.91,45.37],[2,1.87,17.47]],"batl":[[0,2.12,36.97],[1,2.04,0],[2,2.12,0]],"ltp":2.22,"tv":26.09,"id":8535963}]}]}
{"op":"mcm","clk":"1005282913","pt":1580641849357,"mc":[{"id":"1.168219389","rc":[{"batb":[[0,1.91,45.37],[1,1.87,17.47],[2,1.67,409.76]],"ltp":2.22,"tv":26.09,"id":8535963},{"batb":[[0,1.89,47.05],[1,1.82,19.12],[2,1.58,416.47]],"ltp":1.81,"tv":25.79,"id":2309796}]}]}
{"op":"mcm","clk":"1005283069","pt":1580641850165,"mc":[{"id":"1.168219389","rc":[{"batb":[[0,1.87,17.47],[1,1.67,409.76],[2,1.01,10.52]],"ltp":2.22,"tv":26.09,"id":8535963},{"batb":[[0,1.82,19.12],[1,1.58,416.47],[2,1.01,10.52]],"ltp":1.81,"tv":25.79,"id":2309796}]}]}
{"op":"mcm","clk":"1005283367","pt":1580641851580,"mc":[{"id":"1.168219389","rc":[{"batb":[[1,1.86,158.79],[2,1.84,164.45]],"batl":[[0,2.14,92.12],[1,2.16,103.5]],"ltp":2.22,"tv":26.09,"id":8535963}]}]}
{"op":"mcm","clk":"1005283595","pt":1580641852758,"mc":[{"id":"1.168219389","rc":[{"batb":[[1,1.67,409.76],[2,1.01,10.52]],"ltp":2.22,"tv":26.09,"id":8535963},{"batb":[[1,1.01,10.52],[2,1.01,0]],"ltp":1.81,"tv":25.79,"id":2309796}]}]}
{"op":"mcm","clk":"1005284137","pt":1580641855721,"mc":[{"id":"1.168219389","rc":[{"batb":[[1,1.86,158.79],[2,1.85,48.73]],"batl":[[0,2.04,40.33]],"ltp":2.22,"tv":26.09,"id":8535963},{"batb":[[0,2,27.7],[1,1.95,43.69],[2,1.93,15.97]],"batl":[[0,2.18,35.29]],"ltp":1.81,"tv":25.79,"id":2309796}]}]}
{"op":"mcm","clk":"1005284627","pt":1580641858477,"mc":[{"id":"1.168219389","rc":[{"batl":[[0,1.95,160.76],[1,1.97,135.11],[2,2.04,40.33]],"ltp":2.22,"tv":26.09,"id":8535963}]}]}
{"op":"mcm","clk":"1005285466","pt":1580641862722,"mc":[{"id":"1.168219389","rc":[{"batb":[[0,1.85,48.73],[1,1.84,106.36],[2,1.83,18.65]],"batl":[[0,2.04,40.33],[1,1.97,0],[2,2.04,0]],"ltp":2.22,"tv":26.09,"id":8535963},{"batb":[[0,1.95,43.69],[1,1.93,15.97],[2,1.62,415.43]],"ltp":1.81,"tv":25.79,"id":2309796}]}]}
{"op":"mcm","clk":"1005285741","pt":1580641864217,"mc":[{"id":"1.168219389","rc":[{"batb":[[0,1.84,106.36],[1,1.83,18.65],[2,1.67,409.76]],"ltp":2.22,"tv":26.09,"id":8535963},{"batb":[[0,1.93,15.97],[1,1.62,415.43],[2,1.01,10.52]],"ltp":1.81,"tv":25.79,"id":2309796}]}]}
{"op":"mcm","clk":"1005285988","pt":1580641865638,"mc":[{"id":"1.168219389","rc":[{"batb":[[2,1.82,170.25]],"batl":[[0,2.02,194.66],[1,2.04,121.89]],"ltp":2.22,"tv":26.09,"id":8535963}]}]}
{"op":"mcm","clk":"1005287909","pt":1580641875747,"mc":[{"id":"1.168219389","rc":[{"trd":[[1.84,45.44]],"batb":[[0,1.83,18.65],[1,1.67,409.76],[2,1.01,10.52]],"ltp":1.84,"tv":71.53,"id":8535963}],"tv":97.32}]}
{"op":"mcm","clk":"1005288596","pt":1580641879458,"mc":[{"id":"1.168219389","rc":[{"batb":[[0,1.83,204.12],[1,1.81,173.51],[2,1.67,409.76]],"ltp":1.84,"tv":71.53,"id":8535963}]}]}
{"op":"mcm","clk":"1005289185","pt":1580641882457,"mc":[{"id":"1.168219389","rc":[{"batb":[[0,1.83,18.65],[1,1.67,409.76],[2,1.01,10.52]],"ltp":1.84,"tv":71.53,"id":8535963}]}]}
{"op":"mcm","clk":"1005289792","pt":1580641885750,"mc":[{"id":"1.168219389","rc":[{"batb":[[0,1.87,175.98],[1,1.85,161.65],[2,1.83,18.65]],"batl":[[0,1.96,148.86],[1,1.98,133.12]],"ltp":1.84,"tv":71.53,"id":8535963}]}]}
{"op":"mcm","clk":"1005291076","pt":1580641892481,"mc":[{"id":"1.168219389","rc":[{"batb":[[0,1.83,18.65],[1,1.67,409.76],[2,1.01,10.52]],"ltp":1.84,"tv":71.53,"id":8535963}]}]}
{"op":"mcm","clk":"1005291637","pt":1580641895460,"mc":[{"id":"1.168219389","rc":[{"batb":[[0,1.83,204.12],[1,1.81,173.51],[2,1.67,409.76]],"batl":[[0,2.02,199.74],[1,2.04,121.9]],"ltp":1.84,"tv":71.53,"id":8535963}]}]}
{"op":"mcm","clk":"1005292577","pt":1580641900657,"mc":[{"id":"1.168219389","rc":[{"batb":[[1,1.01,10.52],[2,1.01,0]],"ltp":1.81,"tv":25.79,"id":2309796}]}]}
{"op":"mcm","clk":"1005292681","pt":1580641901239,"mc":[{"id":"1.168219389","rc":[{"batb":[[2,1.8,52.09]],"batl":[[0,1.91,104.31],[1,1.93,143.8],[2,1.98,42.01]],"ltp":1.84,"tv":71.53,"id":8535963},{"batb":[[0,2,42.01],[1,1.93,15.97],[2,1.01,10.52]],"batl":[[0,2.26,32.77]],"ltp":1.81,"tv":25.79,"id":2309796}]}]}
{"op":"mcm","clk":"1005292889","pt":1580641902363,"mc":[{"id":"1.168219389","rc":[{"batb":[[0,2.06,25.89],[1,2,42.01],[2,1.94,15.66]],"ltp":1.81,"tv":25.79,"id":2309796}]}]}
{"op":"mcm","clk":"1005293469","pt":1580641905272,"mc":[{"id":"1.168219389","rc":[{"batb":[[0,1.83,18.65],[1,1.8,52.09],[2,1.67,409.76]],"batl":[[0,1.98,42.01],[1,1.93,0],[2,1.98,0]],"ltp":1.84,"tv":71.53,"id":8535963}]}]}
{"op":"mcm","clk":"1005294093","pt":1580641908286,"mc":[{"id":"1.168219389","rc":[{"batb":[[0,1.84,154.57],[1,1.83,18.65],[2,1.82,170.28]],"batl":[[0,1.92,124.98],[1,1.94,141.46],[2,1.98,42.01]],"ltp":1.84,"tv":71.53,"id":8535963}]}]}
{"op":"mcm","clk":"1005294469","pt":1580641909980,"mc":[{"id":"1.168219389","rc":[{"batb":[[1,1.83,18.49]],"ltp":1.84,"tv":71.53,"id":8535963},{"batb":[[2,1.93,15.82]],"ltp":1.81,"tv":25.79,"id":2309796}]}]}
{"op":"mcm","clk":"1005295486","pt":1580641915193,"mc":[{"id":"1.168219389","rc":[{"batb":[[0,1.83,18.49],[1,1.8,52.09],[2,1.67,409.76]],"batl":[[0,1.98,42.01],[1,1.94,0],[2,1.98,0]],"ltp":1.84,"tv":71.53,"id":8535963}]}]}
{"op":"mcm","clk":"1005296167","pt":1580641918692,"mc":[{"id":"1.168219389","rc":[{"batb":[[0,1.85,120.7],[1,1.84,18.33],[2,1.83,167.15]],"batl":[[0,1.93,148.8],[1,1.95,139.18],[2,1.98,42.01]],"ltp":1.84,"tv":71.53,"id":8535963},{"batb":[[0,2.04,26.36]],"ltp":1.81,"tv":25.79,"id":2309796}]}]}
{"op":"mcm","clk":"1005296871","pt":1580641922683,"mc":[{"id":"1.168219389","rc":[{"batl":[[0,1.93,103.36]],"ltp":1.84,"tv":71.53,"id":8535963}]}]}
{"op":"mcm","clk":"1005297412","pt":1580641925646,"mc":[{"id":"1.168219389","rc":[{"batb":[[0,1.85,168.12]],"ltp":1.84,"tv":71.53,"id":8535963}]}]}
{"op":"mcm","clk":"1005297579","pt":1580641926553,"mc":[{"id":"1.168219389","rc":[{"batb":[[1,1.84,18.18]],"ltp":1.84,"tv":71.53,"id":8535963},{"batb":[[2,1.92,16.13]],"ltp":1.81,"tv":25.79,"id":2309796}]}]}
{"op":"mcm","clk":"1005301634","pt":1580641950691,"mc":[{"id":"1.168219389","rc":[{"batb":[[0,1.85,186.14]],"ltp":1.84,"tv":71.53,"id":8535963}]}]}
{"op":"mcm","clk":"1005301768","pt":1580641951694,"mc":[{"id":"1.168219389","rc":[{"batb":[[1,1.83,167.15],[2,1.8,52.09]],"ltp":1.84,"tv":71.53,"id":8535963},{"batb":[[2,1.91,16.21]],"ltp":1.81,"tv":25.79,"id":2309796}]}]}
{"op":"mcm","clk":"1005306226","pt":1580641977508,"mc":[{"id":"1.168219389","rc":[{"trd":[[1.93,27.82]],"batl":[[0,1.98,42.01],[1,1.95,0],[2,1.98,0]],"ltp":1.93,"tv":99.35,"id":8535963},{"trd":[[2.06,26.06]],"ltp":2.06,"tv":51.84,"id":2309796}],"tv":151.2}]}
{"op":"mcm","clk":"1005306703","pt":1580641980440,"mc":[{"id":"1.168219389","rc":[{"batl":[[0,1.94,163.63],[1,1.96,136.97],[2,1.98,42.01]],"ltp":1.93,"tv":99.35,"id":8535963}]}]}
{"op":"mcm","clk":"1005307541","pt":1580641985450,"mc":[{"id":"1.168219389","rc":[{"batb":[[0,1.8,52.09],[1,1.67,409.76],[2,1.65,26.59]],"batl":[[0,1.98,42.01],[1,1.96,0],[2,1.98,0]],"ltp":1.93,"tv":99.35,"id":8535963},{"batb":[[0,2,42.01],[1,1.91,16.21],[2,1.67,409.76]],"ltp":2.06,"tv":51.84,"id":2309796}]}]}
{"op":"mcm","clk":"1005307693","pt":1580641986254,"mc":[{"id":"1.168219389","rc":[{"batb":[[0,1.67,409.76],[1,1.65,26.59],[2,1.01,10.52]],"ltp":1.93,"tv":99.35,"id":8535963},{"batb":[[0,1.91,16.21],[1,1.67,409.76],[2,1.01,10.52]],"ltp":2.06,"tv":51.84,"id":2309796}]}]}
{"op":"mcm","clk":"1005308077","pt":1580641988546,"mc":[{"id":"1.168219389","rc":[{"batb":[[1,1.66,166.54],[2,1.65,145.92]],"batl":[[0,2.08,187.68],[1,2.1,112]],"ltp":1.93,"tv":99.35,"id":8535963}]}]}
{"op":"mcm","clk":"1005309223","pt":1580641994562,"mc":[{"id":"1.168219389","rc":[{"batb":[[0,1.66,166.54],[1,1.65,145.92],[2,1.01,10.52]],"ltp":1.93,"tv":99.35,"id":8535963},{"batb":[[1,1.01,10.52],[2,1.01,0]],"ltp":2.06,"tv":51.84,"id":2309796}]}]}
{"op":"mcm","clk":"1005309420","pt":1580641995646,"mc":[{"id":"1.168219389","rc":[{"batl":[[0,1.72,112.89],[1,1.74,199.02]],"ltp":1.93,"tv":99.35,"id":8535963}]}]}
{"op":"mcm","clk":"1005309568","pt":1580641996436,"mc":[{"id":"1.168219389","rc":[{"batb":[[2,1.43,45.72]],"ltp":1.93,"tv":99.35,"id":8535963},{"batb":[[0,2.36,17.62],[1,2.12,23.92],[2,1.01,10.52]],"ltp":2.06,"tv":51.84,"id":2309796}]}]}
{"op":"mcm","clk":"1005309776","pt":1580641997641,"mc":[{"id":"1.168219389","rc":[{"batb":[[2,1.64,65.54]],"batl":[[2,1.79,42.01]],"ltp":1.93,"tv":99.35,"id":8535963},{"batl":[[0,2.58,26.05]],"ltp":2.06,"tv":51.84,"id":2309796}]}]}
{"op":"mcm","clk":"1005309946","pt":1580641998745,"mc":[{"id":"1.168219389","rc":[{"batb":[[1,2.28,32.77],[2,2.12,23.92]],"ltp":2.06,"tv":51.84,"id":2309796}]}]}
{"op":"mcm","clk":"1005310740","pt":1580642003352,"mc":[{"id":"1.168219389","rc":[{"batl":[[0,1.79,42.01],[1,1.74,0],[2,1.79,0]],"ltp":1.93,"tv":99.35,"id":8535963}]}]}
{"op":"mcm","clk":"1005311335","pt":1580642006742,"mc":[{"id":"1.168219389","rc":[{"batb":[[0,1.64,65.54],[1,1.44,436.19],[2,1.43,45.71]],"ltp":1.93,"tv":99.35,"id":8535963},{"batb":[[0,2.28,32.77],[1,2.12,23.92],[2,1.86,398.62]],"ltp":2.06,"tv":51.84,"id":2309796}]}]}
{"op":"mcm","clk":"1005311687","pt":1580642008636,"mc":[{"id":"1.168219389","rc":[{"batb":[[0,1.44,436.19],[1,1.43,45.71],[2,1.01,10.51]],"ltp":1.93,"tv":99.35,"id":8535963},{"batb":[[0,2.12,23.92],[1,1.86,398.62],[2,1.01,10.52]],"ltp":2.06,"tv":51.84,"id":2309796}]}]}
{"op":"mcm","clk":"1005311803","pt":1580642009427,"mc":[{"id":"1.168219389","rc":[{"batb":[[0,1.45,170.87],[1,1.44,638.43],[2,1.43,45.71]],"batl":[[0,1.89,156.2],[1,1.91,147.95]],"ltp":1.93,"tv":99.35,"id":8535963}]}]}
{"op":"mcm","clk":"1005311930","pt":1580642010175,"mc":[{"id":"1.168219389","rc":[{"batb":[[0,2.1,24.16]],"ltp":2.06,"tv":51.84,"id":2309796}]}]}
{"op":"mcm","clk":"1005313570","pt":1580642020155,"mc":[{"id":"1.168219389","rc":[{"batb":[[1,1.44,202.25]],"batl":[[0,1.49,129.98],[1,1.5,167.88]],"ltp":1.93,"tv":99.35,"id":8535963},{"batb":[[1,1.01,10.52],[2,1.01,0]],"ltp":2.06,"tv":51.84,"id":2309796}]}]}
{"op":"mcm","clk":"1005313826","pt":1580642021592,"mc":[{"id":"1.168219389","rc":[{"batb":[[1,1.44,297.19]],"batl":[[2,1.55,42.01]],"ltp":1.93,"tv":99.35,"id":8535963},{"batb":[[0,3,23.29],[1,2.56,14.16],[2,1.01,10.52]],"batl":[[0,3.25,18.48]],"ltp":2.06,"tv":51.84,"id":2309796}]}]}
{"op":"mcm","clk":"1005314184","pt":1580642023657,"mc":[{"id":"1.168219389","rc":[{"batb":[[1,2.82,22.69],[2,2.56,14.16]],"ltp":2.06,"tv":51.84,"id":2309796}]}]}
{"op":"mcm","clk":"1005315932","pt":1580642033621,"mc":[{"id":"1.168219389","rc":[{"batb":[[0,1.44,94.95],[1,1.28,485.89],[2,1.24,93.24]],"batl":[[0,1.55,42.01],[1,1.5,0],[2,1.55,0]],"ltp":1.93,"tv":99.35,"id":8535963},{"batb":[[0,2.82,22.69],[1,2.56,14.16],[2,2.22,384.52]],"ltp":2.06,"tv":51.84,"id":2309796}]}]}
{"op":"mcm","clk":"1005316054","pt":1580642034318,"mc":[{"id":"1.168219389","rc":[{"batb":[[0,1.28,485.9],[1,1.24,93.24],[2,1.01,10.51]],"ltp":1.93,"tv":99.35,"id":8535963},{"batb":[[0,2.56,14.16],[1,2.22,384.52],[2,1.01,10.52]],"ltp":2.06,"tv":51.84,"id":2309796}]}]}
{"op":"mcm","clk":"1005316431","pt":1580642036627,"mc":[{"id":"1.168219389","rc":[{"batb":[[1,1.26,171.27],[2,1.25,411.1]],"batl":[[0,1.64,168.72],[1,1.65,118.04]],"ltp":1.93,"tv":99.35,"id":8535963}]}]}
{"op":"mcm","clk":"1005316790","pt":1580642038513,"mc":[{"id":"1.168219389","rc":[{"batb":[[1,1.24,93.24],[2,1.01,10.51]],"ltp":1.93,"tv":99.35,"id":8535963}]}]}
{"op":"mcm","clk":"1005316863","pt":1580642038931,"mc":[{"id":"1.168219389","rc":[{"batb":[[0,1.24,93.25],[1,1.01,10.51],[2,1.01,0]],"ltp":1.93,"tv":99.35,"id":8535963},{"batb":[[1,1.01,10.52],[2,1.01,0]],"ltp":2.06,"tv":51.84,"id":2309796}]}]}
{"op":"mcm","clk":"1005317210","pt":1580642040725,"mc":[{"id":"1.168219389","rc":[{"batb":[[0,1.58,213.13],[1,1.57,143.2],[2,1.24,93.25]],"ltp":1.93,"tv":99.35,"id":8535963}]}]}
{"op":"mcm","clk":"1005317445","pt":1580642041687,"mc":[{"id":"1.168219389","rc":[{"batb":[[2,1.56,32.18]],"batl":[[2,1.68,42.01]],"ltp":1.93,"tv":99.35,"id":8535963},{"batb":[[1,2.46,28.57],[2,2.2,21.48]],"batl":[[0,2.8,22.69]],"ltp":2.06,"tv":51.84,"id":2309796}]}]}
{"op":"mcm","clk":"1005319390","pt":1580642051757,"mc":[{"id":"1.168219389","rc":[{"batb":[[0,1.55,75.62],[1,1.38,448.46],[2,1.31,67.59]],"batl":[[0,1.68,42.01],[1,1.65,0],[2,1.68,0]],"ltp":1.93,"tv":99.35,"id":8535963},{"batb":[[0,2.46,28.57],[1,2.2,21.48],[2,1.97,394.86]],"ltp":2.06,"tv":51.84,"id":2309796}]}]}
{"op":"mcm","clk":"1005319585","pt":1580642052735,"mc":[{"id":"1.168219389","rc":[{"batb":[[0,1.38,448.46],[1,1.31,67.59],[2,1.01,10.51]],"ltp":1.93,"tv":99.35,"id":8535963},{"batb":[[0,2.2,21.48],[1,1.97,394.86],[2,1.01,10.52]],"ltp":2.06,"tv":51.84,"id":2309796}]}]}
{"op":"mcm","clk":"1005320332","pt":1580642057002,"mc":[{"id":"1.168219389","rc":[{"batb":[[0,1.52,284.8],[1,1.51,167.02],[2,1.38,448.46]],"batl":[[0,1.58,200.79],[1,1.59,134.43]],"ltp":1.93,"tv":99.35,"id":8535963}]}]}
{"op":"mcm","clk":"1005321016","pt":1580642060734,"mc":[{"id":"1.168219389","rc":[{"batb":[[0,1.38,448.46],[1,1.31,67.59],[2,1.01,10.51]],"ltp":1.93,"tv":99.35,"id":8535963}]}]}
{"op":"mcm","clk":"1005321502","pt":1580642063426,"mc":[{"id":"1.168219389","rc":[{"batb":[[1,1.33,376.42],[2,1.32,307.1]],"batl":[[0,1.84,185.89],[1,1.86,160.43]],"ltp":1.93,"tv":99.35,"id":8535963}]}]}
{"op":"mcm","clk":"1005324171","pt":1580642078347,"mc":[{"id":"1.168219389","rc":[{"batb":[[0,1.33,376.43],[1,1.32,307.1],[2,1.31,67.59]],"ltp":1.93,"tv":99.35,"id":8535963},{"batb":[[1,1.01,10.52],[2,1.01,0]],"ltp":2.06,"tv":51.84,"id":2309796}]}]}
{"op":"mcm","clk":"1005324419","pt":1580642079764,"mc":[{"id":"1.168219389","rc":[{"trd":[[1.48,0.02]],"batb":[[0,1.33,376.42]],"batl":[[0,1.37,228.27],[1,1.38,237.39]],"ltp":1.48,"tv":99.37,"id":8535963}],"tv":151.22}]}
{"op":"mcm","clk":"1005324592","pt":1580642080650,"mc":[{"id":"1.168219389","rc":[{"batb":[[0,3.7,13.85],[1,2.92,24.78],[2,1.01,10.52]],"ltp":2.06,"tv":51.84,"id":2309796}]}]}
{"op":"mcm","clk":"1005324788","pt":1580642081756,"mc":[{"id":"1.168219389","rc":[{"batb":[[0,1.33,503.29]],"ltp":1.48,"tv":99.37,"id":8535963},{"batl":[[0,4,13.44]],"ltp":2.06,"tv":51.84,"id":2309796}]}]}
{"op":"mcm","clk":"1005324876","pt":1580642082233,"mc":[{"id":"1.168219389","rc":[{"batb":[[2,2.42,381.73]],"ltp":2.06,"tv":51.84,"id":2309796}]}]}
{"op":"mcm","clk":"1005325039","pt":1580642083347,"mc":[{"id":"1.168219389","rc":[{"batl":[[2,1.41,42.01]],"ltp":1.48,"tv":99.37,"id":8535963},{"batb":[[1,3.4,16.8],[2,2.92,24.78]],"ltp":2.06,"tv":51.84,"id":2309796}]}]}
{"op":"mcm","clk":"1005328463","pt":1580642102331,"mc":[{"id":"1.168219389","rc":[{"batb":[[0,1.33,441.06]],"ltp":1.48,"tv":99.37,"id":8535963}]}]}
{"op":"mcm","clk":"1005328725","pt":1580642103731,"mc":[{"id":"1.168219389","rc":[{"batb":[[0,1.33,126.87],[1,1.31,67.59],[2,1.22,523]],"batl":[[0,1.41,42.01],[1,1.38,0],[2,1.41,0]],"ltp":1.48,"tv":99.37,"id":8535963}]}]}
{"op":"mcm","clk":"1005328902","pt":1580642104712,"mc":[{"id":"1.168219389","rc":[{"batb":[[0,1.22,523],[1,1.13,187.97],[2,1.01,10.51]],"ltp":1.48,"tv":99.37,"id":8535963},{"batb":[[0,2.92,24.78],[1,2.42,381.73],[2,1.01,10.52]],"ltp":2.06,"tv":51.84,"id":2309796}]}]}
{"op":"mcm","clk":"1005329049","pt":1580642105529,"mc":[{"id":"1.168219389","rc":[{"batb":[[0,1.13,187.97],[1,1.01,10.51],[2,1.01,0]],"ltp":1.48,"tv":99.37,"id":8535963},{"batb":[[1,1.01,10.52],[2,1.01,0]],"ltp":2.06,"tv":51.84,"id":2309796}]}]}
{"op":"mcm","clk":"1005329808","pt":1580642109733,"mc":[{"id":"1.168219389","rc":[{"batb":[[0,1.29,247.14],[1,1.28,361.2],[2,1.13,187.97]],"batl":[[0,1.32,220.89],[1,1.33,284.08]],"ltp":1.48,"tv":99.37,"id":8535963}]}]}
{"op":"mcm","clk":"1005330122","pt":1580642111521,"mc":[{"id":"1.168219389","rc":[{"batb":[[2,1.2,530.86]],"ltp":1.48,"tv":99.37,"id":8535963},{"batb":[[1,2.52,381.46],[2,1.01,10.52]],"ltp":2.06,"tv":51.84,"id":2309796}]}]}
{"op":"mcm","clk":"1005331077","pt":1580642116653,"mc":[{"id":"1.168219389","rc":[{"batb":[[0,1.2,530.86],[1,1.13,187.97],[2,1.01,10.51]],"ltp":1.48,"tv":99.37,"id":8535963}]}]}
{"op":"mcm","clk":"1005331617","pt":1580642119668,"mc":[{"id":"1.168219389","rc":[{"batb":[[1,1.14,606.18],[2,1.13,708.97]],"batl":[[0,1.52,240.25],[1,1.53,155.3]],"ltp":1.48,"tv":99.37,"id":8535963}]}]}
{"op":"mcm","clk":"1005331812","pt":1580642120638,"mc":[{"id":"1.168219389","rc":[{"batb":[[0,1.14,606.18],[1,1.13,708.97],[2,1.01,10.51]],"ltp":1.48,"tv":99.37,"id":8535963},{"batb":[[1,1.01,10.52],[2,1.01,0]],"ltp":2.06,"tv":51.84,"id":2309796}]}]}
{"op":"mcm","clk":"1005334459","pt":1580642135684,"mc":[{"id":"1.168219389","rc":[{"batl":[[0,1.16,316.74],[1,1.17,617.87]],"ltp":1.48,"tv":99.37,"id":8535963}]}]}
{"op":"mcm","clk":"1005334575","pt":1580642136281,"mc":[{"id":"1.168219389","rc":[{"batb":[[2,1.08,275.62]],"ltp":1.48,"tv":99.37,"id":8535963},{"batb":[[0,7,12.12],[1,4.9,13.93],[2,1.01,10.52]],"ltp":2.06,"tv":51.84,"id":2309796}]}]}
{"op":"mcm","clk":"1005334767","pt":1580642137245,"mc":[{"id":"1.168219389","rc":[{"batl":[[2,1.18,42.01]],"ltp":1.48,"tv":99.37,"id":8535963},{"batb":[[1,6.6,6.72],[2,4.9,13.93]],"batl":[[0,8.4,5.04]],"ltp":2.06,"tv":51.84,"id":2309796}]}]}
{"op":"mcm","clk":"1005334874","pt":1580642137976,"mc":[{"id":"1.168219389","rc":[{"batb":[[2,1.09,779.05]],"ltp":1.48,"tv":99.37,"id":8535963}]}]}
{"op":"mcm","clk":"1005337748","pt":1580642154382,"mc":[{"id":"1.168219389","rc":[{"trd":[[1.14,52.73]],"batb":[[0,1.14,579.81]],"ltp":1.14,"tv":152.1,"id":8535963}],"tv":203.95}]}
{"op":"mcm","clk":"1005341000","pt":1580642172713,"mc":[{"id":"1.168219389","rc":[{"batb":[[0,1.13,187.97],[1,1.09,779.05],[2,1.08,275.62]],"batl":[[0,1.18,42.01],[1,1.17,0],[2,1.18,0]],"ltp":1.14,"tv":152.1,"id":8535963}]}]}
{"op":"mcm","clk":"1005341057","pt":1580642172983,"mc":[{"id":"1.168219389","rc":[{"batb":[[0,1.09,779.05],[1,1.08,275.62],[2,1.01,10.51]],"ltp":1.14,"tv":152.1,"id":8535963},{"batb":[[0,6.6,6.72],[1,4.9,13.93],[2,3.15,373.59]],"ltp":2.06,"tv":51.84,"id":2309796}]}]}
{"op":"mcm","clk":"1005341309","pt":1580642174415,"mc":[{"id":"1.168219389","rc":[{"batb":[[0,4.9,13.93],[1,3.15,373.59],[2,1.01,10.52]],"ltp":2.06,"tv":51.84,"id":2309796}]}]}
{"op":"mcm","clk":"1005341488","pt":1580642175312,"mc":[{"id":"1.168219389","rc":[{"batb":[[0,1.1,913.69],[1,1.09,1040.86],[2,1.08,275.62]],"batl":[[0,1.25,296.48],[1,1.26,378.82]],"ltp":1.14,"tv":152.1,"id":8535963}]}]}
{"op":"mcm","clk":"1005341725","pt":1580642176312,"mc":[{"id":"1.168219389","rc":[{"batb":[[0,1.09,779.05],[1,1.08,275.62],[2,1.01,10.51]],"batl":[[0,1.14,88],[1,1.26,6.67]],"ltp":1.14,"tv":152.1,"id":8535963}]}]}
{"op":"mcm","clk":"1005341900","pt":1580642177114,"mc":[{"id":"1.168219389","rc":[{"batl":[[1,1.26,0]],"ltp":1.14,"tv":152.1,"id":8535963}]}]}
{"op":"mcm","clk":"1005342345","pt":1580642179512,"mc":[{"id":"1.168219389","rc":[{"batb":[[0,1.16,223.31],[1,1.15,754.35],[2,1.09,779.05]],"batl":[[0,1.18,489.85],[1,1.19,538.34]],"ltp":1.14,"tv":152.1,"id":8535963}]}]}
{"op":"mcm","clk":"1005343183","pt":1580642183754,"mc":[{"id":"1.168219389","rc":[{"batb":[[0,1.09,779.05],[1,1.08,275.62],[2,1.01,10.51]],"ltp":1.14,"tv":152.1,"id":8535963}]}]}
{"op":"mcm","clk":"1005343771","pt":1580642186714,"mc":[{"id":"1.168219389","rc":[{"batb":[[0,1.1,913.69],[1,1.09,1040.86],[2,1.08,275.62]],"batl":[[0,1.25,296.48],[1,1.26,378.82]],"ltp":1.14,"tv":152.1,"id":8535963}]}]}
{"op":"mcm","clk":"1005345243","pt":1580642194747,"mc":[{"id":"1.168219389","rc":[{"trd":[[1.1,73.94]],"batb":[[0,1.1,876.72],[1,1.09,261.81]],"ltp":1.1,"tv":226.04,"id":8535963},{"batb":[[1,1.01,10.52],[2,1.01,0]],"ltp":2.06,"tv":51.84,"id":2309796}],"tv":277.89}]}
{"op":"mcm","clk":"1005345635","pt":1580642196739,"mc":[{"id":"1.168219389","rc":[{"batl":[[0,1.12,608.25],[1,1.13,539.11]],"ltp":1.1,"tv":226.04,"id":8535963},{"batb":[[0,9.2,16.52],[1,6.4,15.03],[2,4.9,13.93]],"ltp":2.06,"tv":51.84,"id":2309796}]}]}
{"op":"mcm","clk":"1005345761","pt":1580642197454,"mc":[{"id":"1.168219389","rc":[{"batb":[[0,1.1,1044.76]],"ltp":1.1,"tv":226.04,"id":8535963},{"batb":[[1,8.4,5.04],[2,6.4,15.03]],"batl":[[0,11,4.2]],"ltp":2.06,"tv":51.84,"id":2309796}]}]}
{"op":"mcm","clk":"1005347153","pt":1580642205417,"mc":[{"id":"1.168219389","rc":[{"batl":[[1,1.13,486.15]],"ltp":1.1,"tv":226.04,"id":8535963}]}]}
{"op":"mcm","clk":"1005347761","pt":1580642208591,"mc":[{"id":"1.168219389","rc":[{"trd":[[1.1,249.94]],"batb":[[0,1.1,956.76],[1,1.09,316.57]],"batl":[[0,1.12,661.68],[1,1.13,454.71]],"ltp":1.1,"tv":402.04,"id":8535963}],"tv":453.89}]}
{"op":"mcm","clk":"1005348088","pt":1580642210398,"mc":[{"id":"1.168219389","rc":[{"batb":[[0,1.06,1349.26],[1,1.01,10.51],[2,1.08,0]],"ltp":1.1,"tv":402.04,"id":8535963},{"batb":[[0,6.4,14.71],[1,3.5,371.08],[2,1.01,10.52]],"ltp":2.06,"tv":51.84,"id":2309796}]}]}
{"op":"mcm","clk":"1005348291","pt":1580642211565,"mc":[{"id":"1.168219389","rc":[{"batb":[[0,1.1,38.47],[1,1.09,32.53],[2,1.06,1349.26]],"batl":[[0,1.12,31.73]],"ltp":1.1,"tv":402.04,"id":8535963}]}]}
{"op":"mcm","clk":"1005348428","pt":1580642212355,"mc":[{"id":"1.168219389","rc":[{"batb":[[0,1.06,1349.26],[1,1.01,10.51],[2,1.06,0]],"ltp":1.1,"tv":402.04,"id":8535963}]}]}
{"op":"mcm","clk":"1005348634","pt":1580642213683,"mc":[{"id":"1.168219389","rc":[{"batb":[[0,1.07,1206.01],[1,1.06,1349.26],[2,1.01,10.51]],"batl":[[0,1.18,504.08],[1,1.19,541.09]],"ltp":1.1,"tv":402.04,"id":8535963}]}]}
{"op":"mcm","clk":"1005352035","pt":1580642232520,"mc":[{"id":"1.168219389","rc":[{"batl":[[0,1.14,1512.35],[1,1.18,504.08],[2,1.19,541.09]],"ltp":1.1,"tv":402.04,"id":8535963}]}]}
{"op":"mcm","clk":"1005355007","pt":1580642248740,"mc":[{"id":"1.168219389","rc":[{"batb":[[0,1.06,1349.26],[1,1.01,10.51],[2,1.01,0]],"ltp":1.1,"tv":402.04,"id":8535963}]}]}
{"op":"mcm","clk":"1005355333","pt":1580642250544,"mc":[{"id":"1.168219389","rc":[{"batl":[[0,1.07,364],[1,1.14,1512.35],[2,1.18,504.08]],"ltp":1.1,"tv":402.04,"id":8535963}]}]}
{"op":"mcm","clk":"1005355544","pt":1580642251652,"mc":[{"id":"1.168219389","rc":[{"trd":[[1.07,728],[1.14,1271.67]],"batb":[[0,1.06,393.65]],"batl":[[0,1.14,902.88],[1,1.18,504.08],[2,1.19,541.09]],"ltp":1.14,"tv":2348.98,"id":8535963}],"tv":2400.83}]}
{"op":"mcm","clk":"1005355730","pt":1580642252684,"mc":[{"id":"1.168219389","rc":[{"trd":[[1.14,1605.74]],"batb":[[0,1.09,264.06]],"batl":[[0,1.14,735.85],[2,1.19,0]],"ltp":1.14,"tv":2683.05,"id":8535963},{"batb":[[1,4.3,19.2],[2,3.5,371.08]],"ltp":2.06,"tv":51.84,"id":2309796}],"tv":2734.9}]}
{"op":"mcm","clk":"1005355860","pt":1580642253423,"mc":[{"id":"1.168219389","rc":[{"trd":[[1.14,2025.84]],"batl":[[0,1.14,525.8],[1,1.18,546.09]],"ltp":1.14,"tv":3103.15,"id":8535963},{"batb":[[0,6.6,6.72],[1,6.4,14.71],[2,4.3,19.2]],"ltp":2.06,"tv":51.84,"id":2309796}],"tv":3155.0}]}
{"op":"mcm","clk":"1005356220","pt":1580642255338,"mc":[{"id":"1.168219389","rc":[{"trd":[[1.14,3077.44]],"batb":[[0,1.15,104.91],[1,1.14,495.72],[2,1.09,1043.11]],"batl":[[0,1.17,244.01],[1,1.18,642.47]],"ltp":1.14,"tv":4154.75,"id":8535963}],"tv":4206.6}]}
{"op":"mcm","clk":"1005356430","pt":1580642256553,"mc":[{"id":"1.168219389","rc":[{"batl":[[0,8,37.86]],"ltp":2.06,"tv":51.84,"id":2309796}]}]}
{"op":"mcm","clk":"1005356784","pt":1580642258536,"mc":[{"id":"1.168219389","rc":[{"batb":[[0,1.15,439.85],[1,1.14,856.29]],"batl":[[0,1.17,431.94]],"ltp":1.14,"tv":4154.75,"id":8535963},{"batl":[[0,8,5.88]],"ltp":2.06,"tv":51.84,"id":2309796}]}]}
{"op":"mcm","clk":"1005359691","pt":1580642273494,"mc":[{"id":"1.168219389","rc":[{"batb":[[0,1.15,371.97]],"ltp":1.14,"tv":4154.75,"id":8535963}]}]}
{"op":"mcm","clk":"1005360022","pt":1580642275306,"mc":[{"id":"1.168219389","rc":[{"batb":[[0,1.14,168.04],[1,1.09,1043.11],[2,1.01,10.51]],"batl":[[0,1.18,42.01],[1,1.18,0]],"ltp":1.14,"tv":4154.75,"id":8535963},{"batb":[[1,4.3,19.2],[2,3.5,371.08]],"ltp":2.06,"tv":51.84,"id":2309796}]}]}
{"op":"mcm","clk":"1005360263","pt":1580642276530,"mc":[{"id":"1.168219389","rc":[{"batb":[[0,1.09,1043.11],[1,1.01,10.51],[2,1.01,0]],"ltp":1.14,"tv":4154.75,"id":8535963},{"batb":[[0,4.3,19.2],[1,3.5,371.08],[2,1.01,10.52]],"ltp":2.06,"tv":51.84,"id":2309796}]}]}
{"op":"mcm","clk":"1005360647","pt":1580642278435,"mc":[{"id":"1.168219389","rc":[{"batb":[[0,1.1,630.21],[1,1.09,1326.94],[2,1.08,286.4]],"batl":[[0,1.28,237.67],[1,1.29,348.42]],"ltp":1.14,"tv":4154.75,"id":8535963},{"batb":[[0,4.6,16.92]],"ltp":2.06,"tv":51.84,"id":2309796}]}]}
{"op":"mcm","clk":"1005361000","pt":1580642280346,"mc":[{"id":"1.168219389","rc":[{"batb":[[0,1.09,779.05],[1,1.08,286.4],[2,1.01,10.51]],"ltp":1.14,"tv":4154.75,"id":8535963}]}]}
{"op":"mcm","clk":"1005361176","pt":1580642281093,"mc":[{"id":"1.168219389","rc":[{"batb":[[0,1.08,286.4],[1,1.01,10.51],[2,1.01,0]],"ltp":1.14,"tv":4154.75,"id":8535963},{"batb":[[1,1.01,10.52],[2,1.01,0]],"ltp":2.06,"tv":51.84,"id":2309796}]}]}
{"op":"mcm","clk":"1005361649","pt":1580642283756,"mc":[{"id":"1.168219389","rc":[{"batb":[[0,1.25,451.83],[1,1.24,460.44],[2,1.23,96.31]],"batl":[[1,1.29,390.43]],"ltp":1.14,"tv":4154.75,"id":8535963},{"batb":[[1,4.5,11.76],[2,3.05,23.13]],"ltp":2.06,"tv":51.84,"id":2309796}]}]}
{"op":"mcm","clk":"1005361749","pt":1580642284242,"mc":[{"id":"1.168219389","rc":[{"batl":[[0,5.2,9.24]],"ltp":2.06,"tv":51.84,"id":2309796}]}]}
{"op":"mcm","clk":"1005365739","pt":1580642304526,"mc":[{"id":"1.168219389","rc":[{"batb":[[0,1.18,549.72],[1,1.15,157.21],[2,1.01,10.51]],"ltp":1.14,"tv":4154.75,"id":8535963},{"batb":[[0,3.05,23.13],[1,2.62,379.26],[2,1.01,10.52]],"ltp":2.06,"tv":51.84,"id":2309796}]}]}
{"op":"mcm","clk":"1005366339","pt":1580642307713,"mc":[{"id":"1.168219389","rc":[{"batb":[[1,1.16,859.35],[2,1.15,412.5]],"batl":[[0,1.5,272.72],[1,1.51,170.26]],"ltp":1.14,"tv":4154.75,"id":8535963}]}]}
{"op":"mcm","clk":"1005366436","pt":1580642308358,"mc":[{"id":"1.168219389","rc":[{"batb":[[0,1.28,26.52],[1,1.18,549.72],[2,1.16,859.35]],"ltp":1.14,"tv":4154.75,"id":8535963}]}]}
{"op":"mcm","clk":"1005367275","pt":1580642313086,"mc":[{"id":"1.168219389","rc":[{"trd":[[1.28,7.07]],"batb":[[0,1.28,22.98]],"ltp":1.28,"tv":4161.83,"id":8535963}],"tv":4213.68}]}
{"op":"mcm","clk":"1005368947","pt":1580642321680,"mc":[{"id":"1.168219389","rc":[{"batb":[[1,1.16,859.35],[2,1.15,412.5]],"ltp":1.28,"tv":4161.83,"id":8535963},{"batb":[[1,1.01,10.52],[2,1.01,0]],"ltp":2.06,"tv":51.84,"id":2309796}]}]}
{"op":"mcm","clk":"1005369277","pt":1580642323505,"mc":[{"id":"1.168219389","rc":[{"trd":[[1.28,53.04]],"batb":[[0,1.16,1027.39],[1,1.15,412.5],[2,1.08,296.16]],"batl":[[0,1.19,532.75],[1,1.2,524.26],[2,1.28,22.69]],"ltp":1.28,"tv":4207.79,"id":8535963},{"batb":[[0,6.4,16.13],[1,3.85,13.22],[2,3.05,23.13]],"batl":[[0,7.4,5.88]],"ltp":2.06,"tv":51.84,"id":2309796}],"tv":4259.64}]}
{"op":"mcm","clk":"1005369333","pt":1580642323814,"mc":[{"id":"1.168219389","rc":[{"batl":[[2,1.28,0]],"ltp":1.28,"tv":4207.79,"id":8535963},{"batb":[[2,1.01,10.52]],"ltp":2.06,"tv":51.84,"id":2309796}]}]}
{"op":"mcm","clk":"1005369694","pt":1580642325712,"mc":[{"id":"1.168219389","rc":[{"batb":[[2,1.11,684.32]],"batl":[[1,1.2,544.71]],"ltp":1.28,"tv":4207.79,"id":8535963},{"batb":[[2,3,380.84]],"ltp":2.06,"tv":51.84,"id":2309796}]}]}
{"op":"mcm","clk":"1005369811","pt":1580642326308,"mc":[{"id":"1.168219389","rc":[{"batl":[[1,1.2,566.27]],"ltp":1.28,"tv":4207.79,"id":8535963},{"batb":[[1,6,8.4],[2,3.85,13.22]],"ltp":2.06,"tv":51.84,"id":2309796}]}]}
{"op":"mcm","clk":"1005370009","pt":1580642327439,"mc":[{"id":"1.168219389","rc":[{"batb":[[0,1.16,896.38],[1,1.15,157.21]],"ltp":1.28,"tv":4207.79,"id":8535963}]}]}
{"op":"mcm","clk":"1005370632","pt":1580642330386,"mc":[{"id":"1.168219389","rc":[{"batb":[[0,1.17,175.13],[1,1.16,896.38],[2,1.15,157.21]],"ltp":1.28,"tv":4207.79,"id":8535963}]}]}
{"op":"mcm","clk":"1005372257","pt":1580642338466,"mc":[{"id":"1.168219389","rc":[{"batb":[[2,1.15,1467.04]],"ltp":1.28,"tv":4207.79,"id":8535963}]}]}
{"op":"mcm","clk":"1005373489","pt":1580642344671,"mc":[{"id":"1.168219389","rc":[{"trd":[[1.19,110]],"batl":[[0,1.19,477.75]],"ltp":1.19,"tv":4317.79,"id":8535963}],"tv":4369.64}]}
{"op":"mcm","clk":"1005373693","pt":1580642345582,"mc":[{"id":"1.168219389","rc":[{"batb":[[0,1.16,168.04],[1,1.11,684.32],[2,1.08,296.16]],"batl":[[0,1.2,42.01],[1,1.2,0]],"ltp":1.19,"tv":4317.79,"id":8535963},{"batb":[[0,6,8.4],[1,3.85,13.22],[2,3,380.84]],"ltp":2.06,"tv":51.84,"id":2309796}]}]}
{"op":"mcm","clk":"1005373900","pt":1580642346559,"mc":[{"id":"1.168219389","rc":[{"batb":[[0,1.11,684.32],[1,1.08,296.16],[2,1.01,10.51]],"ltp":1.19,"tv":4317.79,"id":8535963},{"batb":[[0,3.85,13.22],[1,3,380.84],[2,1.01,10.52]],"ltp":2.06,"tv":51.84,"id":2309796}]}]}
{"op":"mcm","clk":"1005374526","pt":1580642349549,"mc":[{"id":"1.168219389","rc":[{"batb":[[1,1.09,1183.89],[2,1.08,296.16]],"batl":[[0,1.36,221.82],[1,1.37,257.25]],"ltp":1.19,"tv":4317.79,"id":8535963}]}]}
{"op":"mcm","clk":"1005375354","pt":1580642354044,"mc":[{"id":"1.168219389","rc":[{"batb":[[1,1.08,296.16],[2,1.01,10.51]],"ltp":1.19,"tv":4317.79,"id":8535963}]}]}
{"op":"mcm","clk":"1005375816","pt":1580642356740,"mc":[{"id":"1.168219389","rc":[{"batb":[[0,1.08,296.16],[1,1.01,10.51],[2,1.01,0]],"ltp":1.19,"tv":4317.79,"id":8535963},{"batb":[[1,1.01,10.52],[2,1.01,0]],"ltp":2.06,"tv":51.84,"id":2309796}]}]}
{"op":"mcm","clk":"1005376006","pt":1580642357755,"mc":[{"id":"1.168219389","rc":[{"batb":[[0,1.33,152.7],[1,1.32,317.3],[2,1.31,69.95]],"batl":[[0,1.36,263.83]],"ltp":1.19,"tv":4317.79,"id":8535963},{"batb":[[1,3.8,14.28],[2,2.3,19.91]],"ltp":2.06,"tv":51.84,"id":2309796}]}]}
{"op":"mcm","clk":"1005376445","pt":1580642360152,"mc":[{"id":"1.168219389","rc":[{"batb":[[2,2.38,382.3]],"ltp":2.06,"tv":51.84,"id":2309796}]}]}
{"op":"mcm","clk":"1005377891","pt":1580642367613,"mc":[{"id":"1.168219389","rc":[{"trd":[[3.85,16.5]],"batb":[[0,3.85,4.97]],"ltp":3.85,"tv":68.35,"id":2309796}],"tv":4386.14}]}
{"op":"mcm","clk":"1005379546","pt":1580642376614,"mc":[{"id":"1.168219389","rc":[{"batb":[[0,1.23,516.48],[1,1.16,148.39],[2,1.01,10.51]],"ltp":1.19,"tv":4317.79,"id":8535963},{"batb":[[0,2.38,382.3],[1,2.3,19.91],[2,1.01,10.52]],"ltp":3.85,"tv":68.35,"id":2309796}]}]}
{"op":"mcm","clk":"1005379842","pt":1580642378211,"mc":[{"id":"1.168219389","rc":[{"batb":[[0,1.16,148.39],[1,1.01,10.51],[2,1.01,0]],"ltp":1.19,"tv":4317.79,"id":8535963},{"batb":[[0,2.3,19.91],[1,1.01,10.52],[2,1.01,0]],"ltp":3.85,"tv":68.35,"id":2309796}]}]}
{"op":"mcm","clk":"1005380110","pt":1580642379753,"mc":[{"id":"1.168219389","rc":[{"batb":[[0,1.17,542.84],[1,1.16,711.5],[2,1.01,10.51]],"batl":[[0,1.81,143.46],[1,1.83,175.4]],"ltp":1.19,"tv":4317.79,"id":8535963},{"batb":[[0,2.28,20.22]],"batl":[[0,4.3,1.96]],"ltp":3.85,"tv":68.35,"id":2309796}]}]}
{"op":"mcm","clk":"1005381012","pt":1580642384448,"mc":[{"id":"1.168219389","rc":[{"batl":[[0,1.19,175.18],[1,1.2,541.19]],"ltp":1.19,"tv":4317.79,"id":8535963}]}]}
{"op":"mcm","clk":"1005381212","pt":1580642385555,"mc":[{"id":"1.168219389","rc":[{"batb":[[1,1.16,879.54],[2,1.11,684.32]],"batl":[[1,1.2,583.2]],"ltp":1.19,"tv":4317.79,"id":8535963},{"batb":[[0,6,18.1],[1,5.9,8.4],[2,3.7,14.48]],"batl":[[0,7.2,6.72]],"ltp":3.85,"tv":68.35,"id":2309796}]}]}
{"op":"mcm","clk":"1005383764","pt":1580642399686,"mc":[{"id":"1.168219389","rc":[{"batb":[[0,1.16,314.62],[1,1.11,684.32],[2,1.09,273.66]],"batl":[[0,1.2,42.01],[1,1.2,0]],"ltp":1.19,"tv":4317.79,"id":8535963}]}]}
{"op":"mcm","clk":"1005383937","pt":1580642400593,"mc":[{"id":"1.168219389","rc":[{"batb":[[0,1.11,684.32],[1,1.09,273.66],[2,1.01,10.51]],"ltp":1.19,"tv":4317.79,"id":8535963},{"batb":[[0,3.7,14.48],[1,3,380.84],[2,1.01,10.52]],"ltp":3.85,"tv":68.35,"id":2309796}]}]}
{"op":"mcm","clk":"1005384346","pt":1580642402577,"mc":[{"id":"1.168219389","rc":[{"batb":[[1,1.1,428.34],[2,1.09,1025.28]],"batl":[[0,1.37,253.57],[1,1.38,248.32]],"ltp":1.19,"tv":4317.79,"id":8535963}]}]}
{"op":"mcm","clk":"1005389921","pt":1580642432765,"mc":[{"id":"1.168219389","rc":[{"batb":[[1,1.09,273.66],[2,1.01,10.51]],"ltp":1.19,"tv":4317.79,"id":8535963}]}]}
{"op":"mcm","clk":"1005390282","pt":1580642434679,"mc":[{"id":"1.168219389","rc":[{"batb":[[0,1.09,273.66],[1,1.01,10.51],[2,1.01,0]],"ltp":1.19,"tv":4317.79,"id":8535963},{"batb":[[1,1.01,10.52],[2,1.01,0]],"ltp":3.85,"tv":68.35,"id":2309796}]}]}
{"op":"mcm","clk":"1005390453","pt":1580642435683,"mc":[{"id":"1.168219389","rc":[{"batb":[[0,1.33,396.3],[1,1.32,320.96],[2,1.09,273.66]],"ltp":1.19,"tv":4317.79,"id":8535963}]}]}
{"op":"mcm","clk":"1005390663","pt":1580642436760,"mc":[{"id":"1.168219389","rc":[{"batb":[[1,1.32,386.5],[2,1.17,138.4]],"ltp":1.19,"tv":4317.79,"id":8535963},{"batb":[[1,2.24,21.24],[2,1.01,10.52]],"ltp":3.85,"tv":68.35,"id":2309796}]}]}
{"op":"mcm","clk":"1005390785","pt":1580642437491,"mc":[{"id":"1.168219389","rc":[{"batb":[[2,1.3,139.47]],"batl":[[0,1.37,295.58]],"ltp":1.19,"tv":4317.79,"id":8535963},{"batb":[[0,3.7,29.6]],"batl":[[0,4.3,12.6]],"ltp":3.85,"tv":68.35,"id":2309796}]}]}
{"op":"mcm","clk":"1005391049","pt":1580642438860,"mc":[{"id":"1.168219389","rc":[{"batb":[[1,2.38,382.3],[2,2.24,21.24]],"ltp":3.85,"tv":68.35,"id":2309796}]}]}
{"op":"mcm","clk":"1005394692","pt":1580642458578,"mc":[{"id":"1.168219389","rc":[{"batb":[[0,1.23,516.48],[1,1.17,138.4],[2,1.01,10.51]],"ltp":1.19,"tv":4317.79,"id":8535963},{"batb":[[0,2.38,382.3],[1,2.24,21.24],[2,1.01,10.52]],"ltp":3.85,"tv":68.35,"id":2309796}]}]}
{"op":"mcm","clk":"1005395031","pt":1580642460557,"mc":[{"id":"1.168219389","rc":[{"batb":[[0,1.17,138.4],[1,1.01,10.51],[2,1.01,0]],"ltp":1.19,"tv":4317.79,"id":8535963},{"batb":[[0,2.24,21.24],[1,1.01,10.52],[2,1.01,0]],"ltp":3.85,"tv":68.35,"id":2309796}]}]}
{"op":"mcm","clk":"1005395114","pt":1580642461020,"mc":[{"id":"1.168219389","rc":[{"batb":[[0,1.18,200.5],[1,1.17,817.75],[2,1.01,10.51]],"batl":[[0,1.82,125.5],[1,1.84,172.42]],"ltp":1.19,"tv":4317.79,"id":8535963}]}]}
{"op":"mcm","clk":"1005396067","pt":1580642466527,"mc":[{"id":"1.168219389","rc":[{"batb":[[0,1.17,138.4],[1,1.01,10.51],[2,1.01,0]],"ltp":1.19,"tv":4317.79,"id":8535963}]}]}
{"op":"mcm","clk":"1005396609","pt":1580642469560,"mc":[{"id":"1.168219389","rc":[{"batb":[[0,1.75,176.07],[1,1.73,208.59],[2,1.17,138.4]],"batl":[[0,1.82,125.51],[1,1.83,42.01],[2,1.84,172.43]],"ltp":1.19,"tv":4317.79,"id":8535963},{"batb":[[1,2.2,34.45],[2,1.01,10.52]],"ltp":3.85,"tv":68.35,"id":2309796}]}]}
{"op":"mcm","clk":"1005396819","pt":1580642470632,"mc":[{"id":"1.168219389","rc":[{"batb":[[1,1.73,231.09],[2,1.7,59.65]],"ltp":1.19,"tv":4317.79,"id":8535963},{"batb":[[2,2.04,27.46]],"batl":[[0,2.42,29.41]],"ltp":3.85,"tv":68.35,"id":2309796}]}]}
{"op":"mcm","clk":"1005398910","pt":1580642482356,"mc":[{"id":"1.168219389","rc":[{"trd":[[1.75,26.52]],"batb":[[0,1.75,162.81]],"ltp":1.75,"tv":4344.31,"id":8535963}],"tv":4412.66}]}
{"op":"mcm","clk":"1005400626","pt":1580642492325,"mc":[{"id":"1.168219389","rc":[{"trd":[[2.24,42.48]],"batb":[[0,2.2,34.45],[1,2.04,27.46],[2,1.74,404.28]],"batl":[[0,2.24,1659.15],[1,2.42,29.41]],"ltp":2.24,"tv":110.83,"id":2309796}],"tv":4455.15}]}
{"op":"mcm","clk":"1005400966","pt":1580642494479,"mc":[{"id":"1.168219389","rc":[{"batb":[[0,1.73,22.5],[1,1.7,59.65],[2,1.53,34.78]],"batl":[[0,1.83,42.01],[1,1.83,0],[2,1.84,0]],"ltp":1.75,"tv":4344.31,"id":8535963}]}]}
{"op":"mcm","clk":"1005401287","pt":1580642496279,"mc":[{"id":"1.168219389","rc":[{"batb":[[0,1.74,21.95],[2,1.54,33.99]],"ltp":1.75,"tv":4344.31,"id":8535963},{"batb":[[0,2.2,56.24],[1,2.02,28.09]],"ltp":2.24,"tv":110.83,"id":2309796}]}]}
{"op":"mcm","clk":"1005401476","pt":1580642497279,"mc":[{"id":"1.168219389","rc":[{"batb":[[0,1.76,142.71],[1,1.74,226.21],[2,1.7,59.65]],"batl":[[0,1.83,188.96],[1,1.85,169.3]],"ltp":1.75,"tv":4344.31,"id":8535963}]}]}
{"op":"mcm","clk":"1005402567","pt":1580642503441,"mc":[{"id":"1.168219389","rc":[{"batl":[[0,1.83,159.37]],"ltp":1.75,"tv":4344.31,"id":8535963}]}]}
{"op":"mcm","clk":"1005402740","pt":1580642504344,"mc":[{"id":"1.168219389","rc":[{"batb":[[1,1.75,21.79],[2,1.74,204.26]],"ltp":1.75,"tv":4344.31,"id":8535963}]}]}
{"op":"mcm","clk":"1005403057","pt":1580642506408,"mc":[{"id":"1.168219389","rc":[{"batb":[[0,1.76,173.51]],"ltp":1.75,"tv":4344.31,"id":8535963}]}]}
{"op":"mcm","clk":"1005403688","pt":1580642510251,"mc":[{"id":"1.168219389","rc":[{"batl":[[0,1.83,117.36]],"ltp":1.75,"tv":4344.31,"id":8535963},{"batb":[[0,2.2,21.79]],"batl":[[1,2.42,0]],"ltp":2.24,"tv":110.83,"id":2309796}]}]}
{"op":"mcm","clk":"1005404228","pt":1580642513114,"mc":[{"id":"1.168219389","rc":[{"batl":[[1,1.84,42.01],[2,1.85,169.3]],"ltp":1.75,"tv":4344.31,"id":8535963},{"batb":[[1,2.18,35.29],[2,2.02,28.09]],"batl":[[1,2.38,30.25]],"ltp":2.24,"tv":110.83,"id":2309796}]}]}
{"op":"mcm","clk":"1005405081","pt":1580642517802,"mc":[{"id":"1.168219389","rc":[{"batl":[[0,2.38,30.25],[1,2.38,0]],"ltp":2.24,"tv":110.83,"id":2309796}]}]}
{"op":"mcm","clk":"1005405808","pt":1580642521410,"mc":[{"id":"1.168219389","rc":[{"trd":[[1.83,117.36]],"batb":[[0,1.75,21.79],[1,1.54,33.75],[2,1.52,425.49]],"ltp":1.83,"tv":4461.67,"id":8535963},{"trd":[[2.2,141.21]],"batb":[[0,2.02,28.09],[1,1.74,404.28],[2,1.01,10.52]],"batl":[[0,2.2,1539.73],[1,2.38,30.25]],"ltp":2.2,"tv":252.04,"id":2309796}],"tv":4713.72}]}
{"op":"mcm","clk":"1005406400","pt":1580642524753,"mc":[{"id":"1.168219389","rc":[{"batb":[[0,1.77,122.71],[1,1.76,21.32],[2,1.75,221.86]],"batl":[[0,1.84,155.92],[1,1.86,208.26]],"ltp":1.83,"tv":4461.67,"id":8535963},{"trd":[[2.2,210.11]],"batb":[[0,2.18,22.5],[1,2.16,36.13],[2,2.02,28.09]],"batl":[[0,2.2,1505.28]],"ltp":2.2,"tv":320.94,"id":2309796}],"tv":4782.62}]}
{"op":"mcm","clk":"1005406461","pt":1580642525024,"mc":[{"id":"1.168219389","rc":[{"batb":[[2,1.75,200.07]],"ltp":1.83,"tv":4461.67,"id":8535963},{"batb":[[2,2,29.03]],"ltp":2.2,"tv":320.94,"id":2309796}]}]}
{"op":"mcm","clk":"1005411505","pt":1580642551476,"mc":[{"id":"1.168219389","rc":[{"batb":[[0,1.72,57.97],[1,1.55,33.05],[2,1.52,425.49]],"batl":[[0,1.86,42.01],[1,1.86,0]],"ltp":1.83,"tv":4461.67,"id":8535963},{"batb":[[0,2.16,36.13],[1,2,29.03],[2,1.74,404.28]],"ltp":2.2,"tv":320.94,"id":2309796}]}]}
{"op":"mcm","clk":"1005411727","pt":1580642552580,"mc":[{"id":"1.168219389","rc":[{"batb":[[0,1.55,33.05],[1,1.52,425.49],[2,1.01,10.51]],"ltp":1.83,"tv":4461.67,"id":8535963},{"batb":[[0,2,29.03],[1,1.74,404.28],[2,1.01,10.52]],"batl":[[1,2.38,0]],"ltp":2.2,"tv":320.94,"id":2309796}]}]}
{"op":"mcm","clk":"1005412130","pt":1580642554485,"mc":[{"id":"1.168219389","rc":[{"batb":[[0,1.57,166.17],[1,1.56,185.16],[2,1.55,33.05]],"batl":[[0,1.99,149.41],[1,2.02,195.05]],"ltp":1.83,"tv":4461.67,"id":8535963}]}]}
{"op":"mcm","clk":"1005412178","pt":1580642554774,"mc":[{"id":"1.168219389","rc":[{"batb":[[2,1.52,425.49]],"ltp":1.83,"tv":4461.67,"id":8535963}]}]}
{"op":"mcm","clk":"1005413322","pt":1580642560846,"mc":[{"id":"1.168219389","rc":[{"batb":[[0,1.56,33.05],[1,1.52,425.49],[2,1.01,10.51]],"ltp":1.83,"tv":4461.67,"id":8535963}]}]}
{"op":"mcm","clk":"1005413532","pt":1580642562068,"mc":[{"id":"1.168219389","rc":[{"trd":[[2,4.54]],"batb":[[0,2,26.76]],"ltp":2.0,"tv":325.48,"id":2309796}],"tv":4787.16}]}
{"op":"mcm","clk":"1005414054","pt":1580642564732,"mc":[{"id":"1.168219389","rc":[{"trd":[[1.83,433.38]],"ltp":1.83,"tv":4777.69,"id":8535963},{"trd":[[2.2,472.98]],"batl":[[0,2.2,1242.41]],"ltp":2.2,"tv":588.35,"id":2309796}],"tv":5366.05}]}
{"op":"mcm","clk":"1005414866","pt":1580642568762,"mc":[{"id":"1.168219389","rc":[{"batl":[[0,2.02,220.15],[1,2.04,125.53]],"ltp":1.83,"tv":4777.69,"id":8535963}]}]}
{"op":"mcm","clk":"1005415094","pt":1580642570080,"mc":[{"id":"1.168219389","rc":[{"batb":[[1,1.01,10.51],[2,1.01,0]],"ltp":1.83,"tv":4777.69,"id":8535963}]}]}
{"op":"mcm","clk":"1005415412","pt":1580642571587,"mc":[{"id":"1.168219389","rc":[{"batb":[[0,1.92,141.22],[1,1.9,152.92],[2,1.83,50.41]],"batl":[[0,2.02,261.32]],"ltp":1.83,"tv":4777.69,"id":8535963},{"batb":[[0,2,68.77]],"batl":[[0,2.2,1276.86]],"ltp":2.2,"tv":588.35,"id":2309796}]}]}
{"op":"mcm","clk":"1005415572","pt":1580642572404,"mc":[{"id":"1.168219389","rc":[{"batb":[[1,1.91,16.68],[2,1.9,152.92]],"ltp":1.83,"tv":4777.69,"id":8535963},{"batb":[[1,1.88,17.7],[2,1.74,404.28]],"ltp":2.2,"tv":588.35,"id":2309796}]}]}
{"op":"mcm","clk":"1005417758","pt":1580642583468,"mc":[{"id":"1.168219389","rc":[{"batl":[[0,2.2,34.45]],"ltp":2.2,"tv":588.35,"id":2309796}]}]}
{"op":"mcm","clk":"1005418339","pt":1580642586583,"mc":[{"id":"1.168219389","rc":[{"batb":[[0,1.72,23.6],[1,1.58,416.47],[2,1.01,10.51]],"ltp":1.83,"tv":4777.69,"id":8535963},{"batb":[[0,1.88,17.7],[1,1.74,404.28],[2,1.01,10.52]],"ltp":2.2,"tv":588.35,"id":2309796}]}]}
{"op":"mcm","clk":"1005418910","pt":1580642589595,"mc":[{"id":"1.168219389","rc":[{"batb":[[0,1.73,205.76],[1,1.72,23.6],[2,1.71,216.37]],"batl":[[0,2.14,130.41],[1,2.16,106.52]],"ltp":1.83,"tv":4777.69,"id":8535963}]}]}
{"op":"mcm","clk":"1005419080","pt":1580642590403,"mc":[{"id":"1.168219389","rc":[{"batb":[[0,1.72,23.6],[1,1.58,416.47],[2,1.01,10.51]],"ltp":1.83,"tv":4777.69,"id":8535963}]}]}
{"op":"mcm","clk":"1005419397","pt":1580642592109,"mc":[{"id":"1.168219389","rc":[{"batb":[[1,1.01,10.51],[2,1.01,0]],"ltp":1.83,"tv":4777.69,"id":8535963},{"batb":[[1,1.01,10.52],[2,1.01,0]],"ltp":2.2,"tv":588.35,"id":2309796}]}]}
{"op":"mcm","clk":"1005419690","pt":1580642593705,"mc":[{"id":"1.168219389","rc":[{"batb":[[0,1.93,44.53],[1,1.72,23.6],[2,1.01,10.51]],"batl":[[0,2.14,36.13]],"ltp":1.83,"tv":4777.69,"id":8535963},{"batb":[[0,1.88,190.72],[1,1.86,163.52],[2,1.01,10.52]],"batl":[[0,1.96,135.5],[1,1.98,137.18],[2,2.06,39.49]],"ltp":2.2,"tv":588.35,"id":2309796}]}]}
{"op":"mcm","clk":"1005419788","pt":1580642594134,"mc":[{"id":"1.168219389","rc":[{"batb":[[0,2.04,27.38],[1,1.93,44.53],[2,1.89,17.39]],"ltp":1.83,"tv":4777.69,"id":8535963},{"batb":[[2,1.8,20.3]],"ltp":2.2,"tv":588.35,"id":2309796}]}]}
{"op":"mcm","clk":"1005421075","pt":1580642600649,"mc":[{"id":"1.168219389","rc":[{"batb":[[0,1.89,17.39],[1,1.67,409.76],[2,1.01,10.51]],"ltp":1.83,"tv":4777.69,"id":8535963},{"batb":[[0,1.8,20.3],[1,1.58,416.47],[2,1.01,10.52]],"ltp":2.2,"tv":588.35,"id":2309796}]}]}
{"op":"mcm","clk":"1005421661","pt":1580642603530,"mc":[{"id":"1.168219389","rc":[{"batb":[[0,1.81,163.65],[1,1.8,20.3],[2,1.79,185.27]],"batl":[[0,2.12,195.93],[1,2.14,109.47]],"ltp":2.2,"tv":588.35,"id":2309796}]}]}
{"op":"mcm","clk":"1005422372","pt":1580642606718,"mc":[{"id":"1.168219389","rc":[{"batb":[[0,1.8,20.3],[1,1.58,416.47],[2,1.01,10.52]],"ltp":2.2,"tv":588.35,"id":2309796}]}]}
{"op":"mcm","clk":"1005422489","pt":1580642607241,"mc":[{"id":"1.168219389","rc":[{"batb":[[1,1.01,10.52],[2,1.01,0]],"ltp":2.2,"tv":588.35,"id":2309796}]}]}
{"op":"mcm","clk":"1005423015","pt":1580642609724,"mc":[{"id":"1.168219389","rc":[{"batb":[[0,1.9,163.15],[1,1.89,17.39],[2,1.88,158.15]],"batl":[[0,1.99,151.83],[1,2,42.01],[2,2.02,194.81]],"ltp":1.83,"tv":4777.69,"id":8535963},{"batb":[[0,2.02,27.85],[1,1.99,42.01],[2,1.88,17.7]],"batl":[[0,2.22,33.61]],"ltp":2.2,"tv":588.35,"id":2309796}]}]}
{"op":"mcm","clk":"1005423146","pt":1580642610362,"mc":[{"id":"1.168219389","rc":[{"batb":[[1,1.88,17.7],[2,1.01,10.52]],"ltp":2.2,"tv":588.35,"id":2309796}]}]}
{"op":"mcm","clk":"1005423386","pt":1580642611537,"mc":[{"id":"1.168219389","rc":[{"batb":[[2,1.67,409.76]],"ltp":2.2,"tv":588.35,"id":2309796}]}]}
{"op":"mcm","clk":"1005423579","pt":1580642612437,"mc":[{"id":"1.168219389","rc":[{"batb":[[1,2,42.01],[2,1.88,17.7]],"ltp":2.2,"tv":588.35,"id":2309796}]}]}
{"op":"mcm","clk":"1005425856","pt":1580642624586,"mc":[{"id":"1.168219389","rc":[{"batb":[[0,1.67,409.76],[1,1.66,26.44],[2,1.01,10.51]],"ltp":1.83,"tv":4777.69,"id":8535963},{"batb":[[0,1.88,17.7],[1,1.67,409.76],[2,1.01,10.52]],"ltp":2.2,"tv":588.35,"id":2309796}]}]}
{"op":"mcm","clk":"1005426497","pt":1580642627757,"mc":[{"id":"1.168219389","rc":[{"batb":[[0,1.69,133.76],[1,1.68,115.57],[2,1.67,409.76]],"batl":[[0,2.16,185.42],[1,2.18,103.84]],"ltp":1.83,"tv":4777.69,"id":8535963}]}]}
{"op":"mcm","clk":"1005426658","pt":1580642628557,"mc":[{"id":"1.168219389","rc":[{"batl":[[0,2.1,168.04]],"ltp":2.2,"tv":588.35,"id":2309796}]}]}
{"op":"mcm","clk":"1005428856","pt":1580642640486,"mc":[{"id":"1.168219389","rc":[{"batb":[[2,1.66,26.44]],"ltp":1.83,"tv":4777.69,"id":8535963},{"batb":[[1,1.01,10.52],[2,1.01,0]],"ltp":2.2,"tv":588.35,"id":2309796}]}]}
{"op":"mcm","clk":"1005429077","pt":1580642641566,"mc":[{"id":"1.168219389","rc":[{"batl":[[0,1.75,130.25],[1,1.77,194.42]],"ltp":1.83,"tv":4777.69,"id":8535963},{"batl":[[0,2.56,26.89]],"ltp":2.2,"tv":588.35,"id":2309796}]}]}
{"op":"mcm","clk":"1005429197","pt":1580642642161,"mc":[{"id":"1.168219389","rc":[{"batb":[[0,2.38,17.78],[1,2.02,28.4],[2,1.01,10.52]],"ltp":2.2,"tv":588.35,"id":2309796}]}]}
{"op":"mcm","clk":"1005429529","pt":1580642643672,"mc":[{"id":"1.168219389","rc":[{"batb":[[2,1.82,401.24]],"ltp":2.2,"tv":588.35,"id":2309796}]}]}
{"op":"mcm","clk":"1005432091","pt":1580642656725,"mc":[{"id":"1.168219389","rc":[{"batb":[[0,1.66,26.44],[1,1.65,63.85],[2,1.46,435.7]],"ltp":1.83,"tv":4777.69,"id":8535963}]}]}
{"op":"mcm","clk":"1005432246","pt":1580642657421,"mc":[{"id":"1.168219389","rc":[{"batb":[[0,1.65,63.85],[1,1.46,435.7],[2,1.37,55.86]],"ltp":1.83,"tv":4777.69,"id":8535963},{"trd":[[2.38,35.56]],"batb":[[0,2.02,28.4],[1,1.82,401.24],[2,1.01,10.52]],"batl":[[0,2.38,822.42],[1,2.56,26.89]],"ltp":2.38,"tv":623.91,"id":2309796}],"tv":5401.61}]}
{"op":"mcm","clk":"1005432500","pt":1580642658607,"mc":[{"id":"1.168219389","rc":[{"batb":[[0,1.46,435.7],[1,1.37,55.86],[2,1.01,10.51]],"ltp":1.83,"tv":4777.69,"id":8535963},{"batl":[[1,2.56,0]],"ltp":2.38,"tv":623.91,"id":2309796}]}]}
{"op":"mcm","clk":"1005432726","pt":1580642659741,"mc":[{"id":"1.168219389","rc":[{"batb":[[1,1.39,361.02],[2,1.38,311.52]],"batl":[[0,2.02,224.62],[1,2.04,125.56]],"ltp":1.83,"tv":4777.69,"id":8535963},{"batb":[[1,2,28.48],[2,1.82,401.24]],"ltp":2.38,"tv":623.91,"id":2309796}]}]}
{"op":"mcm","clk":"1005432894","pt":1580642660667,"mc":[{"id":"1.168219389","rc":[{"batb":[[0,2,28.48],[1,1.82,401.24],[2,1.01,10.52]],"ltp":2.38,"tv":623.91,"id":2309796}]}]}
{"op":"mcm","clk":"1005433575","pt":1580642663729,"mc":[{"id":"1.168219389","rc":[{"batb":[[1,1.38,55.71],[2,1.01,10.51]],"ltp":1.83,"tv":4777.69,"id":8535963}]}]}
{"op":"mcm","clk":"1005433957","pt":1580642665641,"mc":[{"id":"1.168219389","rc":[{"batb":[[0,1.38,55.71],[1,1.01,10.51],[2,1.01,0]],"ltp":1.83,"tv":4777.69,"id":8535963},{"batb":[[1,1.01,10.52],[2,1.01,0]],"ltp":2.38,"tv":623.91,"id":2309796}]}]}
{"op":"mcm","clk":"1005434142","pt":1580642666543,"mc":[{"id":"1.168219389","rc":[{"batb":[[0,1.92,136.67],[1,1.9,152.95],[2,1.38,55.71]],"ltp":1.83,"tv":4777.69,"id":8535963}]}]}
{"op":"mcm","clk":"1005434350","pt":1580642667543,"mc":[{"id":"1.168219389","rc":[{"batb":[[1,1.91,16.76],[2,1.9,152.95]],"batl":[[0,2.02,265.79]],"ltp":1.83,"tv":4777.69,"id":8535963},{"batb":[[0,2,70.49],[1,1.84,18.73],[2,1.01,10.52]],"batl":[[0,2.2,34.45],[1,2.38,822.42]],"ltp":2.38,"tv":623.91,"id":2309796}]}]}
{"op":"mcm","clk":"1005434636","pt":1580642668933,"mc":[{"id":"1.168219389","rc":[{"batb":[[2,1.67,409.76]],"ltp":2.38,"tv":623.91,"id":2309796}]}]}
{"op":"mcm","clk":"1005436843","pt":1580642680625,"mc":[{"id":"1.168219389","rc":[{"batb":[[0,1.65,26.91],[1,1.58,416.47],[2,1.01,10.51]],"ltp":1.83,"tv":4777.69,"id":8535963},{"batb":[[0,1.84,18.73],[1,1.67,409.76],[2,1.01,10.52]],"batl":[[0,2.38,822.42],[1,2.38,0]],"ltp":2.38,"tv":623.91,"id":2309796}]}]}
{"op":"mcm","clk":"1005437378","pt":1580642683516,"mc":[{"id":"1.168219389","rc":[{"batb":[[0,1.67,222.92],[1,1.66,120.83],[2,1.65,26.91]],"batl":[[0,2.2,144.43],[1,2.22,98.97]],"ltp":1.83,"tv":4777.69,"id":8535963}]}]}
{"op":"mcm","clk":"1005438800","pt":1580642691602,"mc":[{"id":"1.168219389","rc":[{"batl":[[0,1.74,168.66],[1,1.76,197.9]],"ltp":1.83,"tv":4777.69,"id":8535963},{"batb":[[1,1.01,10.52],[2,1.01,0]],"ltp":2.38,"tv":623.91,"id":2309796}]}]}
{"op":"mcm","clk":"1005439001","pt":1580642692725,"mc":[{"id":"1.168219389","rc":[{"trd":[[2.38,70.33]],"batb":[[0,2.02,27.85]],"batl":[[0,2.38,805.03]],"ltp":2.38,"tv":658.69,"id":2309796}],"tv":5436.38}]}
{"op":"mcm","clk":"1005439201","pt":1580642693723,"mc":[{"id":"1.168219389","rc":[{"batl":[[2,1.77,42.01]],"ltp":1.83,"tv":4777.69,"id":8535963},{"batb":[[0,2.3,31.93],[1,2.02,27.85],[2,1.01,10.52]],"batl":[[1,2.56,26.89]],"ltp":2.38,"tv":658.69,"id":2309796}]}]}
{"op":"mcm","clk":"1005439372","pt":1580642694727,"mc":[{"id":"1.168219389","rc":[{"batb":[[2,1.86,398.62]],"ltp":2.38,"tv":658.69,"id":2309796}]}]}
{"op":"mcm","clk":"1005441418","pt":1580642705736,"mc":[{"id":"1.168219389","rc":[{"batb":[[0,1.64,65.54],[1,1.44,436.18],[2,1.37,55.94]],"batl":[[0,1.77,42.01],[1,1.76,0],[2,1.77,0]],"ltp":1.83,"tv":4777.69,"id":8535963}]}]}
{"op":"mcm","clk":"1005441584","pt":1580642706639,"mc":[{"id":"1.168219389","rc":[{"batb":[[0,1.44,436.18],[1,1.37,55.94],[2,1.01,10.51]],"ltp":1.83,"tv":4777.69,"id":8535963},{"batb":[[0,2.02,27.85],[1,1.86,398.62],[2,1.01,10.52]],"batl":[[1,2.56,0]],"ltp":2.38,"tv":658.69,"id":2309796}]}]}
{"op":"mcm","clk":"1005441990","pt":1580642708651,"mc":[{"id":"1.168219389","rc":[{"batb":[[1,1.39,179.99],[2,1.38,253.78]],"batl":[[0,1.99,137.12],[1,2.02,194.87]],"ltp":1.83,"tv":4777.69,"id":8535963}]}]}
{"op":"mcm","clk":"1005443294","pt":1580642715661,"mc":[{"id":"1.168219389","rc":[{"batb":[[0,1.39,179.99],[1,1.38,253.78],[2,1.37,55.94]],"ltp":1.83,"tv":4777.69,"id":8535963},{"batb":[[1,1.01,10.52],[2,1.01,0]],"ltp":2.38,"tv":658.69,"id":2309796}]}]}
{"op":"mcm","clk":"1005443456","pt":1580642716556,"mc":[{"id":"1.168219389","rc":[{"trd":[[1.72,474.47]],"batb":[[1,1.37,55.94],[2,1.08,287.74]],"ltp":1.72,"tv":5252.16,"id":8535963},{"trd":[[2.38,483.72]],"batb":[[0,1.01,10.52],[1,1.01,0]],"batl":[[0,2.38,426.89]],"ltp":2.38,"tv":1072.07,"id":2309796}],"tv":6324.24}]}
{"op":"mcm","clk":"1005443605","pt":1580642717563,"mc":[{"id":"1.168219389","rc":[{"batb":[[1,1.38,110.07],[2,1.37,55.94]],"ltp":1.72,"tv":5252.16,"id":8535963},{"trd":[[2.38,544.21]],"batl":[[0,2.38,396.65],[1,3.55,15.96]],"ltp":2.38,"tv":1132.57,"id":2309796}],"tv":6384.74}]}
{"op":"mcm","clk":"1005443813","pt":1580642718740,"mc":[{"id":"1.168219389","rc":[{"batb":[[1,1.37,55.94],[2,1.08,287.74]],"ltp":1.72,"tv":5252.16,"id":8535963}]}]}
{"op":"mcm","clk":"1005443970","pt":1580642719645,"mc":[{"id":"1.168219389","rc":[{"trd":[[1.72,977.24]],"batb":[[0,1.4,150.76],[1,1.39,243.47],[2,1.37,55.94]],"ltp":1.72,"tv":5754.93,"id":8535963},{"trd":[[2.38,907.57]],"batb":[[0,2.3,385.09],[1,1.01,10.52]],"batl":[[0,2.38,33.3]],"ltp":2.38,"tv":1495.92,"id":2309796}],"tv":7250.86}]}
{"op":"mcm","clk":"1005444250","pt":1580642721358,"mc":[{"id":"1.168219389","rc":[{"batb":[[1,1.39,351.01]],"ltp":1.72,"tv":5754.93,"id":8535963},{"trd":[[2.38,968.06]],"batl":[[0,2.38,3.05]],"ltp":2.38,"tv":1556.41,"id":2309796}],"tv":7311.35}]}
{"op":"mcm","clk":"1005444506","pt":1580642722652,"mc":[{"id":"1.168219389","rc":[{"trd":[[1.72,981.46]],"batb":[[0,1.4,359.54]],"batl":[[0,1.45,259.84],[1,1.46,190.37]],"ltp":1.72,"tv":5759.15,"id":8535963},{"trd":[[2.38,971.11]],"batl":[[0,3.55,15.96],[1,3.55,0]],"ltp":2.38,"tv":1559.46,"id":2309796}],"tv":7318.62}]}
{"op":"mcm","clk":"1005444822","pt":1580642724592,"mc":[{"id":"1.168219389","rc":[{"batl":[[2,1.72,46.07]],"ltp":1.72,"tv":5759.15,"id":8535963}]}]}
{"op":"mcm","clk":"1005445046","pt":1580642725764,"mc":[{"id":"1.168219389","rc":[{"batl":[[1,1.46,232.38]],"ltp":1.72,"tv":5759.15,"id":8535963},{"batb":[[0,3.15,19.32],[1,2.3,385.09],[2,1.01,10.52]],"ltp":2.38,"tv":1559.46,"id":2309796}]}]}
{"op":"mcm","clk":"1005445197","pt":1580642726549,"mc":[{"id":"1.168219389","rc":[{"batl":[[2,1.72,0]],"ltp":1.72,"tv":5759.15,"id":8535963}]}]}
{"op":"mcm","clk":"1005445374","pt":1580642727486,"mc":[{"id":"1.168219389","rc":[{"batb":[[0,1.39,107.54],[1,1.25,505.09],[2,1.08,287.74]],"batl":[[0,1.46,42.01],[1,1.46,0]],"ltp":1.72,"tv":5759.15,"id":8535963}]}]}
{"op":"mcm","clk":"1005445574","pt":1580642728561,"mc":[{"id":"1.168219389","rc":[{"batb":[[0,1.08,287.74],[1,1.01,10.51],[2,1.08,0]],"ltp":1.72,"tv":5759.15,"id":8535963},{"batb":[[0,1.01,10.52],[1,2.3,0],[2,1.01,0]],"ltp":2.38,"tv":1559.46,"id":2309796}]}]}
{"op":"mcm","clk":"1005445967","pt":1580642730752,"mc":[{"id":"1.168219389","rc":[{"batb":[[0,1.09,1042.75],[1,1.08,423.87],[2,1.01,10.51]],"batl":[[0,1.76,148.25],[1,1.78,189.24]],"ltp":1.72,"tv":5759.15,"id":8535963},{"batb":[[0,2.32,18.02],[1,1.01,10.52]],"ltp":2.38,"tv":1559.46,"id":2309796}]}]}
{"op":"mcm","clk":"1005446321","pt":1580642732692,"mc":[{"id":"1.168219389","rc":[{"batb":[[0,1.09,278.77],[1,1.01,10.51],[2,1.01,0]],"ltp":1.72,"tv":5759.15,"id":8535963}]}]}
{"op":"mcm","clk":"1005446807","pt":1580642735576,"mc":[{"id":"1.168219389","rc":[{"batb":[[0,1.69,212.08],[1,1.67,233.24],[2,1.09,278.77]],"batl":[[0,1.76,190.26]],"ltp":1.72,"tv":5759.15,"id":8535963},{"batb":[[0,2.32,49.11]],"ltp":2.38,"tv":1559.46,"id":2309796}]}]}
{"op":"mcm","clk":"1005446934","pt":1580642736270,"mc":[{"id":"1.168219389","rc":[{"batb":[[1,1.67,259.28],[2,1.64,65.54]],"ltp":1.72,"tv":5759.15,"id":8535963},{"batb":[[1,1.99,28.72],[2,1.01,10.52]],"batl":[[0,2.56,26.89]],"ltp":2.38,"tv":1559.46,"id":2309796}]}]}
{"op":"mcm","clk":"1005447053","pt":1580642736884,"mc":[{"id":"1.168219389","rc":[{"batb":[[2,1.86,398.62]],"ltp":2.38,"tv":1559.46,"id":2309796}]}]}
{"op":"mcm","clk":"1005453750","pt":1580642772276,"mc":[{"id":"1.168219389","rc":[{"batb":[[0,1.67,26.04],[1,1.64,65.54],[2,1.44,436.18]],"batl":[[0,1.76,42.01],[1,1.78,0]],"ltp":1.72,"tv":5759.15,"id":8535963}]}]}
{"op":"mcm","clk":"1005454378","pt":1580642775700,"mc":[{"id":"1.168219389","rc":[{"batl":[[1,2.02,131.2],[2,2.04,124.98]],"ltp":1.72,"tv":5759.15,"id":8535963}]}]}
{"op":"mcm","clk":"1005459339","pt":1580642801347,"mc":[{"id":"1.168219389","rc":[{"batb":[[0,1.64,65.54],[1,1.44,436.18],[2,1.4,197.11]],"ltp":1.72,"tv":5759.15,"id":8535963},{"batb":[[0,2.32,31.09]],"ltp":2.38,"tv":1559.46,"id":2309796}]}]}
{"op":"mcm","clk":"1005459583","pt":1580642802613,"mc":[{"id":"1.168219389","rc":[{"batb":[[0,1.44,436.18],[1,1.4,197.11],[2,1.39,242.41]],"batl":[[0,2.02,131.2],[1,2.04,124.98],[2,2.04,0]],"ltp":1.72,"tv":5759.15,"id":8535963},{"batb":[[0,1.99,28.72],[1,1.86,398.62],[2,1.01,10.52]],"ltp":2.38,"tv":1559.46,"id":2309796}]}]}
{"op":"mcm","clk":"1005460028","pt":1580642804758,"mc":[{"id":"1.168219389","rc":[{"batb":[[1,1.38,55.16],[2,1.01,10.51]],"ltp":1.72,"tv":5759.15,"id":8535963}]}]}
{"op":"mcm","clk":"1005460483","pt":1580642806520,"mc":[{"id":"1.168219389","rc":[{"batb":[[0,1.38,55.16],[1,1.01,10.51],[2,1.01,0]],"ltp":1.72,"tv":5759.15,"id":8535963},{"batb":[[1,1.01,10.52],[2,1.01,0]],"ltp":2.38,"tv":1559.46,"id":2309796}]}]}
{"op":"mcm","clk":"1005460713","pt":1580642807431,"mc":[{"id":"1.168219389","rc":[{"batb":[[0,1.62,249.53],[1,1.61,133.88],[2,1.38,55.16]],"batl":[[0,1.69,206.17],[1,1.71,215.43]],"ltp":1.72,"tv":5759.15,"id":8535963}]}]}
{"op":"mcm","clk":"1005461115","pt":1580642809658,"mc":[{"id":"1.168219389","rc":[{"batb":[[0,1.38,55.16],[1,1.01,10.51],[2,1.38,0]],"ltp":1.72,"tv":5759.15,"id":8535963}]}]}
{"op":"mcm","clk":"1005461265","pt":1580642810467,"mc":[{"id":"1.168219389","rc":[{"batb":[[0,1.38,503.6]],"ltp":1.72,"tv":5759.15,"id":8535963},{"batb":[[1,1.97,394.86],[2,1.01,10.52]],"ltp":2.38,"tv":1559.46,"id":2309796}]}]}
{"op":"mcm","clk":"1005461707","pt":1580642812567,"mc":[{"id":"1.168219389","rc":[{"batb":[[0,1.4,197.11],[1,1.39,242.41],[2,1.38,503.6]],"batl":[[0,2.02,131.2],[1,2.04,124.98]],"ltp":1.72,"tv":5759.15,"id":8535963}]}]}
{"op":"mcm","clk":"1005473063","pt":1580642872601,"mc":[{"id":"1.168219389","rc":[{"batb":[[2,1.38,55.16]],"ltp":1.72,"tv":5759.15,"id":8535963},{"batb":[[1,1.01,10.52],[2,1.01,0]],"ltp":2.38,"tv":1559.46,"id":2309796}]}]}
{"op":"mcm","clk":"1005473404","pt":1580642874380,"mc":[{"id":"1.168219389","rc":[{"batl":[[0,1.44,220.2],[1,1.45,196.3]],"ltp":1.72,"tv":5759.15,"id":8535963}]}]}
{"op":"mcm","clk":"1005473637","pt":1580642875608,"mc":[{"id":"1.168219389","rc":[{"batb":[[2,1.38,165.22]],"batl":[[2,1.46,42.01]],"ltp":1.72,"tv":5759.15,"id":8535963},{"batb":[[0,3.3,18.25],[1,3.15,19.32],[2,2.36,17.55]],"batl":[[0,3.6,15.96]],"ltp":2.38,"tv":1559.46,"id":2309796}]}]}
{"op":"mcm","clk":"1005473831","pt":1580642876685,"mc":[{"id":"1.168219389","rc":[{"batb":[[2,2.38,382.3]],"ltp":2.38,"tv":1559.46,"id":2309796}]}]}
{"op":"mcm","clk":"1005477961","pt":1580642900718,"mc":[{"id":"1.168219389","rc":[{"batb":[[0,1.23,516.48],[1,1.09,280.5],[2,1.01,10.51]],"ltp":1.72,"tv":5759.15,"id":8535963},{"batb":[[0,2.38,382.3],[1,2.36,17.55],[2,1.01,10.52]],"ltp":2.38,"tv":1559.46,"id":2309796}]}]}
{"op":"mcm","clk":"1005478390","pt":1580642902748,"mc":[{"id":"1.168219389","rc":[{"batb":[[0,1.09,877.72],[1,1.08,592.18]],"batl":[[0,1.75,193.4],[1,1.77,192.69]],"ltp":1.72,"tv":5759.15,"id":8535963},{"batb":[[0,2.36,17.55],[1,1.01,10.52],[2,1.01,0]],"ltp":2.38,"tv":1559.46,"id":2309796}]}]}
{"op":"mcm","clk":"1005478477","pt":1580642903176,"mc":[{"id":"1.168219389","rc":[{"batb":[[0,1.09,280.5],[1,1.01,10.51],[2,1.01,0]],"ltp":1.72,"tv":5759.15,"id":8535963}]}]}
{"op":"mcm","clk":"1005478905","pt":1580642905467,"mc":[{"id":"1.168219389","rc":[{"batb":[[0,1.32,376.21],[1,1.31,327.09],[2,1.09,280.5]],"batl":[[0,1.36,285.23],[1,1.37,250.73]],"ltp":1.72,"tv":5759.15,"id":8535963}]}]}
{"op":"mcm","clk":"1005479097","pt":1580642906664,"mc":[{"id":"1.168219389","rc":[{"batb":[[2,1.2,530.86]],"ltp":1.72,"tv":5759.15,"id":8535963},{"batb":[[0,2.52,381.46],[1,2.36,17.55],[2,1.01,10.52]],"ltp":2.38,"tv":1559.46,"id":2309796}]}]}
{"op":"mcm","clk":"1005479534","pt":1580642909367,"mc":[{"id":"1.168219389","rc":[{"batb":[[0,1.2,530.86],[1,1.09,280.5],[2,1.01,10.51]],"ltp":1.72,"tv":5759.15,"id":8535963}]}]}
{"op":"mcm","clk":"1005479804","pt":1580642910975,"mc":[{"id":"1.168219389","rc":[{"batb":[[0,1.09,280.5],[1,1.01,10.51],[2,1.01,0]],"ltp":1.72,"tv":5759.15,"id":8535963},{"batb":[[0,2.36,17.55],[1,1.01,10.52],[2,1.01,0]],"ltp":2.38,"tv":1559.46,"id":2309796}]}]}
{"op":"mcm","clk":"1005480022","pt":1580642912302,"mc":[{"id":"1.168219389","rc":[{"batb":[[0,1.09,877.72],[1,1.08,592.18],[2,1.01,10.51]],"batl":[[0,1.75,193.4],[1,1.77,192.69]],"ltp":1.72,"tv":5759.15,"id":8535963}]}]}
{"op":"mcm","clk":"1005484960","pt":1580642940753,"mc":[{"id":"1.168219389","rc":[{"batb":[[2,1.04,555.26]],"batl":[[0,1.11,1108.83]],"ltp":1.72,"tv":5759.15,"id":8535963},{"batb":[[0,9.2,16.13],[1,5.7,19.83],[2,1.01,10.52]],"ltp":2.38,"tv":1559.46,"id":2309796}]}]}
{"op":"mcm","clk":"1005485152","pt":1580642941668,"mc":[{"id":"1.168219389","rc":[{"batb":[[1,1.08,760.22]],"ltp":1.72,"tv":5759.15,"id":8535963},{"batl":[[0,13.5,3.36]],"ltp":2.38,"tv":1559.46,"id":2309796}]}]}
{"op":"mcm","clk":"1005485209","pt":1580642941992,"mc":[{"id":"1.168219389","rc":[{"batb":[[2,1.05,1069.56]],"ltp":1.72,"tv":5759.15,"id":8535963},{"batb":[[2,3.6,374.22]],"ltp":2.38,"tv":1559.46,"id":2309796}]}]}
{"op":"mcm","clk":"1005489579","pt":1580642966712,"mc":[{"id":"1.168219389","rc":[{"batl":[[0,1.11,1150.84]],"ltp":1.72,"tv":5759.15,"id":8535963},{"batb":[[0,10,4.2],[1,9.2,16.13],[2,5.7,19.83]],"ltp":2.38,"tv":1559.46,"id":2309796}]}]}
{"op":"mcm","clk":"1005489983","pt":1580642968697,"mc":[{"id":"1.168219389","rc":[{"trd":[[1.09,15.15]],"batb":[[0,1.09,870.15]],"ltp":1.09,"tv":5774.3,"id":8535963}],"tv":7333.77}]}
{"op":"mcm","clk":"1005490822","pt":1580642973190,"mc":[{"id":"1.168219389","rc":[{"batb":[[0,1.08,168.04],[1,1.05,1069.56],[2,1.04,555.26]],"batl":[[0,1.11,42.01]],"ltp":1.09,"tv":5774.3,"id":8535963},{"batb":[[1,5.7,19.83],[2,3.6,374.22]],"ltp":2.38,"tv":1559.46,"id":2309796}]}]}
{"op":"mcm","clk":"1005491059","pt":1580642974642,"mc":[{"id":"1.168219389","rc":[{"batb":[[1,1.04,555.26],[2,1.01,10.51]],"batl":[[0,1.09,80],[1,1.11,42.01]],"ltp":1.09,"tv":5774.3,"id":8535963},{"batb":[[2,1.01,10.52]],"ltp":2.38,"tv":1559.46,"id":2309796}]}]}
{"op":"mcm","clk":"1005491104","pt":1580642974815,"mc":[{"id":"1.168219389","rc":[{"batb":[[0,1.04,555.26],[1,1.01,10.51],[2,1.01,0]],"batl":[[1,1.11,0]],"ltp":1.09,"tv":5774.3,"id":8535963},{"batb":[[0,5.7,19.83],[1,1.01,10.52],[2,1.01,0]],"ltp":2.38,"tv":1559.46,"id":2309796}]}]}
{"op":"mcm","clk":"1005491388","pt":1580642976513,"mc":[{"id":"1.168219389","rc":[{"batb":[[0,1.05,321.33],[1,1.04,1486.59],[2,1.01,10.51]],"batl":[[1,1.2,604.23],[2,1.21,480.08]],"ltp":1.09,"tv":5774.3,"id":8535963}]}]}
{"op":"mcm","clk":"1005493924","pt":1580642990521,"mc":[{"id":"1.168219389","rc":[{"batb":[[0,1.04,555.26],[1,1.01,10.51],[2,1.01,0]],"ltp":1.09,"tv":5774.3,"id":8535963},{"batb":[[1,1.01,12.36]],"ltp":2.38,"tv":1559.46,"id":2309796}]}]}
{"op":"mcm","clk":"1005494033","pt":1580642991115,"mc":[{"id":"1.168219389","rc":[{"batb":[[1,1.01,10.52]],"ltp":2.38,"tv":1559.46,"id":2309796}]}]}
{"op":"mcm","clk":"1005494555","pt":1580642993766,"mc":[{"id":"1.168219389","rc":[{"trd":[[1.09,175.15]],"batb":[[0,1.17,684.43],[1,1.16,494.89],[2,1.1,245.33]],"batl":[[0,1.19,42.01]],"ltp":1.09,"tv":5934.3,"id":8535963},{"batb":[[0,6.2,7.56],[1,5.7,19.83],[2,3.75,13.3]],"ltp":2.38,"tv":1559.46,"id":2309796}],"tv":7493.77}]}
{"op":"mcm","clk":"1005494688","pt":1580642994501,"mc":[{"id":"1.168219389","rc":[{"trd":[[1.17,1.01]],"batb":[[0,1.17,683.42]],"ltp":1.17,"tv":5935.31,"id":8535963},{"trd":[[7,0.17]],"ltp":7.0,"tv":1559.63,"id":2309796}],"tv":7494.94}]}
{"op":"mcm","clk":"1005494868","pt":1580642995468,"mc":[{"id":"1.168219389","rc":[{"batb":[[2,1.11,684.32]],"ltp":1.17,"tv":5935.31,"id":8535963}]}]}
{"op":"mcm","clk":"1005495095","pt":1580642996594,"mc":[{"id":"1.168219389","rc":[{"batb":[[0,1.17,736.12]],"ltp":1.17,"tv":5935.31,"id":8535963}]}]}
{"op":"mcm","clk":"1005496667","pt":1580643004498,"mc":[{"id":"1.168219389","rc":[{"batb":[[0,1.17,138.87],[1,1.11,684.32],[2,1.1,245.33]],"batl":[[1,1.2,0],[2,1.21,0]],"ltp":1.17,"tv":5935.31,"id":8535963}]}]}
{"op":"mcm","clk":"1005496887","pt":1580643005484,"mc":[{"id":"1.168219389","rc":[{"batb":[[0,1.11,684.32],[1,1.1,245.33],[2,1.01,10.51]],"ltp":1.17,"tv":5935.31,"id":8535963},{"batb":[[0,3.75,13.3],[1,3,380.84],[2,1.01,10.52]],"ltp":7.0,"tv":1559.63,"id":2309796}]}]}
{"op":"mcm","clk":"1005497271","pt":1580643007493,"mc":[{"id":"1.168219389","rc":[{"batb":[[1,1.1,1246.68],[2,1.09,187.61]],"batl":[[0,1.35,303.04],[1,1.36,261.98]],"ltp":1.17,"tv":5935.31,"id":8535963}]}]}
{"op":"mcm","clk":"1005497732","pt":1580643009912,"mc":[{"id":"1.168219389","rc":[{"batb":[[1,1.1,245.33],[2,1.01,10.51]],"ltp":1.17,"tv":5935.31,"id":8535963}]}]}
{"op":"mcm","clk":"1005498293","pt":1580643012686,"mc":[{"id":"1.168219389","rc":[{"batb":[[0,1.1,245.33],[1,1.01,10.51],[2,1.01,0]],"ltp":1.17,"tv":5935.31,"id":8535963},{"batb":[[1,1.01,10.52],[2,1.01,0]],"ltp":7.0,"tv":1559.63,"id":2309796}]}]}
{"op":"mcm","clk":"1005498488","pt":1580643013708,"mc":[{"id":"1.168219389","rc":[{"batb":[[0,1.31,474.91],[1,1.3,344.74],[2,1.28,149.55]],"batl":[[0,1.34,42.01],[1,1.35,303.04],[2,1.36,261.98]],"ltp":1.17,"tv":5935.31,"id":8535963},{"batb":[[0,3.95,13.44],[1,3.75,13.3],[2,2.74,11.64]],"batl":[[0,4.6,10.92]],"ltp":7.0,"tv":1559.63,"id":2309796}]}]}
{"op":"mcm","clk":"1005498562","pt":1580643014393,"mc":[{"id":"1.168219389","rc":[{"batb":[[2,1.21,110.23]],"ltp":1.17,"tv":5935.31,"id":8535963}]}]}
{"op":"mcm","clk":"1005498821","pt":1580643015427,"mc":[{"id":"1.168219389","rc":[{"batb":[[2,1.27,155.44]],"ltp":1.17,"tv":5935.31,"id":8535963}]}]}
{"op":"mcm","clk":"1005499032","pt":1580643016651,"mc":[{"id":"1.168219389","rc":[{"batb":[[2,1.21,110.23]],"ltp":1.17,"tv":5935.31,"id":8535963}]}]}
{"op":"mcm","clk":"1005499248","pt":1580643017835,"mc":[{"id":"1.168219389","rc":[{"batb":[[2,1.28,149.55]],"ltp":1.17,"tv":5935.31,"id":8535963}]}]}
{"op":"mcm","clk":"1005500722","pt":1580643025638,"mc":[{"id":"1.168219389","rc":[{"trd":[[1.34,42.01],[1.35,303.04]],"batb":[[0,1.31,395.1],[1,1.21,110.23],[2,1.2,530.86]],"batl":[[0,1.36,261.98],[1,1.35,0],[2,1.36,0]],"ltp":1.35,"tv":6280.36,"id":8535963},{"trd":[[3.85,122.76],[3.9,14.43],[3.95,26.88]],"batb":[[0,3.75,13.3],[1,2.74,11.64],[2,2.52,381.46]],"batl":[[0,3.85,15.87]],"ltp":3.85,"tv":1707.2,"id":2309796}],"tv":7987.57}]}
{"op":"mcm","clk":"1005500921","pt":1580643026645,"mc":[{"id":"1.168219389","rc":[{"batb":[[0,1.31,69.55]],"ltp":1.35,"tv":6280.36,"id":8535963}]}]}
{"op":"mcm","clk":"1005500972","pt":1580643027028,"mc":[{"id":"1.168219389","rc":[{"batb":[[0,1.21,110.23],[1,1.2,530.86],[2,1.01,10.51]],"ltp":1.35,"tv":6280.36,"id":8535963},{"batb":[[0,2.74,11.64],[1,2.52,381.46],[2,1.01,10.52]],"ltp":3.85,"tv":1707.2,"id":2309796}]}]}
{"op":"mcm","clk":"1005501324","pt":1580643028765,"mc":[{"id":"1.168219389","rc":[{"trd":[[1.35,307.58]],"ltp":1.35,"tv":6284.9,"id":8535963},{"trd":[[3.85,152.91]],"ltp":3.85,"tv":1737.36,"id":2309796}],"tv":8022.26}]}
{"op":"mcm","clk":"1005501475","pt":1580643029439,"mc":[{"id":"1.168219389","rc":[{"batb":[[0,1.22,178.95],[1,1.21,629.56],[2,1.2,530.86]],"batl":[[0,1.58,200.73],[1,1.59,138.9]],"ltp":1.35,"tv":6284.9,"id":8535963}]}]}
{"op":"mcm","clk":"1005506754","pt":1580643058949,"mc":[{"id":"1.168219389","rc":[{"trd":[[2.74,23.28]],"batb":[[0,2.52,381.46],[1,1.01,10.52],[2,1.01,0]],"batl":[[0,2.74,88.36]],"ltp":2.74,"tv":1760.64,"id":2309796}],"tv":8045.54}]}
{"op":"mcm","clk":"1005507739","pt":1580643063940,"mc":[{"id":"1.168219389","rc":[{"trd":[[1.57,37.86]],"ltp":1.57,"tv":6322.76,"id":8535963},{"trd":[[2.74,44.97]],"batl":[[0,2.74,66.67]],"ltp":2.74,"tv":1782.33,"id":2309796}],"tv":8105.09}]}
{"op":"mcm","clk":"1005508619","pt":1580643068672,"mc":[{"id":"1.168219389","rc":[{"trd":[[1.57,154.21]],"batb":[[2,1.01,10.51]],"batl":[[0,1.24,89.06],[1,1.25,406.27]],"ltp":1.57,"tv":6439.11,"id":8535963},{"trd":[[2.74,111.64]],"batb":[[0,1.01,10.52],[1,1.01,0]],"ltp":2.74,"tv":1849.0,"id":2309796}],"tv":8288.11}]}
{"op":"mcm","clk":"1005508818","pt":1580643069739,"mc":[{"id":"1.168219389","rc":[{"batb":[[1,1.21,628.3],[2,1.11,214.09]],"batl":[[0,1.25,406.27],[1,1.25,0]],"ltp":1.57,"tv":6439.11,"id":8535963},{"batb":[[0,4.9,14.08],[1,3.1,20.77],[2,1.01,10.52]],"ltp":2.74,"tv":1849.0,"id":2309796}]}]}
{"op":"mcm","clk":"1005508916","pt":1580643070285,"mc":[{"id":"1.168219389","rc":[{"batl":[[0,5.9,8.4]],"ltp":2.74,"tv":1849.0,"id":2309796}]}]}
{"op":"mcm","clk":"1005509312","pt":1580643072463,"mc":[{"id":"1.168219389","rc":[{"batb":[[0,1.22,233.44],[2,1.13,629.97]],"batl":[[0,1.25,600.1],[1,1.26,378.23]],"ltp":1.57,"tv":6439.11,"id":8535963},{"batb":[[0,5,10.08],[1,4.9,14.08],[2,3.1,20.77]],"ltp":2.74,"tv":1849.0,"id":2309796}]}]}
{"op":"mcm","clk":"1005512874","pt":1580643091418,"mc":[{"id":"1.168219389","rc":[{"batb":[[0,1.13,629.97],[1,1.11,214.09],[2,1.01,10.51]],"batl":[[0,1.25,42.01],[1,1.26,0]],"ltp":1.57,"tv":6439.11,"id":8535963},{"batb":[[1,3.1,20.77],[2,2.9,375.84]],"ltp":2.74,"tv":1849.0,"id":2309796}]}]}
{"op":"mcm","clk":"1005513123","pt":1580643092593,"mc":[{"id":"1.168219389","rc":[{"batb":[[0,1.11,214.09],[1,1.01,10.51],[2,1.01,0]],"ltp":1.57,"tv":6439.11,"id":8535963},{"batb":[[2,1.01,10.52]],"ltp":2.74,"tv":1849.0,"id":2309796}]}]}
{"op":"mcm","clk":"1005513167","pt":1580643092800,"mc":[{"id":"1.168219389","rc":[{"batb":[[0,3.1,20.77],[1,1.01,10.52],[2,1.01,0]],"ltp":2.74,"tv":1849.0,"id":2309796}]}]}
{"op":"mcm","clk":"1005513447","pt":1580643094406,"mc":[{"id":"1.168219389","rc":[{"batb":[[0,1.12,542.86],[1,1.11,842.89],[2,1.01,10.51]],"ltp":1.57,"tv":6439.11,"id":8535963}]}]}
{"op":"mcm","clk":"1005514105","pt":1580643097726,"mc":[{"id":"1.168219389","rc":[{"batb":[[2,1.03,699.88]],"batl":[[0,1.14,623.77],[1,1.15,517.29]],"ltp":1.57,"tv":6439.11,"id":8535963},{"batb":[[0,7.6,9.84],[1,4,22.5],[2,3.1,20.77]],"ltp":2.74,"tv":1849.0,"id":2309796}]}]}
{"op":"mcm","clk":"1005514291","pt":1580643098620,"mc":[{"id":"1.168219389","rc":[{"batb":[[1,1.11,1010.93],[2,1.07,893.98]],"batl":[[0,1.14,665.78]],"ltp":1.57,"tv":6439.11,"id":8535963},{"batb":[[0,8,5.88],[1,7.6,9.84],[2,4,22.5]],"batl":[[0,10,4.2]],"ltp":2.74,"tv":1849.0,"id":2309796}]}]}
{"op":"mcm","clk":"1005515561","pt":1580643105514,"mc":[{"id":"1.168219389","rc":[{"batb":[[0,1.11,382.13],[1,1.07,893.98],[2,1.03,699.88]],"batl":[[0,1.14,42.01],[1,1.15,0]],"ltp":1.57,"tv":6439.11,"id":8535963}]}]}
{"op":"mcm","clk":"1005516203","pt":1580643109229,"mc":[{"id":"1.168219389","rc":[{"trd":[[1.14,3121.44]],"ltp":1.14,"tv":6483.1,"id":8535963}],"tv":8332.11}]}
{"op":"mcm","clk":"1005517302","pt":1580643114917,"mc":[{"id":"1.168219389","rc":[{"batb":[[0,1.07,893.98],[1,1.03,699.88],[2,1.01,10.51]],"ltp":1.14,"tv":6483.1,"id":8535963},{"batb":[[0,4,22.5],[1,3.35,371.23],[2,1.01,10.52]],"ltp":2.74,"tv":1849.0,"id":2309796}]}]}
{"op":"mcm","clk":"1005517465","pt":1580643115827,"mc":[{"id":"1.168219389","rc":[{"batb":[[0,1.03,699.88],[1,1.01,10.51],[2,1.01,0]],"ltp":1.14,"tv":6483.1,"id":8535963},{"batb":[[1,1.01,10.52],[2,1.01,0]],"ltp":2.74,"tv":1849.0,"id":2309796}]}]}
{"op":"mcm","clk":"1005517783","pt":1580643117865,"mc":[{"id":"1.168219389","rc":[{"batb":[[0,1.04,1138.78],[1,1.03,699.88],[2,1.01,10.51]],"batl":[[0,1.32,169.09],[1,1.33,291.28]],"ltp":1.14,"tv":6483.1,"id":8535963}]}]}
{"op":"mcm","clk":"1005519411","pt":1580643126663,"mc":[{"id":"1.168219389","rc":[{"batl":[[0,1.05,970.35],[1,1.06,270.86]],"ltp":1.14,"tv":6483.1,"id":8535963},{"batb":[[0,18,6.85],[1,7.4,10.31],[2,4,22.5]],"ltp":2.74,"tv":1849.0,"id":2309796}]}]}
{"op":"mcm","clk":"1005519476","pt":1580643126980,"mc":[{"id":"1.168219389","rc":[{"batb":[[2,1.01,10.52]],"ltp":2.74,"tv":1849.0,"id":2309796}]}]}
{"op":"mcm","clk":"1005519676","pt":1580643128195,"mc":[{"id":"1.168219389","rc":[{"batb":[[2,1.01,4076.97]],"ltp":1.14,"tv":6483.1,"id":8535963},{"batb":[[2,4.1,374.13]],"ltp":2.74,"tv":1849.0,"id":2309796}]}]}
{"op":"mcm","clk":"1005521923","pt":1580643141678,"mc":[{"id":"1.168219389","rc":[{"batb":[[0,1.03,699.88],[1,1.01,4076.97],[2,1.01,0]],"ltp":1.14,"tv":6483.1,"id":8535963}]}]}
{"op":"mcm","clk":"1005521999","pt":1580643142109,"mc":[{"id":"1.168219389","rc":[{"batb":[[0,1.01,4076.97],[1,1.01,0]],"ltp":1.14,"tv":6483.1,"id":8535963},{"batb":[[0,7.4,10.31],[1,4.1,374.13],[2,1.01,10.52]],"ltp":2.74,"tv":1849.0,"id":2309796}]}]}
{"op":"mcm","clk":"1005522225","pt":1580643143327,"mc":[{"id":"1.168219389","rc":[{"batb":[[0,1.01,10.51]],"ltp":1.14,"tv":6483.1,"id":8535963},{"batb":[[1,1.01,10.52],[2,1.01,0]],"ltp":2.74,"tv":1849.0,"id":2309796}]}]}
{"op":"mcm","clk":"1005522567","pt":1580643144666,"mc":[{"id":"1.168219389","rc":[{"batl":[[0,1.14,325],[1,1.15,720.14]],"ltp":1.14,"tv":6483.1,"id":8535963}]}]}
{"op":"mcm","clk":"1005522884","pt":1580643146302,"mc":[{"id":"1.168219389","rc":[{"batb":[[0,1.05,1243.8],[1,1.01,10.51]],"batl":[[0,1.07,1196.79]],"ltp":1.14,"tv":6483.1,"id":8535963}]}]}
{"op":"mcm","clk":"1005523257","pt":1580643148301,"mc":[{"id":"1.168219389","rc":[{"batb":[[1,1.02,2184.08],[2,1.01,10.51]],"ltp":1.14,"tv":6483.1,"id":8535963},{"batb":[[1,4,369.93],[2,1.01,10.52]],"ltp":2.74,"tv":1849.0,"id":2309796}]}]}
{"op":"mcm","clk":"1005524083","pt":1580643153013,"mc":[{"id":"1.168219389","rc":[{"batb":[[0,1.02,2184.08],[1,1.01,10.51],[2,1.01,0]],"ltp":1.14,"tv":6483.1,"id":8535963}]}]}
{"op":"mcm","clk":"1005524513","pt":1580643155492,"mc":[{"id":"1.168219389","rc":[{"batb":[[0,1.01,10.51],[1,1.01,0]],"ltp":1.14,"tv":6483.1,"id":8535963},{"batb":[[1,1.01,10.52],[2,1.01,0]],"ltp":2.74,"tv":1849.0,"id":2309796}]}]}
{"op":"mcm","clk":"1005524685","pt":1580643156502,"mc":[{"id":"1.168219389","rc":[{"batl":[[0,1.14,325],[1,1.15,720.14]],"ltp":1.14,"tv":6483.1,"id":8535963}]}]}
{"op":"mcm","clk":"1005525071","pt":1580643158497,"mc":[{"id":"1.168219389","rc":[{"batb":[[0,1.07,22],[1,1.01,10.51]],"ltp":1.14,"tv":6483.1,"id":8535963}]}]}
{"op":"mcm","clk":"1005525653","pt":1580643161764,"mc":[{"id":"1.168219389","rc":[{"batb":[[0,1.01,10.52],[1,1.01,0]],"ltp":2.74,"tv":1849.0,"id":2309796}]}]}
{"op":"mcm","clk":"1005525673","pt":1580643161777,"mc":[{"id":"1.168219389","marketDefinition":{"bspMarket":false,"turnInPlayEnabled":true,"persistenceEnabled":true,"marketBaseRate":5.0,"eventId":"29681328","eventTypeId":"2","numberOfWinners":1,"bettingType":"ODDS","marketType":"SET_WINNER","marketTime":"2020-02-02T10:45:00.000Z","suspendTime":"2020-02-02T10:45:00.000Z","bspReconciled":false,"complete":true,"inPlay":true,"crossMatching":true,"runnersVoidable":false,"numberOfActiveRunners":2,"betDelay":3,"status":"SUSPENDED","runners":[{"status":"ACTIVE","sortPriority":1,"id":8535963,"name":"Nikola Milojevic"},{"status":"ACTIVE","sortPriority":2,"id":2309796,"name":"Robin Haase"}],"regulators":["MR_INT"],"countryCode":"IN","discountAllowed":true,"timezone":"UTC","openDate":"2020-02-02T10:45:00.000Z","version":3148561716,"name":"Set 1 Winner","eventName":"Milojevic v Haase"}}]}
{"op":"mcm","clk":"1005532516","pt":1580643195672,"mc":[{"id":"1.168219389","tv":0.0}]}
{"op":"mcm","clk":"1005532622","pt":1580643196181,"mc":[{"id":"1.168219389","marketDefinition":{"bspMarket":false,"turnInPlayEnabled":true,"persistenceEnabled":true,"marketBaseRate":5.0,"eventId":"29681328","eventTypeId":"2","numberOfWinners":1,"bettingType":"ODDS","marketType":"SET_WINNER","marketTime":"2020-02-02T10:45:00.000Z","suspendTime":"2020-02-02T10:45:00.000Z","bspReconciled":false,"complete":true,"inPlay":true,"crossMatching":false,"runnersVoidable":false,"numberOfActiveRunners":0,"betDelay":3,"status":"CLOSED","settledTime":"2020-02-02T11:33:13.000Z","runners":[{"status":"WINNER","sortPriority":1,"id":8535963,"name":"Nikola Milojevic"},{"status":"LOSER","sortPriority":2,"id":2309796,"name":"Robin Haase"}],"regulators":["MR_INT"],"countryCode":"IN","discountAllowed":true,"timezone":"UTC","openDate":"2020-02-02T10:45:00.000Z","version":3148562578,"name":"Set 1 Winner","eventName":"Milojevic v Haase"}}]}
