{"op":"mcm","clk":"998176899","pt":1580569848193,"mc":[{"id":"1.168219388","marketDefinition":{"bspMarket":false,"turnInPlayEnabled":true,"persistenceEnabled":true,"marketBaseRate":5.0,"eventId":"29681328","eventTypeId":"2","numberOfWinners":1,"bettingType":"ODDS","marketType":"SET_BETTING","marketTime":"2020-02-02T11:30:00.000Z","suspendTime":"2020-02-02T11:30:00.000Z","bspReconciled":false,"complete":true,"inPlay":false,"crossMatching":false,"runnersVoidable":false,"numberOfActiveRunners":4,"betDelay":0,"status":"OPEN","runners":[{"status":"ACTIVE","sortPriority":1,"id":16586500,"name":"Milojevic 2-0"},{"status":"ACTIVE","sortPriority":2,"id":16586502,"name":"Milojevic 2-1"},{"status":"ACTIVE","sortPriority":3,"id":13508961,"name":"Haase 2-0"},{"status":"ACTIVE","sortPriority":4,"id":13508964,"name":"Haase 2-1"}],"regulators":["MR_INT"],"countryCode":"IN","discountAllowed":false,"timezone":"UTC","openDate":"2020-02-02T11:30:00.000Z","version":3145750585,"name":"Set Betting","eventName":"Milojevic v Haase"}}]}
{"op":"mcm","clk":"998177333","pt":1580569849772,"mc":[{"id":"1.168219388","marketDefinition":{"bspMarket":false,"turnInPlayEnabled":true,"persistenceEnabled":true,"marketBaseRate":5.0,"eventId":"29681328","eventTypeId":"2","numberOfWinners":1,"bettingType":"ODDS","marketType":"SET_BETTING","marketTime":"2020-02-02T11:30:00.000Z","suspendTime":"2020-02-02T11:30:00.000Z","bspReconciled":false,"complete":true,"inPlay":false,"crossMatching":false,"runnersVoidable":false,"numberOfActiveRunners":4,"betDelay":0,"status":"OPEN","runners":[{"status":"ACTIVE","sortPriority":1,"id":16586500,"name":"Milojevic 2-0"},{"status":"ACTIVE","sortPriority":2,"id":16586502,"name":"Milojevic 2-1"},{"status":"ACTIVE","sortPriority":3,"id":13508961,"name":"Haase 2-0"},{"status":"ACTIVE","sortPriority":4,"id":13508964,"name":"Haase 2-1"}],"regulators":["MR_INT"],"countryCode":"IN","discountAllowed":false,"timezone":"UTC","openDate":"2020-02-02T11:30:00.000Z","version":3145750585,"name":"Set Betting","eventName":"Milojevic v Haase"}}]}
{"op":"mcm","clk":"998177617","pt":1580569850776,"mc":[{"id":"1.168219388","marketDefinition":{"bspMarket":false,"turnInPlayEnabled":true,"persistenceEnabled":true,"marketBaseRate":5.0,"eventId":"29681328","eventTypeId":"2","numberOfWinners":1,"bettingType":"ODDS","marketType":"SET_BETTING","marketTime":"2020-02-02T11:30:00.000Z","suspendTime":"2020-02-02T11:30:00.000Z","bspReconciled":false,"complete":true,"inPlay":false,"crossMatching":false,"runnersVoidable":false,"numberOfActiveRunners":4,"betDelay":0,"status":"OPEN","runners":[{"status":"ACTIVE","sortPriority":1,"id":16586500,"name":"Milojevic 2-0"},{"status":"ACTIVE","sortPriority":2,"id":16586502,"name":"Milojevic 2-1"},{"status":"ACTIVE","sortPriority":3,"id":13508961,"name":"Haase 2-0"},{"status":"ACTIVE","sortPriority":4,"id":13508964,"name":"Haase 2-1"}],"regulators":["MR_INT"],"countryCode":"IN","discountAllowed":true,"timezone":"UTC","openDate":"2020-02-02T11:30:00.000Z","version":3145750585,"name":"Set Betting","eventName":"Milojevic v Haase"}}]}
{"op":"mcm","clk":"999097912","pt":1580573538938,"mc":[{"id":"1.168219388","rc":[{"batb":[[0,1.02,2]],"ltp":0.0,"tv":0.0,"id":13508961},{"batb":[[0,1.02,2]],"ltp":0.0,"tv":0.0,"id":16586500},{"batb":[[0,1.02,2]],"ltp":0.0,"tv":0.0,"id":13508964},{"batb":[[0,1.02,2]],"ltp":0.0,"tv":0.0,"id":16586502}]}]}
{"op":"mcm","clk":"1000453357","pt":1580581062267,"mc":[{"id":"1.168219388","rc":[{"batb":[[0,2.24,30.29],[1,1.02,2]],"ltp":0.0,"tv":0.0,"id":13508961}]}]}
{"op":"mcm","clk":"1002635957","pt":1580596406656,"mc":[{"id":"1.168219388","rc":[{"batb":[[0,1.02,2],[1,1.02,0]],"ltp":0.0,"tv":0.0,"id":13508961}]}]}
{"op":"mcm","clk":"1002649212","pt":1580596610001,"mc":[{"id":"1.168219388","rc":[{"batb":[[0,2.24,30.29],[1,1.02,2]],"ltp":0.0,"tv":0.0,"id":13508961}]}]}
{"op":"mcm","clk":"1003058632","pt":1580602468618,"mc":[{"id":"1.168219388","rc":[{"batb":[[2,1.01,0.51]],"ltp":0.0,"tv":0.0,"id":13508961},{"batb":[[1,1.01,0.51]],"ltp":0.0,"tv":0.0,"id":16586500},{"batb":[[1,1.01,0.51]],"ltp":0.0,"tv":0.0,"id":13508964},{"batb":[[1,1.01,0.51]],"ltp":0.0,"tv":0.0,"id":16586502}]}]}
{"op":"mcm","clk":"1003180254","pt":1580604002817,"mc":[{"id":"1.168219388","rc":[{"batb":[[2,1.01,1.01]],"ltp":0.0,"tv":0.0,"id":13508961},{"batb":[[1,1.01,1.01]],"ltp":0.0,"tv":0.0,"id":16586500},{"batb":[[1,1.01,1.01]],"ltp":0.0,"tv":0.0,"id":13508964},{"batb":[[1,1.01,1.01]],"ltp":0.0,"tv":0.0,"id":16586502}]}]}
{"op":"mcm","clk":"1004704063","pt":1580635607319,"mc":[{"id":"1.168219388","marketDefinition":{"bspMarket":false,"turnInPlayEnabled":true,"persistenceEnabled":true,"marketBaseRate":5.0,"eventId":"29681328","eventTypeId":"2","numberOfWinners":1,"bettingType":"ODDS","marketType":"SET_BETTING","marketTime":"2020-02-02T11:23:00.000Z","suspendTime":"2020-02-02T11:23:00.000Z","bspReconciled":false,"complete":true,"inPlay":false,"crossMatching":false,"runnersVoidable":false,"numberOfActiveRunners":4,"betDelay":0,"status":"OPEN","runners":[{"status":"ACTIVE","sortPriority":1,"id":16586500,"name":"Milojevic 2-0"},{"status":"ACTIVE","sortPriority":2,"id":16586502,"name":"Milojevic 2-1"},{"status":"ACTIVE","sortPriority":3,"id":13508961,"name":"Haase 2-0"},{"status":"ACTIVE","sortPriority":4,"id":13508964,"name":"Haase 2-1"}],"regulators":["MR_INT"],"countryCode":"IN","discountAllowed":true,"timezone":"UTC","openDate":"2020-02-02T11:30:00.000Z","version":3148345183,"name":"Set Betting","eventName":"Milojevic v Haase"}}]}
{"op":"mcm","clk":"1004704272","pt":1580635610363,"mc":[{"id":"1.168219388","marketDefinition":{"bspMarket":false,"turnInPlayEnabled":true,"persistenceEnabled":true,"marketBaseRate":5.0,"eventId":"29681328","eventTypeId":"2","numberOfWinners":1,"bettingType":"ODDS","marketType":"SET_BETTING","marketTime":"2020-02-02T11:23:00.000Z","suspendTime":"2020-02-02T11:23:00.000Z","bspReconciled":false,"complete":true,"inPlay":false,"crossMatching":false,"runnersVoidable":false,"numberOfActiveRunners":4,"betDelay":0,"status":"OPEN","runners":[{"status":"ACTIVE","sortPriority":1,"id":16586500,"name":"Milojevic 2-0"},{"status":"ACTIVE","sortPriority":2,"id":16586502,"name":"Milojevic 2-1"},{"status":"ACTIVE","sortPriority":3,"id":13508961,"name":"Haase 2-0"},{"status":"ACTIVE","sortPriority":4,"id":13508964,"name":"Haase 2-1"}],"regulators":["MR_INT"],"countryCode":"IN","discountAllowed":true,"timezone":"UTC","openDate":"2020-02-02T11:23:00.000Z","version":3148345183,"name":"Set Betting","eventName":"Milojevic v Haase"}}]}
{"op":"mcm","clk":"1004873395","pt":1580638601679,"mc":[{"id":"1.168219388","rc":[{"batb":[[0,1.02,2],[1,1.01,1.01],[2,1.01,0]],"ltp":0.0,"tv":0.0,"id":13508961}]}]}
{"op":"mcm","clk":"1005053389","pt":1580640381602,"mc":[{"id":"1.168219388","rc":[{"batb":[[0,2.78,11.25],[1,1.02,2],[2,1.01,1.01]],"batl":[[0,3.05,11.09]],"ltp":0.0,"tv":0.0,"id":13508961},{"batb":[[0,3.65,14.08],[1,1.02,2],[2,1.01,1.01]],"batl":[[0,4.1,13.61]],"ltp":0.0,"tv":0.0,"id":16586500},{"batb":[[0,4.4,18.18],[1,1.02,2],[2,1.01,1.01]],"batl":[[0,5.1,17.31]],"ltp":0.0,"tv":0.0,"id":13508964},{"batb":[[0,5,13.06],[1,1.02,2],[2,1.01,1.01]],"batl":[[0,5.9,12.51]],"ltp":0.0,"tv":0.0,"id":16586502}]}]}
{"op":"mcm","clk":"1005056582","pt":1580640406412,"mc":[{"id":"1.168219388","marketDefinition":{"bspMarket":false,"turnInPlayEnabled":true,"persistenceEnabled":true,"marketBaseRate":5.0,"eventId":"29681328","eventTypeId":"2","numberOfWinners":1,"bettingType":"ODDS","marketType":"SET_BETTING","marketTime":"2020-02-02T10:45:00.000Z","suspendTime":"2020-02-02T10:45:00.000Z","bspReconciled":false,"complete":true,"inPlay":false,"crossMatching":false,"runnersVoidable":false,"numberOfActiveRunners":4,"betDelay":0,"status":"OPEN","runners":[{"status":"ACTIVE","sortPriority":1,"id":16586500,"name":"Milojevic 2-0"},{"status":"ACTIVE","sortPriority":2,"id":16586502,"name":"Milojevic 2-1"},{"status":"ACTIVE","sortPriority":3,"id":13508961,"name":"Haase 2-0"},{"status":"ACTIVE","sortPriority":4,"id":13508964,"name":"Haase 2-1"}],"regulators":["MR_INT"],"countryCode":"IN","discountAllowed":true,"timezone":"UTC","openDate":"2020-02-02T11:23:00.000Z","version":3148437219,"name":"Set Betting","eventName":"Milojevic v Haase"}}]}
{"op":"mcm","clk":"1005058517","pt":1580640420442,"mc":[{"id":"1.168219388","marketDefinition":{"bspMarket":false,"turnInPlayEnabled":true,"persistenceEnabled":true,"marketBaseRate":5.0,"eventId":"29681328","eventTypeId":"2","numberOfWinners":1,"bettingType":"ODDS","marketType":"SET_BETTING","marketTime":"2020-02-02T10:45:00.000Z","suspendTime":"2020-02-02T10:45:00.000Z","bspReconciled":false,"complete":true,"inPlay":false,"crossMatching":false,"runnersVoidable":false,"numberOfActiveRunners":4,"betDelay":0,"status":"OPEN","runners":[{"status":"ACTIVE","sortPriority":1,"id":16586500,"name":"Milojevic 2-0"},{"status":"ACTIVE","sortPriority":2,"id":16586502,"name":"Milojevic 2-1"},{"status":"ACTIVE","sortPriority":3,"id":13508961,"name":"Haase 2-0"},{"status":"ACTIVE","sortPriority":4,"id":13508964,"name":"Haase 2-1"}],"regulators":["MR_INT"],"countryCode":"IN","discountAllowed":true,"timezone":"UTC","openDate":"2020-02-02T10:45:00.000Z","version":3148437219,"name":"Set Betting","eventName":"Milojevic v Haase"}}]}
{"op":"mcm","clk":"1005094206","pt":1580640705750,"mc":[{"id":"1.168219388","rc":[{"batb":[[1,4.3,18.25],[2,1.02,2]],"ltp":0.0,"tv":0.0,"id":13508964}]}]}
{"op":"mcm","clk":"1005094229","pt":1580640705960,"mc":[{"id":"1.168219388","rc":[{"batb":[[0,4.3,18.25],[1,1.02,2],[2,1.01,1.01]],"ltp":0.0,"tv":0.0,"id":13508964}]}]}
{"op":"mcm","clk":"1005106695","pt":1580640813138,"mc":[{"id":"1.168219388","rc":[{"batb":[[1,2.74,23.53],[2,1.02,2]],"batl":[[1,3.1,19.32]],"ltp":0.0,"tv":0.0,"id":13508961},{"batb":[[0,3.65,29.21]],"batl":[[1,4.3,12.6]],"ltp":0.0,"tv":0.0,"id":16586500},{"batb":[[0,4.3,30.86]],"batl":[[0,5.1,27.39]],"ltp":0.0,"tv":0.0,"id":13508964},{"batb":[[1,4.8,10.92],[2,1.02,2]],"batl":[[0,5.9,20.91]],"ltp":0.0,"tv":0.0,"id":16586502}]}]}
{"op":"mcm","clk":"1005107684","pt":1580640821343,"mc":[{"id":"1.168219388","marketDefinition":{"bspMarket":false,"turnInPlayEnabled":true,"persistenceEnabled":true,"marketBaseRate":5.0,"eventId":"29681328","eventTypeId":"2","numberOfWinners":1,"bettingType":"ODDS","marketType":"SET_BETTING","marketTime":"2020-02-02T10:45:00.000Z","suspendTime":"2020-02-02T10:45:00.000Z","bspReconciled":false,"complete":true,"inPlay":false,"crossMatching":true,"runnersVoidable":false,"numberOfActiveRunners":4,"betDelay":0,"status":"OPEN","runners":[{"status":"ACTIVE","sortPriority":1,"id":16586500,"name":"Milojevic 2-0"},{"status":"ACTIVE","sortPriority":2,"id":16586502,"name":"Milojevic 2-1"},{"status":"ACTIVE","sortPriority":3,"id":13508961,"name":"Haase 2-0"},{"status":"ACTIVE","sortPriority":4,"id":13508964,"name":"Haase 2-1"}],"regulators":["MR_INT"],"countryCode":"IN","discountAllowed":true,"timezone":"UTC","openDate":"2020-02-02T10:45:00.000Z","version":3148437219,"name":"Set Betting","eventName":"Milojevic v Haase"}}]}
{"op":"mcm","clk":"1005134252","pt":1580641036391,"mc":[{"id":"1.168219388","rc":[{"batb":[[0,2.8,11.09]],"batl":[[0,3.05,10.94]],"ltp":0.0,"tv":0.0,"id":13508961},{"batb":[[0,3.65,15.12],[1,3.6,14.32],[2,1.02,2]],"ltp":0.0,"tv":0.0,"id":16586500},{"batb":[[0,4.4,17.94],[1,4.3,12.6],[2,1.02,2]],"batl":[[0,5.1,27.16]],"ltp":0.0,"tv":0.0,"id":13508964},{"batl":[[0,5.8,12.75],[1,5.9,8.4]],"ltp":0.0,"tv":0.0,"id":16586502}]}]}
{"op":"mcm","clk":"1005137469","pt":1580641060220,"mc":[{"id":"1.168219388","rc":[{"batb":[[0,2.74,23.53],[1,1.02,2],[2,1.01,1.01]],"batl":[[0,3.1,19.32],[1,3.1,0]],"ltp":0.0,"tv":0.0,"id":13508961},{"batb":[[1,1.02,2],[2,1.01,1.01]],"batl":[[0,4.3,12.6],[1,4.3,0]],"ltp":0.0,"tv":0.0,"id":16586500},{"batb":[[0,4.3,12.6],[1,1.02,2],[2,1.01,1.01]],"batl":[[0,5.1,10.08]],"ltp":0.0,"tv":0.0,"id":13508964},{"batb":[[0,4.8,10.92],[1,1.02,2],[2,1.01,1.01]],"batl":[[0,5.9,8.4],[1,5.9,0]],"ltp":0.0,"tv":0.0,"id":16586502}]}]}
{"op":"mcm","clk":"1005137575","pt":1580641060914,"mc":[{"id":"1.168219388","marketDefinition":{"bspMarket":false,"turnInPlayEnabled":true,"persistenceEnabled":true,"marketBaseRate":5.0,"eventId":"29681328","eventTypeId":"2","numberOfWinners":1,"bettingType":"ODDS","marketType":"SET_BETTING","marketTime":"2020-02-02T10:45:00.000Z","suspendTime":"2020-02-02T10:45:00.000Z","bspReconciled":false,"complete":true,"inPlay":true,"crossMatching":true,"runnersVoidable":false,"numberOfActiveRunners":4,"betDelay":3,"status":"OPEN","runners":[{"status":"ACTIVE","sortPriority":1,"id":16586500,"name":"Milojevic 2-0"},{"status":"ACTIVE","sortPriority":2,"id":16586502,"name":"Milojevic 2-1"},{"status":"ACTIVE","sortPriority":3,"id":13508961,"name":"Haase 2-0"},{"status":"ACTIVE","sortPriority":4,"id":13508964,"name":"Haase 2-1"}],"regulators":["MR_INT"],"countryCode":"IN","discountAllowed":true,"timezone":"UTC","openDate":"2020-02-02T10:45:00.000Z","version":3148446542,"name":"Set Betting","eventName":"Milojevic v Haase"},"rc":[{"batb":[[0,1.01,0.51],[1,1.02,0],[2,1.01,0]],"ltp":0.0,"tv":0.0,"id":13508961},{"batb":[[0,1.01,0.51],[1,1.02,0],[2,1.01,0]],"ltp":0.0,"tv":0.0,"id":16586500},{"batb":[[0,1.01,0.51],[1,1.02,0],[2,1.01,0]],"ltp":0.0,"tv":0.0,"id":13508964},{"batb":[[0,1.01,0.51],[1,1.02,0],[2,1.01,0]],"ltp":0.0,"tv":0.0,"id":16586502}]}]}
{"op":"mcm","clk":"1005138919","pt":1580641072720,"mc":[{"id":"1.168219388","rc":[{"batb":[[0,2.5,27.73],[1,1.01,0.51]],"batl":[[0,2.88,21.85]],"ltp":0.0,"tv":0.0,"id":13508961},{"batb":[[0,4,13.44],[1,1.01,0.51]],"batl":[[0,4.9,10.08]],"ltp":0.0,"tv":0.0,"id":16586500},{"batb":[[0,4.3,12.6],[1,1.01,0.51]],"batl":[[0,5.2,9.24]],"ltp":0.0,"tv":0.0,"id":13508964},{"batb":[[0,4.8,10.92],[1,1.01,0.51]],"batl":[[0,5.9,8.4]],"ltp":0.0,"tv":0.0,"id":16586502}]}]}
{"op":"mcm","clk":"1005139029","pt":1580641073507,"mc":[{"id":"1.168219388","rc":[{"batb":[[0,2.54,14.32],[1,2.5,27.73],[2,2.28,19.28]],"batl":[[0,2.76,14.01],[1,2.88,21.85],[2,2.96,11.72]],"ltp":0.0,"tv":0.0,"id":13508961},{"batb":[[0,4.1,21.4],[1,4,13.44],[2,3.75,13.14]],"batl":[[0,4.7,20.3],[1,4.9,10.08],[2,5.7,13.45]],"ltp":0.0,"tv":0.0,"id":16586500},{"batb":[[0,4.4,17.86],[1,4.3,12.6],[2,1.01,0.51]],"batl":[[0,5.2,25.84],[1,5.3,15.66]],"ltp":0.0,"tv":0.0,"id":13508964},{"batb":[[0,5,13.3],[1,4.8,10.92],[2,1.01,0.51]],"batl":[[0,5.9,20.99]],"ltp":0.0,"tv":0.0,"id":16586502}]}]}
{"op":"mcm","clk":"1005140661","pt":1580641086732,"mc":[{"id":"1.168219388","rc":[{"batb":[[0,2.5,27.73],[1,2.28,19.28],[2,1.01,0.51]],"batl":[[0,2.88,21.85],[1,2.96,11.72],[2,2.96,0]],"ltp":0.0,"tv":0.0,"id":13508961},{"batb":[[0,4,13.44],[1,3.75,13.14],[2,1.01,0.51]],"batl":[[0,4.9,10.08],[1,5.7,13.45],[2,5.7,0]],"ltp":0.0,"tv":0.0,"id":16586500},{"batl":[[0,5.2,9.24]],"ltp":0.0,"tv":0.0,"id":13508964}]}]}
{"op":"mcm","clk":"1005140772","pt":1580641087625,"mc":[{"id":"1.168219388","rc":[{"batb":[[0,2.28,19.28],[1,1.01,0.51],[2,1.01,0]],"batl":[[0,2.96,11.72],[1,2.96,0]],"ltp":0.0,"tv":0.0,"id":13508961},{"batb":[[0,3.75,13.14],[1,1.01,0.51],[2,1.01,0]],"batl":[[0,5.7,13.45],[1,5.7,0]],"ltp":0.0,"tv":0.0,"id":16586500},{"batb":[[1,1.01,0.51],[2,1.01,0]],"batl":[[0,5.3,15.66],[1,5.3,0]],"ltp":0.0,"tv":0.0,"id":13508964},{"batb":[[1,1.01,0.51],[2,1.01,0]],"batl":[[0,5.9,12.59]],"ltp":0.0,"tv":0.0,"id":16586502}]}]}
{"op":"mcm","clk":"1005140994","pt":1580641089343,"mc":[{"id":"1.168219388","rc":[{"batl":[[0,2.74,148.61],[1,2.96,11.72]],"ltp":0.0,"tv":0.0,"id":13508961}]}]}
{"op":"mcm","clk":"1005141267","pt":1580641091332,"mc":[{"id":"1.168219388","rc":[{"batb":[[0,2.38,54.53],[1,2.34,84.04],[2,2.28,19.28]],"ltp":0.0,"tv":0.0,"id":13508961},{"batb":[[0,3.8,40.16],[1,3.75,44.69],[2,1.01,0.51]],"ltp":0.0,"tv":0.0,"id":16586500},{"batb":[[0,4.4,74.43],[1,4.3,44.89],[2,1.01,0.51]],"ltp":0.0,"tv":0.0,"id":13508964},{"batb":[[0,5,59.32],[1,4.9,33.37],[2,1.01,0.51]],"ltp":0.0,"tv":0.0,"id":16586502}]}]}
{"op":"mcm","clk":"1005142102","pt":1580641098016,"mc":[{"id":"1.168219388","rc":[{"batb":[[0,2.28,19.28],[1,1.01,0.51],[2,2.28,0]],"batl":[[0,2.96,11.72],[1,2.96,0]],"ltp":0.0,"tv":0.0,"id":13508961}]}]}
{"op":"mcm","clk":"1005142554","pt":1580641101647,"mc":[{"id":"1.168219388","rc":[{"batb":[[0,2.86,50.21],[1,2.82,51.13],[2,2.72,11.96]],"batl":[[1,3.25,24]],"ltp":0.0,"tv":0.0,"id":13508961},{"batb":[[2,3.45,16.13]],"batl":[[0,4.3,25.49],[1,5,17.7]],"ltp":0.0,"tv":0.0,"id":16586500},{"batb":[[1,4.3,63.3]],"batl":[[0,5.1,17],[1,5.2,16.13]],"ltp":0.0,"tv":0.0,"id":13508964},{"batl":[[0,5.8,12.75]],"ltp":0.0,"tv":0.0,"id":16586502}]}]}
{"op":"mcm","clk":"1005142678","pt":1580641102636,"mc":[{"id":"1.168219388","rc":[{"batl":[[1,3.05,20.16],[2,3.25,24]],"ltp":0.0,"tv":0.0,"id":13508961},{"batb":[[1,3.75,59.81]],"batl":[[1,4.4,11.76],[2,5,17.7]],"ltp":0.0,"tv":0.0,"id":16586500},{"batb":[[2,4.2,12.6]],"batl":[[0,5.1,27.08]],"ltp":0.0,"tv":0.0,"id":13508964},{"batb":[[2,4.8,10.92]],"batl":[[1,5.9,8.4]],"ltp":0.0,"tv":0.0,"id":16586502}]}]}
{"op":"mcm","clk":"1005144510","pt":1580641116685,"mc":[{"id":"1.168219388","rc":[{"batb":[[0,2.64,25.21],[1,2.44,15.89],[2,1.01,0.51]],"batl":[[0,3.05,20.16],[1,3.25,24],[2,3.25,0]],"ltp":0.0,"tv":0.0,"id":13508961},{"batb":[[0,3.75,15.12],[1,3.45,16.13],[2,1.01,0.51]],"batl":[[0,4.4,11.76],[1,5,17.7],[2,5,0]],"ltp":0.0,"tv":0.0,"id":16586500},{"batb":[[0,4.4,37.74]],"batl":[[0,5.1,10.08]],"ltp":0.0,"tv":0.0,"id":13508964}]}]}
{"op":"mcm","clk":"1005144651","pt":1580641117731,"mc":[{"id":"1.168219388","rc":[{"batb":[[0,2.44,15.89],[1,1.01,0.51],[2,1.01,0]],"batl":[[0,3.25,24],[1,3.25,0]],"ltp":0.0,"tv":0.0,"id":13508961},{"batb":[[0,3.45,16.13],[1,1.01,0.51],[2,1.01,0]],"batl":[[0,5,17.7],[1,5,0]],"ltp":0.0,"tv":0.0,"id":16586500},{"batb":[[2,1.01,0.51]],"batl":[[0,5.2,16.13],[1,5.2,0]],"ltp":0.0,"tv":0.0,"id":13508964},{"batb":[[2,1.01,0.51]],"batl":[[1,5.9,0]],"ltp":0.0,"tv":0.0,"id":16586502}]}]}
{"op":"mcm","clk":"1005145009","pt":1580641120298,"mc":[{"id":"1.168219388","rc":[{"batb":[[0,2.8,42.53],[1,2.76,54.1],[2,2.44,15.89]],"ltp":0.0,"tv":0.0,"id":13508961},{"batb":[[0,3.9,45.22],[1,3.85,29.59],[2,3.45,16.13]],"ltp":0.0,"tv":0.0,"id":16586500},{"batb":[[0,4.4,62.71]],"ltp":0.0,"tv":0.0,"id":13508964}]}]}
{"op":"mcm","clk":"1005145506","pt":1580641123999,"mc":[{"id":"1.168219388","rc":[{"batb":[[0,2.44,15.89],[1,1.01,0.51],[2,2.44,0]],"ltp":0.0,"tv":0.0,"id":13508961},{"batb":[[0,3.45,16.13],[1,1.01,0.51],[2,3.45,0]],"ltp":0.0,"tv":0.0,"id":16586500},{"batb":[[0,4.4,37.74]],"ltp":0.0,"tv":0.0,"id":13508964}]}]}
{"op":"mcm","clk":"1005145829","pt":1580641126696,"mc":[{"id":"1.168219388","rc":[{"batb":[[0,2.56,50.22],[1,2.52,68.7],[2,2.44,15.89]],"ltp":0.0,"tv":0.0,"id":13508961},{"batb":[[0,3.5,50.11],[1,3.45,54.61],[2,1.01,0.51]],"ltp":0.0,"tv":0.0,"id":16586500}]}]}
{"op":"mcm","clk":"1005146424","pt":1580641131430,"mc":[{"id":"1.168219388","rc":[{"batb":[[0,2.44,15.89],[1,1.01,0.51],[2,2.44,0]],"ltp":0.0,"tv":0.0,"id":13508961}]}]}
{"op":"mcm","clk":"1005146851","pt":1580641134715,"mc":[{"id":"1.168219388","rc":[{"batb":[[0,3.05,74.78],[1,3,54.18],[2,2.8,22.69]],"batl":[[0,3.25,42.48]],"ltp":0.0,"tv":0.0,"id":13508961},{"batb":[[0,3.5,66.91]],"batl":[[0,4.1,13.44],[1,5,17.7]],"ltp":0.0,"tv":0.0,"id":16586500},{"batb":[[2,4.2,12.6]],"batl":[[0,5.1,10.08],[1,5.2,16.13]],"ltp":0.0,"tv":0.0,"id":13508964},{"batb":[[2,4.8,10.92]],"batl":[[0,5.8,21.15]],"ltp":0.0,"tv":0.0,"id":16586502}]}]}
{"op":"mcm","clk":"1005146977","pt":1580641135506,"mc":[{"id":"1.168219388","rc":[{"batb":[[2,2.9,25.02]],"batl":[[1,3.45,20.46]],"ltp":0.0,"tv":0.0,"id":13508961},{"batb":[[2,3.25,18.73]],"batl":[[0,3.9,15.58],[1,4.1,13.44],[2,4.4,23.37]],"ltp":0.0,"tv":0.0,"id":16586500},{"batl":[[0,5.1,26.92],[1,5.2,0]],"ltp":0.0,"tv":0.0,"id":13508964},{"batl":[[0,5.8,8.4],[1,5.9,12.59]],"ltp":0.0,"tv":0.0,"id":16586502}]}]}
{"op":"mcm","clk":"1005147804","pt":1580641141646,"mc":[{"id":"1.168219388","rc":[{"batb":[[0,3.05,33.35]],"ltp":0.0,"tv":0.0,"id":13508961},{"batb":[[0,3.5,54.31],[1,3.45,16.13]],"ltp":0.0,"tv":0.0,"id":16586500},{"batb":[[0,4.3,63.3],[1,4.2,12.6],[2,1.01,0.51]],"ltp":0.0,"tv":0.0,"id":13508964},{"batb":[[0,5,45.77],[1,4.8,10.92],[2,1.01,0.51]],"ltp":0.0,"tv":0.0,"id":16586502}]}]}
{"op":"mcm","clk":"1005148262","pt":1580641144656,"mc":[{"id":"1.168219388","rc":[{"batb":[[0,3.55,51.55],[1,3.5,54.31],[2,3.45,16.13]],"ltp":0.0,"tv":0.0,"id":16586500},{"batb":[[0,4.3,76.56],[1,4.2,59.55]],"ltp":0.0,"tv":0.0,"id":13508964},{"batb":[[0,5.1,32.15],[1,5,45.77],[2,4.8,10.92]],"ltp":0.0,"tv":0.0,"id":16586502}]}]}
{"op":"mcm","clk":"1005149077","pt":1580641149730,"mc":[{"id":"1.168219388","rc":[{"batb":[[0,2.64,12.75],[1,1.01,0.51],[2,2.9,0]],"batl":[[0,3.45,20.46],[1,3.45,0]],"ltp":0.0,"tv":0.0,"id":13508961},{"batb":[[0,3.25,18.73],[1,1.01,0.51],[2,3.45,0]],"batl":[[0,4.4,23.37],[1,4.1,0],[2,4.4,0]],"ltp":0.0,"tv":0.0,"id":16586500},{"batb":[[0,4.3,18.41],[1,1.01,0.51],[2,1.01,0]],"batl":[[0,5.1,16.84]],"ltp":0.0,"tv":0.0,"id":13508964},{"batb":[[0,5,13.3],[1,1.01,0.51],[2,4.8,0]],"batl":[[0,5.9,12.59],[1,5.9,0]],"ltp":0.0,"tv":0.0,"id":16586502}]}]}
{"op":"mcm","clk":"1005149467","pt":1580641152707,"mc":[{"id":"1.168219388","rc":[{"batb":[[0,2.76,52.96],[1,2.72,55.76],[2,2.64,12.75]],"ltp":0.0,"tv":0.0,"id":13508961},{"batb":[[0,3.35,52.93],[1,3.3,43.29],[2,3.25,18.41]],"batl":[[0,4.5,22.98]],"ltp":0.0,"tv":0.0,"id":16586500},{"batb":[[0,4.3,63.34],[1,4.2,47.19],[2,1.01,0.51]],"ltp":0.0,"tv":0.0,"id":13508964},{"batb":[[0,5.1,25.85],[1,5,45.87],[2,1.01,0.51]],"batl":[[0,5.9,12.43]],"ltp":0.0,"tv":0.0,"id":16586502}]}]}
{"op":"mcm","clk":"1005150155","pt":1580641158225,"mc":[{"id":"1.168219388","rc":[{"batb":[[0,2.64,12.75],[1,1.01,0.51],[2,2.64,0]],"ltp":0.0,"tv":0.0,"id":13508961},{"batb":[[0,3.25,18.41],[1,1.01,0.51],[2,3.25,0]],"ltp":0.0,"tv":0.0,"id":16586500}]}]}
{"op":"mcm","clk":"1005150552","pt":1580641161176,"mc":[{"id":"1.168219388","rc":[{"batb":[[0,3.05,33.35],[1,3,54.17],[2,2.64,12.75]],"ltp":0.0,"tv":0.0,"id":13508961},{"batb":[[0,3.55,51.55],[1,3.5,37.51],[2,3.25,18.41]],"ltp":0.0,"tv":0.0,"id":16586500},{"batb":[[0,4.3,76.56]],"ltp":0.0,"tv":0.0,"id":13508964}]}]}
{"op":"mcm","clk":"1005150765","pt":1580641162655,"mc":[{"id":"1.168219388","rc":[{"batl":[[0,4.3,758.75],[1,4.5,22.98]],"ltp":0.0,"tv":0.0,"id":16586500}]}]}
{"op":"mcm","clk":"1005153760","pt":1580641184596,"mc":[{"id":"1.168219388","rc":[{"batb":[[0,2.64,12.75],[1,1.01,0.51],[2,2.64,0]],"ltp":0.0,"tv":0.0,"id":13508961},{"batb":[[0,3.25,18.41],[1,1.01,0.51],[2,3.25,0]],"batl":[[0,4.5,22.98],[1,4.5,0]],"ltp":0.0,"tv":0.0,"id":16586500},{"batb":[[0,4.3,63.34]],"ltp":0.0,"tv":0.0,"id":13508964}]}]}
{"op":"mcm","clk":"1005154113","pt":1580641187577,"mc":[{"id":"1.168219388","rc":[{"batb":[[0,2.76,52.96],[1,2.72,55.76],[2,2.64,12.75]],"ltp":0.0,"tv":0.0,"id":13508961},{"batb":[[0,3.35,52.93],[1,3.3,43.29],[2,3.25,18.41]],"ltp":0.0,"tv":0.0,"id":16586500}]}]}
{"op":"mcm","clk":"1005154168","pt":1580641188102,"mc":[{"id":"1.168219388","rc":[{"batb":[[0,3.25,18.41],[1,1.01,0.51],[2,3.25,0]],"ltp":0.0,"tv":0.0,"id":16586500},{"batb":[[1,1.01,0.51],[2,1.01,0]],"ltp":0.0,"tv":0.0,"id":13508964}]}]}
{"op":"mcm","clk":"1005154749","pt":1580641191692,"mc":[{"id":"1.168219388","rc":[{"batl":[[0,2.86,12.75],[1,3.2,24.63],[2,3.45,20.46]],"ltp":0.0,"tv":0.0,"id":13508961},{"batb":[[0,3.95,53.09],[1,3.9,53.24],[2,3.5,15.5]],"batl":[[1,5.6,14.16]],"ltp":0.0,"tv":0.0,"id":16586500},{"batb":[[0,4.4,53.17],[1,4.3,63.34],[2,1.01,0.51]],"batl":[[1,5.2,16.05]],"ltp":0.0,"tv":0.0,"id":13508964},{"batb":[[0,5.1,43.11]],"ltp":0.0,"tv":0.0,"id":16586502}]}]}
{"op":"mcm","clk":"1005154866","pt":1580641192730,"mc":[{"id":"1.168219388","rc":[{"batl":[[1,3,21],[2,3.2,24.63]],"ltp":0.0,"tv":0.0,"id":13508961},{"batb":[[2,3.85,14.28]],"batl":[[1,4.6,10.92],[2,5.6,14.16]],"ltp":0.0,"tv":0.0,"id":16586500},{"batb":[[2,4.2,12.6]],"batl":[[0,5.1,26.92]],"ltp":0.0,"tv":0.0,"id":13508964},{"batb":[[1,5,45.63],[2,4.9,10.08]],"batl":[[1,6,8.4]],"ltp":0.0,"tv":0.0,"id":16586502}]}]}
{"op":"mcm","clk":"1005156332","pt":1580641201456,"mc":[{"id":"1.168219388","rc":[{"batb":[[0,3.95,28.32],[1,3.9,24.31]],"ltp":0.0,"tv":0.0,"id":16586500}]}]}
{"op":"mcm","clk":"1005156710","pt":1580641203257,"mc":[{"id":"1.168219388","rc":[{"batb":[[0,2.64,12.75],[1,2.62,25.21],[2,2.3,18.57]],"ltp":0.0,"tv":0.0,"id":13508961},{"batb":[[0,4.4,17.86]],"ltp":0.0,"tv":0.0,"id":13508964},{"batb":[[0,5.1,31.36],[1,5,13.06]],"ltp":0.0,"tv":0.0,"id":16586502}]}]}
{"op":"mcm","clk":"1005156945","pt":1580641204340,"mc":[{"id":"1.168219388","rc":[{"batb":[[0,4,26.24],[1,3.95,28.32],[2,3.9,24.31]],"ltp":0.0,"tv":0.0,"id":16586500}]}]}
{"op":"mcm","clk":"1005157287","pt":1580641206118,"mc":[{"id":"1.168219388","rc":[{"batb":[[0,2.74,56.69],[1,2.7,56.65],[2,2.64,12.75]],"ltp":0.0,"tv":0.0,"id":13508961},{"batb":[[0,4,43.78]],"ltp":0.0,"tv":0.0,"id":16586500},{"batb":[[1,4.3,86.61],[2,4.2,59.13]],"ltp":0.0,"tv":0.0,"id":13508964},{"batb":[[0,5.2,25.4],[1,5.1,31.36],[2,5,13.06]],"ltp":0.0,"tv":0.0,"id":16586502}]}]}
{"op":"mcm","clk":"1005157687","pt":1580641208235,"mc":[{"id":"1.168219388","rc":[{"batb":[[0,2.62,25.21],[1,2.3,18.57],[2,1.01,0.51]],"batl":[[0,3,21],[1,3.2,24.63],[2,3.2,0]],"ltp":0.0,"tv":0.0,"id":13508961},{"batb":[[0,3.85,14.28],[1,3.5,15.5],[2,1.01,0.51]],"batl":[[0,4.6,10.92],[1,5.6,14.16],[2,5.6,0]],"ltp":0.0,"tv":0.0,"id":16586500},{"batb":[[0,4.3,63.34],[1,4.2,59.13],[2,1.01,0.51]],"batl":[[0,5.1,10.08]],"ltp":0.0,"tv":0.0,"id":13508964},{"batb":[[0,5.1,31.36],[1,5,13.06],[2,4.9,10.08]],"ltp":0.0,"tv":0.0,"id":16586502}]}]}
{"op":"mcm","clk":"1005157952","pt":1580641209776,"mc":[{"id":"1.168219388","rc":[{"batb":[[0,2.3,18.57],[1,1.01,0.51],[2,1.01,0]],"batl":[[0,3.2,24.63],[1,3.2,0]],"ltp":0.0,"tv":0.0,"id":13508961},{"batb":[[0,3.5,15.5],[1,1.01,0.51],[2,1.01,0]],"batl":[[0,5.6,14.16],[1,5.6,0]],"ltp":0.0,"tv":0.0,"id":16586500},{"batb":[[1,4.2,46.53]],"batl":[[0,5.2,16.05],[1,5.2,0]],"ltp":0.0,"tv":0.0,"id":13508964},{"batb":[[2,1.01,0.51]],"batl":[[1,6,0]],"ltp":0.0,"tv":0.0,"id":16586502}]}]}
{"op":"mcm","clk":"1005158244","pt":1580641211252,"mc":[{"id":"1.168219388","rc":[{"batb":[[0,2.38,67.99],[1,2.34,83.27],[2,2.3,18.57]],"ltp":0.0,"tv":0.0,"id":13508961},{"batb":[[0,3.6,37.26],[1,3.55,36.58],[2,3.5,15.5]],"ltp":0.0,"tv":0.0,"id":16586500},{"batb":[[0,5.1,49.89],[1,5,45.48]],"ltp":0.0,"tv":0.0,"id":16586502}]}]}
{"op":"mcm","clk":"1005161303","pt":1580641228749,"mc":[{"id":"1.168219388","rc":[{"batb":[[0,2.3,18.57],[1,1.01,0.51],[2,2.3,0]],"ltp":0.0,"tv":0.0,"id":13508961}]}]}
{"op":"mcm","clk":"1005161750","pt":1580641231563,"mc":[{"id":"1.168219388","rc":[{"batb":[[0,3,66.79],[1,2.96,44.59],[2,2.3,18.57]],"ltp":0.0,"tv":0.0,"id":13508961}]}]}
{"op":"mcm","clk":"1005161946","pt":1580641232679,"mc":[{"id":"1.168219388","rc":[{"batb":[[2,2.88,10.31]],"batl":[[1,3.25,18.48],[2,3.45,20.85]],"ltp":0.0,"tv":0.0,"id":13508961},{"batb":[[1,3.55,52.54]],"batl":[[0,3.95,15.03],[1,4.2,12.6],[2,4.5,22.03]],"ltp":0.0,"tv":0.0,"id":16586500},{"batb":[[1,4.2,78.41]],"batl":[[0,5,28.02],[1,5.1,16.92]],"ltp":0.0,"tv":0.0,"id":13508964},{"batb":[[2,4.9,10.08]],"batl":[[0,5.9,20.83]],"ltp":0.0,"tv":0.0,"id":16586502}]}]}
{"op":"mcm","clk":"1005165386","pt":1580641251743,"mc":[{"id":"1.168219388","rc":[{"batb":[[0,2.6,13.45],[1,1.01,0.51],[2,2.88,0]],"batl":[[0,3.45,20.85],[1,3.25,0],[2,3.45,0]],"ltp":0.0,"tv":0.0,"id":13508961},{"batb":[[0,3.3,18.33],[1,1.01,0.51],[2,3.5,0]],"batl":[[0,4.5,22.03],[1,4.2,0],[2,4.5,0]],"ltp":0.0,"tv":0.0,"id":16586500},{"batb":[[0,4.2,65.81],[1,1.01,0.51],[2,1.01,0]],"batl":[[0,5.1,16.92],[1,5.1,0]],"ltp":0.0,"tv":0.0,"id":13508964},{"batb":[[0,5.1,42.28],[2,1.01,0.51]],"batl":[[0,5.9,12.43]],"ltp":0.0,"tv":0.0,"id":16586502}]}]}
{"op":"mcm","clk":"1005165879","pt":1580641254115,"mc":[{"id":"1.168219388","rc":[{"batb":[[0,2.72,43.35],[1,2.68,57.85],[2,2.6,13.45]],"ltp":0.0,"tv":0.0,"id":13508961},{"batb":[[0,3.35,56.81],[1,3.3,61.82],[2,1.01,0.51]],"ltp":0.0,"tv":0.0,"id":16586500},{"batb":[[0,4.2,87.19],[1,4.1,49.29],[2,1.01,0.51]],"ltp":0.0,"tv":0.0,"id":13508964}]}]}
{"op":"mcm","clk":"1005166246","pt":1580641256314,"mc":[{"id":"1.168219388","rc":[{"batb":[[0,2.6,13.45],[1,1.01,0.51],[2,2.6,0]],"ltp":0.0,"tv":0.0,"id":13508961}]}]}
{"op":"mcm","clk":"1005166815","pt":1580641259632,"mc":[{"id":"1.168219388","rc":[{"batb":[[0,3.2,73.73],[1,3.15,47.4],[2,2.6,13.45]],"ltp":0.0,"tv":0.0,"id":13508961}]}]}
{"op":"mcm","clk":"1005166993","pt":1580641260755,"mc":[{"id":"1.168219388","rc":[{"batb":[[2,3.05,21.64]],"batl":[[1,3.5,16.8],[2,3.95,15.11]],"ltp":0.0,"tv":0.0,"id":13508961},{"batb":[[1,3.3,79.47],[2,2.94,24.39]],"batl":[[0,3.65,17.7],[1,3.85,14.28],[2,3.95,15.11]],"ltp":0.0,"tv":0.0,"id":16586500},{"batb":[[0,4.2,99.79]],"batl":[[0,5,28.26]],"ltp":0.0,"tv":0.0,"id":13508964},{"batb":[[2,4.8,10.92]],"batl":[[0,5.8,8.4],[1,5.9,12.43]],"ltp":0.0,"tv":0.0,"id":16586502}]}]}
{"op":"mcm","clk":"1005173213","pt":1580641296400,"mc":[{"id":"1.168219388","rc":[{"batb":[[0,3.05,21.64],[1,3,21],[2,2.9,25.26]],"ltp":0.0,"tv":0.0,"id":13508961},{"batb":[[0,3.3,35.98],[1,2.94,24.39],[2,1.01,0.51]],"ltp":0.0,"tv":0.0,"id":16586500},{"batb":[[0,4.2,78.41]],"ltp":0.0,"tv":0.0,"id":13508964}]}]}
{"op":"mcm","clk":"1005173738","pt":1580641299370,"mc":[{"id":"1.168219388","rc":[{"batb":[[1,3,104.5],[2,2.96,44.44]],"ltp":0.0,"tv":0.0,"id":13508961},{"batb":[[1,3.05,35.12],[2,3,55.33]],"ltp":0.0,"tv":0.0,"id":16586500}]}]}
{"op":"mcm","clk":"1005175517","pt":1580641308318,"mc":[{"id":"1.168219388","rc":[{"batb":[[0,3,104.5],[1,2.96,44.44],[2,2.9,25.26]],"batl":[[0,3.5,16.8],[1,3.95,15.11],[2,3.95,0]],"ltp":0.0,"tv":0.0,"id":13508961},{"batb":[[0,3.3,17.64]],"batl":[[0,3.85,14.28],[1,3.95,15.11],[2,3.95,0]],"ltp":0.0,"tv":0.0,"id":16586500}]}]}
{"op":"mcm","clk":"1005175794","pt":1580641309913,"mc":[{"id":"1.168219388","rc":[{"batb":[[0,3,83.5]],"batl":[[0,3.95,15.11],[1,3.95,0]],"ltp":0.0,"tv":0.0,"id":13508961},{"batb":[[0,3.05,35.12],[1,3,55.33],[2,2.94,24.39]],"batl":[[0,3.95,15.11],[1,3.95,0]],"ltp":0.0,"tv":0.0,"id":16586500},{"batb":[[0,4.2,65.81]],"batl":[[0,5,18.18]],"ltp":0.0,"tv":0.0,"id":13508964},{"batb":[[2,1.01,0.51]],"batl":[[0,5.9,12.43],[1,5.9,0]],"ltp":0.0,"tv":0.0,"id":16586502}]}]}
{"op":"mcm","clk":"1005177567","pt":1580641319418,"mc":[{"id":"1.168219388","rc":[{"batb":[[0,2.94,24.39],[1,1.01,0.51],[2,2.94,0]],"ltp":0.0,"tv":0.0,"id":16586500},{"batb":[[1,1.01,0.51],[2,1.01,0]],"ltp":0.0,"tv":0.0,"id":13508964}]}]}
{"op":"mcm","clk":"1005178168","pt":1580641322731,"mc":[{"id":"1.168219388","rc":[{"batb":[[2,2.9,47.1]],"batl":[[0,3.35,17.64],[1,3.95,15.11]],"ltp":0.0,"tv":0.0,"id":13508961},{"batb":[[0,3.6,31.74],[1,3.55,36.64],[2,3.45,16.8]],"batl":[[1,4.1,13.44]],"ltp":0.0,"tv":0.0,"id":16586500},{"batb":[[0,4.3,30.31],[1,4.2,78.41],[2,1.01,0.51]],"batl":[[0,5,28.26]],"ltp":0.0,"tv":0.0,"id":13508964},{"batb":[[2,4.8,10.92]],"batl":[[0,5.8,8.4],[1,5.9,12.43]],"ltp":0.0,"tv":0.0,"id":16586502}]}]}
{"op":"mcm","clk":"1005178286","pt":1580641323321,"mc":[{"id":"1.168219388","rc":[{"batl":[[0,3.2,24.23],[1,3.35,17.64],[2,3.55,18.96]],"ltp":0.0,"tv":0.0,"id":13508961},{"batb":[[2,3.5,15.66]],"batl":[[2,4.2,13.38]],"ltp":0.0,"tv":0.0,"id":16586500},{"batl":[[0,5,27.94]],"ltp":0.0,"tv":0.0,"id":13508964}]}]}
{"op":"mcm","clk":"1005180603","pt":1580641336061,"mc":[{"id":"1.168219388","rc":[{"batb":[[0,2.9,21.85],[1,2.78,11.25],[2,1.01,0.51]],"batl":[[0,3.35,17.64],[1,3.55,18.96],[2,3.55,0]],"ltp":0.0,"tv":0.0,"id":13508961},{"batb":[[0,3.45,16.8],[1,3.15,20.14],[2,1.01,0.51]],"batl":[[0,4.1,13.44],[1,4.2,13.38],[2,4.2,0]],"ltp":0.0,"tv":0.0,"id":16586500},{"batb":[[0,4.2,78.41],[1,1.01,0.51],[2,1.01,0]],"ltp":0.0,"tv":0.0,"id":13508964}]}]}
{"op":"mcm","clk":"1005180923","pt":1580641337765,"mc":[{"id":"1.168219388","rc":[{"batb":[[0,2.78,11.25],[1,1.01,0.51],[2,1.01,0]],"batl":[[0,3.55,18.96],[1,3.55,0]],"ltp":0.0,"tv":0.0,"id":13508961},{"batb":[[0,3.15,20.14],[1,1.01,0.51],[2,1.01,0]],"batl":[[0,4.2,13.38],[1,4.2,0]],"ltp":0.0,"tv":0.0,"id":16586500},{"batb":[[0,4.2,65.81]],"batl":[[0,5,17.86]],"ltp":0.0,"tv":0.0,"id":13508964},{"batb":[[2,1.01,0.51]],"batl":[[0,5.9,12.43],[1,5.9,0]],"ltp":0.0,"tv":0.0,"id":16586502}]}]}
{"op":"mcm","clk":"1005181111","pt":1580641338882,"mc":[{"id":"1.168219388","rc":[{"batb":[[0,2.9,41.63],[1,2.86,48.86],[2,2.78,11.25]],"ltp":0.0,"tv":0.0,"id":13508961},{"batb":[[0,3.25,71.99],[1,3.2,46.81],[2,3.15,20.14]],"ltp":0.0,"tv":0.0,"id":16586500},{"batb":[[0,4.2,82.9],[1,4.1,49.34],[2,1.01,0.51]],"ltp":0.0,"tv":0.0,"id":13508964}]}]}
{"op":"mcm","clk":"1005182438","pt":1580641346285,"mc":[{"id":"1.168219388","rc":[{"trd":[[2.86,97.72],[2.9,83.26]],"batb":[[0,2.78,11.25],[1,1.01,0.51],[2,2.78,0]],"batl":[[0,2.8,64.87],[1,3.55,18.96]],"ltp":2.86,"tv":180.98,"id":13508961}],"tv":180.98}]}
{"op":"mcm","clk":"1005182555","pt":1580641346882,"mc":[{"id":"1.168219388","rc":[{"batb":[[0,3.25,45.46],[1,3.15,20.14],[2,1.01,0.51]],"ltp":0.0,"tv":0.0,"id":16586500}]}]}
{"op":"mcm","clk":"1005183188","pt":1580641350430,"mc":[{"id":"1.168219388","rc":[{"trd":[[2.8,129.74]],"batb":[[0,2.84,33.35],[1,2.78,11.25],[2,1.01,0.51]],"batl":[[0,3.55,18.96],[1,3.55,0]],"ltp":2.8,"tv":310.72,"id":13508961},{"batb":[[0,3.3,32.52],[1,3.25,45.46],[2,3.15,20.14]],"ltp":0.0,"tv":0.0,"id":16586500},{"batb":[[0,4.2,66.76],[1,1.01,0.51],[2,1.01,0]],"ltp":0.0,"tv":0.0,"id":13508964}],"tv":310.72}]}
{"op":"mcm","clk":"1005183385","pt":1580641351513,"mc":[{"id":"1.168219388","rc":[{"batb":[[0,3.15,20.14],[1,1.01,0.51],[2,3.15,0]],"ltp":0.0,"tv":0.0,"id":16586500},{"batb":[[0,5.1,31.45],[1,5,13.06]],"ltp":0.0,"tv":0.0,"id":16586502}]}]}
{"op":"mcm","clk":"1005184002","pt":1580641354697,"mc":[{"id":"1.168219388","rc":[{"batb":[[0,2.88,36.5],[1,2.84,49.57],[2,2.78,34.78]],"batl":[[0,3.2,18.48],[1,3.55,18.96]],"ltp":2.8,"tv":310.72,"id":13508961},{"batb":[[0,3.8,38.22],[1,3.75,32.19],[2,3.6,15.96]],"batl":[[1,4.3,12.6]],"ltp":0.0,"tv":0.0,"id":16586500},{"batb":[[0,4.3,47.31],[1,4.2,79.36],[2,1.01,0.51]],"batl":[[0,5,27.94]],"ltp":0.0,"tv":0.0,"id":13508964},{"batb":[[0,5.2,28.27],[1,5.1,31.45],[2,5,13.06]],"batl":[[0,5.9,20.83]],"ltp":0.0,"tv":0.0,"id":16586502}]}]}
{"op":"mcm","clk":"1005184184","pt":1580641355595,"mc":[{"id":"1.168219388","rc":[{"batl":[[0,3.05,11.09],[1,3.2,18.48],[2,3.3,22.9]],"ltp":2.8,"tv":310.72,"id":13508961},{"batb":[[2,3.7,13.85]],"batl":[[2,4.4,23.68]],"ltp":0.0,"tv":0.0,"id":16586500},{"batb":[[0,4.3,66.19],[1,4.2,60.08]],"batl":[[0,5,27.71]],"ltp":0.0,"tv":0.0,"id":13508964}]}]}
{"op":"mcm","clk":"1005187757","pt":1580641374649,"mc":[{"id":"1.168219388","rc":[{"batb":[[0,2.78,34.78],[1,2.68,12.43],[2,1.01,0.51]],"ltp":2.8,"tv":310.72,"id":13508961},{"batb":[[0,3.7,13.85],[1,3.6,15.96],[2,3.4,16.76]],"ltp":0.0,"tv":0.0,"id":16586500},{"batb":[[0,5.1,31.45],[1,5,13.06],[2,4.8,10.92]],"ltp":0.0,"tv":0.0,"id":16586502}]}]}
{"op":"mcm","clk":"1005187974","pt":1580641375722,"mc":[{"id":"1.168219388","rc":[{"batb":[[0,2.68,12.43],[1,1.01,0.51],[2,1.01,0]],"batl":[[0,3.3,22.9],[1,3.2,0],[2,3.3,0]],"ltp":2.8,"tv":310.72,"id":13508961},{"batb":[[0,3.4,16.76],[1,1.01,0.51],[2,3.4,0]],"batl":[[0,4.4,23.68],[1,4.3,0],[2,4.4,0]],"ltp":0.0,"tv":0.0,"id":16586500},{"batb":[[1,4.2,47.48]],"batl":[[0,5,17.62]],"ltp":0.0,"tv":0.0,"id":13508964},{"batb":[[2,1.01,0.51]],"batl":[[0,5.9,12.43]],"ltp":0.0,"tv":0.0,"id":16586502}]}]}
{"op":"mcm","clk":"1005188337","pt":1580641377524,"mc":[{"id":"1.168219388","rc":[{"batb":[[0,2.78,51.8],[1,2.74,54.29],[2,2.68,12.43]],"ltp":2.8,"tv":310.72,"id":13508961},{"batb":[[0,3.55,40.52],[1,3.5,37.95],[2,3.4,16.76]],"ltp":0.0,"tv":0.0,"id":16586500},{"batb":[[0,5.1,49.33],[1,5,45.63]],"ltp":0.0,"tv":0.0,"id":16586502}]}]}
{"op":"mcm","clk":"1005188554","pt":1580641378645,"mc":[{"id":"1.168219388","rc":[{"batb":[[0,3.4,16.76],[1,1.01,0.51],[2,3.4,0]],"ltp":0.0,"tv":0.0,"id":16586500},{"batb":[[0,5.1,31.36],[1,5,13.06]],"ltp":0.0,"tv":0.0,"id":16586502}]}]}
{"op":"mcm","clk":"1005189117","pt":1580641381645,"mc":[{"id":"1.168219388","rc":[{"batb":[[0,3.95,37.5],[1,3.9,29.34],[2,3.4,16.76]],"ltp":0.0,"tv":0.0,"id":16586500},{"batb":[[0,5.2,34.37],[1,5.1,31.36],[2,5,13.06]],"ltp":0.0,"tv":0.0,"id":16586502}]}]}
{"op":"mcm","clk":"1005189340","pt":1580641382736,"mc":[{"id":"1.168219388","rc":[{"batb":[[2,2.7,24.37]],"batl":[[0,2.92,12.2],[1,3.1,29.95]],"ltp":2.8,"tv":310.72,"id":13508961},{"batb":[[2,3.85,25.02]],"batl":[[0,4.4,35.45],[1,4.6,21.64]],"ltp":0.0,"tv":0.0,"id":16586500},{"batb":[[0,4.3,66.04],[1,4.2,60.08]],"batl":[[0,5,27.55]],"ltp":0.0,"tv":0.0,"id":13508964},{"batl":[[1,6,8.4]],"ltp":0.0,"tv":0.0,"id":16586502}]}]}
{"op":"mcm","clk":"1005190710","pt":1580641389968,"mc":[{"id":"1.168219388","rc":[{"batb":[[0,2.7,24.37],[1,2.62,13.3],[2,1.01,0.51]],"batl":[[0,3.1,29.95],[1,3.1,0]],"ltp":2.8,"tv":310.72,"id":13508961},{"batb":[[0,3.75,15.12],[1,3.6,14.4],[2,1.01,0.51]],"batl":[[0,4.4,11.76]],"ltp":0.0,"tv":0.0,"id":16586500},{"batb":[[0,5.2,22.21]],"ltp":0.0,"tv":0.0,"id":16586502}]}]}
{"op":"mcm","clk":"1005191258","pt":1580641392757,"mc":[{"id":"1.168219388","rc":[{"batb":[[0,2.72,64],[1,2.68,57.45],[2,2.62,13.3]],"batl":[[0,3.1,10.62]],"ltp":2.8,"tv":310.72,"id":13508961},{"batb":[[0,3.75,55],[1,3.7,33.09],[2,3.6,14.4]],"batl":[[0,4.6,21.64],[1,4.6,0]],"ltp":0.0,"tv":0.0,"id":16586500},{"batb":[[1,4.2,47.48]],"batl":[[0,5,17.47]],"ltp":0.0,"tv":0.0,"id":13508964},{"batl":[[1,6,0]],"ltp":0.0,"tv":0.0,"id":16586502}]}]}
{"op":"mcm","clk":"1005192118","pt":1580641396458,"mc":[{"id":"1.168219388","rc":[{"batb":[[0,2.62,13.3],[1,1.01,0.51],[2,2.62,0]],"ltp":2.8,"tv":310.72,"id":13508961}]}]}
{"op":"mcm","clk":"1005192680","pt":1580641399274,"mc":[{"id":"1.168219388","rc":[{"batb":[[0,2.88,55.22],[1,2.84,49.44],[2,2.62,13.3]],"ltp":2.8,"tv":310.72,"id":13508961}]}]}
{"op":"mcm","clk":"1005192938","pt":1580641400766,"mc":[{"id":"1.168219388","rc":[{"batb":[[2,2.82,33.46]],"batl":[[1,3.2,18.48],[2,3.35,22.03]],"ltp":2.8,"tv":310.72,"id":13508961},{"batl":[[0,4.1,14.01],[1,4.2,12.6],[2,4.3,24.71]],"ltp":0.0,"tv":0.0,"id":16586500},{"batb":[[1,4.2,60.08]],"batl":[[1,5.1,10.08]],"ltp":0.0,"tv":0.0,"id":13508964},{"batl":[[0,5.8,8.4],[1,5.9,12.43]],"ltp":0.0,"tv":0.0,"id":16586502}]}]}
{"op":"mcm","clk":"1005194314","pt":1580641407684,"mc":[{"id":"1.168219388","rc":[{"batb":[[0,2.82,22.69],[1,2.72,11.88],[2,1.01,0.51]],"batl":[[0,3.2,18.48],[1,3.35,22.03],[2,3.35,0]],"ltp":2.8,"tv":310.72,"id":13508961},{"batb":[[0,3.55,15.96],[1,3.35,17.47],[2,1.01,0.51]],"batl":[[0,4.2,12.6],[1,4.3,24.71],[2,4.3,0]],"ltp":0.0,"tv":0.0,"id":16586500},{"batb":[[0,5.1,31.36],[1,5,13.06],[2,4.8,10.92]],"ltp":0.0,"tv":0.0,"id":16586502}]}]}
{"op":"mcm","clk":"1005194353","pt":1580641407900,"mc":[{"id":"1.168219388","rc":[{"batb":[[0,2.72,11.88],[1,1.01,0.51],[2,1.01,0]],"batl":[[0,3.35,22.03],[1,3.35,0]],"ltp":2.8,"tv":310.72,"id":13508961},{"batb":[[0,3.35,17.47],[1,1.01,0.51],[2,1.01,0]],"batl":[[0,4.3,24.71],[1,4.3,0]],"ltp":0.0,"tv":0.0,"id":16586500},{"batb":[[1,4.2,47.48]],"batl":[[1,5.1,0]],"ltp":0.0,"tv":0.0,"id":13508964},{"batb":[[2,1.01,0.51]],"batl":[[0,5.9,12.43],[1,5.9,0]],"ltp":0.0,"tv":0.0,"id":16586502}]}]}
{"op":"mcm","clk":"1005194995","pt":1580641410600,"mc":[{"id":"1.168219388","rc":[{"batb":[[0,2.8,49.35],[1,2.76,53.29],[2,2.72,11.88]],"ltp":2.8,"tv":310.72,"id":13508961},{"batb":[[0,3.55,31.08],[1,3.5,38.03],[2,3.35,17.47]],"ltp":0.0,"tv":0.0,"id":16586500},{"batb":[[0,5.1,43.91],[1,5,45.71]],"ltp":0.0,"tv":0.0,"id":16586502}]}]}
{"op":"mcm","clk":"1005195817","pt":1580641414436,"mc":[{"id":"1.168219388","rc":[{"batb":[[0,3.35,17.47],[1,1.01,0.51],[2,3.35,0]],"ltp":0.0,"tv":0.0,"id":16586500},{"batb":[[0,5.1,31.45],[1,5,13.06]],"ltp":0.0,"tv":0.0,"id":16586502}]}]}
{"op":"mcm","clk":"1005196411","pt":1580641417332,"mc":[{"id":"1.168219388","rc":[{"batb":[[0,3.9,48.49],[1,3.85,30.15],[2,3.35,17.47]],"ltp":0.0,"tv":0.0,"id":16586500},{"batb":[[0,5.2,28.01],[1,5.1,31.45],[2,5,13.06]],"ltp":0.0,"tv":0.0,"id":16586502}]}]}
{"op":"mcm","clk":"1005196680","pt":1580641418697,"mc":[{"id":"1.168219388","rc":[{"batl":[[0,2.96,11.64],[1,3.1,19.32],[2,3.2,24.63]],"ltp":2.8,"tv":310.72,"id":13508961},{"batb":[[2,3.75,28.18]],"batl":[[1,4.5,11.76],[2,5,17.94]],"ltp":0.0,"tv":0.0,"id":16586500},{"batb":[[1,4.2,60.08]],"batl":[[0,5,10.08],[1,5.1,16.92]],"ltp":0.0,"tv":0.0,"id":13508964},{"batl":[[0,5.9,20.68]],"ltp":0.0,"tv":0.0,"id":16586502}]}]}
{"op":"mcm","clk":"1005202649","pt":1580641448209,"mc":[{"id":"1.168219388","rc":[{"batb":[[0,2.7,24.37],[1,2.46,15.58],[2,1.01,0.51]],"batl":[[0,3.1,19.32],[1,3.2,24.63],[2,3.2,0]],"ltp":2.8,"tv":310.72,"id":13508961},{"batb":[[0,3.75,15.12],[1,3.55,15.26],[2,1.01,0.51]],"batl":[[0,4.5,11.76],[1,5,17.94],[2,5,0]],"ltp":0.0,"tv":0.0,"id":16586500},{"batb":[[0,4.3,54.72]],"ltp":0.0,"tv":0.0,"id":13508964},{"batb":[[0,5.1,31.45],[1,5,13.06],[2,4.9,10.08]],"ltp":0.0,"tv":0.0,"id":16586502}]}]}
{"op":"mcm","clk":"1005202957","pt":1580641449824,"mc":[{"id":"1.168219388","rc":[{"batb":[[0,2.46,15.58],[1,1.01,0.51],[2,1.01,0]],"batl":[[0,3.2,24.63],[1,3.2,0]],"ltp":2.8,"tv":310.72,"id":13508961},{"batb":[[0,3.55,15.26],[1,1.01,0.51],[2,1.01,0]],"batl":[[0,5,17.94],[1,5,0]],"ltp":0.0,"tv":0.0,"id":16586500},{"batb":[[1,4.2,47.48]],"batl":[[0,5.1,16.92],[1,5.1,0]],"ltp":0.0,"tv":0.0,"id":13508964},{"batb":[[2,1.01,0.51]],"batl":[[0,5.9,12.27]],"ltp":0.0,"tv":0.0,"id":16586502}]}]}
{"op":"mcm","clk":"1005203646","pt":1580641453097,"mc":[{"id":"1.168219388","rc":[{"batb":[[0,2.74,53.78],[1,2.7,56.41],[2,2.46,15.58]],"ltp":2.8,"tv":310.72,"id":13508961},{"batb":[[0,4,47.6],[1,3.95,28.38],[2,3.55,15.26]],"ltp":0.0,"tv":0.0,"id":16586500},{"batb":[[0,4.3,80.16]],"ltp":0.0,"tv":0.0,"id":13508964},{"batb":[[0,5.2,31.22],[1,5.1,31.45],[2,5,13.06]],"ltp":0.0,"tv":0.0,"id":16586502}]}]}
{"op":"mcm","clk":"1005204388","pt":1580641456719,"mc":[{"id":"1.168219388","rc":[{"batb":[[0,2.46,15.58],[1,1.01,0.51],[2,2.46,0]],"ltp":2.8,"tv":310.72,"id":13508961},{"batb":[[0,3.55,15.26],[1,1.01,0.51],[2,3.55,0]],"ltp":0.0,"tv":0.0,"id":16586500},{"batb":[[0,4.3,59.28]],"ltp":0.0,"tv":0.0,"id":13508964},{"batb":[[0,5.1,31.45],[1,5,13.06],[2,1.01,0.51]],"ltp":0.0,"tv":0.0,"id":16586502}]}]}
{"op":"mcm","clk":"1005205211","pt":1580641460734,"mc":[{"id":"1.168219388","rc":[{"batb":[[0,2.54,54.19],[1,2.5,69.33],[2,2.46,15.58]],"ltp":2.8,"tv":310.72,"id":13508961},{"batb":[[0,3.65,32.88],[1,3.6,35.47],[2,3.55,15.26]],"ltp":0.0,"tv":0.0,"id":16586500},{"batb":[[0,5.1,45.96],[1,5,45.61]],"ltp":0.0,"tv":0.0,"id":16586502}]}]}
{"op":"mcm","clk":"1005207128","pt":1580641469655,"mc":[{"id":"1.168219388","rc":[{"batb":[[0,3.55,15.26],[1,1.01,0.51],[2,3.55,0]],"ltp":0.0,"tv":0.0,"id":16586500},{"batb":[[1,1.01,0.51],[2,1.01,0]],"ltp":0.0,"tv":0.0,"id":13508964},{"batb":[[0,5.1,31.36],[1,5,13.06]],"ltp":0.0,"tv":0.0,"id":16586502}]}]}
{"op":"mcm","clk":"1005207817","pt":1580641472741,"mc":[{"id":"1.168219388","rc":[{"batb":[[2,2.46,44.15]],"batl":[[0,2.82,22.69],[1,3.2,24.63]],"ltp":2.8,"tv":310.72,"id":13508961},{"batb":[[0,4.4,63.65],[1,4.3,45.64],[2,4.2,12.6]],"batl":[[1,5.1,10.08]],"ltp":0.0,"tv":0.0,"id":16586500},{"batb":[[0,4.4,45.69],[1,4.3,59.28],[2,4.2,12.6]],"batl":[[0,5.1,27]],"ltp":0.0,"tv":0.0,"id":13508964},{"batb":[[0,5.2,39.11],[1,5.1,31.36],[2,5,13.06]],"batl":[[1,6,8.4]],"ltp":0.0,"tv":0.0,"id":16586502}]}]}
{"op":"mcm","clk":"1005208025","pt":1580641473753,"mc":[{"id":"1.168219388","rc":[{"batl":[[0,2.66,15.26],[1,2.82,22.69],[2,2.9,12.43]],"ltp":2.8,"tv":310.72,"id":13508961},{"batb":[[1,4.3,64.52]],"batl":[[2,6.2,11.25]],"ltp":0.0,"tv":0.0,"id":16586500},{"batb":[[0,4.4,63.47],[1,4.3,58.96]],"batl":[[1,5.3,15.97]],"ltp":0.0,"tv":0.0,"id":13508964},{"batl":[[0,6,20.28],[1,6,0]],"ltp":0.0,"tv":0.0,"id":16586502}]}]}
{"op":"mcm","clk":"1005211144","pt":1580641490136,"mc":[{"id":"1.168219388","rc":[{"batb":[[0,2.18,21.56],[1,1.01,0.51],[2,2.46,0]],"batl":[[0,2.9,12.43],[1,2.82,0],[2,2.9,0]],"ltp":2.8,"tv":310.72,"id":13508961},{"batb":[[0,3.85,24.39],[1,1.01,0.51],[2,4.2,0]],"batl":[[0,6.2,11.25],[1,5.1,0],[2,6.2,0]],"ltp":0.0,"tv":0.0,"id":16586500},{"batb":[[0,4.3,58.96],[1,1.01,0.51],[2,4.2,0]],"batl":[[0,5.3,15.97],[1,5.3,0]],"ltp":0.0,"tv":0.0,"id":13508964},{"batb":[[0,5.2,28.36]],"batl":[[0,6,11.88]],"ltp":0.0,"tv":0.0,"id":16586502}]}]}
{"op":"mcm","clk":"1005211824","pt":1580641493691,"mc":[{"id":"1.168219388","rc":[{"batb":[[0,4.3,63.01]],"ltp":0.0,"tv":0.0,"id":13508964}]}]}
{"op":"mcm","clk":"1005212335","pt":1580641496386,"mc":[{"id":"1.168219388","rc":[{"batb":[[0,2.74,50.53],[1,2.7,56.48],[2,2.18,21.56]],"ltp":2.8,"tv":310.72,"id":13508961},{"batb":[[0,4,52.18],[1,3.95,28.32],[2,3.85,24.39]],"ltp":0.0,"tv":0.0,"id":16586500},{"batb":[[0,4.3,81.16],[1,4.2,46.85],[2,1.01,0.51]],"ltp":0.0,"tv":0.0,"id":13508964}]}]}
{"op":"mcm","clk":"1005212496","pt":1580641497177,"mc":[{"id":"1.168219388","rc":[{"batb":[[2,2.66,12.67]],"batl":[[1,2.98,21],[2,3.15,25.1]],"ltp":2.8,"tv":310.72,"id":13508961},{"batl":[[0,4.5,23.05],[1,4.6,10.92],[2,5.4,15.26]],"ltp":0.0,"tv":0.0,"id":16586500},{"batl":[[0,5,27.63],[1,5.2,16.44]],"ltp":0.0,"tv":0.0,"id":13508964},{"batl":[[0,5.9,12.43],[1,6,8.4]],"ltp":0.0,"tv":0.0,"id":16586502}]}]}
{"op":"mcm","clk":"1005212678","pt":1580641498188,"mc":[{"id":"1.168219388","rc":[{"batb":[[2,3.9,14.28]],"ltp":0.0,"tv":0.0,"id":16586500}]}]}
{"op":"mcm","clk":"1005213171","pt":1580641500486,"mc":[{"id":"1.168219388","rc":[{"batb":[[1,4.2,59.45]],"ltp":0.0,"tv":0.0,"id":13508964}]}]}
{"op":"mcm","clk":"1005214847","pt":1580641508997,"mc":[{"id":"1.168219388","rc":[{"batb":[[0,2.6,26.05],[1,2.36,17.47],[2,1.01,0.51]],"batl":[[0,2.98,21],[1,3.15,25.1],[2,3.15,0]],"ltp":2.8,"tv":310.72,"id":13508961},{"batb":[[0,3.9,14.28],[1,3.6,14.79],[2,1.01,0.51]],"batl":[[0,4.6,10.92],[1,5.4,15.26],[2,5.4,0]],"ltp":0.0,"tv":0.0,"id":16586500},{"batb":[[0,4.3,58.96]],"batl":[[0,5,10.08]],"ltp":0.0,"tv":0.0,"id":13508964},{"batb":[[0,5.1,31.36],[1,5,13.06],[2,4.9,10.08]],"ltp":0.0,"tv":0.0,"id":16586502}]}]}
{"op":"mcm","clk":"1005215033","pt":1580641509907,"mc":[{"id":"1.168219388","rc":[{"batb":[[0,2.36,17.47],[1,1.01,0.51],[2,1.01,0]],"batl":[[0,3.15,25.1],[1,3.15,0]],"ltp":2.8,"tv":310.72,"id":13508961},{"batb":[[0,3.6,14.79],[1,1.01,0.51],[2,1.01,0]],"batl":[[0,5.4,15.26],[1,5.4,0]],"ltp":0.0,"tv":0.0,"id":16586500},{"batb":[[1,4.2,46.85]],"batl":[[0,5.2,16.44],[1,5.2,0]],"ltp":0.0,"tv":0.0,"id":13508964},{"batb":[[2,1.01,0.51]],"batl":[[1,6,0]],"ltp":0.0,"tv":0.0,"id":16586502}]}]}
{"op":"mcm","clk":"1005215415","pt":1580641511912,"mc":[{"id":"1.168219388","rc":[{"batb":[[0,2.44,54.35],[1,2.4,77.48],[2,2.36,17.47]],"ltp":2.8,"tv":310.72,"id":13508961},{"batb":[[0,3.7,30.98],[1,3.65,34.35],[2,3.6,14.79]],"ltp":0.0,"tv":0.0,"id":16586500},{"batb":[[0,5.1,50.43],[1,5,45.54]],"ltp":0.0,"tv":0.0,"id":16586502}]}]}
{"op":"mcm","clk":"1005217192","pt":1580641519993,"mc":[{"id":"1.168219388","rc":[{"batb":[[0,2.36,17.47],[1,1.01,0.51],[2,2.36,0]],"ltp":2.8,"tv":310.72,"id":13508961}]}]}
{"op":"mcm","clk":"1005217749","pt":1580641522700,"mc":[{"id":"1.168219388","rc":[{"batb":[[0,2.96,43.67],[1,2.92,46.15],[2,2.36,17.47]],"ltp":2.8,"tv":310.72,"id":13508961}]}]}
{"op":"mcm","clk":"1005217903","pt":1580641523508,"mc":[{"id":"1.168219388","rc":[{"batb":[[2,2.86,10.46]],"batl":[[1,3.35,21.56]],"ltp":2.8,"tv":310.72,"id":13508961},{"batl":[[0,4,14.32],[1,4.7,20.77],[2,5.4,15.26]],"ltp":0.0,"tv":0.0,"id":16586500},{"batb":[[1,4.2,66.13]],"batl":[[0,5.1,17.39],[1,5.2,16.44]],"ltp":0.0,"tv":0.0,"id":13508964}]}]}
{"op":"mcm","clk":"1005217982","pt":1580641523928,"mc":[{"id":"1.168219388","rc":[{"batl":[[2,5.4,0]],"ltp":0.0,"tv":0.0,"id":16586500},{"batb":[[0,4.3,40.55]],"batl":[[1,5.2,0]],"ltp":0.0,"tv":0.0,"id":13508964}]}]}
{"op":"mcm","clk":"1005218179","pt":1580641524881,"mc":[{"id":"1.168219388","rc":[{"batl":[[1,3.2,18.48],[2,3.35,21.56]],"ltp":2.8,"tv":310.72,"id":13508961},{"batb":[[1,3.65,49.47]],"batl":[[1,4.3,12.6],[2,4.7,20.77]],"ltp":0.0,"tv":0.0,"id":16586500},{"batb":[[2,4.1,13.44]],"batl":[[0,4.9,10.08],[1,5.1,17.39]],"ltp":0.0,"tv":0.0,"id":13508964},{"batb":[[2,4.8,10.92]],"batl":[[0,5.9,20.83]],"ltp":0.0,"tv":0.0,"id":16586502}]}]}
{"op":"mcm","clk":"1005221248","pt":1580641539750,"mc":[{"id":"1.168219388","rc":[{"batb":[[2,2.78,23.53]],"batl":[[0,3.2,18.48],[1,3.35,21.56],[2,3.35,0]],"ltp":2.8,"tv":310.72,"id":13508961},{"batb":[[2,3.35,17.31]],"batl":[[0,4.3,12.6],[1,4.7,20.77],[2,4.7,0]],"ltp":0.0,"tv":0.0,"id":16586500}]}]}
{"op":"mcm","clk":"1005221331","pt":1580641540138,"mc":[{"id":"1.168219388","rc":[{"batb":[[0,2.58,13.77],[1,1.01,0.51],[2,2.78,0]],"batl":[[0,3.35,21.56],[1,3.35,0]],"ltp":2.8,"tv":310.72,"id":13508961},{"batb":[[0,3.35,17.31],[1,1.01,0.51],[2,3.35,0]],"batl":[[0,4.7,20.77],[1,4.7,0]],"ltp":0.0,"tv":0.0,"id":16586500},{"batb":[[0,4.2,66.13],[1,1.01,0.51],[2,4.1,0]],"batl":[[0,5.1,17.39],[1,5.1,0]],"ltp":0.0,"tv":0.0,"id":13508964},{"batb":[[0,5.1,41.67],[2,1.01,0.51]],"batl":[[0,5.9,12.43]],"ltp":0.0,"tv":0.0,"id":16586502}]}]}
{"op":"mcm","clk":"1005222103","pt":1580641543532,"mc":[{"id":"1.168219388","rc":[{"batb":[[0,2.68,45.47],[1,2.64,59.97],[2,2.58,13.77]],"ltp":2.8,"tv":310.72,"id":13508961},{"batb":[[0,3.45,50.2],[1,3.4,40.58],[2,3.35,17.31]],"ltp":0.0,"tv":0.0,"id":16586500},{"batb":[[0,4.2,88.53],[1,4.1,49.5],[2,1.01,0.51]],"ltp":0.0,"tv":0.0,"id":13508964}]}]}
{"op":"mcm","clk":"1005222946","pt":1580641547369,"mc":[{"id":"1.168219388","rc":[{"batb":[[0,2.58,13.77],[1,1.01,0.51],[2,2.58,0]],"ltp":2.8,"tv":310.72,"id":13508961}]}]}
{"op":"mcm","clk":"1005223603","pt":1580641550360,"mc":[{"id":"1.168219388","rc":[{"batb":[[0,3.15,44.31],[1,3.1,49.4],[2,2.58,13.77]],"ltp":2.8,"tv":310.72,"id":13508961}]}]}
{"op":"mcm","clk":"1005223761","pt":1580641551146,"mc":[{"id":"1.168219388","rc":[{"batb":[[2,3,22.42]],"batl":[[1,3.4,16.8],[2,3.55,19.36]],"ltp":2.8,"tv":310.72,"id":13508961},{"batb":[[0,3.45,67]],"batl":[[0,3.75,16.76],[1,4,13.44],[2,4.1,14.01]],"ltp":0.0,"tv":0.0,"id":16586500},{"batb":[[1,4.1,62.94]],"batl":[[0,4.9,28.42]],"ltp":0.0,"tv":0.0,"id":13508964},{"batb":[[1,5,32.48],[2,4.9,13.53]],"batl":[[0,5.9,20.83]],"ltp":0.0,"tv":0.0,"id":16586502}]}]}
{"op":"mcm","clk":"1005226309","pt":1580641562755,"mc":[{"id":"1.168219388","rc":[{"batb":[[0,2.94,21],[1,2.84,10.62],[2,1.01,0.51]],"batl":[[0,3.4,16.8],[1,3.55,19.36],[2,3.55,0]],"ltp":2.8,"tv":310.72,"id":13508961},{"batb":[[0,3.45,16.8],[1,3.2,19.2],[2,1.01,0.51]],"batl":[[0,4,13.44],[1,4.1,14.01],[2,4.1,0]],"ltp":0.0,"tv":0.0,"id":16586500},{"batb":[[0,5.1,34.03]],"ltp":0.0,"tv":0.0,"id":16586502}]}]}
{"op":"mcm","clk":"1005226563","pt":1580641563991,"mc":[{"id":"1.168219388","rc":[{"batb":[[0,2.84,10.62],[1,1.01,0.51],[2,1.01,0]],"batl":[[0,3.55,19.36],[1,3.55,0]],"ltp":2.8,"tv":310.72,"id":13508961},{"batb":[[0,3.2,19.2],[1,1.01,0.51],[2,1.01,0]],"batl":[[0,4.1,14.01],[1,4.1,0]],"ltp":0.0,"tv":0.0,"id":16586500},{"batb":[[1,4.1,49.5]],"batl":[[0,4.9,18.33]],"ltp":0.0,"tv":0.0,"id":13508964},{"batl":[[0,5.9,12.43]],"ltp":0.0,"tv":0.0,"id":16586502}]}]}
{"op":"mcm","clk":"1005227131","pt":1580641566700,"mc":[{"id":"1.168219388","rc":[{"batb":[[0,3.35,37.62],[1,3.3,43.76],[2,3.2,19.2]],"ltp":0.0,"tv":0.0,"id":16586500}]}]}
{"op":"mcm","clk":"1005227809","pt":1580641569478,"mc":[{"id":"1.168219388","rc":[{"batb":[[0,3.25,59.63],[1,3.2,45.49],[2,2.84,10.62]],"ltp":2.8,"tv":310.72,"id":13508961}]}]}
{"op":"mcm","clk":"1005227937","pt":1580641570098,"mc":[{"id":"1.168219388","rc":[{"batb":[[2,3.15,20.06]],"batl":[[1,4.1,13.77]],"ltp":2.8,"tv":310.72,"id":13508961},{"batl":[[0,3.6,18.57],[1,3.85,15.66]],"ltp":0.0,"tv":0.0,"id":16586500},{"batb":[[0,4.2,69.25],[1,4.1,70.04]],"ltp":0.0,"tv":0.0,"id":13508964},{"batb":[[1,5,45.93],[2,1.01,0.51]],"batl":[[0,5.8,12.83]],"ltp":0.0,"tv":0.0,"id":16586502}]}]}
{"op":"mcm","clk":"1005228124","pt":1580641570999,"mc":[{"id":"1.168219388","rc":[{"batl":[[1,3.6,15.96],[2,4.1,13.77]],"ltp":2.8,"tv":310.72,"id":13508961},{"batb":[[2,3.25,18.48]],"batl":[[1,3.8,14.28],[2,3.85,15.66]],"ltp":0.0,"tv":0.0,"id":16586500},{"batb":[[1,4.1,83.48]],"batl":[[0,4.9,28.42]],"ltp":0.0,"tv":0.0,"id":13508964},{"batb":[[2,4.7,10.92]],"batl":[[0,5.7,8.4],[1,5.8,12.83]],"ltp":0.0,"tv":0.0,"id":16586502}]}]}
{"op":"mcm","clk":"1005244787","pt":1580641652631,"mc":[{"id":"1.168219388","rc":[{"batb":[[0,2.98,23.6],[1,1.01,0.51],[2,3.15,0]],"batl":[[0,4.1,13.77],[1,3.6,0],[2,4.1,0]],"ltp":2.8,"tv":310.72,"id":13508961},{"batb":[[0,2.88,25.65],[1,1.01,0.51],[2,3.25,0]],"batl":[[0,3.85,15.66],[1,3.8,0],[2,3.85,0]],"ltp":0.0,"tv":0.0,"id":16586500},{"batb":[[0,4.2,46.85],[1,4.1,70.04]],"batl":[[0,4.9,18.33]],"ltp":0.0,"tv":0.0,"id":13508964},{"batb":[[0,5.1,25.85],[2,1.01,0.51]],"batl":[[0,5.8,12.83],[1,5.8,0]],"ltp":0.0,"tv":0.0,"id":16586502}]}]}
{"op":"mcm","clk":"1005245605","pt":1580641656729,"mc":[{"id":"1.168219388","rc":[{"batb":[[0,3.35,43.81],[1,3.3,42.3],[2,2.98,23.6]],"ltp":2.8,"tv":310.72,"id":13508961},{"batb":[[0,3.25,60.9],[1,3.2,47],[2,2.88,25.65]],"ltp":0.0,"tv":0.0,"id":16586500},{"batb":[[0,4.2,60.26]],"ltp":0.0,"tv":0.0,"id":13508964}]}]}
{"op":"mcm","clk":"1005246215","pt":1580641659617,"mc":[{"id":"1.168219388","rc":[{"batb":[[0,2.98,23.6],[1,1.01,0.51],[2,2.98,0]],"ltp":2.8,"tv":310.72,"id":13508961},{"batb":[[0,2.88,25.65],[1,1.01,0.51],[2,2.88,0]],"ltp":0.0,"tv":0.0,"id":16586500},{"batb":[[0,4.2,46.85]],"ltp":0.0,"tv":0.0,"id":13508964}]}]}
{"op":"mcm","clk":"1005246339","pt":1580641660254,"mc":[{"id":"1.168219388","rc":[{"batb":[[0,5.1,33.95]],"ltp":0.0,"tv":0.0,"id":16586502}]}]}
{"op":"mcm","clk":"1005246846","pt":1580641662558,"mc":[{"id":"1.168219388","rc":[{"batb":[[0,3.05,52.74],[1,3,53.53],[2,2.98,23.6]],"ltp":2.8,"tv":310.72,"id":13508961},{"batb":[[0,3,47.89],[1,2.96,46.02],[2,2.88,25.65]],"ltp":0.0,"tv":0.0,"id":16586500}]}]}
{"op":"mcm","clk":"1005249493","pt":1580641675686,"mc":[{"id":"1.168219388","rc":[{"batb":[[0,2.88,25.65],[1,1.01,0.51],[2,2.88,0]],"ltp":0.0,"tv":0.0,"id":16586500},{"batb":[[1,4.1,20.54]],"ltp":0.0,"tv":0.0,"id":13508964}]}]}
{"op":"mcm","clk":"1005250072","pt":1580641678676,"mc":[{"id":"1.168219388","rc":[{"batb":[[0,3.55,58.43],[1,3.5,37.74],[2,2.88,25.65]],"ltp":0.0,"tv":0.0,"id":16586500},{"batb":[[0,4.3,26.89],[1,4.2,46.85],[2,4.1,20.54]],"ltp":0.0,"tv":0.0,"id":13508964}]}]}
{"op":"mcm","clk":"1005250231","pt":1580641679465,"mc":[{"id":"1.168219388","rc":[{"batl":[[0,3.3,22.66],[1,3.4,16.8],[2,3.7,17.47]],"ltp":2.8,"tv":310.72,"id":13508961},{"batb":[[2,3.45,16.21]],"batl":[[1,4,13.44],[2,4.1,13.85]],"ltp":0.0,"tv":0.0,"id":16586500},{"batb":[[1,4.2,66.68],[2,4.1,13.44]],"batl":[[0,4.9,28.42]],"ltp":0.0,"tv":0.0,"id":13508964},{"batb":[[1,5,32.48],[2,4.9,13.53]],"batl":[[0,5.7,8.4],[1,5.8,12.83]],"ltp":0.0,"tv":0.0,"id":16586502}]}]}
{"op":"mcm","clk":"1005252933","pt":1580641693564,"mc":[{"id":"1.168219388","rc":[{"batb":[[0,2.96,21],[1,2.84,10.54],[2,1.01,0.51]],"batl":[[0,3.4,16.8],[1,3.7,17.47],[2,3.7,0]],"ltp":2.8,"tv":310.72,"id":13508961},{"batb":[[0,3.4,16.8],[1,3.1,21.09],[2,1.01,0.51]],"batl":[[0,4,13.44],[1,4.1,13.85],[2,4.1,0]],"ltp":0.0,"tv":0.0,"id":16586500},{"batb":[[0,4.2,66.68],[1,4.1,13.44],[2,1.01,0.51]],"ltp":0.0,"tv":0.0,"id":13508964}]}]}
{"op":"mcm","clk":"1005253024","pt":1580641694102,"mc":[{"id":"1.168219388","rc":[{"batb":[[0,2.84,10.54],[1,1.01,0.51],[2,1.01,0]],"batl":[[0,3.7,17.47],[1,3.7,0]],"ltp":2.8,"tv":310.72,"id":13508961},{"batb":[[0,3.1,21.09],[1,1.01,0.51],[2,1.01,0]],"batl":[[0,4.1,13.85],[1,4.1,0]],"ltp":0.0,"tv":0.0,"id":16586500},{"batb":[[1,1.01,0.51],[2,1.01,0]],"batl":[[0,4.9,18.33]],"ltp":0.0,"tv":0.0,"id":13508964},{"batl":[[0,5.8,12.83],[1,5.8,0]],"ltp":0.0,"tv":0.0,"id":16586502}]}]}
{"op":"mcm","clk":"1005253490","pt":1580641696612,"mc":[{"id":"1.168219388","rc":[{"batb":[[0,4.2,67.25]],"ltp":0.0,"tv":0.0,"id":13508964}]}]}
{"op":"mcm","clk":"1005254299","pt":1580641700574,"mc":[{"id":"1.168219388","rc":[{"batb":[[0,3.1,59.73],[1,3.05,51.27],[2,2.84,10.54]],"ltp":2.8,"tv":310.72,"id":13508961},{"batb":[[0,3.5,45.03],[1,3.45,39.21],[2,3.1,21.09]],"ltp":0.0,"tv":0.0,"id":16586500},{"batb":[[0,4.3,23.89],[1,4.2,67.25],[2,1.01,0.51]],"ltp":0.0,"tv":0.0,"id":13508964}]}]}
{"op":"mcm","clk":"1005254917","pt":1580641703700,"mc":[{"id":"1.168219388","rc":[{"batb":[[0,2.84,10.54],[1,1.01,0.51],[2,2.84,0]],"ltp":2.8,"tv":310.72,"id":13508961},{"batb":[[0,3.1,21.09],[1,1.01,0.51],[2,3.1,0]],"ltp":0.0,"tv":0.0,"id":16586500},{"batb":[[0,4.2,67.25],[1,1.01,0.51],[2,1.01,0]],"ltp":0.0,"tv":0.0,"id":13508964}]}]}
{"op":"mcm","clk":"1005255504","pt":1580641706720,"mc":[{"id":"1.168219388","rc":[{"batb":[[0,2.92,36.44],[1,2.88,47.8],[2,2.84,10.54]],"ltp":2.8,"tv":310.72,"id":13508961},{"batb":[[0,3.25,46.22],[1,3.2,47.16],[2,3.1,21.09]],"ltp":0.0,"tv":0.0,"id":16586500},{"batb":[[0,4.2,79.93],[1,4.1,49.65],[2,1.01,0.51]],"ltp":0.0,"tv":0.0,"id":13508964}]}]}
{"op":"mcm","clk":"1005255693","pt":1580641707580,"mc":[{"id":"1.168219388","rc":[{"batb":[[0,3.1,21.09],[1,1.01,0.51],[2,3.1,0]],"ltp":0.0,"tv":0.0,"id":16586500},{"batb":[[0,4.2,67.25],[1,1.01,0.51],[2,1.01,0]],"ltp":0.0,"tv":0.0,"id":13508964}]}]}
{"op":"mcm","clk":"1005256340","pt":1580641710685,"mc":[{"id":"1.168219388","rc":[{"batb":[[0,3.75,54.91],[1,3.7,33.02],[2,3.1,21.09]],"ltp":0.0,"tv":0.0,"id":16586500},{"batb":[[0,4.3,35.02],[1,4.2,67.25],[2,1.01,0.51]],"ltp":0.0,"tv":0.0,"id":13508964},{"batb":[[0,5.1,45.95]],"ltp":0.0,"tv":0.0,"id":16586502}]}]}
{"op":"mcm","clk":"1005256536","pt":1580641711698,"mc":[{"id":"1.168219388","rc":[{"batb":[[2,2.84,33.23]],"batl":[[0,3.15,10.39],[1,3.25,18.48],[2,3.4,21.48]],"ltp":2.8,"tv":310.72,"id":13508961},{"batb":[[2,3.65,14.24]],"batl":[[1,4.3,36.99]],"ltp":0.0,"tv":0.0,"id":16586500},{"batb":[[1,4.2,66.7],[2,4.1,13.44]],"batl":[[0,4.9,28.42]],"ltp":0.0,"tv":0.0,"id":13508964},{"batl":[[0,5.8,8.4],[1,5.9,12.67]],"ltp":0.0,"tv":0.0,"id":16586502}]}]}
{"op":"mcm","clk":"1005258762","pt":1580641722627,"mc":[{"id":"1.168219388","rc":[{"batb":[[0,2.84,22.69],[1,2.74,11.72],[2,1.01,0.51]],"batl":[[0,3.25,18.48],[1,3.4,21.48],[2,3.4,0]],"ltp":2.8,"tv":310.72,"id":13508961},{"batb":[[0,3.6,15.96],[1,3.35,17.31],[2,1.01,0.51]],"batl":[[0,4.3,36.99],[1,4.3,0]],"ltp":0.0,"tv":0.0,"id":16586500},{"batb":[[0,5.1,34.28]],"ltp":0.0,"tv":0.0,"id":16586502}]}]}
{"op":"mcm","clk":"1005259036","pt":1580641724110,"mc":[{"id":"1.168219388","rc":[{"batb":[[0,2.74,11.72],[1,1.01,0.51],[2,1.01,0]],"batl":[[0,3.4,21.48],[1,3.4,0]],"ltp":2.8,"tv":310.72,"id":13508961},{"batb":[[0,3.35,17.31],[1,1.01,0.51],[2,1.01,0]],"batl":[[0,4.3,24.39]],"ltp":0.0,"tv":0.0,"id":16586500},{"batb":[[2,1.01,0.51]],"batl":[[0,4.9,18.33]],"ltp":0.0,"tv":0.0,"id":13508964},{"batl":[[0,5.9,12.67],[1,5.9,0]],"ltp":0.0,"tv":0.0,"id":16586502}]}]}
{"op":"mcm","clk":"1005259348","pt":1580641725712,"mc":[{"id":"1.168219388","rc":[{"batb":[[0,2.82,46.03],[1,2.78,52.28],[2,2.74,11.72]],"ltp":2.8,"tv":310.72,"id":13508961},{"batb":[[0,3.5,54.76],[1,3.45,39.11],[2,3.35,17.31]],"ltp":0.0,"tv":0.0,"id":16586500}]}]}
{"op":"mcm","clk":"1005262204","pt":1580641740706,"mc":[{"id":"1.168219388","rc":[{"batb":[[0,3.35,17.31],[1,1.01,0.51],[2,3.35,0]],"ltp":0.0,"tv":0.0,"id":16586500},{"batb":[[0,5.1,33.95],[1,4.9,13.53],[2,1.01,0.51]],"ltp":0.0,"tv":0.0,"id":16586502}]}]}
{"op":"mcm","clk":"1005262758","pt":1580641743694,"mc":[{"id":"1.168219388","rc":[{"batb":[[0,3.9,53.59],[1,3.85,30.03],[2,3.35,17.31]],"ltp":0.0,"tv":0.0,"id":16586500},{"batb":[[0,5.2,20.46],[1,5.1,33.95],[2,4.9,13.53]],"ltp":0.0,"tv":0.0,"id":16586502}]}]}
{"op":"mcm","clk":"1005262942","pt":1580641744587,"mc":[{"id":"1.168219388","rc":[{"batl":[[0,2.98,11.49],[1,3.2,24.71],[2,3.4,21.48]],"ltp":2.8,"tv":310.72,"id":13508961},{"batb":[[2,3.8,12.9]],"batl":[[1,4.5,22.42]],"ltp":0.0,"tv":0.0,"id":16586500},{"batb":[[0,4.3,54.22]],"batl":[[1,5,18.18]],"ltp":0.0,"tv":0.0,"id":13508964},{"batb":[[2,5,13.45]],"ltp":0.0,"tv":0.0,"id":16586502}]}]}
{"op":"mcm","clk":"1005263098","pt":1580641745335,"mc":[{"id":"1.168219388","rc":[{"batb":[[2,2.74,35.25]],"batl":[[1,3.15,19.32],[2,3.2,24.71]],"ltp":2.8,"tv":310.72,"id":13508961},{"batl":[[1,4.4,11.76],[2,4.5,22.42]],"ltp":0.0,"tv":0.0,"id":16586500},{"batb":[[1,4.2,47.42],[2,4.1,13.44]],"batl":[[0,4.9,10.08]],"ltp":0.0,"tv":0.0,"id":13508964},{"batl":[[0,5.8,8.4],[1,5.9,12.51]],"ltp":0.0,"tv":0.0,"id":16586502}]}]}
{"op":"mcm","clk":"1005265143","pt":1580641755701,"mc":[{"id":"1.168219388","rc":[{"batb":[[0,2.74,35.25],[1,2.66,12.51],[2,1.01,0.51]],"ltp":2.8,"tv":310.72,"id":13508961},{"batb":[[0,3.8,12.9],[1,3.75,15.12],[2,3.55,14.95]],"ltp":0.0,"tv":0.0,"id":16586500},{"batb":[[0,5.1,33.95],[1,5,13.45],[2,4.8,10.92]],"ltp":0.0,"tv":0.0,"id":16586502}]}]}
{"op":"mcm","clk":"1005265311","pt":1580641756606,"mc":[{"id":"1.168219388","rc":[{"batb":[[0,2.66,12.51],[1,1.01,0.51],[2,1.01,0]],"batl":[[0,3.2,24.71],[1,3.15,0],[2,3.2,0]],"ltp":2.8,"tv":310.72,"id":13508961},{"batb":[[0,3.55,14.95],[1,1.01,0.51],[2,3.55,0]],"batl":[[0,4.5,22.42],[1,4.4,0],[2,4.5,0]],"ltp":0.0,"tv":0.0,"id":16586500},{"batb":[[2,1.01,0.51]],"batl":[[0,5,18.18],[1,5,0]],"ltp":0.0,"tv":0.0,"id":13508964},{"batb":[[2,1.01,0.51]],"batl":[[0,5.9,12.51],[1,5.9,0]],"ltp":0.0,"tv":0.0,"id":16586502}]}]}
{"op":"mcm","clk":"1005265703","pt":1580641758719,"mc":[{"id":"1.168219388","rc":[{"batb":[[0,2.76,57.61],[1,2.72,55.34],[2,2.66,12.51]],"ltp":2.8,"tv":310.72,"id":13508961},{"batb":[[0,3.75,37.64],[1,3.7,33.16],[2,3.55,14.95]],"ltp":0.0,"tv":0.0,"id":16586500},{"batb":[[1,5,46.08]],"ltp":0.0,"tv":0.0,"id":16586502}]}]}
{"op":"mcm","clk":"1005266433","pt":1580641762636,"mc":[{"id":"1.168219388","rc":[{"batb":[[0,3.55,14.95],[1,1.01,0.51],[2,3.55,0]],"ltp":0.0,"tv":0.0,"id":16586500},{"batb":[[1,5,13.45]],"ltp":0.0,"tv":0.0,"id":16586502}]}]}
{"op":"mcm","clk":"1005267074","pt":1580641765723,"mc":[{"id":"1.168219388","rc":[{"batb":[[0,4,49.56],[1,3.95,28.29],[2,3.55,14.95]],"ltp":0.0,"tv":0.0,"id":16586500},{"batb":[[0,5.2,27.5],[1,5.1,33.95],[2,5,13.45]],"ltp":0.0,"tv":0.0,"id":16586502}]}]}
{"op":"mcm","clk":"1005267266","pt":1580641766632,"mc":[{"id":"1.168219388","rc":[{"batl":[[0,2.9,12.27],[1,3.15,25.65]],"ltp":2.8,"tv":310.72,"id":13508961},{"batb":[[2,3.9,23.76]],"batl":[[1,5.3,15.74]],"ltp":0.0,"tv":0.0,"id":16586500},{"batb":[[1,4.2,67.25]],"batl":[[0,5.1,17.31]],"ltp":0.0,"tv":0.0,"id":13508964},{"batb":[[2,5,13.3]],"batl":[[0,5.9,12.27]],"ltp":0.0,"tv":0.0,"id":16586502}]}]}
{"op":"mcm","clk":"1005267464","pt":1580641767425,"mc":[{"id":"1.168219388","rc":[{"batb":[[2,2.66,37.72]],"batl":[[1,3.05,20.16],[2,3.15,25.65]],"ltp":2.8,"tv":310.72,"id":13508961},{"batb":[[2,3.9,38.05]],"batl":[[1,4.7,10.92],[2,5.3,15.74]],"ltp":0.0,"tv":0.0,"id":16586500},{"batb":[[2,4.1,13.44]],"batl":[[0,4.9,10.08],[1,5.1,17.31]],"ltp":0.0,"tv":0.0,"id":13508964},{"batl":[[1,6,8.4]],"ltp":0.0,"tv":0.0,"id":16586502}]}]}
{"op":"mcm","clk":"1005272140","pt":1580641791646,"mc":[{"id":"1.168219388","rc":[{"batb":[[0,2.66,25.21],[1,2.4,16.76],[2,1.01,0.51]],"batl":[[0,3.05,20.16],[1,3.15,25.65],[2,3.15,0]],"ltp":2.8,"tv":310.72,"id":13508961},{"batb":[[0,3.9,14.28],[1,3.65,14.16],[2,1.01,0.51]],"batl":[[0,4.7,10.92],[1,5.3,15.74],[2,5.3,0]],"ltp":0.0,"tv":0.0,"id":16586500},{"batb":[[0,4.2,67.25],[1,4.1,13.44],[2,1.01,0.51]],"ltp":0.0,"tv":0.0,"id":13508964},{"batb":[[0,5.1,33.95],[1,5,13.3],[2,4.9,10.08]],"ltp":0.0,"tv":0.0,"id":16586502}]}]}
{"op":"mcm","clk":"1005272259","pt":1580641792209,"mc":[{"id":"1.168219388","rc":[{"batb":[[0,2.4,16.76],[1,1.01,0.51],[2,1.01,0]],"batl":[[0,3.15,25.65],[1,3.15,0]],"ltp":2.8,"tv":310.72,"id":13508961},{"batb":[[0,3.65,14.16],[1,1.01,0.51],[2,1.01,0]],"batl":[[0,5.3,15.74],[1,5.3,0]],"ltp":0.0,"tv":0.0,"id":16586500},{"batb":[[1,1.01,0.51],[2,1.01,0]],"batl":[[0,5.1,17.31],[1,5.1,0]],"ltp":0.0,"tv":0.0,"id":13508964},{"batb":[[2,1.01,0.51]],"batl":[[1,6,0]],"ltp":0.0,"tv":0.0,"id":16586502}]}]}
{"op":"mcm","clk":"1005273039","pt":1580641796403,"mc":[{"id":"1.168219388","rc":[{"batb":[[0,2.7,57.79],[1,2.66,58.59],[2,2.4,16.76]],"ltp":2.8,"tv":310.72,"id":13508961},{"batb":[[0,4.1,55.23],[1,4,54.14],[2,3.65,14.16]],"ltp":0.0,"tv":0.0,"id":16586500},{"batb":[[0,4.3,44.62],[1,4.2,67.25],[2,1.01,0.51]],"ltp":0.0,"tv":0.0,"id":13508964},{"batb":[[0,5.2,31.5],[1,5.1,33.95],[2,5,13.3]],"ltp":0.0,"tv":0.0,"id":16586502}]}]}
{"op":"mcm","clk":"1005273801","pt":1580641800540,"mc":[{"id":"1.168219388","rc":[{"batb":[[0,2.4,16.76],[1,1.01,0.51],[2,2.4,0]],"ltp":2.8,"tv":310.72,"id":13508961},{"batb":[[0,3.65,14.16],[1,1.01,0.51],[2,3.65,0]],"ltp":0.0,"tv":0.0,"id":16586500},{"batb":[[0,4.2,67.25],[1,1.01,0.51],[2,1.01,0]],"ltp":0.0,"tv":0.0,"id":13508964},{"batb":[[0,5.1,33.95],[1,5,13.3],[2,1.01,0.51]],"ltp":0.0,"tv":0.0,"id":16586502}]}]}
{"op":"mcm","clk":"1005274346","pt":1580641803451,"mc":[{"id":"1.168219388","rc":[{"batb":[[0,2.48,69.97],[1,2.44,73.84],[2,2.4,16.76]],"ltp":2.8,"tv":310.72,"id":13508961},{"batb":[[0,3.7,57.1],[1,3.65,48.21],[2,1.01,0.51]],"ltp":0.0,"tv":0.0,"id":16586500},{"batb":[[0,4.2,82.82],[1,4.1,49.47],[2,1.01,0.51]],"ltp":0.0,"tv":0.0,"id":13508964},{"batb":[[0,5.1,47.52],[1,5,45.79]],"ltp":0.0,"tv":0.0,"id":16586502}]}]}
{"op":"mcm","clk":"1005274612","pt":1580641804836,"mc":[{"id":"1.168219388","rc":[{"batb":[[0,2.4,16.76],[1,1.01,0.51],[2,2.4,0]],"ltp":2.8,"tv":310.72,"id":13508961}]}]}
{"op":"mcm","clk":"1005275332","pt":1580641808755,"mc":[{"id":"1.168219388","rc":[{"batb":[[0,2.96,45.09],[1,2.92,46.08],[2,2.86,10.46]],"batl":[[1,3.35,22.03]],"ltp":2.8,"tv":310.72,"id":13508961},{"batb":[[2,3.45,16.21]],"batl":[[0,4.1,13.77],[1,4.7,20.14]],"ltp":0.0,"tv":0.0,"id":16586500},{"batl":[[0,4.9,18.88],[1,5,18.02]],"ltp":0.0,"tv":0.0,"id":13508964},{"batb":[[1,5,32.49],[2,4.9,13.61]],"ltp":0.0,"tv":0.0,"id":16586502}]}]}
{"op":"mcm","clk":"1005275393","pt":1580641809178,"mc":[{"id":"1.168219388","rc":[{"batl":[[1,3.25,18.48],[2,3.35,22.03]],"ltp":2.8,"tv":310.72,"id":13508961},{"batb":[[0,3.7,72.22]],"batl":[[1,4.4,11.76],[2,4.7,20.14]],"ltp":0.0,"tv":0.0,"id":16586500},{"batb":[[2,4,13.44]],"batl":[[0,4.8,10.92],[1,4.9,18.88],[2,5,18.02]],"ltp":0.0,"tv":0.0,"id":13508964},{"batl":[[0,5.9,20.68]],"ltp":0.0,"tv":0.0,"id":16586502}]}]}
{"op":"mcm","clk":"1005278060","pt":1580641823453,"mc":[{"id":"1.168219388","rc":[{"batb":[[0,2.78,23.53],[1,2.58,13.77],[2,1.01,0.51]],"batl":[[0,3.25,18.48],[1,3.35,22.03],[2,3.35,0]],"ltp":2.8,"tv":310.72,"id":13508961},{"batb":[[0,3.7,15.12],[1,3.45,16.21],[2,1.01,0.51]],"batl":[[0,4.4,11.76],[1,4.7,20.14],[2,4.7,0]],"ltp":0.0,"tv":0.0,"id":16586500},{"batb":[[0,4.2,68.23]],"batl":[[1,5,18.02],[2,5,0]],"ltp":0.0,"tv":0.0,"id":13508964},{"batb":[[0,5.1,37.52]],"ltp":0.0,"tv":0.0,"id":16586502}]}]}
{"op":"mcm","clk":"1005278185","pt":1580641824180,"mc":[{"id":"1.168219388","rc":[{"batb":[[0,2.58,13.77],[1,1.01,0.51],[2,1.01,0]],"batl":[[0,3.35,22.03],[1,3.35,0]],"ltp":2.8,"tv":310.72,"id":13508961},{"batb":[[0,3.45,16.21],[1,1.01,0.51],[2,1.01,0]],"batl":[[0,4.7,20.14],[1,4.7,0]],"ltp":0.0,"tv":0.0,"id":16586500},{"batb":[[2,1.01,0.51]],"batl":[[0,5,18.02],[1,5,0]],"ltp":0.0,"tv":0.0,"id":13508964},{"batl":[[0,5.9,12.27]],"ltp":0.0,"tv":0.0,"id":16586502}]}]}
{"op":"mcm","clk":"1005278644","pt":1580641826685,"mc":[{"id":"1.168219388","rc":[{"batb":[[0,2.7,47.52],[1,2.66,58.69],[2,2.58,13.77]],"ltp":2.8,"tv":310.72,"id":13508961},{"batb":[[0,3.5,58.13],[1,3.45,55.22],[2,1.01,0.51]],"ltp":0.0,"tv":0.0,"id":16586500}]}]}
{"op":"mcm","clk":"1005279156","pt":1580641829593,"mc":[{"id":"1.168219388","rc":[{"batb":[[0,2.58,13.77],[1,1.01,0.51],[2,2.58,0]],"ltp":2.8,"tv":310.72,"id":13508961}]}]}
{"op":"mcm","clk":"1005279715","pt":1580641832549,"mc":[{"id":"1.168219388","rc":[{"batb":[[0,3.1,73.5],[1,3.05,51.12],[2,2.58,13.77]],"ltp":2.8,"tv":310.72,"id":13508961}]}]}
{"op":"mcm","clk":"1005279820","pt":1580641833130,"mc":[{"id":"1.168219388","rc":[{"batb":[[2,3,22.9]],"batl":[[1,3.4,16.8],[2,3.5,19.75]],"ltp":2.8,"tv":310.72,"id":13508961},{"batb":[[0,3.5,74.93],[2,3.25,18.33]],"batl":[[0,3.85,15.66],[1,4.1,13.44],[2,4.2,12.9]],"ltp":0.0,"tv":0.0,"id":16586500},{"batb":[[2,4,13.44]],"batl":[[0,4.8,10.92],[1,4.9,18.96]],"ltp":0.0,"tv":0.0,"id":13508964},{"batl":[[0,5.8,8.4],[1,5.9,12.27]],"ltp":0.0,"tv":0.0,"id":16586502}]}]}
{"op":"mcm","clk":"1005282777","pt":1580641848674,"mc":[{"id":"1.168219388","rc":[{"batb":[[0,3,22.9],[1,2.94,21],[2,2.8,11.02]],"ltp":2.8,"tv":310.72,"id":13508961},{"batb":[[0,3.5,16.8],[1,3.45,16.21]],"ltp":0.0,"tv":0.0,"id":16586500},{"batb":[[0,4.2,66.68]],"ltp":0.0,"tv":0.0,"id":13508964},{"batb":[[0,5.1,33.95]],"ltp":0.0,"tv":0.0,"id":16586502}]}]}
{"op":"mcm","clk":"1005282913","pt":1580641849357,"mc":[{"id":"1.168219388","rc":[{"batb":[[0,2.94,21],[1,2.8,11.02],[2,1.01,0.51]],"batl":[[0,3.4,16.8],[1,3.5,19.75],[2,3.5,0]],"ltp":2.8,"tv":310.72,"id":13508961},{"batb":[[1,3.25,18.33],[2,1.01,0.51]],"batl":[[0,4.1,13.44],[1,4.2,12.9],[2,4.2,0]],"ltp":0.0,"tv":0.0,"id":16586500}]}]}
{"op":"mcm","clk":"1005283069","pt":1580641850165,"mc":[{"id":"1.168219388","rc":[{"batb":[[0,2.8,11.02],[1,1.01,0.51],[2,1.01,0]],"batl":[[0,3.5,19.75],[1,3.5,0]],"ltp":2.8,"tv":310.72,"id":13508961},{"batb":[[0,3.25,18.33],[1,1.01,0.51],[2,1.01,0]],"batl":[[0,4.2,12.9],[1,4.2,0]],"ltp":0.0,"tv":0.0,"id":16586500},{"batb":[[2,1.01,0.51]],"batl":[[0,4.9,18.96],[1,4.9,0]],"ltp":0.0,"tv":0.0,"id":13508964},{"batl":[[0,5.9,12.27],[1,5.9,0]],"ltp":0.0,"tv":0.0,"id":16586502}]}]}
{"op":"mcm","clk":"1005283367","pt":1580641851580,"mc":[{"id":"1.168219388","rc":[{"batb":[[0,2.92,50.23],[1,2.88,47.7],[2,2.8,11.02]],"ltp":2.8,"tv":310.72,"id":13508961},{"batb":[[0,3.4,36.36],[1,3.35,42.1],[2,3.25,18.33]],"ltp":0.0,"tv":0.0,"id":16586500}]}]}
{"op":"mcm","clk":"1005283595","pt":1580641852758,"mc":[{"id":"1.168219388","rc":[{"batb":[[0,2.8,11.02],[1,1.01,0.51],[2,2.8,0]],"ltp":2.8,"tv":310.72,"id":13508961},{"batb":[[0,3.25,18.33],[1,1.01,0.51],[2,3.25,0]],"ltp":0.0,"tv":0.0,"id":16586500}]}]}
{"op":"mcm","clk":"1005284137","pt":1580641855721,"mc":[{"id":"1.168219388","rc":[{"batb":[[0,3.25,48.41],[1,3.2,45.54],[2,3.15,20.46]],"batl":[[1,3.55,15.96],[2,3.65,18.1]],"ltp":2.8,"tv":310.72,"id":13508961},{"batb":[[0,3.4,36.36],[1,3.35,59.74],[2,3.25,18.33]],"batl":[[0,3.65,17.7],[1,3.95,15.19],[2,4,13.44]],"ltp":0.0,"tv":0.0,"id":16586500},{"batb":[[2,4,13.44]],"batl":[[0,4.8,10.92],[1,4.9,18.96]],"ltp":0.0,"tv":0.0,"id":13508964},{"batl":[[0,5.7,8.4],[1,5.8,12.83]],"ltp":0.0,"tv":0.0,"id":16586502}]}]}
{"op":"mcm","clk":"1005285466","pt":1580641862722,"mc":[{"id":"1.168219388","rc":[{"batb":[[0,3.05,20.16],[1,2.96,24.08],[2,1.01,0.51]],"batl":[[0,3.55,15.96],[1,3.65,18.1],[2,3.65,0]],"ltp":2.8,"tv":310.72,"id":13508961},{"batb":[[0,3.35,17.64],[1,3.2,19.67],[2,1.01,0.51]],"batl":[[0,3.95,15.19],[1,4,13.44],[2,4,0]],"ltp":0.0,"tv":0.0,"id":16586500},{"batb":[[0,5.1,25.85]],"ltp":0.0,"tv":0.0,"id":16586502}]}]}
{"op":"mcm","clk":"1005285741","pt":1580641864217,"mc":[{"id":"1.168219388","rc":[{"batb":[[0,2.96,24.08],[1,1.01,0.51],[2,1.01,0]],"batl":[[0,3.65,18.1],[1,3.65,0]],"ltp":2.8,"tv":310.72,"id":13508961},{"batb":[[0,3.2,19.67],[1,1.01,0.51],[2,1.01,0]],"batl":[[1,4,0]],"ltp":0.0,"tv":0.0,"id":16586500},{"batb":[[2,1.01,0.51]],"batl":[[0,4.9,18.96],[1,4.9,0]],"ltp":0.0,"tv":0.0,"id":13508964},{"batl":[[0,5.8,12.83],[1,5.8,0]],"ltp":0.0,"tv":0.0,"id":16586502}]}]}
{"op":"mcm","clk":"1005285988","pt":1580641865638,"mc":[{"id":"1.168219388","rc":[{"batb":[[0,3.1,62.13],[1,3.05,51.21],[2,2.96,24.08]],"ltp":2.8,"tv":310.72,"id":13508961},{"batb":[[0,3.3,65.3],[1,3.25,45.11],[2,3.2,19.67]],"ltp":0.0,"tv":0.0,"id":16586500}]}]}
{"op":"mcm","clk":"1005289185","pt":1580641882457,"mc":[{"id":"1.168219388","rc":[{"batb":[[0,2.96,24.08],[1,1.01,0.51],[2,2.96,0]],"ltp":2.8,"tv":310.72,"id":13508961},{"batb":[[0,3.2,19.67],[1,1.01,0.51],[2,3.2,0]],"ltp":0.0,"tv":0.0,"id":16586500}]}]}
{"op":"mcm","clk":"1005289792","pt":1580641885750,"mc":[{"id":"1.168219388","rc":[{"batb":[[0,3.2,67.59],[1,3.15,47.17],[2,2.96,24.08]],"ltp":2.8,"tv":310.72,"id":13508961},{"batb":[[0,3.4,61.03],[1,3.35,41.9],[2,3.2,19.67]],"ltp":0.0,"tv":0.0,"id":16586500}]}]}
{"op":"mcm","clk":"1005291076","pt":1580641892481,"mc":[{"id":"1.168219388","rc":[{"batb":[[0,2.96,24.08],[1,1.01,0.51],[2,2.96,0]],"ltp":2.8,"tv":310.72,"id":13508961},{"batb":[[0,3.2,19.67],[1,1.01,0.51],[2,3.2,0]],"ltp":0.0,"tv":0.0,"id":16586500}]}]}
{"op":"mcm","clk":"1005291637","pt":1580641895460,"mc":[{"id":"1.168219388","rc":[{"batb":[[0,3.1,63.42],[1,3.05,51.21],[2,2.96,24.08]],"ltp":2.8,"tv":310.72,"id":13508961},{"batb":[[0,3.3,64.22],[1,3.25,45.11],[2,3.2,19.67]],"ltp":0.0,"tv":0.0,"id":16586500}]}]}
{"op":"mcm","clk":"1005292186","pt":1580641898476,"mc":[{"id":"1.168219388","rc":[{"batb":[[0,2.96,24.08],[1,1.01,0.51],[2,2.96,0]],"ltp":2.8,"tv":310.72,"id":13508961}]}]}
{"op":"mcm","clk":"1005292681","pt":1580641901239,"mc":[{"id":"1.168219388","rc":[{"batb":[[0,3.3,66.8],[1,3.25,43.63],[2,3.2,18.48]],"batl":[[1,3.75,15.12]],"ltp":2.8,"tv":310.72,"id":13508961},{"batb":[[1,3.25,63.59]],"batl":[[0,3.8,14.28],[1,3.95,15.19]],"ltp":0.0,"tv":0.0,"id":16586500},{"batb":[[2,4,13.44]],"batl":[[0,4.8,10.92],[1,4.9,18.96]],"ltp":0.0,"tv":0.0,"id":13508964},{"batl":[[0,5.6,8.4],[1,5.8,12.83]],"ltp":0.0,"tv":0.0,"id":16586502}]}]}
{"op":"mcm","clk":"1005292889","pt":1580641902363,"mc":[{"id":"1.168219388","rc":[{"batb":[[1,3.25,62.36]],"batl":[[2,4.3,24.63]],"ltp":2.8,"tv":310.72,"id":13508961},{"batl":[[0,3.55,18.96],[1,3.8,14.28],[2,3.85,15.97]],"ltp":0.0,"tv":0.0,"id":16586500},{"batb":[[0,4.2,46.85],[1,4.1,70.4]],"ltp":0.0,"tv":0.0,"id":13508964},{"batl":[[1,5.7,13.3]],"ltp":0.0,"tv":0.0,"id":16586502}]}]}
{"op":"mcm","clk":"1005293469","pt":1580641905272,"mc":[{"id":"1.168219388","rc":[{"batb":[[0,3.3,48.67]],"ltp":2.8,"tv":310.72,"id":13508961},{"batb":[[0,3.3,43.84],[1,3.25,18.48]],"ltp":0.0,"tv":0.0,"id":16586500},{"batb":[[0,4.2,32.13]],"ltp":0.0,"tv":0.0,"id":13508964}]}]}
{"op":"mcm","clk":"1005294093","pt":1580641908286,"mc":[{"id":"1.168219388","rc":[{"batb":[[0,3.35,40],[1,3.3,43.84],[2,3.25,18.48]],"ltp":0.0,"tv":0.0,"id":16586500},{"batb":[[0,5.1,33.25]],"ltp":0.0,"tv":0.0,"id":16586502}]}]}
{"op":"mcm","clk":"1005294469","pt":1580641909980,"mc":[{"id":"1.168219388","rc":[{"batl":[[0,3.6,18.25]],"ltp":2.8,"tv":310.72,"id":13508961},{"batl":[[0,3.6,18.73],[2,3.85,15.74]],"ltp":0.0,"tv":0.0,"id":16586500},{"batl":[[0,4.8,30.2],[1,4.9,0]],"ltp":0.0,"tv":0.0,"id":13508964}]}]}
{"op":"mcm","clk":"1005295486","pt":1580641915193,"mc":[{"id":"1.168219388","rc":[{"batb":[[0,3.3,32.13]],"ltp":2.8,"tv":310.72,"id":13508961},{"batb":[[0,4.1,70.4],[1,4,13.44],[2,1.01,0.51]],"ltp":0.0,"tv":0.0,"id":13508964}]}]}
{"op":"mcm","clk":"1005296167","pt":1580641918692,"mc":[{"id":"1.168219388","rc":[{"batb":[[1,3.25,43.63],[2,3.2,37.68]],"batl":[[2,4.2,25.65]],"ltp":2.8,"tv":310.72,"id":13508961},{"batb":[[0,3.35,58.43]],"batl":[[0,3.6,18.49],[2,3.9,15.5]],"ltp":0.0,"tv":0.0,"id":16586500},{"batb":[[0,4.1,91.54],[1,4,65.29]],"ltp":0.0,"tv":0.0,"id":13508964},{"batb":[[0,5.1,43.92]],"batl":[[1,5.8,13.06]],"ltp":0.0,"tv":0.0,"id":16586502}]}]}
{"op":"mcm","clk":"1005296871","pt":1580641922683,"mc":[{"id":"1.168219388","rc":[{"batb":[[0,3.25,43.63],[1,3.2,37.68],[2,3,22.58]],"ltp":2.8,"tv":310.72,"id":13508961},{"batb":[[0,3.35,42.62],[1,3.25,18.48],[2,3.2,19.12]],"ltp":0.0,"tv":0.0,"id":16586500},{"batb":[[0,4.1,79.92]],"ltp":0.0,"tv":0.0,"id":13508964},{"batb":[[0,5.1,33.25],[1,4.9,13.61],[2,4.6,10.92]],"ltp":0.0,"tv":0.0,"id":16586502}]}]}
{"op":"mcm","clk":"1005297412","pt":1580641925646,"mc":[{"id":"1.168219388","rc":[{"batb":[[0,3.25,60.15],[1,3.2,82.57]],"ltp":2.8,"tv":310.72,"id":13508961},{"batb":[[0,3.4,33.23],[1,3.35,42.62],[2,3.25,18.48]],"ltp":0.0,"tv":0.0,"id":16586500},{"batb":[[0,5.2,21.96],[1,5.1,33.25],[2,4.9,13.61]],"ltp":0.0,"tv":0.0,"id":16586502}]}]}
{"op":"mcm","clk":"1005297579","pt":1580641926553,"mc":[{"id":"1.168219388","rc":[{"batl":[[2,4.2,12.98]],"ltp":2.8,"tv":310.72,"id":13508961},{"batb":[[2,3.25,37.37]],"batl":[[0,3.6,18.25],[2,3.9,15.34]],"ltp":0.0,"tv":0.0,"id":16586500},{"batb":[[0,4.1,58.99],[1,4,87.09]],"ltp":0.0,"tv":0.0,"id":13508964},{"batb":[[2,5,13.45]],"batl":[[1,5.8,12.9]],"ltp":0.0,"tv":0.0,"id":16586502}]}]}
{"op":"mcm","clk":"1005301634","pt":1580641950691,"mc":[{"id":"1.168219388","rc":[{"batl":[[0,3.55,18.96],[1,3.6,18.25],[2,3.75,15.12]],"ltp":2.8,"tv":310.72,"id":13508961},{"batl":[[1,3.65,18.02],[2,3.8,14.28]],"ltp":0.0,"tv":0.0,"id":16586500}]}]}
{"op":"mcm","clk":"1005301768","pt":1580641951694,"mc":[{"id":"1.168219388","rc":[{"batb":[[2,2.98,23.37]],"batl":[[1,3.75,15.12],[2,4.2,12.98]],"ltp":2.8,"tv":310.72,"id":13508961},{"batb":[[2,3.25,37.13]],"batl":[[0,3.65,18.02],[1,3.8,14.28],[2,3.95,15.11]],"ltp":0.0,"tv":0.0,"id":16586500},{"batb":[[2,5,13.3]],"batl":[[1,5.8,12.75]],"ltp":0.0,"tv":0.0,"id":16586502}]}]}
{"op":"mcm","clk":"1005307541","pt":1580641985450,"mc":[{"id":"1.168219388","rc":[{"batb":[[0,3.2,18.48],[1,2.98,23.37],[2,1.01,0.51]],"batl":[[0,3.75,15.12],[1,4.2,12.98],[2,4.2,0]],"ltp":2.8,"tv":310.72,"id":13508961},{"batb":[[0,3.25,18.48],[1,2.9,25.34],[2,1.01,0.51]],"batl":[[0,3.8,14.28],[1,3.95,15.11],[2,3.95,0]],"ltp":0.0,"tv":0.0,"id":16586500},{"batb":[[0,4,35.24],[1,1.01,0.51],[2,1.01,0]],"ltp":0.0,"tv":0.0,"id":13508964},{"batb":[[0,5,13.3],[1,4.6,10.92],[2,1.01,0.51]],"ltp":0.0,"tv":0.0,"id":16586502}]}]}
{"op":"mcm","clk":"1005307693","pt":1580641986254,"mc":[{"id":"1.168219388","rc":[{"batb":[[0,2.98,23.37],[1,1.01,0.51],[2,1.01,0]],"batl":[[0,4.2,12.98],[1,4.2,0]],"ltp":2.8,"tv":310.72,"id":13508961},{"batb":[[0,2.9,25.34],[1,1.01,0.51],[2,1.01,0]],"batl":[[0,3.95,15.11],[1,3.95,0]],"ltp":0.0,"tv":0.0,"id":16586500},{"batb":[[0,4,21.79]],"batl":[[0,4.8,19.28]],"ltp":0.0,"tv":0.0,"id":13508964},{"batb":[[1,1.01,0.51],[2,1.01,0]],"batl":[[0,5.8,12.75],[1,5.8,0]],"ltp":0.0,"tv":0.0,"id":16586502}]}]}
{"op":"mcm","clk":"1005308077","pt":1580641988546,"mc":[{"id":"1.168219388","rc":[{"batb":[[0,3.05,44.32],[1,3,52.94],[2,2.98,23.37]],"ltp":2.8,"tv":310.72,"id":13508961},{"batb":[[0,3,60.92],[1,2.96,46.33],[2,2.9,25.34]],"ltp":0.0,"tv":0.0,"id":16586500},{"batb":[[0,4.1,32.51],[1,4,74.25],[2,1.01,0.51]],"ltp":0.0,"tv":0.0,"id":13508964},{"batb":[[0,5.1,43.18],[1,5,46.44],[2,1.01,0.51]],"ltp":0.0,"tv":0.0,"id":16586502}]}]}
{"op":"mcm","clk":"1005308905","pt":1580641992660,"mc":[{"id":"1.168219388","rc":[{"batb":[[0,2.98,23.37],[1,1.01,0.51],[2,2.98,0]],"ltp":2.8,"tv":310.72,"id":13508961}]}]}
{"op":"mcm","clk":"1005309420","pt":1580641995646,"mc":[{"id":"1.168219388","rc":[{"batb":[[0,3.8,27.01],[1,3.75,30.72],[2,2.98,23.37]],"ltp":2.8,"tv":310.72,"id":13508961}]}]}
{"op":"mcm","clk":"1005309568","pt":1580641996436,"mc":[{"id":"1.168219388","rc":[{"batb":[[2,3.7,13.53]],"batl":[[1,5.5,14.56]],"ltp":2.8,"tv":310.72,"id":13508961},{"batl":[[0,3.2,24.31],[1,3.5,19.83]],"ltp":0.0,"tv":0.0,"id":16586500},{"batl":[[0,4.7,20.22]],"ltp":0.0,"tv":0.0,"id":13508964}]}]}
{"op":"mcm","clk":"1005309776","pt":1580641997641,"mc":[{"id":"1.168219388","rc":[{"batl":[[1,4.3,12.6],[2,5.5,14.56]],"ltp":2.8,"tv":310.72,"id":13508961},{"batb":[[1,4,87.7]],"batl":[[0,4.7,31.14]],"ltp":0.0,"tv":0.0,"id":13508964},{"batb":[[2,4.6,10.92]],"batl":[[0,5.6,8.4],[1,5.8,12.75]],"ltp":0.0,"tv":0.0,"id":16586502}]}]}
{"op":"mcm","clk":"1005309946","pt":1580641998745,"mc":[{"id":"1.168219388","rc":[{"batb":[[1,2.96,67.33]],"batl":[[1,3.4,16.8],[2,3.5,19.83]],"ltp":0.0,"tv":0.0,"id":16586500}]}]}
{"op":"mcm","clk":"1005310740","pt":1580642003352,"mc":[{"id":"1.168219388","rc":[{"batb":[[0,3.75,30.72],[1,3.7,13.53],[2,3.6,15.96]],"ltp":2.8,"tv":310.72,"id":13508961},{"batb":[[0,4,87.7],[1,1.01,0.51],[2,1.01,0]],"ltp":0.0,"tv":0.0,"id":13508964}]}]}
{"op":"mcm","clk":"1005311335","pt":1580642006742,"mc":[{"id":"1.168219388","rc":[{"batb":[[0,3.6,15.96],[1,3.35,17.62],[2,1.01,0.51]],"batl":[[0,4.3,12.6],[1,5.5,14.56],[2,5.5,0]],"ltp":2.8,"tv":310.72,"id":13508961},{"batb":[[0,2.96,21],[1,2.52,14.71],[2,1.01,0.51]],"batl":[[0,3.4,16.8],[1,3.5,19.83],[2,3.5,0]],"ltp":0.0,"tv":0.0,"id":16586500},{"batb":[[0,4,65.73],[1,3.95,26.88],[2,1.01,0.51]],"ltp":0.0,"tv":0.0,"id":13508964}]}]}
{"op":"mcm","clk":"1005311687","pt":1580642008636,"mc":[{"id":"1.168219388","rc":[{"batb":[[0,3.35,17.62],[1,1.01,0.51],[2,1.01,0]],"batl":[[0,5.5,14.56],[1,5.5,0]],"ltp":2.8,"tv":310.72,"id":13508961},{"batb":[[0,2.52,14.71],[1,1.01,0.51],[2,1.01,0]],"batl":[[0,3.5,19.83],[1,3.5,0]],"ltp":0.0,"tv":0.0,"id":16586500},{"batb":[[0,4,52.28]],"batl":[[0,4.7,20.22]],"ltp":0.0,"tv":0.0,"id":13508964},{"batb":[[2,1.01,0.51]],"batl":[[0,5.8,12.75],[1,5.8,0]],"ltp":0.0,"tv":0.0,"id":16586502}]}]}
{"op":"mcm","clk":"1005311803","pt":1580642009427,"mc":[{"id":"1.168219388","rc":[{"batb":[[0,3.35,73.17],[1,3.3,41.45],[2,1.01,0.51]],"ltp":2.8,"tv":310.72,"id":13508961},{"batb":[[0,2.62,53.5],[1,2.58,66.36],[2,2.52,14.71]],"ltp":0.0,"tv":0.0,"id":16586500}]}]}
{"op":"mcm","clk":"1005311930","pt":1580642010175,"mc":[{"id":"1.168219388","rc":[{"batb":[[0,3.35,55.55],[1,3.3,59.39]],"ltp":2.8,"tv":310.72,"id":13508961},{"batb":[[2,2.54,14.32]],"batl":[[0,3.55,19.04]],"ltp":0.0,"tv":0.0,"id":16586500},{"batb":[[0,4,30.49],[2,3.9,24.16]],"batl":[[0,4.6,21.09]],"ltp":0.0,"tv":0.0,"id":13508964},{"batb":[[1,5,46.28]],"batl":[[0,5.9,12.43]],"ltp":0.0,"tv":0.0,"id":16586502}]}]}
{"op":"mcm","clk":"1005313108","pt":1580642017163,"mc":[{"id":"1.168219388","rc":[{"batb":[[0,3.3,17.94],[1,1.01,0.51],[2,1.01,0]],"ltp":2.8,"tv":310.72,"id":13508961}]}]}
{"op":"mcm","clk":"1005313570","pt":1580642020155,"mc":[{"id":"1.168219388","rc":[{"batb":[[0,4.8,37.45],[1,4.7,35.49],[2,3.3,17.94]],"ltp":2.8,"tv":310.72,"id":13508961}]}]}
{"op":"mcm","clk":"1005313826","pt":1580642021592,"mc":[{"id":"1.168219388","rc":[{"batb":[[1,4.7,50.75],[2,4,22.82]],"batl":[[0,5.4,9.24],[1,5.5,14.56],[2,8.4,11.8]],"ltp":2.8,"tv":310.72,"id":13508961},{"batl":[[0,2.76,14.01],[1,3.05,11.17]],"ltp":0.0,"tv":0.0,"id":16586500},{"batb":[[2,3.9,38.44]],"batl":[[0,4.5,22.82],[1,4.6,32.01]],"ltp":0.0,"tv":0.0,"id":13508964},{"batb":[[2,4.6,10.92]],"batl":[[0,5.6,8.4],[1,5.9,12.43]],"ltp":0.0,"tv":0.0,"id":16586502}]}]}
{"op":"mcm","clk":"1005314184","pt":1580642023657,"mc":[{"id":"1.168219388","rc":[{"batb":[[2,4.5,11.76]],"ltp":2.8,"tv":310.72,"id":13508961},{"batb":[[1,2.6,26.05],[2,2.58,66.36]],"batl":[[1,2.98,21],[2,3.05,11.17]],"ltp":0.0,"tv":0.0,"id":16586500}]}]}
{"op":"mcm","clk":"1005315932","pt":1580642033621,"mc":[{"id":"1.168219388","rc":[{"batb":[[0,4.5,11.76],[1,4,22.82],[2,1.01,0.51]],"batl":[[1,8.4,11.8],[2,8.4,0]],"ltp":2.8,"tv":310.72,"id":13508961},{"batb":[[0,2.6,26.05],[1,2.2,21.32],[2,1.01,0.51]],"batl":[[0,2.62,15.14],[1,3.05,11.17],[2,3.05,0]],"ltp":0.0,"tv":0.0,"id":16586500},{"batb":[[0,3.9,14.28],[1,3.8,12.83],[2,1.01,0.51]],"batl":[[0,4.6,32.01],[1,4.6,0]],"ltp":0.0,"tv":0.0,"id":13508964},{"batl":[[0,5.9,12.43],[1,5.9,0]],"ltp":0.0,"tv":0.0,"id":16586502}]}]}
{"op":"mcm","clk":"1005316054","pt":1580642034318,"mc":[{"id":"1.168219388","rc":[{"batb":[[0,4,22.82],[1,1.01,0.51],[2,1.01,0]],"batl":[[0,8.4,11.8],[1,8.4,0]],"ltp":2.8,"tv":310.72,"id":13508961},{"batb":[[0,2.2,21.32],[1,1.01,0.51],[2,1.01,0]],"ltp":0.0,"tv":0.0,"id":16586500},{"batb":[[0,3.8,12.83],[1,1.01,0.51],[2,1.01,0]],"batl":[[0,4.6,21.09]],"ltp":0.0,"tv":0.0,"id":13508964},{"batb":[[2,1.01,0.51]],"ltp":0.0,"tv":0.0,"id":16586502}]}]}
{"op":"mcm","clk":"1005316431","pt":1580642036627,"mc":[{"id":"1.168219388","rc":[{"batb":[[0,4,99.57],[1,3.95,26.59],[2,1.01,0.51]],"ltp":2.8,"tv":310.72,"id":13508961},{"trd":[[2.62,15.13]],"batb":[[0,2.26,69.53],[1,2.24,49.26],[2,2.2,21.32]],"batl":[[0,2.62,7.58],[1,2.94,21],[2,3.05,11.17]],"ltp":2.62,"tv":15.12,"id":16586500},{"batb":[[0,3.9,35.82],[1,3.85,29.19],[2,3.8,12.83]],"ltp":0.0,"tv":0.0,"id":13508964},{"batl":[[0,5.5,9.24],[1,5.9,12.43]],"ltp":0.0,"tv":0.0,"id":16586502}],"tv":325.85}]}
{"op":"mcm","clk":"1005316490","pt":1580642036897,"mc":[{"id":"1.168219388","rc":[{"batl":[[1,3.05,11.17],[2,3.05,0]],"ltp":2.62,"tv":15.12,"id":16586500},{"batl":[[0,5.9,12.43],[1,5.9,0]],"ltp":0.0,"tv":0.0,"id":16586502}]}]}
{"op":"mcm","clk":"1005316790","pt":1580642038513,"mc":[{"id":"1.168219388","rc":[{"batb":[[0,2.2,21.32],[1,1.01,0.51],[2,2.2,0]],"ltp":2.62,"tv":15.12,"id":16586500},{"batb":[[0,3.8,12.83],[1,1.01,0.51],[2,3.8,0]],"ltp":0.0,"tv":0.0,"id":13508964}]}]}
{"op":"mcm","clk":"1005317210","pt":1580642040725,"mc":[{"id":"1.168219388","rc":[{"trd":[[2.62,30.29]],"batb":[[0,2.88,31.63],[1,2.84,51.76],[2,2.2,21.32]],"batl":[[0,3.05,11.17],[1,3.05,0]],"ltp":2.62,"tv":30.28,"id":16586500},{"batb":[[0,4,58.59],[1,3.95,27.06],[2,3.8,12.83]],"ltp":0.0,"tv":0.0,"id":13508964}],"tv":341.01}]}
{"op":"mcm","clk":"1005317445","pt":1580642041687,"mc":[{"id":"1.168219388","rc":[{"batb":[[0,4,113.01],[2,3.45,15.97]],"batl":[[0,4.6,32.48],[1,7,17.94],[2,8.4,11.8]],"ltp":2.8,"tv":310.72,"id":13508961},{"batb":[[2,2.76,11.41]],"batl":[[1,3.4,20.93]],"ltp":2.62,"tv":30.28,"id":16586500},{"batb":[[0,4,72.03]],"batl":[[1,4.7,10.92]],"ltp":0.0,"tv":0.0,"id":13508964},{"batb":[[2,4.6,10.92]],"batl":[[0,5.5,9.24],[1,5.9,12.43]],"ltp":0.0,"tv":0.0,"id":16586502}]}]}
{"op":"mcm","clk":"1005317478","pt":1580642041896,"mc":[{"id":"1.168219388","rc":[{"batl":[[2,8.4,0]],"ltp":2.8,"tv":310.72,"id":13508961}]}]}
{"op":"mcm","clk":"1005317919","pt":1580642044235,"mc":[{"id":"1.168219388","rc":[{"batb":[[2,2.78,23.53]],"batl":[[1,3.2,18.48],[2,3.4,20.93]],"ltp":2.62,"tv":30.28,"id":16586500}]}]}
{"op":"mcm","clk":"1005318968","pt":1580642049528,"mc":[{"id":"1.168219388","rc":[{"batb":[[0,4,88.15],[1,3.45,15.97],[2,1.01,0.51]],"ltp":2.8,"tv":310.72,"id":13508961}]}]}
{"op":"mcm","clk":"1005319390","pt":1580642051757,"mc":[{"id":"1.168219388","rc":[{"batb":[[0,4,13.44]],"batl":[[0,4.6,10.92]],"ltp":2.8,"tv":310.72,"id":13508961},{"batb":[[0,2.78,23.53],[1,2.34,17.86],[2,1.01,0.51]],"batl":[[0,3.2,18.48],[1,3.4,20.93],[2,3.4,0]],"ltp":2.62,"tv":30.28,"id":16586500},{"batb":[[0,4,13.44],[1,3.8,12.83],[2,1.01,0.51]],"ltp":0.0,"tv":0.0,"id":13508964}]}]}
{"op":"mcm","clk":"1005319585","pt":1580642052735,"mc":[{"id":"1.168219388","rc":[{"batb":[[0,3.45,15.97],[1,1.01,0.51],[2,1.01,0]],"batl":[[0,7,17.94],[1,7,0]],"ltp":2.8,"tv":310.72,"id":13508961},{"batb":[[0,2.34,17.86],[1,1.01,0.51],[2,1.01,0]],"batl":[[0,3.4,20.93],[1,3.4,0]],"ltp":2.62,"tv":30.28,"id":16586500},{"batb":[[0,3.8,12.83],[1,1.01,0.51],[2,1.01,0]],"batl":[[1,4.7,0]],"ltp":0.0,"tv":0.0,"id":13508964},{"batb":[[2,1.01,0.51]],"batl":[[0,5.9,12.43],[1,5.9,0]],"ltp":0.0,"tv":0.0,"id":16586502}]}]}
{"op":"mcm","clk":"1005319910","pt":1580642054536,"mc":[{"id":"1.168219388","rc":[{"batb":[[0,5.1,43.8]],"ltp":0.0,"tv":0.0,"id":16586502}]}]}
{"op":"mcm","clk":"1005320332","pt":1580642057002,"mc":[{"id":"1.168219388","rc":[{"batb":[[0,4.3,53.87],[1,4.2,45.78],[2,3.45,15.97]],"ltp":2.8,"tv":310.72,"id":13508961},{"batb":[[0,2.76,60.69],[1,2.72,57.71],[2,2.34,17.86]],"ltp":2.62,"tv":30.28,"id":16586500},{"batb":[[0,4,46.19],[1,3.95,27.2],[2,3.8,12.83]],"ltp":0.0,"tv":0.0,"id":13508964}]}]}
{"op":"mcm","clk":"1005321016","pt":1580642060734,"mc":[{"id":"1.168219388","rc":[{"batb":[[0,3.45,15.97],[1,1.01,0.51],[2,3.45,0]],"ltp":2.8,"tv":310.72,"id":13508961},{"batb":[[0,2.34,17.86],[1,1.01,0.51],[2,2.34,0]],"ltp":2.62,"tv":30.28,"id":16586500},{"batb":[[0,3.8,12.83],[1,1.01,0.51],[2,3.8,0]],"ltp":0.0,"tv":0.0,"id":13508964}]}]}
{"op":"mcm","clk":"1005321502","pt":1580642063426,"mc":[{"id":"1.168219388","rc":[{"batb":[[0,3.5,35.81],[1,3.45,53.31],[2,1.01,0.51]],"ltp":2.8,"tv":310.72,"id":13508961},{"batb":[[0,2.42,44.77],[1,2.38,82.55],[2,2.34,17.86]],"ltp":2.62,"tv":30.28,"id":16586500},{"batb":[[0,3.9,50.61],[1,3.85,29],[2,3.8,12.83]],"ltp":0.0,"tv":0.0,"id":13508964},{"batb":[[0,5.1,51.18]],"ltp":0.0,"tv":0.0,"id":16586502}]}]}
{"op":"mcm","clk":"1005323865","pt":1580642076761,"mc":[{"id":"1.168219388","rc":[{"batb":[[0,3.45,15.97],[1,1.01,0.51],[2,1.01,0]],"ltp":2.8,"tv":310.72,"id":13508961},{"batb":[[0,5.1,35.66]],"ltp":0.0,"tv":0.0,"id":16586502}]}]}
{"op":"mcm","clk":"1005324419","pt":1580642079764,"mc":[{"id":"1.168219388","rc":[{"batb":[[0,5.9,27.71],[1,5.8,22.18],[2,3.45,15.97]],"ltp":2.8,"tv":310.72,"id":13508961}]}]}
{"op":"mcm","clk":"1005324592","pt":1580642080650,"mc":[{"id":"1.168219388","rc":[{"batb":[[2,5.7,19.28]],"batl":[[1,14.5,10.7]],"ltp":2.8,"tv":310.72,"id":13508961},{"batl":[[0,2.54,17.47],[1,2.8,13.61]],"ltp":2.62,"tv":30.28,"id":16586500},{"batl":[[0,4.4,23.76],[1,4.5,22.66]],"ltp":0.0,"tv":0.0,"id":13508964},{"batl":[[0,5.8,12.67],[1,5.9,12.43]],"ltp":0.0,"tv":0.0,"id":16586502}]}]}
{"op":"mcm","clk":"1005324788","pt":1580642081756,"mc":[{"id":"1.168219388","rc":[{"batl":[[0,6.6,6.72],[1,7,17.94],[2,14.5,10.7]],"ltp":2.8,"tv":310.72,"id":13508961},{"batb":[[0,2.42,74.18]],"batl":[[1,2.72,24.37],[2,2.8,13.61]],"ltp":2.62,"tv":30.28,"id":16586500},{"batb":[[2,3.8,27.11]],"batl":[[1,4.5,34.42]],"ltp":0.0,"tv":0.0,"id":13508964},{"batb":[[2,4.6,10.92]],"batl":[[0,5.5,9.24],[1,5.8,12.67],[2,5.9,12.43]],"ltp":0.0,"tv":0.0,"id":16586502}]}]}
{"op":"mcm","clk":"1005328338","pt":1580642101725,"mc":[{"id":"1.168219388","rc":[{"batb":[[0,2.42,29.41],[1,2.34,17.86],[2,2,28.09]],"ltp":2.62,"tv":30.28,"id":16586500},{"batb":[[0,3.9,28.38],[1,3.8,27.11],[2,3.7,13.45]],"ltp":0.0,"tv":0.0,"id":13508964}]}]}
{"op":"mcm","clk":"1005328463","pt":1580642102331,"mc":[{"id":"1.168219388","rc":[{"batb":[[0,5.1,27.96]],"ltp":0.0,"tv":0.0,"id":16586502}]}]}
{"op":"mcm","clk":"1005328725","pt":1580642103731,"mc":[{"id":"1.168219388","rc":[{"batb":[[0,5.7,19.28],[1,5.4,9.24],[2,4.6,16.13]],"ltp":2.8,"tv":310.72,"id":13508961},{"batb":[[0,3.8,27.11],[1,3.7,13.45],[2,1.01,0.51]],"ltp":0.0,"tv":0.0,"id":13508964}]}]}
{"op":"mcm","clk":"1005328902","pt":1580642104712,"mc":[{"id":"1.168219388","rc":[{"batb":[[0,4.6,16.13],[1,1.01,0.51],[2,4.6,0]],"batl":[[0,14.5,10.7],[1,7,0],[2,14.5,0]],"ltp":2.8,"tv":310.72,"id":13508961},{"batb":[[0,2.4,78.67],[1,2.36,84.29]],"batl":[[0,2.8,13.61],[1,2.72,0],[2,2.8,0]],"ltp":2.62,"tv":30.28,"id":16586500},{"batb":[[0,3.95,26.69]],"batl":[[0,4.5,22.66],[1,4.5,0]],"ltp":0.0,"tv":0.0,"id":13508964},{"batb":[[2,1.01,0.51]],"batl":[[0,5.9,12.43],[1,5.8,0],[2,5.9,0]],"ltp":0.0,"tv":0.0,"id":16586502}]}]}
{"op":"mcm","clk":"1005329049","pt":1580642105529,"mc":[{"id":"1.168219388","rc":[{"batb":[[0,2,28.09],[1,1.01,0.51],[2,2,0]],"ltp":2.62,"tv":30.28,"id":16586500},{"batb":[[0,3.7,13.45],[1,1.01,0.51],[2,1.01,0]],"ltp":0.0,"tv":0.0,"id":13508964}]}]}
{"op":"mcm","clk":"1005329808","pt":1580642109733,"mc":[{"id":"1.168219388","rc":[{"batb":[[0,6.6,20.66],[1,6.4,35.52],[2,4.6,16.13]],"ltp":2.8,"tv":310.72,"id":13508961},{"batb":[[0,2.32,65.82],[1,2.3,45.67],[2,2,28.09]],"ltp":2.62,"tv":30.28,"id":16586500},{"batb":[[0,3.95,26.32],[1,3.9,28.54],[2,3.7,13.45]],"ltp":0.0,"tv":0.0,"id":13508964}]}]}
{"op":"mcm","clk":"1005331077","pt":1580642116653,"mc":[{"id":"1.168219388","rc":[{"batb":[[0,4.6,16.13],[1,1.01,0.51],[2,4.6,0]],"ltp":2.8,"tv":310.72,"id":13508961},{"batb":[[0,2,28.09],[1,1.01,0.51],[2,2,0]],"ltp":2.62,"tv":30.28,"id":16586500},{"batb":[[0,3.7,13.45],[1,1.01,0.51],[2,3.7,0]],"ltp":0.0,"tv":0.0,"id":13508964}]}]}
{"op":"mcm","clk":"1005331617","pt":1580642119668,"mc":[{"id":"1.168219388","rc":[{"batb":[[0,4.7,28.86],[1,4.6,53.82],[2,1.01,0.51]],"ltp":2.8,"tv":310.72,"id":13508961},{"batb":[[0,2.04,102.58],[1,2.02,66.07],[2,2,28.09]],"ltp":2.62,"tv":30.28,"id":16586500},{"batb":[[0,3.85,33.88],[1,3.8,30.16],[2,3.7,13.45]],"ltp":0.0,"tv":0.0,"id":13508964}]}]}
{"op":"mcm","clk":"1005333936","pt":1580642132753,"mc":[{"id":"1.168219388","rc":[{"batb":[[0,4.6,16.13],[1,1.01,0.51],[2,1.01,0]],"ltp":2.8,"tv":310.72,"id":13508961}]}]}
{"op":"mcm","clk":"1005334459","pt":1580642135684,"mc":[{"id":"1.168219388","rc":[{"batb":[[0,11.5,16.72],[1,11,27.19],[2,4.6,16.13]],"ltp":2.8,"tv":310.72,"id":13508961}]}]}
{"op":"mcm","clk":"1005334575","pt":1580642136281,"mc":[{"id":"1.168219388","rc":[{"batb":[[2,10.5,11.64]],"batl":[[1,20,5.9]],"ltp":2.8,"tv":310.72,"id":13508961},{"batl":[[0,2.16,27.3],[1,2.36,21.32]],"ltp":2.62,"tv":30.28,"id":16586500},{"batl":[[0,4.2,12.98]],"ltp":0.0,"tv":0.0,"id":13508964},{"batl":[[0,6,12.12]],"ltp":0.0,"tv":0.0,"id":16586502}]}]}
{"op":"mcm","clk":"1005334767","pt":1580642137245,"mc":[{"id":"1.168219388","rc":[{"batb":[[2,10.5,15.85]],"ltp":2.8,"tv":310.72,"id":13508961},{"batb":[[2,2,70.1]],"batl":[[1,2.22,33.61],[2,2.36,21.32]],"ltp":2.62,"tv":30.28,"id":16586500},{"batb":[[0,3.9,14.28],[1,3.85,33.88],[2,3.8,30.16]],"batl":[[1,4.6,10.92]],"ltp":0.0,"tv":0.0,"id":13508964},{"batb":[[2,4.6,10.92]],"batl":[[0,5.5,9.24],[1,6,12.12]],"ltp":0.0,"tv":0.0,"id":16586502}]}]}
{"op":"mcm","clk":"1005341000","pt":1580642172713,"mc":[{"id":"1.168219388","rc":[{"batb":[[0,10.5,15.85],[1,7.4,10.31],[2,1.01,0.51]],"ltp":2.8,"tv":310.72,"id":13508961},{"batb":[[0,2,70.1],[1,1.92,15.97],[2,1.01,0.51]],"ltp":2.62,"tv":30.28,"id":16586500}]}]}
{"op":"mcm","clk":"1005341057","pt":1580642172983,"mc":[{"id":"1.168219388","rc":[{"batb":[[0,10.5,4.2]],"batl":[[0,20,5.9],[1,20,0]],"ltp":2.8,"tv":310.72,"id":13508961},{"batb":[[0,2,42.01]],"batl":[[0,2.22,33.61],[1,2.36,21.32],[2,2.36,0]],"ltp":2.62,"tv":30.28,"id":16586500}]}]}
{"op":"mcm","clk":"1005341309","pt":1580642174415,"mc":[{"id":"1.168219388","rc":[{"batb":[[0,7.4,10.31],[1,1.01,0.51],[2,1.01,0]],"ltp":2.8,"tv":310.72,"id":13508961},{"batb":[[0,1.92,15.97],[1,1.01,0.51],[2,1.01,0]],"batl":[[0,2.36,21.32],[1,2.36,0]],"ltp":2.62,"tv":30.28,"id":16586500},{"batb":[[0,3.85,33.88],[1,3.8,30.16],[2,3.7,13.45]],"batl":[[1,4.6,0]],"ltp":0.0,"tv":0.0,"id":13508964},{"batb":[[2,1.01,0.51]],"batl":[[0,6,12.12],[1,6,0]],"ltp":0.0,"tv":0.0,"id":16586502}]}]}
{"op":"mcm","clk":"1005341488","pt":1580642175312,"mc":[{"id":"1.168219388","rc":[{"batb":[[0,8,14.55],[1,7.8,23.37],[2,7.4,10.31]],"ltp":2.8,"tv":310.72,"id":13508961},{"batb":[[0,1.97,74.17],[1,1.95,74.19],[2,1.92,15.97]],"ltp":2.62,"tv":30.28,"id":16586500}]}]}
{"op":"mcm","clk":"1005341725","pt":1580642176312,"mc":[{"id":"1.168219388","rc":[{"batb":[[0,7.6,10.23],[1,1.01,0.51],[2,7.4,0]],"ltp":2.8,"tv":310.72,"id":13508961},{"batb":[[0,1.92,15.97],[1,1.01,0.51],[2,1.92,0]],"batl":[[0,2.34,21.48]],"ltp":2.62,"tv":30.28,"id":16586500}]}]}
{"op":"mcm","clk":"1005342345","pt":1580642179512,"mc":[{"id":"1.168219388","rc":[{"batb":[[0,10.5,21.31],[1,10,33.02],[2,7.6,10.23]],"ltp":2.8,"tv":310.72,"id":13508961},{"batb":[[0,2.08,74.42],[1,2.06,62.84],[2,1.92,15.97]],"ltp":2.62,"tv":30.28,"id":16586500}]}]}
{"op":"mcm","clk":"1005343183","pt":1580642183754,"mc":[{"id":"1.168219388","rc":[{"batb":[[0,7.6,10.23],[1,1.01,0.51],[2,7.6,0]],"ltp":2.8,"tv":310.72,"id":13508961},{"batb":[[0,1.92,15.97],[1,1.01,0.51],[2,1.92,0]],"ltp":2.62,"tv":30.28,"id":16586500}]}]}
{"op":"mcm","clk":"1005343771","pt":1580642186714,"mc":[{"id":"1.168219388","rc":[{"batb":[[0,8,14.55],[1,7.8,23.37],[2,7.6,10.23]],"ltp":2.8,"tv":310.72,"id":13508961},{"batb":[[0,1.97,74.17],[1,1.95,74.19],[2,1.92,15.97]],"ltp":2.62,"tv":30.28,"id":16586500}]}]}
{"op":"mcm","clk":"1005344916","pt":1580642193013,"mc":[{"id":"1.168219388","rc":[{"batb":[[0,7.6,10.23],[1,1.01,0.51],[2,7.6,0]],"ltp":2.8,"tv":310.72,"id":13508961},{"batb":[[0,5.1,20.96]],"ltp":0.0,"tv":0.0,"id":16586502}]}]}
{"op":"mcm","clk":"1005345635","pt":1580642196739,"mc":[{"id":"1.168219388","rc":[{"batb":[[0,15,17.99],[1,14.5,15.22],[2,14,6.22]],"batl":[[1,29,6.37]],"ltp":2.8,"tv":310.72,"id":13508961},{"batl":[[0,2.04,15.82],[1,2.2,25.65],[2,2.34,21.48]],"ltp":2.62,"tv":30.28,"id":16586500},{"batl":[[1,4.3,25.34]],"ltp":0.0,"tv":0.0,"id":13508964}]}]}
{"op":"mcm","clk":"1005345761","pt":1580642197454,"mc":[{"id":"1.168219388","rc":[{"batb":[[2,1.93,44.53]],"batl":[[1,2.14,36.13],[2,2.2,25.65]],"ltp":2.62,"tv":30.28,"id":16586500},{"batb":[[0,3.85,48.16]],"batl":[[0,4.3,25.34],[1,4.5,11.76]],"ltp":0.0,"tv":0.0,"id":13508964},{"batb":[[1,5,46.04],[2,4.6,10.92]],"batl":[[0,5.5,9.24],[1,6,12.12]],"ltp":0.0,"tv":0.0,"id":16586502}]}]}
{"op":"mcm","clk":"1005347153","pt":1580642205417,"mc":[{"id":"1.168219388","rc":[{"batb":[[0,5,46.04],[1,4.6,10.92],[2,1.01,0.51]],"ltp":0.0,"tv":0.0,"id":16586502}]}]}
{"op":"mcm","clk":"1005347761","pt":1580642208591,"mc":[{"id":"1.168219388","rc":[{"batb":[[0,15,14.65],[1,14,6.22],[2,13,3.36]],"ltp":2.8,"tv":310.72,"id":13508961},{"batb":[[0,5,64.82],[1,4.9,34.88],[2,4.6,10.92]],"ltp":0.0,"tv":0.0,"id":16586502}]}]}
{"op":"mcm","clk":"1005348088","pt":1580642210398,"mc":[{"id":"1.168219388","rc":[{"batb":[[0,9.6,14.48],[1,1.01,0.51],[2,13,0]],"batl":[[0,29,6.37],[1,29,0]],"ltp":2.8,"tv":310.72,"id":13508961},{"batb":[[0,1.85,17.86],[1,1.01,0.51],[2,1.93,0]],"batl":[[0,2.2,25.65],[1,2.14,0],[2,2.2,0]],"ltp":2.62,"tv":30.28,"id":16586500},{"batb":[[0,3.85,33.88]],"batl":[[1,4.5,0]],"ltp":0.0,"tv":0.0,"id":13508964},{"batb":[[2,1.01,0.51]],"batl":[[0,6,12.12],[1,6,0]],"ltp":0.0,"tv":0.0,"id":16586502}]}]}
{"op":"mcm","clk":"1005348634","pt":1580642213683,"mc":[{"id":"1.168219388","rc":[{"batb":[[0,10.5,22.06],[1,10,33.24],[2,9.8,14.08]],"batl":[[0,29,6.14]],"ltp":2.8,"tv":310.72,"id":13508961},{"batb":[[0,1.91,66.05],[1,1.89,81.79],[2,1.84,18.25]],"batl":[[0,2.18,26.2]],"ltp":2.62,"tv":30.28,"id":16586500},{"batb":[[2,3.75,13.14]],"batl":[[0,4.4,24.08]],"ltp":0.0,"tv":0.0,"id":13508964}]}]}
{"op":"mcm","clk":"1005355007","pt":1580642248740,"mc":[{"id":"1.168219388","rc":[{"batb":[[0,1.84,18.25],[1,1.01,0.51],[2,1.84,0]],"ltp":2.62,"tv":30.28,"id":16586500}]}]}
{"op":"mcm","clk":"1005355544","pt":1580642251652,"mc":[{"id":"1.168219388","rc":[{"batb":[[0,2.08,97.3],[1,2.06,62.85],[2,1.84,18.25]],"ltp":2.62,"tv":30.28,"id":16586500}]}]}
{"op":"mcm","clk":"1005355730","pt":1580642252684,"mc":[{"id":"1.168219388","rc":[{"batb":[[1,10,24.98]],"batl":[[0,13,12.83],[1,19,6.29]],"ltp":2.8,"tv":310.72,"id":13508961},{"batb":[[0,2.08,70.33],[2,2.02,26.91]],"batl":[[1,2.44,19.2]],"ltp":2.62,"tv":30.28,"id":16586500},{"batb":[[0,3.8,30.16],[1,3.7,13.45],[2,1.01,0.51]],"batl":[[0,4.3,25.41]],"ltp":0.0,"tv":0.0,"id":13508964},{"batl":[[0,5.9,12.59]],"ltp":0.0,"tv":0.0,"id":16586502}]}]}
{"op":"mcm","clk":"1005355860","pt":1580642253423,"mc":[{"id":"1.168219388","rc":[{"batb":[[1,10,29.18]],"batl":[[1,13.5,3.36],[2,19,6.29]],"ltp":2.8,"tv":310.72,"id":13508961},{"batb":[[2,2.02,68.08]],"batl":[[1,2.24,33.61],[2,2.44,19.2]],"ltp":2.62,"tv":30.28,"id":16586500},{"batb":[[0,3.8,44.44]],"batl":[[1,4.5,11.76]],"ltp":0.0,"tv":0.0,"id":13508964},{"batb":[[2,4.6,10.92]],"batl":[[0,5.5,9.24],[1,5.9,12.59]],"ltp":0.0,"tv":0.0,"id":16586502}]}]}
{"op":"mcm","clk":"1005356082","pt":1580642254532,"mc":[{"id":"1.168219388","rc":[{"batb":[[1,10,24.98]],"ltp":2.8,"tv":310.72,"id":13508961},{"batl":[[0,5.9,12.59],[1,5.9,0]],"ltp":0.0,"tv":0.0,"id":16586502}]}]}
{"op":"mcm","clk":"1005356220","pt":1580642255338,"mc":[{"id":"1.168219388","rc":[{"batb":[[0,10.5,31.39],[1,9.8,14.08],[2,6.6,13.93]],"ltp":2.8,"tv":310.72,"id":13508961},{"batb":[[0,3.8,70.01],[1,3.75,31.31],[2,3.7,13.45]],"ltp":0.0,"tv":0.0,"id":13508964}]}]}
{"op":"mcm","clk":"1005356543","pt":1580642257137,"mc":[{"id":"1.168219388","rc":[{"batl":[[0,5.4,9.24],[1,5.9,12.59]],"ltp":0.0,"tv":0.0,"id":16586502}]}]}
{"op":"mcm","clk":"1005356784","pt":1580642258536,"mc":[{"id":"1.168219388","rc":[{"batb":[[0,11,19],[1,10.5,31.39],[2,10,4.2]],"ltp":2.8,"tv":310.72,"id":13508961}]}]}
{"op":"mcm","clk":"1005358849","pt":1580642269258,"mc":[{"id":"1.168219388","rc":[{"batl":[[1,19,6.29],[2,19,0]],"ltp":2.8,"tv":310.72,"id":13508961}]}]}
{"op":"mcm","clk":"1005359478","pt":1580642272385,"mc":[{"id":"1.168219388","rc":[{"batl":[[0,13,16.19]],"ltp":2.8,"tv":310.72,"id":13508961}]}]}
{"op":"mcm","clk":"1005359691","pt":1580642273494,"mc":[{"id":"1.168219388","rc":[{"batb":[[0,2.06,62.85],[1,2.02,68.08],[2,1.94,15.58]],"ltp":2.62,"tv":30.28,"id":16586500},{"batb":[[0,3.8,44.91],[1,3.7,13.45],[2,1.01,0.51]],"ltp":0.0,"tv":0.0,"id":13508964},{"batb":[[0,5,53.33]],"ltp":0.0,"tv":0.0,"id":16586502}]}]}
{"op":"mcm","clk":"1005360022","pt":1580642275306,"mc":[{"id":"1.168219388","rc":[{"batb":[[0,10,4.2],[1,6.6,13.93],[2,1.01,0.51]],"batl":[[0,13,3.36]],"ltp":2.8,"tv":310.72,"id":13508961},{"batb":[[0,2.02,41.17],[1,1.94,15.58],[2,1.01,0.51]],"batl":[[0,2.24,33.61],[1,2.44,19.2],[2,2.44,0]],"ltp":2.62,"tv":30.28,"id":16586500}]}]}
{"op":"mcm","clk":"1005360263","pt":1580642276530,"mc":[{"id":"1.168219388","rc":[{"batb":[[0,6.6,13.93],[1,1.01,0.51],[2,1.01,0]],"batl":[[0,19,6.29],[1,19,0]],"ltp":2.8,"tv":310.72,"id":13508961},{"batb":[[0,1.94,15.58],[1,1.01,0.51],[2,1.01,0]],"batl":[[0,2.44,19.2],[1,2.44,0]],"ltp":2.62,"tv":30.28,"id":16586500},{"batb":[[0,3.85,29.39],[1,3.8,30.63],[2,3.7,13.45]],"batl":[[1,4.5,0]],"ltp":0.0,"tv":0.0,"id":13508964},{"batb":[[2,1.01,0.51]],"batl":[[0,5.9,12.59],[1,5.9,0]],"ltp":0.0,"tv":0.0,"id":16586502}]}]}
{"op":"mcm","clk":"1005360647","pt":1580642278435,"mc":[{"id":"1.168219388","rc":[{"batb":[[0,7.2,31.96],[1,7,42.95],[2,1.01,0.51]],"batl":[[0,21,5.51]],"ltp":2.8,"tv":310.72,"id":13508961},{"batb":[[0,1.97,82.27],[1,1.95,74.19],[2,1.92,15.97]],"batl":[[0,2.4,20.22]],"ltp":2.62,"tv":30.28,"id":16586500},{"batb":[[2,3.75,13.22]],"batl":[[0,4.3,24.71]],"ltp":0.0,"tv":0.0,"id":13508964},{"batb":[[0,5,40.43],[1,4.9,48.49]],"batl":[[0,5.8,12.67]],"ltp":0.0,"tv":0.0,"id":16586502}]}]}
{"op":"mcm","clk":"1005361000","pt":1580642280346,"mc":[{"id":"1.168219388","rc":[{"batb":[[0,1.92,15.97],[1,1.01,0.51],[2,1.92,0]],"ltp":2.62,"tv":30.28,"id":16586500},{"batb":[[1,3.75,13.22],[2,1.01,0.51]],"ltp":0.0,"tv":0.0,"id":13508964}]}]}
{"op":"mcm","clk":"1005361649","pt":1580642283756,"mc":[{"id":"1.168219388","rc":[{"batb":[[1,7,49.68],[2,4.6,15.66]],"batl":[[0,8.6,11.57],[1,8.8,5.04],[2,12.5,13.93]],"ltp":2.8,"tv":310.72,"id":13508961},{"batb":[[0,2.28,53.19],[1,2.26,48.25],[2,2.22,20.69]],"batl":[[1,2.44,28.57],[2,2.8,13.38]],"ltp":2.62,"tv":30.28,"id":16586500},{"batb":[[0,3.9,29.54],[1,3.85,43.67],[2,3.75,13.06]],"batl":[[1,4.5,34.74]],"ltp":0.0,"tv":0.0,"id":13508964},{"batb":[[2,4.6,10.92]],"batl":[[0,5.4,9.24],[1,5.8,12.67]],"ltp":0.0,"tv":0.0,"id":16586502}]}]}
{"op":"mcm","clk":"1005365739","pt":1580642304526,"mc":[{"id":"1.168219388","rc":[{"batb":[[0,4.6,15.66],[1,1.01,0.51],[2,4.6,0]],"batl":[[0,12.5,13.93],[1,8.8,0],[2,12.5,0]],"ltp":2.8,"tv":310.72,"id":13508961},{"batb":[[0,2.06,25.49],[1,1.01,0.51],[2,2.22,0]],"batl":[[0,2.8,13.38],[1,2.44,0],[2,2.8,0]],"ltp":2.62,"tv":30.28,"id":16586500},{"batb":[[0,3.7,13.38],[1,1.01,0.51],[2,3.75,0]],"batl":[[0,4.5,22.98],[1,4.5,0]],"ltp":0.0,"tv":0.0,"id":13508964},{"batb":[[2,1.01,0.51]],"batl":[[0,5.8,12.67],[1,5.8,0]],"ltp":0.0,"tv":0.0,"id":16586502}]}]}
{"op":"mcm","clk":"1005366339","pt":1580642307713,"mc":[{"id":"1.168219388","rc":[{"batb":[[0,4.8,29.88],[1,4.7,53.45],[2,1.01,0.51]],"batl":[[0,12.5,13.77]],"ltp":2.8,"tv":310.72,"id":13508961},{"batb":[[0,2.1,107.29],[1,2.08,61.12],[2,2.06,25.49]],"ltp":2.62,"tv":30.28,"id":16586500},{"batb":[[0,3.8,56.63],[1,3.75,44.86],[2,1.01,0.51]],"ltp":0.0,"tv":0.0,"id":13508964}]}]}
{"op":"mcm","clk":"1005368755","pt":1580642320506,"mc":[{"id":"1.168219388","rc":[{"batb":[[0,4.7,15.5],[1,1.01,0.51],[2,1.01,0]],"ltp":2.8,"tv":310.72,"id":13508961}]}]}
{"op":"mcm","clk":"1005369277","pt":1580642323505,"mc":[{"id":"1.168219388","rc":[{"batb":[[0,10,29.51],[1,9.8,14.86],[2,9.4,15.19]],"batl":[[0,12,3.36],[1,12.5,13.77],[2,21,5.35]],"ltp":2.8,"tv":310.72,"id":13508961},{"batb":[[0,2.1,59.49],[1,2.08,38.65]],"batl":[[0,2.22,25.02],[1,2.32,31.09],[2,2.56,17.07]],"ltp":2.62,"tv":30.28,"id":16586500},{"batb":[[1,3.75,59.98],[2,3.7,13.77]],"batl":[[0,4.4,35.76],[1,4.5,22.98]],"ltp":0.0,"tv":0.0,"id":13508964},{"batb":[[2,4.6,10.92]],"batl":[[0,5.5,9.24],[1,5.8,12.67]],"ltp":0.0,"tv":0.0,"id":16586502}]}]}
{"op":"mcm","clk":"1005369333","pt":1580642323814,"mc":[{"id":"1.168219388","rc":[{"batl":[[1,2.56,17.07],[2,2.56,0]],"ltp":2.62,"tv":30.28,"id":16586500},{"batl":[[1,4.5,0]],"ltp":0.0,"tv":0.0,"id":13508964}]}]}
{"op":"mcm","clk":"1005369811","pt":1580642326308,"mc":[{"id":"1.168219388","rc":[{"batb":[[0,2.12,48.08],[1,2.1,59.49],[2,2.08,38.65]],"batl":[[1,2.3,31.93],[2,2.56,17.07]],"ltp":2.62,"tv":30.28,"id":16586500}]}]}
{"op":"mcm","clk":"1005373489","pt":1580642344671,"mc":[{"id":"1.168219388","rc":[{"batb":[[0,10,25.73]],"ltp":2.8,"tv":310.72,"id":13508961}]}]}
{"op":"mcm","clk":"1005373693","pt":1580642345582,"mc":[{"id":"1.168219388","rc":[{"batb":[[0,9.2,5.04],[1,5.8,18.8],[2,1.01,0.51]],"batl":[[1,21,5.35],[2,21,0]],"ltp":2.8,"tv":310.72,"id":13508961},{"batb":[[0,2.08,38.65],[1,1.94,15.58],[2,1.01,0.51]],"batl":[[0,2.3,31.93],[1,2.56,17.07],[2,2.56,0]],"ltp":2.62,"tv":30.28,"id":16586500},{"batb":[[0,3.8,28.27],[1,3.75,46.6]],"ltp":0.0,"tv":0.0,"id":13508964}]}]}
{"op":"mcm","clk":"1005373900","pt":1580642346559,"mc":[{"id":"1.168219388","rc":[{"batb":[[0,5.8,18.8],[1,1.01,0.51],[2,1.01,0]],"batl":[[0,21,5.35],[1,21,0]],"ltp":2.8,"tv":310.72,"id":13508961},{"batb":[[0,1.94,15.58],[1,1.01,0.51],[2,1.01,0]],"batl":[[0,2.56,17.07],[1,2.56,0]],"ltp":2.62,"tv":30.28,"id":16586500},{"batb":[[1,3.75,31.48]],"batl":[[0,4.4,24]],"ltp":0.0,"tv":0.0,"id":13508964},{"batb":[[2,1.01,0.51]],"batl":[[0,5.8,12.67],[1,5.8,0]],"ltp":0.0,"tv":0.0,"id":16586502}]}]}
{"op":"mcm","clk":"1005374526","pt":1580642349549,"mc":[{"id":"1.168219388","rc":[{"batb":[[0,6,28.38],[1,5.9,22.67],[2,5.8,18.8]],"ltp":2.8,"tv":310.72,"id":13508961},{"batb":[[0,1.98,74.08],[1,1.96,73.04],[2,1.94,15.58]],"ltp":2.62,"tv":30.28,"id":16586500}]}]}
{"op":"mcm","clk":"1005375354","pt":1580642354044,"mc":[{"id":"1.168219388","rc":[{"batb":[[0,1.94,15.58],[1,1.01,0.51],[2,1.94,0]],"ltp":2.62,"tv":30.28,"id":16586500},{"batb":[[0,3.7,13.77],[1,1.01,0.51],[2,3.7,0]],"ltp":0.0,"tv":0.0,"id":13508964}]}]}
{"op":"mcm","clk":"1005376006","pt":1580642357755,"mc":[{"id":"1.168219388","rc":[{"batb":[[0,6,36.78]],"batl":[[0,7,17.55],[1,7.4,5.88],[2,12,15.34]],"ltp":2.8,"tv":310.72,"id":13508961},{"batb":[[0,2.42,56.24],[1,2.38,82.95],[2,2.36,17.47]],"batl":[[1,2.58,26.05],[2,3.35,21.95]],"ltp":2.62,"tv":30.28,"id":16586500},{"batb":[[0,3.9,61.51],[1,3.85,29.75],[2,3.8,25.41]],"batl":[[1,4.5,11.76],[2,4.6,20.93]],"ltp":0.0,"tv":0.0,"id":13508964},{"batb":[[2,4.6,10.92]],"batl":[[0,5.4,9.24],[1,5.7,13.3],[2,5.8,12.67]],"ltp":0.0,"tv":0.0,"id":16586502}]}]}
{"op":"mcm","clk":"1005379546","pt":1580642376614,"mc":[{"id":"1.168219388","rc":[{"batb":[[0,3.55,15.03],[1,1.01,0.51],[2,5.8,0]],"batl":[[0,12,15.34],[1,7.4,0],[2,12,0]],"ltp":2.8,"tv":310.72,"id":13508961},{"batb":[[0,2.1,24.23],[1,1.01,0.51],[2,2.36,0]],"batl":[[0,3.35,21.95],[1,2.58,0],[2,3.35,0]],"ltp":2.62,"tv":30.28,"id":16586500},{"batb":[[0,3.7,13.77],[1,1.01,0.51],[2,3.8,0]],"batl":[[0,4.6,20.93],[1,4.5,0],[2,4.6,0]],"ltp":0.0,"tv":0.0,"id":13508964},{"batb":[[2,1.01,0.51]],"batl":[[0,5.8,12.67],[1,5.7,0],[2,5.8,0]],"ltp":0.0,"tv":0.0,"id":16586502}]}]}
{"op":"mcm","clk":"1005380110","pt":1580642379753,"mc":[{"id":"1.168219388","rc":[{"batb":[[0,3.55,62.74],[1,3.5,38.09],[2,1.01,0.51]],"ltp":2.8,"tv":310.72,"id":13508961},{"batb":[[0,2.14,65.84],[1,2.12,57.86],[2,2.1,24.23]],"batl":[[0,3.35,21.72]],"ltp":2.62,"tv":30.28,"id":16586500},{"batb":[[0,3.8,35.89],[1,3.75,31.68],[2,3.7,13.77]],"batl":[[0,4.7,20.93]],"ltp":0.0,"tv":0.0,"id":13508964}]}]}
{"op":"mcm","clk":"1005380481","pt":1580642381725,"mc":[{"id":"1.168219388","rc":[{"batb":[[0,3.55,15.03],[1,1.01,0.51],[2,1.01,0]],"ltp":2.8,"tv":310.72,"id":13508961}]}]}
{"op":"mcm","clk":"1005381012","pt":1580642384448,"mc":[{"id":"1.168219388","rc":[{"batb":[[0,9.8,19.19],[1,9.6,15.66],[2,3.55,15.03]],"ltp":2.8,"tv":310.72,"id":13508961}]}]}
{"op":"mcm","clk":"1005381212","pt":1580642385555,"mc":[{"id":"1.168219388","rc":[{"batb":[[2,9,11.97]],"batl":[[0,12,18.7],[1,19.5,6.14]],"ltp":2.8,"tv":310.72,"id":13508961},{"batb":[[2,2.1,62.04]],"batl":[[0,2.26,23.53],[1,2.34,31.09],[2,2.62,15.89]],"ltp":2.62,"tv":30.28,"id":16586500},{"batl":[[0,4.2,13.38],[1,4.3,37.31]],"ltp":0.0,"tv":0.0,"id":13508964},{"batb":[[2,4.6,10.92]],"batl":[[0,5.5,9.24],[1,5.8,12.67]],"ltp":0.0,"tv":0.0,"id":16586502}]}]}
{"op":"mcm","clk":"1005381267","pt":1580642385888,"mc":[{"id":"1.168219388","rc":[{"batb":[[2,9,6.92]],"ltp":2.8,"tv":310.72,"id":13508961}]}]}
{"op":"mcm","clk":"1005381902","pt":1580642389472,"mc":[{"id":"1.168219388","rc":[{"batb":[[2,9.2,5.04]],"ltp":2.8,"tv":310.72,"id":13508961},{"batb":[[2,3.7,28.89]],"ltp":0.0,"tv":0.0,"id":13508964}]}]}
{"op":"mcm","clk":"1005383764","pt":1580642399686,"mc":[{"id":"1.168219388","rc":[{"batb":[[0,9.2,5.04],[1,9,6.92],[2,5.5,10.46]],"ltp":2.8,"tv":310.72,"id":13508961},{"batb":[[0,2.1,62.04],[1,1.97,29.43],[2,1.01,0.51]],"ltp":2.62,"tv":30.28,"id":16586500},{"batb":[[0,3.75,31.68],[1,3.7,28.89],[2,3.65,14.32]],"ltp":0.0,"tv":0.0,"id":13508964},{"batb":[[0,5,33.14]],"ltp":0.0,"tv":0.0,"id":16586502}]}]}
{"op":"mcm","clk":"1005383937","pt":1580642400593,"mc":[{"id":"1.168219388","rc":[{"batb":[[0,5.5,10.46],[1,1.01,0.51],[2,5.5,0]],"batl":[[0,19.5,6.14],[1,19.5,0]],"ltp":2.8,"tv":310.72,"id":13508961},{"batb":[[0,1.97,29.43],[1,1.01,0.51],[2,1.01,0]],"batl":[[0,2.62,15.89],[1,2.34,0],[2,2.62,0]],"ltp":2.62,"tv":30.28,"id":16586500},{"batb":[[1,3.65,14.32],[2,1.01,0.51]],"batl":[[0,4.3,24.71],[1,4.3,0]],"ltp":0.0,"tv":0.0,"id":13508964},{"batb":[[2,1.01,0.51]],"batl":[[0,5.8,12.67],[1,5.8,0]],"ltp":0.0,"tv":0.0,"id":16586502}]}]}
{"op":"mcm","clk":"1005384346","pt":1580642402577,"mc":[{"id":"1.168219388","rc":[{"batb":[[0,5.9,21.06],[1,5.8,23.65],[2,5.5,10.46]],"ltp":2.8,"tv":310.72,"id":13508961},{"batb":[[0,2,73.11],[1,1.98,70.81],[2,1.97,29.43]],"ltp":2.62,"tv":30.28,"id":16586500},{"batb":[[1,3.7,32.65],[2,3.65,14.32]],"ltp":0.0,"tv":0.0,"id":13508964}]}]}
{"op":"mcm","clk":"1005389921","pt":1580642432765,"mc":[{"id":"1.168219388","rc":[{"batb":[[0,1.97,29.43],[1,1.01,0.51],[2,1.97,0]],"ltp":2.62,"tv":30.28,"id":16586500},{"batb":[[0,3.65,14.32],[1,1.01,0.51],[2,3.65,0]],"ltp":0.0,"tv":0.0,"id":13508964}]}]}
{"op":"mcm","clk":"1005390453","pt":1580642435683,"mc":[{"id":"1.168219388","rc":[{"batb":[[0,2.44,77.72],[1,2.4,80.96],[2,1.97,29.43]],"ltp":2.62,"tv":30.28,"id":16586500},{"batb":[[0,3.9,32.33],[1,3.85,29.89],[2,3.65,14.32]],"ltp":0.0,"tv":0.0,"id":13508964},{"batb":[[0,5,45.3]],"ltp":0.0,"tv":0.0,"id":16586502}]}]}
{"op":"mcm","clk":"1005390663","pt":1580642436760,"mc":[{"id":"1.168219388","rc":[{"batl":[[0,6.6,19.43],[1,11,7.16]],"ltp":2.8,"tv":310.72,"id":13508961},{"batb":[[1,2.42,16.29],[2,2.4,80.96]],"batl":[[1,3.45,20.46]],"ltp":2.62,"tv":30.28,"id":16586500},{"batb":[[2,3.75,13.14]],"batl":[[1,4.7,20.85]],"ltp":0.0,"tv":0.0,"id":13508964}]}]}
{"op":"mcm","clk":"1005390785","pt":1580642437491,"mc":[{"id":"1.168219388","rc":[{"batb":[[0,5.9,29.46]],"batl":[[1,7.2,6.72],[2,11,7.16]],"ltp":2.8,"tv":310.72,"id":13508961},{"batl":[[0,2.62,41.1]],"ltp":2.62,"tv":30.28,"id":16586500},{"batb":[[1,3.85,44.17]],"batl":[[1,4.5,11.76],[2,4.7,20.85]],"ltp":0.0,"tv":0.0,"id":13508964},{"batb":[[2,4.6,10.92]],"batl":[[0,5.4,9.24],[1,5.8,12.67]],"ltp":0.0,"tv":0.0,"id":16586502}]}]}
{"op":"mcm","clk":"1005394692","pt":1580642458578,"mc":[{"id":"1.168219388","rc":[{"batb":[[0,3.45,16.37],[1,1.01,0.51],[2,5.5,0]],"batl":[[0,11,7.16],[1,7.2,0],[2,11,0]],"ltp":2.8,"tv":310.72,"id":13508961},{"batb":[[0,2.14,22.82],[1,1.01,0.51],[2,2.4,0]],"batl":[[0,3.45,20.46],[1,3.45,0]],"ltp":2.62,"tv":30.28,"id":16586500},{"batb":[[0,3.65,14.08],[1,1.01,0.51],[2,3.75,0]],"batl":[[0,4.7,20.85],[1,4.5,0],[2,4.7,0]],"ltp":0.0,"tv":0.0,"id":13508964},{"batb":[[0,5,33.14],[2,1.01,0.51]],"batl":[[0,5.8,12.67],[1,5.8,0]],"ltp":0.0,"tv":0.0,"id":16586502}]}]}
{"op":"mcm","clk":"1005395114","pt":1580642461020,"mc":[{"id":"1.168219388","rc":[{"batb":[[0,3.5,50.94],[1,3.45,55.79],[2,1.01,0.51]],"ltp":2.8,"tv":310.72,"id":13508961},{"batb":[[0,2.16,76.79],[1,2.14,79.11],[2,1.01,0.51]],"ltp":2.62,"tv":30.28,"id":16586500},{"batb":[[0,3.75,48.02],[1,3.7,32.61],[2,3.65,14.08]],"ltp":0.0,"tv":0.0,"id":13508964}]}]}
{"op":"mcm","clk":"1005396067","pt":1580642466527,"mc":[{"id":"1.168219388","rc":[{"batb":[[0,3.45,16.37],[1,1.01,0.51],[2,1.01,0]],"ltp":2.8,"tv":310.72,"id":13508961},{"batb":[[0,2.14,22.82],[1,1.01,0.51],[2,1.01,0]],"ltp":2.62,"tv":30.28,"id":16586500},{"batb":[[0,3.65,14.08],[1,1.01,0.51],[2,3.65,0]],"ltp":0.0,"tv":0.0,"id":13508964},{"batb":[[1,4.9,13.61]],"ltp":0.0,"tv":0.0,"id":16586502}]}]}
{"op":"mcm","clk":"1005396609","pt":1580642469560,"mc":[{"id":"1.168219388","rc":[{"batb":[[0,3.5,67.75],[1,3.45,55.79],[2,1.01,0.51]],"batl":[[0,4,13.44],[1,11,7.16]],"ltp":2.8,"tv":310.72,"id":13508961},{"batb":[[0,3.2,46.93],[1,3.15,69.39],[2,2.14,22.82]],"batl":[[1,3.6,15.96]],"ltp":2.62,"tv":30.28,"id":16586500},{"batb":[[0,4.1,54.54],[1,4,53.88],[2,3.95,13.44]],"batl":[[0,4.6,10.92],[1,4.7,20.85]],"ltp":0.0,"tv":0.0,"id":13508964},{"batb":[[0,5.1,33],[1,5,33.14],[2,4.9,13.61]],"batl":[[0,5.5,9.24],[1,5.8,12.67]],"ltp":0.0,"tv":0.0,"id":16586502}]}]}
{"op":"mcm","clk":"1005396819","pt":1580642470632,"mc":[{"id":"1.168219388","rc":[{"batb":[[2,3.15,20.38]],"batl":[[0,3.85,15.82],[1,3.95,2.13],[2,4,13.44]],"ltp":2.8,"tv":310.72,"id":13508961},{"batb":[[2,3.1,21.24]],"batl":[[2,3.75,16.68]],"ltp":2.62,"tv":30.28,"id":16586500},{"batb":[[1,4,75.91],[2,3.95,36.58]],"batl":[[1,4.7,20.38]],"ltp":0.0,"tv":0.0,"id":13508964}]}]}
{"op":"mcm","clk":"1005396954","pt":1580642471484,"mc":[{"id":"1.168219388","rc":[{"batl":[[1,4,13.44],[2,4.8,19.91]],"ltp":2.8,"tv":310.72,"id":13508961}]}]}
{"op":"mcm","clk":"1005400966","pt":1580642494479,"mc":[{"id":"1.168219388","rc":[{"batb":[[0,3.5,46.61]],"ltp":2.8,"tv":310.72,"id":13508961},{"batb":[[0,4.1,36.55]],"ltp":0.0,"tv":0.0,"id":13508964}]}]}
{"op":"mcm","clk":"1005401287","pt":1580642496279,"mc":[{"id":"1.168219388","rc":[{"batb":[[1,3.45,39.42],[2,3.4,16.68]],"batl":[[0,3.8,16.21],[2,4.7,20.3]],"ltp":2.8,"tv":310.72,"id":13508961},{"batb":[[2,3.1,20.93]],"batl":[[0,3.45,20.14],[2,3.8,16.37]],"ltp":2.62,"tv":30.28,"id":16586500}]}]}
{"op":"mcm","clk":"1005401476","pt":1580642497279,"mc":[{"id":"1.168219388","rc":[{"batb":[[0,3.2,73.07]],"ltp":2.62,"tv":30.28,"id":16586500},{"batb":[[0,5.1,47.51]],"ltp":0.0,"tv":0.0,"id":16586502}]}]}
{"op":"mcm","clk":"1005402567","pt":1580642503441,"mc":[{"id":"1.168219388","rc":[{"batb":[[0,3.5,16.8]],"ltp":2.8,"tv":310.72,"id":13508961},{"batb":[[0,3.2,48.58],[1,3.15,19.32]],"ltp":2.62,"tv":30.28,"id":16586500},{"batb":[[0,5.1,33],[1,4.9,13.61],[2,4.6,10.92]],"ltp":0.0,"tv":0.0,"id":16586502}]}]}
{"op":"mcm","clk":"1005402740","pt":1580642504344,"mc":[{"id":"1.168219388","rc":[{"batb":[[2,3.1,20.61]],"batl":[[0,3.5,19.91],[2,3.8,16.21]],"ltp":2.62,"tv":30.28,"id":16586500},{"batb":[[1,4,53.88]],"batl":[[0,4.6,31.93]],"ltp":0.0,"tv":0.0,"id":13508964},{"batb":[[1,5,13.38],[2,4.9,13.61]],"ltp":0.0,"tv":0.0,"id":16586502}]}]}
{"op":"mcm","clk":"1005403057","pt":1580642506408,"mc":[{"id":"1.168219388","rc":[{"batb":[[1,3.45,60.2],[2,3.4,57.14]],"ltp":2.8,"tv":310.72,"id":13508961},{"batb":[[0,3.25,35.46],[1,3.2,48.58],[2,3.15,19.32]],"ltp":2.62,"tv":30.28,"id":16586500},{"batb":[[0,5.2,20.41],[1,5.1,33],[2,5,13.38]],"ltp":0.0,"tv":0.0,"id":16586502}]}]}
{"op":"mcm","clk":"1005403572","pt":1580642509499,"mc":[{"id":"1.168219388","rc":[{"trd":[[3.5,30]],"batb":[[0,3.5,1.81]],"ltp":3.5,"tv":340.72,"id":13508961}],"tv":371.01}]}
{"op":"mcm","clk":"1005403688","pt":1580642510251,"mc":[{"id":"1.168219388","rc":[{"batb":[[0,3.45,60.2],[1,3.4,57.14],[2,3.1,20.77]],"batl":[[1,4.7,20.3],[2,4.7,0]],"ltp":3.5,"tv":340.72,"id":13508961}]}]}
{"op":"mcm","clk":"1005404228","pt":1580642513114,"mc":[{"id":"1.168219388","rc":[{"batb":[[0,3.45,77]],"batl":[[1,3.95,13.44],[2,4.7,20.3]],"ltp":3.5,"tv":340.72,"id":13508961}]}]}
{"op":"mcm","clk":"1005405808","pt":1580642521410,"mc":[{"id":"1.168219388","rc":[{"batb":[[0,3.45,66.59]],"ltp":3.5,"tv":340.72,"id":13508961},{"batl":[[1,3.8,16.21],[2,3.8,0]],"ltp":2.62,"tv":30.28,"id":16586500}]}]}
{"op":"mcm","clk":"1005406400","pt":1580642524753,"mc":[{"id":"1.168219388","rc":[{"batb":[[2,3.35,17.31]],"batl":[[0,3.75,16.68],[1,3.8,16.21],[2,3.95,13.44]],"ltp":3.5,"tv":340.72,"id":13508961},{"batb":[[2,3.15,39.62]],"batl":[[1,3.65,15.12],[2,3.8,16.21]],"ltp":2.62,"tv":30.28,"id":16586500},{"batb":[[1,4,75.99]],"ltp":0.0,"tv":0.0,"id":13508964}]}]}
{"op":"mcm","clk":"1005406461","pt":1580642525024,"mc":[{"id":"1.168219388","rc":[{"batb":[[1,3.4,40.46]],"batl":[[1,3.95,13.44],[2,4.6,21.01]],"ltp":3.5,"tv":340.72,"id":13508961},{"batl":[[0,3.5,19.59],[2,3.85,15.89]],"ltp":2.62,"tv":30.28,"id":16586500}]}]}
{"op":"mcm","clk":"1005411505","pt":1580642551476,"mc":[{"id":"1.168219388","rc":[{"batb":[[0,3.45,16.8],[1,3.05,21.48],[2,1.01,0.51]],"batl":[[0,3.95,13.44],[1,4.6,21.01],[2,4.6,0]],"ltp":3.5,"tv":340.72,"id":13508961},{"batb":[[0,3.15,19.32],[1,2.78,11.17],[2,1.01,0.51]],"batl":[[0,3.65,15.12],[1,3.85,15.89],[2,3.85,0]],"ltp":2.62,"tv":30.28,"id":16586500},{"batb":[[0,4,53.88],[1,3.95,36.58],[2,1.01,0.51]],"batl":[[0,4.6,10.92]],"ltp":0.0,"tv":0.0,"id":13508964},{"batb":[[0,5.1,33],[1,4.9,13.61],[2,4.6,10.92]],"ltp":0.0,"tv":0.0,"id":16586502}]}]}
{"op":"mcm","clk":"1005411727","pt":1580642552580,"mc":[{"id":"1.168219388","rc":[{"batb":[[0,3.05,21.48],[1,1.01,0.51],[2,1.01,0]],"batl":[[0,4.6,21.01],[1,4.6,0]],"ltp":3.5,"tv":340.72,"id":13508961},{"batb":[[0,2.78,11.17],[1,1.01,0.51],[2,1.01,0]],"batl":[[0,3.85,15.89],[1,3.85,0]],"ltp":2.62,"tv":30.28,"id":16586500},{"batb":[[1,3.95,23.13]],"batl":[[0,4.7,20.38],[1,4.7,0]],"ltp":0.0,"tv":0.0,"id":13508964},{"batb":[[2,1.01,0.51]],"batl":[[0,5.8,12.67],[1,5.8,0]],"ltp":0.0,"tv":0.0,"id":16586502}]}]}
{"op":"mcm","clk":"1005412130","pt":1580642554485,"mc":[{"id":"1.168219388","rc":[{"batb":[[0,3.15,62.14],[1,3.1,50.73],[2,3.05,21.48]],"ltp":3.5,"tv":340.72,"id":13508961},{"batb":[[0,2.86,57.03],[1,2.82,53.58],[2,2.78,11.17]],"ltp":2.62,"tv":30.28,"id":16586500},{"batb":[[1,3.95,51.08]],"ltp":0.0,"tv":0.0,"id":13508964},{"batb":[[0,5.1,42.59],[1,5,34.13],[2,4.9,13.61]],"ltp":0.0,"tv":0.0,"id":16586502}]}]}
{"op":"mcm","clk":"1005413322","pt":1580642560846,"mc":[{"id":"1.168219388","rc":[{"batb":[[0,3.05,21.48],[1,1.01,0.51],[2,3.05,0]],"ltp":3.5,"tv":340.72,"id":13508961},{"batb":[[0,2.78,11.17],[1,1.01,0.51],[2,2.78,0]],"ltp":2.62,"tv":30.28,"id":16586500},{"batb":[[0,5.1,33],[1,4.9,13.61],[2,1.01,0.51]],"ltp":0.0,"tv":0.0,"id":16586502}]}]}
{"op":"mcm","clk":"1005414054","pt":1580642564732,"mc":[{"id":"1.168219388","rc":[{"batb":[[0,4,42.93]],"ltp":0.0,"tv":0.0,"id":13508964}]}]}
{"op":"mcm","clk":"1005414866","pt":1580642568762,"mc":[{"id":"1.168219388","rc":[{"batb":[[0,3.1,80.77],[1,3.05,73.79],[2,1.01,0.51]],"ltp":3.5,"tv":340.72,"id":13508961},{"batb":[[1,3.95,23.13]],"ltp":0.0,"tv":0.0,"id":13508964}]}]}
{"op":"mcm","clk":"1005415412","pt":1580642571587,"mc":[{"id":"1.168219388","rc":[{"batb":[[0,3.15,19.32],[1,3.1,80.77],[2,3.05,73.79]],"batl":[[0,3.65,15.12],[1,4.6,21.01]],"ltp":3.5,"tv":340.72,"id":13508961},{"batb":[[0,3.55,45.83],[1,3.5,39.21],[2,3.4,16.8]],"batl":[[1,3.9,14.28]],"ltp":2.62,"tv":30.28,"id":16586500},{"batb":[[0,4.1,46.84],[1,4,66.86],[2,3.95,23.13]],"batl":[[0,4.7,31.3]],"ltp":0.0,"tv":0.0,"id":13508964},{"batb":[[0,5.2,35.44],[1,5.1,33],[2,4.9,13.61]],"batl":[[0,5.5,9.24],[1,5.8,12.67]],"ltp":0.0,"tv":0.0,"id":16586502}]}]}
{"op":"mcm","clk":"1005415572","pt":1580642572404,"mc":[{"id":"1.168219388","rc":[{"batl":[[0,3.45,20.69],[1,3.65,15.12],[2,3.95,14.87]],"ltp":3.5,"tv":340.72,"id":13508961},{"batb":[[2,3.45,16.37]],"batl":[[2,4.2,13.22]],"ltp":2.62,"tv":30.28,"id":16586500},{"batb":[[1,4,88.97],[2,1.01,0.51]],"ltp":0.0,"tv":0.0,"id":13508964}]}]}
{"op":"mcm","clk":"1005418339","pt":1580642586583,"mc":[{"id":"1.168219388","rc":[{"batb":[[0,2.88,25.49],[1,1.01,0.51],[2,3.05,0]],"batl":[[0,3.95,14.87],[1,3.65,0],[2,3.95,0]],"ltp":3.5,"tv":340.72,"id":13508961},{"batb":[[0,3.05,22.27],[1,1.01,0.51],[2,3.45,0]],"batl":[[0,4.2,13.22],[1,3.9,0],[2,4.2,0]],"ltp":2.62,"tv":30.28,"id":16586500},{"batb":[[0,4,22.11],[1,1.01,0.51],[2,1.01,0]],"batl":[[0,4.7,20.38]],"ltp":0.0,"tv":0.0,"id":13508964},{"batb":[[0,4.9,13.61],[1,1.01,0.51],[2,4.9,0]],"batl":[[0,5.8,12.67],[1,5.8,0]],"ltp":0.0,"tv":0.0,"id":16586502}]}]}
{"op":"mcm","clk":"1005418910","pt":1580642589595,"mc":[{"id":"1.168219388","rc":[{"batb":[[0,2.94,50.45],[1,2.9,47.99],[2,2.88,25.49]],"ltp":3.5,"tv":340.72,"id":13508961},{"batb":[[0,3.15,78.38],[1,3.1,52.57],[2,3.05,22.27]],"ltp":2.62,"tv":30.28,"id":16586500},{"batb":[[0,4,97.54],[1,3.95,27.65],[2,1.01,0.51]],"ltp":0.0,"tv":0.0,"id":13508964},{"batb":[[0,5.2,20.51],[1,5.1,33.05],[2,4.9,13.61]],"ltp":0.0,"tv":0.0,"id":16586502}]}]}
{"op":"mcm","clk":"1005419080","pt":1580642590403,"mc":[{"id":"1.168219388","rc":[{"batb":[[0,3.05,22.27],[1,1.01,0.51],[2,3.05,0]],"ltp":2.62,"tv":30.28,"id":16586500},{"batb":[[0,4,75.22],[1,1.01,0.51],[2,1.01,0]],"ltp":0.0,"tv":0.0,"id":13508964}]}]}
{"op":"mcm","clk":"1005419690","pt":1580642593705,"mc":[{"id":"1.168219388","rc":[{"batb":[[0,2.96,21],[1,2.94,50.45],[2,2.9,47.99]],"batl":[[0,3.4,16.8],[1,3.95,14.87]],"ltp":3.5,"tv":340.72,"id":13508961},{"batb":[[0,3.8,41.32],[1,3.75,33.24],[2,3.6,15.96]],"batl":[[0,4.2,25.82]],"ltp":2.62,"tv":30.28,"id":16586500},{"batb":[[0,4.1,61.35],[1,4,88.66],[2,1.01,0.51]],"batl":[[0,4.7,31.3]],"ltp":0.0,"tv":0.0,"id":13508964},{"batb":[[0,5.2,43.83]],"batl":[[0,5.5,9.24],[1,5.8,12.67]],"ltp":0.0,"tv":0.0,"id":16586502}]}]}
{"op":"mcm","clk":"1005419788","pt":1580642594134,"mc":[{"id":"1.168219388","rc":[{"batl":[[0,3.2,24.47],[1,3.4,16.8],[2,3.5,19.59]],"ltp":3.5,"tv":340.72,"id":13508961},{"batb":[[2,3.7,13.61]],"batl":[[1,4.5,22.82]],"ltp":2.62,"tv":30.28,"id":16586500},{"batb":[[1,4,88.43]],"batl":[[0,4.7,30.91]],"ltp":0.0,"tv":0.0,"id":13508964}]}]}
{"op":"mcm","clk":"1005421075","pt":1580642600649,"mc":[{"id":"1.168219388","rc":[{"batb":[[0,2.76,11.49],[1,1.01,0.51],[2,2.9,0]],"batl":[[0,3.5,19.59],[1,3.4,0],[2,3.5,0]],"ltp":3.5,"tv":340.72,"id":13508961},{"batb":[[0,3.35,17.23],[1,1.01,0.51],[2,3.7,0]],"batl":[[0,4.5,22.82],[1,4.5,0]],"ltp":2.62,"tv":30.28,"id":16586500},{"batb":[[0,4.1,50.4],[1,4,74.98]],"batl":[[0,4.7,19.99]],"ltp":0.0,"tv":0.0,"id":13508964},{"batb":[[0,5.2,27.84]],"batl":[[0,5.8,12.67],[1,5.8,0]],"ltp":0.0,"tv":0.0,"id":16586502}]}]}
{"op":"mcm","clk":"1005421661","pt":1580642603530,"mc":[{"id":"1.168219388","rc":[{"batb":[[0,2.82,57.45],[1,2.78,53.46],[2,2.76,11.49]],"ltp":3.5,"tv":340.72,"id":13508961},{"batb":[[0,3.5,43.97],[1,3.45,40.61],[2,3.35,17.23]],"ltp":2.62,"tv":30.28,"id":16586500}]}]}
{"op":"mcm","clk":"1005422372","pt":1580642606718,"mc":[{"id":"1.168219388","rc":[{"batb":[[0,2.76,11.49],[1,1.01,0.51],[2,2.76,0]],"ltp":3.5,"tv":340.72,"id":13508961},{"batb":[[0,3.35,17.23],[1,1.01,0.51],[2,3.35,0]],"ltp":2.62,"tv":30.28,"id":16586500}]}]}
{"op":"mcm","clk":"1005423015","pt":1580642609724,"mc":[{"id":"1.168219388","rc":[{"batb":[[0,3.2,18.48],[1,3.15,96.28],[2,3.1,50.24]],"batl":[[1,3.65,15.12],[2,4.2,13.06]],"ltp":3.5,"tv":340.72,"id":13508961},{"batb":[[0,3.5,43.97],[1,3.45,40.61],[2,3.35,34.88]],"batl":[[0,3.75,16.68],[1,3.9,14.28],[2,4.2,13.45]],"ltp":2.62,"tv":30.28,"id":16586500},{"batb":[[1,4,88.43]],"batl":[[0,4.7,30.91]],"ltp":0.0,"tv":0.0,"id":13508964},{"batl":[[0,5.5,9.24],[1,5.8,12.67]],"ltp":0.0,"tv":0.0,"id":16586502}]}]}
{"op":"mcm","clk":"1005423146","pt":1580642610362,"mc":[{"id":"1.168219388","rc":[{"batl":[[0,5.8,12.67],[1,5.8,0]],"ltp":0.0,"tv":0.0,"id":16586502}]}]}
{"op":"mcm","clk":"1005423579","pt":1580642612437,"mc":[{"id":"1.168219388","rc":[{"batl":[[0,5.4,9.24],[1,5.8,12.67]],"ltp":0.0,"tv":0.0,"id":16586502}]}]}
{"op":"mcm","clk":"1005425856","pt":1580642624586,"mc":[{"id":"1.168219388","rc":[{"batb":[[0,2.92,24.94],[1,1.01,0.51],[2,3.1,0]],"batl":[[0,4.2,13.06],[1,3.65,0],[2,4.2,0]],"ltp":3.5,"tv":340.72,"id":13508961},{"batb":[[0,2.94,24.31],[1,1.01,0.51],[2,3.35,0]],"batl":[[0,4.2,13.45],[1,3.9,0],[2,4.2,0]],"ltp":2.62,"tv":30.28,"id":16586500},{"batb":[[0,4,74.98],[1,1.01,0.51],[2,1.01,0]],"batl":[[0,4.7,19.99]],"ltp":0.0,"tv":0.0,"id":13508964},{"batb":[[0,5.1,33.05],[1,4.9,13.61],[2,1.01,0.51]],"batl":[[0,5.8,12.67],[1,5.8,0]],"ltp":0.0,"tv":0.0,"id":16586502}]}]}
{"op":"mcm","clk":"1005426497","pt":1580642627757,"mc":[{"id":"1.168219388","rc":[{"batb":[[0,2.94,56.44],[1,2.92,24.94],[2,2.9,47.94]],"ltp":3.5,"tv":340.72,"id":13508961},{"batb":[[0,3.05,82.25],[1,3,57.07],[2,2.94,24.31]],"ltp":2.62,"tv":30.28,"id":16586500},{"batb":[[0,4,92.41],[1,3.95,27.71],[2,1.01,0.51]],"ltp":0.0,"tv":0.0,"id":13508964},{"batb":[[0,5.1,46.83],[1,5,34.16],[2,4.9,13.61]],"ltp":0.0,"tv":0.0,"id":16586502}]}]}
{"op":"mcm","clk":"1005428464","pt":1580642638374,"mc":[{"id":"1.168219388","rc":[{"batb":[[0,2.92,24.94],[1,1.01,0.51],[2,2.9,0]],"ltp":3.5,"tv":340.72,"id":13508961}]}]}
{"op":"mcm","clk":"1005429077","pt":1580642641566,"mc":[{"id":"1.168219388","rc":[{"batb":[[0,3.7,44.62],[1,3.65,48.96],[2,2.92,24.94]],"batl":[[1,4.3,12.6]],"ltp":3.5,"tv":340.72,"id":13508961},{"batb":[[1,3,78.07]],"batl":[[0,3.45,16.8],[1,4.2,13.45]],"ltp":2.62,"tv":30.28,"id":16586500},{"batb":[[0,4,105.86]],"batl":[[0,4.6,10.92],[1,4.7,19.99]],"ltp":0.0,"tv":0.0,"id":13508964},{"batl":[[0,5.4,9.24],[1,5.8,12.67]],"ltp":0.0,"tv":0.0,"id":16586502}]}]}
{"op":"mcm","clk":"1005429197","pt":1580642642161,"mc":[{"id":"1.168219388","rc":[{"batb":[[0,3.7,58.07],[2,3.15,20.14]],"batl":[[2,6.2,11.49]],"ltp":3.5,"tv":340.72,"id":13508961},{"batl":[[0,3.25,23.37],[1,3.45,16.8],[2,3.75,16.76]],"ltp":2.62,"tv":30.28,"id":16586500},{"batb":[[0,4,83.98],[2,3.85,24.55]],"batl":[[0,4.6,32.4]],"ltp":0.0,"tv":0.0,"id":13508964},{"batl":[[1,5.7,13.3],[2,5.8,12.67]],"ltp":0.0,"tv":0.0,"id":16586502}]}]}
{"op":"mcm","clk":"1005432091","pt":1580642656725,"mc":[{"id":"1.168219388","rc":[{"trd":[[4.2,10.08]],"batb":[[0,3.7,13.45],[1,3.65,15.12]],"batl":[[0,4.2,8.02]],"ltp":4.2,"tv":350.8,"id":13508961},{"batb":[[0,3,21],[1,2.94,24.31],[2,2.44,15.97]],"ltp":2.62,"tv":30.28,"id":16586500},{"batb":[[0,4,13.44],[1,3.85,24.55],[2,1.01,0.51]],"ltp":0.0,"tv":0.0,"id":13508964},{"batb":[[0,5.1,33.05]],"ltp":0.0,"tv":0.0,"id":16586502}],"tv":381.09}]}
{"op":"mcm","clk":"1005432246","pt":1580642657421,"mc":[{"id":"1.168219388","rc":[{"batb":[[0,3.65,15.12],[1,3.15,20.14],[2,1.01,0.51]],"batl":[[0,4.3,12.6],[1,6.2,11.49],[2,6.2,0]],"ltp":4.2,"tv":350.8,"id":13508961},{"batb":[[1,2.44,15.97],[2,1.01,0.51]],"batl":[[0,3.45,16.8],[1,3.75,16.76],[2,3.75,0]],"ltp":2.62,"tv":30.28,"id":16586500},{"batl":[[0,4.6,10.92]],"ltp":0.0,"tv":0.0,"id":13508964},{"batl":[[1,5.8,12.67],[2,5.8,0]],"ltp":0.0,"tv":0.0,"id":16586502}]}]}
{"op":"mcm","clk":"1005432500","pt":1580642658607,"mc":[{"id":"1.168219388","rc":[{"batb":[[0,3.15,20.14],[1,1.01,0.51],[2,1.01,0]],"batl":[[0,6.2,11.49],[1,6.2,0]],"ltp":4.2,"tv":350.8,"id":13508961},{"batb":[[0,2.44,15.97],[1,1.01,0.51],[2,1.01,0]],"batl":[[0,3.75,16.76],[1,3.75,0]],"ltp":2.62,"tv":30.28,"id":16586500},{"batb":[[0,3.85,24.55],[1,1.01,0.51],[2,1.01,0]],"batl":[[0,4.7,19.99],[1,4.7,0]],"ltp":0.0,"tv":0.0,"id":13508964},{"batl":[[0,5.8,12.67],[1,5.8,0]],"ltp":0.0,"tv":0.0,"id":16586502}]}]}
{"op":"mcm","clk":"1005432726","pt":1580642659741,"mc":[{"id":"1.168219388","rc":[{"batb":[[0,3.15,84.66],[1,3.1,50.35],[2,1.01,0.51]],"ltp":4.2,"tv":350.8,"id":13508961},{"batb":[[0,2.54,62.2],[1,2.5,73.91],[2,2.44,15.97]],"ltp":2.62,"tv":30.28,"id":16586500},{"batb":[[0,3.9,48.16],[1,3.85,54.32],[2,1.01,0.51]],"ltp":0.0,"tv":0.0,"id":13508964}]}]}
{"op":"mcm","clk":"1005433575","pt":1580642663729,"mc":[{"id":"1.168219388","rc":[{"batb":[[0,2.44,15.97],[1,1.01,0.51],[2,2.44,0]],"ltp":2.62,"tv":30.28,"id":16586500},{"batb":[[0,3.85,24.55],[1,1.01,0.51],[2,1.01,0]],"ltp":0.0,"tv":0.0,"id":13508964},{"batb":[[1,4.9,13.61],[2,1.01,0.51]],"ltp":0.0,"tv":0.0,"id":16586502}]}]}
{"op":"mcm","clk":"1005434142","pt":1580642666543,"mc":[{"id":"1.168219388","rc":[{"batb":[[0,3.5,50.02],[1,3.45,40.55],[2,2.44,15.97]],"ltp":2.62,"tv":30.28,"id":16586500},{"batb":[[0,4.1,61.61],[1,4,53.15],[2,3.85,24.55]],"ltp":0.0,"tv":0.0,"id":13508964},{"batb":[[0,5.2,21.36],[1,5.1,33.05],[2,4.9,13.61]],"ltp":0.0,"tv":0.0,"id":16586502}]}]}
{"op":"mcm","clk":"1005434350","pt":1580642667543,"mc":[{"id":"1.168219388","rc":[{"batb":[[0,3.2,18.48],[1,3.15,84.66],[2,3.1,50.35]],"batl":[[0,3.5,19.59],[1,3.7,15.12],[2,4.3,24.86]],"ltp":4.2,"tv":350.8,"id":13508961},{"batb":[[2,3.4,17.07]],"batl":[[0,3.75,16.52],[1,3.85,14.28],[2,4.2,13.14]],"ltp":2.62,"tv":30.28,"id":16586500},{"batb":[[1,4,89.02],[2,1.01,0.51]],"batl":[[0,4.7,30.91]],"ltp":0.0,"tv":0.0,"id":13508964},{"batl":[[0,5.4,9.24],[1,5.7,13.06]],"ltp":0.0,"tv":0.0,"id":16586502}]}]}
{"op":"mcm","clk":"1005436843","pt":1580642680625,"mc":[{"id":"1.168219388","rc":[{"batb":[[0,2.92,25.41],[1,1.01,0.51],[2,3.1,0]],"batl":[[0,4.3,24.86],[1,3.7,0],[2,4.3,0]],"ltp":4.2,"tv":350.8,"id":13508961},{"batb":[[0,2.9,25.26],[1,1.01,0.51],[2,3.4,0]],"batl":[[0,4.2,13.14],[1,3.85,0],[2,4.2,0]],"ltp":2.62,"tv":30.28,"id":16586500},{"batb":[[0,4,75.57],[1,1.01,0.51],[2,1.01,0]],"batl":[[0,4.7,19.99]],"ltp":0.0,"tv":0.0,"id":13508964},{"batb":[[0,5.1,33.05],[1,4.9,13.61],[2,1.01,0.51]],"batl":[[0,5.7,13.06],[1,5.7,0]],"ltp":0.0,"tv":0.0,"id":16586502}]}]}
{"op":"mcm","clk":"1005437378","pt":1580642683516,"mc":[{"id":"1.168219388","rc":[{"batb":[[0,2.92,62.72],[1,2.88,49.09],[2,1.01,0.51]],"ltp":4.2,"tv":350.8,"id":13508961},{"batb":[[0,3.05,35.92],[1,3,57.46],[2,2.9,25.26]],"ltp":2.62,"tv":30.28,"id":16586500},{"batb":[[0,4,100.79],[1,3.95,27.64],[2,1.01,0.51]],"ltp":0.0,"tv":0.0,"id":13508964},{"batb":[[0,5.1,43.36],[1,5,34.22],[2,4.9,13.61]],"ltp":0.0,"tv":0.0,"id":16586502}]}]}
{"op":"mcm","clk":"1005438245","pt":1580642688599,"mc":[{"id":"1.168219388","rc":[{"batb":[[0,2.92,25.41],[1,1.01,0.51],[2,1.01,0]],"ltp":4.2,"tv":350.8,"id":13508961}]}]}
{"op":"mcm","clk":"1005438800","pt":1580642691602,"mc":[{"id":"1.168219388","rc":[{"batb":[[0,3.75,47.53],[1,3.7,32.72],[2,2.92,25.41]],"ltp":4.2,"tv":350.8,"id":13508961}]}]}
{"op":"mcm","clk":"1005439001","pt":1580642692725,"mc":[{"id":"1.168219388","rc":[{"batb":[[0,3.8,13.14],[1,3.75,47.53],[2,3.7,32.72]],"batl":[[1,6.2,11.09]],"ltp":4.2,"tv":350.8,"id":13508961},{"batl":[[0,3.2,24.23],[1,3.7,17.31]],"ltp":2.62,"tv":30.28,"id":16586500},{"batb":[[2,3.9,24.31]],"batl":[[0,4.6,21.24],[1,4.7,19.99]],"ltp":0.0,"tv":0.0,"id":13508964},{"batl":[[0,5.8,12.98]],"ltp":0.0,"tv":0.0,"id":16586502}]}]}
{"op":"mcm","clk":"1005439201","pt":1580642693723,"mc":[{"id":"1.168219388","rc":[{"batb":[[2,3.7,47.84]],"batl":[[0,4.3,37.47]],"ltp":4.2,"tv":350.8,"id":13508961},{"batb":[[2,2.98,21]],"batl":[[1,3.4,16.8],[2,3.7,17.31]],"ltp":2.62,"tv":30.28,"id":16586500},{"batb":[[1,3.95,41.08]],"batl":[[1,4.7,30.91]],"ltp":0.0,"tv":0.0,"id":13508964},{"batl":[[0,5.3,9.24],[1,5.8,12.98]],"ltp":0.0,"tv":0.0,"id":16586502}]}]}
{"op":"mcm","clk":"1005439372","pt":1580642694727,"mc":[{"id":"1.168219388","rc":[{"batl":[[0,4.6,32.17],[1,4.7,19.99]],"ltp":0.0,"tv":0.0,"id":13508964}]}]}
{"op":"mcm","clk":"1005441418","pt":1580642705736,"mc":[{"id":"1.168219388","rc":[{"batb":[[0,3.7,15.12],[1,3.25,19.43],[2,1.01,0.51]],"batl":[[0,4.3,12.6]],"ltp":4.2,"tv":350.8,"id":13508961},{"batb":[[0,2.98,21],[1,2.42,16.37],[2,1.01,0.51]],"batl":[[0,3.4,16.8],[1,3.7,17.31],[2,3.7,0]],"ltp":2.62,"tv":30.28,"id":16586500},{"batb":[[0,3.95,41.08],[1,3.9,24.31],[2,1.01,0.51]],"batl":[[0,4.6,10.92]],"ltp":0.0,"tv":0.0,"id":13508964}]}]}
{"op":"mcm","clk":"1005441584","pt":1580642706639,"mc":[{"id":"1.168219388","rc":[{"batb":[[0,3.25,19.43],[1,1.01,0.51],[2,1.01,0]],"batl":[[0,6.2,11.09],[1,6.2,0]],"ltp":4.2,"tv":350.8,"id":13508961},{"batb":[[0,2.42,16.37],[1,1.01,0.51],[2,1.01,0]],"batl":[[0,3.7,17.31],[1,3.7,0]],"ltp":2.62,"tv":30.28,"id":16586500},{"batb":[[0,3.95,27.64]],"batl":[[0,4.7,19.99],[1,4.7,0]],"ltp":0.0,"tv":0.0,"id":13508964},{"batl":[[0,5.8,12.98],[1,5.8,0]],"ltp":0.0,"tv":0.0,"id":16586502}]}]}
{"op":"mcm","clk":"1005441990","pt":1580642708651,"mc":[{"id":"1.168219388","rc":[{"batb":[[1,3.2,73.15],[2,3.15,48.47]],"ltp":4.2,"tv":350.8,"id":13508961},{"batb":[[0,2.52,44.83],[1,2.48,75.61],[2,2.42,16.37]],"ltp":2.62,"tv":30.28,"id":16586500},{"batb":[[1,3.9,53.32]],"ltp":0.0,"tv":0.0,"id":13508964}]}]}
{"op":"mcm","clk":"1005442154","pt":1580642709420,"mc":[{"id":"1.168219388","rc":[{"batb":[[0,3.2,73.15],[1,3.15,48.47],[2,1.01,0.51]],"ltp":4.2,"tv":350.8,"id":13508961},{"batb":[[2,2.42,16.21]],"batl":[[0,3.7,17.07]],"ltp":2.62,"tv":30.28,"id":16586500}]}]}
{"op":"mcm","clk":"1005442798","pt":1580642712759,"mc":[{"id":"1.168219388","rc":[{"batb":[[0,3.2,19.75],[1,1.01,0.51],[2,1.01,0]],"ltp":4.2,"tv":350.8,"id":13508961},{"batb":[[0,5.1,33.05]],"ltp":0.0,"tv":0.0,"id":16586502}]}]}
{"op":"mcm","clk":"1005443456","pt":1580642716556,"mc":[{"id":"1.168219388","rc":[{"batb":[[0,5.3,40.24],[1,3.8,13.06],[2,1.01,0.51]],"batl":[[1,21,5.43]],"ltp":4.2,"tv":350.8,"id":13508961},{"batl":[[0,2.62,15.89],[1,3.2,24.55]],"ltp":2.62,"tv":30.28,"id":16586500},{"batb":[[2,3.75,13.38]],"batl":[[0,4.4,22.9],[1,4.6,21.24]],"ltp":0.0,"tv":0.0,"id":13508964},{"batb":[[1,5,47.75]],"batl":[[1,5.9,12.51]],"ltp":0.0,"tv":0.0,"id":16586502}]}]}
{"op":"mcm","clk":"1005443605","pt":1580642717563,"mc":[{"id":"1.168219388","rc":[{"batb":[[1,5.1,10.08],[2,3.8,13.06]],"batl":[[0,6,8.4],[1,6.2,11.09],[2,21,5.43]],"ltp":4.2,"tv":350.8,"id":13508961},{"batb":[[0,2.52,71.72]],"batl":[[1,2.86,21.85],[2,3.2,24.55]],"ltp":2.62,"tv":30.28,"id":16586500},{"batb":[[2,3.8,14.28]],"batl":[[0,4.4,34.66]],"ltp":0.0,"tv":0.0,"id":13508964},{"batl":[[0,5.4,9.24],[1,5.8,12.98],[2,5.9,12.51]],"ltp":0.0,"tv":0.0,"id":16586502}]}]}
{"op":"mcm","clk":"1005443970","pt":1580642719645,"mc":[{"id":"1.168219388","rc":[{"batb":[[0,5.3,11.8],[1,5.2,29.32],[2,5.1,10.08]],"ltp":4.2,"tv":350.8,"id":13508961},{"batb":[[0,2.52,26.89],[1,2.42,16.21],[2,1.93,15.97]],"ltp":2.62,"tv":30.28,"id":16586500}]}]}
{"op":"mcm","clk":"1005444506","pt":1580642722652,"mc":[{"id":"1.168219388","rc":[{"batb":[[2,5.1,40.31]],"ltp":4.2,"tv":350.8,"id":13508961},{"batb":[[0,2.54,67.3],[1,2.52,26.89],[2,2.5,74.58]],"ltp":2.62,"tv":30.28,"id":16586500},{"batb":[[0,3.95,38.07]],"ltp":0.0,"tv":0.0,"id":13508964}]}]}
{"op":"mcm","clk":"1005445374","pt":1580642727486,"mc":[{"id":"1.168219388","rc":[{"batb":[[0,5.1,10.08],[1,3.8,13.06],[2,1.01,0.51]],"batl":[[1,21,5.43],[2,21,0]],"ltp":4.2,"tv":350.8,"id":13508961},{"batb":[[0,2.52,26.89],[1,1.93,15.97],[2,1.01,0.51]],"batl":[[0,2.86,21.85],[1,3.2,24.55],[2,3.2,0]],"ltp":2.62,"tv":30.28,"id":16586500},{"batb":[[0,3.8,14.28],[1,3.75,13.38],[2,1.01,0.51]],"batl":[[0,4.4,11.76]],"ltp":0.0,"tv":0.0,"id":13508964},{"batb":[[1,5,34.22]],"batl":[[1,5.9,12.51],[2,5.9,0]],"ltp":0.0,"tv":0.0,"id":16586502}]}]}
{"op":"mcm","clk":"1005445574","pt":1580642728561,"mc":[{"id":"1.168219388","rc":[{"batb":[[0,3.8,13.06],[1,1.01,0.51],[2,1.01,0]],"batl":[[0,21,5.43],[1,21,0]],"ltp":4.2,"tv":350.8,"id":13508961},{"batb":[[0,1.93,15.97],[1,1.01,0.51],[2,1.01,0]],"batl":[[0,3.2,24.55],[1,3.2,0]],"ltp":2.62,"tv":30.28,"id":16586500},{"batb":[[0,3.75,13.38],[1,1.01,0.51],[2,1.01,0]],"batl":[[0,4.6,21.24],[1,4.6,0]],"ltp":0.0,"tv":0.0,"id":13508964},{"batl":[[0,5.9,12.51],[1,5.9,0]],"ltp":0.0,"tv":0.0,"id":16586502}]}]}
{"op":"mcm","clk":"1005445967","pt":1580642730752,"mc":[{"id":"1.168219388","rc":[{"batb":[[1,3.7,46.97],[2,3.65,33.18]],"batl":[[0,20,5.74]],"ltp":4.2,"tv":350.8,"id":13508961},{"batb":[[0,1.98,75.81],[1,1.96,75.01],[2,1.93,15.82]],"batl":[[0,3.2,23.84]],"ltp":2.62,"tv":30.28,"id":16586500},{"batb":[[1,3.7,52.69],[2,3.65,34.11]],"ltp":0.0,"tv":0.0,"id":13508964},{"batb":[[0,5.1,44.36]],"ltp":0.0,"tv":0.0,"id":16586502}]}]}
{"op":"mcm","clk":"1005446321","pt":1580642732692,"mc":[{"id":"1.168219388","rc":[{"batb":[[0,1.93,15.82],[1,1.01,0.51],[2,1.93,0]],"ltp":2.62,"tv":30.28,"id":16586500},{"batb":[[1,1.01,0.51],[2,3.65,0]],"ltp":0.0,"tv":0.0,"id":13508964}]}]}
{"op":"mcm","clk":"1005446807","pt":1580642735576,"mc":[{"id":"1.168219388","rc":[{"batb":[[0,3.8,27.34]],"batl":[[0,4.4,11.76],[1,20,5.74]],"ltp":4.2,"tv":350.8,"id":13508961},{"batb":[[0,3.05,57.55],[1,3,57.81],[2,2.94,21]],"batl":[[1,3.35,17.64]],"ltp":2.62,"tv":30.28,"id":16586500},{"batb":[[0,4.1,36.5],[1,4,67.2],[2,3.75,13.38]],"batl":[[1,4.7,10.92]],"ltp":0.0,"tv":0.0,"id":13508964},{"batl":[[0,5.3,9.24],[1,5.9,12.51]],"ltp":0.0,"tv":0.0,"id":16586502}]}]}
{"op":"mcm","clk":"1005446934","pt":1580642736270,"mc":[{"id":"1.168219388","rc":[{"batl":[[0,4.2,12.98],[1,4.4,11.76],[2,6.2,11.41]],"ltp":4.2,"tv":350.8,"id":13508961},{"batl":[[2,3.7,17.07]],"ltp":2.62,"tv":30.28,"id":16586500},{"batb":[[1,4,89.55],[2,3.95,23.6]],"batl":[[1,4.7,31.22]],"ltp":0.0,"tv":0.0,"id":13508964},{"batl":[[1,5.8,12.9]],"ltp":0.0,"tv":0.0,"id":16586502}]}]}
{"op":"mcm","clk":"1005453750","pt":1580642772276,"mc":[{"id":"1.168219388","rc":[{"batb":[[1,3.2,19.75],[2,1.01,0.51]],"ltp":4.2,"tv":350.8,"id":13508961},{"batb":[[0,2.94,21],[1,2.92,24.86],[2,2.42,16.52]],"ltp":2.62,"tv":30.28,"id":16586500},{"batb":[[0,4,35.79],[1,3.95,23.6],[2,1.01,0.51]],"ltp":0.0,"tv":0.0,"id":13508964}]}]}
{"op":"mcm","clk":"1005454378","pt":1580642775700,"mc":[{"id":"1.168219388","rc":[{"batb":[[2,3.15,64.99]],"ltp":4.2,"tv":350.8,"id":13508961},{"batb":[[2,2.52,53.44]],"ltp":2.62,"tv":30.28,"id":16586500},{"batb":[[1,3.95,75],[2,3.9,29.04]],"ltp":0.0,"tv":0.0,"id":13508964}]}]}
{"op":"mcm","clk":"1005459339","pt":1580642801347,"mc":[{"id":"1.168219388","rc":[{"batb":[[0,3.8,14.28]],"batl":[[0,4.4,11.76],[1,6.2,11.41],[2,6.2,0]],"ltp":4.2,"tv":350.8,"id":13508961},{"batb":[[1,2.52,53.44],[2,2.48,76.27]],"batl":[[0,3.35,17.64],[1,3.7,17.07],[2,3.7,0]],"ltp":2.62,"tv":30.28,"id":16586500},{"batb":[[0,4,13.44]],"batl":[[0,4.7,31.22],[1,4.7,0]],"ltp":0.0,"tv":0.0,"id":13508964}]}]}
{"op":"mcm","clk":"1005459583","pt":1580642802613,"mc":[{"id":"1.168219388","rc":[{"batb":[[0,3.2,19.75],[1,3.15,64.99],[2,3.1,49.45]],"batl":[[0,6.2,11.41],[1,6.2,0]],"ltp":4.2,"tv":350.8,"id":13508961},{"batb":[[0,2.52,53.44],[1,2.48,76.27],[2,2.42,16.52]],"batl":[[0,3.7,17.07],[1,3.7,0]],"ltp":2.62,"tv":30.28,"id":16586500},{"batb":[[0,3.95,75],[1,3.9,29.04],[2,1.01,0.51]],"batl":[[0,4.7,20.3]],"ltp":0.0,"tv":0.0,"id":13508964},{"batl":[[0,5.8,12.9],[1,5.8,0]],"ltp":0.0,"tv":0.0,"id":16586502}]}]}
{"op":"mcm","clk":"1005460028","pt":1580642804758,"mc":[{"id":"1.168219388","rc":[{"batb":[[1,1.01,0.51],[2,3.1,0]],"ltp":4.2,"tv":350.8,"id":13508961},{"batb":[[0,2.42,16.52],[1,1.01,0.51],[2,2.42,0]],"ltp":2.62,"tv":30.28,"id":16586500},{"batb":[[0,3.95,51.33],[1,3.9,23.76]],"ltp":0.0,"tv":0.0,"id":13508964}]}]}
{"op":"mcm","clk":"1005460077","pt":1580642804959,"mc":[{"id":"1.168219388","rc":[{"batb":[[0,2.42,16.37]],"ltp":2.62,"tv":30.28,"id":16586500},{"batb":[[0,3.95,27.73]],"ltp":0.0,"tv":0.0,"id":13508964}]}]}
{"op":"mcm","clk":"1005460713","pt":1580642807431,"mc":[{"id":"1.168219388","rc":[{"batb":[[0,3.95,33.96],[1,3.9,28.43],[2,3.2,19.75]],"ltp":4.2,"tv":350.8,"id":13508961},{"batb":[[0,2.94,40.17],[1,2.9,50.68],[2,2.42,16.37]],"ltp":2.62,"tv":30.28,"id":16586500},{"batb":[[0,4,78.64],[1,3.95,27.73],[2,3.9,23.76]],"ltp":0.0,"tv":0.0,"id":13508964}]}]}
{"op":"mcm","clk":"1005461115","pt":1580642809658,"mc":[{"id":"1.168219388","rc":[{"batb":[[0,3.2,19.75],[1,1.01,0.51],[2,3.2,0]],"ltp":4.2,"tv":350.8,"id":13508961},{"batb":[[0,2.42,16.37],[1,1.01,0.51],[2,2.42,0]],"ltp":2.62,"tv":30.28,"id":16586500},{"batb":[[0,3.95,27.73],[1,3.9,23.76],[2,1.01,0.51]],"ltp":0.0,"tv":0.0,"id":13508964}]}]}
{"op":"mcm","clk":"1005461707","pt":1580642812567,"mc":[{"id":"1.168219388","rc":[{"batb":[[1,3.15,64.99],[2,3.1,49.45]],"ltp":4.2,"tv":350.8,"id":13508961},{"batb":[[0,2.52,53.44],[1,2.48,76.27],[2,2.42,16.37]],"ltp":2.62,"tv":30.28,"id":16586500},{"batb":[[0,3.95,51.4],[1,3.9,52.8]],"ltp":0.0,"tv":0.0,"id":13508964}]}]}
{"op":"mcm","clk":"1005472879","pt":1580642871441,"mc":[{"id":"1.168219388","rc":[{"batb":[[1,1.01,0.51],[2,3.1,0]],"ltp":4.2,"tv":350.8,"id":13508961},{"batb":[[0,5.1,35.42]],"ltp":0.0,"tv":0.0,"id":16586502}]}]}
{"op":"mcm","clk":"1005473404","pt":1580642874380,"mc":[{"id":"1.168219388","rc":[{"batb":[[0,5.3,22.74],[1,5.2,29.03],[2,3.2,19.75]],"ltp":4.2,"tv":350.8,"id":13508961}]}]}
{"op":"mcm","clk":"1005473637","pt":1580642875608,"mc":[{"id":"1.168219388","rc":[{"batb":[[0,5.3,34.54],[2,5.1,10.08]],"batl":[[0,6.2,18.97],[1,21,5.67]],"ltp":4.2,"tv":350.8,"id":13508961},{"batb":[[0,2.52,80.33]],"batl":[[0,2.6,16.05],[1,2.84,22.69],[2,3.2,24.55]],"ltp":2.62,"tv":30.28,"id":16586500},{"batb":[[2,3.8,14.28]],"batl":[[0,4.5,34.27],[1,4.6,21.09]],"ltp":0.0,"tv":0.0,"id":13508964},{"batb":[[1,5,47.75]],"batl":[[0,5.3,9.24],[1,5.8,12.9],[2,5.9,12.43]],"ltp":0.0,"tv":0.0,"id":16586502}]}]}
{"op":"mcm","clk":"1005473831","pt":1580642876685,"mc":[{"id":"1.168219388","rc":[{"batb":[[0,3.95,28.43],[1,3.9,23.76]],"ltp":0.0,"tv":0.0,"id":13508964},{"batb":[[0,5.1,33.05]],"ltp":0.0,"tv":0.0,"id":16586502}]}]}
{"op":"mcm","clk":"1005474376","pt":1580642879693,"mc":[{"id":"1.168219388","rc":[{"batb":[[0,4,27.93],[1,3.95,28.43],[2,3.9,23.76]],"ltp":0.0,"tv":0.0,"id":13508964}]}]}
{"op":"mcm","clk":"1005477961","pt":1580642900718,"mc":[{"id":"1.168219388","rc":[{"batb":[[0,3.8,13.06],[1,1.01,0.51],[2,5.1,0]],"batl":[[0,21,5.67],[1,21,0]],"ltp":4.2,"tv":350.8,"id":13508961},{"batb":[[0,1.93,15.89],[1,1.01,0.51],[2,2.42,0]],"batl":[[0,3.2,24.55],[1,2.84,0],[2,3.2,0]],"ltp":2.62,"tv":30.28,"id":16586500},{"batb":[[0,3.75,13.38],[1,1.01,0.51],[2,3.9,0]],"batl":[[0,4.6,21.09],[1,4.6,0]],"ltp":0.0,"tv":0.0,"id":13508964},{"batb":[[1,5,34.22]],"batl":[[0,5.9,12.43],[1,5.8,0],[2,5.9,0]],"ltp":0.0,"tv":0.0,"id":16586502}]}]}
{"op":"mcm","clk":"1005478390","pt":1580642902748,"mc":[{"id":"1.168219388","rc":[{"batb":[[1,3.75,52],[2,3.7,32.14]],"ltp":4.2,"tv":350.8,"id":13508961},{"batb":[[0,1.96,86.22],[1,1.94,77.39],[2,1.93,15.89]],"ltp":2.62,"tv":30.28,"id":16586500},{"batb":[[0,3.75,63.71],[1,3.7,33.09],[2,1.01,0.51]],"ltp":0.0,"tv":0.0,"id":13508964}]}]}
{"op":"mcm","clk":"1005478477","pt":1580642903176,"mc":[{"id":"1.168219388","rc":[{"batb":[[1,1.01,0.51],[2,3.7,0]],"ltp":4.2,"tv":350.8,"id":13508961},{"batb":[[0,1.93,15.89],[1,1.01,0.51],[2,1.93,0]],"ltp":2.62,"tv":30.28,"id":16586500},{"batb":[[0,3.75,13.38],[1,1.01,0.51],[2,1.01,0]],"ltp":0.0,"tv":0.0,"id":13508964}]}]}
{"op":"mcm","clk":"1005478905","pt":1580642905467,"mc":[{"id":"1.168219388","rc":[{"batb":[[0,6,51.03],[1,5.9,21.52],[2,3.8,13.06]],"ltp":4.2,"tv":350.8,"id":13508961},{"batb":[[0,2.38,64.13],[1,2.36,44.01],[2,1.93,15.89]],"ltp":2.62,"tv":30.28,"id":16586500},{"batb":[[0,3.95,31.71],[1,3.9,29.36],[2,3.75,13.38]],"ltp":0.0,"tv":0.0,"id":13508964}]}]}
{"op":"mcm","clk":"1005479534","pt":1580642909367,"mc":[{"id":"1.168219388","rc":[{"batb":[[0,3.8,13.06],[1,1.01,0.51],[2,3.8,0]],"ltp":4.2,"tv":350.8,"id":13508961},{"batb":[[0,1.93,15.89],[1,1.01,0.51],[2,1.93,0]],"ltp":2.62,"tv":30.28,"id":16586500},{"batb":[[0,3.75,13.38],[1,1.01,0.51],[2,3.75,0]],"ltp":0.0,"tv":0.0,"id":13508964}]}]}
{"op":"mcm","clk":"1005480022","pt":1580642912302,"mc":[{"id":"1.168219388","rc":[{"batb":[[1,3.75,52],[2,3.7,32.14]],"ltp":4.2,"tv":350.8,"id":13508961},{"batb":[[0,1.96,86.22],[1,1.94,77.39],[2,1.93,15.89]],"ltp":2.62,"tv":30.28,"id":16586500},{"batb":[[0,3.75,63.71],[1,3.7,33.09],[2,1.01,0.51]],"ltp":0.0,"tv":0.0,"id":13508964}]}]}
{"op":"mcm","clk":"1005484241","pt":1580642937094,"mc":[{"id":"1.168219388","rc":[{"batb":[[1,1.01,0.51],[2,3.7,0]],"ltp":4.2,"tv":350.8,"id":13508961},{"batb":[[0,5.1,23.22]],"ltp":0.0,"tv":0.0,"id":16586502}]}]}
{"op":"mcm","clk":"1005484960","pt":1580642940753,"mc":[{"id":"1.168219388","rc":[{"batb":[[0,17,14.36],[1,16.5,11.95],[2,14.5,5.98]],"ltp":4.2,"tv":350.8,"id":13508961},{"batl":[[0,2.04,15.66],[1,2.24,23.92],[2,3.2,24.55]],"ltp":2.62,"tv":30.28,"id":16586500},{"batl":[[0,4.2,12.9],[1,4.6,21.09]],"ltp":0.0,"tv":0.0,"id":13508964},{"batb":[[1,5,47.6]],"ltp":0.0,"tv":0.0,"id":16586502}]}]}
{"op":"mcm","clk":"1005485152","pt":1580642941668,"mc":[{"id":"1.168219388","rc":[{"batb":[[0,1.96,129.91]],"batl":[[1,2.16,36.13],[2,2.24,23.92]],"ltp":2.62,"tv":30.28,"id":16586500},{"batb":[[2,3.65,15.12]],"batl":[[1,4.3,12.6]],"ltp":0.0,"tv":0.0,"id":13508964},{"batb":[[2,4.5,11.76]],"batl":[[0,5.3,9.24],[1,5.9,12.43]],"ltp":0.0,"tv":0.0,"id":16586502}]}]}
{"op":"mcm","clk":"1005490822","pt":1580642973190,"mc":[{"id":"1.168219388","rc":[{"batb":[[0,9,7.16],[1,1.01,0.51],[2,14.5,0]],"ltp":4.2,"tv":350.8,"id":13508961},{"batb":[[0,1.96,43.69],[1,1.83,18.65],[2,1.01,0.51]],"batl":[[0,2.16,36.13],[1,2.24,23.92],[2,2.24,0]],"ltp":2.62,"tv":30.28,"id":16586500}]}]}
{"op":"mcm","clk":"1005491104","pt":1580642974815,"mc":[{"id":"1.168219388","rc":[{"batb":[[0,1.83,18.65],[1,1.01,0.51],[2,1.01,0]],"batl":[[0,2.24,23.92],[1,2.24,0]],"ltp":2.62,"tv":30.28,"id":16586500},{"batb":[[2,1.01,0.51]],"batl":[[1,4.3,0]],"ltp":0.0,"tv":0.0,"id":13508964},{"batb":[[2,1.01,0.51]],"batl":[[0,5.9,12.43],[1,5.9,0]],"ltp":0.0,"tv":0.0,"id":16586502}]}]}
{"op":"mcm","clk":"1005491388","pt":1580642976513,"mc":[{"id":"1.168219388","rc":[{"batb":[[0,9.8,16.87],[1,9.6,15.24],[2,9,7.16]],"ltp":4.2,"tv":350.8,"id":13508961},{"batb":[[0,1.88,61.64],[1,1.86,89.42],[2,1.83,18.65]],"ltp":2.62,"tv":30.28,"id":16586500}]}]}
{"op":"mcm","clk":"1005493924","pt":1580642990521,"mc":[{"id":"1.168219388","rc":[{"batb":[[0,1.83,18.65],[1,1.01,0.51],[2,1.83,0]],"ltp":2.62,"tv":30.28,"id":16586500}]}]}
{"op":"mcm","clk":"1005494555","pt":1580642993766,"mc":[{"id":"1.168219388","rc":[{"batb":[[0,9.8,21.07]],"batl":[[0,11.5,17.07],[1,13,3.36],[2,18,7]],"ltp":4.2,"tv":350.8,"id":13508961},{"batb":[[0,2.14,59.57],[1,2.12,59.97],[2,2.1,24.63]],"batl":[[1,2.3,31.93],[2,2.56,16.6]],"ltp":2.62,"tv":30.28,"id":16586500},{"batb":[[1,3.7,48.21]],"batl":[[1,4.3,37.94]],"ltp":0.0,"tv":0.0,"id":13508964},{"batb":[[2,4.9,13.69]],"batl":[[0,5.3,9.24],[1,5.8,12.67],[2,5.9,12.43]],"ltp":0.0,"tv":0.0,"id":16586502}]}]}
{"op":"mcm","clk":"1005494688","pt":1580642994501,"mc":[{"id":"1.168219388","rc":[{"batl":[[1,2.56,16.6],[2,2.56,0]],"ltp":2.62,"tv":30.28,"id":16586500},{"batl":[[0,4.3,37.94],[1,4.3,0]],"ltp":0.0,"tv":0.0,"id":13508964},{"batb":[[1,5,34.22]],"batl":[[2,5.9,0]],"ltp":0.0,"tv":0.0,"id":16586502}]}]}
{"op":"mcm","clk":"1005495095","pt":1580642996594,"mc":[{"id":"1.168219388","rc":[{"batb":[[2,2.1,62.44]],"batl":[[1,2.32,31.09],[2,2.56,16.6]],"ltp":2.62,"tv":30.28,"id":16586500}]}]}
{"op":"mcm","clk":"1005495779","pt":1580643000305,"mc":[{"id":"1.168219388","rc":[{"trd":[[11.5,0.34]],"batl":[[0,11.5,16.91]],"ltp":11.5,"tv":351.14,"id":13508961}],"tv":381.43}]}
{"op":"mcm","clk":"1005496667","pt":1580643004498,"mc":[{"id":"1.168219388","rc":[{"batb":[[0,9.8,4.2],[1,9,7.16],[2,5.8,19.04]],"ltp":11.5,"tv":351.14,"id":13508961},{"batb":[[0,2.1,62.44],[1,1.96,30.29],[2,1.01,0.51]],"ltp":2.62,"tv":30.28,"id":16586500},{"batb":[[0,3.75,45.12]],"ltp":0.0,"tv":0.0,"id":13508964}]}]}
{"op":"mcm","clk":"1005496887","pt":1580643005484,"mc":[{"id":"1.168219388","rc":[{"batb":[[0,5.8,19.04],[1,1.01,0.51],[2,5.8,0]],"batl":[[0,18,7],[1,13,0],[2,18,0]],"ltp":11.5,"tv":351.14,"id":13508961},{"batb":[[0,1.96,30.29],[1,1.01,0.51],[2,1.01,0]],"batl":[[0,2.56,16.6],[1,2.32,0],[2,2.56,0]],"ltp":2.62,"tv":30.28,"id":16586500},{"batb":[[1,3.7,33.09]],"batl":[[0,4.3,25.34]],"ltp":0.0,"tv":0.0,"id":13508964},{"batl":[[0,5.8,12.67],[1,5.8,0]],"ltp":0.0,"tv":0.0,"id":16586502}]}]}
{"op":"mcm","clk":"1005497271","pt":1580643007493,"mc":[{"id":"1.168219388","rc":[{"batb":[[0,6,58.64],[1,5.9,21.7],[2,5.8,19.04]],"ltp":11.5,"tv":351.14,"id":13508961},{"batb":[[0,2,79.62],[1,1.98,73.55],[2,1.96,30.29]],"ltp":2.62,"tv":30.28,"id":16586500},{"batb":[[0,5.1,31.19]],"ltp":0.0,"tv":0.0,"id":16586502}]}]}
{"op":"mcm","clk":"1005497732","pt":1580643009912,"mc":[{"id":"1.168219388","rc":[{"batb":[[0,1.96,30.29],[1,1.01,0.51],[2,1.96,0]],"ltp":2.62,"tv":30.28,"id":16586500},{"batb":[[0,3.75,13.38],[1,1.01,0.51],[2,1.01,0]],"ltp":0.0,"tv":0.0,"id":13508964}]}]}
{"op":"mcm","clk":"1005498488","pt":1580643013708,"mc":[{"id":"1.168219388","rc":[{"batb":[[0,6.4,7.56],[1,6,58.64],[2,5.9,21.7]],"batl":[[0,7,17.7],[1,8,5.88],[2,9.4,9.52]],"ltp":11.5,"tv":351.14,"id":13508961},{"batb":[[0,2.42,45.43],[1,2.38,102.82],[2,2.32,31.09]],"batl":[[1,2.6,26.05],[2,3,11.17]],"ltp":2.62,"tv":30.28,"id":16586500},{"batb":[[0,3.85,32.99],[1,3.8,31.41],[2,3.75,28.5]],"batl":[[1,4.4,11.76]],"ltp":0.0,"tv":0.0,"id":13508964},{"batl":[[0,5.3,9.24],[1,5.8,12.67]],"ltp":0.0,"tv":0.0,"id":16586502}]}]}
{"op":"mcm","clk":"1005498562","pt":1580643014393,"mc":[{"id":"1.168219388","rc":[{"batl":[[0,4.3,24.23]],"ltp":0.0,"tv":0.0,"id":13508964}]}]}
{"op":"mcm","clk":"1005498821","pt":1580643015427,"mc":[{"id":"1.168219388","rc":[{"trd":[[5.1,6.72]],"batb":[[0,5.1,27.83]],"ltp":5.1,"tv":6.72,"id":16586502}],"tv":388.15}]}
{"op":"mcm","clk":"1005499680","pt":1580643020213,"mc":[{"id":"1.168219388","rc":[{"batl":[[1,4.4,0]],"ltp":0.0,"tv":0.0,"id":13508964}]}]}
{"op":"mcm","clk":"1005500275","pt":1580643023243,"mc":[{"id":"1.168219388","rc":[{"batl":[[0,4.3,36.84]],"ltp":0.0,"tv":0.0,"id":13508964}]}]}
{"op":"mcm","clk":"1005500722","pt":1580643025638,"mc":[{"id":"1.168219388","rc":[{"batb":[[1,6,47.1]],"batl":[[1,9.4,9.52],[2,9.4,0]],"ltp":11.5,"tv":351.14,"id":13508961},{"batb":[[2,2.18,21.79]],"batl":[[1,3,11.17],[2,3,0]],"ltp":2.62,"tv":30.28,"id":16586500}]}]}
{"op":"mcm","clk":"1005500921","pt":1580643026645,"mc":[{"id":"1.168219388","rc":[{"batb":[[1,5.8,19.04],[2,4.3,19.51]],"ltp":11.5,"tv":351.14,"id":13508961},{"batb":[[0,2.38,17],[1,2.18,21.79],[2,1.01,0.51]],"ltp":2.62,"tv":30.28,"id":16586500},{"batb":[[0,3.8,31.41],[1,3.75,28.5],[2,1.01,0.51]],"ltp":0.0,"tv":0.0,"id":13508964}]}]}
{"op":"mcm","clk":"1005500972","pt":1580643027028,"mc":[{"id":"1.168219388","rc":[{"batb":[[0,4.3,19.51],[1,1.01,0.51],[2,4.3,0]],"batl":[[0,9.4,9.52],[1,9.4,0]],"ltp":11.5,"tv":351.14,"id":13508961},{"batb":[[0,2.18,21.79],[1,1.01,0.51],[2,1.01,0]],"batl":[[0,3,11.17],[1,3,0]],"ltp":2.62,"tv":30.28,"id":16586500},{"batb":[[1,3.75,13.38]],"batl":[[0,4.3,24.23]],"ltp":0.0,"tv":0.0,"id":13508964},{"batl":[[0,5.8,12.67],[1,5.8,0]],"ltp":5.1,"tv":6.72,"id":16586502}]}]}
{"op":"mcm","clk":"1005501475","pt":1580643029439,"mc":[{"id":"1.168219388","rc":[{"batb":[[0,4.3,58],[1,4.2,47.53],[2,1.01,0.51]],"ltp":11.5,"tv":351.14,"id":13508961},{"batb":[[0,2.22,86.27],[1,2.2,53.91],[2,2.18,21.79]],"ltp":2.62,"tv":30.28,"id":16586500},{"batb":[[1,3.75,45.95]],"ltp":0.0,"tv":0.0,"id":13508964}]}]}
{"op":"mcm","clk":"1005508041","pt":1580643065640,"mc":[{"id":"1.168219388","rc":[{"batb":[[0,4.3,19.51],[1,1.01,0.51],[2,1.01,0]],"ltp":11.5,"tv":351.14,"id":13508961}]}]}
{"op":"mcm","clk":"1005508619","pt":1580643068672,"mc":[{"id":"1.168219388","rc":[{"batb":[[0,8.2,18.35],[1,8,22.37],[2,4.3,19.51]],"ltp":11.5,"tv":351.14,"id":13508961}]}]}
{"op":"mcm","clk":"1005508818","pt":1580643069739,"mc":[{"id":"1.168219388","rc":[{"batb":[[0,8.2,23.39],[2,7.6,10.23]],"batl":[[1,10.5,4.2],[2,16,8.58]],"ltp":11.5,"tv":351.14,"id":13508961},{"batb":[[1,2.2,88.36]],"batl":[[0,2.34,21.17],[1,2.46,28.57],[2,2.76,13.61]],"ltp":2.62,"tv":30.28,"id":16586500},{"batb":[[2,3.7,28.97]],"batl":[[0,4.2,12.98],[1,4.3,36.84]],"ltp":0.0,"tv":0.0,"id":13508964},{"batl":[[0,5.3,9.24],[1,5.8,12.67]],"ltp":5.1,"tv":6.72,"id":16586502}]}]}
{"op":"mcm","clk":"1005508916","pt":1580643070285,"mc":[{"id":"1.168219388","rc":[{"batl":[[1,2.76,13.61],[2,2.76,0]],"ltp":2.62,"tv":30.28,"id":16586500}]}]}
{"op":"mcm","clk":"1005509312","pt":1580643072463,"mc":[{"id":"1.168219388","rc":[{"batl":[[1,2.44,28.57],[2,2.76,13.61]],"ltp":2.62,"tv":30.28,"id":16586500}]}]}
{"op":"mcm","clk":"1005512874","pt":1580643091418,"mc":[{"id":"1.168219388","rc":[{"batb":[[0,8.2,5.04],[1,4.9,14.01],[2,1.01,0.51]],"batl":[[0,10.5,4.2],[1,16,8.58],[2,16,0]],"ltp":11.5,"tv":351.14,"id":13508961},{"batb":[[0,2.2,34.45],[1,2,28.33],[2,1.01,0.51]],"batl":[[0,2.44,28.57],[1,2.76,13.61],[2,2.76,0]],"ltp":2.62,"tv":30.28,"id":16586500},{"batb":[[0,3.7,28.97],[1,1.01,0.51],[2,3.7,0]],"batl":[[0,4.3,36.84],[1,4.3,0]],"ltp":0.0,"tv":0.0,"id":13508964},{"batb":[[0,4.9,13.69],[1,4.5,11.76],[2,1.01,0.51]],"ltp":5.1,"tv":6.72,"id":16586502}]}]}
{"op":"mcm","clk":"1005513167","pt":1580643092800,"mc":[{"id":"1.168219388","rc":[{"batb":[[0,4.9,14.01],[1,1.01,0.51],[2,1.01,0]],"batl":[[0,16,8.58],[1,16,0]],"ltp":11.5,"tv":351.14,"id":13508961},{"batb":[[0,2,28.33],[1,1.01,0.51],[2,1.01,0]],"batl":[[0,2.76,13.61],[1,2.76,0]],"ltp":2.62,"tv":30.28,"id":16586500},{"batb":[[0,3.7,13.85]],"batl":[[0,4.3,24.23]],"ltp":0.0,"tv":0.0,"id":13508964},{"batb":[[1,1.01,0.51],[2,1.01,0]],"batl":[[0,5.8,12.67],[1,5.8,0]],"ltp":5.1,"tv":6.72,"id":16586502}]}]}
{"op":"mcm","clk":"1005513447","pt":1580643094406,"mc":[{"id":"1.168219388","rc":[{"batb":[[0,2.04,92.21],[1,2.02,69.41],[2,2,28.33]],"ltp":2.62,"tv":30.28,"id":16586500},{"batb":[[0,3.7,65.24],[1,3.65,34.69],[2,1.01,0.51]],"ltp":0.0,"tv":0.0,"id":13508964},{"batb":[[0,5,50.22],[1,4.9,50.17],[2,1.01,0.51]],"ltp":5.1,"tv":6.72,"id":16586502}]}]}
{"op":"mcm","clk":"1005514105","pt":1580643097726,"mc":[{"id":"1.168219388","rc":[{"batb":[[0,13,29.67],[1,12.5,20.67],[2,12,9.28]],"ltp":11.5,"tv":351.14,"id":13508961},{"batb":[[0,2.04,132.54]],"batl":[[0,2.14,27.54],[1,2.26,32.77],[2,2.5,18.02]],"ltp":2.62,"tv":30.28,"id":16586500},{"batb":[[1,3.65,48.85],[2,3.6,15.96]],"batl":[[0,4.2,38.17],[1,4.3,24.23]],"ltp":0.0,"tv":0.0,"id":13508964},{"batb":[[2,4.5,11.76]],"batl":[[0,5.3,9.24],[1,5.8,12.67]],"ltp":5.1,"tv":6.72,"id":16586502}]}]}
{"op":"mcm","clk":"1005514291","pt":1580643098620,"mc":[{"id":"1.168219388","rc":[{"batl":[[1,4.3,0]],"ltp":0.0,"tv":0.0,"id":13508964}]}]}
{"op":"mcm","clk":"1005515561","pt":1580643105514,"mc":[{"id":"1.168219388","rc":[{"batb":[[0,13,3.36],[1,12,9.28],[2,6.2,15.74]],"ltp":11.5,"tv":351.14,"id":13508961},{"batb":[[0,2.04,40.33],[1,2,28.33],[2,1.84,18.33]],"ltp":2.62,"tv":30.28,"id":16586500},{"batb":[[0,3.7,13.85],[1,3.65,14.16]],"ltp":0.0,"tv":0.0,"id":13508964},{"batb":[[0,4.9,13.69],[1,4.5,11.76],[2,1.01,0.51]],"ltp":5.1,"tv":6.72,"id":16586502}]}]}
{"op":"mcm","clk":"1005517302","pt":1580643114917,"mc":[{"id":"1.168219388","rc":[{"batb":[[0,6.2,15.74],[1,1.01,0.51],[2,6.2,0]],"ltp":11.5,"tv":351.14,"id":13508961},{"batb":[[0,1.84,18.33],[1,1.01,0.51],[2,1.84,0]],"batl":[[0,2.5,18.02],[1,2.26,0],[2,2.5,0]],"ltp":2.62,"tv":30.28,"id":16586500},{"batb":[[0,3.65,14.16],[1,1.01,0.51],[2,3.6,0]],"batl":[[0,4.2,25.57]],"ltp":0.0,"tv":0.0,"id":13508964},{"batb":[[1,1.01,0.51],[2,1.01,0]],"batl":[[0,5.8,12.67],[1,5.8,0]],"ltp":5.1,"tv":6.72,"id":16586502}]}]}
{"op":"mcm","clk":"1005517783","pt":1580643117865,"mc":[{"id":"1.168219388","rc":[{"batb":[[0,6.4,48.93],[1,6.2,53.75],[2,1.01,0.51]],"ltp":11.5,"tv":351.14,"id":13508961},{"batb":[[0,1.89,89.91],[1,1.87,88.31],[2,1.84,18.33]],"ltp":2.62,"tv":30.28,"id":16586500},{"batb":[[0,3.65,61.6],[1,3.6,36.03],[2,1.01,0.51]],"ltp":0.0,"tv":0.0,"id":13508964},{"batb":[[0,5.1,25.67],[1,5,35.05],[2,4.9,13.69]],"ltp":5.1,"tv":6.72,"id":16586502}]}]}
{"op":"mcm","clk":"1005518823","pt":1580643123492,"mc":[{"id":"1.168219388","rc":[{"batb":[[0,6.2,15.74],[1,1.01,0.51],[2,1.01,0]],"ltp":11.5,"tv":351.14,"id":13508961},{"batb":[[0,5,35.05],[1,4.9,13.69],[2,1.01,0.51]],"ltp":5.1,"tv":6.72,"id":16586502}]}]}
{"op":"mcm","clk":"1005519411","pt":1580643126663,"mc":[{"id":"1.168219388","rc":[{"batb":[[0,34,11.71],[1,32,9.04],[2,27,3.48]],"ltp":11.5,"tv":351.14,"id":13508961},{"batl":[[0,1.95,18.02],[1,2.16,26.59],[2,2.5,18.02]],"ltp":2.62,"tv":30.28,"id":16586500},{"batl":[[0,4.1,13.77],[1,4.2,25.57]],"ltp":0.0,"tv":0.0,"id":13508964},{"batb":[[0,5,57.21],[1,4.9,50.38]],"batl":[[1,5.9,12.35]],"ltp":5.1,"tv":6.72,"id":16586502}]}]}
{"op":"mcm","clk":"1005519476","pt":1580643126980,"mc":[{"id":"1.168219388","rc":[{"batl":[[2,2.5,0]],"ltp":2.62,"tv":30.28,"id":16586500},{"batl":[[1,4.2,0]],"ltp":0.0,"tv":0.0,"id":13508964},{"batb":[[1,4.9,36.69]],"batl":[[0,5.9,12.35],[1,5.9,0]],"ltp":5.1,"tv":6.72,"id":16586502}]}]}
{"op":"mcm","clk":"1005519676","pt":1580643128195,"mc":[{"id":"1.168219388","rc":[{"batb":[[0,1.89,136.96]],"batl":[[1,2.1,37.81],[2,2.16,26.59]],"ltp":2.62,"tv":30.28,"id":16586500},{"batb":[[2,3.5,16.8]],"batl":[[0,4.1,27.21]],"ltp":0.0,"tv":0.0,"id":13508964},{"batb":[[2,4.5,11.76]],"batl":[[0,5.3,9.24],[1,5.9,12.35]],"ltp":5.1,"tv":6.72,"id":16586502}]}]}
{"op":"mcm","clk":"1005521923","pt":1580643141678,"mc":[{"id":"1.168219388","rc":[{"batb":[[0,27,3.48],[1,11.5,9.84],[2,1.01,0.51]],"ltp":11.5,"tv":351.14,"id":13508961},{"batb":[[0,1.89,47.05],[1,1.84,18.33],[2,1.75,21.72]],"ltp":2.62,"tv":30.28,"id":16586500},{"batb":[[0,3.65,51.75]],"ltp":0.0,"tv":0.0,"id":13508964}]}]}
{"op":"mcm","clk":"1005521999","pt":1580643142109,"mc":[{"id":"1.168219388","rc":[{"batb":[[0,11.5,9.84],[1,1.01,0.51],[2,1.01,0]],"ltp":11.5,"tv":351.14,"id":13508961},{"batb":[[1,1.75,21.72],[2,1.01,0.51]],"batl":[[0,2.1,37.81],[1,2.16,26.59],[2,2.16,0]],"ltp":2.62,"tv":30.28,"id":16586500}]}]}
{"op":"mcm","clk":"1005522225","pt":1580643143327,"mc":[{"id":"1.168219388","rc":[{"batb":[[0,1.75,21.72],[1,1.01,0.51],[2,1.01,0]],"batl":[[0,2.16,26.59],[1,2.16,0]],"ltp":2.62,"tv":30.28,"id":16586500},{"batb":[[2,1.01,0.51]],"batl":[[0,4.1,13.77]],"ltp":0.0,"tv":0.0,"id":13508964},{"batb":[[2,1.01,0.51]],"batl":[[0,5.9,12.35],[1,5.9,0]],"ltp":5.1,"tv":6.72,"id":16586502}]}]}
{"op":"mcm","clk":"1005522567","pt":1580643144666,"mc":[{"id":"1.168219388","rc":[{"batb":[[0,13,10.82],[1,12.5,21.25],[2,11.5,9.84]],"ltp":11.5,"tv":351.14,"id":13508961},{"batb":[[0,1.8,99.09],[1,1.78,101.07],[2,1.75,21.72]],"ltp":2.62,"tv":30.28,"id":16586500}]}]}
{"op":"mcm","clk":"1005522603","pt":1580643144889,"mc":[{"id":"1.168219388","rc":[{"batb":[[0,11.5,9.84],[1,1.01,0.51],[2,11.5,0]],"ltp":11.5,"tv":351.14,"id":13508961},{"batb":[[0,1.75,21.72],[1,1.01,0.51],[2,1.75,0]],"ltp":2.62,"tv":30.28,"id":16586500}]}]}
{"op":"mcm","clk":"1005522884","pt":1580643146302,"mc":[{"id":"1.168219388","rc":[{"batb":[[0,26,8.15],[1,25,10],[2,11.5,9.84]],"ltp":11.5,"tv":351.14,"id":13508961},{"batb":[[0,1.93,58.5],[1,1.91,82.54],[2,1.75,21.72]],"ltp":2.62,"tv":30.28,"id":16586500},{"batb":[[0,3.65,64.18]],"ltp":0.0,"tv":0.0,"id":13508964}]}]}
{"op":"mcm","clk":"1005524083","pt":1580643153013,"mc":[{"id":"1.168219388","rc":[{"batb":[[0,11.5,9.84],[1,1.01,0.51],[2,11.5,0]],"ltp":11.5,"tv":351.14,"id":13508961},{"batb":[[0,1.75,21.72],[1,1.01,0.51],[2,1.75,0]],"ltp":2.62,"tv":30.28,"id":16586500},{"batb":[[0,3.65,51.75]],"ltp":0.0,"tv":0.0,"id":13508964}]}]}
{"op":"mcm","clk":"1005524685","pt":1580643156502,"mc":[{"id":"1.168219388","rc":[{"batb":[[0,13,10.82],[1,12.5,21.25],[2,11.5,9.84]],"ltp":11.5,"tv":351.14,"id":13508961},{"batb":[[0,1.8,99.09],[1,1.78,101.07],[2,1.75,21.72]],"ltp":2.62,"tv":30.28,"id":16586500}]}]}
{"op":"mcm","clk":"1005525653","pt":1580643161764,"mc":[{"id":"1.168219388","rc":[{"batb":[[0,11.5,9.84],[1,1.01,0.51],[2,11.5,0]],"ltp":11.5,"tv":351.14,"id":13508961}]}]}
{"op":"mcm","clk":"1005526263","pt":1580643164312,"mc":[{"id":"1.168219388","rc":[{"batb":[[0,1.01,0.51],[1,1.01,0]],"ltp":11.5,"tv":351.14,"id":13508961},{"batb":[[0,1.81,51.25],[1,1.8,99.09],[2,1.78,101.07]],"batl":[[0,1.85,21.32],[1,1.97,17.31],[2,2,42.01]],"ltp":2.62,"tv":30.28,"id":16586500},{"batb":[[2,3.5,16.8]],"batl":[[0,4,13.44],[1,4.1,13.77],[2,4.7,20.22]],"ltp":0.0,"tv":0.0,"id":13508964},{"batb":[[0,5.1,12.9],[1,5,43.6],[2,4.9,36.69]],"batl":[[0,5.3,9.24],[1,5.9,12.35],[2,6.8,18.8]],"ltp":5.1,"tv":6.72,"id":16586502}]}]}
{"op":"mcm","clk":"1005527848","pt":1580643171999,"mc":[{"id":"1.168219388","rc":[{"batb":[[0,14,13.44],[1,1.01,0.51]],"ltp":11.5,"tv":351.14,"id":13508961}]}]}
{"op":"mcm","clk":"1005530922","pt":1580643187177,"mc":[{"id":"1.168219388","rc":[{"batl":[[0,1.85,21.01],[1,1.98,17.07]],"ltp":2.62,"tv":30.28,"id":16586500},{"batb":[[0,3.65,37.59],[1,3.6,50.82]],"batl":[[0,4,27.76],[1,4.7,20.22],[2,4.7,0]],"ltp":0.0,"tv":0.0,"id":13508964},{"batb":[[0,5.1,12.75]],"batl":[[2,6.8,18.65]],"ltp":5.1,"tv":6.72,"id":16586502}]}]}
{"op":"mcm","clk":"1005532516","pt":1580643195672,"mc":[{"id":"1.168219388","rc":[{"batl":[[0,1.86,20.69],[1,1.99,16.84]],"ltp":2.62,"tv":30.28,"id":16586500},{"batb":[[1,3.6,36.03],[2,3.55,15.26]],"batl":[[0,3.95,14.79],[1,4,13.44],[2,4.6,21.48]],"ltp":0.0,"tv":0.0,"id":13508964},{"batl":[[1,6,12.12],[2,6.8,18.49]],"ltp":5.1,"tv":6.72,"id":16586502}]}]}
{"op":"mcm","clk":"1005541398","pt":1580643239197,"mc":[{"id":"1.168219388","rc":[{"trd":[[3.65,17.69]],"batb":[[0,3.65,28.74]],"ltp":3.65,"tv":17.69,"id":13508964}],"tv":405.84}]}
{"op":"mcm","clk":"1005549151","pt":1580643279682,"mc":[{"id":"1.168219388","rc":[{"batb":[[1,1.61,28.8],[2,1.01,0.51]],"batl":[[0,1.99,16.84],[1,2,42.01],[2,2,0]],"ltp":2.62,"tv":30.28,"id":16586500},{"batb":[[0,3.5,16.8],[1,3.3,18.18],[2,1.01,0.51]],"batl":[[0,4,13.44],[1,4.6,21.48],[2,4.6,0]],"ltp":3.65,"tv":17.69,"id":13508964},{"batb":[[0,4.7,15.11],[1,4.5,11.76],[2,1.01,0.51]],"batl":[[1,6.8,18.49],[2,6.8,0]],"ltp":5.1,"tv":6.72,"id":16586502}]}]}
{"op":"mcm","clk":"1005549406","pt":1580643281080,"mc":[{"id":"1.168219388","rc":[{"batb":[[0,1.61,28.8],[1,1.01,0.51],[2,1.01,0]],"batl":[[1,2,0]],"ltp":2.62,"tv":30.28,"id":16586500},{"batb":[[0,3.3,18.18],[1,1.01,0.51],[2,1.01,0]],"batl":[[0,4.6,21.48],[1,4.6,0]],"ltp":3.65,"tv":17.69,"id":13508964},{"batb":[[1,1.01,0.51],[2,1.01,0]],"batl":[[0,6.8,18.49],[1,6.8,0]],"ltp":5.1,"tv":6.72,"id":16586502}]}]}
{"op":"mcm","clk":"1005549717","pt":1580643282682,"mc":[{"id":"1.168219388","rc":[{"batb":[[0,1.62,28.17],[1,1.61,28.8],[2,1.01,0.51]],"batl":[[1,2.02,16.44]],"ltp":2.62,"tv":30.28,"id":16586500},{"batb":[[1,3.25,18.57],[2,1.01,0.51]],"batl":[[0,4.5,21.95],[1,4.6,21.48]],"ltp":3.65,"tv":17.69,"id":13508964}]}]}
{"op":"mcm","clk":"1005549779","pt":1580643283000,"mc":[{"id":"1.168219388","rc":[{"batb":[[1,1.01,0.51],[2,1.01,0]],"batl":[[0,2.02,16.44],[1,2.02,0]],"ltp":2.62,"tv":30.28,"id":16586500},{"batb":[[0,3.25,18.57],[1,1.01,0.51],[2,1.01,0]],"batl":[[1,4.6,0]],"ltp":3.65,"tv":17.69,"id":13508964}]}]}
{"op":"mcm","clk":"1005550317","pt":1580643285672,"mc":[{"id":"1.168219388","rc":[{"batb":[[0,3.7,34.46],[1,3.65,34.75],[2,3.25,18.57]],"ltp":3.65,"tv":17.69,"id":13508964},{"batb":[[0,5.1,45.6],[1,5,35.07],[2,4.7,15.11]],"ltp":5.1,"tv":6.72,"id":16586502}]}]}
{"op":"mcm","clk":"1005550922","pt":1580643288872,"mc":[{"id":"1.168219388","rc":[{"batb":[[0,1.78,69.23],[1,1.76,107.58],[2,1.62,28.17]],"ltp":2.62,"tv":30.28,"id":16586500}]}]}
{"op":"mcm","clk":"1005551594","pt":1580643292505,"mc":[{"id":"1.168219388","rc":[{"batb":[[0,1.62,28.17],[1,1.01,0.51],[2,1.62,0]],"ltp":2.62,"tv":30.28,"id":16586500},{"batb":[[0,3.25,18.57],[1,1.01,0.51],[2,3.25,0]],"ltp":3.65,"tv":17.69,"id":13508964},{"batb":[[0,4.7,15.11],[1,1.01,0.51],[2,4.7,0]],"ltp":5.1,"tv":6.72,"id":16586502}]}]}
{"op":"mcm","clk":"1005552226","pt":1580643295707,"mc":[{"id":"1.168219388","rc":[{"batb":[[0,1.65,110.02],[1,1.64,69.11],[2,1.62,28.17]],"ltp":2.62,"tv":30.28,"id":16586500}]}]}
{"op":"mcm","clk":"1005552410","pt":1580643296571,"mc":[{"id":"1.168219388","rc":[{"batb":[[0,1.68,61.33],[1,1.65,110.02],[2,1.64,69.11]],"batl":[[0,1.71,27.54],[1,1.84,63.49],[2,2.02,16.44]],"ltp":2.62,"tv":30.28,"id":16586500},{"batb":[[0,4.1,26.92],[1,4,55.23],[2,3.95,23.21]],"batl":[[0,4.5,33.71],[1,5.4,14.95]],"ltp":3.65,"tv":17.69,"id":13508964},{"batb":[[0,5.7,22.44],[1,5.6,47.8],[2,5.2,12.51]],"batl":[[0,5.9,8.4],[1,6.8,18.49],[2,8.2,12.75]],"ltp":5.1,"tv":6.72,"id":16586502}]}]}
{"op":"mcm","clk":"1005552599","pt":1580643297588,"mc":[{"id":"1.168219388","rc":[{"batl":[[2,2.02,0]],"ltp":2.62,"tv":30.28,"id":16586500}]}]}
{"op":"mcm","clk":"1005556029","pt":1580643315215,"mc":[{"id":"1.168219388","rc":[{"batb":[[0,1.47,41.23],[1,1.01,0.51],[2,1.64,0]],"batl":[[0,1.84,21.48],[1,1.84,0]],"ltp":2.62,"tv":30.28,"id":16586500},{"batb":[[0,3.6,14.48],[1,1.01,0.51],[2,3.95,0]],"batl":[[0,5.4,14.95],[1,5.4,0]],"ltp":3.65,"tv":17.69,"id":13508964},{"batb":[[0,5.2,12.51],[1,1.01,0.51],[2,5.2,0]],"batl":[[0,8.2,12.75],[1,6.8,0],[2,8.2,0]],"ltp":5.1,"tv":6.72,"id":16586502}]}]}
{"op":"mcm","clk":"1005556765","pt":1580643318724,"mc":[{"id":"1.168219388","rc":[{"batb":[[0,1.49,82.37],[1,1.48,102.03],[2,1.47,41.23]],"ltp":2.62,"tv":30.28,"id":16586500},{"batb":[[0,3.7,35.83],[1,3.65,49.22],[2,1.01,0.51]],"ltp":3.65,"tv":17.69,"id":13508964},{"batb":[[1,5.1,43.88],[2,5,35.18]],"ltp":5.1,"tv":6.72,"id":16586502}]}]}
{"op":"mcm","clk":"1005557476","pt":1580643322348,"mc":[{"id":"1.168219388","rc":[{"batb":[[0,1.47,41.23],[1,1.01,0.51],[2,1.47,0]],"ltp":2.62,"tv":30.28,"id":16586500},{"batb":[[0,3.65,14.48],[1,1.01,0.51],[2,1.01,0]],"ltp":3.65,"tv":17.69,"id":13508964},{"batb":[[1,1.01,0.51],[2,5,0]],"ltp":5.1,"tv":6.72,"id":16586502}]}]}
{"op":"mcm","clk":"1005558144","pt":1580643325443,"mc":[{"id":"1.168219388","rc":[{"batb":[[0,1.49,82.37],[1,1.48,102.03],[2,1.47,41.23]],"ltp":2.62,"tv":30.28,"id":16586500},{"batb":[[0,4.9,27.38],[1,4.8,36.15],[2,3.65,14.48]],"ltp":3.65,"tv":17.69,"id":13508964},{"batb":[[0,6.8,24.57],[1,6.6,37.81],[2,5.2,12.51]],"ltp":5.1,"tv":6.72,"id":16586502}]}]}
{"op":"mcm","clk":"1005558435","pt":1580643326730,"mc":[{"id":"1.168219388","rc":[{"batb":[[0,1.53,78.98],[1,1.49,82.37],[2,1.48,102.03]],"batl":[[0,1.54,40.21],[1,1.66,30.69]],"ltp":2.62,"tv":30.28,"id":16586500},{"batb":[[2,4.7,15.58]],"batl":[[0,5.2,9.24],[1,5.4,14.95],[2,6.8,18.18]],"ltp":3.65,"tv":17.69,"id":13508964},{"batb":[[1,6.6,51.34],[2,5.9,18.25]],"batl":[[0,7,6.72],[1,8.2,12.75],[2,10.5,7.95]],"ltp":5.1,"tv":6.72,"id":16586502}]}]}
{"op":"mcm","clk":"1005558883","pt":1580643328742,"mc":[{"id":"1.168219388","rc":[{"batl":[[1,1.64,42.01],[2,1.66,30.69]],"ltp":2.62,"tv":30.28,"id":16586500}]}]}
{"op":"mcm","clk":"1005560793","pt":1580643337547,"mc":[{"id":"1.168219388","rc":[{"batb":[[1,1.34,62.39],[2,1.01,0.51]],"batl":[[0,1.64,42.01],[1,1.66,30.69],[2,1.66,0]],"ltp":2.62,"tv":30.28,"id":16586500},{"batb":[[0,4.4,11.76],[1,4.1,20.77],[2,1.01,0.51]],"batl":[[1,6.8,18.18],[2,6.8,0]],"ltp":3.65,"tv":17.69,"id":13508964},{"batb":[[0,5.9,18.25],[1,5.7,8.4],[2,1.01,0.51]],"batl":[[1,10.5,7.95],[2,10.5,0]],"ltp":5.1,"tv":6.72,"id":16586502}]}]}
{"op":"mcm","clk":"1005561080","pt":1580643339143,"mc":[{"id":"1.168219388","rc":[{"batb":[[0,1.34,62.39],[1,1.01,0.51],[2,1.01,0]],"batl":[[0,1.66,30.69],[1,1.66,0]],"ltp":2.62,"tv":30.28,"id":16586500},{"batb":[[0,4.1,20.77],[1,1.01,0.51],[2,1.01,0]],"batl":[[0,6.8,18.18],[1,6.8,0]],"ltp":3.65,"tv":17.69,"id":13508964},{"batb":[[1,1.01,0.51],[2,1.01,0]],"batl":[[0,10.5,7.95],[1,10.5,0]],"ltp":5.1,"tv":6.72,"id":16586502}]}]}
{"op":"mcm","clk":"1005561236","pt":1580643340049,"mc":[{"id":"1.168219388","rc":[{"batb":[[0,1.35,83.68],[1,1.34,221.45],[2,1.01,0.51]],"ltp":2.62,"tv":30.28,"id":16586500},{"batb":[[0,4.3,34.88],[1,4.2,49.06],[2,4.1,20.77]],"ltp":3.65,"tv":17.69,"id":13508964},{"batb":[[0,6,19.38],[1,5.9,42.85],[2,1.01,0.51]],"ltp":5.1,"tv":6.72,"id":16586502}]}]}
{"op":"mcm","clk":"1005561499","pt":1580643341241,"mc":[{"id":"1.168219388","rc":[{"batb":[[0,1.34,62.39],[1,1.01,0.51],[2,1.01,0]],"ltp":2.62,"tv":30.28,"id":16586500},{"batb":[[0,4.1,20.77],[1,1.01,0.51],[2,4.1,0]],"ltp":3.65,"tv":17.69,"id":13508964},{"batb":[[0,5.9,18.25],[1,1.01,0.51],[2,1.01,0]],"ltp":5.1,"tv":6.72,"id":16586502}]}]}
{"op":"mcm","clk":"1005562853","pt":1580643347734,"mc":[{"id":"1.168219388","rc":[{"batb":[[0,1.35,83.68],[1,1.34,221.45],[2,1.01,0.51]],"ltp":2.62,"tv":30.28,"id":16586500},{"batb":[[0,4.3,34.88],[1,4.2,49.06],[2,4.1,20.77]],"ltp":3.65,"tv":17.69,"id":13508964},{"batb":[[0,6,19.38],[1,5.9,42.85],[2,1.01,0.51]],"ltp":5.1,"tv":6.72,"id":16586502}]}]}
{"op":"mcm","clk":"1005566332","pt":1580643365472,"mc":[{"id":"1.168219388","rc":[{"batb":[[0,1.34,62.39],[1,1.01,0.51],[2,1.01,0]],"ltp":2.62,"tv":30.28,"id":16586500}]}]}
{"op":"mcm","clk":"1005567052","pt":1580643368508,"mc":[{"id":"1.168219388","rc":[{"batb":[[0,1.6,92.18],[1,1.59,77.21],[2,1.34,62.39]],"ltp":2.62,"tv":30.28,"id":16586500}]}]}
{"op":"mcm","clk":"1005567206","pt":1580643369204,"mc":[{"id":"1.168219388","rc":[{"batb":[[2,1.57,31.32]],"batl":[[1,1.82,22.42]],"ltp":2.62,"tv":30.28,"id":16586500},{"batl":[[0,4.8,19.75],[1,6,11.88]],"ltp":3.65,"tv":17.69,"id":13508964},{"batb":[[2,5.3,11.96]],"batl":[[0,7.2,17.07],[1,9.2,10.15]],"ltp":5.1,"tv":6.72,"id":16586502}]}]}
{"op":"mcm","clk":"1005567364","pt":1580643370013,"mc":[{"id":"1.168219388","rc":[{"batb":[[0,1.62,67.22],[1,1.6,92.18],[2,1.59,77.21]],"batl":[[1,1.75,42.01],[2,1.82,22.42]],"ltp":2.62,"tv":30.28,"id":16586500},{"batl":[[0,4.8,30.67]],"ltp":3.65,"tv":17.69,"id":13508964},{"batl":[[0,6.2,7.56],[1,7.2,17.07],[2,9.2,10.15]],"ltp":5.1,"tv":6.72,"id":16586502}]}]}
{"op":"mcm","clk":"1005570416","pt":1580643385588,"mc":[{"id":"1.168219388","rc":[{"batb":[[1,1.4,50.67],[2,1.01,0.51]],"batl":[[0,1.75,42.01],[1,1.82,22.42],[2,1.82,0]],"ltp":2.62,"tv":30.28,"id":16586500},{"batb":[[0,4,13.44],[1,3.7,14.01],[2,1.01,0.51]],"batl":[[0,4.8,10.92]],"ltp":3.65,"tv":17.69,"id":13508964},{"batb":[[0,5.3,11.96],[1,5.2,9.24],[2,1.01,0.51]],"batl":[[1,9.2,10.15],[2,9.2,0]],"ltp":5.1,"tv":6.72,"id":16586502}]}]}
{"op":"mcm","clk":"1005570766","pt":1580643387300,"mc":[{"id":"1.168219388","rc":[{"batb":[[0,1.4,50.67],[1,1.01,0.51],[2,1.01,0]],"batl":[[0,1.82,22.42],[1,1.82,0]],"ltp":2.62,"tv":30.28,"id":16586500},{"batb":[[0,3.7,14.01],[1,1.01,0.51],[2,1.01,0]],"batl":[[0,6,11.88],[1,6,0]],"ltp":3.65,"tv":17.69,"id":13508964},{"batb":[[1,1.01,0.51],[2,1.01,0]],"batl":[[0,9.2,10.15],[1,9.2,0]],"ltp":5.1,"tv":6.72,"id":16586502}]}]}
{"op":"mcm","clk":"1005571016","pt":1580643388608,"mc":[{"id":"1.168219388","rc":[{"batb":[[0,1.01,0.51],[1,1.01,0]],"ltp":11.5,"tv":351.14,"id":13508961}]}]}
{"op":"mcm","clk":"1005571584","pt":1580643391681,"mc":[{"id":"1.168219388","rc":[{"batb":[[0,1.75,90.36],[1,1.73,113.97],[2,1.72,22.9]],"batl":[[1,2.02,16.21]],"ltp":2.62,"tv":30.28,"id":16586500},{"batb":[[0,3.75,56.04],[1,3.7,47.37],[2,3.3,18.41]],"batl":[[0,4.1,13.53],[1,5.1,16.68],[2,6,11.88]],"ltp":3.65,"tv":17.69,"id":13508964},{"batb":[[1,5.2,41.01],[2,5.1,33.66]],"batl":[[0,6.2,11.49],[1,7.8,14.4],[2,9.2,10.15]],"ltp":5.1,"tv":6.72,"id":16586502}]}]}
{"op":"mcm","clk":"1005571748","pt":1580643392385,"mc":[{"id":"1.168219388","rc":[{"batb":[[1,1.74,56.29],[2,1.73,113.97]],"batl":[[1,1.9,42.01],[2,2.02,16.21]],"ltp":2.62,"tv":30.28,"id":16586500},{"batb":[[1,3.7,62.49]],"batl":[[1,4.3,12.6],[2,5.1,16.68]],"ltp":3.65,"tv":17.69,"id":13508964},{"batl":[[0,5.5,9.24],[1,6.2,11.49],[2,7.8,14.4]],"ltp":5.1,"tv":6.72,"id":16586502}]}]}
{"op":"mcm","clk":"1005573855","pt":1580643402505,"mc":[{"id":"1.168219388","rc":[{"batb":[[0,1.74,56.29],[1,1.72,22.9],[2,1.51,36.98]],"ltp":2.62,"tv":30.28,"id":16586500},{"batb":[[0,3.7,29.13],[1,3.3,18.41],[2,1.01,0.51]],"ltp":3.65,"tv":17.69,"id":13508964},{"batb":[[1,4.6,26.82],[2,1.01,0.51]],"ltp":5.1,"tv":6.72,"id":16586502}]}]}
{"op":"mcm","clk":"1005573946","pt":1580643403030,"mc":[{"id":"1.168219388","rc":[{"batb":[[0,1.51,36.98],[1,1.01,0.51],[2,1.51,0]],"batl":[[0,2.02,16.21],[1,1.9,0],[2,2.02,0]],"ltp":2.62,"tv":30.28,"id":16586500},{"batb":[[0,3.3,18.41],[1,1.01,0.51],[2,1.01,0]],"batl":[[0,5.1,16.68],[1,4.3,0],[2,5.1,0]],"ltp":3.65,"tv":17.69,"id":13508964},{"batb":[[0,4.6,15.89],[1,1.01,0.51],[2,1.01,0]],"batl":[[0,7.8,14.4],[1,6.2,0],[2,7.8,0]],"ltp":5.1,"tv":6.72,"id":16586502}]}]}
{"op":"mcm","clk":"1005574472","pt":1580643405731,"mc":[{"id":"1.168219388","rc":[{"batb":[[0,1.52,125.62],[1,1.51,131.29],[2,1.01,0.51]],"ltp":2.62,"tv":30.28,"id":16586500},{"batb":[[0,3.35,58.79],[1,3.3,62.58],[2,1.01,0.51]],"ltp":3.65,"tv":17.69,"id":13508964},{"batb":[[0,4.6,74.36],[1,4.5,44.43],[2,1.01,0.51]],"ltp":5.1,"tv":6.72,"id":16586502}]}]}
{"op":"mcm","clk":"1005574907","pt":1580643407710,"mc":[{"id":"1.168219388","rc":[{"batb":[[0,1.51,36.98],[1,1.01,0.51],[2,1.01,0]],"ltp":2.62,"tv":30.28,"id":16586500}]}]}
{"op":"mcm","clk":"1005575585","pt":1580643410687,"mc":[{"id":"1.168219388","rc":[{"batb":[[0,1.94,56.93],[1,1.92,81.4],[2,1.51,36.98]],"ltp":2.62,"tv":30.28,"id":16586500}]}]}
{"op":"mcm","clk":"1005575746","pt":1580643411646,"mc":[{"id":"1.168219388","rc":[{"batb":[[2,1.91,16.52]],"batl":[[1,2.18,26.04]],"ltp":2.62,"tv":30.28,"id":16586500},{"batb":[[2,3.05,21.87]],"batl":[[0,3.65,17.78],[1,3.9,2.15],[2,4.2,13.38]],"ltp":3.65,"tv":17.69,"id":13508964},{"batb":[[2,4.3,18.73]],"batl":[[0,5.4,15.19],[1,6.2,11.33]],"ltp":5.1,"tv":6.72,"id":16586502}]}]}
{"op":"mcm","clk":"1005575831","pt":1580643412028,"mc":[{"id":"1.168219388","rc":[{"batl":[[1,2.08,38.65],[2,2.18,26.04]],"ltp":2.62,"tv":30.28,"id":16586500},{"batb":[[0,3.35,76.43]],"batl":[[1,3.9,14.28]],"ltp":3.65,"tv":17.69,"id":13508964},{"batl":[[0,4.9,10.08],[1,5.4,15.19],[2,6.2,11.33]],"ltp":5.1,"tv":6.72,"id":16586502}]}]}
{"op":"mcm","clk":"1005578089","pt":1580643423644,"mc":[{"id":"1.168219388","rc":[{"batb":[[0,17,15.12],[1,1.01,0.51]],"ltp":11.5,"tv":351.14,"id":13508961}]}]}
{"op":"mcm","clk":"1005578330","pt":1580643424709,"mc":[{"id":"1.168219388","rc":[{"batb":[[0,1.89,47.05],[1,1.71,23.21],[2,1.01,0.51]],"batl":[[0,2.08,38.65],[1,2.18,26.04],[2,2.18,0]],"ltp":2.62,"tv":30.28,"id":16586500},{"batb":[[0,3.35,17.64],[1,3.05,21.87],[2,1.01,0.51]],"batl":[[0,3.9,14.28],[1,4.2,13.38],[2,4.2,0]],"ltp":3.65,"tv":17.69,"id":13508964},{"batb":[[0,4.3,18.73],[1,4.2,12.6],[2,1.01,0.51]],"batl":[[1,6.2,11.33],[2,6.2,0]],"ltp":5.1,"tv":6.72,"id":16586502}]}]}
{"op":"mcm","clk":"1005578423","pt":1580643425113,"mc":[{"id":"1.168219388","rc":[{"batb":[[0,1.71,23.21],[1,1.01,0.51],[2,1.01,0]],"batl":[[0,2.18,26.04],[1,2.18,0]],"ltp":2.62,"tv":30.28,"id":16586500},{"batb":[[0,3.05,21.87],[1,1.01,0.51],[2,1.01,0]],"batl":[[0,4.2,13.38],[1,4.2,0]],"ltp":3.65,"tv":17.69,"id":13508964},{"batb":[[1,1.01,0.51],[2,1.01,0]],"batl":[[0,6.2,11.33],[1,6.2,0]],"ltp":5.1,"tv":6.72,"id":16586502}]}]}
{"op":"mcm","clk":"1005578830","pt":1580643427120,"mc":[{"id":"1.168219388","rc":[{"batb":[[0,1.74,87.93],[1,1.72,116.23],[2,1.71,23.21]],"ltp":2.62,"tv":30.28,"id":16586500},{"batb":[[0,3.15,35.61],[1,3.1,51.92],[2,3.05,21.87]],"ltp":3.65,"tv":17.69,"id":13508964},{"batb":[[0,4.3,79.78],[1,4.2,52.04],[2,1.01,0.51]],"ltp":5.1,"tv":6.72,"id":16586502}]}]}
{"op":"mcm","clk":"1005579335","pt":1580643429608,"mc":[{"id":"1.168219388","rc":[{"batb":[[0,3.05,21.87],[1,1.01,0.51],[2,3.05,0]],"ltp":3.65,"tv":17.69,"id":13508964},{"batb":[[0,4.3,18.73],[1,1.01,0.51],[2,1.01,0]],"ltp":5.1,"tv":6.72,"id":16586502}]}]}
{"op":"mcm","clk":"1005579946","pt":1580643432501,"mc":[{"id":"1.168219388","rc":[{"batb":[[0,3.8,48.1],[1,3.75,32.37],[2,3.05,21.87]],"ltp":3.65,"tv":17.69,"id":13508964},{"batb":[[0,5.2,48.58],[1,5.1,33.55],[2,4.3,18.73]],"ltp":5.1,"tv":6.72,"id":16586502}]}]}
{"op":"mcm","clk":"1005580152","pt":1580643433712,"mc":[{"id":"1.168219388","rc":[{"batl":[[0,1.81,22.74],[1,2.02,16.52]],"ltp":2.62,"tv":30.28,"id":16586500},{"batb":[[2,3.7,13.85]],"batl":[[1,5.2,16.6]],"ltp":3.65,"tv":17.69,"id":13508964},{"batb":[[0,5.3,11.8],[1,5.2,48.58],[2,5.1,33.55]],"batl":[[1,7.8,14.08]],"ltp":5.1,"tv":6.72,"id":16586502}]}]}
{"op":"mcm","clk":"1005580318","pt":1580643434518,"mc":[{"id":"1.168219388","rc":[{"batb":[[0,1.74,144.22]],"batl":[[1,1.91,42.01],[2,2.02,16.52]],"ltp":2.62,"tv":30.28,"id":16586500},{"batb":[[2,3.7,28.97]],"batl":[[1,4.3,12.6],[2,5.2,16.6]],"ltp":3.65,"tv":17.69,"id":13508964},{"batl":[[0,5.5,9.24],[1,6.2,11.33],[2,7.8,14.08]],"ltp":5.1,"tv":6.72,"id":16586502}]}]}
{"op":"mcm","clk":"1005582312","pt":1580643443603,"mc":[{"id":"1.168219388","rc":[{"batb":[[0,1.74,56.29],[1,1.5,37.45],[2,1.01,0.51]],"batl":[[0,1.91,42.01],[1,2.02,16.52],[2,2.02,0]],"ltp":2.62,"tv":30.28,"id":16586500},{"batb":[[0,3.7,15.12],[1,3.3,18.02],[2,1.01,0.51]],"batl":[[0,4.3,12.6],[1,5.2,16.6],[2,5.2,0]],"ltp":3.65,"tv":17.69,"id":13508964},{"batb":[[0,4.6,26.82],[1,1.01,0.51],[2,5.1,0]],"batl":[[1,7.8,14.08],[2,7.8,0]],"ltp":5.1,"tv":6.72,"id":16586502}]}]}
{"op":"mcm","clk":"1005582629","pt":1580643445215,"mc":[{"id":"1.168219388","rc":[{"batb":[[0,1.5,37.45],[1,1.01,0.51],[2,1.01,0]],"batl":[[0,2.02,16.52],[1,2.02,0]],"ltp":2.62,"tv":30.28,"id":16586500},{"batb":[[0,3.3,18.02],[1,1.01,0.51],[2,1.01,0]],"batl":[[0,5.2,16.6],[1,5.2,0]],"ltp":3.65,"tv":17.69,"id":13508964},{"batb":[[0,4.6,15.89]],"batl":[[0,7.8,14.08],[1,7.8,0]],"ltp":5.1,"tv":6.72,"id":16586502}]}]}
{"op":"mcm","clk":"1005582790","pt":1580643446022,"mc":[{"id":"1.168219388","rc":[{"batb":[[0,1.51,152.77],[1,1.5,134.48],[2,1.01,0.51]],"ltp":2.62,"tv":30.28,"id":16586500},{"batb":[[0,3.4,41.26],[1,3.35,42.72],[2,3.3,18.02]],"ltp":3.65,"tv":17.69,"id":13508964},{"batb":[[0,4.6,80.32],[1,4.5,44.34],[2,1.01,0.51]],"ltp":5.1,"tv":6.72,"id":16586502}]}]}
{"op":"mcm","clk":"1005585258","pt":1580643458571,"mc":[{"id":"1.168219388","rc":[{"batb":[[0,1.5,37.45],[1,1.01,0.51],[2,1.01,0]],"ltp":2.62,"tv":30.28,"id":16586500}]}]}
{"op":"mcm","clk":"1005585908","pt":1580643461653,"mc":[{"id":"1.168219388","rc":[{"batb":[[0,1.92,89.93],[1,1.9,84.13],[2,1.5,37.45]],"ltp":2.62,"tv":30.28,"id":16586500}]}]}
{"op":"mcm","clk":"1005585986","pt":1580643462080,"mc":[{"id":"1.168219388","rc":[{"batb":[[1,1.9,100.89],[2,1.88,47.05]],"batl":[[1,2.08,38.65],[2,2.16,26.59]],"ltp":2.62,"tv":30.28,"id":16586500},{"batb":[[0,3.4,58.06]],"batl":[[0,3.7,17.39],[1,3.95,13.44],[2,4.2,13.06]],"ltp":3.65,"tv":17.69,"id":13508964},{"batb":[[2,4.3,18.49]],"batl":[[0,4.9,10.08],[1,5.4,15.19],[2,6.2,11.41]],"ltp":5.1,"tv":6.72,"id":16586502}]}]}
{"op":"mcm","clk":"1005588667","pt":1580643475497,"mc":[{"id":"1.168219388","rc":[{"batb":[[0,1.88,47.05],[1,1.71,23.6],[2,1.01,0.51]],"batl":[[0,2.08,38.65],[1,2.16,26.59],[2,2.16,0]],"ltp":2.62,"tv":30.28,"id":16586500},{"batb":[[0,3.4,16.8],[1,3.1,21.48],[2,1.01,0.51]],"batl":[[0,3.95,13.44],[1,4.2,13.06],[2,4.2,0]],"ltp":3.65,"tv":17.69,"id":13508964},{"batb":[[0,4.3,18.49],[1,4.2,12.6],[2,1.01,0.51]],"batl":[[1,6.2,11.41],[2,6.2,0]],"ltp":5.1,"tv":6.72,"id":16586502}]}]}
{"op":"mcm","clk":"1005589015","pt":1580643477217,"mc":[{"id":"1.168219388","rc":[{"batb":[[0,1.71,23.6],[1,1.01,0.51],[2,1.01,0]],"batl":[[0,2.16,26.59],[1,2.16,0]],"ltp":2.62,"tv":30.28,"id":16586500},{"batb":[[0,3.1,21.48],[1,1.01,0.51],[2,1.01,0]],"batl":[[0,4.2,13.06],[1,4.2,0]],"ltp":3.65,"tv":17.69,"id":13508964},{"batb":[[1,1.01,0.51],[2,1.01,0]],"batl":[[0,6.2,11.41],[1,6.2,0]],"ltp":5.1,"tv":6.72,"id":16586502}]}]}
{"op":"mcm","clk":"1005589350","pt":1580643478686,"mc":[{"id":"1.168219388","rc":[{"batb":[[0,1.73,80.01],[1,1.71,118.56],[2,1.7,23.76]],"ltp":2.62,"tv":30.28,"id":16586500},{"batb":[[0,3.15,68.36],[1,3.1,72.91],[2,1.01,0.51]],"batl":[[0,4.2,12.9]],"ltp":3.65,"tv":17.69,"id":13508964},{"batb":[[0,4.3,81.2],[1,4.2,51.99],[2,1.01,0.51]],"ltp":5.1,"tv":6.72,"id":16586502}]}]}
{"op":"mcm","clk":"1005590332","pt":1580643483603,"mc":[{"id":"1.168219388","rc":[{"batb":[[0,3.1,21.24],[1,1.01,0.51],[2,1.01,0]],"ltp":3.65,"tv":17.69,"id":13508964},{"batb":[[0,4.3,18.49],[1,1.01,0.51],[2,1.01,0]],"ltp":5.1,"tv":6.72,"id":16586502}]}]}
{"op":"mcm","clk":"1005591032","pt":1580643486722,"mc":[{"id":"1.168219388","rc":[{"batb":[[0,3.85,46.25],[1,3.8,31.42],[2,3.1,21.24]],"ltp":3.65,"tv":17.69,"id":13508964},{"batb":[[0,5.3,21.58],[1,5.2,32.49],[2,4.3,18.49]],"ltp":5.1,"tv":6.72,"id":16586502}]}]}
{"op":"mcm","clk":"1005591189","pt":1580643487444,"mc":[{"id":"1.168219388","rc":[{"batl":[[0,1.8,23.29],[1,1.99,16.92]],"ltp":2.62,"tv":30.28,"id":16586500},{"batb":[[2,3.75,13.3]],"batl":[[1,5.3,15.66]],"ltp":3.65,"tv":17.69,"id":13508964},{"batb":[[0,5.3,33.46],[2,4.7,15.66]],"batl":[[1,7.8,14.08]],"ltp":5.1,"tv":6.72,"id":16586502}]}]}
{"op":"mcm","clk":"1005591472","pt":1580643488733,"mc":[{"id":"1.168219388","rc":[{"batb":[[0,1.73,137.14]],"batl":[[1,1.9,42.01],[2,1.99,16.92]],"ltp":2.62,"tv":30.28,"id":16586500},{"batl":[[1,4.4,11.76],[2,5.3,15.66]],"ltp":3.65,"tv":17.69,"id":13508964},{"batl":[[0,5.5,9.24],[1,6.2,11.41],[2,7.8,14.08]],"ltp":5.1,"tv":6.72,"id":16586502}]}]}
{"op":"mcm","clk":"1005594660","pt":1580643503155,"mc":[{"id":"1.168219388","rc":[{"batb":[[0,1.49,38.63],[1,1.01,0.51],[2,1.7,0]],"batl":[[0,1.99,16.92],[1,1.9,0],[2,1.99,0]],"ltp":2.62,"tv":30.28,"id":16586500},{"batb":[[0,3.35,17.62],[1,1.01,0.51],[2,3.75,0]],"batl":[[0,5.3,15.66],[1,4.4,0],[2,5.3,0]],"ltp":3.65,"tv":17.69,"id":13508964},{"batb":[[0,4.7,15.66],[1,1.01,0.51],[2,4.7,0]],"batl":[[0,7.8,14.08],[1,6.2,0],[2,7.8,0]],"ltp":5.1,"tv":6.72,"id":16586502}]}]}
{"op":"mcm","clk":"1005595259","pt":1580643505835,"mc":[{"id":"1.168219388","rc":[{"batb":[[0,1.51,77.88],[1,1.5,96.59],[2,1.49,38.63]],"ltp":2.62,"tv":30.28,"id":16586500},{"batb":[[0,3.45,31.12],[1,3.4,41.35],[2,3.35,17.62]],"ltp":3.65,"tv":17.69,"id":13508964},{"batb":[[0,4.7,40.73],[1,4.6,42.75],[2,1.01,0.51]],"ltp":5.1,"tv":6.72,"id":16586502}]}]}
{"op":"mcm","clk":"1005595648","pt":1580643507451,"mc":[{"id":"1.168219388","rc":[{"batb":[[0,1.49,38.63],[1,1.01,0.51],[2,1.49,0]],"ltp":2.62,"tv":30.28,"id":16586500},{"batb":[[0,3.35,17.62],[1,1.01,0.51],[2,3.35,0]],"ltp":3.65,"tv":17.69,"id":13508964},{"batb":[[0,4.7,15.66],[1,1.01,0.51],[2,1.01,0]],"ltp":5.1,"tv":6.72,"id":16586502}]}]}
{"op":"mcm","clk":"1005596832","pt":1580643512956,"mc":[{"id":"1.168219388","rc":[{"batb":[[0,1.51,77.88],[1,1.5,96.59],[2,1.49,38.63]],"ltp":2.62,"tv":30.28,"id":16586500},{"batb":[[0,3.45,31.12],[1,3.4,41.35],[2,3.35,17.62]],"ltp":3.65,"tv":17.69,"id":13508964},{"batb":[[0,4.7,40.73],[1,4.6,42.75],[2,1.01,0.51]],"ltp":5.1,"tv":6.72,"id":16586502}]}]}
{"op":"mcm","clk":"1005597637","pt":1580643516788,"mc":[{"id":"1.168219388","rc":[{"batb":[[0,3.35,17.62],[1,1.01,0.51],[2,3.35,0]],"ltp":3.65,"tv":17.69,"id":13508964},{"batb":[[0,4.7,15.66],[1,1.01,0.51],[2,1.01,0]],"ltp":5.1,"tv":6.72,"id":16586502}]}]}
{"op":"mcm","clk":"1005598484","pt":1580643520607,"mc":[{"id":"1.168219388","rc":[{"batb":[[0,1.53,78.98],[1,1.51,77.88],[2,1.5,96.59]],"batl":[[0,1.57,37.69],[1,1.66,42.01],[2,1.79,23.68]],"ltp":2.62,"tv":30.28,"id":16586500},{"batb":[[0,4.8,29.29],[1,4.7,37.9],[2,4.6,16.44]],"batl":[[0,5.3,24.9],[1,8,13.3]],"ltp":3.65,"tv":17.69,"id":13508964},{"batb":[[0,6.6,20.41],[1,6.4,55.43],[2,5.5,9.24]],"batl":[[0,6.8,6.72],[1,7.8,14.08],[2,12.5,14.08]],"ltp":5.1,"tv":6.72,"id":16586502}]}]}
{"op":"mcm","clk":"1005600556","pt":1580643529708,"mc":[{"id":"1.168219388","rc":[{"batb":[[1,1.27,80.18],[2,1.01,0.51]],"batl":[[0,1.66,42.01],[1,1.79,23.68],[2,1.79,0]],"ltp":2.62,"tv":30.28,"id":16586500},{"batb":[[0,4.4,11.76],[1,3.75,13.22],[2,1.01,0.51]],"batl":[[0,5.3,9.24]],"ltp":3.65,"tv":17.69,"id":13508964},{"batb":[[0,5.5,9.24],[1,5.3,11.72],[2,1.01,0.51]],"batl":[[1,12.5,14.08],[2,12.5,0]],"ltp":5.1,"tv":6.72,"id":16586502}]}]}
{"op":"mcm","clk":"1005600840","pt":1580643531106,"mc":[{"id":"1.168219388","rc":[{"batb":[[0,1.27,80.18],[1,1.01,0.51],[2,1.01,0]],"batl":[[0,1.79,23.68],[1,1.79,0]],"ltp":2.62,"tv":30.28,"id":16586500},{"batb":[[0,3.75,13.22],[1,1.01,0.51],[2,1.01,0]],"batl":[[0,8,13.3],[1,8,0]],"ltp":3.65,"tv":17.69,"id":13508964},{"batb":[[0,5.3,11.72],[1,1.01,0.51],[2,1.01,0]],"batl":[[0,12.5,14.08],[1,12.5,0]],"ltp":5.1,"tv":6.72,"id":16586502}]}]}
{"op":"mcm","clk":"1005601401","pt":1580643533703,"mc":[{"id":"1.168219388","rc":[{"batb":[[0,1.45,142.49],[1,1.44,114.91],[2,1.27,80.18]],"ltp":2.62,"tv":30.28,"id":16586500},{"batb":[[0,5.1,47.49],[1,5,32.6],[2,3.75,13.22]],"ltp":3.65,"tv":17.69,"id":13508964},{"batb":[[0,7,40.81],[1,6.8,34.98],[2,5.3,11.72]],"ltp":5.1,"tv":6.72,"id":16586502}]}]}
{"op":"mcm","clk":"1005601954","pt":1580643536110,"mc":[{"id":"1.168219388","rc":[{"batb":[[0,1.27,80.18],[1,1.01,0.51],[2,1.27,0]],"ltp":2.62,"tv":30.28,"id":16586500},{"batb":[[0,3.75,13.22],[1,1.01,0.51],[2,3.75,0]],"ltp":3.65,"tv":17.69,"id":13508964},{"batb":[[0,5.3,11.72],[1,1.01,0.51],[2,5.3,0]],"ltp":5.1,"tv":6.72,"id":16586502}]}]}
{"op":"mcm","clk":"1005602547","pt":1580643539101,"mc":[{"id":"1.168219388","rc":[{"batb":[[0,1.27,209.15],[1,1.26,222.25],[2,1.01,0.51]],"ltp":2.62,"tv":30.28,"id":16586500},{"batb":[[0,3.9,35.8],[1,3.85,30.55],[2,3.75,13.22]],"ltp":3.65,"tv":17.69,"id":13508964},{"batb":[[0,5.3,39.82],[1,5.2,32.4],[2,1.01,0.51]],"ltp":5.1,"tv":6.72,"id":16586502}]}]}
{"op":"mcm","clk":"1005603921","pt":1580643545703,"mc":[{"id":"1.168219388","rc":[{"batb":[[0,1.27,80.18],[1,1.01,0.51],[2,1.01,0]],"ltp":2.62,"tv":30.28,"id":16586500}]}]}
{"op":"mcm","clk":"1005604571","pt":1580643548714,"mc":[{"id":"1.168219388","rc":[{"batb":[[0,1.72,88.68],[1,1.7,121.02],[2,1.27,80.18]],"ltp":2.62,"tv":30.28,"id":16586500}]}]}
{"op":"mcm","clk":"1005604728","pt":1580643549505,"mc":[{"id":"1.168219388","rc":[{"batb":[[2,1.69,24.16]],"batl":[[1,1.97,17.31]],"ltp":2.62,"tv":30.28,"id":16586500},{"batl":[[0,4.3,24.86],[1,5.3,15.66]],"ltp":3.65,"tv":17.69,"id":13508964},{"batb":[[2,4.7,15.58]],"batl":[[0,6.2,11.25],[1,7.8,14.01]],"ltp":5.1,"tv":6.72,"id":16586502}]}]}
{"op":"mcm","clk":"1005604851","pt":1580643550134,"mc":[{"id":"1.168219388","rc":[{"batb":[[0,1.72,146.65]],"batl":[[1,1.87,42.01],[2,1.97,17.31]],"ltp":2.62,"tv":30.28,"id":16586500},{"batb":[[2,3.8,14.28]],"batl":[[1,4.4,11.76],[2,5.3,15.66]],"ltp":3.65,"tv":17.69,"id":13508964},{"batl":[[0,5.5,9.24],[1,6.2,11.25],[2,7.8,14.01]],"ltp":5.1,"tv":6.72,"id":16586502}]}]}
{"op":"mcm","clk":"1005609510","pt":1580643572656,"mc":[{"id":"1.168219388","rc":[{"batb":[[0,1.72,57.97],[1,1.49,38.71],[2,1.01,0.51]],"batl":[[0,1.87,42.01],[1,1.97,17.31],[2,1.97,0]],"ltp":2.62,"tv":30.28,"id":16586500},{"batb":[[0,3.8,14.28],[1,3.4,17.07],[2,1.01,0.51]],"batl":[[0,4.4,11.76],[1,5.3,15.66],[2,5.3,0]],"ltp":3.65,"tv":17.69,"id":13508964},{"batb":[[0,4.7,15.58],[1,4.6,10.92],[2,1.01,0.51]],"batl":[[1,7.8,14.01],[2,7.8,0]],"ltp":5.1,"tv":6.72,"id":16586502}]}]}
{"op":"mcm","clk":"1005609707","pt":1580643573562,"mc":[{"id":"1.168219388","rc":[{"batb":[[0,1.49,38.71],[1,1.01,0.51],[2,1.01,0]],"batl":[[0,1.97,17.31],[1,1.97,0]],"ltp":2.62,"tv":30.28,"id":16586500},{"batb":[[0,3.4,17.07],[1,1.01,0.51],[2,1.01,0]],"batl":[[0,5.3,15.66],[1,5.3,0]],"ltp":3.65,"tv":17.69,"id":13508964},{"batb":[[1,1.01,0.51],[2,1.01,0]],"batl":[[0,7.8,14.01],[1,7.8,0]],"ltp":5.1,"tv":6.72,"id":16586502}]}]}
{"op":"mcm","clk":"1005610048","pt":1580643575266,"mc":[{"id":"1.168219388","rc":[{"batb":[[0,1.5,117.47],[1,1.49,138.22],[2,1.01,0.51]],"ltp":2.62,"tv":30.28,"id":16586500},{"batb":[[0,3.45,52.37],[1,3.4,58.21],[2,1.01,0.51]],"ltp":3.65,"tv":17.69,"id":13508964},{"batb":[[0,4.7,45.89],[1,4.6,42.67],[2,1.01,0.51]],"ltp":5.1,"tv":6.72,"id":16586502}]}]}
{"op":"mcm","clk":"1005610469","pt":1580643577386,"mc":[{"id":"1.168219388","rc":[{"batb":[[0,3.4,17.07],[1,1.01,0.51],[2,1.01,0]],"ltp":3.65,"tv":17.69,"id":13508964},{"batb":[[0,4.7,15.58],[1,1.01,0.51],[2,1.01,0]],"ltp":5.1,"tv":6.72,"id":16586502}]}]}
{"op":"mcm","clk":"1005611135","pt":1580643580594,"mc":[{"id":"1.168219388","rc":[{"batb":[[0,4.8,46.2],[1,4.7,37.61],[2,3.4,17.07]],"ltp":3.65,"tv":17.69,"id":13508964},{"batb":[[0,6.6,26.77],[1,6.4,40.31],[2,4.7,15.58]],"ltp":5.1,"tv":6.72,"id":16586502}]}]}
{"op":"mcm","clk":"1005611253","pt":1580643581081,"mc":[{"id":"1.168219388","rc":[{"batb":[[2,1.27,80.1]],"batl":[[0,1.57,37.77],[1,1.78,23.92]],"ltp":2.62,"tv":30.28,"id":16586500},{"batb":[[2,4.6,16.37]],"batl":[[1,8,13.38]],"ltp":3.65,"tv":17.69,"id":13508964},{"batb":[[1,6.4,55.26],[2,5.3,11.72]],"batl":[[1,12.5,14.01]],"ltp":5.1,"tv":6.72,"id":16586502}]}]}
{"op":"mcm","clk":"1005611482","pt":1580643582209,"mc":[{"id":"1.168219388","rc":[{"batb":[[0,1.53,78.98],[1,1.5,117.47],[2,1.49,138.22]],"batl":[[1,1.65,42.01],[2,1.78,23.92]],"ltp":2.62,"tv":30.28,"id":16586500},{"batl":[[0,5.3,24.9]],"ltp":3.65,"tv":17.69,"id":13508964},{"batb":[[2,5.5,9.24]],"batl":[[0,6.8,6.72],[1,7.8,14.01],[2,12.5,14.01]],"ltp":5.1,"tv":6.72,"id":16586502}]}]}
{"op":"mcm","clk":"1005613698","pt":1580643592711,"mc":[{"id":"1.168219388","rc":[{"batb":[[1,1.49,38.71],[2,1.27,80.1]],"ltp":2.62,"tv":30.28,"id":16586500},{"batb":[[0,4.6,16.37],[1,4.4,11.76],[2,3.8,12.98]],"ltp":3.65,"tv":17.69,"id":13508964},{"batb":[[0,6.4,14.95],[1,5.5,9.24],[2,5.3,11.72]],"ltp":5.1,"tv":6.72,"id":16586502}]}]}
{"op":"mcm","clk":"1005613874","pt":1580643593524,"mc":[{"id":"1.168219388","rc":[{"batb":[[0,1.27,80.1],[1,1.01,0.51],[2,1.27,0]],"batl":[[0,1.78,23.92],[1,1.65,0],[2,1.78,0]],"ltp":2.62,"tv":30.28,"id":16586500},{"batb":[[0,3.8,12.98],[1,1.01,0.51],[2,3.8,0]],"batl":[[0,8,13.38],[1,8,0]],"ltp":3.65,"tv":17.69,"id":13508964},{"batb":[[0,5.3,11.72],[1,1.01,0.51],[2,5.3,0]],"batl":[[0,12.5,14.01],[1,7.8,0],[2,12.5,0]],"ltp":5.1,"tv":6.72,"id":16586502}]}]}
{"op":"mcm","clk":"1005614305","pt":1580643595712,"mc":[{"id":"1.168219388","rc":[{"batb":[[1,1.26,293.86],[2,1.25,236.92]],"ltp":2.62,"tv":30.28,"id":16586500},{"batb":[[0,3.9,55.84],[1,3.85,30.36],[2,3.8,12.98]],"ltp":3.65,"tv":17.69,"id":13508964},{"batb":[[0,5.3,46.1],[1,5.2,32.31],[2,1.01,0.51]],"ltp":5.1,"tv":6.72,"id":16586502}]}]}
{"op":"mcm","clk":"1005614383","pt":1580643596136,"mc":[{"id":"1.168219388","rc":[{"batb":[[1,1.01,0.51],[2,1.25,0]],"ltp":2.62,"tv":30.28,"id":16586500},{"batb":[[0,3.8,12.98],[1,1.01,0.51],[2,3.8,0]],"ltp":3.65,"tv":17.69,"id":13508964},{"batb":[[0,5.3,11.72],[1,1.01,0.51],[2,1.01,0]],"ltp":5.1,"tv":6.72,"id":16586502}]}]}
{"op":"mcm","clk":"1005614748","pt":1580643597691,"mc":[{"id":"1.168219388","rc":[{"batb":[[0,1.45,85.34],[1,1.44,114.41],[2,1.27,80.1]],"ltp":2.62,"tv":30.28,"id":16586500},{"batb":[[0,5.2,30.86],[1,5.1,31.41],[2,3.8,12.98]],"ltp":3.65,"tv":17.69,"id":13508964},{"batb":[[0,7,46.64],[1,6.8,34.84],[2,5.3,11.72]],"ltp":5.1,"tv":6.72,"id":16586502}]}]}
{"op":"mcm","clk":"1005615515","pt":1580643601495,"mc":[{"id":"1.168219388","rc":[{"batb":[[0,1.27,80.1],[1,1.01,0.51],[2,1.27,0]],"ltp":2.62,"tv":30.28,"id":16586500},{"batb":[[0,3.8,12.98],[1,1.01,0.51],[2,3.8,0]],"ltp":3.65,"tv":17.69,"id":13508964},{"batb":[[0,5.3,11.72],[1,1.01,0.51],[2,5.3,0]],"ltp":5.1,"tv":6.72,"id":16586502}]}]}
{"op":"mcm","clk":"1005616112","pt":1580643604235,"mc":[{"id":"1.168219388","rc":[{"batb":[[1,1.26,295.99],[2,1.25,236.92]],"ltp":2.62,"tv":30.28,"id":16586500},{"batb":[[0,3.9,54.7],[1,3.85,30.36],[2,3.8,12.98]],"ltp":3.65,"tv":17.69,"id":13508964},{"batb":[[0,5.3,46.37],[1,5.2,32.31],[2,1.01,0.51]],"ltp":5.1,"tv":6.72,"id":16586502}]}]}
{"op":"mcm","clk":"1005618845","pt":1580643618327,"mc":[{"id":"1.168219388","rc":[{"batb":[[0,3.8,12.98],[1,1.01,0.51],[2,3.8,0]],"ltp":3.65,"tv":17.69,"id":13508964},{"batb":[[0,5.3,11.72],[1,1.01,0.51],[2,1.01,0]],"ltp":5.1,"tv":6.72,"id":16586502}]}]}
{"op":"mcm","clk":"1005619515","pt":1580643621528,"mc":[{"id":"1.168219388","rc":[{"batb":[[0,7.4,32.47],[1,7.2,28.6],[2,3.8,12.98]],"ltp":3.65,"tv":17.69,"id":13508964},{"batb":[[0,10.5,18.74],[1,10,37.79],[2,5.3,11.72]],"ltp":5.1,"tv":6.72,"id":16586502}]}]}
{"op":"mcm","clk":"1005619746","pt":1580643622650,"mc":[{"id":"1.168219388","rc":[{"batb":[[0,1.28,149.55],[1,1.27,80.1],[2,1.26,295.99]],"batl":[[0,1.33,76.95],[1,1.35,42.01],[2,1.42,55.86]],"ltp":2.62,"tv":30.28,"id":16586500},{"batb":[[2,6.6,20.96]],"batl":[[1,8.2,5.04],[2,9.2,9.99]],"ltp":3.65,"tv":17.69,"id":13508964},{"batb":[[2,9.4,15.42]],"batl":[[0,11,4.2],[1,12.5,14.01],[2,14.5,10.62]],"ltp":5.1,"tv":6.72,"id":16586502}]}]}
{"op":"mcm","clk":"1005623574","pt":1580643642746,"mc":[{"id":"1.168219388","rc":[{"batb":[[0,1.01,0.51],[1,1.01,0]],"ltp":11.5,"tv":351.14,"id":13508961}]}]}
{"op":"mcm","clk":"1005626651","pt":1580643658416,"mc":[{"id":"1.168219388","rc":[{"batb":[[2,1.23,99.53]],"ltp":2.62,"tv":30.28,"id":16586500},{"batb":[[0,6.6,20.96],[1,5.5,10.78],[2,1.01,0.51]],"ltp":3.65,"tv":17.69,"id":13508964},{"batb":[[0,9.4,15.42],[1,8.4,5.04],[2,8,8.97]],"ltp":5.1,"tv":6.72,"id":16586502}]}]}
{"op":"mcm","clk":"1005627287","pt":1580643661750,"mc":[{"id":"1.168219388","rc":[{"batb":[[1,6,48.79],[2,5.9,22.34]],"ltp":3.65,"tv":17.69,"id":13508964},{"batb":[[1,8.6,21.61],[2,8.4,27.55]],"ltp":5.1,"tv":6.72,"id":16586502}]}]}
{"op":"mcm","clk":"1005633618","pt":1580643693456,"mc":[{"id":"1.168219388","rc":[{"batb":[[1,1.23,99.53],[2,1.22,309.4]],"batl":[[0,1.35,42.01],[1,1.42,55.86],[2,1.42,0]],"ltp":2.62,"tv":30.28,"id":16586500},{"batb":[[0,6.6,6.72]],"batl":[[0,8.2,5.04],[1,9.2,9.99],[2,9.2,0]],"ltp":3.65,"tv":17.69,"id":13508964},{"batb":[[0,8.6,21.61],[1,8.4,27.55],[2,8,8.97]],"batl":[[1,14.5,10.62],[2,14.5,0]],"ltp":5.1,"tv":6.72,"id":16586502}]}]}
{"op":"mcm","clk":"1005634034","pt":1580643695330,"mc":[{"id":"1.168219388","rc":[{"batb":[[0,1.23,99.53],[1,1.22,309.4],[2,1.21,272.16]],"batl":[[0,1.42,55.86],[1,1.42,0]],"ltp":2.62,"tv":30.28,"id":16586500},{"batb":[[0,6,48.79],[1,5.9,22.34],[2,5.5,10.62]],"batl":[[0,9.2,9.99],[1,9.2,0]],"ltp":3.65,"tv":17.69,"id":13508964},{"batb":[[1,8.4,22.51]],"batl":[[0,14.5,10.62],[1,14.5,0]],"ltp":5.1,"tv":6.72,"id":16586502}]}]}
{"op":"mcm","clk":"1005636686","pt":1580643708748,"mc":[{"id":"1.168219388","rc":[{"batb":[[0,9,13.44],[1,1.01,0.51]],"ltp":11.5,"tv":351.14,"id":13508961}]}]}
{"op":"mcm","clk":"1005637225","pt":1580643711221,"mc":[{"id":"1.168219388","rc":[{"batb":[[0,5.5,10.62],[1,1.01,0.51],[2,5.5,0]],"ltp":3.65,"tv":17.69,"id":13508964},{"batb":[[0,8,8.97],[1,1.01,0.51],[2,8,0]],"ltp":5.1,"tv":6.72,"id":16586502}]}]}
{"op":"mcm","clk":"1005637922","pt":1580643714750,"mc":[{"id":"1.168219388","rc":[{"batb":[[0,8.4,33.34],[1,8.2,21.52],[2,5.5,10.62]],"ltp":3.65,"tv":17.69,"id":13508964},{"batb":[[0,12,14.36],[1,11.5,28.4],[2,8,8.97]],"ltp":5.1,"tv":6.72,"id":16586502}]}]}
{"op":"mcm","clk":"1005638023","pt":1580643715247,"mc":[{"id":"1.168219388","rc":[{"batl":[[0,1.28,95.21],[1,1.35,71.6]],"ltp":2.62,"tv":30.28,"id":16586500},{"batb":[[2,7.6,10.39]],"batl":[[1,10.5,7.63]],"ltp":3.65,"tv":17.69,"id":13508964},{"batb":[[2,10.5,11.57]],"batl":[[1,16.5,8.26]],"ltp":5.1,"tv":6.72,"id":16586502}]}]}
{"op":"mcm","clk":"1005638332","pt":1580643716576,"mc":[{"id":"1.168219388","rc":[{"batb":[[0,1.24,168.04],[1,1.23,99.53],[2,1.22,309.4]],"ltp":2.62,"tv":30.28,"id":16586500},{"batl":[[0,9.2,15.03]],"ltp":3.65,"tv":17.69,"id":13508964},{"batl":[[0,12.5,3.36],[1,14.5,10.62],[2,16.5,8.26]],"ltp":5.1,"tv":6.72,"id":16586502}]}]}
{"op":"mcm","clk":"1005638579","pt":1580643717659,"mc":[{"id":"1.168219388","rc":[{"batl":[[1,1.3,42.01],[2,1.35,71.6]],"ltp":2.62,"tv":30.28,"id":16586500}]}]}
{"op":"mcm","clk":"1005641584","pt":1580643732385,"mc":[{"id":"1.168219388","rc":[{"batb":[[1,1.19,119.99],[2,1.01,0.51]],"batl":[[0,1.3,42.01],[1,1.35,71.6],[2,1.35,0]],"ltp":2.62,"tv":30.28,"id":16586500},{"batb":[[0,7.2,6.72],[1,6.2,15.58],[2,1.01,0.51]],"batl":[[0,9.2,5.04]],"ltp":3.65,"tv":17.69,"id":13508964},{"batb":[[0,9.4,4.2],[1,9.2,6.85],[2,1.01,0.51]],"batl":[[1,16.5,8.26],[2,16.5,0]],"ltp":5.1,"tv":6.72,"id":16586502}]}]}
{"op":"mcm","clk":"1005641769","pt":1580643733502,"mc":[{"id":"1.168219388","rc":[{"batb":[[0,1.19,119.99],[1,1.01,0.51],[2,1.01,0]],"batl":[[0,1.35,71.6],[1,1.35,0]],"ltp":2.62,"tv":30.28,"id":16586500},{"batb":[[0,6.2,15.58],[1,1.01,0.51],[2,1.01,0]],"batl":[[0,10.5,7.63],[1,10.5,0]],"ltp":3.65,"tv":17.69,"id":13508964},{"batb":[[0,9.2,6.85],[1,1.01,0.51],[2,1.01,0]],"batl":[[0,16.5,8.26],[1,16.5,0]],"ltp":5.1,"tv":6.72,"id":16586502}]}]}
{"op":"mcm","clk":"1005642058","pt":1580643734977,"mc":[{"id":"1.168219388","rc":[{"batb":[[0,1.19,478.77],[1,1.18,237.14],[2,1.01,0.51]],"ltp":2.62,"tv":30.28,"id":16586500},{"batb":[[0,7,37.14],[1,6.8,32.3],[2,6.2,15.58]],"ltp":3.65,"tv":17.69,"id":13508964},{"batb":[[0,10,20.08],[1,9.8,16.23],[2,9.2,6.85]],"ltp":5.1,"tv":6.72,"id":16586502}]}]}
{"op":"mcm","clk":"1005642719","pt":1580643738416,"mc":[{"id":"1.168219388","rc":[{"batb":[[0,1.01,0.51],[1,1.01,0]],"ltp":11.5,"tv":351.14,"id":13508961}]}]}
{"op":"mcm","clk":"1005644839","pt":1580643749225,"mc":[{"id":"1.168219388","rc":[{"batb":[[0,6.2,15.58],[1,1.01,0.51],[2,6.2,0]],"ltp":3.65,"tv":17.69,"id":13508964},{"batb":[[0,9.2,6.85],[1,1.01,0.51],[2,9.2,0]],"ltp":5.1,"tv":6.72,"id":16586502}]}]}
{"op":"mcm","clk":"1005645481","pt":1580643752449,"mc":[{"id":"1.168219388","rc":[{"batb":[[0,9.6,15.6],[1,9.4,16.34],[2,6.2,15.58]],"ltp":3.65,"tv":17.69,"id":13508964},{"batb":[[0,13.5,9.1],[1,13,22.2],[2,9.2,6.85]],"ltp":5.1,"tv":6.72,"id":16586502}]}]}
{"op":"mcm","clk":"1005645631","pt":1580643753249,"mc":[{"id":"1.168219388","rc":[{"batb":[[2,1.17,139.66]],"batl":[[0,1.24,115.43],[1,1.29,92.06]],"ltp":2.62,"tv":30.28,"id":16586500},{"batb":[[2,8.6,7.63]],"batl":[[0,11,7.32],[1,12.5,14.4]],"ltp":3.65,"tv":17.69,"id":13508964},{"batb":[[2,12,8.97]],"batl":[[1,18,7]],"ltp":5.1,"tv":6.72,"id":16586502}]}]}
{"op":"mcm","clk":"1005645929","pt":1580643754652,"mc":[{"id":"1.168219388","rc":[{"batb":[[0,1.21,168.04],[1,1.19,478.77],[2,1.18,237.14]],"batl":[[1,1.26,42.01],[2,1.29,92.06]],"ltp":2.62,"tv":30.28,"id":16586500},{"batl":[[0,10.5,4.2],[1,11,7.32],[2,12.5,14.4]],"ltp":3.65,"tv":17.69,"id":13508964}]}]}
{"op":"mcm","clk":"1005646603","pt":1580643757764,"mc":[{"id":"1.168219388","rc":[{"batb":[[1,1.19,424.99]],"ltp":2.62,"tv":30.28,"id":16586500}]}]}
{"op":"mcm","clk":"1005647194","pt":1580643760643,"mc":[{"id":"1.168219388","rc":[{"batb":[[2,1.18,291.38]],"ltp":2.62,"tv":30.28,"id":16586500},{"batb":[[0,9.6,26.72]],"ltp":3.65,"tv":17.69,"id":13508964},{"trd":[[13.5,6.72]],"batb":[[0,13.5,5.74]],"ltp":13.5,"tv":13.44,"id":16586502}],"tv":412.56}]}
{"op":"mcm","clk":"1005647316","pt":1580643761234,"mc":[{"id":"1.168219388","rc":[{"batb":[[0,1.19,424.99],[1,1.18,291.38],[2,1.17,139.66]],"ltp":2.62,"tv":30.28,"id":16586500},{"batl":[[0,11,7.32],[1,12.5,14.4],[2,12.5,0]],"ltp":3.65,"tv":17.69,"id":13508964},{"batb":[[0,13,22.2],[1,12,8.97],[2,10.5,16.4]],"ltp":13.5,"tv":13.44,"id":16586502}]}]}
{"op":"mcm","clk":"1005647814","pt":1580643763879,"mc":[{"id":"1.168219388","rc":[{"batl":[[0,11,11.52]],"ltp":3.65,"tv":17.69,"id":13508964},{"batb":[[0,13,30.04],[1,12.5,23.24],[2,12,8.97]],"ltp":13.5,"tv":13.44,"id":16586502}]}]}
{"op":"mcm","clk":"1005648468","pt":1580643767253,"mc":[{"id":"1.168219388","rc":[{"batl":[[0,11,7.32]],"ltp":3.65,"tv":17.69,"id":13508964}]}]}
{"op":"mcm","clk":"1005649081","pt":1580643770671,"mc":[{"id":"1.168219388","rc":[{"batb":[[0,1.21,168.04],[1,1.19,424.99],[2,1.18,291.38]],"ltp":2.62,"tv":30.28,"id":16586500},{"batl":[[0,10.5,4.2],[1,11,7.32],[2,12.5,14.4]],"ltp":3.65,"tv":17.69,"id":13508964}]}]}
{"op":"mcm","clk":"1005649272","pt":1580643771643,"mc":[{"id":"1.168219388","rc":[{"batb":[[0,1.17,139.66],[1,1.01,0.51],[2,1.18,0]],"batl":[[0,1.29,92.06],[1,1.26,0],[2,1.29,0]],"ltp":2.62,"tv":30.28,"id":16586500},{"batb":[[0,7.4,10.86],[1,1.01,0.51],[2,8.6,0]],"batl":[[0,12.5,14.4],[1,11,0],[2,12.5,0]],"ltp":3.65,"tv":17.69,"id":13508964},{"batb":[[0,10.5,12.2],[1,1.01,0.51],[2,12,0]],"batl":[[0,18,7],[1,18,0]],"ltp":13.5,"tv":13.44,"id":16586502}]}]}
{"op":"mcm","clk":"1005649838","pt":1580643774466,"mc":[{"id":"1.168219388","rc":[{"batb":[[0,1.17,423.46],[1,1.16,324.04],[2,1.01,0.51]],"batl":[[0,1.28,93.55]],"ltp":2.62,"tv":30.28,"id":16586500},{"batb":[[0,8.4,19.19],[1,8.2,22.06],[2,7.6,10.46]],"batl":[[0,12.5,13.85]],"ltp":3.65,"tv":17.69,"id":13508964},{"batb":[[0,11.5,27.35],[1,11,30.46],[2,10.5,12.2]],"ltp":13.5,"tv":13.44,"id":16586502}]}]}
{"op":"mcm","clk":"1005650274","pt":1580643776757,"mc":[{"id":"1.168219388","rc":[{"batb":[[0,1.16,141.86],[1,1.01,0.51],[2,1.01,0]],"ltp":2.62,"tv":30.28,"id":16586500},{"batb":[[0,7.6,10.46],[1,1.01,0.51],[2,7.6,0]],"ltp":3.65,"tv":17.69,"id":13508964},{"batb":[[0,10.5,12.2],[1,1.01,0.51],[2,10.5,0]],"ltp":13.5,"tv":13.44,"id":16586502}]}]}
{"op":"mcm","clk":"1005650817","pt":1580643779660,"mc":[{"id":"1.168219388","rc":[{"batl":[[0,9.2,112.53],[1,12.5,13.85]],"ltp":3.65,"tv":17.69,"id":13508964}]}]}
