{"op":"mcm","clk":"998176899","pt":1580569848193,"mc":[{"id":"1.168219390","marketDefinition":{"bspMarket":false,"turnInPlayEnabled":true,"persistenceEnabled":true,"marketBaseRate":5.0,"eventId":"29681328","eventTypeId":"2","numberOfWinners":1,"bettingType":"ODDS","marketType":"SET_WINNER","marketTime":"2020-02-02T11:30:00.000Z","suspendTime":"2020-02-02T11:30:00.000Z","bspReconciled":false,"complete":true,"inPlay":false,"crossMatching":false,"runnersVoidable":false,"numberOfActiveRunners":2,"betDelay":0,"status":"OPEN","runners":[{"status":"ACTIVE","sortPriority":1,"id":8535963,"name":"Nikola Milojevic"},{"status":"ACTIVE","sortPriority":2,"id":2309796,"name":"Robin Haase"}],"regulators":["MR_INT"],"countryCode":"IN","discountAllowed":false,"timezone":"UTC","openDate":"2020-02-02T11:30:00.000Z","version":3145750575,"name":"Set 2 Winner","eventName":"Milojevic v Haase"}}]}
{"op":"mcm","clk":"998177333","pt":1580569849772,"mc":[{"id":"1.168219390","marketDefinition":{"bspMarket":false,"turnInPlayEnabled":true,"persistenceEnabled":true,"marketBaseRate":5.0,"eventId":"29681328","eventTypeId":"2","numberOfWinners":1,"bettingType":"ODDS","marketType":"SET_WINNER","marketTime":"2020-02-02T11:30:00.000Z","suspendTime":"2020-02-02T11:30:00.000Z","bspReconciled":false,"complete":true,"inPlay":false,"crossMatching":false,"runnersVoidable":false,"numberOfActiveRunners":2,"betDelay":0,"status":"OPEN","runners":[{"status":"ACTIVE","sortPriority":1,"id":8535963,"name":"Nikola Milojevic"},{"status":"ACTIVE","sortPriority":2,"id":2309796,"name":"Robin Haase"}],"regulators":["MR_INT"],"countryCode":"IN","discountAllowed":false,"timezone":"UTC","openDate":"2020-02-02T11:30:00.000Z","version":3145750575,"name":"Set 2 Winner","eventName":"Milojevic v Haase"}}]}
{"op":"mcm","clk":"998177617","pt":1580569850776,"mc":[{"id":"1.168219390","marketDefinition":{"bspMarket":false,"turnInPlayEnabled":true,"persistenceEnabled":true,"marketBaseRate":5.0,"eventId":"29681328","eventTypeId":"2","numberOfWinners":1,"bettingType":"ODDS","marketType":"SET_WINNER","marketTime":"2020-02-02T11:30:00.000Z","suspendTime":"2020-02-02T11:30:00.000Z","bspReconciled":false,"complete":true,"inPlay":false,"crossMatching":false,"runnersVoidable":false,"numberOfActiveRunners":2,"betDelay":0,"status":"OPEN","runners":[{"status":"ACTIVE","sortPriority":1,"id":8535963,"name":"Nikola Milojevic"},{"status":"ACTIVE","sortPriority":2,"id":2309796,"name":"Robin Haase"}],"regulators":["MR_INT"],"countryCode":"IN","discountAllowed":true,"timezone":"UTC","openDate":"2020-02-02T11:30:00.000Z","version":3145750575,"name":"Set 2 Winner","eventName":"Milojevic v Haase"}}]}
{"op":"mcm","clk":"998189144","pt":1580569893697,"mc":[{"id":"1.168219390","rc":[{"batb":[[0,1.01,20]],"ltp":0.0,"tv":0.0,"id":8535963},{"batb":[[0,1.01,20]],"ltp":0.0,"tv":0.0,"id":2309796}]}]}
{"op":"mcm","clk":"998246771","pt":1580570113734,"mc":[{"id":"1.168219390","rc":[{"batb":[[0,1.01,10]],"ltp":0.0,"tv":0.0,"id":8535963},{"batb":[[0,1.01,10]],"ltp":0.0,"tv":0.0,"id":2309796}]}]}
{"op":"mcm","clk":"1003058525","pt":1580602467518,"mc":[{"id":"1.168219390","rc":[{"batb":[[0,1.01,12.53]],"ltp":0.0,"tv":0.0,"id":8535963},{"batb":[[0,1.01,12.53]],"ltp":0.0,"tv":0.0,"id":2309796}]}]}
{"op":"mcm","clk":"1003058632","pt":1580602468618,"mc":[{"id":"1.168219390","rc":[{"batb":[[0,1.01,10.51]],"ltp":0.0,"tv":0.0,"id":8535963},{"batb":[[0,1.01,10.51]],"ltp":0.0,"tv":0.0,"id":2309796}]}]}
{"op":"mcm","clk":"1003180170","pt":1580604001642,"mc":[{"id":"1.168219390","rc":[{"batb":[[0,1.01,13.04]],"ltp":0.0,"tv":0.0,"id":8535963},{"batb":[[0,1.01,13.04]],"ltp":0.0,"tv":0.0,"id":2309796}]}]}
{"op":"mcm","clk":"1003180241","pt":1580604002662,"mc":[{"id":"1.168219390","rc":[{"batb":[[0,1.01,11.01]],"ltp":0.0,"tv":0.0,"id":8535963},{"batb":[[0,1.01,11.01]],"ltp":0.0,"tv":0.0,"id":2309796}]}]}
{"op":"mcm","clk":"1003389712","pt":1580607092754,"mc":[{"id":"1.168219390","rc":[{"batb":[[0,1.01,13.01]],"ltp":0.0,"tv":0.0,"id":8535963},{"batb":[[0,1.01,13.01]],"ltp":0.0,"tv":0.0,"id":2309796}]}]}
{"op":"mcm","clk":"1003389751","pt":1580607093169,"mc":[{"id":"1.168219390","rc":[{"batb":[[0,1.01,11.02]],"ltp":0.0,"tv":0.0,"id":8535963},{"batb":[[0,1.01,11.02]],"ltp":0.0,"tv":0.0,"id":2309796}]}]}
{"op":"mcm","clk":"1004704063","pt":1580635607319,"mc":[{"id":"1.168219390","marketDefinition":{"bspMarket":false,"turnInPlayEnabled":true,"persistenceEnabled":true,"marketBaseRate":5.0,"eventId":"29681328","eventTypeId":"2","numberOfWinners":1,"bettingType":"ODDS","marketType":"SET_WINNER","marketTime":"2020-02-02T11:23:00.000Z","suspendTime":"2020-02-02T11:23:00.000Z","bspReconciled":false,"complete":true,"inPlay":false,"crossMatching":false,"runnersVoidable":false,"numberOfActiveRunners":2,"betDelay":0,"status":"OPEN","runners":[{"status":"ACTIVE","sortPriority":1,"id":8535963,"name":"Nikola Milojevic"},{"status":"ACTIVE","sortPriority":2,"id":2309796,"name":"Robin Haase"}],"regulators":["MR_INT"],"countryCode":"IN","discountAllowed":true,"timezone":"UTC","openDate":"2020-02-02T11:30:00.000Z","version":3148345187,"name":"Set 2 Winner","eventName":"Milojevic v Haase"}}]}
{"op":"mcm","clk":"1004704272","pt":1580635610363,"mc":[{"id":"1.168219390","marketDefinition":{"bspMarket":false,"turnInPlayEnabled":true,"persistenceEnabled":true,"marketBaseRate":5.0,"eventId":"29681328","eventTypeId":"2","numberOfWinners":1,"bettingType":"ODDS","marketType":"SET_WINNER","marketTime":"2020-02-02T11:23:00.000Z","suspendTime":"2020-02-02T11:23:00.000Z","bspReconciled":false,"complete":true,"inPlay":false,"crossMatching":false,"runnersVoidable":false,"numberOfActiveRunners":2,"betDelay":0,"status":"OPEN","runners":[{"status":"ACTIVE","sortPriority":1,"id":8535963,"name":"Nikola Milojevic"},{"status":"ACTIVE","sortPriority":2,"id":2309796,"name":"Robin Haase"}],"regulators":["MR_INT"],"countryCode":"IN","discountAllowed":true,"timezone":"UTC","openDate":"2020-02-02T11:23:00.000Z","version":3148345187,"name":"Set 2 Winner","eventName":"Milojevic v Haase"}}]}
{"op":"mcm","clk":"1005053389","pt":1580640381602,"mc":[{"id":"1.168219390","rc":[{"batb":[[0,2.1,24.08],[1,1.01,11.02]],"ltp":0.0,"tv":0.0,"id":8535963},{"batb":[[0,1.79,19.99],[1,1.01,11.02]],"ltp":0.0,"tv":0.0,"id":2309796}]}]}
{"op":"mcm","clk":"1005056066","pt":1580640402412,"mc":[{"id":"1.168219390","marketDefinition":{"bspMarket":false,"turnInPlayEnabled":true,"persistenceEnabled":true,"marketBaseRate":5.0,"eventId":"29681328","eventTypeId":"2","numberOfWinners":1,"bettingType":"ODDS","marketType":"SET_WINNER","marketTime":"2020-02-02T11:23:00.000Z","suspendTime":"2020-02-02T11:23:00.000Z","bspReconciled":false,"complete":true,"inPlay":false,"crossMatching":true,"runnersVoidable":false,"numberOfActiveRunners":2,"betDelay":0,"status":"OPEN","runners":[{"status":"ACTIVE","sortPriority":1,"id":8535963,"name":"Nikola Milojevic"},{"status":"ACTIVE","sortPriority":2,"id":2309796,"name":"Robin Haase"}],"regulators":["MR_INT"],"countryCode":"IN","discountAllowed":true,"timezone":"UTC","openDate":"2020-02-02T11:23:00.000Z","version":3148345187,"name":"Set 2 Winner","eventName":"Milojevic v Haase"}}]}
{"op":"mcm","clk":"1005056582","pt":1580640406412,"mc":[{"id":"1.168219390","marketDefinition":{"bspMarket":false,"turnInPlayEnabled":true,"persistenceEnabled":true,"marketBaseRate":5.0,"eventId":"29681328","eventTypeId":"2","numberOfWinners":1,"bettingType":"ODDS","marketType":"SET_WINNER","marketTime":"2020-02-02T10:45:00.000Z","suspendTime":"2020-02-02T10:45:00.000Z","bspReconciled":false,"complete":true,"inPlay":false,"crossMatching":true,"runnersVoidable":false,"numberOfActiveRunners":2,"betDelay":0,"status":"OPEN","runners":[{"status":"ACTIVE","sortPriority":1,"id":8535963,"name":"Nikola Milojevic"},{"status":"ACTIVE","sortPriority":2,"id":2309796,"name":"Robin Haase"}],"regulators":["MR_INT"],"countryCode":"IN","discountAllowed":true,"timezone":"UTC","openDate":"2020-02-02T11:23:00.000Z","version":3148437223,"name":"Set 2 Winner","eventName":"Milojevic v Haase"}}]}
{"op":"mcm","clk":"1005058517","pt":1580640420442,"mc":[{"id":"1.168219390","marketDefinition":{"bspMarket":false,"turnInPlayEnabled":true,"persistenceEnabled":true,"marketBaseRate":5.0,"eventId":"29681328","eventTypeId":"2","numberOfWinners":1,"bettingType":"ODDS","marketType":"SET_WINNER","marketTime":"2020-02-02T10:45:00.000Z","suspendTime":"2020-02-02T10:45:00.000Z","bspReconciled":false,"complete":true,"inPlay":false,"crossMatching":true,"runnersVoidable":false,"numberOfActiveRunners":2,"betDelay":0,"status":"OPEN","runners":[{"status":"ACTIVE","sortPriority":1,"id":8535963,"name":"Nikola Milojevic"},{"status":"ACTIVE","sortPriority":2,"id":2309796,"name":"Robin Haase"}],"regulators":["MR_INT"],"countryCode":"IN","discountAllowed":true,"timezone":"UTC","openDate":"2020-02-02T10:45:00.000Z","version":3148437223,"name":"Set 2 Winner","eventName":"Milojevic v Haase"}}]}
{"op":"mcm","clk":"1005106695","pt":1580640813138,"mc":[{"id":"1.168219390","rc":[{"batb":[[1,2.08,38.65],[2,1.01,11.02]],"batl":[[0,2.34,31.09]],"ltp":0.0,"tv":0.0,"id":8535963},{"batb":[[1,1.76,54.61],[2,1.01,11.02]],"batl":[[0,1.94,42.01]],"ltp":0.0,"tv":0.0,"id":2309796}]}]}
{"op":"mcm","clk":"1005134252","pt":1580641036391,"mc":[{"id":"1.168219390","rc":[{"batb":[[0,1.8,19.75]],"ltp":0.0,"tv":0.0,"id":2309796}]}]}
{"op":"mcm","clk":"1005137469","pt":1580641060220,"mc":[{"id":"1.168219390","rc":[{"batb":[[0,2.08,38.65],[1,1.01,11.02],[2,1.01,0]],"ltp":0.0,"tv":0.0,"id":8535963},{"batb":[[0,1.76,54.61],[1,1.01,11.02],[2,1.01,0]],"ltp":0.0,"tv":0.0,"id":2309796}]}]}
{"op":"mcm","clk":"1005137575","pt":1580641060914,"mc":[{"id":"1.168219390","marketDefinition":{"bspMarket":false,"turnInPlayEnabled":true,"persistenceEnabled":true,"marketBaseRate":5.0,"eventId":"29681328","eventTypeId":"2","numberOfWinners":1,"bettingType":"ODDS","marketType":"SET_WINNER","marketTime":"2020-02-02T10:45:00.000Z","suspendTime":"2020-02-02T10:45:00.000Z","bspReconciled":false,"complete":true,"inPlay":true,"crossMatching":true,"runnersVoidable":false,"numberOfActiveRunners":2,"betDelay":3,"status":"OPEN","runners":[{"status":"ACTIVE","sortPriority":1,"id":8535963,"name":"Nikola Milojevic"},{"status":"ACTIVE","sortPriority":2,"id":2309796,"name":"Robin Haase"}],"regulators":["MR_INT"],"countryCode":"IN","discountAllowed":true,"timezone":"UTC","openDate":"2020-02-02T10:45:00.000Z","version":3148446442,"name":"Set 2 Winner","eventName":"Milojevic v Haase"},"rc":[{"batb":[[0,1.01,10.52],[1,1.01,0]],"ltp":0.0,"tv":0.0,"id":8535963},{"batb":[[0,1.01,10.52],[1,1.01,0]],"ltp":0.0,"tv":0.0,"id":2309796}]}]}
{"op":"mcm","clk":"1005138919","pt":1580641072720,"mc":[{"id":"1.168219390","rc":[{"batb":[[0,2.12,36.97],[1,1.01,10.52]],"batl":[[0,2.4,29.41]],"ltp":0.0,"tv":0.0,"id":8535963},{"batb":[[0,1.71,58.81],[1,1.01,10.52]],"batl":[[0,1.89,42.01]],"ltp":0.0,"tv":0.0,"id":2309796}]}]}
{"op":"mcm","clk":"1005139029","pt":1580641073507,"mc":[{"id":"1.168219390","rc":[{"batb":[[0,2.16,22.5],[1,2.12,60.57],[2,1.01,10.52]],"ltp":0.0,"tv":0.0,"id":8535963},{"batb":[[0,1.76,21.24],[1,1.71,82.1],[2,1.01,10.52]],"ltp":0.0,"tv":0.0,"id":2309796}]}]}
{"op":"mcm","clk":"1005140661","pt":1580641086732,"mc":[{"id":"1.168219390","rc":[{"batb":[[0,2.12,60.57],[1,1.01,10.52],[2,1.01,0]],"ltp":0.0,"tv":0.0,"id":8535963},{"batb":[[0,1.71,82.1],[1,1.01,10.52],[2,1.01,0]],"ltp":0.0,"tv":0.0,"id":2309796}]}]}
{"op":"mcm","clk":"1005140772","pt":1580641087625,"mc":[{"id":"1.168219390","rc":[{"batb":[[0,2.12,23.6]],"ltp":0.0,"tv":0.0,"id":8535963},{"batb":[[0,1.71,23.29]],"ltp":0.0,"tv":0.0,"id":2309796}]}]}
{"op":"mcm","clk":"1005142554","pt":1580641101647,"mc":[{"id":"1.168219390","rc":[{"batb":[[1,2.08,25.02],[2,1.01,10.52]],"ltp":0.0,"tv":0.0,"id":8535963},{"batb":[[0,1.78,20.38],[1,1.74,21.95],[2,1.01,10.52]],"ltp":0.0,"tv":0.0,"id":2309796}]}]}
{"op":"mcm","clk":"1005142678","pt":1580641102636,"mc":[{"id":"1.168219390","rc":[{"batb":[[1,2.1,37.81],[2,2.08,25.02]],"batl":[[0,2.36,30.25]],"ltp":0.0,"tv":0.0,"id":8535963},{"batb":[[2,1.73,57.13]],"batl":[[0,1.92,42.01]],"ltp":0.0,"tv":0.0,"id":2309796}]}]}
{"op":"mcm","clk":"1005144510","pt":1580641116685,"mc":[{"id":"1.168219390","rc":[{"batb":[[0,2.1,37.81],[1,2.08,25.02],[2,1.01,10.52]],"ltp":0.0,"tv":0.0,"id":8535963},{"batb":[[0,1.74,21.95],[1,1.73,57.13],[2,1.01,10.52]],"ltp":0.0,"tv":0.0,"id":2309796}]}]}
{"op":"mcm","clk":"1005144651","pt":1580641117731,"mc":[{"id":"1.168219390","rc":[{"batb":[[0,2.08,25.02],[1,1.01,10.52],[2,1.01,0]],"ltp":0.0,"tv":0.0,"id":8535963},{"batb":[[1,1.01,10.52],[2,1.01,0]],"ltp":0.0,"tv":0.0,"id":2309796}]}]}
{"op":"mcm","clk":"1005146851","pt":1580641134715,"mc":[{"id":"1.168219390","rc":[{"batb":[[1,2.06,39.49],[2,1.01,10.52]],"batl":[[0,2.32,31.09]],"ltp":0.0,"tv":0.0,"id":8535963},{"batb":[[0,1.76,54.61],[1,1.74,21.95],[2,1.01,10.52]],"batl":[[0,1.94,42.01]],"ltp":0.0,"tv":0.0,"id":2309796}]}]}
{"op":"mcm","clk":"1005146977","pt":1580641135506,"mc":[{"id":"1.168219390","rc":[{"batb":[[2,2.04,26.36]],"ltp":0.0,"tv":0.0,"id":8535963},{"batb":[[0,1.81,19.28],[1,1.77,20.85],[2,1.76,54.61]],"ltp":0.0,"tv":0.0,"id":2309796}]}]}
{"op":"mcm","clk":"1005149077","pt":1580641149730,"mc":[{"id":"1.168219390","rc":[{"batb":[[0,2.04,26.36],[1,1.01,10.52],[2,2.04,0]],"ltp":0.0,"tv":0.0,"id":8535963},{"batb":[[0,1.77,20.85],[1,1.01,10.52],[2,1.76,0]],"ltp":0.0,"tv":0.0,"id":2309796}]}]}
{"op":"mcm","clk":"1005149467","pt":1580641152707,"mc":[{"id":"1.168219390","rc":[{"batb":[[0,2.06,26.04]],"ltp":0.0,"tv":0.0,"id":8535963},{"batb":[[0,1.76,21.09]],"ltp":0.0,"tv":0.0,"id":2309796}]}]}
{"op":"mcm","clk":"1005154749","pt":1580641191692,"mc":[{"id":"1.168219390","rc":[{"batb":[[0,2.14,22.74],[1,2.1,24.08],[2,2.06,26.04]],"ltp":0.0,"tv":0.0,"id":8535963},{"batb":[[1,1.71,23.21],[2,1.01,10.52]],"ltp":0.0,"tv":0.0,"id":2309796}]}]}
{"op":"mcm","clk":"1005154866","pt":1580641192730,"mc":[{"id":"1.168219390","rc":[{"batb":[[1,2.12,36.97],[2,2.1,24.08]],"batl":[[0,2.38,30.25]],"ltp":0.0,"tv":0.0,"id":8535963},{"batb":[[1,1.73,57.13],[2,1.71,23.21]],"batl":[[0,1.9,42.01]],"ltp":0.0,"tv":0.0,"id":2309796}]}]}
{"op":"mcm","clk":"1005157687","pt":1580641208235,"mc":[{"id":"1.168219390","rc":[{"batb":[[0,2.12,36.97],[1,2.1,24.08],[2,1.01,10.52]],"ltp":0.0,"tv":0.0,"id":8535963},{"batb":[[0,1.73,57.13],[1,1.71,23.21],[2,1.01,10.52]],"ltp":0.0,"tv":0.0,"id":2309796}]}]}
{"op":"mcm","clk":"1005157952","pt":1580641209776,"mc":[{"id":"1.168219390","rc":[{"batb":[[0,2.1,24.08],[1,1.01,10.52],[2,1.01,0]],"ltp":0.0,"tv":0.0,"id":8535963},{"batb":[[0,1.71,23.21],[1,1.01,10.52],[2,1.01,0]],"ltp":0.0,"tv":0.0,"id":2309796}]}]}
{"op":"mcm","clk":"1005161946","pt":1580641232679,"mc":[{"id":"1.168219390","rc":[{"batb":[[1,2.08,38.65],[2,2.06,25.41]],"batl":[[0,2.36,30.25]],"ltp":0.0,"tv":0.0,"id":8535963},{"batb":[[0,1.79,19.99],[1,1.75,77.09],[2,1.01,10.52]],"batl":[[0,1.92,42.01]],"ltp":0.0,"tv":0.0,"id":2309796}]}]}
{"op":"mcm","clk":"1005165386","pt":1580641251743,"mc":[{"id":"1.168219390","rc":[{"batb":[[0,2.06,25.41],[1,1.01,10.52],[2,2.06,0]],"ltp":0.0,"tv":0.0,"id":8535963},{"batb":[[0,1.75,21.64],[1,1.01,10.52],[2,1.01,0]],"ltp":0.0,"tv":0.0,"id":2309796}]}]}
{"op":"mcm","clk":"1005166993","pt":1580641260755,"mc":[{"id":"1.168219390","rc":[{"batb":[[1,2.04,40.33],[2,2,27.93]],"batl":[[0,2.3,31.93]],"ltp":0.0,"tv":0.0,"id":8535963},{"batb":[[0,1.82,19.04],[1,1.79,72.84],[2,1.01,10.52]],"batl":[[0,1.97,42.01]],"ltp":0.0,"tv":0.0,"id":2309796}]}]}
{"op":"mcm","clk":"1005175517","pt":1580641308318,"mc":[{"id":"1.168219390","rc":[{"batb":[[0,2.04,40.33],[1,2,27.93],[2,1.01,10.52]],"ltp":0.0,"tv":0.0,"id":8535963},{"batb":[[0,1.79,72.84],[1,1.01,10.52],[2,1.01,0]],"ltp":0.0,"tv":0.0,"id":2309796}]}]}
{"op":"mcm","clk":"1005175794","pt":1580641309913,"mc":[{"id":"1.168219390","rc":[{"batb":[[0,2,27.93],[1,1.01,10.52],[2,1.01,0]],"ltp":0.0,"tv":0.0,"id":8535963},{"batb":[[0,1.79,19.91]],"ltp":0.0,"tv":0.0,"id":2309796}]}]}
{"op":"mcm","clk":"1005178168","pt":1580641322731,"mc":[{"id":"1.168219390","rc":[{"batb":[[0,2.06,39.49],[1,2,27.93],[2,1.01,10.52]],"batl":[[0,2.32,31.09]],"ltp":0.0,"tv":0.0,"id":8535963},{"batb":[[1,1.77,53.77],[2,1.01,10.52]],"batl":[[0,1.94,42.01]],"ltp":0.0,"tv":0.0,"id":2309796}]}]}
{"op":"mcm","clk":"1005178286","pt":1580641323321,"mc":[{"id":"1.168219390","rc":[{"batb":[[0,2.1,24.23],[1,2.06,39.49],[2,2.04,26.44]],"ltp":0.0,"tv":0.0,"id":8535963},{"batb":[[1,1.77,74.39]],"ltp":0.0,"tv":0.0,"id":2309796}]}]}
{"op":"mcm","clk":"1005178487","pt":1580641324427,"mc":[{"id":"1.168219390","rc":[{"batl":[[1,2.84,228.62]],"ltp":0.0,"tv":0.0,"id":8535963},{"batl":[[1,2.4,289.78]],"ltp":0.0,"tv":0.0,"id":2309796}]}]}
{"op":"mcm","clk":"1005180603","pt":1580641336061,"mc":[{"id":"1.168219390","rc":[{"batb":[[0,2.06,39.49],[1,2.04,26.44],[2,1.01,10.52]],"ltp":0.0,"tv":0.0,"id":8535963},{"batb":[[0,1.77,74.39],[1,1.01,10.52],[2,1.01,0]],"ltp":0.0,"tv":0.0,"id":2309796}]}]}
{"op":"mcm","clk":"1005180923","pt":1580641337765,"mc":[{"id":"1.168219390","rc":[{"batb":[[0,2.04,26.44],[1,1.01,10.52],[2,1.01,0]],"batl":[[0,2.84,228.62],[1,2.84,0]],"ltp":0.0,"tv":0.0,"id":8535963},{"batb":[[0,1.77,20.61]],"batl":[[0,2.4,289.78],[1,2.4,0]],"ltp":0.0,"tv":0.0,"id":2309796}]}]}
{"op":"mcm","clk":"1005184002","pt":1580641354697,"mc":[{"id":"1.168219390","rc":[{"batb":[[0,2.08,38.65],[1,2.04,26.44],[2,1.01,10.52]],"batl":[[0,2.36,30.25],[1,2.84,228.62]],"ltp":0.0,"tv":0.0,"id":8535963},{"batb":[[1,1.75,55.45],[2,1.01,10.52]],"batl":[[0,1.92,42.01]],"ltp":0.0,"tv":0.0,"id":2309796}]}]}
{"op":"mcm","clk":"1005184184","pt":1580641355595,"mc":[{"id":"1.168219390","rc":[{"batb":[[0,2.12,23.37],[1,2.08,63.83]],"ltp":0.0,"tv":0.0,"id":8535963},{"batb":[[1,1.75,77.01]],"ltp":0.0,"tv":0.0,"id":2309796}]}]}
{"op":"mcm","clk":"1005184372","pt":1580641356705,"mc":[{"id":"1.168219390","rc":[{"batl":[[1,2.3,309.75]],"ltp":0.0,"tv":0.0,"id":2309796}]}]}
{"op":"mcm","clk":"1005187974","pt":1580641375722,"mc":[{"id":"1.168219390","rc":[{"batb":[[0,2.08,25.18],[1,1.01,10.52],[2,1.01,0]],"batl":[[0,2.84,228.62],[1,2.84,0]],"ltp":0.0,"tv":0.0,"id":8535963},{"batb":[[0,1.75,21.56],[1,1.01,10.52],[2,1.01,0]],"batl":[[0,2.3,309.75],[1,2.3,0]],"ltp":0.0,"tv":0.0,"id":2309796}]}]}
{"op":"mcm","clk":"1005189340","pt":1580641382736,"mc":[{"id":"1.168219390","rc":[{"batb":[[0,2.16,22.19],[1,2.14,36.13],[2,2.1,24.08]],"batl":[[0,2.4,29.41],[1,2.84,228.62]],"ltp":0.0,"tv":0.0,"id":8535963},{"batb":[[1,1.73,79.48],[2,1.01,10.52]],"batl":[[0,1.9,42.01],[1,2.3,309.75]],"ltp":0.0,"tv":0.0,"id":2309796}]}]}
{"op":"mcm","clk":"1005190710","pt":1580641389968,"mc":[{"id":"1.168219390","rc":[{"batb":[[0,2.14,36.13],[1,2.1,24.08],[2,1.01,10.52]],"ltp":0.0,"tv":0.0,"id":8535963},{"batb":[[0,1.73,79.48],[1,1.01,10.52],[2,1.01,0]],"ltp":0.0,"tv":0.0,"id":2309796}]}]}
{"op":"mcm","clk":"1005191258","pt":1580641392757,"mc":[{"id":"1.168219390","rc":[{"batb":[[0,2.1,24.08],[1,1.01,10.52],[2,1.01,0]],"batl":[[0,2.84,228.62],[1,2.84,0]],"ltp":0.0,"tv":0.0,"id":8535963},{"batb":[[0,1.73,22.35]],"batl":[[0,2.3,309.75],[1,2.3,0]],"ltp":0.0,"tv":0.0,"id":2309796}]}]}
{"op":"mcm","clk":"1005192938","pt":1580641400766,"mc":[{"id":"1.168219390","rc":[{"batb":[[1,2.06,39.49],[2,2.04,26.04]],"batl":[[0,2.32,31.09],[1,2.84,228.62]],"ltp":0.0,"tv":0.0,"id":8535963},{"batb":[[0,1.79,19.99],[1,1.77,20.93],[2,1.76,54.61]],"batl":[[0,1.94,42.01],[1,2.3,309.75]],"ltp":0.0,"tv":0.0,"id":2309796}]}]}
{"op":"mcm","clk":"1005194314","pt":1580641407684,"mc":[{"id":"1.168219390","rc":[{"batb":[[0,2.06,39.49],[1,2.04,26.04],[2,1.01,10.52]],"ltp":0.0,"tv":0.0,"id":8535963},{"batb":[[0,1.77,20.93],[1,1.76,54.61],[2,1.01,10.52]],"ltp":0.0,"tv":0.0,"id":2309796}]}]}
{"op":"mcm","clk":"1005194353","pt":1580641407900,"mc":[{"id":"1.168219390","rc":[{"batb":[[0,2.04,26.04],[1,1.01,10.52],[2,1.01,0]],"batl":[[0,2.84,228.62],[1,2.84,0]],"ltp":0.0,"tv":0.0,"id":8535963},{"batb":[[1,1.01,10.52],[2,1.01,0]],"batl":[[0,2.3,309.75],[1,2.3,0]],"ltp":0.0,"tv":0.0,"id":2309796}]}]}
{"op":"mcm","clk":"1005196680","pt":1580641418697,"mc":[{"id":"1.168219390","rc":[{"batb":[[0,2.14,22.98],[1,2.12,36.97],[2,2.1,24.16]],"batl":[[0,2.38,30.25],[1,2.84,228.62]],"ltp":0.0,"tv":0.0,"id":8535963},{"batb":[[1,1.73,57.13],[2,1.72,22.66]],"batl":[[0,1.9,42.01],[1,2.3,309.75]],"ltp":0.0,"tv":0.0,"id":2309796}]}]}
{"op":"mcm","clk":"1005202649","pt":1580641448209,"mc":[{"id":"1.168219390","rc":[{"batb":[[0,2.12,36.97],[1,2.1,24.16],[2,1.01,10.52]],"ltp":0.0,"tv":0.0,"id":8535963},{"batb":[[0,1.73,57.13],[1,1.72,22.66],[2,1.01,10.52]],"ltp":0.0,"tv":0.0,"id":2309796}]}]}
{"op":"mcm","clk":"1005202957","pt":1580641449824,"mc":[{"id":"1.168219390","rc":[{"batb":[[0,2.1,24.16],[1,1.01,10.52],[2,1.01,0]],"batl":[[0,2.84,228.62],[1,2.84,0]],"ltp":0.0,"tv":0.0,"id":8535963},{"batb":[[0,1.72,22.66],[1,1.01,10.52],[2,1.01,0]],"batl":[[0,2.3,309.75],[1,2.3,0]],"ltp":0.0,"tv":0.0,"id":2309796}]}]}
{"op":"mcm","clk":"1005207817","pt":1580641472741,"mc":[{"id":"1.168219390","rc":[{"batb":[[0,2.16,36.13],[1,2.1,24.16],[2,1.01,10.52]],"batl":[[0,2.46,28.57]],"ltp":0.0,"tv":0.0,"id":8535963},{"batb":[[1,1.7,59.65],[2,1.01,10.52]],"batl":[[0,1.86,42.01],[1,2.3,309.75]],"ltp":0.0,"tv":0.0,"id":2309796}]}]}
{"op":"mcm","clk":"1005208025","pt":1580641473753,"mc":[{"id":"1.168219390","rc":[{"batb":[[0,2.2,21.01],[1,2.16,58.63]],"ltp":0.0,"tv":0.0,"id":8535963},{"batb":[[2,1.68,24.94]],"ltp":0.0,"tv":0.0,"id":2309796}]}]}
{"op":"mcm","clk":"1005208393","pt":1580641475550,"mc":[{"id":"1.168219390","rc":[{"batl":[[1,3.15,200.42]],"ltp":0.0,"tv":0.0,"id":8535963}]}]}
{"op":"mcm","clk":"1005211144","pt":1580641490136,"mc":[{"id":"1.168219390","rc":[{"batb":[[0,2.16,22.5],[1,1.01,10.52],[2,1.01,0]],"batl":[[0,3.15,200.42],[1,3.15,0]],"ltp":0.0,"tv":0.0,"id":8535963},{"batb":[[0,1.68,24.94],[1,1.01,10.52],[2,1.68,0]],"batl":[[0,2.3,309.75],[1,2.3,0]],"ltp":0.0,"tv":0.0,"id":2309796}]}]}
{"op":"mcm","clk":"1005212496","pt":1580641497177,"mc":[{"id":"1.168219390","rc":[{"batb":[[1,2.14,36.13],[2,2.12,23.84]],"batl":[[0,2.42,29.41],[1,3.15,200.42]],"ltp":0.0,"tv":0.0,"id":8535963},{"batb":[[0,1.75,21.32],[1,1.7,23.53],[2,1.01,10.52]],"batl":[[0,1.88,42.01],[1,2.3,309.75]],"ltp":0.0,"tv":0.0,"id":2309796}]}]}
{"op":"mcm","clk":"1005212678","pt":1580641498188,"mc":[{"id":"1.168219390","rc":[{"batb":[[1,1.71,58.81],[2,1.7,23.53]],"ltp":0.0,"tv":0.0,"id":2309796}]}]}
{"op":"mcm","clk":"1005214847","pt":1580641508997,"mc":[{"id":"1.168219390","rc":[{"batb":[[0,2.14,36.13],[1,2.12,23.84],[2,1.01,10.52]],"ltp":0.0,"tv":0.0,"id":8535963},{"batb":[[0,1.71,58.81],[1,1.7,23.53],[2,1.01,10.52]],"ltp":0.0,"tv":0.0,"id":2309796}]}]}
{"op":"mcm","clk":"1005215033","pt":1580641509907,"mc":[{"id":"1.168219390","rc":[{"batb":[[0,2.12,23.84],[1,1.01,10.52],[2,1.01,0]],"batl":[[0,3.15,200.42],[1,3.15,0]],"ltp":0.0,"tv":0.0,"id":8535963},{"batb":[[0,1.7,23.53],[1,1.01,10.52],[2,1.01,0]],"batl":[[0,2.3,309.75],[1,2.3,0]],"ltp":0.0,"tv":0.0,"id":2309796}]}]}
{"op":"mcm","clk":"1005217903","pt":1580641523508,"mc":[{"id":"1.168219390","rc":[{"batb":[[1,2.08,24.86],[2,1.01,10.52]],"ltp":0.0,"tv":0.0,"id":8535963},{"batb":[[0,1.78,20.22],[1,1.73,22.19],[2,1.71,236.57]],"ltp":0.0,"tv":0.0,"id":2309796}]}]}
{"op":"mcm","clk":"1005217982","pt":1580641523928,"mc":[{"id":"1.168219390","rc":[{"batb":[[2,1.01,10.52]],"ltp":0.0,"tv":0.0,"id":2309796}]}]}
{"op":"mcm","clk":"1005218179","pt":1580641524881,"mc":[{"id":"1.168219390","rc":[{"batb":[[1,2.1,37.81],[2,2.08,24.86]],"batl":[[0,2.38,30.25]],"ltp":0.0,"tv":0.0,"id":8535963},{"batb":[[1,1.74,56.29],[2,1.73,22.19]],"batl":[[0,1.91,42.01],[1,2.3,309.75]],"ltp":0.0,"tv":0.0,"id":2309796}]}]}
{"op":"mcm","clk":"1005218400","pt":1580641526105,"mc":[{"id":"1.168219390","rc":[{"batl":[[1,3,213.45]],"ltp":0.0,"tv":0.0,"id":8535963}]}]}
{"op":"mcm","clk":"1005221248","pt":1580641539750,"mc":[{"id":"1.168219390","rc":[{"batb":[[0,2.1,37.81],[1,2.08,24.86],[2,1.01,10.52]],"ltp":0.0,"tv":0.0,"id":8535963},{"batb":[[0,1.74,56.29],[1,1.73,22.19],[2,1.01,10.52]],"ltp":0.0,"tv":0.0,"id":2309796}]}]}
{"op":"mcm","clk":"1005221331","pt":1580641540138,"mc":[{"id":"1.168219390","rc":[{"batb":[[0,2.08,24.86],[1,1.01,10.52],[2,1.01,0]],"batl":[[0,3,213.45],[1,3,0]],"ltp":0.0,"tv":0.0,"id":8535963},{"batb":[[0,1.73,22.19],[1,1.01,10.52],[2,1.01,0]],"batl":[[0,2.3,309.75],[1,2.3,0]],"ltp":0.0,"tv":0.0,"id":2309796}]}]}
{"op":"mcm","clk":"1005223761","pt":1580641551146,"mc":[{"id":"1.168219390","rc":[{"batb":[[0,2.08,63.51],[1,2.04,26.04],[2,1.01,10.52]],"batl":[[0,2.34,31.09],[1,3,213.45]],"ltp":0.0,"tv":0.0,"id":8535963},{"batb":[[0,1.81,19.36],[1,1.77,20.77],[2,1.75,55.45]],"batl":[[0,1.93,42.01],[1,2.3,309.75]],"ltp":0.0,"tv":0.0,"id":2309796}]}]}
{"op":"mcm","clk":"1005226309","pt":1580641562755,"mc":[{"id":"1.168219390","rc":[{"batb":[[0,2.08,38.65]],"ltp":0.0,"tv":0.0,"id":8535963},{"batb":[[0,1.77,20.77],[1,1.75,55.45],[2,1.01,10.52]],"ltp":0.0,"tv":0.0,"id":2309796}]}]}
{"op":"mcm","clk":"1005226563","pt":1580641563991,"mc":[{"id":"1.168219390","rc":[{"batb":[[0,2.04,26.04],[1,1.01,10.52],[2,1.01,0]],"batl":[[0,3,213.45],[1,3,0]],"ltp":0.0,"tv":0.0,"id":8535963},{"batb":[[1,1.01,10.52],[2,1.01,0]],"batl":[[0,2.3,309.75],[1,2.3,0]],"ltp":0.0,"tv":0.0,"id":2309796}]}]}
{"op":"mcm","clk":"1005227937","pt":1580641570098,"mc":[{"id":"1.168219390","rc":[{"batb":[[1,1.99,28.64],[2,1.01,10.52]],"ltp":0.0,"tv":0.0,"id":8535963},{"batb":[[0,1.83,18.57],[1,1.81,19.43],[2,1.01,10.52]],"ltp":0.0,"tv":0.0,"id":2309796}]}]}
{"op":"mcm","clk":"1005228124","pt":1580641570999,"mc":[{"id":"1.168219390","rc":[{"batb":[[0,2.04,66.37]],"batl":[[0,2.28,32.77]],"ltp":0.0,"tv":0.0,"id":8535963},{"batb":[[2,1.79,52.93]],"batl":[[0,1.97,42.01],[1,2.3,309.75]],"ltp":0.0,"tv":0.0,"id":2309796}]}]}
{"op":"mcm","clk":"1005228461","pt":1580641572619,"mc":[{"id":"1.168219390","rc":[{"batl":[[1,2.84,228.62]],"ltp":0.0,"tv":0.0,"id":8535963}]}]}
{"op":"mcm","clk":"1005244787","pt":1580641652631,"mc":[{"id":"1.168219390","rc":[{"batb":[[0,1.99,28.64],[1,1.01,10.52],[2,1.01,0]],"batl":[[0,2.84,228.62],[1,2.84,0]],"ltp":0.0,"tv":0.0,"id":8535963},{"batb":[[0,1.81,19.43],[1,1.01,10.52],[2,1.79,0]],"batl":[[0,2.3,309.75],[1,2.3,0]],"ltp":0.0,"tv":0.0,"id":2309796}]}]}
{"op":"mcm","clk":"1005250231","pt":1580641679465,"mc":[{"id":"1.168219390","rc":[{"batb":[[0,2.08,24.86],[1,2.06,39.49],[2,2.02,27.07]],"batl":[[0,2.32,31.09],[1,2.84,228.62]],"ltp":0.0,"tv":0.0,"id":8535963},{"batb":[[1,1.78,20.22],[2,1.77,53.77]],"batl":[[0,1.95,42.01],[1,2.3,309.75]],"ltp":0.0,"tv":0.0,"id":2309796}]}]}
{"op":"mcm","clk":"1005252933","pt":1580641693564,"mc":[{"id":"1.168219390","rc":[{"batb":[[0,2.06,39.49],[1,2.02,27.07],[2,1.01,10.52]],"ltp":0.0,"tv":0.0,"id":8535963},{"batb":[[0,1.78,20.22],[1,1.77,53.77],[2,1.01,10.52]],"ltp":0.0,"tv":0.0,"id":2309796}]}]}
{"op":"mcm","clk":"1005253024","pt":1580641694102,"mc":[{"id":"1.168219390","rc":[{"batb":[[0,2.02,27.07],[1,1.01,10.52],[2,1.01,0]],"batl":[[0,2.84,228.62],[1,2.84,0]],"ltp":0.0,"tv":0.0,"id":8535963},{"batb":[[1,1.01,10.52],[2,1.01,0]],"batl":[[0,2.3,309.75],[1,2.3,0]],"ltp":0.0,"tv":0.0,"id":2309796}]}]}
{"op":"mcm","clk":"1005256536","pt":1580641711698,"mc":[{"id":"1.168219390","rc":[{"batb":[[0,2.12,23.76],[1,2.08,38.65],[2,2.06,25.73]],"batl":[[0,2.34,31.09],[1,2.84,228.62]],"ltp":0.0,"tv":0.0,"id":8535963},{"batb":[[1,1.76,21.17],[2,1.75,55.45]],"batl":[[0,1.93,42.01],[1,2.3,309.75]],"ltp":0.0,"tv":0.0,"id":2309796}]}]}
{"op":"mcm","clk":"1005258762","pt":1580641722627,"mc":[{"id":"1.168219390","rc":[{"batb":[[0,2.08,38.65],[1,2.06,25.73],[2,1.01,10.52]],"ltp":0.0,"tv":0.0,"id":8535963},{"batb":[[0,1.76,21.17],[1,1.75,55.45],[2,1.01,10.52]],"ltp":0.0,"tv":0.0,"id":2309796}]}]}
{"op":"mcm","clk":"1005259036","pt":1580641724110,"mc":[{"id":"1.168219390","rc":[{"batb":[[0,2.06,25.73],[1,1.01,10.52],[2,1.01,0]],"batl":[[0,2.84,228.62],[1,2.84,0]],"ltp":0.0,"tv":0.0,"id":8535963},{"batb":[[1,1.01,10.52],[2,1.01,0]],"batl":[[0,2.3,309.75],[1,2.3,0]],"ltp":0.0,"tv":0.0,"id":2309796}]}]}
{"op":"mcm","clk":"1005262942","pt":1580641744587,"mc":[{"id":"1.168219390","rc":[{"batb":[[0,2.14,22.66],[1,2.08,24.71],[2,2.06,25.73]],"ltp":0.0,"tv":0.0,"id":8535963},{"batb":[[1,1.74,21.87],[2,1.01,10.52]],"ltp":0.0,"tv":0.0,"id":2309796}]}]}
{"op":"mcm","clk":"1005263098","pt":1580641745335,"mc":[{"id":"1.168219390","rc":[{"batb":[[1,2.1,37.81],[2,2.08,24.71]],"batl":[[0,2.38,30.25]],"ltp":0.0,"tv":0.0,"id":8535963},{"batb":[[1,1.74,78.17]],"batl":[[0,1.91,42.01],[1,2.3,309.75]],"ltp":0.0,"tv":0.0,"id":2309796}]}]}
{"op":"mcm","clk":"1005263270","pt":1580641746300,"mc":[{"id":"1.168219390","rc":[{"batl":[[1,3.15,200.42]],"ltp":0.0,"tv":0.0,"id":8535963}]}]}
{"op":"mcm","clk":"1005265311","pt":1580641756606,"mc":[{"id":"1.168219390","rc":[{"batb":[[0,2.08,24.71],[1,1.01,10.52],[2,2.08,0]],"batl":[[0,3.15,200.42],[1,3.15,0]],"ltp":0.0,"tv":0.0,"id":8535963},{"batb":[[0,1.74,21.87],[1,1.01,10.52],[2,1.01,0]],"batl":[[0,2.3,309.75],[1,2.3,0]],"ltp":0.0,"tv":0.0,"id":2309796}]}]}
{"op":"mcm","clk":"1005267266","pt":1580641766632,"mc":[{"id":"1.168219390","rc":[{"batb":[[0,2.18,21.87],[1,2.14,23.21],[2,1.01,10.52]],"ltp":0.0,"tv":0.0,"id":8535963},{"batb":[[1,1.69,24.08],[2,1.01,10.52]],"ltp":0.0,"tv":0.0,"id":2309796}]}]}
{"op":"mcm","clk":"1005267464","pt":1580641767425,"mc":[{"id":"1.168219390","rc":[{"batb":[[1,2.16,36.13],[2,2.14,23.21]],"batl":[[0,2.44,28.57],[1,3.15,200.42]],"ltp":0.0,"tv":0.0,"id":8535963},{"batb":[[1,1.7,59.65],[2,1.69,24.08]],"batl":[[0,1.87,42.01],[1,2.3,309.75]],"ltp":0.0,"tv":0.0,"id":2309796}]}]}
{"op":"mcm","clk":"1005272140","pt":1580641791646,"mc":[{"id":"1.168219390","rc":[{"batb":[[0,2.16,36.13],[1,2.14,23.21],[2,1.01,10.52]],"ltp":0.0,"tv":0.0,"id":8535963},{"batb":[[0,1.7,59.65],[1,1.69,24.08],[2,1.01,10.52]],"ltp":0.0,"tv":0.0,"id":2309796}]}]}
{"op":"mcm","clk":"1005272259","pt":1580641792209,"mc":[{"id":"1.168219390","rc":[{"batb":[[0,2.14,23.21],[1,1.01,10.52],[2,1.01,0]],"batl":[[0,3.15,200.42],[1,3.15,0]],"ltp":0.0,"tv":0.0,"id":8535963},{"batb":[[0,1.69,24.08],[1,1.01,10.52],[2,1.01,0]],"batl":[[0,2.3,309.75],[1,2.3,0]],"ltp":0.0,"tv":0.0,"id":2309796}]}]}
{"op":"mcm","clk":"1005275332","pt":1580641808755,"mc":[{"id":"1.168219390","rc":[{"batb":[[1,2.1,24.23],[2,1.01,10.52]],"ltp":0.0,"tv":0.0,"id":8535963},{"batb":[[0,1.77,20.77],[1,1.73,568.02],[2,1.72,22.98]],"ltp":0.0,"tv":0.0,"id":2309796}]}]}
{"op":"mcm","clk":"1005275393","pt":1580641809178,"mc":[{"id":"1.168219390","rc":[{"batb":[[1,2.12,36.97],[2,2.1,24.23]],"batl":[[0,2.4,29.41],[1,3.15,200.42]],"ltp":0.0,"tv":0.0,"id":8535963},{"batb":[[2,1.72,80.95]],"batl":[[0,1.89,42.01],[1,2.3,309.75]],"ltp":0.0,"tv":0.0,"id":2309796}]}]}
{"op":"mcm","clk":"1005278060","pt":1580641823453,"mc":[{"id":"1.168219390","rc":[{"batb":[[0,2.12,36.97],[1,2.1,24.23],[2,1.01,10.52]],"ltp":0.0,"tv":0.0,"id":8535963},{"batb":[[0,1.72,80.95],[1,1.01,10.52],[2,1.72,0]],"ltp":0.0,"tv":0.0,"id":2309796}]}]}
{"op":"mcm","clk":"1005278185","pt":1580641824180,"mc":[{"id":"1.168219390","rc":[{"batb":[[0,2.1,24.23],[1,1.01,10.52],[2,1.01,0]],"batl":[[0,3.15,200.42],[1,3.15,0]],"ltp":0.0,"tv":0.0,"id":8535963},{"batb":[[0,1.72,22.98]],"batl":[[0,2.3,309.75],[1,2.3,0]],"ltp":0.0,"tv":0.0,"id":2309796}]}]}
{"op":"mcm","clk":"1005279820","pt":1580641833130,"mc":[{"id":"1.168219390","rc":[{"batb":[[0,2.1,62.04],[1,2.06,25.57],[2,1.01,10.52]],"batl":[[0,2.38,30.25]],"ltp":0.0,"tv":0.0,"id":8535963},{"batb":[[0,1.79,19.91],[1,1.75,21.56],[2,1.74,56.29]],"batl":[[0,1.91,42.01],[1,2.3,309.75]],"ltp":0.0,"tv":0.0,"id":2309796}]}]}
{"op":"mcm","clk":"1005280090","pt":1580641834530,"mc":[{"id":"1.168219390","rc":[{"batl":[[1,3,213.45]],"ltp":0.0,"tv":0.0,"id":8535963}]}]}
{"op":"mcm","clk":"1005280719","pt":1580641837936,"mc":[{"id":"1.168219390","rc":[{"batb":[[1,1.75,572.95]],"ltp":0.0,"tv":0.0,"id":2309796}]}]}
{"op":"mcm","clk":"1005282777","pt":1580641848674,"mc":[{"id":"1.168219390","rc":[{"batb":[[1,1.75,21.56]],"ltp":0.0,"tv":0.0,"id":2309796}]}]}
{"op":"mcm","clk":"1005282913","pt":1580641849357,"mc":[{"id":"1.168219390","rc":[{"batb":[[0,2.1,37.81]],"ltp":0.0,"tv":0.0,"id":8535963},{"batb":[[0,1.75,21.56],[1,1.74,56.29],[2,1.01,10.52]],"ltp":0.0,"tv":0.0,"id":2309796}]}]}
{"op":"mcm","clk":"1005283069","pt":1580641850165,"mc":[{"id":"1.168219390","rc":[{"batb":[[0,2.06,25.57],[1,1.01,10.52],[2,1.01,0]],"batl":[[0,3,213.45],[1,3,0]],"ltp":0.0,"tv":0.0,"id":8535963},{"batb":[[1,1.01,10.52],[2,1.01,0]],"batl":[[0,2.3,309.75],[1,2.3,0]],"ltp":0.0,"tv":0.0,"id":2309796}]}]}
{"op":"mcm","clk":"1005284137","pt":1580641855721,"mc":[{"id":"1.168219390","rc":[{"batb":[[0,2.08,38.65],[1,2.06,25.57],[2,2.02,26.83]],"batl":[[0,2.34,31.09],[1,3,213.45]],"ltp":0.0,"tv":0.0,"id":8535963},{"batb":[[0,1.82,18.88],[1,1.77,20.61],[2,1.76,54.61]],"batl":[[0,1.93,42.01],[1,2.3,309.75]],"ltp":0.0,"tv":0.0,"id":2309796}]}]}
{"op":"mcm","clk":"1005285466","pt":1580641862722,"mc":[{"id":"1.168219390","rc":[{"batb":[[1,2.02,26.83],[2,1.01,10.52]],"ltp":0.0,"tv":0.0,"id":8535963},{"batb":[[0,1.77,20.61],[1,1.76,54.61],[2,1.01,10.52]],"ltp":0.0,"tv":0.0,"id":2309796}]}]}
{"op":"mcm","clk":"1005285741","pt":1580641864217,"mc":[{"id":"1.168219390","rc":[{"batb":[[0,2.02,26.83],[1,1.01,10.52],[2,1.01,0]],"batl":[[0,3,213.45],[1,3,0]],"ltp":0.0,"tv":0.0,"id":8535963},{"batb":[[1,1.01,10.52],[2,1.01,0]],"batl":[[0,2.3,309.75],[1,2.3,0]],"ltp":0.0,"tv":0.0,"id":2309796}]}]}
{"op":"mcm","clk":"1005292681","pt":1580641901239,"mc":[{"id":"1.168219390","rc":[{"batb":[[0,2.02,68]],"batl":[[0,2.28,32.77]],"ltp":0.0,"tv":0.0,"id":8535963},{"batb":[[0,1.79,52.93],[1,1.77,20.61],[2,1.01,10.52]],"batl":[[0,1.98,42.01],[1,2.3,309.75]],"ltp":0.0,"tv":0.0,"id":2309796}]}]}
{"op":"mcm","clk":"1005292889","pt":1580641902363,"mc":[{"id":"1.168219390","rc":[{"batb":[[1,1.97,29.51],[2,1.01,10.52]],"ltp":0.0,"tv":0.0,"id":8535963},{"batb":[[0,1.85,18.02],[1,1.82,19.12],[2,1.79,52.93]],"ltp":0.0,"tv":0.0,"id":2309796}]}]}
{"op":"mcm","clk":"1005293240","pt":1580641904163,"mc":[{"id":"1.168219390","rc":[{"batl":[[1,2.84,228.62]],"ltp":0.0,"tv":0.0,"id":8535963}]}]}
{"op":"mcm","clk":"1005294469","pt":1580641909980,"mc":[{"id":"1.168219390","rc":[{"batb":[[0,2.04,26.59],[1,2.02,41.17],[2,1.98,29.27]],"ltp":0.0,"tv":0.0,"id":8535963},{"batb":[[0,1.84,18.18],[1,1.81,19.28]],"ltp":0.0,"tv":0.0,"id":2309796}]}]}
{"op":"mcm","clk":"1005296167","pt":1580641918692,"mc":[{"id":"1.168219390","rc":[{"batb":[[0,2.04,26.28],[2,1.98,28.95]],"ltp":0.0,"tv":0.0,"id":8535963},{"batb":[[1,1.8,19.43]],"ltp":0.0,"tv":0.0,"id":2309796}]}]}
{"op":"mcm","clk":"1005297579","pt":1580641926553,"mc":[{"id":"1.168219390","rc":[{"batb":[[0,2.04,26.04],[2,1.99,28.64]],"ltp":0.0,"tv":0.0,"id":8535963},{"batb":[[0,1.83,18.57]],"ltp":0.0,"tv":0.0,"id":2309796}]}]}
{"op":"mcm","clk":"1005301634","pt":1580641950691,"mc":[{"id":"1.168219390","rc":[{"batb":[[0,2.06,25.81],[1,2.04,26.04],[2,2.02,41.17]],"ltp":0.0,"tv":0.0,"id":8535963},{"batb":[[2,1.79,72.76]],"ltp":0.0,"tv":0.0,"id":2309796}]}]}
{"op":"mcm","clk":"1005301768","pt":1580641951694,"mc":[{"id":"1.168219390","rc":[{"batb":[[1,2.02,41.17],[2,2,28.33]],"ltp":0.0,"tv":0.0,"id":8535963},{"batb":[[1,1.79,72.76],[2,1.75,541.59]],"ltp":0.0,"tv":0.0,"id":2309796}]}]}
{"op":"mcm","clk":"1005307541","pt":1580641985450,"mc":[{"id":"1.168219390","rc":[{"batb":[[0,2.02,41.17],[1,2,28.33],[2,1.01,10.52]],"ltp":0.0,"tv":0.0,"id":8535963},{"batb":[[0,1.79,72.76],[1,1.01,10.52],[2,1.75,0]],"ltp":0.0,"tv":0.0,"id":2309796}]}]}
{"op":"mcm","clk":"1005307693","pt":1580641986254,"mc":[{"id":"1.168219390","rc":[{"batb":[[0,2,28.33],[1,1.01,10.52],[2,1.01,0]],"batl":[[0,2.84,228.62],[1,2.84,0]],"ltp":0.0,"tv":0.0,"id":8535963},{"batb":[[0,1.79,19.83]],"batl":[[0,2.3,309.75],[1,2.3,0]],"ltp":0.0,"tv":0.0,"id":2309796}]}]}
{"op":"mcm","clk":"1005309568","pt":1580641996436,"mc":[{"id":"1.168219390","rc":[{"batb":[[1,1.93,15.82],[2,1.01,10.52]],"ltp":0.0,"tv":0.0,"id":8535963},{"batb":[[0,1.88,17.07],[1,1.85,18.1],[2,1.01,10.52]],"ltp":0.0,"tv":0.0,"id":2309796}]}]}
{"op":"mcm","clk":"1005309776","pt":1580641997641,"mc":[{"id":"1.168219390","rc":[{"batb":[[1,1.99,42.01],[2,1.93,15.82]],"ltp":0.0,"tv":0.0,"id":8535963},{"batb":[[2,1.82,50.41]],"batl":[[0,2,42.01],[1,2.3,309.75]],"ltp":0.0,"tv":0.0,"id":2309796}]}]}
{"op":"mcm","clk":"1005309946","pt":1580641998745,"mc":[{"id":"1.168219390","rc":[{"batl":[[0,2.22,33.61],[1,2.7,245.56]],"ltp":0.0,"tv":0.0,"id":8535963}]}]}
{"op":"mcm","clk":"1005311335","pt":1580642006742,"mc":[{"id":"1.168219390","rc":[{"batb":[[0,1.99,42.01],[1,1.93,15.82],[2,1.01,10.52]],"ltp":0.0,"tv":0.0,"id":8535963},{"batb":[[0,1.85,18.1],[1,1.82,50.41],[2,1.01,10.52]],"ltp":0.0,"tv":0.0,"id":2309796}]}]}
{"op":"mcm","clk":"1005311687","pt":1580642008636,"mc":[{"id":"1.168219390","rc":[{"batb":[[0,1.93,15.82],[1,1.01,10.52],[2,1.01,0]],"batl":[[0,2.7,245.56],[1,2.7,0]],"ltp":0.0,"tv":0.0,"id":8535963},{"batb":[[1,1.01,10.52],[2,1.01,0]],"batl":[[0,2.3,309.75],[1,2.3,0]],"ltp":0.0,"tv":0.0,"id":2309796}]}]}
{"op":"mcm","clk":"1005311930","pt":1580642010175,"mc":[{"id":"1.168219390","rc":[{"batb":[[0,1.94,15.5]],"ltp":0.0,"tv":0.0,"id":8535963},{"batb":[[0,1.83,18.65]],"ltp":0.0,"tv":0.0,"id":2309796}]}]}
{"op":"mcm","clk":"1005313826","pt":1580642021592,"mc":[{"id":"1.168219390","rc":[{"batb":[[0,1.94,60.03],[1,1.87,17.31],[2,1.01,10.52]],"ltp":0.0,"tv":0.0,"id":8535963},{"batb":[[0,1.93,15.66],[1,1.89,16.68],[2,1.86,48.73]],"batl":[[0,2.06,39.49]],"ltp":0.0,"tv":0.0,"id":2309796}]}]}
{"op":"mcm","clk":"1005314184","pt":1580642023657,"mc":[{"id":"1.168219390","rc":[{"batl":[[0,2.16,36.13],[1,2.7,245.56]],"ltp":0.0,"tv":0.0,"id":8535963}]}]}
{"op":"mcm","clk":"1005314231","pt":1580642023982,"mc":[{"id":"1.168219390","rc":[{"batl":[[1,2.6,257.57]],"ltp":0.0,"tv":0.0,"id":2309796}]}]}
{"op":"mcm","clk":"1005315932","pt":1580642033621,"mc":[{"id":"1.168219390","rc":[{"batb":[[0,1.94,44.53]],"ltp":0.0,"tv":0.0,"id":8535963},{"batb":[[0,1.89,16.68],[1,1.86,48.73],[2,1.01,10.52]],"ltp":0.0,"tv":0.0,"id":2309796}]}]}
{"op":"mcm","clk":"1005316054","pt":1580642034318,"mc":[{"id":"1.168219390","rc":[{"batb":[[0,1.87,17.31],[1,1.01,10.52],[2,1.01,0]],"batl":[[0,2.7,245.56],[1,2.7,0]],"ltp":0.0,"tv":0.0,"id":8535963},{"batb":[[1,1.01,10.52],[2,1.01,0]],"batl":[[0,2.6,257.57],[1,2.6,0]],"ltp":0.0,"tv":0.0,"id":2309796}]}]}
{"op":"mcm","clk":"1005317445","pt":1580642041687,"mc":[{"id":"1.168219390","rc":[{"batb":[[0,1.98,29.03],[1,1.91,16.29],[2,1.87,17.31]],"batl":[[0,2.2,34.45],[1,2.7,245.56]],"ltp":0.0,"tv":0.0,"id":8535963},{"batb":[[1,1.85,66.59],[2,1.01,10.52]],"batl":[[0,2.04,40.33],[1,2.6,257.57]],"ltp":0.0,"tv":0.0,"id":2309796}]}]}
{"op":"mcm","clk":"1005317478","pt":1580642041896,"mc":[{"id":"1.168219390","rc":[{"batb":[[2,1.01,10.52]],"ltp":0.0,"tv":0.0,"id":8535963}]}]}
{"op":"mcm","clk":"1005317919","pt":1580642044235,"mc":[{"id":"1.168219390","rc":[{"batb":[[1,1.96,43.69],[2,1.91,16.29]],"ltp":0.0,"tv":0.0,"id":8535963}]}]}
{"op":"mcm","clk":"1005319390","pt":1580642051757,"mc":[{"id":"1.168219390","rc":[{"batb":[[0,1.96,43.69],[1,1.91,16.29],[2,1.01,10.52]],"ltp":0.0,"tv":0.0,"id":8535963},{"batb":[[0,1.85,66.59],[1,1.01,10.52],[2,1.01,0]],"ltp":0.0,"tv":0.0,"id":2309796}]}]}
{"op":"mcm","clk":"1005319585","pt":1580642052735,"mc":[{"id":"1.168219390","rc":[{"batb":[[0,1.91,16.29],[1,1.01,10.52],[2,1.01,0]],"batl":[[0,2.7,245.56],[1,2.7,0]],"ltp":0.0,"tv":0.0,"id":8535963},{"batb":[[0,1.85,17.86]],"batl":[[0,2.6,257.57],[1,2.6,0]],"ltp":0.0,"tv":0.0,"id":2309796}]}]}
{"op":"mcm","clk":"1005324592","pt":1580642080650,"mc":[{"id":"1.168219390","rc":[{"batb":[[1,1.83,18.57],[2,1.01,10.52]],"ltp":0.0,"tv":0.0,"id":8535963},{"batb":[[0,1.97,29.74],[1,1.93,15.74],[2,1.01,10.52]],"ltp":0.0,"tv":0.0,"id":2309796}]}]}
{"op":"mcm","clk":"1005324788","pt":1580642081756,"mc":[{"id":"1.168219390","rc":[{"batb":[[0,1.92,45.37],[1,1.91,16.29],[2,1.83,18.57]],"batl":[[0,2.14,36.13],[1,2.7,245.56]],"ltp":0.0,"tv":0.0,"id":8535963},{"batb":[[2,1.89,47.05]],"batl":[[0,2.08,38.65],[1,2.6,257.57]],"ltp":0.0,"tv":0.0,"id":2309796}]}]}
{"op":"mcm","clk":"1005328902","pt":1580642104712,"mc":[{"id":"1.168219390","rc":[{"batb":[[0,1.83,18.57],[1,1.01,10.52],[2,1.83,0]],"batl":[[0,2.7,245.56],[1,2.7,0]],"ltp":0.0,"tv":0.0,"id":8535963},{"batb":[[0,1.93,15.74],[1,1.01,10.52],[2,1.89,0]],"batl":[[0,2.6,257.57],[1,2.6,0]],"ltp":0.0,"tv":0.0,"id":2309796}]}]}
{"op":"mcm","clk":"1005334575","pt":1580642136281,"mc":[{"id":"1.168219390","rc":[{"batb":[[1,1.8,19.75],[2,1.01,10.52]],"ltp":0.0,"tv":0.0,"id":8535963},{"batb":[[0,2.04,26.04],[1,1.98,29.11],[2,1.01,10.52]],"ltp":0.0,"tv":0.0,"id":2309796}]}]}
{"op":"mcm","clk":"1005334767","pt":1580642137245,"mc":[{"id":"1.168219390","rc":[{"batb":[[1,1.82,50.41],[2,1.8,19.75]],"batl":[[0,2,42.01]],"ltp":0.0,"tv":0.0,"id":8535963},{"batb":[[1,1.99,42.01],[2,1.98,29.11]],"batl":[[0,2.24,33.61],[1,2.6,257.57]],"ltp":0.0,"tv":0.0,"id":2309796}]}]}
{"op":"mcm","clk":"1005334874","pt":1580642137976,"mc":[{"id":"1.168219390","rc":[{"batl":[[1,2.52,270.1]],"ltp":0.0,"tv":0.0,"id":8535963}]}]}
{"op":"mcm","clk":"1005341057","pt":1580642172983,"mc":[{"id":"1.168219390","rc":[{"batb":[[0,1.82,50.41],[1,1.8,19.75],[2,1.01,10.52]],"ltp":0.0,"tv":0.0,"id":8535963},{"batb":[[0,1.99,42.01],[1,1.98,29.11],[2,1.01,10.52]],"ltp":0.0,"tv":0.0,"id":2309796}]}]}
{"op":"mcm","clk":"1005341309","pt":1580642174415,"mc":[{"id":"1.168219390","rc":[{"batb":[[0,1.8,19.75],[1,1.01,10.52],[2,1.01,0]],"batl":[[0,2.52,270.1],[1,2.52,0]],"ltp":0.0,"tv":0.0,"id":8535963},{"batb":[[0,1.98,29.11],[1,1.01,10.52],[2,1.01,0]],"batl":[[0,2.6,257.57],[1,2.6,0]],"ltp":0.0,"tv":0.0,"id":2309796}]}]}
{"op":"mcm","clk":"1005341725","pt":1580642176312,"mc":[{"id":"1.168219390","rc":[{"batb":[[0,1.79,19.83]],"ltp":0.0,"tv":0.0,"id":8535963},{"batb":[[0,1.98,28.95]],"ltp":0.0,"tv":0.0,"id":2309796}]}]}
{"op":"mcm","clk":"1005345635","pt":1580642196739,"mc":[{"id":"1.168219390","rc":[{"batb":[[1,1.76,20.93],[2,1.01,10.52]],"ltp":0.0,"tv":0.0,"id":8535963},{"batb":[[0,2.1,24.31],[1,2.02,26.99],[2,1.98,28.95]],"ltp":0.0,"tv":0.0,"id":2309796}]}]}
{"op":"mcm","clk":"1005345761","pt":1580642197454,"mc":[{"id":"1.168219390","rc":[{"batb":[[0,1.79,72.76]],"batl":[[0,1.98,42.01]],"ltp":0.0,"tv":0.0,"id":8535963},{"batb":[[1,2.02,68.16],[2,1.01,10.52]],"batl":[[0,2.28,32.77],[1,2.6,257.57]],"ltp":0.0,"tv":0.0,"id":2309796}]}]}
{"op":"mcm","clk":"1005345955","pt":1580642198544,"mc":[{"id":"1.168219390","rc":[{"batl":[[1,2.4,289.78]],"ltp":0.0,"tv":0.0,"id":8535963}]}]}
{"op":"mcm","clk":"1005348088","pt":1580642210398,"mc":[{"id":"1.168219390","rc":[{"batb":[[0,1.76,20.93],[1,1.01,10.52],[2,1.01,0]],"batl":[[0,2.4,289.78],[1,2.4,0]],"ltp":0.0,"tv":0.0,"id":8535963},{"batb":[[0,2.02,26.99],[1,1.01,10.52],[2,1.01,0]],"batl":[[0,2.6,257.57],[1,2.6,0]],"ltp":0.0,"tv":0.0,"id":2309796}]}]}
{"op":"mcm","clk":"1005348634","pt":1580642213683,"mc":[{"id":"1.168219390","rc":[{"batb":[[0,1.75,21.4]],"ltp":0.0,"tv":0.0,"id":8535963},{"batb":[[0,2.04,26.44]],"ltp":0.0,"tv":0.0,"id":2309796}]}]}
{"op":"mcm","clk":"1005355730","pt":1580642252684,"mc":[{"id":"1.168219390","rc":[{"batb":[[0,1.84,18.33],[1,1.81,19.2],[2,1.01,10.52]],"ltp":0.0,"tv":0.0,"id":8535963},{"batb":[[1,1.96,30.06],[2,1.01,10.52]],"ltp":0.0,"tv":0.0,"id":2309796}]}]}
{"op":"mcm","clk":"1005355860","pt":1580642253423,"mc":[{"id":"1.168219390","rc":[{"batb":[[1,1.81,70.45]],"batl":[[0,2.02,41.17],[1,2.4,289.78]],"ltp":0.0,"tv":0.0,"id":8535963},{"batb":[[1,2,42.01],[2,1.96,30.06]],"batl":[[0,2.22,33.61],[1,2.6,257.57]],"ltp":0.0,"tv":0.0,"id":2309796}]}]}
{"op":"mcm","clk":"1005358849","pt":1580642269258,"mc":[{"id":"1.168219390","rc":[{"batb":[[1,1.81,19.2]],"ltp":0.0,"tv":0.0,"id":8535963},{"batb":[[1,1.96,30.06],[2,1.01,10.52]],"ltp":0.0,"tv":0.0,"id":2309796}]}]}
{"op":"mcm","clk":"1005359478","pt":1580642272385,"mc":[{"id":"1.168219390","rc":[{"batb":[[1,1.82,50.41],[2,1.81,19.2]],"ltp":0.0,"tv":0.0,"id":8535963},{"batb":[[1,1.99,42.01],[2,1.96,30.06]],"ltp":0.0,"tv":0.0,"id":2309796}]}]}
{"op":"mcm","clk":"1005360022","pt":1580642275306,"mc":[{"id":"1.168219390","rc":[{"batb":[[0,1.82,50.41],[1,1.81,19.2],[2,1.01,10.52]],"ltp":0.0,"tv":0.0,"id":8535963},{"batb":[[0,1.99,42.01],[1,1.96,30.06],[2,1.01,10.52]],"ltp":0.0,"tv":0.0,"id":2309796}]}]}
{"op":"mcm","clk":"1005360263","pt":1580642276530,"mc":[{"id":"1.168219390","rc":[{"batb":[[0,1.81,19.2],[1,1.01,10.52],[2,1.01,0]],"batl":[[0,2.4,289.78],[1,2.4,0]],"ltp":0.0,"tv":0.0,"id":8535963},{"batb":[[0,1.96,30.06],[1,1.01,10.52],[2,1.01,0]],"batl":[[0,2.6,257.57],[1,2.6,0]],"ltp":0.0,"tv":0.0,"id":2309796}]}]}
{"op":"mcm","clk":"1005360647","pt":1580642278435,"mc":[{"id":"1.168219390","rc":[{"batb":[[0,1.8,19.59]],"ltp":0.0,"tv":0.0,"id":8535963},{"batb":[[0,1.97,29.35]],"ltp":0.0,"tv":0.0,"id":2309796}]}]}
{"op":"mcm","clk":"1005361649","pt":1580642283756,"mc":[{"id":"1.168219390","rc":[{"batb":[[0,1.9,16.52],[1,1.86,66.36],[2,1.01,10.52]],"batl":[[0,2.06,39.49],[1,2.4,289.78]],"ltp":0.0,"tv":0.0,"id":8535963},{"batb":[[1,1.95,43.69],[2,1.9,16.52]],"batl":[[0,2.16,36.13],[1,2.6,257.57]],"ltp":0.0,"tv":0.0,"id":2309796}]}]}
{"op":"mcm","clk":"1005365739","pt":1580642304526,"mc":[{"id":"1.168219390","rc":[{"batb":[[0,1.86,17.62],[1,1.01,10.52],[2,1.01,0]],"batl":[[0,2.4,289.78],[1,2.4,0]],"ltp":0.0,"tv":0.0,"id":8535963},{"batb":[[0,1.9,16.52],[1,1.01,10.52],[2,1.9,0]],"batl":[[0,2.6,257.57],[1,2.6,0]],"ltp":0.0,"tv":0.0,"id":2309796}]}]}
{"op":"mcm","clk":"1005369277","pt":1580642323505,"mc":[{"id":"1.168219390","rc":[{"batb":[[1,1.85,48.73],[2,1.82,18.8]],"batl":[[0,2.04,40.33],[1,2.4,289.78]],"ltp":0.0,"tv":0.0,"id":8535963},{"batb":[[0,2.02,27.22],[1,1.96,43.69],[2,1.94,15.5]],"batl":[[0,2.18,35.29],[1,2.6,257.57]],"ltp":0.0,"tv":0.0,"id":2309796}]}]}
{"op":"mcm","clk":"1005373693","pt":1580642345582,"mc":[{"id":"1.168219390","rc":[{"batb":[[0,1.85,48.73],[1,1.82,18.8],[2,1.01,10.52]],"ltp":0.0,"tv":0.0,"id":8535963},{"batb":[[0,1.96,43.69],[1,1.94,15.5],[2,1.01,10.52]],"ltp":0.0,"tv":0.0,"id":2309796}]}]}
{"op":"mcm","clk":"1005373900","pt":1580642346559,"mc":[{"id":"1.168219390","rc":[{"batb":[[0,1.82,18.8],[1,1.01,10.52],[2,1.01,0]],"batl":[[0,2.4,289.78],[1,2.4,0]],"ltp":0.0,"tv":0.0,"id":8535963},{"batb":[[0,1.94,15.5],[1,1.01,10.52],[2,1.01,0]],"batl":[[0,2.6,257.57],[1,2.6,0]],"ltp":0.0,"tv":0.0,"id":2309796}]}]}
{"op":"mcm","clk":"1005376006","pt":1580642357755,"mc":[{"id":"1.168219390","rc":[{"batb":[[0,1.93,15.66],[1,1.89,47.05],[2,1.88,17]],"batl":[[0,2.08,38.65],[1,2.4,289.78]],"ltp":0.0,"tv":0.0,"id":8535963},{"batb":[[1,1.93,44.53],[2,1.86,17.7]],"batl":[[0,2.14,36.13],[1,2.6,257.57]],"ltp":0.0,"tv":0.0,"id":2309796}]}]}
{"op":"mcm","clk":"1005379546","pt":1580642376614,"mc":[{"id":"1.168219390","rc":[{"batb":[[0,1.88,17],[1,1.01,10.52],[2,1.88,0]],"batl":[[0,2.4,289.78],[1,2.4,0]],"ltp":0.0,"tv":0.0,"id":8535963},{"batb":[[0,1.86,17.7],[1,1.01,10.52],[2,1.86,0]],"batl":[[0,2.6,257.57],[1,2.6,0]],"ltp":0.0,"tv":0.0,"id":2309796}]}]}
{"op":"mcm","clk":"1005380110","pt":1580642379753,"mc":[{"id":"1.168219390","rc":[{"batb":[[0,1.89,16.92]],"ltp":0.0,"tv":0.0,"id":8535963}]}]}
{"op":"mcm","clk":"1005381212","pt":1580642385555,"mc":[{"id":"1.168219390","rc":[{"batb":[[1,1.87,47.89],[2,1.85,18.02]],"batl":[[0,2.08,38.65],[1,2.4,289.78]],"ltp":0.0,"tv":0.0,"id":8535963},{"batb":[[0,1.99,28.64],[1,1.95,43.69],[2,1.91,16.21]],"batl":[[0,2.16,36.13],[1,2.6,257.57]],"ltp":0.0,"tv":0.0,"id":2309796}]}]}
{"op":"mcm","clk":"1005381267","pt":1580642385888,"mc":[{"id":"1.168219390","rc":[{"batl":[[0,2.4,289.78],[1,2.4,0]],"ltp":0.0,"tv":0.0,"id":8535963}]}]}
{"op":"mcm","clk":"1005381902","pt":1580642389472,"mc":[{"id":"1.168219390","rc":[{"batl":[[0,2.06,39.49],[1,2.4,289.78]],"ltp":0.0,"tv":0.0,"id":8535963}]}]}
{"op":"mcm","clk":"1005383937","pt":1580642400593,"mc":[{"id":"1.168219390","rc":[{"batb":[[0,1.85,18.02],[1,1.01,10.52],[2,1.85,0]],"batl":[[0,2.4,289.78],[1,2.4,0]],"ltp":0.0,"tv":0.0,"id":8535963},{"batb":[[0,1.91,16.21],[1,1.01,10.52],[2,1.91,0]],"batl":[[0,2.6,257.57],[1,2.6,0]],"ltp":0.0,"tv":0.0,"id":2309796}]}]}
{"op":"mcm","clk":"1005390663","pt":1580642436760,"mc":[{"id":"1.168219390","rc":[{"batb":[[0,1.96,29.98],[1,1.91,16.21],[2,1.01,10.52]],"ltp":0.0,"tv":0.0,"id":8535963},{"batb":[[1,1.83,18.73],[2,1.01,10.52]],"ltp":0.0,"tv":0.0,"id":2309796}]}]}
{"op":"mcm","clk":"1005390785","pt":1580642437491,"mc":[{"id":"1.168219390","rc":[{"batb":[[2,1.9,46.21]],"batl":[[0,2.1,37.81]],"ltp":0.0,"tv":0.0,"id":8535963},{"batb":[[1,1.9,46.21],[2,1.83,18.73]],"batl":[[0,2.12,36.97],[1,2.6,257.57]],"ltp":0.0,"tv":0.0,"id":2309796}]}]}
{"op":"mcm","clk":"1005391049","pt":1580642438860,"mc":[{"id":"1.168219390","rc":[{"batl":[[1,2.7,245.56]],"ltp":0.0,"tv":0.0,"id":8535963}]}]}
{"op":"mcm","clk":"1005394692","pt":1580642458578,"mc":[{"id":"1.168219390","rc":[{"batb":[[0,1.91,16.21],[1,1.01,10.52],[2,1.9,0]],"batl":[[0,2.7,245.56],[1,2.7,0]],"ltp":0.0,"tv":0.0,"id":8535963},{"batb":[[0,1.83,18.73],[1,1.01,10.52],[2,1.83,0]],"batl":[[0,2.6,257.57],[1,2.6,0]],"ltp":0.0,"tv":0.0,"id":2309796}]}]}
{"op":"mcm","clk":"1005396609","pt":1580642469560,"mc":[{"id":"1.168219390","rc":[{"batb":[[0,2.02,41.17],[1,1.91,16.21],[2,1.01,10.52]],"batl":[[0,2.26,32.77],[1,2.7,245.56]],"ltp":0.0,"tv":0.0,"id":8535963},{"batb":[[1,1.8,52.09],[2,1.01,10.52]],"batl":[[0,1.99,42.01],[1,2.6,257.57]],"ltp":0.0,"tv":0.0,"id":2309796}]}]}
{"op":"mcm","clk":"1005396819","pt":1580642470632,"mc":[{"id":"1.168219390","rc":[{"batb":[[0,2.06,25.89],[1,2.02,41.17],[2,1.99,28.8]],"ltp":0.0,"tv":0.0,"id":8535963},{"batb":[[2,1.79,19.83]],"ltp":0.0,"tv":0.0,"id":2309796}]}]}
{"op":"mcm","clk":"1005400808","pt":1580642493478,"mc":[{"id":"1.168219390","rc":[{"batb":[[0,2.06,25.73]],"ltp":0.0,"tv":0.0,"id":8535963}]}]}
{"op":"mcm","clk":"1005402740","pt":1580642504344,"mc":[{"id":"1.168219390","rc":[{"batb":[[0,2.06,25.49],[2,2,28.4]],"ltp":0.0,"tv":0.0,"id":8535963},{"batb":[[0,1.82,18.96]],"ltp":0.0,"tv":0.0,"id":2309796}]}]}
{"op":"mcm","clk":"1005405808","pt":1580642521410,"mc":[{"id":"1.168219390","rc":[{"batl":[[0,2.6,257.57],[1,2.6,0]],"ltp":0.0,"tv":0.0,"id":2309796}]}]}
{"op":"mcm","clk":"1005406400","pt":1580642524753,"mc":[{"id":"1.168219390","rc":[{"batl":[[0,1.98,42.01],[1,2.6,257.57]],"ltp":0.0,"tv":0.0,"id":2309796}]}]}
{"op":"mcm","clk":"1005406461","pt":1580642525024,"mc":[{"id":"1.168219390","rc":[{"batb":[[2,1.78,20.22]],"ltp":0.0,"tv":0.0,"id":2309796}]}]}
{"op":"mcm","clk":"1005411505","pt":1580642551476,"mc":[{"id":"1.168219390","rc":[{"batb":[[0,2.02,41.17],[1,2,28.4],[2,1.01,10.52]],"ltp":0.0,"tv":0.0,"id":8535963},{"batb":[[0,1.8,52.09],[1,1.78,20.22],[2,1.01,10.52]],"ltp":0.0,"tv":0.0,"id":2309796}]}]}
{"op":"mcm","clk":"1005411727","pt":1580642552580,"mc":[{"id":"1.168219390","rc":[{"batb":[[0,2,28.4],[1,1.01,10.52],[2,1.01,0]],"batl":[[0,2.7,245.56],[1,2.7,0]],"ltp":0.0,"tv":0.0,"id":8535963},{"batb":[[0,1.78,20.22],[1,1.01,10.52],[2,1.01,0]],"batl":[[0,2.6,257.57],[1,2.6,0]],"ltp":0.0,"tv":0.0,"id":2309796}]}]}
{"op":"mcm","clk":"1005415412","pt":1580642571587,"mc":[{"id":"1.168219390","rc":[{"batb":[[0,2.06,39.49],[1,2,28.4],[2,1.01,10.52]],"batl":[[0,2.3,31.93],[1,2.7,245.56]],"ltp":0.0,"tv":0.0,"id":8535963},{"batb":[[0,1.78,73.99]],"batl":[[0,1.96,42.01]],"ltp":0.0,"tv":0.0,"id":2309796}]}]}
{"op":"mcm","clk":"1005415572","pt":1580642572404,"mc":[{"id":"1.168219390","rc":[{"batb":[[0,2.12,23.84],[1,2.06,39.49],[2,2.04,26.59]],"ltp":0.0,"tv":0.0,"id":8535963},{"batb":[[1,1.76,21.24],[2,1.01,10.52]],"ltp":0.0,"tv":0.0,"id":2309796}]}]}
{"op":"mcm","clk":"1005415939","pt":1580642574153,"mc":[{"id":"1.168219390","rc":[{"batl":[[1,2.4,289.78]],"ltp":0.0,"tv":0.0,"id":2309796}]}]}
{"op":"mcm","clk":"1005418339","pt":1580642586583,"mc":[{"id":"1.168219390","rc":[{"batb":[[0,2.04,26.59],[1,1.01,10.52],[2,2.04,0]],"batl":[[0,2.7,245.56],[1,2.7,0]],"ltp":0.0,"tv":0.0,"id":8535963},{"batb":[[0,1.76,21.24],[1,1.01,10.52],[2,1.01,0]],"batl":[[0,2.4,289.78],[1,2.4,0]],"ltp":0.0,"tv":0.0,"id":2309796}]}]}
{"op":"mcm","clk":"1005419690","pt":1580642593705,"mc":[{"id":"1.168219390","rc":[{"batb":[[0,2.08,38.65],[1,2.04,26.59],[2,1.01,10.52]],"batl":[[0,2.34,31.09],[1,2.7,245.56]],"ltp":0.0,"tv":0.0,"id":8535963},{"batb":[[1,1.75,55.45],[2,1.01,10.52]],"batl":[[0,1.94,42.01],[1,2.4,289.78]],"ltp":0.0,"tv":0.0,"id":2309796}]}]}
{"op":"mcm","clk":"1005419788","pt":1580642594134,"mc":[{"id":"1.168219390","rc":[{"batb":[[0,2.16,22.58],[1,2.08,63.36]],"ltp":0.0,"tv":0.0,"id":8535963},{"batb":[[2,1.73,22.35]],"ltp":0.0,"tv":0.0,"id":2309796}]}]}
{"op":"mcm","clk":"1005421075","pt":1580642600649,"mc":[{"id":"1.168219390","rc":[{"batb":[[0,2.08,24.71],[1,1.01,10.52],[2,1.01,0]],"batl":[[0,2.7,245.56],[1,2.7,0]],"ltp":0.0,"tv":0.0,"id":8535963},{"batb":[[0,1.73,22.35],[1,1.01,10.52],[2,1.73,0]],"batl":[[0,2.4,289.78],[1,2.4,0]],"ltp":0.0,"tv":0.0,"id":2309796}]}]}
{"op":"mcm","clk":"1005423015","pt":1580642609724,"mc":[{"id":"1.168219390","rc":[{"batb":[[1,2.04,40.33],[2,2,27.7]],"batl":[[0,2.28,32.77],[1,2.7,245.56]],"ltp":0.0,"tv":0.0,"id":8535963},{"batb":[[0,1.8,19.51],[1,1.79,52.93],[2,1.77,20.69]],"batl":[[0,1.98,42.01],[1,2.4,289.78]],"ltp":0.0,"tv":0.0,"id":2309796}]}]}
{"op":"mcm","clk":"1005425856","pt":1580642624586,"mc":[{"id":"1.168219390","rc":[{"batb":[[0,2,27.7],[1,1.01,10.52],[2,2,0]],"batl":[[0,2.7,245.56],[1,2.7,0]],"ltp":0.0,"tv":0.0,"id":8535963},{"batb":[[0,1.77,20.69],[1,1.01,10.52],[2,1.77,0]],"batl":[[0,2.4,289.78],[1,2.4,0]],"ltp":0.0,"tv":0.0,"id":2309796}]}]}
{"op":"mcm","clk":"1005429077","pt":1580642641566,"mc":[{"id":"1.168219390","rc":[{"batb":[[1,1.99,42.01],[2,1.01,10.52]],"batl":[[0,2.22,33.61],[1,2.7,245.56]],"ltp":0.0,"tv":0.0,"id":8535963},{"batb":[[0,1.82,50.41],[1,1.77,20.69],[2,1.01,10.52]],"batl":[[0,2.02,41.17],[1,2.4,289.78]],"ltp":0.0,"tv":0.0,"id":2309796}]}]}
{"op":"mcm","clk":"1005429197","pt":1580642642161,"mc":[{"id":"1.168219390","rc":[{"batb":[[2,1.93,15.82]],"ltp":0.0,"tv":0.0,"id":8535963},{"batb":[[0,1.87,17.47],[1,1.82,69.45]],"ltp":0.0,"tv":0.0,"id":2309796}]}]}
{"op":"mcm","clk":"1005432246","pt":1580642657421,"mc":[{"id":"1.168219390","rc":[{"batb":[[0,1.99,42.01],[1,1.93,15.82],[2,1.01,10.52]],"ltp":0.0,"tv":0.0,"id":8535963},{"batb":[[0,1.82,69.45],[1,1.01,10.52],[2,1.01,0]],"ltp":0.0,"tv":0.0,"id":2309796}]}]}
{"op":"mcm","clk":"1005432500","pt":1580642658607,"mc":[{"id":"1.168219390","rc":[{"batb":[[0,1.93,15.82],[1,1.01,10.52],[2,1.01,0]],"batl":[[0,2.7,245.56],[1,2.7,0]],"ltp":0.0,"tv":0.0,"id":8535963},{"batb":[[0,1.82,19.04]],"batl":[[0,2.4,289.78],[1,2.4,0]],"ltp":0.0,"tv":0.0,"id":2309796}]}]}
{"op":"mcm","clk":"1005434350","pt":1580642667543,"mc":[{"id":"1.168219390","rc":[{"batb":[[0,2.06,25.41],[1,2,42.01],[2,1.99,28.64]],"batl":[[0,2.24,33.61],[1,2.7,245.56]],"ltp":0.0,"tv":0.0,"id":8535963},{"batb":[[1,1.81,51.25],[2,1.79,20.14]],"batl":[[0,2,42.01],[1,2.4,289.78]],"ltp":0.0,"tv":0.0,"id":2309796}]}]}
{"op":"mcm","clk":"1005436843","pt":1580642680625,"mc":[{"id":"1.168219390","rc":[{"batb":[[0,1.99,28.64],[1,1.01,10.52],[2,1.99,0]],"batl":[[0,2.7,245.56],[1,2.7,0]],"ltp":0.0,"tv":0.0,"id":8535963},{"batb":[[0,1.79,20.14],[1,1.01,10.52],[2,1.79,0]],"batl":[[0,2.4,289.78],[1,2.4,0]],"ltp":0.0,"tv":0.0,"id":2309796}]}]}
{"op":"mcm","clk":"1005439001","pt":1580642692725,"mc":[{"id":"1.168219390","rc":[{"batb":[[1,1.91,16.21],[2,1.01,10.52]],"ltp":0.0,"tv":0.0,"id":8535963},{"batb":[[0,1.89,16.92],[1,1.84,18.41],[2,1.01,10.52]],"ltp":0.0,"tv":0.0,"id":2309796}]}]}
{"op":"mcm","clk":"1005439201","pt":1580642693723,"mc":[{"id":"1.168219390","rc":[{"batb":[[1,1.97,42.85],[2,1.91,16.21]],"batl":[[0,2.2,34.45],[1,2.7,245.56]],"ltp":0.0,"tv":0.0,"id":8535963},{"batb":[[1,1.85,48.73],[2,1.84,67.98]],"batl":[[0,2.04,40.33],[1,2.4,289.78]],"ltp":0.0,"tv":0.0,"id":2309796}]}]}
{"op":"mcm","clk":"1005439372","pt":1580642694727,"mc":[{"id":"1.168219390","rc":[{"batb":[[1,1.84,67.98],[2,1.01,10.52]],"ltp":0.0,"tv":0.0,"id":2309796}]}]}
{"op":"mcm","clk":"1005441418","pt":1580642705736,"mc":[{"id":"1.168219390","rc":[{"batb":[[0,1.97,42.85],[1,1.91,16.21],[2,1.01,10.52]],"ltp":0.0,"tv":0.0,"id":8535963},{"batb":[[0,1.84,67.98],[1,1.01,10.52],[2,1.01,0]],"ltp":0.0,"tv":0.0,"id":2309796}]}]}
{"op":"mcm","clk":"1005441584","pt":1580642706639,"mc":[{"id":"1.168219390","rc":[{"batb":[[0,1.91,16.21],[1,1.01,10.52],[2,1.01,0]],"batl":[[0,2.7,245.56],[1,2.7,0]],"ltp":0.0,"tv":0.0,"id":8535963},{"batb":[[0,1.84,18.41]],"batl":[[0,2.4,289.78],[1,2.4,0]],"ltp":0.0,"tv":0.0,"id":2309796}]}]}
{"op":"mcm","clk":"1005441990","pt":1580642708651,"mc":[{"id":"1.168219390","rc":[{"batb":[[1,1.83,18.49],[2,1.01,10.52]],"ltp":0.0,"tv":0.0,"id":2309796}]}]}
{"op":"mcm","clk":"1005442154","pt":1580642709420,"mc":[{"id":"1.168219390","rc":[{"batb":[[0,1.83,18.49],[1,1.01,10.52],[2,1.01,0]],"ltp":0.0,"tv":0.0,"id":2309796}]}]}
{"op":"mcm","clk":"1005443456","pt":1580642716556,"mc":[{"id":"1.168219390","rc":[{"batb":[[1,1.8,19.59],[2,1.01,10.52]],"ltp":0.0,"tv":0.0,"id":8535963},{"batb":[[0,1.96,30.06],[1,1.89,16.76],[2,1.01,10.52]],"ltp":0.0,"tv":0.0,"id":2309796}]}]}
{"op":"mcm","clk":"1005443605","pt":1580642717563,"mc":[{"id":"1.168219390","rc":[{"batb":[[0,1.92,45.37],[1,1.91,16.21],[2,1.8,19.59]],"batl":[[0,2.16,36.13],[1,2.7,245.56]],"ltp":0.0,"tv":0.0,"id":8535963},{"batb":[[2,1.88,47.05]],"batl":[[0,2.08,38.65],[1,2.4,289.78]],"ltp":0.0,"tv":0.0,"id":2309796}]}]}
{"op":"mcm","clk":"1005443813","pt":1580642718740,"mc":[{"id":"1.168219390","rc":[{"batb":[[0,1.91,16.21],[1,1.8,19.59],[2,1.01,10.52]],"ltp":0.0,"tv":0.0,"id":8535963}]}]}
{"op":"mcm","clk":"1005444250","pt":1580642721358,"mc":[{"id":"1.168219390","rc":[{"batb":[[0,1.93,44.53],[1,1.91,16.21],[2,1.8,19.59]],"ltp":0.0,"tv":0.0,"id":8535963}]}]}
{"op":"mcm","clk":"1005445374","pt":1580642727486,"mc":[{"id":"1.168219390","rc":[{"batb":[[1,1.8,19.59],[2,1.01,10.52]],"ltp":0.0,"tv":0.0,"id":8535963},{"batb":[[0,1.89,16.76],[1,1.88,47.05],[2,1.01,10.52]],"ltp":0.0,"tv":0.0,"id":2309796}]}]}
{"op":"mcm","clk":"1005445574","pt":1580642728561,"mc":[{"id":"1.168219390","rc":[{"batb":[[0,1.8,19.59],[1,1.01,10.52],[2,1.01,0]],"batl":[[0,2.7,245.56],[1,2.7,0]],"ltp":0.0,"tv":0.0,"id":8535963},{"batb":[[1,1.01,10.52],[2,1.01,0]],"batl":[[0,2.4,289.78],[1,2.4,0]],"ltp":0.0,"tv":0.0,"id":2309796}]}]}
{"op":"mcm","clk":"1005446807","pt":1580642735576,"mc":[{"id":"1.168219390","rc":[{"batb":[[0,1.95,43.69],[1,1.8,19.59],[2,1.01,10.52]],"batl":[[0,2.18,35.29],[1,2.7,245.56]],"ltp":0.0,"tv":0.0,"id":8535963},{"batb":[[1,1.86,48.73],[2,1.01,10.52]],"batl":[[0,2.06,39.49],[1,2.4,289.78]],"ltp":0.0,"tv":0.0,"id":2309796}]}]}
{"op":"mcm","clk":"1005446934","pt":1580642736270,"mc":[{"id":"1.168219390","rc":[{"batb":[[0,1.99,28.72],[1,1.95,43.69],[2,1.9,16.44]],"ltp":0.0,"tv":0.0,"id":8535963},{"batb":[[2,1.84,18.25]],"ltp":0.0,"tv":0.0,"id":2309796}]}]}
{"op":"mcm","clk":"1005459339","pt":1580642801347,"mc":[{"id":"1.168219390","rc":[{"batb":[[0,1.95,43.69],[1,1.9,16.44],[2,1.01,10.52]],"ltp":0.0,"tv":0.0,"id":8535963},{"batb":[[0,1.86,48.73],[1,1.84,18.25],[2,1.01,10.52]],"ltp":0.0,"tv":0.0,"id":2309796}]}]}
{"op":"mcm","clk":"1005459583","pt":1580642802613,"mc":[{"id":"1.168219390","rc":[{"batb":[[0,1.9,16.44],[1,1.01,10.52],[2,1.01,0]],"batl":[[0,2.7,245.56],[1,2.7,0]],"ltp":0.0,"tv":0.0,"id":8535963},{"batb":[[0,1.84,18.25],[1,1.01,10.52],[2,1.01,0]],"batl":[[0,2.4,289.78],[1,2.4,0]],"ltp":0.0,"tv":0.0,"id":2309796}]}]}
{"op":"mcm","clk":"1005473637","pt":1580642875608,"mc":[{"id":"1.168219390","rc":[{"batb":[[0,1.91,45.37],[1,1.9,16.44],[2,1.8,19.67]],"batl":[[0,2.14,36.13]],"ltp":0.0,"tv":0.0,"id":8535963},{"batb":[[0,1.97,29.51],[1,1.9,16.68],[2,1.88,47.05]],"batl":[[0,2.1,37.81]],"ltp":0.0,"tv":0.0,"id":2309796}]}]}
{"op":"mcm","clk":"1005473831","pt":1580642876685,"mc":[{"id":"1.168219390","rc":[{"batl":[[1,2.52,270.1]],"ltp":0.0,"tv":0.0,"id":8535963},{"batl":[[1,2.7,245.56]],"ltp":0.0,"tv":0.0,"id":2309796}]}]}
{"op":"mcm","clk":"1005477961","pt":1580642900718,"mc":[{"id":"1.168219390","rc":[{"batb":[[0,1.8,19.67],[1,1.01,10.52],[2,1.8,0]],"batl":[[0,2.52,270.1],[1,2.52,0]],"ltp":0.0,"tv":0.0,"id":8535963},{"batb":[[0,1.9,16.68],[1,1.01,10.52],[2,1.88,0]],"batl":[[0,2.7,245.56],[1,2.7,0]],"ltp":0.0,"tv":0.0,"id":2309796}]}]}
{"op":"mcm","clk":"1005484960","pt":1580642940753,"mc":[{"id":"1.168219390","rc":[{"batb":[[1,1.76,21.01],[2,1.01,10.52]],"ltp":0.0,"tv":0.0,"id":8535963},{"batb":[[0,2.1,24.55],[1,2.02,27.54],[2,1.9,16.68]],"ltp":0.0,"tv":0.0,"id":2309796}]}]}
{"op":"mcm","clk":"1005485152","pt":1580642941668,"mc":[{"id":"1.168219390","rc":[{"batb":[[0,1.82,50.41],[1,1.8,19.67],[2,1.76,21.01]],"batl":[[0,2.02,41.17],[1,2.52,270.1]],"ltp":0.0,"tv":0.0,"id":8535963},{"batb":[[2,1.97,42.85]],"batl":[[0,2.22,33.61],[1,2.7,245.56]],"ltp":0.0,"tv":0.0,"id":2309796}]}]}
{"op":"mcm","clk":"1005490822","pt":1580642973190,"mc":[{"id":"1.168219390","rc":[{"batb":[[1,1.76,21.01],[2,1.01,10.52]],"ltp":0.0,"tv":0.0,"id":8535963},{"batb":[[0,2.02,27.54],[1,1.97,42.85],[2,1.01,10.52]],"ltp":0.0,"tv":0.0,"id":2309796}]}]}
{"op":"mcm","clk":"1005491104","pt":1580642974815,"mc":[{"id":"1.168219390","rc":[{"batb":[[0,1.76,21.01],[1,1.01,10.52],[2,1.01,0]],"batl":[[0,2.52,270.1],[1,2.52,0]],"ltp":0.0,"tv":0.0,"id":8535963},{"batb":[[1,1.01,10.52],[2,1.01,0]],"batl":[[0,2.7,245.56],[1,2.7,0]],"ltp":0.0,"tv":0.0,"id":2309796}]}]}
{"op":"mcm","clk":"1005494555","pt":1580642993766,"mc":[{"id":"1.168219390","rc":[{"batb":[[0,1.86,17.62],[1,1.85,48.73],[2,1.82,19.04]],"batl":[[0,2.06,39.49],[1,2.52,270.1]],"ltp":0.0,"tv":0.0,"id":8535963},{"batb":[[1,1.96,43.69],[2,1.93,15.74]],"batl":[[0,2.18,35.29],[1,2.7,245.56]],"ltp":0.0,"tv":0.0,"id":2309796}]}]}
{"op":"mcm","clk":"1005494688","pt":1580642994501,"mc":[{"id":"1.168219390","rc":[{"batb":[[1,1.82,19.04],[2,1.01,10.52]],"ltp":0.0,"tv":0.0,"id":8535963},{"batb":[[1,1.93,15.74],[2,1.01,10.52]],"batl":[[0,2.7,245.56],[1,2.7,0]],"ltp":0.0,"tv":0.0,"id":2309796}]}]}
{"op":"mcm","clk":"1005495095","pt":1580642996594,"mc":[{"id":"1.168219390","rc":[{"batb":[[0,1.86,66.36]],"ltp":0.0,"tv":0.0,"id":8535963},{"batb":[[1,1.95,43.69],[2,1.93,15.74]],"batl":[[0,2.16,36.13],[1,2.7,245.56]],"ltp":0.0,"tv":0.0,"id":2309796}]}]}
{"op":"mcm","clk":"1005496887","pt":1580643005484,"mc":[{"id":"1.168219390","rc":[{"batb":[[0,1.82,19.04],[1,1.01,10.52],[2,1.01,0]],"batl":[[0,2.52,270.1],[1,2.52,0]],"ltp":0.0,"tv":0.0,"id":8535963},{"batb":[[0,1.93,15.74],[1,1.01,10.52],[2,1.93,0]],"batl":[[0,2.7,245.56],[1,2.7,0]],"ltp":0.0,"tv":0.0,"id":2309796}]}]}
{"op":"mcm","clk":"1005498488","pt":1580643013708,"mc":[{"id":"1.168219390","rc":[{"batb":[[0,1.94,15.42],[1,1.89,63.73],[2,1.82,19.04]],"batl":[[0,2.12,36.97],[1,2.52,270.1]],"ltp":0.0,"tv":0.0,"id":8535963},{"batb":[[1,1.91,45.37],[2,1.85,18.02]],"batl":[[0,2.12,36.97],[1,2.7,245.56]],"ltp":0.0,"tv":0.0,"id":2309796}]}]}
{"op":"mcm","clk":"1005498562","pt":1580643014393,"mc":[{"id":"1.168219390","rc":[{"batb":[[2,1.01,10.52]],"batl":[[0,2.52,270.1],[1,2.52,0]],"ltp":0.0,"tv":0.0,"id":8535963}]}]}
{"op":"mcm","clk":"1005498821","pt":1580643015427,"mc":[{"id":"1.168219390","rc":[{"batl":[[0,2.1,37.81],[1,2.52,270.1]],"ltp":0.0,"tv":0.0,"id":8535963}]}]}
{"op":"mcm","clk":"1005500722","pt":1580643025638,"mc":[{"id":"1.168219390","rc":[{"batb":[[1,1.89,16.68]],"ltp":0.0,"tv":0.0,"id":8535963}]}]}
{"op":"mcm","clk":"1005500972","pt":1580643027028,"mc":[{"id":"1.168219390","rc":[{"batb":[[0,1.89,16.68],[1,1.01,10.52],[2,1.01,0]],"batl":[[0,2.52,270.1],[1,2.52,0]],"ltp":0.0,"tv":0.0,"id":8535963},{"batb":[[0,1.85,18.02],[1,1.01,10.52],[2,1.85,0]],"batl":[[0,2.7,245.56],[1,2.7,0]],"ltp":0.0,"tv":0.0,"id":2309796}]}]}
{"op":"mcm","clk":"1005508818","pt":1580643069739,"mc":[{"id":"1.168219390","rc":[{"batb":[[1,1.84,18.33],[2,1.01,10.52]],"ltp":0.0,"tv":0.0,"id":8535963},{"batb":[[0,1.98,29.11],[1,1.89,16.68],[2,1.01,10.52]],"ltp":0.0,"tv":0.0,"id":2309796}]}]}
{"op":"mcm","clk":"1005508916","pt":1580643070285,"mc":[{"id":"1.168219390","rc":[{"batb":[[1,1.88,47.05],[2,1.84,18.33]],"batl":[[0,2.1,37.81],[1,2.52,270.1]],"ltp":0.0,"tv":0.0,"id":8535963},{"batb":[[1,1.91,45.37],[2,1.89,16.68]],"batl":[[0,2.14,36.13],[1,2.7,245.56]],"ltp":0.0,"tv":0.0,"id":2309796}]}]}
{"op":"mcm","clk":"1005512874","pt":1580643091418,"mc":[{"id":"1.168219390","rc":[{"batb":[[0,1.88,47.05],[1,1.84,18.33],[2,1.01,10.52]],"ltp":0.0,"tv":0.0,"id":8535963},{"batb":[[0,1.91,45.37],[1,1.89,16.68],[2,1.01,10.52]],"ltp":0.0,"tv":0.0,"id":2309796}]}]}
{"op":"mcm","clk":"1005513167","pt":1580643092800,"mc":[{"id":"1.168219390","rc":[{"batb":[[0,1.84,18.33],[1,1.01,10.52],[2,1.01,0]],"batl":[[0,2.52,270.1],[1,2.52,0]],"ltp":0.0,"tv":0.0,"id":8535963},{"batb":[[0,1.89,16.68],[1,1.01,10.52],[2,1.01,0]],"batl":[[0,2.7,245.56],[1,2.7,0]],"ltp":0.0,"tv":0.0,"id":2309796}]}]}
{"op":"mcm","clk":"1005514105","pt":1580643097726,"mc":[{"id":"1.168219390","rc":[{"batb":[[1,1.78,20.22],[2,1.01,10.52]],"ltp":0.0,"tv":0.0,"id":8535963},{"batb":[[0,2.04,26.36],[1,1.95,30.61],[2,1.89,16.68]],"ltp":0.0,"tv":0.0,"id":2309796}]}]}
{"op":"mcm","clk":"1005514291","pt":1580643098620,"mc":[{"id":"1.168219390","rc":[{"batb":[[0,1.86,48.73],[1,1.84,18.33],[2,1.78,20.22]],"batl":[[0,2.06,39.49],[1,2.52,270.1]],"ltp":0.0,"tv":0.0,"id":8535963},{"batb":[[1,1.95,74.3],[2,1.01,10.52]],"batl":[[0,2.16,36.13],[1,2.7,245.56]],"ltp":0.0,"tv":0.0,"id":2309796}]}]}
{"op":"mcm","clk":"1005517302","pt":1580643114917,"mc":[{"id":"1.168219390","rc":[{"batb":[[0,1.78,20.22],[1,1.01,10.52],[2,1.78,0]],"batl":[[0,2.52,270.1],[1,2.52,0]],"ltp":0.0,"tv":0.0,"id":8535963},{"batb":[[0,1.95,30.61],[1,1.01,10.52],[2,1.01,0]],"batl":[[0,2.7,245.56],[1,2.7,0]],"ltp":0.0,"tv":0.0,"id":2309796}]}]}
{"op":"mcm","clk":"1005519411","pt":1580643126663,"mc":[{"id":"1.168219390","rc":[{"batb":[[1,1.75,21.72],[2,1.01,10.52]],"ltp":0.0,"tv":0.0,"id":8535963},{"batb":[[0,2.12,23.76],[1,2.02,27.22],[2,1.96,178.13]],"ltp":0.0,"tv":0.0,"id":2309796}]}]}
{"op":"mcm","clk":"1005519476","pt":1580643126980,"mc":[{"id":"1.168219390","rc":[{"batb":[[2,1.01,10.52]],"ltp":0.0,"tv":0.0,"id":2309796}]}]}
{"op":"mcm","clk":"1005519676","pt":1580643128195,"mc":[{"id":"1.168219390","rc":[{"batb":[[0,1.83,50.41],[1,1.78,20.22],[2,1.75,21.72]],"batl":[[0,2.04,40.33],[1,2.52,270.1]],"ltp":0.0,"tv":0.0,"id":8535963},{"batb":[[2,1.98,42.85]],"batl":[[0,2.2,34.45],[1,2.7,245.56]],"ltp":0.0,"tv":0.0,"id":2309796}]}]}
{"op":"mcm","clk":"1005521999","pt":1580643142109,"mc":[{"id":"1.168219390","rc":[{"batb":[[1,1.75,21.72],[2,1.01,10.52]],"ltp":0.0,"tv":0.0,"id":8535963},{"batb":[[0,2.02,27.22],[1,1.98,42.85],[2,1.01,10.52]],"ltp":0.0,"tv":0.0,"id":2309796}]}]}
{"op":"mcm","clk":"1005522225","pt":1580643143327,"mc":[{"id":"1.168219390","rc":[{"batb":[[0,1.75,21.72],[1,1.01,10.52],[2,1.01,0]],"batl":[[0,2.52,270.1],[1,2.52,0]],"ltp":0.0,"tv":0.0,"id":8535963},{"batb":[[1,1.01,10.52],[2,1.01,0]],"batl":[[0,2.7,245.56],[1,2.7,0]],"ltp":0.0,"tv":0.0,"id":2309796}]}]}
{"op":"mcm","clk":"1005526154","pt":1580643163720,"mc":[{"id":"1.168219390","rc":[{"batb":[[0,1.8,187.96],[1,1.78,197.51],[2,1.75,21.72]],"batl":[[0,1.88,162.41],[1,1.9,162.44],[2,2.52,270.1]],"ltp":0.0,"tv":0.0,"id":8535963}]}]}
{"op":"mcm","clk":"1005526263","pt":1580643164312,"mc":[{"id":"1.168219390","rc":[{"batb":[[0,1.81,51.25],[1,1.8,187.96],[2,1.78,197.51]],"batl":[[2,2.02,41.17]],"ltp":0.0,"tv":0.0,"id":8535963},{"batb":[[0,2.16,22.11],[1,2.02,27.22],[2,2,42.01]],"batl":[[0,2.22,33.61],[1,2.7,245.56]],"ltp":0.0,"tv":0.0,"id":2309796}]}]}
{"op":"mcm","clk":"1005530922","pt":1580643187177,"mc":[{"id":"1.168219390","rc":[{"batb":[[1,2,69.94],[2,1.01,10.52]],"ltp":0.0,"tv":0.0,"id":2309796}]}]}
{"op":"mcm","clk":"1005532516","pt":1580643195672,"mc":[{"id":"1.168219390","rc":[{"batb":[[0,2.14,22.82]],"ltp":0.0,"tv":0.0,"id":2309796}]}]}
{"op":"mcm","clk":"1005548892","pt":1580643278365,"mc":[{"id":"1.168219390","rc":[{"trd":[[2.14,45.62]],"batb":[[0,2,69.94],[1,1.01,10.52],[2,1.01,0]],"batl":[[0,2.14,12.56],[1,2.22,33.61],[2,2.7,245.56]],"ltp":2.14,"tv":45.62,"id":2309796}],"tv":45.62}]}
{"op":"mcm","clk":"1005549151","pt":1580643279682,"mc":[{"id":"1.168219390","rc":[{"batb":[[1,1.61,28.8],[2,1.01,10.52]],"batl":[[0,2.02,41.17],[1,2.52,270.1],[2,2.02,0]],"ltp":0.0,"tv":0.0,"id":8535963}]}]}
{"op":"mcm","clk":"1005549406","pt":1580643281080,"mc":[{"id":"1.168219390","rc":[{"batb":[[0,1.61,28.8],[1,1.01,10.52],[2,1.01,0]],"batl":[[0,2.52,270.1],[1,2.52,0]],"ltp":0.0,"tv":0.0,"id":8535963},{"batb":[[0,2,27.93]],"batl":[[1,2.7,245.56],[2,2.7,0]],"ltp":2.14,"tv":45.62,"id":2309796}]}]}
{"op":"mcm","clk":"1005549717","pt":1580643282682,"mc":[{"id":"1.168219390","rc":[{"batb":[[0,1.64,28.17],[1,1.61,28.8],[2,1.01,10.52]],"ltp":0.0,"tv":0.0,"id":8535963},{"batb":[[1,1.98,29.11],[2,1.01,10.52]],"ltp":2.14,"tv":45.62,"id":2309796}]}]}
{"op":"mcm","clk":"1005549779","pt":1580643283000,"mc":[{"id":"1.168219390","rc":[{"batb":[[1,1.01,10.52],[2,1.01,0]],"ltp":0.0,"tv":0.0,"id":8535963},{"batb":[[0,1.98,29.11],[1,1.01,10.52],[2,1.01,0]],"ltp":2.14,"tv":45.62,"id":2309796}]}]}
{"op":"mcm","clk":"1005550317","pt":1580643285672,"mc":[{"id":"1.168219390","rc":[{"trd":[[1.87,14.38]],"ltp":1.87,"tv":14.38,"id":8535963},{"trd":[[2.14,58.18]],"batl":[[0,2.7,245.56],[1,2.7,0]],"ltp":2.14,"tv":58.17,"id":2309796}],"tv":72.55}]}
{"op":"mcm","clk":"1005550922","pt":1580643288872,"mc":[{"id":"1.168219390","rc":[{"batb":[[0,1.78,123.6],[1,1.76,204.63],[2,1.64,28.17]],"batl":[[0,1.85,157.99],[1,1.87,170.41],[2,2.52,270.1]],"ltp":1.87,"tv":14.38,"id":8535963}]}]}
{"op":"mcm","clk":"1005551594","pt":1580643292505,"mc":[{"id":"1.168219390","rc":[{"batb":[[0,1.64,28.17],[1,1.01,10.52],[2,1.64,0]],"batl":[[0,2.52,270.1],[1,1.87,0],[2,2.52,0]],"ltp":1.87,"tv":14.38,"id":8535963}]}]}
{"op":"mcm","clk":"1005552226","pt":1580643295707,"mc":[{"id":"1.168219390","rc":[{"batb":[[0,1.65,200.59],[1,1.64,159.63],[2,1.01,10.52]],"ltp":1.87,"tv":14.38,"id":8535963}]}]}
{"op":"mcm","clk":"1005552410","pt":1580643296571,"mc":[{"id":"1.168219390","rc":[{"batb":[[0,1.68,61.33],[1,1.65,200.59],[2,1.64,159.63]],"batl":[[0,1.71,124.17],[1,1.73,218.6],[2,1.85,42.01]],"ltp":1.87,"tv":14.38,"id":8535963},{"batb":[[0,2.4,16.52],[1,2.18,57.16],[2,1.01,10.52]],"batl":[[0,2.46,28.57]],"ltp":2.14,"tv":58.17,"id":2309796}]}]}
{"op":"mcm","clk":"1005553091","pt":1580643300393,"mc":[{"id":"1.168219390","rc":[{"batl":[[1,3.15,200.42]],"ltp":2.14,"tv":58.17,"id":2309796}]}]}
{"op":"mcm","clk":"1005556029","pt":1580643315215,"mc":[{"id":"1.168219390","rc":[{"batb":[[0,1.48,41.24],[1,1.01,10.51],[2,1.64,0]],"batl":[[0,2.22,329.01],[1,1.73,0],[2,1.85,0]],"ltp":1.87,"tv":14.38,"id":8535963},{"batb":[[0,2.18,21.87],[1,1.01,10.52],[2,1.01,0]],"batl":[[0,3.15,200.42],[1,3.15,0]],"ltp":2.14,"tv":58.17,"id":2309796}]}]}
{"op":"mcm","clk":"1005556765","pt":1580643318724,"mc":[{"id":"1.168219390","rc":[{"batb":[[0,1.49,147.1],[1,1.48,235.35],[2,1.01,10.51]],"batl":[[0,1.85,137.86],[1,1.87,170.47],[2,2.22,329.01]],"ltp":1.87,"tv":14.38,"id":8535963}]}]}
{"op":"mcm","clk":"1005557476","pt":1580643322348,"mc":[{"id":"1.168219390","rc":[{"batb":[[0,1.48,41.24],[1,1.01,10.51],[2,1.01,0]],"batl":[[0,2.22,329.01],[1,1.87,0],[2,2.22,0]],"ltp":1.87,"tv":14.38,"id":8535963}]}]}
{"op":"mcm","clk":"1005558144","pt":1580643325443,"mc":[{"id":"1.168219390","rc":[{"batb":[[0,1.49,147.1],[1,1.48,235.35],[2,1.01,10.51]],"batl":[[0,1.54,283.68],[1,1.55,158.8]],"ltp":1.87,"tv":14.38,"id":8535963}]}]}
{"op":"mcm","clk":"1005558435","pt":1580643326730,"mc":[{"id":"1.168219390","rc":[{"batb":[[0,1.53,78.98],[1,1.49,147.1],[2,1.48,235.35]],"ltp":1.87,"tv":14.38,"id":8535963},{"batb":[[0,2.86,10.46],[1,2.52,14.56],[2,1.01,10.52]],"batl":[[0,2.9,21.85]],"ltp":2.14,"tv":58.17,"id":2309796}]}]}
{"op":"mcm","clk":"1005558883","pt":1580643328742,"mc":[{"id":"1.168219390","rc":[{"trd":[[1.54,85.7]],"batl":[[0,1.54,240.83],[2,1.63,42.01]],"ltp":1.54,"tv":100.07,"id":8535963},{"batb":[[1,2.52,41.44]],"batl":[[1,3.9,158.24]],"ltp":2.14,"tv":58.17,"id":2309796}],"tv":158.25}]}
{"op":"mcm","clk":"1005559050","pt":1580643329548,"mc":[{"id":"1.168219390","rc":[{"batb":[[1,2.58,26.05],[2,2.52,14.56]],"ltp":2.14,"tv":58.17,"id":2309796}]}]}
{"op":"mcm","clk":"1005559699","pt":1580643332714,"mc":[{"id":"1.168219390","rc":[{"batl":[[0,1.54,267.98]],"ltp":1.54,"tv":100.07,"id":8535963}]}]}
{"op":"mcm","clk":"1005560793","pt":1580643337547,"mc":[{"id":"1.168219390","rc":[{"batb":[[1,1.35,62.4],[2,1.01,10.51]],"batl":[[0,1.63,42.01],[1,1.95,409.86],[2,1.63,0]],"ltp":1.54,"tv":100.07,"id":8535963},{"batb":[[0,2.58,26.05],[1,2.52,14.56],[2,1.01,10.52]],"ltp":2.14,"tv":58.17,"id":2309796}]}]}
{"op":"mcm","clk":"1005561080","pt":1580643339143,"mc":[{"id":"1.168219390","rc":[{"batb":[[0,1.35,62.4],[1,1.01,10.51],[2,1.01,0]],"batl":[[0,1.95,409.86],[1,1.95,0]],"ltp":1.54,"tv":100.07,"id":8535963},{"batb":[[0,2.52,14.56],[1,1.01,10.52],[2,1.01,0]],"batl":[[0,3.9,158.24],[1,3.9,0]],"ltp":2.14,"tv":58.17,"id":2309796}]}]}
{"op":"mcm","clk":"1005561236","pt":1580643340049,"mc":[{"id":"1.168219390","rc":[{"batb":[[1,1.34,452.4],[2,1.33,318.7]],"batl":[[0,1.66,229.79],[1,1.67,121.95],[2,1.95,409.86]],"ltp":1.54,"tv":100.07,"id":8535963}]}]}
{"op":"mcm","clk":"1005561499","pt":1580643341241,"mc":[{"id":"1.168219390","rc":[{"batb":[[1,1.01,10.51],[2,1.33,0]],"batl":[[0,1.95,409.86],[1,1.67,0],[2,1.95,0]],"ltp":1.54,"tv":100.07,"id":8535963}]}]}
{"op":"mcm","clk":"1005562853","pt":1580643347734,"mc":[{"id":"1.168219390","rc":[{"batb":[[0,1.35,219.83],[1,1.34,302.63],[2,1.01,10.51]],"batl":[[0,1.66,229.79],[1,1.67,121.95],[2,1.95,409.86]],"ltp":1.54,"tv":100.07,"id":8535963}]}]}
{"op":"mcm","clk":"1005566332","pt":1580643365472,"mc":[{"id":"1.168219390","rc":[{"batb":[[0,1.35,62.4],[1,1.01,10.51],[2,1.01,0]],"ltp":1.54,"tv":100.07,"id":8535963}]}]}
{"op":"mcm","clk":"1005567052","pt":1580643368508,"mc":[{"id":"1.168219390","rc":[{"batb":[[0,1.6,166.1],[1,1.59,146.9],[2,1.35,62.4]],"ltp":1.54,"tv":100.07,"id":8535963}]}]}
{"op":"mcm","clk":"1005567206","pt":1580643369204,"mc":[{"id":"1.168219390","rc":[{"batb":[[1,1.59,178.22],[2,1.41,50.68]],"ltp":1.54,"tv":100.07,"id":8535963},{"batb":[[1,2.22,20.85],[2,1.01,10.52]],"ltp":2.14,"tv":58.17,"id":2309796}]}]}
{"op":"mcm","clk":"1005567364","pt":1580643370013,"mc":[{"id":"1.168219390","rc":[{"batb":[[0,1.62,67.22],[1,1.6,166.1],[2,1.59,178.22]],"batl":[[2,1.73,42.01]],"ltp":1.54,"tv":100.07,"id":8535963},{"batb":[[1,2.36,30.25],[2,2.22,20.85]],"batl":[[0,2.62,25.21]],"ltp":2.14,"tv":58.17,"id":2309796}]}]}
{"op":"mcm","clk":"1005567638","pt":1580643371456,"mc":[{"id":"1.168219390","rc":[{"batl":[[1,3.45,180.4]],"ltp":2.14,"tv":58.17,"id":2309796}]}]}
{"op":"mcm","clk":"1005570416","pt":1580643385588,"mc":[{"id":"1.168219390","rc":[{"batb":[[1,1.41,50.68],[2,1.01,10.51]],"batl":[[0,1.73,42.01],[1,1.95,409.86],[2,1.73,0]],"ltp":1.54,"tv":100.07,"id":8535963},{"batb":[[0,2.36,30.25],[1,2.22,20.85],[2,1.01,10.52]],"ltp":2.14,"tv":58.17,"id":2309796}]}]}
{"op":"mcm","clk":"1005570766","pt":1580643387300,"mc":[{"id":"1.168219390","rc":[{"batb":[[0,1.41,50.68],[1,1.01,10.51],[2,1.01,0]],"batl":[[0,1.62,2.12]],"ltp":1.54,"tv":100.07,"id":8535963},{"batb":[[0,2.22,20.85],[1,1.01,10.52],[2,1.01,0]],"batl":[[0,3.45,180.4],[1,3.45,0]],"ltp":2.14,"tv":58.17,"id":2309796}]}]}
{"op":"mcm","clk":"1005571584","pt":1580643391681,"mc":[{"id":"1.168219390","rc":[{"batb":[[0,1.75,186.27],[1,1.73,216.81],[2,1.52,36.98]],"batl":[[0,1.82,148.89],[1,1.84,179.12]],"ltp":1.54,"tv":100.07,"id":8535963},{"batb":[[1,1.97,29.43],[2,1.01,10.52]],"ltp":2.14,"tv":58.17,"id":2309796}]}]}
{"op":"mcm","clk":"1005571748","pt":1580643392385,"mc":[{"id":"1.168219390","rc":[{"batl":[[2,1.88,42.01]],"ltp":1.54,"tv":100.07,"id":8535963},{"batb":[[1,2.12,36.97],[2,1.97,29.43]],"ltp":2.14,"tv":58.17,"id":2309796}]}]}
{"op":"mcm","clk":"1005572000","pt":1580643393711,"mc":[{"id":"1.168219390","rc":[{"batb":[[1,1.74,56.29],[2,1.73,216.81]],"ltp":1.54,"tv":100.07,"id":8535963},{"batl":[[0,2.36,30.25],[1,2.92,221.26]],"ltp":2.14,"tv":58.17,"id":2309796}]}]}
{"op":"mcm","clk":"1005572167","pt":1580643394502,"mc":[{"id":"1.168219390","rc":[{"batl":[[0,2.34,31.09]],"ltp":2.14,"tv":58.17,"id":2309796}]}]}
{"op":"mcm","clk":"1005573855","pt":1580643402505,"mc":[{"id":"1.168219390","rc":[{"batb":[[0,1.75,22.9],[2,1.52,36.98]],"batl":[[0,1.88,42.01],[1,2.36,299.17],[2,1.88,0]],"ltp":1.54,"tv":100.07,"id":8535963}]}]}
{"op":"mcm","clk":"1005573946","pt":1580643403030,"mc":[{"id":"1.168219390","rc":[{"batb":[[0,1.52,36.98],[1,1.01,10.52],[2,1.52,0]],"batl":[[0,2.36,299.17],[1,2.36,0]],"ltp":1.54,"tv":100.07,"id":8535963},{"batb":[[0,1.97,29.43],[1,1.01,10.52],[2,1.97,0]],"batl":[[0,2.92,221.26],[1,2.92,0]],"ltp":2.14,"tv":58.17,"id":2309796}]}]}
{"op":"mcm","clk":"1005574472","pt":1580643405731,"mc":[{"id":"1.168219390","rc":[{"batb":[[0,1.52,266.23],[1,1.51,179.42],[2,1.01,10.52]],"batl":[[0,2.02,129.25],[1,2.04,131.38],[2,2.36,299.17]],"ltp":1.54,"tv":100.07,"id":8535963}]}]}
{"op":"mcm","clk":"1005574907","pt":1580643407710,"mc":[{"id":"1.168219390","rc":[{"batb":[[0,1.52,36.98],[1,1.01,10.52],[2,1.01,0]],"ltp":1.54,"tv":100.07,"id":8535963}]}]}
{"op":"mcm","clk":"1005575585","pt":1580643410687,"mc":[{"id":"1.168219390","rc":[{"batb":[[0,1.93,177.69],[1,1.91,157.44],[2,1.52,36.98]],"batl":[[2,2.36,0]],"ltp":1.54,"tv":100.07,"id":8535963}]}]}
{"op":"mcm","clk":"1005575746","pt":1580643411646,"mc":[{"id":"1.168219390","rc":[{"batb":[[0,1.94,16.52],[1,1.93,177.69],[2,1.91,157.44]],"ltp":1.54,"tv":100.07,"id":8535963},{"batb":[[1,1.85,18.1],[2,1.01,10.52]],"ltp":2.14,"tv":58.17,"id":2309796}]}]}
{"op":"mcm","clk":"1005575831","pt":1580643412028,"mc":[{"id":"1.168219390","rc":[{"batl":[[2,2.06,39.49]],"ltp":1.54,"tv":100.07,"id":8535963},{"batb":[[1,1.94,44.53],[2,1.85,18.1]],"batl":[[0,2.12,36.97]],"ltp":2.14,"tv":58.17,"id":2309796}]}]}
{"op":"mcm","clk":"1005576384","pt":1580643414933,"mc":[{"id":"1.168219390","rc":[{"batl":[[1,2.6,257.57]],"ltp":2.14,"tv":58.17,"id":2309796}]}]}
{"op":"mcm","clk":"1005578330","pt":1580643424709,"mc":[{"id":"1.168219390","rc":[{"batb":[[0,1.89,47.05],[1,1.74,23.21],[2,1.01,10.52]],"batl":[[0,2.06,39.49],[1,2.6,257.57],[2,2.06,0]],"ltp":1.54,"tv":100.07,"id":8535963},{"batb":[[0,1.94,44.53],[1,1.85,18.1],[2,1.01,10.52]],"ltp":2.14,"tv":58.17,"id":2309796}]}]}
{"op":"mcm","clk":"1005578423","pt":1580643425113,"mc":[{"id":"1.168219390","rc":[{"batb":[[0,1.74,23.21],[1,1.01,10.52],[2,1.01,0]],"batl":[[0,2.6,257.57],[1,2.6,0]],"ltp":1.54,"tv":100.07,"id":8535963},{"batb":[[0,1.85,18.1],[1,1.01,10.52],[2,1.01,0]],"batl":[[0,2.6,257.57],[1,2.6,0]],"ltp":2.14,"tv":58.17,"id":2309796}]}]}
{"op":"mcm","clk":"1005578830","pt":1580643427120,"mc":[{"id":"1.168219390","rc":[{"batb":[[0,1.74,181.91],[1,1.72,221.1],[2,1.01,10.52]],"batl":[[0,2.18,130.02],[1,2.2,106.05],[2,2.6,257.57]],"ltp":1.54,"tv":100.07,"id":8535963}]}]}
{"op":"mcm","clk":"1005579335","pt":1580643429608,"mc":[{"id":"1.168219390","rc":[{"batl":[[0,2.6,257.57],[1,2.2,0],[2,2.6,0]],"ltp":1.54,"tv":100.07,"id":8535963}]}]}
{"op":"mcm","clk":"1005579946","pt":1580643432501,"mc":[{"id":"1.168219390","rc":[{"batl":[[0,1.81,163.69],[1,1.83,182.17]],"ltp":1.54,"tv":100.07,"id":8535963}]}]}
{"op":"mcm","clk":"1005580152","pt":1580643433712,"mc":[{"id":"1.168219390","rc":[{"batb":[[2,1.52,37.45]],"ltp":1.54,"tv":100.07,"id":8535963},{"batb":[[0,2.22,20.54],[1,1.98,28.95],[2,1.01,10.52]],"ltp":2.14,"tv":58.17,"id":2309796}]}]}
{"op":"mcm","clk":"1005580318","pt":1580643434518,"mc":[{"id":"1.168219390","rc":[{"batb":[[0,1.74,238.2]],"batl":[[2,1.89,42.01]],"ltp":1.54,"tv":100.07,"id":8535963},{"batb":[[1,2.12,36.97],[2,1.98,28.95]],"batl":[[0,2.34,31.09]],"ltp":2.14,"tv":58.17,"id":2309796}]}]}
{"op":"mcm","clk":"1005580441","pt":1580643435108,"mc":[{"id":"1.168219390","rc":[{"batl":[[1,3,213.45]],"ltp":2.14,"tv":58.17,"id":2309796}]}]}
{"op":"mcm","clk":"1005582312","pt":1580643443603,"mc":[{"id":"1.168219390","rc":[{"batb":[[0,1.74,56.29],[1,1.52,37.45],[2,1.01,10.52]],"batl":[[0,1.89,42.01],[1,2.3,309.75],[2,1.89,0]],"ltp":1.54,"tv":100.07,"id":8535963},{"batb":[[0,2.12,36.97],[1,1.98,28.95],[2,1.01,10.52]],"ltp":2.14,"tv":58.17,"id":2309796}]}]}
{"op":"mcm","clk":"1005582629","pt":1580643445215,"mc":[{"id":"1.168219390","rc":[{"batb":[[0,1.52,37.45],[1,1.01,10.52],[2,1.01,0]],"batl":[[0,2.3,309.75],[1,2.3,0]],"ltp":1.54,"tv":100.07,"id":8535963},{"batb":[[0,1.98,28.95],[1,1.01,10.52],[2,1.01,0]],"batl":[[0,3,213.45],[1,3,0]],"ltp":2.14,"tv":58.17,"id":2309796}]}]}
{"op":"mcm","clk":"1005582790","pt":1580643446022,"mc":[{"id":"1.168219390","rc":[{"batb":[[1,1.51,280.83],[2,1.5,184.6]],"batl":[[0,2.02,217.62],[1,2.04,131.32],[2,2.3,309.75]],"ltp":1.54,"tv":100.07,"id":8535963}]}]}
{"op":"mcm","clk":"1005585258","pt":1580643458571,"mc":[{"id":"1.168219390","rc":[{"batb":[[1,1.01,10.52],[2,1.5,0]],"ltp":1.54,"tv":100.07,"id":8535963}]}]}
{"op":"mcm","clk":"1005585908","pt":1580643461653,"mc":[{"id":"1.168219390","rc":[{"batb":[[0,1.92,163.27],[1,1.9,160.03],[2,1.55,678.99]],"ltp":1.54,"tv":100.07,"id":8535963}]}]}
{"op":"mcm","clk":"1005585986","pt":1580643462080,"mc":[{"id":"1.168219390","rc":[{"batb":[[0,1.93,16.76],[1,1.92,163.27],[2,1.9,160.03]],"batl":[[2,2.06,39.49]],"ltp":1.54,"tv":100.07,"id":8535963},{"batb":[[1,1.95,43.69],[2,1.86,17.7]],"batl":[[0,2.14,36.13]],"ltp":2.14,"tv":58.17,"id":2309796}]}]}
{"op":"mcm","clk":"1005586501","pt":1580643464469,"mc":[{"id":"1.168219390","rc":[{"batl":[[1,2.72,241.55]],"ltp":2.14,"tv":58.17,"id":2309796}]}]}
{"op":"mcm","clk":"1005586675","pt":1580643465269,"mc":[{"id":"1.168219390","rc":[{"trd":[[1.93,4.24]],"batb":[[0,1.93,14.64]],"ltp":1.93,"tv":104.32,"id":8535963}],"tv":162.5}]}
{"op":"mcm","clk":"1005588667","pt":1580643475497,"mc":[{"id":"1.168219390","rc":[{"batb":[[0,1.88,47.05],[1,1.73,23.6],[2,1.01,10.52]],"batl":[[0,2.06,39.49],[1,2.3,309.75],[2,2.06,0]],"ltp":1.93,"tv":104.32,"id":8535963},{"batb":[[0,1.95,43.69],[1,1.86,17.7],[2,1.01,10.52]],"ltp":2.14,"tv":58.17,"id":2309796}]}]}
{"op":"mcm","clk":"1005589015","pt":1580643477217,"mc":[{"id":"1.168219390","rc":[{"batb":[[0,1.73,23.6],[1,1.01,10.52],[2,1.01,0]],"batl":[[0,2.3,309.75],[1,2.3,0]],"ltp":1.93,"tv":104.32,"id":8535963},{"batb":[[0,1.86,17.7],[1,1.01,10.52],[2,1.01,0]],"batl":[[0,2.72,241.55],[1,2.72,0]],"ltp":2.14,"tv":58.17,"id":2309796}]}]}
{"op":"mcm","clk":"1005589350","pt":1580643478686,"mc":[{"id":"1.168219390","rc":[{"batb":[[0,1.73,167.76],[1,1.71,225.52],[2,1.01,10.52]],"batl":[[0,2.16,107.63],[1,2.18,108.78],[2,2.3,309.75]],"ltp":1.93,"tv":104.32,"id":8535963}]}]}
{"op":"mcm","clk":"1005590332","pt":1580643483603,"mc":[{"id":"1.168219390","rc":[{"batl":[[0,2.3,309.75],[1,2.18,0],[2,2.3,0]],"ltp":1.93,"tv":104.32,"id":8535963}]}]}
{"op":"mcm","clk":"1005591032","pt":1580643486722,"mc":[{"id":"1.168219390","rc":[{"batl":[[0,1.8,188.31],[1,1.82,185.3],[2,2.3,309.75]],"ltp":1.93,"tv":104.32,"id":8535963}]}]}
{"op":"mcm","clk":"1005591189","pt":1580643487444,"mc":[{"id":"1.168219390","rc":[{"batb":[[2,1.51,38.63]],"ltp":1.93,"tv":104.32,"id":8535963},{"batb":[[0,2.24,19.99],[1,2,28.25],[2,1.01,10.52]],"ltp":2.14,"tv":58.17,"id":2309796}]}]}
{"op":"mcm","clk":"1005591472","pt":1580643488733,"mc":[{"id":"1.168219390","rc":[{"batb":[[0,1.73,224.9]],"batl":[[2,1.88,42.01]],"ltp":1.93,"tv":104.32,"id":8535963},{"batb":[[1,2.14,36.13],[2,2,28.25]],"batl":[[0,2.38,30.25],[1,2.72,241.55]],"ltp":2.14,"tv":58.17,"id":2309796}]}]}
{"op":"mcm","clk":"1005594660","pt":1580643503155,"mc":[{"id":"1.168219390","rc":[{"batb":[[0,1.51,38.63],[1,1.01,10.52],[2,1.51,0]],"batl":[[0,2.3,309.75],[1,1.82,0],[2,1.88,0]],"ltp":1.93,"tv":104.32,"id":8535963},{"batb":[[0,2,28.25],[1,1.01,10.52],[2,2,0]],"batl":[[0,2.72,241.55],[1,2.72,0]],"ltp":2.14,"tv":58.17,"id":2309796}]}]}
{"op":"mcm","clk":"1005595259","pt":1580643505835,"mc":[{"id":"1.168219390","rc":[{"batb":[[0,1.51,177.63],[1,1.5,183.74],[2,1.01,10.52]],"batl":[[0,1.99,113.74],[1,2.02,203.84],[2,2.3,309.75]],"ltp":1.93,"tv":104.32,"id":8535963}]}]}
{"op":"mcm","clk":"1005595648","pt":1580643507451,"mc":[{"id":"1.168219390","rc":[{"batb":[[0,1.51,38.63],[1,1.01,10.52],[2,1.01,0]],"batl":[[0,2.3,309.75],[1,2.02,0],[2,2.3,0]],"ltp":1.93,"tv":104.32,"id":8535963}]}]}
{"op":"mcm","clk":"1005596726","pt":1580643512581,"mc":[{"id":"1.168219390","rc":[{"batl":[[0,3.15,200.42]],"ltp":2.14,"tv":58.17,"id":2309796}]}]}
{"op":"mcm","clk":"1005596832","pt":1580643512956,"mc":[{"id":"1.168219390","rc":[{"batb":[[0,1.51,177.63],[1,1.5,183.74],[2,1.01,10.52]],"batl":[[0,1.99,113.74],[1,2.02,203.84],[2,2.3,309.75]],"ltp":1.93,"tv":104.32,"id":8535963}]}]}
{"op":"mcm","clk":"1005597637","pt":1580643516788,"mc":[{"id":"1.168219390","rc":[{"batl":[[0,2.3,309.75],[1,2.02,0],[2,2.3,0]],"ltp":1.93,"tv":104.32,"id":8535963}]}]}
{"op":"mcm","clk":"1005598484","pt":1580643520607,"mc":[{"id":"1.168219390","rc":[{"batb":[[0,1.53,78.98],[1,1.51,177.63],[2,1.5,183.74]],"batl":[[0,1.56,254.66],[1,1.57,151.57],[2,1.64,42.01]],"ltp":1.93,"tv":104.32,"id":8535963},{"batb":[[0,2.76,11.33],[1,2.56,26.89],[2,2.26,19.59]],"batl":[[0,2.88,21.85]],"ltp":2.14,"tv":58.17,"id":2309796}]}]}
{"op":"mcm","clk":"1005598918","pt":1580643522593,"mc":[{"id":"1.168219390","rc":[{"batl":[[1,3.9,158.24]],"ltp":2.14,"tv":58.17,"id":2309796}]}]}
{"op":"mcm","clk":"1005600556","pt":1580643529708,"mc":[{"id":"1.168219390","rc":[{"batb":[[1,1.28,80.19],[2,1.01,10.51]],"batl":[[0,1.64,42.01],[1,1.95,409.86],[2,1.64,0]],"ltp":1.93,"tv":104.32,"id":8535963},{"batb":[[0,2.56,26.89],[1,2.26,19.59],[2,1.01,10.52]],"ltp":2.14,"tv":58.17,"id":2309796}]}]}
{"op":"mcm","clk":"1005600840","pt":1580643531106,"mc":[{"id":"1.168219390","rc":[{"batb":[[0,1.28,80.19],[1,1.01,10.51],[2,1.01,0]],"batl":[[0,1.95,409.86],[1,1.95,0]],"ltp":1.93,"tv":104.32,"id":8535963},{"batb":[[0,2.26,19.59],[1,1.01,10.52],[2,1.01,0]],"batl":[[0,3.9,158.24],[1,3.9,0]],"ltp":2.14,"tv":58.17,"id":2309796}]}]}
{"op":"mcm","clk":"1005601401","pt":1580643533703,"mc":[{"id":"1.168219390","rc":[{"batb":[[0,1.45,261.57],[1,1.44,218.6],[2,1.28,80.18]],"batl":[[0,1.5,260.31],[1,1.51,175.47],[2,1.95,409.86]],"ltp":1.93,"tv":104.32,"id":8535963}]}]}
{"op":"mcm","clk":"1005601954","pt":1580643536110,"mc":[{"id":"1.168219390","rc":[{"batb":[[0,1.28,80.19],[1,1.01,10.51],[2,1.28,0]],"batl":[[0,1.95,409.86],[1,1.51,0],[2,1.95,0]],"ltp":1.93,"tv":104.32,"id":8535963}]}]}
{"op":"mcm","clk":"1005602547","pt":1580643539101,"mc":[{"id":"1.168219390","rc":[{"batb":[[1,1.27,234.61],[2,1.26,422.79]],"batl":[[0,1.79,183.78],[1,1.81,188.57],[2,1.95,409.86]],"ltp":1.93,"tv":104.32,"id":8535963}]}]}
{"op":"mcm","clk":"1005603921","pt":1580643545703,"mc":[{"id":"1.168219390","rc":[{"batb":[[1,1.01,10.51],[2,1.26,0]],"ltp":1.93,"tv":104.32,"id":8535963}]}]}
{"op":"mcm","clk":"1005604359","pt":1580643547718,"mc":[{"id":"1.168219390","rc":[{"batl":[[2,1.95,0]],"ltp":1.93,"tv":104.32,"id":8535963}]}]}
{"op":"mcm","clk":"1005604571","pt":1580643548714,"mc":[{"id":"1.168219390","rc":[{"batb":[[0,1.72,160.57],[1,1.7,230.19],[2,1.28,80.19]],"ltp":1.93,"tv":104.32,"id":8535963}]}]}
{"op":"mcm","clk":"1005604728","pt":1580643549505,"mc":[{"id":"1.168219390","rc":[{"batb":[[0,1.72,184.73],[2,1.51,38.71]],"ltp":1.93,"tv":104.32,"id":8535963},{"batb":[[1,2.02,27.54],[2,1.01,10.52]],"ltp":2.14,"tv":58.17,"id":2309796}]}]}
{"op":"mcm","clk":"1005604851","pt":1580643550134,"mc":[{"id":"1.168219390","rc":[{"batb":[[0,1.72,242.7]],"batl":[[2,1.85,42.01]],"ltp":1.93,"tv":104.32,"id":8535963},{"batb":[[1,2.16,36.13],[2,2.02,27.54]],"batl":[[0,2.38,30.25]],"ltp":2.14,"tv":58.17,"id":2309796}]}]}
{"op":"mcm","clk":"1005605089","pt":1580643551106,"mc":[{"id":"1.168219390","rc":[{"batl":[[1,3,213.45]],"ltp":2.14,"tv":58.17,"id":2309796}]}]}
{"op":"mcm","clk":"1005609510","pt":1580643572656,"mc":[{"id":"1.168219390","rc":[{"batb":[[0,1.72,82.13],[1,1.51,38.71],[2,1.01,10.52]],"batl":[[0,1.85,42.01],[1,2.3,309.75],[2,1.85,0]],"ltp":1.93,"tv":104.32,"id":8535963}]}]}
{"op":"mcm","clk":"1005609707","pt":1580643573562,"mc":[{"id":"1.168219390","rc":[{"batb":[[0,1.51,38.71],[1,1.01,10.52],[2,1.01,0]],"batl":[[0,2.3,309.75],[1,2.3,0]],"ltp":1.93,"tv":104.32,"id":8535963},{"batb":[[0,2.02,27.54],[1,1.01,10.52],[2,2.02,0]],"batl":[[0,3,213.45],[1,3,0]],"ltp":2.14,"tv":58.17,"id":2309796}]}]}
{"op":"mcm","clk":"1005610048","pt":1580643575266,"mc":[{"id":"1.168219390","rc":[{"batb":[[1,1.5,214.22],[2,1.49,189.28]],"batl":[[0,1.98,119.55],[1,2,139.26],[2,2.3,309.75]],"ltp":1.93,"tv":104.32,"id":8535963}]}]}
{"op":"mcm","clk":"1005610469","pt":1580643577386,"mc":[{"id":"1.168219390","rc":[{"batl":[[0,2.3,309.75],[1,2,0],[2,2.3,0]],"ltp":1.93,"tv":104.32,"id":8535963}]}]}
{"op":"mcm","clk":"1005611135","pt":1580643580594,"mc":[{"id":"1.168219390","rc":[{"batl":[[0,1.55,201.9],[1,1.56,155.5]],"ltp":1.93,"tv":104.32,"id":8535963}]}]}
{"op":"mcm","clk":"1005611253","pt":1580643581081,"mc":[{"id":"1.168219390","rc":[{"batb":[[0,2.78,11.33],[1,2.28,19.36],[2,1.01,10.52]],"ltp":2.14,"tv":58.17,"id":2309796}]}]}
{"op":"mcm","clk":"1005611482","pt":1580643582209,"mc":[{"id":"1.168219390","rc":[{"batb":[[0,1.53,78.98],[1,1.51,38.71],[2,1.5,214.22]],"batl":[[2,1.64,42.01]],"ltp":1.93,"tv":104.32,"id":8535963},{"batb":[[1,2.58,26.05],[2,2.28,19.36]],"batl":[[0,2.9,21.85]],"ltp":2.14,"tv":58.17,"id":2309796}]}]}
{"op":"mcm","clk":"1005611799","pt":1580643583692,"mc":[{"id":"1.168219390","rc":[{"batl":[[1,3.9,158.24]],"ltp":2.14,"tv":58.17,"id":2309796}]}]}
{"op":"mcm","clk":"1005613698","pt":1580643592711,"mc":[{"id":"1.168219390","rc":[{"batb":[[2,1.28,80.11]],"batl":[[0,1.64,42.01],[1,1.95,409.86],[2,1.64,0]],"ltp":1.93,"tv":104.32,"id":8535963}]}]}
{"op":"mcm","clk":"1005613874","pt":1580643593524,"mc":[{"id":"1.168219390","rc":[{"batb":[[0,1.28,80.11],[1,1.01,10.51],[2,1.28,0]],"batl":[[0,1.95,409.86],[1,1.95,0]],"ltp":1.93,"tv":104.32,"id":8535963},{"batb":[[0,2.28,19.36],[1,1.01,10.52],[2,2.28,0]],"batl":[[0,3.9,158.24],[1,3.9,0]],"ltp":2.14,"tv":58.17,"id":2309796}]}]}
{"op":"mcm","clk":"1005614305","pt":1580643595712,"mc":[{"id":"1.168219390","rc":[{"batb":[[1,1.26,548.17],[2,1.25,450.68]],"batl":[[0,1.78,175.79],[1,1.8,191.96],[2,1.95,409.86]],"ltp":1.93,"tv":104.32,"id":8535963}]}]}
{"op":"mcm","clk":"1005614383","pt":1580643596136,"mc":[{"id":"1.168219390","rc":[{"batb":[[1,1.01,10.51],[2,1.25,0]],"batl":[[0,1.95,409.86],[1,1.8,0],[2,1.95,0]],"ltp":1.93,"tv":104.32,"id":8535963}]}]}
{"op":"mcm","clk":"1005614748","pt":1580643597691,"mc":[{"id":"1.168219390","rc":[{"batb":[[0,1.45,152.83],[1,1.44,217.65],[2,1.28,80.1]],"batl":[[0,1.49,181.91],[1,1.5,180.68],[2,1.95,409.86]],"ltp":1.93,"tv":104.32,"id":8535963}]}]}
{"op":"mcm","clk":"1005615515","pt":1580643601495,"mc":[{"id":"1.168219390","rc":[{"batb":[[0,1.28,80.11],[1,1.01,10.51],[2,1.28,0]],"batl":[[0,1.95,409.86],[1,1.5,0],[2,1.95,0]],"ltp":1.93,"tv":104.32,"id":8535963}]}]}
{"op":"mcm","clk":"1005616112","pt":1580643604235,"mc":[{"id":"1.168219390","rc":[{"batb":[[1,1.26,552.08],[2,1.25,450.7]],"batl":[[0,1.78,173.05],[1,1.8,191.96],[2,1.95,409.86]],"ltp":1.93,"tv":104.32,"id":8535963}]}]}
{"op":"mcm","clk":"1005618845","pt":1580643618327,"mc":[{"id":"1.168219390","rc":[{"batl":[[0,1.95,409.86],[1,1.8,0],[2,1.95,0]],"ltp":1.93,"tv":104.32,"id":8535963}]}]}
{"op":"mcm","clk":"1005619515","pt":1580643621528,"mc":[{"id":"1.168219390","rc":[{"trd":[[1.48,0.02]],"batb":[[0,1.28,80.1]],"batl":[[0,1.3,448.32],[1,1.31,324.73]],"ltp":1.48,"tv":104.34,"id":8535963}],"tv":162.52}]}
{"op":"mcm","clk":"1005619746","pt":1580643622650,"mc":[{"id":"1.168219390","rc":[{"batb":[[0,1.28,229.65]],"ltp":1.48,"tv":104.34,"id":8535963},{"batb":[[0,4,22.11],[1,3.35,17.15],[2,1.01,10.52]],"batl":[[0,4.5,11.76]],"ltp":2.14,"tv":58.17,"id":2309796}]}]}
{"op":"mcm","clk":"1005619935","pt":1580643623627,"mc":[{"id":"1.168219390","rc":[{"batl":[[2,1.66,579.81]],"ltp":1.48,"tv":104.34,"id":8535963},{"batl":[[1,6,106.18]],"ltp":2.14,"tv":58.17,"id":2309796}]}]}
{"op":"mcm","clk":"1005620151","pt":1580643624741,"mc":[{"id":"1.168219390","rc":[{"batl":[[2,1.34,42.01]],"ltp":1.48,"tv":104.34,"id":8535963},{"batb":[[1,3.9,14.28],[2,3.35,17.15]],"ltp":2.14,"tv":58.17,"id":2309796}]}]}
{"op":"mcm","clk":"1005626651","pt":1580643658416,"mc":[{"id":"1.168219390","rc":[{"batb":[[1,1.23,99.53],[2,1.01,10.51]],"batl":[[0,1.34,42.01],[1,1.66,579.81],[2,1.34,0]],"ltp":1.48,"tv":104.34,"id":8535963}]}]}
{"op":"mcm","clk":"1005627287","pt":1580643661750,"mc":[{"id":"1.168219390","rc":[{"batb":[[2,1.22,577.25]],"batl":[[1,1.39,356.54],[2,1.4,238.36]],"ltp":1.48,"tv":104.34,"id":8535963},{"batb":[[0,4.1,459.34],[1,4,22.11],[2,3.9,14.28]],"ltp":2.14,"tv":58.17,"id":2309796}]}]}
{"op":"mcm","clk":"1005633618","pt":1580643693456,"mc":[{"id":"1.168219390","rc":[{"batb":[[0,1.28,149.55]],"ltp":1.48,"tv":104.34,"id":8535963},{"batb":[[1,3.9,14.28],[2,3.35,17.15]],"ltp":2.14,"tv":58.17,"id":2309796}]}]}
{"op":"mcm","clk":"1005634034","pt":1580643695330,"mc":[{"id":"1.168219390","rc":[{"batb":[[0,1.23,99.53],[1,1.22,577.25],[2,1.21,527.31]],"batl":[[0,1.39,356.54],[1,1.4,238.36],[2,1.66,579.81]],"ltp":1.48,"tv":104.34,"id":8535963},{"batb":[[1,3.35,17.15],[2,1.01,10.52]],"batl":[[0,6,106.18],[1,6,0]],"ltp":2.14,"tv":58.17,"id":2309796}]}]}
{"op":"mcm","clk":"1005634234","pt":1580643696446,"mc":[{"id":"1.168219390","rc":[{"batb":[[0,3.35,17.15],[1,1.01,10.52],[2,1.01,0]],"ltp":2.14,"tv":58.17,"id":2309796}]}]}
{"op":"mcm","clk":"1005637225","pt":1580643711221,"mc":[{"id":"1.168219390","rc":[{"batl":[[0,1.66,579.81],[1,1.4,0],[2,1.66,0]],"ltp":1.48,"tv":104.34,"id":8535963}]}]}
{"op":"mcm","clk":"1005637922","pt":1580643714750,"mc":[{"id":"1.168219390","rc":[{"batl":[[0,1.25,298.06],[1,1.26,404.41]],"ltp":1.48,"tv":104.34,"id":8535963},{"batb":[[0,3.9,482.96],[1,3.35,17.15],[2,1.01,10.52]],"ltp":2.14,"tv":58.17,"id":2309796}]}]}
{"op":"mcm","clk":"1005638023","pt":1580643715247,"mc":[{"id":"1.168219390","rc":[{"batb":[[0,4.6,16.05],[1,3.85,24.55]],"ltp":2.14,"tv":58.17,"id":2309796}]}]}
{"op":"mcm","clk":"1005638332","pt":1580643716576,"mc":[{"id":"1.168219390","rc":[{"batb":[[0,1.24,168.04],[1,1.23,99.53],[2,1.22,577.25]],"batl":[[2,1.3,42.01]],"ltp":1.48,"tv":104.34,"id":8535963},{"batb":[[1,4.4,11.76],[2,3.85,24.55]],"batl":[[0,5.1,10.08]],"ltp":2.14,"tv":58.17,"id":2309796}]}]}
{"op":"mcm","clk":"1005638579","pt":1580643717659,"mc":[{"id":"1.168219390","rc":[{"batl":[[1,7.2,92.18]],"ltp":2.14,"tv":58.17,"id":2309796}]}]}
{"op":"mcm","clk":"1005641584","pt":1580643732385,"mc":[{"id":"1.168219390","rc":[{"batb":[[1,1.2,119.99],[2,1.01,10.51]],"batl":[[0,1.3,42.01],[1,1.58,650.58],[2,1.3,0]],"ltp":1.48,"tv":104.34,"id":8535963},{"batb":[[0,4.4,11.76],[1,3.85,24.55],[2,1.01,10.52]],"ltp":2.14,"tv":58.17,"id":2309796}]}]}
{"op":"mcm","clk":"1005641769","pt":1580643733502,"mc":[{"id":"1.168219390","rc":[{"batb":[[0,1.2,119.99],[1,1.01,10.51],[2,1.01,0]],"batl":[[0,1.58,650.58],[1,1.58,0]],"ltp":1.48,"tv":104.34,"id":8535963},{"batb":[[0,3.85,24.55],[1,1.01,10.52],[2,1.01,0]],"batl":[[0,7.2,92.18],[1,7.2,0]],"ltp":2.14,"tv":58.17,"id":2309796}]}]}
{"op":"mcm","clk":"1005642058","pt":1580643734977,"mc":[{"id":"1.168219390","rc":[{"batb":[[1,1.19,670.91],[2,1.18,460.93]],"batl":[[0,1.32,424.49],[1,1.33,301.36],[2,1.58,650.58]],"ltp":1.48,"tv":104.34,"id":8535963}]}]}
{"op":"mcm","clk":"1005644839","pt":1580643749225,"mc":[{"id":"1.168219390","rc":[{"batl":[[0,1.58,650.58],[1,1.33,0],[2,1.58,0]],"ltp":1.48,"tv":104.34,"id":8535963}]}]}
{"op":"mcm","clk":"1005645080","pt":1580643750520,"mc":[{"id":"1.168219390","rc":[{"batb":[[0,1.19,670.91],[1,1.18,460.93],[2,1.01,10.51]],"ltp":1.48,"tv":104.34,"id":8535963}]}]}
{"op":"mcm","clk":"1005645481","pt":1580643752449,"mc":[{"id":"1.168219390","rc":[{"batl":[[0,1.22,434.92],[1,1.23,463.22],[2,1.58,650.58]],"ltp":1.48,"tv":104.34,"id":8535963}]}]}
{"op":"mcm","clk":"1005645631","pt":1580643753249,"mc":[{"id":"1.168219390","rc":[{"batb":[[0,1.19,792.87],[2,1.17,139.66]],"ltp":1.48,"tv":104.34,"id":8535963},{"batb":[[0,5.2,11.88],[1,4.5,16.92],[2,1.01,10.52]],"ltp":2.14,"tv":58.17,"id":2309796}]}]}
{"op":"mcm","clk":"1005645929","pt":1580643754652,"mc":[{"id":"1.168219390","rc":[{"batb":[[0,1.21,168.04],[1,1.19,792.87],[2,1.18,460.93]],"batl":[[2,1.26,42.01]],"ltp":1.48,"tv":104.34,"id":8535963},{"batb":[[1,4.9,10.08],[2,4.5,16.92]],"batl":[[0,5.8,8.4]],"ltp":2.14,"tv":58.17,"id":2309796}]}]}
{"op":"mcm","clk":"1005645996","pt":1580643754956,"mc":[{"id":"1.168219390","rc":[{"batl":[[1,8.6,81.89]],"ltp":2.14,"tv":58.17,"id":2309796}]}]}
{"op":"mcm","clk":"1005646603","pt":1580643757764,"mc":[{"id":"1.168219390","rc":[{"batb":[[1,1.19,693.76]],"ltp":1.48,"tv":104.34,"id":8535963}]}]}
{"op":"mcm","clk":"1005647194","pt":1580643760643,"mc":[{"id":"1.168219390","rc":[{"batb":[[2,1.18,560.88]],"batl":[[0,1.22,531.67]],"ltp":1.48,"tv":104.34,"id":8535963}]}]}
{"op":"mcm","clk":"1005647316","pt":1580643761234,"mc":[{"id":"1.168219390","rc":[{"batb":[[0,1.19,693.76],[1,1.18,560.88],[2,1.17,139.66]],"batl":[[2,1.58,650.58]],"ltp":1.48,"tv":104.34,"id":8535963}]}]}
{"op":"mcm","clk":"1005647814","pt":1580643763879,"mc":[{"id":"1.168219390","rc":[{"batl":[[2,1.25,42.01]],"ltp":1.48,"tv":104.34,"id":8535963}]}]}
{"op":"mcm","clk":"1005648468","pt":1580643767253,"mc":[{"id":"1.168219390","rc":[{"batl":[[2,1.58,650.58]],"ltp":1.48,"tv":104.34,"id":8535963}]}]}
{"op":"mcm","clk":"1005649081","pt":1580643770671,"mc":[{"id":"1.168219390","rc":[{"batb":[[0,1.21,168.04],[1,1.19,693.76],[2,1.18,560.88]],"batl":[[2,1.26,42.01]],"ltp":1.48,"tv":104.34,"id":8535963}]}]}
{"op":"mcm","clk":"1005649272","pt":1580643771643,"mc":[{"id":"1.168219390","rc":[{"batb":[[0,1.17,139.66],[1,1.01,10.51],[2,1.18,0]],"batl":[[0,1.58,650.58],[1,1.23,0],[2,1.26,0]],"ltp":1.48,"tv":104.34,"id":8535963},{"batb":[[0,4.5,16.44],[1,1.01,10.52],[2,4.5,0]],"batl":[[0,8.6,81.89],[1,8.6,0]],"ltp":2.14,"tv":58.17,"id":2309796}]}]}
{"op":"mcm","clk":"1005649672","pt":1580643773667,"mc":[{"id":"1.168219390","rc":[{"batb":[[0,1.19,47.77],[1,1.17,139.66],[2,1.01,10.51]],"ltp":1.48,"tv":104.34,"id":8535963}]}]}
{"op":"mcm","clk":"1005649838","pt":1580643774466,"mc":[{"id":"1.168219390","rc":[{"batb":[[0,1.17,936.73],[1,1.16,353.2]],"batl":[[0,1.26,448.64],[1,1.27,384.46],[2,1.58,650.58]],"ltp":1.48,"tv":104.34,"id":8535963}]}]}
{"op":"mcm","clk":"1005650274","pt":1580643776757,"mc":[{"id":"1.168219390","rc":[{"batb":[[0,1.17,139.66],[1,1.01,10.51],[2,1.01,0]],"batl":[[0,1.58,650.58],[1,1.27,0],[2,1.58,0]],"ltp":1.48,"tv":104.34,"id":8535963}]}]}
{"op":"mcm","clk":"1005651025","pt":1580643780671,"mc":[{"id":"1.168219390","rc":[{"batb":[[0,1.23,445.82],[1,1.22,520.94],[2,1.19,122.04]],"batl":[[0,1.26,448.64],[1,1.27,384.46],[2,1.29,42.01]],"ltp":1.48,"tv":104.34,"id":8535963},{"batb":[[1,4.4,11.76],[2,3.75,13.14]],"ltp":2.14,"tv":58.17,"id":2309796}]}]}
{"op":"mcm","clk":"1005651135","pt":1580643781258,"mc":[{"id":"1.168219390","rc":[{"batb":[[0,1.24,168.04],[1,1.23,445.82],[2,1.22,520.94]],"ltp":1.48,"tv":104.34,"id":8535963},{"batl":[[0,5.1,10.08]],"ltp":2.14,"tv":58.17,"id":2309796}]}]}
{"op":"mcm","clk":"1005651317","pt":1580643782168,"mc":[{"id":"1.168219390","rc":[{"batl":[[1,7.2,92.18]],"ltp":2.14,"tv":58.17,"id":2309796}]}]}
{"op":"mcm","clk":"1005654306","pt":1580643797484,"mc":[{"id":"1.168219390","rc":[{"batb":[[0,1.19,122.04],[1,1.01,10.51],[2,1.22,0]],"batl":[[0,1.58,650.58],[1,1.27,0],[2,1.29,0]],"ltp":1.48,"tv":104.34,"id":8535963},{"batb":[[0,3.75,13.14],[1,1.01,10.52],[2,3.75,0]],"batl":[[0,7.2,92.18],[1,7.2,0]],"ltp":2.14,"tv":58.17,"id":2309796}]}]}
{"op":"mcm","clk":"1005654803","pt":1580643799902,"mc":[{"id":"1.168219390","rc":[{"batb":[[0,1.19,729.7],[1,1.18,524.72],[2,1.01,10.51]],"batl":[[0,1.34,390.19],[1,1.35,281.87],[2,1.58,650.58]],"ltp":1.48,"tv":104.34,"id":8535963}]}]}
{"op":"mcm","clk":"1005656004","pt":1580643806078,"mc":[{"id":"1.168219390","rc":[{"batl":[[0,1.58,650.58],[1,1.35,0],[2,1.58,0]],"ltp":1.48,"tv":104.34,"id":8535963}]}]}
{"op":"mcm","clk":"1005656690","pt":1580643809766,"mc":[{"id":"1.168219390","rc":[{"batb":[[2,1.17,140.68]],"batl":[[0,1.22,495.79],[1,1.23,463],[2,1.58,650.58]],"ltp":1.48,"tv":104.34,"id":8535963},{"batb":[[0,5.2,11.8],[1,4.6,16.29],[2,1.01,10.52]],"ltp":2.14,"tv":58.17,"id":2309796}]}]}
{"op":"mcm","clk":"1005656799","pt":1580643810353,"mc":[{"id":"1.168219390","rc":[{"batb":[[0,1.21,168.04],[1,1.19,729.7],[2,1.18,524.72]],"batl":[[2,1.25,42.01]],"ltp":1.48,"tv":104.34,"id":8535963},{"batb":[[1,4.9,10.08],[2,4.6,16.29]],"batl":[[0,5.8,8.4]],"ltp":2.14,"tv":58.17,"id":2309796}]}]}
{"op":"mcm","clk":"1005657027","pt":1580643811580,"mc":[{"id":"1.168219390","rc":[{"batl":[[1,8.6,81.89]],"ltp":2.14,"tv":58.17,"id":2309796}]}]}
{"op":"mcm","clk":"1005659445","pt":1580643824666,"mc":[{"id":"1.168219390","rc":[{"batb":[[1,1.17,140.68],[2,1.01,10.51]],"batl":[[0,1.25,42.01],[1,1.58,650.58],[2,1.25,0]],"ltp":1.48,"tv":104.34,"id":8535963},{"batb":[[0,4.9,10.08],[1,4.6,16.29],[2,1.01,10.52]],"ltp":2.14,"tv":58.17,"id":2309796}]}]}
{"op":"mcm","clk":"1005659562","pt":1580643825361,"mc":[{"id":"1.168219390","rc":[{"batb":[[0,1.17,140.68],[1,1.01,10.51],[2,1.01,0]],"batl":[[0,1.58,650.58],[1,1.58,0]],"ltp":1.48,"tv":104.34,"id":8535963},{"batb":[[0,4.6,16.29],[1,1.01,10.52],[2,1.01,0]],"batl":[[0,8.6,81.89],[1,8.6,0]],"ltp":2.14,"tv":58.17,"id":2309796}]}]}
{"op":"mcm","clk":"1005659988","pt":1580643827385,"mc":[{"id":"1.168219390","rc":[{"batb":[[0,1.17,944.72],[1,1.16,346.17],[2,1.01,10.51]],"batl":[[0,1.26,528.62],[1,1.27,382.6],[2,1.58,650.58]],"ltp":1.48,"tv":104.34,"id":8535963}]}]}
{"op":"mcm","clk":"1005660352","pt":1580643829516,"mc":[{"id":"1.168219390","rc":[{"batl":[[0,1.58,650.58],[1,1.27,0],[2,1.58,0]],"ltp":1.48,"tv":104.34,"id":8535963}]}]}
{"op":"mcm","clk":"1005660950","pt":1580643832723,"mc":[{"id":"1.168219390","rc":[{"batl":[[0,1.2,512.11],[1,1.21,513.99]],"ltp":1.48,"tv":104.34,"id":8535963}]}]}
{"op":"mcm","clk":"1005661103","pt":1580643833520,"mc":[{"id":"1.168219390","rc":[{"batb":[[2,1.13,183.56]],"ltp":1.48,"tv":104.34,"id":8535963},{"batb":[[0,5.7,19.36],[1,5.1,12.43],[2,1.01,10.52]],"ltp":2.14,"tv":58.17,"id":2309796}]}]}
{"op":"mcm","clk":"1005661301","pt":1580643834717,"mc":[{"id":"1.168219390","rc":[{"batl":[[2,1.23,42.01]],"ltp":1.48,"tv":104.34,"id":8535963},{"batb":[[1,5.3,9.24],[2,5.1,12.43]],"batl":[[0,6.4,7.56]],"ltp":2.14,"tv":58.17,"id":2309796}]}]}
{"op":"mcm","clk":"1005661496","pt":1580643835721,"mc":[{"id":"1.168219390","rc":[{"batl":[[1,9.8,75.27]],"ltp":2.14,"tv":58.17,"id":2309796}]}]}
{"op":"mcm","clk":"1005667539","pt":1580643869608,"mc":[{"id":"1.168219390","rc":[{"trd":[[1.18,0.02]],"batb":[[0,1.17,140.68],[1,1.13,183.56],[2,1.01,10.51]],"batl":[[0,1.23,42.01],[1,1.49,761.67],[2,1.23,0]],"ltp":1.18,"tv":104.35,"id":8535963}],"tv":162.53}]}
{"op":"mcm","clk":"1005668058","pt":1580643872589,"mc":[{"id":"1.168219390","rc":[{"batb":[[1,1.14,394.86],[2,1.13,973.07]],"batl":[[0,1.23,564.49],[1,1.24,439.65],[2,1.49,761.67]],"ltp":1.18,"tv":104.35,"id":8535963}]}]}
{"op":"mcm","clk":"1005668937","pt":1580643877590,"mc":[{"id":"1.168219390","rc":[{"batb":[[0,1.14,394.86],[1,1.13,973.07],[2,1.01,10.51]],"batl":[[0,1.23,522.48]],"ltp":1.18,"tv":104.35,"id":8535963},{"batb":[[0,5.1,12.43],[1,1.01,10.52],[2,5.1,0]],"batl":[[0,9.8,75.27],[1,9.8,0]],"ltp":2.14,"tv":58.17,"id":2309796}]}]}
{"op":"mcm","clk":"1005670649","pt":1580643887315,"mc":[{"id":"1.168219390","rc":[{"batb":[[0,1.13,183.56],[1,1.01,10.51],[2,1.01,0]],"ltp":1.18,"tv":104.35,"id":8535963}]}]}
{"op":"mcm","clk":"1005671305","pt":1580643890706,"mc":[{"id":"1.168219390","rc":[{"batb":[[0,1.2,486.59],[1,1.19,623.42],[2,1.13,183.56]],"ltp":1.18,"tv":104.35,"id":8535963}]}]}
{"op":"mcm","clk":"1005671368","pt":1580643891082,"mc":[{"id":"1.168219390","rc":[{"batb":[[0,1.2,604.77],[2,1.16,148]],"ltp":1.18,"tv":104.35,"id":8535963},{"batb":[[1,4.7,15.19],[2,1.01,10.52]],"ltp":2.14,"tv":58.17,"id":2309796}]}]}
{"op":"mcm","clk":"1005671605","pt":1580643892418,"mc":[{"id":"1.168219390","rc":[{"batl":[[2,1.25,42.01]],"ltp":1.18,"tv":104.35,"id":8535963},{"batb":[[1,5,10.08],[2,4.7,15.19]],"batl":[[0,5.9,8.4]],"ltp":2.14,"tv":58.17,"id":2309796}]}]}
{"op":"mcm","clk":"1005671791","pt":1580643893330,"mc":[{"id":"1.168219390","rc":[{"batl":[[1,7.8,87.91]],"ltp":2.14,"tv":58.17,"id":2309796}]}]}
{"op":"mcm","clk":"1005673334","pt":1580643901728,"mc":[{"id":"1.168219390","rc":[{"batb":[[0,1.2,118.18],[1,1.16,148],[2,1.01,10.51]],"batl":[[0,1.25,42.01],[1,1.49,761.67],[2,1.25,0]],"ltp":1.18,"tv":104.35,"id":8535963}]}]}
{"op":"mcm","clk":"1005673482","pt":1580643902535,"mc":[{"id":"1.168219390","rc":[{"batb":[[0,1.16,148],[1,1.01,10.51],[2,1.01,0]],"ltp":1.18,"tv":104.35,"id":8535963},{"batb":[[0,5,10.08],[1,4.7,15.19],[2,1.01,10.52]],"ltp":2.14,"tv":58.17,"id":2309796}]}]}
{"op":"mcm","clk":"1005673674","pt":1580643903409,"mc":[{"id":"1.168219390","rc":[{"batl":[[0,1.49,761.67],[1,1.49,0]],"ltp":1.18,"tv":104.35,"id":8535963},{"batb":[[0,4.7,15.19],[1,1.01,10.52],[2,1.01,0]],"batl":[[0,7.8,87.91],[1,7.8,0]],"ltp":2.14,"tv":58.17,"id":2309796}]}]}
{"op":"mcm","clk":"1005673990","pt":1580643904702,"mc":[{"id":"1.168219390","rc":[{"batb":[[0,1.17,375.9],[1,1.16,903.87],[2,1.01,10.51]],"batl":[[0,1.25,275.05],[1,1.26,405.89],[2,1.49,761.67]],"ltp":1.18,"tv":104.35,"id":8535963}]}]}
{"op":"mcm","clk":"1005674819","pt":1580643908719,"mc":[{"id":"1.168219390","rc":[{"batb":[[0,1.16,148],[1,1.01,10.51],[2,1.01,0]],"ltp":1.18,"tv":104.35,"id":8535963}]}]}
{"op":"mcm","clk":"1005675479","pt":1580643911742,"mc":[{"id":"1.168219390","rc":[{"batb":[[0,1.22,606],[1,1.21,498.32],[2,1.16,148]],"ltp":1.18,"tv":104.35,"id":8535963}]}]}
{"op":"mcm","clk":"1005675665","pt":1580643912711,"mc":[{"id":"1.168219390","rc":[{"batb":[[0,1.22,877.66],[2,1.2,120.07]],"batl":[[2,1.27,42.01]],"ltp":1.18,"tv":104.35,"id":8535963},{"batb":[[0,4.7,26.11],[1,4.4,17.47],[2,1.01,10.52]],"batl":[[0,5.5,9.24]],"ltp":2.14,"tv":58.17,"id":2309796}]}]}
{"op":"mcm","clk":"1005676042","pt":1580643914732,"mc":[{"id":"1.168219390","rc":[{"batl":[[1,7.2,92.18]],"ltp":2.14,"tv":58.17,"id":2309796}]}]}
{"op":"mcm","clk":"1005677791","pt":1580643923743,"mc":[{"id":"1.168219390","rc":[{"batb":[[0,1.22,168.04],[1,1.2,120.07],[2,1.01,10.51]],"batl":[[0,1.27,42.01],[1,1.49,761.67],[2,1.27,0]],"ltp":1.18,"tv":104.35,"id":8535963},{"batb":[[0,4.7,10.92]],"ltp":2.14,"tv":58.17,"id":2309796}]}]}
{"op":"mcm","clk":"1005677917","pt":1580643924464,"mc":[{"id":"1.168219390","rc":[{"batb":[[2,1.01,13.55]],"ltp":1.18,"tv":104.35,"id":8535963}]}]}
{"op":"mcm","clk":"1005678089","pt":1580643925428,"mc":[{"id":"1.168219390","rc":[{"batb":[[0,1.2,120.07],[1,1.01,10.51],[2,1.01,0]],"batl":[[0,1.49,761.67],[1,1.49,0]],"ltp":1.18,"tv":104.35,"id":8535963},{"batb":[[0,4.4,17.47],[1,1.01,10.52],[2,1.01,0]],"batl":[[0,7.2,92.18],[1,7.2,0]],"ltp":2.14,"tv":58.17,"id":2309796}]}]}
{"op":"mcm","clk":"1005678323","pt":1580643926655,"mc":[{"id":"1.168219390","rc":[{"batb":[[0,1.2,537],[1,1.19,621.03],[2,1.01,10.51]],"batl":[[0,1.27,339.74],[1,1.28,369.99],[2,1.49,761.67]],"ltp":1.18,"tv":104.35,"id":8535963}]}]}
{"op":"mcm","clk":"1005678384","pt":1580643926983,"mc":[{"id":"1.168219390","rc":[{"batb":[[0,1.2,120.07],[1,1.01,10.51],[2,1.01,0]],"batl":[[0,1.49,761.67],[1,1.28,0],[2,1.49,0]],"ltp":1.18,"tv":104.35,"id":8535963}]}]}
{"op":"mcm","clk":"1005678657","pt":1580643928370,"mc":[{"id":"1.168219390","rc":[{"batb":[[1,1.01,10.52]],"ltp":1.18,"tv":104.35,"id":8535963}]}]}
{"op":"mcm","clk":"1005679058","pt":1580643930462,"mc":[{"id":"1.168219390","rc":[{"batb":[[0,1.22,352.85],[1,1.21,550.09],[2,1.2,120.07]],"batl":[[0,1.25,503.26],[1,1.26,400.41],[2,1.49,761.67]],"ltp":1.18,"tv":104.35,"id":8535963}]}]}
{"op":"mcm","clk":"1005679469","pt":1580643932748,"mc":[{"id":"1.168219390","rc":[{"batb":[[0,1.2,120.07],[1,1.01,10.52],[2,1.2,0]],"batl":[[0,1.49,761.67],[1,1.26,0],[2,1.49,0]],"ltp":1.18,"tv":104.35,"id":8535963}]}]}
{"op":"mcm","clk":"1005679987","pt":1580643935668,"mc":[{"id":"1.168219390","rc":[{"batb":[[0,1.2,537],[1,1.19,621.03],[2,1.01,10.52]],"batl":[[0,1.27,339.74],[1,1.28,369.99],[2,1.49,761.67]],"ltp":1.18,"tv":104.35,"id":8535963}]}]}
{"op":"mcm","clk":"1005680046","pt":1580643935996,"mc":[{"id":"1.168219390","rc":[{"batb":[[0,1.2,120.07],[1,1.01,10.52],[2,1.01,0]],"ltp":1.18,"tv":104.35,"id":8535963}]}]}
{"op":"mcm","clk":"1005680602","pt":1580643938658,"mc":[{"id":"1.168219390","rc":[{"batb":[[0,1.24,404.85],[1,1.23,495.01],[2,1.2,120.07]],"ltp":1.18,"tv":104.35,"id":8535963}]}]}
{"op":"mcm","clk":"1005680796","pt":1580643939681,"mc":[{"id":"1.168219390","rc":[{"batb":[[0,1.24,499.03],[2,1.22,103.15]],"ltp":1.18,"tv":104.35,"id":8535963},{"batb":[[1,4.3,18.88],[2,1.01,10.52]],"ltp":2.14,"tv":58.17,"id":2309796}]}]}
{"op":"mcm","clk":"1005680922","pt":1580643940371,"mc":[{"id":"1.168219390","rc":[{"batb":[[1,1.23,663.05]],"batl":[[1,1.28,412]],"ltp":1.18,"tv":104.35,"id":8535963},{"batb":[[0,4.5,11.76],[1,4.4,17.47],[2,4.3,18.88]],"batl":[[0,5.3,9.24]],"ltp":2.14,"tv":58.17,"id":2309796}]}]}
{"op":"mcm","clk":"1005681159","pt":1580643941667,"mc":[{"id":"1.168219390","rc":[{"batl":[[1,6.6,98.95]],"ltp":2.14,"tv":58.17,"id":2309796}]}]}
{"op":"mcm","clk":"1005682418","pt":1580643948713,"mc":[{"id":"1.168219390","rc":[{"batb":[[0,1.24,94.18],[1,1.23,382.81]],"batl":[[0,1.28,362.2],[1,1.49,761.67],[2,1.49,0]],"ltp":1.18,"tv":104.35,"id":8535963}]}]}
{"op":"mcm","clk":"1005682563","pt":1580643949518,"mc":[{"id":"1.168219390","rc":[{"batb":[[0,1.23,214.77],[1,1.22,103.15],[2,1.01,10.52]],"batl":[[0,1.28,320.19]],"ltp":1.18,"tv":104.35,"id":8535963},{"batb":[[0,4.3,18.88],[1,1.01,10.52],[2,4.3,0]],"batl":[[0,6.6,98.95],[1,6.6,0]],"ltp":2.14,"tv":58.17,"id":2309796}]}]}
{"op":"mcm","clk":"1005683336","pt":1580643953415,"mc":[{"id":"1.168219390","rc":[{"batb":[[0,1.24,271.84],[1,1.23,491.5],[2,1.22,103.15]],"batl":[[0,1.27,460.83],[1,1.28,367.4],[2,1.49,761.67]],"ltp":1.18,"tv":104.35,"id":8535963}]}]}
{"op":"mcm","clk":"1005683746","pt":1580643955723,"mc":[{"id":"1.168219390","rc":[{"batb":[[0,1.23,214.77],[1,1.22,103.15],[2,1.01,10.52]],"batl":[[0,1.28,320.19],[1,1.49,761.67],[2,1.49,0]],"ltp":1.18,"tv":104.35,"id":8535963}]}]}
{"op":"mcm","clk":"1005684140","pt":1580643958021,"mc":[{"id":"1.168219390","rc":[{"batb":[[1,1.22,619.82]],"batl":[[1,1.29,356.52],[2,1.49,761.67]],"ltp":1.18,"tv":104.35,"id":8535963}]}]}
{"op":"mcm","clk":"1005684390","pt":1580643959410,"mc":[{"id":"1.168219390","rc":[{"batb":[[0,1.22,103.15],[1,1.01,10.52],[2,1.01,0]],"ltp":1.18,"tv":104.35,"id":8535963}]}]}
{"op":"mcm","clk":"1005685023","pt":1580643962698,"mc":[{"id":"1.168219390","rc":[{"batb":[[0,1.25,373.53],[1,1.24,637.55],[2,1.22,1937.49]],"batl":[[1,1.29,398.53]],"ltp":1.18,"tv":104.35,"id":8535963},{"batb":[[0,4.4,11.76],[1,4.3,18.88],[2,1.01,10.52]],"batl":[[0,5.2,9.24],[1,6.6,98.95]],"ltp":2.14,"tv":58.17,"id":2309796}]}]}
{"op":"mcm","clk":"1005685162","pt":1580643963397,"mc":[{"id":"1.168219390","rc":[{"batb":[[0,1.25,462.91],[2,1.2,113.77]],"ltp":1.18,"tv":104.35,"id":8535963},{"batb":[[2,3.45,16.05]],"ltp":2.14,"tv":58.17,"id":2309796}]}]}
{"op":"mcm","clk":"1005699595","pt":1580644049685,"mc":[{"id":"1.168219390","rc":[{"batb":[[0,1.24,168.04],[1,1.2,113.77],[2,1.01,10.52]],"batl":[[0,1.29,42.01],[1,1.49,761.67],[2,1.49,0]],"ltp":1.18,"tv":104.35,"id":8535963},{"batb":[[1,3.45,16.05],[2,1.01,10.52]],"ltp":2.14,"tv":58.17,"id":2309796}]}]}
{"op":"mcm","clk":"1005699889","pt":1580644051386,"mc":[{"id":"1.168219390","rc":[{"batb":[[0,1.2,113.77],[1,1.01,10.52],[2,1.01,0]],"batl":[[0,1.49,761.67],[1,1.49,0]],"ltp":1.18,"tv":104.35,"id":8535963},{"batb":[[0,3.45,16.05],[1,1.01,10.52],[2,1.01,0]],"batl":[[0,6.6,98.95],[1,6.6,0]],"ltp":2.14,"tv":58.17,"id":2309796}]}]}
{"op":"mcm","clk":"1005700041","pt":1580644052424,"mc":[{"id":"1.168219390","rc":[{"batb":[[0,1.21,224.15],[1,1.2,691.67],[2,1.01,10.52]],"batl":[[0,1.38,325.46],[1,1.39,246.73],[2,1.49,761.67]],"ltp":1.18,"tv":104.35,"id":8535963}]}]}
{"op":"mcm","clk":"1005703002","pt":1580644071431,"mc":[{"id":"1.168219390","rc":[{"batl":[[0,1.49,761.67],[1,1.39,0],[2,1.49,0]],"ltp":1.18,"tv":104.35,"id":8535963}]}]}
{"op":"mcm","clk":"1005703507","pt":1580644074340,"mc":[{"id":"1.168219390","rc":[{"batl":[[0,1.23,240.33],[1,1.24,446.87],[2,1.49,761.67]],"ltp":1.18,"tv":104.35,"id":8535963}]}]}
{"op":"mcm","clk":"1005703641","pt":1580644075142,"mc":[{"id":"1.168219390","rc":[{"batb":[[2,1.17,139.05]],"ltp":1.18,"tv":104.35,"id":8535963},{"batb":[[0,5,13.14],[1,4,21.95],[2,1.01,10.52]],"ltp":2.14,"tv":58.17,"id":2309796}]}]}
{"op":"mcm","clk":"1005703833","pt":1580644076463,"mc":[{"id":"1.168219390","rc":[{"batb":[[1,1.2,859.71]],"batl":[[2,1.25,42.01]],"ltp":1.18,"tv":104.35,"id":8535963},{"batb":[[0,5,23.22]],"batl":[[0,6,8.4]],"ltp":2.14,"tv":58.17,"id":2309796}]}]}
{"op":"mcm","clk":"1005704170","pt":1580644078569,"mc":[{"id":"1.168219390","rc":[{"batl":[[1,7.8,87.91]],"ltp":2.14,"tv":58.17,"id":2309796}]}]}
{"op":"mcm","clk":"1005706529","pt":1580644095599,"mc":[{"id":"1.168219390","rc":[{"batb":[[0,1.2,281.81],[1,1.17,139.05],[2,1.01,10.51]],"batl":[[0,1.25,42.01],[1,1.49,761.67],[2,1.25,0]],"ltp":1.18,"tv":104.35,"id":8535963}]}]}
{"op":"mcm","clk":"1005706651","pt":1580644096380,"mc":[{"id":"1.168219390","rc":[{"batb":[[0,1.2,168.04]],"ltp":1.18,"tv":104.35,"id":8535963},{"batb":[[0,5,10.08],[1,4,21.79]],"ltp":2.14,"tv":58.17,"id":2309796}]}]}
{"op":"mcm","clk":"1005706821","pt":1580644097594,"mc":[{"id":"1.168219390","rc":[{"batb":[[0,1.17,139.05],[1,1.01,10.51],[2,1.01,0]],"batl":[[0,1.49,761.67],[1,1.49,0]],"ltp":1.18,"tv":104.35,"id":8535963},{"batb":[[0,4,21.79],[1,1.01,10.52],[2,1.01,0]],"batl":[[0,7.8,87.91],[1,7.8,0]],"ltp":2.14,"tv":58.17,"id":2309796}]}]}
{"op":"mcm","clk":"1005706972","pt":1580644098559,"mc":[{"id":"1.168219390","rc":[{"batl":[[0,1.25,909.42],[1,1.49,761.67]],"ltp":1.18,"tv":104.35,"id":8535963}]}]}
{"op":"mcm","clk":"1005707075","pt":1580644099195,"mc":[{"id":"1.168219390","rc":[{"batl":[[0,1.49,761.67],[1,1.49,0]],"ltp":1.18,"tv":104.35,"id":8535963}]}]}
{"op":"mcm","clk":"1005707316","pt":1580644100488,"mc":[{"id":"1.168219390","rc":[{"batb":[[0,1.22,329.58],[1,1.21,548.99],[2,1.17,139.05]],"batl":[[0,1.25,525.4],[1,1.26,399.62],[2,1.49,761.67]],"ltp":1.18,"tv":104.35,"id":8535963}]}]}
{"op":"mcm","clk":"1005708051","pt":1580644105706,"mc":[{"id":"1.168219390","rc":[{"batb":[[0,1.17,139.05],[1,1.01,10.51],[2,1.17,0]],"batl":[[0,1.49,761.67],[1,1.26,0],[2,1.49,0]],"ltp":1.18,"tv":104.35,"id":8535963}]}]}
{"op":"mcm","clk":"1005708475","pt":1580644108699,"mc":[{"id":"1.168219390","rc":[{"batb":[[0,1.18,176.68],[1,1.17,834.68],[2,1.01,10.51]],"batl":[[0,1.3,263.39],[1,1.31,328.63],[2,1.49,761.67]],"ltp":1.18,"tv":104.35,"id":8535963}]}]}
{"op":"mcm","clk":"1005710464","pt":1580644123229,"mc":[{"id":"1.168219390","rc":[{"batl":[[0,1.49,761.67],[1,1.31,0],[2,1.49,0]],"ltp":1.18,"tv":104.35,"id":8535963}]}]}
{"op":"mcm","clk":"1005710931","pt":1580644126698,"mc":[{"id":"1.168219390","rc":[{"batb":[[1,1.17,1002.72]],"batl":[[0,1.2,451.2],[1,1.21,515.31],[2,1.49,761.67]],"ltp":1.18,"tv":104.35,"id":8535963},{"batb":[[0,5.6,8.4],[1,4,21.79],[2,1.01,10.52]],"batl":[[0,6.8,6.72]],"ltp":2.14,"tv":58.17,"id":2309796}]}]}
{"op":"mcm","clk":"1005710974","pt":1580644127012,"mc":[{"id":"1.168219390","rc":[{"batb":[[2,1.15,163.82]],"ltp":1.18,"tv":104.35,"id":8535963},{"batb":[[0,5.7,19.59],[1,5.6,8.4],[2,4.8,14.48]],"ltp":2.14,"tv":58.17,"id":2309796}]}]}
{"op":"mcm","clk":"1005711281","pt":1580644129225,"mc":[{"id":"1.168219390","rc":[{"batl":[[1,9.8,75.27]],"ltp":2.14,"tv":58.17,"id":2309796}]}]}
{"op":"mcm","clk":"1005713826","pt":1580644148491,"mc":[{"id":"1.168219390","rc":[{"batb":[[0,1.17,168.05],[1,1.15,163.82],[2,1.01,10.51]],"batl":[[0,1.49,761.67],[1,1.21,0],[2,1.49,0]],"ltp":1.18,"tv":104.35,"id":8535963},{"batb":[[0,5.6,8.4],[1,4.8,14.48],[2,1.01,10.52]],"ltp":2.14,"tv":58.17,"id":2309796}]}]}
{"op":"mcm","clk":"1005713956","pt":1580644149483,"mc":[{"id":"1.168219390","rc":[{"batb":[[0,1.15,163.83],[1,1.01,10.51],[2,1.01,0]],"ltp":1.18,"tv":104.35,"id":8535963},{"batb":[[0,4.8,14.48],[1,1.01,10.52],[2,1.01,0]],"batl":[[0,9.8,75.27],[1,9.8,0]],"ltp":2.14,"tv":58.17,"id":2309796}]}]}
{"op":"mcm","clk":"1005714116","pt":1580644150693,"mc":[{"id":"1.168219390","rc":[{"batb":[[0,1.16,274.61],[1,1.15,971.13],[2,1.01,10.51]],"batl":[[0,1.24,363.06],[1,1.25,422.77],[2,1.49,761.67]],"ltp":1.18,"tv":104.35,"id":8535963}]}]}
{"op":"mcm","clk":"1005714301","pt":1580644152100,"mc":[{"id":"1.168219390","rc":[{"batl":[[0,1.49,761.67],[1,1.25,0],[2,1.49,0]],"ltp":1.18,"tv":104.35,"id":8535963}]}]}
{"op":"mcm","clk":"1005714779","pt":1580644155613,"mc":[{"id":"1.168219390","rc":[{"trd":[[1.18,0.05]],"batb":[[0,1.16,274.59],[2,1.13,178.45]],"batl":[[0,1.18,507.92],[1,1.19,576.13],[2,1.49,761.67]],"ltp":1.18,"tv":104.39,"id":8535963},{"batb":[[0,6.4,15.19],[1,5.6,20.06],[2,4.8,14.48]],"ltp":2.14,"tv":58.17,"id":2309796}],"tv":162.57}]}
{"op":"mcm","clk":"1005714925","pt":1580644156725,"mc":[{"id":"1.168219390","rc":[{"batb":[[1,6.2,7.56],[2,5.6,20.06]],"batl":[[0,7.4,5.88]],"ltp":2.14,"tv":58.17,"id":2309796}]}]}
{"op":"mcm","clk":"1005715161","pt":1580644158411,"mc":[{"id":"1.168219390","rc":[{"batl":[[1,11.5,70.11]],"ltp":2.14,"tv":58.17,"id":2309796}]}]}
{"op":"mcm","clk":"1005716417","pt":1580644167538,"mc":[{"id":"1.168219390","rc":[{"batb":[[0,1.15,367.42],[1,1.13,178.45],[2,1.01,10.51]],"batl":[[0,1.49,761.67],[1,1.19,0],[2,1.49,0]],"ltp":1.18,"tv":104.39,"id":8535963},{"batb":[[0,5.6,20.06],[1,1.01,10.52],[2,5.6,0]],"batl":[[0,11.5,70.11],[1,11.5,0]],"ltp":2.14,"tv":58.17,"id":2309796}]}]}
{"op":"mcm","clk":"1005716757","pt":1580644170211,"mc":[{"id":"1.168219390","rc":[{"batb":[[1,1.14,802.06],[2,1.13,178.45]],"batl":[[0,1.2,482.86],[1,1.21,514.2],[2,1.49,761.67]],"ltp":1.18,"tv":104.39,"id":8535963}]}]}
{"op":"mcm","clk":"1005717098","pt":1580644172735,"mc":[{"id":"1.168219390","rc":[{"batb":[[1,1.13,178.45],[2,1.01,10.51]],"batl":[[0,1.49,761.67],[1,1.21,0],[2,1.49,0]],"ltp":1.18,"tv":104.39,"id":8535963}]}]}
{"op":"mcm","clk":"1005717503","pt":1580644175730,"mc":[{"id":"1.168219390","rc":[{"batb":[[1,1.14,802.06],[2,1.13,178.45]],"batl":[[0,1.17,511.7],[1,1.18,612.58],[2,1.49,761.67]],"ltp":1.18,"tv":104.39,"id":8535963}]}]}
{"op":"mcm","clk":"1005717613","pt":1580644176530,"mc":[{"id":"1.168219390","rc":[{"batl":[[1,1.18,654.59]],"ltp":1.18,"tv":104.39,"id":8535963},{"batb":[[0,6.8,13.22],[1,6.4,7.56],[2,6,16.84]],"batl":[[0,7.8,5.88],[1,11.5,70.11]],"ltp":2.14,"tv":58.17,"id":2309796}]}]}
{"op":"mcm","clk":"1005721611","pt":1580644206610,"mc":[{"id":"1.168219390","rc":[{"batb":[[0,1.1,232.35],[1,1.01,10.51],[2,1.13,0]],"batl":[[0,1.18,42.01],[1,1.49,761.67],[2,1.49,0]],"ltp":1.18,"tv":104.39,"id":8535963},{"batb":[[0,6.4,7.56],[1,6,16.84],[2,1.01,10.52]],"ltp":2.14,"tv":58.17,"id":2309796}]}]}
{"op":"mcm","clk":"1005721737","pt":1580644207601,"mc":[{"id":"1.168219390","rc":[{"batl":[[0,1.49,761.67],[1,1.49,0]],"ltp":1.18,"tv":104.39,"id":8535963},{"batb":[[0,6,16.84],[1,1.01,10.52],[2,1.01,0]],"batl":[[0,11.5,70.11],[1,11.5,0]],"ltp":2.14,"tv":58.17,"id":2309796}]}]}
{"op":"mcm","clk":"1005722246","pt":1580644211227,"mc":[{"id":"1.168219390","rc":[{"batb":[[0,1.14,681.24],[1,1.13,495.82],[2,1.1,232.35]],"batl":[[0,1.16,331.78],[1,1.17,661.43],[2,1.49,761.67]],"ltp":1.18,"tv":104.39,"id":8535963}]}]}
{"op":"mcm","clk":"1005722563","pt":1580644213503,"mc":[{"id":"1.168219390","rc":[{"batb":[[0,1.1,232.35],[1,1.01,10.51],[2,1.1,0]],"batl":[[0,1.49,761.67],[1,1.17,0],[2,1.49,0]],"ltp":1.18,"tv":104.39,"id":8535963}]}]}
{"op":"mcm","clk":"1005723610","pt":1580644219715,"mc":[{"id":"1.168219390","rc":[{"batb":[[0,1.17,488.52],[1,1.16,659.76],[2,1.1,232.35]],"batl":[[0,1.19,236.2],[1,1.2,552.87],[2,1.49,761.67]],"ltp":1.18,"tv":104.39,"id":8535963}]}]}
{"op":"mcm","clk":"1005723772","pt":1580644220608,"mc":[{"id":"1.168219390","rc":[{"batb":[[1,1.16,981.46],[2,1.13,187.26]],"batl":[[1,1.2,594.88]],"ltp":1.18,"tv":104.39,"id":8535963},{"batb":[[0,6,25.24],[1,5.6,20.06],[2,1.01,10.52]],"batl":[[0,7.2,6.72]],"ltp":2.14,"tv":58.17,"id":2309796}]}]}
{"op":"mcm","clk":"1005724211","pt":1580644223331,"mc":[{"id":"1.168219390","rc":[{"batl":[[1,9.8,75.27]],"ltp":2.14,"tv":58.17,"id":2309796}]}]}
{"op":"mcm","clk":"1005725603","pt":1580644232583,"mc":[{"id":"1.168219390","rc":[{"batb":[[0,1.16,168.04],[1,1.13,187.26],[2,1.01,10.51]],"batl":[[0,1.2,42.01],[1,1.49,761.67],[2,1.49,0]],"ltp":1.18,"tv":104.39,"id":8535963},{"batb":[[0,6,8.4]],"ltp":2.14,"tv":58.17,"id":2309796}]}]}
{"op":"mcm","clk":"1005725759","pt":1580644233573,"mc":[{"id":"1.168219390","rc":[{"batb":[[0,1.13,187.26],[1,1.01,10.51],[2,1.01,0]],"batl":[[0,1.49,761.67],[1,1.49,0]],"ltp":1.18,"tv":104.39,"id":8535963},{"batb":[[0,5.6,20.06],[1,1.01,10.52],[2,1.01,0]],"batl":[[0,9.8,75.27],[1,9.8,0]],"ltp":2.14,"tv":58.17,"id":2309796}]}]}
{"op":"mcm","clk":"1005726054","pt":1580644235569,"mc":[{"id":"1.168219390","rc":[{"batb":[[0,1.14,749.25],[1,1.13,614.47],[2,1.01,10.51]],"batl":[[0,1.21,214.6],[1,1.22,495.74],[2,1.49,761.67]],"ltp":1.18,"tv":104.39,"id":8535963}]}]}
{"op":"mcm","clk":"1005726102","pt":1580644235988,"mc":[{"id":"1.168219390","rc":[{"batb":[[0,1.13,187.26],[1,1.01,10.51],[2,1.01,0]],"ltp":1.18,"tv":104.39,"id":8535963}]}]}
{"op":"mcm","clk":"1005726607","pt":1580644239701,"mc":[{"id":"1.168219390","rc":[{"batb":[[0,1.19,367.45],[1,1.18,658.83],[2,1.17,137.46]],"ltp":1.18,"tv":104.39,"id":8535963},{"batb":[[1,5.4,11.17],[2,1.01,10.52]],"ltp":2.14,"tv":58.17,"id":2309796}]}]}
{"op":"mcm","clk":"1005726728","pt":1580644240506,"mc":[{"id":"1.168219390","rc":[{"batl":[[1,1.22,537.75]],"ltp":1.18,"tv":104.39,"id":8535963},{"batb":[[0,5.6,28.47]],"batl":[[0,6.8,6.72]],"ltp":2.14,"tv":58.17,"id":2309796}]}]}
{"op":"mcm","clk":"1005727007","pt":1580644242296,"mc":[{"id":"1.168219390","rc":[{"batl":[[1,8.6,81.89]],"ltp":2.14,"tv":58.17,"id":2309796}]}]}
{"op":"mcm","clk":"1005727326","pt":1580644244405,"mc":[{"id":"1.168219390","rc":[{"batb":[[0,1.15,156.66],[1,1.01,10.51],[2,1.17,0]],"batl":[[0,1.22,42.01],[1,1.49,761.67],[2,1.49,0]],"ltp":1.18,"tv":104.39,"id":8535963},{"batb":[[0,5.6,8.4]],"ltp":2.14,"tv":58.17,"id":2309796}]}]}
{"op":"mcm","clk":"1005727476","pt":1580644245512,"mc":[{"id":"1.168219390","rc":[{"batl":[[0,1.49,761.67],[1,1.49,0]],"ltp":1.18,"tv":104.39,"id":8535963},{"batb":[[0,5.4,11.17],[1,1.01,10.52],[2,1.01,0]],"batl":[[0,8.6,81.89],[1,8.6,0]],"ltp":2.14,"tv":58.17,"id":2309796}]}]}
{"op":"mcm","clk":"1005727808","pt":1580644247723,"mc":[{"id":"1.168219390","rc":[{"batb":[[0,1.17,393.47],[1,1.15,156.66],[2,1.01,10.51]],"ltp":1.18,"tv":104.39,"id":8535963}]}]}
{"op":"mcm","clk":"1005728138","pt":1580644249691,"mc":[{"id":"1.168219390","rc":[{"batb":[[0,1.18,767.5],[1,1.17,393.47],[2,1.15,156.66]],"batl":[[0,1.21,444.8],[1,1.22,488.67],[2,1.49,761.67]],"ltp":1.18,"tv":104.39,"id":8535963}]}]}
{"op":"mcm","clk":"1005728319","pt":1580644251000,"mc":[{"id":"1.168219390","rc":[{"batb":[[0,1.17,393.47],[1,1.15,156.66],[2,1.01,10.51]],"batl":[[0,1.49,761.67],[1,1.22,0],[2,1.49,0]],"ltp":1.18,"tv":104.39,"id":8535963}]}]}
{"op":"mcm","clk":"1005728707","pt":1580644253893,"mc":[{"id":"1.168219390","rc":[{"batb":[[1,1.16,755.61],[2,1.15,156.66]],"batl":[[0,1.23,484.73],[1,1.24,440.33],[2,1.49,761.67]],"ltp":1.18,"tv":104.39,"id":8535963}]}]}
{"op":"mcm","clk":"1005729429","pt":1580644259320,"mc":[{"id":"1.168219390","rc":[{"batl":[[0,1.49,761.67],[1,1.24,0],[2,1.49,0]],"ltp":1.18,"tv":104.39,"id":8535963}]}]}
{"op":"mcm","clk":"1005729876","pt":1580644262736,"mc":[{"id":"1.168219390","rc":[{"batb":[[1,1.16,923.65]],"batl":[[0,1.19,322.83],[1,1.2,591.93],[2,1.49,761.67]],"ltp":1.18,"tv":104.39,"id":8535963},{"batb":[[0,6,8.4],[1,5.5,2.78],[2,5.4,11.17]],"batl":[[0,7.2,6.72]],"ltp":2.14,"tv":58.17,"id":2309796}]}]}
{"op":"mcm","clk":"1005729973","pt":1580644263374,"mc":[{"id":"1.168219390","rc":[{"batb":[[0,6.2,16.29],[1,6,8.4],[2,5.6,20.06]],"ltp":2.14,"tv":58.17,"id":2309796}]}]}
{"op":"mcm","clk":"1005730285","pt":1580644265432,"mc":[{"id":"1.168219390","rc":[{"batl":[[1,9.8,75.27]],"ltp":2.14,"tv":58.17,"id":2309796}]}]}
{"op":"mcm","clk":"1005732455","pt":1580644281690,"mc":[{"id":"1.168219390","rc":[{"batb":[[0,1.16,168.04],[1,1.15,156.66],[2,1.12,200.09]],"batl":[[0,1.2,42.01],[1,1.49,761.67],[2,1.49,0]],"ltp":1.18,"tv":104.39,"id":8535963}]}]}
{"op":"mcm","clk":"1005732483","pt":1580644281889,"mc":[{"id":"1.168219390","rc":[{"batb":[[1,1.12,200.09],[2,1.01,10.51]],"ltp":1.18,"tv":104.39,"id":8535963},{"batb":[[0,6,8.4],[1,5.6,20.06],[2,1.01,10.52]],"ltp":2.14,"tv":58.17,"id":2309796}]}]}
{"op":"mcm","clk":"1005732745","pt":1580644283474,"mc":[{"id":"1.168219390","rc":[{"batb":[[0,1.12,200.09],[1,1.01,10.51],[2,1.01,0]],"batl":[[0,1.49,761.67],[1,1.49,0]],"ltp":1.18,"tv":104.39,"id":8535963},{"batb":[[0,5.6,20.06],[1,1.01,10.52],[2,1.01,0]],"batl":[[0,9.8,75.27],[1,9.8,0]],"ltp":2.14,"tv":58.17,"id":2309796}]}]}
{"op":"mcm","clk":"1005733388","pt":1580644287675,"mc":[{"id":"1.168219390","rc":[{"batb":[[0,1.16,661.29],[1,1.15,495.47],[2,1.12,200.09]],"batl":[[0,1.19,746.99],[1,1.2,373.31],[2,1.49,761.67]],"ltp":1.18,"tv":104.39,"id":8535963}]}]}
{"op":"mcm","clk":"1005733712","pt":1580644289783,"mc":[{"id":"1.168219390","rc":[{"batb":[[0,1.12,200.09],[1,1.01,10.51],[2,1.12,0]],"batl":[[0,1.49,761.67],[1,1.2,0],[2,1.49,0]],"ltp":1.18,"tv":104.39,"id":8535963}]}]}
{"op":"mcm","clk":"1005734093","pt":1580644292576,"mc":[{"id":"1.168219390","rc":[{"batb":[[0,1.14,254.19],[1,1.13,926.65],[2,1.12,200.09]],"batl":[[0,1.22,580.27],[1,1.23,459.58],[2,1.49,761.67]],"ltp":1.18,"tv":104.39,"id":8535963}]}]}
{"op":"mcm","clk":"1005734709","pt":1580644297133,"mc":[{"id":"1.168219390","rc":[{"batl":[[0,1.49,761.67],[1,1.23,0],[2,1.49,0]],"ltp":1.18,"tv":104.39,"id":8535963}]}]}
{"op":"mcm","clk":"1005735256","pt":1580644300712,"mc":[{"id":"1.168219390","rc":[{"batl":[[0,1.16,710.27],[1,1.17,480.45],[2,1.49,761.67]],"ltp":1.18,"tv":104.39,"id":8535963},{"batb":[[0,7.2,10.94],[1,6.8,6.72],[2,6,16.68]],"batl":[[0,8.4,5.04]],"ltp":2.14,"tv":58.17,"id":2309796}]}]}
{"op":"mcm","clk":"1005735703","pt":1580644303754,"mc":[{"id":"1.168219390","rc":[{"batl":[[1,12.5,65.97]],"ltp":2.14,"tv":58.17,"id":2309796}]}]}
{"op":"mcm","clk":"1005737302","pt":1580644315569,"mc":[{"id":"1.168219390","rc":[{"batb":[[0,1.07,316.69],[1,1.01,10.51],[2,1.12,0]],"batl":[[0,1.49,761.67],[1,1.17,0],[2,1.49,0]],"ltp":1.18,"tv":104.39,"id":8535963},{"batb":[[0,6,16.68],[1,1.01,10.52],[2,6,0]],"batl":[[0,12.5,65.97],[1,12.5,0]],"ltp":2.14,"tv":58.17,"id":2309796}]}]}
{"op":"mcm","clk":"1005737689","pt":1580644318499,"mc":[{"id":"1.168219390","rc":[{"batb":[[0,1.09,313.02],[1,1.08,921.94],[2,1.07,316.69]],"batl":[[0,1.2,650.91],[1,1.21,459.34],[2,1.49,761.67]],"ltp":1.18,"tv":104.39,"id":8535963}]}]}
{"op":"mcm","clk":"1005739061","pt":1580644328487,"mc":[{"id":"1.168219390","rc":[{"batb":[[0,1.07,316.69],[1,1.01,10.51],[2,1.07,0]],"batl":[[0,1.49,761.67],[1,1.21,0],[2,1.49,0]],"ltp":1.18,"tv":104.39,"id":8535963}]}]}
{"op":"mcm","clk":"1005739416","pt":1580644331378,"mc":[{"id":"1.168219390","rc":[{"batb":[[0,1.13,228.52],[1,1.12,963.09],[2,1.07,316.69]],"batl":[[0,1.15,845.15],[1,1.16,314.63],[2,1.49,761.67]],"ltp":1.18,"tv":104.39,"id":8535963}]}]}
{"op":"mcm","clk":"1005739834","pt":1580644334823,"mc":[{"id":"1.168219390","rc":[{"batb":[[0,1.07,316.69],[1,1.01,10.51],[2,1.07,0]],"batl":[[0,1.49,761.67],[1,1.16,0],[2,1.49,0]],"ltp":1.18,"tv":104.39,"id":8535963}]}]}
{"op":"mcm","clk":"1005740047","pt":1580644336621,"mc":[{"id":"1.168219390","rc":[{"trd":[[1.08,8.4]],"ltp":1.08,"tv":112.79,"id":8535963},{"trd":[[12.5,0.72]],"batl":[[0,12.5,65.25]],"ltp":12.5,"tv":58.9,"id":2309796}],"tv":171.69}]}
{"op":"mcm","clk":"1005740198","pt":1580644337726,"mc":[{"id":"1.168219390","rc":[{"batb":[[0,1.09,315.38],[1,1.08,919.56],[2,1.07,316.69]],"batl":[[0,1.2,648.75],[1,1.21,461.48],[2,1.49,761.67]],"ltp":1.08,"tv":112.79,"id":8535963}]}]}
{"op":"mcm","clk":"1005740883","pt":1580644342735,"mc":[{"id":"1.168219390","rc":[{"batl":[[0,1.49,761.67],[1,1.21,0],[2,1.49,0]],"ltp":1.08,"tv":112.79,"id":8535963}]}]}
{"op":"mcm","clk":"1005741267","pt":1580644345643,"mc":[{"id":"1.168219390","rc":[{"batl":[[0,1.1,371.77],[1,1.11,835.98]],"ltp":1.08,"tv":112.79,"id":8535963}]}]}
{"op":"mcm","clk":"1005741397","pt":1580644346633,"mc":[{"id":"1.168219390","rc":[{"batb":[[0,1.09,483.42]],"batl":[[2,1.12,42.01]],"ltp":1.08,"tv":112.79,"id":8535963},{"batb":[[0,10,13.14],[1,9.2,5.04],[2,7.2,11.17]],"batl":[[0,12,3.36]],"ltp":12.5,"tv":58.9,"id":2309796}]}]}
{"op":"mcm","clk":"1005741781","pt":1580644349321,"mc":[{"id":"1.168219390","rc":[{"batl":[[1,21,53.02]],"ltp":12.5,"tv":58.9,"id":2309796}]}]}
{"op":"mcm","clk":"1005744128","pt":1580644368278,"mc":[{"id":"1.168219390","rc":[{"trd":[[1.09,172]],"batb":[[0,1.09,397.42]],"ltp":1.09,"tv":284.79,"id":8535963}],"tv":343.69}]}
{"op":"mcm","clk":"1005744558","pt":1580644371376,"mc":[{"id":"1.168219390","rc":[{"batb":[[0,1.09,451.9]],"ltp":1.09,"tv":284.79,"id":8535963}]}]}
{"op":"mcm","clk":"1005745020","pt":1580644374653,"mc":[{"id":"1.168219390","rc":[{"batb":[[0,1.09,168.04],[1,1.07,316.69],[2,1.01,10.51]],"batl":[[0,1.12,42.01],[1,1.38,979.44],[2,1.12,0]],"ltp":1.09,"tv":284.79,"id":8535963}]}]}
{"op":"mcm","clk":"1005745155","pt":1580644375651,"mc":[{"id":"1.168219390","rc":[{"batb":[[0,1.01,10.51],[1,1.07,0],[2,1.01,0]],"batl":[[0,1.38,979.44],[1,1.38,0]],"ltp":1.09,"tv":284.79,"id":8535963},{"batb":[[0,7.2,11.17],[1,1.01,10.52],[2,7.2,0]],"batl":[[0,21,53.02],[1,21,0]],"ltp":12.5,"tv":58.9,"id":2309796}]}]}
{"op":"mcm","clk":"1005745416","pt":1580644377648,"mc":[{"id":"1.168219390","rc":[{"batb":[[0,1.02,1310.68],[1,1.01,10.51]],"batl":[[0,1.16,835.57],[1,1.17,314.21]],"ltp":1.09,"tv":284.79,"id":8535963}]}]}
{"op":"mcm","clk":"1005745660","pt":1580644379641,"mc":[{"id":"1.168219390","rc":[{"batb":[[0,1.01,10.51],[1,1.01,0]],"ltp":1.09,"tv":284.79,"id":8535963}]}]}
{"op":"mcm","clk":"1005746037","pt":1580644382681,"mc":[{"id":"1.168219390","rc":[{"batb":[[0,1.07,1249.44],[1,1.01,10.51]],"batl":[[0,1.09,1048.09]],"ltp":1.09,"tv":284.79,"id":8535963}]}]}
{"op":"mcm","clk":"1005746096","pt":1580644383050,"mc":[{"id":"1.168219390","rc":[{"batl":[[0,1.09,1001.36]],"ltp":1.09,"tv":284.79,"id":8535963}]}]}
{"op":"mcm","clk":"1005746276","pt":1580644384463,"mc":[{"id":"1.168219390","rc":[{"batb":[[0,1.01,10.51],[1,1.01,0]],"batl":[[0,1.37,1017.22]],"ltp":1.09,"tv":284.79,"id":8535963},{"batl":[[0,24,50.13]],"ltp":12.5,"tv":58.9,"id":2309796}]}]}
{"op":"mcm","clk":"1005746634","pt":1580644387365,"mc":[{"id":"1.168219390","rc":[{"batb":[[0,1.02,1310.68],[1,1.01,10.51]],"batl":[[0,1.16,791.47],[1,1.17,357.93]],"ltp":1.09,"tv":284.79,"id":8535963}]}]}
{"op":"mcm","clk":"1005748164","pt":1580644399707,"mc":[{"id":"1.168219390","rc":[{"batl":[[0,1.03,725.84],[1,1.04,566.61]],"ltp":1.09,"tv":284.79,"id":8535963}]}]}
{"op":"mcm","clk":"1005748286","pt":1580644400617,"mc":[{"id":"1.168219390","rc":[{"batl":[[1,1.04,608.62]],"ltp":1.09,"tv":284.79,"id":8535963},{"batb":[[0,25,4.48],[1,17,7.87],[2,1.01,10.52]],"ltp":12.5,"tv":58.9,"id":2309796}]}]}
{"op":"mcm","clk":"1005748523","pt":1580644402398,"mc":[{"id":"1.168219390","rc":[{"batl":[[2,1.3,1231.73]],"ltp":1.09,"tv":284.79,"id":8535963},{"batl":[[0,160,37.04]],"ltp":12.5,"tv":58.9,"id":2309796}]}]}
{"op":"mcm","clk":"1005750562","pt":1580644418351,"mc":[{"id":"1.168219390","rc":[{"batl":[[0,1.03,660.71]],"ltp":1.09,"tv":284.79,"id":8535963}]}]}
{"op":"mcm","clk":"1005750937","pt":1580644421350,"mc":[{"id":"1.168219390","rc":[{"batl":[[1,1.04,673.12]],"ltp":1.09,"tv":284.79,"id":8535963}]}]}
{"op":"mcm","clk":"1005754242","pt":1580644447704,"mc":[{"id":"1.168219390","rc":[{"batl":[[0,1.03,589.14]],"ltp":1.09,"tv":284.79,"id":8535963}]}]}
{"op":"mcm","clk":"1005754545","pt":1580644450005,"mc":[{"id":"1.168219390","rc":[{"batl":[[1,1.04,744.01]],"ltp":1.09,"tv":284.79,"id":8535963}]}]}
{"op":"mcm","clk":"1005759100","pt":1580644485757,"mc":[{"id":"1.168219390","rc":[{"batb":[[0,1.01,10.51],[1,1.01,0]],"batl":[[0,1.3,1231.73],[1,1.04,0],[2,1.3,0]],"ltp":1.09,"tv":284.79,"id":8535963},{"batb":[[0,17,7.87],[1,1.01,10.52],[2,1.01,0]],"ltp":12.5,"tv":58.9,"id":2309796}]}]}
{"op":"mcm","clk":"1005759723","pt":1580644490448,"mc":[{"id":"1.168219390","rc":[{"batb":[[0,1.03,296.25],[1,1.02,1011.52],[2,1.01,10.51]],"batl":[[0,1.04,1285.48],[1,1.3,1231.73]],"ltp":1.09,"tv":284.79,"id":8535963}]}]}
{"op":"mcm","clk":"1005760435","pt":1580644495983,"mc":[{"id":"1.168219390","rc":[{"batb":[[0,1.01,10.51],[1,1.02,0],[2,1.01,0]],"batl":[[0,1.3,1231.73],[1,1.3,0]],"ltp":1.09,"tv":284.79,"id":8535963}]}]}
{"op":"mcm","clk":"1005760812","pt":1580644498887,"mc":[{"id":"1.168219390","rc":[{"batb":[[0,1.01,1334.17]],"batl":[[0,1.05,713.7],[1,1.06,554.24],[2,1.3,1231.73]],"ltp":1.09,"tv":284.79,"id":8535963}]}]}
{"op":"mcm","clk":"1005761972","pt":1580644507789,"mc":[{"id":"1.168219390","rc":[{"batb":[[0,1.01,10.51]],"ltp":1.09,"tv":284.79,"id":8535963}]}]}
{"op":"mcm","clk":"1005762351","pt":1580644510676,"mc":[{"id":"1.168219390","rc":[{"batb":[[0,1.04,1285.48],[1,1.01,10.51]],"ltp":1.09,"tv":284.79,"id":8535963}]}]}
{"op":"mcm","clk":"1005762440","pt":1580644511418,"mc":[{"id":"1.168219390","rc":[{"batb":[[1,1.03,647.32],[2,1.02,995.25]],"ltp":1.09,"tv":284.79,"id":8535963},{"batb":[[1,11.5,9.6],[2,1.01,10.52]],"ltp":12.5,"tv":58.9,"id":2309796}]}]}
{"op":"mcm","clk":"1005762586","pt":1580644512473,"mc":[{"id":"1.168219390","rc":[{"batl":[[0,65,40.51]],"ltp":12.5,"tv":58.9,"id":2309796}]}]}
{"op":"mcm","clk":"1005762620","pt":1580644512802,"mc":[{"id":"1.168219390","rc":[{"batb":[[0,1.04,1453.52]],"batl":[[1,1.06,596.25]],"ltp":1.09,"tv":284.79,"id":8535963}]}]}
{"op":"mcm","clk":"1005763769","pt":1580644521749,"mc":[{"id":"1.168219390","rc":[{"trd":[[1.05,44]],"batl":[[0,1.05,691.7]],"ltp":1.05,"tv":328.79,"id":8535963}],"tv":387.69}]}
{"op":"mcm","clk":"1005764364","pt":1580644526444,"mc":[{"id":"1.168219390","rc":[{"batb":[[0,1.04,168.04],[1,1.02,995.25],[2,1.01,10.51]],"batl":[[0,1.06,42.01],[1,1.3,1231.73],[2,1.3,0]],"ltp":1.05,"tv":328.79,"id":8535963},{"batb":[[0,11.5,9.6],[1,1.01,10.52],[2,1.01,0]],"ltp":12.5,"tv":58.9,"id":2309796}]}]}
{"op":"mcm","clk":"1005764541","pt":1580644527821,"mc":[{"id":"1.168219390","rc":[{"batb":[[0,1.02,995.25],[1,1.01,10.51],[2,1.01,0]],"batl":[[0,1.3,1231.73],[1,1.3,0]],"ltp":1.05,"tv":328.79,"id":8535963}]}]}
{"op":"mcm","clk":"1005764673","pt":1580644529013,"mc":[{"id":"1.168219390","rc":[{"batb":[[0,1.03,477.21],[1,1.02,1824.04],[2,1.01,10.51]],"batl":[[0,1.08,536.78],[1,1.09,694.64],[2,1.3,1231.73]],"ltp":1.05,"tv":328.79,"id":8535963}]}]}
{"op":"mcm","clk":"1005765448","pt":1580644535648,"mc":[{"id":"1.168219390","rc":[{"batb":[[0,1.02,995.25],[1,1.01,10.51],[2,1.01,0]],"ltp":1.05,"tv":328.79,"id":8535963}]}]}
{"op":"mcm","clk":"1005765837","pt":1580644538747,"mc":[{"id":"1.168219390","rc":[{"batb":[[0,1.07,494.85],[1,1.06,761.7],[2,1.02,995.25]],"ltp":1.05,"tv":328.79,"id":8535963},{"batb":[[0,12.5,3.36],[1,11.5,9.6],[2,1.01,10.52]],"ltp":12.5,"tv":58.9,"id":2309796}]}]}
{"op":"mcm","clk":"1005765909","pt":1580644539375,"mc":[{"id":"1.168219390","rc":[{"batb":[[1,1.06,1140.95],[2,1.04,529.06]],"ltp":1.05,"tv":328.79,"id":8535963},{"batb":[[2,8.4,7.95]],"ltp":12.5,"tv":58.9,"id":2309796}]}]}
{"op":"mcm","clk":"1005766059","pt":1580644540637,"mc":[{"id":"1.168219390","rc":[{"batl":[[0,30,46.85]],"ltp":12.5,"tv":58.9,"id":2309796}]}]}
{"op":"mcm","clk":"1005767288","pt":1580644550696,"mc":[{"id":"1.168219390","rc":[{"trd":[[1.08,545.18]],"batl":[[0,1.09,694.64],[1,1.3,1231.73],[2,1.3,0]],"ltp":1.08,"tv":865.57,"id":8535963},{"trd":[[13.5,42.94]],"batl":[[0,13.5,81.06],[1,30,46.85]],"ltp":13.5,"tv":101.84,"id":2309796}],"tv":967.41}]}
{"op":"mcm","clk":"1005767352","pt":1580644551177,"mc":[{"id":"1.168219390","rc":[{"batb":[[1,1.06,940.41]],"ltp":1.08,"tv":865.57,"id":8535963}]}]}
{"op":"mcm","clk":"1005767805","pt":1580644554383,"mc":[{"id":"1.168219390","rc":[{"trd":[[1.08,885.14]],"batb":[[0,1.07,693.52],[1,1.06,813.39]],"batl":[[0,1.09,889.66]],"ltp":1.08,"tv":1205.53,"id":8535963},{"trd":[[13.5,166.14]],"batl":[[0,13.5,5.86]],"ltp":13.5,"tv":225.04,"id":2309796}],"tv":1430.57}]}
{"op":"mcm","clk":"1005768181","pt":1580644557550,"mc":[{"id":"1.168219390","rc":[{"trd":[[1.08,958.39]],"batb":[[0,1.04,529.06],[1,1.01,10.51],[2,1.04,0]],"batl":[[0,1.3,1231.73],[1,1.3,0]],"ltp":1.08,"tv":1278.78,"id":8535963},{"trd":[[13.5,172]],"batb":[[1,8.4,7.95],[2,1.01,10.52]],"batl":[[0,30,46.85],[1,30,0]],"ltp":13.5,"tv":230.9,"id":2309796}],"tv":1509.68}]}
{"op":"mcm","clk":"1005768217","pt":1580644557862,"mc":[{"id":"1.168219390","rc":[{"batb":[[0,8.4,7.95],[1,1.01,10.52],[2,1.01,0]],"ltp":13.5,"tv":230.9,"id":2309796}]}]}
{"op":"mcm","clk":"1005768590","pt":1580644560652,"mc":[{"id":"1.168219390","rc":[{"batb":[[0,1.05,1273.23],[1,1.04,529.06],[2,1.01,10.51]],"batl":[[0,1.12,211.17],[1,1.13,867.75],[2,1.3,1231.73]],"ltp":1.08,"tv":1278.78,"id":8535963}]}]}
{"op":"mcm","clk":"1005768706","pt":1580644561558,"mc":[{"id":"1.168219390","rc":[{"batl":[[0,1.3,1231.73],[1,1.13,0],[2,1.3,0]],"ltp":1.08,"tv":1278.78,"id":8535963}]}]}
{"op":"mcm","clk":"1005769148","pt":1580644564523,"mc":[{"id":"1.168219390","rc":[{"batl":[[0,1.06,262.66],[1,1.07,989.22],[2,1.3,1231.73]],"ltp":1.08,"tv":1278.78,"id":8535963}]}]}
{"op":"mcm","clk":"1005769231","pt":1580644565150,"mc":[{"id":"1.168219390","rc":[{"batb":[[2,1.02,866.68]],"batl":[[1,1.07,1031.23]],"ltp":1.08,"tv":1278.78,"id":8535963},{"batb":[[0,14.5,5.43],[1,9.6,14.63],[2,1.01,10.52]],"ltp":13.5,"tv":230.9,"id":2309796}]}]}
{"op":"mcm","clk":"1005769452","pt":1580644566948,"mc":[{"id":"1.168219390","rc":[{"batl":[[0,42,43.46]],"ltp":13.5,"tv":230.9,"id":2309796}]}]}
{"op":"mcm","clk":"1005770641","pt":1580644575439,"mc":[{"id":"1.168219390","rc":[{"batb":[[0,1.02,866.68],[1,1.01,10.51],[2,1.02,0]],"batl":[[0,1.07,42.01],[1,1.3,1231.73],[2,1.3,0]],"ltp":1.08,"tv":1278.78,"id":8535963},{"batb":[[0,9.6,14.63],[1,1.01,10.52],[2,1.01,0]],"ltp":13.5,"tv":230.9,"id":2309796}]}]}
{"op":"mcm","clk":"1005770709","pt":1580644575866,"mc":[{"id":"1.168219390","rc":[{"batl":[[0,1.3,1231.73],[1,1.3,0]],"ltp":1.08,"tv":1278.78,"id":8535963}]}]}
{"op":"mcm","clk":"1005771094","pt":1580644578677,"mc":[{"id":"1.168219390","rc":[{"batb":[[0,1.03,1297.96],[1,1.02,866.68],[2,1.01,10.51]],"batl":[[0,1.11,1078.46],[1,1.3,1231.73]],"ltp":1.08,"tv":1278.78,"id":8535963}]}]}
{"op":"mcm","clk":"1005771866","pt":1580644584086,"mc":[{"id":"1.168219390","rc":[{"trd":[[1.11,1078.46]],"batl":[[0,1.3,1231.73],[1,1.3,0]],"ltp":1.11,"tv":2357.24,"id":8535963},{"trd":[[9.6,8.58],[10,119.71]],"batb":[[0,9.6,10.34]],"ltp":9.6,"tv":359.19,"id":2309796}],"tv":2716.43}]}
{"op":"mcm","clk":"1005772428","pt":1580644587684,"mc":[{"id":"1.168219390","rc":[{"batl":[[0,1.05,1273.23],[1,1.3,1231.73]],"ltp":1.11,"tv":2357.24,"id":8535963},{"batb":[[0,20,4.88],[1,12,8.73],[2,9.6,10.34]],"ltp":9.6,"tv":359.19,"id":2309796}]}]}
{"op":"mcm","clk":"1005772462","pt":1580644587874,"mc":[{"id":"1.168219390","rc":[{"batb":[[1,1.02,852.83]],"ltp":1.11,"tv":2357.24,"id":8535963},{"batb":[[2,1.01,10.52]],"ltp":9.6,"tv":359.19,"id":2309796}]}]}
{"op":"mcm","clk":"1005772748","pt":1580644590003,"mc":[{"id":"1.168219390","rc":[{"batl":[[0,95,38.67]],"ltp":9.6,"tv":359.19,"id":2309796}]}]}
{"op":"mcm","clk":"1005774700","pt":1580644604690,"mc":[{"id":"1.168219390","rc":[{"batb":[[0,1.02,852.83],[1,1.01,10.51],[2,1.01,0]],"batl":[[0,1.3,1231.73],[1,1.3,0]],"ltp":1.11,"tv":2357.24,"id":8535963}]}]}
{"op":"mcm","clk":"1005774739","pt":1580644604890,"mc":[{"id":"1.168219390","rc":[{"batb":[[0,1.01,10.51],[1,1.01,0]],"ltp":1.11,"tv":2357.24,"id":8535963},{"batb":[[0,12,8.73],[1,1.01,10.52],[2,1.01,0]],"ltp":9.6,"tv":359.19,"id":2309796}]}]}
{"op":"mcm","clk":"1005775087","pt":1580644607515,"mc":[{"id":"1.168219390","rc":[{"batb":[[0,1.01,1334.17]],"batl":[[0,1.08,377.58],[1,1.09,852.38]],"ltp":1.11,"tv":2357.24,"id":8535963}]}]}
{"op":"mcm","clk":"1005775198","pt":1580644608320,"mc":[{"id":"1.168219390","rc":[{"batb":[[0,1.01,10.51]],"ltp":1.11,"tv":2357.24,"id":8535963}]}]}
{"op":"mcm","clk":"1005775616","pt":1580644611696,"mc":[{"id":"1.168219390","rc":[{"batb":[[0,1.04,1285.48],[1,1.01,10.51]],"batl":[[0,1.05,732.01],[1,1.06,536.11]],"ltp":1.11,"tv":2357.24,"id":8535963}]}]}
{"op":"mcm","clk":"1005775871","pt":1580644613425,"mc":[{"id":"1.168219390","rc":[{"batl":[[2,1.32,1166.57]],"ltp":1.11,"tv":2357.24,"id":8535963},{"batl":[[0,65,40.51]],"ltp":9.6,"tv":359.19,"id":2309796}]}]}
{"op":"mcm","clk":"1005776259","pt":1580644616337,"mc":[{"id":"1.168219390","rc":[{"batb":[[0,1.01,10.51],[1,1.01,0]],"batl":[[0,1.32,1166.57],[1,1.06,0],[2,1.32,0]],"ltp":1.11,"tv":2357.24,"id":8535963}]}]}
{"op":"mcm","clk":"1005776621","pt":1580644619220,"mc":[{"id":"1.168219390","rc":[{"batb":[[0,1.01,1334.17]],"batl":[[0,1.08,377.58],[1,1.09,852.38]],"ltp":1.11,"tv":2357.24,"id":8535963}]}]}
{"op":"mcm","clk":"1005777325","pt":1580644624822,"mc":[{"id":"1.168219390","rc":[{"batb":[[0,1.01,10.51]],"ltp":1.11,"tv":2357.24,"id":8535963}]}]}
{"op":"mcm","clk":"1005777661","pt":1580644627754,"mc":[{"id":"1.168219390","rc":[{"batb":[[0,1.07,583.32],[1,1.06,672.39],[2,1.01,10.51]],"ltp":1.11,"tv":2357.24,"id":8535963}]}]}
{"op":"mcm","clk":"1005777780","pt":1580644628758,"mc":[{"id":"1.168219390","rc":[{"batb":[[0,1.07,541.19],[1,1.06,1074.53],[2,1.02,774.23]],"batl":[[1,1.09,810.96]],"ltp":1.11,"tv":2357.24,"id":8535963},{"batb":[[1,7.2,11.25],[2,1.01,10.52]],"ltp":9.6,"tv":359.19,"id":2309796}]}]}
{"op":"mcm","clk":"1005777875","pt":1580644629544,"mc":[{"id":"1.168219390","rc":[{"batl":[[0,1.08,419.59],[2,1.35,1063.8]],"ltp":1.11,"tv":2357.24,"id":8535963},{"batb":[[0,13,3.36],[1,12,8.73],[2,7.2,11.25]],"batl":[[0,30,46.85]],"ltp":9.6,"tv":359.19,"id":2309796}]}]}
{"op":"mcm","clk":"1005777912","pt":1580644629856,"mc":[{"id":"1.168219390","rc":[{"batb":[[0,1.07,489.98]],"batl":[[1,1.09,760.62]],"ltp":1.11,"tv":2357.24,"id":8535963}]}]}
{"op":"mcm","clk":"1005778028","pt":1580644630958,"mc":[{"id":"1.168219390","rc":[{"batb":[[1,1.06,1117.06]],"batl":[[0,1.08,461.4]],"ltp":1.11,"tv":2357.24,"id":8535963}]}]}
{"op":"mcm","clk":"1005778246","pt":1580644632742,"mc":[{"id":"1.168219390","rc":[{"batb":[[1,1.06,1168.76]],"batl":[[0,1.08,512.21]],"ltp":1.11,"tv":2357.24,"id":8535963}]}]}
{"op":"mcm","clk":"1005779284","pt":1580644640658,"mc":[{"id":"1.168219390","rc":[{"batb":[[0,1.06,402.14],[1,1.02,774.23],[2,1.01,10.51]],"batl":[[0,1.08,42.01],[1,1.35,1063.8],[2,1.35,0]],"ltp":1.11,"tv":2357.24,"id":8535963}]}]}
{"op":"mcm","clk":"1005779317","pt":1580644640918,"mc":[{"id":"1.168219390","rc":[{"batb":[[0,1.02,774.23],[1,1.01,10.51],[2,1.01,0]],"ltp":1.11,"tv":2357.24,"id":8535963},{"batb":[[1,7.2,11.25],[2,1.01,10.52]],"ltp":9.6,"tv":359.19,"id":2309796}]}]}
{"op":"mcm","clk":"1005779481","pt":1580644642163,"mc":[{"id":"1.168219390","rc":[{"batl":[[0,1.35,1063.8],[1,1.35,0]],"ltp":1.11,"tv":2357.24,"id":8535963},{"batb":[[0,7.2,11.25],[1,1.01,10.52],[2,1.01,0]],"ltp":9.6,"tv":359.19,"id":2309796}]}]}
{"op":"mcm","clk":"1005779691","pt":1580644643637,"mc":[{"id":"1.168219390","rc":[{"batb":[[0,1.06,168.04],[1,1.03,1297.96],[2,1.02,774.23]],"batl":[[0,1.16,756.54],[1,1.17,392.56]],"ltp":1.11,"tv":2357.24,"id":8535963}]}]}
{"op":"mcm","clk":"1005779764","pt":1580644644227,"mc":[{"id":"1.168219390","rc":[{"batb":[[0,1.03,1297.96],[1,1.02,774.23],[2,1.01,10.51]],"ltp":1.11,"tv":2357.24,"id":8535963}]}]}
{"op":"mcm","clk":"1005780220","pt":1580644647747,"mc":[{"id":"1.168219390","rc":[{"batl":[[0,1.05,1273.23]],"ltp":1.11,"tv":2357.24,"id":8535963},{"batb":[[0,19,5.82],[1,11.5,9.68],[2,7.2,11.25]],"ltp":9.6,"tv":359.19,"id":2309796}]}]}
{"op":"mcm","clk":"1005780243","pt":1580644647903,"mc":[{"id":"1.168219390","rc":[{"batb":[[2,1.01,10.52]],"ltp":9.6,"tv":359.19,"id":2309796}]}]}
{"op":"mcm","clk":"1005780490","pt":1580644649636,"mc":[{"id":"1.168219390","rc":[{"batl":[[0,1.05,1315.24],[1,1.31,1200.25]],"ltp":1.11,"tv":2357.24,"id":8535963},{"batl":[[0,95,38.67]],"ltp":9.6,"tv":359.19,"id":2309796}]}]}
{"op":"mcm","clk":"1005781994","pt":1580644661637,"mc":[{"id":"1.168219390","rc":[{"batb":[[0,1.01,10.51],[1,1.02,0],[2,1.01,0]],"batl":[[0,1.05,42.01]],"ltp":1.11,"tv":2357.24,"id":8535963},{"batb":[[0,11.5,9.68],[1,1.01,10.52],[2,1.01,0]],"ltp":9.6,"tv":359.19,"id":2309796}]}]}
{"op":"mcm","clk":"1005782149","pt":1580644662736,"mc":[{"id":"1.168219390","rc":[{"batl":[[0,1.31,1200.25],[1,1.31,0]],"ltp":1.11,"tv":2357.24,"id":8535963}]}]}
{"op":"mcm","clk":"1005782586","pt":1580644666152,"mc":[{"id":"1.168219390","rc":[{"batb":[[0,1.04,1285.48],[1,1.01,10.51]],"batl":[[0,1.05,274.15],[1,1.06,989.65]],"ltp":1.11,"tv":2357.24,"id":8535963}]}]}
{"op":"mcm","clk":"1005782826","pt":1580644667771,"mc":[{"id":"1.168219390","rc":[{"batl":[[2,1.32,1166.57]],"ltp":1.11,"tv":2357.24,"id":8535963},{"batl":[[0,65,40.51]],"ltp":9.6,"tv":359.19,"id":2309796}]}]}
{"op":"mcm","clk":"1005783432","pt":1580644672805,"mc":[{"id":"1.168219390","rc":[{"batb":[[0,1.01,10.51],[1,1.01,0]],"batl":[[0,1.32,1166.57],[1,1.06,0],[2,1.32,0]],"ltp":1.11,"tv":2357.24,"id":8535963}]}]}
{"op":"mcm","clk":"1005783811","pt":1580644675684,"mc":[{"id":"1.168219390","rc":[{"batb":[[0,1.02,381.91],[1,1.01,948.47]],"batl":[[0,1.09,1226.51]],"ltp":1.11,"tv":2357.24,"id":8535963}]}]}
{"op":"mcm","clk":"1005785037","pt":1580644685600,"mc":[{"id":"1.168219390","rc":[{"batl":[[0,1.03,1297.96]],"ltp":1.11,"tv":2357.24,"id":8535963}]}]}
{"op":"mcm","clk":"1005785090","pt":1580644686030,"mc":[{"id":"1.168219390","rc":[{"batb":[[0,18,6.77]],"ltp":9.6,"tv":359.19,"id":2309796}]}]}
{"op":"mcm","clk":"1005785253","pt":1580644687222,"mc":[{"id":"1.168219390","rc":[{"batl":[[0,1.03,1339.97]],"ltp":1.11,"tv":2357.24,"id":8535963}]}]}
{"op":"mcm","clk":"1005785429","pt":1580644688528,"mc":[{"id":"1.168219390","rc":[{"batl":[[1,1.29,1283.47]],"ltp":1.11,"tv":2357.24,"id":8535963}]}]}
{"op":"mcm","clk":"1005786057","pt":1580644692849,"mc":[{"id":"1.168219390","rc":[{"batb":[[0,1.02,269.75]],"ltp":1.11,"tv":2357.24,"id":8535963}]}]}
{"op":"mcm","clk":"1005786460","pt":1580644695733,"mc":[{"id":"1.168219390","rc":[{"batb":[[1,1.01,1061.74]],"ltp":1.11,"tv":2357.24,"id":8535963}]}]}
{"op":"mcm","clk":"1005787560","pt":1580644703750,"mc":[{"id":"1.168219390","rc":[{"batb":[[0,1.01,10.51],[1,1.01,0]],"batl":[[0,1.03,42.01]],"ltp":1.11,"tv":2357.24,"id":8535963}]}]}
{"op":"mcm","clk":"1005788042","pt":1580644707636,"mc":[{"id":"1.168219390","rc":[{"batb":[[0,1.02,1310.68],[1,1.01,10.51]],"batl":[[0,1.03,1297.96]],"ltp":1.11,"tv":2357.24,"id":8535963}]}]}
{"op":"mcm","clk":"1005788358","pt":1580644710346,"mc":[{"id":"1.168219390","rc":[{"batl":[[1,1.3,1262.86]],"ltp":1.11,"tv":2357.24,"id":8535963},{"batl":[[0,520,35.51]],"ltp":9.6,"tv":359.19,"id":2309796}]}]}
{"op":"mcm","clk":"1005788601","pt":1580644712477,"mc":[{"id":"1.168219390","rc":[{"batb":[[0,1.01,10.51],[1,1.01,0]],"batl":[[0,1.3,1262.86],[1,1.3,0]],"ltp":1.11,"tv":2357.24,"id":8535963}]}]}
{"op":"mcm","clk":"1005788914","pt":1580644715287,"mc":[{"id":"1.168219390","rc":[{"batl":[[0,1.05,1273.23]],"ltp":1.11,"tv":2357.24,"id":8535963}]}]}
{"op":"mcm","clk":"1005789473","pt":1580644720393,"mc":[{"id":"1.168219390","rc":[{"batb":[[0,1.04,252.74],[1,1.03,1042.76],[2,1.01,10.51]],"ltp":1.11,"tv":2357.24,"id":8535963}]}]}
{"op":"mcm","clk":"1005789574","pt":1580644721291,"mc":[{"id":"1.168219390","rc":[{"batb":[[1,1.03,1751.61]],"batl":[[0,1.05,1315.24]],"ltp":1.11,"tv":2357.24,"id":8535963},{"batb":[[1,10.5,11.02],[2,1.01,10.52]],"ltp":9.6,"tv":359.19,"id":2309796}]}]}
{"op":"mcm","clk":"1005789804","pt":1580644723165,"mc":[{"id":"1.168219390","rc":[{"batl":[[1,1.31,1200.25]],"ltp":1.11,"tv":2357.24,"id":8535963},{"batl":[[0,95,38.67]],"ltp":9.6,"tv":359.19,"id":2309796}]}]}
{"op":"mcm","clk":"1005791111","pt":1580644734610,"mc":[{"id":"1.168219390","rc":[{"batb":[[0,1.03,1751.61],[1,1.01,10.51],[2,1.01,0]],"ltp":1.11,"tv":2357.24,"id":8535963}]}]}
{"op":"mcm","clk":"1005791491","pt":1580644737638,"mc":[{"id":"1.168219390","rc":[{"batb":[[0,1.03,2006.81]],"ltp":1.11,"tv":2357.24,"id":8535963}]}]}
{"op":"mcm","clk":"1005791830","pt":1580644740677,"mc":[{"id":"1.168219390","rc":[{"batb":[[0,1.03,708.85]],"batl":[[0,1.05,42.01]],"ltp":1.11,"tv":2357.24,"id":8535963}]}]}
{"op":"mcm","clk":"1005791925","pt":1580644741266,"mc":[{"id":"1.168219390","rc":[{"batb":[[0,1.01,10.51],[1,1.01,0]],"ltp":1.11,"tv":2357.24,"id":8535963},{"batb":[[0,10.5,11.02],[1,1.01,10.52],[2,1.01,0]],"ltp":9.6,"tv":359.19,"id":2309796}]}]}
{"op":"mcm","clk":"1005792677","pt":1580644746117,"mc":[{"id":"1.168219390","rc":[{"batb":[[0,1.04,1285.48],[1,1.01,10.51]],"batl":[[0,1.06,1261.22]],"ltp":1.11,"tv":2357.24,"id":8535963}]}]}
{"op":"mcm","clk":"1005792946","pt":1580644748124,"mc":[{"id":"1.168219390","rc":[{"batl":[[1,1.32,1166.57]],"ltp":1.11,"tv":2357.24,"id":8535963},{"batl":[[0,65,40.51]],"ltp":9.6,"tv":359.19,"id":2309796}]}]}
{"op":"mcm","clk":"1005793259","pt":1580644750652,"mc":[{"id":"1.168219390","rc":[{"batb":[[0,1.01,10.51],[1,1.01,0]],"batl":[[0,1.32,1166.57],[1,1.32,0]],"ltp":1.11,"tv":2357.24,"id":8535963}]}]}
{"op":"mcm","clk":"1005793613","pt":1580644753430,"mc":[{"id":"1.168219390","rc":[{"batb":[[0,1.02,699.98],[1,1.01,627.26]],"batl":[[0,1.09,1195.27]],"ltp":1.11,"tv":2357.24,"id":8535963}]}]}
{"op":"mcm","clk":"1005795310","pt":1580644767044,"mc":[{"id":"1.168219390","rc":[{"batb":[[0,1.01,10.51],[1,1.01,0]],"ltp":1.11,"tv":2357.24,"id":8535963}]}]}
{"op":"mcm","clk":"1005795725","pt":1580644770571,"mc":[{"id":"1.168219390","rc":[{"batb":[[0,1.07,1570.59],[1,1.03,677.45],[2,1.01,10.51]],"ltp":1.11,"tv":2357.24,"id":8535963},{"batb":[[1,6.6,13.53],[2,1.01,10.52]],"ltp":9.6,"tv":359.19,"id":2309796}]}]}
{"op":"mcm","clk":"1005795766","pt":1580644770983,"mc":[{"id":"1.168219390","rc":[{"batb":[[0,12.5,3.36],[1,10.5,11.02],[2,6.6,13.53]],"ltp":9.6,"tv":359.19,"id":2309796}]}]}
{"op":"mcm","clk":"1005795922","pt":1580644772295,"mc":[{"id":"1.168219390","rc":[{"batl":[[1,1.35,1063.8]],"ltp":1.11,"tv":2357.24,"id":8535963},{"batl":[[0,30,46.85]],"ltp":9.6,"tv":359.19,"id":2309796}]}]}
{"op":"mcm","clk":"1005796978","pt":1580644780668,"mc":[{"id":"1.168219390","rc":[{"batl":[[0,1.09,1135.77]],"ltp":1.11,"tv":2357.24,"id":8535963}]}]}
{"op":"mcm","clk":"1005798313","pt":1580644790499,"mc":[{"id":"1.168219390","rc":[{"batb":[[0,1.03,677.45],[1,1.01,10.51],[2,1.01,0]],"batl":[[0,1.35,1063.8],[1,1.35,0]],"ltp":1.11,"tv":2357.24,"id":8535963},{"batb":[[1,6.6,13.53],[2,1.01,10.52]],"ltp":9.6,"tv":359.19,"id":2309796}]}]}
{"op":"mcm","clk":"1005798524","pt":1580644792018,"mc":[{"id":"1.168219390","rc":[{"batb":[[0,6.6,13.53],[1,1.01,10.52],[2,1.01,0]],"ltp":9.6,"tv":359.19,"id":2309796}]}]}
{"op":"mcm","clk":"1005799127","pt":1580644796320,"mc":[{"id":"1.168219390","rc":[{"batb":[[0,1.08,1237.87],[1,1.03,677.45],[2,1.01,10.51]],"batl":[[0,1.1,545.32],[1,1.11,664]],"ltp":1.11,"tv":2357.24,"id":8535963}]}]}
{"op":"mcm","clk":"1005799346","pt":1580644797802,"mc":[{"id":"1.168219390","rc":[{"batl":[[2,1.37,1017.22]],"ltp":1.11,"tv":2357.24,"id":8535963},{"batl":[[0,24,50.13]],"ltp":9.6,"tv":359.19,"id":2309796}]}]}
{"op":"mcm","clk":"1005799920","pt":1580644801646,"mc":[{"id":"1.168219390","rc":[{"batb":[[0,1.03,677.45],[1,1.01,10.51],[2,1.01,0]],"batl":[[0,1.37,1017.22],[1,1.11,0],[2,1.37,0]],"ltp":1.11,"tv":2357.24,"id":8535963}]}]}
{"op":"mcm","clk":"1005800477","pt":1580644804315,"mc":[{"id":"1.168219390","rc":[{"batb":[[0,1.04,635.49],[1,1.03,1333.74],[2,1.01,10.51]],"batl":[[0,1.16,368.28],[1,1.17,635.48]],"ltp":1.11,"tv":2357.24,"id":8535963}]}]}
{"op":"mcm","clk":"1005801607","pt":1580644811485,"mc":[{"id":"1.168219390","rc":[{"batb":[[0,1.03,677.45],[1,1.01,10.51],[2,1.01,0]],"ltp":1.11,"tv":2357.24,"id":8535963}]}]}
{"op":"mcm","clk":"1005801987","pt":1580644814592,"mc":[{"id":"1.168219390","rc":[{"batb":[[0,1.14,581.69],[1,1.13,596.91],[2,1.03,677.45]],"ltp":1.11,"tv":2357.24,"id":8535963}]}]}
{"op":"mcm","clk":"1005802131","pt":1580644815685,"mc":[{"id":"1.168219390","rc":[{"batb":[[0,1.14,757.54],[1,1.13,764.95],[2,1.1,235.57]],"batl":[[0,1.16,410.29]],"ltp":1.11,"tv":2357.24,"id":8535963},{"batb":[[0,7,6.72],[1,6.6,13.53],[2,5.9,18.18]],"batl":[[0,8.8,5.04]],"ltp":9.6,"tv":359.19,"id":2309796}]}]}
{"op":"mcm","clk":"1005802273","pt":1580644816789,"mc":[{"id":"1.168219390","rc":[{"batl":[[2,1.45,846.03]],"ltp":1.11,"tv":2357.24,"id":8535963},{"batl":[[1,12.5,65.25]],"ltp":9.6,"tv":359.19,"id":2309796}]}]}
{"op":"mcm","clk":"1005803878","pt":1580644828197,"mc":[{"id":"1.168219390","rc":[{"batb":[[0,1.14,175.85],[1,1.13,168.04]],"batl":[[0,1.16,42.01],[1,1.45,846.03],[2,1.45,0]],"ltp":1.11,"tv":2357.24,"id":8535963}]}]}
{"op":"mcm","clk":"1005804983","pt":1580644835636,"mc":[{"id":"1.168219390","rc":[{"batb":[[0,1.14,755.85],[1,1.13,766.66]],"batl":[[0,1.16,412.17],[1,1.17,635.83],[2,1.45,846.03]],"ltp":1.11,"tv":2357.24,"id":8535963}]}]}
{"op":"mcm","clk":"1005805516","pt":1580644839743,"mc":[{"id":"1.168219390","rc":[{"batb":[[0,1.14,635.31]],"ltp":1.11,"tv":2357.24,"id":8535963}]}]}
{"op":"mcm","clk":"1005805763","pt":1580644841331,"mc":[{"id":"1.168219390","rc":[{"trd":[[1.16,44]],"batl":[[0,1.16,370.16]],"ltp":1.16,"tv":2401.24,"id":8535963}],"tv":2760.43}]}
{"op":"mcm","clk":"1005805973","pt":1580644842743,"mc":[{"id":"1.168219390","rc":[{"batb":[[1,1.13,888.26]],"batl":[[0,1.16,488.8]],"ltp":1.16,"tv":2401.24,"id":8535963}]}]}
{"op":"mcm","clk":"1005806380","pt":1580644845750,"mc":[{"id":"1.168219390","rc":[{"batb":[[0,1.13,168.04],[1,1.1,235.57],[2,1.01,10.51]],"batl":[[0,1.45,846.03],[1,1.17,0],[2,1.45,0]],"ltp":1.16,"tv":2401.24,"id":8535963},{"batb":[[1,5.9,18.18],[2,1.01,10.52]],"ltp":9.6,"tv":359.19,"id":2309796}]}]}
{"op":"mcm","clk":"1005806489","pt":1580644846447,"mc":[{"id":"1.168219390","rc":[{"batb":[[0,1.1,235.57],[1,1.01,10.51],[2,1.01,0]],"ltp":1.16,"tv":2401.24,"id":8535963},{"batb":[[0,5.9,18.18],[1,1.01,10.52],[2,1.01,0]],"batl":[[0,12.5,65.25],[1,12.5,0]],"ltp":9.6,"tv":359.19,"id":2309796}]}]}
{"op":"mcm","clk":"1005806830","pt":1580644848759,"mc":[{"id":"1.168219390","rc":[{"batb":[[0,6,17.55],[1,5.9,18.18],[2,1.01,10.52]],"ltp":9.6,"tv":359.19,"id":2309796}]}]}
{"op":"mcm","clk":"1005806851","pt":1580644848971,"mc":[{"id":"1.168219390","rc":[{"batb":[[1,1.01,10.52],[2,1.01,0]],"ltp":9.6,"tv":359.19,"id":2309796}]}]}
{"op":"mcm","clk":"1005807055","pt":1580644850674,"mc":[{"id":"1.168219390","rc":[{"batb":[[0,1.13,781.93],[1,1.12,405.41],[2,1.1,235.57]],"batl":[[0,1.15,315.84],[1,1.16,689.12],[2,1.45,846.03]],"ltp":1.16,"tv":2401.24,"id":8535963}]}]}
{"op":"mcm","clk":"1005807628","pt":1580644854660,"mc":[{"id":"1.168219390","rc":[{"batb":[[0,1.1,235.57],[1,1.01,10.51],[2,1.1,0]],"batl":[[0,1.45,846.03],[1,1.16,0],[2,1.45,0]],"ltp":1.16,"tv":2401.24,"id":8535963}]}]}
{"op":"mcm","clk":"1005808065","pt":1580644857600,"mc":[{"id":"1.168219390","rc":[{"batb":[[0,1.11,217.62],[1,1.1,1232],[2,1.01,10.51]],"batl":[[0,1.19,693.99],[1,1.2,426.49],[2,1.45,846.03]],"ltp":1.16,"tv":2401.24,"id":8535963}]}]}
{"op":"mcm","clk":"1005810177","pt":1580644872242,"mc":[{"id":"1.168219390","rc":[{"batb":[[0,1.1,235.57],[1,1.01,10.51],[2,1.01,0]],"ltp":1.16,"tv":2401.24,"id":8535963}]}]}
{"op":"mcm","clk":"1005810630","pt":1580644875599,"mc":[{"id":"1.168219390","rc":[{"batb":[[0,1.16,648.4],[1,1.15,500.7],[2,1.13,187.03]],"batl":[[0,1.19,574.89],[1,1.45,846.03],[2,1.45,0]],"ltp":1.16,"tv":2401.24,"id":8535963},{"batb":[[1,5.5,10.78],[2,1.01,10.52]],"ltp":9.6,"tv":359.19,"id":2309796}]}]}
{"op":"mcm","clk":"1005810819","pt":1580644877031,"mc":[{"id":"1.168219390","rc":[{"batb":[[2,1.14,168.04]],"batl":[[0,1.18,42.01],[1,1.19,574.89],[2,1.45,846.03]],"ltp":1.16,"tv":2401.24,"id":8535963},{"batb":[[0,6.4,7.56],[1,6,17.55],[2,5.5,10.78]],"batl":[[0,8,5.88]],"ltp":9.6,"tv":359.19,"id":2309796}]}]}
{"op":"mcm","clk":"1005811063","pt":1580644878724,"mc":[{"id":"1.168219390","rc":[{"batb":[[0,1.16,578.28],[1,1.15,660]],"batl":[[0,1.18,284.29]],"ltp":1.16,"tv":2401.24,"id":8535963},{"batl":[[0,11.5,69.3]],"ltp":9.6,"tv":359.19,"id":2309796}]}]}
{"op":"mcm","clk":"1005811444","pt":1580644881623,"mc":[{"id":"1.168219390","rc":[{"batb":[[1,1.15,730.73]],"batl":[[0,1.18,353.28]],"ltp":1.16,"tv":2401.24,"id":8535963},{"batl":[[0,7.8,5.88],[1,11.5,69.3]],"ltp":9.6,"tv":359.19,"id":2309796}]}]}
{"op":"mcm","clk":"1005812954","pt":1580644892249,"mc":[{"id":"1.168219390","rc":[{"batb":[[0,1.14,168.04],[1,1.13,187.03],[2,1.01,10.51]],"batl":[[0,1.45,846.03],[1,1.19,0],[2,1.45,0]],"ltp":1.16,"tv":2401.24,"id":8535963},{"batb":[[1,5.5,10.78],[2,1.01,10.52]],"ltp":9.6,"tv":359.19,"id":2309796}]}]}
{"op":"mcm","clk":"1005813199","pt":1580644894072,"mc":[{"id":"1.168219390","rc":[{"batb":[[0,1.13,187.03],[1,1.01,10.51],[2,1.01,0]],"ltp":1.16,"tv":2401.24,"id":8535963},{"batb":[[0,5.5,10.78],[1,1.01,10.52],[2,1.01,0]],"batl":[[0,11.5,69.3],[1,11.5,0]],"ltp":9.6,"tv":359.19,"id":2309796}]}]}
{"op":"mcm","clk":"1005813537","pt":1580644895682,"mc":[{"id":"1.168219390","rc":[{"batb":[[0,1.13,846.43],[1,1.12,529.03],[2,1.01,10.51]],"batl":[[0,1.2,263.11],[1,1.21,515.42],[2,1.45,846.03]],"ltp":1.16,"tv":2401.24,"id":8535963}]}]}
{"op":"mcm","clk":"1005814238","pt":1580644900290,"mc":[{"id":"1.168219390","rc":[{"batb":[[0,1.13,187.03],[1,1.01,10.51],[2,1.01,0]],"batl":[[0,1.45,846.03],[1,1.21,0],[2,1.45,0]],"ltp":1.16,"tv":2401.24,"id":8535963}]}]}
{"op":"mcm","clk":"1005814751","pt":1580644903568,"mc":[{"id":"1.168219390","rc":[{"batb":[[0,1.18,367.65],[1,1.17,695.95],[2,1.13,187.03]],"batl":[[0,1.2,263.08],[1,1.21,515.42],[2,1.45,846.03]],"ltp":1.16,"tv":2401.24,"id":8535963}]}]}
{"op":"mcm","clk":"1005814854","pt":1580644904190,"mc":[{"id":"1.168219390","rc":[{"batb":[[0,1.18,497.16],[2,1.16,150.13]],"ltp":1.16,"tv":2401.24,"id":8535963},{"batb":[[1,5.2,12.27],[2,1.01,10.52]],"ltp":9.6,"tv":359.19,"id":2309796}]}]}
{"op":"mcm","clk":"1005815025","pt":1580644905402,"mc":[{"id":"1.168219390","rc":[{"batb":[[2,1.16,318.16]],"batl":[[0,1.2,305.09]],"ltp":1.16,"tv":2401.24,"id":8535963},{"batb":[[0,6,8.4],[1,5.5,10.78],[2,5.2,12.27]],"batl":[[0,7.4,5.88]],"ltp":9.6,"tv":359.19,"id":2309796}]}]}
{"op":"mcm","clk":"1005815214","pt":1580644906568,"mc":[{"id":"1.168219390","rc":[{"batl":[[1,9.8,74.36]],"ltp":9.6,"tv":359.19,"id":2309796}]}]}
{"op":"mcm","clk":"1005817511","pt":1580644919692,"mc":[{"id":"1.168219390","rc":[{"batb":[[0,1.16,318.16],[1,1.01,10.51],[2,1.16,0]],"batl":[[0,1.2,42.01],[1,1.45,846.03],[2,1.45,0]],"ltp":1.16,"tv":2401.24,"id":8535963},{"batb":[[1,5.2,12.27],[2,1.01,10.52]],"ltp":9.6,"tv":359.19,"id":2309796}]}]}
{"op":"mcm","clk":"1005817576","pt":1580644920112,"mc":[{"id":"1.168219390","rc":[{"batb":[[0,1.16,150.13]],"batl":[[0,1.45,846.03],[1,1.45,0]],"ltp":1.16,"tv":2401.24,"id":8535963},{"batb":[[0,5.2,12.27],[1,1.01,10.52],[2,1.01,0]],"batl":[[0,9.8,74.36],[1,9.8,0]],"ltp":9.6,"tv":359.19,"id":2309796}]}]}
{"op":"mcm","clk":"1005818032","pt":1580644922420,"mc":[{"id":"1.168219390","rc":[{"batb":[[0,1.16,510.88],[1,1.15,799.28],[2,1.01,10.51]],"batl":[[0,1.22,521.6],[1,1.23,456.64],[2,1.45,846.03]],"ltp":1.16,"tv":2401.24,"id":8535963}]}]}
{"op":"mcm","clk":"1005818455","pt":1580644925017,"mc":[{"id":"1.168219390","rc":[{"batb":[[1,1.01,10.51],[2,1.01,0]],"batl":[[0,1.45,846.03],[1,1.23,0],[2,1.45,0]],"ltp":1.16,"tv":2401.24,"id":8535963}]}]}
{"op":"mcm","clk":"1005819553","pt":1580644931605,"mc":[{"id":"1.168219390","rc":[{"batb":[[0,1.16,150.13]],"batl":[[0,1.22,521.6],[1,1.23,456.64],[2,1.45,846.03]],"ltp":1.16,"tv":2401.24,"id":8535963}]}]}
{"op":"mcm","clk":"1005819948","pt":1580644933688,"mc":[{"id":"1.168219390","rc":[{"batb":[[0,1.19,560.17],[1,1.18,568.67],[2,1.16,150.13]],"ltp":1.16,"tv":2401.24,"id":8535963}]}]}
{"op":"mcm","clk":"1005820114","pt":1580644934690,"mc":[{"id":"1.168219390","rc":[{"batb":[[0,1.2,119.05],[1,1.19,688.66],[2,1.18,568.67]],"ltp":1.16,"tv":2401.24,"id":8535963},{"batb":[[1,5,13.38],[2,1.01,10.52]],"ltp":9.6,"tv":359.19,"id":2309796}]}]}
{"op":"mcm","clk":"1005820164","pt":1580644935001,"mc":[{"id":"1.168219390","rc":[{"batl":[[0,1.21,42.01],[1,1.22,521.6],[2,1.23,456.64]],"ltp":1.16,"tv":2401.24,"id":8535963},{"batb":[[0,5.7,8.4],[1,5.2,12.27],[2,5,13.38]],"batl":[[0,7,6.72],[1,9.8,74.36]],"ltp":9.6,"tv":359.19,"id":2309796}]}]}
{"op":"mcm","clk":"1005823024","pt":1580644951762,"mc":[{"id":"1.168219390","rc":[{"batb":[[1,1.19,128.49],[2,1.18,533.03]],"batl":[[1,1.23,456.64],[2,1.45,846.03]],"ltp":1.16,"tv":2401.24,"id":8535963}]}]}
{"op":"mcm","clk":"1005823080","pt":1580644952135,"mc":[{"id":"1.168219390","rc":[{"batb":[[0,1.19,128.49],[1,1.18,533.03],[2,1.01,10.51]],"batl":[[0,1.23,456.64],[1,1.45,846.03],[2,1.45,0]],"ltp":1.16,"tv":2401.24,"id":8535963},{"batb":[[0,5,13.38],[1,1.01,10.52],[2,5,0]],"batl":[[0,9.8,74.36],[1,9.8,0]],"ltp":9.6,"tv":359.19,"id":2309796}]}]}
{"op":"mcm","clk":"1005824528","pt":1580644960663,"mc":[{"id":"1.168219390","rc":[{"batb":[[2,1.17,607.81]],"batl":[[0,1.23,603.26],[1,1.24,433.52],[2,1.45,846.03]],"ltp":1.16,"tv":2401.24,"id":8535963}]}]}
{"op":"mcm","clk":"1005825185","pt":1580644964592,"mc":[{"id":"1.168219390","rc":[{"batl":[[0,1.45,846.03],[1,1.24,0],[2,1.45,0]],"ltp":1.16,"tv":2401.24,"id":8535963}]}]}
{"op":"mcm","clk":"1005825362","pt":1580644965570,"mc":[{"id":"1.168219390","rc":[{"batb":[[0,1.18,533.03],[1,1.17,607.81],[2,1.01,10.51]],"ltp":1.16,"tv":2401.24,"id":8535963}]}]}
{"op":"mcm","clk":"1005825697","pt":1580644967642,"mc":[{"id":"1.168219390","rc":[{"batl":[[0,1.21,634.98],[1,1.22,466.65],[2,1.45,846.03]],"ltp":1.16,"tv":2401.24,"id":8535963}]}]}
{"op":"mcm","clk":"1005825839","pt":1580644968549,"mc":[{"id":"1.168219390","rc":[{"batb":[[0,1.18,661.6],[2,1.16,147.37]],"ltp":1.16,"tv":2401.24,"id":8535963},{"batb":[[0,5.4,10.94],[1,5.1,12.51],[2,1.01,10.52]],"ltp":9.6,"tv":359.19,"id":2309796}]}]}
{"op":"mcm","clk":"1005826041","pt":1580644969664,"mc":[{"id":"1.168219390","rc":[{"batb":[[2,1.16,315.41]],"batl":[[0,1.2,42.01],[1,1.21,634.98],[2,1.22,466.65]],"ltp":1.16,"tv":2401.24,"id":8535963},{"batb":[[0,5.9,8.4],[1,5.4,10.94],[2,5.1,12.51]],"batl":[[0,7.2,6.72],[1,9.8,74.36]],"ltp":9.6,"tv":359.19,"id":2309796}]}]}
{"op":"mcm","clk":"1005828238","pt":1580644981628,"mc":[{"id":"1.168219390","rc":[{"batb":[[0,1.16,315.41],[1,1.01,10.51],[2,1.16,0]],"batl":[[1,1.22,381.86],[2,1.45,846.03]],"ltp":1.16,"tv":2401.24,"id":8535963},{"batb":[[1,5.1,12.51],[2,1.01,10.52]],"ltp":9.6,"tv":359.19,"id":2309796}]}]}
{"op":"mcm","clk":"1005828312","pt":1580644982100,"mc":[{"id":"1.168219390","rc":[{"batb":[[0,1.16,147.37]],"batl":[[0,1.22,381.86],[1,1.45,846.03],[2,1.45,0]],"ltp":1.16,"tv":2401.24,"id":8535963},{"batb":[[0,5.1,12.51],[1,1.01,10.52],[2,1.01,0]],"batl":[[0,9.8,74.36],[1,9.8,0]],"ltp":9.6,"tv":359.19,"id":2309796}]}]}
{"op":"mcm","clk":"1005828556","pt":1580644983374,"mc":[{"id":"1.168219390","rc":[{"batl":[[0,1.45,846.03],[1,1.45,0]],"ltp":1.16,"tv":2401.24,"id":8535963}]}]}
{"op":"mcm","clk":"1005829152","pt":1580644986714,"mc":[{"id":"1.168219390","rc":[{"batb":[[0,1.18,292.97],[1,1.17,693.07],[2,1.16,147.37]],"batl":[[0,1.2,331.72],[1,1.21,513.31],[2,1.45,846.03]],"ltp":1.16,"tv":2401.24,"id":8535963}]}]}
{"op":"mcm","clk":"1005829326","pt":1580644987727,"mc":[{"id":"1.168219390","rc":[{"batb":[[0,1.16,147.37],[1,1.01,10.51],[2,1.16,0]],"batl":[[0,1.45,846.03],[1,1.21,0],[2,1.45,0]],"ltp":1.16,"tv":2401.24,"id":8535963}]}]}
{"op":"mcm","clk":"1005829809","pt":1580644990594,"mc":[{"id":"1.168219390","rc":[{"batb":[[0,1.16,804.79],[1,1.15,500.03],[2,1.01,10.51]],"batl":[[0,1.22,381.86],[1,1.23,461.62],[2,1.45,846.03]],"ltp":1.16,"tv":2401.24,"id":8535963}]}]}
{"op":"mcm","clk":"1005829945","pt":1580644991328,"mc":[{"id":"1.168219390","rc":[{"batl":[[0,1.45,846.03],[1,1.23,0],[2,1.45,0]],"ltp":1.16,"tv":2401.24,"id":8535963}]}]}
{"op":"mcm","clk":"1005830519","pt":1580644994638,"mc":[{"id":"1.168219390","rc":[{"batl":[[0,1.19,728.73],[1,1.2,392.04],[2,1.45,846.03]],"ltp":1.16,"tv":2401.24,"id":8535963}]}]}
{"op":"mcm","clk":"1005830643","pt":1580644995321,"mc":[{"id":"1.168219390","rc":[{"batb":[[1,1.15,668.07],[2,1.12,198.28]],"batl":[[0,1.19,770.74]],"ltp":1.16,"tv":2401.24,"id":8535963},{"batb":[[0,6.4,7.56],[1,5.9,17.94],[2,5.3,11.8]],"batl":[[0,7.8,5.88]],"ltp":9.6,"tv":359.19,"id":2309796}]}]}
{"op":"mcm","clk":"1005830816","pt":1580644996228,"mc":[{"id":"1.168219390","rc":[{"batl":[[1,11.5,69.3]],"ltp":9.6,"tv":359.19,"id":2309796}]}]}
{"op":"mcm","clk":"1005832949","pt":1580645008761,"mc":[{"id":"1.168219390","rc":[{"batb":[[0,1.15,168.04],[1,1.12,198.28],[2,1.01,10.51]],"batl":[[0,1.19,42.01],[1,1.45,846.03],[2,1.45,0]],"ltp":1.16,"tv":2401.24,"id":8535963},{"batb":[[1,5.3,11.8],[2,1.01,10.52]],"ltp":9.6,"tv":359.19,"id":2309796}]}]}
{"op":"mcm","clk":"1005833196","pt":1580645010060,"mc":[{"id":"1.168219390","rc":[{"batb":[[0,1.12,198.28],[1,1.01,10.51],[2,1.01,0]],"batl":[[0,1.45,846.03],[1,1.45,0]],"ltp":1.16,"tv":2401.24,"id":8535963},{"batb":[[0,5.3,11.8],[1,1.01,10.52],[2,1.01,0]],"batl":[[0,11.5,69.3],[1,11.5,0]],"ltp":9.6,"tv":359.19,"id":2309796}]}]}
{"op":"mcm","clk":"1005833357","pt":1580645010969,"mc":[{"id":"1.168219390","rc":[{"batb":[[0,1.12,1195.55],[1,1.11,198.83],[2,1.01,10.51]],"batl":[[0,1.22,637.79],[1,1.23,454.12],[2,1.45,846.03]],"ltp":1.16,"tv":2401.24,"id":8535963}]}]}
{"op":"mcm","clk":"1005833653","pt":1580645012446,"mc":[{"id":"1.168219390","rc":[{"batb":[[0,1.12,198.28],[1,1.01,10.51],[2,1.01,0]],"ltp":1.16,"tv":2401.24,"id":8535963}]}]}
{"op":"mcm","clk":"1005834329","pt":1580645015637,"mc":[{"id":"1.168219390","rc":[{"batb":[[0,1.19,430.91],[1,1.18,654.09],[2,1.12,198.28]],"ltp":1.16,"tv":2401.24,"id":8535963}]}]}
{"op":"mcm","clk":"1005834425","pt":1580645016238,"mc":[{"id":"1.168219390","rc":[{"batb":[[0,1.19,553.34],[2,1.13,179.79]],"ltp":1.16,"tv":2401.24,"id":8535963},{"batb":[[1,3.8,25.57],[2,1.01,10.52]],"ltp":9.6,"tv":359.19,"id":2309796}]}]}
{"op":"mcm","clk":"1005834573","pt":1580645017040,"mc":[{"id":"1.168219390","rc":[{"batl":[[0,1.21,42.01],[1,1.22,637.79],[2,1.23,454.12]],"ltp":1.16,"tv":2401.24,"id":8535963},{"batb":[[0,5.7,8.4],[1,5.3,11.8],[2,3.8,25.57]],"batl":[[0,7,6.72]],"ltp":9.6,"tv":359.19,"id":2309796}]}]}
{"op":"mcm","clk":"1005834813","pt":1580645018326,"mc":[{"id":"1.168219390","rc":[{"batl":[[1,9.8,74.36]],"ltp":9.6,"tv":359.19,"id":2309796}]}]}
{"op":"mcm","clk":"1005839966","pt":1580645044881,"mc":[{"id":"1.168219390","rc":[{"batb":[[0,1.19,501.12]],"batl":[[1,1.22,492.12],[2,1.45,846.03]],"ltp":1.16,"tv":2401.24,"id":8535963}]}]}
{"op":"mcm","clk":"1005840541","pt":1580645047872,"mc":[{"id":"1.168219390","rc":[{"batl":[[0,1.21,238.5]],"ltp":1.16,"tv":2401.24,"id":8535963}]}]}
{"op":"mcm","clk":"1005842488","pt":1580645058090,"mc":[{"id":"1.168219390","rc":[{"batl":[[0,1.21,42.01]],"ltp":1.16,"tv":2401.24,"id":8535963}]}]}
{"op":"mcm","clk":"1005843090","pt":1580645061617,"mc":[{"id":"1.168219390","rc":[{"trd":[[1.21,42.01]],"batb":[[0,1.19,555.27]],"batl":[[0,1.22,634.35],[1,1.23,452.96]],"ltp":1.21,"tv":2443.25,"id":8535963},{"trd":[[5.7,25.72]],"batb":[[0,5.3,11.8],[1,3.8,25.57],[2,1.01,10.52]],"batl":[[0,5.7,9.05],[1,7,6.72],[2,9.8,74.36]],"ltp":5.7,"tv":384.9,"id":2309796}],"tv":2828.15}]}
{"op":"mcm","clk":"1005843146","pt":1580645061921,"mc":[{"id":"1.168219390","rc":[{"batl":[[1,9.8,74.36],[2,9.8,0]],"ltp":5.7,"tv":384.9,"id":2309796}]}]}
{"op":"mcm","clk":"1005843712","pt":1580645065060,"mc":[{"id":"1.168219390","rc":[{"batb":[[2,1.17,168.04]],"batl":[[0,1.22,676.36]],"ltp":1.21,"tv":2443.25,"id":8535963},{"trd":[[5.7,34.12]],"batb":[[0,5.5,9.24],[1,5.3,11.8],[2,3.8,25.57]],"batl":[[0,5.7,4.85],[1,6.8,6.72],[2,9.8,74.36]],"ltp":5.7,"tv":393.3,"id":2309796}],"tv":2836.55}]}
{"op":"mcm","clk":"1005851027","pt":1580645104329,"mc":[{"id":"1.168219390","rc":[{"batb":[[0,1.13,179.79],[1,1.01,10.51],[2,1.17,0]],"batl":[[0,1.45,846.03],[1,1.23,0],[2,1.45,0]],"ltp":1.21,"tv":2443.25,"id":8535963},{"batb":[[0,3.8,25.57],[1,1.01,10.52],[2,3.8,0]],"batl":[[1,9.8,74.36],[2,9.8,0]],"ltp":5.7,"tv":393.3,"id":2309796}]}]}
{"op":"mcm","clk":"1005851523","pt":1580645106769,"mc":[{"id":"1.168219390","rc":[{"batb":[[0,1.14,333.15],[1,1.13,1024.35],[2,1.01,10.51]],"batl":[[0,1.33,339.09],[1,1.34,289.34],[2,1.45,846.03]],"ltp":1.21,"tv":2443.25,"id":8535963}]}]}
{"op":"mcm","clk":"1005851883","pt":1580645108622,"mc":[{"id":"1.168219390","rc":[{"batl":[[0,1.45,846.03],[1,1.34,0],[2,1.45,0]],"ltp":1.21,"tv":2443.25,"id":8535963}]}]}
{"op":"mcm","clk":"1005852479","pt":1580645111643,"mc":[{"id":"1.168219390","rc":[{"trd":[[1.21,64.87]],"batl":[[0,1.16,602.16],[1,1.17,520.62],[2,1.45,846.03]],"ltp":1.21,"tv":2466.11,"id":8535963},{"trd":[[5.7,38.97]],"ltp":5.7,"tv":398.15,"id":2309796}],"tv":2864.26}]}
{"op":"mcm","clk":"1005852595","pt":1580645112363,"mc":[{"id":"1.168219390","rc":[{"batb":[[2,1.09,257.84]],"ltp":1.21,"tv":2466.11,"id":8535963},{"batb":[[0,6.8,13.06],[1,4.9,13.85],[2,1.01,10.52]],"ltp":5.7,"tv":398.15,"id":2309796}]}]}
{"op":"mcm","clk":"1005852780","pt":1580645113446,"mc":[{"id":"1.168219390","rc":[{"batl":[[0,8.6,5.04]],"ltp":5.7,"tv":398.15,"id":2309796}]}]}
{"op":"mcm","clk":"1005853148","pt":1580645115253,"mc":[{"id":"1.168219390","rc":[{"batl":[[1,14,61.92]],"ltp":5.7,"tv":398.15,"id":2309796}]}]}
{"op":"mcm","clk":"1005854439","pt":1580645121554,"mc":[{"id":"1.168219390","rc":[{"batb":[[0,1.09,257.84],[1,1.01,10.51],[2,1.09,0]],"batl":[[0,1.45,846.03],[1,1.17,0],[2,1.45,0]],"ltp":1.21,"tv":2466.11,"id":8535963},{"batb":[[0,4.9,13.85],[1,1.01,10.52],[2,1.01,0]],"ltp":5.7,"tv":398.15,"id":2309796}]}]}
{"op":"mcm","clk":"1005854558","pt":1580645122136,"mc":[{"id":"1.168219390","rc":[{"batl":[[0,14,61.92],[1,14,0]],"ltp":5.7,"tv":398.15,"id":2309796}]}]}
{"op":"mcm","clk":"1005855399","pt":1580645126248,"mc":[{"id":"1.168219390","rc":[{"batb":[[0,1.15,616.76],[1,1.14,548.13],[2,1.09,257.84]],"batl":[[0,1.17,272.19],[1,1.18,614.45],[2,1.45,846.03]],"ltp":1.21,"tv":2466.11,"id":8535963}]}]}
{"op":"mcm","clk":"1005855775","pt":1580645128317,"mc":[{"id":"1.168219390","rc":[{"batl":[[0,12.5,65.25]],"ltp":5.7,"tv":398.15,"id":2309796}]}]}
{"op":"mcm","clk":"1005856045","pt":1580645129741,"mc":[{"id":"1.168219390","rc":[{"batb":[[0,1.09,257.84],[1,1.01,10.51],[2,1.09,0]],"batl":[[0,1.45,846.03],[1,1.18,0],[2,1.45,0]],"ltp":1.21,"tv":2466.11,"id":8535963}]}]}
{"op":"mcm","clk":"1005856667","pt":1580645132657,"mc":[{"id":"1.168219390","rc":[{"batb":[[0,1.1,860.4],[1,1.09,613.53],[2,1.01,10.51]],"batl":[[0,1.24,549.16],[1,1.25,413.03],[2,1.45,846.03]],"ltp":1.21,"tv":2466.11,"id":8535963}]}]}
{"op":"mcm","clk":"1005856913","pt":1580645134021,"mc":[{"id":"1.168219390","rc":[{"batl":[[0,1.45,846.03],[1,1.25,0],[2,1.45,0]],"ltp":1.21,"tv":2466.11,"id":8535963}]}]}
{"op":"mcm","clk":"1005857627","pt":1580645137752,"mc":[{"id":"1.168219390","rc":[{"batb":[[2,1.07,349.98]],"batl":[[0,1.12,741.13],[1,1.13,446.09]],"ltp":1.21,"tv":2466.11,"id":8535963},{"batb":[[0,8.8,7.24],[1,6.6,13.77],[2,4.9,13.85]],"ltp":5.7,"tv":398.15,"id":2309796}]}]}
{"op":"mcm","clk":"1005857662","pt":1580645137965,"mc":[{"id":"1.168219390","rc":[{"batb":[[2,1.01,10.52]],"ltp":5.7,"tv":398.15,"id":2309796}]}]}
{"op":"mcm","clk":"1005857931","pt":1580645139456,"mc":[{"id":"1.168219390","rc":[{"batl":[[1,1.13,488.1],[2,1.38,979.44]],"ltp":1.21,"tv":2466.11,"id":8535963},{"batb":[[0,8.8,12.28]],"batl":[[0,11.5,3.36],[1,21,53.02]],"ltp":5.7,"tv":398.15,"id":2309796}]}]}
{"op":"mcm","clk":"1005860146","pt":1580645150751,"mc":[{"id":"1.168219390","rc":[{"batb":[[0,1.09,257.84],[1,1.07,349.98],[2,1.01,10.51]],"batl":[[0,1.13,42.01],[1,1.38,979.44],[2,1.38,0]],"ltp":1.21,"tv":2466.11,"id":8535963}]}]}
{"op":"mcm","clk":"1005860185","pt":1580645150959,"mc":[{"id":"1.168219390","rc":[{"batb":[[0,1.07,349.98],[1,1.01,10.51],[2,1.01,0]],"ltp":1.21,"tv":2466.11,"id":8535963},{"batb":[[0,8.8,5.04]],"ltp":5.7,"tv":398.15,"id":2309796}]}]}
{"op":"mcm","clk":"1005860466","pt":1580645152451,"mc":[{"id":"1.168219390","rc":[{"batl":[[0,1.38,979.44],[1,1.38,0]],"ltp":1.21,"tv":2466.11,"id":8535963},{"batb":[[0,6.6,13.77],[1,1.01,10.52],[2,1.01,0]],"batl":[[0,21,53.02],[1,21,0]],"ltp":5.7,"tv":398.15,"id":2309796}]}]}
{"op":"mcm","clk":"1005861179","pt":1580645155650,"mc":[{"id":"1.168219390","rc":[{"batb":[[0,1.11,543.01],[1,1.1,664.92],[2,1.07,349.98]],"batl":[[0,1.13,832.48],[1,1.14,345.12],[2,1.38,979.44]],"ltp":1.21,"tv":2466.11,"id":8535963}]}]}
{"op":"mcm","clk":"1005861557","pt":1580645157614,"mc":[{"id":"1.168219390","rc":[{"batl":[[0,17,56.8]],"ltp":5.7,"tv":398.15,"id":2309796}]}]}
{"op":"mcm","clk":"1005861979","pt":1580645159736,"mc":[{"id":"1.168219390","rc":[{"batb":[[0,1.07,349.98],[1,1.01,10.51],[2,1.07,0]],"batl":[[0,1.38,979.44],[1,1.14,0],[2,1.38,0]],"ltp":1.21,"tv":2466.11,"id":8535963}]}]}
{"op":"mcm","clk":"1005862477","pt":1580645162346,"mc":[{"id":"1.168219390","rc":[{"batb":[[0,1.08,906.42],[1,1.07,681.95],[2,1.01,10.51]],"batl":[[0,1.16,341.9],[1,1.17,652.49],[2,1.38,979.44]],"ltp":1.21,"tv":2466.11,"id":8535963}]}]}
{"op":"mcm","clk":"1005864162","pt":1580645171185,"mc":[{"id":"1.168219390","rc":[{"batb":[[0,1.07,349.98],[1,1.01,10.51],[2,1.01,0]],"ltp":1.21,"tv":2466.11,"id":8535963}]}]}
{"op":"mcm","clk":"1005864920","pt":1580645174765,"mc":[{"id":"1.168219390","rc":[{"batb":[[0,1.14,802.34],[1,1.13,547.04],[2,1.09,273.1]],"ltp":1.21,"tv":2466.11,"id":8535963},{"batb":[[1,4.5,16.52],[2,1.01,10.52]],"ltp":5.7,"tv":398.15,"id":2309796}]}]}
{"op":"mcm","clk":"1005864987","pt":1580645175081,"mc":[{"id":"1.168219390","rc":[{"batb":[[1,1.13,715.08]],"batl":[[1,1.17,694.5]],"ltp":1.21,"tv":2466.11,"id":8535963},{"batb":[[0,7,6.72],[1,6.6,13.77],[2,4.5,16.52]],"batl":[[0,8.8,5.04]],"ltp":5.7,"tv":398.15,"id":2309796}]}]}
{"op":"mcm","clk":"1005865494","pt":1580645177557,"mc":[{"id":"1.168219390","rc":[{"batl":[[1,12.5,65.25]],"ltp":5.7,"tv":398.15,"id":2309796}]}]}
{"op":"mcm","clk":"1005867956","pt":1580645189500,"mc":[{"id":"1.168219390","rc":[{"batl":[[0,1.16,378.59]],"ltp":1.21,"tv":2466.11,"id":8535963}]}]}
{"op":"mcm","clk":"1005868167","pt":1580645190689,"mc":[{"id":"1.168219390","rc":[{"batb":[[0,1.14,174.28],[1,1.13,168.04]],"batl":[[0,1.17,42.01],[1,1.38,979.44],[2,1.38,0]],"ltp":1.21,"tv":2466.11,"id":8535963}]}]}
{"op":"mcm","clk":"1005868289","pt":1580645191275,"mc":[{"id":"1.168219390","rc":[{"batb":[[0,1.13,168.04],[1,1.09,273.1],[2,1.01,10.51]],"ltp":1.21,"tv":2466.11,"id":8535963},{"batb":[[1,4.5,16.52],[2,1.01,10.52]],"ltp":5.7,"tv":398.15,"id":2309796}]}]}
{"op":"mcm","clk":"1005868450","pt":1580645192191,"mc":[{"id":"1.168219390","rc":[{"batb":[[0,1.09,273.1],[1,1.01,10.51],[2,1.01,0]],"batl":[[0,1.38,979.44],[1,1.38,0]],"ltp":1.21,"tv":2466.11,"id":8535963},{"batb":[[0,4.5,16.52],[1,1.01,10.52],[2,1.01,0]],"batl":[[0,12.5,65.25],[1,12.5,0]],"ltp":5.7,"tv":398.15,"id":2309796}]}]}
{"op":"mcm","clk":"1005868699","pt":1580645193578,"mc":[{"id":"1.168219390","rc":[{"batb":[[0,1.09,1497.09]],"batl":[[0,1.26,425.89],[1,1.27,380.96],[2,1.38,979.44]],"ltp":1.21,"tv":2466.11,"id":8535963}]}]}
{"op":"mcm","clk":"1005868932","pt":1580645194698,"mc":[{"id":"1.168219390","rc":[{"batb":[[0,1.09,273.1]],"batl":[[0,1.38,979.44],[1,1.27,0],[2,1.38,0]],"ltp":1.21,"tv":2466.11,"id":8535963}]}]}
{"op":"mcm","clk":"1005869106","pt":1580645195506,"mc":[{"id":"1.168219390","rc":[{"batb":[[0,1.16,308.81],[1,1.15,801.43],[2,1.09,273.1]],"batl":[[0,1.18,465.59],[1,1.19,571.89],[2,1.38,979.44]],"ltp":1.21,"tv":2466.11,"id":8535963}]}]}
{"op":"mcm","clk":"1005869692","pt":1580645198808,"mc":[{"id":"1.168219390","rc":[{"batl":[[0,11.5,69.3]],"ltp":5.7,"tv":398.15,"id":2309796}]}]}
{"op":"mcm","clk":"1005869995","pt":1580645200489,"mc":[{"id":"1.168219390","rc":[{"batb":[[0,1.09,273.1],[1,1.01,10.51],[2,1.09,0]],"batl":[[0,1.38,979.44],[1,1.19,0],[2,1.38,0]],"ltp":1.21,"tv":2466.11,"id":8535963}]}]}
{"op":"mcm","clk":"1005870586","pt":1580645203302,"mc":[{"id":"1.168219390","rc":[{"batb":[[0,1.09,1497.09]],"batl":[[0,1.26,425.89],[1,1.27,380.96],[2,1.38,979.44]],"ltp":1.21,"tv":2466.11,"id":8535963}]}]}
{"op":"mcm","clk":"1005871791","pt":1580645209721,"mc":[{"id":"1.168219390","rc":[{"batb":[[0,1.09,273.1]],"ltp":1.21,"tv":2466.11,"id":8535963}]}]}
{"op":"mcm","clk":"1005872094","pt":1580645211362,"mc":[{"id":"1.168219390","rc":[{"batl":[[2,1.38,0]],"ltp":1.21,"tv":2466.11,"id":8535963}]}]}
{"op":"mcm","clk":"1005872331","pt":1580645212730,"mc":[{"id":"1.168219390","rc":[{"batb":[[0,1.23,362.12],[1,1.22,516.23],[2,1.09,273.1]],"ltp":1.21,"tv":2466.11,"id":8535963}]}]}
{"op":"mcm","clk":"1005872503","pt":1580645213742,"mc":[{"id":"1.168219390","rc":[{"batb":[[0,1.24,97.96],[1,1.23,362.12],[2,1.22,516.23]],"batl":[[0,1.26,467.9]],"ltp":1.21,"tv":2466.11,"id":8535963},{"batb":[[0,4.9,10.08],[1,4.5,16.52],[2,2.96,23.76]],"batl":[[0,5.9,8.4]],"ltp":5.7,"tv":398.15,"id":2309796}]}]}
{"op":"mcm","clk":"1005872887","pt":1580645215737,"mc":[{"id":"1.168219390","rc":[{"batl":[[2,1.56,681.34]],"ltp":1.21,"tv":2466.11,"id":8535963},{"batl":[[1,7.8,86.74]],"ltp":5.7,"tv":398.15,"id":2309796}]}]}
{"op":"mcm","clk":"1005875597","pt":1580645229677,"mc":[{"id":"1.168219390","rc":[{"batb":[[1,1.2,168.04],[2,1.13,186.87]],"batl":[[0,1.26,42.01],[1,1.56,681.34],[2,1.56,0]],"ltp":1.21,"tv":2466.11,"id":8535963}]}]}
{"op":"mcm","clk":"1005875773","pt":1580645230591,"mc":[{"id":"1.168219390","rc":[{"batb":[[0,1.2,168.04],[1,1.13,186.87],[2,1.01,10.51]],"ltp":1.21,"tv":2466.11,"id":8535963},{"batb":[[1,2.96,23.76],[2,1.01,10.52]],"batl":[[0,7.8,86.74],[1,7.8,0]],"ltp":5.7,"tv":398.15,"id":2309796}]}]}
{"op":"mcm","clk":"1005875921","pt":1580645231376,"mc":[{"id":"1.168219390","rc":[{"trd":[[1.26,44]],"batb":[[0,1.13,186.87],[1,1.01,10.51],[2,1.01,0]],"batl":[[0,1.26,20.01]],"ltp":1.26,"tv":2510.1,"id":8535963},{"batb":[[0,2.96,23.76],[1,1.01,10.52],[2,1.01,0]],"ltp":5.7,"tv":398.15,"id":2309796}],"tv":2908.26}]}
{"op":"mcm","clk":"1005876197","pt":1580645232692,"mc":[{"id":"1.168219390","rc":[{"batb":[[0,1.13,1009.31],[1,1.12,361.42],[2,1.01,10.51]],"batl":[[0,1.49,306.08],[1,1.5,178.39],[2,1.56,681.34]],"ltp":1.26,"tv":2510.1,"id":8535963}]}]}
{"op":"mcm","clk":"1005876374","pt":1580645233627,"mc":[{"id":"1.168219390","rc":[{"batl":[[0,5.8,8.4],[1,7.8,86.74]],"ltp":5.7,"tv":398.15,"id":2309796}]}]}
{"op":"mcm","clk":"1005876594","pt":1580645234669,"mc":[{"id":"1.168219390","rc":[{"batl":[[0,7.8,86.74],[1,7.8,0]],"ltp":5.7,"tv":398.15,"id":2309796}]}]}
{"op":"mcm","clk":"1005880264","pt":1580645253576,"mc":[{"id":"1.168219390","rc":[{"batl":[[0,1.56,681.34],[1,1.5,0],[2,1.56,0]],"ltp":1.26,"tv":2510.1,"id":8535963}]}]}
{"op":"mcm","clk":"1005880811","pt":1580645256687,"mc":[{"id":"1.168219390","rc":[{"batl":[[0,1.15,308.89],[1,1.16,702.14]],"ltp":1.26,"tv":2510.1,"id":8535963}]}]}
{"op":"mcm","clk":"1005881023","pt":1580645257762,"mc":[{"id":"1.168219390","rc":[{"batb":[[0,1.13,1006],[1,1.12,529.46],[2,1.07,325.27]],"batl":[[1,1.16,744.15]],"ltp":1.26,"tv":2510.1,"id":8535963},{"batb":[[0,7.2,6.72],[1,6.8,12.59],[2,4.4,17.62]],"batl":[[0,8.8,5.04]],"ltp":5.7,"tv":398.15,"id":2309796}]}]}
{"op":"mcm","clk":"1005881616","pt":1580645260693,"mc":[{"id":"1.168219390","rc":[{"batl":[[2,1.43,878.65]],"ltp":1.26,"tv":2510.1,"id":8535963},{"batl":[[1,14,61.92]],"ltp":5.7,"tv":398.15,"id":2309796}]}]}
{"op":"mcm","clk":"1005883191","pt":1580645268673,"mc":[{"id":"1.168219390","rc":[{"batb":[[0,1.13,183.56],[1,1.12,168.04]],"batl":[[0,1.16,42.01],[1,1.43,878.65],[2,1.43,0]],"ltp":1.26,"tv":2510.1,"id":8535963}]}]}
{"op":"mcm","clk":"1005883245","pt":1580645268995,"mc":[{"id":"1.168219390","rc":[{"batb":[[0,1.12,168.04],[1,1.07,325.27],[2,1.01,10.51]],"ltp":1.26,"tv":2510.1,"id":8535963},{"batb":[[1,4.4,17.62],[2,1.01,10.52]],"ltp":5.7,"tv":398.15,"id":2309796}]}]}
{"op":"mcm","clk":"1005883487","pt":1580645270163,"mc":[{"id":"1.168219390","rc":[{"batb":[[0,1.07,325.27],[1,1.01,10.51],[2,1.01,0]],"batl":[[0,1.43,878.65],[1,1.43,0]],"ltp":1.26,"tv":2510.1,"id":8535963},{"batb":[[0,4.4,17.62],[1,1.01,10.52],[2,1.01,0]],"batl":[[0,14,61.92],[1,14,0]],"ltp":5.7,"tv":398.15,"id":2309796}]}]}
{"op":"mcm","clk":"1005883729","pt":1580645271590,"mc":[{"id":"1.168219390","rc":[{"batb":[[0,1.08,926.84],[1,1.07,636.63],[2,1.01,10.51]],"batl":[[0,1.27,532.91],[1,1.28,362.55],[2,1.43,878.65]],"ltp":1.26,"tv":2510.1,"id":8535963}]}]}
{"op":"mcm","clk":"1005885154","pt":1580645278705,"mc":[{"id":"1.168219390","rc":[{"batl":[[0,1.43,878.65],[1,1.28,0],[2,1.43,0]],"ltp":1.26,"tv":2510.1,"id":8535963}]}]}
{"op":"mcm","clk":"1005885755","pt":1580645281611,"mc":[{"id":"1.168219390","rc":[{"batl":[[0,1.1,1171.07]],"ltp":1.26,"tv":2510.1,"id":8535963}]}]}
{"op":"mcm","clk":"1005885956","pt":1580645282608,"mc":[{"id":"1.168219390","rc":[{"batb":[[2,1.05,457.61]],"ltp":1.26,"tv":2510.1,"id":8535963},{"batb":[[0,10,12.51],[1,9,6.92],[2,1.01,10.52]],"ltp":5.7,"tv":398.15,"id":2309796}]}]}
{"op":"mcm","clk":"1005886128","pt":1580645283404,"mc":[{"id":"1.168219390","rc":[{"batl":[[0,1.1,1213.08]],"ltp":1.26,"tv":2510.1,"id":8535963},{"batb":[[0,11,4.2],[1,10,12.51],[2,9,6.92]],"ltp":5.7,"tv":398.15,"id":2309796}]}]}
{"op":"mcm","clk":"1005886352","pt":1580645284609,"mc":[{"id":"1.168219390","rc":[{"batl":[[1,1.37,1017.22]],"ltp":1.26,"tv":2510.1,"id":8535963},{"batl":[[0,24,50.13]],"ltp":5.7,"tv":398.15,"id":2309796}]}]}
{"op":"mcm","clk":"1005891692","pt":1580645310154,"mc":[{"id":"1.168219390","rc":[{"trd":[[11,0.82]],"batb":[[0,11,3.79]],"ltp":11.0,"tv":398.97,"id":2309796}],"tv":2909.08}]}
{"op":"mcm","clk":"1005893541","pt":1580645318729,"mc":[{"id":"1.168219390","rc":[{"batb":[[0,1.07,325.27],[1,1.05,457.61],[2,1.01,10.51]],"batl":[[0,1.1,42.01]],"ltp":1.26,"tv":2510.1,"id":8535963}]}]}
{"op":"mcm","clk":"1005893589","pt":1580645318884,"mc":[{"id":"1.168219390","rc":[{"batb":[[0,1.05,457.61],[1,1.01,10.51],[2,1.01,0]],"ltp":1.26,"tv":2510.1,"id":8535963},{"batb":[[1,9,6.92],[2,1.01,10.52]],"ltp":11.0,"tv":398.97,"id":2309796}]}]}
{"op":"mcm","clk":"1005893920","pt":1580645320535,"mc":[{"id":"1.168219390","rc":[{"batl":[[0,1.37,1017.22],[1,1.37,0]],"ltp":1.26,"tv":2510.1,"id":8535963},{"batb":[[0,9,6.92],[1,1.01,10.52],[2,1.01,0]],"ltp":11.0,"tv":398.97,"id":2309796}]}]}
{"op":"mcm","clk":"1005894580","pt":1580645323723,"mc":[{"id":"1.168219390","rc":[{"batb":[[0,1.08,238.32],[1,1.07,959.19],[2,1.05,457.61]],"batl":[[0,1.09,534.99],[1,1.1,636.9],[2,1.37,1017.22]],"ltp":1.26,"tv":2510.1,"id":8535963}]}]}
{"op":"mcm","clk":"1005894811","pt":1580645324738,"mc":[{"id":"1.168219390","rc":[{"batb":[[0,1.05,457.61],[1,1.01,10.51],[2,1.05,0]],"batl":[[0,1.37,1017.22],[1,1.1,0],[2,1.37,0]],"ltp":1.26,"tv":2510.1,"id":8535963}]}]}
{"op":"mcm","clk":"1005895425","pt":1580645327644,"mc":[{"id":"1.168219390","rc":[{"batb":[[0,1.06,975.81],[1,1.05,743.13],[2,1.01,10.51]],"batl":[[0,1.11,387.02],[1,1.12,807.64],[2,1.37,1017.22]],"ltp":1.26,"tv":2510.1,"id":8535963}]}]}
{"op":"mcm","clk":"1005895596","pt":1580645328339,"mc":[{"id":"1.168219390","rc":[{"batl":[[0,1.37,1017.22],[1,1.12,0],[2,1.37,0]],"ltp":1.26,"tv":2510.1,"id":8535963}]}]}
{"op":"mcm","clk":"1005896080","pt":1580645330753,"mc":[{"id":"1.168219390","rc":[{"batb":[[2,1.02,814.59]],"batl":[[0,1.07,369.69],[1,1.08,869.05],[2,1.37,1017.22]],"ltp":1.26,"tv":2510.1,"id":8535963},{"batb":[[0,13,6.92],[1,10.5,11.57],[2,9,6.92]],"ltp":11.0,"tv":398.97,"id":2309796}]}]}
{"op":"mcm","clk":"1005896158","pt":1580645331123,"mc":[{"id":"1.168219390","rc":[{"batb":[[0,1.06,1143.85]],"batl":[[1,1.08,911.06]],"ltp":1.26,"tv":2510.1,"id":8535963},{"batb":[[0,13,10.28],[2,1.01,10.52]],"ltp":11.0,"tv":398.97,"id":2309796}]}]}
{"op":"mcm","clk":"1005896530","pt":1580645333039,"mc":[{"id":"1.168219390","rc":[{"batl":[[0,42,43.46]],"ltp":11.0,"tv":398.97,"id":2309796}]}]}
{"op":"mcm","clk":"1005897859","pt":1580645339737,"mc":[{"id":"1.168219390","rc":[{"batb":[[0,1.06,168.04],[1,1.05,457.61]],"batl":[[0,1.08,42.01],[1,1.37,1017.22],[2,1.37,0]],"ltp":1.26,"tv":2510.1,"id":8535963}]}]}
{"op":"mcm","clk":"1005897984","pt":1580645340443,"mc":[{"id":"1.168219390","rc":[{"batb":[[0,1.02,814.59],[1,1.01,10.51],[2,1.02,0]],"batl":[[0,1.37,1017.22],[1,1.37,0]],"ltp":1.26,"tv":2510.1,"id":8535963},{"batb":[[0,10.5,11.57],[1,1.01,10.52],[2,1.01,0]],"ltp":11.0,"tv":398.97,"id":2309796}]}]}
{"op":"mcm","clk":"1005898338","pt":1580645342371,"mc":[{"id":"1.168219390","rc":[{"batb":[[0,1.03,1295.3],[1,1.02,814.59],[2,1.01,10.51]],"batl":[[0,1.09,395.45],[1,1.1,821.01],[2,1.37,1017.22]],"ltp":1.26,"tv":2510.1,"id":8535963}]}]}
{"op":"mcm","clk":"1005899708","pt":1580645349450,"mc":[{"id":"1.168219390","rc":[{"batb":[[0,1.02,814.59],[1,1.01,10.51],[2,1.01,0]],"ltp":1.26,"tv":2510.1,"id":8535963}]}]}
{"op":"mcm","clk":"1005900259","pt":1580645352512,"mc":[{"id":"1.168219390","rc":[{"batb":[[0,1.08,440.62],[1,1.07,802.13],[2,1.02,814.59]],"ltp":1.26,"tv":2510.1,"id":8535963}]}]}
{"op":"mcm","clk":"1005900390","pt":1580645353238,"mc":[{"id":"1.168219390","rc":[{"batb":[[1,1.07,1142.27],[2,1.04,522.13]],"batl":[[1,1.1,863.02]],"ltp":1.26,"tv":2510.1,"id":8535963},{"batb":[[0,11,4.2],[1,10.5,11.57],[2,9,6.92]],"ltp":11.0,"tv":398.97,"id":2309796}]}]}
{"op":"mcm","clk":"1005900795","pt":1580645355428,"mc":[{"id":"1.168219390","rc":[{"batl":[[0,24,50.13]],"ltp":11.0,"tv":398.97,"id":2309796}]}]}
{"op":"mcm","clk":"1005902797","pt":1580645365664,"mc":[{"id":"1.168219390","rc":[{"batb":[[0,1.04,522.13],[1,1.01,10.51],[2,1.04,0]],"batl":[[0,1.1,42.01],[1,1.37,1017.22],[2,1.37,0]],"ltp":1.26,"tv":2510.1,"id":8535963},{"batb":[[1,9,6.92],[2,1.01,10.52]],"ltp":11.0,"tv":398.97,"id":2309796}]}]}
{"op":"mcm","clk":"1005902886","pt":1580645366147,"mc":[{"id":"1.168219390","rc":[{"batl":[[0,1.37,1017.22],[1,1.37,0]],"ltp":1.26,"tv":2510.1,"id":8535963},{"batb":[[0,9,6.92],[1,1.01,10.52],[2,1.01,0]],"ltp":11.0,"tv":398.97,"id":2309796}]}]}
{"op":"mcm","clk":"1005903679","pt":1580645370119,"mc":[{"id":"1.168219390","rc":[{"batb":[[0,1.07,1246.87],[1,1.04,522.13],[2,1.01,10.51]],"batl":[[0,1.09,1143.59],[1,1.37,1017.22]],"ltp":1.26,"tv":2510.1,"id":8535963}]}]}
{"op":"mcm","clk":"1005904332","pt":1580645373300,"mc":[{"id":"1.168219390","rc":[{"batl":[[0,30,46.85]],"ltp":11.0,"tv":398.97,"id":2309796}]}]}
{"op":"mcm","clk":"1005904856","pt":1580645375728,"mc":[{"id":"1.168219390","rc":[{"batb":[[0,1.04,522.13],[1,1.01,10.51],[2,1.01,0]],"batl":[[0,1.37,1017.22],[1,1.37,0]],"ltp":1.26,"tv":2510.1,"id":8535963}]}]}
{"op":"mcm","clk":"1005905414","pt":1580645378397,"mc":[{"id":"1.168219390","rc":[{"batb":[[0,1.05,1270.62],[1,1.04,522.13],[2,1.01,10.51]],"batl":[[0,1.11,402.51],[1,1.12,792.29],[2,1.37,1017.22]],"ltp":1.26,"tv":2510.1,"id":8535963}]}]}
{"op":"mcm","clk":"1005908624","pt":1580645395521,"mc":[{"id":"1.168219390","rc":[{"batl":[[0,1.37,1017.22],[1,1.12,0],[2,1.37,0]],"ltp":1.26,"tv":2510.1,"id":8535963}]}]}
{"op":"mcm","clk":"1005909189","pt":1580645398739,"mc":[{"id":"1.168219390","rc":[{"batl":[[0,1.07,1246.87],[1,1.37,1017.22]],"ltp":1.26,"tv":2510.1,"id":8535963}]}]}
{"op":"mcm","clk":"1005909327","pt":1580645399453,"mc":[{"id":"1.168219390","rc":[{"batb":[[0,1.05,1438.66]],"ltp":1.26,"tv":2510.1,"id":8535963},{"batb":[[0,14.5,5.59],[1,11,10.62],[2,1.01,10.52]],"ltp":11.0,"tv":398.97,"id":2309796}]}]}
{"op":"mcm","clk":"1005909739","pt":1580645401744,"mc":[{"id":"1.168219390","rc":[{"batl":[[0,42,43.46]],"ltp":11.0,"tv":398.97,"id":2309796}]}]}
{"op":"mcm","clk":"1005912092","pt":1580645414728,"mc":[{"id":"1.168219390","rc":[{"batb":[[0,1.05,168.04]],"batl":[[0,1.37,1017.22],[1,1.37,0]],"ltp":1.26,"tv":2510.1,"id":8535963}]}]}
{"op":"mcm","clk":"1005912195","pt":1580645415213,"mc":[{"id":"1.168219390","rc":[{"batb":[[1,1.01,10.51],[2,1.01,0]],"ltp":1.26,"tv":2510.1,"id":8535963},{"batb":[[0,11,10.62],[1,1.01,10.52],[2,1.01,0]],"ltp":11.0,"tv":398.97,"id":2309796}]}]}
{"op":"mcm","clk":"1005912390","pt":1580645416224,"mc":[{"id":"1.168219390","rc":[{"batb":[[0,1.01,10.51],[1,1.01,0]],"ltp":1.26,"tv":2510.1,"id":8535963}]}]}
{"op":"mcm","clk":"1005912625","pt":1580645417582,"mc":[{"id":"1.168219390","rc":[{"batb":[[0,1.02,1308],[1,1.01,10.51]],"batl":[[0,1.09,880.87],[1,1.1,340]],"ltp":1.26,"tv":2510.1,"id":8535963}]}]}
{"op":"mcm","clk":"1005912858","pt":1580645418724,"mc":[{"id":"1.168219390","rc":[{"batb":[[0,1.01,10.51],[1,1.01,0]],"ltp":1.26,"tv":2510.1,"id":8535963}]}]}
{"op":"mcm","clk":"1005913065","pt":1580645419734,"mc":[{"id":"1.168219390","rc":[{"batb":[[0,1.04,1282.84],[1,1.01,10.51]],"batl":[[0,1.06,1258.63]],"ltp":1.26,"tv":2510.1,"id":8535963}]}]}
{"op":"mcm","clk":"1005913517","pt":1580645422064,"mc":[{"id":"1.168219390","rc":[{"batl":[[1,1.32,1166.57]],"ltp":1.26,"tv":2510.1,"id":8535963},{"batl":[[0,65,40.51]],"ltp":11.0,"tv":398.97,"id":2309796}]}]}
{"op":"mcm","clk":"1005913729","pt":1580645423250,"mc":[{"id":"1.168219390","rc":[{"batb":[[0,1.01,10.51],[1,1.01,0]],"batl":[[0,1.32,1166.57],[1,1.32,0]],"ltp":1.26,"tv":2510.1,"id":8535963}]}]}
{"op":"mcm","clk":"1005914273","pt":1580645426437,"mc":[{"id":"1.168219390","rc":[{"batb":[[0,1.02,1308],[1,1.01,10.51]],"ltp":1.26,"tv":2510.1,"id":8535963}]}]}
{"op":"mcm","clk":"1005914526","pt":1580645427658,"mc":[{"id":"1.168219390","rc":[{"batl":[[0,1.03,1196.34]],"ltp":1.26,"tv":2510.1,"id":8535963}]}]}
{"op":"mcm","clk":"1005914713","pt":1580645428651,"mc":[{"id":"1.168219390","rc":[{"batb":[[0,26,3.52],[1,17.5,7.16],[2,1.01,10.52]],"ltp":11.0,"tv":398.97,"id":2309796}]}]}
{"op":"mcm","clk":"1005914817","pt":1580645429133,"mc":[{"id":"1.168219390","rc":[{"batl":[[1,1.04,42.01]],"ltp":1.26,"tv":2510.1,"id":8535963}]}]}
{"op":"mcm","clk":"1005915259","pt":1580645431551,"mc":[{"id":"1.168219390","rc":[{"batl":[[2,1.3,1262.86]],"ltp":1.26,"tv":2510.1,"id":8535963},{"batl":[[0,520,35.51]],"ltp":11.0,"tv":398.97,"id":2309796}]}]}
{"op":"mcm","clk":"1005916760","pt":1580645439589,"mc":[{"id":"1.168219390","rc":[{"trd":[[1.02,76.82]],"batb":[[0,1.02,1269.57]],"ltp":1.02,"tv":2586.92,"id":8535963}],"tv":2985.9}]}
{"op":"mcm","clk":"1005917270","pt":1580645442666,"mc":[{"id":"1.168219390","rc":[{"batb":[[0,1.01,10.51],[1,1.01,0]],"batl":[[0,1.04,42.01],[1,1.3,1262.86],[2,1.3,0]],"ltp":1.02,"tv":2586.92,"id":8535963}]}]}
{"op":"mcm","clk":"1005917441","pt":1580645443673,"mc":[{"id":"1.168219390","rc":[{"batb":[[0,17.5,7.16],[1,1.01,10.52],[2,1.01,0]],"ltp":11.0,"tv":398.97,"id":2309796}]}]}
{"op":"mcm","clk":"1005917529","pt":1580645444195,"mc":[{"id":"1.168219390","rc":[{"batl":[[0,1.3,1262.86],[1,1.3,0]],"ltp":1.02,"tv":2586.92,"id":8535963}]}]}
{"op":"mcm","clk":"1005917769","pt":1580645445690,"mc":[{"id":"1.168219390","rc":[{"batl":[[0,1.05,691.15],[1,1.06,574]],"ltp":1.02,"tv":2586.92,"id":8535963}]}]}
{"op":"mcm","clk":"1005918332","pt":1580645449003,"mc":[{"id":"1.168219390","rc":[{"batb":[[0,1.02,241.25],[1,1.01,964.26]],"batl":[[0,1.03,1295.3]],"ltp":1.02,"tv":2586.92,"id":8535963}]}]}
{"op":"mcm","clk":"1005918692","pt":1580645451113,"mc":[{"id":"1.168219390","rc":[{"batl":[[1,1.29,1305.67]],"ltp":1.02,"tv":2586.92,"id":8535963}]}]}
{"op":"mcm","clk":"1005918932","pt":1580645452296,"mc":[{"id":"1.168219390","rc":[{"batb":[[0,1.01,10.51],[1,1.01,0]],"batl":[[0,1.29,1305.67],[1,1.29,0]],"ltp":1.02,"tv":2586.92,"id":8535963}]}]}
{"op":"mcm","clk":"1005919435","pt":1580645455210,"mc":[{"id":"1.168219390","rc":[{"batl":[[0,1.05,812.12],[1,1.06,454.18]],"ltp":1.02,"tv":2586.92,"id":8535963}]}]}
{"op":"mcm","clk":"1005923079","pt":1580645474554,"mc":[{"id":"1.168219390","rc":[{"batb":[[0,1.04,1282.84],[1,1.03,682.25],[2,1.01,10.51]],"ltp":1.02,"tv":2586.92,"id":8535963},{"batb":[[1,11,10.62],[2,1.01,10.52]],"ltp":11.0,"tv":398.97,"id":2309796}]}]}
{"op":"mcm","clk":"1005923204","pt":1580645475254,"mc":[{"id":"1.168219390","rc":[{"batb":[[0,1.04,1450.88]],"batl":[[1,1.06,496.19]],"ltp":1.02,"tv":2586.92,"id":8535963}]}]}
{"op":"mcm","clk":"1005923464","pt":1580645476628,"mc":[{"id":"1.168219390","rc":[{"batl":[[2,1.32,1166.57]],"ltp":1.02,"tv":2586.92,"id":8535963},{"batl":[[0,65,40.51]],"ltp":11.0,"tv":398.97,"id":2309796}]}]}
{"op":"mcm","clk":"1005924129","pt":1580645480244,"mc":[{"id":"1.168219390","rc":[{"batl":[[0,1.05,759.59]],"ltp":1.02,"tv":2586.92,"id":8535963}]}]}
{"op":"mcm","clk":"1005924651","pt":1580645483260,"mc":[{"id":"1.168219390","rc":[{"batl":[[1,1.06,548.22]],"ltp":1.02,"tv":2586.92,"id":8535963}]}]}
{"op":"mcm","clk":"1005926142","pt":1580645491348,"mc":[{"id":"1.168219390","rc":[{"batb":[[0,1.04,168.04],[1,1.01,10.51],[2,1.01,0]],"batl":[[0,1.06,42.01],[1,1.32,1166.57],[2,1.32,0]],"ltp":1.02,"tv":2586.92,"id":8535963},{"batb":[[0,11,10.62],[1,1.01,10.52],[2,1.01,0]],"ltp":11.0,"tv":398.97,"id":2309796}]}]}
{"op":"mcm","clk":"1005926299","pt":1580645492152,"mc":[{"id":"1.168219390","rc":[{"batb":[[0,1.01,10.51],[1,1.01,0]],"batl":[[0,1.32,1166.57],[1,1.32,0]],"ltp":1.02,"tv":2586.92,"id":8535963}]}]}
{"op":"mcm","clk":"1005926632","pt":1580645493955,"mc":[{"id":"1.168219390","rc":[{"batl":[[0,1.09,1063.65]],"ltp":1.02,"tv":2586.92,"id":8535963}]}]}
{"op":"mcm","clk":"1005927065","pt":1580645496615,"mc":[{"id":"1.168219390","rc":[{"trd":[[1.04,1344.32]],"batb":[[0,1.07,574.71],[1,1.01,10.51]],"ltp":1.04,"tv":3931.24,"id":8535963}],"tv":4330.22}]}
{"op":"mcm","clk":"1005927265","pt":1580645497470,"mc":[{"id":"1.168219390","rc":[{"batb":[[0,1.07,932.16],[1,1.03,678.55],[2,1.01,10.51]],"ltp":1.04,"tv":3931.24,"id":8535963},{"batb":[[1,8.8,7.16],[2,1.01,10.52]],"ltp":11.0,"tv":398.97,"id":2309796}]}]}
{"op":"mcm","clk":"1005927660","pt":1580645499763,"mc":[{"id":"1.168219390","rc":[{"batb":[[0,1.07,1598.4]],"batl":[[0,1.09,1223.99],[1,1.35,1063.8]],"ltp":1.04,"tv":3931.24,"id":8535963},{"batl":[[0,30,46.85]],"ltp":11.0,"tv":398.97,"id":2309796}]}]}
{"op":"mcm","clk":"1005927694","pt":1580645499975,"mc":[{"id":"1.168219390","rc":[{"batb":[[0,1.07,1766.44]],"ltp":1.04,"tv":3931.24,"id":8535963}]}]}
{"op":"mcm","clk":"1005927882","pt":1580645501092,"mc":[{"id":"1.168219390","rc":[{"batb":[[0,11.5,3.36],[1,11,10.62],[2,8.8,7.16]],"ltp":11.0,"tv":398.97,"id":2309796}]}]}
{"op":"mcm","clk":"1005928521","pt":1580645504717,"mc":[{"id":"1.168219390","rc":[{"batb":[[0,1.07,168.04]],"batl":[[0,1.35,1063.8],[1,1.35,0]],"ltp":1.04,"tv":3931.24,"id":8535963},{"batb":[[1,8.8,7.16],[2,1.01,10.52]],"ltp":11.0,"tv":398.97,"id":2309796}]}]}
{"op":"mcm","clk":"1005928843","pt":1580645506630,"mc":[{"id":"1.168219390","rc":[{"batb":[[0,1.03,678.55],[1,1.01,10.51],[2,1.01,0]],"ltp":1.04,"tv":3931.24,"id":8535963},{"batb":[[0,8.8,7.16],[1,1.01,10.52],[2,1.01,0]],"batl":[[1,1000,1.7]],"ltp":11.0,"tv":398.97,"id":2309796}]}]}
{"op":"mcm","clk":"1005928971","pt":1580645507285,"mc":[{"id":"1.168219390","rc":[{"batb":[[0,1.04,1120.27],[1,1.03,678.55],[2,1.01,10.51]],"batl":[[0,1.11,466.35],[1,1.12,729.02]],"ltp":1.04,"tv":3931.24,"id":8535963}]}]}
{"op":"mcm","clk":"1005929495","pt":1580645510302,"mc":[{"id":"1.168219390","rc":[{"batl":[[0,12,0.02]],"ltp":11.0,"tv":398.97,"id":2309796}]}]}
{"op":"mcm","clk":"1005929733","pt":1580645511694,"mc":[{"id":"1.168219390","rc":[{"trd":[[1.09,172.18]],"batl":[[0,1.05,1141.92]],"ltp":1.09,"tv":3931.42,"id":8535963},{"trd":[[12,0.02]],"ltp":12.0,"tv":398.99,"id":2309796}],"tv":4330.41}]}
{"op":"mcm","clk":"1005929903","pt":1580645512705,"mc":[{"id":"1.168219390","rc":[{"batb":[[0,17.5,7.24],[1,11,10.46],[2,1.01,10.52]],"ltp":12.0,"tv":398.99,"id":2309796}]}]}
{"op":"mcm","clk":"1005930044","pt":1580645513510,"mc":[{"id":"1.168219390","rc":[{"batb":[[0,1.04,1288.31]],"ltp":1.09,"tv":3931.42,"id":8535963}]}]}
{"op":"mcm","clk":"1005930240","pt":1580645514705,"mc":[{"id":"1.168219390","rc":[{"batl":[[1,1.32,1166.57]],"ltp":1.09,"tv":3931.42,"id":8535963},{"batl":[[0,65,40.51]],"ltp":12.0,"tv":398.99,"id":2309796}]}]}
{"op":"mcm","clk":"1005930307","pt":1580645515123,"mc":[{"id":"1.168219390","rc":[{"batl":[[1,1.06,42.01],[2,1.32,1166.57]],"ltp":1.09,"tv":3931.42,"id":8535963}]}]}
{"op":"mcm","clk":"1005931790","pt":1580645523718,"mc":[{"id":"1.168219390","rc":[{"batb":[[0,1.04,168.04]],"batl":[[0,1.06,42.01],[1,1.32,1166.57],[2,1.32,0]],"ltp":1.09,"tv":3931.42,"id":8535963}]}]}
{"op":"mcm","clk":"1005931886","pt":1580645524212,"mc":[{"id":"1.168219390","rc":[{"batb":[[0,1.01,10.51],[1,1.03,0],[2,1.01,0]],"batl":[[0,1.32,1166.57],[1,1.32,0]],"ltp":1.09,"tv":3931.42,"id":8535963},{"batb":[[0,11,10.46],[1,1.01,10.52],[2,1.01,0]],"ltp":12.0,"tv":398.99,"id":2309796}]}]}
{"op":"mcm","clk":"1005932285","pt":1580645526425,"mc":[{"id":"1.168219390","rc":[{"batl":[[0,1.09,1223.99]],"ltp":1.09,"tv":3931.42,"id":8535963}]}]}
{"op":"mcm","clk":"1005933940","pt":1580645535758,"mc":[{"id":"1.168219390","marketDefinition":{"bspMarket":false,"turnInPlayEnabled":true,"persistenceEnabled":true,"marketBaseRate":5.0,"eventId":"29681328","eventTypeId":"2","numberOfWinners":1,"bettingType":"ODDS","marketType":"SET_WINNER","marketTime":"2020-02-02T10:45:00.000Z","suspendTime":"2020-02-02T10:45:00.000Z","bspReconciled":false,"complete":true,"inPlay":true,"crossMatching":true,"runnersVoidable":false,"numberOfActiveRunners":2,"betDelay":3,"status":"SUSPENDED","runners":[{"status":"ACTIVE","sortPriority":1,"id":8535963,"name":"Nikola Milojevic"},{"status":"ACTIVE","sortPriority":2,"id":2309796,"name":"Robin Haase"}],"regulators":["MR_INT"],"countryCode":"IN","discountAllowed":true,"timezone":"UTC","openDate":"2020-02-02T10:45:00.000Z","version":3148670464,"name":"Set 2 Winner","eventName":"Milojevic v Haase"},"rc":[{"batb":[[0,1.01,10.52],[1,1.01,0]],"ltp":12.0,"tv":398.99,"id":2309796}]}]}
{"op":"mcm","clk":"1005939628","pt":1580645566982,"mc":[{"id":"1.168219390","tv":0.0}]}
{"op":"mcm","clk":"1005939867","pt":1580645568270,"mc":[{"id":"1.168219390","marketDefinition":{"bspMarket":false,"turnInPlayEnabled":true,"persistenceEnabled":true,"marketBaseRate":5.0,"eventId":"29681328","eventTypeId":"2","numberOfWinners":1,"bettingType":"ODDS","marketType":"SET_WINNER","marketTime":"2020-02-02T10:45:00.000Z","suspendTime":"2020-02-02T10:45:00.000Z","bspReconciled":false,"complete":true,"inPlay":true,"crossMatching":false,"runnersVoidable":false,"numberOfActiveRunners":0,"betDelay":3,"status":"CLOSED","settledTime":"2020-02-02T12:12:45.000Z","runners":[{"status":"WINNER","sortPriority":1,"id":8535963,"name":"Nikola Milojevic"},{"status":"LOSER","sortPriority":2,"id":2309796,"name":"Robin Haase"}],"regulators":["MR_INT"],"countryCode":"IN","discountAllowed":true,"timezone":"UTC","openDate":"2020-02-02T10:45:00.000Z","version":3148671922,"name":"Set 2 Winner","eventName":"Milojevic v Haase"}}]}
