{"op":"mcm","clk":"998176899","pt":1580569848193,"mc":[{"id":"1.168219387","marketDefinition":{"bspMarket":false,"turnInPlayEnabled":true,"persistenceEnabled":true,"marketBaseRate":5.0,"eventId":"29681328","eventTypeId":"2","numberOfWinners":1,"bettingType":"ODDS","marketType":"MATCH_ODDS","marketTime":"2020-02-02T11:30:00.000Z","suspendTime":"2020-02-02T11:30:00.000Z","bspReconciled":false,"complete":true,"inPlay":false,"crossMatching":false,"runnersVoidable":false,"numberOfActiveRunners":2,"betDelay":0,"status":"OPEN","runners":[{"status":"ACTIVE","sortPriority":1,"id":8535963,"name":"Nikola Milojevic"},{"status":"ACTIVE","sortPriority":2,"id":2309796,"name":"Robin Haase"}],"regulators":["MR_INT"],"countryCode":"IN","discountAllowed":false,"timezone":"UTC","openDate":"2020-02-02T11:30:00.000Z","version":3145750580,"name":"Match Odds","eventName":"Milojevic v Haase"},"rc":[{"batb":[[0,1.03,47.71],[1,1.02,3840.68],[2,1.01,3879.77]],"ltp":0.0,"tv":0.0,"id":8535963},{"batb":[[0,1.03,47.71],[1,1.02,3840.68],[2,1.01,3879.77]],"ltp":0.0,"tv":0.0,"id":2309796}]}]}
{"op":"mcm","clk":"998177333","pt":1580569849772,"mc":[{"id":"1.168219387","marketDefinition":{"bspMarket":false,"turnInPlayEnabled":true,"persistenceEnabled":true,"marketBaseRate":5.0,"eventId":"29681328","eventTypeId":"2","numberOfWinners":1,"bettingType":"ODDS","marketType":"MATCH_ODDS","marketTime":"2020-02-02T11:30:00.000Z","suspendTime":"2020-02-02T11:30:00.000Z","bspReconciled":false,"complete":true,"inPlay":false,"crossMatching":false,"runnersVoidable":false,"numberOfActiveRunners":2,"betDelay":0,"status":"OPEN","runners":[{"status":"ACTIVE","sortPriority":1,"id":8535963,"name":"Nikola Milojevic"},{"status":"ACTIVE","sortPriority":2,"id":2309796,"name":"Robin Haase"}],"regulators":["MR_INT"],"countryCode":"IN","discountAllowed":false,"timezone":"UTC","openDate":"2020-02-02T11:30:00.000Z","version":3145750580,"name":"Match Odds","eventName":"Milojevic v Haase"}}]}
{"op":"mcm","clk":"998177617","pt":1580569850776,"mc":[{"id":"1.168219387","marketDefinition":{"bspMarket":false,"turnInPlayEnabled":true,"persistenceEnabled":true,"marketBaseRate":5.0,"eventId":"29681328","eventTypeId":"2","numberOfWinners":1,"bettingType":"ODDS","marketType":"MATCH_ODDS","marketTime":"2020-02-02T11:30:00.000Z","suspendTime":"2020-02-02T11:30:00.000Z","bspReconciled":false,"complete":true,"inPlay":false,"crossMatching":false,"runnersVoidable":false,"numberOfActiveRunners":2,"betDelay":0,"status":"OPEN","runners":[{"status":"ACTIVE","sortPriority":1,"id":8535963,"name":"Nikola Milojevic"},{"status":"ACTIVE","sortPriority":2,"id":2309796,"name":"Robin Haase"}],"regulators":["MR_INT"],"countryCode":"IN","discountAllowed":true,"timezone":"UTC","openDate":"2020-02-02T11:30:00.000Z","version":3145750580,"name":"Match Odds","eventName":"Milojevic v Haase"}}]}
{"op":"mcm","clk":"998178785","pt":1580569855012,"mc":[{"id":"1.168219387","rc":[{"batb":[[0,1.05,152.2],[1,1.04,168.86],[2,1.03,237.77]],"ltp":0.0,"tv":0.0,"id":8535963},{"batb":[[0,1.05,152.2],[1,1.04,168.86],[2,1.03,237.77]],"ltp":0.0,"tv":0.0,"id":2309796}]}]}
{"op":"mcm","clk":"998186317","pt":1580569882959,"mc":[{"id":"1.168219387","marketDefinition":{"bspMarket":false,"turnInPlayEnabled":true,"persistenceEnabled":true,"marketBaseRate":5.0,"eventId":"29681328","eventTypeId":"2","numberOfWinners":1,"bettingType":"ODDS","marketType":"MATCH_ODDS","marketTime":"2020-02-02T11:30:00.000Z","suspendTime":"2020-02-02T11:30:00.000Z","bspReconciled":false,"complete":true,"inPlay":false,"crossMatching":true,"runnersVoidable":false,"numberOfActiveRunners":2,"betDelay":0,"status":"OPEN","runners":[{"status":"ACTIVE","sortPriority":1,"id":8535963,"name":"Nikola Milojevic"},{"status":"ACTIVE","sortPriority":2,"id":2309796,"name":"Robin Haase"}],"regulators":["MR_INT"],"countryCode":"IN","discountAllowed":true,"timezone":"UTC","openDate":"2020-02-02T11:30:00.000Z","version":3145750580,"name":"Match Odds","eventName":"Milojevic v Haase"}}]}
{"op":"mcm","clk":"998401441","pt":1580570709524,"mc":[{"id":"1.168219387","rc":[{"batb":[[0,1.06,50.48],[1,1.05,152.2],[2,1.04,168.86]],"ltp":0.0,"tv":0.0,"id":8535963},{"batb":[[0,1.06,50.48],[1,1.05,152.2],[2,1.04,168.86]],"ltp":0.0,"tv":0.0,"id":2309796}]}]}
{"op":"mcm","clk":"998502303","pt":1580571085218,"mc":[{"id":"1.168219387","rc":[{"batb":[[0,1.13,75.72],[1,1.06,50.48],[2,1.05,152.2]],"ltp":0.0,"tv":0.0,"id":8535963}]}]}
{"op":"mcm","clk":"999097805","pt":1580573538585,"mc":[{"id":"1.168219387","rc":[{"batl":[[0,990,2.2]],"ltp":0.0,"tv":0.0,"id":8535963},{"batl":[[0,990,2.2]],"ltp":0.0,"tv":0.0,"id":2309796}]}]}
{"op":"mcm","clk":"999739390","pt":1580576337361,"mc":[{"id":"1.168219387","rc":[{"batb":[[0,1.14,15.12],[1,1.13,75.72],[2,1.06,50.48]],"batl":[[0,16,3.36],[1,990,2.2]],"ltp":0.0,"tv":0.0,"id":8535963},{"batb":[[0,1.07,15.12],[1,1.06,50.48],[2,1.05,152.2]],"batl":[[0,9.8,3.36],[1,990,2.2]],"ltp":0.0,"tv":0.0,"id":2309796}]}]}
{"op":"mcm","clk":"999769294","pt":1580576559629,"mc":[{"id":"1.168219387","rc":[{"batb":[[0,1.08,37.86],[1,1.07,15.12]],"ltp":0.0,"tv":0.0,"id":2309796}]}]}
{"op":"mcm","clk":"999772359","pt":1580576580138,"mc":[{"id":"1.168219387","rc":[{"batb":[[1,1.05,152.2],[2,1.04,168.86]],"ltp":0.0,"tv":0.0,"id":2309796}]}]}
{"op":"mcm","clk":"999781528","pt":1580576641355,"mc":[{"id":"1.168219387","rc":[{"batb":[[0,1.09,15.12],[1,1.08,37.86],[2,1.05,152.2]],"ltp":0.0,"tv":0.0,"id":2309796}]}]}
{"op":"mcm","clk":"999786027","pt":1580576670264,"mc":[{"id":"1.168219387","rc":[{"batb":[[0,1.93,41.65],[1,1.14,15.12],[2,1.13,75.72]],"ltp":0.0,"tv":0.0,"id":8535963},{"batb":[[0,1.36,68.68],[1,1.09,15.12],[2,1.08,37.86]],"ltp":0.0,"tv":0.0,"id":2309796}]}]}
{"op":"mcm","clk":"999787531","pt":1580576680077,"mc":[{"id":"1.168219387","rc":[{"batb":[[0,1.14,15.12],[1,1.13,75.72],[2,1.06,50.48]],"ltp":0.0,"tv":0.0,"id":8535963},{"batb":[[0,1.09,15.12],[1,1.08,37.86],[2,1.05,152.2]],"ltp":0.0,"tv":0.0,"id":2309796}]}]}
{"op":"mcm","clk":"999788194","pt":1580576683407,"mc":[{"id":"1.168219387","rc":[{"batb":[[0,2.2,31.77],[1,2.18,41.65],[2,1.14,15.12]],"ltp":0.0,"tv":0.0,"id":8535963},{"batb":[[0,1.52,37.86],[1,1.09,15.12],[2,1.08,37.86]],"ltp":0.0,"tv":0.0,"id":2309796}]}]}
{"op":"mcm","clk":"999788470","pt":1580576684667,"mc":[{"id":"1.168219387","rc":[{"batb":[[1,1.4,57.11],[2,1.09,15.12]],"ltp":0.0,"tv":0.0,"id":2309796}]}]}
{"op":"mcm","clk":"999788552","pt":1580576685064,"mc":[{"id":"1.168219387","rc":[{"batb":[[0,1.54,51.62],[1,1.52,37.86]],"ltp":0.0,"tv":0.0,"id":2309796}]}]}
{"op":"mcm","clk":"999791282","pt":1580576702753,"mc":[{"id":"1.168219387","rc":[{"batb":[[2,1.13,75.72]],"ltp":0.0,"tv":0.0,"id":8535963},{"batb":[[2,1.08,37.86]],"ltp":0.0,"tv":0.0,"id":2309796}]}]}
{"op":"mcm","clk":"999802240","pt":1580576773662,"mc":[{"id":"1.168219387","rc":[{"batb":[[1,1.08,37.86],[2,1.05,152.2]],"ltp":0.0,"tv":0.0,"id":2309796}]}]}
{"op":"mcm","clk":"999802260","pt":1580576773781,"mc":[{"id":"1.168219387","rc":[{"batb":[[1,1.53,37.86],[2,1.08,37.86]],"ltp":0.0,"tv":0.0,"id":2309796}]}]}
{"op":"mcm","clk":"999832176","pt":1580576975187,"mc":[{"id":"1.168219387","rc":[{"batb":[[0,1.54,89.48],[1,1.08,37.86],[2,1.05,152.2]],"ltp":0.0,"tv":0.0,"id":2309796}]}]}
{"op":"mcm","clk":"999862944","pt":1580577176754,"mc":[{"id":"1.168219387","rc":[{"batb":[[0,1.57,37.86],[1,1.54,51.62],[2,1.08,37.86]],"ltp":0.0,"tv":0.0,"id":2309796}]}]}
{"op":"mcm","clk":"999863025","pt":1580577177231,"mc":[{"id":"1.168219387","rc":[{"batb":[[0,1.58,50.56],[1,1.57,37.86]],"ltp":0.0,"tv":0.0,"id":2309796}]}]}
{"op":"mcm","clk":"999886444","pt":1580577330132,"mc":[{"id":"1.168219387","rc":[{"batb":[[0,2.18,41.65],[1,1.13,75.72],[2,1.06,50.48]],"ltp":0.0,"tv":0.0,"id":8535963}]}]}
{"op":"mcm","clk":"999886810","pt":1580577332375,"mc":[{"id":"1.168219387","rc":[{"batb":[[0,1.94,33.42]],"ltp":0.0,"tv":0.0,"id":8535963}]}]}
{"op":"mcm","clk":"999887058","pt":1580577333997,"mc":[{"id":"1.168219387","rc":[{"batb":[[1,1.56,37.86]],"ltp":0.0,"tv":0.0,"id":2309796}]}]}
{"op":"mcm","clk":"999891168","pt":1580577359757,"mc":[{"id":"1.168219387","rc":[{"batb":[[0,1.95,13.44]],"ltp":0.0,"tv":0.0,"id":8535963}]}]}
{"op":"mcm","clk":"999891217","pt":1580577360079,"mc":[{"id":"1.168219387","rc":[{"batb":[[0,2,32.44],[1,1.95,13.44],[2,1.13,75.72]],"ltp":0.0,"tv":0.0,"id":8535963}]}]}
{"op":"mcm","clk":"999894216","pt":1580577379723,"mc":[{"id":"1.168219387","rc":[{"batb":[[1,1.57,37.86]],"ltp":0.0,"tv":0.0,"id":2309796}]}]}
{"op":"mcm","clk":"999894303","pt":1580577380215,"mc":[{"id":"1.168219387","rc":[{"batb":[[0,1.98,30.98]],"ltp":0.0,"tv":0.0,"id":8535963}]}]}
{"op":"mcm","clk":"999894713","pt":1580577383108,"mc":[{"id":"1.168219387","rc":[{"batb":[[0,1.58,88.42],[1,1.08,37.86],[2,1.05,152.2]],"ltp":0.0,"tv":0.0,"id":2309796}]}]}
{"op":"mcm","clk":"999895715","pt":1580577389442,"mc":[{"id":"1.168219387","rc":[{"batb":[[0,1.58,50.56],[1,1.57,37.86],[2,1.08,37.86]],"ltp":0.0,"tv":0.0,"id":2309796}]}]}
{"op":"mcm","clk":"999900575","pt":1580577418599,"mc":[{"id":"1.168219387","rc":[{"batb":[[1,1.13,75.72],[2,1.06,50.48]],"ltp":0.0,"tv":0.0,"id":8535963}]}]}
{"op":"mcm","clk":"999900633","pt":1580577419005,"mc":[{"id":"1.168219387","rc":[{"batb":[[1,1.08,37.86],[2,1.05,152.2]],"ltp":0.0,"tv":0.0,"id":2309796}]}]}
{"op":"mcm","clk":"999901876","pt":1580577426648,"mc":[{"id":"1.168219387","rc":[{"batb":[[0,2.08,43.92],[1,1.98,30.98],[2,1.13,75.72]],"ltp":0.0,"tv":0.0,"id":8535963}]}]}
{"op":"mcm","clk":"999901945","pt":1580577427034,"mc":[{"id":"1.168219387","rc":[{"batb":[[0,2.12,31.54],[1,2.08,43.92]],"ltp":0.0,"tv":0.0,"id":8535963},{"batb":[[1,1.57,35.59],[2,1.08,37.86]],"ltp":0.0,"tv":0.0,"id":2309796}]}]}
{"op":"mcm","clk":"999918050","pt":1580577536753,"mc":[{"id":"1.168219387","rc":[{"batb":[[1,1.08,37.86],[2,1.05,152.2]],"ltp":0.0,"tv":0.0,"id":2309796}]}]}
{"op":"mcm","clk":"999918118","pt":1580577537231,"mc":[{"id":"1.168219387","rc":[{"batb":[[0,1.62,47.04],[1,1.61,35.59],[2,1.08,37.86]],"ltp":0.0,"tv":0.0,"id":2309796}]}]}
{"op":"mcm","clk":"999944305","pt":1580577707727,"mc":[{"id":"1.168219387","rc":[{"batb":[[1,1.13,75.72],[2,1.06,50.48]],"ltp":0.0,"tv":0.0,"id":8535963},{"batb":[[1,1.08,37.86],[2,1.05,152.2]],"ltp":0.0,"tv":0.0,"id":2309796}]}]}
{"op":"mcm","clk":"999944404","pt":1580577708416,"mc":[{"id":"1.168219387","rc":[{"batb":[[1,2.1,43.92],[2,1.13,75.72]],"ltp":0.0,"tv":0.0,"id":8535963},{"batb":[[1,1.6,35.59],[2,1.08,37.86]],"ltp":0.0,"tv":0.0,"id":2309796}]}]}
{"op":"mcm","clk":"999973646","pt":1580577897766,"mc":[{"id":"1.168219387","rc":[{"batb":[[0,2.1,43.92],[1,1.13,75.72],[2,1.06,50.48]],"ltp":0.0,"tv":0.0,"id":8535963}]}]}
{"op":"mcm","clk":"999973734","pt":1580577898295,"mc":[{"id":"1.168219387","rc":[{"batb":[[0,2.14,31.96],[1,2.1,43.92],[2,1.13,75.72]],"ltp":0.0,"tv":0.0,"id":8535963}]}]}
{"op":"mcm","clk":"999974789","pt":1580577904325,"mc":[{"id":"1.168219387","rc":[{"batb":[[0,2.14,75.88],[1,1.13,75.72],[2,1.06,50.48]],"ltp":0.0,"tv":0.0,"id":8535963}]}]}
{"op":"mcm","clk":"999977423","pt":1580577920230,"mc":[{"id":"1.168219387","rc":[{"batb":[[0,2.14,31.96],[1,2.12,43.92],[2,1.13,75.72]],"ltp":0.0,"tv":0.0,"id":8535963},{"batb":[[1,1.59,35.59]],"ltp":0.0,"tv":0.0,"id":2309796}]}]}
{"op":"mcm","clk":"1000058588","pt":1580578430335,"mc":[{"id":"1.168219387","rc":[{"batb":[[0,2.12,43.92],[1,1.13,75.72],[2,1.06,50.48]],"ltp":0.0,"tv":0.0,"id":8535963}]}]}
{"op":"mcm","clk":"1000059532","pt":1580578435561,"mc":[{"id":"1.168219387","rc":[{"batb":[[0,1.89,34.6]],"ltp":0.0,"tv":0.0,"id":8535963},{"batb":[[0,1.66,35.59],[1,1.62,47.04]],"ltp":0.0,"tv":0.0,"id":2309796}]}]}
{"op":"mcm","clk":"1000059598","pt":1580578435940,"mc":[{"id":"1.168219387","rc":[{"batb":[[0,1.67,44.05],[1,1.66,35.59]],"ltp":0.0,"tv":0.0,"id":2309796}]}]}
{"op":"mcm","clk":"1000060249","pt":1580578439643,"mc":[{"id":"1.168219387","rc":[{"batb":[[0,2.02,45.43],[1,1.89,34.6],[2,1.13,75.72]],"ltp":0.0,"tv":0.0,"id":8535963},{"batb":[[1,1.65,35.59]],"ltp":0.0,"tv":0.0,"id":2309796}]}]}
{"op":"mcm","clk":"1000060352","pt":1580578440254,"mc":[{"id":"1.168219387","rc":[{"batb":[[0,2.04,31.87],[1,2.02,45.43]],"ltp":0.0,"tv":0.0,"id":8535963}]}]}
{"op":"mcm","clk":"1000204864","pt":1580579341091,"mc":[{"id":"1.168219387","rc":[{"batb":[[2,1.13,75.72]],"ltp":0.0,"tv":0.0,"id":2309796}]}]}
{"op":"mcm","clk":"1000299305","pt":1580580031073,"mc":[{"id":"1.168219387","rc":[{"batb":[[1,1.13,75.72],[2,1.06,50.48]],"ltp":0.0,"tv":0.0,"id":8535963}]}]}
{"op":"mcm","clk":"1000299758","pt":1580580034391,"mc":[{"id":"1.168219387","rc":[{"batb":[[0,1.65,35.59],[1,1.13,75.72],[2,1.08,37.86]],"ltp":0.0,"tv":0.0,"id":2309796}]}]}
{"op":"mcm","clk":"1000300442","pt":1580580039431,"mc":[{"id":"1.168219387","rc":[{"batb":[[0,1.39,58.91]],"ltp":0.0,"tv":0.0,"id":2309796}]}]}
{"op":"mcm","clk":"1000303258","pt":1580580057574,"mc":[{"id":"1.168219387","rc":[{"batb":[[0,1.4,12.6]],"ltp":0.0,"tv":0.0,"id":2309796}]}]}
{"op":"mcm","clk":"1000303286","pt":1580580057769,"mc":[{"id":"1.168219387","rc":[{"batb":[[0,1.46,56.01],[1,1.4,12.6],[2,1.13,75.72]],"ltp":0.0,"tv":0.0,"id":2309796}]}]}
{"op":"mcm","clk":"1000305123","pt":1580580069669,"mc":[{"id":"1.168219387","rc":[{"batb":[[0,2.26,31.48],[1,2.2,40.89],[2,1.13,75.72]],"ltp":0.0,"tv":0.0,"id":8535963},{"batb":[[0,1.57,51.99],[1,1.55,35.59],[2,1.4,12.6]],"ltp":0.0,"tv":0.0,"id":2309796}]}]}
{"op":"mcm","clk":"1000311206","pt":1580580112936,"mc":[{"id":"1.168219387","rc":[{"batb":[[2,1.13,75.72]],"ltp":0.0,"tv":0.0,"id":2309796}]}]}
{"op":"mcm","clk":"1000353807","pt":1580580412238,"mc":[{"id":"1.168219387","rc":[{"batb":[[0,2.26,47.21]],"ltp":0.0,"tv":0.0,"id":8535963},{"batb":[[0,1.57,77.78]],"ltp":0.0,"tv":0.0,"id":2309796}]}]}
{"op":"mcm","clk":"1000359194","pt":1580580446176,"mc":[{"id":"1.168219387","rc":[{"batb":[[0,2.2,40.89],[1,1.13,75.72],[2,1.06,50.48]],"ltp":0.0,"tv":0.0,"id":8535963}]}]}
{"op":"mcm","clk":"1000360025","pt":1580580451514,"mc":[{"id":"1.168219387","rc":[{"batb":[[0,1.82,56.03]],"ltp":0.0,"tv":0.0,"id":8535963},{"batb":[[0,1.61,35.59],[1,1.57,77.78]],"ltp":0.0,"tv":0.0,"id":2309796}]}]}
{"op":"mcm","clk":"1000360085","pt":1580580451895,"mc":[{"id":"1.168219387","rc":[{"batb":[[0,1.62,70.83],[1,1.61,35.59]],"ltp":0.0,"tv":0.0,"id":2309796}]}]}
{"op":"mcm","clk":"1000361212","pt":1580580458762,"mc":[{"id":"1.168219387","rc":[{"batb":[[0,2.1,43.16],[1,1.82,56.03],[2,1.13,75.72]],"ltp":0.0,"tv":0.0,"id":8535963},{"batb":[[1,1.6,35.59]],"ltp":0.0,"tv":0.0,"id":2309796}]}]}
{"op":"mcm","clk":"1000361285","pt":1580580459239,"mc":[{"id":"1.168219387","rc":[{"batb":[[0,2.12,48.04],[1,2.1,43.16]],"ltp":0.0,"tv":0.0,"id":8535963}]}]}
{"op":"mcm","clk":"1000367235","pt":1580580498412,"mc":[{"id":"1.168219387","rc":[{"batb":[[1,1.6,56.79]],"ltp":0.0,"tv":0.0,"id":2309796}]}]}
{"op":"mcm","clk":"1000386534","pt":1580580615749,"mc":[{"id":"1.168219387","rc":[{"batb":[[1,1.13,75.72],[2,1.06,50.48]],"ltp":0.0,"tv":0.0,"id":8535963},{"batb":[[0,1.64,56.79],[1,1.62,70.83]],"ltp":0.0,"tv":0.0,"id":2309796}]}]}
{"op":"mcm","clk":"1000386640","pt":1580580616340,"mc":[{"id":"1.168219387","rc":[{"batb":[[1,2.06,43.92],[2,1.13,75.72]],"ltp":0.0,"tv":0.0,"id":8535963},{"batb":[[0,1.65,67.53],[1,1.64,56.79]],"ltp":0.0,"tv":0.0,"id":2309796}]}]}
{"op":"mcm","clk":"1000388175","pt":1580580625601,"mc":[{"id":"1.168219387","rc":[{"batb":[[1,1.63,43.92]],"ltp":0.0,"tv":0.0,"id":2309796}]}]}
{"op":"mcm","clk":"1000396413","pt":1580580679053,"mc":[{"id":"1.168219387","rc":[{"batb":[[1,1.63,56.04]],"ltp":0.0,"tv":0.0,"id":2309796}]}]}
{"op":"mcm","clk":"1000420102","pt":1580580837540,"mc":[{"id":"1.168219387","rc":[{"batb":[[0,2.06,43.92],[1,1.13,75.72],[2,1.06,50.48]],"ltp":0.0,"tv":0.0,"id":8535963},{"batb":[[0,1.63,56.04],[1,1.13,75.72],[2,1.08,37.86]],"ltp":0.0,"tv":0.0,"id":2309796}]}]}
{"op":"mcm","clk":"1000420211","pt":1580580838274,"mc":[{"id":"1.168219387","rc":[{"batb":[[0,2.12,46.79],[1,2.06,43.92],[2,1.13,75.72]],"ltp":0.0,"tv":0.0,"id":8535963},{"batb":[[0,1.66,67.4],[1,1.63,56.04],[2,1.13,75.72]],"ltp":0.0,"tv":0.0,"id":2309796}]}]}
{"op":"mcm","clk":"1000910631","pt":1580583909033,"mc":[{"id":"1.168219387","rc":[{"batb":[[0,2.12,62.29]],"ltp":0.0,"tv":0.0,"id":8535963},{"batb":[[0,1.66,89.78]],"ltp":0.0,"tv":0.0,"id":2309796}]}]}
{"op":"mcm","clk":"1001017527","pt":1580584438455,"mc":[{"id":"1.168219387","rc":[{"batb":[[0,2.06,43.92],[1,1.13,75.72],[2,1.06,50.48]],"ltp":0.0,"tv":0.0,"id":8535963},{"batb":[[0,1.63,56.04],[1,1.13,75.72],[2,1.08,37.86]],"ltp":0.0,"tv":0.0,"id":2309796}]}]}
{"op":"mcm","clk":"1001017611","pt":1580584438837,"mc":[{"id":"1.168219387","rc":[{"batb":[[0,2.08,63.81],[1,2.06,43.92],[2,1.13,75.72]],"ltp":0.0,"tv":0.0,"id":8535963},{"batb":[[0,1.64,91.07],[1,1.63,56.04],[2,1.13,75.72]],"ltp":0.0,"tv":0.0,"id":2309796}]}]}
{"op":"mcm","clk":"1001185528","pt":1580585313903,"mc":[{"id":"1.168219387","rc":[{"batl":[[1,95,15.9],[2,990,2.2]],"ltp":0.0,"tv":0.0,"id":8535963},{"batl":[[1,95,15.9],[2,990,2.2]],"ltp":0.0,"tv":0.0,"id":2309796}]}]}
{"op":"mcm","clk":"1001299917","pt":1580585907603,"mc":[{"id":"1.168219387","rc":[{"batb":[[2,1.93,40.71]],"ltp":0.0,"tv":0.0,"id":8535963},{"batb":[[2,1.58,65.28]],"ltp":0.0,"tv":0.0,"id":2309796}]}]}
{"op":"mcm","clk":"1001614813","pt":1580587700994,"mc":[{"id":"1.168219387","rc":[{"batb":[[0,2.08,79.31]],"ltp":0.0,"tv":0.0,"id":8535963},{"batb":[[0,1.64,113.57]],"ltp":0.0,"tv":0.0,"id":2309796}]}]}
{"op":"mcm","clk":"1001615277","pt":1580587703215,"mc":[{"id":"1.168219387","rc":[{"batb":[[2,1.13,75.72]],"ltp":0.0,"tv":0.0,"id":8535963},{"batb":[[2,1.13,75.72]],"ltp":0.0,"tv":0.0,"id":2309796}]}]}
{"op":"mcm","clk":"1001615403","pt":1580587703796,"mc":[{"id":"1.168219387","rc":[{"batb":[[2,1.93,51.29]],"ltp":0.0,"tv":0.0,"id":8535963},{"batb":[[2,1.58,82.25]],"ltp":0.0,"tv":0.0,"id":2309796}]}]}
{"op":"mcm","clk":"1001684458","pt":1580588039296,"mc":[{"id":"1.168219387","rc":[{"batb":[[0,2.08,79.56]],"ltp":0.0,"tv":0.0,"id":8535963},{"batb":[[0,1.64,114.07]],"ltp":0.0,"tv":0.0,"id":2309796}]}]}
{"op":"mcm","clk":"1001865183","pt":1580589022733,"mc":[{"id":"1.168219387","rc":[{"batb":[[0,1.65,5.91],[1,1.64,114.07],[2,1.63,56.04]],"ltp":0.0,"tv":0.0,"id":2309796}]}]}
{"op":"mcm","clk":"1001865276","pt":1580589023278,"mc":[{"id":"1.168219387","rc":[{"batb":[[0,1.66,112.52],[1,1.65,5.91]],"ltp":0.0,"tv":0.0,"id":2309796}]}]}
{"op":"mcm","clk":"1002110336","pt":1580590580705,"mc":[{"id":"1.168219387","rc":[{"batb":[[0,2.06,43.92],[1,1.93,51.29],[2,1.13,75.72]],"batl":[[0,2.5,74.61],[1,16,3.36],[2,95,15.9]],"ltp":0.0,"tv":0.0,"id":8535963},{"batb":[[0,1.65,5.91],[1,1.63,56.04],[2,1.58,82.25]],"batl":[[0,1.92,86.31],[1,9.8,3.36],[2,95,15.9]],"ltp":0.0,"tv":0.0,"id":2309796}]}]}
{"op":"mcm","clk":"1002111960","pt":1580590594532,"mc":[{"id":"1.168219387","rc":[{"batl":[[0,16,3.36],[1,95,15.9],[2,990,2.2]],"ltp":0.0,"tv":0.0,"id":8535963},{"batl":[[0,9.8,3.36],[1,95,15.9],[2,990,2.2]],"ltp":0.0,"tv":0.0,"id":2309796}]}]}
{"op":"mcm","clk":"1002112393","pt":1580590598947,"mc":[{"id":"1.168219387","rc":[{"batb":[[0,2.08,79.56],[1,2.06,43.92],[2,1.93,51.29]],"ltp":0.0,"tv":0.0,"id":8535963},{"batb":[[0,1.66,112.52],[1,1.65,5.91],[2,1.63,56.04]],"ltp":0.0,"tv":0.0,"id":2309796}]}]}
{"op":"mcm","clk":"1002138687","pt":1580590844695,"mc":[{"id":"1.168219387","rc":[{"batb":[[0,2.08,142.81],[2,1.13,75.72]],"ltp":0.0,"tv":0.0,"id":8535963},{"batb":[[0,1.66,201.81]],"ltp":0.0,"tv":0.0,"id":2309796}]}]}
{"op":"mcm","clk":"1002138763","pt":1580590845281,"mc":[{"id":"1.168219387","rc":[{"batb":[[2,1.97,88.21]],"ltp":0.0,"tv":0.0,"id":8535963}]}]}
{"op":"mcm","clk":"1002232398","pt":1580591655653,"mc":[{"id":"1.168219387","rc":[{"batb":[[0,2.12,140.79],[1,2.1,7.45],[2,2.06,43.92]],"ltp":0.0,"tv":0.0,"id":8535963}]}]}
{"op":"mcm","clk":"1002232487","pt":1580591656565,"mc":[{"id":"1.168219387","rc":[{"batb":[[0,1.67,207.38],[1,1.63,56.04],[2,1.6,142.61]],"ltp":0.0,"tv":0.0,"id":2309796}]}]}
{"op":"mcm","clk":"1002287007","pt":1580592150663,"mc":[{"id":"1.168219387","rc":[{"batb":[[0,2.26,26.89]],"ltp":0.0,"tv":0.0,"id":8535963}]}]}
{"op":"mcm","clk":"1002291379","pt":1580592191651,"mc":[{"id":"1.168219387","rc":[{"batb":[[1,2.18,71.96],[2,2.1,7.45]],"ltp":0.0,"tv":0.0,"id":8535963},{"batb":[[0,1.7,94.52],[1,1.67,5.91],[2,1.63,56.04]],"ltp":0.0,"tv":0.0,"id":2309796}]}]}
{"op":"mcm","clk":"1002296760","pt":1580592240597,"mc":[{"id":"1.168219387","rc":[{"batb":[[0,2.18,71.96],[1,2.1,7.45],[2,2.06,43.92]],"ltp":0.0,"tv":0.0,"id":8535963}]}]}
{"op":"mcm","clk":"1002438556","pt":1580593690686,"mc":[{"id":"1.168219387","rc":[{"batb":[[0,2.18,70.32]],"ltp":0.0,"tv":0.0,"id":8535963},{"batb":[[0,1.7,96.64]],"ltp":0.0,"tv":0.0,"id":2309796}]}]}
{"op":"mcm","clk":"1002477217","pt":1580594192318,"mc":[{"id":"1.168219387","rc":[{"batb":[[1,2.06,43.92],[2,1.98,7.45]],"ltp":0.0,"tv":0.0,"id":8535963}]}]}
{"op":"mcm","clk":"1002477273","pt":1580594192940,"mc":[{"id":"1.168219387","rc":[{"batb":[[0,1.71,5.91],[1,1.7,96.64]],"ltp":0.0,"tv":0.0,"id":2309796}]}]}
{"op":"mcm","clk":"1002486032","pt":1580594311301,"mc":[{"id":"1.168219387","rc":[{"batb":[[0,1.72,68.47],[1,1.71,5.91]],"ltp":0.0,"tv":0.0,"id":2309796}]}]}
{"op":"mcm","clk":"1002524484","pt":1580594893549,"mc":[{"id":"1.168219387","rc":[{"batb":[[2,2,37.86]],"ltp":0.0,"tv":0.0,"id":8535963}]}]}
{"op":"mcm","clk":"1002649403","pt":1580596613475,"mc":[{"id":"1.168219387","rc":[{"batl":[[0,1.84,420.1],[1,9.8,3.36],[2,95,15.9]],"ltp":0.0,"tv":0.0,"id":2309796}]}]}
{"op":"mcm","clk":"1002649549","pt":1580596616280,"mc":[{"id":"1.168219387","rc":[{"batl":[[1,1.85,420.1],[2,9.8,3.36]],"ltp":0.0,"tv":0.0,"id":2309796}]}]}
{"op":"mcm","clk":"1002649677","pt":1580596618705,"mc":[{"id":"1.168219387","rc":[{"batl":[[2,1.86,420.1]],"ltp":0.0,"tv":0.0,"id":2309796}]}]}
{"op":"mcm","clk":"1002780357","pt":1580598673402,"mc":[{"id":"1.168219387","rc":[{"batb":[[0,2.2,7.45],[1,2.18,70.32],[2,2.06,43.92]],"ltp":0.0,"tv":0.0,"id":8535963},{"batb":[[1,1.63,56.04],[2,1.61,37.86]],"ltp":0.0,"tv":0.0,"id":2309796}]}]}
{"op":"mcm","clk":"1002784739","pt":1580598729643,"mc":[{"id":"1.168219387","rc":[{"batb":[[0,2.22,44.34],[1,2.2,7.45]],"ltp":0.0,"tv":0.0,"id":8535963},{"batb":[[0,1.7,96.64]],"ltp":0.0,"tv":0.0,"id":2309796}]}]}
{"op":"mcm","clk":"1002784759","pt":1580598729861,"mc":[{"id":"1.168219387","rc":[{"batb":[[1,1.64,205.32],[2,1.63,56.04]],"ltp":0.0,"tv":0.0,"id":2309796}]}]}
{"op":"mcm","clk":"1002799785","pt":1580598923431,"mc":[{"id":"1.168219387","rc":[{"batb":[[1,1.63,56.04],[2,1.61,37.86]],"ltp":0.0,"tv":0.0,"id":2309796}]}]}
{"op":"mcm","clk":"1002874338","pt":1580599921682,"mc":[{"id":"1.168219387","rc":[{"batb":[[1,1.63,243.54]],"ltp":0.0,"tv":0.0,"id":2309796}]}]}
{"op":"mcm","clk":"1002967481","pt":1580601316307,"mc":[{"id":"1.168219387","rc":[{"batb":[[1,2.06,43.92],[2,2.02,115.81]],"ltp":0.0,"tv":0.0,"id":8535963}]}]}
{"op":"mcm","clk":"1002967512","pt":1580601316823,"mc":[{"id":"1.168219387","rc":[{"batb":[[0,1.71,6.01],[1,1.7,96.64],[2,1.63,243.54]],"ltp":0.0,"tv":0.0,"id":2309796}]}]}
{"op":"mcm","clk":"1002975127","pt":1580601422348,"mc":[{"id":"1.168219387","rc":[{"batb":[[0,2.2,57.13]],"ltp":0.0,"tv":0.0,"id":8535963},{"batb":[[0,1.72,68.47],[1,1.71,6.01]],"ltp":0.0,"tv":0.0,"id":2309796}]}]}
{"op":"mcm","clk":"1003084035","pt":1580602758541,"mc":[{"id":"1.168219387","rc":[{"batb":[[0,1.73,258.02],[1,1.72,68.47],[2,1.71,6.01]],"ltp":0.0,"tv":0.0,"id":2309796}]}]}
{"op":"mcm","clk":"1003084182","pt":1580602760465,"mc":[{"id":"1.168219387","rc":[{"batb":[[2,2,37.86]],"ltp":0.0,"tv":0.0,"id":8535963}]}]}
{"op":"mcm","clk":"1003084260","pt":1580602761655,"mc":[{"id":"1.168219387","rc":[{"batb":[[1,2,37.86],[2,1.94,125.67]],"ltp":0.0,"tv":0.0,"id":8535963}]}]}
{"op":"mcm","clk":"1003084468","pt":1580602764457,"mc":[{"id":"1.168219387","rc":[{"batb":[[2,1.97,46.19]],"ltp":0.0,"tv":0.0,"id":8535963}]}]}
{"op":"mcm","clk":"1003091535","pt":1580602863485,"mc":[{"id":"1.168219387","rc":[{"batb":[[0,1.74,41.53],[1,1.73,258.02]],"ltp":0.0,"tv":0.0,"id":2309796}]}]}
{"op":"mcm","clk":"1003101469","pt":1580603002248,"mc":[{"id":"1.168219387","rc":[{"batb":[[1,1.71,6.01],[2,1.68,173.72]],"ltp":0.0,"tv":0.0,"id":2309796}]}]}
{"op":"mcm","clk":"1003111040","pt":1580603136419,"mc":[{"id":"1.168219387","rc":[{"batb":[[0,1.72,328.06]],"ltp":0.0,"tv":0.0,"id":2309796}]}]}
{"op":"mcm","clk":"1003176900","pt":1580603947105,"mc":[{"id":"1.168219387","rc":[{"batb":[[1,1.68,173.72],[2,1.67,56.04]],"ltp":0.0,"tv":0.0,"id":2309796}]}]}
{"op":"mcm","clk":"1003197763","pt":1580604292227,"mc":[{"id":"1.168219387","rc":[{"batb":[[1,1.69,56.04],[2,1.68,173.72]],"ltp":0.0,"tv":0.0,"id":2309796}]}]}
{"op":"mcm","clk":"1003199715","pt":1580604321761,"mc":[{"id":"1.168219387","rc":[{"trd":[[2.2,50.41]],"batb":[[0,2.2,31.93]],"ltp":2.2,"tv":50.41,"id":8535963}],"tv":50.41}]}
{"op":"mcm","clk":"1003199751","pt":1580604322378,"mc":[{"id":"1.168219387","rc":[{"batb":[[0,1.73,86.41],[1,1.72,259.59],[2,1.69,56.04]],"ltp":0.0,"tv":0.0,"id":2309796}]}]}
{"op":"mcm","clk":"1003200533","pt":1580604334490,"mc":[{"id":"1.168219387","rc":[{"batb":[[0,1.73,344.43],[1,1.69,56.04],[2,1.68,173.72]],"ltp":0.0,"tv":0.0,"id":2309796}]}]}
{"op":"mcm","clk":"1003211285","pt":1580604526507,"mc":[{"id":"1.168219387","rc":[{"batb":[[1,1.68,173.72],[2,1.64,56.04]],"ltp":0.0,"tv":0.0,"id":2309796}]}]}
{"op":"mcm","clk":"1003214059","pt":1580604569703,"mc":[{"id":"1.168219387","rc":[{"batb":[[2,1.61,37.86]],"ltp":0.0,"tv":0.0,"id":2309796}]}]}
{"op":"mcm","clk":"1003214069","pt":1580604569805,"mc":[{"id":"1.168219387","rc":[{"batb":[[1,1.69,56.04],[2,1.68,173.72]],"ltp":0.0,"tv":0.0,"id":2309796}]}]}
{"op":"mcm","clk":"1003243912","pt":1580605053732,"mc":[{"id":"1.168219387","rc":[{"batb":[[1,1.68,173.72],[2,1.64,56.04]],"ltp":0.0,"tv":0.0,"id":2309796}]}]}
{"op":"mcm","clk":"1003245749","pt":1580605087297,"mc":[{"id":"1.168219387","rc":[{"batb":[[1,1.69,56.04],[2,1.68,173.72]],"ltp":0.0,"tv":0.0,"id":2309796}]}]}
{"op":"mcm","clk":"1003302786","pt":1580605929656,"mc":[{"id":"1.168219387","rc":[{"batb":[[1,1.68,173.72],[2,1.64,56.04]],"ltp":0.0,"tv":0.0,"id":2309796}]}]}
{"op":"mcm","clk":"1003305648","pt":1580605971249,"mc":[{"id":"1.168219387","rc":[{"batb":[[1,1.69,56.04],[2,1.68,173.72]],"ltp":0.0,"tv":0.0,"id":2309796}]}]}
{"op":"mcm","clk":"1003374981","pt":1580606910102,"mc":[{"id":"1.168219387","rc":[{"batb":[[0,1.73,86.41]],"ltp":0.0,"tv":0.0,"id":2309796}]}]}
{"op":"mcm","clk":"1003375091","pt":1580606911641,"mc":[{"id":"1.168219387","rc":[{"batb":[[0,1.73,344.43]],"ltp":0.0,"tv":0.0,"id":2309796}]}]}
{"op":"mcm","clk":"1003387255","pt":1580607061268,"mc":[{"id":"1.168219387","rc":[{"batb":[[1,1.68,173.72],[2,1.64,56.04]],"ltp":0.0,"tv":0.0,"id":2309796}]}]}
{"op":"mcm","clk":"1003390024","pt":1580607096271,"mc":[{"id":"1.168219387","rc":[{"batb":[[1,1.69,56.04],[2,1.68,173.72]],"ltp":0.0,"tv":0.0,"id":2309796}]}]}
{"op":"mcm","clk":"1003634816","pt":1580610511653,"mc":[{"id":"1.168219387","rc":[{"batb":[[0,1.73,86.41]],"ltp":0.0,"tv":0.0,"id":2309796}]}]}
{"op":"mcm","clk":"1003646134","pt":1580610661921,"mc":[{"id":"1.168219387","rc":[{"batb":[[0,1.73,344.43]],"ltp":0.0,"tv":0.0,"id":2309796}]}]}
{"op":"mcm","clk":"1003655687","pt":1580610788930,"mc":[{"id":"1.168219387","rc":[{"batb":[[0,1.73,476.8]],"ltp":0.0,"tv":0.0,"id":2309796}]}]}
{"op":"mcm","clk":"1003655808","pt":1580610790627,"mc":[{"id":"1.168219387","rc":[{"batb":[[2,1.68,265.03]],"ltp":0.0,"tv":0.0,"id":2309796}]}]}
{"op":"mcm","clk":"1003786798","pt":1580612961947,"mc":[{"id":"1.168219387","rc":[{"batb":[[1,1.68,265.03],[2,1.64,56.04]],"ltp":0.0,"tv":0.0,"id":2309796}]}]}
{"op":"mcm","clk":"1003788254","pt":1580612998692,"mc":[{"id":"1.168219387","rc":[{"batb":[[2,1.61,37.86]],"ltp":0.0,"tv":0.0,"id":2309796}]}]}
{"op":"mcm","clk":"1003788259","pt":1580612998795,"mc":[{"id":"1.168219387","rc":[{"batb":[[1,1.69,56.04],[2,1.68,265.03]],"ltp":0.0,"tv":0.0,"id":2309796}]}]}
{"op":"mcm","clk":"1003826249","pt":1580613963751,"mc":[{"id":"1.168219387","rc":[{"batb":[[1,1.68,265.03],[2,1.61,37.86]],"ltp":0.0,"tv":0.0,"id":2309796}]}]}
{"op":"mcm","clk":"1003826256","pt":1580613963855,"mc":[{"id":"1.168219387","rc":[{"batb":[[2,1.64,56.04]],"ltp":0.0,"tv":0.0,"id":2309796}]}]}
{"op":"mcm","clk":"1003828170","pt":1580614000374,"mc":[{"id":"1.168219387","rc":[{"batb":[[1,1.69,56.04],[2,1.68,265.03]],"ltp":0.0,"tv":0.0,"id":2309796}]}]}
{"op":"mcm","clk":"1003836786","pt":1580614169592,"mc":[{"id":"1.168219387","rc":[{"trd":[[1.75,4.54]],"batl":[[0,1.84,420.35]],"ltp":1.75,"tv":4.53,"id":2309796}],"tv":54.95}]}
{"op":"mcm","clk":"1003841622","pt":1580614262784,"mc":[{"id":"1.168219387","rc":[{"batb":[[0,1.73,86.41]],"ltp":1.75,"tv":4.53,"id":2309796}]}]}
{"op":"mcm","clk":"1003881643","pt":1580615110510,"mc":[{"id":"1.168219387","rc":[{"batl":[[1,990,2.2],[2,1000,0.02]],"ltp":2.2,"tv":50.41,"id":8535963},{"batb":[[0,1.73,478.54]],"ltp":1.75,"tv":4.53,"id":2309796}]}]}
{"op":"mcm","clk":"1003916305","pt":1580616089210,"mc":[{"id":"1.168219387","rc":[{"batb":[[2,1.61,37.86]],"ltp":1.75,"tv":4.53,"id":2309796}]}]}
{"op":"mcm","clk":"1003916334","pt":1580616089828,"mc":[{"id":"1.168219387","rc":[{"batb":[[2,1.68,265.03]],"ltp":1.75,"tv":4.53,"id":2309796}]}]}
{"op":"mcm","clk":"1003916636","pt":1580616096226,"mc":[{"id":"1.168219387","rc":[{"batb":[[2,1.98,46.19]],"ltp":2.2,"tv":50.41,"id":8535963},{"batb":[[1,1.68,265.03],[2,1.67,56.04]],"ltp":1.75,"tv":4.53,"id":2309796}]}]}
{"op":"mcm","clk":"1003939117","pt":1580616653561,"mc":[{"id":"1.168219387","rc":[{"batl":[[1,95,15.9],[2,990,2.2]],"ltp":2.2,"tv":50.41,"id":8535963}]}]}
{"op":"mcm","clk":"1003986149","pt":1580617621141,"mc":[{"id":"1.168219387","rc":[{"batb":[[2,1.64,56.04]],"ltp":1.75,"tv":4.53,"id":2309796}]}]}
{"op":"mcm","clk":"1003987830","pt":1580617660477,"mc":[{"id":"1.168219387","rc":[{"batb":[[2,1.67,56.04]],"ltp":1.75,"tv":4.53,"id":2309796}]}]}
{"op":"mcm","clk":"1004037077","pt":1580618710515,"mc":[{"id":"1.168219387","rc":[{"batb":[[0,1.73,86.41]],"ltp":1.75,"tv":4.53,"id":2309796}]}]}
{"op":"mcm","clk":"1004074931","pt":1580619686221,"mc":[{"id":"1.168219387","rc":[{"batb":[[0,1.73,476.8]],"ltp":1.75,"tv":4.53,"id":2309796}]}]}
{"op":"mcm","clk":"1004101861","pt":1580620389997,"mc":[{"id":"1.168219387","rc":[{"batl":[[0,4.2,153.72],[1,16,3.36],[2,95,15.9]],"ltp":2.2,"tv":50.41,"id":8535963}]}]}
{"op":"mcm","clk":"1004102461","pt":1580620406431,"mc":[{"id":"1.168219387","rc":[{"batl":[[1,95,15.9],[2,990,2.2]],"ltp":2.2,"tv":50.41,"id":8535963}]}]}
{"op":"mcm","clk":"1004112303","pt":1580620627736,"mc":[{"id":"1.168219387","rc":[{"batb":[[2,1.64,56.04]],"ltp":1.75,"tv":4.53,"id":2309796}]}]}
{"op":"mcm","clk":"1004114000","pt":1580620662710,"mc":[{"id":"1.168219387","rc":[{"batb":[[2,1.61,37.86]],"ltp":1.75,"tv":4.53,"id":2309796}]}]}
{"op":"mcm","clk":"1004114008","pt":1580620662813,"mc":[{"id":"1.168219387","rc":[{"batb":[[2,1.67,56.04]],"ltp":1.75,"tv":4.53,"id":2309796}]}]}
{"op":"mcm","clk":"1004158638","pt":1580621693112,"mc":[{"id":"1.168219387","rc":[{"batb":[[0,1.73,598.06]],"ltp":1.75,"tv":4.53,"id":2309796}]}]}
{"op":"mcm","clk":"1004158709","pt":1580621695386,"mc":[{"id":"1.168219387","rc":[{"batb":[[1,1.67,56.04],[2,1.61,37.86]],"ltp":1.75,"tv":4.53,"id":2309796}]}]}
{"op":"mcm","clk":"1004158730","pt":1580621696007,"mc":[{"id":"1.168219387","rc":[{"batb":[[1,1.69,343.5],[2,1.67,56.04]],"ltp":1.75,"tv":4.53,"id":2309796}]}]}
{"op":"mcm","clk":"1004210904","pt":1580623286748,"mc":[{"id":"1.168219387","rc":[{"batb":[[0,1.73,86.41]],"ltp":1.75,"tv":4.53,"id":2309796}]}]}
{"op":"mcm","clk":"1004210910","pt":1580623286956,"mc":[{"id":"1.168219387","rc":[{"batb":[[0,1.73,600.17]],"ltp":1.75,"tv":4.53,"id":2309796}]}]}
{"op":"mcm","clk":"1004218618","pt":1580623514358,"mc":[{"id":"1.168219387","rc":[{"batb":[[2,1.64,56.04]],"ltp":1.75,"tv":4.53,"id":2309796}]}]}
{"op":"mcm","clk":"1004219753","pt":1580623550515,"mc":[{"id":"1.168219387","rc":[{"batb":[[2,1.67,56.04]],"ltp":1.75,"tv":4.53,"id":2309796}]}]}
{"op":"mcm","clk":"1004281287","pt":1580625569720,"mc":[{"id":"1.168219387","rc":[{"batb":[[2,1.61,37.86]],"ltp":1.75,"tv":4.53,"id":2309796}]}]}
{"op":"mcm","clk":"1004281292","pt":1580625569821,"mc":[{"id":"1.168219387","rc":[{"batb":[[1,1.69,399.53]],"ltp":1.75,"tv":4.53,"id":2309796}]}]}
{"op":"mcm","clk":"1004288464","pt":1580625772370,"mc":[{"id":"1.168219387","rc":[{"batb":[[1,1.69,343.5],[2,1.67,56.04]],"ltp":1.75,"tv":4.53,"id":2309796}]}]}
{"op":"mcm","clk":"1004293455","pt":1580626009448,"mc":[{"id":"1.168219387","rc":[{"batl":[[0,95,15.9],[1,990,2.2],[2,1000,0.02]],"ltp":2.2,"tv":50.41,"id":8535963}]}]}
{"op":"mcm","clk":"1004294843","pt":1580626060242,"mc":[{"id":"1.168219387","rc":[{"batl":[[0,13.5,3.36],[1,95,15.9],[2,990,2.2]],"ltp":2.2,"tv":50.41,"id":8535963}]}]}
{"op":"mcm","clk":"1004301053","pt":1580626274415,"mc":[{"id":"1.168219387","rc":[{"batl":[[0,4.2,153.72],[1,13.5,3.36],[2,95,15.9]],"ltp":2.2,"tv":50.41,"id":8535963}]}]}
{"op":"mcm","clk":"1004301363","pt":1580626287033,"mc":[{"id":"1.168219387","rc":[{"batl":[[1,95,15.9],[2,990,2.2]],"ltp":2.2,"tv":50.41,"id":8535963}]}]}
{"op":"mcm","clk":"1004321935","pt":1580626887030,"mc":[{"id":"1.168219387","rc":[{"batb":[[0,1.73,86.41]],"ltp":1.75,"tv":4.53,"id":2309796}]}]}
{"op":"mcm","clk":"1004324205","pt":1580626980442,"mc":[{"id":"1.168219387","rc":[{"batb":[[0,1.73,602.54],[1,1.67,56.04],[2,1.61,37.86]],"ltp":1.75,"tv":4.53,"id":2309796}]}]}
{"op":"mcm","clk":"1004324218","pt":1580626981156,"mc":[{"id":"1.168219387","rc":[{"batb":[[2,1.98,288.04]],"ltp":2.2,"tv":50.41,"id":8535963},{"batb":[[1,1.69,343.5],[2,1.67,56.04]],"ltp":1.75,"tv":4.53,"id":2309796}]}]}
{"op":"mcm","clk":"1004324457","pt":1580626989557,"mc":[{"id":"1.168219387","rc":[{"batb":[[1,1.69,399.53],[2,1.61,37.86]],"ltp":1.75,"tv":4.53,"id":2309796}]}]}
{"op":"mcm","clk":"1004394196","pt":1580628779971,"mc":[{"id":"1.168219387","rc":[{"batb":[[0,2.2,32.05]],"ltp":2.2,"tv":50.41,"id":8535963}]}]}
{"op":"mcm","clk":"1004394253","pt":1580628781059,"mc":[{"id":"1.168219387","rc":[{"batb":[[1,1.69,343.5],[2,1.64,56.04]],"ltp":1.75,"tv":4.53,"id":2309796}]}]}
{"op":"mcm","clk":"1004396012","pt":1580628825367,"mc":[{"id":"1.168219387","rc":[{"batb":[[1,1.69,399.53],[2,1.61,37.86]],"ltp":1.75,"tv":4.53,"id":2309796}]}]}
{"op":"mcm","clk":"1004405313","pt":1580629079652,"mc":[{"id":"1.168219387","rc":[{"batb":[[0,1.73,602.65]],"ltp":1.75,"tv":4.53,"id":2309796}]}]}
{"op":"mcm","clk":"1004416051","pt":1580629334913,"mc":[{"id":"1.168219387","rc":[{"batb":[[0,1.73,601.63]],"ltp":1.75,"tv":4.53,"id":2309796}]}]}
{"op":"mcm","clk":"1004423388","pt":1580629519291,"mc":[{"id":"1.168219387","rc":[{"batb":[[0,2.2,34.07]],"ltp":2.2,"tv":50.41,"id":8535963},{"batb":[[0,1.73,600.62]],"ltp":1.75,"tv":4.53,"id":2309796}]}]}
{"op":"mcm","clk":"1004425837","pt":1580629573962,"mc":[{"id":"1.168219387","rc":[{"batb":[[0,1.73,599.6]],"ltp":1.75,"tv":4.53,"id":2309796}]}]}
{"op":"mcm","clk":"1004428282","pt":1580629628033,"mc":[{"id":"1.168219387","rc":[{"batb":[[0,1.73,598.58]],"ltp":1.75,"tv":4.53,"id":2309796}]}]}
{"op":"mcm","clk":"1004445896","pt":1580630028656,"mc":[{"id":"1.168219387","rc":[{"batb":[[0,2.2,36.48]],"ltp":2.2,"tv":50.41,"id":8535963},{"batb":[[0,1.73,597.57]],"ltp":1.75,"tv":4.53,"id":2309796}]}]}
{"op":"mcm","clk":"1004448142","pt":1580630081138,"mc":[{"id":"1.168219387","rc":[{"batb":[[0,1.73,596.55]],"ltp":1.75,"tv":4.53,"id":2309796}]}]}
{"op":"mcm","clk":"1004466324","pt":1580630453932,"mc":[{"id":"1.168219387","rc":[{"batb":[[1,1.69,381.36]],"ltp":1.75,"tv":4.53,"id":2309796}]}]}
{"op":"mcm","clk":"1004472222","pt":1580630580503,"mc":[{"id":"1.168219387","rc":[{"batb":[[0,1.73,80.42]],"ltp":1.75,"tv":4.53,"id":2309796}]}]}
{"op":"mcm","clk":"1004473649","pt":1580630616732,"mc":[{"id":"1.168219387","rc":[{"batb":[[0,1.73,596.55]],"ltp":1.75,"tv":4.53,"id":2309796}]}]}
{"op":"mcm","clk":"1004474526","pt":1580630637356,"mc":[{"id":"1.168219387","rc":[{"batb":[[1,1.69,397.26]],"ltp":1.75,"tv":4.53,"id":2309796}]}]}
{"op":"mcm","clk":"1004546829","pt":1580632284383,"mc":[{"id":"1.168219387","rc":[{"batb":[[0,1.73,80.42]],"ltp":1.75,"tv":4.53,"id":2309796}]}]}
{"op":"mcm","clk":"1004546937","pt":1580632286495,"mc":[{"id":"1.168219387","rc":[{"batb":[[1,2,274.88],[2,1.98,46.19]],"ltp":2.2,"tv":50.41,"id":8535963},{"batb":[[1,1.69,53.76],[2,1.67,353.75]],"ltp":1.75,"tv":4.53,"id":2309796}]}]}
{"op":"mcm","clk":"1004547105","pt":1580632289800,"mc":[{"id":"1.168219387","rc":[{"batb":[[1,1.67,353.75],[2,1.61,37.86]],"ltp":1.75,"tv":4.53,"id":2309796}]}]}
{"op":"mcm","clk":"1004547655","pt":1580632302323,"mc":[{"id":"1.168219387","rc":[{"batb":[[0,1.72,94.11]],"ltp":1.75,"tv":4.53,"id":2309796}]}]}
{"op":"mcm","clk":"1004578003","pt":1580632984351,"mc":[{"id":"1.168219387","rc":[{"batb":[[0,2.2,41.11]],"ltp":2.2,"tv":50.41,"id":8535963},{"trd":[[1.72,9.91],[1.74,0.23]],"batb":[[0,1.72,89.04]],"ltp":1.72,"tv":14.67,"id":2309796}],"tv":65.08}]}
{"op":"mcm","clk":"1004621942","pt":1580633923191,"mc":[{"id":"1.168219387","rc":[{"trd":[[1.75,5.04],[1.78,4.56]],"batl":[[0,1.84,420.1]],"ltp":1.78,"tv":19.73,"id":2309796}],"tv":70.15}]}
{"op":"mcm","clk":"1004631327","pt":1580634077357,"mc":[{"id":"1.168219387","rc":[{"batb":[[1,2,321.07],[2,1.81,37.86]],"ltp":2.2,"tv":50.41,"id":8535963}]}]}
{"op":"mcm","clk":"1004632852","pt":1580634103782,"mc":[{"id":"1.168219387","rc":[{"batb":[[1,1.67,408.27]],"ltp":1.78,"tv":19.73,"id":2309796}]}]}
{"op":"mcm","clk":"1004651999","pt":1580634508938,"mc":[{"id":"1.168219387","rc":[{"batl":[[0,1.83,2.27],[1,1.84,420.1],[2,1.85,420.1]],"ltp":1.78,"tv":19.73,"id":2309796}]}]}
{"op":"mcm","clk":"1004691405","pt":1580635306370,"mc":[{"id":"1.168219387","rc":[{"trd":[[1.72,49.91]],"batb":[[0,1.72,69.04]],"ltp":1.72,"tv":59.73,"id":2309796}],"tv":110.14}]}
{"op":"mcm","clk":"1004691535","pt":1580635308471,"mc":[{"id":"1.168219387","rc":[{"batb":[[0,2.2,56.46]],"ltp":2.2,"tv":50.41,"id":8535963},{"batb":[[0,1.7,97.66]],"ltp":1.72,"tv":59.73,"id":2309796}]}]}
{"op":"mcm","clk":"1004692369","pt":1580635326180,"mc":[{"id":"1.168219387","rc":[{"batb":[[0,1.72,7.57],[1,1.7,97.66],[2,1.67,408.27]],"ltp":1.72,"tv":59.73,"id":2309796}]}]}
{"op":"mcm","clk":"1004696179","pt":1580635431322,"mc":[{"id":"1.168219387","rc":[{"batb":[[0,1.73,55.86],[1,1.72,7.57]],"ltp":1.72,"tv":59.73,"id":2309796}]}]}
{"op":"mcm","clk":"1004704063","pt":1580635607319,"mc":[{"id":"1.168219387","marketDefinition":{"bspMarket":false,"turnInPlayEnabled":true,"persistenceEnabled":true,"marketBaseRate":5.0,"eventId":"29681328","eventTypeId":"2","numberOfWinners":1,"bettingType":"ODDS","marketType":"MATCH_ODDS","marketTime":"2020-02-02T11:23:00.000Z","suspendTime":"2020-02-02T11:23:00.000Z","bspReconciled":false,"complete":true,"inPlay":false,"crossMatching":true,"runnersVoidable":false,"numberOfActiveRunners":2,"betDelay":0,"status":"OPEN","runners":[{"status":"ACTIVE","sortPriority":1,"id":8535963,"name":"Nikola Milojevic"},{"status":"ACTIVE","sortPriority":2,"id":2309796,"name":"Robin Haase"}],"regulators":["MR_INT"],"countryCode":"IN","discountAllowed":true,"timezone":"UTC","openDate":"2020-02-02T11:30:00.000Z","version":3148345181,"name":"Match Odds","eventName":"Milojevic v Haase"}}]}
{"op":"mcm","clk":"1004704272","pt":1580635610363,"mc":[{"id":"1.168219387","marketDefinition":{"bspMarket":false,"turnInPlayEnabled":true,"persistenceEnabled":true,"marketBaseRate":5.0,"eventId":"29681328","eventTypeId":"2","numberOfWinners":1,"bettingType":"ODDS","marketType":"MATCH_ODDS","marketTime":"2020-02-02T11:23:00.000Z","suspendTime":"2020-02-02T11:23:00.000Z","bspReconciled":false,"complete":true,"inPlay":false,"crossMatching":true,"runnersVoidable":false,"numberOfActiveRunners":2,"betDelay":0,"status":"OPEN","runners":[{"status":"ACTIVE","sortPriority":1,"id":8535963,"name":"Nikola Milojevic"},{"status":"ACTIVE","sortPriority":2,"id":2309796,"name":"Robin Haase"}],"regulators":["MR_INT"],"countryCode":"IN","discountAllowed":true,"timezone":"UTC","openDate":"2020-02-02T11:23:00.000Z","version":3148345181,"name":"Match Odds","eventName":"Milojevic v Haase"}}]}
{"op":"mcm","clk":"1004706087","pt":1580635651969,"mc":[{"id":"1.168219387","rc":[{"batb":[[1,2,274.88]],"ltp":2.2,"tv":50.41,"id":8535963},{"batb":[[2,1.67,353.75]],"ltp":1.72,"tv":59.73,"id":2309796}]}]}
{"op":"mcm","clk":"1004712133","pt":1580635803042,"mc":[{"id":"1.168219387","rc":[{"batb":[[1,1.67,353.75],[2,1.61,37.86]],"ltp":1.72,"tv":59.73,"id":2309796}]}]}
{"op":"mcm","clk":"1004713239","pt":1580635829962,"mc":[{"id":"1.168219387","rc":[{"batb":[[0,2.2,112.81]],"ltp":2.2,"tv":50.41,"id":8535963},{"batb":[[0,1.7,195.32]],"ltp":1.72,"tv":59.73,"id":2309796}]}]}
{"op":"mcm","clk":"1004713396","pt":1580635833211,"mc":[{"id":"1.168219387","rc":[{"batb":[[0,1.72,7.57],[1,1.71,526.57],[2,1.7,195.32]],"ltp":1.72,"tv":59.73,"id":2309796}]}]}
{"op":"mcm","clk":"1004713772","pt":1580635842727,"mc":[{"id":"1.168219387","rc":[{"batb":[[0,1.7,195.32],[1,1.67,353.75],[2,1.61,37.86]],"ltp":1.72,"tv":59.73,"id":2309796}]}]}
{"op":"mcm","clk":"1004713784","pt":1580635843027,"mc":[{"id":"1.168219387","rc":[{"batb":[[0,1.71,526.57],[1,1.7,195.32],[2,1.67,353.75]],"ltp":1.72,"tv":59.73,"id":2309796}]}]}
{"op":"mcm","clk":"1004714069","pt":1580635850500,"mc":[{"id":"1.168219387","rc":[{"batb":[[0,1.72,7.57],[1,1.71,526.57],[2,1.7,195.32]],"ltp":1.72,"tv":59.73,"id":2309796}]}]}
{"op":"mcm","clk":"1004718559","pt":1580635957082,"mc":[{"id":"1.168219387","rc":[{"batb":[[1,1.7,195.32],[2,1.67,353.75]],"ltp":1.72,"tv":59.73,"id":2309796}]}]}
{"op":"mcm","clk":"1004718915","pt":1580635964673,"mc":[{"id":"1.168219387","rc":[{"batb":[[0,1.73,111.73],[1,1.72,7.57]],"ltp":1.72,"tv":59.73,"id":2309796}]}]}
{"op":"mcm","clk":"1004719012","pt":1580635967182,"mc":[{"id":"1.168219387","rc":[{"batb":[[0,1.74,7.57],[1,1.73,111.73],[2,1.72,7.57]],"ltp":1.72,"tv":59.73,"id":2309796}]}]}
{"op":"mcm","clk":"1004735913","pt":1580636363999,"mc":[{"id":"1.168219387","rc":[{"batb":[[0,1.73,111.73],[1,1.72,7.57],[2,1.67,353.75]],"ltp":1.72,"tv":59.73,"id":2309796}]}]}
{"op":"mcm","clk":"1004749240","pt":1580636612554,"mc":[{"id":"1.168219387","rc":[{"batl":[[0,1.83,422.37]],"ltp":1.72,"tv":59.73,"id":2309796}]}]}
{"op":"mcm","clk":"1004749435","pt":1580636616570,"mc":[{"id":"1.168219387","rc":[{"batl":[[0,1.82,420.1],[1,1.83,422.37],[2,1.84,420.1]],"ltp":1.72,"tv":59.73,"id":2309796}]}]}
{"op":"mcm","clk":"1004756105","pt":1580636769469,"mc":[{"id":"1.168219387","rc":[{"batl":[[0,3.75,153.72]],"ltp":2.2,"tv":50.41,"id":8535963}]}]}
{"op":"mcm","clk":"1004761466","pt":1580636883004,"mc":[{"id":"1.168219387","rc":[{"batl":[[0,1.81,2.27],[1,1.82,420.1],[2,1.83,420.1]],"ltp":1.72,"tv":59.73,"id":2309796}]}]}
{"op":"mcm","clk":"1004764802","pt":1580636947507,"mc":[{"id":"1.168219387","rc":[{"batb":[[0,1.74,7.57],[1,1.73,111.73],[2,1.72,7.57]],"ltp":1.72,"tv":59.73,"id":2309796}]}]}
{"op":"mcm","clk":"1004764924","pt":1580636949017,"mc":[{"id":"1.168219387","rc":[{"batb":[[2,1.67,353.75]],"ltp":1.72,"tv":59.73,"id":2309796}]}]}
{"op":"mcm","clk":"1004765022","pt":1580636950352,"mc":[{"id":"1.168219387","rc":[{"batl":[[0,1.8,7.57],[1,1.81,2.27],[2,1.82,420.1]],"ltp":1.72,"tv":59.73,"id":2309796}]}]}
{"op":"mcm","clk":"1004765132","pt":1580636952102,"mc":[{"id":"1.168219387","rc":[{"batl":[[0,1.81,2.27],[1,1.82,420.1],[2,1.83,420.1]],"ltp":1.72,"tv":59.73,"id":2309796}]}]}
{"op":"mcm","clk":"1004768385","pt":1580637008698,"mc":[{"id":"1.168219387","rc":[{"batb":[[1,1.7,195.32]],"ltp":1.72,"tv":59.73,"id":2309796}]}]}
{"op":"mcm","clk":"1004771097","pt":1580637054564,"mc":[{"id":"1.168219387","rc":[{"batb":[[0,1.72,7.57],[1,1.71,526.57],[2,1.7,195.32]],"ltp":1.72,"tv":59.73,"id":2309796}]}]}
{"op":"mcm","clk":"1004771628","pt":1580637066399,"mc":[{"id":"1.168219387","rc":[{"batb":[[1,1.7,195.32],[2,1.67,353.75]],"ltp":1.72,"tv":59.73,"id":2309796}]}]}
{"op":"mcm","clk":"1004775317","pt":1580637138319,"mc":[{"id":"1.168219387","rc":[{"batb":[[0,1.73,111.73],[1,1.72,7.57]],"ltp":1.72,"tv":59.73,"id":2309796}]}]}
{"op":"mcm","clk":"1004782524","pt":1580637277253,"mc":[{"id":"1.168219387","rc":[{"batl":[[0,1.81,9.84]],"ltp":1.72,"tv":59.73,"id":2309796}]}]}
{"op":"mcm","clk":"1004782674","pt":1580637280694,"mc":[{"id":"1.168219387","rc":[{"batb":[[1,1.67,353.75],[2,1.61,37.86]],"batl":[[0,1.81,2.27]],"ltp":1.72,"tv":59.73,"id":2309796}]}]}
{"op":"mcm","clk":"1004788992","pt":1580637398645,"mc":[{"id":"1.168219387","rc":[{"batb":[[0,1.7,195.32]],"ltp":1.72,"tv":59.73,"id":2309796}]}]}
{"op":"mcm","clk":"1004789007","pt":1580637398854,"mc":[{"id":"1.168219387","rc":[{"batb":[[1,1.69,532.92],[2,1.67,353.75]],"ltp":1.72,"tv":59.73,"id":2309796}]}]}
{"op":"mcm","clk":"1004791082","pt":1580637429375,"mc":[{"id":"1.168219387","rc":[{"batb":[[0,1.71,526.57],[1,1.7,195.32]],"ltp":1.72,"tv":59.73,"id":2309796}]}]}
{"op":"mcm","clk":"1004796515","pt":1580637528423,"mc":[{"id":"1.168219387","rc":[{"batb":[[0,1.72,138.97],[1,1.71,526.57]],"ltp":1.72,"tv":59.73,"id":2309796}]}]}
{"op":"mcm","clk":"1004805001","pt":1580637656672,"mc":[{"id":"1.168219387","rc":[{"batb":[[1,1.67,353.75],[2,1.61,37.86]],"ltp":1.72,"tv":59.73,"id":2309796}]}]}
{"op":"mcm","clk":"1004814957","pt":1580637786227,"mc":[{"id":"1.168219387","rc":[{"batb":[[0,1.7,195.32],[1,1.69,532.92],[2,1.67,353.75]],"ltp":1.72,"tv":59.73,"id":2309796}]}]}
{"op":"mcm","clk":"1004815243","pt":1580637790300,"mc":[{"id":"1.168219387","rc":[{"batb":[[0,1.72,7.57],[1,1.7,195.32]],"ltp":1.72,"tv":59.73,"id":2309796}]}]}
{"op":"mcm","clk":"1004816898","pt":1580637814249,"mc":[{"id":"1.168219387","rc":[{"batb":[[0,1.72,15.14]],"ltp":1.72,"tv":59.73,"id":2309796}]}]}
{"op":"mcm","clk":"1004823549","pt":1580637917707,"mc":[{"id":"1.168219387","rc":[{"batb":[[1,1.67,353.75],[2,1.61,37.86]],"ltp":1.72,"tv":59.73,"id":2309796}]}]}
{"op":"mcm","clk":"1004823555","pt":1580637917806,"mc":[{"id":"1.168219387","rc":[{"batb":[[0,1.73,111.73],[1,1.72,15.14],[2,1.67,353.75]],"ltp":1.72,"tv":59.73,"id":2309796}]}]}
{"op":"mcm","clk":"1004825611","pt":1580637950913,"mc":[{"id":"1.168219387","rc":[{"batb":[[1,1.67,353.75],[2,1.61,37.86]],"ltp":1.72,"tv":59.73,"id":2309796}]}]}
{"op":"mcm","clk":"1004832065","pt":1580638051316,"mc":[{"id":"1.168219387","rc":[{"batb":[[0,1.7,724.84]],"ltp":1.72,"tv":59.73,"id":2309796}]}]}
{"op":"mcm","clk":"1004853982","pt":1580638355306,"mc":[{"id":"1.168219387","rc":[{"batb":[[0,1.72,7.57],[1,1.7,724.84],[2,1.67,353.75]],"ltp":1.72,"tv":59.73,"id":2309796}]}]}
{"op":"mcm","clk":"1004860314","pt":1580638440651,"mc":[{"id":"1.168219387","rc":[{"batb":[[0,1.73,111.73],[1,1.72,7.57],[2,1.7,529.52]],"ltp":1.72,"tv":59.73,"id":2309796}]}]}
{"op":"mcm","clk":"1004860333","pt":1580638440858,"mc":[{"id":"1.168219387","rc":[{"batb":[[2,1.67,353.75]],"ltp":1.72,"tv":59.73,"id":2309796}]}]}
{"op":"mcm","clk":"1004870854","pt":1580638568002,"mc":[{"id":"1.168219387","rc":[{"trd":[[1.81,4.54],[1.82,154.48]],"batl":[[0,1.82,342.86],[1,1.83,420.1],[2,1.84,420.1]],"ltp":1.82,"tv":218.75,"id":2309796}],"tv":269.16}]}
{"op":"mcm","clk":"1004904475","pt":1580638982798,"mc":[{"id":"1.168219387","rc":[{"batb":[[1,2,37.86]],"ltp":2.2,"tv":50.41,"id":8535963},{"batb":[[2,1.61,37.86]],"ltp":1.82,"tv":218.75,"id":2309796}]}]}
{"op":"mcm","clk":"1004904675","pt":1580638985258,"mc":[{"id":"1.168219387","rc":[{"batb":[[1,2.18,21.36],[2,2,37.86]],"ltp":2.2,"tv":50.41,"id":8535963},{"batb":[[2,1.71,35.5]],"ltp":1.82,"tv":218.75,"id":2309796}]}]}
{"op":"mcm","clk":"1004949120","pt":1580639405171,"mc":[{"id":"1.168219387","rc":[{"batb":[[0,1.73,118.58]],"ltp":1.82,"tv":218.75,"id":2309796}]}]}
{"op":"mcm","clk":"1004957186","pt":1580639485229,"mc":[{"id":"1.168219387","rc":[{"batb":[[0,1.74,7.57],[1,1.73,118.58],[2,1.72,7.57]],"ltp":1.82,"tv":218.75,"id":2309796}]}]}
{"op":"mcm","clk":"1004957330","pt":1580639486736,"mc":[{"id":"1.168219387","rc":[{"batb":[[2,1.71,35.5]],"ltp":1.82,"tv":218.75,"id":2309796}]}]}
{"op":"mcm","clk":"1005037074","pt":1580640261598,"mc":[{"id":"1.168219387","rc":[{"batb":[[0,1.73,118.58],[1,1.71,35.5],[2,1.61,37.86]],"ltp":1.82,"tv":218.75,"id":2309796}]}]}
{"op":"mcm","clk":"1005053389","pt":1580640381602,"mc":[{"id":"1.168219387","rc":[{"batb":[[1,2.18,87.57],[2,2.16,21.73]],"ltp":2.2,"tv":50.41,"id":8535963},{"batb":[[0,1.75,87.42],[1,1.73,118.58],[2,1.72,35.01]],"ltp":1.82,"tv":218.75,"id":2309796}]}]}
{"op":"mcm","clk":"1005056582","pt":1580640406412,"mc":[{"id":"1.168219387","marketDefinition":{"bspMarket":false,"turnInPlayEnabled":true,"persistenceEnabled":true,"marketBaseRate":5.0,"eventId":"29681328","eventTypeId":"2","numberOfWinners":1,"bettingType":"ODDS","marketType":"MATCH_ODDS","marketTime":"2020-02-02T10:45:00.000Z","suspendTime":"2020-02-02T10:45:00.000Z","bspReconciled":false,"complete":true,"inPlay":false,"crossMatching":true,"runnersVoidable":false,"numberOfActiveRunners":2,"betDelay":0,"status":"OPEN","runners":[{"status":"ACTIVE","sortPriority":1,"id":8535963,"name":"Nikola Milojevic"},{"status":"ACTIVE","sortPriority":2,"id":2309796,"name":"Robin Haase"}],"regulators":["MR_INT"],"countryCode":"IN","discountAllowed":true,"timezone":"UTC","openDate":"2020-02-02T11:23:00.000Z","version":3148437217,"name":"Match Odds","eventName":"Milojevic v Haase"}}]}
{"op":"mcm","clk":"1005058517","pt":1580640420442,"mc":[{"id":"1.168219387","marketDefinition":{"bspMarket":false,"turnInPlayEnabled":true,"persistenceEnabled":true,"marketBaseRate":5.0,"eventId":"29681328","eventTypeId":"2","numberOfWinners":1,"bettingType":"ODDS","marketType":"MATCH_ODDS","marketTime":"2020-02-02T10:45:00.000Z","suspendTime":"2020-02-02T10:45:00.000Z","bspReconciled":false,"complete":true,"inPlay":false,"crossMatching":true,"runnersVoidable":false,"numberOfActiveRunners":2,"betDelay":0,"status":"OPEN","runners":[{"status":"ACTIVE","sortPriority":1,"id":8535963,"name":"Nikola Milojevic"},{"status":"ACTIVE","sortPriority":2,"id":2309796,"name":"Robin Haase"}],"regulators":["MR_INT"],"countryCode":"IN","discountAllowed":true,"timezone":"UTC","openDate":"2020-02-02T10:45:00.000Z","version":3148437217,"name":"Match Odds","eventName":"Milojevic v Haase"}}]}
{"op":"mcm","clk":"1005068112","pt":1580640499558,"mc":[{"id":"1.168219387","rc":[{"trd":[[1.82,196.49]],"batl":[[0,1.82,321.85]],"ltp":1.82,"tv":260.76,"id":2309796}],"tv":311.17}]}
{"op":"mcm","clk":"1005078818","pt":1580640584492,"mc":[{"id":"1.168219387","rc":[{"batb":[[1,1.73,118.26]],"ltp":1.82,"tv":260.76,"id":2309796}]}]}
{"op":"mcm","clk":"1005078888","pt":1580640585070,"mc":[{"id":"1.168219387","rc":[{"batb":[[1,2.18,87.18]],"ltp":2.2,"tv":50.41,"id":8535963}]}]}
{"op":"mcm","clk":"1005094206","pt":1580640705750,"mc":[{"id":"1.168219387","rc":[{"batb":[[0,2.2,199.83]],"ltp":2.2,"tv":50.41,"id":8535963},{"trd":[[1.75,21.23]],"batb":[[0,1.75,79.32]],"ltp":1.75,"tv":276.95,"id":2309796}],"tv":327.36}]}
{"op":"mcm","clk":"1005094229","pt":1580640705960,"mc":[{"id":"1.168219387","rc":[{"batb":[[1,2.16,21.73],[2,2,37.86]],"ltp":2.2,"tv":50.41,"id":8535963}]}]}
{"op":"mcm","clk":"1005106695","pt":1580640813138,"mc":[{"id":"1.168219387","rc":[{"batb":[[2,2.14,36.13]],"batl":[[0,2.4,29.41],[1,3.75,153.72],[2,95,15.9]],"ltp":2.2,"tv":50.41,"id":8535963},{"batb":[[2,1.72,92.98]],"ltp":1.75,"tv":276.95,"id":2309796}]}]}
{"op":"mcm","clk":"1005109905","pt":1580640839258,"mc":[{"id":"1.168219387","rc":[{"batl":[[0,2.32,39.86],[1,2.4,29.41],[2,3.75,153.72]],"ltp":2.2,"tv":50.41,"id":8535963}]}]}
{"op":"mcm","clk":"1005111978","pt":1580640856997,"mc":[{"id":"1.168219387","rc":[{"trd":[[1.75,21.26]],"batb":[[0,1.75,79.31]],"ltp":1.75,"tv":276.98,"id":2309796}],"tv":327.39}]}
{"op":"mcm","clk":"1005118551","pt":1580640910729,"mc":[{"id":"1.168219387","rc":[{"batl":[[0,2.3,39.86]],"ltp":2.2,"tv":50.41,"id":8535963},{"batb":[[1,1.73,152.79]],"ltp":1.75,"tv":276.98,"id":2309796}]}]}
{"op":"mcm","clk":"1005118663","pt":1580640911552,"mc":[{"id":"1.168219387","rc":[{"batl":[[0,1.79,20],[1,1.82,321.85],[2,1.83,420.1]],"ltp":1.75,"tv":276.98,"id":2309796}]}]}
{"op":"mcm","clk":"1005118694","pt":1580640911767,"mc":[{"id":"1.168219387","rc":[{"batb":[[1,2.18,21.36],[2,2.16,21.73]],"ltp":2.2,"tv":50.41,"id":8535963},{"batb":[[1,1.73,118.26],[2,1.72,57.97]],"ltp":1.75,"tv":276.98,"id":2309796}]}]}
{"op":"mcm","clk":"1005119152","pt":1580640915559,"mc":[{"id":"1.168219387","rc":[{"batb":[[0,1.75,79.32]],"ltp":1.75,"tv":276.98,"id":2309796}]}]}
{"op":"mcm","clk":"1005121109","pt":1580640931363,"mc":[{"id":"1.168219387","rc":[{"batl":[[0,1.82,321.85],[1,1.83,420.1],[2,1.84,420.1]],"ltp":1.75,"tv":276.98,"id":2309796}]}]}
{"op":"mcm","clk":"1005121161","pt":1580640931778,"mc":[{"id":"1.168219387","rc":[{"batb":[[1,2.16,21.73],[2,2.14,36.13]],"ltp":2.2,"tv":50.41,"id":8535963},{"batb":[[1,1.73,152.79]],"ltp":1.75,"tv":276.98,"id":2309796}]}]}
{"op":"mcm","clk":"1005123029","pt":1580640947311,"mc":[{"id":"1.168219387","rc":[{"batl":[[0,2.28,39.86]],"ltp":2.2,"tv":50.41,"id":8535963}]}]}
{"op":"mcm","clk":"1005123076","pt":1580640947790,"mc":[{"id":"1.168219387","rc":[{"batb":[[1,2.14,58.24],[2,2,37.86]],"ltp":2.2,"tv":50.41,"id":8535963},{"batb":[[1,1.74,34.06],[2,1.73,152.79]],"ltp":1.75,"tv":276.98,"id":2309796}]}]}
{"op":"mcm","clk":"1005132811","pt":1580641025770,"mc":[{"id":"1.168219387","rc":[{"trd":[[2.28,19.79]],"batl":[[0,2.28,20.06]],"ltp":2.28,"tv":70.2,"id":8535963},{"trd":[[1.78,29.89]],"ltp":1.78,"tv":302.31,"id":2309796}],"tv":372.51}]}
{"op":"mcm","clk":"1005133174","pt":1580641027860,"mc":[{"id":"1.168219387","rc":[{"trd":[[2.2,590.22],[2.22,0.24]],"batb":[[0,2.14,58.24],[1,2,37.86],[2,1.84,216.74]],"ltp":2.2,"tv":610.25,"id":8535963},{"trd":[[1.82,366.17]],"batl":[[0,1.82,152.17]],"ltp":1.82,"tv":471.99,"id":2309796}],"tv":1082.25}]}
{"op":"mcm","clk":"1005133290","pt":1580641028951,"mc":[{"id":"1.168219387","rc":[{"batb":[[0,2.2,31.4],[1,2.14,58.24],[2,2,37.86]],"ltp":2.2,"tv":610.25,"id":8535963},{"batb":[[0,1.79,61.33],[1,1.75,79.32],[2,1.74,34.06]],"ltp":1.82,"tv":471.99,"id":2309796}]}]}
{"op":"mcm","clk":"1005133660","pt":1580641032176,"mc":[{"id":"1.168219387","rc":[{"trd":[[1.79,1]],"batb":[[0,1.79,60.83]],"ltp":1.79,"tv":473.0,"id":2309796}],"tv":1083.25}]}
{"op":"mcm","clk":"1005134252","pt":1580641036391,"mc":[{"id":"1.168219387","rc":[{"batb":[[1,2.16,89.38],[2,2.14,58.24]],"ltp":2.2,"tv":610.25,"id":8535963},{"batb":[[0,1.79,146.59],[1,1.74,34.08],[2,1.73,41.38]],"ltp":1.79,"tv":473.0,"id":2309796}]}]}
{"op":"mcm","clk":"1005135944","pt":1580641048661,"mc":[{"id":"1.168219387","rc":[{"trd":[[2.2,667.07]],"batb":[[0,2.16,89.38],[1,2.14,58.24],[2,2,37.86]],"ltp":2.2,"tv":687.1,"id":8535963},{"trd":[[1.82,441.45]],"batl":[[0,1.82,106.04]],"ltp":1.82,"tv":548.27,"id":2309796}],"tv":1235.37}]}
{"op":"mcm","clk":"1005136004","pt":1580641049077,"mc":[{"id":"1.168219387","rc":[{"batb":[[0,2.18,50.52],[1,2.16,89.38],[2,2.14,58.24]],"ltp":2.2,"tv":687.1,"id":8535963},{"batb":[[0,1.8,8.89],[1,1.79,146.59],[2,1.74,34.08]],"ltp":1.82,"tv":548.27,"id":2309796}]}]}
{"op":"mcm","clk":"1005136146","pt":1580641050169,"mc":[{"id":"1.168219387","rc":[{"batb":[[2,1.75,5.33]],"ltp":1.82,"tv":548.27,"id":2309796}]}]}
{"op":"mcm","clk":"1005137469","pt":1580641060220,"mc":[{"id":"1.168219387","rc":[{"batb":[[1,2.14,58.24],[2,2,37.86]],"ltp":2.2,"tv":687.1,"id":8535963},{"batb":[[1,1.79,60.83],[2,1.74,34.08]],"ltp":1.82,"tv":548.27,"id":2309796}]}]}
{"op":"mcm","clk":"1005137575","pt":1580641060914,"mc":[{"id":"1.168219387","marketDefinition":{"bspMarket":false,"turnInPlayEnabled":true,"persistenceEnabled":true,"marketBaseRate":5.0,"eventId":"29681328","eventTypeId":"2","numberOfWinners":1,"bettingType":"ODDS","marketType":"MATCH_ODDS","marketTime":"2020-02-02T10:45:00.000Z","suspendTime":"2020-02-02T10:45:00.000Z","bspReconciled":false,"complete":true,"inPlay":true,"crossMatching":true,"runnersVoidable":false,"numberOfActiveRunners":2,"betDelay":3,"status":"OPEN","runners":[{"status":"ACTIVE","sortPriority":1,"id":8535963,"name":"Nikola Milojevic"},{"status":"ACTIVE","sortPriority":2,"id":2309796,"name":"Robin Haase"}],"regulators":["MR_INT"],"countryCode":"IN","discountAllowed":true,"timezone":"UTC","openDate":"2020-02-02T10:45:00.000Z","version":3148446476,"name":"Match Odds","eventName":"Milojevic v Haase"},"rc":[{"batb":[[0,1.11,37.97],[1,1.05,152.3],[2,1.04,169.36]],"batl":[[0,1000,0.02],[1,2.4,0],[2,3.75,0]],"ltp":2.2,"tv":687.1,"id":8535963},{"batb":[[0,1.11,37.99],[1,1.05,152.3],[2,1.04,169.36]],"batl":[[0,3,42.01],[1,10,2.53],[2,1000,0.02]],"ltp":1.82,"tv":548.27,"id":2309796}]}]}
{"op":"mcm","clk":"1005138000","pt":1580641064706,"mc":[{"id":"1.168219387","rc":[{"batb":[[1,1.1,568.02],[2,1.05,152.2]],"ltp":2.2,"tv":687.1,"id":8535963},{"batb":[[1,1.1,568.02],[2,1.05,152.2]],"ltp":1.82,"tv":548.27,"id":2309796}]}]}
{"op":"mcm","clk":"1005138347","pt":1580641067618,"mc":[{"id":"1.168219387","rc":[{"batb":[[0,1.2,284.07],[1,1.11,37.86],[2,1.1,568.02]],"ltp":2.2,"tv":687.1,"id":8535963}]}]}
{"op":"mcm","clk":"1005138404","pt":1580641068034,"mc":[{"id":"1.168219387","rc":[{"batb":[[0,1.2,284.09],[1,1.11,37.86],[2,1.1,568.02]],"ltp":1.82,"tv":548.27,"id":2309796}]}]}
{"op":"mcm","clk":"1005138919","pt":1580641072720,"mc":[{"id":"1.168219387","rc":[{"batb":[[0,2.4,240.13],[1,2.28,32.77],[2,1.2,284.07]],"batl":[[0,2.5,7.38],[1,2.56,333.13],[2,2.58,26.05]],"ltp":2.2,"tv":687.1,"id":8535963},{"trd":[[1.75,21.3]],"batb":[[0,1.64,65.54],[1,1.2,284.07],[2,1.11,37.86]],"batl":[[0,1.7,13.06],[1,1.71,196],[2,1.79,42.01]],"ltp":1.75,"tv":548.3,"id":2309796}],"tv":1235.41}]}
{"op":"mcm","clk":"1005139029","pt":1580641073507,"mc":[{"id":"1.168219387","rc":[{"batb":[[1,2.34,72.54],[2,2.28,32.77]],"ltp":2.2,"tv":687.1,"id":8535963},{"batb":[[0,1.69,103.7],[1,1.64,65.54],[2,1.58,130.61]],"ltp":1.75,"tv":548.3,"id":2309796}]}]}
{"op":"mcm","clk":"1005140661","pt":1580641086732,"mc":[{"id":"1.168219387","rc":[{"batb":[[0,2.28,32.77],[1,2.22,84.19],[2,1.6,75.72]],"batl":[[0,2.58,26.05],[1,1000,0.02],[2,2.58,0]],"ltp":2.2,"tv":687.1,"id":8535963},{"batb":[[0,1.64,65.54],[1,1.58,130.61],[2,1.3,113.59]],"batl":[[0,1.79,42.01],[1,3,42.01],[2,10,2.53]],"ltp":1.75,"tv":548.3,"id":2309796}]}]}
{"op":"mcm","clk":"1005140772","pt":1580641087625,"mc":[{"id":"1.168219387","rc":[{"batb":[[0,2.22,84.19],[1,1.6,75.72],[2,1.5,113.58]],"batl":[[0,1000,0.02],[1,1000,0]],"ltp":2.2,"tv":687.1,"id":8535963},{"batb":[[0,1.58,130.61],[1,1.3,113.59],[2,1.25,378.62]],"batl":[[0,3,42.01],[1,10,2.53],[2,1000,0.02]],"ltp":1.75,"tv":548.3,"id":2309796}]}]}
{"op":"mcm","clk":"1005140804","pt":1580641087934,"mc":[{"id":"1.168219387","rc":[{"batb":[[1,1.7,75.72],[2,1.6,75.72]],"ltp":2.2,"tv":687.1,"id":8535963}]}]}
{"op":"mcm","clk":"1005141267","pt":1580641091332,"mc":[{"id":"1.168219387","rc":[{"batb":[[0,1.6,217.66],[1,1.59,206.66],[2,1.58,130.61]],"batl":[[0,1.83,160.99],[1,1.85,247.93],[2,3,42.01]],"ltp":1.75,"tv":548.3,"id":2309796}]}]}
{"op":"mcm","clk":"1005142102","pt":1580641098016,"mc":[{"id":"1.168219387","rc":[{"batb":[[0,1.58,130.61],[1,1.3,113.59],[2,1.25,378.62]],"ltp":1.75,"tv":548.3,"id":2309796}]}]}
{"op":"mcm","clk":"1005142438","pt":1580641100760,"mc":[{"id":"1.168219387","rc":[{"batb":[[0,2.24,326.3],[1,2.22,84.19],[2,1.7,75.72]],"batl":[[0,2.4,263.99],[1,2.44,155.9],[2,1000,0.02]],"ltp":2.2,"tv":687.1,"id":8535963},{"batb":[[0,1.74,10.88],[1,1.58,130.61],[2,1.3,113.59]],"batl":[[0,1.78,14.01],[1,1.79,198],[2,1.83,160.99]],"ltp":1.75,"tv":548.3,"id":2309796}]}]}
{"op":"mcm","clk":"1005142554","pt":1580641101647,"mc":[{"id":"1.168219387","rc":[{"batb":[[2,2.1,97.17]],"batl":[[1,2.44,150]],"ltp":2.2,"tv":687.1,"id":8535963},{"batb":[[0,1.77,282.6],[1,1.76,90.64],[2,1.75,292.96]],"ltp":1.75,"tv":548.3,"id":2309796}]}]}
{"op":"mcm","clk":"1005142678","pt":1580641102636,"mc":[{"id":"1.168219387","rc":[{"batb":[[2,2.16,36.13]],"batl":[[2,2.46,28.57]],"ltp":2.2,"tv":687.1,"id":8535963}]}]}
{"op":"mcm","clk":"1005143812","pt":1580641111264,"mc":[{"id":"1.168219387","rc":[{"trd":[[1.77,7.58]],"batb":[[0,1.77,278.81]],"ltp":1.77,"tv":555.88,"id":2309796}],"tv":1242.98}]}
{"op":"mcm","clk":"1005144510","pt":1580641116685,"mc":[{"id":"1.168219387","rc":[{"batb":[[0,2.16,36.13],[1,2.1,97.17],[2,1.7,75.72]],"batl":[[0,2.46,28.57],[1,1000,0.02],[2,2.46,0]],"ltp":2.2,"tv":687.1,"id":8535963},{"batb":[[0,1.7,59.65],[1,1.65,111.73],[2,1.3,113.59]],"batl":[[0,1.86,42.01],[1,3,42.01],[2,10,2.53]],"ltp":1.77,"tv":555.88,"id":2309796}]}]}
{"op":"mcm","clk":"1005144651","pt":1580641117731,"mc":[{"id":"1.168219387","rc":[{"trd":[[2.16,4.54]],"batb":[[0,2.1,97.17],[1,1.7,75.72],[2,1.6,75.72]],"batl":[[0,1000,0.02],[1,1000,0]],"ltp":2.16,"tv":691.64,"id":8535963},{"batb":[[0,1.65,111.73],[1,1.3,113.59],[2,1.25,378.62]],"batl":[[0,3,42.01],[1,10,2.53],[2,1000,0.02]],"ltp":1.77,"tv":555.88,"id":2309796}],"tv":1247.52}]}
{"op":"mcm","clk":"1005145009","pt":1580641120298,"mc":[{"id":"1.168219387","rc":[{"batb":[[0,1.75,246.23],[1,1.73,304.47],[2,1.65,111.73]],"batl":[[0,1.81,221.29],[1,1.83,256.45],[2,3,42.01]],"ltp":1.77,"tv":555.88,"id":2309796}]}]}
{"op":"mcm","clk":"1005145506","pt":1580641123999,"mc":[{"id":"1.168219387","rc":[{"batb":[[1,2.08,19.79],[2,1.7,75.72]],"ltp":2.16,"tv":691.64,"id":8535963},{"batb":[[0,1.65,111.73],[1,1.3,113.59],[2,1.25,378.62]],"batl":[[0,3,42.01],[1,10,2.53],[2,1000,0.02]],"ltp":1.77,"tv":555.88,"id":2309796}]}]}
{"op":"mcm","clk":"1005145677","pt":1580641125601,"mc":[{"id":"1.168219387","rc":[{"batl":[[1,7,2.27],[2,10,2.53]],"ltp":1.77,"tv":555.88,"id":2309796}]}]}
{"op":"mcm","clk":"1005145829","pt":1580641126696,"mc":[{"id":"1.168219387","rc":[{"batb":[[0,1.67,173.83],[1,1.66,176.57],[2,1.65,111.73]],"batl":[[0,1.91,203.43],[1,1.93,217.37],[2,3,42.01]],"ltp":1.77,"tv":555.88,"id":2309796}]}]}
{"op":"mcm","clk":"1005146424","pt":1580641131430,"mc":[{"id":"1.168219387","rc":[{"batb":[[0,1.65,111.73],[1,1.3,113.59],[2,1.25,378.62]],"batl":[[0,1.77,10],[1,1.91,203.43],[2,1.93,217.37]],"ltp":1.77,"tv":555.88,"id":2309796}]}]}
{"op":"mcm","clk":"1005146716","pt":1580641133719,"mc":[{"id":"1.168219387","rc":[{"trd":[[2.28,27.55]],"batl":[[0,2.24,12.71],[1,2.28,340.48],[2,2.3,141]],"ltp":2.28,"tv":699.4,"id":8535963},{"trd":[[1.77,17.58]],"batl":[[0,1.86,13.52],[1,1.87,183],[2,1.89,405.29]],"ltp":1.77,"tv":565.88,"id":2309796}],"tv":1265.28}]}
{"op":"mcm","clk":"1005146851","pt":1580641134715,"mc":[{"id":"1.168219387","rc":[{"batb":[[1,2.08,58.44],[2,1.6,75.72]],"batl":[[1,2.26,3.71],[2,2.28,340.48]],"ltp":2.28,"tv":699.4,"id":8535963},{"batb":[[0,1.84,273.19],[1,1.82,257.29],[2,1.77,9.24]],"ltp":1.77,"tv":565.88,"id":2309796}]}]}
{"op":"mcm","clk":"1005146977","pt":1580641135506,"mc":[{"id":"1.168219387","rc":[{"batb":[[2,2.02,108.82]],"batl":[[1,2.28,340.48],[2,2.3,141]],"ltp":2.28,"tv":699.4,"id":8535963},{"batb":[[1,1.83,79.39],[2,1.82,257.29]],"ltp":1.77,"tv":565.88,"id":2309796}]}]}
{"op":"mcm","clk":"1005147804","pt":1580641141646,"mc":[{"id":"1.168219387","rc":[{"trd":[[2.24,12.71],[2.28,310.35]],"batl":[[0,2.28,57.68],[1,2.3,141],[2,2.34,31.09]],"ltp":2.28,"tv":994.91,"id":8535963},{"trd":[[1.78,392.14],[1.8,15.82],[1.82,956.04],[1.83,158.78],[1.84,546.39]],"batb":[[0,1.75,55.45],[1,1.73,95.36],[2,1.55,20]],"ltp":1.78,"tv":2163.71,"id":2309796}],"tv":3158.62}]}
{"op":"mcm","clk":"1005148262","pt":1580641144656,"mc":[{"id":"1.168219387","rc":[{"batb":[[0,1.82,238.73],[1,1.8,267.22],[2,1.75,55.45]],"batl":[[2,1.89,667.72]],"ltp":1.78,"tv":2163.71,"id":2309796}]}]}
{"op":"mcm","clk":"1005149077","pt":1580641149730,"mc":[{"id":"1.168219387","rc":[{"batb":[[0,2.08,19.79],[1,2.02,108.82],[2,1.6,75.72]],"batl":[[0,1000,0.02],[1,2.3,0],[2,2.34,0]],"ltp":2.28,"tv":994.91,"id":8535963},{"batb":[[0,1.73,95.36],[1,1.55,20],[2,1.3,113.59]],"batl":[[0,3,42.01],[1,7,2.27],[2,10,2.53]],"ltp":1.78,"tv":2163.71,"id":2309796}]}]}
{"op":"mcm","clk":"1005149467","pt":1580641152707,"mc":[{"id":"1.168219387","rc":[{"batb":[[1,2.04,106.85]],"ltp":2.28,"tv":994.91,"id":8535963},{"batb":[[0,1.73,226.04],[1,1.71,317.64],[2,1.7,97.01]],"batl":[[0,1.95,223.34],[1,1.97,204.66],[2,3,42.01]],"ltp":1.78,"tv":2163.71,"id":2309796}]}]}
{"op":"mcm","clk":"1005150155","pt":1580641158225,"mc":[{"id":"1.168219387","rc":[{"batb":[[0,1.7,97.01],[1,1.55,20],[2,1.3,113.59]],"batl":[[0,3,42.01],[1,7,2.27],[2,10,2.53]],"ltp":1.78,"tv":2163.71,"id":2309796}]}]}
{"op":"mcm","clk":"1005150552","pt":1580641161176,"mc":[{"id":"1.168219387","rc":[{"batb":[[0,1.82,238.73],[1,1.8,267.22],[2,1.7,97.01]],"batl":[[0,1.89,262.43],[1,1.91,224.85],[2,3,42.01]],"ltp":1.78,"tv":2163.71,"id":2309796}]}]}
{"op":"mcm","clk":"1005153760","pt":1580641184596,"mc":[{"id":"1.168219387","rc":[{"batb":[[0,1.7,97.01],[1,1.55,20],[2,1.3,113.59]],"batl":[[0,3,42.01],[1,7,2.27],[2,10,2.53]],"ltp":1.78,"tv":2163.71,"id":2309796}]}]}
{"op":"mcm","clk":"1005154113","pt":1580641187577,"mc":[{"id":"1.168219387","rc":[{"batb":[[0,1.73,226.04],[1,1.71,317.64],[2,1.7,97.01]],"batl":[[0,1.95,223.34],[1,1.97,204.66],[2,3,42.01]],"ltp":1.78,"tv":2163.71,"id":2309796}]}]}
{"op":"mcm","clk":"1005154168","pt":1580641188102,"mc":[{"id":"1.168219387","rc":[{"batl":[[0,3,42.01],[1,7,2.27],[2,10,2.53]],"ltp":1.78,"tv":2163.71,"id":2309796}]}]}
{"op":"mcm","clk":"1005154558","pt":1580641190701,"mc":[{"id":"1.168219387","rc":[{"trd":[[2.38,5.91]],"batl":[[0,2.46,8.58],[1,2.5,146],[2,2.56,470.57]],"ltp":2.38,"tv":1000.82,"id":8535963},{"trd":[[1.73,8.13]],"batb":[[0,1.73,217.91]],"batl":[[0,1.76,213],[1,1.81,1040.47],[2,1.83,1444.41]],"ltp":1.73,"tv":2171.84,"id":2309796}],"tv":3172.66}]}
{"op":"mcm","clk":"1005154749","pt":1580641191692,"mc":[{"id":"1.168219387","rc":[{"batb":[[0,2.28,78.21],[1,2.14,93.79],[2,2.08,19.79]],"ltp":2.38,"tv":1000.82,"id":8535963},{"batl":[[1,1.79,270.15],[2,1.81,370.34]],"ltp":1.73,"tv":2171.84,"id":2309796}]}]}
{"op":"mcm","clk":"1005154866","pt":1580641192730,"mc":[{"id":"1.168219387","rc":[{"batb":[[1,2.22,33.61],[2,2.14,93.79]],"batl":[[1,2.5,173.73]],"ltp":2.38,"tv":1000.82,"id":8535963}]}]}
{"op":"mcm","clk":"1005155701","pt":1580641197401,"mc":[{"id":"1.168219387","rc":[{"batb":[[2,1.7,591.05]],"batl":[[2,1.8,480.59]],"ltp":1.73,"tv":2171.84,"id":2309796}]}]}
{"op":"mcm","clk":"1005156332","pt":1580641201456,"mc":[{"id":"1.168219387","rc":[{"batl":[[0,2.5,173.73],[1,2.56,470.57],[2,1000,0.02]],"ltp":2.38,"tv":1000.82,"id":8535963},{"trd":[[1.73,48.13]],"batb":[[0,1.73,197.91]],"ltp":1.73,"tv":2211.84,"id":2309796}],"tv":3212.66}]}
{"op":"mcm","clk":"1005156604","pt":1580641202724,"mc":[{"id":"1.168219387","rc":[{"trd":[[1.71,158.72],[1.73,443.95]],"batb":[[0,1.71,238.28],[1,1.7,591.05],[2,1.68,510.84]],"ltp":1.71,"tv":2766.37,"id":2309796}],"tv":3767.19}]}
{"op":"mcm","clk":"1005156710","pt":1580641203257,"mc":[{"id":"1.168219387","rc":[{"batb":[[0,1.7,591.05],[1,1.68,510.84],[2,1.67,62.17]],"batl":[[1,1.8,480.59],[2,1.81,104.05]],"ltp":1.71,"tv":2766.37,"id":2309796}]}]}
{"op":"mcm","clk":"1005156945","pt":1580641204340,"mc":[{"id":"1.168219387","rc":[{"batb":[[0,2.36,10.23],[1,2.28,78.21],[2,2.22,33.61]],"ltp":2.38,"tv":1000.82,"id":8535963},{"batb":[[0,1.7,601]],"ltp":1.71,"tv":2766.37,"id":2309796}]}]}
{"op":"mcm","clk":"1005157287","pt":1580641206118,"mc":[{"id":"1.168219387","rc":[{"batb":[[0,1.72,214.76],[1,1.7,925.75],[2,1.68,510.84]],"batl":[[1,1.78,296.95],[2,1.8,752.17]],"ltp":1.71,"tv":2766.37,"id":2309796}]}]}
{"op":"mcm","clk":"1005157687","pt":1580641208235,"mc":[{"id":"1.168219387","rc":[{"batb":[[0,2.22,33.61],[1,2.14,93.79],[2,2.08,19.79]],"batl":[[0,2.5,27.73],[1,1000,0.02],[2,1000,0]],"ltp":2.38,"tv":1000.82,"id":8535963},{"batb":[[0,1.7,494.03],[1,1.68,510.84],[2,1.67,62.17]],"batl":[[0,1.8,480.59],[1,1.82,497.4],[2,1.83,42.01]],"ltp":1.71,"tv":2766.37,"id":2309796}]}]}
{"op":"mcm","clk":"1005157952","pt":1580641209776,"mc":[{"id":"1.168219387","rc":[{"batb":[[0,2.14,93.79],[1,2.08,19.79],[2,1.7,75.72]],"batl":[[0,1000,0.02],[1,1000,0]],"ltp":2.38,"tv":1000.82,"id":8535963},{"batb":[[2,1.57,127.94]],"batl":[[2,3,42.01]],"ltp":1.71,"tv":2766.37,"id":2309796}]}]}
{"op":"mcm","clk":"1005158244","pt":1580641211252,"mc":[{"id":"1.168219387","rc":[{"batb":[[2,1.59,247.73]],"batl":[[2,1.87,211.92]],"ltp":1.71,"tv":2766.37,"id":2309796}]}]}
{"op":"mcm","clk":"1005161303","pt":1580641228749,"mc":[{"id":"1.168219387","rc":[{"batb":[[2,1.57,127.94]],"batl":[[0,1.87,211.92],[1,1.89,232.76],[2,3,42.01]],"ltp":1.71,"tv":2766.37,"id":2309796}]}]}
{"op":"mcm","clk":"1005161750","pt":1580641231563,"mc":[{"id":"1.168219387","rc":[{"batl":[[0,2.28,12.08],[1,2.34,202],[2,2.36,76.83]],"ltp":2.38,"tv":1000.82,"id":8535963},{"batb":[[0,1.81,184.37],[1,1.79,272.5],[2,1.7,494.03]],"batl":[[0,1.83,12.57],[1,1.86,765.08],[2,1.87,211.92]],"ltp":1.71,"tv":2766.37,"id":2309796}]}]}
{"op":"mcm","clk":"1005161946","pt":1580641232679,"mc":[{"id":"1.168219387","rc":[{"batb":[[1,2.12,36.97],[2,2.08,19.79]],"batl":[[2,2.36,107.08]],"ltp":2.38,"tv":1000.82,"id":8535963},{"batb":[[1,1.79,354.57],[2,1.74,56.29]],"ltp":1.71,"tv":2766.37,"id":2309796}]}]}
{"op":"mcm","clk":"1005162756","pt":1580641237791,"mc":[{"id":"1.168219387","rc":[{"batb":[[2,1.78,494.03]],"batl":[[2,1.87,692.51]],"ltp":1.71,"tv":2766.37,"id":2309796}]}]}
{"op":"mcm","clk":"1005165105","pt":1580641250717,"mc":[{"id":"1.168219387","rc":[{"batl":[[1,2.36,107.08],[2,2.4,86.03]],"ltp":2.38,"tv":1000.82,"id":8535963},{"batl":[[1,1.86,559.08]],"ltp":1.71,"tv":2766.37,"id":2309796}]}]}
{"op":"mcm","clk":"1005165386","pt":1580641251743,"mc":[{"id":"1.168219387","rc":[{"batb":[[0,2.08,19.79],[1,2.04,105.98],[2,1.6,75.72]],"batl":[[0,1000,0.02],[1,2.36,0],[2,2.4,0]],"ltp":2.38,"tv":1000.82,"id":8535963},{"batb":[[0,1.78,494.03],[1,1.76,510.84],[2,1.69,99.53]],"batl":[[0,1.87,480.59],[1,1.89,497.4],[2,3,42.01]],"ltp":1.71,"tv":2766.37,"id":2309796}]}]}
{"op":"mcm","clk":"1005165879","pt":1580641254115,"mc":[{"id":"1.168219387","rc":[{"batb":[[2,1.71,195.66]],"batl":[[2,1.94,209.62]],"ltp":1.71,"tv":2766.37,"id":2309796}]}]}
{"op":"mcm","clk":"1005166049","pt":1580641255138,"mc":[{"id":"1.168219387","rc":[{"batl":[[0,2.2,5],[1,1000,0.02]],"ltp":2.38,"tv":1000.82,"id":8535963}]}]}
{"op":"mcm","clk":"1005166246","pt":1580641256314,"mc":[{"id":"1.168219387","rc":[{"batb":[[2,1.69,99.53]],"ltp":1.71,"tv":2766.37,"id":2309796}]}]}
{"op":"mcm","clk":"1005166373","pt":1580641257026,"mc":[{"id":"1.168219387","rc":[{"batl":[[0,1.94,209.62],[1,1.96,208.12],[2,3,42.01]],"ltp":1.71,"tv":2766.37,"id":2309796}]}]}
{"op":"mcm","clk":"1005166815","pt":1580641259632,"mc":[{"id":"1.168219387","rc":[{"batl":[[0,2.16,7.92],[1,2.2,5],[2,2.22,180]],"ltp":2.38,"tv":1000.82,"id":8535963},{"batb":[[0,1.87,233.98],[1,1.85,244.69],[2,1.84,108.32]],"batl":[[0,1.92,407.59],[1,1.94,419.62],[2,1.96,208.12]],"ltp":1.71,"tv":2766.37,"id":2309796}]}]}
{"op":"mcm","clk":"1005166993","pt":1580641260755,"mc":[{"id":"1.168219387","rc":[{"batb":[[2,2,42.01]],"batl":[[2,2.22,213.61]],"ltp":2.38,"tv":1000.82,"id":8535963},{"batb":[[1,1.86,73.02],[2,1.85,244.69]],"ltp":1.71,"tv":2766.37,"id":2309796}]}]}
{"op":"mcm","clk":"1005167346","pt":1580641262633,"mc":[{"id":"1.168219387","rc":[{"trd":[[1.87,60.81]],"batb":[[0,1.87,203.56]],"ltp":1.87,"tv":2827.18,"id":2309796}],"tv":3828.0}]}
{"op":"mcm","clk":"1005169422","pt":1580641274262,"mc":[{"id":"1.168219387","rc":[{"batl":[[1,2.22,213.61],[2,2.24,393.82]],"ltp":2.38,"tv":1000.82,"id":8535963}]}]}
{"op":"mcm","clk":"1005169947","pt":1580641277379,"mc":[{"id":"1.168219387","rc":[{"trd":[[2.08,10]],"batb":[[0,2.08,14.79]],"ltp":2.08,"tv":1010.82,"id":8535963}],"tv":3838.0}]}
{"op":"mcm","clk":"1005172373","pt":1580641291472,"mc":[{"id":"1.168219387","rc":[{"trd":[[2.08,11.51]],"batb":[[0,2.08,14.04]],"ltp":2.08,"tv":1012.33,"id":8535963}],"tv":3839.52}]}
{"op":"mcm","clk":"1005173213","pt":1580641296400,"mc":[{"id":"1.168219387","rc":[{"batb":[[0,1.86,73.02],[1,1.84,108.32],[2,1.82,50.41]],"batl":[[1,1.94,210],[2,1.99,42.01]],"ltp":1.87,"tv":2827.18,"id":2309796}]}]}
{"op":"mcm","clk":"1005175047","pt":1580641305753,"mc":[{"id":"1.168219387","rc":[{"batl":[[0,1.87,154],[1,1.92,407.59],[2,1.94,210]],"ltp":1.87,"tv":2827.18,"id":2309796}]}]}
{"op":"mcm","clk":"1005175410","pt":1580641307740,"mc":[{"id":"1.168219387","rc":[{"batl":[[1,2.22,33.61]],"ltp":2.08,"tv":1012.33,"id":8535963},{"batl":[[2,1.99,42.01]],"ltp":1.87,"tv":2827.18,"id":2309796}]}]}
{"op":"mcm","clk":"1005175517","pt":1580641308318,"mc":[{"id":"1.168219387","rc":[{"batb":[[1,2,42.01],[2,1.91,65.31]],"batl":[[0,2.22,33.61],[1,1000,0.02],[2,2.24,0]],"ltp":2.08,"tv":1012.33,"id":8535963},{"batb":[[0,1.82,50.41],[1,1.81,217.22],[2,1.79,354.09]],"batl":[[1,1.99,42.01],[2,2.08,311.14]],"ltp":1.87,"tv":2827.18,"id":2309796}]}]}
{"op":"mcm","clk":"1005175794","pt":1580641309913,"mc":[{"id":"1.168219387","rc":[{"batb":[[1,1.91,65.31],[2,1.6,75.72]],"batl":[[0,1000,0.02],[1,1000,0]],"ltp":2.08,"tv":1012.33,"id":8535963},{"batb":[[0,1.81,217.22],[1,1.79,354.09],[2,1.55,20]],"batl":[[1,2.08,311.14],[2,2.1,169.7]],"ltp":1.87,"tv":2827.18,"id":2309796}]}]}
{"op":"mcm","clk":"1005177131","pt":1580641317222,"mc":[{"id":"1.168219387","rc":[{"trd":[[1.87,299.35]],"batl":[[0,1.87,34.73]],"ltp":1.87,"tv":3065.72,"id":2309796}],"tv":4078.06}]}
{"op":"mcm","clk":"1005177567","pt":1580641319418,"mc":[{"id":"1.168219387","rc":[{"batl":[[1,3,42.01],[2,7,2.27]],"ltp":1.87,"tv":3065.72,"id":2309796}]}]}
{"op":"mcm","clk":"1005178168","pt":1580641322731,"mc":[{"id":"1.168219387","rc":[{"batb":[[0,2.12,86.57],[1,2.1,103.02],[2,2.08,52.68]],"batl":[[0,2.28,13.56],[1,2.32,188.09],[2,1000,0.02]],"ltp":2.08,"tv":1012.33,"id":8535963},{"batb":[[2,1.77,53.77]],"batl":[[0,1.83,10.74],[1,1.86,733.65],[2,1.87,215.09]],"ltp":1.87,"tv":3065.72,"id":2309796}]}]}
{"op":"mcm","clk":"1005178286","pt":1580641323321,"mc":[{"id":"1.168219387","rc":[{"batb":[[0,2.12,180.99]],"ltp":2.08,"tv":1012.33,"id":8535963}]}]}
{"op":"mcm","clk":"1005178487","pt":1580641324427,"mc":[{"id":"1.168219387","rc":[{"batl":[[2,3,213.45]],"ltp":2.08,"tv":1012.33,"id":8535963}]}]}
{"op":"mcm","clk":"1005179260","pt":1580641328553,"mc":[{"id":"1.168219387","rc":[{"batb":[[2,1.77,547.81]],"batl":[[1,1.86,1214.24]],"ltp":1.87,"tv":3065.72,"id":2309796}]}]}
{"op":"mcm","clk":"1005180365","pt":1580641334729,"mc":[{"id":"1.168219387","rc":[{"trd":[[1.83,179.9]],"batl":[[0,1.86,1214.42],[1,1.87,215.09],[2,1.88,497.4]],"ltp":1.83,"tv":3086.84,"id":2309796}],"tv":4099.18}]}
{"op":"mcm","clk":"1005180527","pt":1580641335687,"mc":[{"id":"1.168219387","rc":[{"batl":[[0,2.32,31.09],[1,3,213.45],[2,1000,0.02]],"ltp":2.08,"tv":1012.33,"id":8535963},{"batl":[[0,1.86,480.59]],"ltp":1.83,"tv":3086.84,"id":2309796}]}]}
{"op":"mcm","clk":"1005180603","pt":1580641336061,"mc":[{"id":"1.168219387","rc":[{"batb":[[0,2.08,52.68],[1,2,113.77],[2,1.77,402.27]],"ltp":2.08,"tv":1012.33,"id":8535963},{"batb":[[0,1.77,547.81],[1,1.75,599.67],[2,1.55,20]],"batl":[[1,1.87,34.73]],"ltp":1.83,"tv":3086.84,"id":2309796}]}]}
{"op":"mcm","clk":"1005180923","pt":1580641337765,"mc":[{"id":"1.168219387","rc":[{"batb":[[0,2.08,14.04]],"batl":[[0,3,213.45],[1,1000,0.02],[2,1000,0]],"ltp":2.08,"tv":1012.33,"id":8535963},{"batb":[[0,1.77,494.03]],"ltp":1.83,"tv":3086.84,"id":2309796}]}]}
{"op":"mcm","clk":"1005181111","pt":1580641338882,"mc":[{"id":"1.168219387","rc":[{"batb":[[1,1.76,283.61],[2,1.75,599.67]],"ltp":1.83,"tv":3086.84,"id":2309796}]}]}
{"op":"mcm","clk":"1005182555","pt":1580641346882,"mc":[{"id":"1.168219387","rc":[{"batb":[[1,1.76,234.53]],"ltp":1.83,"tv":3086.84,"id":2309796}]}]}
{"op":"mcm","clk":"1005183188","pt":1580641350430,"mc":[{"id":"1.168219387","rc":[{"batb":[[1,1.76,200.26]],"ltp":1.83,"tv":3086.84,"id":2309796}]}]}
{"op":"mcm","clk":"1005183385","pt":1580641351513,"mc":[{"id":"1.168219387","rc":[{"batb":[[0,1.76,200.26],[1,1.75,88.83],[2,1.74,299.98]],"ltp":1.83,"tv":3086.84,"id":2309796}]}]}
{"op":"mcm","clk":"1005183814","pt":1580641353701,"mc":[{"id":"1.168219387","rc":[{"batb":[[0,2.22,930.57],[1,2.16,1018.08],[2,2.08,14.04]],"batl":[[0,2.42,417.46],[1,3,213.45],[2,1000,0.02]],"ltp":2.08,"tv":1012.33,"id":8535963},{"batb":[[0,1.76,209.01]],"batl":[[0,1.8,15.16],[1,1.81,3592.8],[2,1.86,1740.32]],"ltp":1.83,"tv":3086.84,"id":2309796}]}]}
{"op":"mcm","clk":"1005184002","pt":1580641354697,"mc":[{"id":"1.168219387","rc":[{"batb":[[0,2.22,93.06],[1,2.16,101.81],[2,2.14,36.13]],"batl":[[0,2.4,29.41],[1,2.42,417.46],[2,3,213.45]],"ltp":2.08,"tv":1012.33,"id":8535963},{"batl":[[1,1.81,238],[2,1.82,256.97]],"ltp":1.83,"tv":3086.84,"id":2309796}]}]}
{"op":"mcm","clk":"1005184184","pt":1580641355595,"mc":[{"id":"1.168219387","rc":[{"batb":[[1,2.2,86.08],[2,2.16,101.81]],"ltp":2.08,"tv":1012.33,"id":8535963}]}]}
{"op":"mcm","clk":"1005185629","pt":1580641363816,"mc":[{"id":"1.168219387","rc":[{"trd":[[1.8,46.14],[1.81,204.97]],"batl":[[0,1.81,137.79],[1,1.82,256.97],[2,1.83,480.59]],"ltp":1.81,"tv":3317.59,"id":2309796}],"tv":4329.92}]}
{"op":"mcm","clk":"1005186610","pt":1580641369058,"mc":[{"id":"1.168219387","rc":[{"batb":[[0,1.76,929.56]],"ltp":1.81,"tv":3317.59,"id":2309796}]}]}
{"op":"mcm","clk":"1005187757","pt":1580641374649,"mc":[{"id":"1.168219387","rc":[{"batb":[[0,2.2,86.08],[1,2.14,36.13],[2,2.1,99.45]],"batl":[[1,3,213.45],[2,1000,0.02]],"ltp":2.08,"tv":1012.33,"id":8535963},{"batb":[[0,1.76,720.55],[2,1.73,57.13]],"batl":[[0,1.83,480.59],[1,1.85,497.4],[2,1.87,34.73]],"ltp":1.81,"tv":3317.59,"id":2309796}]}]}
{"op":"mcm","clk":"1005187974","pt":1580641375722,"mc":[{"id":"1.168219387","rc":[{"batb":[[0,2.1,99.45],[1,2.08,14.04],[2,1.77,402.27]],"batl":[[0,3,213.45],[1,1000,0.02],[2,1000,0]],"ltp":2.08,"tv":1012.33,"id":8535963},{"batb":[[1,1.72,494.03],[2,1.71,95.28]],"ltp":1.81,"tv":3317.59,"id":2309796}]}]}
{"op":"mcm","clk":"1005188337","pt":1580641377524,"mc":[{"id":"1.168219387","rc":[{"trd":[[1.76,33.61]],"batb":[[0,1.76,703.75],[1,1.73,182.61],[2,1.72,494.03]],"ltp":1.76,"tv":3351.19,"id":2309796}],"tv":4363.53}]}
{"op":"mcm","clk":"1005188594","pt":1580641378858,"mc":[{"id":"1.168219387","rc":[{"batb":[[2,1.71,413.7]],"ltp":1.76,"tv":3351.19,"id":2309796}]}]}
{"op":"mcm","clk":"1005189117","pt":1580641381645,"mc":[{"id":"1.168219387","rc":[{"batb":[[2,1.6,75.72]],"batl":[[0,2.48,186],[1,2.5,263.54],[2,3,213.45]],"ltp":2.08,"tv":1012.33,"id":8535963},{"batb":[[1,1.74,11.73],[2,1.73,182.61]],"batl":[[0,1.78,526.9],[1,1.8,377.92],[2,1.83,1954.75]],"ltp":1.76,"tv":3351.19,"id":2309796}]}]}
{"op":"mcm","clk":"1005189340","pt":1580641382736,"mc":[{"id":"1.168219387","rc":[{"batb":[[0,2.26,79.7],[1,2.2,34.45],[2,2.18,89.15]],"batl":[[0,2.46,28.57],[1,2.48,186],[2,2.5,263.54]],"ltp":2.08,"tv":1012.33,"id":8535963}]}]}
{"op":"mcm","clk":"1005190089","pt":1580641386972,"mc":[{"id":"1.168219387","rc":[{"batl":[[2,1.83,1474.16]],"ltp":1.76,"tv":3351.19,"id":2309796}]}]}
{"op":"mcm","clk":"1005190268","pt":1580641387845,"mc":[{"id":"1.168219387","rc":[{"batl":[[2,1.82,480.59]],"ltp":1.76,"tv":3351.19,"id":2309796}]}]}
{"op":"mcm","clk":"1005190637","pt":1580641389556,"mc":[{"id":"1.168219387","rc":[{"batl":[[1,3,213.45],[2,1000,0.02]],"ltp":2.08,"tv":1012.33,"id":8535963},{"batb":[[1,1.73,182.61],[2,1.72,494.03]],"batl":[[0,1.78,285.85]],"ltp":1.76,"tv":3351.19,"id":2309796}]}]}
{"op":"mcm","clk":"1005190710","pt":1580641389968,"mc":[{"id":"1.168219387","rc":[{"batb":[[0,2.2,34.45],[1,2.18,89.15],[2,2.08,14.04]],"ltp":2.08,"tv":1012.33,"id":8535963},{"batb":[[1,1.72,494.03],[2,1.71,187.77]],"batl":[[0,1.82,480.59],[1,1.84,539.41],[2,1.87,34.73]],"ltp":1.76,"tv":3351.19,"id":2309796}]}]}
{"op":"mcm","clk":"1005191258","pt":1580641392757,"mc":[{"id":"1.168219387","rc":[{"batb":[[0,2.18,89.15],[1,2.08,14.04],[2,1.86,398.62]],"batl":[[0,3,213.45],[1,1000,0.02],[2,1000,0]],"ltp":2.08,"tv":1012.33,"id":8535963},{"batl":[[1,1.83,282.52],[2,1.84,497.4]],"ltp":1.76,"tv":3351.19,"id":2309796}]}]}
{"op":"mcm","clk":"1005192118","pt":1580641396458,"mc":[{"id":"1.168219387","rc":[{"batb":[[2,1.7,510.84]],"batl":[[0,1.83,282.52],[1,1.85,249.08],[2,1.87,34.73]],"ltp":1.76,"tv":3351.19,"id":2309796}]}]}
{"op":"mcm","clk":"1005192680","pt":1580641399274,"mc":[{"id":"1.168219387","rc":[{"trd":[[2.24,25.67]],"batb":[[0,2.24,279.95],[1,2.18,89.15],[2,2.08,14.04]],"batl":[[0,2.3,89.05],[1,2.36,250.22],[2,3,213.45]],"ltp":2.24,"tv":1025.29,"id":8535963},{"batb":[[0,1.76,1010.29],[1,1.74,300.29],[2,1.72,876.64]],"batl":[[1,1.84,194],[2,1.85,249.08]],"ltp":1.76,"tv":3351.19,"id":2309796}],"tv":4376.49}]}
{"op":"mcm","clk":"1005192938","pt":1580641400766,"mc":[{"id":"1.168219387","rc":[{"batb":[[1,2.18,91.83],[2,2.12,36.97]],"batl":[[1,2.36,280.47]],"ltp":2.24,"tv":1025.29,"id":8535963},{"batb":[[0,1.76,1096.29],[1,1.75,2.62],[2,1.74,356.58]],"ltp":1.76,"tv":3351.19,"id":2309796}]}]}
{"op":"mcm","clk":"1005193916","pt":1580641405807,"mc":[{"id":"1.168219387","rc":[{"batl":[[1,1.84,674.59]],"ltp":1.76,"tv":3351.19,"id":2309796}]}]}
{"op":"mcm","clk":"1005194314","pt":1580641407684,"mc":[{"id":"1.168219387","rc":[{"batb":[[0,2.18,2.68],[1,2.12,36.97],[2,2.08,14.04]],"batl":[[0,2.36,30.25],[1,3,213.45],[2,1000,0.02]],"ltp":2.24,"tv":1025.29,"id":8535963},{"batb":[[0,1.76,703.75],[2,1.74,56.29]],"batl":[[0,1.84,480.59],[1,1.86,497.4],[2,1.87,34.73]],"ltp":1.76,"tv":3351.19,"id":2309796}]}]}
{"op":"mcm","clk":"1005194353","pt":1580641407900,"mc":[{"id":"1.168219387","rc":[{"batb":[[1,2.08,14.04],[2,2.06,102.84]],"batl":[[0,3,213.45],[1,1000,0.02],[2,1000,0]],"ltp":2.24,"tv":1025.29,"id":8535963},{"batb":[[2,1.73,92.53]],"ltp":1.76,"tv":3351.19,"id":2309796}]}]}
{"op":"mcm","clk":"1005194995","pt":1580641410600,"mc":[{"id":"1.168219387","rc":[{"batb":[[2,1.73,399.5]],"ltp":1.76,"tv":3351.19,"id":2309796}]}]}
{"op":"mcm","clk":"1005195996","pt":1580641415327,"mc":[{"id":"1.168219387","rc":[{"batb":[[1,1.73,399.5],[2,1.71,318.83]],"ltp":1.76,"tv":3351.19,"id":2309796}]}]}
{"op":"mcm","clk":"1005196411","pt":1580641417332,"mc":[{"id":"1.168219387","rc":[{"batl":[[0,2.44,189],[1,2.46,276.82],[2,3,213.45]],"ltp":2.24,"tv":1025.29,"id":8535963},{"batb":[[1,1.74,16.44],[2,1.73,399.5]],"batl":[[0,1.78,576.56],[1,1.79,195.28],[2,1.8,214]],"ltp":1.76,"tv":3351.19,"id":2309796}]}]}
{"op":"mcm","clk":"1005196680","pt":1580641418697,"mc":[{"id":"1.168219387","rc":[{"batb":[[0,2.24,82.38],[1,2.2,34.45],[2,2.18,2.68]],"batl":[[1,2.46,305.39]],"ltp":2.24,"tv":1025.29,"id":8535963}]}]}
{"op":"mcm","clk":"1005198369","pt":1580641426737,"mc":[{"id":"1.168219387","rc":[{"trd":[[1.76,38.65]],"batb":[[0,1.76,701.23]],"ltp":1.76,"tv":3356.24,"id":2309796}],"tv":4381.53}]}
{"op":"mcm","clk":"1005198737","pt":1580641428553,"mc":[{"id":"1.168219387","rc":[{"batb":[[2,2.14,93.24]],"ltp":2.24,"tv":1025.29,"id":8535963}]}]}
{"op":"mcm","clk":"1005199248","pt":1580641431048,"mc":[{"id":"1.168219387","rc":[{"batb":[[0,1.74,16.44],[1,1.73,399.5],[2,1.71,318.83]],"ltp":1.76,"tv":3356.24,"id":2309796}]}]}
{"op":"mcm","clk":"1005199889","pt":1580641434256,"mc":[{"id":"1.168219387","rc":[{"trd":[[1.78,1545.28]],"batb":[[0,1.78,124.64],[1,1.74,16.44],[2,1.73,399.5]],"batl":[[0,1.79,195.28],[1,1.8,214],[2,1.81,371.21]],"ltp":1.78,"tv":4509.38,"id":2309796}],"tv":5534.68}]}
{"op":"mcm","clk":"1005200591","pt":1580641437442,"mc":[{"id":"1.168219387","rc":[{"trd":[[1.78,1593.82]],"batb":[[0,1.78,100.37]],"ltp":1.78,"tv":4557.92,"id":2309796}],"tv":5583.22}]}
{"op":"mcm","clk":"1005201937","pt":1580641444510,"mc":[{"id":"1.168219387","rc":[{"batb":[[1,1.73,399.5],[2,1.71,318.83]],"ltp":1.78,"tv":4557.92,"id":2309796}]}]}
{"op":"mcm","clk":"1005202489","pt":1580641447416,"mc":[{"id":"1.168219387","rc":[{"batb":[[1,1.76,12.26],[2,1.73,399.5]],"batl":[[1,1.8,225.64]],"ltp":1.78,"tv":4557.92,"id":2309796}]}]}
{"op":"mcm","clk":"1005202649","pt":1580641448209,"mc":[{"id":"1.168219387","rc":[{"batb":[[0,2.2,34.45],[1,2.14,93.24],[2,2.08,14.04]],"batl":[[0,2.46,28.57],[1,3,213.45],[2,1000,0.02]],"ltp":2.24,"tv":1025.29,"id":8535963},{"batb":[[1,1.69,60.49],[2,1.63,112.99]],"batl":[[0,1.83,42.01],[1,1.87,34.73],[2,3,42.01]],"ltp":1.78,"tv":4557.92,"id":2309796}]}]}
{"op":"mcm","clk":"1005202957","pt":1580641449824,"mc":[{"id":"1.168219387","rc":[{"batb":[[0,2.14,93.24],[1,2.08,14.04],[2,1.86,398.62]],"batl":[[0,3,213.45],[1,1000,0.02],[2,1000,0]],"ltp":2.24,"tv":1025.29,"id":8535963},{"batb":[[1,1.63,112.99],[2,1.55,20]],"batl":[[0,1.87,34.73],[1,3,42.01],[2,7,2.27]],"ltp":1.78,"tv":4557.92,"id":2309796}]}]}
{"op":"mcm","clk":"1005203646","pt":1580641453097,"mc":[{"id":"1.168219387","rc":[{"trd":[[1.78,1794.56]],"batb":[[0,1.71,323.65],[1,1.69,332.26],[2,1.63,112.99]],"batl":[[0,1.77,108.34],[1,1.79,277.13],[2,1.87,34.73]],"ltp":1.78,"tv":4758.66,"id":2309796}],"tv":5783.96}]}
{"op":"mcm","clk":"1005203849","pt":1580641453942,"mc":[{"id":"1.168219387","rc":[{"batb":[[0,1.63,112.99],[1,1.55,20],[2,1.3,113.59]],"batl":[[0,1.87,34.73],[1,3,42.01],[2,7,2.27]],"ltp":1.78,"tv":4758.66,"id":2309796}]}]}
{"op":"mcm","clk":"1005205211","pt":1580641460734,"mc":[{"id":"1.168219387","rc":[{"batb":[[0,1.64,353.51],[1,1.63,303.27],[2,1.55,20]],"batl":[[0,1.86,211.82],[1,1.87,34.73],[2,1.88,236.78]],"ltp":1.78,"tv":4758.66,"id":2309796}]}]}
{"op":"mcm","clk":"1005205425","pt":1580641461940,"mc":[{"id":"1.168219387","rc":[{"batl":[[0,1.78,25.33],[1,1.86,211.82],[2,1.87,34.73]],"ltp":1.78,"tv":4758.66,"id":2309796}]}]}
{"op":"mcm","clk":"1005207128","pt":1580641469655,"mc":[{"id":"1.168219387","rc":[{"batl":[[1,1.87,34.73],[2,3,42.01]],"ltp":1.78,"tv":4758.66,"id":2309796}]}]}
{"op":"mcm","clk":"1005207519","pt":1580641471365,"mc":[{"id":"1.168219387","rc":[{"batb":[[2,1.6,75.72]],"batl":[[0,1000,0.02],[1,1000,0]],"ltp":2.24,"tv":1025.29,"id":8535963}]}]}
{"op":"mcm","clk":"1005207817","pt":1580641472741,"mc":[{"id":"1.168219387","rc":[{"batb":[[0,2.46,6.73],[1,2.36,86.72],[2,2.34,31.09]],"batl":[[0,2.66,590.1],[1,1000,0.02]],"ltp":2.24,"tv":1025.29,"id":8535963},{"batb":[[0,1.66,8.52],[1,1.64,353.51],[2,1.63,303.27]],"batl":[[0,1.69,238],[1,1.7,299.28],[2,1.71,123.92]],"ltp":1.78,"tv":4758.66,"id":2309796}]}]}
{"op":"mcm","clk":"1005208025","pt":1580641473753,"mc":[{"id":"1.168219387","rc":[{"batb":[[1,2.42,65.86],[2,2.36,86.72]],"ltp":2.24,"tv":1025.29,"id":8535963}]}]}
{"op":"mcm","clk":"1005208089","pt":1580641474063,"mc":[{"id":"1.168219387","rc":[{"batb":[[2,2.36,89.33]],"ltp":2.24,"tv":1025.29,"id":8535963},{"batb":[[1,1.65,2.68],[2,1.64,353.51]],"ltp":1.78,"tv":4758.66,"id":2309796}]}]}
{"op":"mcm","clk":"1005208393","pt":1580641475550,"mc":[{"id":"1.168219387","rc":[{"batl":[[1,3.65,170.41],[2,1000,0.02]],"ltp":2.24,"tv":1025.29,"id":8535963}]}]}
{"op":"mcm","clk":"1005211026","pt":1580641489554,"mc":[{"id":"1.168219387","rc":[{"batb":[[0,2.42,65.86],[1,2.36,89.33],[2,2.34,31.09]],"batl":[[0,2.66,25.21]],"ltp":2.24,"tv":1025.29,"id":8535963},{"batb":[[0,1.65,2.68],[1,1.64,353.51],[2,1.63,797.3]],"batl":[[0,1.7,299.28],[1,1.71,123.92],[2,1.72,315.81]],"ltp":1.78,"tv":4758.66,"id":2309796}]}]}
{"op":"mcm","clk":"1005211144","pt":1580641490136,"mc":[{"id":"1.168219387","rc":[{"batb":[[0,2.36,2.61],[1,2.28,78.29],[2,2.08,14.04]],"batl":[[0,3.65,170.41],[1,1000,0.02],[2,1000,0]],"ltp":2.24,"tv":1025.29,"id":8535963},{"batb":[[1,1.63,494.03],[2,1.61,510.84]],"batl":[[0,1.73,480.59],[1,1.75,497.4],[2,1.78,25.33]],"ltp":1.78,"tv":4758.66,"id":2309796}]}]}
{"op":"mcm","clk":"1005211824","pt":1580641493691,"mc":[{"id":"1.168219387","rc":[{"batb":[[0,2.28,78.29],[1,2.08,14.04],[2,1.97,394.86]],"ltp":2.24,"tv":1025.29,"id":8535963},{"batl":[[0,1.78,25.33],[1,1.87,34.73],[2,3,42.01]],"ltp":1.78,"tv":4758.66,"id":2309796}]}]}
{"op":"mcm","clk":"1005212047","pt":1580641494747,"mc":[{"id":"1.168219387","rc":[{"batl":[[0,1000,0.02],[1,1000,0]],"ltp":2.24,"tv":1025.29,"id":8535963},{"batl":[[0,1.66,41.65],[1,1.78,25.33],[2,1.87,34.73]],"ltp":1.78,"tv":4758.66,"id":2309796}]}]}
{"op":"mcm","clk":"1005212222","pt":1580641495750,"mc":[{"id":"1.168219387","rc":[{"batl":[[0,2.36,6.73],[1,2.38,2562.6],[2,2.46,1175.78]],"ltp":2.24,"tv":1025.29,"id":8535963},{"trd":[[1.66,83.3]],"batb":[[0,1.7,108.74],[1,1.65,2.68],[2,1.63,494.03]],"batl":[[0,1.77,226],[1,1.78,415.08]],"ltp":1.66,"tv":4841.96,"id":2309796}],"tv":5867.26}]}
{"op":"mcm","clk":"1005212335","pt":1580641496386,"mc":[{"id":"1.168219387","rc":[{"batl":[[1,2.46,427.17],[2,2.48,135]],"ltp":2.24,"tv":1025.29,"id":8535963},{"batb":[[0,1.71,315.69],[1,1.7,108.74],[2,1.69,332.12]],"batl":[[0,1.77,442.01],[2,1.79,277.02]],"ltp":1.66,"tv":4841.96,"id":2309796}]}]}
{"op":"mcm","clk":"1005212496","pt":1580641497177,"mc":[{"id":"1.168219387","rc":[{"batb":[[1,2.16,91.11],[2,2.08,14.04]],"ltp":2.24,"tv":1025.29,"id":8535963},{"trd":[[1.77,67.9]],"batb":[[1,1.7,205.6]],"batl":[[0,1.77,416.85]],"ltp":1.77,"tv":4892.28,"id":2309796}],"tv":5917.58}]}
{"op":"mcm","clk":"1005213171","pt":1580641500486,"mc":[{"id":"1.168219387","rc":[{"batb":[[1,2.24,33.61],[2,2.16,91.11]],"ltp":2.24,"tv":1025.29,"id":8535963}]}]}
{"op":"mcm","clk":"1005213594","pt":1580641502652,"mc":[{"id":"1.168219387","rc":[{"batb":[[1,1.7,699.63]],"ltp":1.77,"tv":4892.28,"id":2309796}]}]}
{"op":"mcm","clk":"1005214742","pt":1580641508607,"mc":[{"id":"1.168219387","rc":[{"batl":[[0,2.46,83.18],[1,2.52,26.89],[2,3.45,180.4]],"ltp":2.24,"tv":1025.29,"id":8535963},{"batl":[[0,1.77,216.01],[1,1.78,25.33]],"ltp":1.77,"tv":4892.28,"id":2309796}]}]}
{"op":"mcm","clk":"1005214847","pt":1580641508997,"mc":[{"id":"1.168219387","rc":[{"batb":[[0,2.24,33.61],[1,2.16,91.11],[2,2.08,14.04]],"batl":[[0,2.52,26.89],[1,3.45,180.4],[2,1000,0.02]],"ltp":2.24,"tv":1025.29,"id":8535963},{"batb":[[0,1.7,494.03],[1,1.68,510.84],[2,1.67,62.17]],"batl":[[0,1.78,25.33],[1,1.81,522.6],[2,1.83,497.4]],"ltp":1.77,"tv":4892.28,"id":2309796}]}]}
{"op":"mcm","clk":"1005215033","pt":1580641509907,"mc":[{"id":"1.168219387","rc":[{"batb":[[0,2.16,91.11],[1,2.08,14.04],[2,1.97,394.86]],"batl":[[0,3.45,180.4],[1,1000,0.02],[2,1000,0]],"ltp":2.24,"tv":1025.29,"id":8535963},{"batb":[[2,1.59,122.67]],"batl":[[1,1.81,480.59]],"ltp":1.77,"tv":4892.28,"id":2309796}]}]}
{"op":"mcm","clk":"1005215415","pt":1580641511912,"mc":[{"id":"1.168219387","rc":[{"batb":[[2,1.61,212.83]],"ltp":1.77,"tv":4892.28,"id":2309796}]}]}
{"op":"mcm","clk":"1005216510","pt":1580641516991,"mc":[{"id":"1.168219387","rc":[{"trd":[[1.7,22.72]],"batb":[[0,1.7,482.68]],"ltp":1.7,"tv":4915.0,"id":2309796}],"tv":5940.3}]}
{"op":"mcm","clk":"1005217006","pt":1580641519128,"mc":[{"id":"1.168219387","rc":[{"trd":[[2.28,310.97]],"ltp":2.28,"tv":1025.91,"id":8535963},{"trd":[[1.78,1795.35]],"batl":[[0,1.78,24.54]],"ltp":1.78,"tv":4915.79,"id":2309796}],"tv":5941.7}]}
{"op":"mcm","clk":"1005217192","pt":1580641519993,"mc":[{"id":"1.168219387","rc":[{"batb":[[2,1.59,122.67]],"batl":[[1,1.85,256.39],[2,1.87,275.48]],"ltp":1.78,"tv":4915.79,"id":2309796}]}]}
{"op":"mcm","clk":"1005217749","pt":1580641522700,"mc":[{"id":"1.168219387","rc":[{"trd":[[2.28,330.14]],"batb":[[0,2.16,386.13]],"batl":[[0,2.24,10.7],[1,2.3,78.81],[2,2.34,175]],"ltp":2.28,"tv":1045.08,"id":8535963},{"trd":[[1.78,1819.89]],"batb":[[0,1.79,281.04],[1,1.77,283.05],[2,1.76,467.87]],"batl":[[0,1.85,433.39],[1,1.86,15.78]],"ltp":1.78,"tv":4940.32,"id":2309796}],"tv":5985.41}]}
{"op":"mcm","clk":"1005217903","pt":1580641523508,"mc":[{"id":"1.168219387","rc":[{"batb":[[0,2.16,388.77],[2,2.06,103.07]],"ltp":2.28,"tv":1045.08,"id":8535963},{"batb":[[1,1.77,369.95]],"ltp":1.78,"tv":4940.32,"id":2309796}]}]}
{"op":"mcm","clk":"1005218179","pt":1580641524881,"mc":[{"id":"1.168219387","rc":[{"batb":[[1,2.14,36.13],[2,2.08,14.04]],"ltp":2.28,"tv":1045.08,"id":8535963},{"batl":[[2,1.87,317.49]],"ltp":1.78,"tv":4940.32,"id":2309796}]}]}
{"op":"mcm","clk":"1005219424","pt":1580641530999,"mc":[{"id":"1.168219387","rc":[{"trd":[[2.24,34.29]],"batl":[[0,2.24,2.08]],"ltp":2.24,"tv":1053.7,"id":8535963},{"trd":[[1.8,56.87]],"ltp":1.8,"tv":4951.05,"id":2309796}],"tv":6004.76}]}
{"op":"mcm","clk":"1005219781","pt":1580641532636,"mc":[{"id":"1.168219387","rc":[{"batb":[[0,2.2,26.5],[1,2.16,388.77],[2,2.14,36.13]],"ltp":2.24,"tv":1053.7,"id":8535963}]}]}
{"op":"mcm","clk":"1005220211","pt":1580641534712,"mc":[{"id":"1.168219387","rc":[{"trd":[[2.24,35.9]],"batl":[[0,2.3,79.28],[1,2.34,175],[2,2.4,29.41]],"ltp":2.24,"tv":1055.31,"id":8535963},{"trd":[[1.8,58.87]],"ltp":1.8,"tv":4953.05,"id":2309796}],"tv":6008.37}]}
{"op":"mcm","clk":"1005220400","pt":1580641535511,"mc":[{"id":"1.168219387","rc":[{"trd":[[2.24,36.37]],"batl":[[0,2.3,78.81]],"ltp":2.24,"tv":1055.78,"id":8535963},{"trd":[[1.8,59.45]],"batl":[[0,1.8,3.42],[1,1.85,433.39],[2,1.86,15.78]],"ltp":1.8,"tv":4953.63,"id":2309796}],"tv":6009.42}]}
{"op":"mcm","clk":"1005220644","pt":1580641536728,"mc":[{"id":"1.168219387","rc":[{"batl":[[0,1.8,2],[2,1.86,37.53]],"ltp":1.8,"tv":4953.63,"id":2309796}]}]}
{"op":"mcm","clk":"1005220805","pt":1580641537555,"mc":[{"id":"1.168219387","rc":[{"batl":[[0,1.85,433.39],[1,1.86,37.53],[2,1.87,317.49]],"ltp":1.8,"tv":4953.63,"id":2309796}]}]}
{"op":"mcm","clk":"1005220980","pt":1580641538625,"mc":[{"id":"1.168219387","rc":[{"batb":[[2,2.14,42.45]],"batl":[[2,2.4,33.7]],"ltp":2.24,"tv":1055.78,"id":8535963},{"batl":[[0,1.85,455.49],[2,1.87,340.99]],"ltp":1.8,"tv":4953.63,"id":2309796}]}]}
{"op":"mcm","clk":"1005221248","pt":1580641539750,"mc":[{"id":"1.168219387","rc":[{"batb":[[1,2.16,2.64],[2,2.14,36.13]],"batl":[[1,2.4,29.41],[2,2.46,4.25]],"ltp":2.24,"tv":1055.78,"id":8535963},{"batb":[[1,1.77,285.68],[2,1.72,57.97]],"batl":[[0,1.85,278.49],[1,1.86,21.75]],"ltp":1.8,"tv":4953.63,"id":2309796}]}]}
{"op":"mcm","clk":"1005221331","pt":1580641540138,"mc":[{"id":"1.168219387","rc":[{"batb":[[2,2.08,14.04]],"batl":[[0,2.46,4.25],[1,3.15,200.42],[2,1000,0.02]],"ltp":2.24,"tv":1055.78,"id":8535963},{"batb":[[0,1.77,2.63],[1,1.69,25.21],[2,1.67,103.39]],"batl":[[0,1.87,58.23],[1,3,42.01],[2,7,2.27]],"ltp":1.8,"tv":4953.63,"id":2309796}]}]}
{"op":"mcm","clk":"1005221772","pt":1580641542039,"mc":[{"id":"1.168219387","rc":[{"batb":[[2,2.14,5.82]],"ltp":2.24,"tv":1055.78,"id":8535963},{"batb":[[1,1.72,27.34],[2,1.69,25.21]],"ltp":1.8,"tv":4953.63,"id":2309796}]}]}
{"op":"mcm","clk":"1005222103","pt":1580641543532,"mc":[{"id":"1.168219387","rc":[{"batb":[[2,1.69,292.63]],"batl":[[1,1.91,198.4],[2,1.93,218.33]],"ltp":1.8,"tv":4953.63,"id":2309796}]}]}
{"op":"mcm","clk":"1005222823","pt":1580641546742,"mc":[{"id":"1.168219387","rc":[{"batb":[[1,2.16,7.42]],"ltp":2.24,"tv":1055.78,"id":8535963},{"batl":[[0,1.85,20.1],[1,1.87,58.23],[2,1.91,198.4]],"ltp":1.8,"tv":4953.63,"id":2309796}]}]}
{"op":"mcm","clk":"1005222946","pt":1580641547369,"mc":[{"id":"1.168219387","rc":[{"batb":[[1,2.16,2.64]],"ltp":2.24,"tv":1055.78,"id":8535963},{"batb":[[2,1.69,25.21]],"batl":[[0,1.87,58.23],[1,1.91,198.4],[2,1.93,218.33]],"ltp":1.8,"tv":4953.63,"id":2309796}]}]}
{"op":"mcm","clk":"1005223187","pt":1580641548546,"mc":[{"id":"1.168219387","rc":[{"batl":[[1,1000,0.02],[2,1000,0]],"ltp":2.24,"tv":1055.78,"id":8535963}]}]}
{"op":"mcm","clk":"1005223252","pt":1580641548868,"mc":[{"id":"1.168219387","rc":[{"batb":[[1,2.14,5.82],[2,2.08,14.04]],"ltp":2.24,"tv":1055.78,"id":8535963}]}]}
{"op":"mcm","clk":"1005223603","pt":1580641550360,"mc":[{"id":"1.168219387","rc":[{"trd":[[2.2,693.57]],"batb":[[0,2.14,5.82],[1,2.08,14.04],[2,2.06,103.07]],"batl":[[0,2.2,302.8],[1,2.24,1156.44],[2,2.46,4.25]],"ltp":2.2,"tv":1082.28,"id":8535963},{"trd":[[1.84,578.08],[1.86,41.4]],"batb":[[0,1.86,1007.56],[1,1.84,281.96],[2,1.82,258.29]],"batl":[[1,1.89,7.23],[2,1.91,198.4]],"ltp":1.86,"tv":5026.72,"id":2309796}],"tv":6109.01}]}
{"op":"mcm","clk":"1005223761","pt":1580641551146,"mc":[{"id":"1.168219387","rc":[{"batb":[[2,2.06,142.56]],"batl":[[2,2.3,31.93]],"ltp":2.2,"tv":1082.28,"id":8535963},{"batb":[[1,1.84,356.94]],"ltp":1.86,"tv":5026.72,"id":2309796}]}]}
{"op":"mcm","clk":"1005224473","pt":1580641554693,"mc":[{"id":"1.168219387","rc":[{"batl":[[1,2.24,301.04]],"ltp":2.2,"tv":1082.28,"id":8535963},{"batb":[[0,1.86,92.49]],"ltp":1.86,"tv":5026.72,"id":2309796}]}]}
{"op":"mcm","clk":"1005224893","pt":1580641556676,"mc":[{"id":"1.168219387","rc":[{"batb":[[2,1.83,494.03]],"batl":[[2,1.91,678.99]],"ltp":1.86,"tv":5026.72,"id":2309796}]}]}
{"op":"mcm","clk":"1005225163","pt":1580641557871,"mc":[{"id":"1.168219387","rc":[{"batb":[[1,2.12,5.04],[2,2.08,14.04]],"batl":[[1,2.24,306.02],[2,2.28,5.09]],"ltp":2.2,"tv":1082.28,"id":8535963},{"batl":[[1,1.88,22.04],[2,1.89,28.73]],"ltp":1.86,"tv":5026.72,"id":2309796}]}]}
{"op":"mcm","clk":"1005226309","pt":1580641562755,"mc":[{"id":"1.168219387","rc":[{"batb":[[0,2.08,14.04],[1,2.06,39.49],[2,2.02,110.78]],"batl":[[0,2.24,4.98],[1,2.28,5.09],[2,2.3,31.93]],"ltp":2.2,"tv":1082.28,"id":8535963},{"batb":[[0,1.83,494.03],[1,1.81,532.13],[2,1.79,21.31]],"batl":[[0,1.87,34.73],[1,1.89,21.5],[2,1.91,480.59]],"ltp":1.86,"tv":5026.72,"id":2309796}]}]}
{"op":"mcm","clk":"1005226563","pt":1580641563991,"mc":[{"id":"1.168219387","rc":[{"batb":[[1,2.02,110.78],[2,1.77,402.27]],"batl":[[2,2.46,4.25]],"ltp":2.2,"tv":1082.28,"id":8535963}]}]}
{"op":"mcm","clk":"1005226909","pt":1580641565698,"mc":[{"id":"1.168219387","rc":[{"batb":[[0,2.12,4.54],[1,2.08,14.04],[2,2.02,110.78]],"ltp":2.2,"tv":1082.28,"id":8535963},{"batl":[[1,1.88,19.04],[2,1.89,21.5]],"ltp":1.86,"tv":5026.72,"id":2309796}]}]}
{"op":"mcm","clk":"1005227131","pt":1580641566700,"mc":[{"id":"1.168219387","rc":[{"batl":[[2,3,213.45]],"ltp":2.2,"tv":1082.28,"id":8535963},{"batl":[[1,1.89,21.5],[2,1.95,199.19]],"ltp":1.86,"tv":5026.72,"id":2309796}]}]}
{"op":"mcm","clk":"1005227809","pt":1580641569478,"mc":[{"id":"1.168219387","rc":[{"trd":[[2.12,18.03]],"batb":[[0,2.08,14.04],[1,2.06,2.54]],"batl":[[0,2.16,660.64],[1,2.18,3.75],[2,2.22,85.18]],"ltp":2.12,"tv":1100.31,"id":8535963},{"trd":[[1.87,368.81],[1.88,10.09]],"batb":[[0,1.88,234.21],[1,1.87,110.54],[2,1.86,253.34]],"batl":[[0,1.89,21.5],[1,1.94,7.34]],"ltp":1.88,"tv":5106.27,"id":2309796}],"tv":6206.59}]}
{"op":"mcm","clk":"1005227937","pt":1580641570098,"mc":[{"id":"1.168219387","rc":[{"batb":[[0,1.88,304.16]],"ltp":1.88,"tv":5106.27,"id":2309796}]}]}
{"op":"mcm","clk":"1005228461","pt":1580641572619,"mc":[{"id":"1.168219387","rc":[{"batl":[[2,2.2,34.45]],"ltp":2.12,"tv":1100.31,"id":8535963}]}]}
{"op":"mcm","clk":"1005229881","pt":1580641579322,"mc":[{"id":"1.168219387","rc":[{"batl":[[1,1.95,199.19],[2,1.97,205.1]],"ltp":1.88,"tv":5106.27,"id":2309796}]}]}
{"op":"mcm","clk":"1005230503","pt":1580641582289,"mc":[{"id":"1.168219387","rc":[{"batl":[[0,2.16,674.2]],"ltp":2.12,"tv":1100.31,"id":8535963},{"batl":[[1,1.92,13],[2,1.95,199.19]],"ltp":1.88,"tv":5106.27,"id":2309796}]}]}
{"op":"mcm","clk":"1005231291","pt":1580641585918,"mc":[{"id":"1.168219387","rc":[{"trd":[[1.88,60.77]],"batb":[[0,1.88,278.81]],"ltp":1.88,"tv":5156.95,"id":2309796}],"tv":6257.27}]}
{"op":"mcm","clk":"1005232465","pt":1580641591620,"mc":[{"id":"1.168219387","rc":[{"trd":[[1.89,4]],"batl":[[0,1.89,19.5]],"ltp":1.89,"tv":5160.95,"id":2309796}],"tv":6261.27}]}
{"op":"mcm","clk":"1005232683","pt":1580641592735,"mc":[{"id":"1.168219387","rc":[{"trd":[[2.12,35.4]],"batl":[[0,2.1,83.93],[1,2.16,674.2],[2,2.18,3.75]],"ltp":2.12,"tv":1117.68,"id":8535963},{"trd":[[1.89,23.5]],"batl":[[0,1.92,13],[1,1.95,199.19],[2,1.97,205.1]],"ltp":1.89,"tv":5180.45,"id":2309796}],"tv":6298.13}]}
{"op":"mcm","clk":"1005233503","pt":1580641596762,"mc":[{"id":"1.168219387","rc":[{"batb":[[1,2.02,110.78],[2,1.99,42.01]],"ltp":2.12,"tv":1117.68,"id":8535963}]}]}
{"op":"mcm","clk":"1005236782","pt":1580641613483,"mc":[{"id":"1.168219387","rc":[{"trd":[[2.1,0.91]],"batl":[[0,2.1,83.02]],"ltp":2.1,"tv":1118.59,"id":8535963},{"trd":[[1.9,1.01]],"ltp":1.9,"tv":5181.46,"id":2309796}],"tv":6300.06}]}
{"op":"mcm","clk":"1005241912","pt":1580641638034,"mc":[{"id":"1.168219387","rc":[{"trd":[[2.04,25.27],[2.08,51.58]],"batb":[[0,2.02,110.78],[1,1.99,42.01],[2,1.89,68.53]],"ltp":2.04,"tv":1183.93,"id":8535963},{"trd":[[1.92,13],[1.95,26.44]],"batl":[[0,1.95,172.75],[1,1.97,205.1],[2,1.98,478.31]],"ltp":1.95,"tv":5220.9,"id":2309796}],"tv":6404.83}]}
{"op":"mcm","clk":"1005242568","pt":1580641641496,"mc":[{"id":"1.168219387","rc":[{"batb":[[0,1.88,305.21]],"batl":[[0,1.95,198.19]],"ltp":1.95,"tv":5220.9,"id":2309796}]}]}
{"op":"mcm","clk":"1005243331","pt":1580641645214,"mc":[{"id":"1.168219387","rc":[{"trd":[[2.1,83.93]],"batl":[[0,2.16,674.2],[1,2.18,3.75],[2,2.2,34.45]],"ltp":2.1,"tv":1266.95,"id":8535963},{"trd":[[1.9,92.81]],"batl":[[0,1.89,6.99],[1,1.95,198.19],[2,1.97,205.1]],"ltp":1.9,"tv":5312.7,"id":2309796}],"tv":6579.65}]}
{"op":"mcm","clk":"1005243879","pt":1580641648126,"mc":[{"id":"1.168219387","rc":[{"batl":[[0,2.16,660.64]],"ltp":2.1,"tv":1266.95,"id":8535963}]}]}
{"op":"mcm","clk":"1005244593","pt":1580641651726,"mc":[{"id":"1.168219387","rc":[{"trd":[[2.12,41.63]],"batl":[[0,2.18,3.75],[1,2.2,34.45],[2,2.22,85.18]],"ltp":2.12,"tv":1273.18,"id":8535963},{"trd":[[1.89,30.49]],"batl":[[0,1.95,198.19],[1,1.97,205.1],[2,2.02,41.17]],"ltp":1.89,"tv":5319.69,"id":2309796}],"tv":6592.87}]}
{"op":"mcm","clk":"1005244787","pt":1580641652631,"mc":[{"id":"1.168219387","rc":[{"batb":[[0,1.89,68.53],[1,1.77,402.27],[2,1.5,113.58]],"batl":[[0,3,213.45],[1,1000,0.02],[2,2.22,0]],"ltp":2.12,"tv":1273.18,"id":8535963},{"trd":[[1.89,30.97]],"batb":[[0,1.89,187.12],[1,1.81,78.52],[2,1.55,20]],"batl":[[0,3,42.01],[1,7,2.27],[2,10,2.53]],"ltp":1.89,"tv":5320.17,"id":2309796}],"tv":6593.36}]}
{"op":"mcm","clk":"1005244881","pt":1580641653117,"mc":[{"id":"1.168219387","rc":[{"batb":[[0,1.81,78.52],[1,1.55,20],[2,1.4,75.73]],"ltp":1.89,"tv":5320.17,"id":2309796}]}]}
{"op":"mcm","clk":"1005245134","pt":1580641654334,"mc":[{"id":"1.168219387","rc":[{"batl":[[0,1.9,36.21],[1,3,42.01],[2,7,2.27]],"ltp":1.89,"tv":5320.17,"id":2309796}]}]}
{"op":"mcm","clk":"1005245319","pt":1580641655340,"mc":[{"id":"1.168219387","rc":[{"batb":[[0,1.97,20.17],[1,1.9,20.06],[2,1.89,68.53]],"batl":[[0,2.26,9.25],[1,2.3,8.75],[2,3,213.45]],"ltp":2.12,"tv":1273.18,"id":8535963},{"batb":[[1,1.8,34.73],[2,1.78,34.16]],"batl":[[0,1.9,36.95],[1,2.04,5.63],[2,2.12,5.71]],"ltp":1.89,"tv":5320.17,"id":2309796}]}]}
{"op":"mcm","clk":"1005245605","pt":1580641656729,"mc":[{"id":"1.168219387","rc":[{"trd":[[1.9,166.7]],"batb":[[0,1.91,132.94],[1,1.89,228.71],[2,1.81,78.52]],"batl":[[0,1.98,230.69],[1,2,196.04],[2,2.04,5.63]],"ltp":1.9,"tv":5394.06,"id":2309796}],"tv":6667.24}]}
{"op":"mcm","clk":"1005245700","pt":1580641657213,"mc":[{"id":"1.168219387","rc":[{"batb":[[0,1.81,78.52],[1,1.8,34.73],[2,1.78,34.16]],"batl":[[0,2.04,5.63],[1,2.12,5.71],[2,3,42.01]],"ltp":1.9,"tv":5394.06,"id":2309796}]}]}
{"op":"mcm","clk":"1005246215","pt":1580641659617,"mc":[{"id":"1.168219387","rc":[{"batb":[[0,1.83,374.73],[1,1.81,78.52],[2,1.8,34.73]],"ltp":1.9,"tv":5394.06,"id":2309796}]}]}
{"op":"mcm","clk":"1005246671","pt":1580641661749,"mc":[{"id":"1.168219387","rc":[{"batl":[[0,2.22,9.75],[1,2.26,9.25],[2,2.3,8.75]],"ltp":2.12,"tv":1273.18,"id":8535963},{"batb":[[1,1.82,35.14],[2,1.81,78.52]],"ltp":1.9,"tv":5394.06,"id":2309796}]}]}
{"op":"mcm","clk":"1005246846","pt":1580641662558,"mc":[{"id":"1.168219387","rc":[{"batb":[[1,1.82,202.91]],"batl":[[1,2.1,286.21],[2,2.12,171.16]],"ltp":1.9,"tv":5394.06,"id":2309796}]}]}
{"op":"mcm","clk":"1005247881","pt":1580641667640,"mc":[{"id":"1.168219387","rc":[{"batl":[[1,2.08,233.57],[2,2.1,286.21]],"ltp":1.9,"tv":5394.06,"id":2309796}]}]}
{"op":"mcm","clk":"1005248071","pt":1580641668744,"mc":[{"id":"1.168219387","rc":[{"batb":[[0,2,17.06],[1,1.97,20.17],[2,1.9,20.06]],"ltp":2.12,"tv":1273.18,"id":8535963},{"batl":[[0,2,16.63],[1,2.04,5.63],[2,2.08,233.57]],"ltp":1.9,"tv":5394.06,"id":2309796}]}]}
{"op":"mcm","clk":"1005248111","pt":1580641668962,"mc":[{"id":"1.168219387","rc":[{"batb":[[0,1.97,20.17],[1,1.9,20.06],[2,1.89,68.53]],"ltp":2.12,"tv":1273.18,"id":8535963},{"batl":[[0,2.04,5.63],[1,2.08,233.57],[2,2.1,286.21]],"ltp":1.9,"tv":5394.06,"id":2309796}]}]}
{"op":"mcm","clk":"1005249493","pt":1580641675686,"mc":[{"id":"1.168219387","rc":[{"batl":[[2,2.12,5.71]],"ltp":1.9,"tv":5394.06,"id":2309796}]}]}
{"op":"mcm","clk":"1005249808","pt":1580641677382,"mc":[{"id":"1.168219387","rc":[{"batl":[[0,2.26,9.25],[1,2.3,8.75],[2,3,213.45]],"ltp":2.12,"tv":1273.18,"id":8535963},{"batb":[[0,1.82,167.77],[1,1.81,78.52],[2,1.8,302.25]],"batl":[[1,2.12,5.71],[2,3,42.01]],"ltp":1.9,"tv":5394.06,"id":2309796}]}]}
{"op":"mcm","clk":"1005250072","pt":1580641678676,"mc":[{"id":"1.168219387","rc":[{"batb":[[0,1.98,304.27],[1,1.97,20.17],[2,1.9,20.06]],"batl":[[0,2.24,327.58],[1,2.26,9.25],[2,2.28,209]],"ltp":2.12,"tv":1273.18,"id":8535963},{"batl":[[0,1.86,14.66],[1,1.88,217.14],[2,1.9,427]],"ltp":1.9,"tv":5394.06,"id":2309796}]}]}
{"op":"mcm","clk":"1005250231","pt":1580641679465,"mc":[{"id":"1.168219387","rc":[{"batb":[[0,2.1,98.2],[1,2.06,39.49],[2,1.97,139.61]],"ltp":2.12,"tv":1273.18,"id":8535963}]}]}
{"op":"mcm","clk":"1005250385","pt":1580641680367,"mc":[{"id":"1.168219387","rc":[{"batb":[[0,2.12,2.6],[1,2.1,98.2],[2,2.06,39.49]],"ltp":2.12,"tv":1273.18,"id":8535963}]}]}
{"op":"mcm","clk":"1005250938","pt":1580641683093,"mc":[{"id":"1.168219387","rc":[{"batb":[[2,2.08,95.79]],"ltp":2.12,"tv":1273.18,"id":8535963}]}]}
{"op":"mcm","clk":"1005251445","pt":1580641685666,"mc":[{"id":"1.168219387","rc":[{"batb":[[2,2.08,100.85]],"batl":[[0,2.24,337.31]],"ltp":2.12,"tv":1273.18,"id":8535963},{"trd":[[1.82,956.54]],"batb":[[0,1.82,167.52],[1,1.81,114.81]],"batl":[[2,1.89,480.59]],"ltp":1.82,"tv":5394.56,"id":2309796}],"tv":6667.75}]}
{"op":"mcm","clk":"1005252933","pt":1580641693564,"mc":[{"id":"1.168219387","rc":[{"batb":[[1,2.06,45.57],[2,1.97,139.61]],"batl":[[0,2.24,9.73],[2,2.3,31.93]],"ltp":2.12,"tv":1273.18,"id":8535963},{"batb":[[0,1.81,36.29],[1,1.8,34.73],[2,1.79,197.58]],"batl":[[0,1.82,5],[1,1.89,480.59],[2,1.91,515.9]],"ltp":1.82,"tv":5394.56,"id":2309796}]}]}
{"op":"mcm","clk":"1005253024","pt":1580641694102,"mc":[{"id":"1.168219387","rc":[{"batb":[[1,2.06,6.08]],"batl":[[0,2.26,9.25],[1,3,213.45],[2,1000,0.02]],"ltp":2.12,"tv":1273.18,"id":8535963},{"batb":[[0,1.8,34.73],[1,1.79,197.58],[2,1.78,1013.83]],"ltp":1.82,"tv":5394.56,"id":2309796}]}]}
{"op":"mcm","clk":"1005254106","pt":1580641699713,"mc":[{"id":"1.168219387","rc":[{"trd":[[2.2,697.71]],"batb":[[1,2.08,5.06],[2,2.06,6.08]],"ltp":2.2,"tv":1277.32,"id":8535963},{"trd":[[1.82,961.54]],"batl":[[0,1.89,480.59],[1,1.91,515.9],[2,1.94,19.25]],"ltp":1.82,"tv":5399.56,"id":2309796}],"tv":6676.89}]}
{"op":"mcm","clk":"1005254299","pt":1580641700574,"mc":[{"id":"1.168219387","rc":[{"batb":[[1,2.06,6.08],[2,1.97,139.61]],"ltp":2.2,"tv":1277.32,"id":8535963},{"batb":[[0,1.83,275.44],[1,1.81,262.89],[2,1.8,34.73]],"batl":[[1,1.9,216.38],[2,1.91,515.9]],"ltp":1.82,"tv":5399.56,"id":2309796}]}]}
{"op":"mcm","clk":"1005254437","pt":1580641701282,"mc":[{"id":"1.168219387","rc":[{"batb":[[2,1.8,249.82]],"ltp":1.82,"tv":5399.56,"id":2309796}]}]}
{"op":"mcm","clk":"1005254917","pt":1580641703700,"mc":[{"id":"1.168219387","rc":[{"batl":[[0,2.24,9.73],[1,2.26,9.25],[2,3,213.45]],"ltp":2.2,"tv":1277.32,"id":8535963},{"batb":[[0,1.81,36.29],[1,1.8,249.82],[2,1.79,197.58]],"batl":[[1,1.91,515.9],[2,1.94,19.25]],"ltp":1.82,"tv":5399.56,"id":2309796}]}]}
{"op":"mcm","clk":"1005254951","pt":1580641703899,"mc":[{"id":"1.168219387","rc":[{"batl":[[0,2.26,9.25],[1,3,213.45],[2,1000,0.02]],"ltp":2.2,"tv":1277.32,"id":8535963},{"batb":[[0,1.8,249.82],[1,1.79,197.58],[2,1.78,1013.83]],"ltp":1.82,"tv":5399.56,"id":2309796}]}]}
{"op":"mcm","clk":"1005255504","pt":1580641706720,"mc":[{"id":"1.168219387","rc":[{"batb":[[1,2.08,5.31],[2,2.06,6.08]],"ltp":2.2,"tv":1277.32,"id":8535963}]}]}
{"op":"mcm","clk":"1005255693","pt":1580641707580,"mc":[{"id":"1.168219387","rc":[{"batb":[[1,2.06,6.08],[2,1.97,139.61]],"ltp":2.2,"tv":1277.32,"id":8535963}]}]}
{"op":"mcm","clk":"1005255919","pt":1580641708594,"mc":[{"id":"1.168219387","rc":[{"batb":[[0,2.06,6.08],[1,1.97,139.61],[2,1.9,20.06]],"ltp":2.2,"tv":1277.32,"id":8535963},{"batb":[[0,1.8,34.73],[1,1.78,34.16],[2,1.77,284.46]],"ltp":1.82,"tv":5399.56,"id":2309796}]}]}
{"op":"mcm","clk":"1005255968","pt":1580641708803,"mc":[{"id":"1.168219387","rc":[{"batb":[[1,1.77,284.46],[2,1.75,293.83]],"ltp":1.82,"tv":5399.56,"id":2309796}]}]}
{"op":"mcm","clk":"1005256340","pt":1580641710685,"mc":[{"id":"1.168219387","rc":[{"batb":[[0,2.2,98.37],[1,2.16,91.73],[2,2.06,6.08]],"batl":[[1,2.32,252.49],[2,2.36,161]],"ltp":2.2,"tv":1277.32,"id":8535963},{"trd":[[1.8,87.63],[1.81,226.53]],"batb":[[0,1.8,20.64],[2,1.76,9.87]],"batl":[[0,1.83,244.68],[1,1.84,210],[2,1.85,248.8]],"ltp":1.81,"tv":5449.3,"id":2309796}],"tv":6726.63}]}
{"op":"mcm","clk":"1005256536","pt":1580641711698,"mc":[{"id":"1.168219387","rc":[{"batb":[[0,2.2,100.93],[1,2.16,181.11],[2,2.12,36.97]],"batl":[[2,2.36,191.25]],"ltp":2.2,"tv":1277.32,"id":8535963}]}]}
{"op":"mcm","clk":"1005257371","pt":1580641715511,"mc":[{"id":"1.168219387","rc":[{"trd":[[2.26,9.25]],"batl":[[0,2.32,252.49],[1,2.36,191.25],[2,3,213.45]],"ltp":2.26,"tv":1286.57,"id":8535963},{"trd":[[1.79,12.68],[1.8,128.91]],"batb":[[0,1.77,284.46],[1,1.76,384.6],[2,1.75,293.83]],"batl":[[0,1.79,51.7],[1,1.83,244.68],[2,1.84,210]],"ltp":1.79,"tv":5502.27,"id":2309796}],"tv":6788.84}]}
{"op":"mcm","clk":"1005257834","pt":1580641717710,"mc":[{"id":"1.168219387","rc":[{"batb":[[1,2.16,186.14],[2,2.14,5.32]],"batl":[[0,2.28,5.59],[1,2.32,252.49],[2,2.36,191.25]],"ltp":2.26,"tv":1286.57,"id":8535963},{"batb":[[0,1.79,23.31],[1,1.77,284.46],[2,1.76,878.63]],"batl":[[0,1.83,244.68],[1,1.84,210],[2,1.85,269.7]],"ltp":1.79,"tv":5502.27,"id":2309796}]}]}
{"op":"mcm","clk":"1005257993","pt":1580641718709,"mc":[{"id":"1.168219387","rc":[{"batl":[[1,2.32,256.35],[2,2.34,4.75]],"ltp":2.26,"tv":1286.57,"id":8535963},{"batb":[[2,1.76,903.11]],"ltp":1.79,"tv":5502.27,"id":2309796}]}]}
{"op":"mcm","clk":"1005258363","pt":1580641720584,"mc":[{"id":"1.168219387","rc":[{"batb":[[2,1.76,893.24]],"ltp":1.79,"tv":5502.27,"id":2309796}]}]}
{"op":"mcm","clk":"1005258563","pt":1580641721503,"mc":[{"id":"1.168219387","rc":[{"batl":[[1,2.3,4.95],[2,2.32,256.35]],"ltp":2.26,"tv":1286.57,"id":8535963},{"batb":[[1,1.78,24.66],[2,1.77,306.83]],"ltp":1.79,"tv":5502.27,"id":2309796}]}]}
{"op":"mcm","clk":"1005258762","pt":1580641722627,"mc":[{"id":"1.168219387","rc":[{"batb":[[0,2.2,2.56],[1,2.14,5.32],[2,2.12,36.97]],"batl":[[0,2.32,3.86],[1,2.34,4.75],[2,2.36,30.25]],"ltp":2.26,"tv":1286.57,"id":8535963},{"batb":[[0,1.78,24.66],[1,1.76,893.24],[2,1.75,24.47]],"batl":[[0,1.86,480.59],[1,1.87,18.73],[2,1.88,515.94]],"ltp":1.79,"tv":5502.27,"id":2309796}]}]}
{"op":"mcm","clk":"1005259036","pt":1580641724110,"mc":[{"id":"1.168219387","rc":[{"batb":[[2,2.06,109.86]],"batl":[[2,3,213.45]],"ltp":2.26,"tv":1286.57,"id":8535963}]}]}
{"op":"mcm","clk":"1005259348","pt":1580641725712,"mc":[{"id":"1.168219387","rc":[{"batb":[[1,2.16,5.28],[2,2.14,5.32]],"batl":[[0,2.28,4.59],[1,2.3,3.95],[2,2.32,3.86]],"ltp":2.26,"tv":1286.57,"id":8535963},{"batb":[[0,1.79,23.31],[1,1.78,24.66],[2,1.76,893.24]],"ltp":1.79,"tv":5502.27,"id":2309796}]}]}
{"op":"mcm","clk":"1005259410","pt":1580641726036,"mc":[{"id":"1.168219387","rc":[{"batb":[[1,2.14,5.32],[2,2.06,109.86]],"batl":[[0,2.3,3.95],[1,2.32,3.86],[2,2.34,4.75]],"ltp":2.26,"tv":1286.57,"id":8535963},{"batb":[[0,1.78,24.66],[1,1.76,893.24],[2,1.75,24.47]],"ltp":1.79,"tv":5502.27,"id":2309796}]}]}
{"op":"mcm","clk":"1005260638","pt":1580641732632,"mc":[{"id":"1.168219387","rc":[{"batb":[[1,2.16,4.78],[2,2.14,5.32]],"batl":[[0,2.28,5.34],[1,2.3,3.95],[2,2.32,3.86]],"ltp":2.26,"tv":1286.57,"id":8535963},{"batb":[[0,1.79,24.31],[1,1.78,24.66],[2,1.76,893.24]],"ltp":1.79,"tv":5502.27,"id":2309796}]}]}
{"op":"mcm","clk":"1005260707","pt":1580641733017,"mc":[{"id":"1.168219387","rc":[{"batb":[[1,2.14,5.32],[2,2.06,109.86]],"batl":[[0,2.3,3.95],[1,2.32,3.86],[2,2.34,4.75]],"ltp":2.26,"tv":1286.57,"id":8535963},{"batb":[[0,1.78,24.66],[1,1.76,893.24],[2,1.75,24.47]],"ltp":1.79,"tv":5502.27,"id":2309796}]}]}
{"op":"mcm","clk":"1005261782","pt":1580641738718,"mc":[{"id":"1.168219387","rc":[{"batb":[[0,2.14,5.32],[1,2.06,109.86],[2,1.97,20.17]],"ltp":2.26,"tv":1286.57,"id":8535963}]}]}
{"op":"mcm","clk":"1005261973","pt":1580641739617,"mc":[{"id":"1.168219387","rc":[{"batl":[[0,1.85,23.3],[1,1.86,480.59],[2,1.87,18.73]],"ltp":1.79,"tv":5502.27,"id":2309796}]}]}
{"op":"mcm","clk":"1005262204","pt":1580641740706,"mc":[{"id":"1.168219387","rc":[{"batl":[[0,1.86,480.59],[1,1.87,18.73],[2,1.88,515.94]],"ltp":1.79,"tv":5502.27,"id":2309796}]}]}
{"op":"mcm","clk":"1005262370","pt":1580641741710,"mc":[{"id":"1.168219387","rc":[{"batb":[[1,1.76,24.48]],"ltp":1.79,"tv":5502.27,"id":2309796}]}]}
{"op":"mcm","clk":"1005262467","pt":1580641742204,"mc":[{"id":"1.168219387","rc":[{"batl":[[1,3,213.45],[2,1000,0.02]],"ltp":2.26,"tv":1286.57,"id":8535963},{"batb":[[1,1.73,318.14],[2,1.72,92.61]],"ltp":1.79,"tv":5502.27,"id":2309796}]}]}
{"op":"mcm","clk":"1005262758","pt":1580641743694,"mc":[{"id":"1.168219387","rc":[{"batl":[[1,2.44,171],[2,3,213.45]],"ltp":2.26,"tv":1286.57,"id":8535963},{"trd":[[1.78,1845.45]],"batb":[[0,1.78,11.88],[1,1.74,12.05],[2,1.73,318.14]],"batl":[[0,1.79,183.11],[1,1.8,700.88],[2,1.81,266.9]],"ltp":1.78,"tv":5527.83,"id":2309796}],"tv":6814.4}]}
{"op":"mcm","clk":"1005262942","pt":1580641744587,"mc":[{"id":"1.168219387","rc":[{"batb":[[0,2.24,82.22],[1,2.2,2.61],[2,2.14,98.09]],"ltp":2.26,"tv":1286.57,"id":8535963},{"batb":[[1,1.74,14.74]],"ltp":1.78,"tv":5527.83,"id":2309796}]}]}
{"op":"mcm","clk":"1005263098","pt":1580641745335,"mc":[{"id":"1.168219387","rc":[{"batb":[[2,2.18,35.29]],"batl":[[1,2.42,29.41],[2,2.44,171]],"ltp":2.26,"tv":1286.57,"id":8535963}]}]}
{"op":"mcm","clk":"1005264051","pt":1580641750235,"mc":[{"id":"1.168219387","rc":[{"batb":[[1,1.74,508.77]],"ltp":1.78,"tv":5527.83,"id":2309796}]}]}
{"op":"mcm","clk":"1005264216","pt":1580641751128,"mc":[{"id":"1.168219387","rc":[{"trd":[[2.26,11.25]],"batb":[[1,2.22,5.34],[2,2.2,7.78]],"ltp":2.26,"tv":1288.57,"id":8535963},{"trd":[[1.79,15.21]],"batb":[[1,1.77,23.37],[2,1.74,508.77]],"batl":[[0,1.79,180.58],[2,1.81,289.61]],"ltp":1.79,"tv":5530.36,"id":2309796}],"tv":6818.93}]}
{"op":"mcm","clk":"1005264717","pt":1580641753641,"mc":[{"id":"1.168219387","rc":[{"batb":[[2,1.74,496.72]],"ltp":1.79,"tv":5530.36,"id":2309796}]}]}
{"op":"mcm","clk":"1005265143","pt":1580641755701,"mc":[{"id":"1.168219387","rc":[{"batl":[[2,3,213.45]],"ltp":2.26,"tv":1288.57,"id":8535963},{"batl":[[0,1.8,107.67],[1,1.81,22.71],[2,1.82,21.75]],"ltp":1.79,"tv":5530.36,"id":2309796}]}]}
{"op":"mcm","clk":"1005265311","pt":1580641756606,"mc":[{"id":"1.168219387","rc":[{"batb":[[0,2.2,2.61],[1,2.14,98.09],[2,2.06,6.08]],"batl":[[0,3,213.45],[1,1000,0.02],[2,3,0]],"ltp":2.26,"tv":1288.57,"id":8535963},{"batb":[[0,1.77,23.37],[1,1.74,496.72],[2,1.73,178.12]],"batl":[[0,1.82,21.75],[1,1.83,480.59],[2,1.85,497.4]],"ltp":1.79,"tv":5530.36,"id":2309796}]}]}
{"op":"mcm","clk":"1005265703","pt":1580641758719,"mc":[{"id":"1.168219387","rc":[{"batl":[[2,1.84,258.02]],"ltp":1.79,"tv":5530.36,"id":2309796}]}]}
{"op":"mcm","clk":"1005265855","pt":1580641759421,"mc":[{"id":"1.168219387","rc":[{"batb":[[0,2.2,7.73]],"batl":[[0,2.3,4.45],[1,3,213.45],[2,1000,0.02]],"ltp":2.26,"tv":1288.57,"id":8535963}]}]}
{"op":"mcm","clk":"1005266093","pt":1580641760736,"mc":[{"id":"1.168219387","rc":[{"batb":[[1,1.75,232.73],[2,1.74,496.72]],"ltp":1.79,"tv":5530.36,"id":2309796}]}]}
{"op":"mcm","clk":"1005266433","pt":1580641762636,"mc":[{"id":"1.168219387","rc":[{"batb":[[0,2.22,5.34],[1,2.2,7.73],[2,2.14,98.09]],"ltp":2.26,"tv":1288.57,"id":8535963},{"batl":[[0,1.81,20.5],[1,1.82,21.75],[2,1.83,480.59]],"ltp":1.79,"tv":5530.36,"id":2309796}]}]}
{"op":"mcm","clk":"1005266632","pt":1580641763535,"mc":[{"id":"1.168219387","rc":[{"batb":[[0,2.2,7.73],[1,2.14,98.09],[2,2.06,6.08]],"ltp":2.26,"tv":1288.57,"id":8535963},{"batb":[[1,1.71,318.31],[2,1.7,98.04]],"batl":[[0,1.82,21.75],[1,1.83,480.59],[2,1.85,497.4]],"ltp":1.79,"tv":5530.36,"id":2309796}]}]}
{"op":"mcm","clk":"1005266778","pt":1580641764241,"mc":[{"id":"1.168219387","rc":[{"batl":[[1,1000,0.02],[2,1000,0]],"ltp":2.26,"tv":1288.57,"id":8535963}]}]}
{"op":"mcm","clk":"1005267074","pt":1580641765723,"mc":[{"id":"1.168219387","rc":[{"batb":[[0,2.24,2],[1,2.2,7.73],[2,2.18,92.53]],"batl":[[0,2.36,7.73],[1,2.46,342.68],[2,2.5,182]],"ltp":2.26,"tv":1288.57,"id":8535963},{"trd":[[1.77,114.64]],"batb":[[0,1.71,318.31],[1,1.7,98.04],[2,1.69,332.17]],"batl":[[0,1.77,413.25],[1,1.78,17.16],[2,1.79,276.63]],"ltp":1.77,"tv":5577.1,"id":2309796}],"tv":6865.67}]}
{"op":"mcm","clk":"1005267266","pt":1580641766632,"mc":[{"id":"1.168219387","rc":[{"batb":[[0,2.28,77.27],[1,2.24,2],[2,2.2,7.73]],"ltp":2.26,"tv":1288.57,"id":8535963}]}]}
{"op":"mcm","clk":"1005267464","pt":1580641767425,"mc":[{"id":"1.168219387","rc":[{"batb":[[1,2.24,35.61]],"batl":[[2,2.5,209.73]],"ltp":2.26,"tv":1288.57,"id":8535963}]}]}
{"op":"mcm","clk":"1005268437","pt":1580641772411,"mc":[{"id":"1.168219387","rc":[{"batb":[[2,2.2,5.12]],"ltp":2.26,"tv":1288.57,"id":8535963}]}]}
{"op":"mcm","clk":"1005271397","pt":1580641787514,"mc":[{"id":"1.168219387","rc":[{"batb":[[0,1.76,5],[1,1.71,318.31],[2,1.7,98.04]],"ltp":1.77,"tv":5577.1,"id":2309796}]}]}
{"op":"mcm","clk":"1005272140","pt":1580641791646,"mc":[{"id":"1.168219387","rc":[{"batb":[[0,2.24,33.61],[1,2.18,88.83],[2,2.14,5.32]],"batl":[[0,2.5,27.73],[1,2.52,4.26],[2,2.6,3.71]],"ltp":2.26,"tv":1288.57,"id":8535963},{"batb":[[1,1.66,92.79],[2,1.63,32.23]],"batl":[[0,1.8,42.01],[1,1.87,18.73],[2,1.88,18.54]],"ltp":1.77,"tv":5577.1,"id":2309796}]}]}
{"op":"mcm","clk":"1005272259","pt":1580641792209,"mc":[{"id":"1.168219387","rc":[{"batb":[[0,2.18,88.83],[1,2.14,5.32],[2,2.06,6.08]],"batl":[[0,2.52,4.26],[1,2.6,3.71],[2,3.45,180.4]],"ltp":2.26,"tv":1288.57,"id":8535963},{"batb":[[1,1.66,29.78]],"batl":[[0,1.87,18.73],[1,1.88,18.54],[2,1.91,18.5]],"ltp":1.77,"tv":5577.1,"id":2309796}]}]}
{"op":"mcm","clk":"1005272705","pt":1580641794597,"mc":[{"id":"1.168219387","rc":[{"batl":[[2,2.62,3.25]],"ltp":2.26,"tv":1288.57,"id":8535963}]}]}
{"op":"mcm","clk":"1005273039","pt":1580641796403,"mc":[{"id":"1.168219387","rc":[{"trd":[[1.76,48.65]],"batb":[[0,1.69,330.04],[1,1.67,345.92],[2,1.66,29.78]],"batl":[[0,1.75,227.78],[1,1.77,286.91],[2,1.87,18.73]],"ltp":1.76,"tv":5587.1,"id":2309796}],"tv":6875.67}]}
{"op":"mcm","clk":"1005273305","pt":1580641797733,"mc":[{"id":"1.168219387","rc":[{"batb":[[0,2.32,19.39],[1,2.18,88.83],[2,2.14,5.32]],"batl":[[0,2.36,20.32],[1,2.52,4.26],[2,2.6,3.71]],"ltp":2.26,"tv":1288.57,"id":8535963},{"batb":[[0,1.73,21.13],[1,1.69,330.04],[2,1.67,345.92]],"batl":[[1,1.76,19.77],[2,1.77,286.91]],"ltp":1.76,"tv":5587.1,"id":2309796}]}]}
{"op":"mcm","clk":"1005273404","pt":1580641798316,"mc":[{"id":"1.168219387","rc":[{"batb":[[0,2.18,94.19],[1,2.14,5.32],[2,2.06,6.08]],"batl":[[0,2.52,4.26],[1,2.6,3.71],[2,2.62,3.25]],"ltp":2.26,"tv":1288.57,"id":8535963},{"batb":[[0,1.69,330.04],[1,1.67,345.92],[2,1.66,29.78]],"batl":[[1,1.77,286.91],[2,1.84,224.95]],"ltp":1.76,"tv":5587.1,"id":2309796}]}]}
{"op":"mcm","clk":"1005273667","pt":1580641799698,"mc":[{"id":"1.168219387","rc":[{"batl":[[0,2.62,3.25],[1,3.45,180.4],[2,1000,0.02]],"ltp":2.26,"tv":1288.57,"id":8535963},{"batb":[[0,1.62,269.36],[1,1.59,121.72],[2,1.55,20]],"batl":[[2,1.83,178.12]],"ltp":1.76,"tv":5587.1,"id":2309796}]}]}
{"op":"mcm","clk":"1005273801","pt":1580641800540,"mc":[{"id":"1.168219387","rc":[{"batl":[[0,1.83,178.12],[1,1.84,224.95],[2,1.87,18.73]],"ltp":1.76,"tv":5587.1,"id":2309796}]}]}
{"op":"mcm","clk":"1005274192","pt":1580641802576,"mc":[{"id":"1.168219387","rc":[{"batl":[[0,2.52,3.76],[1,2.62,3.25],[2,3.45,180.4]],"ltp":2.26,"tv":1288.57,"id":8535963},{"batb":[[0,1.66,25.78],[1,1.62,269.36],[2,1.59,121.72]],"ltp":1.76,"tv":5587.1,"id":2309796}]}]}
{"op":"mcm","clk":"1005274346","pt":1580641803451,"mc":[{"id":"1.168219387","rc":[{"batl":[[0,2.62,3.25],[1,3.45,180.4],[2,1000,0.02]],"ltp":2.26,"tv":1288.57,"id":8535963},{"batb":[[0,1.62,510.68],[1,1.61,198.51]],"batl":[[1,1.84,462.51],[2,1.86,244.47]],"ltp":1.76,"tv":5587.1,"id":2309796}]}]}
{"op":"mcm","clk":"1005274612","pt":1580641804836,"mc":[{"id":"1.168219387","rc":[{"batb":[[0,1.62,269.36],[1,1.59,121.72],[2,1.55,20]],"ltp":1.76,"tv":5587.1,"id":2309796}]}]}
{"op":"mcm","clk":"1005274947","pt":1580641806762,"mc":[{"id":"1.168219387","rc":[{"batl":[[0,1.84,462.51],[1,1.86,244.47],[2,1.87,18.73]],"ltp":1.76,"tv":5587.1,"id":2309796}]}]}
{"op":"mcm","clk":"1005275119","pt":1580641807739,"mc":[{"id":"1.168219387","rc":[{"batl":[[0,2.24,7.64],[1,2.3,95.22],[2,2.36,184]],"ltp":2.26,"tv":1288.57,"id":8535963},{"batb":[[0,1.75,111.01],[1,1.74,587.62],[2,1.62,269.36]],"batl":[[0,1.84,439.34],[1,1.86,762.64]],"ltp":1.76,"tv":5587.1,"id":2309796}]}]}
{"op":"mcm","clk":"1005275332","pt":1580641808755,"mc":[{"id":"1.168219387","rc":[{"batb":[[2,2.12,2.62]],"ltp":2.26,"tv":1288.57,"id":8535963},{"batb":[[0,1.8,2.57],[1,1.78,193.48],[2,1.76,374.37]],"ltp":1.76,"tv":5587.1,"id":2309796}]}]}
{"op":"mcm","clk":"1005275393","pt":1580641809178,"mc":[{"id":"1.168219387","rc":[{"batb":[[1,2.14,41.45]],"ltp":2.26,"tv":1288.57,"id":8535963},{"batl":[[1,1.86,804.65]],"ltp":1.76,"tv":5587.1,"id":2309796}]}]}
{"op":"mcm","clk":"1005275881","pt":1580641811642,"mc":[{"id":"1.168219387","rc":[{"batb":[[0,2.18,88.83]],"ltp":2.26,"tv":1288.57,"id":8535963},{"batl":[[0,1.84,418.56]],"ltp":1.76,"tv":5587.1,"id":2309796}]}]}
{"op":"mcm","clk":"1005276451","pt":1580641814656,"mc":[{"id":"1.168219387","rc":[{"batb":[[2,1.77,494.03]],"ltp":1.76,"tv":5587.1,"id":2309796}]}]}
{"op":"mcm","clk":"1005276618","pt":1580641815453,"mc":[{"id":"1.168219387","rc":[{"batb":[[2,2.12,8.66]],"batl":[[1,2.3,99.87],[2,2.34,4.75]],"ltp":2.26,"tv":1288.57,"id":8535963},{"batb":[[2,1.77,517.4]],"ltp":1.76,"tv":5587.1,"id":2309796}]}]}
{"op":"mcm","clk":"1005277923","pt":1580641822746,"mc":[{"id":"1.168219387","rc":[{"batl":[[0,2.3,99.87],[1,2.34,4.75],[2,2.4,29.41]],"ltp":2.26,"tv":1288.57,"id":8535963},{"batl":[[0,1.84,237.56],[1,1.86,286.48]],"ltp":1.76,"tv":5587.1,"id":2309796}]}]}
{"op":"mcm","clk":"1005278060","pt":1580641823453,"mc":[{"id":"1.168219387","rc":[{"batb":[[0,2.14,36.13],[1,2.12,8.66],[2,2.1,98.67]],"batl":[[0,2.3,4.65]],"ltp":2.26,"tv":1288.57,"id":8535963},{"batb":[[1,1.77,517.4],[2,1.75,534.59]],"batl":[[0,1.86,42.01],[1,1.88,499.13],[2,1.89,234.59]],"ltp":1.76,"tv":5587.1,"id":2309796}]}]}
{"op":"mcm","clk":"1005278185","pt":1580641824180,"mc":[{"id":"1.168219387","rc":[{"batb":[[0,2.12,8.66],[1,2.1,98.67],[2,2.06,6.08]],"batl":[[2,2.62,3.25]],"ltp":2.26,"tv":1288.57,"id":8535963},{"batl":[[0,1.88,499.13],[1,1.89,234.59],[2,1.9,497.4]],"ltp":1.76,"tv":5587.1,"id":2309796}]}]}
{"op":"mcm","clk":"1005278644","pt":1580641826685,"mc":[{"id":"1.168219387","rc":[{"batb":[[0,2.14,5.82],[1,2.12,8.66],[2,2.1,98.67]],"ltp":2.26,"tv":1288.57,"id":8535963},{"batl":[[0,1.87,21.5],[1,1.88,499.13],[2,1.89,389.67]],"ltp":1.76,"tv":5587.1,"id":2309796}]}]}
{"op":"mcm","clk":"1005278679","pt":1580641826891,"mc":[{"id":"1.168219387","rc":[{"batb":[[0,2.12,8.66],[1,2.1,98.67],[2,2.06,6.08]],"ltp":2.26,"tv":1288.57,"id":8535963},{"batl":[[0,1.88,499.13],[1,1.89,389.67],[2,1.9,497.4]],"ltp":1.76,"tv":5587.1,"id":2309796}]}]}
{"op":"mcm","clk":"1005278888","pt":1580641828170,"mc":[{"id":"1.168219387","rc":[{"batl":[[1,1.89,174.58]],"ltp":1.76,"tv":5587.1,"id":2309796}]}]}
{"op":"mcm","clk":"1005279156","pt":1580641829593,"mc":[{"id":"1.168219387","rc":[{"batl":[[0,1.89,174.58],[1,1.91,243.63],[2,1.94,19.25]],"ltp":1.76,"tv":5587.1,"id":2309796}]}]}
{"op":"mcm","clk":"1005279364","pt":1580641830679,"mc":[{"id":"1.168219387","rc":[{"batb":[[0,2.12,6.04]],"ltp":2.26,"tv":1288.57,"id":8535963}]}]}
{"op":"mcm","clk":"1005279715","pt":1580641832549,"mc":[{"id":"1.168219387","rc":[{"batl":[[0,2.16,10.99],[1,2.22,93.65],[2,2.24,371.84]],"ltp":2.26,"tv":1288.57,"id":8535963},{"batb":[[0,1.84,107.39],[1,1.83,220.97],[2,1.81,262.49]],"batl":[[0,1.87,100],[1,1.89,174.58],[2,1.91,442.63]],"ltp":1.76,"tv":5587.1,"id":2309796}]}]}
{"op":"mcm","clk":"1005279820","pt":1580641833130,"mc":[{"id":"1.168219387","rc":[{"batb":[[2,2.08,38.65]],"ltp":2.26,"tv":1288.57,"id":8535963},{"batb":[[2,1.82,78.21]],"ltp":1.76,"tv":5587.1,"id":2309796}]}]}
{"op":"mcm","clk":"1005281075","pt":1580641839765,"mc":[{"id":"1.168219387","rc":[{"batb":[[1,2.1,104.31]],"batl":[[1,2.22,98.9],[2,2.24,376.32]],"ltp":2.26,"tv":1288.57,"id":8535963},{"batb":[[1,1.83,244]],"batl":[[2,1.9,18.65]],"ltp":1.76,"tv":5587.1,"id":2309796}]}]}
{"op":"mcm","clk":"1005282319","pt":1580641846269,"mc":[{"id":"1.168219387","rc":[{"batl":[[0,1.89,174.58],[1,1.9,18.65],[2,1.91,620.75]],"ltp":1.76,"tv":5587.1,"id":2309796}]}]}
{"op":"mcm","clk":"1005282777","pt":1580641848674,"mc":[{"id":"1.168219387","rc":[{"batl":[[0,2.22,98.9],[1,2.24,4.48],[2,2.3,4.65]],"ltp":2.26,"tv":1288.57,"id":8535963},{"batb":[[1,1.83,23.03]],"batl":[[0,1.89,19.5],[2,1.91,196.62]],"ltp":1.76,"tv":5587.1,"id":2309796}]}]}
{"op":"mcm","clk":"1005282913","pt":1580641849357,"mc":[{"id":"1.168219387","rc":[{"trd":[[2.2,787.53],[2.22,48.38]],"batb":[[0,2.08,38.65],[1,2.06,6.08],[2,2.04,107.95]],"batl":[[0,2.22,69.58]],"ltp":2.22,"tv":1426.53,"id":8535963},{"trd":[[1.84,685.47]],"batb":[[0,1.81,23.29],[1,1.77,23.37],[2,1.76,54.61]],"batl":[[0,1.91,196.62],[1,1.92,42.01],[2,1.93,100]],"ltp":1.84,"tv":5694.49,"id":2309796}],"tv":7121.02}]}
{"op":"mcm","clk":"1005283069","pt":1580641850165,"mc":[{"id":"1.168219387","rc":[{"batb":[[0,2.06,6.08],[1,2.04,107.95],[2,1.97,20.17]],"ltp":2.22,"tv":1426.53,"id":8535963},{"batb":[[2,1.75,23.75]],"batl":[[1,1.93,100],[2,1.94,19.25]],"ltp":1.84,"tv":5694.49,"id":2309796}]}]}
{"op":"mcm","clk":"1005283367","pt":1580641851580,"mc":[{"id":"1.168219387","rc":[{"batb":[[0,2.08,5.81],[1,2.06,6.08],[2,2.04,107.95]],"ltp":2.22,"tv":1426.53,"id":8535963},{"batb":[[2,1.76,283.53]],"batl":[[2,1.94,257.37]],"ltp":1.84,"tv":5694.49,"id":2309796}]}]}
{"op":"mcm","clk":"1005283595","pt":1580641852758,"mc":[{"id":"1.168219387","rc":[{"batb":[[0,2.1,5.64],[1,2.08,5.81],[2,2.06,6.08]],"ltp":2.22,"tv":1426.53,"id":8535963},{"batb":[[2,1.75,23.75]],"batl":[[0,1.9,20.45],[1,1.91,196.62],[2,1.93,100]],"ltp":1.84,"tv":5694.49,"id":2309796}]}]}
{"op":"mcm","clk":"1005283616","pt":1580641852859,"mc":[{"id":"1.168219387","rc":[{"batl":[[1,1.91,18.5]],"ltp":1.84,"tv":5694.49,"id":2309796}]}]}
{"op":"mcm","clk":"1005283926","pt":1580641854596,"mc":[{"id":"1.168219387","rc":[{"batl":[[0,2.16,304.06],[1,2.18,152],[2,2.22,69.58]],"ltp":2.22,"tv":1426.53,"id":8535963},{"trd":[[1.9,183.66]],"batl":[[0,1.9,11.97]],"ltp":1.9,"tv":5711.45,"id":2309796}],"tv":7137.98}]}
{"op":"mcm","clk":"1005284137","pt":1580641855721,"mc":[{"id":"1.168219387","rc":[{"batb":[[0,1.87,275.85],[1,1.85,247.11],[2,1.81,23.29]],"ltp":1.9,"tv":5711.45,"id":2309796}]}]}
{"op":"mcm","clk":"1005284375","pt":1580641857072,"mc":[{"id":"1.168219387","rc":[{"batl":[[2,2.24,4.48]],"ltp":2.22,"tv":1426.53,"id":8535963}]}]}
{"op":"mcm","clk":"1005284807","pt":1580641859390,"mc":[{"id":"1.168219387","rc":[{"batl":[[2,1.93,294.93]],"ltp":1.9,"tv":5711.45,"id":2309796}]}]}
{"op":"mcm","clk":"1005285466","pt":1580641862722,"mc":[{"id":"1.168219387","rc":[{"batb":[[0,2.06,6.08],[1,2.04,43.02],[2,2,115.19]],"batl":[[0,2.16,4.72],[1,2.18,5.25]],"ltp":2.22,"tv":1426.53,"id":8535963},{"batb":[[0,1.87,22.27],[1,1.86,21.18],[2,1.85,2.67]],"batl":[[0,1.91,18.5],[1,1.93,294.93],[2,1.94,19.25]],"ltp":1.9,"tv":5711.45,"id":2309796}]}]}
{"op":"mcm","clk":"1005285590","pt":1580641863416,"mc":[{"id":"1.168219387","rc":[{"batl":[[0,2.18,5.25],[1,2.26,32.77],[2,2.3,4.65]],"ltp":2.22,"tv":1426.53,"id":8535963},{"batb":[[0,1.86,21.18],[1,1.85,2.67],[2,1.82,215.09]],"ltp":1.9,"tv":5711.45,"id":2309796}]}]}
{"op":"mcm","clk":"1005285741","pt":1580641864217,"mc":[{"id":"1.168219387","rc":[{"batb":[[1,2.04,2.69]],"batl":[[1,2.3,4.65],[2,2.34,4.75]],"ltp":2.22,"tv":1426.53,"id":8535963},{"batb":[[2,1.82,430.18]],"ltp":1.9,"tv":5711.45,"id":2309796}]}]}
{"op":"mcm","clk":"1005285988","pt":1580641865638,"mc":[{"id":"1.168219387","rc":[{"batb":[[0,2.1,4.54],[1,2.08,5.31],[2,2.06,6.08]],"ltp":2.22,"tv":1426.53,"id":8535963},{"batb":[[2,1.82,690.89]],"batl":[[0,1.87,1.68],[1,1.9,20.65],[2,1.91,18.5]],"ltp":1.9,"tv":5711.45,"id":2309796}]}]}
{"op":"mcm","clk":"1005286137","pt":1580641866434,"mc":[{"id":"1.168219387","rc":[{"trd":[[2.16,16.09]],"batb":[[0,2.08,5.31],[1,2.06,6.08],[2,2.04,2.69]],"ltp":2.16,"tv":1438.07,"id":8535963},{"trd":[[1.87,370.09]],"batb":[[0,1.87,17.99],[1,1.86,21.18],[2,1.85,2.67]],"batl":[[0,1.91,18.5],[1,1.93,294.93],[2,1.94,19.25]],"ltp":1.87,"tv":5712.73,"id":2309796}],"tv":7150.81}]}
{"op":"mcm","clk":"1005286620","pt":1580641869053,"mc":[{"id":"1.168219387","rc":[{"batb":[[0,2.1,6.14],[1,2.08,5.31],[2,2.06,6.08]],"ltp":2.16,"tv":1438.07,"id":8535963},{"batl":[[0,1.9,18.85],[1,1.91,18.5],[2,1.93,294.93]],"ltp":1.87,"tv":5712.73,"id":2309796}]}]}
{"op":"mcm","clk":"1005288360","pt":1580641878245,"mc":[{"id":"1.168219387","rc":[{"trd":[[1.87,373.45]],"batb":[[0,1.87,16.31]],"ltp":1.87,"tv":5716.09,"id":2309796}],"tv":7154.17}]}
{"op":"mcm","clk":"1005288954","pt":1580641881229,"mc":[{"id":"1.168219387","rc":[{"batb":[[0,2.06,6.08],[1,2.04,2.69],[2,2,115.19]],"batl":[[0,2.3,4.65],[1,2.34,4.75],[2,2.62,3.25]],"ltp":2.16,"tv":1438.07,"id":8535963},{"trd":[[1.87,406.07]],"batb":[[0,1.86,21.18],[1,1.85,2.67],[2,1.82,690.89]],"batl":[[0,1.87,33.69]],"ltp":1.87,"tv":5748.71,"id":2309796}],"tv":7186.79}]}
{"op":"mcm","clk":"1005289185","pt":1580641882457,"mc":[{"id":"1.168219387","rc":[{"batb":[[2,1.82,430.18]],"ltp":1.87,"tv":5748.71,"id":2309796}]}]}
{"op":"mcm","clk":"1005289367","pt":1580641883521,"mc":[{"id":"1.168219387","rc":[{"batb":[[1,2,115.19],[2,1.97,20.17]],"ltp":2.16,"tv":1438.07,"id":8535963},{"batb":[[1,1.82,430.18],[2,1.8,80.65]],"ltp":1.87,"tv":5748.71,"id":2309796}]}]}
{"op":"mcm","clk":"1005289565","pt":1580641884638,"mc":[{"id":"1.168219387","rc":[{"batb":[[0,2.08,8.81],[1,2.06,6.08],[2,2,115.19]],"batl":[[0,2.18,5.25],[1,2.3,4.65],[2,2.34,4.75]],"ltp":2.16,"tv":1438.07,"id":8535963},{"trd":[[1.87,444.61]],"batl":[[0,1.87,14.42]],"ltp":1.87,"tv":5787.25,"id":2309796}],"tv":7225.33}]}
{"op":"mcm","clk":"1005289792","pt":1580641885750,"mc":[{"id":"1.168219387","rc":[{"trd":[[2.14,3.15]],"batb":[[0,2.12,10.54],[1,2.08,8.81],[2,2.06,6.08]],"batl":[[0,2.14,8.6],[1,2.18,5.25],[2,2.3,4.65]],"ltp":2.14,"tv":1441.22,"id":8535963},{"trd":[[1.87,469.84]],"batb":[[0,1.86,228.93],[1,1.84,248.79],[2,1.82,430.18]],"batl":[[0,1.9,10.15],[2,1.93,540.69]],"ltp":1.87,"tv":5812.48,"id":2309796}],"tv":7253.71}]}
{"op":"mcm","clk":"1005289826","pt":1580641885933,"mc":[{"id":"1.168219387","rc":[{"batb":[[0,2.08,8.81],[1,2.06,6.08],[2,2,115.19]],"batl":[[0,2.18,5.25],[1,2.3,4.65],[2,2.34,4.75]],"ltp":2.14,"tv":1441.22,"id":8535963},{"batl":[[0,1.91,18.5],[1,1.93,540.69],[2,1.94,19.25]],"ltp":1.87,"tv":5812.48,"id":2309796}]}]}
{"op":"mcm","clk":"1005290168","pt":1580641887661,"mc":[{"id":"1.168219387","rc":[{"batl":[[0,2.16,4.97],[1,2.18,5.25],[2,2.3,4.65]],"ltp":2.14,"tv":1441.22,"id":8535963}]}]}
{"op":"mcm","clk":"1005290262","pt":1580641888162,"mc":[{"id":"1.168219387","rc":[{"batl":[[0,2.18,5.25],[1,2.3,4.65],[2,2.34,4.75]],"ltp":2.14,"tv":1441.22,"id":8535963}]}]}
{"op":"mcm","clk":"1005291076","pt":1580641892481,"mc":[{"id":"1.168219387","rc":[{"batb":[[0,1.86,21.18],[1,1.82,430.18],[2,1.8,80.65]],"batl":[[1,1.93,294.93]],"ltp":1.87,"tv":5812.48,"id":2309796}]}]}
{"op":"mcm","clk":"1005291526","pt":1580641894762,"mc":[{"id":"1.168219387","rc":[{"batb":[[0,2.1,12.04],[1,2.08,8.81],[2,2.06,6.08]],"batl":[[0,2.16,5.47],[1,2.18,5.25],[2,2.3,4.65]],"ltp":2.14,"tv":1441.22,"id":8535963},{"batl":[[0,1.9,40.15],[1,1.91,18.5],[2,1.93,294.93]],"ltp":1.87,"tv":5812.48,"id":2309796}]}]}
{"op":"mcm","clk":"1005291637","pt":1580641895460,"mc":[{"id":"1.168219387","rc":[{"batb":[[0,2.08,8.81],[1,2.06,6.08],[2,2,115.19]],"batl":[[0,2.18,5.25],[1,2.3,4.65],[2,2.34,4.75]],"ltp":2.14,"tv":1441.22,"id":8535963},{"batb":[[1,1.82,695.88],[2,1.8,348.08]],"batl":[[0,1.91,18.5],[1,1.93,294.93],[2,1.94,19.25]],"ltp":1.87,"tv":5812.48,"id":2309796}]}]}
{"op":"mcm","clk":"1005292186","pt":1580641898476,"mc":[{"id":"1.168219387","rc":[{"batb":[[1,2,115.19],[2,1.86,398.62]],"batl":[[1,3,213.45],[2,1000,0.02]],"ltp":2.14,"tv":1441.22,"id":8535963},{"batb":[[1,1.82,430.18],[2,1.8,80.65]],"batl":[[2,1.96,176.46]],"ltp":1.87,"tv":5812.48,"id":2309796}]}]}
{"op":"mcm","clk":"1005292281","pt":1580641898959,"mc":[{"id":"1.168219387","rc":[{"batb":[[1,1.8,80.65],[2,1.55,20]],"batl":[[1,1.93,100]],"ltp":1.87,"tv":5812.48,"id":2309796}]}]}
{"op":"mcm","clk":"1005292577","pt":1580641900657,"mc":[{"id":"1.168219387","rc":[{"trd":[[2.08,72.59]],"batb":[[0,2,290.03],[1,1.86,398.62],[2,1.6,75.72]],"batl":[[0,2.12,340.16],[1,2.14,2993.4],[2,2.18,930.62]],"ltp":2.08,"tv":1462.23,"id":8535963},{"trd":[[1.91,3.69]],"batb":[[0,1.88,1112.76],[1,1.86,21.18],[2,1.8,80.65]],"batl":[[0,1.91,14.81]],"ltp":1.91,"tv":5816.17,"id":2309796}],"tv":7278.41}]}
{"op":"mcm","clk":"1005292681","pt":1580641901239,"mc":[{"id":"1.168219387","rc":[{"batb":[[1,1.98,42.85],[2,1.86,398.62]],"batl":[[1,2.14,170],[2,2.18,133.08]],"ltp":2.08,"tv":1462.23,"id":8535963},{"batb":[[0,1.89,246.19],[1,1.88,111.28],[2,1.87,236.18]],"ltp":1.91,"tv":5816.17,"id":2309796}]}]}
{"op":"mcm","clk":"1005292889","pt":1580641902363,"mc":[{"id":"1.168219387","rc":[{"batb":[[0,2.06,2.61],[1,2,290.03],[2,1.98,42.85]],"ltp":2.08,"tv":1462.23,"id":8535963},{"trd":[[1.91,33.31]],"batb":[[0,1.9,67.43],[1,1.89,246.19],[2,1.88,111.28]],"batl":[[0,1.93,100],[1,1.96,176.46],[2,1.98,212.66]],"ltp":1.91,"tv":5845.79,"id":2309796}],"tv":7308.03}]}
{"op":"mcm","clk":"1005293073","pt":1580641903369,"mc":[{"id":"1.168219387","rc":[{"batl":[[0,2.08,25.21],[1,2.12,340.16],[2,2.14,170]],"ltp":2.08,"tv":1462.23,"id":8535963}]}]}
{"op":"mcm","clk":"1005293469","pt":1580641905272,"mc":[{"id":"1.168219387","rc":[{"trd":[[2.08,97.8],[2.12,206.75]],"batl":[[0,2.12,175.04],[1,2.14,170],[2,2.18,133.08]],"ltp":2.12,"tv":1652.56,"id":8535963},{"trd":[[1.89,708.57],[1.9,318.51],[1.92,40.31]],"batb":[[0,1.88,111.28],[1,1.86,21.18],[2,1.85,48.73]],"batl":[[1,1.98,10.99],[2,2,367.84]],"ltp":1.89,"tv":6685.54,"id":2309796}],"tv":8338.11}]}
{"op":"mcm","clk":"1005294093","pt":1580641908286,"mc":[{"id":"1.168219387","rc":[{"batb":[[0,1.88,338.78],[1,1.86,261.5]],"batl":[[1,1.95,205.18],[2,1.97,204.85]],"ltp":1.89,"tv":6685.54,"id":2309796}]}]}
{"op":"mcm","clk":"1005294413","pt":1580641909672,"mc":[{"id":"1.168219387","rc":[{"batl":[[0,1.9,840.19],[1,1.93,100],[2,1.95,205.18]],"ltp":1.89,"tv":6685.54,"id":2309796}]}]}
{"op":"mcm","clk":"1005294469","pt":1580641909980,"mc":[{"id":"1.168219387","rc":[{"batb":[[1,2.02,113.3],[2,2,174.84]],"ltp":2.12,"tv":1652.56,"id":8535963},{"batb":[[0,1.89,68.45],[1,1.88,338.78],[2,1.86,261.5]],"ltp":1.89,"tv":6685.54,"id":2309796}]}]}
{"op":"mcm","clk":"1005295214","pt":1580641913762,"mc":[{"id":"1.168219387","rc":[{"batb":[[0,2.06,10.15]],"batl":[[0,2.12,189.31]],"ltp":2.12,"tv":1652.56,"id":8535963}]}]}
{"op":"mcm","clk":"1005295391","pt":1580641914667,"mc":[{"id":"1.168219387","rc":[{"trd":[[2.12,396.06]],"batl":[[0,2.14,170],[1,2.18,133.08],[2,2.72,241.55]],"ltp":2.12,"tv":1841.87,"id":8535963},{"trd":[[1.88,738.33],[1.89,1057.83]],"batb":[[0,1.86,261.5],[1,1.85,48.73],[2,1.84,2.56]],"batl":[[0,1.88,220.61],[1,1.9,840.19],[2,1.93,100]],"ltp":1.88,"tv":7712.36,"id":2309796}],"tv":9554.24}]}
{"op":"mcm","clk":"1005295486","pt":1580641915193,"mc":[{"id":"1.168219387","rc":[{"batb":[[0,1.86,21.18]],"ltp":1.88,"tv":7712.36,"id":2309796}]}]}
{"op":"mcm","clk":"1005296167","pt":1580641918692,"mc":[{"id":"1.168219387","rc":[{"batb":[[0,2.06,121.65],[1,2,174.84],[2,1.98,42.85]],"ltp":2.12,"tv":1841.87,"id":8535963},{"trd":[[1.88,1131.26]],"batb":[[0,1.87,221.14],[1,1.86,21.18],[2,1.85,293.33]],"batl":[[0,1.88,24.15]],"ltp":1.88,"tv":8105.29,"id":2309796}],"tv":9947.17}]}
{"op":"mcm","clk":"1005296871","pt":1580641922683,"mc":[{"id":"1.168219387","rc":[{"trd":[[2.14,173.15]],"batl":[[0,2.18,133.08],[1,2.72,241.55],[2,1000,0.02]],"ltp":2.14,"tv":2011.87,"id":8535963},{"trd":[[1.86,83.76],[1.87,1106.67]],"batb":[[0,1.85,48.73],[1,1.84,2.56],[2,1.81,77.42]],"batl":[[0,1.86,403.33],[1,1.88,24.15],[2,1.9,840.19]],"ltp":1.86,"tv":8784.48,"id":2309796}],"tv":10796.35}]}
{"op":"mcm","clk":"1005297412","pt":1580641925646,"mc":[{"id":"1.168219387","rc":[{"batb":[[0,2.06,114.11]],"ltp":2.14,"tv":2011.87,"id":8535963},{"trd":[[1.86,890.42]],"batb":[[0,1.86,220.38],[1,1.85,48.73],[2,1.84,251.56]],"batl":[[0,1.88,24.15],[1,1.9,840.19],[2,1.93,334.43]],"ltp":1.86,"tv":9591.14,"id":2309796}],"tv":11603.01}]}
{"op":"mcm","clk":"1005297579","pt":1580641926553,"mc":[{"id":"1.168219387","rc":[{"batb":[[0,2.06,112.3]],"ltp":2.14,"tv":2011.87,"id":8535963},{"batb":[[0,1.87,70.66],[1,1.86,220.38],[2,1.85,48.73]],"ltp":1.86,"tv":9591.14,"id":2309796}]}]}
{"op":"mcm","clk":"1005297683","pt":1580641927193,"mc":[{"id":"1.168219387","rc":[{"batl":[[1,1.89,2.27],[2,1.9,840.19]],"ltp":1.86,"tv":9591.14,"id":2309796}]}]}
{"op":"mcm","clk":"1005297790","pt":1580641927780,"mc":[{"id":"1.168219387","rc":[{"batl":[[0,2.16,13.55],[1,2.18,133.08],[2,2.72,241.55]],"ltp":2.14,"tv":2011.87,"id":8535963}]}]}
{"op":"mcm","clk":"1005298193","pt":1580641930167,"mc":[{"id":"1.168219387","rc":[{"batb":[[0,2.06,109.68]],"ltp":2.14,"tv":2011.87,"id":8535963},{"batl":[[1,1.9,840.19],[2,1.92,12.98]],"ltp":1.86,"tv":9591.14,"id":2309796}]}]}
{"op":"mcm","clk":"1005299739","pt":1580641938663,"mc":[{"id":"1.168219387","rc":[{"trd":[[1.87,1110.67]],"batb":[[0,1.87,68.66]],"ltp":1.87,"tv":9595.14,"id":2309796}],"tv":11607.01}]}
{"op":"mcm","clk":"1005299879","pt":1580641939453,"mc":[{"id":"1.168219387","rc":[{"trd":[[1.87,1115.21]],"batb":[[0,1.87,66.38]],"ltp":1.87,"tv":9599.68,"id":2309796}],"tv":11611.56}]}
{"op":"mcm","clk":"1005300283","pt":1580641941774,"mc":[{"id":"1.168219387","rc":[{"trd":[[1.87,1247.98]],"batb":[[0,1.86,220.38],[1,1.85,48.73],[2,1.84,249]],"batl":[[0,1.87,33.62],[1,1.88,24.15],[2,1.9,840.19]],"ltp":1.87,"tv":9732.44,"id":2309796}],"tv":11744.32}]}
{"op":"mcm","clk":"1005300633","pt":1580641944198,"mc":[{"id":"1.168219387","rc":[{"batl":[[2,1.9,420.1]],"ltp":1.87,"tv":9732.44,"id":2309796}]}]}
{"op":"mcm","clk":"1005301634","pt":1580641950691,"mc":[{"id":"1.168219387","rc":[{"batb":[[0,2.08,107.87],[1,2.06,109.68],[2,2,174.84]],"ltp":2.14,"tv":2011.87,"id":8535963},{"batb":[[0,1.86,292.22]],"ltp":1.87,"tv":9732.44,"id":2309796}]}]}
{"op":"mcm","clk":"1005301768","pt":1580641951694,"mc":[{"id":"1.168219387","rc":[{"batb":[[1,2,174.84],[2,1.98,42.85]],"ltp":2.14,"tv":2011.87,"id":8535963}]}]}
{"op":"mcm","clk":"1005301910","pt":1580641952599,"mc":[{"id":"1.168219387","rc":[{"trd":[[1.87,1255.37]],"batl":[[0,1.87,29.92]],"ltp":1.87,"tv":9739.84,"id":2309796}],"tv":11751.72}]}
{"op":"mcm","clk":"1005306484","pt":1580641979045,"mc":[{"id":"1.168219387","rc":[{"trd":[[2.14,199.3]],"batl":[[0,2.14,244.83],[1,2.16,13.55],[2,2.18,133.08]],"ltp":2.14,"tv":2038.02,"id":8535963},{"trd":[[1.87,1285.29]],"batl":[[0,1.88,24.15],[1,1.9,420.1],[2,1.92,433.08]],"ltp":1.87,"tv":9769.76,"id":2309796}],"tv":11807.79}]}
{"op":"mcm","clk":"1005307541","pt":1580641985450,"mc":[{"id":"1.168219387","rc":[{"batb":[[0,1.98,42.85],[1,1.93,67.67],[2,1.67,409.76]],"batl":[[1,2.18,35.29],[2,2.72,241.55]],"ltp":2.14,"tv":2038.02,"id":8535963},{"batb":[[0,1.85,48.73],[1,1.79,324.86],[2,1.55,20]],"batl":[[2,1.92,420.1]],"ltp":1.87,"tv":9769.76,"id":2309796}]}]}
{"op":"mcm","clk":"1005307693","pt":1580641986254,"mc":[{"id":"1.168219387","rc":[{"batb":[[0,1.93,67.67],[1,1.67,409.76],[2,1.5,113.58]],"batl":[[1,2.72,241.55],[2,1000,0.02]],"ltp":2.14,"tv":2038.02,"id":8535963},{"batb":[[0,1.79,324.86],[1,1.55,20],[2,1.4,75.73]],"ltp":1.87,"tv":9769.76,"id":2309796}]}]}
{"op":"mcm","clk":"1005307858","pt":1580641987221,"mc":[{"id":"1.168219387","rc":[{"trd":[[1.88,1179.18]],"batl":[[0,1.9,420.28],[1,1.92,420.1],[2,1.94,420.1]],"ltp":1.88,"tv":9817.69,"id":2309796}],"tv":11855.71}]}
{"op":"mcm","clk":"1005308077","pt":1580641988546,"mc":[{"id":"1.168219387","rc":[{"batb":[[0,1.97,32.17],[1,1.93,67.67],[2,1.91,32.39]],"batl":[[1,2.2,4.83],[2,2.22,4.75]],"ltp":2.14,"tv":2038.02,"id":8535963},{"batb":[[0,1.84,22.47],[1,1.82,23.64],[2,1.79,610.9]],"ltp":1.88,"tv":9817.69,"id":2309796}]}]}
{"op":"mcm","clk":"1005308905","pt":1580641992660,"mc":[{"id":"1.168219387","rc":[{"batb":[[2,1.79,324.86]],"ltp":1.88,"tv":9817.69,"id":2309796}]}]}
{"op":"mcm","clk":"1005309223","pt":1580641994562,"mc":[{"id":"1.168219387","rc":[{"batb":[[2,1.79,81.2]],"ltp":1.88,"tv":9817.69,"id":2309796}]}]}
{"op":"mcm","clk":"1005309420","pt":1580641995646,"mc":[{"id":"1.168219387","rc":[{"trd":[[2,420.09],[2.02,411.78],[2.04,428.89],[2.06,395.63],[2.08,485.58],[2.1,464.02],[2.12,396.22]],"batb":[[1,1.93,269.86],[2,1.91,253.42]],"batl":[[0,1.98,11.03],[1,2,179.85],[2,2.02,958.79]],"ltp":2.0,"tv":4437.17,"id":8535963},{"trd":[[1.88,1179.36],[1.9,738.61],[1.92,460.4],[1.94,420.1],[1.96,420.1],[1.98,420.1],[2,420.1]],"batb":[[0,1.9,365.06],[1,1.84,22.47],[2,1.82,23.64]],"batl":[[0,2.04,10.38],[1,2.08,12.19],[2,2.1,9.75]],"ltp":2.0,"tv":12338.46,"id":2309796}],"tv":16775.63}]}
{"op":"mcm","clk":"1005309568","pt":1580641996436,"mc":[{"id":"1.168219387","rc":[{"batb":[[0,1.93,269.86],[1,1.91,253.42],[2,1.75,92.84]],"ltp":2.0,"tv":4437.17,"id":8535963},{"batb":[[0,2,114.72],[1,1.9,66.8],[2,1.84,22.47]],"batl":[[0,2.08,12.19],[1,2.1,9.75],[2,2.14,215]],"ltp":2.0,"tv":12338.46,"id":2309796}]}]}
{"op":"mcm","clk":"1005309776","pt":1580641997641,"mc":[{"id":"1.168219387","rc":[{"batb":[[0,1.97,2.64],[1,1.93,269.86],[2,1.91,253.42]],"ltp":2.0,"tv":4437.17,"id":8535963},{"batb":[[1,1.92,2.64],[2,1.9,66.8]],"ltp":2.0,"tv":12338.46,"id":2309796}]}]}
{"op":"mcm","clk":"1005309946","pt":1580641998745,"mc":[{"id":"1.168219387","rc":[{"batb":[[1,1.95,43.69],[2,1.92,2.64]],"ltp":2.0,"tv":12338.46,"id":2309796}]}]}
{"op":"mcm","clk":"1005310740","pt":1580642003352,"mc":[{"id":"1.168219387","rc":[{"trd":[[1.98,11.03],[2,599.94]],"batb":[[1,1.93,67.67],[2,1.91,32.39]],"batl":[[0,2.02,958.79],[1,2.04,40.33],[2,2.06,163.97]],"ltp":2.0,"tv":4628.05,"id":8535963},{"trd":[[2,829.38],[2.02,10.81]],"batb":[[0,1.95,43.69],[1,1.92,2.64],[2,1.9,88.56]],"batl":[[0,2,114.72],[1,2.08,12.19],[2,2.1,9.75]],"ltp":2.0,"tv":12758.55,"id":2309796}],"tv":17386.6}]}
{"op":"mcm","clk":"1005311335","pt":1580642006742,"mc":[{"id":"1.168219387","rc":[{"batb":[[1,1.85,48.73],[2,1.8,34.23]],"batl":[[0,2.04,40.33],[1,2.12,8.92],[2,2.14,244.83]],"ltp":2.0,"tv":4628.05,"id":8535963},{"batl":[[1,2.18,35.29],[2,2.26,9.25]],"ltp":2.0,"tv":12758.55,"id":2309796}]}]}
{"op":"mcm","clk":"1005311365","pt":1580642006952,"mc":[{"id":"1.168219387","rc":[{"batb":[[2,1.77,35.37]],"ltp":2.0,"tv":4628.05,"id":8535963},{"batl":[[2,2.3,8.95]],"ltp":2.0,"tv":12758.55,"id":2309796}]}]}
{"op":"mcm","clk":"1005311687","pt":1580642008636,"mc":[{"id":"1.168219387","rc":[{"batb":[[1,1.8,389.85]],"batl":[[0,2.14,244.83],[1,2.16,8.44],[2,2.18,9.5]],"ltp":2.0,"tv":4628.05,"id":8535963},{"batb":[[0,1.92,2.64],[1,1.9,66.8],[2,1.87,19.27]],"batl":[[1,2.3,8.95],[2,2.32,8.61]],"ltp":2.0,"tv":12758.55,"id":2309796}]}]}
{"op":"mcm","clk":"1005311803","pt":1580642009427,"mc":[{"id":"1.168219387","rc":[{"batb":[[2,1.79,35.31]],"batl":[[0,2.14,512.49],[1,2.16,165.04]],"ltp":2.0,"tv":4628.05,"id":8535963},{"batl":[[1,2.28,9.09],[2,2.3,8.95]],"ltp":2.0,"tv":12758.55,"id":2309796}]}]}
{"op":"mcm","clk":"1005311930","pt":1580642010175,"mc":[{"id":"1.168219387","rc":[{"batb":[[1,1.88,69.24]],"batl":[[0,1.98,210.05],[1,2,114.72],[2,2.28,9.09]],"ltp":2.0,"tv":12758.55,"id":2309796}]}]}
{"op":"mcm","clk":"1005312816","pt":1580642015474,"mc":[{"id":"1.168219387","rc":[{"batl":[[0,2.12,232.73],[1,2.14,512.49],[2,2.16,165.04]],"ltp":2.0,"tv":4628.05,"id":8535963}]}]}
{"op":"mcm","clk":"1005313108","pt":1580642017163,"mc":[{"id":"1.168219387","rc":[{"batl":[[1,2.14,244.83],[2,2.16,8.44]],"ltp":2.0,"tv":4628.05,"id":8535963}]}]}
{"op":"mcm","clk":"1005313379","pt":1580642018766,"mc":[{"id":"1.168219387","rc":[{"batb":[[0,1.79,35.31],[1,1.77,125.15],[2,1.76,332.3]],"batl":[[0,2.12,9.67]],"ltp":2.0,"tv":4628.05,"id":8535963},{"batb":[[1,1.9,23.46],[2,1.88,69.24]],"ltp":2.0,"tv":12758.55,"id":2309796}]}]}
{"op":"mcm","clk":"1005313402","pt":1580642018980,"mc":[{"id":"1.168219387","rc":[{"batl":[[0,2.14,244.83],[1,2.16,8.44],[2,2.18,9.5]],"ltp":2.0,"tv":4628.05,"id":8535963},{"batb":[[1,1.88,69.24],[2,1.87,19.27]],"ltp":2.0,"tv":12758.55,"id":2309796}]}]}
{"op":"mcm","clk":"1005313570","pt":1580642020155,"mc":[{"id":"1.168219387","rc":[{"trd":[[2,714.66],[2.02,617.67]],"batb":[[0,1.77,89.78],[1,1.76,332.3],[2,1.75,34.19]],"batl":[[0,1.82,219],[1,1.83,310.23],[2,1.84,113.08]],"ltp":2.0,"tv":4948.66,"id":8535963},{"trd":[[1.98,630.15],[2,944.1]],"batb":[[0,2.2,14.07],[1,1.92,2.64],[2,1.88,69.24]],"batl":[[0,2.28,6.5],[1,2.32,8.61],[2,2.34,8.75]],"ltp":2.0,"tv":13083.32,"id":2309796}],"tv":18031.98}]}
{"op":"mcm","clk":"1005313826","pt":1580642021592,"mc":[{"id":"1.168219387","rc":[{"batb":[[0,2.2,99.2],[1,2.06,103.86],[2,1.92,2.64]],"ltp":2.0,"tv":13083.32,"id":2309796}]}]}
{"op":"mcm","clk":"1005314184","pt":1580642023657,"mc":[{"id":"1.168219387","rc":[{"batb":[[1,2.14,36.13],[2,2.06,103.86]],"ltp":2.0,"tv":13083.32,"id":2309796}]}]}
{"op":"mcm","clk":"1005315774","pt":1580642032715,"mc":[{"id":"1.168219387","rc":[{"batb":[[1,1.76,298.32],[2,1.74,792.7]],"batl":[[0,1.83,290.96],[1,1.84,113.08],[2,1.85,360.93]],"ltp":2.0,"tv":4948.66,"id":8535963},{"batl":[[0,2.4,29.41],[1,2.76,7.27],[2,3,48.32]],"ltp":2.0,"tv":13083.32,"id":2309796}]}]}
{"op":"mcm","clk":"1005315932","pt":1580642033621,"mc":[{"id":"1.168219387","rc":[{"batb":[[0,1.74,494.03],[1,1.72,510.84],[2,1.71,58.81]],"batl":[[0,1.86,480.59],[1,1.87,42.01],[2,1.88,497.4]],"ltp":2.0,"tv":4948.66,"id":8535963},{"batb":[[0,2.14,36.13],[1,2.06,103.86],[2,2.04,22.24]],"ltp":2.0,"tv":13083.32,"id":2309796}]}]}
{"op":"mcm","clk":"1005316054","pt":1580642034318,"mc":[{"id":"1.168219387","rc":[{"batb":[[2,1.59,127.54]],"batl":[[1,1.88,497.4],[2,1.94,194.93]],"ltp":2.0,"tv":4948.66,"id":8535963},{"batb":[[0,2.06,103.86],[1,2.04,22.24],[2,1.99,20.51]],"batl":[[0,2.76,7.27],[1,3,48.32],[2,10,2.53]],"ltp":2.0,"tv":13083.32,"id":2309796}]}]}
{"op":"mcm","clk":"1005316130","pt":1580642034804,"mc":[{"id":"1.168219387","rc":[{"batl":[[0,2.2,16.64],[1,2.76,7.27],[2,3,48.32]],"ltp":2.0,"tv":13083.32,"id":2309796}]}]}
{"op":"mcm","clk":"1005316431","pt":1580642036627,"mc":[{"id":"1.168219387","rc":[{"batb":[[2,1.6,213.42]],"batl":[[2,1.94,379.22]],"ltp":2.0,"tv":4948.66,"id":8535963}]}]}
{"op":"mcm","clk":"1005316790","pt":1580642038513,"mc":[{"id":"1.168219387","rc":[{"batb":[[2,1.62,241.98]],"batl":[[0,1.94,379.22],[1,1.96,232.24],[2,2.02,9.5]],"ltp":2.0,"tv":4948.66,"id":8535963}]}]}
{"op":"mcm","clk":"1005316863","pt":1580642038931,"mc":[{"id":"1.168219387","rc":[{"batb":[[2,1.59,127.54]],"batl":[[0,1.94,184.29]],"ltp":2.0,"tv":4948.66,"id":8535963}]}]}
{"op":"mcm","clk":"1005317210","pt":1580642040725,"mc":[{"id":"1.168219387","rc":[{"batb":[[0,1.9,166.12],[1,1.89,38.41],[2,1.87,258.92]],"batl":[[0,1.93,170],[1,1.94,184.29],[2,1.96,232.24]],"ltp":2.0,"tv":4948.66,"id":8535963},{"batb":[[0,2.08,353.68],[1,2.06,103.86],[2,2.04,22.24]],"batl":[[0,2.12,6.58],[1,2.14,11.25],[2,2.2,16.64]],"ltp":2.0,"tv":13083.32,"id":2309796}]}]}
{"op":"mcm","clk":"1005317445","pt":1580642041687,"mc":[{"id":"1.168219387","rc":[{"batb":[[2,1.87,333.35]],"batl":[[2,1.96,274.25]],"ltp":2.0,"tv":4948.66,"id":8535963},{"batb":[[2,2.04,62.57]],"ltp":2.0,"tv":13083.32,"id":2309796}]}]}
{"op":"mcm","clk":"1005317478","pt":1580642041896,"mc":[{"id":"1.168219387","rc":[{"batb":[[1,2.06,106.49]],"ltp":2.0,"tv":13083.32,"id":2309796}]}]}
{"op":"mcm","clk":"1005317828","pt":1580642043750,"mc":[{"id":"1.168219387","rc":[{"batl":[[2,2.22,168]],"ltp":2.0,"tv":13083.32,"id":2309796}]}]}
{"op":"mcm","clk":"1005319390","pt":1580642051757,"mc":[{"id":"1.168219387","rc":[{"trd":[[1.9,72.79]],"batb":[[0,1.89,38.41],[1,1.83,2.59],[2,1.78,53.77]],"batl":[[0,1.96,42.01],[1,2.12,241.98],[2,2.14,250.08]],"ltp":1.9,"tv":5021.44,"id":8535963},{"batb":[[0,2.06,2.63],[1,2.04,40.33],[2,1.93,63.89]],"batl":[[0,2.14,11.25],[1,2.26,32.77],[2,2.54,7.75]],"ltp":2.0,"tv":13083.32,"id":2309796}],"tv":18104.77}]}
{"op":"mcm","clk":"1005319585","pt":1580642052735,"mc":[{"id":"1.168219387","rc":[{"batb":[[2,1.66,109.45]],"batl":[[0,2.12,241.98],[1,2.14,250.08],[2,2.16,5.22]],"ltp":1.9,"tv":5021.44,"id":8535963},{"batb":[[1,1.93,63.89],[2,1.88,20.71]],"batl":[[1,2.54,7.75],[2,2.76,7.27]],"ltp":2.0,"tv":13083.32,"id":2309796}]}]}
{"op":"mcm","clk":"1005319910","pt":1580642054536,"mc":[{"id":"1.168219387","rc":[{"batb":[[0,1.83,2.59],[1,1.66,109.45],[2,1.65,35.73]],"ltp":1.9,"tv":5021.44,"id":8535963},{"batl":[[0,2.54,7.75],[1,2.76,7.27],[2,3,48.32]],"ltp":2.0,"tv":13083.32,"id":2309796}]}]}
{"op":"mcm","clk":"1005320332","pt":1580642057002,"mc":[{"id":"1.168219387","rc":[{"batb":[[0,1.83,209.28],[1,1.81,261.97],[2,1.66,109.45]],"batl":[[0,1.89,167],[1,1.91,224.4],[2,2.12,241.98]],"ltp":1.9,"tv":5021.44,"id":8535963}]}]}
{"op":"mcm","clk":"1005320554","pt":1580642058326,"mc":[{"id":"1.168219387","rc":[{"batl":[[2,2.08,5.69]],"ltp":1.9,"tv":5021.44,"id":8535963},{"batb":[[1,1.93,83.82]],"ltp":2.0,"tv":13083.32,"id":2309796}]}]}
{"op":"mcm","clk":"1005320725","pt":1580642059136,"mc":[{"id":"1.168219387","rc":[{"batb":[[2,1.7,465.47]],"ltp":1.9,"tv":5021.44,"id":8535963}]}]}
{"op":"mcm","clk":"1005321016","pt":1580642060734,"mc":[{"id":"1.168219387","rc":[{"batb":[[0,1.83,2.59],[1,1.7,465.47],[2,1.66,109.45]],"batl":[[0,2.12,241.98],[1,2.14,250.08],[2,2.16,5.22]],"ltp":1.9,"tv":5021.44,"id":8535963},{"batb":[[1,1.93,63.89]],"ltp":2.0,"tv":13083.32,"id":2309796}]}]}
{"op":"mcm","clk":"1005321502","pt":1580642063426,"mc":[{"id":"1.168219387","rc":[{"batb":[[2,1.67,233.16]],"batl":[[0,2.08,141.87],[1,2.1,169.6],[2,2.12,241.98]],"ltp":1.9,"tv":5021.44,"id":8535963}]}]}
{"op":"mcm","clk":"1005321641","pt":1580642064225,"mc":[{"id":"1.168219387","rc":[{"trd":[[1.83,5.19]],"batb":[[0,1.7,465.47],[1,1.67,233.16],[2,1.66,285.91]],"batl":[[0,1.83,8.76],[1,2.08,141.87],[2,2.1,169.6]],"ltp":1.83,"tv":5026.63,"id":8535963}],"tv":18109.96}]}
{"op":"mcm","clk":"1005321867","pt":1580642065592,"mc":[{"id":"1.168219387","rc":[{"trd":[[1.83,6.5]],"batl":[[0,1.83,7.45]],"ltp":1.83,"tv":5027.94,"id":8535963},{"trd":[[2.2,1.09]],"ltp":2.2,"tv":13084.41,"id":2309796}],"tv":18112.36}]}
{"op":"mcm","clk":"1005322609","pt":1580642069729,"mc":[{"id":"1.168219387","rc":[{"batb":[[0,1.93,63.89],[1,1.88,20.71],[2,1.87,17.27]],"ltp":2.2,"tv":13084.41,"id":2309796}]}]}
{"op":"mcm","clk":"1005322770","pt":1580642070640,"mc":[{"id":"1.168219387","rc":[{"batl":[[1,2.06,243.66],[2,2.08,141.87]],"ltp":1.83,"tv":5027.94,"id":8535963}]}]}
{"op":"mcm","clk":"1005322811","pt":1580642070962,"mc":[{"id":"1.168219387","rc":[{"batl":[[2,2.08,148.06]],"ltp":1.83,"tv":5027.94,"id":8535963},{"batb":[[0,1.93,84.25]],"ltp":2.2,"tv":13084.41,"id":2309796}]}]}
{"op":"mcm","clk":"1005323196","pt":1580642073126,"mc":[{"id":"1.168219387","rc":[{"trd":[[1.83,13.95]],"batl":[[0,2.06,243.66],[1,2.08,148.06],[2,2.1,169.6]],"ltp":1.83,"tv":5035.4,"id":8535963},{"trd":[[2.2,7.29]],"batl":[[0,2.2,10.44],[1,2.54,7.75],[2,2.76,7.27]],"ltp":2.2,"tv":13090.61,"id":2309796}],"tv":18126.01}]}
{"op":"mcm","clk":"1005323865","pt":1580642076761,"mc":[{"id":"1.168219387","rc":[{"batl":[[1,2.08,6.19],[2,2.14,250.08]],"ltp":1.83,"tv":5035.4,"id":8535963}]}]}
{"op":"mcm","clk":"1005323999","pt":1580642077461,"mc":[{"id":"1.168219387","rc":[{"batb":[[0,1.67,233.16],[1,1.66,285.91],[2,1.65,35.73]],"ltp":1.83,"tv":5035.4,"id":8535963}]}]}
{"op":"mcm","clk":"1005324419","pt":1580642079764,"mc":[{"id":"1.168219387","rc":[{"batl":[[0,1.72,431.89],[1,1.74,301.45],[2,1.75,155.57]],"ltp":1.83,"tv":5035.4,"id":8535963},{"trd":[[2.2,28.18]],"batb":[[0,2.4,8.01],[1,2.36,475.96],[2,2.3,155.57]],"batl":[[0,2.46,6.28],[2,2.6,169]],"ltp":2.2,"tv":13111.5,"id":2309796}],"tv":18146.9}]}
{"op":"mcm","clk":"1005324592","pt":1580642080650,"mc":[{"id":"1.168219387","rc":[{"trd":[[1.72,10.72]],"batl":[[0,1.72,426.53]],"ltp":1.72,"tv":5046.11,"id":8535963},{"batb":[[1,2.38,68.3],[2,2.36,475.96]],"ltp":2.2,"tv":13111.5,"id":2309796}],"tv":18157.62}]}
{"op":"mcm","clk":"1005324788","pt":1580642081756,"mc":[{"id":"1.168219387","rc":[{"trd":[[2.46,5.12]],"batl":[[0,2.46,3.72]],"ltp":2.46,"tv":13116.61,"id":2309796}],"tv":18162.73}]}
{"op":"mcm","clk":"1005325039","pt":1580642083347,"mc":[{"id":"1.168219387","rc":[{"batl":[[2,2.58,26.05]],"ltp":2.46,"tv":13116.61,"id":2309796}]}]}
{"op":"mcm","clk":"1005325601","pt":1580642086594,"mc":[{"id":"1.168219387","rc":[{"batl":[[2,1.75,636.16]],"ltp":1.72,"tv":5046.11,"id":8535963}]}]}
{"op":"mcm","clk":"1005326300","pt":1580642090626,"mc":[{"id":"1.168219387","rc":[{"trd":[[1.67,17.1],[1.68,5.45]],"batb":[[0,1.67,224.61]],"ltp":1.67,"tv":5068.66,"id":8535963},{"trd":[[2.46,8.84]],"batl":[[0,2.54,7.75],[1,2.58,26.05],[2,2.6,169]],"ltp":2.46,"tv":13120.33,"id":2309796}],"tv":18189.0}]}
{"op":"mcm","clk":"1005326444","pt":1580642091378,"mc":[{"id":"1.168219387","rc":[{"trd":[[1.72,15.08]],"batl":[[0,1.72,424.35]],"ltp":1.72,"tv":5073.03,"id":8535963}],"tv":18193.37}]}
{"op":"mcm","clk":"1005326641","pt":1580642092499,"mc":[{"id":"1.168219387","rc":[{"batl":[[0,1.68,67],[1,1.72,424.35],[2,1.74,301.45]],"ltp":1.72,"tv":5073.03,"id":8535963},{"batb":[[0,2.38,68.3],[1,2.36,475.96],[2,2.3,187.5]],"ltp":2.46,"tv":13120.33,"id":2309796}]}]}
{"op":"mcm","clk":"1005326842","pt":1580642093613,"mc":[{"id":"1.168219387","rc":[{"trd":[[1.67,19.51]],"batb":[[0,1.67,222.2]],"ltp":1.67,"tv":5075.44,"id":8535963},{"trd":[[2.5,1.61]],"ltp":2.5,"tv":13121.94,"id":2309796}],"tv":18197.39}]}
{"op":"mcm","clk":"1005326941","pt":1580642094098,"mc":[{"id":"1.168219387","rc":[{"trd":[[1.68,9.81]],"batl":[[0,1.68,64.82]],"ltp":1.68,"tv":5079.8,"id":8535963}],"tv":18201.75}]}
{"op":"mcm","clk":"1005327111","pt":1580642094901,"mc":[{"id":"1.168219387","rc":[{"batl":[[1,1.7,10.61],[2,1.72,424.35]],"ltp":1.68,"tv":5079.8,"id":8535963},{"batl":[[0,2.5,8.99],[1,2.54,7.75],[2,2.58,26.05]],"ltp":2.5,"tv":13121.94,"id":2309796}]}]}
{"op":"mcm","clk":"1005327643","pt":1580642098010,"mc":[{"id":"1.168219387","rc":[{"batl":[[0,1.7,10.61],[1,1.72,424.35],[2,1.74,301.45]],"ltp":1.68,"tv":5079.8,"id":8535963}]}]}
{"op":"mcm","clk":"1005327800","pt":1580642098939,"mc":[{"id":"1.168219387","rc":[{"trd":[[1.7,0.14]],"batl":[[0,1.7,10.54]],"ltp":1.7,"tv":5079.94,"id":8535963}],"tv":18201.89}]}
{"op":"mcm","clk":"1005328338","pt":1580642101725,"mc":[{"id":"1.168219387","rc":[{"trd":[[1.67,149.15]],"batb":[[0,1.67,157.38]],"batl":[[0,1.72,199.89],[1,1.74,301.45],[2,1.75,636.16]],"ltp":1.67,"tv":5209.58,"id":8535963},{"batl":[[0,2.54,7.75],[1,2.58,26.05],[2,2.66,456.77]],"ltp":2.5,"tv":13121.94,"id":2309796}],"tv":18331.53}]}
{"op":"mcm","clk":"1005328463","pt":1580642102331,"mc":[{"id":"1.168219387","rc":[{"trd":[[1.67,463.91]],"batb":[[0,1.66,285.91],[1,1.65,35.73],[2,1.63,66.38]],"batl":[[0,1.67,42.62],[1,1.75,636.16],[2,1.77,497.4]],"ltp":1.67,"tv":5524.34,"id":8535963}],"tv":18646.29}]}
{"op":"mcm","clk":"1005328725","pt":1580642103731,"mc":[{"id":"1.168219387","rc":[{"batb":[[0,1.66,109.45],[1,1.63,66.38],[2,1.61,494.03]],"ltp":1.67,"tv":5524.34,"id":8535963},{"batb":[[1,2.3,187.5],[2,2.18,87.26]],"batl":[[0,2.58,26.05],[1,3,42.01],[2,3.3,5.85]],"ltp":2.5,"tv":13121.94,"id":2309796}]}]}
{"op":"mcm","clk":"1005328902","pt":1580642104712,"mc":[{"id":"1.168219387","rc":[{"trd":[[1.67,531.73]],"batb":[[0,1.61,494.03],[1,1.59,510.84],[2,1.51,482.27]],"batl":[[0,1.67,8.71],[1,1.72,40.75],[2,1.75,480.59]],"ltp":1.67,"tv":5592.16,"id":8535963},{"batb":[[0,2.18,87.26],[1,2.08,6.31],[2,1.7,75.72]],"batl":[[0,3,42.01],[1,3.4,5.69],[2,3.95,4.7]],"ltp":2.5,"tv":13121.94,"id":2309796}],"tv":18714.11}]}
{"op":"mcm","clk":"1005329049","pt":1580642105529,"mc":[{"id":"1.168219387","rc":[{"batl":[[1,1.75,480.59],[2,1.77,497.4]],"ltp":1.67,"tv":5592.16,"id":8535963}]}]}
{"op":"mcm","clk":"1005329299","pt":1580642106723,"mc":[{"id":"1.168219387","rc":[{"batl":[[0,1.66,21],[1,1.67,8.71],[2,1.75,480.59]],"ltp":1.67,"tv":5592.16,"id":8535963}]}]}
{"op":"mcm","clk":"1005329392","pt":1580642107217,"mc":[{"id":"1.168219387","rc":[{"batb":[[1,2.1,5.34],[2,2.08,6.31]],"batl":[[1,3.35,5.9],[2,3.4,5.69]],"ltp":2.5,"tv":13121.94,"id":2309796}]}]}
{"op":"mcm","clk":"1005329808","pt":1580642109733,"mc":[{"id":"1.168219387","rc":[{"batb":[[0,1.62,324.42],[1,1.61,691.91],[2,1.6,11.19]],"batl":[[1,1.67,212.14],[2,1.69,333.49]],"ltp":1.67,"tv":5592.16,"id":8535963},{"batb":[[0,2.5,11.22],[1,2.18,87.26],[2,2.1,5.34]],"batl":[[0,2.64,10.68],[1,3,42.01],[2,3.35,5.9]],"ltp":2.5,"tv":13121.94,"id":2309796}]}]}
{"op":"mcm","clk":"1005329981","pt":1580642110607,"mc":[{"id":"1.168219387","rc":[{"batb":[[2,1.59,510.84]],"batl":[[1,1.67,200.64]],"ltp":1.67,"tv":5592.16,"id":8535963},{"batb":[[0,2.18,87.26],[1,2.1,5.34],[2,2.08,6.31]],"batl":[[0,3,42.01],[1,3.35,5.9],[2,3.4,5.69]],"ltp":2.5,"tv":13121.94,"id":2309796}]}]}
{"op":"mcm","clk":"1005330357","pt":1580642112599,"mc":[{"id":"1.168219387","rc":[{"batl":[[0,1.63,10],[1,1.66,21],[2,1.67,200.64]],"ltp":1.67,"tv":5592.16,"id":8535963}]}]}
{"op":"mcm","clk":"1005330446","pt":1580642113122,"mc":[{"id":"1.168219387","rc":[{"batl":[[2,1.67,191.93]],"ltp":1.67,"tv":5592.16,"id":8535963}]}]}
{"op":"mcm","clk":"1005331077","pt":1580642116653,"mc":[{"id":"1.168219387","rc":[{"batb":[[0,1.61,494.03],[1,1.59,510.84],[2,1.51,482.27]],"batl":[[2,1.74,56.29]],"ltp":1.67,"tv":5592.16,"id":8535963}]}]}
{"op":"mcm","clk":"1005331222","pt":1580642117457,"mc":[{"id":"1.168219387","rc":[{"batl":[[0,1.66,21],[1,1.74,56.29],[2,1.75,480.59]],"ltp":1.67,"tv":5592.16,"id":8535963}]}]}
{"op":"mcm","clk":"1005331617","pt":1580642119668,"mc":[{"id":"1.168219387","rc":[{"batl":[[1,1.67,2.73],[2,1.74,56.29]],"ltp":1.67,"tv":5592.16,"id":8535963}]}]}
{"op":"mcm","clk":"1005331812","pt":1580642120638,"mc":[{"id":"1.168219387","rc":[{"batl":[[0,1.62,10],[1,1.66,21],[2,1.67,2.73]],"ltp":1.67,"tv":5592.16,"id":8535963},{"batb":[[1,2.16,4.78],[2,2.1,5.34]],"ltp":2.5,"tv":13121.94,"id":2309796}]}]}
{"op":"mcm","clk":"1005331847","pt":1580642120860,"mc":[{"id":"1.168219387","rc":[{"batb":[[1,2.1,5.34],[2,2.08,6.31]],"ltp":2.5,"tv":13121.94,"id":2309796}]}]}
{"op":"mcm","clk":"1005332569","pt":1580642124868,"mc":[{"id":"1.168219387","rc":[{"batl":[[0,1.66,21],[1,1.67,2.73],[2,1.74,56.29]],"ltp":1.67,"tv":5592.16,"id":8535963}]}]}
{"op":"mcm","clk":"1005332836","pt":1580642126360,"mc":[{"id":"1.168219387","rc":[{"batb":[[2,1.49,395.56]],"ltp":1.67,"tv":5592.16,"id":8535963}]}]}
{"op":"mcm","clk":"1005333122","pt":1580642127954,"mc":[{"id":"1.168219387","rc":[{"trd":[[1.61,20]],"batb":[[0,1.61,484.04]],"ltp":1.61,"tv":5612.16,"id":8535963}],"tv":18734.11}]}
{"op":"mcm","clk":"1005333360","pt":1580642129446,"mc":[{"id":"1.168219387","rc":[{"trd":[[1.61,65.43]],"batb":[[0,1.61,461.32]],"ltp":1.61,"tv":5657.59,"id":8535963}],"tv":18779.54}]}
{"op":"mcm","clk":"1005333936","pt":1580642132753,"mc":[{"id":"1.168219387","rc":[{"batb":[[0,1.49,395.56],[1,1.48,271.47],[2,1.43,43.43]],"ltp":1.61,"tv":5657.59,"id":8535963}]}]}
{"op":"mcm","clk":"1005334459","pt":1580642135684,"mc":[{"id":"1.168219387","rc":[{"batb":[[2,1.45,746.04]],"batl":[[0,1.52,10.62],[1,1.53,524.4],[2,1.54,514.82]],"ltp":1.61,"tv":5657.59,"id":8535963},{"batb":[[0,2.86,192.93],[1,2.84,324.66],[2,2.18,87.26]],"batl":[[0,3,47.44],[1,3.15,141],[2,3.35,5.9]],"ltp":2.5,"tv":13121.94,"id":2309796}]}]}
{"op":"mcm","clk":"1005334575","pt":1580642136281,"mc":[{"id":"1.168219387","rc":[{"batb":[[0,2.88,41.94],[1,2.86,192.93],[2,2.84,324.66]],"ltp":2.5,"tv":13121.94,"id":2309796}]}]}
{"op":"mcm","clk":"1005334767","pt":1580642137245,"mc":[{"id":"1.168219387","rc":[{"batl":[[1,1.53,566.41]],"ltp":1.61,"tv":5657.59,"id":8535963},{"batb":[[1,2.86,214.78]],"batl":[[2,3.3,17.64]],"ltp":2.5,"tv":13121.94,"id":2309796}]}]}
{"op":"mcm","clk":"1005335922","pt":1580642144204,"mc":[{"id":"1.168219387","rc":[{"trd":[[1.52,3.36]],"batl":[[0,1.52,8.94]],"ltp":1.52,"tv":5660.95,"id":8535963}],"tv":18782.9}]}
{"op":"mcm","clk":"1005336097","pt":1580642145169,"mc":[{"id":"1.168219387","rc":[{"trd":[[1.5,35.12]],"batb":[[2,1.45,791.25]],"ltp":1.5,"tv":5696.08,"id":8535963},{"trd":[[3,17.56]],"batl":[[0,3,29.88],[2,3.25,6.7]],"ltp":3.0,"tv":13139.5,"id":2309796}],"tv":18835.59}]}
{"op":"mcm","clk":"1005336608","pt":1580642148083,"mc":[{"id":"1.168219387","rc":[{"batb":[[2,1.46,389.85]],"ltp":1.5,"tv":5696.08,"id":8535963},{"trd":[[3,77.32]],"batl":[[0,3.15,141],[1,3.25,6.7],[2,3.3,17.64]],"ltp":3.0,"tv":13199.26,"id":2309796}],"tv":18895.34}]}
{"op":"mcm","clk":"1005337748","pt":1580642154382,"mc":[{"id":"1.168219387","rc":[{"batl":[[0,1.53,566.41],[1,1.54,514.82],[2,1.63,242.82]],"ltp":1.5,"tv":5696.08,"id":8535963}]}]}
{"op":"mcm","clk":"1005337928","pt":1580642155378,"mc":[{"id":"1.168219387","rc":[{"batl":[[0,1.5,5.3],[1,1.53,566.41],[2,1.54,514.82]],"ltp":1.5,"tv":5696.08,"id":8535963}]}]}
{"op":"mcm","clk":"1005338233","pt":1580642157262,"mc":[{"id":"1.168219387","rc":[{"batb":[[0,2.96,4.8],[1,2.88,41.94],[2,2.86,214.78]],"batl":[[0,3.05,7.61],[1,3.15,141],[2,3.25,6.7]],"ltp":3.0,"tv":13199.26,"id":2309796}]}]}
{"op":"mcm","clk":"1005338363","pt":1580642158070,"mc":[{"id":"1.168219387","rc":[{"batb":[[0,2.88,41.94],[1,2.86,214.78],[2,2.84,324.66]],"batl":[[0,3.15,141],[1,3.25,6.7],[2,3.3,17.64]],"ltp":3.0,"tv":13199.26,"id":2309796}]}]}
{"op":"mcm","clk":"1005338603","pt":1580642159500,"mc":[{"id":"1.168219387","rc":[{"batl":[[2,3.3,24.29]],"ltp":3.0,"tv":13199.26,"id":2309796}]}]}
{"op":"mcm","clk":"1005338937","pt":1580642161106,"mc":[{"id":"1.168219387","rc":[{"batb":[[0,2.96,4.8],[1,2.88,41.94],[2,2.86,214.78]],"batl":[[0,3.05,7.61],[1,3.15,141],[2,3.25,6.7]],"ltp":3.0,"tv":13199.26,"id":2309796}]}]}
{"op":"mcm","clk":"1005339179","pt":1580642162396,"mc":[{"id":"1.168219387","rc":[{"trd":[[1.5,36.87]],"batl":[[0,1.5,3.56]],"ltp":1.5,"tv":5697.82,"id":8535963},{"trd":[[3,78.19]],"ltp":3.0,"tv":13200.14,"id":2309796}],"tv":18897.97}]}
{"op":"mcm","clk":"1005339502","pt":1580642164111,"mc":[{"id":"1.168219387","rc":[{"trd":[[1.49,0.2]],"batb":[[0,1.49,395.46]],"ltp":1.49,"tv":5698.02,"id":8535963}],"tv":18898.16}]}
{"op":"mcm","clk":"1005340474","pt":1580642169792,"mc":[{"id":"1.168219387","rc":[{"trd":[[1.49,10.81]],"batb":[[0,1.49,390.15]],"ltp":1.49,"tv":5708.63,"id":8535963}],"tv":18908.77}]}
{"op":"mcm","clk":"1005341000","pt":1580642172713,"mc":[{"id":"1.168219387","rc":[{"batb":[[0,1.49,159.43],[1,1.46,389.86],[2,1.45,45.21]],"batl":[[1,1.53,42.01],[2,1.63,242.82]],"ltp":1.49,"tv":5708.63,"id":8535963},{"batb":[[0,2.88,41.94],[1,2.86,21.85],[2,2.58,55.63]],"batl":[[0,3.25,6.7],[1,3.3,24.29],[2,3.35,5.9]],"ltp":3.0,"tv":13200.14,"id":2309796}]}]}
{"op":"mcm","clk":"1005341057","pt":1580642172983,"mc":[{"id":"1.168219387","rc":[{"batb":[[0,1.46,389.86],[1,1.45,45.21],[2,1.44,233.17]],"ltp":1.49,"tv":5708.63,"id":8535963},{"batb":[[0,2.86,21.85],[1,2.58,55.08],[2,1.97,17.17]],"ltp":3.0,"tv":13200.14,"id":2309796}]}]}
{"op":"mcm","clk":"1005341309","pt":1580642174415,"mc":[{"id":"1.168219387","rc":[{"batl":[[1,1.63,242.82],[2,1.66,21]],"ltp":1.49,"tv":5708.63,"id":8535963},{"batb":[[0,2.58,55.08],[1,1.97,17.17],[2,1.95,18.31]],"batl":[[1,3.3,6.65]],"ltp":3.0,"tv":13200.14,"id":2309796}]}]}
{"op":"mcm","clk":"1005341488","pt":1580642175312,"mc":[{"id":"1.168219387","rc":[{"trd":[[1.5,43.98]],"batb":[[0,1.5,1.8],[1,1.46,389.86],[2,1.45,45.21]],"batl":[[0,1.62,278.79],[1,1.63,430.87]],"ltp":1.5,"tv":5715.75,"id":8535963}],"tv":18915.89}]}
{"op":"mcm","clk":"1005341725","pt":1580642176312,"mc":[{"id":"1.168219387","rc":[{"batl":[[0,1.63,242.82],[1,1.66,21],[2,1.89,435.28]],"ltp":1.5,"tv":5715.75,"id":8535963}]}]}
{"op":"mcm","clk":"1005341900","pt":1580642177114,"mc":[{"id":"1.168219387","rc":[{"batl":[[0,1.66,21],[1,1.89,435.28],[2,2.04,5.38]],"ltp":1.5,"tv":5715.75,"id":8535963}]}]}
{"op":"mcm","clk":"1005342345","pt":1580642179512,"mc":[{"id":"1.168219387","rc":[{"batb":[[0,1.5,393.19],[1,1.49,267.51],[2,1.46,389.86]],"batl":[[0,1.55,384.21],[1,1.56,219.66],[2,1.66,21]],"ltp":1.5,"tv":5715.75,"id":8535963}]}]}
{"op":"mcm","clk":"1005342603","pt":1580642180801,"mc":[{"id":"1.168219387","rc":[{"batl":[[2,1.6,213.41]],"ltp":1.5,"tv":5715.75,"id":8535963}]}]}
{"op":"mcm","clk":"1005343183","pt":1580642183754,"mc":[{"id":"1.168219387","rc":[{"batb":[[0,1.5,1.8],[1,1.46,389.86],[2,1.45,45.21]],"batl":[[0,1.6,213.41],[1,1.66,21],[2,1.89,435.28]],"ltp":1.5,"tv":5715.75,"id":8535963}]}]}
{"op":"mcm","clk":"1005343771","pt":1580642186714,"mc":[{"id":"1.168219387","rc":[{"batl":[[1,1.62,278.79],[2,1.63,188.05]],"ltp":1.5,"tv":5715.75,"id":8535963}]}]}
{"op":"mcm","clk":"1005344916","pt":1580642193013,"mc":[{"id":"1.168219387","rc":[{"batl":[[1,1.66,21],[2,1.89,435.28]],"ltp":1.5,"tv":5715.75,"id":8535963}]}]}
{"op":"mcm","clk":"1005345243","pt":1580642194747,"mc":[{"id":"1.168219387","rc":[{"batb":[[1,1.45,45.22],[2,1.44,733.69]],"ltp":1.5,"tv":5715.75,"id":8535963},{"batl":[[0,3.3,6.65],[1,3.35,5.9],[2,3.4,5.69]],"ltp":3.0,"tv":13200.14,"id":2309796}]}]}
{"op":"mcm","clk":"1005345264","pt":1580642194813,"mc":[{"id":"1.168219387","rc":[{"batb":[[1,1.44,733.7],[2,1.43,362.12]],"ltp":1.5,"tv":5715.75,"id":8535963}]}]}
{"op":"mcm","clk":"1005345635","pt":1580642196739,"mc":[{"id":"1.168219387","rc":[{"trd":[[1.48,0.02],[1.5,47.58]],"batb":[[0,1.44,733.69],[1,1.43,362.12],[2,1.42,585.81]],"batl":[[0,1.47,123.52],[1,1.48,731.52],[2,1.49,581.25]],"ltp":1.48,"tv":5719.36,"id":8535963},{"batb":[[0,3.15,6.69],[1,3.05,89.38],[2,2.8,45.16]],"batl":[[0,3.25,5.13],[1,3.3,6.65],[2,3.35,5.9]],"ltp":3.0,"tv":13200.14,"id":2309796}],"tv":18919.51}]}
{"op":"mcm","clk":"1005346077","pt":1580642199229,"mc":[{"id":"1.168219387","rc":[{"batl":[[2,1.49,623.26]],"ltp":1.48,"tv":5719.36,"id":8535963},{"batb":[[1,3.05,109.55]],"ltp":3.0,"tv":13200.14,"id":2309796}]}]}
{"op":"mcm","clk":"1005346604","pt":1580642202449,"mc":[{"id":"1.168219387","rc":[{"batl":[[2,1.49,1103.85]],"ltp":1.48,"tv":5719.36,"id":8535963}]}]}
{"op":"mcm","clk":"1005346921","pt":1580642204220,"mc":[{"id":"1.168219387","rc":[{"batb":[[2,1.42,950.45]],"ltp":1.48,"tv":5719.36,"id":8535963}]}]}
{"op":"mcm","clk":"1005347153","pt":1580642205417,"mc":[{"id":"1.168219387","rc":[{"trd":[[1.44,756.19]],"batb":[[0,1.44,355.59]],"ltp":1.44,"tv":6475.55,"id":8535963},{"batb":[[2,2.92,3.19]],"ltp":3.0,"tv":13200.14,"id":2309796}],"tv":19675.69}]}
{"op":"mcm","clk":"1005347471","pt":1580642207023,"mc":[{"id":"1.168219387","rc":[{"trd":[[3.15,0.5]],"batb":[[0,3.15,6.44]],"ltp":3.15,"tv":13200.64,"id":2309796}],"tv":19676.19}]}
{"op":"mcm","clk":"1005347761","pt":1580642208591,"mc":[{"id":"1.168219387","rc":[{"batb":[[0,1.44,416.62]],"batl":[[1,1.48,813.32]],"ltp":1.44,"tv":6475.55,"id":8535963}]}]}
{"op":"mcm","clk":"1005348088","pt":1580642210398,"mc":[{"id":"1.168219387","rc":[{"batb":[[0,1.42,405.58],[1,1.41,704.12],[2,1.39,510.84]],"batl":[[0,1.49,480.59],[1,1.51,497.4],[2,1.52,36.01]],"ltp":1.44,"tv":6475.55,"id":8535963},{"batb":[[0,2.92,3.19],[1,2.84,3.47],[2,2.8,45.16]],"batl":[[0,3.4,5.69],[1,3.9,4.65],[2,3.95,4.7]],"ltp":3.15,"tv":13200.64,"id":2309796}]}]}
{"op":"mcm","clk":"1005348428","pt":1580642212355,"mc":[{"id":"1.168219387","rc":[{"batb":[[2,1.4,487.31]],"ltp":1.44,"tv":6475.55,"id":8535963}]}]}
{"op":"mcm","clk":"1005348634","pt":1580642213683,"mc":[{"id":"1.168219387","rc":[{"batb":[[0,1.45,202.65],[1,1.43,44.43],[2,1.42,405.58]],"ltp":1.44,"tv":6475.55,"id":8535963},{"batb":[[1,2.84,47.06],[2,1.97,17.17]],"batl":[[0,3.35,2.9],[1,3.4,5.69],[2,3.9,4.65]],"ltp":3.15,"tv":13200.64,"id":2309796}]}]}
{"op":"mcm","clk":"1005350336","pt":1580642223498,"mc":[{"id":"1.168219387","rc":[{"batl":[[0,1.49,503.59]],"ltp":1.44,"tv":6475.55,"id":8535963}]}]}
{"op":"mcm","clk":"1005350985","pt":1580642226886,"mc":[{"id":"1.168219387","rc":[{"trd":[[1.45,42.01]],"batb":[[0,1.45,181.65]],"ltp":1.45,"tv":6517.56,"id":8535963}],"tv":19718.2}]}
{"op":"mcm","clk":"1005352035","pt":1580642232520,"mc":[{"id":"1.168219387","rc":[{"trd":[[1.45,127.47]],"batb":[[0,1.45,138.92]],"ltp":1.45,"tv":6603.02,"id":8535963}],"tv":19803.67}]}
{"op":"mcm","clk":"1005352615","pt":1580642235601,"mc":[{"id":"1.168219387","rc":[{"trd":[[1.45,350.97]],"batb":[[0,1.45,27.17],[1,1.42,405.58],[2,1.41,905.98]],"ltp":1.45,"tv":6826.52,"id":8535963},{"batl":[[0,3.4,5.69],[1,3.9,4.65],[2,3.95,4.7]],"ltp":3.15,"tv":13200.64,"id":2309796}],"tv":20027.16}]}
{"op":"mcm","clk":"1005354398","pt":1580642245744,"mc":[{"id":"1.168219387","rc":[{"batl":[[0,3.35,2.9],[1,3.4,5.69],[2,3.9,4.65]],"ltp":3.15,"tv":13200.64,"id":2309796}]}]}
{"op":"mcm","clk":"1005354481","pt":1580642246061,"mc":[{"id":"1.168219387","rc":[{"batl":[[0,3.4,5.69],[1,3.9,4.65],[2,3.95,4.7]],"ltp":3.15,"tv":13200.64,"id":2309796}]}]}
{"op":"mcm","clk":"1005355007","pt":1580642248740,"mc":[{"id":"1.168219387","rc":[{"batb":[[2,1.41,494.03]],"ltp":1.45,"tv":6826.52,"id":8535963}]}]}
{"op":"mcm","clk":"1005355129","pt":1580642249428,"mc":[{"id":"1.168219387","rc":[{"batl":[[0,1.49,23],[1,1.54,32.75],[2,1.55,339.09]],"ltp":1.45,"tv":6826.52,"id":8535963},{"batb":[[0,2.84,47.06],[1,1.97,17.17],[2,1.95,18.31]],"ltp":3.15,"tv":13200.64,"id":2309796}]}]}
{"op":"mcm","clk":"1005355544","pt":1580642251652,"mc":[{"id":"1.168219387","rc":[{"trd":[[1.49,33.81]],"batb":[[0,1.5,443.15],[1,1.49,288.15],[2,1.45,27.17]],"batl":[[0,1.54,47.95],[1,1.55,339.09],[2,1.56,1020.73]],"ltp":1.49,"tv":6849.52,"id":8535963},{"trd":[[3,89.61]],"batl":[[0,2.96,8.04],[1,3.05,138.3],[2,3.1,64.17]],"ltp":3.0,"tv":13212.06,"id":2309796}],"tv":20061.58}]}
{"op":"mcm","clk":"1005355730","pt":1580642252684,"mc":[{"id":"1.168219387","rc":[{"batb":[[0,1.5,477.16],[2,1.45,257.84]],"batl":[[1,1.55,227.62],[2,1.56,800.14]],"ltp":1.49,"tv":6849.52,"id":8535963},{"batb":[[1,2.48,61.14],[2,1.97,17.17]],"ltp":3.0,"tv":13212.06,"id":2309796}]}]}
{"op":"mcm","clk":"1005355860","pt":1580642253423,"mc":[{"id":"1.168219387","rc":[{"batb":[[2,1.45,211.83]],"batl":[[1,1.55,269.63]],"ltp":1.49,"tv":6849.52,"id":8535963},{"batb":[[0,2.84,69.75]],"ltp":3.0,"tv":13212.06,"id":2309796}]}]}
{"op":"mcm","clk":"1005356082","pt":1580642254532,"mc":[{"id":"1.168219387","rc":[{"batl":[[1,1.55,227.62]],"ltp":1.49,"tv":6849.52,"id":8535963}]}]}
{"op":"mcm","clk":"1005356220","pt":1580642255338,"mc":[{"id":"1.168219387","rc":[{"batb":[[0,1.5,408.65]],"batl":[[0,1.54,284.32]],"ltp":1.49,"tv":6849.52,"id":8535963}]}]}
{"op":"mcm","clk":"1005356430","pt":1580642256553,"mc":[{"id":"1.168219387","rc":[{"batb":[[2,1.46,487.31]],"ltp":1.49,"tv":6849.52,"id":8535963}]}]}
{"op":"mcm","clk":"1005356543","pt":1580642257137,"mc":[{"id":"1.168219387","rc":[{"batl":[[0,1.54,326.33]],"ltp":1.49,"tv":6849.52,"id":8535963}]}]}
{"op":"mcm","clk":"1005356784","pt":1580642258536,"mc":[{"id":"1.168219387","rc":[{"batb":[[2,1.48,494.03]],"batl":[[0,1.54,393.4],[2,1.56,1280.73]],"ltp":1.49,"tv":6849.52,"id":8535963},{"trd":[[2.96,15.76]],"batl":[[0,3.05,138.46],[1,3.1,64.17],[2,3.15,62.27]],"ltp":2.96,"tv":13227.82,"id":2309796}],"tv":20077.34}]}
{"op":"mcm","clk":"1005356872","pt":1580642258956,"mc":[{"id":"1.168219387","rc":[{"batl":[[2,3.15,65.17]],"ltp":2.96,"tv":13227.82,"id":2309796}]}]}
{"op":"mcm","clk":"1005357406","pt":1580642261563,"mc":[{"id":"1.168219387","rc":[{"trd":[[1.51,0.31]],"batl":[[0,1.51,19.69],[1,1.54,393.4],[2,1.55,227.62]],"ltp":1.51,"tv":6849.83,"id":8535963},{"trd":[[2.96,15.92]],"batl":[[0,3.05,138.3]],"ltp":2.96,"tv":13227.98,"id":2309796}],"tv":20077.81}]}
{"op":"mcm","clk":"1005358849","pt":1580642269258,"mc":[{"id":"1.168219387","rc":[{"trd":[[1.51,20],[1.54,37.27]],"batl":[[0,1.54,298.92],[1,1.55,227.62],[2,1.56,1280.73]],"ltp":1.54,"tv":6906.79,"id":8535963},{"trd":[[2.84,159.71],[2.96,25.96]],"batb":[[0,2.48,61.14],[1,1.97,17.17],[2,1.95,18.31]],"ltp":2.84,"tv":13397.72,"id":2309796}],"tv":20304.52}]}
{"op":"mcm","clk":"1005359478","pt":1580642272385,"mc":[{"id":"1.168219387","rc":[{"trd":[[1.5,864.37]],"batb":[[0,1.49,288.4],[1,1.48,494.03],[2,1.47,257.08]],"batl":[[1,1.55,269.63]],"ltp":1.5,"tv":7723.58,"id":8535963},{"batb":[[0,2.84,22.69],[1,2.48,61.14],[2,1.97,17.17]],"batl":[[2,3.15,84.49]],"ltp":2.84,"tv":13397.72,"id":2309796}],"tv":21121.31}]}
{"op":"mcm","clk":"1005359691","pt":1580642273494,"mc":[{"id":"1.168219387","rc":[{"batl":[[0,1.54,234.83],[1,1.55,42.01],[2,1.56,1047.73]],"ltp":1.5,"tv":7723.58,"id":8535963},{"batl":[[0,3.05,3.3]],"ltp":2.84,"tv":13397.72,"id":2309796}]}]}
{"op":"mcm","clk":"1005360022","pt":1580642275306,"mc":[{"id":"1.168219387","rc":[{"batb":[[0,1.48,494.03],[1,1.47,257.08],[2,1.46,1037.03]],"batl":[[0,1.55,42.01],[1,1.56,480.59],[2,1.58,497.4]],"ltp":1.5,"tv":7723.58,"id":8535963},{"batb":[[2,1.91,20.39]],"batl":[[0,3.15,22.22],[1,3.2,2.88],[2,3.25,2.86]],"ltp":2.84,"tv":13397.72,"id":2309796}]}]}
{"op":"mcm","clk":"1005360263","pt":1580642276530,"mc":[{"id":"1.168219387","rc":[{"batl":[[0,1.56,480.59],[1,1.58,497.4],[2,1.89,435.28]],"ltp":1.5,"tv":7723.58,"id":8535963},{"batb":[[0,2.48,61.14],[1,1.91,20.39],[2,1.82,24.14]],"batl":[[0,3.15,2.9]],"ltp":2.84,"tv":13397.72,"id":2309796}]}]}
{"op":"mcm","clk":"1005360647","pt":1580642278435,"mc":[{"id":"1.168219387","rc":[{"batl":[[2,1.64,195.81]],"ltp":1.5,"tv":7723.58,"id":8535963},{"batb":[[0,2.54,57.44]],"ltp":2.84,"tv":13397.72,"id":2309796}]}]}
{"op":"mcm","clk":"1005360845","pt":1580642279444,"mc":[{"id":"1.168219387","rc":[{"batb":[[0,1.49,232.73],[1,1.48,494.03],[2,1.47,257.08]],"ltp":1.5,"tv":7723.58,"id":8535963}]}]}
{"op":"mcm","clk":"1005361000","pt":1580642280346,"mc":[{"id":"1.168219387","rc":[{"batl":[[0,1.64,195.81],[1,1.65,183.57],[2,1.89,435.28]],"ltp":1.5,"tv":7723.58,"id":8535963}]}]}
{"op":"mcm","clk":"1005361176","pt":1580642281093,"mc":[{"id":"1.168219387","rc":[{"batl":[[2,2.1,5.45]],"ltp":1.5,"tv":7723.58,"id":8535963}]}]}
{"op":"mcm","clk":"1005361451","pt":1580642282742,"mc":[{"id":"1.168219387","rc":[{"batl":[[0,1.64,210.09],[2,1.69,278]],"ltp":1.5,"tv":7723.58,"id":8535963},{"batb":[[1,2.46,353.02],[2,1.91,20.39]],"batl":[[0,2.62,1844.66],[1,2.66,10.31],[2,2.68,2473.6]],"ltp":2.84,"tv":13397.72,"id":2309796}]}]}
{"op":"mcm","clk":"1005361649","pt":1580642283756,"mc":[{"id":"1.168219387","rc":[{"batb":[[0,1.6,42.69],[1,1.59,519.53],[2,1.58,216.46]],"batl":[[0,1.64,252.1],[1,1.65,225.58]],"ltp":1.5,"tv":7723.58,"id":8535963},{"batb":[[0,2.54,84.32],[2,2.2,86.47]],"batl":[[0,2.62,184.47],[2,2.68,167.64]],"ltp":2.84,"tv":13397.72,"id":2309796}]}]}
{"op":"mcm","clk":"1005361749","pt":1580642284242,"mc":[{"id":"1.168219387","rc":[{"batl":[[0,1.64,210.09]],"ltp":1.5,"tv":7723.58,"id":8535963}]}]}
{"op":"mcm","clk":"1005362794","pt":1580642289652,"mc":[{"id":"1.168219387","rc":[{"batl":[[2,1.67,480.59]],"ltp":1.5,"tv":7723.58,"id":8535963}]}]}
{"op":"mcm","clk":"1005363762","pt":1580642294260,"mc":[{"id":"1.168219387","rc":[{"batb":[[2,1.58,319.8]],"ltp":1.5,"tv":7723.58,"id":8535963}]}]}
{"op":"mcm","clk":"1005365608","pt":1580642303728,"mc":[{"id":"1.168219387","rc":[{"batl":[[2,2.68,8.64]],"ltp":2.84,"tv":13397.72,"id":2309796}]}]}
{"op":"mcm","clk":"1005365739","pt":1580642304526,"mc":[{"id":"1.168219387","rc":[{"batb":[[0,1.58,103.34],[1,1.57,494.03],[2,1.55,510.84]],"batl":[[0,1.67,480.59],[1,1.69,497.4],[2,2.16,342.82]],"ltp":1.5,"tv":7723.58,"id":8535963},{"batb":[[0,2.2,86.08],[1,1.8,75.72],[2,1.75,21.19]],"batl":[[0,2.94,7.25],[1,3.1,6.35],[2,6.4,2.73]],"ltp":2.84,"tv":13397.72,"id":2309796}]}]}
{"op":"mcm","clk":"1005366339","pt":1580642307713,"mc":[{"id":"1.168219387","rc":[{"batl":[[2,1.83,254.01]],"ltp":1.5,"tv":7723.58,"id":8535963}]}]}
{"op":"mcm","clk":"1005367746","pt":1580642315376,"mc":[{"id":"1.168219387","rc":[{"batb":[[0,1.64,21],[1,1.58,103.34],[2,1.57,494.03]],"ltp":1.5,"tv":7723.58,"id":8535963}]}]}
{"op":"mcm","clk":"1005368755","pt":1580642320506,"mc":[{"id":"1.168219387","rc":[{"batb":[[1,1.52,39.99],[2,1.51,567.61]],"batl":[[2,2.16,342.82]],"ltp":1.5,"tv":7723.58,"id":8535963}]}]}
{"op":"mcm","clk":"1005368947","pt":1580642321680,"mc":[{"id":"1.168219387","rc":[{"trd":[[1.67,607.45]],"batl":[[0,1.67,442.73],[2,2.34,4.25]],"ltp":1.67,"tv":7799.3,"id":8535963}],"tv":21197.03}]}
{"op":"mcm","clk":"1005369119","pt":1580642322702,"mc":[{"id":"1.168219387","rc":[{"trd":[[1.64,42]],"batb":[[0,1.52,39.99],[1,1.51,2057.68],[2,1.5,597.15]],"batl":[[0,1.55,1451.61],[1,1.59,279],[2,1.67,442.73]],"ltp":1.64,"tv":7841.31,"id":8535963},{"batb":[[0,2.84,5.53],[1,2.72,272.24],[2,2.2,86.08]],"batl":[[0,2.92,6.87],[1,2.94,7.25],[2,2.96,139]],"ltp":2.84,"tv":13397.72,"id":2309796}],"tv":21239.03}]}
{"op":"mcm","clk":"1005369277","pt":1580642323505,"mc":[{"id":"1.168219387","rc":[{"batl":[[1,1.56,353.23],[2,1.57,217.78]],"ltp":1.64,"tv":7841.31,"id":8535963},{"batb":[[1,2.8,45.24],[2,2.72,272.24]],"ltp":2.84,"tv":13397.72,"id":2309796}]}]}
{"op":"mcm","clk":"1005369333","pt":1580642323814,"mc":[{"id":"1.168219387","rc":[{"batb":[[0,1.51,2057.68],[1,1.5,597.15],[2,1.48,40.01]],"ltp":1.64,"tv":7841.31,"id":8535963},{"batl":[[1,2.96,139],[2,3,166.56]],"ltp":2.84,"tv":13397.72,"id":2309796}]}]}
{"op":"mcm","clk":"1005369811","pt":1580642326308,"mc":[{"id":"1.168219387","rc":[{"batb":[[2,2.72,296.61]],"ltp":2.84,"tv":13397.72,"id":2309796}]}]}
{"op":"mcm","clk":"1005370836","pt":1580642331239,"mc":[{"id":"1.168219387","rc":[{"trd":[[1.55,81.58]],"batl":[[0,1.55,1410.82]],"ltp":1.55,"tv":7922.89,"id":8535963}],"tv":21320.61}]}
{"op":"mcm","clk":"1005371247","pt":1580642333362,"mc":[{"id":"1.168219387","rc":[{"trd":[[1.55,88.31]],"batl":[[0,1.55,1407.46]],"ltp":1.55,"tv":7929.61,"id":8535963}],"tv":21327.34}]}
{"op":"mcm","clk":"1005372257","pt":1580642338466,"mc":[{"id":"1.168219387","rc":[{"trd":[[1.55,142.87]],"batl":[[0,1.55,1380.18]],"ltp":1.55,"tv":7984.17,"id":8535963}],"tv":21381.9}]}
{"op":"mcm","clk":"1005372771","pt":1580642341040,"mc":[{"id":"1.168219387","rc":[{"trd":[[1.55,153.77]],"batl":[[0,1.55,1374.73]],"ltp":1.55,"tv":7995.08,"id":8535963}],"tv":21392.8}]}
{"op":"mcm","clk":"1005373251","pt":1580642343451,"mc":[{"id":"1.168219387","rc":[{"trd":[[1.55,164.13]],"batl":[[0,1.55,1369.55]],"ltp":1.55,"tv":8005.44,"id":8535963}],"tv":21403.17}]}
{"op":"mcm","clk":"1005373489","pt":1580642344671,"mc":[{"id":"1.168219387","rc":[{"trd":[[1.52,6.09]],"batl":[[1,1.56,327.45]],"ltp":1.52,"tv":8008.17,"id":8535963},{"trd":[[2.92,1.42]],"batl":[[0,2.92,5.45],[1,3,166.56],[2,3.05,20.16]],"ltp":2.92,"tv":13399.14,"id":2309796}],"tv":21407.32}]}
{"op":"mcm","clk":"1005373693","pt":1580642345582,"mc":[{"id":"1.168219387","rc":[{"batb":[[0,1.47,89.06],[1,1.46,42.38],[2,1.45,27.17]],"batl":[[0,1.58,42.01],[1,1.95,409.86],[2,2.18,4.75]],"ltp":1.52,"tv":8008.17,"id":8535963},{"batb":[[0,2.72,24.37],[1,2.4,67.98],[2,1.85,17.57]],"batl":[[0,3.05,20.16],[1,3.2,6.43],[2,3.35,6.1]],"ltp":2.92,"tv":13399.14,"id":2309796}]}]}
{"op":"mcm","clk":"1005373900","pt":1580642346559,"mc":[{"id":"1.168219387","rc":[{"batb":[[0,1.45,27.17],[1,1.44,187.34],[2,1.43,63.71]],"batl":[[0,1.95,409.86],[1,2.18,4.75],[2,2.34,4.25]],"ltp":1.52,"tv":8008.17,"id":8535963},{"batb":[[0,2.4,67.98],[1,1.85,17.57],[2,1.8,75.72]],"batl":[[0,3.35,6.1],[1,6.4,2.73],[2,7,2.27]],"ltp":2.92,"tv":13399.14,"id":2309796}]}]}
{"op":"mcm","clk":"1005374526","pt":1580642349549,"mc":[{"id":"1.168219387","rc":[{"batb":[[1,1.44,696.84],[2,1.43,385.62]],"batl":[[0,1.72,313.17],[1,1.74,308.13],[2,1.95,409.86]],"ltp":1.52,"tv":8008.17,"id":8535963}]}]}
{"op":"mcm","clk":"1005375354","pt":1580642354044,"mc":[{"id":"1.168219387","rc":[{"batb":[[1,1.44,187.34],[2,1.43,63.71]],"ltp":1.52,"tv":8008.17,"id":8535963}]}]}
{"op":"mcm","clk":"1005375816","pt":1580642356740,"mc":[{"id":"1.168219387","rc":[{"batb":[[0,1.66,1355.42],[1,1.45,27.17],[2,1.44,187.34]],"batl":[[0,1.72,1621.31],[2,2.18,4.75]],"ltp":1.52,"tv":8008.17,"id":8535963},{"batl":[[0,2.52,242.98],[1,3.35,6.1],[2,6.4,2.73]],"ltp":2.92,"tv":13399.14,"id":2309796}]}]}
{"op":"mcm","clk":"1005376006","pt":1580642357755,"mc":[{"id":"1.168219387","rc":[{"batb":[[0,1.67,42.47],[1,1.66,1777.89],[2,1.65,184.76]],"batl":[[0,1.72,1663.32],[2,1.76,733.79]],"ltp":1.52,"tv":8008.17,"id":8535963},{"batb":[[0,2.4,97.39],[1,1.95,122.9],[2,1.85,17.57]],"batl":[[0,2.5,9.39],[1,2.52,174],[2,2.96,1852.33]],"ltp":2.92,"tv":13399.14,"id":2309796}]}]}
{"op":"mcm","clk":"1005376040","pt":1580642357930,"mc":[{"id":"1.168219387","rc":[{"batl":[[2,2.68,24.37]],"ltp":2.92,"tv":13399.14,"id":2309796}]}]}
{"op":"mcm","clk":"1005376445","pt":1580642360152,"mc":[{"id":"1.168219387","rc":[{"batl":[[0,1.7,10.97],[1,1.72,1663.32],[2,1.74,308.13]],"ltp":1.52,"tv":8008.17,"id":8535963},{"batl":[[0,2.5,18.34]],"ltp":2.92,"tv":13399.14,"id":2309796}]}]}
{"op":"mcm","clk":"1005377567","pt":1580642365814,"mc":[{"id":"1.168219387","rc":[{"trd":[[1.67,634.74]],"batb":[[0,1.67,28.83]],"ltp":1.67,"tv":8035.46,"id":8535963}],"tv":21434.6}]}
{"op":"mcm","clk":"1005377891","pt":1580642367613,"mc":[{"id":"1.168219387","rc":[{"trd":[[1.7,12.48]],"batl":[[0,1.7,4.8]],"ltp":1.7,"tv":8047.79,"id":8535963}],"tv":21446.94}]}
{"op":"mcm","clk":"1005379546","pt":1580642376614,"mc":[{"id":"1.168219387","rc":[{"batb":[[0,1.64,494.03],[1,1.62,510.84],[2,1.53,146.82]],"batl":[[0,1.77,480.59],[1,1.79,497.4],[2,2.22,329.01]],"ltp":1.7,"tv":8047.79,"id":8535963},{"batb":[[0,1.95,62],[1,1.8,75.72],[2,1.7,75.72]],"batl":[[0,2.94,6.75],[1,3.15,6.1],[2,3.35,6.1]],"ltp":2.92,"tv":13399.14,"id":2309796}]}]}
{"op":"mcm","clk":"1005379755","pt":1580642377648,"mc":[{"id":"1.168219387","rc":[{"batl":[[0,2.42,1.68],[1,2.94,6.75],[2,3.15,6.1]],"ltp":2.92,"tv":13399.14,"id":2309796}]}]}
{"op":"mcm","clk":"1005379842","pt":1580642378211,"mc":[{"id":"1.168219387","rc":[{"batb":[[1,1.7,75.72],[2,1.6,75.72]],"ltp":2.92,"tv":13399.14,"id":2309796}]}]}
{"op":"mcm","clk":"1005380110","pt":1580642379753,"mc":[{"id":"1.168219387","rc":[{"batb":[[2,1.53,369.09]],"batl":[[2,2.06,239.19]],"ltp":1.7,"tv":8047.79,"id":8535963},{"batl":[[0,2.42,3.46]],"ltp":2.92,"tv":13399.14,"id":2309796}]}]}
{"op":"mcm","clk":"1005380167","pt":1580642380030,"mc":[{"id":"1.168219387","rc":[{"batl":[[0,2.42,1.78]],"ltp":2.92,"tv":13399.14,"id":2309796}]}]}
{"op":"mcm","clk":"1005380481","pt":1580642381725,"mc":[{"id":"1.168219387","rc":[{"batb":[[0,1.53,369.09],[1,1.52,288],[2,1.47,43.67]],"batl":[[2,2.22,329.01]],"ltp":1.7,"tv":8047.79,"id":8535963}]}]}
{"op":"mcm","clk":"1005380664","pt":1580642382581,"mc":[{"id":"1.168219387","rc":[{"batl":[[2,1000,0.02]],"ltp":1.7,"tv":8047.79,"id":8535963},{"batl":[[0,2.94,6.75],[1,3.15,6.1],[2,3.35,6.1]],"ltp":2.92,"tv":13399.14,"id":2309796}]}]}
{"op":"mcm","clk":"1005381012","pt":1580642384448,"mc":[{"id":"1.168219387","rc":[{"batb":[[0,1.54,10.66],[1,1.53,369.09],[2,1.52,288]],"batl":[[0,1.55,328.36],[1,1.56,9.03],[2,1.57,270.64]],"ltp":1.7,"tv":8047.79,"id":8535963},{"batb":[[0,2.74,136.86],[1,1.95,62],[2,1.7,75.72]],"batl":[[0,2.92,154],[1,2.94,6.75],[2,2.96,324.01]],"ltp":2.92,"tv":13399.14,"id":2309796}]}]}
{"op":"mcm","clk":"1005381212","pt":1580642385555,"mc":[{"id":"1.168219387","rc":[{"batb":[[1,2.72,48.39],[2,2.34,73.1]],"ltp":2.92,"tv":13399.14,"id":2309796}]}]}
{"op":"mcm","clk":"1005381902","pt":1580642389472,"mc":[{"id":"1.168219387","rc":[{"trd":[[1.55,167.17]],"batl":[[0,1.55,325.32]],"ltp":1.55,"tv":8050.83,"id":8535963},{"trd":[[2.8,1.68]],"batb":[[2,2.68,24.37]],"ltp":2.8,"tv":13400.82,"id":2309796}],"tv":21451.66}]}
{"op":"mcm","clk":"1005382144","pt":1580642390753,"mc":[{"id":"1.168219387","rc":[{"batl":[[2,1.57,751.23]],"ltp":1.55,"tv":8050.83,"id":8535963}]}]}
{"op":"mcm","clk":"1005382486","pt":1580642392656,"mc":[{"id":"1.168219387","rc":[{"trd":[[1.55,170.39]],"batl":[[0,1.55,322.1]],"ltp":1.55,"tv":8054.05,"id":8535963},{"trd":[[2.8,3.46]],"ltp":2.8,"tv":13402.6,"id":2309796}],"tv":21456.66}]}
{"op":"mcm","clk":"1005382670","pt":1580642393650,"mc":[{"id":"1.168219387","rc":[{"trd":[[1.55,171.74]],"batl":[[0,1.55,321.43]],"ltp":1.55,"tv":8055.39,"id":8535963}],"tv":21458.0}]}
{"op":"mcm","clk":"1005383067","pt":1580642395993,"mc":[{"id":"1.168219387","rc":[{"trd":[[1.55,188.1]],"batl":[[0,1.55,313.25]],"ltp":1.55,"tv":8071.76,"id":8535963}],"tv":21474.36}]}
{"op":"mcm","clk":"1005383764","pt":1580642399686,"mc":[{"id":"1.168219387","rc":[{"trd":[[1.55,190.07]],"batb":[[0,1.53,146.82],[1,1.51,494.03],[2,1.49,596.54]],"batl":[[0,1.55,311.28],[1,1.57,480.59],[2,1.59,539.41]],"ltp":1.55,"tv":8073.73,"id":8535963},{"trd":[[2.8,4.55]],"batl":[[0,3,21],[1,3.2,5.03],[2,3.35,6.1]],"ltp":2.8,"tv":13403.69,"id":2309796}],"tv":21477.43}]}
{"op":"mcm","clk":"1005383937","pt":1580642400593,"mc":[{"id":"1.168219387","rc":[{"batb":[[0,1.55,13.64],[2,1.49,510.84]],"batl":[[0,1.57,480.59],[1,1.59,497.4],[2,1.95,409.86]],"ltp":1.55,"tv":8073.73,"id":8535963},{"batb":[[0,2.34,73.1],[1,1.84,19.72],[2,1.8,75.72]],"batl":[[0,3.2,5.03],[1,3.35,6.1],[2,6.4,2.73]],"ltp":2.8,"tv":13403.69,"id":2309796}]}]}
{"op":"mcm","clk":"1005384346","pt":1580642402577,"mc":[{"id":"1.168219387","rc":[{"batl":[[2,1.73,223.25]],"ltp":1.55,"tv":8073.73,"id":8535963}]}]}
{"op":"mcm","clk":"1005384600","pt":1580642403879,"mc":[{"id":"1.168219387","rc":[{"batb":[[0,1.55,15.83]],"ltp":1.55,"tv":8073.73,"id":8535963}]}]}
{"op":"mcm","clk":"1005386448","pt":1580642413328,"mc":[{"id":"1.168219387","rc":[{"trd":[[1.55,195.75]],"batb":[[0,1.55,12.99]],"ltp":1.55,"tv":8079.4,"id":8535963}],"tv":21483.1}]}
{"op":"mcm","clk":"1005387666","pt":1580642420260,"mc":[{"id":"1.168219387","rc":[{"batb":[[0,1.55,10.8]],"ltp":1.55,"tv":8079.4,"id":8535963}]}]}
{"op":"mcm","clk":"1005389965","pt":1580642432978,"mc":[{"id":"1.168219387","rc":[{"batl":[[0,1.73,223.25],[1,1.75,302.88],[2,1.95,409.86]],"ltp":1.55,"tv":8079.4,"id":8535963}]}]}
{"op":"mcm","clk":"1005390282","pt":1580642434679,"mc":[{"id":"1.168219387","rc":[{"batl":[[2,2.2,5.33]],"ltp":1.55,"tv":8079.4,"id":8535963}]}]}
{"op":"mcm","clk":"1005390453","pt":1580642435683,"mc":[{"id":"1.168219387","rc":[{"batb":[[0,1.68,243.97],[1,1.67,176.78],[2,1.66,523.06]],"batl":[[2,1.77,186]],"ltp":1.55,"tv":8079.4,"id":8535963},{"batb":[[0,2.36,12.63],[1,2.34,73.1],[2,1.84,19.72]],"batl":[[0,2.46,12.07],[1,2.48,398.36],[2,2.52,148.81]],"ltp":2.8,"tv":13403.69,"id":2309796}]}]}
{"op":"mcm","clk":"1005390663","pt":1580642436760,"mc":[{"id":"1.168219387","rc":[{"batb":[[0,1.69,102.99],[1,1.68,243.97],[2,1.67,176.78]],"ltp":1.55,"tv":8079.4,"id":8535963},{"batb":[[2,1.92,64.6]],"ltp":2.8,"tv":13403.69,"id":2309796}]}]}
{"op":"mcm","clk":"1005390785","pt":1580642437491,"mc":[{"id":"1.168219387","rc":[{"batl":[[0,1.73,265.26]],"ltp":1.55,"tv":8079.4,"id":8535963},{"batb":[[0,2.36,42.88]],"ltp":2.8,"tv":13403.69,"id":2309796}]}]}
{"op":"mcm","clk":"1005392058","pt":1580642444383,"mc":[{"id":"1.168219387","rc":[{"trd":[[2.36,10.68]],"batb":[[0,2.36,37.54]],"ltp":2.36,"tv":13414.38,"id":2309796}],"tv":21493.79}]}
{"op":"mcm","clk":"1005393180","pt":1580642450403,"mc":[{"id":"1.168219387","rc":[{"trd":[[1.69,16.37]],"batb":[[0,1.69,94.81]],"ltp":1.69,"tv":8095.77,"id":8535963}],"tv":21510.15}]}
{"op":"mcm","clk":"1005393935","pt":1580642454538,"mc":[{"id":"1.168219387","rc":[{"batb":[[0,2.36,30.25]],"batl":[[0,2.48,398.36],[1,2.52,148.81],[2,2.64,25.21]],"ltp":2.36,"tv":13414.38,"id":2309796}]}]}
{"op":"mcm","clk":"1005394127","pt":1580642455660,"mc":[{"id":"1.168219387","rc":[{"batl":[[0,1.7,4.2],[1,1.73,265.26],[2,1.75,302.88]],"ltp":1.69,"tv":8095.77,"id":8535963}]}]}
{"op":"mcm","clk":"1005394468","pt":1580642457555,"mc":[{"id":"1.168219387","rc":[{"trd":[[1.7,16.68]],"batl":[[0,1.73,265.26],[1,1.75,302.88],[2,1.78,512.83]],"ltp":1.7,"tv":8099.97,"id":8535963},{"trd":[[2.42,2.95]],"batb":[[0,2.36,37.54]],"batl":[[0,2.42,4.87],[1,2.48,234.36],[2,2.52,148.81]],"ltp":2.42,"tv":13417.33,"id":2309796}],"tv":21517.3}]}
{"op":"mcm","clk":"1005394692","pt":1580642458578,"mc":[{"id":"1.168219387","rc":[{"batb":[[0,1.61,103.34],[1,1.55,151.25],[2,1.52,39.74]],"batl":[[0,2.22,329.01],[1,1000,0.02],[2,1.78,0]],"ltp":1.7,"tv":8099.97,"id":8535963},{"batb":[[0,1.92,64.6],[1,1.7,75.72],[2,1.6,75.72]],"batl":[[0,2.94,5.25],[1,3.2,5.03],[2,3.35,6.1]],"ltp":2.42,"tv":13417.33,"id":2309796}]}]}
{"op":"mcm","clk":"1005395031","pt":1580642460557,"mc":[{"id":"1.168219387","rc":[{"batl":[[0,2.36,2.73],[1,2.94,5.25],[2,3.2,5.03]],"ltp":2.42,"tv":13417.33,"id":2309796}]}]}
{"op":"mcm","clk":"1005395114","pt":1580642461020,"mc":[{"id":"1.168219387","rc":[{"batb":[[2,1.54,255.49]],"batl":[[0,2.08,244.68],[1,2.1,174.7],[2,2.22,329.01]],"ltp":1.7,"tv":8099.97,"id":8535963}]}]}
{"op":"mcm","clk":"1005395599","pt":1580642463766,"mc":[{"id":"1.168219387","rc":[{"batb":[[1,1.56,389.85],[2,1.55,151.25]],"ltp":1.7,"tv":8099.97,"id":8535963}]}]}
{"op":"mcm","clk":"1005396067","pt":1580642466527,"mc":[{"id":"1.168219387","rc":[{"batl":[[0,2.22,329.01],[1,1000,0.02],[2,2.22,0]],"ltp":1.7,"tv":8099.97,"id":8535963}]}]}
{"op":"mcm","clk":"1005396157","pt":1580642467055,"mc":[{"id":"1.168219387","rc":[{"batl":[[0,2.06,233.57],[1,2.22,329.01],[2,1000,0.02]],"ltp":1.7,"tv":8099.97,"id":8535963}]}]}
{"op":"mcm","clk":"1005396434","pt":1580642468565,"mc":[{"id":"1.168219387","rc":[{"batl":[[0,1000,0.02],[1,2.22,0],[2,1000,0]],"ltp":1.7,"tv":8099.97,"id":8535963}]}]}
{"op":"mcm","clk":"1005396609","pt":1580642469560,"mc":[{"id":"1.168219387","rc":[{"batb":[[0,2.02,118.85],[1,1.94,536.67],[2,1.81,118.85]],"batl":[[0,2.12,36.97],[1,2.14,232],[2,2.16,558.76]],"ltp":1.7,"tv":8099.97,"id":8535963},{"batb":[[0,1.93,218.24],[1,1.92,64.6],[2,1.91,227.58]],"batl":[[0,2,182.9],[1,2.02,419.73],[2,2.36,2.73]],"ltp":2.42,"tv":13417.33,"id":2309796}]}]}
{"op":"mcm","clk":"1005396819","pt":1580642470632,"mc":[{"id":"1.168219387","rc":[{"batb":[[1,2,120.38],[2,1.94,536.67]],"ltp":1.7,"tv":8099.97,"id":8535963},{"batl":[[2,2.06,39.49]],"ltp":2.42,"tv":13417.33,"id":2309796}]}]}
{"op":"mcm","clk":"1005397073","pt":1580642472182,"mc":[{"id":"1.168219387","rc":[{"batb":[[1,2,127.85]],"batl":[[0,2.06,9.23],[1,2.12,36.97],[2,2.14,232]],"ltp":1.7,"tv":8099.97,"id":8535963},{"batl":[[0,2,190.37]],"ltp":2.42,"tv":13417.33,"id":2309796}]}]}
{"op":"mcm","clk":"1005399187","pt":1580642484148,"mc":[{"id":"1.168219387","rc":[{"trd":[[2.06,396.58]],"batl":[[0,2.06,8.28]],"ltp":2.06,"tv":8100.92,"id":8535963},{"trd":[[1.94,421.11]],"ltp":1.94,"tv":13418.34,"id":2309796}],"tv":21519.26}]}
{"op":"mcm","clk":"1005399947","pt":1580642488390,"mc":[{"id":"1.168219387","rc":[{"trd":[[2.06,402.04]],"batl":[[0,2.06,5.55]],"ltp":2.06,"tv":8106.38,"id":8535963}],"tv":21524.72}]}
{"op":"mcm","clk":"1005400080","pt":1580642489075,"mc":[{"id":"1.168219387","rc":[{"batb":[[0,1.96,22.72],[1,1.93,218.24],[2,1.92,64.6]],"ltp":1.94,"tv":13418.34,"id":2309796}]}]}
{"op":"mcm","clk":"1005400808","pt":1580642493478,"mc":[{"id":"1.168219387","rc":[{"trd":[[2.02,619.82],[2.06,407.59]],"batb":[[0,2.02,116.7]],"batl":[[0,2.12,36.97],[1,2.14,232],[2,2.16,558.76]],"ltp":2.06,"tv":8114.08,"id":8535963},{"trd":[[1.91,224.87],[1.92,589.59],[1.93,436.48],[1.94,427],[1.96,465.53],[1.99,2.18]],"batb":[[0,1.91,131.8],[1,1.9,46.21],[2,1.84,74.28]],"batl":[[0,1.94,133.55],[1,2,190.37],[2,2.02,419.73]],"ltp":1.91,"tv":14229.08,"id":2309796}],"tv":22343.17}]}
{"op":"mcm","clk":"1005400966","pt":1580642494479,"mc":[{"id":"1.168219387","rc":[{"batb":[[1,2,120.38]],"ltp":2.06,"tv":8114.08,"id":8535963},{"batb":[[0,1.9,46.21],[1,1.84,74.28],[2,1.55,20]],"batl":[[0,1.93,100],[1,1.94,133.55]],"ltp":1.91,"tv":14229.08,"id":2309796}]}]}
{"op":"mcm","clk":"1005401287","pt":1580642496279,"mc":[{"id":"1.168219387","rc":[{"batb":[[1,2,118.89]],"ltp":2.06,"tv":8114.08,"id":8535963},{"batb":[[0,1.91,65.31],[1,1.9,46.21],[2,1.83,75.22]],"ltp":1.91,"tv":14229.08,"id":2309796}]}]}
{"op":"mcm","clk":"1005401476","pt":1580642497279,"mc":[{"id":"1.168219387","rc":[{"batl":[[0,2.08,7.55],[1,2.12,36.97],[2,2.14,232]],"ltp":2.06,"tv":8114.08,"id":8535963},{"batb":[[0,1.92,161.89],[1,1.91,65.31],[2,1.9,277.6]],"batl":[[2,1.96,7.47]],"ltp":1.91,"tv":14229.08,"id":2309796}]}]}
{"op":"mcm","clk":"1005401726","pt":1580642498623,"mc":[{"id":"1.168219387","rc":[{"batl":[[0,2.12,36.97],[1,2.14,232],[2,2.16,558.76]],"ltp":2.06,"tv":8114.08,"id":8535963},{"batl":[[2,1.99,247.07]],"ltp":1.91,"tv":14229.08,"id":2309796}]}]}
{"op":"mcm","clk":"1005401877","pt":1580642499501,"mc":[{"id":"1.168219387","rc":[{"batl":[[1,1.99,247.07],[2,2.02,519.15]],"ltp":1.91,"tv":14229.08,"id":2309796}]}]}
{"op":"mcm","clk":"1005402251","pt":1580642501531,"mc":[{"id":"1.168219387","rc":[{"batl":[[0,2.08,7.55],[1,2.12,36.97],[2,2.14,232]],"ltp":2.06,"tv":8114.08,"id":8535963},{"batl":[[1,1.96,7.47],[2,1.99,247.07]],"ltp":1.91,"tv":14229.08,"id":2309796}]}]}
{"op":"mcm","clk":"1005402428","pt":1580642502591,"mc":[{"id":"1.168219387","rc":[{"trd":[[1.92,856.69]],"batb":[[0,1.92,28.34]],"ltp":1.92,"tv":14496.18,"id":2309796}],"tv":22610.27}]}
{"op":"mcm","clk":"1005402567","pt":1580642503441,"mc":[{"id":"1.168219387","rc":[{"batl":[[0,2.12,36.97],[1,2.14,232],[2,2.16,558.76]],"ltp":2.06,"tv":8114.08,"id":8535963},{"trd":[[1.92,890.3],[1.93,439.84]],"batb":[[0,1.91,65.31],[1,1.9,46.21],[2,1.83,75.22]],"batl":[[0,1.93,98.32],[1,2.02,224],[2,2.06,39.49]],"ltp":1.93,"tv":14533.15,"id":2309796}],"tv":22647.23}]}
{"op":"mcm","clk":"1005402740","pt":1580642504344,"mc":[{"id":"1.168219387","rc":[{"batb":[[0,2.02,233.7],[1,1.94,536.67],[2,1.93,44.53]],"ltp":2.06,"tv":8114.08,"id":8535963}]}]}
{"op":"mcm","clk":"1005403057","pt":1580642506408,"mc":[{"id":"1.168219387","rc":[{"trd":[[2.08,488.65]],"batl":[[0,2.08,4.48],[1,2.12,36.97],[2,2.14,232]],"ltp":2.08,"tv":8117.15,"id":8535963},{"trd":[[1.92,893.63]],"batb":[[0,1.91,268.3],[2,1.89,235.29]],"batl":[[1,1.96,7.47],[2,1.98,217.48]],"ltp":1.92,"tv":14536.47,"id":2309796}],"tv":22653.63}]}
{"op":"mcm","clk":"1005403688","pt":1580642510251,"mc":[{"id":"1.168219387","rc":[{"batb":[[2,1.86,75.61]],"ltp":2.08,"tv":8117.15,"id":8535963}]}]}
{"op":"mcm","clk":"1005404228","pt":1580642513114,"mc":[{"id":"1.168219387","rc":[{"batb":[[1,1.96,43.69],[2,1.94,536.67]],"ltp":2.08,"tv":8117.15,"id":8535963}]}]}
{"op":"mcm","clk":"1005404423","pt":1580642514222,"mc":[{"id":"1.168219387","rc":[{"batl":[[0,1.96,7.47],[1,1.98,217.48],[2,2,201.71]],"ltp":1.92,"tv":14536.47,"id":2309796}]}]}
{"op":"mcm","clk":"1005404837","pt":1580642516524,"mc":[{"id":"1.168219387","rc":[{"batl":[[0,2.12,36.97],[1,2.14,232],[2,2.16,558.76]],"ltp":2.08,"tv":8117.15,"id":8535963},{"batl":[[0,1.98,217.48],[1,2,201.71],[2,2.02,224]],"ltp":1.92,"tv":14536.47,"id":2309796}]}]}
{"op":"mcm","clk":"1005404977","pt":1580642517321,"mc":[{"id":"1.168219387","rc":[{"batl":[[0,1.92,98.32],[1,1.98,217.48],[2,2,201.71]],"ltp":1.92,"tv":14536.47,"id":2309796}]}]}
{"op":"mcm","clk":"1005405397","pt":1580642519534,"mc":[{"id":"1.168219387","rc":[{"trd":[[1.92,908.95]],"batl":[[0,1.92,102.02],[1,1.96,10.73],[2,1.98,217.48]],"ltp":1.92,"tv":14551.79,"id":2309796}],"tv":22668.95}]}
{"op":"mcm","clk":"1005405808","pt":1580642521410,"mc":[{"id":"1.168219387","rc":[{"batb":[[0,1.91,223.57],[1,1.89,235.29],[2,1.83,75.22]],"batl":[[2,2.02,224]],"ltp":1.92,"tv":14551.79,"id":2309796}]}]}
{"op":"mcm","clk":"1005406130","pt":1580642523215,"mc":[{"id":"1.168219387","rc":[{"trd":[[2.08,492.01]],"ltp":2.08,"tv":8120.51,"id":8535963},{"trd":[[1.92,912.59]],"batb":[[2,1.84,224.33]],"batl":[[0,1.92,98.38]],"ltp":1.92,"tv":14555.43,"id":2309796}],"tv":22675.95}]}
{"op":"mcm","clk":"1005406400","pt":1580642524753,"mc":[{"id":"1.168219387","rc":[{"batb":[[0,2.04,115.51],[1,2.02,233.7],[2,1.96,43.69]],"ltp":2.08,"tv":8120.51,"id":8535963},{"batb":[[1,1.9,67.19],[2,1.89,282.34]],"batl":[[2,1.97,157.99]],"ltp":1.92,"tv":14555.43,"id":2309796}]}]}
{"op":"mcm","clk":"1005406461","pt":1580642525024,"mc":[{"id":"1.168219387","rc":[{"batb":[[1,2.02,116.7]],"ltp":2.08,"tv":8120.51,"id":8535963},{"batb":[[0,1.91,158.26]],"ltp":1.92,"tv":14555.43,"id":2309796}]}]}
{"op":"mcm","clk":"1005406719","pt":1580642526354,"mc":[{"id":"1.168219387","rc":[{"batl":[[0,1.92,87.02]],"ltp":1.92,"tv":14555.43,"id":2309796}]}]}
{"op":"mcm","clk":"1005407372","pt":1580642529735,"mc":[{"id":"1.168219387","rc":[{"trd":[[1.91,247.59]],"batb":[[0,1.91,146.9]],"batl":[[1,1.97,157.99],[2,1.99,204.79]],"ltp":1.91,"tv":14578.15,"id":2309796}],"tv":22698.67}]}
{"op":"mcm","clk":"1005407413","pt":1580642529947,"mc":[{"id":"1.168219387","rc":[{"batb":[[0,1.9,67.19],[1,1.89,47.05],[2,1.84,224.33]],"ltp":1.91,"tv":14578.15,"id":2309796}]}]}
{"op":"mcm","clk":"1005407957","pt":1580642532763,"mc":[{"id":"1.168219387","rc":[{"batl":[[0,2.12,48.84]],"ltp":2.08,"tv":8120.51,"id":8535963},{"batl":[[1,1.94,9.31],[2,1.97,157.99]],"ltp":1.91,"tv":14578.15,"id":2309796}]}]}
{"op":"mcm","clk":"1005407979","pt":1580642532832,"mc":[{"id":"1.168219387","rc":[{"batb":[[0,1.9,336.37],[2,1.88,239.33]],"ltp":1.91,"tv":14578.15,"id":2309796}]}]}
{"op":"mcm","clk":"1005408710","pt":1580642536969,"mc":[{"id":"1.168219387","rc":[{"trd":[[2.08,495.37]],"ltp":2.08,"tv":8123.87,"id":8535963},{"trd":[[1.92,916.23]],"batl":[[0,1.92,83.38]],"ltp":1.92,"tv":14581.79,"id":2309796}],"tv":22705.67}]}
{"op":"mcm","clk":"1005411505","pt":1580642551476,"mc":[{"id":"1.168219387","rc":[{"batb":[[0,1.96,43.69],[1,1.87,74.67],[2,1.67,409.76]],"batl":[[0,2.12,36.97],[1,2.72,241.55],[2,1000,0.02]],"ltp":2.08,"tv":8123.87,"id":8535963},{"batb":[[0,1.89,47.05],[1,1.83,194.93],[2,1.82,76.32]],"batl":[[1,2.06,39.49],[2,2.94,5.25]],"ltp":1.92,"tv":14581.79,"id":2309796}]}]}
{"op":"mcm","clk":"1005411727","pt":1580642552580,"mc":[{"id":"1.168219387","rc":[{"batb":[[0,1.87,74.67],[1,1.67,409.76],[2,1.52,39.74]],"batl":[[0,2.72,241.55],[1,1000,0.02],[2,1000,0]],"ltp":2.08,"tv":8123.87,"id":8535963},{"batb":[[0,1.83,194.93],[1,1.82,76.32],[2,1.55,20]],"batl":[[1,2.94,5.25],[2,6.4,2.73]],"ltp":1.92,"tv":14581.79,"id":2309796}]}]}
{"op":"mcm","clk":"1005412130","pt":1580642554485,"mc":[{"id":"1.168219387","rc":[{"batb":[[0,1.88,24.46],[1,1.87,74.67],[2,1.82,25.64]],"batl":[[0,2.22,5.75],[1,2.72,241.55],[2,1000,0.02]],"ltp":2.08,"tv":8123.87,"id":8535963},{"batb":[[0,1.83,218.96],[1,1.82,343.21],[2,1.8,275.72]],"batl":[[1,2.14,7.25],[2,2.16,260.99]],"ltp":1.92,"tv":14581.79,"id":2309796}]}]}
{"op":"mcm","clk":"1005413075","pt":1580642559500,"mc":[{"id":"1.168219387","rc":[{"batl":[[1,2.12,214.25],[2,2.14,7.25]],"ltp":1.92,"tv":14581.79,"id":2309796}]}]}
{"op":"mcm","clk":"1005413322","pt":1580642560846,"mc":[{"id":"1.168219387","rc":[{"batb":[[1,1.82,76.32],[2,1.55,20]],"ltp":1.92,"tv":14581.79,"id":2309796}]}]}
{"op":"mcm","clk":"1005413706","pt":1580642562869,"mc":[{"id":"1.168219387","rc":[{"batl":[[1,1000,0.02],[2,1000,0]],"ltp":2.08,"tv":8123.87,"id":8535963}]}]}
{"op":"mcm","clk":"1005414054","pt":1580642564732,"mc":[{"id":"1.168219387","rc":[{"trd":[[1.92,1082.99]],"batl":[[0,2.12,214.25],[1,2.14,7.25],[2,2.22,6.75]],"ltp":1.92,"tv":14748.55,"id":2309796}],"tv":22872.43}]}
{"op":"mcm","clk":"1005414202","pt":1580642565437,"mc":[{"id":"1.168219387","rc":[{"batb":[[0,1.83,452.53]],"ltp":1.92,"tv":14748.55,"id":2309796}]}]}
{"op":"mcm","clk":"1005414508","pt":1580642566987,"mc":[{"id":"1.168219387","rc":[{"batl":[[1,2.6,257.57],[2,1000,0.02]],"ltp":2.08,"tv":8123.87,"id":8535963}]}]}
{"op":"mcm","clk":"1005414866","pt":1580642568762,"mc":[{"id":"1.168219387","rc":[{"batb":[[2,1.81,252.4]],"ltp":1.92,"tv":14748.55,"id":2309796}]}]}
{"op":"mcm","clk":"1005414917","pt":1580642569071,"mc":[{"id":"1.168219387","rc":[{"batb":[[1,1.81,252.4],[2,1.79,280.84]],"ltp":1.92,"tv":14748.55,"id":2309796}]}]}
{"op":"mcm","clk":"1005415094","pt":1580642570080,"mc":[{"id":"1.168219387","rc":[{"batb":[[0,1.83,24.03]],"ltp":1.92,"tv":14748.55,"id":2309796}]}]}
